{"info": {"id": "1.167206536", "eventId": "29646660", "eventName": "2m Juv Hrd", "marketType": "WIN", "openDate": 1578745259983, "name": "Kemp  11th Jan", "numberOfActiveRunner": 9, "countryCode": "", "sport": "HORSE RACING", "venue": "", "volume": {"total": 626915.33, "preMatch": 462803.0, "inPlay": 164112.33}, "winner": {"id": 27145248, "name": "Goa Lil", "status": "WINNER", "position": 4}, "delay": 1}, "runners": [{"id": 19835010, "name": "Fraser Island", "status": "LOSER", "position": 1, "inPlayOdds": 2.2, "inPlayTime": 1578745259983, "avgPrematch": 2.09, "closedOdds": 1000.0, "maxPrematch": 2.28, "minPrematch": 1.93, "maxInPlay": 1000.0, "minInPlay": 2.08, "inPlayIndex": 4652, "lengthOdds": 4894, "lengthOddsPrematch": 4652, "lengthOddsInPlay": 242, "tradedVolume": 323102.12, "preMatchVolume": 285145.44, "inPlayVolume": 37956.68}, {"id": 19698534, "name": "Lord Lamington", "status": "LOSER", "position": 2, "inPlayOdds": 2.54, "inPlayTime": 1578745259983, "avgPrematch": 3.48, "closedOdds": 350.0, "maxPrematch": 5.7, "minPrematch": 2.56, "maxInPlay": 1000.0, "minInPlay": 1.71, "inPlayIndex": 5220, "lengthOdds": 5462, "lengthOddsPrematch": 5220, "lengthOddsInPlay": 242, "tradedVolume": 173048.39, "preMatchVolume": 132973.91, "inPlayVolume": 40074.48}, {"id": 6710054, "name": "Zarafshan", "status": "LOSER", "position": 3, "inPlayOdds": 22.0, "inPlayTime": 1578745259983, "avgPrematch": 17.41, "closedOdds": 1000.0, "maxPrematch": 24.0, "minPrematch": 11.0, "maxInPlay": 1000.0, "minInPlay": 5.9, "inPlayIndex": 2644, "lengthOdds": 2877, "lengthOddsPrematch": 2644, "lengthOddsInPlay": 233, "tradedVolume": 16423.13, "preMatchVolume": 12233.57, "inPlayVolume": 4189.56}, {"id": 27145248, "name": "Goa Lil", "status": "WINNER", "position": 4, "inPlayOdds": 23.0, "inPlayTime": 1578745259983, "avgPrematch": 20.76, "closedOdds": 1.01, "maxPrematch": 30.0, "minPrematch": 14.0, "maxInPlay": 32.0, "minInPlay": 1.01, "inPlayIndex": 2469, "lengthOdds": 2711, "lengthOddsPrematch": 2469, "lengthOddsInPlay": 242, "tradedVolume": 92571.82, "preMatchVolume": 13318.41, "inPlayVolume": 79253.41}, {"id": 19249441, "name": "Highway To Success", "status": "LOSER", "position": 5, "inPlayOdds": 34.0, "inPlayTime": 1578745259983, "avgPrematch": 25.7, "closedOdds": 1000.0, "maxPrematch": 36.0, "minPrematch": 17.5, "maxInPlay": 1000.0, "minInPlay": 22.0, "inPlayIndex": 2495, "lengthOdds": 2666, "lengthOddsPrematch": 2495, "lengthOddsInPlay": 171, "tradedVolume": 11554.0, "preMatchVolume": 10958.84, "inPlayVolume": 595.16}, {"id": 22864389, "name": "Sir Canford", "status": "LOSER", "position": 6, "inPlayOdds": 40.0, "inPlayTime": 1578745259983, "avgPrematch": 27.96, "closedOdds": 1000.0, "maxPrematch": 55.0, "minPrematch": 8.8, "maxInPlay": 1000.0, "minInPlay": 15.0, "inPlayIndex": 3197, "lengthOdds": 3427, "lengthOddsPrematch": 3197, "lengthOddsInPlay": 230, "tradedVolume": 7272.92, "preMatchVolume": 5529.04, "inPlayVolume": 1743.88}, {"id": 19641179, "name": "Fume", "status": "LOSER", "position": 7, "inPlayOdds": 290.0, "inPlayTime": 1578745259983, "avgPrematch": 209.27, "closedOdds": 1000.0, "maxPrematch": 490.0, "minPrematch": 80.0, "maxInPlay": 1000.0, "minInPlay": 160.0, "inPlayIndex": 1721, "lengthOdds": 1874, "lengthOddsPrematch": 1721, "lengthOddsInPlay": 153, "tradedVolume": 1100.49, "preMatchVolume": 1042.14, "inPlayVolume": 58.35}, {"id": 19963552, "name": "Pushmi Pullyu", "status": "LOSER", "position": 8, "inPlayOdds": 250.0, "inPlayTime": 1578745259983, "avgPrematch": 294.93, "closedOdds": 1000.0, "maxPrematch": 590.0, "minPrematch": 150.0, "maxInPlay": 1000.0, "minInPlay": 230.0, "inPlayIndex": 1429, "lengthOdds": 1558, "lengthOddsPrematch": 1429, "lengthOddsInPlay": 129, "tradedVolume": 977.81, "preMatchVolume": 882.51, "inPlayVolume": 95.3}, {"id": 19746625, "name": "Lonimoss Bareliere", "status": "LOSER", "position": 9, "inPlayOdds": 840.0, "inPlayTime": 1578745259983, "avgPrematch": 568.2, "closedOdds": 1000.0, "maxPrematch": 1000.0, "minPrematch": 150.0, "maxInPlay": 1000.0, "minInPlay": 720.0, "inPlayIndex": 1242, "lengthOdds": 1384, "lengthOddsPrematch": 1242, "lengthOddsInPlay": 142, "tradedVolume": 864.65, "preMatchVolume": 719.14, "inPlayVolume": 145.51}], "marketUpdates": [{"timestamp": 1578654109866000000, "openDate": "2020-01-11T12:20:00.000Z", "status": "OPEN", "betDelay": 0, "inPlay": false, "complete": true}, {"timestamp": 1578745258965000000, "openDate": "2020-01-11T12:20:00.000Z", "status": "SUSPENDED", "betDelay": 0, "inPlay": false, "complete": true}, {"timestamp": 1578745259983000000, "openDate": "2020-01-11T12:20:00.000Z", "status": "OPEN", "betDelay": 1, "inPlay": true, "complete": true}, {"timestamp": 1578745500982000000, "openDate": "2020-01-11T12:20:00.000Z", "status": "SUSPENDED", "betDelay": 1, "inPlay": true, "complete": true}, {"timestamp": 1578745627840000000, "openDate": "2020-01-11T12:20:00.000Z", "status": "CLOSED", "betDelay": 1, "inPlay": true, "complete": true}], "odds": [{"runnerId": 19835010, "odds": [{"timestamp": 1578674816688, "ltp": 2.06, "tv": 3.99, "trd": [[2.06, 4]], "batb": [[0, 2.06, 2.33]], "batl": NaN}, {"timestamp": 1578674822870, "ltp": 2.04, "tv": 14.0, "trd": [[2.04, 0.24], [2.06, 13.76]], "batb": [[0, 2.04, 10], [1, 2.02, 1.7], [2, 2, 4]], "batl": NaN}, {"timestamp": 1578674825791, "ltp": 2.04, "tv": 14.0, "trd": NaN, "batb": [[2, 2, 7]], "batl": NaN}, {"timestamp": 1578674875960, "ltp": 2.04, "tv": 14.0, "trd": NaN, "batb": [[0, 2.06, 1.7], [1, 2.04, 10]], "batl": NaN}, {"timestamp": 1578674882869, "ltp": 2.04, "tv": 14.0, "trd": NaN, "batb": [[0, 2.06, 4.25]], "batl": NaN}, {"timestamp": 1578674935510, "ltp": 2.04, "tv": 14.0, "trd": NaN, "batb": [[0, 2.08, 1.87], [1, 2.06, 4.25], [2, 2.04, 8.13]], "batl": NaN}, {"timestamp": 1578674993936, "ltp": 2.04, "tv": 14.0, "trd": NaN, "batb": [[0, 2.1, 1.7], [1, 2.08, 1.87], [2, 2.06, 2.55]], "batl": NaN}, {"timestamp": 1578675026651, "ltp": 2.04, "tv": 14.0, "trd": NaN, "batb": NaN, "batl": [[0, 2.2, 200], [1, 2.96, 5.98], [2, 2.98, 12]]}, {"timestamp": 1578675039788, "ltp": 2.04, "tv": 14.0, "trd": NaN, "batb": NaN, "batl": [[1, 2.96, 5.78]]}, {"timestamp": 1578675076239, "ltp": 2.04, "tv": 14.0, "trd": NaN, "batb": [[0, 2.12, 1.87], [1, 2.1, 1.7]], "batl": NaN}, {"timestamp": 1578675305195, "ltp": 2.1, "tv": 20.0, "trd": [[2.1, 2.26], [2.12, 3.74]], "batb": [[0, 2.06, 3.12], [1, 2.04, 8.13], [2, 2, 7]], "batl": NaN}, {"timestamp": 1578675319817, "ltp": 2.1, "tv": 20.0, "trd": NaN, "batb": [[0, 2.06, 2.55]], "batl": NaN}, {"timestamp": 1578675352981, "ltp": 2.1, "tv": 20.0, "trd": NaN, "batb": [[0, 2.08, 2.67], [1, 2.06, 2.55], [2, 2.04, 8.13]], "batl": [[1, 2.96, 4.88]]}, {"timestamp": 1578675401927, "ltp": 2.1, "tv": 20.0, "trd": NaN, "batb": [[0, 2.08, 10.8], [2, 2, 7]], "batl": NaN}, {"timestamp": 1578675423664, "ltp": 2.1, "tv": 20.0, "trd": NaN, "batb": [[0, 2.1, 2.55], [1, 2.08, 10.8], [2, 2.06, 2.55]], "batl": NaN}, {"timestamp": 1578675611980, "ltp": 2.1, "tv": 20.01, "trd": [[2.06, 13.77], [2.1, 2.26]], "batb": [[0, 2.1, 2.55], [1, 2.08, 10.82], [2, 2.06, 2.55]], "batl": [[1, 2.96, 4.89]]}, {"timestamp": 1578675642638, "ltp": 2.1, "tv": 20.01, "trd": NaN, "batb": [[0, 2.1, 10.7], [1, 2.08, 2.67]], "batl": NaN}, {"timestamp": 1578675841489, "ltp": 2.1, "tv": 20.01, "trd": NaN, "batb": [[0, 2.12, 1.9], [1, 2.1, 10.7], [2, 2.08, 2.67]], "batl": NaN}, {"timestamp": 1578675846972, "ltp": 2.1, "tv": 20.01, "trd": NaN, "batb": [[0, 2.12, 10.05], [1, 2.1, 2.55]], "batl": NaN}, {"timestamp": 1578675867392, "ltp": 2.1, "tv": 20.01, "trd": NaN, "batb": [[0, 2.12, 10.85]], "batl": NaN}, {"timestamp": 1578675903955, "ltp": 2.1, "tv": 20.01, "trd": NaN, "batb": [[0, 2.14, 3.36], [1, 2.12, 10.05], [2, 2.1, 2.55]], "batl": NaN}, {"timestamp": 1578675935907, "ltp": 2.1, "tv": 20.01, "trd": NaN, "batb": [[0, 2.14, 11.51], [1, 2.12, 1.9]], "batl": NaN}, {"timestamp": 1578676597091, "ltp": 2.2, "tv": 40.47, "trd": [[2.2, 20.46]], "batb": NaN, "batl": [[0, 2.2, 189.77]]}, {"timestamp": 1578676607439, "ltp": 2.2, "tv": 40.47, "trd": NaN, "batb": [[2, 2.1, 5.55]], "batl": NaN}, {"timestamp": 1578676652859, "ltp": 2.2, "tv": 60.93, "trd": [[2.2, 40.92]], "batb": NaN, "batl": [[0, 2.2, 179.54]]}, {"timestamp": 1578676754565, "ltp": 2.2, "tv": 60.93, "trd": NaN, "batb": NaN, "batl": [[0, 2.18, 137], [1, 2.2, 179.54], [2, 2.96, 4.89]]}, {"timestamp": 1578676808355, "ltp": 2.14, "tv": 83.94, "trd": [[2.14, 23.02]], "batb": [[0, 2.12, 1.9], [1, 2.1, 5.55], [2, 2.08, 2.67]], "batl": [[0, 2.14, 3.49], [1, 2.18, 137], [2, 2.2, 179.54]]}, {"timestamp": 1578676815748, "ltp": 2.14, "tv": 83.94, "trd": NaN, "batb": [[1, 2.1, 2.55]], "batl": NaN}, {"timestamp": 1578676978989, "ltp": 2.14, "tv": 90.92, "trd": [[2.14, 30]], "batb": [[0, 2.14, 7.04], [1, 2.12, 1.9], [2, 2.1, 2.55]], "batl": [[0, 2.18, 137], [1, 2.2, 179.54], [2, 2.96, 4.89]]}, {"timestamp": 1578676982793, "ltp": 2.14, "tv": 90.92, "trd": NaN, "batb": [[0, 2.16, 2.55], [1, 2.14, 7.04], [2, 2.12, 1.9]], "batl": NaN}, {"timestamp": 1578677001314, "ltp": 2.14, "tv": 90.92, "trd": NaN, "batb": [[1, 2.12, 1.9], [2, 2.1, 2.55]], "batl": NaN}, {"timestamp": 1578677006893, "ltp": 2.14, "tv": 90.92, "trd": NaN, "batb": [[1, 2.14, 2.01], [2, 2.12, 1.9]], "batl": NaN}, {"timestamp": 1578677011992, "ltp": 2.14, "tv": 90.92, "trd": NaN, "batb": [[0, 2.16, 4.26]], "batl": NaN}, {"timestamp": 1578677033998, "ltp": 2.18, "tv": 105.0, "trd": [[2.18, 14.08]], "batb": NaN, "batl": [[0, 2.18, 129.96]]}, {"timestamp": 1578677265934, "ltp": 2.18, "tv": 105.0, "trd": NaN, "batb": NaN, "batl": [[2, 2.3, 150]]}, {"timestamp": 1578677374343, "ltp": 2.16, "tv": 113.51, "trd": [[2.16, 8.51]], "batb": [[0, 2.14, 2.01], [1, 2.12, 1.9], [2, 2.1, 5.55]], "batl": [[0, 2.18, 130.71]]}, {"timestamp": 1578677375820, "ltp": 2.16, "tv": 113.51, "trd": NaN, "batb": NaN, "batl": [[2, 2.28, 6]]}, {"timestamp": 1578677382254, "ltp": 2.16, "tv": 113.51, "trd": NaN, "batb": [[2, 2.1, 2.55]], "batl": NaN}, {"timestamp": 1578677390948, "ltp": 2.16, "tv": 113.51, "trd": NaN, "batb": NaN, "batl": [[0, 2.18, 129.96]]}, {"timestamp": 1578677391526, "ltp": 2.14, "tv": 117.53, "trd": [[2.14, 34.02]], "batb": [[0, 2.12, 4.1], [1, 2.1, 2.55], [2, 2.08, 2.67]], "batl": NaN}, {"timestamp": 1578677556848, "ltp": 2.14, "tv": 117.53, "trd": NaN, "batb": [[2, 2.08, 102.67]], "batl": NaN}, {"timestamp": 1578677875795, "ltp": 2.14, "tv": 117.53, "trd": NaN, "batb": NaN, "batl": [[0, 2.18, 132.96]]}, {"timestamp": 1578677877725, "ltp": 2.14, "tv": 117.53, "trd": NaN, "batb": NaN, "batl": [[0, 2.16, 3], [1, 2.18, 129.96], [2, 2.2, 179.54]]}, {"timestamp": 1578677878824, "ltp": 2.14, "tv": 117.53, "trd": NaN, "batb": NaN, "batl": [[0, 2.18, 129.96], [1, 2.2, 179.54], [2, 2.28, 6]]}, {"timestamp": 1578678370181, "ltp": 2.14, "tv": 117.53, "trd": NaN, "batb": [[0, 2.14, 102.2], [1, 2.12, 4.1], [2, 2.1, 2.55]], "batl": NaN}, {"timestamp": 1578678422723, "ltp": 2.14, "tv": 117.53, "trd": NaN, "batb": [[0, 2.16, 2.55], [1, 2.14, 102.2], [2, 2.12, 4.1]], "batl": NaN}, {"timestamp": 1578678453053, "ltp": 2.18, "tv": 160.53, "trd": [[2.18, 57.08]], "batb": NaN, "batl": [[0, 2.18, 108.46]]}, {"timestamp": 1578678466661, "ltp": 2.18, "tv": 160.53, "trd": NaN, "batb": [[0, 2.16, 4.75], [2, 2.12, 1.9]], "batl": NaN}, {"timestamp": 1578678530619, "ltp": 2.16, "tv": 170.03, "trd": [[2.16, 18.01]], "batb": [[0, 2.14, 102.2], [1, 2.12, 1.9], [2, 2.1, 5.55]], "batl": NaN}, {"timestamp": 1578678537212, "ltp": 2.14, "tv": 374.43, "trd": [[2.14, 238.42]], "batb": [[0, 2.12, 1.9], [1, 2.1, 5.55], [2, 2.08, 2.67]], "batl": [[0, 2.14, 3.8], [1, 2.18, 108.46], [2, 2.2, 179.54]]}, {"timestamp": 1578678544512, "ltp": 2.14, "tv": 374.43, "trd": NaN, "batb": [[1, 2.1, 2.55]], "batl": NaN}, {"timestamp": 1578678573498, "ltp": 2.1, "tv": 383.34, "trd": [[2.1, 7.37], [2.12, 7.54]], "batb": [[0, 2.08, 2.67], [1, 2.06, 2.55], [2, 2, 7]], "batl": [[0, 2.1, 4.32], [1, 2.14, 3.8], [2, 2.18, 108.46]]}, {"timestamp": 1578678580983, "ltp": 2.1, "tv": 383.34, "trd": NaN, "batb": NaN, "batl": [[0, 2.14, 3.8], [1, 2.18, 108.46], [2, 2.2, 179.54]]}, {"timestamp": 1578678589276, "ltp": 2.08, "tv": 388.68, "trd": [[2.08, 5.34]], "batb": [[0, 2.06, 2.55], [1, 2, 7], [2, 1.88, 25]], "batl": [[0, 2.08, 1.65], [1, 2.14, 3.8], [2, 2.18, 108.46]]}, {"timestamp": 1578678603001, "ltp": 2.08, "tv": 388.68, "trd": NaN, "batb": [[0, 2.02, 2.55]], "batl": NaN}, {"timestamp": 1578678622940, "ltp": 2.08, "tv": 388.68, "trd": NaN, "batb": [[0, 2.04, 102.2], [1, 2.02, 2.55], [2, 2, 7]], "batl": NaN}, {"timestamp": 1578678633970, "ltp": 2.08, "tv": 388.68, "trd": NaN, "batb": NaN, "batl": [[0, 2.14, 3.8], [1, 2.18, 108.46], [2, 2.2, 179.54]]}, {"timestamp": 1578678634158, "ltp": 2.08, "tv": 388.68, "trd": NaN, "batb": NaN, "batl": [[1, 2.16, 6.21], [2, 2.18, 108.46]]}, {"timestamp": 1578678661970, "ltp": 2.08, "tv": 388.68, "trd": NaN, "batb": [[0, 2.06, 2.55], [1, 2.04, 102.2], [2, 2.02, 2.55]], "batl": NaN}, {"timestamp": 1578678729315, "ltp": 2.08, "tv": 388.68, "trd": NaN, "batb": [[0, 2.1, 100], [1, 2.06, 2.55], [2, 2.04, 102.2]], "batl": NaN}, {"timestamp": 1578678750685, "ltp": 2.08, "tv": 388.68, "trd": NaN, "batb": NaN, "batl": [[1, 2.16, 43.58]]}, {"timestamp": 1578678758865, "ltp": 2.08, "tv": 388.68, "trd": NaN, "batb": [[0, 2.06, 102.55], [1, 2.04, 102.2], [2, 2.02, 2.55]], "batl": NaN}, {"timestamp": 1578678770681, "ltp": 2.08, "tv": 401.36, "trd": [[2.08, 18.03]], "batb": [[2, 2.02, 102.55]], "batl": [[0, 2.08, 2.51], [1, 2.14, 3.8], [2, 2.16, 37.37]]}, {"timestamp": 1578678830460, "ltp": 2.08, "tv": 405.36, "trd": [[2.08, 22.03]], "batb": NaN, "batl": [[0, 2.14, 4.31], [1, 2.16, 37.37], [2, 2.18, 108.46]]}, {"timestamp": 1578678835161, "ltp": 2.14, "tv": 413.36, "trd": [[2.08, 23.05], [2.14, 245.4]], "batb": NaN, "batl": [[0, 2.16, 37.68], [1, 2.18, 108.46], [2, 2.2, 179.54]]}, {"timestamp": 1578678850470, "ltp": 2.16, "tv": 446.3, "trd": [[2.14, 246.02], [2.16, 50.33]], "batb": NaN, "batl": [[0, 2.16, 21.21]]}, {"timestamp": 1578678851603, "ltp": 2.16, "tv": 446.3, "trd": NaN, "batb": [[0, 2.08, 102.2], [1, 2.06, 102.55]], "batl": [[0, 2.16, 33.52]]}, {"timestamp": 1578678872917, "ltp": 2.16, "tv": 446.3, "trd": NaN, "batb": NaN, "batl": [[0, 2.14, 3.71], [1, 2.16, 33.52], [2, 2.18, 108.46]]}, {"timestamp": 1578678895148, "ltp": 2.16, "tv": 463.31, "trd": [[2.14, 253.44], [2.16, 59.91]], "batb": NaN, "batl": [[0, 2.16, 28.73], [1, 2.18, 108.46], [2, 2.2, 179.54]]}, {"timestamp": 1578678903622, "ltp": 2.16, "tv": 463.31, "trd": NaN, "batb": [[0, 2.1, 2.55], [1, 2.08, 102.2], [2, 2.06, 102.55]], "batl": NaN}, {"timestamp": 1578678962704, "ltp": 2.16, "tv": 506.11, "trd": [[2.16, 102.71]], "batb": NaN, "batl": [[0, 2.16, 7.33]]}, {"timestamp": 1578678981621, "ltp": 2.16, "tv": 506.11, "trd": NaN, "batb": NaN, "batl": [[0, 2.14, 39], [1, 2.16, 7.33], [2, 2.18, 108.46]]}, {"timestamp": 1578678986504, "ltp": 2.16, "tv": 506.11, "trd": NaN, "batb": NaN, "batl": [[0, 2.16, 46.33], [1, 2.18, 108.46], [2, 2.2, 179.54]]}, {"timestamp": 1578678996841, "ltp": 2.1, "tv": 523.99, "trd": [[2.1, 25.25]], "batb": [[0, 2.1, 95.81], [1, 2.06, 102.55], [2, 2.04, 6]], "batl": NaN}, {"timestamp": 1578679014954, "ltp": 2.1, "tv": 541.87, "trd": [[2.1, 43.13]], "batb": [[0, 2.1, 86.87]], "batl": NaN}, {"timestamp": 1578679022172, "ltp": 2.1, "tv": 541.87, "trd": NaN, "batb": [[0, 2.12, 2.55], [1, 2.1, 86.87], [2, 2.06, 102.55]], "batl": NaN}, {"timestamp": 1578679224562, "ltp": 2.12, "tv": 546.97, "trd": [[2.12, 12.64]], "batb": [[0, 2.1, 86.87], [1, 2.06, 102.55], [2, 2.04, 6]], "batl": [[0, 2.12, 2.45], [1, 2.16, 46.33], [2, 2.18, 108.46]]}, {"timestamp": 1578679230955, "ltp": 2.12, "tv": 546.97, "trd": NaN, "batb": [[0, 2.1, 91.87]], "batl": NaN}, {"timestamp": 1578679231261, "ltp": 2.12, "tv": 551.87, "trd": [[2.12, 17.54]], "batb": [[0, 2.12, 2.68], [1, 2.1, 91.87], [2, 2.06, 102.55]], "batl": [[0, 2.16, 39], [1, 2.18, 108.46], [2, 2.2, 179.54]]}, {"timestamp": 1578679240568, "ltp": 2.12, "tv": 551.87, "trd": NaN, "batb": [[0, 2.12, 12.93]], "batl": NaN}, {"timestamp": 1578679262228, "ltp": 2.12, "tv": 551.87, "trd": NaN, "batb": [[0, 2.14, 2.55], [1, 2.12, 12.93], [2, 2.1, 91.87]], "batl": NaN}, {"timestamp": 1578679307220, "ltp": 2.12, "tv": 551.87, "trd": NaN, "batb": NaN, "batl": [[2, 2.2, 191.54]]}, {"timestamp": 1578679356321, "ltp": 2.14, "tv": 556.98, "trd": [[2.14, 258.55]], "batb": [[0, 2.12, 12.93], [1, 2.1, 91.87], [2, 2.06, 102.55]], "batl": NaN}, {"timestamp": 1578679382134, "ltp": 2.14, "tv": 556.98, "trd": NaN, "batb": [[0, 2.14, 2.55], [1, 2.12, 12.93], [2, 2.1, 91.87]], "batl": NaN}, {"timestamp": 1578679398905, "ltp": 2.14, "tv": 562.08, "trd": [[2.14, 263.65]], "batb": [[0, 2.12, 12.93], [1, 2.1, 91.87], [2, 2.06, 102.55]], "batl": NaN}, {"timestamp": 1578679441681, "ltp": 2.14, "tv": 562.08, "trd": NaN, "batb": [[0, 2.14, 2.55], [1, 2.12, 12.93], [2, 2.1, 91.87]], "batl": NaN}, {"timestamp": 1578679445209, "ltp": 2.14, "tv": 562.08, "trd": NaN, "batb": NaN, "batl": [[1, 2.2, 191.54], [2, 2.28, 6]]}, {"timestamp": 1578679523117, "ltp": 2.14, "tv": 562.08, "trd": NaN, "batb": NaN, "batl": [[0, 2.16, 89]]}, {"timestamp": 1578679555688, "ltp": 2.16, "tv": 604.48, "trd": [[2.16, 145.11]], "batb": NaN, "batl": [[0, 2.16, 67.8]]}, {"timestamp": 1578679816624, "ltp": 2.16, "tv": 625.88, "trd": [[2.16, 166.51]], "batb": NaN, "batl": [[0, 2.16, 57.1]]}, {"timestamp": 1578679915730, "ltp": 2.1, "tv": 675.88, "trd": [[2.1, 62.17], [2.12, 43.4], [2.14, 268.75]], "batb": [[0, 2.1, 82.35], [1, 2.06, 102.55], [2, 2.04, 6]], "batl": NaN}, {"timestamp": 1578679922752, "ltp": 2.1, "tv": 675.88, "trd": NaN, "batb": [[0, 2.12, 2.55], [1, 2.1, 82.35], [2, 2.06, 102.55]], "batl": NaN}, {"timestamp": 1578679930962, "ltp": 2.12, "tv": 680.99, "trd": [[2.12, 48.51]], "batb": [[0, 2.1, 82.35], [1, 2.06, 102.55], [2, 2.04, 6]], "batl": [[0, 2.12, 9.45], [1, 2.16, 57.1], [2, 2.2, 179.54]]}, {"timestamp": 1578679933972, "ltp": 2.12, "tv": 680.99, "trd": NaN, "batb": [[1, 2.08, 6], [2, 2.06, 102.55]], "batl": NaN}, {"timestamp": 1578679983027, "ltp": 2.12, "tv": 680.99, "trd": NaN, "batb": [[0, 2.1, 84.9]], "batl": NaN}, {"timestamp": 1578680220640, "ltp": 2.12, "tv": 699.89, "trd": [[2.12, 67.41]], "batb": [[0, 2.12, 11.5], [1, 2.1, 84.9], [2, 2.08, 6]], "batl": [[0, 2.16, 57.1], [1, 2.2, 179.54], [2, 2.28, 6]]}, {"timestamp": 1578680222530, "ltp": 2.12, "tv": 699.89, "trd": NaN, "batb": [[0, 2.14, 2.55], [1, 2.12, 11.5], [2, 2.1, 84.9]], "batl": NaN}, {"timestamp": 1578680516999, "ltp": 2.14, "tv": 818.99, "trd": [[2.14, 273.86], [2.16, 280.51]], "batb": [[0, 2.12, 11.5], [1, 2.1, 84.9], [2, 2.08, 6]], "batl": [[0, 2.2, 179.64], [1, 2.28, 6], [2, 2.3, 150]]}, {"timestamp": 1578680522433, "ltp": 2.14, "tv": 818.99, "trd": NaN, "batb": [[0, 2.14, 2.55], [1, 2.12, 11.5], [2, 2.1, 84.9]], "batl": NaN}, {"timestamp": 1578680609972, "ltp": 2.14, "tv": 824.1, "trd": [[2.14, 278.96]], "batb": [[0, 2.12, 11.5], [1, 2.1, 84.9], [2, 2.08, 6]], "batl": [[0, 2.14, 1.45], [1, 2.2, 179.64], [2, 2.28, 6]]}, {"timestamp": 1578680641315, "ltp": 2.14, "tv": 824.1, "trd": NaN, "batb": NaN, "batl": [[0, 2.2, 179.64], [1, 2.28, 6], [2, 2.3, 150]]}, {"timestamp": 1578680642937, "ltp": 2.14, "tv": 824.1, "trd": NaN, "batb": [[0, 2.14, 2.55], [1, 2.12, 11.5], [2, 2.1, 84.9]], "batl": NaN}, {"timestamp": 1578680809896, "ltp": 2.2, "tv": 834.76, "trd": [[2.16, 280.71], [2.2, 51.38]], "batb": NaN, "batl": [[0, 2.2, 174.31]]}, {"timestamp": 1578680817181, "ltp": 2.2, "tv": 834.76, "trd": NaN, "batb": [[2, 2.1, 87.9]], "batl": NaN}, {"timestamp": 1578681176348, "ltp": 2.2, "tv": 845.0, "trd": [[2.2, 61.62]], "batb": NaN, "batl": [[0, 2.2, 169.19]]}, {"timestamp": 1578681283629, "ltp": 2.14, "tv": 850.1, "trd": [[2.14, 284.07]], "batb": [[0, 2.12, 11.5], [1, 2.1, 87.9], [2, 2.08, 6]], "batl": NaN}, {"timestamp": 1578681286971, "ltp": 2.14, "tv": 850.1, "trd": NaN, "batb": [[1, 2.1, 84.9]], "batl": NaN}, {"timestamp": 1578681302680, "ltp": 2.14, "tv": 850.1, "trd": NaN, "batb": [[0, 2.14, 2.55], [1, 2.12, 11.5], [2, 2.1, 84.9]], "batl": NaN}, {"timestamp": 1578681321794, "ltp": 2.1, "tv": 986.1, "trd": [[2.1, 170.07], [2.12, 90.41], [2.14, 289.17]], "batb": [[0, 2.1, 30.95], [1, 2.08, 6], [2, 2.06, 102.55]], "batl": NaN}, {"timestamp": 1578681493983, "ltp": 2.1, "tv": 1048.01, "trd": [[2.1, 231.97]], "batb": [[0, 2.08, 6], [1, 2.06, 102.55], [2, 2.04, 6]], "batl": NaN}, {"timestamp": 1578681501906, "ltp": 2.1, "tv": 1048.01, "trd": NaN, "batb": NaN, "batl": [[0, 2.18, 4], [1, 2.2, 169.19], [2, 2.28, 6]]}, {"timestamp": 1578681543751, "ltp": 2.1, "tv": 1048.01, "trd": NaN, "batb": [[0, 2.1, 2.55], [1, 2.08, 6], [2, 2.06, 102.55]], "batl": NaN}, {"timestamp": 1578681564367, "ltp": 2.1, "tv": 1048.01, "trd": NaN, "batb": [[0, 2.1, 12.07]], "batl": NaN}, {"timestamp": 1578681586310, "ltp": 2.1, "tv": 1048.01, "trd": NaN, "batb": NaN, "batl": [[0, 2.2, 169.19], [1, 2.28, 6], [2, 2.3, 150]]}, {"timestamp": 1578681696989, "ltp": 2.1, "tv": 1048.01, "trd": NaN, "batb": [[0, 2.1, 14.2]], "batl": NaN}, {"timestamp": 1578682157593, "ltp": 2.08, "tv": 1085.11, "trd": [[2.08, 31.75], [2.1, 260.38]], "batb": [[0, 2.08, 1.65], [1, 2.06, 102.55], [2, 2.04, 6]], "batl": NaN}, {"timestamp": 1578682166497, "ltp": 2.08, "tv": 1085.11, "trd": NaN, "batb": NaN, "batl": [[0, 2.18, 4.35], [1, 2.2, 169.19], [2, 2.28, 6]]}, {"timestamp": 1578682240990, "ltp": 2.08, "tv": 1085.11, "trd": NaN, "batb": [[0, 2.08, 6.65]], "batl": NaN}, {"timestamp": 1578682261837, "ltp": 2.08, "tv": 1085.11, "trd": NaN, "batb": [[0, 2.1, 2.55], [1, 2.08, 6.65], [2, 2.06, 102.55]], "batl": NaN}, {"timestamp": 1578682344714, "ltp": 2.08, "tv": 1085.11, "trd": NaN, "batb": NaN, "batl": [[0, 2.18, 26.93]]}, {"timestamp": 1578682433980, "ltp": 2.08, "tv": 1085.11, "trd": NaN, "batb": [[1, 2.08, 1.65]], "batl": NaN}, {"timestamp": 1578682443004, "ltp": 2.08, "tv": 1085.11, "trd": NaN, "batb": [[0, 2.08, 1.65], [1, 2.06, 102.55], [2, 2.04, 6]], "batl": NaN}, {"timestamp": 1578682665461, "ltp": 2.18, "tv": 1103.81, "trd": [[2.18, 75.78]], "batb": NaN, "batl": [[0, 2.18, 17.58]]}, {"timestamp": 1578682667447, "ltp": 2.18, "tv": 1103.81, "trd": NaN, "batb": [[0, 2.08, 4.65]], "batl": NaN}, {"timestamp": 1578682678369, "ltp": 2.18, "tv": 1103.81, "trd": NaN, "batb": [[0, 2.1, 3], [1, 2.08, 1.65], [2, 2.06, 102.55]], "batl": NaN}, {"timestamp": 1578682695198, "ltp": 2.18, "tv": 1103.81, "trd": NaN, "batb": [[0, 2.08, 4.65], [1, 2.06, 102.55], [2, 2.04, 6]], "batl": NaN}, {"timestamp": 1578682706910, "ltp": 2.1, "tv": 1107.81, "trd": [[2.1, 264.38]], "batb": [[0, 2.1, 1], [1, 2.08, 1.65], [2, 2.06, 102.55]], "batl": NaN}, {"timestamp": 1578682707124, "ltp": 2.1, "tv": 1109.81, "trd": [[2.1, 266.38]], "batb": [[0, 2.08, 1.65], [1, 2.06, 102.55], [2, 2.04, 6]], "batl": NaN}, {"timestamp": 1578682823802, "ltp": 2.1, "tv": 1109.83, "trd": [[2.06, 13.77], [2.08, 31.75], [2.1, 266.38], [2.14, 289.18], [2.16, 280.71]], "batb": NaN, "batl": NaN}, {"timestamp": 1578682903695, "ltp": 2.06, "tv": 1115.83, "trd": [[2.06, 16.47], [2.08, 35.05]], "batb": [[0, 2.06, 101.2], [1, 2.04, 6], [2, 2.02, 102.55]], "batl": NaN}, {"timestamp": 1578682904081, "ltp": 2.06, "tv": 1115.83, "trd": NaN, "batb": NaN, "batl": [[0, 2.18, 5.3]]}, {"timestamp": 1578682912069, "ltp": 2.06, "tv": 1115.83, "trd": NaN, "batb": NaN, "batl": [[0, 2.16, 1.65], [1, 2.18, 5.3], [2, 2.2, 169.19]]}, {"timestamp": 1578682965720, "ltp": 2.06, "tv": 1121.83, "trd": [[2.06, 22.47]], "batb": [[0, 2.06, 98.2]], "batl": NaN}, {"timestamp": 1578682982551, "ltp": 2.06, "tv": 1121.83, "trd": NaN, "batb": [[0, 2.08, 2.55], [1, 2.06, 98.2], [2, 2.04, 6]], "batl": NaN}, {"timestamp": 1578683103077, "ltp": 2.06, "tv": 1121.83, "trd": NaN, "batb": NaN, "batl": [[0, 2.12, 3], [1, 2.16, 1.65], [2, 2.18, 5.3]]}, {"timestamp": 1578683110298, "ltp": 2.06, "tv": 1121.83, "trd": NaN, "batb": NaN, "batl": [[0, 2.1, 1.65], [1, 2.12, 3]]}, {"timestamp": 1578683115310, "ltp": 2.06, "tv": 1121.83, "trd": NaN, "batb": [[0, 2.08, 4.39]], "batl": NaN}, {"timestamp": 1578683311681, "ltp": 2.08, "tv": 1130.6, "trd": [[2.08, 43.82]], "batb": [[0, 2.06, 98.2], [1, 2.04, 6], [2, 2.02, 102.55]], "batl": [[0, 2.08, 80.76], [1, 2.1, 1.65], [2, 2.12, 3]]}, {"timestamp": 1578683314000, "ltp": 2.08, "tv": 1130.6, "trd": NaN, "batb": NaN, "batl": [[0, 2.08, 82.41], [1, 2.12, 3], [2, 2.2, 169.19]]}, {"timestamp": 1578683314484, "ltp": 2.08, "tv": 1130.6, "trd": NaN, "batb": [[0, 2.06, 103.49]], "batl": [[2, 2.18, 6]]}, {"timestamp": 1578683342148, "ltp": 2.08, "tv": 1130.6, "trd": NaN, "batb": [[0, 2.06, 106.04]], "batl": NaN}, {"timestamp": 1578683678928, "ltp": 2.08, "tv": 1295.43, "trd": [[2.08, 208.64]], "batb": [[0, 2.08, 13.74], [1, 2.06, 106.04], [2, 2.04, 6]], "batl": [[0, 2.12, 3], [1, 2.18, 6], [2, 2.2, 169.19]]}, {"timestamp": 1578683685526, "ltp": 2.08, "tv": 1295.43, "trd": NaN, "batb": [[0, 2.08, 24.08]], "batl": NaN}, {"timestamp": 1578683701930, "ltp": 2.08, "tv": 1295.43, "trd": NaN, "batb": [[0, 2.1, 2.55], [1, 2.08, 24.08], [2, 2.06, 106.04]], "batl": NaN}, {"timestamp": 1578683715787, "ltp": 2.1, "tv": 1300.53, "trd": [[2.1, 271.49]], "batb": [[0, 2.08, 24.08], [1, 2.06, 106.04], [2, 2.04, 6]], "batl": [[0, 2.1, 2.45], [1, 2.12, 3], [2, 2.18, 6]]}, {"timestamp": 1578683762522, "ltp": 2.1, "tv": 1305.43, "trd": [[2.1, 276.39]], "batb": [[0, 2.08, 24.18]], "batl": [[0, 2.12, 3], [1, 2.18, 6], [2, 2.2, 169.19]]}, {"timestamp": 1578683773832, "ltp": 2.1, "tv": 1305.43, "trd": NaN, "batb": [[0, 2.1, 5.1], [1, 2.08, 24.08], [2, 2.06, 106.04]], "batl": NaN}, {"timestamp": 1578683843815, "ltp": 2.1, "tv": 1315.64, "trd": [[2.1, 286.59]], "batb": [[0, 2.08, 24.08], [1, 2.06, 106.04], [2, 2.04, 6]], "batl": NaN}, {"timestamp": 1578683882861, "ltp": 2.1, "tv": 1315.64, "trd": NaN, "batb": [[0, 2.1, 2.55], [1, 2.08, 24.08], [2, 2.06, 106.04]], "batl": NaN}, {"timestamp": 1578683978768, "ltp": 2.12, "tv": 1321.64, "trd": [[2.12, 96.41]], "batb": [[0, 2.12, 17], [1, 2.1, 2.55], [2, 2.08, 24.08]], "batl": [[0, 2.18, 6], [1, 2.2, 169.19], [2, 2.28, 6]]}, {"timestamp": 1578683979138, "ltp": 2.12, "tv": 1321.64, "trd": NaN, "batb": NaN, "batl": [[0, 2.18, 18.28]]}, {"timestamp": 1578684106697, "ltp": 2.12, "tv": 1321.64, "trd": NaN, "batb": NaN, "batl": [[2, 2.24, 10]]}, {"timestamp": 1578684348611, "ltp": 2.12, "tv": 1321.64, "trd": NaN, "batb": NaN, "batl": [[0, 2.16, 77], [1, 2.18, 18.28], [2, 2.2, 169.19]]}, {"timestamp": 1578684639947, "ltp": 2.12, "tv": 1331.64, "trd": [[2.12, 106.41]], "batb": [[0, 2.12, 12]], "batl": NaN}, {"timestamp": 1578684723801, "ltp": 2.12, "tv": 1349.69, "trd": [[2.12, 124.46]], "batb": [[0, 2.12, 2.97], [1, 2.1, 5.51]], "batl": NaN}, {"timestamp": 1578684811605, "ltp": 2.12, "tv": 1355.63, "trd": [[2.12, 130.4]], "batb": [[0, 2.1, 5.51], [1, 2.08, 24.08], [2, 2.06, 106.04]], "batl": [[0, 2.12, 9.03], [1, 2.16, 77], [2, 2.18, 18.28]]}, {"timestamp": 1578684818808, "ltp": 2.1, "tv": 1366.64, "trd": [[2.1, 297.6]], "batb": [[0, 2.08, 24.08], [1, 2.06, 106.04], [2, 2.04, 6]], "batl": [[0, 2.1, 3.53]]}, {"timestamp": 1578684819128, "ltp": 2.1, "tv": 1366.64, "trd": NaN, "batb": NaN, "batl": [[2, 2.18, 6]]}, {"timestamp": 1578684824937, "ltp": 2.08, "tv": 1373.7, "trd": [[2.08, 215.7]], "batb": [[0, 2.08, 20.55]], "batl": [[0, 2.16, 77], [1, 2.18, 6], [2, 2.2, 169.19]]}, {"timestamp": 1578684895690, "ltp": 2.08, "tv": 1373.7, "trd": NaN, "batb": NaN, "batl": [[0, 2.14, 1.9], [1, 2.16, 77], [2, 2.18, 6]]}, {"timestamp": 1578684902989, "ltp": 2.08, "tv": 1373.7, "trd": NaN, "batb": [[0, 2.1, 2.55], [1, 2.08, 20.55], [2, 2.06, 106.04]], "batl": NaN}, {"timestamp": 1578684955792, "ltp": 2.08, "tv": 1373.7, "trd": NaN, "batb": NaN, "batl": [[1, 2.18, 6], [2, 2.2, 169.19]]}, {"timestamp": 1578685260894, "ltp": 2.08, "tv": 1373.7, "trd": NaN, "batb": [[0, 2.1, 3.35]], "batl": NaN}, {"timestamp": 1578685450841, "ltp": 2.1, "tv": 1377.7, "trd": [[2.1, 300], [2.12, 132.01]], "batb": [[0, 2.1, 1.35]], "batl": NaN}, {"timestamp": 1578685534932, "ltp": 2.1, "tv": 1377.7, "trd": NaN, "batb": NaN, "batl": [[1, 2.18, 11]]}, {"timestamp": 1578685953961, "ltp": 2.1, "tv": 1377.7, "trd": NaN, "batb": NaN, "batl": [[2, 2.2, 179.19]]}, {"timestamp": 1578686015762, "ltp": 2.08, "tv": 1397.71, "trd": [[2.08, 233], [2.1, 302.7]], "batb": [[0, 2.08, 11.9], [1, 2.06, 106.04], [2, 2.04, 6]], "batl": NaN}, {"timestamp": 1578686077255, "ltp": 2.08, "tv": 1397.71, "trd": NaN, "batb": NaN, "batl": [[1, 2.16, 5], [2, 2.18, 11]]}, {"timestamp": 1578686165907, "ltp": 2.08, "tv": 1397.71, "trd": NaN, "batb": NaN, "batl": [[0, 2.12, 26], [1, 2.14, 1.9], [2, 2.16, 5]]}, {"timestamp": 1578686210361, "ltp": 2.08, "tv": 1397.71, "trd": NaN, "batb": [[0, 2.08, 21.9]], "batl": NaN}, {"timestamp": 1578686226359, "ltp": 2.08, "tv": 1397.71, "trd": NaN, "batb": NaN, "batl": [[0, 2.1, 10], [1, 2.12, 26], [2, 2.14, 1.9]]}, {"timestamp": 1578686294949, "ltp": 2.1, "tv": 1417.71, "trd": [[2.1, 322.7]], "batb": NaN, "batl": [[0, 2.12, 26], [1, 2.14, 1.9], [2, 2.16, 5]]}, {"timestamp": 1578686343951, "ltp": 2.1, "tv": 1417.71, "trd": NaN, "batb": NaN, "batl": [[0, 2.1, 30], [1, 2.12, 26], [2, 2.14, 1.9]]}, {"timestamp": 1578686368802, "ltp": 2.1, "tv": 1417.71, "trd": NaN, "batb": [[0, 2.08, 23.6]], "batl": NaN}, {"timestamp": 1578686387404, "ltp": 2.1, "tv": 1462.13, "trd": [[2.1, 367.12]], "batb": NaN, "batl": [[0, 2.1, 7.79]]}, {"timestamp": 1578686408666, "ltp": 2.1, "tv": 1476.13, "trd": [[2.1, 381.12]], "batb": NaN, "batl": [[0, 2.12, 26.79], [1, 2.14, 1.9], [2, 2.16, 5]]}, {"timestamp": 1578686481360, "ltp": 2.08, "tv": 1496.13, "trd": [[2.08, 253]], "batb": [[0, 2.08, 13.6]], "batl": NaN}, {"timestamp": 1578686659937, "ltp": 2.08, "tv": 1496.13, "trd": NaN, "batb": NaN, "batl": [[0, 2.1, 5.79], [1, 2.12, 26], [2, 2.14, 1.9]]}, {"timestamp": 1578686672562, "ltp": 2.1, "tv": 1506.13, "trd": [[2.1, 391.12]], "batb": NaN, "batl": [[0, 2.12, 26.79], [1, 2.14, 1.9], [2, 2.16, 5]]}, {"timestamp": 1578687017860, "ltp": 2.08, "tv": 1533.33, "trd": [[2.08, 280.21]], "batb": [[0, 2.06, 106.04], [1, 2.04, 6], [2, 2.02, 102.55]], "batl": [[0, 2.08, 86.4], [1, 2.12, 26.79], [2, 2.14, 1.9]]}, {"timestamp": 1578687038475, "ltp": 2.08, "tv": 1533.33, "trd": NaN, "batb": NaN, "batl": [[0, 2.12, 26.79], [1, 2.14, 1.9], [2, 2.16, 5]]}, {"timestamp": 1578687044916, "ltp": 2.08, "tv": 1533.33, "trd": NaN, "batb": [[0, 2.08, 232], [1, 2.06, 100.75], [2, 2.04, 6]], "batl": NaN}, {"timestamp": 1578687045786, "ltp": 2.1, "tv": 1534.91, "trd": [[2.1, 392.71]], "batb": [[0, 2.1, 18.59], [1, 2.08, 232], [2, 2.06, 100.75]], "batl": [[0, 2.12, 26]]}, {"timestamp": 1578687046225, "ltp": 2.08, "tv": 1734.92, "trd": [[2.08, 443.05], [2.1, 429.87]], "batb": [[0, 2.08, 150.58], [1, 2.06, 100.75], [2, 2.04, 6]], "batl": NaN}, {"timestamp": 1578687051899, "ltp": 2.08, "tv": 1734.92, "trd": NaN, "batb": [[0, 2.08, 152.56]], "batl": NaN}, {"timestamp": 1578687084934, "ltp": 2.0, "tv": 2466.69, "trd": [[2, 8], [2.02, 205.12], [2.04, 12.24], [2.06, 224], [2.08, 748.17]], "batb": [[0, 1.88, 25], [1, 1.85, 8.11], [2, 1.75, 90]], "batl": [[0, 1.99, 6.68], [1, 2, 485.59], [2, 2.12, 26]]}, {"timestamp": 1578687085418, "ltp": 2.0, "tv": 2466.69, "trd": NaN, "batb": NaN, "batl": [[0, 1.99, 32.1]]}, {"timestamp": 1578687086709, "ltp": 1.99, "tv": 2470.69, "trd": [[1.99, 4]], "batb": NaN, "batl": [[0, 1.99, 30.1]]}, {"timestamp": 1578687094330, "ltp": 1.99, "tv": 2470.69, "trd": NaN, "batb": NaN, "batl": [[0, 1.98, 6], [1, 1.99, 30.1], [2, 2, 485.59]]}, {"timestamp": 1578687115559, "ltp": 1.99, "tv": 2470.69, "trd": NaN, "batb": NaN, "batl": [[0, 1.97, 2], [1, 1.98, 6], [2, 1.99, 30.1]]}, {"timestamp": 1578687119950, "ltp": 1.99, "tv": 2470.69, "trd": NaN, "batb": NaN, "batl": [[0, 1.96, 6], [1, 1.97, 2]]}, {"timestamp": 1578687120853, "ltp": 1.99, "tv": 2470.69, "trd": NaN, "batb": NaN, "batl": [[0, 1.95, 4.78], [1, 1.96, 6], [2, 1.97, 2]]}, {"timestamp": 1578687121948, "ltp": 1.95, "tv": 2474.69, "trd": [[1.95, 4]], "batb": [[0, 1.89, 2.55], [1, 1.88, 25], [2, 1.85, 8.11]], "batl": [[0, 1.95, 2.78]]}, {"timestamp": 1578687122968, "ltp": 1.95, "tv": 2478.69, "trd": [[1.95, 8]], "batb": NaN, "batl": [[0, 1.96, 6.78], [1, 1.97, 2], [2, 1.99, 25.42]]}, {"timestamp": 1578687124803, "ltp": 2.0, "tv": 2717.45, "trd": [[1.95, 9.56], [1.96, 12], [1.97, 4], [1.99, 54.84], [2, 178.37]], "batb": NaN, "batl": [[0, 2, 400.41], [1, 2.12, 26], [2, 2.14, 1.9]]}, {"timestamp": 1578687129999, "ltp": 2.0, "tv": 2717.45, "trd": NaN, "batb": [[0, 1.9, 6.89], [1, 1.89, 2.55], [2, 1.88, 25]], "batl": [[1, 2.1, 6.23], [2, 2.12, 26]]}, {"timestamp": 1578687163983, "ltp": 2.0, "tv": 2717.45, "trd": NaN, "batb": [[0, 1.91, 2.06], [1, 1.9, 6.89], [2, 1.89, 2.55]], "batl": NaN}, {"timestamp": 1578687173534, "ltp": 2.0, "tv": 2773.46, "trd": [[2, 234.37]], "batb": NaN, "batl": [[0, 2, 372.4]]}, {"timestamp": 1578687183725, "ltp": 2.0, "tv": 2773.46, "trd": NaN, "batb": [[0, 1.91, 4.61]], "batl": NaN}, {"timestamp": 1578687194735, "ltp": 2.0, "tv": 2795.0, "trd": [[2, 255.91]], "batb": NaN, "batl": [[0, 2, 361.63]]}, {"timestamp": 1578687204077, "ltp": 2.0, "tv": 2795.0, "trd": NaN, "batb": NaN, "batl": [[1, 2.08, 25], [2, 2.1, 6.23]]}, {"timestamp": 1578687208880, "ltp": 2.0, "tv": 2945.76, "trd": [[2, 406.68]], "batb": NaN, "batl": [[0, 2, 286.25]]}, {"timestamp": 1578687231691, "ltp": 2.0, "tv": 2989.8, "trd": [[2, 450.72]], "batb": NaN, "batl": [[0, 2, 264.23]]}, {"timestamp": 1578687244927, "ltp": 2.0, "tv": 3086.2, "trd": [[2, 547.12]], "batb": NaN, "batl": [[0, 2, 216.03]]}, {"timestamp": 1578687260294, "ltp": 2.0, "tv": 3107.42, "trd": [[2, 568.34]], "batb": NaN, "batl": [[0, 2, 205.42]]}, {"timestamp": 1578687278830, "ltp": 2.0, "tv": 3321.83, "trd": [[2, 782.74]], "batb": NaN, "batl": [[0, 2, 98.21]]}, {"timestamp": 1578687295614, "ltp": 2.0, "tv": 3348.8, "trd": [[2, 809.72]], "batb": NaN, "batl": [[0, 2, 84.72]]}, {"timestamp": 1578687299651, "ltp": 2.0, "tv": 3366.89, "trd": [[2, 827.8]], "batb": NaN, "batl": [[0, 2, 75.68]]}, {"timestamp": 1578687302935, "ltp": 2.0, "tv": 3366.89, "trd": NaN, "batb": [[0, 1.92, 2.88], [1, 1.91, 4.61]], "batl": NaN}, {"timestamp": 1578687307939, "ltp": 2.0, "tv": 3366.89, "trd": NaN, "batb": [[0, 1.93, 2.04], [1, 1.92, 2.88], [2, 1.91, 2.55]], "batl": NaN}, {"timestamp": 1578687315456, "ltp": 2.0, "tv": 3416.89, "trd": [[2, 877.8]], "batb": NaN, "batl": [[0, 2, 50.68]]}, {"timestamp": 1578687319465, "ltp": 2.0, "tv": 3416.89, "trd": NaN, "batb": [[0, 1.94, 4.39], [1, 1.93, 2.04], [2, 1.92, 2.88]], "batl": NaN}, {"timestamp": 1578687329964, "ltp": 2.0, "tv": 3416.89, "trd": NaN, "batb": [[0, 1.95, 7.42], [1, 1.94, 4.39], [2, 1.93, 2.04]], "batl": NaN}, {"timestamp": 1578687335982, "ltp": 2.0, "tv": 3416.89, "trd": NaN, "batb": [[0, 1.95, 9.53]], "batl": NaN}, {"timestamp": 1578687356808, "ltp": 2.0, "tv": 3416.89, "trd": NaN, "batb": [[0, 1.96, 2.01], [1, 1.95, 9.53], [2, 1.94, 4.39]], "batl": NaN}, {"timestamp": 1578687360220, "ltp": 2.0, "tv": 3436.17, "trd": [[2, 897.08]], "batb": NaN, "batl": [[0, 2, 41.04]]}, {"timestamp": 1578687362997, "ltp": 2.0, "tv": 3436.17, "trd": NaN, "batb": [[0, 1.96, 4.56]], "batl": NaN}, {"timestamp": 1578687372519, "ltp": 2.0, "tv": 3453.52, "trd": [[2, 914.44]], "batb": NaN, "batl": [[0, 2, 32.37]]}, {"timestamp": 1578687382839, "ltp": 2.0, "tv": 3453.52, "trd": NaN, "batb": [[0, 1.96, 6.67], [1, 1.95, 7.42]], "batl": NaN}, {"timestamp": 1578687384443, "ltp": 2.0, "tv": 3472.8, "trd": [[2, 933.72]], "batb": NaN, "batl": [[0, 2, 22.73]]}, {"timestamp": 1578687411580, "ltp": 2.0, "tv": 3518.26, "trd": [[2, 979.17]], "batb": NaN, "batl": [[0, 2.08, 25], [1, 2.1, 6.23], [2, 2.12, 26]]}, {"timestamp": 1578687425996, "ltp": 2.0, "tv": 3518.26, "trd": NaN, "batb": NaN, "batl": [[0, 2.06, 4], [1, 2.08, 25], [2, 2.1, 6.23]]}, {"timestamp": 1578687426908, "ltp": 2.0, "tv": 3518.26, "trd": NaN, "batb": [[0, 1.97, 2.8], [1, 1.96, 6.67], [2, 1.95, 7.42]], "batl": NaN}, {"timestamp": 1578687429000, "ltp": 2.0, "tv": 3518.26, "trd": NaN, "batb": [[0, 1.97, 4.9], [1, 1.96, 4.56]], "batl": NaN}, {"timestamp": 1578687444618, "ltp": 2.0, "tv": 3518.26, "trd": NaN, "batb": [[0, 1.97, 304.9]], "batl": NaN}, {"timestamp": 1578687446970, "ltp": 2.0, "tv": 3518.26, "trd": NaN, "batb": NaN, "batl": [[1, 2.1, 6.23], [2, 2.12, 26]]}, {"timestamp": 1578687447924, "ltp": 2.0, "tv": 3518.26, "trd": NaN, "batb": [[0, 1.98, 19.47], [1, 1.97, 304.9], [2, 1.96, 4.56]], "batl": NaN}, {"timestamp": 1578687451752, "ltp": 2.0, "tv": 3518.26, "trd": NaN, "batb": [[0, 1.98, 319.47], [1, 1.97, 4.9]], "batl": NaN}, {"timestamp": 1578687454146, "ltp": 2.0, "tv": 3518.26, "trd": NaN, "batb": [[0, 1.99, 3], [1, 1.98, 319.47], [2, 1.97, 4.9]], "batl": [[0, 2.1, 6.23], [1, 2.12, 26], [2, 2.14, 1.9]]}, {"timestamp": 1578687460980, "ltp": 2.0, "tv": 3518.26, "trd": NaN, "batb": [[0, 2, 300], [1, 1.99, 3], [2, 1.98, 19.47]], "batl": NaN}, {"timestamp": 1578687462973, "ltp": 2.0, "tv": 3518.26, "trd": NaN, "batb": [[0, 2.02, 19.57], [1, 2, 300], [2, 1.99, 3]], "batl": NaN}, {"timestamp": 1578687468980, "ltp": 2.0, "tv": 3518.26, "trd": NaN, "batb": [[1, 1.99, 3], [2, 1.97, 4.9]], "batl": NaN}, {"timestamp": 1578687470003, "ltp": 2.0, "tv": 3518.26, "trd": NaN, "batb": [[0, 2.06, 10.09], [1, 2.04, 300], [2, 1.99, 3]], "batl": NaN}, {"timestamp": 1578687473878, "ltp": 2.0, "tv": 3518.26, "trd": NaN, "batb": [[0, 2.06, 12.19]], "batl": NaN}, {"timestamp": 1578687474687, "ltp": 2.0, "tv": 3518.26, "trd": NaN, "batb": [[0, 2.06, 21.5], [1, 2.02, 300]], "batl": [[0, 2.08, 6.35], [1, 2.1, 6.23], [2, 2.12, 26]]}, {"timestamp": 1578687476721, "ltp": 2.0, "tv": 3518.26, "trd": NaN, "batb": [[0, 2.06, 2.1]], "batl": NaN}, {"timestamp": 1578687479622, "ltp": 2.0, "tv": 3518.26, "trd": NaN, "batb": [[1, 2.04, 6], [2, 2.02, 300]], "batl": NaN}, {"timestamp": 1578687481920, "ltp": 2.0, "tv": 3518.26, "trd": NaN, "batb": [[0, 2.06, 4.66], [1, 2.04, 16.18]], "batl": NaN}, {"timestamp": 1578687486922, "ltp": 2.0, "tv": 3518.26, "trd": NaN, "batb": [[1, 2.04, 25.77]], "batl": NaN}, {"timestamp": 1578687499076, "ltp": 2.0, "tv": 3518.26, "trd": NaN, "batb": [[0, 2.06, 11.23]], "batl": NaN}, {"timestamp": 1578687506399, "ltp": 2.0, "tv": 3518.26, "trd": NaN, "batb": [[2, 2.02, 283]], "batl": NaN}, {"timestamp": 1578687513973, "ltp": 2.0, "tv": 3518.26, "trd": NaN, "batb": [[0, 2.06, 294.23], [2, 1.97, 2.8]], "batl": NaN}, {"timestamp": 1578687514736, "ltp": 2.08, "tv": 3530.96, "trd": [[2.08, 760.88]], "batb": [[0, 2.08, 13.79], [1, 2.06, 294.23], [2, 2.04, 6]], "batl": [[0, 2.1, 6.23], [1, 2.12, 26], [2, 2.14, 1.9]]}, {"timestamp": 1578687517144, "ltp": 2.08, "tv": 3530.96, "trd": NaN, "batb": [[2, 1.97, 2.8]], "batl": NaN}, {"timestamp": 1578687520958, "ltp": 2.08, "tv": 3530.96, "trd": NaN, "batb": [[2, 2.02, 350]], "batl": NaN}, {"timestamp": 1578687521968, "ltp": 2.08, "tv": 3530.96, "trd": NaN, "batb": [[0, 2.08, 15.89], [1, 2.06, 292.13]], "batl": [[0, 2.12, 26], [1, 2.14, 1.9], [2, 2.16, 5]]}, {"timestamp": 1578687524574, "ltp": 2.08, "tv": 3530.96, "trd": NaN, "batb": [[2, 2.04, 6]], "batl": NaN}, {"timestamp": 1578687530578, "ltp": 2.08, "tv": 3530.96, "trd": NaN, "batb": NaN, "batl": [[0, 2.1, 1.7], [1, 2.12, 26], [2, 2.14, 1.9]]}, {"timestamp": 1578687531698, "ltp": 2.08, "tv": 3530.96, "trd": NaN, "batb": NaN, "batl": [[0, 2.12, 26], [1, 2.14, 1.9], [2, 2.16, 5]]}, {"timestamp": 1578687653532, "ltp": 2.06, "tv": 3986.97, "trd": [[2.06, 648.22], [2.08, 792.66]], "batb": [[0, 2.06, 80.01], [1, 2.04, 6], [2, 2.02, 350]], "batl": NaN}, {"timestamp": 1578687654168, "ltp": 2.06, "tv": 3986.97, "trd": NaN, "batb": [[0, 2.08, 6.34], [1, 2.06, 80.01], [2, 2.04, 6]], "batl": NaN}, {"timestamp": 1578687657563, "ltp": 2.06, "tv": 3986.97, "trd": NaN, "batb": [[0, 2.08, 8.04]], "batl": NaN}, {"timestamp": 1578687680363, "ltp": 2.08, "tv": 4003.06, "trd": [[2.08, 808.75]], "batb": [[0, 2.06, 80.01], [1, 2.04, 6], [2, 2.02, 350]], "batl": [[0, 2.08, 8.98], [1, 2.12, 26], [2, 2.14, 1.9]]}, {"timestamp": 1578687689690, "ltp": 2.06, "tv": 4038.56, "trd": [[2.06, 683.73]], "batb": [[0, 2.06, 62.26]], "batl": [[0, 2.12, 26], [1, 2.14, 1.9], [2, 2.16, 5]]}, {"timestamp": 1578687695991, "ltp": 2.06, "tv": 4056.1, "trd": [[2.06, 701.27]], "batb": [[0, 2.06, 53.49], [1, 2.04, 41]], "batl": NaN}, {"timestamp": 1578687700974, "ltp": 2.12, "tv": 4106.82, "trd": [[2.12, 182.73]], "batb": NaN, "batl": [[0, 2.14, 2.54], [1, 2.16, 5], [2, 2.18, 6]]}, {"timestamp": 1578687701822, "ltp": 2.12, "tv": 4106.82, "trd": NaN, "batb": NaN, "batl": [[2, 2.18, 25.76]]}, {"timestamp": 1578687716452, "ltp": 2.12, "tv": 4106.82, "trd": NaN, "batb": [[0, 2.08, 3], [1, 2.06, 53.49], [2, 2.04, 41]], "batl": NaN}, {"timestamp": 1578687722964, "ltp": 2.12, "tv": 4106.82, "trd": NaN, "batb": [[0, 2.08, 5.55]], "batl": NaN}, {"timestamp": 1578687750008, "ltp": 2.12, "tv": 4106.82, "trd": NaN, "batb": [[0, 2.08, 2.55]], "batl": NaN}, {"timestamp": 1578687777867, "ltp": 2.12, "tv": 4106.82, "trd": NaN, "batb": [[0, 2.08, 12.55]], "batl": NaN}, {"timestamp": 1578687779161, "ltp": 2.12, "tv": 4106.82, "trd": NaN, "batb": [[0, 2.08, 60.63]], "batl": NaN}, {"timestamp": 1578687789960, "ltp": 2.12, "tv": 4108.1, "trd": [[2.12, 184.01]], "batb": [[0, 2.12, 9.89], [1, 2.08, 60.63], [2, 2.06, 53.49]], "batl": [[0, 2.14, 1.9]]}, {"timestamp": 1578687842976, "ltp": 2.12, "tv": 4108.1, "trd": NaN, "batb": [[1, 2.08, 58.08]], "batl": NaN}, {"timestamp": 1578687902002, "ltp": 2.12, "tv": 4108.1, "trd": NaN, "batb": [[2, 2.04, 6]], "batl": NaN}, {"timestamp": 1578687912837, "ltp": 2.12, "tv": 4108.1, "trd": NaN, "batb": [[1, 2.1, 6], [2, 2.08, 58.08]], "batl": NaN}, {"timestamp": 1578687938701, "ltp": 2.12, "tv": 4118.1, "trd": [[2.12, 194.01]], "batb": [[0, 2.12, 4.89]], "batl": NaN}, {"timestamp": 1578687940903, "ltp": 2.12, "tv": 4118.1, "trd": NaN, "batb": [[1, 2.1, 27.9]], "batl": NaN}, {"timestamp": 1578687951802, "ltp": 2.12, "tv": 4118.1, "trd": NaN, "batb": NaN, "batl": [[0, 2.14, 186.9]]}, {"timestamp": 1578687952721, "ltp": 2.12, "tv": 4127.88, "trd": [[2.12, 203.79]], "batb": [[0, 2.1, 27.9], [1, 2.08, 58.08], [2, 2.04, 6]], "batl": [[0, 2.12, 1.38], [1, 2.14, 186.9], [2, 2.16, 5]]}, {"timestamp": 1578687953033, "ltp": 2.12, "tv": 4127.88, "trd": NaN, "batb": NaN, "batl": [[0, 2.12, 20.3]]}, {"timestamp": 1578687987911, "ltp": 2.12, "tv": 4127.88, "trd": NaN, "batb": NaN, "batl": [[0, 2.12, 205.3], [1, 2.14, 1.9]]}, {"timestamp": 1578687988019, "ltp": 2.12, "tv": 4128.54, "trd": [[2.12, 204.45]], "batb": NaN, "batl": [[0, 2.12, 204.97]]}, {"timestamp": 1578687995963, "ltp": 2.1, "tv": 4184.34, "trd": [[2.1, 485.67]], "batb": [[0, 2.08, 58.08], [1, 2.04, 6], [2, 2.02, 350]], "batl": [[0, 2.1, 157.1], [1, 2.12, 19.97], [2, 2.14, 1.9]]}, {"timestamp": 1578687997546, "ltp": 2.08, "tv": 4205.3, "trd": [[2.08, 829.71]], "batb": [[0, 2.08, 47.6]], "batl": [[1, 2.12, 11]]}, {"timestamp": 1578687998851, "ltp": 2.08, "tv": 4217.3, "trd": [[2.08, 841.71]], "batb": [[0, 2.08, 41.6]], "batl": NaN}, {"timestamp": 1578687999135, "ltp": 2.08, "tv": 4217.3, "trd": NaN, "batb": NaN, "batl": [[1, 2.12, 1.05]]}, {"timestamp": 1578688050820, "ltp": 2.08, "tv": 4235.05, "trd": [[2.08, 859.45]], "batb": [[0, 2.08, 32.73]], "batl": NaN}, {"timestamp": 1578688052735, "ltp": 2.08, "tv": 4235.05, "trd": NaN, "batb": [[1, 2.04, 15.38]], "batl": NaN}, {"timestamp": 1578688053232, "ltp": 2.08, "tv": 4300.51, "trd": [[2.08, 924.91]], "batb": [[0, 2.04, 15.38], [1, 2.02, 350], [2, 2, 22.02]], "batl": [[0, 2.08, 9.27], [1, 2.1, 157.1], [2, 2.12, 1.05]]}, {"timestamp": 1578688054633, "ltp": 2.08, "tv": 4300.51, "trd": NaN, "batb": [[0, 2.04, 39.57]], "batl": [[2, 2.14, 1.9]]}, {"timestamp": 1578688080514, "ltp": 2.08, "tv": 4300.51, "trd": NaN, "batb": NaN, "batl": [[0, 2.08, 29.27]]}, {"timestamp": 1578688111074, "ltp": 2.08, "tv": 4300.51, "trd": NaN, "batb": NaN, "batl": [[0, 2.08, 20], [1, 2.14, 1.9], [2, 2.16, 5]]}, {"timestamp": 1578688135655, "ltp": 2.08, "tv": 4340.51, "trd": [[2.08, 964.91]], "batb": [[0, 2.08, 1.67], [1, 2.04, 39.57], [2, 2.02, 350]], "batl": [[0, 2.14, 1.9], [1, 2.16, 5], [2, 2.18, 6]]}, {"timestamp": 1578688179877, "ltp": 2.08, "tv": 4340.51, "trd": NaN, "batb": [[1, 2.06, 3], [2, 2.04, 39.57]], "batl": NaN}, {"timestamp": 1578688187004, "ltp": 2.08, "tv": 4340.51, "trd": NaN, "batb": [[2, 2.04, 67.37]], "batl": NaN}, {"timestamp": 1578688273908, "ltp": 2.08, "tv": 4340.51, "trd": NaN, "batb": [[0, 2.06, 3], [1, 2.04, 67.37], [2, 2.02, 350]], "batl": NaN}, {"timestamp": 1578688301412, "ltp": 2.16, "tv": 4344.51, "trd": [[2.14, 292.98], [2.16, 280.91]], "batb": NaN, "batl": [[0, 2.16, 4.9], [1, 2.18, 6], [2, 2.2, 179.19]]}, {"timestamp": 1578688360740, "ltp": 2.06, "tv": 4350.51, "trd": [[2.06, 707.27]], "batb": [[0, 2.04, 67.37], [1, 2.02, 350], [2, 2, 22.02]], "batl": NaN}, {"timestamp": 1578688369769, "ltp": 2.06, "tv": 4350.51, "trd": NaN, "batb": NaN, "batl": [[0, 2.14, 2.89], [1, 2.16, 4.9], [2, 2.18, 6]]}, {"timestamp": 1578688386748, "ltp": 2.06, "tv": 4350.51, "trd": NaN, "batb": [[0, 2.04, 69.14]], "batl": NaN}, {"timestamp": 1578688754773, "ltp": 2.04, "tv": 4353.91, "trd": [[2.04, 15.65]], "batb": [[0, 2.04, 67.44]], "batl": NaN}, {"timestamp": 1578688763898, "ltp": 2.04, "tv": 4353.91, "trd": NaN, "batb": NaN, "batl": [[0, 2.14, 4.59]]}, {"timestamp": 1578688835326, "ltp": 2.04, "tv": 4353.91, "trd": NaN, "batb": [[0, 2.06, 10], [1, 2.04, 67.44], [2, 2.02, 350]], "batl": NaN}, {"timestamp": 1578688992824, "ltp": 2.04, "tv": 4353.91, "trd": NaN, "batb": [[0, 2.06, 11.77], [1, 2.04, 65.67]], "batl": NaN}, {"timestamp": 1578689677923, "ltp": 2.04, "tv": 4353.91, "trd": NaN, "batb": NaN, "batl": [[0, 2.1, 2.6], [1, 2.14, 4.59], [2, 2.16, 4.9]]}, {"timestamp": 1578689681526, "ltp": 2.04, "tv": 4353.91, "trd": NaN, "batb": NaN, "batl": [[0, 2.08, 1.7], [1, 2.1, 2.6], [2, 2.14, 2.89]]}, {"timestamp": 1578689687642, "ltp": 2.04, "tv": 4353.91, "trd": NaN, "batb": NaN, "batl": [[0, 2.08, 4.3], [1, 2.14, 2.89], [2, 2.16, 4.9]]}, {"timestamp": 1578689693854, "ltp": 2.06, "tv": 4359.11, "trd": [[2.06, 712.46]], "batb": [[0, 2.06, 9.17]], "batl": [[0, 2.08, 1.7]]}, {"timestamp": 1578689699919, "ltp": 2.06, "tv": 4359.11, "trd": NaN, "batb": NaN, "batl": [[0, 2.12, 1.7]]}, {"timestamp": 1578690056398, "ltp": 2.06, "tv": 4359.62, "trd": [[1.99, 54.85], [2, 979.38], [2.02, 205.16], [2.04, 15.65], [2.06, 712.53], [2.08, 965.04], [2.1, 485.7], [2.12, 204.45], [2.14, 292.99], [2.16, 280.91], [2.18, 75.78]], "batb": [[1, 2.04, 65.68]], "batl": NaN}, {"timestamp": 1578690150388, "ltp": 2.06, "tv": 4359.62, "trd": NaN, "batb": NaN, "batl": [[0, 2.1, 2.3], [1, 2.12, 1.7], [2, 2.14, 2.89]]}, {"timestamp": 1578690152516, "ltp": 2.06, "tv": 4359.62, "trd": NaN, "batb": NaN, "batl": [[0, 2.08, 1.7], [1, 2.14, 2.89], [2, 2.16, 4.9]]}, {"timestamp": 1578690159937, "ltp": 2.06, "tv": 4359.62, "trd": NaN, "batb": NaN, "batl": [[0, 2.12, 1.7]]}, {"timestamp": 1578690243883, "ltp": 2.14, "tv": 4366.62, "trd": [[2.12, 207.85], [2.14, 296.59]], "batb": NaN, "batl": [[0, 2.14, 1.09], [1, 2.16, 4.9], [2, 2.18, 6]]}, {"timestamp": 1578690274330, "ltp": 2.14, "tv": 4366.62, "trd": NaN, "batb": [[0, 2.1, 3], [1, 2.06, 9.17], [2, 2.04, 65.68]], "batl": NaN}, {"timestamp": 1578690284930, "ltp": 2.14, "tv": 4366.62, "trd": NaN, "batb": [[0, 2.08, 3]], "batl": NaN}, {"timestamp": 1578690400902, "ltp": 2.14, "tv": 4366.62, "trd": NaN, "batb": [[0, 2.06, 9.17], [1, 2.04, 65.68], [2, 2.02, 350]], "batl": NaN}, {"timestamp": 1578690490553, "ltp": 2.06, "tv": 4376.62, "trd": [[2.06, 722.53]], "batb": [[0, 2.06, 4.17]], "batl": NaN}, {"timestamp": 1578690539469, "ltp": 2.06, "tv": 4376.62, "trd": NaN, "batb": [[0, 2.08, 8.4], [1, 2.06, 4.17], [2, 2.04, 65.68]], "batl": NaN}, {"timestamp": 1578690612001, "ltp": 2.18, "tv": 4392.62, "trd": [[2.14, 298.77], [2.16, 290.71], [2.18, 79.8]], "batb": [[2, 2.04, 53.83]], "batl": [[0, 2.18, 3.99], [1, 2.2, 379.19], [2, 2.24, 10]]}, {"timestamp": 1578690615780, "ltp": 2.18, "tv": 4392.62, "trd": NaN, "batb": [[0, 2.1, 2.01], [1, 2.08, 8.4], [2, 2.06, 4.17]], "batl": NaN}, {"timestamp": 1578690661746, "ltp": 2.18, "tv": 4392.62, "trd": NaN, "batb": NaN, "batl": [[0, 2.18, 25.98]]}, {"timestamp": 1578690671956, "ltp": 2.06, "tv": 4421.78, "trd": [[2.06, 730.87], [2.08, 981.84], [2.1, 489.72]], "batb": [[0, 2.04, 53.83], [1, 2.02, 350], [2, 2, 30.4]], "batl": [[0, 2.06, 35.42], [1, 2.18, 25.98], [2, 2.2, 379.19]]}, {"timestamp": 1578690687472, "ltp": 2.04, "tv": 4492.62, "trd": [[2.04, 86.49]], "batb": [[0, 2.04, 18.41]], "batl": [[0, 2.18, 48.11], [1, 2.2, 379.19], [2, 2.24, 10]]}, {"timestamp": 1578690690710, "ltp": 2.04, "tv": 4492.62, "trd": NaN, "batb": [[0, 2.06, 50.15], [1, 2.04, 18.41], [2, 2.02, 350]], "batl": [[0, 2.16, 47.82], [1, 2.18, 48.11], [2, 2.2, 379.19]]}, {"timestamp": 1578690696430, "ltp": 2.04, "tv": 4492.62, "trd": NaN, "batb": NaN, "batl": [[0, 2.14, 4.3], [1, 2.16, 47.82], [2, 2.18, 48.11]]}, {"timestamp": 1578690784763, "ltp": 2.04, "tv": 4492.62, "trd": NaN, "batb": NaN, "batl": [[2, 2.18, 26.12]]}, {"timestamp": 1578690978251, "ltp": 2.04, "tv": 4492.62, "trd": NaN, "batb": [[0, 2.06, 57.34]], "batl": NaN}, {"timestamp": 1578691063541, "ltp": 2.14, "tv": 4496.62, "trd": [[2.14, 302.77]], "batb": NaN, "batl": [[0, 2.14, 2.3]]}, {"timestamp": 1578691064846, "ltp": 2.14, "tv": 4496.88, "trd": [[2.14, 303.03]], "batb": NaN, "batl": [[0, 2.14, 2.17]]}, {"timestamp": 1578691067984, "ltp": 2.14, "tv": 4500.18, "trd": [[2.14, 306.33]], "batb": NaN, "batl": [[0, 2.16, 48.34], [1, 2.18, 26.12], [2, 2.2, 379.19]]}, {"timestamp": 1578691069954, "ltp": 2.14, "tv": 4501.22, "trd": [[2.14, 307.37]], "batb": [[0, 2.14, 1.13], [1, 2.06, 57.34], [2, 2.04, 18.41]], "batl": [[0, 2.16, 47.82]]}, {"timestamp": 1578691071462, "ltp": 2.16, "tv": 4508.09, "trd": [[2.16, 297.58]], "batb": NaN, "batl": [[0, 2.16, 44.39]]}, {"timestamp": 1578691256739, "ltp": 2.16, "tv": 4508.09, "trd": NaN, "batb": [[1, 2.1, 18], [2, 2.06, 57.34]], "batl": NaN}, {"timestamp": 1578691289894, "ltp": 2.16, "tv": 4508.09, "trd": NaN, "batb": [[2, 2.06, 10.79]], "batl": [[0, 2.18, 26.12], [1, 2.2, 379.19], [2, 2.24, 10]]}, {"timestamp": 1578691347277, "ltp": 2.16, "tv": 4508.09, "trd": NaN, "batb": [[1, 2.12, 25], [2, 2.1, 18]], "batl": NaN}, {"timestamp": 1578691405689, "ltp": 2.12, "tv": 4560.35, "trd": [[2.12, 257.85], [2.14, 309.63]], "batb": [[0, 2.1, 18], [1, 2.06, 10.79], [2, 2.02, 350]], "batl": [[0, 2.12, 1.87], [1, 2.18, 26.12], [2, 2.2, 379.19]]}, {"timestamp": 1578691413979, "ltp": 2.12, "tv": 4560.35, "trd": NaN, "batb": [[2, 2.04, 6]], "batl": NaN}, {"timestamp": 1578691414706, "ltp": 2.12, "tv": 4560.35, "trd": NaN, "batb": NaN, "batl": [[0, 2.18, 26.12], [1, 2.2, 379.19], [2, 2.24, 10]]}, {"timestamp": 1578691433168, "ltp": 2.12, "tv": 4560.35, "trd": NaN, "batb": NaN, "batl": [[0, 2.18, 44.42]]}, {"timestamp": 1578691778500, "ltp": 2.1, "tv": 4596.35, "trd": [[2.1, 525.72]], "batb": [[0, 2.06, 10.79], [1, 2.04, 17.85], [2, 2.02, 350]], "batl": [[0, 2.08, 62], [1, 2.18, 44.42], [2, 2.2, 379.19]]}, {"timestamp": 1578691779218, "ltp": 2.1, "tv": 4596.35, "trd": NaN, "batb": NaN, "batl": [[1, 2.18, 33.84]]}, {"timestamp": 1578692139894, "ltp": 2.06, "tv": 4617.93, "trd": [[2.06, 752.45]], "batb": [[0, 2.04, 17.85], [1, 2.02, 350], [2, 2, 40.4]], "batl": NaN}, {"timestamp": 1578692155730, "ltp": 2.04, "tv": 4653.63, "trd": [[2.04, 122.19]], "batb": [[0, 2.02, 350], [1, 2, 40.4], [2, 1.96, 2.01]], "batl": NaN}, {"timestamp": 1578692160582, "ltp": 2.04, "tv": 4653.63, "trd": NaN, "batb": NaN, "batl": [[0, 2.06, 6], [1, 2.08, 62], [2, 2.18, 33.84]]}, {"timestamp": 1578692172887, "ltp": 2.04, "tv": 4653.63, "trd": NaN, "batb": [[0, 2.04, 31.11], [1, 2.02, 350], [2, 2, 40.4]], "batl": NaN}, {"timestamp": 1578692183540, "ltp": 2.02, "tv": 5353.63, "trd": [[2.02, 842.94], [2.04, 184.41]], "batb": [[0, 2.02, 31.11], [1, 2, 40.4], [2, 1.96, 2.01]], "batl": NaN}, {"timestamp": 1578692305546, "ltp": 2.02, "tv": 5353.63, "trd": NaN, "batb": [[1, 2, 32.27]], "batl": [[0, 2.06, 18.74]]}, {"timestamp": 1578692416970, "ltp": 2.06, "tv": 5369.55, "trd": [[2.06, 768.37]], "batb": NaN, "batl": [[0, 2.06, 10.78]]}, {"timestamp": 1578692691883, "ltp": 2.06, "tv": 5369.55, "trd": NaN, "batb": [[2, 1.96, 3.91]], "batl": NaN}, {"timestamp": 1578692710679, "ltp": 2.06, "tv": 5369.55, "trd": NaN, "batb": [[2, 1.97, 1.9]], "batl": NaN}, {"timestamp": 1578692876816, "ltp": 2.06, "tv": 5389.45, "trd": [[2.06, 788.27]], "batb": NaN, "batl": [[0, 2.08, 62.83], [1, 2.18, 33.84], [2, 2.2, 379.19]]}, {"timestamp": 1578693114419, "ltp": 2.08, "tv": 5410.93, "trd": [[2.06, 789.93], [2.08, 1001.66]], "batb": NaN, "batl": [[0, 2.08, 52.09]]}, {"timestamp": 1578693344225, "ltp": 2.08, "tv": 5410.93, "trd": NaN, "batb": NaN, "batl": [[1, 2.1, 2.37], [2, 2.18, 33.84]]}, {"timestamp": 1578693632874, "ltp": 2.08, "tv": 5410.93, "trd": NaN, "batb": [[0, 2.06, 10.25], [1, 2.02, 31.11], [2, 2, 32.27]], "batl": NaN}, {"timestamp": 1578693633839, "ltp": 2.06, "tv": 5431.43, "trd": [[2.06, 810.43]], "batb": [[0, 2.02, 31.11], [1, 2, 32.27], [2, 1.97, 1.9]], "batl": NaN}, {"timestamp": 1578693751777, "ltp": 2.06, "tv": 5431.43, "trd": NaN, "batb": [[0, 2.04, 8.5], [1, 2.02, 31.11], [2, 2, 32.27]], "batl": NaN}, {"timestamp": 1578693764614, "ltp": 2.04, "tv": 5448.43, "trd": [[2.04, 201.41]], "batb": [[0, 2.02, 31.11], [1, 2, 32.27], [2, 1.97, 1.9]], "batl": NaN}, {"timestamp": 1578693844017, "ltp": 2.04, "tv": 5448.43, "trd": NaN, "batb": [[0, 2.04, 2], [1, 2.02, 31.11], [2, 2, 32.27]], "batl": NaN}, {"timestamp": 1578693889892, "ltp": 2.04, "tv": 5452.43, "trd": [[2.04, 205.41]], "batb": [[0, 2.02, 31.11], [1, 2, 32.27], [2, 1.97, 1.9]], "batl": NaN}, {"timestamp": 1578694147585, "ltp": 2.08, "tv": 5469.9, "trd": [[2.08, 1019.13]], "batb": [[0, 2.04, 12.86], [1, 2.02, 31.11], [2, 2, 32.27]], "batl": [[0, 2.08, 43.36]]}, {"timestamp": 1578694161518, "ltp": 2.04, "tv": 5495.62, "trd": [[2.04, 231.13]], "batb": [[0, 2.02, 31.11], [1, 2, 32.27], [2, 1.97, 1.9]], "batl": NaN}, {"timestamp": 1578694175662, "ltp": 2.08, "tv": 5496.28, "trd": [[2.08, 1019.79]], "batb": NaN, "batl": [[0, 2.08, 43.03]]}, {"timestamp": 1578694239938, "ltp": 2.08, "tv": 5496.8, "trd": [[2.08, 1020.31]], "batb": NaN, "batl": [[0, 2.08, 42.77]]}, {"timestamp": 1578694242156, "ltp": 2.08, "tv": 5497.2, "trd": [[2.08, 1020.71]], "batb": NaN, "batl": [[0, 2.08, 42.57]]}, {"timestamp": 1578694245564, "ltp": 2.08, "tv": 5497.6, "trd": [[2.08, 1021.11]], "batb": NaN, "batl": [[0, 2.08, 42.37]]}, {"timestamp": 1578694249340, "ltp": 2.08, "tv": 5497.6, "trd": NaN, "batb": NaN, "batl": [[2, 2.16, 4]]}, {"timestamp": 1578694286692, "ltp": 2.08, "tv": 5518.28, "trd": [[2.08, 1041.79]], "batb": NaN, "batl": [[0, 2.08, 32.03]]}, {"timestamp": 1578694325964, "ltp": 2.08, "tv": 5518.28, "trd": NaN, "batb": NaN, "batl": [[2, 2.14, 25.9]]}, {"timestamp": 1578694326377, "ltp": 2.08, "tv": 5518.28, "trd": NaN, "batb": NaN, "batl": [[1, 2.1, 4.37]]}, {"timestamp": 1578694389548, "ltp": 2.02, "tv": 5525.78, "trd": [[2.02, 850.44]], "batb": [[0, 2.02, 27.36]], "batl": NaN}, {"timestamp": 1578694393662, "ltp": 2.02, "tv": 5531.78, "trd": [[2.02, 856.44]], "batb": [[0, 2.02, 24.36]], "batl": NaN}, {"timestamp": 1578694443919, "ltp": 2.02, "tv": 5580.5, "trd": [[2.02, 905.16]], "batb": [[0, 2, 32.27], [1, 1.97, 1.9], [2, 1.96, 3.91]], "batl": NaN}, {"timestamp": 1578694446629, "ltp": 2.08, "tv": 5601.66, "trd": [[2.08, 1062.95]], "batb": NaN, "batl": [[0, 2.08, 21.45]]}, {"timestamp": 1578694488484, "ltp": 2.08, "tv": 5601.66, "trd": NaN, "batb": [[1, 1.97, 24.7]], "batl": NaN}, {"timestamp": 1578694523644, "ltp": 2.0, "tv": 5660.5, "trd": [[2, 1038.22]], "batb": [[0, 2, 2.85]], "batl": [[0, 2.06, 12.73], [1, 2.08, 21.45], [2, 2.1, 4.37]]}, {"timestamp": 1578694550739, "ltp": 2.0, "tv": 5660.5, "trd": NaN, "batb": [[1, 1.98, 3], [2, 1.97, 24.7]], "batl": NaN}, {"timestamp": 1578694568693, "ltp": 2.0, "tv": 5660.5, "trd": NaN, "batb": [[2, 1.97, 1.9]], "batl": NaN}, {"timestamp": 1578694573358, "ltp": 2.0, "tv": 5660.5, "trd": NaN, "batb": [[1, 1.97, 1.9], [2, 1.96, 3.91]], "batl": NaN}, {"timestamp": 1578694651573, "ltp": 2.0, "tv": 5660.5, "trd": NaN, "batb": [[1, 1.97, 6.9]], "batl": NaN}, {"timestamp": 1578694979629, "ltp": 2.0, "tv": 5660.5, "trd": NaN, "batb": [[1, 1.97, 1.9]], "batl": [[1, 2.08, 45.45]]}, {"timestamp": 1578695126048, "ltp": 2.06, "tv": 5685.96, "trd": [[2.06, 835.89]], "batb": [[0, 2.06, 13.39], [1, 2, 2.85], [2, 1.97, 1.9]], "batl": [[0, 2.08, 45.45], [1, 2.1, 4.37], [2, 2.16, 4]]}, {"timestamp": 1578695131940, "ltp": 2.06, "tv": 5685.96, "trd": NaN, "batb": [[1, 2, 10.98]], "batl": NaN}, {"timestamp": 1578695196558, "ltp": 2.06, "tv": 5685.96, "trd": NaN, "batb": NaN, "batl": [[0, 2.08, 21.45], [2, 2.14, 15]]}, {"timestamp": 1578695218698, "ltp": 2.06, "tv": 5685.96, "trd": NaN, "batb": [[0, 2.06, 18.25]], "batl": NaN}, {"timestamp": 1578695259612, "ltp": 2.08, "tv": 5696.18, "trd": [[2.08, 1073.17]], "batb": NaN, "batl": [[0, 2.08, 16.34]]}, {"timestamp": 1578695267234, "ltp": 2.08, "tv": 5696.18, "trd": NaN, "batb": [[0, 2.06, 4.86]], "batl": NaN}, {"timestamp": 1578695284554, "ltp": 2.08, "tv": 5722.68, "trd": [[2.08, 1099.67]], "batb": [[0, 2.04, 12.86], [1, 2.02, 4.86], [2, 2, 10.98]], "batl": [[0, 2.08, 3.09]]}, {"timestamp": 1578695359876, "ltp": 2.08, "tv": 5722.68, "trd": NaN, "batb": NaN, "batl": [[2, 2.16, 4]]}, {"timestamp": 1578695565421, "ltp": 2.08, "tv": 5722.68, "trd": NaN, "batb": NaN, "batl": [[1, 2.1, 24.37]]}, {"timestamp": 1578695679388, "ltp": 2.08, "tv": 5722.68, "trd": NaN, "batb": NaN, "batl": [[2, 2.12, 1.53]]}, {"timestamp": 1578695884677, "ltp": 2.08, "tv": 5722.68, "trd": NaN, "batb": NaN, "batl": [[0, 2.08, 4.62], [2, 2.16, 4]]}, {"timestamp": 1578695937929, "ltp": 2.08, "tv": 5722.68, "trd": NaN, "batb": [[1, 2.02, 23.86]], "batl": NaN}, {"timestamp": 1578696515775, "ltp": 2.08, "tv": 5730.68, "trd": [[2.08, 1107.67]], "batb": NaN, "batl": [[0, 2.1, 24.99], [1, 2.16, 4], [2, 2.18, 14.03]]}, {"timestamp": 1578696535601, "ltp": 2.1, "tv": 5762.68, "trd": [[2.08, 1108.91], [2.1, 556.48]], "batb": NaN, "batl": [[0, 2.1, 8.99]]}, {"timestamp": 1578696650991, "ltp": 2.1, "tv": 5762.68, "trd": NaN, "batb": [[0, 2.02, 23.86], [1, 2, 10.98], [2, 1.97, 1.9]], "batl": [[0, 2.1, 109.49]]}, {"timestamp": 1578696651403, "ltp": 2.1, "tv": 5762.68, "trd": NaN, "batb": NaN, "batl": [[0, 2.08, 20.9], [1, 2.1, 109.49], [2, 2.16, 4]]}, {"timestamp": 1578696705771, "ltp": 2.1, "tv": 5762.68, "trd": NaN, "batb": NaN, "batl": [[0, 2.08, 121.4], [1, 2.1, 8.99]]}, {"timestamp": 1578696706487, "ltp": 2.1, "tv": 5762.68, "trd": NaN, "batb": NaN, "batl": [[0, 2.06, 8.57], [1, 2.08, 112.6], [2, 2.1, 8.99]]}, {"timestamp": 1578696707564, "ltp": 2.1, "tv": 5762.68, "trd": NaN, "batb": NaN, "batl": [[1, 2.08, 100.5]]}, {"timestamp": 1578696757925, "ltp": 2.1, "tv": 5762.68, "trd": NaN, "batb": [[0, 2.02, 4.86], [1, 2, 25.2]], "batl": NaN}, {"timestamp": 1578696790373, "ltp": 2.1, "tv": 5762.68, "trd": NaN, "batb": [[0, 2.04, 9.22], [1, 2.02, 4.86], [2, 2, 25.2]], "batl": NaN}, {"timestamp": 1578696806976, "ltp": 2.1, "tv": 5762.68, "trd": NaN, "batb": NaN, "batl": [[0, 2.06, 17.14]]}, {"timestamp": 1578697006935, "ltp": 2.1, "tv": 5762.68, "trd": NaN, "batb": NaN, "batl": [[0, 2.06, 20.2]]}, {"timestamp": 1578697114629, "ltp": 2.04, "tv": 5781.12, "trd": [[2.04, 249.57]], "batb": [[0, 2.02, 4.86], [1, 2, 25.2], [2, 1.97, 1.9]], "batl": [[0, 2.06, 20.98]]}, {"timestamp": 1578697119353, "ltp": 2.04, "tv": 5781.12, "trd": NaN, "batb": NaN, "batl": [[0, 2.06, 20.2]]}, {"timestamp": 1578697203924, "ltp": 2.04, "tv": 5780.15, "trd": [[1.99, 54.83], [2, 1037.85], [2.02, 905.08], [2.04, 249.55], [2.06, 835.77], [2.08, 1108.66], [2.1, 556.43], [2.12, 257.84], [2.14, 309.6], [2.16, 297.57], [2.18, 79.8]], "batb": [[0, 2.02, 4.86]], "batl": [[0, 2.06, 20.19]]}, {"timestamp": 1578697346779, "ltp": 2.02, "tv": 5785.25, "trd": [[2.02, 910.18]], "batb": [[0, 2.02, 2.31]], "batl": NaN}, {"timestamp": 1578697380534, "ltp": 2.02, "tv": 5785.25, "trd": NaN, "batb": [[1, 2, 10.98], [2, 1.98, 5.37]], "batl": NaN}, {"timestamp": 1578697462934, "ltp": 2.02, "tv": 5785.25, "trd": NaN, "batb": [[2, 1.97, 1.9]], "batl": NaN}, {"timestamp": 1578697544538, "ltp": 2.02, "tv": 5785.25, "trd": NaN, "batb": NaN, "batl": [[2, 2.1, 19.49]]}, {"timestamp": 1578697735648, "ltp": 2.02, "tv": 5785.25, "trd": NaN, "batb": [[0, 2.02, 3.88]], "batl": NaN}, {"timestamp": 1578697753989, "ltp": 2.0, "tv": 5814.99, "trd": [[2, 1059.81], [2.02, 917.96]], "batb": [[0, 1.97, 1.9], [1, 1.96, 3.91], [2, 1.88, 25]], "batl": [[0, 2.06, 20.32]]}, {"timestamp": 1578697762189, "ltp": 2.0, "tv": 5814.99, "trd": NaN, "batb": NaN, "batl": [[0, 2.04, 8.26], [1, 2.06, 20.19], [2, 2.08, 100.5]]}, {"timestamp": 1578697788971, "ltp": 2.0, "tv": 5814.99, "trd": NaN, "batb": [[2, 1.89, 6]], "batl": [[1, 2.06, 30.79]]}, {"timestamp": 1578698160337, "ltp": 2.0, "tv": 5814.99, "trd": NaN, "batb": [[0, 1.97, 15.12], [1, 1.96, 138.48]], "batl": NaN}, {"timestamp": 1578698176996, "ltp": 2.0, "tv": 5814.99, "trd": NaN, "batb": [[1, 1.96, 3.91]], "batl": NaN}, {"timestamp": 1578698195912, "ltp": 2.0, "tv": 5814.99, "trd": NaN, "batb": [[0, 1.97, 17.09]], "batl": NaN}, {"timestamp": 1578698199297, "ltp": 2.0, "tv": 5814.99, "trd": NaN, "batb": NaN, "batl": [[1, 2.06, 20.19]]}, {"timestamp": 1578698444886, "ltp": 2.0, "tv": 5814.99, "trd": NaN, "batb": [[0, 1.98, 6], [1, 1.97, 17.09], [2, 1.96, 3.91]], "batl": NaN}, {"timestamp": 1578698575348, "ltp": 2.0, "tv": 5814.99, "trd": NaN, "batb": NaN, "batl": [[0, 2.04, 18.26]]}, {"timestamp": 1578698607500, "ltp": 2.0, "tv": 5814.99, "trd": NaN, "batb": [[0, 1.97, 17.09], [1, 1.96, 3.91], [2, 1.88, 25]], "batl": NaN}, {"timestamp": 1578698652525, "ltp": 1.97, "tv": 5824.99, "trd": [[1.97, 14]], "batb": [[0, 1.97, 12.09]], "batl": NaN}, {"timestamp": 1578698664862, "ltp": 1.96, "tv": 5838.98, "trd": [[1.96, 12.06], [1.97, 27.94]], "batb": [[0, 1.96, 3.88], [1, 1.88, 25], [2, 1.85, 8.11]], "batl": [[0, 2.02, 7.98], [1, 2.04, 18.13], [2, 2.06, 20.19]]}, {"timestamp": 1578698686973, "ltp": 1.96, "tv": 5842.78, "trd": [[1.96, 15.86]], "batb": [[0, 1.88, 25], [1, 1.85, 8.11], [2, 1.8, 10.4]], "batl": NaN}, {"timestamp": 1578698688774, "ltp": 1.96, "tv": 5842.78, "trd": NaN, "batb": [[0, 1.89, 144.79], [1, 1.88, 25], [2, 1.85, 8.11]], "batl": [[0, 1.96, 2], [1, 2.04, 18.26]]}, {"timestamp": 1578698690375, "ltp": 1.96, "tv": 5846.78, "trd": [[1.96, 19.86]], "batb": NaN, "batl": [[0, 2.04, 18.26], [1, 2.06, 20.19], [2, 2.08, 100.5]]}, {"timestamp": 1578698691189, "ltp": 1.96, "tv": 5846.78, "trd": NaN, "batb": [[0, 1.9, 6.43], [1, 1.89, 144.79], [2, 1.88, 25]], "batl": [[2, 2.08, 110.5]]}, {"timestamp": 1578698695767, "ltp": 1.96, "tv": 5846.78, "trd": NaN, "batb": [[0, 1.91, 3], [1, 1.9, 6.43], [2, 1.89, 144.79]], "batl": NaN}, {"timestamp": 1578698704613, "ltp": 1.96, "tv": 5846.78, "trd": NaN, "batb": [[1, 1.9, 145.26], [2, 1.88, 25]], "batl": [[0, 2.02, 7.98], [1, 2.04, 18.13], [2, 2.06, 20.19]]}, {"timestamp": 1578698706002, "ltp": 1.96, "tv": 5846.78, "trd": NaN, "batb": [[0, 1.92, 37.06], [1, 1.91, 3], [2, 1.9, 145.26]], "batl": [[0, 2, 35.71], [1, 2.02, 7.85], [2, 2.04, 18.13]]}, {"timestamp": 1578698717921, "ltp": 1.96, "tv": 5846.78, "trd": NaN, "batb": [[0, 1.93, 3], [1, 1.92, 37.06]], "batl": NaN}, {"timestamp": 1578698718796, "ltp": 1.96, "tv": 5846.78, "trd": NaN, "batb": [[2, 1.91, 6]], "batl": NaN}, {"timestamp": 1578698720593, "ltp": 1.96, "tv": 5846.78, "trd": NaN, "batb": [[0, 1.93, 139.67]], "batl": NaN}, {"timestamp": 1578698728819, "ltp": 1.96, "tv": 5846.78, "trd": NaN, "batb": [[2, 1.9, 6.43]], "batl": NaN}, {"timestamp": 1578698734742, "ltp": 1.96, "tv": 5846.78, "trd": NaN, "batb": [[0, 1.94, 2], [1, 1.93, 139.67], [2, 1.92, 37.06]], "batl": NaN}, {"timestamp": 1578698759832, "ltp": 1.96, "tv": 5846.78, "trd": NaN, "batb": [[0, 1.95, 35.42], [1, 1.94, 2], [2, 1.93, 139.67]], "batl": NaN}, {"timestamp": 1578698766571, "ltp": 1.96, "tv": 5846.78, "trd": NaN, "batb": [[0, 1.96, 3], [1, 1.95, 35.42], [2, 1.94, 2]], "batl": NaN}, {"timestamp": 1578698886651, "ltp": 2.0, "tv": 5867.3, "trd": [[2, 1080.33]], "batb": NaN, "batl": [[0, 2, 25.45]]}, {"timestamp": 1578698905337, "ltp": 1.96, "tv": 5873.3, "trd": [[1.96, 25.86]], "batb": [[0, 1.95, 35.42], [1, 1.94, 2], [2, 1.88, 25]], "batl": NaN}, {"timestamp": 1578698927741, "ltp": 1.96, "tv": 5873.3, "trd": NaN, "batb": NaN, "batl": [[0, 1.99, 2.95], [1, 2, 25.45], [2, 2.02, 7.85]]}, {"timestamp": 1578698980567, "ltp": 1.96, "tv": 5873.3, "trd": NaN, "batb": [[1, 1.94, 21.32]], "batl": NaN}, {"timestamp": 1578699038355, "ltp": 1.99, "tv": 5879.2, "trd": [[1.99, 60.73]], "batb": [[0, 1.99, 2.13], [1, 1.95, 35.42], [2, 1.94, 21.32]], "batl": [[0, 2, 25.45], [1, 2.02, 7.85], [2, 2.04, 18.13]]}, {"timestamp": 1578699054979, "ltp": 1.99, "tv": 5883.2, "trd": [[1.99, 64.73]], "batb": [[0, 1.95, 35.55], [1, 1.94, 21.32], [2, 1.88, 25]], "batl": NaN}, {"timestamp": 1578699055748, "ltp": 1.99, "tv": 5883.46, "trd": [[1.99, 64.99]], "batb": [[0, 1.95, 35.42]], "batl": NaN}, {"timestamp": 1578699081489, "ltp": 1.95, "tv": 5889.46, "trd": [[1.95, 15.56]], "batb": [[0, 1.95, 32.42]], "batl": NaN}, {"timestamp": 1578699093729, "ltp": 1.95, "tv": 5889.46, "trd": NaN, "batb": [[0, 1.96, 3], [1, 1.95, 32.42], [2, 1.94, 21.32]], "batl": NaN}, {"timestamp": 1578699111973, "ltp": 2.0, "tv": 5909.98, "trd": [[2, 1100.84]], "batb": [[0, 1.96, 8.13]], "batl": [[0, 2, 15.19], [1, 2.04, 18.13], [2, 2.06, 11.63]]}, {"timestamp": 1578699126869, "ltp": 2.0, "tv": 5909.98, "trd": NaN, "batb": [[0, 1.96, 3]], "batl": [[0, 2.02, 16.18], [2, 2.06, 20.22]]}, {"timestamp": 1578699128405, "ltp": 2.0, "tv": 5909.98, "trd": NaN, "batb": NaN, "batl": [[2, 2.06, 11.63]]}, {"timestamp": 1578699146981, "ltp": 2.0, "tv": 5909.98, "trd": NaN, "batb": NaN, "batl": [[0, 1.98, 3.74], [1, 2.02, 16.18], [2, 2.04, 18.13]]}, {"timestamp": 1578699147807, "ltp": 2.0, "tv": 5909.98, "trd": NaN, "batb": [[0, 1.96, 8.13]], "batl": [[0, 2.02, 8.33], [1, 2.04, 18.13], [2, 2.06, 11.63]]}, {"timestamp": 1578699159214, "ltp": 2.0, "tv": 5909.98, "trd": NaN, "batb": [[0, 1.97, 10.14], [1, 1.96, 8.13]], "batl": NaN}, {"timestamp": 1578699160904, "ltp": 2.0, "tv": 5909.98, "trd": NaN, "batb": [[0, 2, 200], [1, 1.97, 10.14], [2, 1.96, 8.13]], "batl": NaN}, {"timestamp": 1578699175609, "ltp": 2.0, "tv": 5909.98, "trd": NaN, "batb": [[2, 1.96, 5.13]], "batl": NaN}, {"timestamp": 1578699195738, "ltp": 2.0, "tv": 5909.98, "trd": NaN, "batb": [[0, 1.97, 10.14], [1, 1.94, 21.32], [2, 1.88, 25]], "batl": [[0, 2, 7.9], [1, 2.02, 8.33], [2, 2.04, 18.13]]}, {"timestamp": 1578699226448, "ltp": 2.0, "tv": 5909.98, "trd": NaN, "batb": [[0, 1.95, 10.14]], "batl": NaN}, {"timestamp": 1578699241692, "ltp": 2.0, "tv": 5909.98, "trd": NaN, "batb": [[0, 1.95, 16.88]], "batl": NaN}, {"timestamp": 1578699251824, "ltp": 2.0, "tv": 5909.98, "trd": NaN, "batb": [[0, 1.96, 3], [1, 1.95, 16.88], [2, 1.94, 21.32]], "batl": NaN}, {"timestamp": 1578699259998, "ltp": 2.0, "tv": 5909.98, "trd": NaN, "batb": [[0, 1.97, 4.97], [1, 1.96, 3], [2, 1.95, 6.74]], "batl": NaN}, {"timestamp": 1578699287543, "ltp": 2.0, "tv": 5909.98, "trd": NaN, "batb": [[0, 1.97, 24.01]], "batl": NaN}, {"timestamp": 1578699289950, "ltp": 2.0, "tv": 5909.98, "trd": NaN, "batb": [[1, 1.95, 6.74], [2, 1.94, 2]], "batl": NaN}, {"timestamp": 1578699340975, "ltp": 2.0, "tv": 5909.98, "trd": NaN, "batb": NaN, "batl": [[0, 2, 35.14]]}, {"timestamp": 1578699341794, "ltp": 2.0, "tv": 5909.98, "trd": NaN, "batb": NaN, "batl": [[0, 2, 38.2]]}, {"timestamp": 1578699498782, "ltp": 2.0, "tv": 5930.18, "trd": [[2, 1121.04]], "batb": NaN, "batl": [[0, 2, 28.1]]}, {"timestamp": 1578699554886, "ltp": 2.0, "tv": 5930.18, "trd": NaN, "batb": [[2, 1.94, 752]], "batl": NaN}, {"timestamp": 1578699591612, "ltp": 2.0, "tv": 5930.18, "trd": NaN, "batb": [[2, 1.94, 2]], "batl": NaN}, {"timestamp": 1578699682638, "ltp": 1.97, "tv": 5967.52, "trd": [[1.97, 65.28]], "batb": [[0, 1.97, 5.34]], "batl": NaN}, {"timestamp": 1578699700255, "ltp": 1.97, "tv": 5967.52, "trd": NaN, "batb": [[1, 1.96, 12.83], [2, 1.95, 6.74]], "batl": NaN}, {"timestamp": 1578699897718, "ltp": 1.97, "tv": 5971.52, "trd": [[1.97, 69.28]], "batb": [[0, 1.96, 12.83], [1, 1.95, 6.74], [2, 1.94, 2]], "batl": NaN}, {"timestamp": 1578699898848, "ltp": 1.97, "tv": 5971.52, "trd": NaN, "batb": [[0, 1.96, 24.57]], "batl": NaN}, {"timestamp": 1578700035937, "ltp": 2.0, "tv": 5987.3, "trd": [[2, 1136.82]], "batb": NaN, "batl": [[0, 2, 20.21]]}, {"timestamp": 1578700111041, "ltp": 2.0, "tv": 5997.56, "trd": [[2, 1147.08]], "batb": NaN, "batl": [[0, 2, 15.08]]}, {"timestamp": 1578700199636, "ltp": 2.0, "tv": 6000.86, "trd": [[2, 1150.38]], "batb": NaN, "batl": [[0, 2, 13.43]]}, {"timestamp": 1578700202153, "ltp": 2.0, "tv": 6003.46, "trd": [[2, 1152.98]], "batb": NaN, "batl": [[0, 2, 12.13]]}, {"timestamp": 1578700204253, "ltp": 2.0, "tv": 6006.06, "trd": [[2, 1155.58]], "batb": NaN, "batl": [[0, 2, 10.83]]}, {"timestamp": 1578700205944, "ltp": 2.0, "tv": 6007.56, "trd": [[2, 1157.08]], "batb": NaN, "batl": [[0, 2, 10.08]]}, {"timestamp": 1578700207841, "ltp": 2.0, "tv": 6009.06, "trd": [[2, 1158.58]], "batb": NaN, "batl": [[0, 2, 9.33]]}, {"timestamp": 1578700209634, "ltp": 2.0, "tv": 6009.94, "trd": [[2, 1159.46]], "batb": NaN, "batl": [[0, 2, 8.89]]}, {"timestamp": 1578700211847, "ltp": 2.0, "tv": 6010.82, "trd": [[2, 1160.34]], "batb": NaN, "batl": [[0, 2, 8.45]]}, {"timestamp": 1578700213943, "ltp": 2.0, "tv": 6011.34, "trd": [[2, 1160.86]], "batb": NaN, "batl": [[0, 2, 8.19]]}, {"timestamp": 1578700216052, "ltp": 2.0, "tv": 6011.86, "trd": [[2, 1161.38]], "batb": NaN, "batl": [[0, 2, 7.93]]}, {"timestamp": 1578700217959, "ltp": 2.0, "tv": 6012.14, "trd": [[2, 1161.66]], "batb": NaN, "batl": [[0, 2, 7.79]]}, {"timestamp": 1578700219848, "ltp": 2.0, "tv": 6012.42, "trd": [[2, 1161.94]], "batb": NaN, "batl": [[0, 2, 7.65]]}, {"timestamp": 1578700221893, "ltp": 2.0, "tv": 6012.62, "trd": [[2, 1162.14]], "batb": NaN, "batl": [[0, 2, 7.55]]}, {"timestamp": 1578700224197, "ltp": 2.0, "tv": 6012.82, "trd": [[2, 1162.34]], "batb": NaN, "batl": [[0, 2, 7.45]]}, {"timestamp": 1578700225894, "ltp": 2.0, "tv": 6013.02, "trd": [[2, 1162.54]], "batb": NaN, "batl": [[0, 2, 7.35]]}, {"timestamp": 1578700228874, "ltp": 2.0, "tv": 6013.22, "trd": [[2, 1162.74]], "batb": NaN, "batl": [[0, 2, 7.25]]}, {"timestamp": 1578700351321, "ltp": 2.0, "tv": 6027.72, "trd": [[2, 1177.25]], "batb": [[0, 2, 9.77], [1, 1.96, 24.57], [2, 1.95, 6.74]], "batl": [[0, 2.02, 8.33], [1, 2.04, 18.13], [2, 2.06, 8.56]]}, {"timestamp": 1578700352710, "ltp": 2.0, "tv": 6027.72, "trd": NaN, "batb": NaN, "batl": [[2, 2.06, 17.18]]}, {"timestamp": 1578700374625, "ltp": 2.02, "tv": 6044.39, "trd": [[2.02, 934.62]], "batb": [[0, 2.02, 1.44]], "batl": [[0, 2.04, 18.13], [1, 2.06, 17.18], [2, 2.08, 100.5]]}, {"timestamp": 1578700379558, "ltp": 2.02, "tv": 6047.27, "trd": [[2.02, 937.5]], "batb": [[0, 1.96, 24.57], [1, 1.95, 6.74], [2, 1.94, 2]], "batl": [[0, 2.02, 129.14], [1, 2.04, 18.13], [2, 2.06, 17.18]]}, {"timestamp": 1578700380274, "ltp": 2.02, "tv": 6047.27, "trd": NaN, "batb": NaN, "batl": [[0, 2, 23.66], [1, 2.02, 129.14], [2, 2.04, 18.13]]}, {"timestamp": 1578700395887, "ltp": 2.02, "tv": 6047.27, "trd": NaN, "batb": NaN, "batl": [[0, 2.04, 18.13], [1, 2.06, 6], [2, 2.08, 100.5]]}, {"timestamp": 1578700400754, "ltp": 2.02, "tv": 6047.27, "trd": NaN, "batb": [[0, 1.96, 33.16]], "batl": NaN}, {"timestamp": 1578700406294, "ltp": 2.02, "tv": 6047.27, "trd": NaN, "batb": NaN, "batl": [[1, 2.06, 18.21]]}, {"timestamp": 1578700407374, "ltp": 2.02, "tv": 6047.27, "trd": NaN, "batb": [[0, 2, 17.02], [1, 1.96, 33.16], [2, 1.95, 6.74]], "batl": NaN}, {"timestamp": 1578700412916, "ltp": 2.02, "tv": 6047.27, "trd": NaN, "batb": [[0, 1.96, 33.16], [1, 1.95, 6.74], [2, 1.94, 2]], "batl": NaN}, {"timestamp": 1578700427927, "ltp": 2.02, "tv": 6047.27, "trd": NaN, "batb": NaN, "batl": [[0, 2.02, 129.14], [1, 2.04, 18.13], [2, 2.06, 18.21]]}, {"timestamp": 1578700428639, "ltp": 2.02, "tv": 6047.27, "trd": NaN, "batb": NaN, "batl": [[2, 2.06, 6]]}, {"timestamp": 1578700443523, "ltp": 2.02, "tv": 6047.27, "trd": NaN, "batb": NaN, "batl": [[0, 2.04, 18.13], [1, 2.06, 6], [2, 2.08, 100.5]]}, {"timestamp": 1578700452954, "ltp": 2.02, "tv": 6047.27, "trd": NaN, "batb": [[0, 2, 17.02], [1, 1.96, 33.16], [2, 1.95, 6.74]], "batl": NaN}, {"timestamp": 1578700457062, "ltp": 2.02, "tv": 6047.27, "trd": NaN, "batb": [[0, 1.96, 33.16], [1, 1.95, 6.74], [2, 1.94, 2]], "batl": NaN}, {"timestamp": 1578700481967, "ltp": 2.02, "tv": 6047.27, "trd": NaN, "batb": NaN, "batl": [[1, 2.06, 15.13]]}, {"timestamp": 1578700527948, "ltp": 2.02, "tv": 6047.27, "trd": NaN, "batb": [[1, 1.94, 2], [2, 1.88, 25]], "batl": NaN}, {"timestamp": 1578700528823, "ltp": 2.02, "tv": 6047.27, "trd": NaN, "batb": [[0, 1.97, 8.3], [1, 1.96, 33.16], [2, 1.94, 2]], "batl": NaN}, {"timestamp": 1578700540777, "ltp": 2.02, "tv": 6047.27, "trd": NaN, "batb": [[0, 1.98, 10.37], [1, 1.97, 8.3], [2, 1.96, 11.74]], "batl": NaN}, {"timestamp": 1578700573762, "ltp": 2.02, "tv": 6047.27, "trd": NaN, "batb": [[0, 1.98, 21.2]], "batl": NaN}, {"timestamp": 1578700609563, "ltp": 2.02, "tv": 6047.27, "trd": NaN, "batb": NaN, "batl": [[1, 2.06, 23.76]]}, {"timestamp": 1578700673945, "ltp": 1.98, "tv": 6089.66, "trd": [[1.98, 42.4]], "batb": [[0, 1.97, 8.3], [1, 1.96, 11.74], [2, 1.94, 2]], "batl": [[0, 1.98, 29.29], [1, 2.04, 18.13], [2, 2.06, 23.76]]}, {"timestamp": 1578700674967, "ltp": 1.98, "tv": 6089.66, "trd": NaN, "batb": NaN, "batl": [[0, 1.98, 37.42], [1, 2.04, 10], [2, 2.06, 14.62]]}, {"timestamp": 1578700680352, "ltp": 1.98, "tv": 6089.66, "trd": NaN, "batb": [[0, 1.96, 11.74], [1, 1.94, 7.7], [2, 1.88, 25]], "batl": [[2, 2.06, 21.22]]}, {"timestamp": 1578700710573, "ltp": 1.95, "tv": 6139.42, "trd": [[1.95, 41.84], [1.96, 49.34]], "batb": [[0, 1.94, 7.7], [1, 1.88, 25], [2, 1.85, 8.11]], "batl": [[0, 1.95, 4.41], [1, 1.98, 8.13], [2, 2.04, 10]]}, {"timestamp": 1578700712985, "ltp": 1.95, "tv": 6142.98, "trd": [[1.95, 45.4]], "batb": NaN, "batl": [[0, 1.95, 2.63]]}, {"timestamp": 1578700714983, "ltp": 1.95, "tv": 6142.98, "trd": NaN, "batb": NaN, "batl": [[0, 1.95, 10.76], [1, 2.04, 10], [2, 2.06, 21.22]]}, {"timestamp": 1578700715697, "ltp": 1.95, "tv": 6146.54, "trd": [[1.95, 48.96]], "batb": NaN, "batl": [[0, 1.95, 8.98]]}, {"timestamp": 1578700717191, "ltp": 1.95, "tv": 6148.68, "trd": [[1.95, 51.1]], "batb": NaN, "batl": [[0, 1.95, 7.91]]}, {"timestamp": 1578700719605, "ltp": 1.95, "tv": 6150.82, "trd": [[1.95, 53.24]], "batb": NaN, "batl": [[0, 1.95, 6.84]]}, {"timestamp": 1578700721705, "ltp": 1.95, "tv": 6152.12, "trd": [[1.95, 54.54]], "batb": NaN, "batl": [[0, 1.95, 6.19]]}, {"timestamp": 1578700723908, "ltp": 1.95, "tv": 6153.42, "trd": [[1.95, 55.84]], "batb": NaN, "batl": [[0, 1.95, 5.54]]}, {"timestamp": 1578700736229, "ltp": 1.95, "tv": 6153.42, "trd": NaN, "batb": NaN, "batl": [[2, 2.06, 29.86]]}, {"timestamp": 1578700743366, "ltp": 1.95, "tv": 6154.18, "trd": [[1.95, 56.6]], "batb": NaN, "batl": [[0, 1.95, 5.16]]}, {"timestamp": 1578700745066, "ltp": 1.95, "tv": 6154.8, "trd": [[1.95, 57.22]], "batb": NaN, "batl": [[0, 1.95, 4.85]]}, {"timestamp": 1578700747124, "ltp": 1.95, "tv": 6155.42, "trd": [[1.95, 57.84]], "batb": NaN, "batl": [[0, 1.95, 4.54]]}, {"timestamp": 1578700784584, "ltp": 1.95, "tv": 6155.42, "trd": NaN, "batb": NaN, "batl": [[1, 2.02, 45], [2, 2.04, 10]]}, {"timestamp": 1578700802441, "ltp": 1.95, "tv": 6155.8, "trd": [[1.95, 58.22]], "batb": NaN, "batl": [[0, 1.95, 4.35]]}, {"timestamp": 1578700804712, "ltp": 1.95, "tv": 6156.18, "trd": [[1.95, 58.6]], "batb": NaN, "batl": [[0, 1.95, 4.16]]}, {"timestamp": 1578700806415, "ltp": 1.95, "tv": 6156.4, "trd": [[1.95, 58.82]], "batb": NaN, "batl": [[0, 1.95, 4.05]]}, {"timestamp": 1578700808940, "ltp": 1.95, "tv": 6156.62, "trd": [[1.95, 59.04]], "batb": NaN, "batl": [[0, 1.95, 3.94]]}, {"timestamp": 1578700810532, "ltp": 1.95, "tv": 6156.82, "trd": [[1.95, 59.24]], "batb": NaN, "batl": [[0, 1.95, 3.84]]}, {"timestamp": 1578700812641, "ltp": 1.95, "tv": 6157.02, "trd": [[1.95, 59.44]], "batb": NaN, "batl": [[0, 1.95, 3.74]]}, {"timestamp": 1578700832748, "ltp": 1.95, "tv": 6157.02, "trd": NaN, "batb": [[0, 1.94, 2], [1, 1.89, 6], [2, 1.88, 25]], "batl": NaN}, {"timestamp": 1578700916915, "ltp": 1.94, "tv": 6161.02, "trd": [[1.94, 4]], "batb": [[0, 1.89, 6], [1, 1.88, 25], [2, 1.85, 8.11]], "batl": [[0, 1.94, 3], [1, 1.95, 3.74], [2, 2.02, 45]]}, {"timestamp": 1578700917991, "ltp": 1.94, "tv": 6161.02, "trd": NaN, "batb": NaN, "batl": [[0, 1.94, 6.74], [1, 2.02, 45], [2, 2.04, 10]]}, {"timestamp": 1578701006707, "ltp": 1.94, "tv": 6161.02, "trd": NaN, "batb": NaN, "batl": [[0, 1.93, 2], [1, 1.94, 6.74], [2, 2.02, 45]]}, {"timestamp": 1578701009114, "ltp": 1.94, "tv": 6161.02, "trd": NaN, "batb": NaN, "batl": [[0, 1.93, 5.74], [1, 1.94, 3]]}, {"timestamp": 1578701012938, "ltp": 1.94, "tv": 6161.02, "trd": NaN, "batb": NaN, "batl": [[0, 1.93, 3.74]]}, {"timestamp": 1578701018325, "ltp": 1.94, "tv": 6161.02, "trd": NaN, "batb": NaN, "batl": [[0, 1.93, 8.74]]}, {"timestamp": 1578701065938, "ltp": 1.93, "tv": 6178.5, "trd": [[1.93, 17.48]], "batb": [[0, 1.93, 191.26], [1, 1.89, 6], [2, 1.88, 25]], "batl": [[0, 1.94, 3], [1, 2.02, 45], [2, 2.04, 10]]}, {"timestamp": 1578701066708, "ltp": 1.93, "tv": 6178.5, "trd": NaN, "batb": [[1, 1.9, 5.08], [2, 1.89, 6]], "batl": NaN}, {"timestamp": 1578701137362, "ltp": 1.94, "tv": 6184.5, "trd": [[1.94, 10]], "batb": [[0, 1.94, 6], [1, 1.93, 191.26], [2, 1.9, 5.08]], "batl": [[0, 2.02, 45], [1, 2.04, 10], [2, 2.06, 14.62]]}, {"timestamp": 1578701143354, "ltp": 1.94, "tv": 6184.5, "trd": NaN, "batb": [[0, 1.94, 143.47]], "batl": NaN}, {"timestamp": 1578701178743, "ltp": 2.02, "tv": 6203.08, "trd": [[2.02, 956.08]], "batb": NaN, "batl": [[0, 2.02, 35.71]]}, {"timestamp": 1578701279851, "ltp": 2.02, "tv": 6203.08, "trd": NaN, "batb": NaN, "batl": [[0, 2, 5.62], [1, 2.02, 35.71], [2, 2.04, 10]]}, {"timestamp": 1578701286378, "ltp": 2.02, "tv": 6203.08, "trd": NaN, "batb": [[0, 1.94, 6]], "batl": NaN}, {"timestamp": 1578701369380, "ltp": 2.02, "tv": 6203.08, "trd": NaN, "batb": [[0, 1.95, 3], [1, 1.94, 6], [2, 1.93, 191.26]], "batl": NaN}, {"timestamp": 1578701491421, "ltp": 2.02, "tv": 6203.08, "trd": NaN, "batb": [[0, 1.95, 13]], "batl": NaN}, {"timestamp": 1578701661792, "ltp": 2.02, "tv": 6203.08, "trd": NaN, "batb": NaN, "batl": [[0, 2, 41.33], [1, 2.04, 10], [2, 2.06, 14.62]]}, {"timestamp": 1578701719563, "ltp": 1.94, "tv": 6241.08, "trd": [[1.94, 22], [1.95, 85.44]], "batb": [[0, 1.93, 191.26], [1, 1.9, 5.08], [2, 1.88, 25]], "batl": [[0, 1.94, 1], [1, 2, 41.33], [2, 2.04, 10]]}, {"timestamp": 1578701722754, "ltp": 1.94, "tv": 6241.08, "trd": NaN, "batb": [[2, 1.89, 49.08]], "batl": [[2, 2.02, 45.92]]}, {"timestamp": 1578701724088, "ltp": 1.94, "tv": 6241.08, "trd": NaN, "batb": NaN, "batl": [[1, 2, 53.91]]}, {"timestamp": 1578701725781, "ltp": 1.94, "tv": 6243.08, "trd": [[1.94, 24]], "batb": [[0, 1.94, 5], [1, 1.93, 191.26], [2, 1.9, 5.08]], "batl": [[0, 2, 53.91], [1, 2.02, 45.92], [2, 2.04, 10]]}, {"timestamp": 1578701734893, "ltp": 1.94, "tv": 6243.08, "trd": NaN, "batb": NaN, "batl": [[0, 1.99, 2.94], [1, 2, 53.91], [2, 2.02, 45.92]]}, {"timestamp": 1578701786657, "ltp": 1.94, "tv": 6243.08, "trd": NaN, "batb": [[0, 1.95, 47.57], [1, 1.94, 5], [2, 1.93, 191.26]], "batl": NaN}, {"timestamp": 1578701861772, "ltp": 1.94, "tv": 6243.08, "trd": NaN, "batb": [[0, 1.96, 10.22], [1, 1.95, 47.57], [2, 1.94, 5]], "batl": [[0, 1.99, 15.8]]}, {"timestamp": 1578701874793, "ltp": 1.94, "tv": 6243.08, "trd": NaN, "batb": [[1, 1.94, 5], [2, 1.93, 191.26]], "batl": [[2, 2.04, 10]]}, {"timestamp": 1578701875766, "ltp": 1.94, "tv": 6243.08, "trd": NaN, "batb": NaN, "batl": [[1, 2, 41.33]]}, {"timestamp": 1578702037726, "ltp": 2.0, "tv": 6294.36, "trd": [[1.99, 96.59], [2, 1196.93]], "batb": NaN, "batl": [[0, 2, 31.49], [1, 2.04, 10], [2, 2.06, 6]]}, {"timestamp": 1578702054384, "ltp": 1.96, "tv": 6314.8, "trd": [[1.96, 69.78]], "batb": [[0, 1.94, 18.29], [1, 1.93, 191.26], [2, 1.9, 5.08]], "batl": [[0, 1.96, 46.8], [1, 2, 31.49], [2, 2.04, 10]]}, {"timestamp": 1578702055974, "ltp": 1.96, "tv": 6314.8, "trd": NaN, "batb": NaN, "batl": [[0, 1.96, 66.8]]}, {"timestamp": 1578702168857, "ltp": 1.96, "tv": 6417.91, "trd": [[1.96, 172.88]], "batb": NaN, "batl": [[0, 1.96, 15.25]]}, {"timestamp": 1578702247312, "ltp": 1.96, "tv": 6446.57, "trd": [[1.96, 201.54]], "batb": NaN, "batl": [[0, 2, 32.41], [1, 2.04, 10], [2, 2.06, 6]]}, {"timestamp": 1578702253520, "ltp": 1.96, "tv": 6446.57, "trd": NaN, "batb": [[0, 1.95, 3], [1, 1.94, 18.29], [2, 1.93, 191.26]], "batl": NaN}, {"timestamp": 1578702503649, "ltp": 1.95, "tv": 6450.57, "trd": [[1.95, 89.44]], "batb": [[0, 1.95, 1]], "batl": NaN}, {"timestamp": 1578702636936, "ltp": 1.95, "tv": 6450.57, "trd": NaN, "batb": [[1, 1.94, 25.14]], "batl": NaN}, {"timestamp": 1578703339861, "ltp": 1.95, "tv": 6450.57, "trd": NaN, "batb": NaN, "batl": [[0, 1.97, 5.92], [1, 2, 31.49], [2, 2.04, 10]]}, {"timestamp": 1578703688340, "ltp": 1.95, "tv": 6450.57, "trd": NaN, "batb": [[0, 1.95, 9.51]], "batl": NaN}, {"timestamp": 1578703961475, "ltp": 1.97, "tv": 6460.99, "trd": [[1.96, 203.38], [1.97, 77.86]], "batb": NaN, "batl": [[0, 2, 32.2], [1, 2.04, 10], [2, 2.06, 6]]}, {"timestamp": 1578704145935, "ltp": 2.0, "tv": 6512.27, "trd": [[1.97, 79.28], [2, 1246.79]], "batb": NaN, "batl": [[0, 2, 6.56], [2, 2.06, 27.43]]}, {"timestamp": 1578704161963, "ltp": 1.95, "tv": 6514.27, "trd": [[1.95, 91.44]], "batb": [[0, 1.94, 25.14], [1, 1.93, 191.26], [2, 1.9, 5.08]], "batl": NaN}, {"timestamp": 1578704162941, "ltp": 1.95, "tv": 6514.27, "trd": NaN, "batb": NaN, "batl": [[0, 1.99, 2.94], [1, 2, 6.56], [2, 2.04, 10]]}, {"timestamp": 1578704300839, "ltp": 1.99, "tv": 6520.15, "trd": [[1.99, 102.47]], "batb": [[0, 1.99, 7.37], [1, 1.94, 11.85], [2, 1.93, 191.26]], "batl": [[0, 2, 6.56], [1, 2.04, 10], [2, 2.06, 18.21]]}, {"timestamp": 1578704302640, "ltp": 1.99, "tv": 6520.15, "trd": NaN, "batb": NaN, "batl": [[2, 2.06, 26.92]]}, {"timestamp": 1578704391737, "ltp": 2.0, "tv": 6533.27, "trd": [[2, 1259.91]], "batb": [[0, 2, 5.44], [1, 1.99, 7.37], [2, 1.94, 11.85]], "batl": [[0, 2.04, 10], [1, 2.06, 26.92], [2, 2.08, 100.5]]}, {"timestamp": 1578704396623, "ltp": 2.0, "tv": 6533.27, "trd": NaN, "batb": [[0, 1.99, 7.37], [1, 1.94, 11.85], [2, 1.93, 191.26]], "batl": NaN}, {"timestamp": 1578705229632, "ltp": 1.99, "tv": 6533.64, "trd": [[1.99, 102.85]], "batb": [[0, 1.99, 7.18]], "batl": NaN}, {"timestamp": 1578705704719, "ltp": 1.99, "tv": 6533.64, "trd": NaN, "batb": NaN, "batl": [[0, 2.02, 3.06], [1, 2.04, 10], [2, 2.06, 26.92]]}, {"timestamp": 1578705705541, "ltp": 1.99, "tv": 6533.64, "trd": NaN, "batb": NaN, "batl": [[0, 2.04, 10], [1, 2.06, 26.92], [2, 2.08, 100.5]]}, {"timestamp": 1578706387904, "ltp": 1.99, "tv": 6533.64, "trd": NaN, "batb": [[0, 2, 3.06], [1, 1.99, 7.18], [2, 1.94, 11.85]], "batl": NaN}, {"timestamp": 1578706397697, "ltp": 1.99, "tv": 6533.64, "trd": NaN, "batb": NaN, "batl": [[1, 2.06, 46.83]]}, {"timestamp": 1578706398887, "ltp": 1.99, "tv": 6533.64, "trd": NaN, "batb": NaN, "batl": [[0, 2.04, 29.91]]}, {"timestamp": 1578706399712, "ltp": 1.99, "tv": 6533.64, "trd": NaN, "batb": [[0, 1.99, 7.18], [1, 1.94, 11.85], [2, 1.93, 191.26]], "batl": NaN}, {"timestamp": 1578706402203, "ltp": 1.99, "tv": 6533.64, "trd": NaN, "batb": [[1, 1.95, 3.14], [2, 1.94, 11.85]], "batl": NaN}, {"timestamp": 1578706438164, "ltp": 1.99, "tv": 6533.64, "trd": NaN, "batb": [[2, 1.94, 161.85]], "batl": NaN}, {"timestamp": 1578706468971, "ltp": 1.99, "tv": 6533.64, "trd": NaN, "batb": [[1, 1.95, 9.14], [2, 1.94, 156.85]], "batl": NaN}, {"timestamp": 1578706510332, "ltp": 1.99, "tv": 6533.64, "trd": NaN, "batb": [[1, 1.96, 10], [2, 1.95, 9.14]], "batl": NaN}, {"timestamp": 1578707739664, "ltp": 1.99, "tv": 6533.64, "trd": NaN, "batb": NaN, "batl": [[0, 2.02, 2.5], [1, 2.04, 29.91], [2, 2.06, 46.83]]}, {"timestamp": 1578707740740, "ltp": 1.99, "tv": 6533.64, "trd": NaN, "batb": NaN, "batl": [[0, 2.04, 29.91], [1, 2.06, 46.83], [2, 2.08, 100.5]]}, {"timestamp": 1578708129217, "ltp": 2.04, "tv": 6553.44, "trd": [[2.04, 269.35]], "batb": NaN, "batl": [[0, 2.04, 20.01]]}, {"timestamp": 1578709586693, "ltp": 2.04, "tv": 6553.44, "trd": NaN, "batb": [[0, 2, 11], [1, 1.99, 7.18], [2, 1.96, 10]], "batl": NaN}, {"timestamp": 1578710126776, "ltp": 2.0, "tv": 6575.44, "trd": [[2, 1281.91]], "batb": [[0, 1.99, 7.18], [1, 1.96, 10], [2, 1.95, 3.14]], "batl": [[0, 2, 9], [1, 2.04, 20.01], [2, 2.06, 46.83]]}, {"timestamp": 1578710127081, "ltp": 2.0, "tv": 6575.44, "trd": NaN, "batb": NaN, "batl": [[2, 2.06, 34.61]]}, {"timestamp": 1578710137567, "ltp": 1.99, "tv": 6589.8, "trd": [[1.99, 117.21]], "batb": [[0, 1.96, 10], [1, 1.95, 16.37], [2, 1.94, 156.85]], "batl": [[0, 1.99, 1.82], [2, 2.06, 43.33]]}, {"timestamp": 1578710143703, "ltp": 1.99, "tv": 6589.8, "trd": NaN, "batb": [[0, 1.97, 3], [1, 1.96, 10], [2, 1.95, 16.37]], "batl": NaN}, {"timestamp": 1578710208563, "ltp": 1.99, "tv": 6589.8, "trd": NaN, "batb": [[0, 1.97, 6.4]], "batl": NaN}, {"timestamp": 1578710213921, "ltp": 1.99, "tv": 6589.8, "trd": NaN, "batb": [[0, 1.97, 3.4]], "batl": NaN}, {"timestamp": 1578710274884, "ltp": 1.96, "tv": 6597.45, "trd": [[1.96, 204.22], [1.97, 86.08]], "batb": [[0, 1.96, 9.58], [1, 1.95, 3.14], [2, 1.94, 156.85]], "batl": [[0, 2.04, 20.01], [1, 2.06, 43.33], [2, 2.08, 100.5]]}, {"timestamp": 1578710278703, "ltp": 1.96, "tv": 6597.45, "trd": NaN, "batb": [[0, 1.96, 145.64]], "batl": NaN}, {"timestamp": 1578710285269, "ltp": 1.96, "tv": 6597.45, "trd": NaN, "batb": [[0, 1.97, 3], [1, 1.96, 145.64], [2, 1.95, 3.14]], "batl": NaN}, {"timestamp": 1578710526224, "ltp": 1.96, "tv": 6597.45, "trd": NaN, "batb": [[0, 1.97, 52.37]], "batl": NaN}, {"timestamp": 1578710528590, "ltp": 1.96, "tv": 6597.45, "trd": NaN, "batb": [[1, 1.96, 9.58]], "batl": NaN}, {"timestamp": 1578710531883, "ltp": 1.96, "tv": 6597.45, "trd": NaN, "batb": [[0, 1.97, 49.37]], "batl": NaN}, {"timestamp": 1578710559116, "ltp": 1.96, "tv": 6597.45, "trd": NaN, "batb": [[0, 1.96, 9.58], [1, 1.95, 3.14], [2, 1.94, 156.85]], "batl": NaN}, {"timestamp": 1578710563828, "ltp": 1.96, "tv": 6603.45, "trd": [[1.96, 210.22]], "batb": [[0, 1.96, 6.58]], "batl": NaN}, {"timestamp": 1578710564853, "ltp": 1.96, "tv": 6603.45, "trd": NaN, "batb": [[0, 1.97, 3], [1, 1.96, 6.58], [2, 1.95, 3.14]], "batl": NaN}, {"timestamp": 1578710672585, "ltp": 1.96, "tv": 6603.45, "trd": NaN, "batb": NaN, "batl": [[2, 2.08, 111.5]]}, {"timestamp": 1578710679184, "ltp": 1.96, "tv": 6603.45, "trd": NaN, "batb": [[0, 1.96, 6.58], [1, 1.95, 3.14], [2, 1.94, 156.85]], "batl": NaN}, {"timestamp": 1578710693913, "ltp": 1.96, "tv": 6603.45, "trd": NaN, "batb": [[0, 1.96, 142.64]], "batl": NaN}, {"timestamp": 1578710711835, "ltp": 1.96, "tv": 6603.45, "trd": NaN, "batb": [[0, 1.97, 3], [1, 1.96, 142.64], [2, 1.95, 3.14]], "batl": NaN}, {"timestamp": 1578710845397, "ltp": 1.96, "tv": 6603.45, "trd": NaN, "batb": [[1, 1.96, 144.84]], "batl": NaN}, {"timestamp": 1578710869605, "ltp": 1.96, "tv": 6603.45, "trd": NaN, "batb": [[0, 1.97, 51.52]], "batl": NaN}, {"timestamp": 1578710881361, "ltp": 1.96, "tv": 6603.45, "trd": NaN, "batb": [[1, 1.96, 8.78]], "batl": NaN}, {"timestamp": 1578710893562, "ltp": 1.96, "tv": 6603.45, "trd": NaN, "batb": [[0, 1.97, 48.52]], "batl": NaN}, {"timestamp": 1578710905598, "ltp": 1.96, "tv": 6603.45, "trd": NaN, "batb": [[0, 1.96, 8.78], [1, 1.95, 3.14], [2, 1.94, 156.85]], "batl": NaN}, {"timestamp": 1578710923424, "ltp": 1.96, "tv": 6603.45, "trd": NaN, "batb": [[0, 1.96, 144.84]], "batl": NaN}, {"timestamp": 1578710926829, "ltp": 1.96, "tv": 6603.45, "trd": NaN, "batb": [[0, 1.97, 3], [1, 1.96, 144.84], [2, 1.95, 3.14]], "batl": NaN}, {"timestamp": 1578711247521, "ltp": 1.96, "tv": 6603.45, "trd": NaN, "batb": [[0, 1.97, 51.52]], "batl": NaN}, {"timestamp": 1578711481823, "ltp": 1.96, "tv": 6603.45, "trd": NaN, "batb": [[1, 1.96, 8.78]], "batl": NaN}, {"timestamp": 1578711491866, "ltp": 1.96, "tv": 6603.45, "trd": NaN, "batb": [[0, 1.97, 48.52]], "batl": NaN}, {"timestamp": 1578711499877, "ltp": 1.96, "tv": 6603.45, "trd": NaN, "batb": [[0, 1.96, 8.78], [1, 1.95, 3.14], [2, 1.94, 156.85]], "batl": NaN}, {"timestamp": 1578711514789, "ltp": 1.96, "tv": 6603.45, "trd": NaN, "batb": [[1, 1.95, 13.14]], "batl": [[2, 2.08, 100.5]]}, {"timestamp": 1578711523818, "ltp": 1.96, "tv": 6603.45, "trd": NaN, "batb": [[0, 1.97, 13.13], [1, 1.96, 144.84], [2, 1.95, 13.14]], "batl": NaN}, {"timestamp": 1578711530600, "ltp": 1.96, "tv": 6603.45, "trd": NaN, "batb": [[0, 1.98, 3], [1, 1.97, 13.13], [2, 1.96, 144.84]], "batl": NaN}, {"timestamp": 1578711542640, "ltp": 1.96, "tv": 6603.45, "trd": NaN, "batb": [[1, 1.96, 8.78], [2, 1.95, 13.14]], "batl": NaN}, {"timestamp": 1578711547454, "ltp": 1.96, "tv": 6603.45, "trd": NaN, "batb": [[0, 1.97, 3]], "batl": NaN}, {"timestamp": 1578711918389, "ltp": 1.96, "tv": 6603.45, "trd": NaN, "batb": [[0, 1.97, 6.4]], "batl": NaN}, {"timestamp": 1578711926947, "ltp": 1.96, "tv": 6603.45, "trd": NaN, "batb": [[0, 1.97, 3.4]], "batl": NaN}, {"timestamp": 1578712018720, "ltp": 1.96, "tv": 6603.45, "trd": NaN, "batb": [[0, 1.96, 8.78], [1, 1.95, 13.14], [2, 1.94, 156.85]], "batl": NaN}, {"timestamp": 1578712019396, "ltp": 1.96, "tv": 6603.45, "trd": NaN, "batb": [[0, 1.96, 144.84]], "batl": NaN}, {"timestamp": 1578712084923, "ltp": 2.04, "tv": 6620.33, "trd": [[2.04, 286.23]], "batb": [[0, 1.97, 13.13], [1, 1.96, 144.84], [2, 1.95, 13.14]], "batl": [[0, 2.04, 11.56]]}, {"timestamp": 1578712096532, "ltp": 2.04, "tv": 6620.33, "trd": NaN, "batb": [[0, 1.97, 148.5], [1, 1.96, 8.78]], "batl": NaN}, {"timestamp": 1578712166867, "ltp": 2.04, "tv": 6620.33, "trd": NaN, "batb": [[0, 1.98, 3], [1, 1.97, 148.5], [2, 1.96, 8.78]], "batl": NaN}, {"timestamp": 1578712172458, "ltp": 2.04, "tv": 6620.33, "trd": NaN, "batb": [[1, 1.97, 13.13]], "batl": NaN}, {"timestamp": 1578712183572, "ltp": 2.04, "tv": 6620.33, "trd": NaN, "batb": [[0, 1.97, 13.13], [1, 1.96, 8.78], [2, 1.95, 13.14]], "batl": NaN}, {"timestamp": 1578712775342, "ltp": 2.04, "tv": 6620.33, "trd": NaN, "batb": [[0, 1.98, 7.1], [1, 1.97, 13.13], [2, 1.96, 8.78]], "batl": NaN}, {"timestamp": 1578712855902, "ltp": 2.04, "tv": 6620.33, "trd": NaN, "batb": NaN, "batl": [[0, 2, 1.53], [1, 2.04, 11.56], [2, 2.06, 43.33]]}, {"timestamp": 1578712856913, "ltp": 2.04, "tv": 6620.33, "trd": NaN, "batb": NaN, "batl": [[0, 2.04, 11.56], [1, 2.06, 43.33], [2, 2.08, 100.5]]}, {"timestamp": 1578713074756, "ltp": 2.04, "tv": 6620.33, "trd": NaN, "batb": [[0, 2, 85.12], [1, 1.98, 7.1], [2, 1.97, 13.13]], "batl": NaN}, {"timestamp": 1578713463581, "ltp": 2.04, "tv": 6620.33, "trd": NaN, "batb": [[0, 2, 81.72]], "batl": NaN}, {"timestamp": 1578713469676, "ltp": 2.08, "tv": 6783.77, "trd": [[2.04, 309.35], [2.06, 922.42], [2.08, 1162.32]], "batb": [[0, 1.98, 7.1], [1, 1.97, 13.13], [2, 1.96, 8.78]], "batl": [[0, 2.08, 73.67], [1, 2.1, 28.99], [2, 2.12, 6]]}, {"timestamp": 1578713472360, "ltp": 2.08, "tv": 6783.77, "trd": NaN, "batb": [[0, 1.99, 6], [1, 1.98, 7.1], [2, 1.97, 13.13]], "batl": NaN}, {"timestamp": 1578713617710, "ltp": 2.08, "tv": 6783.77, "trd": NaN, "batb": NaN, "batl": [[2, 2.12, 16.35]]}, {"timestamp": 1578716389952, "ltp": 1.99, "tv": 6803.77, "trd": [[1.99, 137.21]], "batb": [[0, 1.98, 7.1], [1, 1.97, 13.13], [2, 1.96, 8.78]], "batl": NaN}, {"timestamp": 1578716392551, "ltp": 1.99, "tv": 6803.77, "trd": NaN, "batb": NaN, "batl": [[0, 2.06, 4], [1, 2.08, 73.67], [2, 2.1, 28.99]]}, {"timestamp": 1578716661791, "ltp": 1.99, "tv": 6803.77, "trd": NaN, "batb": NaN, "batl": [[0, 2.06, 14]]}, {"timestamp": 1578716662569, "ltp": 1.99, "tv": 6803.77, "trd": NaN, "batb": [[1, 1.96, 8.78], [2, 1.95, 22.58]], "batl": [[0, 2.06, 19]]}, {"timestamp": 1578716663183, "ltp": 1.99, "tv": 6803.77, "trd": NaN, "batb": NaN, "batl": [[0, 2.06, 15]]}, {"timestamp": 1578716683212, "ltp": 1.99, "tv": 6803.77, "trd": NaN, "batb": [[1, 1.97, 3.97], [2, 1.96, 8.78]], "batl": [[0, 2.04, 3.83], [1, 2.06, 15], [2, 2.08, 73.67]]}, {"timestamp": 1578716689938, "ltp": 1.99, "tv": 6803.77, "trd": NaN, "batb": NaN, "batl": [[0, 2.04, 8.83]]}, {"timestamp": 1578716690555, "ltp": 1.99, "tv": 6803.77, "trd": NaN, "batb": NaN, "batl": [[0, 2.04, 13.83]]}, {"timestamp": 1578718450752, "ltp": 2.04, "tv": 6823.37, "trd": [[2.04, 328.95]], "batb": NaN, "batl": [[0, 2.04, 4.03]]}, {"timestamp": 1578718466876, "ltp": 2.04, "tv": 6823.37, "trd": NaN, "batb": [[0, 2, 10], [1, 1.98, 7.1], [2, 1.97, 3.97]], "batl": NaN}, {"timestamp": 1578718489201, "ltp": 2.04, "tv": 6823.37, "trd": NaN, "batb": [[0, 1.98, 7.1], [1, 1.97, 3.97], [2, 1.96, 8.78]], "batl": NaN}, {"timestamp": 1578718557849, "ltp": 2.04, "tv": 6831.43, "trd": [[2.04, 337.01]], "batb": NaN, "batl": [[0, 2.06, 15], [1, 2.08, 73.67], [2, 2.1, 28.99]]}, {"timestamp": 1578718559984, "ltp": 2.04, "tv": 6831.43, "trd": NaN, "batb": [[0, 1.99, 2.77], [1, 1.98, 7.1]], "batl": NaN}, {"timestamp": 1578718592780, "ltp": 2.04, "tv": 6831.43, "trd": NaN, "batb": [[0, 1.99, 3.92]], "batl": NaN}, {"timestamp": 1578718615361, "ltp": 2.04, "tv": 6831.43, "trd": NaN, "batb": [[0, 1.99, 7.33]], "batl": NaN}, {"timestamp": 1578718645970, "ltp": 2.04, "tv": 6831.43, "trd": NaN, "batb": [[0, 2, 12.97], [1, 1.99, 141.34], [2, 1.98, 7.1]], "batl": NaN}, {"timestamp": 1578718646588, "ltp": 2.04, "tv": 6831.43, "trd": NaN, "batb": [[0, 2, 28.39]], "batl": NaN}, {"timestamp": 1578718658613, "ltp": 2.04, "tv": 6831.43, "trd": NaN, "batb": [[0, 2.02, 3.86], [1, 2, 28.39], [2, 1.99, 137.42]], "batl": NaN}, {"timestamp": 1578718661494, "ltp": 2.04, "tv": 6831.43, "trd": NaN, "batb": [[2, 1.99, 3.4]], "batl": NaN}, {"timestamp": 1578718662317, "ltp": 2.04, "tv": 6831.43, "trd": NaN, "batb": [[1, 2, 12.97]], "batl": NaN}, {"timestamp": 1578718713759, "ltp": 2.04, "tv": 6831.43, "trd": NaN, "batb": [[0, 2.02, 8.97], [2, 1.98, 7.1]], "batl": NaN}, {"timestamp": 1578718714888, "ltp": 2.04, "tv": 6831.43, "trd": NaN, "batb": NaN, "batl": [[0, 2.04, 5], [1, 2.06, 15], [2, 2.08, 73.67]]}, {"timestamp": 1578718715567, "ltp": 2.04, "tv": 6831.43, "trd": NaN, "batb": NaN, "batl": [[0, 2.04, 10]]}, {"timestamp": 1578719044635, "ltp": 2.0, "tv": 6871.43, "trd": [[2, 1303.97], [2.02, 974.03]], "batb": [[0, 2, 1.94], [1, 1.98, 7.1], [2, 1.96, 8.78]], "batl": NaN}, {"timestamp": 1578719083490, "ltp": 2.0, "tv": 6871.43, "trd": NaN, "batb": [[0, 2, 16.84]], "batl": NaN}, {"timestamp": 1578719288866, "ltp": 2.0, "tv": 6871.43, "trd": NaN, "batb": [[0, 2.02, 5.11], [1, 2, 16.84], [2, 1.98, 7.1]], "batl": NaN}, {"timestamp": 1578719414846, "ltp": 2.0, "tv": 6871.43, "trd": NaN, "batb": [[0, 2.02, 137.13]], "batl": NaN}, {"timestamp": 1578719415569, "ltp": 2.04, "tv": 6891.42, "trd": [[2.04, 357]], "batb": [[0, 2.02, 142.7]], "batl": [[0, 2.06, 15], [1, 2.08, 73.67], [2, 2.1, 28.99]]}, {"timestamp": 1578719416857, "ltp": 2.04, "tv": 6891.42, "trd": NaN, "batb": [[0, 2.02, 137.13]], "batl": NaN}, {"timestamp": 1578719417985, "ltp": 2.04, "tv": 6891.42, "trd": NaN, "batb": NaN, "batl": [[0, 2.06, 19.68]]}, {"timestamp": 1578719430774, "ltp": 2.04, "tv": 6891.42, "trd": NaN, "batb": [[0, 2.02, 5.11]], "batl": NaN}, {"timestamp": 1578719460748, "ltp": 2.06, "tv": 6899.86, "trd": [[2.06, 930.86]], "batb": [[1, 2, 32.47]], "batl": [[0, 2.06, 15.46]]}, {"timestamp": 1578719461834, "ltp": 2.06, "tv": 6899.86, "trd": NaN, "batb": [[1, 2, 48.1]], "batl": [[0, 2.06, 10.78], [1, 2.08, 78.31]]}, {"timestamp": 1578719497956, "ltp": 2.06, "tv": 6899.86, "trd": NaN, "batb": [[1, 2, 16.84]], "batl": NaN}, {"timestamp": 1578719518864, "ltp": 2.06, "tv": 6921.42, "trd": [[2.06, 952.42]], "batb": NaN, "batl": [[0, 2.08, 78.31], [1, 2.1, 28.99], [2, 2.12, 6]]}, {"timestamp": 1578719520099, "ltp": 2.06, "tv": 6921.42, "trd": NaN, "batb": [[0, 2.04, 8.55], [1, 2.02, 5.11], [2, 2, 16.84]], "batl": NaN}, {"timestamp": 1578719522878, "ltp": 2.06, "tv": 6921.42, "trd": NaN, "batb": [[1, 2.02, 20.59]], "batl": NaN}, {"timestamp": 1578720199061, "ltp": 2.06, "tv": 6921.42, "trd": NaN, "batb": NaN, "batl": [[0, 2.06, 5], [1, 2.08, 78.31], [2, 2.1, 28.99]]}, {"timestamp": 1578720234994, "ltp": 2.0, "tv": 7013.37, "trd": [[2, 1337.65], [2.02, 1015.2], [2.04, 374.11]], "batb": [[0, 1.96, 8.78], [1, 1.95, 3.14], [2, 1.94, 17.05]], "batl": [[0, 1.99, 13.04], [1, 2, 454.02], [2, 2.06, 5]]}, {"timestamp": 1578720235611, "ltp": 2.0, "tv": 7013.37, "trd": NaN, "batb": [[2, 1.94, 26.31]], "batl": [[0, 1.99, 37.84]]}, {"timestamp": 1578720245001, "ltp": 2.0, "tv": 7013.37, "trd": NaN, "batb": [[0, 1.97, 24.63], [1, 1.96, 8.78], [2, 1.95, 3.14]], "batl": NaN}, {"timestamp": 1578720274534, "ltp": 2.0, "tv": 7013.37, "trd": NaN, "batb": [[0, 1.97, 54.03]], "batl": NaN}, {"timestamp": 1578720479812, "ltp": 1.99, "tv": 7089.06, "trd": [[1.99, 212.89]], "batb": [[2, 1.95, 14.05]], "batl": [[0, 2, 454.02], [1, 2.06, 5], [2, 2.08, 73.67]]}, {"timestamp": 1578720548961, "ltp": 1.99, "tv": 7089.06, "trd": NaN, "batb": NaN, "batl": [[1, 2.06, 10]]}, {"timestamp": 1578720567886, "ltp": 1.99, "tv": 7089.06, "trd": NaN, "batb": [[0, 1.98, 17.88], [1, 1.97, 54.03], [2, 1.96, 8.78]], "batl": NaN}, {"timestamp": 1578720569582, "ltp": 1.99, "tv": 7089.06, "trd": NaN, "batb": [[2, 1.96, 18.19]], "batl": NaN}, {"timestamp": 1578720571693, "ltp": 1.99, "tv": 7089.06, "trd": NaN, "batb": [[1, 1.97, 64.83], [2, 1.96, 8.78]], "batl": NaN}, {"timestamp": 1578720572311, "ltp": 1.99, "tv": 7089.06, "trd": NaN, "batb": [[1, 1.97, 54.03]], "batl": NaN}, {"timestamp": 1578720639963, "ltp": 1.95, "tv": 7256.7, "trd": [[1.95, 97.72], [1.96, 227.78], [1.97, 194.13], [1.98, 78.15]], "batb": [[0, 1.94, 30.34], [1, 1.93, 191.26], [2, 1.9, 5.08]], "batl": [[0, 1.95, 116.18], [1, 2, 454.02], [2, 2.06, 10]]}, {"timestamp": 1578720640685, "ltp": 1.95, "tv": 7256.7, "trd": NaN, "batb": [[0, 1.94, 50.81]], "batl": NaN}, {"timestamp": 1578720642977, "ltp": 1.95, "tv": 7489.02, "trd": [[1.95, 330.03]], "batb": [[0, 1.95, 20.62], [1, 1.94, 55.94], [2, 1.93, 191.26]], "batl": [[0, 2, 454.02], [1, 2.06, 10], [2, 2.08, 73.67]]}, {"timestamp": 1578720656995, "ltp": 1.95, "tv": 7530.27, "trd": [[1.95, 371.28]], "batb": [[0, 1.94, 55.94], [1, 1.93, 191.26], [2, 1.9, 5.08]], "batl": [[0, 1.95, 179.37], [1, 2, 454.02], [2, 2.06, 10]]}, {"timestamp": 1578720657403, "ltp": 1.95, "tv": 7530.27, "trd": NaN, "batb": [[0, 1.94, 47.3]], "batl": NaN}, {"timestamp": 1578720659000, "ltp": 1.95, "tv": 7530.27, "trd": NaN, "batb": [[0, 1.94, 37.8]], "batl": NaN}, {"timestamp": 1578720664004, "ltp": 1.93, "tv": 7889.02, "trd": [[1.93, 300.62], [1.94, 99.6]], "batb": [[0, 1.93, 49.69], [1, 1.9, 5.08], [2, 1.85, 8.11]], "batl": [[0, 1.99, 9.87]]}, {"timestamp": 1578720664107, "ltp": 1.93, "tv": 7889.02, "trd": NaN, "batb": NaN, "batl": [[0, 1.99, 18.73]]}, {"timestamp": 1578720669837, "ltp": 1.93, "tv": 7889.02, "trd": NaN, "batb": [[0, 1.94, 5], [1, 1.93, 49.69], [2, 1.9, 5.08]], "batl": NaN}, {"timestamp": 1578720762144, "ltp": 1.99, "tv": 7905.02, "trd": [[1.99, 228.9]], "batb": NaN, "batl": [[0, 1.99, 10.73]]}, {"timestamp": 1578720832755, "ltp": 1.99, "tv": 7921.18, "trd": [[1.99, 245.06]], "batb": NaN, "batl": [[0, 1.99, 2.64]]}, {"timestamp": 1578720897308, "ltp": 1.99, "tv": 7921.18, "trd": NaN, "batb": [[0, 1.94, 22.88]], "batl": NaN}, {"timestamp": 1578721313851, "ltp": 1.99, "tv": 7925.18, "trd": [[1.99, 249.06]], "batb": NaN, "batl": [[0, 2, 454.66], [1, 2.06, 10], [2, 2.08, 73.67]]}, {"timestamp": 1578721398514, "ltp": 1.99, "tv": 7925.18, "trd": NaN, "batb": NaN, "batl": [[0, 1.99, 15.95], [1, 2, 454.02], [2, 2.06, 10]]}, {"timestamp": 1578721400214, "ltp": 1.99, "tv": 7925.18, "trd": NaN, "batb": NaN, "batl": [[0, 1.99, 23.61]]}, {"timestamp": 1578721401552, "ltp": 1.99, "tv": 7925.18, "trd": NaN, "batb": NaN, "batl": [[0, 1.98, 15.31], [1, 1.99, 23.61], [2, 2, 454.02]]}, {"timestamp": 1578721411541, "ltp": 1.99, "tv": 7925.18, "trd": NaN, "batb": [[0, 1.94, 17.88]], "batl": NaN}, {"timestamp": 1578721439969, "ltp": 1.98, "tv": 7955.8, "trd": [[1.98, 108.77]], "batb": [[0, 1.94, 17.88]], "batl": [[0, 1.99, 23.61], [1, 2, 454.02], [2, 2.06, 10]]}, {"timestamp": 1578722028983, "ltp": 1.98, "tv": 7955.8, "trd": NaN, "batb": NaN, "batl": [[2, 2.04, 17.2]]}, {"timestamp": 1578722029968, "ltp": 1.98, "tv": 7955.82, "trd": [[1.98, 108.79]], "batb": [[0, 1.94, 17.88]], "batl": [[0, 1.98, 19.99], [1, 1.99, 23.61], [2, 2, 454.02]]}, {"timestamp": 1578722031969, "ltp": 1.98, "tv": 7955.82, "trd": NaN, "batb": NaN, "batl": [[0, 1.99, 23.61], [1, 2, 454.02], [2, 2.04, 17.2]]}, {"timestamp": 1578722036974, "ltp": 1.98, "tv": 7955.82, "trd": NaN, "batb": NaN, "batl": [[0, 1.99, 25.61]]}, {"timestamp": 1578722038000, "ltp": 1.98, "tv": 7955.82, "trd": NaN, "batb": NaN, "batl": [[0, 1.99, 23.61]]}, {"timestamp": 1578722038882, "ltp": 1.98, "tv": 7955.82, "trd": NaN, "batb": NaN, "batl": [[0, 1.98, 2], [1, 1.99, 23.61], [2, 2, 454.02]]}, {"timestamp": 1578722202902, "ltp": 1.99, "tv": 8005.81, "trd": [[1.98, 112.79], [1.99, 295.06]], "batb": NaN, "batl": [[0, 2, 454.63], [1, 2.04, 17.2], [2, 2.06, 10]]}, {"timestamp": 1578722229136, "ltp": 1.99, "tv": 8005.81, "trd": NaN, "batb": NaN, "batl": [[0, 1.99, 22.61], [1, 2, 454.02], [2, 2.04, 17.2]]}, {"timestamp": 1578722249944, "ltp": 1.99, "tv": 8005.81, "trd": NaN, "batb": [[0, 1.95, 25], [1, 1.94, 17.88], [2, 1.93, 49.69]], "batl": NaN}, {"timestamp": 1578722250767, "ltp": 1.99, "tv": 8005.81, "trd": NaN, "batb": [[1, 1.94, 27.72]], "batl": NaN}, {"timestamp": 1578722251434, "ltp": 1.99, "tv": 8005.81, "trd": NaN, "batb": [[1, 1.94, 36.81]], "batl": NaN}, {"timestamp": 1578722267876, "ltp": 1.99, "tv": 8005.81, "trd": NaN, "batb": [[0, 1.96, 7.66], [1, 1.95, 25], [2, 1.94, 18.93]], "batl": NaN}, {"timestamp": 1578722272578, "ltp": 1.99, "tv": 8005.81, "trd": NaN, "batb": [[1, 1.94, 9.85], [2, 1.93, 49.69]], "batl": NaN}, {"timestamp": 1578722273559, "ltp": 1.99, "tv": 8005.81, "trd": NaN, "batb": [[1, 1.93, 49.69], [2, 1.9, 5.08]], "batl": NaN}, {"timestamp": 1578722301937, "ltp": 1.99, "tv": 8005.81, "trd": NaN, "batb": [[0, 1.93, 49.69], [1, 1.9, 5.08], [2, 1.85, 8.11]], "batl": NaN}, {"timestamp": 1578722308898, "ltp": 1.99, "tv": 8005.81, "trd": NaN, "batb": [[2, 1.86, 13.7]], "batl": [[0, 1.98, 12.86], [1, 1.99, 22.61], [2, 2, 454.02]]}, {"timestamp": 1578722341872, "ltp": 1.99, "tv": 8005.81, "trd": NaN, "batb": [[0, 1.94, 13.13], [1, 1.93, 49.69], [2, 1.9, 5.08]], "batl": [[0, 1.99, 22.61], [1, 2, 462.89], [2, 2.04, 17.2]]}, {"timestamp": 1578722400595, "ltp": 1.99, "tv": 8051.04, "trd": [[1.99, 340.29]], "batb": NaN, "batl": [[0, 2, 462.89], [1, 2.04, 17.2], [2, 2.06, 10]]}, {"timestamp": 1578722442912, "ltp": 1.99, "tv": 8051.04, "trd": NaN, "batb": [[0, 1.94, 17.45]], "batl": NaN}, {"timestamp": 1578722449213, "ltp": 1.99, "tv": 8051.04, "trd": NaN, "batb": NaN, "batl": [[1, 2.02, 5], [2, 2.04, 17.2]]}, {"timestamp": 1578722493954, "ltp": 1.99, "tv": 8051.04, "trd": NaN, "batb": NaN, "batl": [[1, 2.04, 17.2], [2, 2.06, 10]]}, {"timestamp": 1578722494057, "ltp": 1.99, "tv": 8051.04, "trd": NaN, "batb": NaN, "batl": [[0, 2, 467.89]]}, {"timestamp": 1578722505497, "ltp": 1.99, "tv": 8051.04, "trd": NaN, "batb": NaN, "batl": [[0, 2, 462.89], [1, 2.02, 5], [2, 2.04, 17.2]]}, {"timestamp": 1578722551740, "ltp": 1.99, "tv": 8051.04, "trd": NaN, "batb": NaN, "batl": [[0, 2, 467.89], [1, 2.04, 17.2], [2, 2.06, 10]]}, {"timestamp": 1578722572979, "ltp": 1.94, "tv": 8112.52, "trd": [[1.94, 161.08]], "batb": [[0, 1.93, 49.69], [1, 1.9, 5.08], [2, 1.85, 8.11]], "batl": [[0, 1.94, 19.26], [1, 2, 467.89], [2, 2.04, 17.2]]}, {"timestamp": 1578722575988, "ltp": 1.94, "tv": 8151.03, "trd": [[1.94, 199.59]], "batb": NaN, "batl": [[0, 2, 467.89], [1, 2.04, 17.2], [2, 2.06, 10]]}, {"timestamp": 1578722576405, "ltp": 1.94, "tv": 8151.03, "trd": NaN, "batb": NaN, "batl": [[0, 1.99, 12.95], [1, 2, 467.89], [2, 2.04, 17.2]]}, {"timestamp": 1578722586493, "ltp": 1.94, "tv": 8151.03, "trd": NaN, "batb": NaN, "batl": [[0, 1.99, 17.95], [1, 2, 462.89]]}, {"timestamp": 1578722610409, "ltp": 1.94, "tv": 8151.03, "trd": NaN, "batb": [[0, 1.94, 16.17], [1, 1.93, 49.69], [2, 1.9, 5.08]], "batl": NaN}, {"timestamp": 1578722678934, "ltp": 1.94, "tv": 8151.03, "trd": NaN, "batb": NaN, "batl": [[1, 2, 454.02]]}, {"timestamp": 1578722679713, "ltp": 1.94, "tv": 8151.03, "trd": NaN, "batb": NaN, "batl": [[0, 1.98, 12.86], [1, 1.99, 17.95], [2, 2, 454.02]]}, {"timestamp": 1578722689614, "ltp": 1.94, "tv": 8151.03, "trd": NaN, "batb": NaN, "batl": [[0, 1.98, 17.86], [1, 1.99, 12.95]]}, {"timestamp": 1578722781514, "ltp": 1.94, "tv": 8171.03, "trd": [[1.94, 219.6]], "batb": [[0, 1.94, 6.17]], "batl": NaN}, {"timestamp": 1578722876421, "ltp": 1.94, "tv": 8171.03, "trd": NaN, "batb": NaN, "batl": [[0, 1.95, 2], [1, 1.98, 17.86]]}, {"timestamp": 1578722885118, "ltp": 1.94, "tv": 8171.03, "trd": NaN, "batb": NaN, "batl": [[1, 1.97, 5], [2, 1.98, 12.86]]}, {"timestamp": 1578722891805, "ltp": 1.94, "tv": 8171.03, "trd": NaN, "batb": NaN, "batl": [[2, 1.99, 21.31]]}, {"timestamp": 1578722892537, "ltp": 1.94, "tv": 8171.03, "trd": NaN, "batb": NaN, "batl": [[2, 1.98, 15.31]]}, {"timestamp": 1578722894637, "ltp": 1.95, "tv": 8175.03, "trd": [[1.95, 375.28]], "batb": [[0, 1.95, 5.66], [1, 1.94, 6.17], [2, 1.93, 49.69]], "batl": [[0, 1.97, 5], [1, 1.98, 15.31], [2, 1.99, 21.31]]}, {"timestamp": 1578722895522, "ltp": 1.95, "tv": 8175.03, "trd": NaN, "batb": [[0, 1.94, 6.17], [1, 1.93, 49.69], [2, 1.9, 5.08]], "batl": NaN}, {"timestamp": 1578722896611, "ltp": 1.95, "tv": 8175.03, "trd": NaN, "batb": [[0, 1.95, 15.31], [1, 1.94, 6.17], [2, 1.93, 49.69]], "batl": NaN}, {"timestamp": 1578722901933, "ltp": 1.95, "tv": 8175.03, "trd": NaN, "batb": [[0, 1.94, 21.48], [1, 1.93, 49.69], [2, 1.9, 5.08]], "batl": NaN}, {"timestamp": 1578722904004, "ltp": 1.95, "tv": 8175.03, "trd": NaN, "batb": [[0, 1.94, 29.14]], "batl": NaN}, {"timestamp": 1578723150987, "ltp": 1.97, "tv": 8179.03, "trd": [[1.97, 198.13]], "batb": NaN, "batl": [[0, 1.97, 3]]}, {"timestamp": 1578723151507, "ltp": 1.99, "tv": 8249.44, "trd": [[1.97, 204.13], [1.98, 143.42], [1.99, 374.06]], "batb": NaN, "batl": [[0, 1.99, 17.38], [1, 2, 455.77], [2, 2.04, 17.2]]}, {"timestamp": 1578723152968, "ltp": 1.99, "tv": 8249.44, "trd": NaN, "batb": [[0, 1.95, 6], [1, 1.94, 29.14], [2, 1.93, 49.69]], "batl": [[0, 1.97, 4], [1, 1.99, 4.43], [2, 2, 455.77]]}, {"timestamp": 1578723186916, "ltp": 1.99, "tv": 8249.44, "trd": NaN, "batb": NaN, "batl": [[0, 1.98, 4]]}, {"timestamp": 1578723202965, "ltp": 1.99, "tv": 8249.44, "trd": NaN, "batb": NaN, "batl": [[0, 1.97, 2.11], [1, 1.98, 4], [2, 1.99, 4.43]]}, {"timestamp": 1578723237994, "ltp": 1.99, "tv": 8249.44, "trd": NaN, "batb": NaN, "batl": [[0, 1.98, 4], [1, 1.99, 4.43], [2, 2, 454.02]]}, {"timestamp": 1578723238811, "ltp": 1.99, "tv": 8249.44, "trd": NaN, "batb": NaN, "batl": [[2, 2, 455.55]]}, {"timestamp": 1578723271488, "ltp": 1.99, "tv": 8249.44, "trd": NaN, "batb": NaN, "batl": [[0, 1.97, 2.11], [1, 1.98, 4], [2, 1.99, 4.43]]}, {"timestamp": 1578723316945, "ltp": 1.99, "tv": 8249.44, "trd": NaN, "batb": NaN, "batl": [[0, 1.98, 4], [1, 1.99, 4.43], [2, 2, 454.02]]}, {"timestamp": 1578723317872, "ltp": 1.99, "tv": 8249.44, "trd": NaN, "batb": NaN, "batl": [[2, 2, 455.55]]}, {"timestamp": 1578723362840, "ltp": 1.98, "tv": 8257.44, "trd": [[1.98, 151.42]], "batb": NaN, "batl": [[0, 1.99, 4.43], [1, 2, 455.55], [2, 2.06, 10]]}, {"timestamp": 1578723368962, "ltp": 1.98, "tv": 8257.44, "trd": NaN, "batb": [[0, 1.95, 8.08], [1, 1.94, 38.22]], "batl": NaN}, {"timestamp": 1578723369464, "ltp": 1.98, "tv": 8257.44, "trd": NaN, "batb": [[1, 1.94, 48.07]], "batl": NaN}, {"timestamp": 1578723380946, "ltp": 1.98, "tv": 8257.44, "trd": NaN, "batb": NaN, "batl": [[0, 1.98, 12.86], [1, 1.99, 4.43], [2, 2, 454.02]]}, {"timestamp": 1578723417910, "ltp": 1.98, "tv": 8257.44, "trd": NaN, "batb": NaN, "batl": [[0, 1.98, 15.86]]}, {"timestamp": 1578723432800, "ltp": 1.95, "tv": 8267.44, "trd": [[1.95, 385.28]], "batb": [[0, 1.95, 3.08]], "batl": NaN}, {"timestamp": 1578723446921, "ltp": 1.95, "tv": 8267.44, "trd": NaN, "batb": NaN, "batl": [[0, 1.98, 3], [2, 2, 459.09]]}, {"timestamp": 1578723447647, "ltp": 1.95, "tv": 8267.44, "trd": NaN, "batb": NaN, "batl": [[0, 1.97, 5.07], [1, 1.98, 3], [2, 1.99, 4.43]]}, {"timestamp": 1578723486963, "ltp": 1.95, "tv": 8267.44, "trd": NaN, "batb": NaN, "batl": [[0, 1.98, 3], [1, 1.99, 4.43], [2, 2, 454.02]]}, {"timestamp": 1578723487892, "ltp": 1.95, "tv": 8267.44, "trd": NaN, "batb": NaN, "batl": [[2, 2, 456.04]]}, {"timestamp": 1578723538864, "ltp": 1.95, "tv": 8267.44, "trd": NaN, "batb": NaN, "batl": [[0, 1.97, 1.86], [1, 1.98, 3], [2, 1.99, 4.43]]}, {"timestamp": 1578723570953, "ltp": 1.95, "tv": 8267.44, "trd": NaN, "batb": NaN, "batl": [[0, 1.98, 3], [1, 1.99, 4.43], [2, 2, 454.02]]}, {"timestamp": 1578723571676, "ltp": 1.95, "tv": 8267.44, "trd": NaN, "batb": NaN, "batl": [[2, 2, 455.23]]}, {"timestamp": 1578723604896, "ltp": 1.95, "tv": 8267.44, "trd": NaN, "batb": NaN, "batl": [[0, 1.97, 1.86], [1, 1.98, 3], [2, 1.99, 4.43]]}, {"timestamp": 1578723638997, "ltp": 1.95, "tv": 8267.44, "trd": NaN, "batb": NaN, "batl": [[0, 1.98, 3], [1, 1.99, 4.43], [2, 2, 454.02]]}, {"timestamp": 1578723639824, "ltp": 1.95, "tv": 8267.44, "trd": NaN, "batb": NaN, "batl": [[2, 2, 455.23]]}, {"timestamp": 1578723675969, "ltp": 1.95, "tv": 8267.44, "trd": NaN, "batb": NaN, "batl": [[0, 1.97, 1.86], [1, 1.98, 3], [2, 1.99, 4.43]]}, {"timestamp": 1578723714912, "ltp": 1.95, "tv": 8267.44, "trd": NaN, "batb": NaN, "batl": [[0, 1.98, 3], [1, 1.99, 4.43], [2, 2, 454.02]]}, {"timestamp": 1578723715885, "ltp": 1.95, "tv": 8267.44, "trd": NaN, "batb": NaN, "batl": [[2, 2, 455.23]]}, {"timestamp": 1578723716811, "ltp": 1.95, "tv": 8267.44, "trd": NaN, "batb": NaN, "batl": [[0, 1.98, 13]]}, {"timestamp": 1578723751492, "ltp": 1.95, "tv": 8267.44, "trd": NaN, "batb": NaN, "batl": [[0, 1.97, 4.36], [1, 1.98, 13], [2, 1.99, 4.43]]}, {"timestamp": 1578723756002, "ltp": 1.95, "tv": 8267.44, "trd": NaN, "batb": NaN, "batl": [[0, 1.97, 7.36], [1, 1.98, 10]]}, {"timestamp": 1578723780998, "ltp": 1.95, "tv": 8273.6, "trd": [[1.95, 391.44]], "batb": [[0, 1.94, 48.07], [1, 1.93, 49.69], [2, 1.9, 5.08]], "batl": NaN}, {"timestamp": 1578723784821, "ltp": 1.95, "tv": 8273.6, "trd": NaN, "batb": NaN, "batl": [[0, 1.97, 3]]}, {"timestamp": 1578724011720, "ltp": 1.94, "tv": 8313.6, "trd": [[1.94, 259.59]], "batb": [[0, 1.94, 28.07]], "batl": NaN}, {"timestamp": 1578724013615, "ltp": 1.94, "tv": 8313.6, "trd": NaN, "batb": [[0, 1.94, 9.14]], "batl": NaN}, {"timestamp": 1578724176337, "ltp": 1.94, "tv": 8313.6, "trd": NaN, "batb": [[0, 1.94, 11.28]], "batl": NaN}, {"timestamp": 1578724254875, "ltp": 1.94, "tv": 8313.6, "trd": NaN, "batb": [[0, 1.95, 15.96], [1, 1.94, 11.28], [2, 1.93, 49.69]], "batl": NaN}, {"timestamp": 1578724263971, "ltp": 1.94, "tv": 8313.6, "trd": NaN, "batb": [[0, 1.95, 18.1], [1, 1.94, 9.14]], "batl": NaN}, {"timestamp": 1578724322880, "ltp": 1.97, "tv": 8319.59, "trd": [[1.97, 210.13]], "batb": NaN, "batl": [[0, 1.98, 10], [1, 1.99, 17.38], [2, 2, 454.02]]}, {"timestamp": 1578724341775, "ltp": 1.97, "tv": 8319.59, "trd": NaN, "batb": NaN, "batl": [[0, 1.97, 6.84], [1, 1.98, 10], [2, 1.99, 17.38]]}, {"timestamp": 1578724358708, "ltp": 1.97, "tv": 8319.59, "trd": NaN, "batb": NaN, "batl": [[0, 1.97, 9.84]]}, {"timestamp": 1578724374918, "ltp": 1.97, "tv": 8319.59, "trd": NaN, "batb": NaN, "batl": [[0, 1.97, 3]]}, {"timestamp": 1578724417503, "ltp": 1.97, "tv": 8319.59, "trd": NaN, "batb": [[0, 1.96, 5.96], [1, 1.95, 18.1], [2, 1.94, 9.14]], "batl": NaN}, {"timestamp": 1578724460961, "ltp": 1.97, "tv": 8319.59, "trd": NaN, "batb": [[1, 1.95, 2.14]], "batl": NaN}, {"timestamp": 1578724461320, "ltp": 1.97, "tv": 8325.59, "trd": [[1.97, 216.13]], "batb": [[0, 1.97, 5], [1, 1.96, 5.96], [2, 1.95, 2.14]], "batl": [[0, 1.98, 10], [1, 1.99, 17.38], [2, 2, 454.02]]}, {"timestamp": 1578724463973, "ltp": 1.97, "tv": 8325.59, "trd": NaN, "batb": [[0, 1.97, 7.14], [2, 1.94, 9.14]], "batl": NaN}, {"timestamp": 1578724465925, "ltp": 1.97, "tv": 8333.59, "trd": [[1.97, 224.13]], "batb": [[0, 1.97, 3.14]], "batl": NaN}, {"timestamp": 1578724472978, "ltp": 1.97, "tv": 8333.59, "trd": NaN, "batb": [[2, 1.94, 16.8]], "batl": NaN}, {"timestamp": 1578724474833, "ltp": 1.97, "tv": 8333.59, "trd": NaN, "batb": [[2, 1.94, 24.45]], "batl": NaN}, {"timestamp": 1578724488486, "ltp": 1.97, "tv": 8333.59, "trd": NaN, "batb": NaN, "batl": [[0, 1.98, 13]]}, {"timestamp": 1578724496615, "ltp": 1.97, "tv": 8333.59, "trd": NaN, "batb": [[1, 1.94, 24.45], [2, 1.93, 49.69]], "batl": NaN}, {"timestamp": 1578724510939, "ltp": 1.97, "tv": 8333.59, "trd": NaN, "batb": [[0, 1.97, 2.14]], "batl": NaN}, {"timestamp": 1578724538946, "ltp": 1.97, "tv": 8333.59, "trd": NaN, "batb": [[0, 1.95, 2.14]], "batl": NaN}, {"timestamp": 1578724556694, "ltp": 1.97, "tv": 8333.59, "trd": NaN, "batb": NaN, "batl": [[0, 1.97, 7.59], [1, 1.98, 13], [2, 1.99, 17.38]]}, {"timestamp": 1578724593665, "ltp": 1.97, "tv": 8333.59, "trd": NaN, "batb": NaN, "batl": [[0, 1.97, 10.59], [1, 1.98, 10]]}, {"timestamp": 1578724600964, "ltp": 1.97, "tv": 8333.59, "trd": NaN, "batb": NaN, "batl": [[0, 1.97, 3]]}, {"timestamp": 1578724601845, "ltp": 1.97, "tv": 8333.59, "trd": NaN, "batb": [[0, 1.96, 1.68], [1, 1.95, 2.14], [2, 1.94, 24.45]], "batl": [[2, 1.99, 4.43]]}, {"timestamp": 1578724602976, "ltp": 1.97, "tv": 8333.59, "trd": NaN, "batb": [[0, 1.96, 4.05]], "batl": NaN}, {"timestamp": 1578724603961, "ltp": 1.97, "tv": 8333.59, "trd": NaN, "batb": [[0, 1.95, 6.21], [1, 1.94, 24.45], [2, 1.93, 49.69]], "batl": NaN}, {"timestamp": 1578724604936, "ltp": 1.97, "tv": 8333.59, "trd": NaN, "batb": [[0, 1.96, 4.05], [1, 1.95, 2.14], [2, 1.94, 24.45]], "batl": NaN}, {"timestamp": 1578724616999, "ltp": 1.97, "tv": 8333.59, "trd": NaN, "batb": [[0, 1.96, 6.19], [1, 1.94, 24.45], [2, 1.93, 49.69]], "batl": NaN}, {"timestamp": 1578724617888, "ltp": 1.97, "tv": 8333.59, "trd": NaN, "batb": [[0, 1.96, 2.14], [1, 1.95, 4.07], [2, 1.94, 24.45]], "batl": NaN}, {"timestamp": 1578724619977, "ltp": 1.97, "tv": 8333.59, "trd": NaN, "batb": [[0, 1.96, 6.19], [1, 1.94, 24.45], [2, 1.93, 49.69]], "batl": NaN}, {"timestamp": 1578724620903, "ltp": 1.97, "tv": 8333.59, "trd": NaN, "batb": [[0, 1.96, 2.14]], "batl": NaN}, {"timestamp": 1578724621990, "ltp": 1.96, "tv": 8342.47, "trd": [[1.96, 232.06], [1.97, 228.73]], "batb": [[0, 1.96, 9.97]], "batl": [[0, 1.98, 10.7], [1, 1.99, 4.43], [2, 2, 459.17]]}, {"timestamp": 1578724622965, "ltp": 1.96, "tv": 8342.47, "trd": NaN, "batb": [[0, 1.95, 10.03]], "batl": NaN}, {"timestamp": 1578724635988, "ltp": 1.96, "tv": 8342.47, "trd": NaN, "batb": [[0, 1.95, 4]], "batl": NaN}, {"timestamp": 1578724637836, "ltp": 1.96, "tv": 8342.47, "trd": NaN, "batb": NaN, "batl": [[0, 1.97, 4.48], [1, 1.98, 10], [2, 1.99, 4.43]]}, {"timestamp": 1578724643818, "ltp": 1.96, "tv": 8342.47, "trd": NaN, "batb": [[0, 1.95, 10.53]], "batl": NaN}, {"timestamp": 1578724644945, "ltp": 1.96, "tv": 8342.47, "trd": NaN, "batb": [[0, 1.96, 4.03], [1, 1.95, 6.53], [2, 1.94, 24.45]], "batl": NaN}, {"timestamp": 1578724670837, "ltp": 1.96, "tv": 8342.47, "trd": NaN, "batb": [[0, 1.96, 10.56], [1, 1.94, 24.45], [2, 1.93, 49.69]], "batl": NaN}, {"timestamp": 1578724671862, "ltp": 1.96, "tv": 8342.47, "trd": NaN, "batb": [[0, 1.96, 10.55]], "batl": NaN}, {"timestamp": 1578724675870, "ltp": 1.96, "tv": 8342.47, "trd": NaN, "batb": [[0, 1.96, 6.53], [1, 1.95, 4.04], [2, 1.94, 24.45]], "batl": [[0, 1.98, 10.7], [1, 1.99, 4.43], [2, 2, 457.64]]}, {"timestamp": 1578724676952, "ltp": 1.97, "tv": 8343.87, "trd": [[1.97, 230.13]], "batb": [[0, 1.97, 3.31], [1, 1.96, 6.53]], "batl": [[0, 1.98, 10], [1, 1.99, 17.38]]}, {"timestamp": 1578724678964, "ltp": 1.97, "tv": 8343.87, "trd": NaN, "batb": [[0, 1.97, 5.35], [2, 1.94, 43.38]], "batl": NaN}, {"timestamp": 1578724679833, "ltp": 1.97, "tv": 8343.87, "trd": NaN, "batb": [[0, 1.97, 3.31]], "batl": NaN}, {"timestamp": 1578724687835, "ltp": 1.97, "tv": 8343.87, "trd": NaN, "batb": NaN, "batl": [[0, 1.98, 12]]}, {"timestamp": 1578724689957, "ltp": 1.98, "tv": 8355.35, "trd": [[1.98, 162.9]], "batb": NaN, "batl": [[0, 1.98, 6.26]]}, {"timestamp": 1578724690988, "ltp": 1.98, "tv": 8355.35, "trd": NaN, "batb": [[0, 1.97, 7.82]], "batl": NaN}, {"timestamp": 1578724691874, "ltp": 1.98, "tv": 8355.35, "trd": NaN, "batb": [[0, 1.97, 6.69]], "batl": NaN}, {"timestamp": 1578724692966, "ltp": 1.98, "tv": 8355.35, "trd": NaN, "batb": [[0, 1.97, 5.74]], "batl": NaN}, {"timestamp": 1578724693953, "ltp": 1.98, "tv": 8355.35, "trd": NaN, "batb": [[0, 1.97, 3.31]], "batl": NaN}, {"timestamp": 1578724747882, "ltp": 1.98, "tv": 8355.35, "trd": NaN, "batb": [[0, 1.97, 6.53], [1, 1.95, 3.29]], "batl": NaN}, {"timestamp": 1578724748984, "ltp": 1.98, "tv": 8355.35, "trd": NaN, "batb": [[0, 1.97, 9.79], [1, 1.94, 43.38], [2, 1.93, 49.69]], "batl": NaN}, {"timestamp": 1578724751981, "ltp": 1.98, "tv": 8355.35, "trd": NaN, "batb": [[0, 1.97, 6.53]], "batl": NaN}, {"timestamp": 1578724752954, "ltp": 1.98, "tv": 8355.35, "trd": NaN, "batb": [[0, 1.97, 9.79]], "batl": NaN}, {"timestamp": 1578724754955, "ltp": 1.98, "tv": 8355.35, "trd": NaN, "batb": [[0, 1.97, 6.53], [1, 1.95, 3.29], [2, 1.94, 43.38]], "batl": NaN}, {"timestamp": 1578724755986, "ltp": 1.98, "tv": 8355.35, "trd": NaN, "batb": [[0, 1.97, 9.79], [1, 1.94, 43.38], [2, 1.93, 49.69]], "batl": NaN}, {"timestamp": 1578724757883, "ltp": 1.98, "tv": 8355.35, "trd": NaN, "batb": [[0, 1.97, 6.53], [1, 1.95, 3.29], [2, 1.94, 43.38]], "batl": NaN}, {"timestamp": 1578724758701, "ltp": 1.98, "tv": 8355.35, "trd": NaN, "batb": [[0, 1.97, 9.79], [1, 1.94, 43.38], [2, 1.93, 49.69]], "batl": NaN}, {"timestamp": 1578724760813, "ltp": 1.98, "tv": 8355.35, "trd": NaN, "batb": [[0, 1.97, 6.53], [1, 1.95, 3.29], [2, 1.94, 43.38]], "batl": NaN}, {"timestamp": 1578724762615, "ltp": 1.98, "tv": 8355.35, "trd": NaN, "batb": [[0, 1.97, 9.79], [1, 1.94, 43.38], [2, 1.93, 49.69]], "batl": NaN}, {"timestamp": 1578724769919, "ltp": 1.98, "tv": 8355.35, "trd": NaN, "batb": [[0, 1.97, 6.53]], "batl": NaN}, {"timestamp": 1578724770892, "ltp": 1.98, "tv": 8355.35, "trd": NaN, "batb": [[0, 1.97, 23.63]], "batl": NaN}, {"timestamp": 1578724771917, "ltp": 1.99, "tv": 8411.53, "trd": [[1.97, 239.03], [1.98, 175.42], [1.99, 408.82]], "batb": [[0, 1.97, 2.08]], "batl": [[0, 2, 457.64], [1, 2.06, 10], [2, 2.08, 73.67]]}, {"timestamp": 1578724772994, "ltp": 1.99, "tv": 8411.53, "trd": NaN, "batb": [[0, 1.94, 43.38], [1, 1.93, 49.69], [2, 1.9, 5.08]], "batl": [[0, 1.99, 3.01], [1, 2, 457.64], [2, 2.06, 10]]}, {"timestamp": 1578724773915, "ltp": 1.99, "tv": 8411.53, "trd": NaN, "batb": [[0, 1.95, 2.08], [1, 1.94, 43.38], [2, 1.93, 49.69]], "batl": NaN}, {"timestamp": 1578724775000, "ltp": 2.0, "tv": 8451.45, "trd": [[1.99, 414.84], [2, 1371.55]], "batb": [[0, 1.96, 3.75], [1, 1.95, 2.08], [2, 1.94, 43.38]], "batl": [[0, 2, 440.69], [1, 2.06, 10], [2, 2.08, 73.67]]}, {"timestamp": 1578724776995, "ltp": 2.0, "tv": 8451.45, "trd": NaN, "batb": [[0, 1.98, 3.55], [1, 1.97, 3], [2, 1.95, 2.08]], "batl": NaN}, {"timestamp": 1578724778698, "ltp": 2.0, "tv": 8451.45, "trd": NaN, "batb": [[0, 1.98, 3.35]], "batl": NaN}, {"timestamp": 1578724780959, "ltp": 2.0, "tv": 8451.45, "trd": NaN, "batb": [[0, 1.98, 3.18], [1, 1.95, 2.08], [2, 1.94, 43.38]], "batl": NaN}, {"timestamp": 1578724781936, "ltp": 1.98, "tv": 8457.81, "trd": [[1.98, 181.78]], "batb": [[0, 1.95, 2.08], [1, 1.94, 43.38], [2, 1.93, 49.69]], "batl": NaN}, {"timestamp": 1578724806944, "ltp": 1.95, "tv": 8467.8, "trd": [[1.95, 401.44]], "batb": [[0, 1.95, 11.55]], "batl": [[1, 2.06, 29]]}, {"timestamp": 1578724830995, "ltp": 1.95, "tv": 8467.8, "trd": NaN, "batb": NaN, "batl": [[1, 2.04, 4], [2, 2.06, 29]]}, {"timestamp": 1578724842999, "ltp": 1.95, "tv": 8467.8, "trd": NaN, "batb": NaN, "batl": [[1, 2.02, 4]]}, {"timestamp": 1578724912932, "ltp": 1.95, "tv": 8467.8, "trd": NaN, "batb": NaN, "batl": [[1, 2.06, 29], [2, 2.08, 73.67]]}, {"timestamp": 1578724913920, "ltp": 1.95, "tv": 8467.8, "trd": NaN, "batb": NaN, "batl": [[0, 2, 444.69]]}, {"timestamp": 1578724919930, "ltp": 1.95, "tv": 8467.8, "trd": NaN, "batb": [[0, 1.96, 8.9], [1, 1.95, 11.55], [2, 1.94, 43.38]], "batl": NaN}, {"timestamp": 1578724948953, "ltp": 1.95, "tv": 8467.8, "trd": NaN, "batb": NaN, "batl": [[0, 2, 440.69], [1, 2.04, 4], [2, 2.06, 29]]}, {"timestamp": 1578724962928, "ltp": 1.95, "tv": 8467.8, "trd": NaN, "batb": NaN, "batl": [[1, 2.04, 23], [2, 2.06, 10]]}, {"timestamp": 1578725018829, "ltp": 1.95, "tv": 8467.8, "trd": NaN, "batb": NaN, "batl": [[1, 2.02, 4], [2, 2.04, 19]]}, {"timestamp": 1578725053571, "ltp": 1.95, "tv": 8467.8, "trd": NaN, "batb": NaN, "batl": [[0, 2, 444.69], [1, 2.04, 19], [2, 2.06, 10]]}, {"timestamp": 1578725064001, "ltp": 1.95, "tv": 8467.8, "trd": NaN, "batb": NaN, "batl": [[0, 1.99, 200], [1, 2, 444.69], [2, 2.04, 19]]}, {"timestamp": 1578725080917, "ltp": 1.95, "tv": 8467.8, "trd": NaN, "batb": NaN, "batl": [[1, 2, 441.07]]}, {"timestamp": 1578725081802, "ltp": 1.95, "tv": 8467.8, "trd": NaN, "batb": NaN, "batl": [[0, 1.98, 12.86], [1, 1.99, 200], [2, 2, 441.07]]}, {"timestamp": 1578725088842, "ltp": 1.95, "tv": 8467.8, "trd": NaN, "batb": NaN, "batl": [[0, 1.98, 16.86], [2, 2, 437.07]]}, {"timestamp": 1578725113974, "ltp": 1.95, "tv": 8467.8, "trd": NaN, "batb": NaN, "batl": [[0, 1.98, 4], [2, 2, 449.8]]}, {"timestamp": 1578725255790, "ltp": 1.98, "tv": 8471.8, "trd": [[1.98, 185.78]], "batb": NaN, "batl": [[0, 1.98, 2]]}, {"timestamp": 1578725283983, "ltp": 1.98, "tv": 8475.8, "trd": [[1.98, 189.78]], "batb": [[0, 1.96, 9.46]], "batl": [[0, 1.99, 200], [1, 2, 449.8], [2, 2.06, 10]]}, {"timestamp": 1578725299983, "ltp": 1.98, "tv": 8475.8, "trd": NaN, "batb": NaN, "batl": [[0, 1.99, 203]]}, {"timestamp": 1578725316921, "ltp": 1.98, "tv": 8476.91, "trd": [[1.98, 190.88]], "batb": [[0, 1.96, 8.9]], "batl": [[0, 1.98, 12.31], [1, 1.99, 203], [2, 2, 437.07]]}, {"timestamp": 1578725318991, "ltp": 1.98, "tv": 8476.91, "trd": NaN, "batb": [[0, 1.97, 4.71], [1, 1.96, 8.9], [2, 1.95, 11.55]], "batl": NaN}, {"timestamp": 1578725325825, "ltp": 1.98, "tv": 8476.91, "trd": NaN, "batb": [[2, 1.94, 43.38]], "batl": NaN}, {"timestamp": 1578725345966, "ltp": 1.98, "tv": 8476.91, "trd": NaN, "batb": NaN, "batl": [[0, 1.98, 15.31], [1, 1.99, 200]]}, {"timestamp": 1578725361002, "ltp": 1.98, "tv": 8476.91, "trd": NaN, "batb": NaN, "batl": [[0, 1.98, 3], [2, 2, 449.26]]}, {"timestamp": 1578725366805, "ltp": 1.98, "tv": 8476.91, "trd": NaN, "batb": [[0, 1.97, 4.72]], "batl": NaN}, {"timestamp": 1578725521998, "ltp": 1.99, "tv": 8505.81, "trd": [[1.98, 196.88], [1.99, 437.74]], "batb": NaN, "batl": [[0, 1.99, 188.55], [1, 2, 449.26], [2, 2.06, 10]]}, {"timestamp": 1578725522922, "ltp": 1.99, "tv": 8581.55, "trd": [[1.99, 513.48]], "batb": [[0, 1.98, 13.51], [1, 1.94, 43.38], [2, 1.93, 49.69]], "batl": [[0, 1.99, 150.68]]}, {"timestamp": 1578725523909, "ltp": 1.99, "tv": 8601.51, "trd": [[1.99, 533.44]], "batb": [[0, 1.98, 8.81]], "batl": [[0, 1.99, 140.7]]}, {"timestamp": 1578725527913, "ltp": 1.99, "tv": 8601.51, "trd": NaN, "batb": NaN, "batl": [[2, 2.04, 18.5]]}, {"timestamp": 1578725545922, "ltp": 1.99, "tv": 8601.51, "trd": NaN, "batb": NaN, "batl": [[0, 1.99, 142.7]]}, {"timestamp": 1578725672901, "ltp": 1.98, "tv": 8608.51, "trd": [[1.98, 203.88]], "batb": [[0, 1.98, 5.31]], "batl": NaN}, {"timestamp": 1578725686815, "ltp": 1.98, "tv": 8619.13, "trd": [[1.98, 214.5]], "batb": [[0, 1.94, 43.38], [1, 1.93, 49.69], [2, 1.9, 5.08]], "batl": NaN}, {"timestamp": 1578725688002, "ltp": 1.98, "tv": 8619.13, "trd": NaN, "batb": [[0, 1.94, 24.45]], "batl": NaN}, {"timestamp": 1578725689916, "ltp": 1.98, "tv": 8619.13, "trd": NaN, "batb": [[0, 1.95, 7.66], [1, 1.94, 24.45], [2, 1.93, 49.69]], "batl": NaN}, {"timestamp": 1578725692002, "ltp": 1.98, "tv": 8619.13, "trd": NaN, "batb": NaN, "batl": [[0, 1.98, 2.96], [1, 1.99, 142.7], [2, 2, 449.26]]}, {"timestamp": 1578725692926, "ltp": 1.98, "tv": 8619.13, "trd": NaN, "batb": NaN, "batl": [[0, 1.97, 12.38], [1, 1.98, 2.96], [2, 1.99, 142.7]]}, {"timestamp": 1578725696708, "ltp": 1.98, "tv": 8619.13, "trd": NaN, "batb": [[0, 1.95, 36.91]], "batl": NaN}, {"timestamp": 1578725697907, "ltp": 1.98, "tv": 8619.13, "trd": NaN, "batb": [[1, 1.94, 43.38]], "batl": NaN}, {"timestamp": 1578725716002, "ltp": 1.98, "tv": 8619.13, "trd": NaN, "batb": NaN, "batl": [[0, 1.97, 14.38], [2, 1.99, 140.7]]}, {"timestamp": 1578725724976, "ltp": 1.98, "tv": 8619.13, "trd": NaN, "batb": NaN, "batl": [[0, 1.97, 2]]}, {"timestamp": 1578725731978, "ltp": 1.95, "tv": 8623.13, "trd": [[1.95, 405.44]], "batb": [[0, 1.95, 34.91]], "batl": NaN}, {"timestamp": 1578725765971, "ltp": 1.96, "tv": 8645.67, "trd": [[1.95, 412.54], [1.96, 247.5]], "batb": [[0, 1.96, 8.46], [1, 1.95, 31.36], [2, 1.94, 43.38]], "batl": NaN}, {"timestamp": 1578725802976, "ltp": 1.96, "tv": 8645.67, "trd": NaN, "batb": [[0, 1.96, 5.46]], "batl": NaN}, {"timestamp": 1578725835948, "ltp": 1.96, "tv": 8645.67, "trd": NaN, "batb": NaN, "batl": [[0, 1.97, 8.96]]}, {"timestamp": 1578725836925, "ltp": 1.96, "tv": 8656.59, "trd": [[1.96, 258.42]], "batb": [[0, 1.95, 31.36], [1, 1.94, 43.38], [2, 1.93, 49.69]], "batl": [[0, 1.97, 2]]}, {"timestamp": 1578725837949, "ltp": 1.96, "tv": 8656.59, "trd": NaN, "batb": NaN, "batl": [[1, 1.98, 5.51]]}, {"timestamp": 1578725887894, "ltp": 1.96, "tv": 8656.59, "trd": NaN, "batb": [[0, 1.96, 14], [1, 1.95, 31.36], [2, 1.94, 43.38]], "batl": [[1, 1.98, 2.96], [2, 1.99, 142.99]]}, {"timestamp": 1578725889902, "ltp": 1.96, "tv": 8656.59, "trd": NaN, "batb": NaN, "batl": [[1, 1.98, 5.29]]}, {"timestamp": 1578725895820, "ltp": 1.96, "tv": 8656.59, "trd": NaN, "batb": [[0, 1.96, 34]], "batl": NaN}, {"timestamp": 1578725902977, "ltp": 1.98, "tv": 8696.59, "trd": [[1.97, 243.03], [1.98, 250.51]], "batb": [[0, 1.96, 14]], "batl": [[1, 1.99, 141.03], [2, 2, 441.4]]}, {"timestamp": 1578725909784, "ltp": 1.98, "tv": 8696.59, "trd": NaN, "batb": NaN, "batl": [[1, 1.98, 3.29], [2, 1.99, 140.7]]}, {"timestamp": 1578725919829, "ltp": 1.98, "tv": 8696.59, "trd": NaN, "batb": NaN, "batl": [[0, 1.97, 5]]}, {"timestamp": 1578725999918, "ltp": 1.96, "tv": 8750.27, "trd": [[1.96, 312.1]], "batb": [[0, 1.95, 31.36], [1, 1.94, 43.38], [2, 1.93, 49.69]], "batl": [[0, 1.96, 6.16], [1, 1.97, 5], [2, 1.98, 2.96]]}, {"timestamp": 1578726000720, "ltp": 1.96, "tv": 8762.59, "trd": [[1.96, 324.42]], "batb": [[0, 1.96, 128.42], [1, 1.95, 31.36], [2, 1.94, 43.38]], "batl": [[0, 1.97, 5], [1, 1.98, 2.96], [2, 1.99, 140.7]]}, {"timestamp": 1578726001824, "ltp": 1.97, "tv": 8772.58, "trd": [[1.97, 253.02]], "batb": [[0, 1.97, 16.15], [1, 1.96, 128.42], [2, 1.95, 31.36]], "batl": [[0, 1.98, 2.96], [1, 1.99, 140.7], [2, 2, 441.4]]}, {"timestamp": 1578726009914, "ltp": 1.97, "tv": 8772.58, "trd": NaN, "batb": [[0, 1.97, 36.72]], "batl": NaN}, {"timestamp": 1578726015953, "ltp": 1.97, "tv": 8772.58, "trd": NaN, "batb": [[1, 1.95, 31.36], [2, 1.94, 24.45]], "batl": [[0, 1.98, 16]]}, {"timestamp": 1578726016931, "ltp": 1.97, "tv": 8772.58, "trd": NaN, "batb": [[0, 1.95, 31.36], [1, 1.94, 24.45], [2, 1.93, 49.69]], "batl": [[0, 1.97, 12.38], [1, 1.98, 16], [2, 1.99, 140.7]]}, {"timestamp": 1578726017862, "ltp": 1.97, "tv": 8772.58, "trd": NaN, "batb": [[1, 1.94, 38.31]], "batl": NaN}, {"timestamp": 1578726018944, "ltp": 1.97, "tv": 8772.58, "trd": NaN, "batb": NaN, "batl": [[1, 1.98, 19]]}, {"timestamp": 1578726029916, "ltp": 1.97, "tv": 8772.58, "trd": NaN, "batb": NaN, "batl": [[0, 1.96, 7.6], [1, 1.97, 12.38], [2, 1.98, 19]]}, {"timestamp": 1578726041926, "ltp": 1.97, "tv": 8772.58, "trd": NaN, "batb": NaN, "batl": [[0, 1.96, 12.93]]}, {"timestamp": 1578726042919, "ltp": 1.97, "tv": 8772.58, "trd": NaN, "batb": NaN, "batl": [[0, 1.96, 7.86]]}, {"timestamp": 1578726043956, "ltp": 1.96, "tv": 8788.3, "trd": [[1.96, 340.13]], "batb": [[0, 1.96, 120.56], [1, 1.95, 31.36], [2, 1.94, 38.31]], "batl": [[0, 1.97, 12.38], [1, 1.98, 19], [2, 1.99, 140.7]]}, {"timestamp": 1578726044842, "ltp": 1.96, "tv": 8788.3, "trd": NaN, "batb": [[0, 1.96, 134.28], [2, 1.94, 24.45]], "batl": NaN}, {"timestamp": 1578726056937, "ltp": 1.97, "tv": 8811.78, "trd": [[1.97, 276.5]], "batb": NaN, "batl": [[0, 1.98, 19.64], [1, 1.99, 140.7], [2, 2, 437.07]]}, {"timestamp": 1578726058864, "ltp": 1.97, "tv": 8811.78, "trd": NaN, "batb": [[0, 1.96, 13.71]], "batl": [[0, 1.98, 32.39]]}, {"timestamp": 1578726059949, "ltp": 1.97, "tv": 8811.78, "trd": NaN, "batb": [[0, 1.96, 8.99]], "batl": NaN}, {"timestamp": 1578726060874, "ltp": 1.97, "tv": 8811.78, "trd": NaN, "batb": [[0, 1.95, 31.36], [1, 1.94, 24.45], [2, 1.93, 49.69]], "batl": NaN}, {"timestamp": 1578726081913, "ltp": 1.97, "tv": 8811.78, "trd": NaN, "batb": [[1, 1.94, 33.54]], "batl": NaN}, {"timestamp": 1578726098802, "ltp": 1.97, "tv": 8811.78, "trd": NaN, "batb": [[0, 1.96, 14.17], [1, 1.95, 31.36], [2, 1.94, 33.54]], "batl": NaN}, {"timestamp": 1578726101998, "ltp": 1.97, "tv": 8813.05, "trd": [[1.97, 277.78]], "batb": [[0, 1.97, 3.62], [1, 1.96, 14.17], [2, 1.95, 29.25]], "batl": [[0, 1.98, 31.75]]}, {"timestamp": 1578726115951, "ltp": 1.97, "tv": 8813.05, "trd": NaN, "batb": NaN, "batl": [[0, 1.98, 44.5]]}, {"timestamp": 1578726128739, "ltp": 1.97, "tv": 8813.05, "trd": NaN, "batb": [[0, 1.97, 4.37]], "batl": NaN}, {"timestamp": 1578726133845, "ltp": 1.98, "tv": 8823.05, "trd": [[1.98, 260.51]], "batb": NaN, "batl": [[0, 1.98, 39.5]]}, {"timestamp": 1578726150996, "ltp": 1.98, "tv": 8823.05, "trd": NaN, "batb": [[1, 1.95, 29.25], [2, 1.94, 33.54]], "batl": NaN}, {"timestamp": 1578726153004, "ltp": 1.97, "tv": 8824.55, "trd": [[1.97, 279.28]], "batb": [[0, 1.95, 29.25], [1, 1.94, 33.54], [2, 1.93, 49.69]], "batl": NaN}, {"timestamp": 1578726168896, "ltp": 1.98, "tv": 8829.83, "trd": [[1.98, 265.78]], "batb": NaN, "batl": [[0, 1.98, 36.86]]}, {"timestamp": 1578726178958, "ltp": 1.99, "tv": 8906.97, "trd": [[1.98, 339.51], [1.99, 536.86]], "batb": NaN, "batl": [[0, 1.99, 138.99], [1, 2, 437.07], [2, 2.06, 10]]}, {"timestamp": 1578726179836, "ltp": 1.99, "tv": 8906.97, "trd": NaN, "batb": [[1, 1.94, 52.41]], "batl": NaN}, {"timestamp": 1578726199417, "ltp": 1.99, "tv": 8942.97, "trd": [[1.99, 572.86]], "batb": NaN, "batl": [[0, 1.99, 120.99]]}, {"timestamp": 1578726203821, "ltp": 1.99, "tv": 8942.97, "trd": NaN, "batb": NaN, "batl": [[2, 2.04, 13.33]]}, {"timestamp": 1578726227446, "ltp": 1.99, "tv": 9011.55, "trd": [[1.99, 641.44]], "batb": NaN, "batl": [[0, 1.99, 86.7]]}, {"timestamp": 1578726244880, "ltp": 1.99, "tv": 9184.95, "trd": [[1.99, 814.84]], "batb": NaN, "batl": [[0, 2, 437.07], [1, 2.02, 17.68], [2, 2.04, 24.22]]}, {"timestamp": 1578726246784, "ltp": 1.99, "tv": 9184.95, "trd": NaN, "batb": NaN, "batl": [[1, 2.04, 13.33], [2, 2.06, 10]]}, {"timestamp": 1578726249992, "ltp": 1.99, "tv": 9184.95, "trd": NaN, "batb": NaN, "batl": [[0, 2, 442.07]]}, {"timestamp": 1578726254761, "ltp": 1.99, "tv": 9184.95, "trd": NaN, "batb": [[0, 1.96, 16.2], [1, 1.95, 29.25], [2, 1.94, 52.41]], "batl": NaN}, {"timestamp": 1578726282903, "ltp": 1.99, "tv": 9184.95, "trd": NaN, "batb": NaN, "batl": [[0, 1.99, 2.98], [1, 2, 442.07], [2, 2.04, 13.33]]}, {"timestamp": 1578726283937, "ltp": 1.99, "tv": 9184.95, "trd": NaN, "batb": NaN, "batl": [[0, 2, 442.07], [1, 2.04, 13.33], [2, 2.06, 10]]}, {"timestamp": 1578726285962, "ltp": 1.99, "tv": 9184.95, "trd": NaN, "batb": NaN, "batl": [[0, 2, 437.07], [1, 2.02, 5], [2, 2.04, 13.33]]}, {"timestamp": 1578726291970, "ltp": 1.99, "tv": 9184.95, "trd": NaN, "batb": [[0, 1.97, 5.11], [1, 1.96, 16.2], [2, 1.95, 29.25]], "batl": NaN}, {"timestamp": 1578726306885, "ltp": 1.99, "tv": 9184.95, "trd": NaN, "batb": [[1, 1.95, 29.25], [2, 1.94, 52.41]], "batl": NaN}, {"timestamp": 1578726321988, "ltp": 1.99, "tv": 9184.95, "trd": NaN, "batb": [[0, 1.95, 29.25], [1, 1.94, 52.41], [2, 1.93, 49.69]], "batl": NaN}, {"timestamp": 1578726333980, "ltp": 1.99, "tv": 9184.95, "trd": NaN, "batb": NaN, "batl": [[1, 2.04, 13.33], [2, 2.06, 10]]}, {"timestamp": 1578726334910, "ltp": 1.99, "tv": 9184.95, "trd": NaN, "batb": NaN, "batl": [[0, 2, 442.07]]}, {"timestamp": 1578726346930, "ltp": 1.99, "tv": 9184.95, "trd": NaN, "batb": NaN, "batl": [[0, 2, 437.07], [1, 2.02, 5], [2, 2.04, 13.33]]}, {"timestamp": 1578726353918, "ltp": 1.99, "tv": 9184.95, "trd": NaN, "batb": NaN, "batl": [[0, 1.99, 19.49], [1, 2, 437.07], [2, 2.02, 5]]}, {"timestamp": 1578726358914, "ltp": 1.99, "tv": 9184.95, "trd": NaN, "batb": [[0, 1.96, 14.97], [1, 1.95, 29.25], [2, 1.94, 52.41]], "batl": NaN}, {"timestamp": 1578726382992, "ltp": 1.99, "tv": 9184.95, "trd": NaN, "batb": NaN, "batl": [[0, 1.99, 24.49], [2, 2.04, 13.33]]}, {"timestamp": 1578726441967, "ltp": 1.99, "tv": 9184.95, "trd": NaN, "batb": NaN, "batl": [[0, 1.99, 5]]}, {"timestamp": 1578726514985, "ltp": 1.99, "tv": 9184.95, "trd": NaN, "batb": NaN, "batl": [[2, 2.06, 10]]}, {"timestamp": 1578726516535, "ltp": 1.99, "tv": 9184.95, "trd": NaN, "batb": NaN, "batl": [[0, 1.98, 1.7], [1, 1.99, 5], [2, 2, 437.07]]}, {"timestamp": 1578726524960, "ltp": 1.99, "tv": 9184.95, "trd": NaN, "batb": NaN, "batl": [[0, 1.99, 5], [1, 2, 437.07], [2, 2.06, 10]]}, {"timestamp": 1578726598956, "ltp": 1.99, "tv": 9184.95, "trd": NaN, "batb": NaN, "batl": [[0, 1.99, 10.92]]}, {"timestamp": 1578726607877, "ltp": 1.99, "tv": 9195.43, "trd": [[1.99, 825.32]], "batb": NaN, "batl": [[0, 1.99, 5.68]]}, {"timestamp": 1578726624680, "ltp": 1.99, "tv": 9195.43, "trd": NaN, "batb": [[0, 1.96, 15.06]], "batl": NaN}, {"timestamp": 1578726648910, "ltp": 1.99, "tv": 9195.43, "trd": NaN, "batb": NaN, "batl": [[0, 1.99, 8.68]]}, {"timestamp": 1578726674936, "ltp": 1.99, "tv": 9195.43, "trd": NaN, "batb": NaN, "batl": [[0, 1.98, 150], [1, 1.99, 8.68], [2, 2, 437.07]]}, {"timestamp": 1578726679959, "ltp": 1.97, "tv": 9195.61, "trd": [[1.97, 279.45]], "batb": [[0, 1.96, 14.97]], "batl": [[0, 1.97, 2.51], [1, 1.98, 150], [2, 1.99, 8.68]]}, {"timestamp": 1578726680934, "ltp": 1.97, "tv": 9195.61, "trd": NaN, "batb": NaN, "batl": [[0, 1.97, 2.17]]}, {"timestamp": 1578726681968, "ltp": 1.97, "tv": 9195.61, "trd": NaN, "batb": NaN, "batl": [[0, 1.98, 150], [1, 1.99, 8.68], [2, 2, 437.07]]}, {"timestamp": 1578726683933, "ltp": 1.97, "tv": 9195.61, "trd": NaN, "batb": NaN, "batl": [[0, 1.97, 2.68], [1, 1.98, 150], [2, 1.99, 8.68]]}, {"timestamp": 1578726684963, "ltp": 1.97, "tv": 9195.61, "trd": NaN, "batb": NaN, "batl": [[0, 1.98, 150], [1, 1.99, 8.68], [2, 2, 437.07]]}, {"timestamp": 1578726688854, "ltp": 1.97, "tv": 9195.61, "trd": NaN, "batb": NaN, "batl": [[0, 1.97, 3.05], [1, 1.98, 150], [2, 1.99, 8.68]]}, {"timestamp": 1578726689947, "ltp": 1.96, "tv": 9225.55, "trd": [[1.96, 370.07]], "batb": [[0, 1.95, 29.25], [1, 1.94, 52.41], [2, 1.93, 50.45]], "batl": [[0, 1.96, 135.03], [1, 1.97, 3.77]]}, {"timestamp": 1578726690948, "ltp": 1.96, "tv": 9225.55, "trd": NaN, "batb": NaN, "batl": [[0, 1.96, 138.01], [1, 1.99, 8.68], [2, 2, 437.07]]}, {"timestamp": 1578726691879, "ltp": 1.96, "tv": 9225.55, "trd": NaN, "batb": NaN, "batl": [[0, 1.96, 135.03]]}, {"timestamp": 1578726729913, "ltp": 1.96, "tv": 9225.55, "trd": NaN, "batb": NaN, "batl": [[0, 1.96, 137.08]]}, {"timestamp": 1578726730896, "ltp": 1.96, "tv": 9225.55, "trd": NaN, "batb": NaN, "batl": [[0, 1.96, 137.2]]}, {"timestamp": 1578726731933, "ltp": 1.96, "tv": 9225.55, "trd": NaN, "batb": NaN, "batl": [[0, 1.96, 135.03]]}, {"timestamp": 1578726734727, "ltp": 1.96, "tv": 9225.55, "trd": NaN, "batb": NaN, "batl": [[1, 1.98, 3], [2, 1.99, 5.68]]}, {"timestamp": 1578726818941, "ltp": 1.96, "tv": 9251.89, "trd": [[1.96, 396.41]], "batb": [[0, 1.95, 55.64]], "batl": [[0, 1.96, 121.86]]}, {"timestamp": 1578726856997, "ltp": 1.96, "tv": 9251.89, "trd": NaN, "batb": NaN, "batl": [[1, 1.97, 3]]}, {"timestamp": 1578726894923, "ltp": 1.96, "tv": 9251.89, "trd": NaN, "batb": NaN, "batl": [[1, 1.99, 5.68], [2, 2, 437.07]]}, {"timestamp": 1578726895946, "ltp": 1.96, "tv": 9251.89, "trd": NaN, "batb": NaN, "batl": [[0, 1.96, 124.86]]}, {"timestamp": 1578726914950, "ltp": 1.96, "tv": 9251.89, "trd": NaN, "batb": [[0, 1.95, 74.19]], "batl": NaN}, {"timestamp": 1578726932910, "ltp": 1.96, "tv": 9251.89, "trd": NaN, "batb": NaN, "batl": [[0, 1.96, 121.86], [1, 1.98, 3], [2, 1.99, 5.68]]}, {"timestamp": 1578726945001, "ltp": 1.96, "tv": 9251.89, "trd": NaN, "batb": NaN, "batl": [[1, 1.99, 5.68], [2, 2, 437.07]]}, {"timestamp": 1578726945930, "ltp": 1.96, "tv": 9251.89, "trd": NaN, "batb": NaN, "batl": [[1, 1.97, 3], [2, 1.99, 5.68]]}, {"timestamp": 1578726982876, "ltp": 1.96, "tv": 9251.89, "trd": NaN, "batb": NaN, "batl": [[0, 1.96, 124.86], [1, 1.99, 5.68], [2, 2, 437.07]]}, {"timestamp": 1578726993883, "ltp": 1.96, "tv": 9251.89, "trd": NaN, "batb": NaN, "batl": [[1, 1.98, 20], [2, 1.99, 5.68]]}, {"timestamp": 1578727009000, "ltp": 1.96, "tv": 9251.89, "trd": NaN, "batb": NaN, "batl": [[0, 1.96, 121.86], [1, 1.97, 3], [2, 1.98, 20]]}, {"timestamp": 1578727045662, "ltp": 1.96, "tv": 9251.89, "trd": NaN, "batb": NaN, "batl": [[0, 1.96, 124.86], [1, 1.98, 20], [2, 1.99, 5.68]]}, {"timestamp": 1578727058887, "ltp": 1.96, "tv": 9251.89, "trd": NaN, "batb": NaN, "batl": [[0, 1.96, 121.86], [1, 1.97, 3], [2, 1.98, 20]]}, {"timestamp": 1578727066915, "ltp": 1.96, "tv": 9251.89, "trd": NaN, "batb": [[0, 1.95, 76.82]], "batl": NaN}, {"timestamp": 1578727068001, "ltp": 1.96, "tv": 9251.89, "trd": NaN, "batb": [[0, 1.95, 74.19]], "batl": NaN}, {"timestamp": 1578727068977, "ltp": 1.96, "tv": 9251.89, "trd": NaN, "batb": [[0, 1.95, 92.83]], "batl": NaN}, {"timestamp": 1578727069903, "ltp": 1.96, "tv": 9251.89, "trd": NaN, "batb": [[0, 1.95, 74.19]], "batl": [[0, 1.96, 127.59]]}, {"timestamp": 1578727071908, "ltp": 1.96, "tv": 9251.89, "trd": NaN, "batb": NaN, "batl": [[0, 1.96, 131.06], [1, 1.98, 20], [2, 1.99, 5.68]]}, {"timestamp": 1578727072995, "ltp": 1.96, "tv": 9251.89, "trd": NaN, "batb": NaN, "batl": [[0, 1.96, 131.87]]}, {"timestamp": 1578727073917, "ltp": 1.96, "tv": 9251.89, "trd": NaN, "batb": NaN, "batl": [[0, 1.96, 132.28]]}, {"timestamp": 1578727075003, "ltp": 1.96, "tv": 9251.89, "trd": NaN, "batb": NaN, "batl": [[0, 1.96, 132.72]]}, {"timestamp": 1578727076913, "ltp": 1.95, "tv": 9259.89, "trd": [[1.95, 420.54]], "batb": [[0, 1.95, 70.19]], "batl": NaN}, {"timestamp": 1578727080933, "ltp": 1.95, "tv": 9259.89, "trd": NaN, "batb": NaN, "batl": [[0, 1.96, 133.26]]}, {"timestamp": 1578727086919, "ltp": 1.95, "tv": 9259.89, "trd": NaN, "batb": NaN, "batl": [[0, 1.96, 133.7]]}, {"timestamp": 1578727089949, "ltp": 1.95, "tv": 9259.89, "trd": NaN, "batb": NaN, "batl": [[0, 1.96, 133.26]]}, {"timestamp": 1578727091852, "ltp": 1.95, "tv": 9259.89, "trd": NaN, "batb": NaN, "batl": [[0, 1.96, 132.84]]}, {"timestamp": 1578727095923, "ltp": 1.95, "tv": 9259.89, "trd": NaN, "batb": NaN, "batl": [[0, 1.96, 132.45]]}, {"timestamp": 1578727096947, "ltp": 1.95, "tv": 9259.89, "trd": NaN, "batb": NaN, "batl": [[0, 1.96, 129.45]]}, {"timestamp": 1578727097725, "ltp": 1.95, "tv": 9259.89, "trd": NaN, "batb": NaN, "batl": [[1, 1.97, 3], [2, 1.98, 20]]}, {"timestamp": 1578727099942, "ltp": 1.95, "tv": 9259.89, "trd": NaN, "batb": NaN, "batl": [[0, 1.96, 121.86]]}, {"timestamp": 1578727100964, "ltp": 1.95, "tv": 9259.89, "trd": NaN, "batb": NaN, "batl": [[0, 1.96, 130.11]]}, {"timestamp": 1578727105956, "ltp": 1.95, "tv": 9259.89, "trd": NaN, "batb": NaN, "batl": [[0, 1.96, 121.86], [1, 1.97, 11.07]]}, {"timestamp": 1578727106840, "ltp": 1.95, "tv": 9259.89, "trd": NaN, "batb": NaN, "batl": [[0, 1.96, 129.91], [1, 1.97, 3]]}, {"timestamp": 1578727109975, "ltp": 1.95, "tv": 9259.89, "trd": NaN, "batb": NaN, "batl": [[0, 1.96, 132.51], [1, 1.98, 20], [2, 1.99, 5.68]]}, {"timestamp": 1578727112766, "ltp": 1.95, "tv": 9259.89, "trd": NaN, "batb": NaN, "batl": [[0, 1.96, 132.11]]}, {"timestamp": 1578727117975, "ltp": 1.95, "tv": 9259.89, "trd": NaN, "batb": NaN, "batl": [[0, 1.96, 132.81]]}, {"timestamp": 1578727121953, "ltp": 1.95, "tv": 9259.89, "trd": NaN, "batb": NaN, "batl": [[0, 1.96, 124.86]]}, {"timestamp": 1578727122981, "ltp": 1.95, "tv": 9259.89, "trd": NaN, "batb": NaN, "batl": [[0, 1.96, 132.45]]}, {"timestamp": 1578727128969, "ltp": 1.95, "tv": 9259.89, "trd": NaN, "batb": NaN, "batl": [[0, 1.96, 132.56]]}, {"timestamp": 1578727134934, "ltp": 1.95, "tv": 9259.89, "trd": NaN, "batb": NaN, "batl": [[0, 1.96, 129.47], [1, 1.97, 3], [2, 1.98, 20]]}, {"timestamp": 1578727141949, "ltp": 1.95, "tv": 9259.89, "trd": NaN, "batb": NaN, "batl": [[0, 1.96, 129.09]]}, {"timestamp": 1578727146958, "ltp": 1.95, "tv": 9259.89, "trd": NaN, "batb": NaN, "batl": [[0, 1.96, 128.72]]}, {"timestamp": 1578727148866, "ltp": 1.95, "tv": 9259.89, "trd": NaN, "batb": NaN, "batl": [[0, 1.96, 129.26]]}, {"timestamp": 1578727149952, "ltp": 1.95, "tv": 9259.89, "trd": NaN, "batb": NaN, "batl": [[0, 1.96, 129.86]]}, {"timestamp": 1578727150976, "ltp": 1.95, "tv": 9259.89, "trd": NaN, "batb": NaN, "batl": [[0, 1.96, 130.41], [1, 1.97, 6.48]]}, {"timestamp": 1578727151853, "ltp": 1.95, "tv": 9259.89, "trd": NaN, "batb": NaN, "batl": [[0, 1.96, 121.86]]}, {"timestamp": 1578727160996, "ltp": 1.96, "tv": 9265.89, "trd": [[1.96, 402.41]], "batb": NaN, "batl": [[0, 1.96, 118.86]]}, {"timestamp": 1578727176936, "ltp": 1.96, "tv": 9269.89, "trd": [[1.96, 406.41]], "batb": NaN, "batl": [[0, 1.96, 116.86]]}, {"timestamp": 1578727178902, "ltp": 1.96, "tv": 9277.89, "trd": [[1.96, 414.41]], "batb": NaN, "batl": [[0, 1.96, 112.86]]}, {"timestamp": 1578727180704, "ltp": 1.96, "tv": 9281.89, "trd": [[1.96, 418.41]], "batb": NaN, "batl": [[0, 1.96, 110.86]]}, {"timestamp": 1578727182003, "ltp": 1.96, "tv": 9289.89, "trd": [[1.96, 426.41]], "batb": NaN, "batl": [[0, 1.96, 106.86]]}, {"timestamp": 1578727183913, "ltp": 1.96, "tv": 9293.89, "trd": [[1.96, 430.41]], "batb": NaN, "batl": [[0, 1.96, 104.86]]}, {"timestamp": 1578727185001, "ltp": 1.96, "tv": 9296.81, "trd": [[1.96, 433.33]], "batb": NaN, "batl": [[0, 1.96, 103.4]]}, {"timestamp": 1578727185929, "ltp": 1.96, "tv": 9300.81, "trd": [[1.96, 437.33]], "batb": NaN, "batl": [[0, 1.96, 101.4]]}, {"timestamp": 1578727187944, "ltp": 1.96, "tv": 9304.81, "trd": [[1.96, 441.33]], "batb": NaN, "batl": [[0, 1.96, 99.4]]}, {"timestamp": 1578727188922, "ltp": 1.96, "tv": 9308.81, "trd": [[1.96, 445.33]], "batb": NaN, "batl": [[0, 1.96, 97.4]]}, {"timestamp": 1578727189907, "ltp": 1.96, "tv": 9312.81, "trd": [[1.96, 449.33]], "batb": NaN, "batl": [[0, 1.96, 95.4]]}, {"timestamp": 1578727191002, "ltp": 1.96, "tv": 9320.81, "trd": [[1.96, 457.33]], "batb": NaN, "batl": [[0, 1.96, 91.4]]}, {"timestamp": 1578727192920, "ltp": 1.96, "tv": 9321.55, "trd": [[1.96, 458.07]], "batb": NaN, "batl": [[0, 1.96, 91.03]]}, {"timestamp": 1578727194632, "ltp": 1.96, "tv": 9325.55, "trd": [[1.96, 462.07]], "batb": NaN, "batl": [[0, 1.96, 89.03]]}, {"timestamp": 1578727195611, "ltp": 1.96, "tv": 9329.55, "trd": [[1.96, 466.07]], "batb": NaN, "batl": [[0, 1.96, 87.03]]}, {"timestamp": 1578727196957, "ltp": 1.96, "tv": 9333.55, "trd": [[1.96, 470.07]], "batb": NaN, "batl": [[0, 1.96, 85.03]]}, {"timestamp": 1578727197942, "ltp": 1.96, "tv": 9337.55, "trd": [[1.96, 474.07]], "batb": NaN, "batl": [[0, 1.96, 83.03]]}, {"timestamp": 1578727198927, "ltp": 1.96, "tv": 9341.55, "trd": [[1.96, 478.07]], "batb": NaN, "batl": [[0, 1.96, 84.03], [1, 1.97, 3.48]]}, {"timestamp": 1578727199909, "ltp": 1.96, "tv": 9345.55, "trd": [[1.96, 482.07]], "batb": NaN, "batl": [[0, 1.96, 82.03]]}, {"timestamp": 1578727201932, "ltp": 1.96, "tv": 9346.29, "trd": [[1.96, 482.81]], "batb": NaN, "batl": [[0, 1.96, 81.66]]}, {"timestamp": 1578727202919, "ltp": 1.96, "tv": 9350.29, "trd": [[1.96, 486.81]], "batb": NaN, "batl": [[0, 1.96, 79.66]]}, {"timestamp": 1578727203640, "ltp": 1.96, "tv": 9354.29, "trd": [[1.96, 490.81]], "batb": NaN, "batl": [[0, 1.96, 77.66]]}, {"timestamp": 1578727204933, "ltp": 1.96, "tv": 9358.29, "trd": [[1.96, 494.81]], "batb": NaN, "batl": [[0, 1.96, 75.66]]}, {"timestamp": 1578727205969, "ltp": 1.96, "tv": 9509.61, "trd": [[1.96, 646.13]], "batb": [[0, 1.95, 70.2]], "batl": [[0, 1.97, 3.48], [1, 1.98, 20], [2, 1.99, 5.68]]}, {"timestamp": 1578727206956, "ltp": 1.96, "tv": 9509.61, "trd": NaN, "batb": [[0, 1.96, 1.43], [1, 1.95, 70.19], [2, 1.94, 52.41]], "batl": NaN}, {"timestamp": 1578727207931, "ltp": 1.96, "tv": 9512.46, "trd": [[1.96, 648.99]], "batb": [[0, 1.95, 70.19], [1, 1.94, 52.41], [2, 1.93, 50.45]], "batl": [[0, 1.96, 4.96], [1, 1.97, 3.48], [2, 1.98, 20]]}, {"timestamp": 1578727208856, "ltp": 1.96, "tv": 9512.46, "trd": NaN, "batb": NaN, "batl": [[0, 1.96, 5.42]]}, {"timestamp": 1578727210869, "ltp": 1.96, "tv": 9512.46, "trd": NaN, "batb": NaN, "batl": [[0, 1.96, 5.75]]}, {"timestamp": 1578727211951, "ltp": 1.96, "tv": 9512.46, "trd": NaN, "batb": NaN, "batl": [[0, 1.97, 5.48], [1, 1.98, 20], [2, 1.99, 5.68]]}, {"timestamp": 1578727212930, "ltp": 1.96, "tv": 9512.46, "trd": NaN, "batb": NaN, "batl": [[0, 1.96, 6.72], [1, 1.97, 5.48], [2, 1.98, 20]]}, {"timestamp": 1578727214949, "ltp": 1.96, "tv": 9512.46, "trd": NaN, "batb": NaN, "batl": [[0, 1.96, 7.09]]}, {"timestamp": 1578727215938, "ltp": 1.96, "tv": 9512.46, "trd": NaN, "batb": NaN, "batl": [[0, 1.96, 7.51]]}, {"timestamp": 1578727218940, "ltp": 1.96, "tv": 9512.46, "trd": NaN, "batb": NaN, "batl": [[0, 1.96, 7.71]]}, {"timestamp": 1578727219970, "ltp": 1.96, "tv": 9516.46, "trd": [[1.96, 652.99]], "batb": NaN, "batl": [[0, 1.96, 5.71]]}, {"timestamp": 1578727220956, "ltp": 1.96, "tv": 9520.46, "trd": [[1.96, 656.99]], "batb": NaN, "batl": [[0, 1.96, 2.07], [1, 1.97, 9.24]]}, {"timestamp": 1578727221945, "ltp": 1.96, "tv": 9520.46, "trd": NaN, "batb": NaN, "batl": [[0, 1.97, 9.24], [1, 1.98, 20], [2, 1.99, 5.68]]}, {"timestamp": 1578727222985, "ltp": 1.96, "tv": 9520.46, "trd": NaN, "batb": [[0, 1.96, 1.94], [1, 1.95, 70.19], [2, 1.94, 52.41]], "batl": [[1, 1.98, 24.66]]}, {"timestamp": 1578727223972, "ltp": 1.96, "tv": 9520.46, "trd": NaN, "batb": [[0, 1.96, 12.52]], "batl": [[0, 1.97, 5.76]]}, {"timestamp": 1578727224953, "ltp": 1.96, "tv": 9528.46, "trd": [[1.96, 664.99]], "batb": [[0, 1.96, 8.52]], "batl": [[0, 1.97, 3.76]]}, {"timestamp": 1578727225946, "ltp": 1.96, "tv": 9528.46, "trd": NaN, "batb": [[0, 1.96, 8.66]], "batl": NaN}, {"timestamp": 1578727227967, "ltp": 1.96, "tv": 9528.46, "trd": NaN, "batb": [[0, 1.96, 16.26]], "batl": NaN}, {"timestamp": 1578727228844, "ltp": 1.96, "tv": 9528.46, "trd": NaN, "batb": [[0, 1.96, 43.94], [2, 1.94, 24.45]], "batl": [[1, 1.98, 20]]}, {"timestamp": 1578727229977, "ltp": 1.96, "tv": 9528.46, "trd": NaN, "batb": [[0, 1.96, 43.98]], "batl": [[0, 1.98, 24.56], [1, 1.99, 5.68], [2, 2, 457.07]]}, {"timestamp": 1578727230968, "ltp": 1.96, "tv": 9528.46, "trd": NaN, "batb": [[0, 1.96, 27.68]], "batl": [[1, 1.99, 18.66]]}, {"timestamp": 1578727232937, "ltp": 1.96, "tv": 9528.46, "trd": NaN, "batb": [[0, 1.97, 16.33], [1, 1.96, 27.68], [2, 1.95, 70.19]], "batl": NaN}, {"timestamp": 1578727233966, "ltp": 1.96, "tv": 9528.46, "trd": NaN, "batb": [[0, 1.97, 17.51]], "batl": NaN}, {"timestamp": 1578727234943, "ltp": 1.96, "tv": 9528.46, "trd": NaN, "batb": [[0, 1.96, 27.68], [1, 1.95, 70.19], [2, 1.94, 24.45]], "batl": [[0, 1.98, 20], [1, 1.99, 23.06]]}, {"timestamp": 1578727235972, "ltp": 1.96, "tv": 9528.46, "trd": NaN, "batb": [[0, 1.97, 16.37], [1, 1.96, 27.68], [2, 1.95, 70.19]], "batl": NaN}, {"timestamp": 1578727236953, "ltp": 1.96, "tv": 9528.46, "trd": NaN, "batb": [[0, 1.97, 16.4]], "batl": [[0, 1.98, 23]]}, {"timestamp": 1578727237984, "ltp": 1.96, "tv": 9528.46, "trd": NaN, "batb": [[0, 1.96, 8.99], [1, 1.95, 70.19], [2, 1.94, 24.45]], "batl": NaN}, {"timestamp": 1578727238965, "ltp": 1.96, "tv": 9528.46, "trd": NaN, "batb": [[0, 1.97, 17.51], [1, 1.96, 8.99], [2, 1.95, 70.19]], "batl": NaN}, {"timestamp": 1578727239942, "ltp": 1.96, "tv": 9528.46, "trd": NaN, "batb": [[0, 1.97, 16.51]], "batl": NaN}, {"timestamp": 1578727241955, "ltp": 1.96, "tv": 9528.46, "trd": NaN, "batb": [[0, 1.97, 16.57]], "batl": NaN}, {"timestamp": 1578727244985, "ltp": 1.96, "tv": 9528.46, "trd": NaN, "batb": [[0, 1.97, 16.65]], "batl": NaN}, {"timestamp": 1578727245966, "ltp": 1.96, "tv": 9528.46, "trd": NaN, "batb": [[0, 1.96, 16.76], [1, 1.95, 79.22], [2, 1.94, 24.45]], "batl": NaN}, {"timestamp": 1578727252976, "ltp": 1.96, "tv": 9528.46, "trd": NaN, "batb": NaN, "batl": [[1, 1.99, 18.66]]}, {"timestamp": 1578727253956, "ltp": 1.96, "tv": 9528.46, "trd": NaN, "batb": NaN, "batl": [[0, 1.98, 25.14]]}, {"timestamp": 1578727255967, "ltp": 1.96, "tv": 9528.46, "trd": NaN, "batb": NaN, "batl": [[1, 1.99, 21.12]]}, {"timestamp": 1578727259991, "ltp": 1.96, "tv": 9528.46, "trd": NaN, "batb": NaN, "batl": [[1, 1.99, 18.66]]}, {"timestamp": 1578727260976, "ltp": 1.98, "tv": 9543.12, "trd": [[1.98, 354.17]], "batb": NaN, "batl": [[0, 1.98, 17.81]]}, {"timestamp": 1578727261958, "ltp": 1.98, "tv": 9543.12, "trd": NaN, "batb": NaN, "batl": [[0, 1.98, 15.67]]}, {"timestamp": 1578727262990, "ltp": 1.98, "tv": 9543.12, "trd": NaN, "batb": NaN, "batl": [[1, 1.99, 20.82]]}, {"timestamp": 1578727286989, "ltp": 1.98, "tv": 9543.12, "trd": NaN, "batb": [[0, 1.96, 35.45]], "batl": NaN}, {"timestamp": 1578727287916, "ltp": 1.98, "tv": 9543.12, "trd": NaN, "batb": [[0, 1.97, 17.06], [1, 1.96, 18.69], [2, 1.95, 79.22]], "batl": NaN}, {"timestamp": 1578727292002, "ltp": 1.98, "tv": 9543.12, "trd": NaN, "batb": NaN, "batl": [[1, 1.99, 18.66]]}, {"timestamp": 1578727305928, "ltp": 1.98, "tv": 9543.12, "trd": NaN, "batb": [[0, 1.97, 25.57]], "batl": NaN}, {"timestamp": 1578727335976, "ltp": 1.98, "tv": 9558.44, "trd": [[1.98, 369.48]], "batb": NaN, "batl": [[0, 1.98, 8.01]]}, {"timestamp": 1578727336908, "ltp": 1.98, "tv": 9566.1, "trd": [[1.98, 377.14]], "batb": NaN, "batl": [[0, 1.98, 4.18]]}, {"timestamp": 1578727338917, "ltp": 1.98, "tv": 9573.76, "trd": [[1.98, 384.8]], "batb": NaN, "batl": [[0, 1.99, 19.01], [1, 2, 457.07], [2, 2.06, 10]]}, {"timestamp": 1578727341911, "ltp": 1.98, "tv": 9573.76, "trd": NaN, "batb": [[0, 1.97, 17.06]], "batl": NaN}, {"timestamp": 1578727346002, "ltp": 1.98, "tv": 9573.76, "trd": NaN, "batb": [[0, 1.97, 32.37], [1, 1.96, 34]], "batl": NaN}, {"timestamp": 1578727346979, "ltp": 1.98, "tv": 9574.46, "trd": [[1.98, 385.5]], "batb": [[0, 1.98, 17.06], [1, 1.97, 15.31], [2, 1.96, 34]], "batl": [[0, 1.99, 18.66]]}, {"timestamp": 1578727351807, "ltp": 1.99, "tv": 9605.08, "trd": [[1.99, 855.94]], "batb": NaN, "batl": [[0, 1.99, 3.35]]}, {"timestamp": 1578727415991, "ltp": 1.99, "tv": 9605.08, "trd": NaN, "batb": NaN, "batl": [[0, 1.99, 5.35]]}, {"timestamp": 1578727450950, "ltp": 1.99, "tv": 9615.78, "trd": [[1.99, 866.64]], "batb": [[0, 1.99, 21.58]], "batl": [[0, 2, 457.07], [1, 2.06, 10], [2, 2.08, 73.67]]}, {"timestamp": 1578727452970, "ltp": 1.99, "tv": 9615.78, "trd": NaN, "batb": [[0, 1.99, 4.65], [1, 1.98, 17.02], [2, 1.97, 15.31]], "batl": NaN}, {"timestamp": 1578727454936, "ltp": 1.99, "tv": 9619.78, "trd": [[1.99, 870.64]], "batb": [[0, 1.99, 19.58], [1, 1.97, 15.31], [2, 1.96, 34]], "batl": NaN}, {"timestamp": 1578727456957, "ltp": 1.99, "tv": 9619.78, "trd": NaN, "batb": [[1, 1.97, 22.38]], "batl": NaN}, {"timestamp": 1578727466773, "ltp": 1.99, "tv": 9619.78, "trd": NaN, "batb": NaN, "batl": [[1, 2.04, 2], [2, 2.06, 10]]}, {"timestamp": 1578727477969, "ltp": 1.99, "tv": 9619.78, "trd": NaN, "batb": NaN, "batl": [[1, 2.04, 15]]}, {"timestamp": 1578727483790, "ltp": 1.99, "tv": 9619.78, "trd": NaN, "batb": NaN, "batl": [[1, 2.04, 115]]}, {"timestamp": 1578727490998, "ltp": 1.99, "tv": 9619.78, "trd": NaN, "batb": NaN, "batl": [[2, 2.06, 110]]}, {"timestamp": 1578727517972, "ltp": 1.99, "tv": 9619.78, "trd": NaN, "batb": NaN, "batl": [[1, 2.02, 2], [2, 2.04, 113]]}, {"timestamp": 1578727531949, "ltp": 1.99, "tv": 9634.48, "trd": [[1.99, 885.34]], "batb": [[0, 1.99, 9.58]], "batl": NaN}, {"timestamp": 1578727532981, "ltp": 1.99, "tv": 9634.48, "trd": NaN, "batb": [[0, 1.98, 9.9]], "batl": NaN}, {"timestamp": 1578727533859, "ltp": 1.99, "tv": 9634.48, "trd": NaN, "batb": [[1, 1.97, 15.31]], "batl": NaN}, {"timestamp": 1578727546976, "ltp": 1.99, "tv": 9634.48, "trd": NaN, "batb": NaN, "batl": [[0, 1.99, 10], [1, 2, 457.07], [2, 2.02, 2]]}, {"timestamp": 1578727553973, "ltp": 2.0, "tv": 9834.48, "trd": [[1.99, 905.34], [2, 1551.55]], "batb": NaN, "batl": [[0, 2, 367.07], [1, 2.02, 2], [2, 2.04, 113]]}, {"timestamp": 1578727556809, "ltp": 2.0, "tv": 9834.48, "trd": NaN, "batb": NaN, "batl": [[0, 1.99, 2], [1, 2, 367.07]]}, {"timestamp": 1578727566911, "ltp": 2.0, "tv": 9834.48, "trd": NaN, "batb": NaN, "batl": [[2, 2.04, 100]]}, {"timestamp": 1578727623994, "ltp": 2.0, "tv": 9834.48, "trd": NaN, "batb": [[2, 1.96, 44.3]], "batl": NaN}, {"timestamp": 1578727746993, "ltp": 1.99, "tv": 9838.48, "trd": [[1.99, 909.34]], "batb": [[0, 1.99, 3], [1, 1.98, 9.9], [2, 1.97, 15.31]], "batl": [[0, 2, 367.07], [1, 2.04, 100], [2, 2.06, 100]]}, {"timestamp": 1578727747875, "ltp": 1.99, "tv": 9838.48, "trd": NaN, "batb": [[1, 1.98, 9.74]], "batl": NaN}, {"timestamp": 1578727748967, "ltp": 1.99, "tv": 9838.48, "trd": NaN, "batb": [[1, 1.97, 15.31], [2, 1.96, 44.3]], "batl": NaN}, {"timestamp": 1578727749898, "ltp": 1.99, "tv": 9838.48, "trd": NaN, "batb": [[0, 1.99, 12.71]], "batl": NaN}, {"timestamp": 1578727750978, "ltp": 1.99, "tv": 9838.48, "trd": NaN, "batb": [[0, 1.99, 3], [1, 1.98, 9.75], [2, 1.97, 15.31]], "batl": NaN}, {"timestamp": 1578727751873, "ltp": 1.99, "tv": 9838.48, "trd": NaN, "batb": [[0, 1.99, 12.7], [1, 1.97, 15.31], [2, 1.96, 44.3]], "batl": NaN}, {"timestamp": 1578727753001, "ltp": 1.99, "tv": 9838.48, "trd": NaN, "batb": [[0, 1.99, 3], [1, 1.98, 9.74], [2, 1.97, 15.31]], "batl": NaN}, {"timestamp": 1578727753999, "ltp": 1.99, "tv": 9838.48, "trd": NaN, "batb": [[0, 1.99, 12.68], [1, 1.97, 15.31], [2, 1.96, 44.3]], "batl": NaN}, {"timestamp": 1578727754985, "ltp": 1.99, "tv": 9838.48, "trd": NaN, "batb": [[0, 1.99, 3]], "batl": NaN}, {"timestamp": 1578727755861, "ltp": 1.99, "tv": 9838.48, "trd": NaN, "batb": [[1, 1.98, 9.65], [2, 1.97, 15.31]], "batl": NaN}, {"timestamp": 1578727757000, "ltp": 1.99, "tv": 9838.48, "trd": NaN, "batb": [[0, 1.99, 12.6], [1, 1.97, 15.31], [2, 1.96, 44.3]], "batl": NaN}, {"timestamp": 1578727757981, "ltp": 1.99, "tv": 9838.48, "trd": NaN, "batb": [[0, 1.99, 3], [1, 1.98, 9.66], [2, 1.97, 15.31]], "batl": NaN}, {"timestamp": 1578727759905, "ltp": 1.99, "tv": 9838.48, "trd": NaN, "batb": [[1, 1.97, 15.31], [2, 1.96, 44.3]], "batl": NaN}, {"timestamp": 1578727760997, "ltp": 1.99, "tv": 9838.48, "trd": NaN, "batb": [[0, 1.99, 12.61]], "batl": NaN}, {"timestamp": 1578727761980, "ltp": 1.99, "tv": 9838.48, "trd": NaN, "batb": [[0, 1.99, 12.62]], "batl": NaN}, {"timestamp": 1578727762907, "ltp": 1.99, "tv": 9838.48, "trd": NaN, "batb": [[0, 1.99, 12.63]], "batl": NaN}, {"timestamp": 1578727763991, "ltp": 2.0, "tv": 9849.72, "trd": [[2, 1562.79]], "batb": [[0, 1.99, 3]], "batl": [[0, 2, 361.45]]}, {"timestamp": 1578727764980, "ltp": 2.0, "tv": 9849.72, "trd": NaN, "batb": [[1, 1.98, 9.69], [2, 1.97, 15.31]], "batl": NaN}, {"timestamp": 1578727765802, "ltp": 2.0, "tv": 9849.72, "trd": NaN, "batb": [[1, 1.98, 9.7]], "batl": NaN}, {"timestamp": 1578727766992, "ltp": 2.0, "tv": 9849.72, "trd": NaN, "batb": [[1, 1.97, 15.31], [2, 1.96, 44.3]], "batl": NaN}, {"timestamp": 1578727767913, "ltp": 2.0, "tv": 9855.72, "trd": [[2, 1568.79]], "batb": [[0, 1.99, 12.65]], "batl": [[0, 2, 358.45]]}, {"timestamp": 1578727772003, "ltp": 2.0, "tv": 9855.72, "trd": NaN, "batb": [[0, 1.99, 3], [1, 1.98, 9.81], [2, 1.97, 15.31]], "batl": NaN}, {"timestamp": 1578727772905, "ltp": 2.0, "tv": 9855.72, "trd": NaN, "batb": [[1, 1.97, 15.31], [2, 1.96, 44.3]], "batl": NaN}, {"timestamp": 1578727773829, "ltp": 2.0, "tv": 9855.72, "trd": NaN, "batb": [[0, 1.99, 12.77]], "batl": NaN}, {"timestamp": 1578727774915, "ltp": 2.0, "tv": 9855.72, "trd": NaN, "batb": [[0, 1.99, 3]], "batl": NaN}, {"timestamp": 1578727775693, "ltp": 2.0, "tv": 9855.72, "trd": NaN, "batb": [[1, 1.98, 9.77], [2, 1.97, 15.31]], "batl": NaN}, {"timestamp": 1578727776936, "ltp": 2.0, "tv": 9855.72, "trd": NaN, "batb": [[1, 1.97, 15.31], [2, 1.96, 44.3]], "batl": NaN}, {"timestamp": 1578727778802, "ltp": 2.0, "tv": 9855.72, "trd": NaN, "batb": [[0, 1.99, 12.68]], "batl": NaN}, {"timestamp": 1578727779938, "ltp": 2.0, "tv": 9855.72, "trd": NaN, "batb": [[0, 1.99, 3], [1, 1.98, 9.73], [2, 1.97, 15.31]], "batl": NaN}, {"timestamp": 1578727781909, "ltp": 2.0, "tv": 9855.72, "trd": NaN, "batb": [[0, 1.99, 12.67], [1, 1.97, 15.31], [2, 1.96, 44.3]], "batl": NaN}, {"timestamp": 1578727782830, "ltp": 2.0, "tv": 9855.72, "trd": NaN, "batb": [[0, 1.99, 3], [1, 1.98, 9.71], [2, 1.97, 15.31]], "batl": NaN}, {"timestamp": 1578727783918, "ltp": 2.0, "tv": 9855.72, "trd": NaN, "batb": [[0, 1.99, 12.67], [1, 1.97, 15.31], [2, 1.96, 44.3]], "batl": NaN}, {"timestamp": 1578727786913, "ltp": 2.0, "tv": 9855.72, "trd": NaN, "batb": [[0, 1.99, 3], [1, 1.98, 9.71], [2, 1.97, 15.31]], "batl": NaN}, {"timestamp": 1578727787742, "ltp": 2.0, "tv": 9855.72, "trd": NaN, "batb": NaN, "batl": [[1, 2.02, 2], [2, 2.04, 100]]}, {"timestamp": 1578727788832, "ltp": 2.0, "tv": 9855.72, "trd": NaN, "batb": [[0, 1.99, 12.66], [1, 1.97, 15.31], [2, 1.96, 44.3]], "batl": NaN}, {"timestamp": 1578727789921, "ltp": 2.0, "tv": 9855.72, "trd": NaN, "batb": [[0, 1.99, 3], [1, 1.98, 9.71], [2, 1.97, 15.31]], "batl": NaN}, {"timestamp": 1578727791727, "ltp": 2.0, "tv": 9855.72, "trd": NaN, "batb": NaN, "batl": [[1, 2.02, 14.52]]}, {"timestamp": 1578727792955, "ltp": 2.0, "tv": 9855.72, "trd": NaN, "batb": [[0, 1.99, 12.65], [1, 1.97, 15.31], [2, 1.96, 44.3]], "batl": NaN}, {"timestamp": 1578727793941, "ltp": 2.0, "tv": 9855.72, "trd": NaN, "batb": [[0, 1.99, 3], [1, 1.98, 9.71], [2, 1.97, 15.31]], "batl": NaN}, {"timestamp": 1578727794765, "ltp": 2.0, "tv": 9855.72, "trd": NaN, "batb": [[0, 1.99, 12.66], [1, 1.97, 15.31], [2, 1.96, 44.3]], "batl": NaN}, {"timestamp": 1578727795924, "ltp": 2.0, "tv": 9855.72, "trd": NaN, "batb": [[0, 1.99, 3], [1, 1.98, 9.75], [2, 1.97, 15.31]], "batl": NaN}, {"timestamp": 1578727796951, "ltp": 2.0, "tv": 9855.72, "trd": NaN, "batb": [[1, 1.97, 15.31], [2, 1.96, 44.3]], "batl": NaN}, {"timestamp": 1578727797936, "ltp": 2.0, "tv": 9855.72, "trd": NaN, "batb": [[0, 1.99, 12.77]], "batl": NaN}, {"timestamp": 1578727798968, "ltp": 2.0, "tv": 9855.72, "trd": NaN, "batb": [[0, 1.99, 3]], "batl": NaN}, {"timestamp": 1578727799947, "ltp": 2.0, "tv": 9855.72, "trd": NaN, "batb": [[0, 1.99, 12.71]], "batl": NaN}, {"timestamp": 1578727800938, "ltp": 2.0, "tv": 9855.72, "trd": NaN, "batb": [[0, 1.99, 3], [1, 1.98, 9.73], [2, 1.97, 15.31]], "batl": NaN}, {"timestamp": 1578727801929, "ltp": 2.0, "tv": 9855.72, "trd": NaN, "batb": [[0, 1.99, 12.68], [1, 1.97, 15.31], [2, 1.96, 44.3]], "batl": NaN}, {"timestamp": 1578727802761, "ltp": 2.0, "tv": 9855.72, "trd": NaN, "batb": [[0, 1.99, 12.67]], "batl": NaN}, {"timestamp": 1578727803948, "ltp": 2.0, "tv": 9855.72, "trd": NaN, "batb": [[0, 1.99, 3], [1, 1.98, 9.74], [2, 1.97, 15.31]], "batl": NaN}, {"timestamp": 1578727805973, "ltp": 2.0, "tv": 9855.72, "trd": NaN, "batb": [[0, 1.99, 12.7], [1, 1.97, 15.31], [2, 1.96, 44.3]], "batl": NaN}, {"timestamp": 1578727806955, "ltp": 2.0, "tv": 9855.72, "trd": NaN, "batb": [[0, 1.99, 12.71]], "batl": NaN}, {"timestamp": 1578727807943, "ltp": 2.0, "tv": 9855.72, "trd": NaN, "batb": [[0, 1.99, 12.72]], "batl": NaN}, {"timestamp": 1578727808976, "ltp": 2.0, "tv": 9855.72, "trd": NaN, "batb": [[0, 1.99, 3], [1, 1.98, 9.78], [2, 1.97, 15.31]], "batl": NaN}, {"timestamp": 1578727809970, "ltp": 2.0, "tv": 9855.72, "trd": NaN, "batb": [[1, 1.97, 15.31], [2, 1.96, 44.3]], "batl": NaN}, {"timestamp": 1578727810770, "ltp": 2.0, "tv": 9855.72, "trd": NaN, "batb": [[0, 1.99, 12.74]], "batl": NaN}, {"timestamp": 1578727811968, "ltp": 2.0, "tv": 9855.72, "trd": NaN, "batb": [[0, 1.99, 3], [1, 1.98, 9.78], [2, 1.97, 15.31]], "batl": NaN}, {"timestamp": 1578727812956, "ltp": 2.0, "tv": 9855.72, "trd": NaN, "batb": [[1, 1.97, 15.31], [2, 1.96, 44.3]], "batl": NaN}, {"timestamp": 1578727813982, "ltp": 2.0, "tv": 9855.72, "trd": NaN, "batb": [[0, 1.99, 12.73]], "batl": NaN}, {"timestamp": 1578727816973, "ltp": 2.0, "tv": 9855.72, "trd": NaN, "batb": [[0, 1.99, 3]], "batl": NaN}, {"timestamp": 1578727817971, "ltp": 2.0, "tv": 9855.72, "trd": NaN, "batb": [[0, 1.99, 12.72]], "batl": NaN}, {"timestamp": 1578727819001, "ltp": 2.0, "tv": 9855.72, "trd": NaN, "batb": [[0, 1.99, 3], [1, 1.98, 9.82], [2, 1.97, 15.31]], "batl": NaN}, {"timestamp": 1578727819884, "ltp": 2.0, "tv": 9855.72, "trd": NaN, "batb": [[0, 1.99, 12.84], [1, 1.97, 15.31], [2, 1.96, 44.3]], "batl": NaN}, {"timestamp": 1578727820967, "ltp": 2.0, "tv": 9855.72, "trd": NaN, "batb": [[0, 1.99, 3], [1, 1.98, 9.96], [2, 1.97, 15.31]], "batl": NaN}, {"timestamp": 1578727821795, "ltp": 2.0, "tv": 9855.72, "trd": NaN, "batb": [[1, 1.98, 9.98]], "batl": NaN}, {"timestamp": 1578727822984, "ltp": 2.0, "tv": 9855.72, "trd": NaN, "batb": [[0, 1.99, 12.94], [1, 1.97, 15.31], [2, 1.96, 44.3]], "batl": NaN}, {"timestamp": 1578727823969, "ltp": 2.0, "tv": 9855.72, "trd": NaN, "batb": [[0, 1.99, 3]], "batl": NaN}, {"timestamp": 1578727824797, "ltp": 2.0, "tv": 9855.72, "trd": NaN, "batb": [[1, 1.98, 9.99], [2, 1.97, 15.31]], "batl": NaN}, {"timestamp": 1578727825893, "ltp": 2.0, "tv": 9855.72, "trd": NaN, "batb": [[1, 1.98, 9.97]], "batl": NaN}, {"timestamp": 1578727826987, "ltp": 2.0, "tv": 9855.72, "trd": NaN, "batb": [[0, 1.99, 12.93], [1, 1.97, 15.31], [2, 1.96, 44.3]], "batl": NaN}, {"timestamp": 1578727827921, "ltp": 2.0, "tv": 9855.72, "trd": NaN, "batb": [[0, 1.99, 3], [1, 1.98, 9.98], [2, 1.97, 15.31]], "batl": NaN}, {"timestamp": 1578727828993, "ltp": 2.0, "tv": 9855.72, "trd": NaN, "batb": [[1, 1.97, 15.31], [2, 1.96, 44.3]], "batl": NaN}, {"timestamp": 1578727829984, "ltp": 2.0, "tv": 9855.72, "trd": NaN, "batb": [[0, 1.99, 12.93]], "batl": NaN}, {"timestamp": 1578727832000, "ltp": 2.0, "tv": 9855.72, "trd": NaN, "batb": [[0, 1.99, 3], [1, 1.98, 9.98], [2, 1.97, 15.31]], "batl": NaN}, {"timestamp": 1578727832989, "ltp": 2.0, "tv": 9855.72, "trd": NaN, "batb": [[0, 1.99, 12.93], [1, 1.97, 15.31], [2, 1.96, 44.3]], "batl": NaN}, {"timestamp": 1578727833923, "ltp": 2.0, "tv": 9855.72, "trd": NaN, "batb": [[0, 1.99, 12.91]], "batl": NaN}, {"timestamp": 1578727834954, "ltp": 2.0, "tv": 9855.72, "trd": NaN, "batb": [[0, 1.99, 3], [1, 1.98, 9.96], [2, 1.97, 15.31]], "batl": NaN}, {"timestamp": 1578727835939, "ltp": 2.0, "tv": 9855.72, "trd": NaN, "batb": [[0, 1.99, 12.92], [1, 1.97, 15.31], [2, 1.96, 44.3]], "batl": NaN}, {"timestamp": 1578727836922, "ltp": 2.0, "tv": 9855.72, "trd": NaN, "batb": [[0, 1.99, 3], [1, 1.98, 9.97], [2, 1.97, 15.31]], "batl": NaN}, {"timestamp": 1578727837963, "ltp": 2.0, "tv": 9855.72, "trd": NaN, "batb": [[1, 1.97, 15.31], [2, 1.96, 44.3]], "batl": NaN}, {"timestamp": 1578727839821, "ltp": 2.0, "tv": 9855.72, "trd": NaN, "batb": [[0, 1.99, 12.92]], "batl": NaN}, {"timestamp": 1578727840856, "ltp": 2.0, "tv": 9855.72, "trd": NaN, "batb": [[0, 1.99, 12.9]], "batl": NaN}, {"timestamp": 1578727841951, "ltp": 2.0, "tv": 9855.72, "trd": NaN, "batb": [[0, 1.99, 3], [1, 1.98, 9.96], [2, 1.97, 15.31]], "batl": NaN}, {"timestamp": 1578727842977, "ltp": 2.0, "tv": 9855.72, "trd": NaN, "batb": [[1, 1.97, 15.31], [2, 1.96, 44.3]], "batl": NaN}, {"timestamp": 1578727846762, "ltp": 2.0, "tv": 9855.72, "trd": NaN, "batb": [[1, 1.98, 9.97], [2, 1.97, 15.31]], "batl": NaN}, {"timestamp": 1578727847953, "ltp": 2.0, "tv": 9855.72, "trd": NaN, "batb": [[0, 1.99, 12.92], [1, 1.97, 15.31], [2, 1.96, 44.3]], "batl": NaN}, {"timestamp": 1578727849965, "ltp": 2.0, "tv": 9855.72, "trd": NaN, "batb": [[0, 1.99, 3]], "batl": NaN}, {"timestamp": 1578727850856, "ltp": 2.0, "tv": 9855.72, "trd": NaN, "batb": [[0, 1.99, 12.93]], "batl": NaN}, {"timestamp": 1578727851879, "ltp": 2.0, "tv": 9855.72, "trd": NaN, "batb": [[0, 1.99, 3], [1, 1.98, 9.98], [2, 1.97, 15.31]], "batl": NaN}, {"timestamp": 1578727852969, "ltp": 2.0, "tv": 9855.72, "trd": NaN, "batb": [[0, 1.99, 12.93], [1, 1.97, 15.31], [2, 1.96, 44.3]], "batl": NaN}, {"timestamp": 1578727854985, "ltp": 2.0, "tv": 9855.72, "trd": NaN, "batb": [[0, 1.99, 3], [1, 1.98, 9.98], [2, 1.97, 15.31]], "batl": NaN}, {"timestamp": 1578727855966, "ltp": 2.0, "tv": 9855.72, "trd": NaN, "batb": [[0, 1.99, 12.93], [1, 1.97, 15.31], [2, 1.96, 44.3]], "batl": NaN}, {"timestamp": 1578727856854, "ltp": 2.0, "tv": 9855.72, "trd": NaN, "batb": [[0, 1.99, 3], [1, 1.98, 9.98], [2, 1.97, 15.31]], "batl": NaN}, {"timestamp": 1578727857889, "ltp": 2.0, "tv": 9855.72, "trd": NaN, "batb": [[0, 1.99, 12.93], [1, 1.97, 15.31], [2, 1.96, 44.3]], "batl": NaN}, {"timestamp": 1578727858871, "ltp": 2.0, "tv": 9855.72, "trd": NaN, "batb": [[0, 1.99, 3], [1, 1.98, 9.98], [2, 1.97, 15.31]], "batl": NaN}, {"timestamp": 1578727861976, "ltp": 2.0, "tv": 9855.72, "trd": NaN, "batb": [[0, 1.99, 12.93], [1, 1.97, 15.31], [2, 1.96, 44.3]], "batl": NaN}, {"timestamp": 1578727862864, "ltp": 2.0, "tv": 9855.72, "trd": NaN, "batb": [[0, 1.99, 3]], "batl": NaN}, {"timestamp": 1578727863790, "ltp": 2.0, "tv": 9855.72, "trd": NaN, "batb": [[1, 1.98, 9.97], [2, 1.97, 15.31]], "batl": NaN}, {"timestamp": 1578727864359, "ltp": 2.0, "tv": 9855.72, "trd": NaN, "batb": [[0, 1.99, 12.92], [1, 1.97, 15.31], [2, 1.96, 44.3]], "batl": NaN}, {"timestamp": 1578727867001, "ltp": 2.0, "tv": 9855.72, "trd": NaN, "batb": [[0, 1.99, 3]], "batl": NaN}, {"timestamp": 1578727867986, "ltp": 2.0, "tv": 9855.72, "trd": NaN, "batb": [[1, 1.98, 9.96], [2, 1.97, 15.31]], "batl": NaN}, {"timestamp": 1578727868966, "ltp": 2.0, "tv": 9855.72, "trd": NaN, "batb": [[1, 1.97, 15.31], [2, 1.96, 44.3]], "batl": NaN}, {"timestamp": 1578727870879, "ltp": 2.0, "tv": 9855.72, "trd": NaN, "batb": [[0, 1.99, 12.93]], "batl": NaN}, {"timestamp": 1578727871981, "ltp": 2.0, "tv": 9855.72, "trd": NaN, "batb": [[0, 1.99, 3]], "batl": NaN}, {"timestamp": 1578727873885, "ltp": 2.0, "tv": 9855.72, "trd": NaN, "batb": [[0, 1.99, 12.93]], "batl": NaN}, {"timestamp": 1578727874914, "ltp": 2.0, "tv": 9855.72, "trd": NaN, "batb": [[0, 1.99, 3]], "batl": NaN}, {"timestamp": 1578727875907, "ltp": 2.0, "tv": 9859.72, "trd": [[2, 1572.79]], "batb": [[0, 1.99, 12.93]], "batl": [[0, 2, 356.45]]}, {"timestamp": 1578727876906, "ltp": 2.0, "tv": 9859.72, "trd": NaN, "batb": [[0, 1.99, 3]], "batl": NaN}, {"timestamp": 1578727877887, "ltp": 2.0, "tv": 9859.72, "trd": NaN, "batb": [[1, 1.98, 9.91], [2, 1.97, 15.31]], "batl": NaN}, {"timestamp": 1578727878978, "ltp": 2.0, "tv": 9859.72, "trd": NaN, "batb": [[0, 1.99, 12.82], [1, 1.97, 15.31], [2, 1.96, 44.3]], "batl": NaN}, {"timestamp": 1578727879905, "ltp": 2.0, "tv": 9859.72, "trd": NaN, "batb": [[0, 1.99, 3]], "batl": NaN}, {"timestamp": 1578727880997, "ltp": 2.0, "tv": 9859.72, "trd": NaN, "batb": [[0, 1.99, 12.8]], "batl": NaN}, {"timestamp": 1578727881606, "ltp": 2.0, "tv": 9859.72, "trd": NaN, "batb": [[0, 1.99, 12.81]], "batl": NaN}, {"timestamp": 1578727882894, "ltp": 2.0, "tv": 9859.72, "trd": NaN, "batb": [[0, 1.99, 12.84]], "batl": NaN}, {"timestamp": 1578727883925, "ltp": 2.0, "tv": 9859.72, "trd": NaN, "batb": [[0, 1.99, 3], [1, 1.98, 9.88], [2, 1.97, 15.31]], "batl": NaN}, {"timestamp": 1578727884905, "ltp": 2.0, "tv": 9859.72, "trd": NaN, "batb": [[1, 1.97, 15.31], [2, 1.96, 44.3]], "batl": NaN}, {"timestamp": 1578727885941, "ltp": 2.0, "tv": 9859.72, "trd": NaN, "batb": [[0, 1.99, 12.84]], "batl": NaN}, {"timestamp": 1578727886911, "ltp": 2.0, "tv": 9859.72, "trd": NaN, "batb": [[0, 1.99, 12.86]], "batl": NaN}, {"timestamp": 1578727887802, "ltp": 2.0, "tv": 9859.72, "trd": NaN, "batb": [[0, 1.99, 12.88]], "batl": NaN}, {"timestamp": 1578727888940, "ltp": 2.0, "tv": 9859.72, "trd": NaN, "batb": [[0, 1.99, 3]], "batl": NaN}, {"timestamp": 1578727891740, "ltp": 2.0, "tv": 9859.72, "trd": NaN, "batb": [[0, 1.99, 12.89]], "batl": NaN}, {"timestamp": 1578727892934, "ltp": 2.0, "tv": 9859.72, "trd": NaN, "batb": [[0, 1.99, 12.88]], "batl": NaN}, {"timestamp": 1578727893924, "ltp": 2.0, "tv": 9859.72, "trd": NaN, "batb": [[0, 1.99, 3], [1, 1.98, 9.92], [2, 1.97, 15.31]], "batl": NaN}, {"timestamp": 1578727894907, "ltp": 2.0, "tv": 9859.72, "trd": NaN, "batb": [[1, 1.97, 15.31], [2, 1.96, 44.3]], "batl": NaN}, {"timestamp": 1578727895748, "ltp": 2.0, "tv": 9859.72, "trd": NaN, "batb": [[1, 1.98, 9.93], [2, 1.97, 15.31]], "batl": NaN}, {"timestamp": 1578727896950, "ltp": 2.0, "tv": 9859.72, "trd": NaN, "batb": [[0, 1.99, 12.87], [1, 1.97, 15.31], [2, 1.96, 44.3]], "batl": NaN}, {"timestamp": 1578727897947, "ltp": 2.0, "tv": 9859.72, "trd": NaN, "batb": [[0, 1.99, 12.88]], "batl": NaN}, {"timestamp": 1578727899816, "ltp": 2.0, "tv": 9859.72, "trd": NaN, "batb": [[0, 1.99, 3], [1, 1.98, 9.93], [2, 1.97, 15.31]], "batl": NaN}, {"timestamp": 1578727900954, "ltp": 2.0, "tv": 9859.72, "trd": NaN, "batb": [[0, 1.99, 12.87], [1, 1.97, 15.31], [2, 1.96, 44.3]], "batl": NaN}, {"timestamp": 1578727902927, "ltp": 2.0, "tv": 9859.72, "trd": NaN, "batb": [[0, 1.99, 3]], "batl": NaN}, {"timestamp": 1578727904943, "ltp": 2.0, "tv": 9859.72, "trd": NaN, "batb": [[1, 1.98, 9.92], [2, 1.97, 15.31]], "batl": NaN}, {"timestamp": 1578727905934, "ltp": 2.0, "tv": 9859.72, "trd": NaN, "batb": [[1, 1.98, 9.93]], "batl": NaN}, {"timestamp": 1578727906965, "ltp": 2.0, "tv": 9859.72, "trd": NaN, "batb": [[0, 1.99, 12.88], [1, 1.97, 15.31], [2, 1.96, 44.3]], "batl": NaN}, {"timestamp": 1578727908929, "ltp": 2.0, "tv": 9859.72, "trd": NaN, "batb": [[0, 1.99, 12.87]], "batl": NaN}, {"timestamp": 1578727909967, "ltp": 2.0, "tv": 9859.72, "trd": NaN, "batb": [[0, 1.99, 3]], "batl": NaN}, {"timestamp": 1578727914972, "ltp": 2.0, "tv": 9859.72, "trd": NaN, "batb": [[1, 1.98, 9.93], [2, 1.97, 15.31]], "batl": NaN}, {"timestamp": 1578727915949, "ltp": 2.0, "tv": 9859.72, "trd": NaN, "batb": [[0, 1.99, 12.88], [1, 1.97, 15.31], [2, 1.96, 44.3]], "batl": NaN}, {"timestamp": 1578727916828, "ltp": 2.0, "tv": 9859.72, "trd": NaN, "batb": [[0, 1.99, 12.87]], "batl": NaN}, {"timestamp": 1578727917857, "ltp": 2.0, "tv": 9859.72, "trd": NaN, "batb": [[0, 1.99, 3], [1, 1.98, 9.92], [2, 1.97, 15.31]], "batl": NaN}, {"timestamp": 1578727919974, "ltp": 2.0, "tv": 9859.72, "trd": NaN, "batb": [[1, 1.97, 15.31], [2, 1.96, 44.3]], "batl": NaN}, {"timestamp": 1578727920753, "ltp": 2.0, "tv": 9859.72, "trd": NaN, "batb": [[1, 1.98, 10.02], [2, 1.97, 15.31]], "batl": NaN}, {"timestamp": 1578727921838, "ltp": 2.0, "tv": 9859.72, "trd": NaN, "batb": [[0, 1.99, 12.96], [1, 1.97, 15.31], [2, 1.96, 44.3]], "batl": NaN}, {"timestamp": 1578727922877, "ltp": 2.0, "tv": 9859.72, "trd": NaN, "batb": [[0, 1.99, 3], [1, 1.98, 10], [2, 1.97, 15.31]], "batl": NaN}, {"timestamp": 1578727923863, "ltp": 2.0, "tv": 9859.72, "trd": NaN, "batb": [[0, 1.99, 12.94], [1, 1.97, 15.31], [2, 1.96, 44.3]], "batl": NaN}, {"timestamp": 1578727924943, "ltp": 2.0, "tv": 9859.72, "trd": NaN, "batb": [[0, 1.99, 3], [1, 1.98, 9.97], [2, 1.97, 15.31]], "batl": NaN}, {"timestamp": 1578727925775, "ltp": 2.0, "tv": 9859.72, "trd": NaN, "batb": [[1, 1.98, 9.95]], "batl": NaN}, {"timestamp": 1578727926962, "ltp": 2.0, "tv": 9859.72, "trd": NaN, "batb": [[1, 1.97, 15.31], [2, 1.96, 44.3]], "batl": NaN}, {"timestamp": 1578727928975, "ltp": 2.0, "tv": 9859.72, "trd": NaN, "batb": [[0, 1.99, 12.9]], "batl": NaN}, {"timestamp": 1578727929958, "ltp": 2.0, "tv": 9859.72, "trd": NaN, "batb": [[0, 1.99, 3]], "batl": NaN}, {"timestamp": 1578727930891, "ltp": 2.0, "tv": 9859.72, "trd": NaN, "batb": [[0, 1.99, 12.89]], "batl": NaN}, {"timestamp": 1578727931975, "ltp": 2.0, "tv": 9859.72, "trd": NaN, "batb": [[0, 1.99, 12.86]], "batl": NaN}, {"timestamp": 1578727932954, "ltp": 2.0, "tv": 9859.72, "trd": NaN, "batb": [[0, 1.99, 12.84]], "batl": NaN}, {"timestamp": 1578727933987, "ltp": 2.0, "tv": 9859.72, "trd": NaN, "batb": [[0, 1.99, 3], [1, 1.98, 9.89], [2, 1.97, 15.31]], "batl": NaN}, {"timestamp": 1578727934967, "ltp": 2.0, "tv": 9859.72, "trd": NaN, "batb": [[1, 1.98, 9.9]], "batl": NaN}, {"timestamp": 1578727936003, "ltp": 2.0, "tv": 9859.72, "trd": NaN, "batb": [[1, 1.97, 15.31], [2, 1.96, 44.3]], "batl": NaN}, {"timestamp": 1578727937975, "ltp": 2.0, "tv": 9859.72, "trd": NaN, "batb": [[0, 1.99, 12.87]], "batl": NaN}, {"timestamp": 1578727938959, "ltp": 2.0, "tv": 9859.72, "trd": NaN, "batb": [[0, 1.99, 3]], "batl": NaN}, {"timestamp": 1578727939894, "ltp": 2.0, "tv": 9859.72, "trd": NaN, "batb": [[1, 1.98, 9.92], [2, 1.97, 15.31]], "batl": NaN}, {"timestamp": 1578727940995, "ltp": 2.0, "tv": 9859.72, "trd": NaN, "batb": [[0, 1.99, 12.86], [1, 1.97, 15.31], [2, 1.96, 44.3]], "batl": NaN}, {"timestamp": 1578727941991, "ltp": 2.0, "tv": 9859.72, "trd": NaN, "batb": [[0, 1.99, 3]], "batl": NaN}, {"timestamp": 1578727943996, "ltp": 2.0, "tv": 9859.72, "trd": NaN, "batb": [[1, 1.98, 9.92], [2, 1.97, 15.31]], "batl": NaN}, {"timestamp": 1578727944889, "ltp": 2.0, "tv": 9859.72, "trd": NaN, "batb": [[0, 1.99, 12.87], [1, 1.97, 15.31], [2, 1.96, 44.3]], "batl": NaN}, {"timestamp": 1578727945979, "ltp": 2.0, "tv": 9859.72, "trd": NaN, "batb": [[0, 1.99, 3], [1, 1.98, 9.93], [2, 1.97, 15.31]], "batl": NaN}, {"timestamp": 1578727946904, "ltp": 2.0, "tv": 9859.72, "trd": NaN, "batb": [[1, 1.97, 15.31], [2, 1.96, 44.3]], "batl": NaN}, {"timestamp": 1578727947883, "ltp": 2.0, "tv": 9859.72, "trd": NaN, "batb": [[0, 1.99, 12.87]], "batl": NaN}, {"timestamp": 1578727948914, "ltp": 2.0, "tv": 9859.72, "trd": NaN, "batb": [[0, 1.99, 3], [1, 1.98, 9.92], [2, 1.97, 15.31]], "batl": NaN}, {"timestamp": 1578727950000, "ltp": 2.0, "tv": 9859.72, "trd": NaN, "batb": [[1, 1.97, 15.31], [2, 1.96, 44.3]], "batl": NaN}, {"timestamp": 1578727950883, "ltp": 2.0, "tv": 9859.72, "trd": NaN, "batb": [[1, 1.98, 9.92], [2, 1.97, 15.31]], "batl": NaN}, {"timestamp": 1578727951811, "ltp": 2.0, "tv": 9859.72, "trd": NaN, "batb": [[1, 1.97, 15.31], [2, 1.96, 44.3]], "batl": NaN}, {"timestamp": 1578727953001, "ltp": 2.0, "tv": 9859.72, "trd": NaN, "batb": [[0, 1.99, 12.86]], "batl": NaN}, {"timestamp": 1578727953897, "ltp": 2.0, "tv": 9859.72, "trd": NaN, "batb": [[0, 1.99, 3], [1, 1.98, 9.61], [2, 1.97, 15.31]], "batl": NaN}, {"timestamp": 1578727954888, "ltp": 2.0, "tv": 9859.72, "trd": NaN, "batb": [[1, 1.98, 10.01]], "batl": NaN}, {"timestamp": 1578727955920, "ltp": 2.0, "tv": 9859.72, "trd": NaN, "batb": [[0, 1.99, 12.95], [1, 1.97, 15.31], [2, 1.96, 44.3]], "batl": NaN}, {"timestamp": 1578727957891, "ltp": 2.0, "tv": 9859.72, "trd": NaN, "batb": [[0, 1.99, 3], [1, 1.98, 9.97], [2, 1.97, 15.31]], "batl": NaN}, {"timestamp": 1578727958925, "ltp": 2.0, "tv": 9859.72, "trd": NaN, "batb": [[1, 1.98, 9.95]], "batl": NaN}, {"timestamp": 1578727959918, "ltp": 2.0, "tv": 9859.72, "trd": NaN, "batb": [[1, 1.98, 9.94]], "batl": NaN}, {"timestamp": 1578727960916, "ltp": 2.0, "tv": 9859.72, "trd": NaN, "batb": [[0, 1.99, 12.88], [1, 1.97, 15.31], [2, 1.96, 44.3]], "batl": NaN}, {"timestamp": 1578727961955, "ltp": 2.0, "tv": 9859.72, "trd": NaN, "batb": [[0, 1.99, 12.84]], "batl": NaN}, {"timestamp": 1578727962990, "ltp": 2.0, "tv": 9859.72, "trd": NaN, "batb": [[0, 1.99, 12.56]], "batl": NaN}, {"timestamp": 1578727963976, "ltp": 2.0, "tv": 9859.72, "trd": NaN, "batb": [[0, 1.99, 3]], "batl": NaN}, {"timestamp": 1578727964798, "ltp": 2.0, "tv": 9859.72, "trd": NaN, "batb": [[0, 1.99, 12.86]], "batl": NaN}, {"timestamp": 1578727965903, "ltp": 2.0, "tv": 9859.72, "trd": NaN, "batb": [[0, 1.99, 3]], "batl": NaN}, {"timestamp": 1578727966832, "ltp": 2.0, "tv": 9859.72, "trd": NaN, "batb": [[1, 1.98, 9.94], [2, 1.97, 15.31]], "batl": NaN}, {"timestamp": 1578727968959, "ltp": 2.0, "tv": 9859.72, "trd": NaN, "batb": [[0, 1.99, 12.89], [1, 1.97, 15.31], [2, 1.96, 44.3]], "batl": NaN}, {"timestamp": 1578727969832, "ltp": 2.0, "tv": 9859.72, "trd": NaN, "batb": [[0, 1.99, 12.86]], "batl": NaN}, {"timestamp": 1578727970929, "ltp": 2.0, "tv": 9859.72, "trd": NaN, "batb": [[0, 1.99, 3]], "batl": NaN}, {"timestamp": 1578727972855, "ltp": 2.0, "tv": 9859.72, "trd": NaN, "batb": [[0, 1.99, 12.81]], "batl": NaN}, {"timestamp": 1578727973949, "ltp": 2.0, "tv": 9859.72, "trd": NaN, "batb": [[0, 1.99, 13.57]], "batl": NaN}, {"timestamp": 1578727974934, "ltp": 2.0, "tv": 9859.72, "trd": NaN, "batb": [[0, 1.99, 3.74]], "batl": NaN}, {"timestamp": 1578727975923, "ltp": 2.0, "tv": 9859.72, "trd": NaN, "batb": [[1, 1.98, 9.88], [2, 1.97, 15.31]], "batl": NaN}, {"timestamp": 1578727976956, "ltp": 2.0, "tv": 9859.72, "trd": NaN, "batb": [[0, 1.99, 13.58], [1, 1.97, 15.31], [2, 1.96, 44.3]], "batl": NaN}, {"timestamp": 1578727977937, "ltp": 2.0, "tv": 9859.72, "trd": NaN, "batb": [[0, 1.99, 3.74], [1, 1.98, 9.89], [2, 1.97, 15.31]], "batl": NaN}, {"timestamp": 1578727978976, "ltp": 2.0, "tv": 9859.72, "trd": NaN, "batb": [[0, 1.99, 13.59], [1, 1.97, 15.31], [2, 1.96, 44.3]], "batl": NaN}, {"timestamp": 1578727979967, "ltp": 2.0, "tv": 9859.72, "trd": NaN, "batb": [[0, 1.99, 3.74]], "batl": NaN}, {"timestamp": 1578727980748, "ltp": 2.0, "tv": 9859.72, "trd": NaN, "batb": [[1, 1.98, 9.9], [2, 1.97, 15.31]], "batl": [[0, 2, 358.45], [1, 2.02, 12.52]]}, {"timestamp": 1578727981947, "ltp": 2.0, "tv": 9859.72, "trd": NaN, "batb": [[0, 1.99, 13.6], [1, 1.97, 15.31], [2, 1.96, 44.3]], "batl": NaN}, {"timestamp": 1578727982932, "ltp": 2.0, "tv": 9859.72, "trd": NaN, "batb": [[0, 1.99, 3.74]], "batl": NaN}, {"timestamp": 1578727983758, "ltp": 2.0, "tv": 9859.72, "trd": NaN, "batb": [[0, 1.99, 13.6]], "batl": NaN}, {"timestamp": 1578727985971, "ltp": 2.0, "tv": 9859.72, "trd": NaN, "batb": [[0, 1.99, 3.74], [1, 1.98, 9.91], [2, 1.97, 15.31]], "batl": NaN}, {"timestamp": 1578727987995, "ltp": 2.0, "tv": 9859.72, "trd": NaN, "batb": [[1, 1.97, 15.31], [2, 1.96, 44.3]], "batl": NaN}, {"timestamp": 1578727988983, "ltp": 2.0, "tv": 9859.72, "trd": NaN, "batb": [[0, 1.99, 13.6]], "batl": NaN}, {"timestamp": 1578727991995, "ltp": 2.0, "tv": 9859.72, "trd": NaN, "batb": [[0, 1.99, 3.74]], "batl": NaN}, {"timestamp": 1578727992774, "ltp": 2.0, "tv": 9859.72, "trd": NaN, "batb": [[1, 1.98, 9.91], [2, 1.97, 15.31]], "batl": NaN}, {"timestamp": 1578727993807, "ltp": 2.0, "tv": 9859.72, "trd": NaN, "batb": [[0, 1.99, 13.6], [1, 1.97, 15.31], [2, 1.96, 44.3]], "batl": NaN}, {"timestamp": 1578727994950, "ltp": 2.0, "tv": 9859.72, "trd": NaN, "batb": [[0, 1.99, 3.74], [1, 1.98, 9.91], [2, 1.97, 15.31]], "batl": NaN}, {"timestamp": 1578727995993, "ltp": 2.0, "tv": 9859.72, "trd": NaN, "batb": [[0, 1.99, 13.6], [1, 1.97, 15.31], [2, 1.96, 44.3]], "batl": NaN}, {"timestamp": 1578727996984, "ltp": 2.0, "tv": 9859.72, "trd": NaN, "batb": [[0, 1.99, 3.74], [1, 1.98, 9.91], [2, 1.97, 15.31]], "batl": NaN}, {"timestamp": 1578728000923, "ltp": 2.0, "tv": 9859.72, "trd": NaN, "batb": [[0, 1.99, 13.6], [1, 1.97, 15.31], [2, 1.96, 44.3]], "batl": NaN}, {"timestamp": 1578728001906, "ltp": 2.0, "tv": 9859.72, "trd": NaN, "batb": [[0, 1.99, 3.74]], "batl": NaN}, {"timestamp": 1578728002992, "ltp": 2.0, "tv": 9859.72, "trd": NaN, "batb": [[0, 1.99, 13.6]], "batl": NaN}, {"timestamp": 1578728003613, "ltp": 2.0, "tv": 9859.72, "trd": NaN, "batb": [[0, 1.99, 13.59]], "batl": NaN}, {"timestamp": 1578728004912, "ltp": 2.0, "tv": 9859.72, "trd": NaN, "batb": [[0, 1.99, 3.74], [1, 1.98, 9.91], [2, 1.97, 15.31]], "batl": NaN}, {"timestamp": 1578728006000, "ltp": 2.0, "tv": 9859.72, "trd": NaN, "batb": [[0, 1.99, 13.61], [1, 1.97, 15.31], [2, 1.96, 44.3]], "batl": NaN}, {"timestamp": 1578728006936, "ltp": 2.0, "tv": 9859.72, "trd": NaN, "batb": [[0, 1.99, 3.74], [1, 1.98, 9.91], [2, 1.97, 15.31]], "batl": NaN}, {"timestamp": 1578728007922, "ltp": 2.0, "tv": 9859.72, "trd": NaN, "batb": [[0, 1.99, 13.6], [1, 1.97, 15.31], [2, 1.96, 44.3]], "batl": NaN}, {"timestamp": 1578728008907, "ltp": 2.0, "tv": 9859.72, "trd": NaN, "batb": [[0, 1.99, 3.74]], "batl": NaN}, {"timestamp": 1578728009942, "ltp": 2.0, "tv": 9859.72, "trd": NaN, "batb": [[1, 1.98, 9.98], [2, 1.97, 15.31]], "batl": NaN}, {"timestamp": 1578728010824, "ltp": 2.0, "tv": 9859.72, "trd": NaN, "batb": [[0, 1.99, 13.68], [1, 1.97, 15.31], [2, 1.96, 44.3]], "batl": NaN}, {"timestamp": 1578728011810, "ltp": 2.0, "tv": 9859.72, "trd": NaN, "batb": [[0, 1.99, 3.74]], "batl": NaN}, {"timestamp": 1578728012946, "ltp": 2.0, "tv": 9859.72, "trd": NaN, "batb": [[1, 1.98, 10], [2, 1.97, 15.31]], "batl": NaN}, {"timestamp": 1578728013835, "ltp": 2.0, "tv": 9859.72, "trd": NaN, "batb": [[0, 1.99, 13.66], [1, 1.97, 15.31], [2, 1.96, 44.3]], "batl": NaN}, {"timestamp": 1578728014926, "ltp": 2.0, "tv": 9859.72, "trd": NaN, "batb": [[0, 1.99, 3.74], [1, 1.98, 9.95], [2, 1.97, 15.31]], "batl": NaN}, {"timestamp": 1578728015914, "ltp": 2.0, "tv": 9859.72, "trd": NaN, "batb": [[1, 1.98, 9.93]], "batl": NaN}, {"timestamp": 1578728016952, "ltp": 2.0, "tv": 9859.72, "trd": NaN, "batb": [[0, 1.99, 13.62], [1, 1.97, 15.31], [2, 1.96, 44.3]], "batl": NaN}, {"timestamp": 1578728017930, "ltp": 2.0, "tv": 9859.72, "trd": NaN, "batb": [[0, 1.99, 3.74]], "batl": NaN}, {"timestamp": 1578728019955, "ltp": 2.0, "tv": 9859.72, "trd": NaN, "batb": [[0, 1.99, 13.61]], "batl": NaN}, {"timestamp": 1578728021932, "ltp": 2.0, "tv": 9859.72, "trd": NaN, "batb": [[0, 1.99, 3.74], [1, 1.98, 9.91], [2, 1.97, 15.31]], "batl": NaN}, {"timestamp": 1578728022963, "ltp": 2.0, "tv": 9859.72, "trd": NaN, "batb": [[0, 1.99, 13.6], [1, 1.97, 15.31], [2, 1.96, 44.3]], "batl": NaN}, {"timestamp": 1578728023847, "ltp": 2.0, "tv": 9859.72, "trd": NaN, "batb": [[0, 1.99, 3.74], [1, 1.98, 9.92], [2, 1.97, 15.31]], "batl": NaN}, {"timestamp": 1578728024940, "ltp": 2.0, "tv": 9859.72, "trd": NaN, "batb": [[0, 1.99, 13.61], [1, 1.97, 15.31], [2, 1.96, 44.3]], "batl": NaN}, {"timestamp": 1578728025459, "ltp": 2.0, "tv": 9859.72, "trd": NaN, "batb": [[0, 1.99, 3.74], [1, 1.98, 9.92], [2, 1.97, 15.31]], "batl": NaN}, {"timestamp": 1578728026959, "ltp": 2.0, "tv": 9859.72, "trd": NaN, "batb": [[0, 1.99, 13.61], [1, 1.97, 15.31], [2, 1.96, 44.3]], "batl": NaN}, {"timestamp": 1578728027954, "ltp": 2.0, "tv": 9859.72, "trd": NaN, "batb": [[0, 1.99, 3.74], [1, 1.98, 9.92], [2, 1.97, 15.31]], "batl": NaN}, {"timestamp": 1578728028947, "ltp": 2.0, "tv": 9859.72, "trd": NaN, "batb": [[1, 1.97, 15.31], [2, 1.96, 44.3]], "batl": NaN}, {"timestamp": 1578728029974, "ltp": 2.0, "tv": 9859.72, "trd": NaN, "batb": [[1, 1.98, 9.94], [2, 1.97, 15.31]], "batl": NaN}, {"timestamp": 1578728030863, "ltp": 2.0, "tv": 9859.72, "trd": NaN, "batb": [[1, 1.98, 9.93]], "batl": NaN}, {"timestamp": 1578728031946, "ltp": 2.0, "tv": 9859.72, "trd": NaN, "batb": [[0, 1.99, 13.62], [1, 1.97, 15.31], [2, 1.96, 44.3]], "batl": NaN}, {"timestamp": 1578728032974, "ltp": 2.0, "tv": 9859.72, "trd": NaN, "batb": [[0, 1.99, 13.61]], "batl": NaN}, {"timestamp": 1578728033966, "ltp": 2.0, "tv": 9859.72, "trd": NaN, "batb": [[0, 1.99, 3.74]], "batl": NaN}, {"timestamp": 1578728034950, "ltp": 2.0, "tv": 9859.72, "trd": NaN, "batb": [[0, 1.99, 13.59]], "batl": NaN}, {"timestamp": 1578728035881, "ltp": 2.0, "tv": 9859.72, "trd": NaN, "batb": [[0, 1.99, 3.74], [1, 1.98, 9.91], [2, 1.97, 15.31]], "batl": NaN}, {"timestamp": 1578728038998, "ltp": 2.0, "tv": 9859.72, "trd": NaN, "batb": [[1, 1.97, 15.31], [2, 1.96, 44.3]], "batl": NaN}, {"timestamp": 1578728039981, "ltp": 2.0, "tv": 9859.72, "trd": NaN, "batb": [[0, 1.99, 13.6]], "batl": NaN}, {"timestamp": 1578728040976, "ltp": 2.0, "tv": 9859.72, "trd": NaN, "batb": [[0, 1.99, 3.74]], "batl": NaN}, {"timestamp": 1578728042972, "ltp": 2.0, "tv": 9859.72, "trd": NaN, "batb": [[0, 1.99, 13.61]], "batl": NaN}, {"timestamp": 1578728043857, "ltp": 2.0, "tv": 9859.72, "trd": NaN, "batb": [[0, 1.99, 3.74]], "batl": NaN}, {"timestamp": 1578728044959, "ltp": 2.0, "tv": 9859.72, "trd": NaN, "batb": [[0, 1.99, 13.61]], "batl": NaN}, {"timestamp": 1578728046983, "ltp": 2.0, "tv": 9859.72, "trd": NaN, "batb": [[0, 1.99, 3.74], [1, 1.98, 9.93], [2, 1.97, 15.31]], "batl": NaN}, {"timestamp": 1578728047972, "ltp": 2.0, "tv": 9859.72, "trd": NaN, "batb": [[0, 1.99, 13.61], [1, 1.97, 15.31], [2, 1.96, 44.3]], "batl": NaN}, {"timestamp": 1578728049984, "ltp": 2.0, "tv": 9859.72, "trd": NaN, "batb": [[0, 1.99, 3.74], [1, 1.98, 9.93], [2, 1.97, 15.31]], "batl": NaN}, {"timestamp": 1578728050869, "ltp": 2.0, "tv": 9859.72, "trd": NaN, "batb": [[0, 1.99, 13.61], [1, 1.97, 15.31], [2, 1.96, 44.3]], "batl": NaN}, {"timestamp": 1578728051904, "ltp": 2.0, "tv": 9859.72, "trd": NaN, "batb": [[0, 1.99, 3.74], [1, 1.98, 9.92], [2, 1.97, 15.31]], "batl": NaN}, {"timestamp": 1578728052993, "ltp": 2.0, "tv": 9859.72, "trd": NaN, "batb": [[1, 1.97, 15.31], [2, 1.96, 44.3]], "batl": NaN}, {"timestamp": 1578728055994, "ltp": 2.0, "tv": 9859.72, "trd": NaN, "batb": [[0, 1.99, 13.61]], "batl": NaN}, {"timestamp": 1578728057860, "ltp": 2.0, "tv": 9859.72, "trd": NaN, "batb": [[0, 1.99, 13.63]], "batl": NaN}, {"timestamp": 1578728058952, "ltp": 2.0, "tv": 9859.72, "trd": NaN, "batb": [[0, 1.99, 3.74]], "batl": NaN}, {"timestamp": 1578728060876, "ltp": 2.0, "tv": 9859.72, "trd": NaN, "batb": [[0, 1.99, 13.62]], "batl": NaN}, {"timestamp": 1578728061965, "ltp": 2.0, "tv": 9859.72, "trd": NaN, "batb": [[0, 1.99, 3.74]], "batl": NaN}, {"timestamp": 1578728062798, "ltp": 2.0, "tv": 9859.72, "trd": NaN, "batb": [[0, 1.99, 13.62]], "batl": NaN}, {"timestamp": 1578728063895, "ltp": 2.0, "tv": 9919.72, "trd": [[2, 1632.79]], "batb": [[0, 1.99, 13.61]], "batl": [[0, 2, 328.45]]}, {"timestamp": 1578728064976, "ltp": 2.0, "tv": 9919.72, "trd": NaN, "batb": [[0, 1.99, 3.74]], "batl": NaN}, {"timestamp": 1578728065903, "ltp": 2.0, "tv": 9919.72, "trd": NaN, "batb": [[0, 1.99, 13.61]], "batl": NaN}, {"timestamp": 1578728066933, "ltp": 2.0, "tv": 9919.72, "trd": NaN, "batb": [[0, 1.99, 13.3]], "batl": NaN}, {"timestamp": 1578728067871, "ltp": 2.0, "tv": 9919.72, "trd": NaN, "batb": [[0, 1.99, 3.74]], "batl": NaN}, {"timestamp": 1578728069004, "ltp": 2.0, "tv": 9939.72, "trd": [[2, 1652.79]], "batb": [[0, 1.99, 13.61]], "batl": [[0, 2, 318.45]]}, {"timestamp": 1578728069988, "ltp": 2.0, "tv": 9939.72, "trd": NaN, "batb": [[0, 1.99, 3.74]], "batl": NaN}, {"timestamp": 1578728070913, "ltp": 2.0, "tv": 9939.72, "trd": NaN, "batb": [[0, 1.99, 13.61]], "batl": NaN}, {"timestamp": 1578728071999, "ltp": 2.0, "tv": 9939.72, "trd": NaN, "batb": [[0, 1.99, 13.62]], "batl": NaN}, {"timestamp": 1578728072981, "ltp": 2.0, "tv": 9939.72, "trd": NaN, "batb": [[0, 1.99, 3.74], [1, 1.98, 9.92], [2, 1.97, 15.31]], "batl": NaN}, {"timestamp": 1578728073913, "ltp": 2.0, "tv": 9939.72, "trd": NaN, "batb": [[1, 1.98, 9.61]], "batl": NaN}, {"timestamp": 1578728074996, "ltp": 2.0, "tv": 9939.72, "trd": NaN, "batb": [[0, 1.99, 13.61], [1, 1.97, 15.31], [2, 1.96, 44.3]], "batl": NaN}, {"timestamp": 1578728075916, "ltp": 2.0, "tv": 9939.72, "trd": NaN, "batb": [[0, 1.99, 13.57]], "batl": NaN}, {"timestamp": 1578728076905, "ltp": 2.0, "tv": 9939.72, "trd": NaN, "batb": [[0, 1.99, 3.74]], "batl": NaN}, {"timestamp": 1578728078816, "ltp": 2.0, "tv": 9939.72, "trd": NaN, "batb": [[0, 1.99, 13.56]], "batl": NaN}, {"timestamp": 1578728079905, "ltp": 2.0, "tv": 9939.72, "trd": NaN, "batb": [[0, 1.99, 3.74], [1, 1.98, 9.88], [2, 1.97, 15.31]], "batl": NaN}, {"timestamp": 1578728080830, "ltp": 2.0, "tv": 9939.72, "trd": NaN, "batb": [[0, 1.99, 13.57], [1, 1.97, 15.31], [2, 1.96, 44.3]], "batl": NaN}, {"timestamp": 1578728081924, "ltp": 2.0, "tv": 9939.72, "trd": NaN, "batb": [[0, 1.99, 3.74], [1, 1.98, 9.89], [2, 1.97, 15.31]], "batl": NaN}, {"timestamp": 1578728082812, "ltp": 2.0, "tv": 9939.72, "trd": NaN, "batb": [[0, 1.99, 13.58], [1, 1.97, 15.31], [2, 1.96, 44.3]], "batl": NaN}, {"timestamp": 1578728084926, "ltp": 2.0, "tv": 9939.72, "trd": NaN, "batb": [[0, 1.99, 3.74], [1, 1.98, 9.91], [2, 1.97, 15.31]], "batl": NaN}, {"timestamp": 1578728085909, "ltp": 2.0, "tv": 9939.72, "trd": NaN, "batb": [[0, 1.99, 13.59], [1, 1.97, 15.31], [2, 1.96, 44.3]], "batl": NaN}, {"timestamp": 1578728086947, "ltp": 2.0, "tv": 9939.72, "trd": NaN, "batb": [[0, 1.99, 3.74], [1, 1.98, 9.9], [2, 1.97, 15.31]], "batl": NaN}, {"timestamp": 1578728087931, "ltp": 2.0, "tv": 9939.72, "trd": NaN, "batb": [[0, 1.99, 13.6], [1, 1.97, 15.31], [2, 1.96, 44.3]], "batl": NaN}, {"timestamp": 1578728088925, "ltp": 2.0, "tv": 9939.72, "trd": NaN, "batb": [[0, 1.99, 3.74], [1, 1.98, 9.91], [2, 1.97, 15.31]], "batl": NaN}, {"timestamp": 1578728089951, "ltp": 2.0, "tv": 9939.72, "trd": NaN, "batb": [[0, 1.99, 13.61], [1, 1.97, 15.31], [2, 1.96, 44.3]], "batl": NaN}, {"timestamp": 1578728091932, "ltp": 2.0, "tv": 9939.72, "trd": NaN, "batb": [[0, 1.99, 3.74], [1, 1.98, 9.91], [2, 1.97, 15.31]], "batl": NaN}, {"timestamp": 1578728092920, "ltp": 2.0, "tv": 9939.72, "trd": NaN, "batb": [[0, 1.99, 13.61], [1, 1.97, 15.31], [2, 1.96, 44.3]], "batl": NaN}, {"timestamp": 1578728093952, "ltp": 1.99, "tv": 9966.94, "trd": [[1.99, 936.56]], "batb": [[0, 1.97, 15.31], [1, 1.96, 44.3], [2, 1.95, 52.84]], "batl": [[0, 1.99, 15.39], [1, 2, 318.45], [2, 2.02, 12.52]]}, {"timestamp": 1578728095928, "ltp": 1.99, "tv": 9966.94, "trd": NaN, "batb": NaN, "batl": [[0, 1.99, 20.39]]}, {"timestamp": 1578728103862, "ltp": 1.99, "tv": 9966.94, "trd": NaN, "batb": NaN, "batl": [[2, 2.04, 100]]}, {"timestamp": 1578728109851, "ltp": 1.99, "tv": 9966.94, "trd": NaN, "batb": NaN, "batl": [[0, 1.99, 22.39], [1, 2, 316.45]]}, {"timestamp": 1578728166838, "ltp": 1.99, "tv": 10011.71, "trd": [[1.99, 981.34]], "batb": NaN, "batl": [[0, 2, 316.45], [1, 2.04, 100], [2, 2.06, 100]]}, {"timestamp": 1578728172772, "ltp": 1.99, "tv": 10011.71, "trd": NaN, "batb": NaN, "batl": [[1, 2.02, 2], [2, 2.04, 100]]}, {"timestamp": 1578728185950, "ltp": 1.99, "tv": 10011.71, "trd": NaN, "batb": NaN, "batl": [[0, 2, 318.45], [1, 2.04, 100], [2, 2.06, 100]]}, {"timestamp": 1578728193944, "ltp": 1.99, "tv": 10011.71, "trd": NaN, "batb": NaN, "batl": [[1, 2.04, 113.6]]}, {"timestamp": 1578728210987, "ltp": 1.99, "tv": 10011.71, "trd": NaN, "batb": NaN, "batl": [[0, 2, 316.45], [1, 2.02, 2], [2, 2.04, 113.6]]}, {"timestamp": 1578728236921, "ltp": 1.99, "tv": 10011.71, "trd": NaN, "batb": NaN, "batl": [[0, 2, 318.45], [1, 2.04, 113.6], [2, 2.06, 100]]}, {"timestamp": 1578728274974, "ltp": 1.99, "tv": 10011.71, "trd": NaN, "batb": [[2, 1.95, 53.59]], "batl": [[0, 2, 316.45], [1, 2.02, 2], [2, 2.04, 113.6]]}, {"timestamp": 1578728299749, "ltp": 1.99, "tv": 10011.71, "trd": NaN, "batb": NaN, "batl": [[0, 2, 318.45], [1, 2.04, 113.6], [2, 2.06, 100]]}, {"timestamp": 1578728312885, "ltp": 1.99, "tv": 10011.71, "trd": NaN, "batb": NaN, "batl": [[0, 2, 316.45], [1, 2.02, 2], [2, 2.04, 113.6]]}, {"timestamp": 1578728324917, "ltp": 1.99, "tv": 10011.71, "trd": NaN, "batb": NaN, "batl": [[1, 2.04, 113.6], [2, 2.06, 100]]}, {"timestamp": 1578728325743, "ltp": 1.99, "tv": 10011.71, "trd": NaN, "batb": NaN, "batl": [[0, 2, 318.45]]}, {"timestamp": 1578728369882, "ltp": 1.99, "tv": 10011.71, "trd": NaN, "batb": NaN, "batl": [[0, 1.99, 26.8], [1, 2, 318.45], [2, 2.04, 113.6]]}, {"timestamp": 1578728375994, "ltp": 1.99, "tv": 10011.71, "trd": NaN, "batb": NaN, "batl": [[0, 1.99, 28.8], [1, 2, 316.45]]}, {"timestamp": 1578728408922, "ltp": 1.99, "tv": 10011.71, "trd": NaN, "batb": NaN, "batl": [[1, 2, 296.45]]}, {"timestamp": 1578728541949, "ltp": 1.99, "tv": 10061.72, "trd": [[1.99, 1031.34]], "batb": NaN, "batl": [[0, 1.99, 3.79]]}, {"timestamp": 1578728542976, "ltp": 1.99, "tv": 10061.72, "trd": NaN, "batb": [[0, 1.97, 40.44]], "batl": NaN}, {"timestamp": 1578728562995, "ltp": 1.99, "tv": 10061.72, "trd": NaN, "batb": NaN, "batl": [[2, 2.04, 100]]}, {"timestamp": 1578728725958, "ltp": 1.99, "tv": 10069.3, "trd": [[1.99, 1038.92]], "batb": [[0, 1.99, 16.21], [1, 1.97, 40.44], [2, 1.96, 44.3]], "batl": [[0, 2, 296.45], [1, 2.04, 100], [2, 2.06, 100]]}, {"timestamp": 1578728727000, "ltp": 1.99, "tv": 10069.3, "trd": NaN, "batb": [[1, 1.97, 49.38]], "batl": NaN}, {"timestamp": 1578728727864, "ltp": 1.99, "tv": 10069.3, "trd": NaN, "batb": [[1, 1.97, 51.17]], "batl": NaN}, {"timestamp": 1578728734959, "ltp": 1.99, "tv": 10069.3, "trd": NaN, "batb": NaN, "batl": [[1, 2.02, 2], [2, 2.04, 100]]}, {"timestamp": 1578728738979, "ltp": 1.99, "tv": 10101.72, "trd": [[1.99, 1071.34]], "batb": [[0, 1.97, 51.17], [1, 1.96, 51], [2, 1.95, 44.56]], "batl": [[0, 1.99, 16.79], [1, 2, 296.45], [2, 2.02, 2]]}, {"timestamp": 1578728741970, "ltp": 1.99, "tv": 10101.72, "trd": NaN, "batb": [[1, 1.96, 44.3]], "batl": NaN}, {"timestamp": 1578728745763, "ltp": 1.99, "tv": 10101.72, "trd": NaN, "batb": [[0, 1.97, 26.05]], "batl": NaN}, {"timestamp": 1578728746488, "ltp": 1.99, "tv": 10101.72, "trd": NaN, "batb": [[0, 1.97, 17.11], [1, 1.96, 53.29]], "batl": NaN}, {"timestamp": 1578728747997, "ltp": 1.99, "tv": 10101.72, "trd": NaN, "batb": [[0, 1.97, 15.31]], "batl": NaN}, {"timestamp": 1578728752916, "ltp": 1.99, "tv": 10101.72, "trd": NaN, "batb": [[0, 1.97, 31.41]], "batl": NaN}, {"timestamp": 1578728761720, "ltp": 1.99, "tv": 10101.72, "trd": NaN, "batb": NaN, "batl": [[0, 1.99, 18.79], [2, 2.04, 100]]}, {"timestamp": 1578728772943, "ltp": 1.97, "tv": 10111.72, "trd": [[1.97, 289.45]], "batb": [[0, 1.97, 26.41]], "batl": NaN}, {"timestamp": 1578728796953, "ltp": 1.99, "tv": 10121.6, "trd": [[1.99, 1081.22]], "batb": NaN, "batl": [[0, 1.99, 13.85]]}, {"timestamp": 1578728807984, "ltp": 1.97, "tv": 10173.6, "trd": [[1.97, 341.45]], "batb": [[0, 1.96, 53.7], [1, 1.95, 44.56], [2, 1.93, 50.45]], "batl": NaN}, {"timestamp": 1578728808870, "ltp": 1.97, "tv": 10174.42, "trd": [[1.97, 342.27]], "batb": [[0, 1.96, 53.29], [1, 1.95, 59.82]], "batl": NaN}, {"timestamp": 1578728814805, "ltp": 1.96, "tv": 10202.42, "trd": [[1.96, 692.99]], "batb": [[0, 1.96, 39.29]], "batl": NaN}, {"timestamp": 1578728824993, "ltp": 1.96, "tv": 10202.42, "trd": NaN, "batb": [[0, 1.96, 34.6], [1, 1.95, 44.56]], "batl": NaN}, {"timestamp": 1578728825918, "ltp": 1.96, "tv": 10202.42, "trd": NaN, "batb": [[0, 1.96, 25.61], [2, 1.94, 13.82]], "batl": NaN}, {"timestamp": 1578728840823, "ltp": 1.96, "tv": 10202.42, "trd": NaN, "batb": NaN, "batl": [[0, 1.97, 7], [1, 1.99, 13.85], [2, 2, 296.45]]}, {"timestamp": 1578728841915, "ltp": 1.97, "tv": 10216.42, "trd": [[1.97, 356.27]], "batb": [[0, 1.97, 6.13], [1, 1.96, 25.61], [2, 1.95, 44.56]], "batl": [[0, 1.99, 13.85], [1, 2, 296.45], [2, 2.04, 100]]}, {"timestamp": 1578728912818, "ltp": 1.97, "tv": 10228.68, "trd": [[1.97, 368.53]], "batb": [[0, 1.96, 25.61], [1, 1.95, 44.56], [2, 1.94, 13.82]], "batl": [[0, 1.97, 8.87], [1, 1.99, 13.85], [2, 2, 296.45]]}, {"timestamp": 1578728928905, "ltp": 1.97, "tv": 10228.68, "trd": NaN, "batb": NaN, "batl": [[1, 1.99, 11.85]]}, {"timestamp": 1578728929936, "ltp": 1.97, "tv": 10228.68, "trd": NaN, "batb": NaN, "batl": [[1, 1.98, 2], [2, 1.99, 11.85]]}, {"timestamp": 1578728945730, "ltp": 1.97, "tv": 10228.68, "trd": NaN, "batb": [[1, 1.95, 19.31]], "batl": NaN}, {"timestamp": 1578728968000, "ltp": 1.97, "tv": 10228.68, "trd": NaN, "batb": NaN, "batl": [[0, 1.97, 10.87], [1, 1.99, 11.85], [2, 2, 296.45]]}, {"timestamp": 1578728993801, "ltp": 1.97, "tv": 10228.68, "trd": NaN, "batb": NaN, "batl": [[0, 1.97, 8.87], [1, 1.98, 2], [2, 1.99, 11.85]]}, {"timestamp": 1578729058879, "ltp": 1.97, "tv": 10228.68, "trd": NaN, "batb": NaN, "batl": [[0, 1.97, 10.87], [1, 1.99, 11.85], [2, 2, 296.45]]}, {"timestamp": 1578729065924, "ltp": 1.97, "tv": 10228.68, "trd": NaN, "batb": NaN, "batl": [[1, 1.99, 40.85]]}, {"timestamp": 1578729070996, "ltp": 1.97, "tv": 10228.68, "trd": NaN, "batb": NaN, "batl": [[0, 1.97, 8.87]]}, {"timestamp": 1578729071929, "ltp": 1.97, "tv": 10228.68, "trd": NaN, "batb": NaN, "batl": [[1, 1.98, 2], [2, 1.99, 40.85]]}, {"timestamp": 1578729083949, "ltp": 1.97, "tv": 10228.68, "trd": NaN, "batb": NaN, "batl": [[0, 1.97, 10.87], [1, 1.99, 40.85], [2, 2, 296.45]]}, {"timestamp": 1578729109978, "ltp": 1.97, "tv": 10228.68, "trd": NaN, "batb": NaN, "batl": [[0, 1.97, 8.87], [1, 1.98, 2], [2, 1.99, 40.85]]}, {"timestamp": 1578729122916, "ltp": 1.97, "tv": 10228.68, "trd": NaN, "batb": NaN, "batl": [[0, 1.97, 10.87], [1, 1.99, 40.85], [2, 2, 296.45]]}, {"timestamp": 1578729127001, "ltp": 1.97, "tv": 10250.42, "trd": [[1.97, 390.27]], "batb": NaN, "batl": [[0, 1.98, 13.05]]}, {"timestamp": 1578729170938, "ltp": 1.96, "tv": 10301.65, "trd": [[1.96, 744.21]], "batb": [[0, 1.95, 19.31], [1, 1.94, 15.58], [2, 1.93, 50.45]], "batl": [[0, 1.96, 24.39], [1, 1.98, 13.05], [2, 1.99, 40.85]]}, {"timestamp": 1578729171965, "ltp": 1.96, "tv": 10305.65, "trd": [[1.96, 748.21]], "batb": [[1, 1.94, 9.08]], "batl": [[0, 1.96, 22.39]]}, {"timestamp": 1578729172945, "ltp": 1.96, "tv": 10309.65, "trd": [[1.96, 752.21]], "batb": [[1, 1.93, 50.45], [2, 1.91, 15.31]], "batl": [[0, 1.96, 20.39]]}, {"timestamp": 1578729174953, "ltp": 1.96, "tv": 10311.15, "trd": [[1.96, 753.71]], "batb": NaN, "batl": [[0, 1.96, 19.64]]}, {"timestamp": 1578729176966, "ltp": 1.96, "tv": 10315.15, "trd": [[1.96, 757.71]], "batb": NaN, "batl": [[0, 1.96, 17.64]]}, {"timestamp": 1578729177959, "ltp": 1.96, "tv": 10319.15, "trd": [[1.96, 761.71]], "batb": NaN, "batl": [[0, 1.96, 15.64]]}, {"timestamp": 1578729178781, "ltp": 1.96, "tv": 10320.65, "trd": [[1.96, 763.21]], "batb": NaN, "batl": [[0, 1.96, 14.89]]}, {"timestamp": 1578729179972, "ltp": 1.96, "tv": 10324.65, "trd": [[1.96, 767.21]], "batb": NaN, "batl": [[0, 1.96, 12.89]]}, {"timestamp": 1578729181938, "ltp": 1.96, "tv": 10326.35, "trd": [[1.96, 768.91]], "batb": [[1, 1.93, 56.65]], "batl": [[0, 1.96, 12.04]]}, {"timestamp": 1578729182971, "ltp": 1.96, "tv": 10330.35, "trd": [[1.96, 772.91]], "batb": NaN, "batl": [[0, 1.96, 10.04]]}, {"timestamp": 1578729184880, "ltp": 1.96, "tv": 10332.05, "trd": [[1.96, 774.61]], "batb": NaN, "batl": [[0, 1.96, 9.19]]}, {"timestamp": 1578729186855, "ltp": 1.96, "tv": 10335.47, "trd": [[1.96, 778.03]], "batb": NaN, "batl": [[0, 1.96, 7.48]]}, {"timestamp": 1578729188558, "ltp": 1.96, "tv": 10338.89, "trd": [[1.96, 781.45]], "batb": NaN, "batl": [[0, 1.96, 5.77]]}, {"timestamp": 1578729190885, "ltp": 1.96, "tv": 10340.95, "trd": [[1.96, 783.51]], "batb": NaN, "batl": [[0, 1.96, 4.74]]}, {"timestamp": 1578729192894, "ltp": 1.96, "tv": 10343.01, "trd": [[1.96, 785.57]], "batb": NaN, "batl": [[0, 1.96, 3.71]]}, {"timestamp": 1578729200862, "ltp": 1.96, "tv": 10343.01, "trd": NaN, "batb": NaN, "batl": [[1, 1.97, 3], [2, 1.98, 13.05]]}, {"timestamp": 1578729201788, "ltp": 1.96, "tv": 10344.25, "trd": [[1.96, 786.81]], "batb": NaN, "batl": [[0, 1.96, 3.09]]}, {"timestamp": 1578729203959, "ltp": 1.96, "tv": 10350.43, "trd": [[1.96, 792.99]], "batb": [[0, 1.96, 10.3], [1, 1.95, 19.31], [2, 1.93, 56.65]], "batl": [[0, 1.97, 3], [1, 1.98, 13.05], [2, 1.99, 40.85]]}, {"timestamp": 1578729204990, "ltp": 1.96, "tv": 10350.43, "trd": NaN, "batb": [[2, 1.94, 4.73]], "batl": NaN}, {"timestamp": 1578729205975, "ltp": 1.96, "tv": 10350.43, "trd": NaN, "batb": [[0, 1.96, 10.67]], "batl": NaN}, {"timestamp": 1578729231843, "ltp": 1.96, "tv": 10360.43, "trd": [[1.96, 802.99]], "batb": [[0, 1.96, 5.67]], "batl": NaN}, {"timestamp": 1578729232826, "ltp": 1.96, "tv": 10360.43, "trd": NaN, "batb": [[2, 1.93, 50.45]], "batl": NaN}, {"timestamp": 1578729249954, "ltp": 1.96, "tv": 10361.17, "trd": [[1.96, 803.73]], "batb": [[0, 1.95, 19.31], [1, 1.94, 9.77], [2, 1.93, 53.07]], "batl": NaN}, {"timestamp": 1578729459780, "ltp": 1.95, "tv": 10361.6, "trd": [[1.95, 420.98]], "batb": [[0, 1.95, 19.09]], "batl": NaN}, {"timestamp": 1578729480934, "ltp": 1.95, "tv": 10361.66, "trd": [[1.95, 421.04]], "batb": [[0, 1.95, 19.06]], "batl": NaN}, {"timestamp": 