{"info": {"id": "1.167206557", "eventId": "29646660", "eventName": "2m4f Grd2 Chs", "marketType": "WIN", "openDate": 1578751539952, "name": "Kemp  11th Jan", "numberOfActiveRunner": 5, "countryCode": "", "sport": "HORSE RACING", "venue": "", "volume": {"total": 1110192.57, "preMatch": 805634.41, "inPlay": 304558.16}, "winner": {"id": 10709204, "name": "Frodon", "status": "WINNER", "position": 2}, "delay": 1}, "runners": [{"id": 140424, "name": "Top Notch", "status": "LOSER", "position": 1, "inPlayOdds": 2.14, "inPlayTime": 1578751539952, "avgPrematch": 2.13, "closedOdds": 1000.0, "maxPrematch": 2.28, "minPrematch": 1.85, "maxInPlay": 1000.0, "minInPlay": 1.25, "inPlayIndex": 3553, "lengthOdds": 3859, "lengthOddsPrematch": 3553, "lengthOddsInPlay": 306, "tradedVolume": 514237.48, "preMatchVolume": 418300.51, "inPlayVolume": 95936.97}, {"id": 10709204, "name": "Frodon", "status": "WINNER", "position": 2, "inPlayOdds": 2.36, "inPlayTime": 1578751539952, "avgPrematch": 2.73, "closedOdds": 1.01, "maxPrematch": 3.7, "minPrematch": 2.3, "maxInPlay": 7.0, "minInPlay": 1.01, "inPlayIndex": 4747, "lengthOdds": 5054, "lengthOddsPrematch": 4747, "lengthOddsInPlay": 307, "tradedVolume": 461587.43, "preMatchVolume": 288253.98, "inPlayVolume": 173333.45}, {"id": 9517702, "name": "Kauto Riko", "status": "LOSER", "position": 3, "inPlayOdds": 19.5, "inPlayTime": 1578751539952, "avgPrematch": 11.41, "closedOdds": 1000.0, "maxPrematch": 23.0, "minPrematch": 7.2, "maxInPlay": 1000.0, "minInPlay": 10.5, "inPlayIndex": 2913, "lengthOdds": 3213, "lengthOddsPrematch": 2913, "lengthOddsInPlay": 300, "tradedVolume": 63809.26, "preMatchVolume": 56788.27, "inPlayVolume": 7020.99}, {"id": 10539153, "name": "Keeper Hill", "status": "LOSER", "position": 4, "inPlayOdds": 20.0, "inPlayTime": 1578751539952, "avgPrematch": 22.67, "closedOdds": 1000.0, "maxPrematch": 42.0, "minPrematch": 16.5, "maxInPlay": 1000.0, "minInPlay": 1.66, "inPlayIndex": 2910, "lengthOdds": 3217, "lengthOddsPrematch": 2910, "lengthOddsInPlay": 307, "tradedVolume": 54268.16, "preMatchVolume": 30754.48, "inPlayVolume": 23513.68}, {"id": 10612432, "name": "Born Survivor", "status": "LOSER", "position": 5, "inPlayOdds": 55.0, "inPlayTime": 1578751539952, "avgPrematch": 40.93, "closedOdds": 1000.0, "maxPrematch": 80.0, "minPrematch": 21.0, "maxInPlay": 1000.0, "minInPlay": 22.0, "inPlayIndex": 2209, "lengthOdds": 2511, "lengthOddsPrematch": 2209, "lengthOddsInPlay": 302, "tradedVolume": 16290.24, "preMatchVolume": 11537.17, "inPlayVolume": 4753.07}], "marketUpdates": [{"timestamp": 1578655090867000000, "openDate": "2020-01-11T12:20:00.000Z", "status": "OPEN", "betDelay": 0, "inPlay": false, "complete": true}, {"timestamp": 1578751539952000000, "openDate": "2020-01-11T12:20:00.000Z", "status": "OPEN", "betDelay": 1, "inPlay": true, "complete": true}, {"timestamp": 1578751845806000000, "openDate": "2020-01-11T12:20:00.000Z", "status": "SUSPENDED", "betDelay": 1, "inPlay": true, "complete": true}, {"timestamp": 1578752008975000000, "openDate": "2020-01-11T12:20:00.000Z", "status": "CLOSED", "betDelay": 1, "inPlay": true, "complete": true}], "odds": [{"runnerId": 140424, "odds": [{"timestamp": 1578657624702, "ltp": 1.89, "tv": 200.0, "trd": [[1.89, 159.84], [1.9, 36.21], [1.91, 3.96]], "batb": [[0, 1.89, 71.58], [1, 1.84, 6], [2, 1.83, 162.45]], "batl": NaN}, {"timestamp": 1578657625599, "ltp": 1.89, "tv": 200.0, "trd": NaN, "batb": [[0, 1.89, 151.5]], "batl": NaN}, {"timestamp": 1578657654459, "ltp": 1.89, "tv": 200.0, "trd": NaN, "batb": NaN, "batl": [[0, 2.08, 2.74], [1, 2.1, 122.58]]}, {"timestamp": 1578657813111, "ltp": 1.89, "tv": 200.0, "trd": NaN, "batb": NaN, "batl": [[0, 2.06, 2], [1, 2.08, 2.74], [2, 2.1, 122.58]]}, {"timestamp": 1578658224517, "ltp": 1.89, "tv": 200.0, "trd": NaN, "batb": [[0, 1.9, 1.98], [1, 1.89, 151.5], [2, 1.84, 6]], "batl": NaN}, {"timestamp": 1578660696323, "ltp": 1.89, "tv": 200.0, "trd": NaN, "batb": NaN, "batl": [[0, 2.02, 4], [1, 2.06, 2], [2, 2.08, 2.74]]}, {"timestamp": 1578660705644, "ltp": 1.89, "tv": 200.0, "trd": NaN, "batb": NaN, "batl": [[2, 2.1, 122.58]]}, {"timestamp": 1578660762927, "ltp": 1.89, "tv": 200.0, "trd": NaN, "batb": NaN, "batl": [[1, 2.1, 122.58], [2, 2.1, 0]]}, {"timestamp": 1578660763135, "ltp": 1.89, "tv": 200.0, "trd": NaN, "batb": NaN, "batl": [[1, 2.08, 2], [2, 2.1, 122.58]]}, {"timestamp": 1578661250130, "ltp": 1.89, "tv": 199.99, "trd": [[1.9, 36.2], [1.91, 3.96]], "batb": [[0, 1.9, 1.98]], "batl": [[0, 2, 2.85], [1, 2.02, 4], [2, 2.08, 2]]}, {"timestamp": 1578661259416, "ltp": 1.89, "tv": 199.99, "trd": NaN, "batb": NaN, "batl": [[2, 2.1, 122.58]]}, {"timestamp": 1578661417738, "ltp": 1.89, "tv": 199.99, "trd": NaN, "batb": NaN, "batl": [[0, 1.99, 2], [1, 2, 2.85], [2, 2.02, 4]]}, {"timestamp": 1578661536864, "ltp": 1.89, "tv": 199.99, "trd": NaN, "batb": NaN, "batl": [[0, 1.99, 38.06]]}, {"timestamp": 1578661669994, "ltp": 1.89, "tv": 199.99, "trd": NaN, "batb": NaN, "batl": [[0, 1.99, 2], [1, 2, 14.08]]}, {"timestamp": 1578663132007, "ltp": 1.89, "tv": 459.98, "trd": [[1.89, 415.88], [1.9, 40.15]], "batb": [[0, 1.89, 23.48], [1, 1.84, 6], [2, 1.83, 162.45]], "batl": NaN}, {"timestamp": 1578663136899, "ltp": 1.89, "tv": 459.98, "trd": NaN, "batb": [[0, 1.84, 6], [1, 1.83, 162.45], [2, 1.8, 42.87]], "batl": NaN}, {"timestamp": 1578663342000, "ltp": 1.99, "tv": 463.98, "trd": [[1.99, 4]], "batb": NaN, "batl": [[0, 2, 14.08], [1, 2.02, 4], [2, 2.1, 122.58]]}, {"timestamp": 1578663348613, "ltp": 1.99, "tv": 463.98, "trd": NaN, "batb": [[0, 1.85, 3], [1, 1.84, 6], [2, 1.83, 162.45]], "batl": NaN}, {"timestamp": 1578663375024, "ltp": 2.0, "tv": 491.99, "trd": [[2, 28]], "batb": NaN, "batl": [[0, 2.02, 4.08], [1, 2.1, 122.58], [2, 2.1, 0]]}, {"timestamp": 1578663377941, "ltp": 2.0, "tv": 491.99, "trd": NaN, "batb": NaN, "batl": [[0, 2.02, 4], [1, 2.08, 23.78], [2, 2.1, 122.58]]}, {"timestamp": 1578663390483, "ltp": 2.0, "tv": 491.99, "trd": NaN, "batb": [[0, 1.86, 2.14], [1, 1.85, 3], [2, 1.84, 6]], "batl": NaN}, {"timestamp": 1578663395788, "ltp": 2.0, "tv": 491.99, "trd": NaN, "batb": [[0, 1.87, 3], [1, 1.86, 2.14]], "batl": NaN}, {"timestamp": 1578663411949, "ltp": 2.0, "tv": 491.99, "trd": NaN, "batb": NaN, "batl": [[0, 2, 6.95], [1, 2.02, 4]]}, {"timestamp": 1578663464740, "ltp": 2.0, "tv": 503.98, "trd": [[2, 40]], "batb": NaN, "batl": [[0, 2.02, 4.95], [1, 2.1, 122.58], [2, 2.1, 0]]}, {"timestamp": 1578663465519, "ltp": 2.0, "tv": 503.98, "trd": NaN, "batb": [[0, 1.88, 2.12], [1, 1.87, 3]], "batl": NaN}, {"timestamp": 1578663472603, "ltp": 2.0, "tv": 503.98, "trd": NaN, "batb": [[0, 1.89, 3], [1, 1.88, 2.12]], "batl": NaN}, {"timestamp": 1578663481916, "ltp": 2.0, "tv": 503.98, "trd": NaN, "batb": NaN, "batl": [[0, 2.02, 4], [1, 2.08, 18.01], [2, 2.1, 122.58]]}, {"timestamp": 1578663516644, "ltp": 2.0, "tv": 503.98, "trd": NaN, "batb": NaN, "batl": [[0, 2, 5.5], [1, 2.02, 4]]}, {"timestamp": 1578663540925, "ltp": 2.0, "tv": 503.98, "trd": NaN, "batb": [[0, 1.9, 2.09], [1, 1.84, 6], [2, 1.83, 162.45]], "batl": NaN}, {"timestamp": 1578663541029, "ltp": 2.0, "tv": 503.98, "trd": NaN, "batb": [[0, 1.91, 3], [1, 1.9, 2.09], [2, 1.84, 6]], "batl": NaN}, {"timestamp": 1578663614955, "ltp": 2.0, "tv": 503.98, "trd": NaN, "batb": [[1, 1.84, 6], [2, 1.83, 162.45]], "batl": NaN}, {"timestamp": 1578663615161, "ltp": 2.0, "tv": 503.98, "trd": NaN, "batb": [[0, 1.92, 2.07], [1, 1.91, 3], [2, 1.84, 6]], "batl": NaN}, {"timestamp": 1578663732426, "ltp": 2.0, "tv": 503.98, "trd": NaN, "batb": [[0, 1.92, 11.35]], "batl": NaN}, {"timestamp": 1578664934590, "ltp": 2.0, "tv": 503.98, "trd": NaN, "batb": [[0, 1.92, 21.35]], "batl": NaN}, {"timestamp": 1578664983039, "ltp": 2.0, "tv": 503.98, "trd": NaN, "batb": [[0, 1.92, 11.35]], "batl": NaN}, {"timestamp": 1578665100821, "ltp": 2.0, "tv": 503.98, "trd": NaN, "batb": [[2, 1.9, 159.81]], "batl": [[2, 2.1, 0]]}, {"timestamp": 1578665105393, "ltp": 2.0, "tv": 503.98, "trd": NaN, "batb": NaN, "batl": [[2, 2.08, 133.17]]}, {"timestamp": 1578665505606, "ltp": 1.92, "tv": 526.69, "trd": [[1.92, 22.71]], "batb": [[0, 1.91, 3], [1, 1.9, 159.81], [2, 1.86, 6]], "batl": [[0, 1.92, 55.64], [1, 2, 5.5], [2, 2.02, 4]]}, {"timestamp": 1578665511982, "ltp": 1.9, "tv": 637.97, "trd": [[1.9, 145.43], [1.91, 9.96]], "batb": [[0, 1.9, 107.17], [1, 1.86, 6], [2, 1.85, 169.21]], "batl": [[0, 2, 5.5], [1, 2.02, 4], [2, 2.08, 133.17]]}, {"timestamp": 1578665512191, "ltp": 1.9, "tv": 637.97, "trd": NaN, "batb": [[0, 1.9, 159.81]], "batl": NaN}, {"timestamp": 1578665563757, "ltp": 1.9, "tv": 637.97, "trd": NaN, "batb": [[0, 1.9, 162.01]], "batl": NaN}, {"timestamp": 1578665603885, "ltp": 1.9, "tv": 637.97, "trd": NaN, "batb": NaN, "batl": [[0, 1.99, 2], [1, 2, 5.5], [2, 2.02, 4]]}, {"timestamp": 1578665969159, "ltp": 1.9, "tv": 917.23, "trd": [[1.9, 424.69]], "batb": [[0, 1.9, 22.38]], "batl": NaN}, {"timestamp": 1578665974203, "ltp": 1.9, "tv": 917.23, "trd": NaN, "batb": [[0, 1.9, 2.2]], "batl": NaN}, {"timestamp": 1578665997802, "ltp": 1.9, "tv": 917.23, "trd": NaN, "batb": [[1, 1.87, 6.43], [2, 1.86, 6]], "batl": NaN}, {"timestamp": 1578666168310, "ltp": 1.9, "tv": 917.23, "trd": NaN, "batb": [[0, 1.88, 2.2]], "batl": NaN}, {"timestamp": 1578666499920, "ltp": 1.9, "tv": 917.23, "trd": NaN, "batb": [[0, 1.89, 100], [1, 1.88, 2.2], [2, 1.87, 6.43]], "batl": NaN}, {"timestamp": 1578666786408, "ltp": 1.9, "tv": 917.23, "trd": NaN, "batb": [[0, 1.89, 102.2], [1, 1.87, 6.43], [2, 1.86, 6]], "batl": NaN}, {"timestamp": 1578668625903, "ltp": 1.9, "tv": 917.29, "trd": [[1.9, 424.71], [1.91, 9.96], [1.92, 22.73], [2, 40.03]], "batb": [[0, 1.89, 102.2], [1, 1.87, 6.44]], "batl": [[1, 2, 5.51]]}, {"timestamp": 1578669429917, "ltp": 1.9, "tv": 917.29, "trd": NaN, "batb": NaN, "batl": [[0, 1.95, 33], [1, 1.99, 2], [2, 2, 5.51]]}, {"timestamp": 1578669485858, "ltp": 1.9, "tv": 917.29, "trd": NaN, "batb": [[0, 1.9, 3], [1, 1.89, 102.2], [2, 1.87, 6.44]], "batl": NaN}, {"timestamp": 1578669868905, "ltp": 1.9, "tv": 917.29, "trd": NaN, "batb": [[1, 1.89, 100]], "batl": NaN}, {"timestamp": 1578669869012, "ltp": 1.9, "tv": 917.29, "trd": NaN, "batb": [[0, 1.9, 5.2]], "batl": NaN}, {"timestamp": 1578670035827, "ltp": 1.95, "tv": 983.29, "trd": [[1.95, 66]], "batb": [[0, 1.95, 17], [1, 1.9, 5.2], [2, 1.89, 100]], "batl": [[0, 1.99, 2], [1, 2, 5.51], [2, 2.02, 4]]}, {"timestamp": 1578670038918, "ltp": 1.95, "tv": 983.29, "trd": NaN, "batb": [[1, 1.9, 2.2]], "batl": NaN}, {"timestamp": 1578670042014, "ltp": 1.95, "tv": 983.29, "trd": NaN, "batb": NaN, "batl": [[1, 2.02, 4], [2, 2.06, 6]]}, {"timestamp": 1578670045842, "ltp": 1.95, "tv": 983.29, "trd": NaN, "batb": NaN, "batl": [[2, 2.06, 15.83]]}, {"timestamp": 1578670061859, "ltp": 1.95, "tv": 983.29, "trd": NaN, "batb": NaN, "batl": [[1, 2, 4], [2, 2.02, 4]]}, {"timestamp": 1578670065472, "ltp": 1.95, "tv": 1017.29, "trd": [[1.95, 100]], "batb": [[0, 1.9, 2.2], [1, 1.89, 100], [2, 1.86, 6]], "batl": [[0, 1.94, 583], [1, 1.99, 2], [2, 2, 4]]}, {"timestamp": 1578670073855, "ltp": 1.95, "tv": 1017.29, "trd": NaN, "batb": [[0, 1.9, 8.54]], "batl": NaN}, {"timestamp": 1578670079959, "ltp": 1.95, "tv": 1017.29, "trd": NaN, "batb": NaN, "batl": [[0, 1.93, 8.74], [1, 1.94, 583], [2, 1.99, 2]]}, {"timestamp": 1578670096718, "ltp": 1.95, "tv": 1017.29, "trd": NaN, "batb": NaN, "batl": [[2, 2.02, 4]]}, {"timestamp": 1578670824387, "ltp": 1.9, "tv": 1034.37, "trd": [[1.9, 441.78]], "batb": [[0, 1.89, 100], [1, 1.86, 6], [2, 1.85, 169.21]], "batl": [[0, 1.9, 116.46], [1, 1.93, 8.74], [2, 1.94, 583]]}, {"timestamp": 1578670825506, "ltp": 1.9, "tv": 1034.37, "trd": NaN, "batb": NaN, "batl": [[1, 1.94, 583], [2, 2.02, 4]]}, {"timestamp": 1578670827224, "ltp": 1.9, "tv": 1034.37, "trd": NaN, "batb": [[2, 1.8, 19.08]], "batl": NaN}, {"timestamp": 1578670830736, "ltp": 1.89, "tv": 1234.37, "trd": [[1.89, 615.88]], "batb": [[0, 1.86, 6], [1, 1.8, 19.08], [2, 1.71, 9.71]], "batl": [[0, 1.89, 16.46]]}, {"timestamp": 1578670839614, "ltp": 1.89, "tv": 1234.37, "trd": NaN, "batb": [[0, 1.8, 19.08], [1, 1.71, 9.71], [2, 1.4, 44]], "batl": NaN}, {"timestamp": 1578670842816, "ltp": 1.85, "tv": 1238.37, "trd": [[1.85, 4]], "batb": [[0, 1.86, 11], [1, 1.85, 167.21], [2, 1.8, 136.61]], "batl": NaN}, {"timestamp": 1578670847534, "ltp": 1.85, "tv": 1238.37, "trd": NaN, "batb": [[1, 1.85, 169.21], [2, 1.8, 134.57]], "batl": NaN}, {"timestamp": 1578670856345, "ltp": 1.89, "tv": 1253.57, "trd": [[1.89, 631.08]], "batb": NaN, "batl": [[0, 1.89, 8.86]]}, {"timestamp": 1578670861967, "ltp": 1.89, "tv": 1253.57, "trd": NaN, "batb": [[0, 1.87, 8.83], [1, 1.86, 11], [2, 1.85, 169.21]], "batl": NaN}, {"timestamp": 1578670873597, "ltp": 1.89, "tv": 1271.29, "trd": [[1.89, 648.8]], "batb": NaN, "batl": [[0, 1.94, 583], [1, 2.02, 4], [2, 2.08, 133.17]]}, {"timestamp": 1578670876494, "ltp": 1.89, "tv": 1271.29, "trd": NaN, "batb": NaN, "batl": [[0, 1.93, 10.75], [1, 1.94, 583], [2, 2.02, 4]]}, {"timestamp": 1578671100916, "ltp": 1.89, "tv": 1271.29, "trd": NaN, "batb": [[0, 1.87, 15.39]], "batl": NaN}, {"timestamp": 1578671321772, "ltp": 1.89, "tv": 1271.29, "trd": NaN, "batb": [[0, 1.89, 100], [1, 1.87, 15.39]], "batl": NaN}, {"timestamp": 1578671335904, "ltp": 1.89, "tv": 1271.29, "trd": NaN, "batb": [[0, 1.9, 33.14], [1, 1.89, 100], [2, 1.87, 15.39]], "batl": NaN}, {"timestamp": 1578671611317, "ltp": 1.93, "tv": 1292.79, "trd": [[1.93, 21.5]], "batb": [[0, 1.93, 14.75], [1, 1.9, 33.14], [2, 1.89, 100]], "batl": [[0, 1.94, 583], [1, 2.02, 4], [2, 2.06, 6]]}, {"timestamp": 1578671634847, "ltp": 1.93, "tv": 1292.79, "trd": NaN, "batb": [[0, 1.93, 19]], "batl": NaN}, {"timestamp": 1578671635058, "ltp": 1.93, "tv": 1292.79, "trd": NaN, "batb": [[1, 1.89, 100], [2, 1.87, 15.39]], "batl": NaN}, {"timestamp": 1578671637452, "ltp": 1.93, "tv": 1292.79, "trd": NaN, "batb": [[2, 1.87, 6.56]], "batl": NaN}, {"timestamp": 1578671682149, "ltp": 1.93, "tv": 1292.79, "trd": NaN, "batb": [[1, 1.92, 8.6], [2, 1.89, 100]], "batl": NaN}, {"timestamp": 1578671907978, "ltp": 1.94, "tv": 1336.13, "trd": [[1.94, 43.34]], "batb": NaN, "batl": [[0, 1.94, 561.33]]}, {"timestamp": 1578671920547, "ltp": 1.94, "tv": 1380.13, "trd": [[1.94, 87.34]], "batb": NaN, "batl": [[0, 1.94, 539.33]]}, {"timestamp": 1578671927852, "ltp": 1.94, "tv": 1740.13, "trd": [[1.94, 447.34]], "batb": NaN, "batl": [[0, 1.94, 359.33]]}, {"timestamp": 1578671938954, "ltp": 1.94, "tv": 1747.63, "trd": [[1.94, 454.84]], "batb": NaN, "batl": [[0, 1.94, 355.58]]}, {"timestamp": 1578671954506, "ltp": 1.94, "tv": 2458.79, "trd": [[1.94, 1166]], "batb": NaN, "batl": [[0, 2.02, 4], [1, 2.06, 6], [2, 2.08, 133.17]]}, {"timestamp": 1578672348395, "ltp": 1.94, "tv": 2458.79, "trd": NaN, "batb": [[2, 1.9, 151.26]], "batl": NaN}, {"timestamp": 1578672349389, "ltp": 1.94, "tv": 2458.79, "trd": NaN, "batb": [[2, 1.91, 22.88]], "batl": NaN}, {"timestamp": 1578672457925, "ltp": 1.94, "tv": 2458.79, "trd": NaN, "batb": NaN, "batl": [[0, 2, 4], [1, 2.02, 4], [2, 2.06, 6]]}, {"timestamp": 1578672568270, "ltp": 1.94, "tv": 2458.79, "trd": NaN, "batb": [[0, 1.94, 15], [1, 1.93, 19], [2, 1.92, 8.6]], "batl": NaN}, {"timestamp": 1578672907810, "ltp": 1.94, "tv": 2458.79, "trd": NaN, "batb": NaN, "batl": [[0, 1.95, 7], [1, 2, 4], [2, 2.02, 4]]}, {"timestamp": 1578672908181, "ltp": 1.95, "tv": 2472.78, "trd": [[1.95, 113.99]], "batb": NaN, "batl": [[0, 2, 4], [1, 2.02, 4], [2, 2.06, 6]]}, {"timestamp": 1578672992742, "ltp": 1.95, "tv": 2472.78, "trd": NaN, "batb": [[0, 1.96, 14.75], [1, 1.94, 15], [2, 1.93, 4.25]], "batl": NaN}, {"timestamp": 1578672999471, "ltp": 1.95, "tv": 2472.78, "trd": NaN, "batb": NaN, "batl": [[0, 2.02, 4], [1, 2.06, 6], [2, 2.08, 133.17]]}, {"timestamp": 1578673022672, "ltp": 1.96, "tv": 2502.28, "trd": [[1.96, 29.5]], "batb": [[0, 1.94, 15], [1, 1.93, 4.25], [2, 1.92, 8.6]], "batl": [[0, 1.96, 10.25], [1, 2.02, 4], [2, 2.06, 6]]}, {"timestamp": 1578673045916, "ltp": 1.94, "tv": 2532.28, "trd": [[1.94, 1196]], "batb": [[0, 1.93, 4.25], [1, 1.92, 8.6], [2, 1.89, 100]], "batl": NaN}, {"timestamp": 1578673048820, "ltp": 1.94, "tv": 2532.28, "trd": NaN, "batb": [[2, 1.9, 10.92]], "batl": NaN}, {"timestamp": 1578673069167, "ltp": 1.94, "tv": 2532.28, "trd": NaN, "batb": NaN, "batl": [[0, 1.96, 40.25]]}, {"timestamp": 1578673093001, "ltp": 1.94, "tv": 2532.28, "trd": NaN, "batb": [[0, 1.93, 104.25]], "batl": NaN}, {"timestamp": 1578673096814, "ltp": 1.94, "tv": 2532.28, "trd": NaN, "batb": [[0, 1.94, 10.69], [1, 1.93, 104.25], [2, 1.92, 8.6]], "batl": NaN}, {"timestamp": 1578673143904, "ltp": 1.94, "tv": 2532.28, "trd": NaN, "batb": NaN, "batl": [[1, 2, 50], [2, 2.02, 4]]}, {"timestamp": 1578673215918, "ltp": 1.94, "tv": 2532.28, "trd": NaN, "batb": NaN, "batl": [[1, 2, 52]]}, {"timestamp": 1578673218213, "ltp": 1.94, "tv": 2532.28, "trd": NaN, "batb": [[0, 1.95, 3], [1, 1.94, 10.69], [2, 1.93, 104.25]], "batl": NaN}, {"timestamp": 1578673221011, "ltp": 1.94, "tv": 2532.28, "trd": NaN, "batb": [[0, 1.94, 10.69], [1, 1.93, 104.25], [2, 1.92, 8.6]], "batl": NaN}, {"timestamp": 1578673222924, "ltp": 1.94, "tv": 2532.28, "trd": NaN, "batb": NaN, "batl": [[1, 2, 53]]}, {"timestamp": 1578673229625, "ltp": 1.94, "tv": 2532.28, "trd": NaN, "batb": NaN, "batl": [[0, 1.95, 1], [1, 1.96, 40.25], [2, 2, 52]]}, {"timestamp": 1578673239726, "ltp": 1.94, "tv": 2532.28, "trd": NaN, "batb": NaN, "batl": [[2, 2, 50]]}, {"timestamp": 1578673244912, "ltp": 1.95, "tv": 2534.28, "trd": [[1.95, 115.99]], "batb": [[0, 1.95, 2.4], [1, 1.94, 10.69], [2, 1.93, 104.25]], "batl": [[0, 1.96, 40.25], [1, 2, 50], [2, 2.02, 4]]}, {"timestamp": 1578673245847, "ltp": 1.95, "tv": 2534.28, "trd": NaN, "batb": [[2, 1.93, 100]], "batl": NaN}, {"timestamp": 1578673257939, "ltp": 1.95, "tv": 2534.28, "trd": NaN, "batb": [[0, 1.95, 4.4]], "batl": NaN}, {"timestamp": 1578673420230, "ltp": 1.96, "tv": 2577.16, "trd": [[1.96, 72.38]], "batb": NaN, "batl": [[0, 1.96, 18.81]]}, {"timestamp": 1578673534675, "ltp": 1.96, "tv": 2577.16, "trd": NaN, "batb": [[0, 1.95, 2]], "batl": NaN}, {"timestamp": 1578673647371, "ltp": 1.95, "tv": 2581.16, "trd": [[1.95, 119.99]], "batb": [[0, 1.94, 10.69], [1, 1.93, 100], [2, 1.92, 8.6]], "batl": [[0, 1.95, 83], [1, 1.96, 18.81], [2, 2, 50]]}, {"timestamp": 1578673877739, "ltp": 1.95, "tv": 2747.16, "trd": [[1.95, 285.99]], "batb": [[0, 1.95, 17], [1, 1.94, 10.69], [2, 1.93, 100]], "batl": [[0, 1.96, 18.81], [1, 2, 50], [2, 2.02, 4]]}, {"timestamp": 1578673886972, "ltp": 1.95, "tv": 2747.16, "trd": NaN, "batb": [[2, 1.92, 8.6]], "batl": NaN}, {"timestamp": 1578673887857, "ltp": 1.95, "tv": 2747.16, "trd": NaN, "batb": [[1, 1.93, 25.43], [2, 1.92, 108.6]], "batl": NaN}, {"timestamp": 1578673986468, "ltp": 1.96, "tv": 2784.78, "trd": [[1.96, 110]], "batb": NaN, "batl": [[0, 2, 50], [1, 2.02, 4], [2, 2.06, 6]]}, {"timestamp": 1578673993932, "ltp": 1.96, "tv": 2784.78, "trd": NaN, "batb": [[2, 1.92, 8.6]], "batl": NaN}, {"timestamp": 1578673995856, "ltp": 1.96, "tv": 2784.78, "trd": NaN, "batb": [[1, 1.93, 6]], "batl": NaN}, {"timestamp": 1578674000946, "ltp": 1.96, "tv": 2784.78, "trd": NaN, "batb": [[1, 1.92, 8.6], [2, 1.88, 200]], "batl": NaN}, {"timestamp": 1578674011177, "ltp": 1.96, "tv": 2784.78, "trd": NaN, "batb": [[2, 1.89, 6]], "batl": NaN}, {"timestamp": 1578674084575, "ltp": 1.96, "tv": 2784.78, "trd": NaN, "batb": NaN, "batl": [[0, 1.99, 2], [1, 2, 50], [2, 2.02, 4]]}, {"timestamp": 1578674085194, "ltp": 1.96, "tv": 2784.78, "trd": NaN, "batb": NaN, "batl": [[0, 2, 50], [1, 2.02, 4], [2, 2.06, 6]]}, {"timestamp": 1578674362512, "ltp": 1.96, "tv": 2784.78, "trd": NaN, "batb": [[0, 1.96, 20.41], [1, 1.95, 17], [2, 1.92, 8.6]], "batl": NaN}, {"timestamp": 1578674369877, "ltp": 1.96, "tv": 2784.78, "trd": NaN, "batb": [[2, 1.94, 153.01]], "batl": NaN}, {"timestamp": 1578674370820, "ltp": 1.96, "tv": 2784.78, "trd": NaN, "batb": [[1, 1.95, 27.64]], "batl": NaN}, {"timestamp": 1578674372596, "ltp": 1.96, "tv": 2784.78, "trd": NaN, "batb": NaN, "batl": [[2, 2.06, 0]]}, {"timestamp": 1578674374120, "ltp": 1.96, "tv": 2784.78, "trd": NaN, "batb": NaN, "batl": [[2, 2.16, 123.99]]}, {"timestamp": 1578674375287, "ltp": 1.96, "tv": 2784.78, "trd": NaN, "batb": [[1, 1.95, 37.82]], "batl": NaN}, {"timestamp": 1578674655552, "ltp": 1.96, "tv": 2784.78, "trd": NaN, "batb": [[0, 1.97, 55], [1, 1.96, 20.41], [2, 1.95, 37.82]], "batl": NaN}, {"timestamp": 1578674672922, "ltp": 2.0, "tv": 2884.78, "trd": [[2, 140.03]], "batb": [[0, 2, 5]], "batl": [[0, 2.02, 4], [1, 2.16, 123.99], [2, 2.16, 0]]}, {"timestamp": 1578674679853, "ltp": 2.0, "tv": 2884.78, "trd": NaN, "batb": [[0, 2, 50], [2, 1.95, 27.18]], "batl": NaN}, {"timestamp": 1578674692873, "ltp": 2.02, "tv": 2892.78, "trd": [[2.02, 7.99]], "batb": [[0, 2.02, 4.18], [1, 2, 50], [2, 1.96, 20.41]], "batl": [[0, 2.16, 123.99], [1, 2.16, 0]]}, {"timestamp": 1578674693871, "ltp": 2.02, "tv": 2892.78, "trd": NaN, "batb": NaN, "batl": [[0, 2.14, 4], [1, 2.16, 123.99]]}, {"timestamp": 1578674708869, "ltp": 2.02, "tv": 2892.78, "trd": NaN, "batb": NaN, "batl": [[0, 2.1, 46], [1, 2.14, 4], [2, 2.16, 123.99]]}, {"timestamp": 1578674716671, "ltp": 2.02, "tv": 2892.78, "trd": NaN, "batb": NaN, "batl": [[1, 2.16, 123.99], [2, 2.16, 0]]}, {"timestamp": 1578674822870, "ltp": 2.02, "tv": 2892.78, "trd": NaN, "batb": NaN, "batl": [[0, 2.1, 81]]}, {"timestamp": 1578674895053, "ltp": 2.02, "tv": 2898.77, "trd": [[2.02, 13.99]], "batb": [[0, 2.02, 1.19]], "batl": NaN}, {"timestamp": 1578675141796, "ltp": 2.02, "tv": 2898.77, "trd": NaN, "batb": [[1, 2, 5], [2, 1.98, 45]], "batl": NaN}, {"timestamp": 1578675142827, "ltp": 2.02, "tv": 2901.15, "trd": [[2.02, 16.36]], "batb": [[0, 2, 5], [1, 1.98, 45], [2, 1.96, 20.41]], "batl": [[0, 2.1, 81.81]]}, {"timestamp": 1578675154301, "ltp": 2.0, "tv": 2911.15, "trd": [[2, 150.03]], "batb": [[0, 1.98, 45], [1, 1.96, 20.41], [2, 1.95, 27.18]], "batl": [[0, 2, 95], [1, 2.1, 81.81], [2, 2.16, 123.99]]}, {"timestamp": 1578675159929, "ltp": 2.0, "tv": 2911.15, "trd": NaN, "batb": [[2, 1.95, 36.49]], "batl": NaN}, {"timestamp": 1578675168139, "ltp": 2.0, "tv": 2911.15, "trd": NaN, "batb": NaN, "batl": [[2, 2.14, 6]]}, {"timestamp": 1578675335959, "ltp": 2.0, "tv": 2911.15, "trd": NaN, "batb": [[1, 1.96, 100.41]], "batl": NaN}, {"timestamp": 1578675337629, "ltp": 2.0, "tv": 2911.15, "trd": NaN, "batb": [[1, 1.97, 10.53], [2, 1.96, 100.41]], "batl": NaN}, {"timestamp": 1578675417767, "ltp": 1.98, "tv": 2921.15, "trd": [[1.98, 10]], "batb": [[0, 1.98, 40]], "batl": NaN}, {"timestamp": 1578675481167, "ltp": 1.98, "tv": 2921.15, "trd": NaN, "batb": [[0, 1.98, 54.59]], "batl": NaN}, {"timestamp": 1578675509822, "ltp": 1.98, "tv": 2921.15, "trd": NaN, "batb": [[0, 1.99, 17.85], [1, 1.98, 54.59], [2, 1.97, 10.53]], "batl": NaN}, {"timestamp": 1578675626429, "ltp": 1.98, "tv": 2921.25, "trd": [[1.9, 441.8], [1.91, 9.96], [1.92, 22.74], [1.93, 21.52], [1.95, 286.01], [2, 150.03], [2.02, 16.38]], "batb": [[0, 1.99, 17.88], [1, 1.98, 54.62], [2, 1.97, 10.55]], "batl": NaN}, {"timestamp": 1578675835691, "ltp": 1.98, "tv": 2921.25, "trd": NaN, "batb": [[0, 1.99, 37.98]], "batl": NaN}, {"timestamp": 1578675839501, "ltp": 1.98, "tv": 2921.25, "trd": NaN, "batb": [[0, 1.99, 48.42], [2, 1.96, 100.41]], "batl": NaN}, {"timestamp": 1578675840498, "ltp": 1.98, "tv": 2921.25, "trd": NaN, "batb": [[2, 1.96, 80]], "batl": NaN}, {"timestamp": 1578675846972, "ltp": 1.98, "tv": 2921.25, "trd": NaN, "batb": [[2, 1.97, 6]], "batl": NaN}, {"timestamp": 1578675943883, "ltp": 1.98, "tv": 2921.25, "trd": NaN, "batb": [[0, 1.99, 30.55]], "batl": NaN}, {"timestamp": 1578675945824, "ltp": 1.98, "tv": 2921.25, "trd": NaN, "batb": [[0, 1.99, 20.1], [2, 1.97, 16.55]], "batl": NaN}, {"timestamp": 1578676182914, "ltp": 2.0, "tv": 3111.25, "trd": [[2, 340.03]], "batb": [[0, 2, 105], [1, 1.99, 20.1], [2, 1.98, 54.62]], "batl": [[0, 2.1, 81.81], [1, 2.14, 6], [2, 2.16, 123.99]]}, {"timestamp": 1578676185204, "ltp": 2.02, "tv": 3112.87, "trd": [[2.02, 18]], "batb": [[0, 2.02, 9.48], [1, 2, 105], [2, 1.99, 20.1]], "batl": [[0, 2.1, 81]]}, {"timestamp": 1578676227394, "ltp": 2.1, "tv": 3132.39, "trd": [[2.1, 19.52]], "batb": NaN, "batl": [[0, 2.1, 71.24]]}, {"timestamp": 1578676255503, "ltp": 2.1, "tv": 3132.39, "trd": NaN, "batb": [[0, 2.02, 19.24]], "batl": NaN}, {"timestamp": 1578676319273, "ltp": 2.1, "tv": 3132.39, "trd": NaN, "batb": NaN, "batl": [[0, 2.08, 2], [1, 2.1, 71.24], [2, 2.14, 6]]}, {"timestamp": 1578676359719, "ltp": 2.02, "tv": 3170.39, "trd": [[2.02, 56]], "batb": [[0, 2, 105.24], [1, 1.99, 20.1], [2, 1.98, 54.62]], "batl": NaN}, {"timestamp": 1578676485463, "ltp": 2.0, "tv": 3176.39, "trd": [[2, 345.55], [2.02, 56.48]], "batb": [[0, 2, 102.24]], "batl": NaN}, {"timestamp": 1578676817869, "ltp": 2.0, "tv": 3176.39, "trd": NaN, "batb": [[0, 2.02, 33], [1, 2, 102.24], [2, 1.99, 20.1]], "batl": NaN}, {"timestamp": 1578676907652, "ltp": 2.0, "tv": 3176.39, "trd": NaN, "batb": [[1, 2, 2102.24]], "batl": NaN}, {"timestamp": 1578676908178, "ltp": 2.0, "tv": 3176.39, "trd": NaN, "batb": [[0, 2.02, 44.66]], "batl": NaN}, {"timestamp": 1578677071482, "ltp": 2.02, "tv": 3264.39, "trd": [[2.02, 144.48]], "batb": [[0, 2, 2102.9], [1, 1.99, 20.1], [2, 1.98, 54.62]], "batl": NaN}, {"timestamp": 1578677079860, "ltp": 2.02, "tv": 3264.39, "trd": NaN, "batb": NaN, "batl": [[0, 2.04, 50], [1, 2.08, 2], [2, 2.1, 71.24]]}, {"timestamp": 1578677080067, "ltp": 2.04, "tv": 3284.13, "trd": [[2.04, 19.74]], "batb": NaN, "batl": [[0, 2.04, 40.13]]}, {"timestamp": 1578677082764, "ltp": 2.04, "tv": 3284.13, "trd": NaN, "batb": [[0, 2, 302.9]], "batl": NaN}, {"timestamp": 1578677093569, "ltp": 2.0, "tv": 3334.13, "trd": [[2, 394.23], [2.02, 145.81]], "batb": [[0, 2, 277.9]], "batl": NaN}, {"timestamp": 1578677095710, "ltp": 2.0, "tv": 3334.13, "trd": NaN, "batb": NaN, "batl": [[1, 2.08, 13.33]]}, {"timestamp": 1578677195877, "ltp": 2.0, "tv": 3334.13, "trd": NaN, "batb": NaN, "batl": [[1, 2.06, 14.81], [2, 2.08, 2358.33]]}, {"timestamp": 1578677213686, "ltp": 2.0, "tv": 3489.93, "trd": [[2, 550.03]], "batb": [[0, 1.99, 20.1], [1, 1.98, 54.62], [2, 1.97, 6]], "batl": [[0, 2, 944.1], [1, 2.04, 40.13], [2, 2.06, 14.81]]}, {"timestamp": 1578677215606, "ltp": 2.0, "tv": 3539.93, "trd": [[2, 600.03]], "batb": NaN, "batl": [[0, 2, 919.1]]}, {"timestamp": 1578677216603, "ltp": 2.0, "tv": 3539.93, "trd": NaN, "batb": NaN, "batl": [[0, 2, 930.88], [2, 2.08, 2347]]}, {"timestamp": 1578677217701, "ltp": 2.0, "tv": 3653.93, "trd": [[2, 714.03]], "batb": NaN, "batl": [[0, 2, 873.88]]}, {"timestamp": 1578677219008, "ltp": 2.0, "tv": 3817.13, "trd": [[2, 877.23]], "batb": NaN, "batl": [[0, 2, 792.28]]}, {"timestamp": 1578677220994, "ltp": 2.0, "tv": 3817.13, "trd": NaN, "batb": NaN, "batl": [[0, 2, 11.78], [1, 2.02, 780.5], [2, 2.04, 40.13]]}, {"timestamp": 1578677223794, "ltp": 2.0, "tv": 3817.13, "trd": NaN, "batb": NaN, "batl": [[0, 2, 24.98]]}, {"timestamp": 1578677235410, "ltp": 2.0, "tv": 3817.13, "trd": NaN, "batb": [[0, 1.99, 44.79]], "batl": NaN}, {"timestamp": 1578677244297, "ltp": 2.0, "tv": 3867.09, "trd": [[2, 927.19]], "batb": [[0, 2, 96.02], [1, 1.99, 44.79], [2, 1.98, 54.62]], "batl": [[0, 2.02, 780.5], [1, 2.04, 40.13], [2, 2.06, 6]]}, {"timestamp": 1578677246704, "ltp": 2.0, "tv": 3867.09, "trd": NaN, "batb": [[0, 2, 109.22]], "batl": NaN}, {"timestamp": 1578677255622, "ltp": 2.0, "tv": 3867.09, "trd": NaN, "batb": NaN, "batl": [[2, 2.06, 1240]]}, {"timestamp": 1578677276855, "ltp": 2.0, "tv": 4085.52, "trd": [[2, 1145.62]], "batb": [[0, 1.99, 44.79], [1, 1.98, 54.62], [2, 1.97, 6]], "batl": NaN}, {"timestamp": 1578677293149, "ltp": 2.0, "tv": 4085.52, "trd": NaN, "batb": [[0, 2, 87], [1, 1.99, 44.79], [2, 1.98, 54.62]], "batl": NaN}, {"timestamp": 1578677306978, "ltp": 2.0, "tv": 4085.52, "trd": NaN, "batb": NaN, "batl": [[1, 2.04, 1363.13]]}, {"timestamp": 1578677360384, "ltp": 2.0, "tv": 4259.52, "trd": [[2, 1319.62]], "batb": [[0, 1.99, 44.79], [1, 1.98, 54.62], [2, 1.97, 6]], "batl": NaN}, {"timestamp": 1578677363922, "ltp": 2.0, "tv": 4259.52, "trd": NaN, "batb": NaN, "batl": [[0, 2, 42], [1, 2.02, 780.5], [2, 2.04, 1363.13]]}, {"timestamp": 1578677371548, "ltp": 2.0, "tv": 4343.52, "trd": [[2, 1403.61]], "batb": [[0, 2, 35], [1, 1.99, 44.79], [2, 1.98, 54.62]], "batl": [[0, 2.02, 780.5], [1, 2.04, 1363.13], [2, 2.06, 1240]]}, {"timestamp": 1578677374343, "ltp": 2.0, "tv": 4343.52, "trd": NaN, "batb": [[1, 1.99, 87]], "batl": NaN}, {"timestamp": 1578677496791, "ltp": 2.0, "tv": 4343.52, "trd": NaN, "batb": [[2, 1.98, 87.62]], "batl": NaN}, {"timestamp": 1578677567187, "ltp": 2.0, "tv": 4343.52, "trd": NaN, "batb": [[0, 2, 79]], "batl": NaN}, {"timestamp": 1578677664562, "ltp": 2.0, "tv": 4343.52, "trd": NaN, "batb": NaN, "batl": [[0, 2.04, 1363.13], [1, 2.06, 2020.5], [2, 2.08, 2347]]}, {"timestamp": 1578677666960, "ltp": 2.0, "tv": 4343.52, "trd": NaN, "batb": [[0, 2.02, 25.54], [1, 2, 79], [2, 1.99, 62.31]], "batl": NaN}, {"timestamp": 1578677669456, "ltp": 2.0, "tv": 4343.52, "trd": NaN, "batb": [[0, 2.02, 67.12], [2, 1.99, 20.1]], "batl": NaN}, {"timestamp": 1578677710930, "ltp": 2.02, "tv": 4477.76, "trd": [[2.02, 280.05]], "batb": [[0, 2, 79], [1, 1.99, 20.1], [2, 1.98, 87.62]], "batl": [[0, 2.02, 3093.88], [1, 2.04, 1363.13], [2, 2.06, 2020.5]]}, {"timestamp": 1578677725643, "ltp": 2.02, "tv": 4477.76, "trd": NaN, "batb": [[0, 1.99, 20.1], [1, 1.98, 87.62], [2, 1.97, 6]], "batl": NaN}, {"timestamp": 1578677729620, "ltp": 2.0, "tv": 4561.75, "trd": [[2, 1487.61]], "batb": NaN, "batl": [[0, 2, 1.77], [1, 2.02, 3093.88], [2, 2.04, 1363.13]]}, {"timestamp": 1578677802815, "ltp": 2.0, "tv": 4561.75, "trd": NaN, "batb": [[0, 1.99, 53.1]], "batl": NaN}, {"timestamp": 1578677827751, "ltp": 2.0, "tv": 4561.75, "trd": NaN, "batb": [[0, 1.99, 99.07]], "batl": NaN}, {"timestamp": 1578677831832, "ltp": 2.0, "tv": 4561.75, "trd": NaN, "batb": NaN, "batl": [[0, 2.02, 3093.88], [1, 2.04, 1363.13], [2, 2.06, 2020.5]]}, {"timestamp": 1578677834240, "ltp": 2.0, "tv": 4561.75, "trd": NaN, "batb": [[0, 2, 42], [1, 1.99, 99.07], [2, 1.98, 87.62]], "batl": NaN}, {"timestamp": 1578677904918, "ltp": 2.0, "tv": 4641.75, "trd": [[2, 1567.61]], "batb": [[0, 2, 2]], "batl": NaN}, {"timestamp": 1578677906543, "ltp": 2.0, "tv": 4645.75, "trd": [[2, 1571.61]], "batb": NaN, "batl": NaN}, {"timestamp": 1578677914250, "ltp": 2.0, "tv": 4645.75, "trd": NaN, "batb": [[0, 2, 35]], "batl": NaN}, {"timestamp": 1578677932542, "ltp": 2.0, "tv": 4715.75, "trd": [[2, 1641.61]], "batb": [[0, 1.99, 99.07], [1, 1.98, 87.62], [2, 1.97, 6]], "batl": NaN}, {"timestamp": 1578677941165, "ltp": 2.0, "tv": 4715.75, "trd": NaN, "batb": [[0, 2, 44], [1, 1.99, 99.07], [2, 1.98, 87.62]], "batl": NaN}, {"timestamp": 1578677942490, "ltp": 2.0, "tv": 4719.75, "trd": [[2, 1645.61]], "batb": [[0, 2, 42]], "batl": NaN}, {"timestamp": 1578678180998, "ltp": 2.0, "tv": 4719.75, "trd": NaN, "batb": NaN, "batl": [[0, 2.04, 1363.13], [1, 2.06, 2020.5], [2, 2.08, 2347]]}, {"timestamp": 1578678181884, "ltp": 2.0, "tv": 4719.75, "trd": NaN, "batb": NaN, "batl": [[0, 2.02, 46.19], [1, 2.04, 1363.13], [2, 2.06, 5114.38]]}, {"timestamp": 1578678267675, "ltp": 2.0, "tv": 4719.75, "trd": NaN, "batb": NaN, "batl": [[0, 2.02, 117.43]]}, {"timestamp": 1578678314095, "ltp": 2.0, "tv": 4719.75, "trd": NaN, "batb": [[0, 2, 97]], "batl": NaN}, {"timestamp": 1578678317018, "ltp": 2.0, "tv": 4719.75, "trd": NaN, "batb": NaN, "batl": [[0, 2.02, 71.24]]}, {"timestamp": 1578678328626, "ltp": 2.0, "tv": 4719.75, "trd": NaN, "batb": [[0, 2, 42]], "batl": NaN}, {"timestamp": 1578678358360, "ltp": 2.0, "tv": 4719.75, "trd": NaN, "batb": NaN, "batl": [[0, 2.02, 117.43]]}, {"timestamp": 1578678605929, "ltp": 2.0, "tv": 4719.75, "trd": NaN, "batb": NaN, "batl": [[1, 2.04, 1501.42]]}, {"timestamp": 1578678700002, "ltp": 2.0, "tv": 4719.75, "trd": NaN, "batb": [[0, 2, 184.86]], "batl": [[0, 2.02, 71.24]]}, {"timestamp": 1578678943775, "ltp": 2.0, "tv": 4719.75, "trd": NaN, "batb": NaN, "batl": [[0, 2.02, 73.79]]}, {"timestamp": 1578678952267, "ltp": 2.0, "tv": 4719.75, "trd": NaN, "batb": NaN, "batl": [[1, 2.04, 1461.29]]}, {"timestamp": 1578678971616, "ltp": 2.02, "tv": 4867.34, "trd": [[2.02, 427.63]], "batb": NaN, "batl": [[0, 2.04, 1461.29], [1, 2.06, 5114.38], [2, 2.08, 2347]]}, {"timestamp": 1578678973531, "ltp": 2.02, "tv": 4867.34, "trd": NaN, "batb": [[0, 2.02, 61.3], [1, 2, 184.86], [2, 1.99, 53.1]], "batl": NaN}, {"timestamp": 1578678985407, "ltp": 2.02, "tv": 4867.34, "trd": NaN, "batb": NaN, "batl": [[0, 2.04, 138.29]]}, {"timestamp": 1578678998235, "ltp": 2.02, "tv": 4867.34, "trd": NaN, "batb": NaN, "batl": [[1, 2.06, 6], [2, 2.08, 2]]}, {"timestamp": 1578679001123, "ltp": 2.02, "tv": 4867.34, "trd": NaN, "batb": NaN, "batl": [[1, 2.08, 2], [2, 2.08, 0]]}, {"timestamp": 1578679047768, "ltp": 2.04, "tv": 5143.92, "trd": [[2.04, 296.32]], "batb": [[0, 2.04, 3861.71], [1, 2.02, 61.3], [2, 2, 184.86]], "batl": [[0, 2.08, 2], [1, 2.14, 126.16]]}, {"timestamp": 1578679048599, "ltp": 2.04, "tv": 5143.92, "trd": NaN, "batb": [[0, 2.06, 13.92], [1, 2.04, 3861.71], [2, 2.02, 61.3]], "batl": [[1, 2.12, 8.76], [2, 2.14, 126.16]]}, {"timestamp": 1578679049586, "ltp": 2.04, "tv": 5143.92, "trd": NaN, "batb": [[0, 2.06, 26.77]], "batl": NaN}, {"timestamp": 1578679053707, "ltp": 2.04, "tv": 5143.92, "trd": NaN, "batb": NaN, "batl": [[1, 2.12, 18.22]]}, {"timestamp": 1578679100750, "ltp": 2.04, "tv": 5143.92, "trd": NaN, "batb": [[2, 2.02, 1261.3]], "batl": NaN}, {"timestamp": 1578679129147, "ltp": 2.04, "tv": 5143.92, "trd": NaN, "batb": NaN, "batl": [[0, 2.08, 9]]}, {"timestamp": 1578679138044, "ltp": 2.04, "tv": 5143.92, "trd": NaN, "batb": NaN, "batl": [[1, 2.12, 28.22]]}, {"timestamp": 1578679139373, "ltp": 2.04, "tv": 5143.92, "trd": NaN, "batb": NaN, "batl": [[0, 2.08, 2]]}, {"timestamp": 1578679154966, "ltp": 2.06, "tv": 5195.92, "trd": [[2.06, 52]], "batb": [[0, 2.04, 3862.48], [1, 2.02, 1261.3], [2, 2, 264.21]], "batl": NaN}, {"timestamp": 1578679163604, "ltp": 2.06, "tv": 5195.92, "trd": NaN, "batb": [[2, 2, 192.35]], "batl": NaN}, {"timestamp": 1578679168581, "ltp": 2.06, "tv": 5195.92, "trd": NaN, "batb": [[0, 2.06, 71.77], [1, 2.04, 3861.71], [2, 2.02, 1261.3]], "batl": NaN}, {"timestamp": 1578679174817, "ltp": 2.06, "tv": 5195.92, "trd": NaN, "batb": NaN, "batl": [[1, 2.12, 38.67]]}, {"timestamp": 1578679188904, "ltp": 2.06, "tv": 5337.91, "trd": [[2.06, 194]], "batb": [[0, 2.04, 3862.48], [1, 2.02, 1261.3], [2, 2, 192.35]], "batl": NaN}, {"timestamp": 1578679206752, "ltp": 2.06, "tv": 5337.91, "trd": NaN, "batb": NaN, "batl": [[1, 2.12, 48.13]]}, {"timestamp": 1578679264335, "ltp": 2.06, "tv": 5337.91, "trd": NaN, "batb": NaN, "batl": [[0, 2.08, 25.15]]}, {"timestamp": 1578679385567, "ltp": 2.06, "tv": 5337.91, "trd": NaN, "batb": NaN, "batl": [[1, 2.1, 111], [2, 2.12, 48.13]]}, {"timestamp": 1578679387557, "ltp": 2.06, "tv": 5337.91, "trd": NaN, "batb": NaN, "batl": [[0, 2.08, 48.32], [2, 2.12, 28.93]]}, {"timestamp": 1578679390471, "ltp": 2.06, "tv": 5337.91, "trd": NaN, "batb": NaN, "batl": [[0, 2.08, 70.42], [2, 2.12, 10]]}, {"timestamp": 1578679401618, "ltp": 2.06, "tv": 5337.91, "trd": NaN, "batb": [[0, 2.02, 1262.07], [1, 2, 4054.06], [2, 1.99, 53.1]], "batl": NaN}, {"timestamp": 1578679408432, "ltp": 2.06, "tv": 5337.91, "trd": NaN, "batb": [[0, 2.04, 6.77], [1, 2.02, 1261.3], [2, 2, 4054.06]], "batl": NaN}, {"timestamp": 1578679431471, "ltp": 2.06, "tv": 5339.45, "trd": [[2.06, 195.54]], "batb": [[0, 2.04, 6]], "batl": [[0, 2.06, 1.23], [1, 2.08, 70.42], [2, 2.1, 111]]}, {"timestamp": 1578679443808, "ltp": 2.06, "tv": 5339.45, "trd": NaN, "batb": NaN, "batl": [[0, 2.06, 3.23]]}, {"timestamp": 1578679782889, "ltp": 2.06, "tv": 5339.45, "trd": NaN, "batb": [[1, 2.02, 1200]], "batl": NaN}, {"timestamp": 1578680011568, "ltp": 2.06, "tv": 5341.91, "trd": [[2.06, 198]], "batb": NaN, "batl": [[0, 2.08, 70.42], [1, 2.1, 111], [2, 2.12, 10]]}, {"timestamp": 1578680063838, "ltp": 2.06, "tv": 5341.91, "trd": NaN, "batb": [[0, 2.04, 77], [2, 2, 3983.06]], "batl": NaN}, {"timestamp": 1578680169859, "ltp": 2.06, "tv": 5341.91, "trd": NaN, "batb": NaN, "batl": [[0, 2.06, 2], [1, 2.08, 70.42], [2, 2.1, 111]]}, {"timestamp": 1578680247864, "ltp": 2.06, "tv": 5345.76, "trd": [[2.06, 201.84]], "batb": NaN, "batl": [[0, 2.08, 70.5], [1, 2.1, 111], [2, 2.12, 10]]}, {"timestamp": 1578680248351, "ltp": 2.06, "tv": 5345.92, "trd": [[2.06, 202]], "batb": NaN, "batl": [[0, 2.08, 70.42]]}, {"timestamp": 1578680263102, "ltp": 2.06, "tv": 5345.92, "trd": NaN, "batb": NaN, "batl": [[0, 2.06, 2], [1, 2.08, 70.42], [2, 2.1, 111]]}, {"timestamp": 1578680345154, "ltp": 2.04, "tv": 5494.48, "trd": [[2.04, 444.88]], "batb": [[0, 2.04, 2.72]], "batl": NaN}, {"timestamp": 1578680347775, "ltp": 2.04, "tv": 5494.48, "trd": NaN, "batb": NaN, "batl": [[0, 2.06, 8]]}, {"timestamp": 1578680544932, "ltp": 2.04, "tv": 5499.92, "trd": [[2.04, 450.32]], "batb": [[0, 2.02, 1200], [1, 2, 3983.06], [2, 1.99, 53.1]], "batl": [[0, 2.04, 27.28], [1, 2.06, 8], [2, 2.08, 70.42]]}, {"timestamp": 1578680552952, "ltp": 2.04, "tv": 5499.92, "trd": NaN, "batb": [[0, 2, 3983.06], [1, 1.99, 53.1], [2, 1.98, 87.62]], "batl": NaN}, {"timestamp": 1578680553842, "ltp": 2.04, "tv": 5499.92, "trd": NaN, "batb": NaN, "batl": [[0, 2.04, 33.28], [1, 2.06, 2]]}, {"timestamp": 1578680565766, "ltp": 2.04, "tv": 5499.92, "trd": NaN, "batb": [[0, 2, 121.35]], "batl": NaN}, {"timestamp": 1578680763256, "ltp": 2.04, "tv": 5499.92, "trd": NaN, "batb": [[2, 1.98, 47.62]], "batl": NaN}, {"timestamp": 1578680772836, "ltp": 2.04, "tv": 5499.92, "trd": NaN, "batb": NaN, "batl": [[0, 2.02, 60], [1, 2.04, 33.28], [2, 2.06, 2]]}, {"timestamp": 1578680774455, "ltp": 2.04, "tv": 5499.92, "trd": NaN, "batb": NaN, "batl": [[0, 2.02, 87.29]]}, {"timestamp": 1578680781555, "ltp": 2.04, "tv": 5499.92, "trd": NaN, "batb": NaN, "batl": [[0, 2.02, 93.29], [1, 2.04, 27.28]]}, {"timestamp": 1578680792761, "ltp": 2.04, "tv": 5499.92, "trd": NaN, "batb": [[0, 2, 79.35]], "batl": NaN}, {"timestamp": 1578680884987, "ltp": 2.04, "tv": 5499.92, "trd": NaN, "batb": NaN, "batl": [[1, 2.06, 2], [2, 2.08, 25.15]]}, {"timestamp": 1578680885889, "ltp": 2.0, "tv": 5554.48, "trd": [[2, 1700.17]], "batb": [[0, 2, 52.07]], "batl": [[0, 2.02, 66]]}, {"timestamp": 1578680886884, "ltp": 2.0, "tv": 5554.48, "trd": NaN, "batb": NaN, "batl": [[1, 2.04, 8.11], [2, 2.06, 28.77]]}, {"timestamp": 1578680929615, "ltp": 2.02, "tv": 5600.38, "trd": [[2.02, 473.53]], "batb": NaN, "batl": [[0, 2.02, 43.05]]}, {"timestamp": 1578680946159, "ltp": 2.02, "tv": 5623.92, "trd": [[2.02, 497.07]], "batb": NaN, "batl": [[0, 2.02, 31.28]]}, {"timestamp": 1578680948753, "ltp": 2.02, "tv": 5623.92, "trd": NaN, "batb": NaN, "batl": [[2, 2.06, 2]]}, {"timestamp": 1578681014463, "ltp": 2.02, "tv": 5623.92, "trd": NaN, "batb": [[0, 2, 102.07]], "batl": NaN}, {"timestamp": 1578681308962, "ltp": 2.0, "tv": 5783.92, "trd": [[2, 1860.17]], "batb": [[0, 2, 22.07]], "batl": NaN}, {"timestamp": 1578681366128, "ltp": 2.0, "tv": 5783.92, "trd": NaN, "batb": NaN, "batl": [[2, 2.06, 113]]}, {"timestamp": 1578681367918, "ltp": 2.0, "tv": 5783.92, "trd": NaN, "batb": NaN, "batl": [[1, 2.04, 55.81]]}, {"timestamp": 1578681372858, "ltp": 2.0, "tv": 5828.06, "trd": [[2, 1904.31]], "batb": [[0, 1.99, 53.1], [1, 1.98, 47.62], [2, 1.88, 163.44]], "batl": [[0, 2, 55.93], [1, 2.02, 31.28], [2, 2.04, 55.81]]}, {"timestamp": 1578681373966, "ltp": 2.0, "tv": 5828.06, "trd": NaN, "batb": NaN, "batl": [[0, 2, 69.16], [2, 2.04, 8.11]]}, {"timestamp": 1578681375231, "ltp": 2.0, "tv": 5828.06, "trd": NaN, "batb": NaN, "batl": [[0, 2, 13.23]]}, {"timestamp": 1578681378425, "ltp": 2.0, "tv": 5828.06, "trd": NaN, "batb": NaN, "batl": [[0, 2.02, 31.28], [1, 2.04, 8.11], [2, 2.06, 113]]}, {"timestamp": 1578681379259, "ltp": 2.0, "tv": 5828.06, "trd": NaN, "batb": [[2, 1.89, 6]], "batl": NaN}, {"timestamp": 1578681383959, "ltp": 2.0, "tv": 5828.06, "trd": NaN, "batb": [[0, 2, 17.03], [1, 1.99, 53.1], [2, 1.98, 47.62]], "batl": NaN}, {"timestamp": 1578681386772, "ltp": 1.99, "tv": 5948.05, "trd": [[1.99, 89.94], [2, 1938.37]], "batb": [[0, 1.99, 10.13], [1, 1.98, 47.62], [2, 1.89, 6]], "batl": NaN}, {"timestamp": 1578681462846, "ltp": 1.99, "tv": 5948.05, "trd": NaN, "batb": [[0, 1.98, 47.62], [1, 1.89, 6], [2, 1.88, 163.44]], "batl": NaN}, {"timestamp": 1578681479276, "ltp": 1.99, "tv": 5948.05, "trd": NaN, "batb": NaN, "batl": [[1, 2.04, 31.45]]}, {"timestamp": 1578681494406, "ltp": 1.99, "tv": 5948.05, "trd": NaN, "batb": NaN, "batl": [[1, 2.04, 55.18]]}, {"timestamp": 1578681515115, "ltp": 1.99, "tv": 5948.05, "trd": NaN, "batb": NaN, "batl": [[2, 2.06, 111]]}, {"timestamp": 1578681565847, "ltp": 1.99, "tv": 5948.05, "trd": NaN, "batb": [[0, 1.99, 15.32], [1, 1.98, 47.62], [2, 1.89, 6]], "batl": NaN}, {"timestamp": 1578681570781, "ltp": 1.99, "tv": 5948.05, "trd": NaN, "batb": NaN, "batl": [[0, 2.02, 101.28]]}, {"timestamp": 1578681572568, "ltp": 1.99, "tv": 5948.05, "trd": NaN, "batb": NaN, "batl": [[0, 2, 44.9], [1, 2.02, 101.28], [2, 2.04, 8.11]]}, {"timestamp": 1578681578583, "ltp": 1.99, "tv": 5960.05, "trd": [[1.99, 101.94]], "batb": [[0, 1.99, 9.32]], "batl": [[1, 2.02, 95.28]]}, {"timestamp": 1578682016032, "ltp": 1.99, "tv": 5960.05, "trd": NaN, "batb": [[2, 1.9, 100]], "batl": NaN}, {"timestamp": 1578682140383, "ltp": 2.0, "tv": 5969.85, "trd": [[2, 1948.16]], "batb": NaN, "batl": [[0, 2, 40.01]]}, {"timestamp": 1578682151020, "ltp": 2.0, "tv": 6049.87, "trd": [[2, 2028.18]], "batb": [[0, 2, 159.99], [1, 1.99, 9.32], [2, 1.98, 47.62]], "batl": [[0, 2.02, 95.28], [1, 2.04, 8.11], [2, 2.06, 111]]}, {"timestamp": 1578682153390, "ltp": 2.0, "tv": 6049.87, "trd": NaN, "batb": [[0, 2, 168.66]], "batl": NaN}, {"timestamp": 1578682155801, "ltp": 2.0, "tv": 6049.87, "trd": NaN, "batb": [[0, 2, 177.32]], "batl": NaN}, {"timestamp": 1578682170921, "ltp": 2.02, "tv": 6239.87, "trd": [[2.02, 687.07]], "batb": NaN, "batl": [[0, 2.04, 8.39], [1, 2.06, 111], [2, 2.08, 25.15]]}, {"timestamp": 1578682172340, "ltp": 2.02, "tv": 6240.43, "trd": [[2.02, 687.63]], "batb": [[0, 2.02, 11.42], [1, 2, 177.32], [2, 1.99, 9.32]], "batl": [[0, 2.04, 8.11]]}, {"timestamp": 1578682173709, "ltp": 2.02, "tv": 6240.43, "trd": NaN, "batb": [[0, 2.02, 21.34]], "batl": NaN}, {"timestamp": 1578682203624, "ltp": 2.02, "tv": 6240.43, "trd": NaN, "batb": [[1, 2, 247.32]], "batl": NaN}, {"timestamp": 1578682519933, "ltp": 2.04, "tv": 6256.65, "trd": [[2.04, 466.54]], "batb": [[0, 2.04, 12.29], [1, 2.02, 21.34], [2, 2, 247.32]], "batl": [[0, 2.06, 111], [1, 2.08, 25.15], [2, 2.12, 10]]}, {"timestamp": 1578682665461, "ltp": 2.04, "tv": 6256.65, "trd": NaN, "batb": [[1, 2.02, 71.34]], "batl": NaN}, {"timestamp": 1578682701927, "ltp": 2.06, "tv": 6478.65, "trd": [[2.06, 424]], "batb": [[0, 2.06, 89], [1, 2.04, 12.29], [2, 2.02, 71.34]], "batl": [[0, 2.08, 25.15], [1, 2.12, 10], [2, 2.14, 126.16]]}, {"timestamp": 1578682702903, "ltp": 2.06, "tv": 6478.65, "trd": NaN, "batb": [[2, 2.02, 61.42]], "batl": NaN}, {"timestamp": 1578682703634, "ltp": 2.06, "tv": 6478.65, "trd": NaN, "batb": [[0, 2.06, 105.55], [2, 2.02, 50]], "batl": NaN}, {"timestamp": 1578682740751, "ltp": 2.08, "tv": 6528.95, "trd": [[2.08, 50.3]], "batb": NaN, "batl": [[0, 2.12, 10], [1, 2.14, 126.16], [2, 3.1, 9]]}, {"timestamp": 1578682781421, "ltp": 2.08, "tv": 6528.95, "trd": NaN, "batb": NaN, "batl": [[0, 2.12, 28]]}, {"timestamp": 1578682803805, "ltp": 2.02, "tv": 6890.17, "trd": [[2.02, 813.17], [2.04, 491.12], [2.06, 635.1]], "batb": [[0, 2, 238.1], [1, 1.98, 47.62], [2, 1.9, 100]], "batl": [[0, 2.02, 19.39], [1, 2.12, 28], [2, 2.14, 126.16]]}, {"timestamp": 1578682804910, "ltp": 2.02, "tv": 6910.21, "trd": [[2.02, 833.21]], "batb": NaN, "batl": [[0, 2.02, 9.37]]}, {"timestamp": 1578682811812, "ltp": 2.02, "tv": 6910.29, "trd": [[1.9, 441.81], [1.92, 22.75], [1.93, 21.52], [1.95, 286.01], [1.99, 101.94], [2, 2028.22], [2.02, 833.23], [2.06, 635.11]], "batb": [[1, 1.98, 47.62], [2, 1.91, 6]], "batl": NaN}, {"timestamp": 1578682812984, "ltp": 2.02, "tv": 6929.02, "trd": [[2.02, 851.97]], "batb": NaN, "batl": [[0, 2.12, 28], [1, 2.14, 126.16], [2, 3.1, 9]]}, {"timestamp": 1578682814507, "ltp": 2.02, "tv": 6929.02, "trd": NaN, "batb": NaN, "batl": [[0, 2.12, 46.43]]}, {"timestamp": 1578682816002, "ltp": 2.02, "tv": 6929.02, "trd": NaN, "batb": NaN, "batl": [[0, 2.12, 65.02]]}, {"timestamp": 1578683112400, "ltp": 2.0, "tv": 6939.02, "trd": [[2, 2038.22]], "batb": [[0, 2, 233.1]], "batl": NaN}, {"timestamp": 1578683139853, "ltp": 2.12, "tv": 6963.02, "trd": [[2.12, 24]], "batb": NaN, "batl": [[0, 2.12, 53.02]]}, {"timestamp": 1578683143530, "ltp": 2.12, "tv": 6963.02, "trd": NaN, "batb": [[0, 2, 283.1]], "batl": NaN}, {"timestamp": 1578683150828, "ltp": 2.12, "tv": 6963.02, "trd": NaN, "batb": [[0, 2.02, 50], [1, 2, 233.1], [2, 1.98, 47.62]], "batl": NaN}, {"timestamp": 1578683213542, "ltp": 2.12, "tv": 6963.02, "trd": NaN, "batb": [[0, 2.02, 550]], "batl": NaN}, {"timestamp": 1578683260080, "ltp": 2.12, "tv": 6963.02, "trd": NaN, "batb": [[0, 2.04, 68.18], [1, 2.02, 550], [2, 2, 233.1]], "batl": NaN}, {"timestamp": 1578683297182, "ltp": 2.12, "tv": 6963.02, "trd": NaN, "batb": NaN, "batl": [[0, 2.08, 6], [1, 2.12, 53.02], [2, 2.14, 126.16]]}, {"timestamp": 1578683406953, "ltp": 2.04, "tv": 7003.02, "trd": [[2.04, 531.12]], "batb": [[0, 2.04, 48.18]], "batl": NaN}, {"timestamp": 1578683430290, "ltp": 2.04, "tv": 7003.02, "trd": NaN, "batb": NaN, "batl": [[0, 2.08, 106]]}, {"timestamp": 1578683431998, "ltp": 2.04, "tv": 7003.02, "trd": NaN, "batb": NaN, "batl": [[0, 2.06, 19.1], [1, 2.08, 106], [2, 2.12, 34.59]]}, {"timestamp": 1578683434810, "ltp": 2.04, "tv": 7003.02, "trd": NaN, "batb": NaN, "batl": [[0, 2.06, 37.11], [2, 2.12, 16]]}, {"timestamp": 1578683438192, "ltp": 2.04, "tv": 7003.02, "trd": NaN, "batb": NaN, "batl": [[0, 2.06, 53.11], [2, 2.14, 126.16]]}, {"timestamp": 1578683550078, "ltp": 2.06, "tv": 7109.24, "trd": [[2.06, 741.33]], "batb": [[0, 2.06, 106.89], [1, 2.04, 48.18], [2, 2.02, 550]], "batl": [[0, 2.08, 106], [1, 2.14, 126.16], [2, 3.1, 9]]}, {"timestamp": 1578683551053, "ltp": 2.06, "tv": 7109.24, "trd": NaN, "batb": [[0, 2.06, 116.16]], "batl": NaN}, {"timestamp": 1578683552355, "ltp": 2.06, "tv": 7109.24, "trd": NaN, "batb": [[0, 2.06, 125.44]], "batl": NaN}, {"timestamp": 1578683558462, "ltp": 2.08, "tv": 7309.24, "trd": [[2.08, 250.3]], "batb": NaN, "batl": [[0, 2.08, 6]]}, {"timestamp": 1578683559912, "ltp": 2.08, "tv": 7321.25, "trd": [[2.08, 262.3]], "batb": [[0, 2.08, 14.43], [1, 2.06, 125.44], [2, 2.04, 48.18]], "batl": [[0, 2.14, 126.16], [1, 3.1, 9], [2, 3.1, 0]]}, {"timestamp": 1578683569335, "ltp": 2.08, "tv": 7321.25, "trd": NaN, "batb": [[1, 2.06, 225.44]], "batl": NaN}, {"timestamp": 1578683608893, "ltp": 2.08, "tv": 7321.25, "trd": NaN, "batb": NaN, "batl": [[0, 3.1, 9], [1, 3.1, 0]]}, {"timestamp": 1578683609668, "ltp": 2.08, "tv": 7321.25, "trd": NaN, "batb": [[0, 2.1, 3], [1, 2.08, 14.43], [2, 2.06, 225.44]], "batl": NaN}, {"timestamp": 1578683610682, "ltp": 2.08, "tv": 7321.25, "trd": NaN, "batb": [[2, 2.06, 206.89]], "batl": NaN}, {"timestamp": 1578683614806, "ltp": 2.08, "tv": 7321.25, "trd": NaN, "batb": NaN, "batl": [[0, 2.16, 123.99], [1, 3.1, 9]]}, {"timestamp": 1578683623316, "ltp": 2.08, "tv": 7321.25, "trd": NaN, "batb": [[1, 2.08, 29.1]], "batl": NaN}, {"timestamp": 1578683632239, "ltp": 2.08, "tv": 7321.25, "trd": NaN, "batb": [[0, 2.08, 29.1], [1, 2.06, 206.89], [2, 2.04, 48.18]], "batl": NaN}, {"timestamp": 1578683639934, "ltp": 2.16, "tv": 7361.25, "trd": [[2.16, 40]], "batb": NaN, "batl": [[0, 2.16, 103.99]]}, {"timestamp": 1578683644025, "ltp": 2.16, "tv": 7361.25, "trd": NaN, "batb": NaN, "batl": [[0, 2.16, 123.99]]}, {"timestamp": 1578683664890, "ltp": 2.16, "tv": 7361.25, "trd": NaN, "batb": [[0, 2.08, 43.21]], "batl": NaN}, {"timestamp": 1578683722691, "ltp": 2.16, "tv": 7361.25, "trd": NaN, "batb": NaN, "batl": [[0, 2.14, 2], [1, 2.16, 123.99], [2, 3.1, 9]]}, {"timestamp": 1578683732797, "ltp": 2.16, "tv": 7361.25, "trd": NaN, "batb": NaN, "batl": [[2, 2.5, 19.15]]}, {"timestamp": 1578683836485, "ltp": 2.16, "tv": 7361.25, "trd": NaN, "batb": NaN, "batl": [[0, 2.12, 2], [1, 2.14, 2], [2, 2.16, 123.99]]}, {"timestamp": 1578683946708, "ltp": 2.16, "tv": 7361.25, "trd": NaN, "batb": NaN, "batl": [[0, 2.12, 12]]}, {"timestamp": 1578684161876, "ltp": 2.16, "tv": 7361.25, "trd": NaN, "batb": [[0, 2.1, 12.31], [1, 2.08, 43.21], [2, 2.06, 206.89]], "batl": NaN}, {"timestamp": 1578684196999, "ltp": 2.12, "tv": 7385.25, "trd": [[2.12, 48]], "batb": [[0, 2.12, 8], [1, 2.1, 12.31], [2, 2.08, 43.21]], "batl": [[0, 2.14, 8.24], [1, 2.16, 123.99], [2, 2.5, 19.15]]}, {"timestamp": 1578684220641, "ltp": 2.12, "tv": 7385.25, "trd": NaN, "batb": [[1, 2.1, 32.31]], "batl": NaN}, {"timestamp": 1578684244944, "ltp": 2.12, "tv": 7391.25, "trd": [[2.12, 54]], "batb": [[0, 2.12, 5]], "batl": NaN}, {"timestamp": 1578684285194, "ltp": 2.12, "tv": 7391.25, "trd": NaN, "batb": [[1, 2.1, 79.93]], "batl": NaN}, {"timestamp": 1578684303976, "ltp": 2.12, "tv": 7391.25, "trd": NaN, "batb": NaN, "batl": [[2, 2.26, 10]]}, {"timestamp": 1578684862590, "ltp": 2.12, "tv": 7395.25, "trd": [[2.12, 58]], "batb": [[0, 2.12, 3]], "batl": NaN}, {"timestamp": 1578685059688, "ltp": 2.16, "tv": 7595.25, "trd": [[2.14, 16.48], [2.16, 223.52]], "batb": NaN, "batl": [[0, 2.16, 32.23], [1, 2.26, 10], [2, 2.5, 19.15]]}, {"timestamp": 1578685062896, "ltp": 2.16, "tv": 7595.25, "trd": NaN, "batb": NaN, "batl": [[0, 2.26, 124.15], [1, 2.5, 19.15], [2, 2.52, 19.15]]}, {"timestamp": 1578685065971, "ltp": 2.16, "tv": 7595.25, "trd": NaN, "batb": NaN, "batl": [[0, 2.24, 4], [1, 2.26, 124.15], [2, 2.5, 19.15]]}, {"timestamp": 1578685069803, "ltp": 2.16, "tv": 7595.25, "trd": NaN, "batb": [[0, 2.12, 103]], "batl": NaN}, {"timestamp": 1578685070186, "ltp": 2.16, "tv": 7595.25, "trd": NaN, "batb": [[0, 2.14, 12.48], [1, 2.12, 103], [2, 2.1, 79.93]], "batl": NaN}, {"timestamp": 1578685071598, "ltp": 2.16, "tv": 7595.25, "trd": NaN, "batb": [[0, 2.14, 24.68]], "batl": NaN}, {"timestamp": 1578685072804, "ltp": 2.16, "tv": 7595.25, "trd": NaN, "batb": [[0, 2.14, 42.72]], "batl": [[1, 2.26, 10]]}, {"timestamp": 1578685083336, "ltp": 2.16, "tv": 7595.25, "trd": NaN, "batb": [[0, 2.16, 3], [1, 2.14, 42.72], [2, 2.12, 103]], "batl": [[0, 2.26, 10], [1, 2.5, 19.15], [2, 2.52, 19.15]]}, {"timestamp": 1578685086731, "ltp": 2.16, "tv": 7595.25, "trd": NaN, "batb": NaN, "batl": [[0, 2.24, 28], [1, 2.26, 10], [2, 2.5, 19.15]]}, {"timestamp": 1578685142418, "ltp": 2.16, "tv": 7599.25, "trd": [[2.16, 227.52]], "batb": [[0, 2.16, 1]], "batl": NaN}, {"timestamp": 1578685255855, "ltp": 2.16, "tv": 7601.25, "trd": [[2.16, 229.52]], "batb": [[0, 2.14, 42.72], [1, 2.12, 103], [2, 2.1, 79.93]], "batl": [[0, 2.16, 103.17], [1, 2.24, 28], [2, 2.26, 10]]}, {"timestamp": 1578685256774, "ltp": 2.16, "tv": 7601.25, "trd": NaN, "batb": [[0, 2.14, 39.63]], "batl": NaN}, {"timestamp": 1578685258279, "ltp": 2.16, "tv": 7601.25, "trd": NaN, "batb": [[0, 2.14, 30.51]], "batl": NaN}, {"timestamp": 1578685262853, "ltp": 2.16, "tv": 7601.25, "trd": NaN, "batb": NaN, "batl": [[1, 2.2, 2], [2, 2.24, 28]]}, {"timestamp": 1578685281290, "ltp": 2.14, "tv": 7661.25, "trd": [[2.14, 76.48]], "batb": [[0, 2.12, 103.51], [1, 2.1, 79.93], [2, 2.08, 6]], "batl": NaN}, {"timestamp": 1578685282301, "ltp": 2.14, "tv": 7661.25, "trd": NaN, "batb": [[0, 2.12, 103]], "batl": NaN}, {"timestamp": 1578685283706, "ltp": 2.14, "tv": 7661.25, "trd": NaN, "batb": NaN, "batl": [[0, 2.14, 6.02], [1, 2.16, 103.17], [2, 2.2, 2]]}, {"timestamp": 1578685286991, "ltp": 2.14, "tv": 7664.43, "trd": [[2.14, 79.67]], "batb": NaN, "batl": [[0, 2.14, 4.43]]}, {"timestamp": 1578685320995, "ltp": 2.14, "tv": 7673.29, "trd": [[2.14, 88.52]], "batb": NaN, "batl": [[0, 2.16, 103.17], [1, 2.2, 2], [2, 2.24, 28]]}, {"timestamp": 1578685329262, "ltp": 2.12, "tv": 7799.31, "trd": [[2.12, 184.02]], "batb": [[0, 2.12, 39.99]], "batl": NaN}, {"timestamp": 1578685557466, "ltp": 2.12, "tv": 7799.31, "trd": NaN, "batb": NaN, "batl": [[0, 2.14, 10.96], [1, 2.16, 103.17], [2, 2.2, 2]]}, {"timestamp": 1578685671869, "ltp": 2.14, "tv": 7813.63, "trd": [[2.14, 102.84]], "batb": NaN, "batl": [[0, 2.14, 3.8]]}, {"timestamp": 1578685672944, "ltp": 2.14, "tv": 7821.23, "trd": [[2.14, 110.44]], "batb": [[0, 2.14, 15.93], [1, 2.12, 39.99], [2, 2.1, 79.93]], "batl": [[0, 2.16, 103.17], [1, 2.2, 2], [2, 2.24, 28]]}, {"timestamp": 1578685839945, "ltp": 2.14, "tv": 7853.09, "trd": [[2.14, 142.3]], "batb": [[0, 2.12, 39.99], [1, 2.1, 79.93], [2, 2.08, 6]], "batl": [[0, 2.14, 34.07], [1, 2.16, 103.17], [2, 2.2, 2]]}, {"timestamp": 1578685840151, "ltp": 2.12, "tv": 7865.67, "trd": [[2.12, 196.6]], "batb": [[0, 2.12, 33.7]], "batl": NaN}, {"timestamp": 1578685843978, "ltp": 2.12, "tv": 7865.67, "trd": NaN, "batb": NaN, "batl": [[0, 2.14, 42.59]]}, {"timestamp": 1578685953961, "ltp": 2.12, "tv": 7899.73, "trd": [[2.12, 230.66]], "batb": [[0, 2.12, 16.67]], "batl": NaN}, {"timestamp": 1578685999838, "ltp": 2.12, "tv": 7899.73, "trd": NaN, "batb": [[0, 2.12, 48.18]], "batl": NaN}, {"timestamp": 1578686215644, "ltp": 2.12, "tv": 7899.73, "trd": NaN, "batb": NaN, "batl": [[0, 2.14, 141.59]]}, {"timestamp": 1578686413750, "ltp": 2.12, "tv": 7899.73, "trd": NaN, "batb": NaN, "batl": [[2, 2.2, 24]]}, {"timestamp": 1578686428998, "ltp": 2.14, "tv": 8023.29, "trd": [[2.14, 265.87]], "batb": NaN, "batl": [[0, 2.14, 79.81]]}, {"timestamp": 1578686432989, "ltp": 2.14, "tv": 8023.29, "trd": NaN, "batb": [[0, 2.12, 56.78]], "batl": NaN}, {"timestamp": 1578686433811, "ltp": 2.14, "tv": 8040.87, "trd": [[2.14, 283.45]], "batb": NaN, "batl": [[0, 2.14, 71.02]]}, {"timestamp": 1578686435989, "ltp": 2.14, "tv": 8040.87, "trd": NaN, "batb": [[0, 2.12, 64.01]], "batl": NaN}, {"timestamp": 1578686453310, "ltp": 2.12, "tv": 8090.87, "trd": [[2.12, 280.66]], "batb": [[0, 2.12, 39.02]], "batl": NaN}, {"timestamp": 1578686611859, "ltp": 2.12, "tv": 8094.87, "trd": [[2.12, 284.66]], "batb": [[0, 2.12, 37.01]], "batl": NaN}, {"timestamp": 1578686931407, "ltp": 2.12, "tv": 8111.9, "trd": [[2.12, 301.69]], "batb": [[0, 2.12, 28.5]], "batl": NaN}, {"timestamp": 1578687156436, "ltp": 2.16, "tv": 8288.4, "trd": [[2.14, 425.49], [2.16, 263.98]], "batb": NaN, "batl": [[0, 2.16, 85.94], [1, 2.2, 24], [2, 2.24, 28]]}, {"timestamp": 1578687210844, "ltp": 2.16, "tv": 8288.4, "trd": NaN, "batb": [[1, 2.1, 579.93]], "batl": NaN}, {"timestamp": 1578687211267, "ltp": 2.16, "tv": 8288.4, "trd": NaN, "batb": [[0, 2.12, 34.77]], "batl": NaN}, {"timestamp": 1578687212760, "ltp": 2.16, "tv": 8288.4, "trd": NaN, "batb": [[0, 2.12, 45.52]], "batl": NaN}, {"timestamp": 1578687217465, "ltp": 2.16, "tv": 8288.4, "trd": NaN, "batb": [[0, 2.12, 55.3]], "batl": NaN}, {"timestamp": 1578687549293, "ltp": 2.16, "tv": 8288.4, "trd": NaN, "batb": NaN, "batl": [[0, 2.14, 1.7], [1, 2.16, 85.94], [2, 2.2, 24]]}, {"timestamp": 1578687550723, "ltp": 2.16, "tv": 8288.4, "trd": NaN, "batb": NaN, "batl": [[0, 2.16, 85.94], [1, 2.2, 24], [2, 2.24, 28]]}, {"timestamp": 1578687591749, "ltp": 2.16, "tv": 8288.4, "trd": NaN, "batb": [[0, 2.12, 103.48]], "batl": NaN}, {"timestamp": 1578687755502, "ltp": 2.16, "tv": 8288.4, "trd": NaN, "batb": [[0, 2.12, 90.82]], "batl": NaN}, {"timestamp": 1578688072817, "ltp": 2.16, "tv": 8288.4, "trd": NaN, "batb": NaN, "batl": [[1, 2.2, 2], [2, 2.22, 23]]}, {"timestamp": 1578688098777, "ltp": 2.12, "tv": 8294.4, "trd": [[2.12, 307.69]], "batb": [[0, 2.12, 87.82]], "batl": NaN}, {"timestamp": 1578688438336, "ltp": 2.12, "tv": 8294.4, "trd": NaN, "batb": NaN, "batl": [[1, 2.2, 28.3], [2, 2.24, 28]]}, {"timestamp": 1578688508844, "ltp": 2.12, "tv": 8294.4, "trd": NaN, "batb": [[0, 2.14, 33], [1, 2.12, 87.82], [2, 2.1, 579.93]], "batl": NaN}, {"timestamp": 1578688518649, "ltp": 2.16, "tv": 8466.28, "trd": [[2.16, 435.86]], "batb": [[0, 2.16, 21.06], [1, 2.14, 33], [2, 2.12, 87.82]], "batl": [[0, 2.2, 28.3], [1, 2.24, 28], [2, 2.26, 124.15]]}, {"timestamp": 1578688529484, "ltp": 2.16, "tv": 8466.28, "trd": NaN, "batb": NaN, "batl": [[1, 2.24, 36.53]]}, {"timestamp": 1578688540106, "ltp": 2.16, "tv": 8466.28, "trd": NaN, "batb": NaN, "batl": [[0, 2.18, 2.97], [1, 2.2, 28.3], [2, 2.24, 36.53]]}, {"timestamp": 1578688561723, "ltp": 2.16, "tv": 8466.28, "trd": NaN, "batb": NaN, "batl": [[1, 2.2, 2], [2, 2.22, 12.99]]}, {"timestamp": 1578688584329, "ltp": 2.16, "tv": 8466.28, "trd": NaN, "batb": NaN, "batl": [[0, 2.2, 4.95], [1, 2.22, 12.99], [2, 2.24, 36.53]]}, {"timestamp": 1578688590660, "ltp": 2.16, "tv": 8466.28, "trd": NaN, "batb": NaN, "batl": [[2, 2.24, 28]]}, {"timestamp": 1578688616921, "ltp": 2.16, "tv": 8466.28, "trd": NaN, "batb": NaN, "batl": [[2, 2.24, 36.54]]}, {"timestamp": 1578688685556, "ltp": 2.16, "tv": 8466.28, "trd": NaN, "batb": NaN, "batl": [[1, 2.24, 48.54], [2, 2.26, 124.15]]}, {"timestamp": 1578688699765, "ltp": 2.16, "tv": 8466.28, "trd": NaN, "batb": NaN, "batl": [[0, 2.2, 2], [1, 2.22, 2.92], [2, 2.24, 48.54]]}, {"timestamp": 1578688805972, "ltp": 2.16, "tv": 8482.28, "trd": [[2.16, 451.86]], "batb": [[0, 2.16, 13.06]], "batl": NaN}, {"timestamp": 1578688824199, "ltp": 2.16, "tv": 8492.28, "trd": [[2.16, 461.86]], "batb": [[0, 2.16, 8.06]], "batl": NaN}, {"timestamp": 1578689069229, "ltp": 2.16, "tv": 8500.8, "trd": [[2.16, 470.38]], "batb": [[0, 2.16, 3.8]], "batl": NaN}, {"timestamp": 1578689190189, "ltp": 2.2, "tv": 8504.8, "trd": [[2.2, 4]], "batb": [[0, 2.2, 2.95], [1, 2.16, 3.8], [2, 2.14, 33]], "batl": [[0, 2.22, 9.04], [1, 2.24, 48.54], [2, 2.26, 124.15]]}, {"timestamp": 1578689208817, "ltp": 2.2, "tv": 8504.8, "trd": NaN, "batb": [[0, 2.16, 3.8], [1, 2.14, 33], [2, 2.12, 81.55]], "batl": NaN}, {"timestamp": 1578689327828, "ltp": 2.22, "tv": 8510.7, "trd": [[2.22, 5.9]], "batb": NaN, "batl": [[0, 2.22, 6.09]]}, {"timestamp": 1578689393394, "ltp": 2.14, "tv": 8569.44, "trd": [[2.14, 476.63], [2.16, 477.98]], "batb": [[0, 2.14, 13.69], [1, 2.12, 81.55], [2, 2.1, 579.93]], "batl": [[0, 2.24, 48.54], [1, 2.26, 124.15], [2, 2.5, 19.15]]}, {"timestamp": 1578689399901, "ltp": 2.14, "tv": 8569.44, "trd": NaN, "batb": [[0, 2.16, 3], [1, 2.14, 13.69], [2, 2.12, 81.55]], "batl": NaN}, {"timestamp": 1578689538711, "ltp": 2.16, "tv": 8575.44, "trd": [[2.16, 483.98]], "batb": [[0, 2.14, 13.69], [1, 2.12, 81.55], [2, 2.1, 579.93]], "batl": [[0, 2.24, 49.13]]}, {"timestamp": 1578689542886, "ltp": 2.16, "tv": 8575.44, "trd": NaN, "batb": NaN, "batl": [[0, 2.24, 48.54]]}, {"timestamp": 1578689552146, "ltp": 2.16, "tv": 8575.44, "trd": NaN, "batb": NaN, "batl": [[0, 2.22, 2.92], [1, 2.24, 48.54], [2, 2.26, 124.15]]}, {"timestamp": 1578689568248, "ltp": 2.14, "tv": 8602.62, "trd": [[2.14, 503.81]], "batb": [[0, 2.12, 81.65], [1, 2.1, 579.93], [2, 2.08, 6]], "batl": NaN}, {"timestamp": 1578689624503, "ltp": 2.14, "tv": 8602.62, "trd": NaN, "batb": NaN, "batl": [[0, 2.2, 50], [1, 2.22, 2.92], [2, 2.24, 48.54]]}, {"timestamp": 1578689649374, "ltp": 2.14, "tv": 8602.62, "trd": NaN, "batb": NaN, "batl": [[0, 2.18, 2.97], [1, 2.2, 50]]}, {"timestamp": 1578689797633, "ltp": 2.14, "tv": 8602.62, "trd": NaN, "batb": [[0, 2.14, 26.5], [1, 2.12, 81.55], [2, 2.1, 579.93]], "batl": NaN}, {"timestamp": 1578689812966, "ltp": 2.14, "tv": 8602.62, "trd": NaN, "batb": NaN, "batl": [[0, 2.16, 3], [1, 2.18, 2.97], [2, 2.2, 50]]}, {"timestamp": 1578689826994, "ltp": 2.14, "tv": 8608.62, "trd": [[2.14, 509.81]], "batb": [[0, 2.14, 23.49]], "batl": NaN}, {"timestamp": 1578690014907, "ltp": 2.14, "tv": 8608.87, "trd": [[1.9, 441.81], [1.92, 22.75], [1.93, 21.53], [1.95, 286.01], [1.99, 101.95], [2, 2038.32], [2.02, 852.02], [2.06, 741.36], [2.08, 262.31], [2.12, 307.71], [2.14, 509.84], [2.16, 483.98]], "batb": [[0, 2.14, 23.5], [1, 2.12, 81.56], [2, 2.1, 579.93]], "batl": NaN}, {"timestamp": 1578690035743, "ltp": 2.14, "tv": 8608.87, "trd": NaN, "batb": [[1, 2.12, 74.33]], "batl": NaN}, {"timestamp": 1578690067187, "ltp": 2.14, "tv": 8608.87, "trd": NaN, "batb": [[0, 2.14, 223.5]], "batl": NaN}, {"timestamp": 1578690068909, "ltp": 2.14, "tv": 8608.87, "trd": NaN, "batb": [[1, 2.12, 57.97]], "batl": NaN}, {"timestamp": 1578690069406, "ltp": 2.16, "tv": 8614.87, "trd": [[2.16, 489.98]], "batb": [[0, 2.16, 17.4], [1, 2.14, 223.5], [2, 2.12, 57.97]], "batl": [[0, 2.18, 2.97], [1, 2.2, 50], [2, 2.24, 36.54]]}, {"timestamp": 1578690070710, "ltp": 2.16, "tv": 8614.87, "trd": NaN, "batb": [[0, 2.16, 31.77], [2, 2.12, 48.18]], "batl": NaN}, {"timestamp": 1578690074711, "ltp": 2.16, "tv": 8614.87, "trd": NaN, "batb": [[1, 2.14, 23.5]], "batl": NaN}, {"timestamp": 1578690075697, "ltp": 2.16, "tv": 8614.87, "trd": NaN, "batb": [[0, 2.14, 26.03], [1, 2.12, 48.18], [2, 2.1, 579.93]], "batl": NaN}, {"timestamp": 1578690076993, "ltp": 2.16, "tv": 8614.87, "trd": NaN, "batb": [[0, 2.14, 23.5], [1, 2.12, 61.77]], "batl": NaN}, {"timestamp": 1578690077923, "ltp": 2.16, "tv": 8614.87, "trd": NaN, "batb": [[1, 2.12, 70.35]], "batl": NaN}, {"timestamp": 1578690086517, "ltp": 2.16, "tv": 8614.87, "trd": NaN, "batb": [[0, 2.16, 100], [1, 2.14, 23.5], [2, 2.12, 70.35]], "batl": NaN}, {"timestamp": 1578690088338, "ltp": 2.18, "tv": 8620.81, "trd": [[2.18, 5.93]], "batb": [[0, 2.18, 8.55], [1, 2.16, 100], [2, 2.14, 23.5]], "batl": [[0, 2.2, 50], [1, 2.24, 36.54], [2, 2.26, 124.15]]}, {"timestamp": 1578690118995, "ltp": 2.18, "tv": 8637.91, "trd": [[2.18, 23.04]], "batb": [[0, 2.16, 100], [1, 2.14, 23.5], [2, 2.12, 48.18]], "batl": [[0, 2.18, 1.45], [1, 2.2, 50], [2, 2.24, 36.54]]}, {"timestamp": 1578690119879, "ltp": 2.18, "tv": 8637.91, "trd": NaN, "batb": NaN, "batl": [[2, 2.22, 8.87]]}, {"timestamp": 1578690177126, "ltp": 2.18, "tv": 8637.91, "trd": NaN, "batb": [[2, 2.12, 56.78]], "batl": NaN}, {"timestamp": 1578690473783, "ltp": 2.18, "tv": 8640.81, "trd": [[2.18, 25.94]], "batb": [[0, 2.18, 1.35], [1, 2.16, 100], [2, 2.14, 23.5]], "batl": [[0, 2.2, 50], [1, 2.22, 8.87], [2, 2.24, 53.07]]}, {"timestamp": 1578690477522, "ltp": 2.18, "tv": 8643.51, "trd": [[2.18, 28.64]], "batb": [[0, 2.16, 100], [1, 2.14, 23.5], [2, 2.12, 56.78]], "batl": [[0, 2.18, 2.65], [1, 2.2, 50], [2, 2.22, 8.87]]}, {"timestamp": 1578690501951, "ltp": 2.18, "tv": 8643.51, "trd": NaN, "batb": NaN, "batl": [[0, 2.18, 24.65]]}, {"timestamp": 1578690560998, "ltp": 2.18, "tv": 8643.51, "trd": NaN, "batb": NaN, "batl": [[1, 2.22, 8.87], [2, 2.24, 53.07]]}, {"timestamp": 1578690561924, "ltp": 2.18, "tv": 8643.51, "trd": NaN, "batb": NaN, "batl": [[1, 2.24, 53.07], [2, 2.26, 10]]}, {"timestamp": 1578690603471, "ltp": 2.18, "tv": 8692.81, "trd": [[2.18, 77.94]], "batb": [[0, 2.18, 23.53], [1, 2.16, 100], [2, 2.14, 23.5]], "batl": [[0, 2.24, 53.07], [1, 2.26, 10], [2, 2.5, 19.15]]}, {"timestamp": 1578690662643, "ltp": 2.18, "tv": 8700.81, "trd": [[2.18, 85.94]], "batb": [[0, 2.18, 19.53]], "batl": NaN}, {"timestamp": 1578690668261, "ltp": 2.18, "tv": 8700.81, "trd": NaN, "batb": NaN, "batl": [[0, 2.24, 28], [1, 2.26, 31.53]]}, {"timestamp": 1578690687472, "ltp": 2.18, "tv": 8700.81, "trd": NaN, "batb": NaN, "batl": [[2, 2.3, 20]]}, {"timestamp": 1578690689986, "ltp": 2.18, "tv": 8700.81, "trd": NaN, "batb": NaN, "batl": [[0, 2.22, 2], [1, 2.24, 28], [2, 2.26, 31.53]]}, {"timestamp": 1578690709617, "ltp": 2.18, "tv": 8700.81, "trd": NaN, "batb": NaN, "batl": [[0, 2.22, 13]]}, {"timestamp": 1578690749807, "ltp": 2.18, "tv": 8700.81, "trd": NaN, "batb": [[0, 2.2, 7.94], [1, 2.18, 19.53], [2, 2.16, 100]], "batl": NaN}, {"timestamp": 1578690918904, "ltp": 2.2, "tv": 8716.69, "trd": [[2.2, 19.88]], "batb": [[0, 2.18, 19.53], [1, 2.16, 100], [2, 2.14, 23.5]], "batl": [[0, 2.2, 37.49], [1, 2.22, 13], [2, 2.24, 28]]}, {"timestamp": 1578690920893, "ltp": 2.2, "tv": 8716.69, "trd": NaN, "batb": NaN, "batl": [[2, 2.24, 36.79]]}, {"timestamp": 1578690972567, "ltp": 2.2, "tv": 8716.69, "trd": NaN, "batb": NaN, "batl": [[1, 2.22, 2]]}, {"timestamp": 1578691130566, "ltp": 2.18, "tv": 8741.29, "trd": [[2.18, 110.54]], "batb": [[0, 2.18, 7.23]], "batl": [[0, 2.2, 177.49]]}, {"timestamp": 1578691131870, "ltp": 2.18, "tv": 8755.75, "trd": [[2.18, 125]], "batb": [[0, 2.16, 100], [1, 2.14, 23.5], [2, 2.12, 10.6]], "batl": [[0, 2.18, 1.8], [1, 2.2, 177.49], [2, 2.22, 2]]}, {"timestamp": 1578691158966, "ltp": 2.18, "tv": 8759.35, "trd": [[2.18, 128.6]], "batb": [[0, 2.18, 10.55], [1, 2.16, 100], [2, 2.14, 23.5]], "batl": [[0, 2.2, 37.49], [1, 2.22, 2], [2, 2.24, 28]]}, {"timestamp": 1578691290618, "ltp": 2.2, "tv": 8834.33, "trd": [[2.2, 94.86]], "batb": NaN, "batl": [[0, 2.22, 2], [1, 2.24, 28], [2, 2.26, 31.53]]}, {"timestamp": 1578691321849, "ltp": 2.2, "tv": 8834.33, "trd": NaN, "batb": NaN, "batl": [[0, 2.24, 28], [1, 2.26, 31.53], [2, 2.3, 20]]}, {"timestamp": 1578691406998, "ltp": 2.18, "tv": 8854.33, "trd": [[2.18, 148.6]], "batb": [[0, 2.16, 100.55], [1, 2.14, 23.5], [2, 2.12, 10.6]], "batl": NaN}, {"timestamp": 1578691419437, "ltp": 2.18, "tv": 8854.33, "trd": NaN, "batb": NaN, "batl": [[0, 2.22, 119.15], [1, 2.24, 28], [2, 2.26, 31.53]]}, {"timestamp": 1578691420927, "ltp": 2.18, "tv": 8854.33, "trd": NaN, "batb": NaN, "batl": [[0, 2.2, 10.11], [1, 2.22, 119.15], [2, 2.24, 28]]}, {"timestamp": 1578691435768, "ltp": 2.18, "tv": 8854.33, "trd": NaN, "batb": NaN, "batl": [[1, 2.24, 28], [2, 2.26, 31.53]]}, {"timestamp": 1578691436144, "ltp": 2.18, "tv": 8854.33, "trd": NaN, "batb": NaN, "batl": [[0, 2.24, 28], [1, 2.26, 31.53], [2, 2.3, 20]]}, {"timestamp": 1578691474931, "ltp": 2.18, "tv": 8854.33, "trd": NaN, "batb": [[1, 2.12, 10.6], [2, 2.1, 597.93]], "batl": NaN}, {"timestamp": 1578691533935, "ltp": 2.18, "tv": 8854.33, "trd": NaN, "batb": NaN, "batl": [[1, 2.26, 10]]}, {"timestamp": 1578691534037, "ltp": 2.18, "tv": 8854.33, "trd": NaN, "batb": [[1, 2.12, 37.49]], "batl": [[2, 2.28, 17]]}, {"timestamp": 1578691804844, "ltp": 2.16, "tv": 9054.33, "trd": [[2.16, 688.88], [2.18, 149.7]], "batb": [[0, 2.12, 38.04], [1, 2.1, 597.93], [2, 2.08, 6]], "batl": NaN}, {"timestamp": 1578691805829, "ltp": 2.16, "tv": 9054.33, "trd": NaN, "batb": [[0, 2.12, 57.88]], "batl": NaN}, {"timestamp": 1578691807948, "ltp": 2.16, "tv": 9054.33, "trd": NaN, "batb": [[0, 2.14, 6.55], [1, 2.12, 57.33], [2, 2.1, 597.93]], "batl": NaN}, {"timestamp": 1578691817675, "ltp": 2.16, "tv": 9054.33, "trd": NaN, "batb": [[0, 2.14, 130.15]], "batl": NaN}, {"timestamp": 1578691818976, "ltp": 2.16, "tv": 9054.33, "trd": NaN, "batb": [[0, 2.16, 22.26], [1, 2.14, 129.6], [2, 2.12, 37.49]], "batl": NaN}, {"timestamp": 1578691821986, "ltp": 2.16, "tv": 9054.33, "trd": NaN, "batb": [[1, 2.14, 123.6]], "batl": NaN}, {"timestamp": 1578691831865, "ltp": 2.16, "tv": 9054.33, "trd": NaN, "batb": [[0, 2.16, 222.26]], "batl": NaN}, {"timestamp": 1578691833411, "ltp": 2.16, "tv": 9054.33, "trd": NaN, "batb": [[1, 2.12, 37.49], [2, 2.1, 597.93]], "batl": NaN}, {"timestamp": 1578691900744, "ltp": 2.16, "tv": 9054.33, "trd": NaN, "batb": NaN, "batl": [[2, 2.3, 20]]}, {"timestamp": 1578692024228, "ltp": 2.16, "tv": 9054.33, "trd": NaN, "batb": NaN, "batl": [[2, 2.3, 44.9]]}, {"timestamp": 1578692132220, "ltp": 2.16, "tv": 9054.33, "trd": NaN, "batb": NaN, "batl": [[0, 2.22, 20], [1, 2.24, 28], [2, 2.26, 10]]}, {"timestamp": 1578692751328, "ltp": 2.16, "tv": 9054.33, "trd": NaN, "batb": NaN, "batl": [[0, 2.2, 2], [1, 2.22, 20], [2, 2.24, 28]]}, {"timestamp": 1578692753750, "ltp": 2.16, "tv": 9054.33, "trd": NaN, "batb": [[0, 2.18, 7.04], [1, 2.16, 222.26], [2, 2.12, 37.49]], "batl": NaN}, {"timestamp": 1578692759962, "ltp": 2.16, "tv": 9054.33, "trd": NaN, "batb": [[2, 2.12, 10.6]], "batl": NaN}, {"timestamp": 1578693216548, "ltp": 2.2, "tv": 9058.33, "trd": [[2.2, 98.86]], "batb": [[0, 2.2, 17.74], [1, 2.18, 7.04], [2, 2.16, 222.26]], "batl": [[0, 2.22, 20], [1, 2.24, 28], [2, 2.26, 10]]}, {"timestamp": 1578693253659, "ltp": 2.2, "tv": 9066.35, "trd": [[2.2, 106.88]], "batb": [[0, 2.2, 13.73]], "batl": NaN}, {"timestamp": 1578693272784, "ltp": 2.2, "tv": 9092.35, "trd": [[2.2, 132.88]], "batb": [[0, 2.18, 7.77], [1, 2.16, 222.26], [2, 2.12, 10.6]], "batl": NaN}, {"timestamp": 1578693375960, "ltp": 2.2, "tv": 9092.35, "trd": NaN, "batb": [[0, 2.18, 27.77]], "batl": NaN}, {"timestamp": 1578693776739, "ltp": 2.2, "tv": 9092.35, "trd": NaN, "batb": NaN, "batl": [[2, 2.26, 24.99]]}, {"timestamp": 1578693903715, "ltp": 2.18, "tv": 9132.36, "trd": [[2.18, 188.24], [2.2, 134.35]], "batb": [[0, 2.18, 7.76]], "batl": NaN}, {"timestamp": 1578693966936, "ltp": 2.18, "tv": 9132.36, "trd": NaN, "batb": NaN, "batl": [[0, 2.22, 70]]}, {"timestamp": 1578694050651, "ltp": 2.18, "tv": 9147.88, "trd": [[2.18, 203.76]], "batb": [[0, 2.16, 222.26], [1, 2.12, 10.6], [2, 2.1, 577.93]], "batl": [[0, 2.18, 2.24], [1, 2.22, 70], [2, 2.24, 28]]}, {"timestamp": 1578694066983, "ltp": 2.18, "tv": 9152.36, "trd": [[2.18, 208.24]], "batb": [[0, 2.18, 18.47], [1, 2.16, 222.26], [2, 2.12, 10.6]], "batl": [[0, 2.22, 70], [1, 2.24, 28], [2, 2.26, 24.99]]}, {"timestamp": 1578694211900, "ltp": 2.18, "tv": 9152.36, "trd": NaN, "batb": NaN, "batl": [[0, 2.2, 50], [1, 2.22, 70], [2, 2.24, 28]]}, {"timestamp": 1578694216903, "ltp": 2.18, "tv": 9173.55, "trd": [[2.18, 229.43]], "batb": [[0, 2.18, 7.87]], "batl": NaN}, {"timestamp": 1578694318162, "ltp": 2.18, "tv": 9183.55, "trd": [[2.18, 239.43]], "batb": [[0, 2.18, 2.87]], "batl": NaN}, {"timestamp": 1578694388763, "ltp": 2.18, "tv": 9189.29, "trd": [[2.18, 245.17]], "batb": [[0, 2.16, 222.26], [1, 2.12, 10.6], [2, 2.1, 577.93]], "batl": NaN}, {"timestamp": 1578694391245, "ltp": 2.2, "tv": 9199.29, "trd": [[2.2, 144.35]], "batb": NaN, "batl": [[0, 2.2, 45]]}, {"timestamp": 1578694456926, "ltp": 2.16, "tv": 9221.3, "trd": [[2.16, 710.89]], "batb": [[0, 2.16, 211.24]], "batl": NaN}, {"timestamp": 1578694478955, "ltp": 2.16, "tv": 9229.3, "trd": [[2.16, 718.89]], "batb": [[0, 2.16, 207.24]], "batl": NaN}, {"timestamp": 1578694479978, "ltp": 2.16, "tv": 9229.3, "trd": NaN, "batb": NaN, "batl": [[0, 2.2, 55.94]]}, {"timestamp": 1578694527308, "ltp": 2.16, "tv": 9229.3, "trd": NaN, "batb": [[0, 2.16, 329.7]], "batl": NaN}, {"timestamp": 1578694535944, "ltp": 2.16, "tv": 9229.3, "trd": NaN, "batb": NaN, "batl": [[2, 2.24, 32]]}, {"timestamp": 1578694570382, "ltp": 2.16, "tv": 9229.3, "trd": NaN, "batb": NaN, "batl": [[0, 2.18, 20], [1, 2.2, 55.94], [2, 2.22, 70]]}, {"timestamp": 1578694635943, "ltp": 2.16, "tv": 9229.3, "trd": NaN, "batb": [[1, 2.12, 48.2]], "batl": NaN}, {"timestamp": 1578694670401, "ltp": 2.16, "tv": 9229.3, "trd": NaN, "batb": [[0, 2.16, 207.24]], "batl": NaN}, {"timestamp": 1578694718272, "ltp": 2.16, "tv": 9229.3, "trd": NaN, "batb": [[0, 2.16, 329.7]], "batl": NaN}, {"timestamp": 1578694831446, "ltp": 2.16, "tv": 9249.31, "trd": [[2.16, 738.89]], "batb": [[0, 2.16, 319.7]], "batl": NaN}, {"timestamp": 1578694832425, "ltp": 2.16, "tv": 9249.31, "trd": NaN, "batb": NaN, "batl": [[1, 2.2, 65.81]]}, {"timestamp": 1578694838963, "ltp": 2.18, "tv": 9289.31, "trd": [[2.18, 285.17]], "batb": [[0, 2.18, 180], [1, 2.16, 319.7], [2, 2.12, 48.2]], "batl": [[0, 2.2, 65.81], [1, 2.22, 70], [2, 2.24, 32]]}, {"timestamp": 1578694845460, "ltp": 2.18, "tv": 9289.31, "trd": NaN, "batb": [[1, 2.16, 197.24]], "batl": NaN}, {"timestamp": 1578694880976, "ltp": 2.18, "tv": 9289.31, "trd": NaN, "batb": [[2, 2.12, 10.6]], "batl": NaN}, {"timestamp": 1578695033146, "ltp": 2.18, "tv": 9329.31, "trd": [[2.18, 325.17]], "batb": [[0, 2.18, 160]], "batl": NaN}, {"timestamp": 1578695288844, "ltp": 2.2, "tv": 9362.03, "trd": [[2.2, 177.07]], "batb": NaN, "batl": [[0, 2.2, 49.45]]}, {"timestamp": 1578695320115, "ltp": 2.2, "tv": 9460.92, "trd": [[2.2, 275.96]], "batb": [[0, 2.2, 150.56], [1, 2.18, 160], [2, 2.16, 197.24]], "batl": [[0, 2.22, 70], [1, 2.24, 32], [2, 2.26, 10]]}, {"timestamp": 1578695384397, "ltp": 2.2, "tv": 9464.32, "trd": [[2.2, 279.36]], "batb": [[0, 2.2, 148.86]], "batl": NaN}, {"timestamp": 1578695589257, "ltp": 2.2, "tv": 9464.32, "trd": NaN, "batb": NaN, "batl": [[2, 2.26, 11.53]]}, {"timestamp": 1578695925625, "ltp": 2.2, "tv": 9464.32, "trd": NaN, "batb": NaN, "batl": [[0, 2.22, 71.53], [2, 2.26, 10]]}, {"timestamp": 1578695963251, "ltp": 2.2, "tv": 9464.32, "trd": NaN, "batb": [[0, 2.2, 269.09]], "batl": NaN}, {"timestamp": 1578696010895, "ltp": 2.2, "tv": 9464.32, "trd": NaN, "batb": [[0, 2.2, 148.86]], "batl": NaN}, {"timestamp": 1578696055187, "ltp": 2.2, "tv": 9472.84, "trd": [[2.2, 287.88]], "batb": [[0, 2.2, 144.6]], "batl": NaN}, {"timestamp": 1578696164925, "ltp": 2.2, "tv": 9512.1, "trd": [[2.2, 327.14]], "batb": [[0, 2.2, 124.97]], "batl": NaN}, {"timestamp": 1578696265331, "ltp": 2.2, "tv": 9512.1, "trd": NaN, "batb": [[0, 2.2, 245.2]], "batl": NaN}, {"timestamp": 1578696333688, "ltp": 2.2, "tv": 9572.1, "trd": [[2.2, 387.14]], "batb": [[0, 2.2, 215.2]], "batl": NaN}, {"timestamp": 1578696393751, "ltp": 2.2, "tv": 9572.1, "trd": NaN, "batb": [[0, 2.2, 94.97]], "batl": NaN}, {"timestamp": 1578696399559, "ltp": 2.2, "tv": 9572.1, "trd": NaN, "batb": NaN, "batl": [[1, 2.24, 42]]}, {"timestamp": 1578696406733, "ltp": 2.18, "tv": 9786.74, "trd": [[2.18, 349.87], [2.2, 577.08]], "batb": [[0, 2.18, 147.65], [1, 2.16, 197.24], [2, 2.12, 10.6]], "batl": [[0, 2.2, 405.03], [1, 2.22, 71.53], [2, 2.24, 42]]}, {"timestamp": 1578696496934, "ltp": 2.18, "tv": 9786.74, "trd": NaN, "batb": [[0, 2.18, 171.1]], "batl": NaN}, {"timestamp": 1578696504350, "ltp": 2.18, "tv": 9786.74, "trd": NaN, "batb": [[0, 2.18, 292.44]], "batl": NaN}, {"timestamp": 1578696508972, "ltp": 2.2, "tv": 9803.92, "trd": [[2.2, 594.26]], "batb": NaN, "batl": [[0, 2.2, 396.44]]}, {"timestamp": 1578696520561, "ltp": 2.2, "tv": 9803.92, "trd": NaN, "batb": [[0, 2.18, 171.1]], "batl": NaN}, {"timestamp": 1578696537995, "ltp": 2.18, "tv": 9815.92, "trd": [[2.18, 361.87]], "batb": [[0, 2.18, 165.1]], "batl": NaN}, {"timestamp": 1578696553752, "ltp": 2.18, "tv": 9815.92, "trd": NaN, "batb": NaN, "batl": [[1, 2.22, 571.53]]}, {"timestamp": 1578696668904, "ltp": 2.18, "tv": 9815.92, "trd": NaN, "batb": [[1, 2.12, 10.6], [2, 2.1, 577.93]], "batl": NaN}, {"timestamp": 1578696877969, "ltp": 2.18, "tv": 10146.11, "trd": [[2.18, 692.06]], "batb": [[0, 2.12, 10.6], [1, 2.1, 577.93], [2, 2.08, 6]], "batl": [[0, 2.18, 334.91], [1, 2.2, 396.44], [2, 2.22, 571.53]]}, {"timestamp": 1578696878789, "ltp": 2.18, "tv": 10146.11, "trd": NaN, "batb": NaN, "batl": [[0, 2.16, 30.65], [1, 2.18, 334.91], [2, 2.2, 396.44]]}, {"timestamp": 1578696879869, "ltp": 2.18, "tv": 10146.11, "trd": NaN, "batb": [[0, 2.12, 21.15]], "batl": [[0, 2.16, 60.15]]}, {"timestamp": 1578696883777, "ltp": 2.16, "tv": 10192.39, "trd": [[2.16, 785.17]], "batb": NaN, "batl": [[0, 2.16, 37]]}, {"timestamp": 1578696886952, "ltp": 2.16, "tv": 10192.39, "trd": NaN, "batb": [[0, 2.12, 29.8]], "batl": NaN}, {"timestamp": 1578696889769, "ltp": 2.16, "tv": 10251.83, "trd": [[2.16, 844.61]], "batb": [[0, 2.12, 154.57]], "batl": [[0, 2.16, 7.27]]}, {"timestamp": 1578696895967, "ltp": 2.12, "tv": 10560.76, "trd": [[2.12, 616.64]], "batb": [[0, 2.1, 577.93], [1, 2.08, 6], [2, 2.06, 100]], "batl": [[0, 2.12, 180.55], [1, 2.16, 7.27]]}, {"timestamp": 1578696896992, "ltp": 2.12, "tv": 10586.02, "trd": [[2.12, 641.9]], "batb": [[0, 2.1, 598.8]], "batl": [[0, 2.12, 167.92], [1, 2.2, 396.44], [2, 2.22, 571.53]]}, {"timestamp": 1578696898789, "ltp": 2.12, "tv": 10586.02, "trd": NaN, "batb": [[0, 2.1, 612.94]], "batl": NaN}, {"timestamp": 1578696911934, "ltp": 2.1, "tv": 10921.86, "trd": [[2.1, 355.36]], "batb": [[0, 2.1, 445.01]], "batl": [[0, 2.2, 396.44], [1, 2.22, 571.53], [2, 2.24, 42]]}, {"timestamp": 1578696921004, "ltp": 2.1, "tv": 10921.86, "trd": NaN, "batb": NaN, "batl": [[0, 2.22, 21.53], [1, 2.24, 42], [2, 2.26, 10]]}, {"timestamp": 1578696923000, "ltp": 2.1, "tv": 10921.86, "trd": NaN, "batb": [[0, 2.12, 3], [1, 2.1, 445.01], [2, 2.08, 6]], "batl": NaN}, {"timestamp": 1578696950584, "ltp": 2.1, "tv": 10921.86, "trd": NaN, "batb": [[0, 2.12, 503]], "batl": NaN}, {"timestamp": 1578696951981, "ltp": 2.1, "tv": 10921.86, "trd": NaN, "batb": [[0, 2.14, 61.33], [1, 2.12, 503], [2, 2.1, 430.88]], "batl": NaN}, {"timestamp": 1578696952967, "ltp": 2.1, "tv": 10921.86, "trd": NaN, "batb": [[0, 2.14, 129.28], [2, 2.1, 410.01]], "batl": NaN}, {"timestamp": 1578696978999, "ltp": 2.1, "tv": 10921.86, "trd": NaN, "batb": [[1, 2.12, 500]], "batl": [[0, 2.2, 20], [1, 2.22, 21.53], [2, 2.24, 42]]}, {"timestamp": 1578697004116, "ltp": 2.2, "tv": 10940.59, "trd": [[2.2, 612.99]], "batb": NaN, "batl": [[0, 2.2, 10.64]]}, {"timestamp": 1578697018646, "ltp": 2.2, "tv": 10940.59, "trd": NaN, "batb": NaN, "batl": [[0, 2.18, 2], [1, 2.2, 10.64], [2, 2.22, 21.53]]}, {"timestamp": 1578697062665, "ltp": 2.14, "tv": 10946.59, "trd": [[2.14, 515.83]], "batb": [[0, 2.14, 126.28]], "batl": NaN}, {"timestamp": 1578697077916, "ltp": 2.14, "tv": 10946.59, "trd": NaN, "batb": [[0, 2.16, 8.08], [1, 2.14, 126.28], [2, 2.12, 500]], "batl": NaN}, {"timestamp": 1578697095807, "ltp": 2.14, "tv": 10946.59, "trd": NaN, "batb": NaN, "batl": [[0, 2.18, 5.06]]}, {"timestamp": 1578697208827, "ltp": 2.14, "tv": 10945.59, "trd": [[1.9, 441.8], [1.91, 9.96], [1.92, 22.74], [1.93, 21.52], [1.95, 286.01], [1.99, 101.94], [2, 2038.14], [2.02, 851.93], [2.06, 741.3], [2.08, 262.3], [2.1, 355.36], [2.12, 641.5], [2.14, 515.79], [2.16, 844.55], [2.18, 692.01], [2.2, 612.94]], "batb": [[0, 2.16, 8.08], [1, 2.14, 126.18]], "batl": [[0, 2.18, 5.06]]}, {"timestamp": 1578697231963, "ltp": 2.14, "tv": 10945.59, "trd": NaN, "batb": [[1, 2.14, 135.48]], "batl": NaN}, {"timestamp": 1578697233972, "ltp": 2.18, "tv": 10955.72, "trd": [[2.18, 702.13]], "batb": [[0, 2.18, 4.66], [1, 2.16, 8.08], [2, 2.14, 135.48]], "batl": [[0, 2.2, 10.64], [1, 2.22, 21.53], [2, 2.24, 42]]}, {"timestamp": 1578697278894, "ltp": 2.2, "tv": 10977.0, "trd": [[2.2, 634.22]], "batb": [[0, 2.2, 10.64], [1, 2.18, 4.66], [2, 2.16, 8.08]], "batl": [[0, 2.22, 21.53], [1, 2.24, 42], [2, 2.26, 10]]}, {"timestamp": 1578697285937, "ltp": 2.2, "tv": 10998.28, "trd": [[2.2, 655.5]], "batb": [[0, 2.18, 4.66], [1, 2.16, 8.08], [2, 2.14, 104.16]], "batl": [[0, 2.2, 11.56], [1, 2.22, 21.53], [2, 2.24, 42]]}, {"timestamp": 1578697286712, "ltp": 2.2, "tv": 10998.28, "trd": NaN, "batb": [[2, 2.14, 198.66]], "batl": NaN}, {"timestamp": 1578697382327, "ltp": 2.2, "tv": 10998.28, "trd": NaN, "batb": NaN, "batl": [[0, 2.2, 28]]}, {"timestamp": 1578697414695, "ltp": 2.2, "tv": 10998.28, "trd": NaN, "batb": NaN, "batl": [[0, 2.2, 30]]}, {"timestamp": 1578697471974, "ltp": 2.2, "tv": 10998.28, "trd": NaN, "batb": [[2, 2.14, 189.36]], "batl": NaN}, {"timestamp": 1578697649758, "ltp": 2.2, "tv": 11023.82, "trd": [[2.2, 681.04]], "batb": NaN, "batl": [[0, 2.2, 17.23]]}, {"timestamp": 1578697728747, "ltp": 2.2, "tv": 11023.82, "trd": NaN, "batb": [[0, 2.18, 24.66]], "batl": NaN}, {"timestamp": 1578697757424, "ltp": 2.2, "tv": 11023.82, "trd": NaN, "batb": NaN, "batl": [[1, 2.22, 20]]}, {"timestamp": 1578697766631, "ltp": 2.2, "tv": 11029.84, "trd": [[2.2, 687.06]], "batb": NaN, "batl": [[0, 2.2, 14.22]]}, {"timestamp": 1578697770002, "ltp": 2.18, "tv": 11041.07, "trd": [[2.18, 707.24], [2.2, 693.18]], "batb": [[0, 2.18, 22.11]], "batl": [[0, 2.2, 14.22]]}, {"timestamp": 1578698023715, "ltp": 2.18, "tv": 11041.07, "trd": NaN, "batb": [[1, 2.16, 17.8], [2, 2.14, 94.86]], "batl": NaN}, {"timestamp": 1578698025487, "ltp": 2.18, "tv": 11041.07, "trd": NaN, "batb": [[1, 2.16, 8.08], [2, 2.14, 47.43]], "batl": NaN}, {"timestamp": 1578698026102, "ltp": 2.18, "tv": 11041.07, "trd": NaN, "batb": [[2, 2.12, 6]], "batl": NaN}, {"timestamp": 1578698047947, "ltp": 2.18, "tv": 11085.28, "trd": [[2.18, 751.46]], "batb": [[0, 2.16, 8.08], [1, 2.12, 6], [2, 2.1, 410.01]], "batl": [[0, 2.18, 477.89], [1, 2.2, 14.22], [2, 2.22, 20]]}, {"timestamp": 1578698048818, "ltp": 2.18, "tv": 11085.28, "trd": NaN, "batb": [[1, 2.12, 37.54]], "batl": NaN}, {"timestamp": 1578698052855, "ltp": 2.18, "tv": 11085.28, "trd": NaN, "batb": [[1, 2.12, 58.02]], "batl": NaN}, {"timestamp": 1578698055723, "ltp": 2.18, "tv": 11085.28, "trd": NaN, "batb": NaN, "batl": [[2, 2.22, 30]]}, {"timestamp": 1578698075437, "ltp": 2.18, "tv": 11085.28, "trd": NaN, "batb": NaN, "batl": [[1, 2.2, 347.22]]}, {"timestamp": 1578698281977, "ltp": 2.18, "tv": 11085.28, "trd": NaN, "batb": NaN, "batl": [[1, 2.2, 344.16]]}, {"timestamp": 1578698282181, "ltp": 2.18, "tv": 11085.28, "trd": NaN, "batb": NaN, "batl": [[0, 2.18, 480.95]]}, {"timestamp": 1578698284797, "ltp": 2.18, "tv": 11085.28, "trd": NaN, "batb": NaN, "batl": [[0, 2.18, 477.89]]}, {"timestamp": 1578698285773, "ltp": 2.16, "tv": 11091.46, "trd": [[2.16, 850.73]], "batb": [[0, 2.16, 4.99]], "batl": NaN}, {"timestamp": 1578698286901, "ltp": 2.16, "tv": 11101.44, "trd": [[2.16, 860.71]], "batb": [[0, 2.12, 58.02], [1, 2.1, 410.01], [2, 2.08, 6]], "batl": [[0, 2.16, 15.01], [1, 2.18, 477.89], [2, 2.2, 344.16]]}, {"timestamp": 1578698289981, "ltp": 2.16, "tv": 11101.44, "trd": NaN, "batb": NaN, "batl": [[0, 2.16, 18.07]]}, {"timestamp": 1578698325457, "ltp": 2.16, "tv": 11101.44, "trd": NaN, "batb": NaN, "batl": [[0, 2.14, 15.01], [1, 2.16, 3.06], [2, 2.18, 477.89]]}, {"timestamp": 1578698329974, "ltp": 2.12, "tv": 11131.46, "trd": [[2.12, 671.51]], "batb": [[0, 2.12, 43.01]], "batl": [[0, 2.16, 3.06], [1, 2.18, 477.89], [2, 2.2, 344.16]]}, {"timestamp": 1578698339361, "ltp": 2.12, "tv": 11131.46, "trd": NaN, "batb": NaN, "batl": [[0, 2.14, 6], [1, 2.16, 3.06], [2, 2.18, 477.89]]}, {"timestamp": 1578698438410, "ltp": 2.14, "tv": 11143.46, "trd": [[2.14, 527.79]], "batb": [[0, 2.14, 6.95], [1, 2.12, 43.01], [2, 2.1, 410.01]], "batl": [[0, 2.16, 3.06], [1, 2.18, 477.89], [2, 2.2, 344.16]]}, {"timestamp": 1578698532280, "ltp": 2.14, "tv": 11157.36, "trd": [[2.14, 541.69]], "batb": [[0, 2.12, 43.01], [1, 2.1, 410.01], [2, 2.08, 6]], "batl": [[0, 2.14, 18.05], [1, 2.16, 3.06], [2, 2.18, 477.89]]}, {"timestamp": 1578698608888, "ltp": 2.14, "tv": 11157.36, "trd": NaN, "batb": NaN, "batl": [[1, 2.18, 477.89], [2, 2.2, 344.16]]}, {"timestamp": 1578698688774, "ltp": 2.14, "tv": 11193.46, "trd": [[2.14, 577.79]], "batb": [[0, 2.14, 81.95], [1, 2.12, 43.01], [2, 2.1, 410.01]], "batl": [[0, 2.18, 477.89], [1, 2.2, 344.16], [2, 2.22, 20]]}, {"timestamp": 1578698701892, "ltp": 2.14, "tv": 11193.46, "trd": NaN, "batb": NaN, "batl": [[0, 2.2, 344.16], [1, 2.22, 20], [2, 2.24, 42]]}, {"timestamp": 1578698702710, "ltp": 2.14, "tv": 11193.46, "trd": NaN, "batb": [[0, 2.16, 12.47], [1, 2.14, 81.95], [2, 2.12, 43.01]], "batl": NaN}, {"timestamp": 1578698703896, "ltp": 2.14, "tv": 11193.46, "trd": NaN, "batb": [[0, 2.16, 23.23], [2, 2.12, 22.53]], "batl": NaN}, {"timestamp": 1578698704613, "ltp": 2.14, "tv": 11193.46, "trd": NaN, "batb": [[0, 2.16, 34.66], [2, 2.1, 410.01]], "batl": NaN}, {"timestamp": 1578698706980, "ltp": 2.14, "tv": 11193.46, "trd": NaN, "batb": NaN, "batl": [[0, 2.2, 11.16]]}, {"timestamp": 1578698709596, "ltp": 2.14, "tv": 11193.46, "trd": NaN, "batb": NaN, "batl": [[0, 2.2, 2]]}, {"timestamp": 1578698712991, "ltp": 2.14, "tv": 11193.46, "trd": NaN, "batb": [[2, 2.12, 6]], "batl": NaN}, {"timestamp": 1578698779989, "ltp": 2.16, "tv": 11237.46, "trd": [[2.16, 904.71]], "batb": [[0, 2.16, 12.66]], "batl": NaN}, {"timestamp": 1578698781218, "ltp": 2.16, "tv": 11239.92, "trd": [[2.16, 907.17]], "batb": [[0, 2.14, 81.95], [1, 2.12, 27.93], [2, 2.1, 410.01]], "batl": NaN}, {"timestamp": 1578698797130, "ltp": 2.16, "tv": 11239.92, "trd": NaN, "batb": [[1, 2.12, 40.73]], "batl": NaN}, {"timestamp": 1578698861587, "ltp": 2.14, "tv": 11243.92, "trd": [[2.14, 581.79]], "batb": [[0, 2.14, 79.95]], "batl": NaN}, {"timestamp": 1578698907953, "ltp": 2.14, "tv": 11243.92, "trd": NaN, "batb": [[0, 2.16, 8.08], [1, 2.14, 79.95], [2, 2.12, 40.73]], "batl": NaN}, {"timestamp": 1578698908974, "ltp": 2.14, "tv": 11243.92, "trd": NaN, "batb": [[0, 2.16, 19.51], [2, 2.12, 18.8]], "batl": NaN}, {"timestamp": 1578698934860, "ltp": 2.16, "tv": 11281.92, "trd": [[2.16, 945.16]], "batb": [[0, 2.14, 79.95], [1, 2.12, 18.8], [2, 2.1, 410.01]], "batl": NaN}, {"timestamp": 1578699119972, "ltp": 2.14, "tv": 11290.43, "trd": [[2.14, 590.31]], "batb": [[0, 2.14, 75.69]], "batl": NaN}, {"timestamp": 1578699331966, "ltp": 2.14, "tv": 11290.43, "trd": NaN, "batb": NaN, "batl": [[0, 2.16, 2.88], [1, 2.2, 2], [2, 2.22, 20]]}, {"timestamp": 1578699455515, "ltp": 2.14, "tv": 11430.43, "trd": [[2.14, 730.31]], "batb": [[0, 2.14, 5.69]], "batl": NaN}, {"timestamp": 1578699458897, "ltp": 2.14, "tv": 11430.43, "trd": NaN, "batb": [[1, 2.12, 28.67]], "batl": NaN}, {"timestamp": 1578699461922, "ltp": 2.14, "tv": 11430.43, "trd": NaN, "batb": NaN, "batl": [[0, 2.16, 202.88]]}, {"timestamp": 1578699463000, "ltp": 2.14, "tv": 11441.81, "trd": [[2.14, 741.68]], "batb": [[0, 2.12, 38.24], [1, 2.1, 410.01], [2, 2.08, 6]], "batl": [[0, 2.14, 12.73], [1, 2.16, 202.88], [2, 2.2, 2]]}, {"timestamp": 1578699481638, "ltp": 2.14, "tv": 11441.81, "trd": NaN, "batb": [[0, 2.12, 25.44]], "batl": NaN}, {"timestamp": 1578699501746, "ltp": 2.14, "tv": 11441.81, "trd": NaN, "batb": [[0, 2.12, 121.63]], "batl": NaN}, {"timestamp": 1578699502869, "ltp": 2.14, "tv": 11441.81, "trd": NaN, "batb": NaN, "batl": [[0, 2.16, 202.88], [1, 2.2, 2], [2, 2.22, 20]]}, {"timestamp": 1578699503948, "ltp": 2.14, "tv": 11441.81, "trd": NaN, "batb": [[0, 2.14, 34.6], [1, 2.12, 121.63], [2, 2.1, 410.01]], "batl": NaN}, {"timestamp": 1578699545866, "ltp": 2.14, "tv": 11441.81, "trd": NaN, "batb": [[0, 2.14, 234.6], [1, 2.12, 111.76]], "batl": NaN}, {"timestamp": 1578699605558, "ltp": 2.14, "tv": 11445.81, "trd": [[2.14, 745.68]], "batb": [[0, 2.14, 232.6]], "batl": NaN}, {"timestamp": 1578699633699, "ltp": 2.14, "tv": 11445.81, "trd": NaN, "batb": NaN, "batl": [[2, 2.22, 25.9]]}, {"timestamp": 1578699684937, "ltp": 2.14, "tv": 11449.81, "trd": [[2.14, 749.68]], "batb": [[0, 2.14, 230.6]], "batl": NaN}, {"timestamp": 1578699941498, "ltp": 2.14, "tv": 11449.81, "trd": NaN, "batb": [[1, 2.12, 15.58]], "batl": NaN}, {"timestamp": 1578699964791, "ltp": 2.14, "tv": 11449.81, "trd": NaN, "batb": NaN, "batl": [[2, 2.22, 29.9]]}, {"timestamp": 1578700128952, "ltp": 2.16, "tv": 11483.33, "trd": [[2.16, 978.68]], "batb": NaN, "batl": [[0, 2.16, 186.12]]}, {"timestamp": 1578700273333, "ltp": 2.16, "tv": 11483.33, "trd": NaN, "batb": NaN, "batl": [[0, 2.16, 232.42]]}, {"timestamp": 1578700490700, "ltp": 2.14, "tv": 11488.52, "trd": [[2.14, 754.88]], "batb": [[0, 2.14, 228]], "batl": NaN}, {"timestamp": 1578700800625, "ltp": 2.14, "tv": 11488.52, "trd": NaN, "batb": NaN, "batl": [[1, 2.18, 2], [2, 2.2, 2]]}, {"timestamp": 1578700826878, "ltp": 2.14, "tv": 11570.52, "trd": [[2.14, 836.88]], "batb": [[0, 2.14, 187]], "batl": NaN}, {"timestamp": 1578700910991, "ltp": 2.14, "tv": 11570.52, "trd": NaN, "batb": [[0, 2.12, 15.58], [1, 2.1, 410.01], [2, 2.08, 6]], "batl": NaN}, {"timestamp": 1578700911660, "ltp": 2.14, "tv": 11570.52, "trd": NaN, "batb": [[0, 2.12, 239.92]], "batl": NaN}, {"timestamp": 1578700925269, "ltp": 2.14, "tv": 11570.52, "trd": NaN, "batb": NaN, "batl": [[0, 2.14, 94], [1, 2.16, 232.42], [2, 2.18, 2]]}, {"timestamp": 1578700971843, "ltp": 2.14, "tv": 11570.52, "trd": NaN, "batb": [[0, 2.12, 364.34]], "batl": NaN}, {"timestamp": 1578701092892, "ltp": 2.14, "tv": 11611.82, "trd": [[2.14, 878.18]], "batb": NaN, "batl": [[0, 2.14, 73.35]]}, {"timestamp": 1578701232435, "ltp": 2.14, "tv": 11705.32, "trd": [[2.14, 971.68]], "batb": NaN, "batl": [[0, 2.14, 26.6]]}, {"timestamp": 1578701335864, "ltp": 2.12, "tv": 11711.32, "trd": [[2.12, 677.51]], "batb": [[0, 2.12, 361.34]], "batl": NaN}, {"timestamp": 1578701341248, "ltp": 2.12, "tv": 11711.32, "trd": NaN, "batb": NaN, "batl": [[0, 2.14, 29.6]]}, {"timestamp": 1578701833725, "ltp": 2.12, "tv": 11751.32, "trd": [[2.12, 717.51]], "batb": [[0, 2.12, 341.34]], "batl": NaN}, {"timestamp": 1578701835015, "ltp": 2.12, "tv": 11751.32, "trd": NaN, "batb": NaN, "batl": [[0, 2.14, 33.4]]}, {"timestamp": 1578702362939, "ltp": 2.12, "tv": 11751.32, "trd": NaN, "batb": [[0, 2.12, 216.92]], "batl": NaN}, {"timestamp": 1578702471730, "ltp": 2.12, "tv": 11775.32, "trd": [[2.12, 741.51]], "batb": [[0, 2.12, 204.92]], "batl": NaN}, {"timestamp": 1578702569978, "ltp": 2.12, "tv": 11775.32, "trd": NaN, "batb": NaN, "batl": [[0, 2.14, 79.7], [1, 2.16, 186.12]]}, {"timestamp": 1578702732715, "ltp": 2.12, "tv": 11775.32, "trd": NaN, "batb": [[0, 2.12, 329.34]], "batl": NaN}, {"timestamp": 1578702938792, "ltp": 2.12, "tv": 11863.4, "trd": [[2.12, 829.59]], "batb": [[0, 2.12, 117.72]], "batl": [[0, 2.14, 53.1]]}, {"timestamp": 1578702942904, "ltp": 2.12, "tv": 11863.4, "trd": NaN, "batb": [[0, 2.1, 528.85], [1, 2.08, 6], [2, 2.06, 100]], "batl": NaN}, {"timestamp": 1578702943518, "ltp": 2.12, "tv": 11863.4, "trd": NaN, "batb": [[0, 2.12, 9.76], [1, 2.1, 528.85], [2, 2.08, 6]], "batl": [[0, 2.14, 62.21]]}, {"timestamp": 1578702944902, "ltp": 2.12, "tv": 11863.4, "trd": NaN, "batb": NaN, "batl": [[0, 2.14, 71.12]]}, {"timestamp": 1578702948504, "ltp": 2.12, "tv": 11863.4, "trd": NaN, "batb": [[0, 2.12, 50.72]], "batl": NaN}, {"timestamp": 1578702959561, "ltp": 2.12, "tv": 11863.4, "trd": NaN, "batb": [[0, 2.12, 168.43], [1, 2.1, 410.01]], "batl": NaN}, {"timestamp": 1578702960955, "ltp": 2.12, "tv": 11863.4, "trd": NaN, "batb": NaN, "batl": [[0, 2.14, 62.01]]}, {"timestamp": 1578702961161, "ltp": 2.12, "tv": 11863.4, "trd": NaN, "batb": NaN, "batl": [[0, 2.14, 58.21]]}, {"timestamp": 1578704148923, "ltp": 2.12, "tv": 11883.4, "trd": [[2.12, 849.59]], "batb": [[0, 2.12, 158.43]], "batl": NaN}, {"timestamp": 1578704149637, "ltp": 2.12, "tv": 11883.4, "trd": NaN, "batb": NaN, "batl": [[0, 2.14, 67.37]]}, {"timestamp": 1578704278614, "ltp": 2.12, "tv": 11883.4, "trd": NaN, "batb": NaN, "batl": [[0, 2.14, 66.37]]}, {"timestamp": 1578704424668, "ltp": 2.12, "tv": 11883.4, "trd": NaN, "batb": [[0, 2.12, 257.17]], "batl": NaN}, {"timestamp": 1578704775083, "ltp": 2.14, "tv": 11888.4, "trd": [[2.14, 976.68]], "batb": NaN, "batl": [[0, 2.14, 63.87]]}, {"timestamp": 1578705070881, "ltp": 2.14, "tv": 11888.4, "trd": NaN, "batb": NaN, "batl": [[0, 2.14, 66.87]]}, {"timestamp": 1578705121694, "ltp": 2.14, "tv": 11888.4, "trd": NaN, "batb": NaN, "batl": [[0, 2.14, 63.87]]}, {"timestamp": 1578706194488, "ltp": 2.12, "tv": 12211.82, "trd": [[2.12, 1173.01]], "batb": [[0, 2.12, 95.49]], "batl": NaN}, {"timestamp": 1578706204996, "ltp": 2.12, "tv": 12211.82, "trd": NaN, "batb": [[0, 2.12, 219.9]], "batl": NaN}, {"timestamp": 1578706505916, "ltp": 2.14, "tv": 12339.56, "trd": [[2.14, 1104.42]], "batb": [[0, 2.14, 136.13], [1, 2.12, 219.9], [2, 2.1, 410.01]], "batl": [[0, 2.16, 186.12], [1, 2.18, 2], [2, 2.2, 28.38]]}, {"timestamp": 1578706508535, "ltp": 2.14, "tv": 12339.56, "trd": NaN, "batb": [[0, 2.14, 141.25]], "batl": NaN}, {"timestamp": 1578706509935, "ltp": 2.14, "tv": 12345.56, "trd": [[2.14, 1110.42]], "batb": [[0, 2.14, 138.25]], "batl": NaN}, {"timestamp": 1578707134502, "ltp": 2.14, "tv": 12345.56, "trd": NaN, "batb": [[0, 2.14, 261.5], [1, 2.12, 95.49]], "batl": NaN}, {"timestamp": 1578707267412, "ltp": 2.14, "tv": 12345.56, "trd": NaN, "batb": [[0, 2.14, 138.25]], "batl": NaN}, {"timestamp": 1578707286450, "ltp": 2.14, "tv": 12345.56, "trd": NaN, "batb": [[0, 2.14, 261.5]], "batl": NaN}, {"timestamp": 1578707468547, "ltp": 2.14, "tv": 12345.56, "trd": NaN, "batb": [[0, 2.14, 138.25]], "batl": NaN}, {"timestamp": 1578707506456, "ltp": 2.14, "tv": 12345.56, "trd": NaN, "batb": [[0, 2.14, 261.5]], "batl": NaN}, {"timestamp": 1578708138411, "ltp": 2.14, "tv": 12345.56, "trd": NaN, "batb": [[0, 2.14, 138.25]], "batl": NaN}, {"timestamp": 1578708157338, "ltp": 2.14, "tv": 12345.56, "trd": NaN, "batb": [[0, 2.14, 261.5]], "batl": NaN}, {"timestamp": 1578708388284, "ltp": 2.14, "tv": 12385.56, "trd": [[2.14, 1150.42]], "batb": [[0, 2.14, 241.5]], "batl": NaN}, {"timestamp": 1578708447614, "ltp": 2.14, "tv": 12385.56, "trd": NaN, "batb": [[0, 2.14, 118.25]], "batl": NaN}, {"timestamp": 1578708495779, "ltp": 2.14, "tv": 12405.56, "trd": [[2.14, 1170.42]], "batb": [[0, 2.14, 108.25]], "batl": NaN}, {"timestamp": 1578708771868, "ltp": 2.14, "tv": 12622.05, "trd": [[2.14, 1386.92]], "batb": [[0, 2.12, 95.49], [1, 2.1, 410.01], [2, 2.08, 6]], "batl": [[0, 2.14, 91.75], [1, 2.16, 186.12], [2, 2.18, 2]]}, {"timestamp": 1578709115487, "ltp": 2.14, "tv": 12622.05, "trd": NaN, "batb": [[0, 2.1, 410.01], [1, 2.08, 6], [2, 2.06, 100]], "batl": NaN}, {"timestamp": 1578709259331, "ltp": 2.14, "tv": 12622.05, "trd": NaN, "batb": [[0, 2.12, 8.23], [1, 2.1, 410.01], [2, 2.08, 6]], "batl": NaN}, {"timestamp": 1578709551842, "ltp": 2.12, "tv": 12638.51, "trd": [[2.12, 1189.47]], "batb": [[0, 2.1, 410.01], [1, 2.08, 6], [2, 2.06, 100]], "batl": [[0, 2.12, 91.77], [1, 2.14, 91.75], [2, 2.16, 186.12]]}, {"timestamp": 1578709555808, "ltp": 2.12, "tv": 12734.07, "trd": [[2.12, 1285.03]], "batb": [[0, 2.1, 535.61]], "batl": [[0, 2.12, 43.99]]}, {"timestamp": 1578711091906, "ltp": 2.12, "tv": 12734.07, "trd": NaN, "batb": NaN, "batl": [[0, 2.12, 45.95]]}, {"timestamp": 1578711092939, "ltp": 2.12, "tv": 12737.99, "trd": [[2.12, 1288.94]], "batb": NaN, "batl": [[0, 2.12, 43.99]]}, {"timestamp": 1578711442153, "ltp": 2.1, "tv": 12753.99, "trd": [[2.1, 371.36]], "batb": [[0, 2.1, 527.61]], "batl": NaN}, {"timestamp": 1578711573805, "ltp": 2.1, "tv": 12754.39, "trd": [[2.1, 371.76]], "batb": [[0, 2.1, 527.41]], "batl": NaN}, {"timestamp": 1578713339791, "ltp": 2.1, "tv": 12754.39, "trd": NaN, "batb": NaN, "batl": [[0, 2.12, 45.99]]}, {"timestamp": 1578715707930, "ltp": 2.12, "tv": 12846.37, "trd": [[2.12, 1380.92]], "batb": [[0, 2.12, 3], [1, 2.1, 527.41], [2, 2.08, 6]], "batl": [[0, 2.14, 91.75], [1, 2.16, 186.12], [2, 2.18, 2]]}, {"timestamp": 1578716336368, "ltp": 2.12, "tv": 12846.37, "trd": NaN, "batb": [[0, 2.12, 104.29]], "batl": NaN}, {"timestamp": 1578716337870, "ltp": 2.12, "tv": 12846.37, "trd": NaN, "batb": [[1, 2.1, 401.81]], "batl": NaN}, {"timestamp": 1578716838339, "ltp": 2.12, "tv": 12866.36, "trd": [[2.12, 1400.92]], "batb": [[0, 2.12, 94.3]], "batl": NaN}, {"timestamp": 1578716854778, "ltp": 2.12, "tv": 12866.36, "trd": NaN, "batb": [[0, 2.1, 401.81], [1, 2.08, 6], [2, 2.06, 100]], "batl": NaN}, {"timestamp": 1578716865309, "ltp": 2.12, "tv": 12866.36, "trd": NaN, "batb": [[0, 2.1, 527.41]], "batl": NaN}, {"timestamp": 1578716998319, "ltp": 2.12, "tv": 12866.36, "trd": NaN, "batb": [[0, 2.12, 8.23], [1, 2.1, 527.41], [2, 2.08, 6]], "batl": NaN}, {"timestamp": 1578717301975, "ltp": 2.12, "tv": 12882.82, "trd": [[2.12, 1417.38]], "batb": [[0, 2.1, 527.41], [1, 2.08, 6], [2, 2.06, 100]], "batl": [[0, 2.12, 1.77], [1, 2.14, 91.75], [2, 2.16, 186.12]]}, {"timestamp": 1578717334690, "ltp": 2.1, "tv": 12886.36, "trd": [[2.1, 375.3]], "batb": [[0, 2.1, 525.64]], "batl": [[0, 2.14, 91.75], [1, 2.16, 186.12], [2, 2.18, 2]]}, {"timestamp": 1578717629563, "ltp": 2.1, "tv": 12886.36, "trd": NaN, "batb": [[0, 2.12, 8.23], [1, 2.1, 525.64], [2, 2.08, 6]], "batl": NaN}, {"timestamp": 1578721059753, "ltp": 2.1, "tv": 12886.36, "trd": NaN, "batb": [[1, 2.1, 400.04]], "batl": NaN}, {"timestamp": 1578722040893, "ltp": 2.12, "tv": 12902.82, "trd": [[2.12, 1433.84]], "batb": [[0, 2.1, 400.04], [1, 2.08, 6], [2, 2.06, 100]], "batl": [[0, 2.12, 11.77], [1, 2.14, 91.75], [2, 2.16, 186.12]]}, {"timestamp": 1578722045782, "ltp": 2.12, "tv": 12902.82, "trd": NaN, "batb": NaN, "batl": [[0, 2.14, 91.75], [1, 2.16, 186.12], [2, 2.18, 2]]}, {"timestamp": 1578722048002, "ltp": 2.12, "tv": 12902.82, "trd": NaN, "batb": [[0, 2.1, 525.64]], "batl": NaN}, {"timestamp": 1578722060808, "ltp": 2.1, "tv": 12908.82, "trd": [[2.1, 381.3]], "batb": [[0, 2.1, 522.64]], "batl": NaN}, {"timestamp": 1578722122714, "ltp": 2.1, "tv": 12908.82, "trd": NaN, "batb": [[0, 2.12, 2], [1, 2.1, 522.64], [2, 2.08, 6]], "batl": NaN}, {"timestamp": 1578722450934, "ltp": 2.1, "tv": 12908.82, "trd": NaN, "batb": NaN, "batl": [[0, 2.14, 105.75]]}, {"timestamp": 1578723261669, "ltp": 2.14, "tv": 12917.82, "trd": [[2.14, 1395.92]], "batb": NaN, "batl": [[0, 2.14, 101.25]]}, {"timestamp": 1578723303932, "ltp": 2.14, "tv": 12917.82, "trd": NaN, "batb": [[1, 2.1, 397.04]], "batl": NaN}, {"timestamp": 1578723447647, "ltp": 2.14, "tv": 12917.82, "trd": NaN, "batb": [[1, 2.1, 522.64]], "batl": NaN}, {"timestamp": 1578723463968, "ltp": 2.14, "tv": 12917.82, "trd": NaN, "batb": [[1, 2.1, 397.04]], "batl": NaN}, {"timestamp": 1578723908285, "ltp": 2.14, "tv": 12917.82, "trd": NaN, "batb": [[1, 2.1, 522.64]], "batl": NaN}, {"timestamp": 1578723936318, "ltp": 2.14, "tv": 12927.82, "trd": [[2.14, 1405.92]], "batb": NaN, "batl": [[0, 2.14, 96.25]]}, {"timestamp": 1578724232641, "ltp": 2.14, "tv": 12927.82, "trd": NaN, "batb": [[1, 2.1, 397.04]], "batl": NaN}, {"timestamp": 1578724514714, "ltp": 2.12, "tv": 12931.82, "trd": [[2.12, 1437.84]], "batb": [[0, 2.1, 397.04], [1, 2.08, 6], [2, 2.06, 100]], "batl": NaN}, {"timestamp": 1578724539689, "ltp": 2.12, "tv": 12931.82, "trd": NaN, "batb": NaN, "batl": [[2, 2.18, 8.23]]}, {"timestamp": 1578724569539, "ltp": 2.1, "tv": 12988.78, "trd": [[2.1, 438.26]], "batb": [[0, 2.1, 368.56]], "batl": NaN}, {"timestamp": 1578724648950, "ltp": 2.1, "tv": 12988.78, "trd": NaN, "batb": [[0, 2.12, 8.23], [1, 2.1, 368.56], [2, 2.08, 6]], "batl": NaN}, {"timestamp": 1578724814682, "ltp": 2.12, "tv": 13005.25, "trd": [[2.12, 1454.3]], "batb": [[0, 2.1, 368.56], [1, 2.08, 6], [2, 2.06, 100]], "batl": NaN}, {"timestamp": 1578724824973, "ltp": 2.12, "tv": 13005.25, "trd": NaN, "batb": NaN, "batl": [[0, 2.14, 106.25]]}, {"timestamp": 1578724833982, "ltp": 2.12, "tv": 13005.25, "trd": NaN, "batb": NaN, "batl": [[0, 2.12, 2], [1, 2.14, 106.25], [2, 2.16, 186.12]]}, {"timestamp": 1578724842999, "ltp": 2.1, "tv": 13015.25, "trd": [[2.1, 448.26]], "batb": [[0, 2.1, 363.56]], "batl": NaN}, {"timestamp": 1578724880971, "ltp": 2.1, "tv": 13015.25, "trd": NaN, "batb": NaN, "batl": [[1, 2.14, 92.25]]}, {"timestamp": 1578724881739, "ltp": 2.1, "tv": 13015.25, "trd": NaN, "batb": NaN, "batl": [[0, 2.12, 16]]}, {"timestamp": 1578724887966, "ltp": 2.1, "tv": 13015.25, "trd": NaN, "batb": [[0, 2.1, 489.16]], "batl": NaN}, {"timestamp": 1578725664789, "ltp": 2.1, "tv": 13095.25, "trd": [[2.1, 528.26]], "batb": [[0, 2.1, 449.16]], "batl": NaN}, {"timestamp": 1578725921802, "ltp": 2.1, "tv": 13101.25, "trd": [[2.1, 534.26]], "batb": [[0, 2.1, 446.16]], "batl": NaN}, {"timestamp": 1578725999918, "ltp": 2.1, "tv": 13121.25, "trd": [[2.1, 554.26]], "batb": [[0, 2.1, 436.16]], "batl": NaN}, {"timestamp": 1578726308958, "ltp": 2.12, "tv": 13137.25, "trd": [[2.12, 1470.3]], "batb": NaN, "batl": [[0, 2.12, 8]]}, {"timestamp": 1578726441967, "ltp": 2.1, "tv": 13142.52, "trd": [[2.1, 559.54]], "batb": [[0, 2.1, 433.52]], "batl": NaN}, {"timestamp": 1578726534871, "ltp": 2.12, "tv": 13154.52, "trd": [[2.12, 1482.3]], "batb": NaN, "batl": [[0, 2.12, 2]]}, {"timestamp": 1578726647001, "ltp": 2.1, "tv": 13174.52, "trd": [[2.1, 579.54]], "batb": [[0, 2.1, 423.52]], "batl": NaN}, {"timestamp": 1578726801994, "ltp": 2.1, "tv": 13174.52, "trd": NaN, "batb": [[1, 2.08, 19.5]], "batl": NaN}, {"timestamp": 1578726824952, "ltp": 2.12, "tv": 13178.52, "trd": [[2.12, 1486.3]], "batb": [[0, 2.12, 14.21], [1, 2.1, 423.52], [2, 2.08, 19.5]], "batl": [[0, 2.14, 92.25], [1, 2.16, 186.12], [2, 2.18, 2]]}, {"timestamp": 1578726833974, "ltp": 2.12, "tv": 13178.52, "trd": NaN, "batb": NaN, "batl": [[0, 2.14, 105.25]]}, {"timestamp": 1578726834949, "ltp": 2.12, "tv": 13178.52, "trd": NaN, "batb": [[1, 2.1, 297.92]], "batl": NaN}, {"timestamp": 1578726854793, "ltp": 2.12, "tv": 13178.52, "trd": NaN, "batb": [[2, 2.08, 6]], "batl": NaN}, {"timestamp": 1578726963741, "ltp": 2.12, "tv": 13178.52, "trd": NaN, "batb": [[0, 2.12, 138.62]], "batl": NaN}, {"timestamp": 1578726978748, "ltp": 2.12, "tv": 13178.52, "trd": NaN, "batb": [[0, 2.12, 14.21]], "batl": NaN}, {"timestamp": 1578726992956, "ltp": 2.12, "tv": 13178.52, "trd": NaN, "batb": [[0, 2.12, 138.62]], "batl": NaN}, {"timestamp": 1578727064810, "ltp": 2.12, "tv": 13178.52, "trd": NaN, "batb": [[0, 2.12, 14.21]], "batl": NaN}, {"timestamp": 1578727356599, "ltp": 2.12, "tv": 13178.52, "trd": NaN, "batb": [[0, 2.12, 36.16]], "batl": NaN}, {"timestamp": 1578727461864, "ltp": 2.12, "tv": 13188.52, "trd": [[2.12, 1496.3]], "batb": [[0, 2.12, 31.16]], "batl": NaN}, {"timestamp": 1578727520961, "ltp": 2.12, "tv": 13213.72, "trd": [[2.12, 1521.5]], "batb": [[0, 2.12, 18.56]], "batl": [[0, 2.14, 254.9]]}, {"timestamp": 1578727541985, "ltp": 2.12, "tv": 13213.72, "trd": NaN, "batb": NaN, "batl": [[2, 2.18, 12.5]]}, {"timestamp": 1578727576917, "ltp": 2.12, "tv": 13229.72, "trd": [[2.12, 1537.5]], "batb": [[0, 2.12, 10.56]], "batl": NaN}, {"timestamp": 1578727636937, "ltp": 2.12, "tv": 13239.72, "trd": [[2.12, 1547.5]], "batb": [[0, 2.12, 5.56]], "batl": NaN}, {"timestamp": 1578727691922, "ltp": 2.14, "tv": 13739.72, "trd": [[2.14, 1905.92]], "batb": NaN, "batl": [[0, 2.14, 4.9]]}, {"timestamp": 1578727692800, "ltp": 2.14, "tv": 13739.72, "trd": NaN, "batb": [[0, 2.12, 15.85]], "batl": [[0, 2.14, 16.43]]}, {"timestamp": 1578727693992, "ltp": 2.14, "tv": 13739.72, "trd": NaN, "batb": NaN, "batl": [[0, 2.14, 26.05]]}, {"timestamp": 1578727697001, "ltp": 2.14, "tv": 13739.72, "trd": NaN, "batb": [[0, 2.12, 24.97], [1, 2.1, 303.59]], "batl": [[0, 2.14, 21.15]]}, {"timestamp": 1578727699796, "ltp": 2.14, "tv": 13739.72, "trd": NaN, "batb": NaN, "batl": [[0, 2.14, 34.15]]}, {"timestamp": 1578727709812, "ltp": 2.14, "tv": 13739.72, "trd": NaN, "batb": [[1, 2.1, 306.7]], "batl": NaN}, {"timestamp": 1578727717915, "ltp": 2.14, "tv": 13739.72, "trd": NaN, "batb": NaN, "batl": [[2, 2.18, 2]]}, {"timestamp": 1578727783918, "ltp": 2.12, "tv": 13739.76, "trd": [[2.12, 1547.54]], "batb": [[0, 2.12, 24.95]], "batl": NaN}, {"timestamp": 1578727819884, "ltp": 2.12, "tv": 13739.76, "trd": NaN, "batb": [[0, 2.12, 25.65]], "batl": NaN}, {"timestamp": 1578727912958, "ltp": 2.12, "tv": 13739.76, "trd": NaN, "batb": NaN, "batl": [[2, 2.18, 35]]}, {"timestamp": 1578727962990, "ltp": 2.12, "tv": 13739.76, "trd": NaN, "batb": [[0, 2.12, 150.06]], "batl": NaN}, {"timestamp": 1578727963976, "ltp": 2.12, "tv": 13739.76, "trd": NaN, "batb": NaN, "batl": [[0, 2.14, 13]]}, {"timestamp": 1578728015914, "ltp": 2.12, "tv": 13759.76, "trd": [[2.12, 1567.53]], "batb": [[0, 2.12, 140.07]], "batl": NaN}, {"timestamp": 1578728019955, "ltp": 2.12, "tv": 13759.76, "trd": NaN, "batb": [[0, 2.12, 15.65]], "batl": NaN}, {"timestamp": 1578728020847, "ltp": 2.12, "tv": 13759.76, "trd": NaN, "batb": NaN, "batl": [[0, 2.14, 38.36]]}, {"timestamp": 1578728569974, "ltp": 2.12, "tv": 13763.16, "trd": [[2.12, 1570.94]], "batb": [[0, 2.12, 13.95]], "batl": NaN}, {"timestamp": 1578728577858, "ltp": 2.12, "tv": 13763.16, "trd": NaN, "batb": [[0, 2.12, 15.65]], "batl": NaN}, {"timestamp": 1578728658963, "ltp": 2.14, "tv": 13812.23, "trd": [[2.14, 1954.98]], "batb": NaN, "batl": [[0, 2.14, 13.82]]}, {"timestamp": 1578728661907, "ltp": 2.14, "tv": 13812.23, "trd": NaN, "batb": NaN, "batl": [[0, 2.14, 30.82]]}, {"timestamp": 1578728792761, "ltp": 2.14, "tv": 13852.22, "trd": [[2.14, 1994.97]], "batb": [[0, 2.12, 26.05]], "batl": [[0, 2.14, 10.83]]}, {"timestamp": 1578728793950, "ltp": 2.14, "tv": 13852.22, "trd": NaN, "batb": [[0, 2.12, 35.82]], "batl": NaN}, {"timestamp": 1578728898794, "ltp": 2.16, "tv": 13901.28, "trd": [[2.14, 2016.63], [2.16, 1006.08]], "batb": [[0, 2.14, 8.15], [1, 2.12, 35.82], [2, 2.1, 306.7]], "batl": [[0, 2.16, 172.42], [1, 2.18, 35], [2, 2.2, 4284.42]]}, {"timestamp": 1578728899976, "ltp": 2.16, "tv": 13901.28, "trd": NaN, "batb": [[2, 2.1, 297.92]], "batl": NaN}, {"timestamp": 1578728939833, "ltp": 2.16, "tv": 13901.28, "trd": NaN, "batb": NaN, "batl": [[1, 2.18, 42.98]]}, {"timestamp": 1578728945730, "ltp": 2.16, "tv": 13901.28, "trd": NaN, "batb": NaN, "batl": [[0, 2.16, 183.42]]}, {"timestamp": 1578728994935, "ltp": 2.16, "tv": 13901.28, "trd": NaN, "batb": NaN, "batl": [[0, 2.16, 185.42]]}, {"timestamp": 1578729117908, "ltp": 2.16, "tv": 13901.28, "trd": NaN, "batb": [[0, 2.14, 47.86]], "batl": NaN}, {"timestamp": 1578729144836, "ltp": 2.16, "tv": 13901.28, "trd": NaN, "batb": [[1, 2.12, 49.29]], "batl": NaN}, {"timestamp": 1578729173929, "ltp": 2.16, "tv": 13901.28, "trd": NaN, "batb": [[0, 2.14, 66.41]], "batl": NaN}, {"timestamp": 1578729229928, "ltp": 2.16, "tv": 13901.28, "trd": NaN, "batb": [[0, 2.14, 75.08]], "batl": NaN}, {"timestamp": 1578729283723, "ltp": 2.16, "tv": 13901.28, "trd": NaN, "batb": [[0, 2.14, 79.13]], "batl": NaN}, {"timestamp": 1578729394941, "ltp": 2.16, "tv": 13901.28, "trd": NaN, "batb": [[0, 2.14, 82.21]], "batl": NaN}, {"timestamp": 1578729596973, "ltp": 2.14, "tv": 13937.29, "trd": [[2.14, 2052.64]], "batb": [[0, 2.14, 64.21]], "batl": NaN}, {"timestamp": 1578729646928, "ltp": 2.14, "tv": 13937.29, "trd": NaN, "batb": [[1, 2.12, 99.29]], "batl": NaN}, {"timestamp": 1578729668990, "ltp": 2.14, "tv": 13937.29, "trd": NaN, "batb": [[0, 2.14, 91.51]], "batl": NaN}, {"timestamp": 1578729670899, "ltp": 2.14, "tv": 13937.29, "trd": NaN, "batb": [[1, 2.12, 86.04]], "batl": NaN}, {"timestamp": 1578729724992, "ltp": 2.14, "tv": 13937.29, "trd": NaN, "batb": [[0, 2.14, 104.27]], "batl": NaN}, {"timestamp": 1578729778960, "ltp": 2.14, "tv": 13937.29, "trd": NaN, "batb": [[0, 2.14, 110.23]], "batl": NaN}, {"timestamp": 1578729790943, "ltp": 2.14, "tv": 13944.05, "trd": [[2.14, 2059.4]], "batb": [[0, 2.14, 106.85]], "batl": NaN}, {"timestamp": 1578729805966, "ltp": 2.14, "tv": 13952.05, "trd": [[2.14, 2067.4]], "batb": [[0, 2.14, 102.85]], "batl": NaN}, {"timestamp": 1578729818923, "ltp": 2.14, "tv": 13952.05, "trd": NaN, "batb": [[1, 2.12, 107.04], [2, 2.1, 319.92]], "batl": [[0, 2.16, 202.42], [1, 2.18, 59.98], [2, 2.2, 4301.42]]}, {"timestamp": 1578729833974, "ltp": 2.14, "tv": 13952.05, "trd": NaN, "batb": [[0, 2.14, 105.57]], "batl": NaN}, {"timestamp": 1578729905951, "ltp": 2.16, "tv": 13962.05, "trd": [[2.16, 1016.08]], "batb": NaN, "batl": [[0, 2.16, 197.42]]}, {"timestamp": 1578729926886, "ltp": 2.16, "tv": 13962.05, "trd": NaN, "batb": NaN, "batl": [[0, 2.16, 200.42]]}, {"timestamp": 1578729933000, "ltp": 2.16, "tv": 13962.05, "trd": NaN, "batb": NaN, "batl": [[0, 2.16, 322.54]]}, {"timestamp": 1578729963799, "ltp": 2.16, "tv": 13962.05, "trd": NaN, "batb": NaN, "batl": [[0, 2.16, 200.42]]}, {"timestamp": 1578729977329, "ltp": 2.16, "tv": 13962.05, "trd": NaN, "batb": NaN, "batl": [[0, 2.16, 322.54]]}, {"timestamp": 1578729991951, "ltp": 2.16, "tv": 13962.05, "trd": NaN, "batb": NaN, "batl": [[0, 2.16, 200.42]]}, {"timestamp": 1578730003977, "ltp": 2.16, "tv": 13962.05, "trd": NaN, "batb": [[0, 2.14, 177.07]], "batl": NaN}, {"timestamp": 1578730053848, "ltp": 2.16, "tv": 13962.05, "trd": NaN, "batb": [[0, 2.14, 181.51]], "batl": NaN}, {"timestamp": 1578730068801, "ltp": 2.16, "tv": 13962.05, "trd": NaN, "batb": [[1, 2.12, 115.04]], "batl": NaN}, {"timestamp": 1578730078002, "ltp": 2.16, "tv": 13962.05, "trd": NaN, "batb": [[2, 2.1, 327.92]], "batl": NaN}, {"timestamp": 1578730081889, "ltp": 2.16, "tv": 13962.05, "trd": NaN, "batb": NaN, "batl": [[0, 2.16, 197.42]]}, {"timestamp": 1578730109820, "ltp": 2.16, "tv": 13962.05, "trd": NaN, "batb": [[0, 2.14, 186.76]], "batl": NaN}, {"timestamp": 1578730129954, "ltp": 2.16, "tv": 13962.05, "trd": NaN, "batb": [[0, 2.14, 115.26], [1, 2.12, 186.54]], "batl": NaN}, {"timestamp": 1578730133966, "ltp": 2.16, "tv": 13962.05, "trd": NaN, "batb": [[2, 2.1, 329.92]], "batl": NaN}, {"timestamp": 1578730148979, "ltp": 2.16, "tv": 13962.05, "trd": NaN, "batb": [[0, 2.14, 147.26], [2, 2.1, 297.92]], "batl": NaN}, {"timestamp": 1578730149861, "ltp": 2.16, "tv": 13962.05, "trd": NaN, "batb": NaN, "batl": [[0, 2.16, 198.42]]}, {"timestamp": 1578730150957, "ltp": 2.16, "tv": 13962.05, "trd": NaN, "batb": [[0, 2.14, 169.35], [2, 2.1, 330.92]], "batl": NaN}, {"timestamp": 1578730160873, "ltp": 2.16, "tv": 13970.71, "trd": [[2.16, 1024.74]], "batb": NaN, "batl": [[0, 2.16, 194.09]]}, {"timestamp": 1578730163980, "ltp": 2.16, "tv": 13970.71, "trd": NaN, "batb": [[0, 2.14, 171.81]], "batl": NaN}, {"timestamp": 1578730236478, "ltp": 2.16, "tv": 13970.71, "trd": NaN, "batb": NaN, "batl": [[1, 2.18, 52]]}, {"timestamp": 1578730403918, "ltp": 2.14, "tv": 13990.71, "trd": [[2.14, 2087.4]], "batb": [[0, 2.14, 161.81]], "batl": NaN}, {"timestamp": 1578730438967, "ltp": 2.14, "tv": 13990.71, "trd": NaN, "batb": [[0, 2.14, 164.28]], "batl": NaN}, {"timestamp": 1578730443964, "ltp": 2.14, "tv": 13990.71, "trd": NaN, "batb": NaN, "batl": [[1, 2.18, 60]]}, {"timestamp": 1578730534859, "ltp": 2.14, "tv": 13990.71, "trd": NaN, "batb": [[0, 2.14, 169.38]], "batl": NaN}, {"timestamp": 1578730559986, "ltp": 2.14, "tv": 14020.71, "trd": [[2.14, 2117.4]], "batb": [[0, 2.14, 154.38]], "batl": NaN}, {"timestamp": 1578730634980, "ltp": 2.16, "tv": 14069.77, "trd": [[2.16, 1073.8]], "batb": NaN, "batl": [[0, 2.16, 169.56]]}, {"timestamp": 1578730686779, "ltp": 2.16, "tv": 14069.77, "trd": NaN, "batb": [[1, 2.12, 197.54]], "batl": NaN}, {"timestamp": 1578730704969, "ltp": 2.16, "tv": 14069.77, "trd": NaN, "batb": NaN, "batl": [[1, 2.18, 52]]}, {"timestamp": 1578730708970, "ltp": 2.16, "tv": 14069.77, "trd": NaN, "batb": [[2, 2.1, 344.92]], "batl": NaN}, {"timestamp": 1578730714975, "ltp": 2.16, "tv": 14069.77, "trd": NaN, "batb": [[0, 2.14, 169]], "batl": NaN}, {"timestamp": 1578730750899, "ltp": 2.16, "tv": 14079.97, "trd": [[2.16, 1084]], "batb": [[0, 2.14, 163.9]], "batl": [[0, 2.16, 164.46]]}, {"timestamp": 1578730769353, "ltp": 2.16, "tv": 14079.97, "trd": NaN, "batb": [[0, 2.14, 170.7]], "batl": NaN}, {"timestamp": 1578730788862, "ltp": 2.16, "tv": 14442.89, "trd": [[2.16, 1446.92]], "batb": [[0, 2.16, 18.54], [1, 2.14, 223.7], [2, 2.12, 210.54]], "batl": [[0, 2.18, 52], [1, 2.2, 4301.42], [2, 2.22, 178.33]]}, {"timestamp": 1578730789992, "ltp": 2.16, "tv": 14442.89, "trd": NaN, "batb": [[0, 2.16, 47.14], [2, 2.12, 200.14]], "batl": NaN}, {"timestamp": 1578730790976, "ltp": 2.16, "tv": 14442.89, "trd": NaN, "batb": [[0, 2.16, 82.61], [2, 2.12, 190.36]], "batl": NaN}, {"timestamp": 1578730791593, "ltp": 2.16, "tv": 14442.89, "trd": NaN, "batb": [[1, 2.14, 227.02]], "batl": NaN}, {"timestamp": 1578730810901, "ltp": 2.16, "tv": 14442.89, "trd": NaN, "batb": NaN, "batl": [[0, 2.18, 58.7]]}, {"timestamp": 1578730824850, "ltp": 2.16, "tv": 14442.89, "trd": NaN, "batb": [[1, 2.14, 110.41]], "batl": [[2, 2.22, 38.5]]}, {"timestamp": 1578730825621, "ltp": 2.16, "tv": 14442.89, "trd": NaN, "batb": NaN, "batl": [[0, 2.18, 72.7]]}, {"timestamp": 1578730837878, "ltp": 2.16, "tv": 14442.89, "trd": NaN, "batb": NaN, "batl": [[0, 2.18, 222.7]]}, {"timestamp": 1578730838967, "ltp": 2.16, "tv": 14442.89, "trd": NaN, "batb": [[0, 2.16, 37.62]], "batl": NaN}, {"timestamp": 1578730854867, "ltp": 2.16, "tv": 14442.89, "trd": NaN, "batb": [[1, 2.14, 107.09]], "batl": NaN}, {"timestamp": 1578730879999, "ltp": 2.16, "tv": 14442.89, "trd": NaN, "batb": [[0, 2.16, 102.39]], "batl": NaN}, {"timestamp": 1578730881903, "ltp": 2.16, "tv": 14442.89, "trd": NaN, "batb": [[1, 2.14, 110.41]], "batl": NaN}, {"timestamp": 1578730914828, "ltp": 2.16, "tv": 14446.89, "trd": [[2.16, 1450.92]], "batb": [[0, 2.16, 100.39]], "batl": NaN}, {"timestamp": 1578730929888, "ltp": 2.18, "tv": 14456.99, "trd": [[2.18, 761.56]], "batb": NaN, "batl": [[0, 2.18, 217.65]]}, {"timestamp": 1578730933900, "ltp": 2.18, "tv": 14456.99, "trd": NaN, "batb": [[0, 2.16, 130.38]], "batl": NaN}, {"timestamp": 1578730965958, "ltp": 2.18, "tv": 14456.99, "trd": NaN, "batb": NaN, "batl": [[2, 2.22, 178.33]]}, {"timestamp": 1578730967916, "ltp": 2.18, "tv": 14456.99, "trd": NaN, "batb": NaN, "batl": [[0, 2.18, 210.95]]}, {"timestamp": 1578730988980, "ltp": 2.18, "tv": 14456.99, "trd": NaN, "batb": [[0, 2.16, 145.22]], "batl": NaN}, {"timestamp": 1578731020928, "ltp": 2.18, "tv": 14456.99, "trd": NaN, "batb": NaN, "batl": [[2, 2.22, 38.5]]}, {"timestamp": 1578731035968, "ltp": 2.18, "tv": 14456.99, "trd": NaN, "batb": NaN, "batl": [[2, 2.22, 178.33]]}, {"timestamp": 1578731043750, "ltp": 2.18, "tv": 14456.99, "trd": NaN, "batb": [[0, 2.16, 152.13]], "batl": NaN}, {"timestamp": 1578731047975, "ltp": 2.18, "tv": 14456.99, "trd": NaN, "batb": NaN, "batl": [[0, 2.18, 240.95]]}, {"timestamp": 1578731079715, "ltp": 2.18, "tv": 14456.99, "trd": NaN, "batb": NaN, "batl": [[0, 2.18, 249.95]]}, {"timestamp": 1578731098967, "ltp": 2.18, "tv": 14456.99, "trd": NaN, "batb": [[0, 2.16, 156.45]], "batl": NaN}, {"timestamp": 1578731126750, "ltp": 2.18, "tv": 14456.99, "trd": NaN, "batb": NaN, "batl": [[2, 2.22, 38.5]]}, {"timestamp": 1578731132878, "ltp": 2.18, "tv": 14456.99, "trd": NaN, "batb": NaN, "batl": [[0, 2.18, 240.95]]}, {"timestamp": 1578731141908, "ltp": 2.18, "tv": 14456.99, "trd": NaN, "batb": NaN, "batl": [[2, 2.22, 178.33]]}, {"timestamp": 1578731153993, "ltp": 2.18, "tv": 14456.99, "trd": NaN, "batb": [[0, 2.16, 158.45]], "batl": NaN}, {"timestamp": 1578731180933, "ltp": 2.16, "tv": 14757.0, "trd": [[2.16, 1750.93]], "batb": [[0, 2.16, 8.44]], "batl": NaN}, {"timestamp": 1578731187959, "ltp": 2.16, "tv": 14757.0, "trd": NaN, "batb": NaN, "batl": [[0, 2.18, 247.95]]}, {"timestamp": 1578731198983, "ltp": 2.16, "tv": 14757.0, "trd": NaN, "batb": [[1, 2.14, 107.09], [2, 2.12, 176.9]], "batl": NaN}, {"timestamp": 1578731202594, "ltp": 2.16, "tv": 14757.0, "trd": NaN, "batb": NaN, "batl": [[2, 2.22, 38.5]]}, {"timestamp": 1578731208803, "ltp": 2.16, "tv": 14757.0, "trd": NaN, "batb": [[0, 2.16, 10.73]], "batl": NaN}, {"timestamp": 1578731217921, "ltp": 2.16, "tv": 14757.0, "trd": NaN, "batb": NaN, "batl": [[2, 2.22, 178.33]]}, {"timestamp": 1578731225953, "ltp": 2.14, "tv": 14837.0, "trd": [[2.14, 2175.94], [2.16, 1772.39]], "batb": [[0, 2.14, 77.82], [1, 2.12, 182.14], [2, 2.1, 346.92]], "batl": [[0, 2.16, 19.12], [1, 2.18, 247.95], [2, 2.2, 4301.42]]}, {"timestamp": 1578731226939, "ltp": 2.14, "tv": 14837.0, "trd": NaN, "batb": [[0, 2.14, 59.66]], "batl": [[0, 2.16, 67.82]]}, {"timestamp": 1578731227924, "ltp": 2.14, "tv": 14837.0, "trd": NaN, "batb": [[0, 2.14, 119.66], [1, 2.12, 191.61], [2, 2.1, 299.92]], "batl": NaN}, {"timestamp": 1578731228960, "ltp": 2.14, "tv": 14837.0, "trd": NaN, "batb": [[0, 2.14, 159.52]], "batl": [[0, 2.16, 44.19]]}, {"timestamp": 1578731229943, "ltp": 2.14, "tv": 14837.0, "trd": NaN, "batb": NaN, "batl": [[0, 2.16, 19]]}, {"timestamp": 1578731230862, "ltp": 2.14, "tv": 14837.0, "trd": NaN, "batb": [[0, 2.14, 282.78]], "batl": [[0, 2.18, 247.95], [1, 2.2, 4301.42], [2, 2.22, 22.5]]}, {"timestamp": 1578731237940, "ltp": 2.14, "tv": 14837.0, "trd": NaN, "batb": NaN, "batl": [[0, 2.18, 240.95], [2, 2.22, 162.33]]}, {"timestamp": 1578731238664, "ltp": 2.14, "tv": 14837.0, "trd": NaN, "batb": NaN, "batl": [[0, 2.16, 18.21], [1, 2.18, 240.95], [2, 2.2, 4301.42]]}, {"timestamp": 1578731241568, "ltp": 2.14, "tv": 14897.0, "trd": [[2.14, 2235.95]], "batb": [[0, 2.14, 252.77]], "batl": NaN}, {"timestamp": 1578731246969, "ltp": 2.14, "tv": 14897.0, "trd": NaN, "batb": [[0, 2.14, 129.52]], "batl": NaN}, {"timestamp": 1578731248978, "ltp": 2.14, "tv": 14897.0, "trd": NaN, "batb": NaN, "batl": [[0, 2.18, 240.95], [1, 2.2, 4301.42], [2, 2.22, 22.5]]}, {"timestamp": 1578731255775, "ltp": 2.14, "tv": 14897.0, "trd": NaN, "batb": NaN, "batl": [[0, 2.16, 124], [1, 2.18, 240.95], [2, 2.2, 4301.42]]}, {"timestamp": 1578731259998, "ltp": 2.14, "tv": 14897.0, "trd": NaN, "batb": [[0, 2.14, 189.98]], "batl": NaN}, {"timestamp": 1578731260981, "ltp": 2.14, "tv": 14897.0, "trd": NaN, "batb": [[0, 2.14, 129.98], [2, 2.1, 362.92]], "batl": NaN}, {"timestamp": 1578731265806, "ltp": 2.14, "tv": 14897.0, "trd": NaN, "batb": NaN, "batl": [[0, 2.16, 138], [1, 2.18, 226.95]]}, {"timestamp": 1578731288927, "ltp": 2.14, "tv": 14897.0, "trd": NaN, "batb": NaN, "batl": [[1, 2.18, 233.55]]}, {"timestamp": 1578731308968, "ltp": 2.16, "tv": 14906.82, "trd": [[2.16, 1782.21]], "batb": NaN, "batl": [[0, 2.16, 133.09]]}, {"timestamp": 1578731319979, "ltp": 2.16, "tv": 14906.82, "trd": NaN, "batb": [[0, 2.14, 132.25]], "batl": NaN}, {"timestamp": 1578731373974, "ltp": 2.16, "tv": 14906.82, "trd": NaN, "batb": [[0, 2.14, 142.11]], "batl": NaN}, {"timestamp": 1578731409001, "ltp": 2.14, "tv": 14916.92, "trd": [[2.14, 2246.05]], "batb": [[0, 2.14, 137.06]], "batl": NaN}, {"timestamp": 1578731412913, "ltp": 2.16, "tv": 14925.34, "trd": [[2.16, 1790.63]], "batb": NaN, "batl": [[0, 2.16, 128.88]]}, {"timestamp": 1578731428980, "ltp": 2.16, "tv": 14925.34, "trd": NaN, "batb": [[0, 2.14, 143.53]], "batl": NaN}, {"timestamp": 1578731484952, "ltp": 2.16, "tv": 14925.34, "trd": NaN, "batb": [[0, 2.14, 146.55]], "batl": NaN}, {"timestamp": 1578731495368, "ltp": 2.14, "tv": 14933.85, "trd": [[2.14, 2254.56]], "batb": [[0, 2.14, 142.3]], "batl": NaN}, {"timestamp": 1578731526948, "ltp": 2.14, "tv": 14941.19, "trd": [[2.14, 2261.9]], "batb": [[0, 2.14, 138.63]], "batl": NaN}, {"timestamp": 1578731527740, "ltp": 2.14, "tv": 14941.19, "trd": NaN, "batb": NaN, "batl": [[0, 2.16, 145.16]]}, {"timestamp": 1578731594916, "ltp": 2.14, "tv": 14941.19, "trd": NaN, "batb": [[0, 2.14, 141.98]], "batl": NaN}, {"timestamp": 1578731616980, "ltp": 2.14, "tv": 15225.14, "trd": [[2.14, 2545.84]], "batb": [[0, 2.12, 191.61], [1, 2.1, 362.92], [2, 2.08, 70.21]], "batl": [[0, 2.14, 58.03], [1, 2.16, 145.16], [2, 2.18, 233.55]]}, {"timestamp": 1578731617959, "ltp": 2.14, "tv": 15250.06, "trd": [[2.14, 2570.76]], "batb": [[2, 2.08, 6]], "batl": [[0, 2.14, 63.98]]}, {"timestamp": 1578731618990, "ltp": 2.14, "tv": 15250.06, "trd": NaN, "batb": [[0, 2.12, 176.9]], "batl": NaN}, {"timestamp": 1578731622959, "ltp": 2.14, "tv": 15250.06, "trd": NaN, "batb": [[1, 2.1, 377.66]], "batl": NaN}, {"timestamp": 1578731626878, "ltp": 2.14, "tv": 15250.06, "trd": NaN, "batb": NaN, "batl": [[0, 2.14, 77.98], [1, 2.16, 131.16]]}, {"timestamp": 1578731635978, "ltp": 2.14, "tv": 15250.06, "trd": NaN, "batb": NaN, "batl": [[0, 2.14, 127.98]]}, {"timestamp": 1578731649939, "ltp": 2.14, "tv": 15270.06, "trd": [[2.14, 2590.76]], "batb": NaN, "batl": [[0, 2.14, 117.98]]}, {"timestamp": 1578731657854, "ltp": 2.14, "tv": 15270.06, "trd": NaN, "batb": [[0, 2.12, 123.9], [2, 2.08, 62.14]], "batl": [[0, 2.14, 133.98]]}, {"timestamp": 1578731687997, "ltp": 2.14, "tv": 15270.06, "trd": NaN, "batb": [[0, 2.12, 173.9], [2, 2.08, 6]], "batl": NaN}, {"timestamp": 1578731715749, "ltp": 2.14, "tv": 15270.06, "trd": NaN, "batb": [[1, 2.1, 360.66]], "batl": [[1, 2.16, 124.16], [2, 2.18, 228.55]]}, {"timestamp": 1578731726871, "ltp": 2.12, "tv": 15470.06, "trd": [[2.12, 1770.94]], "batb": [[0, 2.12, 73.9]], "batl": NaN}, {"timestamp": 1578731733948, "ltp": 2.14, "tv": 15524.06, "trd": [[2.14, 2644.76]], "batb": [[0, 2.12, 23.9], [2, 2.08, 50.22]], "batl": [[0, 2.14, 90.98], [1, 2.16, 112.16], [2, 2.18, 216.55]]}, {"timestamp": 1578731734967, "ltp": 2.14, "tv": 15524.06, "trd": NaN, "batb": NaN, "batl": [[0, 2.14, 102.47]]}, {"timestamp": 1578731758986, "ltp": 2.14, "tv": 15524.06, "trd": NaN, "batb": NaN, "batl": [[1, 2.16, 120.16], [2, 2.18, 209.95]]}, {"timestamp": 1578731759914, "ltp": 2.14, "tv": 15524.06, "trd": NaN, "batb": [[0, 2.12, 65.12], [2, 2.08, 6]], "batl": NaN}, {"timestamp": 1578731774649, "ltp": 2.14, "tv": 15524.06, "trd": NaN, "batb": [[2, 2.08, 46.22]], "batl": NaN}, {"timestamp": 1578731813856, "ltp": 2.14, "tv": 15524.06, "trd": NaN, "batb": [[0, 2.12, 23.9]], "batl": NaN}, {"timestamp": 1578731814944, "ltp": 2.14, "tv": 15524.06, "trd": NaN, "batb": [[0, 2.12, 29.3]], "batl": NaN}, {"timestamp": 1578731817971, "ltp": 2.14, "tv": 15534.06, "trd": [[2.14, 2654.76]], "batb": NaN, "batl": [[0, 2.14, 97.47]]}, {"timestamp": 1578731822545, "ltp": 2.14, "tv": 15534.06, "trd": NaN, "batb": [[0, 2.12, 65.3]], "batl": NaN}, {"timestamp": 1578731869924, "ltp": 2.14, "tv": 15534.06, "trd": NaN, "batb": [[0, 2.12, 67.84]], "batl": NaN}, {"timestamp": 1578731896270, "ltp": 2.14, "tv": 15563.06, "trd": [[2.14, 2683.76]], "batb": NaN, "batl": [[0, 2.14, 82.97]]}, {"timestamp": 1578731897769, "ltp": 2.14, "tv": 15563.06, "trd": NaN, "batb": NaN, "batl": [[0, 2.14, 93.63]]}, {"timestamp": 1578731916993, "ltp": 2.14, "tv": 15563.06, "trd": NaN, "batb": [[0, 2.12, 31.84]], "batl": NaN}, {"timestamp": 1578731935932, "ltp": 2.14, "tv": 15563.06, "trd": NaN, "batb": [[0, 2.12, 67.84]], "batl": NaN}, {"timestamp": 1578731975691, "ltp": 2.14, "tv": 15595.4, "trd": [[2.14, 2716.11]], "batb": NaN, "batl": [[0, 2.14, 77.46]]}, {"timestamp": 1578731976997, "ltp": 2.14, "tv": 15595.4, "trd": NaN, "batb": [[0, 2.12, 82.53]], "batl": NaN}, {"timestamp": 1578731986599, "ltp": 2.14, "tv": 15629.68, "trd": [[2.14, 2750.39]], "batb": NaN, "batl": [[0, 2.14, 60.32]]}, {"timestamp": 1578732000702, "ltp": 2.14, "tv": 15629.68, "trd": NaN, "batb": NaN, "batl": [[0, 2.14, 90.32]]}, {"timestamp": 1578732005943, "ltp": 2.14, "tv": 15669.3, "trd": [[2.14, 2790.01]], "batb": NaN, "batl": [[0, 2.14, 70.51]]}, {"timestamp": 1578732013947, "ltp": 2.14, "tv": 15669.3, "trd": NaN, "batb": NaN, "batl": [[2, 2.18, 217.8]]}, {"timestamp": 1578732022971, "ltp": 2.12, "tv": 15674.58, "trd": [[2.12, 1776.22]], "batb": [[0, 2.12, 79.89]], "batl": NaN}, {"timestamp": 1578732048884, "ltp": 2.12, "tv": 15674.58, "trd": NaN, "batb": NaN, "batl": [[2, 2.18, 67.8]]}, {"timestamp": 1578732082922, "ltp": 2.14, "tv": 15724.58, "trd": [[2.14, 2840.01]], "batb": NaN, "batl": [[0, 2.14, 45.51]]}, {"timestamp": 1578732084746, "ltp": 2.14, "tv": 15734.58, "trd": [[2.14, 2850.01]], "batb": NaN, "batl": [[0, 2.14, 40.5]]}, {"timestamp": 1578732085949, "ltp": 2.14, "tv": 15742.58, "trd": [[2.14, 2858.01]], "batb": NaN, "batl": [[0, 2.14, 36.5]]}, {"timestamp": 1578732087777, "ltp": 2.14, "tv": 15746.58, "trd": [[2.14, 2862.01]], "batb": NaN, "batl": [[0, 2.14, 34.5]]}, {"timestamp": 1578732088769, "ltp": 2.14, "tv": 15746.58, "trd": NaN, "batb": [[0, 2.12, 100.09]], "batl": NaN}, {"timestamp": 1578732089970, "ltp": 2.14, "tv": 15746.58, "trd": NaN, "batb": NaN, "batl": [[0, 2.14, 30]]}, {"timestamp": 1578732116979, "ltp": 2.16, "tv": 15845.5, "trd": [[2.14, 2922.01], [2.16, 1829.55]], "batb": [[0, 2.14, 8.15], [1, 2.12, 64.09], [2, 2.1, 360.66]], "batl": [[0, 2.16, 100.7], [1, 2.18, 67.8], [2, 2.2, 4292.07]]}, {"timestamp": 1578732117913, "ltp": 2.16, "tv": 15845.5, "trd": NaN, "batb": [[1, 2.12, 77.83]], "batl": NaN}, {"timestamp": 1578732118904, "ltp": 2.16, "tv": 15845.5, "trd": NaN, "batb": [[1, 2.12, 111.83], [2, 2.1, 345.92]], "batl": NaN}, {"timestamp": 1578732125741, "ltp": 2.16, "tv": 15845.5, "trd": NaN, "batb": NaN, "batl": [[0, 2.16, 222.81], [1, 2.18, 80.1]]}, {"timestamp": 1578732141930, "ltp": 2.16, "tv": 15845.5, "trd": NaN, "batb": NaN, "batl": [[0, 2.16, 251.81]]}, {"timestamp": 1578732144846, "ltp": 2.16, "tv": 15845.5, "trd": NaN, "batb": [[1, 2.12, 121.36]], "batl": NaN}, {"timestamp": 1578732153935, "ltp": 2.16, "tv": 15853.98, "trd": [[2.16, 1838.03]], "batb": NaN, "batl": [[0, 2.16, 247.57]]}, {"timestamp": 1578732159968, "ltp": 2.16, "tv": 15853.98, "trd": NaN, "batb": [[1, 2.12, 133.36]], "batl": [[0, 2.16, 259.57], [1, 2.18, 492.1], [2, 2.2, 4304.07]]}, {"timestamp": 1578732160965, "ltp": 2.16, "tv": 15853.98, "trd": NaN, "batb": NaN, "batl": [[1, 2.18, 484.25]]}, {"timestamp": 1578732191918, "ltp": 2.16, "tv": 15862.24, "trd": [[2.16, 1846.29]], "batb": NaN, "batl": [[0, 2.16, 255.44]]}, {"timestamp": 1578732199981, "ltp": 2.16, "tv": 15862.24, "trd": NaN, "batb": [[1, 2.12, 95.69]], "batl": NaN}, {"timestamp": 1578732253932, "ltp": 2.16, "tv": 15862.24, "trd": NaN, "batb": [[0, 2.14, 34.48]], "batl": NaN}, {"timestamp": 1578732255956, "ltp": 2.16, "tv": 15862.24, "trd": NaN, "batb": [[1, 2.12, 107.66]], "batl": NaN}, {"timestamp": 1578732308999, "ltp": 2.16, "tv": 15862.24, "trd": NaN, "batb": [[0, 2.14, 46.79]], "batl": NaN}, {"timestamp": 1578732310906, "ltp": 2.16, "tv": 15862.24, "trd": NaN, "batb": [[1, 2.12, 110.4]], "batl": NaN}, {"timestamp": 1578732332978, "ltp": 2.14, "tv": 15892.25, "trd": [[2.14, 2952.02]], "batb": [[0, 2.14, 31.79]], "batl": NaN}, {"timestamp": 1578732339983, "ltp": 2.14, "tv": 15892.25, "trd": NaN, "batb": NaN, "batl": [[0, 2.16, 259.97]]}, {"timestamp": 1578732340972, "ltp": 2.14, "tv": 15892.25, "trd": NaN, "batb": [[1, 2.12, 95.69]], "batl": NaN}, {"timestamp": 1578732341864, "ltp": 2.14, "tv": 15892.25, "trd": NaN, "batb": [[1, 2.12, 106.75]], "batl": NaN}, {"timestamp": 1578732347964, "ltp": 2.14, "tv": 15892.25, "trd": NaN, "batb": NaN, "batl": [[0, 2.16, 137.86]]}, {"timestamp": 1578732363912, "ltp": 2.16, "tv": 15902.43, "trd": [[2.16, 1856.47]], "batb": NaN, "batl": [[0, 2.16, 132.77]]}, {"timestamp": 1578732365001, "ltp": 2.16, "tv": 15902.43, "trd": NaN, "batb": [[0, 2.14, 76.24]], "batl": NaN}, {"timestamp": 1578732366974, "ltp": 2.16, "tv": 15902.43, "trd": NaN, "batb": [[1, 2.12, 110.4]], "batl": NaN}, {"timestamp": 1578732377917, "ltp": 2.16, "tv": 15952.43, "trd": [[2.16, 1906.47]], "batb": NaN, "batl": [[0, 2.16, 107.77]]}, {"timestamp": 1578732379987, "ltp": 2.16, "tv": 15952.43, "trd": NaN, "batb": NaN, "batl": [[0, 2.16, 229.88]]}, {"timestamp": 1578732418978, "ltp": 2.16, "tv": 15952.43, "trd": NaN, "batb": [[1, 2.12, 131.29]], "batl": NaN}, {"timestamp": 1578732459923, "ltp": 2.16, "tv": 15952.43, "trd": NaN, "batb": NaN, "batl": [[0, 2.16, 107.77]]}, {"timestamp": 1578732474943, "ltp": 2.16, "tv": 15952.43, "trd": NaN, "batb": [[0, 2.12, 64.4], [1, 2.1, 345.92], [2, 2.08, 59]], "batl": [[0, 2.14, 16.14], [1, 2.16, 107.77], [2, 2.18, 484.25]]}, {"timestamp": 1578732475923, "ltp": 2.16, "tv": 15952.43, "trd": NaN, "batb": [[0, 2.12, 105.69], [2, 2.08, 6]], "batl": [[0, 2.14, 13.5], [1, 2.16, 103.24]]}, {"timestamp": 1578732478934, "ltp": 2.16, "tv": 15952.43, "trd": NaN, "batb": NaN, "batl": [[0, 2.14, 4.52]]}, {"timestamp": 1578732488952, "ltp": 2.16, "tv": 15952.43, "trd": NaN, "batb": NaN, "batl": [[0, 2.14, 33.52], [1, 2.16, 74.24]]}, {"timestamp": 1578732501771, "ltp": 2.16, "tv": 15952.43, "trd": NaN, "batb": NaN, "batl": [[0, 2.14, 49.52], [1, 2.16, 66.24]]}, {"timestamp": 1578732528911, "ltp": 2.16, "tv": 15952.43, "trd": NaN, "batb": [[0, 2.12, 169.17]], "batl": NaN}, {"timestamp": 1578732544815, "ltp": 2.14, "tv": 15962.71, "trd": [[2.14, 2962.3]], "batb": NaN, "batl": [[0, 2.14, 44.38]]}, {"timestamp": 1578732575902, "ltp": 2.14, "tv": 15962.71, "trd": NaN, "batb": NaN, "batl": [[0, 2.14, 28.38]]}, {"timestamp": 1578732576990, "ltp": 2.14, "tv": 15962.71, "trd": NaN, "batb": NaN, "batl": [[0, 2.14, 40.38], [1, 2.16, 116.24]]}, {"timestamp": 1578732577610, "ltp": 2.14, "tv": 15962.71, "trd": NaN, "batb": NaN, "batl": [[0, 2.14, 28.38]]}, {"timestamp": 1578732580912, "ltp": 2.14, "tv": 15962.71, "trd": NaN, "batb": NaN, "batl": [[0, 2.14, 40.38]]}, {"timestamp": 1578732583904, "ltp": 2.14, "tv": 15962.71, "trd": NaN, "batb": [[0, 2.12, 204.87]], "batl": NaN}, {"timestamp": 1578732600935, "ltp": 2.14, "tv": 15962.71, "trd": NaN, "batb": [[0, 2.12, 190.87]], "batl": [[0, 2.14, 28.38]]}, {"timestamp": 1578732605838, "ltp": 2.14, "tv": 15962.71, "trd": NaN, "batb": NaN, "batl": [[0, 2.14, 39.38]]}, {"timestamp": 1578732606922, "ltp": 2.14, "tv": 15962.71, "trd": NaN, "batb": NaN, "batl": [[0, 2.14, 28.38]]}, {"timestamp": 1578732609949, "ltp": 2.14, "tv": 15989.95, "trd": [[2.14, 2989.54]], "batb": NaN, "batl": [[0, 2.14, 14.76]]}, {"timestamp": 1578732618935, "ltp": 2.14, "tv": 15989.95, "trd": NaN, "batb": [[0, 2.12, 315.28]], "batl": NaN}, {"timestamp": 1578732623863, "ltp": 2.14, "tv": 16019.47, "trd": [[2.14, 3019.06]], "batb": [[0, 2.14, 185.24], [1, 2.12, 315.28], [2, 2.1, 345.92]], "batl": [[0, 2.16, 116.24], [1, 2.18, 484.25], [2, 2.2, 4284.42]]}, {"timestamp": 1578732624956, "ltp": 2.14, "tv": 16019.47, "trd": NaN, "batb": [[1, 2.12, 300.59]], "batl": [[2, 2.2, 4294.42]]}, {"timestamp": 1578732625730, "ltp": 2.14, "tv": 16019.47, "trd": NaN, "batb": [[1, 2.12, 315.3]], "batl": [[0, 2.16, 66.24]]}, {"timestamp": 1578732634887, "ltp": 2.14, "tv": 16019.47, "trd": NaN, "batb": [[1, 2.12, 190.89]], "batl": NaN}, {"timestamp": 1578732639864, "ltp": 2.14, "tv": 16019.47, "trd": NaN, "batb": [[1, 2.12, 91.71]], "batl": NaN}, {"timestamp": 1578732645879, "ltp": 2.14, "tv": 16019.47, "trd": NaN, "batb": NaN, "batl": [[0, 2.16, 91.24]]}, {"timestamp": 1578732648003, "ltp": 2.14, "tv": 16019.47, "trd": NaN, "batb": NaN, "batl": [[2, 2.2, 4298.42]]}, {"timestamp": 1578732657000, "ltp": 2.14, "tv": 16019.47, "trd": NaN, "batb": NaN, "batl": [[1, 2.18, 495.08]]}, {"timestamp": 1578732661893, "ltp": 2.14, "tv": 16019.47, "trd": NaN, "batb": NaN, "batl": [[1, 2.18, 507.08]]}, {"timestamp": 1578732678904, "ltp": 2.14, "tv": 16019.47, "trd": NaN, "batb": NaN, "batl": [[0, 2.16, 79.24]]}, {"timestamp": 1578732682908, "ltp": 2.14, "tv": 16019.47, "trd": NaN, "batb": [[0, 2.14, 308.49]], "batl": NaN}, {"timestamp": 1578732689954, "ltp": 2.14, "tv": 16039.47, "trd": [[2.14, 3039.06]], "batb": [[0, 2.14, 298.49]], "batl": [[0, 2.16, 94.24]]}, {"timestamp": 1578732693949, "ltp": 2.14, "tv": 16039.47, "trd": NaN, "batb": [[0, 2.14, 369.22]], "batl": NaN}, {"timestamp": 1578732707954, "ltp": 2.14, "tv": 16039.47, "trd": NaN, "batb": NaN, "batl": [[1, 2.18, 496.25]]}, {"timestamp": 1578732748914, "ltp": 2.14, "tv": 16039.47, "trd": NaN, "batb": [[0, 2.14, 402.27]], "batl": NaN}, {"timestamp": 1578732761906, "ltp": 2.14, "tv": 16039.47, "trd": NaN, "batb": [[1, 2.12, 109.71]], "batl": [[1, 2.18, 502.25]]}, {"timestamp": 1578732769902, "ltp": 2.14, "tv": 16039.47, "trd": NaN, "batb": [[2, 2.1, 360.92]], "batl": NaN}, {"timestamp": 1578732777806, "ltp": 2.16, "tv": 16251.65, "trd": [[2.16, 2118.65]], "batb": [[0, 2.14, 279.02]], "batl": [[0, 2.16, 11.91]]}, {"timestamp": 1578732778936, "ltp": 2.16, "tv": 16274.42, "trd": [[2.16, 2141.42]], "batb": [[1, 2.12, 95.97]], "batl": [[0, 2.18, 502.25], [1, 2.2, 4298.42], [2, 2.22, 142.33]]}, {"timestamp": 1578732781824, "ltp": 2.16, "tv": 16274.42, "trd": NaN, "batb": NaN, "batl": [[0, 2.16, 18.04], [1, 2.18, 502.25], [2, 2.2, 4298.42]]}, {"timestamp": 1578732786723, "ltp": 2.16, "tv": 16274.42, "trd": NaN, "batb": NaN, "batl": [[0, 2.16, 39.04]]}, {"timestamp": 1578732804442, "ltp": 2.16, "tv": 16274.42, "trd": NaN, "batb": [[0, 2.14, 300.04]], "batl": NaN}, {"timestamp": 1578732816967, "ltp": 2.16, "tv": 16274.42, "trd": NaN, "batb": NaN, "batl": [[0, 2.16, 21]]}, {"timestamp": 1578732829965, "ltp": 2.16, "tv": 16274.42, "trd": NaN, "batb": NaN, "batl": [[0, 2.16, 39]]}, {"timestamp": 1578732839979, "ltp": 2.16, "tv": 16278.42, "trd": [[2.16, 2145.42]], "batb": NaN, "batl": [[0, 2.16, 37]]}, {"timestamp": 1578732840907, "ltp": 2.16, "tv": 16278.42, "trd": NaN, "batb": [[0, 2.14, 361.04], [2, 2.1, 299.92]], "batl": [[0, 2.16, 36]]}, {"timestamp": 1578732841892, "ltp": 2.16, "tv": 16278.42, "trd": NaN, "batb": [[0, 2.14, 484.29]], "batl": NaN}, {"timestamp": 1578732854824, "ltp": 2.16, "tv": 16278.42, "trd": NaN, "batb": [[0, 2.14, 423.29], [2, 2.1, 361.92]], "batl": [[0, 2.16, 19]]}, {"timestamp": 1578732858921, "ltp": 2.16, "tv": 16278.42, "trd": NaN, "batb": [[0, 2.14, 438.87]], "batl": NaN}, {"timestamp": 1578732869733, "ltp": 2.16, "tv": 16290.56, "trd": [[2.16, 2157.56]], "batb": NaN, "batl": [[0, 2.16, 12.93]]}, {"timestamp": 1578732876959, "ltp": 2.16, "tv": 16290.56, "trd": NaN, "batb": NaN, "batl": [[0, 2.16, 30.05]]}, {"timestamp": 1578732878935, "ltp": 2.16, "tv": 16290.56, "trd": NaN, "batb": NaN, "batl": [[0, 2.16, 12.93]]}, {"timestamp": 1578732881960, "ltp": 2.16, "tv": 16316.42, "trd": [[2.16, 2183.42]], "batb": [[0, 2.16, 87.07], [1, 2.14, 499.87], [2, 2.12, 95.97]], "batl": [[0, 2.18, 502.25], [1, 2.2, 4298.42], [2, 2.22, 158.33]]}, {"timestamp": 1578732886945, "ltp": 2.16, "tv": 16316.42, "trd": NaN, "batb": NaN, "batl": [[2, 2.22, 165.79]]}, {"timestamp": 1578732889949, "ltp": 2.16, "tv": 16316.42, "trd": NaN, "batb": [[1, 2.14, 376.62]], "batl": NaN}, {"timestamp": 1578732890985, "ltp": 2.16, "tv": 16316.42, "trd": NaN, "batb": NaN, "batl": [[0, 2.18, 526.25]]}, {"timestamp": 1578732899947, "ltp": 2.16, "tv": 16316.42, "trd": NaN, "batb": NaN, "batl": [[0, 2.18, 508.25], [1, 2.2, 4284.42], [2, 2.22, 142.33]]}, {"timestamp": 1578732900987, "ltp": 2.16, "tv": 16316.42, "trd": NaN, "batb": NaN, "batl": [[2, 2.22, 149.79]]}, {"timestamp": 1578732901983, "ltp": 2.16, "tv": 16316.42, "trd": NaN, "batb": NaN, "batl": [[0, 2.18, 524.25], [1, 2.2, 4300.42], [2, 2.22, 158.33]]}, {"timestamp": 1578732905989, "ltp": 2.16, "tv": 16316.42, "trd": NaN, "batb": NaN, "batl": [[2, 2.22, 165.79]]}, {"timestamp": 1578732911964, "ltp": 2.16, "tv": 16316.42, "trd": NaN, "batb": NaN, "batl": [[0, 2.18, 529.25]]}, {"timestamp": 1578732913988, "ltp": 2.16, "tv": 16316.42, "trd": NaN, "batb": [[1, 2.14, 236.24]], "batl": [[2, 2.22, 158.33]]}, {"timestamp": 1578732924002, "ltp": 2.16, "tv": 16476.42, "trd": [[2.16, 2343.42]], "batb": [[0, 2.16, 7.07]], "batl": [[2, 2.22, 165.79]]}, {"timestamp": 1578732924996, "ltp": 2.18, "tv": 16476.59, "trd": [[2.18, 761.73]], "batb": NaN, "batl": [[0, 2.18, 529.16]]}, {"timestamp": 1578732925917, "ltp": 2.18, "tv": 16476.59, "trd": NaN, "batb": [[2, 2.12, 81.26]], "batl": NaN}, {"timestamp": 1578732929907, "ltp": 2.18, "tv": 16476.59, "trd": NaN, "batb": NaN, "batl": [[2, 2.22, 158.33]]}, {"timestamp": 1578732931915, "ltp": 2.18, "tv": 16480.39, "trd": [[2.18, 765.53]], "batb": NaN, "batl": [[0, 2.18, 527.26]]}, {"timestamp": 1578732932906, "ltp": 2.16, "tv": 16494.53, "trd": [[2.16, 2357.56]], "batb": [[0, 2.14, 236.24], [1, 2.12, 81.26], [2, 2.1, 361.92]], "batl": [[0, 2.16, 78.93], [1, 2.18, 527.26], [2, 2.2, 4300.42]]}, {"timestamp": 1578732933993, "ltp": 2.16, "tv": 16494.53, "trd": NaN, "batb": [[0, 2.14, 237.29], [1, 2.12, 96.56]], "batl": NaN}, {"timestamp": 1578732936934, "ltp": 2.16, "tv": 16494.53, "trd": NaN, "batb": [[0, 2.14, 360.55]], "batl": NaN}, {"timestamp": 1578732938927, "ltp": 2.16, "tv": 16494.53, "trd": NaN, "batb": NaN, "batl": [[0, 2.16, 62.93], [1, 2.18, 511.26], [2, 2.2, 4284.42]]}, {"timestamp": 1578732956944, "ltp": 2.16, "tv": 16494.53, "trd": NaN, "batb": NaN, "batl": [[0, 2.16, 86.93], [1, 2.18, 487.26]]}, {"timestamp": 1578732964957, "ltp": 2.16, "tv": 16494.53, "trd": NaN, "batb": [[0, 2.14, 237.29]], "batl": NaN}, {"timestamp": 1578732968990, "ltp": 2.16, "tv": 16494.53, "trd": NaN, "batb": NaN, "batl": [[1, 2.18, 482.26]]}, {"timestamp": 1578732969964, "ltp": 2.16, "tv": 16494.53, "trd": NaN, "batb": [[0, 2.14, 321.27]], "batl": NaN}, {"timestamp": 1578732994916, "ltp": 2.16, "tv": 16494.53, "trd": NaN, "batb": NaN, "batl": [[0, 2.16, 186.93]]}, {"timestamp": 1578733023833, "ltp": 2.16, "tv": 16494.53, "trd": NaN, "batb": [[0, 2.14, 360.79]], "batl": NaN}, {"timestamp": 1578733079920, "ltp": 2.16, "tv": 16494.53, "trd": NaN, "batb": [[0, 2.14, 379.95]], "batl": NaN}, {"timestamp": 1578733134873, "ltp": 2.16, "tv": 16494.53, "trd": NaN, "batb": [[0, 2.14, 390.06]], "batl": NaN}, {"timestamp": 1578733148986, "ltp": 2.16, "tv": 16494.53, "trd": NaN, "batb": [[0, 2.14, 451.06], [2, 2.1, 299.92]], "batl": NaN}, {"timestamp": 1578733161902, "ltp": 2.16, "tv": 16578.67, "trd": [[2.16, 2441.7]], "batb": NaN, "batl": [[0, 2.16, 144.86]]}, {"timestamp": 1578733165004, "ltp": 2.14, "tv": 16618.67, "trd": [[2.14, 3079.06]], "batb": [[0, 2.14, 431.06]], "batl": NaN}, {"timestamp": 1578733167901, "ltp": 2.14, "tv": 16668.67, "trd": [[2.14, 3129.06]], "batb": [[0, 2.14, 406.06]], "batl": NaN}, {"timestamp": 1578733177001, "ltp": 2.14, "tv": 16668.67, "trd": NaN, "batb": [[0, 2.14, 455.27]], "batl": NaN}, {"timestamp": 1578733188892, "ltp": 2.14, "tv": 16668.67, "trd": NaN, "batb": [[0, 2.14, 460.04]], "batl": NaN}, {"timestamp": 1578733205942, "ltp": 2.14, "tv": 16670.67, "trd": [[2.14, 3131.06]], "batb": [[0, 2.14, 459.04]], "batl": NaN}, {"timestamp": 1578733206934, "ltp": 2.14, "tv": 16671.67, "trd": [[2.14, 3132.06]], "batb": [[0, 2.14, 458.54]], "batl": NaN}, {"timestamp": 1578733244808, "ltp": 2.14, "tv": 16671.67, "trd": NaN, "batb": [[0, 2.14, 523.02], [2, 2.1, 361.92]], "batl": NaN}, {"timestamp": 1578733260914, "ltp": 2.14, "tv": 16671.67, "trd": NaN, "batb": [[0, 2.14, 399.77]], "batl": NaN}, {"timestamp": 1578733283900, "ltp": 2.14, "tv": 16674.67, "trd": [[2.14, 3135.06]], "batb": [[0, 2.14, 398.27]], "batl": NaN}, {"timestamp": 1578733332995, "ltp": 2.14, "tv": 16674.67, "trd": NaN, "batb": NaN, "batl": [[0, 2.16, 294.86]]}, {"timestamp": 1578733342991, "ltp": 2.16, "tv": 16694.29, "trd": [[2.16, 2461.32]], "batb": NaN, "batl": [[0, 2.16, 285.05]]}, {"timestamp": 1578733363895, "ltp": 2.14, "tv": 16730.29, "trd": [[2.14, 3171.06]], "batb": [[0, 2.14, 380.27]], "batl": NaN}, {"timestamp": 1578733390926, "ltp": 2.16, "tv": 16790.01, "trd": [[2.16, 2521.04]], "batb": NaN, "batl": [[0, 2.16, 255.19]]}, {"timestamp": 1578733410937, "ltp": 2.16, "tv": 16790.01, "trd": NaN, "batb": NaN, "batl": [[1, 2.18, 487.16]]}, {"timestamp": 1578733421936, "ltp": 2.16, "tv": 16790.01, "trd": NaN, "batb": [[0, 2.14, 380.97]], "batl": NaN}, {"timestamp": 1578733441970, "ltp": 2.16, "tv": 16800.35, "trd": [[2.16, 2531.38]], "batb": NaN, "batl": [[0, 2.16, 250.02]]}, {"timestamp": 1578733455964, "ltp": 2.14, "tv": 16860.35, "trd": [[2.14, 3231.06]], "batb": [[0, 2.14, 350.97]], "batl": NaN}, {"timestamp": 1578733459903, "ltp": 2.14, "tv": 16860.35, "trd": NaN, "batb": NaN, "batl": [[1, 2.18, 457.16]]}, {"timestamp": 1578733461871, "ltp": 2.14, "tv": 16920.61, "trd": [[2.14, 3291.32]], "batb": [[0, 2.14, 320.84]], "batl": NaN}, {"timestamp": 1578733463957, "ltp": 2.14, "tv": 16920.61, "trd": NaN, "batb": [[0, 2.14, 323.14]], "batl": NaN}, {"timestamp": 1578733475001, "ltp": 2.16, "tv": 16930.57, "trd": [[2.16, 2541.34]], "batb": NaN, "batl": [[0, 2.16, 245.04]]}, {"timestamp": 1578733482002, "ltp": 2.16, "tv": 17338.57, "trd": [[2.16, 2949.34]], "batb": NaN, "batl": [[0, 2.16, 41.04]]}, {"timestamp": 1578733487992, "ltp": 2.16, "tv": 17338.57, "trd": NaN, "batb": NaN, "batl": [[0, 2.16, 70.04]]}, {"timestamp": 1578733507525, "ltp": 2.16, "tv": 17338.57, "trd": NaN, "batb": NaN, "batl": [[1, 2.18, 452.26]]}, {"timestamp": 1578733595950, "ltp": 2.16, "tv": 17338.57, "trd": NaN, "batb": [[2, 2.1, 461.92]], "batl": NaN}, {"timestamp": 1578733630989, "ltp": 2.16, "tv": 17338.57, "trd": NaN, "batb": [[0, 2.14, 493.14]], "batl": NaN}, {"timestamp": 1578733656989, "ltp": 2.14, "tv": 17378.57, "trd": [[2.14, 3331.32]], "batb": [[0, 2.14, 473.14]], "batl": NaN}, {"timestamp": 1578733718916, "ltp": 2.14, "tv": 17378.57, "trd": NaN, "batb": [[0, 2.14, 483.42]], "batl": NaN}, {"timestamp": 1578733723961, "ltp": 2.14, "tv": 17388.57, "trd": [[2.14, 3341.32]], "batb": [[0, 2.14, 478.42]], "batl": NaN}, {"timestamp": 1578733775998, "ltp": 2.14, "tv": 17398.57, "trd": [[2.14, 3351.32]], "batb": [[0, 2.14, 473.42]], "batl": NaN}, {"timestamp": 1578733789996, "ltp": 2.14, "tv": 17398.57, "trd": NaN, "batb": [[1, 2.12, 105.72]], "batl": NaN}, {"timestamp": 1578733834969, "ltp": 2.14, "tv": 17398.57, "trd": NaN, "batb": [[0, 2.14, 660.68], [2, 2.1, 399.92]], "batl": NaN}, {"timestamp": 1578733836883, "ltp": 2.14, "tv": 17398.57, "trd": NaN, "batb": [[0, 2.14, 596.68], [2, 2.1, 464.92]], "batl": NaN}, {"timestamp": 1578733850574, "ltp": 2.14, "tv": 17398.57, "trd": NaN, "batb": [[0, 2.14, 473.42]], "batl": NaN}, {"timestamp": 1578733902950, "ltp": 2.14, "tv": 17398.57, "trd": NaN, "batb": [[1, 2.12, 116.1]], "batl": NaN}, {"timestamp": 1578733928970, "ltp": 2.14, "tv": 17398.57, "trd": NaN, "batb": NaN, "batl": [[0, 2.16, 120.04]]}, {"timestamp": 1578733997881, "ltp": 2.16, "tv": 17408.75, "trd": [[2.16, 2959.52]], "batb": NaN, "batl": [[0, 2.16, 114.95]]}, {"timestamp": 1578734062923, "ltp": 2.16, "tv": 17408.75, "trd": NaN, "batb": [[2, 2.1, 364.92]], "batl": NaN}, {"timestamp": 1578734064952, "ltp": 2.16, "tv": 17408.75, "trd": NaN, "batb": [[0, 2.14, 474.13]], "batl": NaN}, {"timestamp": 1578734102997, "ltp": 2.16, "tv": 17467.75, "trd": [[2.16, 3018.52]], "batb": NaN, "batl": [[0, 2.16, 85.45]]}, {"timestamp": 1578734118903, "ltp": 2.16, "tv": 17467.75, "trd": NaN, "batb": [[2, 2.1, 373.67]], "batl": NaN}, {"timestamp": 1578734182985, "ltp": 2.14, "tv": 17767.75, "trd": [[2.14, 3651.32]], "batb": [[0, 2.14, 324.13]], "batl": NaN}, {"timestamp": 1578734202929, "ltp": 2.14, "tv": 17767.75, "trd": NaN, "batb": [[0, 2.14, 388.13]], "batl": NaN}, {"timestamp": 1578734203943, "ltp": 2.16, "tv": 17798.53, "trd": [[2.16, 3049.3]], "batb": [[2, 2.1, 308.67]], "batl": [[0, 2.16, 70.06]]}, {"timestamp": 1578734206933, "ltp": 2.16, "tv": 17798.53, "trd": NaN, "batb": [[0, 2.14, 459.72]], "batl": NaN}, {"timestamp": 1578734210745, "ltp": 2.16, "tv": 17808.87, "trd": [[2.16, 3059.64]], "batb": NaN, "batl": [[0, 2.16, 64.89]]}, {"timestamp": 1578734218344, "ltp": 2.16, "tv": 17808.87, "trd": NaN, "batb": [[0, 2.14, 582.98]], "batl": NaN}, {"timestamp": 1578734226840, "ltp": 2.14, "tv": 17812.28, "trd": [[2.14, 3654.72]], "batb": [[0, 2.14, 581.28]], "batl": NaN}, {"timestamp": 1578734239955, "ltp": 2.14, "tv": 17812.28, "trd": NaN, "batb": [[0, 2.14, 517.28], [2, 2.1, 373.67]], "batl": NaN}, {"timestamp": 1578734240845, "ltp": 2.14, "tv": 17812.28, "trd": NaN, "batb": [[2, 2.1, 364.92]], "batl": NaN}, {"timestamp": 1578734250954, "ltp": 2.14, "tv": 17812.28, "trd": NaN, "batb": [[0, 2.14, 394.02]], "batl": NaN}, {"timestamp": 1578734280936, "ltp": 2.14, "tv": 17812.28, "trd": NaN, "batb": [[1, 2.12, 95.03]], "batl": NaN}, {"timestamp": 1578734282568, "ltp": 2.14, "tv": 17812.28, "trd": NaN, "batb": [[1, 2.12, 106.35]], "batl": NaN}, {"timestamp": 1578734302592, "ltp": 2.14, "tv": 17822.28, "trd": [[2.14, 3664.72]], "batb": [[0, 2.14, 389.02]], "batl": NaN}, {"timestamp": 1578734314935, "ltp": 2.14, "tv": 17922.28, "trd": [[2.14, 3764.72]], "batb": [[0, 2.14, 339.02]], "batl": NaN}, {"timestamp": 1578734351943, "ltp": 2.14, "tv": 17922.28, "trd": NaN, "batb": [[0, 2.14, 539.02]], "batl": NaN}, {"timestamp": 1578734398937, "ltp": 2.14, "tv": 17922.28, "trd": NaN, "batb": [[0, 2.14, 547.8]], "batl": NaN}, {"timestamp": 1578734413959, "ltp": 2.16, "tv": 17930.16, "trd": [[2.16, 3067.52]], "batb": NaN, "batl": [[0, 2.16, 60.95]]}, {"timestamp": 1578734454904, "ltp": 2.16, "tv": 17930.16, "trd": NaN, "batb": [[0, 2.14, 551.9]], "batl": NaN}, {"timestamp": 1578734543930, "ltp": 2.16, "tv": 17972.68, "trd": [[2.16, 3110.04]], "batb": [[1, 2.12, 85.09]], "batl": [[0, 2.16, 39.69]]}, {"timestamp": 1578734550944, "ltp": 2.16, "tv": 17972.68, "trd": NaN, "batb": NaN, "batl": [[0, 2.16, 69.69]]}, {"timestamp": 1578734564286, "ltp": 2.16, "tv": 17972.68, "trd": NaN, "batb": [[0, 2.14, 568.87]], "batl": NaN}, {"timestamp": 1578734588831, "ltp": 2.14, "tv": 17982.68, "trd": [[2.14, 3774.72]], "batb": [[0, 2.14, 563.87]], "batl": NaN}, {"timestamp": 1578734598843, "ltp": 2.16, "tv": 18122.06, "trd": [[2.16, 3249.42]], "batb": [[0, 2.16, 30.31], [1, 2.14, 627.87], [2, 2.12, 85.09]], "batl": [[0, 2.18, 452.26], [1, 2.2, 4284.42], [2, 2.22, 2.5]]}, {"timestamp": 1578734610815, "ltp": 2.18, "tv": 18522.06, "trd": [[2.18, 1165.53]], "batb": NaN, "batl": [[0, 2.18, 252.26]]}, {"timestamp": 1578734612949, "ltp": 2.16, "tv": 18562.06, "trd": [[2.16, 3289.42]], "batb": [[0, 2.16, 10.31]], "batl": NaN}, {"timestamp": 1578734614927, "ltp": 2.16, "tv": 18562.06, "trd": NaN, "batb": [[2, 2.12, 73.77]], "batl": NaN}, {"timestamp": 1578734616962, "ltp": 2.16, "tv": 18562.06, "trd": NaN, "batb": NaN, "batl": [[0, 2.18, 258.26]]}, {"timestamp": 1578734619959, "ltp": 2.16, "tv": 18562.06, "trd": NaN, "batb": [[1, 2.14, 637.41]], "batl": NaN}, {"timestamp": 1578734628962, "ltp": 2.16, "tv": 18562.06, "trd": NaN, "batb": NaN, "batl": [[0, 2.18, 287.26]]}, {"timestamp": 1578734630937, "ltp": 2.16, "tv": 18562.06, "trd": NaN, "batb": [[0, 2.16, 110.31]], "batl": NaN}, {"timestamp": 1578734665000, "ltp": 2.16, "tv": 18562.06, "trd": NaN, "batb": NaN, "batl": [[0, 2.18, 281.26]]}, {"timestamp": 1578734673922, "ltp": 2.16, "tv": 18562.06, "trd": NaN, "batb": [[1, 2.14, 654.91]], "batl": NaN}, {"timestamp": 1578734714962, "ltp": 2.16, "tv": 18602.06, "trd": [[2.16, 3329.42]], "batb": [[0, 2.16, 90.31]], "batl": NaN}, {"timestamp": 1578734729877, "ltp": 2.16, "tv": 18602.06, "trd": NaN, "batb": [[1, 2.14, 663.08]], "batl": NaN}, {"timestamp": 1578734783937, "ltp": 2.16, "tv": 18602.06, "trd": NaN, "batb": [[1, 2.14, 673.62]], "batl": NaN}, {"timestamp": 1578734829902, "ltp": 2.18, "tv": 18646.06, "trd": [[2.18, 1209.53]], "batb": NaN, "batl": [[0, 2.18, 259.26]]}, {"timestamp": 1578734839908, "ltp": 2.18, "tv": 18646.06, "trd": NaN, "batb": [[1, 2.14, 678.51]], "batl": NaN}, {"timestamp": 1578734882998, "ltp": 2.16, "tv": 18652.06, "trd": [[2.16, 3335.42]], "batb": [[0, 2.16, 87.31]], "batl": NaN}, {"timestamp": 1578734890942, "ltp": 2.18, "tv": 18840.06, "trd": [[2.18, 1397.53]], "batb": NaN, "batl": [[0, 2.18, 165.26]]}, {"timestamp": 1578734893912, "ltp": 2.18, "tv": 18840.06, "trd": NaN, "batb": [[1, 2.14, 566.49]], "batl": NaN}, {"timestamp": 1578734906867, "ltp": 2.18, "tv": 18861.18, "trd": [[2.18, 1418.65]], "batb": NaN, "batl": [[0, 2.18, 154.7]]}, {"timestamp": 1578734908955, "ltp": 2.18, "tv": 18861.18, "trd": NaN, "batb": NaN, "batl": [[0, 2.18, 354.7]]}, {"timestamp": 1578734949923, "ltp": 2.18, "tv": 18861.18, "trd": NaN, "batb": [[0, 2.16, 148.76]], "batl": [[0, 2.18, 429.7]]}, {"timestamp": 1578734951817, "ltp": 2.18, "tv": 18861.18, "trd": NaN, "batb": NaN, "batl": [[0, 2.18, 454.7]]}, {"timestamp": 1578734952811, "ltp": 2.18, "tv": 18961.18, "trd": [[2.18, 1518.65]], "batb": NaN, "batl": [[0, 2.18, 504.7]]}, {"timestamp": 1578735004727, "ltp": 2.18, "tv": 18961.18, "trd": NaN, "batb": [[0, 2.16, 177.21]], "batl": NaN}, {"timestamp": 1578735058932, "ltp": 2.18, "tv": 18961.18, "trd": NaN, "batb": [[0, 2.16, 190.38]], "batl": NaN}, {"timestamp": 1578735062912, "ltp": 2.16, "tv": 18981.18, "trd": [[2.16, 3355.42]], "batb": [[0, 2.16, 180.38]], "batl": NaN}, {"timestamp": 1578735081953, "ltp": 2.16, "tv": 18981.18, "trd": NaN, "batb": [[0, 2.16, 181.09]], "batl": NaN}, {"timestamp": 1578735092937, "ltp": 2.16, "tv": 18981.18, "trd": NaN, "batb": [[2, 2.12, 82.28]], "batl": NaN}, {"timestamp": 1578735099982, "ltp": 2.18, "tv": 18991.42, "trd": [[2.18, 1528.89]], "batb": NaN, "batl": [[0, 2.18, 499.58]]}, {"timestamp": 1578735111974, "ltp": 2.18, "tv": 18991.42, "trd": NaN, "batb": [[2, 2.12, 112.28]], "batl": NaN}, {"timestamp": 1578735113895, "ltp": 2.18, "tv": 18991.42, "trd": NaN, "batb": [[0, 2.16, 187.23]], "batl": NaN}, {"timestamp": 1578735128990, "ltp": 2.16, "tv": 19025.46, "trd": [[2.16, 3389.46]], "batb": [[0, 2.16, 170.21]], "batl": NaN}, {"timestamp": 1578735138995, "ltp": 2.16, "tv": 19025.46, "trd": NaN, "batb": [[2, 2.12, 152.28]], "batl": NaN}, {"timestamp": 1578735167937, "ltp": 2.16, "tv": 19125.46, "trd": [[2.16, 3489.46]], "batb": [[0, 2.16, 120.21]], "batl": NaN}, {"timestamp": 1578735169912, "ltp": 2.16, "tv": 19125.46, "trd": NaN, "batb": [[0, 2.16, 123.08]], "batl": NaN}, {"timestamp": 1578735226958, "ltp": 2.16, "tv": 19135.46, "trd": [[2.16, 3499.46]], "batb": [[0, 2.16, 118.08]], "batl": NaN}, {"timestamp": 1578735237900, "ltp": 2.16, "tv": 19135.46, "trd": NaN, "batb": [[0, 2.16, 210.14]], "batl": NaN}, {"timestamp": 1578735354951, "ltp": 2.18, "tv": 19319.58, "trd": [[2.18, 1713.01]], "batb": [[0, 2.16, 118.08]], "batl": [[0, 2.18, 407.52]]}, {"timestamp": 1578735383908, "ltp": 2.16, "tv": 19343.58, "trd": [[2.16, 3523.46]], "batb": [[0, 2.16, 106.08]], "batl": NaN}, {"timestamp": 1578735423941, "ltp": 2.18, "tv": 19432.38, "trd": [[2.18, 1801.81]], "batb": NaN, "batl": [[0, 2.18, 363.12]]}, {"timestamp": 1578735435964, "ltp": 2.18, "tv": 19432.38, "trd": NaN, "batb": NaN, "batl": [[0, 2.18, 462.12]]}, {"timestamp": 1578735452839, "ltp": 2.16, "tv": 19442.2, "trd": [[2.16, 3533.28]], "batb": [[0, 2.16, 101.17]], "batl": NaN}, {"timestamp": 1578735453919, "ltp": 2.18, "tv": 19451.94, "trd": [[2.18, 1811.55]], "batb": NaN, "batl": [[0, 2.18, 457.25]]}, {"timestamp": 1578735461958, "ltp": 2.18, "tv": 19451.94, "trd": NaN, "batb": NaN, "batl": [[0, 2.18, 957.25]]}, {"timestamp": 1578735477976, "ltp": 2.18, "tv": 19451.94, "trd": NaN, "batb": [[0, 2.16, 159.17]], "batl": NaN}, {"timestamp": 1578735487972, "ltp": 2.16, "tv": 19553.42, "trd": [[2.16, 3634.76]], "batb": [[0, 2.16, 108.43]], "batl": NaN}, {"timestamp": 1578735501004, "ltp": 2.16, "tv": 19553.42, "trd": NaN, "batb": [[0, 2.16, 201.63]], "batl": NaN}, {"timestamp": 1578735502984, "ltp": 2.18, "tv": 19558.7, "trd": [[2.18, 1816.83]], "batb": NaN, "batl": [[0, 2.18, 954.61]]}, {"timestamp": 1578735503816, "ltp": 2.16, "tv": 19588.7, "trd": [[2.16, 3664.76]], "batb": [[0, 2.16, 186.63]], "batl": NaN}, {"timestamp": 1578735509894, "ltp": 2.16, "tv": 19628.7, "trd": [[2.16, 3704.76]], "batb": [[0, 2.16, 166.63]], "batl": NaN}, {"timestamp": 1578735512926, "ltp": 2.18, "tv": 19632.7, "trd": [[2.18, 1820.83]], "batb": NaN, "batl": [[0, 2.18, 952.61]]}, {"timestamp": 1578735518946, "ltp": 2.18, "tv": 19632.7, "trd": NaN, "batb": [[2, 2.12, 143.77]], "batl": NaN}, {"timestamp": 1578735535001, "ltp": 2.18, "tv": 19637.7, "trd": [[2.18, 1825.83]], "batb": NaN, "batl": [[0, 2.18, 950.11]]}, {"timestamp": 1578735587953, "ltp": 2.18, "tv": 19637.7, "trd": NaN, "batb": NaN, "batl": [[2, 2.22, 6386.57]]}, {"timestamp": 1578735608957, "ltp": 2.18, "tv": 19637.7, "trd": NaN, "batb": [[0, 2.16, 172.96]], "batl": NaN}, {"timestamp": 1578735616985, "ltp": 2.16, "tv": 19837.69, "trd": [[2.16, 3904.75]], "batb": [[0, 2.16, 72.96]], "batl": NaN}, {"timestamp": 1578735617762, "ltp": 2.16, "tv": 19837.69, "trd": NaN, "batb": [[0, 2.16, 109.96], [1, 2.14, 539.49], [2, 2.12, 120.77]], "batl": NaN}, {"timestamp": 1578735618177, "ltp": 2.18, "tv": 19841.69, "trd": [[2.18, 1829.83]], "batb": NaN, "batl": [[0, 2.18, 948.11]]}, {"timestamp": 1578735619990, "ltp": 2.18, "tv": 20041.69, "trd": [[2.18, 2029.83]], "batb": NaN, "batl": [[0, 2.18, 848.11]]}, {"timestamp": 1578735625901, "ltp": 2.16, "tv": 20045.77, "trd": [[2.16, 3908.84]], "batb": [[0, 2.16, 107.92]], "batl": NaN}, {"timestamp": 1578735629887, "ltp": 2.16, "tv": 20065.78, "trd": [[2.16, 3928.84]], "batb": [[0, 2.16, 97.92]], "batl": NaN}, {"timestamp": 1578735639814, "ltp": 2.16, "tv": 20571.55, "trd": [[2.16, 4434.62]], "batb": [[0, 2.14, 539.49], [1, 2.12, 181.58], [2, 2.1, 437.92]], "batl": [[0, 2.16, 247.11], [1, 2.18, 848.11], [2, 2.2, 4284.42]]}, {"timestamp": 1578735640901, "ltp": 2.16, "tv": 20723.27, "trd": [[2.16, 4586.33]], "batb": [[0, 2.14, 551.49], [2, 2.1, 449.92]], "batl": [[0, 2.16, 171.25]]}, {"timestamp": 1578735641937, "ltp": 2.16, "tv": 20723.27, "trd": NaN, "batb": [[1, 2.12, 157.17]], "batl": NaN}, {"timestamp": 1578735652939, "ltp": 2.14, "tv": 20765.83, "trd": [[2.14, 3817.28]], "batb": [[0, 2.14, 530.21]], "batl": NaN}, {"timestamp": 1578735663864, "ltp": 2.14, "tv": 20765.83, "trd": NaN, "batb": [[0, 2.14, 532.93]], "batl": NaN}, {"timestamp": 1578735696801, "ltp": 2.14, "tv": 20765.83, "trd": NaN, "batb": NaN, "batl": [[0, 2.16, 271.25]]}, {"timestamp": 1578735719947, "ltp": 2.14, "tv": 20765.83, "trd": NaN, "batb": [[0, 2.14, 483.93], [1, 2.12, 179.17], [2, 2.1, 471.92]], "batl": NaN}, {"timestamp": 1578735770816, "ltp": 2.14, "tv": 20785.83, "trd": [[2.14, 3837.28]], "batb": [[0, 2.14, 473.93]], "batl": NaN}, {"timestamp": 1578735778813, "ltp": 2.14, "tv": 20785.83, "trd": NaN, "batb": [[0, 2.14, 544.93]], "batl": NaN}, {"timestamp": 1578735786799, "ltp": 2.14, "tv": 20985.83, "trd": [[2.14, 4037.28]], "batb": [[0, 2.14, 444.93]], "batl": NaN}, {"timestamp": 1578735790968, "ltp": 2.14, "tv": 20985.83, "trd": NaN, "batb": [[0, 2.14, 373.93]], "batl": NaN}, {"timestamp": 1578735803979, "ltp": 2.16, "tv": 21006.23, "trd": [[2.16, 4606.73]], "batb": NaN, "batl": [[0, 2.16, 261.05]]}, {"timestamp": 1578735819898, "ltp": 2.16, "tv": 21006.23, "trd": NaN, "batb": [[0, 2.14, 422.93]], "batl": NaN}, {"timestamp": 1578735827780, "ltp": 2.16, "tv": 21006.23, "trd": NaN, "batb": [[0, 2.14, 491.93]], "batl": NaN}, {"timestamp": 1578735828979, "ltp": 2.16, "tv": 21006.23, "trd": NaN, "batb": [[0, 2.14, 501.21]], "batl": NaN}, {"timestamp": 1578735884000, "ltp": 2.16, "tv": 21006.23, "trd": NaN, "batb": [[0, 2.14, 505.55]], "batl": NaN}, {"timestamp": 1578735899949, "ltp": 2.14, "tv": 21086.23, "trd": [[2.14, 4117.28]], "batb": [[0, 2.14, 465.55]], "batl": NaN}, {"timestamp": 1578735938976, "ltp": 2.14, "tv": 21086.23, "trd": NaN, "batb": [[0, 2.14, 467.63]], "batl": NaN}, {"timestamp": 1578735943991, "ltp": 2.14, "tv": 21086.23, "trd": NaN, "batb": [[1, 2.12, 154.77]], "batl": NaN}, {"timestamp": 1578735954004, "ltp": 2.14, "tv": 21086.23, "trd": NaN, "batb": [[1, 2.12, 166.09]], "batl": NaN}, {"timestamp": 1578735973911, "ltp": 2.16, "tv": 21391.91, "trd": [[2.16, 4912.41]], "batb": NaN, "batl": [[0, 2.16, 108.21]]}, {"timestamp": 1578735976796, "ltp": 2.16, "tv": 21391.91, "trd": NaN, "batb": [[0, 2.14, 590.89]], "batl": NaN}, {"timestamp": 1578735977995, "ltp": 2.14, "tv": 21407.91, "trd": [[2.14, 4133.28]], "batb": [[0, 2.14, 582.89]], "batl": NaN}, {"timestamp": 1578735994913, "ltp": 2.14, "tv": 21407.91, "trd": NaN, "batb": [[0, 2.14, 585.75]], "batl": NaN}, {"timestamp": 1578736012967, "ltp": 2.14, "tv": 21407.91, "trd": NaN, "batb": NaN, "batl": [[0, 2.16, 8.21]]}, {"timestamp": 1578736048955, "ltp": 2.14, "tv": 21407.91, "trd": NaN, "batb": [[0, 2.14, 611.77]], "batl": NaN}, {"timestamp": 1578736053965, "ltp": 2.14, "tv": 21419.91, "trd": [[2.14, 4145.28]], "batb": [[0, 2.14, 605.77]], "batl": NaN}, {"timestamp": 1578736103829, "ltp": 2.14, "tv": 21419.91, "trd": NaN, "batb": [[0, 2.14, 617.93]], "batl": NaN}, {"timestamp": 1578736116937, "ltp": 2.14, "tv": 21419.91, "trd": NaN, "batb": NaN, "batl": [[0, 2.16, 10.21]]}, {"timestamp": 1578736154963, "ltp": 2.14, "tv": 21469.91, "trd": [[2.14, 4195.28]], "batb": [[0, 2.14, 592.93]], "batl": NaN}, {"timestamp": 1578736158961, "ltp": 2.14, "tv": 21469.91, "trd": NaN, "batb": [[0, 2.14, 598.61]], "batl": NaN}, {"timestamp": 1578736177922, "ltp": 2.16, "tv": 21489.81, "trd": [[2.16, 4932.31]], "batb": NaN, "batl": [[0, 2.18, 848.37], [1, 2.2, 4284.42], [2, 2.22, 6386.57]]}, {"timestamp": 1578736178913, "ltp": 2.16, "tv": 21490.33, "trd": [[2.16, 4932.83]], "batb": [[0, 2.16, 7.81], [1, 2.14, 598.61], [2, 2.12, 166.09]], "batl": [[0, 2.18, 848.11], [2, 2.22, 6394.03]]}, {"timestamp": 1578736179913, "ltp": 2.16, "tv": 21490.33, "trd": NaN, "batb": [[2, 2.12, 154.77]], "batl": NaN}, {"timestamp": 1578736183908, "ltp": 2.16, "tv": 21490.33, "trd": NaN, "batb": NaN, "batl": [[2, 2.22, 6386.57]]}, {"timestamp": 1578736207956, "ltp": 2.16, "tv": 21490.33, "trd": NaN, "batb": NaN, "batl": [[1, 2.2, 4292.07]]}, {"timestamp": 1578736214941, "ltp": 2.16, "tv": 21490.33, "trd": NaN, "batb": [[1, 2.14, 533.47]], "batl": NaN}, {"timestamp": 1578736231003, "ltp": 2.16, "tv": 21490.33, "trd": NaN, "batb": [[1, 2.14, 593.87]], "batl": NaN}, {"timestamp": 1578736259846, "ltp": 2.16, "tv": 21494.24, "trd": [[2.16, 4936.75]], "batb": [[0, 2.16, 5.86]], "batl": NaN}, {"timestamp": 1578736260946, "ltp": 2.16, "tv": 21494.24, "trd": NaN, "batb": [[0, 2.16, 7.81]], "batl": NaN}, {"timestamp": 1578736261947, "ltp": 2.16, "tv": 21494.24, "trd": NaN, "batb": [[2, 2.12, 151.38]], "batl": NaN}, {"timestamp": 1578736265965, "ltp": 2.16, "tv": 21494.24, "trd": NaN, "batb": NaN, "batl": [[2, 2.22, 6384.07]]}, {"timestamp": 1578736268986, "ltp": 2.16, "tv": 21494.24, "trd": NaN, "batb": [[0, 2.16, 53.18]], "batl": NaN}, {"timestamp": 1578736280969, "ltp": 2.16, "tv": 21494.24, "trd": NaN, "batb": [[1, 2.14, 470.61]], "batl": NaN}, {"timestamp": 1578736323934, "ltp": 2.16, "tv": 21494.24, "trd": NaN, "batb": [[0, 2.16, 74.2]], "batl": NaN}, {"timestamp": 1578736333991, "ltp": 2.16, "tv": 21507.86, "trd": [[2.16, 4950.37]], "batb": [[0, 2.16, 67.39]], "batl": NaN}, {"timestamp": 1578736348991, "ltp": 2.16, "tv": 21607.87, "trd": [[2.16, 5050.37]], "batb": [[0, 2.16, 17.39]], "batl": NaN}, {"timestamp": 1578736357490, "ltp": 2.16, "tv": 21627.87, "trd": [[2.16, 5070.37]], "batb": [[0, 2.16, 7.39]], "batl": NaN}, {"timestamp": 1578736378870, "ltp": 2.16, "tv": 21627.87, "trd": NaN, "batb": [[0, 2.16, 17.5]], "batl": NaN}, {"timestamp": 1578736407910, "ltp": 2.16, "tv": 21627.87, "trd": NaN, "batb": [[0, 2.16, 100.5]], "batl": NaN}, {"timestamp": 1578736433990, "ltp": 2.16, "tv": 21627.87, "trd": NaN, "batb": [[0, 2.16, 105.18]], "batl": NaN}, {"timestamp": 1578736489801, "ltp": 2.16, "tv": 21627.87, "trd": NaN, "batb": [[0, 2.16, 109.2]], "batl": NaN}, {"timestamp": 1578736513423, "ltp": 2.16, "tv": 21629.87, "trd": [[2.16, 5072.37]], "batb": [[0, 2.16, 108.2]], "batl": NaN}, {"timestamp": 1578736539825, "ltp": 2.16, "tv": 21629.87, "trd": NaN, "batb": NaN, "batl": [[1, 2.2, 4284.42], [2, 2.22, 6391.53]]}, {"timestamp": 1578736543946, "ltp": 2.16, "tv": 21629.87, "trd": NaN, "batb": [[0, 2.16, 110.62]], "batl": NaN}, {"timestamp": 1578736545636, "ltp": 2.16, "tv": 21629.87, "trd": NaN, "batb": NaN, "batl": [[2, 2.22, 6384.07]]}, {"timestamp": 1578736653951, "ltp": 2.18, "tv": 21649.31, "trd": [[2.18, 2049.27]], "batb": NaN, "batl": [[0, 2.18, 838.39]]}, {"timestamp": 1578736671951, "ltp": 2.16, "tv": 21660.03, "trd": [[2.16, 5083.09]], "batb": [[0, 2.16, 105.26]], "batl": NaN}, {"timestamp": 1578736682979, "ltp": 2.16, "tv": 21660.03, "trd": NaN, "batb": NaN, "batl": [[2, 2.22, 6391.53]]}, {"timestamp": 1578736713926, "ltp": 2.16, "tv": 21660.03, "trd": NaN, "batb": NaN, "batl": [[2, 2.22, 6384.07]]}, {"timestamp": 1578736780823, "ltp": 2.16, "tv": 21680.03, "trd": [[2.16, 5103.09]], "batb": [[0, 2.16, 95.26]], "batl": NaN}, {"timestamp": 1578736814987, "ltp": 2.16, "tv": 21720.03, "trd": [[2.16, 5143.09]], "batb": [[0, 2.16, 75.26]], "batl": NaN}, {"timestamp": 1578736839918, "ltp": 2.18, "tv": 21724.03, "trd": [[2.18, 2053.27]], "batb": NaN, "batl": [[0, 2.18, 836.39]]}, {"timestamp": 1578736848923, "ltp": 2.16, "tv": 21729.03, "trd": [[2.16, 5148.09]], "batb": [[0, 2.16, 72.76]], "batl": NaN}, {"timestamp": 1578736852727, "ltp": 2.16, "tv": 21733.03, "trd": [[2.16, 5152.09]], "batb": [[0, 2.16, 70.76]], "batl": NaN}, {"timestamp": 1578736916004, "ltp": 2.16, "tv": 21773.03, "trd": [[2.16, 5192.09]], "batb": [[0, 2.16, 50.76]], "batl": NaN}, {"timestamp": 1578736985998, "ltp": 2.16, "tv": 21873.03, "trd": [[2.16, 5292.09]], "batb": [[0, 2.14, 471.37], [1, 2.12, 151.38], [2, 2.1, 471.92]], "batl": NaN}, {"timestamp": 1578736987962, "ltp": 2.16, "tv": 21873.03, "trd": NaN, "batb": [[1, 2.12, 166.58]], "batl": NaN}, {"timestamp": 1578737040988, "ltp": 2.16, "tv": 21873.03, "trd": NaN, "batb": [[0, 2.14, 402.37]], "batl": NaN}, {"timestamp": 1578737046710, "ltp": 2.16, "tv": 21874.55, "trd": [[2.16, 5293.61]], "batb": [[0, 2.14, 401.61], [1, 2.12, 190.58], [2, 2.1, 495.92]], "batl": [[0, 2.18, 862.39], [1, 2.2, 4310.42]]}, {"timestamp": 1578737047909, "ltp": 2.16, "tv": 21874.55, "trd": NaN, "batb": NaN, "batl": [[0, 2.16, 27.28], [1, 2.18, 862.39], [2, 2.2, 4310.42]]}, {"timestamp": 1578737055430, "ltp": 2.14, "tv": 21888.55, "trd": [[2.14, 4209.28]], "batb": [[0, 2.14, 394.61]], "batl": NaN}, {"timestamp": 1578737064904, "ltp": 2.16, "tv": 21943.11, "trd": [[2.16, 5348.17]], "batb": [[0, 2.16, 132.72], [1, 2.14, 394.61], [2, 2.12, 190.58]], "batl": [[0, 2.18, 862.39], [1, 2.2, 4310.42], [2, 2.22, 6384.07]]}, {"timestamp": 1578737065899, "ltp": 2.16, "tv": 22007.11, "trd": [[2.16, 5412.17]], "batb": [[0, 2.16, 100.72], [2, 2.12, 175.38]], "batl": [[1, 2.2, 4284.42], [2, 2.22, 6391.53]]}, {"timestamp": 1578737066704, "ltp": 2.16, "tv": 22007.11, "trd": NaN, "batb": [[1, 2.14, 502.61]], "batl": [[1, 2.2, 4315.42]]}, {"timestamp": 1578737067805, "ltp": 2.16, "tv": 22007.11, "trd": NaN, "batb": NaN, "batl": [[2, 2.22, 6384.07]]}, {"timestamp": 1578737087926, "ltp": 2.16, "tv": 22007.11, "trd": NaN, "batb": [[1, 2.14, 431.02]], "batl": NaN}, {"timestamp": 1578737094868, "ltp": 2.16, "tv": 22067.11, "trd": [[2.16, 5472.17]], "batb": [[0, 2.16, 70.72]], "batl": NaN}, {"timestamp": 1578737145875, "ltp": 2.16, "tv": 22137.83, "trd": [[2.16, 5542.89]], "batb": [[0, 2.14, 323.02], [1, 2.12, 175.38], [2, 2.1, 495.92]], "batl": [[0, 2.16, 27.01], [1, 2.18, 862.39], [2, 2.2, 4315.42]]}, {"timestamp": 1578737147980, "ltp": 2.16, "tv": 22137.83, "trd": NaN, "batb": [[1, 2.12, 190.09]], "batl": NaN}, {"timestamp": 1578737148991, "ltp": 2.16, "tv": 22137.83, "trd": NaN, "batb": [[0, 2.14, 325.42]], "batl": NaN}, {"timestamp": 1578737155982, "ltp": 2.16, "tv": 22137.83, "trd": NaN, "batb": NaN, "batl": [[0, 2.16, 72.94]]}, {"timestamp": 1578737156998, "ltp": 2.16, "tv": 22137.83, "trd": NaN, "batb": NaN, "batl": [[2, 2.2, 4284.42]]}, {"timestamp": 1578737160900, "ltp": 2.14, "tv": 22169.83, "trd": [[2.14, 4241.28]], "batb": [[0, 2.14, 309.42]], "batl": NaN}, {"timestamp": 1578737203955, "ltp": 2.14, "tv": 22169.83, "trd": NaN, "batb": [[0, 2.14, 314.38]], "batl": NaN}, {"timestamp": 1578737207960, "ltp": 2.14, "tv": 22169.83, "trd": NaN, "batb": [[0, 2.14, 412.38]], "batl": NaN}, {"timestamp": 1578737208959, "ltp": 2.14, "tv": 22169.83, "trd": NaN, "batb": [[0, 2.14, 314.38]], "batl": NaN}, {"timestamp": 1578737209959, "ltp": 2.14, "tv": 22173.93, "trd": [[2.14, 4245.38]], "batb": [[0, 2.14, 312.33]], "batl": NaN}, {"timestamp": 1578737259857, "ltp": 2.14, "tv": 22173.93, "trd": NaN, "batb": [[0, 2.14, 314.65]], "batl": NaN}, {"timestamp": 1578737263911, "ltp": 2.14, "tv": 22173.93, "trd": NaN, "batb": NaN, "batl": [[2, 2.2, 4306.42]]}, {"timestamp": 1578737313980, "ltp": 2.14, "tv": 22173.93, "trd": NaN, "batb": [[0, 2.14, 333.78]], "batl": NaN}, {"timestamp": 1578737331000, "ltp": 2.14, "tv": 22173.93, "trd": NaN, "batb": NaN, "batl": [[0, 2.16, 45.93], [1, 2.18, 836.39], [2, 2.2, 4284.42]]}, {"timestamp": 1578737335997, "ltp": 2.14, "tv": 22173.93, "trd": NaN, "batb": [[0, 2.14, 457.03]], "batl": NaN}, {"timestamp": 1578737344908, "ltp": 2.14, "tv": 22173.93, "trd": NaN, "batb": [[0, 2.14, 531.03]], "batl": NaN}, {"timestamp": 1578737367941, "ltp": 2.14, "tv": 22173.93, "trd": NaN, "batb": NaN, "batl": [[0, 2.16, 145.93]]}, {"timestamp": 1578737369850, "ltp": 2.14, "tv": 22173.93, "trd": NaN, "batb": [[0, 2.14, 554.42]], "batl": NaN}, {"timestamp": 1578737403910, "ltp": 2.14, "tv": 22183.93, "trd": [[2.14, 4255.38]], "batb": [[0, 2.14, 549.42]], "batl": NaN}, {"timestamp": 1578737407910, "ltp": 2.16, "tv": 22194.25, "trd": [[2.16, 5553.21]], "batb": NaN, "batl": [[0, 2.16, 140.77]]}, {"timestamp": 1578737415004, "ltp": 2.14, "tv": 22198.25, "trd": [[2.14, 4259.38]], "batb": [[0, 2.14, 547.42]], "batl": NaN}, {"timestamp": 1578737415906, "ltp": 2.16, "tv": 22202.21, "trd": [[2.16, 5557.17]], "batb": NaN, "batl": [[0, 2.16, 138.79]]}, {"timestamp": 1578737421938, "ltp": 2.16, "tv": 22212.41, "trd": [[2.16, 5567.37]], "batb": NaN, "batl": [[0, 2.16, 133.69]]}, {"timestamp": 1578737423946, "ltp": 2.16, "tv": 22212.41, "trd": NaN, "batb": [[0, 2.14, 558.35]], "batl": NaN}, {"timestamp": 1578737428952, "ltp": 2.16, "tv": 22233.07, "trd": [[2.16, 5588.03]], "batb": NaN, "batl": [[0, 2.16, 123.36]]}, {"timestamp": 1578737457973, "ltp": 2.16, "tv": 22233.07, "trd": NaN, "batb": [[0, 2.14, 484.35]], "batl": NaN}, {"timestamp": 1578737459906, "ltp": 2.16, "tv": 22233.07, "trd": NaN, "batb": [[0, 2.14, 361.1]], "batl": NaN}, {"timestamp": 1578737466930, "ltp": 2.16, "tv": 22242.79, "trd": [[2.16, 5597.75]], "batb": NaN, "batl": [[0, 2.16, 118.5]]}, {"timestamp": 1578737478926, "ltp": 2.16, "tv": 22242.79, "trd": NaN, "batb": [[0, 2.14, 369.36]], "batl": NaN}, {"timestamp": 1578737491827, "ltp": 2.16, "tv": 22242.79, "trd": NaN, "batb": [[1, 2.12, 192.09], [2, 2.1, 493.92]], "batl": NaN}, {"timestamp": 1578737499946, "ltp": 2.14, "tv": 22262.79, "trd": [[2.14, 4279.38]], "batb": [[0, 2.14, 359.36]], "batl": NaN}, {"timestamp": 1578737533975, "ltp": 2.14, "tv": 22262.79, "trd": NaN, "batb": [[0, 2.14, 363.22]], "batl": NaN}, {"timestamp": 1578737583936, "ltp": 2.14, "tv": 22274.79, "trd": [[2.14, 4291.38]], "batb": [[0, 2.14, 357.22]], "batl": NaN}, {"timestamp": 1578737589975, "ltp": 2.14, "tv": 22274.79, "trd": NaN, "batb": [[1, 2.12, 196.45]], "batl": NaN}, {"timestamp": 1578737611874, "ltp": 2.16, "tv": 22285.13, "trd": [[2.16, 5608.09]], "batb": NaN, "batl": [[0, 2.16, 113.33]]}, {"timestamp": 1578737618899, "ltp": 2.16, "tv": 22305.51, "trd": [[2.16, 5628.47]], "batb": NaN, "batl": [[0, 2.16, 103.14]]}, {"timestamp": 1578737640002, "ltp": 2.16, "tv": 22323.65, "trd": [[2.16, 5646.61]], "batb": NaN, "batl": [[0, 2.16, 94.07]]}, {"timestamp": 1578737643920, "ltp": 2.16, "tv": 22323.65, "trd": NaN, "batb": [[1, 2.12, 198.51]], "batl": NaN}, {"timestamp": 1578737644921, "ltp": 2.16, "tv": 22363.65, "trd": [[2.16, 5686.61]], "batb": NaN, "batl": [[0, 2.16, 74.07]]}, {"timestamp": 1578737664584, "ltp": 2.16, "tv": 22403.65, "trd": [[2.16, 5726.61]], "batb": NaN, "batl": [[0, 2.16, 54.07]]}, {"timestamp": 1578737680988, "ltp": 2.16, "tv": 22423.65, "trd": [[2.16, 5746.61]], "batb": NaN, "batl": [[0, 2.16, 44.07]]}, {"timestamp": 1578737688991, "ltp": 2.16, "tv": 22462.37, "trd": [[2.16, 5785.33]], "batb": NaN, "batl": [[0, 2.16, 24.71]]}, {"timestamp": 1578737706487, "ltp": 2.14, "tv": 22470.37, "trd": [[2.14, 4299.38]], "batb": [[0, 2.14, 353.22]], "batl": NaN}, {"timestamp": 1578737751002, "ltp": 2.14, "tv": 22470.37, "trd": NaN, "batb": NaN, "batl": [[0, 2.16, 70.74]]}, {"timestamp": 1578737754937, "ltp": 2.14, "tv": 22470.37, "trd": NaN, "batb": [[1, 2.12, 201.32]], "batl": NaN}, {"timestamp": 1578737768942, "ltp": 2.14, "tv": 22470.37, "trd": NaN, "batb": NaN, "batl": [[2, 2.2, 4314.42]]}, {"timestamp": 1578737780983, "ltp": 2.14, "tv": 22474.37, "trd": [[2.14, 4303.38]], "batb": [[0, 2.14, 351.22]], "batl": NaN}, {"timestamp": 1578737786991, "ltp": 2.16, "tv": 22513.63, "trd": [[2.16, 5824.59]], "batb": NaN, "batl": [[0, 2.16, 51.11]]}, {"timestamp": 1578737789983, "ltp": 2.16, "tv": 22513.63, "trd": NaN, "batb": NaN, "batl": [[0, 2.16, 71.11], [1, 2.18, 856.39], [2, 2.2, 4334.42]]}, {"timestamp": 1578737796995, "ltp": 2.14, "tv": 22517.63, "trd": [[2.14, 4307.38]], "batb": [[0, 2.14, 349.22]], "batl": NaN}, {"timestamp": 1578737810853, "ltp": 2.14, "tv": 22527.63, "trd": [[2.14, 4317.38]], "batb": [[0, 2.14, 344.22]], "batl": NaN}, {"timestamp": 1578737816941, "ltp": 2.14, "tv": 22527.63, "trd": NaN, "batb": NaN, "batl": [[0, 2.16, 117.1]]}, {"timestamp": 1578737863920, "ltp": 2.14, "tv": 22527.63, "trd": NaN, "batb": [[0, 2.14, 268.97], [1, 2.12, 192.09]], "batl": NaN}, {"timestamp": 1578737868786, "ltp": 2.14, "tv": 22577.63, "trd": [[2.14, 4367.38]], "batb": [[0, 2.14, 243.97]], "batl": NaN}, {"timestamp": 1578737910943, "ltp": 2.16, "tv": 22626.63, "trd": [[2.16, 5873.59]], "batb": NaN, "batl": [[0, 2.16, 92.6]]}, {"timestamp": 1578737911948, "ltp": 2.16, "tv": 22626.63, "trd": NaN, "batb": [[0, 2.14, 317.97]], "batl": [[0, 2.16, 72.6]]}, {"timestamp": 1578737918992, "ltp": 2.16, "tv": 22626.63, "trd": NaN, "batb": [[0, 2.14, 441.22]], "batl": NaN}, {"timestamp": 1578737919781, "ltp": 2.16, "tv": 22626.63, "trd": NaN, "batb": [[0, 2.14, 490.75]], "batl": NaN}, {"timestamp": 1578737933916, "ltp": 2.16, "tv": 22626.63, "trd": NaN, "batb": NaN, "batl": [[1, 2.18, 876.39]]}, {"timestamp": 1578737974991, "ltp": 2.16, "tv": 22626.63, "trd": NaN, "batb": [[0, 2.14, 513.89]], "batl": NaN}, {"timestamp": 1578737998001, "ltp": 2.16, "tv": 22626.63, "trd": NaN, "batb": [[0, 2.14, 439.89]], "batl": [[0, 2.16, 93.6]]}, {"timestamp": 1578738005822, "ltp": 2.16, "tv": 22626.63, "trd": NaN, "batb": [[0, 2.14, 316.64]], "batl": NaN}, {"timestamp": 1578738008940, "ltp": 2.16, "tv": 22626.63, "trd": NaN, "batb": NaN, "batl": [[0, 2.16, 193.6]]}, {"timestamp": 1578738012919, "ltp": 2.16, "tv": 22626.63, "trd": NaN, "batb": NaN, "batl": [[0, 2.16, 172.6]]}, {"timestamp": 1578738022957, "ltp": 2.16, "tv": 22626.63, "trd": NaN, "batb": NaN, "batl": [[0, 2.16, 193.6]]}, {"timestamp": 1578738024966, "ltp": 2.16, "tv": 22646.63, "trd": [[2.16, 5893.59]], "batb": NaN, "batl": [[0, 2.16, 183.6]]}, {"timestamp": 1578738027546, "ltp": 2.16, "tv": 22646.63, "trd": NaN, "batb": NaN, "batl": [[2, 2.2, 4342.07]]}, {"timestamp": 1578738029864, "ltp": 2.16, "tv": 22646.63, "trd": NaN, "batb": [[0, 2.14, 327.47]], "batl": NaN}, {"timestamp": 1578738040958, "ltp": 2.14, "tv": 22686.63, "trd": [[2.14, 4407.38]], "batb": [[0, 2.14, 307.47]], "batl": NaN}, {"timestamp": 1578738060991, "ltp": 2.14, "tv": 22886.63, "trd": [[2.14, 4607.38]], "batb": [[0, 2.14, 207.47]], "batl": NaN}, {"timestamp": 1578738070998, "ltp": 2.14, "tv": 22886.63, "trd": NaN, "batb": NaN, "batl": [[2, 2.2, 4322.07]]}, {"timestamp": 1578738084926, "ltp": 2.14, "tv": 22886.63, "trd": NaN, "batb": [[0, 2.14, 212.48]], "batl": NaN}, {"timestamp": 1578738122895, "ltp": 2.14, "tv": 22966.63, "trd": [[2.14, 4687.38]], "batb": [[0, 2.14, 172.48]], "batl": NaN}, {"timestamp": 1578738129815, "ltp": 2.14, "tv": 22966.63, "trd": NaN, "batb": NaN, "batl": [[2, 2.2, 4342.07]]}, {"timestamp": 1578738139965, "ltp": 2.14, "tv": 22966.63, "trd": NaN, "batb": [[0, 2.14, 174.81]], "batl": NaN}, {"timestamp": 1578738158575, "ltp": 2.14, "tv": 22974.63, "trd": [[2.14, 4695.38]], "batb": [[0, 2.14, 170.81]], "batl": NaN}, {"timestamp": 1578738194709, "ltp": 2.14, "tv": 22974.63, "trd": NaN, "batb": [[0, 2.14, 178.51]], "batl": NaN}, {"timestamp": 1578738195908, "ltp": 2.14, "tv": 22974.63, "trd": NaN, "batb": [[0, 2.14, 186.21]], "batl": NaN}, {"timestamp": 1578738197189, "ltp": 2.14, "tv": 22974.63, "trd": NaN, "batb": [[0, 2.14, 193.91]], "batl": NaN}, {"timestamp": 1578738219765, "ltp": 2.14, "tv": 22974.63, "trd": NaN, "batb": NaN, "batl": [[0, 2.16, 282.6], [1, 2.18, 777.39]]}, {"timestamp": 1578738224854, "ltp": 2.14, "tv": 22974.63, "trd": NaN, "batb": NaN, "batl": [[2, 2.2, 4322.07]]}, {"timestamp": 1578738251898, "ltp": 2.14, "tv": 23078.63, "trd": [[2.14, 4795.38], [2.16, 5897.59]], "batb": [[0, 2.14, 143.91]], "batl": [[0, 2.16, 280.6]]}, {"timestamp": 1578738254912, "ltp": 2.14, "tv": 23078.63, "trd": NaN, "batb": [[1, 2.12, 97.09], [2, 2.1, 397.92]], "batl": [[0, 2.16, 259.6], [1, 2.18, 757.39]]}, {"timestamp": 1578738259925, "ltp": 2.14, "tv": 23078.63, "trd": NaN, "batb": [[1, 2.12, 172.09], [2, 2.1, 473.92]], "batl": [[0, 2.16, 279.6], [1, 2.18, 777.39]]}, {"timestamp": 1578738319835, "ltp": 2.14, "tv": 23118.63, "trd": [[2.14, 4835.38]], "batb": [[0, 2.14, 123.91]], "batl": NaN}, {"timestamp": 1578738384920, "ltp": 2.16, "tv": 23122.63, "trd": [[2.16, 5901.59]], "batb": NaN, "batl": [[0, 2.16, 277.6]]}, {"timestamp": 1578738389991, "ltp": 2.16, "tv": 23122.63, "trd": NaN, "batb": NaN, "batl": [[0, 2.16, 257.6], [2, 2.2, 4342.07]]}, {"timestamp": 1578738404000, "ltp": 2.16, "tv": 23122.63, "trd": NaN, "batb": NaN, "batl": [[0, 2.16, 277.6]]}, {"timestamp": 1578738408834, "ltp": 2.16, "tv": 23122.63, "trd": NaN, "batb": NaN, "batl": [[0, 2.16, 257.6]]}, {"timestamp": 1578738421931, "ltp": 2.16, "tv": 23143.01, "trd": [[2.16, 5921.97]], "batb": NaN, "batl": [[0, 2.16, 247.41]]}, {"timestamp": 1578738425931, "ltp": 2.16, "tv": 23143.01, "trd": NaN, "batb": [[1, 2.12, 272.09]], "batl": [[0, 2.16, 287.41]]}, {"timestamp": 1578738463814, "ltp": 2.14, "tv": 23153.01, "trd": [[2.14, 4845.38]], "batb": [[0, 2.14, 118.91]], "batl": NaN}, {"timestamp": 1578738467910, "ltp": 2.14, "tv": 23153.01, "trd": NaN, "batb": [[0, 2.14, 121.58]], "batl": NaN}, {"timestamp": 1578738470821, "ltp": 2.14, "tv": 23153.01, "trd": NaN, "batb": NaN, "batl": [[0, 2.16, 267.41]]}, {"timestamp": 1578738474534, "ltp": 2.16, "tv": 23162.51, "trd": [[2.16, 5931.47]], "batb": NaN, "batl": [[0, 2.16, 262.66]]}, {"timestamp": 1578738483939, "ltp": 2.16, "tv": 23162.51, "trd": NaN, "batb": [[0, 2.14, 141.39]], "batl": NaN}, {"timestamp": 1578738484843, "ltp": 2.16, "tv": 23172.47, "trd": [[2.16, 5941.43]], "batb": NaN, "batl": [[0, 2.16, 257.68]]}, {"timestamp": 1578738512900, "ltp": 2.16, "tv": 23232.19, "trd": [[2.16, 6001.15]], "batb": NaN, "batl": [[0, 2.16, 227.82]]}, {"timestamp": 1578738522917, "ltp": 2.16, "tv": 23232.19, "trd": NaN, "batb": [[0, 2.14, 172.92]], "batl": [[0, 2.16, 207.82], [1, 2.18, 757.39], [2, 2.2, 4322.07]]}, {"timestamp": 1578738523953, "ltp": 2.16, "tv": 23232.19, "trd": NaN, "batb": NaN, "batl": [[2, 2.2, 4314.42]]}, {"timestamp": 1578738525818, "ltp": 2.16, "tv": 23252.19, "trd": [[2.16, 6021.15]], "batb": NaN, "batl": [[0, 2.16, 197.82]]}, {"timestamp": 1578738563949, "ltp": 2.14, "tv": 23332.18, "trd": [[2.14, 4925.38]], "batb": [[0, 2.14, 132.92]], "batl": NaN}, {"timestamp": 1578738578848, "ltp": 2.14, "tv": 23332.18, "trd": NaN, "batb": [[0, 2.14, 147.65]], "batl": NaN}, {"timestamp": 1578738633959, "ltp": 2.14, "tv": 23332.18, "trd": NaN, "batb": [[0, 2.14, 154.54]], "batl": NaN}, {"timestamp": 1578738645991, "ltp": 2.14, "tv": 23332.18, "trd": NaN, "batb": NaN, "batl": [[0, 2.16, 368.06]]}, {"timestamp": 1578738687970, "ltp": 2.14, "tv": 23332.18, "trd": NaN, "batb": [[0, 2.14, 157.76]], "batl": NaN}, {"timestamp": 1578738704858, "ltp": 2.14, "tv": 23336.18, "trd": [[2.14, 4929.38]], "batb": [[0, 2.14, 155.76]], "batl": NaN}, {"timestamp": 1578738714904, "ltp": 2.14, "tv": 23386.18, "trd": [[2.14, 4979.38]], "batb": [[0, 2.14, 130.76]], "batl": NaN}, {"timestamp": 1578738742870, "ltp": 2.14, "tv": 23396.18, "trd": [[2.14, 4989.38]], "batb": [[0, 2.14, 125.76]], "batl": NaN}, {"timestamp": 1578738751747, "ltp": 2.14, "tv": 23416.18, "trd": [[2.14, 5009.38]], "batb": [[0, 2.14, 115.76]], "batl": NaN}, {"timestamp": 1578738769879, "ltp": 2.14, "tv": 23416.18, "trd": NaN, "batb": NaN, "batl": [[2, 2.2, 4322.07]]}, {"timestamp": 1578738771865, "ltp": 2.14, "tv": 23536.18, "trd": [[2.14, 5129.38]], "batb": [[0, 2.14, 55.76]], "batl": NaN}, {"timestamp": 1578738782966, "ltp": 2.14, "tv": 23536.18, "trd": NaN, "batb": NaN, "batl": [[2, 2.2, 4314.42]]}, {"timestamp": 1578738783957, "ltp": 2.14, "tv": 23536.18, "trd": NaN, "batb": [[1, 2.12, 257.38]], "batl": NaN}, {"timestamp": 1578738811906, "ltp": 2.16, "tv": 23655.06, "trd": [[2.16, 6140.03]], "batb": NaN, "batl": [[0, 2.16, 308.62]]}, {"timestamp": 1578738819899, "ltp": 2.16, "tv": 23659.06, "trd": [[2.16, 6144.03]], "batb": NaN, "batl": [[0, 2.16, 306.62]]}, {"timestamp": 1578738825916, "ltp": 2.14, "tv": 23685.06, "trd": [[2.14, 5155.38]], "batb": [[0, 2.14, 42.76]], "batl": NaN}, {"timestamp": 1578738826921, "ltp": 2.14, "tv": 23765.06, "trd": [[2.14, 5235.38]], "batb": [[0, 2.14, 2.76]], "batl": NaN}, {"timestamp": 1578738853991, "ltp": 2.14, "tv": 23765.06, "trd": NaN, "batb": [[0, 2.14, 11.77]], "batl": NaN}, {"timestamp": 1578738859989, "ltp": 2.14, "tv": 23765.06, "trd": NaN, "batb": NaN, "batl": [[1, 2.18, 765.24]]}, {"timestamp": 1578738869987, "ltp": 2.16, "tv": 23771.06, "trd": [[2.16, 6150.03]], "batb": NaN, "batl": [[0, 2.16, 303.62]]}, {"timestamp": 1578738905998, "ltp": 2.16, "tv": 23771.06, "trd": NaN, "batb": NaN, "batl": [[1, 2.18, 757.39]]}, {"timestamp": 1578738907844, "ltp": 2.16, "tv": 23771.06, "trd": NaN, "batb": [[0, 2.14, 18.99]], "batl": NaN}, {"timestamp": 1578738918988, "ltp": 2.16, "tv": 23771.06, "trd": NaN, "batb": NaN, "batl": [[2, 2.2, 4322.07]]}, {"timestamp": 1578738949809, "ltp": 2.16, "tv": 23771.06, "trd": NaN, "batb": [[0, 2.14, 21.99]], "batl": NaN}, {"timestamp": 1578738957734, "ltp": 2.14, "tv": 23791.06, "trd": [[2.14, 5255.38]], "batb": [[0, 2.14, 11.99]], "batl": NaN}, {"timestamp": 1578738961972, "ltp": 2.14, "tv": 23791.06, "trd": NaN, "batb": [[0, 2.14, 15.37]], "batl": NaN}, {"timestamp": 1578738988986, "ltp": 2.14, "tv": 23821.8, "trd": [[2.14, 5286.12]], "batb": [[0, 2.12, 257.38], [1, 2.1, 473.92], [2, 2.08, 86.98]], "batl": [[0, 2.14, 184.63], [1, 2.16, 303.62], [2, 2.18, 757.39]]}, {"timestamp": 1578738990003, "ltp": 2.14, "tv": 23837.8, "trd": [[2.14, 5302.12]], "batb": [[2, 2.08, 10.93]], "batl": [[0, 2.14, 176.63]]}, {"timestamp": 1578738990915, "ltp": 2.14, "tv": 23841.8, "trd": [[2.14, 5306.12]], "batb": NaN, "batl": [[0, 2.14, 188.63]]}, {"timestamp": 1578738996796, "ltp": 2.14, "tv": 23841.8, "trd": NaN, "batb": NaN, "batl": [[0, 2.14, 174.63]]}, {"timestamp": 1578739011968, "ltp": 2.12, "tv": 23869.8, "trd": [[2.12, 1804.22]], "batb": [[0, 2.12, 243.38]], "batl": NaN}, {"timestamp": 1578739013904, "ltp": 2.14, "tv": 23899.8, "trd": [[2.14, 5336.12]], "batb": [[0, 2.12, 168.38], [2, 2.08, 83.24]], "batl": [[0, 2.14, 159.63]]}, {"timestamp": 1578739017951, "ltp": 2.14, "tv": 23899.8, "trd": NaN, "batb": [[0, 2.12, 172.12]], "batl": NaN}, {"timestamp": 1578739065994, "ltp": 2.12, "tv": 23917.8, "trd": [[2.12, 1822.22]], "batb": [[0, 2.12, 163.12]], "batl": NaN}, {"timestamp": 1578739077997, "ltp": 2.14, "tv": 23928.02, "trd": [[2.14, 5346.34]], "batb": NaN, "batl": [[0, 2.14, 154.52]]}, {"timestamp": 1578739081912, "ltp": 2.14, "tv": 23928.02, "trd": NaN, "batb": [[1, 2.1, 455.92]], "batl": NaN}, {"timestamp": 1578739083929, "ltp": 2.14, "tv": 23928.02, "trd": NaN, "batb": [[0, 2.12, 220.12], [2, 2.08, 10.93]], "batl": NaN}, {"timestamp": 1578739087827, "ltp": 2.14, "tv": 23974.02, "trd": [[2.14, 5392.34]], "batb": NaN, "batl": [[0, 2.14, 131.52]]}, {"timestamp": 1578739088907, "ltp": 2.14, "tv": 23978.02, "trd": [[2.14, 5396.34]], "batb": NaN, "batl": [[0, 2.14, 129.52]]}, {"timestamp": 1578739090626, "ltp": 2.14, "tv": 23978.02, "trd": NaN, "batb": NaN, "batl": [[0, 2.14, 157.52]]}, {"timestamp": 1578739092950, "ltp": 2.12, "tv": 24038.02, "trd": [[2.12, 1882.22]], "batb": [[0, 2.12, 190.12]], "batl": NaN}, {"timestamp": 1578739107763, "ltp": 2.12, "tv": 24038.02, "trd": NaN, "batb": NaN, "batl": [[0, 2.14, 357.52]]}, {"timestamp": 1578739128002, "ltp": 2.12, "tv": 24038.02, "trd": NaN, "batb": [[0, 2.12, 193.52]], "batl": NaN}, {"timestamp": 1578739137927, "ltp": 2.14, "tv": 24047.55, "trd": [[2.14, 5405.87]], "batb": NaN, "batl": [[0, 2.14, 347.99]]}, {"timestamp": 1578739143902, "ltp": 2.14, "tv": 24047.55, "trd": NaN, "batb": [[0, 2.12, 265.79]], "batl": NaN}, {"timestamp": 1578739170956, "ltp": 2.12, "tv": 24055.65, "trd": [[2.12, 1890.32]], "batb": [[0, 2.12, 261.74]], "batl": NaN}, {"timestamp": 1578739205932, "ltp": 2.12, "tv": 24055.65, "trd": NaN, "batb": [[0, 2.12, 511.74]], "batl": NaN}, {"timestamp": 1578739226993, "ltp": 2.12, "tv": 24055.65, "trd": NaN, "batb": [[0, 2.12, 541.74]], "batl": NaN}, {"timestamp": 1578739232930, "ltp": 2.12, "tv": 24055.65, "trd": NaN, "batb": NaN, "batl": [[0, 2.14, 446.99], [1, 2.16, 204.62]]}, {"timestamp": 1578739234995, "ltp": 2.12, "tv": 24060.65, "trd": [[2.12, 1895.32]], "batb": [[0, 2.12, 539.24]], "batl": NaN}, {"timestamp": 1578739244993, "ltp": 2.14, "tv": 24079.05, "trd": [[2.14, 5424.27]], "batb": NaN, "batl": [[0, 2.14, 437.79]]}, {"timestamp": 1578739272856, "ltp": 2.14, "tv": 24087.83, "trd": [[2.14, 5433.05]], "batb": NaN, "batl": [[0, 2.14, 433.4]]}, {"timestamp": 1578739285998, "ltp": 2.14, "tv": 24095.69, "trd": [[2.14, 5440.91]], "batb": NaN, "batl": [[0, 2.14, 429.47]]}, {"timestamp": 1578739345917, "ltp": 2.14, "tv": 24128.34, "trd": [[2.14, 5473.56]], "batb": NaN, "batl": [[0, 2.14, 396.82]]}, {"timestamp": 1578739369960, "ltp": 2.12, "tv": 24168.34, "trd": [[2.12, 1935.32]], "batb": [[0, 2.12, 519.24]], "batl": NaN}, {"timestamp": 1578739370960, "ltp": 2.12, "tv": 25174.1, "trd": [[2.12, 2941.07]], "batb": [[0, 2.12, 16.36]], "batl": NaN}, {"timestamp": 1578739371961, "ltp": 2.12, "tv": 25174.1, "trd": NaN, "batb": [[0, 2.12, 71.36]], "batl": NaN}, {"timestamp": 1578739378999, "ltp": 2.12, "tv": 25174.1, "trd": NaN, "batb": [[0, 2.12, 16.36], [2, 2.08, 67.1]], "batl": NaN}, {"timestamp": 1578739394911, "ltp": 2.14, "tv": 25174.16, "trd": [[2.14, 5473.62]], "batb": NaN, "batl": [[0, 2.14, 396.79]]}, {"timestamp": 1578739398946, "ltp": 2.14, "tv": 25174.16, "trd": NaN, "batb": NaN, "batl": [[0, 2.14, 496.79]]}, {"timestamp": 1578739402926, "ltp": 2.14, "tv": 25174.16, "trd": NaN, "batb": [[0, 2.12, 25.62]], "batl": NaN}, {"timestamp": 1578739446913, "ltp": 2.14, "tv": 25174.16, "trd": NaN, "batb": [[0, 2.12, 77.79], [2, 2.08, 10.93]], "batl": NaN}, {"timestamp": 1578739451937, "ltp": 2.14, "tv": 25174.16, "trd": NaN, "batb": [[0, 2.12, 158.09]], "batl": NaN}, {"timestamp": 1578739452933, "ltp": 2.14, "tv": 25174.16, "trd": NaN, "batb": [[0, 2.12, 105.92], [2, 2.08, 64.1]], "batl": NaN}, {"timestamp": 1578739457871, "ltp": 2.14, "tv": 25174.16, "trd": NaN, "batb": [[0, 2.12, 110.29]], "batl": NaN}, {"timestamp": 1578739500947, "ltp": 2.12, "tv": 25180.16, "trd": [[2.12, 2947.07]], "batb": [[0, 2.12, 107.29]], "batl": NaN}, {"timestamp": 1578739506834, "ltp": 2.12, "tv": 25191.7, "trd": [[2.12, 2958.61]], "batb": [[0, 2.12, 101.52]], "batl": NaN}, {"timestamp": 1578739528944, "ltp": 2.12, "tv": 25191.7, "trd": NaN, "batb": [[0, 2.12, 351.52]], "batl": NaN}, {"timestamp": 1578739534864, "ltp": 2.14, "tv": 25205.7, "trd": [[2.14, 5487.62]], "batb": NaN, "batl": [[0, 2.14, 489.79]]}, {"timestamp": 1578739540967, "ltp": 2.14, "tv": 25205.7, "trd": NaN, "batb": [[0, 2.12, 358.52]], "batl": NaN}, {"timestamp": 1578739543891, "ltp": 2.14, "tv": 25205.7, "trd": NaN, "batb": [[0, 2.12, 407.52], [2, 2.08, 10.93]], "batl": NaN}, {"timestamp": 1578739544984, "ltp": 2.14, "tv": 25232.08, "trd": [[2.14, 5514]], "batb": NaN, "batl": [[0, 2.14, 476.6]]}, {"timestamp": 1578739561985, "ltp": 2.12, "tv": 25242.08, "trd": [[2.12, 2968.61]], "batb": [[0, 2.12, 402.52]], "batl": NaN}, {"timestamp": 1578739563922, "ltp": 2.14, "tv": 25442.08, "trd": [[2.14, 5714]], "batb": NaN, "batl": [[0, 2.14, 376.6]]}, {"timestamp": 1578739566828, "ltp": 2.14, "tv": 25442.08, "trd": NaN, "batb": NaN, "batl": [[1, 2.16, 359.62]]}, {"timestamp": 1578739567935, "ltp": 2.14, "tv": 25442.08, "trd": NaN, "batb": [[0, 2.12, 404.63]], "batl": NaN}, {"timestamp": 1578739583853, "ltp": 2.12, "tv": 25474.08, "trd": [[2.12, 3000.62]], "batb": [[0, 2.12, 388.63]], "batl": NaN}, {"timestamp": 1578739605904, "ltp": 2.12, "tv": 25474.08, "trd": NaN, "batb": NaN, "batl": [[0, 2.14, 396.6]]}, {"timestamp": 1578739640863, "ltp": 2.12, "tv": 25474.08, "trd": NaN, "batb": NaN, "batl": [[2, 2.18, 457.39]]}, {"timestamp": 1578739644981, "ltp": 2.12, "tv": 25474.08, "trd": NaN, "batb": NaN, "batl": [[0, 2.14, 596.6], [2, 2.18, 257.39]]}, {"timestamp": 1578739646972, "ltp": 2.12, "tv": 25474.08, "trd": NaN, "batb": [[2, 2.08, 165.93]], "batl": NaN}, {"timestamp": 1578739655955, "ltp": 2.14, "tv": 25574.08, "trd": [[2.14, 5814]], "batb": NaN, "batl": [[0, 2.14, 546.6]]}, {"timestamp": 1578739663990, "ltp": 2.14, "tv": 25674.08, "trd": [[2.14, 5914]], "batb": NaN, "batl": [[0, 2.14, 496.6]]}, {"timestamp": 1578739677912, "ltp": 2.14, "tv": 25674.08, "trd": NaN, "batb": [[0, 2.12, 392.15]], "batl": NaN}, {"timestamp": 1578739733903, "ltp": 2.14, "tv": 25674.08, "trd": NaN, "batb": [[0, 2.12, 447.28]], "batl": NaN}, {"timestamp": 1578739738002, "ltp": 2.14, "tv": 25674.08, "trd": NaN, "batb": [[0, 2.12, 448.04]], "batl": NaN}, {"timestamp": 1578739787975, "ltp": 2.14, "tv": 25674.08, "trd": NaN, "batb": [[0, 2.12, 476.21]], "batl": NaN}, {"timestamp": 1578739841941, "ltp": 2.14, "tv": 25674.08, "trd": NaN, "batb": [[0, 2.12, 489.48]], "batl": NaN}, {"timestamp": 1578739845840, "ltp": 2.12, "tv": 25682.08, "trd": [[2.12, 3008.62]], "batb": [[0, 2.12, 485.48]], "batl": NaN}, {"timestamp": 1578739897938, "ltp": 2.12, "tv": 25682.08, "trd": NaN, "batb": [[0, 2.12, 491.74]], "batl": NaN}, {"timestamp": 1578739899822, "ltp": 2.12, "tv": 25694.09, "trd": [[2.12, 3020.62]], "batb": [[0, 2.12, 485.74]], "batl": NaN}, {"timestamp": 1578739911933, "ltp": 2.14, "tv": 25756.75, "trd": [[2.14, 5976.66]], "batb": NaN, "batl": [[0, 2.14, 465.27]]}, {"timestamp": 1578739954001, "ltp": 2.14, "tv": 25756.75, "trd": NaN, "batb": [[0, 2.12, 488.75]], "batl": NaN}, {"timestamp": 1578739963933, "ltp": 2.14, "tv": 25756.75, "trd": NaN, "batb": [[2, 2.08, 10.93]], "batl": [[1, 2.16, 204.62]]}, {"timestamp": 1578739964719, "ltp": 2.14, "tv": 25756.75, "trd": NaN, "batb": [[0, 2.12, 526.75]], "batl": NaN}, {"timestamp": 1578739980931, "ltp": 2.12, "tv": 25796.75, "trd": [[2.12, 3060.62]], "batb": [[0, 2.12, 506.74]], "batl": NaN}, {"timestamp": 1578740007989, "ltp": 2.12, "tv": 25796.75, "trd": NaN, "batb": [[0, 2.12, 509.27]], "batl": NaN}, {"timestamp": 1578740035958, "ltp": 2.14, "tv": 25845.43, "trd": [[2.14, 6025.34]], "batb": NaN, "batl": [[0, 2.14, 440.93]]}, {"timestamp": 1578740073982, "ltp": 2.12, "tv": 25855.43, "trd": [[2.12, 3070.62]], "batb": [[0, 2.12, 504.28]], "batl": NaN}, {"timestamp": 1578740078996, "ltp": 2.12, "tv": 25855.82, "trd": [[2.12, 3071.01]], "batb": [[0, 2.12, 504.08]], "batl": NaN}, {"timestamp": 1578740080619, "ltp": 2.14, "tv": 25859.82, "trd": [[2.14, 6029.34]], "batb": NaN, "batl": [[0, 2.14, 438.93]]}, {"timestamp": 1578740090996, "ltp": 2.12, "tv": 25863.82, "trd": [[2.12, 3075.01]], "batb": [[0, 2.12, 502.08]], "batl": NaN}, {"timestamp": 1578740103960, "ltp": 2.14, "tv": 25903.82, "trd": [[2.14, 6069.34]], "batb": NaN, "batl": [[0, 2.14, 418.93]]}, {"timestamp": 1578740170957, "ltp": 2.14, "tv": 26032.91, "trd": [[2.14, 6198.43]], "batb": NaN, "batl": [[0, 2.14, 289.84]]}, {"timestamp": 1578740178962, "ltp": 2.14, "tv": 26151.61, "trd": [[2.14, 6317.13]], "batb": NaN, "batl": [[0, 2.14, 230.49]]}, {"timestamp": 1578740226934, "ltp": 2.14, "tv": 26151.61, "trd": NaN, "batb": [[0, 2.12, 502.82]], "batl": NaN}, {"timestamp": 1578740228928, "ltp": 2.14, "tv": 26151.61, "trd": NaN, "batb": [[0, 2.12, 511.83]], "batl": NaN}, {"timestamp": 1578740235840, "ltp": 2.12, "tv": 26157.61, "trd": [[2.12, 3081.01]], "batb": [[0, 2.12, 508.83]], "batl": NaN}, {"timestamp": 1578740259001, "ltp": 2.14, "tv": 26183.33, "trd": [[2.14, 6342.85]], "batb": NaN, "batl": [[0, 2.14, 217.63]]}, {"timestamp": 1578740278911, "ltp": 2.14, "tv": 26203.33, "trd": [[2.14, 6362.85]], "batb": NaN, "batl": [[0, 2.14, 207.63]]}, {"timestamp": 1578740280938, "ltp": 2.14, "tv": 26205.55, "trd": [[2.14, 6365.07]], "batb": [[0, 2.12, 533.72]], "batl": [[0, 2.14, 205.41]]}, {"timestamp": 1578740281925, "ltp": 2.14, "tv": 26205.55, "trd": NaN, "batb": [[0, 2.12, 545.46]], "batl": NaN}, {"timestamp": 1578740288920, "ltp": 2.14, "tv": 26219.11, "trd": [[2.14, 6378.63]], "batb": [[0, 2.12, 566.03]], "batl": [[0, 2.14, 198.63]]}, {"timestamp": 1578740301934, "ltp": 2.14, "tv": 26219.11, "trd": NaN, "batb": [[0, 2.12, 766.03]], "batl": NaN}, {"timestamp": 1578740313958, "ltp": 2.14, "tv": 26219.11, "trd": NaN, "batb": NaN, "batl": [[2, 2.18, 57.39]]}, {"timestamp": 1578740327966, "ltp": 2.12, "tv": 26227.11, "trd": [[2.12, 3089.01]], "batb": [[0, 2.12, 762.03]], "batl": NaN}, {"timestamp": 1578740337987, "ltp": 2.12, "tv": 26227.11, "trd": NaN, "batb": [[0, 2.12, 767.5]], "batl": NaN}, {"timestamp": 1578740357980, "ltp": 2.12, "tv": 26227.11, "trd": NaN, "batb": [[0, 2.12, 891.92]], "batl": NaN}, {"timestamp": 1578740364004, "ltp": 2.14, "tv": 26386.21, "trd": [[2.14, 6537.73]], "batb": NaN, "batl": [[0, 2.14, 119.08]]}, {"timestamp": 1578740376930, "ltp": 2.14, "tv": 26386.21, "trd": NaN, "batb": [[0, 2.12, 767.5]], "batl": NaN}, {"timestamp": 1578740381807, "ltp": 2.14, "tv": 26386.21, "trd": NaN, "batb": [[0, 2.14, 8.15], [1, 2.12, 767.5], [2, 2.1, 455.92]], "batl": [[0, 2.16, 204.62], [1, 2.18, 57.39], [2, 2.2, 4480.03]]}, {"timestamp": 1578740388716, "ltp": 2.14, "tv": 26402.52, "trd": [[2.14, 6554.03]], "batb": [[0, 2.12, 767.5], [1, 2.1, 455.92], [2, 2.08, 62.11]], "batl": [[2, 2.2, 4472.38]]}, {"timestamp": 1578740390911, "ltp": 2.14, "tv": 26402.52, "trd": NaN, "batb": [[0, 2.14, 179.92], [1, 2.12, 767.5], [2, 2.1, 455.92]], "batl": NaN}, {"timestamp": 1578740391936, "ltp": 2.14, "tv": 26402.52, "trd": NaN, "batb": NaN, "batl": [[2, 2.2, 4480.03]]}, {"timestamp": 1578740392932, "ltp": 2.14, "tv": 26402.52, "trd": NaN, "batb": NaN, "batl": [[2, 2.2, 4322.07]]}, {"timestamp": 1578740393925, "ltp": 2.14, "tv": 26402.52, "trd": NaN, "batb": [[1, 2.12, 769.97]], "batl": NaN}, {"timestamp": 1578740428979, "ltp": 2.14, "tv": 26402.52, "trd": NaN, "batb": [[1, 2.12, 787.97]], "batl": [[2, 2.2, 4314.42]]}, {"timestamp": 1578740439002, "ltp": 2.14, "tv": 26402.52, "trd": NaN, "batb": NaN, "batl": [[2, 2.2, 4472.38]]}, {"timestamp": 1578740447904, "ltp": 2.14, "tv": 26402.52, "trd": NaN, "batb": [[1, 2.12, 640.91]], "batl": NaN}, {"timestamp": 1578740480974, "ltp": 2.14, "tv": 26402.52, "trd": NaN, "batb": NaN, "batl": [[0, 2.16, 304.62]]}, {"timestamp": 1578740502915, "ltp": 2.14, "tv": 26402.52, "trd": NaN, "batb": [[0, 2.14, 258.19]], "batl": NaN}, {"timestamp": 1578740526805, "ltp": 2.16, "tv": 26602.52, "trd": [[2.16, 6350.03]], "batb": NaN, "batl": [[0, 2.16, 204.62]]}, {"timestamp": 1578740545945, "ltp": 2.16, "tv": 26642.52, "trd": [[2.16, 6390.03]], "batb": NaN, "batl": [[0, 2.16, 184.62]]}, {"timestamp": 1578740552963, "ltp": 2.16, "tv": 26659.66, "trd": [[2.16, 6407.18]], "batb": NaN, "batl": [[0, 2.16, 176.05]]}, {"timestamp": 1578740557960, "ltp": 2.16, "tv": 26659.66, "trd": NaN, "batb": [[0, 2.14, 294.77]], "batl": NaN}, {"timestamp": 1578740572992, "ltp": 2.16, "tv": 26699.66, "trd": [[2.16, 6447.18]], "batb": NaN, "batl": [[0, 2.16, 156.04]]}, {"timestamp": 1578740593903, "ltp": 2.16, "tv": 26699.66, "trd": NaN, "batb": [[1, 2.12, 664.91], [2, 2.1, 489.92]], "batl": NaN}, {"timestamp": 1578740594806, "ltp": 2.16, "tv": 26699.66, "trd": NaN, "batb": NaN, "batl": [[0, 2.16, 256.04]]}, {"timestamp": 1578740608984, "ltp": 2.16, "tv": 26725.2, "trd": [[2.16, 6472.71]], "batb": NaN, "batl": [[0, 2.16, 243.28]]}, {"timestamp": 1578740611982, "ltp": 2.16, "tv": 26766.02, "trd": [[2.16, 6513.54]], "batb": NaN, "batl": [[0, 2.16, 222.86]]}, {"timestamp": 1578740613004, "ltp": 2.16, "tv": 26766.02, "trd": NaN, "batb": [[0, 2.14, 311.86]], "batl": NaN}, {"timestamp": 1578740626918, "ltp": 2.16, "tv": 26782.02, "trd": [[2.16, 6529.54]], "batb": NaN, "batl": [[0, 2.16, 214.86]]}, {"timestamp": 1578740633003, "ltp": 2.16, "tv": 26804.02, "trd": [[2.16, 6551.54]], "batb": NaN, "batl": [[0, 2.16, 203.86], [1, 2.18, 157.39]]}, {"timestamp": 1578740656971, "ltp": 2.16, "tv": 26824.03, "trd": [[2.16, 6571.54]], "batb": NaN, "batl": [[0, 2.16, 193.86]]}, {"timestamp": 1578740667981, "ltp": 2.16, "tv": 26824.03, "trd": NaN, "batb": [[0, 2.14, 319.85]], "batl": NaN}, {"timestamp": 1578740673980, "ltp": 2.16, "tv": 26824.03, "trd": NaN, "batb": [[0, 2.14, 362.41]], "batl": NaN}, {"timestamp": 1578740678003, "ltp": 2.16, "tv": 27040.03, "trd": [[2.14, 6564.03], [2.16, 6777.54]], "batb": [[0, 2.14, 357.41]], "batl": [[0, 2.16, 90.86]]}, {"timestamp": 1578740690995, "ltp": 2.16, "tv": 27040.03, "trd": NaN, "batb": NaN, "batl": [[2, 2.2, 4480.03]]}, {"timestamp": 1578740691804, "ltp": 2.16, "tv": 27176.22, "trd": [[2.16, 6913.74]], "batb": NaN, "batl": [[0, 2.16, 22.76]]}, {"timestamp": 1578740695976, "ltp": 2.16, "tv": 27176.22, "trd": NaN, "batb": NaN, "batl": [[2, 2.2, 4322.07]]}, {"timestamp": 1578740697904, "ltp": 2.16, "tv": 27200.68, "trd": [[2.16, 6938.2]], "batb": NaN, "batl": [[0, 2.16, 10.53]]}, {"timestamp": 1578740704923, "ltp": 2.16, "tv": 27221.74, "trd": [[2.16, 6959.26]], "batb": [[0, 2.16, 19.47], [1, 2.14, 448.41], [2, 2.12, 664.91]], "batl": [[0, 2.18, 157.39], [1, 2.2, 4322.07], [2, 2.22, 6391.53]]}, {"timestamp": 1578740723934, "ltp": 2.16, "tv": 27221.74, "trd": NaN, "batb": [[1, 2.14, 452.18]], "batl": NaN}, {"timestamp": 1578740741957, "ltp": 2.18, "tv": 27239.34, "trd": [[2.18, 2070.87]], "batb": NaN, "batl": [[0, 2.18, 148.59]]}, {"timestamp": 1578740745950, "ltp": 2.18, "tv": 27239.34, "trd": NaN, "batb": [[0, 2.16, 189.71]], "batl": NaN}, {"timestamp": 1578740747878, "ltp": 2.18, "tv": 27239.34, "trd": NaN, "batb": [[0, 2.16, 389.71]], "batl": NaN}, {"timestamp": 1578740760916, "ltp": 2.18, "tv": 27442.92, "trd": [[2.18, 2274.45]], "batb": NaN, "batl": [[0, 2.18, 46.8]]}, {"timestamp": 1578740771943, "ltp": 2.18, "tv": 27454.92, "trd": [[2.18, 2286.45]], "batb": NaN, "batl": [[0, 2.18, 40.8]]}, {"timestamp": 1578740774945, "ltp": 2.18, "tv": 27653.92, "trd": [[2.18, 2485.45]], "batb": [[0, 2.18, 82.1], [1, 2.16, 291.71], [2, 2.14, 452.18]], "batl": [[0, 2.2, 4322.07], [1, 2.22, 6391.53], [2, 2.24, 6416.07]]}, {"timestamp": 1578740777941, "ltp": 2.18, "tv": 27653.92, "trd": NaN, "batb": [[2, 2.14, 455.79]], "batl": NaN}, {"timestamp": 1578740780943, "ltp": 2.18, "tv": 27653.92, "trd": NaN, "batb": NaN, "batl": [[0, 2.2, 4350.07], [1, 2.22, 6419.53]]}, {"timestamp": 1578740781852, "ltp": 2.18, "tv": 27653.92, "trd": NaN, "batb": NaN, "batl": [[0, 2.2, 4342.42], [1, 2.22, 6412.07]]}, {"timestamp": 1578740782935, "ltp": 2.18, "tv": 27653.92, "trd": NaN, "batb": NaN, "batl": [[0, 2.2, 4350.07]]}, {"timestamp": 1578740785932, "ltp": 2.18, "tv": 27653.92, "trd": NaN, "batb": [[1, 2.16, 331.71]], "batl": NaN}, {"timestamp": 1578740805864, "ltp": 2.18, "tv": 27818.12, "trd": [[2.18, 2649.65]], "batb": [[0, 2.16, 229.71], [1, 2.14, 486.79], [2, 2.12, 689.91]], "batl": [[0, 2.18, 132.51], [1, 2.2, 4350.07], [2, 2.22, 6412.07]]}, {"timestamp": 1578740807985, "ltp": 2.18, "tv": 27818.12, "trd": NaN, "batb": NaN, "batl": [[2, 2.22, 6384.07]]}, {"timestamp": 1578740808959, "ltp": 2.18, "tv": 27818.12, "trd": NaN, "batb": [[0, 2.16, 230.41]], "batl": NaN}, {"timestamp": 1578740814985, "ltp": 2.18, "tv": 27818.12, "trd": NaN, "batb": NaN, "batl": [[1, 2.2, 4362.07]]}, {"timestamp": 1578740821960, "ltp": 2.18, "tv": 27818.12, "trd": NaN, "batb": [[2, 2.12, 694.91]], "batl": [[0, 2.18, 137.51]]}, {"timestamp": 1578740830907, "ltp": 2.18, "tv": 27818.12, "trd": NaN, "batb": NaN, "batl": [[0, 2.18, 237.51]]}, {"timestamp": 1578740832970, "ltp": 2.18, "tv": 27818.12, "trd": NaN, "batb": [[1, 2.14, 339.48]], "batl": NaN}, {"timestamp": 1578740833990, "ltp": 2.16, "tv": 27938.12, "trd": [[2.16, 7079.25]], "batb": [[0, 2.16, 170.42]], "batl": NaN}, {"timestamp": 1578740838987, "ltp": 2.18, "tv": 27978.12, "trd": [[2.18, 2689.65]], "batb": NaN, "batl": [[0, 2.18, 217.5]]}, {"timestamp": 1578740847921, "ltp": 2.18, "tv": 27978.12, "trd": NaN, "batb": [[1, 2.14, 354.16]], "batl": NaN}, {"timestamp": 1578740849912, "ltp": 2.18, "tv": 28012.17, "trd": [[2.18, 2723.7]], "batb": NaN, "batl": [[0, 2.18, 200.48]]}, {"timestamp": 1578740868945, "ltp": 2.16, "tv": 28036.17, "trd": [[2.16, 7103.26]], "batb": [[0, 2.16, 158.42]], "batl": NaN}, {"timestamp": 1578740888738, "ltp": 2.18, "tv": 28071.92, "trd": [[2.18, 2759.45]], "batb": [[0, 2.16, 241.08]], "batl": [[0, 2.18, 182.6]]}, {"timestamp": 1578740894965, "ltp": 2.18, "tv": 28071.92, "trd": NaN, "batb": NaN, "batl": [[1, 2.2, 4354.42]]}, {"timestamp": 1578740902999, "ltp": 2.18, "tv": 28071.92, "trd": NaN, "batb": NaN, "batl": [[1, 2.2, 4358.42]]}, {"timestamp": 1578740942859, "ltp": 2.18, "tv": 28071.92, "trd": NaN, "batb": [[0, 2.16, 277.71]], "batl": NaN}, {"timestamp": 1578740958957, "ltp": 2.18, "tv": 28100.78, "trd": [[2.18, 2788.31]], "batb": NaN, "batl": [[0, 2.18, 168.18]]}, {"timestamp": 1578740982908, "ltp": 2.16, "tv": 28110.78, "trd": [[2.16, 7113.25]], "batb": [[0, 2.16, 272.71]], "batl": NaN}, {"timestamp": 1578740993002, "ltp": 2.18, "tv": 28141.03, "trd": [[2.18, 2818.56]], "batb": NaN, "batl": [[0, 2.18, 153.05]]}, {"timestamp": 1578741036887, "ltp": 2.18, "tv": 28141.03, "trd": NaN, "batb": [[0, 2.16, 289.67]], "batl": NaN}, {"timestamp": 1578741043992, "ltp": 2.18, "tv": 28141.03, "trd": NaN, "batb": NaN, "batl": [[2, 2.22, 6391.53]]}, {"timestamp": 1578741045002, "ltp": 2.18, "tv": 28141.03, "trd": NaN, "batb": NaN, "batl": [[0, 2.18, 353.05]]}, {"timestamp": 1578741059829, "ltp": 2.18, "tv": 28150.89, "trd": [[2.18, 2828.42]], "batb": NaN, "batl": [[0, 2.18, 348.12]]}, {"timestamp": 1578741091995, "ltp": 2.18, "tv": 28150.89, "trd": NaN, "batb": [[0, 2.16, 297.49]], "batl": NaN}, {"timestamp": 1578741093975, "ltp": 2.16, "tv": 28370.89, "trd": [[2.16, 7333.25]], "batb": [[0, 2.16, 187.49]], "batl": NaN}, {"timestamp": 1578741101884, "ltp": 2.16, "tv": 28370.89, "trd": NaN, "batb": [[1, 2.14, 464.16]], "batl": NaN}, {"timestamp": 1578741125946, "ltp": 2.18, "tv": 28389.67, "trd": [[2.18, 2847.2]], "batb": NaN, "batl": [[0, 2.18, 338.73]]}, {"timestamp": 1578741148003, "ltp": 2.18, "tv": 28389.67, "trd": NaN, "batb": [[1, 2.14, 467.8]], "batl": NaN}, {"timestamp": 1578741164972, "ltp": 2.18, "tv": 28389.67, "trd": NaN, "batb": NaN, "batl": [[0, 2.18, 343], [2, 2.22, 6384.07]]}, {"timestamp": 1578741170912, "ltp": 2.18, "tv": 28389.67, "trd": NaN, "batb": NaN, "batl": [[0, 2.18, 305], [2, 2.22, 6421.07]]}, {"timestamp": 1578741201935, "ltp": 2.18, "tv": 28389.67, "trd": NaN, "batb": [[0, 2.16, 43.42], [1, 2.14, 464.16]], "batl": NaN}, {"timestamp": 1578741202941, "ltp": 2.18, "tv": 28389.67, "trd": NaN, "batb": [[1, 2.14, 449.48]], "batl": NaN}, {"timestamp": 1578741210846, "ltp": 2.18, "tv": 28389.67, "trd": NaN, "batb": [[0, 2.16, 51.93]], "batl": NaN}, {"timestamp": 1578741215962, "ltp": 2.18, "tv": 28389.67, "trd": NaN, "batb": NaN, "batl": [[1, 2.2, 4516.38]]}, {"timestamp": 1578741256891, "ltp": 2.18, "tv": 28389.67, "trd": NaN, "batb": [[0, 2.16, 136.85]], "batl": NaN}, {"timestamp": 1578741262917, "ltp": 2.18, "tv": 28389.67, "trd": NaN, "batb": NaN, "batl": [[0, 2.18, 340], [2, 2.22, 6384.07]]}, {"timestamp": 1578741276946, "ltp": 2.18, "tv": 28389.67, "trd": NaN, "batb": NaN, "batl": [[0, 2.18, 305], [2, 2.22, 6418.07]]}, {"timestamp": 1578741310939, "ltp": 2.18, "tv": 28389.67, "trd": NaN, "batb": [[0, 2.16, 177.67]], "batl": NaN}, {"timestamp": 1578741360906, "ltp": 2.18, "tv": 28408.45, "trd": [[2.18, 2865.98]], "batb": NaN, "batl": [[0, 2.18, 295.61]]}, {"timestamp": 1578741366911, "ltp": 2.18, "tv": 28408.45, "trd": NaN, "batb": [[0, 2.16, 196.57]], "batl": NaN}, {"timestamp": 1578741422987, "ltp": 2.18, "tv": 28408.45, "trd": NaN, "batb": [[0, 2.16, 205.32]], "batl": NaN}, {"timestamp": 1578741440830, "ltp": 2.16, "tv": 28428.45, "trd": [[2.16, 7353.25]], "batb": [[0, 2.16, 195.32]], "batl": NaN}, {"timestamp": 1578741455939, "ltp": 2.18, "tv": 28445.47, "trd": [[2.18, 2883.01]], "batb": NaN, "batl": [[0, 2.18, 287.1]]}, {"timestamp": 1578741458936, "ltp": 2.18, "tv": 28445.47, "trd": NaN, "batb": [[2, 2.12, 662.96]], "batl": NaN}, {"timestamp": 1578741462962, "ltp": 2.18, "tv": 28453.53, "trd": [[2.18, 2891.07]], "batb": NaN, "batl": [[0, 2.18, 283.07]]}, {"timestamp": 1578741472852, "ltp": 2.16, "tv": 28503.53, "trd": [[2.16, 7403.25]], "batb": [[0, 2.16, 170.32]], "batl": NaN}, {"timestamp": 1578741477990, "ltp": 2.16, "tv": 28503.53, "trd": NaN, "batb": [[0, 2.16, 174.34]], "batl": NaN}, {"timestamp": 1578741528937, "ltp": 2.16, "tv": 28503.53, "trd": NaN, "batb": NaN, "batl": [[1, 2.2, 4358.42]]}, {"timestamp": 1578741588884, "ltp": 2.16, "tv": 28505.63, "trd": [[2.16, 7405.35]], "batb": [[0, 2.16, 173.29]], "batl": NaN}, {"timestamp": 1578741591920, "ltp": 2.18, "tv": 28507.71, "trd": [[2.18, 2893.15]], "batb": NaN, "batl": [[0, 2.18, 282.03]]}, {"timestamp": 1578741603849, "ltp": 2.16, "tv": 28512.51, "trd": [[2.16, 7410.15]], "batb": [[0, 2.16, 170.89]], "batl": NaN}, {"timestamp": 1578741606914, "ltp": 2.14, "tv": 30178.3, "trd": [[2.14, 7888.04], [2.16, 7751.93]], "batb": [[0, 2.12, 662.96], [1, 2.1, 526.92], [2, 2.08, 19.92]], "batl": [[0, 2.14, 78.75], [1, 2.16, 41.01], [2, 2.18, 282.03]]}, {"timestamp": 1578741607949, "ltp": 2.14, "tv": 30178.3, "trd": NaN, "batb": [[0, 2.12, 539.96], [2, 2.08, 151.97]], "batl": NaN}, {"timestamp": 1578741608816, "ltp": 2.14, "tv": 30178.3, "trd": NaN, "batb": [[1, 2.1, 551.26]], "batl": NaN}, {"timestamp": 1578741612886, "ltp": 2.14, "tv": 30335.8, "trd": [[2.14, 8045.54]], "batb": [[0, 2.14, 21.25], [1, 2.12, 539.96], [2, 2.1, 551.26]], "batl": [[0, 2.16, 41.01], [1, 2.18, 282.03], [2, 2.2, 4318.42]]}, {"timestamp": 1578741613981, "ltp": 2.14, "tv": 30378.3, "trd": [[2.14, 8088.04]], "batb": [[0, 2.12, 668.96], [1, 2.1, 551.26], [2, 2.08, 10.93]], "batl": [[1, 2.18, 321.03]]}, {"timestam