{"info": {"id": "1.166703748", "eventId": "29632571", "eventName": "Over/Under 3.5 Goals", "marketType": "OVER_UNDER_35", "openDate": 1578772101023, "name": "Inter v Atalanta", "numberOfActiveRunner": 2, "countryCode": "", "sport": "TENNIS", "venue": "", "volume": {"total": 480492.4, "preMatch": 28646.21, "inPlay": 451846.19}, "winner": {"id": 1222344, "name": "Under 3.5 Goals", "status": "WINNER", "position": 1}, "delay": 7}, "runners": [{"id": 1222344, "name": "Under 3.5 Goals", "status": "WINNER", "position": 1, "inPlayOdds": 1.52, "inPlayTime": 1578772101023, "avgPrematch": 1.54, "closedOdds": 1.01, "maxPrematch": 1.62, "minPrematch": 1.52, "maxInPlay": 2.16, "minInPlay": 1.01, "inPlayIndex": 1113, "lengthOdds": 5305, "lengthOddsPrematch": 1113, "lengthOddsInPlay": 4192, "tradedVolume": 427420.07, "preMatchVolume": 20158.86, "inPlayVolume": 407261.21}, {"id": 1222345, "name": "Over 3.5 Goals", "status": "LOSER", "position": 2, "inPlayOdds": 2.88, "inPlayTime": 1578772101023, "avgPrematch": 2.82, "closedOdds": 1000.0, "maxPrematch": 2.94, "minPrematch": 2.52, "maxInPlay": 1000.0, "minInPlay": 1.85, "inPlayIndex": 888, "lengthOdds": 4261, "lengthOddsPrematch": 888, "lengthOddsInPlay": 3373, "tradedVolume": 53072.33, "preMatchVolume": 8487.35, "inPlayVolume": 44584.98}], "marketUpdates": [{"timestamp": 1578513294362000000, "openDate": "2020-01-11T19:45:00.000Z", "status": "OPEN", "betDelay": 0, "inPlay": false, "complete": true}, {"timestamp": 1578772101023000000, "openDate": "2020-01-11T19:45:00.000Z", "status": "OPEN", "betDelay": 7, "inPlay": true, "complete": true}, {"timestamp": 1578772294860000000, "openDate": "2020-01-11T19:45:00.000Z", "status": "SUSPENDED", "betDelay": 7, "inPlay": true, "complete": true}, {"timestamp": 1578772347979000000, "openDate": "2020-01-11T19:45:00.000Z", "status": "OPEN", "betDelay": 7, "inPlay": true, "complete": true}, {"timestamp": 1578774525024000000, "openDate": "2020-01-11T19:45:00.000Z", "status": "SUSPENDED", "betDelay": 7, "inPlay": true, "complete": true}, {"timestamp": 1578774556973000000, "openDate": "2020-01-11T19:45:00.000Z", "status": "OPEN", "betDelay": 7, "inPlay": true, "complete": true}, {"timestamp": 1578774580039000000, "openDate": "2020-01-11T19:45:00.000Z", "status": "SUSPENDED", "betDelay": 7, "inPlay": true, "complete": true}, {"timestamp": 1578774582036000000, "openDate": "2020-01-11T19:45:00.000Z", "status": "OPEN", "betDelay": 7, "inPlay": true, "complete": true}, {"timestamp": 1578774866982000000, "openDate": "2020-01-11T19:45:00.000Z", "status": "OPEN", "betDelay": 1, "inPlay": true, "complete": true}, {"timestamp": 1578775780035000000, "openDate": "2020-01-11T19:45:00.000Z", "status": "OPEN", "betDelay": 7, "inPlay": true, "complete": true}, {"timestamp": 1578777631947000000, "openDate": "2020-01-11T19:45:00.000Z", "status": "SUSPENDED", "betDelay": 7, "inPlay": true, "complete": true}, {"timestamp": 1578777690042000000, "openDate": "2020-01-11T19:45:00.000Z", "status": "OPEN", "betDelay": 7, "inPlay": true, "complete": true}, {"timestamp": 1578778337987000000, "openDate": "2020-01-11T19:45:00.000Z", "status": "SUSPENDED", "betDelay": 7, "inPlay": true, "complete": true}, {"timestamp": 1578778432037000000, "openDate": "2020-01-11T19:45:00.000Z", "status": "OPEN", "betDelay": 7, "inPlay": true, "complete": true}, {"timestamp": 1578778774964000000, "openDate": "2020-01-11T19:45:00.000Z", "status": "SUSPENDED", "betDelay": 7, "inPlay": true, "complete": true}, {"timestamp": 1578778874174000000, "openDate": "2020-01-11T19:45:00.000Z", "status": "CLOSED", "betDelay": 7, "inPlay": true, "complete": true}], "odds": [{"runnerId": 1222344, "odds": [{"timestamp": 1578566084451, "ltp": 1.62, "tv": 8.65, "trd": [[1.62, 8.66]], "batb": NaN, "batl": [[0, 1.62, 216.38]]}, {"timestamp": 1578567751933, "ltp": 1.62, "tv": 8.67, "trd": [[1.62, 8.67]], "batb": [[2, 1.51, 9.52]], "batl": [[0, 1.62, 216.46]]}, {"timestamp": 1578574113983, "ltp": 1.62, "tv": 8.67, "trd": NaN, "batb": [[0, 1.56, 81.03]], "batl": NaN}, {"timestamp": 1578574971012, "ltp": 1.62, "tv": 8.67, "trd": NaN, "batb": [[0, 1.54, 84.03]], "batl": NaN}, {"timestamp": 1578578823992, "ltp": 1.62, "tv": 8.67, "trd": NaN, "batb": [[2, 1.2, 118.87]], "batl": [[0, 1.62, 195.41]]}, {"timestamp": 1578581809788, "ltp": 1.62, "tv": 8.67, "trd": NaN, "batb": [[1, 1.2, 118.87], [2, 1.19, 124.23]], "batl": NaN}, {"timestamp": 1578581931966, "ltp": 1.62, "tv": 8.67, "trd": NaN, "batb": NaN, "batl": [[0, 1.69, 199.79]]}, {"timestamp": 1578582026726, "ltp": 1.62, "tv": 8.67, "trd": [[1.62, 8.67]], "batb": [[1, 1.53, 377.33], [2, 1.2, 118.77]], "batl": NaN}, {"timestamp": 1578584362961, "ltp": 1.62, "tv": 8.67, "trd": NaN, "batb": [[1, 1.51, 391.99]], "batl": [[0, 1.67, 199.77]]}, {"timestamp": 1578584363066, "ltp": 1.62, "tv": 8.67, "trd": NaN, "batb": [[1, 1.2, 118.77], [2, 1.19, 124.14]], "batl": NaN}, {"timestamp": 1578584370991, "ltp": 1.62, "tv": 8.67, "trd": NaN, "batb": NaN, "batl": [[0, 1.66, 199.75]]}, {"timestamp": 1578584383931, "ltp": 1.62, "tv": 8.67, "trd": NaN, "batb": [[1, 1.5, 400], [2, 1.2, 118.77]], "batl": [[0, 1.65, 199.9]]}, {"timestamp": 1578584590970, "ltp": 1.62, "tv": 8.67, "trd": NaN, "batb": [[0, 1.53, 85.62]], "batl": NaN}, {"timestamp": 1578584772772, "ltp": 1.62, "tv": 8.67, "trd": NaN, "batb": [[1, 1.52, 384.49]], "batl": NaN}, {"timestamp": 1578586421954, "ltp": 1.62, "tv": 8.67, "trd": NaN, "batb": [[1, 1.51, 391.99]], "batl": NaN}, {"timestamp": 1578586980013, "ltp": 1.62, "tv": 8.67, "trd": NaN, "batb": [[0, 1.53, 81.69]], "batl": NaN}, {"timestamp": 1578589339707, "ltp": 1.62, "tv": 8.66, "trd": [[1.62, 8.67]], "batb": [[0, 1.51, 476.89], [1, 1.2, 118.62], [2, 1.19, 123.98]], "batl": NaN}, {"timestamp": 1578596551911, "ltp": 1.62, "tv": 8.66, "trd": [[1.62, 8.67]], "batb": [[1, 1.2, 118.73], [2, 1.19, 124.09]], "batl": NaN}, {"timestamp": 1578603751928, "ltp": 1.62, "tv": 8.66, "trd": [[1.62, 8.67]], "batb": [[1, 1.2, 118.63], [2, 1.19, 123.99]], "batl": NaN}, {"timestamp": 1578605378842, "ltp": 1.62, "tv": 8.66, "trd": NaN, "batb": [[0, 1.54, 80.18], [1, 1.51, 391.99], [2, 1.2, 118.63]], "batl": NaN}, {"timestamp": 1578610951918, "ltp": 1.62, "tv": 8.66, "trd": [[1.62, 8.66]], "batb": [[2, 1.2, 118.6]], "batl": NaN}, {"timestamp": 1578617955723, "ltp": 1.62, "tv": 8.66, "trd": NaN, "batb": [[2, 1.45, 14.84]], "batl": NaN}, {"timestamp": 1578617957006, "ltp": 1.62, "tv": 8.66, "trd": NaN, "batb": NaN, "batl": [[0, 1.6, 20.98], [1, 1.65, 199.9]]}, {"timestamp": 1578617991736, "ltp": 1.62, "tv": 8.66, "trd": NaN, "batb": NaN, "batl": [[1, 1.61, 199.91]]}, {"timestamp": 1578618151932, "ltp": 1.62, "tv": 8.66, "trd": [[1.62, 8.67]], "batb": [[2, 1.45, 14.85]], "batl": [[0, 1.6, 21]]}, {"timestamp": 1578620368820, "ltp": 1.62, "tv": 8.66, "trd": NaN, "batb": [[1, 1.52, 384.49]], "batl": NaN}, {"timestamp": 1578625351924, "ltp": 1.62, "tv": 8.66, "trd": NaN, "batb": [[2, 1.45, 14.87]], "batl": [[0, 1.6, 21.01]]}, {"timestamp": 1578632551910, "ltp": 1.62, "tv": 8.66, "trd": [[1.62, 8.66]], "batb": [[2, 1.45, 14.87]], "batl": [[0, 1.6, 21.02]]}, {"timestamp": 1578635996054, "ltp": 1.62, "tv": 8.66, "trd": NaN, "batb": [[1, 1.53, 377.33]], "batl": [[1, 1.61, 0]]}, {"timestamp": 1578636018854, "ltp": 1.62, "tv": 8.66, "trd": [[1.62, 8.66]], "batb": [[1, 1.52, 384.49], [2, 1.45, 14.88]], "batl": [[0, 1.6, 21.03], [1, 1.61, 199.91]]}, {"timestamp": 1578636263990, "ltp": 1.62, "tv": 8.66, "trd": NaN, "batb": [[2, 1.2, 118.47]], "batl": [[0, 1.61, 199.91], [1, 1.61, 0]]}, {"timestamp": 1578643351913, "ltp": 1.62, "tv": 8.66, "trd": [[1.62, 8.67]], "batb": [[2, 1.2, 118.69]], "batl": NaN}, {"timestamp": 1578646951917, "ltp": 1.62, "tv": 8.66, "trd": NaN, "batb": [[2, 1.2, 118.66]], "batl": NaN}, {"timestamp": 1578654151919, "ltp": 1.62, "tv": 8.66, "trd": [[1.62, 8.67]], "batb": [[2, 1.2, 118.72]], "batl": NaN}, {"timestamp": 1578656804029, "ltp": 1.62, "tv": 8.66, "trd": NaN, "batb": [[2, 1.3, 150]], "batl": NaN}, {"timestamp": 1578658537757, "ltp": 1.62, "tv": 8.66, "trd": NaN, "batb": [[0, 1.53, 81.69]], "batl": NaN}, {"timestamp": 1578660366961, "ltp": 1.62, "tv": 8.66, "trd": NaN, "batb": [[1, 1.3, 150], [2, 1.29, 150]], "batl": NaN}, {"timestamp": 1578660516029, "ltp": 1.62, "tv": 8.66, "trd": NaN, "batb": NaN, "batl": [[0, 1.68, 199.89]]}, {"timestamp": 1578660616733, "ltp": 1.62, "tv": 8.66, "trd": NaN, "batb": [[1, 1.52, 384.49], [2, 1.3, 150]], "batl": NaN}, {"timestamp": 1578661352024, "ltp": 1.62, "tv": 8.66, "trd": [[1.62, 8.66]], "batb": NaN, "batl": NaN}, {"timestamp": 1578661534958, "ltp": 1.62, "tv": 8.66, "trd": NaN, "batb": [[0, 1.54, 80.18]], "batl": NaN}, {"timestamp": 1578661697976, "ltp": 1.62, "tv": 8.66, "trd": NaN, "batb": [[0, 1.54, 450.3], [1, 1.3, 150], [2, 1.29, 150]], "batl": NaN}, {"timestamp": 1578661698142, "ltp": 1.62, "tv": 8.66, "trd": NaN, "batb": [[0, 1.54, 80.18]], "batl": NaN}, {"timestamp": 1578661735900, "ltp": 1.62, "tv": 8.66, "trd": NaN, "batb": [[0, 1.55, 363.39], [1, 1.54, 80.18], [2, 1.3, 150]], "batl": NaN}, {"timestamp": 1578668552027, "ltp": 1.62, "tv": 8.66, "trd": [[1.62, 8.67]], "batb": NaN, "batl": NaN}, {"timestamp": 1578669559875, "ltp": 1.62, "tv": 8.66, "trd": NaN, "batb": [[0, 1.54, 80.18], [1, 1.3, 150], [2, 1.29, 150]], "batl": NaN}, {"timestamp": 1578669563601, "ltp": 1.62, "tv": 8.66, "trd": NaN, "batb": [[1, 1.52, 384.49], [2, 1.3, 150]], "batl": [[0, 1.68, 199.89]]}, {"timestamp": 1578669567910, "ltp": 1.62, "tv": 8.66, "trd": NaN, "batb": [[1, 1.3, 150], [2, 1.29, 150]], "batl": NaN}, {"timestamp": 1578669568842, "ltp": 1.62, "tv": 8.66, "trd": NaN, "batb": [[1, 1.53, 377.33], [2, 1.3, 150]], "batl": NaN}, {"timestamp": 1578669572035, "ltp": 1.62, "tv": 8.66, "trd": NaN, "batb": [[0, 1.55, 363.39], [1, 1.54, 80.18]], "batl": NaN}, {"timestamp": 1578669584788, "ltp": 1.62, "tv": 8.66, "trd": NaN, "batb": [[0, 1.54, 80.18], [1, 1.52, 384.49]], "batl": [[0, 1.67, 199.77]]}, {"timestamp": 1578669615023, "ltp": 1.62, "tv": 8.66, "trd": NaN, "batb": [[1, 1.3, 150], [2, 1.29, 150]], "batl": [[0, 1.65, 199.9]]}, {"timestamp": 1578669645042, "ltp": 1.62, "tv": 8.66, "trd": NaN, "batb": [[1, 1.5, 400], [2, 1.3, 150]], "batl": NaN}, {"timestamp": 1578669683919, "ltp": 1.62, "tv": 8.66, "trd": NaN, "batb": [[1, 1.3, 150], [2, 1.29, 150]], "batl": NaN}, {"timestamp": 1578669728887, "ltp": 1.62, "tv": 8.66, "trd": NaN, "batb": [[1, 1.51, 391.99], [2, 1.3, 150]], "batl": NaN}, {"timestamp": 1578672483981, "ltp": 1.62, "tv": 8.66, "trd": NaN, "batb": [[0, 1.51, 476.89], [1, 1.3, 150], [2, 1.29, 150]], "batl": NaN}, {"timestamp": 1578673382223, "ltp": 1.62, "tv": 8.66, "trd": NaN, "batb": [[0, 1.51, 475.33]], "batl": NaN}, {"timestamp": 1578675751995, "ltp": 1.62, "tv": 8.66, "trd": [[1.62, 8.67]], "batb": NaN, "batl": NaN}, {"timestamp": 1578682952056, "ltp": 1.62, "tv": 8.66, "trd": [[1.62, 8.67]], "batb": NaN, "batl": NaN}, {"timestamp": 1578688098022, "ltp": 1.62, "tv": 8.66, "trd": NaN, "batb": [[0, 1.52, 81.74], [1, 1.51, 391.99], [2, 1.3, 150]], "batl": NaN}, {"timestamp": 1578688100307, "ltp": 1.62, "tv": 8.66, "trd": NaN, "batb": [[0, 1.53, 377.33], [1, 1.52, 81.74]], "batl": NaN}, {"timestamp": 1578688122760, "ltp": 1.62, "tv": 8.66, "trd": NaN, "batb": [[1, 1.51, 83.34]], "batl": NaN}, {"timestamp": 1578697352006, "ltp": 1.62, "tv": 8.66, "trd": [[1.62, 8.67]], "batb": NaN, "batl": NaN}, {"timestamp": 1578697354597, "ltp": 1.62, "tv": 8.66, "trd": NaN, "batb": [[2, 1.5, 10.1]], "batl": NaN}, {"timestamp": 1578697655712, "ltp": 1.62, "tv": 8.66, "trd": NaN, "batb": [[2, 1.3, 150]], "batl": NaN}, {"timestamp": 1578697732993, "ltp": 1.62, "tv": 8.66, "trd": NaN, "batb": [[1, 1.51, 93.24]], "batl": NaN}, {"timestamp": 1578701597728, "ltp": 1.56, "tv": 15.0, "trd": [[1.56, 6.34]], "batb": NaN, "batl": NaN}, {"timestamp": 1578702139996, "ltp": 1.56, "tv": 20.61, "trd": [[1.56, 11.95]], "batb": NaN, "batl": NaN}, {"timestamp": 1578707101986, "ltp": 1.56, "tv": 20.61, "trd": NaN, "batb": [[1, 1.51, 88.48]], "batl": NaN}, {"timestamp": 1578707226665, "ltp": 1.56, "tv": 20.61, "trd": NaN, "batb": [[1, 1.51, 78.58]], "batl": NaN}, {"timestamp": 1578707301798, "ltp": 1.56, "tv": 20.61, "trd": NaN, "batb": [[1, 1.52, 9.71], [2, 1.51, 78.58]], "batl": NaN}, {"timestamp": 1578707824879, "ltp": 1.56, "tv": 20.61, "trd": NaN, "batb": [[2, 1.49, 81.78]], "batl": NaN}, {"timestamp": 1578710316012, "ltp": 1.56, "tv": 20.61, "trd": NaN, "batb": [[2, 1.51, 78.58]], "batl": NaN}, {"timestamp": 1578715629676, "ltp": 1.56, "tv": 20.61, "trd": NaN, "batb": NaN, "batl": [[1, 1000, 1.87]]}, {"timestamp": 1578715637098, "ltp": 1.56, "tv": 20.61, "trd": NaN, "batb": NaN, "batl": [[1, 1000, 2.43]]}, {"timestamp": 1578715648701, "ltp": 1.56, "tv": 21.17, "trd": [[1.56, 12.51]], "batb": NaN, "batl": [[1, 1000, 1.87]]}, {"timestamp": 1578716913905, "ltp": 1.56, "tv": 21.17, "trd": NaN, "batb": [[0, 1.56, 7.47], [1, 1.53, 377.33], [2, 1.52, 9.71]], "batl": NaN}, {"timestamp": 1578716927923, "ltp": 1.56, "tv": 21.17, "trd": NaN, "batb": [[1, 1.55, 363.39]], "batl": NaN}, {"timestamp": 1578719299696, "ltp": 1.56, "tv": 21.17, "trd": NaN, "batb": [[0, 1.55, 363.39], [1, 1.52, 9.71], [2, 1.51, 78.58]], "batl": NaN}, {"timestamp": 1578721258676, "ltp": 1.56, "tv": 21.17, "trd": NaN, "batb": NaN, "batl": [[0, 1.61, 3.83], [1, 1.65, 199.9], [2, 1000, 1.87]]}, {"timestamp": 1578721828984, "ltp": 1.56, "tv": 21.17, "trd": NaN, "batb": NaN, "batl": [[1, 1.64, 199.93]]}, {"timestamp": 1578722648930, "ltp": 1.56, "tv": 21.17, "trd": NaN, "batb": NaN, "batl": [[1, 1.65, 199.9]]}, {"timestamp": 1578722659962, "ltp": 1.56, "tv": 21.17, "trd": NaN, "batb": NaN, "batl": [[1, 1.64, 199.93]]}, {"timestamp": 1578722662801, "ltp": 1.56, "tv": 21.17, "trd": NaN, "batb": NaN, "batl": [[1, 1.65, 199.9]]}, {"timestamp": 1578722664462, "ltp": 1.56, "tv": 21.17, "trd": NaN, "batb": NaN, "batl": [[1, 1.64, 199.93]]}, {"timestamp": 1578722665960, "ltp": 1.56, "tv": 21.17, "trd": NaN, "batb": NaN, "batl": [[1, 1.65, 199.9]]}, {"timestamp": 1578722666683, "ltp": 1.56, "tv": 21.17, "trd": NaN, "batb": NaN, "batl": [[1, 1.64, 199.93]]}, {"timestamp": 1578725196937, "ltp": 1.56, "tv": 21.17, "trd": NaN, "batb": NaN, "batl": [[1, 1.65, 199.9]]}, {"timestamp": 1578725471989, "ltp": 1.56, "tv": 21.17, "trd": NaN, "batb": NaN, "batl": [[1, 1.64, 199.93]]}, {"timestamp": 1578728626510, "ltp": 1.56, "tv": 21.17, "trd": NaN, "batb": [[1, 1.51, 78.58], [2, 1.3, 150]], "batl": NaN}, {"timestamp": 1578728698880, "ltp": 1.56, "tv": 21.17, "trd": NaN, "batb": [[1, 1.51, 88.48]], "batl": NaN}, {"timestamp": 1578728714038, "ltp": 1.56, "tv": 21.17, "trd": NaN, "batb": [[0, 1.56, 17.86], [1, 1.55, 363.39], [2, 1.51, 88.48]], "batl": NaN}, {"timestamp": 1578728717025, "ltp": 1.56, "tv": 21.17, "trd": NaN, "batb": [[1, 1.54, 370.12]], "batl": NaN}, {"timestamp": 1578728844857, "ltp": 1.56, "tv": 21.17, "trd": NaN, "batb": [[2, 1.51, 78.58]], "batl": NaN}, {"timestamp": 1578728917044, "ltp": 1.56, "tv": 21.17, "trd": NaN, "batb": [[2, 1.52, 9.71]], "batl": NaN}, {"timestamp": 1578729065045, "ltp": 1.56, "tv": 21.17, "trd": NaN, "batb": [[2, 1.51, 78.58]], "batl": NaN}, {"timestamp": 1578729209056, "ltp": 1.56, "tv": 21.17, "trd": NaN, "batb": [[2, 1.52, 9.71]], "batl": NaN}, {"timestamp": 1578729376020, "ltp": 1.56, "tv": 21.17, "trd": NaN, "batb": [[1, 1.55, 363.39]], "batl": NaN}, {"timestamp": 1578729499249, "ltp": 1.56, "tv": 21.17, "trd": NaN, "batb": [[2, 1.51, 78.58]], "batl": NaN}, {"timestamp": 1578729572242, "ltp": 1.56, "tv": 21.17, "trd": NaN, "batb": [[2, 1.51, 88.48]], "batl": NaN}, {"timestamp": 1578729717965, "ltp": 1.56, "tv": 21.17, "trd": NaN, "batb": [[2, 1.51, 78.58]], "batl": NaN}, {"timestamp": 1578729862768, "ltp": 1.56, "tv": 21.17, "trd": NaN, "batb": [[2, 1.51, 88.48]], "batl": NaN}, {"timestamp": 1578730103970, "ltp": 1.56, "tv": 21.17, "trd": NaN, "batb": [[1, 1.51, 88.48], [2, 1.3, 150]], "batl": [[1, 1000, 1.87], [2, 1000, 0]]}, {"timestamp": 1578730234970, "ltp": 1.61, "tv": 25.0, "trd": [[1.61, 3.83]], "batb": NaN, "batl": [[0, 1000, 1.87], [1, 1000, 0]]}, {"timestamp": 1578731058988, "ltp": 1.61, "tv": 25.0, "trd": NaN, "batb": NaN, "batl": [[0, 1.71, 199.81], [1, 1000, 1.87]]}, {"timestamp": 1578731481799, "ltp": 1.61, "tv": 25.0, "trd": NaN, "batb": [[1, 1.55, 363.39], [2, 1.51, 88.48]], "batl": NaN}, {"timestamp": 1578732154279, "ltp": 1.61, "tv": 25.0, "trd": NaN, "batb": [[1, 1.54, 370.12]], "batl": NaN}, {"timestamp": 1578732300946, "ltp": 1.61, "tv": 25.0, "trd": NaN, "batb": [[0, 1.57, 5.83], [1, 1.56, 17.86], [2, 1.54, 370.12]], "batl": NaN}, {"timestamp": 1578732303035, "ltp": 1.61, "tv": 25.0, "trd": NaN, "batb": [[0, 1.57, 23.37], [1, 1.54, 370.12], [2, 1.51, 88.48]], "batl": NaN}, {"timestamp": 1578732794933, "ltp": 1.61, "tv": 25.0, "trd": NaN, "batb": [[1, 1.55, 363.39]], "batl": NaN}, {"timestamp": 1578733116043, "ltp": 1.61, "tv": 25.0, "trd": NaN, "batb": [[1, 1.51, 88.48], [2, 1.3, 150]], "batl": NaN}, {"timestamp": 1578733122464, "ltp": 1.61, "tv": 25.0, "trd": NaN, "batb": [[1, 1.54, 370.12], [2, 1.51, 88.48]], "batl": NaN}, {"timestamp": 1578733232019, "ltp": 1.61, "tv": 25.0, "trd": NaN, "batb": [[1, 1.54, 444.33]], "batl": NaN}, {"timestamp": 1578733233053, "ltp": 1.61, "tv": 25.0, "trd": NaN, "batb": [[2, 1.51, 9.9]], "batl": NaN}, {"timestamp": 1578733624993, "ltp": 1.61, "tv": 25.0, "trd": NaN, "batb": NaN, "batl": [[0, 1.7, 199.75]]}, {"timestamp": 1578734472854, "ltp": 1.61, "tv": 25.0, "trd": NaN, "batb": [[2, 1.3, 150]], "batl": NaN}, {"timestamp": 1578734519008, "ltp": 1.57, "tv": 48.37, "trd": [[1.57, 23.37]], "batb": [[0, 1.57, 11.33]], "batl": NaN}, {"timestamp": 1578734519322, "ltp": 1.57, "tv": 48.37, "trd": NaN, "batb": [[0, 1.54, 444.33], [1, 1.3, 150], [2, 1.29, 150]], "batl": NaN}, {"timestamp": 1578734534744, "ltp": 1.57, "tv": 48.37, "trd": NaN, "batb": [[0, 1.56, 17.86], [1, 1.54, 444.33], [2, 1.3, 150]], "batl": NaN}, {"timestamp": 1578734552141, "ltp": 1.57, "tv": 48.37, "trd": NaN, "batb": [[2, 1.52, 9.71]], "batl": NaN}, {"timestamp": 1578734945995, "ltp": 1.57, "tv": 48.37, "trd": NaN, "batb": [[1, 1.55, 363.39], [2, 1.54, 444.33]], "batl": NaN}, {"timestamp": 1578734946989, "ltp": 1.57, "tv": 48.37, "trd": NaN, "batb": [[1, 1.54, 74.21], [2, 1.52, 9.71]], "batl": NaN}, {"timestamp": 1578734951868, "ltp": 1.57, "tv": 48.37, "trd": NaN, "batb": [[1, 1.54, 444.33]], "batl": NaN}, {"timestamp": 1578734963991, "ltp": 1.57, "tv": 48.37, "trd": NaN, "batb": [[1, 1.55, 363.39], [2, 1.54, 74.21]], "batl": NaN}, {"timestamp": 1578734980962, "ltp": 1.57, "tv": 48.37, "trd": NaN, "batb": [[0, 1.57, 7.43], [1, 1.56, 17.86], [2, 1.55, 363.39]], "batl": NaN}, {"timestamp": 1578734986747, "ltp": 1.57, "tv": 48.37, "trd": NaN, "batb": [[0, 1.57, 20.55], [1, 1.55, 363.39], [2, 1.54, 74.21]], "batl": NaN}, {"timestamp": 1578736445626, "ltp": 1.57, "tv": 48.37, "trd": NaN, "batb": [[0, 1.57, 35.76]], "batl": [[0, 1.64, 8.51], [1, 1.7, 199.75], [2, 1000, 1.87]]}, {"timestamp": 1578736451051, "ltp": 1.57, "tv": 48.37, "trd": NaN, "batb": NaN, "batl": [[0, 1.64, 208.44], [1, 1000, 1.87], [2, 1000, 0]]}, {"timestamp": 1578736451936, "ltp": 1.57, "tv": 48.37, "trd": NaN, "batb": NaN, "batl": [[0, 1.64, 199.93]]}, {"timestamp": 1578736475895, "ltp": 1.57, "tv": 48.37, "trd": NaN, "batb": NaN, "batl": [[0, 1.62, 8.51], [1, 1.64, 199.93], [2, 1000, 1.87]]}, {"timestamp": 1578736646025, "ltp": 1.57, "tv": 48.37, "trd": NaN, "batb": [[1, 1.54, 444.33], [2, 1.51, 9.9]], "batl": NaN}, {"timestamp": 1578736647699, "ltp": 1.57, "tv": 48.37, "trd": NaN, "batb": [[0, 1.57, 20.55], [1, 1.56, 15.47], [2, 1.54, 444.33]], "batl": NaN}, {"timestamp": 1578736834053, "ltp": 1.57, "tv": 48.37, "trd": NaN, "batb": [[2, 1.55, 72.86]], "batl": NaN}, {"timestamp": 1578737247928, "ltp": 1.62, "tv": 56.4, "trd": [[1.62, 16.69]], "batb": NaN, "batl": [[0, 1.64, 200.42], [1, 1000, 1.87], [2, 1000, 0]]}, {"timestamp": 1578737296009, "ltp": 1.62, "tv": 56.4, "trd": NaN, "batb": [[2, 1.54, 444.33]], "batl": NaN}, {"timestamp": 1578737503797, "ltp": 1.62, "tv": 56.88, "trd": [[1.62, 17.18]], "batb": NaN, "batl": [[0, 1.64, 199.93]]}, {"timestamp": 1578737581035, "ltp": 1.62, "tv": 56.88, "trd": NaN, "batb": [[1, 1.56, 30.95]], "batl": NaN}, {"timestamp": 1578737904992, "ltp": 1.62, "tv": 56.88, "trd": NaN, "batb": [[0, 1.57, 13.12]], "batl": NaN}, {"timestamp": 1578737942040, "ltp": 1.62, "tv": 56.88, "trd": NaN, "batb": [[2, 1.55, 363.39]], "batl": NaN}, {"timestamp": 1578738026031, "ltp": 1.62, "tv": 56.88, "trd": NaN, "batb": [[2, 1.54, 444.33]], "batl": NaN}, {"timestamp": 1578740148998, "ltp": 1.62, "tv": 56.88, "trd": NaN, "batb": [[2, 1.54, 74.21]], "batl": [[0, 1000, 1.87], [1, 1000, 0]]}, {"timestamp": 1578740210041, "ltp": 1.62, "tv": 56.88, "trd": NaN, "batb": NaN, "batl": [[0, 1.71, 199.81], [1, 1000, 1.87]]}, {"timestamp": 1578740287000, "ltp": 1.62, "tv": 56.88, "trd": NaN, "batb": NaN, "batl": [[0, 1.7, 199.75]]}, {"timestamp": 1578740341621, "ltp": 1.62, "tv": 56.88, "trd": NaN, "batb": [[0, 1.56, 30.95], [1, 1.54, 74.21], [2, 1.51, 9.9]], "batl": NaN}, {"timestamp": 1578740343043, "ltp": 1.62, "tv": 56.88, "trd": NaN, "batb": [[0, 1.56, 38.04]], "batl": [[1, 100, 1.87], [2, 1000, 1.87]]}, {"timestamp": 1578740350729, "ltp": 1.62, "tv": 56.88, "trd": NaN, "batb": NaN, "batl": [[1, 100, 2.8]]}, {"timestamp": 1578740357824, "ltp": 1.62, "tv": 56.88, "trd": NaN, "batb": NaN, "batl": [[1, 1000, 2.8], [2, 1000, 0]]}, {"timestamp": 1578740368024, "ltp": 1.56, "tv": 58.75, "trd": [[1.56, 14.38]], "batb": [[0, 1.56, 37.1]], "batl": [[1, 1000, 1.87]]}, {"timestamp": 1578740400988, "ltp": 1.56, "tv": 58.75, "trd": NaN, "batb": [[1, 1.54, 444.33]], "batl": NaN}, {"timestamp": 1578740413825, "ltp": 1.56, "tv": 58.75, "trd": NaN, "batb": [[2, 1.3, 150]], "batl": NaN}, {"timestamp": 1578740490912, "ltp": 1.56, "tv": 58.75, "trd": NaN, "batb": [[2, 1.49, 10.31]], "batl": NaN}, {"timestamp": 1578740877865, "ltp": 1.56, "tv": 58.75, "trd": NaN, "batb": [[0, 1.57, 6.46], [1, 1.56, 37.1], [2, 1.54, 444.33]], "batl": NaN}, {"timestamp": 1578741066011, "ltp": 1.57, "tv": 64.26, "trd": [[1.57, 28.89]], "batb": [[0, 1.56, 38.05], [1, 1.54, 74.21], [2, 1.53, 377.33]], "batl": [[0, 1.69, 199.79]]}, {"timestamp": 1578741066950, "ltp": 1.57, "tv": 64.26, "trd": NaN, "batb": [[2, 1.49, 10.31]], "batl": NaN}, {"timestamp": 1578741069948, "ltp": 1.56, "tv": 102.32, "trd": [[1.56, 51.48], [1.57, 29.84]], "batb": [[0, 1.54, 74.21], [1, 1.49, 10.31], [2, 1.3, 150]], "batl": NaN}, {"timestamp": 1578741073848, "ltp": 1.56, "tv": 102.32, "trd": NaN, "batb": [[0, 1.54, 92.73]], "batl": NaN}, {"timestamp": 1578741077077, "ltp": 1.56, "tv": 102.32, "trd": NaN, "batb": NaN, "batl": [[0, 1.62, 21.29], [1, 1.69, 199.79], [2, 1000, 1.87]]}, {"timestamp": 1578741085964, "ltp": 1.56, "tv": 102.32, "trd": NaN, "batb": NaN, "batl": [[0, 1.61, 199.91], [1, 1.62, 21.29]]}, {"timestamp": 1578741088053, "ltp": 1.56, "tv": 102.32, "trd": NaN, "batb": NaN, "batl": [[1, 1000, 1.87], [2, 1000, 0]]}, {"timestamp": 1578741096006, "ltp": 1.56, "tv": 102.32, "trd": NaN, "batb": [[1, 1.52, 384.49], [2, 1.49, 10.31]], "batl": NaN}, {"timestamp": 1578741105936, "ltp": 1.56, "tv": 102.32, "trd": NaN, "batb": NaN, "batl": [[0, 1.59, 21.7], [1, 1.61, 199.91], [2, 1000, 1.87]]}, {"timestamp": 1578741139869, "ltp": 1.56, "tv": 102.32, "trd": NaN, "batb": [[0, 1.54, 18.52], [1, 1.53, 75.61], [2, 1.52, 384.49]], "batl": NaN}, {"timestamp": 1578741301410, "ltp": 1.56, "tv": 102.32, "trd": NaN, "batb": NaN, "batl": [[0, 1.59, 30.21]]}, {"timestamp": 1578741419982, "ltp": 1.56, "tv": 102.32, "trd": NaN, "batb": [[2, 1.51, 391.99]], "batl": [[1, 1.6, 199.76]]}, {"timestamp": 1578742268783, "ltp": 1.56, "tv": 102.32, "trd": NaN, "batb": [[2, 1.52, 384.49]], "batl": [[1, 1.61, 199.91]]}, {"timestamp": 1578742287954, "ltp": 1.56, "tv": 102.32, "trd": NaN, "batb": [[2, 1.51, 391.99]], "batl": [[1, 1.6, 199.76]]}, {"timestamp": 1578742294962, "ltp": 1.54, "tv": 120.65, "trd": [[1.54, 18.16], [1.58, 0.17]], "batb": [[0, 1.54, 9.44]], "batl": NaN}, {"timestamp": 1578742297761, "ltp": 1.54, "tv": 120.65, "trd": NaN, "batb": [[2, 1.5, 400]], "batl": [[0, 1.59, 230.1], [1, 1000, 1.87], [2, 1000, 0]]}, {"timestamp": 1578742298889, "ltp": 1.54, "tv": 129.67, "trd": [[1.54, 27.18]], "batb": [[0, 1.54, 4.93]], "batl": NaN}, {"timestamp": 1578742303040, "ltp": 1.54, "tv": 129.67, "trd": NaN, "batb": [[0, 1.53, 75.61], [1, 1.5, 400], [2, 1.49, 10.31]], "batl": NaN}, {"timestamp": 1578742314978, "ltp": 1.54, "tv": 129.67, "trd": NaN, "batb": [[0, 1.52, 77.07]], "batl": NaN}, {"timestamp": 1578742374931, "ltp": 1.54, "tv": 129.67, "trd": NaN, "batb": [[0, 1.52, 461.56], [1, 1.49, 10.31], [2, 1.3, 150]], "batl": NaN}, {"timestamp": 1578742387970, "ltp": 1.54, "tv": 129.67, "trd": NaN, "batb": [[1, 1.3, 150], [2, 1.29, 150]], "batl": NaN}, {"timestamp": 1578742462917, "ltp": 1.54, "tv": 129.67, "trd": NaN, "batb": [[1, 1.47, 10.74], [2, 1.3, 150]], "batl": NaN}, {"timestamp": 1578743103962, "ltp": 1.54, "tv": 129.67, "trd": NaN, "batb": [[0, 1.52, 442.87]], "batl": NaN}, {"timestamp": 1578743547319, "ltp": 1.53, "tv": 136.73, "trd": [[1.53, 7.06]], "batb": NaN, "batl": NaN}, {"timestamp": 1578743949949, "ltp": 1.53, "tv": 136.73, "trd": NaN, "batb": NaN, "batl": [[0, 1.59, 199.89]]}, {"timestamp": 1578744061038, "ltp": 1.53, "tv": 136.73, "trd": NaN, "batb": NaN, "batl": [[0, 1.57, 30.48], [1, 1.59, 199.89], [2, 1000, 1.87]]}, {"timestamp": 1578744093585, "ltp": 1.53, "tv": 136.73, "trd": NaN, "batb": NaN, "batl": [[1, 1.61, 199.91]]}, {"timestamp": 1578744104979, "ltp": 1.53, "tv": 136.73, "trd": NaN, "batb": NaN, "batl": [[0, 1.61, 199.91], [1, 1000, 1.87], [2, 1000, 0]]}, {"timestamp": 1578744105191, "ltp": 1.53, "tv": 136.73, "trd": NaN, "batb": NaN, "batl": [[0, 1.59, 21.7], [1, 1.61, 199.91], [2, 1000, 1.87]]}, {"timestamp": 1578744120202, "ltp": 1.53, "tv": 136.73, "trd": NaN, "batb": NaN, "batl": [[0, 1.59, 30.21]]}, {"timestamp": 1578744316027, "ltp": 1.53, "tv": 136.73, "trd": NaN, "batb": NaN, "batl": [[1, 1.6, 199.76]]}, {"timestamp": 1578746295045, "ltp": 1.53, "tv": 136.73, "trd": NaN, "batb": NaN, "batl": [[1, 1.61, 199.91]]}, {"timestamp": 1578746517027, "ltp": 1.53, "tv": 136.73, "trd": NaN, "batb": NaN, "batl": [[1, 1000, 1.87], [2, 1000, 0]]}, {"timestamp": 1578746547041, "ltp": 1.53, "tv": 136.73, "trd": NaN, "batb": NaN, "batl": [[0, 1.59, 230.1]]}, {"timestamp": 1578746550010, "ltp": 1.53, "tv": 136.73, "trd": NaN, "batb": NaN, "batl": [[0, 1.59, 199.89]]}, {"timestamp": 1578746551014, "ltp": 1.53, "tv": 136.73, "trd": NaN, "batb": NaN, "batl": [[0, 1.57, 21.97], [1, 1.59, 199.89], [2, 1000, 1.87]]}, {"timestamp": 1578746641737, "ltp": 1.53, "tv": 136.73, "trd": NaN, "batb": NaN, "batl": [[0, 1.57, 30.48]]}, {"timestamp": 1578747163037, "ltp": 1.53, "tv": 136.73, "trd": NaN, "batb": NaN, "batl": [[1, 1.6, 199.76]]}, {"timestamp": 1578747163919, "ltp": 1.53, "tv": 136.73, "trd": NaN, "batb": NaN, "batl": [[1, 1000, 1.87], [2, 1000, 0]]}, {"timestamp": 1578747166499, "ltp": 1.53, "tv": 136.73, "trd": NaN, "batb": NaN, "batl": [[0, 1.58, 21.83]]}, {"timestamp": 1578747179006, "ltp": 1.53, "tv": 136.73, "trd": NaN, "batb": NaN, "batl": [[1, 1.6, 199.76], [2, 1000, 1.87]]}, {"timestamp": 1578747180835, "ltp": 1.53, "tv": 136.73, "trd": NaN, "batb": NaN, "batl": [[0, 1.58, 30.35]]}, {"timestamp": 1578748077007, "ltp": 1.53, "tv": 136.73, "trd": NaN, "batb": NaN, "batl": [[1, 1.61, 199.91]]}, {"timestamp": 1578748090023, "ltp": 1.53, "tv": 136.73, "trd": NaN, "batb": NaN, "batl": [[0, 1.61, 199.91], [1, 1000, 1.87], [2, 1000, 0]]}, {"timestamp": 1578748090127, "ltp": 1.53, "tv": 136.73, "trd": NaN, "batb": NaN, "batl": [[0, 1.59, 21.7], [1, 1.61, 199.91], [2, 1000, 1.87]]}, {"timestamp": 1578748261812, "ltp": 1.53, "tv": 136.73, "trd": NaN, "batb": NaN, "batl": [[0, 1.59, 30.21]]}, {"timestamp": 1578748328892, "ltp": 1.53, "tv": 136.73, "trd": NaN, "batb": [[0, 1.52, 384.49], [1, 1.5, 60.72], [2, 1.47, 10.74]], "batl": NaN}, {"timestamp": 1578748366070, "ltp": 1.53, "tv": 136.73, "trd": NaN, "batb": [[2, 1.3, 150]], "batl": NaN}, {"timestamp": 1578748427157, "ltp": 1.53, "tv": 136.73, "trd": NaN, "batb": [[2, 1.46, 10.98]], "batl": NaN}, {"timestamp": 1578748548881, "ltp": 1.53, "tv": 136.73, "trd": NaN, "batb": [[2, 1.3, 150]], "batl": NaN}, {"timestamp": 1578748609600, "ltp": 1.53, "tv": 136.73, "trd": NaN, "batb": [[2, 1.47, 10.74]], "batl": NaN}, {"timestamp": 1578748732865, "ltp": 1.53, "tv": 136.73, "trd": NaN, "batb": NaN, "batl": [[1, 1000, 1.87], [2, 1000, 0]]}, {"timestamp": 1578748753993, "ltp": 1.53, "tv": 136.73, "trd": NaN, "batb": NaN, "batl": [[1, 1.61, 199.91], [2, 1000, 1.87]]}, {"timestamp": 1578748975829, "ltp": 1.53, "tv": 136.73, "trd": NaN, "batb": NaN, "batl": [[0, 1.59, 230.1], [1, 1000, 1.87], [2, 1000, 0]]}, {"timestamp": 1578748977914, "ltp": 1.53, "tv": 136.73, "trd": NaN, "batb": NaN, "batl": [[0, 1.57, 21.97], [1, 1.59, 199.89], [2, 1000, 1.87]]}, {"timestamp": 1578748981048, "ltp": 1.53, "tv": 136.73, "trd": NaN, "batb": NaN, "batl": [[0, 1.57, 30.48]]}, {"timestamp": 1578749409944, "ltp": 1.53, "tv": 136.73, "trd": NaN, "batb": NaN, "batl": [[1, 1.61, 199.91]]}, {"timestamp": 1578749426030, "ltp": 1.53, "tv": 136.73, "trd": NaN, "batb": NaN, "batl": [[0, 1.61, 199.91], [1, 1000, 1.87], [2, 1000, 0]]}, {"timestamp": 1578749426625, "ltp": 1.53, "tv": 136.73, "trd": NaN, "batb": NaN, "batl": [[0, 1.59, 21.7], [1, 1.61, 199.91], [2, 1000, 1.87]]}, {"timestamp": 1578749442768, "ltp": 1.53, "tv": 136.73, "trd": NaN, "batb": NaN, "batl": [[0, 1.59, 221.59], [1, 1000, 1.87], [2, 1000, 0]]}, {"timestamp": 1578749445548, "ltp": 1.53, "tv": 136.73, "trd": NaN, "batb": NaN, "batl": [[0, 1.57, 21.97], [1, 1.59, 199.89], [2, 1000, 1.87]]}, {"timestamp": 1578749464798, "ltp": 1.53, "tv": 136.73, "trd": NaN, "batb": NaN, "batl": [[0, 1.57, 30.48]]}, {"timestamp": 1578749845964, "ltp": 1.53, "tv": 136.73, "trd": NaN, "batb": NaN, "batl": [[1, 1.61, 199.91]]}, {"timestamp": 1578749860883, "ltp": 1.53, "tv": 136.73, "trd": NaN, "batb": NaN, "batl": [[0, 1.59, 30.21]]}, {"timestamp": 1578749925833, "ltp": 1.53, "tv": 136.73, "trd": NaN, "batb": NaN, "batl": [[0, 1.59, 230.1], [1, 1000, 1.87], [2, 1000, 0]]}, {"timestamp": 1578749928740, "ltp": 1.53, "tv": 136.73, "trd": NaN, "batb": NaN, "batl": [[0, 1.57, 21.97], [1, 1.59, 199.89], [2, 1000, 1.87]]}, {"timestamp": 1578749940970, "ltp": 1.53, "tv": 136.73, "trd": NaN, "batb": NaN, "batl": [[0, 1.57, 30.48]]}, {"timestamp": 1578750250978, "ltp": 1.53, "tv": 136.73, "trd": NaN, "batb": [[2, 1.3, 150]], "batl": NaN}, {"timestamp": 1578750310956, "ltp": 1.53, "tv": 136.73, "trd": NaN, "batb": [[2, 1.46, 10.98]], "batl": NaN}, {"timestamp": 1578750686875, "ltp": 1.57, "tv": 153.82, "trd": [[1.57, 46.93]], "batb": NaN, "batl": [[0, 1.57, 13.39]]}, {"timestamp": 1578750817032, "ltp": 1.57, "tv": 153.82, "trd": NaN, "batb": NaN, "batl": [[1, 1.6, 199.76]]}, {"timestamp": 1578750837045, "ltp": 1.57, "tv": 153.82, "trd": NaN, "batb": NaN, "batl": [[0, 1.56, 155.53], [1, 1.57, 13.39], [2, 1.6, 199.76]]}, {"timestamp": 1578750838735, "ltp": 1.57, "tv": 153.82, "trd": NaN, "batb": NaN, "batl": [[0, 1.55, 4.94], [1, 1.56, 155.53]]}, {"timestamp": 1578750839142, "ltp": 1.55, "tv": 157.97, "trd": [[1.55, 4.16]], "batb": NaN, "batl": [[0, 1.55, 2.86]]}, {"timestamp": 1578750961823, "ltp": 1.55, "tv": 157.97, "trd": NaN, "batb": NaN, "batl": [[0, 1.55, 11.37]]}, {"timestamp": 1578752438967, "ltp": 1.55, "tv": 157.97, "trd": NaN, "batb": NaN, "batl": [[2, 1.59, 199.89]]}, {"timestamp": 1578753158898, "ltp": 1.55, "tv": 157.97, "trd": NaN, "batb": NaN, "batl": [[2, 1.6, 199.76]]}, {"timestamp": 1578753364028, "ltp": 1.55, "tv": 157.97, "trd": NaN, "batb": NaN, "batl": [[2, 1.61, 199.91]]}, {"timestamp": 1578753423894, "ltp": 1.55, "tv": 157.97, "trd": NaN, "batb": NaN, "batl": [[2, 1.6, 199.76]]}, {"timestamp": 1578754142717, "ltp": 1.55, "tv": 157.97, "trd": NaN, "batb": [[1, 1.49, 61.96]], "batl": NaN}, {"timestamp": 1578754834805, "ltp": 1.55, "tv": 157.97, "trd": NaN, "batb": [[0, 1.54, 45], [1, 1.53, 45], [2, 1.52, 429.49]], "batl": [[0, 1.55, 56.37], [1, 1.56, 200.53], [2, 1.57, 45]]}, {"timestamp": 1578754835572, "ltp": 1.55, "tv": 157.97, "trd": NaN, "batb": NaN, "batl": [[1, 1.56, 45]]}, {"timestamp": 1578754909992, "ltp": 1.55, "tv": 157.97, "trd": NaN, "batb": [[2, 1.52, 45]], "batl": NaN}, {"timestamp": 1578755149001, "ltp": 1.55, "tv": 157.97, "trd": NaN, "batb": [[2, 1.52, 429.49]], "batl": NaN}, {"timestamp": 1578755229753, "ltp": 1.55, "tv": 167.01, "trd": [[1.55, 13.19]], "batb": NaN, "batl": [[0, 1.55, 47.34]]}, {"timestamp": 1578755232541, "ltp": 1.55, "tv": 167.01, "trd": NaN, "batb": [[0, 1.54, 61.06]], "batl": NaN}, {"timestamp": 1578755375799, "ltp": 1.55, "tv": 167.01, "trd": NaN, "batb": [[2, 1.52, 45]], "batl": NaN}, {"timestamp": 1578755765026, "ltp": 1.54, "tv": 212.03, "trd": [[1.54, 72.2]], "batb": [[0, 1.54, 38.55]], "batl": NaN}, {"timestamp": 1578755769746, "ltp": 1.54, "tv": 212.03, "trd": NaN, "batb": [[0, 1.54, 22.49], [1, 1.53, 54.4]], "batl": NaN}, {"timestamp": 1578755779381, "ltp": 1.54, "tv": 212.03, "trd": NaN, "batb": [[1, 1.53, 45]], "batl": NaN}, {"timestamp": 1578757470987, "ltp": 1.54, "tv": 212.03, "trd": NaN, "batb": [[2, 1.52, 429.49]], "batl": NaN}, {"timestamp": 1578757474308, "ltp": 1.54, "tv": 212.03, "trd": NaN, "batb": [[0, 1.54, 38.55]], "batl": NaN}, {"timestamp": 1578758010461, "ltp": 1.54, "tv": 212.03, "trd": NaN, "batb": [[0, 1.54, 43.22]], "batl": NaN}, {"timestamp": 1578758278009, "ltp": 1.53, "tv": 360.43, "trd": [[1.53, 69.01], [1.54, 158.65]], "batb": [[0, 1.53, 14.02], [1, 1.52, 429.49], [2, 1.51, 12.98]], "batl": [[0, 1.55, 86.83]]}, {"timestamp": 1578758315748, "ltp": 1.53, "tv": 360.43, "trd": NaN, "batb": NaN, "batl": [[0, 1.54, 117.51], [1, 1.55, 86.83], [2, 1.56, 45]]}, {"timestamp": 1578758317924, "ltp": 1.54, "tv": 496.63, "trd": [[1.54, 294.85]], "batb": NaN, "batl": [[0, 1.54, 125.39], [1, 1.55, 47.34]]}, {"timestamp": 1578758335785, "ltp": 1.54, "tv": 496.63, "trd": NaN, "batb": [[2, 1.51, 57.98]], "batl": NaN}, {"timestamp": 1578758385443, "ltp": 1.54, "tv": 496.63, "trd": NaN, "batb": NaN, "batl": [[0, 1.54, 230.08]]}, {"timestamp": 1578758399884, "ltp": 1.54, "tv": 580.35, "trd": [[1.54, 378.57]], "batb": NaN, "batl": [[0, 1.54, 188.22]]}, {"timestamp": 1578758663934, "ltp": 1.54, "tv": 580.35, "trd": NaN, "batb": [[1, 1.52, 45], [2, 1.51, 449.97]], "batl": NaN}, {"timestamp": 1578758780638, "ltp": 1.54, "tv": 580.35, "trd": NaN, "batb": [[1, 1.52, 49.61], [2, 1.51, 454.62]], "batl": [[0, 1.54, 192.77], [1, 1.55, 51.87]]}, {"timestamp": 1578758925845, "ltp": 1.54, "tv": 580.35, "trd": NaN, "batb": [[1, 1.52, 434.1], [2, 1.51, 62.63]], "batl": NaN}, {"timestamp": 1578758929534, "ltp": 1.54, "tv": 580.35, "trd": NaN, "batb": [[0, 1.53, 18.61]], "batl": NaN}, {"timestamp": 1578758932345, "ltp": 1.54, "tv": 580.35, "trd": NaN, "batb": [[0, 1.53, 14.02]], "batl": NaN}, {"timestamp": 1578758933145, "ltp": 1.54, "tv": 580.35, "trd": NaN, "batb": [[0, 1.53, 18.61]], "batl": NaN}, {"timestamp": 1578758934555, "ltp": 1.54, "tv": 580.35, "trd": NaN, "batb": [[0, 1.53, 14.02]], "batl": NaN}, {"timestamp": 1578758936959, "ltp": 1.54, "tv": 580.35, "trd": NaN, "batb": [[0, 1.53, 18.61]], "batl": NaN}, {"timestamp": 1578758937680, "ltp": 1.54, "tv": 580.35, "trd": NaN, "batb": [[0, 1.53, 14.02]], "batl": NaN}, {"timestamp": 1578758942071, "ltp": 1.54, "tv": 580.35, "trd": NaN, "batb": [[0, 1.53, 18.61]], "batl": NaN}, {"timestamp": 1578758946983, "ltp": 1.54, "tv": 580.35, "trd": NaN, "batb": [[0, 1.53, 14.02]], "batl": NaN}, {"timestamp": 1578758948950, "ltp": 1.54, "tv": 580.35, "trd": NaN, "batb": [[0, 1.53, 18.61]], "batl": NaN}, {"timestamp": 1578758949890, "ltp": 1.54, "tv": 580.35, "trd": NaN, "batb": [[0, 1.53, 14.02]], "batl": NaN}, {"timestamp": 1578758950404, "ltp": 1.54, "tv": 580.35, "trd": NaN, "batb": [[0, 1.53, 18.61]], "batl": NaN}, {"timestamp": 1578758951292, "ltp": 1.54, "tv": 580.35, "trd": NaN, "batb": [[0, 1.53, 14.02]], "batl": NaN}, {"timestamp": 1578758953301, "ltp": 1.54, "tv": 580.35, "trd": NaN, "batb": [[0, 1.53, 18.61]], "batl": NaN}, {"timestamp": 1578758954948, "ltp": 1.54, "tv": 580.35, "trd": NaN, "batb": [[0, 1.53, 14.02]], "batl": NaN}, {"timestamp": 1578758955562, "ltp": 1.54, "tv": 580.35, "trd": NaN, "batb": [[0, 1.53, 18.61]], "batl": NaN}, {"timestamp": 1578758957475, "ltp": 1.54, "tv": 580.35, "trd": NaN, "batb": [[0, 1.53, 14.02]], "batl": NaN}, {"timestamp": 1578758958971, "ltp": 1.54, "tv": 580.35, "trd": NaN, "batb": [[0, 1.53, 18.61]], "batl": NaN}, {"timestamp": 1578758959455, "ltp": 1.54, "tv": 580.35, "trd": NaN, "batb": [[0, 1.53, 14.02]], "batl": NaN}, {"timestamp": 1578758960266, "ltp": 1.54, "tv": 580.35, "trd": NaN, "batb": [[0, 1.53, 18.61]], "batl": NaN}, {"timestamp": 1578758961651, "ltp": 1.54, "tv": 580.35, "trd": NaN, "batb": [[0, 1.53, 14.02]], "batl": NaN}, {"timestamp": 1578758962963, "ltp": 1.54, "tv": 580.35, "trd": NaN, "batb": [[0, 1.53, 18.61]], "batl": NaN}, {"timestamp": 1578758964977, "ltp": 1.54, "tv": 580.35, "trd": NaN, "batb": [[0, 1.53, 14.02]], "batl": NaN}, {"timestamp": 1578758967673, "ltp": 1.54, "tv": 580.35, "trd": NaN, "batb": [[0, 1.53, 18.61]], "batl": NaN}, {"timestamp": 1578758969301, "ltp": 1.54, "tv": 580.35, "trd": NaN, "batb": [[0, 1.53, 14.02]], "batl": NaN}, {"timestamp": 1578758971716, "ltp": 1.54, "tv": 580.35, "trd": NaN, "batb": [[0, 1.53, 18.61]], "batl": NaN}, {"timestamp": 1578758973167, "ltp": 1.54, "tv": 580.35, "trd": NaN, "batb": [[0, 1.53, 14.02]], "batl": NaN}, {"timestamp": 1578758974686, "ltp": 1.54, "tv": 580.35, "trd": NaN, "batb": [[0, 1.53, 18.61]], "batl": NaN}, {"timestamp": 1578758975682, "ltp": 1.54, "tv": 580.35, "trd": NaN, "batb": [[0, 1.53, 14.02]], "batl": NaN}, {"timestamp": 1578758976332, "ltp": 1.54, "tv": 580.35, "trd": NaN, "batb": [[0, 1.53, 18.61]], "batl": NaN}, {"timestamp": 1578758978886, "ltp": 1.54, "tv": 580.35, "trd": NaN, "batb": [[0, 1.53, 14.02]], "batl": NaN}, {"timestamp": 1578758979983, "ltp": 1.54, "tv": 580.35, "trd": NaN, "batb": [[0, 1.53, 18.61]], "batl": NaN}, {"timestamp": 1578758980795, "ltp": 1.54, "tv": 580.35, "trd": NaN, "batb": [[0, 1.53, 14.02]], "batl": NaN}, {"timestamp": 1578758982011, "ltp": 1.54, "tv": 580.35, "trd": NaN, "batb": [[0, 1.53, 18.61]], "batl": NaN}, {"timestamp": 1578758982622, "ltp": 1.54, "tv": 580.35, "trd": NaN, "batb": [[0, 1.53, 14.02]], "batl": NaN}, {"timestamp": 1578758983380, "ltp": 1.54, "tv": 580.35, "trd": NaN, "batb": [[0, 1.53, 18.61]], "batl": NaN}, {"timestamp": 1578758984679, "ltp": 1.54, "tv": 580.35, "trd": NaN, "batb": [[0, 1.53, 14.02]], "batl": NaN}, {"timestamp": 1578758985819, "ltp": 1.54, "tv": 580.35, "trd": NaN, "batb": [[0, 1.53, 18.61]], "batl": NaN}, {"timestamp": 1578758987334, "ltp": 1.54, "tv": 580.35, "trd": NaN, "batb": [[0, 1.53, 14.02]], "batl": NaN}, {"timestamp": 1578758988815, "ltp": 1.54, "tv": 580.35, "trd": NaN, "batb": [[0, 1.53, 18.61]], "batl": NaN}, {"timestamp": 1578758989245, "ltp": 1.54, "tv": 580.35, "trd": NaN, "batb": [[0, 1.53, 14.02]], "batl": NaN}, {"timestamp": 1578758990505, "ltp": 1.54, "tv": 580.35, "trd": NaN, "batb": [[0, 1.53, 18.61]], "batl": NaN}, {"timestamp": 1578758991375, "ltp": 1.54, "tv": 580.35, "trd": NaN, "batb": [[0, 1.53, 14.02]], "batl": NaN}, {"timestamp": 1578758992584, "ltp": 1.54, "tv": 580.35, "trd": NaN, "batb": [[0, 1.53, 18.61]], "batl": NaN}, {"timestamp": 1578758993893, "ltp": 1.54, "tv": 580.35, "trd": NaN, "batb": [[0, 1.53, 14.02]], "batl": NaN}, {"timestamp": 1578758994210, "ltp": 1.54, "tv": 580.35, "trd": NaN, "batb": [[0, 1.53, 18.61]], "batl": NaN}, {"timestamp": 1578758997000, "ltp": 1.54, "tv": 580.35, "trd": NaN, "batb": [[0, 1.53, 14.02]], "batl": NaN}, {"timestamp": 1578758997603, "ltp": 1.54, "tv": 580.35, "trd": NaN, "batb": [[0, 1.53, 18.61]], "batl": NaN}, {"timestamp": 1578758999705, "ltp": 1.54, "tv": 580.35, "trd": NaN, "batb": [[0, 1.53, 14.02]], "batl": NaN}, {"timestamp": 1578759000583, "ltp": 1.54, "tv": 580.35, "trd": NaN, "batb": [[0, 1.53, 18.61]], "batl": NaN}, {"timestamp": 1578759001996, "ltp": 1.54, "tv": 580.35, "trd": NaN, "batb": [[0, 1.53, 14.02]], "batl": NaN}, {"timestamp": 1578759002983, "ltp": 1.54, "tv": 580.35, "trd": NaN, "batb": [[0, 1.53, 18.61]], "batl": NaN}, {"timestamp": 1578759004001, "ltp": 1.54, "tv": 580.35, "trd": NaN, "batb": [[0, 1.53, 14.02]], "batl": NaN}, {"timestamp": 1578759005740, "ltp": 1.54, "tv": 580.35, "trd": NaN, "batb": [[0, 1.53, 18.61]], "batl": NaN}, {"timestamp": 1578759006708, "ltp": 1.54, "tv": 580.35, "trd": NaN, "batb": [[0, 1.53, 14.02]], "batl": NaN}, {"timestamp": 1578759008905, "ltp": 1.54, "tv": 580.35, "trd": NaN, "batb": [[0, 1.53, 18.61]], "batl": NaN}, {"timestamp": 1578759009924, "ltp": 1.54, "tv": 580.35, "trd": NaN, "batb": [[0, 1.53, 14.02]], "batl": NaN}, {"timestamp": 1578759012012, "ltp": 1.54, "tv": 580.35, "trd": NaN, "batb": [[0, 1.53, 18.61]], "batl": NaN}, {"timestamp": 1578759012679, "ltp": 1.54, "tv": 580.35, "trd": NaN, "batb": [[0, 1.53, 14.02]], "batl": NaN}, {"timestamp": 1578759014602, "ltp": 1.54, "tv": 580.35, "trd": NaN, "batb": [[0, 1.53, 18.61]], "batl": NaN}, {"timestamp": 1578759015801, "ltp": 1.54, "tv": 580.35, "trd": NaN, "batb": [[0, 1.53, 14.02]], "batl": NaN}, {"timestamp": 1578759017254, "ltp": 1.54, "tv": 580.35, "trd": NaN, "batb": [[0, 1.53, 18.61]], "batl": NaN}, {"timestamp": 1578759018612, "ltp": 1.54, "tv": 580.35, "trd": NaN, "batb": [[0, 1.53, 14.02]], "batl": NaN}, {"timestamp": 1578759020527, "ltp": 1.54, "tv": 580.35, "trd": NaN, "batb": [[0, 1.53, 18.61]], "batl": NaN}, {"timestamp": 1578759021832, "ltp": 1.54, "tv": 580.35, "trd": NaN, "batb": [[0, 1.53, 14.02]], "batl": NaN}, {"timestamp": 1578759022548, "ltp": 1.54, "tv": 580.35, "trd": NaN, "batb": [[0, 1.53, 18.61]], "batl": NaN}, {"timestamp": 1578759023921, "ltp": 1.54, "tv": 773.12, "trd": [[1.54, 571.34]], "batb": [[0, 1.53, 14.02]], "batl": [[0, 1.55, 51.87], [1, 1.56, 45], [2, 1.57, 45]]}, {"timestamp": 1578759025019, "ltp": 1.54, "tv": 773.12, "trd": NaN, "batb": [[0, 1.53, 18.62]], "batl": [[0, 1.54, 241.33], [1, 1.55, 51.87], [2, 1.56, 45]]}, {"timestamp": 1578759026022, "ltp": 1.54, "tv": 781.89, "trd": [[1.54, 580.11]], "batb": NaN, "batl": [[0, 1.54, 191.77], [2, 1.56, 49.54]]}, {"timestamp": 1578759026676, "ltp": 1.54, "tv": 781.89, "trd": NaN, "batb": NaN, "batl": [[0, 1.54, 236.77]]}, {"timestamp": 1578759035531, "ltp": 1.54, "tv": 867.64, "trd": [[1.54, 665.86]], "batb": NaN, "batl": [[0, 1.54, 151.02]]}, {"timestamp": 1578759036360, "ltp": 1.54, "tv": 867.64, "trd": NaN, "batb": NaN, "batl": [[0, 1.54, 155.63]]}, {"timestamp": 1578759037743, "ltp": 1.54, "tv": 867.64, "trd": NaN, "batb": NaN, "batl": [[0, 1.54, 151.02]]}, {"timestamp": 1578759039040, "ltp": 1.54, "tv": 867.64, "trd": NaN, "batb": NaN, "batl": [[0, 1.54, 155.63]]}, {"timestamp": 1578759039335, "ltp": 1.54, "tv": 867.64, "trd": NaN, "batb": NaN, "batl": [[0, 1.54, 262.33]]}, {"timestamp": 1578759041434, "ltp": 1.54, "tv": 893.48, "trd": [[1.54, 691.7]], "batb": NaN, "batl": [[0, 1.54, 249.41]]}, {"timestamp": 1578759673044, "ltp": 1.54, "tv": 893.48, "trd": NaN, "batb": [[1, 1.52, 49.61], [2, 1.51, 454.62]], "batl": NaN}, {"timestamp": 1578759673935, "ltp": 1.54, "tv": 893.48, "trd": NaN, "batb": [[2, 1.51, 62.63]], "batl": NaN}, {"timestamp": 1578759683024, "ltp": 1.53, "tv": 919.02, "trd": [[1.53, 94.55]], "batb": [[0, 1.53, 5.85]], "batl": NaN}, {"timestamp": 1578759684034, "ltp": 1.53, "tv": 919.02, "trd": NaN, "batb": [[0, 1.52, 49.61], [1, 1.51, 62.63], [2, 1.49, 81.78]], "batl": NaN}, {"timestamp": 1578759685812, "ltp": 1.53, "tv": 919.02, "trd": NaN, "batb": NaN, "batl": [[0, 1.53, 19.11], [1, 1.54, 249.41], [2, 1.55, 49.53]]}, {"timestamp": 1578759687013, "ltp": 1.53, "tv": 923.02, "trd": [[1.53, 98.55]], "batb": NaN, "batl": [[0, 1.53, 17.11]]}, {"timestamp": 1578759687937, "ltp": 1.53, "tv": 923.02, "trd": NaN, "batb": NaN, "batl": [[0, 1.53, 29.88]]}, {"timestamp": 1578759688637, "ltp": 1.53, "tv": 923.02, "trd": NaN, "batb": NaN, "batl": [[0, 1.53, 34.54]]}, {"timestamp": 1578759729414, "ltp": 1.53, "tv": 923.02, "trd": NaN, "batb": [[2, 1.5, 45]], "batl": NaN}, {"timestamp": 1578759750694, "ltp": 1.53, "tv": 923.02, "trd": NaN, "batb": NaN, "batl": [[0, 1.53, 25.34]]}, {"timestamp": 1578759751692, "ltp": 1.53, "tv": 923.02, "trd": NaN, "batb": NaN, "batl": [[0, 1.53, 20.69]]}, {"timestamp": 1578759784926, "ltp": 1.53, "tv": 923.02, "trd": NaN, "batb": [[0, 1.52, 434.1]], "batl": NaN}, {"timestamp": 1578759786031, "ltp": 1.53, "tv": 955.67, "trd": [[1.53, 131.21]], "batb": NaN, "batl": [[0, 1.54, 249.41], [1, 1.55, 49.53], [2, 1.56, 49.54]]}, {"timestamp": 1578759787023, "ltp": 1.53, "tv": 955.67, "trd": NaN, "batb": NaN, "batl": [[0, 1.54, 49.61]]}, {"timestamp": 1578759788939, "ltp": 1.53, "tv": 955.67, "trd": NaN, "batb": [[0, 1.53, 23.04], [1, 1.52, 434.1], [2, 1.51, 62.63]], "batl": [[0, 1.54, 59.16]]}, {"timestamp": 1578759789944, "ltp": 1.53, "tv": 955.67, "trd": NaN, "batb": [[0, 1.53, 68.04]], "batl": NaN}, {"timestamp": 1578759791035, "ltp": 1.53, "tv": 955.67, "trd": NaN, "batb": NaN, "batl": [[0, 1.54, 9.56]]}, {"timestamp": 1578759791959, "ltp": 1.53, "tv": 955.67, "trd": NaN, "batb": NaN, "batl": [[0, 1.55, 49.53], [1, 1.56, 49.54], [2, 1.57, 45]]}, {"timestamp": 1578759794024, "ltp": 1.53, "tv": 955.67, "trd": NaN, "batb": NaN, "batl": [[0, 1.55, 192.94]]}, {"timestamp": 1578759818797, "ltp": 1.53, "tv": 955.67, "trd": NaN, "batb": [[1, 1.52, 49.61]], "batl": NaN}, {"timestamp": 1578759830015, "ltp": 1.53, "tv": 955.67, "trd": NaN, "batb": NaN, "batl": [[1, 1.56, 70.64]]}, {"timestamp": 1578759901040, "ltp": 1.53, "tv": 955.67, "trd": NaN, "batb": NaN, "batl": [[0, 1.54, 9.56], [1, 1.55, 192.94], [2, 1.56, 70.64]]}, {"timestamp": 1578759902027, "ltp": 1.53, "tv": 955.67, "trd": NaN, "batb": NaN, "batl": [[0, 1.54, 54.56]]}, {"timestamp": 1578759903870, "ltp": 1.53, "tv": 955.67, "trd": NaN, "batb": NaN, "batl": [[0, 1.54, 59.87]]}, {"timestamp": 1578759966855, "ltp": 1.53, "tv": 955.67, "trd": NaN, "batb": [[2, 1.51, 454.62]], "batl": NaN}, {"timestamp": 1578759989046, "ltp": 1.53, "tv": 955.67, "trd": NaN, "batb": [[1, 1.52, 434.1], [2, 1.51, 62.63]], "batl": NaN}, {"timestamp": 1578759989953, "ltp": 1.53, "tv": 955.67, "trd": NaN, "batb": NaN, "batl": [[0, 1.54, 54.56]]}, {"timestamp": 1578759991044, "ltp": 1.53, "tv": 955.67, "trd": NaN, "batb": NaN, "batl": [[0, 1.54, 9.56]]}, {"timestamp": 1578759991922, "ltp": 1.53, "tv": 955.67, "trd": NaN, "batb": NaN, "batl": [[0, 1.55, 192.94], [1, 1.56, 70.64], [2, 1.57, 45]]}, {"timestamp": 1578760038978, "ltp": 1.53, "tv": 955.67, "trd": NaN, "batb": NaN, "batl": [[0, 1.55, 49.53]]}, {"timestamp": 1578760041978, "ltp": 1.53, "tv": 955.67, "trd": NaN, "batb": NaN, "batl": [[0, 1.55, 199.12]]}, {"timestamp": 1578760042988, "ltp": 1.53, "tv": 955.67, "trd": NaN, "batb": NaN, "batl": [[0, 1.55, 208.68]]}, {"timestamp": 1578760049003, "ltp": 1.53, "tv": 955.67, "trd": NaN, "batb": NaN, "batl": [[0, 1.55, 59.09]]}, {"timestamp": 1578760049986, "ltp": 1.53, "tv": 955.67, "trd": NaN, "batb": [[1, 1.52, 49.61]], "batl": NaN}, {"timestamp": 1578760054878, "ltp": 1.53, "tv": 955.67, "trd": NaN, "batb": [[2, 1.51, 454.62]], "batl": NaN}, {"timestamp": 1578760063984, "ltp": 1.53, "tv": 955.67, "trd": NaN, "batb": NaN, "batl": [[0, 1.55, 209.27]]}, {"timestamp": 1578760069024, "ltp": 1.53, "tv": 955.67, "trd": NaN, "batb": [[2, 1.51, 62.63]], "batl": NaN}, {"timestamp": 1578760190899, "ltp": 1.53, "tv": 955.67, "trd": NaN, "batb": NaN, "batl": [[0, 1.55, 204.74], [2, 1.57, 50.25]]}, {"timestamp": 1578760512737, "ltp": 1.53, "tv": 955.67, "trd": NaN, "batb": [[0, 1.54, 4.66], [1, 1.53, 68.04], [2, 1.52, 49.61]], "batl": [[1, 1.56, 49.54], [2, 1.57, 71.35]]}, {"timestamp": 1578760683960, "ltp": 1.53, "tv": 955.67, "trd": NaN, "batb": NaN, "batl": [[0, 1.55, 54.56]]}, {"timestamp": 1578760685906, "ltp": 1.53, "tv": 955.67, "trd": NaN, "batb": NaN, "batl": [[0, 1.55, 59.2]]}, {"timestamp": 1578760686947, "ltp": 1.53, "tv": 955.67, "trd": NaN, "batb": [[0, 1.54, 49.66]], "batl": NaN}, {"timestamp": 1578760687967, "ltp": 1.53, "tv": 955.67, "trd": NaN, "batb": NaN, "batl": [[0, 1.55, 54.56]]}, {"timestamp": 1578761043007, "ltp": 1.54, "tv": 1055.0, "trd": [[1.54, 791.02]], "batb": [[0, 1.53, 68.04], [1, 1.52, 49.61], [2, 1.51, 62.63]], "batl": [[0, 1.54, 78.68], [1, 1.55, 54.56], [2, 1.56, 49.54]]}, {"timestamp": 1578761044026, "ltp": 1.54, "tv": 1055.0, "trd": NaN, "batb": NaN, "batl": [[0, 1.54, 128.37], [1, 1.55, 59.22]]}, {"timestamp": 1578761045812, "ltp": 1.54, "tv": 1055.0, "trd": NaN, "batb": [[0, 1.53, 49.66]], "batl": [[1, 1.55, 49.66]]}, {"timestamp": 1578761223033, "ltp": 1.54, "tv": 1226.37, "trd": [[1.54, 962.4]], "batb": NaN, "batl": [[0, 1.54, 42.68]]}, {"timestamp": 1578761223913, "ltp": 1.53, "tv": 1325.7, "trd": [[1.53, 230.53]], "batb": [[0, 1.52, 49.61], [1, 1.51, 62.63], [2, 1.5, 445]], "batl": [[0, 1.53, 131.35], [1, 1.54, 87.68], [2, 1.55, 49.66]]}, {"timestamp": 1578761224938, "ltp": 1.53, "tv": 1356.36, "trd": [[1.53, 261.19]], "batb": NaN, "batl": [[0, 1.53, 116.02], [1, 1.54, 49.72]]}, {"timestamp": 1578761225943, "ltp": 1.53, "tv": 1356.36, "trd": NaN, "batb": NaN, "batl": [[0, 1.53, 203.7]]}, {"timestamp": 1578761248958, "ltp": 1.53, "tv": 1356.36, "trd": NaN, "batb": NaN, "batl": [[0, 1.53, 208.45]]}, {"timestamp": 1578761286732, "ltp": 1.52, "tv": 1356.73, "trd": [[1.52, 0.38]], "batb": [[0, 1.52, 49.42]], "batl": NaN}, {"timestamp": 1578761336997, "ltp": 1.52, "tv": 1356.73, "trd": NaN, "batb": NaN, "batl": [[0, 1.53, 333.96]]}, {"timestamp": 1578761337157, "ltp": 1.52, "tv": 1356.73, "trd": NaN, "batb": [[0, 1.52, 4.61]], "batl": NaN}, {"timestamp": 1578761338566, "ltp": 1.52, "tv": 1356.73, "trd": NaN, "batb": [[0, 1.51, 62.63], [1, 1.5, 449.84], [2, 1.49, 78.42]], "batl": NaN}, {"timestamp": 1578761339783, "ltp": 1.52, "tv": 1356.73, "trd": NaN, "batb": NaN, "batl": [[0, 1.53, 329.21]]}, {"timestamp": 1578761361899, "ltp": 1.53, "tv": 1685.69, "trd": [[1.53, 590.15]], "batb": [[0, 1.52, 5.14], [1, 1.51, 454.62], [2, 1.5, 49.84]], "batl": [[0, 1.53, 164.73]]}, {"timestamp": 1578761362798, "ltp": 1.53, "tv": 1685.69, "trd": NaN, "batb": NaN, "batl": [[0, 1.53, 306.32]]}, {"timestamp": 1578761363812, "ltp": 1.53, "tv": 1787.67, "trd": [[1.53, 692.13]], "batb": NaN, "batl": [[0, 1.53, 255.33]]}, {"timestamp": 1578761364803, "ltp": 1.53, "tv": 1923.87, "trd": [[1.53, 828.33]], "batb": [[0, 1.52, 50.14]], "batl": [[0, 1.53, 232.23]]}, {"timestamp": 1578761366011, "ltp": 1.53, "tv": 1923.87, "trd": NaN, "batb": NaN, "batl": [[0, 1.53, 187.23]]}, {"timestamp": 1578761373008, "ltp": 1.53, "tv": 1923.87, "trd": NaN, "batb": [[1, 1.51, 62.63], [2, 1.5, 449.84]], "batl": NaN}, {"timestamp": 1578761374918, "ltp": 1.53, "tv": 1923.87, "trd": NaN, "batb": NaN, "batl": [[0, 1.53, 192.03]]}, {"timestamp": 1578761396037, "ltp": 1.53, "tv": 1923.87, "trd": NaN, "batb": NaN, "batl": [[0, 1.53, 403.55]]}, {"timestamp": 1578761398035, "ltp": 1.53, "tv": 1923.87, "trd": NaN, "batb": NaN, "batl": [[0, 1.53, 448.55]]}, {"timestamp": 1578761465308, "ltp": 1.53, "tv": 2031.43, "trd": [[1.53, 935.89]], "batb": NaN, "batl": [[0, 1.53, 394.77]]}, {"timestamp": 1578761569013, "ltp": 1.53, "tv": 2031.43, "trd": NaN, "batb": [[0, 1.52, 434.63], [2, 1.5, 49.84]], "batl": [[0, 1.53, 49.8]]}, {"timestamp": 1578761570015, "ltp": 1.53, "tv": 2031.43, "trd": NaN, "batb": NaN, "batl": [[0, 1.54, 49.72], [1, 1.55, 49.66], [2, 1.56, 49.54]]}, {"timestamp": 1578761571008, "ltp": 1.53, "tv": 2031.43, "trd": NaN, "batb": NaN, "batl": [[0, 1.54, 673.27]]}, {"timestamp": 1578761571796, "ltp": 1.53, "tv": 2031.43, "trd": NaN, "batb": [[0, 1.53, 30.18], [1, 1.52, 434.63], [2, 1.51, 62.63]], "batl": [[0, 1.54, 686.61]]}, {"timestamp": 1578761572487, "ltp": 1.53, "tv": 2031.43, "trd": NaN, "batb": [[0, 1.52, 434.63], [1, 1.51, 62.63], [2, 1.5, 49.84]], "batl": NaN}, {"timestamp": 1578762032934, "ltp": 1.52, "tv": 2184.54, "trd": [[1.52, 153.49]], "batb": [[0, 1.52, 358.08]], "batl": NaN}, {"timestamp": 1578762033903, "ltp": 1.52, "tv": 2184.54, "trd": NaN, "batb": [[0, 1.52, 362.94]], "batl": [[0, 1.53, 4.83], [1, 1.54, 686.61], [2, 1.55, 49.66]]}, {"timestamp": 1578762034338, "ltp": 1.52, "tv": 2184.54, "trd": NaN, "batb": NaN, "batl": [[0, 1.53, 45.19]]}, {"timestamp": 1578762043027, "ltp": 1.53, "tv": 2188.54, "trd": [[1.53, 939.89]], "batb": NaN, "batl": [[0, 1.53, 43.19]]}, {"timestamp": 1578762045037, "ltp": 1.53, "tv": 2231.73, "trd": [[1.53, 983.08]], "batb": NaN, "batl": [[0, 1.54, 686.61], [1, 1.55, 49.66], [2, 1.56, 49.54]]}, {"timestamp": 1578762045609, "ltp": 1.53, "tv": 2231.73, "trd": NaN, "batb": [[0, 1.52, 407.94]], "batl": NaN}, {"timestamp": 1578762051613, "ltp": 1.53, "tv": 2231.73, "trd": NaN, "batb": NaN, "batl": [[0, 1.54, 63.06]]}, {"timestamp": 1578762061036, "ltp": 1.53, "tv": 2231.73, "trd": NaN, "batb": [[0, 1.53, 16.69], [1, 1.52, 407.94], [2, 1.51, 62.63]], "batl": NaN}, {"timestamp": 1578762061947, "ltp": 1.53, "tv": 2231.73, "trd": NaN, "batb": [[0, 1.53, 66.54]], "batl": NaN}, {"timestamp": 1578762071958, "ltp": 1.53, "tv": 2231.73, "trd": NaN, "batb": NaN, "batl": [[0, 1.54, 1039.51]]}, {"timestamp": 1578762073041, "ltp": 1.53, "tv": 2231.73, "trd": NaN, "batb": [[0, 1.53, 16.69]], "batl": NaN}, {"timestamp": 1578762074025, "ltp": 1.53, "tv": 2231.73, "trd": NaN, "batb": [[0, 1.52, 407.94], [1, 1.51, 62.63], [2, 1.5, 49.84]], "batl": NaN}, {"timestamp": 1578762345546, "ltp": 1.53, "tv": 2231.73, "trd": NaN, "batb": [[0, 1.53, 4.86], [1, 1.52, 407.94], [2, 1.51, 62.63]], "batl": NaN}, {"timestamp": 1578762376783, "ltp": 1.53, "tv": 2231.73, "trd": NaN, "batb": [[1, 1.52, 49.86]], "batl": NaN}, {"timestamp": 1578762405935, "ltp": 1.53, "tv": 2241.08, "trd": [[1.53, 992.42]], "batb": [[0, 1.52, 49.86], [1, 1.51, 62.63], [2, 1.5, 526.69]], "batl": NaN}, {"timestamp": 1578762407716, "ltp": 1.53, "tv": 2241.08, "trd": NaN, "batb": NaN, "batl": [[0, 1.53, 4.86], [1, 1.54, 1039.51], [2, 1.55, 49.66]]}, {"timestamp": 1578762408411, "ltp": 1.53, "tv": 2241.08, "trd": NaN, "batb": NaN, "batl": [[0, 1.53, 49.86]]}, {"timestamp": 1578762428144, "ltp": 1.53, "tv": 2245.16, "trd": [[1.53, 996.51]], "batb": NaN, "batl": [[0, 1.53, 47.82]]}, {"timestamp": 1578762538469, "ltp": 1.53, "tv": 2286.2, "trd": [[1.53, 1037.54]], "batb": NaN, "batl": [[0, 1.53, 27.3]]}, {"timestamp": 1578762548178, "ltp": 1.53, "tv": 2286.2, "trd": NaN, "batb": NaN, "batl": [[1, 1.54, 1071.16]]}, {"timestamp": 1578762549910, "ltp": 1.53, "tv": 2286.2, "trd": NaN, "batb": [[2, 1.5, 449.84]], "batl": NaN}, {"timestamp": 1578762550971, "ltp": 1.53, "tv": 2286.2, "trd": NaN, "batb": NaN, "batl": [[0, 1.53, 32.17], [1, 1.54, 94.71]]}, {"timestamp": 1578762552787, "ltp": 1.53, "tv": 2286.2, "trd": NaN, "batb": NaN, "batl": [[0, 1.53, 27.3]]}, {"timestamp": 1578762553901, "ltp": 1.53, "tv": 2286.2, "trd": NaN, "batb": NaN, "batl": [[0, 1.53, 32.18]]}, {"timestamp": 1578762554893, "ltp": 1.53, "tv": 2286.2, "trd": NaN, "batb": NaN, "batl": [[0, 1.53, 27.3]]}, {"timestamp": 1578762556490, "ltp": 1.53, "tv": 2286.2, "trd": NaN, "batb": NaN, "batl": [[0, 1.53, 32.18]]}, {"timestamp": 1578762558909, "ltp": 1.53, "tv": 2286.2, "trd": NaN, "batb": NaN, "batl": [[0, 1.53, 27.3]]}, {"timestamp": 1578762560711, "ltp": 1.53, "tv": 2286.2, "trd": NaN, "batb": NaN, "batl": [[0, 1.53, 32.18]]}, {"timestamp": 1578762562901, "ltp": 1.53, "tv": 2286.2, "trd": NaN, "batb": NaN, "batl": [[0, 1.53, 27.3]]}, {"timestamp": 1578762563998, "ltp": 1.53, "tv": 2286.2, "trd": NaN, "batb": NaN, "batl": [[0, 1.53, 32.18]]}, {"timestamp": 1578762564902, "ltp": 1.53, "tv": 2286.2, "trd": NaN, "batb": NaN, "batl": [[0, 1.53, 27.3]]}, {"timestamp": 1578762567001, "ltp": 1.53, "tv": 2286.2, "trd": NaN, "batb": NaN, "batl": [[0, 1.53, 32.18]]}, {"timestamp": 1578762568011, "ltp": 1.53, "tv": 2286.2, "trd": NaN, "batb": NaN, "batl": [[0, 1.53, 27.3]]}, {"timestamp": 1578762568487, "ltp": 1.53, "tv": 2286.2, "trd": NaN, "batb": NaN, "batl": [[0, 1.53, 32.18]]}, {"timestamp": 1578762569925, "ltp": 1.53, "tv": 2286.2, "trd": NaN, "batb": NaN, "batl": [[0, 1.53, 27.3]]}, {"timestamp": 1578762570907, "ltp": 1.53, "tv": 2286.2, "trd": NaN, "batb": NaN, "batl": [[0, 1.53, 32.18]]}, {"timestamp": 1578762572922, "ltp": 1.53, "tv": 2286.2, "trd": NaN, "batb": NaN, "batl": [[1, 1.54, 83.62]]}, {"timestamp": 1578762574124, "ltp": 1.53, "tv": 2286.2, "trd": NaN, "batb": NaN, "batl": [[0, 1.53, 27.3]]}, {"timestamp": 1578762575925, "ltp": 1.53, "tv": 2286.2, "trd": NaN, "batb": NaN, "batl": [[0, 1.53, 32.18]]}, {"timestamp": 1578762576961, "ltp": 1.53, "tv": 2286.2, "trd": NaN, "batb": NaN, "batl": [[0, 1.53, 27.3]]}, {"timestamp": 1578762577324, "ltp": 1.53, "tv": 2286.2, "trd": NaN, "batb": NaN, "batl": [[0, 1.53, 32.18]]}, {"timestamp": 1578762578317, "ltp": 1.53, "tv": 2286.2, "trd": NaN, "batb": NaN, "batl": [[0, 1.53, 27.3]]}, {"timestamp": 1578762579326, "ltp": 1.53, "tv": 2286.2, "trd": NaN, "batb": NaN, "batl": [[0, 1.53, 32.18]]}, {"timestamp": 1578762580437, "ltp": 1.53, "tv": 2286.2, "trd": NaN, "batb": NaN, "batl": [[0, 1.53, 27.3]]}, {"timestamp": 1578762581824, "ltp": 1.53, "tv": 2286.2, "trd": NaN, "batb": NaN, "batl": [[0, 1.53, 32.18]]}, {"timestamp": 1578762585134, "ltp": 1.53, "tv": 2286.2, "trd": NaN, "batb": NaN, "batl": [[0, 1.53, 27.3]]}, {"timestamp": 1578762586145, "ltp": 1.53, "tv": 2286.2, "trd": NaN, "batb": NaN, "batl": [[0, 1.53, 32.18]]}, {"timestamp": 1578762587158, "ltp": 1.53, "tv": 2286.2, "trd": NaN, "batb": NaN, "batl": [[0, 1.53, 27.3]]}, {"timestamp": 1578762588240, "ltp": 1.53, "tv": 2286.2, "trd": NaN, "batb": NaN, "batl": [[0, 1.53, 32.18]]}, {"timestamp": 1578762589440, "ltp": 1.53, "tv": 2286.2, "trd": NaN, "batb": NaN, "batl": [[0, 1.53, 27.3]]}, {"timestamp": 1578762592032, "ltp": 1.53, "tv": 2286.2, "trd": NaN, "batb": NaN, "batl": [[0, 1.53, 32.18]]}, {"timestamp": 1578762592763, "ltp": 1.53, "tv": 2286.2, "trd": NaN, "batb": NaN, "batl": [[0, 1.53, 27.3]]}, {"timestamp": 1578762594347, "ltp": 1.53, "tv": 2286.2, "trd": NaN, "batb": NaN, "batl": [[0, 1.53, 32.18]]}, {"timestamp": 1578762595179, "ltp": 1.53, "tv": 2286.2, "trd": NaN, "batb": NaN, "batl": [[0, 1.53, 27.3]]}, {"timestamp": 1578762597554, "ltp": 1.53, "tv": 2286.2, "trd": NaN, "batb": NaN, "batl": [[0, 1.53, 32.18]]}, {"timestamp": 1578762601856, "ltp": 1.53, "tv": 2286.2, "trd": NaN, "batb": NaN, "batl": [[0, 1.53, 27.3]]}, {"timestamp": 1578762602803, "ltp": 1.53, "tv": 2286.2, "trd": NaN, "batb": NaN, "batl": [[0, 1.53, 32.18]]}, {"timestamp": 1578762603985, "ltp": 1.53, "tv": 2286.2, "trd": NaN, "batb": NaN, "batl": [[0, 1.53, 27.3]]}, {"timestamp": 1578762605461, "ltp": 1.53, "tv": 2286.2, "trd": NaN, "batb": NaN, "batl": [[0, 1.53, 32.18]]}, {"timestamp": 1578762607485, "ltp": 1.53, "tv": 2286.2, "trd": NaN, "batb": NaN, "batl": [[0, 1.53, 27.3]]}, {"timestamp": 1578762608386, "ltp": 1.53, "tv": 2286.2, "trd": NaN, "batb": NaN, "batl": [[0, 1.53, 32.18]]}, {"timestamp": 1578762610581, "ltp": 1.53, "tv": 2286.2, "trd": NaN, "batb": NaN, "batl": [[0, 1.53, 27.3]]}, {"timestamp": 1578762611981, "ltp": 1.53, "tv": 2286.2, "trd": NaN, "batb": NaN, "batl": [[0, 1.53, 32.18]]}, {"timestamp": 1578762612984, "ltp": 1.53, "tv": 2286.2, "trd": NaN, "batb": NaN, "batl": [[0, 1.53, 27.3]]}, {"timestamp": 1578762613996, "ltp": 1.53, "tv": 2286.2, "trd": NaN, "batb": NaN, "batl": [[0, 1.53, 32.18]]}, {"timestamp": 1578762614495, "ltp": 1.53, "tv": 2286.2, "trd": NaN, "batb": NaN, "batl": [[0, 1.53, 27.3]]}, {"timestamp": 1578762616988, "ltp": 1.53, "tv": 2313.5, "trd": [[1.53, 1064.84]], "batb": NaN, "batl": [[0, 1.53, 13.65]]}, {"timestamp": 1578762623599, "ltp": 1.53, "tv": 2323.73, "trd": [[1.53, 1075.07]], "batb": NaN, "batl": [[0, 1.53, 3.42]]}, {"timestamp": 1578762624891, "ltp": 1.53, "tv": 2330.3, "trd": [[1.53, 1081.65]], "batb": [[0, 1.53, 41.58], [1, 1.52, 49.86], [2, 1.51, 62.63]], "batl": [[0, 1.54, 83.62], [1, 1.55, 49.66], [2, 1.56, 49.54]]}, {"timestamp": 1578762625819, "ltp": 1.53, "tv": 2330.3, "trd": NaN, "batb": [[0, 1.53, 49.75], [1, 1.52, 70.68]], "batl": [[0, 1.54, 63.06]]}, {"timestamp": 1578762649213, "ltp": 1.53, "tv": 2330.3, "trd": NaN, "batb": [[1, 1.52, 49.86]], "batl": NaN}, {"timestamp": 1578762650837, "ltp": 1.53, "tv": 2330.3, "trd": NaN, "batb": NaN, "batl": [[0, 1.54, 58.35]]}, {"timestamp": 1578762652018, "ltp": 1.53, "tv": 2330.3, "trd": NaN, "batb": NaN, "batl": [[0, 1.54, 63.2]]}, {"timestamp": 1578762652537, "ltp": 1.53, "tv": 2330.3, "trd": NaN, "batb": NaN, "batl": [[0, 1.54, 58.35]]}, {"timestamp": 1578762653714, "ltp": 1.53, "tv": 2330.3, "trd": NaN, "batb": NaN, "batl": [[0, 1.54, 63.2]]}, {"timestamp": 1578762654466, "ltp": 1.53, "tv": 2330.3, "trd": NaN, "batb": NaN, "batl": [[0, 1.54, 58.35]]}, {"timestamp": 1578762655144, "ltp": 1.53, "tv": 2330.3, "trd": NaN, "batb": NaN, "batl": [[0, 1.54, 63.2]]}, {"timestamp": 1578762659028, "ltp": 1.53, "tv": 2330.3, "trd": NaN, "batb": NaN, "batl": [[0, 1.54, 58.35]]}, {"timestamp": 1578762661850, "ltp": 1.53, "tv": 2330.3, "trd": NaN, "batb": NaN, "batl": [[0, 1.54, 63.2]]}, {"timestamp": 1578762662329, "ltp": 1.53, "tv": 2330.3, "trd": NaN, "batb": NaN, "batl": [[0, 1.54, 58.35]]}, {"timestamp": 1578762735010, "ltp": 1.53, "tv": 2330.3, "trd": NaN, "batb": [[0, 1.53, 64.4]], "batl": NaN}, {"timestamp": 1578762891025, "ltp": 1.53, "tv": 2330.3, "trd": NaN, "batb": [[2, 1.51, 454.62]], "batl": NaN}, {"timestamp": 1578762920838, "ltp": 1.53, "tv": 2330.3, "trd": NaN, "batb": [[2, 1.51, 62.63]], "batl": NaN}, {"timestamp": 1578762968024, "ltp": 1.53, "tv": 2579.61, "trd": [[1.53, 1330.96]], "batb": [[0, 1.53, 45]], "batl": [[0, 1.54, 63.23]]}, {"timestamp": 1578762968988, "ltp": 1.53, "tv": 2669.61, "trd": [[1.53, 1420.96]], "batb": [[0, 1.52, 49.86], [1, 1.51, 62.63], [2, 1.5, 449.84]], "batl": [[0, 1.53, 184.6], [1, 1.54, 63.23], [2, 1.55, 49.66]]}, {"timestamp": 1578762971906, "ltp": 1.53, "tv": 2669.61, "trd": NaN, "batb": [[2, 1.5, 526.69]], "batl": NaN}, {"timestamp": 1578762974728, "ltp": 1.53, "tv": 2669.61, "trd": NaN, "batb": NaN, "batl": [[1, 1.54, 85.45]]}, {"timestamp": 1578762976927, "ltp": 1.53, "tv": 2669.61, "trd": NaN, "batb": [[2, 1.5, 449.84]], "batl": [[0, 1.53, 179.59]]}, {"timestamp": 1578762995028, "ltp": 1.53, "tv": 2669.61, "trd": NaN, "batb": NaN, "batl": [[1, 1.54, 63.23]]}, {"timestamp": 1578762996850, "ltp": 1.53, "tv": 2669.61, "trd": NaN, "batb": [[2, 1.5, 526.69]], "batl": NaN}, {"timestamp": 1578762998964, "ltp": 1.53, "tv": 2669.61, "trd": NaN, "batb": [[0, 1.52, 53.49]], "batl": NaN}, {"timestamp": 1578763023972, "ltp": 1.53, "tv": 2669.61, "trd": NaN, "batb": [[1, 1.51, 454.62], [2, 1.5, 126.69]], "batl": NaN}, {"timestamp": 1578763024987, "ltp": 1.53, "tv": 2669.61, "trd": NaN, "batb": NaN, "batl": [[0, 1.53, 200.21]]}, {"timestamp": 1578763025781, "ltp": 1.53, "tv": 2805.81, "trd": [[1.53, 1557.15]], "batb": NaN, "batl": [[0, 1.53, 132.11]]}, {"timestamp": 1578763026884, "ltp": 1.53, "tv": 2805.81, "trd": NaN, "batb": [[0, 1.52, 8.49]], "batl": [[0, 1.53, 264.79]]}, {"timestamp": 1578763034992, "ltp": 1.53, "tv": 2818.61, "trd": [[1.53, 1569.95]], "batb": NaN, "batl": [[0, 1.53, 258.39]]}, {"timestamp": 1578763048009, "ltp": 1.53, "tv": 3073.27, "trd": [[1.53, 1824.62]], "batb": NaN, "batl": [[0, 1.53, 131.06]]}, {"timestamp": 1578763049017, "ltp": 1.53, "tv": 3073.27, "trd": NaN, "batb": [[0, 1.52, 53.49]], "batl": [[0, 1.53, 176.06]]}, {"timestamp": 1578763055048, "ltp": 1.53, "tv": 3073.27, "trd": NaN, "batb": [[1, 1.51, 62.63]], "batl": NaN}, {"timestamp": 1578763055842, "ltp": 1.53, "tv": 3073.27, "trd": NaN, "batb": NaN, "batl": [[0, 1.53, 45]]}, {"timestamp": 1578763057011, "ltp": 1.53, "tv": 3118.27, "trd": [[1.53, 1869.62]], "batb": [[0, 1.53, 4.95], [1, 1.52, 53.49], [2, 1.51, 62.63]], "batl": [[0, 1.54, 58.35], [1, 1.55, 49.66], [2, 1.56, 49.54]]}, {"timestamp": 1578763057809, "ltp": 1.53, "tv": 3118.27, "trd": NaN, "batb": [[0, 1.53, 45]], "batl": [[0, 1.54, 71.51]]}, {"timestamp": 1578763060946, "ltp": 1.53, "tv": 3118.27, "trd": NaN, "batb": NaN, "batl": [[2, 1.56, 70.64]]}, {"timestamp": 1578763061918, "ltp": 1.53, "tv": 3118.27, "trd": NaN, "batb": [[0, 1.53, 422.33]], "batl": [[0, 1.54, 26.51]]}, {"timestamp": 1578763063024, "ltp": 1.53, "tv": 3118.27, "trd": NaN, "batb": [[0, 1.53, 427.68]], "batl": [[0, 1.54, 13.16], [1, 1.55, 70.08]]}, {"timestamp": 1578763138024, "ltp": 1.53, "tv": 3118.27, "trd": NaN, "batb": [[0, 1.53, 448.37]], "batl": NaN}, {"timestamp": 1578763504002, "ltp": 1.53, "tv": 3118.27, "trd": NaN, "batb": [[0, 1.53, 71.04]], "batl": [[0, 1.54, 747.49]]}, {"timestamp": 1578763504978, "ltp": 1.53, "tv": 3143.81, "trd": [[1.53, 1895.16]], "batb": [[0, 1.53, 58.27]], "batl": NaN}, {"timestamp": 1578763505881, "ltp": 1.53, "tv": 3143.81, "trd": NaN, "batb": [[0, 1.53, 37.58]], "batl": NaN}, {"timestamp": 1578763507275, "ltp": 1.53, "tv": 3143.81, "trd": NaN, "batb": NaN, "batl": [[0, 1.54, 752.44]]}, {"timestamp": 1578763517532, "ltp": 1.53, "tv": 3143.81, "trd": NaN, "batb": NaN, "batl": [[1, 1.55, 49.66]]}, {"timestamp": 1578763540012, "ltp": 1.53, "tv": 3143.81, "trd": NaN, "batb": [[2, 1.51, 454.62]], "batl": NaN}, {"timestamp": 1578763541015, "ltp": 1.53, "tv": 3143.81, "trd": NaN, "batb": NaN, "batl": [[0, 1.54, 18.11]]}, {"timestamp": 1578763542033, "ltp": 1.53, "tv": 3143.81, "trd": NaN, "batb": NaN, "batl": [[0, 1.54, 31.59]]}, {"timestamp": 1578763543910, "ltp": 1.53, "tv": 3143.81, "trd": NaN, "batb": NaN, "batl": [[0, 1.55, 73.26], [1, 1.56, 70.64], [2, 1.57, 45]]}, {"timestamp": 1578763545036, "ltp": 1.53, "tv": 3143.81, "trd": NaN, "batb": NaN, "batl": [[0, 1.55, 664.79]]}, {"timestamp": 1578763582757, "ltp": 1.53, "tv": 3143.81, "trd": NaN, "batb": [[0, 1.53, 58.27]], "batl": NaN}, {"timestamp": 1578763690128, "ltp": 1.53, "tv": 3143.81, "trd": NaN, "batb": [[0, 1.53, 58.31]], "batl": NaN}, {"timestamp": 1578763884028, "ltp": 1.53, "tv": 3143.81, "trd": NaN, "batb": [[0, 1.53, 435.64], [2, 1.51, 62.63]], "batl": NaN}, {"timestamp": 1578763885031, "ltp": 1.53, "tv": 3143.81, "trd": NaN, "batb": [[0, 1.54, 5.33], [1, 1.53, 435.64], [2, 1.52, 53.49]], "batl": NaN}, {"timestamp": 1578763885983, "ltp": 1.53, "tv": 3143.81, "trd": NaN, "batb": NaN, "batl": [[0, 1.55, 660.13]]}, {"timestamp": 1578763886577, "ltp": 1.53, "tv": 3143.81, "trd": NaN, "batb": NaN, "batl": [[2, 1.57, 49.88]]}, {"timestamp": 1578763907842, "ltp": 1.53, "tv": 3143.81, "trd": NaN, "batb": [[1, 1.53, 414.95]], "batl": NaN}, {"timestamp": 1578763932971, "ltp": 1.53, "tv": 3143.81, "trd": NaN, "batb": NaN, "batl": [[0, 1.55, 68.6]]}, {"timestamp": 1578763933880, "ltp": 1.53, "tv": 3143.81, "trd": NaN, "batb": [[0, 1.54, 5.26]], "batl": NaN}, {"timestamp": 1578764018683, "ltp": 1.53, "tv": 3143.81, "trd": NaN, "batb": [[1, 1.53, 436.24]], "batl": NaN}, {"timestamp": 1578764066044, "ltp": 1.53, "tv": 3143.81, "trd": NaN, "batb": [[1, 1.53, 414.95]], "batl": NaN}, {"timestamp": 1578764067152, "ltp": 1.53, "tv": 3143.81, "trd": NaN, "batb": [[1, 1.53, 435.64]], "batl": NaN}, {"timestamp": 1578764624005, "ltp": 1.53, "tv": 3143.81, "trd": NaN, "batb": [[1, 1.53, 58.31]], "batl": NaN}, {"timestamp": 1578764639968, "ltp": 1.53, "tv": 3143.81, "trd": NaN, "batb": NaN, "batl": [[0, 1.55, 89.02]]}, {"timestamp": 1578764640984, "ltp": 1.53, "tv": 3143.81, "trd": NaN, "batb": NaN, "batl": [[0, 1.55, 94]]}, {"timestamp": 1578764743012, "ltp": 1.54, "tv": 3149.07, "trd": [[1.54, 967.66]], "batb": [[0, 1.53, 58.31], [1, 1.52, 53.49], [2, 1.51, 62.63]], "batl": NaN}, {"timestamp": 1578764746027, "ltp": 1.54, "tv": 3149.07, "trd": NaN, "batb": [[0, 1.53, 37.62]], "batl": NaN}, {"timestamp": 1578764746614, "ltp": 1.54, "tv": 3149.07, "trd": NaN, "batb": NaN, "batl": [[0, 1.54, 5.01], [1, 1.55, 94], [2, 1.56, 70.64]]}, {"timestamp": 1578764751043, "ltp": 1.54, "tv": 3149.07, "trd": NaN, "batb": NaN, "batl": [[0, 1.55, 94], [1, 1.56, 70.64], [2, 1.57, 49.88]]}, {"timestamp": 1578764751688, "ltp": 1.54, "tv": 3149.07, "trd": NaN, "batb": NaN, "batl": [[0, 1.54, 5.01], [1, 1.55, 94], [2, 1.56, 70.64]]}, {"timestamp": 1578764752692, "ltp": 1.54, "tv": 3149.07, "trd": NaN, "batb": NaN, "batl": [[0, 1.55, 94], [1, 1.56, 70.64], [2, 1.57, 49.88]]}, {"timestamp": 1578764754027, "ltp": 1.54, "tv": 3149.07, "trd": NaN, "batb": NaN, "batl": [[0, 1.54, 5.01], [1, 1.55, 94], [2, 1.56, 70.64]]}, {"timestamp": 1578764755029, "ltp": 1.54, "tv": 3149.07, "trd": NaN, "batb": [[2, 1.51, 454.62]], "batl": [[0, 1.55, 94], [1, 1.56, 70.64], [2, 1.57, 49.88]]}, {"timestamp": 1578764756744, "ltp": 1.54, "tv": 3149.07, "trd": NaN, "batb": NaN, "batl": [[0, 1.54, 5.01], [1, 1.55, 94], [2, 1.56, 70.64]]}, {"timestamp": 1578764759020, "ltp": 1.54, "tv": 3149.07, "trd": NaN, "batb": NaN, "batl": [[0, 1.55, 73.58], [1, 1.56, 70.64], [2, 1.57, 49.88]]}, {"timestamp": 1578764759815, "ltp": 1.54, "tv": 3149.07, "trd": NaN, "batb": NaN, "batl": [[0, 1.54, 5.01], [1, 1.55, 73.58], [2, 1.56, 70.64]]}, {"timestamp": 1578764762044, "ltp": 1.54, "tv": 3149.07, "trd": NaN, "batb": NaN, "batl": [[0, 1.55, 73.58], [1, 1.56, 70.64], [2, 1.57, 49.88]]}, {"timestamp": 1578764762891, "ltp": 1.54, "tv": 3149.07, "trd": NaN, "batb": NaN, "batl": [[0, 1.54, 5.01], [1, 1.55, 73.58], [2, 1.56, 70.64]]}, {"timestamp": 1578764763809, "ltp": 1.54, "tv": 3149.07, "trd": NaN, "batb": NaN, "batl": [[0, 1.55, 73.58], [1, 1.56, 70.64], [2, 1.57, 49.88]]}, {"timestamp": 1578764780958, "ltp": 1.54, "tv": 3149.07, "trd": NaN, "batb": [[0, 1.53, 32.26]], "batl": [[0, 1.54, 5.01], [1, 1.55, 73.58], [2, 1.56, 70.64]]}, {"timestamp": 1578764785046, "ltp": 1.54, "tv": 3149.07, "trd": NaN, "batb": [[0, 1.53, 37.31]], "batl": NaN}, {"timestamp": 1578764794965, "ltp": 1.53, "tv": 3182.03, "trd": [[1.53, 1928.12]], "batb": [[0, 1.53, 4.35]], "batl": NaN}, {"timestamp": 1578764795871, "ltp": 1.53, "tv": 3182.03, "trd": NaN, "batb": [[0, 1.52, 53.49], [1, 1.51, 454.62], [2, 1.5, 45]], "batl": NaN}, {"timestamp": 1578764840013, "ltp": 1.53, "tv": 3182.03, "trd": NaN, "batb": NaN, "batl": [[0, 1.54, 25.57]]}, {"timestamp": 1578764881878, "ltp": 1.53, "tv": 3182.03, "trd": NaN, "batb": NaN, "batl": [[0, 1.54, 5.01]]}, {"timestamp": 1578764887853, "ltp": 1.53, "tv": 3182.03, "trd": NaN, "batb": NaN, "batl": [[0, 1.54, 25.57]]}, {"timestamp": 1578764889871, "ltp": 1.53, "tv": 3198.68, "trd": [[1.53, 1944.77]], "batb": NaN, "batl": [[1, 1.55, 49.97]]}, {"timestamp": 1578764990965, "ltp": 1.53, "tv": 3198.68, "trd": NaN, "batb": [[0, 1.53, 5.06], [1, 1.52, 53.49], [2, 1.51, 454.62]], "batl": [[0, 1.54, 25.58]]}, {"timestamp": 1578765077040, "ltp": 1.53, "tv": 3208.8, "trd": [[1.53, 1954.89]], "batb": [[0, 1.52, 53.49], [1, 1.51, 454.62], [2, 1.5, 45]], "batl": [[0, 1.53, 4.94], [1, 1.54, 25.58], [2, 1.55, 49.97]]}, {"timestamp": 1578765077990, "ltp": 1.53, "tv": 3213.74, "trd": [[1.53, 1959.83]], "batb": NaN, "batl": [[0, 1.54, 25.58], [1, 1.55, 49.97], [2, 1.56, 70.64]]}, {"timestamp": 1578765084876, "ltp": 1.53, "tv": 3223.74, "trd": [[1.53, 1969.83]], "batb": NaN, "batl": NaN}, {"timestamp": 1578765090983, "ltp": 1.53, "tv": 3233.74, "trd": [[1.53, 1979.83]], "batb": NaN, "batl": NaN}, {"timestamp": 1578765097988, "ltp": 1.53, "tv": 3233.74, "trd": NaN, "batb": NaN, "batl": [[0, 1.53, 10], [1, 1.54, 25.58], [2, 1.55, 49.97]]}, {"timestamp": 1578765098880, "ltp": 1.53, "tv": 3243.74, "trd": [[1.53, 1989.83]], "batb": NaN, "batl": [[0, 1.54, 25.58], [1, 1.55, 49.97], [2, 1.56, 70.64]]}, {"timestamp": 1578765107789, "ltp": 1.53, "tv": 3253.74, "trd": [[1.53, 1999.83]], "batb": NaN, "batl": NaN}, {"timestamp": 1578765223044, "ltp": 1.53, "tv": 3253.74, "trd": NaN, "batb": NaN, "batl": [[0, 1.54, 542.6]]}, {"timestamp": 1578765379056, "ltp": 1.53, "tv": 3253.74, "trd": NaN, "batb": NaN, "batl": [[0, 1.54, 25.58]]}, {"timestamp": 1578765395987, "ltp": 1.53, "tv": 3253.74, "trd": NaN, "batb": NaN, "batl": [[0, 1.54, 557.67]]}, {"timestamp": 1578765423955, "ltp": 1.53, "tv": 3253.74, "trd": NaN, "batb": [[0, 1.53, 5.1], [1, 1.52, 53.49], [2, 1.51, 454.62]], "batl": [[0, 1.54, 552.64]]}, {"timestamp": 1578765424739, "ltp": 1.53, "tv": 3253.74, "trd": NaN, "batb": NaN, "batl": [[0, 1.54, 532.09]]}, {"timestamp": 1578765619035, "ltp": 1.53, "tv": 3262.93, "trd": [[1.53, 2009.02]], "batb": [[0, 1.52, 54], [1, 1.51, 454.62], [2, 1.5, 45]], "batl": NaN}, {"timestamp": 1578765687022, "ltp": 1.53, "tv": 3262.93, "trd": NaN, "batb": NaN, "batl": [[0, 1.54, 537.17]]}, {"timestamp": 1578765970033, "ltp": 1.53, "tv": 3262.93, "trd": NaN, "batb": NaN, "batl": [[1, 1.55, 207.81]]}, {"timestamp": 1578765972005, "ltp": 1.53, "tv": 3262.93, "trd": NaN, "batb": [[0, 1.52, 177.16], [1, 1.51, 574.33], [2, 1.5, 163.74]], "batl": NaN}, {"timestamp": 1578765979053, "ltp": 1.53, "tv": 3262.93, "trd": NaN, "batb": NaN, "batl": [[0, 1.54, 5.08]]}, {"timestamp": 1578765980829, "ltp": 1.53, "tv": 3262.93, "trd": NaN, "batb": NaN, "batl": [[0, 1.55, 207.81], [1, 1.56, 70.64], [2, 1.57, 200.87]]}, {"timestamp": 1578765983016, "ltp": 1.53, "tv": 3262.93, "trd": NaN, "batb": NaN, "batl": [[0, 1.55, 49.97]]}, {"timestamp": 1578765983810, "ltp": 1.53, "tv": 3262.93, "trd": NaN, "batb": [[0, 1.53, 32.15], [1, 1.52, 176.66], [2, 1.51, 574.33]], "batl": [[0, 1.55, 865.9]]}, {"timestamp": 1578766155927, "ltp": 1.53, "tv": 3262.93, "trd": NaN, "batb": [[1, 1.52, 561.15], [2, 1.51, 182.34]], "batl": NaN}, {"timestamp": 1578766157048, "ltp": 1.53, "tv": 3262.93, "trd": NaN, "batb": NaN, "batl": [[0, 1.55, 49.97]]}, {"timestamp": 1578766306056, "ltp": 1.53, "tv": 3281.3, "trd": [[1.53, 2027.39]], "batb": [[0, 1.53, 33.18]], "batl": NaN}, {"timestamp": 1578766310935, "ltp": 1.53, "tv": 3281.3, "trd": NaN, "batb": NaN, "batl": [[0, 1.55, 58.54]]}, {"timestamp": 1578766377160, "ltp": 1.53, "tv": 3281.3, "trd": NaN, "batb": [[0, 1.53, 37.21]], "batl": NaN}, {"timestamp": 1578766423018, "ltp": 1.53, "tv": 3281.3, "trd": NaN, "batb": [[1, 1.52, 176.66], [2, 1.51, 574.33]], "batl": NaN}, {"timestamp": 1578766571757, "ltp": 1.53, "tv": 3281.3, "trd": NaN, "batb": [[0, 1.53, 10.21]], "batl": [[0, 1.55, 49.97]]}, {"timestamp": 1578766587931, "ltp": 1.53, "tv": 3281.3, "trd": NaN, "batb": [[0, 1.53, 38.32]], "batl": [[0, 1.55, 58.54]]}, {"timestamp": 1578766623014, "ltp": 1.53, "tv": 3281.3, "trd": NaN, "batb": [[1, 1.52, 561.15], [2, 1.51, 182.34]], "batl": NaN}, {"timestamp": 1578766628424, "ltp": 1.53, "tv": 3281.3, "trd": NaN, "batb": [[0, 1.53, 10.21]], "batl": [[0, 1.55, 49.97]]}, {"timestamp": 1578766645830, "ltp": 1.53, "tv": 3281.3, "trd": NaN, "batb": [[0, 1.53, 37.23]], "batl": [[0, 1.55, 58.54]]}, {"timestamp": 1578766671681, "ltp": 1.53, "tv": 3281.3, "trd": NaN, "batb": NaN, "batl": [[0, 1.55, 49.97]]}, {"timestamp": 1578766673860, "ltp": 1.53, "tv": 3281.3, "trd": NaN, "batb": [[1, 1.52, 176.66]], "batl": [[0, 1.55, 1111.05]]}, {"timestamp": 1578767291943, "ltp": 1.53, "tv": 3281.3, "trd": NaN, "batb": NaN, "batl": [[1, 1.56, 49.54], [2, 1.57, 221.97]]}, {"timestamp": 1578767616889, "ltp": 1.53, "tv": 3281.3, "trd": NaN, "batb": [[0, 1.53, 82.23]], "batl": NaN}, {"timestamp": 1578767701597, "ltp": 1.53, "tv": 3281.3, "trd": NaN, "batb": [[0, 1.53, 37.23], [1, 1.52, 131.66], [2, 1.51, 137.34]], "batl": [[0, 1.55, 1066.05], [1, 1.56, 4.54], [2, 1.57, 176.97]]}, {"timestamp": 1578768101055, "ltp": 1.53, "tv": 3281.3, "trd": NaN, "batb": [[0, 1.53, 52.23]], "batl": NaN}, {"timestamp": 1578768101849, "ltp": 1.53, "tv": 3281.3, "trd": NaN, "batb": NaN, "batl": [[0, 1.55, 1081.05]]}, {"timestamp": 1578768288025, "ltp": 1.53, "tv": 3389.6, "trd": [[1.53, 2135.69]], "batb": [[0, 1.52, 131.66], [1, 1.51, 137.34], [2, 1.5, 518.74]], "batl": NaN}, {"timestamp": 1578768288929, "ltp": 1.53, "tv": 3389.6, "trd": NaN, "batb": [[0, 1.53, 12.62], [1, 1.52, 131.66], [2, 1.51, 137.34]], "batl": [[0, 1.54, 27.54], [1, 1.55, 1116.29], [2, 1.56, 4.54]]}, {"timestamp": 1578768292859, "ltp": 1.54, "tv": 3417.14, "trd": [[1.54, 995.2]], "batb": NaN, "batl": [[0, 1.55, 1116.29], [1, 1.56, 4.54], [2, 1.57, 176.97]]}, {"timestamp": 1578768293975, "ltp": 1.54, "tv": 3417.14, "trd": NaN, "batb": [[0, 1.53, 27.62]], "batl": NaN}, {"timestamp": 1578768312996, "ltp": 1.54, "tv": 3417.14, "trd": NaN, "batb": NaN, "batl": [[2, 1.57, 155.87]]}, {"timestamp": 1578768348439, "ltp": 1.54, "tv": 3417.14, "trd": NaN, "batb": [[0, 1.53, 49.9]], "batl": NaN}, {"timestamp": 1578768411811, "ltp": 1.54, "tv": 3417.88, "trd": [[1.54, 995.95]], "batb": NaN, "batl": NaN}, {"timestamp": 1578768600038, "ltp": 1.54, "tv": 3417.88, "trd": NaN, "batb": NaN, "batl": [[0, 1.55, 1246.85]]}, {"timestamp": 1578768601555, "ltp": 1.54, "tv": 3417.88, "trd": NaN, "batb": [[0, 1.53, 54.9], [1, 1.52, 136.66], [2, 1.51, 142.34]], "batl": [[0, 1.55, 1251.85], [1, 1.56, 9.54], [2, 1.57, 160.87]]}, {"timestamp": 1578768662912, "ltp": 1.54, "tv": 3417.88, "trd": NaN, "batb": [[1, 1.52, 181.66], [2, 1.51, 187.34]], "batl": [[1, 1.56, 54.54], [2, 1.57, 205.87]]}, {"timestamp": 1578768663806, "ltp": 1.54, "tv": 3417.88, "trd": NaN, "batb": [[2, 1.51, 182.34]], "batl": [[1, 1.56, 49.54], [2, 1.57, 200.87]]}, {"timestamp": 1578768665006, "ltp": 1.54, "tv": 3417.88, "trd": NaN, "batb": [[1, 1.52, 176.66]], "batl": NaN}, {"timestamp": 1578768918640, "ltp": 1.54, "tv": 3417.88, "trd": NaN, "batb": [[2, 1.51, 574.33]], "batl": NaN}, {"timestamp": 1578768944983, "ltp": 1.53, "tv": 3421.78, "trd": [[1.53, 2139.58]], "batb": [[0, 1.53, 52.95]], "batl": NaN}, {"timestamp": 1578768951998, "ltp": 1.53, "tv": 3421.78, "trd": NaN, "batb": NaN, "batl": [[0, 1.55, 1481.52]]}, {"timestamp": 1578769012962, "ltp": 1.53, "tv": 3421.78, "trd": NaN, "batb": [[1, 1.52, 561.15], [2, 1.51, 182.34]], "batl": NaN}, {"timestamp": 1578769026986, "ltp": 1.53, "tv": 3421.78, "trd": NaN, "batb": NaN, "batl": [[0, 1.55, 420.44]]}, {"timestamp": 1578769035983, "ltp": 1.53, "tv": 3421.78, "trd": NaN, "batb": [[1, 1.52, 176.66], [2, 1.51, 574.33]], "batl": NaN}, {"timestamp": 1578769047029, "ltp": 1.53, "tv": 3421.78, "trd": NaN, "batb": [[0, 1.53, 430.28], [2, 1.51, 182.34]], "batl": NaN}, {"timestamp": 1578769048917, "ltp": 1.53, "tv": 3421.78, "trd": NaN, "batb": NaN, "batl": [[0, 1.55, 418.23]]}, {"timestamp": 1578769051814, "ltp": 1.53, "tv": 3421.78, "trd": NaN, "batb": NaN, "batl": [[0, 1.55, 287.67]]}, {"timestamp": 1578769053027, "ltp": 1.53, "tv": 3421.78, "trd": NaN, "batb": [[0, 1.54, 15.37], [1, 1.53, 52.95], [2, 1.52, 176.66]], "batl": NaN}, {"timestamp": 1578769054041, "ltp": 1.53, "tv": 3421.78, "trd": NaN, "batb": [[0, 1.53, 52.95], [1, 1.52, 176.66], [2, 1.51, 182.34]], "batl": NaN}, {"timestamp": 1578769067694, "ltp": 1.53, "tv": 3421.78, "trd": NaN, "batb": NaN, "batl": [[0, 1.55, 285.36]]}, {"timestamp": 1578769144054, "ltp": 1.53, "tv": 3421.78, "trd": NaN, "batb": [[2, 1.51, 574.33]], "batl": NaN}, {"timestamp": 1578769149979, "ltp": 1.53, "tv": 3421.78, "trd": NaN, "batb": NaN, "batl": [[0, 1.55, 289.88]]}, {"timestamp": 1578769209872, "ltp": 1.53, "tv": 3421.79, "trd": [[1.52, 153.46], [1.53, 2139.62], [1.56, 51.48], [1.57, 46.92], [1.61, 3.83]], "batb": [[0, 1.53, 52.99]], "batl": [[0, 1.54, 3.06], [1, 1.55, 289.87], [2, 1.56, 49.54]]}, {"timestamp": 1578769215778, "ltp": 1.53, "tv": 3421.79, "trd": NaN, "batb": NaN, "batl": [[1, 1.55, 289.51]]}, {"timestamp": 1578769234498, "ltp": 1.53, "tv": 3434.53, "trd": [[1.53, 2152.36]], "batb": [[0, 1.53, 46.62]], "batl": NaN}, {"timestamp": 1578769240009, "ltp": 1.53, "tv": 3434.53, "trd": NaN, "batb": NaN, "batl": [[1, 1.55, 289.87]]}, {"timestamp": 1578769262944, "ltp": 1.53, "tv": 3434.53, "trd": NaN, "batb": NaN, "batl": [[1, 1.55, 334.87]]}, {"timestamp": 1578769264054, "ltp": 1.53, "tv": 3434.53, "trd": NaN, "batb": NaN, "batl": [[1, 1.55, 329.87]]}, {"timestamp": 1578769300908, "ltp": 1.53, "tv": 3434.53, "trd": NaN, "batb": [[0, 1.53, 51.62]], "batl": [[0, 1.54, 8.06]]}, {"timestamp": 1578769301991, "ltp": 1.53, "tv": 3434.53, "trd": NaN, "batb": NaN, "batl": [[0, 1.54, 5], [1, 1.55, 332.93]]}, {"timestamp": 1578769329972, "ltp": 1.53, "tv": 3434.53, "trd": NaN, "batb": NaN, "batl": [[0, 1.54, 12.65]]}, {"timestamp": 1578769351973, "ltp": 1.53, "tv": 3470.16, "trd": [[1.53, 2187.99]], "batb": [[0, 1.53, 33.8]], "batl": NaN}, {"timestamp": 1578769352773, "ltp": 1.53, "tv": 3470.16, "trd": NaN, "batb": [[0, 1.53, 42.89]], "batl": [[0, 1.54, 26.16]]}, {"timestamp": 1578769357008, "ltp": 1.53, "tv": 3470.16, "trd": NaN, "batb": [[0, 1.53, 20.57]], "batl": [[1, 1.55, 333.16]]}, {"timestamp": 1578769376804, "ltp": 1.53, "tv": 3470.16, "trd": NaN, "batb": [[0, 1.53, 30.67]], "batl": NaN}, {"timestamp": 1578769388011, "ltp": 1.53, "tv": 3470.16, "trd": NaN, "batb": [[0, 1.53, 53.54]], "batl": NaN}, {"timestamp": 1578769397048, "ltp": 1.53, "tv": 3470.16, "trd": NaN, "batb": [[0, 1.53, 30.67]], "batl": NaN}, {"timestamp": 1578769440907, "ltp": 1.54, "tv": 3520.48, "trd": [[1.54, 1046.27]], "batb": NaN, "batl": [[0, 1.54, 1]]}, {"timestamp": 1578769441708, "ltp": 1.54, "tv": 3520.48, "trd": NaN, "batb": [[0, 1.53, 59.83]], "batl": [[1, 1.55, 332.93]]}, {"timestamp": 1578769455817, "ltp": 1.54, "tv": 3521.48, "trd": [[1.54, 1047.27]], "batb": NaN, "batl": [[0, 1.55, 332.93], [1, 1.56, 49.54], [2, 1.57, 200.87]]}, {"timestamp": 1578769465898, "ltp": 1.53, "tv": 3527.6, "trd": [[1.53, 2194.11]], "batb": [[0, 1.53, 56.77]], "batl": [[0, 1.55, 329.87]]}, {"timestamp": 1578769467436, "ltp": 1.53, "tv": 3527.6, "trd": NaN, "batb": NaN, "batl": [[0, 1.54, 1.49], [1, 1.55, 329.87], [2, 1.56, 49.54]]}, {"timestamp": 1578769472011, "ltp": 1.54, "tv": 3530.59, "trd": [[1.54, 1050.25]], "batb": [[0, 1.54, 8.61], [1, 1.53, 46.67], [2, 1.52, 176.66]], "batl": [[0, 1.55, 1289.57], [1, 1.56, 49.54], [2, 1.57, 200.87]]}, {"timestamp": 1578769473024, "ltp": 1.54, "tv": 3530.59, "trd": NaN, "batb": [[1, 1.53, 61.67]], "batl": NaN}, {"timestamp": 1578769501985, "ltp": 1.54, "tv": 3548.51, "trd": [[1.54, 1068.17]], "batb": [[0, 1.53, 61.67], [1, 1.52, 176.66], [2, 1.51, 574.33]], "batl": [[0, 1.55, 1290.26]]}, {"timestamp": 1578769503994, "ltp": 1.54, "tv": 3548.51, "trd": NaN, "batb": [[0, 1.53, 71.04]], "batl": NaN}, {"timestamp": 1578769591984, "ltp": 1.55, "tv": 3676.62, "trd": [[1.54, 1068.86], [1.55, 140.61]], "batb": [[0, 1.54, 15.17], [1, 1.53, 71.04], [2, 1.52, 176.66]], "batl": [[0, 1.55, 1162.15]]}, {"timestamp": 1578769593001, "ltp": 1.55, "tv": 3676.62, "trd": NaN, "batb": [[0, 1.54, 18.6]], "batl": NaN}, {"timestamp": 1578769594009, "ltp": 1.55, "tv": 3676.62, "trd": NaN, "batb": [[0, 1.54, 33.6], [1, 1.53, 71.73]], "batl": [[0, 1.55, 1173]]}, {"timestamp": 1578769595015, "ltp": 1.55, "tv": 4906.74, "trd": [[1.55, 1370.74]], "batb": [[0, 1.54, 73.6]], "batl": [[0, 1.55, 557.93]]}, {"timestamp": 1578769595973, "ltp": 1.55, "tv": 4906.74, "trd": NaN, "batb": NaN, "batl": [[0, 1.55, 1305.48]]}, {"timestamp": 1578769602027, "ltp": 1.55, "tv": 4906.74, "trd": NaN, "batb": [[0, 1.54, 58.43]], "batl": NaN}, {"timestamp": 1578769602986, "ltp": 1.55, "tv": 4906.74, "trd": NaN, "batb": [[0, 1.54, 226.97]], "batl": NaN}, {"timestamp": 1578769603985, "ltp": 1.55, "tv": 4906.74, "trd": NaN, "batb": [[1, 1.53, 190.58]], "batl": NaN}, {"timestamp": 1578769622855, "ltp": 1.55, "tv": 4906.74, "trd": NaN, "batb": [[0, 1.54, 242.66]], "batl": NaN}, {"timestamp": 1578769624029, "ltp": 1.55, "tv": 4906.74, "trd": NaN, "batb": [[1, 1.53, 232.15]], "batl": NaN}, {"timestamp": 1578769631985, "ltp": 1.55, "tv": 4906.74, "trd": NaN, "batb": [[0, 1.54, 472.26]], "batl": NaN}, {"timestamp": 1578769731823, "ltp": 1.54, "tv": 4912.87, "trd": [[1.54, 1074.98]], "batb": [[0, 1.54, 469.2]], "batl": NaN}, {"timestamp": 1578769753056, "ltp": 1.54, "tv": 4912.87, "trd": NaN, "batb": NaN, "batl": [[0, 1.55, 1294.64]]}, {"timestamp": 1578769755868, "ltp": 1.54, "tv": 4912.87, "trd": NaN, "batb": NaN, "batl": [[0, 1.55, 1311.89]]}, {"timestamp": 1578769763872, "ltp": 1.54, "tv": 4917.46, "trd": [[1.54, 1079.58]], "batb": [[0, 1.54, 466.9]], "batl": NaN}, {"timestamp": 1578769813983, "ltp": 1.54, "tv": 5075.98, "trd": [[1.54, 1238.1]], "batb": [[0, 1.54, 432.64]], "batl": [[0, 1.55, 1356.89]]}, {"timestamp": 1578769815688, "ltp": 1.54, "tv": 5075.98, "trd": NaN, "batb": NaN, "batl": [[0, 1.55, 1371.89]]}, {"timestamp": 1578769835965, "ltp": 1.54, "tv": 5075.98, "trd": NaN, "batb": NaN, "batl": [[0, 1.55, 77.25]]}, {"timestamp": 1578769836769, "ltp": 1.54, "tv": 5075.98, "trd": NaN, "batb": NaN, "batl": [[0, 1.55, 15]]}, {"timestamp": 1578769838967, "ltp": 1.54, "tv": 5075.98, "trd": NaN, "batb": NaN, "batl": [[0, 1.55, 875.2]]}, {"timestamp": 1578769839982, "ltp": 1.54, "tv": 5075.98, "trd": NaN, "batb": NaN, "batl": [[0, 1.55, 937.46]]}, {"timestamp": 1578769870996, "ltp": 1.54, "tv": 5161.44, "trd": [[1.54, 1323.56]], "batb": [[0, 1.54, 389.91]], "batl": NaN}, {"timestamp": 1578769872943, "ltp": 1.54, "tv": 5161.44, "trd": NaN, "batb": [[2, 1.52, 657.65]], "batl": NaN}, {"timestamp": 1578769900933, "ltp": 1.54, "tv": 5161.44, "trd": NaN, "batb": [[0, 1.54, 394.91]], "batl": [[0, 1.55, 942.46]]}, {"timestamp": 1578769901965, "ltp": 1.54, "tv": 5161.44, "trd": NaN, "batb": NaN, "batl": [[0, 1.55, 82.26]]}, {"timestamp": 1578769902559, "ltp": 1.54, "tv": 5161.44, "trd": NaN, "batb": NaN, "batl": [[0, 1.55, 20]]}, {"timestamp": 1578769903959, "ltp": 1.54, "tv": 5161.44, "trd": NaN, "batb": [[2, 1.52, 176.66]], "batl": NaN}, {"timestamp": 1578769920979, "ltp": 1.54, "tv": 5161.44, "trd": NaN, "batb": NaN, "batl": [[0, 1.55, 700.95]]}, {"timestamp": 1578769921978, "ltp": 1.54, "tv": 5161.44, "trd": NaN, "batb": NaN, "batl": [[0, 1.55, 763.2]]}, {"timestamp": 1578769925679, "ltp": 1.54, "tv": 5161.44, "trd": NaN, "batb": NaN, "batl": [[0, 1.55, 768]]}, {"timestamp": 1578769936970, "ltp": 1.54, "tv": 5161.44, "trd": NaN, "batb": NaN, "batl": [[0, 1.55, 763.2]]}, {"timestamp": 1578769953917, "ltp": 1.54, "tv": 5201.45, "trd": [[1.54, 1363.57]], "batb": [[0, 1.54, 374.9]], "batl": NaN}, {"timestamp": 1578769989897, "ltp": 1.54, "tv": 5201.45, "trd": NaN, "batb": NaN, "batl": [[0, 1.55, 745.95]]}, {"timestamp": 1578770024970, "ltp": 1.54, "tv": 5399.69, "trd": [[1.54, 1561.81]], "batb": [[0, 1.54, 293.17]], "batl": NaN}, {"timestamp": 1578770056834, "ltp": 1.54, "tv": 5399.69, "trd": NaN, "batb": NaN, "batl": [[0, 1.55, 763.2]]}, {"timestamp": 1578770071044, "ltp": 1.54, "tv": 5399.69, "trd": NaN, "batb": [[2, 1.52, 657.65]], "batl": NaN}, {"timestamp": 1578770072035, "ltp": 1.54, "tv": 5399.69, "trd": NaN, "batb": NaN, "batl": [[0, 1.55, 765.63]]}, {"timestamp": 1578770099972, "ltp": 1.54, "tv": 5399.69, "trd": NaN, "batb": [[2, 1.52, 176.66]], "batl": NaN}, {"timestamp": 1578770162968, "ltp": 1.54, "tv": 5399.69, "trd": NaN, "batb": [[0, 1.54, 446.72]], "batl": NaN}, {"timestamp": 1578770163931, "ltp": 1.54, "tv": 5399.69, "trd": NaN, "batb": NaN, "batl": [[0, 1.55, 745.95]]}, {"timestamp": 1578770186019, "ltp": 1.54, "tv": 5399.69, "trd": NaN, "batb": NaN, "batl": [[0, 1.55, 763.2]]}, {"timestamp": 1578770193998, "ltp": 1.54, "tv": 5399.69, "trd": NaN, "batb": [[2, 1.52, 180.44]], "batl": NaN}, {"timestamp": 1578770244952, "ltp": 1.54, "tv": 5399.69, "trd": NaN, "batb": NaN, "batl": [[0, 1.55, 82.25]]}, {"timestamp": 1578770245993, "ltp": 1.54, "tv": 5399.69, "trd": NaN, "batb": NaN, "batl": [[0, 1.55, 20]]}, {"timestamp": 1578770251807, "ltp": 1.54, "tv": 5399.69, "trd": NaN, "batb": [[0, 1.54, 490.77], [1, 1.53, 704.14]], "batl": NaN}, {"timestamp": 1578770263979, "ltp": 1.54, "tv": 5399.69, "trd": NaN, "batb": [[0, 1.54, 446.72], [1, 1.53, 232.15]], "batl": NaN}, {"timestamp": 1578770264996, "ltp": 1.54, "tv": 5399.69, "trd": NaN, "batb": [[2, 1.52, 661.43]], "batl": NaN}, {"timestamp": 1578770268896, "ltp": 1.55, "tv": 5439.68, "trd": [[1.55, 1410.73]], "batb": [[0, 1.55, 133.56], [1, 1.54, 446.72], [2, 1.53, 232.15]], "batl": [[0, 1.56, 49.54], [1, 1.57, 200.87], [2, 1.59, 154.15]]}, {"timestamp": 1578770269809, "ltp": 1.55, "tv": 5439.68, "trd": NaN, "batb": [[1, 1.54, 466.72]], "batl": NaN}, {"timestamp": 1578770276040, "ltp": 1.55, "tv": 5706.81, "trd": [[1.55, 1677.85]], "batb": [[0, 1.54, 466.72], [1, 1.53, 232.15], [2, 1.52, 661.43]], "batl": [[0, 1.55, 554.17], [1, 1.56, 49.54], [2, 1.57, 200.87]]}, {"timestamp": 1578770276889, "ltp": 1.55, "tv": 5706.81, "trd": NaN, "batb": NaN, "batl": [[0, 1.55, 625.78]]}, {"timestamp": 1578770278015, "ltp": 1.55, "tv": 5706.81, "trd": NaN, "batb": [[0, 1.54, 511.45]], "batl": [[0, 1.56, 49.54], [1, 1.57, 200.87], [2, 1.59, 154.15]]}, {"timestamp": 1578770279014, "ltp": 1.55, "tv": 5706.81, "trd": NaN, "batb": [[0, 1.54, 543.16]], "batl": NaN}, {"timestamp": 1578770284796, "ltp": 1.55, "tv": 5706.81, "trd": NaN, "batb": NaN, "batl": [[2, 1.58, 45]]}, {"timestamp": 1578770287031, "ltp": 1.54, "tv": 5768.03, "trd": [[1.54, 1623.04]], "batb": [[0, 1.54, 512.54]], "batl": NaN}, {"timestamp": 1578770310962, "ltp": 1.54, "tv": 5768.03, "trd": NaN, "batb": NaN, "batl": [[0, 1.55, 913.5], [1, 1.56, 49.54], [2, 1.57, 200.87]]}, {"timestamp": 1578770311954, "ltp": 1.54, "tv": 5768.03, "trd": NaN, "batb": [[0, 1.54, 467.81]], "batl": [[0, 1.55, 985.15]]}, {"timestamp": 1578770315938, "ltp": 1.54, "tv": 5768.03, "trd": NaN, "batb": NaN, "batl": [[0, 1.55, 71.65]]}, {"timestamp": 1578770317043, "ltp": 1.54, "tv": 5768.03, "trd": NaN, "batb": [[0, 1.54, 512.44]], "batl": [[0, 1.56, 49.54], [1, 1.57, 200.87], [2, 1.58, 45]]}, {"timestamp": 1578770318977, "ltp": 1.54, "tv": 5768.03, "trd": NaN, "batb": NaN, "batl": [[0, 1.55, 905.69], [1, 1.56, 49.54], [2, 1.57, 200.87]]}, {"timestamp": 1578770319981, "ltp": 1.54, "tv": 5768.03, "trd": NaN, "batb": [[0, 1.54, 467.81]], "batl": [[0, 1.55, 977.34]]}, {"timestamp": 1578770321042, "ltp": 1.54, "tv": 5768.03, "trd": NaN, "batb": [[0, 1.54, 436.11]], "batl": NaN}, {"timestamp": 1578770322049, "ltp": 1.54, "tv": 5768.03, "trd": NaN, "batb": [[2, 1.52, 180.44]], "batl": NaN}, {"timestamp": 1578770324055, "ltp": 1.54, "tv": 5768.03, "trd": NaN, "batb": [[1, 1.53, 704.14]], "batl": NaN}, {"timestamp": 1578770335999, "ltp": 1.54, "tv": 5768.03, "trd": NaN, "batb": [[0, 1.54, 391.11]], "batl": NaN}, {"timestamp": 1578770353991, "ltp": 1.54, "tv": 5768.03, "trd": NaN, "batb": [[1, 1.53, 232.15], [2, 1.52, 661.43]], "batl": NaN}, {"timestamp": 1578770359015, "ltp": 1.55, "tv": 5777.03, "trd": [[1.55, 1686.85]], "batb": NaN, "batl": [[0, 1.55, 972.84]]}, {"timestamp": 1578770384000, "ltp": 1.55, "tv": 5783.57, "trd": [[1.55, 1693.39]], "batb": NaN, "batl": [[0, 1.55, 969.57]]}, {"timestamp": 1578770414050, "ltp": 1.55, "tv": 5783.57, "trd": NaN, "batb": NaN, "batl": [[0, 1.55, 71.65]]}, {"timestamp": 1578770414753, "ltp": 1.55, "tv": 5783.57, "trd": NaN, "batb": [[0, 1.54, 436.11]], "batl": [[0, 1.55, 45]]}, {"timestamp": 1578770415991, "ltp": 1.55, "tv": 5783.57, "trd": NaN, "batb": [[2, 1.52, 180.44]], "batl": [[0, 1.56, 49.54], [1, 1.57, 200.87], [2, 1.58, 45]]}, {"timestamp": 1578770416990, "ltp": 1.55, "tv": 5783.57, "trd": NaN, "batb": NaN, "batl": [[0, 1.55, 736.87], [1, 1.56, 49.54], [2, 1.57, 200.87]]}, {"timestamp": 1578770417950, "ltp": 1.55, "tv": 5783.57, "trd": NaN, "batb": NaN, "batl": [[0, 1.55, 781.87]]}, {"timestamp": 1578770433976, "ltp": 1.55, "tv": 5783.57, "trd": NaN, "batb": NaN, "batl": [[0, 1.55, 45]]}, {"timestamp": 1578770434989, "ltp": 1.55, "tv": 5783.57, "trd": NaN, "batb": NaN, "batl": [[0, 1.56, 49.54], [1, 1.57, 200.87], [2, 1.58, 45]]}, {"timestamp": 1578770437016, "ltp": 1.55, "tv": 5783.57, "trd": NaN, "batb": NaN, "batl": [[0, 1.55, 929.77], [1, 1.56, 49.54], [2, 1.57, 200.87]]}, {"timestamp": 1578770437965, "ltp": 1.55, "tv": 5783.57, "trd": NaN, "batb": NaN, "batl": [[0, 1.55, 974.77]]}, {"timestamp": 1578770442016, "ltp": 1.55, "tv": 5783.57, "trd": NaN, "batb": [[2, 1.52, 661.43]], "batl": NaN}, {"timestamp": 1578770443908, "ltp": 1.55, "tv": 5783.57, "trd": NaN, "batb": NaN, "batl": [[0, 1.55, 1000.14]]}, {"timestamp": 1578770449896, "ltp": 1.55, "tv": 5783.57, "trd": NaN, "batb": NaN, "batl": [[0, 1.55, 70.37]]}, {"timestamp": 1578770451000, "ltp": 1.55, "tv": 5783.57, "trd": NaN, "batb": NaN, "batl": [[0, 1.55, 25.37]]}, {"timestamp": 1578770452006, "ltp": 1.55, "tv": 5783.57, "trd": NaN, "batb": NaN, "batl": [[0, 1.56, 49.54], [1, 1.57, 200.87], [2, 1.58, 45]]}, {"timestamp": 1578770452904, "ltp": 1.55, "tv": 5783.57, "trd": NaN, "batb": NaN, "batl": [[0, 1.55, 794.23], [1, 1.56, 49.54], [2, 1.57, 200.87]]}, {"timestamp": 1578770454013, "ltp": 1.55, "tv": 5783.57, "trd": NaN, "batb": NaN, "batl": [[0, 1.55, 864.62]]}, {"timestamp": 1578770460617, "ltp": 1.55, "tv": 5783.57, "trd": NaN, "batb": NaN, "batl": [[0, 1.55, 866.32]]}, {"timestamp": 1578770467858, "ltp": 1.55, "tv": 5783.57, "trd": NaN, "batb": NaN, "batl": [[0, 1.55, 72.09]]}, {"timestamp": 1578770469037, "ltp": 1.55, "tv": 5783.57, "trd": NaN, "batb": NaN, "batl": [[0, 1.55, 1.7]]}, {"timestamp": 1578770469937, "ltp": 1.55, "tv": 5783.57, "trd": NaN, "batb": NaN, "batl": [[2, 1.57, 422.87]]}, {"timestamp": 1578770474933, "ltp": 1.55, "tv": 5783.57, "trd": NaN, "batb": NaN, "batl": [[1, 1.56, 271.54]]}, {"timestamp": 1578770496940, "ltp": 1.55, "tv": 5783.57, "trd": NaN, "batb": NaN, "batl": [[0, 1.55, 5.12]]}, {"timestamp": 1578770499052, "ltp": 1.55, "tv": 5783.57, "trd": NaN, "batb": [[0, 1.54, 479.99]], "batl": NaN}, {"timestamp": 1578770499951, "ltp": 1.55, "tv": 5783.57, "trd": NaN, "batb": NaN, "batl": [[0, 1.55, 942.57]]}, {"timestamp": 1578770500956, "ltp": 1.55, "tv": 5783.57, "trd": NaN, "batb": [[0, 1.54, 441.11]], "batl": [[0, 1.55, 1021.81]]}, {"timestamp": 1578770520049, "ltp": 1.55, "tv": 5783.57, "trd": NaN, "batb": [[2, 1.52, 180.44]], "batl": NaN}, {"timestamp": 1578770539990, "ltp": 1.55, "tv": 5783.57, "trd": NaN, "batb": [[2, 1.52, 724.43]], "batl": [[0, 1.55, 1025.81]]}, {"timestamp": 1578770557020, "ltp": 1.55, "tv": 5850.59, "trd": [[1.55, 1760.41]], "batb": NaN, "batl": [[0, 1.55, 924.55]]}, {"timestamp": 1578770572021, "ltp": 1.55, "tv": 5922.86, "trd": [[1.55, 1832.68]], "batb": NaN, "batl": [[0, 1.55, 888.42]]}, {"timestamp": 1578770573036, "ltp": 1.55, "tv": 5922.86, "trd": NaN, "batb": [[2, 1.52, 180.44]], "batl": NaN}, {"timestamp": 1578770574046, "ltp": 1.55, "tv": 5922.86, "trd": NaN, "batb": NaN, "batl": [[0, 1.55, 914.53]]}, {"timestamp": 1578770578942, "ltp": 1.55, "tv": 5922.86, "trd": NaN, "batb": [[0, 1.54, 472.81]], "batl": [[0, 1.55, 888.42]]}, {"timestamp": 1578770579650, "ltp": 1.55, "tv": 5922.86, "trd": NaN, "batb": NaN, "batl": [[0, 1.55, 914.54]]}, {"timestamp": 1578770584956, "ltp": 1.54, "tv": 6172.36, "trd": [[1.54, 1872.54]], "batb": [[0, 1.54, 348.06]], "batl": NaN}, {"timestamp": 1578770585979, "ltp": 1.54, "tv": 6172.36, "trd": NaN, "batb": NaN, "batl": [[0, 1.55, 888.42]]}, {"timestamp": 1578770587048, "ltp": 1.54, "tv": 6172.36, "trd": NaN, "batb": [[0, 1.54, 316.36]], "batl": [[0, 1.55, 914.52]]}, {"timestamp": 1578770594880, "ltp": 1.54, "tv": 6172.36, "trd": NaN, "batb": NaN, "batl": [[0, 1.55, 888.42]]}, {"timestamp": 1578770595952, "ltp": 1.54, "tv": 6280.74, "trd": [[1.54, 1980.92]], "batb": [[0, 1.54, 189.25]], "batl": [[0, 1.55, 914.52]]}, {"timestamp": 1578770596964, "ltp": 1.54, "tv": 6280.74, "trd": NaN, "batb": NaN, "batl": [[0, 1.55, 1144.12]]}, {"timestamp": 1578770597968, "ltp": 1.54, "tv": 6280.74, "trd": NaN, "batb": NaN, "batl": [[0, 1.55, 1149.12]]}, {"timestamp": 1578770616012, "ltp": 1.54, "tv": 6280.74, "trd": NaN, "batb": NaN, "batl": [[0, 1.55, 309.7]]}, {"timestamp": 1578770617013, "ltp": 1.54, "tv": 6280.74, "trd": NaN, "batb": [[0, 1.54, 234.25]], "batl": NaN}, {"timestamp": 1578770620976, "ltp": 1.54, "tv": 6280.74, "trd": NaN, "batb": [[0, 1.54, 237.69]], "batl": NaN}, {"timestamp": 1578770627998, "ltp": 1.54, "tv": 6280.74, "trd": NaN, "batb": [[1, 1.53, 376.56]], "batl": NaN}, {"timestamp": 1578770630895, "ltp": 1.54, "tv": 6299.11, "trd": [[1.54, 1999.28]], "batb": [[0, 1.54, 228.51]], "batl": NaN}, {"timestamp": 1578770652017, "ltp": 1.54, "tv": 6299.11, "trd": NaN, "batb": [[2, 1.52, 963.18]], "batl": NaN}, {"timestamp": 1578770671040, "ltp": 1.54, "tv": 6579.6, "trd": [[1.54, 2279.78]], "batb": [[0, 1.54, 88.26]], "batl": [[0, 1.55, 319.7]]}, {"timestamp": 1578770672046, "ltp": 1.54, "tv": 6579.6, "trd": NaN, "batb": [[0, 1.54, 16.99]], "batl": NaN}, {"timestamp": 1578770672957, "ltp": 1.54, "tv": 6579.6, "trd": NaN, "batb": [[1, 1.53, 233.55]], "batl": NaN}, {"timestamp": 1578770673959, "ltp": 1.54, "tv": 6613.1, "trd": [[1.54, 2313.28]], "batb": [[0, 1.53, 233.79], [1, 1.52, 963.18], [2, 1.51, 182.34]], "batl": [[0, 1.55, 339.7]]}, {"timestamp": 1578770675053, "ltp": 1.54, "tv": 6613.1, "trd": NaN, "batb": NaN, "batl": [[0, 1.55, 371.41]]}, {"timestamp": 1578770681960, "ltp": 1.54, "tv": 6613.34, "trd": [[1.54, 2313.52]], "batb": [[0, 1.53, 233.55]], "batl": NaN}, {"timestamp": 1578770683055, "ltp": 1.54, "tv": 6613.34, "trd": NaN, "batb": [[0, 1.53, 279.48]], "batl": NaN}, {"timestamp": 1578770691051, "ltp": 1.54, "tv": 6613.34, "trd": NaN, "batb": [[1, 1.52, 180.44], [2, 1.51, 913.74]], "batl": NaN}, {"timestamp": 1578770696966, "ltp": 1.54, "tv": 6613.34, "trd": NaN, "batb": [[0, 1.53, 233.55]], "batl": [[0, 1.54, 25.97], [1, 1.55, 529.19], [2, 1.56, 271.54]]}, {"timestamp": 1578770698974, "ltp": 1.54, "tv": 6621.35, "trd": [[1.54, 2321.52]], "batb": NaN, "batl": [[0, 1.54, 21.97]]}, {"timestamp": 1578770700004, "ltp": 1.54, "tv": 6621.35, "trd": NaN, "batb": NaN, "batl": [[0, 1.55, 529.19], [1, 1.56, 271.54], [2, 1.57, 422.87]]}, {"timestamp": 1578770701008, "ltp": 1.54, "tv": 6671.27, "trd": [[1.54, 2371.44]], "batb": [[0, 1.54, 10], [1, 1.53, 233.55], [2, 1.52, 180.44]], "batl": [[0, 1.55, 531.19]]}, {"timestamp": 1578770702021, "ltp": 1.53, "tv": 6800.62, "trd": [[1.53, 2293.46], [1.54, 2401.44]], "batb": [[0, 1.53, 139.42], [1, 1.52, 180.44], [2, 1.51, 913.74]], "batl": [[0, 1.54, 39.04], [1, 1.55, 531.19], [2, 1.56, 271.54]]}, {"timestamp": 1578770702982, "ltp": 1.53, "tv": 6800.62, "trd": NaN, "batb": [[0, 1.53, 162.22]], "batl": [[0, 1.54, 74.96]]}, {"timestamp": 1578770703999, "ltp": 1.53, "tv": 6800.62, "trd": NaN, "batb": [[0, 1.53, 220.95]], "batl": [[0, 1.54, 92.99]]}, {"timestamp": 1578770720019, "ltp": 1.53, "tv": 7503.09, "trd": [[1.53, 2995.93]], "batb": [[0, 1.52, 376.88], [1, 1.51, 913.74], [2, 1.5, 139.34]], "batl": [[0, 1.54, 96.9]]}, {"timestamp": 1578770721032, "ltp": 1.53, "tv": 7503.09, "trd": NaN, "batb": NaN, "batl": [[0, 1.54, 231.5]]}, {"timestamp": 1578770722032, "ltp": 1.53, "tv": 7503.09, "trd": NaN, "batb": NaN, "batl": [[0, 1.54, 235.56]]}, {"timestamp": 1578770722999, "ltp": 1.53, "tv": 7503.09, "trd": NaN, "batb": [[0, 1.53, 75.63], [1, 1.52, 376.88], [2, 1.51, 913.74]], "batl": [[0, 1.54, 235.55]]}, {"timestamp": 1578770725017, "ltp": 1.53, "tv": 7503.09, "trd": NaN, "batb": NaN, "batl": [[0, 1.54, 231.5]]}, {"timestamp": 1578770726012, "ltp": 1.53, "tv": 7503.09, "trd": NaN, "batb": NaN, "batl": [[0, 1.54, 235.53]]}, {"timestamp": 1578770726935, "ltp": 1.53, "tv": 7503.09, "trd": NaN, "batb": NaN, "batl": [[1, 1.55, 499.49]]}, {"timestamp": 1578770728030, "ltp": 1.53, "tv": 7503.09, "trd": NaN, "batb": NaN, "batl": [[0, 1.54, 235.51]]}, {"timestamp": 1578770730004, "ltp": 1.53, "tv": 7503.09, "trd": NaN, "batb": NaN, "batl": [[0, 1.54, 235.49]]}, {"timestamp": 1578770741017, "ltp": 1.53, "tv": 7503.09, "trd": NaN, "batb": NaN, "batl": [[0, 1.54, 231.5]]}, {"timestamp": 1578770744035, "ltp": 1.53, "tv": 7503.09, "trd": NaN, "batb": [[1, 1.52, 1118.12], [2, 1.51, 182.34]], "batl": NaN}, {"timestamp": 1578770745031, "ltp": 1.53, "tv": 7506.83, "trd": [[1.53, 2999.67]], "batb": [[0, 1.53, 73.76]], "batl": NaN}, {"timestamp": 1578770771961, "ltp": 1.53, "tv": 7542.3, "trd": [[1.53, 3004.53], [1.54, 2432.06]], "batb": [[0, 1.53, 86.34]], "batl": [[0, 1.54, 216.19]]}, {"timestamp": 1578770772969, "ltp": 1.53, "tv": 7542.3, "trd": NaN, "batb": NaN, "batl": [[0, 1.54, 301.31]]}, {"timestamp": 1578770776037, "ltp": 1.53, "tv": 7542.3, "trd": NaN, "batb": NaN, "batl": [[1, 1.55, 503.75]]}, {"timestamp": 1578770776881, "ltp": 1.53, "tv": 7542.3, "trd": NaN, "batb": NaN, "batl": [[0, 1.54, 551.31]]}, {"timestamp": 1578770778964, "ltp": 1.53, "tv": 7542.3, "trd": NaN, "batb": [[0, 1.53, 113.86]], "batl": NaN}, {"timestamp": 1578770779878, "ltp": 1.53, "tv": 7542.3, "trd": NaN, "batb": [[0, 1.53, 86.34]], "batl": NaN}, {"timestamp": 1578770782983, "ltp": 1.53, "tv": 7542.3, "trd": NaN, "batb": NaN, "batl": [[0, 1.54, 636.43]]}, {"timestamp": 1578770803973, "ltp": 1.53, "tv": 7542.3, "trd": NaN, "batb": NaN, "batl": [[0, 1.54, 639.93]]}, {"timestamp": 1578770843022, "ltp": 1.53, "tv": 7542.3, "trd": NaN, "batb": NaN, "batl": [[0, 1.54, 639.6]]}, {"timestamp": 1578770844945, "ltp": 1.53, "tv": 7624.68, "trd": [[1.53, 3086.91]], "batb": [[0, 1.53, 45.15]], "batl": NaN}, {"timestamp": 1578770852965, "ltp": 1.54, "tv": 7924.68, "trd": [[1.54, 2732.06]], "batb": NaN, "batl": [[0, 1.54, 489.61]]}, {"timestamp": 1578770853854, "ltp": 1.54, "tv": 7924.68, "trd": NaN, "batb": [[0, 1.53, 82.68]], "batl": [[0, 1.54, 561.96]]}, {"timestamp": 1578770856957, "ltp": 1.54, "tv": 7924.68, "trd": NaN, "batb": NaN, "batl": [[0, 1.54, 566.21], [1, 1.55, 499.49]]}, {"timestamp": 1578770863981, "ltp": 1.53, "tv": 8090.02, "trd": [[1.53, 3252.26]], "batb": [[0, 1.52, 1163.3], [1, 1.51, 182.34], [2, 1.5, 139.34]], "batl": [[0, 1.53, 146.93], [1, 1.54, 566.21], [2, 1.55, 499.49]]}, {"timestamp": 1578770864987, "ltp": 1.53, "tv": 8090.02, "trd": NaN, "batb": [[0, 1.52, 994.96]], "batl": [[1, 1.54, 622.92]]}, {"timestamp": 1578770866054, "ltp": 1.53, "tv": 8094.02, "trd": [[1.53, 3256.25]], "batb": NaN, "batl": [[0, 1.53, 172.16]]}, {"timestamp": 1578770868985, "ltp": 1.53, "tv": 8094.02, "trd": NaN, "batb": NaN, "batl": [[0, 1.53, 144.93]]}, {"timestamp": 1578770869990, "ltp": 1.53, "tv": 8094.02, "trd": NaN, "batb": NaN, "batl": [[0, 1.53, 172.16]]}, {"timestamp": 1578770870798, "ltp": 1.53, "tv": 8094.02, "trd": NaN, "batb": NaN, "batl": [[0, 1.53, 144.93], [1, 1.54, 852.52]]}, {"timestamp": 1578770871979, "ltp": 1.53, "tv": 8094.02, "trd": NaN, "batb": NaN, "batl": [[0, 1.53, 172.16]]}, {"timestamp": 1578770873000, "ltp": 1.53, "tv": 8094.02, "trd": NaN, "batb": NaN, "batl": [[0, 1.53, 144.93], [1, 1.54, 820.82]]}, {"timestamp": 1578770874973, "ltp": 1.53, "tv": 8094.02, "trd": NaN, "batb": [[0, 1.52, 1084.97]], "batl": NaN}, {"timestamp": 1578770875985, "ltp": 1.53, "tv": 8220.59, "trd": [[1.53, 3382.83]], "batb": NaN, "batl": [[0, 1.53, 81.65]]}, {"timestamp": 1578770880008, "ltp": 1.53, "tv": 8220.59, "trd": NaN, "batb": NaN, "batl": [[0, 1.53, 89.12]]}, {"timestamp": 1578770885994, "ltp": 1.53, "tv": 8220.59, "trd": NaN, "batb": [[2, 1.5, 184.34]], "batl": NaN}, {"timestamp": 1578770889020, "ltp": 1.53, "tv": 8220.59, "trd": NaN, "batb": NaN, "batl": [[0, 1.53, 160.72]]}, {"timestamp": 1578770898020, "ltp": 1.53, "tv": 8220.59, "trd": NaN, "batb": NaN, "batl": [[0, 1.53, 153.25]]}, {"timestamp": 1578770903005, "ltp": 1.52, "tv": 8260.6, "trd": [[1.52, 193.47]], "batb": [[0, 1.52, 1064.97]], "batl": NaN}, {"timestamp": 1578770903941, "ltp": 1.52, "tv": 8260.6, "trd": NaN, "batb": [[0, 1.52, 1092.43]], "batl": [[0, 1.53, 192.04]]}, {"timestamp": 1578770910032, "ltp": 1.52, "tv": 8260.6, "trd": NaN, "batb": [[0, 1.52, 1234.25]], "batl": NaN}, {"timestamp": 1578770914046, "ltp": 1.52, "tv": 8260.6, "trd": NaN, "batb": [[0, 1.52, 1092.43]], "batl": NaN}, {"timestamp": 1578770918012, "ltp": 1.53, "tv": 8279.72, "trd": [[1.53, 3401.94]], "batb": NaN, "batl": [[0, 1.53, 172.93]]}, {"timestamp": 1578770918952, "ltp": 1.53, "tv": 8279.72, "trd": NaN, "batb": [[0, 1.52, 1235.65]], "batl": [[1, 1.54, 1042.82]]}, {"timestamp": 1578770920056, "ltp": 1.53, "tv": 8279.72, "trd": NaN, "batb": [[0, 1.52, 1371.59]], "batl": [[0, 1.53, 172.94]]}, {"timestamp": 1578770920934, "ltp": 1.53, "tv": 8279.72, "trd": NaN, "batb": NaN, "batl": [[0, 1.53, 228.43]]}, {"timestamp": 1578770922043, "ltp": 1.53, "tv": 8279.72, "trd": NaN, "batb": NaN, "batl": [[0, 1.53, 201.12]]}, {"timestamp": 1578770924044, "ltp": 1.53, "tv": 8279.72, "trd": NaN, "batb": NaN, "batl": [[1, 1.54, 1236.52]]}, {"timestamp": 1578770928964, "ltp": 1.53, "tv": 8279.72, "trd": NaN, "batb": NaN, "batl": [[0, 1.53, 423.12]]}, {"timestamp": 1578770929955, "ltp": 1.53, "tv": 8279.72, "trd": NaN, "batb": NaN, "batl": [[0, 1.53, 450.41]]}, {"timestamp": 1578770931944, "ltp": 1.52, "tv": 8294.66, "trd": [[1.52, 208.41]], "batb": [[0, 1.52, 1364.12]], "batl": [[0, 1.53, 457.88]]}, {"timestamp": 1578770944965, "ltp": 1.52, "tv": 8294.66, "trd": NaN, "batb": NaN, "batl": [[0, 1.53, 430.59]]}, {"timestamp": 1578770945972, "ltp": 1.52, "tv": 8294.66, "trd": NaN, "batb": NaN, "batl": [[0, 1.53, 496.79], [1, 1.54, 1170.33]]}, {"timestamp": 1578770949981, "ltp": 1.52, "tv": 8294.66, "trd": NaN, "batb": NaN, "batl": [[0, 1.53, 524.08]]}, {"timestamp": 1578770961981, "ltp": 1.52, "tv": 8313.34, "trd": [[1.52, 227.09]], "batb": [[0, 1.52, 1354.78]], "batl": NaN}, {"timestamp": 1578770962986, "ltp": 1.52, "tv": 8313.34, "trd": NaN, "batb": [[0, 1.52, 1242.03]], "batl": [[0, 1.53, 533.42]]}, {"timestamp": 1578770982926, "ltp": 1.53, "tv": 8319.74, "trd": [[1.53, 3408.34]], "batb": NaN, "batl": [[0, 1.53, 530.22]]}, {"timestamp": 1578770985932, "ltp": 1.53, "tv": 8319.74, "trd": NaN, "batb": NaN, "batl": [[0, 1.53, 780.22], [1, 1.54, 920.33]]}, {"timestamp": 1578770995980, "ltp": 1.53, "tv": 8319.74, "trd": NaN, "batb": NaN, "batl": [[0, 1.53, 860.22]]}, {"timestamp": 1578770997045, "ltp": 1.52, "tv": 8367.34, "trd": [[1.52, 274.69]], "batb": [[0, 1.52, 1218.23]], "batl": [[0, 1.53, 849.61]]}, {"timestamp": 1578770998048, "ltp": 1.53, "tv": 8466.54, "trd": [[1.53, 3507.55]], "batb": NaN, "batl": [[0, 1.53, 800.01]]}, {"timestamp": 1578770998940, "ltp": 1.53, "tv": 8466.54, "trd": NaN, "batb": NaN, "batl": [[0, 1.53, 803.32]]}, {"timestamp": 1578771000053, "ltp": 1.53, "tv": 8466.54, "trd": NaN, "batb": NaN, "batl": [[0, 1.53, 747.83]]}, {"timestamp": 1578771012005, "ltp": 1.53, "tv": 8627.47, "trd": [[1.53, 3668.48]], "batb": NaN, "batl": [[0, 1.53, 664.38]]}, {"timestamp": 1578771013973, "ltp": 1.53, "tv": 8627.47, "trd": NaN, "batb": [[2, 1.5, 317.34]], "batl": NaN}, {"timestamp": 1578771015040, "ltp": 1.53, "tv": 8627.47, "trd": NaN, "batb": [[1, 1.51, 314.34]], "batl": NaN}, {"timestamp": 1578771017735, "ltp": 1.53, "tv": 8627.47, "trd": NaN, "batb": [[0, 1.52, 1422.02]], "batl": NaN}, {"timestamp": 1578771018851, "ltp": 1.53, "tv": 8627.47, "trd": NaN, "batb": NaN, "batl": [[0, 1.53, 749.5]]}, {"timestamp": 1578771025041, "ltp": 1.53, "tv": 8630.76, "trd": [[1.53, 3671.77]], "batb": NaN, "batl": [[0, 1.53, 746.21]]}, {"timestamp": 1578771027941, "ltp": 1.53, "tv": 9135.4, "trd": [[1.52, 648.4], [1.53, 3802.69]], "batb": [[0, 1.52, 1235.17]], "batl": [[0, 1.53, 680.75]]}, {"timestamp": 1578771029905, "ltp": 1.53, "tv": 9135.4, "trd": NaN, "batb": NaN, "batl": [[0, 1.53, 823.65]]}, {"timestamp": 1578771034036, "ltp": 1.53, "tv": 9248.7, "trd": [[1.53, 3915.99]], "batb": NaN, "batl": [[0, 1.53, 767]]}, {"timestamp": 1578771038964, "ltp": 1.52, "tv": 9263.65, "trd": [[1.52, 663.36]], "batb": [[0, 1.52, 1227.69]], "batl": NaN}, {"timestamp": 1578771044949, "ltp": 1.53, "tv": 9307.63, "trd": [[1.53, 3959.97]], "batb": NaN, "batl": [[0, 1.53, 745.01]]}, {"timestamp": 1578771048980, "ltp": 1.53, "tv": 9435.13, "trd": [[1.53, 4087.46]], "batb": NaN, "batl": [[0, 1.53, 681.26]]}, {"timestamp": 1578771052902, "ltp": 1.52, "tv": 9465.13, "trd": [[1.52, 693.36]], "batb": [[0, 1.52, 1212.69]], "batl": NaN}, {"timestamp": 1578771058977, "ltp": 1.52, "tv": 9465.13, "trd": NaN, "batb": [[0, 1.52, 1359.87]], "batl": NaN}, {"timestamp": 1578771080920, "ltp": 1.53, "tv": 9494.93, "trd": [[1.53, 4117.26]], "batb": NaN, "batl": [[0, 1.53, 666.36]]}, {"timestamp": 1578771085046, "ltp": 1.53, "tv": 9494.93, "trd": NaN, "batb": NaN, "batl": [[0, 1.53, 674.02]]}, {"timestamp": 1578771108965, "ltp": 1.53, "tv": 9494.93, "trd": NaN, "batb": [[0, 1.52, 1484.64]], "batl": NaN}, {"timestamp": 1578771117969, "ltp": 1.53, "tv": 9494.93, "trd": NaN, "batb": [[0, 1.52, 1658.63]], "batl": NaN}, {"timestamp": 1578771121988, "ltp": 1.52, "tv": 9513.61, "trd": [[1.52, 712.04]], "batb": [[0, 1.52, 1649.29]], "batl": NaN}, {"timestamp": 1578771131019, "ltp": 1.52, "tv": 9513.61, "trd": NaN, "batb": NaN, "batl": [[0, 1.53, 666.36]]}, {"timestamp": 1578771132034, "ltp": 1.52, "tv": 9528.91, "trd": [[1.52, 727.34]], "batb": [[0, 1.52, 1641.64]], "batl": NaN}, {"timestamp": 1578771142050, "ltp": 1.53, "tv": 9963.03, "trd": [[1.53, 4551.38]], "batb": NaN, "batl": [[0, 1.53, 449.31]]}, {"timestamp": 1578771143954, "ltp": 1.53, "tv": 9969.69, "trd": [[1.53, 4558.04]], "batb": NaN, "batl": [[0, 1.53, 445.98]]}, {"timestamp": 1578771149959, "ltp": 1.53, "tv": 9969.69, "trd": NaN, "batb": [[1, 1.51, 182.34]], "batl": NaN}, {"timestamp": 1578771158864, "ltp": 1.53, "tv": 9973.69, "trd": [[1.53, 4562.04]], "batb": NaN, "batl": [[0, 1.53, 443.98]]}, {"timestamp": 1578771161989, "ltp": 1.53, "tv": 9973.69, "trd": NaN, "batb": [[0, 1.52, 1788.82]], "batl": NaN}, {"timestamp": 1578771162964, "ltp": 1.53, "tv": 10041.67, "trd": [[1.53, 4630.02]], "batb": NaN, "batl": [[0, 1.53, 409.99]]}, {"timestamp": 1578771176019, "ltp": 1.53, "tv": 10056.61, "trd": [[1.53, 4644.96]], "batb": NaN, "batl": [[0, 1.53, 395.05]]}, {"timestamp": 1578771178989, "ltp": 1.53, "tv": 10093.27, "trd": [[1.53, 4681.62]], "batb": NaN, "batl": [[0, 1.53, 376.72]]}, {"timestamp": 1578771180006, "ltp": 1.53, "tv": 10321.8, "trd": [[1.53, 4910.15]], "batb": [[0, 1.52, 2028.68]], "batl": [[0, 1.53, 262.45]]}, {"timestamp": 1578771181020, "ltp": 1.53, "tv": 10846.7, "trd": [[1.53, 5435.05]], "batb": [[0, 1.53, 71.6], [1, 1.52, 2073.68], [2, 1.51, 182.34]], "batl": [[0, 1.54, 974.45], [1, 1.55, 499.49], [2, 1.56, 271.54]]}, {"timestamp": 1578771183033, "ltp": 1.53, "tv": 10846.7, "trd": NaN, "batb": NaN, "batl": [[0, 1.54, 1087.61]]}, {"timestamp": 1578771184004, "ltp": 1.53, "tv": 10846.7, "trd": NaN, "batb": [[0, 1.52, 2073.68], [1, 1.51, 182.34], [2, 1.5, 317.34]], "batl": NaN}, {"timestamp": 1578771214972, "ltp": 1.53, "tv": 10846.7, "trd": NaN, "batb": [[0, 1.53, 71.6], [1, 1.52, 2073.68], [2, 1.51, 182.34]], "batl": NaN}, {"timestamp": 1578771216982, "ltp": 1.53, "tv": 10846.7, "trd": NaN, "batb": [[0, 1.53, 251.95]], "batl": NaN}, {"timestamp": 1578771217999, "ltp": 1.53, "tv": 10846.7, "trd": NaN, "batb": [[1, 1.52, 1191.67], [2, 1.51, 890.15]], "batl": NaN}, {"timestamp": 1578771224965, "ltp": 1.53, "tv": 10852.7, "trd": [[1.53, 5441.05]], "batb": [[0, 1.53, 248.95]], "batl": NaN}, {"timestamp": 1578771226909, "ltp": 1.53, "tv": 10852.7, "trd": NaN, "batb": [[0, 1.53, 397.73]], "batl": [[0, 1.54, 893.9]]}, {"timestamp": 1578771230008, "ltp": 1.53, "tv": 10852.7, "trd": NaN, "batb": [[0, 1.53, 442.73]], "batl": NaN}, {"timestamp": 1578771231007, "ltp": 1.53, "tv": 10852.7, "trd": NaN, "batb": [[0, 1.53, 310.95]], "batl": NaN}, {"timestamp": 1578771231970, "ltp": 1.53, "tv": 10852.7, "trd": NaN, "batb": [[0, 1.53, 453.48]], "batl": NaN}, {"timestamp": 1578771232974, "ltp": 1.53, "tv": 10852.7, "trd": NaN, "batb": [[0, 1.53, 498.48]], "batl": NaN}, {"timestamp": 1578771234807, "ltp": 1.53, "tv": 10852.7, "trd": NaN, "batb": [[0, 1.53, 635.06], [1, 1.52, 1334.98]], "batl": NaN}, {"timestamp": 1578771235810, "ltp": 1.53, "tv": 10852.7, "trd": NaN, "batb": [[0, 1.53, 690.8]], "batl": NaN}, {"timestamp": 1578771258054, "ltp": 1.53, "tv": 11012.7, "trd": [[1.53, 5601.05]], "batb": [[0, 1.53, 610.8]], "batl": NaN}, {"timestamp": 1578771264037, "ltp": 1.53, "tv": 11012.7, "trd": NaN, "batb": [[1, 1.52, 1664.98]], "batl": NaN}, {"timestamp": 1578771267043, "ltp": 1.53, "tv": 11012.7, "trd": NaN, "batb": [[0, 1.53, 752.66]], "batl": NaN}, {"timestamp": 1578771268055, "ltp": 1.53, "tv": 11012.7, "trd": NaN, "batb": [[2, 1.51, 182.34]], "batl": NaN}, {"timestamp": 1578771269959, "ltp": 1.53, "tv": 11012.7, "trd": NaN, "batb": NaN, "batl": [[2, 1.56, 399.54]]}, {"timestamp": 1578771280982, "ltp": 1.53, "tv": 11624.97, "trd": [[1.53, 6213.32]], "batb": [[0, 1.53, 632.94]], "batl": [[0, 1.54, 868.9], [1, 1.55, 464.49]]}, {"timestamp": 1578771281997, "ltp": 1.53, "tv": 11624.97, "trd": NaN, "batb": [[0, 1.53, 577.2]], "batl": NaN}, {"timestamp": 1578771282897, "ltp": 1.53, "tv": 11624.97, "trd": NaN, "batb": [[0, 1.53, 509.86]], "batl": [[0, 1.54, 900.61]]}, {"timestamp": 1578771283999, "ltp": 1.53, "tv": 11624.97, "trd": NaN, "batb": [[0, 1.53, 31.1], [1, 1.52, 1521.67]], "batl": NaN}, {"timestamp": 1578771288000, "ltp": 1.53, "tv": 11624.97, "trd": NaN, "batb": NaN, "batl": [[0, 1.54, 1102.47]]}, {"timestamp": 1578771291033, "ltp": 1.54, "tv": 11629.85, "trd": [[1.54, 2736.93]], "batb": NaN, "batl": [[0, 1.54, 1100.04]]}, {"timestamp": 1578771291991, "ltp": 1.53, "tv": 11692.04, "trd": [[1.53, 6275.51]], "batb": [[0, 1.52, 1521.67], [1, 1.51, 182.34], [2, 1.5, 928.74]], "batl": [[0, 1.53, 320.3], [1, 1.54, 1100.04], [2, 1.55, 464.49]]}, {"timestamp": 1578771292990, "ltp": 1.53, "tv": 11692.04, "trd": NaN, "batb": [[2, 1.5, 1054.4]], "batl": NaN}, {"timestamp": 1578771295018, "ltp": 1.53, "tv": 11692.04, "trd": NaN, "batb": [[2, 1.5, 1187.4]], "batl": NaN}, {"timestamp": 1578771298577, "ltp": 1.53, "tv": 12164.37, "trd": [[1.53, 6747.85]], "batb": NaN, "batl": [[0, 1.53, 84.14]]}, {"timestamp": 1578771300004, "ltp": 1.53, "tv": 12164.37, "trd": NaN, "batb": [[1, 1.51, 431.08]], "batl": NaN}, {"timestamp": 1578771301006, "ltp": 1.53, "tv": 12164.37, "trd": NaN, "batb": [[0, 1.52, 1525.22]], "batl": NaN}, {"timestamp": 1578771310022, "ltp": 1.53, "tv": 12164.37, "trd": NaN, "batb": [[0, 1.52, 1521.67]], "batl": NaN}, {"timestamp": 1578771320978, "ltp": 1.53, "tv": 12164.37, "trd": NaN, "batb": [[2, 1.5, 317.34]], "batl": NaN}, {"timestamp": 1578771322042, "ltp": 1.54, "tv": 12342.35, "trd": [[1.53, 6916.13], [1.54, 2746.63]], "batb": [[0, 1.52, 1518.39]], "batl": [[0, 1.53, 77.54], [1, 1.54, 1095.19]]}, {"timestamp": 1578771323040, "ltp": 1.54, "tv": 12342.35, "trd": NaN, "batb": [[0, 1.53, 140.24], [1, 1.52, 1518.39], [2, 1.51, 431.08]], "batl": [[0, 1.54, 1095.19], [1, 1.55, 464.49], [2, 1.56, 399.54]]}, {"timestamp": 1578771323960, "ltp": 1.54, "tv": 12342.35, "trd": NaN, "batb": [[0, 1.53, 592.31]], "batl": [[0, 1.54, 893.32]]}, {"timestamp": 1578771325054, "ltp": 1.54, "tv": 12342.35, "trd": NaN, "batb": [[0, 1.53, 632.88]], "batl": [[0, 1.54, 780.16]]}, {"timestamp": 1578771325972, "ltp": 1.54, "tv": 12342.35, "trd": NaN, "batb": [[1, 1.52, 1663.2]], "batl": NaN}, {"timestamp": 1578771327021, "ltp": 1.54, "tv": 12342.35, "trd": NaN, "batb": [[0, 1.53, 661.02]], "batl": [[0, 1.54, 748.45]]}, {"timestamp": 1578771328030, "ltp": 1.54, "tv": 12342.35, "trd": NaN, "batb": [[0, 1.53, 669.02]], "batl": NaN}, {"timestamp": 1578771334963, "ltp": 1.54, "tv": 12349.96, "trd": [[1.53, 6919.74], [1.54, 2750.63]], "batb": [[0, 1.53, 686.78], [1, 1.52, 1795.2], [2, 1.51, 563.08]], "batl": [[0, 1.54, 746.45], [2, 1.56, 271.54]]}, {"timestamp": 1578771336052, "ltp": 1.54, "tv": 12349.96, "trd": NaN, "batb": NaN, "batl": [[0, 1.54, 839.16]]}, {"timestamp": 1578771343985, "ltp": 1.54, "tv": 12349.96, "trd": NaN, "batb": [[0, 1.53, 667.21], [1, 1.52, 1663.2], [2, 1.51, 431.08]], "batl": NaN}, {"timestamp": 1578771345050, "ltp": 1.53, "tv": 12489.96, "trd": [[1.53, 7059.73]], "batb": [[0, 1.53, 597.21]], "batl": NaN}, {"timestamp": 1578771346891, "ltp": 1.53, "tv": 12489.96, "trd": NaN, "batb": NaN, "batl": [[0, 1.54, 916.6]]}, {"timestamp": 1578771348962, "ltp": 1.53, "tv": 12495.32, "trd": [[1.53, 7065.09]], "batb": [[0, 1.53, 594.53]], "batl": NaN}, {"timestamp": 1578771371030, "ltp": 1.54, "tv": 12533.74, "trd": [[1.54, 2789.05]], "batb": NaN, "batl": [[0, 1.54, 897.39]]}, {"timestamp": 1578771378918, "ltp": 1.54, "tv": 12533.74, "trd": NaN, "batb": [[2, 1.51, 182.34]], "batl": [[0, 1.54, 870.04]]}, {"timestamp": 1578771381035, "ltp": 1.54, "tv": 12533.74, "trd": NaN, "batb": [[0, 1.53, 626.24]], "batl": NaN}, {"timestamp": 1578771387051, "ltp": 1.54, "tv": 12533.74, "trd": NaN, "batb": [[0, 1.53, 946.63]], "batl": NaN}, {"timestamp": 1578771390018, "ltp": 1.54, "tv": 12533.74, "trd": NaN, "batb": [[2, 1.51, 314.34]], "batl": NaN}, {"timestamp": 1578771393964, "ltp": 1.54, "tv": 12533.74, "trd": NaN, "batb": [[0, 1.53, 986.54]], "batl": NaN}, {"timestamp": 1578771406980, "ltp": 1.54, "tv": 12533.74, "trd": NaN, "batb": [[2, 1.51, 1045.6]], "batl": NaN}, {"timestamp": 1578771435006, "ltp": 1.54, "tv": 12533.74, "trd": NaN, "batb": NaN, "batl": [[0, 1.54, 950.63]]}, {"timestamp": 1578771436027, "ltp": 1.54, "tv": 12533.74, "trd": NaN, "batb": NaN, "batl": [[0, 1.54, 1010.88]]}, {"timestamp": 1578771440898, "ltp": 1.54, "tv": 12533.74, "trd": NaN, "batb": NaN, "batl": [[0, 1.54, 950.63]]}, {"timestamp": 1578771442025, "ltp": 1.54, "tv": 12533.74, "trd": NaN, "batb": NaN, "batl": [[0, 1.54, 1010.88]]}, {"timestamp": 1578771443026, "ltp": 1.54, "tv": 12533.74, "trd": NaN, "batb": [[0, 1.53, 1024.54], [2, 1.51, 913.6]], "batl": [[2, 1.56, 399.54]]}, {"timestamp": 1578771444019, "ltp": 1.54, "tv": 12533.74, "trd": NaN, "batb": NaN, "batl": [[0, 1.54, 950.63]]}, {"timestamp": 1578771449629, "ltp": 1.54, "tv": 12533.74, "trd": NaN, "batb": [[0, 1.53, 992.83]], "batl": [[0, 1.54, 1010.02]]}, {"timestamp": 1578771454923, "ltp": 1.54, "tv": 12533.74, "trd": NaN, "batb": [[2, 1.51, 1045.6]], "batl": [[2, 1.56, 271.54]]}, {"timestamp": 1578771458042, "ltp": 1.54, "tv": 12533.74, "trd": NaN, "batb": [[0, 1.53, 1035.39]], "batl": NaN}, {"timestamp": 1578771470973, "ltp": 1.53, "tv": 12541.74, "trd": [[1.53, 7073.1]], "batb": [[0, 1.53, 1031.39]], "batl": NaN}, {"timestamp": 1578771479968, "ltp": 1.53, "tv": 12549.39, "trd": [[1.53, 7080.75]], "batb": [[0, 1.53, 1027.56]], "batl": NaN}, {"timestamp": 1578771482961, "ltp": 1.54, "tv": 12564.7, "trd": [[1.54, 2804.36]], "batb": NaN, "batl": [[0, 1.54, 1002.37]]}, {"timestamp": 1578771494015, "ltp": 1.54, "tv": 12564.7, "trd": NaN, "batb": [[2, 1.51, 913.6]], "batl": NaN}, {"timestamp": 1578771494972, "ltp": 1.54, "tv": 12569.29, "trd": [[1.54, 2808.95]], "batb": [[2, 1.51, 182.34]], "batl": [[0, 1.54, 1000.07]]}, {"timestamp": 1578771515003, "ltp": 1.54, "tv": 12808.21, "trd": [[1.54, 3047.87]], "batb": NaN, "batl": [[0, 1.54, 880.61]]}, {"timestamp": 1578771519031, "ltp": 1.53, "tv": 13108.23, "trd": [[1.53, 7380.76]], "batb": [[0, 1.53, 1230.38]], "batl": [[0, 1.54, 868.28]]}, {"timestamp": 1578771523954, "ltp": 1.53, "tv": 13108.23, "trd": NaN, "batb": NaN, "batl": [[0, 1.54, 961.23]]}, {"timestamp": 1578771527041, "ltp": 1.54, "tv": 13479.64, "trd": [[1.54, 3419.28]], "batb": [[2, 1.51, 982.33]], "batl": [[0, 1.54, 775.53]]}, {"timestamp": 1578771528044, "ltp": 1.54, "tv": 13479.64, "trd": NaN, "batb": [[2, 1.51, 182.34]], "batl": NaN}, {"timestamp": 1578771530054, "ltp": 1.54, "tv": 13479.64, "trd": NaN, "batb": NaN, "batl": [[2, 1.56, 399.54]]}, {"timestamp": 1578771534046, "ltp": 1.54, "tv": 13609.64, "trd": [[1.54, 3549.28]], "batb": NaN, "batl": [[0, 1.54, 710.53]]}, {"timestamp": 1578771535041, "ltp": 1.54, "tv": 13609.64, "trd": NaN, "batb": [[0, 1.53, 1262.08]], "batl": NaN}, {"timestamp": 1578771541956, "ltp": 1.54, "tv": 13609.64, "trd": NaN, "batb": [[0, 1.53, 1230.38]], "batl": NaN}, {"timestamp": 1578771542957, "ltp": 1.54, "tv": 13609.64, "trd": NaN, "batb": [[2, 1.51, 945.66]], "batl": NaN}, {"timestamp": 1578771543965, "ltp": 1.54, "tv": 13609.64, "trd": NaN, "batb": [[0, 1.53, 1172.57]], "batl": NaN}, {"timestamp": 1578771544764, "ltp": 1.53, "tv": 13621.99, "trd": [[1.53, 7393.12]], "batb": [[0, 1.53, 1166.39]], "batl": NaN}, {"timestamp": 1578771545874, "ltp": 1.53, "tv": 13754.02, "trd": [[1.53, 7525.14]], "batb": [[0, 1.53, 1206.95]], "batl": NaN}, {"timestamp": 1578771546992, "ltp": 1.53, "tv": 13754.02, "trd": NaN, "batb": [[2, 1.51, 1072.14]], "batl": NaN}, {"timestamp": 1578771552973, "ltp": 1.53, "tv": 13795.02, "trd": [[1.53, 7566.14]], "batb": [[0, 1.53, 1186.44]], "batl": NaN}, {"timestamp": 1578771554982, "ltp": 1.53, "tv": 13795.02, "trd": NaN, "batb": [[0, 1.53, 1102.13]], "batl": NaN}, {"timestamp": 1578771556966, "ltp": 1.53, "tv": 13795.02, "trd": NaN, "batb": [[0, 1.53, 1228.8]], "batl": NaN}, {"timestamp": 1578771563977, "ltp": 1.53, "tv": 13795.02, "trd": NaN, "batb": [[2, 1.51, 182.34]], "batl": NaN}, {"timestamp": 1578771565976, "ltp": 1.53, "tv": 13795.02, "trd": NaN, "batb": [[2, 1.51, 1069.25]], "batl": NaN}, {"timestamp": 1578771578991, "ltp": 1.53, "tv": 13825.63, "trd": [[1.53, 7596.76]], "batb": [[0, 1.53, 1213.49]], "batl": NaN}, {"timestamp": 1578771584977, "ltp": 1.53, "tv": 14011.53, "trd": [[1.53, 7782.66]], "batb": [[0, 1.53, 1120.54]], "batl": [[0, 1.54, 617.58]]}, {"timestamp": 1578771590012, "ltp": 1.53, "tv": 14011.53, "trd": NaN, "batb": NaN, "batl": [[0, 1.54, 694.62]]}, {"timestamp": 1578771591015, "ltp": 1.53, "tv": 14021.53, "trd": [[1.53, 7792.66]], "batb": [[0, 1.53, 1115.54]], "batl": NaN}, {"timestamp": 1578771597018, "ltp": 1.53, "tv": 14021.53, "trd": NaN, "batb": [[0, 1.53, 1257.67]], "batl": NaN}, {"timestamp": 1578771598019, "ltp": 1.53, "tv": 14021.53, "trd": NaN, "batb": [[0, 1.53, 1395.13]], "batl": [[0, 1.54, 732.88]]}, {"timestamp": 1578771600017, "ltp": 1.53, "tv": 14021.53, "trd": NaN, "batb": NaN, "batl": [[2, 1.56, 271.54]]}, {"timestamp": 1578771601027, "ltp": 1.53, "tv": 14025.33, "trd": [[1.53, 7796.45]], "batb": [[0, 1.53, 1393.23]], "batl": NaN}, {"timestamp": 1578771602028, "ltp": 1.54, "tv": 14033.57, "trd": [[1.54, 3557.52]], "batb": [[0, 1.53, 1352.65], [1, 1.52, 1635.73], [2, 1.51, 1064.61]], "batl": [[0, 1.54, 669.37], [1, 1.55, 438.39], [2, 1.56, 267]]}, {"timestamp": 1578771604031, "ltp": 1.54, "tv": 14033.57, "trd": NaN, "batb": [[0, 1.53, 1344.65]], "batl": NaN}, {"timestamp": 1578771605032, "ltp": 1.54, "tv": 14033.57, "trd": NaN, "batb": [[0, 1.53, 1520.76]], "batl": NaN}, {"timestamp": 1578771605856, "ltp": 1.54, "tv": 14033.57, "trd": NaN, "batb": NaN, "batl": [[0, 1.54, 682.19]]}, {"timestamp": 1578771607046, "ltp": 1.54, "tv": 14033.57, "trd": NaN, "batb": NaN, "batl": [[2, 1.56, 395]]}, {"timestamp": 1578771609053, "ltp": 1.54, "tv": 14043.56, "trd": [[1.54, 3567.52]], "batb": NaN, "batl": [[0, 1.54, 677.19]]}, {"timestamp": 1578771614040, "ltp": 1.54, "tv": 14043.56, "trd": NaN, "batb": [[0, 1.53, 1489.06]], "batl": NaN}, {"timestamp": 1578771615047, "ltp": 1.54, "tv": 14043.56, "trd": NaN, "batb": NaN, "batl": [[0, 1.54, 678.1]]}, {"timestamp": 1578771623834, "ltp": 1.54, "tv": 14432.55, "trd": [[1.54, 3956.5]], "batb": NaN, "batl": [[0, 1.54, 483.61]]}, {"timestamp": 1578771625054, "ltp": 1.54, "tv": 14432.55, "trd": NaN, "batb": NaN, "batl": [[0, 1.54, 492.12]]}, {"timestamp": 1578771625955, "ltp": 1.54, "tv": 14773.37, "trd": [[1.54, 4297.32]], "batb": NaN, "batl": [[0, 1.54, 321.71]]}, {"timestamp": 1578771628968, "ltp": 1.54, "tv": 14787.15, "trd": [[1.54, 4311.1]], "batb": NaN, "batl": [[0, 1.54, 314.82]]}, {"timestamp": 1578771631000, "ltp": 1.54, "tv": 14787.15, "trd": NaN, "batb": [[2, 1.51, 868.1]], "batl": NaN}, {"timestamp": 1578771635973, "ltp": 1.54, "tv": 14787.15, "trd": NaN, "batb": NaN, "batl": [[2, 1.56, 267]]}, {"timestamp": 1578771642956, "ltp": 1.53, "tv": 14789.37, "trd": [[1.53, 7798.67]], "batb": [[0, 1.53, 1487.95]], "batl": NaN}, {"timestamp": 1578771644966, "ltp": 1.53, "tv": 14789.37, "trd": NaN, "batb": NaN, "batl": [[2, 1.56, 395]]}, {"timestamp": 1578771653005, "ltp": 1.53, "tv": 14886.24, "trd": [[1.53, 7895.55]], "batb": [[0, 1.53, 1439.51]], "batl": NaN}, {"timestamp": 1578771656013, "ltp": 1.53, "tv": 14886.24, "trd": NaN, "batb": NaN, "batl": [[0, 1.54, 237.78]]}, {"timestamp": 1578771657017, "ltp": 1.53, "tv": 14886.24, "trd": NaN, "batb": [[0, 1.53, 1471.21]], "batl": [[0, 1.54, 160.35]]}, {"timestamp": 1578771657984, "ltp": 1.53, "tv": 14886.24, "trd": NaN, "batb": [[0, 1.53, 1482.51]], "batl": NaN}, {"timestamp": 1578771658988, "ltp": 1.53, "tv": 14886.24, "trd": NaN, "batb": [[0, 1.53, 1482.49]], "batl": NaN}, {"timestamp": 1578771663014, "ltp": 1.53, "tv": 14886.24, "trd": NaN, "batb": [[0, 1.53, 1482.43]], "batl": NaN}, {"timestamp": 1578771663990, "ltp": 1.53, "tv": 14886.24, "trd": NaN, "batb": [[0, 1.53, 1482.42]], "batl": NaN}, {"timestamp": 1578771666026, "ltp": 1.54, "tv": 14890.24, "trd": [[1.54, 4315.1]], "batb": NaN, "batl": [[0, 1.54, 158.35]]}, {"timestamp": 1578771667006, "ltp": 1.54, "tv": 14894.24, "trd": [[1.54, 4319.1]], "batb": [[0, 1.53, 1471.21]], "batl": [[0, 1.54, 156.35]]}, {"timestamp": 1578771668921, "ltp": 1.54, "tv": 14902.24, "trd": [[1.54, 4327.1]], "batb": NaN, "batl": [[0, 1.54, 152.35]]}, {"timestamp": 1578771670041, "ltp": 1.54, "tv": 14906.24, "trd": [[1.54, 4331.1]], "batb": NaN, "batl": [[0, 1.54, 150.35]]}, {"timestamp": 1578771672920, "ltp": 1.54, "tv": 15206.94, "trd": [[1.54, 4631.79]], "batb": [[0, 1.54, 103.17], [1, 1.53, 1471.21], [2, 1.52, 1635.73]], "batl": [[0, 1.55, 500.05], [1, 1.56, 267], [2, 1.57, 545]]}, {"timestamp": 1578771674035, "ltp": 1.54, "tv": 15206.94, "trd": NaN, "batb": [[0, 1.54, 160.39]], "batl": [[0, 1.55, 342.26]]}, {"timestamp": 1578771675046, "ltp": 1.54, "tv": 15206.94, "trd": NaN, "batb": NaN, "batl": [[1, 1.56, 395]]}, {"timestamp": 1578771676985, "ltp": 1.54, "tv": 15206.94, "trd": NaN, "batb": [[1, 1.53, 1484.11]], "batl": [[1, 1.56, 267]]}, {"timestamp": 1578771678999, "ltp": 1.54, "tv": 15207.7, "trd": [[1.54, 4632.56]], "batb": [[0, 1.54, 160]], "batl": NaN}, {"timestamp": 1578771681016, "ltp": 1.54, "tv": 15207.99, "trd": [[1.54, 4632.85]], "batb": [[0, 1.54, 159.86]], "batl": NaN}, {"timestamp": 1578771681934, "ltp": 1.54, "tv": 15233.24, "trd": [[1.54, 4658.09]], "batb": [[0, 1.54, 147.24]], "batl": NaN}, {"timestamp": 1578771690014, "ltp": 1.54, "tv": 15237.24, "trd": [[1.54, 4662.09]], "batb": [[0, 1.54, 145.24]], "batl": NaN}, {"timestamp": 1578771692623, "ltp": 1.54, "tv": 15237.24, "trd": NaN, "batb": NaN, "batl": [[0, 1.55, 420.86]]}, {"timestamp": 1578771696041, "ltp": 1.54, "tv": 15360.72, "trd": [[1.54, 4785.57]], "batb": [[0, 1.54, 83.5]], "batl": [[0, 1.55, 549.86], [1, 1.56, 395]]}, {"timestamp": 1578771697053, "ltp": 1.54, "tv": 15422.54, "trd": [[1.54, 4847.39]], "batb": [[0, 1.54, 36.45]], "batl": NaN}, {"timestamp": 1578771698020, "ltp": 1.54, "tv": 15458.98, "trd": [[1.54, 4883.84]], "batb": [[0, 1.53, 1495.89], [1, 1.52, 1635.73], [2, 1.51, 177.7]], "batl": NaN}, {"timestamp": 1578771699023, "ltp": 1.54, "tv": 15458.98, "trd": NaN, "batb": [[0, 1.53, 1495.88]], "batl": [[0, 1.55, 652.1]]}, {"timestamp": 1578771700042, "ltp": 1.54, "tv": 15458.98, "trd": NaN, "batb": [[0, 1.53, 2004.39]], "batl": NaN}, {"timestamp": 1578771702019, "ltp": 1.54, "tv": 15458.98, "trd": NaN, "batb": [[1, 1.52, 1785.73]], "batl": NaN}, {"timestamp": 1578771704035, "ltp": 1.54, "tv": 15458.98, "trd": NaN, "batb": NaN, "batl": [[0, 1.55, 636.3]]}, {"timestamp": 1578771705039, "ltp": 1.53, "tv": 15463.57, "trd": [[1.53, 7900.14]], "batb": [[0, 1.53, 2002.07]], "batl": NaN}, {"timestamp": 1578771706036, "ltp": 1.53, "tv": 15463.57, "trd": NaN, "batb": [[0, 1.53, 2002.06], [2, 1.51, 963.69]], "batl": NaN}, {"timestamp": 1578771706950, "ltp": 1.53, "tv": 15463.57, "trd": NaN, "batb": [[0, 1.53, 1990.34]], "batl": NaN}, {"timestamp": 1578771708052, "ltp": 1.53, "tv": 15463.57, "trd": NaN, "batb": [[0, 1.53, 2002.04]], "batl": NaN}, {"timestamp": 1578771708954, "ltp": 1.53, "tv": 15463.57, "trd": NaN, "batb": [[0, 1.53, 1990.34]], "batl": [[0, 1.54, 29.57], [1, 1.55, 636.3], [2, 1.56, 395]]}, {"timestamp": 1578771710013, "ltp": 1.54, "tv": 15522.7, "trd": [[1.54, 4942.97]], "batb": [[0, 1.54, 7.31], [1, 1.53, 2002.01], [2, 1.52, 1459.14]], "batl": [[0, 1.55, 636.3], [1, 1.56, 395], [2, 1.57, 545]]}, {"timestamp": 1578771712017, "ltp": 1.54, "tv": 15522.7, "trd": NaN, "batb": [[2, 1.52, 1224.87]], "batl": NaN}, {"timestamp": 1578771715031, "ltp": 1.54, "tv": 15522.7, "trd": NaN, "batb": [[0, 1.54, 35.44]], "batl": NaN}, {"timestamp": 1578771718953, "ltp": 1.54, "tv": 15526.67, "trd": [[1.54, 4946.93]], "batb": [[0, 1.54, 33.46], [1, 1.53, 1990.34]], "batl": NaN}, {"timestamp": 1578771719954, "ltp": 1.54, "tv": 15526.67, "trd": NaN, "batb": [[1, 1.53, 1962.21]], "batl": [[0, 1.55, 765.3]]}, {"timestamp": 1578771725981, "ltp": 1.54, "tv": 15526.67, "trd": NaN, "batb": [[2, 1.52, 1254.44]], "batl": NaN}, {"timestamp": 1578771728967, "ltp": 1.54, "tv": 15526.67, "trd": NaN, "batb": [[2, 1.52, 1354.44]], "batl": NaN}, {"timestamp": 1578771747872, "ltp": 1.54, "tv": 15560.13, "trd": [[1.54, 4980.39]], "batb": [[0, 1.53, 1962.21], [1, 1.52, 1354.44], [2, 1.51, 277.7]], "batl": NaN}, {"timestamp": 1578771750982, "ltp": 1.54, "tv": 15560.13, "trd": NaN, "batb": [[0, 1.53, 1609.39]], "batl": [[0, 1.54, 59.58], [1, 1.55, 663.06], [2, 1.56, 395]]}, {"timestamp": 1578771752985, "ltp": 1.54, "tv": 15560.13, "trd": NaN, "batb": [[0, 1.53, 1097.67]], "batl": [[0, 1.54, 104.58]]}, {"timestamp": 1578771753986, "ltp": 1.54, "tv": 15560.13, "trd": NaN, "batb": [[0, 1.53, 881.87]], "batl": NaN}, {"timestamp": 1578771754987, "ltp": 1.54, "tv": 15560.13, "trd": NaN, "batb": [[0, 1.53, 761.48]], "batl": NaN}, {"timestamp": 1578771755989, "ltp": 1.54, "tv": 15560.13, "trd": NaN, "batb": [[0, 1.53, 966.3]], "batl": [[0, 1.54, 168.76]]}, {"timestamp": 1578771761012, "ltp": 1.54, "tv": 15560.13, "trd": NaN, "batb": [[0, 1.53, 1002]], "batl": NaN}, {"timestamp": 1578771766009, "ltp": 1.54, "tv": 15560.13, "trd": NaN, "batb": [[0, 1.53, 847.81]], "batl": [[0, 1.54, 104.58], [1, 1.55, 584.47]]}, {"timestamp": 1578771779903, "ltp": 1.54, "tv": 15560.13, "trd": NaN, "batb": [[1, 1.52, 1447.39]], "batl": NaN}, {"timestamp": 1578771782040, "ltp": 1.54, "tv": 15560.13, "trd": NaN, "batb": [[0, 1.53, 802.81], [1, 1.52, 1402.39], [2, 1.51, 232.7]], "batl": [[0, 1.54, 59.58], [1, 1.55, 539.47], [2, 1.56, 350]]}, {"timestamp": 1578771784042, "ltp": 1.54, "tv": 15560.13, "trd": NaN, "batb": [[0, 1.53, 837.81]], "batl": NaN}, {"timestamp": 1578771798960, "ltp": 1.54, "tv": 15560.13, "trd": NaN, "batb": NaN, "batl": [[1, 1.55, 309.86]]}, {"timestamp": 1578771807992, "ltp": 1.54, "tv": 15561.6, "trd": [[1.54, 4981.87]], "batb": NaN, "batl": [[0, 1.54, 58.11]]}, {"timestamp": 1578771809046, "ltp": 1.53, "tv": 15566.2, "trd": [[1.53, 7904.74]], "batb": [[0, 1.53, 835.52]], "batl": NaN}, {"timestamp": 1578771809951, "ltp": 1.53, "tv": 15566.2, "trd": NaN, "batb": [[0, 1.53, 775.77]], "batl": NaN}, {"timestamp": 1578771815997, "ltp": 1.53, "tv": 15583.26, "trd": [[1.53, 7921.8]], "batb": [[0, 1.53, 767.23]], "batl": NaN}, {"timestamp": 1578771817993, "ltp": 1.54, "tv": 15583.27, "trd": [[1.54, 4981.88]], "batb": NaN, "batl": [[0, 1.54, 58.1]]}, {"timestamp": 1578771818987, "ltp": 1.54, "tv": 15583.27, "trd": NaN, "batb": [[1, 1.52, 1309.44]], "batl": NaN}, {"timestamp": 1578771826009, "ltp": 1.54, "tv": 15584.01, "trd": [[1.54, 4982.62]], "batb": NaN, "batl": [[0, 1.54, 57.36], [1, 1.55, 246.2]]}, {"timestamp": 1578771828014, "ltp": 1.54, "tv": 15592.51, "trd": [[1.54, 4991.12]], "batb": [[1, 1.52, 1164.63]], "batl": [[0, 1.54, 48.86]]}, {"timestamp": 1578771829016, "ltp": 1.54, "tv": 15609.53, "trd": [[1.54, 5008.14]], "batb": NaN, "batl": [[0, 1.54, 31.84]]}, {"timestamp": 1578771830023, "ltp": 1.53, "tv": 15613.52, "trd": [[1.53, 7925.8]], "batb": [[0, 1.53, 619.6]], "batl": NaN}, {"timestamp": 1578771836044, "ltp": 1.53, "tv": 15613.52, "trd": NaN, "batb": [[1, 1.52, 1306.45]], "batl": NaN}, {"timestamp": 1578771838004, "ltp": 1.53, "tv": 15613.52, "trd": NaN, "batb": NaN, "batl": [[0, 1.54, 231.84]]}, {"timestamp": 1578771842039, "ltp": 1.53, "tv": 15613.52, "trd": NaN, "batb": [[2, 1.51, 234.72]], "batl": NaN}, {"timestamp": 1578771850947, "ltp": 1.52, "tv": 17333.25, "trd": [[1.52, 1178.35], [1.53, 9194.52]], "batb": [[0, 1.52, 1080.95], [1, 1.51, 234.72], [2, 1.5, 409.59]], "batl": NaN}, {"timestamp": 1578771853016, "ltp": 1.52, "tv": 17333.25, "trd": NaN, "batb": [[0, 1.52, 939.13]], "batl": [[0, 1.54, 331.22]]}, {"timestamp": 1578771853957, "ltp": 1.52, "tv": 17333.25, "trd": NaN, "batb": NaN, "batl": [[0, 1.53, 15.31], [1, 1.54, 331.22], [2, 1.55, 246.2]]}, {"timestamp": 1578771857927, "ltp": 1.52, "tv": 17333.25, "trd": NaN, "batb": NaN, "batl": [[0, 1.53, 104.29], [1, 1.54, 474.68]]}, {"timestamp": 1578771860041, "ltp": 1.52, "tv": 17333.25, "trd": NaN, "batb": [[0, 1.52, 814.37]], "batl": NaN}, {"timestamp": 1578771863963, "ltp": 1.52, "tv": 17333.25, "trd": NaN, "batb": NaN, "batl": [[1, 1.54, 604.68]]}, {"timestamp": 1578771873049, "ltp": 1.52, "tv": 17333.25, "trd": NaN, "batb": NaN, "batl": [[0, 1.53, 136], [1, 1.54, 572.98]]}, {"timestamp": 1578771875994, "ltp": 1.52, "tv": 17338.78, "trd": [[1.52, 1183.87]], "batb": [[0, 1.52, 811.6]], "batl": NaN}, {"timestamp": 1578771876997, "ltp": 1.52, "tv": 17353.79, "trd": [[1.52, 1198.89]], "batb": [[0, 1.52, 804.09]], "batl": [[0, 1.53, 138.75]]}, {"timestamp": 1578771878055, "ltp": 1.52, "tv": 17353.79, "trd": NaN, "batb": NaN, "batl": [[0, 1.53, 146.21]]}, {"timestamp": 1578771882011, "ltp": 1.53, "tv": 17355.65, "trd": [[1.53, 9196.37]], "batb": [[0, 1.52, 609.57]], "batl": [[0, 1.53, 145.28]]}, {"timestamp": 1578771883005, "ltp": 1.52, "tv": 17423.74, "trd": [[1.52, 1266.98]], "batb": [[0, 1.52, 575.52]], "batl": NaN}, {"timestamp": 1578771883992, "ltp": 1.52, "tv": 17438.76, "trd": [[1.52, 1282]], "batb": [[0, 1.52, 568.01]], "batl": NaN}, {"timestamp": 1578771884886, "ltp": 1.52, "tv": 17438.76, "trd": NaN, "batb": NaN, "batl": [[0, 1.53, 345.28], [1, 1.54, 229.51]]}, {"timestamp": 1578771889968, "ltp": 1.53, "tv": 17469.38, "trd": [[1.53, 9226.99]], "batb": NaN, "batl": [[0, 1.53, 233.53]]}, {"timestamp": 1578771892002, "ltp": 1.52, "tv": 17588.54, "trd": [[1.52, 1401.17]], "batb": [[0, 1.52, 508.43]], "batl": [[0, 1.53, 230.78]]}, {"timestamp": 1578771895989, "ltp": 1.52, "tv": 17588.54, "trd": NaN, "batb": NaN, "batl": [[0, 1.53, 474.8]]}, {"timestamp": 1578771900005, "ltp": 1.52, "tv": 17678.59, "trd": [[1.52, 1491.21]], "batb": [[0, 1.52, 463.41]], "batl": NaN}, {"timestamp": 1578771904978, "ltp": 1.52, "tv": 17678.59, "trd": NaN, "batb": NaN, "batl": [[0, 1.53, 605.8]]}, {"timestamp": 1578771907026, "ltp": 1.52, "tv": 17685.61, "trd": [[1.52, 1498.23]], "batb": [[0, 1.52, 459.9]], "batl": NaN}, {"timestamp": 1578771908039, "ltp": 1.52, "tv": 17711.14, "trd": [[1.52, 1523.77]], "batb": [[0, 1.52, 447.13]], "batl": NaN}, {"timestamp": 1578771915056, "ltp": 1.52, "tv": 17724.76, "trd": [[1.52, 1537.39]], "batb": [[0, 1.52, 440.32]], "batl": NaN}, {"timestamp": 1578771916051, "ltp": 1.52, "tv": 17729.78, "trd": [[1.52, 1542.41]], "batb": [[0, 1.52, 437.81]], "batl": NaN}, {"timestamp": 1578771918947, "ltp": 1.52, "tv": 17729.78, "trd": NaN, "batb": [[2, 1.5, 424.89]], "batl": [[0, 1.53, 474.8], [1, 1.54, 99.51]]}, {"timestamp": 1578771921053, "ltp": 1.52, "tv": 17746.81, "trd": [[1.52, 1559.43]], "batb": [[0, 1.52, 429.3]], "batl": NaN}, {"timestamp": 1578771921957, "ltp": 1.52, "tv": 17746.81, "trd": NaN, "batb": NaN, "batl": [[0, 1.53, 605.8], [1, 1.54, 229.51]]}, {"timestamp": 1578771924053, "ltp": 1.52, "tv": 17746.81, "trd": NaN, "batb": NaN, "batl": [[0, 1.53, 474.8], [1, 1.54, 99.51]]}, {"timestamp": 1578771927047, "ltp": 1.52, "tv": 17746.81, "trd": NaN, "batb": NaN, "batl": [[0, 1.53, 605.8], [1, 1.54, 229.51]]}, {"timestamp": 1578771936034, "ltp": 1.53, "tv": 17750.42, "trd": [[1.53, 9230.6]], "batb": NaN, "batl": [[0, 1.53, 603.99]]}, {"timestamp": 1578771948980, "ltp": 1.53, "tv": 17750.42, "trd": NaN, "batb": NaN, "batl": [[0, 1.53, 575.02]]}, {"timestamp": 1578771951964, "ltp": 1.53, "tv": 17750.42, "trd": NaN, "batb": NaN, "batl": [[0, 1.53, 444.02], [1, 1.54, 99.51]]}, {"timestamp": 1578771959984, "ltp": 1.54, "tv": 18784.91, "trd": [[1.53, 10134.78], [1.54, 5138.46]], "batb": NaN, "batl": [[0, 1.54, 34.35], [1, 1.55, 246.2], [2, 1.56, 350]]}, {"timestamp": 1578771963003, "ltp": 1.54, "tv": 18784.91, "trd": NaN, "batb": [[0, 1.52, 608.18]], "batl": NaN}, {"timestamp": 1578771963789, "ltp": 1.54, "tv": 18784.91, "trd": NaN, "batb": NaN, "batl": [[0, 1.55, 246.2], [1, 1.56, 350], [2, 1.57, 500]]}, {"timestamp": 1578771966992, "ltp": 1.54, "tv": 18784.91, "trd": NaN, "batb": NaN, "batl": [[0, 1.55, 277.91]]}, {"timestamp": 1578771969980, "ltp": 1.52, "tv": 18989.84, "trd": [[1.52, 1764.36]], "batb": [[0, 1.52, 505.72]], "batl": NaN}, {"timestamp": 1578771975003, "ltp": 1.52, "tv": 18989.84, "trd": NaN, "batb": [[0, 1.53, 32.01], [1, 1.52, 505.72], [2, 1.51, 234.72]], "batl": NaN}, {"timestamp": 1578771975898, "ltp": 1.52, "tv": 18989.84, "trd": NaN, "batb": [[1, 1.52, 358.54]], "batl": NaN}, {"timestamp": 1578771977018, "ltp": 1.53, "tv": 19020.64, "trd": [[1.53, 10165.57]], "batb": [[0, 1.53, 1.21], [1, 1.52, 373.5]], "batl": NaN}, {"timestamp": 1578771978023, "ltp": 1.53, "tv": 19020.64, "trd": NaN, "batb": [[1, 1.52, 520.69]], "batl": NaN}, {"timestamp": 1578771996055, "ltp": 1.52, "tv": 19132.75, "trd": [[1.52, 1874.06], [1.53, 10167.99]], "batb": [[0, 1.52, 465.84], [1, 1.51, 234.72], [2, 1.5, 424.89]], "batl": NaN}, {"timestamp": 1578771997011, "ltp": 1.52, "tv": 19132.75, "trd": NaN, "batb": NaN, "batl": [[0, 1.53, 2.46], [1, 1.55, 277.91], [2, 1.56, 350]]}, {"timestamp": 1578771998011, "ltp": 1.52, "tv": 19132.75, "trd": NaN, "batb": NaN, "batl": [[1, 1.54, 3], [2, 1.55, 277.91]]}, {"timestamp": 1578772000021, "ltp": 1.55, "tv": 19202.75, "trd": [[1.53, 10172.91], [1.54, 5144.46], [1.55, 1891.75]], "batb": NaN, "batl": [[0, 1.55, 248.37], [1, 1.56, 350], [2, 1.57, 500]]}, {"timestamp": 1578772011042, "ltp": 1.52, "tv": 19209.11, "trd": [[1.52, 1880.41]], "batb": [[0, 1.52, 462.66]], "batl": NaN}, {"timestamp": 1578772013032, "ltp": 1.52, "tv": 19209.11, "trd": NaN, "batb": [[0, 1.54, 314.1], [1, 1.52, 462.66], [2, 1.51, 234.72]], "batl": NaN}, {"timestamp": 1578772014028, "ltp": 1.54, "tv": 19837.3, "trd": [[1.54, 5772.64]], "batb": [[0, 1.53, 31.7], [1, 1.52, 435.95]], "batl": [[0, 1.54, 2.25], [1, 1.55, 248.37], [2, 1.56, 350]]}, {"timestamp": 1578772014965, "ltp": 1.54, "tv": 19837.3, "trd": NaN, "batb": [[1, 1.52, 571.81], [2, 1.51, 384.78]], "batl": NaN}, {"timestamp": 1578772017961, "ltp": 1.54, "tv": 19837.3, "trd": NaN, "batb": [[0, 1.52, 603.51], [1, 1.51, 384.78], [2, 1.5, 424.89]], "batl": [[0, 1.54, 34.1], [1, 1.55, 216.67]]}, {"timestamp": 1578772019054, "ltp": 1.54, "tv": 19905.5, "trd": [[1.53, 10173.2], [1.54, 5840.55]], "batb": [[0, 1.54, 19.53], [1, 1.52, 603.51], [2, 1.51, 384.78]], "batl": [[0, 1.55, 216.67], [1, 1.56, 350], [2, 1.57, 500]]}, {"timestamp": 1578772020957, "ltp": 1.54, "tv": 19940.52, "trd": [[1.54, 5875.57]], "batb": [[0, 1.54, 2.02]], "batl": NaN}, {"timestamp": 1578772027968, "ltp": 1.54, "tv": 19940.52, "trd": NaN, "batb": [[1, 1.53, 31.7], [2, 1.52, 571.81]], "batl": NaN}, {"timestamp": 1578772029954, "ltp": 1.54, "tv": 19944.54, "trd": [[1.54, 5879.59]], "batb": [[0, 1.53, 31.71], [1, 1.52, 571.81], [2, 1.51, 384.78]], "batl": NaN}, {"timestamp": 1578772036034, "ltp": 1.54, "tv": 19944.54, "trd": NaN, "batb": [[0, 1.53, 34.66]], "batl": [[0, 1.55, 225.35]]}, {"timestamp": 1578772037977, "ltp": 1.53, "tv": 19948.27, "trd": [[1.53, 10176.92], [1.54, 5879.61]], "batb": [[0, 1.53, 32.79]], "batl": NaN}, {"timestamp": 1578772038998, "ltp": 1.54, "tv": 19976.26, "trd": [[1.54, 5896.99], [1.55, 1902.36]], "batb": [[0, 1.54, 21.95], [1, 1.53, 32.49], [2, 1.52, 571.81]], "batl": [[0, 1.55, 211.36]]}, {"timestamp": 1578772040984, "ltp": 1.54, "tv": 20019.96, "trd": [[1.54, 5940.69]], "batb": [[0, 1.53, 32.49], [1, 1.52, 571.81], [2, 1.51, 384.78]], "batl": NaN}, {"timestamp": 1578772045976, "ltp": 1.54, "tv": 20019.96, "trd": NaN, "batb": [[0, 1.53, 41.53]], "batl": NaN}, {"timestamp": 1578772046969, "ltp": 1.53, "tv": 20021.21, "trd": [[1.53, 10178.17]], "batb": [[0, 1.53, 40.9]], "batl": NaN}, {"timestamp": 1578772048962, "ltp": 1.53, "tv": 20062.11, "trd": [[1.53, 10219.08]], "batb": [[0, 1.52, 571.81], [1, 1.51, 384.78], [2, 1.5, 424.89]], "batl": NaN}, {"timestamp": 1578772050001, "ltp": 1.53, "tv": 20062.11, "trd": NaN, "batb": [[0, 1.52, 435.95]], "batl": [[0, 1.53, 2.46], [1, 1.54, 31.7], [2, 1.55, 211.36]]}, {"timestamp": 1578772050989, "ltp": 1.53, "tv": 20062.11, "trd": NaN, "batb": NaN, "batl": [[0, 1.53, 133.46], [1, 1.54, 161.7]]}, {"timestamp": 1578772051772, "ltp": 1.53, "tv": 20062.11, "trd": NaN, "batb": NaN, "batl": [[1, 1.54, 265.84]]}, {"timestamp": 1578772053858, "ltp": 1.53, "tv": 20066.23, "trd": [[1.53, 10223.2]], "batb": NaN, "batl": [[0, 1.53, 131.4]]}, {"timestamp": 1578772055998, "ltp": 1.53, "tv": 20066.23, "trd": NaN, "batb": [[0, 1.52, 288.77]], "batl": NaN}, {"timestamp": 1578772056995, "ltp": 1.53, "tv": 20066.23, "trd": NaN, "batb": NaN, "batl": [[1, 1.54, 234.14]]}, {"timestamp": 1578772063000, "ltp": 1.53, "tv": 20066.23, "trd": NaN, "batb": NaN, "batl": [[0, 1.53, 131]]}, {"timestamp": 1578772070993, "ltp": 1.53, "tv": 20066.23, "trd": NaN, "batb": [[0, 1.52, 320.47]], "batl": [[0, 1.54, 234.14], [1, 1.55, 211.36], [2, 1.56, 350]]}, {"timestamp": 1578772071983, "ltp": 1.52, "tv": 20106.23, "trd": [[1.52, 1920.41]], "batb": [[0, 1.52, 300.47]], "batl": NaN}, {"timestamp": 1578772088936, "ltp": 1.52, "tv": 20109.97, "trd": [[1.52, 1924.15]], "batb": [[0, 1.52, 298.6]], "batl": NaN}, {"timestamp": 1578772092027, "ltp": 1.52, "tv": 20158.86, "trd": [[1.52, 1973.05]], "batb": [[0, 1.52, 274.15]], "batl": NaN}, {"timestamp": 1578772098026, "ltp": 1.52, "tv": 20158.86, "trd": NaN, "batb": NaN, "batl": [[0, 1.54, 104.14], [1, 1.55, 82.36], [2, 1.56, 222]]}, {"timestamp": 1578772098957, "ltp": 1.52, "tv": 20158.86, "trd": NaN, "batb": [[0, 1.52, 421.95]], "batl": NaN}, {"timestamp": 1578772099563, "ltp": 1.52, "tv": 20158.86, "trd": NaN, "batb": NaN, "batl": [[0, 1.55, 82.36], [1, 1.56, 222], [2, 1.57, 373]]}, {"timestamp": 1578772101023, "ltp": 1.52, "tv": 20158.86, "trd": NaN, "batb": [[0, 1.52, 227.49], [1, 1.51, 265.07], [2, 1.5, 306.15]], "batl": NaN}, {"timestamp": 1578772108019, "ltp": 1.52, "tv": 20158.86, "trd": NaN, "batb": [[2, 1.5, 453.24]], "batl": [[0, 1.55, 96.15], [1, 1.57, 101.12], [2, 1.59, 97.8]]}, {"timestamp": 1578772108966, "ltp": 1.52, "tv": 20405.93, "trd": [[1.52, 2220.11]], "batb": [[0, 1.51, 265.07], [1, 1.5, 306.15], [2, 1.49, 140.83]], "batl": [[0, 1.62, 499.75], [1, 1.57, 0], [2, 1.59, 0]]}, {"timestamp": 1578772114004, "ltp": 1.52, "tv": 20405.93, "trd": NaN, "batb": NaN, "batl": [[1, 1.65, 21.28], [2, 2.32, 1.95]]}, {"timestamp": 1578772114999, "ltp": 1.52, "tv": 20405.93, "trd": NaN, "batb": NaN, "batl": [[0, 1.59, 7.66], [1, 1.62, 499.75]]}, {"timestamp": 1578772116004, "ltp": 1.52, "tv": 20405.93, "trd": NaN, "batb": [[2, 1.49, 408.74]], "batl": [[0, 1.58, 85.12], [1, 1.59, 7.66], [2, 1.61, 17.02]]}, {"timestamp": 1578772117012, "ltp": 1.52, "tv": 20405.93, "trd": NaN, "batb": [[1, 1.5, 535.75]], "batl": [[0, 1.55, 4.26], [1, 1.58, 85.12], [2, 1.59, 7.66]]}, {"timestamp": 1578772118011, "ltp": 1.52, "tv": 20405.93, "trd": NaN, "batb": [[0, 1.52, 31.7], [1, 1.51, 265.07], [2, 1.5, 535.75]], "batl": NaN}, {"timestamp": 1578772123020, "ltp": 1.52, "tv": 20405.93, "trd": NaN, "batb": NaN, "batl": [[0, 1.55, 32.45]]}, {"timestamp": 1578772124032, "ltp": 1.52, "tv": 20405.93, "trd": NaN, "batb": [[1, 1.51, 290.27], [2, 1.5, 629.98]], "batl": [[0, 1.55, 125.28], [1, 1.57, 450], [2, 1.58, 197.62]]}, {"timestamp": 1578772125024, "ltp": 1.52, "tv": 20405.93, "trd": NaN, "batb": NaN, "batl": [[1, 1.58, 85.12], [2, 2.32, 1.95]]}, {"timestamp": 1578772126020, "ltp": 1.52, "tv": 20405.93, "trd": NaN, "batb": [[0, 1.51, 290.27], [1, 1.5, 629.98], [2, 1.49, 484.27]], "batl": NaN}, {"timestamp": 1578772127024, "ltp": 1.52, "tv": 20420.89, "trd": [[1.52, 2235.07]], "batb": [[0, 1.51, 361.34]], "batl": NaN}, {"timestamp": 1578772128017, "ltp": 1.52, "tv": 20420.89, "trd": NaN, "batb": [[0, 1.51, 265.07]], "batl": [[2, 2.32, 0]]}, {"timestamp": 1578772128999, "ltp": 1.52, "tv": 20420.89, "trd": NaN, "batb": NaN, "batl": [[0, 1.54, 3], [1, 1.55, 125.28], [2, 1.57, 20.2]]}, {"timestamp": 1578772131049, "ltp": 1.52, "tv": 20420.89, "trd": NaN, "batb": [[0, 1.51, 265.92], [2, 1.49, 505.55]], "batl": NaN}, {"timestamp": 1578772132044, "ltp": 1.52, "tv": 20420.89, "trd": NaN, "batb": NaN, "batl": [[2, 1.56, 900]]}, {"timestamp": 1578772132990, "ltp": 1.52, "tv": 20420.89, "trd": NaN, "batb": [[2, 1.49, 488.53]], "batl": NaN}, {"timestamp": 1578772135024, "ltp": 1.52, "tv": 20420.89, "trd": NaN, "batb": NaN, "batl": [[0, 1.52, 1.02], [1, 1.54, 3], [2, 1.55, 125.28]]}, {"timestamp": 1578772136011, "ltp": 1.52, "tv": 20420.89, "trd": NaN, "batb": NaN, "batl": [[0, 1.52, 5.74], [2, 1.55, 74.06]]}, {"timestamp": 1578772136903, "ltp": 1.52, "tv": 20420.89, "trd": NaN, "batb": NaN, "batl": [[1, 1.54, 31.83]]}, {"timestamp": 1578772138009, "ltp": 1.52, "tv": 20420.89, "trd": NaN, "batb": NaN, "batl": [[1, 1.54, 55.14], [2, 1.55, 573.96]]}, {"timestamp": 1578772139014, "ltp": 1.52, "tv": 20420.89, "trd": NaN, "batb": NaN, "batl": [[2, 1.55, 74.06]]}, {"timestamp": 1578772140008, "ltp": 1.52, "tv": 20420.89, "trd": NaN, "batb": [[1, 1.5, 756.98], [2, 1.49, 1120.54]], "batl": [[1, 1.54, 86.84]]}, {"timestamp": 1578772142048, "ltp": 1.52, "tv": 20420.89, "trd": NaN, "batb": NaN, "batl": [[0, 1.52, 1.02]]}, {"timestamp": 1578772143047, "ltp": 1.52, "tv": 20420.89, "trd": NaN, "batb": NaN, "batl": [[1, 1.53, 52.83], [2, 1.54, 86.84]]}, {"timestamp": 1578772144036, "ltp": 1.52, "tv": 20420.89, "trd": NaN, "batb": NaN, "batl": [[1, 1.54, 86.84], [2, 1.55, 74.06]]}, {"timestamp": 1578772147044, "ltp": 1.51, "tv": 20421.37, "trd": [[1.51, 0.48]], "batb": [[0, 1.51, 265.68]], "batl": [[1, 1.54, 55.14]]}, {"timestamp": 1578772148952, "ltp": 1.51, "tv": 20421.37, "trd": NaN, "batb": [[2, 1.49, 488.53]], "batl": NaN}, {"timestamp": 1578772150049, "ltp": 1.51, "tv": 20421.37, "trd": NaN, "batb": [[0, 1.51, 297.39]], "batl": NaN}, {"timestamp": 1578772151035, "ltp": 1.51, "tv": 20421.37, "trd": NaN, "batb": [[1, 1.5, 629.98]], "batl": NaN}, {"timestamp": 1578772153956, "ltp": 1.51, "tv": 20427.42, "trd": [[1.51, 6.52]], "batb": [[0, 1.51, 291.34]], "batl": [[1, 1.53, 20.72], [2, 1.54, 55.14]]}, {"timestamp": 1578772155950, "ltp": 1.51, "tv": 20427.45, "trd": [[1.51, 6.55]], "batb": [[0, 1.51, 291.31]], "batl": NaN}, {"timestamp": 1578772158042, "ltp": 1.51, "tv": 20427.45, "trd": NaN, "batb": [[2, 1.49, 602.53]], "batl": NaN}, {"timestamp": 1578772159039, "ltp": 1.51, "tv": 20427.45, "trd": NaN, "batb": [[2, 1.49, 488.53]], "batl": NaN}, {"timestamp": 1578772160029, "ltp": 1.51, "tv": 20436.89, "trd": [[1.51, 16]], "batb": [[0, 1.51, 286.59]], "batl": NaN}, {"timestamp": 1578772161961, "ltp": 1.51, "tv": 20564.88, "trd": [[1.51, 143.99]], "batb": [[0, 1.51, 222.59], [1, 1.5, 400.38]], "batl": [[1, 1.53, 50.52]]}, {"timestamp": 1578772165013, "ltp": 1.51, "tv": 20564.88, "trd": NaN, "batb": [[2, 1.49, 728.47]], "batl": [[2, 1.54, 277.63]]}, {"timestamp": 1578772174045, "ltp": 1.51, "tv": 20564.88, "trd": NaN, "batb": [[2, 1.49, 707.18]], "batl": NaN}, {"timestamp": 1578772176969, "ltp": 1.51, "tv": 20567.13, "trd": [[1.51, 146.24]], "batb": [[0, 1.51, 221.47]], "batl": NaN}, {"timestamp": 1578772179050, "ltp": 1.51, "tv": 20567.13, "trd": NaN, "batb": [[0, 1.51, 71.41]], "batl": NaN}, {"timestamp": 1578772179996, "ltp": 1.51, "tv": 20567.13, "trd": NaN, "batb": [[1, 1.5, 330.66]], "batl": NaN}, {"timestamp": 1578772180983, "ltp": 1.51, "tv": 20569.16, "trd": [[1.51, 148.27]], "batb": [[0, 1.51, 70.39]], "batl": NaN}, {"timestamp": 1578772182969, "ltp": 1.51, "tv": 20606.54, "trd": [[1.51, 185.65]], "batb": [[0, 1.51, 51.7]], "batl": NaN}, {"timestamp": 1578772185997, "ltp": 1.51, "tv": 20606.54, "trd": NaN, "batb": NaN, "batl": [[1, 1.53, 73.86]]}, {"timestamp": 1578772187991, "ltp": 1.51, "tv": 20606.54, "trd": NaN, "batb": [[1, 1.5, 483.73]], "batl": NaN}, {"timestamp": 1578772190967, "ltp": 1.51, "tv": 20658.23, "trd": [[1.51, 237.34]], "batb": [[0, 1.5, 483.73], [1, 1.49, 707.18], [2, 1.48, 1934.44]], "batl": NaN}, {"timestamp": 1578772192015, "ltp": 1.51, "tv": 20658.23, "trd": NaN, "batb": [[0, 1.5, 459.22]], "batl": NaN}, {"timestamp": 1578772192997, "ltp": 1.51, "tv": 20658.23, "trd": NaN, "batb": NaN, "batl": [[1, 1.53, 140.95]]}, {"timestamp": 1578772196017, "ltp": 1.51, "tv": 20658.23, "trd": NaN, "batb": NaN, "batl": [[0, 1.51, 19.58], [1, 1.52, 1.02], [2, 1.53, 140.95]]}, {"timestamp": 1578772197010, "ltp": 1.51, "tv": 20658.23, "trd": NaN, "batb": NaN, "batl": [[0, 1.52, 1.02], [1, 1.53, 140.95], [2, 1.54, 1595.38]]}, {"timestamp": 1578772197996, "ltp": 1.51, "tv": 20658.23, "trd": NaN, "batb": NaN, "batl": [[0, 1.51, 570.15], [1, 1.52, 1.02], [2, 1.53, 140.95]]}, {"timestamp": 1578772199036, "ltp": 1.5, "tv": 20743.36, "trd": [[1.5, 85.12]], "batb": [[0, 1.5, 416.66], [1, 1.49, 394.26]], "batl": NaN}, {"timestamp": 1578772200033, "ltp": 1.51, "tv": 20748.28, "trd": [[1.51, 242.27]], "batb": NaN, "batl": [[0, 1.51, 567.69]]}, {"timestamp": 1578772201021, "ltp": 1.51, "tv": 20748.28, "trd": NaN, "batb": NaN, "batl": [[2, 1.53, 120.22]]}, {"timestamp": 1578772206035, "ltp": 1.51, "tv": 20748.28, "trd": NaN, "batb": [[2, 1.48, 942.32]], "batl": NaN}, {"timestamp": 1578772207025, "ltp": 1.51, "tv": 20758.09, "trd": [[1.51, 252.07]], "batb": [[0, 1.5, 263.59]], "batl": [[0, 1.51, 557.89], [1, 1.53, 120.22], [2, 1.54, 718.63]]}, {"timestamp": 1578772209009, "ltp": 1.51, "tv": 20758.09, "trd": NaN, "batb": NaN, "batl": [[2, 1.54, 666.49]]}, {"timestamp": 1578772210055, "ltp": 1.51, "tv": 20758.09, "trd": NaN, "batb": NaN, "batl": [[0, 1.51, 569.98]]}, {"timestamp": 1578772214029, "ltp": 1.51, "tv": 20758.09, "trd": NaN, "batb": NaN, "batl": [[1, 1.53, 536.22]]}, {"timestamp": 1578772215020, "ltp": 1.51, "tv": 20758.09, "trd": NaN, "batb": [[0, 1.5, 463.59]], "batl": [[0, 1.51, 601.47]]}, {"timestamp": 1578772216019, "ltp": 1.51, "tv": 20758.09, "trd": NaN, "batb": NaN, "batl": [[1, 1.52, 272.2], [2, 1.53, 536.22]]}, {"timestamp": 1578772219055, "ltp": 1.5, "tv": 20762.68, "trd": [[1.5, 89.72]], "batb": [[0, 1.5, 461.29]], "batl": NaN}, {"timestamp": 1578772221046, "ltp": 1.51, "tv": 20808.38, "trd": [[1.5, 106.74], [1.51, 280.74]], "batb": [[0, 1.5, 452.78]], "batl": [[0, 1.51, 573.73], [2, 1.53, 120.22]]}, {"timestamp": 1578772222038, "ltp": 1.51, "tv": 20808.38, "trd": NaN, "batb": NaN, "batl": [[0, 1.51, 573.94]]}, {"timestamp": 1578772226954, "ltp": 1.51, "tv": 20808.38, "trd": NaN, "batb": [[2, 1.48, 614.14]], "batl": NaN}, {"timestamp": 1578772233979, "ltp": 1.5, "tv": 20810.18, "trd": [[1.5, 108.54]], "batb": [[0, 1.5, 451.87]], "batl": NaN}, {"timestamp": 1578772235048, "ltp": 1.5, "tv": 20810.18, "trd": NaN, "batb": NaN, "batl": [[0, 1.51, 1026.85], [1, 1.52, 736.2], [2, 1.53, 576.22]]}, {"timestamp": 1578772236042, "ltp": 1.5, "tv": 20861.25, "trd": [[1.5, 159.62]], "batb": [[0, 1.5, 426.34]], "batl": NaN}, {"timestamp": 1578772236982, "ltp": 1.51, "tv": 21779.67, "trd": [[1.51, 1199.16]], "batb": NaN, "batl": [[0, 1.51, 567.64]]}, {"timestamp": 1578772237971, "ltp": 1.51, "tv": 21779.67, "trd": NaN, "batb": [[1, 1.49, 370.44]], "batl": NaN}, {"timestamp": 1578772239957, "ltp": 1.5, "tv": 21921.68, "trd": [[1.5, 301.63]], "batb": [[0, 1.5, 355.33]], "batl": NaN}, {"timestamp": 1578772240961, "ltp": 1.5, "tv": 22467.46, "trd": [[1.5, 847.41]], "batb": [[0, 1.49, 370.44], [1, 1.48, 614.14], [2, 1.47, 1647.19]], "batl": [[0, 1.5, 271.55], [1, 1.51, 567.64], [2, 1.52, 736.2]]}, {"timestamp": 1578772241962, "ltp": 1.5, "tv": 22467.46, "trd": NaN, "batb": [[1, 1.48, 293.85]], "batl": [[0, 1.51, 567.64], [1, 1.52, 736.2], [2, 1.53, 523.08]]}, {"timestamp": 1578772242966, "ltp": 1.5, "tv": 22467.46, "trd": NaN, "batb": [[2, 1.47, 2841.54]], "batl": NaN}, {"timestamp": 1578772243962, "ltp": 1.5, "tv": 22467.46, "trd": NaN, "batb": [[2, 1.47, 1647.19]], "batl": NaN}, {"timestamp": 1578772245012, "ltp": 1.5, "tv": 22475.12, "trd": [[1.5, 855.07]], "batb": [[0, 1.5, 38.73], [1, 1.49, 370.44], [2, 1.48, 293.85]], "batl": NaN}, {"timestamp": 1578772245958, "ltp": 1.5, "tv": 22475.12, "trd": NaN, "batb": [[0, 1.49, 370.44], [1, 1.48, 293.85], [2, 1.47, 1647.19]], "batl": NaN}, {"timestamp": 1578772248055, "ltp": 1.5, "tv": 22475.12, "trd": NaN, "batb": NaN, "batl": [[0, 1.51, 592.09]]}, {"timestamp": 1578772248994, "ltp": 1.5, "tv": 22475.12, "trd": NaN, "batb": NaN, "batl": [[0, 1.51, 935.02]]}, {"timestamp": 1578772253994, "ltp": 1.5, "tv": 22475.12, "trd": NaN, "batb": NaN, "batl": [[0, 1.51, 698.25]]}, {"timestamp": 1578772254993, "ltp": 1.5, "tv": 22475.12, "trd": NaN, "batb": [[0, 1.49, 140.83]], "batl": [[0, 1.5, 2.3], [1, 1.51, 698.25], [2, 1.52, 736.2]]}, {"timestamp": 1578772256986, "ltp": 1.5, "tv": 22475.12, "trd": NaN, "batb": NaN, "batl": [[0, 1.5, 104.44]]}, {"timestamp": 1578772257977, "ltp": 1.5, "tv": 22481.25, "trd": [[1.5, 861.2]], "batb": NaN, "batl": [[0, 1.5, 98.31]]}, {"timestamp": 1578772259971, "ltp": 1.5, "tv": 22481.84, "trd": [[1.5, 861.79]], "batb": NaN, "batl": [[0, 1.5, 98.49]]}, {"timestamp": 1578772260987, "ltp": 1.5, "tv": 22507.46, "trd": [[1.5, 887.41]], "batb": [[1, 1.48, 781.85]], "batl": [[0, 1.5, 85.68]]}, {"timestamp": 1578772264028, "ltp": 1.5, "tv": 22507.46, "trd": NaN, "batb": [[1, 1.48, 293.85]], "batl": [[1, 1.51, 929.24]]}, {"timestamp": 1578772265855, "ltp": 1.5, "tv": 22507.46, "trd": NaN, "batb": NaN, "batl": [[0, 1.5, 85.21]]}, {"timestamp": 1578772270045, "ltp": 1.5, "tv": 22507.46, "trd": NaN, "batb": NaN, "batl": [[1, 1.51, 464.24], [2, 1.52, 272.2]]}, {"timestamp": 1578772271046, "ltp": 1.49, "tv": 22513.18, "trd": [[1.49, 5.72]], "batb": [[0, 1.49, 137.98]], "batl": NaN}, {"timestamp": 1578772273991, "ltp": 1.49, "tv": 22519.18, "trd": [[1.49, 11.72]], "batb": [[0, 1.49, 134.98]], "batl": NaN}, {"timestamp": 1578772281005, "ltp": 1.5, "tv": 22528.36, "trd": [[1.5, 896.59]], "batb": NaN, "batl": [[0, 1.5, 80.62]]}, {"timestamp": 1578772284044, "ltp": 1.49, "tv": 22728.36, "trd": [[1.49, 211.72]], "batb": [[0, 1.49, 34.98]], "batl": NaN}, {"timestamp": 1578772285035, "ltp": 1.49, "tv": 22739.57, "trd": [[1.49, 222.92]], "batb": [[0, 1.49, 29.37]], "batl": NaN}, {"timestamp": 1578772286034, "ltp": 1.49, "tv": 22798.31, "trd": [[1.49, 281.67]], "batb": [[0, 1.48, 267.87], [1, 1.47, 1647.19], [2, 1.46, 1357.98]], "batl": [[0, 1.49, 170.63], [1, 1.5, 80.62], [2, 1.51, 393.3]]}, {"timestamp": 1578772287034, "ltp": 1.49, "tv": 22798.31, "trd": NaN, "batb": [[0, 1.48, 38.27], [1, 1.47, 1404]], "batl": NaN}, {"timestamp": 1578772288028, "ltp": 1.49, "tv": 22814.59, "trd": [[1.49, 297.95]], "batb": [[1, 1.47, 1325.73]], "batl": [[0, 1.49, 162.49]]}, {"timestamp": 1578772288914, "ltp": 1.49, "tv": 22814.59, "trd": NaN, "batb": NaN, "batl": [[0, 1.49, 162.96]]}, {"timestamp": 1578772290015, "ltp": 1.49, "tv": 22814.59, "trd": NaN, "batb": NaN, "batl": [[2, 1.51, 361.59]]}, {"timestamp": 1578772291956, "ltp": 1.49, "tv": 22814.59, "trd": NaN, "batb": NaN, "batl": [[0, 1.5, 81.09], [1, 1.51, 361.59], [2, 1.53, 456]]}, {"timestamp": 1578772293054, "ltp": 1.49, "tv": 22814.59, "trd": NaN, "batb": NaN, "batl": [[0, 1.5, 112.69], [2, 1.53, 906]]}, {"timestamp": 1578772293949, "ltp": 1.49, "tv": 22815.53, "trd": [[1.49, 298.89]], "batb": [[0, 1.49, 38.53], [1, 1.48, 38.27], [2, 1.47, 817.73]], "batl": [[0, 1.5, 447.85], [2, 1.53, 450]]}, {"timestamp": 1578772294860, "ltp": 1.49, "tv": 22815.53, "trd": NaN, "batb": [[2, 1.47, 791.36]], "batl": [[0, 1.5, 112.21], [1, 1.51, 30.56]]}, {"timestamp": 1578772296040, "ltp": 1.49, "tv": 22815.53, "trd": NaN, "batb": NaN, "batl": [[0, 1.5, 80.62], [1, 1.54, 3], [2, 27, 1.7]]}, {"timestamp": 1578772308353, "ltp": 1.49, "tv": 22815.53, "trd": NaN, "batb": [[0, 1.48, 38.27], [1, 1.47, 791.36], [2, 1.46, 267.87]], "batl": NaN}, {"timestamp": 1578772347979, "ltp": 1.49, "tv": 22815.53, "trd": NaN, "batb": [[1, 1.47, 560.82], [2, 1.46, 38.27]], "batl": NaN}, {"timestamp": 1578772355022, "ltp": 1.49, "tv": 22815.53, "trd": NaN, "batb": [[0, 1.85, 65.82], [1, 1.67, 459.21], [2, 1.48, 38.27]], "batl": NaN}, {"timestamp": 1578772356009, "ltp": 1.49, "tv": 22815.53, "trd": NaN, "batb": [[0, 1.97, 25.01], [1, 1.85, 65.82], [2, 1.67, 688.81]], "batl": [[0, 2.48, 186]]}, {"timestamp": 1578772356995, "ltp": 1.49, "tv": 22815.53, "trd": NaN, "batb": [[0, 2.04, 334], [1, 2.02, 369], [2, 2, 185]], "batl": [[0, 2.42, 205], [1, 2.44, 206], [2, 2.46, 185]]}, {"timestamp": 1578772357976, "ltp": 1.49, "tv": 22815.53, "trd": NaN, "batb": NaN, "batl": [[0, 2.28, 15.31], [1, 2.42, 205], [2, 2.44, 206]]}, {"timestamp": 1578772362030, "ltp": 1.49, "tv": 22815.53, "trd": NaN, "batb": [[2, 2, 225.29]], "batl": [[1, 2.38, 1999.75], [2, 2.42, 205]]}, {"timestamp": 1578772363012, "ltp": 1.49, "tv": 22815.53, "trd": NaN, "batb": [[1, 2.02, 409.29]], "batl": NaN}, {"timestamp": 1578772364005, "ltp": 1.49, "tv": 22815.53, "trd": NaN, "batb": [[0, 2.04, 374.29]], "batl": NaN}, {"timestamp": 1578772364993, "ltp": 1.49, "tv": 22815.53, "trd": NaN, "batb": [[0, 2.08, 80.59], [1, 2.06, 358], [2, 2.04, 334]], "batl": [[0, 2.28, 39.31], [1, 2.42, 205], [2, 2.44, 206]]}, {"timestamp": 1578772366041, "ltp": 1.49, "tv": 22815.53, "trd": NaN, "batb": [[0, 2.08, 120.88], [1, 2.06, 458.16], [2, 2.04, 1209.23]], "batl": [[0, 2.26, 1.95], [1, 2.28, 15.31], [2, 2.42, 205]]}, {"timestamp": 1578772367023, "ltp": 1.49, "tv": 22815.53, "trd": NaN, "batb": [[2, 2.04, 334]], "batl": NaN}, {"timestamp": 1578772368009, "ltp": 1.49, "tv": 22815.53, "trd": NaN, "batb": [[0, 2.16, 23.4], [1, 2.08, 120.88], [2, 2.06, 458.16]], "batl": NaN}, {"timestamp": 1578772369001, "ltp": 1.49, "tv": 22815.53, "trd": NaN, "batb": NaN, "batl": [[0, 2.22, 7.66], [1, 2.26, 1.95], [2, 2.28, 15.31]]}, {"timestamp": 1578772369992, "ltp": 1.49, "tv": 22815.53, "trd": NaN, "batb": NaN, "batl": [[0, 2.26, 51.95], [1, 2.28, 15.31], [2, 2.42, 205]]}, {"timestamp": 1578772371027, "ltp": 1.49, "tv": 22815.53, "trd": NaN, "batb": NaN, "batl": [[1, 2.28, 1027.4]]}, {"timestamp": 1578772372020, "ltp": 1.49, "tv": 22815.53, "trd": NaN, "batb": [[2, 2.06, 377.58]], "batl": [[0, 2.26, 81.8], [2, 2.32, 200]]}, {"timestamp": 1578772373009, "ltp": 2.08, "tv": 22848.93, "trd": [[2.08, 30], [2.16, 3.4]], "batb": [[0, 2.08, 105.88], [1, 2.06, 1642.35], [2, 2.04, 1721.09]], "batl": NaN}, {"timestamp": 1578772373995, "ltp": 2.08, "tv": 22848.93, "trd": NaN, "batb": NaN, "batl": [[1, 2.28, 1012.09]]}, {"timestamp": 1578772375041, "ltp": 2.08, "tv": 22868.93, "trd": [[2.08, 50]], "batb": [[0, 2.08, 95.88]], "batl": [[0, 2.26, 31.8]]}, {"timestamp": 1578772375927, "ltp": 2.08, "tv": 22868.93, "trd": NaN, "batb": [[0, 2.1, 409.09], [1, 2.08, 408.38], [2, 2.06, 1739.35]], "batl": [[1, 2.28, 1310.4], [2, 2.3, 394.67]]}, {"timestamp": 1578772377028, "ltp": 2.14, "tv": 22888.94, "trd": [[2.14, 20]], "batb": [[0, 2.14, 18.09], [1, 2.1, 449.09], [2, 2.08, 95.88]], "batl": [[0, 2.16, 13.67], [1, 2.26, 39.46], [2, 2.28, 1012.09]]}, {"timestamp": 1578772378023, "ltp": 2.16, "tv": 22916.28, "trd": [[2.16, 30.74]], "batb": [[0, 2.16, 13.21], [1, 2.12, 40], [2, 2.1, 569.38]], "batl": [[0, 2.22, 3.4], [1, 2.26, 9.61]]}, {"timestamp": 1578772379046, "ltp": 2.12, "tv": 22921.2, "trd": [[2.12, 4.92]], "batb": [[0, 2.12, 37.54], [1, 2.1, 569.38], [2, 2.08, 441.88]], "batl": [[0, 2.22, 4.09]]}, {"timestamp": 1578772380032, "ltp": 2.16, "tv": 22968.0, "trd": [[2.16, 77.54]], "batb": NaN, "batl": [[0, 2.16, 77.29], [1, 2.2, 50], [2, 2.22, 3.4]]}, {"timestamp": 1578772381024, "ltp": 2.1, "tv": 23051.3, "trd": [[2.1, 8.22], [2.12, 80]], "batb": [[0, 2.1, 1517.91], [1, 2.08, 441.88], [2, 2.06, 1719.77]], "batl": NaN}, {"timestamp": 1578772382021, "ltp": 2.1, "tv": 23140.53, "trd": [[2.1, 86.28], [2.16, 88.71]], "batb": [[0, 2.1, 1478.88]], "batl": [[0, 2.16, 66.19], [1, 2.2, 61.21]]}, {"timestamp": 1578772384025, "ltp": 2.16, "tv": 23154.21, "trd": [[2.16, 102.39]], "batb": NaN, "batl": [[0, 2.16, 59.35]]}, {"timestamp": 1578772384907, "ltp": 2.16, "tv": 23154.21, "trd": NaN, "batb": [[0, 2.12, 40], [1, 2.1, 1478.88], [2, 2.08, 441.88]], "batl": NaN}, {"timestamp": 1578772385966, "ltp": 2.16, "tv": 23377.11, "trd": [[2.12, 136.42], [2.16, 268.88]], "batb": [[0, 2.12, 11.79], [1, 2.1, 1112.93]], "batl": [[0, 2.2, 11.21], [1, 2.22, 3.4], [2, 2.28, 1558.65]]}, {"timestamp": 1578772386964, "ltp": 2.14, "tv": 23394.75, "trd": [[2.12, 146.92], [2.14, 27.14]], "batb": [[0, 2.14, 279.89], [1, 2.12, 1752.63], [2, 2.1, 2821.09]], "batl": [[2, 2.28, 249]]}, {"timestamp": 1578772387959, "ltp": 2.14, "tv": 23426.67, "trd": [[2.14, 59.06]], "batb": [[0, 2.14, 250.26], [1, 2.12, 6.54], [2, 2.1, 183.13]], "batl": [[2, 2.26, 21.18]]}, {"timestamp": 1578772388952, "ltp": 2.14, "tv": 23475.27, "trd": [[2.14, 107.66]], "batb": [[0, 2.14, 225.96], [2, 2.1, 179.02]], "batl": NaN}, {"timestamp": 1578772390974, "ltp": 2.14, "tv": 23484.45, "trd": [[2.14, 116.84]], "batb": [[0, 2.14, 221.37], [1, 2.12, 25.94], [2, 2.1, 59.02]], "batl": [[0, 2.2, 37.68], [2, 2.26, 272.18]]}, {"timestamp": 1578772392023, "ltp": 2.14, "tv": 23539.74, "trd": [[2.14, 172.13]], "batb": [[0, 2.14, 193.73], [1, 2.12, 1.7]], "batl": [[0, 2.2, 11.21], [2, 2.24, 108.73]]}, {"timestamp": 1578772392968, "ltp": 2.14, "tv": 23595.19, "trd": [[2.14, 210.71], [2.16, 285.75]], "batb": [[0, 2.14, 174.18], [2, 2.1, 799.11]], "batl": [[0, 2.2, 41.06], [1, 2.22, 11.07], [2, 2.26, 272.18]]}, {"timestamp": 1578772394032, "ltp": 2.16, "tv": 23600.92, "trd": [[2.16, 291.48]], "batb": [[0, 2.16, 77.27], [1, 2.14, 174.18], [2, 2.12, 1.7]], "batl": NaN}, {"timestamp": 1578772394980, "ltp": 2.16, "tv": 23611.97, "trd": [[2.16, 302.53]], "batb": [[0, 2.16, 71.75], [1, 2.14, 2025.04], [2, 2.12, 307.7]], "batl": [[1, 2.22, 3.4]]}, {"timestamp": 1578772395979, "ltp": 2.16, "tv": 23642.04, "trd": [[2.16, 332.6]], "batb": [[0, 2.16, 46.61], [1, 2.14, 174.18]], "batl": [[0, 2.2, 111.85]]}, {"timestamp": 1578772396977, "ltp": 2.14, "tv": 23723.96, "trd": [[2.14, 230.71], [2.16, 394.52]], "batb": [[0, 2.14, 164.18], [1, 2.12, 307.7], [2, 2.1, 481.29]], "batl": NaN}, {"timestamp": 1578772397970, "ltp": 2.14, "tv": 23756.67, "trd": [[2.14, 263.43]], "batb": [[0, 2.14, 147.82]], "batl": NaN}, {"timestamp": 1578772399006, "ltp": 2.14, "tv": 23771.82, "trd": [[2.14, 278.58]], "batb": [[0, 2.14, 180.44], [1, 2.12, 348]], "batl": [[0, 2.16, 50], [1, 2.2, 137.39], [2, 2.22, 3.4]]}, {"timestamp": 1578772400005, "ltp": 2.14, "tv": 23996.05, "trd": [[2.14, 502.81]], "batb": [[0, 2.14, 68.32], [1, 2.12, 416.71], [2, 2.1, 536.69]], "batl": [[0, 2.2, 151.9], [1, 2.22, 47.08], [2, 2.26, 272.18]]}, {"timestamp": 1578772401002, "ltp": 2.14, "tv": 23996.05, "trd": NaN, "batb": [[1, 2.12, 448.13], [2, 2.1, 642.64]], "batl": [[1, 2.22, 222.99], [2, 2.24, 267]]}, {"timestamp": 1578772402030, "ltp": 2.14, "tv": 23996.05, "trd": NaN, "batb": [[1, 2.12, 468.53]], "batl": [[1, 2.22, 286.84]]}, {"timestamp": 1578772403016, "ltp": 2.12, "tv": 27853.88, "trd": [[2.12, 3868.09], [2.14, 639.46]], "batb": [[0, 2.12, 393.23], [1, 2.1, 2320.24], [2, 2.08, 1464.47]], "batl": [[0, 2.14, 33.73], [1, 2.2, 193.56], [2, 2.22, 286.84]]}, {"timestamp": 1578772404015, "ltp": 2.14, "tv": 27870.99, "trd": [[2.14, 656.57]], "batb": [[1, 2.1, 2638.66], [2, 2.08, 584.66]], "batl": [[0, 2.14, 16.63], [1, 2.16, 233.34], [2, 2.2, 257.41]]}, {"timestamp": 1578772405006, "ltp": 2.14, "tv": 27870.99, "trd": NaN, "batb": NaN, "batl": [[0, 2.14, 39.43], [2, 2.2, 200.82]]}, {"timestamp": 1578772406002, "ltp": 2.14, "tv": 27951.99, "trd": [[2.14, 737.57]], "batb": [[0, 2.1, 961.06], [1, 2.08, 666.66], [2, 2.06, 1766.87]], "batl": [[0, 2.14, 5.11]]}, {"timestamp": 1578772407006, "ltp": 2.14, "tv": 27951.99, "trd": NaN, "batb": NaN, "batl": [[0, 2.14, 14.29], [1, 2.16, 282.45]]}, {"timestamp": 1578772407989, "ltp": 2.14, "tv": 27951.99, "trd": NaN, "batb": NaN, "batl": [[1, 2.16, 382.45]]}, {"timestamp": 1578772408980, "ltp": 2.14, "tv": 27968.92, "trd": [[2.14, 754.5]], "batb": [[2, 2.06, 1669.87]], "batl": [[0, 2.14, 2.72], [1, 2.16, 458.99]]}, {"timestamp": 1578772409981, "ltp": 2.14, "tv": 27968.92, "trd": NaN, "batb": [[0, 2.12, 1253.83], [1, 2.1, 961.06], [2, 2.08, 666.66]], "batl": [[0, 2.14, 2], [2, 2.18, 90]]}, {"timestamp": 1578772410978, "ltp": 2.14, "tv": 27968.92, "trd": NaN, "batb": [[0, 2.12, 99], [1, 2.1, 1744.8]], "batl": [[0, 2.14, 82.21], [1, 2.16, 460.69], [2, 2.18, 165.15]]}, {"timestamp": 1578772411983, "ltp": 2.12, "tv": 27983.04, "trd": [[2.12, 3882.21]], "batb": [[0, 2.12, 91.94], [1, 2.1, 1876.74]], "batl": [[0, 2.14, 155.24]]}, {"timestamp": 1578772413015, "ltp": 2.12, "tv": 27983.04, "trd": NaN, "batb": [[2, 2.08, 1083.32]], "batl": [[0, 2.14, 206.75], [1, 2.16, 442.71]]}, {"timestamp": 1578772413968, "ltp": 2.12, "tv": 28015.04, "trd": [[2.12, 3914.21]], "batb": [[0, 2.12, 75.94], [1, 2.1, 1467.65]], "batl": [[0, 2.14, 217.8], [1, 2.16, 362.35], [2, 2.18, 329.15]]}, {"timestamp": 1578772415025, "ltp": 2.12, "tv": 28040.58, "trd": [[2.12, 3939.75]], "batb": [[0, 2.12, 1929.71], [1, 2.1, 3129.8]], "batl": [[0, 2.14, 246.89], [2, 2.18, 679]]}, {"timestamp": 1578772416002, "ltp": 2.12, "tv": 28040.58, "trd": NaN, "batb": [[1, 2.1, 3114.52]], "batl": [[2, 2.18, 689.71]]}, {"timestamp": 1578772417002, "ltp": 2.12, "tv": 28070.45, "trd": [[2.12, 3969.61]], "batb": [[0, 2.12, 1623.78], [1, 2.1, 3099.42]], "batl": [[0, 2.14, 279.26]]}, {"timestamp": 1578772418000, "ltp": 2.12, "tv": 28070.45, "trd": NaN, "batb": NaN, "batl": [[0, 2.14, 268.2], [1, 2.16, 357.76], [2, 2.18, 599.71]]}, {"timestamp": 1578772418985, "ltp": 2.12, "tv": 28075.64, "trd": [[2.12, 3974.81]], "batb": [[0, 2.12, 1621.18]], "batl": [[2, 2.18, 603.12]]}, {"timestamp": 1578772420033, "ltp": 2.12, "tv": 28926.85, "trd": [[2.12, 4826.01]], "batb": [[0, 2.1, 1437.27], [1, 2.08, 1083.32], [2, 2.06, 635.38]], "batl": [[0, 2.14, 752.41]]}, {"timestamp": 1578772421024, "ltp": 2.12, "tv": 28926.85, "trd": NaN, "batb": NaN, "batl": [[0, 2.12, 5.36], [1, 2.14, 761.43], [2, 2.16, 344.99]]}, {"timestamp": 1578772422022, "ltp": 2.12, "tv": 28926.85, "trd": NaN, "batb": NaN, "batl": [[0, 2.12, 5.51], [2, 2.16, 337.34]]}, {"timestamp": 1578772423018, "ltp": 2.12, "tv": 28926.85, "trd": NaN, "batb": [[0, 2.1, 1356.68]], "batl": [[1, 2.14, 608.44]]}, {"timestamp": 1578772424004, "ltp": 2.12, "tv": 28926.85, "trd": NaN, "batb": NaN, "batl": [[0, 2.12, 58.35], [1, 2.14, 652.99], [2, 2.16, 352.65]]}, {"timestamp": 1578772424895, "ltp": 2.12, "tv": 28926.85, "trd": NaN, "batb": [[1, 2.08, 987.91]], "batl": [[0, 2.12, 62.94], [1, 2.14, 742.99]]}, {"timestamp": 1578772426002, "ltp": 2.16, "tv": 30098.69, "trd": [[2.12, 4888.95], [2.14, 1472.49], [2.16, 785.43]], "batb": NaN, "batl": [[0, 2.18, 535.86], [1, 2.2, 413.05], [2, 2.22, 537.56]]}, {"timestamp": 1578772426995, "ltp": 2.16, "tv": 30100.39, "trd": [[2.16, 787.13]], "batb": NaN, "batl": [[0, 2.18, 525.15]]}, {"timestamp": 1578772428048, "ltp": 2.12, "tv": 30201.97, "trd": [[2.12, 4890.95], [2.16, 886.71]], "batb": [[2, 2.06, 2628.08]], "batl": [[0, 2.16, 14.74], [1, 2.18, 525.15], [2, 2.2, 349.2]]}, {"timestamp": 1578772429042, "ltp": 2.12, "tv": 30396.27, "trd": [[2.12, 5075.91], [2.14, 1481.84]], "batb": NaN, "batl": [[0, 2.16, 30.28]]}, {"timestamp": 1578772430030, "ltp": 2.12, "tv": 30469.73, "trd": [[2.12, 5149.37]], "batb": NaN, "batl": [[0, 2.16, 14.74]]}, {"timestamp": 1578772431026, "ltp": 2.12, "tv": 30498.29, "trd": [[2.12, 5177.93]], "batb": NaN, "batl": [[0, 2.12, 2.27], [1, 2.16, 14.74], [2, 2.18, 525.15]]}, {"timestamp": 1578772431967, "ltp": 2.1, "tv": 30522.68, "trd": [[2.1, 108.4], [2.12, 5180.2]], "batb": [[0, 2.1, 1345.62]], "batl": [[0, 2.12, 25.97], [1, 2.14, 1.69], [2, 2.16, 14.74]]}, {"timestamp": 1578772433026, "ltp": 2.12, "tv": 30573.65, "trd": [[2.12, 5231.17]], "batb": [[0, 2.12, 56.92], [1, 2.1, 1345.62], [2, 2.08, 2793.6]], "batl": [[0, 2.14, 1.69], [1, 2.16, 14.74], [2, 2.18, 525.15]]}, {"timestamp": 1578772434026, "ltp": 2.12, "tv": 30609.24, "trd": [[2.12, 5266.76]], "batb": [[0, 2.12, 21.36], [1, 2.1, 1376.83], [2, 2.08, 2887.05]], "batl": [[1, 2.18, 525.15], [2, 2.2, 1685.12]]}, {"timestamp": 1578772434956, "ltp": 2.12, "tv": 30654.78, "trd": [[2.12, 5312.3]], "batb": [[0, 2.1, 1376.83], [1, 2.08, 2887.05], [2, 2.06, 2628.08]], "batl": NaN}, {"timestamp": 1578772436023, "ltp": 2.14, "tv": 30673.48, "trd": [[2.14, 1500.55]], "batb": [[0, 2.12, 44.64], [1, 2.1, 1376.83], [2, 2.08, 2470.39]], "batl": [[0, 2.16, 43.1]]}, {"timestamp": 1578772437014, "ltp": 2.14, "tv": 30673.48, "trd": NaN, "batb": NaN, "batl": [[1, 2.18, 361.15]]}, {"timestamp": 1578772439044, "ltp": 2.14, "tv": 30673.48, "trd": NaN, "batb": [[0, 2.14, 1.75], [1, 2.12, 44.64], [2, 2.1, 1376.83]], "batl": [[2, 2.2, 373.2]]}, {"timestamp": 1578772440043, "ltp": 2.14, "tv": 30675.24, "trd": [[2.14, 1502.3]], "batb": [[0, 2.12, 44.64], [1, 2.1, 1376.83], [2, 2.08, 768.86]], "batl": NaN}, {"timestamp": 1578772441035, "ltp": 2.14, "tv": 30675.24, "trd": NaN, "batb": [[2, 2.08, 749.28]], "batl": [[0, 2.14, 43.85], [1, 2.16, 324.1], [2, 2.18, 403.58]]}, {"timestamp": 1578772442038, "ltp": 2.14, "tv": 30675.24, "trd": NaN, "batb": NaN, "batl": [[0, 2.16, 324.1], [1, 2.18, 403.58], [2, 2.2, 373.2]]}, {"timestamp": 1578772442979, "ltp": 2.14, "tv": 30675.24, "trd": NaN, "batb": NaN, "batl": [[0, 2.16, 43.1], [1, 2.18, 75.15], [2, 2.2, 91.2]]}, {"timestamp": 1578772443967, "ltp": 2.12, "tv": 30947.99, "trd": [[2.12, 5585.05]], "batb": [[0, 2.1, 1409.32], [1, 2.08, 749.28], [2, 2.06, 635.38]], "batl": [[0, 2.16, 72.95]]}, {"timestamp": 1578772445037, "ltp": 2.12, "tv": 30949.86, "trd": [[2.12, 5586.91]], "batb": [[0, 2.1, 1383.89], [1, 2.08, 645.12]], "batl": NaN}, {"timestamp": 1578772445968, "ltp": 2.12, "tv": 30949.86, "trd": NaN, "batb": NaN, "batl": [[0, 2.16, 98.48]]}, {"timestamp": 1578772447990, "ltp": 2.12, "tv": 30949.86, "trd": NaN, "batb": [[0, 2.1, 468.21], [2, 2.06, 654.96]], "batl": [[0, 2.14, 2], [1, 2.16, 98.48], [2, 2.18, 239.15]]}, {"timestamp": 1578772449055, "ltp": 2.12, "tv": 30949.86, "trd": NaN, "batb": [[0, 2.1, 148.27], [1, 2.08, 723.43]], "batl": NaN}, {"timestamp": 1578772449944, "ltp": 2.14, "tv": 30951.86, "trd": [[2.14, 1504.3]], "batb": [[0, 2.1, 38.27]], "batl": [[0, 2.16, 98.48], [1, 2.18, 239.15], [2, 2.2, 91.2]]}, {"timestamp": 1578772451039, "ltp": 2.14, "tv": 30951.86, "trd": NaN, "batb": NaN, "batl": [[0, 2.16, 114.17]]}, {"timestamp": 1578772451969, "ltp": 2.1, "tv": 30988.88, "trd": [[2.1, 145.43]], "batb": [[0, 2.1, 19.75]], "batl": [[0, 2.14, 43.85], [1, 2.16, 128.92], [2, 2.18, 239.15]]}, {"timestamp": 1578772452958, "ltp": 2.1, "tv": 30988.88, "trd": NaN, "batb": NaN, "batl": [[1, 2.16, 156.24]]}, {"timestamp": 1578772453944, "ltp": 2.1, "tv": 30988.88, "trd": NaN, "batb": [[1, 2.08, 645.12]], "batl": [[1, 2.16, 125.81]]}, {"timestamp": 1578772455040, "ltp": 2.1, "tv": 30988.88, "trd": NaN, "batb": [[0, 2.1, 58.06], [1, 2.08, 563.12], [2, 2.06, 547.96]], "batl": NaN}, {"timestamp": 1578772455985, "ltp": 2.14, "tv": 30996.24, "trd": [[2.14, 1511.66]], "batb": NaN, "batl": [[0, 2.14, 40.17], [2, 2.18, 271.1]]}, {"timestamp": 1578772456977, "ltp": 2.12, "tv": 31649.31, "trd": [[2.12, 6239.98]], "batb": [[2, 2.06, 2169.41]], "batl": [[1, 2.16, 1854.82], [2, 2.18, 2090]]}, {"timestamp": 1578772457965, "ltp": 2.14, "tv": 31664.0, "trd": [[2.14, 1526.35]], "batb": NaN, "batl": [[0, 2.14, 25.48], [2, 2.18, 2387.74]]}, {"timestamp": 1578772458954, "ltp": 2.1, "tv": 31716.32, "trd": [[2.1, 181.96], [2.12, 6255.77]], "batb": [[0, 2.1, 39.79]], "batl": [[0, 2.14, 25.89]]}, {"timestamp": 1578772459942, "ltp": 2.14, "tv": 31750.65, "trd": [[2.12, 6256.58], [2.14, 1559.87]], "batb": [[2, 2.06, 2149.83]], "batl": [[0, 2.14, 8.72]]}, {"timestamp": 1578772460976, "ltp": 2.14, "tv": 31750.65, "trd": NaN, "batb": [[0, 2.12, 51.78], [1, 2.1, 85.17], [2, 2.08, 563.12]], "batl": NaN}, {"timestamp": 1578772461970, "ltp": 2.14, "tv": 31750.65, "trd": NaN, "batb": NaN, "batl": [[1, 2.16, 1895.3]]}, {"timestamp": 1578772462957, "ltp": 2.14, "tv": 31750.65, "trd": NaN, "batb": NaN, "batl": [[1, 2.16, 2015.52]]}, {"timestamp": 1578772463950, "ltp": 2.12, "tv": 31850.65, "trd": [[2.12, 6356.58]], "batb": [[0, 2.12, 1.78], [1, 2.1, 55.11]], "batl": [[0, 2.14, 46.64]]}, {"timestamp": 1578772464986, "ltp": 2.12, "tv": 31850.65, "trd": NaN, "batb": [[2, 2.08, 469.67]], "batl": [[0, 2.14, 8.72]]}, {"timestamp": 1578772465976, "ltp": 2.14, "tv": 31859.37, "trd": [[2.14, 1568.59]], "batb": [[0, 2.12, 27.32], [1, 2.1, 486.95]], "batl": [[0, 2.16, 2015.52], [1, 2.18, 2387.74], [2, 2.2, 819.67]]}, {"timestamp": 1578772467011, "ltp": 2.14, "tv": 31859.37, "trd": NaN, "batb": [[2, 2.08, 560.67]], "batl": [[0, 2.16, 2045.79]]}, {"timestamp": 1578772468052, "ltp": 2.12, "tv": 31875.85, "trd": [[2.12, 6373.06]], "batb": [[0, 2.12, 19.08]], "batl": [[0, 2.14, 8.83], [1, 2.16, 2015.94], [2, 2.18, 2387.74]]}, {"timestamp": 1578772468981, "ltp": 2.12, "tv": 31875.85, "trd": NaN, "batb": [[1, 2.1, 532.4]], "batl": [[0, 2.16, 2028.59], [1, 2.18, 2387.74], [2, 2.2, 819.67]]}, {"timestamp": 1578772471987, "ltp": 2.16, "tv": 33254.28, "trd": [[2.16, 2265.13]], "batb": NaN, "batl": [[0, 2.16, 650.16], [1, 2.18, 833.84]]}, {"timestamp": 1578772472982, "ltp": 2.16, "tv": 33254.28, "trd": NaN, "batb": [[2, 2.08, 599.83]], "batl": [[0, 2.16, 634.31]]}, {"timestamp": 1578772473967, "ltp": 2.12, "tv": 33258.02, "trd": [[2.12, 6376.8]], "batb": [[0, 2.12, 17.2]], "batl": [[2, 2.2, 1641.25]]}, {"timestamp": 1578772474957, "ltp": 2.14, "tv": 33259.7, "trd": [[2.14, 1570.27]], "batb": [[0, 2.14, 13.77], [1, 2.12, 17.2], [2, 2.1, 532.4]], "batl": [[0, 2.16, 619.89]]}, {"timestamp": 1578772476002, "ltp": 2.12, "tv": 33297.73, "trd": [[2.12, 6387.29], [2.14, 1597.81]], "batb": [[0, 2.12, 11.96], [1, 2.1, 532.4], [2, 2.08, 599.83]], "batl": NaN}, {"timestamp": 1578772477990, "ltp": 2.12, "tv": 33297.73, "trd": NaN, "batb": NaN, "batl": [[0, 2.16, 1459.36], [2, 2.2, 1115.12]]}, {"timestamp": 1578772478977, "ltp": 2.12, "tv": 33297.73, "trd": NaN, "batb": [[1, 2.1, 596.25]], "batl": [[0, 2.16, 781.67]]}, {"timestamp": 1578772480014, "ltp": 2.12, "tv": 33297.73, "trd": NaN, "batb": [[0, 2.12, 56.6], [2, 2.08, 691.31]], "batl": [[0, 2.16, 2133.77]]}, {"timestamp": 1578772481003, "ltp": 2.12, "tv": 33339.85, "trd": [[2.12, 6429.42]], "batb": [[0, 2.12, 35.54], [1, 2.1, 904.25]], "batl": NaN}, {"timestamp": 1578772481991, "ltp": 2.12, "tv": 33339.85, "trd": NaN, "batb": [[0, 2.12, 107.73]], "batl": NaN}, {"timestamp": 1578772482975, "ltp": 2.12, "tv": 33339.85, "trd": NaN, "batb": [[2, 2.08, 652.15]], "batl": NaN}, {"timestamp": 1578772484013, "ltp": 2.12, "tv": 33339.85, "trd": NaN, "batb": NaN, "batl": [[0, 2.14, 1807.53], [1, 2.16, 2133.77], [2, 2.18, 833.84]]}, {"timestamp": 1578772484998, "ltp": 2.12, "tv": 33349.85, "trd": [[2.12, 6439.42]], "batb": [[0, 2.12, 102.73], [2, 2.08, 561.15]], "batl": NaN}, {"timestamp": 1578772485999, "ltp": 2.12, "tv": 33502.92, "trd": [[2.12, 6592.48]], "batb": [[0, 2.12, 26.2]], "batl": NaN}, {"timestamp": 1578772487018, "ltp": 2.12, "tv": 33502.92, "trd": NaN, "batb": NaN, "batl": [[1, 2.16, 3083.24], [2, 2.18, 537.81]]}, {"timestamp": 1578772487975, "ltp": 2.12, "tv": 33502.92, "trd": NaN, "batb": [[1, 2.1, 888.93]], "batl": [[0, 2.16, 3083.24], [1, 2.18, 537.81], [2, 2.2, 704.33]]}, {"timestamp": 1578772489012, "ltp": 2.12, "tv": 33523.27, "trd": [[2.12, 6612.83]], "batb": [[0, 2.12, 15.51], [1, 2.1, 580.93], [2, 2.08, 564.98]], "batl": NaN}, {"timestamp": 1578772490005, "ltp": 2.12, "tv": 33524.01, "trd": [[2.12, 6613.58]], "batb": [[0, 2.12, 15.14], [2, 2.08, 473.5]], "batl": NaN}, {"timestamp": 1578772490991, "ltp": 2.12, "tv": 33524.01, "trd": NaN, "batb": NaN, "batl": [[0, 2.14, 1.87], [1, 2.16, 3030.12], [2, 2.18, 537.81]]}, {"timestamp": 1578772491976, "ltp": 2.12, "tv": 33524.76, "trd": [[2.12, 6614.32]], "batb": [[0, 2.12, 14.77]], "batl": NaN}, {"timestamp": 1578772493009, "ltp": 2.12, "tv": 33532.42, "trd": [[2.12, 6621.98]], "batb": [[0, 2.12, 10.94], [2, 2.08, 503.85]], "batl": NaN}, {"timestamp": 1578772494000, "ltp": 2.12, "tv": 33571.86, "trd": [[2.12, 6661.42]], "batb": [[0, 2.1, 580.93], [1, 2.08, 503.85], [2, 2.06, 727.54]], "batl": NaN}, {"timestamp": 1578772494988, "ltp": 2.12, "tv": 33573.73, "trd": [[2.12, 6663.29]], "batb": [[1, 2.08, 519.17]], "batl": [[0, 2.14, 866.12], [1, 2.16, 3060.55], [2, 2.18, 2296.29]]}, {"timestamp": 1578772496028, "ltp": 2.12, "tv": 33573.73, "trd": NaN, "batb": [[0, 2.1, 517.08]], "batl": NaN}, {"timestamp": 1578772497011, "ltp": 2.12, "tv": 33578.44, "trd": [[2.12, 6668]], "batb": NaN, "batl": [[0, 2.14, 910.86]]}, {"timestamp": 1578772497996, "ltp": 2.12, "tv": 33578.44, "trd": NaN, "batb": NaN, "batl": [[0, 2.12, 86.01], [1, 2.14, 909.97], [2, 2.16, 3060.55]]}, {"timestamp": 1578772499031, "ltp": 2.12, "tv": 33581.48, "trd": [[2.12, 6671.04]], "batb": [[1, 2.08, 473.42]], "batl": [[0, 2.12, 82.98], [1, 2.14, 908.1]]}, {"timestamp": 1578772501021, "ltp": 2.12, "tv": 33581.48, "trd": NaN, "batb": NaN, "batl": [[1, 2.14, 916.1]]}, {"timestamp": 1578772502995, "ltp": 2.12, "tv": 33581.48, "trd": NaN, "batb": [[1, 2.08, 457.36]], "batl": NaN}, {"timestamp": 1578772503990, "ltp": 2.12, "tv": 33581.48, "trd": NaN, "batb": NaN, "batl": [[0, 2.12, 122.15], [1, 2.14, 229.1], [2, 2.16, 1829.08]]}, {"timestamp": 1578772504986, "ltp": 2.12, "tv": 33581.48, "trd": NaN, "batb": [[2, 2.06, 687.54]], "batl": [[1, 2.14, 51.85], [2, 2.16, 30.43]]}, {"timestamp": 1578772506035, "ltp": 2.12, "tv": 33588.31, "trd": [[2.12, 6677.87]], "batb": [[2, 2.06, 575.54]], "batl": [[0, 2.12, 116.09]]}, {"timestamp": 1578772507025, "ltp": 2.1, "tv": 33673.43, "trd": [[2.1, 267.08]], "batb": [[0, 2.1, 474.52]], "batl": [[0, 2.12, 86.24]]}, {"timestamp": 1578772508024, "ltp": 2.1, "tv": 33673.43, "trd": NaN, "batb": [[1, 2.08, 460.88]], "batl": [[0, 2.12, 140.07]]}, {"timestamp": 1578772508908, "ltp": 2.1, "tv": 33673.43, "trd": NaN, "batb": [[1, 2.08, 114.88]], "batl": [[0, 2.12, 88.4]]}, {"timestamp": 1578772509998, "ltp": 2.1, "tv": 33673.43, "trd": NaN, "batb": [[1, 2.08, 65.69]], "batl": [[0, 2.12, 90.26]]}, {"timestamp": 1578772511050, "ltp": 2.1, "tv": 33673.43, "trd": NaN, "batb": [[0, 2.1, 494.71]], "batl": NaN}, {"timestamp": 1578772512036, "ltp": 2.1, "tv": 33673.43, "trd": NaN, "batb": NaN, "batl": [[0, 2.12, 91.97]]}, {"timestamp": 1578772513037, "ltp": 2.1, "tv": 33678.26, "trd": [[2.1, 271.92]], "batb": [[0, 2.1, 492.29]], "batl": [[0, 2.12, 89.67]]}, {"timestamp": 1578772514014, "ltp": 2.1, "tv": 33678.26, "trd": NaN, "batb": NaN, "batl": [[0, 2.12, 97.32]]}, {"timestamp": 1578772514899, "ltp": 2.12, "tv": 33869.37, "trd": [[2.1, 353.03], [2.12, 6787.87]], "batb": [[0, 2.1, 451.73]], "batl": [[0, 2.12, 42.33]]}, {"timestamp": 1578772516044, "ltp": 2.1, "tv": 33893.59, "trd": [[2.1, 377.25]], "batb": [[0, 2.1, 439.63]], "batl": [[2, 2.16, 448.24]]}, {"timestamp": 1578772517038, "ltp": 2.12, "tv": 33928.54, "trd": [[2.12, 6822.82]], "batb": NaN, "batl": [[0, 2.12, 24.85]]}, {"timestamp": 1578772518024, "ltp": 2.12, "tv": 33952.82, "trd": [[2.12, 6847.09]], "batb": NaN, "batl": [[0, 2.12, 2.38]]}, {"timestamp": 1578772519021, "ltp": 2.12, "tv": 33952.82, "trd": NaN, "batb": [[2, 2.06, 217.54]], "batl": NaN}, {"timestamp": 1578772520046, "ltp": 2.1, "tv": 33996.45, "trd": [[2.1, 420.88]], "batb": [[0, 2.1, 417.81], [2, 2.06, 237.54]], "batl": [[2, 2.16, 866.05]]}, {"timestamp": 1578772521033, "ltp": 2.1, "tv": 33996.45, "trd": NaN, "batb": [[0, 2.1, 372.36]], "batl": NaN}, {"timestamp": 1578772522024, "ltp": 2.1, "tv": 33996.45, "trd": NaN, "batb": NaN, "batl": [[0, 2.12, 4.67]]}, {"timestamp": 1578772523056, "ltp": 2.1, "tv": 34011.78, "trd": [[2.1, 436.2]], "batb": [[0, 2.1, 364.69]], "batl": NaN}, {"timestamp": 1578772524044, "ltp": 2.1, "tv": 34087.08, "trd": [[2.1, 511.51]], "batb": [[0, 2.1, 327.04], [1, 2.08, 81.43]], "batl": NaN}, {"timestamp": 1578772525043, "ltp": 2.1, "tv": 34741.16, "trd": [[2.1, 1165.59]], "batb": [[0, 2.08, 81.43], [1, 2.06, 98.59], [2, 2.04, 599.49]], "batl": [[0, 2.1, 172.96], [1, 2.12, 3032.07], [2, 2.14, 2013.73]]}, {"timestamp": 1578772526033, "ltp": 2.1, "tv": 34741.16, "trd": NaN, "batb": [[0, 2.08, 50.12]], "batl": NaN}, {"timestamp": 1578772527019, "ltp": 2.1, "tv": 34741.16, "trd": NaN, "batb": [[0, 2.08, 3.83], [1, 2.06, 67.16]], "batl": NaN}, {"timestamp": 1578772527957, "ltp": 2.1, "tv": 34741.16, "trd": NaN, "batb": NaN, "batl": [[0, 2.1, 173.98]]}, {"timestamp": 1578772529050, "ltp": 2.1, "tv": 34747.09, "trd": [[2.1, 1171.52]], "batb": [[2, 2.04, 500.32]], "batl": [[0, 2.1, 183.18]]}, {"timestamp": 1578772530035, "ltp": 2.1, "tv": 34747.09, "trd": NaN, "batb": [[1, 2.06, 47.16]], "batl": [[1, 2.12, 3056.73]]}, {"timestamp": 1578772531021, "ltp": 2.08, "tv": 34754.74, "trd": [[2.08, 57.65]], "batb": [[0, 2.04, 500.32], [1, 2.02, 741.69], [2, 2, 2454.14]], "batl": [[0, 2.08, 26.02], [1, 2.1, 182.16], [2, 2.12, 3056.73]]}, {"timestamp": 1578772531960, "ltp": 2.08, "tv": 34754.74, "trd": NaN, "batb": [[0, 2.04, 454.24], [1, 2.02, 783.4]], "batl": [[1, 2.1, 216.88], [2, 2.12, 1890.91]]}, {"timestamp": 1578772533055, "ltp": 2.08, "tv": 34780.76, "trd": [[2.08, 83.68]], "batb": [[0, 2.04, 438.04]], "batl": [[0, 2.1, 216.88], [1, 2.12, 1890.91], [2, 2.14, 2256.68]]}, {"timestamp": 1578772534048, "ltp": 2.08, "tv": 34780.76, "trd": NaN, "batb": [[2, 2, 2475.42]], "batl": [[0, 2.08, 46.29], [1, 2.1, 1236.57], [2, 2.12, 1903.76]]}, {"timestamp": 1578772535036, "ltp": 2.08, "tv": 34780.76, "trd": NaN, "batb": [[0, 2.06, 326], [1, 2.04, 438.04], [2, 2.02, 783.4]], "batl": [[1, 2.1, 208.72], [2, 2.12, 1937.27]]}, {"timestamp": 1578772536036, "ltp": 2.08, "tv": 34780.76, "trd": NaN, "batb": [[0, 2.04, 438.04], [1, 2.02, 783.4], [2, 2, 2475.42]], "batl": NaN}, {"timestamp": 1578772537038, "ltp": 2.08, "tv": 34820.76, "trd": [[2.08, 123.68]], "batb": [[0, 2.04, 486.11], [1, 2.02, 832.41]], "batl": [[0, 2.08, 26.29]]}, {"timestamp": 1578772537967, "ltp": 2.08, "tv": 34873.34, "trd": [[2.08, 176.26]], "batb": [[0, 2.08, 23.71], [1, 2.04, 486.11], [2, 2.02, 832.41]], "batl": [[0, 2.1, 204.72], [1, 2.12, 1937.27], [2, 2.14, 2678.14]]}, {"timestamp": 1578772538971, "ltp": 2.08, "tv": 34885.63, "trd": [[2.08, 188.54]], "batb": [[0, 2.08, 13.29]], "batl": NaN}, {"timestamp": 1578772539950, "ltp": 2.1, "tv": 35092.25, "trd": [[2.1, 1378.13]], "batb": [[1, 2.04, 398.11]], "batl": [[0, 2.12, 1937.27], [1, 2.14, 2678.14], [2, 2.16, 689.81]]}, {"timestamp": 1578772541044, "ltp": 2.1, "tv": 35108.51, "trd": [[2.1, 1394.4]], "batb": NaN, "batl": [[0, 2.12, 434.72]]}, {"timestamp": 1578772541978, "ltp": 2.1, "tv": 35108.51, "trd": NaN, "batb": [[0, 2.08, 263.29], [2, 2.02, 748.99]], "batl": [[0, 2.12, 1329.18]]}, {"timestamp": 1578772542965, "ltp": 2.1, "tv": 35108.51, "trd": NaN, "batb": [[1, 2.06, 30.14], [2, 2.04, 398.11]], "batl": [[0, 2.1, 8.64], [1, 2.12, 1314.36], [2, 2.14, 2678.14]]}, {"timestamp": 1578772544979, "ltp": 2.1, "tv": 35121.15, "trd": [[2.1, 1407.04]], "batb": NaN, "batl": [[0, 2.12, 1314.36], [1, 2.14, 2678.14], [2, 2.16, 689.81]]}, {"timestamp": 1578772545970, "ltp": 2.1, "tv": 35234.62, "trd": [[2.1, 1520.51]], "batb": NaN, "batl": [[0, 2.1, 307], [1, 2.12, 1314.36], [2, 2.14, 2634.29]]}, {"timestamp": 1578772546997, "ltp": 2.12, "tv": 35961.52, "trd": [[2.1, 1827.51], [2.12, 7266.99]], "batb": [[1, 2.06, 84.81]], "batl": [[0, 2.14, 2636], [1, 2.16, 691.51], [2, 2.18, 482.28]]}, {"timestamp": 1578772547985, "ltp": 2.12, "tv": 35963.52, "trd": [[2.12, 7268.99]], "batb": [[2, 2.04, 414.48]], "batl": [[0, 2.14, 966.11]]}, {"timestamp": 1578772548972, "ltp": 2.12, "tv": 35963.52, "trd": NaN, "batb": [[1, 2.06, 133.73]], "batl": [[1, 2.16, 700.75]]}, {"timestamp": 1578772549974, "ltp": 2.12, "tv": 35966.73, "trd": [[2.12, 7272.21]], "batb": [[2, 2.04, 558.24]], "batl": NaN}, {"timestamp": 1578772551005, "ltp": 2.1, "tv": 36004.11, "trd": [[2.1, 1864.88]], "batb": NaN, "batl": [[1, 2.16, 273.7]]}, {"timestamp": 1578772551989, "ltp": 2.1, "tv": 36103.3, "trd": [[2.1, 1964.07]], "batb": NaN, "batl": NaN}, {"timestamp": 1578772552975, "ltp": 2.1, "tv": 36103.3, "trd": NaN, "batb": [[1, 2.06, 135.6]], "batl": NaN}, {"timestamp": 1578772553955, "ltp": 2.1, "tv": 37170.73, "trd": [[2.08, 1170.96], [2.1, 2049.09]], "batb": [[0, 2.08, 10.15], [1, 2.06, 141.13]], "batl": NaN}, {"timestamp": 1578772554993, "ltp": 2.1, "tv": 37185.85, "trd": [[2.1, 2064.21]], "batb": [[0, 2.06, 525.31], [1, 2.04, 558.24], [2, 2.02, 691.11]], "batl": [[0, 2.12, 298], [1, 2.14, 966.11], [2, 2.16, 273.7]]}, {"timestamp": 1578772555974, "ltp": 2.1, "tv": 37185.85, "trd": NaN, "batb": [[0, 2.08, 46.29], [1, 2.06, 541.52], [2, 2.04, 558.24]], "batl": [[1, 2.14, 2488.94]]}, {"timestamp": 1578772556989, "ltp": 2.1, "tv": 37189.68, "trd": [[2.1, 2068.03]], "batb": NaN, "batl": NaN}, {"timestamp": 1578772557972, "ltp": 2.1, "tv": 37212.43, "trd": [[2.1, 2090.78]], "batb": NaN, "batl": NaN}, {"timestamp": 1578772559996, "ltp": 2.1, "tv": 37214.89, "trd": [[2.1, 2093.25]], "batb": NaN, "batl": NaN}, {"timestamp": 1578772561985, "ltp": 2.1, "tv": 37897.86, "trd": [[2.1, 2776.22]], "batb": NaN, "batl": [[0, 2.12, 1874.37]]}, {"timestamp": 1578772564003, "ltp": 2.08, "tv": 37899.7, "trd": [[2.08, 1172.8]], "batb": [[0, 2.08, 45.37]], "batl": [[0, 2.1, 2], [1, 2.12, 1874.37], [2, 2.14, 2488.94]]}, {"timestamp": 1578772564986, "ltp": 2.08, "tv": 37901.7, "trd": [[2.08, 1174.8]], "batb": [[0, 2.08, 44.37]], "batl": [[2, 2.14, 2067.48]]}, {"timestamp": 1578772566024, "ltp": 2.1, "tv": 37903.7, "trd": [[2.1, 2778.22]], "batb": NaN, "batl": [[0, 2.12, 1874.37], [1, 2.14, 2067.48], [2, 2.16, 288.17]]}, {"timestamp": 1578772567028, "ltp": 2.1, "tv": 37903.7, "trd": NaN, "batb": [[0, 2.08, 64.37]], "batl": [[0, 2.12, 298], [1, 2.14, 544.65]]}, {"timestamp": 1578772568995, "ltp": 2.1, "tv": 37903.7, "trd": NaN, "batb": NaN, "batl": [[0, 2.1, 1.8], [1, 2.12, 298], [2, 2.14, 544.65]]}, {"timestamp": 1578772571010, "ltp": 2.1, "tv": 37905.5, "trd": [[2.1, 2780.02]], "batb": NaN, "batl": [[0, 2.12, 299.87], [1, 2.14, 544.65], [2, 2.16, 288.17]]}, {"timestamp": 1578772571998, "ltp": 2.1, "tv": 37905.5, "trd": NaN, "batb": NaN, "batl": [[0, 2.12, 725.08]]}, {"timestamp": 1578772573030, "ltp": 2.1, "tv": 37905.5, "trd": NaN, "batb": NaN, "batl": [[0, 2.12, 731.14]]}, {"timestamp": 1578772574008, "ltp": 2.1, "tv": 37905.5, "trd": NaN, "batb": [[1, 2.06, 207.52]], "batl": NaN}, {"timestamp": 1578772575051, "ltp": 2.08, "tv": 38005.5, "trd": [[2.08, 1274.8]], "batb": [[0, 2.08, 14.37]], "batl": [[0, 2.12, 733], [1, 2.14, 2319.65], [2, 2.16, 1975.15]]}, {"timestamp": 1578772577014, "ltp": 2.08, "tv": 38029.68, "trd": [[2.08, 1298.98]], "batb": [[0, 2.08, 2.28]], "batl": NaN}, {"timestamp": 1578772580004, "ltp": 2.1, "tv": 38037.29, "trd": [[2.08, 1302.72], [2.1, 2783.89]], "batb": [[0, 2.06, 207.93], [1, 2.04, 558.24], [2, 2.02, 2320.26]], "batl": NaN}, {"timestamp": 1578772582029, "ltp": 2.1, "tv": 38037.29, "trd": NaN, "batb": NaN, "batl": [[0, 2.12, 1158.21]]}, {"timestamp": 1578772583002, "ltp": 2.1, "tv": 38037.29, "trd": NaN, "batb": [[0, 2.08, 10.41], [1, 2.06, 207.52], [2, 2.04, 558.24]], "batl": NaN}, {"timestamp": 1578772584033, "ltp": 2.1, "tv": 38037.29, "trd": NaN, "batb": NaN, "batl": [[0, 2.1, 1.87], [1, 2.12, 1158.21], [2, 2.14, 2319.65]]}, {"timestamp": 1578772585021, "ltp": 2.1, "tv": 38037.29, "trd": NaN, "batb": [[1, 2.06, 158.89]], "batl": [[1, 2.12, 1160.08]]}, {"timestamp": 1578772586004, "ltp": 2.08, "tv": 38047.7, "trd": [[2.08, 1313.13]], "batb": [[0, 2.06, 127.3], [1, 2.04, 558.24], [2, 2.02, 2320.26]], "batl": NaN}, {"timestamp": 1578772587046, "ltp": 2.08, "tv": 38047.7, "trd": NaN, "batb": NaN, "batl": [[0, 2.08, 4.26], [1, 2.1, 1.87], [2, 2.12, 1160.08]]}, {"timestamp": 1578772588029, "ltp": 2.08, "tv": 38047.7, "trd": NaN, "batb": NaN, "batl": [[2, 2.12, 734.87]]}, {"timestamp": 1578772590033, "ltp": 2.08, "tv": 38047.7, "trd": NaN, "batb": NaN, "batl": [[1, 2.1, 10.87]]}, {"timestamp": 1578772591011, "ltp": 2.08, "tv": 38047.7, "trd": NaN, "batb": [[0, 2.06, 97.16], [1, 2.04, 462.07]], "batl": [[1, 2.1, 336.87], [2, 2.12, 742.53]]}, {"timestamp": 1578772592053, "ltp": 2.08, "tv": 38051.95, "trd": [[2.08, 1317.38]], "batb": NaN, "batl": [[0, 2.1, 336.87], [1, 2.12, 742.53], [2, 2.14, 2319.65]]}, {"timestamp": 1578772593033, "ltp": 2.08, "tv": 38051.95, "trd": NaN, "batb": NaN, "batl": [[1, 2.12, 332.94]]}, {"timestamp": 1578772594023, "ltp": 2.08, "tv": 38051.95, "trd": NaN, "batb": NaN, "batl": [[1, 2.12, 347.93], [2, 2.14, 2334.12]]}, {"timestamp": 1578772595011, "ltp": 2.08, "tv": 38051.95, "trd": NaN, "batb": NaN, "batl": [[0, 2.1, 765.92]]}, {"timestamp": 1578772597028, "ltp": 2.08, "tv": 38056.59, "trd": [[2.08, 1322.02]], "batb": [[0, 2.08, 5.36], [1, 2.06, 97.16], [2, 2.04, 462.07]], "batl": NaN}, {"timestamp": 1578772599042, "ltp": 2.08, "tv": 38056.59, "trd": NaN, "batb": [[0, 2.08, 35.21]], "batl": NaN}, {"timestamp": 1578772600028, "ltp": 2.08, "tv": 38056.59, "trd": NaN, "batb": NaN, "batl": [[0, 2.1, 1194.97]]}, {"timestamp": 1578772602022, "ltp": 2.08, "tv": 38071.38, "trd": [[2.08, 1336.8]], "batb": [[0, 2.08, 27.82]], "batl": [[1, 2.12, 1839.15]]}, {"timestamp": 1578772602953, "ltp": 2.08, "tv": 38097.49, "trd": [[2.08, 1362.92]], "batb": [[0, 2.08, 14.76]], "batl": [[0, 2.1, 1193.1]]}, {"timestamp": 1578772604041, "ltp": 2.06, "tv": 38137.74, "trd": [[2.06, 10.98], [2.08, 1392.19]], "batb": [[0, 2.06, 91.67], [1, 2.04, 462.07], [2, 2.02, 2320.26]], "batl": NaN}, {"timestamp": 1578772605031, "ltp": 2.06, "tv": 38137.74, "trd": NaN, "batb": NaN, "batl": [[1, 2.12, 2965.02]]}, {"timestamp": 1578772605967, "ltp": 2.06, "tv": 38137.74, "trd": NaN, "batb": [[1, 2.04, 414.48]], "batl": NaN}, {"timestamp": 1578772606952, "ltp": 2.06, "tv": 38219.96, "trd": [[2.06, 93.2]], "batb": [[0, 2.06, 50.56], [1, 2.04, 398.11]], "batl": NaN}, {"timestamp": 1578772608041, "ltp": 2.06, "tv": 38219.96, "trd": NaN, "batb": [[1, 2.04, 382.07]], "batl": [[2, 2.14, 2303.77]]}, {"timestamp": 1578772609036, "ltp": 2.06, "tv": 38229.15, "trd": [[2.06, 102.38]], "batb": [[0, 2.06, 45.97]], "batl": [[0, 2.1, 867.1], [1, 2.12, 1541.15], [2, 2.14, 2011.77]]}, {"timestamp": 1578772609957, "ltp": 2.06, "tv": 38229.15, "trd": NaN, "batb": [[1, 2.04, 407.36]], "batl": [[1, 2.12, 49.93], [2, 2.14, 236.77]]}, {"timestamp": 1578772611053, "ltp": 2.08, "tv": 38249.15, "trd": [[2.08, 1412.19]], "batb": NaN, "batl": NaN}, {"timestamp": 1578772611983, "ltp": 2.08, "tv": 38249.15, "trd": NaN, "batb": NaN, "batl": [[2, 2.14, 222.3]]}, {"timestamp": 1578772612975, "ltp": 2.08, "tv": 38334.27, "trd": [[2.08, 1497.31]], "batb": NaN, "batl": [[1, 2.12, 48.06]]}, {"timestamp": 1578772613960, "ltp": 2.06, "tv": 38426.21, "trd": [[2.06, 194.32]], "batb": [[0, 2.04, 73.36], [1, 2.02, 2320.26], [2, 2, 2593.75]], "batl": [[0, 2.06, 4.45], [1, 2.1, 867.1], [2, 2.12, 48.06]]}, {"timestamp": 1578772615043, "ltp": 2.06, "tv": 38426.21, "trd": NaN, "batb": NaN, "batl": [[0, 2.08, 46.29], [1, 2.1, 944.45]]}, {"timestamp": 1578772616031, "ltp": 2.06, "tv": 38426.21, "trd": NaN, "batb": NaN, "batl": [[1, 2.1, 968.45]]}, {"timestamp": 1578772616964, "ltp": 2.06, "tv": 38426.21, "trd": NaN, "batb": NaN, "batl": [[0, 2.08, 56.29]]}, {"timestamp": 1578772618052, "ltp": 2.06, "tv": 38426.21, "trd": NaN, "batb": [[1, 2.02, 2159.11]], "batl": [[2, 2.12, 15.58]]}, {"timestamp": 1578772618979, "ltp": 2.06, "tv": 38426.21, "trd": NaN, "batb": NaN, "batl": [[2, 2.12, 30.05]]}, {"timestamp": 1578772619962, "ltp": 2.06, "tv": 38426.21, "trd": NaN, "batb": NaN, "batl": [[0, 2.08, 46.29]]}, {"timestamp": 1578772621007, "ltp": 2.06, "tv": 38426.21, "trd": NaN, "batb": NaN, "batl": [[2, 2.12, 271.51]]}, {"timestamp": 1578772622048, "ltp": 2.06, "tv": 38430.65, "trd": [[2.06, 198.76]], "batb": NaN, "batl": [[1, 2.1, 1138.69], [2, 2.12, 30.05]]}, {"timestamp": 1578772622982, "ltp": 2.06, "tv": 38430.65, "trd": NaN, "batb": [[0, 2.04, 403.36]], "batl": [[1, 2.1, 1432.69], [2, 2.12, 1755.11]]}, {"timestamp": 1578772623990, "ltp": 2.06, "tv": 38565.82, "trd": [[2.06, 333.94]], "batb": NaN, "batl": [[1, 2.1, 1003.64]]}, {"timestamp": 1578772624980, "ltp": 2.06, "tv": 38565.82, "trd": NaN, "batb": [[0, 2.06, 20], [1, 2.04, 403.36], [2, 2.02, 2159.11]], "batl": [[0, 2.08, 77.93], [1, 2.1, 574.59], [2, 2.12, 1749.05]]}, {"timestamp": 1578772625973, "ltp": 2.06, "tv": 38565.82, "trd": NaN, "batb": NaN, "batl": [[0, 2.08, 46.29], [1, 2.1, 1182.04]]}, {"timestamp": 1578772628005, "ltp": 2.06, "tv": 38569.04, "trd": [[2.06, 337.16]], "batb": [[0, 2.06, 16.78]], "batl": NaN}, {"timestamp": 1578772628997, "ltp": 2.06, "tv": 38602.6, "trd": [[2.06, 370.72]], "batb": [[0, 2.04, 403.36], [1, 2.02, 2159.11], [2, 2, 2593.75]], "batl": [[0, 2.06, 15.59], [1, 2.08, 78.66], [2, 2.1, 1422.79]]}, {"timestamp": 1578772629978, "ltp": 2.06, "tv": 38602.6, "trd": NaN, "batb": [[0, 2.04, 430.36]], "batl": NaN}, {"timestamp": 1578772632015, "ltp": 2.06, "tv": 38602.6, "trd": NaN, "batb": [[1, 2.02, 2174.95]], "batl": [[0, 2.06, 17.46], [1, 2.08, 84.72], [2, 2.1, 1486.64]]}, {"timestamp": 1578772633004, "ltp": 2.06, "tv": 38602.6, "trd": NaN, "batb": [[1, 2.02, 2223.49]], "batl": NaN}, {"timestamp": 1578772636004, "ltp": 2.04, "tv": 38622.6, "trd": [[2.04, 20]], "batb": [[0, 2.04, 437.3]], "batl": NaN}, {"timestamp": 1578772636993, "ltp": 2.04, "tv": 38622.6, "trd": NaN, "batb": NaN, "batl": [[0, 2.06, 19.16]]}, {"timestamp": 1578772637993, "ltp": 2.04, "tv": 38625.5, "trd": [[2.04, 22.9]], "batb": [[0, 2.04, 485.85]], "batl": NaN}, {"timestamp": 1578772638985, "ltp": 2.06, "tv": 38728.64, "trd": [[2.04, 106.88], [2.06, 389.88]], "batb": [[0, 2.04, 443.86]], "batl": [[0, 2.08, 950.74], [1, 2.1, 1486.64], [2, 2.12, 1749.05]]}, {"timestamp": 1578772639970, "ltp": 2.06, "tv": 38754.43, "trd": [[2.06, 415.67]], "batb": NaN, "batl": NaN}, {"timestamp": 1578772642000, "ltp": 2.06, "tv": 38754.43, "trd": NaN, "batb": NaN, "batl": [[1, 2.1, 1192.64]]}, {"timestamp": 1578772642998, "ltp": 2.06, "tv": 38756.58, "trd": [[2.06, 417.82]], "batb": NaN, "batl": [[0, 2.06, 6.85], [1, 2.08, 950.74], [2, 2.1, 1192.64]]}, {"timestamp": 1578772645023, "ltp": 2.06, "tv": 38756.58, "trd": NaN, "batb": [[1, 2.02, 2174.95]], "batl": NaN}, {"timestamp": 1578772646995, "ltp": 2.06, "tv": 38810.59, "trd": [[2.06, 471.83]], "batb": [[0, 2.04, 459.6], [1, 2.02, 2159.11]], "batl": [[0, 2.08, 950.74], [1, 2.1, 320.44], [2, 2.12, 1749.05]]}, {"timestamp": 1578772649011, "ltp": 2.06, "tv": 38810.59, "trd": NaN, "batb": NaN, "batl": [[1, 2.1, 311.44]]}, {"timestamp": 1578772650004, "ltp": 2.06, "tv": 38810.59, "trd": NaN, "batb": NaN, "batl": [[0, 2.08, 1014.59]]}, {"timestamp": 1578772650988, "ltp": 2.04, "tv": 38861.2, "trd": [[2.04, 157.48]], "batb": [[0, 2.04, 434.3], [1, 2.02, 445.96]], "batl": NaN}, {"timestamp": 1578772653017, "ltp": 2.04, "tv": 38866.51, "trd": [[2.04, 162.8]], "batb": [[0, 2.04, 431.64]], "batl": [[0, 2.08, 1079.34], [1, 2.1, 603.44]]}, {"timestamp": 1578772654003, "ltp": 2.04, "tv": 38866.51, "trd": NaN, "batb": NaN, "batl": [[0, 2.08, 1266.3]]}, {"timestamp": 1578772655001, "ltp": 2.04, "tv": 38866.51, "trd": NaN, "batb": NaN, "batl": [[0, 2.08, 1202.45]]}, {"timestamp": 1578772655988, "ltp": 2.04, "tv": 38866.51, "trd": NaN, "batb": [[0, 2.06, 50], [1, 2.04, 479.71], [2, 2.02, 609.8]], "batl": [[0, 2.08, 975.83]]}, {"timestamp": 1578772657034, "ltp": 2.08, "tv": 38883.31, "trd": [[2.08, 1514.11]], "batb": NaN, "batl": [[0, 2.08, 951.36]]}, {"timestamp": 1578772658023, "ltp": 2.06, "tv": 38928.09, "trd": [[2.06, 516.61]], "batb": [[0, 2.06, 27.61]], "batl": [[0, 2.08, 936.28], [2, 2.12, 322.99]]}, {"timestamp": 1578772663009, "ltp": 2.06, "tv": 38940.21, "trd": [[2.06, 528.72]], "batb": [[0, 2.06, 21.55], [1, 2.04, 629.71]], "batl": [[2, 2.12, 315.34]]}, {"timestamp": 1578772664014, "ltp": 2.06, "tv": 38940.21, "trd": NaN, "batb": [[1, 2.04, 307.75]], "batl": NaN}, {"timestamp": 1578772666033, "ltp": 2.06, "tv": 38944.8, "trd": [[2.06, 533.32]], "batb": [[0, 2.06, 19.25]], "batl": NaN}, {"timestamp": 1578772667016, "ltp": 2.06, "tv": 38952.46, "trd": [[2.06, 540.98]], "batb": [[0, 2.06, 15.42]], "batl": NaN}, {"timestamp": 1578772668012, "ltp": 2.06, "tv": 38959.38, "trd": [[2.06, 547.9]], "batb": [[0, 2.06, 11.96]], "batl": NaN}, {"timestamp": 1578772671017, "ltp": 2.06, "tv": 38967.04, "trd": [[2.06, 555.55]], "batb": [[0, 2.06, 8.13]], "batl": NaN}, {"timestamp": 1578772673046, "ltp": 2.06, "tv": 38985.06, "trd": [[2.06, 573.57]], "batb": [[0, 2.04, 330.75], [1, 2.02, 609.8], [2, 2, 2593.75]], "batl": [[0, 2.06, 25.61], [1, 2.08, 936.28], [2, 2.1, 539.59]]}, {"timestamp": 1578772674034, "ltp": 2.06, "tv": 38985.06, "trd": NaN, "batb": NaN, "batl": [[0, 2.06, 153.29]]}, {"timestamp": 1578772675021, "ltp": 2.06, "tv": 38985.06, "trd": NaN, "batb": [[1, 2.02, 545.07]], "batl": NaN}, {"timestamp": 1578772675953, "ltp": 2.06, "tv": 38985.06, "trd": NaN, "batb": [[1, 2.02, 445.96]], "batl": NaN}, {"timestamp": 1578772677048, "ltp": 2.06, "tv": 38985.06, "trd": NaN, "batb": NaN, "batl": [[1, 2.08, 903.91]]}, {"timestamp": 1578772678041, "ltp": 2.06, "tv": 38985.06, "trd": NaN, "batb": [[2, 2, 810.93]], "batl": NaN}, {"timestamp": 1578772679028, "ltp": 2.06, "tv": 39008.81, "trd": [[2.04, 184.23], [2.06, 575.89]], "batb": [[0, 2.04, 320.04]], "batl": [[0, 2.06, 150.97]]}, {"timestamp": 1578772680055, "ltp": 2.06, "tv": 39008.81, "trd": NaN, "batb": NaN, "batl": [[0, 2.06, 23.29]]}, {"timestamp": 1578772681049, "ltp": 2.06, "tv": 39008.81, "trd": NaN, "batb": [[0, 2.04, 665.04]], "batl": NaN}, {"timestamp": 1578772682052, "ltp": 2.06, "tv": 39008.81, "trd": NaN, "batb": NaN, "batl": [[0, 2.06, 26.25], [1, 2.08, 984.25]]}, {"timestamp": 1578772683042, "ltp": 2.08, "tv": 39876.38, "trd": [[2.06, 628.39], [2.08, 2329.19]], "batb": NaN, "batl": [[0, 2.08, 621.12], [1, 2.1, 539.59], [2, 2.12, 315.34]]}, {"timestamp": 1578772684030, "ltp": 2.08, "tv": 39876.38, "trd": NaN, "batb": NaN, "batl": [[0, 2.08, 449.24]]}, {"timestamp": 1578772685048, "ltp": 2.04, "tv": 39880.7, "trd": [[2.04, 188.55]], "batb": [[0, 2.04, 662.88]], "batl": NaN}, {"timestamp": 1578772686033, "ltp": 2.04, "tv": 39880.7, "trd": NaN, "batb": [[0, 2.06, 50], [1, 2.04, 662.88], [2, 2.02, 445.96]], "batl": NaN}, {"timestamp": 1578772687020, "ltp": 2.04, "tv": 39880.7, "trd": NaN, "batb": NaN, "batl": [[0, 2.08, 433.01]]}, {"timestamp": 1578772687956, "ltp": 2.04, "tv": 40136.06, "trd": [[2.04, 343.91], [2.06, 728.39]], "batb": [[0, 2.04, 585.2], [1, 2.02, 445.96], [2, 2, 810.93]], "batl": [[0, 2.06, 47.16], [1, 2.08, 433.01], [2, 2.1, 539.59]]}, {"timestamp": 1578772689043, "ltp": 2.04, "tv": 40136.06, "trd": NaN, "batb": NaN, "batl": [[0, 2.08, 433.01], [1, 2.1, 539.59], [2, 2.12, 315.34]]}, {"timestamp": 1578772690031, "ltp": 2.04, "tv": 40136.06, "trd": NaN, "batb": [[2, 2, 1275.06]], "batl": NaN}, {"timestamp": 1578772693030, "ltp": 2.04, "tv": 40173.52, "trd": [[2.04, 381.36]], "batb": [[0, 2.04, 566.47]], "batl": [[2, 2.12, 300.87]]}, {"timestamp": 1578772694955, "ltp": 2.08, "tv": 40174.03, "trd": [[2.08, 2329.71]], "batb": [[2, 2, 1277.35]], "batl": [[0, 2.08, 432.75]]}, {"timestamp": 1578772696040, "ltp": 2.08, "tv": 40174.03, "trd": NaN, "batb": NaN, "batl": [[0, 2.08, 636.43]]}, {"timestamp": 1578772697972, "ltp": 2.08, "tv": 40174.03, "trd": NaN, "batb": NaN, "batl": [[0, 2.08, 620.69], [2, 2.12, 726.08]]}, {"timestamp": 1578772698963, "ltp": 2.08, "tv": 40174.03, "trd": NaN, "batb": [[1, 2.02, 455.96]], "batl": NaN}, {"timestamp": 1578772699977, "ltp": 2.06, "tv": 40175.9, "trd": [[2.06, 730.25]], "batb": NaN, "batl": [[1, 2.1, 554.91]]}, {"timestamp": 1578772700968, "ltp": 2.06, "tv": 40772.5, "trd": [[2.04, 966.56], [2.06, 741.65]], "batb": [[0, 2.02, 455.96]