{"info": {"id": "1.166703737", "eventId": "29632571", "eventName": "Over/Under 5.5 Goals", "marketType": "OVER_UNDER_55", "openDate": 1578772101023, "name": "Inter v Atalanta", "numberOfActiveRunner": 2, "countryCode": "", "sport": "TENNIS", "venue": "", "volume": {"total": 191351.24, "preMatch": 9925.36, "inPlay": 181425.88}, "winner": {"id": 1485567, "name": "Under 5.5 Goals", "status": "WINNER", "position": 1}, "delay": 7}, "runners": [{"id": 1485567, "name": "Under 5.5 Goals", "status": "WINNER", "position": 1, "inPlayOdds": 1.07, "inPlayTime": 1578772101023, "avgPrematch": 1.08, "closedOdds": 1.01, "maxPrematch": 1.09, "minPrematch": 1.07, "maxInPlay": 1.17, "minInPlay": 1.01, "inPlayIndex": 197, "lengthOdds": 1383, "lengthOddsPrematch": 197, "lengthOddsInPlay": 1186, "tradedVolume": 187041.24, "preMatchVolume": 9299.95, "inPlayVolume": 177741.29}, {"id": 1485568, "name": "Over 5.5 Goals", "status": "LOSER", "position": 2, "inPlayOdds": 15.0, "inPlayTime": 1578772101023, "avgPrematch": 13.2, "closedOdds": 1000.0, "maxPrematch": 15.5, "minPrematch": 12.0, "maxInPlay": 1000.0, "minInPlay": 6.6, "inPlayIndex": 251, "lengthOdds": 1494, "lengthOddsPrematch": 251, "lengthOddsInPlay": 1243, "tradedVolume": 4310.0, "preMatchVolume": 625.41, "inPlayVolume": 3684.59}], "marketUpdates": [{"timestamp": 1578513294362000000, "openDate": "2020-01-11T19:45:00.000Z", "status": "OPEN", "betDelay": 0, "inPlay": false, "complete": true}, {"timestamp": 1578772101023000000, "openDate": "2020-01-11T19:45:00.000Z", "status": "OPEN", "betDelay": 7, "inPlay": true, "complete": true}, {"timestamp": 1578772294860000000, "openDate": "2020-01-11T19:45:00.000Z", "status": "SUSPENDED", "betDelay": 7, "inPlay": true, "complete": true}, {"timestamp": 1578772347979000000, "openDate": "2020-01-11T19:45:00.000Z", "status": "OPEN", "betDelay": 7, "inPlay": true, "complete": true}, {"timestamp": 1578774525024000000, "openDate": "2020-01-11T19:45:00.000Z", "status": "SUSPENDED", "betDelay": 7, "inPlay": true, "complete": true}, {"timestamp": 1578774556973000000, "openDate": "2020-01-11T19:45:00.000Z", "status": "OPEN", "betDelay": 7, "inPlay": true, "complete": true}, {"timestamp": 1578774580039000000, "openDate": "2020-01-11T19:45:00.000Z", "status": "SUSPENDED", "betDelay": 7, "inPlay": true, "complete": true}, {"timestamp": 1578774582036000000, "openDate": "2020-01-11T19:45:00.000Z", "status": "OPEN", "betDelay": 7, "inPlay": true, "complete": true}, {"timestamp": 1578774866982000000, "openDate": "2020-01-11T19:45:00.000Z", "status": "OPEN", "betDelay": 1, "inPlay": true, "complete": true}, {"timestamp": 1578775780035000000, "openDate": "2020-01-11T19:45:00.000Z", "status": "OPEN", "betDelay": 7, "inPlay": true, "complete": true}, {"timestamp": 1578777631947000000, "openDate": "2020-01-11T19:45:00.000Z", "status": "SUSPENDED", "betDelay": 7, "inPlay": true, "complete": true}, {"timestamp": 1578777690042000000, "openDate": "2020-01-11T19:45:00.000Z", "status": "OPEN", "betDelay": 7, "inPlay": true, "complete": true}, {"timestamp": 1578778337987000000, "openDate": "2020-01-11T19:45:00.000Z", "status": "SUSPENDED", "betDelay": 7, "inPlay": true, "complete": true}, {"timestamp": 1578778432037000000, "openDate": "2020-01-11T19:45:00.000Z", "status": "OPEN", "betDelay": 7, "inPlay": true, "complete": true}, {"timestamp": 1578778774964000000, "openDate": "2020-01-11T19:45:00.000Z", "status": "SUSPENDED", "betDelay": 7, "inPlay": true, "complete": true}, {"timestamp": 1578778868827000000, "openDate": "2020-01-11T19:45:00.000Z", "status": "CLOSED", "betDelay": 7, "inPlay": true, "complete": true}], "odds": [{"runnerId": 1485567, "odds": [{"timestamp": 1578735999607, "ltp": 1.09, "tv": 34.0, "trd": [[1.09, 34]], "batb": NaN, "batl": NaN}, {"timestamp": 1578736031946, "ltp": 1.09, "tv": 34.0, "trd": NaN, "batb": NaN, "batl": [[1, 1.11, 7.66], [2, 1.12, 0]]}, {"timestamp": 1578736886586, "ltp": 1.09, "tv": 34.0, "trd": NaN, "batb": NaN, "batl": [[1, 1.11, 304.16], [2, 1.12, 249.96]]}, {"timestamp": 1578736902880, "ltp": 1.09, "tv": 34.0, "trd": NaN, "batb": NaN, "batl": [[1, 1.11, 7.66], [2, 1.12, 0]]}, {"timestamp": 1578738647821, "ltp": 1.09, "tv": 34.0, "trd": NaN, "batb": NaN, "batl": [[1, 1.11, 280.16], [2, 1.12, 233.46]]}, {"timestamp": 1578738702991, "ltp": 1.09, "tv": 34.0, "trd": NaN, "batb": NaN, "batl": [[1, 1.11, 7.66], [2, 1.12, 0]]}, {"timestamp": 1578739531043, "ltp": 1.09, "tv": 34.0, "trd": NaN, "batb": NaN, "batl": [[1, 1.11, 259.16], [2, 1.12, 245.71]]}, {"timestamp": 1578739600045, "ltp": 1.09, "tv": 34.0, "trd": NaN, "batb": NaN, "batl": [[1, 1.11, 7.66], [2, 1.12, 0]]}, {"timestamp": 1578740486022, "ltp": 1.09, "tv": 34.0, "trd": NaN, "batb": NaN, "batl": [[1, 1.11, 304.16], [2, 1.12, 273.21]]}, {"timestamp": 1578740501797, "ltp": 1.09, "tv": 34.0, "trd": NaN, "batb": NaN, "batl": [[1, 1.11, 7.66], [2, 1.12, 0]]}, {"timestamp": 1578746731958, "ltp": 1.09, "tv": 34.0, "trd": NaN, "batb": [[2, 1.06, 3156.48]], "batl": NaN}, {"timestamp": 1578755919841, "ltp": 1.09, "tv": 34.0, "trd": NaN, "batb": NaN, "batl": [[0, 1.1, 371.01], [1, 1.11, 256.16]]}, {"timestamp": 1578758009457, "ltp": 1.09, "tv": 52.68, "trd": [[1.09, 52.69]], "batb": NaN, "batl": NaN}, {"timestamp": 1578759834890, "ltp": 1.09, "tv": 52.68, "trd": NaN, "batb": [[1, 1.07, 2303.49]], "batl": [[2, 1.12, 12.66]]}, {"timestamp": 1578760417024, "ltp": 1.09, "tv": 52.68, "trd": NaN, "batb": [[0, 1.07, 2303.49], [1, 1.06, 3156.48], [2, 1.05, 3945.49]], "batl": NaN}, {"timestamp": 1578760425710, "ltp": 1.09, "tv": 52.68, "trd": NaN, "batb": NaN, "batl": [[0, 1.1, 1136.59]]}, {"timestamp": 1578760515955, "ltp": 1.09, "tv": 52.68, "trd": NaN, "batb": [[0, 1.07, 2296.74]], "batl": NaN}, {"timestamp": 1578760516923, "ltp": 1.09, "tv": 52.68, "trd": NaN, "batb": [[1, 1.06, 3169.09]], "batl": [[2, 1.12, 0]]}, {"timestamp": 1578760518046, "ltp": 1.09, "tv": 52.68, "trd": NaN, "batb": NaN, "batl": [[2, 1.12, 12.61]]}, {"timestamp": 1578760556665, "ltp": 1.09, "tv": 52.68, "trd": NaN, "batb": NaN, "batl": [[0, 1.09, 50], [1, 1.1, 1136.59], [2, 1.11, 256.16]]}, {"timestamp": 1578760558940, "ltp": 1.09, "tv": 52.68, "trd": NaN, "batb": NaN, "batl": [[1, 1.1, 1186.59]]}, {"timestamp": 1578760559752, "ltp": 1.09, "tv": 52.68, "trd": NaN, "batb": NaN, "batl": [[2, 1.11, 306.16]]}, {"timestamp": 1578762217859, "ltp": 1.09, "tv": 52.68, "trd": NaN, "batb": NaN, "batl": [[0, 1.09, 65.31]]}, {"timestamp": 1578762455974, "ltp": 1.09, "tv": 52.68, "trd": NaN, "batb": NaN, "batl": [[0, 1.09, 69.14]]}, {"timestamp": 1578762958898, "ltp": 1.09, "tv": 62.02, "trd": [[1.09, 62.03]], "batb": NaN, "batl": [[0, 1.09, 64.47]]}, {"timestamp": 1578763069027, "ltp": 1.09, "tv": 62.02, "trd": NaN, "batb": [[1, 1.06, 3156.48]], "batl": NaN}, {"timestamp": 1578763070043, "ltp": 1.09, "tv": 62.02, "trd": NaN, "batb": [[1, 1.06, 3169.46]], "batl": NaN}, {"timestamp": 1578763608888, "ltp": 1.09, "tv": 62.02, "trd": NaN, "batb": [[0, 1.07, 2298.44]], "batl": NaN}, {"timestamp": 1578763614821, "ltp": 1.09, "tv": 62.02, "trd": NaN, "batb": [[0, 1.07, 2298.48]], "batl": NaN}, {"timestamp": 1578763655258, "ltp": 1.09, "tv": 62.02, "trd": NaN, "batb": [[0, 1.07, 2296.77]], "batl": NaN}, {"timestamp": 1578763765868, "ltp": 1.09, "tv": 62.02, "trd": NaN, "batb": [[0, 1.07, 2300.6]], "batl": NaN}, {"timestamp": 1578764328052, "ltp": 1.09, "tv": 62.02, "trd": NaN, "batb": [[0, 1.07, 1535.02], [1, 1.06, 2403.88]], "batl": NaN}, {"timestamp": 1578764977978, "ltp": 1.09, "tv": 62.02, "trd": NaN, "batb": [[0, 1.07, 3237.44]], "batl": NaN}, {"timestamp": 1578764982769, "ltp": 1.09, "tv": 62.02, "trd": NaN, "batb": [[1, 1.06, 4106.3]], "batl": NaN}, {"timestamp": 1578765970033, "ltp": 1.09, "tv": 62.02, "trd": NaN, "batb": NaN, "batl": [[0, 1.09, 392.46], [1, 1.1, 1511.59], [2, 1.11, 628.24]]}, {"timestamp": 1578765972005, "ltp": 1.09, "tv": 62.02, "trd": NaN, "batb": [[0, 1.07, 3542.78], [1, 1.06, 4414.53], [2, 1.05, 4250.04]], "batl": NaN}, {"timestamp": 1578766239896, "ltp": 1.09, "tv": 62.02, "trd": NaN, "batb": [[1, 1.06, 4454.34], [2, 1.05, 4294.44]], "batl": NaN}, {"timestamp": 1578766575903, "ltp": 1.09, "tv": 62.02, "trd": NaN, "batb": [[0, 1.08, 312.17], [1, 1.07, 3542.78], [2, 1.06, 4454.34]], "batl": NaN}, {"timestamp": 1578766580930, "ltp": 1.09, "tv": 62.02, "trd": NaN, "batb": [[0, 1.07, 3542.78], [1, 1.06, 4454.34], [2, 1.05, 4294.44]], "batl": NaN}, {"timestamp": 1578766600042, "ltp": 1.09, "tv": 62.02, "trd": NaN, "batb": NaN, "batl": [[0, 1.09, 507.55]]}, {"timestamp": 1578767122763, "ltp": 1.09, "tv": 62.02, "trd": NaN, "batb": [[0, 1.07, 13750.26]], "batl": NaN}, {"timestamp": 1578767294759, "ltp": 1.09, "tv": 62.02, "trd": NaN, "batb": [[1, 1.06, 4454.39]], "batl": NaN}, {"timestamp": 1578767580971, "ltp": 1.09, "tv": 66.02, "trd": [[1.09, 66.03]], "batb": NaN, "batl": [[0, 1.09, 505.55]]}, {"timestamp": 1578767635043, "ltp": 1.08, "tv": 72.73, "trd": [[1.08, 6.71]], "batb": NaN, "batl": NaN}, {"timestamp": 1578767768027, "ltp": 1.08, "tv": 72.73, "trd": NaN, "batb": [[0, 1.08, 318.61], [1, 1.07, 13750.26], [2, 1.06, 4454.39]], "batl": NaN}, {"timestamp": 1578767773802, "ltp": 1.09, "tv": 76.02, "trd": [[1.09, 69.32]], "batb": NaN, "batl": [[0, 1.09, 502.26]]}, {"timestamp": 1578767808462, "ltp": 1.09, "tv": 131.07, "trd": [[1.09, 124.37]], "batb": NaN, "batl": [[0, 1.09, 447.22]]}, {"timestamp": 1578768174501, "ltp": 1.09, "tv": 131.07, "trd": NaN, "batb": [[2, 1.06, 5220.48]], "batl": NaN}, {"timestamp": 1578768175773, "ltp": 1.09, "tv": 131.07, "trd": NaN, "batb": [[1, 1.07, 14516.34]], "batl": NaN}, {"timestamp": 1578768205015, "ltp": 1.09, "tv": 131.07, "trd": NaN, "batb": [[1, 1.07, 13750.26]], "batl": NaN}, {"timestamp": 1578768313416, "ltp": 1.09, "tv": 131.07, "trd": NaN, "batb": [[2, 1.06, 5207.45]], "batl": NaN}, {"timestamp": 1578768831004, "ltp": 1.09, "tv": 231.07, "trd": [[1.09, 224.36]], "batb": NaN, "batl": [[0, 1.09, 397.22]]}, {"timestamp": 1578768930684, "ltp": 1.08, "tv": 251.5, "trd": [[1.08, 27.14]], "batb": [[0, 1.08, 308.39]], "batl": NaN}, {"timestamp": 1578769089886, "ltp": 1.08, "tv": 251.5, "trd": NaN, "batb": NaN, "batl": [[0, 1.09, 1162.8]]}, {"timestamp": 1578769090982, "ltp": 1.08, "tv": 251.5, "trd": NaN, "batb": [[0, 1.07, 13750.26], [1, 1.06, 5207.45], [2, 1.05, 5060.53]], "batl": NaN}, {"timestamp": 1578769108013, "ltp": 1.08, "tv": 251.5, "trd": NaN, "batb": NaN, "batl": [[1, 1.1, 1894.38]]}, {"timestamp": 1578769351973, "ltp": 1.08, "tv": 251.49, "trd": [[1.09, 224.35]], "batb": [[0, 1.07, 13746.66], [1, 1.06, 5206.71], [2, 1.05, 5060.22]], "batl": [[0, 1.09, 1162.53], [1, 1.1, 1894.03], [2, 1.11, 628.23]]}, {"timestamp": 1578769439701, "ltp": 1.08, "tv": 251.49, "trd": NaN, "batb": [[0, 1.08, 50], [1, 1.07, 13746.66], [2, 1.06, 5206.71]], "batl": NaN}, {"timestamp": 1578769870022, "ltp": 1.08, "tv": 269.94, "trd": [[1.08, 45.6]], "batb": [[0, 1.08, 40.77]], "batl": NaN}, {"timestamp": 1578770058821, "ltp": 1.09, "tv": 273.94, "trd": [[1.09, 228.35]], "batb": NaN, "batl": [[0, 1.09, 1160.53]]}, {"timestamp": 1578770066055, "ltp": 1.08, "tv": 293.94, "trd": [[1.08, 65.6]], "batb": [[0, 1.08, 30.77]], "batl": NaN}, {"timestamp": 1578770088752, "ltp": 1.09, "tv": 294.93, "trd": [[1.09, 229.34]], "batb": NaN, "batl": [[0, 1.09, 1159.54]]}, {"timestamp": 1578770193998, "ltp": 1.09, "tv": 294.93, "trd": NaN, "batb": [[0, 1.08, 604.78]], "batl": NaN}, {"timestamp": 1578770194914, "ltp": 1.09, "tv": 294.93, "trd": NaN, "batb": [[0, 1.08, 935.81]], "batl": NaN}, {"timestamp": 1578770274701, "ltp": 1.09, "tv": 294.93, "trd": NaN, "batb": [[1, 1.07, 14328.32]], "batl": NaN}, {"timestamp": 1578770281894, "ltp": 1.09, "tv": 294.93, "trd": NaN, "batb": [[0, 1.08, 1881.59]], "batl": NaN}, {"timestamp": 1578770301832, "ltp": 1.09, "tv": 1442.95, "trd": [[1.09, 1377.36]], "batb": [[0, 1.08, 1307.58]], "batl": [[0, 1.09, 585.53]]}, {"timestamp": 1578770302942, "ltp": 1.09, "tv": 1442.95, "trd": NaN, "batb": NaN, "batl": [[0, 1.09, 890.59]]}, {"timestamp": 1578770304925, "ltp": 1.09, "tv": 1442.95, "trd": NaN, "batb": [[0, 1.08, 1402.58]], "batl": NaN}, {"timestamp": 1578770319981, "ltp": 1.09, "tv": 1442.95, "trd": NaN, "batb": [[0, 1.08, 1434.29]], "batl": [[0, 1.09, 922.3]]}, {"timestamp": 1578770341967, "ltp": 1.09, "tv": 1442.95, "trd": NaN, "batb": [[0, 1.08, 488.5]], "batl": NaN}, {"timestamp": 1578770368999, "ltp": 1.08, "tv": 1485.93, "trd": [[1.08, 108.58]], "batb": [[0, 1.08, 467.01]], "batl": NaN}, {"timestamp": 1578770374021, "ltp": 1.08, "tv": 1485.93, "trd": NaN, "batb": [[0, 1.08, 646.1]], "batl": NaN}, {"timestamp": 1578770420986, "ltp": 1.08, "tv": 1577.77, "trd": [[1.08, 200.41]], "batb": [[0, 1.08, 600.19]], "batl": NaN}, {"timestamp": 1578770483950, "ltp": 1.09, "tv": 1577.87, "trd": [[1.09, 1377.46]], "batb": NaN, "batl": [[0, 1.09, 922.24]]}, {"timestamp": 1578770587048, "ltp": 1.09, "tv": 1577.87, "trd": NaN, "batb": NaN, "batl": [[0, 1.09, 336.76]]}, {"timestamp": 1578770671040, "ltp": 1.09, "tv": 1587.09, "trd": [[1.09, 1386.68]], "batb": NaN, "batl": [[0, 1.09, 332.15]]}, {"timestamp": 1578770677921, "ltp": 1.09, "tv": 1587.09, "trd": NaN, "batb": NaN, "batl": [[0, 1.09, 410.67]]}, {"timestamp": 1578770700004, "ltp": 1.09, "tv": 1946.82, "trd": [[1.09, 1746.41]], "batb": NaN, "batl": [[0, 1.09, 230.81]]}, {"timestamp": 1578770701008, "ltp": 1.09, "tv": 1946.82, "trd": NaN, "batb": [[1, 1.07, 14341.23]], "batl": NaN}, {"timestamp": 1578770702021, "ltp": 1.09, "tv": 1946.82, "trd": NaN, "batb": [[1, 1.07, 14340.91]], "batl": NaN}, {"timestamp": 1578770706016, "ltp": 1.09, "tv": 1946.82, "trd": NaN, "batb": [[0, 1.08, 421.09]], "batl": NaN}, {"timestamp": 1578770713000, "ltp": 1.09, "tv": 1952.18, "trd": [[1.09, 1751.77]], "batb": NaN, "batl": [[0, 1.09, 228.13]]}, {"timestamp": 1578770722032, "ltp": 1.08, "tv": 2139.04, "trd": [[1.08, 387.27]], "batb": [[0, 1.08, 327.67], [1, 1.07, 14346.74]], "batl": NaN}, {"timestamp": 1578770726935, "ltp": 1.08, "tv": 2139.04, "trd": NaN, "batb": [[0, 1.08, 377.67]], "batl": NaN}, {"timestamp": 1578770731005, "ltp": 1.08, "tv": 2139.04, "trd": NaN, "batb": [[1, 1.07, 14338.32]], "batl": NaN}, {"timestamp": 1578770749957, "ltp": 1.08, "tv": 2325.89, "trd": [[1.08, 574.13]], "batb": [[0, 1.08, 284.24]], "batl": NaN}, {"timestamp": 1578770751047, "ltp": 1.08, "tv": 2325.89, "trd": NaN, "batb": [[1, 1.07, 14341.4]], "batl": NaN}, {"timestamp": 1578770752999, "ltp": 1.08, "tv": 2325.89, "trd": NaN, "batb": [[1, 1.07, 14338.32]], "batl": NaN}, {"timestamp": 1578770773963, "ltp": 1.08, "tv": 2325.89, "trd": NaN, "batb": [[0, 1.08, 234.24]], "batl": NaN}, {"timestamp": 1578770789984, "ltp": 1.08, "tv": 2325.89, "trd": NaN, "batb": [[0, 1.08, 267.91]], "batl": NaN}, {"timestamp": 1578770800993, "ltp": 1.08, "tv": 2699.62, "trd": [[1.08, 947.85]], "batb": [[0, 1.08, 412.08], [1, 1.07, 14341.4]], "batl": NaN}, {"timestamp": 1578770820898, "ltp": 1.09, "tv": 2721.64, "trd": [[1.09, 1773.79]], "batb": NaN, "batl": [[0, 1.09, 206.1]]}, {"timestamp": 1578770832019, "ltp": 1.09, "tv": 2721.64, "trd": NaN, "batb": [[1, 1.07, 14338.32]], "batl": NaN}, {"timestamp": 1578770841033, "ltp": 1.08, "tv": 2726.22, "trd": [[1.08, 952.43]], "batb": [[0, 1.08, 409.79]], "batl": NaN}, {"timestamp": 1578770866953, "ltp": 1.08, "tv": 2726.22, "trd": NaN, "batb": [[0, 1.08, 396.41]], "batl": NaN}, {"timestamp": 1578770903005, "ltp": 1.08, "tv": 2726.22, "trd": NaN, "batb": [[0, 1.08, 406.41]], "batl": NaN}, {"timestamp": 1578770942954, "ltp": 1.08, "tv": 2729.62, "trd": [[1.08, 955.84]], "batb": [[0, 1.08, 404.7]], "batl": NaN}, {"timestamp": 1578770965987, "ltp": 1.08, "tv": 2729.62, "trd": NaN, "batb": [[0, 1.08, 406.41]], "batl": NaN}, {"timestamp": 1578771013973, "ltp": 1.08, "tv": 2729.62, "trd": NaN, "batb": [[2, 1.06, 5395.71]], "batl": [[1, 1.1, 2076.03], [2, 1.11, 808.23]]}, {"timestamp": 1578771015040, "ltp": 1.08, "tv": 2729.62, "trd": NaN, "batb": [[1, 1.07, 14525.32]], "batl": NaN}, {"timestamp": 1578771037054, "ltp": 1.09, "tv": 2764.22, "trd": [[1.09, 1808.39]], "batb": NaN, "batl": [[0, 1.09, 188.81]]}, {"timestamp": 1578771046979, "ltp": 1.08, "tv": 3164.21, "trd": [[1.08, 1355.83]], "batb": [[0, 1.08, 206.41], [1, 1.07, 14530.53]], "batl": NaN}, {"timestamp": 1578771050051, "ltp": 1.08, "tv": 3164.21, "trd": NaN, "batb": NaN, "batl": [[0, 1.09, 188.52]]}, {"timestamp": 1578771051965, "ltp": 1.08, "tv": 3250.75, "trd": [[1.08, 1442.36]], "batb": [[0, 1.08, 163.14], [1, 1.07, 14533.56]], "batl": NaN}, {"timestamp": 1578771068004, "ltp": 1.08, "tv": 3250.75, "trd": NaN, "batb": [[1, 1.07, 14532.35]], "batl": NaN}, {"timestamp": 1578771078005, "ltp": 1.08, "tv": 3250.75, "trd": NaN, "batb": [[1, 1.07, 14525.32]], "batl": NaN}, {"timestamp": 1578771149959, "ltp": 1.08, "tv": 3250.75, "trd": NaN, "batb": [[1, 1.07, 14338.32]], "batl": NaN}, {"timestamp": 1578771200962, "ltp": 1.09, "tv": 3345.54, "trd": [[1.09, 1903.18]], "batb": NaN, "batl": [[0, 1.09, 93.73]]}, {"timestamp": 1578771201972, "ltp": 1.09, "tv": 3345.54, "trd": NaN, "batb": NaN, "batl": [[0, 1.09, 506.84]]}, {"timestamp": 1578771205050, "ltp": 1.09, "tv": 3345.54, "trd": NaN, "batb": NaN, "batl": [[0, 1.09, 491.63]]}, {"timestamp": 1578771208964, "ltp": 1.08, "tv": 6025.72, "trd": [[1.08, 4122.54]], "batb": [[0, 1.07, 14378.32], [1, 1.06, 5395.71], [2, 1.05, 5634.79]], "batl": [[0, 1.08, 5482.96], [1, 1.09, 491.63], [2, 1.1, 2076.03]]}, {"timestamp": 1578771209961, "ltp": 1.08, "tv": 6723.09, "trd": [[1.08, 4819.92]], "batb": NaN, "batl": [[0, 1.08, 5134.27]]}, {"timestamp": 1578771210976, "ltp": 1.08, "tv": 6727.09, "trd": [[1.08, 4823.92]], "batb": NaN, "batl": [[0, 1.08, 5132.27]]}, {"timestamp": 1578771212992, "ltp": 1.08, "tv": 6727.09, "trd": NaN, "batb": [[0, 1.07, 14401.68]], "batl": NaN}, {"timestamp": 1578771215972, "ltp": 1.08, "tv": 6727.09, "trd": NaN, "batb": NaN, "batl": [[0, 1.08, 5149.32]]}, {"timestamp": 1578771238007, "ltp": 1.08, "tv": 6727.09, "trd": NaN, "batb": [[0, 1.07, 14403.4]], "batl": NaN}, {"timestamp": 1578771238999, "ltp": 1.08, "tv": 6727.09, "trd": NaN, "batb": NaN, "batl": [[0, 1.08, 5480.35]]}, {"timestamp": 1578771240005, "ltp": 1.08, "tv": 6727.09, "trd": NaN, "batb": [[0, 1.07, 14363.4]], "batl": NaN}, {"timestamp": 1578771258054, "ltp": 1.08, "tv": 6727.09, "trd": NaN, "batb": [[2, 1.05, 5653.51]], "batl": NaN}, {"timestamp": 1578771267043, "ltp": 1.08, "tv": 6727.09, "trd": NaN, "batb": [[0, 1.07, 14480.61]], "batl": NaN}, {"timestamp": 1578771309020, "ltp": 1.07, "tv": 6812.21, "trd": [[1.07, 85.12]], "batb": [[0, 1.07, 14438.05]], "batl": NaN}, {"timestamp": 1578771334963, "ltp": 1.07, "tv": 6812.21, "trd": NaN, "batb": [[0, 1.07, 14625.05]], "batl": NaN}, {"timestamp": 1578771343985, "ltp": 1.07, "tv": 6812.21, "trd": NaN, "batb": [[0, 1.07, 14438.05]], "batl": NaN}, {"timestamp": 1578771349974, "ltp": 1.08, "tv": 6892.21, "trd": [[1.08, 4903.92]], "batb": NaN, "batl": [[0, 1.08, 5440.35]]}, {"timestamp": 1578771390018, "ltp": 1.08, "tv": 6892.21, "trd": NaN, "batb": [[0, 1.07, 14880.41]], "batl": NaN}, {"timestamp": 1578771395031, "ltp": 1.08, "tv": 6892.21, "trd": NaN, "batb": [[2, 1.05, 5908.87]], "batl": NaN}, {"timestamp": 1578771406980, "ltp": 1.08, "tv": 6918.08, "trd": [[1.08, 4929.79]], "batb": NaN, "batl": [[0, 1.08, 5414.48]]}, {"timestamp": 1578771443026, "ltp": 1.08, "tv": 6918.08, "trd": NaN, "batb": [[0, 1.07, 14693.41]], "batl": NaN}, {"timestamp": 1578771454923, "ltp": 1.08, "tv": 6918.08, "trd": NaN, "batb": [[0, 1.07, 14880.41]], "batl": NaN}, {"timestamp": 1578771494015, "ltp": 1.08, "tv": 6918.08, "trd": NaN, "batb": [[0, 1.07, 14693.41]], "batl": NaN}, {"timestamp": 1578771497975, "ltp": 1.08, "tv": 6933.39, "trd": [[1.08, 4945.09]], "batb": NaN, "batl": [[0, 1.08, 5406.83]]}, {"timestamp": 1578771519031, "ltp": 1.07, "tv": 7469.13, "trd": [[1.07, 620.86]], "batb": [[0, 1.07, 14434.83]], "batl": NaN}, {"timestamp": 1578771528044, "ltp": 1.07, "tv": 7469.13, "trd": NaN, "batb": [[0, 1.07, 14434.29]], "batl": NaN}, {"timestamp": 1578771529047, "ltp": 1.07, "tv": 7469.13, "trd": NaN, "batb": [[0, 1.07, 14433.75]], "batl": NaN}, {"timestamp": 1578771532968, "ltp": 1.07, "tv": 7553.32, "trd": [[1.07, 705.05]], "batb": [[0, 1.07, 14395.15]], "batl": NaN}, {"timestamp": 1578771549779, "ltp": 1.07, "tv": 7553.32, "trd": NaN, "batb": [[0, 1.07, 14383.45]], "batl": NaN}, {"timestamp": 1578771556966, "ltp": 1.07, "tv": 7573.32, "trd": [[1.07, 725.05]], "batb": [[0, 1.07, 14373.44]], "batl": NaN}, {"timestamp": 1578771583021, "ltp": 1.07, "tv": 7573.32, "trd": NaN, "batb": [[0, 1.07, 14374.21]], "batl": NaN}, {"timestamp": 1578771678999, "ltp": 1.07, "tv": 7583.32, "trd": [[1.07, 735.05]], "batb": [[0, 1.07, 14369.21]], "batl": NaN}, {"timestamp": 1578771710949, "ltp": 1.08, "tv": 7783.32, "trd": [[1.08, 5145.09]], "batb": NaN, "batl": [[0, 1.08, 5306.83]]}, {"timestamp": 1578771725981, "ltp": 1.08, "tv": 7783.32, "trd": NaN, "batb": [[0, 1.07, 14397.21]], "batl": NaN}, {"timestamp": 1578771728967, "ltp": 1.08, "tv": 7783.32, "trd": NaN, "batb": [[0, 1.07, 14396.45]], "batl": NaN}, {"timestamp": 1578771731976, "ltp": 1.08, "tv": 7784.85, "trd": [[1.08, 5146.63]], "batb": NaN, "batl": [[0, 1.08, 5306.06]]}, {"timestamp": 1578771766009, "ltp": 1.07, "tv": 7792.32, "trd": [[1.07, 742.52]], "batb": [[0, 1.07, 14392.71]], "batl": NaN}, {"timestamp": 1578771792036, "ltp": 1.07, "tv": 7792.32, "trd": NaN, "batb": NaN, "batl": [[2, 1.1, 928.01]]}, {"timestamp": 1578771796055, "ltp": 1.07, "tv": 7807.63, "trd": [[1.07, 757.83]], "batb": [[0, 1.07, 14385.06]], "batl": NaN}, {"timestamp": 1578771807992, "ltp": 1.07, "tv": 7807.63, "trd": NaN, "batb": [[0, 1.07, 14375.06], [1, 1.06, 5405.71]], "batl": NaN}, {"timestamp": 1578771829016, "ltp": 1.07, "tv": 7822.94, "trd": [[1.07, 773.14]], "batb": [[0, 1.07, 14367.4]], "batl": NaN}, {"timestamp": 1578771836044, "ltp": 1.08, "tv": 7876.69, "trd": [[1.08, 5200.38]], "batb": [[0, 1.07, 14377.4], [1, 1.06, 5395.71]], "batl": [[0, 1.08, 5252.31]]}, {"timestamp": 1578771837003, "ltp": 1.08, "tv": 7876.69, "trd": NaN, "batb": [[0, 1.07, 14367.4], [1, 1.06, 5405.71]], "batl": NaN}, {"timestamp": 1578771839024, "ltp": 1.08, "tv": 7876.69, "trd": NaN, "batb": [[0, 1.07, 14369.11]], "batl": NaN}, {"timestamp": 1578771840022, "ltp": 1.08, "tv": 7876.69, "trd": NaN, "batb": [[1, 1.06, 5407.41]], "batl": NaN}, {"timestamp": 1578771841034, "ltp": 1.08, "tv": 7876.69, "trd": NaN, "batb": [[2, 1.05, 5910.58]], "batl": NaN}, {"timestamp": 1578771853016, "ltp": 1.08, "tv": 7876.69, "trd": NaN, "batb": [[1, 1.06, 5620.21]], "batl": NaN}, {"timestamp": 1578771854860, "ltp": 1.08, "tv": 7876.69, "trd": NaN, "batb": [[1, 1.06, 5407.41]], "batl": NaN}, {"timestamp": 1578771856032, "ltp": 1.08, "tv": 7876.69, "trd": NaN, "batb": [[1, 1.06, 5513.81], [2, 1.05, 6016.98]], "batl": NaN}, {"timestamp": 1578771857035, "ltp": 1.08, "tv": 7876.69, "trd": NaN, "batb": NaN, "batl": [[1, 1.09, 796.13]]}, {"timestamp": 1578771894995, "ltp": 1.07, "tv": 7922.61, "trd": [[1.07, 819.06]], "batb": [[0, 1.07, 14346.15]], "batl": NaN}, {"timestamp": 1578771904978, "ltp": 1.07, "tv": 7922.61, "trd": NaN, "batb": NaN, "batl": [[1, 1.09, 979.13]]}, {"timestamp": 1578771918947, "ltp": 1.07, "tv": 7922.61, "trd": NaN, "batb": NaN, "batl": [[1, 1.09, 796.13]]}, {"timestamp": 1578771921957, "ltp": 1.07, "tv": 7922.61, "trd": NaN, "batb": NaN, "batl": [[1, 1.09, 979.13]]}, {"timestamp": 1578771924053, "ltp": 1.07, "tv": 7922.61, "trd": NaN, "batb": NaN, "batl": [[1, 1.09, 796.13]]}, {"timestamp": 1578771927047, "ltp": 1.07, "tv": 7922.61, "trd": NaN, "batb": NaN, "batl": [[1, 1.09, 979.13]]}, {"timestamp": 1578771927986, "ltp": 1.07, "tv": 7922.61, "trd": NaN, "batb": NaN, "batl": [[0, 1.08, 5275.27]]}, {"timestamp": 1578771933043, "ltp": 1.08, "tv": 7945.57, "trd": [[1.08, 5223.34]], "batb": [[0, 1.07, 4141.8]], "batl": [[0, 1.08, 5263.79]]}, {"timestamp": 1578771934054, "ltp": 1.08, "tv": 7945.57, "trd": NaN, "batb": [[1, 1.06, 5503.81]], "batl": NaN}, {"timestamp": 1578771934947, "ltp": 1.08, "tv": 7945.57, "trd": NaN, "batb": [[0, 1.07, 4151.8]], "batl": NaN}, {"timestamp": 1578771941980, "ltp": 1.08, "tv": 7945.57, "trd": NaN, "batb": [[0, 1.07, 3570.14]], "batl": NaN}, {"timestamp": 1578771950972, "ltp": 1.08, "tv": 7945.57, "trd": NaN, "batb": [[0, 1.07, 1867.72]], "batl": NaN}, {"timestamp": 1578771951964, "ltp": 1.08, "tv": 7945.57, "trd": NaN, "batb": [[0, 1.07, 746.56], [1, 1.06, 3973.12]], "batl": [[1, 1.09, 796.13]]}, {"timestamp": 1578771956988, "ltp": 1.07, "tv": 7945.76, "trd": [[1.07, 819.25]], "batb": [[0, 1.07, 746.46]], "batl": NaN}, {"timestamp": 1578771959984, "ltp": 1.07, "tv": 8673.14, "trd": [[1.07, 1546.62]], "batb": [[0, 1.07, 19.08]], "batl": NaN}, {"timestamp": 1578771960991, "ltp": 1.07, "tv": 8673.14, "trd": NaN, "batb": [[0, 1.07, 35.35]], "batl": NaN}, {"timestamp": 1578771961992, "ltp": 1.07, "tv": 8673.14, "trd": NaN, "batb": NaN, "batl": [[0, 1.08, 5288.63]]}, {"timestamp": 1578771963789, "ltp": 1.07, "tv": 8673.14, "trd": NaN, "batb": [[0, 1.07, 34.54]], "batl": NaN}, {"timestamp": 1578771968985, "ltp": 1.07, "tv": 8694.62, "trd": [[1.07, 1568.11]], "batb": [[0, 1.07, 25.98]], "batl": NaN}, {"timestamp": 1578771989051, "ltp": 1.07, "tv": 8746.58, "trd": [[1.07, 1620.07]], "batb": [[0, 1.06, 3973.12], [1, 1.05, 6016.98], [2, 1.04, 7900.7]], "batl": [[0, 1.07, 224.02], [1, 1.08, 5288.63], [2, 1.09, 796.13]]}, {"timestamp": 1578771990011, "ltp": 1.07, "tv": 8746.58, "trd": NaN, "batb": [[0, 1.06, 3993.83]], "batl": NaN}, {"timestamp": 1578771990853, "ltp": 1.07, "tv": 8746.58, "trd": NaN, "batb": [[0, 1.06, 3983.12]], "batl": [[0, 1.07, 266.3], [1, 1.08, 5246.74]]}, {"timestamp": 1578772006048, "ltp": 1.07, "tv": 8778.77, "trd": [[1.07, 1652.26]], "batb": NaN, "batl": [[0, 1.07, 234.11]]}, {"timestamp": 1578772014028, "ltp": 1.07, "tv": 8886.06, "trd": [[1.07, 1759.55]], "batb": NaN, "batl": [[0, 1.07, 126.82], [2, 1.09, 491.63]]}, {"timestamp": 1578772017961, "ltp": 1.07, "tv": 9012.88, "trd": [[1.07, 1886.37]], "batb": NaN, "batl": [[0, 1.08, 5246.74], [1, 1.09, 491.63], [2, 1.1, 928.01]]}, {"timestamp": 1578772019054, "ltp": 1.07, "tv": 9012.88, "trd": NaN, "batb": [[0, 1.07, 10], [1, 1.06, 3973.12], [2, 1.05, 6016.98]], "batl": NaN}, {"timestamp": 1578772019746, "ltp": 1.07, "tv": 9012.88, "trd": NaN, "batb": [[0, 1.07, 41.7]], "batl": NaN}, {"timestamp": 1578772031054, "ltp": 1.07, "tv": 9012.88, "trd": NaN, "batb": NaN, "batl": [[0, 1.08, 5278.44]]}, {"timestamp": 1578772033875, "ltp": 1.07, "tv": 9012.88, "trd": NaN, "batb": NaN, "batl": [[1, 1.09, 674.63]]}, {"timestamp": 1578772051772, "ltp": 1.07, "tv": 9012.88, "trd": NaN, "batb": [[0, 1.07, 31.7], [1, 1.06, 3983.12]], "batl": NaN}, {"timestamp": 1578772054963, "ltp": 1.07, "tv": 9012.88, "trd": NaN, "batb": [[1, 1.06, 3973.12]], "batl": [[1, 1.09, 1028.13]]}, {"timestamp": 1578772055998, "ltp": 1.07, "tv": 9012.88, "trd": NaN, "batb": [[0, 1.07, 41.7]], "batl": NaN}, {"timestamp": 1578772070993, "ltp": 1.07, "tv": 9012.88, "trd": NaN, "batb": NaN, "batl": [[1, 1.09, 845.13]]}, {"timestamp": 1578772082019, "ltp": 1.07, "tv": 9267.76, "trd": [[1.07, 2141.25]], "batb": [[0, 1.06, 3983.12], [1, 1.05, 6016.98], [2, 1.04, 7900.7]], "batl": [[0, 1.07, 113.71], [1, 1.08, 5278.44], [2, 1.09, 845.13]]}, {"timestamp": 1578772085011, "ltp": 1.07, "tv": 9267.76, "trd": NaN, "batb": NaN, "batl": [[0, 1.07, 145.41], [1, 1.08, 5246.74]]}, {"timestamp": 1578772094022, "ltp": 1.07, "tv": 9299.95, "trd": [[1.07, 2173.44]], "batb": NaN, "batl": [[0, 1.07, 113.22]]}, {"timestamp": 1578772098026, "ltp": 1.07, "tv": 9299.95, "trd": NaN, "batb": [[0, 1.06, 3794.12], [1, 1.05, 5826.98], [2, 1.04, 7708.7]], "batl": [[0, 1.07, 136.18], [1, 1.08, 5223.78]]}, {"timestamp": 1578772098957, "ltp": 1.07, "tv": 9299.95, "trd": NaN, "batb": [[0, 1.06, 3804.24]], "batl": NaN}, {"timestamp": 1578772099563, "ltp": 1.07, "tv": 9299.95, "trd": NaN, "batb": [[0, 1.06, 3764.44]], "batl": NaN}, {"timestamp": 1578772101023, "ltp": 1.07, "tv": 9299.95, "trd": NaN, "batb": [[0, 1.06, 1733.67], [1, 1.05, 5522.43], [2, 1.04, 7364.94]], "batl": [[0, 1.07, 22.96], [1, 1.09, 78.52], [2, 1.09, 0]]}, {"timestamp": 1578772108019, "ltp": 1.07, "tv": 9299.95, "trd": NaN, "batb": [[0, 1.06, 2070.95], [1, 1.05, 5862.92], [2, 1.04, 7708.7]], "batl": [[1, 1.08, 177.42], [2, 1.09, 261.96]]}, {"timestamp": 1578772108966, "ltp": 1.07, "tv": 9299.95, "trd": NaN, "batb": [[0, 1.06, 1733.67], [1, 1.05, 6022.43], [2, 1.04, 7364.94]], "batl": [[1, 1.09, 78.52], [2, 1.09, 0]]}, {"timestamp": 1578772109962, "ltp": 1.07, "tv": 9299.95, "trd": NaN, "batb": [[0, 1.06, 1743.79]], "batl": [[1, 1.08, 29.36], [2, 1.09, 78.52]]}, {"timestamp": 1578772111004, "ltp": 1.07, "tv": 9299.95, "trd": NaN, "batb": NaN, "batl": [[1, 1.08, 114.48]]}, {"timestamp": 1578772112000, "ltp": 1.07, "tv": 9299.95, "trd": NaN, "batb": NaN, "batl": [[2, 1.09, 163.64]]}, {"timestamp": 1578772113015, "ltp": 1.07, "tv": 9344.21, "trd": [[1.07, 2217.7]], "batb": NaN, "batl": [[0, 1.08, 115.31], [1, 1.09, 163.64], [2, 1.11, 21.28]]}, {"timestamp": 1578772114004, "ltp": 1.07, "tv": 9344.21, "trd": NaN, "batb": [[1, 1.05, 6212.43], [2, 1.04, 7556.94]], "batl": NaN}, {"timestamp": 1578772114999, "ltp": 1.07, "tv": 9345.04, "trd": [[1.07, 2218.53]], "batb": NaN, "batl": [[0, 1.08, 114.48]]}, {"timestamp": 1578772116004, "ltp": 1.07, "tv": 9345.04, "trd": NaN, "batb": NaN, "batl": [[2, 1.1, 17.02]]}, {"timestamp": 1578772117012, "ltp": 1.07, "tv": 9345.04, "trd": NaN, "batb": [[0, 1.06, 1733.67], [1, 1.05, 6214.43], [2, 1.04, 7558.94]], "batl": [[1, 1.09, 467.14], [2, 1.1, 351.41]]}, {"timestamp": 1578772118011, "ltp": 1.07, "tv": 9345.04, "trd": NaN, "batb": NaN, "batl": [[1, 1.09, 163.64], [2, 1.1, 27.66]]}, {"timestamp": 1578772119992, "ltp": 1.07, "tv": 9345.04, "trd": NaN, "batb": [[0, 1.07, 109.38], [1, 1.06, 1733.67], [2, 1.05, 6214.43]], "batl": NaN}, {"timestamp": 1578772120976, "ltp": 1.08, "tv": 9557.84, "trd": [[1.08, 5436.14]], "batb": NaN, "batl": [[0, 1.08, 8.08]]}, {"timestamp": 1578772123020, "ltp": 1.08, "tv": 9557.84, "trd": NaN, "batb": [[0, 1.07, 126.4], [1, 1.06, 1735.67]], "batl": NaN}, {"timestamp": 1578772124032, "ltp": 1.08, "tv": 9557.84, "trd": NaN, "batb": [[0, 1.07, 3538.14]], "batl": [[2, 1.1, 927.66]]}, {"timestamp": 1578772126020, "ltp": 1.08, "tv": 9557.84, "trd": NaN, "batb": NaN, "batl": [[2, 1.1, 1226.21]]}, {"timestamp": 1578772128999, "ltp": 1.08, "tv": 9557.84, "trd": NaN, "batb": NaN, "batl": [[1, 1.09, 284.78], [2, 1.1, 1247.49]]}, {"timestamp": 1578772129988, "ltp": 1.08, "tv": 9557.84, "trd": NaN, "batb": NaN, "batl": [[1, 1.09, 383.75], [2, 1.1, 1226.21]]}, {"timestamp": 1578772131049, "ltp": 1.08, "tv": 9557.84, "trd": NaN, "batb": [[0, 1.07, 3559.42]], "batl": [[2, 1.1, 1519.96]]}, {"timestamp": 1578772132044, "ltp": 1.08, "tv": 9557.84, "trd": NaN, "batb": NaN, "batl": [[1, 1.09, 674.46]]}, {"timestamp": 1578772132990, "ltp": 1.08, "tv": 9557.84, "trd": NaN, "batb": [[0, 1.07, 3542.4]], "batl": [[2, 1.1, 1502.94]]}, {"timestamp": 1578772134031, "ltp": 1.08, "tv": 9557.84, "trd": NaN, "batb": [[0, 1.07, 6943.59]], "batl": NaN}, {"timestamp": 1578772135024, "ltp": 1.08, "tv": 9557.84, "trd": NaN, "batb": [[1, 1.06, 5136.87], [2, 1.05, 9615.63]], "batl": NaN}, {"timestamp": 1578772144036, "ltp": 1.07, "tv": 9720.88, "trd": [[1.07, 2381.57]], "batb": [[0, 1.07, 6862.07], [1, 1.06, 5322.93], [2, 1.05, 9805.46]], "batl": [[1, 1.09, 1002.45]]}, {"timestamp": 1578772146042, "ltp": 1.07, "tv": 9720.88, "trd": NaN, "batb": [[0, 1.07, 3460.45]], "batl": [[2, 1.1, 602.94]]}, {"timestamp": 1578772151035, "ltp": 1.07, "tv": 9720.88, "trd": NaN, "batb": NaN, "batl": [[1, 1.09, 1305.95]]}, {"timestamp": 1578772153020, "ltp": 1.07, "tv": 9720.88, "trd": NaN, "batb": NaN, "batl": [[0, 1.08, 39.78]]}, {"timestamp": 1578772153956, "ltp": 1.07, "tv": 9720.88, "trd": NaN, "batb": [[0, 1.07, 5161.26]], "batl": [[2, 1.1, 1052.94]]}, {"timestamp": 1578772154951, "ltp": 1.07, "tv": 9720.88, "trd": NaN, "batb": [[0, 1.07, 6862.07]], "batl": [[2, 1.1, 1502.94]]}, {"timestamp": 1578772159039, "ltp": 1.07, "tv": 9720.88, "trd": NaN, "batb": NaN, "batl": [[0, 1.08, 177.68]]}, {"timestamp": 1578772163053, "ltp": 1.07, "tv": 9720.88, "trd": NaN, "batb": NaN, "batl": [[0, 1.08, 39.78]]}, {"timestamp": 1578772165013, "ltp": 1.07, "tv": 9720.88, "trd": NaN, "batb": [[0, 1.07, 7058.17]], "batl": NaN}, {"timestamp": 1578772175975, "ltp": 1.07, "tv": 9720.88, "trd": NaN, "batb": NaN, "batl": [[0, 1.08, 81.88]]}, {"timestamp": 1578772177959, "ltp": 1.07, "tv": 9720.88, "trd": NaN, "batb": [[0, 1.07, 7075.19]], "batl": [[2, 1.1, 1519.96]]}, {"timestamp": 1578772185997, "ltp": 1.07, "tv": 9720.88, "trd": NaN, "batb": [[1, 1.06, 6490.93], [2, 1.05, 10945.46]], "batl": [[2, 1.1, 2669.96]]}, {"timestamp": 1578772194971, "ltp": 1.08, "tv": 9873.96, "trd": [[1.08, 5589.22]], "batb": NaN, "batl": [[0, 1.08, 5.33]]}, {"timestamp": 1578772203007, "ltp": 1.08, "tv": 9873.96, "trd": NaN, "batb": [[0, 1.07, 7095]], "batl": NaN}, {"timestamp": 1578772203998, "ltp": 1.08, "tv": 9873.96, "trd": NaN, "batb": [[0, 1.07, 7077.98]], "batl": NaN}, {"timestamp": 1578772205038, "ltp": 1.08, "tv": 9873.96, "trd": NaN, "batb": [[2, 1.05, 10445.46]], "batl": NaN}, {"timestamp": 1578772206035, "ltp": 1.08, "tv": 9873.96, "trd": NaN, "batb": NaN, "batl": [[2, 1.1, 1769.96]]}, {"timestamp": 1578772211013, "ltp": 1.08, "tv": 9873.96, "trd": NaN, "batb": [[1, 1.06, 6507.96]], "batl": [[2, 1.1, 1752.94]]}, {"timestamp": 1578772214029, "ltp": 1.08, "tv": 9873.96, "trd": NaN, "batb": NaN, "batl": [[1, 1.09, 3292.95]]}, {"timestamp": 1578772216019, "ltp": 1.08, "tv": 9873.96, "trd": NaN, "batb": NaN, "batl": [[2, 1.1, 1480.47]]}, {"timestamp": 1578772218010, "ltp": 1.08, "tv": 9873.96, "trd": NaN, "batb": NaN, "batl": [[1, 1.09, 3309.97]]}, {"timestamp": 1578772221046, "ltp": 1.08, "tv": 9873.96, "trd": NaN, "batb": NaN, "batl": [[0, 1.08, 18.52], [1, 1.09, 2222.97], [2, 1.1, 330.47]]}, {"timestamp": 1578772223039, "ltp": 1.08, "tv": 9879.29, "trd": [[1.08, 5594.55]], "batb": NaN, "batl": [[0, 1.08, 780.96]]}, {"timestamp": 1578772224031, "ltp": 1.08, "tv": 9879.29, "trd": NaN, "batb": NaN, "batl": [[0, 1.08, 914.55]]}, {"timestamp": 1578772225023, "ltp": 1.08, "tv": 9879.29, "trd": NaN, "batb": [[0, 1.07, 8243.98]], "batl": NaN}, {"timestamp": 1578772230042, "ltp": 1.08, "tv": 9879.29, "trd": NaN, "batb": [[0, 1.07, 8222.7]], "batl": [[2, 1.1, 309.19]]}, {"timestamp": 1578772233979, "ltp": 1.08, "tv": 9879.29, "trd": NaN, "batb": [[0, 1.07, 6947.1]], "batl": [[1, 1.09, 2137.85]]}, {"timestamp": 1578772235048, "ltp": 1.08, "tv": 9879.29, "trd": NaN, "batb": [[1, 1.06, 6532.96]], "batl": [[1, 1.09, 3329.85], [2, 1.1, 1462.19]]}, {"timestamp": 1578772236982, "ltp": 1.08, "tv": 9879.29, "trd": NaN, "batb": [[0, 1.07, 6968.38]], "batl": [[2, 1.1, 1483.47]]}, {"timestamp": 1578772241962, "ltp": 1.08, "tv": 9879.29, "trd": NaN, "batb": [[1, 1.06, 7808.56]], "batl": NaN}, {"timestamp": 1578772243962, "ltp": 1.08, "tv": 9879.29, "trd": NaN, "batb": [[0, 1.07, 6940.52]], "batl": NaN}, {"timestamp": 1578772257977, "ltp": 1.08, "tv": 9879.29, "trd": NaN, "batb": [[0, 1.07, 3539.32]], "batl": NaN}, {"timestamp": 1578772259971, "ltp": 1.07, "tv": 9883.29, "trd": [[1.07, 2385.57]], "batb": [[0, 1.07, 3537.32]], "batl": NaN}, {"timestamp": 1578772260987, "ltp": 1.07, "tv": 9883.29, "trd": NaN, "batb": [[0, 1.07, 3535.32]], "batl": NaN}, {"timestamp": 1578772264028, "ltp": 1.07, "tv": 9883.29, "trd": NaN, "batb": [[0, 1.07, 1409.3], [1, 1.06, 6532.96]], "batl": [[1, 1.09, 2429.85]]}, {"timestamp": 1578772272003, "ltp": 1.07, "tv": 9883.29, "trd": NaN, "batb": [[1, 1.06, 10207.1]], "batl": [[1, 1.09, 3329.85]]}, {"timestamp": 1578772275035, "ltp": 1.07, "tv": 9883.29, "trd": NaN, "batb": [[0, 1.07, 1411.3]], "batl": NaN}, {"timestamp": 1578772278020, "ltp": 1.07, "tv": 9883.29, "trd": NaN, "batb": NaN, "batl": [[2, 1.1, 1462.19]]}, {"timestamp": 1578772282055, "ltp": 1.07, "tv": 9883.29, "trd": NaN, "batb": [[0, 1.07, 1390.02]], "batl": NaN}, {"timestamp": 1578772284044, "ltp": 1.07, "tv": 9883.29, "trd": NaN, "batb": NaN, "batl": [[1, 1.09, 3351.13]]}, {"timestamp": 1578772288914, "ltp": 1.07, "tv": 9883.29, "trd": NaN, "batb": [[1, 1.06, 10228.38]], "batl": NaN}, {"timestamp": 1578772293949, "ltp": 1.07, "tv": 9883.29, "trd": NaN, "batb": [[0, 1.07, 224.02], [1, 1.06, 9060.38], [2, 1.05, 9305.46]], "batl": [[1, 1.09, 2159.13], [2, 1.1, 309.19]]}, {"timestamp": 1578772294860, "ltp": 1.07, "tv": 9883.29, "trd": NaN, "batb": [[0, 1.07, 27.93], [1, 1.06, 9039.1]], "batl": [[1, 1.09, 2137.85]]}, {"timestamp": 1578772296040, "ltp": 1.07, "tv": 9883.29, "trd": NaN, "batb": [[1, 1.06, 5161.87], [2, 1.05, 8925.63]], "batl": [[0, 1.08, 118.91], [1, 1.09, 177.49], [2, 1.1, 10.64]]}, {"timestamp": 1578772296937, "ltp": 1.07, "tv": 9883.29, "trd": NaN, "batb": NaN, "batl": [[0, 1.08, 13.19], [1, 1.09, 78.52]]}, {"timestamp": 1578772347979, "ltp": 1.07, "tv": 9883.29, "trd": NaN, "batb": [[0, 1.06, 1760.67], [1, 1.05, 5524.43], [2, 1.04, 7366.94]], "batl": [[0, 1.09, 78.52], [1, 1.09, 0], [2, 1.1, 0]]}, {"timestamp": 1578772356009, "ltp": 1.09, "tv": 10040.33, "trd": [[1.09, 2060.22]], "batb": [[0, 1.16, 595.85], [1, 1.15, 595.85], [2, 1.14, 595.85]], "batl": NaN}, {"timestamp": 1578772359020, "ltp": 1.09, "tv": 10040.33, "trd": NaN, "batb": [[1, 1.15, 675.78]], "batl": [[0, 90, 2.67]]}, {"timestamp": 1578772363012, "ltp": 1.09, "tv": 10040.33, "trd": NaN, "batb": [[0, 1.15, 675.78], [1, 1.14, 595.85], [2, 1.13, 595.85]], "batl": [[0, 15, 1.94], [1, 90, 2.67]]}, {"timestamp": 1578772364005, "ltp": 1.09, "tv": 10040.33, "trd": NaN, "batb": [[0, 1.15, 1557.78], [1, 1.14, 1465.85], [2, 1.13, 1484.85]], "batl": NaN}, {"timestamp": 1578772364993, "ltp": 1.09, "tv": 10040.33, "trd": NaN, "batb": [[0, 1.16, 883], [1, 1.15, 1557.78], [2, 1.14, 1465.85]], "batl": NaN}, {"timestamp": 1578772366041, "ltp": 1.09, "tv": 10040.33, "trd": NaN, "batb": [[0, 1.16, 904.28], [1, 1.15, 2323.87], [2, 1.14, 2338.34]], "batl": [[0, 1.22, 21.28], [1, 15, 1.94], [2, 90, 2.67]]}, {"timestamp": 1578772368009, "ltp": 1.09, "tv": 10040.33, "trd": NaN, "batb": [[0, 1.16, 983.53], [2, 1.14, 2564.29]], "batl": NaN}, {"timestamp": 1578772369001, "ltp": 1.09, "tv": 10040.33, "trd": NaN, "batb": NaN, "batl": [[0, 1.19, 7.66], [1, 1.22, 21.28], [2, 15, 1.94]]}, {"timestamp": 1578772369992, "ltp": 1.09, "tv": 10040.33, "trd": NaN, "batb": [[1, 1.15, 2497.87], [2, 1.14, 2739.29]], "batl": NaN}, {"timestamp": 1578772375927, "ltp": 1.09, "tv": 10040.33, "trd": NaN, "batb": [[0, 1.16, 2108.53]], "batl": [[1, 1.2, 337.5], [2, 1.21, 450]]}, {"timestamp": 1578772377028, "ltp": 1.09, "tv": 10040.33, "trd": NaN, "batb": [[2, 1.14, 2803.75]], "batl": [[1, 1.21, 1338], [2, 1.22, 929.01]]}, {"timestamp": 1578772378023, "ltp": 1.16, "tv": 10046.45, "trd": [[1.16, 6.12]], "batb": [[0, 1.16, 2105.47], [1, 1.15, 2637.37], [2, 1.14, 3077.02]], "batl": [[2, 1.22, 986.83]]}, {"timestamp": 1578772379046, "ltp": 1.16, "tv": 10107.68, "trd": [[1.16, 67.35]], "batb": [[0, 1.16, 2074.86]], "batl": NaN}, {"timestamp": 1578772380032, "ltp": 1.16, "tv": 10107.68, "trd": NaN, "batb": [[2, 1.14, 3240.83]], "batl": NaN}, {"timestamp": 1578772383028, "ltp": 1.16, "tv": 10107.68, "trd": NaN, "batb": NaN, "batl": [[0, 1.17, 3.06], [1, 1.19, 7.66], [2, 1.2, 346.44]]}, {"timestamp": 1578772384025, "ltp": 1.16, "tv": 10107.68, "trd": NaN, "batb": [[0, 1.16, 3199.86], [2, 1.14, 3340.83]], "batl": [[2, 1.2, 557.75]]}, {"timestamp": 1578772385966, "ltp": 1.16, "tv": 10107.68, "trd": NaN, "batb": [[0, 1.16, 949.86]], "batl": NaN}, {"timestamp": 1578772388952, "ltp": 1.16, "tv": 10107.68, "trd": NaN, "batb": NaN, "batl": [[2, 1.2, 642.88]]}, {"timestamp": 1578772389985, "ltp": 1.17, "tv": 10113.8, "trd": [[1.17, 6.12]], "batb": [[0, 1.17, 22.48], [1, 1.16, 949.86], [2, 1.15, 2637.37]], "batl": [[0, 1.19, 92.78], [1, 1.2, 658.08], [2, 1.21, 888]]}, {"timestamp": 1578772390974, "ltp": 1.17, "tv": 10113.8, "trd": NaN, "batb": [[0, 1.16, 949.86], [1, 1.15, 2637.37], [2, 1.14, 3406.83]], "batl": NaN}, {"timestamp": 1578772392968, "ltp": 1.17, "tv": 10153.8, "trd": [[1.17, 46.12]], "batb": [[0, 1.17, 688], [1, 1.16, 949.86], [2, 1.15, 2637.37]], "batl": [[1, 1.2, 1108.08]]}, {"timestamp": 1578772394032, "ltp": 1.17, "tv": 10153.8, "trd": NaN, "batb": [[1, 1.16, 2074.86]], "batl": [[1, 1.2, 1542.88]]}, {"timestamp": 1578772394980, "ltp": 1.17, "tv": 10204.88, "trd": [[1.17, 97.2]], "batb": [[0, 1.17, 662.46]], "batl": NaN}, {"timestamp": 1578772395979, "ltp": 1.17, "tv": 10204.88, "trd": NaN, "batb": [[1, 1.16, 949.86]], "batl": [[1, 1.2, 1092.88]]}, {"timestamp": 1578772396977, "ltp": 1.17, "tv": 10204.88, "trd": NaN, "batb": [[1, 1.16, 969.45]], "batl": NaN}, {"timestamp": 1578772397970, "ltp": 1.17, "tv": 10204.88, "trd": NaN, "batb": [[1, 1.16, 2054.75]], "batl": NaN}, {"timestamp": 1578772399006, "ltp": 1.17, "tv": 10204.88, "trd": NaN, "batb": NaN, "batl": [[1, 1.2, 1805.88]]}, {"timestamp": 1578772400005, "ltp": 1.17, "tv": 10204.88, "trd": NaN, "batb": [[1, 1.16, 1026.83]], "batl": [[0, 1.19, 143.43], [1, 1.2, 1355.88]]}, {"timestamp": 1578772401002, "ltp": 1.17, "tv": 10204.88, "trd": NaN, "batb": [[0, 1.17, 1140.58], [1, 1.16, 1446.66], [2, 1.15, 2985.57]], "batl": [[0, 1.19, 674.98]]}, {"timestamp": 1578772402030, "ltp": 1.17, "tv": 10204.88, "trd": NaN, "batb": NaN, "batl": [[0, 1.18, 7.65], [1, 1.19, 674.98], [2, 1.2, 1355.88]]}, {"timestamp": 1578772404015, "ltp": 1.17, "tv": 10204.88, "trd": NaN, "batb": [[1, 1.16, 2571.66]], "batl": [[2, 1.2, 1805.88]]}, {"timestamp": 1578772405006, "ltp": 1.17, "tv": 10204.88, "trd": NaN, "batb": [[1, 1.16, 3318.16]], "batl": [[1, 1.19, 659.77]]}, {"timestamp": 1578772407006, "ltp": 1.17, "tv": 10264.88, "trd": [[1.17, 157.2]], "batb": [[0, 1.17, 1110.58]], "batl": [[0, 1.18, 112.35]]}, {"timestamp": 1578772408980, "ltp": 1.17, "tv": 10264.88, "trd": NaN, "batb": NaN, "batl": [[1, 1.19, 1317.77]]}, {"timestamp": 1578772411983, "ltp": 1.17, "tv": 10269.47, "trd": [[1.17, 161.79]], "batb": [[0, 1.17, 1130.76]], "batl": NaN}, {"timestamp": 1578772413015, "ltp": 1.17, "tv": 10269.47, "trd": NaN, "batb": [[1, 1.16, 3599.41]], "batl": [[2, 1.2, 1918.38]]}, {"timestamp": 1578772413968, "ltp": 1.17, "tv": 10269.47, "trd": NaN, "batb": [[1, 1.16, 3318.16]], "batl": [[2, 1.2, 1805.88]]}, {"timestamp": 1578772416002, "ltp": 1.17, "tv": 10269.47, "trd": NaN, "batb": [[0, 1.17, 897.6]], "batl": [[2, 1.2, 1699.26]]}, {"timestamp": 1578772417002, "ltp": 1.17, "tv": 10591.81, "trd": [[1.17, 484.14]], "batb": [[0, 1.17, 561.04]], "batl": NaN}, {"timestamp": 1578772418985, "ltp": 1.17, "tv": 10610.5, "trd": [[1.17, 502.82]], "batb": [[0, 1.17, 551.7]], "batl": NaN}, {"timestamp": 1578772421024, "ltp": 1.17, "tv": 10933.82, "trd": [[1.17, 826.14]], "batb": [[0, 1.17, 390.04]], "batl": NaN}, {"timestamp": 1578772423018, "ltp": 1.17, "tv": 10933.82, "trd": NaN, "batb": NaN, "batl": [[0, 1.18, 249.92]]}, {"timestamp": 1578772424004, "ltp": 1.17, "tv": 10933.82, "trd": NaN, "batb": [[0, 1.17, 22.48]], "batl": NaN}, {"timestamp": 1578772424895, "ltp": 1.17, "tv": 10933.82, "trd": NaN, "batb": NaN, "batl": [[2, 1.2, 1248.12]]}, {"timestamp": 1578772431967, "ltp": 1.17, "tv": 10933.82, "trd": NaN, "batb": NaN, "batl": [[0, 1.18, 706.91]]}, {"timestamp": 1578772433026, "ltp": 1.17, "tv": 10933.82, "trd": NaN, "batb": [[2, 1.15, 2905.63]], "batl": [[0, 1.18, 1466.91], [1, 1.19, 1767.77]]}, {"timestamp": 1578772434026, "ltp": 1.17, "tv": 10933.82, "trd": NaN, "batb": NaN, "batl": [[0, 1.18, 1459.25]]}, {"timestamp": 1578772436023, "ltp": 1.17, "tv": 10978.78, "trd": [[1.17, 871.1]], "batb": [[0, 1.16, 3318.16], [1, 1.15, 2905.63], [2, 1.14, 3180.88]], "batl": [[0, 1.17, 2.52], [1, 1.18, 1459.25], [2, 1.19, 1767.77]]}, {"timestamp": 1578772437014, "ltp": 1.16, "tv": 11178.78, "trd": [[1.16, 267.35]], "batb": [[0, 1.16, 3218.16], [1, 1.15, 2907.63], [2, 1.14, 3182.88]], "batl": [[2, 1.19, 1937.27]]}, {"timestamp": 1578772440043, "ltp": 1.16, "tv": 11178.78, "trd": NaN, "batb": [[0, 1.16, 3499.41]], "batl": NaN}, {"timestamp": 1578772441035, "ltp": 1.16, "tv": 11178.78, "trd": NaN, "batb": NaN, "batl": [[0, 1.17, 10.17]]}, {"timestamp": 1578772442038, "ltp": 1.17, "tv": 11188.96, "trd": [[1.17, 881.28]], "batb": NaN, "batl": [[0, 1.18, 1459.25], [1, 1.19, 1937.27], [2, 1.2, 1411.9]]}, {"timestamp": 1578772442979, "ltp": 1.17, "tv": 11188.96, "trd": NaN, "batb": [[2, 1.14, 3408.83]], "batl": [[0, 1.18, 891], [2, 1.2, 1248.12]]}, {"timestamp": 1578772443967, "ltp": 1.17, "tv": 11188.96, "trd": NaN, "batb": [[0, 1.16, 3508.43], [2, 1.14, 3182.88]], "batl": [[2, 1.2, 798.12]]}, {"timestamp": 1578772445037, "ltp": 1.17, "tv": 11188.96, "trd": NaN, "batb": [[0, 1.16, 2093.16]], "batl": [[1, 1.19, 1487.27]]}, {"timestamp": 1578772446968, "ltp": 1.17, "tv": 11188.96, "trd": NaN, "batb": NaN, "batl": [[1, 1.19, 1402.15]]}, {"timestamp": 1578772447990, "ltp": 1.17, "tv": 11188.96, "trd": NaN, "batb": NaN, "batl": [[2, 1.2, 713]]}, {"timestamp": 1578772449055, "ltp": 1.16, "tv": 11194.96, "trd": [[1.16, 273.35]], "batb": [[0, 1.16, 2090.16]], "batl": [[2, 1.2, 725]]}, {"timestamp": 1578772449944, "ltp": 1.16, "tv": 11194.96, "trd": NaN, "batb": NaN, "batl": [[0, 1.17, 34.44], [1, 1.18, 891], [2, 1.19, 1402.15]]}, {"timestamp": 1578772451039, "ltp": 1.16, "tv": 11194.96, "trd": NaN, "batb": NaN, "batl": [[1, 1.18, 699.25]]}, {"timestamp": 1578772451969, "ltp": 1.16, "tv": 11194.96, "trd": NaN, "batb": NaN, "batl": [[2, 1.19, 2302.15]]}, {"timestamp": 1578772452958, "ltp": 1.16, "tv": 11194.96, "trd": NaN, "batb": [[1, 1.15, 4069.52]], "batl": NaN}, {"timestamp": 1578772455040, "ltp": 1.16, "tv": 11194.96, "trd": NaN, "batb": [[0, 1.16, 2068.88], [1, 1.15, 5231.41]], "batl": NaN}, {"timestamp": 1578772456977, "ltp": 1.16, "tv": 11194.96, "trd": NaN, "batb": NaN, "batl": [[1, 1.18, 1428.25]]}, {"timestamp": 1578772457965, "ltp": 1.16, "tv": 11194.96, "trd": NaN, "batb": [[1, 1.15, 5057.41]], "batl": NaN}, {"timestamp": 1578772460976, "ltp": 1.16, "tv": 11194.96, "trd": NaN, "batb": [[0, 1.16, 2085.9]], "batl": NaN}, {"timestamp": 1578772461970, "ltp": 1.16, "tv": 11194.96, "trd": NaN, "batb": [[1, 1.15, 5078.69]], "batl": NaN}, {"timestamp": 1578772462957, "ltp": 1.16, "tv": 11194.96, "trd": NaN, "batb": NaN, "batl": [[2, 1.19, 2294.49]]}, {"timestamp": 1578772468981, "ltp": 1.16, "tv": 11194.96, "trd": NaN, "batb": NaN, "batl": [[1, 1.18, 2193.6]]}, {"timestamp": 1578772471002, "ltp": 1.16, "tv": 11297.73, "trd": [[1.16, 376.12]], "batb": [[0, 1.16, 2034.51]], "batl": [[0, 1.17, 42.1]]}, {"timestamp": 1578772473967, "ltp": 1.16, "tv": 11303.85, "trd": [[1.16, 382.24]], "batb": [[0, 1.16, 2031.45]], "batl": NaN}, {"timestamp": 1578772476002, "ltp": 1.16, "tv": 11303.85, "trd": NaN, "batb": NaN, "batl": [[2, 1.19, 2230.51]]}, {"timestamp": 1578772476996, "ltp": 1.16, "tv": 11303.85, "trd": NaN, "batb": [[0, 1.16, 1626.75]], "batl": [[1, 1.18, 1428.25], [2, 1.19, 1727.5]]}, {"timestamp": 1578772480014, "ltp": 1.16, "tv": 11331.41, "trd": [[1.16, 409.8]], "batb": [[0, 1.16, 1612.97]], "batl": NaN}, {"timestamp": 1578772482975, "ltp": 1.16, "tv": 11331.41, "trd": NaN, "batb": NaN, "batl": [[0, 1.17, 108.74]]}, {"timestamp": 1578772484013, "ltp": 1.16, "tv": 11331.41, "trd": NaN, "batb": [[0, 1.16, 846.89]], "batl": [[0, 1.17, 637.5]]}, {"timestamp": 1578772485999, "ltp": 1.16, "tv": 11331.41, "trd": NaN, "batb": NaN, "batl": [[2, 1.19, 827.5]]}, {"timestamp": 1578772487018, "ltp": 1.16, "tv": 11331.41, "trd": NaN, "batb": [[1, 1.15, 3916.8]], "batl": NaN}, {"timestamp": 1578772487975, "ltp": 1.16, "tv": 11331.41, "trd": NaN, "batb": [[0, 1.16, 829.86]], "batl": [[1, 1.18, 1410.24]]}, {"timestamp": 1578772491976, "ltp": 1.16, "tv": 11331.41, "trd": NaN, "batb": [[0, 1.16, 151.76]], "batl": NaN}, {"timestamp": 1578772494000, "ltp": 1.16, "tv": 11331.41, "trd": NaN, "batb": NaN, "batl": [[1, 1.18, 1860.24]]}, {"timestamp": 1578772494988, "ltp": 1.16, "tv": 11331.41, "trd": NaN, "batb": [[1, 1.15, 3337.98]], "batl": [[0, 1.17, 669.2]]}, {"timestamp": 1578772496028, "ltp": 1.16, "tv": 11407.95, "trd": [[1.16, 486.34]], "batb": [[0, 1.16, 113.49]], "batl": NaN}, {"timestamp": 1578772497011, "ltp": 1.16, "tv": 11407.95, "trd": NaN, "batb": [[0, 1.16, 40.98]], "batl": NaN}, {"timestamp": 1578772499980, "ltp": 1.16, "tv": 11484.49, "trd": [[1.16, 562.87]], "batb": [[0, 1.16, 2.71]], "batl": NaN}, {"timestamp": 1578772501021, "ltp": 1.16, "tv": 11484.49, "trd": NaN, "batb": NaN, "batl": [[0, 1.17, 1443.2]]}, {"timestamp": 1578772503990, "ltp": 1.16, "tv": 11484.49, "trd": NaN, "batb": NaN, "batl": [[0, 1.17, 669.2], [1, 1.18, 1131.24], [2, 1.19, 169.5]]}, {"timestamp": 1578772504986, "ltp": 1.16, "tv": 11484.49, "trd": NaN, "batb": [[1, 1.15, 2176.09]], "batl": [[0, 1.17, 363.64], [1, 1.18, 681.24]]}, {"timestamp": 1578772506035, "ltp": 1.16, "tv": 11484.49, "trd": NaN, "batb": [[2, 1.14, 3007.88]], "batl": [[0, 1.17, 198.44]]}, {"timestamp": 1578772508024, "ltp": 1.16, "tv": 11484.49, "trd": NaN, "batb": [[2, 1.14, 3308.54]], "batl": [[1, 1.18, 962.99]]}, {"timestamp": 1578772508908, "ltp": 1.15, "tv": 17031.65, "trd": [[1.15, 5541.74], [1.16, 568.29]], "batb": [[0, 1.14, 4210.55], [1, 1.13, 3083.09], [2, 1.12, 3206.46]], "batl": [[0, 1.15, 70643.64], [1, 1.17, 198.44], [2, 1.18, 1300.49]]}, {"timestamp": 1578772512036, "ltp": 1.15, "tv": 17846.92, "trd": [[1.15, 6357.01]], "batb": [[0, 1.14, 5413.22]], "batl": [[0, 1.15, 69828.37], [2, 1.18, 1750.49]]}, {"timestamp": 1578772513037, "ltp": 1.15, "tv": 18036.21, "trd": [[1.15, 6546.3]], "batb": NaN, "batl": [[0, 1.15, 69639.08]]}, {"timestamp": 1578772514014, "ltp": 1.15, "tv": 18036.21, "trd": NaN, "batb": NaN, "batl": [[1, 1.16, 173.06], [2, 1.17, 198.44]]}, {"timestamp": 1578772514899, "ltp": 1.15, "tv": 18325.19, "trd": [[1.15, 6835.28]], "batb": NaN, "batl": [[0, 1.15, 69350.1]]}, {"timestamp": 1578772516044, "ltp": 1.15, "tv": 18325.19, "trd": NaN, "batb": NaN, "batl": [[2, 1.17, 504]]}, {"timestamp": 1578772517038, "ltp": 1.15, "tv": 20000.88, "trd": [[1.15, 8510.98]], "batb": [[0, 1.14, 5451.52]], "batl": [[0, 1.15, 68512.25], [1, 1.16, 188.36], [2, 1.17, 632.23]]}, {"timestamp": 1578772518024, "ltp": 1.15, "tv": 20000.88, "trd": NaN, "batb": NaN, "batl": [[1, 1.16, 193.23]]}, {"timestamp": 1578772520046, "ltp": 1.15, "tv": 20000.88, "trd": NaN, "batb": NaN, "batl": [[1, 1.16, 959.32]]}, {"timestamp": 1578772521033, "ltp": 1.15, "tv": 20089.17, "trd": [[1.15, 8599.27]], "batb": NaN, "batl": [[0, 1.15, 68423.96]]}, {"timestamp": 1578772522024, "ltp": 1.15, "tv": 20089.17, "trd": NaN, "batb": NaN, "batl": [[1, 1.16, 1574.39]]}, {"timestamp": 1578772523056, "ltp": 1.15, "tv": 20089.17, "trd": NaN, "batb": [[0, 1.14, 5153.6]], "batl": NaN}, {"timestamp": 1578772524044, "ltp": 1.15, "tv": 20089.17, "trd": NaN, "batb": [[0, 1.14, 4855.67]], "batl": [[0, 1.15, 68462.23], [1, 1.16, 806.43]]}, {"timestamp": 1578772525043, "ltp": 1.15, "tv": 20128.33, "trd": [[1.15, 8638.42]], "batb": [[0, 1.14, 4749.27]], "batl": [[0, 1.15, 68442.65], [1, 1.16, 1624.43], [2, 1.17, 1379.23]]}, {"timestamp": 1578772527957, "ltp": 1.15, "tv": 20128.33, "trd": NaN, "batb": NaN, "batl": [[1, 1.16, 1626.3]]}, {"timestamp": 1578772530035, "ltp": 1.15, "tv": 20128.33, "trd": NaN, "batb": NaN, "batl": [[1, 1.16, 1434.93]]}, {"timestamp": 1578772531021, "ltp": 1.14, "tv": 20132.07, "trd": [[1.14, 3.74]], "batb": [[0, 1.14, 4747.4]], "batl": NaN}, {"timestamp": 1578772533055, "ltp": 1.14, "tv": 20135.47, "trd": [[1.14, 7.14]], "batb": [[0, 1.14, 4745.7]], "batl": [[0, 1.15, 68404.38], [1, 1.16, 1433.07]]}, {"timestamp": 1578772534048, "ltp": 1.14, "tv": 20135.47, "trd": NaN, "batb": NaN, "batl": [[2, 1.17, 1312.59]]}, {"timestamp": 1578772535036, "ltp": 1.15, "tv": 20183.13, "trd": [[1.15, 8686.09]], "batb": NaN, "batl": [[0, 1.15, 68380.55], [2, 1.17, 789.1]]}, {"timestamp": 1578772536036, "ltp": 1.15, "tv": 20183.13, "trd": NaN, "batb": [[2, 1.12, 3226.04]], "batl": NaN}, {"timestamp": 1578772537038, "ltp": 1.15, "tv": 20183.13, "trd": NaN, "batb": NaN, "batl": [[0, 1.15, 68383.55]]}, {"timestamp": 1578772539950, "ltp": 1.15, "tv": 20183.13, "trd": NaN, "batb": NaN, "batl": [[0, 1.15, 68400.57]]}, {"timestamp": 1578772541044, "ltp": 1.15, "tv": 20183.13, "trd": NaN, "batb": NaN, "batl": [[0, 1.15, 68476.43]]}, {"timestamp": 1578772541978, "ltp": 1.15, "tv": 20183.13, "trd": NaN, "batb": NaN, "batl": [[0, 1.15, 69044.44]]}, {"timestamp": 1578772542965, "ltp": 1.15, "tv": 20183.13, "trd": NaN, "batb": NaN, "batl": [[0, 1.15, 663.89]]}, {"timestamp": 1578772545970, "ltp": 1.14, "tv": 20273.67, "trd": [[1.14, 83.68], [1.15, 8700.09]], "batb": [[0, 1.14, 4707.43]], "batl": [[0, 1.15, 656.89]]}, {"timestamp": 1578772549974, "ltp": 1.14, "tv": 33618.5, "trd": [[1.14, 13428.51]], "batb": [[0, 1.13, 3083.09], [1, 1.12, 3226.04], [2, 1.11, 3146.19]], "batl": [[0, 1.14, 59745.02], [1, 1.15, 656.89], [2, 1.16, 1433.07]]}, {"timestamp": 1578772556989, "ltp": 1.14, "tv": 35501.56, "trd": [[1.14, 15311.57]], "batb": [[0, 1.13, 4002.13]], "batl": [[0, 1.14, 58803.49], [2, 1.16, 1883.07]]}, {"timestamp": 1578772557972, "ltp": 1.14, "tv": 35714.36, "trd": [[1.14, 15524.37]], "batb": [[0, 1.13, 4369.47]], "batl": [[0, 1.14, 58697.09], [1, 1.15, 1879.89]]}, {"timestamp": 1578772559996, "ltp": 1.14, "tv": 35714.36, "trd": NaN, "batb": NaN, "batl": [[0, 1.14, 58714.9]]}, {"timestamp": 1578772561985, "ltp": 1.14, "tv": 35714.36, "trd": NaN, "batb": NaN, "batl": [[0, 1.14, 58713.03], [1, 1.15, 1429.89]]}, {"timestamp": 1578772564986, "ltp": 1.14, "tv": 36991.18, "trd": [[1.14, 16801.19]], "batb": NaN, "batl": [[0, 1.14, 58074.62]]}, {"timestamp": 1578772566024, "ltp": 1.14, "tv": 37035.67, "trd": [[1.14, 16845.68]], "batb": [[0, 1.13, 4263.07]], "batl": [[0, 1.14, 58030.13]]}, {"timestamp": 1578772568002, "ltp": 1.14, "tv": 37035.67, "trd": NaN, "batb": NaN, "batl": [[0, 1.14, 58012.32]]}, {"timestamp": 1578772568995, "ltp": 1.13, "tv": 37039.41, "trd": [[1.13, 3.74]], "batb": [[0, 1.13, 4261.19]], "batl": NaN}, {"timestamp": 1578772570027, "ltp": 1.13, "tv": 37039.41, "trd": NaN, "batb": NaN, "batl": [[0, 1.14, 58044.02]]}, {"timestamp": 1578772571010, "ltp": 1.13, "tv": 37039.41, "trd": NaN, "batb": [[2, 1.11, 8247.99]], "batl": NaN}, {"timestamp": 1578772571998, "ltp": 1.13, "tv": 37039.41, "trd": NaN, "batb": [[0, 1.13, 3667.22]], "batl": NaN}, {"timestamp": 1578772573030, "ltp": 1.14, "tv": 37089.41, "trd": [[1.14, 16895.68]], "batb": [[1, 1.12, 2928.12]], "batl": [[0, 1.14, 58019.02]]}, {"timestamp": 1578772574008, "ltp": 1.14, "tv": 37089.41, "trd": NaN, "batb": [[0, 1.13, 3490.22], [1, 1.12, 2630.2]], "batl": NaN}, {"timestamp": 1578772577014, "ltp": 1.14, "tv": 37089.41, "trd": NaN, "batb": NaN, "batl": [[0, 1.14, 58036.05]]}, {"timestamp": 1578772577992, "ltp": 1.14, "tv": 37223.92, "trd": [[1.14, 17030.19]], "batb": [[0, 1.13, 2724.13]], "batl": [[0, 1.14, 57901.54]]}, {"timestamp": 1578772579021, "ltp": 1.14, "tv": 37223.92, "trd": NaN, "batb": [[0, 1.13, 2553.42]], "batl": [[2, 1.16, 1574.87]]}, {"timestamp": 1578772580004, "ltp": 1.13, "tv": 37227.66, "trd": [[1.13, 7.48]], "batb": [[0, 1.13, 2334.02]], "batl": [[2, 1.16, 1268]]}, {"timestamp": 1578772582029, "ltp": 1.13, "tv": 37227.66, "trd": NaN, "batb": [[1, 1.12, 3929.2]], "batl": [[1, 1.15, 1542.39], [2, 1.16, 818]]}, {"timestamp": 1578772583002, "ltp": 1.13, "tv": 37227.66, "trd": NaN, "batb": NaN, "batl": [[1, 1.15, 1879.89]]}, {"timestamp": 1578772584033, "ltp": 1.13, "tv": 37227.66, "trd": NaN, "batb": [[0, 1.13, 2244.32]], "batl": NaN}, {"timestamp": 1578772585021, "ltp": 1.13, "tv": 37227.66, "trd": NaN, "batb": [[0, 1.13, 2175.5]], "batl": NaN}, {"timestamp": 1578772586004, "ltp": 1.13, "tv": 37227.66, "trd": NaN, "batb": NaN, "batl": [[0, 1.14, 58215.14]]}, {"timestamp": 1578772587046, "ltp": 1.13, "tv": 37227.66, "trd": NaN, "batb": NaN, "batl": [[0, 1.14, 58556.87]]}, {"timestamp": 1578772590033, "ltp": 1.13, "tv": 37227.66, "trd": NaN, "batb": NaN, "batl": [[1, 1.15, 2329.89]]}, {"timestamp": 1578772593033, "ltp": 1.13, "tv": 37228.1, "trd": [[1.13, 7.93]], "batb": [[0, 1.13, 2175.28]], "batl": NaN}, {"timestamp": 1578772605031, "ltp": 1.13, "tv": 37228.1, "trd": NaN, "batb": [[0, 1.13, 2262.22]], "batl": NaN}, {"timestamp": 1578772605967, "ltp": 1.13, "tv": 37228.1, "trd": NaN, "batb": [[0, 1.13, 927.21]], "batl": NaN}, {"timestamp": 1578772609036, "ltp": 1.13, "tv": 37228.1, "trd": NaN, "batb": NaN, "batl": [[1, 1.15, 1556.89], [2, 1.17, 826.72]]}, {"timestamp": 1578772611983, "ltp": 1.13, "tv": 37228.1, "trd": NaN, "batb": NaN, "batl": [[2, 1.16, 17.02]]}, {"timestamp": 1578772613960, "ltp": 1.13, "tv": 37228.1, "trd": NaN, "batb": [[1, 1.12, 5228.2]], "batl": NaN}, {"timestamp": 1578772618052, "ltp": 1.13, "tv": 37270.66, "trd": [[1.13, 50.49]], "batb": [[0, 1.13, 905.93]], "batl": NaN}, {"timestamp": 1578772621007, "ltp": 1.13, "tv": 37332.72, "trd": [[1.13, 112.55]], "batb": [[0, 1.13, 874.9]], "batl": NaN}, {"timestamp": 1578772622982, "ltp": 1.13, "tv": 37332.72, "trd": NaN, "batb": NaN, "batl": [[1, 1.15, 2375.89], [2, 1.16, 835.02]]}, {"timestamp": 1578772623990, "ltp": 1.13, "tv": 37332.72, "trd": NaN, "batb": [[1, 1.12, 3929.2]], "batl": [[1, 1.15, 1925.89]]}, {"timestamp": 1578772624980, "ltp": 1.13, "tv": 37332.72, "trd": NaN, "batb": [[1, 1.12, 2630.2]], "batl": [[1, 1.15, 1475.89]]}, {"timestamp": 1578772632015, "ltp": 1.13, "tv": 37332.72, "trd": NaN, "batb": [[1, 1.12, 5228.2]], "batl": [[1, 1.15, 2375.89]]}, {"timestamp": 1578772636004, "ltp": 1.13, "tv": 38322.03, "trd": [[1.13, 1101.85]], "batb": [[0, 1.13, 380.25]], "batl": NaN}, {"timestamp": 1578772638985, "ltp": 1.13, "tv": 38339.05, "trd": [[1.13, 1118.87]], "batb": [[0, 1.13, 72.01]], "batl": NaN}, {"timestamp": 1578772639970, "ltp": 1.14, "tv": 38347.67, "trd": [[1.14, 17038.8]], "batb": NaN, "batl": [[0, 1.14, 58552.56]]}, {"timestamp": 1578772642000, "ltp": 1.13, "tv": 38491.68, "trd": [[1.13, 1262.88]], "batb": [[0, 1.12, 5228.2], [1, 1.11, 8247.99], [2, 1.1, 8299.06]], "batl": [[0, 1.13, 28], [1, 1.14, 58552.56], [2, 1.15, 2375.89]]}, {"timestamp": 1578772642998, "ltp": 1.13, "tv": 38491.68, "trd": NaN, "batb": NaN, "batl": [[1, 1.14, 58552.28]]}, {"timestamp": 1578772646995, "ltp": 1.13, "tv": 38519.68, "trd": [[1.13, 1290.88]], "batb": NaN, "batl": [[0, 1.14, 58552.28], [1, 1.15, 2375.89], [2, 1.16, 835.02]]}, {"timestamp": 1578772649011, "ltp": 1.13, "tv": 38519.68, "trd": NaN, "batb": [[0, 1.13, 818], [1, 1.12, 5228.2], [2, 1.11, 8247.99]], "batl": NaN}, {"timestamp": 1578772650004, "ltp": 1.14, "tv": 38565.25, "trd": [[1.14, 17084.38]], "batb": [[1, 1.12, 5266.5]], "batl": [[0, 1.14, 58529.49], [2, 1.16, 856.3]]}, {"timestamp": 1578772650988, "ltp": 1.14, "tv": 38565.25, "trd": NaN, "batb": [[1, 1.12, 5228.2]], "batl": NaN}, {"timestamp": 1578772657034, "ltp": 1.14, "tv": 38565.25, "trd": NaN, "batb": [[0, 1.13, 927.51]], "batl": NaN}, {"timestamp": 1578772658023, "ltp": 1.14, "tv": 38565.25, "trd": NaN, "batb": [[0, 1.13, 948.79]], "batl": NaN}, {"timestamp": 1578772662017, "ltp": 1.13, "tv": 38565.7, "trd": [[1.13, 1291.32]], "batb": [[0, 1.13, 130.57]], "batl": NaN}, {"timestamp": 1578772663009, "ltp": 1.14, "tv": 38577.7, "trd": [[1.14, 17096.38]], "batb": NaN, "batl": [[0, 1.14, 58523.49]]}, {"timestamp": 1578772664014, "ltp": 1.14, "tv": 38577.7, "trd": NaN, "batb": [[0, 1.13, 142.5]], "batl": NaN}, {"timestamp": 1578772666033, "ltp": 1.14, "tv": 38577.7, "trd": NaN, "batb": [[0, 1.13, 121.22]], "batl": [[2, 1.16, 835.02]]}, {"timestamp": 1578772667016, "ltp": 1.14, "tv": 38577.7, "trd": NaN, "batb": [[0, 1.13, 134.52]], "batl": NaN}, {"timestamp": 1578772668012, "ltp": 1.14, "tv": 38577.7, "trd": NaN, "batb": [[2, 1.11, 8850.31]], "batl": NaN}, {"timestamp": 1578772669043, "ltp": 1.14, "tv": 38577.7, "trd": NaN, "batb": NaN, "batl": [[0, 1.14, 59360.49]]}, {"timestamp": 1578772670028, "ltp": 1.14, "tv": 38577.7, "trd": NaN, "batb": [[2, 1.11, 9091.4]], "batl": NaN}, {"timestamp": 1578772671017, "ltp": 1.14, "tv": 38577.7, "trd": NaN, "batb": [[1, 1.12, 5329.2]], "batl": NaN}, {"timestamp": 1578772673046, "ltp": 1.14, "tv": 38577.7, "trd": NaN, "batb": [[1, 1.12, 5350.48]], "batl": [[2, 1.16, 856.3]]}, {"timestamp": 1578772680055, "ltp": 1.13, "tv": 38790.5, "trd": [[1.13, 1504.13]], "batb": [[0, 1.13, 28.12]], "batl": NaN}, {"timestamp": 1578772687020, "ltp": 1.13, "tv": 38790.5, "trd": NaN, "batb": [[0, 1.13, 41.74]], "batl": NaN}, {"timestamp": 1578772692043, "ltp": 1.13, "tv": 38873.98, "trd": [[1.13, 1587.61]], "batb": [[0, 1.12, 5350.48], [1, 1.11, 9091.4], [2, 1.1, 9199.1]], "batl": [[0, 1.13, 38.27], [1, 1.14, 59360.49], [2, 1.15, 2375.89]]}, {"timestamp": 1578772696980, "ltp": 1.13, "tv": 38873.98, "trd": NaN, "batb": NaN, "batl": [[0, 1.13, 45.74]]}, {"timestamp": 1578772699977, "ltp": 1.13, "tv": 38948.89, "trd": [[1.13, 1662.51]], "batb": [[0, 1.12, 5367.5]], "batl": [[0, 1.13, 8.29], [1, 1.14, 59329.06]]}, {"timestamp": 1578772706050, "ltp": 1.13, "tv": 38948.89, "trd": NaN, "batb": NaN, "batl": [[1, 1.14, 58492.06]]}, {"timestamp": 1578772710029, "ltp": 1.13, "tv": 38948.89, "trd": NaN, "batb": NaN, "batl": [[2, 1.15, 1556.89]]}, {"timestamp": 1578772712014, "ltp": 1.13, "tv": 38948.89, "trd": NaN, "batb": [[0, 1.12, 4068.5]], "batl": [[2, 1.15, 1106.89]]}, {"timestamp": 1578772713005, "ltp": 1.13, "tv": 38965.47, "trd": [[1.13, 1679.1]], "batb": NaN, "batl": [[0, 1.14, 58492.06], [1, 1.15, 1106.89], [2, 1.16, 38.3]]}, {"timestamp": 1578772714011, "ltp": 1.13, "tv": 38965.47, "trd": NaN, "batb": NaN, "batl": [[0, 1.14, 58535.7]]}, {"timestamp": 1578772715011, "ltp": 1.13, "tv": 38965.47, "trd": NaN, "batb": NaN, "batl": [[0, 1.14, 58535.32]]}, {"timestamp": 1578772717040, "ltp": 1.13, "tv": 38965.47, "trd": NaN, "batb": [[0, 1.13, 7.66], [1, 1.12, 4068.5], [2, 1.11, 9091.4]], "batl": NaN}, {"timestamp": 1578772717983, "ltp": 1.13, "tv": 38965.47, "trd": NaN, "batb": [[0, 1.12, 4068.5], [1, 1.11, 9091.4], [2, 1.1, 9199.1]], "batl": NaN}, {"timestamp": 1578772718985, "ltp": 1.13, "tv": 38965.47, "trd": NaN, "batb": NaN, "batl": [[2, 1.16, 50.3]]}, {"timestamp": 1578772720992, "ltp": 1.13, "tv": 38965.47, "trd": NaN, "batb": NaN, "batl": [[0, 1.14, 59366.32], [1, 1.15, 1946.89], [2, 1.16, 866.3]]}, {"timestamp": 1578772728034, "ltp": 1.13, "tv": 38965.47, "trd": NaN, "batb": [[0, 1.12, 5367.5]], "batl": [[1, 1.15, 2396.89]]}, {"timestamp": 1578772731023, "ltp": 1.13, "tv": 38965.47, "trd": NaN, "batb": NaN, "batl": [[0, 1.14, 58535.32]]}, {"timestamp": 1578772732012, "ltp": 1.13, "tv": 38965.47, "trd": NaN, "batb": NaN, "batl": [[0, 1.13, 2], [1, 1.14, 58535.32], [2, 1.15, 2396.89]]}, {"timestamp": 1578772738011, "ltp": 1.13, "tv": 38969.47, "trd": [[1.13, 1683.1]], "batb": NaN, "batl": [[0, 1.14, 58535.32], [1, 1.15, 2396.89], [2, 1.16, 866.3]]}, {"timestamp": 1578772739049, "ltp": 1.13, "tv": 38969.47, "trd": NaN, "batb": [[0, 1.12, 5350.48]], "batl": NaN}, {"timestamp": 1578772746006, "ltp": 1.13, "tv": 38969.47, "trd": NaN, "batb": [[0, 1.13, 17.02], [1, 1.12, 5350.48], [2, 1.11, 9091.4]], "batl": [[0, 1.14, 59371.32]]}, {"timestamp": 1578772749029, "ltp": 1.13, "tv": 39003.47, "trd": [[1.13, 1717.1]], "batb": [[0, 1.12, 5350.5], [1, 1.11, 9091.4], [2, 1.1, 9199.1]], "batl": NaN}, {"timestamp": 1578772750021, "ltp": 1.12, "tv": 39080.0, "trd": [[1.12, 76.48], [1.13, 1717.15]], "batb": [[0, 1.12, 5312.24]], "batl": NaN}, {"timestamp": 1578772753040, "ltp": 1.12, "tv": 39156.54, "trd": [[1.12, 153.02]], "batb": [[0, 1.12, 5273.97]], "batl": NaN}, {"timestamp": 1578772754033, "ltp": 1.12, "tv": 39156.54, "trd": NaN, "batb": NaN, "batl": [[2, 1.16, 845.02]]}, {"timestamp": 1578772756022, "ltp": 1.12, "tv": 39156.54, "trd": NaN, "batb": [[0, 1.13, 16.17], [1, 1.12, 5273.97], [2, 1.11, 9091.4]], "batl": NaN}, {"timestamp": 1578772759930, "ltp": 1.12, "tv": 39156.54, "trd": NaN, "batb": NaN, "batl": [[1, 1.15, 2418.17]]}, {"timestamp": 1578772766979, "ltp": 1.13, "tv": 39161.37, "trd": [[1.13, 1721.98]], "batb": [[0, 1.13, 13.76]], "batl": NaN}, {"timestamp": 1578772769051, "ltp": 1.13, "tv": 39161.37, "trd": NaN, "batb": [[2, 1.11, 6540.5]], "batl": NaN}, {"timestamp": 1578772769986, "ltp": 1.13, "tv": 39161.37, "trd": NaN, "batb": NaN, "batl": [[2, 1.16, 1029.24]]}, {"timestamp": 1578772774042, "ltp": 1.13, "tv": 39161.37, "trd": NaN, "batb": [[1, 1.12, 2675.97]], "batl": [[1, 1.15, 1518.17]]}, {"timestamp": 1578772777992, "ltp": 1.13, "tv": 39188.95, "trd": [[1.13, 1749.56]], "batb": [[0, 1.12, 2675.97], [1, 1.11, 6540.5], [2, 1.1, 9199.1]], "batl": [[0, 1.13, 3.2], [1, 1.14, 59371.32], [2, 1.15, 1518.17]]}, {"timestamp": 1578772781050, "ltp": 1.13, "tv": 39192.15, "trd": [[1.13, 1752.76]], "batb": NaN, "batl": [[0, 1.14, 59371.32], [1, 1.15, 1518.17], [2, 1.16, 1029.24]]}, {"timestamp": 1578772784993, "ltp": 1.13, "tv": 39192.15, "trd": NaN, "batb": [[0, 1.12, 2692.99]], "batl": NaN}, {"timestamp": 1578772785988, "ltp": 1.13, "tv": 39192.15, "trd": NaN, "batb": [[0, 1.12, 5290.99]], "batl": [[1, 1.15, 2418.17]]}, {"timestamp": 1578772819047, "ltp": 1.13, "tv": 39192.15, "trd": NaN, "batb": [[0, 1.12, 5269.71]], "batl": NaN}, {"timestamp": 1578772823055, "ltp": 1.13, "tv": 39192.15, "trd": NaN, "batb": NaN, "batl": [[0, 1.13, 8.51], [1, 1.14, 59371.32], [2, 1.15, 2418.17]]}, {"timestamp": 1578772824037, "ltp": 1.12, "tv": 39210.84, "trd": [[1.12, 171.7]], "batb": [[0, 1.12, 5260.37]], "batl": NaN}, {"timestamp": 1578772825038, "ltp": 1.12, "tv": 39210.84, "trd": NaN, "batb": [[1, 1.11, 6561.78]], "batl": NaN}, {"timestamp": 1578772826028, "ltp": 1.12, "tv": 39210.84, "trd": NaN, "batb": NaN, "batl": [[2, 1.15, 1968.17]]}, {"timestamp": 1578772827020, "ltp": 1.12, "tv": 39210.98, "trd": [[1.12, 171.84]], "batb": [[0, 1.12, 5260.3]], "batl": NaN}, {"timestamp": 1578772829046, "ltp": 1.12, "tv": 39210.98, "trd": NaN, "batb": NaN, "batl": [[2, 1.15, 1518.17]]}, {"timestamp": 1578772831028, "ltp": 1.12, "tv": 39210.98, "trd": NaN, "batb": NaN, "batl": [[2, 1.15, 1535.19]]}, {"timestamp": 1578772832960, "ltp": 1.12, "tv": 39226.28, "trd": [[1.12, 187.15]], "batb": [[0, 1.12, 5252.65]], "batl": NaN}, {"timestamp": 1578772834052, "ltp": 1.12, "tv": 39226.28, "trd": NaN, "batb": [[0, 1.12, 5292.65]], "batl": [[1, 1.14, 59821.32]]}, {"timestamp": 1578772835964, "ltp": 1.12, "tv": 39226.28, "trd": NaN, "batb": [[0, 1.12, 4471.22]], "batl": NaN}, {"timestamp": 1578772836959, "ltp": 1.12, "tv": 39226.28, "trd": NaN, "batb": NaN, "batl": [[1, 1.14, 60228.06], [2, 1.15, 891.33]]}, {"timestamp": 1578772838047, "ltp": 1.13, "tv": 39232.51, "trd": [[1.13, 1758.99]], "batb": NaN, "batl": [[0, 1.13, 5.4]]}, {"timestamp": 1578772842055, "ltp": 1.13, "tv": 39232.51, "trd": NaN, "batb": NaN, "batl": [[0, 1.13, 882.4]]}, {"timestamp": 1578772842952, "ltp": 1.13, "tv": 39232.51, "trd": NaN, "batb": NaN, "batl": [[0, 1.13, 1084.39]]}, {"timestamp": 1578772843992, "ltp": 1.13, "tv": 39232.51, "trd": NaN, "batb": NaN, "batl": [[0, 1.13, 1598.84]]}, {"timestamp": 1578772845978, "ltp": 1.13, "tv": 39232.51, "trd": NaN, "batb": [[0, 1.12, 1702.82]], "batl": [[0, 1.13, 1658.42]]}, {"timestamp": 1578772846965, "ltp": 1.13, "tv": 39232.51, "trd": NaN, "batb": [[0, 1.12, 1485.94]], "batl": NaN}, {"timestamp": 1578772847946, "ltp": 1.13, "tv": 39232.56, "trd": [[1.13, 1759.04]], "batb": NaN, "batl": [[0, 1.13, 1658.4]]}, {"timestamp": 1578772848979, "ltp": 1.13, "tv": 39232.56, "trd": NaN, "batb": [[0, 1.12, 719.85]], "batl": NaN}, {"timestamp": 1578772851007, "ltp": 1.13, "tv": 39232.56, "trd": NaN, "batb": NaN, "batl": [[0, 1.13, 1658.78]]}, {"timestamp": 1578772853962, "ltp": 1.13, "tv": 39232.56, "trd": NaN, "batb": [[1, 1.11, 9275.38]], "batl": NaN}, {"timestamp": 1578772858004, "ltp": 1.13, "tv": 39232.56, "trd": NaN, "batb": [[0, 1.12, 642.79]], "batl": NaN}, {"timestamp": 1578772858992, "ltp": 1.12, "tv": 39266.61, "trd": [[1.12, 221.2]], "batb": [[0, 1.12, 625.76]], "batl": NaN}, {"timestamp": 1578772866995, "ltp": 1.12, "tv": 39291.07, "trd": [[1.12, 245.66]], "batb": [[0, 1.12, 613.53]], "batl": NaN}, {"timestamp": 1578772869001, "ltp": 1.12, "tv": 39307.03, "trd": [[1.12, 261.61]], "batb": [[0, 1.12, 357.39]], "batl": NaN}, {"timestamp": 1578772875025, "ltp": 1.12, "tv": 39307.03, "trd": NaN, "batb": [[0, 1.12, 340.36]], "batl": NaN}, {"timestamp": 1578772879036, "ltp": 1.12, "tv": 39307.03, "trd": NaN, "batb": [[2, 1.1, 9304.6]], "batl": NaN}, {"timestamp": 1578772880995, "ltp": 1.12, "tv": 39307.03, "trd": NaN, "batb": [[0, 1.12, 242.05]], "batl": NaN}, {"timestamp": 1578772882045, "ltp": 1.12, "tv": 39307.03, "trd": NaN, "batb": [[1, 1.11, 9292.4]], "batl": NaN}, {"timestamp": 1578772883027, "ltp": 1.12, "tv": 39307.03, "trd": NaN, "batb": NaN, "batl": [[2, 1.15, 1109.83]]}, {"timestamp": 1578772884010, "ltp": 1.12, "tv": 39307.03, "trd": NaN, "batb": [[1, 1.11, 7591.81]], "batl": NaN}, {"timestamp": 1578772885042, "ltp": 1.12, "tv": 39307.03, "trd": NaN, "batb": NaN, "batl": [[2, 1.15, 1088.55]]}, {"timestamp": 1578772886032, "ltp": 1.12, "tv": 39307.03, "trd": NaN, "batb": NaN, "batl": [[1, 1.14, 59778.06], [2, 1.15, 1071.52]]}, {"timestamp": 1578772888004, "ltp": 1.12, "tv": 39308.49, "trd": [[1.12, 263.08]], "batb": [[0, 1.12, 241.32]], "batl": NaN}, {"timestamp": 1578772889049, "ltp": 1.12, "tv": 39308.49, "trd": NaN, "batb": [[1, 1.11, 7350.72]], "batl": NaN}, {"timestamp": 1578772891020, "ltp": 1.12, "tv": 39308.49, "trd": NaN, "batb": NaN, "batl": [[1, 1.14, 59799.34]]}, {"timestamp": 1578772893031, "ltp": 1.12, "tv": 39308.49, "trd": NaN, "batb": NaN, "batl": [[1, 1.14, 59816.37]]}, {"timestamp": 1578772894020, "ltp": 1.12, "tv": 39308.49, "trd": NaN, "batb": NaN, "batl": [[0, 1.13, 2103.41]]}, {"timestamp": 1578772896043, "ltp": 1.12, "tv": 39414.92, "trd": [[1.12, 369.51]], "batb": [[0, 1.12, 188.11]], "batl": NaN}, {"timestamp": 1578772898031, "ltp": 1.12, "tv": 39414.92, "trd": NaN, "batb": [[1, 1.11, 5993.92]], "batl": [[0, 1.13, 1653.41]]}, {"timestamp": 1578772899022, "ltp": 1.12, "tv": 39414.92, "trd": NaN, "batb": [[1, 1.11, 6004.14]], "batl": NaN}, {"timestamp": 1578772902049, "ltp": 1.12, "tv": 39414.92, "trd": NaN, "batb": [[2, 1.1, 9307.1]], "batl": NaN}, {"timestamp": 1578772913047, "ltp": 1.12, "tv": 39414.92, "trd": NaN, "batb": [[0, 1.12, 230.67], [1, 1.11, 4647.34]], "batl": [[1, 1.14, 59366.37]]}, {"timestamp": 1578772914973, "ltp": 1.12, "tv": 39414.92, "trd": NaN, "batb": [[1, 1.11, 4650.74]], "batl": NaN}, {"timestamp": 1578772920969, "ltp": 1.12, "tv": 39414.92, "trd": NaN, "batb": [[1, 1.11, 6007.54]], "batl": [[1, 1.14, 59816.37]]}, {"timestamp": 1578772921967, "ltp": 1.12, "tv": 39414.92, "trd": NaN, "batb": [[2, 1.1, 10730.1]], "batl": [[0, 1.13, 1765.91]]}, {"timestamp": 1578772922971, "ltp": 1.12, "tv": 39414.92, "trd": NaN, "batb": NaN, "batl": [[0, 1.13, 2103.41]]}, {"timestamp": 1578772925973, "ltp": 1.12, "tv": 39414.92, "trd": NaN, "batb": NaN, "batl": [[1, 1.14, 59366.37]]}, {"timestamp": 1578772929989, "ltp": 1.12, "tv": 39414.92, "trd": NaN, "batb": [[1, 1.11, 5827.54]], "batl": NaN}, {"timestamp": 1578772930999, "ltp": 1.12, "tv": 39414.92, "trd": NaN, "batb": [[1, 1.11, 4470.74]], "batl": NaN}, {"timestamp": 1578772931985, "ltp": 1.12, "tv": 39414.92, "trd": NaN, "batb": [[1, 1.11, 4361.66]], "batl": NaN}, {"timestamp": 1578772937979, "ltp": 1.12, "tv": 39414.92, "trd": NaN, "batb": [[1, 1.11, 5225.22]], "batl": NaN}, {"timestamp": 1578772938980, "ltp": 1.12, "tv": 39535.29, "trd": [[1.12, 489.88]], "batb": [[0, 1.12, 170.48]], "batl": [[0, 1.13, 1226.41], [1, 1.14, 58530.37]]}, {"timestamp": 1578772939966, "ltp": 1.12, "tv": 39563.96, "trd": [[1.12, 518.55]], "batb": [[0, 1.12, 156.14], [1, 1.11, 5203.94]], "batl": NaN}, {"timestamp": 1578772941009, "ltp": 1.12, "tv": 39563.96, "trd": NaN, "batb": NaN, "batl": [[1, 1.14, 58980.37]]}, {"timestamp": 1578772946028, "ltp": 1.12, "tv": 39567.7, "trd": [[1.12, 522.29]], "batb": [[0, 1.12, 154.27]], "batl": [[1, 1.14, 58530.37]]}, {"timestamp": 1578772947005, "ltp": 1.12, "tv": 39567.7, "trd": NaN, "batb": [[2, 1.1, 10751.39]], "batl": NaN}, {"timestamp": 1578772950045, "ltp": 1.12, "tv": 39567.7, "trd": NaN, "batb": [[1, 1.11, 3847.14], [2, 1.1, 9328.39]], "batl": [[0, 1.13, 776.41]]}, {"timestamp": 1578772952965, "ltp": 1.12, "tv": 39605.08, "trd": [[1.12, 559.67]], "batb": [[0, 1.12, 135.58]], "batl": NaN}, {"timestamp": 1578772955055, "ltp": 1.12, "tv": 39605.08, "trd": NaN, "batb": [[1, 1.11, 2996.84]], "batl": NaN}, {"timestamp": 1578772956048, "ltp": 1.12, "tv": 39608.82, "trd": [[1.12, 563.41]], "batb": [[0, 1.12, 133.71]], "batl": NaN}, {"timestamp": 1578772957937, "ltp": 1.12, "tv": 39608.82, "trd": NaN, "batb": [[0, 1.12, 229.05]], "batl": NaN}, {"timestamp": 1578772959024, "ltp": 1.12, "tv": 39608.82, "trd": NaN, "batb": [[2, 1.1, 5927.19]], "batl": NaN}, {"timestamp": 1578772963973, "ltp": 1.12, "tv": 39608.82, "trd": NaN, "batb": [[1, 1.11, 2101.84]], "batl": NaN}, {"timestamp": 1578772967046, "ltp": 1.12, "tv": 39619.7, "trd": [[1.12, 574.28]], "batb": [[0, 1.12, 223.61]], "batl": NaN}, {"timestamp": 1578772968969, "ltp": 1.13, "tv": 39685.7, "trd": [[1.13, 1825.04]], "batb": NaN, "batl": [[0, 1.13, 743.41]]}, {"timestamp": 1578772971051, "ltp": 1.12, "tv": 39695.7, "trd": [[1.12, 584.28]], "batb": [[0, 1.12, 218.61]], "batl": NaN}, {"timestamp": 1578772979993, "ltp": 1.13, "tv": 42480.15, "trd": [[1.12, 584.51], [1.13, 4609.27]], "batb": [[0, 1.12, 218.5]], "batl": [[0, 1.14, 58530.37], [1, 1.15, 1071.52], [2, 1.16, 343.04]]}, {"timestamp": 1578772984997, "ltp": 1.13, "tv": 42480.15, "trd": NaN, "batb": NaN, "batl": [[0, 1.14, 58750.12]]}, {"timestamp": 1578772986041, "ltp": 1.12, "tv": 42758.86, "trd": [[1.12, 863.21]], "batb": [[0, 1.11, 2101.84], [1, 1.1, 5927.19], [2, 1.09, 9436.5]], "batl": [[0, 1.12, 776.79], [1, 1.13, 804], [2, 1.14, 59548.12]]}, {"timestamp": 1578772986980, "ltp": 1.12, "tv": 42758.86, "trd": NaN, "batb": [[0, 1.11, 1922.51]], "batl": [[2, 1.14, 59270.16]]}, {"timestamp": 1578772987976, "ltp": 1.12, "tv": 43370.58, "trd": [[1.12, 1474.94]], "batb": NaN, "batl": [[0, 1.12, 470.93], [1, 1.13, 1334.47], [2, 1.14, 59206.39]]}, {"timestamp": 1578772989014, "ltp": 1.12, "tv": 43370.58, "trd": NaN, "batb": [[0, 1.11, 1156.43], [1, 1.1, 8773.19]], "batl": [[0, 1.13, 1784.47], [1, 1.14, 59206.39], [2, 1.15, 1071.52]]}, {"timestamp": 1578772991042, "ltp": 1.12, "tv": 43370.58, "trd": NaN, "batb": NaN, "batl": [[1, 1.14, 58892.79]]}, {"timestamp": 1578772993016, "ltp": 1.11, "tv": 43389.04, "trd": [[1.11, 18.46]], "batb": [[0, 1.11, 1147.2]], "batl": [[0, 1.13, 1871.41]]}, {"timestamp": 1578772994020, "ltp": 1.11, "tv": 43389.04, "trd": NaN, "batb": NaN, "batl": [[0, 1.12, 328.12], [1, 1.13, 1940.22], [2, 1.14, 58892.79]]}, {"timestamp": 1578772994999, "ltp": 1.11, "tv": 43389.04, "trd": NaN, "batb": NaN, "batl": [[0, 1.12, 405.97]]}, {"timestamp": 1578772996002, "ltp": 1.11, "tv": 43389.04, "trd": NaN, "batb": [[0, 1.11, 1969.2]], "batl": NaN}, {"timestamp": 1578772996888, "ltp": 1.11, "tv": 43389.04, "trd": NaN, "batb": [[0, 1.11, 1382.58]], "batl": [[1, 1.13, 2390.22]]}, {"timestamp": 1578772997984, "ltp": 1.11, "tv": 43389.04, "trd": NaN, "batb": NaN, "batl": [[0, 1.12, 725.17]]}, {"timestamp": 1578773002031, "ltp": 1.11, "tv": 43389.04, "trd": NaN, "batb": NaN, "batl": [[0, 1.12, 766.32]]}, {"timestamp": 1578773003022, "ltp": 1.11, "tv": 47650.42, "trd": [[1.11, 4279.84]], "batb": [[0, 1.1, 8773.19], [1, 1.09, 9436.5], [2, 1.08, 9590.41]], "batl": [[0, 1.11, 121.2], [1, 1.12, 775.46], [2, 1.13, 2390.22]]}, {"timestamp": 1578773005049, "ltp": 1.11, "tv": 47650.42, "trd": NaN, "batb": NaN, "batl": [[0, 1.11, 130.43]]}, {"timestamp": 1578773006042, "ltp": 1.11, "tv": 47650.42, "trd": NaN, "batb": NaN, "batl": [[1, 1.12, 800.24]]}, {"timestamp": 1578773007999, "ltp": 1.11, "tv": 47650.5, "trd": [[1.11, 4279.92]], "batb": NaN, "batl": [[0, 1.11, 130.35]]}, {"timestamp": 1578773009035, "ltp": 1.11, "tv": 47650.74, "trd": [[1.11, 4280.16]], "batb": NaN, "batl": [[0, 1.11, 130.11], [1, 1.12, 775.46]]}, {"timestamp": 1578773010021, "ltp": 1.11, "tv": 47780.85, "trd": [[1.11, 4410.26]], "batb": NaN, "batl": [[0, 1.12, 1627.46], [1, 1.13, 2390.22], [2, 1.14, 58875.76]]}, {"timestamp": 1578773011009, "ltp": 1.11, "tv": 47924.7, "trd": [[1.11, 4554.12]], "batb": NaN, "batl": NaN}, {"timestamp": 1578773012041, "ltp": 1.11, "tv": 47924.7, "trd": NaN, "batb": NaN, "batl": [[0, 1.12, 1595.45]]}, {"timestamp": 1578773013035, "ltp": 1.11, "tv": 47924.7, "trd": NaN, "batb": [[0, 1.1, 8804.9]], "batl": NaN}, {"timestamp": 1578773016042, "ltp": 1.11, "tv": 47949.47, "trd": [[1.11, 4578.89]], "batb": [[0, 1.1, 8773.19]], "batl": [[2, 1.14, 58960.89]]}, {"timestamp": 1578773017030, "ltp": 1.11, "tv": 47949.47, "trd": NaN, "batb": NaN, "batl": [[0, 1.12, 1586.31]]}, {"timestamp": 1578773017914, "ltp": 1.11, "tv": 47949.47, "trd": NaN, "batb": [[0, 1.1, 8790.22]], "batl": [[0, 1.12, 1577.17]]}, {"timestamp": 1578773019054, "ltp": 1.11, "tv": 47981.48, "trd": [[1.11, 4610.9]], "batb": NaN, "batl": NaN}, {"timestamp": 1578773020022, "ltp": 1.11, "tv": 47981.48, "trd": NaN, "batb": [[0, 1.1, 8790.39]], "batl": NaN}, {"timestamp": 1578773021056, "ltp": 1.11, "tv": 47981.48, "trd": NaN, "batb": [[2, 1.08, 9590.5]], "batl": NaN}, {"timestamp": 1578773022047, "ltp": 1.11, "tv": 47981.48, "trd": NaN, "batb": [[2, 1.08, 9590.58]], "batl": NaN}, {"timestamp": 1578773023039, "ltp": 1.11, "tv": 47981.48, "trd": NaN, "batb": [[0, 1.11, 24.78], [1, 1.1, 8790.39], [2, 1.09, 9436.5]], "batl": [[2, 1.14, 58939.61]]}, {"timestamp": 1578773025023, "ltp": 1.11, "tv": 48040.26, "trd": [[1.11, 4669.68]], "batb": [[0, 1.1, 8790.39], [1, 1.09, 9436.5], [2, 1.08, 9590.67]], "batl": [[0, 1.12, 1633.23]]}, {"timestamp": 1578773027959, "ltp": 1.11, "tv": 48040.26, "trd": NaN, "batb": [[0, 1.1, 8790.56]], "batl": NaN}, {"timestamp": 1578773030047, "ltp": 1.11, "tv": 48040.26, "trd": NaN, "batb": [[1, 1.09, 9436.59], [2, 1.08, 9590.75]], "batl": [[1, 1.13, 2411.5]]}, {"timestamp": 1578773031963, "ltp": 1.11, "tv": 48040.26, "trd": NaN, "batb": NaN, "batl": [[2, 1.14, 58854.48]]}, {"timestamp": 1578773032948, "ltp": 1.11, "tv": 48040.26, "trd": NaN, "batb": NaN, "batl": [[0, 1.12, 1577.17]]}, {"timestamp": 1578773033947, "ltp": 1.11, "tv": 48040.58, "trd": [[1.11, 4670]], "batb": [[0, 1.1, 8790.47]], "batl": [[0, 1.12, 1577.71], [2, 1.14, 59854.48]]}, {"timestamp": 1578773035049, "ltp": 1.11, "tv": 48041.12, "trd": [[1.11, 4670.54]], "batb": NaN, "batl": [[0, 1.12, 1577.17]]}, {"timestamp": 1578773038964, "ltp": 1.11, "tv": 48041.12, "trd": NaN, "batb": NaN, "batl": [[1, 1.13, 2496.62]]}, {"timestamp": 1578773045981, "ltp": 1.11, "tv": 48041.12, "trd": NaN, "batb": NaN, "batl": [[1, 1.13, 2046.62]]}, {"timestamp": 1578773052977, "ltp": 1.11, "tv": 48041.12, "trd": NaN, "batb": NaN, "batl": [[0, 1.11, 24.78], [1, 1.12, 1577.17], [2, 1.13, 2046.62]]}, {"timestamp": 1578773053979, "ltp": 1.11, "tv": 48041.12, "trd": NaN, "batb": NaN, "batl": [[1, 1.12, 2027.17]]}, {"timestamp": 1578773062998, "ltp": 1.1, "tv": 48141.12, "trd": [[1.1, 100]], "batb": [[0, 1.1, 8740.47]], "batl": NaN}, {"timestamp": 1578773063994, "ltp": 1.1, "tv": 48164.09, "trd": [[1.1, 122.96]], "batb": [[0, 1.1, 8728.99]], "batl": NaN}, {"timestamp": 1578773066986, "ltp": 1.1, "tv": 48264.09, "trd": [[1.1, 222.96]], "batb": [[0, 1.1, 8678.99]], "batl": NaN}, {"timestamp": 1578773067980, "ltp": 1.1, "tv": 48264.09, "trd": NaN, "batb": NaN, "batl": [[0, 1.11, 62.15]]}, {"timestamp": 1578773071992, "ltp": 1.1, "tv": 48264.09, "trd": NaN, "batb": NaN, "batl": [[0, 1.11, 79.17]]}, {"timestamp": 1578773072984, "ltp": 1.1, "tv": 48266.02, "trd": [[1.1, 224.89]], "batb": [[0, 1.1, 8678.03]], "batl": NaN}, {"timestamp": 1578773075021, "ltp": 1.1, "tv": 48266.02, "trd": NaN, "batb": NaN, "batl": [[0, 1.11, 189.65]]}, {"timestamp": 1578773076019, "ltp": 1.1, "tv": 48266.02, "trd": NaN, "batb": NaN, "batl": [[0, 1.11, 321.41]]}, {"timestamp": 1578773076998, "ltp": 1.1, "tv": 48266.02, "trd": NaN, "batb": NaN, "batl": [[2, 1.13, 1890.87]]}, {"timestamp": 1578773079992, "ltp": 1.1, "tv": 48274.53, "trd": [[1.1, 233.4]], "batb": [[0, 1.1, 8673.77]], "batl": NaN}, {"timestamp": 1578773083986, "ltp": 1.1, "tv": 48274.53, "trd": NaN, "batb": NaN, "batl": [[0, 1.11, 514.68]]}, {"timestamp": 1578773087026, "ltp": 1.1, "tv": 48274.53, "trd": NaN, "batb": [[0, 1.1, 8652.49]], "batl": [[2, 1.13, 1869.59]]}, {"timestamp": 1578773090024, "ltp": 1.1, "tv": 48274.53, "trd": NaN, "batb": NaN, "batl": [[2, 1.13, 1346.78]]}, {"timestamp": 1578773094025, "ltp": 1.11, "tv": 48275.41, "trd": [[1.11, 4671.42]], "batb": [[1, 1.09, 9457.87]], "batl": [[0, 1.11, 514.24], [2, 1.13, 1368.06]]}, {"timestamp": 1578773097002, "ltp": 1.11, "tv": 48275.41, "trd": NaN, "batb": NaN, "batl": [[0, 1.11, 984.91]]}, {"timestamp": 1578773103951, "ltp": 1.11, "tv": 48275.41, "trd": NaN, "batb": NaN, "batl": [[2, 1.13, 2368.06]]}, {"timestamp": 1578773104955, "ltp": 1.11, "tv": 48275.41, "trd": NaN, "batb": [[0, 1.1, 7229.49]], "batl": [[0, 1.11, 510.8], [1, 1.12, 1577.17]]}, {"timestamp": 1578773106023, "ltp": 1.11, "tv": 48275.41, "trd": NaN, "batb": [[0, 1.1, 5806.49]], "batl": [[2, 1.13, 1918.06]]}, {"timestamp": 1578773109031, "ltp": 1.11, "tv": 48275.41, "trd": NaN, "batb": [[0, 1.1, 4105.89]], "batl": NaN}, {"timestamp": 1578773110035, "ltp": 1.11, "tv": 48275.41, "trd": NaN, "batb": [[0, 1.1, 3339.8]], "batl": NaN}, {"timestamp": 1578773111971, "ltp": 1.11, "tv": 48275.41, "trd": NaN, "batb": [[1, 1.09, 10957.87]], "batl": [[1, 1.12, 1689.67]]}, {"timestamp": 1578773113031, "ltp": 1.11, "tv": 48275.41, "trd": NaN, "batb": NaN, "batl": [[1, 1.12, 2027.17]]}, {"timestamp": 1578773114039, "ltp": 1.11, "tv": 48275.41, "trd": NaN, "batb": [[0, 1.1, 4762.8]], "batl": [[2, 1.13, 2368.06]]}, {"timestamp": 1578773118036, "ltp": 1.11, "tv": 48275.41, "trd": NaN, "batb": NaN, "batl": [[2, 1.13, 2595.56]]}, {"timestamp": 1578773120032, "ltp": 1.11, "tv": 48275.41, "trd": NaN, "batb": NaN, "batl": [[0, 1.11, 1080.26]]}, {"timestamp": 1578773122027, "ltp": 1.1, "tv": 48279.41, "trd": [[1.1, 237.4]], "batb": [[0, 1.1, 4760.8]], "batl": NaN}, {"timestamp": 1578773124964, "ltp": 1.1, "tv": 48279.41, "trd": NaN, "batb": NaN, "batl": [[0, 1.11, 1042.89]]}, {"timestamp": 1578773125964, "ltp": 1.1, "tv": 48279.41, "trd": NaN, "batb": NaN, "batl": [[2, 1.13, 2145.56]]}, {"timestamp": 1578773131979, "ltp": 1.1, "tv": 48354.15, "trd": [[1.1, 312.14]], "batb": [[0, 1.1, 4723.44]], "batl": NaN}, {"timestamp": 1578773133007, "ltp": 1.1, "tv": 48354.15, "trd": NaN, "batb": NaN, "batl": [[1, 1.12, 2477.17]]}, {"timestamp": 1578773136980, "ltp": 1.1, "tv": 48354.15, "trd": NaN, "batb": NaN, "batl": [[0, 1.11, 1340.81]]}, {"timestamp": 1578773143859, "ltp": 1.1, "tv": 48354.15, "trd": NaN, "batb": [[0, 1.1, 3884.44]], "batl": NaN}, {"timestamp": 1578773148016, "ltp": 1.1, "tv": 48354.15, "trd": NaN, "batb": NaN, "batl": [[0, 1.11, 2199.81]]}, {"timestamp": 1578773153007, "ltp": 1.1, "tv": 48354.15, "trd": NaN, "batb": NaN, "batl": [[0, 1.11, 2284.93]]}, {"timestamp": 1578773154013, "ltp": 1.1, "tv": 48354.15, "trd": NaN, "batb": [[0, 1.1, 3627.28]], "batl": NaN}, {"timestamp": 1578773155014, "ltp": 1.1, "tv": 48354.15, "trd": NaN, "batb": [[0, 1.1, 2204.28]], "batl": [[0, 1.11, 1425.93], [1, 1.12, 1625.17]]}, {"timestamp": 1578773157012, "ltp": 1.1, "tv": 48354.15, "trd": NaN, "batb": [[0, 1.1, 2056.24]], "batl": NaN}, {"timestamp": 1578773160021, "ltp": 1.1, "tv": 48354.15, "trd": NaN, "batb": [[0, 1.1, 1857.22]], "batl": [[2, 1.13, 2060.44]]}, {"timestamp": 1578773161020, "ltp": 1.1, "tv": 48354.15, "trd": NaN, "batb": NaN, "batl": [[2, 1.13, 2039.16]]}, {"timestamp": 1578773162018, "ltp": 1.1, "tv": 48354.15, "trd": NaN, "batb": [[0, 1.1, 1362.37], [1, 1.09, 12457.87]], "batl": NaN}, {"timestamp": 1578773167010, "ltp": 1.1, "tv": 48354.15, "trd": NaN, "batb": [[1, 1.09, 12474.89]], "batl": [[1, 1.12, 1710.29]]}, {"timestamp": 1578773168004, "ltp": 1.1, "tv": 48354.15, "trd": NaN, "batb": NaN, "batl": [[1, 1.12, 1731.57]]}, {"timestamp": 1578773170013, "ltp": 1.1, "tv": 48354.15, "trd": NaN, "batb": [[0, 1.1, 1220.51]], "batl": NaN}, {"timestamp": 1578773171039, "ltp": 1.1, "tv": 48354.15, "trd": NaN, "batb": [[0, 1.1, 1042.2]], "batl": NaN}, {"timestamp": 1578773173044, "ltp": 1.1, "tv": 48354.15, "trd": NaN, "batb": [[0, 1.1, 935.8]], "batl": NaN}, {"timestamp": 1578773174954, "ltp": 1.1, "tv": 48354.15, "trd": NaN, "batb": NaN, "batl": [[0, 1.11, 2374.93], [1, 1.12, 2614.57]]}, {"timestamp": 1578773176011, "ltp": 1.1, "tv": 48354.15, "trd": NaN, "batb": [[0, 1.1, 637.88]], "batl": [[0, 1.11, 2289.81]]}, {"timestamp": 1578773177037, "ltp": 1.1, "tv": 48354.15, "trd": NaN, "batb": [[0, 1.1, 365.41], [1, 1.09, 10974.89]], "batl": [[0, 1.11, 1991.89], [1, 1.12, 2164.57]]}, {"timestamp": 1578773178044, "ltp": 1.1, "tv": 48354.15, "trd": NaN, "batb": NaN, "batl": [[0, 1.11, 1881.41], [1, 1.12, 1714.57]]}, {"timestamp": 1578773179040, "ltp": 1.1, "tv": 48524.39, "trd": [[1.1, 482.39]], "batb": [[0, 1.1, 280.28]], "batl": NaN}, {"timestamp": 1578773180047, "ltp": 1.1, "tv": 48912.59, "trd": [[1.1, 870.59]], "batb": [[0, 1.1, 86.19]], "batl": [[0, 1.11, 1770.93]]}, {"timestamp": 1578773185050, "ltp": 1.1, "tv": 48912.59, "trd": NaN, "batb": [[2, 1.08, 11181.75]], "batl": [[0, 1.11, 2670.93]]}, {"timestamp": 1578773187049, "ltp": 1.1, "tv": 48943.21, "trd": [[1.1, 901.2]], "batb": [[0, 1.1, 70.88]], "batl": NaN}, {"timestamp": 1578773189041, "ltp": 1.1, "tv": 48943.21, "trd": NaN, "batb": [[0, 1.1, 184.41]], "batl": NaN}, {"timestamp": 1578773200976, "ltp": 1.1, "tv": 48943.21, "trd": NaN, "batb": [[1, 1.09, 10699.37]], "batl": NaN}, {"timestamp": 1578773214968, "ltp": 1.1, "tv": 48943.21, "trd": NaN, "batb": [[0, 1.1, 70.88]], "batl": NaN}, {"timestamp": 1578773218989, "ltp": 1.1, "tv": 48943.21, "trd": NaN, "batb": NaN, "batl": [[1, 1.12, 2714.57]]}, {"timestamp": 1578773225997, "ltp": 1.1, "tv": 48943.21, "trd": NaN, "batb": NaN, "batl": [[1, 1.12, 2947.28]]}, {"timestamp": 1578773231996, "ltp": 1.1, "tv": 48943.21, "trd": NaN, "batb": NaN, "batl": [[1, 1.12, 2714.57]]}, {"timestamp": 1578773245001, "ltp": 1.1, "tv": 48943.21, "trd": NaN, "batb": [[1, 1.09, 9199.37]], "batl": [[0, 1.11, 2220.93]]}, {"timestamp": 1578773247997, "ltp": 1.1, "tv": 48943.21, "trd": NaN, "batb": [[1, 1.09, 9197.37], [2, 1.08, 11179.75]], "batl": [[2, 1.13, 1811.66]]}, {"timestamp": 1578773249001, "ltp": 1.1, "tv": 48943.21, "trd": NaN, "batb": NaN, "batl": [[1, 1.12, 2629.45]]}, {"timestamp": 1578773256045, "ltp": 1.1, "tv": 48943.21, "trd": NaN, "batb": NaN, "batl": [[0, 1.11, 2306.05]]}, {"timestamp": 1578773257998, "ltp": 1.1, "tv": 48943.21, "trd": NaN, "batb": [[1, 1.09, 9216.1]], "batl": NaN}, {"timestamp": 1578773259005, "ltp": 1.1, "tv": 48943.21, "trd": NaN, "batb": [[2, 1.08, 12770.75]], "batl": [[0, 1.11, 2418.55]]}, {"timestamp": 1578773260055, "ltp": 1.1, "tv": 48943.21, "trd": NaN, "batb": NaN, "batl": [[0, 1.11, 2756.05]]}, {"timestamp": 1578773260917, "ltp": 1.1, "tv": 48943.21, "trd": NaN, "batb": [[2, 1.08, 12812.85]], "batl": NaN}, {"timestamp": 1578773272051, "ltp": 1.1, "tv": 48943.21, "trd": NaN, "batb": [[1, 1.09, 4114.3]], "batl": NaN}, {"timestamp": 1578773273020, "ltp": 1.1, "tv": 48943.21, "trd": NaN, "batb": [[1, 1.09, 4097.28]], "batl": NaN}, {"timestamp": 1578773273949, "ltp": 1.1, "tv": 48943.21, "trd": NaN, "batb": [[1, 1.09, 3408.47]], "batl": NaN}, {"timestamp": 1578773276957, "ltp": 1.1, "tv": 48975.55, "trd": [[1.1, 933.55]], "batb": [[0, 1.1, 54.71]], "batl": NaN}, {"timestamp": 1578773277963, "ltp": 1.1, "tv": 48975.55, "trd": NaN, "batb": [[1, 1.09, 2518.47]], "batl": NaN}, {"timestamp": 1578773279971, "ltp": 1.1, "tv": 48975.55, "trd": NaN, "batb": [[2, 1.08, 12829.87]], "batl": NaN}, {"timestamp": 1578773280971, "ltp": 1.1, "tv": 49030.25, "trd": [[1.1, 988.25]], "batb": [[0, 1.09, 2518.47], [1, 1.08, 12829.87], [2, 1.07, 13267.03]], "batl": [[0, 1.1, 1016], [1, 1.11, 2756.05], [2, 1.12, 1982.13]]}, {"timestamp": 1578773282044, "ltp": 1.1, "tv": 49030.25, "trd": NaN, "batb": NaN, "batl": [[1, 1.11, 2734.77], [2, 1.12, 1904.28]]}, {"timestamp": 1578773283055, "ltp": 1.1, "tv": 49030.25, "trd": NaN, "batb": [[0, 1.09, 1569.38]], "batl": [[0, 1.1, 1019.06]]}, {"timestamp": 1578773283966, "ltp": 1.1, "tv": 49030.25, "trd": NaN, "batb": NaN, "batl": [[1, 1.11, 3734.77]]}, {"timestamp": 1578773285965, "ltp": 1.1, "tv": 49030.25, "trd": NaN, "batb": [[0, 1.09, 1462.98]], "batl": NaN}, {"timestamp": 1578773286973, "ltp": 1.1, "tv": 49030.25, "trd": NaN, "batb": NaN, "batl": [[1, 1.11, 3710.43]]}, {"timestamp": 1578773287982, "ltp": 1.1, "tv": 49030.25, "trd": NaN, "batb": NaN, "batl": [[0, 1.1, 1720.01]]}, {"timestamp": 1578773289043, "ltp": 1.1, "tv": 49030.25, "trd": NaN, "batb": [[0, 1.09, 867.13]], "batl": [[0, 1.1, 1833.98]]}, {"timestamp": 1578773289989, "ltp": 1.1, "tv": 49030.25, "trd": NaN, "batb": [[0, 1.09, 737.1]], "batl": NaN}, {"timestamp": 1578773292017, "ltp": 1.1, "tv": 49030.25, "trd": NaN, "batb": [[0, 1.09, 738.8], [1, 1.08, 11238.87]], "batl": [[1, 1.11, 2810.43]]}, {"timestamp": 1578773293982, "ltp": 1.1, "tv": 49030.25, "trd": NaN, "batb": NaN, "batl": [[0, 1.1, 1858.32]]}, {"timestamp": 1578773298992, "ltp": 1.1, "tv": 49030.25, "trd": NaN, "batb": [[1, 1.08, 12829.87]], "batl": [[0, 1.1, 1970.82]]}, {"timestamp": 1578773299988, "ltp": 1.1, "tv": 49030.25, "trd": NaN, "batb": NaN, "batl": [[0, 1.1, 2758.32]]}, {"timestamp": 1578773303990, "ltp": 1.1, "tv": 49030.25, "trd": NaN, "batb": [[0, 1.09, 717.52]], "batl": NaN}, {"timestamp": 1578773306978, "ltp": 1.09, "tv": 49210.25, "trd": [[1.09, 2240.21]], "batb": [[0, 1.09, 627.52], [1, 1.08, 12831.57]], "batl": NaN}, {"timestamp": 1578773308025, "ltp": 1.09, "tv": 49210.25, "trd": NaN, "batb": [[0, 1.09, 321.34]], "batl": NaN}, {"timestamp": 1578773310002, "ltp": 1.09, "tv": 49210.25, "trd": NaN, "batb": [[0, 1.09, 221.34]], "batl": NaN}, {"timestamp": 1578773310995, "ltp": 1.09, "tv": 49210.25, "trd": NaN, "batb": [[0, 1.09, 169.48], [1, 1.08, 12852.85]], "batl": NaN}, {"timestamp": 1578773311985, "ltp": 1.09, "tv": 49210.25, "trd": NaN, "batb": [[0, 1.09, 52.22]], "batl": NaN}, {"timestamp": 1578773318985, "ltp": 1.09, "tv": 49210.25, "trd": NaN, "batb": [[0, 1.09, 20.51]], "batl": NaN}, {"timestamp": 1578773320027, "ltp": 1.09, "tv": 49210.25, "trd": NaN, "batb": [[2, 1.07, 13268.73]], "batl": NaN}, {"timestamp": 1578773327997, "ltp": 1.09, "tv": 49210.25, "trd": NaN, "batb": NaN, "batl": [[2, 1.12, 1883]]}, {"timestamp": 1578773335037, "ltp": 1.09, "tv": 49210.25, "trd": NaN, "batb": NaN, "batl": [[1, 1.11, 2831.71]]}, {"timestamp": 1578773341027, "ltp": 1.09, "tv": 49210.25, "trd": NaN, "batb": NaN, "batl": [[0, 1.1, 2737.04]]}, {"timestamp": 1578773343023, "ltp": 1.09, "tv": 49210.25, "trd": NaN, "batb": NaN, "batl": [[0, 1.1, 2830.47], [1, 1.11, 2509.63]]}, {"timestamp": 1578773344012, "ltp": 1.09, "tv": 49210.25, "trd": NaN, "batb": NaN, "batl": [[1, 1.11, 2072.43]]}, {"timestamp": 1578773347957, "ltp": 1.09, "tv": 49251.28, "trd": [[1.09, 2281.24]], "batb": [[0, 1.08, 12852.85], [1, 1.07, 13268.73], [2, 1.06, 12747.67]], "batl": [[0, 1.1, 2806.9]]}, {"timestamp": 1578773349955, "ltp": 1.09, "tv": 49251.28, "trd": NaN, "batb": NaN, "batl": [[0, 1.09, 40.57], [1, 1.1, 2806.13], [2, 1.11, 2072.43]]}, {"timestamp": 1578773351022, "ltp": 1.09, "tv": 49251.28, "trd": NaN, "batb": NaN, "batl": [[0, 1.09, 78.92]]}, {"timestamp": 1578773354966, "ltp": 1.09, "tv": 49251.28, "trd": NaN, "batb": NaN, "batl": [[0, 1.09, 95.95]]}, {"timestamp": 1578773356946, "ltp": 1.09, "tv": 49251.28, "trd": NaN, "batb": [[0, 1.08, 12667.85]], "batl": NaN}, {"timestamp": 1578773360041, "ltp": 1.09, "tv": 49261.28, "trd": [[1.09, 2291.24]], "batb": NaN, "batl": [[0, 1.09, 90.95]]}, {"timestamp": 1578773364964, "ltp": 1.08, "tv": 49262.74, "trd": [[1.08, 5596.01]], "batb": [[0, 1.08, 12667.12]], "batl": NaN}, {"timestamp": 1578773366043, "ltp": 1.08, "tv": 49262.74, "trd": NaN, "batb": NaN, "batl": [[0, 1.09, 115.29]]}, {"timestamp": 1578773368041, "ltp": 1.08, "tv": 49262.74, "trd": NaN, "batb": [[0, 1.08, 12072.01]], "batl": NaN}, {"timestamp": 1578773374963, "ltp": 1.08, "tv": 49262.74, "trd": NaN, "batb": [[0, 1.08, 6970.22], [1, 1.07, 13270.73], [2, 1.06, 12749.67]], "batl": NaN}, {"timestamp": 1578773375950, "ltp": 1.08, "tv": 49262.74, "trd": NaN, "batb": [[0, 1.08, 6983.92]], "batl": NaN}, {"timestamp": 1578773377000, "ltp": 1.08, "tv": 49262.74, "trd": NaN, "batb": [[0, 1.08, 6970.22]], "batl": NaN}, {"timestamp": 1578773380995, "ltp": 1.08, "tv": 49262.74, "trd": NaN, "batb": NaN, "batl": [[2, 1.11, 1987.3]]}, {"timestamp": 1578773382999, "ltp": 1.08, "tv": 49262.74, "trd": NaN, "batb": [[0, 1.08, 6603.8]], "batl": NaN}, {"timestamp": 1578773384005, "ltp": 1.08, "tv": 49262.74, "trd": NaN, "batb": [[0, 1.08, 5719.8]], "batl": NaN}, {"timestamp": 1578773386004, "ltp": 1.08, "tv": 49262.74, "trd": NaN, "batb": [[0, 1.08, 4128.8]], "batl": NaN}, {"timestamp": 1578773386993, "ltp": 1.08, "tv": 50282.74, "trd": [[1.08, 6616.02]], "batb": [[0, 1.08, 3618.79]], "batl": NaN}, {"timestamp": 1578773388000, "ltp": 1.08, "tv": 50282.74, "trd": NaN, "batb": [[0, 1.08, 1493]], "batl": [[0, 1.09, 1139.29], [1, 1.1, 2891.25]]}, {"timestamp": 1578773394005, "ltp": 1.08, "tv": 50282.74, "trd": NaN, "batb": [[1, 1.07, 14971.53]], "batl": NaN}, {"timestamp": 1578773395022, "ltp": 1.08, "tv": 50282.74, "trd": NaN, "batb": [[1, 1.07, 16672.33]], "batl": NaN}, {"timestamp": 1578773396011, "ltp": 1.08, "tv": 50282.74, "trd": NaN, "batb": [[0, 1.08, 1130.52]], "batl": NaN}, {"timestamp": 1578773398010, "ltp": 1.08, "tv": 50282.74, "trd": NaN, "batb": NaN, "batl": [[2, 1.11, 2247.8]]}, {"timestamp": 1578773401031, "ltp": 1.08, "tv": 50282.74, "trd": NaN, "batb": [[0, 1.08, 1109.23]], "batl": [[2, 1.11, 2226.52]]}, {"timestamp": 1578773404032, "ltp": 1.08, "tv": 50286.74, "trd": [[1.08, 6620.02]], "batb": [[0, 1.08, 1107.23]], "batl": NaN}, {"timestamp": 1578773405044, "ltp": 1.08, "tv": 50286.74, "trd": NaN, "batb": NaN, "batl": [[0, 1.09, 1224.41]]}, {"timestamp": 1578773406034, "ltp": 1.08, "tv": 50286.74, "trd": NaN, "batb": [[0, 1.08, 1090.21]], "batl": NaN}, {"timestamp": 1578773408040, "ltp": 1.08, "tv": 50286.74, "trd": NaN, "batb": [[0, 1.08, 1111.49]], "batl": [[2, 1.11, 2247.8]]}, {"timestamp": 1578773410951, "ltp": 1.08, "tv": 50286.74, "trd": NaN, "batb": [[0, 1.08, 815.3]], "batl": NaN}, {"timestamp": 1578773412916, "ltp": 1.08, "tv": 50286.74, "trd": NaN, "batb": [[1, 1.07, 16689.36]], "batl": NaN}, {"timestamp": 1578773426052, "ltp": 1.08, "tv": 50286.74, "trd": NaN, "batb": [[0, 1.08, 643.43]], "batl": NaN}, {"timestamp": 1578773427048, "ltp": 1.08, "tv": 50286.74, "trd": NaN, "batb": NaN, "batl": [[0, 1.09, 1230.43]]}, {"timestamp": 1578773428045, "ltp": 1.08, "tv": 50363.28, "trd": [[1.08, 6696.55]], "batb": [[0, 1.08, 605.16]], "batl": NaN}, {"timestamp": 1578773429044, "ltp": 1.08, "tv": 50381.97, "trd": [[1.08, 6715.24]], "batb": [[0, 1.08, 595.81]], "batl": NaN}, {"timestamp": 1578773437992, "ltp": 1.08, "tv": 50381.97, "trd": NaN, "batb": NaN, "batl": [[1, 1.1, 4891.25]]}, {"timestamp": 1578773450018, "ltp": 1.08, "tv": 50458.5, "trd": [[1.08, 6791.78]], "batb": [[0, 1.08, 557.54]], "batl": NaN}, {"timestamp": 1578773462014, "ltp": 1.08, "tv": 50458.5, "trd": NaN, "batb": [[2, 1.06, 12753.17]], "batl": NaN}, {"timestamp": 1578773463014, "ltp": 1.08, "tv": 56642.12, "trd": [[1.08, 12975.4]], "batb": [[0, 1.07, 16687.36], [1, 1.06, 12753.17], [2, 1.05, 20866.68]], "batl": [[0, 1.08, 52193.63], [1, 1.09, 1230.43], [2, 1.1, 4891.25]]}, {"timestamp": 1578773464011, "ltp": 1.08, "tv": 56642.12, "trd": NaN, "batb": NaN, "batl": [[2, 1.1, 4776.55]]}, {"timestamp": 1578773465016, "ltp": 1.08, "tv": 56642.12, "trd": NaN, "batb": NaN, "batl": [[2, 1.1, 4326.55]]}, {"timestamp": 1578773465905, "ltp": 1.08, "tv": 56642.12, "trd": NaN, "batb": NaN, "batl": [[2, 1.1, 3876.55]]}, {"timestamp": 1578773467055, "ltp": 1.08, "tv": 56642.12, "trd": NaN, "batb": NaN, "batl": [[0, 1.08, 52493.63], [1, 1.09, 1206.09]]}, {"timestamp": 1578773468026, "ltp": 1.08, "tv": 56642.12, "trd": NaN, "batb": [[0, 1.07, 16091.51]], "batl": [[2, 1.1, 3290.31]]}, {"timestamp": 1578773469028, "ltp": 1.08, "tv": 56642.12, "trd": NaN, "batb": NaN, "batl": [[2, 1.1, 3197.61]]}, {"timestamp": 1578773470031, "ltp": 1.08, "tv": 59275.43, "trd": [[1.08, 15608.71]], "batb": [[0, 1.07, 16123.21]], "batl": [[0, 1.08, 49860.32]]}, {"timestamp": 1578773471039, "ltp": 1.08, "tv": 59317.99, "trd": [[1.08, 15651.27]], "batb": [[0, 1.07, 16144.49]], "batl": [[0, 1.08, 49981.24]]}, {"timestamp": 1578773472032, "ltp": 1.08, "tv": 59317.99, "trd": NaN, "batb": NaN, "batl": [[0, 1.08, 442.2], [1, 1.09, 1120.97]]}, {"timestamp": 1578773473033, "ltp": 1.08, "tv": 59317.99, "trd": NaN, "batb": NaN, "batl": [[1, 1.09, 2020.97]]}, {"timestamp": 1578773474026, "ltp": 1.08, "tv": 59317.99, "trd": NaN, "batb": [[2, 1.05, 20870.51]], "batl": [[0, 1.08, 797.57]]}, {"timestamp": 1578773475026, "ltp": 1.08, "tv": 59317.99, "trd": NaN, "batb": NaN, "batl": [[0, 1.08, 655.36]]}, {"timestamp": 1578773476034, "ltp": 1.08, "tv": 59317.99, "trd": NaN, "batb": NaN, "batl": [[0, 1.08, 131.21], [1, 1.09, 2014.95]]}, {"timestamp": 1578773477041, "ltp": 1.08, "tv": 59317.99, "trd": NaN, "batb": NaN, "batl": [[0, 1.08, 24.34]]}, {"timestamp": 1578773478046, "ltp": 1.08, "tv": 59317.99, "trd": NaN, "batb": NaN, "batl": [[0, 1.09, 2014.95], [1, 1.1, 3197.61], [2, 1.11, 2259.8]]}, {"timestamp": 1578773479027, "ltp": 1.08, "tv": 59317.99, "trd": NaN, "batb": NaN, "batl": [[0, 1.08, 85.12], [1, 1.09, 2014.95], [2, 1.1, 3197.61]]}, {"timestamp": 1578773480032, "ltp": 1.08, "tv": 59317.99, "trd": NaN, "batb": NaN, "batl": [[0, 1.08, 136.43]]}, {"timestamp": 1578773483027, "ltp": 1.07, "tv": 59917.99, "trd": [[1.07, 2985.57]], "batb": [[0, 1.07, 15844.49]], "batl": [[0, 1.08, 275.76]]}, {"timestamp": 1578773484029, "ltp": 1.07, "tv": 99285.56, "trd": [[1.07, 42353.13]], "batb": [[0, 1.06, 12751.17], [1, 1.05, 20870.51], [2, 1.04, 21775.47]], "batl": [[0, 1.07, 25476.93], [1, 1.08, 89.71], [2, 1.09, 2014.95]]}, {"timestamp": 1578773485025, "ltp": 1.07, "tv": 99285.56, "trd": NaN, "batb": NaN, "batl": [[2, 1.09, 1114.95]]}, {"timestamp": 1578773485961, "ltp": 1.07, "tv": 100211.07, "trd": [[1.07, 43278.64]], "batb": NaN, "batl": [[0, 1.07, 24551.42]]}, {"timestamp": 1578773489957, "ltp": 1.07, "tv": 100211.07, "trd": NaN, "batb": NaN, "batl": [[0, 1.07, 24554.48], [1, 1.08, 106.74]]}, {"timestamp": 1578773491000, "ltp": 1.07, "tv": 105840.91, "trd": [[1.07, 48908.49]], "batb": [[0, 1.06, 16925.31]], "batl": [[0, 1.07, 20809.47]]}, {"timestamp": 1578773492051, "ltp": 1.07, "tv": 105948.3, "trd": [[1.07, 49015.88]], "batb": NaN, "batl": [[0, 1.07, 20702.08], [1, 1.08, 674.41]]}, {"timestamp": 1578773492991, "ltp": 1.07, "tv": 105948.3, "trd": NaN, "batb": NaN, "batl": [[0, 1.07, 21504.93], [1, 1.08, 1574.41]]}, {"timestamp": 1578773493978, "ltp": 1.07, "tv": 105948.3, "trd": NaN, "batb": NaN, "batl": [[0, 1.07, 21512.58], [1, 1.08, 1580.42]]}, {"timestamp": 1578773494968, "ltp": 1.07, "tv": 105948.3, "trd": NaN, "batb": NaN, "batl": [[1, 1.08, 1911.45]]}, {"timestamp": 1578773495967, "ltp": 1.07, "tv": 105948.3, "trd": NaN, "batb": NaN, "batl": [[0, 1.07, 26614.37]]}, {"timestamp": 1578773496971, "ltp": 1.07, "tv": 105948.3, "trd": NaN, "batb": NaN, "batl": [[1, 1.08, 2017.85]]}, {"timestamp": 1578773499013, "ltp": 1.07, "tv": 107437.92, "trd": [[1.07, 50505.49]], "batb": NaN, "batl": [[0, 1.07, 25892.87], [2, 1.09, 1041.02]]}, {"timestamp": 1578773502005, "ltp": 1.07, "tv": 107437.92, "trd": NaN, "batb": [[0, 1.06, 16425.31]], "batl": NaN}, {"timestamp": 1578773503997, "ltp": 1.07, "tv": 107660.56, "trd": [[1.07, 50728.13]], "batb": NaN, "batl": [[0, 1.07, 25781.55]]}, {"timestamp": 1578773504989, "ltp": 1.07, "tv": 107660.56, "trd": NaN, "batb": NaN, "batl": [[0, 1.07, 25934.44], [1, 1.08, 2013.26]]}, {"timestamp": 1578773505993, "ltp": 1.07, "tv": 107660.56, "trd": NaN, "batb": NaN, "batl": [[0, 1.07, 26724.98]]}, {"timestamp": 1578773506993, "ltp": 1.07, "tv": 109150.18, "trd": [[1.07, 52217.75]], "batb": NaN, "batl": [[0, 1.07, 25980.46], [1, 1.08, 2007.24], [2, 1.09, 1147.43]]}, {"timestamp": 1578773508992, "ltp": 1.07, "tv": 109150.18, "trd": NaN, "batb": NaN, "batl": [[0, 1.07, 25977.4]]}, {"timestamp": 1578773512020, "ltp": 1.06, "tv": 109165.48, "trd": [[1.06, 15.31]], "batb": [[0, 1.06, 16417.65]], "batl": NaN}, {"timestamp": 1578773513029, "ltp": 1.06, "tv": 109174.67, "trd": [[1.06, 24.49]], "batb": [[0, 1.06, 16413.06]], "batl": NaN}, {"timestamp": 1578773513977, "ltp": 1.07, "tv": 110453.56, "trd": [[1.07, 53496.65]], "batb": NaN, "batl": [[0, 1.07, 25337.95]]}, {"timestamp": 1578773519987, "ltp": 1.07, "tv": 110453.56, "trd": NaN, "batb": NaN, "batl": [[1, 1.08, 3023.24]]}, {"timestamp": 1578773521033, "ltp": 1.07, "tv": 110453.56, "trd": NaN, "batb": [[0, 1.06, 16434.34]], "batl": NaN}, {"timestamp": 1578773522035, "ltp": 1.07, "tv": 111619.72, "trd": [[1.07, 54662.8]], "batb": [[0, 1.06, 16451.37]], "batl": [[0, 1.07, 24754.87]]}, {"timestamp": 1578773523045, "ltp": 1.07, "tv": 111619.72, "trd": NaN, "batb": [[0, 1.06, 14614.3]], "batl": [[1, 1.08, 2573.24]]}, {"timestamp": 1578773526022, "ltp": 1.07, "tv": 111619.72, "trd": NaN, "batb": [[0, 1.06, 14053.31]], "batl": NaN}, {"timestamp": 1578773529034, "ltp": 1.07, "tv": 112896.54, "trd": [[1.07, 55939.62]], "batb": NaN, "batl": [[0, 1.07, 24116.46]]}, {"timestamp": 1578773530044, "ltp": 1.07, "tv": 112896.54, "trd": NaN, "batb": [[0, 1.06, 8951.52]], "batl": NaN}, {"timestamp": 1578773531053, "ltp": 1.07, "tv": 112896.54, "trd": NaN, "batb": NaN, "batl": [[0, 1.07, 24133.48]]}, {"timestamp": 1578773534955, "ltp": 1.07, "tv": 112896.54, "trd": NaN, "batb": [[0, 1.06, 8920.4]], "batl": NaN}, {"timestamp": 1578773537051, "ltp": 1.07, "tv": 112932.29, "trd": [[1.07, 55975.38]], "batb": NaN, "batl": [[0, 1.07, 24115.6], [1, 1.08, 2910.74]]}, {"timestamp": 1578773538027, "ltp": 1.07, "tv": 112932.29, "trd": NaN, "batb": NaN, "batl": [[1, 1.08, 2573.24]]}, {"timestamp": 1578773539010, "ltp": 1.07, "tv": 112932.29, "trd": NaN, "batb": [[0, 1.06, 8682.89]], "batl": NaN}, {"timestamp": 1578773545054, "ltp": 1.07, "tv": 112932.29, "trd": NaN, "batb": [[0, 1.06, 10519.99]], "batl": NaN}, {"timestamp": 1578773546048, "ltp": 1.07, "tv": 112932.29, "trd": NaN, "batb": NaN, "batl": [[1, 1.08, 3023.24]]}, {"timestamp": 1578773552976, "ltp": 1.07, "tv": 112932.29, "trd": NaN, "batb": NaN, "batl": [[0, 1.07, 24222]]}, {"timestamp": 1578773559967, "ltp": 1.07, "tv": 112932.29, "trd": NaN, "batb": NaN, "batl": [[1, 1.08, 2831.72]]}, {"timestamp": 1578773571993, "ltp": 1.07, "tv": 112932.29, "trd": NaN, "batb": [[1, 1.05, 20884.28]], "batl": NaN}, {"timestamp": 1578773584031, "ltp": 1.07, "tv": 112932.29, "trd": NaN, "batb": NaN, "batl": [[0, 1.07, 24137.05]]}, {"timestamp": 1578773589032, "ltp": 1.06, "tv": 112938.41, "trd": [[1.06, 30.61]], "batb": [[0, 1.06, 10516.92]], "batl": NaN}, {"timestamp": 1578773591044, "ltp": 1.06, "tv": 112942.41, "trd": [[1.06, 34.61]], "batb": [[0, 1.06, 10514.93]], "batl": NaN}, {"timestamp": 1578773592037, "ltp": 1.06, "tv": 112952.41, "trd": [[1.06, 44.61]], "batb": [[0, 1.06, 10509.93]], "batl": NaN}, {"timestamp": 1578773595045, "ltp": 1.06, "tv": 112952.41, "trd": NaN, "batb": [[0, 1.06, 10509.15]], "batl": NaN}, {"timestamp": 1578773602929, "ltp": 1.06, "tv": 112952.41, "trd": NaN, "batb": NaN, "batl": [[2, 1.09, 1062.3]]}, {"timestamp": 1578773606034, "ltp": 1.06, "tv": 112952.76, "trd": [[1.06, 44.96]], "batb": [[0, 1.06, 10508.97]], "batl": NaN}, {"timestamp": 1578773607037, "ltp": 1.06, "tv": 112952.76, "trd": NaN, "batb": [[0, 1.06, 10171.7]], "batl": NaN}, {"timestamp": 1578773607971, "ltp": 1.06, "tv": 112952.76, "trd": NaN, "batb": [[0, 1.06, 9918.98]], "batl": NaN}, {"timestamp": 1578773608971, "ltp": 1.06, "tv": 112952.76, "trd": NaN, "batb": NaN, "batl": [[1, 1.08, 2916.84]]}, {"timestamp": 1578773609967, "ltp": 1.07, "tv": 112953.2, "trd": [[1.07, 55975.82]], "batb": NaN, "batl": [[0, 1.07, 24136.83]]}, {"timestamp": 1578773614046, "ltp": 1.07, "tv": 112953.2, "trd": NaN, "batb": [[0, 1.06, 6517.79]], "batl": NaN}, {"timestamp": 1578773617030, "ltp": 1.07, "tv": 112953.2, "trd": NaN, "batb": NaN, "batl": [[0, 1.07, 19119.99]]}, {"timestamp": 1578773620962, "ltp": 1.07, "tv": 112953.2, "trd": NaN, "batb": [[0, 1.06, 6411.39]], "batl": NaN}, {"timestamp": 1578773622055, "ltp": 1.07, "tv": 112953.2, "trd": NaN, "batb": [[0, 1.06, 6428.73]], "batl": NaN}, {"timestamp": 1578773622938, "ltp": 1.07, "tv": 113021.3, "trd": [[1.07, 56043.92]], "batb": [[0, 1.06, 6091.45]], "batl": [[0, 1.07, 19085.94], [2, 1.09, 3062.3]]}, {"timestamp": 1578773623978, "ltp": 1.06, "tv": 123054.98, "trd": [[1.06, 10078.64]], "batb": [[0, 1.06, 1074.61]], "batl": NaN}, {"timestamp": 1578773624968, "ltp": 1.06, "tv": 123054.98, "trd": NaN, "batb": [[0, 1.05, 20882.28], [1, 1.04, 21775.47], [2, 1.03, 21024.06]], "batl": [[1, 1.08, 2466.84]]}, {"timestamp": 1578773630905, "ltp": 1.06, "tv": 123054.98, "trd": NaN, "batb": NaN, "batl": [[0, 1.07, 20265.94]]}, {"timestamp": 1578773631970, "ltp": 1.06, "tv": 123054.98, "trd": NaN, "batb": [[0, 1.06, 165.56], [1, 1.05, 24595.57], [2, 1.04, 21775.47]], "batl": NaN}, {"timestamp": 1578773633013, "ltp": 1.06, "tv": 123586.38, "trd": [[1.06, 10610.04]], "batb": [[0, 1.05, 24596.35], [1, 1.04, 21775.47], [2, 1.03, 21024.06]], "batl": [[0, 1.07, 20715.94]]}, {"timestamp": 1578773634021, "ltp": 1.06, "tv": 123672.28, "trd": [[1.06, 10695.94]], "batb": [[0, 1.05, 24595.57]], "batl": NaN}, {"timestamp": 1578773634981, "ltp": 1.06, "tv": 123672.28, "trd": NaN, "batb": NaN, "batl": [[0, 1.07, 20609.54]]}, {"timestamp": 1578773635983, "ltp": 1.06, "tv": 123672.28, "trd": NaN, "batb": NaN, "batl": [[0, 1.07, 20578.29]]}, {"timestamp": 1578773638985, "ltp": 1.06, "tv": 123672.28, "trd": NaN, "batb": [[0, 1.05, 24907.19]], "batl": NaN}, {"timestamp": 1578773639989, "ltp": 1.06, "tv": 123672.28, "trd": NaN, "batb": [[0, 1.06, 38.3], [1, 1.05, 24907.19], [2, 1.04, 21775.47]], "batl": NaN}, {"timestamp": 1578773641988, "ltp": 1.06, "tv": 123784.71, "trd": [[1.06, 10808.37]], "batb": [[0, 1.05, 24909.19], [1, 1.04, 21775.47], [2, 1.03, 21024.06]], "batl": [[0, 1.06, 51.18], [1, 1.07, 20578.29], [2, 1.08, 2466.84]]}, {"timestamp": 1578773642993, "ltp": 1.06, "tv": 123835.9, "trd": [[1.06, 10859.56]], "batb": [[0, 1.05, 24907.19]], "batl": [[0, 1.07, 20578.29], [1, 1.08, 2466.84], [2, 1.09, 3062.3]]}, {"timestamp": 1578773645000, "ltp": 1.06, "tv": 124791.69, "trd": [[1.06, 11815.35]], "batb": NaN, "batl": [[0, 1.06, 579.55], [1, 1.07, 20578.29], [2, 1.08, 2356.53]]}, {"timestamp": 1578773646009, "ltp": 1.06, "tv": 125725.54, "trd": [[1.06, 12749.2]], "batb": NaN, "batl": [[0, 1.07, 20578.29], [1, 1.08, 1906.53], [2, 1.09, 3041.02]]}, {"timestamp": 1578773647017, "ltp": 1.06, "tv": 125725.54, "trd": NaN, "batb": [[0, 1.06, 12.83], [1, 1.05, 24907.19], [2, 1.04, 21775.47]], "batl": NaN}, {"timestamp": 1578773648020, "ltp": 1.06, "tv": 125725.54, "trd": NaN, "batb": [[0, 1.06, 251.68]], "batl": NaN}, {"timestamp": 1578773648984, "ltp": 1.06, "tv": 125725.54, "trd": NaN, "batb": [[0, 1.06, 41.97]], "batl": NaN}, {"timestamp": 1578773649997, "ltp": 1.06, "tv": 125725.54, "trd": NaN, "batb": [[0, 1.06, 63.26]], "batl": NaN}, {"timestamp": 1578773651008, "ltp": 1.06, "tv": 125725.54, "trd": NaN, "batb": [[0, 1.06, 41.97], [1, 1.05, 24909.19]], "batl": [[0, 1.07, 20609.54]]}, {"timestamp": 1578773652016, "ltp": 1.06, "tv": 125809.49, "trd": [[1.06, 12833.15]], "batb": [[0, 1.05, 24909.19], [1, 1.04, 21775.47], [2, 1.03, 21024.06]], "batl": [[0, 1.06, 100.89], [1, 1.07, 20609.54], [2, 1.08, 1927.81]]}, {"timestamp": 1578773653036, "ltp": 1.06, "tv": 125809.49, "trd": NaN, "batb": [[0, 1.05, 25407.19]], "batl": [[0, 1.07, 20609.54], [1, 1.08, 1927.81], [2, 1.09, 3041.02]]}, {"timestamp": 1578773654041, "ltp": 1.06, "tv": 125809.49, "trd": NaN, "batb": [[0, 1.05, 24907.19]], "batl": [[0, 1.07, 21059.54]]}, {"timestamp": 1578773655014, "ltp": 1.06, "tv": 125809.49, "trd": NaN, "batb": [[0, 1.06, 186.09], [1, 1.05, 24907.19], [2, 1.04, 21775.47]], "batl": NaN}, {"timestamp": 1578773661049, "ltp": 1.06, "tv": 125809.49, "trd": NaN, "batb": [[0, 1.06, 207.37], [1, 1.05, 24909.19]], "batl": NaN}, {"timestamp": 1578773663053, "ltp": 1.06, "tv": 125852.05, "trd": [[1.06, 12875.71]], "batb": [[0, 1.06, 186.09]], "batl": NaN}, {"timestamp": 1578773665043, "ltp": 1.06, "tv": 125852.05, "trd": NaN, "batb": NaN, "batl": [[0, 1.07, 21072.25]]}, {"timestamp": 1578773666048, "ltp": 1.06, "tv": 125852.05, "trd": NaN, "batb": NaN, "batl": [[2, 1.09, 3392.52]]}, {"timestamp": 1578773667024, "ltp": 1.06, "tv": 125862.26, "trd": [[1.06, 12885.92]], "batb": [[0, 1.06, 180.98]], "batl": NaN}, {"timestamp": 1578773668019, "ltp": 1.06, "tv": 125862.26, "trd": NaN, "batb": [[0, 1.06, 21.28]], "batl": NaN}, {"timestamp": 1578773676048, "ltp": 1.06, "tv": 125862.38, "trd": [[1.06, 12886.04]], "batb": [[0, 1.06, 21.22]], "batl": NaN}, {"timestamp": 1578773682974, "ltp": 1.06, "tv": 125862.38, "trd": NaN, "batb": [[0, 1.05, 24924.22], [1, 1.04, 21775.47], [2, 1.03, 21024.06]], "batl": NaN}, {"timestamp": 1578773687958, "ltp": 1.06, "tv": 125862.38, "trd": NaN, "batb": NaN, "batl": [[0, 1.06, 2.3], [1, 1.07, 21072.25], [2, 1.08, 1927.81]]}, {"timestamp": 1578773689960, "ltp": 1.06, "tv": 125862.38, "trd": NaN, "batb": [[0, 1.05, 25424.22]], "batl": [[1, 1.07, 21028.29]]}, {"timestamp": 1578773695981, "ltp": 1.06, "tv": 125864.68, "trd": [[1.06, 12888.34]], "batb": NaN, "batl": [[0, 1.07, 21028.29], [1, 1.08, 1927.81], [2, 1.09, 3392.52]]}, {"timestamp": 1578773697003, "ltp": 1.06, "tv": 125866.98, "trd": [[1.06, 12890.63]], "batb": NaN, "batl": [[0, 1.06, 42.08], [1, 1.07, 21028.29], [2, 1.08, 1927.81]]}, {"timestamp": 1578773698001, "ltp": 1.06, "tv": 125866.98, "trd": NaN, "batb": NaN, "batl": [[2, 1.08, 1784.16]]}, {"timestamp": 1578773699011, "ltp": 1.06, "tv": 125869.27, "trd": [[1.06, 12892.93]], "batb": [[0, 1.05, 24792.81]], "batl": [[0, 1.06, 39.78]]}, {"timestamp": 1578773700007, "ltp": 1.06, "tv": 125869.27, "trd": NaN, "batb": NaN, "batl": [[2, 1.08, 1762.88]]}, {"timestamp": 1578773700967, "ltp": 1.06, "tv": 125871.57, "trd": [[1.06, 12895.23]], "batb": NaN, "batl": [[0, 1.06, 37.48]]}, {"timestamp": 1578773704014, "ltp": 1.06, "tv": 125871.57, "trd": NaN, "batb": [[0, 1.05, 22780.32]], "batl": [[0, 1.06, 81.85], [1, 1.07, 20578.29]]}, {"timestamp": 1578773705030, "ltp": 1.06, "tv": 125871.57, "trd": NaN, "batb": [[0, 1.05, 20267.9]], "batl": [[0, 1.06, 209.16], [1, 1.07, 20128.29], [2, 1.08, 3762.88]]}, {"timestamp": 1578773706995, "ltp": 1.06, "tv": 125871.57, "trd": NaN, "batb": NaN, "batl": [[2, 1.08, 3784.16]]}, {"timestamp": 1578773708006, "ltp": 1.05, "tv": 125936.04, "trd": [[1.05, 64.47]], "batb": [[0, 1.05, 20242.56]], "batl": NaN}, {"timestamp": 1578773709032, "ltp": 1.05, "tv": 125936.04, "trd": NaN, "batb": NaN, "batl": [[0, 1.06, 370.54]]}, {"timestamp": 1578773710029, "ltp": 1.05, "tv": 125936.04, "trd": NaN, "batb": NaN, "batl": [[0, 1.06, 223.16]]}, {"timestamp": 1578773711043, "ltp": 1.05, "tv": 125936.04, "trd": NaN, "batb": NaN, "batl": [[2, 1.08, 3139.43]]}, {"timestamp": 1578773712010, "ltp": 1.05, "tv": 125936.04, "trd": NaN, "batb": [[0, 1.05, 24267.56]], "batl": [[1, 1.07, 21028.29]]}, {"timestamp": 1578773715022, "ltp": 1.05, "tv": 125936.04, "trd": NaN, "batb": [[0, 1.05, 24288.84]], "batl": NaN}, {"timestamp": 1578773718027, "ltp": 1.05, "tv": 125936.04, "trd": NaN, "batb": NaN, "batl": [[0, 1.06, 897.71]]}, {"timestamp": 1578773719029, "ltp": 1.05, "tv": 125936.04, "trd": NaN, "batb": NaN, "batl": [[0, 1.06, 904.6]]}, {"timestamp": 1578773720036, "ltp": 1.05, "tv": 125936.04, "trd": NaN, "batb": NaN, "batl": [[0, 1.06, 1054.99]]}, {"timestamp": 1578773722040, "ltp": 1.05, "tv": 125936.04, "trd": NaN, "batb": [[0, 1.05, 24290.54]], "batl": NaN}, {"timestamp": 1578773723042, "ltp": 1.06, "tv": 125975.96, "trd": [[1.06, 12935.15]], "batb": NaN, "batl": [[0, 1.06, 1015.06]]}, {"timestamp": 1578773725958, "ltp": 1.06, "tv": 125975.96, "trd": NaN, "batb": NaN, "batl": [[0, 1.06, 1008.17]]}, {"timestamp": 1578773727027, "ltp": 1.06, "tv": 125975.96, "trd": NaN, "batb": NaN, "batl": [[0, 1.06, 333.62]]}, {"timestamp": 1578773728042, "ltp": 1.06, "tv": 125975.96, "trd": NaN, "batb": [[0, 1.05, 24294.54]], "batl": [[0, 1.06, 319.62]]}, {"timestamp": 1578773730038, "ltp": 1.05, "tv": 125991.27, "trd": [[1.05, 79.78]], "batb": [[0, 1.05, 24286.88]], "batl": NaN}, {"timestamp": 1578773732052, "ltp": 1.05, "tv": 125993.6, "trd": [[1.05, 82.1]], "batb": [[0, 1.05, 24285.72]], "batl": NaN}, {"timestamp": 1578773735959, "ltp": 1.05, "tv": 125993.6, "trd": NaN, "batb": NaN, "batl": [[0, 1.06, 656.89]]}, {"timestamp": 1578773740032, "ltp": 1.05, "tv": 125993.6, "trd": NaN, "batb": [[1, 1.04, 21777.18]], "batl": NaN}, {"timestamp": 1578773741034, "ltp": 1.05, "tv": 125993.6, "trd": NaN, "batb": NaN, "batl": [[0, 1.06, 994.17]]}, {"timestamp": 1578773743959, "ltp": 1.05, "tv": 125993.6, "trd": NaN, "batb": NaN, "batl": [[0, 1.06, 1001.06]]}, {"timestamp": 1578773745971, "ltp": 1.05, "tv": 125993.6, "trd": NaN, "batb": [[0, 1.05, 22273.22]], "batl": NaN}, {"timestamp": 1578773746966, "ltp": 1.05, "tv": 126008.9, "trd": [[1.05, 97.41]], "batb": [[0, 1.05, 22265.57]], "batl": [[2, 1.08, 3054.3]]}, {"timestamp": 1578773752957, "ltp": 1.05, "tv": 126008.9, "trd": NaN, "batb": [[1, 1.04, 24027.18], [2, 1.03, 21025.76]], "batl": NaN}, {"timestamp": 1578773753962, "ltp": 1.05, "tv": 126008.9, "trd": NaN, "batb": NaN, "batl": [[1, 1.07, 21113.41]]}, {"timestamp": 1578773759002, "ltp": 1.05, "tv": 126008.9, "trd": NaN, "batb": [[0, 1.05, 16312.71]], "batl": NaN}, {"timestamp": 1578773760968, "ltp": 1.05, "tv": 126008.9, "trd": NaN, "batb": [[1, 1.04, 25174.18]], "batl": [[0, 1.06, 2183.06]]}, {"timestamp": 1578773763973, "ltp": 1.05, "tv": 126249.03, "trd": [[1.05, 337.53]], "batb": [[0, 1.05, 16192.65]], "batl": NaN}, {"timestamp": 1578773765033, "ltp": 1.05, "tv": 126279.64, "trd": [[1.05, 368.15]], "batb": [[0, 1.05, 16177.35]], "batl": NaN}, {"timestamp": 1578773766019, "ltp": 1.05, "tv": 126279.64, "trd": NaN, "batb": NaN, "batl": [[1, 1.07, 20663.41]]}, {"timestamp": 1578773768988, "ltp": 1.05, "tv": 126279.64, "trd": NaN, "batb": [[0, 1.05, 12776.15]], "batl": NaN}, {"timestamp": 1578773769980, "ltp": 1.05, "tv": 126519.64, "trd": [[1.05, 608.15]], "batb": [[0, 1.05, 12656.15]], "batl": NaN}, {"timestamp": 1578773770987, "ltp": 1.05, "tv": 126527.29, "trd": [[1.05, 615.8]], "batb": [[0, 1.05, 12652.33]], "batl": NaN}, {"timestamp": 1578773772989, "ltp": 1.05, "tv": 126527.29, "trd": NaN, "batb": NaN, "batl": [[0, 1.06, 2633.06]]}, {"timestamp": 1578773773987, "ltp": 1.05, "tv": 126527.29, "trd": NaN, "batb": [[0, 1.05, 11588.33]], "batl": NaN}, {"timestamp": 1578773778016, "ltp": 1.05, "tv": 126527.29, "trd": NaN, "batb": NaN, "batl": [[2, 1.08, 3386.99]]}, {"timestamp": 1578773779009, "ltp": 1.05, "tv": 126527.29, "trd": NaN, "batb": [[0, 1.05, 9122.39]], "batl": NaN}, {"timestamp": 1578773784032, "ltp": 1.05, "tv": 126527.29, "trd": NaN, "batb": [[0, 1.05, 9035.98]], "batl": NaN}, {"timestamp": 1578773786046, "ltp": 1.05, "tv": 126527.29, "trd": NaN, "batb": [[0, 1.05, 7023.48]], "batl": NaN}, {"timestamp": 1578773789037, "ltp": 1.05, "tv": 127001.8, "trd": [[1.05, 1090.31]], "batb": [[0, 1.05, 6679.76]], "batl": NaN}, {"timestamp": 1578773790996, "ltp": 1.05, "tv": 127002.06, "trd": [[1.05, 1090.57]], "batb": [[0, 1.05, 6679.63]], "batl": NaN}, {"timestamp": 1578773794034, "ltp": 1.05, "tv": 127078.6, "trd": [[1.05, 1167.11]], "batb": [[0, 1.05, 6641.36], [1, 1.04, 27424.18]], "batl": NaN}, {"timestamp": 1578773798037, "ltp": 1.05, "tv": 127082.34, "trd": [[1.05, 1170.85]], "batb": [[0, 1.05, 6639.49]], "batl": NaN}, {"timestamp": 1578773799046, "ltp": 1.05, "tv": 127082.34, "trd": NaN, "batb": [[1, 1.04, 25174.18]], "batl": [[0, 1.06, 2183.06]]}, {"timestamp": 1578773802021, "ltp": 1.05, "tv": 127086.34, "trd": [[1.05, 1174.85]], "batb": [[0, 1.05, 6637.49]], "batl": NaN}, {"timestamp": 1578773805029, "ltp": 1.05, "tv": 127086.34, "trd": NaN, "batb": [[0, 1.05, 6616.21]], "batl": [[2, 1.08, 3365.71]]}, {"timestamp": 1578773806034, "ltp": 1.05, "tv": 127086.34, "trd": NaN, "batb": [[0, 1.05, 6871.57]], "batl": [[1, 1.07, 20213.41]]}, {"timestamp": 1578773813033, "ltp": 1.05, "tv": 127086.34, "trd": NaN, "batb": [[0, 1.05, 6892.85]], "batl": [[0, 1.06, 2633.06], [2, 1.08, 3386.99]]}, {"timestamp": 1578773816042, "ltp": 1.05, "tv": 127086.34, "trd": NaN, "batb": [[0, 1.05, 6637.49]], "batl": NaN}, {"timestamp": 1578773819046, "ltp": 1.05, "tv": 127086.34, "trd": NaN, "batb": [[0, 1.05, 5702.24], [1, 1.04, 27424.18]], "batl": [[0, 1.06, 3083.06]]}, {"timestamp": 1578773846008, "ltp": 1.05, "tv": 127086.34, "trd": NaN, "batb": NaN, "batl": [[2, 1.08, 3365.71]]}, {"timestamp": 1578773852995, "ltp": 1.05, "tv": 127086.34, "trd": NaN, "batb": NaN, "batl": [[1, 1.07, 20234.69]]}, {"timestamp": 1578773859019, "ltp": 1.05, "tv": 127086.34, "trd": NaN, "batb": [[0, 1.05, 4833.6]], "batl": NaN}, {"timestamp": 1578773865031, "ltp": 1.05, "tv": 127086.34, "trd": NaN, "batb": [[0, 1.05, 4816.57]], "batl": NaN}, {"timestamp": 1578773866034, "ltp": 1.05, "tv": 127891.48, "trd": [[1.05, 1979.99]], "batb": [[0, 1.05, 4414]], "batl": NaN}, {"timestamp": 1578773870022, "ltp": 1.05, "tv": 127891.48, "trd": NaN, "batb": [[0, 1.05, 4224]], "batl": NaN}, {"timestamp": 1578773880012, "ltp": 1.05, "tv": 127891.48, "trd": NaN, "batb": NaN, "batl": [[1, 1.07, 22234.69]]}, {"timestamp": 1578773884954, "ltp": 1.05, "tv": 127891.48, "trd": NaN, "batb": [[1, 1.04, 22924.18]], "batl": [[0, 1.06, 2183.06]]}, {"timestamp": 1578773891971, "ltp": 1.05, "tv": 127891.48, "trd": NaN, "batb": [[1, 1.04, 27424.18]], "batl": [[0, 1.06, 3083.06]]}, {"timestamp": 1578773902986, "ltp": 1.05, "tv": 127891.48, "trd": NaN, "batb": [[0, 1.05, 3961.61]], "batl": NaN}, {"timestamp": 1578773906981, "ltp": 1.05, "tv": 127891.48, "trd": NaN, "batb": [[0, 1.05, 3447.74]], "batl": NaN}, {"timestamp": 1578773911996, "ltp": 1.05, "tv": 127891.48, "trd": NaN, "batb": NaN, "batl": [[1, 1.07, 20234.69]]}, {"timestamp": 1578773912997, "ltp": 1.05, "tv": 127891.48, "trd": NaN, "batb": [[0, 1.05, 3469.02]], "batl": [[1, 1.07, 20255.97]]}, {"timestamp": 1578773915001, "ltp": 1.05, "tv": 127891.48, "trd": NaN, "batb": NaN, "batl": [[0, 1.06, 1901.06]]}, {"timestamp": 1578773915987, "ltp": 1.05, "tv": 127892.06, "trd": [[1.05, 1980.57]], "batb": [[0, 1.05, 3468.73]], "batl": NaN}, {"timestamp": 1578773916981, "ltp": 1.05, "tv": 127892.06, "trd": NaN, "batb": [[1, 1.04, 27441.2]], "batl": NaN}, {"timestamp": 1578773921999, "ltp": 1.05, "tv": 127972.64, "trd": [[1.05, 2061.15]], "batb": [[0, 1.05, 3428.44]], "batl": NaN}, {"timestamp": 1578773922997, "ltp": 1.05, "tv": 127972.64, "trd": NaN, "batb": [[0, 1.05, 3768.92]], "batl": [[1, 1.07, 22255.97]]}, {"timestamp": 1578773925985, "ltp": 1.05, "tv": 127972.64, "trd": NaN, "batb": NaN, "batl": [[2, 1.08, 2349.71]]}, {"timestamp": 1578773932029, "ltp": 1.05, "tv": 127972.64, "trd": NaN, "batb": [[0, 1.05, 4187.85], [2, 1.03, 22266.76]], "batl": NaN}, {"timestamp": 1578773933029, "ltp": 1.05, "tv": 130446.64, "trd": [[1.05, 4535.15]], "batb": [[0, 1.05, 2950.85], [1, 1.04, 26294.2]], "batl": [[0, 1.06, 3127.06], [1, 1.07, 22653.47]]}, {"timestamp": 1578773933994, "ltp": 1.05, "tv": 130446.64, "trd": NaN, "batb": [[0, 1.05, 1056.44], [1, 1.04, 26277.18]], "batl": [[1, 1.07, 22568.35]]}, {"timestamp": 1578773935038, "ltp": 1.05, "tv": 130446.64, "trd": NaN, "batb": NaN, "batl": [[1, 1.07, 20568.35]]}, {"timestamp": 1578773937039, "ltp": 1.05, "tv": 130446.64, "trd": NaN, "batb": [[0, 1.05, 950.04]], "batl": NaN}, {"timestamp": 1578773941006, "ltp": 1.05, "tv": 130446.64, "trd": NaN, "batb": [[1, 1.04, 27426.18]], "batl": NaN}, {"timestamp": 1578773942052, "ltp": 1.05, "tv": 130446.64, "trd": NaN, "batb": [[0, 1.05, 907.48]], "batl": NaN}, {"timestamp": 1578773943007, "ltp": 1.05, "tv": 130477.26, "trd": [[1.05, 4565.76]], "batb": [[0, 1.05, 892.17]], "batl": NaN}, {"timestamp": 1578773944004, "ltp": 1.05, "tv": 130477.26, "trd": NaN, "batb": [[0, 1.05, 677.67]], "batl": NaN}, {"timestamp": 1578773946042, "ltp": 1.05, "tv": 130477.26, "trd": NaN, "batb": NaN, "batl": [[1, 1.07, 22568.35]]}, {"timestamp": 1578773948045, "ltp": 1.05, "tv": 130477.26, "trd": NaN, "batb": [[0, 1.05, 698.95]], "batl": NaN}, {"timestamp": 1578773953034, "ltp": 1.05, "tv": 131377.25, "trd": [[1.05, 5465.76]], "batb": [[0, 1.05, 248.95]], "batl": NaN}, {"timestamp": 1578773954022, "ltp": 1.05, "tv": 131377.25, "trd": NaN, "batb": NaN, "batl": [[1, 1.07, 22234.23]]}, {"timestamp": 1578773954959, "ltp": 1.05, "tv": 131377.25, "trd": NaN, "batb": NaN, "batl": [[1, 1.07, 22081.35]]}, {"timestamp": 1578773957959, "ltp": 1.05, "tv": 131377.25, "trd": NaN, "batb": NaN, "batl": [[1, 1.07, 21747.23]]}, {"timestamp": 1578773958961, "ltp": 1.05, "tv": 131377.25, "trd": NaN, "batb": [[1, 1.04, 27441.48]], "batl": NaN}, {"timestamp": 1578773959964, "ltp": 1.05, "tv": 131377.25, "trd": NaN, "batb": [[1, 1.04, 27458.51]], "batl": [[0, 1.06, 3212.19]]}, {"timestamp": 1578773960956, "ltp": 1.05, "tv": 131865.2, "trd": [[1.05, 5953.7]], "batb": [[0, 1.05, 4.98]], "batl": NaN}, {"timestamp": 1578773961957, "ltp": 1.05, "tv": 131875.16, "trd": [[1.05, 5963.66]], "batb": [[0, 1.04, 27456.51], [1, 1.03, 22266.76], [2, 1.02, 21751.78]], "batl": [[0, 1.05, 213.99], [1, 1.06, 3212.19], [2, 1.07, 21747.23]]}, {"timestamp": 1578773962954, "ltp": 1.05, "tv": 131875.16, "trd": NaN, "batb": NaN, "batl": [[2, 1.07, 21624.92]]}, {"timestamp": 1578773964054, "ltp": 1.05, "tv": 131875.16, "trd": NaN, "batb": NaN, "batl": [[1, 1.06, 3205.29]]}, {"timestamp": 1578773965050, "ltp": 1.05, "tv": 131875.16, "trd": NaN, "batb": NaN, "batl": [[0, 1.05, 452.99]]}, {"timestamp": 1578773965995, "ltp": 1.05, "tv": 131875.16, "trd": NaN, "batb": NaN, "batl": [[1, 1.06, 2755.29]]}, {"timestamp": 1578773969054, "ltp": 1.05, "tv": 131875.16, "trd": NaN, "batb": [[1, 1.03, 22265.06], [2, 1.02, 21750.08]], "batl": NaN}, {"timestamp": 1578773970056, "ltp": 1.05, "tv": 131875.16, "trd": NaN, "batb": [[0, 1.04, 27454.81]], "batl": [[0, 1.05, 968.65]]}, {"timestamp": 1578773970990, "ltp": 1.05, "tv": 131875.16, "trd": NaN, "batb": [[0, 1.04, 27478.43]], "batl": [[0, 1.05, 2210.51]]}, {"timestamp": 1578773971992, "ltp": 1.05, "tv": 131875.16, "trd": NaN, "batb": NaN, "batl": [[0, 1.05, 2250.8]]}, {"timestamp": 1578773972981, "ltp": 1.05, "tv": 131903.35, "trd": [[1.05, 5991.85]], "batb": NaN, "batl": [[0, 1.05, 2236.71]]}, {"timestamp": 1578773973970, "ltp": 1.05, "tv": 131903.35, "trd": NaN, "batb": NaN, "batl": [[0, 1.05, 2686.71]]}, {"timestamp": 1578773979001, "ltp": 1.05, "tv": 131903.35, "trd": NaN, "batb": NaN, "batl": [[0, 1.05, 2663.44]]}, {"timestamp": 1578773984979, "ltp": 1.05, "tv": 131903.35, "trd": NaN, "batb": [[0, 1.04, 25235.39]], "batl": NaN}, {"timestamp": 1578773985974, "ltp": 1.05, "tv": 131903.35, "trd": NaN, "batb": [[0, 1.04, 25277.95], [2, 1.02, 21847.62]], "batl": [[1, 1.06, 2305.29]]}, {"timestamp": 1578773991010, "ltp": 1.04, "tv": 132032.28, "trd": [[1.04, 128.93]], "batb": [[0, 1.04, 21812.29], [2, 1.02, 21855.27]], "batl": NaN}, {"timestamp": 1578773992010, "ltp": 1.04, "tv": 132032.28, "trd": NaN, "batb": [[1, 1.03, 24863.16]], "batl": NaN}, {"timestamp": 1578773993989, "ltp": 1.04, "tv": 132032.28, "trd": NaN, "batb": [[0, 1.04, 20663.29]], "batl": [[0, 1.05, 3113.44]]}, {"timestamp": 1578774006024, "ltp": 1.04, "tv": 132032.28, "trd": NaN, "batb": [[0, 1.04, 18413.29]], "batl": NaN}, {"timestamp": 1578774012022, "ltp": 1.04, "tv": 132035.19, "trd": [[1.04, 131.84]], "batb": [[0, 1.04, 18411.84]], "batl": NaN}, {"timestamp": 1578774014008, "ltp": 1.04, "tv": 132035.19, "trd": NaN, "batb": [[1, 1.03, 27461.26]], "batl": NaN}, {"timestamp": 1578774016016, "ltp": 1.05, "tv": 132035.22, "trd": [[1.05, 5991.89]], "batb": NaN, "batl": [[0, 1.05, 3113.42]]}, {"timestamp": 1578774027037, "ltp": 1.05, "tv": 132036.8, "trd": [[1.05, 5993.47]], "batb": NaN, "batl": [[0, 1.05, 3112.63]]}, {"timestamp": 1578774030037, "ltp": 1.05, "tv": 132036.8, "trd": NaN, "batb": [[0, 1.04, 18219.84]], "batl": NaN}, {"timestamp": 1578774031045, "ltp": 1.05, "tv": 132062.8, "trd": [[1.05, 6019.47]], "batb": NaN, "batl": [[0, 1.05, 3099.63]]}, {"timestamp": 1578774045970, "ltp": 1.05, "tv": 132062.8, "trd": NaN, "batb": [[0, 1.04, 11416.68]], "batl": [[2, 1.07, 21582.36]]}, {"timestamp": 1578774051984, "ltp": 1.05, "tv": 132062.8, "trd": NaN, "batb": [[0, 1.04, 8865.79], [1, 1.03, 18107.21], [2, 1.02, 12501.22]], "batl": [[1, 1.06, 2347.85]]}, {"timestamp": 1578774053987, "ltp": 1.05, "tv": 132062.8, "trd": NaN, "batb": [[1, 1.03, 15509.11]], "batl": [[0, 1.05, 2649.63]]}, {"timestamp": 1578774055045, "ltp": 1.05, "tv": 132062.8, "trd": NaN, "batb": [[0, 1.04, 8229.89]], "batl": NaN}, {"timestamp": 1578774056979, "ltp": 1.05, "tv": 132062.8, "trd": NaN, "batb": [[1, 1.03, 15512.11]], "batl": NaN}, {"timestamp": 1578774069990, "ltp": 1.05, "tv": 132062.8, "trd": NaN, "batb": [[1, 1.03, 18110.21]], "batl": [[0, 1.05, 3099.63]]}, {"timestamp": 1578774077038, "ltp": 1.05, "tv": 132062.8, "trd": NaN, "batb": [[0, 1.04, 8066.43]], "batl": NaN}, {"timestamp": 1578774081003, "ltp": 1.05, "tv": 132062.8, "trd": NaN, "batb": [[0, 1.04, 7998.56]], "batl": NaN}, {"timestamp": 1578774092916, "ltp": 1.05, "tv": 132062.8, "trd": NaN, "batb": NaN, "batl": [[1, 1.06, 2842.1]]}, {"timestamp": 1578774123986, "ltp": 1.05, "tv": 132062.8, "trd": NaN, "batb": NaN, "batl": [[1, 1.06, 2756.98]]}, {"timestamp": 1578774129973, "ltp": 1.05, "tv": 132062.8, "trd": NaN, "batb": NaN, "batl": [[0, 1.05, 3107.28]]}, {"timestamp": 1578774140000, "ltp": 1.05, "tv": 132062.8, "trd": NaN, "batb": NaN, "batl": [[0, 1.05, 3099.63]]}, {"timestamp": 1578774144020, "ltp": 1.05, "tv": 132062.8, "trd": NaN, "batb": NaN, "batl": [[1, 1.06, 4842.1]]}, {"timestamp": 1578774146999, "ltp": 1.04, "tv": 132078.11, "trd": [[1.04, 147.15]], "batb": [[0, 1.04, 7990.91]], "batl": NaN}, {"timestamp": 1578774151033, "ltp": 1.04, "tv": 132078.11, "trd": NaN, "batb": NaN, "batl": [[1, 1.06, 4756.98]]}, {"timestamp": 1578774153915, "ltp": 1.04, "tv": 132078.11, "trd": NaN, "batb": [[1, 1.03, 18108.21], [2, 1.02, 12499.22]], "batl": [[1, 1.06, 4262.73], [2, 1.07, 21184.86]]}, {"timestamp": 1578774158047, "ltp": 1.04, "tv": 132078.11, "trd": NaN, "batb": NaN, "batl": [[0, 1.05, 3184.75]]}, {"timestamp": 1578774162052, "ltp": 1.04, "tv": 132078.11, "trd": NaN, "batb": NaN, "batl": [[1, 1.06, 4274.73]]}, {"timestamp": 1578774171053, "ltp": 1.05, "tv": 132079.99, "trd": [[1.05, 6021.34]], "batb": NaN, "batl": [[0, 1.05, 3183.82]]}, {"timestamp": 1578774171945, "ltp": 1.05, "tv": 132079.99, "trd": NaN, "batb": [[0, 1.04, 7948.35]], "batl": NaN}, {"timestamp": 1578774184977, "ltp": 1.05, "tv": 132079.99, "trd": NaN, "batb": [[1, 1.03, 18125.24]], "batl": NaN}, {"timestamp": 1578774186973, "ltp": 1.05, "tv": 132079.99, "trd": NaN, "batb": [[0, 1.04, 7476.89]], "batl": NaN}, {"timestamp": 1578774189965, "ltp": 1.04, "tv": 132209.99, "trd": [[1.04, 277.15]], "batb": [[0, 1.04, 6645.8]], "batl": NaN}, {"timestamp": 1578774190957, "ltp": 1.05, "tv": 132212.83, "trd": [[1.05, 6024.19]], "batb": NaN, "batl": [[0, 1.05, 3182.39]]}, {"timestamp": 1578774191962, "ltp": 1.05, "tv": 132212.83, "trd": NaN, "batb": NaN, "batl": [[1, 1.06, 4286.73]]}, {"timestamp": 1578774195977, "ltp": 1.05, "tv": 132212.83, "trd": NaN, "batb": [[0, 1.04, 6539.4]], "batl": NaN}, {"timestamp": 1578774205970, "ltp": 1.05, "tv": 132212.83, "trd": NaN, "batb": [[1, 1.03, 15527.14]], "batl": [[0, 1.05, 2732.39]]}, {"timestamp": 1578774211982, "ltp": 1.05, "tv": 132212.83, "trd": NaN, "batb": [[0, 1.04, 6154.4]], "batl": NaN}, {"timestamp": 1578774217033, "ltp": 1.04, "tv": 132240.83, "trd": [[1.04, 305.15]], "batb": [[0, 1.04, 6140.4]], "batl": NaN}, {"timestamp": 1578774220028, "ltp": 1.04, "tv": 132240.83, "trd": NaN, "batb": NaN, "batl": [[2, 1.07, 20004.86]]}, {"timestamp": 1578774222019, "ltp": 1.04, "tv": 132240.83, "trd": NaN, "batb": NaN, "batl": [[1, 1.06, 4298.73]]}, {"timestamp": 1578774227020, "ltp": 1.04, "tv": 134734.83, "trd": [[1.04, 2799.15]], "batb": [[0, 1.04, 4893.4]], "batl": NaN}, {"timestamp": 1578774228032, "ltp": 1.04, "tv": 134734.83, "trd": NaN, "batb": [[0, 1.04, 4779.37]], "batl": NaN}, {"timestamp": 1578774231028, "ltp": 1.04, "tv": 134734.83, "trd": NaN, "batb": [[2, 1.02, 13707.22]], "batl": NaN}, {"timestamp": 1578774237963, "ltp": 1.04, "tv": 134734.83, "trd": NaN, "batb": [[0, 1.04, 322.3]], "batl": [[1, 1.06, 3961.46]]}, {"timestamp": 1578774239016, "ltp": 1.04, "tv": 134848.27, "trd": [[1.04, 2912.59]], "batb": [[0, 1.03, 15527.14], [1, 1.02, 13707.22], [2, 1.01, 48041.82]], "batl": [[0, 1.04, 390.24], [1, 1.05, 2732.39], [2, 1.06, 3792.22]]}, {"timestamp": 1578774240011, "ltp": 1.04, "tv": 134848.27, "trd": NaN, "batb": NaN, "batl": [[2, 1.06, 3641.83]]}, {"timestamp": 1578774240956, "ltp": 1.04, "tv": 134848.27, "trd": NaN, "batb": NaN, "batl": [[1, 1.05, 2718.53]]}, {"timestamp": 1578774241952, "ltp": 1.04, "tv": 134848.27, "trd": NaN, "batb": NaN, "batl": [[2, 1.06, 3304.56]]}, {"timestamp": 1578774244962, "ltp": 1.04, "tv": 134848.27, "trd": NaN, "batb": NaN, "batl": [[0, 1.04, 444.13]]}, {"timestamp": 1578774245956, "ltp": 1.04, "tv": 134848.27, "trd": NaN, "batb": [[2, 1.01, 48541.82]], "batl": [[0, 1.04, 499.72], [1, 1.05, 2268.53]]}, {"timestamp": 1578774246953, "ltp": 1.04, "tv": 134848.27, "trd": NaN, "batb": NaN, "batl": [[0, 1.04, 653.87]]}, {"timestamp": 1578774247950, "ltp": 1.04, "tv": 134848.27, "trd": NaN, "batb": [[2, 1.01, 48041.82]], "batl": [[0, 1.04, 698.45], [2, 1.06, 3262]]}, {"timestamp": 1578774248942, "ltp": 1.04, "tv": 134848.27, "trd": NaN, "batb": NaN, "batl": [[0, 1.04, 1042.21]]}, {"timestamp": 1578774249956, "ltp": 1.04, "tv": 134848.27, "trd": NaN, "batb": NaN, "batl": [[0, 1.04, 698.45]]}, {"timestamp": 1578774252049, "ltp": 1.04, "tv": 134848.27, "trd": NaN, "batb": NaN, "batl": [[1, 1.05, 2280.53]]}, {"timestamp": 1578774253047, "ltp": 1.04, "tv": 134848.27, "trd": NaN, "batb": NaN, "batl": [[0, 1.04, 1148.45]]}, {"timestamp": 1578774254039, "ltp": 1.04, "tv": 134848.27, "trd": NaN, "batb": [[0, 1.03, 15569.7]], "batl": [[1, 1.05, 2323.09]]}, {"timestamp": 1578774262968, "ltp": 1.03, "tv": 134852.15, "trd": [[1.03, 3.88]], "batb": [[0, 1.03, 15567.76]], "batl": [[0, 1.04, 1165.47]]}, {"timestamp": 1578774271965, "ltp": 1.03, "tv": 134852.15, "trd": NaN, "batb": [[0, 1.03, 15373.76]], "batl": NaN}, {"timestamp": 1578774280986, "ltp": 1.03, "tv": 134852.15, "trd": NaN, "batb": [[1, 1.02, 13709.22], [2, 1.01, 48043.82]], "batl": [[2, 1.06, 3730.25]]}, {"timestamp": 1578774282993, "ltp": 1.03, "tv": 134852.15, "trd": NaN, "batb": NaN, "batl": [[1, 1.05, 2335.09]]}, {"timestamp": 1578774283986, "ltp": 1.03, "tv": 134852.15, "trd": NaN, "batb": NaN, "batl": [[1, 1.05, 2911.99]]}, {"timestamp": 1578774285993, "ltp": 1.03, "tv": 134852.15, "trd": NaN, "batb": [[0, 1.03, 12775.66]], "batl": NaN}, {"timestamp": 1578774293021, "ltp": 1.03, "tv": 134852.15, "trd": NaN, "batb": [[0, 1.03, 9374.46], [1, 1.02, 16891.22]], "batl": NaN}, {"timestamp": 1578774296012, "ltp": 1.03, "tv": 134852.15, "trd": NaN, "batb": NaN, "batl": [[0, 1.04, 2351.47]]}, {"timestamp": 1578774300030, "ltp": 1.03, "tv": 134852.15, "trd": NaN, "batb": [[2, 1.01, 51445.01]], "batl": NaN}, {"timestamp": 1578774304037, "ltp": 1.03, "tv": 134852.15, "trd": NaN, "batb": NaN, "batl": [[0, 1.04, 3038.99]]}, {"timestamp": 1578774313016, "ltp": 1.03, "tv": 134852.15, "trd": NaN, "batb": NaN, "batl": [[1, 1.05, 2923.99]]}, {"timestamp": 1578774322965, "ltp": 1.03, "tv": 134852.15, "trd": NaN, "batb": [[0, 1.03, 8995.27]], "batl": NaN}, {"timestamp": 1578774324963, "ltp": 1.03, "tv": 134852.15, "trd": NaN, "batb": NaN, "batl": [[1, 1.05, 4923.99]]}, {"timestamp": 1578774327056, "ltp": 1.03, "tv": 134852.15, "trd": NaN, "batb": [[0, 1.03, 8585.39]], "batl": NaN}, {"timestamp": 1578774328055, "ltp": 1.03, "tv": 134852.15, "trd": NaN, "batb": NaN, "batl": [[0, 1.04, 1852.99]]}, {"timestamp": 1578774330040, "ltp": 1.03, "tv": 134852.15, "trd": NaN, "batb": NaN, "batl": [[1, 1.05, 2923.99]]}, {"timestamp": 1578774331043, "ltp": 1.03, "tv": 134852.15, "trd": NaN, "batb": [[0, 1.03, 7344.39]], "batl": NaN}, {"timestamp": 1578774335960, "ltp": 1.03, "tv": 134918.15, "trd": [[1.03, 69.89]], "batb": [[0, 1.03, 7311.38]], "batl": NaN}, {"timestamp": 1578774337978, "ltp": 1.03, "tv": 134918.15, "trd": NaN, "batb": NaN, "batl": [[0, 1.04, 3093.99]]}, {"timestamp": 1578774340966, "ltp": 1.03, "tv": 134918.15, "trd": NaN, "batb": [[0, 1.03, 6835.32]], "batl": NaN}, {"timestamp": 1578774342958, "ltp": 1.03, "tv": 134918.15, "trd": NaN, "batb": NaN, "batl": [[1, 1.05, 2935.99]]}, {"timestamp": 1578774343955, "ltp": 1.03, "tv": 134918.15, "trd": NaN, "batb": [[0, 1.03, 6069.23]], "batl": NaN}, {"timestamp": 1578774351002, "ltp": 1.03, "tv": 134918.15, "trd": NaN, "batb": NaN, "batl": [[1, 1.05, 4935.99]]}, {"timestamp": 1578774364987, "ltp": 1.03, "tv": 134918.15, "trd": NaN, "batb": [[0, 1.03, 6052.21]], "batl": NaN}, {"timestamp": 1578774373028, "ltp": 1.03, "tv": 134918.15, "trd": NaN, "batb": NaN, "batl": [[1, 1.05, 4947.99]]}, {"timestamp": 1578774377036, "ltp": 1.03, "tv": 134918.15, "trd": NaN, "batb": [[2, 1.01, 51452.66]], "batl": NaN}, {"timestamp": 1578774384023, "ltp": 1.03, "tv": 135052.15, "trd": [[1.03, 203.88]], "batb": [[0, 1.03, 5985.21]], "batl": NaN}, {"timestamp": 1578774389047, "ltp": 1.03, "tv": 135052.15, "trd": NaN, "batb": NaN, "batl": [[1, 1.05, 4862.87]]}, {"timestamp": 1578774391041, "ltp": 1.03, "tv": 135066.16, "trd": [[1.03, 217.89]], "batb": [[0, 1.03, 5978.21]], "batl": NaN}, {"timestamp": 1578774394041, "ltp": 1.03, "tv": 135066.16, "trd": NaN, "batb": [[1, 1.02, 16889.22], [2, 1.01, 51450.66]], "batl": [[1, 1.05, 4285.97], [2, 1.06, 3262]]}, {"timestamp": 1578774395036, "ltp": 1.03, "tv": 135066.16, "trd": NaN, "batb": NaN, "batl": [[0, 1.04, 3179.11]]}, {"timestamp": 1578774398961, "ltp": 1.03, "tv": 135066.16, "trd": NaN, "batb": NaN, "batl": [[0, 1.04, 1938.11]]}, {"timestamp": 1578774402970, "ltp": 1.03, "tv": 135066.16, "trd": NaN, "batb": NaN, "batl": [[1, 1.05, 4297.97]]}, {"timestamp": 1578774413031, "ltp": 1.03, "tv": 135066.16, "trd": NaN, "batb": [[1, 1.02, 13707.22]], "batl": [[0, 1.04, 1488.11]]}, {"timestamp": 1578774413998, "ltp": 1.04, "tv": 135117.4, "trd": [[1.04, 2963.83]], "batb": NaN, "batl": [[0, 1.04, 1436.86]]}, {"timestamp": 1578774421011, "ltp": 1.04, "tv": 135117.4, "trd": NaN, "batb": [[2, 1.01, 51950.66]], "batl": NaN}, {"timestamp": 1578774422007, "ltp": 1.04, "tv": 135117.4, "trd": NaN, "batb": [[2, 1.01, 51450.66]], "batl": NaN}, {"timestamp": 1578774426968, "ltp": 1.04, "tv": 135117.4, "trd": NaN, "batb": [[0, 1.03, 5935.65]], "batl": NaN}, {"timestamp": 1578774433002, "ltp": 1.04, "tv": 135117.4, "trd": NaN, "batb": NaN, "batl": [[1, 1.05, 4309.97]]}, {"timestamp": 1578774446027, "ltp": 1.04, "tv": 135117.4, "trd": NaN, "batb": NaN, "batl": [[0, 1.04, 1351.74], [1, 1.05, 4267.41]]}, {"timestamp": 1578774447029, "ltp": 1.04, "tv": 135117.91, "trd": [[1.04, 2964.34]], "batb": NaN, "batl": [[0, 1.04, 1351.49]]}, {"timestamp": 1578774451833, "ltp": 1.04, "tv": 135117.91, "trd": NaN, "batb": [[0, 1.03, 5410.65]], "batl": NaN}, {"timestamp": 1578774453921, "ltp": 1.04, "tv": 135117.91, "trd": NaN, "batb": [[2, 1.01, 51950.66]], "batl": NaN}, {"timestamp": 1578774455019, "ltp": 1.04, "tv": 135117.91, "trd": NaN, "batb": [[2, 1.01, 51450.66]], "batl": NaN}, {"timestamp": 1578774462974, "ltp": 1.04, "tv": 135117.91, "trd": NaN, "batb": NaN, "batl": [[1, 1.05, 4279.41]]}, {"timestamp": 1578774469972, "ltp": 1.04, "tv": 135270.97, "trd": [[1.04, 3117.41]], "batb": NaN, "batl": [[0, 1.04, 1274.96]]}, {"timestamp": 1578774478966, "ltp": 1.04, "tv": 135270.97, "trd": NaN, "batb": [[2, 1.01, 51500.66]], "batl": NaN}, {"timestamp": 1578774484980, "ltp": 1.04, "tv": 135270.97, "trd": NaN, "batb": [[0, 1.03, 410.65]], "batl": [[0, 1.04, 587.44], [1, 1.05, 3699.94]]}, {"timestamp": 1578774485978, "ltp": 1.04, "tv": 135270.97, "trd": NaN, "batb": [[0, 1.03, 7.12]], "batl": [[0, 1.04, 323.81], [1, 1.05, 3341.02]]}, {"timestamp": 1578774492978, "ltp": 1.03, "tv": 135285.21, "trd": [[1.03, 232.12]], "batb": [[0, 1.02, 13707.22], [1, 1.01, 51500.66], [2, 1.01, 0]], "batl": [[0, 1.03, 2.39], [1, 1.04, 323.81], [2, 1.05, 3353.02]]}, {"timestamp": 1578774494963, "ltp": 1.03, "tv": 135285.21, "trd": NaN, "batb": NaN, "batl": [[2, 1.05, 3370.93]]}, {"timestamp": 1578774497007, "ltp": 1.03, "tv": 135285.21, "trd": NaN, "batb": NaN, "batl": [[0, 1.03, 101.7]]}, {"timestamp": 1578774500996, "ltp": 1.03, "tv": 135285.21, "trd": NaN, "batb": NaN, "batl": [[0, 1.03, 219.08]]}, {"timestamp": 1578774503986, "ltp": 1.03, "tv": 135285.21, "trd": NaN, "batb": NaN, "batl": [[1, 1.04, 279.23]]}, {"timestamp": 1578774506019, "ltp": 1.02, "tv": 135331.13, "trd": [[1.02, 45.92]], "batb": [[0, 1.02, 13684.26]], "batl": NaN}, {"timestamp": 1578774510920, "ltp": 1.02, "tv": 135331.13, "trd": NaN, "batb": NaN, "batl": [[0, 1.03, 263.66]]}, {"timestamp": 1578774517996, "ltp": 1.02, "tv": 135331.13, "trd": NaN, "batb": NaN, "batl": [[0, 1.03, 264.09]]}, {"timestamp": 1578774521029, "ltp": 1.03, "tv": 135335.23, "trd": [[1.03, 236.22]], "batb": NaN, "batl": [[0, 1.03, 262.04]]}, {"timestamp": 1578774521915, "ltp": 1.03, "tv": 135335.23, "trd": NaN, "batb": [[1, 1.01, 51506.66]], "batl": [[2, 1.05, 3926.43]]}, {"timestamp": 1578774523023, "ltp": 1.03, "tv": 135335.23, "trd": NaN, "batb": NaN, "batl": [[1, 1.04, 291.23]]}, {"timestamp": 1578774525926, "ltp": 1.03, "tv": 135335.23, "trd": NaN, "batb": [[0, 1.02, 13488.26], [1, 1.01, 51308.66]], "batl": [[2, 1.05, 3370.93]]}, {"timestamp": 1578774563963, "ltp": 1.03, "tv": 135335.23, "trd": NaN, "batb": [[0, 1.02, 12280.26]], "batl": NaN}, {"timestamp": 1578774566004, "ltp": 1.03, "tv": 135335.23, "trd": NaN, "batb": [[1, 1.01, 53775.66]], "batl": [[0, 1.03, 1461.04], [1, 1.04, 1424.23]]}, {"timestamp": 1578774568916, "ltp": 1.03, "tv": 135335.23, "trd": NaN, "batb": NaN, "batl": [[0, 1.03, 262.04]]}, {"timestamp": 1578774570010, "ltp": 1.03, "tv": 135335.23, "trd": NaN, "batb": [[1, 1.01, 53973.66]], "batl": NaN}, {"timestamp": 1578774573986, "ltp": 1.02, "tv": 135341.05, "trd": [[1.02, 51.74]], "batb": [[0, 1.02, 12277.36]], "batl": NaN}, {"timestamp": 1578774576024, "ltp": 1.02, "tv": 135341.05, "trd": NaN, "batb": NaN, "batl": [[0, 1.03, 217.03]]}, {"timestamp": 1578774581022, "ltp": 1.02, "tv": 135341.05, "trd": NaN, "batb": [[1, 1.01, 53775.66]], "batl": NaN}, {"timestamp": 1578774583000, "ltp": 1.02, "tv": 135341.05, "trd": NaN, "batb": NaN, "batl": [[0, 1.03, 254.4]]}, {"timestamp": 1578774584046, "ltp": 1.03, "tv": 135369.15, "trd": [[1.03, 264.32]], "batb": NaN, "batl": [[0, 1.03, 271.31]]}, {"timestamp": 1578774586037, "ltp": 1.03, "tv": 135384.91, "trd": [[1.03, 280.09]], "batb": NaN, "batl": [[0, 1.03, 263.43]]}, {"timestamp": 1578774590041, "ltp": 1.03, "tv": 135384.91, "trd": NaN, "batb": NaN, "batl": [[1, 1.04, 1466.79]]}, {"timestamp": 1578774595039, "ltp": 1.03, "tv": 135384.91, "trd": NaN, "batb": [[0, 1.02, 8876.16], [1, 1.01, 53973.66]], "batl": NaN}, {"timestamp": 1578774596926, "ltp": 1.03, "tv": 135385.07, "trd": [[1.03, 280.24]], "batb": [[0, 1.02, 7879.23]], "batl": [[0, 1.03, 263.35]]}, {"timestamp": 1578774601020, "ltp": 1.03, "tv": 135385.07, "trd": NaN, "batb": [[0, 1.02, 7822.28]], "batl": NaN}, {"timestamp": 1578774602037, "ltp": 1.03, "tv": 135385.07, "trd": NaN, "batb": [[0, 1.02, 7864.84], [1, 1.01, 57374.86]], "batl": NaN}, {"timestamp": 1578774605030, "ltp": 1.03, "tv": 135385.07, "trd": NaN, "batb": NaN, "batl": [[1, 1.04, 2217.42], [2, 1.05, 3948.23]]}, {"timestamp": 1578774606033, "ltp": 1.03, "tv": 135409.8, "trd": [[1.03, 304.97]], "batb": NaN, "batl": [[0, 1.03, 238.62]]}, {"timestamp": 1578774608974, "ltp": 1.02, "tv": 135949.01, "trd": [[1.02, 590.95]], "batb": [[0, 1.02, 7325.63]], "batl": NaN}, {"timestamp": 1578774612957, "ltp": 1.02, "tv": 135949.01, "trd": NaN, "batb": NaN, "batl": [[1, 1.04, 2229.42]]}, {"timestamp": 1578774619982, "ltp": 1.02, "tv": 135949.01, "trd": NaN, "batb": NaN, "batl": [[0, 1.03, 163.88]]}, {"timestamp": 1578774622998, "ltp": 1.02, "tv": 135949.01, "trd": NaN, "batb": [[0, 1.02, 6559.54]], "batl": NaN}, {"timestamp": 1578774624982, "ltp": 1.02, "tv": 135949.01, "trd": NaN, "batb": NaN, "batl": [[1, 1.04, 2247.33]]}, {"timestamp": 1578774629951, "ltp": 1.02, "tv": 135949.01, "trd": NaN, "batb": NaN, "batl": [[0, 1.03, 161.67]]}, {"timestamp": 1578774636008, "ltp": 1.02, "tv": 135949.01, "trd": NaN, "batb": [[0, 1.02, 6060.1]], "batl": [[0, 1.03, 1398.67]]}, {"timestamp": 1578774643024, "ltp": 1.02, "tv": 136099.68, "trd": [[1.02, 741.62]], "batb": [[0, 1.02, 5984.77]], "batl": [[0, 1.03, 1848.67], [1, 1.04, 2259.33]]}, {"timestamp": 1578774644024, "ltp": 1.02, "tv": 136099.68, "trd": NaN, "batb": NaN, "batl": [[0, 1.03, 1850.88]]}, {"timestamp": 1578774647020, "ltp": 1.02, "tv": 136180.81, "trd": [[1.02, 822.75]], "batb": [[0, 1.02, 5944.2]], "batl": NaN}, {"timestamp": 1578774655896, "ltp": 1.02, "tv": 136180.81, "trd": NaN, "batb": [[0, 1.02, 5837.8]], "batl": NaN}, {"timestamp": 1578774667046, "ltp": 1.02, "tv": 136180.81, "trd": NaN, "batb": [[1, 1.01, 57415.42]], "batl": NaN}, {"timestamp": 1578774672960, "ltp": 1.02, "tv": 136180.81, "trd": NaN, "batb": NaN, "batl": [[1, 1.04, 2271.33]]}, {"timestamp": 1578774679977, "ltp": 1.02, "tv": 136180.81, "trd": NaN, "batb": [[0, 1.02, 5854.82]], "batl": NaN}, {"timestamp": 1578774683041, "ltp": 1.02, "tv": 136180.81, "trd": NaN, "batb": [[0, 1.02, 870.46]], "batl": NaN}, {"timestamp": 1578774685948, "ltp": 1.02, "tv": 136180.81, "trd": NaN, "batb": NaN, "batl": [[0, 1.03, 1936]]}, {"timestamp": 1578774687056, "ltp": 1.02, "tv": 136180.81, "trd": NaN, "batb": NaN, "batl": [[1, 1.04, 4271.33]]}, {"timestamp": 1578774692006, "ltp": 1.02, "tv": 136209.32, "trd": [[1.02, 851.26]], "batb": [[0, 1.02, 856.2]], "batl": [[0, 1.03, 2804.5], [2, 1.05, 3370.93]]}, {"timestamp": 1578774694953, "ltp": 1.02, "tv": 136284.07, "trd": [[1.02, 926.01]], "batb": [[0, 1.02, 818.83]], "batl": NaN}, {"timestamp": 1578774695998, "ltp": 1.02, "tv": 136284.07, "trd": NaN, "batb": [[1, 1.01, 57413.42]], "batl": [[0, 1.03, 1936], [1, 1.04, 3520.7]]}, {"timestamp": 1578774702028, "ltp": 1.02, "tv": 136284.07, "trd": NaN, "batb": [[0, 1.02, 801.81]], "batl": NaN}, {"timestamp": 1578774702972, "ltp": 1.02, "tv": 136284.07, "trd": NaN, "batb": NaN, "batl": [[1, 1.04, 3532.7]]}, {"timestamp": 1578774721011, "ltp": 1.02, "tv": 136284.07, "trd": NaN, "batb": [[0, 1.02, 381.44]], "batl": NaN}, {"timestamp": 1578774723022, "ltp": 1.02, "tv": 136284.07, "trd": NaN, "batb": NaN, "batl": [[0, 1.03, 1486]]}, {"timestamp": 1578774733011, "ltp": 1.02, "tv": 136284.07, "trd": NaN, "batb": NaN, "batl": [[1, 1.04, 3544.7]]}, {"timestamp": 1578774735033, "ltp": 1.02, "tv": 136284.07, "trd": NaN, "batb": [[0, 1.02, 283.9]], "batl": NaN}, {"timestamp": 1578774741046, "ltp": 1.02, "tv": 136284.07, "trd": NaN, "batb": NaN, "batl": [[1, 1.04, 3502.14]]}, {"timestamp": 1578774742926, "ltp": 1.02, "tv": 136851.87, "trd": [[1.02, 1493.81]], "batb": [[0, 1.01, 57413.42], [1, 1.01, 0]], "batl": [[0, 1.02, 41.9], [1, 1.03, 1486], [2, 1.04, 3502.14]]}, {"timestamp": 1578774745032, "ltp": 1.02, "tv": 136851.87, "trd": NaN, "batb": NaN, "batl": [[0, 1.02, 42.06], [1, 1.03, 1471.77]]}, {"timestamp": 1578774747956, "ltp": 1.02, "tv": 136851.87, "trd": NaN, "batb": NaN, "batl": [[1, 1.03, 1514.33]]}, {"timestamp": 1578774751843, "ltp": 1.02, "tv": 136851.87, "trd": NaN, "batb": NaN, "batl": [[1, 1.03, 1483.55]]}, {"timestamp": 1578774753036, "ltp": 1.02, "tv": 136851.87, "trd": NaN, "batb": NaN, "batl": [[0, 1.02, 195.13]]}, {"timestamp": 1578774756967, "ltp": 1.02, "tv": 136851.87, "trd": NaN, "batb": NaN, "batl": [[0, 1.02, 194.97]]}, {"timestamp": 1578774758957, "ltp": 1.02, "tv": 136851.87, "trd": NaN, "batb": NaN, "batl": [[0, 1.02, 323.09]]}, {"timestamp": 1578774763050, "ltp": 1.02, "tv": 136851.87, "trd": NaN, "batb": NaN, "batl": [[0, 1.02, 356.09], [1, 1.03, 2482.05], [2, 1.04, 4139.27]]}, {"timestamp": 1578774763948, "ltp": 1.02, "tv": 136851.87, "trd": NaN, "batb": NaN, "batl": [[1, 1.03, 4482.05]]}, {"timestamp": 1578774765971, "ltp": 1.02, "tv": 136851.87, "trd": NaN, "batb": NaN, "batl": [[0, 1.02, 356.97]]}, {"timestamp": 1578774773048, "ltp": 1.01, "tv": 136863.49, "trd": [[1.01, 11.62]], "batb": [[0, 1.01, 57407.61]], "batl": [[0, 1.02, 358.47]]}, {"timestamp": 1578774780970, "ltp": 1.01, "tv": 136863.49, "trd": NaN, "batb": NaN, "batl": [[0, 1.02, 360.09]]}, {"timestamp": 1578774783958, "ltp": 1.01, "tv": 136863.49, "trd": NaN, "batb": NaN, "batl": [[0, 1.02, 1620.09]]}, {"timestamp": 1578774787989, "ltp": 1.01, "tv": 136863.49, "trd": NaN, "batb": NaN, "batl": [[0, 1.02, 1620.16]]}, {"timestamp": 1578774794997, "ltp": 1.01, "tv": 136863.49, "trd": NaN, "batb": NaN, "batl": [[0, 1.02, 1630.76]]}, {"timestamp": 1578774801005, "ltp": 1.01, "tv": 136863.49, "trd": NaN, "batb": NaN, "batl": [[0, 1.02, 1801]]}, {"timestamp": 1578774805020, "ltp": 1.01, "tv": 136863.49, "trd": NaN, "batb": [[0, 1.01, 61907.61]], "batl": [[1, 1.03, 4932.05]]}, {"timestamp": 1578774816020, "ltp": 1.01, "tv": 136863.49, "trd": NaN, "batb": [[0, 1.01, 61992.73]], "batl": [[1, 1.03, 3933.55], [2, 1.04, 3502.14]]}, {"timestamp": 1578774817032, "ltp": 1.02, "tv": 136871.61, "trd": [[1.02, 1501.93]], "batb": NaN, "batl": [[0, 1.02, 1796.94]]}, {"timestamp": 1578774820026, "ltp": 1.02, "tv": 136871.61, "trd": NaN, "batb": [[0, 1.01, 61886.33]], "batl": NaN}, {"timestamp": 1578774828019, "ltp": 1.02, "tv": 136871.69, "trd": [[1.02, 1502.01]], "batb": NaN, "batl": [[0, 1.02, 1796.9]]}, {"timestamp": 1578774831034, "ltp": 1.02, "tv": 136871.69, "trd": NaN, "batb": NaN, "batl": [[1, 1.03, 3890.99]]}, {"timestamp": 1578774837040, "ltp": 1.02, "tv": 136871.69, "trd": NaN, "batb": NaN, "batl": [[1, 1.03, 3810.98]]}, {"timestamp": 1578774843952, "ltp": 1.02, "tv": 136871.69, "trd": NaN, "batb": [[0, 1.01, 59419.33]], "batl": NaN}, {"timestamp": 1578774845954, "ltp": 1.02, "tv": 136871.69, "trd": NaN, "batb": [[0, 1.01, 54919.33]], "batl": [[1, 1.03, 3360.98]]}, {"timestamp": 1578774846965, "ltp": 1.02, "tv": 136871.69, "trd": NaN, "batb": NaN, "batl": [[1, 1.03, 3403.54]]}, {"timestamp": 1578774850048, "ltp": 1.02, "tv": 136871.69, "trd": NaN, "batb": NaN, "batl": [[1, 1.03, 3360.98]]}, {"timestamp": 1578774857957, "ltp": 1.02, "tv": 136871.69, "trd": NaN, "batb": [[0, 1.01, 59419.33]], "batl": [[1, 1.03, 3810.98]]}, {"timestamp": 1578774858976, "ltp": 1.02, "tv": 136871.69, "trd": NaN, "batb": NaN, "batl": [[1, 1.03, 3853.54]]}, {"timestamp": 1578774859971, "ltp": 1.02, "tv": 136871.69, "trd": NaN, "batb": [[0, 1.01, 54919.33]], "batl": [[1, 1.03, 3403.54]]}, {"timestamp": 1578774860994, "ltp": 1.02, "tv": 136871.69, "trd": NaN, "batb": [[0, 1.01, 54721.33]], "batl": NaN}, {"timestamp": 1578774871029, "ltp": 1.02, "tv": 136956.81, "trd": [[1.02, 1587.13]], "batb": NaN, "batl": [[0, 1.02, 1754.34]]}, {"timestamp": 1578774896006, "ltp": 1.02, "tv": 136956.81, "trd": NaN, "batb": NaN, "batl": [[0, 1.02, 1721.34]]}, {"timestamp": 1578774906014, "ltp": 1.02, "tv": 136956.81, "trd": NaN, "batb": [[0, 1.01, 59221.33]], "batl": [[0, 1.02, 2171.34]]}, {"timestamp": 1578774914033, "ltp": 1.02, "tv": 136956.81, "trd": NaN, "batb": [[0, 1.01, 54721.33]], "batl": [[0, 1.02, 1721.34]]}, {"timestamp": 1578774915958, "ltp": 1.02, "tv": 136956.81, "trd": NaN, "batb": [[0, 1.01, 59221.33]], "batl": [[1, 1.03, 3853.54]]}, {"timestamp": 1578774930982, "ltp": 1.02, "tv": 136956.84, "trd": [[1.02, 1587.16]], "batb": NaN, "batl": [[0, 1.02, 1721.33]]}, {"timestamp": 1578774951987, "ltp": 1.02, "tv": 138678.17, "trd": [[1.02, 3308.49]], "batb": NaN, "batl": [[0, 1.03, 3853.54], [1, 1.04, 3502.14], [2, 1.05, 2142.93]]}, {"timestamp": 1578774953021, "ltp": 1.02, "tv": 138678.17, "trd": NaN, "batb": [[0, 1.01, 61632.33]], "batl": NaN}, {"timestamp": 1578774954803, "ltp": 1.02, "tv": 138678.17, "trd": NaN, "batb": NaN, "batl": [[0, 1.03, 3871.45]]}, {"timestamp": 1578774957899, "ltp": 1.02, "tv": 138678.17, "trd": NaN, "batb": [[0, 1.01, 61804.26]], "batl": NaN}, {"timestamp": 1578774963028, "ltp": 1.02, "tv": 138678.17, "trd": NaN, "batb": NaN, "batl": [[0, 1.02, 17.02], [1, 1.03, 3871.45], [2, 1.04, 3502.14]]}, {"timestamp": 1578774969021, "ltp": 1.02, "tv": 138678.17, "trd": NaN, "batb": NaN, "batl": [[0, 1.02, 40.45]]}, {"timestamp": 1578774971013, "ltp": 1.02, "tv": 138678.17, "trd": NaN, "batb": [[0, 1.01, 61811.91]], "batl": [[0, 1.02, 53.75]]}, {"timestamp": 1578774979041, "ltp": 1.02, "tv": 138678.17, "trd": NaN, "batb": NaN, "batl": [[0, 1.02, 30.33]]}, {"timestamp": 1578775015784, "ltp": 1.02, "tv": 138678.17, "trd": NaN, "batb": NaN, "batl": [[0, 1.02, 127.67]]}, {"timestamp": 1578775019802, "ltp": 1.02, "tv": 138678.17, "trd": NaN, "batb": NaN, "batl": [[0, 1.02, 151.1]]}, {"timestamp": 1578775029003, "ltp": 1.01, "tv": 138683.53, "trd": [[1.01, 16.98]], "batb": [[0, 1.01, 61809.23]], "batl": NaN}, {"timestamp": 1578775030899, "ltp": 1.01, "tv": 138683.53, "trd": NaN, "batb": [[0, 1.01, 61810.94]], "batl": NaN}, {"timestamp": 1578775031697, "ltp": 1.01, "tv": 138683.53, "trd": NaN, "batb": NaN, "batl": [[0, 1.02, 162.6]]}, {"timestamp": 1578775035027, "ltp": 1.01, "tv": 138683.53, "trd": NaN, "batb": NaN, "batl": [[0, 1.02, 174.1]]}, {"timestamp": 1578775035714, "ltp": 1.01, "tv": 138683.53, "trd": NaN, "batb": NaN, "batl": [[0, 1.02, 185.6]]}, {"timestamp": 1578775036917, "ltp": 1.01, "tv": 138683.53, "trd": NaN, "batb": NaN, "batl": [[0, 1.02, 197.1]]}, {"timestamp": 1578775056027, "ltp": 1.02, "tv": 138880.64, "trd": [[1.02, 3505.6]], "batb": NaN, "batl": [[0, 1.02, 98.54]]}, {"timestamp": 1578775058030, "ltp": 1.02, "tv": 138880.64, "trd": NaN, "batb": NaN, "batl": [[0, 1.02, 75.12]]}, {"timestamp": 1578775068857, "ltp": 1.02, "tv": 138880.64, "trd": NaN, "batb": NaN, "batl": [[0, 1.02, 94.83]]}, {"timestamp": 1578775083980, "ltp": 1.02, "tv": 138880.64, "trd": NaN, "batb": NaN, "batl": [[0, 1.02, 118.25]]}, {"timestamp": 1578775084975, "ltp": 1.02, "tv": 138880.64, "trd": NaN, "batb": NaN, "batl": [[0, 1.02, 94.83]]}, {"timestamp": 1578775112034, "ltp": 1.02, "tv": 138885.23, "trd": [[1.02, 3510.19]], "batb": NaN, "batl": [[0, 1.02, 92.53]]}, {"timestamp": 1578775132036, "ltp": 1.01, "tv": 139650.57, "trd": [[1.01, 782.32]], "batb": [[0, 1.01, 61428.26]], "batl": NaN}, {"timestamp": 1578775138048, "ltp": 1.01, "tv": 139650.57, "trd": NaN, "batb": NaN, "batl": [[0, 1.02, 115.95]]}, {"timestamp": 1578775158959, "ltp": 1.01, "tv": 139814.36, "trd": [[1.01, 946.11]], "batb": [[0, 1.01, 61346.37]], "batl": NaN}, {"timestamp": 1578775179944, "ltp": 1.02, "tv": 139930.31, "trd": [[1.02, 3626.14]], "batb": NaN, "batl": [[0, 1.03, 3871.45], [1, 1.04, 3502.14], [2, 1.05, 2144.64]]}, {"timestamp": 1578775182017, "ltp": 1.02, "tv": 139930.31, "trd": NaN, "batb": [[0, 1.02, 23.42], [1, 1.01, 61346.37]], "batl": NaN}, {"timestamp": 1578775183004, "ltp": 1.02, "tv": 139953.74, "trd": [[1.02, 3649.57]], "batb": [[0, 1.01, 61346.37], [1, 1.01, 0]], "batl": NaN}, {"timestamp": 1578775188030, "ltp": 1.02, "tv": 139953.74, "trd": NaN, "batb": NaN, "batl": [[0, 1.02, 153.07], [1, 1.03, 3871.45], [2, 1.04, 3502.14]]}, {"timestamp": 1578775200426, "ltp": 1.02, "tv": 139953.74, "trd": NaN, "batb": [[0, 1.01, 61443.91]], "batl": NaN}, {"timestamp": 1578775205966, "ltp": 1.02, "tv": 139953.74, "trd": NaN, "batb": [[0, 1.01, 61446.97]], "batl": NaN}, {"timestamp": 1578775232976, "ltp": 1.02, "tv": 139979.75, "trd": [[1.02, 3675.58]], "batb": NaN, "batl": [[0, 1.02, 127.05]]}, {"timestamp": 1578775277930, "ltp": 1.02, "tv": 140106.81, "trd": [[1.02, 3802.64]], "batb": NaN, "batl": [[0, 1.03, 3871.45], [1, 1.04, 3502.14], [2, 1.05, 2144.64]]}, {"timestamp": 1578775314958, "ltp": 1.02, "tv": 140106.81, "trd": NaN, "batb": [[0, 1.01, 61450.8]], "batl": NaN}, {"timestamp": 1578775325962, "ltp": 1.02, "tv": 140106.81, "trd": NaN, "batb": [[0, 1.01, 61460.16]], "batl": NaN}, {"timestamp": 1578775341013, "ltp": 1.02, "tv": 140106.81, "trd": NaN, "batb": [[0, 1.02, 22287.97], [1, 1.01, 61460.16]], "batl": NaN}, {"timestamp": 1578775342001, "ltp": 1.02, "tv": 140106.81, "trd": NaN, "batb": [[0, 1.02, 22291.97]], "batl": NaN}, {"timestamp": 1578775344005, "ltp": 1.02, "tv": 140106.81, "trd": NaN, "batb": [[0, 1.02, 22323.67]], "batl": NaN}, {"timestamp": 1578775345913, "ltp": 1.02, "tv": 140106.81, "trd": NaN, "batb": NaN, "batl": [[0, 1.03, 4041.69]]}, {"timestamp": 1578775359052, "ltp": 1.02, "tv": 140106.81, "trd": NaN, "batb": NaN, "batl": [[1, 1.04, 3514.14]]}, {"timestamp": 1578775381996, "ltp": 1.03, "tv": 140258.34, "trd": [[1.03, 456.51]], "batb": NaN, "batl": [[0, 1.03, 3965.92]]}, {"timestamp": 1578775388974, "ltp": 1.03, "tv": 140258.34, "trd": NaN, "batb": NaN, "batl": [[1, 1.04, 3526.14]]}, {"timestamp": 1578775402990, "ltp": 1.02, "tv": 140804.84, "trd": [[1.02, 4349.14]], "batb": [[0, 1.02, 22050.42]], "batl": NaN}, {"timestamp": 1578775410785, "ltp": 1.02, "tv": 140804.84, "trd": NaN, "batb": [[0, 1.02, 22018.72]], "batl": NaN}, {"timestamp": 1578775418842, "ltp": 1.02, "tv": 140804.84, "trd": NaN, "batb": NaN, "batl": [[1, 1.04, 3538.14]]}, {"timestamp": 1578775423936, "ltp": 1.03, "tv": 140809.68, "trd": [[1.03, 461.35]], "batb": NaN, "batl": [[0, 1.03, 3963.5]]}, {"timestamp": 1578775440766, "ltp": 1.03, "tv": 140813.42, "trd": [[1.03, 465.09]], "batb": NaN, "batl": [[0, 1.03, 3961.63]]}, {"timestamp": 1578775448686, "ltp": 1.03, "tv": 140813.42, "trd": NaN, "batb": NaN, "batl": [[1, 1.04, 3550.14]]}, {"timestamp": 1578775462975, "ltp": 1.02, "tv": 141537.64, "trd": [[1.02, 5073.36]], "batb": [[0, 1.02, 21656.61]], "batl": NaN}, {"timestamp": 1578775467977, "ltp": 1.02, "tv": 141539.35, "trd": [[1.02, 5075.07]], "batb": [[0, 1.02, 21654.9]], "batl": NaN}, {"timestamp": 1578775478994, "ltp": 1.02, "tv": 141539.35, "trd": NaN, "batb": NaN, "batl": [[1, 1.04, 3562.14]]}, {"timestamp": 1578775508962, "ltp": 1.02, "tv": 141539.35, "trd": NaN, "batb": NaN, "batl": [[1, 1.04, 3574.14]]}, {"timestamp": 1578775516768, "ltp": 1.02, "tv": 141546.83, "trd": [[1.02, 5082.54]], "batb": [[0, 1.02, 21651.16]], "batl": NaN}, {"timestamp": 1578775539001, "ltp": 1.02, "tv": 141546.83, "trd": NaN, "batb": NaN, "batl": [[1, 1.04, 3586.14]]}, {"timestamp": 1578775566937, "ltp": 1.02, "tv": 141822.83, "trd": [[1.02, 5358.54]], "batb": [[0, 1.02, 21513.16]], "batl": NaN}, {"timestamp": 1578775569039, "ltp": 1.02, "tv": 141822.83, "trd": NaN, "batb": NaN, "batl": [[1, 1.04, 3598.14]]}, {"timestamp": 1578775576053, "ltp": 1.02, "tv": 141822.83, "trd": NaN, "batb": [[1, 1.01, 61463.22]], "batl": NaN}, {"timestamp": 1578775581858, "ltp": 1.02, "tv": 141823.89, "trd": [[1.02, 5359.6]], "batb": [[0, 1.02, 21512.63]], "batl": NaN}, {"timestamp": 1578775583959, "ltp": 1.02, "tv": 141823.89, "trd": NaN, "batb": [[1, 1.01, 61464.36]], "batl": NaN}, {"timestamp": 1578775589667, "ltp": 1.02, "tv": 141823.89, "trd": NaN, "batb": [[1, 1.01, 61602.36]], "batl": NaN}, {"timestamp": 1578775598862, "ltp": 1.02, "tv": 141823.89, "trd": NaN, "batb": NaN, "batl": [[1, 1.04, 3610.14]]}, {"timestamp": 1578775614023, "ltp": 1.02, "tv": 141823.89, "trd": NaN, "batb": [[1, 1.01, 61599.3]], "batl": NaN}, {"timestamp": 1578775621927, "ltp": 1.02, "tv": 141823.89, "trd": NaN, "batb": [[0, 1.02, 21557.63]], "batl": NaN}, {"timestamp": 1578775629020, "ltp": 1.02, "tv": 141823.89, "trd": NaN, "batb": NaN, "batl": [[1, 1.04, 3622.14]]}, {"timestamp": 1578775659024, "ltp": 1.02, "tv": 141823.89, "trd": NaN, "batb": NaN, "batl": [[1, 1.04, 3634.14]]}, {"timestamp": 1578775689000, "ltp": 1.02, "tv": 141823.89, "trd": NaN, "batb": NaN, "batl": [[1, 1.04, 3646.14]]}, {"timestamp": 1578775719028, "ltp": 1.02, "tv": 141823.89, "trd": NaN, "batb": NaN, "batl": [[1, 1.04, 3658.14]]}, {"timestamp": 1578775748983, "ltp": 1.02, "tv": 141823.89, "trd": NaN, "batb": NaN, "batl": [[1, 1.04, 3670.14]]}, {"timestamp": 1578775779040, "ltp": 1.02, "tv": 141823.89, "trd": NaN, "batb": NaN, "batl": [[1, 1.04, 3682.14]]}, {"timestamp": 1578775789854, "ltp": 1.02, "tv": 141823.89, "trd": NaN, "batb": [[1, 1.01, 59188.3]], "batl": [[0, 1.03, 2765.83], [1, 1.04, 2549.14]]}, {"timestamp": 1578775794871, "ltp": 1.02, "tv": 142445.83, "trd": [[1.02, 5981.54]], "batb": [[0, 1.02, 21246.66]], "batl": NaN}, {"timestamp": 1578775812987, "ltp": 1.02, "tv": 142538.49, "trd": [[1.02, 6074.21]], "batb": [[0, 1.02, 21200.33]], "batl": NaN}, {"timestamp": 1578775815592, "ltp": 1.02, "tv": 142538.49, "trd": NaN, "batb": NaN, "batl": [[1, 1.04, 2561.14]]}, {"timestamp": 1578775818009, "ltp": 1.02, "tv": 142541.71, "trd": [[1.02, 6077.43]], "batb": [[0, 1.02, 21197.11]], "batl": NaN}, {"timestamp": 1578775829004, "ltp": 1.02, "tv": 142714.01, "trd": [[1.02, 6249.73]], "batb": [[0, 1.02, 21110.96]], "batl": NaN}, {"timestamp": 1578775832027, "ltp": 1.02, "tv": 142714.01, "trd": NaN, "batb": [[1, 1.01, 59090.76]], "batl": NaN}, {"timestamp": 1578775833019, "ltp": 1.02, "tv": 142714.01, "trd": NaN, "batb": [[1, 1.01, 58993.23]], "batl": NaN}, {"timestamp": 1578775835879, "ltp": 1.02, "tv": 143525.97, "trd": [[1.02, 7061.69]], "batb": [[0, 1.02, 20704.98]], "batl": NaN}, {"timestamp": 1578775845615, "ltp": 1.02, "tv": 143525.97, "trd": NaN, "batb": NaN, "batl": [[1, 1.04, 2573.14]]}, {"timestamp": 1578775852052, "ltp": 1.02, "tv": 143525.97, "trd": NaN, "batb": [[0, 1.02, 20899.67]], "batl": NaN}, {"timestamp": 1578775860037, "ltp": 1.02, "tv": 143525.97, "trd": NaN, "batb": [[1, 1.01, 61437.23]], "batl": [[0, 1.03, 3949.83], [1, 1.04, 3821.14]]}, {"timestamp": 1578775862026, "ltp": 1.02, "tv": 143828.15, "trd": [[1.02, 7363.87]], "batb": [[0, 1.02, 20748.58]], "batl": NaN}, {"timestamp": 1578775866042, "ltp": 1.02, "tv": 143828.15, "trd": NaN, "batb": [[1, 1.01, 56937.23]], "batl": [[0, 1.03, 3499.83]]}, {"timestamp": 1578775870042, "ltp": 1.02, "tv": 143828.15, "trd": NaN, "batb": NaN, "batl": [[0, 1.03, 3597.18]]}, {"timestamp": 1578775870958, "ltp": 1.02, "tv": 144728.15, "trd": [[1.02, 8263.87]], "batb": [[0, 1.02, 20298.58]], "batl": NaN}, {"timestamp": 1578775873056, "ltp": 1.02, "tv": 145628.15, "trd": [[1.02, 9163.87]], "batb": [[0, 1.02, 19848.58]], "batl": [[2, 1.05, 2142.93]]}, {"timestamp": 1578775875961, "ltp": 1.02, "tv": 145628.15, "trd": NaN, "batb": NaN, "batl": [[1, 1.04, 3833.14]]}, {"timestamp": 1578775879969, "ltp": 1.02, "tv": 145990.01, "trd": [[1.02, 9525.73]], "batb": [[0, 1.02, 19667.65]], "batl": NaN}, {"timestamp": 1578775880956, "ltp": 1.02, "tv": 145990.01, "trd": NaN, "batb": NaN, "batl": [[1, 1.04, 3834.84]]}, {"timestamp": 1578775882051, "ltp": 1.02, "tv": 145990.01, "trd": NaN, "batb": NaN, "batl": [[2, 1.05, 2151.45]]}, {"timestamp": 1578775884872, "ltp": 1.03, "tv": 147416.63, "trd": [[1.03, 1891.71]], "batb": NaN, "batl": [[0, 1.03, 2883.87]]}, {"timestamp": 1578775892955, "ltp": 1.03, "tv": 147416.63, "trd": NaN, "batb": NaN, "batl": [[0, 1.03, 2968.99]]}, {"timestamp": 1578775893991, "ltp": 1.02, "tv": 148316.63, "trd": [[1.02, 10425.73]], "batb": [[0, 1.02, 19217.65]], "batl": NaN}, {"timestamp": 1578775901992, "ltp": 1.02, "tv": 149043.77, "trd": [[1.02, 11152.87]], "batb": [[0, 1.02, 18854.08]], "batl": NaN}, {"timestamp": 1578775905997, "ltp": 1.02, "tv": 149043.77, "trd": NaN, "batb": NaN, "batl": [[1, 1.04, 3846.84]]}, {"timestamp": 1578775908995, "ltp": 1.02, "tv": 149043.77, "trd": NaN, "batb": NaN, "batl": [[0, 1.03, 2986.01]]}, {"timestamp": 1578775930027, "ltp": 1.02, "tv": 149043.77, "trd": NaN, "batb": [[1, 1.01, 56979.79]], "batl": NaN}, {"timestamp": 1578775935955, "ltp": 1.02, "tv": 149043.77, "trd": NaN, "batb": NaN, "batl": [[1, 1.04, 3858.84]]}, {"timestamp": 1578775937048, "ltp": 1.03, "tv": 149049.9, "trd": [[1.03, 1897.83]], "batb": NaN, "batl": [[0, 1.03, 2982.95]]}, {"timestamp": 1578775938040, "ltp": 1.02, "tv": 149076.5, "trd": [[1.02, 11179.47]], "batb": [[0, 1.02, 18840.78]], "batl": NaN}, {"timestamp": 1578775952055, "ltp": 1.02, "tv": 149976.5, "trd": [[1.02, 12079.47]], "batb": [[0, 1.02, 18390.78]], "batl": NaN}, {"timestamp": 1578775953976, "ltp": 1.02, "tv": 149976.5, "trd": NaN, "batb": [[1, 1.01, 56996.81]], "batl": NaN}, {"timestamp": 1578775958980, "ltp": 1.02, "tv": 150876.5, "trd": [[1.02, 12979.47]], "batb": [[0, 1.02, 17940.78]], "batl": NaN}, {"timestamp": 1578775965986, "ltp": 1.02, "tv": 150876.5, "trd": NaN, "batb": NaN, "batl": [[0, 1.03, 3432.95], [1, 1.04, 3870.84]]}, {"timestamp": 1578775966987, "ltp": 1.02, "tv": 150876.5, "trd": NaN, "batb": [[1, 1.01, 55945.23]], "batl": [[0, 1.03, 2982.95]]}, {"timestamp": 1578775980010, "ltp": 1.02, "tv": 151451.76, "trd": [[1.02, 13554.73]], "batb": [[0, 1.02, 17653.15]], "batl": NaN}, {"timestamp": 1578775984001, "ltp": 1.02, "tv": 151460.28, "trd": [[1.02, 13563.25]], "batb": [[0, 1.02, 17648.89]], "batl": NaN}, {"timestamp": 1578775992022, "ltp": 1.02, "tv": 151809.27, "trd": [[1.02, 13912.25]], "batb": [[0, 1.02, 17474.39]], "batl": NaN}, {"timestamp": 1578775996027, "ltp": 1.02, "tv": 151809.27, "trd": NaN, "batb": NaN, "batl": [[1, 1.04, 3882.84]]}, {"timestamp": 1578775997020, "ltp": 1.02, "tv": 152709.27, "trd": [[1.02, 14812.25]], "batb": [[0, 1.02, 17024.39]], "batl": NaN}, {"timestamp": 1578775999042, "ltp": 1.02, "tv": 152794.39, "trd": [[1.02, 14897.37]], "batb": [[0, 1.02, 16981.83]], "batl": NaN}, {"timestamp": 1578776000043, "ltp": 1.02, "tv": 154071.21, "trd": [[1.02, 16174.18]], "batb": [[0, 1.02, 16343.42]], "batl": NaN}, {"timestamp": 1578776002032, "ltp": 1.02, "tv": 156531.21, "trd": [[1.02, 18634.18]], "batb": [[0, 1.02, 15113.42]], "batl": NaN}, {"timestamp": 1578776003959, "ltp": 1.02, "tv": 157431.21, "trd": [[1.02, 19534.18]], "batb": [[0, 1.02, 14663.42]], "batl": NaN}, {"timestamp": 1578776005053, "ltp": 1.02, "tv": 158331.21, "trd": [[1.02, 20434.18]], "batb": [[0, 1.02, 14213.42]], "batl": NaN}, {"timestamp": 1578776006049, "ltp": 1.02, "tv": 158331.21, "trd": NaN, "batb": [[1, 1.01, 50945.23]], "batl": [[0, 1.03, 2997.12]]}, {"timestamp": 1578776007036, "ltp": 1.02, "tv": 159693.15, "trd": [[1.02, 21796.12]], "batb": [[0, 1.02, 13532.45]], "batl": NaN}, {"timestamp": 1578776011049, "ltp": 1.02, "tv": 160070.6, "trd": [[1.02, 22173.57]], "batb": [[0, 1.02, 13155], [1, 1.01, 50361.96]], "batl": NaN}, {"timestamp": 1578776012027, "ltp": 1.02, "tv": 160970.6, "trd": [[1.02, 23073.57]], "batb": [[0, 1.02, 12705]], "batl": NaN}, {"timestamp": 1578776014049, "ltp": 1.02, "tv": 161870.6, "trd": [[1.02, 23973.57]], "batb": [[0, 1.02, 12255]], "batl": NaN}, {"timestamp": 1578776015043, "ltp": 1.02, "tv": 163232.54, "trd": [[1.02, 25335.51]], "batb": [[0, 1.02, 11574.03], [1, 1.01, 50057.42]], "batl": NaN}, {"timestamp": 1578776019031, "ltp": 1.02, "tv": 164132.54, "trd": [[1.02, 26235.51]], "batb": [[0, 1.02, 11124.03]], "batl": NaN}, {"timestamp": 1578776022048, "ltp": 1.02, "tv": 165409.35, "trd": [[1.02, 27512.32]], "batb": [[0, 1.02, 10485.62]], "batl": NaN}, {"timestamp": 1578776023036, "ltp": 1.02, "tv": 165702.98, "trd": [[1.02, 27805.95]], "batb": [[0, 1.02, 10277.88]], "batl": NaN}, {"timestamp": 1578776026036, "ltp": 1.02, "tv": 165702.98, "trd": NaN, "batb": NaN, "batl": [[1, 1.04, 3894.84]]}, {"timestamp": 1578776029985, "ltp": 1.02, "tv": 166979.79, "trd": [[1.02, 29082.77]], "batb": [[0, 1.02, 9639.47]], "batl": NaN}, {"timestamp": 1578776030974, "ltp": 1.02, "tv": 167064.91, "trd": [[1.02, 29167.89]], "batb": [[0, 1.02, 9596.91]], "batl": NaN}, {"timestamp": 1578776035051, "ltp": 1.02, "tv": 167186.77, "trd": [[1.02, 29289.75]], "batb": [[0, 1.02, 9475.05]], "batl": [[1, 1.04, 3893.14], [2, 1.05, 2142.93]]}, {"timestamp": 1578776035982, "ltp": 1.02, "tv": 167200.07, "trd": [[1.02, 29303.05]], "batb": [[0, 1.02, 9468.4]], "batl": NaN}, {"timestamp": 1578776038054, "ltp": 1.02, "tv": 168648.65, "trd": [[1.02, 30751.63]], "batb": [[0, 1.02, 8744.11]], "batl": NaN}, {"timestamp": 1578776038987, "ltp": 1.02, "tv": 169548.65, "trd": [[1.02, 31651.63]], "batb": [[0, 1.02, 8294.11]], "batl": NaN}, {"timestamp": 1578776039996, "ltp": 1.02, "tv": 169948.65, "trd": [[1.02, 32051.63]], "batb": [[0, 1.02, 8094.11]], "batl": NaN}, {"timestamp": 1578776041979, "ltp": 1.02, "tv": 169948.65, "trd": NaN, "batb": NaN, "batl": [[0, 1.03, 2998.82], [1, 1.04, 3901.65], [2, 1.05, 2151.45]]}, {"timestamp": 1578776044991, "ltp": 1.02, "tv": 171225.47, "trd": [[1.02, 33328.44]], "batb": [[0, 1.02, 7455.7]], "batl": NaN}, {"timestamp": 1578776045983, "ltp": 1.02, "tv": 171310.59, "trd": [[1.02, 33413.56]], "batb": [[0, 1.02, 7413.14]], "batl": [[0, 1.03, 3448.82]]}, {"timestamp": 1578776052996, "ltp": 1.02, "tv": 172587.41, "trd": [[1.02, 34690.38]], "batb": [[0, 1.02, 6774.73]], "batl": NaN}, {"timestamp": 1578776053983, "ltp": 1.02, "tv": 172672.53, "trd": [[1.02, 34775.5]], "batb": [[0, 1.02, 6732.17]], "batl": NaN}, {"timestamp": 1578776056004, "ltp": 1.02, "tv": 173704.67, "trd": [[1.02, 35807.64]], "batb": [[0, 1.02, 6216.1], [1, 1.01, 50060.49]], "batl": [[1, 1.04, 3913.65]]}, {"timestamp": 1578776057004, "ltp": 1.02, "tv": 173704.67, "trd": NaN, "batb": [[1, 1.01, 50057.42]], "batl": NaN}, {"timestamp": 1578776059020, "ltp": 1.02, "tv": 174604.67, "trd": [[1.02, 36707.64]], "batb": [[0, 1.02, 5766.1]], "batl": [[0, 1.03, 2998.82]]}, {"timestamp": 1578776060001, "ltp": 1.02, "tv": 176981.48, "trd": [[1.02, 39084.46]], "batb": [[0, 1.02, 4577.69]], "batl": NaN}, {"timestamp": 1578776062019, "ltp": 1.02, "tv": 177066.6, "trd": [[1.02, 39169.58]], "batb": [[0, 1.02, 4535.13]], "batl": NaN}, {"timestamp": 1578776063992, "ltp": 1.02, "tv": 177066.6, "trd": NaN, "batb": [[1, 1.01, 50057.8]], "batl": NaN}, {"timestamp": 1578776067000, "ltp": 1.02, "tv": 179741.52, "trd": [[1.02, 41844.5]], "batb": [[0, 1.02, 1860.21]], "batl": NaN}, {"timestamp": 1578776068028, "ltp": 1.02, "tv": 181018.34, "trd": [[1.02, 43121.31]], "batb": [[0, 1.02, 1221.8]], "batl": NaN}, {"timestamp": 1578776069013, "ltp": 1.02, "tv": 182240.14, "trd": [[1.02, 44343.11]], "batb": [[0, 1.01, 50057.8], [1, 1.01, 0]], "batl": [[0, 1.02, 42.56], [1, 1.03, 2913.7], [2, 1.04, 3913.65]]}, {"timestamp": 1578776069998, "ltp": 1.02, "tv": 182240.14, "trd": NaN, "batb": NaN, "batl": [[0, 1.03, 2871.14], [1, 1.04, 3913.65], [2, 1.05, 2151.45]]}, {"timestamp": 1578776070998, "ltp": 1.02, "tv": 182240.14, "trd": NaN, "batb": NaN, "batl": [[0, 1.02, 1165], [1, 1.03, 2871.14], [2, 1.04, 3913.65]]}, {"timestamp": 1578776076035, "ltp": 1.02, "tv": 182240.14, "trd": NaN, "batb": NaN, "batl": [[0, 1.02, 1292.68]]}, {"timestamp": 1578776077031, "ltp": 1.02, "tv": 182240.14, "trd": NaN, "batb": [[0, 1.01, 22848.25]], "batl": [[0, 1.02, 1377.8]]}, {"timestamp": 1578776080031, "ltp": 1.02, "tv": 182240.14, "trd": NaN, "batb": [[0, 1.01, 27348.25]], "batl": [[0, 1.02, 1827.8], [1, 1.03, 2700.9]]}, {"timestamp": 1578776089017, "ltp": 1.02, "tv": 182240.14, "trd": NaN, "batb": NaN, "batl": [[0, 1.02, 2159.48]]}, {"timestamp": 1578776094046, "ltp": 1.02, "tv": 182240.14, "trd": NaN, "batb": [[0, 1.01, 24904.25]], "batl": [[0, 1.02, 4159.48]]}, {"timestamp": 1578776095972, "ltp": 1.02, "tv": 182240.14, "trd": NaN, "batb": NaN, "batl": [[0, 1.02, 4222.47]]}, {"timestamp": 1578776102965, "ltp": 1.02, "tv": 182240.14, "trd": NaN, "batb": [[0, 1.01, 27213.25]], "batl": NaN}, {"timestamp": 1578776104007, "ltp": 1.02, "tv": 182240.14, "trd": NaN, "batb": [[0, 1.01, 20404.25]], "batl": [[0, 1.02, 3772.47]]}, {"timestamp": 1578776106978, "ltp": 1.02, "tv": 182240.14, "trd": NaN, "batb": [[0, 1.01, 20129.49]], "batl": [[0, 1.02, 3790.38]]}, {"timestamp": 1578776112007, "ltp": 1.02, "tv": 182240.14, "trd": NaN, "batb": [[0, 1.01, 24629.49]], "batl": [[0, 1.02, 4240.38]]}, {"timestamp": 1578776136011, "ltp": 1.02, "tv": 182240.14, "trd": NaN, "batb": [[0, 1.01, 23884.49]], "batl": NaN}, {"timestamp": 1578776144027, "ltp": 1.02, "tv": 182240.14, "trd": NaN, "batb": NaN, "batl": [[1, 1.03, 2686.73]]}, {"timestamp": 1578776155037, "ltp": 1.02, "tv": 182240.14, "trd": NaN, "batb": [[0, 1.01, 23118.4]], "batl": NaN}, {"timestamp": 1578776159030, "ltp": 1.02, "tv": 182240.14, "trd": NaN, "batb": NaN, "batl": [[0, 1.02, 12752.46]]}, {"timestamp": 1578776160016, "ltp": 1.01, "tv": 182240.43, "trd": [[1.01, 946.4]], "batb": [[0, 1.01, 23118.26]], "batl": NaN}, {"timestamp": 1578776160962, "ltp": 1.01, "tv": 182240.43, "trd": NaN, "batb": [[0, 1.01, 23101.23]], "batl": NaN}, {"timestamp": 1578776162054, "ltp": 1.01, "tv": 182240.43, "trd": NaN, "batb": [[0, 1.01, 23058.67]], "batl": NaN}, {"timestamp": 1578776168974, "ltp": 1.01, "tv": 182240.43, "trd": NaN, "batb": NaN, "batl": [[0, 1.02, 12689.47]]}, {"timestamp": 1578776182950, "ltp": 1.01, "tv": 182481.96, "trd": [[1.01, 1187.92]], "batb": [[0, 1.01, 22937.91]], "batl": NaN}, {"timestamp": 1578776192026, "ltp": 1.01, "tv": 184012.65, "trd": [[1.01, 2718.62]], "batb": [[0, 1.01, 23172.56]], "batl": NaN}, {"timestamp": 1578776195973, "ltp": 1.01, "tv": 184012.65, "trd": NaN, "batb": [[0, 1.01, 18672.56]], "batl": NaN}, {"timestamp": 1578776203024, "ltp": 1.01, "tv": 184012.65, "trd": NaN, "batb": NaN, "batl": [[0, 1.02, 11074.47]]}, {"timestamp": 1578776206986, "ltp": 1.01, "tv": 184012.65, "trd": NaN, "batb": NaN, "batl": [[0, 1.02, 10742.8]]}, {"timestamp": 1578776208026, "ltp": 1.01, "tv": 184012.65, "trd": NaN, "batb": [[0, 1.01, 1648.38]], "batl": NaN}, {"timestamp": 1578776212036, "ltp": 1.01, "tv": 184012.65, "trd": NaN, "batb": NaN, "batl": [[0, 1.02, 11998.8]]}, {"timestamp": 1578776214041, "ltp": 1.01, "tv": 184012.65, "trd": NaN, "batb": [[0, 1.01, 1668.38]], "batl": NaN}, {"timestamp": 1578776217055, "ltp": 1.01, "tv": 184069.7, "trd": [[1.01, 2775.66]], "batb": [[0, 1.01, 1639.86]], "batl": NaN}, {"timestamp": 1578776222033, "ltp": 1.01, "tv": 184345.23, "trd": [[1.01, 3051.19]], "batb": [[0, 1.01, 1502.09]], "batl": NaN}, {"timestamp": 1578776225949, "ltp": 1.01, "tv": 184345.45, "trd": [[1.01, 3051.42]], "batb": [[0, 1.01, 1501.98]], "batl": NaN}, {"timestamp": 1578776230958, "ltp": 1.01, "tv": 184841.46, "trd": [[1.01, 3547.43]], "batb": [[0, 1.01, 1253.98]], "batl": NaN}, {"timestamp": 1578776235973, "ltp": 1.01, "tv": 186341.18, "trd": [[1.01, 5047.15]], "batb": [[0, 1.01, 504.11]], "batl": NaN}, {"timestamp": 1578776236972, "ltp": 1.01, "tv": 186341.18, "trd": NaN, "batb": NaN, "batl": [[0, 1.02, 12448.8]]}, {"timestamp": 1578776238956, "ltp": 1.01, "tv": 186348.02, "trd": [[1.01, 5053.99]], "batb": [[0, 1.01, 500.69]], "batl": [[0, 1.02, 12363.68]]}, {"timestamp": 1578776244992, "ltp": 1.01, "tv": 186348.02, "trd": NaN, "batb": NaN, "batl": [[0, 1.02, 12278.56]]}, {"timestamp": 1578776245978, "ltp": 1.01, "tv": 186546.02, "trd": [[1.01, 5251.99]], "batb": [[0, 1.01, 401.69]], "batl": NaN}, {"timestamp": 1578776248991, "ltp": 1.01, "tv": 186546.02, "trd": NaN, "batb": NaN, "batl": [[0, 1.02, 3766.47]]}, {"timestamp": 1578776254992, "ltp": 1.01, "tv": 186947.71, "trd": [[1.01, 5653.68]], "batb": NaN, "batl": NaN}, {"timestamp": 1578776255986, "ltp": 1.01, "tv": 186947.71, "trd": NaN, "batb": NaN, "batl": [[0, 1.01, 8758.92], [1, 1.02, 3766.47], [2, 1.03, 2686.73]]}, {"timestamp": 1578776263996, "ltp": 1.01, "tv": 186951.55, "trd": [[1.01, 5657.52]], "batb": NaN, "batl": [[0, 1.01, 8757]]}, {"timestamp": 1578776278997, "ltp": 1.01, "tv": 186951.59, "trd": [[1.01, 5657.56]], "batb": NaN, "batl": [[0, 1.01, 8756.98]]}, {"timestamp": 1578776317964, "ltp": 1.01, "tv": 186952.37, "trd": [[1.01, 5658.34]], "batb": NaN, "batl": [[0, 1.01, 8756.59]]}, {"timestamp": 1578776342006, "ltp": 1.01, "tv": 186952.37, "trd": NaN, "batb": NaN, "batl": [[1, 1.02, 3316.47]]}, {"timestamp": 1578776357024, "ltp": 1.01, "tv": 186952.37, "trd": NaN, "batb": NaN, "batl": [[0, 1.01, 10373.89]]}, {"timestamp": 1578776360957, "ltp": 1.01, "tv": 186953.87, "trd": [[1.01, 5659.84]], "batb": NaN, "batl": [[0, 1.01, 10373.14]]}, {"timestamp": 1578776376961, "ltp": 1.01, "tv": 186953.87, "trd": NaN, "batb": NaN, "batl": [[0, 1.01, 11224.35]]}, {"timestamp": 1578776391988, "ltp": 1.01, "tv": 186953.87, "trd": NaN, "batb": NaN, "batl": [[1, 1.02, 3273.91]]}, {"timestamp": 1578776398011, "ltp": 1.01, "tv": 186953.87, "trd": NaN, "batb": NaN, "batl": [[0, 1.01, 12075.55]]}, {"timestamp": 1578776407999, "ltp": 1.01, "tv": 186953.87, "trd": NaN, "batb": NaN, "batl": [[0, 1.01, 14075.55]]}, {"timestamp": 1578776409000, "ltp": 1.01, "tv": 186953.87, "trd": NaN, "batb": NaN, "batl": [[0, 1.01, 15267.55]]}, {"timestamp": 1578776416030, "ltp": 1.01, "tv": 186953.87, "trd": NaN, "batb": NaN, "batl": [[0, 1.01, 16118.76]]}, {"timestamp": 1578776417024, "ltp": 1.01, "tv": 186993.87, "trd": [[1.01, 5699.84]], "batb": NaN, "batl": [[0, 1.01, 16098.76]]}, {"timestamp": 1578776419950, "ltp": 1.01, "tv": 186993.87, "trd": NaN, "batb": NaN, "batl": [[0, 1.01, 16145.89]]}, {"timestamp": 1578776431041, "ltp": 1.01, "tv": 186993.87, "trd": NaN, "batb": NaN, "batl": [[2, 1.03, 1317.98]]}, {"timestamp": 1578776451967, "ltp": 1.01, "tv": 186993.87, "trd": NaN, "batb": NaN, "batl": [[0, 1.01, 16163.8]]}, {"timestamp": 1578776456996, "ltp": 1.01, "tv": 187031.24, "trd": [[1.01, 5737.21]], "batb": NaN, "batl": [[0, 1.01, 16145.11]]}, {"timestamp": 1578776485017, "ltp": 1.01, "tv": 187031.24, "trd": NaN, "batb": NaN, "batl": [[0, 1.01, 16645.11]]}, {"timestamp": 1578776497012, "ltp": 1.01, "tv": 187031.24, "trd": NaN, "batb": NaN, "batl": [[0, 1.01, 17357.23]]}, {"timestamp": 1578776543994, "ltp": 1.01, "tv": 187031.24, "trd": NaN, "batb": NaN, "batl": [[0, 1.01, 17533.64]]}, {"timestamp": 1578776592967, "ltp": 1.01, "tv": 187031.24, "trd": NaN, "batb": NaN, "batl": [[2, 1.03, 1220.64]]}, {"timestamp": 1578776687053, "ltp": 1.01, "tv": 187031.24, "trd": NaN, "batb": NaN, "batl": [[0, 1.01, 15065.14]]}, {"timestamp": 1578776722012, "ltp": 1.01, "tv": 187031.24, "trd": NaN, "batb": NaN, "batl": [[0, 1.01, 16682.43]]}, {"timestamp": 1578776748056, "ltp": 1.01, "tv": 187031.24, "trd": NaN, "batb": NaN, "batl": [[0, 1.01, 14980.02]]}, {"timestamp": 1578776948031, "ltp": 1.01, "tv": 187031.24, "trd": NaN, "batb": NaN, "batl": [[2, 1.03, 36.64]]}, {"timestamp": 1578777039907, "ltp": 1.01, "tv": 187031.24, "trd": NaN, "batb": NaN, "batl": [[0, 1.01, 13362.72]]}, {"timestamp": 1578777268019, "ltp": 1.01, "tv": 187031.24, "trd": NaN, "batb": NaN, "batl": [[0, 1.01, 12650.6]]}, {"timestamp": 1578777498006, "ltp": 1.01, "tv": 187041.24, "trd": [[1.01, 5747.21]], "batb": NaN, "batl": [[0, 1.01, 12645.6]]}, {"timestamp": 1578777582002, "ltp": 1.01, "tv": 187041.24, "trd": NaN, "batb": NaN, "batl": [[0, 1.01, 12469.19]]}, {"timestamp": 1578777631947, "ltp": 1.01, "tv": 187041.24, "trd": NaN, "batb": NaN, "batl": [[0, 1.01, 11277.19], [1, 1.02, 2017.91]]}, {"timestamp": 1578777633044, "ltp": 1.01, "tv": 187041.24, "trd": NaN, "batb": NaN, "batl": [[0, 1.01, 11230.06]]}, {"timestamp": 1578777685432, "ltp": 1.01, "tv": 187041.24, "trd": NaN, "batb": NaN, "batl": [[0, 1.01, 9230.06], [1, 1.02, 17.91]]}, {"timestamp": 1578777699037, "ltp": 1.01, "tv": 187041.24, "trd": NaN, "batb": NaN, "batl": [[0, 90, 2.67]]}, {"timestamp": 1578777700021, "ltp": 1.01, "tv": 187041.24, "trd": NaN, "batb": NaN, "batl": [[0, 1.01, 1135], [1, 90, 2.67]]}, {"timestamp": 1578777705034, "ltp": 1.01, "tv": 187041.24, "trd": NaN, "batb": NaN, "batl": [[0, 1.01, 2240.16]]}, {"timestamp": 1578777718961, "ltp": 1.01, "tv": 187041.24, "trd": NaN, "batb": NaN, "batl": [[1, 1.04, 262.21], [2, 1.07, 802.85]]}, {"timestamp": 1578777756974, "ltp": 1.01, "tv": 187041.24, "trd": NaN, "batb": NaN, "batl": [[0, 1.01, 2258.07], [1, 1.02, 17.91], [2, 1.04, 262.21]]}, {"timestamp": 1578777761028, "ltp": 1.01, "tv": 187041.24, "trd": NaN, "batb": NaN, "batl": [[0, 1.01, 4811.18]]}, {"timestamp": 1578777771050, "ltp": 1.01, "tv": 187041.24, "trd": NaN, "batb": NaN, "batl": [[2, 1.03, 17.91]]}, {"timestamp": 1578777774031, "ltp": 1.01, "tv": 187041.24, "trd": NaN, "batb": NaN, "batl": [[0, 1.01, 4987.59]]}, {"timestamp": 1578777785984, "ltp": 1.01, "tv": 187041.24, "trd": NaN, "batb": NaN, "batl": [[0, 1.01, 6987.59]]}, {"timestamp": 1578777788978, "ltp": 1.01, "tv": 187041.24, "trd": NaN, "batb": NaN, "batl": [[0, 1.01, 7155.65]]}, {"timestamp": 1578777799007, "ltp": 1.01, "tv": 187041.24, "trd": NaN, "batb": NaN, "batl": [[0, 1.01, 7355.72]]}, {"timestamp": 1578778010992, "ltp": 1.01, "tv": 187041.24, "trd": NaN, "batb": NaN, "batl": [[0, 1.01, 7100.86]]}, {"timestamp": 1578778162037, "ltp": 1.01, "tv": 187041.24, "trd": NaN, "batb": NaN, "batl": [[0, 1.01, 5047.86]]}, {"timestamp": 1578778223997, "ltp": 1.01, "tv": 187041.24, "trd": NaN, "batb": NaN, "batl": [[0, 1.01, 4282.51]]}, {"timestamp": 1578778337987, "ltp": 1.01, "tv": 187041.24, "trd": NaN, "batb": NaN, "batl": [[0, 1.01, 3147.51]]}, {"timestamp": 1578778338560, "ltp": 1.01, "tv": 187041.24, "trd": NaN, "batb": NaN, "batl": [[0, 1.01, 2647.4]]}, {"timestamp": 1578778349972, "ltp": 1.01, "tv": 187041.24, "trd": NaN, "batb": NaN, "batl": [[0, 1.01, 647.4]]}, {"timestamp": 1578778427675, "ltp": 1.01, "tv": 187041.24, "trd": NaN, "batb": NaN, "batl": [[0, 1.01, 84.95], [1, 1.02, 0], [2, 1.03, 0]]}, {"timestamp": 1578778443040, "ltp": 1.01, "tv": 187041.24, "trd": NaN, "batb": NaN, "batl": [[1, 90, 2.67]]}, {"timestamp": 1578778465048, "ltp": 1.01, "tv": 187041.24, "trd": NaN, "batb": NaN, "batl": [[1, 1.04, 262.21], [2, 1.07, 802.85]]}, {"timestamp": 1578778468056, "ltp": 1.01, "tv": 187041.24, "trd": NaN, "batb": NaN, "batl": [[0, 1.01, 1088.95]]}, {"timestamp": 1578778471997, "ltp": 1.01, "tv": 187041.24, "trd": NaN, "batb": NaN, "batl": [[0, 1.01, 1525.45]]}, {"timestamp": 1578778488997, "ltp": 1.01, "tv": 187041.24, "trd": NaN, "batb": NaN, "batl": [[0, 1.01, 1543.36], [1, 1.02, 17.91], [2, 1.03, 17.91]]}, {"timestamp": 1578778515052, "ltp": 1.01, "tv": 187041.24, "trd": NaN, "batb": NaN, "batl": [[0, 1.01, 1543.89]]}, {"timestamp": 1578778539988, "ltp": 1.01, "tv": 187041.24, "trd": NaN, "batb": NaN, "batl": [[0, 1.01, 539.89]]}, {"timestamp": 1578778543991, "ltp": 1.01, "tv": 187041.24, "trd": NaN, "batb": NaN, "batl": [[0, 1.01, 739.96]]}, {"timestamp": 1578778774964, "ltp": 1.01, "tv": 187041.24, "trd": NaN, "batb": NaN, "batl": [[0, 1.01, 303.46]]}, {"timestamp": 1578778790411, "ltp": 1.01, "tv": 187041.24, "trd": NaN, "batb": NaN, "batl": [[0, 1.01, 0.53], [1, 1.02, 0], [2, 1.03, 0]]}]}, {"runnerId": 1485568, "odds": [{"timestamp": 1578758009457, "ltp": 12.0, "tv": 1.7, "trd": [[12, 1.7]], "batb": NaN, "batl": [[0, 12, 3.3]]}, {"timestamp": 1578758365939, "ltp": 12.0, "tv": 1.7, "trd": NaN, "batb": [[0, 11, 35.24], [1, 9.8, 10], [2, 9.8, 0]], "batl": NaN}, {"timestamp": 1578758381434, "ltp": 12.0, "tv": 1.7, "trd": NaN, "batb": [[0, 11.5, 27.8], [1, 11, 35.24], [2, 9.8, 10]], "batl": NaN}, {"timestamp": 1578758382938, "ltp": 12.0, "tv": 1.7, "trd": NaN, "batb": [[2, 10.5, 32.02]], "batl": NaN}, {"timestamp": 1578758383964, "ltp": 12.0, "tv": 1.7, "trd": NaN, "batb": [[0, 11, 35.24], [1, 10.5, 32.02], [2, 9.8, 10]], "batl": NaN}, {"timestamp": 1578758386873, "ltp": 12.0, "tv": 1.7, "trd": NaN, "batb": [[0, 11.5, 35.02], [1, 11, 35.24], [2, 10.5, 32.02]], "batl": NaN}, {"timestamp": 1578758387950, "ltp": 12.0, "tv": 1.7, "trd": NaN, "batb": [[0, 10.5, 32.02], [1, 9.8, 10], [2, 10.5, 0]], "batl": NaN}, {"timestamp": 1578758390967, "ltp": 12.0, "tv": 1.7, "trd": NaN, "batb": [[0, 11, 35.24], [1, 10.5, 32.02], [2, 9.8, 10]], "batl": NaN}, {"timestamp": 1578758403674, "ltp": 12.0, "tv": 1.7, "trd": NaN, "batb": [[1, 9.8, 10], [2, 9.8, 0]], "batl": NaN}, {"timestamp": 1578758665945, "ltp": 12.0, "tv": 1.7, "trd": NaN, "batb": [[0, 11, 27.12], [1, 10.5, 32.02], [2, 9.8, 10]], "batl": NaN}, {"timestamp": 1578759002983, "ltp": 12.0, "tv": 1.7, "trd": NaN, "batb": [[0, 11.5, 35.02], [1, 11, 27.12], [2, 10.5, 32.02]], "batl": NaN}, {"timestamp": 1578759004001, "ltp": 12.0, "tv": 1.7, "trd": NaN, "batb": [[0, 11, 27.12], [1, 10.5, 32.02], [2, 9.8, 10]], "batl": NaN}, {"timestamp": 1578759011041, "ltp": 12.0, "tv": 1.7, "trd": NaN, "batb": [[0, 11.5, 28.96], [1, 11, 27.12], [2, 10.5, 32.02]], "batl": NaN}, {"timestamp": 1578759012012, "ltp": 12.0, "tv": 1.7, "trd": NaN, "batb": [[0, 11, 27.12], [1, 10.5, 32.02], [2, 9.8, 10]], "batl": NaN}, {"timestamp": 1578759625866, "ltp": 12.0, "tv": 1.7, "trd": NaN, "batb": [[0, 10.5, 32.02], [1, 9.8, 10], [2, 9.8, 0]], "batl": NaN}, {"timestamp": 1578759640981, "ltp": 12.0, "tv": 1.7, "trd": NaN, "batb": [[0, 11.5, 37.52], [1, 11, 28.44], [2, 10.5, 32.02]], "batl": NaN}, {"timestamp": 1578759643005, "ltp": 12.0, "tv": 1.7, "trd": NaN, "batb": [[0, 11, 28.44], [1, 9.8, 10], [2, 10.5, 0]], "batl": NaN}, {"timestamp": 1578759648813, "ltp": 12.0, "tv": 1.7, "trd": NaN, "batb": [[0, 11.5, 37.52], [1, 11, 28.44], [2, 9.8, 10]], "batl": NaN}, {"timestamp": 1578759650985, "ltp": 12.0, "tv": 1.7, "trd": NaN, "batb": [[0, 11, 28.44], [1, 10.5, 32.02]], "batl": NaN}, {"timestamp": 1578759652030, "ltp": 12.0, "tv": 1.7, "trd": NaN, "batb": [[0, 11.5, 35.02], [1, 11, 28.44], [2, 10.5, 32.02]], "batl": NaN}, {"timestamp": 1578759652966, "ltp": 12.0, "tv": 1.7, "trd": NaN, "batb": [[0, 11, 28.44], [1, 10.5, 32.02], [2, 9.8, 10]], "batl": NaN}, {"timestamp": 1578759684034, "ltp": 12.0, "tv": 8.3, "trd": [[12, 8.3]], "batb": [[0, 12, 46.33], [1, 11.5, 35.02], [2, 11, 28.44]], "batl": [[0, 15, 15.83], [1, 15, 0]]}, {"timestamp": 1578759684945, "ltp": 12.0, "tv": 8.3, "trd": NaN, "batb": [[0, 9.8, 10], [1, 11.5, 0], [2, 11, 0]], "batl": NaN}, {"timestamp": 1578759685812, "ltp": 12.0, "tv": 8.3, "trd": NaN, "batb": [[0, 11, 28.44], [1, 10.5, 32.02], [2, 9.8, 10]], "batl": NaN}, {"timestamp": 1578759693861, "ltp": 12.0, "tv": 8.3, "trd": NaN, "batb": [[0, 12, 34.95], [1, 11.5, 27.8], [2, 11, 28.44]], "batl": NaN}, {"timestamp": 1578759786031, "ltp": 12.0, "tv": 8.3, "trd": NaN, "batb": [[2, 11, 0]], "batl": NaN}, {"timestamp": 1578759794024, "ltp": 12.0, "tv": 8.3, "trd": NaN, "batb": [[0, 11.5, 27.8], [1, 11, 27.42]], "batl": NaN}, {"timestamp": 1578759797048, "ltp": 12.0, "tv": 8.3, "trd": NaN, "batb": [[2, 9.8, 10]], "batl": NaN}, {"timestamp": 1578759836030, "ltp": 12.0, "tv": 8.3, "trd": NaN, "batb": [[2, 10, 2.74]], "batl": [[1, 1000, 2.64]]}, {"timestamp": 1578759836876, "ltp": 12.0, "tv": 8.3, "trd": NaN, "batb": NaN, "batl": [[1, 1000, 0.37]]}, {"timestamp": 1578759837980, "ltp": 12.0, "tv": 8.3, "trd": NaN, "batb": NaN, "batl": [[0, 15, 16.2], [1, 1000, 0]]}, {"timestamp": 1578760216828, "ltp": 12.0, "tv": 8.3, "trd": NaN, "batb": [[0, 11, 27.42], [1, 10, 2.74], [2, 9.8, 10]], "batl": NaN}, {"timestamp": 1578760418008, "ltp": 12.0, "tv": 8.3, "trd": NaN, "batb": [[1, 10.5, 32.02], [2, 10, 2.74]], "batl": NaN}, {"timestamp": 1578760419023, "ltp": 12.0, "tv": 8.3, "trd": NaN, "batb": [[0, 11, 35.24]], "batl": NaN}, {"timestamp": 1578760428039, "ltp": 12.0, "tv": 8.3, "trd": NaN, "batb": [[0, 11.5, 35.02], [1, 11, 35.24], [2, 10.5, 32.02]], "batl": NaN}, {"timestamp": 1578760516923, "ltp": 12.0, "tv": 8.3, "trd": NaN, "batb": [[2, 10, 2.74]], "batl": NaN}, {"timestamp": 1578760518046, "ltp": 12.0, "tv": 8.3, "trd": NaN, "batb": [[2, 9.8, 10]], "batl": NaN}, {"timestamp": 1578760519034, "ltp": 12.0, "tv": 8.3, "trd": NaN, "batb": [[2, 10.5, 2.27]], "batl": NaN}, {"timestamp": 1578762057921, "ltp": 12.0, "tv": 8.3, "trd": NaN, "batb": [[2, 10.5, 12.27]], "batl": NaN}, {"timestamp": 1578762112024, "ltp": 12.0, "tv": 8.3, "trd": NaN, "batb": [[0, 11, 35.24], [1, 10.5, 44.29], [2, 10.5, 0]], "batl": NaN}, {"timestamp": 1578762134710, "ltp": 12.0, "tv": 8.3, "trd": NaN, "batb": [[0, 11.5, 37.52], [1, 11, 35.24], [2, 10.5, 12.27]], "batl": NaN}, {"timestamp": 1578762157971, "ltp": 12.0, "tv": 8.3, "trd": NaN, "batb": [[0, 11.5, 35.02], [2, 10.5, 44.29]], "batl": NaN}, {"timestamp": 1578762158772, "ltp": 12.0, "tv": 8.3, "trd": NaN, "batb": [[0, 11, 35.24], [1, 10.5, 44.29], [2, 10.5, 0]], "batl": NaN}, {"timestamp": 1578762162055, "ltp": 12.0, "tv": 8.3, "trd": NaN, "batb": [[0, 12, 34.95], [1, 11.5, 27.46], [2, 11, 35.24]], "batl": NaN}, {"timestamp": 1578762162958, "ltp": 12.0, "tv": 8.3, "trd": NaN, "batb": [[0, 11, 35.24], [1, 10.5, 44.29], [2, 11, 0]], "batl": NaN}, {"timestamp": 1578762166988, "ltp": 12.0, "tv": 8.3, "trd": NaN, "batb": [[0, 11.5, 37.52], [1, 11, 35.24], [2, 10.5, 44.29]], "batl": NaN}, {"timestamp": 1578762182990, "ltp": 12.0, "tv": 8.3, "trd": NaN, "batb": [[2, 10.5, 12.27]], "batl": NaN}, {"timestamp": 1578762373781, "ltp": 12.0, "tv": 8.3, "trd": NaN, "batb": [[2, 10.5, 2.27]], "batl": NaN}, {"timestamp": 1578762905015, "ltp": 12.0, "tv": 8.3, "trd": NaN, "batb": [[0, 12.5, 10], [1, 11.5, 37.52], [2, 11, 35.24]], "batl": NaN}, {"timestamp": 1578763072023, "ltp": 12.0, "tv": 8.3, "trd": NaN, "batb": [[2, 11, 37.19]], "batl": NaN}, {"timestamp": 1578763189699, "ltp": 13.5, "tv": 11.3, "trd": [[13.5, 3]], "batb": NaN, "batl": NaN}, {"timestamp": 1578763438818, "ltp": 13.5, "tv": 11.3, "trd": NaN, "batb": [[1, 11, 37.19], [2, 9.8, 10]], "batl": NaN}, {"timestamp": 1578763478034, "ltp": 13.5, "tv": 11.3, "trd": NaN, "batb": [[1, 11.5, 28.96], [2, 11, 37.19]], "batl": NaN}, {"timestamp": 1578764138964, "ltp": 13.5, "tv": 15.3, "trd": [[13.5, 7]], "batb": NaN, "batl": NaN}, {"timestamp": 1578764154019, "ltp": 13.5, "tv": 15.3, "trd": NaN, "batb": [[1, 11, 37.19], [2, 10.5, 33.02]], "batl": NaN}, {"timestamp": 1578764159006, "ltp": 13.5, "tv": 15.3, "trd": NaN, "batb": [[1, 11.5, 27.46], [2, 11, 37.19]], "batl": NaN}, {"timestamp": 1578764375033, "ltp": 13.5, "tv": 15.3, "trd": NaN, "batb": [[1, 11, 37.19], [2, 10.5, 32.14]], "batl": NaN}, {"timestamp": 1578764478976, "ltp": 13.5, "tv": 15.3, "trd": NaN, "batb": [[1, 11.5, 27.46], [2, 11, 37.19]], "batl": NaN}, {"timestamp": 1578764618954, "ltp": 13.5, "tv": 15.3, "trd": NaN, "batb": [[1, 11, 37.19], [2, 10.5, 32.02]], "batl": NaN}, {"timestamp": 1578764642985, "ltp": 13.5, "tv": 15.3, "trd": NaN, "batb": [[1, 11.5, 35.02], [2, 11, 37.19]], "batl": NaN}, {"timestamp": 1578765539048, "ltp": 13.5, "tv": 15.3, "trd": NaN, "batb": [[1, 11, 37.19], [2, 10.5, 32.52]], "batl": NaN}, {"timestamp": 1578765783921, "ltp": 13.5, "tv": 15.3, "trd": NaN, "batb": [[1, 11.5, 27.8], [2, 11, 37.19]], "batl": NaN}, {"timestamp": 1578765970033, "ltp": 13.5, "tv": 15.3, "trd": NaN, "batb": NaN, "batl": [[1, 15.5, 21.97], [2, 18, 17.96]]}, {"timestamp": 1578765972005, "ltp": 13.5, "tv": 15.3, "trd": NaN, "batb": [[1, 11.5, 58.89], [2, 11, 69.69]], "batl": NaN}, {"timestamp": 1578766574041, "ltp": 13.5, "tv": 15.3, "trd": NaN, "batb": [[1, 11.5, 31.09]], "batl": NaN}, {"timestamp": 1578766579045, "ltp": 13.5, "tv": 15.3, "trd": NaN, "batb": [[1, 11.5, 60.05]], "batl": NaN}, {"timestamp": 1578766601956, "ltp": 13.5, "tv": 15.3, "trd": NaN, "batb": [[1, 12, 29.79], [2, 11.5, 60.05]], "batl": NaN}, {"timestamp": 1578767296961, "ltp": 13.5, "tv": 15.3, "trd": NaN, "batb": [[2, 11.5, 61.58]], "batl": NaN}, {"timestamp": 1578767666988, "ltp": 12.5, "tv": 23.3, "trd": [[12.5, 8]], "batb": [[0, 12.5, 6]], "batl": NaN}, {"timestamp": 1578767667953, "ltp": 12.5, "tv": 23.3, "trd": NaN, "batb": [[1, 11.5, 61.58], [2, 11, 67.74]], "batl": NaN}, {"timestamp": 1578767766913, "ltp": 12.5, "tv": 35.3, "trd": [[12.5, 20]], "batb": [[0, 11.5, 61.58], [1, 11, 67.74], [2, 10.5, 34.05]], "batl": [[0, 12.5, 19], [1, 15, 16.2], [2, 15.5, 21.97]]}, {"timestamp": 1578767768027, "ltp": 12.5, "tv": 35.3, "trd": NaN, "batb": NaN, "batl": [[1, 15, 38.21]]}, {"timestamp": 1578767773802, "ltp": 12.0, "tv": 35.59, "trd": [[12, 8.6]], "batb": NaN, "batl": NaN}, {"timestamp": 1578767808462, "ltp": 12.0, "tv": 40.59, "trd": [[12, 13.6]], "batb": NaN, "batl": NaN}, {"timestamp": 1578768225859, "ltp": 12.5, "tv": 56.71, "trd": [[12.5, 36.12]], "batb": NaN, "batl": [[0, 12.5, 10.94]]}, {"timestamp": 1578768226971, "ltp": 12.5, "tv": 78.59, "trd": [[12.5, 58]], "batb": [[0, 12, 28.47], [1, 11.5, 61.58], [2, 11, 67.74]], "batl": [[0, 15, 38.21], [1, 15.5, 21.97], [2, 18, 17.96]]}, {"timestamp": 1578768229665, "ltp": 12.5, "tv": 78.59, "trd": NaN, "batb": [[0, 11.5, 61.58], [1, 11, 67.74], [2, 11, 0]], "batl": [[0, 15, 16.2]]}, {"timestamp": 1578768232971, "ltp": 12.5, "tv": 78.59, "trd": NaN, "batb": [[2, 10, 33.39]], "batl": NaN}, {"timestamp": 1578768313416, "ltp": 12.5, "tv": 78.59, "trd": NaN, "batb": [[0, 11.5, 60.05]], "batl": [[0, 15, 15.83]]}, {"timestamp": 1578769090982, "ltp": 12.5, "tv": 78.59, "trd": NaN, "batb": [[0, 12, 4.97], [1, 11.5, 60.05], [2, 11, 67.74]], "batl": NaN}, {"timestamp": 1578769351973, "ltp": 12.5, "tv": 78.59, "trd": NaN, "batb": NaN, "batl": [[0, 15, 15.85]]}, {"timestamp": 1578769608019, "ltp": 12.0, "tv": 84.72, "trd": [[12, 19.72]], "batb": [[0, 12, 1.91]], "batl": NaN}, {"timestamp": 1578770088752, "ltp": 12.0, "tv": 88.62, "trd": [[12, 23.63]], "batb": [[0, 11.5, 60.05], [1, 11, 67.74], [2, 10, 33.39]], "batl": NaN}, {"timestamp": 1578770090848, "ltp": 12.0, "tv": 88.62, "trd": NaN, "batb": [[0, 12, 29.79], [1, 11.5, 60.05], [2, 11, 67.74]], "batl": NaN}, {"timestamp": 1578770194914, "ltp": 12.0, "tv": 88.62, "trd": NaN, "batb": [[1, 11.5, 31.09]], "batl": [[0, 13.5, 26.48], [1, 15, 39.69], [2, 15.5, 21.97]]}, {"timestamp": 1578770225033, "ltp": 12.0, "tv": 88.62, "trd": NaN, "batb": [[1, 11.5, 68.61]], "batl": NaN}, {"timestamp": 1578770257003, "ltp": 12.0, "tv": 88.62, "trd": NaN, "batb": [[1, 11.5, 31.09]], "batl": NaN}, {"timestamp": 1578770296021, "ltp": 12.0, "tv": 88.62, "trd": NaN, "batb": [[1, 11.5, 66.11]], "batl": NaN}, {"timestamp": 1578770304034, "ltp": 12.0, "tv": 88.62, "trd": NaN, "batb": NaN, "batl": [[0, 13, 5.96], [1, 13.5, 26.48], [2, 15, 39.69]]}, {"timestamp": 1578770315938, "ltp": 12.0, "tv": 88.62, "trd": NaN, "batb": NaN, "batl": [[0, 13, 9.71]]}, {"timestamp": 1578770344960, "ltp": 12.0, "tv": 88.62, "trd": NaN, "batb": NaN, "batl": [[1, 15, 39.69], [2, 15.5, 21.97]]}, {"timestamp": 1578770375706, "ltp": 12.0, "tv": 88.62, "trd": NaN, "batb": NaN, "batl": [[1, 13.5, 26.48], [2, 15, 39.69]]}, {"timestamp": 1578770410677, "ltp": 12.0, "tv": 88.62, "trd": NaN, "batb": NaN, "batl": [[0, 12.5, 5.7], [1, 13, 9.71], [2, 13.5, 26.48]]}, {"timestamp": 1578770411952, "ltp": 12.5, "tv": 99.45, "trd": [[12.5, 68.82]], "batb": NaN, "batl": [[0, 13, 9.99], [1, 13.5, 26.48], [2, 15, 39.69]]}, {"timestamp": 1578770416990, "ltp": 12.5, "tv": 99.45, "trd": NaN, "batb": [[0, 12, 32.67]], "batl": NaN}, {"timestamp": 1578770557020, "ltp": 12.0, "tv": 111.45, "trd": [[12, 35.63]], "batb": [[0, 12, 26.67]], "batl": NaN}, {"timestamp": 1578770588954, "ltp": 12.0, "tv": 111.45, "trd": NaN, "batb": [[0, 12, 2.88]], "batl": NaN}, {"timestamp": 1578770656042, "ltp": 12.0, "tv": 111.45, "trd": NaN, "batb": [[1, 11.5, 31.09]], "batl": NaN}, {"timestamp": 1578770675962, "ltp": 12.0, "tv": 111.45, "trd": NaN, "batb": [[1, 11.5, 60.05]], "batl": NaN}, {"timestamp": 1578770696000, "ltp": 12.0, "tv": 111.45, "trd": NaN, "batb": [[1, 11.5, 31.09]], "batl": NaN}, {"timestamp": 1578770701008, "ltp": 12.0, "tv": 111.45, "trd": NaN, "batb": [[0, 11.5, 33.97], [1, 11, 67.74], [2, 10.5, 62.1]], "batl": NaN}, {"timestamp": 1578770707000, "ltp": 12.0, "tv": 111.45, "trd": NaN, "batb": NaN, "batl": [[1, 15, 39.69], [2, 15.5, 21.97]]}, {"timestamp": 1578770711986, "ltp": 12.0, "tv": 111.45, "trd": NaN, "batb": [[0, 11.5, 71.49], [2, 10.5, 30.08]], "batl": NaN}, {"timestamp": 1578770722032, "ltp": 12.0, "tv": 111.45, "trd": NaN, "batb": [[0, 11.5, 33.97], [2, 10.5, 62.1]], "batl": NaN}, {"timestamp": 1578770737045, "ltp": 12.0, "tv": 111.45, "trd": NaN, "batb": [[0, 11.5, 68.99], [2, 10.5, 30.08]], "batl": NaN}, {"timestamp": 1578770741962, "ltp": 12.0, "tv": 111.45, "trd": NaN, "batb": [[0, 11.5, 33.97], [2, 10.5, 62.78]], "batl": NaN}, {"timestamp": 1578770773963, "ltp": 12.0, "tv": 111.45, "trd": NaN, "batb": [[0, 11.5, 68.99], [2, 10.5, 30.08]], "batl": NaN}, {"timestamp": 1578770820898, "ltp": 12.0, "tv": 113.45, "trd": [[12, 37.63]], "batb": NaN, "batl": NaN}, {"timestamp": 1578770838018, "ltp": 12.0, "tv": 113.45, "trd": NaN, "batb": NaN, "batl": [[0, 13, 29.99]]}, {"timestamp": 1578770841033, "ltp": 12.0, "tv": 113.45, "trd": NaN, "batb": NaN, "batl": [[1, 13.5, 26.48], [2, 15, 39.69]]}, {"timestamp": 1578770867973, "ltp": 12.0, "tv": 113.45, "trd": NaN, "batb": NaN, "batl": [[0, 13, 26.24]]}, {"timestamp": 1578770869990, "ltp": 12.0, "tv": 113.45, "trd": NaN, "batb": NaN, "batl": [[1, 15, 39.69], [2, 15.5, 21.97]]}, {"timestamp": 1578770881988, "ltp": 12.0, "tv": 113.45, "trd": NaN, "batb": [[0, 12, 1.81], [1, 11.5, 68.99], [2, 11, 67.74]], "batl": NaN}, {"timestamp": 1578770894005, "ltp": 12.0, "tv": 113.45, "trd": NaN, "batb": [[0, 11.5, 68.99], [1, 11, 67.74], [2, 10.5, 30.08]], "batl": NaN}, {"timestamp": 1578770903941, "ltp": 12.0, "tv": 113.45, "trd": NaN, "batb": NaN, "batl": [[1, 13.5, 26.48], [2, 15, 39.69]]}, {"timestamp": 1578770925038, "ltp": 12.0, "tv": 113.45, "trd": NaN, "batb": [[0, 11.5, 33.97], [2, 10.5, 62.1]], "batl": NaN}, {"timestamp": 1578770942954, "ltp": 12.0, "tv": 113.45, "trd": NaN, "batb": [[0, 11.5, 71.49], [2, 10.5, 30.08]], "batl": NaN}, {"timestamp": 1578770943974, "ltp": 12.0, "tv": 113.45, "trd": NaN, "batb": NaN, "batl": [[1, 15, 39.69], [2, 15.5, 21.97]]}, {"timestamp": 1578770966990, "ltp": 12.0, "tv": 113.45, "trd": NaN, "batb": NaN, "batl": [[1, 13.5, 26.48], [2, 15, 39.69]]}, {"timestamp": 1578770988043, "ltp": 13.0, "tv": 144.06, "trd": [[12.5, 69.39], [13, 30.04]], "batb": NaN, "batl": [[0, 13, 10.94]]}, {"timestamp": 1578770990955, "ltp": 13.0, "tv": 144.06, "trd": NaN, "batb": NaN, "batl": [[1, 15, 39.69], [2, 15.5, 21.97]]}, {"timestamp": 1578771006029, "ltp": 13.0, "tv": 144.06, "trd": NaN, "batb": [[0, 11.5, 33.97], [2, 10.5, 62.1]], "batl": NaN}, {"timestamp": 1578771013973, "ltp": 13.0, "tv": 144.06, "trd": NaN, "batb": [[1, 11, 85.74], [2, 10.5, 81.1]], "batl": [[2, 15.5, 34.97]]}, {"timestamp": 1578771037054, "ltp": 13.0, "tv": 144.06, "trd": NaN, "batb": [[0, 12.5, 22.13], [1, 11.5, 68.99], [2, 11, 85.74]], "batl": NaN}, {"timestamp": 1578771047978, "ltp": 13.0, "tv": 144.06, "trd": NaN, "batb": NaN, "batl": [[1, 15, 15.85]]}, {"timestamp": 1578771054960, "ltp": 12.5, "tv": 165.72, "trd": [[12.5, 91.05]], "batb": [[0, 12.5, 11.3]], "batl": NaN}, {"timestamp": 1578771055963, "ltp": 12.5, "tv": 176.54, "trd": [[12.5, 101.87]], "batb": [[0, 12.5, 5.89]], "batl": NaN}, {"timestamp": 1578771061992, "ltp": 12.5, "tv": 181.96, "trd": [[12.5, 107.29]], "batb": [[0, 12.5, 3.18], [1, 11.5, 33.97]], "batl": NaN}, {"timestamp": 1578771070026, "ltp": 12.5, "tv": 184.66, "trd": [[12.5, 109.99]], "batb": [[0, 12.5, 1.83]], "batl": NaN}, {"timestamp": 1578771070926, "ltp": 12.5, "tv": 184.66, "trd": NaN, "batb": [[0, 12.5, 10.34]], "batl": NaN}, {"timestamp": 1578771075010, "ltp": 12.5, "tv": 194.52, "trd": [[12.5, 119.85]], "batb": [[0, 12.5, 5.41], [1, 11.5, 68.99]], "batl": NaN}, {"timestamp": 1578771082023, "ltp": 12.5, "tv": 199.46, "trd": [[12.5, 124.79]], "batb": [[0, 12.5, 2.95]], "batl": NaN}, {"timestamp": 1578771090996, "ltp": 12.5, "tv": 204.56, "trd": [[12.5, 129.9]], "batb": [[0, 11.5, 69.38], [1, 11, 85.74], [2, 10.5, 49.08]], "batl": NaN}, {"timestamp": 1578771149959, "ltp": 12.5, "tv": 204.56, "trd": NaN, "batb": [[0, 11.5, 34.36], [2, 10.5, 81.6]], "batl": NaN}, {"timestamp": 1578771157959, "ltp": 12.5, "tv": 204.56, "trd": NaN, "batb": [[0, 11.5, 62.16]], "batl": NaN}, {"timestamp": 1578771165006, "ltp": 12.5, "tv": 204.56, "trd": NaN, "batb": [[2, 10.5, 49.08]], "batl": NaN}, {"timestamp": 1578771200962, "ltp": 12.0, "tv": 213.96, "trd": [[12, 46.24], [12.5, 130.68]], "batb": [[0, 11.5, 61.77]], "batl": NaN}, {"timestamp": 1578771205050, "ltp": 12.0, "tv": 213.96, "trd": NaN, "batb": [[0, 11.5, 58.89]], "batl": NaN}, {"timestamp": 1578771208964, "ltp": 13.0, "tv": 224.9, "trd": [[13, 40.98]], "batb": NaN, "batl": [[0, 15, 19.42], [1, 15.5, 34.97], [2, 16, 34.34]]}, {"timestamp": 1578771209961, "ltp": 13.0, "tv": 224.9, "trd": NaN, "batb": NaN, "batl": [[0, 15, 43.26]]}, {"timestamp": 1578771211889, "ltp": 13.0, "tv": 224.9, "trd": NaN, "batb": [[0, 12, 29.79], [1, 11.5, 58.89], [2, 11, 85.74]], "batl": [[0, 15, 19.42]]}, {"timestamp": 1578771232974, "ltp": 13.0, "tv": 224.9, "trd": NaN, "batb": [[0, 14, 2.64], [1, 12, 29.79], [2, 11.5, 58.89]], "batl": NaN}, {"timestamp": 1578771240005, "ltp": 13.0, "tv": 224.9, "trd": NaN, "batb": NaN, "batl": [[0, 15, 15.85]]}, {"timestamp": 1578771240801, "ltp": 13.0, "tv": 224.9, "trd": NaN, "batb": [[0, 14, 28.18]], "batl": NaN}, {"timestamp": 1578771242835, "ltp": 13.0, "tv": 224.9, "trd": NaN, "batb": [[1, 13.5, 26.48], [2, 12, 29.79]], "batl": NaN}, {"timestamp": 1578771269959, "ltp": 13.0, "tv": 224.9, "trd": NaN, "batb": NaN, "batl": [[0, 14.5, 26.39], [1, 15, 15.85], [2, 15.5, 21.97]]}, {"timestamp": 1578771270745, "ltp": 13.0, "tv": 224.9, "trd": NaN, "batb": NaN, "batl": [[1, 15, 39.69]]}, {"timestamp": 1578771273974, "ltp": 14.0, "tv": 281.25, "trd": [[14, 56.36]], "batb": [[0, 13.5, 26.48], [1, 12, 29.79], [2, 11.5, 75.89]], "batl": [[0, 14, 21.82], [1, 14.5, 26.39], [2, 15, 39.69]]}, {"timestamp": 1578771274975, "ltp": 14.0, "tv": 281.25, "trd": NaN, "batb": NaN, "batl": [[2, 15, 42.33]]}, {"timestamp": 1578771276946, "ltp": 14.0, "tv": 281.25, "trd": NaN, "batb": NaN, "batl": [[1, 14.5, 51.05]]}, {"timestamp": 1578771295018, "ltp": 14.0, "tv": 281.25, "trd": NaN, "batb": [[2, 11.5, 58.89]], "batl": [[1, 14.5, 53.69], [2, 15, 39.69]]}, {"timestamp": 1578771301006, "ltp": 14.0, "tv": 281.25, "trd": NaN, "batb": [[0, 13.5, 27.12]], "batl": NaN}, {"timestamp": 1578771319987, "ltp": 13.5, "tv": 299.62, "trd": [[13.5, 25.37]], "batb": [[0, 13.5, 17.93]], "batl": NaN}, {"timestamp": 1578771320978, "ltp": 13.5, "tv": 299.62, "trd": NaN, "batb": NaN, "batl": [[1, 14.5, 57.39]]}, {"timestamp": 1578771323040, "ltp": 13.5, "tv": 299.62, "trd": NaN, "batb": NaN, "batl": [[1, 14.5, 53.69]]}, {"timestamp": 1578771329933, "ltp": 14.0, "tv": 305.74, "trd": [[14, 62.48]], "batb": NaN, "batl": [[0, 14, 18.76]]}, {"timestamp": 1578771334963, "ltp": 14.0, "tv": 305.74, "trd": NaN, "batb": NaN, "batl": [[2, 15, 52.69]]}, {"timestamp": 1578771339054, "ltp": 14.0, "tv": 305.74, "trd": NaN, "batb": NaN, "batl": [[1, 14.5, 57.39]]}, {"timestamp": 1578771343985, "ltp": 14.0, "tv": 305.74, "trd": NaN, "batb": NaN, "batl": [[2, 15, 39.69]]}, {"timestamp": 1578771350975, "ltp": 14.0, "tv": 305.74, "trd": NaN, "batb": NaN, "batl": [[1, 14.5, 56.11]]}, {"timestamp": 1578771361028, "ltp": 14.0, "tv": 305.74, "trd": NaN, "batb": NaN, "batl": [[1, 14.5, 53.69]]}, {"timestamp": 1578771395031, "ltp": 14.0, "tv": 312.74, "trd": [[14, 69.48]], "batb": NaN, "batl": [[0, 14, 15.26], [1, 14.5, 57.19]]}, {"timestamp": 1578771406980, "ltp": 13.5, "tv": 350.68, "trd": [[13.5, 63.3]], "batb": [[0, 12, 29.79], [1, 11.5, 58.89], [2, 11, 85.74]], "batl": NaN}, {"timestamp": 1578771407976, "ltp": 13.5, "tv": 350.68, "trd": NaN, "batb": [[0, 13.5, 21.54], [1, 12, 29.79], [2, 11.5, 58.89]], "batl": [[1, 14.5, 57.69]]}, {"timestamp": 1578771416008, "ltp": 13.5, "tv": 350.68, "trd": NaN, "batb": [[1, 12, 30.66]], "batl": NaN}, {"timestamp": 1578771438000, "ltp": 13.5, "tv": 350.68, "trd": NaN, "batb": NaN, "batl": [[1, 14.5, 54.19]]}, {"timestamp": 1578771530054, "ltp": 13.5, "tv": 350.68, "trd": NaN, "batb": [[2, 11.5, 75.89]], "batl": NaN}, {"timestamp": 1578771531963, "ltp": 14.0, "tv": 381.2, "trd": [[14, 100]], "batb": [[0, 14, 6.17], [1, 13.5, 21.54], [2, 1