{"info": {"id": "1.166703739", "eventId": "29632571", "eventName": "Over/Under 2.5 Goals", "marketType": "OVER_UNDER_25", "openDate": 1578772101023, "name": "Inter v Atalanta", "numberOfActiveRunner": 2, "countryCode": "", "sport": "TENNIS", "venue": "", "volume": {"total": 911016.59, "preMatch": 154892.51, "inPlay": 756124.08}, "winner": {"id": 47972, "name": "Under 2.5 Goals", "status": "WINNER", "position": 1}, "delay": 7}, "runners": [{"id": 47972, "name": "Under 2.5 Goals", "status": "WINNER", "position": 1, "inPlayOdds": 2.3, "inPlayTime": 1578772101023, "avgPrematch": 2.37, "closedOdds": 1.04, "maxPrematch": 2.56, "minPrematch": 2.28, "maxInPlay": 4.9, "minInPlay": 1.04, "inPlayIndex": 1263, "lengthOdds": 6193, "lengthOddsPrematch": 1263, "lengthOddsInPlay": 4930, "tradedVolume": 633172.22, "preMatchVolume": 53566.43, "inPlayVolume": 579605.79}, {"id": 47973, "name": "Over 2.5 Goals", "status": "LOSER", "position": 2, "inPlayOdds": 1.76, "inPlayTime": 1578772101023, "avgPrematch": 1.72, "closedOdds": 21.0, "maxPrematch": 1.78, "minPrematch": 1.64, "maxInPlay": 21.0, "minInPlay": 1.26, "inPlayIndex": 1658, "lengthOdds": 6143, "lengthOddsPrematch": 1658, "lengthOddsInPlay": 4485, "tradedVolume": 277844.37, "preMatchVolume": 101326.08, "inPlayVolume": 176518.29}], "marketUpdates": [{"timestamp": 1578513294362000000, "openDate": "2020-01-11T19:45:00.000Z", "status": "OPEN", "betDelay": 0, "inPlay": false, "complete": true}, {"timestamp": 1578772101023000000, "openDate": "2020-01-11T19:45:00.000Z", "status": "OPEN", "betDelay": 7, "inPlay": true, "complete": true}, {"timestamp": 1578772294860000000, "openDate": "2020-01-11T19:45:00.000Z", "status": "SUSPENDED", "betDelay": 7, "inPlay": true, "complete": true}, {"timestamp": 1578772347979000000, "openDate": "2020-01-11T19:45:00.000Z", "status": "OPEN", "betDelay": 7, "inPlay": true, "complete": true}, {"timestamp": 1578774525024000000, "openDate": "2020-01-11T19:45:00.000Z", "status": "SUSPENDED", "betDelay": 7, "inPlay": true, "complete": true}, {"timestamp": 1578774556973000000, "openDate": "2020-01-11T19:45:00.000Z", "status": "OPEN", "betDelay": 7, "inPlay": true, "complete": true}, {"timestamp": 1578774580039000000, "openDate": "2020-01-11T19:45:00.000Z", "status": "SUSPENDED", "betDelay": 7, "inPlay": true, "complete": true}, {"timestamp": 1578774582036000000, "openDate": "2020-01-11T19:45:00.000Z", "status": "OPEN", "betDelay": 7, "inPlay": true, "complete": true}, {"timestamp": 1578774866982000000, "openDate": "2020-01-11T19:45:00.000Z", "status": "OPEN", "betDelay": 1, "inPlay": true, "complete": true}, {"timestamp": 1578775780035000000, "openDate": "2020-01-11T19:45:00.000Z", "status": "OPEN", "betDelay": 7, "inPlay": true, "complete": true}, {"timestamp": 1578777631947000000, "openDate": "2020-01-11T19:45:00.000Z", "status": "SUSPENDED", "betDelay": 7, "inPlay": true, "complete": true}, {"timestamp": 1578777690042000000, "openDate": "2020-01-11T19:45:00.000Z", "status": "OPEN", "betDelay": 7, "inPlay": true, "complete": true}, {"timestamp": 1578778337987000000, "openDate": "2020-01-11T19:45:00.000Z", "status": "SUSPENDED", "betDelay": 7, "inPlay": true, "complete": true}, {"timestamp": 1578778432037000000, "openDate": "2020-01-11T19:45:00.000Z", "status": "OPEN", "betDelay": 7, "inPlay": true, "complete": true}, {"timestamp": 1578778774964000000, "openDate": "2020-01-11T19:45:00.000Z", "status": "SUSPENDED", "betDelay": 7, "inPlay": true, "complete": true}, {"timestamp": 1578778909258000000, "openDate": "2020-01-11T19:45:00.000Z", "status": "CLOSED", "betDelay": 7, "inPlay": true, "complete": true}], "odds": [{"runnerId": 47972, "odds": [{"timestamp": 1578651947757, "ltp": 2.44, "tv": 1.67, "trd": [[2.44, 1.67]], "batb": NaN, "batl": [[0, 2.44, 15.38]]}, {"timestamp": 1578654151919, "ltp": 2.44, "tv": 1.67, "trd": NaN, "batb": NaN, "batl": [[0, 2.44, 15.38]]}, {"timestamp": 1578658474009, "ltp": 2.44, "tv": 1.67, "trd": NaN, "batb": [[1, 2.36, 29.19]], "batl": NaN}, {"timestamp": 1578660366961, "ltp": 2.44, "tv": 1.67, "trd": NaN, "batb": NaN, "batl": [[1, 2.5, 2.42]]}, {"timestamp": 1578660616733, "ltp": 2.44, "tv": 1.67, "trd": NaN, "batb": NaN, "batl": [[1, 2.5, 202.17]]}, {"timestamp": 1578661352024, "ltp": 2.44, "tv": 1.67, "trd": [[2.44, 1.67]], "batb": NaN, "batl": [[0, 2.44, 15.35]]}, {"timestamp": 1578661484053, "ltp": 2.44, "tv": 1.67, "trd": NaN, "batb": NaN, "batl": [[1, 2.5, 2.42], [2, 2.52, 199.76]]}, {"timestamp": 1578661484959, "ltp": 2.44, "tv": 1.67, "trd": NaN, "batb": NaN, "batl": [[2, 2.52, 0]]}, {"timestamp": 1578661509014, "ltp": 2.44, "tv": 1.67, "trd": NaN, "batb": NaN, "batl": [[2, 2.52, 199.76]]}, {"timestamp": 1578661697976, "ltp": 2.44, "tv": 1.67, "trd": NaN, "batb": [[2, 2.34, 149.22]], "batl": [[2, 2.56, 199.92]]}, {"timestamp": 1578661698142, "ltp": 2.44, "tv": 1.67, "trd": NaN, "batb": [[2, 2.32, 4]], "batl": [[2, 2.56, 0]]}, {"timestamp": 1578661699778, "ltp": 2.44, "tv": 17.02, "trd": [[2.44, 17.02]], "batb": NaN, "batl": [[0, 2.5, 2.42], [1, 2.5, 0]]}, {"timestamp": 1578661735900, "ltp": 2.44, "tv": 17.02, "trd": NaN, "batb": [[0, 2.38, 147.88]], "batl": [[1, 2.62, 199.75]]}, {"timestamp": 1578661737644, "ltp": 2.44, "tv": 17.02, "trd": NaN, "batb": NaN, "batl": [[1, 2.58, 199.75]]}, {"timestamp": 1578661877958, "ltp": 2.44, "tv": 17.02, "trd": NaN, "batb": NaN, "batl": [[1, 2.54, 2], [2, 2.58, 201.75]]}, {"timestamp": 1578663673674, "ltp": 2.44, "tv": 17.02, "trd": NaN, "batb": [[0, 2.4, 2], [1, 2.38, 145.88], [2, 2.36, 27.19]], "batl": NaN}, {"timestamp": 1578663688801, "ltp": 2.44, "tv": 17.02, "trd": NaN, "batb": [[1, 2.38, 1]], "batl": NaN}, {"timestamp": 1578663738925, "ltp": 2.44, "tv": 17.02, "trd": NaN, "batb": [[2, 2.36, 29.19]], "batl": NaN}, {"timestamp": 1578664752962, "ltp": 2.5, "tv": 22.68, "trd": [[2.48, 0.85], [2.5, 4.82]], "batb": NaN, "batl": [[0, 2.54, 2], [1, 2.58, 201.75], [2, 2.58, 0]]}, {"timestamp": 1578664765015, "ltp": 2.5, "tv": 22.68, "trd": NaN, "batb": [[0, 2.4, 4]], "batl": NaN}, {"timestamp": 1578665131169, "ltp": 2.5, "tv": 22.68, "trd": NaN, "batb": NaN, "batl": [[1, 2.56, 8.48], [2, 2.58, 201.75]]}, {"timestamp": 1578668117416, "ltp": 2.5, "tv": 22.68, "trd": NaN, "batb": NaN, "batl": [[1, 2.56, 208.4], [2, 2.58, 2]]}, {"timestamp": 1578668143789, "ltp": 2.5, "tv": 22.68, "trd": NaN, "batb": NaN, "batl": [[1, 2.56, 8.48], [2, 2.58, 201.75]]}, {"timestamp": 1578668552027, "ltp": 2.5, "tv": 22.72, "trd": [[2.44, 17.06], [2.48, 0.85], [2.5, 4.82]], "batb": NaN, "batl": [[1, 2.56, 8.5]]}, {"timestamp": 1578669553775, "ltp": 2.5, "tv": 22.72, "trd": NaN, "batb": NaN, "batl": [[0, 2.54, 201.75], [2, 2.58, 2]]}, {"timestamp": 1578669554878, "ltp": 2.5, "tv": 22.72, "trd": NaN, "batb": NaN, "batl": [[1, 2.58, 2], [2, 2.58, 0]]}, {"timestamp": 1578669572035, "ltp": 2.5, "tv": 22.72, "trd": NaN, "batb": [[2, 2.36, 176.12]], "batl": NaN}, {"timestamp": 1578669572570, "ltp": 2.5, "tv": 22.72, "trd": NaN, "batb": [[2, 2.36, 29.19]], "batl": NaN}, {"timestamp": 1578669597697, "ltp": 2.5, "tv": 22.72, "trd": NaN, "batb": NaN, "batl": [[0, 2.52, 8.5], [1, 2.54, 201.75], [2, 2.58, 2]]}, {"timestamp": 1578669615023, "ltp": 2.5, "tv": 22.72, "trd": NaN, "batb": NaN, "batl": [[0, 2.5, 199.75], [1, 2.52, 8.5], [2, 2.54, 2]]}, {"timestamp": 1578669615788, "ltp": 2.5, "tv": 22.72, "trd": NaN, "batb": NaN, "batl": [[1, 2.54, 2], [2, 2.58, 2]]}, {"timestamp": 1578669625944, "ltp": 2.5, "tv": 22.72, "trd": NaN, "batb": NaN, "batl": [[0, 2.48, 8.5], [1, 2.5, 199.75], [2, 2.54, 2]]}, {"timestamp": 1578669634837, "ltp": 2.5, "tv": 22.72, "trd": NaN, "batb": NaN, "batl": [[1, 2.54, 2], [2, 2.58, 2]]}, {"timestamp": 1578669637734, "ltp": 2.5, "tv": 22.72, "trd": NaN, "batb": NaN, "batl": [[0, 2.54, 2], [1, 2.58, 2], [2, 2.58, 0]]}, {"timestamp": 1578669645042, "ltp": 2.5, "tv": 22.72, "trd": NaN, "batb": NaN, "batl": [[0, 2.52, 199.76], [1, 2.54, 2], [2, 2.58, 2]]}, {"timestamp": 1578669658168, "ltp": 2.5, "tv": 22.72, "trd": NaN, "batb": NaN, "batl": [[0, 2.5, 8.5], [1, 2.52, 199.76], [2, 2.54, 2]]}, {"timestamp": 1578669671001, "ltp": 2.5, "tv": 22.72, "trd": NaN, "batb": NaN, "batl": [[0, 2.48, 199.99], [1, 2.5, 8.5]]}, {"timestamp": 1578669672801, "ltp": 2.5, "tv": 22.72, "trd": NaN, "batb": NaN, "batl": [[1, 2.54, 2], [2, 2.58, 2]]}, {"timestamp": 1578669717244, "ltp": 2.5, "tv": 22.72, "trd": NaN, "batb": NaN, "batl": [[0, 2.46, 8.5], [1, 2.48, 199.99], [2, 2.54, 2]]}, {"timestamp": 1578671569834, "ltp": 2.46, "tv": 29.32, "trd": [[2.46, 6.59]], "batb": NaN, "batl": [[0, 2.46, 1.9]]}, {"timestamp": 1578671765984, "ltp": 2.46, "tv": 32.71, "trd": [[2.46, 9.99]], "batb": NaN, "batl": [[0, 2.48, 199.99], [1, 2.54, 2], [2, 2.54, 0]]}, {"timestamp": 1578671768890, "ltp": 2.46, "tv": 32.71, "trd": NaN, "batb": [[0, 2.4, 12.5]], "batl": NaN}, {"timestamp": 1578672259954, "ltp": 2.48, "tv": 46.49, "trd": [[2.48, 14.62]], "batb": NaN, "batl": [[0, 2.48, 193.1]]}, {"timestamp": 1578672483981, "ltp": 2.48, "tv": 46.49, "trd": NaN, "batb": [[2, 2.36, 2]], "batl": NaN}, {"timestamp": 1578675751995, "ltp": 2.48, "tv": 46.56, "trd": [[2.44, 17.09], [2.46, 10.01], [2.48, 14.64], [2.5, 4.83]], "batb": [[0, 2.4, 12.51]], "batl": NaN}, {"timestamp": 1578680379013, "ltp": 2.48, "tv": 46.56, "trd": NaN, "batb": NaN, "batl": [[0, 2.48, 195.1]]}, {"timestamp": 1578681613801, "ltp": 2.48, "tv": 46.56, "trd": NaN, "batb": [[0, 2.4, 4]], "batl": NaN}, {"timestamp": 1578682952056, "ltp": 2.48, "tv": 46.57, "trd": [[2.44, 17.09], [2.46, 10.01], [2.48, 14.64]], "batb": NaN, "batl": NaN}, {"timestamp": 1578683192436, "ltp": 2.48, "tv": 46.57, "trd": NaN, "batb": NaN, "batl": [[0, 2.48, 193.1]]}, {"timestamp": 1578683326709, "ltp": 2.48, "tv": 46.57, "trd": NaN, "batb": NaN, "batl": [[0, 2.48, 195.1]]}, {"timestamp": 1578684393021, "ltp": 2.48, "tv": 46.57, "trd": NaN, "batb": NaN, "batl": [[0, 2.48, 193.1]]}, {"timestamp": 1578684393134, "ltp": 2.4, "tv": 50.22, "trd": [[2.4, 3.3], [2.42, 0.22], [2.44, 17.22]], "batb": [[0, 2.4, 2.35]], "batl": NaN}, {"timestamp": 1578684400948, "ltp": 2.4, "tv": 50.22, "trd": NaN, "batb": NaN, "batl": [[1, 2.54, 4]]}, {"timestamp": 1578684779530, "ltp": 2.4, "tv": 50.22, "trd": NaN, "batb": [[1, 2.38, 9.59]], "batl": NaN}, {"timestamp": 1578685052769, "ltp": 2.4, "tv": 50.22, "trd": NaN, "batb": [[0, 2.42, 8.45], [1, 2.4, 2.35], [2, 2.38, 1]], "batl": NaN}, {"timestamp": 1578685108287, "ltp": 2.4, "tv": 50.22, "trd": NaN, "batb": [[0, 2.42, 10.45], [2, 2.32, 151.39]], "batl": NaN}, {"timestamp": 1578685172764, "ltp": 2.4, "tv": 50.22, "trd": NaN, "batb": [[2, 2.32, 153.39]], "batl": NaN}, {"timestamp": 1578685237453, "ltp": 2.4, "tv": 50.22, "trd": NaN, "batb": [[2, 2.32, 151.39]], "batl": NaN}, {"timestamp": 1578685542970, "ltp": 2.4, "tv": 50.22, "trd": NaN, "batb": [[2, 2.32, 179.41]], "batl": NaN}, {"timestamp": 1578686115037, "ltp": 2.4, "tv": 50.22, "trd": NaN, "batb": NaN, "batl": [[0, 2.54, 4], [1, 2.54, 0]]}, {"timestamp": 1578686116041, "ltp": 2.4, "tv": 50.22, "trd": NaN, "batb": [[2, 2.32, 28.02]], "batl": NaN}, {"timestamp": 1578686134051, "ltp": 2.4, "tv": 50.22, "trd": NaN, "batb": [[2, 2.32, 179.41]], "batl": [[0, 2.54, 203.75]]}, {"timestamp": 1578687373055, "ltp": 2.4, "tv": 50.22, "trd": NaN, "batb": [[0, 2.46, 8.31], [1, 2.42, 2], [2, 2.4, 2.35]], "batl": NaN}, {"timestamp": 1578688124959, "ltp": 2.4, "tv": 50.22, "trd": NaN, "batb": [[1, 2.44, 8.38], [2, 2.42, 2]], "batl": NaN}, {"timestamp": 1578688128050, "ltp": 2.4, "tv": 50.22, "trd": NaN, "batb": [[0, 2.44, 8.38], [1, 2.42, 2], [2, 2.4, 2.35]], "batl": NaN}, {"timestamp": 1578688204504, "ltp": 2.4, "tv": 50.22, "trd": NaN, "batb": NaN, "batl": [[1, 2.58, 2]]}, {"timestamp": 1578689230890, "ltp": 2.4, "tv": 50.22, "trd": NaN, "batb": [[0, 2.42, 10.45], [1, 2.4, 2.35], [2, 2.36, 146.93]], "batl": NaN}, {"timestamp": 1578689558981, "ltp": 2.4, "tv": 50.22, "trd": NaN, "batb": [[2, 2.34, 149.22]], "batl": NaN}, {"timestamp": 1578690038015, "ltp": 2.4, "tv": 50.23, "trd": [[2.44, 17.23], [2.46, 10.02], [2.48, 14.64], [2.5, 4.83]], "batb": [[0, 2.42, 10.45]], "batl": NaN}, {"timestamp": 1578693291888, "ltp": 2.4, "tv": 50.23, "trd": NaN, "batb": NaN, "batl": [[2, 2.6, 2]]}, {"timestamp": 1578697352006, "ltp": 2.4, "tv": 50.21, "trd": [[2.44, 17.22], [2.46, 10.01], [2.48, 14.64], [2.5, 4.83]], "batb": [[0, 2.42, 10.44]], "batl": NaN}, {"timestamp": 1578697583878, "ltp": 2.4, "tv": 50.21, "trd": NaN, "batb": [[0, 2.46, 8.31], [1, 2.42, 2], [2, 2.4, 2.35]], "batl": NaN}, {"timestamp": 1578698459045, "ltp": 2.4, "tv": 50.21, "trd": NaN, "batb": [[0, 2.46, 15.65], [1, 2.44, 7.41], [2, 2.42, 2]], "batl": [[0, 2.52, 7.17], [1, 2.54, 210.87], [2, 2.58, 2]]}, {"timestamp": 1578698463824, "ltp": 2.4, "tv": 50.21, "trd": NaN, "batb": NaN, "batl": [[1, 2.54, 11.12], [2, 2.58, 201.75]]}, {"timestamp": 1578698814934, "ltp": 2.4, "tv": 50.21, "trd": NaN, "batb": [[0, 2.46, 7.35], [1, 2.44, 15.78]], "batl": NaN}, {"timestamp": 1578702129792, "ltp": 2.52, "tv": 57.37, "trd": [[2.52, 7.17]], "batb": NaN, "batl": [[0, 2.54, 11.12], [1, 2.58, 201.75], [2, 2.6, 2]]}, {"timestamp": 1578702130507, "ltp": 2.52, "tv": 57.37, "trd": NaN, "batb": NaN, "batl": [[0, 2.54, 4], [1, 2.56, 7.11], [2, 2.58, 208.8]]}, {"timestamp": 1578702245405, "ltp": 2.52, "tv": 57.37, "trd": NaN, "batb": NaN, "batl": [[1, 2.56, 9.11], [2, 2.58, 206.8]]}, {"timestamp": 1578704605790, "ltp": 2.52, "tv": 57.37, "trd": NaN, "batb": [[0, 2.48, 8.24], [1, 2.46, 7.35], [2, 2.44, 7.41]], "batl": NaN}, {"timestamp": 1578704606612, "ltp": 2.52, "tv": 57.37, "trd": NaN, "batb": [[0, 2.48, 15.6]], "batl": NaN}, {"timestamp": 1578704613643, "ltp": 2.52, "tv": 57.37, "trd": NaN, "batb": NaN, "batl": [[0, 2.54, 11.19]]}, {"timestamp": 1578705345259, "ltp": 2.52, "tv": 57.37, "trd": NaN, "batb": NaN, "batl": [[0, 2.54, 4], [1, 2.56, 2]]}, {"timestamp": 1578707160945, "ltp": 2.52, "tv": 57.37, "trd": NaN, "batb": [[0, 2.48, 32.63]], "batl": [[1, 2.56, 19.02]]}, {"timestamp": 1578707161461, "ltp": 2.52, "tv": 57.37, "trd": NaN, "batb": [[0, 2.5, 7.34], [1, 2.48, 32.63], [2, 2.46, 7.35]], "batl": [[1, 2.56, 26.19]]}, {"timestamp": 1578708733489, "ltp": 2.52, "tv": 57.37, "trd": NaN, "batb": NaN, "batl": [[0, 2.54, 11.24]]}, {"timestamp": 1578713443600, "ltp": 2.52, "tv": 57.37, "trd": NaN, "batb": NaN, "batl": [[0, 2.54, 4]]}, {"timestamp": 1578714042961, "ltp": 2.52, "tv": 57.37, "trd": NaN, "batb": NaN, "batl": [[1, 2.56, 19.02]]}, {"timestamp": 1578714823470, "ltp": 2.52, "tv": 57.37, "trd": NaN, "batb": NaN, "batl": [[1, 2.56, 26.29]]}, {"timestamp": 1578714824601, "ltp": 2.52, "tv": 57.37, "trd": NaN, "batb": NaN, "batl": [[1, 2.56, 19.02]]}, {"timestamp": 1578714825481, "ltp": 2.52, "tv": 57.37, "trd": NaN, "batb": NaN, "batl": [[1, 2.56, 26.29]]}, {"timestamp": 1578714844299, "ltp": 2.52, "tv": 57.37, "trd": NaN, "batb": NaN, "batl": [[1, 2.56, 19.02]]}, {"timestamp": 1578714925949, "ltp": 2.52, "tv": 57.37, "trd": NaN, "batb": NaN, "batl": [[0, 2.54, 45.51], [1, 2.56, 26.29]]}, {"timestamp": 1578716351911, "ltp": 2.52, "tv": 57.37, "trd": NaN, "batb": NaN, "batl": [[2, 2.58, 7.05]]}, {"timestamp": 1578716548979, "ltp": 2.52, "tv": 57.37, "trd": NaN, "batb": NaN, "batl": [[2, 2.58, 206.8]]}, {"timestamp": 1578717694741, "ltp": 2.54, "tv": 60.78, "trd": [[2.54, 3.4]], "batb": NaN, "batl": [[0, 2.54, 43.81]]}, {"timestamp": 1578719212045, "ltp": 2.54, "tv": 60.78, "trd": NaN, "batb": NaN, "batl": [[2, 2.58, 7.05]]}, {"timestamp": 1578720291016, "ltp": 2.54, "tv": 60.78, "trd": NaN, "batb": NaN, "batl": [[2, 2.58, 206.8]]}, {"timestamp": 1578720477030, "ltp": 2.54, "tv": 60.78, "trd": NaN, "batb": NaN, "batl": [[2, 2.58, 7.05]]}, {"timestamp": 1578720482030, "ltp": 2.54, "tv": 60.78, "trd": NaN, "batb": NaN, "batl": [[2, 2.58, 206.8]]}, {"timestamp": 1578720484811, "ltp": 2.54, "tv": 60.78, "trd": NaN, "batb": NaN, "batl": [[2, 2.58, 7.05]]}, {"timestamp": 1578720485734, "ltp": 2.54, "tv": 60.78, "trd": NaN, "batb": NaN, "batl": [[2, 2.58, 206.8]]}, {"timestamp": 1578720554818, "ltp": 2.54, "tv": 60.78, "trd": NaN, "batb": NaN, "batl": [[2, 2.58, 7.05]]}, {"timestamp": 1578721225837, "ltp": 2.54, "tv": 60.78, "trd": NaN, "batb": NaN, "batl": [[0, 2.54, 46.1]]}, {"timestamp": 1578721828984, "ltp": 2.54, "tv": 60.78, "trd": NaN, "batb": NaN, "batl": [[2, 2.58, 206.8]]}, {"timestamp": 1578722284794, "ltp": 2.54, "tv": 60.78, "trd": NaN, "batb": NaN, "batl": [[0, 2.54, 38.78]]}, {"timestamp": 1578722462774, "ltp": 2.54, "tv": 60.78, "trd": NaN, "batb": NaN, "batl": [[1, 2.56, 19.02]]}, {"timestamp": 1578722482806, "ltp": 2.54, "tv": 62.26, "trd": [[2.54, 4.88]], "batb": NaN, "batl": [[0, 2.54, 37.3]]}, {"timestamp": 1578722648930, "ltp": 2.54, "tv": 62.26, "trd": NaN, "batb": NaN, "batl": [[2, 2.58, 7.05]]}, {"timestamp": 1578722659962, "ltp": 2.54, "tv": 62.26, "trd": NaN, "batb": NaN, "batl": [[2, 2.58, 206.8]]}, {"timestamp": 1578722661046, "ltp": 2.54, "tv": 62.26, "trd": NaN, "batb": NaN, "batl": [[1, 2.56, 26.41]]}, {"timestamp": 1578722661664, "ltp": 2.54, "tv": 62.26, "trd": NaN, "batb": NaN, "batl": [[1, 2.56, 19.02]]}, {"timestamp": 1578722662801, "ltp": 2.54, "tv": 62.26, "trd": NaN, "batb": NaN, "batl": [[1, 2.56, 26.41], [2, 2.58, 7.05]]}, {"timestamp": 1578722664462, "ltp": 2.54, "tv": 62.26, "trd": NaN, "batb": NaN, "batl": [[2, 2.58, 206.8]]}, {"timestamp": 1578722665960, "ltp": 2.54, "tv": 62.26, "trd": NaN, "batb": NaN, "batl": [[2, 2.58, 7.05]]}, {"timestamp": 1578722666683, "ltp": 2.52, "tv": 65.69, "trd": [[2.52, 10.6]], "batb": NaN, "batl": [[2, 2.58, 206.8]]}, {"timestamp": 1578722667147, "ltp": 2.52, "tv": 65.69, "trd": NaN, "batb": NaN, "batl": [[0, 2.54, 44.74]]}, {"timestamp": 1578723086042, "ltp": 2.52, "tv": 65.69, "trd": NaN, "batb": NaN, "batl": [[2, 2.58, 7.05]]}, {"timestamp": 1578723239426, "ltp": 2.52, "tv": 65.69, "trd": NaN, "batb": NaN, "batl": [[0, 2.54, 37.3]]}, {"timestamp": 1578723934036, "ltp": 2.52, "tv": 65.69, "trd": NaN, "batb": NaN, "batl": [[2, 2.58, 206.8]]}, {"timestamp": 1578723965984, "ltp": 2.54, "tv": 100.21, "trd": [[2.54, 39.41]], "batb": NaN, "batl": [[0, 2.54, 2.77]]}, {"timestamp": 1578723966763, "ltp": 2.54, "tv": 100.21, "trd": NaN, "batb": NaN, "batl": [[1, 2.56, 19.02]]}, {"timestamp": 1578723998036, "ltp": 2.54, "tv": 105.75, "trd": [[2.54, 44.95]], "batb": [[0, 2.54, 1.06], [1, 2.5, 7.34], [2, 2.48, 32.63]], "batl": [[0, 2.56, 19.02], [1, 2.58, 206.8], [2, 2.6, 9.04]]}, {"timestamp": 1578724016038, "ltp": 2.54, "tv": 105.75, "trd": NaN, "batb": [[1, 2.52, 3.83], [2, 2.5, 7.34]], "batl": NaN}, {"timestamp": 1578724016859, "ltp": 2.52, "tv": 109.58, "trd": [[2.52, 13.37], [2.54, 46.01]], "batb": [[0, 2.52, 1.06], [1, 2.5, 7.34], [2, 2.48, 32.63]], "batl": NaN}, {"timestamp": 1578724034957, "ltp": 2.52, "tv": 109.58, "trd": NaN, "batb": [[2, 2.48, 36.45]], "batl": NaN}, {"timestamp": 1578724111482, "ltp": 2.5, "tv": 117.48, "trd": [[2.5, 10.61], [2.52, 15.49]], "batb": [[0, 2.5, 4.44], [1, 2.48, 36.45], [2, 2.46, 7.35]], "batl": NaN}, {"timestamp": 1578724114001, "ltp": 2.5, "tv": 117.48, "trd": NaN, "batb": NaN, "batl": [[0, 2.56, 26.46]]}, {"timestamp": 1578724205807, "ltp": 2.5, "tv": 117.48, "trd": NaN, "batb": NaN, "batl": [[1, 2.58, 7.05], [2, 2.6, 208.8]]}, {"timestamp": 1578724576949, "ltp": 2.5, "tv": 117.48, "trd": NaN, "batb": NaN, "batl": [[1, 2.58, 206.8], [2, 2.6, 9.04]]}, {"timestamp": 1578724653745, "ltp": 2.5, "tv": 117.48, "trd": NaN, "batb": NaN, "batl": [[1, 2.58, 7.05], [2, 2.6, 208.8]]}, {"timestamp": 1578724829031, "ltp": 2.5, "tv": 117.48, "trd": NaN, "batb": NaN, "batl": [[1, 2.58, 206.8], [2, 2.6, 9.04]]}, {"timestamp": 1578724856753, "ltp": 2.5, "tv": 117.48, "trd": NaN, "batb": NaN, "batl": [[1, 2.58, 7.05], [2, 2.6, 208.8]]}, {"timestamp": 1578724858040, "ltp": 2.5, "tv": 117.48, "trd": NaN, "batb": NaN, "batl": [[0, 2.54, 7.52], [1, 2.56, 26.46], [2, 2.58, 7.05]]}, {"timestamp": 1578724878477, "ltp": 2.5, "tv": 117.48, "trd": NaN, "batb": NaN, "batl": [[0, 2.56, 26.46], [1, 2.58, 7.05], [2, 2.6, 208.8]]}, {"timestamp": 1578724925125, "ltp": 2.5, "tv": 117.48, "trd": NaN, "batb": NaN, "batl": [[0, 2.54, 7.52], [1, 2.56, 26.46], [2, 2.58, 7.05]]}, {"timestamp": 1578725755013, "ltp": 2.5, "tv": 117.48, "trd": NaN, "batb": NaN, "batl": [[2, 2.58, 206.8]]}, {"timestamp": 1578725759221, "ltp": 2.5, "tv": 121.5, "trd": [[2.5, 14.63]], "batb": [[0, 2.5, 2.43]], "batl": NaN}, {"timestamp": 1578726081603, "ltp": 2.5, "tv": 121.5, "trd": NaN, "batb": NaN, "batl": [[0, 2.56, 26.46], [1, 2.58, 206.8], [2, 2.6, 9.04]]}, {"timestamp": 1578726082800, "ltp": 2.5, "tv": 121.5, "trd": NaN, "batb": NaN, "batl": [[0, 2.54, 7.53], [1, 2.56, 26.46], [2, 2.58, 206.8]]}, {"timestamp": 1578726083998, "ltp": 2.5, "tv": 121.5, "trd": NaN, "batb": NaN, "batl": [[0, 2.56, 26.46], [1, 2.58, 206.8], [2, 2.6, 9.04]]}, {"timestamp": 1578728587011, "ltp": 2.5, "tv": 125.88, "trd": [[2.5, 19.01]], "batb": [[0, 2.48, 36.7], [1, 2.46, 7.35], [2, 2.44, 7.41]], "batl": NaN}, {"timestamp": 1578728587735, "ltp": 2.5, "tv": 125.88, "trd": NaN, "batb": [[0, 2.48, 36.45]], "batl": [[0, 2.54, 7.58], [1, 2.56, 26.46], [2, 2.58, 206.8]]}, {"timestamp": 1578728781474, "ltp": 2.5, "tv": 125.88, "trd": NaN, "batb": [[0, 2.5, 7.71], [1, 2.48, 36.45], [2, 2.46, 7.35]], "batl": NaN}, {"timestamp": 1578728995971, "ltp": 2.5, "tv": 133.1, "trd": [[2.5, 26.23]], "batb": [[0, 2.5, 4.1]], "batl": NaN}, {"timestamp": 1578728997852, "ltp": 2.5, "tv": 133.1, "trd": NaN, "batb": [[0, 2.48, 36.45], [1, 2.46, 7.35], [2, 2.44, 7.41]], "batl": NaN}, {"timestamp": 1578729046036, "ltp": 2.5, "tv": 133.1, "trd": NaN, "batb": NaN, "batl": [[0, 2.52, 2.55], [1, 2.54, 7.58], [2, 2.56, 26.46]]}, {"timestamp": 1578729046815, "ltp": 2.5, "tv": 133.1, "trd": NaN, "batb": NaN, "batl": [[0, 2.52, 10.21]]}, {"timestamp": 1578729047597, "ltp": 2.5, "tv": 133.1, "trd": NaN, "batb": [[0, 2.5, 7.71], [1, 2.48, 36.45], [2, 2.46, 7.35]], "batl": NaN}, {"timestamp": 1578729048799, "ltp": 2.5, "tv": 133.1, "trd": NaN, "batb": NaN, "batl": [[0, 2.52, 2.55]]}, {"timestamp": 1578729072444, "ltp": 2.5, "tv": 133.1, "trd": NaN, "batb": NaN, "batl": [[1, 2.56, 26.46], [2, 2.58, 206.8]]}, {"timestamp": 1578729215794, "ltp": 2.5, "tv": 140.32, "trd": [[2.5, 33.44]], "batb": [[0, 2.5, 4.1]], "batl": NaN}, {"timestamp": 1578729216880, "ltp": 2.5, "tv": 140.32, "trd": NaN, "batb": NaN, "batl": [[1, 2.54, 7.6], [2, 2.56, 26.46]]}, {"timestamp": 1578729421901, "ltp": 2.5, "tv": 148.01, "trd": [[2.5, 41.14]], "batb": [[0, 2.48, 36.71], [1, 2.46, 7.35], [2, 2.44, 7.41]], "batl": NaN}, {"timestamp": 1578729613728, "ltp": 2.48, "tv": 159.4, "trd": [[2.48, 25.52], [2.5, 41.65]], "batb": [[0, 2.48, 31.02]], "batl": NaN}, {"timestamp": 1578729615336, "ltp": 2.48, "tv": 159.4, "trd": NaN, "batb": [[0, 2.5, 7.74], [1, 2.48, 31.02], [2, 2.46, 7.35]], "batl": NaN}, {"timestamp": 1578729689003, "ltp": 2.5, "tv": 167.14, "trd": [[2.5, 49.39]], "batb": [[0, 2.48, 31.02], [1, 2.46, 7.35], [2, 2.44, 7.41]], "batl": NaN}, {"timestamp": 1578729689981, "ltp": 2.5, "tv": 167.14, "trd": NaN, "batb": [[1, 2.46, 10.17]], "batl": [[0, 2.52, 10.23]]}, {"timestamp": 1578729738894, "ltp": 2.5, "tv": 167.14, "trd": NaN, "batb": [[0, 2.48, 28.22]], "batl": NaN}, {"timestamp": 1578730410002, "ltp": 2.5, "tv": 174.9, "trd": [[2.5, 57.14]], "batb": NaN, "batl": [[0, 2.52, 2.55]]}, {"timestamp": 1578730411499, "ltp": 2.5, "tv": 174.9, "trd": NaN, "batb": NaN, "batl": [[0, 2.52, 10.25]]}, {"timestamp": 1578731379022, "ltp": 2.5, "tv": 182.68, "trd": [[2.5, 64.92]], "batb": NaN, "batl": [[0, 2.52, 2.55]]}, {"timestamp": 1578732361940, "ltp": 2.52, "tv": 183.29, "trd": [[2.52, 16.1]], "batb": NaN, "batl": [[0, 2.52, 1.94]]}, {"timestamp": 1578733208396, "ltp": 2.52, "tv": 183.29, "trd": NaN, "batb": NaN, "batl": [[0, 2.52, 9.7]]}, {"timestamp": 1578733975022, "ltp": 2.52, "tv": 183.29, "trd": NaN, "batb": [[0, 2.5, 7.84], [1, 2.48, 28.22], [2, 2.46, 10.17]], "batl": [[0, 2.52, 1.94]]}, {"timestamp": 1578733975908, "ltp": 2.48, "tv": 203.27, "trd": [[2.48, 29.82], [2.5, 80.6]], "batb": [[0, 2.48, 26.06], [1, 2.46, 10.17], [2, 2.44, 7.41]], "batl": NaN}, {"timestamp": 1578733977051, "ltp": 2.48, "tv": 203.27, "trd": NaN, "batb": [[0, 2.48, 20.85]], "batl": [[0, 2.52, 9.73]]}, {"timestamp": 1578733977947, "ltp": 2.48, "tv": 203.27, "trd": NaN, "batb": [[0, 2.48, 28.76]], "batl": NaN}, {"timestamp": 1578734154479, "ltp": 2.48, "tv": 203.27, "trd": NaN, "batb": [[0, 2.5, 7.85], [1, 2.48, 28.76], [2, 2.46, 10.17]], "batl": [[0, 2.52, 1.94]]}, {"timestamp": 1578734191046, "ltp": 2.5, "tv": 217.43, "trd": [[2.5, 94.77]], "batb": [[0, 2.48, 29.53], [1, 2.46, 10.17], [2, 2.44, 7.41]], "batl": NaN}, {"timestamp": 1578734191942, "ltp": 2.5, "tv": 217.43, "trd": NaN, "batb": [[0, 2.48, 28.76]], "batl": NaN}, {"timestamp": 1578734192146, "ltp": 2.5, "tv": 217.43, "trd": NaN, "batb": NaN, "batl": [[0, 2.52, 9.74]]}, {"timestamp": 1578734425996, "ltp": 2.56, "tv": 239.91, "trd": [[2.52, 25.84], [2.54, 53.61], [2.56, 5.13]], "batb": NaN, "batl": [[0, 2.56, 21.33], [1, 2.58, 206.8], [2, 2.56, 0]]}, {"timestamp": 1578734426783, "ltp": 2.56, "tv": 239.91, "trd": NaN, "batb": [[0, 2.5, 9.51], [1, 2.48, 28.76], [2, 2.46, 10.17]], "batl": [[0, 2.56, 13.89], [2, 2.6, 9.14]]}, {"timestamp": 1578734432006, "ltp": 2.56, "tv": 239.91, "trd": NaN, "batb": NaN, "batl": [[0, 2.56, 21.6]]}, {"timestamp": 1578734945995, "ltp": 2.56, "tv": 239.91, "trd": NaN, "batb": NaN, "batl": [[2, 2.6, 208.9]]}, {"timestamp": 1578734946989, "ltp": 2.56, "tv": 239.91, "trd": NaN, "batb": NaN, "batl": [[1, 2.58, 7.05], [2, 2.6, 9.14]]}, {"timestamp": 1578734950868, "ltp": 2.56, "tv": 239.91, "trd": NaN, "batb": NaN, "batl": [[1, 2.58, 206.8]]}, {"timestamp": 1578734963991, "ltp": 2.56, "tv": 239.91, "trd": NaN, "batb": NaN, "batl": [[1, 2.58, 7.05], [2, 2.6, 208.9]]}, {"timestamp": 1578735072791, "ltp": 2.56, "tv": 239.91, "trd": NaN, "batb": NaN, "batl": [[2, 2.6, 210.9]]}, {"timestamp": 1578735873962, "ltp": 2.5, "tv": 272.5, "trd": [[2.5, 127.36]], "batb": [[0, 2.48, 28.76], [1, 2.46, 10.17], [2, 2.44, 7.41]], "batl": [[0, 2.5, 3.7], [1, 2.56, 21.6], [2, 2.58, 7.05]]}, {"timestamp": 1578735875166, "ltp": 2.5, "tv": 272.5, "trd": NaN, "batb": NaN, "batl": [[1, 2.52, 7.87], [2, 2.54, 7.81]]}, {"timestamp": 1578736341955, "ltp": 2.5, "tv": 276.2, "trd": [[2.5, 131.06]], "batb": NaN, "batl": [[0, 2.52, 7.87], [1, 2.54, 7.81], [2, 2.56, 21.6]]}, {"timestamp": 1578736434612, "ltp": 2.5, "tv": 276.29, "trd": [[2.5, 131.15]], "batb": NaN, "batl": [[0, 2.5, 2.91], [1, 2.52, 7.87], [2, 2.54, 7.81]]}, {"timestamp": 1578736449796, "ltp": 2.5, "tv": 276.29, "trd": NaN, "batb": NaN, "batl": [[0, 2.52, 7.87], [1, 2.54, 7.81], [2, 2.56, 21.6]]}, {"timestamp": 1578736457894, "ltp": 2.48, "tv": 282.29, "trd": [[2.48, 35.82]], "batb": [[0, 2.48, 25.76]], "batl": NaN}, {"timestamp": 1578736942040, "ltp": 2.48, "tv": 282.29, "trd": NaN, "batb": NaN, "batl": [[0, 2.54, 7.81], [1, 2.56, 21.6], [2, 2.58, 206.8]]}, {"timestamp": 1578737090025, "ltp": 2.48, "tv": 282.29, "trd": NaN, "batb": NaN, "batl": [[1, 2.56, 221.52], [2, 2.58, 7.05]]}, {"timestamp": 1578737229880, "ltp": 2.48, "tv": 282.29, "trd": NaN, "batb": NaN, "batl": [[1, 2.56, 21.6], [2, 2.58, 206.8]]}, {"timestamp": 1578737909038, "ltp": 2.48, "tv": 282.29, "trd": NaN, "batb": NaN, "batl": [[1, 2.56, 221.52], [2, 2.58, 7.05]]}, {"timestamp": 1578737923020, "ltp": 2.48, "tv": 282.29, "trd": NaN, "batb": NaN, "batl": [[1, 2.56, 21.6], [2, 2.58, 206.8]]}, {"timestamp": 1578737942040, "ltp": 2.48, "tv": 282.29, "trd": NaN, "batb": NaN, "batl": [[2, 2.58, 7.05]]}, {"timestamp": 1578738026031, "ltp": 2.48, "tv": 282.29, "trd": NaN, "batb": NaN, "batl": [[2, 2.58, 206.8]]}, {"timestamp": 1578738044959, "ltp": 2.48, "tv": 282.29, "trd": NaN, "batb": [[0, 2.48, 17.86]], "batl": NaN}, {"timestamp": 1578738046897, "ltp": 2.48, "tv": 282.29, "trd": NaN, "batb": [[1, 2.46, 7.35]], "batl": NaN}, {"timestamp": 1578738048990, "ltp": 2.48, "tv": 282.29, "trd": NaN, "batb": [[0, 2.48, 25.97]], "batl": NaN}, {"timestamp": 1578738051684, "ltp": 2.48, "tv": 282.29, "trd": NaN, "batb": [[1, 2.46, 10.17]], "batl": NaN}, {"timestamp": 1578738545709, "ltp": 2.48, "tv": 282.29, "trd": NaN, "batb": [[0, 2.48, 17.86]], "batl": NaN}, {"timestamp": 1578738549305, "ltp": 2.48, "tv": 282.29, "trd": NaN, "batb": [[1, 2.46, 7.35]], "batl": NaN}, {"timestamp": 1578738569955, "ltp": 2.48, "tv": 282.29, "trd": NaN, "batb": [[0, 2.48, 25.99]], "batl": NaN}, {"timestamp": 1578738570668, "ltp": 2.48, "tv": 282.29, "trd": NaN, "batb": [[0, 2.48, 17.86]], "batl": NaN}, {"timestamp": 1578738571616, "ltp": 2.48, "tv": 282.29, "trd": NaN, "batb": [[0, 2.48, 25.99]], "batl": NaN}, {"timestamp": 1578738572843, "ltp": 2.48, "tv": 282.29, "trd": NaN, "batb": [[1, 2.46, 10.17]], "batl": NaN}, {"timestamp": 1578739150012, "ltp": 2.48, "tv": 297.77, "trd": [[2.48, 51.29]], "batb": [[0, 2.48, 18.26]], "batl": NaN}, {"timestamp": 1578739178222, "ltp": 2.48, "tv": 297.77, "trd": NaN, "batb": [[0, 2.48, 10.12]], "batl": NaN}, {"timestamp": 1578739179847, "ltp": 2.48, "tv": 297.77, "trd": NaN, "batb": [[1, 2.46, 7.35]], "batl": NaN}, {"timestamp": 1578739269939, "ltp": 2.48, "tv": 297.77, "trd": NaN, "batb": NaN, "batl": [[1, 2.56, 221.52], [2, 2.58, 7.05]]}, {"timestamp": 1578739348870, "ltp": 2.48, "tv": 319.25, "trd": [[2.48, 72.77]], "batb": [[0, 2.48, 7.55]], "batl": NaN}, {"timestamp": 1578739349587, "ltp": 2.48, "tv": 319.25, "trd": NaN, "batb": [[1, 2.46, 10.17]], "batl": NaN}, {"timestamp": 1578739350957, "ltp": 2.48, "tv": 319.25, "trd": NaN, "batb": [[0, 2.46, 10.17], [1, 2.44, 7.41], [2, 2.34, 149.22]], "batl": NaN}, {"timestamp": 1578739352242, "ltp": 2.48, "tv": 319.25, "trd": NaN, "batb": [[0, 2.46, 7.35]], "batl": NaN}, {"timestamp": 1578739353176, "ltp": 2.48, "tv": 319.25, "trd": NaN, "batb": [[2, 2.38, 29.86]], "batl": NaN}, {"timestamp": 1578739496293, "ltp": 2.48, "tv": 319.25, "trd": NaN, "batb": [[0, 2.46, 10.17]], "batl": NaN}, {"timestamp": 1578740117993, "ltp": 2.48, "tv": 319.25, "trd": NaN, "batb": NaN, "batl": [[1, 2.56, 21.6], [2, 2.58, 206.8]]}, {"timestamp": 1578740148998, "ltp": 2.48, "tv": 319.25, "trd": NaN, "batb": NaN, "batl": [[2, 2.58, 7.05]]}, {"timestamp": 1578740271826, "ltp": 2.48, "tv": 319.25, "trd": NaN, "batb": NaN, "batl": [[0, 2.56, 21.6], [1, 2.58, 7.05], [2, 2.64, 19.62]]}, {"timestamp": 1578740336991, "ltp": 2.46, "tv": 323.25, "trd": [[2.46, 14.01]], "batb": [[0, 2.46, 8.17]], "batl": NaN}, {"timestamp": 1578740337889, "ltp": 2.46, "tv": 323.25, "trd": NaN, "batb": NaN, "batl": [[1, 2.58, 206.8]]}, {"timestamp": 1578740338877, "ltp": 2.46, "tv": 323.25, "trd": NaN, "batb": [[0, 2.46, 2.83], [2, 2.42, 8.49]], "batl": NaN}, {"timestamp": 1578740340950, "ltp": 2.46, "tv": 323.25, "trd": NaN, "batb": [[0, 2.44, 7.41], [1, 2.42, 8.49], [2, 2.38, 29.86]], "batl": NaN}, {"timestamp": 1578740341621, "ltp": 2.46, "tv": 323.25, "trd": NaN, "batb": [[0, 2.42, 8.49], [1, 2.4, 8.55]], "batl": NaN}, {"timestamp": 1578740447852, "ltp": 2.46, "tv": 323.25, "trd": NaN, "batb": NaN, "batl": [[2, 2.6, 2]]}, {"timestamp": 1578740516709, "ltp": 2.46, "tv": 323.25, "trd": NaN, "batb": [[1, 2.4, 13.55], [2, 2.38, 31.86]], "batl": NaN}, {"timestamp": 1578740518512, "ltp": 2.46, "tv": 323.25, "trd": NaN, "batb": [[1, 2.4, 16.45]], "batl": NaN}, {"timestamp": 1578740544891, "ltp": 2.46, "tv": 323.25, "trd": NaN, "batb": NaN, "batl": [[0, 2.56, 221.52], [1, 2.58, 7.05]]}, {"timestamp": 1578740545952, "ltp": 2.46, "tv": 323.25, "trd": NaN, "batb": NaN, "batl": [[0, 2.54, 8.09], [1, 2.56, 221.52], [2, 2.58, 7.05]]}, {"timestamp": 1578741085964, "ltp": 2.46, "tv": 323.25, "trd": NaN, "batb": NaN, "batl": [[0, 2.52, 199.76], [1, 2.54, 8.09], [2, 2.56, 21.6]]}, {"timestamp": 1578741088053, "ltp": 2.46, "tv": 323.25, "trd": NaN, "batb": NaN, "batl": [[0, 2.52, 207.93]]}, {"timestamp": 1578741105936, "ltp": 2.46, "tv": 323.25, "trd": NaN, "batb": [[0, 2.4, 16.45], [1, 2.38, 40.52], [2, 2.3, 153.68]], "batl": [[0, 2.5, 8.24], [1, 2.52, 207.93], [2, 2.54, 8.09]]}, {"timestamp": 1578741138964, "ltp": 2.46, "tv": 323.25, "trd": NaN, "batb": [[1, 2.38, 10.66], [2, 2.34, 30.75]], "batl": NaN}, {"timestamp": 1578741140962, "ltp": 2.46, "tv": 323.25, "trd": NaN, "batb": [[0, 2.4, 13.55], [2, 2.36, 2.95]], "batl": NaN}, {"timestamp": 1578741419982, "ltp": 2.46, "tv": 323.25, "trd": NaN, "batb": NaN, "batl": [[0, 2.48, 199.99], [1, 2.5, 8.24], [2, 2.52, 8.17]]}, {"timestamp": 1578741421969, "ltp": 2.46, "tv": 323.25, "trd": NaN, "batb": [[0, 2.4, 5]], "batl": NaN}, {"timestamp": 1578741422877, "ltp": 2.46, "tv": 323.25, "trd": NaN, "batb": [[2, 2.36, 11.7]], "batl": [[0, 2.48, 208.31]]}, {"timestamp": 1578741471895, "ltp": 2.46, "tv": 323.25, "trd": NaN, "batb": [[0, 2.4, 13.61]], "batl": [[0, 2.46, 8.39], [1, 2.48, 208.31], [2, 2.5, 8.24]]}, {"timestamp": 1578741569052, "ltp": 2.46, "tv": 323.25, "trd": NaN, "batb": NaN, "batl": [[0, 2.48, 208.31], [1, 2.5, 8.24], [2, 2.52, 8.17]]}, {"timestamp": 1578741893012, "ltp": 2.46, "tv": 323.25, "trd": NaN, "batb": NaN, "batl": [[0, 2.46, 8.41], [1, 2.48, 208.31], [2, 2.5, 8.24]]}, {"timestamp": 1578741893807, "ltp": 2.46, "tv": 323.25, "trd": NaN, "batb": [[0, 2.4, 5]], "batl": NaN}, {"timestamp": 1578742211357, "ltp": 2.46, "tv": 323.25, "trd": NaN, "batb": [[0, 2.4, 13.65]], "batl": [[0, 2.48, 208.31], [1, 2.5, 8.24], [2, 2.52, 8.17]]}, {"timestamp": 1578742244324, "ltp": 2.4, "tv": 334.53, "trd": [[2.4, 14.58]], "batb": [[0, 2.4, 8.01]], "batl": NaN}, {"timestamp": 1578742245909, "ltp": 2.4, "tv": 334.53, "trd": NaN, "batb": NaN, "batl": [[0, 2.46, 8.44], [1, 2.48, 208.31], [2, 2.5, 8.24]]}, {"timestamp": 1578742261002, "ltp": 2.4, "tv": 334.53, "trd": NaN, "batb": NaN, "batl": [[0, 2.48, 208.31], [1, 2.5, 8.24], [2, 2.52, 8.17]]}, {"timestamp": 1578742287954, "ltp": 2.4, "tv": 342.54, "trd": [[2.4, 22.59]], "batb": [[0, 2.38, 10.66], [1, 2.36, 11.7], [2, 2.34, 32.75]], "batl": NaN}, {"timestamp": 1578742288775, "ltp": 2.4, "tv": 342.54, "trd": NaN, "batb": NaN, "batl": [[0, 2.46, 8.44], [1, 2.48, 208.31], [2, 2.5, 8.24]]}, {"timestamp": 1578742294962, "ltp": 2.4, "tv": 342.54, "trd": NaN, "batb": NaN, "batl": [[1, 2.48, 8.32], [2, 2.5, 207.99]]}, {"timestamp": 1578742295960, "ltp": 2.4, "tv": 342.54, "trd": NaN, "batb": NaN, "batl": [[2, 2.5, 8.24]]}, {"timestamp": 1578742297761, "ltp": 2.38, "tv": 365.32, "trd": [[2.38, 22.78]], "batb": [[0, 2.36, 11.7], [1, 2.34, 32.75], [2, 2.26, 158.48]], "batl": [[0, 2.46, 208.19]]}, {"timestamp": 1578742300926, "ltp": 2.38, "tv": 365.32, "trd": NaN, "batb": [[1, 2.34, 41.63]], "batl": [[0, 2.46, 210.19], [2, 2.5, 10.24]]}, {"timestamp": 1578742302039, "ltp": 2.38, "tv": 365.32, "trd": NaN, "batb": NaN, "batl": [[0, 2.44, 8.52], [1, 2.46, 210.19], [2, 2.48, 8.32]]}, {"timestamp": 1578742307056, "ltp": 2.38, "tv": 365.32, "trd": NaN, "batb": [[0, 2.36, 2.95]], "batl": NaN}, {"timestamp": 1578742307960, "ltp": 2.38, "tv": 365.32, "trd": NaN, "batb": [[2, 2.32, 8.96]], "batl": NaN}, {"timestamp": 1578742308542, "ltp": 2.38, "tv": 365.32, "trd": NaN, "batb": [[0, 2.36, 11.76]], "batl": NaN}, {"timestamp": 1578742309838, "ltp": 2.38, "tv": 365.32, "trd": NaN, "batb": [[0, 2.36, 8.81], [1, 2.34, 44.6]], "batl": NaN}, {"timestamp": 1578742314978, "ltp": 2.38, "tv": 365.32, "trd": NaN, "batb": [[1, 2.34, 13.85]], "batl": NaN}, {"timestamp": 1578742374931, "ltp": 2.38, "tv": 365.32, "trd": NaN, "batb": NaN, "batl": [[1, 2.46, 10.44]]}, {"timestamp": 1578742451014, "ltp": 2.38, "tv": 365.32, "trd": NaN, "batb": NaN, "batl": [[0, 2.46, 10.44], [1, 2.48, 8.32], [2, 2.5, 10.24]]}, {"timestamp": 1578742451602, "ltp": 2.38, "tv": 365.32, "trd": NaN, "batb": NaN, "batl": [[0, 2.44, 8.54], [1, 2.46, 10.44], [2, 2.48, 8.32]]}, {"timestamp": 1578742492997, "ltp": 2.38, "tv": 365.32, "trd": NaN, "batb": NaN, "batl": [[0, 2.46, 10.44], [1, 2.48, 8.32], [2, 2.5, 10.24]]}, {"timestamp": 1578742507027, "ltp": 2.38, "tv": 365.32, "trd": NaN, "batb": [[2, 2.32, 10.96]], "batl": NaN}, {"timestamp": 1578742652938, "ltp": 2.38, "tv": 365.32, "trd": NaN, "batb": NaN, "batl": [[0, 2.46, 210.19]]}, {"timestamp": 1578742655003, "ltp": 2.38, "tv": 365.32, "trd": NaN, "batb": NaN, "batl": [[0, 2.44, 8.55], [1, 2.46, 210.19], [2, 2.48, 8.32]]}, {"timestamp": 1578742792841, "ltp": 2.38, "tv": 365.32, "trd": NaN, "batb": NaN, "batl": [[0, 2.46, 210.19], [1, 2.48, 8.32], [2, 2.5, 10.24]]}, {"timestamp": 1578742821361, "ltp": 2.38, "tv": 365.32, "trd": NaN, "batb": NaN, "batl": [[0, 2.44, 8.55], [1, 2.46, 210.19], [2, 2.48, 8.32]]}, {"timestamp": 1578742995854, "ltp": 2.44, "tv": 371.6, "trd": [[2.44, 23.5]], "batb": NaN, "batl": [[0, 2.44, 5.41]]}, {"timestamp": 1578742997769, "ltp": 2.44, "tv": 371.6, "trd": NaN, "batb": NaN, "batl": [[0, 2.46, 210.19], [1, 2.48, 8.32], [2, 2.5, 10.24]]}, {"timestamp": 1578742998265, "ltp": 2.44, "tv": 371.6, "trd": NaN, "batb": NaN, "batl": [[0, 2.44, 8.56], [1, 2.46, 210.19], [2, 2.48, 8.32]]}, {"timestamp": 1578743099764, "ltp": 2.44, "tv": 371.6, "trd": NaN, "batb": NaN, "batl": [[0, 2.46, 210.19], [1, 2.48, 8.32], [2, 2.5, 10.24]]}, {"timestamp": 1578743517193, "ltp": 2.44, "tv": 371.6, "trd": NaN, "batb": NaN, "batl": [[0, 2.44, 8.59], [1, 2.46, 210.19], [2, 2.48, 8.32]]}, {"timestamp": 1578743630917, "ltp": 2.44, "tv": 371.6, "trd": NaN, "batb": NaN, "batl": [[1, 2.46, 10.44]]}, {"timestamp": 1578743646031, "ltp": 2.44, "tv": 371.6, "trd": NaN, "batb": NaN, "batl": [[2, 2.48, 208.31]]}, {"timestamp": 1578743884015, "ltp": 2.44, "tv": 371.6, "trd": NaN, "batb": NaN, "batl": [[2, 2.48, 8.32]]}, {"timestamp": 1578743995473, "ltp": 2.44, "tv": 371.6, "trd": NaN, "batb": [[1, 2.34, 15.43]], "batl": NaN}, {"timestamp": 1578744183992, "ltp": 2.44, "tv": 371.6, "trd": NaN, "batb": NaN, "batl": [[0, 2.46, 10.44], [1, 2.48, 8.32], [2, 2.5, 209.99]]}, {"timestamp": 1578744184196, "ltp": 2.44, "tv": 371.6, "trd": NaN, "batb": NaN, "batl": [[0, 2.44, 8.61], [1, 2.46, 10.44], [2, 2.48, 8.32]]}, {"timestamp": 1578744316027, "ltp": 2.44, "tv": 371.6, "trd": NaN, "batb": NaN, "batl": [[2, 2.48, 208.31]]}, {"timestamp": 1578744529903, "ltp": 2.44, "tv": 371.6, "trd": NaN, "batb": NaN, "batl": [[0, 2.46, 10.44], [1, 2.48, 208.31], [2, 2.5, 10.24]]}, {"timestamp": 1578744780598, "ltp": 2.36, "tv": 386.91, "trd": [[2.36, 15.31]], "batb": [[0, 2.36, 1.16]], "batl": NaN}, {"timestamp": 1578744782698, "ltp": 2.36, "tv": 386.91, "trd": NaN, "batb": [[0, 2.34, 15.43], [1, 2.32, 10.96], [2, 2.3, 24.38]], "batl": NaN}, {"timestamp": 1578744846892, "ltp": 2.36, "tv": 386.91, "trd": NaN, "batb": NaN, "batl": [[1, 2.48, 8.32], [2, 2.5, 209.99]]}, {"timestamp": 1578744875030, "ltp": 2.36, "tv": 386.91, "trd": NaN, "batb": [[2, 2.3, 23.91]], "batl": NaN}, {"timestamp": 1578745169758, "ltp": 2.46, "tv": 386.93, "trd": [[2.46, 14.03]], "batb": NaN, "batl": [[0, 2.46, 10.44]]}, {"timestamp": 1578746452022, "ltp": 2.4, "tv": 442.47, "trd": [[2.4, 78.13]], "batb": NaN, "batl": NaN}, {"timestamp": 1578746517027, "ltp": 2.4, "tv": 442.47, "trd": NaN, "batb": NaN, "batl": [[2, 2.5, 10.24]]}, {"timestamp": 1578746547041, "ltp": 2.4, "tv": 442.47, "trd": NaN, "batb": NaN, "batl": [[1, 2.48, 208.31]]}, {"timestamp": 1578748077007, "ltp": 2.4, "tv": 442.47, "trd": NaN, "batb": [[2, 2.3, 177.59]], "batl": [[1, 2.48, 8.32]]}, {"timestamp": 1578748320949, "ltp": 2.4, "tv": 442.47, "trd": NaN, "batb": [[2, 2.3, 153.68]], "batl": NaN}, {"timestamp": 1578748349434, "ltp": 2.4, "tv": 442.47, "trd": NaN, "batb": NaN, "batl": [[2, 2.5, 8.24]]}, {"timestamp": 1578748464771, "ltp": 2.4, "tv": 442.47, "trd": NaN, "batb": [[0, 2.36, 43.41], [1, 2.34, 15.43], [2, 2.32, 10.96]], "batl": NaN}, {"timestamp": 1578748923021, "ltp": 2.4, "tv": 442.47, "trd": NaN, "batb": NaN, "batl": [[1, 2.48, 208.31]]}, {"timestamp": 1578749404874, "ltp": 2.4, "tv": 442.47, "trd": NaN, "batb": NaN, "batl": [[1, 2.48, 8.32]]}, {"timestamp": 1578749439949, "ltp": 2.4, "tv": 442.47, "trd": NaN, "batb": NaN, "batl": [[1, 2.48, 208.31]]}, {"timestamp": 1578749455589, "ltp": 2.4, "tv": 442.47, "trd": NaN, "batb": [[0, 2.36, 52.59]], "batl": NaN}, {"timestamp": 1578749845964, "ltp": 2.4, "tv": 442.47, "trd": NaN, "batb": NaN, "batl": [[1, 2.48, 8.32]]}, {"timestamp": 1578749925833, "ltp": 2.4, "tv": 442.47, "trd": NaN, "batb": NaN, "batl": [[1, 2.48, 208.31]]}, {"timestamp": 1578750089054, "ltp": 2.36, "tv": 446.47, "trd": [[2.36, 19.31]], "batb": [[0, 2.36, 50.59]], "batl": NaN}, {"timestamp": 1578750134987, "ltp": 2.36, "tv": 497.07, "trd": [[2.36, 69.91]], "batb": [[0, 2.36, 25.29]], "batl": NaN}, {"timestamp": 1578750136914, "ltp": 2.36, "tv": 497.07, "trd": NaN, "batb": [[0, 2.36, 16.11]], "batl": NaN}, {"timestamp": 1578750145000, "ltp": 2.36, "tv": 513.18, "trd": [[2.36, 86.02]], "batb": [[0, 2.34, 15.43], [1, 2.32, 10.96], [2, 2.26, 158.48]], "batl": [[0, 2.36, 7.82], [1, 2.46, 10.44], [2, 2.48, 208.31]]}, {"timestamp": 1578750146048, "ltp": 2.36, "tv": 513.18, "trd": NaN, "batb": NaN, "batl": [[0, 2.46, 10.44], [1, 2.48, 208.31], [2, 2.5, 8.24]]}, {"timestamp": 1578751179892, "ltp": 2.4, "tv": 550.18, "trd": [[2.4, 115.13]], "batb": NaN, "batl": NaN}, {"timestamp": 1578751707307, "ltp": 2.4, "tv": 550.18, "trd": NaN, "batb": NaN, "batl": [[0, 2.38, 126.58], [1, 2.46, 10.44], [2, 2.48, 208.31]]}, {"timestamp": 1578751710002, "ltp": 2.4, "tv": 550.18, "trd": NaN, "batb": NaN, "batl": [[0, 2.38, 137.16], [1, 2.4, 10.5], [2, 2.46, 10.44]]}, {"timestamp": 1578751737051, "ltp": 2.4, "tv": 550.18, "trd": NaN, "batb": NaN, "batl": [[2, 2.46, 8.44]]}, {"timestamp": 1578751806139, "ltp": 2.4, "tv": 550.18, "trd": NaN, "batb": NaN, "batl": [[2, 2.46, 10.44]]}, {"timestamp": 1578751943830, "ltp": 2.4, "tv": 550.18, "trd": NaN, "batb": NaN, "batl": [[2, 2.46, 8.44]]}, {"timestamp": 1578752554436, "ltp": 2.4, "tv": 550.18, "trd": NaN, "batb": NaN, "batl": [[0, 2.38, 141.96]]}, {"timestamp": 1578753143788, "ltp": 2.34, "tv": 556.18, "trd": [[2.34, 6]], "batb": [[0, 2.34, 12.43]], "batl": NaN}, {"timestamp": 1578753364028, "ltp": 2.34, "tv": 556.18, "trd": NaN, "batb": [[2, 2.3, 153.68]], "batl": NaN}, {"timestamp": 1578753366445, "ltp": 2.34, "tv": 556.18, "trd": NaN, "batb": NaN, "batl": [[0, 2.38, 137.16]]}, {"timestamp": 1578753369837, "ltp": 2.34, "tv": 556.18, "trd": NaN, "batb": [[2, 2.26, 158.48]], "batl": NaN}, {"timestamp": 1578755149001, "ltp": 2.34, "tv": 556.18, "trd": NaN, "batb": [[2, 2.3, 153.68]], "batl": NaN}, {"timestamp": 1578755226915, "ltp": 2.34, "tv": 556.18, "trd": NaN, "batb": [[2, 2.26, 158.48]], "batl": NaN}, {"timestamp": 1578755764022, "ltp": 2.34, "tv": 556.18, "trd": NaN, "batb": [[2, 2.28, 156.16]], "batl": NaN}, {"timestamp": 1578755765026, "ltp": 2.34, "tv": 556.18, "trd": NaN, "batb": [[2, 2.1, 44]], "batl": NaN}, {"timestamp": 1578755839601, "ltp": 2.34, "tv": 556.18, "trd": NaN, "batb": [[2, 2.24, 161.27]], "batl": [[2, 2.46, 208.19]]}, {"timestamp": 1578755948374, "ltp": 2.34, "tv": 567.4, "trd": [[2.34, 17.21]], "batb": [[0, 2.34, 6.82]], "batl": NaN}, {"timestamp": 1578755959878, "ltp": 2.34, "tv": 567.4, "trd": NaN, "batb": [[2, 2.28, 156.16]], "batl": [[2, 2.46, 8.44]]}, {"timestamp": 1578756334612, "ltp": 2.34, "tv": 567.4, "trd": NaN, "batb": NaN, "batl": [[0, 2.36, 4.9], [1, 2.38, 137.16], [2, 2.4, 10.5]]}, {"timestamp": 1578756393930, "ltp": 2.34, "tv": 567.4, "trd": NaN, "batb": NaN, "batl": [[0, 2.36, 76.57]]}, {"timestamp": 1578756776922, "ltp": 2.34, "tv": 577.4, "trd": [[2.34, 27.22]], "batb": [[0, 2.34, 1.82]], "batl": NaN}, {"timestamp": 1578756778039, "ltp": 2.34, "tv": 577.4, "trd": NaN, "batb": [[0, 2.34, 11.86]], "batl": NaN}, {"timestamp": 1578756780921, "ltp": 2.34, "tv": 577.4, "trd": NaN, "batb": [[0, 2.34, 11.62]], "batl": NaN}, {"timestamp": 1578757032744, "ltp": 2.36, "tv": 626.77, "trd": [[2.36, 135.38]], "batb": NaN, "batl": [[0, 2.36, 51.89]]}, {"timestamp": 1578757572891, "ltp": 2.36, "tv": 626.77, "trd": NaN, "batb": [[2, 2.3, 153.68]], "batl": NaN}, {"timestamp": 1578758066859, "ltp": 2.36, "tv": 626.77, "trd": NaN, "batb": [[2, 2.3, 303.25]], "batl": NaN}, {"timestamp": 1578758071981, "ltp": 2.36, "tv": 626.77, "trd": NaN, "batb": [[2, 2.3, 302.44]], "batl": NaN}, {"timestamp": 1578758629539, "ltp": 2.36, "tv": 626.77, "trd": NaN, "batb": [[2, 2.3, 383.03]], "batl": NaN}, {"timestamp": 1578758663934, "ltp": 2.36, "tv": 626.77, "trd": NaN, "batb": [[2, 2.3, 229.35]], "batl": NaN}, {"timestamp": 1578758858596, "ltp": 2.34, "tv": 816.24, "trd": [[2.34, 216.69]], "batb": [[0, 2.32, 88.54], [1, 2.3, 229.35], [2, 2.26, 158.48]], "batl": [[0, 2.34, 72.15], [1, 2.36, 51.89], [2, 2.38, 137.16]]}, {"timestamp": 1578758860052, "ltp": 2.34, "tv": 850.29, "trd": [[2.34, 250.74]], "batb": [[1, 2.3, 246.94]], "batl": [[0, 2.34, 55.13], [1, 2.36, 69.03]]}, {"timestamp": 1578758866882, "ltp": 2.32, "tv": 960.55, "trd": [[2.32, 110.26]], "batb": [[0, 2.32, 33.41]], "batl": [[0, 2.36, 69.03], [1, 2.38, 137.16], [2, 2.4, 10.5]]}, {"timestamp": 1578758867803, "ltp": 2.32, "tv": 960.55, "trd": NaN, "batb": [[0, 2.32, 50.59]], "batl": NaN}, {"timestamp": 1578758898006, "ltp": 2.36, "tv": 1271.34, "trd": [[2.36, 446.18]], "batb": NaN, "batl": [[0, 2.38, 137.16], [1, 2.4, 10.5], [2, 2.46, 8.44]]}, {"timestamp": 1578758899030, "ltp": 2.36, "tv": 1271.34, "trd": NaN, "batb": [[0, 2.34, 12.75], [1, 2.32, 50.59], [2, 2.3, 246.94]], "batl": NaN}, {"timestamp": 1578758925845, "ltp": 2.36, "tv": 1271.34, "trd": NaN, "batb": [[2, 2.3, 400.62]], "batl": NaN}, {"timestamp": 1578759082860, "ltp": 2.36, "tv": 1271.34, "trd": NaN, "batb": NaN, "batl": [[0, 2.36, 10.36], [1, 2.38, 137.16], [2, 2.4, 10.5]]}, {"timestamp": 1578759187610, "ltp": 2.36, "tv": 1271.34, "trd": NaN, "batb": [[0, 2.32, 50.59], [1, 2.3, 400.62], [2, 2.1, 44]], "batl": NaN}, {"timestamp": 1578759267384, "ltp": 2.36, "tv": 1271.34, "trd": NaN, "batb": [[2, 2.28, 2]], "batl": NaN}, {"timestamp": 1578759297998, "ltp": 2.36, "tv": 1271.34, "trd": NaN, "batb": NaN, "batl": [[0, 2.34, 15.31], [1, 2.36, 10.36], [2, 2.38, 137.16]]}, {"timestamp": 1578759673044, "ltp": 2.36, "tv": 1271.34, "trd": NaN, "batb": [[1, 2.3, 246.94], [2, 2.28, 158.16]], "batl": NaN}, {"timestamp": 1578759673935, "ltp": 2.36, "tv": 1271.34, "trd": NaN, "batb": [[2, 2.28, 2]], "batl": NaN}, {"timestamp": 1578759747982, "ltp": 2.36, "tv": 1271.34, "trd": NaN, "batb": [[1, 2.3, 400.62]], "batl": NaN}, {"timestamp": 1578759799958, "ltp": 2.34, "tv": 1272.11, "trd": [[2.34, 251.51]], "batb": NaN, "batl": [[0, 2.34, 14.54]]}, {"timestamp": 1578759818797, "ltp": 2.34, "tv": 1272.11, "trd": NaN, "batb": [[1, 2.3, 246.94]], "batl": NaN}, {"timestamp": 1578759827972, "ltp": 2.34, "tv": 1286.55, "trd": [[2.34, 265.95]], "batb": NaN, "batl": [[0, 2.34, 7.32], [2, 2.38, 141.6]]}, {"timestamp": 1578759828688, "ltp": 2.34, "tv": 1293.87, "trd": [[2.34, 273.27]], "batb": NaN, "batl": [[0, 2.34, 3.66]]}, {"timestamp": 1578759831802, "ltp": 2.34, "tv": 1301.19, "trd": [[2.34, 280.59]], "batb": [[0, 2.32, 50.93]], "batl": [[0, 2.36, 10.36], [1, 2.38, 141.6], [2, 2.4, 10.5]]}, {"timestamp": 1578759966855, "ltp": 2.34, "tv": 1301.19, "trd": NaN, "batb": [[2, 2.28, 158.16]], "batl": NaN}, {"timestamp": 1578760022967, "ltp": 2.34, "tv": 1301.19, "trd": NaN, "batb": [[1, 2.3, 400.62], [2, 2.28, 2]], "batl": NaN}, {"timestamp": 1578760049986, "ltp": 2.34, "tv": 1301.19, "trd": NaN, "batb": [[1, 2.3, 246.94]], "batl": NaN}, {"timestamp": 1578760054878, "ltp": 2.34, "tv": 1301.19, "trd": NaN, "batb": [[2, 2.28, 158.16]], "batl": NaN}, {"timestamp": 1578760069024, "ltp": 2.34, "tv": 1301.19, "trd": NaN, "batb": [[2, 2.28, 2]], "batl": NaN}, {"timestamp": 1578760511623, "ltp": 2.34, "tv": 1301.19, "trd": NaN, "batb": NaN, "batl": [[1, 2.38, 137.16], [2, 2.4, 15.3]]}, {"timestamp": 1578760810860, "ltp": 2.32, "tv": 1311.19, "trd": [[2.32, 119.58], [2.34, 281.27]], "batb": [[0, 2.32, 45.93]], "batl": NaN}, {"timestamp": 1578761043007, "ltp": 2.32, "tv": 1311.19, "trd": NaN, "batb": NaN, "batl": [[2, 2.4, 515.57]]}, {"timestamp": 1578761304036, "ltp": 2.32, "tv": 1311.19, "trd": NaN, "batb": [[0, 2.34, 13.82], [1, 2.32, 45.93], [2, 2.3, 246.94]], "batl": [[0, 2.38, 137.16], [1, 2.4, 515.57], [2, 2.42, 450.47]]}, {"timestamp": 1578761569013, "ltp": 2.32, "tv": 1311.19, "trd": NaN, "batb": NaN, "batl": [[1, 2.4, 15.3], [2, 2.44, 383.23]]}, {"timestamp": 1578761570015, "ltp": 2.32, "tv": 1311.19, "trd": NaN, "batb": [[0, 2.32, 45.93], [1, 2.3, 246.94], [2, 2.28, 708.35]], "batl": [[0, 2.36, 13.64], [1, 2.38, 137.16], [2, 2.4, 15.3]]}, {"timestamp": 1578761571008, "ltp": 2.32, "tv": 1311.19, "trd": NaN, "batb": [[0, 2.34, 19.71], [1, 2.32, 45.93], [2, 2.3, 246.94]], "batl": NaN}, {"timestamp": 1578761608638, "ltp": 2.32, "tv": 1311.19, "trd": NaN, "batb": NaN, "batl": [[1, 2.38, 536.49], [2, 2.4, 466.52]]}, {"timestamp": 1578761609934, "ltp": 2.32, "tv": 1311.19, "trd": NaN, "batb": [[0, 2.32, 45.93], [1, 2.3, 246.94], [2, 2.28, 2]], "batl": NaN}, {"timestamp": 1578761648974, "ltp": 2.32, "tv": 1311.19, "trd": NaN, "batb": [[0, 2.34, 9.36], [1, 2.32, 45.93], [2, 2.3, 246.94]], "batl": NaN}, {"timestamp": 1578761804046, "ltp": 2.32, "tv": 1311.19, "trd": NaN, "batb": NaN, "batl": [[1, 2.38, 137.16], [2, 2.4, 15.3]]}, {"timestamp": 1578761865046, "ltp": 2.32, "tv": 1311.19, "trd": NaN, "batb": NaN, "batl": [[1, 2.38, 549], [2, 2.4, 437.21]]}, {"timestamp": 1578761921681, "ltp": 2.32, "tv": 1311.19, "trd": NaN, "batb": NaN, "batl": [[1, 2.38, 137.16], [2, 2.4, 15.3]]}, {"timestamp": 1578761923047, "ltp": 2.32, "tv": 1311.19, "trd": NaN, "batb": [[0, 2.34, 19.3]], "batl": [[0, 2.36, 26.61]]}, {"timestamp": 1578761924988, "ltp": 2.32, "tv": 1311.19, "trd": NaN, "batb": [[0, 2.34, 30.19]], "batl": [[0, 2.36, 12.97]]}, {"timestamp": 1578761925732, "ltp": 2.32, "tv": 1311.19, "trd": NaN, "batb": NaN, "batl": [[0, 2.36, 23.77]]}, {"timestamp": 1578762059025, "ltp": 2.32, "tv": 1311.19, "trd": NaN, "batb": [[2, 2.3, 400.62]], "batl": NaN}, {"timestamp": 1578762071025, "ltp": 2.32, "tv": 1311.19, "trd": NaN, "batb": NaN, "batl": [[0, 2.36, 351.47]]}, {"timestamp": 1578762071958, "ltp": 2.32, "tv": 1311.19, "trd": NaN, "batb": NaN, "batl": [[0, 2.36, 23.77]]}, {"timestamp": 1578762073041, "ltp": 2.32, "tv": 1311.19, "trd": NaN, "batb": [[0, 2.34, 20.27]], "batl": NaN}, {"timestamp": 1578762074955, "ltp": 2.32, "tv": 1311.19, "trd": NaN, "batb": [[0, 2.34, 30.2]], "batl": NaN}, {"timestamp": 1578762079953, "ltp": 2.32, "tv": 1311.19, "trd": NaN, "batb": NaN, "batl": [[1, 2.38, 536.44], [2, 2.4, 403.79]]}, {"timestamp": 1578762080943, "ltp": 2.32, "tv": 1311.19, "trd": NaN, "batb": [[0, 2.34, 19.3]], "batl": NaN}, {"timestamp": 1578762082953, "ltp": 2.32, "tv": 1311.19, "trd": NaN, "batb": [[0, 2.34, 53.13]], "batl": NaN}, {"timestamp": 1578762092767, "ltp": 2.34, "tv": 1417.46, "trd": [[2.34, 387.53]], "batb": [[0, 2.32, 45.93], [1, 2.3, 400.62], [2, 2.28, 2]], "batl": [[0, 2.34, 73.44], [1, 2.36, 23.77], [2, 2.38, 409.87]]}, {"timestamp": 1578762094242, "ltp": 2.34, "tv": 1417.46, "trd": NaN, "batb": NaN, "batl": [[1, 2.36, 37.95]]}, {"timestamp": 1578762117984, "ltp": 2.34, "tv": 1417.46, "trd": NaN, "batb": [[1, 2.3, 246.94]], "batl": NaN}, {"timestamp": 1578762120994, "ltp": 2.34, "tv": 1417.46, "trd": NaN, "batb": NaN, "batl": [[2, 2.38, 10.59]]}, {"timestamp": 1578762157971, "ltp": 2.32, "tv": 1536.83, "trd": [[2.32, 238.95]], "batb": [[0, 2.3, 246.94], [1, 2.28, 2], [2, 2.26, 679.62]], "batl": [[0, 2.36, 37.95], [1, 2.38, 10.59], [2, 2.4, 15.3]]}, {"timestamp": 1578762158772, "ltp": 2.32, "tv": 1536.83, "trd": NaN, "batb": [[0, 2.32, 97.36], [1, 2.3, 246.94], [2, 2.28, 2]], "batl": [[0, 2.36, 61.71]]}, {"timestamp": 1578762360867, "ltp": 2.32, "tv": 1536.83, "trd": NaN, "batb": NaN, "batl": [[0, 2.36, 37.95]]}, {"timestamp": 1578762361882, "ltp": 2.32, "tv": 1536.83, "trd": NaN, "batb": [[0, 2.34, 11.07], [1, 2.32, 97.36], [2, 2.3, 246.94]], "batl": [[0, 2.36, 27.15]]}, {"timestamp": 1578762364569, "ltp": 2.32, "tv": 1536.83, "trd": NaN, "batb": NaN, "batl": [[0, 2.36, 14.17]]}, {"timestamp": 1578762365911, "ltp": 2.32, "tv": 1536.83, "trd": NaN, "batb": NaN, "batl": [[0, 2.36, 25.15]]}, {"timestamp": 1578762366550, "ltp": 2.32, "tv": 1536.83, "trd": NaN, "batb": NaN, "batl": [[0, 2.36, 14.17]]}, {"timestamp": 1578762477742, "ltp": 2.36, "tv": 1540.83, "trd": [[2.36, 450.18]], "batb": NaN, "batl": [[0, 2.36, 12.17]]}, {"timestamp": 1578762550971, "ltp": 2.36, "tv": 1540.83, "trd": NaN, "batb": NaN, "batl": [[0, 2.36, 263.86]]}, {"timestamp": 1578762607485, "ltp": 2.36, "tv": 1546.06, "trd": [[2.36, 455.41]], "batb": NaN, "batl": [[0, 2.36, 261.25]]}, {"timestamp": 1578762735010, "ltp": 2.36, "tv": 1546.06, "trd": NaN, "batb": NaN, "batl": [[0, 2.36, 9.56]]}, {"timestamp": 1578762738952, "ltp": 2.36, "tv": 1546.06, "trd": NaN, "batb": NaN, "batl": [[0, 2.36, 219.38]]}, {"timestamp": 1578762890012, "ltp": 2.36, "tv": 1546.06, "trd": NaN, "batb": [[2, 2.3, 776.76]], "batl": NaN}, {"timestamp": 1578762918757, "ltp": 2.36, "tv": 1546.06, "trd": NaN, "batb": [[2, 2.3, 246.94]], "batl": NaN}, {"timestamp": 1578762968024, "ltp": 2.36, "tv": 1546.06, "trd": NaN, "batb": NaN, "batl": [[0, 2.36, 9.56]]}, {"timestamp": 1578763055842, "ltp": 2.36, "tv": 1546.06, "trd": NaN, "batb": [[2, 2.3, 754.33]], "batl": NaN}, {"timestamp": 1578763057011, "ltp": 2.36, "tv": 1546.06, "trd": NaN, "batb": [[0, 2.34, 87.99]], "batl": [[2, 2.4, 15.46]]}, {"timestamp": 1578763061918, "ltp": 2.36, "tv": 1546.06, "trd": NaN, "batb": [[1, 2.32, 248.75]], "batl": NaN}, {"timestamp": 1578763092055, "ltp": 2.36, "tv": 1546.06, "trd": NaN, "batb": [[1, 2.32, 97.36]], "batl": NaN}, {"timestamp": 1578763388475, "ltp": 2.36, "tv": 1558.54, "trd": [[2.36, 467.89]], "batb": NaN, "batl": [[0, 2.36, 3.32]]}, {"timestamp": 1578763389977, "ltp": 2.36, "tv": 1558.54, "trd": NaN, "batb": NaN, "batl": [[0, 2.38, 10.59], [1, 2.4, 15.46], [2, 2.46, 374.08]]}, {"timestamp": 1578763504002, "ltp": 2.36, "tv": 1558.54, "trd": NaN, "batb": [[2, 2.3, 246.94]], "batl": [[2, 2.42, 423.8]]}, {"timestamp": 1578763504978, "ltp": 2.36, "tv": 1558.54, "trd": NaN, "batb": [[0, 2.34, 11.07]], "batl": NaN}, {"timestamp": 1578763541015, "ltp": 2.36, "tv": 1558.54, "trd": NaN, "batb": [[2, 2.3, 749.12]], "batl": [[2, 2.46, 368.41]]}, {"timestamp": 1578763542033, "ltp": 2.36, "tv": 1558.54, "trd": NaN, "batb": [[0, 2.34, 87.99]], "batl": NaN}, {"timestamp": 1578763884028, "ltp": 2.36, "tv": 1558.54, "trd": NaN, "batb": [[2, 2.3, 902.8]], "batl": NaN}, {"timestamp": 1578763894021, "ltp": 2.36, "tv": 1558.54, "trd": NaN, "batb": [[2, 2.3, 749.12]], "batl": NaN}, {"timestamp": 1578763932971, "ltp": 2.36, "tv": 1558.54, "trd": NaN, "batb": NaN, "batl": [[0, 2.38, 573.59]]}, {"timestamp": 1578763933880, "ltp": 2.36, "tv": 1558.54, "trd": NaN, "batb": [[0, 2.36, 11.63], [1, 2.34, 87.99], [2, 2.32, 97.36]], "batl": NaN}, {"timestamp": 1578763991274, "ltp": 2.36, "tv": 1558.54, "trd": NaN, "batb": [[1, 2.34, 111.62]], "batl": NaN}, {"timestamp": 1578764147911, "ltp": 2.38, "tv": 2132.12, "trd": [[2.38, 596.37]], "batb": NaN, "batl": [[0, 2.4, 15.46], [1, 2.46, 368.41], [2, 2.48, 639.71]]}, {"timestamp": 1578764148978, "ltp": 2.38, "tv": 2132.12, "trd": NaN, "batb": [[0, 2.36, 46.14]], "batl": [[1, 2.42, 33.66], [2, 2.46, 368.41]]}, {"timestamp": 1578764149990, "ltp": 2.38, "tv": 2210.7, "trd": [[2.38, 674.95]], "batb": [[0, 2.36, 23.37]], "batl": [[0, 2.38, 230.06], [1, 2.4, 15.46], [2, 2.42, 33.66]]}, {"timestamp": 1578764150893, "ltp": 2.38, "tv": 2302.72, "trd": [[2.38, 766.97]], "batb": NaN, "batl": [[0, 2.38, 138.04]]}, {"timestamp": 1578764152002, "ltp": 2.38, "tv": 2357.93, "trd": [[2.38, 822.18]], "batb": NaN, "batl": [[0, 2.38, 245.43]]}, {"timestamp": 1578764154019, "ltp": 2.38, "tv": 2603.36, "trd": [[2.38, 1067.61]], "batb": NaN, "batl": [[0, 2.4, 15.46], [1, 2.42, 33.66], [2, 2.46, 368.41]]}, {"timestamp": 1578764154929, "ltp": 2.38, "tv": 2603.36, "trd": NaN, "batb": NaN, "batl": [[0, 2.38, 341.22], [1, 2.4, 15.46], [2, 2.42, 33.66]]}, {"timestamp": 1578764156010, "ltp": 2.38, "tv": 2936.36, "trd": [[2.38, 1400.61]], "batb": [[0, 2.36, 42.79]], "batl": [[0, 2.4, 15.46], [1, 2.42, 33.66], [2, 2.46, 368.41]]}, {"timestamp": 1578764157006, "ltp": 2.38, "tv": 3248.52, "trd": [[2.38, 1712.77]], "batb": NaN, "batl": NaN}, {"timestamp": 1578764158040, "ltp": 2.38, "tv": 3270.64, "trd": [[2.38, 1734.89]], "batb": [[0, 2.36, 23.37]], "batl": [[0, 2.38, 302.77], [1, 2.4, 15.46], [2, 2.42, 33.66]]}, {"timestamp": 1578764159006, "ltp": 2.38, "tv": 3561.51, "trd": [[2.38, 2025.76]], "batb": NaN, "batl": [[0, 2.4, 15.46], [1, 2.42, 33.66], [2, 2.46, 368.41]]}, {"timestamp": 1578764159904, "ltp": 2.38, "tv": 3743.69, "trd": [[2.38, 2207.94]], "batb": NaN, "batl": [[0, 2.38, 116.58], [1, 2.4, 15.46], [2, 2.42, 33.66]]}, {"timestamp": 1578764160955, "ltp": 2.38, "tv": 3743.69, "trd": NaN, "batb": NaN, "batl": [[0, 2.38, 297.57]]}, {"timestamp": 1578764172955, "ltp": 2.38, "tv": 3743.69, "trd": NaN, "batb": [[1, 2.34, 87.99]], "batl": NaN}, {"timestamp": 1578764184865, "ltp": 2.38, "tv": 3743.69, "trd": NaN, "batb": NaN, "batl": [[0, 2.38, 285.61]]}, {"timestamp": 1578764185878, "ltp": 2.38, "tv": 3743.69, "trd": NaN, "batb": NaN, "batl": [[0, 2.38, 297.63]]}, {"timestamp": 1578764253980, "ltp": 2.38, "tv": 3743.69, "trd": NaN, "batb": NaN, "batl": [[0, 2.38, 382.75]]}, {"timestamp": 1578764383045, "ltp": 2.38, "tv": 3743.69, "trd": NaN, "batb": NaN, "batl": [[2, 2.42, 477.38]]}, {"timestamp": 1578764401031, "ltp": 2.38, "tv": 3743.69, "trd": NaN, "batb": [[0, 2.36, 11.63]], "batl": NaN}, {"timestamp": 1578764401977, "ltp": 2.38, "tv": 3743.69, "trd": NaN, "batb": [[0, 2.36, 47]], "batl": NaN}, {"timestamp": 1578764409967, "ltp": 2.38, "tv": 3779.69, "trd": [[2.38, 2243.94]], "batb": NaN, "batl": [[0, 2.38, 364.75]]}, {"timestamp": 1578764446795, "ltp": 2.38, "tv": 3779.69, "trd": NaN, "batb": [[2, 2.32, 99.5]], "batl": [[2, 2.42, 479.44]]}, {"timestamp": 1578764474840, "ltp": 2.38, "tv": 3779.69, "trd": NaN, "batb": [[0, 2.36, 11.63]], "batl": NaN}, {"timestamp": 1578764639968, "ltp": 2.36, "tv": 3802.95, "trd": [[2.36, 491.14]], "batb": [[0, 2.34, 87.99], [1, 2.32, 99.5], [2, 2.3, 249.02]], "batl": [[0, 2.36, 2.37], [1, 2.38, 364.75], [2, 2.4, 15.46]]}, {"timestamp": 1578764640984, "ltp": 2.36, "tv": 3802.95, "trd": NaN, "batb": [[0, 2.34, 11.07], [1, 2.32, 97.36]], "batl": [[2, 2.4, 17.5]]}, {"timestamp": 1578764641965, "ltp": 2.36, "tv": 3802.95, "trd": NaN, "batb": NaN, "batl": [[0, 2.36, 12.76]]}, {"timestamp": 1578764646915, "ltp": 2.34, "tv": 3807.69, "trd": [[2.34, 392.27]], "batb": [[0, 2.34, 8.71]], "batl": [[0, 2.36, 10.39]]}, {"timestamp": 1578764860036, "ltp": 2.34, "tv": 3807.69, "trd": NaN, "batb": [[2, 2.3, 658.46]], "batl": NaN}, {"timestamp": 1578764861030, "ltp": 2.34, "tv": 3807.69, "trd": NaN, "batb": [[0, 2.34, 85.63]], "batl": NaN}, {"timestamp": 1578764945966, "ltp": 2.36, "tv": 3828.47, "trd": [[2.36, 511.93]], "batb": [[0, 2.36, 136.67], [1, 2.34, 85.63], [2, 2.32, 99.5]], "batl": [[0, 2.38, 352.73], [1, 2.4, 15.46], [2, 2.42, 55.34]]}, {"timestamp": 1578764946875, "ltp": 2.36, "tv": 3828.47, "trd": NaN, "batb": [[0, 2.36, 148.98]], "batl": NaN}, {"timestamp": 1578765092040, "ltp": 2.36, "tv": 3839.11, "trd": [[2.36, 522.57]], "batb": [[0, 2.36, 143.66]], "batl": NaN}, {"timestamp": 1578765136940, "ltp": 2.36, "tv": 3839.11, "trd": NaN, "batb": NaN, "batl": [[2, 2.42, 713.91]]}, {"timestamp": 1578765147740, "ltp": 2.36, "tv": 3839.11, "trd": NaN, "batb": NaN, "batl": [[0, 2.38, 386.47]]}, {"timestamp": 1578765159976, "ltp": 2.36, "tv": 3846.77, "trd": [[2.36, 530.23]], "batb": [[0, 2.36, 139.83]], "batl": NaN}, {"timestamp": 1578765223044, "ltp": 2.36, "tv": 3846.77, "trd": NaN, "batb": NaN, "batl": [[0, 2.38, 118.86]]}, {"timestamp": 1578765223947, "ltp": 2.36, "tv": 3846.77, "trd": NaN, "batb": NaN, "batl": [[0, 2.38, 85.12]]}, {"timestamp": 1578765313976, "ltp": 2.36, "tv": 3846.77, "trd": NaN, "batb": NaN, "batl": [[1, 2.4, 72.43]]}, {"timestamp": 1578765346981, "ltp": 2.36, "tv": 3846.77, "trd": NaN, "batb": [[0, 2.36, 127.52]], "batl": [[0, 2.38, 98.84]]}, {"timestamp": 1578765379056, "ltp": 2.36, "tv": 3846.77, "trd": NaN, "batb": NaN, "batl": [[2, 2.42, 55.34]]}, {"timestamp": 1578765395987, "ltp": 2.36, "tv": 3846.77, "trd": NaN, "batb": NaN, "batl": [[2, 2.42, 795.77]]}, {"timestamp": 1578765409937, "ltp": 2.36, "tv": 3846.77, "trd": NaN, "batb": [[0, 2.36, 142.44]], "batl": NaN}, {"timestamp": 1578765410837, "ltp": 2.36, "tv": 3846.77, "trd": NaN, "batb": NaN, "batl": [[2, 2.42, 852.74]]}, {"timestamp": 1578765433478, "ltp": 2.36, "tv": 3846.77, "trd": NaN, "batb": NaN, "batl": [[0, 2.38, 85.12]]}, {"timestamp": 1578765455704, "ltp": 2.36, "tv": 3846.77, "trd": NaN, "batb": NaN, "batl": [[1, 2.4, 15.46]]}, {"timestamp": 1578765461007, "ltp": 2.36, "tv": 3856.41, "trd": [[2.36, 539.87]], "batb": [[0, 2.36, 137.62]], "batl": NaN}, {"timestamp": 1578765539048, "ltp": 2.38, "tv": 3941.53, "trd": [[2.38, 2329.06]], "batb": [[0, 2.36, 213.89], [1, 2.34, 87.64]], "batl": [[0, 2.4, 4.96], [1, 2.42, 850.68], [2, 2.44, 773.15]]}, {"timestamp": 1578765542798, "ltp": 2.38, "tv": 3945.53, "trd": [[2.38, 2333.06]], "batb": [[0, 2.38, 63.82], [1, 2.36, 213.89], [2, 2.34, 87.64]], "batl": NaN}, {"timestamp": 1578765546972, "ltp": 2.38, "tv": 3945.53, "trd": NaN, "batb": [[1, 2.36, 237.17]], "batl": NaN}, {"timestamp": 1578765548960, "ltp": 2.38, "tv": 3945.53, "trd": NaN, "batb": [[0, 2.38, 139.45]], "batl": NaN}, {"timestamp": 1578765564785, "ltp": 2.38, "tv": 3945.53, "trd": NaN, "batb": [[1, 2.36, 213.89]], "batl": NaN}, {"timestamp": 1578765606013, "ltp": 2.38, "tv": 4012.03, "trd": [[2.38, 2399.56]], "batb": [[0, 2.38, 30.58]], "batl": [[0, 2.4, 16.1]]}, {"timestamp": 1578765606704, "ltp": 2.38, "tv": 4012.03, "trd": NaN, "batb": [[0, 2.36, 213.89], [1, 2.34, 85.63], [2, 2.32, 21.92]], "batl": [[0, 2.4, 80.14]]}, {"timestamp": 1578765607806, "ltp": 2.38, "tv": 4012.03, "trd": NaN, "batb": [[0, 2.36, 137.62]], "batl": NaN}, {"timestamp": 1578765782808, "ltp": 2.38, "tv": 4012.03, "trd": NaN, "batb": NaN, "batl": [[0, 2.38, 9.11], [1, 2.4, 80.14], [2, 2.42, 850.68]]}, {"timestamp": 1578765783921, "ltp": 2.38, "tv": 4012.03, "trd": NaN, "batb": [[0, 2.36, 122.7]], "batl": [[0, 2.38, 73.09], [2, 2.42, 852.74]]}, {"timestamp": 1578765787142, "ltp": 2.38, "tv": 4012.03, "trd": NaN, "batb": NaN, "batl": [[1, 2.4, 102.75]]}, {"timestamp": 1578765806578, "ltp": 2.38, "tv": 4012.03, "trd": NaN, "batb": NaN, "batl": [[1, 2.4, 80.14]]}, {"timestamp": 1578765869981, "ltp": 2.38, "tv": 4012.03, "trd": NaN, "batb": NaN, "batl": [[0, 2.38, 158.21]]}, {"timestamp": 1578765949003, "ltp": 2.38, "tv": 4012.03, "trd": NaN, "batb": [[1, 2.34, 8.71]], "batl": NaN}, {"timestamp": 1578765970033, "ltp": 2.38, "tv": 4012.03, "trd": NaN, "batb": NaN, "batl": [[2, 2.42, 880.01]]}, {"timestamp": 1578765972005, "ltp": 2.38, "tv": 4012.03, "trd": NaN, "batb": [[2, 2.32, 50.95]], "batl": NaN}, {"timestamp": 1578765979053, "ltp": 2.38, "tv": 4012.03, "trd": NaN, "batb": NaN, "batl": [[2, 2.42, 139.58]]}, {"timestamp": 1578766040922, "ltp": 2.36, "tv": 4033.43, "trd": [[2.36, 561.27]], "batb": [[0, 2.36, 112]], "batl": NaN}, {"timestamp": 1578766158971, "ltp": 2.36, "tv": 4033.43, "trd": NaN, "batb": [[0, 2.36, 829.21], [1, 2.34, 673.62]], "batl": NaN}, {"timestamp": 1578766179901, "ltp": 2.36, "tv": 4033.43, "trd": NaN, "batb": [[0, 2.36, 112], [1, 2.34, 8.71]], "batl": NaN}, {"timestamp": 1578766180587, "ltp": 2.36, "tv": 4033.43, "trd": NaN, "batb": [[2, 2.32, 727.35]], "batl": NaN}, {"timestamp": 1578766259309, "ltp": 2.36, "tv": 4038.03, "trd": [[2.36, 565.87]], "batb": [[0, 2.36, 109.7]], "batl": NaN}, {"timestamp": 1578766538960, "ltp": 2.36, "tv": 4038.03, "trd": NaN, "batb": NaN, "batl": [[0, 2.38, 149.1], [1, 2.4, 69]]}, {"timestamp": 1578766673860, "ltp": 2.36, "tv": 4038.03, "trd": NaN, "batb": [[2, 2.32, 50.95]], "batl": NaN}, {"timestamp": 1578766831983, "ltp": 2.36, "tv": 4238.03, "trd": [[2.36, 765.87]], "batb": [[0, 2.36, 9.7]], "batl": NaN}, {"timestamp": 1578766883927, "ltp": 2.36, "tv": 4241.64, "trd": [[2.36, 769.47]], "batb": [[0, 2.36, 7.9]], "batl": NaN}, {"timestamp": 1578766939901, "ltp": 2.36, "tv": 4257.43, "trd": [[2.36, 785.27]], "batb": [[0, 2.34, 8.71], [1, 2.32, 48.81], [2, 2.3, 231.43]], "batl": [[0, 2.36, 29.63], [1, 2.38, 149.1], [2, 2.4, 71.04]]}, {"timestamp": 1578766940797, "ltp": 2.36, "tv": 4257.43, "trd": NaN, "batb": NaN, "batl": [[0, 2.36, 43.7]]}, {"timestamp": 1578766967791, "ltp": 2.36, "tv": 4257.43, "trd": NaN, "batb": NaN, "batl": [[2, 2.4, 128]]}, {"timestamp": 1578766974951, "ltp": 2.36, "tv": 4257.43, "trd": NaN, "batb": NaN, "batl": [[0, 2.36, 14.07]]}, {"timestamp": 1578766996000, "ltp": 2.34, "tv": 4295.77, "trd": [[2.34, 430.61]], "batb": [[0, 2.32, 126.39], [1, 2.3, 231.43], [2, 2.28, 860.99]], "batl": NaN}, {"timestamp": 1578766997004, "ltp": 2.34, "tv": 4295.77, "trd": NaN, "batb": [[0, 2.34, 27.06], [1, 2.32, 126.39], [2, 2.3, 231.43]], "batl": NaN}, {"timestamp": 1578767006887, "ltp": 2.34, "tv": 4295.77, "trd": NaN, "batb": [[0, 2.32, 126.39], [1, 2.3, 248.81], [2, 2.28, 860.99]], "batl": NaN}, {"timestamp": 1578767007104, "ltp": 2.34, "tv": 4295.77, "trd": NaN, "batb": [[1, 2.3, 250.89]], "batl": NaN}, {"timestamp": 1578767009010, "ltp": 2.34, "tv": 4295.77, "trd": NaN, "batb": [[0, 2.32, 97.36]], "batl": NaN}, {"timestamp": 1578767010996, "ltp": 2.34, "tv": 4295.77, "trd": NaN, "batb": [[0, 2.34, 65.08], [1, 2.32, 97.36], [2, 2.3, 250.89]], "batl": [[0, 2.36, 99.99]]}, {"timestamp": 1578767028017, "ltp": 2.34, "tv": 4295.77, "trd": NaN, "batb": NaN, "batl": [[0, 2.36, 14.07]]}, {"timestamp": 1578767294759, "ltp": 2.34, "tv": 4326.4, "trd": [[2.34, 461.23]], "batb": [[0, 2.34, 49.77]], "batl": NaN}, {"timestamp": 1578767317958, "ltp": 2.34, "tv": 4326.4, "trd": NaN, "batb": [[0, 2.32, 97.36], [1, 2.3, 250.89], [2, 2.28, 861.1]], "batl": NaN}, {"timestamp": 1578767318959, "ltp": 2.34, "tv": 4326.4, "trd": NaN, "batb": [[1, 2.3, 248.81]], "batl": [[1, 2.38, 176.99]]}, {"timestamp": 1578767319961, "ltp": 2.34, "tv": 4341.71, "trd": [[2.34, 476.55]], "batb": NaN, "batl": NaN}, {"timestamp": 1578767329197, "ltp": 2.34, "tv": 4341.71, "trd": NaN, "batb": NaN, "batl": [[0, 2.34, 1.31], [1, 2.36, 14.07], [2, 2.38, 176.99]]}, {"timestamp": 1578767333904, "ltp": 2.34, "tv": 4388.48, "trd": [[2.34, 523.32]], "batb": [[0, 2.32, 19.78]], "batl": [[0, 2.34, 357.47], [2, 2.38, 179.03]]}, {"timestamp": 1578767334909, "ltp": 2.34, "tv": 4388.48, "trd": NaN, "batb": NaN, "batl": [[0, 2.34, 389.28]]}, {"timestamp": 1578767506870, "ltp": 2.34, "tv": 4463.5, "trd": [[2.34, 598.34]], "batb": NaN, "batl": [[0, 2.34, 351.77]]}, {"timestamp": 1578767520997, "ltp": 2.32, "tv": 4480.53, "trd": [[2.32, 255.98]], "batb": [[0, 2.32, 11.27]], "batl": NaN}, {"timestamp": 1578767548942, "ltp": 2.34, "tv": 4520.91, "trd": [[2.34, 638.72]], "batb": NaN, "batl": [[0, 2.34, 331.58]]}, {"timestamp": 1578767617890, "ltp": 2.34, "tv": 4520.91, "trd": NaN, "batb": NaN, "batl": [[0, 2.34, 299.77]]}, {"timestamp": 1578767619016, "ltp": 2.34, "tv": 4520.91, "trd": NaN, "batb": NaN, "batl": [[0, 2.34, 331.73]]}, {"timestamp": 1578767620020, "ltp": 2.34, "tv": 4520.91, "trd": NaN, "batb": NaN, "batl": [[0, 2.34, 299.77]]}, {"timestamp": 1578767621025, "ltp": 2.34, "tv": 4520.91, "trd": NaN, "batb": NaN, "batl": [[0, 2.34, 331.73]]}, {"timestamp": 1578767701597, "ltp": 2.34, "tv": 4520.91, "trd": NaN, "batb": NaN, "batl": [[0, 2.34, 416.85], [2, 2.38, 93.91]]}, {"timestamp": 1578767702725, "ltp": 2.34, "tv": 4520.91, "trd": NaN, "batb": NaN, "batl": [[0, 2.34, 384.89]]}, {"timestamp": 1578767838937, "ltp": 2.34, "tv": 4533.35, "trd": [[2.34, 651.16]], "batb": NaN, "batl": [[0, 2.34, 378.67]]}, {"timestamp": 1578767905045, "ltp": 2.32, "tv": 4552.04, "trd": [[2.32, 274.67]], "batb": [[0, 2.32, 1.92]], "batl": NaN}, {"timestamp": 1578767905911, "ltp": 2.32, "tv": 4552.04, "trd": NaN, "batb": [[2, 2.28, 860.95]], "batl": [[0, 2.34, 404.27]]}, {"timestamp": 1578767917933, "ltp": 2.34, "tv": 4558.48, "trd": [[2.34, 657.6]], "batb": NaN, "batl": [[0, 2.34, 401.05]]}, {"timestamp": 1578767985036, "ltp": 2.34, "tv": 4558.48, "trd": NaN, "batb": NaN, "batl": [[0, 2.34, 375.45]]}, {"timestamp": 1578768000888, "ltp": 2.34, "tv": 4562.48, "trd": [[2.34, 661.6]], "batb": NaN, "batl": [[0, 2.34, 373.45]]}, {"timestamp": 1578768014923, "ltp": 2.34, "tv": 4566.48, "trd": [[2.34, 665.6]], "batb": NaN, "batl": [[0, 2.34, 371.45]]}, {"timestamp": 1578768085703, "ltp": 2.32, "tv": 4621.99, "trd": [[2.32, 330.18]], "batb": [[0, 2.3, 248.81], [1, 2.28, 860.95], [2, 2.26, 1023.19]], "batl": NaN}, {"timestamp": 1578768086922, "ltp": 2.32, "tv": 4621.99, "trd": NaN, "batb": [[0, 2.32, 71.94], [1, 2.3, 327.07], [2, 2.28, 860.99]], "batl": [[0, 2.34, 442.78]]}, {"timestamp": 1578768288025, "ltp": 2.34, "tv": 4624.04, "trd": [[2.34, 667.65]], "batb": NaN, "batl": [[0, 2.34, 440.73]]}, {"timestamp": 1578768293975, "ltp": 2.34, "tv": 4624.04, "trd": NaN, "batb": [[0, 2.3, 327.07], [1, 2.28, 893.17], [2, 2.26, 1023.03]], "batl": NaN}, {"timestamp": 1578768294771, "ltp": 2.34, "tv": 4624.04, "trd": NaN, "batb": [[2, 2.26, 1022.98]], "batl": NaN}, {"timestamp": 1578768299798, "ltp": 2.34, "tv": 4624.04, "trd": NaN, "batb": NaN, "batl": [[2, 2.38, 98.45]]}, {"timestamp": 1578768300776, "ltp": 2.34, "tv": 4624.04, "trd": NaN, "batb": [[2, 2.26, 1023.11]], "batl": NaN}, {"timestamp": 1578768306970, "ltp": 2.34, "tv": 4624.04, "trd": NaN, "batb": [[2, 2.26, 1022.99]], "batl": NaN}, {"timestamp": 1578768311881, "ltp": 2.34, "tv": 4624.04, "trd": NaN, "batb": NaN, "batl": [[2, 2.38, 93.91]]}, {"timestamp": 1578768312996, "ltp": 2.34, "tv": 4624.04, "trd": NaN, "batb": [[2, 2.26, 1023.19]], "batl": NaN}, {"timestamp": 1578768323994, "ltp": 2.34, "tv": 4624.04, "trd": NaN, "batb": NaN, "batl": [[0, 2.34, 447.27]]}, {"timestamp": 1578768324591, "ltp": 2.34, "tv": 4624.04, "trd": NaN, "batb": [[2, 2.26, 1023.03]], "batl": NaN}, {"timestamp": 1578768328937, "ltp": 2.34, "tv": 4624.04, "trd": NaN, "batb": NaN, "batl": [[0, 2.34, 440.73]]}, {"timestamp": 1578768338028, "ltp": 2.32, "tv": 4626.85, "trd": [[2.32, 332.99]], "batb": [[2, 2.26, 1023.19]], "batl": NaN}, {"timestamp": 1578768346055, "ltp": 2.32, "tv": 4629.14, "trd": [[2.32, 335.28]], "batb": [[2, 2.26, 1022.99]], "batl": NaN}, {"timestamp": 1578768367548, "ltp": 2.32, "tv": 4629.14, "trd": NaN, "batb": [[2, 2.26, 1023.19]], "batl": NaN}, {"timestamp": 1578768378279, "ltp": 2.32, "tv": 4629.14, "trd": NaN, "batb": [[2, 2.26, 1023.11]], "batl": NaN}, {"timestamp": 1578768387970, "ltp": 2.32, "tv": 4629.14, "trd": NaN, "batb": [[0, 2.32, 20], [1, 2.3, 329.07], [2, 2.28, 895.17]], "batl": NaN}, {"timestamp": 1578768411025, "ltp": 2.32, "tv": 5040.53, "trd": [[2.32, 746.67]], "batb": [[0, 2.3, 329.07], [1, 2.28, 893.12], [2, 2.26, 1023.19]], "batl": [[0, 2.32, 817.4], [1, 2.34, 440.73], [2, 2.36, 16.14]]}, {"timestamp": 1578768411811, "ltp": 2.32, "tv": 5181.55, "trd": [[2.32, 887.69]], "batb": NaN, "batl": [[0, 2.32, 741.53]]}, {"timestamp": 1578768471701, "ltp": 2.32, "tv": 5293.33, "trd": [[2.32, 999.47]], "batb": NaN, "batl": [[0, 2.32, 685.64]]}, {"timestamp": 1578768523972, "ltp": 2.3, "tv": 5393.33, "trd": [[2.3, 100]], "batb": [[0, 2.3, 279.07]], "batl": NaN}, {"timestamp": 1578768576033, "ltp": 2.3, "tv": 5393.65, "trd": [[2.3, 100.32]], "batb": [[0, 2.3, 278.91]], "batl": NaN}, {"timestamp": 1578768600038, "ltp": 2.32, "tv": 5677.93, "trd": [[2.32, 1283.75]], "batb": NaN, "batl": [[0, 2.32, 543.5]]}, {"timestamp": 1578768643000, "ltp": 2.32, "tv": 5840.17, "trd": [[2.32, 1445.99]], "batb": NaN, "batl": [[0, 2.32, 462.37]]}, {"timestamp": 1578768647010, "ltp": 2.32, "tv": 5856.45, "trd": [[2.32, 1462.27]], "batb": NaN, "batl": [[0, 2.32, 454.23]]}, {"timestamp": 1578768731980, "ltp": 2.32, "tv": 5879.73, "trd": [[2.32, 1485.55]], "batb": NaN, "batl": [[0, 2.32, 442.59]]}, {"timestamp": 1578768817881, "ltp": 2.32, "tv": 5891.51, "trd": [[2.32, 1497.33]], "batb": NaN, "batl": [[0, 2.32, 436.7]]}, {"timestamp": 1578768828984, "ltp": 2.32, "tv": 5919.29, "trd": [[2.32, 1525.11]], "batb": NaN, "batl": [[0, 2.32, 408.92]]}, {"timestamp": 1578768844040, "ltp": 2.32, "tv": 5929.21, "trd": [[2.32, 1535.03]], "batb": NaN, "batl": [[0, 2.32, 399]]}, {"timestamp": 1578768886001, "ltp": 2.32, "tv": 5933.21, "trd": [[2.32, 1539.03]], "batb": NaN, "batl": [[0, 2.32, 397]]}, {"timestamp": 1578768917732, "ltp": 2.3, "tv": 6033.21, "trd": [[2.3, 200.32]], "batb": [[0, 2.3, 228.91]], "batl": NaN}, {"timestamp": 1578768918640, "ltp": 2.3, "tv": 6033.21, "trd": NaN, "batb": [[2, 2.26, 1181.67]], "batl": NaN}, {"timestamp": 1578768950935, "ltp": 2.32, "tv": 6329.99, "trd": [[2.32, 1835.81]], "batb": NaN, "batl": [[0, 2.32, 248.61]]}, {"timestamp": 1578768973839, "ltp": 2.32, "tv": 6578.27, "trd": [[2.32, 2084.09]], "batb": NaN, "batl": [[0, 2.32, 124.47]]}, {"timestamp": 1578768976042, "ltp": 2.32, "tv": 6732.69, "trd": [[2.32, 2238.51]], "batb": NaN, "batl": [[0, 2.32, 45.44]]}, {"timestamp": 1578768978022, "ltp": 2.32, "tv": 6747.06, "trd": [[2.32, 2252.88]], "batb": NaN, "batl": [[0, 2.32, 31.07]]}, {"timestamp": 1578769004980, "ltp": 2.32, "tv": 6747.06, "trd": NaN, "batb": [[0, 2.3, 228.95]], "batl": NaN}, {"timestamp": 1578769007873, "ltp": 2.32, "tv": 6778.14, "trd": [[2.32, 2283.95]], "batb": NaN, "batl": [[0, 2.34, 440.73], [1, 2.36, 14.07], [2, 2.38, 93.91]]}, {"timestamp": 1578769012962, "ltp": 2.32, "tv": 6778.14, "trd": NaN, "batb": [[1, 2.28, 1049.28], [2, 2.26, 1023.19]], "batl": NaN}, {"timestamp": 1578769026986, "ltp": 2.32, "tv": 6778.14, "trd": NaN, "batb": [[1, 2.28, 220.35], [2, 2.26, 221.4]], "batl": NaN}, {"timestamp": 1578769029912, "ltp": 2.32, "tv": 6778.14, "trd": NaN, "batb": [[1, 2.28, 976.88], [2, 2.26, 1027.33]], "batl": NaN}, {"timestamp": 1578769035983, "ltp": 2.32, "tv": 6778.14, "trd": NaN, "batb": [[1, 2.28, 820.72], [2, 2.26, 1185.81]], "batl": NaN}, {"timestamp": 1578769039009, "ltp": 2.3, "tv": 7289.14, "trd": [[2.3, 711.32]], "batb": [[0, 2.28, 820.72], [1, 2.26, 1185.81], [2, 2.24, 31.21]], "batl": NaN}, {"timestamp": 1578769039899, "ltp": 2.3, "tv": 7289.14, "trd": NaN, "batb": [[0, 2.3, 143.13], [1, 2.28, 820.72], [2, 2.26, 1185.81]], "batl": [[0, 2.34, 491.96]]}, {"timestamp": 1578769047029, "ltp": 2.3, "tv": 7289.14, "trd": NaN, "batb": [[0, 2.32, 151.39], [1, 2.3, 143.13], [2, 2.28, 822.88]], "batl": NaN}, {"timestamp": 1578769048026, "ltp": 2.34, "tv": 7314.14, "trd": [[2.34, 692.65]], "batb": NaN, "batl": [[0, 2.34, 479.46]]}, {"timestamp": 1578769053027, "ltp": 2.34, "tv": 7314.14, "trd": NaN, "batb": [[0, 2.3, 143.13], [1, 2.28, 820.72], [2, 2.26, 1027.33]], "batl": NaN}, {"timestamp": 1578769055036, "ltp": 2.3, "tv": 7322.65, "trd": [[2.3, 719.84]], "batb": [[0, 2.3, 138.87]], "batl": NaN}, {"timestamp": 1578769083009, "ltp": 2.3, "tv": 7322.65, "trd": NaN, "batb": [[0, 2.3, 292.55]], "batl": NaN}, {"timestamp": 1578769156002, "ltp": 2.3, "tv": 7322.65, "trd": NaN, "batb": [[1, 2.28, 822.88]], "batl": NaN}, {"timestamp": 1578769157000, "ltp": 2.3, "tv": 7322.65, "trd": NaN, "batb": [[2, 2.26, 1027.17]], "batl": NaN}, {"timestamp": 1578769158004, "ltp": 2.3, "tv": 7322.65, "trd": NaN, "batb": [[1, 2.28, 820.72]], "batl": NaN}, {"timestamp": 1578769177018, "ltp": 2.32, "tv": 7520.96, "trd": [[2.32, 2482.26]], "batb": NaN, "batl": [[0, 2.32, 124.03], [1, 2.34, 479.46], [2, 2.36, 16.14]]}, {"timestamp": 1578769180000, "ltp": 2.3, "tv": 7527.08, "trd": [[2.3, 725.96]], "batb": [[0, 2.3, 289.49]], "batl": NaN}, {"timestamp": 1578769187041, "ltp": 2.32, "tv": 7538.7, "trd": [[2.32, 2493.88]], "batb": NaN, "batl": [[0, 2.32, 112.41]]}, {"timestamp": 1578769188854, "ltp": 2.32, "tv": 7543.96, "trd": [[2.32, 2499.14]], "batb": NaN, "batl": [[0, 2.32, 107.15]]}, {"timestamp": 1578769193056, "ltp": 2.32, "tv": 7543.96, "trd": NaN, "batb": NaN, "batl": [[0, 2.34, 479.46], [1, 2.36, 14.07], [2, 2.38, 93.91]]}, {"timestamp": 1578769202947, "ltp": 2.32, "tv": 7543.92, "trd": [[2.32, 2499.12], [2.34, 692.64], [2.36, 785.26], [2.38, 2399.56], [2.48, 72.77], [2.52, 25.83], [2.54, 53.61]], "batb": NaN, "batl": NaN}, {"timestamp": 1578769243782, "ltp": 2.32, "tv": 7543.92, "trd": NaN, "batb": NaN, "batl": [[0, 2.32, 100], [1, 2.34, 479.46], [2, 2.36, 16.14]]}, {"timestamp": 1578769303680, "ltp": 2.32, "tv": 7643.92, "trd": [[2.32, 2599.12]], "batb": NaN, "batl": [[0, 2.34, 479.46], [1, 2.36, 16.14], [2, 2.38, 93.91]]}, {"timestamp": 1578769304991, "ltp": 2.32, "tv": 7643.92, "trd": NaN, "batb": NaN, "batl": [[0, 2.32, 85.12], [1, 2.34, 394.34], [2, 2.36, 16.14]]}, {"timestamp": 1578769306003, "ltp": 2.32, "tv": 7729.04, "trd": [[2.32, 2684.25]], "batb": NaN, "batl": [[0, 2.34, 394.34], [1, 2.36, 14.07], [2, 2.38, 93.91]]}, {"timestamp": 1578769328001, "ltp": 2.32, "tv": 7729.04, "trd": NaN, "batb": [[0, 2.32, 69.1], [1, 2.3, 289.49], [2, 2.28, 822.73]], "batl": [[0, 2.34, 323]]}, {"timestamp": 1578769339975, "ltp": 2.32, "tv": 8223.74, "trd": [[2.32, 3178.95]], "batb": [[0, 2.32, 69.06], [2, 2.28, 820.72]], "batl": [[0, 2.34, 391.48]]}, {"timestamp": 1578769340378, "ltp": 2.32, "tv": 8223.74, "trd": NaN, "batb": [[2, 2.28, 822.73]], "batl": NaN}, {"timestamp": 1578769350990, "ltp": 2.32, "tv": 8223.74, "trd": NaN, "batb": NaN, "batl": [[0, 2.34, 323]]}, {"timestamp": 1578769351973, "ltp": 2.34, "tv": 8472.88, "trd": [[2.34, 941.77]], "batb": [[0, 2.32, 146.64]], "batl": [[0, 2.34, 22.64]]}, {"timestamp": 1578769355992, "ltp": 2.34, "tv": 8518.16, "trd": [[2.34, 987.06]], "batb": [[0, 2.34, 40.65], [1, 2.32, 146.64], [2, 2.3, 289.49]], "batl": [[0, 2.36, 14.07], [1, 2.38, 93.91], [2, 2.4, 123.04]]}, {"timestamp": 1578769357008, "ltp": 2.34, "tv": 8518.16, "trd": NaN, "batb": [[2, 2.3, 291.57]], "batl": [[0, 2.36, 29.53], [1, 2.38, 91.87]]}, {"timestamp": 1578769357804, "ltp": 2.34, "tv": 8518.16, "trd": NaN, "batb": [[0, 2.34, 58.92]], "batl": [[1, 2.38, 63.98]]}, {"timestamp": 1578769359010, "ltp": 2.34, "tv": 8518.16, "trd": NaN, "batb": [[0, 2.34, 40.65]], "batl": NaN}, {"timestamp": 1578769364013, "ltp": 2.34, "tv": 8518.16, "trd": NaN, "batb": [[2, 2.3, 137.89]], "batl": NaN}, {"timestamp": 1578769364917, "ltp": 2.34, "tv": 8518.16, "trd": NaN, "batb": [[0, 2.34, 58.92]], "batl": NaN}, {"timestamp": 1578769369925, "ltp": 2.34, "tv": 8518.16, "trd": NaN, "batb": [[1, 2.32, 153.02]], "batl": NaN}, {"timestamp": 1578769370922, "ltp": 2.34, "tv": 8518.16, "trd": NaN, "batb": [[1, 2.32, 323.26]], "batl": NaN}, {"timestamp": 1578769399957, "ltp": 2.34, "tv": 8518.16, "trd": NaN, "batb": [[2, 2.3, 308.13]], "batl": NaN}, {"timestamp": 1578769421982, "ltp": 2.34, "tv": 8575.67, "trd": [[2.34, 1044.56]], "batb": [[0, 2.34, 30.17]], "batl": NaN}, {"timestamp": 1578769423954, "ltp": 2.34, "tv": 8575.67, "trd": NaN, "batb": NaN, "batl": [[0, 2.36, 15.46]]}, {"timestamp": 1578769426648, "ltp": 2.34, "tv": 8575.67, "trd": NaN, "batb": NaN, "batl": [[0, 2.36, 65.46]]}, {"timestamp": 1578769471016, "ltp": 2.34, "tv": 8605.34, "trd": [[2.34, 1074.24]], "batb": [[0, 2.34, 15.33]], "batl": NaN}, {"timestamp": 1578769544849, "ltp": 2.34, "tv": 8605.34, "trd": NaN, "batb": [[0, 2.34, 21.63]], "batl": NaN}, {"timestamp": 1578769564031, "ltp": 2.34, "tv": 8605.34, "trd": NaN, "batb": NaN, "batl": [[0, 2.36, 93.3]]}, {"timestamp": 1578769564978, "ltp": 2.34, "tv": 8605.34, "trd": NaN, "batb": NaN, "batl": [[0, 2.36, 65.46]]}, {"timestamp": 1578769566055, "ltp": 2.34, "tv": 8605.34, "trd": NaN, "batb": NaN, "batl": [[0, 2.36, 93.32]]}, {"timestamp": 1578769567051, "ltp": 2.34, "tv": 8605.34, "trd": NaN, "batb": NaN, "batl": [[0, 2.36, 65.46]]}, {"timestamp": 1578769569972, "ltp": 2.34, "tv": 8605.34, "trd": NaN, "batb": NaN, "batl": [[0, 2.36, 93.3]]}, {"timestamp": 1578769571941, "ltp": 2.34, "tv": 8605.34, "trd": NaN, "batb": NaN, "batl": [[0, 2.36, 65.46]]}, {"timestamp": 1578769572900, "ltp": 2.34, "tv": 8605.34, "trd": NaN, "batb": NaN, "batl": [[0, 2.36, 95.4]]}, {"timestamp": 1578769574020, "ltp": 2.34, "tv": 8605.34, "trd": NaN, "batb": NaN, "batl": [[0, 2.36, 65.46]]}, {"timestamp": 1578769574982, "ltp": 2.34, "tv": 8605.34, "trd": NaN, "batb": NaN, "batl": [[0, 2.36, 93.3]]}, {"timestamp": 1578769576743, "ltp": 2.34, "tv": 8605.34, "trd": NaN, "batb": NaN, "batl": [[0, 2.36, 65.46]]}, {"timestamp": 1578769580888, "ltp": 2.34, "tv": 8605.34, "trd": NaN, "batb": NaN, "batl": [[0, 2.36, 93.32]]}, {"timestamp": 1578769581996, "ltp": 2.34, "tv": 8605.34, "trd": NaN, "batb": NaN, "batl": [[0, 2.36, 65.46]]}, {"timestamp": 1578769583005, "ltp": 2.34, "tv": 8605.34, "trd": NaN, "batb": NaN, "batl": [[0, 2.36, 93.32]]}, {"timestamp": 1578769584003, "ltp": 2.34, "tv": 8605.34, "trd": NaN, "batb": NaN, "batl": [[0, 2.36, 65.46]]}, {"timestamp": 1578769587008, "ltp": 2.34, "tv": 8605.34, "trd": NaN, "batb": NaN, "batl": [[0, 2.36, 93.3]]}, {"timestamp": 1578769587802, "ltp": 2.34, "tv": 8605.34, "trd": NaN, "batb": NaN, "batl": [[0, 2.36, 65.46]]}, {"timestamp": 1578769588879, "ltp": 2.34, "tv": 8605.34, "trd": NaN, "batb": NaN, "batl": [[0, 2.36, 93.3]]}, {"timestamp": 1578769589782, "ltp": 2.34, "tv": 8605.34, "trd": NaN, "batb": NaN, "batl": [[0, 2.36, 65.46]]}, {"timestamp": 1578769593001, "ltp": 2.34, "tv": 8605.34, "trd": NaN, "batb": NaN, "batl": [[0, 2.36, 93.32]]}, {"timestamp": 1578769594009, "ltp": 2.34, "tv": 8605.34, "trd": NaN, "batb": NaN, "batl": [[0, 2.36, 65.46]]}, {"timestamp": 1578769600001, "ltp": 2.34, "tv": 8605.34, "trd": NaN, "batb": NaN, "batl": [[0, 2.36, 93.32]]}, {"timestamp": 1578769601017, "ltp": 2.34, "tv": 8605.34, "trd": NaN, "batb": NaN, "batl": [[0, 2.36, 65.46]]}, {"timestamp": 1578769602986, "ltp": 2.34, "tv": 8605.34, "trd": NaN, "batb": NaN, "batl": [[0, 2.36, 93.3]]}, {"timestamp": 1578769604984, "ltp": 2.34, "tv": 8605.34, "trd": NaN, "batb": NaN, "batl": [[0, 2.36, 65.46]]}, {"timestamp": 1578769605995, "ltp": 2.34, "tv": 8605.34, "trd": NaN, "batb": NaN, "batl": [[0, 2.36, 93.32]]}, {"timestamp": 1578769606797, "ltp": 2.34, "tv": 8605.34, "trd": NaN, "batb": NaN, "batl": [[0, 2.36, 65.46]]}, {"timestamp": 1578769608019, "ltp": 2.34, "tv": 8605.34, "trd": NaN, "batb": NaN, "batl": [[0, 2.36, 93.3]]}, {"timestamp": 1578769609992, "ltp": 2.34, "tv": 8605.34, "trd": NaN, "batb": NaN, "batl": [[0, 2.36, 65.46]]}, {"timestamp": 1578769611009, "ltp": 2.34, "tv": 8605.34, "trd": NaN, "batb": NaN, "batl": [[0, 2.36, 93.32]]}, {"timestamp": 1578769611831, "ltp": 2.34, "tv": 8605.34, "trd": NaN, "batb": NaN, "batl": [[0, 2.36, 65.46]]}, {"timestamp": 1578769619043, "ltp": 2.34, "tv": 8605.34, "trd": NaN, "batb": NaN, "batl": [[0, 2.36, 93.32]]}, {"timestamp": 1578769621951, "ltp": 2.34, "tv": 8605.34, "trd": NaN, "batb": NaN, "batl": [[0, 2.36, 65.46]]}, {"timestamp": 1578769624858, "ltp": 2.34, "tv": 8605.34, "trd": NaN, "batb": NaN, "batl": [[0, 2.36, 93.32]]}, {"timestamp": 1578769625849, "ltp": 2.34, "tv": 8605.34, "trd": NaN, "batb": NaN, "batl": [[0, 2.36, 65.46]]}, {"timestamp": 1578769627050, "ltp": 2.34, "tv": 8605.34, "trd": NaN, "batb": NaN, "batl": [[0, 2.36, 95.38]]}, {"timestamp": 1578769627978, "ltp": 2.34, "tv": 8605.34, "trd": NaN, "batb": NaN, "batl": [[0, 2.36, 65.46]]}, {"timestamp": 1578769628949, "ltp": 2.34, "tv": 8605.34, "trd": NaN, "batb": NaN, "batl": [[0, 2.36, 93.32]]}, {"timestamp": 1578769629954, "ltp": 2.34, "tv": 8605.34, "trd": NaN, "batb": NaN, "batl": [[0, 2.36, 65.46]]}, {"timestamp": 1578769634777, "ltp": 2.34, "tv": 8605.34, "trd": NaN, "batb": NaN, "batl": [[0, 2.36, 93.3]]}, {"timestamp": 1578769680040, "ltp": 2.34, "tv": 8648.6, "trd": [[2.34, 1117.5]], "batb": [[0, 2.32, 323.26], [1, 2.3, 306.05], [2, 2.28, 820.72]], "batl": [[0, 2.34, 21.1], [1, 2.36, 93.3], [2, 2.38, 66.02]]}, {"timestamp": 1578769692966, "ltp": 2.34, "tv": 8669.7, "trd": [[2.34, 1138.6]], "batb": NaN, "batl": [[0, 2.36, 93.3], [1, 2.38, 63.98], [2, 2.4, 123.04]]}, {"timestamp": 1578769693961, "ltp": 2.34, "tv": 8669.7, "trd": NaN, "batb": [[0, 2.34, 31.36], [1, 2.32, 323.26], [2, 2.3, 308.06]], "batl": [[0, 2.36, 65.46]]}, {"timestamp": 1578769706981, "ltp": 2.34, "tv": 8677.18, "trd": [[2.34, 1146.07]], "batb": [[0, 2.34, 27.62]], "batl": NaN}, {"timestamp": 1578769707984, "ltp": 2.34, "tv": 8677.18, "trd": NaN, "batb": [[0, 2.32, 323.26], [1, 2.3, 306.05], [2, 2.28, 820.88]], "batl": [[0, 2.36, 93.25]]}, {"timestamp": 1578769725998, "ltp": 2.32, "tv": 8683.37, "trd": [[2.32, 3185.15]], "batb": [[0, 2.32, 320.17]], "batl": NaN}, {"timestamp": 1578769779889, "ltp": 2.32, "tv": 8683.37, "trd": NaN, "batb": [[2, 2.28, 822.88]], "batl": [[0, 2.36, 77.79]]}, {"timestamp": 1578769787905, "ltp": 2.34, "tv": 8730.27, "trd": [[2.34, 1192.97]], "batb": NaN, "batl": [[0, 2.34, 11.55], [1, 2.36, 77.79], [2, 2.38, 66.02]]}, {"timestamp": 1578769788873, "ltp": 2.34, "tv": 8740.71, "trd": [[2.34, 1203.41]], "batb": NaN, "batl": [[0, 2.34, 6.33]]}, {"timestamp": 1578769793893, "ltp": 2.34, "tv": 8740.71, "trd": NaN, "batb": NaN, "batl": [[0, 2.34, 59.17]]}, {"timestamp": 1578769794900, "ltp": 2.34, "tv": 8740.71, "trd": NaN, "batb": NaN, "batl": [[2, 2.38, 100.52]]}, {"timestamp": 1578769833977, "ltp": 2.32, "tv": 8829.92, "trd": [[2.32, 3188.89], [2.34, 1288.87]], "batb": [[0, 2.32, 318.29]], "batl": [[0, 2.34, 16.44]]}, {"timestamp": 1578769835965, "ltp": 2.32, "tv": 8829.92, "trd": NaN, "batb": [[2, 2.28, 66.35]], "batl": NaN}, {"timestamp": 1578769838967, "ltp": 2.32, "tv": 8829.92, "trd": NaN, "batb": [[2, 2.28, 887.46]], "batl": NaN}, {"timestamp": 1578769841861, "ltp": 2.32, "tv": 8829.92, "trd": NaN, "batb": [[2, 2.28, 1082.87]], "batl": NaN}, {"timestamp": 1578769870996, "ltp": 2.34, "tv": 8862.79, "trd": [[2.34, 1321.75]], "batb": [[1, 2.3, 308.06]], "batl": [[0, 2.36, 77.79], [1, 2.38, 100.52], [2, 2.4, 123.04]]}, {"timestamp": 1578769871989, "ltp": 2.32, "tv": 8902.8, "trd": [[2.32, 3228.89]], "batb": [[0, 2.32, 298.29], [1, 2.3, 306.05]], "batl": [[1, 2.38, 98.48]]}, {"timestamp": 1578769901965, "ltp": 2.32, "tv": 8902.8, "trd": NaN, "batb": [[2, 2.28, 261.76]], "batl": NaN}, {"timestamp": 1578769903959, "ltp": 2.32, "tv": 8902.8, "trd": NaN, "batb": [[2, 2.28, 66.35]], "batl": NaN}, {"timestamp": 1578769920979, "ltp": 2.32, "tv": 8902.8, "trd": NaN, "batb": [[2, 2.28, 831.4]], "batl": NaN}, {"timestamp": 1578769927052, "ltp": 2.32, "tv": 8902.8, "trd": NaN, "batb": NaN, "batl": [[0, 2.34, 2.42], [1, 2.36, 77.79], [2, 2.38, 100.52]]}, {"timestamp": 1578769943004, "ltp": 2.32, "tv": 9252.8, "trd": [[2.32, 3578.9]], "batb": [[0, 2.32, 195.49]], "batl": NaN}, {"timestamp": 1578769944018, "ltp": 2.32, "tv": 9314.04, "trd": [[2.32, 3640.13]], "batb": [[0, 2.32, 193.81]], "batl": NaN}, {"timestamp": 1578769947034, "ltp": 2.32, "tv": 9314.04, "trd": NaN, "batb": [[0, 2.32, 121.6]], "batl": [[0, 2.34, 77.47]]}, {"timestamp": 1578769967030, "ltp": 2.34, "tv": 9373.86, "trd": [[2.34, 1381.57]], "batb": NaN, "batl": [[0, 2.34, 47.56]]}, {"timestamp": 1578769968842, "ltp": 2.32, "tv": 9375.93, "trd": [[2.32, 3642.2]], "batb": [[0, 2.32, 120.57]], "batl": NaN}, {"timestamp": 1578769976797, "ltp": 2.32, "tv": 9379.93, "trd": [[2.32, 3646.21]], "batb": [[0, 2.32, 118.56]], "batl": NaN}, {"timestamp": 1578769981011, "ltp": 2.32, "tv": 9379.93, "trd": NaN, "batb": [[2, 2.28, 1688.54]], "batl": NaN}, {"timestamp": 1578769988915, "ltp": 2.32, "tv": 9379.93, "trd": NaN, "batb": [[2, 2.28, 1769.13]], "batl": NaN}, {"timestamp": 1578770001932, "ltp": 2.32, "tv": 9379.93, "trd": NaN, "batb": [[0, 2.32, 518.56]], "batl": NaN}, {"timestamp": 1578770011032, "ltp": 2.32, "tv": 9379.93, "trd": NaN, "batb": NaN, "batl": [[0, 2.34, 1749.98]]}, {"timestamp": 1578770018048, "ltp": 2.32, "tv": 11269.38, "trd": [[2.32, 5535.66]], "batb": [[0, 2.3, 306.05], [1, 2.28, 1766.97], [2, 2.26, 2203.52]], "batl": [[0, 2.32, 333.53], [1, 2.34, 1749.98], [2, 2.36, 79.81]]}, {"timestamp": 1578770019053, "ltp": 2.32, "tv": 11423.16, "trd": [[2.32, 5689.44]], "batb": NaN, "batl": [[0, 2.32, 256.64], [1, 2.34, 1929.25]]}, {"timestamp": 1578770019953, "ltp": 2.32, "tv": 11457.21, "trd": [[2.32, 5723.49]], "batb": NaN, "batl": [[0, 2.32, 239.62]]}, {"timestamp": 1578770040935, "ltp": 2.32, "tv": 11491.99, "trd": [[2.32, 5758.27]], "batb": NaN, "batl": [[0, 2.32, 222.23]]}, {"timestamp": 1578770071044, "ltp": 2.32, "tv": 11491.99, "trd": NaN, "batb": [[1, 2.28, 1962.38], [2, 2.26, 2005.04]], "batl": NaN}, {"timestamp": 1578770079851, "ltp": 2.32, "tv": 11513.27, "trd": [[2.32, 5779.55]], "batb": NaN, "batl": [[0, 2.32, 211.58]]}, {"timestamp": 1578770082948, "ltp": 2.32, "tv": 11524.05, "trd": [[2.32, 5790.32]], "batb": NaN, "batl": [[0, 2.32, 206.2]]}, {"timestamp": 1578770091863, "ltp": 2.32, "tv": 11524.05, "trd": NaN, "batb": [[1, 2.28, 1960.38]], "batl": NaN}, {"timestamp": 1578770099972, "ltp": 2.32, "tv": 11524.05, "trd": NaN, "batb": [[1, 2.28, 1764.97], [2, 2.26, 2203.52]], "batl": NaN}, {"timestamp": 1578770116986, "ltp": 2.32, "tv": 11560.33, "trd": [[2.32, 5826.6]], "batb": NaN, "batl": [[0, 2.32, 188.06]]}, {"timestamp": 1578770118016, "ltp": 2.32, "tv": 11644.33, "trd": [[2.3, 805.96], [2.32, 5830.6]], "batb": [[0, 2.3, 266.05]], "batl": [[0, 2.32, 186.06]]}, {"timestamp": 1578770148033, "ltp": 2.32, "tv": 11900.41, "trd": [[2.32, 6086.68]], "batb": NaN, "batl": [[0, 2.32, 58.02]]}, {"timestamp": 1578770151950, "ltp": 2.32, "tv": 11934.45, "trd": [[2.32, 6120.73]], "batb": NaN, "batl": [[0, 2.32, 40.99]]}, {"timestamp": 1578770154643, "ltp": 2.32, "tv": 11934.45, "trd": NaN, "batb": [[1, 2.28, 1766.97]], "batl": NaN}, {"timestamp": 1578770160969, "ltp": 2.32, "tv": 11980.73, "trd": [[2.32, 6167.01]], "batb": [[1, 2.28, 1937.21]], "batl": [[0, 2.32, 17.86]]}, {"timestamp": 1578770164846, "ltp": 2.32, "tv": 12003.01, "trd": [[2.32, 6189.29]], "batb": NaN, "batl": [[0, 2.32, 6.72]]}, {"timestamp": 1578770167994, "ltp": 2.32, "tv": 12009.73, "trd": [[2.32, 6196]], "batb": NaN, "batl": [[0, 2.34, 1929.25], [1, 2.36, 79.81], [2, 2.38, 100.52]]}, {"timestamp": 1578770168593, "ltp": 2.32, "tv": 12009.73, "trd": NaN, "batb": NaN, "batl": [[1, 2.36, 77.79]]}, {"timestamp": 1578770173871, "ltp": 2.32, "tv": 12009.73, "trd": NaN, "batb": [[0, 2.32, 30], [1, 2.3, 266.05], [2, 2.28, 1939.37]], "batl": NaN}, {"timestamp": 1578770179051, "ltp": 2.32, "tv": 12009.73, "trd": NaN, "batb": [[0, 2.32, 515.19]], "batl": NaN}, {"timestamp": 1578770187885, "ltp": 2.32, "tv": 12077.83, "trd": [[2.32, 6264.1]], "batb": [[0, 2.32, 481.14]], "batl": NaN}, {"timestamp": 1578770191687, "ltp": 2.32, "tv": 12077.83, "trd": NaN, "batb": NaN, "batl": [[0, 2.34, 1946.27]]}, {"timestamp": 1578770197896, "ltp": 2.32, "tv": 12077.83, "trd": NaN, "batb": [[0, 2.3, 747.19], [1, 2.28, 1939.37], [2, 2.26, 2203.68]], "batl": NaN}, {"timestamp": 1578770199015, "ltp": 2.32, "tv": 12077.83, "trd": NaN, "batb": [[1, 2.28, 1939.26], [2, 2.26, 2203.72]], "batl": NaN}, {"timestamp": 1578770216949, "ltp": 2.32, "tv": 12077.83, "trd": NaN, "batb": [[1, 2.28, 1937.26]], "batl": NaN}, {"timestamp": 1578770218020, "ltp": 2.32, "tv": 12077.83, "trd": NaN, "batb": [[2, 2.26, 2203.52]], "batl": NaN}, {"timestamp": 1578770223965, "ltp": 2.32, "tv": 12077.83, "trd": NaN, "batb": [[1, 2.28, 1938.44], [2, 2.26, 2203.72]], "batl": NaN}, {"timestamp": 1578770229676, "ltp": 2.32, "tv": 12077.83, "trd": NaN, "batb": [[2, 2.26, 2203.56]], "batl": NaN}, {"timestamp": 1578770232039, "ltp": 2.32, "tv": 12107.83, "trd": [[2.32, 6294.1]], "batb": NaN, "batl": NaN}, {"timestamp": 1578770236050, "ltp": 2.32, "tv": 12107.83, "trd": NaN, "batb": [[1, 2.28, 2133.85], [2, 2.26, 2005.24]], "batl": NaN}, {"timestamp": 1578770244952, "ltp": 2.32, "tv": 12107.83, "trd": NaN, "batb": [[1, 2.28, 511.66], [2, 2.26, 221.4]], "batl": NaN}, {"timestamp": 1578770250000, "ltp": 2.32, "tv": 12107.83, "trd": NaN, "batb": [[2, 2.26, 221.28]], "batl": NaN}, {"timestamp": 1578770251807, "ltp": 2.32, "tv": 12107.83, "trd": NaN, "batb": [[0, 2.3, 939.47], [1, 2.28, 316.25]], "batl": NaN}, {"timestamp": 1578770253981, "ltp": 2.32, "tv": 12547.48, "trd": [[2.32, 6733.75]], "batb": NaN, "batl": [[0, 2.32, 411.56], [1, 2.34, 1946.27], [2, 2.36, 77.79]]}, {"timestamp": 1578770257003, "ltp": 2.32, "tv": 12952.76, "trd": [[2.32, 7139.03]], "batb": [[1, 2.28, 314.2]], "batl": [[0, 2.32, 208.92], [2, 2.36, 79.86]]}, {"timestamp": 1578770257955, "ltp": 2.32, "tv": 12986.8, "trd": [[2.32, 7173.08]], "batb": NaN, "batl": [[0, 2.32, 191.9]]}, {"timestamp": 1578770263019, "ltp": 2.32, "tv": 13178.58, "trd": [[2.32, 7364.86]], "batb": NaN, "batl": [[0, 2.32, 96.01]]}, {"timestamp": 1578770266980, "ltp": 2.32, "tv": 13178.58, "trd": NaN, "batb": [[0, 2.3, 1010.87]], "batl": NaN}, {"timestamp": 1578770276040, "ltp": 2.32, "tv": 13178.58, "trd": NaN, "batb": [[1, 2.28, 1727.63], [2, 2.26, 1723.26]], "batl": NaN}, {"timestamp": 1578770276889, "ltp": 2.32, "tv": 13178.58, "trd": NaN, "batb": [[1, 2.28, 314.2], [2, 2.26, 221.28]], "batl": NaN}, {"timestamp": 1578770280021, "ltp": 2.32, "tv": 13178.58, "trd": NaN, "batb": [[1, 2.28, 316.2]], "batl": NaN}, {"timestamp": 1578770310962, "ltp": 2.32, "tv": 13178.58, "trd": NaN, "batb": [[1, 2.28, 1972.61], [2, 2.26, 1743.25]], "batl": NaN}, {"timestamp": 1578770315938, "ltp": 2.32, "tv": 13178.58, "trd": NaN, "batb": [[1, 2.28, 316.2], [2, 2.26, 221.28]], "batl": NaN}, {"timestamp": 1578770319981, "ltp": 2.32, "tv": 13262.87, "trd": [[2.32, 7449.14]], "batb": [[1, 2.28, 1966.06], [2, 2.26, 1932.37]], "batl": [[0, 2.32, 53.86]]}, {"timestamp": 1578770330967, "ltp": 2.32, "tv": 13370.59, "trd": [[2.32, 7556.87]], "batb": [[0, 2.32, 98.07], [1, 2.3, 1010.87], [2, 2.28, 1968.11]], "batl": [[0, 2.34, 1946.27], [1, 2.36, 77.79], [2, 2.38, 100.48]]}, {"timestamp": 1578770335999, "ltp": 2.32, "tv": 13370.59, "trd": NaN, "batb": [[1, 2.3, 1087.58]], "batl": NaN}, {"timestamp": 1578770342603, "ltp": 2.32, "tv": 13370.59, "trd": NaN, "batb": [[2, 2.28, 1966.11]], "batl": NaN}, {"timestamp": 1578770401026, "ltp": 2.32, "tv": 13370.59, "trd": NaN, "batb": NaN, "batl": [[1, 2.36, 80.79]]}, {"timestamp": 1578770406035, "ltp": 2.32, "tv": 13370.59, "trd": NaN, "batb": NaN, "batl": [[2, 2.38, 102.48]]}, {"timestamp": 1578770414050, "ltp": 2.32, "tv": 13370.59, "trd": NaN, "batb": [[2, 2.28, 316.25]], "batl": NaN}, {"timestamp": 1578770416990, "ltp": 2.32, "tv": 13370.59, "trd": NaN, "batb": [[2, 2.28, 2149.58]], "batl": NaN}, {"timestamp": 1578770433976, "ltp": 2.32, "tv": 13370.59, "trd": NaN, "batb": [[2, 2.28, 316.25]], "batl": NaN}, {"timestamp": 1578770437016, "ltp": 2.32, "tv": 13370.59, "trd": NaN, "batb": [[2, 2.28, 1940.97]], "batl": NaN}, {"timestamp": 1578770449896, "ltp": 2.32, "tv": 13370.59, "trd": NaN, "batb": [[1, 2.3, 895.3], [2, 2.28, 511.66]], "batl": NaN}, {"timestamp": 1578770452904, "ltp": 2.32, "tv": 13370.59, "trd": NaN, "batb": [[2, 2.28, 2247.38]], "batl": NaN}, {"timestamp": 1578770467858, "ltp": 2.32, "tv": 13370.59, "trd": NaN, "batb": [[2, 2.28, 511.66]], "batl": NaN}, {"timestamp": 1578770482946, "ltp": 2.32, "tv": 13370.59, "trd": NaN, "batb": [[0, 2.32, 330]], "batl": NaN}, {"timestamp": 1578770496940, "ltp": 2.32, "tv": 13370.59, "trd": NaN, "batb": NaN, "batl": [[0, 2.34, 1996.27], [1, 2.36, 30.79]]}, {"timestamp": 1578770499951, "ltp": 2.32, "tv": 13370.59, "trd": NaN, "batb": [[2, 2.28, 2198.25]], "batl": NaN}, {"timestamp": 1578770505032, "ltp": 2.32, "tv": 13370.59, "trd": NaN, "batb": [[1, 2.3, 1087.58], [2, 2.28, 2002.84]], "batl": NaN}, {"timestamp": 1578770515051, "ltp": 2.32, "tv": 13370.59, "trd": NaN, "batb": [[1, 2.3, 895.3], [2, 2.28, 2198.25]], "batl": NaN}, {"timestamp": 1578770520049, "ltp": 2.32, "tv": 13370.59, "trd": NaN, "batb": [[2, 2.28, 2002.84]], "batl": NaN}, {"timestamp": 1578770538021, "ltp": 2.32, "tv": 13370.59, "trd": NaN, "batb": [[0, 2.32, 405.01]], "batl": NaN}, {"timestamp": 1578770539990, "ltp": 2.32, "tv": 13370.59, "trd": NaN, "batb": [[0, 2.32, 330], [1, 2.3, 1112.78]], "batl": NaN}, {"timestamp": 1578770543026, "ltp": 2.34, "tv": 17890.87, "trd": [[2.34, 5901.84]], "batb": NaN, "batl": [[0, 2.36, 30.79], [1, 2.38, 102.48], [2, 2.4, 125.04]]}, {"timestamp": 1578770543925, "ltp": 2.34, "tv": 17890.87, "trd": NaN, "batb": [[0, 2.32, 498.97]], "batl": [[0, 2.36, 43.65], [1, 2.38, 102.52]]}, {"timestamp": 1578770545720, "ltp": 2.34, "tv": 17890.87, "trd": NaN, "batb": [[0, 2.32, 626.65]], "batl": NaN}, {"timestamp": 1578770566043, "ltp": 2.34, "tv": 17890.87, "trd": NaN, "batb": [[0, 2.32, 1366.65]], "batl": NaN}, {"timestamp": 1578770567023, "ltp": 2.34, "tv": 17890.87, "trd": NaN, "batb": [[0, 2.32, 1416.98]], "batl": NaN}, {"timestamp": 1578770568033, "ltp": 2.34, "tv": 17890.87, "trd": NaN, "batb": [[0, 2.32, 1468.18], [1, 2.3, 1032.36]], "batl": NaN}, {"timestamp": 1578770570042, "ltp": 2.34, "tv": 18818.24, "trd": [[2.34, 6829.22]], "batb": [[1, 2.3, 1005.61]], "batl": [[0, 2.36, 30.79]]}, {"timestamp": 1578770571053, "ltp": 2.32, "tv": 18824.24, "trd": [[2.32, 7562.87]], "batb": [[0, 2.32, 1465.18]], "batl": [[1, 2.38, 100.48]]}, {"timestamp": 1578770572021, "ltp": 2.32, "tv": 18824.24, "trd": NaN, "batb": [[0, 2.34, 1.09], [1, 2.32, 1465.18], [2, 2.3, 1005.61]], "batl": NaN}, {"timestamp": 1578770573036, "ltp": 2.32, "tv": 18824.24, "trd": NaN, "batb": [[2, 2.3, 788.13]], "batl": NaN}, {"timestamp": 1578770583044, "ltp": 2.32, "tv": 18824.24, "trd": NaN, "batb": [[0, 2.34, 852.3], [2, 2.3, 790.21]], "batl": NaN}, {"timestamp": 1578770584049, "ltp": 2.32, "tv": 18824.24, "trd": NaN, "batb": [[0, 2.34, 923.92], [1, 2.32, 1590.32]], "batl": [[0, 2.36, 3]]}, {"timestamp": 1578770584956, "ltp": 2.32, "tv": 18824.24, "trd": NaN, "batb": [[2, 2.3, 722.52]], "batl": NaN}, {"timestamp": 1578770585979, "ltp": 2.34, "tv": 18901.74, "trd": [[2.34, 6906.72]], "batb": [[0, 2.34, 885.18]], "batl": NaN}, {"timestamp": 1578770589959, "ltp": 2.34, "tv": 18901.74, "trd": NaN, "batb": [[0, 2.34, 962.1]], "batl": NaN}, {"timestamp": 1578770590973, "ltp": 2.36, "tv": 18921.76, "trd": [[2.36, 805.29]], "batb": NaN, "batl": [[0, 2.38, 100.48], [1, 2.4, 125.04], [2, 2.42, 48.94]]}, {"timestamp": 1578770591981, "ltp": 2.36, "tv": 18921.76, "trd": NaN, "batb": NaN, "batl": [[0, 2.38, 176.11]]}, {"timestamp": 1578770592978, "ltp": 2.36, "tv": 18938.79, "trd": [[2.36, 822.31]], "batb": [[0, 2.34, 1167.05], [1, 2.32, 1462.64]], "batl": NaN}, {"timestamp": 1578770593986, "ltp": 2.36, "tv": 18955.81, "trd": [[2.36, 839.33]], "batb": NaN, "batl": NaN}, {"timestamp": 1578770595952, "ltp": 2.36, "tv": 18972.84, "trd": [[2.36, 856.36]], "batb": NaN, "batl": NaN}, {"timestamp": 1578770596964, "ltp": 2.36, "tv": 18989.86, "trd": [[2.36, 873.38]], "batb": NaN, "batl": NaN}, {"timestamp": 1578770597968, "ltp": 2.36, "tv": 18989.86, "trd": NaN, "batb": NaN, "batl": [[2, 2.42, 48.96]]}, {"timestamp": 1578770599979, "ltp": 2.36, "tv": 19006.88, "trd": [[2.36, 890.41]], "batb": [[0, 2.34, 1039.37], [1, 2.32, 1386.04]], "batl": NaN}, {"timestamp": 1578770600981, "ltp": 2.36, "tv": 19023.91, "trd": [[2.36, 907.43]], "batb": NaN, "batl": NaN}, {"timestamp": 1578770602989, "ltp": 2.36, "tv": 19023.91, "trd": NaN, "batb": [[0, 2.34, 1110.86]], "batl": NaN}, {"timestamp": 1578770603998, "ltp": 2.36, "tv": 19023.91, "trd": NaN, "batb": NaN, "batl": [[0, 2.38, 100.48]]}, {"timestamp": 1578770605910, "ltp": 2.36, "tv": 19032.28, "trd": [[2.36, 915.81]], "batb": NaN, "batl": NaN}, {"timestamp": 1578770610586, "ltp": 2.36, "tv": 19032.28, "trd": NaN, "batb": [[1, 2.32, 1319.95]], "batl": NaN}, {"timestamp": 1578770612034, "ltp": 2.36, "tv": 19032.28, "trd": NaN, "batb": NaN, "batl": [[2, 2.42, 46.9]]}, {"timestamp": 1578770612997, "ltp": 2.36, "tv": 19032.28, "trd": NaN, "batb": NaN, "batl": [[2, 2.42, 48.96]]}, {"timestamp": 1578770616012, "ltp": 2.36, "tv": 19032.28, "trd": NaN, "batb": NaN, "batl": [[0, 2.38, 77.63], [1, 2.4, 123], [2, 2.42, 137.64]]}, {"timestamp": 1578770617978, "ltp": 2.36, "tv": 19032.28, "trd": NaN, "batb": [[0, 2.36, 92.55], [1, 2.34, 1110.86], [2, 2.32, 1322.09]], "batl": NaN}, {"timestamp": 1578770619984, "ltp": 2.36, "tv": 19032.28, "trd": NaN, "batb": [[2, 2.32, 1238.11]], "batl": NaN}, {"timestamp": 1578770620976, "ltp": 2.36, "tv": 19123.92, "trd": [[2.36, 1007.45]], "batb": [[0, 2.36, 46.73]], "batl": NaN}, {"timestamp": 1578770621987, "ltp": 2.36, "tv": 19169.57, "trd": [[2.36, 1053.09]], "batb": [[0, 2.36, 23.91]], "batl": NaN}, {"timestamp": 1578770622979, "ltp": 2.36, "tv": 19169.57, "trd": NaN, "batb": [[0, 2.36, 92.55], [2, 2.32, 1237.98]], "batl": [[0, 2.38, 169.36]]}, {"timestamp": 1578770623982, "ltp": 2.36, "tv": 19174.16, "trd": [[2.36, 1057.68]], "batb": [[0, 2.36, 90.25]], "batl": [[0, 2.38, 77.63]]}, {"timestamp": 1578770626010, "ltp": 2.36, "tv": 19194.16, "trd": [[2.36, 1077.68]], "batb": [[0, 2.36, 80.25]], "batl": NaN}, {"timestamp": 1578770631900, "ltp": 2.36, "tv": 19194.16, "trd": NaN, "batb": [[1, 2.34, 1120.34]], "batl": NaN}, {"timestamp": 1578770636017, "ltp": 2.36, "tv": 19194.16, "trd": NaN, "batb": NaN, "batl": [[0, 2.38, 2]]}, {"timestamp": 1578770637015, "ltp": 2.36, "tv": 19194.16, "trd": NaN, "batb": [[0, 2.36, 160.85]], "batl": NaN}, {"timestamp": 1578770638016, "ltp": 2.36, "tv": 19194.16, "trd": NaN, "batb": [[0, 2.36, 231.39], [2, 2.32, 1272.76]], "batl": NaN}, {"timestamp": 1578770645015, "ltp": 2.36, "tv": 19199.27, "trd": [[2.36, 1082.79]], "batb": [[0, 2.36, 228.84]], "batl": NaN}, {"timestamp": 1578770647028, "ltp": 2.36, "tv": 19199.27, "trd": NaN, "batb": [[1, 2.34, 1620.34]], "batl": NaN}, {"timestamp": 1578770651050, "ltp": 2.38, "tv": 19201.27, "trd": [[2.38, 2401.56]], "batb": [[0, 2.36, 305.11], [2, 2.32, 1195.18]], "batl": [[0, 2.4, 198], [1, 2.42, 135.58], [2, 2.44, 59.04]]}, {"timestamp": 1578770652017, "ltp": 2.38, "tv": 19201.27, "trd": NaN, "batb": NaN, "batl": [[0, 2.4, 133.96], [2, 2.44, 161.24]]}, {"timestamp": 1578770655035, "ltp": 2.36, "tv": 19227.4, "trd": [[2.36, 1108.93]], "batb": [[0, 2.36, 292.04]], "batl": NaN}, {"timestamp": 1578770656042, "ltp": 2.36, "tv": 19227.4, "trd": NaN, "batb": [[0, 2.36, 315.36]], "batl": [[0, 2.4, 232.7]]}, {"timestamp": 1578770657055, "ltp": 2.38, "tv": 19296.64, "trd": [[2.38, 2470.79]], "batb": [[0, 2.38, 193.08], [1, 2.36, 315.36], [2, 2.34, 1622.56]], "batl": NaN}, {"timestamp": 1578770657977, "ltp": 2.38, "tv": 19296.64, "trd": NaN, "batb": [[0, 2.38, 228.85], [2, 2.34, 1545.29]], "batl": [[0, 2.4, 168.29], [1, 2.42, 108.31]]}, {"timestamp": 1578770663042, "ltp": 2.38, "tv": 19296.64, "trd": NaN, "batb": [[0, 2.38, 193.08], [1, 2.36, 292.04]], "batl": NaN}, {"timestamp": 1578770664046, "ltp": 2.38, "tv": 19296.64, "trd": NaN, "batb": [[0, 2.38, 228.87], [2, 2.34, 1473.8]], "batl": NaN}, {"timestamp": 1578770666054, "ltp": 2.38, "tv": 19344.99, "trd": [[2.38, 2519.15]], "batb": [[0, 2.38, 168.9], [1, 2.36, 237.42]], "batl": NaN}, {"timestamp": 1578770669037, "ltp": 2.38, "tv": 19344.99, "trd": NaN, "batb": [[2, 2.34, 1723.8]], "batl": [[2, 2.44, 1793.14]]}, {"timestamp": 1578770669972, "ltp": 2.38, "tv": 19344.99, "trd": NaN, "batb": NaN, "batl": [[0, 2.4, 1947.17]]}, {"timestamp": 1578770671040, "ltp": 2.38, "tv": 19419.49, "trd": [[2.38, 2593.65]], "batb": [[0, 2.38, 131.65], [1, 2.36, 161.15]], "batl": NaN}, {"timestamp": 1578770672046, "ltp": 2.38, "tv": 19419.49, "trd": NaN, "batb": [[1, 2.36, 108.94]], "batl": [[0, 2.4, 2098.29]]}, {"timestamp": 1578770672957, "ltp": 2.38, "tv": 19419.49, "trd": NaN, "batb": [[0, 2.38, 18.76]], "batl": [[1, 2.42, 144.58]]}, {"timestamp": 1578770673959, "ltp": 2.38, "tv": 19456.63, "trd": [[2.38, 2630.78]], "batb": [[0, 2.36, 109.13], [1, 2.34, 1721.58], [2, 2.32, 1195.31]], "batl": NaN}, {"timestamp": 1578770675962, "ltp": 2.38, "tv": 19457.01, "trd": [[2.38, 2631.17]], "batb": [[0, 2.36, 108.94]], "batl": [[0, 2.38, 46.4], [1, 2.4, 2039.99], [2, 2.42, 146.64]]}, {"timestamp": 1578770676968, "ltp": 2.38, "tv": 19457.01, "trd": NaN, "batb": NaN, "batl": [[0, 2.38, 104.71], [1, 2.4, 2044.58]]}, {"timestamp": 1578770677921, "ltp": 2.38, "tv": 19457.01, "trd": NaN, "batb": NaN, "batl": [[0, 2.38, 154.71]]}, {"timestamp": 1578770680879, "ltp": 2.38, "tv": 19457.01, "trd": NaN, "batb": NaN, "batl": [[0, 2.38, 50]]}, {"timestamp": 1578770683984, "ltp": 2.36, "tv": 19561.66, "trd": [[2.36, 1213.57]], "batb": [[0, 2.36, 56.61]], "batl": [[0, 2.38, 225.52]]}, {"timestamp": 1578770685038, "ltp": 2.36, "tv": 19561.66, "trd": NaN, "batb": [[0, 2.36, 144.36]], "batl": NaN}, {"timestamp": 1578770691051, "ltp": 2.36, "tv": 19685.85, "trd": [[2.36, 1337.77]], "batb": [[0, 2.36, 82.27]], "batl": [[0, 2.38, 125.63]]}, {"timestamp": 1578770691967, "ltp": 2.36, "tv": 19685.85, "trd": NaN, "batb": [[0, 2.36, 183.14]], "batl": [[0, 2.38, 278.73]]}, {"timestamp": 1578770692965, "ltp": 2.38, "tv": 19888.9, "trd": [[2.38, 2834.21]], "batb": [[0, 2.36, 100.88]], "batl": [[0, 2.4, 2044.58], [1, 2.42, 146.64], [2, 2.44, 1793.14]]}, {"timestamp": 1578770693977, "ltp": 2.38, "tv": 19888.9, "trd": NaN, "batb": NaN, "batl": [[1, 2.42, 144.58]]}, {"timestamp": 1578770696000, "ltp": 2.38, "tv": 19888.9, "trd": NaN, "batb": [[0, 2.36, 830.88]], "batl": NaN}, {"timestamp": 1578770696966, "ltp": 2.38, "tv": 19888.9, "trd": NaN, "batb": [[1, 2.34, 1712.1]], "batl": NaN}, {"timestamp": 1578770707000, "ltp": 2.38, "tv": 19888.9, "trd": NaN, "batb": NaN, "batl": [[0, 2.38, 127.68], [1, 2.4, 2044.58], [2, 2.42, 146.64]]}, {"timestamp": 1578770715999, "ltp": 2.36, "tv": 19896.95, "trd": [[2.36, 1345.82]], "batb": [[0, 2.36, 826.85]], "batl": NaN}, {"timestamp": 1578770718024, "ltp": 2.38, "tv": 20024.64, "trd": [[2.38, 2961.9]], "batb": NaN, "batl": [[0, 2.4, 2044.58], [1, 2.42, 144.58], [2, 2.44, 1793.14]]}, {"timestamp": 1578770733017, "ltp": 2.38, "tv": 20024.64, "trd": NaN, "batb": NaN, "batl": [[0, 2.38, 17.02], [1, 2.4, 2044.58], [2, 2.42, 146.64]]}, {"timestamp": 1578770735032, "ltp": 2.38, "tv": 20024.64, "trd": NaN, "batb": [[0, 2.36, 903.12]], "batl": [[1, 2.4, 289.68]]}, {"timestamp": 1578770737045, "ltp": 2.36, "tv": 20025.52, "trd": [[2.36, 1346.71]], "batb": [[0, 2.36, 902.68]], "batl": NaN}, {"timestamp": 1578770740013, "ltp": 2.38, "tv": 20059.57, "trd": [[2.38, 2995.94]], "batb": [[0, 2.38, 69.03], [1, 2.36, 902.68], [2, 2.34, 1714.32]], "batl": [[0, 2.4, 289.68], [1, 2.42, 144.58], [2, 2.44, 161.24]]}, {"timestamp": 1578770741017, "ltp": 2.38, "tv": 20059.57, "trd": NaN, "batb": [[0, 2.38, 191.6]], "batl": NaN}, {"timestamp": 1578770741962, "ltp": 2.38, "tv": 20059.57, "trd": NaN, "batb": [[0, 2.38, 271.5], [2, 2.34, 1637.4]], "batl": NaN}, {"timestamp": 1578770743023, "ltp": 2.38, "tv": 20059.57, "trd": NaN, "batb": [[1, 2.36, 912]], "batl": NaN}, {"timestamp": 1578770746040, "ltp": 2.38, "tv": 20063.39, "trd": [[2.38, 2999.77]], "batb": [[0, 2.38, 269.59]], "batl": NaN}, {"timestamp": 1578770752999, "ltp": 2.38, "tv": 20063.39, "trd": NaN, "batb": NaN, "batl": [[2, 2.44, 1378.74]]}, {"timestamp": 1578770755026, "ltp": 2.38, "tv": 20063.39, "trd": NaN, "batb": [[0, 2.38, 189.69]], "batl": NaN}, {"timestamp": 1578770756031, "ltp": 2.38, "tv": 20079.05, "trd": [[2.38, 3015.43]], "batb": [[0, 2.38, 181.86]], "batl": NaN}, {"timestamp": 1578770764047, "ltp": 2.38, "tv": 20079.05, "trd": NaN, "batb": NaN, "batl": [[2, 2.44, 161.24]]}, {"timestamp": 1578770765056, "ltp": 2.38, "tv": 20079.05, "trd": NaN, "batb": NaN, "batl": [[0, 2.4, 1726.73], [1, 2.42, 1606.12]]}, {"timestamp": 1578770765946, "ltp": 2.38, "tv": 20099.05, "trd": [[2.38, 3035.43]], "batb": [[0, 2.38, 171.85]], "batl": NaN}, {"timestamp": 1578770768958, "ltp": 2.38, "tv": 20442.76, "trd": [[2.38, 3379.13]], "batb": [[0, 2.36, 912], [1, 2.34, 1635.18], [2, 2.32, 1195.17]], "batl": [[0, 2.38, 1383.43], [1, 2.4, 1743.75], [2, 2.42, 1608.18]]}, {"timestamp": 1578770769952, "ltp": 2.38, "tv": 20442.76, "trd": NaN, "batb": [[0, 2.36, 835.73]], "batl": NaN}, {"timestamp": 1578770778964, "ltp": 2.38, "tv": 20442.76, "trd": NaN, "batb": NaN, "batl": [[0, 2.38, 1408.43]]}, {"timestamp": 1578770782983, "ltp": 2.36, "tv": 20488.68, "trd": [[2.36, 1392.63]], "batb": [[0, 2.36, 812.77]], "batl": NaN}, {"timestamp": 1578770786971, "ltp": 2.36, "tv": 20508.68, "trd": [[2.36, 1412.63]], "batb": [[0, 2.36, 802.77]], "batl": NaN}, {"timestamp": 1578770788972, "ltp": 2.36, "tv": 21153.36, "trd": [[2.36, 2057.31]], "batb": [[0, 2.36, 755.78]], "batl": [[0, 2.38, 2027.76]]}, {"timestamp": 1578770789984, "ltp": 2.36, "tv": 21153.36, "trd": NaN, "batb": NaN, "batl": [[0, 2.38, 2027.87]]}, {"timestamp": 1578770792877, "ltp": 2.36, "tv": 21153.36, "trd": NaN, "batb": [[0, 2.36, 854.17]], "batl": [[0, 2.38, 1808.43]]}, {"timestamp": 1578770799992, "ltp": 2.36, "tv": 21191.62, "trd": [[2.36, 2095.57]], "batb": [[0, 2.36, 835.04]], "batl": NaN}, {"timestamp": 1578770809013, "ltp": 2.38, "tv": 21210.27, "trd": [[2.38, 3397.77]], "batb": [[0, 2.36, 825.72]], "batl": [[0, 2.38, 1799.11]]}, {"timestamp": 1578770811999, "ltp": 2.36, "tv": 21260.27, "trd": [[2.36, 2145.57]], "batb": [[0, 2.36, 800.72]], "batl": [[0, 2.38, 1774.11]]}, {"timestamp": 1578770813013, "ltp": 2.36, "tv": 21260.27, "trd": NaN, "batb": [[0, 2.36, 481.14]], "batl": [[0, 2.38, 2044.68]]}, {"timestamp": 1578770813991, "ltp": 2.36, "tv": 21260.27, "trd": NaN, "batb": [[0, 2.36, 426.98]], "batl": NaN}, {"timestamp": 1578770816978, "ltp": 2.36, "tv": 21267.67, "trd": [[2.36, 2152.97]], "batb": [[0, 2.36, 423.28]], "batl": NaN}, {"timestamp": 1578770818008, "ltp": 2.36, "tv": 21270.32, "trd": [[2.36, 2155.63]], "batb": [[0, 2.36, 421.95]], "batl": NaN}, {"timestamp": 1578770822903, "ltp": 2.36, "tv": 21270.32, "trd": NaN, "batb": [[1, 2.34, 1652.2]], "batl": NaN}, {"timestamp": 1578770824005, "ltp": 2.36, "tv": 21281.52, "trd": [[2.36, 2166.83]], "batb": [[0, 2.36, 416.35]], "batl": NaN}, {"timestamp": 1578770841033, "ltp": 2.36, "tv": 21281.52, "trd": NaN, "batb": [[0, 2.34, 1652.2], [1, 2.32, 1195.17], [2, 2.3, 670.48]], "batl": NaN}, {"timestamp": 1578770841919, "ltp": 2.36, "tv": 21281.52, "trd": NaN, "batb": [[0, 2.34, 2195], [1, 2.32, 1193.17]], "batl": NaN}, {"timestamp": 1578770850960, "ltp": 2.36, "tv": 21281.52, "trd": NaN, "batb": [[0, 2.36, 416.35], [1, 2.34, 1778.65], [2, 2.32, 1193.17]], "batl": NaN}, {"timestamp": 1578770851847, "ltp": 2.36, "tv": 21281.52, "trd": NaN, "batb": [[0, 2.36, 529.31], [2, 2.32, 1195.18]], "batl": NaN}, {"timestamp": 1578770852965, "ltp": 2.36, "tv": 21281.52, "trd": NaN, "batb": [[0, 2.36, 672.93]], "batl": NaN}, {"timestamp": 1578770853854, "ltp": 2.36, "tv": 21477.5, "trd": [[2.36, 2362.81]], "batb": [[0, 2.36, 574.94]], "batl": NaN}, {"timestamp": 1578770868985, "ltp": 2.36, "tv": 21477.5, "trd": NaN, "batb": [[0, 2.36, 1304.94]], "batl": [[0, 2.38, 1992.92]]}, {"timestamp": 1578770869990, "ltp": 2.36, "tv": 21477.5, "trd": NaN, "batb": [[0, 2.36, 1534.5]], "batl": NaN}, {"timestamp": 1578770880008, "ltp": 2.36, "tv": 21478.44, "trd": [[2.36, 2363.75]], "batb": [[0, 2.36, 1534.03]], "batl": NaN}, {"timestamp": 1578770889020, "ltp": 2.36, "tv": 21478.44, "trd": NaN, "batb": NaN, "batl": [[0, 2.38, 1774.11]]}, {"timestamp": 1578770890014, "ltp": 2.36, "tv": 21478.44, "trd": NaN, "batb": NaN, "batl": [[0, 2.38, 1927.18]]}, {"timestamp": 1578770900041, "ltp": 2.38, "tv": 21518.44, "trd": [[2.38, 3437.77]], "batb": NaN, "batl": [[0, 2.38, 1907.18]]}, {"timestamp": 1578770901004, "ltp": 2.38, "tv": 21518.44, "trd": NaN, "batb": NaN, "batl": [[1, 2.4, 306.7], [2, 2.42, 146.64]]}, {"timestamp": 1578770903941, "ltp": 2.38, "tv": 21518.44, "trd": NaN, "batb": NaN, "batl": [[0, 2.38, 2021.98]]}, {"timestamp": 1578770926976, "ltp": 2.36, "tv": 21521.0, "trd": [[2.36, 2366.31]], "batb": [[0, 2.36, 1532.75]], "batl": NaN}, {"timestamp": 1578770945972, "ltp": 2.36, "tv": 21521.45, "trd": [[2.36, 2366.75]], "batb": [[0, 2.36, 1532.53]], "batl": NaN}, {"timestamp": 1578770947980, "ltp": 2.38, "tv": 21538.25, "trd": [[2.38, 3454.57]], "batb": NaN, "batl": [[0, 2.38, 2013.58]]}, {"timestamp": 1578770956980, "ltp": 2.38, "tv": 22389.92, "trd": [[2.38, 4306.25]], "batb": [[0, 2.36, 1853]], "batl": [[0, 2.38, 1585.24]]}, {"timestamp": 1578770957974, "ltp": 2.38, "tv": 23510.15, "trd": [[2.38, 5426.48]], "batb": [[0, 2.36, 1537.57]], "batl": [[0, 2.38, 2254.4]]}, {"timestamp": 1578770958988, "ltp": 2.38, "tv": 23877.87, "trd": [[2.38, 5794.2]], "batb": NaN, "batl": [[0, 2.38, 2070.54]]}, {"timestamp": 1578770961981, "ltp": 2.38, "tv": 24123.94, "trd": [[2.38, 6040.26]], "batb": NaN, "batl": [[0, 2.38, 1947.51]]}, {"timestamp": 1578770963992, "ltp": 2.38, "tv": 24123.94, "trd": NaN, "batb": [[1, 2.34, 1661.09]], "batl": NaN}, {"timestamp": 1578770966990, "ltp": 2.36, "tv": 24127.94, "trd": [[2.36, 2370.75]], "batb": [[0, 2.36, 1535.57]], "batl": NaN}, {"timestamp": 1578770971014, "ltp": 2.36, "tv": 24147.94, "trd": [[2.36, 2390.75]], "batb": [[0, 2.36, 1525.57]], "batl": NaN}, {"timestamp": 1578770977022, "ltp": 2.36, "tv": 24147.94, "trd": NaN, "batb": NaN, "batl": [[0, 2.38, 1949.51]]}, {"timestamp": 1578770981032, "ltp": 2.36, "tv": 24624.5, "trd": [[2.36, 2867.32]], "batb": [[0, 2.36, 1211.02]], "batl": [[0, 2.38, 2080.44]]}, {"timestamp": 1578770981929, "ltp": 2.36, "tv": 24624.5, "trd": NaN, "batb": [[0, 2.36, 796.11]], "batl": [[0, 2.38, 2096.76]]}, {"timestamp": 1578770982926, "ltp": 2.36, "tv": 24624.5, "trd": NaN, "batb": [[0, 2.36, 908.98]], "batl": NaN}, {"timestamp": 1578770989958, "ltp": 2.36, "tv": 24624.5, "trd": NaN, "batb": NaN, "batl": [[1, 2.4, 308.7]]}, {"timestamp": 1578770993953, "ltp": 2.36, "tv": 24624.5, "trd": NaN, "batb": [[0, 2.36, 178.98], [1, 2.34, 2391.09]], "batl": NaN}, {"timestamp": 1578770995032, "ltp": 2.36, "tv": 24756.72, "trd": [[2.36, 2999.54]], "batb": [[0, 2.34, 2391.09], [1, 2.32, 1195.18], [2, 2.3, 798.09]], "batl": [[0, 2.36, 83.29], [1, 2.38, 2096.76], [2, 2.4, 308.7]]}, {"timestamp": 1578770995980, "ltp": 2.36, "tv": 24756.72, "trd": NaN, "batb": [[0, 2.34, 2468.01], [1, 2.32, 1193.17]], "batl": [[0, 2.36, 159.31], [2, 2.4, 310.74]]}, {"timestamp": 1578770998048, "ltp": 2.36, "tv": 24756.72, "trd": NaN, "batb": NaN, "batl": [[0, 2.36, 459.31]]}, {"timestamp": 1578770998940, "ltp": 2.36, "tv": 24756.72, "trd": NaN, "batb": [[1, 2.32, 1158.39]], "batl": NaN}, {"timestamp": 1578771000053, "ltp": 2.36, "tv": 24756.72, "trd": NaN, "batb": [[1, 2.32, 1639.52], [2, 2.3, 701.34]], "batl": NaN}, {"timestamp": 1578771001007, "ltp": 2.36, "tv": 24756.72, "trd": NaN, "batb": [[0, 2.34, 2470.01]], "batl": [[0, 2.36, 463.04]]}, {"timestamp": 1578771003981, "ltp": 2.36, "tv": 24850.08, "trd": [[2.36, 3092.9]], "batb": NaN, "batl": [[0, 2.36, 412.63]]}, {"timestamp": 1578771006029, "ltp": 2.36, "tv": 24850.08, "trd": NaN, "batb": [[2, 2.3, 316.96]], "batl": NaN}, {"timestamp": 1578771009999, "ltp": 2.36, "tv": 24850.08, "trd": NaN, "batb": [[0, 2.34, 2874.23], [1, 2.32, 1158.39]], "batl": NaN}, {"timestamp": 1578771012005, "ltp": 2.36, "tv": 24862.39, "trd": [[2.36, 3105.21]], "batb": [[0, 2.34, 2951.15], [1, 2.32, 1161.39]], "batl": [[0, 2.36, 400.31], [1, 2.38, 817.12]]}, {"timestamp": 1578771013973, "ltp": 2.36, "tv": 24862.39, "trd": NaN, "batb": [[0, 2.34, 2221.15], [2, 2.3, 788.34]], "batl": NaN}, {"timestamp": 1578771016933, "ltp": 2.36, "tv": 24862.39, "trd": NaN, "batb": NaN, "batl": [[0, 2.36, 410.31]]}, {"timestamp": 1578771017735, "ltp": 2.36, "tv": 24862.39, "trd": NaN, "batb": [[0, 2.34, 2237.26]], "batl": NaN}, {"timestamp": 1578771024039, "ltp": 2.34, "tv": 24885.36, "trd": [[2.34, 6929.68]], "batb": [[0, 2.34, 2225.78]], "batl": NaN}, {"timestamp": 1578771029905, "ltp": 2.34, "tv": 24885.36, "trd": NaN, "batb": [[1, 2.32, 1158.39], [2, 2.3, 791.34]], "batl": NaN}, {"timestamp": 1578771035036, "ltp": 2.34, "tv": 24885.36, "trd": NaN, "batb": [[2, 2.3, 406.96]], "batl": NaN}, {"timestamp": 1578771038964, "ltp": 2.34, "tv": 24885.36, "trd": NaN, "batb": [[0, 2.34, 2710.97]], "batl": NaN}, {"timestamp": 1578771046979, "ltp": 2.34, "tv": 24902.43, "trd": [[2.34, 6946.75]], "batb": [[0, 2.34, 2702.43]], "batl": NaN}, {"timestamp": 1578771054001, "ltp": 2.34, "tv": 24902.43, "trd": NaN, "batb": NaN, "batl": [[0, 2.36, 835.92]]}, {"timestamp": 1578771054960, "ltp": 2.34, "tv": 24902.43, "trd": NaN, "batb": [[0, 2.34, 2805.46]], "batl": NaN}, {"timestamp": 1578771063993, "ltp": 2.34, "tv": 25106.72, "trd": [[2.34, 7151.04]], "batb": [[0, 2.34, 2703.31]], "batl": NaN}, {"timestamp": 1578771069018, "ltp": 2.34, "tv": 25113.53, "trd": [[2.34, 7157.85]], "batb": [[0, 2.34, 2699.91], [2, 2.3, 791.34]], "batl": NaN}, {"timestamp": 1578771075010, "ltp": 2.34, "tv": 25121.0, "trd": [[2.34, 7165.33]], "batb": [[0, 2.34, 2696.17]], "batl": NaN}, {"timestamp": 1578771080920, "ltp": 2.34, "tv": 25127.44, "trd": [[2.34, 7171.76]], "batb": [[0, 2.34, 2692.95]], "batl": NaN}, {"timestamp": 1578771082023, "ltp": 2.34, "tv": 25327.44, "trd": [[2.34, 7371.76]], "batb": [[0, 2.34, 2592.95]], "batl": NaN}, {"timestamp": 1578771084040, "ltp": 2.34, "tv": 25327.44, "trd": NaN, "batb": [[0, 2.34, 2656.72], [2, 2.3, 406.96]], "batl": NaN}, {"timestamp": 1578771085046, "ltp": 2.34, "tv": 25327.44, "trd": NaN, "batb": NaN, "batl": [[0, 2.36, 837.62]]}, {"timestamp": 1578771085973, "ltp": 2.34, "tv": 25327.44, "trd": NaN, "batb": [[2, 2.3, 791.34]], "batl": NaN}, {"timestamp": 1578771088956, "ltp": 2.34, "tv": 25327.44, "trd": NaN, "batb": NaN, "batl": [[0, 2.36, 835.92]]}, {"timestamp": 1578771097029, "ltp": 2.34, "tv": 25445.68, "trd": [[2.34, 7490.01]], "batb": [[0, 2.34, 2597.6]], "batl": NaN}, {"timestamp": 1578771101049, "ltp": 2.34, "tv": 25449.09, "trd": [[2.34, 7493.41]], "batb": [[0, 2.34, 2595.89]], "batl": NaN}, {"timestamp": 1578771112984, "ltp": 2.34, "tv": 25476.75, "trd": [[2.34, 7521.08]], "batb": [[0, 2.34, 2582.06]], "batl": NaN}, {"timestamp": 1578771113991, "ltp": 2.34, "tv": 25476.75, "trd": NaN, "batb": [[0, 2.34, 2505.14], [2, 2.3, 406.96]], "batl": [[0, 2.36, 2835.92]]}, {"timestamp": 1578771115000, "ltp": 2.34, "tv": 25526.75, "trd": [[2.34, 7571.08]], "batb": [[0, 2.34, 2480.14]], "batl": NaN}, {"timestamp": 1578771117969, "ltp": 2.34, "tv": 25526.75, "trd": NaN, "batb": [[1, 2.32, 1537.03]], "batl": NaN}, {"timestamp": 1578771120977, "ltp": 2.34, "tv": 25530.49, "trd": [[2.34, 7574.82]], "batb": [[0, 2.34, 2478.27]], "batl": NaN}, {"timestamp": 1578771121988, "ltp": 2.34, "tv": 25530.49, "trd": NaN, "batb": [[1, 2.32, 1158.39]], "batl": NaN}, {"timestamp": 1578771123001, "ltp": 2.34, "tv": 25530.49, "trd": NaN, "batb": [[2, 2.3, 791.34]], "batl": NaN}, {"timestamp": 1578771126987, "ltp": 2.36, "tv": 25534.49, "trd": [[2.36, 3109.21]], "batb": [[0, 2.34, 2476.27], [1, 2.32, 1161.39], [2, 2.3, 788.34]], "batl": [[0, 2.36, 2833.92]]}, {"timestamp": 1578771127986, "ltp": 2.34, "tv": 25544.71, "trd": [[2.34, 7585.03]], "batb": [[0, 2.34, 2471.16], [2, 2.3, 403.96]], "batl": NaN}, {"timestamp": 1578771133996, "ltp": 2.34, "tv": 25544.71, "trd": NaN, "batb": [[0, 2.34, 1996.77]], "batl": NaN}, {"timestamp": 1578771134947, "ltp": 2.34, "tv": 25544.71, "trd": NaN, "batb": NaN, "batl": [[0, 2.36, 2981.55]]}, {"timestamp": 1578771144965, "ltp": 2.34, "tv": 25544.71, "trd": NaN, "batb": [[0, 2.34, 2030.43]], "batl": NaN}, {"timestamp": 1578771147048, "ltp": 2.34, "tv": 25544.71, "trd": NaN, "batb": NaN, "batl": [[0, 2.36, 2833.92]]}, {"timestamp": 1578771149959, "ltp": 2.34, "tv": 25544.71, "trd": NaN, "batb": [[2, 2.3, 316.96]], "batl": NaN}, {"timestamp": 1578771161989, "ltp": 2.34, "tv": 25544.71, "trd": NaN, "batb": NaN, "batl": [[0, 2.36, 2948.72], [1, 2.38, 702.31]]}, {"timestamp": 1578771164010, "ltp": 2.34, "tv": 25544.71, "trd": NaN, "batb": NaN, "batl": [[0, 2.36, 3087.78]]}, {"timestamp": 1578771171995, "ltp": 2.34, "tv": 25551.52, "trd": [[2.34, 7591.84]], "batb": [[0, 2.34, 2027.02]], "batl": NaN}, {"timestamp": 1578771176019, "ltp": 2.36, "tv": 25582.3, "trd": [[2.36, 3139.99]], "batb": [[2, 2.3, 701.34]], "batl": [[0, 2.36, 3056.99]]}, {"timestamp": 1578771181020, "ltp": 2.36, "tv": 25582.3, "trd": NaN, "batb": [[2, 2.3, 316.96]], "batl": NaN}, {"timestamp": 1578771182032, "ltp": 2.36, "tv": 25582.3, "trd": NaN, "batb": NaN, "batl": [[0, 2.36, 3064.99]]}, {"timestamp": 1578771189022, "ltp": 2.36, "tv": 25582.3, "trd": NaN, "batb": [[0, 2.34, 2473.02]], "batl": NaN}, {"timestamp": 1578771189942, "ltp": 2.36, "tv": 25582.3, "trd": NaN, "batb": [[0, 2.34, 2505.59]], "batl": NaN}, {"timestamp": 1578771199052, "ltp": 2.36, "tv": 25582.3, "trd": NaN, "batb": NaN, "batl": [[0, 2.36, 2925.94]]}, {"timestamp": 1578771201972, "ltp": 2.34, "tv": 25589.96, "trd": [[2.34, 7599.5]], "batb": [[0, 2.34, 2501.76]], "batl": NaN}, {"timestamp": 1578771204050, "ltp": 2.34, "tv": 25589.96, "trd": NaN, "batb": [[0, 2.34, 2055.76]], "batl": NaN}, {"timestamp": 1578771217999, "ltp": 2.34, "tv": 25589.96, "trd": NaN, "batb": [[0, 2.34, 2501.76]], "batl": NaN}, {"timestamp": 1578771246954, "ltp": 2.34, "tv": 26181.29, "trd": [[2.34, 8190.83]], "batb": [[0, 2.34, 2206.09]], "batl": NaN}, {"timestamp": 1578771247955, "ltp": 2.34, "tv": 26181.29, "trd": NaN, "batb": [[0, 2.34, 2378.67]], "batl": [[0, 2.36, 2997.4]]}, {"timestamp": 1578771251906, "ltp": 2.34, "tv": 26181.29, "trd": NaN, "batb": NaN, "batl": [[0, 2.36, 2858.41]]}, {"timestamp": 1578771259049, "ltp": 2.34, "tv": 26188.77, "trd": [[2.34, 8198.31]], "batb": [[0, 2.34, 2374.93]], "batl": NaN}, {"timestamp": 1578771259950, "ltp": 2.34, "tv": 26188.77, "trd": NaN, "batb": NaN, "batl": [[0, 2.36, 2997.46]]}, {"timestamp": 1578771260961, "ltp": 2.34, "tv": 26188.77, "trd": NaN, "batb": NaN, "batl": [[0, 2.36, 2858.41]]}, {"timestamp": 1578771261960, "ltp": 2.34, "tv": 26188.77, "trd": NaN, "batb": NaN, "batl": [[0, 2.36, 2997.46]]}, {"timestamp": 1578771263033, "ltp": 2.36, "tv": 27151.04, "trd": [[2.36, 4102.26]], "batb": [[0, 2.34, 1893.8]], "batl": [[0, 2.36, 2377.27]]}, {"timestamp": 1578771264037, "ltp": 2.36, "tv": 27151.04, "trd": NaN, "batb": [[0, 2.34, 1924.55]], "batl": NaN}, {"timestamp": 1578771264965, "ltp": 2.36, "tv": 27151.04, "trd": NaN, "batb": NaN, "batl": [[0, 2.36, 2516.32]]}, {"timestamp": 1578771272052, "ltp": 2.36, "tv": 27151.04, "trd": NaN, "batb": NaN, "batl": [[0, 2.36, 2377.27]]}, {"timestamp": 1578771273974, "ltp": 2.36, "tv": 27151.04, "trd": NaN, "batb": NaN, "batl": [[0, 2.36, 2387.74], [1, 2.38, 1702.31]]}, {"timestamp": 1578771274975, "ltp": 2.36, "tv": 27151.04, "trd": NaN, "batb": NaN, "batl": [[0, 2.36, 2601.51]]}, {"timestamp": 1578771280982, "ltp": 2.34, "tv": 27154.78, "trd": [[2.34, 8202.05]], "batb": [[0, 2.34, 1922.68]], "batl": NaN}, {"timestamp": 1578771284911, "ltp": 2.34, "tv": 27154.78, "trd": NaN, "batb": NaN, "batl": [[0, 2.36, 3001.51], [1, 2.38, 1302.31]]}, {"timestamp": 1578771286010, "ltp": 2.34, "tv": 27154.78, "trd": NaN, "batb": NaN, "batl": [[0, 2.36, 2787.74]]}, {"timestamp": 1578771295018, "ltp": 2.34, "tv": 27154.78, "trd": NaN, "batb": NaN, "batl": [[0, 2.36, 2961], [1, 2.38, 1285.99], [2, 2.4, 235.74]]}, {"timestamp": 1578771298577, "ltp": 2.34, "tv": 27177.74, "trd": [[2.34, 8225.01]], "batb": [[0, 2.34, 1911.2]], "batl": NaN}, {"timestamp": 1578771302014, "ltp": 2.34, "tv": 27277.74, "trd": [[2.34, 8325.01]], "batb": [[0, 2.34, 1861.2]], "batl": NaN}, {"timestamp": 1578771304012, "ltp": 2.34, "tv": 27277.74, "trd": NaN, "batb": NaN, "batl": [[0, 2.36, 2990.57]]}, {"timestamp": 1578771313018, "ltp": 2.34, "tv": 27333.97, "trd": [[2.34, 8332.49], [2.36, 4151.02]], "batb": [[0, 2.34, 1857.46]], "batl": [[0, 2.36, 2966.19]]}, {"timestamp": 1578771315027, "ltp": 2.34, "tv": 27334.53, "trd": [[2.34, 8333.05]], "batb": [[0, 2.34, 1857.18]], "batl": NaN}, {"timestamp": 1578771319987, "ltp": 2.34, "tv": 27334.53, "trd": NaN, "batb": NaN, "batl": [[0, 2.36, 2566.19]]}, {"timestamp": 1578771322042, "ltp": 2.36, "tv": 30583.99, "trd": [[2.34, 8337.64], [2.36, 7395.88]], "batb": [[0, 2.34, 1854.88]], "batl": [[0, 2.36, 943.76]]}, {"timestamp": 1578771323960, "ltp": 2.36, "tv": 30583.99, "trd": NaN, "batb": [[0, 2.34, 3295.23], [1, 2.32, 2613.53]], "batl": NaN}, {"timestamp": 1578771325054, "ltp": 2.36, "tv": 30583.99, "trd": NaN, "batb": [[0, 2.34, 3372.15]], "batl": [[0, 2.36, 760.03]]}, {"timestamp": 1578771331037, "ltp": 2.34, "tv": 30625.95, "trd": [[2.34, 8379.6]], "batb": [[0, 2.34, 3351.17]], "batl": NaN}, {"timestamp": 1578771334963, "ltp": 2.34, "tv": 30625.95, "trd": NaN, "batb": [[1, 2.32, 2699.53], [2, 2.3, 403.96]], "batl": NaN}, {"timestamp": 1578771336052, "ltp": 2.34, "tv": 30625.95, "trd": NaN, "batb": [[0, 2.34, 1910.82], [1, 2.32, 1247.39]], "batl": NaN}, {"timestamp": 1578771337049, "ltp": 2.34, "tv": 30625.95, "trd": NaN, "batb": [[2, 2.3, 1917.27]], "batl": NaN}, {"timestamp": 1578771343985, "ltp": 2.34, "tv": 30625.95, "trd": NaN, "batb": [[1, 2.32, 1161.39], [2, 2.3, 1830.27]], "batl": NaN}, {"timestamp": 1578771347964, "ltp": 2.34, "tv": 30625.95, "trd": NaN, "batb": [[0, 2.34, 2089.57]], "batl": NaN}, {"timestamp": 1578771352975, "ltp": 2.34, "tv": 30626.43, "trd": [[2.34, 8380.08]], "batb": [[0, 2.34, 2089.33]], "batl": NaN}, {"timestamp": 1578771356994, "ltp": 2.34, "tv": 30642.43, "trd": [[2.34, 8396.08]], "batb": [[0, 2.34, 2081.33]], "batl": NaN}, {"timestamp": 1578771357994, "ltp": 2.34, "tv": 30642.43, "trd": NaN, "batb": NaN, "batl": [[1, 2.38, 1287.99], [2, 2.4, 233.74]]}, {"timestamp": 1578771361986, "ltp": 2.34, "tv": 30642.43, "trd": NaN, "batb": NaN, "batl": [[0, 2.36, 798.73]]}, {"timestamp": 1578771368020, "ltp": 2.34, "tv": 30642.43, "trd": NaN, "batb": [[1, 2.32, 1121.39]], "batl": NaN}, {"timestamp": 1578771383945, "ltp": 2.34, "tv": 30642.43, "trd": NaN, "batb": NaN, "batl": [[0, 2.36, 873.73]]}, {"timestamp": 1578771388051, "ltp": 2.36, "tv": 30682.43, "trd": [[2.36, 7435.88]], "batb": NaN, "batl": [[0, 2.36, 853.73]]}, {"timestamp": 1578771390018, "ltp": 2.36, "tv": 30682.43, "trd": NaN, "batb": [[2, 2.3, 1917.27]], "batl": NaN}, {"timestamp": 1578771404959, "ltp": 2.34, "tv": 30690.12, "trd": [[2.34, 8403.77]], "batb": [[0, 2.34, 2077.49]], "batl": NaN}, {"timestamp": 1578771407976, "ltp": 2.34, "tv": 30690.12, "trd": NaN, "batb": NaN, "batl": [[0, 2.36, 2130.54]]}, {"timestamp": 1578771408973, "ltp": 2.34, "tv": 30690.12, "trd": NaN, "batb": NaN, "batl": [[0, 2.36, 2369.92]]}, {"timestamp": 1578771414053, "ltp": 2.34, "tv": 30690.12, "trd": NaN, "batb": NaN, "batl": [[0, 2.36, 2130.54]]}, {"timestamp": 1578771418960, "ltp": 2.34, "tv": 30690.12, "trd": NaN, "batb": [[0, 2.34, 2080.49], [1, 2.32, 1118.39]], "batl": NaN}, {"timestamp": 1578771431003, "ltp": 2.34, "tv": 30690.12, "trd": NaN, "batb": [[2, 2.3, 403.96]], "batl": NaN}, {"timestamp": 1578771432004, "ltp": 2.34, "tv": 30690.12, "trd": NaN, "batb": [[0, 2.34, 2003.57]], "batl": NaN}, {"timestamp": 1578771432893, "ltp": 2.34, "tv": 30693.72, "trd": [[2.34, 8407.37]], "batb": [[0, 2.34, 2001.77]], "batl": NaN}, {"timestamp": 1578771436027, "ltp": 2.34, "tv": 30693.72, "trd": NaN, "batb": NaN, "batl": [[0, 2.36, 2310.17]]}, {"timestamp": 1578771443026, "ltp": 2.34, "tv": 30693.72, "trd": NaN, "batb": [[2, 2.3, 316.96]], "batl": NaN}, {"timestamp": 1578771444019, "ltp": 2.34, "tv": 30693.72, "trd": NaN, "batb": [[2, 2.3, 1950.35]], "batl": NaN}, {"timestamp": 1578771446035, "ltp": 2.36, "tv": 31051.22, "trd": [[2.36, 7793.39]], "batb": [[0, 2.34, 1823.02]], "batl": [[0, 2.36, 2131.42]]}, {"timestamp": 1578771454923, "ltp": 2.36, "tv": 31051.22, "trd": NaN, "batb": [[2, 2.3, 2037.35]], "batl": NaN}, {"timestamp": 1578771459054, "ltp": 2.36, "tv": 31051.22, "trd": NaN, "batb": NaN, "batl": [[0, 2.36, 2148.45]]}, {"timestamp": 1578771472032, "ltp": 2.36, "tv": 31051.22, "trd": NaN, "batb": NaN, "batl": [[1, 2.38, 1288.01]]}, {"timestamp": 1578771476957, "ltp": 2.34, "tv": 31651.22, "trd": [[2.34, 9007.37]], "batb": [[0, 2.34, 1523.02]], "batl": [[2, 2.4, 233.89]]}, {"timestamp": 1578771482961, "ltp": 2.34, "tv": 31651.22, "trd": NaN, "batb": NaN, "batl": [[0, 2.36, 2168.99]]}, {"timestamp": 1578771484972, "ltp": 2.34, "tv": 31651.22, "trd": NaN, "batb": NaN, "batl": [[0, 2.36, 2542.71]]}, {"timestamp": 1578771488987, "ltp": 2.34, "tv": 31651.22, "trd": NaN, "batb": [[2, 2.3, 403.96]], "batl": NaN}, {"timestamp": 1578771491994, "ltp": 2.36, "tv": 31707.28, "trd": [[2.36, 7849.45]], "batb": NaN, "batl": [[0, 2.36, 2514.68]]}, {"timestamp": 1578771494015, "ltp": 2.36, "tv": 31707.28, "trd": NaN, "batb": [[2, 2.3, 316.96]], "batl": NaN}, {"timestamp": 1578771494972, "ltp": 2.36, "tv": 31707.28, "trd": NaN, "batb": NaN, "batl": [[1, 2.38, 1287.99], [2, 2.4, 233.74]]}, {"timestamp": 1578771497975, "ltp": 2.36, "tv": 31707.28, "trd": NaN, "batb": [[0, 2.34, 1551.78]], "batl": NaN}, {"timestamp": 1578771498978, "ltp": 2.36, "tv": 31741.33, "trd": [[2.36, 7883.49]], "batb": NaN, "batl": [[0, 2.36, 2497.66]]}, {"timestamp": 1578771501992, "ltp": 2.36, "tv": 31741.33, "trd": NaN, "batb": [[0, 2.34, 1448.08]], "batl": NaN}, {"timestamp": 1578771502999, "ltp": 2.34, "tv": 31752.04, "trd": [[2.34, 9018.09]], "batb": [[0, 2.34, 1206.21], [2, 2.3, 500.93]], "batl": NaN}, {"timestamp": 1578771504008, "ltp": 2.34, "tv": 31752.04, "trd": NaN, "batb": [[0, 2.34, 1072.43]], "batl": NaN}, {"timestamp": 1578771512005, "ltp": 2.34, "tv": 31752.04, "trd": NaN, "batb": NaN, "batl": [[1, 2.38, 287.99]]}, {"timestamp": 1578771519031, "ltp": 2.34, "tv": 31762.04, "trd": [[2.34, 9028.09]], "batb": [[0, 2.34, 1067.43]], "batl": NaN}, {"timestamp": 1578771523051, "ltp": 2.34, "tv": 31762.04, "trd": NaN, "batb": [[0, 2.34, 1064.43], [1, 2.32, 1121.39]], "batl": NaN}, {"timestamp": 1578771523954, "ltp": 2.34, "tv": 33890.9, "trd": [[2.34, 11156.95]], "batb": [[0, 2.32, 1121.39], [1, 2.3, 498.92], [2, 2.28, 372.02]], "batl": [[0, 2.34, 212.39], [1, 2.36, 2497.66], [2, 2.38, 290.03]]}, {"timestamp": 1578771525019, "ltp": 2.34, "tv": 33890.9, "trd": NaN, "batb": [[0, 2.32, 1223.56]], "batl": [[1, 2.36, 2502.66], [2, 2.38, 326.01]]}, {"timestamp": 1578771526033, "ltp": 2.34, "tv": 33890.9, "trd": NaN, "batb": [[2, 2.28, 762.43]], "batl": NaN}, {"timestamp": 1578771527041, "ltp": 2.34, "tv": 33890.9, "trd": NaN, "batb": [[0, 2.32, 1543.73]], "batl": [[1, 2.36, 2506.12]]}, {"timestamp": 1578771528044, "ltp": 2.34, "tv": 33890.9, "trd": NaN, "batb": [[2, 2.28, 372.02]], "batl": [[0, 2.34, 389.09]]}, {"timestamp": 1578771530956, "ltp": 2.34, "tv": 33890.9, "trd": NaN, "batb": [[2, 2.28, 284.02]], "batl": [[1, 2.36, 1229.3]]}, {"timestamp": 1578771531963, "ltp": 2.34, "tv": 33890.9, "trd": NaN, "batb": NaN, "batl": [[0, 2.34, 1794.95]]}, {"timestamp": 1578771534046, "ltp": 2.34, "tv": 33890.9, "trd": NaN, "batb": NaN, "batl": [[0, 2.34, 1833.65], [1, 2.36, 1190.6]]}, {"timestamp": 1578771535041, "ltp": 2.34, "tv": 33890.9, "trd": NaN, "batb": NaN, "batl": [[0, 2.34, 1708.06], [1, 2.36, 1187.14]]}, {"timestamp": 1578771535975, "ltp": 2.34, "tv": 33890.9, "trd": NaN, "batb": NaN, "batl": [[0, 2.34, 1834.23]]}, {"timestamp": 1578771536973, "ltp": 2.34, "tv": 33890.9, "trd": NaN, "batb": NaN, "batl": [[0, 2.34, 1708.06]]}, {"timestamp": 1578771537963, "ltp": 2.34, "tv": 33890.9, "trd": NaN, "batb": NaN, "batl": [[0, 2.34, 1833.96]]}, {"timestamp": 1578771539039, "ltp": 2.34, "tv": 33890.9, "trd": NaN, "batb": NaN, "batl": [[0, 2.34, 1708.06]]}, {"timestamp": 1578771541050, "ltp": 2.34, "tv": 33890.9, "trd": NaN, "batb": NaN, "batl": [[0, 2.34, 1833.96]]}, {"timestamp": 1578771541956, "ltp": 2.34, "tv": 33890.9, "trd": NaN, "batb": NaN, "batl": [[0, 2.34, 1708.06]]}, {"timestamp": 1578771542957, "ltp": 2.34, "tv": 33890.9, "trd": NaN, "batb": NaN, "batl": [[0, 2.34, 1948.77], [1, 2.36, 1072.34]]}, {"timestamp": 1578771543965, "ltp": 2.34, "tv": 33890.9, "trd": NaN, "batb": NaN, "batl": [[0, 2.34, 1822.86]]}, {"timestamp": 1578771546992, "ltp": 2.34, "tv": 33890.9, "trd": NaN, "batb": [[2, 2.28, 674.43]], "batl": NaN}, {"timestamp": 1578771552973, "ltp": 2.32, "tv": 34290.9, "trd": [[2.32, 7962.87]], "batb": [[0, 2.32, 1343.73]], "batl": NaN}, {"timestamp": 1578771563977, "ltp": 2.32, "tv": 34324.18, "trd": [[2.32, 7996.15]], "batb": [[0, 2.32, 1327.09], [2, 2.28, 284.02]], "batl": NaN}, {"timestamp": 1578771564978, "ltp": 2.32, "tv": 34677.59, "trd": [[2.32, 8349.55]], "batb": [[0, 2.32, 1150.39]], "batl": [[0, 2.34, 1763.44]]}, {"timestamp": 1578771565976, "ltp": 2.32, "tv": 34677.59, "trd": NaN, "batb": [[0, 2.32, 1047.77], [2, 2.28, 794.68]], "batl": NaN}, {"timestamp": 1578771566981, "ltp": 2.32, "tv": 34677.59, "trd": NaN, "batb": [[0, 2.32, 1082.98], [2, 2.28, 404.27]], "batl": [[2, 2.38, 326.03]]}, {"timestamp": 1578771567986, "ltp": 2.32, "tv": 34677.59, "trd": NaN, "batb": [[2, 2.28, 794.68]], "batl": [[0, 2.34, 1813.44]]}, {"timestamp": 1578771568987, "ltp": 2.32, "tv": 34677.59, "trd": NaN, "batb": [[0, 2.32, 1152.22]], "batl": NaN}, {"timestamp": 1578771572004, "ltp": 2.32, "tv": 34677.59, "trd": NaN, "batb": [[2, 2.28, 404.27]], "batl": NaN}, {"timestamp": 1578771573013, "ltp": 2.32, "tv": 34677.59, "trd": NaN, "batb": [[0, 2.32, 1129.97]], "batl": [[1, 2.36, 2541.06], [2, 2.38, 1876.72]]}, {"timestamp": 1578771573967, "ltp": 2.32, "tv": 34677.59, "trd": NaN, "batb": [[0, 2.32, 1190.5]], "batl": NaN}, {"timestamp": 1578771574971, "ltp": 2.32, "tv": 34677.59, "trd": NaN, "batb": [[0, 2.32, 1187.5], [1, 2.3, 501.92]], "batl": NaN}, {"timestamp": 1578771584977, "ltp": 2.32, "tv": 34680.99, "trd": [[2.32, 8352.96]], "batb": [[0, 2.32, 1185.8]], "batl": [[0, 2.34, 1827.11]]}, {"timestamp": 1578771589004, "ltp": 2.32, "tv": 34680.99, "trd": NaN, "batb": NaN, "batl": [[0, 2.34, 1828.81], [1, 2.36, 1072.34], [2, 2.38, 326.03]]}, {"timestamp": 1578771592027, "ltp": 2.32, "tv": 34680.99, "trd": NaN, "batb": [[0, 2.32, 1125.49]], "batl": NaN}, {"timestamp": 1578771593008, "ltp": 2.32, "tv": 34680.99, "trd": NaN, "batb": [[0, 2.32, 1007.04]], "batl": NaN}, {"timestamp": 1578771593910, "ltp": 2.32, "tv": 34680.99, "trd": NaN, "batb": NaN, "batl": [[0, 2.34, 1845.84]]}, {"timestamp": 1578771599017, "ltp": 2.32, "tv": 34680.99, "trd": NaN, "batb": NaN, "batl": [[0, 2.34, 1866.38], [1, 2.36, 1051.8]]}, {"timestamp": 1578771600017, "ltp": 2.32, "tv": 34680.99, "trd": NaN, "batb": [[2, 2.28, 492.27]], "batl": [[0, 2.34, 2095.98]]}, {"timestamp": 1578771601027, "ltp": 2.32, "tv": 34690.99, "trd": [[2.32, 8362.96]], "batb": [[0, 2.32, 1078.93], [1, 2.3, 562.27], [2, 2.28, 372.02]], "batl": [[0, 2.34, 1978.7], [1, 2.36, 872.17], [2, 2.38, 195.1]]}, {"timestamp": 1578771603027, "ltp": 2.32, "tv": 36845.94, "trd": [[2.32, 10509.59], [2.34, 11165.27]], "batb": [[0, 2.32, 5.62], [1, 2.3, 709.45]], "batl": [[0, 2.34, 1974.54]]}, {"timestamp": 1578771605856, "ltp": 2.32, "tv": 36857.18, "trd": [[2.32, 10520.82]], "batb": [[0, 2.3, 709.45], [1, 2.28, 372.02], [2, 2.26, 706.11]], "batl": [[0, 2.32, 5.86], [1, 2.34, 1987.36], [2, 2.36, 872.17]]}, {"timestamp": 1578771607046, "ltp": 2.32, "tv": 36868.45, "trd": [[2.32, 10532.09]], "batb": [[0, 2.3, 787.71], [1, 2.28, 370.02]], "batl": [[0, 2.34, 1987.59], [1, 2.36, 874.24], [2, 2.38, 195.1]]}, {"timestamp": 1578771608043, "ltp": 2.32, "tv": 36868.45, "trd": NaN, "batb": NaN, "batl": [[1, 2.36, 872.17]]}, {"timestamp": 1578771609053, "ltp": 2.32, "tv": 36868.91, "trd": [[2.32, 10532.55]], "batb": [[0, 2.32, 2.9], [1, 2.3, 787.71], [2, 2.28, 370.02]], "batl": [[0, 2.34, 1987.36]]}, {"timestamp": 1578771610019, "ltp": 2.32, "tv": 36874.71, "trd": [[2.32, 10538.35]], "batb": [[0, 2.3, 787.71], [1, 2.28, 370.02], [2, 2.26, 706.11]], "batl": [[0, 2.32, 4.75], [1, 2.34, 1987.36], [2, 2.36, 874.24]]}, {"timestamp": 1578771611027, "ltp": 2.32, "tv": 36874.71, "trd": NaN, "batb": [[0, 2.3, 978.28]], "batl": NaN}, {"timestamp": 1578771612023, "ltp": 2.32, "tv": 36874.71, "trd": NaN, "batb": NaN, "batl": [[0, 2.32, 25.29], [1, 2.34, 1966.82]]}, {"timestamp": 1578771613025, "ltp": 2.3, "tv": 36902.05, "trd": [[2.3, 833.3]], "batb": [[0, 2.3, 964.61]], "batl": [[1, 2.34, 1953.15]]}, {"timestamp": 1578771614040, "ltp": 2.3, "tv": 36902.05, "trd": NaN, "batb": NaN, "batl": [[0, 2.32, 26.2]]}, {"timestamp": 1578771619968, "ltp": 2.32, "tv": 36954.46, "trd": [[2.32, 10590.75]], "batb": [[0, 2.32, 106.65], [1, 2.3, 964.61], [2, 2.28, 372.18]], "batl": [[0, 2.34, 1953.15], [1, 2.36, 872.17], [2, 2.38, 195.1]]}, {"timestamp": 1578771621039, "ltp": 2.32, "tv": 36954.46, "trd": NaN, "batb": [[1, 2.3, 1105.72]], "batl": NaN}, {"timestamp": 1578771623052, "ltp": 2.32, "tv": 36954.46, "trd": NaN, "batb": [[1, 2.3, 1243.27]], "batl": [[0, 2.34, 1963.86]]}, {"timestamp": 1578771629981, "ltp": 2.32, "tv": 36964.46, "trd": [[2.32, 10600.75]], "batb": [[0, 2.32, 101.65]], "batl": [[1, 2.36, 882.17]]}, {"timestamp": 1578771631000, "ltp": 2.32, "tv": 36972.12, "trd": [[2.32, 10608.41]], "batb": [[0, 2.32, 97.82], [1, 2.3, 1321.24]], "batl": NaN}, {"timestamp": 1578771632961, "ltp": 2.32, "tv": 36987.42, "trd": [[2.32, 10623.72]], "batb": [[0, 2.32, 90.17]], "batl": NaN}, {"timestamp": 1578771633863, "ltp": 2.32, "tv": 37177.59, "trd": [[2.32, 10813.89]], "batb": [[0, 2.3, 1255.34], [1, 2.28, 370.02], [2, 2.26, 2425.84]], "batl": NaN}, {"timestamp": 1578771634875, "ltp": 2.32, "tv": 37177.59, "trd": NaN, "batb": [[0, 2.3, 1196.31], [1, 2.28, 372.18], [2, 2.26, 2425.68]], "batl": NaN}, {"timestamp": 1578771639988, "ltp": 2.34, "tv": 37207.59, "trd": [[2.34, 11195.27]], "batb": [[0, 2.3, 1161.02]], "batl": [[0, 2.34, 1948.87]]}, {"timestamp": 1578771640995, "ltp": 2.32, "tv": 37307.59, "trd": [[2.32, 10913.89]], "batb": NaN, "batl": [[0, 2.34, 1962.87]]}, {"timestamp": 1578771642006, "ltp": 2.32, "tv": 37307.59, "trd": NaN, "batb": NaN, "batl": [[0, 2.34, 1978.17]]}, {"timestamp": 1578771648979, "ltp": 2.32, "tv": 37310.99, "trd": [[2.32, 10917.29]], "batb": [[2, 2.26, 2423.63]], "batl": NaN}, {"timestamp": 1578771649987, "ltp": 2.32, "tv": 37310.99, "trd": NaN, "batb": [[2, 2.26, 2425.8]], "batl": NaN}, {"timestamp": 1578771654003, "ltp": 2.32, "tv": 37310.99, "trd": NaN, "batb": [[0, 2.3, 1110.61]], "batl": NaN}, {"timestamp": 1578771655010, "ltp": 2.32, "tv": 37310.99, "trd": NaN, "batb": [[2, 2.26, 2425.84]], "batl": NaN}, {"timestamp": 1578771662024, "ltp": 2.32, "tv": 37327.55, "trd": [[2.32, 10933.85]], "batb": [[2, 2.26, 2423.63]], "batl": NaN}, {"timestamp": 1578771663014, "ltp": 2.32, "tv": 37327.55, "trd": NaN, "batb": [[2, 2.26, 2425.8]], "batl": [[0, 2.34, 1979.02]]}, {"timestamp": 1578771663990, "ltp": 2.32, "tv": 37327.55, "trd": NaN, "batb": NaN, "batl": [[0, 2.34, 1982.43]]}, {"timestamp": 1578771665002, "ltp": 2.32, "tv": 37327.55, "trd": NaN, "batb": NaN, "batl": [[0, 2.34, 2356.15], [1, 2.36, 508.45]]}, {"timestamp": 1578771670041, "ltp": 2.32, "tv": 37331.43, "trd": [[2.32, 10937.73]], "batb": [[2, 2.26, 2425.63]], "batl": NaN}, {"timestamp": 1578771670946, "ltp": 2.32, "tv": 37331.43, "trd": NaN, "batb": [[0, 2.32, 1276.81], [1, 2.3, 1114.01], [2, 2.28, 372.18]], "batl": NaN}, {"timestamp": 1578771672032, "ltp": 2.32, "tv": 37331.72, "trd": [[2.32, 10938.02]], "batb": [[0, 2.32, 1553.58]], "batl": NaN}, {"timestamp": 1578771672920, "ltp": 2.32, "tv": 37331.72, "trd": NaN, "batb": [[0, 2.32, 1916.58]], "batl": NaN}, {"timestamp": 1578771676985, "ltp": 2.32, "tv": 37341.72, "trd": [[2.32, 10948.02]], "batb": [[0, 2.32, 1911.58]], "batl": NaN}, {"timestamp": 1578771678999, "ltp": 2.32, "tv": 37343.25, "trd": [[2.32, 10949.55]], "batb": [[0, 2.32, 1547.82]], "batl": [[0, 2.34, 2359.55]]}, {"timestamp": 1578771681016, "ltp": 2.32, "tv": 37370.8, "trd": [[2.32, 10977.1]], "batb": [[0, 2.32, 1534.04]], "batl": [[0, 2.34, 2362.96]]}, {"timestamp": 1578771683987, "ltp": 2.32, "tv": 37370.8, "trd": NaN, "batb": [[0, 2.32, 1537.04], [1, 2.3, 1111.01]], "batl": NaN}, {"timestamp": 1578771685915, "ltp": 2.32, "tv": 37370.8, "trd": NaN, "batb": [[0, 2.32, 1564.55]], "batl": NaN}, {"timestamp": 1578771688994, "ltp": 2.32, "tv": 37370.8, "trd": NaN, "batb": NaN, "batl": [[0, 2.34, 2400.33]]}, {"timestamp": 1578771694031, "ltp": 2.32, "tv": 37370.8, "trd": NaN, "batb": NaN, "batl": [[0, 2.34, 2477.25], [1, 2.36, 2161.14], [2, 2.38, 1866.57]]}, {"timestamp": 1578771696041, "ltp": 2.32, "tv": 37370.8, "trd": NaN, "batb": [[2, 2.28, 284.18]], "batl": [[2, 2.38, 1950.57]]}, {"timestamp": 1578771699023, "ltp": 2.32, "tv": 37375.9, "trd": [[2.32, 10982.2]], "batb": [[0, 2.32, 1562]], "batl": [[1, 2.36, 2131.57]]}, {"timestamp": 1578771702019, "ltp": 2.32, "tv": 37377.1, "trd": [[2.32, 10983.4]], "batb": [[0, 2.32, 1561.4]], "batl": NaN}, {"timestamp": 1578771704035, "ltp": 2.32, "tv": 37377.1, "trd": NaN, "batb": NaN, "batl": [[1, 2.36, 478.88], [2, 2.38, 195.1]]}, {"timestamp": 1578771705039, "ltp": 2.32, "tv": 37385.15, "trd": [[2.32, 10991.45]], "batb": [[0, 2.32, 1557.37]], "batl": [[0, 2.34, 2400.33]]}, {"timestamp": 1578771706036, "ltp": 2.32, "tv": 37385.15, "trd": NaN, "batb": [[2, 2.28, 674.59]], "batl": NaN}, {"timestamp": 1578771708954, "ltp": 2.32, "tv": 37388.89, "trd": [[2.32, 10995.19]], "batb": [[0, 2.32, 1555.5], [1, 2.3, 1171.71]], "batl": NaN}, {"timestamp": 1578771713029, "ltp": 2.32, "tv": 37388.89, "trd": NaN, "batb": NaN, "batl": [[1, 2.36, 468.88]]}, {"timestamp": 1578771718953, "ltp": 2.32, "tv": 37388.89, "trd": NaN, "batb": [[2, 2.28, 284.18]], "batl": NaN}, {"timestamp": 1578771719954, "ltp": 2.32, "tv": 37463.63, "trd": [[2.32, 11069.93]], "batb": [[0, 2.32, 1518.13]], "batl": [[0, 2.34, 2362.96]]}, {"timestamp": 1578771723973, "ltp": 2.32, "tv": 37463.96, "trd": [[2.32, 11070.26]], "batb": [[0, 2.32, 1517.97]], "batl": [[1, 2.36, 105.02]]}, {"timestamp": 1578771724980, "ltp": 2.32, "tv": 37463.96, "trd": NaN, "batb": NaN, "batl": [[0, 2.34, 2364.96]]}, {"timestamp": 1578771727049, "ltp": 2.32, "tv": 37479.26, "trd": [[2.32, 11085.56]], "batb": [[0, 2.32, 1510.32]], "batl": [[2, 2.38, 279.1]]}, {"timestamp": 1578771727954, "ltp": 2.32, "tv": 37486.07, "trd": [[2.32, 11092.37]], "batb": [[0, 2.32, 1506.91]], "batl": [[1, 2.36, 30.02]]}, {"timestamp": 1578771728967, "ltp": 2.32, "tv": 37506.07, "trd": [[2.32, 11112.37]], "batb": [[0, 2.32, 1496.91]], "batl": NaN}, {"timestamp": 1578771735982, "ltp": 2.34, "tv": 37509.47, "trd": [[2.34, 11198.67]], "batb": NaN, "batl": [[0, 2.34, 2363.26]]}, {"timestamp": 1578771738989, "ltp": 2.32, "tv": 37659.47, "trd": [[2.32, 11262.37]], "batb": [[0, 2.32, 1421.91]], "batl": NaN}, {"timestamp": 1578771740993, "ltp": 2.32, "tv": 37659.47, "trd": NaN, "batb": [[0, 2.32, 1541.88]], "batl": NaN}, {"timestamp": 1578771745970, "ltp": 2.32, "tv": 37663.01, "trd": [[2.32, 11265.91]], "batb": [[0, 2.32, 1540.11]], "batl": NaN}, {"timestamp": 1578771750982, "ltp": 2.32, "tv": 37663.01, "trd": NaN, "batb": [[1, 2.3, 999.72]], "batl": NaN}, {"timestamp": 1578771751822, "ltp": 2.32, "tv": 37663.01, "trd": NaN, "batb": [[0, 2.32, 1600.28], [1, 2.3, 792.15]], "batl": NaN}, {"timestamp": 1578771753986, "ltp": 2.32, "tv": 37695.02, "trd": [[2.32, 11297.92]], "batb": [[0, 2.32, 1584.28]], "batl": NaN}, {"timestamp": 1578771755989, "ltp": 2.32, "tv": 37707.6, "trd": [[2.32, 11310.5]], "batb": [[0, 2.32, 1577.99]], "batl": NaN}, {"timestamp": 1578771759013, "ltp": 2.32, "tv": 37707.6, "trd": NaN, "batb": NaN, "batl": [[2, 2.38, 311.1]]}, {"timestamp": 1578771761012, "ltp": 2.32, "tv": 37707.6, "trd": NaN, "batb": NaN, "batl": [[1, 2.36, 62.02]]}, {"timestamp": 1578771762019, "ltp": 2.32, "tv": 37737.6, "trd": [[2.32, 11340.5]], "batb": [[0, 2.32, 1562.99]], "batl": NaN}, {"timestamp": 1578771764031, "ltp": 2.32, "tv": 37737.6, "trd": NaN, "batb": NaN, "batl": [[1, 2.36, 30.02], [2, 2.38, 279.1]]}, {"timestamp": 1578771765029, "ltp": 2.32, "tv": 37759.03, "trd": [[2.32, 11361.93]], "batb": [[0, 2.32, 1552.27]], "batl": [[0, 2.34, 2352.54]]}, {"timestamp": 1578771774028, "ltp": 2.32, "tv": 37789.64, "trd": [[2.32, 11392.54]], "batb": [[0, 2.32, 1536.97]], "batl": NaN}, {"timestamp": 1578771775032, "ltp": 2.32, "tv": 37805.88, "trd": [[2.32, 11408.78]], "batb": [[0, 2.32, 1528.85]], "batl": NaN}, {"timestamp": 1578771781022, "ltp": 2.32, "tv": 37805.88, "trd": NaN, "batb": NaN, "batl": [[0, 2.34, 2237.74]]}, {"timestamp": 1578771784953, "ltp": 2.32, "tv": 37805.88, "trd": NaN, "batb": [[2, 2.28, 305.08]], "batl": NaN}, {"timestamp": 1578771789047, "ltp": 2.32, "tv": 37805.88, "trd": NaN, "batb": [[0, 2.32, 1348.71]], "batl": NaN}, {"timestamp": 1578771790971, "ltp": 2.32, "tv": 37805.88, "trd": NaN, "batb": [[0, 2.32, 1071.8]], "batl": NaN}, {"timestamp": 1578771794042, "ltp": 2.32, "tv": 38693.22, "trd": [[2.32, 12296.12]], "batb": [[0, 2.32, 628.13]], "batl": [[0, 2.34, 2302.01]]}, {"timestamp": 1578771794953, "ltp": 2.32, "tv": 39949.44, "trd": [[2.32, 13552.34]], "batb": [[0, 2.3, 792.17], [1, 2.28, 302.92], [2, 2.26, 1857.54]], "batl": NaN}, {"timestamp": 1578771796055, "ltp": 2.32, "tv": 39949.44, "trd": NaN, "batb": [[0, 2.3, 761.44]], "batl": NaN}, {"timestamp": 1578771797048, "ltp": 2.32, "tv": 39949.48, "trd": [[2.32, 13552.38]], "batb": [[0, 2.3, 761.41]], "batl": [[0, 2.32, 190.55], [1, 2.34, 2302.01], [2, 2.36, 32.09]]}, {"timestamp": 1578771797953, "ltp": 2.32, "tv": 39949.48, "trd": NaN, "batb": [[0, 2.3, 676.11], [1, 2.28, 272.91]], "batl": NaN}, {"timestamp": 1578771799970, "ltp": 2.32, "tv": 39956.18, "trd": [[2.32, 13559.08]], "batb": NaN, "batl": [[0, 2.32, 187.2]]}, {"timestamp": 1578771802951, "ltp": 2.32, "tv": 39956.18, "trd": NaN, "batb": [[0, 2.3, 519.54]], "batl": NaN}, {"timestamp": 1578771806980, "ltp": 2.3, "tv": 41155.78, "trd": [[2.3, 2032.89]], "batb": [[0, 2.28, 479.79], [1, 2.26, 1855.33], [2, 2.24, 3571.94]], "batl": [[0, 2.3, 677.02], [1, 2.32, 187.2], [2, 2.34, 1027.45]]}, {"timestamp": 1578771807992, "ltp": 2.3, "tv": 41155.78, "trd": NaN, "batb": [[0, 2.28, 428.53]], "batl": NaN}, {"timestamp": 1578771809951, "ltp": 2.3, "tv": 41155.78, "trd": NaN, "batb": NaN, "batl": [[2, 2.34, 1063.12]]}, {"timestamp": 1578771810952, "ltp": 2.3, "tv": 41734.94, "trd": [[2.3, 2612.05]], "batb": [[0, 2.28, 549.26]], "batl": [[0, 2.3, 387.44], [1, 2.32, 189.49]]}, {"timestamp": 1578771812011, "ltp": 2.3, "tv": 41734.94, "trd": NaN, "batb": [[0, 2.28, 379.02]], "batl": NaN}, {"timestamp": 1578771815000, "ltp": 2.3, "tv": 41734.94, "trd": NaN, "batb": NaN, "batl": [[0, 2.3, 393.98]]}, {"timestamp": 1578771816878, "ltp": 2.3, "tv": 42044.3, "trd": [[2.3, 2921.41]], "batb": NaN, "batl": [[0, 2.3, 239.29], [2, 2.34, 1059.72]]}, {"timestamp": 1578771818987, "ltp": 2.3, "tv": 42044.3, "trd": NaN, "batb": NaN, "batl": [[0, 2.3, 242.7]]}, {"timestamp": 1578771819998, "ltp": 2.28, "tv": 42048.89, "trd": [[2.28, 4.59]], "batb": [[0, 2.28, 376.72]], "batl": [[1, 2.32, 187.2]]}, {"timestamp": 1578771826009, "ltp": 2.3, "tv": 42103.45, "trd": [[2.3, 2975.98]], "batb": NaN, "batl": [[0, 2.3, 188.14]]}, {"timestamp": 1578771828014, "ltp": 2.3, "tv": 42116.83, "trd": [[2.3, 2989.36]], "batb": NaN, "batl": [[0, 2.3, 181.45]]}, {"timestamp": 1578771829016, "ltp": 2.3, "tv": 42253.03, "trd": [[2.3, 3125.55]], "batb": [[0, 2.28, 539.8]], "batl": [[0, 2.3, 113.35], [2, 2.34, 995.45]]}, {"timestamp": 1578771830023, "ltp": 2.3, "tv": 42287.07, "trd": [[2.3, 3159.6]], "batb": NaN, "batl": [[0, 2.3, 96.33]]}, {"timestamp": 1578771833014, "ltp": 2.3, "tv": 42339.49, "trd": [[2.3, 3212.01]], "batb": NaN, "batl": [[0, 2.3, 70.12]]}, {"timestamp": 1578771835017, "ltp": 2.3, "tv": 42479.72, "trd": [[2.3, 3352.25]], "batb": [[0, 2.3, 83.04], [1, 2.28, 491.76], [2, 2.26, 1857.38]], "batl": [[0, 2.32, 187.2], [1, 2.34, 993.2], [2, 2.36, 32.09]]}, {"timestamp": 1578771836044, "ltp": 2.3, "tv": 42713.96, "trd": [[2.3, 3586.48]], "batb": [[0, 2.28, 491.76], [1, 2.26, 1855.33], [2, 2.24, 3571.94]], "batl": [[0, 2.3, 632.88], [1, 2.32, 187.2], [2, 2.34, 959.77]]}, {"timestamp": 1578771838004, "ltp": 2.3, "tv": 42713.96, "trd": NaN, "batb": NaN, "batl": [[2, 2.34, 991.77]]}, {"timestamp": 1578771839024, "ltp": 2.3, "tv": 43070.62, "trd": [[2.3, 3943.14]], "batb": NaN, "batl": [[0, 2.3, 454.55]]}, {"timestamp": 1578771840022, "ltp": 2.3, "tv": 43210.81, "trd": [[2.28, 8.59], [2.3, 4079.34]], "batb": [[0, 2.28, 489.76]], "batl": [[0, 2.3, 386.45], [1, 2.32, 219.2]]}, {"timestamp": 1578771841034, "ltp": 2.3, "tv": 43210.81, "trd": NaN, "batb": NaN, "batl": [[2, 2.34, 953.07]]}, {"timestamp": 1578771842039, "ltp": 2.28, "tv": 43295.37, "trd": [[2.28, 88.59], [2.3, 4083.9]], "batb": [[0, 2.28, 449.76]], "batl": [[0, 2.3, 422.87]]}, {"timestamp": 1578771843050, "ltp": 2.28, "tv": 43315.37, "trd": [[2.28, 108.59]], "batb": [[0, 2.28, 439.76]], "batl": NaN}, {"timestamp": 1578771845025, "ltp": 2.28, "tv": 43315.37, "trd": NaN, "batb": NaN, "batl": [[2, 2.34, 949.67]]}, {"timestamp": 1578771847029, "ltp": 2.28, "tv": 43315.37, "trd": NaN, "batb": NaN, "batl": [[1, 2.32, 222.6]]}, {"timestamp": 1578771850947, "ltp": 2.28, "tv": 43349.42, "trd": [[2.28, 142.64]], "batb": [[0, 2.28, 422.74]], "batl": NaN}, {"timestamp": 1578771852014, "ltp": 2.28, "tv": 43358.04, "trd": [[2.28, 151.26]], "batb": [[0, 2.28, 418.43], [2, 2.24, 1913.6]], "batl": NaN}, {"timestamp": 1578771853016, "ltp": 2.28, "tv": 43366.66, "trd": [[2.28, 159.87]], "batb": [[0, 2.28, 414.12]], "batl": [[2, 2.34, 1014.84]]}, {"timestamp": 1578771853957, "ltp": 2.28, "tv": 43444.06, "trd": [[2.28, 237.28]], "batb": [[0, 2.28, 375.42]], "batl": [[0, 2.3, 384.17]]}, {"timestamp": 1578771854860, "ltp": 2.28, "tv": 43444.06, "trd": NaN, "batb": NaN, "batl": [[1, 2.32, 226.01], [2, 2.34, 1011.43]]}, {"timestamp": 1578771857927, "ltp": 2.28, "tv": 43459.38, "trd": [[2.28, 252.6]], "batb": [[0, 2.28, 367.76]], "batl": NaN}, {"timestamp": 1578771860953, "ltp": 2.3, "tv": 43470.8, "trd": [[2.3, 4095.32]], "batb": NaN, "batl": [[0, 2.3, 378.46]]}, {"timestamp": 1578771861967, "ltp": 2.28, "tv": 43501.42, "trd": [[2.28, 283.21]], "batb": [[0, 2.28, 352.45]], "batl": NaN}, {"timestamp": 1578771863963, "ltp": 2.28, "tv": 43576.16, "trd": [[2.28, 357.96]], "batb": [[0, 2.28, 315.08]], "batl": [[1, 2.32, 194.01], [2, 2.34, 947.43]]}, {"timestamp": 1578771869040, "ltp": 2.28, "tv": 43676.16, "trd": [[2.28, 457.96]], "batb": [[0, 2.28, 265.08]], "batl": NaN}, {"timestamp": 1578771873994, "ltp": 2.28, "tv": 43676.16, "trd": NaN, "batb": [[0, 2.28, 1236.22]], "batl": [[2, 2.34, 933.43]]}, {"timestamp": 1578771878981, "ltp": 2.28, "tv": 43676.16, "trd": NaN, "batb": NaN, "batl": [[2, 2.34, 2573.47]]}, {"timestamp": 1578771880972, "ltp": 2.28, "tv": 43713.54, "trd": [[2.28, 495.33]], "batb": [[0, 2.28, 1217.53]], "batl": NaN}, {"timestamp": 1578771883005, "ltp": 2.3, "tv": 44519.78, "trd": [[2.3, 4901.56]], "batb": [[0, 2.3, 543.36], [1, 2.28, 246.39], [2, 2.26, 1855.33]], "batl": [[0, 2.32, 194.01], [1, 2.34, 2573.47], [2, 2.36, 1374.83]]}, {"timestamp": 1578771883992, "ltp": 2.3, "tv": 44545.31, "trd": [[2.3, 4927.1]], "batb": [[0, 2.3, 530.59], [2, 2.26, 1857.54]], "batl": [[1, 2.34, 2571.22]]}, {"timestamp": 1578771884886, "ltp": 2.3, "tv": 44594.43, "trd": [[2.3, 4976.22]], "batb": [[0, 2.3, 506.03]], "batl": NaN}, {"timestamp": 1578771885978, "ltp": 2.3, "tv": 45063.36, "trd": [[2.3, 5445.14]], "batb": [[0, 2.3, 248.31]], "batl": [[1, 2.34, 2379.7]]}, {"timestamp": 1578771888969, "ltp": 2.3, "tv": 45216.42, "trd": [[2.3, 5598.21]], "batb": [[0, 2.3, 171.78]], "batl": NaN}, {"timestamp": 1578771889968, "ltp": 2.3, "tv": 45220.42, "trd": [[2.3, 5602.21]], "batb": [[0, 2.3, 169.78]], "batl": [[2, 2.36, 1459.83]]}, {"timestamp": 1578771894995, "ltp": 2.3, "tv": 45272.12, "trd": [[2.3, 5653.91]], "batb": [[0, 2.3, 143.93]], "batl": NaN}, {"timestamp": 1578771897000, "ltp": 2.3, "tv": 45336.86, "trd": [[2.3, 5718.65]], "batb": [[0, 2.3, 111.56], [1, 2.28, 279.04]], "batl": NaN}, {"timestamp": 1578771898013, "ltp": 2.3, "tv": 45411.96, "trd": [[2.3, 5793.75]], "batb": [[0, 2.3, 74.01]], "batl": NaN}, {"timestamp": 1578771899007, "ltp": 2.3, "tv": 45451.06, "trd": [[2.3, 5832.85]], "batb": [[0, 2.3, 54.46]], "batl": NaN}, {"timestamp": 1578771900005, "ltp": 2.32, "tv": 45451.35, "trd": [[2.32, 13559.37]], "batb": NaN, "batl": [[0, 2.32, 193.86], [1, 2.34, 2362.68], [2, 2.36, 1442.81]]}, {"timestamp": 1578771901017, "ltp": 2.3, "tv": 45510.92, "trd": [[2.3, 5892.42]], "batb": [[0, 2.28, 279.04], [1, 2.26, 1855.33], [2, 2.24, 1824.6]], "batl": [[1, 2.34, 722.64], [2, 2.36, 100.07]]}, {"timestamp": 1578771904978, "ltp": 2.28, "tv": 45612.96, "trd": [[2.28, 597.37]], "batb": [[0, 2.28, 228.02]], "batl": [[1, 2.34, 807.64]]}, {"timestamp": 1578771905982, "ltp": 2.28, "tv": 45616.97, "trd": [[2.28, 601.37]], "batb": [[0, 2.28, 226.01]], "batl": NaN}, {"timestamp": 1578771909040, "ltp": 2.28, "tv": 45616.97, "trd": NaN, "batb": [[0, 2.28, 251.23]], "batl": NaN}, {"timestamp": 1578771912051, "ltp": 2.28, "tv": 45616.97, "trd": NaN, "batb": NaN, "batl": [[0, 2.3, 6.49], [1, 2.32, 599.95], [2, 2.34, 435.94]]}, {"timestamp": 1578771914056, "ltp": 2.3, "tv": 45627.52, "trd": [[2.3, 5902.97]], "batb": NaN, "batl": [[0, 2.3, 1.21]]}, {"timestamp": 1578771915056, "ltp": 2.3, "tv": 45627.52, "trd": NaN, "batb": NaN, "batl": [[0, 2.3, 26.21]]}, {"timestamp": 1578771918947, "ltp": 2.3, "tv": 45627.52, "trd": NaN, "batb": [[1, 2.26, 1943.33], [2, 2.24, 1913.6]], "batl": [[2, 2.34, 349.23]]}, {"timestamp": 1578771921053, "ltp": 2.3, "tv": 45635.17, "trd": [[2.3, 5910.62]], "batb": NaN, "batl": [[0, 2.3, 107.51]]}, {"timestamp": 1578771921957, "ltp": 2.3, "tv": 45635.17, "trd": NaN, "batb": [[1, 2.26, 1855.33], [2, 2.24, 1824.6]], "batl": [[2, 2.34, 434.23]]}, {"timestamp": 1578771923056, "ltp": 2.3, "tv": 45635.17, "trd": NaN, "batb": [[0, 2.28, 252.94]], "batl": NaN}, {"timestamp": 1578771924053, "ltp": 2.3, "tv": 45635.17, "trd": NaN, "batb": [[1, 2.26, 1943.33], [2, 2.24, 1913.6]], "batl": [[2, 2.34, 349.23]]}, {"timestamp": 1578771927047, "ltp": 2.3, "tv": 45635.17, "trd": NaN, "batb": [[1, 2.26, 1855.33], [2, 2.24, 1824.6]], "batl": [[2, 2.34, 434.23]]}, {"timestamp": 1578771931038, "ltp": 2.3, "tv": 45635.17, "trd": NaN, "batb": NaN, "batl": [[0, 2.3, 307.51]]}, {"timestamp": 1578771931968, "ltp": 2.28, "tv": 45743.35, "trd": [[2.28, 701.37], [2.3, 5918.8]], "batb": [[0, 2.28, 202.94]], "batl": [[0, 2.3, 299.33]]}, {"timestamp": 1578771934054, "ltp": 2.32, "tv": 46642.63, "trd": [[2.3, 6218.13], [2.32, 14159.32]], "batb": [[0, 2.3, 39.46], [1, 2.28, 202.94], [2, 2.26, 1857.34]], "batl": [[0, 2.34, 432.21], [1, 2.36, 98], [2, 2.38, 275.1]]}, {"timestamp": 1578771934947, "ltp": 2.34, "tv": 47413.12, "trd": [[2.34, 11969.17]], "batb": NaN, "batl": [[0, 2.34, 46.97]]}, {"timestamp": 1578771936034, "ltp": 2.34, "tv": 47413.12, "trd": NaN, "batb": [[0, 2.3, 420.6]], "batl": NaN}, {"timestamp": 1578771936979, "ltp": 2.34, "tv": 47413.12, "trd": NaN, "batb": [[0, 2.32, 381.14], [1, 2.3, 444.99], [2, 2.28, 202.94]], "batl": NaN}, {"timestamp": 1578771937978, "ltp": 2.34, "tv": 47413.12, "trd": NaN, "batb": [[2, 2.28, 239.59]], "batl": NaN}, {"timestamp": 1578771938976, "ltp": 2.34, "tv": 47413.12, "trd": NaN, "batb": [[1, 2.3, 768.45]], "batl": NaN}, {"timestamp": 1578771940978, "ltp": 2.32, "tv": 47513.12, "trd": [[2.32, 14259.32]], "batb": [[0, 2.32, 344.07], [1, 2.3, 362.92]], "batl": NaN}, {"timestamp": 1578771943974, "ltp": 2.32, "tv": 47513.12, "trd": NaN, "batb": [[0, 2.32, 534.64]], "batl": NaN}, {"timestamp": 1578771944974, "ltp": 2.32, "tv": 47513.12, "trd": NaN, "batb": [[0, 2.32, 662.32]], "batl": NaN}, {"timestamp": 1578771946770, "ltp": 2.32, "tv": 47513.12, "trd": NaN, "batb": NaN, "batl": [[0, 2.34, 50.37]]}, {"timestamp": 1578771947976, "ltp": 2.36, "tv": 47619.31, "trd": [[2.34, 12069.92], [2.36, 7888.93]], "batb": NaN, "batl": [[0, 2.36, 95.28], [1, 2.38, 275.1], [2, 2.4, 146.75]]}, {"timestamp": 1578771948980, "ltp": 2.36, "tv": 47619.31, "trd": NaN, "batb": [[0, 2.32, 665.73]], "batl": [[1, 2.38, 273.06]]}, {"timestamp": 1578771951964, "ltp": 2.36, "tv": 47619.31, "trd": NaN, "batb": NaN, "batl": [[0, 2.34, 50], [1, 2.36, 10.28], [2, 2.38, 191.08]]}, {"timestamp": 1578771952954, "ltp": 2.32, "tv": 47719.31, "trd": [[2.32, 14359.32]], "batb": [[0, 2.32, 615.73]], "batl": NaN}, {"timestamp": 1578771955995, "ltp": 2.32, "tv": 47724.91, "trd": [[2.32, 14364.93]], "batb": [[0, 2.32, 612.93]], "batl": NaN}, {"timestamp": 1578771956988, "ltp": 2.32, "tv": 47741.75, "trd": [[2.32, 14381.77]], "batb": [[0, 2.32, 604.51]], "batl": NaN}, {"timestamp": 1578771959984, "ltp": 2.32, "tv": 47741.75, "trd": NaN, "batb": [[2, 2.28, 439.59]], "batl": NaN}, {"timestamp": 1578771961992, "ltp": 2.32, "tv": 47741.75, "trd": NaN, "batb": [[2, 2.28, 437.43]], "batl": [[2, 2.38, 189.06]]}, {"timestamp": 1578771963003, "ltp": 2.32, "tv": 48875.76, "trd": [[2.32, 15515.77]], "batb": [[0, 2.3, 362.92], [1, 2.28, 437.43], [2, 2.26, 1968.33]], "batl": [[0, 2.32, 37.36], [1, 2.34, 50], [2, 2.36, 10.28]]}, {"timestamp": 1578771963789, "ltp": 2.32, "tv": 48875.76, "trd": NaN, "batb": NaN, "batl": [[0, 2.34, 50], [1, 2.36, 10.28], [2, 2.38, 189.06]]}, {"timestamp": 1578771964991, "ltp": 2.32, "tv": 48875.76, "trd": NaN, "batb": NaN, "batl": [[0, 2.34, 55.4]]}, {"timestamp": 1578771965997, "ltp": 2.32, "tv": 48875.76, "trd": NaN, "batb": NaN, "batl": [[0, 2.32, 2.3], [1, 2.34, 55.4], [2, 2.36, 10.28]]}, {"timestamp": 1578771966992, "ltp": 2.32, "tv": 48875.76, "trd": NaN, "batb": [[1, 2.28, 911.81]], "batl": NaN}, {"timestamp": 1578771968985, "ltp": 2.32, "tv": 48880.18, "trd": [[2.32, 15520.2]], "batb": NaN, "batl": [[0, 2.34, 55.49], [1, 2.36, 10.28], [2, 2.38, 189.06]]}, {"timestamp": 1578771969980, "ltp": 2.34, "tv": 48880.41, "trd": [[2.32, 15520.36], [2.34, 12069.98]], "batb": NaN, "batl": [[0, 2.34, 55.37]]}, {"timestamp": 1578771971038, "ltp": 2.34, "tv": 48880.41, "trd": NaN, "batb": NaN, "batl": [[0, 2.32, 475.39], [1, 2.34, 55.37], [2, 2.36, 10.28]]}, {"timestamp": 1578771973012, "ltp": 2.34, "tv": 48880.41, "trd": NaN, "batb": [[1, 2.28, 877.32]], "batl": [[0, 2.32, 525.39]]}, {"timestamp": 1578771978023, "ltp": 2.34, "tv": 48880.41, "trd": NaN, "batb": [[2, 2.26, 1972.85]], "batl": [[1, 2.34, 60.37]]}, {"timestamp": 1578771979017, "ltp": 2.3, "tv": 48992.52, "trd": [[2.3, 6330.24]], "batb": [[0, 2.3, 306.86]], "batl": NaN}, {"timestamp": 1578771981014, "ltp": 2.3, "tv": 49000.18, "trd": [[2.3, 6337.9]], "batb": [[0, 2.3, 303.03]], "batl": [[0, 2.32, 528.8]]}, {"timestamp": 1578771982009, "ltp": 2.32, "tv": 49001.65, "trd": [[2.32, 15521.83]], "batb": [[0, 2.3, 1443.03]], "batl": [[0, 2.32, 528.06]]}, {"timestamp": 1578771983006, "ltp": 2.32, "tv": 49001.65, "trd": NaN, "batb": NaN, "batl": [[0, 2.32, 578.06]]}, {"timestamp": 1578771985000, "ltp": 2.3, "tv": 49003.4, "trd": [[2.3, 6339.65]], "batb": [[0, 2.3, 1442.15]], "batl": NaN}, {"timestamp": 1578771986003, "ltp": 2.3, "tv": 49103.4, "trd": [[2.3, 6439.65]], "batb": [[0, 2.3, 1392.15]], "batl": [[1, 2.34, 92.74]]}, {"timestamp": 1578771987048, "ltp": 2.3, "tv": 49103.4, "trd": NaN, "batb": NaN, "batl": [[0, 2.32, 610.43]]}, {"timestamp": 1578771988010, "ltp": 2.3, "tv": 49251.75, "trd": [[2.3, 6588]], "batb": [[0, 2.3, 1317.98]], "batl": NaN}, {"timestamp": 1578771990011, "ltp": 2.3, "tv": 49336.87, "trd": [[2.3, 6673.12]], "batb": [[0, 2.3, 1275.42]], "batl": NaN}, {"timestamp": 1578771992010, "ltp": 2.3, "tv": 49536.87, "trd": [[2.3, 6873.12]], "batb": [[0, 2.3, 1175.42]], "batl": NaN}, {"timestamp": 1578771992913, "ltp": 2.32, "tv": 50242.7, "trd": [[2.3, 7442.76], [2.32, 15658.03]], "batb": [[0, 2.3, 890.6], [1, 2.28, 4350.25]], "batl": [[0, 2.32, 257.51]]}, {"timestamp": 1578771994916, "ltp": 2.32, "tv": 50247.11, "trd": [[2.32, 15662.43]], "batb": [[1, 2.28, 4390.25]], "batl": [[0, 2.32, 255.31]]}, {"timestamp": 1578771996055, "ltp": 2.32, "tv": 50247.11, "trd": NaN, "batb": NaN, "batl": [[1, 2.34, 1876.4], [2, 2.36, 1901.76]]}, {"timestamp": 1578771997011, "ltp": 2.32, "tv": 50247.11, "trd": NaN, "batb": [[1, 2.28, 4422.6]], "batl": NaN}, {"timestamp": 1578772000021, "ltp": 2.32, "tv": 50247.11, "trd": NaN, "batb": NaN, "batl": [[0, 2.32, 205.31]]}, {"timestamp": 1578772002037, "ltp": 2.3, "tv": 50251.65, "trd": [[2.3, 7447.3]], "batb": [[0, 2.3, 888.33]], "batl": NaN}, {"timestamp": 1578772008046, "ltp": 2.32, "tv": 50447.72, "trd": [[2.3, 7493.22], [2.32, 15812.58]], "batb": [[0, 2.3, 865.37]], "batl": [[0, 2.32, 130.23]]}, {"timestamp": 1578772015962, "ltp": 2.3, "tv": 50534.24, "trd": [[2.3, 7579.75]], "batb": [[0, 2.3, 822.11]], "batl": NaN}, {"timestamp": 1578772017961, "ltp": 2.3, "tv": 50534.24, "trd": NaN, "batb": NaN, "batl": [[1, 2.34, 92.74], [2, 2.36, 10.28]]}, {"timestamp": 1578772019746, "ltp": 2.3, "tv": 50534.24, "trd": NaN, "batb": NaN, "batl": [[0, 2.32, 283.3]]}, {"timestamp": 1578772025855, "ltp": 2.3, "tv": 50625.38, "trd": [[2.3, 7670.89]], "batb": [[0, 2.3, 776.54]], "batl": NaN}, {"timestamp": 1578772026964, "ltp": 2.3, "tv": 50669.38, "trd": [[2.3, 7714.89]], "batb": [[0, 2.3, 754.54]], "batl": NaN}, {"timestamp": 1578772027968, "ltp": 2.32, "tv": 50800.41, "trd": [[2.32, 15943.61]], "batb": [[0, 2.3, 757.94]], "batl": [[0, 2.32, 217.79]]}, {"timestamp": 1578772028960, "ltp": 2.32, "tv": 50800.41, "trd": NaN, "batb": NaN, "batl": [[1, 2.34, 90.74]]}, {"timestamp": 1578772033042, "ltp": 2.32, "tv": 50800.41, "trd": NaN, "batb": NaN, "batl": [[0, 2.32, 263.71]]}, {"timestamp": 1578772033875, "ltp": 2.32, "tv": 50800.41, "trd": NaN, "batb": [[2, 2.26, 1884.85]], "batl": [[2, 2.36, 95.28]]}, {"timestamp": 1578772036034, "ltp": 2.32, "tv": 50926.21, "trd": [[2.32, 16069.41]], "batb": NaN, "batl": [[0, 2.32, 200.81]]}, {"timestamp": 1578772036977, "ltp": 2.32, "tv": 50926.21, "trd": NaN, "batb": [[0, 2.3, 788.76]], "batl": NaN}, {"timestamp": 1578772037977, "ltp": 2.32, "tv": 51451.06, "trd": [[2.32, 16594.25]], "batb": [[0, 2.32, 211.96], [1, 2.3, 788.76], [2, 2.28, 3948.21]], "batl": [[0, 2.34, 90.74], [1, 2.36, 95.28], [2, 2.38, 273.06]]}, {"timestamp": 1578772038998, "ltp": 2.32, "tv": 51491.23, "trd": [[2.32, 16634.43]], "batb": [[0, 2.32, 191.87], [1, 2.3, 790.6]], "batl": NaN}, {"timestamp": 1578772040047, "ltp": 2.32, "tv": 51491.23, "trd": NaN, "batb": [[2, 2.28, 3983.46]], "batl": NaN}, {"timestamp": 1578772040984, "ltp": 2.32, "tv": 51874.95, "trd": [[2.32, 17018.15]], "batb": [[0, 2.3, 790.61], [1, 2.28, 3983.46], [2, 2.26, 1931.98]], "batl": NaN}, {"timestamp": 1578772041979, "ltp": 2.3, "tv": 51879.89, "trd": [[2.3, 7719.8], [2.32, 17018.17]], "batb": [[0, 2.3, 788.14]], "batl": NaN}, {"timestamp": 1578772043971, "ltp": 2.3, "tv": 51907.83, "trd": [[2.3, 7747.75]], "batb": [[0, 2.3, 774.17]], "batl": NaN}, {"timestamp": 1578772045976, "ltp": 2.3, "tv": 51955.49, "trd": [[2.3, 7795.41]], "batb": [[0, 2.3, 750.34]], "batl": NaN}, {"timestamp": 1578772048962, "ltp": 2.3, "tv": 52705.84, "trd": [[2.3, 8545.75]], "batb": [[0, 2.28, 3983.46], [1, 2.26, 1931.98], [2, 2.24, 1822.58]], "batl": NaN}, {"timestamp": 1578772050001, "ltp": 2.3, "tv": 52705.84, "trd": NaN, "batb": [[0, 2.28, 3948.21]], "batl": NaN}, {"timestamp": 1578772051772, "ltp": 2.3, "tv": 52705.84, "trd": NaN, "batb": NaN, "batl": [[0, 2.32, 3.4], [1, 2.34, 90.74], [2, 2.36, 95.28]]}, {"timestamp": 1578772052865, "ltp": 2.3, "tv": 52705.84, "trd": NaN, "batb": [[0, 2.3, 900], [1, 2.28, 3948.21], [2, 2.26, 1931.98]], "batl": NaN}, {"timestamp": 1578772053858, "ltp": 2.3, "tv": 52706.62, "trd": [[2.3, 8546.53]], "batb": [[0, 2.3, 1089.79]], "batl": [[0, 2.32, 6.81]]}, {"timestamp": 1578772055998, "ltp": 2.3, "tv": 52706.62, "trd": NaN, "batb": [[2, 2.26, 1884.85]], "batl": NaN}, {"timestamp": 1578772056995, "ltp": 2.3, "tv": 52721.36, "trd": [[2.3, 8561.27]], "batb": [[0, 2.3, 1075.05]], "batl": [[0, 2.32, 39.18], [1, 2.34, 175.87]]}, {"timestamp": 1578772058979, "ltp": 2.32, "tv": 52728.22, "trd": [[2.32, 17025.03]], "batb": NaN, "batl": [[0, 2.32, 35.75]]}, {"timestamp": 1578772059971, "ltp": 2.32, "tv": 52728.22, "trd": NaN, "batb": [[0, 2.3, 1078.46]], "batl": NaN}, {"timestamp": 1578772060977, "ltp": 2.3, "tv": 52729.14, "trd": [[2.3, 8562.19]], "batb": [[0, 2.3, 1127.54]], "batl": NaN}, {"timestamp": 1578772063000, "ltp": 2.3, "tv": 52766.52, "trd": [[2.3, 8599.57]], "batb": [[0, 2.3, 1112.25], [1, 2.28, 3944.81]], "batl": NaN}, {"timestamp": 1578772064986, "ltp": 2.3, "tv": 52766.52, "trd": NaN, "batb": [[0, 2.3, 1122.25]], "batl": NaN}, {"timestamp": 1578772066030, "ltp": 2.3, "tv": 52806.52, "trd": [[2.3, 8639.57]], "batb": [[0, 2.3, 1102.25]], "batl": NaN}, {"timestamp": 1578772067978, "ltp": 2.3, "tv": 52886.21, "trd": [[2.3, 8719.26]], "batb": [[0, 2.3, 1027.29]], "batl": NaN}, {"timestamp": 1578772069011, "ltp": 2.3, "tv": 52893.73, "trd": [[2.3, 8726.78]], "batb": [[0, 2.3, 1019.77]], "batl": NaN}, {"timestamp": 1578772070993, "ltp": 2.3, "tv": 52910.24, "trd": [[2.3, 8743.29]], "batb": [[0, 2.3, 1003.26]], "batl": [[2, 2.36, 10.28]]}, {"timestamp": 1578772071983, "ltp": 2.3, "tv": 52921.26, "trd": [[2.3, 8754.31]], "batb": [[0, 2.3, 992.24]], "batl": NaN}, {"timestamp": 1578772080032, "ltp": 2.32, "tv": 53110.79, "trd": [[2.32, 17214.57]], "batb": [[0, 2.3, 1024.89]], "batl": [[0, 2.34, 175.87], [1, 2.36, 10.28], [2, 2.38, 273.06]]}, {"timestamp": 1578772081025, "ltp": 2.32, "tv": 53110.79, "trd": NaN, "batb": [[0, 2.3, 1028.3]], "batl": NaN}, {"timestamp": 1578772082019, "ltp": 2.32, "tv": 53110.79, "trd": NaN, "batb": [[0, 2.3, 837.72]], "batl": NaN}, {"timestamp": 1578772083019, "ltp": 2.32, "tv": 53110.79, "trd": NaN, "batb": [[1, 2.28, 3804.85]], "batl": NaN}, {"timestamp": 1578772085011, "ltp": 2.3, "tv": 53176.79, "trd": [[2.3, 8820.31]], "batb": [[0, 2.3, 804.72]], "batl": NaN}, {"timestamp": 1578772086047, "ltp": 2.3, "tv": 53180.79, "trd": [[2.3, 8824.31]], "batb": [[0, 2.3, 802.72]], "batl": NaN}, {"timestamp": 1578772088936, "ltp": 2.3, "tv": 53566.43, "trd": [[2.3, 9209.95]], "batb": [[0, 2.3, 609.9]], "batl": NaN}, {"timestamp": 1578772092027, "ltp": 2.3, "tv": 53566.43, "trd": NaN, "batb": [[0, 2.3, 1461.11]], "batl": NaN}, {"timestamp": 1578772098026, "ltp": 2.3, "tv": 53566.43, "trd": NaN, "batb": NaN, "batl": [[0, 2.34, 1858.39], [1, 2.36, 1798.61], [2, 2.38, 189.06]]}, {"timestamp": 1578772101023, "ltp": 2.3, "tv": 53566.43, "trd": NaN, "batb": [[0, 2.3, 1451.11], [1, 2.28, 3772.2]], "batl": [[0, 2.34, 40.77], [1, 2.36, 0], [2, 2.38, 0]]}, {"timestamp": 1578772103387, "ltp": 2.3, "tv": 53566.43, "trd": NaN, "batb": [[0, 2.3, 599.9]], "batl": NaN}, {"timestamp": 1578772108019, "ltp": 2.3, "tv": 53566.43, "trd": NaN, "batb": [[2, 2.26, 1919.96]], "batl": [[1, 2.36, 33.61], [2, 2.4, 33.2]]}, {"timestamp": 1578772108966, "ltp": 2.34, "tv": 53595.65, "trd": [[2.34, 12099.2]], "batb": [[1, 2.28, 3828.75], [2, 2.26, 1884.85]], "batl": [[0, 2.34, 1419.99], [1, 2.36, 1270.09], [2, 2.38, 384.75]]}, {"timestamp": 1578772109962, "ltp": 2.34, "tv": 53595.65, "trd": NaN, "batb": [[1, 2.28, 3802.07], [2, 2.26, 1899.04]], "batl": NaN}, {"timestamp": 1578772111004, "ltp": 2.34, "tv": 53595.65, "trd": NaN, "batb": [[0, 2.32, 851.21], [1, 2.3, 599.9], [2, 2.28, 3802.07]], "batl": NaN}, {"timestamp": 1578772113015, "ltp": 2.34, "tv": 53595.65, "trd": NaN, "batb": [[0, 2.32, 877.17]], "batl": NaN}, {"timestamp": 1578772114004, "ltp": 2.32, "tv": 53632.45, "trd": [[2.32, 17222.15], [2.34, 12128.41]], "batb": [[0, 2.32, 869.58]], "batl": [[0, 2.34, 1405.38]]}, {"timestamp": 1578772114999, "ltp": 2.32, "tv": 53634.5, "trd": [[2.32, 17224.19]], "batb": [[0, 2.32, 868.56]], "batl": NaN}, {"timestamp": 1578772116004, "ltp": 2.32, "tv": 53638.5, "trd": [[2.32, 17228.19]], "batb": [[0, 2.32, 876.23]], "batl": [[0, 2.34, 32.89], [1, 2.38, 407.02], [2, 2.44, 58.73]]}, {"timestamp": 1578772117012, "ltp": 2.32, "tv": 53653.8, "trd": [[2.32, 17243.5]], "batb": [[0, 2.32, 868.57]], "batl": [[0, 2.34, 18.56], [1, 2.36, 14.33], [2, 2.38, 65.43]]}, {"timestamp": 1578772118011, "ltp": 2.32, "tv": 53654.79, "trd": [[2.32, 17244.49]], "batb": [[0, 2.32, 868.08], [2, 2.28, 4031.67]], "batl": [[0, 2.34, 11.55], [1, 2.38, 65.43], [2, 2.44, 58.73]]}, {"timestamp": 1578772119004, "ltp": 2.32, "tv": 53654.79, "trd": NaN, "batb": [[2, 2.28, 4074.89]], "batl": NaN}, {"timestamp": 1578772119992, "ltp": 2.32, "tv": 53654.79, "trd": NaN, "batb": NaN, "batl": [[1, 2.38, 22.27]]}, {"timestamp": 1578772120976, "ltp": 2.32, "tv": 53798.9, "trd": [[2.32, 17388.6]], "batb": [[0, 2.32, 810.77], [1, 2.3, 609.9]], "batl": NaN}, {"timestamp": 1578772122018, "ltp": 2.32, "tv": 53798.9, "trd": NaN, "batb": [[2, 2.28, 4084.89]], "batl": NaN}, {"timestamp": 1578772123020, "ltp": 2.32, "tv": 53798.9, "trd": NaN, "batb": NaN, "batl": [[1, 2.44, 58.73], [2, 2.46, 79.77]]}, {"timestamp": 1578772124032, "ltp": 2.32, "tv": 53798.9, "trd": NaN, "batb": NaN, "batl": [[1, 2.42, 755.26], [2, 2.44, 58.73]]}, {"timestamp": 1578772125024, "ltp": 2.32, "tv": 53798.9, "trd": NaN, "batb": NaN, "batl": [[1, 2.38, 13.65], [2, 2.42, 755.26]]}, {"timestamp": 1578772126020, "ltp": 2.32, "tv": 53798.9, "trd": NaN, "batb": [[0, 2.32, 784.81], [1, 2.3, 624.96]], "batl": [[1, 2.38, 14.1], [2, 2.44, 58.73]]}, {"timestamp": 1578772127024, "ltp": 2.34, "tv": 53810.06, "trd": [[2.34, 12139.57]], "batb": NaN, "batl": [[0, 2.44, 59.12], [1, 2.46, 79.77], [2, 190, 2.67]]}, {"timestamp": 1578772129988, "ltp": 2.34, "tv": 53822.0, "trd": [[2.34, 12151.51]], "batb": NaN, "batl": [[0, 2.44, 58.73]]}, {"timestamp": 1578772131049, "ltp": 2.32, "tv": 53968.71, "trd": [[2.32, 17535.32]], "batb": [[0, 2.32, 711.45]], "batl": [[2, 2.48, 13.62]]}, {"timestamp": 1578772132044, "ltp": 2.32, "tv": 53968.71, "trd": NaN, "batb": NaN, "batl": [[0, 2.34, 1447.7], [1, 2.36, 1393.97], [2, 2.42, 40.47]]}, {"timestamp": 1578772132990, "ltp": 2.32, "tv": 53976.37, "trd": [[2.32, 17542.97]], "batb": [[0, 2.32, 707.62], [1, 2.3, 609.9]], "batl": [[0, 2.4, 760.62], [1, 2.42, 40.47], [2, 2.44, 58.73]]}, {"timestamp": 1578772134031, "ltp": 2.32, "tv": 53976.37, "trd": NaN, "batb": [[0, 2.32, 718.57]], "batl": [[0, 2.34, 17.02], [1, 2.4, 760.62], [2, 2.42, 53.68]]}, {"timestamp": 1578772135024, "ltp": 2.32, "tv": 54093.9, "trd": [[2.32, 17660.5]], "batb": [[0, 2.32, 601.04]], "batl": [[0, 2.34, 1329.02], [1, 2.36, 1384.01], [2, 2.4, 760.62]]}, {"timestamp": 1578772136011, "ltp": 2.32, "tv": 54140.35, "trd": [[2.32, 17706.95]], "batb": [[0, 2.32, 554.59], [2, 2.28, 611.96]], "batl": [[0, 2.34, 17.02]]}, {"timestamp": 1578772139014, "ltp": 2.32, "tv": 54151.07, "trd": [[2.32, 17717.67]], "batb": [[0, 2.32, 549.23]], "batl": NaN}, {"timestamp": 1578772140008, "ltp": 2.32, "tv": 54151.07, "trd": NaN, "batb": NaN, "batl": [[0, 2.34, 80.87]]}, {"timestamp": 1578772141005, "ltp": 2.32, "tv": 54151.07, "trd": NaN, "batb": [[0, 2.32, 549.53]], "batl": [[0, 2.34, 1308], [2, 2.38, 78.23]]}, {"timestamp": 1578772142048, "ltp": 2.32, "tv": 54980.68, "trd": [[2.32, 18509.91], [2.34, 12188.88]], "batb": [[0, 2.32, 140.34]], "batl": [[0, 2.34, 1289.32], [2, 2.38, 92.92]]}, {"timestamp": 1578772143047, "ltp": 2.34, "tv": 59884.92, "trd": [[2.32, 18714.1], [2.34, 16888.94]], "batb": [[0, 2.3, 609.9], [1, 2.28, 568.74], [2, 2.26, 1909.04]], "batl": [[0, 2.36, 1384.01], [1, 2.38, 71.35], [2, 2.4, 774.33]]}, {"timestamp": 1578772144036, "ltp": 2.34, "tv": 59884.92, "trd": NaN, "batb": NaN, "batl": [[2, 2.4, 760.62]]}, {"timestamp": 1578772145032, "ltp": 2.32, "tv": 59885.31, "trd": [[2.32, 18714.49]], "batb": [[1, 2.28, 642.03]], "batl": [[0, 2.38, 71.35], [1, 2.4, 760.62], [2, 2.42, 54.26]]}, {"timestamp": 1578772146042, "ltp": 2.32, "tv": 59885.31, "trd": NaN, "batb": NaN, "batl": [[0, 2.38, 93.67], [1, 2.42, 54.26], [2, 2.44, 58.73]]}, {"timestamp": 1578772147044, "ltp": 2.32, "tv": 59885.31, "trd": NaN, "batb": NaN, "batl": [[1, 2.4, 378.09], [2, 2.42, 54.26]]}, {"timestamp": 1578772148952, "ltp": 2.32, "tv": 59885.31, "trd": NaN, "batb": NaN, "batl": [[1, 2.42, 54.26], [2, 2.44, 58.73]]}, {"timestamp": 1578772150049, "ltp": 2.32, "tv": 59885.31, "trd": NaN, "batb": NaN, "batl": [[0, 2.38, 71.35]]}, {"timestamp": 1578772151035, "ltp": 2.32, "tv": 59885.31, "trd": NaN, "batb": NaN, "batl": [[0, 2.36, 13.95], [1, 2.38, 71.35], [2, 2.42, 54.26]]}, {"timestamp": 1578772153020, "ltp": 2.32, "tv": 59885.31, "trd": NaN, "batb": [[0, 2.3, 606.5]], "batl": NaN}, {"timestamp": 1578772153956, "ltp": 2.3, "tv": 60491.81, "trd": [[2.3, 9816.45]], "batb": [[0, 2.28, 642.03], [1, 2.26, 1909.04], [2, 2.24, 1930.4]], "batl": [[2, 2.4, 380.31]]}, {"timestamp": 1578772154951, "ltp": 2.3, "tv": 60503.42, "trd": [[2.3, 9828.06]], "batb": [[0, 2.3, 33.04], [1, 2.28, 698.59], [2, 2.26, 1909.04]], "batl": [[0, 2.32, 13.28], [1, 2.36, 13.44], [2, 2.38, 71.35]]}, {"timestamp": 1578772155950, "ltp": 2.3, "tv": 60536.46, "trd": [[2.3, 9861.1]], "batb": [[0, 2.28, 641.12], [1, 2.26, 1909.04], [2, 2.24, 1062.17]], "batl": [[0, 2.32, 36.24], [1, 2.34, 1244.13], [2, 2.36, 13.44]]}, {"timestamp": 1578772157050, "ltp": 2.3, "tv": 60536.46, "trd": NaN, "batb": [[0, 2.28, 626.87], [1, 2.26, 1894.85]], "batl": [[1, 2.36, 13.44], [2, 2.38, 56.66]]}, {"timestamp": 1578772158042, "ltp": 2.3, "tv": 60567.27, "trd": [[2.3, 9891.9]], "batb": NaN, "batl": NaN}, {"timestamp": 1578772159039, "ltp": 2.3, "tv": 60567.33, "trd": [[2.3, 9891.96]], "batb": [[0, 2.28, 538.87]], "batl": [[2, 2.38, 79.64]]}, {"timestamp": 1578772160029, "ltp": 2.3, "tv": 60570.73, "trd": [[2.3, 9895.37]], "batb": NaN, "batl": NaN}, {"timestamp": 1578772160968, "ltp": 2.3, "tv": 60570.73, "trd": NaN, "batb": NaN, "batl": [[0, 2.3, 400], [1, 2.32, 73.61], [2, 2.36, 13.44]]}, {"timestamp": 1578772161961, "ltp": 2.3, "tv": 61863.97, "trd": [[2.3, 11188.6]], "batb": NaN, "batl": [[0, 2.32, 73.61], [1, 2.36, 13.44], [2, 2.38, 56.66]]}, {"timestamp": 1578772163053, "ltp": 2.3, "tv": 61863.97, "trd": NaN, "batb": NaN, "batl": [[0, 2.3, 1628.43], [1, 2.32, 1488.88], [2, 2.34, 1576.12]]}, {"timestamp": 1578772164044, "ltp": 2.3, "tv": 61863.97, "trd": NaN, "batb": NaN, "batl": [[2, 2.34, 1589.65]]}, {"timestamp": 1578772166034, "ltp": 2.28, "tv": 62005.27, "trd": [[2.28, 777.91], [2.3, 11253.36]], "batb": [[0, 2.28, 500.6], [1, 2.26, 2000.85]], "batl": [[0, 2.3, 1596.05]]}, {"timestamp": 1578772166972, "ltp": 2.28, "tv": 62005.27, "trd": NaN, "batb": NaN, "batl": [[2, 2.34, 1604.21]]}, {"timestamp": 1578772168951, "ltp": 2.28, "tv": 62005.27, "trd": NaN, "batb": NaN, "batl": [[1, 2.32, 1451.51]]}, {"timestamp": 1578772170053, "ltp": 2.28, "tv": 62051.19, "trd": [[2.28, 823.83]], "batb": [[0, 2.28, 477.64]], "batl": NaN}, {"timestamp": 1578772171041, "ltp": 2.28, "tv": 62051.19, "trd": NaN, "batb": NaN, "batl": [[1, 2.32, 1438.74]]}, {"timestamp": 1578772172957, "ltp": 2.28, "tv": 62051.19, "trd": NaN, "batb": NaN, "batl": [[0, 2.3, 1659.9]]}, {"timestamp": 1578772174045, "ltp": 2.28, "tv": 62051.19, "trd": NaN, "batb": NaN, "batl": [[1, 2.32, 1438.23]]}, {"timestamp": 1578772175975, "ltp": 2.3, "tv": 62058.52, "trd": [[2.3, 11260.7]], "batb": NaN, "batl": [[0, 2.3, 1656.23]]}, {"timestamp": 1578772177959, "ltp": 2.28, "tv": 62059.02, "trd": [[2.28, 824.33]], "batb": [[0, 2.28, 477.39]], "batl": [[0, 2.3, 1669]]}, {"timestamp": 1578772179050, "ltp": 2.28, "tv": 62059.02, "trd": NaN, "batb": NaN, "batl": [[0, 2.3, 76.62], [1, 2.34, 72.68], [2, 2.36, 164.93]]}, {"timestamp": 1578772180983, "ltp": 2.28, "tv": 63013.8, "trd": [[2.28, 1779.11]], "batb": [[0, 2.26, 2000.85], [1, 2.24, 1062.17], [2, 2.22, 216.93]], "batl": [[2, 2.36, 151.49]]}, {"timestamp": 1578772181976, "ltp": 2.28, "tv": 63033.8, "trd": [[2.28, 1799.11]], "batb": NaN, "batl": NaN}, {"timestamp": 1578772182969, "ltp": 2.28, "tv": 63033.8, "trd": NaN, "batb": NaN, "batl": [[1, 2.32, 8.51], [2, 2.34, 72.68]]}, {"timestamp": 1578772183963, "ltp": 2.26, "tv": 63052.49, "trd": [[2.26, 18.69]], "batb": [[0, 2.26, 1885.5]], "batl": NaN}, {"timestamp": 1578772185006, "ltp": 2.26, "tv": 63080.05, "trd": [[2.26, 46.24], [2.28, 1799.12]], "batb": [[0, 2.26, 1871.73]], "batl": [[0, 2.28, 1.86], [1, 2.3, 76.62], [2, 2.32, 8.51]]}, {"timestamp": 1578772185997, "ltp": 2.28, "tv": 63083.77, "trd": [[2.28, 1802.85]], "batb": [[0, 2.28, 40.7], [1, 2.26, 1871.73], [2, 2.24, 1062.17]], "batl": [[0, 2.3, 76.62], [1, 2.32, 8.51], [2, 2.34, 72.68]]}, {"timestamp": 1578772186994, "ltp": 2.28, "tv": 63482.99, "trd": [[2.28, 1807.44], [2.3, 11655.32]], "batb": [[0, 2.28, 38.4]], "batl": [[0, 2.32, 8.51], [1, 2.34, 72.68], [2, 2.36, 151.49]]}, {"timestamp": 1578772187991, "ltp": 2.28, "tv": 63482.99, "trd": NaN, "batb": NaN, "batl": [[0, 2.32, 70.07]]}, {"timestamp": 1578772188984, "ltp": 2.28, "tv": 63482.99, "trd": NaN, "batb": NaN, "batl": [[0, 2.3, 1530.02], [1, 2.32, 1358.2], [2, 2.34, 72.68]]}, {"timestamp": 1578772189980, "ltp": 2.26, "tv": 65482.98, "trd": [[2.26, 1969.44], [2.28, 1884.24]], "batb": [[0, 2.26, 910.13], [1, 2.24, 959.17], [2, 2.22, 216.93]], "batl": NaN}, {"timestamp": 1578772190967, "ltp": 2.26, "tv": 65494.62, "trd": [[2.26, 1981.08]], "batb": [[0, 2.26, 904.31]], "batl": [[0, 2.32, 70.07], [1, 2.34, 72.68], [2, 2.36, 151.49]]}, {"timestamp": 1578772192015, "ltp": 2.26, "tv": 65494.62, "trd": NaN, "batb": NaN, "batl": [[0, 2.32, 70.58]]}, {"timestamp": 1578772193985, "ltp": 2.26, "tv": 65494.62, "trd": NaN, "batb": [[0, 2.26, 941.41]], "batl": [[0, 2.28, 2.31], [1, 2.32, 70.07], [2, 2.34, 72.68]]}, {"timestamp": 1578772194971, "ltp": 2.26, "tv": 65494.62, "trd": NaN, "batb": NaN, "batl": [[1, 2.3, 8.51], [2, 2.32, 70.07]]}, {"timestamp": 1578772196017, "ltp": 2.28, "tv": 65506.94, "trd": [[2.28, 1896.55]], "batb": NaN, "batl": [[0, 2.3, 8.51], [1, 2.32, 70.07], [2, 2.34, 72.68]]}, {"timestamp": 1578772197010, "ltp": 2.28, "tv": 65545.28, "trd": [[2.28, 1934.89]], "batb": [[1, 2.24, 999.61]], "batl": NaN}, {"timestamp": 1578772197996, "ltp": 2.28, "tv": 65545.28, "trd": NaN, "batb": [[0, 2.28, 63.87], [1, 2.26, 941.41], [2, 2.24, 999.61]], "batl": NaN}, {"timestamp": 1578772200033, "ltp": 2.28, "tv": 65545.28, "trd": NaN, "batb": NaN, "batl": [[0, 2.32, 70.07], [1, 2.34, 72.68], [2, 2.36, 151.49]]}, {"timestamp": 1578772201021, "ltp": 2.28, "tv": 65628.03, "trd": [[2.28, 2017.65]], "batb": [[0, 2.28, 22.49]], "batl": NaN}, {"timestamp": 1578772203007, "ltp": 2.28, "tv": 65628.03, "trd": NaN, "batb": [[2, 2.24, 1004.25]], "batl": NaN}, {"timestamp": 1578772203998, "ltp": 2.28, "tv": 65630.83, "trd": [[2.28, 2020.45]], "batb": [[0, 2.28, 21.09]], "batl": NaN}, {"timestamp": 1578772205038, "ltp": 2.28, "tv": 65651.92, "trd": [[2.28, 2041.54]], "batb": [[0, 2.26, 941.41], [1, 2.24, 1004.25], [2, 2.22, 252.87]], "batl": NaN}, {"timestamp": 1578772206035, "ltp": 2.28, "tv": 65651.92, "trd": NaN, "batb": [[0, 2.26, 904.31], [1, 2.24, 959.17]], "batl": [[0, 2.32, 13.76], [2, 2.36, 375.49]]}, {"timestamp": 1578772207025, "ltp": 2.28, "tv": 65651.92, "trd": NaN, "batb": NaN, "batl": [[0, 2.28, 8.51], [1, 2.32, 13.76], [2, 2.34, 72.68]]}, {"timestamp": 1578772209009, "ltp": 2.28, "tv": 65660.43, "trd": [[2.28, 2050.05]], "batb": NaN, "batl": [[0, 2.32, 13.76], [1, 2.34, 72.68], [2, 2.36, 375.49]]}, {"timestamp": 1578772212017, "ltp": 2.28, "tv": 65660.43, "trd": NaN, "batb": [[0, 2.28, 25.54], [1, 2.26, 904.31], [2, 2.24, 959.17]], "batl": NaN}, {"timestamp": 1578772213029, "ltp": 2.28, "tv": 65716.05, "trd": [[2.28, 2105.67]], "batb": [[0, 2.26, 904.31], [1, 2.24, 959.17], [2, 2.22, 252.87]], "batl": [[0, 2.28, 16.19], [1, 2.32, 13.76], [2, 2.34, 72.68]]}, {"timestamp": 1578772214029, "ltp": 2.28, "tv": 65716.05, "trd": NaN, "batb": NaN, "batl": [[2, 2.34, 311.68]]}, {"timestamp": 1578772216019, "ltp": 2.28, "tv": 65753.03, "trd": [[2.28, 2142.64]], "batb": [[0, 2.28, 1.69], [1, 2.26, 910.31], [2, 2.24, 959.17]], "batl": [[0, 2.3, 1589.06], [1, 2.32, 1453.88]]}, {"timestamp": 1578772217010, "ltp": 2.28, "tv": 65753.48, "trd": [[2.28, 2143.1]], "batb": [[0, 2.28, 1.46]], "batl": NaN}, {"timestamp": 1578772219055, "ltp": 2.26, "tv": 65933.48, "trd": [[2.26, 2158.16], [2.28, 2146.02]], "batb": [[0, 2.26, 821.77], [1, 2.24, 959.17], [2, 2.22, 252.87]], "batl": [[0, 2.28, 3.83], [1, 2.3, 1589.06], [2, 2.32, 1453.88]]}, {"timestamp": 1578772222038, "ltp": 2.28, "tv": 65937.31, "trd": [[2.28, 2149.85]], "batb": NaN, "batl": [[0, 2.32, 258.76], [1, 2.34, 72.68], [2, 2.36, 213.63]]}, {"timestamp": 1578772223039, "ltp": 2.28, "tv": 65937.31, "trd": NaN, "batb": [[1, 2.24, 993.04]], "batl": [[0, 2.28, 100], [1, 2.32, 13.76], [2, 2.34, 72.68]]}, {"timestamp": 1578772224031, "ltp": 2.26, "tv": 65950.99, "trd": [[2.26, 2171.83]], "batb": [[0, 2.26, 814.93], [1, 2.24, 934.91], [2, 2.22, 295.68]], "batl": NaN}, {"timestamp": 1578772225023, "ltp": 2.26, "tv": 65950.99, "trd": NaN, "batb": [[2, 2.22, 205.68]], "batl": NaN}, {"timestamp": 1578772226954, "ltp": 2.26, "tv": 65950.99, "trd": NaN, "batb": [[1, 2.24, 901.05], [2, 2.22, 162.87]], "batl": NaN}, {"timestamp": 1578772228052, "ltp": 2.26, "tv": 65973.37, "trd": [[2.26, 2181.02], [2.28, 2163.04]], "batb": [[0, 2.26, 810.34]], "batl": [[0, 2.28, 93.4]]}, {"timestamp": 1578772229043, "ltp": 2.28, "tv": 65977.13, "trd": [[2.26, 2181.32], [2.28, 2166.5]], "batb": [[0, 2.26, 810.19]], "batl": [[0, 2.28, 91.67]]}, {"timestamp": 1578772230042, "ltp": 2.28, "tv": 65992.79, "trd": [[2.28, 2182.16]], "batb": NaN, "batl": [[0, 2.28, 76.01]]}, {"timestamp": 1578772231048, "ltp": 2.28, "tv": 65992.83, "trd": [[2.28, 2182.21]], "batb": NaN, "batl": [[0, 2.28, 75.99]]}, {"timestamp": 1578772235048, "ltp": 2.26, "tv": 66107.7, "trd": [[2.26, 2220.2], [2.28, 2258.2]], "batb": [[0, 2.26, 790.75], [1, 2.24, 942.68]], "batl": [[0, 2.3, 263], [1, 2.32, 423.86], [2, 2.34, 315.68]]}, {"timestamp": 1578772236042, "ltp": 2.26, "tv": 66111.7, "trd": [[2.26, 2224.2]], "batb": [[0, 2.26, 822.14], [1, 2.24, 952.68]], "batl": NaN}, {"timestamp": 1578772238964, "ltp": 2.26, "tv": 66111.7, "trd": NaN, "batb": NaN, "batl": [[0, 2.28, 274], [1, 2.3, 263], [2, 2.32, 423.86]]}, {"timestamp": 1578772239957, "ltp": 2.26, "tv": 66111.7, "trd": NaN, "batb": [[0, 2.26, 788.75], [1, 2.24, 911.05]], "batl": NaN}, {"timestamp": 1578772240961, "ltp": 2.26, "tv": 66111.86, "trd": [[2.26, 2224.36]], "batb": [[0, 2.26, 788.67], [1, 2.24, 896.74]], "batl": NaN}, {"timestamp": 1578772241962, "ltp": 2.26, "tv": 66900.53, "trd": [[2.26, 3013.03]], "batb": [[0, 2.24, 896.74], [1, 2.22, 76.44], [2, 2.2, 484.4]], "batl": NaN}, {"timestamp": 1578772242966, "ltp": 2.26, "tv": 66900.53, "trd": NaN, "batb": [[1, 2.22, 62.19]], "batl": [[0, 2.26, 1.7], [1, 2.28, 274], [2, 2.3, 263]]}, {"timestamp": 1578772243962, "ltp": 2.26, "tv": 66900.53, "trd": NaN, "batb": [[1, 2.22, 47.94]], "batl": NaN}, {"timestamp": 1578772245958, "ltp": 2.26, "tv": 66900.57, "trd": [[2.26, 3013.07]], "batb": NaN, "batl": [[0, 2.26, 268.69]]}, {"timestamp": 1578772248994, "ltp": 2.26, "tv": 66900.57, "trd": NaN, "batb": NaN, "batl": [[0, 2.26, 284.8]]}, {"timestamp": 1578772250050, "ltp": 2.26, "tv": 66900.57, "trd": NaN, "batb": NaN, "batl": [[2, 2.3, 336.65]]}, {"timestamp": 1578772250969, "ltp": 2.24, "tv": 66911.79, "trd": [[2.24, 11.22]], "batb": [[0, 2.24, 891.14]], "batl": NaN}, {"timestamp": 1578772252005, "ltp": 2.26, "tv": 66945.84, "trd": [[2.26, 3047.12]], "batb": NaN, "batl": [[0, 2.26, 267.78]]}, {"timestamp": 1578772252994, "ltp": 2.26, "tv": 66950.76, "trd": [[2.26, 3052.04]], "batb": NaN, "batl": [[0, 2.26, 265.32]]}, {"timestamp": 1578772253994, "ltp": 2.26, "tv": 66950.76, "trd": NaN, "batb": NaN, "batl": [[0, 2.26, 280.62]]}, {"timestamp": 1578772256986, "ltp": 2.26, "tv": 66954.62, "trd": [[2.26, 3055.91]], "batb": NaN, "batl": [[0, 2.26, 278.69]]}, {"timestamp": 1578772257977, "ltp": 2.26, "tv": 67057.56, "trd": [[2.26, 3158.85]], "batb": NaN, "batl": [[0, 2.26, 231.48]]}, {"timestamp": 1578772259971, "ltp": 2.26, "tv": 67057.56, "trd": NaN, "batb": [[0, 2.24, 892.84]], "batl": NaN}, {"timestamp": 1578772262019, "ltp": 2.24, "tv": 67123.81, "trd": [[2.24, 77.46]], "batb": [[0, 2.24, 826.6]], "batl": NaN}, {"timestamp": 1578772262972, "ltp": 2.24, "tv": 67123.81, "trd": NaN, "batb": [[1, 2.22, 88.89]], "batl": [[1, 2.28, 1768.13], [2, 2.3, 1880.32]]}, {"timestamp": 1578772264028, "ltp": 2.24, "tv": 67124.46, "trd": [[2.24, 78.11]], "batb": [[0, 2.24, 825.94], [2, 2.2, 200.4]], "batl": NaN}, {"timestamp": 1578772265855, "ltp": 2.24, "tv": 67124.46, "trd": NaN, "batb": [[0, 2.24, 847.94], [1, 2.22, 97.4]], "batl": [[0, 2.26, 216.17]]}, {"timestamp": 1578772267056, "ltp": 2.26, "tv": 67126.94, "trd": [[2.24, 79.73], [2.26, 3159.71]], "batb": [[0, 2.24, 846.32]], "batl": [[0, 2.26, 215.74]]}, {"timestamp": 1578772268050, "ltp": 2.24, "tv": 67176.94, "trd": [[2.24, 129.73]], "batb": [[0, 2.24, 819.62]], "batl": [[0, 2.26, 1752.58]]}, {"timestamp": 1578772269042, "ltp": 2.24, "tv": 67176.94, "trd": NaN, "batb": NaN, "batl": [[0, 2.26, 215.74]]}, {"timestamp": 1578772270045, "ltp": 2.24, "tv": 67176.94, "trd": NaN, "batb": NaN, "batl": [[0, 2.26, 20.37], [1, 2.3, 73.65], [2, 2.32, 423.86]]}, {"timestamp": 1578772271046, "ltp": 2.24, "tv": 67188.81, "trd": [[2.24, 139.73], [2.26, 3161.58]], "batb": [[0, 2.24, 854.63]], "batl": [[0, 2.26, 19.44]]}, {"timestamp": 1578772273001, "ltp": 2.24, "tv": 67228.48, "trd": [[2.24, 179.39]], "batb": [[0, 2.24, 829.91]], "batl": NaN}, {"timestamp": 1578772273991, "ltp": 2.24, "tv": 67228.48, "trd": NaN, "batb": NaN, "batl": [[0, 2.26, 1687.68]]}, {"timestamp": 1578772275035, "ltp": 2.24, "tv": 67228.48, "trd": NaN, "batb": NaN, "batl": [[0, 2.26, 19.44]]}, {"timestamp": 1578772276028, "ltp": 2.24, "tv": 67230.0, "trd": [[2.24, 180.9], [2.26, 3161.6]], "batb": [[0, 2.24, 828.4], [1, 2.22, 95.4]], "batl": [[0, 2.26, 19.43]]}, {"timestamp": 1578772277034, "ltp": 2.24, "tv": 67259.28, "trd": [[2.24, 210.18]], "batb": [[0, 2.24, 813.76]], "batl": NaN}, {"timestamp": 1578772280008, "ltp": 2.24, "tv": 67421.79, "trd": [[2.24, 372.69]], "batb": [[0, 2.24, 689.52], [2, 2.2, 202.15]], "batl": [[0, 2.26, 38.11]]}, {"timestamp": 1578772281005, "ltp": 2.24, "tv": 67557.99, "trd": [[2.24, 508.88]], "batb": [[0, 2.24, 621.42]], "batl": NaN}, {"timestamp": 1578772282055, "ltp": 2.24, "tv": 67558.39, "trd": [[2.24, 509.28]], "batb": [[0, 2.24, 621.02]], "batl": NaN}, {"timestamp": 1578772283045, "ltp": 2.24, "tv": 67562.42, "trd": [[2.24, 513.32]], "batb": [[0, 2.24, 618.99], [1, 2.22, 102.73], [2, 2.2, 204.15]], "batl": NaN}, {"timestamp": 1578772285035, "ltp": 2.24, "tv": 67569.95, "trd": [[2.24, 520.79], [2.26, 3161.65]], "batb": [[0, 2.24, 615.25]], "batl": [[0, 2.26, 38.09]]}, {"timestamp": 1578772286034, "ltp": 2.24, "tv": 67583.62, "trd": [[2.24, 534.46]], "batb": [[0, 2.24, 601.58]], "batl": [[0, 2.26, 48.09]]}, {"timestamp": 1578772288028, "ltp": 2.24, "tv": 67736.68, "trd": [[2.24, 687.53]], "batb": [[0, 2.24, 525.05]], "batl": NaN}, {"timestamp": 1578772288914, "ltp": 2.24, "tv": 67738.92, "trd": [[2.24, 689.77]], "batb": [[0, 2.24, 522.81]], "batl": NaN}, {"timestamp": 1578772290955, "ltp": 2.24, "tv": 67938.92, "trd": [[2.24, 889.77]], "batb": [[0, 2.24, 422.81]], "batl": NaN}, {"timestamp": 1578772291956, "ltp": 2.24, "tv": 68030.47, "trd": [[2.24, 906.57], [2.26, 3236.39]], "batb": [[0, 2.24, 406]], "batl": [[0, 2.26, 10.72]]}, {"timestamp": 1578772293054, "ltp": 2.24, "tv": 68061.08, "trd": [[2.24, 937.18]], "batb": [[0, 2.24, 390.7]], "batl": [[2, 2.32, 1249.97]]}, {"timestamp": 1578772293949, "ltp": 2.24, "tv": 68061.08, "trd": NaN, "batb": NaN, "batl": [[0, 2.26, 10], [2, 2.32, 167.86]]}, {"timestamp": 1578772294860, "ltp": 2.24, "tv": 68061.08, "trd": NaN, "batb": [[2, 2.2, 140.13]], "batl": [[1, 2.3, 14.76], [2, 2.32, 13.76]]}, {"timestamp": 1578772296040, "ltp": 2.24, "tv": 68061.08, "trd": NaN, "batb": [[1, 2.22, 61.78], [2, 2.2, 57]], "batl": [[1, 190, 5.09], [2, 2.32, 0]]}, {"timestamp": 1578772296937, "ltp": 2.24, "tv": 68061.08, "trd": NaN, "batb": [[0, 2.24, 82]], "batl": NaN}, {"timestamp": 1578772311946, "ltp": 2.24, "tv": 68061.08, "trd": NaN, "batb": [[1, 2.22, 54.45]], "batl": NaN}, {"timestamp": 1578772315976, "ltp": 2.24, "tv": 68061.08, "trd": NaN, "batb": [[0, 2.24, 60]], "batl": NaN}, {"timestamp": 1578772347979, "ltp": 2.24, "tv": 68061.08, "trd": NaN, "batb": [[0, 2.2, 37], [1, 2.1, 63.21], [2, 2.08, 122.5]], "batl": NaN}, {"timestamp": 1578772349008, "ltp": 2.24, "tv": 68061.08, "trd": NaN, "batb": [[2, 2.08, 10]], "batl": NaN}, {"timestamp": 1578772355022, "ltp": 2.24, "tv": 68061.08, "trd": NaN, "batb": [[0, 3.65, 22.01], [1, 2.2, 37], [2, 2.1, 63.21]], "batl": NaN}, {"timestamp": 1578772356009, "ltp": 2.24, "tv": 68061.08, "trd": NaN, "batb": [[0, 4, 148], [1, 3.85, 58.5], [2, 3.65, 22.01]], "batl": [[0, 5.5, 109]]}, {"timestamp": 1578772356995, "ltp": 2.24, "tv": 68061.08, "trd": NaN, "batb": [[1, 3.95, 152], [2, 3.9, 160]], "batl": [[0, 5.2, 127], [1, 5.3, 117], [2, 5.4, 117]]}, {"timestamp": 1578772359020, "ltp": 2.24, "tv": 68061.08, "trd": NaN, "batb": [[1, 3.95, 266.8]], "batl": NaN}, {"timestamp": 1578772362030, "ltp": 2.24, "tv": 68061.08, "trd": NaN, "batb": NaN, "batl": [[0, 5.1, 1250.05], [1, 5.2, 127], [2, 5.3, 117]]}, {"timestamp": 1578772364993, "ltp": 2.24, "tv": 68061.08, "trd": NaN, "batb": [[0, 4.1, 682.47], [1, 4, 148], [2, 3.95, 266.8]], "batl": NaN}, {"timestamp": 1578772366041, "ltp": 2.24, "tv": 68061.08, "trd": NaN, "batb": [[1, 4, 154.81]], "batl": [[1, 5.2, 131.26]]}, {"timestamp": 1578772367023, "ltp": 4.1, "tv": 68098.45, "trd": [[4.1, 37.37]], "batb": [[0, 4.1, 663.78]], "batl": NaN}, {"timestamp": 1578772368009, "ltp": 4.4, "tv": 68110.07, "trd": [[4.4, 11.62]], "batb": NaN, "batl": NaN}, {"timestamp": 1578772369992, "ltp": 4.1, "tv": 68126.23, "trd": [[4.1, 53.53]], "batb": [[0, 4.1, 709.28], [1, 4, 204.81], [2, 3.95, 317.8]], "batl": NaN}, {"timestamp": 1578772371027, "ltp": 4.4, "tv": 68139.31, "trd": [[4.4, 24.7]], "batb": NaN, "batl": [[0, 5, 4], [1, 5.1, 1250.05], [2, 5.2, 131.26]]}, {"timestamp": 1578772372020, "ltp": 4.4, "tv": 68139.31, "trd": NaN, "batb": NaN, "batl": [[2, 5.2, 127]]}, {"timestamp": 1578772373009, "ltp": 4.1, "tv": 68257.97, "trd": [[4.1, 128.27], [4.4, 25.16], [4.9, 43.46]], "batb": [[0, 4.1, 671.91]], "batl": NaN}, {"timestamp": 1578772375041, "ltp": 4.9, "tv": 68267.86, "trd": [[4.2, 8.52], [4.9, 44.84]], "batb": [[0, 4.2, 600.11], [1, 4.1, 671.91], [2, 4, 204.81]], "batl": NaN}, {"timestamp": 1578772375927, "ltp": 4.9, "tv": 68267.86, "trd": NaN, "batb": [[0, 4.2, 846.2], [1, 4.1, 720.91]], "batl": [[0, 5, 365.5]]}, {"timestamp": 1578772377028, "ltp": 4.9, "tv": 68267.86, "trd": NaN, "batb": [[0, 4.2, 740.73]], "batl": [[0, 4.7, 7.66], [1, 4.8, 173], [2, 4.9, 158]]}, {"timestamp": 1578772378023, "ltp": 4.9, "tv": 68267.86, "trd": NaN, "batb": [[1, 4.1, 667.34]], "batl": [[0, 4.8, 173], [1, 4.9, 168.15], [2, 5, 228.06]]}, {"timestamp": 1578772379046, "ltp": 4.8, "tv": 68271.94, "trd": [[4.8, 4.08]], "batb": NaN, "batl": [[0, 4.8, 170.96], [1, 4.9, 210.5], [2, 5, 185.11]]}, {"timestamp": 1578772380032, "ltp": 4.8, "tv": 68271.94, "trd": NaN, "batb": NaN, "batl": [[1, 4.9, 283.46]]}, {"timestamp": 1578772381024, "ltp": 4.8, "tv": 68271.94, "trd": NaN, "batb": [[0, 4.2, 794.3]], "batl": [[1, 4.9, 958.81]]}, {"timestamp": 1578772382021, "ltp": 4.8, "tv": 68271.94, "trd": NaN, "batb": [[0, 4.3, 15.03], [1, 4.2, 740.73], [2, 4.1, 667.34]], "batl": [[2, 5, 181.11]]}, {"timestamp": 1578772383028, "ltp": 4.8, "tv": 68271.94, "trd": NaN, "batb": [[1, 4.2, 1159.69]], "batl": [[0, 4.8, 470.96], [1, 4.9, 1060.06]]}, {"timestamp": 1578772384025, "ltp": 4.3, "tv": 68279.99, "trd": [[4.3, 8.06]], "batb": [[0, 4.3, 11.01], [1, 4.2, 1300.31]], "batl": [[0, 4.8, 481.17], [1, 4.9, 283.46], [2, 5, 157.11]]}, {"timestamp": 1578772384907, "ltp": 4.3, "tv": 68279.99, "trd": NaN, "batb": NaN, "batl": [[0, 4.8, 494.08]]}, {"timestamp": 1578772385966, "ltp": 4.7, "tv": 68283.67, "trd": [[4.7, 3.68]], "batb": [[1, 4.2, 1067.07]], "batl": [[0, 4.7, 169.16], [1, 4.8, 523.75], [2, 4.9, 283.46]]}, {"timestamp": 1578772386964, "ltp": 4.7, "tv": 68283.67, "trd": NaN, "batb": [[0, 4.2, 1067.07], [1, 4.1, 667.34], [2, 4, 198]], "batl": [[0, 4.5, 5], [1, 4.7, 169.16], [2, 4.8, 524.06]]}, {"timestamp": 1578772387959, "ltp": 4.7, "tv": 68283.67, "trd": NaN, "batb": [[0, 4.2, 918.13]], "batl": [[1, 4.7, 523.91]]}, {"timestamp": 1578772388952, "ltp": 4.5, "tv": 68285.51, "trd": [[4.5, 1.84]], "batb": NaN, "batl": [[0, 4.5, 18.47], [1, 4.6, 30], [2, 4.7, 173.16]]}, {"timestamp": 1578772389985, "ltp": 4.5, "tv": 68285.51, "trd": NaN, "batb": NaN, "batl": [[2, 4.7, 484.65]]}, {"timestamp": 1578772390974, "ltp": 4.5, "tv": 68285.6, "trd": [[4.5, 1.93]], "batb": [[0, 4.3, 58.97], [1, 4.2, 918.13], [2, 4.1, 674.14]], "batl": [[0, 4.5, 18.38], [2, 4.7, 478.99]]}, {"timestamp": 1578772392023, "ltp": 4.3, "tv": 68356.22, "trd": [[4.3, 78.67]], "batb": [[0, 4.3, 23.66]], "batl": [[0, 4.4, 2], [1, 4.5, 18.38], [2, 4.6, 30]]}, {"timestamp": 1578772392968, "ltp": 4.3, "tv": 68356.22, "trd": NaN, "batb": [[1, 4.2, 1120.13]], "batl": NaN}, {"timestamp": 1578772394032, "ltp": 4.4, "tv": 68367.74, "trd": [[4.4, 36.67]], "batb": [[0, 4.4, 44.24], [1, 4.3, 11.69], [2, 4.2, 1260.75]], "batl": [[0, 4.5, 18.38], [1, 4.6, 30], [2, 4.7, 478.99]]}, {"timestamp": 1578772395979, "ltp": 4.5, "tv": 68375.64, "trd": [[4.5, 9.83]], "batb": NaN, "batl": [[0, 4.5, 14.43], [2, 4.7, 476.99]]}, {"timestamp": 1578772396977, "ltp": 4.4, "tv": 68379.38, "trd": [[4.4, 40.41]], "batb": [[0, 4.4, 42.37]], "batl": [[0, 4.6, 30], [1, 4.7, 476.99], [2, 4.8, 524.06]]}, {"timestamp": 1578772397970, "ltp": 4.4, "tv": 68382.78, "trd": [[4.4, 43.82]], "batb": [[0, 4.4, 40.67]], "batl": NaN}, {"timestamp": 1578772399006, "ltp": 4.6, "tv": 68417.12, "trd": [[4.6, 34.34]], "batb": [[0, 4.3, 11.69], [1, 4.2, 1260.75], [2, 4.1, 713.14]], "batl": [[0, 4.6, 12.83]]}, {"timestamp": 1578772400005, "ltp": 4.6, "tv": 68432.96, "trd": [[4.6, 50.18]], "batb": [[1, 4.2, 726.64], [2, 4.1, 738.35]], "batl": [[0, 4.6, 45.59]]}, {"timestamp": 1578772401002, "ltp": 4.3, "tv": 68437.44, "trd": [[4.3, 83.15]], "batb": [[0, 4.3, 91.83], [1, 4.2, 789.64], [2, 4.1, 805.9]], "batl": [[0, 4.6, 135.81]]}, {"timestamp": 1578772402030, "ltp": 4.3, "tv": 68437.44, "trd": NaN, "batb": [[0, 4.3, 98.42], [1, 4.2, 930.26]], "batl": [[0, 4.6, 177.31], [1, 4.7, 472.99]]}, {"timestamp": 1578772403016, "ltp": 4.3, "tv": 68460.58, "trd": [[4.3, 106.3]], "batb": [[0, 4.3, 86.85], [1, 4.2, 789.64]], "batl": [[0, 4.5, 2], [1, 4.6, 459.87], [2, 4.7, 469.16]]}, {"timestamp": 1578772404015, "ltp": 4.3, "tv": 68473.66, "trd": [[4.3, 119.38]], "batb": [[0, 4.3, 274.31]], "batl": [[0, 4.5, 2.31], [1, 4.6, 463.78]]}, {"timestamp": 1578772405006, "ltp": 4.3, "tv": 68495.3, "trd": [[4.3, 141.02]], "batb": [[0, 4.3, 263.49]], "batl": [[0, 4.5, 102.31]]}, {"timestamp": 1578772406002, "ltp": 4.3, "tv": 68530.9, "trd": [[4.3, 176.61]], "batb": [[0, 4.3, 313.66]], "batl": [[0, 4.4, 27.34], [1, 4.5, 102], [2, 4.6, 463.78]]}, {"timestamp": 1578772407006, "ltp": 4.3, "tv": 68538.56, "trd": [[4.3, 184.27]], "batb": [[0, 4.3, 261.97]], "batl": [[2, 4.6, 467.78]]}, {"timestamp": 1578772407989, "ltp": 4.3, "tv": 68585.69, "trd": [[4.3, 214.27], [4.4, 60.95]], "batb": [[0, 4.3, 260.15], [1, 4.2, 803.61], [2, 4.1, 819.26]], "batl": [[0, 4.4, 23.36], [2, 4.6, 732.21]]}, {"timestamp": 1578772408980, "ltp": 4.3, "tv": 68605.69, "trd": [[4.3, 234.27]], "batb": [[0, 4.3, 250.15]], "batl": [[0, 4.4, 40.38], [1, 4.5, 137.12]]}, {"timestamp": 1578772409981, "ltp": 4.3, "tv": 68605.75, "trd": [[4.3, 234.33]], "batb": [[0, 4.3, 236.94], [1, 4.2, 944.23]], "batl": [[0, 4.4, 44.61]]}, {"timestamp": 1578772410978, "ltp": 4.3, "tv": 68605.75, "trd": NaN, "batb": NaN, "batl": [[1, 4.5, 142.97]]}, {"timestamp": 1578772411983, "ltp": 4.4, "tv": 68615.66, "trd": [[4.4, 70.85]], "batb": [[1, 4.2, 1057.89]], "batl": [[0, 4.4, 39.66], [1, 4.5, 270.84], [2, 4.6, 449.65]]}, {"timestamp": 1578772413015, "ltp": 4.4, "tv": 68618.48, "trd": [[4.4, 73.68]], "batb": [[1, 4.2, 945.17], [2, 4.1, 854.41]], "batl": [[0, 4.4, 38.25], [1, 4.5, 281.56]]}, {"timestamp": 1578772413968, "ltp": 4.3, "tv": 69855.42, "trd": [[4.3, 1471.27]], "batb": [[0, 4.2, 804.55], [1, 4.1, 819.26], [2, 4, 342.42]], "batl": [[0, 4.4, 114.46]]}, {"timestamp": 1578772415025, "ltp": 4.3, "tv": 69855.42, "trd": NaN, "batb": [[0, 4.3, 168.94], [1, 4.2, 804.55], [2, 4.1, 819.26]], "batl": [[0, 4.4, 118.46], [1, 4.5, 477.31]]}, {"timestamp": 1578772416002, "ltp": 4.4, "tv": 69855.74, "trd": [[4.4, 73.99]], "batb": [[0, 4.2, 804.55], [1, 4.1, 819.26], [2, 4, 342.42]], "batl": [[0, 4.4, 305.01], [1, 4.5, 475.31]]}, {"timestamp": 1578772417002, "ltp": 4.4, "tv": 69855.74, "trd": NaN, "batb": NaN, "batl": [[0, 4.4, 287.99]]}, {"timestamp": 1578772418000, "ltp": 4.3, "tv": 69894.0, "trd": [[4.3, 1509.54]], "batb": NaN, "batl": [[0, 4.4, 283.39], [1, 4.5, 471.31], [2, 4.6, 356.22]]}, {"timestamp": 1578772418985, "ltp": 4.4, "tv": 69941.53, "trd": [[4.4, 121.52]], "batb": NaN, "batl": [[0, 4.4, 251.18], [2, 4.6, 352.22]]}, {"timestamp": 1578772420033, "ltp": 4.4, "tv": 69941.53, "trd": NaN, "batb": [[0, 4.2, 902.92]], "batl": [[2, 4.6, 347.31]]}, {"timestamp": 1578772421024, "ltp": 4.4, "tv": 69941.53, "trd": NaN, "batb": [[0, 4.2, 1043.54]], "batl": NaN}, {"timestamp": 1578772422022, "ltp": 4.3, "tv": 69947.05, "trd": [[4.3, 1515.06]], "batb": NaN, "batl": [[0, 4.4, 235.87]]}, {"timestamp": 1578772423018, "ltp": 4.4, "tv": 70183.14, "trd": [[4.4, 357.61]], "batb": NaN, "batl": [[0, 4.5, 479.68], [1, 4.6, 347.31], [2, 4.7, 469.16]]}, {"timestamp": 1578772424004, "ltp": 4.4, "tv": 70203.23, "trd": [[4.4, 377.69]], "batb": NaN, "batl": [[0, 4.5, 426.88]]}, {"timestamp": 1578772424895, "ltp": 4.4, "tv": 70303.25, "trd": [[4.4, 477.72]], "batb": NaN, "batl": [[0, 4.5, 336.71]]}, {"timestamp": 1578772426002, "ltp": 4.4, "tv": 70303.25, "trd": NaN, "batb": [[0, 4.2, 938.07]], "batl": NaN}, {"timestamp": 1578772426995, "ltp": 4.3, "tv": 70303.33, "trd": [[4.3, 1515.14]], "batb": NaN, "batl": [[0, 4.4, 15.31], [1, 4.5, 339.8], [2, 4.6, 347.31]]}, {"timestamp": 1578772428048, "ltp": 4.4, "tv": 70328.69, "trd": [[4.3, 1518.95], [4.4, 499.27]], "batb": NaN, "batl": [[0, 4.5, 294], [1, 4.6, 301.9], [2, 4.7, 469.16]]}, {"timestamp": 1578772429042, "ltp": 4.4, "tv": 70328.69, "trd": NaN, "batb": [[0, 4.4, 160.91], [1, 4.2, 938.07], [2, 4.1, 819.26]], "batl": NaN}, {"timestamp": 1578772430030, "ltp": 4.5, "tv": 70362.49, "trd": [[4.4, 530.99], [4.5, 11.91]], "batb": [[0, 4.4, 145.05]], "batl": [[0, 4.5, 292.96], [2, 4.7, 703.1]]}, {"timestamp": 1578772431026, "ltp": 4.4, "tv": 70379.24, "trd": [[4.4, 547.75]], "batb": [[0, 4.4, 136.67], [1, 4.3, 45.04], [2, 4.2, 938.07]], "batl": NaN}, {"timestamp": 1578772431967, "ltp": 4.4, "tv": 70384.85, "trd": [[4.4, 553.35]], "batb": [[0, 4.4, 133.87], [1, 4.3, 137.76]], "batl": [[2, 4.7, 403.1]]}, {"timestamp": 1578772433026, "ltp": 4.5, "tv": 70384.87, "trd": [[4.5, 11.93]], "batb": NaN, "batl": [[0, 4.5, 292.95], [2, 4.7, 461.58]]}, {"timestamp": 1578772434026, "ltp": 4.4, "tv": 70400.53, "trd": [[4.4, 565.59], [4.5, 15.35]], "batb": [[0, 4.4, 127.75]], "batl": [[0, 4.5, 383.41]]}, {"timestamp": 1578772434956, "ltp": 4.4, "tv": 70400.53, "trd": NaN, "batb": [[1, 4.3, 139.76]], "batl": [[0, 4.5, 426.52], [1, 4.6, 709.96]]}, {"timestamp": 1578772436023, "ltp": 4.4, "tv": 70400.53, "trd": NaN, "batb": [[2, 4.2, 902.92]], "batl": NaN}, {"timestamp": 1578772437014, "ltp": 4.4, "tv": 70404.53, "trd": [[4.4, 569.59]], "batb": [[0, 4.4, 125.75]], "batl": [[0, 4.5, 1405.52]]}, {"timestamp": 1578772439044, "ltp": 4.4, "tv": 70454.53, "trd": [[4.4, 619.59]], "batb": [[0, 4.4, 100.75]], "batl": NaN}, {"timestamp": 1578772440043, "ltp": 4.4, "tv": 70464.53, "trd": [[4.4, 629.59]], "batb": [[0, 4.4, 95.75]], "batl": NaN}, {"timestamp": 1578772441035, "ltp": 4.4, "tv": 70464.53, "trd": NaN, "batb": NaN, "batl": [[0, 4.5, 1431.35], [1, 4.6, 301.9], [2, 4.7, 631.48]]}, {"timestamp": 1578772442038, "ltp": 4.4, "tv": 70464.53, "trd": NaN, "batb": [[2, 4.2, 901.98]], "batl": NaN}, {"timestamp": 1578772442979, "ltp": 4.4, "tv": 70464.53, "trd": NaN, "batb": [[2, 4.2, 450.81]], "batl": [[0, 4.5, 1211.52], [1, 4.6, 130.9]]}, {"timestamp": 1578772443967, "ltp": 4.4, "tv": 70469.13, "trd": [[4.4, 634.19]], "batb": [[0, 4.4, 93.45]], "batl": [[2, 4.7, 859.63]]}, {"timestamp": 1578772445037, "ltp": 4.4, "tv": 70499.74, "trd": [[4.4, 664.8]], "batb": [[0, 4.4, 78.14]], "batl": [[0, 4.5, 1179.02], [2, 4.7, 567.21]]}, {"timestamp": 1578772446968, "ltp": 4.4, "tv": 70654.53, "trd": [[4.4, 819.51], [4.5, 15.43]], "batb": [[0, 4.3, 47.83], [1, 4.2, 450.81], [2, 4.1, 450.93]], "batl": [[0, 4.5, 1178.98]]}, {"timestamp": 1578772447990, "ltp": 4.4, "tv": 70654.53, "trd": NaN, "batb": [[0, 4.3, 15.55]], "batl": [[2, 4.7, 169.16]]}