{"info": {"id": "1.166703743", "eventId": "29632571", "eventName": "Over/Under 1.5 Goals", "marketType": "OVER_UNDER_15", "openDate": 1578772101023, "name": "Inter v Atalanta", "numberOfActiveRunner": 2, "countryCode": "", "sport": "TENNIS", "venue": "", "volume": {"total": 372343.77, "preMatch": 36240.77, "inPlay": 336103.0}, "winner": {"id": 1221386, "name": "Over 1.5 Goals", "status": "WINNER", "position": 2}, "delay": 7}, "runners": [{"id": 1221385, "name": "Under 1.5 Goals", "status": "LOSER", "position": 1, "inPlayOdds": 5.1, "inPlayTime": 1578772101023, "avgPrematch": 5.11, "closedOdds": 2.02, "maxPrematch": 5.7, "minPrematch": 4.6, "maxInPlay": 18.0, "minInPlay": 1.97, "inPlayIndex": 683, "lengthOdds": 3809, "lengthOddsPrematch": 683, "lengthOddsInPlay": 3126, "tradedVolume": 98092.98, "preMatchVolume": 3708.99, "inPlayVolume": 94383.99}, {"id": 1221386, "name": "Over 1.5 Goals", "status": "WINNER", "position": 2, "inPlayOdds": 1.25, "inPlayTime": 1578772101023, "avgPrematch": 1.24, "closedOdds": 2.02, "maxPrematch": 1.28, "minPrematch": 1.18, "maxInPlay": 2.04, "minInPlay": 1.06, "inPlayIndex": 901, "lengthOdds": 3820, "lengthOddsPrematch": 901, "lengthOddsInPlay": 2919, "tradedVolume": 274250.79, "preMatchVolume": 32531.78, "inPlayVolume": 241719.01}], "marketUpdates": [{"timestamp": 1578513294362000000, "openDate": "2020-01-11T19:45:00.000Z", "status": "OPEN", "betDelay": 0, "inPlay": false, "complete": true}, {"timestamp": 1578772101023000000, "openDate": "2020-01-11T19:45:00.000Z", "status": "OPEN", "betDelay": 7, "inPlay": true, "complete": true}, {"timestamp": 1578772294860000000, "openDate": "2020-01-11T19:45:00.000Z", "status": "SUSPENDED", "betDelay": 7, "inPlay": true, "complete": true}, {"timestamp": 1578772347979000000, "openDate": "2020-01-11T19:45:00.000Z", "status": "OPEN", "betDelay": 7, "inPlay": true, "complete": true}, {"timestamp": 1578774525024000000, "openDate": "2020-01-11T19:45:00.000Z", "status": "SUSPENDED", "betDelay": 7, "inPlay": true, "complete": true}, {"timestamp": 1578774556973000000, "openDate": "2020-01-11T19:45:00.000Z", "status": "OPEN", "betDelay": 7, "inPlay": true, "complete": true}, {"timestamp": 1578774580039000000, "openDate": "2020-01-11T19:45:00.000Z", "status": "SUSPENDED", "betDelay": 7, "inPlay": true, "complete": true}, {"timestamp": 1578774582036000000, "openDate": "2020-01-11T19:45:00.000Z", "status": "OPEN", "betDelay": 7, "inPlay": true, "complete": true}, {"timestamp": 1578774866982000000, "openDate": "2020-01-11T19:45:00.000Z", "status": "OPEN", "betDelay": 1, "inPlay": true, "complete": true}, {"timestamp": 1578775780035000000, "openDate": "2020-01-11T19:45:00.000Z", "status": "OPEN", "betDelay": 7, "inPlay": true, "complete": true}, {"timestamp": 1578777631947000000, "openDate": "2020-01-11T19:45:00.000Z", "status": "SUSPENDED", "betDelay": 7, "inPlay": true, "complete": true}, {"timestamp": 1578777782982000000, "openDate": "2020-01-11T19:45:00.000Z", "status": "CLOSED", "betDelay": 7, "inPlay": true, "complete": true}], "odds": [{"runnerId": 1221385, "odds": [{"timestamp": 1578604262029, "ltp": 4.6, "tv": 5.57, "trd": [[4.6, 5.57]], "batb": [[0, 4.6, 13.25]], "batl": NaN}, {"timestamp": 1578604262809, "ltp": 4.6, "tv": 5.57, "trd": NaN, "batb": [[0, 4.6, 18.82]], "batl": NaN}, {"timestamp": 1578605377961, "ltp": 4.6, "tv": 5.57, "trd": NaN, "batb": [[0, 4.9, 17.37]], "batl": NaN}, {"timestamp": 1578605599007, "ltp": 4.6, "tv": 5.57, "trd": NaN, "batb": [[0, 4.8, 17.83]], "batl": NaN}, {"timestamp": 1578617950999, "ltp": 4.6, "tv": 5.57, "trd": NaN, "batb": [[1, 2.12, 3.68]], "batl": [[0, 7, 7.39]]}, {"timestamp": 1578618151932, "ltp": 4.6, "tv": 5.57, "trd": NaN, "batb": NaN, "batl": [[0, 7, 7.4]]}, {"timestamp": 1578625658043, "ltp": 4.6, "tv": 5.57, "trd": NaN, "batb": NaN, "batl": [[0, 6.6, 6.62]]}, {"timestamp": 1578632551910, "ltp": 4.6, "tv": 5.57, "trd": NaN, "batb": NaN, "batl": [[0, 6.6, 6.62]]}, {"timestamp": 1578636151942, "ltp": 4.6, "tv": 5.57, "trd": NaN, "batb": NaN, "batl": [[0, 6.6, 6.62]]}, {"timestamp": 1578636262765, "ltp": 4.6, "tv": 5.57, "trd": NaN, "batb": [[1, 2.12, 3]], "batl": NaN}, {"timestamp": 1578647068969, "ltp": 4.6, "tv": 5.57, "trd": NaN, "batb": [[0, 4.7, 18.31]], "batl": NaN}, {"timestamp": 1578658536756, "ltp": 4.6, "tv": 5.57, "trd": NaN, "batb": [[0, 4.8, 17.83]], "batl": NaN}, {"timestamp": 1578668055028, "ltp": 4.6, "tv": 5.57, "trd": NaN, "batb": [[0, 4.8, 20.15]], "batl": NaN}, {"timestamp": 1578672218796, "ltp": 4.6, "tv": 5.57, "trd": NaN, "batb": [[0, 4.7, 20.69]], "batl": NaN}, {"timestamp": 1578672484991, "ltp": 4.6, "tv": 5.57, "trd": NaN, "batb": [[0, 4.6, 21.27]], "batl": NaN}, {"timestamp": 1578683859118, "ltp": 4.6, "tv": 5.57, "trd": NaN, "batb": [[0, 4.7, 4.03], [1, 4.6, 21.27], [2, 2.12, 3]], "batl": [[0, 6.6, 4.03]]}, {"timestamp": 1578685500907, "ltp": 4.6, "tv": 5.57, "trd": NaN, "batb": [[1, 4.6, 13.29]], "batl": NaN}, {"timestamp": 1578685936887, "ltp": 4.6, "tv": 5.57, "trd": NaN, "batb": NaN, "batl": [[0, 6.2, 4.03]]}, {"timestamp": 1578687345025, "ltp": 4.6, "tv": 5.57, "trd": NaN, "batb": NaN, "batl": [[0, 6, 4.03]]}, {"timestamp": 1578687404901, "ltp": 5.6, "tv": 9.26, "trd": [[5.6, 3.7]], "batb": NaN, "batl": NaN}, {"timestamp": 1578687671588, "ltp": 5.6, "tv": 9.26, "trd": NaN, "batb": NaN, "batl": [[0, 5.8, 4.03]]}, {"timestamp": 1578687674705, "ltp": 5.6, "tv": 9.26, "trd": NaN, "batb": NaN, "batl": [[0, 5.7, 4.03]]}, {"timestamp": 1578687885376, "ltp": 5.6, "tv": 9.26, "trd": NaN, "batb": NaN, "batl": [[0, 5.7, 4.03]]}, {"timestamp": 1578687895160, "ltp": 5.6, "tv": 9.26, "trd": NaN, "batb": NaN, "batl": [[0, 5.6, 4.03]]}, {"timestamp": 1578688098022, "ltp": 5.6, "tv": 9.26, "trd": NaN, "batb": [[1, 4.5, 13.67]], "batl": NaN}, {"timestamp": 1578690152047, "ltp": 5.6, "tv": 9.26, "trd": [[5.6, 3.7]], "batb": NaN, "batl": NaN}, {"timestamp": 1578692906519, "ltp": 5.6, "tv": 10.47, "trd": [[5.6, 4.91]], "batb": NaN, "batl": [[0, 5.6, 2.82]]}, {"timestamp": 1578697352006, "ltp": 5.6, "tv": 10.47, "trd": [[5.6, 4.91]], "batb": [[0, 4.7, 4.03]], "batl": [[0, 5.6, 2.82]]}, {"timestamp": 1578698847855, "ltp": 5.6, "tv": 10.47, "trd": NaN, "batb": [[0, 4.5, 13.67], [1, 2.12, 3], [2, 1.44, 2]], "batl": NaN}, {"timestamp": 1578703282362, "ltp": 5.6, "tv": 10.47, "trd": NaN, "batb": [[2, 1.5, 38.28]], "batl": NaN}, {"timestamp": 1578705050795, "ltp": 5.6, "tv": 12.49, "trd": [[5.6, 6.92]], "batb": NaN, "batl": [[0, 5.6, 0.8]]}, {"timestamp": 1578705051358, "ltp": 5.6, "tv": 12.49, "trd": NaN, "batb": [[0, 4.8, 4.03], [1, 4.5, 13.67], [2, 2.12, 3]], "batl": NaN}, {"timestamp": 1578705828762, "ltp": 4.8, "tv": 21.88, "trd": [[4.8, 9.39]], "batb": [[0, 4.5, 13.67], [1, 2.12, 3], [2, 1.5, 38.28]], "batl": NaN}, {"timestamp": 1578707529052, "ltp": 5.6, "tv": 22.68, "trd": [[5.6, 7.72]], "batb": NaN, "batl": NaN}, {"timestamp": 1578707529677, "ltp": 5.6, "tv": 22.68, "trd": NaN, "batb": NaN, "batl": [[0, 6.6, 4.03]]}, {"timestamp": 1578707530289, "ltp": 5.6, "tv": 22.68, "trd": NaN, "batb": [[0, 4.8, 4.03], [1, 4.5, 13.67], [2, 2.12, 3]], "batl": NaN}, {"timestamp": 1578710313010, "ltp": 5.6, "tv": 22.68, "trd": NaN, "batb": [[1, 4.6, 13.29]], "batl": NaN}, {"timestamp": 1578712457855, "ltp": 5.6, "tv": 22.68, "trd": NaN, "batb": [[1, 4.7, 3.37], [2, 4.6, 13.29]], "batl": NaN}, {"timestamp": 1578715234259, "ltp": 5.6, "tv": 22.68, "trd": NaN, "batb": NaN, "batl": [[0, 6.4, 4.03]]}, {"timestamp": 1578715376260, "ltp": 5.6, "tv": 22.68, "trd": NaN, "batb": NaN, "batl": [[0, 6.4, 4.03]]}, {"timestamp": 1578715382153, "ltp": 5.6, "tv": 22.68, "trd": NaN, "batb": NaN, "batl": [[0, 6.2, 4.03]]}, {"timestamp": 1578721236464, "ltp": 5.6, "tv": 22.68, "trd": NaN, "batb": NaN, "batl": [[0, 5.8, 4.03]]}, {"timestamp": 1578721832999, "ltp": 5.6, "tv": 22.68, "trd": NaN, "batb": [[1, 4.6, 13.29], [2, 2.12, 3]], "batl": NaN}, {"timestamp": 1578723962658, "ltp": 5.6, "tv": 22.68, "trd": NaN, "batb": [[1, 4.5, 13.67]], "batl": NaN}, {"timestamp": 1578728714914, "ltp": 5.6, "tv": 22.68, "trd": NaN, "batb": [[0, 4.8, 6.66]], "batl": NaN}, {"timestamp": 1578729689981, "ltp": 5.6, "tv": 22.68, "trd": NaN, "batb": [[0, 4.8, 2.63]], "batl": NaN}, {"timestamp": 1578729691018, "ltp": 5.6, "tv": 22.68, "trd": NaN, "batb": [[0, 4.8, 6.66]], "batl": NaN}, {"timestamp": 1578729837936, "ltp": 5.6, "tv": 22.68, "trd": NaN, "batb": [[0, 4.9, 2], [1, 4.8, 6.66], [2, 4.5, 13.67]], "batl": [[0, 5.7, 2], [1, 5.8, 4.03]]}, {"timestamp": 1578729840215, "ltp": 5.6, "tv": 22.68, "trd": NaN, "batb": [[0, 4.9, 4.56], [1, 4.8, 4.03]], "batl": NaN}, {"timestamp": 1578730323997, "ltp": 5.6, "tv": 22.68, "trd": NaN, "batb": NaN, "batl": [[1, 5.8, 0]]}, {"timestamp": 1578730325807, "ltp": 5.6, "tv": 22.68, "trd": NaN, "batb": NaN, "batl": [[0, 5.7, 6.03]]}, {"timestamp": 1578731784571, "ltp": 5.6, "tv": 22.68, "trd": NaN, "batb": [[2, 4.5, 22.18]], "batl": NaN}, {"timestamp": 1578732771079, "ltp": 5.7, "tv": 25.18, "trd": [[5.7, 2.5]], "batb": NaN, "batl": [[0, 5.7, 3.53]]}, {"timestamp": 1578733187753, "ltp": 5.7, "tv": 25.64, "trd": [[5.7, 2.96]], "batb": NaN, "batl": [[0, 5.7, 3.07]]}, {"timestamp": 1578733229920, "ltp": 5.7, "tv": 25.64, "trd": NaN, "batb": [[1, 4.8, 16.62], [2, 4.5, 8.51]], "batl": NaN}, {"timestamp": 1578738566001, "ltp": 5.7, "tv": 28.71, "trd": [[5.7, 6.03]], "batb": [[1, 4.8, 12.59]], "batl": NaN}, {"timestamp": 1578738566922, "ltp": 5.7, "tv": 28.71, "trd": NaN, "batb": [[0, 4.9, 8.59]], "batl": NaN}, {"timestamp": 1578740876958, "ltp": 5.7, "tv": 28.71, "trd": NaN, "batb": [[0, 4.9, 11.82]], "batl": NaN}, {"timestamp": 1578741138964, "ltp": 5.7, "tv": 28.71, "trd": NaN, "batb": [[1, 4.7, 12.93]], "batl": NaN}, {"timestamp": 1578741146898, "ltp": 5.7, "tv": 28.71, "trd": NaN, "batb": [[0, 4.9, 7.79]], "batl": NaN}, {"timestamp": 1578741148114, "ltp": 5.7, "tv": 28.71, "trd": NaN, "batb": [[0, 4.9, 11.82]], "batl": NaN}, {"timestamp": 1578742313965, "ltp": 5.7, "tv": 28.71, "trd": NaN, "batb": [[1, 4.5, 22.18], [2, 2.12, 3]], "batl": NaN}, {"timestamp": 1578743102957, "ltp": 5.7, "tv": 28.71, "trd": NaN, "batb": [[1, 4.5, 24.92]], "batl": NaN}, {"timestamp": 1578743149126, "ltp": 5.7, "tv": 28.71, "trd": NaN, "batb": [[0, 5.2, 4], [1, 4.9, 11.82], [2, 4.5, 24.92]], "batl": NaN}, {"timestamp": 1578743150596, "ltp": 5.7, "tv": 28.71, "trd": NaN, "batb": [[1, 4.9, 7.79]], "batl": NaN}, {"timestamp": 1578743151307, "ltp": 5.7, "tv": 28.71, "trd": NaN, "batb": [[1, 5.1, 4.03], [2, 4.9, 7.79]], "batl": NaN}, {"timestamp": 1578743297112, "ltp": 5.2, "tv": 32.57, "trd": [[5.2, 3.86]], "batb": [[0, 5.2, 2.07]], "batl": NaN}, {"timestamp": 1578743451991, "ltp": 5.2, "tv": 36.26, "trd": [[5.2, 7.38], [5.5, 0.17]], "batb": [[0, 5.1, 4.34], [1, 4.9, 5.23], [2, 4.5, 24.92]], "batl": NaN}, {"timestamp": 1578743539179, "ltp": 5.1, "tv": 43.71, "trd": [[5.1, 6.84], [5.2, 8]], "batb": [[0, 4.9, 5.84], [1, 4.5, 24.92], [2, 2.12, 3]], "batl": NaN}, {"timestamp": 1578743549485, "ltp": 5.1, "tv": 43.71, "trd": NaN, "batb": [[0, 4.9, 8.4]], "batl": NaN}, {"timestamp": 1578743644022, "ltp": 5.1, "tv": 43.71, "trd": NaN, "batb": NaN, "batl": [[0, 6.2, 5]]}, {"timestamp": 1578744078653, "ltp": 5.1, "tv": 43.71, "trd": NaN, "batb": [[0, 4.9, 5.17], [1, 4.6, 3.23], [2, 4.5, 24.92]], "batl": NaN}, {"timestamp": 1578747142690, "ltp": 5.1, "tv": 43.71, "trd": NaN, "batb": [[1, 4.5, 24.92], [2, 2.12, 3]], "batl": NaN}, {"timestamp": 1578747253946, "ltp": 5.1, "tv": 43.71, "trd": NaN, "batb": [[0, 4.9, 2.61]], "batl": NaN}, {"timestamp": 1578747267582, "ltp": 5.1, "tv": 43.71, "trd": NaN, "batb": [[0, 4.9, 5.17]], "batl": NaN}, {"timestamp": 1578747489705, "ltp": 4.9, "tv": 47.45, "trd": [[4.9, 2.52], [5.1, 8.06]], "batb": [[0, 4.9, 7.33]], "batl": [[0, 5.9, 4.03]]}, {"timestamp": 1578747497579, "ltp": 4.9, "tv": 47.45, "trd": NaN, "batb": [[0, 4.9, 3.3]], "batl": NaN}, {"timestamp": 1578747498384, "ltp": 4.9, "tv": 47.45, "trd": NaN, "batb": [[0, 4.9, 7.33]], "batl": NaN}, {"timestamp": 1578747505669, "ltp": 4.9, "tv": 47.45, "trd": NaN, "batb": [[0, 4.9, 3.3]], "batl": NaN}, {"timestamp": 1578747506302, "ltp": 4.9, "tv": 47.45, "trd": NaN, "batb": [[0, 4.9, 7.33]], "batl": NaN}, {"timestamp": 1578747514887, "ltp": 4.9, "tv": 47.45, "trd": NaN, "batb": [[0, 4.9, 3.3]], "batl": NaN}, {"timestamp": 1578747515693, "ltp": 4.9, "tv": 47.45, "trd": NaN, "batb": [[0, 4.9, 7.33]], "batl": NaN}, {"timestamp": 1578747531939, "ltp": 4.9, "tv": 47.45, "trd": NaN, "batb": [[0, 4.9, 3.3]], "batl": NaN}, {"timestamp": 1578747532828, "ltp": 4.9, "tv": 47.45, "trd": NaN, "batb": [[0, 4.9, 7.33]], "batl": NaN}, {"timestamp": 1578747536113, "ltp": 4.9, "tv": 47.45, "trd": NaN, "batb": NaN, "batl": [[0, 5.8, 8.51], [1, 5.9, 4.03]]}, {"timestamp": 1578747552762, "ltp": 4.9, "tv": 47.45, "trd": NaN, "batb": [[0, 4.9, 3.3]], "batl": NaN}, {"timestamp": 1578747553843, "ltp": 4.9, "tv": 47.45, "trd": NaN, "batb": [[0, 4.9, 7.33]], "batl": NaN}, {"timestamp": 1578747562942, "ltp": 4.9, "tv": 47.45, "trd": NaN, "batb": [[0, 4.9, 3.3]], "batl": NaN}, {"timestamp": 1578747563692, "ltp": 4.9, "tv": 47.45, "trd": NaN, "batb": [[0, 5, 4.03], [1, 4.9, 3.3], [2, 4.5, 24.92]], "batl": NaN}, {"timestamp": 1578747574844, "ltp": 4.9, "tv": 47.45, "trd": NaN, "batb": [[0, 5, 6.53], [1, 4.5, 25.66], [2, 2.12, 3]], "batl": NaN}, {"timestamp": 1578748294449, "ltp": 4.9, "tv": 47.45, "trd": NaN, "batb": [[0, 5, 4.03]], "batl": NaN}, {"timestamp": 1578750030658, "ltp": 4.9, "tv": 47.45, "trd": NaN, "batb": NaN, "batl": [[1, 5.9, 0]]}, {"timestamp": 1578750031967, "ltp": 4.9, "tv": 47.45, "trd": NaN, "batb": NaN, "batl": [[0, 5.8, 12.54]]}, {"timestamp": 1578750032879, "ltp": 4.9, "tv": 47.45, "trd": NaN, "batb": NaN, "batl": [[0, 5.8, 8.51]]}, {"timestamp": 1578750033756, "ltp": 4.9, "tv": 47.45, "trd": NaN, "batb": NaN, "batl": [[0, 5.6, 4.03], [1, 5.8, 8.51]]}, {"timestamp": 1578750035867, "ltp": 4.9, "tv": 47.45, "trd": NaN, "batb": NaN, "batl": [[1, 5.8, 0]]}, {"timestamp": 1578750055900, "ltp": 4.9, "tv": 47.45, "trd": NaN, "batb": NaN, "batl": [[0, 5.3, 8.51]]}, {"timestamp": 1578750076932, "ltp": 5.0, "tv": 51.48, "trd": [[5, 4.03]], "batb": [[0, 4.5, 25.66], [1, 2.12, 3], [2, 1.5, 38.28]], "batl": NaN}, {"timestamp": 1578750077150, "ltp": 5.0, "tv": 51.48, "trd": NaN, "batb": NaN, "batl": [[1, 5.5, 4.03]]}, {"timestamp": 1578750084229, "ltp": 5.0, "tv": 51.48, "trd": NaN, "batb": [[0, 4.5, 28.52]], "batl": NaN}, {"timestamp": 1578750089924, "ltp": 5.0, "tv": 83.76, "trd": [[5, 36.31]], "batb": [[0, 4.9, 1.5], [1, 4.5, 27.78], [2, 2.12, 3]], "batl": NaN}, {"timestamp": 1578750094855, "ltp": 5.0, "tv": 84.52, "trd": [[5, 37.07]], "batb": [[0, 4.9, 3.3], [1, 4.5, 24.92]], "batl": NaN}, {"timestamp": 1578750097935, "ltp": 5.0, "tv": 84.52, "trd": NaN, "batb": NaN, "batl": [[0, 5.5, 4.03], [1, 5.5, 0]]}, {"timestamp": 1578750128719, "ltp": 4.9, "tv": 87.82, "trd": [[4.9, 5.82]], "batb": [[0, 4.5, 24.92], [1, 2.12, 3], [2, 1.5, 38.28]], "batl": NaN}, {"timestamp": 1578750129688, "ltp": 4.9, "tv": 87.82, "trd": NaN, "batb": [[0, 4.8, 2.63], [1, 4.5, 24.92], [2, 2.12, 3]], "batl": NaN}, {"timestamp": 1578750136914, "ltp": 4.9, "tv": 87.82, "trd": NaN, "batb": NaN, "batl": [[0, 5.1, 8.51], [1, 5.5, 4.03]]}, {"timestamp": 1578750137989, "ltp": 4.9, "tv": 87.82, "trd": NaN, "batb": NaN, "batl": [[1, 5.5, 0]]}, {"timestamp": 1578750139913, "ltp": 4.9, "tv": 87.82, "trd": NaN, "batb": NaN, "batl": [[1, 5.4, 4.03]]}, {"timestamp": 1578750141519, "ltp": 4.9, "tv": 87.82, "trd": NaN, "batb": NaN, "batl": [[0, 5.4, 4.03], [1, 5.4, 0]]}, {"timestamp": 1578750150225, "ltp": 4.9, "tv": 87.82, "trd": NaN, "batb": [[1, 4.5, 25.5]], "batl": NaN}, {"timestamp": 1578750235672, "ltp": 4.9, "tv": 87.82, "trd": NaN, "batb": NaN, "batl": [[1, 5.7, 8.51]]}, {"timestamp": 1578750482932, "ltp": 5.4, "tv": 88.24, "trd": [[5.4, 0.42]], "batb": NaN, "batl": [[0, 5.4, 3.61]]}, {"timestamp": 1578750623178, "ltp": 5.4, "tv": 88.67, "trd": [[5.4, 0.84]], "batb": NaN, "batl": [[0, 5.4, 3.18]]}, {"timestamp": 1578751164854, "ltp": 5.4, "tv": 88.67, "trd": NaN, "batb": NaN, "batl": [[0, 5.3, 10.55], [1, 5.4, 3.18], [2, 5.7, 8.51]]}, {"timestamp": 1578751166994, "ltp": 5.4, "tv": 88.67, "trd": NaN, "batb": NaN, "batl": [[2, 5.7, 0]]}, {"timestamp": 1578751333664, "ltp": 5.4, "tv": 88.67, "trd": NaN, "batb": [[0, 4.8, 4.33], [1, 4.7, 2.28], [2, 4.5, 24.92]], "batl": [[0, 5.2, 1.7], [1, 5.3, 12.25], [2, 5.4, 3.18]]}, {"timestamp": 1578751740857, "ltp": 5.4, "tv": 88.67, "trd": NaN, "batb": NaN, "batl": [[1, 5.3, 1.7]]}, {"timestamp": 1578752667179, "ltp": 5.3, "tv": 90.48, "trd": [[5.2, 9.7], [5.3, 0.11]], "batb": NaN, "batl": [[0, 5.3, 1.59], [1, 5.4, 3.18], [2, 5.7, 8.51]]}, {"timestamp": 1578752669981, "ltp": 5.3, "tv": 90.48, "trd": NaN, "batb": NaN, "batl": [[0, 5.4, 3.18], [1, 5.7, 8.51], [2, 5.7, 0]]}, {"timestamp": 1578752670199, "ltp": 5.3, "tv": 90.48, "trd": NaN, "batb": NaN, "batl": [[0, 5.4, 4.89], [1, 5.5, 1.7], [2, 5.7, 8.51]]}, {"timestamp": 1578754145874, "ltp": 5.3, "tv": 90.48, "trd": NaN, "batb": [[2, 4.5, 8.51]], "batl": NaN}, {"timestamp": 1578754833999, "ltp": 5.3, "tv": 90.48, "trd": NaN, "batb": NaN, "batl": [[0, 5.3, 1.7], [1, 5.4, 4.89], [2, 5.5, 1.7]]}, {"timestamp": 1578754835572, "ltp": 5.3, "tv": 90.48, "trd": NaN, "batb": NaN, "batl": [[2, 5.5, 10.21]]}, {"timestamp": 1578754840815, "ltp": 5.3, "tv": 90.48, "trd": NaN, "batb": NaN, "batl": [[2, 5.5, 1.7]]}, {"timestamp": 1578755377376, "ltp": 5.0, "tv": 92.35, "trd": [[5, 38.94]], "batb": NaN, "batl": NaN}, {"timestamp": 1578755433983, "ltp": 5.0, "tv": 92.35, "trd": NaN, "batb": NaN, "batl": [[0, 5.1, 8.51], [1, 5.3, 1.7], [2, 5.4, 4.89]]}, {"timestamp": 1578755434888, "ltp": 5.0, "tv": 92.35, "trd": NaN, "batb": NaN, "batl": [[0, 5.1, 10.21], [1, 5.2, 1.7], [2, 5.3, 1.7]]}, {"timestamp": 1578755436985, "ltp": 5.0, "tv": 92.35, "trd": NaN, "batb": NaN, "batl": [[0, 5.1, 1.7]]}, {"timestamp": 1578755474044, "ltp": 5.0, "tv": 92.35, "trd": NaN, "batb": NaN, "batl": [[0, 5.2, 1.7], [1, 5.3, 1.7], [2, 5.4, 4.89]]}, {"timestamp": 1578755698973, "ltp": 5.0, "tv": 92.35, "trd": NaN, "batb": NaN, "batl": [[0, 5.1, 8.51], [1, 5.2, 1.7], [2, 5.3, 1.7]]}, {"timestamp": 1578755700022, "ltp": 5.0, "tv": 92.35, "trd": NaN, "batb": NaN, "batl": [[0, 5.1, 10.21]]}, {"timestamp": 1578755702964, "ltp": 5.0, "tv": 92.35, "trd": NaN, "batb": NaN, "batl": [[0, 5.1, 1.7]]}, {"timestamp": 1578755704035, "ltp": 5.0, "tv": 92.35, "trd": NaN, "batb": NaN, "batl": [[0, 5.2, 1.7], [1, 5.3, 1.7], [2, 5.4, 4.89]]}, {"timestamp": 1578755844910, "ltp": 5.0, "tv": 92.35, "trd": NaN, "batb": NaN, "batl": [[0, 5.1, 8.51], [1, 5.2, 1.7], [2, 5.3, 1.7]]}, {"timestamp": 1578755845828, "ltp": 5.0, "tv": 92.35, "trd": NaN, "batb": NaN, "batl": [[0, 5.1, 10.21]]}, {"timestamp": 1578755847857, "ltp": 5.0, "tv": 92.35, "trd": NaN, "batb": NaN, "batl": [[0, 5.2, 1.7], [1, 5.3, 1.7], [2, 5.4, 4.89]]}, {"timestamp": 1578755985846, "ltp": 5.0, "tv": 92.35, "trd": NaN, "batb": NaN, "batl": [[0, 5.1, 8.51], [1, 5.2, 1.7], [2, 5.3, 1.7]]}, {"timestamp": 1578755986852, "ltp": 5.0, "tv": 92.35, "trd": NaN, "batb": NaN, "batl": [[0, 5.1, 10.21]]}, {"timestamp": 1578755988549, "ltp": 5.0, "tv": 92.35, "trd": NaN, "batb": NaN, "batl": [[0, 5.1, 1.7]]}, {"timestamp": 1578755990749, "ltp": 5.0, "tv": 92.35, "trd": NaN, "batb": NaN, "batl": [[0, 5.2, 1.7], [1, 5.3, 1.7], [2, 5.4, 4.89]]}, {"timestamp": 1578756129883, "ltp": 5.0, "tv": 92.35, "trd": NaN, "batb": NaN, "batl": [[0, 5.1, 8.51], [1, 5.2, 1.7], [2, 5.3, 1.7]]}, {"timestamp": 1578756130911, "ltp": 5.0, "tv": 92.35, "trd": NaN, "batb": NaN, "batl": [[0, 5.1, 10.21]]}, {"timestamp": 1578756132914, "ltp": 5.0, "tv": 92.35, "trd": NaN, "batb": NaN, "batl": [[0, 5.2, 1.7], [1, 5.3, 1.7], [2, 5.4, 4.89]]}, {"timestamp": 1578756246569, "ltp": 5.0, "tv": 92.35, "trd": NaN, "batb": NaN, "batl": [[0, 5.1, 8.51], [1, 5.2, 1.7], [2, 5.3, 1.7]]}, {"timestamp": 1578756248845, "ltp": 5.0, "tv": 92.35, "trd": NaN, "batb": NaN, "batl": [[0, 5.1, 1.7]]}, {"timestamp": 1578756249676, "ltp": 5.0, "tv": 92.35, "trd": NaN, "batb": NaN, "batl": [[0, 5.2, 1.7], [1, 5.3, 1.7], [2, 5.4, 4.89]]}, {"timestamp": 1578756416876, "ltp": 5.0, "tv": 92.35, "trd": NaN, "batb": NaN, "batl": [[0, 5.1, 8.51], [1, 5.2, 1.7], [2, 5.3, 1.7]]}, {"timestamp": 1578756417384, "ltp": 5.0, "tv": 92.35, "trd": NaN, "batb": NaN, "batl": [[0, 5.1, 10.21]]}, {"timestamp": 1578756419654, "ltp": 5.0, "tv": 92.35, "trd": NaN, "batb": NaN, "batl": [[0, 5.1, 1.7]]}, {"timestamp": 1578756420474, "ltp": 5.0, "tv": 92.35, "trd": NaN, "batb": NaN, "batl": [[0, 5.2, 1.7], [1, 5.3, 1.7], [2, 5.4, 4.89]]}, {"timestamp": 1578756553686, "ltp": 5.0, "tv": 92.35, "trd": NaN, "batb": NaN, "batl": [[0, 5.1, 8.51], [1, 5.2, 1.7], [2, 5.3, 1.7]]}, {"timestamp": 1578756554511, "ltp": 5.0, "tv": 92.35, "trd": NaN, "batb": NaN, "batl": [[0, 5.1, 10.21]]}, {"timestamp": 1578756556721, "ltp": 5.0, "tv": 92.35, "trd": NaN, "batb": NaN, "batl": [[0, 5.1, 1.7]]}, {"timestamp": 1578756558937, "ltp": 5.0, "tv": 92.35, "trd": NaN, "batb": NaN, "batl": [[0, 5.2, 1.7], [1, 5.3, 1.7], [2, 5.4, 4.89]]}, {"timestamp": 1578756744847, "ltp": 5.0, "tv": 92.35, "trd": NaN, "batb": NaN, "batl": [[0, 5.1, 8.51], [1, 5.2, 1.7], [2, 5.3, 1.7]]}, {"timestamp": 1578756745730, "ltp": 5.0, "tv": 92.35, "trd": NaN, "batb": NaN, "batl": [[0, 5.1, 10.21]]}, {"timestamp": 1578756747461, "ltp": 5.0, "tv": 92.35, "trd": NaN, "batb": NaN, "batl": [[0, 5.1, 1.7]]}, {"timestamp": 1578756748061, "ltp": 5.0, "tv": 92.35, "trd": NaN, "batb": NaN, "batl": [[0, 5.2, 1.7], [1, 5.3, 1.7], [2, 5.4, 4.89]]}, {"timestamp": 1578756907873, "ltp": 5.0, "tv": 92.35, "trd": NaN, "batb": NaN, "batl": [[0, 5.1, 8.51], [1, 5.2, 1.7], [2, 5.3, 1.7]]}, {"timestamp": 1578756908624, "ltp": 5.0, "tv": 92.35, "trd": NaN, "batb": NaN, "batl": [[0, 5.1, 10.21]]}, {"timestamp": 1578756933887, "ltp": 5.0, "tv": 92.35, "trd": NaN, "batb": NaN, "batl": [[0, 5.1, 1.7]]}, {"timestamp": 1578756935060, "ltp": 5.0, "tv": 92.35, "trd": NaN, "batb": NaN, "batl": [[0, 5.2, 1.7], [1, 5.3, 1.7], [2, 5.4, 4.89]]}, {"timestamp": 1578757051570, "ltp": 5.0, "tv": 92.35, "trd": NaN, "batb": NaN, "batl": [[0, 5.1, 8.51], [1, 5.2, 1.7], [2, 5.3, 1.7]]}, {"timestamp": 1578757052191, "ltp": 5.0, "tv": 92.35, "trd": NaN, "batb": NaN, "batl": [[0, 5.1, 10.21]]}, {"timestamp": 1578757053790, "ltp": 5.0, "tv": 92.35, "trd": NaN, "batb": NaN, "batl": [[0, 5.1, 1.7]]}, {"timestamp": 1578757262189, "ltp": 5.0, "tv": 92.35, "trd": NaN, "batb": NaN, "batl": [[0, 5.1, 10.21]]}, {"timestamp": 1578757264490, "ltp": 5.0, "tv": 92.35, "trd": NaN, "batb": NaN, "batl": [[0, 5.1, 1.7]]}, {"timestamp": 1578757480720, "ltp": 5.0, "tv": 92.35, "trd": NaN, "batb": NaN, "batl": [[0, 5.1, 10.21]]}, {"timestamp": 1578757484624, "ltp": 5.0, "tv": 92.35, "trd": NaN, "batb": NaN, "batl": [[0, 5.1, 1.7]]}, {"timestamp": 1578757628736, "ltp": 5.0, "tv": 92.35, "trd": NaN, "batb": NaN, "batl": [[0, 5.1, 10.21]]}, {"timestamp": 1578757634051, "ltp": 5.0, "tv": 92.35, "trd": NaN, "batb": NaN, "batl": [[0, 5.1, 1.7]]}, {"timestamp": 1578757758738, "ltp": 5.0, "tv": 92.35, "trd": NaN, "batb": NaN, "batl": [[0, 5.1, 10.21]]}, {"timestamp": 1578757762138, "ltp": 5.0, "tv": 92.35, "trd": NaN, "batb": NaN, "batl": [[0, 5.1, 1.7]]}, {"timestamp": 1578758013589, "ltp": 5.0, "tv": 92.35, "trd": NaN, "batb": NaN, "batl": [[0, 5.1, 10.21]]}, {"timestamp": 1578758018266, "ltp": 5.0, "tv": 92.35, "trd": NaN, "batb": NaN, "batl": [[0, 5.1, 1.7]]}, {"timestamp": 1578758185748, "ltp": 5.0, "tv": 92.35, "trd": NaN, "batb": NaN, "batl": [[0, 5.1, 10.21]]}, {"timestamp": 1578758188537, "ltp": 5.0, "tv": 92.35, "trd": NaN, "batb": NaN, "batl": [[0, 5.1, 1.7]]}, {"timestamp": 1578758336904, "ltp": 5.0, "tv": 92.35, "trd": NaN, "batb": NaN, "batl": [[0, 5.1, 10.21]]}, {"timestamp": 1578758340513, "ltp": 5.0, "tv": 92.35, "trd": NaN, "batb": NaN, "batl": [[0, 5.1, 1.7]]}, {"timestamp": 1578758403674, "ltp": 5.0, "tv": 92.35, "trd": NaN, "batb": NaN, "batl": [[0, 5.1, 10.21]]}, {"timestamp": 1578758408874, "ltp": 5.0, "tv": 92.35, "trd": NaN, "batb": NaN, "batl": [[0, 5.1, 1.7]]}, {"timestamp": 1578758651542, "ltp": 5.0, "tv": 92.35, "trd": NaN, "batb": NaN, "batl": [[0, 5.1, 10.21]]}, {"timestamp": 1578758653436, "ltp": 5.0, "tv": 92.35, "trd": NaN, "batb": NaN, "batl": [[0, 5.1, 1.7]]}, {"timestamp": 1578758837035, "ltp": 5.0, "tv": 92.35, "trd": NaN, "batb": NaN, "batl": [[0, 5.2, 1.7], [1, 5.3, 1.7], [2, 5.4, 4.89]]}, {"timestamp": 1578759130860, "ltp": 5.0, "tv": 92.35, "trd": NaN, "batb": NaN, "batl": [[0, 5.1, 8.51], [1, 5.2, 1.7], [2, 5.3, 1.7]]}, {"timestamp": 1578759132354, "ltp": 5.0, "tv": 92.35, "trd": NaN, "batb": NaN, "batl": [[0, 5.1, 10.21]]}, {"timestamp": 1578759133847, "ltp": 5.0, "tv": 92.35, "trd": NaN, "batb": NaN, "batl": [[0, 5.2, 1.7], [1, 5.3, 1.7], [2, 5.4, 4.89]]}, {"timestamp": 1578759353913, "ltp": 5.0, "tv": 92.35, "trd": NaN, "batb": NaN, "batl": [[0, 5.1, 8.51], [1, 5.2, 1.7], [2, 5.3, 1.7]]}, {"timestamp": 1578759357874, "ltp": 5.0, "tv": 92.35, "trd": NaN, "batb": NaN, "batl": [[0, 5.2, 1.7], [1, 5.3, 1.7], [2, 5.4, 4.89]]}, {"timestamp": 1578759478047, "ltp": 5.0, "tv": 92.35, "trd": NaN, "batb": NaN, "batl": [[0, 5.1, 8.51], [1, 5.2, 1.7], [2, 5.3, 1.7]]}, {"timestamp": 1578759481371, "ltp": 5.0, "tv": 92.35, "trd": NaN, "batb": NaN, "batl": [[0, 5.2, 1.7], [1, 5.3, 1.7], [2, 5.4, 4.89]]}, {"timestamp": 1578759504967, "ltp": 5.2, "tv": 96.05, "trd": [[5.2, 13.41]], "batb": NaN, "batl": [[0, 5.3, 1.7], [1, 5.4, 4.89], [2, 5.4, 0]]}, {"timestamp": 1578759607946, "ltp": 5.2, "tv": 96.05, "trd": NaN, "batb": NaN, "batl": [[0, 5.1, 8.51], [1, 5.3, 1.7], [2, 5.4, 4.89]]}, {"timestamp": 1578759610048, "ltp": 5.2, "tv": 96.05, "trd": NaN, "batb": NaN, "batl": [[0, 5.2, 1.7]]}, {"timestamp": 1578759752825, "ltp": 5.2, "tv": 96.05, "trd": NaN, "batb": NaN, "batl": [[0, 5.1, 8.51], [1, 5.2, 1.7], [2, 5.3, 1.7]]}, {"timestamp": 1578759757589, "ltp": 5.2, "tv": 96.05, "trd": NaN, "batb": NaN, "batl": [[0, 5.2, 1.7], [1, 5.3, 1.7], [2, 5.4, 4.89]]}, {"timestamp": 1578759812668, "ltp": 5.2, "tv": 107.75, "trd": [[5.2, 25.11]], "batb": NaN, "batl": [[0, 5.3, 1.7], [1, 5.4, 4.89], [2, 5.4, 0]]}, {"timestamp": 1578759813286, "ltp": 5.2, "tv": 107.75, "trd": NaN, "batb": NaN, "batl": [[0, 5.4, 4.89], [1, 5.5, 1.7]]}, {"timestamp": 1578759820976, "ltp": 5.2, "tv": 107.75, "trd": NaN, "batb": NaN, "batl": [[1, 5.5, 10.21]]}, {"timestamp": 1578759823893, "ltp": 5.2, "tv": 107.75, "trd": NaN, "batb": NaN, "batl": [[0, 5.4, 8.47]]}, {"timestamp": 1578759825857, "ltp": 5.2, "tv": 107.75, "trd": NaN, "batb": NaN, "batl": [[0, 5.3, 1.7], [1, 5.4, 8.47], [2, 5.5, 10.21]]}, {"timestamp": 1578759833002, "ltp": 5.2, "tv": 107.75, "trd": NaN, "batb": NaN, "batl": [[2, 5.5, 1.7]]}, {"timestamp": 1578762105984, "ltp": 5.2, "tv": 107.75, "trd": NaN, "batb": NaN, "batl": [[0, 5.1, 25.54], [1, 5.3, 1.7], [2, 5.4, 8.47]]}, {"timestamp": 1578762106594, "ltp": 5.2, "tv": 107.75, "trd": NaN, "batb": NaN, "batl": [[1, 5.2, 1.7], [2, 5.3, 1.7]]}, {"timestamp": 1578762108190, "ltp": 5.2, "tv": 107.75, "trd": NaN, "batb": NaN, "batl": [[0, 5.1, 34.05]]}, {"timestamp": 1578762646128, "ltp": 5.1, "tv": 115.75, "trd": [[5.1, 16.06]], "batb": NaN, "batl": [[0, 5.1, 30.05]]}, {"timestamp": 1578762703786, "ltp": 5.1, "tv": 115.75, "trd": NaN, "batb": NaN, "batl": [[0, 5.1, 21.54]]}, {"timestamp": 1578762711986, "ltp": 5.1, "tv": 115.75, "trd": NaN, "batb": NaN, "batl": [[0, 5.1, 30.05]]}, {"timestamp": 1578762733029, "ltp": 5.1, "tv": 115.75, "trd": NaN, "batb": NaN, "batl": [[0, 5.1, 21.54]]}, {"timestamp": 1578762991850, "ltp": 5.1, "tv": 115.75, "trd": NaN, "batb": NaN, "batl": [[0, 5.2, 1.7], [1, 5.3, 23.24], [2, 5.4, 8.47]]}, {"timestamp": 1578763004045, "ltp": 5.1, "tv": 115.75, "trd": NaN, "batb": [[0, 5, 8.03], [1, 4.9, 1.7], [2, 4.8, 4.33]], "batl": NaN}, {"timestamp": 1578763049822, "ltp": 5.1, "tv": 115.75, "trd": NaN, "batb": NaN, "batl": [[2, 5.4, 4.89]]}, {"timestamp": 1578763050818, "ltp": 5.1, "tv": 115.75, "trd": NaN, "batb": NaN, "batl": [[1, 5.3, 26.56]]}, {"timestamp": 1578763951320, "ltp": 5.1, "tv": 115.75, "trd": NaN, "batb": [[0, 5, 1.7]], "batl": NaN}, {"timestamp": 1578763984803, "ltp": 5.1, "tv": 115.75, "trd": NaN, "batb": [[0, 5, 8.03]], "batl": NaN}, {"timestamp": 1578764045441, "ltp": 5.1, "tv": 115.75, "trd": NaN, "batb": [[0, 5, 1.7]], "batl": NaN}, {"timestamp": 1578764055224, "ltp": 5.1, "tv": 115.75, "trd": NaN, "batb": [[0, 5, 8.03]], "batl": NaN}, {"timestamp": 1578764288738, "ltp": 5.1, "tv": 115.75, "trd": NaN, "batb": NaN, "batl": [[0, 5.2, 16.7]]}, {"timestamp": 1578764301444, "ltp": 5.1, "tv": 115.75, "trd": NaN, "batb": NaN, "batl": [[0, 5.2, 21.7]]}, {"timestamp": 1578764384625, "ltp": 5.1, "tv": 115.75, "trd": NaN, "batb": NaN, "batl": [[0, 5.1, 8.51], [1, 5.2, 21.7], [2, 5.3, 26.56]]}, {"timestamp": 1578764393958, "ltp": 5.1, "tv": 115.75, "trd": NaN, "batb": [[0, 5, 1.7]], "batl": NaN}, {"timestamp": 1578764549898, "ltp": 5.1, "tv": 115.75, "trd": NaN, "batb": [[0, 4.9, 1.7], [1, 4.8, 4.33], [2, 4.7, 2.28]], "batl": [[0, 5.1, 10.21]]}, {"timestamp": 1578764578006, "ltp": 5.1, "tv": 115.75, "trd": NaN, "batb": NaN, "batl": [[1, 5.2, 16.7]]}, {"timestamp": 1578764578713, "ltp": 5.1, "tv": 115.75, "trd": NaN, "batb": NaN, "batl": [[0, 5.1, 15.21]]}, {"timestamp": 1578764586747, "ltp": 5.1, "tv": 115.75, "trd": NaN, "batb": NaN, "batl": [[0, 5.1, 30.21], [1, 5.2, 1.7]]}, {"timestamp": 1578765254986, "ltp": 5.1, "tv": 115.75, "trd": NaN, "batb": [[0, 5, 17.02], [1, 4.9, 1.7], [2, 4.8, 4.33]], "batl": NaN}, {"timestamp": 1578765256056, "ltp": 5.1, "tv": 115.75, "trd": NaN, "batb": [[0, 5, 18.73]], "batl": NaN}, {"timestamp": 1578765600836, "ltp": 5.0, "tv": 154.48, "trd": [[5, 77.66]], "batb": [[0, 4.9, 1.7], [1, 4.8, 4.33], [2, 4.7, 2.28]], "batl": NaN}, {"timestamp": 1578765602051, "ltp": 5.0, "tv": 154.48, "trd": NaN, "batb": NaN, "batl": [[0, 5, 1.7], [1, 5.1, 30.21], [2, 5.2, 1.7]]}, {"timestamp": 1578765602652, "ltp": 5.0, "tv": 154.48, "trd": NaN, "batb": [[0, 4.8, 4.33], [1, 4.7, 2.28], [2, 4.5, 8.51]], "batl": NaN}, {"timestamp": 1578765606704, "ltp": 5.0, "tv": 154.48, "trd": NaN, "batb": NaN, "batl": [[0, 5.1, 30.21], [1, 5.2, 1.7], [2, 5.3, 26.56]]}, {"timestamp": 1578765673933, "ltp": 5.0, "tv": 154.48, "trd": NaN, "batb": [[0, 4.9, 8.11], [1, 4.8, 4.33], [2, 4.7, 2.28]], "batl": NaN}, {"timestamp": 1578765674901, "ltp": 5.0, "tv": 154.48, "trd": NaN, "batb": [[0, 4.9, 9.82]], "batl": NaN}, {"timestamp": 1578765684010, "ltp": 5.0, "tv": 154.48, "trd": NaN, "batb": [[0, 4.9, 12.38], [1, 4.8, 1.7]], "batl": NaN}, {"timestamp": 1578765732979, "ltp": 5.0, "tv": 154.48, "trd": NaN, "batb": NaN, "batl": [[0, 5.1, 28.51]]}, {"timestamp": 1578765733980, "ltp": 5.0, "tv": 154.48, "trd": NaN, "batb": [[0, 5, 1.7], [1, 4.9, 12.38], [2, 4.8, 1.7]], "batl": NaN}, {"timestamp": 1578765753593, "ltp": 5.0, "tv": 154.48, "trd": NaN, "batb": [[1, 4.9, 4.26]], "batl": NaN}, {"timestamp": 1578765782808, "ltp": 5.0, "tv": 154.48, "trd": NaN, "batb": [[1, 4.9, 1.7]], "batl": NaN}, {"timestamp": 1578765950008, "ltp": 5.0, "tv": 154.48, "trd": NaN, "batb": NaN, "batl": [[0, 5.1, 30.21]]}, {"timestamp": 1578765970033, "ltp": 5.0, "tv": 154.48, "trd": NaN, "batb": NaN, "batl": [[0, 5.1, 42.12], [1, 5.2, 70.45], [2, 5.3, 94.02]]}, {"timestamp": 1578766248985, "ltp": 5.1, "tv": 238.73, "trd": [[5.1, 100.3]], "batb": [[0, 5.1, 28], [1, 5, 1.7], [2, 4.9, 10.56]], "batl": [[0, 5.2, 70.45], [1, 5.3, 94.02], [2, 5.4, 69.39]]}, {"timestamp": 1578766251036, "ltp": 5.1, "tv": 238.73, "trd": NaN, "batb": [[2, 4.9, 61.9]], "batl": NaN}, {"timestamp": 1578766261029, "ltp": 5.1, "tv": 238.73, "trd": NaN, "batb": [[1, 5, 9.62]], "batl": NaN}, {"timestamp": 1578766352846, "ltp": 5.1, "tv": 238.73, "trd": NaN, "batb": NaN, "batl": [[0, 5.2, 1.7]]}, {"timestamp": 1578766353430, "ltp": 5.1, "tv": 238.73, "trd": NaN, "batb": [[0, 5.1, 31.93]], "batl": NaN}, {"timestamp": 1578766356965, "ltp": 5.1, "tv": 238.73, "trd": NaN, "batb": [[2, 4.9, 53.04]], "batl": NaN}, {"timestamp": 1578766357178, "ltp": 5.1, "tv": 238.73, "trd": NaN, "batb": [[0, 5.1, 40.44]], "batl": NaN}, {"timestamp": 1578766360870, "ltp": 5.1, "tv": 238.73, "trd": NaN, "batb": [[1, 5, 62.29]], "batl": NaN}, {"timestamp": 1578766361682, "ltp": 5.1, "tv": 238.73, "trd": NaN, "batb": NaN, "batl": [[0, 5.2, 23.24], [1, 5.3, 72.48]]}, {"timestamp": 1578766422043, "ltp": 5.1, "tv": 278.73, "trd": [[5.1, 140.3]], "batb": [[0, 5.1, 20.44]], "batl": NaN}, {"timestamp": 1578766423018, "ltp": 5.1, "tv": 278.73, "trd": NaN, "batb": [[0, 5.1, 21.44]], "batl": NaN}, {"timestamp": 1578766424035, "ltp": 5.1, "tv": 278.73, "trd": NaN, "batb": [[0, 5.1, 16.51]], "batl": [[0, 5.2, 91.99]]}, {"timestamp": 1578766575002, "ltp": 5.1, "tv": 278.73, "trd": NaN, "batb": [[1, 5, 54.38]], "batl": NaN}, {"timestamp": 1578766591042, "ltp": 5.1, "tv": 278.73, "trd": NaN, "batb": [[1, 5, 62.29]], "batl": NaN}, {"timestamp": 1578766620503, "ltp": 5.1, "tv": 278.73, "trd": NaN, "batb": [[1, 5, 82.29]], "batl": NaN}, {"timestamp": 1578766631702, "ltp": 5.1, "tv": 278.73, "trd": NaN, "batb": [[1, 5, 74.38]], "batl": NaN}, {"timestamp": 1578766642045, "ltp": 5.1, "tv": 278.73, "trd": NaN, "batb": [[1, 5, 82.29]], "batl": NaN}, {"timestamp": 1578766825550, "ltp": 5.2, "tv": 286.2, "trd": [[5.2, 32.58]], "batb": NaN, "batl": [[0, 5.2, 88.25]]}, {"timestamp": 1578766827045, "ltp": 5.2, "tv": 286.2, "trd": NaN, "batb": [[0, 5.1, 21.57]], "batl": [[0, 5.2, 93.22]]}, {"timestamp": 1578766827803, "ltp": 5.2, "tv": 286.2, "trd": NaN, "batb": NaN, "batl": [[0, 5.2, 24.46], [1, 5.3, 5.03]]}, {"timestamp": 1578766828972, "ltp": 5.2, "tv": 286.2, "trd": NaN, "batb": NaN, "batl": [[0, 5.2, 19.5], [2, 5.4, 72.35]]}, {"timestamp": 1578766942891, "ltp": 5.2, "tv": 286.2, "trd": NaN, "batb": NaN, "batl": [[0, 5.2, 22.37]]}, {"timestamp": 1578766943891, "ltp": 5.2, "tv": 286.2, "trd": NaN, "batb": NaN, "batl": [[0, 5.2, 19.5]]}, {"timestamp": 1578766944898, "ltp": 5.2, "tv": 286.2, "trd": NaN, "batb": NaN, "batl": [[0, 5.2, 22.37]]}, {"timestamp": 1578766945796, "ltp": 5.2, "tv": 286.2, "trd": NaN, "batb": NaN, "batl": [[0, 5.2, 19.5]]}, {"timestamp": 1578766946334, "ltp": 5.2, "tv": 286.2, "trd": NaN, "batb": NaN, "batl": [[0, 5.2, 22.37]]}, {"timestamp": 1578766948038, "ltp": 5.2, "tv": 286.2, "trd": NaN, "batb": NaN, "batl": [[0, 5.2, 19.5]]}, {"timestamp": 1578766949034, "ltp": 5.2, "tv": 286.2, "trd": NaN, "batb": NaN, "batl": [[0, 5.2, 22.37]]}, {"timestamp": 1578766949624, "ltp": 5.2, "tv": 286.2, "trd": NaN, "batb": NaN, "batl": [[0, 5.2, 19.5]]}, {"timestamp": 1578766950413, "ltp": 5.2, "tv": 286.2, "trd": NaN, "batb": NaN, "batl": [[0, 5.2, 22.37]]}, {"timestamp": 1578766952816, "ltp": 5.2, "tv": 286.2, "trd": NaN, "batb": NaN, "batl": [[0, 5.2, 19.5]]}, {"timestamp": 1578766954512, "ltp": 5.2, "tv": 286.2, "trd": NaN, "batb": NaN, "batl": [[0, 5.2, 22.37]]}, {"timestamp": 1578766955798, "ltp": 5.2, "tv": 286.2, "trd": NaN, "batb": NaN, "batl": [[0, 5.2, 19.5]]}, {"timestamp": 1578766956608, "ltp": 5.2, "tv": 286.2, "trd": NaN, "batb": NaN, "batl": [[0, 5.2, 22.37]]}, {"timestamp": 1578766957981, "ltp": 5.2, "tv": 286.2, "trd": NaN, "batb": NaN, "batl": [[0, 5.2, 19.5]]}, {"timestamp": 1578766958611, "ltp": 5.2, "tv": 286.2, "trd": NaN, "batb": NaN, "batl": [[0, 5.2, 22.37]]}, {"timestamp": 1578766959785, "ltp": 5.2, "tv": 286.2, "trd": NaN, "batb": NaN, "batl": [[0, 5.2, 19.5]]}, {"timestamp": 1578766961012, "ltp": 5.2, "tv": 286.2, "trd": NaN, "batb": NaN, "batl": [[0, 5.2, 22.37]]}, {"timestamp": 1578766961823, "ltp": 5.2, "tv": 286.2, "trd": NaN, "batb": NaN, "batl": [[0, 5.2, 19.5]]}, {"timestamp": 1578766962890, "ltp": 5.2, "tv": 286.2, "trd": NaN, "batb": NaN, "batl": [[0, 5.2, 22.37]]}, {"timestamp": 1578766963581, "ltp": 5.2, "tv": 286.2, "trd": NaN, "batb": NaN, "batl": [[0, 5.2, 19.5]]}, {"timestamp": 1578766964686, "ltp": 5.2, "tv": 286.2, "trd": NaN, "batb": NaN, "batl": [[0, 5.2, 22.37]]}, {"timestamp": 1578766965924, "ltp": 5.2, "tv": 286.2, "trd": NaN, "batb": NaN, "batl": [[0, 5.2, 19.5]]}, {"timestamp": 1578766967791, "ltp": 5.2, "tv": 286.2, "trd": NaN, "batb": NaN, "batl": [[0, 5.2, 22.37]]}, {"timestamp": 1578766968898, "ltp": 5.2, "tv": 286.2, "trd": NaN, "batb": NaN, "batl": [[0, 5.2, 19.5]]}, {"timestamp": 1578766970008, "ltp": 5.2, "tv": 286.2, "trd": NaN, "batb": NaN, "batl": [[0, 5.2, 22.37]]}, {"timestamp": 1578766970843, "ltp": 5.2, "tv": 286.2, "trd": NaN, "batb": NaN, "batl": [[0, 5.2, 19.5]]}, {"timestamp": 1578766971820, "ltp": 5.2, "tv": 286.2, "trd": NaN, "batb": NaN, "batl": [[0, 5.2, 22.37]]}, {"timestamp": 1578766973128, "ltp": 5.2, "tv": 286.2, "trd": NaN, "batb": NaN, "batl": [[0, 5.2, 19.5]]}, {"timestamp": 1578766975373, "ltp": 5.2, "tv": 286.2, "trd": NaN, "batb": NaN, "batl": [[0, 5.2, 22.37]]}, {"timestamp": 1578766976491, "ltp": 5.2, "tv": 286.2, "trd": NaN, "batb": NaN, "batl": [[0, 5.2, 19.5]]}, {"timestamp": 1578766977969, "ltp": 5.2, "tv": 286.2, "trd": NaN, "batb": NaN, "batl": [[0, 5.2, 22.37]]}, {"timestamp": 1578766978666, "ltp": 5.2, "tv": 286.2, "trd": NaN, "batb": NaN, "batl": [[0, 5.2, 19.5]]}, {"timestamp": 1578766979970, "ltp": 5.2, "tv": 286.2, "trd": NaN, "batb": NaN, "batl": [[0, 5.2, 22.37]]}, {"timestamp": 1578766980495, "ltp": 5.2, "tv": 286.2, "trd": NaN, "batb": NaN, "batl": [[0, 5.2, 19.5]]}, {"timestamp": 1578766981557, "ltp": 5.2, "tv": 286.2, "trd": NaN, "batb": NaN, "batl": [[0, 5.2, 22.37]]}, {"timestamp": 1578766982996, "ltp": 5.2, "tv": 286.2, "trd": NaN, "batb": NaN, "batl": [[0, 5.2, 19.5]]}, {"timestamp": 1578766984786, "ltp": 5.2, "tv": 286.2, "trd": NaN, "batb": NaN, "batl": [[0, 5.2, 22.37]]}, {"timestamp": 1578766985711, "ltp": 5.2, "tv": 286.2, "trd": NaN, "batb": NaN, "batl": [[0, 5.2, 19.5]]}, {"timestamp": 1578766986986, "ltp": 5.2, "tv": 286.2, "trd": NaN, "batb": NaN, "batl": [[0, 5.2, 22.37]]}, {"timestamp": 1578766987935, "ltp": 5.2, "tv": 286.2, "trd": NaN, "batb": NaN, "batl": [[0, 5.2, 19.5]]}, {"timestamp": 1578766988463, "ltp": 5.2, "tv": 286.2, "trd": NaN, "batb": NaN, "batl": [[0, 5.2, 22.37]]}, {"timestamp": 1578766989985, "ltp": 5.2, "tv": 286.2, "trd": NaN, "batb": NaN, "batl": [[0, 5.2, 19.5]]}, {"timestamp": 1578767090011, "ltp": 5.2, "tv": 286.2, "trd": NaN, "batb": [[1, 5, 74.38]], "batl": NaN}, {"timestamp": 1578767090907, "ltp": 5.2, "tv": 286.2, "trd": NaN, "batb": [[1, 5, 82.29]], "batl": NaN}, {"timestamp": 1578767119581, "ltp": 5.2, "tv": 292.04, "trd": [[5.2, 38.42]], "batb": NaN, "batl": [[0, 5.2, 16.58]]}, {"timestamp": 1578767157687, "ltp": 5.2, "tv": 292.04, "trd": NaN, "batb": NaN, "batl": [[0, 5.2, 19.34]]}, {"timestamp": 1578767290031, "ltp": 5.2, "tv": 292.04, "trd": NaN, "batb": NaN, "batl": [[1, 5.3, 1.7], [2, 5.4, 76.05]]}, {"timestamp": 1578767314037, "ltp": 5.2, "tv": 292.04, "trd": NaN, "batb": [[0, 5.1, 16.51]], "batl": NaN}, {"timestamp": 1578767315947, "ltp": 5.2, "tv": 292.04, "trd": NaN, "batb": NaN, "batl": [[0, 5.2, 87.94]]}, {"timestamp": 1578767320964, "ltp": 5.2, "tv": 292.04, "trd": NaN, "batb": NaN, "batl": [[1, 5.3, 58.67]]}, {"timestamp": 1578767324031, "ltp": 5.2, "tv": 292.04, "trd": NaN, "batb": NaN, "batl": [[1, 5.3, 126.13]]}, {"timestamp": 1578767326467, "ltp": 5.2, "tv": 292.04, "trd": NaN, "batb": NaN, "batl": [[0, 5.2, 19.34]]}, {"timestamp": 1578767327301, "ltp": 5.2, "tv": 292.04, "trd": NaN, "batb": [[0, 5.1, 21.72]], "batl": NaN}, {"timestamp": 1578767413961, "ltp": 5.2, "tv": 292.04, "trd": NaN, "batb": [[1, 5, 29.62]], "batl": NaN}, {"timestamp": 1578767488730, "ltp": 5.1, "tv": 303.26, "trd": [[5.1, 151.52]], "batb": [[0, 5.1, 16.11]], "batl": NaN}, {"timestamp": 1578767506870, "ltp": 5.1, "tv": 315.56, "trd": [[5.1, 163.82]], "batb": [[0, 5.1, 9.96]], "batl": NaN}, {"timestamp": 1578767548942, "ltp": 5.1, "tv": 321.86, "trd": [[5.1, 170.12]], "batb": [[0, 5.1, 6.81]], "batl": NaN}, {"timestamp": 1578767617890, "ltp": 5.1, "tv": 321.86, "trd": NaN, "batb": [[0, 5.1, 1.6]], "batl": NaN}, {"timestamp": 1578767621025, "ltp": 5.1, "tv": 321.86, "trd": NaN, "batb": NaN, "batl": [[0, 5.2, 88.09]]}, {"timestamp": 1578767683003, "ltp": 5.1, "tv": 321.86, "trd": NaN, "batb": [[0, 5, 29.62], [1, 4.9, 53.04], [2, 4.8, 50]], "batl": NaN}, {"timestamp": 1578767690012, "ltp": 5.2, "tv": 342.86, "trd": [[5.2, 59.43]], "batb": NaN, "batl": [[0, 5.2, 77.59]]}, {"timestamp": 1578768217632, "ltp": 5.0, "tv": 434.03, "trd": [[5, 168.83]], "batb": [[0, 4.9, 53.04], [1, 4.8, 50], [2, 4.7, 51.93]], "batl": [[0, 5, 129.84], [1, 5.2, 77.59], [2, 5.3, 126.13]]}, {"timestamp": 1578768218966, "ltp": 5.0, "tv": 434.03, "trd": NaN, "batb": [[0, 4.9, 51.34], [1, 4.8, 57.32], [2, 4.7, 59.42]], "batl": [[1, 5.1, 6.87], [2, 5.2, 77.59]]}, {"timestamp": 1578768219932, "ltp": 5.0, "tv": 434.03, "trd": NaN, "batb": [[0, 4.8, 7.32], [1, 4.7, 59.42], [2, 4.5, 59.41]], "batl": NaN}, {"timestamp": 1578768221961, "ltp": 5.0, "tv": 434.03, "trd": NaN, "batb": NaN, "batl": [[1, 5.1, 76.97]]}, {"timestamp": 1578768222374, "ltp": 5.0, "tv": 434.03, "trd": NaN, "batb": NaN, "batl": [[1, 5.1, 84.73]]}, {"timestamp": 1578768232971, "ltp": 5.0, "tv": 438.62, "trd": [[5, 173.42]], "batb": NaN, "batl": [[0, 5, 130.87]]}, {"timestamp": 1578768233668, "ltp": 5.0, "tv": 438.62, "trd": NaN, "batb": [[0, 4.8, 9.95]], "batl": NaN}, {"timestamp": 1578768235668, "ltp": 5.0, "tv": 438.62, "trd": NaN, "batb": [[0, 4.8, 10.14]], "batl": NaN}, {"timestamp": 1578768239674, "ltp": 5.0, "tv": 438.62, "trd": NaN, "batb": NaN, "batl": [[0, 5, 150.87]]}, {"timestamp": 1578768242990, "ltp": 4.9, "tv": 567.54, "trd": [[4.9, 134.74]], "batb": NaN, "batl": [[0, 4.9, 60.79], [1, 5, 25.61], [2, 5.1, 84.73]]}, {"timestamp": 1578768244048, "ltp": 4.9, "tv": 567.54, "trd": NaN, "batb": [[0, 4.8, 2.82], [2, 4.6, 5.05]], "batl": NaN}, {"timestamp": 1578768245009, "ltp": 4.9, "tv": 567.54, "trd": NaN, "batb": [[0, 4.8, 4.52]], "batl": NaN}, {"timestamp": 1578768245982, "ltp": 4.9, "tv": 567.54, "trd": NaN, "batb": [[2, 4.6, 57.25]], "batl": NaN}, {"timestamp": 1578768246979, "ltp": 4.9, "tv": 567.54, "trd": NaN, "batb": [[0, 4.8, 4.33], [1, 4.7, 59.61]], "batl": NaN}, {"timestamp": 1578768254001, "ltp": 4.9, "tv": 567.54, "trd": NaN, "batb": NaN, "batl": [[0, 4.9, 65.44]]}, {"timestamp": 1578768256672, "ltp": 4.9, "tv": 597.26, "trd": [[4.9, 164.46]], "batb": NaN, "batl": [[0, 4.9, 50.58]]}, {"timestamp": 1578768263004, "ltp": 4.8, "tv": 647.53, "trd": [[4.8, 59.66]], "batb": [[0, 4.8, 22.77]], "batl": [[0, 4.9, 4.65]]}, {"timestamp": 1578768264012, "ltp": 4.8, "tv": 647.53, "trd": NaN, "batb": [[0, 4.8, 26.13]], "batl": NaN}, {"timestamp": 1578768264712, "ltp": 4.8, "tv": 647.53, "trd": NaN, "batb": NaN, "batl": [[0, 5, 33.37], [1, 5.1, 76.97], [2, 5.2, 77.59]]}, {"timestamp": 1578768265821, "ltp": 4.8, "tv": 647.53, "trd": NaN, "batb": NaN, "batl": [[0, 5, 41.88]]}, {"timestamp": 1578768267007, "ltp": 4.8, "tv": 647.53, "trd": NaN, "batb": [[0, 4.8, 78.29]], "batl": NaN}, {"timestamp": 1578768269927, "ltp": 4.8, "tv": 647.53, "trd": NaN, "batb": [[0, 4.8, 80.92]], "batl": NaN}, {"timestamp": 1578768276007, "ltp": 4.8, "tv": 647.53, "trd": NaN, "batb": NaN, "batl": [[0, 4.9, 5.42], [1, 5, 41.88], [2, 5.1, 76.97]]}, {"timestamp": 1578768277034, "ltp": 4.8, "tv": 647.53, "trd": NaN, "batb": [[0, 4.8, 28.76]], "batl": NaN}, {"timestamp": 1578768284920, "ltp": 4.8, "tv": 647.53, "trd": NaN, "batb": [[1, 4.7, 67.75]], "batl": NaN}, {"timestamp": 1578768291052, "ltp": 4.8, "tv": 647.53, "trd": NaN, "batb": NaN, "batl": [[1, 5, 42.03]]}, {"timestamp": 1578768293975, "ltp": 4.8, "tv": 647.53, "trd": NaN, "batb": [[0, 4.8, 26.13]], "batl": NaN}, {"timestamp": 1578768295950, "ltp": 4.8, "tv": 647.53, "trd": NaN, "batb": [[0, 4.8, 34.46], [1, 4.7, 59.42]], "batl": NaN}, {"timestamp": 1578768297773, "ltp": 4.8, "tv": 647.53, "trd": NaN, "batb": [[0, 4.8, 86.62]], "batl": [[2, 5.1, 79.55]]}, {"timestamp": 1578768299054, "ltp": 4.8, "tv": 647.53, "trd": NaN, "batb": NaN, "batl": [[0, 5, 33.52], [1, 5.1, 79.55], [2, 5.2, 77.59]]}, {"timestamp": 1578768311881, "ltp": 4.8, "tv": 647.53, "trd": NaN, "batb": NaN, "batl": [[1, 5.1, 76.97]]}, {"timestamp": 1578768471701, "ltp": 5.0, "tv": 654.23, "trd": [[5, 180.12]], "batb": NaN, "batl": [[0, 5, 27.91]]}, {"timestamp": 1578768475017, "ltp": 5.0, "tv": 654.23, "trd": NaN, "batb": [[0, 4.9, 5.55], [1, 4.8, 86.62], [2, 4.7, 59.42]], "batl": NaN}, {"timestamp": 1578768600038, "ltp": 5.0, "tv": 679.89, "trd": [[5, 205.78]], "batb": NaN, "batl": [[0, 5, 15.08]]}, {"timestamp": 1578768602865, "ltp": 5.0, "tv": 679.89, "trd": NaN, "batb": [[0, 4.9, 27.57]], "batl": [[1, 5.1, 6.87]]}, {"timestamp": 1578768607045, "ltp": 5.0, "tv": 679.89, "trd": NaN, "batb": NaN, "batl": [[0, 5, 7.17]]}, {"timestamp": 1578768632978, "ltp": 5.0, "tv": 679.89, "trd": NaN, "batb": NaN, "batl": [[1, 5.1, 14.63]]}, {"timestamp": 1578768647010, "ltp": 5.0, "tv": 687.07, "trd": [[5, 212.96]], "batb": NaN, "batl": [[0, 5, 3.58]]}, {"timestamp": 1578768649885, "ltp": 5.0, "tv": 687.07, "trd": NaN, "batb": [[0, 4.9, 35.9], [1, 4.8, 78.29]], "batl": NaN}, {"timestamp": 1578768652967, "ltp": 5.0, "tv": 687.07, "trd": NaN, "batb": [[0, 4.9, 84.56]], "batl": NaN}, {"timestamp": 1578768666674, "ltp": 5.0, "tv": 687.07, "trd": NaN, "batb": NaN, "batl": [[0, 5, 7.25]]}, {"timestamp": 1578768669909, "ltp": 5.0, "tv": 687.07, "trd": NaN, "batb": [[0, 4.9, 76.23]], "batl": NaN}, {"timestamp": 1578768670590, "ltp": 5.0, "tv": 687.07, "trd": NaN, "batb": [[0, 4.9, 27.57]], "batl": [[0, 5, 3.58]]}, {"timestamp": 1578768681930, "ltp": 5.0, "tv": 690.65, "trd": [[5, 216.54]], "batb": NaN, "batl": [[0, 5.1, 14.63], [1, 5.2, 77.59], [2, 5.3, 124.42]]}, {"timestamp": 1578768706544, "ltp": 5.0, "tv": 690.65, "trd": NaN, "batb": [[0, 4.9, 43.99]], "batl": NaN}, {"timestamp": 1578768708055, "ltp": 5.0, "tv": 690.65, "trd": NaN, "batb": [[0, 4.9, 94.79]], "batl": [[0, 5.1, 7.76]]}, {"timestamp": 1578768708740, "ltp": 5.0, "tv": 690.65, "trd": NaN, "batb": NaN, "batl": [[2, 5.3, 130.41]]}, {"timestamp": 1578768724963, "ltp": 5.0, "tv": 690.65, "trd": NaN, "batb": [[0, 4.9, 102.9]], "batl": [[0, 5.2, 85.35], [1, 5.3, 130.41], [2, 5.4, 66.21]]}, {"timestamp": 1578768725582, "ltp": 5.0, "tv": 690.65, "trd": NaN, "batb": [[0, 5, 6.66], [1, 4.9, 102.9], [2, 4.8, 78.29]], "batl": NaN}, {"timestamp": 1578768737007, "ltp": 5.0, "tv": 690.65, "trd": NaN, "batb": NaN, "batl": [[0, 5.2, 85.19]]}, {"timestamp": 1578768767898, "ltp": 5.0, "tv": 690.65, "trd": NaN, "batb": [[0, 5, 14.77], [1, 4.9, 94.79]], "batl": NaN}, {"timestamp": 1578768786552, "ltp": 5.0, "tv": 690.65, "trd": NaN, "batb": [[0, 5, 6.66]], "batl": [[0, 5.2, 77.59]]}, {"timestamp": 1578768820977, "ltp": 5.2, "tv": 868.24, "trd": [[5.2, 237.01]], "batb": NaN, "batl": [[0, 5.3, 130.41], [1, 5.4, 66.21], [2, 5.6, 63.84]]}, {"timestamp": 1578768821809, "ltp": 5.2, "tv": 868.24, "trd": NaN, "batb": [[0, 5.1, 5.81], [1, 5, 6.66], [2, 4.9, 94.79]], "batl": [[0, 5.2, 5.7], [1, 5.3, 130.41], [2, 5.4, 66.21]]}, {"timestamp": 1578768822914, "ltp": 5.2, "tv": 868.24, "trd": NaN, "batb": NaN, "batl": [[0, 5.2, 18.11]]}, {"timestamp": 1578768825794, "ltp": 5.2, "tv": 868.24, "trd": NaN, "batb": [[0, 5, 6.66], [1, 4.9, 94.79], [2, 4.8, 78.29]], "batl": NaN}, {"timestamp": 1578768831004, "ltp": 5.2, "tv": 868.24, "trd": NaN, "batb": [[0, 5, 14.57]], "batl": [[0, 5.2, 25.71]]}, {"timestamp": 1578768848956, "ltp": 5.2, "tv": 868.24, "trd": NaN, "batb": NaN, "batl": [[0, 5.2, 40.71]]}, {"timestamp": 1578768933957, "ltp": 5.2, "tv": 868.24, "trd": NaN, "batb": NaN, "batl": [[0, 5.2, 45.71]]}, {"timestamp": 1578768935687, "ltp": 5.2, "tv": 868.24, "trd": NaN, "batb": NaN, "batl": [[0, 5.2, 40.71]]}, {"timestamp": 1578768939955, "ltp": 5.2, "tv": 868.24, "trd": NaN, "batb": NaN, "batl": [[0, 5.2, 65.71]]}, {"timestamp": 1578769056046, "ltp": 5.2, "tv": 868.24, "trd": NaN, "batb": [[0, 5, 14.6]], "batl": NaN}, {"timestamp": 1578769064850, "ltp": 5.2, "tv": 868.24, "trd": NaN, "batb": NaN, "batl": [[0, 5.1, 3.18], [1, 5.2, 65.71], [2, 5.3, 130.41]]}, {"timestamp": 1578769127039, "ltp": 5.2, "tv": 868.24, "trd": NaN, "batb": [[1, 4.9, 98.37]], "batl": NaN}, {"timestamp": 1578769207948, "ltp": 5.2, "tv": 868.19, "trd": [[4.8, 59.64], [4.9, 164.43], [5, 216.53], [5.1, 170.12]], "batb": [[0, 5, 14.62]], "batl": [[1, 5.2, 65.72]]}, {"timestamp": 1578769280783, "ltp": 5.1, "tv": 874.56, "trd": [[5.1, 176.49]], "batb": [[0, 5.1, 2.61], [1, 5, 14.62], [2, 4.9, 98.37]], "batl": [[0, 5.2, 65.72], [1, 5.3, 130.41], [2, 5.4, 66.21]]}, {"timestamp": 1578769282000, "ltp": 5.1, "tv": 874.56, "trd": NaN, "batb": NaN, "batl": [[0, 5.2, 60.02]]}, {"timestamp": 1578769282948, "ltp": 5.1, "tv": 874.56, "trd": NaN, "batb": NaN, "batl": [[0, 5.2, 63.21], [2, 5.4, 69.28]]}, {"timestamp": 1578769317043, "ltp": 5.1, "tv": 874.56, "trd": NaN, "batb": [[0, 5, 14.62], [1, 4.9, 98.37], [2, 4.8, 78.29]], "batl": NaN}, {"timestamp": 1578769327047, "ltp": 5.1, "tv": 874.56, "trd": NaN, "batb": [[0, 5, 6.69]], "batl": [[0, 5.1, 58.76], [1, 5.2, 63.21], [2, 5.3, 130.41]]}, {"timestamp": 1578769329972, "ltp": 5.0, "tv": 940.01, "trd": [[5, 281.99]], "batb": [[0, 4.9, 98.37], [1, 4.8, 78.29], [2, 4.7, 77.47]], "batl": [[0, 5.1, 5.8]]}, {"timestamp": 1578769364917, "ltp": 5.0, "tv": 940.01, "trd": NaN, "batb": [[0, 5, 13.63], [1, 4.9, 98.37], [2, 4.8, 78.29]], "batl": NaN}, {"timestamp": 1578769374005, "ltp": 5.0, "tv": 940.01, "trd": NaN, "batb": NaN, "batl": [[0, 5.2, 63.21], [1, 5.3, 130.41], [2, 5.4, 69.28]]}, {"timestamp": 1578769503994, "ltp": 5.0, "tv": 960.0, "trd": [[5, 301.98]], "batb": [[0, 5, 3.63]], "batl": NaN}, {"timestamp": 1578769505955, "ltp": 5.0, "tv": 960.0, "trd": NaN, "batb": NaN, "batl": [[0, 5.1, 5.91], [1, 5.2, 70.83], [2, 5.3, 130.41]]}, {"timestamp": 1578769506810, "ltp": 5.0, "tv": 960.0, "trd": NaN, "batb": NaN, "batl": [[0, 5.2, 70.83], [1, 5.3, 130.41], [2, 5.4, 69.28]]}, {"timestamp": 1578769556964, "ltp": 5.0, "tv": 960.0, "trd": NaN, "batb": [[0, 5, 6.28]], "batl": NaN}, {"timestamp": 1578769768683, "ltp": 5.0, "tv": 960.0, "trd": NaN, "batb": [[0, 5.1, 18], [1, 5, 6.28], [2, 4.9, 98.37]], "batl": NaN}, {"timestamp": 1578769797818, "ltp": 5.1, "tv": 996.0, "trd": [[5.1, 212.49]], "batb": [[0, 5, 6.28], [1, 4.9, 98.37], [2, 4.8, 78.29]], "batl": [[0, 5.1, 23.13], [1, 5.2, 70.83], [2, 5.3, 130.41]]}, {"timestamp": 1578769798101, "ltp": 5.1, "tv": 996.0, "trd": NaN, "batb": NaN, "batl": [[0, 5.1, 25.13]]}, {"timestamp": 1578769803041, "ltp": 5.1, "tv": 996.0, "trd": NaN, "batb": [[0, 5, 3.63]], "batl": [[1, 5.2, 55.59]]}, {"timestamp": 1578769822946, "ltp": 5.1, "tv": 996.0, "trd": NaN, "batb": NaN, "batl": [[0, 5.1, 40.67]]}, {"timestamp": 1578769900933, "ltp": 5.1, "tv": 996.6, "trd": [[5.1, 213.09]], "batb": NaN, "batl": [[0, 5.1, 40.07]]}, {"timestamp": 1578769951025, "ltp": 5.1, "tv": 996.6, "trd": NaN, "batb": NaN, "batl": [[0, 5.1, 44.86]]}, {"timestamp": 1578770108971, "ltp": 5.1, "tv": 996.6, "trd": NaN, "batb": NaN, "batl": [[1, 5.2, 40.59]]}, {"timestamp": 1578770163931, "ltp": 5.1, "tv": 996.6, "trd": NaN, "batb": [[1, 4.9, 98.57]], "batl": NaN}, {"timestamp": 1578770176970, "ltp": 5.1, "tv": 996.6, "trd": NaN, "batb": NaN, "batl": [[0, 5.1, 76.29]]}, {"timestamp": 1578770180006, "ltp": 5.1, "tv": 1000.77, "trd": [[5.1, 217.26]], "batb": NaN, "batl": [[0, 5.1, 72.12]]}, {"timestamp": 1578770196990, "ltp": 5.0, "tv": 1009.41, "trd": [[5, 310.61]], "batb": [[0, 4.9, 98.57], [1, 4.8, 78.29], [2, 4.7, 77.47]], "batl": NaN}, {"timestamp": 1578770197896, "ltp": 5.0, "tv": 1009.41, "trd": NaN, "batb": [[0, 5, 6.07], [1, 4.9, 98.57], [2, 4.8, 78.29]], "batl": NaN}, {"timestamp": 1578770232039, "ltp": 5.0, "tv": 1009.41, "trd": NaN, "batb": NaN, "batl": [[0, 5.1, 66.22]]}, {"timestamp": 1578770246954, "ltp": 5.0, "tv": 1009.41, "trd": NaN, "batb": NaN, "batl": [[0, 5.1, 71.95]]}, {"timestamp": 1578770247983, "ltp": 5.0, "tv": 1009.41, "trd": NaN, "batb": NaN, "batl": [[0, 5.1, 66.22]]}, {"timestamp": 1578770258896, "ltp": 5.0, "tv": 1009.41, "trd": NaN, "batb": NaN, "batl": [[0, 5.1, 71.58]]}, {"timestamp": 1578770278015, "ltp": 5.0, "tv": 1009.41, "trd": NaN, "batb": NaN, "batl": [[0, 5.1, 76.25]]}, {"timestamp": 1578770279014, "ltp": 5.0, "tv": 1009.41, "trd": NaN, "batb": NaN, "batl": [[0, 5.1, 87.23]]}, {"timestamp": 1578770280021, "ltp": 5.0, "tv": 1009.41, "trd": NaN, "batb": NaN, "batl": [[1, 5.2, 45.26]]}, {"timestamp": 1578770281042, "ltp": 5.0, "tv": 1009.41, "trd": NaN, "batb": NaN, "batl": [[1, 5.2, 49.93]]}, {"timestamp": 1578770288044, "ltp": 5.0, "tv": 1009.41, "trd": NaN, "batb": NaN, "batl": [[1, 5.2, 54.6]]}, {"timestamp": 1578770288991, "ltp": 5.0, "tv": 1009.41, "trd": NaN, "batb": NaN, "batl": [[2, 5.3, 135.08]]}, {"timestamp": 1578770289803, "ltp": 5.0, "tv": 1009.41, "trd": NaN, "batb": NaN, "batl": [[2, 5.3, 139.75]]}, {"timestamp": 1578770291040, "ltp": 5.0, "tv": 1009.41, "trd": NaN, "batb": NaN, "batl": [[2, 5.3, 144.42]]}, {"timestamp": 1578770300361, "ltp": 5.0, "tv": 1009.41, "trd": NaN, "batb": NaN, "batl": [[0, 5.1, 91.9]]}, {"timestamp": 1578770326984, "ltp": 5.0, "tv": 1009.41, "trd": NaN, "batb": NaN, "batl": [[1, 5.2, 59.96]]}, {"timestamp": 1578770341001, "ltp": 5.0, "tv": 1009.41, "trd": NaN, "batb": NaN, "batl": [[0, 5.1, 85.6]]}, {"timestamp": 1578770347876, "ltp": 5.1, "tv": 1048.6, "trd": [[5.1, 256.46]], "batb": NaN, "batl": [[0, 5.1, 66], [2, 5.3, 150.54]]}, {"timestamp": 1578770528915, "ltp": 5.1, "tv": 1052.2, "trd": [[5.1, 260.06]], "batb": NaN, "batl": [[0, 5.1, 64.2]]}, {"timestamp": 1578770530972, "ltp": 5.1, "tv": 1052.2, "trd": NaN, "batb": NaN, "batl": [[0, 5.1, 63.16]]}, {"timestamp": 1578770545720, "ltp": 5.1, "tv": 1052.2, "trd": NaN, "batb": NaN, "batl": [[0, 5.1, 64.2]]}, {"timestamp": 1578770607992, "ltp": 5.1, "tv": 1152.19, "trd": [[5.1, 360.05]], "batb": NaN, "batl": [[0, 5.1, 14.21]]}, {"timestamp": 1578770608684, "ltp": 5.1, "tv": 1152.19, "trd": NaN, "batb": NaN, "batl": [[0, 5.1, 13.16]]}, {"timestamp": 1578770619984, "ltp": 5.1, "tv": 1178.53, "trd": [[5.1, 386.38]], "batb": [[0, 5.1, 69.61], [1, 5, 6.07], [2, 4.9, 98.57]], "batl": [[0, 5.2, 59.96], [1, 5.3, 150.54], [2, 5.4, 75.4]]}, {"timestamp": 1578770620976, "ltp": 5.1, "tv": 1190.43, "trd": [[5.1, 398.28]], "batb": [[0, 5.1, 63.66]], "batl": NaN}, {"timestamp": 1578770621987, "ltp": 5.1, "tv": 1254.08, "trd": [[5.1, 461.94]], "batb": [[0, 5.1, 31.84]], "batl": NaN}, {"timestamp": 1578770623982, "ltp": 5.1, "tv": 1254.08, "trd": NaN, "batb": [[1, 5, 14]], "batl": NaN}, {"timestamp": 1578770626891, "ltp": 5.1, "tv": 1254.08, "trd": NaN, "batb": [[0, 5, 14], [1, 4.9, 98.57], [2, 4.8, 78.29]], "batl": NaN}, {"timestamp": 1578770633008, "ltp": 5.1, "tv": 1254.08, "trd": NaN, "batb": [[0, 5, 46.47]], "batl": NaN}, {"timestamp": 1578770636017, "ltp": 5.1, "tv": 1254.08, "trd": NaN, "batb": [[0, 5.1, 5.36], [1, 5, 46.47], [2, 4.9, 98.57]], "batl": NaN}, {"timestamp": 1578770648046, "ltp": 5.1, "tv": 1254.08, "trd": NaN, "batb": [[0, 5.1, 19.37]], "batl": NaN}, {"timestamp": 1578770655035, "ltp": 5.1, "tv": 1312.18, "trd": [[5.1, 520.04]], "batb": [[0, 5.1, 124.99]], "batl": NaN}, {"timestamp": 1578770656042, "ltp": 5.1, "tv": 1312.18, "trd": NaN, "batb": [[0, 5.1, 118], [1, 5, 104.56]], "batl": NaN}, {"timestamp": 1578770657055, "ltp": 5.1, "tv": 1312.18, "trd": NaN, "batb": [[2, 4.9, 124.11]], "batl": NaN}, {"timestamp": 1578770659969, "ltp": 5.1, "tv": 1312.18, "trd": NaN, "batb": [[1, 5, 96.64]], "batl": NaN}, {"timestamp": 1578770671040, "ltp": 5.1, "tv": 1321.48, "trd": [[5.1, 529.34]], "batb": [[0, 5.1, 113.36]], "batl": NaN}, {"timestamp": 1578770673959, "ltp": 5.1, "tv": 1363.38, "trd": [[5.1, 571.23]], "batb": [[0, 5.1, 124.88], [1, 5, 64.16]], "batl": NaN}, {"timestamp": 1578770675053, "ltp": 5.1, "tv": 1405.07, "trd": [[5.1, 612.93]], "batb": [[0, 5.1, 112.04]], "batl": NaN}, {"timestamp": 1578770676968, "ltp": 5.1, "tv": 1405.07, "trd": NaN, "batb": [[0, 5.1, 104.03]], "batl": NaN}, {"timestamp": 1578770677921, "ltp": 5.1, "tv": 1405.07, "trd": NaN, "batb": [[0, 5.1, 111.24]], "batl": NaN}, {"timestamp": 1578770683984, "ltp": 5.1, "tv": 1421.98, "trd": [[5.1, 629.83]], "batb": [[0, 5.1, 102.79]], "batl": NaN}, {"timestamp": 1578770720019, "ltp": 5.1, "tv": 1421.98, "trd": NaN, "batb": NaN, "batl": [[0, 5.2, 78.29]]}, {"timestamp": 1578770748046, "ltp": 5.1, "tv": 1421.98, "trd": NaN, "batb": NaN, "batl": [[0, 5.2, 65.89]]}, {"timestamp": 1578770766966, "ltp": 5.1, "tv": 1421.98, "trd": NaN, "batb": [[0, 5.1, 123.87]], "batl": NaN}, {"timestamp": 1578770768958, "ltp": 5.1, "tv": 1421.98, "trd": NaN, "batb": [[1, 5, 80.58], [2, 4.9, 107.69]], "batl": NaN}, {"timestamp": 1578770770966, "ltp": 5.1, "tv": 1421.98, "trd": NaN, "batb": [[0, 5.1, 131.23]], "batl": NaN}, {"timestamp": 1578770777960, "ltp": 5.1, "tv": 1421.98, "trd": NaN, "batb": [[0, 5.1, 162.42]], "batl": NaN}, {"timestamp": 1578770807010, "ltp": 5.2, "tv": 1478.96, "trd": [[5.2, 294]], "batb": NaN, "batl": [[0, 5.2, 66.03]]}, {"timestamp": 1578770813013, "ltp": 5.1, "tv": 1482.96, "trd": [[5.1, 633.83]], "batb": [[0, 5.1, 160.42]], "batl": NaN}, {"timestamp": 1578770820898, "ltp": 5.1, "tv": 1482.96, "trd": NaN, "batb": NaN, "batl": [[0, 5.2, 121.23]]}, {"timestamp": 1578770821999, "ltp": 5.1, "tv": 1482.96, "trd": NaN, "batb": [[1, 5, 335.68], [2, 4.9, 374.79]], "batl": NaN}, {"timestamp": 1578770833968, "ltp": 5.1, "tv": 1483.19, "trd": [[5.1, 634.06]], "batb": [[0, 5.1, 152.96]], "batl": NaN}, {"timestamp": 1578770836915, "ltp": 5.1, "tv": 1483.19, "trd": NaN, "batb": [[0, 5.1, 174.25]], "batl": [[0, 5.2, 66.03]]}, {"timestamp": 1578770838018, "ltp": 5.1, "tv": 1483.19, "trd": NaN, "batb": [[0, 5.1, 190.81]], "batl": NaN}, {"timestamp": 1578770841919, "ltp": 5.1, "tv": 1483.19, "trd": NaN, "batb": [[1, 5, 80.58]], "batl": NaN}, {"timestamp": 1578770843022, "ltp": 5.1, "tv": 1483.19, "trd": NaN, "batb": [[0, 5.1, 169.52]], "batl": NaN}, {"timestamp": 1578770846054, "ltp": 5.1, "tv": 1483.19, "trd": NaN, "batb": [[0, 5.1, 169.84]], "batl": NaN}, {"timestamp": 1578770846952, "ltp": 5.1, "tv": 1483.19, "trd": NaN, "batb": NaN, "batl": [[2, 5.4, 84.75]]}, {"timestamp": 1578770848951, "ltp": 5.1, "tv": 1483.19, "trd": NaN, "batb": NaN, "batl": [[2, 5.4, 89.42]]}, {"timestamp": 1578770909033, "ltp": 5.1, "tv": 1483.19, "trd": NaN, "batb": [[0, 5.1, 163.03]], "batl": NaN}, {"timestamp": 1578770918952, "ltp": 5.1, "tv": 1483.19, "trd": NaN, "batb": [[0, 5.1, 153.27]], "batl": NaN}, {"timestamp": 1578770945972, "ltp": 5.1, "tv": 1488.29, "trd": [[5.1, 639.17]], "batb": [[0, 5.1, 150.72]], "batl": NaN}, {"timestamp": 1578770947980, "ltp": 5.2, "tv": 1511.11, "trd": [[5.2, 316.81]], "batb": NaN, "batl": [[0, 5.2, 54.63]]}, {"timestamp": 1578770965987, "ltp": 5.1, "tv": 1514.85, "trd": [[5.1, 642.91]], "batb": [[0, 5.1, 148.85]], "batl": NaN}, {"timestamp": 1578770981032, "ltp": 5.1, "tv": 1522.85, "trd": [[5.1, 650.91]], "batb": [[0, 5.1, 144.85]], "batl": NaN}, {"timestamp": 1578771009999, "ltp": 5.1, "tv": 1812.54, "trd": [[5.1, 940.59]], "batb": [[0, 5, 102.59], [1, 4.9, 374.79], [2, 4.8, 358.24]], "batl": [[0, 5.1, 46.49], [1, 5.2, 54.63], [2, 5.3, 150.54]]}, {"timestamp": 1578771011005, "ltp": 5.1, "tv": 1812.54, "trd": NaN, "batb": [[0, 5, 44.5]], "batl": [[0, 5.1, 62.85], [1, 5.2, 149.09]]}, {"timestamp": 1578771012005, "ltp": 5.1, "tv": 1812.54, "trd": NaN, "batb": NaN, "batl": [[0, 5.1, 94.05]]}, {"timestamp": 1578771013973, "ltp": 5.1, "tv": 1812.54, "trd": NaN, "batb": [[2, 4.8, 400.24]], "batl": NaN}, {"timestamp": 1578771021029, "ltp": 5.1, "tv": 1822.53, "trd": [[5.1, 950.59]], "batb": NaN, "batl": [[0, 5.1, 72.69]]}, {"timestamp": 1578771031011, "ltp": 5.1, "tv": 1822.53, "trd": NaN, "batb": [[0, 5, 22.49]], "batl": [[0, 5.1, 93.47]]}, {"timestamp": 1578771034036, "ltp": 5.1, "tv": 1827.62, "trd": [[5.1, 955.67]], "batb": NaN, "batl": [[0, 5.1, 70.15]]}, {"timestamp": 1578771044949, "ltp": 5.1, "tv": 1841.1, "trd": [[5.1, 969.16]], "batb": NaN, "batl": [[0, 5.1, 63.41]]}, {"timestamp": 1578771046979, "ltp": 5.1, "tv": 1841.1, "trd": NaN, "batb": [[0, 5, 48.49]], "batl": NaN}, {"timestamp": 1578771047978, "ltp": 5.1, "tv": 1841.1, "trd": NaN, "batb": NaN, "batl": [[0, 5.1, 84.19], [1, 5.2, 307.05]]}, {"timestamp": 1578771048980, "ltp": 5.1, "tv": 1841.1, "trd": NaN, "batb": NaN, "batl": [[0, 5.1, 63.41], [1, 5.2, 250.42]]}, {"timestamp": 1578771050051, "ltp": 5.1, "tv": 1841.1, "trd": NaN, "batb": NaN, "batl": [[0, 5.1, 84.24]]}, {"timestamp": 1578771050973, "ltp": 5.1, "tv": 1841.1, "trd": NaN, "batb": NaN, "batl": [[0, 5.1, 63.41]]}, {"timestamp": 1578771051965, "ltp": 5.1, "tv": 1841.1, "trd": NaN, "batb": NaN, "batl": [[0, 5.1, 84.24]]}, {"timestamp": 1578771054001, "ltp": 5.1, "tv": 1841.1, "trd": NaN, "batb": NaN, "batl": [[0, 5.1, 63.41]]}, {"timestamp": 1578771054960, "ltp": 5.1, "tv": 1841.1, "trd": NaN, "batb": NaN, "batl": [[0, 5.1, 84.24]]}, {"timestamp": 1578771055963, "ltp": 5.1, "tv": 1846.78, "trd": [[5.1, 974.84]], "batb": NaN, "batl": [[0, 5.1, 60.57]]}, {"timestamp": 1578771057025, "ltp": 5.1, "tv": 1846.78, "trd": NaN, "batb": NaN, "batl": [[0, 5.1, 81.4]]}, {"timestamp": 1578771058977, "ltp": 5.1, "tv": 1846.78, "trd": NaN, "batb": NaN, "batl": [[0, 5.1, 60.57]]}, {"timestamp": 1578771059983, "ltp": 5.1, "tv": 1846.78, "trd": NaN, "batb": NaN, "batl": [[0, 5.1, 81.4]]}, {"timestamp": 1578771060991, "ltp": 5.1, "tv": 1846.78, "trd": NaN, "batb": NaN, "batl": [[0, 5.1, 60.57]]}, {"timestamp": 1578771061992, "ltp": 5.1, "tv": 1846.78, "trd": NaN, "batb": NaN, "batl": [[0, 5.1, 81.4]]}, {"timestamp": 1578771065002, "ltp": 5.1, "tv": 1846.78, "trd": NaN, "batb": NaN, "batl": [[0, 5.1, 60.57]]}, {"timestamp": 1578771065997, "ltp": 5.1, "tv": 1846.78, "trd": NaN, "batb": NaN, "batl": [[0, 5.1, 81.4]]}, {"timestamp": 1578771066997, "ltp": 5.1, "tv": 1865.46, "trd": [[5.1, 993.52]], "batb": NaN, "batl": [[0, 5.1, 51.23]]}, {"timestamp": 1578771068004, "ltp": 5.0, "tv": 1872.93, "trd": [[5, 318.09]], "batb": [[0, 5, 44.75]], "batl": [[0, 5.1, 72.06]]}, {"timestamp": 1578771070026, "ltp": 5.1, "tv": 1876.67, "trd": [[5.1, 997.25]], "batb": NaN, "batl": [[0, 5.1, 70.19]]}, {"timestamp": 1578771080008, "ltp": 5.1, "tv": 1877.42, "trd": [[5.1, 998]], "batb": NaN, "batl": [[0, 5.1, 48.99]]}, {"timestamp": 1578771080920, "ltp": 5.1, "tv": 1877.42, "trd": NaN, "batb": NaN, "batl": [[0, 5.1, 69.82]]}, {"timestamp": 1578771088956, "ltp": 5.0, "tv": 1881.52, "trd": [[5, 322.2]], "batb": [[0, 5, 42.7]], "batl": NaN}, {"timestamp": 1578771098946, "ltp": 5.1, "tv": 1881.62, "trd": [[5.1, 998.09]], "batb": NaN, "batl": [[0, 5.1, 48.94]]}, {"timestamp": 1578771101957, "ltp": 5.1, "tv": 1881.62, "trd": NaN, "batb": NaN, "batl": [[0, 5.1, 69.77]]}, {"timestamp": 1578771104878, "ltp": 5.0, "tv": 1885.36, "trd": [[5, 325.93]], "batb": [[0, 5, 40.83]], "batl": NaN}, {"timestamp": 1578771105982, "ltp": 5.0, "tv": 1885.36, "trd": NaN, "batb": [[0, 5, 62.1]], "batl": [[0, 5.1, 48.94]]}, {"timestamp": 1578771107055, "ltp": 5.0, "tv": 1885.36, "trd": NaN, "batb": NaN, "batl": [[0, 5.1, 69.77]]}, {"timestamp": 1578771119867, "ltp": 5.0, "tv": 1885.36, "trd": NaN, "batb": NaN, "batl": [[1, 5.2, 227.24]]}, {"timestamp": 1578771142050, "ltp": 5.0, "tv": 1886.82, "trd": [[5, 327.4]], "batb": [[0, 5, 61.37]], "batl": NaN}, {"timestamp": 1578771143954, "ltp": 5.0, "tv": 1886.82, "trd": NaN, "batb": NaN, "batl": [[0, 5.1, 48.94]]}, {"timestamp": 1578771144965, "ltp": 5.0, "tv": 1886.82, "trd": NaN, "batb": [[0, 5, 89.41]], "batl": NaN}, {"timestamp": 1578771145960, "ltp": 5.0, "tv": 1886.82, "trd": NaN, "batb": [[0, 5, 119.06]], "batl": NaN}, {"timestamp": 1578771150964, "ltp": 5.0, "tv": 1886.82, "trd": NaN, "batb": NaN, "batl": [[1, 5.2, 250.34]]}, {"timestamp": 1578771162964, "ltp": 5.1, "tv": 1930.9, "trd": [[5.1, 1042.17]], "batb": NaN, "batl": [[0, 5.1, 26.9]]}, {"timestamp": 1578771178989, "ltp": 5.1, "tv": 1934.84, "trd": [[5.1, 1046.11]], "batb": NaN, "batl": [[0, 5.1, 24.93]]}, {"timestamp": 1578771181020, "ltp": 5.1, "tv": 1934.84, "trd": NaN, "batb": NaN, "batl": [[0, 5.1, 32.93]]}, {"timestamp": 1578771221872, "ltp": 5.1, "tv": 1934.84, "trd": NaN, "batb": [[0, 5, 141.05]], "batl": [[1, 5.2, 226.3]]}, {"timestamp": 1578771224965, "ltp": 5.1, "tv": 1934.84, "trd": NaN, "batb": NaN, "batl": [[1, 5.2, 203.2]]}, {"timestamp": 1578771251016, "ltp": 5.1, "tv": 1934.84, "trd": NaN, "batb": NaN, "batl": [[0, 5.1, 42.93]]}, {"timestamp": 1578771253913, "ltp": 5.1, "tv": 1934.84, "trd": NaN, "batb": NaN, "batl": [[1, 5.2, 187.77]]}, {"timestamp": 1578771259950, "ltp": 5.1, "tv": 1934.84, "trd": NaN, "batb": NaN, "batl": [[1, 5.2, 191.51]]}, {"timestamp": 1578771260961, "ltp": 5.1, "tv": 1934.84, "trd": NaN, "batb": NaN, "batl": [[1, 5.2, 193.38]]}, {"timestamp": 1578771263033, "ltp": 5.1, "tv": 1934.84, "trd": NaN, "batb": NaN, "batl": [[1, 5.2, 195.25]]}, {"timestamp": 1578771268055, "ltp": 5.1, "tv": 1934.84, "trd": NaN, "batb": NaN, "batl": [[1, 5.2, 197.12]]}, {"timestamp": 1578771269959, "ltp": 5.1, "tv": 1934.84, "trd": NaN, "batb": [[2, 4.8, 358.24]], "batl": [[1, 5.2, 198.99]]}, {"timestamp": 1578771276946, "ltp": 5.0, "tv": 1935.48, "trd": [[5, 328.04]], "batb": [[0, 5, 140.73]], "batl": NaN}, {"timestamp": 1578771280982, "ltp": 5.1, "tv": 1958.97, "trd": [[5.1, 1069.61]], "batb": NaN, "batl": [[0, 5.1, 31.19]]}, {"timestamp": 1578771281997, "ltp": 5.1, "tv": 1958.97, "trd": NaN, "batb": [[0, 5, 200.74]], "batl": NaN}, {"timestamp": 1578771291033, "ltp": 5.0, "tv": 1970.11, "trd": [[5, 339.17]], "batb": [[0, 5, 195.17]], "batl": NaN}, {"timestamp": 1578771295018, "ltp": 5.0, "tv": 1970.11, "trd": NaN, "batb": [[2, 4.8, 400.24]], "batl": NaN}, {"timestamp": 1578771298577, "ltp": 5.0, "tv": 1973.85, "trd": [[5, 342.91]], "batb": [[0, 5, 193.3]], "batl": NaN}, {"timestamp": 1578771322042, "ltp": 5.1, "tv": 2023.41, "trd": [[5, 361.6], [5.1, 1100.49]], "batb": [[0, 5, 183.96]], "batl": [[0, 5.1, 15.75]]}, {"timestamp": 1578771323960, "ltp": 5.1, "tv": 2023.41, "trd": NaN, "batb": [[0, 5, 123.95]], "batl": NaN}, {"timestamp": 1578771332037, "ltp": 5.1, "tv": 2027.55, "trd": [[5.1, 1104.62]], "batb": NaN, "batl": [[0, 5.1, 13.68]]}, {"timestamp": 1578771334963, "ltp": 5.1, "tv": 2027.55, "trd": NaN, "batb": [[1, 4.9, 415.79]], "batl": NaN}, {"timestamp": 1578771343985, "ltp": 5.1, "tv": 2027.55, "trd": NaN, "batb": [[1, 4.9, 374.79]], "batl": NaN}, {"timestamp": 1578771365905, "ltp": 5.1, "tv": 2037.55, "trd": [[5.1, 1114.62]], "batb": NaN, "batl": [[0, 5.1, 8.68]]}, {"timestamp": 1578771367013, "ltp": 5.1, "tv": 2037.55, "trd": NaN, "batb": NaN, "batl": [[0, 5.1, 28.68]]}, {"timestamp": 1578771388801, "ltp": 5.1, "tv": 2094.91, "trd": [[5.1, 1171.98]], "batb": [[0, 5, 131.27]], "batl": [[0, 5.2, 198.99], [1, 5.3, 150.54], [2, 5.4, 89.42]]}, {"timestamp": 1578771443026, "ltp": 5.1, "tv": 2094.91, "trd": NaN, "batb": NaN, "batl": [[2, 5.4, 126.42]]}, {"timestamp": 1578771450856, "ltp": 5.1, "tv": 2095.67, "trd": [[5.1, 1172.75]], "batb": [[0, 5, 130.89]], "batl": [[0, 5.1, 1.32], [1, 5.2, 198.99], [2, 5.3, 150.54]]}, {"timestamp": 1578771509881, "ltp": 5.0, "tv": 2103.15, "trd": [[5, 369.07]], "batb": [[0, 5, 127.15]], "batl": NaN}, {"timestamp": 1578771527041, "ltp": 5.1, "tv": 2105.78, "trd": [[5.1, 1175.38]], "batb": [[0, 5.1, 130.19], [1, 5, 127.15], [2, 4.9, 374.79]], "batl": [[0, 5.2, 155.5], [1, 5.3, 150.54], [2, 5.4, 89.42]]}, {"timestamp": 1578771528044, "ltp": 5.1, "tv": 2105.78, "trd": NaN, "batb": [[0, 5.1, 204.5]], "batl": NaN}, {"timestamp": 1578771529047, "ltp": 5.1, "tv": 2105.78, "trd": NaN, "batb": [[1, 5, 186.52]], "batl": [[0, 5.2, 134.54]]}, {"timestamp": 1578771530054, "ltp": 5.1, "tv": 2105.78, "trd": NaN, "batb": NaN, "batl": [[2, 5.4, 126.42]]}, {"timestamp": 1578771530956, "ltp": 5.1, "tv": 2105.78, "trd": NaN, "batb": [[0, 5.1, 206.54], [1, 5, 179.59]], "batl": NaN}, {"timestamp": 1578771535041, "ltp": 5.1, "tv": 2105.78, "trd": NaN, "batb": [[0, 5.1, 230.13]], "batl": NaN}, {"timestamp": 1578771535975, "ltp": 5.1, "tv": 2105.78, "trd": NaN, "batb": NaN, "batl": [[0, 5.2, 104.5]]}, {"timestamp": 1578771537963, "ltp": 5.1, "tv": 2105.78, "trd": NaN, "batb": NaN, "batl": [[0, 5.2, 40.28]]}, {"timestamp": 1578771540049, "ltp": 5.1, "tv": 2259.88, "trd": [[5.1, 1231.12], [5.2, 415.17]], "batb": [[0, 5.1, 202.26], [1, 5, 149.93]], "batl": [[0, 5.3, 150.54], [1, 5.4, 126.42], [2, 5.5, 96.1]]}, {"timestamp": 1578771541050, "ltp": 5.1, "tv": 2288.58, "trd": [[5.1, 1259.82]], "batb": [[0, 5.1, 187.91]], "batl": NaN}, {"timestamp": 1578771541956, "ltp": 5.1, "tv": 2288.58, "trd": NaN, "batb": NaN, "batl": [[0, 5.2, 51.62], [1, 5.3, 150.54], [2, 5.4, 126.42]]}, {"timestamp": 1578771547994, "ltp": 5.1, "tv": 2288.58, "trd": NaN, "batb": [[0, 5.1, 194.68]], "batl": NaN}, {"timestamp": 1578771551868, "ltp": 5.1, "tv": 2288.58, "trd": NaN, "batb": NaN, "batl": [[0, 5.2, 61.62]]}, {"timestamp": 1578771552973, "ltp": 5.1, "tv": 2288.58, "trd": NaN, "batb": [[0, 5.1, 200.04]], "batl": NaN}, {"timestamp": 1578771553979, "ltp": 5.1, "tv": 2288.58, "trd": NaN, "batb": NaN, "batl": [[0, 5.2, 113.91]]}, {"timestamp": 1578771559050, "ltp": 5.1, "tv": 2288.58, "trd": NaN, "batb": NaN, "batl": [[1, 5.3, 160.54]]}, {"timestamp": 1578771560050, "ltp": 5.1, "tv": 2288.58, "trd": NaN, "batb": [[0, 5.1, 209.38]], "batl": [[0, 5.2, 61.62]]}, {"timestamp": 1578771561963, "ltp": 5.1, "tv": 2288.58, "trd": NaN, "batb": [[0, 5.1, 211.25]], "batl": NaN}, {"timestamp": 1578771563977, "ltp": 5.1, "tv": 2288.58, "trd": NaN, "batb": [[0, 5.1, 213.12]], "batl": NaN}, {"timestamp": 1578771568987, "ltp": 5.1, "tv": 2288.58, "trd": NaN, "batb": [[0, 5.1, 253.12]], "batl": NaN}, {"timestamp": 1578771569988, "ltp": 5.1, "tv": 2288.58, "trd": NaN, "batb": [[0, 5.1, 253.49]], "batl": NaN}, {"timestamp": 1578771580910, "ltp": 5.1, "tv": 2288.58, "trd": NaN, "batb": [[0, 5.1, 253.8]], "batl": NaN}, {"timestamp": 1578771591015, "ltp": 5.2, "tv": 2292.58, "trd": [[5.2, 419.17]], "batb": NaN, "batl": [[0, 5.2, 59.62]]}, {"timestamp": 1578771598019, "ltp": 5.2, "tv": 2292.58, "trd": NaN, "batb": NaN, "batl": [[0, 5.2, 209.62]]}, {"timestamp": 1578771600017, "ltp": 5.2, "tv": 2292.58, "trd": NaN, "batb": NaN, "batl": [[2, 5.4, 89.42]]}, {"timestamp": 1578771601027, "ltp": 5.2, "tv": 2292.58, "trd": NaN, "batb": [[0, 5.1, 240.59], [1, 5, 128.66], [2, 4.9, 369.24]], "batl": [[1, 5.3, 154.56], [2, 5.4, 86.34]]}, {"timestamp": 1578771602028, "ltp": 5.2, "tv": 2411.16, "trd": [[5.2, 537.75]], "batb": NaN, "batl": [[0, 5.2, 149.89]]}, {"timestamp": 1578771603027, "ltp": 5.2, "tv": 2411.16, "trd": NaN, "batb": [[2, 4.9, 102.14]], "batl": NaN}, {"timestamp": 1578771607046, "ltp": 5.2, "tv": 2411.16, "trd": NaN, "batb": NaN, "batl": [[2, 5.4, 123.34]]}, {"timestamp": 1578771612023, "ltp": 5.2, "tv": 2411.16, "trd": NaN, "batb": [[0, 5.1, 328.29]], "batl": NaN}, {"timestamp": 1578771614040, "ltp": 5.2, "tv": 2411.16, "trd": NaN, "batb": NaN, "batl": [[0, 5.2, 150.8]]}, {"timestamp": 1578771623052, "ltp": 5.2, "tv": 2411.16, "trd": NaN, "batb": NaN, "batl": [[2, 5.4, 86.34]]}, {"timestamp": 1578771651995, "ltp": 5.1, "tv": 2461.17, "trd": [[5.1, 1309.82]], "batb": [[0, 5.1, 303.28]], "batl": NaN}, {"timestamp": 1578771653005, "ltp": 5.2, "tv": 2762.77, "trd": [[5.2, 839.35]], "batb": [[0, 5.2, 131.08], [1, 5.1, 303.28], [2, 5, 128.66]], "batl": [[0, 5.3, 154.56], [1, 5.4, 97.7], [2, 5.5, 96.1]]}, {"timestamp": 1578771657984, "ltp": 5.2, "tv": 2770.63, "trd": [[5.2, 847.22]], "batb": [[0, 5.2, 127.15]], "batl": NaN}, {"timestamp": 1578771663990, "ltp": 5.2, "tv": 2770.63, "trd": NaN, "batb": [[1, 5.1, 215.58]], "batl": NaN}, {"timestamp": 1578771666026, "ltp": 5.2, "tv": 2778.85, "trd": [[5.2, 855.44]], "batb": [[0, 5.2, 123.03]], "batl": NaN}, {"timestamp": 1578771667006, "ltp": 5.2, "tv": 2790.57, "trd": [[5.2, 867.15]], "batb": [[0, 5.2, 126.52], [1, 5.1, 211.82]], "batl": NaN}, {"timestamp": 1578771668921, "ltp": 5.2, "tv": 2802.28, "trd": [[5.2, 878.87]], "batb": [[0, 5.2, 120.66]], "batl": NaN}, {"timestamp": 1578771670041, "ltp": 5.2, "tv": 2814.44, "trd": [[5.2, 891.03]], "batb": [[0, 5.2, 114.59]], "batl": NaN}, {"timestamp": 1578771670946, "ltp": 5.2, "tv": 2826.4, "trd": [[5.2, 902.98]], "batb": [[0, 5.2, 108.61]], "batl": NaN}, {"timestamp": 1578771672032, "ltp": 5.2, "tv": 2831.66, "trd": [[5.2, 908.24]], "batb": [[0, 5.2, 105.98]], "batl": [[1, 5.4, 86.34]]}, {"timestamp": 1578771672920, "ltp": 5.2, "tv": 2840.51, "trd": [[5.2, 917.1]], "batb": [[0, 5.2, 101.55]], "batl": NaN}, {"timestamp": 1578771674035, "ltp": 5.2, "tv": 2851.13, "trd": [[5.2, 927.72]], "batb": [[0, 5.2, 96.24]], "batl": NaN}, {"timestamp": 1578771675046, "ltp": 5.2, "tv": 2869.64, "trd": [[5.2, 946.23]], "batb": [[0, 5.2, 86.99]], "batl": NaN}, {"timestamp": 1578771675985, "ltp": 5.2, "tv": 3043.62, "trd": [[5.2, 1120.21]], "batb": [[0, 5.1, 211.82], [1, 5, 128.66], [2, 4.9, 102.14]], "batl": [[0, 5.2, 29.94], [1, 5.3, 154.56], [2, 5.4, 86.34]]}, {"timestamp": 1578771684900, "ltp": 5.2, "tv": 3051.1, "trd": [[5.2, 1127.69]], "batb": NaN, "batl": [[0, 5.2, 26.19]]}, {"timestamp": 1578771690014, "ltp": 5.2, "tv": 3051.85, "trd": [[5.2, 1128.44]], "batb": NaN, "batl": [[0, 5.2, 25.82]]}, {"timestamp": 1578771696041, "ltp": 5.2, "tv": 3051.85, "trd": NaN, "batb": NaN, "batl": [[1, 5.3, 192.56], [2, 5.4, 123.34]]}, {"timestamp": 1578771704035, "ltp": 5.2, "tv": 3051.85, "trd": NaN, "batb": [[0, 5.1, 230.31]], "batl": [[1, 5.3, 154.56]]}, {"timestamp": 1578771705039, "ltp": 5.2, "tv": 3051.94, "trd": [[5.2, 1128.53]], "batb": NaN, "batl": [[0, 5.2, 25.77]]}, {"timestamp": 1578771706036, "ltp": 5.2, "tv": 3051.94, "trd": NaN, "batb": [[0, 5.1, 223.54]], "batl": NaN}, {"timestamp": 1578771715031, "ltp": 5.2, "tv": 3051.96, "trd": [[5.2, 1128.54]], "batb": NaN, "batl": [[0, 5.2, 25.77]]}, {"timestamp": 1578771718953, "ltp": 5.2, "tv": 3051.96, "trd": NaN, "batb": [[1, 5, 106.67], [2, 4.9, 80.12]], "batl": NaN}, {"timestamp": 1578771725981, "ltp": 5.2, "tv": 3051.96, "trd": NaN, "batb": [[0, 5.1, 230.31]], "batl": NaN}, {"timestamp": 1578771727049, "ltp": 5.2, "tv": 3051.96, "trd": NaN, "batb": NaN, "batl": [[1, 5.3, 192.56]]}, {"timestamp": 1578771733979, "ltp": 5.2, "tv": 3051.96, "trd": NaN, "batb": NaN, "batl": [[0, 5.2, 36.76]]}, {"timestamp": 1578771734983, "ltp": 5.2, "tv": 3051.96, "trd": NaN, "batb": NaN, "batl": [[0, 5.2, 53.56]]}, {"timestamp": 1578771736990, "ltp": 5.2, "tv": 3051.96, "trd": NaN, "batb": [[0, 5.1, 223.54]], "batl": NaN}, {"timestamp": 1578771738989, "ltp": 5.2, "tv": 3051.96, "trd": NaN, "batb": [[0, 5.1, 241.4]], "batl": NaN}, {"timestamp": 1578771757005, "ltp": 5.1, "tv": 3088.56, "trd": [[5.1, 1346.42]], "batb": [[0, 5.1, 223.1]], "batl": NaN}, {"timestamp": 1578771758009, "ltp": 5.1, "tv": 3094.86, "trd": [[5.1, 1352.72]], "batb": [[0, 5.1, 219.95]], "batl": [[0, 5.2, 134.07]]}, {"timestamp": 1578771764031, "ltp": 5.1, "tv": 3098.59, "trd": [[5.1, 1356.46]], "batb": [[0, 5.1, 218.08]], "batl": NaN}, {"timestamp": 1578771767018, "ltp": 5.1, "tv": 3098.59, "trd": NaN, "batb": [[0, 5.1, 181.73], [1, 5, 78.63]], "batl": [[0, 5.2, 123.07]]}, {"timestamp": 1578771776038, "ltp": 5.1, "tv": 3109.69, "trd": [[5.1, 1367.56]], "batb": [[0, 5.1, 119.36]], "batl": NaN}, {"timestamp": 1578771781022, "ltp": 5.1, "tv": 3128.13, "trd": [[5.1, 1385.99]], "batb": [[0, 5.1, 110.14]], "batl": NaN}, {"timestamp": 1578771782040, "ltp": 5.1, "tv": 3128.13, "trd": NaN, "batb": NaN, "batl": [[0, 5.2, 106.27]]}, {"timestamp": 1578771787046, "ltp": 5.1, "tv": 3210.83, "trd": [[5.1, 1468.7]], "batb": [[0, 5.1, 68.79]], "batl": NaN}, {"timestamp": 1578771788042, "ltp": 5.1, "tv": 3210.83, "trd": NaN, "batb": [[0, 5.1, 74.85]], "batl": [[0, 5.2, 137.63]]}, {"timestamp": 1578771792036, "ltp": 5.1, "tv": 3210.83, "trd": NaN, "batb": NaN, "batl": [[1, 5.3, 186.44], [2, 5.4, 117.22]]}, {"timestamp": 1578771793037, "ltp": 5.1, "tv": 3210.83, "trd": NaN, "batb": [[0, 5.1, 55.36]], "batl": NaN}, {"timestamp": 1578771794953, "ltp": 5.1, "tv": 3219.33, "trd": [[5.1, 1477.19]], "batb": [[0, 5.1, 51.11]], "batl": NaN}, {"timestamp": 1578771797048, "ltp": 5.1, "tv": 3225.63, "trd": [[5.1, 1483.49]], "batb": [[0, 5.1, 47.96]], "batl": NaN}, {"timestamp": 1578771804972, "ltp": 5.2, "tv": 3226.48, "trd": [[5.2, 1129.39]], "batb": NaN, "batl": [[0, 5.2, 137.2]]}, {"timestamp": 1578771807992, "ltp": 5.2, "tv": 3226.48, "trd": NaN, "batb": [[1, 5, 19.26]], "batl": NaN}, {"timestamp": 1578771809046, "ltp": 5.2, "tv": 3226.48, "trd": NaN, "batb": NaN, "batl": [[1, 5.3, 198.07]]}, {"timestamp": 1578771809951, "ltp": 5.2, "tv": 3226.68, "trd": [[5.2, 1129.6]], "batb": NaN, "batl": [[0, 5.2, 137.1]]}, {"timestamp": 1578771817993, "ltp": 5.2, "tv": 3226.68, "trd": NaN, "batb": NaN, "batl": [[1, 5.3, 194.36]]}, {"timestamp": 1578771818987, "ltp": 5.1, "tv": 3277.76, "trd": [[5.1, 1534.57]], "batb": [[0, 5.1, 22.42]], "batl": [[1, 5.3, 198.07]]}, {"timestamp": 1578771827011, "ltp": 5.1, "tv": 3322.14, "trd": [[5.1, 1578.95]], "batb": [[0, 5, 19.49], [1, 4.9, 80.12], [2, 4.8, 332.1]], "batl": NaN}, {"timestamp": 1578771830023, "ltp": 5.1, "tv": 3322.14, "trd": NaN, "batb": NaN, "batl": [[1, 5.3, 186.44]]}, {"timestamp": 1578771833911, "ltp": 5.1, "tv": 3322.14, "trd": NaN, "batb": NaN, "batl": [[1, 5.3, 198.07]]}, {"timestamp": 1578771835017, "ltp": 5.1, "tv": 3322.14, "trd": NaN, "batb": NaN, "batl": [[1, 5.3, 186.44]]}, {"timestamp": 1578771836044, "ltp": 5.1, "tv": 3322.14, "trd": NaN, "batb": [[2, 4.8, 52.15]], "batl": [[1, 5.3, 198.07]]}, {"timestamp": 1578771841034, "ltp": 5.1, "tv": 3322.6, "trd": [[5.1, 1579.41]], "batb": [[0, 5, 19.26]], "batl": [[0, 5.1, 18.46], [1, 5.2, 137.1], [2, 5.3, 198.07]]}, {"timestamp": 1578771842039, "ltp": 5.1, "tv": 3322.6, "trd": NaN, "batb": NaN, "batl": [[2, 5.3, 184.05]]}, {"timestamp": 1578771852014, "ltp": 5.1, "tv": 3359.51, "trd": [[5.1, 1616.32]], "batb": [[0, 5, 19.94]], "batl": [[0, 5.2, 137.1], [1, 5.3, 184.05], [2, 5.4, 103.21]]}, {"timestamp": 1578771857035, "ltp": 5.1, "tv": 3359.51, "trd": NaN, "batb": [[0, 5, 26.88]], "batl": NaN}, {"timestamp": 1578771860953, "ltp": 5.1, "tv": 3359.51, "trd": NaN, "batb": [[0, 5.1, 26.7], [1, 5, 26.2], [2, 4.9, 80.12]], "batl": NaN}, {"timestamp": 1578771861967, "ltp": 5.1, "tv": 3386.21, "trd": [[5.1, 1643.03]], "batb": [[0, 5, 26.2], [1, 4.9, 80.12], [2, 4.8, 52.15]], "batl": NaN}, {"timestamp": 1578771863963, "ltp": 5.1, "tv": 3386.21, "trd": NaN, "batb": [[0, 5, 26.45]], "batl": NaN}, {"timestamp": 1578771876997, "ltp": 5.0, "tv": 3394.48, "trd": [[5, 376.83], [5.1, 1643.54]], "batb": [[0, 5, 22.32]], "batl": NaN}, {"timestamp": 1578771878055, "ltp": 5.0, "tv": 3394.48, "trd": NaN, "batb": NaN, "batl": [[1, 5.3, 381.79]]}, {"timestamp": 1578771880052, "ltp": 5.0, "tv": 3399.4, "trd": [[5, 381.75]], "batb": [[0, 5, 19.86]], "batl": NaN}, {"timestamp": 1578771880972, "ltp": 5.0, "tv": 3399.4, "trd": NaN, "batb": NaN, "batl": [[0, 5.2, 147.1], [1, 5.3, 371.79]]}, {"timestamp": 1578771883992, "ltp": 5.0, "tv": 3399.4, "trd": NaN, "batb": NaN, "batl": [[1, 5.3, 360.16]]}, {"timestamp": 1578771895989, "ltp": 5.0, "tv": 3399.4, "trd": NaN, "batb": NaN, "batl": [[1, 5.3, 162.42]]}, {"timestamp": 1578771900005, "ltp": 5.2, "tv": 3429.4, "trd": [[5.2, 1159.59]], "batb": NaN, "batl": [[0, 5.2, 132.1]]}, {"timestamp": 1578771904978, "ltp": 5.2, "tv": 3429.4, "trd": NaN, "batb": NaN, "batl": [[0, 5.2, 170.1]]}, {"timestamp": 1578771905982, "ltp": 5.2, "tv": 3429.4, "trd": NaN, "batb": NaN, "batl": [[1, 5.3, 388.17]]}, {"timestamp": 1578771908039, "ltp": 5.2, "tv": 3429.4, "trd": NaN, "batb": NaN, "batl": [[1, 5.3, 162.42]]}, {"timestamp": 1578771912051, "ltp": 5.2, "tv": 3429.4, "trd": NaN, "batb": NaN, "batl": [[1, 5.3, 174.05]]}, {"timestamp": 1578771918947, "ltp": 5.2, "tv": 3429.4, "trd": NaN, "batb": NaN, "batl": [[0, 5.2, 132.1], [1, 5.3, 136.05]]}, {"timestamp": 1578771921957, "ltp": 5.2, "tv": 3429.4, "trd": NaN, "batb": NaN, "batl": [[0, 5.2, 170.1], [1, 5.3, 174.05]]}, {"timestamp": 1578771923056, "ltp": 5.2, "tv": 3429.4, "trd": NaN, "batb": [[0, 5.1, 14.98], [1, 5, 19.86], [2, 4.9, 80.12]], "batl": NaN}, {"timestamp": 1578771924053, "ltp": 5.2, "tv": 3429.4, "trd": NaN, "batb": NaN, "batl": [[0, 5.2, 132.1], [1, 5.3, 136.05]]}, {"timestamp": 1578771927047, "ltp": 5.2, "tv": 3429.4, "trd": NaN, "batb": NaN, "batl": [[0, 5.2, 170.1], [1, 5.3, 174.05]]}, {"timestamp": 1578771931038, "ltp": 5.2, "tv": 3429.4, "trd": NaN, "batb": NaN, "batl": [[1, 5.3, 164.75]]}, {"timestamp": 1578771934054, "ltp": 5.2, "tv": 3429.4, "trd": NaN, "batb": NaN, "batl": [[1, 5.3, 162.42]]}, {"timestamp": 1578771937978, "ltp": 5.2, "tv": 3429.4, "trd": NaN, "batb": [[1, 5, 83.7]], "batl": NaN}, {"timestamp": 1578771946770, "ltp": 5.2, "tv": 3429.4, "trd": NaN, "batb": NaN, "batl": [[0, 5.2, 159.86]]}, {"timestamp": 1578771951964, "ltp": 5.2, "tv": 3429.4, "trd": NaN, "batb": NaN, "batl": [[0, 5.2, 121.86], [1, 5.3, 124.42]]}, {"timestamp": 1578771964991, "ltp": 5.2, "tv": 3429.4, "trd": NaN, "batb": [[1, 5, 87.28], [2, 4.9, 76.54]], "batl": NaN}, {"timestamp": 1578771982009, "ltp": 5.1, "tv": 3433.14, "trd": [[5.1, 1647.28]], "batb": [[0, 5.1, 13.11]], "batl": NaN}, {"timestamp": 1578771989051, "ltp": 5.2, "tv": 3440.19, "trd": [[5.2, 1166.64]], "batb": NaN, "batl": [[0, 5.2, 118.34]]}, {"timestamp": 1578771998011, "ltp": 5.2, "tv": 3440.19, "trd": NaN, "batb": NaN, "batl": [[0, 5.2, 126.85]]}, {"timestamp": 1578772010043, "ltp": 5.2, "tv": 3447.43, "trd": [[5.2, 1173.88]], "batb": NaN, "batl": [[0, 5.2, 123.23]]}, {"timestamp": 1578772014028, "ltp": 5.2, "tv": 3447.43, "trd": NaN, "batb": [[0, 5.1, 16.73]], "batl": NaN}, {"timestamp": 1578772024855, "ltp": 5.2, "tv": 3447.43, "trd": NaN, "batb": NaN, "batl": [[0, 5.2, 91.88]]}, {"timestamp": 1578772026964, "ltp": 5.2, "tv": 3447.43, "trd": NaN, "batb": [[0, 5.1, 23.67], [1, 5, 80.34]], "batl": NaN}, {"timestamp": 1578772028960, "ltp": 5.2, "tv": 3631.18, "trd": [[5.2, 1357.63]], "batb": [[0, 5.2, 1.65], [1, 5.1, 23.67], [2, 5, 80.34]], "batl": [[0, 5.3, 124.42], [1, 5.4, 114.57], [2, 5.5, 96.1]]}, {"timestamp": 1578772033875, "ltp": 5.2, "tv": 3631.18, "trd": NaN, "batb": NaN, "batl": [[0, 5.3, 162.42]]}, {"timestamp": 1578772036034, "ltp": 5.2, "tv": 3631.18, "trd": NaN, "batb": [[0, 5.2, 26.65]], "batl": NaN}, {"timestamp": 1578772037977, "ltp": 5.3, "tv": 3681.18, "trd": [[5.3, 50.11]], "batb": [[0, 5.2, 1.65]], "batl": [[0, 5.3, 137.42], [1, 5.4, 103.21]]}, {"timestamp": 1578772040984, "ltp": 5.3, "tv": 3681.18, "trd": NaN, "batb": NaN, "batl": [[1, 5.4, 114.57]]}, {"timestamp": 1578772046969, "ltp": 5.2, "tv": 3684.48, "trd": [[5.2, 1360.94]], "batb": [[0, 5.1, 23.67], [1, 5, 80.34], [2, 4.9, 76.54]], "batl": [[0, 5.2, 1.96], [1, 5.3, 137.42], [2, 5.4, 114.57]]}, {"timestamp": 1578772048962, "ltp": 5.2, "tv": 3684.48, "trd": NaN, "batb": NaN, "batl": [[1, 5.3, 147.42]]}, {"timestamp": 1578772050001, "ltp": 5.2, "tv": 3684.48, "trd": NaN, "batb": NaN, "batl": [[0, 5.2, 39.96]]}, {"timestamp": 1578772052865, "ltp": 5.2, "tv": 3684.48, "trd": NaN, "batb": [[0, 5.1, 94.1]], "batl": NaN}, {"timestamp": 1578772060977, "ltp": 5.2, "tv": 3684.48, "trd": NaN, "batb": NaN, "batl": [[0, 5.2, 49.96], [1, 5.3, 137.42]]}, {"timestamp": 1578772069011, "ltp": 5.2, "tv": 3684.48, "trd": NaN, "batb": NaN, "batl": [[2, 5.4, 105.48]]}, {"timestamp": 1578772070993, "ltp": 5.2, "tv": 3684.48, "trd": NaN, "batb": NaN, "batl": [[0, 5.2, 11.96]]}, {"timestamp": 1578772081025, "ltp": 5.1, "tv": 3689.41, "trd": [[5.1, 1652.2]], "batb": [[0, 5.1, 91.64]], "batl": NaN}, {"timestamp": 1578772083019, "ltp": 5.1, "tv": 3708.1, "trd": [[5.1, 1670.89]], "batb": [[0, 5.1, 82.29]], "batl": NaN}, {"timestamp": 1578772084018, "ltp": 5.1, "tv": 3708.1, "trd": NaN, "batb": NaN, "batl": [[2, 5.4, 114.57]]}, {"timestamp": 1578772093024, "ltp": 5.1, "tv": 3708.99, "trd": [[5.1, 1671.78]], "batb": [[0, 5.1, 81.85]], "batl": NaN}, {"timestamp": 1578772098026, "ltp": 5.1, "tv": 3708.99, "trd": NaN, "batb": NaN, "batl": [[0, 5.2, 196.36], [1, 5.3, 99.42], [2, 5.4, 77.57]]}, {"timestamp": 1578772098957, "ltp": 5.1, "tv": 3708.99, "trd": NaN, "batb": NaN, "batl": [[0, 5.2, 225.02]]}, {"timestamp": 1578772101023, "ltp": 5.1, "tv": 3708.99, "trd": NaN, "batb": [[1, 5, 16.5], [2, 4.9, 25.54]], "batl": [[0, 5.2, 10], [1, 5.3, 0], [2, 5.4, 0]]}, {"timestamp": 1578772108019, "ltp": 5.1, "tv": 3708.99, "trd": NaN, "batb": [[1, 5, 75.87], [2, 4.9, 85.85]], "batl": [[1, 5.3, 28.43], [2, 5.4, 28.2]]}, {"timestamp": 1578772108966, "ltp": 5.2, "tv": 3728.23, "trd": [[5.2, 1380.17]], "batb": [[1, 5, 16.5], [2, 4.9, 25.54]], "batl": [[0, 5.2, 103.62], [1, 8.4, 9.18], [2, 9.2, 27.22]]}, {"timestamp": 1578772109962, "ltp": 5.2, "tv": 3728.23, "trd": NaN, "batb": NaN, "batl": [[2, 18, 10.37]]}, {"timestamp": 1578772113015, "ltp": 5.2, "tv": 3728.23, "trd": NaN, "batb": NaN, "batl": [[1, 5.5, 4.26], [2, 7, 5.28]]}, {"timestamp": 1578772114999, "ltp": 5.2, "tv": 3728.23, "trd": NaN, "batb": NaN, "batl": [[1, 5.3, 7.66], [2, 5.5, 4.26]]}, {"timestamp": 1578772116004, "ltp": 5.2, "tv": 3728.23, "trd": NaN, "batb": NaN, "batl": [[0, 5.3, 16.12], [1, 5.4, 27.64], [2, 5.5, 7.66]]}, {"timestamp": 1578772117012, "ltp": 5.2, "tv": 3728.23, "trd": NaN, "batb": [[2, 4.9, 31.89]], "batl": [[0, 5.3, 11.42]]}, {"timestamp": 1578772119992, "ltp": 5.2, "tv": 3728.23, "trd": NaN, "batb": NaN, "batl": [[1, 5.4, 39.65]]}, {"timestamp": 1578772120976, "ltp": 5.2, "tv": 3728.23, "trd": NaN, "batb": [[1, 5, 22.76]], "batl": [[0, 5.3, 14.48], [1, 5.4, 49.16]]}, {"timestamp": 1578772122018, "ltp": 5.2, "tv": 3728.23, "trd": NaN, "batb": NaN, "batl": [[0, 5.3, 27.2]]}, {"timestamp": 1578772123020, "ltp": 5.2, "tv": 3728.23, "trd": NaN, "batb": NaN, "batl": [[0, 5.3, 23.07], [1, 5.4, 40.25]]}, {"timestamp": 1578772124032, "ltp": 5.2, "tv": 3728.23, "trd": NaN, "batb": [[1, 5, 41.33], [2, 4.9, 50.37]], "batl": [[0, 5.3, 434.38], [1, 5.4, 68.77], [2, 5.5, 3.4]]}, {"timestamp": 1578772125024, "ltp": 5.2, "tv": 3728.23, "trd": NaN, "batb": NaN, "batl": [[1, 5.4, 76.43]]}, {"timestamp": 1578772131049, "ltp": 5.2, "tv": 3728.23, "trd": NaN, "batb": NaN, "batl": [[2, 5.5, 7.66]]}, {"timestamp": 1578772132044, "ltp": 5.2, "tv": 3728.23, "trd": NaN, "batb": NaN, "batl": [[0, 5.2, 317.99], [1, 5.3, 473.14], [2, 5.4, 76.43]]}, {"timestamp": 1578772132990, "ltp": 5.2, "tv": 3728.23, "trd": NaN, "batb": NaN, "batl": [[1, 5.3, 443.55]]}, {"timestamp": 1578772134031, "ltp": 5.2, "tv": 3728.23, "trd": NaN, "batb": NaN, "batl": [[1, 5.3, 463.33]]}, {"timestamp": 1578772136903, "ltp": 5.2, "tv": 3728.23, "trd": NaN, "batb": NaN, "batl": [[1, 5.3, 467.67]]}, {"timestamp": 1578772138009, "ltp": 5.2, "tv": 3728.23, "trd": NaN, "batb": NaN, "batl": [[1, 5.3, 471.94]]}, {"timestamp": 1578772140008, "ltp": 5.2, "tv": 3728.23, "trd": NaN, "batb": [[2, 4.9, 93.37]], "batl": [[0, 5.2, 342.83], [1, 5.3, 483.87], [2, 5.4, 57.7]]}, {"timestamp": 1578772141005, "ltp": 5.2, "tv": 3728.23, "trd": NaN, "batb": NaN, "batl": [[1, 5.3, 515.35]]}, {"timestamp": 1578772142048, "ltp": 5.2, "tv": 3849.76, "trd": [[5.2, 1501.71]], "batb": NaN, "batl": [[0, 5.2, 282.06]]}, {"timestamp": 1578772143047, "ltp": 5.2, "tv": 3849.76, "trd": NaN, "batb": NaN, "batl": [[0, 5.2, 257.22], [1, 5.3, 486.96]]}, {"timestamp": 1578772146042, "ltp": 5.2, "tv": 3849.76, "trd": NaN, "batb": NaN, "batl": [[1, 5.3, 72.54]]}, {"timestamp": 1578772147044, "ltp": 5.2, "tv": 3849.76, "trd": NaN, "batb": NaN, "batl": [[0, 5.3, 72.54], [1, 5.4, 57.7], [2, 5.5, 4.26]]}, {"timestamp": 1578772148053, "ltp": 5.2, "tv": 3849.76, "trd": NaN, "batb": NaN, "batl": [[0, 5.3, 41.06]]}, {"timestamp": 1578772153956, "ltp": 5.2, "tv": 3849.76, "trd": NaN, "batb": NaN, "batl": [[0, 5.2, 312.68], [1, 5.3, 258.06], [2, 5.4, 57.7]]}, {"timestamp": 1578772154951, "ltp": 5.2, "tv": 3849.76, "trd": NaN, "batb": [[1, 5, 51.33]], "batl": [[0, 5.3, 475.06], [1, 5.4, 57.7], [2, 5.5, 4.26]]}, {"timestamp": 1578772158042, "ltp": 5.2, "tv": 3849.76, "trd": NaN, "batb": [[1, 5, 75.6]], "batl": NaN}, {"timestamp": 1578772159039, "ltp": 5.2, "tv": 3849.76, "trd": NaN, "batb": [[2, 4.9, 50.37]], "batl": NaN}, {"timestamp": 1578772161961, "ltp": 5.2, "tv": 3849.76, "trd": NaN, "batb": NaN, "batl": [[0, 5.3, 505.6]]}, {"timestamp": 1578772165013, "ltp": 5.2, "tv": 3849.76, "trd": NaN, "batb": [[1, 5, 111.53], [2, 4.9, 109.01]], "batl": [[0, 5.3, 573.05]]}, {"timestamp": 1578772166034, "ltp": 5.2, "tv": 3849.76, "trd": NaN, "batb": [[1, 5, 57.02]], "batl": NaN}, {"timestamp": 1578772166972, "ltp": 5.2, "tv": 3849.76, "trd": NaN, "batb": NaN, "batl": [[0, 5.3, 811.8]]}, {"timestamp": 1578772167963, "ltp": 5.2, "tv": 3849.76, "trd": NaN, "batb": NaN, "batl": [[0, 5.2, 150], [1, 5.3, 811.8], [2, 5.4, 57.7]]}, {"timestamp": 1578772168951, "ltp": 5.2, "tv": 3849.76, "trd": NaN, "batb": NaN, "batl": [[0, 5.2, 169.13]]}, {"timestamp": 1578772171972, "ltp": 5.2, "tv": 3849.76, "trd": NaN, "batb": [[1, 5, 32.76], [2, 4.9, 134.07]], "batl": NaN}, {"timestamp": 1578772172957, "ltp": 5.2, "tv": 3849.76, "trd": NaN, "batb": NaN, "batl": [[0, 5.2, 180.16]]}, {"timestamp": 1578772175043, "ltp": 5.1, "tv": 3888.03, "trd": [[5.1, 1710.05]], "batb": [[0, 5.1, 62.71]], "batl": NaN}, {"timestamp": 1578772175975, "ltp": 5.1, "tv": 3888.03, "trd": NaN, "batb": NaN, "batl": [[0, 5.2, 273.59]]}, {"timestamp": 1578772176969, "ltp": 5.1, "tv": 3910.52, "trd": [[5.1, 1732.54]], "batb": [[0, 5.1, 51.47]], "batl": NaN}, {"timestamp": 1578772179050, "ltp": 5.1, "tv": 4013.46, "trd": [[5.1, 1835.48]], "batb": [[0, 5, 32.76], [1, 4.9, 134.07], [2, 4.8, 149.04]], "batl": [[0, 5.1, 100.23], [1, 5.2, 273.59], [2, 5.3, 811.8]]}, {"timestamp": 1578772179996, "ltp": 5.1, "tv": 4013.46, "trd": NaN, "batb": [[0, 5, 26.5]], "batl": NaN}, {"timestamp": 1578772183963, "ltp": 5.1, "tv": 4013.46, "trd": NaN, "batb": [[2, 4.8, 103.04]], "batl": NaN}, {"timestamp": 1578772185006, "ltp": 5.1, "tv": 4013.46, "trd": NaN, "batb": NaN, "batl": [[1, 5.2, 254.45]]}, {"timestamp": 1578772185997, "ltp": 5.1, "tv": 4013.46, "trd": NaN, "batb": [[1, 4.9, 145.25]], "batl": [[0, 5.1, 102.1], [1, 5.2, 359.85]]}, {"timestamp": 1578772186994, "ltp": 5.1, "tv": 4013.46, "trd": NaN, "batb": NaN, "batl": [[1, 5.2, 400]]}, {"timestamp": 1578772187991, "ltp": 5.1, "tv": 4013.46, "trd": NaN, "batb": [[2, 4.8, 108.04]], "batl": [[2, 5.3, 816.06]]}, {"timestamp": 1578772188984, "ltp": 5.1, "tv": 4013.46, "trd": NaN, "batb": NaN, "batl": [[0, 5.1, 552.35]]}, {"timestamp": 1578772189980, "ltp": 5.1, "tv": 4013.46, "trd": NaN, "batb": NaN, "batl": [[2, 5.3, 942.06]]}, {"timestamp": 1578772190967, "ltp": 5.1, "tv": 4013.46, "trd": NaN, "batb": NaN, "batl": [[0, 5.1, 100.23]]}, {"timestamp": 1578772192015, "ltp": 5.1, "tv": 4013.46, "trd": NaN, "batb": NaN, "batl": [[1, 5.2, 819], [2, 5.3, 703.31]]}, {"timestamp": 1578772192997, "ltp": 5.1, "tv": 4013.46, "trd": NaN, "batb": NaN, "batl": [[1, 5.2, 306.57], [2, 5.3, 683.73]]}, {"timestamp": 1578772193985, "ltp": 5.1, "tv": 4013.46, "trd": NaN, "batb": [[1, 4.9, 167.76]], "batl": NaN}, {"timestamp": 1578772194971, "ltp": 5.1, "tv": 4013.46, "trd": NaN, "batb": [[1, 4.9, 149.28]], "batl": NaN}, {"timestamp": 1578772197010, "ltp": 5.1, "tv": 4013.46, "trd": NaN, "batb": NaN, "batl": [[1, 5.2, 450.57]]}, {"timestamp": 1578772199036, "ltp": 5.1, "tv": 4013.46, "trd": NaN, "batb": NaN, "batl": [[0, 5.1, 193.66]]}, {"timestamp": 1578772200033, "ltp": 5.1, "tv": 4013.46, "trd": NaN, "batb": NaN, "batl": [[1, 5.2, 446.15]]}, {"timestamp": 1578772205038, "ltp": 5.0, "tv": 4017.2, "trd": [[5, 385.49]], "batb": [[0, 5, 24.63]], "batl": NaN}, {"timestamp": 1578772206035, "ltp": 5.0, "tv": 4017.2, "trd": NaN, "batb": [[1, 4.9, 115.59]], "batl": [[1, 5.2, 435.12]]}, {"timestamp": 1578772214029, "ltp": 5.0, "tv": 4024.86, "trd": [[5, 393.15]], "batb": [[0, 5, 20.8]], "batl": [[0, 5.1, 345.66]]}, {"timestamp": 1578772216019, "ltp": 5.0, "tv": 4024.86, "trd": NaN, "batb": NaN, "batl": [[0, 5.1, 349.4]]}, {"timestamp": 1578772217010, "ltp": 5.0, "tv": 4024.86, "trd": NaN, "batb": NaN, "batl": [[0, 5.1, 786.35]]}, {"timestamp": 1578772219055, "ltp": 5.0, "tv": 4024.86, "trd": NaN, "batb": [[1, 4.9, 148.36]], "batl": NaN}, {"timestamp": 1578772221046, "ltp": 5.0, "tv": 4024.86, "trd": NaN, "batb": NaN, "batl": [[0, 5.1, 197.4], [1, 5.2, 291.12], [2, 5.3, 557.73]]}, {"timestamp": 1578772222038, "ltp": 5.0, "tv": 4200.66, "trd": [[5, 568.95]], "batb": [[0, 4.9, 148.36], [1, 4.8, 108.04], [2, 4.7, 449.48]], "batl": NaN}, {"timestamp": 1578772223039, "ltp": 5.0, "tv": 4200.66, "trd": NaN, "batb": [[0, 4.9, 89.72]], "batl": NaN}, {"timestamp": 1578772224031, "ltp": 5.0, "tv": 4200.66, "trd": NaN, "batb": NaN, "batl": [[0, 5.1, 195.7]]}, {"timestamp": 1578772225971, "ltp": 5.0, "tv": 4200.66, "trd": NaN, "batb": [[1, 4.8, 144.43]], "batl": NaN}, {"timestamp": 1578772226954, "ltp": 5.0, "tv": 4200.66, "trd": NaN, "batb": [[0, 4.9, 56.95], [1, 4.8, 108.04]], "batl": [[2, 5.3, 93.2]]}, {"timestamp": 1578772228052, "ltp": 5.0, "tv": 4200.66, "trd": NaN, "batb": [[0, 4.9, 50.6]], "batl": [[2, 5.3, 4.26]]}, {"timestamp": 1578772229043, "ltp": 5.0, "tv": 4202.95, "trd": [[5, 571.24]], "batb": NaN, "batl": [[2, 5.3, 7.66]]}, {"timestamp": 1578772230042, "ltp": 5.0, "tv": 4202.95, "trd": NaN, "batb": NaN, "batl": [[2, 5.3, 3.4]]}, {"timestamp": 1578772233979, "ltp": 5.0, "tv": 4202.95, "trd": NaN, "batb": NaN, "batl": [[0, 5.1, 225.56], [1, 5.2, 730.26]]}, {"timestamp": 1578772235048, "ltp": 5.0, "tv": 4202.95, "trd": NaN, "batb": [[1, 4.8, 145.62]], "batl": [[0, 5, 167], [1, 5.1, 477.65], [2, 5.2, 877.26]]}, {"timestamp": 1578772236042, "ltp": 5.0, "tv": 4202.95, "trd": NaN, "batb": [[1, 4.8, 126.86]], "batl": [[2, 5.2, 901.26]]}, {"timestamp": 1578772236982, "ltp": 5.0, "tv": 4202.95, "trd": NaN, "batb": NaN, "batl": [[2, 5.2, 905.52]]}, {"timestamp": 1578772237971, "ltp": 5.0, "tv": 4202.95, "trd": NaN, "batb": NaN, "batl": [[2, 5.2, 885.94]]}, {"timestamp": 1578772239957, "ltp": 5.0, "tv": 4202.95, "trd": NaN, "batb": [[1, 4.8, 89.27]], "batl": [[2, 5.2, 861.94]]}, {"timestamp": 1578772242966, "ltp": 5.0, "tv": 4202.95, "trd": NaN, "batb": [[2, 4.7, 155.73]], "batl": NaN}, {"timestamp": 1578772243962, "ltp": 5.0, "tv": 4202.95, "trd": NaN, "batb": [[2, 4.7, 350.73]], "batl": NaN}, {"timestamp": 1578772245012, "ltp": 5.0, "tv": 4202.95, "trd": NaN, "batb": NaN, "batl": [[1, 5.1, 498.08]]}, {"timestamp": 1578772246963, "ltp": 5.0, "tv": 4202.95, "trd": NaN, "batb": NaN, "batl": [[2, 5.2, 711.94]]}, {"timestamp": 1578772248055, "ltp": 5.0, "tv": 4202.95, "trd": NaN, "batb": NaN, "batl": [[1, 5.1, 477.65]]}, {"timestamp": 1578772248994, "ltp": 5.0, "tv": 4202.95, "trd": NaN, "batb": NaN, "batl": [[0, 5, 175.97]]}, {"timestamp": 1578772250050, "ltp": 4.9, "tv": 4213.66, "trd": [[4.9, 175.15]], "batb": [[0, 4.9, 45.25]], "batl": NaN}, {"timestamp": 1578772254993, "ltp": 5.0, "tv": 4214.14, "trd": [[5, 571.72]], "batb": [[2, 4.7, 312.73]], "batl": [[0, 5, 175.73]]}, {"timestamp": 1578772256986, "ltp": 5.0, "tv": 4217.88, "trd": [[5, 575.46]], "batb": NaN, "batl": [[0, 5, 173.86], [1, 5.1, 379.12]]}, {"timestamp": 1578772258971, "ltp": 5.0, "tv": 4217.88, "trd": NaN, "batb": NaN, "batl": [[0, 5, 164.89]]}, {"timestamp": 1578772259971, "ltp": 5.0, "tv": 4217.88, "trd": NaN, "batb": NaN, "batl": [[0, 5, 167.19]]}, {"timestamp": 1578772262019, "ltp": 5.0, "tv": 4217.88, "trd": NaN, "batb": [[0, 4.9, 95.25]], "batl": NaN}, {"timestamp": 1578772262972, "ltp": 4.9, "tv": 4408.37, "trd": [[4.9, 365.63]], "batb": [[0, 4.8, 116.6], [1, 4.7, 312.73], [2, 4.6, 796.32]], "batl": [[2, 5.2, 702.14]]}, {"timestamp": 1578772264028, "ltp": 4.9, "tv": 4408.37, "trd": NaN, "batb": [[0, 4.8, 58.59], [2, 4.6, 640.07]], "batl": [[2, 5.2, 263]]}, {"timestamp": 1578772265855, "ltp": 4.9, "tv": 4408.37, "trd": NaN, "batb": NaN, "batl": [[0, 4.9, 8.97], [1, 5, 167.19], [2, 5.1, 829.67]]}, {"timestamp": 1578772270045, "ltp": 4.9, "tv": 4408.37, "trd": NaN, "batb": [[0, 4.8, 25]], "batl": [[1, 5, 12.3], [2, 5.1, 669.67]]}, {"timestamp": 1578772271046, "ltp": 4.9, "tv": 4408.37, "trd": NaN, "batb": NaN, "batl": [[2, 5.1, 576.24]]}, {"timestamp": 1578772272003, "ltp": 4.9, "tv": 4408.37, "trd": NaN, "batb": NaN, "batl": [[0, 5, 12.3], [1, 5.1, 125.69], [2, 5.2, 439.58]]}, {"timestamp": 1578772273001, "ltp": 4.9, "tv": 4408.37, "trd": NaN, "batb": NaN, "batl": [[0, 5, 2.3]]}, {"timestamp": 1578772273991, "ltp": 4.9, "tv": 4408.37, "trd": NaN, "batb": NaN, "batl": [[0, 5, 44.5]]}, {"timestamp": 1578772275035, "ltp": 4.9, "tv": 4408.37, "trd": NaN, "batb": NaN, "batl": [[0, 5, 15.46]]}, {"timestamp": 1578772276028, "ltp": 5.0, "tv": 4409.91, "trd": [[5, 577]], "batb": NaN, "batl": [[0, 5, 14.68]]}, {"timestamp": 1578772277034, "ltp": 5.0, "tv": 4421.25, "trd": [[5, 588.34]], "batb": NaN, "batl": [[0, 5, 3.35]]}, {"timestamp": 1578772278020, "ltp": 5.0, "tv": 4421.25, "trd": NaN, "batb": NaN, "batl": [[0, 5.1, 125.69], [1, 5.2, 439.58], [2, 5.3, 141.4]]}, {"timestamp": 1578772279014, "ltp": 4.8, "tv": 4439.19, "trd": [[4.8, 77.58]], "batb": [[0, 4.8, 16.03]], "batl": NaN}, {"timestamp": 1578772280008, "ltp": 4.8, "tv": 4439.19, "trd": NaN, "batb": NaN, "batl": [[0, 5.1, 347.92]]}, {"timestamp": 1578772285035, "ltp": 4.8, "tv": 4439.19, "trd": NaN, "batb": [[0, 4.9, 3.06], [1, 4.8, 16.03], [2, 4.7, 312.73]], "batl": NaN}, {"timestamp": 1578772286034, "ltp": 4.8, "tv": 4439.19, "trd": NaN, "batb": [[0, 4.9, 11.12]], "batl": NaN}, {"timestamp": 1578772288028, "ltp": 4.8, "tv": 4439.19, "trd": NaN, "batb": NaN, "batl": [[0, 5, 9.89], [1, 5.1, 347.92], [2, 5.2, 439.58]]}, {"timestamp": 1578772288914, "ltp": 4.8, "tv": 4439.19, "trd": NaN, "batb": NaN, "batl": [[0, 5, 30.32]]}, {"timestamp": 1578772290015, "ltp": 4.8, "tv": 4439.19, "trd": NaN, "batb": NaN, "batl": [[0, 5.1, 347.92], [1, 5.2, 439.58], [2, 5.3, 141.4]]}, {"timestamp": 1578772290955, "ltp": 4.8, "tv": 4536.34, "trd": [[4.8, 152.49], [4.9, 387.87]], "batb": [[0, 4.7, 312.73], [1, 4.6, 640.07], [2, 4.5, 939.21]], "batl": NaN}, {"timestamp": 1578772291956, "ltp": 4.8, "tv": 4536.34, "trd": NaN, "batb": NaN, "batl": [[0, 4.9, 22.96], [1, 5.1, 347.92], [2, 5.2, 439.58]]}, {"timestamp": 1578772293054, "ltp": 4.8, "tv": 4536.34, "trd": NaN, "batb": NaN, "batl": [[2, 5.2, 370.83]]}, {"timestamp": 1578772293949, "ltp": 4.8, "tv": 4536.34, "trd": NaN, "batb": [[0, 4.8, 6.07], [1, 4.7, 117.73], [2, 4.6, 440.07]], "batl": [[2, 5.2, 223.83]]}, {"timestamp": 1578772294860, "ltp": 4.8, "tv": 4536.34, "trd": NaN, "batb": [[0, 4.7, 39.12], [1, 4.6, 357.91], [2, 4.5, 664]], "batl": [[1, 5.1, 247.96], [2, 5.2, 219.57]]}, {"timestamp": 1578772296040, "ltp": 4.8, "tv": 4536.34, "trd": NaN, "batb": [[0, 4.7, 32.71], [1, 4.6, 308.65], [2, 4.5, 343.16]], "batl": [[1, 5.1, 3.74], [2, 19.5, 1.86]]}, {"timestamp": 1578772308353, "ltp": 4.8, "tv": 4536.34, "trd": NaN, "batb": NaN, "batl": [[0, 5.1, 3.74], [1, 19.5, 1.86], [2, 480, 3.4]]}, {"timestamp": 1578772347979, "ltp": 4.8, "tv": 4536.34, "trd": NaN, "batb": [[1, 4.5, 8.51], [2, 4.4, 12.77]], "batl": [[0, 19.5, 1.86], [1, 19.5, 0], [2, 480, 0]]}, {"timestamp": 1578772355022, "ltp": 8.0, "tv": 4536.49, "trd": [[8, 0.15]], "batb": [[0, 10.5, 5.01], [1, 4.7, 32.71], [2, 4.5, 8.51]], "batl": [[0, 19.5, 1.7]]}, {"timestamp": 1578772356009, "ltp": 8.0, "tv": 4536.49, "trd": NaN, "batb": [[0, 14, 76.53], [1, 10.5, 5.01], [2, 4.7, 32.71]], "batl": NaN}, {"timestamp": 1578772356995, "ltp": 8.0, "tv": 4536.49, "trd": NaN, "batb": [[1, 11.5, 76.53], [2, 10.5, 5.01]], "batl": NaN}, {"timestamp": 1578772357976, "ltp": 8.0, "tv": 4536.49, "trd": NaN, "batb": NaN, "batl": [[1, 480, 3.4]]}, {"timestamp": 1578772363012, "ltp": 8.0, "tv": 4536.49, "trd": NaN, "batb": [[0, 15, 38], [1, 14.5, 42], [2, 14, 125.53]], "batl": [[1, 24, 18], [2, 25, 16]]}, {"timestamp": 1578772364005, "ltp": 8.0, "tv": 4536.49, "trd": NaN, "batb": [[0, 15, 165.68]], "batl": NaN}, {"timestamp": 1578772364993, "ltp": 8.0, "tv": 4536.49, "trd": NaN, "batb": [[0, 15.5, 36], [1, 15, 165.68], [2, 14.5, 42]], "batl": NaN}, {"timestamp": 1578772368009, "ltp": 8.0, "tv": 4536.49, "trd": NaN, "batb": NaN, "batl": [[0, 19.5, 51.7]]}, {"timestamp": 1578772369001, "ltp": 8.0, "tv": 4536.49, "trd": NaN, "batb": NaN, "batl": [[1, 21, 7.66], [2, 24, 18]]}, {"timestamp": 1578772371027, "ltp": 8.0, "tv": 4536.49, "trd": NaN, "batb": [[0, 15.5, 336]], "batl": NaN}, {"timestamp": 1578772372020, "ltp": 15.5, "tv": 4540.79, "trd": [[15.5, 4.3]], "batb": [[0, 15.5, 333.85]], "batl": [[0, 18.5, 50], [1, 19.5, 51.7], [2, 21, 7.66]]}, {"timestamp": 1578772373009, "ltp": 15.5, "tv": 4540.79, "trd": NaN, "batb": [[0, 15.5, 372.12]], "batl": NaN}, {"timestamp": 1578772375041, "ltp": 15.5, "tv": 4540.79, "trd": NaN, "batb": NaN, "batl": [[0, 17.5, 50], [1, 18.5, 50], [2, 19.5, 51.7]]}, {"timestamp": 1578772375927, "ltp": 15.5, "tv": 4540.79, "trd": NaN, "batb": [[0, 16, 52.5], [1, 15.5, 372.12], [2, 15, 165.68]], "batl": [[0, 17, 50], [1, 17.5, 50], [2, 18.5, 50]]}, {"timestamp": 1578772377028, "ltp": 15.5, "tv": 4540.79, "trd": NaN, "batb": [[0, 16, 30]], "batl": [[2, 18, 8.47]]}, {"timestamp": 1578772378023, "ltp": 15.5, "tv": 4540.79, "trd": NaN, "batb": [[2, 15, 176.05]], "batl": [[2, 18, 30.23]]}, {"timestamp": 1578772379046, "ltp": 15.5, "tv": 4540.79, "trd": NaN, "batb": NaN, "batl": [[2, 18.5, 50]]}, {"timestamp": 1578772380032, "ltp": 16.0, "tv": 4544.19, "trd": [[16, 3.4]], "batb": [[0, 16, 28.3]], "batl": [[2, 18.5, 69.32]]}, {"timestamp": 1578772381024, "ltp": 16.0, "tv": 4546.69, "trd": [[16, 5.9]], "batb": [[0, 16, 27.05]], "batl": [[2, 18.5, 50]]}, {"timestamp": 1578772383028, "ltp": 16.0, "tv": 4561.49, "trd": [[16, 9.4], [17, 11.3]], "batb": [[0, 16, 25.3]], "batl": [[0, 17, 44.35]]}, {"timestamp": 1578772384025, "ltp": 17.0, "tv": 4561.75, "trd": [[17, 11.56]], "batb": [[0, 16.5, 29.03], [1, 16, 25.3], [2, 15.5, 372.12]], "batl": [[0, 17, 44.22]]}, {"timestamp": 1578772384907, "ltp": 17.5, "tv": 4750.19, "trd": [[17, 100], [17.5, 100]], "batb": [[0, 17.5, 4.26], [1, 17, 2.55], [2, 16.5, 29.03]], "batl": [[0, 18.5, 50], [1, 19.5, 51.7], [2, 22, 121.19]]}, {"timestamp": 1578772385966, "ltp": 15.5, "tv": 4784.46, "trd": [[15.5, 16.74], [16, 26.12], [17, 105.11]], "batb": [[0, 16, 11.01], [1, 15.5, 431.3], [2, 15, 232.56]], "batl": [[1, 19.5, 60.5], [2, 21, 27]]}, {"timestamp": 1578772386964, "ltp": 15.5, "tv": 4784.46, "trd": NaN, "batb": NaN, "batl": [[1, 19.5, 71.71], [2, 20, 17.88]]}, {"timestamp": 1578772387959, "ltp": 18.0, "tv": 4816.8, "trd": [[18, 32.35]], "batb": NaN, "batl": NaN}, {"timestamp": 1578772388952, "ltp": 18.0, "tv": 4816.8, "trd": NaN, "batb": [[0, 16, 41.01]], "batl": [[0, 17.5, 10], [1, 18.5, 50], [2, 19.5, 71.71]]}, {"timestamp": 1578772390974, "ltp": 18.0, "tv": 4816.8, "trd": NaN, "batb": [[1, 15.5, 408.24]], "batl": NaN}, {"timestamp": 1578772392023, "ltp": 17.5, "tv": 4816.94, "trd": [[17.5, 100.14]], "batb": NaN, "batl": [[0, 17.5, 9.93]]}, {"timestamp": 1578772392968, "ltp": 16.5, "tv": 4837.52, "trd": [[16.5, 20.58]], "batb": [[0, 16, 41.93]], "batl": [[2, 19.5, 62.92]]}, {"timestamp": 1578772394032, "ltp": 16.0, "tv": 4843.63, "trd": [[16, 32.14], [17.5, 100.22]], "batb": [[0, 17, 28.12], [1, 16, 68.87], [2, 15.5, 408.24]], "batl": [[0, 17.5, 9.89], [2, 19.5, 51.7]]}, {"timestamp": 1578772394980, "ltp": 17.0, "tv": 4888.02, "trd": [[17, 149.49]], "batb": [[0, 17, 5.93]], "batl": NaN}, {"timestamp": 1578772395979, "ltp": 16.0, "tv": 4898.74, "trd": [[16, 38.27], [17, 154.09]], "batb": [[0, 16, 65.81], [1, 15.5, 408.24], [2, 15, 232.56]], "batl": [[2, 19.5, 70.04]]}, {"timestamp": 1578772396977, "ltp": 16.0, "tv": 4898.74, "trd": NaN, "batb": NaN, "batl": [[2, 19, 10.67]]}, {"timestamp": 1578772397970, "ltp": 16.0, "tv": 4898.74, "trd": NaN, "batb": [[0, 16, 95.81]], "batl": [[2, 19, 18.94]]}, {"timestamp": 1578772399006, "ltp": 17.5, "tv": 4903.52, "trd": [[17.5, 105.01]], "batb": NaN, "batl": [[0, 17.5, 7.5], [2, 19, 10.67]]}, {"timestamp": 1578772400005, "ltp": 17.5, "tv": 4903.52, "trd": NaN, "batb": [[0, 16.5, 8.79], [1, 16, 65.81], [2, 15.5, 408.24]], "batl": [[0, 17, 2.42], [1, 17.5, 7.5], [2, 18, 19.86]]}, {"timestamp": 1578772401002, "ltp": 17.5, "tv": 4903.52, "trd": NaN, "batb": [[0, 16, 88.15], [1, 15.5, 431.3], [2, 15, 232.56]], "batl": [[1, 17.5, 27.32], [2, 18, 39.72]]}, {"timestamp": 1578772402030, "ltp": 17.5, "tv": 4923.28, "trd": [[17, 158.93], [17.5, 119.93]], "batb": [[0, 16.5, 33.07], [1, 16, 88.15], [2, 15.5, 431.3]], "batl": [[0, 17.5, 19.86], [1, 18, 39.72], [2, 18.5, 59]]}, {"timestamp": 1578772403016, "ltp": 17.5, "tv": 4923.28, "trd": NaN, "batb": [[0, 16.5, 10.88]], "batl": [[0, 17.5, 8.8]]}, {"timestamp": 1578772404015, "ltp": 18.0, "tv": 5044.71, "trd": [[17.5, 137.53], [18, 136.18]], "batb": NaN, "batl": [[0, 18.5, 59], [1, 19.5, 88.37], [2, 20, 32]]}, {"timestamp": 1578772405006, "ltp": 16.0, "tv": 5068.73, "trd": [[16, 40.53], [16.5, 42.34]], "batb": [[0, 16, 87.02], [1, 15.5, 431.3], [2, 15, 232.56]], "batl": NaN}, {"timestamp": 1578772407006, "ltp": 18.0, "tv": 5069.11, "trd": [[16, 40.82], [18, 136.26]], "batb": [[0, 16, 86.88]], "batl": [[1, 19.5, 86.67]]}, {"timestamp": 1578772407989, "ltp": 16.0, "tv": 5109.05, "trd": [[16, 80.77]], "batb": [[0, 16, 66.91]], "batl": [[0, 17, 10.85], [1, 18.5, 59], [2, 19.5, 86.67]]}, {"timestamp": 1578772408980, "ltp": 16.0, "tv": 5113.98, "trd": [[16, 85.69]], "batb": [[0, 16, 64.45]], "batl": [[0, 17, 20]]}, {"timestamp": 1578772409981, "ltp": 17.0, "tv": 5114.11, "trd": [[17, 159.06]], "batb": NaN, "batl": [[0, 17, 19.93]]}, {"timestamp": 1578772410978, "ltp": 17.0, "tv": 5114.11, "trd": NaN, "batb": [[0, 16.5, 8.52], [1, 16, 64.45], [2, 15.5, 431.3]], "batl": [[1, 18, 39.72], [2, 18.5, 59]]}, {"timestamp": 1578772411983, "ltp": 17.0, "tv": 5114.11, "trd": NaN, "batb": [[0, 16, 64.45], [1, 15.5, 431.3], [2, 15, 232.56]], "batl": [[1, 18, 48.19]]}, {"timestamp": 1578772413015, "ltp": 16.0, "tv": 5134.11, "trd": [[16, 105.69]], "batb": [[0, 16, 84.45]], "batl": NaN}, {"timestamp": 1578772413968, "ltp": 16.0, "tv": 5160.23, "trd": [[16, 131.81]], "batb": [[0, 16, 71.39]], "batl": NaN}, {"timestamp": 1578772416002, "ltp": 16.0, "tv": 5165.68, "trd": [[16, 137.26]], "batb": [[0, 16, 68.66]], "batl": NaN}, {"timestamp": 1578772417002, "ltp": 16.0, "tv": 5165.68, "trd": NaN, "batb": NaN, "batl": [[1, 18, 58.55]]}, {"timestamp": 1578772418000, "ltp": 17.0, "tv": 5165.88, "trd": [[17, 159.26]], "batb": [[0, 16.5, 94.48], [1, 16, 68.66], [2, 15.5, 393.04]], "batl": [[0, 17, 22.13]]}, {"timestamp": 1578772421024, "ltp": 16.5, "tv": 5174.39, "trd": [[16.5, 50.85]], "batb": [[0, 16.5, 90.23], [1, 16, 99.66]], "batl": NaN}, {"timestamp": 1578772422022, "ltp": 16.5, "tv": 5174.39, "trd": NaN, "batb": [[0, 16.5, 98.48]], "batl": NaN}, {"timestamp": 1578772423018, "ltp": 16.5, "tv": 5174.39, "trd": NaN, "batb": [[0, 16.5, 108.56], [1, 16, 110.41], [2, 15.5, 404.53]], "batl": [[2, 18.5, 66.93]]}, {"timestamp": 1578772424004, "ltp": 17.0, "tv": 5174.53, "trd": [[17, 159.4]], "batb": NaN, "batl": [[0, 17, 22.06], [2, 18.5, 59]]}, {"timestamp": 1578772424895, "ltp": 17.0, "tv": 5174.53, "trd": NaN, "batb": [[1, 16, 140.41]], "batl": NaN}, {"timestamp": 1578772426002, "ltp": 17.0, "tv": 5218.65, "trd": [[17, 203.51]], "batb": [[0, 16.5, 151.88], [1, 16, 110.41]], "batl": [[0, 18, 58.55], [1, 18.5, 59], [2, 19, 28.2]]}, {"timestamp": 1578772428048, "ltp": 18.0, "tv": 5238.09, "trd": [[18, 155.7]], "batb": NaN, "batl": [[0, 18, 48.83]]}, {"timestamp": 1578772429042, "ltp": 18.0, "tv": 5238.11, "trd": [[18, 155.72]], "batb": [[0, 16.5, 171.13]], "batl": [[0, 18, 48.83]]}, {"timestamp": 1578772431967, "ltp": 16.5, "tv": 5241.78, "trd": [[16.5, 54.53]], "batb": [[0, 16.5, 169.29]], "batl": NaN}, {"timestamp": 1578772433026, "ltp": 16.5, "tv": 5241.78, "trd": NaN, "batb": [[0, 17, 6.87], [1, 16.5, 169.29], [2, 16, 110.41]], "batl": NaN}, {"timestamp": 1578772434026, "ltp": 17.0, "tv": 5245.52, "trd": [[17, 207.25]], "batb": [[0, 17, 5]], "batl": NaN}, {"timestamp": 1578772438051, "ltp": 17.0, "tv": 5249.51, "trd": [[17, 211.25]], "batb": [[0, 17, 3]], "batl": NaN}, {"timestamp": 1578772440043, "ltp": 16.5, "tv": 5255.55, "trd": [[16.5, 54.56], [17, 217.24]], "batb": [[0, 17.5, 8.91], [1, 17, 9.46], [2, 16.5, 169.28]], "batl": NaN}, {"timestamp": 1578772441035, "ltp": 16.5, "tv": 5255.55, "trd": NaN, "batb": NaN, "batl": [[0, 18, 994.52]]}, {"timestamp": 1578772442979, "ltp": 16.5, "tv": 5255.55, "trd": NaN, "batb": NaN, "batl": [[2, 19, 9.2]]}, {"timestamp": 1578772445037, "ltp": 17.5, "tv": 5273.37, "trd": [[17.5, 155.35]], "batb": [[0, 17, 9.46], [1, 16.5, 169.28], [2, 16, 80.41]], "batl": [[0, 17.5, 12.37], [1, 18, 994.52], [2, 18.5, 59]]}, {"timestamp": 1578772445968, "ltp": 17.5, "tv": 5273.37, "trd": NaN, "batb": [[1, 16.5, 150.03]], "batl": [[2, 18.5, 50]]}, {"timestamp": 1578772446968, "ltp": 17.5, "tv": 5275.07, "trd": [[17.5, 157.05]], "batb": [[0, 16.5, 150.03], [1, 16, 80.41], [2, 15.5, 404.53]], "batl": [[0, 17.5, 11.52]]}, {"timestamp": 1578772447990, "ltp": 17.0, "tv": 5295.07, "trd": [[17, 237.25]], "batb": [[0, 17, 32.07], [1, 16.5, 150.03], [2, 16, 80.41]], "batl": NaN}, {"timestamp": 1578772449055, "ltp": 17.0, "tv": 5295.07, "trd": NaN, "batb": [[0, 16.5, 150.03], [1, 16, 80.41], [2, 15.5, 404.53]], "batl": NaN}, {"timestamp": 1578772451969, "ltp": 17.0, "tv": 5295.07, "trd": NaN, "batb": [[2, 15.5, 435.56]], "batl": NaN}, {"timestamp": 1578772452958, "ltp": 17.0, "tv": 5295.07, "trd": NaN, "batb": [[2, 15.5, 466.59]], "batl": [[0, 17.5, 51.16]]}, {"timestamp": 1578772453944, "ltp": 17.5, "tv": 5295.14, "trd": [[17.5, 157.12]], "batb": NaN, "batl": [[0, 17.5, 51.12]]}, {"timestamp": 1578772456977, "ltp": 17.5, "tv": 5295.14, "trd": NaN, "batb": NaN, "batl": [[2, 18.5, 71]]}, {"timestamp": 1578772459942, "ltp": 17.5, "tv": 5295.14, "trd": NaN, "batb": [[1, 16, 49.41]], "batl": [[0, 17.5, 54.86]]}, {"timestamp": 1578772460976, "ltp": 17.5, "tv": 5325.14, "trd": [[17.5, 187.12]], "batb": [[0, 16.5, 150.15]], "batl": [[0, 17.5, 39.85]]}, {"timestamp": 1578772461970, "ltp": 17.5, "tv": 5325.14, "trd": NaN, "batb": [[0, 16.5, 140.07]], "batl": NaN}, {"timestamp": 1578772463950, "ltp": 16.5, "tv": 5332.79, "trd": [[16.5, 61.97], [17, 237.49]], "batb": [[0, 16.5, 136.24]], "batl": [[2, 18.5, 78.93]]}, {"timestamp": 1578772468981, "ltp": 17.5, "tv": 5412.5, "trd": [[17.5, 266.83]], "batb": [[0, 17.5, 12.07], [1, 16.5, 136.24], [2, 16, 49.41]], "batl": [[0, 18, 994.52], [1, 18.5, 78.93], [2, 19, 25.5]]}, {"timestamp": 1578772469989, "ltp": 17.5, "tv": 5412.5, "trd": NaN, "batb": [[0, 16.5, 146.32], [1, 16, 49.41], [2, 15.5, 466.59]], "batl": NaN}, {"timestamp": 1578772471002, "ltp": 17.5, "tv": 5412.5, "trd": NaN, "batb": [[0, 16.5, 136.24]], "batl": NaN}, {"timestamp": 1578772477990, "ltp": 17.5, "tv": 5412.5, "trd": NaN, "batb": NaN, "batl": [[0, 17.5, 20.43], [1, 18, 994.52], [2, 18.5, 78.93]]}, {"timestamp": 1578772481003, "ltp": 16.5, "tv": 5489.04, "trd": [[16.5, 138.51]], "batb": [[0, 16.5, 97.97]], "batl": NaN}, {"timestamp": 1578772484013, "ltp": 16.5, "tv": 5489.04, "trd": NaN, "batb": NaN, "batl": [[0, 17.5, 31.72]]}, {"timestamp": 1578772485999, "ltp": 16.5, "tv": 5489.04, "trd": NaN, "batb": NaN, "batl": [[0, 17.5, 60.73]]}, {"timestamp": 1578772487018, "ltp": 16.5, "tv": 5489.04, "trd": NaN, "batb": [[2, 15.5, 435.56]], "batl": [[0, 17.5, 49.44]]}, {"timestamp": 1578772487975, "ltp": 16.5, "tv": 5489.04, "trd": NaN, "batb": [[0, 17.5, 21.28], [1, 16.5, 97.97], [2, 16, 49.41]], "batl": [[0, 18, 994.52], [1, 18.5, 78.93], [2, 19, 25.5]]}, {"timestamp": 1578772489012, "ltp": 16.5, "tv": 5489.04, "trd": NaN, "batb": [[0, 17.5, 66.85]], "batl": NaN}, {"timestamp": 1578772490991, "ltp": 16.5, "tv": 5489.04, "trd": NaN, "batb": [[0, 17.5, 21.28]], "batl": NaN}, {"timestamp": 1578772491976, "ltp": 16.5, "tv": 5489.04, "trd": NaN, "batb": NaN, "batl": [[0, 18, 1016.52]]}, {"timestamp": 1578772493009, "ltp": 16.5, "tv": 5489.04, "trd": NaN, "batb": [[2, 16, 70.69]], "batl": NaN}, {"timestamp": 1578772494000, "ltp": 16.5, "tv": 5489.04, "trd": NaN, "batb": [[1, 17, 3.14], [2, 16.5, 97.97]], "batl": NaN}, {"timestamp": 1578772496028, "ltp": 17.5, "tv": 5492.03, "trd": [[17.5, 269.82]], "batb": [[0, 17.5, 18.29], [1, 17, 12.08]], "batl": NaN}, {"timestamp": 1578772497996, "ltp": 17.5, "tv": 5500.29, "trd": [[17.5, 278.08]], "batb": [[0, 17.5, 18.6]], "batl": NaN}, {"timestamp": 1578772499031, "ltp": 17.5, "tv": 5518.88, "trd": [[17.5, 296.67]], "batb": [[0, 17, 12.08], [1, 16.5, 97.97], [2, 16, 70.69]], "batl": NaN}, {"timestamp": 1578772499980, "ltp": 17.5, "tv": 5518.88, "trd": NaN, "batb": [[0, 17, 37.08]], "batl": NaN}, {"timestamp": 1578772501021, "ltp": 17.5, "tv": 5518.88, "trd": NaN, "batb": [[0, 17, 28.14]], "batl": [[0, 17.5, 21.28], [1, 18, 1016.52], [2, 18.5, 78.93]]}, {"timestamp": 1578772502014, "ltp": 17.5, "tv": 5518.88, "trd": NaN, "batb": [[0, 17, 49.42]], "batl": NaN}, {"timestamp": 1578772502995, "ltp": 17.5, "tv": 5518.88, "trd": NaN, "batb": [[0, 17, 65.42]], "batl": NaN}, {"timestamp": 1578772503990, "ltp": 17.5, "tv": 5518.88, "trd": NaN, "batb": NaN, "batl": [[0, 18, 1002.92], [1, 18.5, 57.93], [2, 19, 7.5]]}, {"timestamp": 1578772504986, "ltp": 17.0, "tv": 5569.0, "trd": [[17, 287.61]], "batb": [[0, 17, 40.36], [2, 16, 49.41]], "batl": [[0, 18, 994.52]]}, {"timestamp": 1578772508908, "ltp": 17.0, "tv": 5569.0, "trd": NaN, "batb": NaN, "batl": [[0, 17.5, 10.73], [1, 18, 994.52], [2, 18.5, 57.93]]}, {"timestamp": 1578772509998, "ltp": 17.0, "tv": 5570.5, "trd": [[17, 289.11]], "batb": [[0, 17, 39.61]], "batl": NaN}, {"timestamp": 1578772511050, "ltp": 17.5, "tv": 5591.95, "trd": [[17.5, 318.12]], "batb": [[0, 17.5, 10.55], [1, 17, 39.61], [2, 16.5, 97.97]], "batl": [[0, 18, 994.52], [1, 18.5, 57.93], [2, 19, 7.5]]}, {"timestamp": 1578772512036, "ltp": 17.5, "tv": 5591.95, "trd": NaN, "batb": NaN, "batl": [[2, 19, 113.56]]}, {"timestamp": 1578772513037, "ltp": 17.5, "tv": 5608.33, "trd": [[17.5, 334.5]], "batb": [[0, 17.5, 2.37]], "batl": NaN}, {"timestamp": 1578772516044, "ltp": 17.5, "tv": 5608.33, "trd": NaN, "batb": NaN, "batl": [[2, 19, 219.62]]}, {"timestamp": 1578772519021, "ltp": 17.5, "tv": 5613.06, "trd": [[17.5, 339.23]], "batb": [[0, 17, 39.61], [1, 16.5, 97.97], [2, 16, 49.41]], "batl": [[0, 17.5, 8.92], [1, 18, 994.52], [2, 18.5, 57.93]]}, {"timestamp": 1578772521033, "ltp": 17.5, "tv": 5614.0, "trd": [[17.5, 340.17]], "batb": NaN, "batl": [[0, 17.5, 8.45]]}, {"timestamp": 1578772522024, "ltp": 17.5, "tv": 5622.45, "trd": [[17.5, 348.62]], "batb": NaN, "batl": [[0, 18, 994.52], [1, 18.5, 57.93], [2, 19, 219.62]]}, {"timestamp": 1578772525043, "ltp": 17.0, "tv": 5676.45, "trd": [[17, 343.11]], "batb": [[0, 17, 12.61]], "batl": [[0, 17.5, 25], [1, 18, 1016.52], [2, 18.5, 79.93]]}, {"timestamp": 1578772527019, "ltp": 17.0, "tv": 5676.45, "trd": NaN, "batb": [[2, 16, 52.47]], "batl": NaN}, {"timestamp": 1578772527957, "ltp": 17.0, "tv": 5676.45, "trd": NaN, "batb": [[0, 17, 62.61], [2, 16, 41.72]], "batl": NaN}, {"timestamp": 1578772529050, "ltp": 17.5, "tv": 5719.01, "trd": [[17.5, 391.18]], "batb": NaN, "batl": [[0, 17.5, 3.72]]}, {"timestamp": 1578772531021, "ltp": 17.5, "tv": 5719.07, "trd": [[17.5, 391.24]], "batb": [[0, 16.5, 97.97], [1, 16, 41.72], [2, 15.5, 76.9]], "batl": [[0, 17.5, 3.69], [1, 18, 1024.92]]}, {"timestamp": 1578772531960, "ltp": 17.5, "tv": 5719.07, "trd": NaN, "batb": NaN, "batl": [[0, 17.5, 32.34], [2, 18.5, 187.5]]}, {"timestamp": 1578772533055, "ltp": 17.5, "tv": 5719.07, "trd": NaN, "batb": NaN, "batl": [[0, 17.5, 42.95]]}, {"timestamp": 1578772535036, "ltp": 17.5, "tv": 5719.07, "trd": NaN, "batb": NaN, "batl": [[0, 17.5, 51.86]]}, {"timestamp": 1578772537967, "ltp": 16.5, "tv": 5827.58, "trd": [[16.5, 138.98], [17.5, 499.28]], "batb": [[0, 16.5, 97.74]], "batl": [[0, 17.5, 20.43]]}, {"timestamp": 1578772539950, "ltp": 17.0, "tv": 5827.74, "trd": [[17, 343.27]], "batb": NaN, "batl": [[0, 17, 22.92], [1, 17.5, 20.43], [2, 18, 1024.92]]}, {"timestamp": 1578772541044, "ltp": 17.0, "tv": 5827.74, "trd": NaN, "batb": [[0, 16.5, 46.16]], "batl": [[2, 18, 1006.08]]}, {"timestamp": 1578772544979, "ltp": 17.0, "tv": 5827.74, "trd": NaN, "batb": [[1, 16, 52.47]], "batl": [[1, 17.5, 76.46]]}, {"timestamp": 1578772545970, "ltp": 17.0, "tv": 5827.74, "trd": NaN, "batb": NaN, "batl": [[1, 17.5, 85.04]]}, {"timestamp": 1578772547985, "ltp": 17.0, "tv": 5827.74, "trd": NaN, "batb": NaN, "batl": [[0, 17, 42.65]]}, {"timestamp": 1578772548972, "ltp": 17.5, "tv": 5917.97, "trd": [[17, 411.04], [17.5, 521.73]], "batb": [[0, 16.5, 76.44]], "batl": [[0, 17.5, 73.82], [1, 18, 1006.08], [2, 18.5, 187.5]]}, {"timestamp": 1578772549974, "ltp": 17.5, "tv": 5917.97, "trd": NaN, "batb": [[0, 17, 18.52], [1, 16.5, 76.44], [2, 16, 52.47]], "batl": NaN}, {"timestamp": 1578772551989, "ltp": 17.5, "tv": 5917.97, "trd": NaN, "batb": NaN, "batl": [[2, 18.5, 79.93]]}, {"timestamp": 1578772553955, "ltp": 17.0, "tv": 5955.01, "trd": [[17, 448.08]], "batb": [[0, 16.5, 76.44], [1, 16, 52.47], [2, 15.5, 76.9]], "batl": [[0, 17, 8.48], [1, 17.5, 73.82], [2, 18, 1006.08]]}, {"timestamp": 1578772556989, "ltp": 17.0, "tv": 5955.01, "trd": NaN, "batb": [[0, 16.5, 98.1]], "batl": NaN}, {"timestamp": 1578772559002, "ltp": 17.0, "tv": 5955.01, "trd": NaN, "batb": NaN, "batl": [[2, 18, 1115.22]]}, {"timestamp": 1578772564003, "ltp": 17.0, "tv": 5955.01, "trd": NaN, "batb": [[0, 16.5, 108.18]], "batl": NaN}, {"timestamp": 1578772564986, "ltp": 17.5, "tv": 6040.13, "trd": [[17, 465.04], [17.5, 589.9]], "batb": NaN, "batl": [[0, 17.5, 39.73], [1, 18, 1115.22], [2, 18.5, 79.93]]}, {"timestamp": 1578772566024, "ltp": 16.5, "tv": 6044.84, "trd": [[16.5, 143.7]], "batb": [[0, 16.5, 105.82]], "batl": NaN}, {"timestamp": 1578772570027, "ltp": 16.5, "tv": 6044.84, "trd": NaN, "batb": [[0, 16.5, 95.74]], "batl": NaN}, {"timestamp": 1578772571010, "ltp": 16.5, "tv": 6044.84, "trd": NaN, "batb": [[0, 16.5, 52.42]], "batl": NaN}, {"timestamp": 1578772573030, "ltp": 16.5, "tv": 6044.84, "trd": NaN, "batb": NaN, "batl": [[0, 17.5, 80.59]]}, {"timestamp": 1578772577014, "ltp": 16.5, "tv": 6044.84, "trd": NaN, "batb": NaN, "batl": [[0, 17.5, 89.5]]}, {"timestamp": 1578772577992, "ltp": 16.5, "tv": 6060.34, "trd": [[16.5, 159.2]], "batb": [[0, 16.5, 47.73]], "batl": NaN}, {"timestamp": 1578772580004, "ltp": 16.5, "tv": 6060.34, "trd": NaN, "batb": NaN, "batl": [[0, 17, 27], [1, 17.5, 89.5], [2, 18, 1115.22]]}, {"timestamp": 1578772580984, "ltp": 16.5, "tv": 6060.34, "trd": NaN, "batb": [[0, 16.5, 39.12]], "batl": NaN}, {"timestamp": 1578772592053, "ltp": 17.5, "tv": 6145.46, "trd": [[17, 519.04], [17.5, 621.02]], "batb": NaN, "batl": [[0, 17.5, 73.94], [1, 18, 1115.22], [2, 18.5, 187.5]]}, {"timestamp": 1578772598007, "ltp": 17.5, "tv": 6145.46, "trd": NaN, "batb": NaN, "batl": [[0, 17, 11.19], [1, 17.5, 73.94], [2, 18, 1115.22]]}, {"timestamp": 1578772599042, "ltp": 17.5, "tv": 6145.46, "trd": NaN, "batb": NaN, "batl": [[0, 17, 19.69]]}, {"timestamp": 1578772600028, "ltp": 17.5, "tv": 6145.46, "trd": NaN, "batb": [[0, 16.5, 36.06]], "batl": NaN}, {"timestamp": 1578772604041, "ltp": 16.5, "tv": 6150.06, "trd": [[16.5, 163.79]], "batb": [[0, 16.5, 33.76]], "batl": NaN}, {"timestamp": 1578772605967, "ltp": 16.5, "tv": 6150.06, "trd": NaN, "batb": NaN, "batl": [[0, 17, 47.69]]}, {"timestamp": 1578772609036, "ltp": 16.5, "tv": 6150.06, "trd": NaN, "batb": NaN, "batl": [[0, 17, 19.69], [1, 17.5, 58.35], [2, 18, 1093.22]]}, {"timestamp": 1578772609957, "ltp": 16.5, "tv": 6150.06, "trd": NaN, "batb": NaN, "batl": [[0, 17.5, 58.35], [1, 18, 1093.22], [2, 18.5, 57.93]]}, {"timestamp": 1578772611053, "ltp": 16.5, "tv": 6246.39, "trd": [[16.5, 175.01], [17.5, 706.14]], "batb": [[0, 16.5, 28.15]], "batl": [[0, 17.5, 15.79]]}, {"timestamp": 1578772611983, "ltp": 16.5, "tv": 6246.39, "trd": NaN, "batb": [[1, 16, 22.35]], "batl": [[1, 18, 1202.36]]}, {"timestamp": 1578772618052, "ltp": 16.5, "tv": 6246.39, "trd": NaN, "batb": NaN, "batl": [[0, 17.5, 55.88]]}, {"timestamp": 1578772621007, "ltp": 16.5, "tv": 6246.39, "trd": NaN, "batb": [[1, 16, 25.41]], "batl": NaN}, {"timestamp": 1578772622982, "ltp": 16.5, "tv": 6246.39, "trd": NaN, "batb": NaN, "batl": [[0, 17.5, 80.88], [1, 18, 1224.36], [2, 18.5, 77.93]]}, {"timestamp": 1578772623990, "ltp": 17.5, "tv": 6252.3, "trd": [[17.5, 712.05]], "batb": [[0, 16.5, 36.67]], "batl": [[0, 17.5, 77.93], [1, 18, 1115.22]]}, {"timestamp": 1578772624980, "ltp": 17.5, "tv": 6252.3, "trd": NaN, "batb": [[0, 16.5, 28.15]], "batl": [[1, 18, 1006.08]]}, {"timestamp": 1578772625973, "ltp": 17.5, "tv": 6252.3, "trd": NaN, "batb": NaN, "batl": [[0, 17, 28], [1, 17.5, 77.93], [2, 18, 1006.08]]}, {"timestamp": 1578772630966, "ltp": 17.5, "tv": 6252.3, "trd": NaN, "batb": NaN, "batl": [[0, 17, 47.17]]}, {"timestamp": 1578772632015, "ltp": 17.5, "tv": 6252.3, "trd": NaN, "batb": NaN, "batl": [[2, 18, 1115.22]]}, {"timestamp": 1578772633004, "ltp": 16.5, "tv": 6269.14, "trd": [[16.5, 191.84]], "batb": [[0, 16.5, 19.73]], "batl": NaN}, {"timestamp": 1578772636004, "ltp": 17.0, "tv": 6344.05, "trd": [[17, 593.95]], "batb": NaN, "batl": [[0, 17, 9.71]]}, {"timestamp": 1578772638985, "ltp": 17.0, "tv": 6363.48, "trd": [[17, 613.37]], "batb": [[0, 17, 15.82], [1, 16.5, 19.73], [2, 16, 25.41]], "batl": [[0, 17.5, 188.71], [1, 18, 1115.22], [2, 18.5, 77.93]]}, {"timestamp": 1578772639970, "ltp": 17.0, "tv": 6363.48, "trd": NaN, "batb": [[0, 16.5, 19.73], [1, 16, 25.41], [2, 15.5, 76.9]], "batl": NaN}, {"timestamp": 1578772641007, "ltp": 17.0, "tv": 6363.48, "trd": NaN, "batb": NaN, "batl": [[1, 18, 1105.09]]}, {"timestamp": 1578772642000, "ltp": 16.5, "tv": 6365.81, "trd": [[16.5, 194.18]], "batb": [[0, 16.5, 18.56]], "batl": NaN}, {"timestamp": 1578772643989, "ltp": 16.5, "tv": 6370.56, "trd": [[16.5, 198.93]], "batb": [[0, 16.5, 16.19]], "batl": NaN}, {"timestamp": 1578772645023, "ltp": 16.5, "tv": 6370.56, "trd": NaN, "batb": [[2, 15.5, 30.76]], "batl": NaN}, {"timestamp": 1578772646010, "ltp": 16.5, "tv": 6370.56, "trd": NaN, "batb": NaN, "batl": [[0, 17, 8.22], [1, 17.5, 188.71], [2, 18, 1105.09]]}, {"timestamp": 1578772646995, "ltp": 16.5, "tv": 6370.56, "trd": NaN, "batb": [[1, 16, 47.75]], "batl": [[0, 17, 18.51]]}, {"timestamp": 1578772647979, "ltp": 16.5, "tv": 6370.56, "trd": NaN, "batb": [[1, 16, 25.41]], "batl": [[0, 17, 39.54]]}, {"timestamp": 1578772654003, "ltp": 16.5, "tv": 6387.58, "trd": [[16.5, 215.95]], "batb": [[0, 16.5, 7.68], [1, 16, 14.66]], "batl": NaN}, {"timestamp": 1578772655001, "ltp": 16.5, "tv": 6387.58, "trd": NaN, "batb": [[0, 16.5, 20.45]], "batl": NaN}, {"timestamp": 1578772657034, "ltp": 17.0, "tv": 6387.65, "trd": [[17, 613.44]], "batb": NaN, "batl": [[0, 17, 39.5]]}, {"timestamp": 1578772658023, "ltp": 16.5, "tv": 6388.02, "trd": [[16.5, 216.32]], "batb": [[0, 16.5, 20.26]], "batl": [[0, 17, 8.19]]}, {"timestamp": 1578772659007, "ltp": 17.5, "tv": 6388.3, "trd": [[17.5, 712.33]], "batb": NaN, "batl": [[0, 17.5, 188.57], [1, 18, 1105.09], [2, 18.5, 77.93]]}, {"timestamp": 1578772662017, "ltp": 16.5, "tv": 6388.59, "trd": [[16.5, 216.61]], "batb": [[0, 16.5, 20.11]], "batl": NaN}, {"timestamp": 1578772672056, "ltp": 16.5, "tv": 6428.32, "trd": [[16.5, 256.35]], "batb": [[0, 16, 6.37], [1, 15.5, 30.76], [2, 15, 127.41]], "batl": NaN}, {"timestamp": 1578772673046, "ltp": 16.5, "tv": 6428.32, "trd": NaN, "batb": NaN, "batl": [[0, 17, 42.56], [1, 17.5, 188.57], [2, 18, 1105.09]]}, {"timestamp": 1578772675953, "ltp": 16.5, "tv": 6428.32, "trd": NaN, "batb": NaN, "batl": [[0, 17, 51.6]]}, {"timestamp": 1578772679028, "ltp": 16.5, "tv": 6428.32, "trd": NaN, "batb": NaN, "batl": [[0, 17, 83.15]]}, {"timestamp": 1578772682052, "ltp": 17.0, "tv": 6445.84, "trd": [[16.5, 261.58], [17, 625.73]], "batb": [[0, 16, 6.12]], "batl": [[0, 17, 77], [1, 17.5, 179.63]]}, {"timestamp": 1578772683042, "ltp": 17.0, "tv": 6445.84, "trd": NaN, "batb": NaN, "batl": [[1, 17.5, 168.91], [2, 18, 1085.23]]}, {"timestamp": 1578772685048, "ltp": 17.0, "tv": 6530.96, "trd": [[17, 710.85]], "batb": NaN, "batl": [[0, 17, 34.44]]}, {"timestamp": 1578772686033, "ltp": 17.0, "tv": 6530.96, "trd": NaN, "batb": [[0, 16, 16.87]], "batl": NaN}, {"timestamp": 1578772687020, "ltp": 17.0, "tv": 6530.96, "trd": NaN, "batb": [[0, 16, 6.12]], "batl": NaN}, {"timestamp": 1578772689043, "ltp": 16.5, "tv": 6534.61, "trd": [[16.5, 265.22]], "batb": NaN, "batl": [[0, 16.5, 7.07], [1, 17, 34.44], [2, 17.5, 168.91]]}, {"timestamp": 1578772690031, "ltp": 16.5, "tv": 6534.61, "trd": NaN, "batb": NaN, "batl": [[0, 16.5, 10.31], [1, 17, 55.47]]}, {"timestamp": 1578772692043, "ltp": 16.5, "tv": 6534.61, "trd": NaN, "batb": NaN, "batl": [[0, 17, 55.47], [1, 17.5, 168.91], [2, 18, 1085.23]]}, {"timestamp": 1578772700968, "ltp": 16.0, "tv": 6535.28, "trd": [[16, 137.93]], "batb": [[0, 16, 5.79]], "batl": NaN}, {"timestamp": 1578772701957, "ltp": 16.0, "tv": 6535.28, "trd": NaN, "batb": [[1, 15.5, 21.84]], "batl": NaN}, {"timestamp": 1578772703974, "ltp": 16.0, "tv": 6535.28, "trd": NaN, "batb": [[2, 15, 90.41]], "batl": NaN}, {"timestamp": 1578772707982, "ltp": 16.0, "tv": 6545.93, "trd": [[16, 148.58]], "batb": [[0, 15.5, 22.3], [1, 15, 90.41], [2, 14.5, 123.72]], "batl": NaN}, {"timestamp": 1578772710029, "ltp": 16.0, "tv": 6545.93, "trd": NaN, "batb": NaN, "batl": [[1, 17.5, 143.91], [2, 18, 1063.23]]}, {"timestamp": 1578772710966, "ltp": 16.0, "tv": 6545.93, "trd": NaN, "batb": NaN, "batl": [[0, 17, 64.93]]}, {"timestamp": 1578772712014, "ltp": 16.0, "tv": 6545.93, "trd": NaN, "batb": NaN, "batl": [[0, 17, 22.87], [1, 17.5, 33.13]]}, {"timestamp": 1578772718985, "ltp": 16.0, "tv": 6546.85, "trd": [[16, 149.5]], "batb": [[0, 15.5, 21.84]], "batl": [[0, 16, 4.73], [1, 17, 22.87], [2, 17.5, 33.13]]}, {"timestamp": 1578772720049, "ltp": 16.0, "tv": 6546.85, "trd": NaN, "batb": NaN, "batl": [[1, 17, 48.87]]}, {"timestamp": 1578772720992, "ltp": 16.0, "tv": 6546.85, "trd": NaN, "batb": NaN, "batl": [[2, 17.5, 58.13]]}, {"timestamp": 1578772726992, "ltp": 16.0, "tv": 6546.85, "trd": NaN, "batb": NaN, "batl": [[0, 16, 15.51], [1, 17, 22.87]]}, {"timestamp": 1578772728034, "ltp": 16.0, "tv": 6546.85, "trd": NaN, "batb": NaN, "batl": [[1, 16.5, 8.52], [2, 17, 22.87]]}, {"timestamp": 1578772729027, "ltp": 15.5, "tv": 6552.45, "trd": [[15.5, 22.35]], "batb": [[0, 15.5, 19.04]], "batl": [[1, 17, 22.87], [2, 17.5, 58.13]]}, {"timestamp": 1578772732012, "ltp": 15.5, "tv": 6567.76, "trd": [[15.5, 37.65]], "batb": [[0, 15.5, 11.39]], "batl": NaN}, {"timestamp": 1578772732998, "ltp": 15.5, "tv": 6567.76, "trd": NaN, "batb": [[0, 15, 90.41], [1, 14.5, 123.72], [2, 14, 203.28]], "batl": NaN}, {"timestamp": 1578772734043, "ltp": 15.5, "tv": 6567.76, "trd": NaN, "batb": [[0, 15, 131.41]], "batl": NaN}, {"timestamp": 1578772735037, "ltp": 15.5, "tv": 6567.76, "trd": NaN, "batb": NaN, "batl": [[0, 15.5, 1.87], [1, 16, 15.51], [2, 17, 22.87]]}, {"timestamp": 1578772741036, "ltp": 16.0, "tv": 6572.35, "trd": [[15.5, 41.39], [16, 150.36]], "batb": NaN, "batl": [[0, 16, 15.08], [1, 17, 22.87], [2, 17.5, 58.13]]}, {"timestamp": 1578772742028, "ltp": 16.0, "tv": 6572.47, "trd": [[16, 150.48]], "batb": NaN, "batl": [[0, 16, 15.02]]}, {"timestamp": 1578772746006, "ltp": 16.0, "tv": 6572.47, "trd": NaN, "batb": NaN, "batl": [[0, 16, 119.78]]}, {"timestamp": 1578772747044, "ltp": 16.0, "tv": 6577.2, "trd": [[16, 155.21]], "batb": NaN, "batl": [[0, 16, 117.42]]}, {"timestamp": 1578772749029, "ltp": 16.0, "tv": 6577.2, "trd": NaN, "batb": NaN, "batl": [[2, 17.5, 54.34]]}, {"timestamp": 1578772750021, "ltp": 15.0, "tv": 6577.53, "trd": [[15, 0.32]], "batb": [[0, 15, 131.25]], "batl": NaN}, {"timestamp": 1578772754033, "ltp": 15.0, "tv": 6577.53, "trd": NaN, "batb": NaN, "batl": [[0, 16, 148.2], [1, 17, 43.9]]}, {"timestamp": 1578772754919, "ltp": 15.0, "tv": 6580.93, "trd": [[15, 3.73]], "batb": [[0, 15, 129.54]], "batl": NaN}, {"timestamp": 1578772756022, "ltp": 15.0, "tv": 6580.93, "trd": NaN, "batb": NaN, "batl": [[0, 16, 170.55]]}, {"timestamp": 1578772761027, "ltp": 16.0, "tv": 6581.07, "trd": [[16, 155.35]], "batb": NaN, "batl": [[0, 16, 170.48]]}, {"timestamp": 1578772764959, "ltp": 15.0, "tv": 6641.07, "trd": [[15, 63.73]], "batb": [[0, 15, 99.54]], "batl": NaN}, {"timestamp": 1578772766979, "ltp": 15.0, "tv": 6641.07, "trd": NaN, "batb": NaN, "batl": [[0, 15.5, 945.69], [1, 16, 170.48], [2, 17, 43.9]]}, {"timestamp": 1578772767961, "ltp": 15.0, "tv": 6641.07, "trd": NaN, "batb": [[0, 15, 90.69]], "batl": [[2, 17, 30.49]]}, {"timestamp": 1578772769051, "ltp": 15.0, "tv": 6641.07, "trd": NaN, "batb": [[0, 15, 23.53]], "batl": [[2, 17, 9.46]]}, {"timestamp": 1578772770972, "ltp": 15.0, "tv": 6641.07, "trd": NaN, "batb": [[0, 15, 11.22]], "batl": NaN}, {"timestamp": 1578772771956, "ltp": 15.5, "tv": 6644.82, "trd": [[15.5, 45.13]], "batb": NaN, "batl": [[0, 15.5, 943.82]]}, {"timestamp": 1578772772940, "ltp": 15.5, "tv": 6644.82, "trd": NaN, "batb": NaN, "batl": [[1, 16, 65.72]]}, {"timestamp": 1578772774042, "ltp": 15.5, "tv": 6644.82, "trd": NaN, "batb": [[2, 14, 134.06]], "batl": NaN}, {"timestamp": 1578772775033, "ltp": 15.5, "tv": 6644.82, "trd": NaN, "batb": NaN, "batl": [[0, 15.5, 985.83]]}, {"timestamp": 1578772775969, "ltp": 15.5, "tv": 6644.82, "trd": NaN, "batb": NaN, "batl": [[0, 15.5, 1008.9], [2, 17, 36.46]]}, {"timestamp": 1578772776956, "ltp": 15.5, "tv": 6644.82, "trd": NaN, "batb": [[0, 15, 11.36]], "batl": NaN}, {"timestamp": 1578772782975, "ltp": 15.0, "tv": 6667.53, "trd": [[15, 86.45]], "batb": [[0, 14.5, 123.72], [1, 14, 134.06], [2, 13.5, 269.1]], "batl": [[0, 15, 73.77], [1, 15.5, 1008.9], [2, 16, 65.72]]}, {"timestamp": 1578772783960, "ltp": 15.0, "tv": 6688.77, "trd": [[15, 107.69]], "batb": NaN, "batl": [[0, 15, 63.14]]}, {"timestamp": 1578772785988, "ltp": 15.0, "tv": 6688.77, "trd": NaN, "batb": [[1, 14, 203.28]], "batl": NaN}, {"timestamp": 1578772786967, "ltp": 15.0, "tv": 6713.39, "trd": [[15, 132.31]], "batb": NaN, "batl": [[0, 15, 50.83]]}, {"timestamp": 1578772788007, "ltp": 15.0, "tv": 6713.39, "trd": NaN, "batb": NaN, "batl": [[0, 15, 69.52]]}, {"timestamp": 1578772788995, "ltp": 15.0, "tv": 6713.39, "trd": NaN, "batb": [[0, 14.5, 168.88]], "batl": NaN}, {"timestamp": 1578772789987, "ltp": 15.0, "tv": 6713.39, "trd": NaN, "batb": [[0, 14.5, 160.57]], "batl": [[2, 16, 24.15]]}, {"timestamp": 1578772792022, "ltp": 15.0, "tv": 6713.85, "trd": [[15, 132.76]], "batb": NaN, "batl": [[0, 15, 69.29]]}, {"timestamp": 1578772795020, "ltp": 15.0, "tv": 6713.85, "trd": NaN, "batb": NaN, "batl": [[0, 15, 50.6]]}, {"timestamp": 1578772797008, "ltp": 15.0, "tv": 6713.85, "trd": NaN, "batb": NaN, "batl": [[0, 15, 93.45]]}, {"timestamp": 1578772797990, "ltp": 15.0, "tv": 6841.53, "trd": [[15, 260.44]], "batb": NaN, "batl": [[0, 15, 29.61]]}, {"timestamp": 1578772799026, "ltp": 15.0, "tv": 6841.53, "trd": NaN, "batb": NaN, "batl": [[0, 15.5, 1008.9], [1, 16, 24.15], [2, 17, 36.46]]}, {"timestamp": 1578772799906, "ltp": 14.5, "tv": 6843.18, "trd": [[14.5, 1.66]], "batb": [[0, 14.5, 159.74]], "batl": NaN}, {"timestamp": 1578772803018, "ltp": 14.5, "tv": 6843.18, "trd": NaN, "batb": [[2, 13.5, 126.09]], "batl": [[0, 15, 1.87], [1, 15.5, 1008.9], [2, 16, 24.15]]}, {"timestamp": 1578772807994, "ltp": 14.5, "tv": 6863.18, "trd": [[14.5, 21.66]], "batb": [[0, 14.5, 118.57]], "batl": NaN}, {"timestamp": 1578772810021, "ltp": 15.0, "tv": 6863.29, "trd": [[15, 260.55]], "batb": NaN, "batl": [[0, 15, 1.82]]}, {"timestamp": 1578772811015, "ltp": 15.0, "tv": 6863.29, "trd": NaN, "batb": NaN, "batl": [[0, 15.5, 1008.9], [1, 16, 24.15], [2, 16.5, 29]]}, {"timestamp": 1578772813024, "ltp": 15.0, "tv": 6863.29, "trd": NaN, "batb": [[1, 14, 271.38]], "batl": NaN}, {"timestamp": 1578772813906, "ltp": 14.5, "tv": 6863.97, "trd": [[14.5, 22.34]], "batb": [[0, 14.5, 118.23], [2, 13.5, 269.1]], "batl": NaN}, {"timestamp": 1578772816037, "ltp": 14.5, "tv": 6863.97, "trd": NaN, "batb": [[0, 15, 4.26], [1, 14.5, 118.23], [2, 14, 271.38]], "batl": NaN}, {"timestamp": 1578772819047, "ltp": 15.5, "tv": 6864.32, "trd": [[15.5, 45.48]], "batb": NaN, "batl": [[0, 15.5, 1008.72]]}, {"timestamp": 1578772822056, "ltp": 15.5, "tv": 6864.32, "trd": NaN, "batb": NaN, "batl": [[2, 16.5, 39.08]]}, {"timestamp": 1578772824037, "ltp": 15.5, "tv": 6864.32, "trd": NaN, "batb": [[1, 14.5, 127.27]], "batl": NaN}, {"timestamp": 1578772827020, "ltp": 15.5, "tv": 6864.32, "trd": NaN, "batb": NaN, "batl": [[1, 16, 34.9]]}, {"timestamp": 1578772834052, "ltp": 15.5, "tv": 6864.42, "trd": [[15.5, 45.58]], "batb": NaN, "batl": [[0, 15.5, 1008.67]]}, {"timestamp": 1578772835030, "ltp": 15.5, "tv": 6864.42, "trd": NaN, "batb": [[1, 14.5, 114.05]], "batl": [[1, 16, 24.15], [2, 16.5, 29]]}, {"timestamp": 1578772835964, "ltp": 15.0, "tv": 6872.76, "trd": [[15, 268.89]], "batb": [[0, 14.5, 114.14], [1, 14, 271.38], [2, 13.5, 126.09]], "batl": NaN}, {"timestamp": 1578772836959, "ltp": 15.5, "tv": 6912.93, "trd": [[15, 285.15], [15.5, 69.48]], "batb": [[0, 14.5, 114.05]], "batl": [[0, 15.5, 996.71]]}, {"timestamp": 1578772838047, "ltp": 15.5, "tv": 6912.93, "trd": NaN, "batb": [[0, 14.5, 105.01]], "batl": NaN}, {"timestamp": 1578772842055, "ltp": 15.5, "tv": 6912.93, "trd": NaN, "batb": [[2, 13.5, 141.47]], "batl": NaN}, {"timestamp": 1578772842952, "ltp": 15.5, "tv": 6912.93, "trd": NaN, "batb": NaN, "batl": [[1, 16, 56.15]]}, {"timestamp": 1578772844986, "ltp": 15.5, "tv": 6912.93, "trd": NaN, "batb": NaN, "batl": [[0, 15, 43.07], [1, 15.5, 996.71], [2, 16, 56.15]]}, {"timestamp": 1578772845978, "ltp": 15.0, "tv": 6956.57, "trd": [[14.5, 25.98], [15, 325.15]], "batb": [[0, 14.5, 103.18], [1, 14, 236.77]], "batl": [[0, 15, 23.08]]}, {"timestamp": 1578772849970, "ltp": 14.5, "tv": 6962.69, "trd": [[14.5, 32.1]], "batb": [[0, 14.5, 100.12]], "batl": [[0, 15, 130.5]]}, {"timestamp": 1578772853962, "ltp": 14.5, "tv": 6962.69, "trd": NaN, "batb": [[2, 13.5, 177.47]], "batl": [[0, 15, 141.21]]}, {"timestamp": 1578772855006, "ltp": 14.5, "tv": 6962.69, "trd": NaN, "batb": [[1, 14, 187.77]], "batl": NaN}, {"timestamp": 1578772855984, "ltp": 15.0, "tv": 7047.81, "trd": [[15, 410.27]], "batb": NaN, "batl": [[0, 15, 98.65]]}, {"timestamp": 1578772856972, "ltp": 15.0, "tv": 7132.93, "trd": [[15, 495.39]], "batb": NaN, "batl": [[0, 15, 56.09]]}, {"timestamp": 1578772861015, "ltp": 15.0, "tv": 7221.8, "trd": [[14.5, 35.85], [15, 580.51]], "batb": [[0, 14.5, 98.25]], "batl": [[0, 15, 13.53]]}, {"timestamp": 1578772862982, "ltp": 15.0, "tv": 7221.8, "trd": NaN, "batb": NaN, "batl": [[0, 15, 45.94]]}, {"timestamp": 1578772871031, "ltp": 15.0, "tv": 7231.79, "trd": [[15, 590.51]], "batb": NaN, "batl": [[0, 15, 40.94]]}, {"timestamp": 1578772872019, "ltp": 15.0, "tv": 7231.79, "trd": NaN, "batb": NaN, "batl": [[0, 15, 94.13]]}, {"timestamp": 1578772873993, "ltp": 15.0, "tv": 7231.79, "trd": NaN, "batb": NaN, "batl": [[2, 16, 33.81]]}, {"timestamp": 1578772875025, "ltp": 14.5, "tv": 7240.3, "trd": [[14.5, 44.36]], "batb": [[0, 14.5, 93.99], [1, 14, 153.16]], "batl": NaN}, {"timestamp": 1578772879036, "ltp": 14.5, "tv": 7240.3, "trd": NaN, "batb": [[1, 14, 153.91]], "batl": NaN}, {"timestamp": 1578772880013, "ltp": 14.5, "tv": 7240.3, "trd": NaN, "batb": NaN, "batl": [[0, 15, 117.96], [1, 15.5, 1032.71]]}, {"timestamp": 1578772886032, "ltp": 14.5, "tv": 7240.3, "trd": NaN, "batb": [[2, 13.5, 141.47]], "batl": NaN}, {"timestamp": 1578772888004, "ltp": 14.5, "tv": 7240.3, "trd": NaN, "batb": NaN, "batl": [[2, 16, 44.56]]}, {"timestamp": 1578772894020, "ltp": 14.5, "tv": 7240.3, "trd": NaN, "batb": NaN, "batl": [[1, 15.5, 1044.2]]}, {"timestamp": 1578772899961, "ltp": 14.5, "tv": 7251.01, "trd": [[14.5, 55.07]], "batb": [[0, 14.5, 88.64]], "batl": NaN}, {"timestamp": 1578772914044, "ltp": 14.5, "tv": 7339.95, "trd": [[14.5, 62.54], [15, 671.97]], "batb": [[0, 14.5, 84.9]], "batl": [[0, 15, 77.23]]}, {"timestamp": 1578772919975, "ltp": 15.0, "tv": 7340.05, "trd": [[15, 672.07]], "batb": NaN, "batl": [[0, 15, 77.18]]}, {"timestamp": 1578772921967, "ltp": 15.0, "tv": 7340.05, "trd": NaN, "batb": [[2, 13.5, 126.09]], "batl": [[0, 15, 111.84]]}, {"timestamp": 1578772928997, "ltp": 15.0, "tv": 7340.05, "trd": NaN, "batb": [[2, 13.5, 73.09]], "batl": NaN}, {"timestamp": 1578772930999, "ltp": 15.0, "tv": 7342.69, "trd": [[15, 674.7]], "batb": NaN, "batl": [[0, 15, 110.53]]}, {"timestamp": 1578772938980, "ltp": 15.0, "tv": 7342.69, "trd": NaN, "batb": NaN, "batl": [[0, 15, 119], [1, 15.5, 1008.2], [2, 16, 12.56]]}, {"timestamp": 1578772939966, "ltp": 15.0, "tv": 7359.71, "trd": [[15, 691.73]], "batb": NaN, "batl": [[0, 15, 110.49]]}, {"timestamp": 1578772943978, "ltp": 15.0, "tv": 7359.71, "trd": NaN, "batb": NaN, "batl": [[1, 15.5, 996.71]]}, {"timestamp": 1578772950930, "ltp": 15.0, "tv": 7418.95, "trd": [[15, 750.97]], "batb": NaN, "batl": [[0, 15, 80.87]]}, {"timestamp": 1578772952965, "ltp": 15.0, "tv": 7419.03, "trd": [[15, 751.05]], "batb": NaN, "batl": [[0, 15, 80.83]]}, {"timestamp": 1578772955055, "ltp": 14.5, "tv": 7419.36, "trd": [[14.5, 62.87]], "batb": [[0, 14.5, 84.74]], "batl": NaN}, {"timestamp": 1578772957044, "ltp": 14.5, "tv": 7420.75, "trd": [[14.5, 64.27]], "batb": [[0, 14.5, 84.04]], "batl": NaN}, {"timestamp": 1578772963039, "ltp": 15.0, "tv": 7420.81, "trd": [[15, 751.1]], "batb": NaN, "batl": [[0, 15, 80.81]]}, {"timestamp": 1578772964963, "ltp": 14.5, "tv": 7463.37, "trd": [[14.5, 106.83]], "batb": [[0, 14.5, 62.76]], "batl": NaN}, {"timestamp": 1578772967984, "ltp": 14.5, "tv": 7467.11, "trd": [[14.5, 110.57]], "batb": [[0, 14.5, 60.89]], "batl": NaN}, {"timestamp": 1578772968969, "ltp": 15.0, "tv": 7467.15, "trd": [[15, 751.14]], "batb": NaN, "batl": [[0, 15, 80.79]]}, {"timestamp": 1578772974992, "ltp": 14.5, "tv": 7472.87, "trd": [[14.5, 116.29]], "batb": [[0, 14.5, 58.03]], "batl": NaN}, {"timestamp": 1578772975977, "ltp": 14.5, "tv": 7472.87, "trd": NaN, "batb": NaN, "batl": [[1, 15.5, 1008.2]]}, {"timestamp": 1578772978950, "ltp": 14.5, "tv": 7475.88, "trd": [[14.5, 119.3]], "batb": [[0, 14.5, 56.52]], "batl": NaN}, {"timestamp": 1578772980986, "ltp": 14.5, "tv": 7476.31, "trd": [[14.5, 119.73]], "batb": [[0, 14.5, 56.31]], "batl": NaN}, {"timestamp": 1578772986041, "ltp": 14.5, "tv": 7476.31, "trd": NaN, "batb": [[1, 14, 139.67]], "batl": [[0, 15, 119.79], [1, 15.5, 1041.2], [2, 16, 45.56]]}, {"timestamp": 1578772989014, "ltp": 14.5, "tv": 7476.31, "trd": NaN, "batb": NaN, "batl": [[2, 16, 161.74]]}, {"timestamp": 1578772990007, "ltp": 14.5, "tv": 7476.31, "trd": NaN, "batb": NaN, "batl": [[0, 15, 144.79]]}, {"timestamp": 1578772993016, "ltp": 14.5, "tv": 7476.31, "trd": NaN, "batb": [[2, 13.5, 88.47]], "batl": NaN}, {"timestamp": 1578772996888, "ltp": 14.5, "tv": 7476.31, "trd": NaN, "batb": NaN, "batl": [[2, 16, 277.92]]}, {"timestamp": 1578773005049, "ltp": 14.5, "tv": 7526.31, "trd": [[14.5, 169.73]], "batb": [[0, 14.5, 31.31]], "batl": NaN}, {"timestamp": 1578773007999, "ltp": 14.5, "tv": 7526.31, "trd": NaN, "batb": [[2, 13.5, 88.86]], "batl": NaN}, {"timestamp": 1578773016042, "ltp": 14.5, "tv": 7526.31, "trd": NaN, "batb": [[2, 13.5, 88.47]], "batl": NaN}, {"timestamp": 1578773017030, "ltp": 14.5, "tv": 7530.05, "trd": [[14.5, 173.47]], "batb": [[0, 14.5, 29.43]], "batl": NaN}, {"timestamp": 1578773019054, "ltp": 14.5, "tv": 7530.86, "trd": [[14.5, 174.28]], "batb": [[0, 14.5, 29.03]], "batl": NaN}, {"timestamp": 1578773025023, "ltp": 14.5, "tv": 7534.86, "trd": [[14.5, 178.28]], "batb": [[0, 14.5, 27.03]], "batl": NaN}, {"timestamp": 1578773027959, "ltp": 14.5, "tv": 7542.47, "trd": [[14.5, 185.89]], "batb": [[0, 14.5, 23.22]], "batl": NaN}, {"timestamp": 1578773030047, "ltp": 14.5, "tv": 7549.95, "trd": [[14.5, 193.38]], "batb": [[0, 14.5, 15.74], [1, 14, 114.14]], "batl": NaN}, {"timestamp": 1578773031036, "ltp": 14.5, "tv": 7565.69, "trd": [[14.5, 209.11]], "batb": [[0, 14, 88.6], [1, 13.5, 88.47], [2, 13, 158.39]], "batl": NaN}, {"timestamp": 1578773031963, "ltp": 14.5, "tv": 7565.69, "trd": NaN, "batb": [[0, 14, 79.62]], "batl": [[1, 15.5, 1032.84]]}, {"timestamp": 1578773032948, "ltp": 14.5, "tv": 7565.69, "trd": NaN, "batb": NaN, "batl": [[1, 15.5, 1022.26]]}, {"timestamp": 1578773038964, "ltp": 14.5, "tv": 7565.69, "trd": NaN, "batb": NaN, "batl": [[0, 14.5, 30.15], [1, 15, 144.79], [2, 15.5, 1022.26]]}, {"timestamp": 1578773039958, "ltp": 14.5, "tv": 7565.69, "trd": NaN, "batb": NaN, "batl": [[0, 14.5, 41.35]]}, {"timestamp": 1578773045981, "ltp": 14.5, "tv": 7565.69, "trd": NaN, "batb": [[2, 13, 120.89]], "batl": NaN}, {"timestamp": 1578773046973, "ltp": 14.0, "tv": 7567.36, "trd": [[14, 1.67]], "batb": [[0, 14, 78.79]], "batl": [[0, 14.5, 41.54], [1, 15, 169.79], [2, 15.5, 999.2]]}, {"timestamp": 1578773051988, "ltp": 14.0, "tv": 7584.39, "trd": [[14, 18.7]], "batb": [[0, 14, 70.28]], "batl": NaN}, {"timestamp": 1578773053979, "ltp": 14.0, "tv": 7584.39, "trd": NaN, "batb": NaN, "batl": [[0, 14.5, 66.2], [2, 15.5, 1117.37]]}, {"timestamp": 1578773056964, "ltp": 14.0, "tv": 7584.39, "trd": NaN, "batb": NaN, "batl": [[0, 14.5, 68.07]]}, {"timestamp": 1578773059055, "ltp": 14.5, "tv": 7584.44, "trd": [[14.5, 209.17]], "batb": NaN, "batl": [[0, 14.5, 68.04], [1, 15, 182.1]]}, {"timestamp": 1578773062001, "ltp": 14.5, "tv": 7584.44, "trd": NaN, "batb": [[1, 13.5, 73.09]], "batl": NaN}, {"timestamp": 1578773069018, "ltp": 14.5, "tv": 7584.44, "trd": NaN, "batb": [[2, 13, 137.55]], "batl": NaN}, {"timestamp": 1578773070009, "ltp": 14.5, "tv": 7584.44, "trd": NaN, "batb": NaN, "batl": [[0, 14.5, 81.26]]}, {"timestamp": 1578773070995, "ltp": 14.5, "tv": 7618.49, "trd": [[14.5, 243.21]], "batb": NaN, "batl": [[0, 14.5, 64.24]]}, {"timestamp": 1578773075021, "ltp": 14.0, "tv": 7618.83, "trd": [[14, 19.04]], "batb": [[0, 14, 70.11]], "batl": NaN}, {"timestamp": 1578773076019, "ltp": 14.0, "tv": 7637.52, "trd": [[14, 37.73]], "batb": [[0, 14, 60.76]], "batl": NaN}, {"timestamp": 1578773077987, "ltp": 14.0, "tv": 7637.52, "trd": NaN, "batb": NaN, "batl": [[0, 14.5, 72.65]]}, {"timestamp": 1578773078990, "ltp": 14.0, "tv": 7637.52, "trd": NaN, "batb": NaN, "batl": [[1, 15, 183.9]]}, {"timestamp": 1578773085029, "ltp": 14.0, "tv": 7641.98, "trd": [[14, 42.05], [14.5, 243.35]], "batb": [[0, 14, 58.6], [2, 13, 78.55]], "batl": [[0, 14.5, 72.58], [1, 15, 182.1]]}, {"timestamp": 1578773086026, "ltp": 14.0, "tv": 7645.72, "trd": [[14, 45.79]], "batb": [[0, 14, 56.72]], "batl": NaN}, {"timestamp": 1578773087026, "ltp": 14.5, "tv": 7646.34, "trd": [[14.5, 243.97]], "batb": NaN, "batl": [[0, 14.5, 72.27]]}, {"timestamp": 1578773088045, "ltp": 14.0, "tv": 7646.72, "trd": [[14, 46.17]], "batb": [[0, 14, 56.54]], "batl": NaN}, {"timestamp": 1578773089001, "ltp": 14.0, "tv": 7646.72, "trd": NaN, "batb": NaN, "batl": [[2, 15.5, 1122.47]]}, {"timestamp": 1578773090024, "ltp": 14.0, "tv": 7666.72, "trd": [[14, 66.17]], "batb": [[0, 14, 46.54]], "batl": NaN}, {"timestamp": 1578773092026, "ltp": 14.0, "tv": 7670.33, "trd": [[14, 69.78]], "batb": [[0, 14, 44.73]], "batl": [[0, 14.5, 113.27], [2, 15.5, 1240.64]]}, {"timestamp": 1578773093017, "ltp": 14.0, "tv": 7670.33, "trd": NaN, "batb": [[0, 14, 44.88]], "batl": NaN}, {"timestamp": 1578773097002, "ltp": 14.5, "tv": 7674.85, "trd": [[14.5, 248.49]], "batb": NaN, "batl": [[0, 14.5, 111.01]]}, {"timestamp": 1578773098035, "ltp": 14.5, "tv": 7674.85, "trd": NaN, "batb": [[2, 13, 88.55]], "batl": [[0, 14.5, 97.79]]}, {"timestamp": 1578773099029, "ltp": 14.0, "tv": 7681.61, "trd": [[14, 76.54]], "batb": [[0, 14, 41.5]], "batl": NaN}, {"timestamp": 1578773100030, "ltp": 14.0, "tv": 7681.61, "trd": NaN, "batb": [[2, 13, 71.89]], "batl": NaN}, {"timestamp": 1578773102025, "ltp": 14.0, "tv": 7681.61, "trd": NaN, "batb": [[0, 14, 49.3]], "batl": NaN}, {"timestamp": 1578773103951, "ltp": 14.5, "tv": 7683.03, "trd": [[14.5, 249.91]], "batb": NaN, "batl": [[0, 14.5, 97.08]]}, {"timestamp": 1578773104955, "ltp": 14.0, "tv": 7721.3, "trd": [[14, 114.81]], "batb": [[0, 14, 30.16]], "batl": [[2, 15.5, 1122.47]]}, {"timestamp": 1578773106023, "ltp": 14.0, "tv": 7721.3, "trd": NaN, "batb": NaN, "batl": [[2, 15.5, 1004.3]]}, {"timestamp": 1578773107020, "ltp": 14.0, "tv": 7721.3, "trd": NaN, "batb": [[2, 13, 88.55]], "batl": [[0, 14.5, 110.3]]}, {"timestamp": 1578773109031, "ltp": 14.0, "tv": 7721.3, "trd": NaN, "batb": NaN, "batl": [[0, 14.5, 110.11]]}, {"timestamp": 1578773110035, "ltp": 14.5, "tv": 7721.45, "trd": [[14.5, 250.07]], "batb": NaN, "batl": [[0, 14.5, 135.04]]}, {"timestamp": 1578773111971, "ltp": 14.5, "tv": 7721.45, "trd": NaN, "batb": NaN, "batl": [[2, 15.5, 1033.84]]}, {"timestamp": 1578773113031, "ltp": 14.5, "tv": 7721.45, "trd": NaN, "batb": [[0, 14, 33.13]], "batl": [[2, 15.5, 1122.47]]}, {"timestamp": 1578773114039, "ltp": 14.5, "tv": 7721.45, "trd": NaN, "batb": NaN, "batl": [[2, 15.5, 1240.64]]}, {"timestamp": 1578773117041, "ltp": 14.0, "tv": 7725.2, "trd": [[14, 118.55]], "batb": [[0, 14, 31.26]], "batl": NaN}, {"timestamp": 1578773118983, "ltp": 14.0, "tv": 7725.2, "trd": NaN, "batb": [[1, 13.5, 77.35]], "batl": NaN}, {"timestamp": 1578773124964, "ltp": 14.0, "tv": 7731.19, "trd": [[14, 124.55]], "batb": [[0, 14, 28.27]], "batl": NaN}, {"timestamp": 1578773125964, "ltp": 14.0, "tv": 7731.19, "trd": NaN, "batb": NaN, "batl": [[2, 15.5, 1245.75]]}, {"timestamp": 1578773134987, "ltp": 14.5, "tv": 7731.33, "trd": [[14.5, 250.2]], "batb": NaN, "batl": [[0, 14.5, 134.97]]}, {"timestamp": 1578773138984, "ltp": 14.5, "tv": 7735.33, "trd": [[14.5, 254.2]], "batb": NaN, "batl": [[0, 14.5, 132.97]]}, {"timestamp": 1578773139985, "ltp": 14.5, "tv": 7735.33, "trd": NaN, "batb": NaN, "batl": [[2, 15.5, 1240.64]]}, {"timestamp": 1578773141973, "ltp": 14.5, "tv": 7735.33, "trd": NaN, "batb": [[0, 14, 28.12]], "batl": NaN}, {"timestamp": 1578773146007, "ltp": 14.5, "tv": 7735.33, "trd": NaN, "batb": NaN, "batl": [[2, 15.5, 1122.47]]}, {"timestamp": 1578773147003, "ltp": 14.5, "tv": 7735.33, "trd": NaN, "batb": NaN, "batl": [[1, 15, 188.05]]}, {"timestamp": 1578773148016, "ltp": 14.0, "tv": 7791.56, "trd": [[14, 180.78]], "batb": [[0, 13.5, 77.35], [1, 13, 88.55], [2, 12.5, 176.14]], "batl": [[0, 14, 20.88], [1, 14.5, 132.97], [2, 15, 188.05]]}, {"timestamp": 1578773154013, "ltp": 14.0, "tv": 7791.56, "trd": NaN, "batb": NaN, "batl": [[0, 14, 27.41], [2, 15, 308.31]]}, {"timestamp": 1578773155014, "ltp": 14.0, "tv": 7795.86, "trd": [[14, 185.08]], "batb": NaN, "batl": [[0, 14, 6.53], [1, 14.5, 91.97], [2, 15, 269.31]]}, {"timestamp": 1578773156017, "ltp": 14.0, "tv": 7808.92, "trd": [[14, 198.14]], "batb": [[0, 14, 35.15], [1, 13.5, 77.35], [2, 13, 88.55]], "batl": [[0, 14.5, 103.41], [1, 15, 269.31], [2, 15.5, 1066.41]]}, {"timestamp": 1578773157012, "ltp": 14.0, "tv": 7858.92, "trd": [[14, 248.14]], "batb": [[0, 14, 10.15]], "batl": NaN}, {"timestamp": 1578773158020, "ltp": 14.0, "tv": 7864.03, "trd": [[14, 253.25]], "batb": [[0, 14, 28.43]], "batl": NaN}, {"timestamp": 1578773159010, "ltp": 14.0, "tv": 7864.03, "trd": NaN, "batb": [[0, 14, 49.27], [2, 13, 71.89]], "batl": NaN}, {"timestamp": 1578773160021, "ltp": 14.0, "tv": 7864.03, "trd": NaN, "batb": [[0, 14, 70.11]], "batl": NaN}, {"timestamp": 1578773161020, "ltp": 14.0, "tv": 7864.03, "trd": NaN, "batb": [[0, 14, 99.46]], "batl": NaN}, {"timestamp": 1578773162018, "ltp": 14.0, "tv": 7864.03, "trd": NaN, "batb": [[0, 14, 126.8]], "batl": NaN}, {"timestamp": 1578773163014, "ltp": 14.0, "tv": 7864.03, "trd": NaN, "batb": NaN, "batl": [[0, 14.5, 116.63]]}, {"timestamp": 1578773165015, "ltp": 14.0, "tv": 7864.03, "trd": NaN, "batb": NaN, "batl": [[2, 15.5, 948.24]]}, {"timestamp": 1578773172040, "ltp": 14.0, "tv": 7864.03, "trd": NaN, "batb": NaN, "batl": [[1, 15, 389.57]]}, {"timestamp": 1578773173044, "ltp": 14.0, "tv": 7864.03, "trd": NaN, "batb": [[0, 14, 128.06]], "batl": NaN}, {"timestamp": 1578773174056, "ltp": 14.0, "tv": 7864.03, "trd": NaN, "batb": NaN, "batl": [[2, 15.5, 943.13]]}, {"timestamp": 1578773174954, "ltp": 14.0, "tv": 7958.03, "trd": [[14, 347.25]], "batb": [[0, 14, 81.05], [2, 13, 88.55]], "batl": [[0, 14.5, 161.63], [1, 15, 429.57], [2, 15.5, 979.13]]}, {"timestamp": 1578773176011, "ltp": 14.0, "tv": 7958.03, "trd": NaN, "batb": [[2, 13, 71.89]], "batl": NaN}, {"timestamp": 1578773177037, "ltp": 14.0, "tv": 7958.03, "trd": NaN, "batb": NaN, "batl": [[1, 15, 309.31]]}, {"timestamp": 1578773180938, "ltp": 14.0, "tv": 7958.03, "trd": NaN, "batb": NaN, "batl": [[1, 15, 315.27]]}, {"timestamp": 1578773182056, "ltp": 14.0, "tv": 8052.03, "trd": [[14, 441.25]], "batb": [[0, 14, 34.06]], "batl": NaN}, {"timestamp": 1578773184055, "ltp": 14.0, "tv": 8120.14, "trd": [[14, 509.36]], "batb": [[0, 13.5, 77.35], [1, 13, 71.89], [2, 12.5, 199.25]], "batl": NaN}, {"timestamp": 1578773186054, "ltp": 14.0, "tv": 8120.14, "trd": NaN, "batb": NaN, "batl": [[0, 14, 1.53], [1, 14.5, 161.63], [2, 15, 195.01]]}, {"timestamp": 1578773191970, "ltp": 14.0, "tv": 8120.14, "trd": NaN, "batb": NaN, "batl": [[2, 15, 315.27]]}, {"timestamp": 1578773192971, "ltp": 14.0, "tv": 8120.14, "trd": NaN, "batb": NaN, "batl": [[2, 15, 309.31]]}, {"timestamp": 1578773194037, "ltp": 14.0, "tv": 8120.14, "trd": NaN, "batb": NaN, "batl": [[1, 14.5, 284.1]]}, {"timestamp": 1578773200002, "ltp": 14.0, "tv": 8120.14, "trd": NaN, "batb": NaN, "batl": [[1, 14.5, 290.06]]}, {"timestamp": 1578773200976, "ltp": 14.0, "tv": 8120.14, "trd": NaN, "batb": [[0, 13.5, 73.09]], "batl": NaN}, {"timestamp": 1578773206979, "ltp": 14.0, "tv": 8120.14, "trd": NaN, "batb": NaN, "batl": [[0, 14, 26.53]]}, {"timestamp": 1578773207972, "ltp": 14.0, "tv": 8120.14, "trd": NaN, "batb": [[1, 13, 76.15]], "batl": NaN}, {"timestamp": 1578773209975, "ltp": 13.5, "tv": 8201.33, "trd": [[13.5, 81.19]], "batb": [[0, 13.5, 32.5]], "batl": NaN}, {"timestamp": 1578773210972, "ltp": 13.5, "tv": 8201.33, "trd": NaN, "batb": [[1, 13, 96.29]], "batl": [[0, 14, 73.53], [1, 14.5, 288.19]]}, {"timestamp": 1578773211969, "ltp": 13.5, "tv": 8201.33, "trd": NaN, "batb": NaN, "batl": [[0, 14, 82.04]]}, {"timestamp": 1578773215969, "ltp": 14.0, "tv": 8210.2, "trd": [[14, 518.23]], "batb": NaN, "batl": [[0, 14, 77.61]]}, {"timestamp": 1578773216972, "ltp": 14.0, "tv": 8210.2, "trd": NaN, "batb": [[0, 13.5, 58.98]], "batl": NaN}, {"timestamp": 1578773218989, "ltp": 13.5, "tv": 8213.94, "trd": [[13.5, 84.93]], "batb": [[0, 13.5, 57.11], [2, 12.5, 132.25]], "batl": NaN}, {"timestamp": 1578773221994, "ltp": 13.5, "tv": 8213.94, "trd": NaN, "batb": NaN, "batl": [[0, 14, 102.61]]}, {"timestamp": 1578773222980, "ltp": 14.0, "tv": 8216.73, "trd": [[14, 521.02]], "batb": NaN, "batl": [[0, 14, 101.21]]}, {"timestamp": 1578773225997, "ltp": 14.0, "tv": 8233.76, "trd": [[14, 538.05]], "batb": NaN, "batl": [[0, 14, 92.7]]}, {"timestamp": 1578773227987, "ltp": 14.0, "tv": 8233.76, "trd": NaN, "batb": [[2, 12.5, 114.14]], "batl": [[2, 15, 303.36]]}, {"timestamp": 1578773229997, "ltp": 13.5, "tv": 8235.82, "trd": [[13.5, 86.99]], "batb": [[0, 13.5, 56.08]], "batl": NaN}, {"timestamp": 1578773230998, "ltp": 13.5, "tv": 8235.82, "trd": NaN, "batb": [[0, 13, 96.29], [1, 12.5, 114.14], [2, 12, 183.45]], "batl": [[2, 15, 246.4]]}, {"timestamp": 1578773231996, "ltp": 13.5, "tv": 8235.82, "trd": NaN, "batb": NaN, "batl": [[2, 15, 126.14]]}, {"timestamp": 1578773234989, "ltp": 13.5, "tv": 8235.82, "trd": NaN, "batb": [[2, 12, 203.21]], "batl": [[1, 14.5, 294.15]]}, {"timestamp": 1578773237983, "ltp": 13.5, "tv": 8235.82, "trd": NaN, "batb": NaN, "batl": [[0, 14, 137.6]]}, {"timestamp": 1578773238989, "ltp": 13.5, "tv": 8235.82, "trd": NaN, "batb": NaN, "batl": [[0, 14, 162.6], [1, 14.5, 416.62]]}, {"timestamp": 1578773240043, "ltp": 13.5, "tv": 8251.2, "trd": [[13.5, 102.37]], "batb": NaN, "batl": [[0, 14, 168.33]]}, {"timestamp": 1578773244033, "ltp": 13.5, "tv": 8251.2, "trd": NaN, "batb": NaN, "batl": [[0, 14, 172.44]]}, {"timestamp": 1578773245001, "ltp": 13.5, "tv": 8251.2, "trd": NaN, "batb": NaN, "batl": [[1, 14.5, 294.15]]}, {"timestamp": 1578773246995, "ltp": 13.5, "tv": 8251.2, "trd": NaN, "batb": [[0, 13, 76.15], [1, 12.5, 132.25]], "batl": NaN}, {"timestamp": 1578773247997, "ltp": 14.0, "tv": 8268.21, "trd": [[13.5, 110.88], [14, 546.55]], "batb": NaN, "batl": [[0, 14, 168.19]]}, {"timestamp": 1578773252052, "ltp": 13.5, "tv": 8271.02, "trd": [[13.5, 113.69]], "batb": NaN, "batl": [[2, 15, 102.31]]}, {"timestamp": 1578773256995, "ltp": 13.5, "tv": 8271.02, "trd": NaN, "batb": [[1, 12.5, 182.25]], "batl": NaN}, {"timestamp": 1578773259005, "ltp": 13.5, "tv": 8271.02, "trd": NaN, "batb": NaN, "batl": [[0, 14, 193.73], [1, 14.5, 324.76]]}, {"timestamp": 1578773260055, "ltp": 13.5, "tv": 8271.02, "trd": NaN, "batb": NaN, "batl": [[1, 14.5, 416.62]]}, {"timestamp": 1578773263030, "ltp": 13.5, "tv": 8271.02, "trd": NaN, "batb": NaN, "batl": [[1, 14.5, 410.66]]}, {"timestamp": 1578773264034, "ltp": 14.0, "tv": 8271.31, "trd": [[14, 546.84]], "batb": NaN, "batl": [[0, 14, 193.58]]}, {"timestamp": 1578773266020, "ltp": 14.0, "tv": 8271.31, "trd": NaN, "batb": [[0, 13, 48.64]], "batl": NaN}, {"timestamp": 1578773266974, "ltp": 14.0, "tv": 8271.31, "trd": NaN, "batb": [[0, 13, 22.92]], "batl": [[1, 14.5, 366.39]]}, {"timestamp": 1578773268028, "ltp": 14.0, "tv": 8271.31, "trd": NaN, "batb": [[1, 12.5, 203.5]], "batl": NaN}, {"timestamp": 1578773269829, "ltp": 14.0, "tv": 8271.31, "trd": NaN, "batb": NaN, "batl": [[0, 14, 199.54]]}, {"timestamp": 1578773273020, "ltp": 13.5, "tv": 8307.87, "trd": [[13.5, 150.25]], "batb": NaN, "batl": [[0, 13.5, 6.44], [1, 14, 199.54], [2, 14.5, 366.39]]}, {"timestamp": 1578773273949, "ltp": 13.5, "tv": 8307.87, "trd": NaN, "batb": NaN, "batl": [[0, 13.5, 42.61]]}, {"timestamp": 1578773278972, "ltp": 13.5, "tv": 8307.87, "trd": NaN, "batb": NaN, "batl": [[0, 13.5, 40.74]]}, {"timestamp": 1578773279971, "ltp": 13.5, "tv": 8307.87, "trd": NaN, "batb": NaN, "batl": [[0, 13.5, 60.74]]}, {"timestamp": 1578773280971, "ltp": 13.5, "tv": 8307.87, "trd": NaN, "batb": NaN, "batl": [[0, 13.5, 76.12]]}, {"timestamp": 1578773284960, "ltp": 13.5, "tv": 8307.87, "trd": NaN, "batb": [[2, 12, 220.24]], "batl": NaN}, {"timestamp": 1578773285965, "ltp": 13.5, "tv": 8307.87, "trd": NaN, "batb": NaN, "batl": [[0, 13.5, 56.12]]}, {"timestamp": 1578773286973, "ltp": 13.5, "tv": 8307.87, "trd": NaN, "batb": NaN, "batl": [[1, 14, 195.43]]}, {"timestamp": 1578773287982, "ltp": 13.5, "tv": 8307.87, "trd": NaN, "batb": [[2, 12, 203.21]], "batl": NaN}, {"timestamp": 1578773292017, "ltp": 13.5, "tv": 8307.87, "trd": NaN, "batb": [[2, 12, 162.31]], "batl": [[2, 14.5, 243.92]]}, {"timestamp": 1578773292977, "ltp": 13.0, "tv": 8347.87, "trd": [[13, 39.99]], "batb": [[0, 13, 2.93]], "batl": NaN}, {"timestamp": 1578773293982, "ltp": 13.0, "tv": 8351.61, "trd": [[13, 43.73]], "batb": [[0, 13, 1.06]], "batl": NaN}, {"timestamp": 1578773294982, "ltp": 13.0, "tv": 8351.61, "trd": NaN, "batb": [[1, 12.5, 220.53]], "batl": NaN}, {"timestamp": 1578773295983, "ltp": 13.0, "tv": 8351.61, "trd": NaN, "batb": NaN, "batl": [[0, 13.5, 109.12]]}, {"timestamp": 1578773296991, "ltp": 13.0, "tv": 8351.61, "trd": NaN, "batb": NaN, "batl": [[2, 14.5, 237.96]]}, {"timestamp": 1578773298992, "ltp": 13.0, "tv": 8351.61, "trd": NaN, "batb": NaN, "batl": [[2, 14.5, 360.43]]}, {"timestamp": 1578773300986, "ltp": 13.0, "tv": 8351.61, "trd": NaN, "batb": [[1, 12.5, 202.42]], "batl": NaN}, {"timestamp": 1578773303990, "ltp": 13.0, "tv": 8351.61, "trd": NaN, "batb": NaN, "batl": [[1, 14, 201.38]]}, {"timestamp": 1578773304981, "ltp": 13.0, "tv": 8351.61, "trd": NaN, "batb": NaN, "batl": [[2, 14.5, 237.96]]}, {"timestamp": 1578773305974, "ltp": 13.0, "tv": 8351.61, "trd": NaN, "batb": NaN, "batl": [[2, 14.5, 115.49]]}, {"timestamp": 1578773309046, "ltp": 13.0, "tv": 8351.61, "trd": NaN, "batb": [[2, 12, 85.31]], "batl": NaN}, {"timestamp": 1578773310995, "ltp": 13.0, "tv": 8351.61, "trd": NaN, "batb": [[0, 13, 21.06]], "batl": NaN}, {"timestamp": 1578773311985, "ltp": 13.0, "tv": 8355.95, "trd": [[13, 48.08]], "batb": [[0, 13, 18.88]], "batl": [[1, 14, 326.18]]}, {"timestamp": 1578773312976, "ltp": 13.0, "tv": 8355.95, "trd": NaN, "batb": NaN, "batl": [[1, 14, 450.98]]}, {"timestamp": 1578773315004, "ltp": 13.0, "tv": 8364.17, "trd": [[13, 56.3]], "batb": [[0, 13, 14.77]], "batl": NaN}, {"timestamp": 1578773316996, "ltp": 13.0, "tv": 8393.71, "trd": [[13, 85.84]], "batb": [[0, 12.5, 152.42], [1, 12, 85.31], [2, 11.5, 258.01]], "batl": [[0, 13, 10.23], [1, 13.5, 109.12], [2, 14, 450.98]]}, {"timestamp": 1578773318985, "ltp": 13.0, "tv": 8402.23, "trd": [[13, 94.36]], "batb": NaN, "batl": [[0, 13, 5.97]]}, {"timestamp": 1578773323026, "ltp": 13.0, "tv": 8402.23, "trd": NaN, "batb": NaN, "batl": [[2, 14, 445.03]]}, {"timestamp": 1578773324025, "ltp": 13.0, "tv": 8414.17, "trd": [[13, 106.3]], "batb": [[0, 13, 140.86], [1, 12.5, 152.42], [2, 12, 85.31]], "batl": [[0, 13.5, 109.12], [1, 14, 445.03], [2, 14.5, 90.83]]}, {"timestamp": 1578773325019, "ltp": 13.0, "tv": 8414.17, "trd": NaN, "batb": NaN, "batl": [[0, 13.5, 135.6]]}, {"timestamp": 1578773327037, "ltp": 13.0, "tv": 8414.17, "trd": NaN, "batb": [[1, 12.5, 156.69]], "batl": NaN}, {"timestamp": 1578773327997, "ltp": 13.5, "tv": 8654.49, "trd": [[13.5, 390.56]], "batb": NaN, "batl": [[0, 13.5, 15.44]]}, {"timestamp": 1578773330007, "ltp": 13.5, "tv": 8654.49, "trd": NaN, "batb": NaN, "batl": [[0, 13.5, 22.25]]}, {"timestamp": 1578773335037, "ltp": 13.0, "tv": 8674.49, "trd": [[13, 126.3]], "batb": [[0, 13, 130.86], [1, 12.5, 152.42]], "batl": NaN}, {"timestamp": 1578773335936, "ltp": 13.0, "tv": 8707.81, "trd": [[13, 159.62]], "batb": [[0, 13, 114.2]], "batl": [[0, 13.5, 137.3]]}, {"timestamp": 1578773343023, "ltp": 13.0, "tv": 8712.74, "trd": [[13, 164.54]], "batb": [[0, 13, 115.85]], "batl": [[0, 13.5, 144.96]]}, {"timestamp": 1578773344012, "ltp": 13.0, "tv": 8712.74, "trd": NaN, "batb": [[2, 12, 95.31]], "batl": [[2, 14.5, 45.83]]}, {"timestamp": 1578773346908, "ltp": 13.0, "tv": 8712.74, "trd": NaN, "batb": NaN, "batl": [[1, 14, 439.07]]}, {"timestamp": 1578773351022, "ltp": 13.0, "tv": 8836.73, "trd": [[13, 288.54]], "batb": [[0, 13, 53.85]], "batl": NaN}, {"timestamp": 1578773352025, "ltp": 13.0, "tv": 8845.25, "trd": [[13, 297.06]], "batb": [[0, 13, 49.59]], "batl": NaN}, {"timestamp": 1578773353021, "ltp": 13.0, "tv": 8862.91, "trd": [[13, 314.72]], "batb": [[0, 13, 40.76]], "batl": NaN}, {"timestamp": 1578773354020, "ltp": 13.0, "tv": 8862.91, "trd": NaN, "batb": NaN, "batl": [[0, 13.5, 151.77]]}, {"timestamp": 1578773356946, "ltp": 13.0, "tv": 8906.11, "trd": [[13, 357.92]], "batb": [[0, 13, 19.16]], "batl": NaN}, {"timestamp": 1578773361967, "ltp": 13.0, "tv": 8906.11, "trd": NaN, "batb": [[2, 12, 75.55]], "batl": NaN}, {"timestamp": 1578773364964, "ltp": 13.0, "tv": 8906.11, "trd": NaN, "batb": [[2, 12, 117.85]], "batl": [[0, 13.5, 155.18]]}, {"timestamp": 1578773367043, "ltp": 13.0, "tv": 8916.32, "trd": [[13, 368.13]], "batb": [[0, 13, 14.05]], "batl": NaN}, {"timestamp": 1578773368041, "ltp": 13.5, "tv": 8916.44, "trd": [[13.5, 390.68]], "batb": NaN, "batl": [[0, 13.5, 155.12]]}, {"timestamp": 1578773368979, "ltp": 13.0, "tv": 8916.9, "trd": [[13, 368.59]], "batb": [[0, 13, 13.82]], "batl": NaN}, {"timestamp": 1578773373967, "ltp": 13.0, "tv": 8922.0, "trd": [[13, 373.7]], "batb": [[0, 13, 11.27]], "batl": NaN}, {"timestamp": 1578773374963, "ltp": 13.0, "tv": 8944.54, "trd": [[13, 396.24]], "batb": [[0, 12.5, 152.42], [1, 12, 117.85], [2, 11.5, 265.16]], "batl": NaN}, {"timestamp": 1578773379996, "ltp": 13.0, "tv": 8944.54, "trd": NaN, "batb": [[0, 12.5, 131.16], [1, 12, 95.55], [2, 11.5, 222.31]], "batl": [[1, 14, 189.47]]}, {"timestamp": 1578773381994, "ltp": 13.0, "tv": 8944.54, "trd": NaN, "batb": [[0, 13, 4.26], [1, 12.5, 131.16], [2, 12, 95.55]], "batl": NaN}, {"timestamp": 1578773384005, "ltp": 13.0, "tv": 8953.06, "trd": [[13, 404.75]], "batb": [[0, 12.5, 131.16], [1, 12, 95.55], [2, 11.5, 222.31]], "batl": [[0, 13, 20.74], [1, 13.5, 155.12], [2, 14, 189.47]]}, {"timestamp": 1578773385004, "ltp": 13.0, "tv": 8953.06, "trd": NaN, "batb": NaN, "batl": [[2, 14, 178.81]]}, {"timestamp": 1578773386993, "ltp": 13.0, "tv": 8953.06, "trd": NaN, "batb": NaN, "batl": [[1, 13.5, 409.66]]}, {"timestamp": 1578773388000, "ltp": 13.0, "tv": 8953.06, "trd": NaN, "batb": [[1, 12, 106.91]], "batl": [[0, 13, 79.74]]}, {"timestamp": 1578773389002, "ltp": 13.0, "tv": 8953.06, "trd": NaN, "batb": [[0, 12.5, 75.91]], "batl": [[2, 14, 119.03]]}, {"timestamp": 1578773391007, "ltp": 13.0, "tv": 8953.06, "trd": NaN, "batb": NaN, "batl": [[0, 13, 90.35]]}, {"timestamp": 1578773395022, "ltp": 12.5, "tv": 8989.28, "trd": [[12.5, 36.22]], "batb": [[0, 12.5, 57.8]], "batl": [[0, 13, 107.01]]}, {"timestamp": 1578773396011, "ltp": 13.0, "tv": 8990.67, "trd": [[13, 406.15]], "batb": NaN, "batl": [[0, 13, 168.29]]}, {"timestamp": 1578773397009, "ltp": 13.0, "tv": 8990.67, "trd": NaN, "batb": [[1, 12, 95.55]], "batl": NaN}, {"timestamp": 1578773401031, "ltp": 13.0, "tv": 8990.67, "trd": NaN, "batb": [[2, 11.5, 200.67]], "batl": NaN}, {"timestamp": 1578773405044, "ltp": 13.0, "tv": 8990.67, "trd": NaN, "batb": NaN, "batl": [[1, 13.5, 402.85]]}, {"timestamp": 1578773409042, "ltp": 13.0, "tv": 8990.67, "trd": NaN, "batb": [[0, 12.5, 57.97]], "batl": NaN}, {"timestamp": 1578773409949, "ltp": 13.0, "tv": 8990.67, "trd": NaN, "batb": [[1, 12, 106.4]], "batl": NaN}, {"timestamp": 1578773411966, "ltp": 13.0, "tv": 8990.67, "trd": NaN, "batb": [[1, 12, 95.55]], "batl": [[0, 13, 175.1]]}, {"timestamp": 1578773412916, "ltp": 13.0, "tv": 8990.72, "trd": [[13, 406.19]], "batb": NaN, "batl": [[0, 13, 175.08]]}, {"timestamp": 1578773413924, "ltp": 13.0, "tv": 8990.72, "trd": NaN, "batb": [[2, 11.5, 115.67]], "batl": NaN}, {"timestamp": 1578773416040, "ltp": 13.0, "tv": 8990.72, "trd": NaN, "batb": [[0, 12.5, 57.8], [1, 12, 97.25]], "batl": [[1, 13.5, 396.04]]}, {"timestamp": 1578773417048, "ltp": 13.0, "tv": 8990.72, "trd": NaN, "batb": NaN, "batl": [[1, 13.5, 392.63]]}, {"timestamp": 1578773423050, "ltp": 13.0, "tv": 8990.72, "trd": NaN, "batb": NaN, "batl": [[0, 13, 181.89]]}, {"timestamp": 1578773424041, "ltp": 13.0, "tv": 8990.72, "trd": NaN, "batb": NaN, "batl": [[0, 13, 185.3]]}, {"timestamp": 1578773425049, "ltp": 13.0, "tv": 8990.72, "trd": NaN, "batb": NaN, "batl": [[0, 13, 181.89]]}, {"timestamp": 1578773427048, "ltp": 12.5, "tv": 9030.72, "trd": [[12.5, 76.22]], "batb": [[0, 12.5, 37.8]], "batl": NaN}, {"timestamp": 1578773432964, "ltp": 12.5, "tv": 9030.72, "trd": NaN, "batb": NaN, "batl": [[1, 13.5, 396.04]]}, {"timestamp": 1578773441892, "ltp": 12.5, "tv": 9030.72, "trd": NaN, "batb": [[2, 11.5, 137.31]], "batl": NaN}, {"timestamp": 1578773443991, "ltp": 13.0, "tv": 9034.73, "trd": [[13, 410.21]], "batb": NaN, "batl": [[0, 13, 179.88]]}, {"timestamp": 1578773447007, "ltp": 12.5, "tv": 9056.1, "trd": [[12.5, 97.58]], "batb": [[0, 12.5, 27.12]], "batl": NaN}, {"timestamp": 1578773451995, "ltp": 12.5, "tv": 9056.1, "trd": NaN, "batb": [[2, 11.5, 115.67]], "batl": NaN}, {"timestamp": 1578773460003, "ltp": 13.0, "tv": 9056.24, "trd": [[13, 410.35]], "batb": NaN, "batl": [[0, 13, 179.81]]}, {"timestamp": 1578773461010, "ltp": 13.0, "tv": 9056.24, "trd": NaN, "batb": NaN, "batl": [[1, 13.5, 268.77]]}, {"timestamp": 1578773462014, "ltp": 13.0, "tv": 9056.24, "trd": NaN, "batb": NaN, "batl": [[2, 14, 94.03]]}, {"timestamp": 1578773464011, "ltp": 13.0, "tv": 9056.24, "trd": NaN, "batb": [[2, 11.5, 137.31]], "batl": NaN}, {"timestamp": 1578773465016, "ltp": 13.0, "tv": 9056.24, "trd": NaN, "batb": NaN, "batl": [[2, 14, 47.03]]}, {"timestamp": 1578773465905, "ltp": 13.0, "tv": 9056.24, "trd": NaN, "batb": NaN, "batl": [[1, 13.5, 141.5], [2, 14, 22.03]]}, {"timestamp": 1578773468026, "ltp": 13.0, "tv": 9056.24, "trd": NaN, "batb": NaN, "batl": [[0, 13, 309.71]]}, {"timestamp": 1578773469028, "ltp": 13.0, "tv": 9056.24, "trd": NaN, "batb": [[2, 11.5, 115.67]], "batl": NaN}, {"timestamp": 1578773472032, "ltp": 12.5, "tv": 9110.48, "trd": [[12.5, 151.82]], "batb": [[0, 12, 97.25], [1, 11.5, 115.67], [2, 11, 186.45]], "batl": [[0, 12.5, 38.88], [1, 13, 309.71], [2, 13.5, 141.5]]}, {"timestamp": 1578773473033, "ltp": 12.5, "tv": 9110.48, "trd": NaN, "batb": NaN, "batl": [[1, 13, 439.61]]}, {"timestamp": 1578773476034, "ltp": 12.5, "tv": 9110.48, "trd": NaN, "batb": NaN, "batl": [[2, 13.5, 138.09]]}, {"timestamp": 1578773477041, "ltp": 12.5, "tv": 9110.48, "trd": NaN, "batb": [[1, 11.5, 137.31]], "batl": NaN}, {"timestamp": 1578773478046, "ltp": 12.5, "tv": 9110.48, "trd": NaN, "batb": [[1, 11.5, 115.67]], "batl": NaN}, {"timestamp": 1578773479027, "ltp": 12.5, "tv": 9113.47, "trd": [[12.5, 154.81]], "batb": [[1, 11.5, 127.63]], "batl": [[0, 12.5, 37.39]]}, {"timestamp": 1578773482030, "ltp": 12.5, "tv": 9113.47, "trd": NaN, "batb": NaN, "batl": [[1, 13, 443.02]]}, {"timestamp": 1578773483027, "ltp": 12.5, "tv": 9113.47, "trd": NaN, "batb": NaN, "batl": [[0, 12.5, 41.5]]}, {"timestamp": 1578773486970, "ltp": 12.5, "tv": 9113.93, "trd": [[12.5, 155.27]], "batb": NaN, "batl": [[0, 12.5, 41.27]]}, {"timestamp": 1578773487967, "ltp": 12.5, "tv": 9113.93, "trd": NaN, "batb": NaN, "batl": [[0, 12.5, 4.11], [1, 13, 384.02], [2, 13.5, 127.52]]}, {"timestamp": 1578773494968, "ltp": 12.5, "tv": 9113.93, "trd": NaN, "batb": [[0, 12, 95.55]], "batl": [[0, 12.5, 14.87]]}, {"timestamp": 1578773495967, "ltp": 12.5, "tv": 9113.93, "trd": NaN, "batb": NaN, "batl": [[0, 12.5, 4.11]]}, {"timestamp": 1578773500006, "ltp": 12.5, "tv": 9113.93, "trd": NaN, "batb": NaN, "batl": [[1, 13, 377.21]]}, {"timestamp": 1578773503997, "ltp": 12.5, "tv": 9113.93, "trd": NaN, "batb": NaN, "batl": [[0, 12.5, 29.11]]}, {"timestamp": 1578773506993, "ltp": 12.5, "tv": 9113.93, "trd": NaN, "batb": NaN, "batl": [[0, 12.5, 35.92], [2, 13.5, 93.42]]}, {"timestamp": 1578773512020, "ltp": 12.5, "tv": 9113.93, "trd": NaN, "batb": NaN, "batl": [[0, 12.5, 46.91]]}, {"timestamp": 1578773513977, "ltp": 12.5, "tv": 9113.93, "trd": NaN, "batb": NaN, "batl": [[0, 12.5, 81.79], [1, 13, 370.4]]}, {"timestamp": 1578773517025, "ltp": 12.5, "tv": 9113.93, "trd": NaN, "batb": [[2, 11, 162.65]], "batl": NaN}, {"timestamp": 1578773519987, "ltp": 12.5, "tv": 9113.93, "trd": NaN, "batb": NaN, "batl": [[0, 12.5, 151.79], [2, 13.5, 38.42]]}, {"timestamp": 1578773521033, "ltp": 12.5, "tv": 9113.93, "trd": NaN, "batb": NaN, "batl": [[0, 12.5, 158.6]]}, {"timestamp": 1578773522035, "ltp": 12.5, "tv": 9113.93, "trd": NaN, "batb": [[0, 12, 86.82]], "batl": NaN}, {"timestamp": 1578773523045, "ltp": 12.5, "tv": 9113.93, "trd": NaN, "batb": [[0, 12, 30]], "batl": [[1, 13, 240.5], [2, 13.5, 23.04]]}, {"timestamp": 1578773526022, "ltp": 12.0, "tv": 9117.66, "trd": [[12, 3.74]], "batb": [[0, 12, 28.13]], "batl": [[1, 13, 110.6]]}, {"timestamp": 1578773527025, "ltp": 12.5, "tv": 9117.77, "trd": [[12.5, 155.37]], "batb": [[2, 11, 186.45]], "batl": [[0, 12.5, 158.55]]}, {"timestamp": 1578773530044, "ltp": 12.5, "tv": 9117.77, "trd": NaN, "batb": NaN, "batl": [[0, 12.5, 187.15]]}, {"timestamp": 1578773532055, "ltp": 12.5, "tv": 9117.77, "trd": NaN, "batb": [[1, 11.5, 130.69]], "batl": NaN}, {"timestamp": 1578773533950, "ltp": 12.5, "tv": 9117.77, "trd": NaN, "batb": NaN, "batl": [[0, 12.5, 319.84]]}, {"timestamp": 1578773534955, "ltp": 12.0, "tv": 9123.91, "trd": [[12, 9.88]], "batb": [[0, 12, 25.06]], "batl": NaN}, {"timestamp": 1578773537051, "ltp": 12.0, "tv": 9123.91, "trd": NaN, "batb": NaN, "batl": [[0, 12.5, 452.53]]}, {"timestamp": 1578773538027, "ltp": 12.0, "tv": 9123.91, "trd": NaN, "batb": NaN, "batl": [[0, 12.5, 319.84]]}, {"timestamp": 1578773539010, "ltp": 12.0, "tv": 9173.91, "trd": [[12, 59.88]], "batb": [[0, 11.5, 130.75], [1, 11, 186.45], [2, 10.5, 214.92]], "batl": NaN}, {"timestamp": 1578773541046, "ltp": 12.0, "tv": 9174.03, "trd": [[12, 60]], "batb": [[0, 11.5, 130.69]], "batl": [[0, 12, 1.81], [1, 12.5, 319.84], [2, 13, 110.6]]}, {"timestamp": 1578773544053, "ltp": 12.0, "tv": 9174.13, "trd": [[12, 60.1]], "batb": NaN, "batl": [[0, 12, 1.76]]}, {"timestamp": 1578773545054, "ltp": 12.0, "tv": 9174.13, "trd": NaN, "batb": NaN, "batl": [[1, 12.5, 452.53]]}, {"timestamp": 1578773547042, "ltp": 12.0, "tv": 9174.13, "trd": NaN, "batb": NaN, "batl": [[0, 12.5, 452.53], [1, 13, 110.6], [2, 13.5, 15.38]]}, {"timestamp": 1578773549948, "ltp": 12.0, "tv": 9174.13, "trd": NaN, "batb": NaN, "batl": [[0, 12.5, 470.64]]}, {"timestamp": 1578773551044, "ltp": 12.0, "tv": 9174.13, "trd": NaN, "batb": NaN, "batl": [[0, 12.5, 452.53]]}, {"timestamp": 1578773557971, "ltp": 12.0, "tv": 9174.13, "trd": NaN, "batb": NaN, "batl": [[0, 12, 10], [1, 12.5, 452.53], [2, 13, 110.6]]}, {"timestamp": 1578773565983, "ltp": 12.0, "tv": 9174.13, "trd": NaN, "batb": NaN, "batl": [[1, 12.5, 470.64]]}, {"timestamp": 1578773566982, "ltp": 12.0, "tv": 9174.13, "trd": NaN, "batb": NaN, "batl": [[2, 13, 99.99]]}, {"timestamp": 1578773567995, "ltp": 12.0, "tv": 9174.13, "trd": NaN, "batb": NaN, "batl": [[2, 13, 65.51]]}, {"timestamp": 1578773568999, "ltp": 12.0, "tv": 9175.77, "trd": [[12, 61.74]], "batb": [[1, 11, 162.65]], "batl": [[0, 12, 9.18]]}, {"timestamp": 1578773574006, "ltp": 12.0, "tv": 9175.77, "trd": NaN, "batb": NaN, "batl": [[0, 12, 20.32]]}, {"timestamp": 1578773575017, "ltp": 12.0, "tv": 9175.77, "trd": NaN, "batb": NaN, "batl": [[0, 12, 54.31]]}, {"timestamp": 1578773576018, "ltp": 12.0, "tv": 9175.77, "trd": NaN, "batb": [[0, 11.5, 74.15]], "batl": [[2, 13, 38]]}, {"timestamp": 1578773577028, "ltp": 12.0, "tv": 9175.77, "trd": NaN, "batb": NaN, "batl": [[0, 12, 74.07]]}, {"timestamp": 1578773578027, "ltp": 12.0, "tv": 9175.77, "trd": NaN, "batb": [[1, 11, 179.99]], "batl": NaN}, {"timestamp": 1578773583039, "ltp": 12.0, "tv": 9175.77, "trd": NaN, "batb": NaN, "batl": [[0, 12, 103.86]]}, {"timestamp": 1578773584031, "ltp": 12.0, "tv": 9175.77, "trd": NaN, "batb": [[1, 11, 85.99]], "batl": NaN}, {"timestamp": 1578773588030, "ltp": 12.0, "tv": 9175.77, "trd": NaN, "batb": [[0, 11.5, 75.68]], "batl": NaN}, {"timestamp": 1578773594043, "ltp": 11.5, "tv": 9195.78, "trd": [[11.5, 20]], "batb": [[0, 11.5, 50.66]], "batl": [[1, 12.5, 463.83]]}, {"timestamp": 1578773597056, "ltp": 11.5, "tv": 9195.78, "trd": NaN, "batb": NaN, "batl": [[1, 12.5, 459.77]]}, {"timestamp": 1578773598047, "ltp": 12.0, "tv": 9199.18, "trd": [[12, 65.14]], "batb": NaN, "batl": [[0, 12, 102.16]]}, {"timestamp": 1578773599040, "ltp": 12.0, "tv": 9199.18, "trd": NaN, "batb": NaN, "batl": [[0, 12, 82.4]]}, {"timestamp": 1578773601042, "ltp": 11.5, "tv": 9203.64, "trd": [[11.5, 24.46]], "batb": [[0, 11.5, 48.43]], "batl": [[0, 12, 163.06]]}, {"timestamp": 1578773602041, "ltp": 11.5, "tv": 9203.64, "trd": NaN, "batb": NaN, "batl": [[2, 13, 34.6]]}, {"timestamp": 1578773602929, "ltp": 11.5, "tv": 9204.32, "trd": [[11.5, 25.15]], "batb": [[0, 11.5, 48.09]], "batl": NaN}, {"timestamp": 1578773608971, "ltp": 12.0, "tv": 9244.48, "trd": [[11.5, 65.15], [12, 65.3]], "batb": [[0, 11.5, 28.09]], "batl": [[0, 12, 162.98], [1, 12.5, 463.18]]}, {"timestamp": 1578773610963, "ltp": 12.0, "tv": 9244.48, "trd": NaN, "batb": NaN, "batl": [[0, 12, 182.74]]}, {"timestamp": 1578773620962, "ltp": 12.0, "tv": 9251.96, "trd": [[12, 72.78]], "batb": NaN, "batl": [[0, 12, 179]]}, {"timestamp": 1578773622055, "ltp": 11.5, "tv": 9271.96, "trd": [[11.5, 85.15]], "batb": [[0, 11.5, 18.09]], "batl": NaN}, {"timestamp": 1578773623978, "ltp": 11.5, "tv": 9287.68, "trd": [[11.5, 100.86]], "batb": [[0, 11.5, 10.23]], "batl": NaN}, {"timestamp": 1578773627973, "ltp": 11.5, "tv": 9287.68, "trd": NaN, "batb": NaN, "batl": [[1, 12.5, 197.8]]}, {"timestamp": 1578773631970, "ltp": 11.5, "tv": 9291.42, "trd": [[11.5, 104.6]], "batb": [[0, 11.5, 8.36]], "batl": NaN}, {"timestamp": 1578773633013, "ltp": 11.5, "tv": 9299.64, "trd": [[11.5, 112.82]], "batb": [[0, 11.5, 4.25]], "batl": NaN}, {"timestamp": 1578773634981, "ltp": 12.0, "tv": 9300.55, "trd": [[12, 73.7]], "batb": NaN, "batl": [[0, 12, 449.9]]}, {"timestamp": 1578773635983, "ltp": 12.0, "tv": 9300.55, "trd": NaN, "batb": NaN, "batl": [[1, 12.5, 190.99]]}, {"timestamp": 1578773636987, "ltp": 11.5, "tv": 9309.05, "trd": [[11.5, 121.32]], "batb": [[0, 11, 85.99], [1, 10.5, 214.92], [2, 10, 239.22]], "batl": [[1, 12.5, 187.58]]}, {"timestamp": 1578773640994, "ltp": 11.5, "tv": 9309.05, "trd": NaN, "batb": [[0, 11, 90.1]], "batl": NaN}, {"timestamp": 1578773642993, "ltp": 11.5, "tv": 9309.05, "trd": NaN, "batb": NaN, "batl": [[0, 12, 457.57]]}, {"timestamp": 1578773643997, "ltp": 11.5, "tv": 9309.05, "trd": NaN, "batb": NaN, "batl": [[0, 12, 460.97]]}, {"timestamp": 1578773645000, "ltp": 11.5, "tv": 9309.05, "trd": NaN, "batb": NaN, "batl": [[1, 12.5, 117.58]]}, {"timestamp": 1578773652016, "ltp": 11.5, "tv": 9309.05, "trd": NaN, "batb": NaN, "batl": [[0, 11.5, 81], [1, 12, 460.97], [2, 12.5, 117.58]]}, {"timestamp": 1578773654041, "ltp": 11.5, "tv": 9309.05, "trd": NaN, "batb": [[1, 10.5, 95.92]], "batl": NaN}, {"timestamp": 1578773661049, "ltp": 11.5, "tv": 9309.05, "trd": NaN, "batb": NaN, "batl": [[0, 11.5, 91]]}, {"timestamp": 1578773663053, "ltp": 11.5, "tv": 9309.05, "trd": NaN, "batb": [[0, 11, 62.85]], "batl": [[2, 12.5, 82.7]]}, {"timestamp": 1578773664045, "ltp": 11.5, "tv": 9309.05, "trd": NaN, "batb": [[0, 11, 30.35]], "batl": [[1, 12, 461.9], [2, 12.5, 71.71]]}, {"timestamp": 1578773665043, "ltp": 11.5, "tv": 9309.05, "trd": NaN, "batb": [[1, 10.5, 69.61]], "batl": [[2, 12.5, 43.11]]}, {"timestamp": 1578773666048, "ltp": 11.5, "tv": 9309.05, "trd": NaN, "batb": [[2, 10, 189.22]], "batl": [[1, 12, 460.97]]}, {"timestamp": 1578773667024, "ltp": 11.5, "tv": 9309.05, "trd": NaN, "batb": [[1, 10.5, 88.71]], "batl": NaN}, {"timestamp": 1578773669019, "ltp": 11.5, "tv": 9309.05, "trd": NaN, "batb": NaN, "batl": [[1, 12, 453.31]]}, {"timestamp": 1578773670011, "ltp": 11.5, "tv": 9309.05, "trd": NaN, "batb": [[0, 11, 13.01]], "batl": [[0, 11.5, 127.45], [1, 12, 450.11]]}, {"timestamp": 1578773671012, "ltp": 11.5, "tv": 9309.05, "trd": NaN, "batb": NaN, "batl": [[0, 11.5, 169.61]]}, {"timestamp": 1578773674045, "ltp": 11.5, "tv": 9309.05, "trd": NaN, "batb": [[0, 11, 19.81]], "batl": NaN}, {"timestamp": 1578773676048, "ltp": 11.5, "tv": 9309.05, "trd": NaN, "batb": NaN, "batl": [[0, 11.5, 177.27]]}, {"timestamp": 1578773679980, "ltp": 11.5, "tv": 9309.05, "trd": NaN, "batb": NaN, "batl": [[0, 11.5, 198.91]]}, {"timestamp": 1578773685961, "ltp": 11.5, "tv": 9309.05, "trd": NaN, "batb": [[2, 10, 139.22]], "batl": NaN}, {"timestamp": 1578773689960, "ltp": 11.0, "tv": 9310.92, "trd": [[11, 1.87]], "batb": [[0, 11, 18.88]], "batl": NaN}, {"timestamp": 1578773694975, "ltp": 11.0, "tv": 9310.92, "trd": NaN, "batb": [[1, 10.5, 69.61]], "batl": NaN}, {"timestamp": 1578773697003, "ltp": 11.0, "tv": 9310.92, "trd": NaN, "batb": NaN, "batl": [[0, 11.5, 177.27]]}, {"timestamp": 1578773698001, "ltp": 11.0, "tv": 9310.92, "trd": NaN, "batb": NaN, "batl": [[1, 12, 442.45]]}, {"timestamp": 1578773699011, "ltp": 11.5, "tv": 9314.04, "trd": [[11.5, 124.44]], "batb": NaN, "batl": [[0, 11.5, 175.71]]}, {"timestamp": 1578773700967, "ltp": 11.5, "tv": 9314.04, "trd": NaN, "batb": [[0, 11, 14.77]], "batl": NaN}, {"timestamp": 1578773704014, "ltp": 11.5, "tv": 9314.04, "trd": NaN, "batb": NaN, "batl": [[0, 11.5, 183.37], [1, 12, 306.77]]}, {"timestamp": 1578773705030, "ltp": 11.5, "tv": 9314.04, "trd": NaN, "batb": NaN, "batl": [[1, 12, 171.09]]}, {"timestamp": 1578773705994, "ltp": 11.5, "tv": 9324.76, "trd": [[11.5, 135.16]], "batb": NaN, "batl": [[0, 11.5, 178.01]]}, {"timestamp": 1578773706995, "ltp": 11.0, "tv": 9344.75, "trd": [[11, 21.87]], "batb": [[0, 11, 4.77], [1, 10.5, 91.57]], "batl": NaN}, {"timestamp": 1578773710029, "ltp": 11.0, "tv": 9344.75, "trd": NaN, "batb": [[1, 10.5, 96.08]], "batl": NaN}, {"timestamp": 1578773712010, "ltp": 11.0, "tv": 9344.75, "trd": NaN, "batb": NaN, "batl": [[1, 12, 167.68]]}, {"timestamp": 1578773715022, "ltp": 11.5, "tv": 9345.86, "trd": [[11.5, 136.26]], "batb": NaN, "batl": [[0, 11.5, 177.46]]}, {"timestamp": 1578773719029, "ltp": 11.0, "tv": 9359.14, "trd": [[11, 35.15]], "batb": [[0, 10.5, 96.08], [1, 10, 139.22], [2, 9.8, 138.77]], "batl": [[0, 11.5, 180.87]]}, {"timestamp": 1578773720036, "ltp": 11.0, "tv": 9359.14, "trd": NaN, "batb": NaN, "batl": [[0, 11.5, 480.25]]}, {"timestamp": 1578773722040, "ltp": 11.0, "tv": 9359.14, "trd": NaN, "batb": [[1, 10, 127.89]], "batl": NaN}, {"timestamp": 1578773725043, "ltp": 11.0, "tv": 9359.14, "trd": NaN, "batb": [[0, 10.5, 69.55]], "batl": NaN}, {"timestamp": 1578773725958, "ltp": 11.0, "tv": 9359.14, "trd": NaN, "batb": NaN, "batl": [[0, 11, 5], [1, 11.5, 480.25], [2, 12, 167.68]]}, {"timestamp": 1578773727027, "ltp": 11.0, "tv": 9359.14, "trd": NaN, "batb": [[0, 10.5, 35.5]], "batl": [[2, 12, 131.19]]}, {"timestamp": 1578773729021, "ltp": 11.0, "tv": 9359.18, "trd": [[11, 35.19]], "batb": NaN, "batl": [[0, 11, 4.98]]}, {"timestamp": 1578773730038, "ltp": 11.0, "tv": 9359.18, "trd": NaN, "batb": NaN, "batl": [[0, 11, 6.98], [2, 12, 122.55]]}, {"timestamp": 1578773731041, "ltp": 11.0, "tv": 9359.18, "trd": NaN, "batb": NaN, "batl": [[2, 12, 92.76]]}, {"timestamp": 1578773732052, "ltp": 11.0, "tv": 9359.18, "trd": NaN, "batb": [[0, 10.5, 26.47]], "batl": NaN}, {"timestamp": 1578773733055, "ltp": 11.0, "tv": 9359.18, "trd": NaN, "batb": NaN, "batl": [[0, 11, 4.98]]}, {"timestamp": 1578773733959, "ltp": 11.0, "tv": 9359.18, "trd": NaN, "batb": [[0, 10.5, 8.76]], "batl": [[0, 11, 30.54]]}, {"timestamp": 1578773734962, "ltp": 11.0, "tv": 9359.18, "trd": NaN, "batb": NaN, "batl": [[0, 11, 41.54]]}, {"timestamp": 1578773737023, "ltp": 11.0, "tv": 9359.18, "trd": NaN, "batb": NaN, "batl": [[0, 11, 50.72], [2, 12, 19.76]]}, {"timestamp": 1578773738032, "ltp": 11.0, "tv": 9359.18, "trd": NaN, "batb": NaN, "batl": [[0, 11, 63.04]]}, {"timestamp": 1578773740032, "ltp": 11.0, "tv": 9359.18, "trd": NaN, "batb": [[1, 10, 75.89]], "batl": NaN}, {"timestamp": 1578773743959, "ltp": 11.0, "tv": 9359.18, "trd": NaN, "batb": NaN, "batl": [[0, 11, 160.04]]}, {"timestamp": 1578773744959, "ltp": 10.5, "tv": 9368.86, "trd": [[10.5, 9.68]], "batb": [[0, 10.5, 12.68], [1, 10, 87.22]], "batl": NaN}, {"timestamp": 1578773745971, "ltp": 10.5, "tv": 9368.86, "trd": NaN, "batb": [[0, 10.5, 3.93]], "batl": [[0, 11, 171.16]]}, {"timestamp": 1578773746966, "ltp": 10.5, "tv": 9368.86, "trd": NaN, "batb": [[1, 10, 75.89], [2, 9.8, 126.94]], "batl": [[0, 11, 180.43], [1, 11.5, 433.82]]}, {"timestamp": 1578773747974, "ltp": 10.5, "tv": 9377.78, "trd": [[10.5, 13.67], [11, 40.12]], "batb": [[0, 10.5, 1.93]], "batl": [[0, 11, 177.97], [1, 11.5, 425.06]]}, {"timestamp": 1578773748964, "ltp": 10.5, "tv": 9377.78, "trd": NaN, "batb": NaN, "batl": [[1, 11.5, 393.98]]}, {"timestamp": 1578773750980, "ltp": 10.5, "tv": 9377.78, "trd": NaN, "batb": [[1, 10, 94.8]], "batl": NaN}, {"timestamp": 1578773753962, "ltp": 10.5, "tv": 9387.09, "trd": [[10.5, 22.99]], "batb": [[0, 10, 94.8], [1, 9.8, 126.94], [2, 9.6, 201.16]], "batl": [[0, 11, 186.48]]}, {"timestamp": 1578773755014, "ltp": 10.5, "tv": 9390.67, "trd": [[10.5, 26.56]], "batb": NaN, "batl": NaN}, {"timestamp": 1578773755974, "ltp": 10.5, "tv": 9392.58, "trd": [[10.5, 28.48]], "batb": NaN, "batl": NaN}, {"timestamp": 1578773757984, "ltp": 10.5, "tv": 9392.58, "trd": NaN, "batb": NaN, "batl": [[1, 11.5, 386.31]]}, {"timestamp": 1578773760008, "ltp": 10.5, "tv": 9392.58, "trd": NaN, "batb": [[0, 10.5, 4.26], [1, 10, 94.8], [2, 9.8, 126.94]], "batl": NaN}, {"timestamp": 1578773762978, "ltp": 10.5, "tv": 9401.1, "trd": [[10.5, 36.99]], "batb": [[0, 10, 94.8], [1, 9.8, 126.94], [2, 9.6, 201.16]], "batl": [[0, 10.5, 43.07], [1, 11, 186.48], [2, 11.5, 386.31]]}, {"timestamp": 1578773763973, "ltp": 10.5, "tv": 9401.1, "trd": NaN, "batb": NaN, "batl": [[0, 11, 186.48], [1, 11.5, 386.31], [2, 12, 19.76]]}, {"timestamp": 1578773765033, "ltp": 10.5, "tv": 9401.1, "trd": NaN, "batb": NaN, "batl": [[0, 10.5, 34.05], [1, 11, 218.79], [2, 11.5, 386.31]]}, {"timestamp": 1578773766019, "ltp": 10.5, "tv": 9401.1, "trd": NaN, "batb": [[1, 9.8, 71.94], [2, 9.6, 148.84]], "batl": [[0, 11, 218.79], [1, 11.5, 386.31], [2, 12, 19.76]]}, {"timestamp": 1578773767975, "ltp": 10.5, "tv": 9401.1, "trd": NaN, "batb": [[0, 10, 75.89]], "batl": NaN}, {"timestamp": 1578773770987, "ltp": 10.5, "tv": 9401.1, "trd": NaN, "batb": [[0, 10, 40.14], [1, 9.8, 35.45]], "batl": [[0, 10.5, 2], [1, 11, 218.79], [2, 11.5, 386.31]]}, {"timestamp": 1578773773987, "ltp": 10.5, "tv": 9401.1, "trd": NaN, "batb": NaN, "batl": [[0, 10.5, 10.84]]}, {"timestamp": 1578773774989, "ltp": 10.5, "tv": 9412.9, "trd": [[10.5, 48.79]], "batb": NaN, "batl": [[0, 10.5, 4.95]]}, {"timestamp": 1578773775998, "ltp": 10.5, "tv": 9412.9, "trd": NaN, "batb": NaN, "batl": [[0, 10.5, 16.24]]}, {"timestamp": 1578773777005, "ltp": 10.5, "tv": 9412.9, "trd": NaN, "batb": [[0, 10, 31.35]], "batl": NaN}, {"timestamp": 1578773778016, "ltp": 10.5, "tv": 9412.9, "trd": NaN, "batb": [[0, 10, 3.83]], "batl": NaN}, {"timestamp": 1578773779009, "ltp": 10.5, "tv": 9412.9, "trd": NaN, "batb": [[0, 10, 39.58]], "batl": [[2, 11.5, 312.78]]}, {"timestamp": 1578773780008, "ltp": 10.5, "tv": 9412.9, "trd": NaN, "batb": [[0, 10, 3.83]], "batl": NaN}, {"timestamp": 1578773781023, "ltp": 10.5, "tv": 9412.9, "trd": NaN, "batb": [[1, 9.8, 53.04], [2, 9.6, 136.47]], "batl": [[0, 10.5, 50.29]]}, {"timestamp": 1578773782017, "ltp": 10.5, "tv": 9412.9, "trd": NaN, "batb": NaN, "batl": [[0, 10.5, 77.67]]}, {"timestamp": 1578773783027, "ltp": 10.5, "tv": 9412.9, "trd": NaN, "batb": NaN, "batl": [[0, 10.5, 81.78]]}, {"timestamp": 1578773784032, "ltp": 10.5, "tv": 9412.9, "trd": NaN, "batb": [[1, 9.8, 26.59]], "batl": NaN}, {"timestamp": 1578773786046, "ltp": 10.5, "tv": 9412.9, "trd": NaN, "batb": NaN, "batl": [[0, 10.5, 199.78], [2, 11.5, 173.91]]}, {"timestamp": 1578773789037, "ltp": 10.5, "tv": 9412.9, "trd": NaN, "batb": [[1, 9.8, 63.07]], "batl": NaN}, {"timestamp": 1578773790039, "ltp": 10.5, "tv": 9433.87, "trd": [[10.5, 69.77]], "batb": [[1, 9.8, 26.59]], "batl": [[0, 10.5, 215.61]]}, {"timestamp": 1578773790996, "ltp": 10.5, "tv": 9433.87, "trd": NaN, "batb": NaN, "batl": [[0, 10.5, 189.3]]}, {"timestamp": 1578773792040, "ltp": 10.5, "tv": 9433.87, "trd": NaN, "batb": [[2, 9.6, 154.55]], "batl": NaN}, {"timestamp": 1578773794034, "ltp": 10.5, "tv": 9457.5, "trd": [[10.5, 93.39]], "batb": NaN, "batl": [[0, 10.5, 177.48], [1, 11, 361.09]]}, {"timestamp": 1578773797039, "ltp": 10.5, "tv": 9457.5, "trd": NaN, "batb": [[0, 10, 8.08]], "batl": NaN}, {"timestamp": 1578773798037, "ltp": 10.5, "tv": 9457.5, "trd": NaN, "batb": NaN, "batl": [[0, 10.5, 186.42]]}, {"timestamp": 1578773799046, "ltp": 10.5, "tv": 9457.5, "trd": NaN, "batb": [[1, 9.8, 89.52]], "batl": [[2, 11.5, 35.04]]}, {"timestamp": 1578773801046, "ltp": 10.5, "tv": 9531.76, "trd": [[10, 50.64], [10.5, 117.01]], "batb": [[0, 9.8, 63.07], [1, 9.6, 154.55], [2, 9.4, 153.06]], "batl": [[0, 10.5, 185.32]]}, {"timestamp": 1578773802021, "ltp": 10.5, "tv": 9531.76, "trd": NaN, "batb": [[0, 9.8, 26.59], [1, 9.6, 156.56]], "batl": NaN}, {"timestamp": 1578773804033, "ltp": 10.5, "tv": 9531.76, "trd": NaN, "batb": [[1, 9.6, 98.56]], "batl": NaN}, {"timestamp": 1578773805029, "ltp": 10.5, "tv": 9531.76, "trd": NaN, "batb": [[1, 9.6, 33.95]], "batl": [[1, 11, 324.41]]}, {"timestamp": 1578773806034, "ltp": 10.5, "tv": 9531.76, "trd": NaN, "batb": [[0, 9.8, 17.59]], "batl": [[1, 11, 315.14]]}, {"timestamp": 1578773807027, "ltp": 10.5, "tv": 9531.76, "trd": NaN, "batb": NaN, "batl": [[1, 11, 282.64]]}, {"timestamp": 1578773809027, "ltp": 10.5, "tv": 9531.76, "trd": NaN, "batb": [[1, 9.6, 38.33]], "batl": NaN}, {"timestamp": 1578773810028, "ltp": 10.5, "tv": 9531.76, "trd": NaN, "batb": [[1, 9.6, 32.2]], "batl": NaN}, {"timestamp": 1578773812036, "ltp": 10.5, "tv": 9555.37, "trd": [[10.5, 140.62]], "batb": [[0, 9.6, 32.2], [1, 9.4, 153.06], [2, 9.2, 157.84]], "batl": [[0, 10, 47.83], [1, 10.5, 173.52], [2, 11, 282.64]]}, {"timestamp": 1578773813934, "ltp": 10.5, "tv": 9555.37, "trd": NaN, "batb": NaN, "batl": [[0, 10, 83.58]]}, {"timestamp": 1578773815035, "ltp": 10.0, "tv": 9578.99, "trd": [[10, 74.26]], "batb": NaN, "batl": [[0, 10, 71.77], [1, 10.5, 199.83]]}, {"timestamp": 1578773819046, "ltp": 10.0, "tv": 9578.99, "trd": NaN, "batb": NaN, "batl": [[2, 11, 424.94]]}, {"timestamp": 1578773821046, "ltp": 10.0, "tv": 9578.99, "trd": NaN, "batb": [[1, 9.4, 188.24]], "batl": NaN}, {"timestamp": 1578773823041, "ltp": 10.0, "tv": 9602.61, "trd": [[10, 97.88]], "batb": NaN, "batl": [[0, 10, 70.73]]}, {"timestamp": 1578773826976, "ltp": 10.0, "tv": 9627.58, "trd": [[10, 122.85]], "batb": NaN, "batl": [[0, 10, 58.24]]}, {"timestamp": 1578773828977, "ltp": 9.6, "tv": 9677.58, "trd": [[9.6, 50]], "batb": [[0, 9.6, 7.2]], "batl": NaN}, {"timestamp": 1578773831995, "ltp": 9.6, "tv": 9677.58, "trd": NaN, "batb": [[1, 9.4, 122.24]], "batl": NaN}, {"timestamp": 1578773833946, "ltp": 10.0, "tv": 9702.56, "trd": [[10, 147.83]], "batb": NaN, "batl": [[0, 10, 45.75]]}, {"timestamp": 1578773836002, "ltp": 10.0, "tv": 9702.56, "trd": NaN, "batb": NaN, "batl": [[2, 11, 429.2]]}, {"timestamp": 1578773839002, "ltp": 10.0, "tv": 9702.56, "trd": NaN, "batb": NaN, "batl": [[0, 10, 170.75], [2, 11, 420.69]]}, {"timestamp": 1578773839994, "ltp": 10.0, "tv": 9702.56, "trd": NaN, "batb": NaN, "batl": [[1, 10.5, 148.42]]}, {"timestamp": 1578773841023, "ltp": 10.0, "tv": 9702.56, "trd": NaN, "batb": [[1, 9.4, 109.31]], "batl": [[0, 10, 45.75]]}, {"timestamp": 1578773841986, "ltp": 10.0, "tv": 9702.56, "trd": NaN, "batb": [[0, 9.6, 28.48], [1, 9.4, 71.28]], "batl": [[0, 10, 55.12]]}, {"timestamp": 1578773842969, "ltp": 10.0, "tv": 9702.56, "trd": NaN, "batb": NaN, "batl": [[0, 10, 82.92]]}, {"timestamp": 1578773844974, "ltp": 9.4, "tv": 9927.06, "trd": [[9.4, 142.56], [9.6, 106.96], [10, 172.81]], "batb": [[0, 9.2, 157.84], [1, 9, 287.51], [2, 8.8, 169.45]], "batl": [[0, 9.4, 2.38], [1, 10, 70.43], [2, 10.5, 148.42]]}, {"timestamp": 1578773846008, "ltp": 9.4, "tv": 9927.06, "trd": NaN, "batb": [[1, 9, 231.26]], "batl": [[1, 9.8, 36.48], [2, 10, 70.43]]}, {"timestamp": 1578773847008, "ltp": 9.4, "tv": 9927.06, "trd": NaN, "batb": NaN, "batl": [[1, 9.8, 51.51]]}, {"timestamp": 1578773848001, "ltp": 9.4, "tv": 9931.82, "trd": [[9.4, 147.32]], "batb": [[0, 9.4, 10.55], [1, 9.2, 157.84], [2, 9, 231.26]], "batl": [[0, 9.8, 13.87], [1, 10, 70.43], [2, 10.5, 156.93]]}, {"timestamp": 1578773848996, "ltp": 9.8, "tv": 9956.8, "trd": [[9.8, 24.98]], "batb": [[0, 9.2, 157.84], [1, 9, 231.26], [2, 8.8, 169.45]], "batl": [[0, 9.8, 1.38], [2, 10.5, 130.62]]}, {"timestamp": 1578773851828, "ltp": 9.8, "tv": 9956.91, "trd": [[9.8, 25.08]], "batb": NaN, "batl": [[0, 9.8, 1.33]]}, {"timestamp": 1578773852995, "ltp": 9.8, "tv": 9956.91, "trd": NaN, "batb": [[0, 9.4, 9.24], [1, 9.2, 157.84], [2, 9, 231.26]], "batl": NaN}, {"timestamp": 1578773854024, "ltp": 9.8, "tv": 9956.91, "trd": NaN, "batb": [[0, 9.2, 157.84], [1, 9, 231.26], [2, 8.8, 169.45]], "batl": NaN}, {"timestamp": 1578773856031, "ltp": 10.0, "tv": 9981.88, "trd": [[9.8, 27.74], [10, 195.13]], "batb": NaN, "batl": [[0, 10, 59.27], [1, 10.5, 130.62], [2, 11, 420.69]]}, {"timestamp": 1578773859019, "ltp": 10.0, "tv": 9981.88, "trd": NaN, "batb": [[2, 8.8, 194.59]], "batl": NaN}, {"timestamp": 1578773866034, "ltp": 10.0, "tv": 9981.88, "trd": NaN, "batb": NaN, "batl": [[2, 11, 136.09]]}, {"timestamp": 1578773867033, "ltp": 10.0, "tv": 10006.86, "trd": [[10, 220.1]], "batb": NaN, "batl": [[0, 9.8, 21.28], [1, 10, 68.06], [2, 10.5, 156.93]]}, {"timestamp": 1578773868035, "ltp": 10.0, "tv": 10006.86, "trd": NaN, "batb": [[0, 9.4, 2.46], [1, 9.2, 157.84], [2, 9, 231.26]], "batl": NaN}, {"timestamp": 1578773869028, "ltp": 9.4, "tv": 10009.33, "trd": [[9.4, 149.79]], "batb": [[0, 9.2, 157.84], [1, 9, 231.26], [2, 8.8, 194.59]], "batl": NaN}, {"timestamp": 1578773874046, "ltp": 10.0, "tv": 10059.07, "trd": [[9.4, 150.01], [9.8, 70.31], [10, 227.07]], "batb": NaN, "batl": [[0, 9.8, 8.72], [1, 10, 100.33], [2, 10.5, 448.91]]}, {"timestamp": 1578773875033, "ltp": 9.2, "tv": 10076.09, "trd": [[9.2, 17.02]], "batb": [[0, 9.2, 149.33]], "batl": [[0, 9.8, 19.51]]}, {"timestamp": 1578773883846, "ltp": 9.2, "tv": 10076.09, "trd": NaN, "batb": [[0, 9.2, 170.61], [1, 9, 175.01]], "batl": [[2, 10.5, 156.93]]}, {"timestamp": 1578773885844, "ltp": 9.8, "tv": 10087.59, "trd": [[9.8, 81.81]], "batb": NaN, "batl": [[0, 9.8, 13.76], [1, 10, 226.33]]}, {"timestamp": 1578773887055, "ltp": 9.8, "tv": 10087.59, "trd": NaN, "batb": [[0, 9.2, 175.45]], "batl": NaN}, {"timestamp": 1578773890049, "ltp": 9.8, "tv": 10111.87, "trd": [[9.8, 106.09]], "batb": NaN, "batl": [[0, 9.8, 1.62]]}, {"timestamp": 1578773891971, "ltp": 9.8, "tv": 10111.87, "trd": NaN, "batb": [[2, 8.8, 252.28]], "batl": NaN}, {"timestamp": 1578773893966, "ltp": 9.8, "tv": 10111.87, "trd": NaN, "batb": [[0, 9.2, 115.96]], "batl": [[0, 9.8, 65.97]]}, {"timestamp": 1578773894963, "ltp": 9.8, "tv": 10111.87, "trd": NaN, "batb": [[0, 9.2, 48.74]], "batl": [[0, 9.6, 4.84], [1, 9.8, 65.97], [2, 10, 226.33]]}, {"timestamp": 1578773896056, "ltp": 9.8, "tv": 10111.87, "trd": NaN, "batb": [[0, 9.4, 20], [1, 9.2, 48.74], [2, 9, 175.01]], "batl": NaN}, {"timestamp": 1578773896958, "ltp": 9.8, "tv": 10136.15, "trd": [[9.6, 116.64], [9.8, 120.68]], "batb": NaN, "batl": [[0, 9.8, 67.77], [1, 10, 220.19], [2, 10.5, 156.93]]}, {"timestamp": 1578773897962, "ltp": 9.8, "tv": 10136.15, "trd": NaN, "batb": [[1, 9.2, 35.19]], "batl": NaN}, {"timestamp": 1578773899954, "ltp": 9.8, "tv": 10136.15, "trd": NaN, "batb": NaN, "batl": [[2, 10.5, 448.91]]}, {"timestamp": 1578773901053, "ltp": 9.8, "tv": 10136.15, "trd": NaN, "batb": NaN, "batl": [[2, 10.5, 444.8]]}, {"timestamp": 1578773901996, "ltp": 9.8, "tv": 10161.12, "trd": [[9.8, 145.66]], "batb": NaN, "batl": [[0, 9.8, 55.29]]}, {"timestamp": 1578773903978, "ltp": 9.8, "tv": 10161.12, "trd": NaN, "batb": [[1, 9.2, 101.55]], "batl": NaN}, {"timestamp": 1578773904973, "ltp": 9.4, "tv": 10167.21, "trd": [[9.4, 156.1]], "batb": [[0, 9.4, 13.91], [1, 9.2, 35.19], [2, 9, 179.85]], "batl": NaN}, {"timestamp": 1578773906981, "ltp": 9.4, "tv": 10170.95, "trd": [[9.4, 159.84]], "batb": [[0, 9.4, 12.04]], "batl": NaN}, {"timestamp": 1578773907977, "ltp": 9.4, "tv": 10170.95, "trd": NaN, "batb": NaN, "batl": [[2, 10.5, 453.31]]}, {"timestamp": 1578773908968, "ltp": 9.8, "tv": 10196.51, "trd": [[9.8, 171.22]], "batb": NaN, "batl": [[0, 9.8, 42.51]]}, {"timestamp": 1578773911002, "ltp": 9.8, "tv": 10196.51, "trd": NaN, "batb": [[2, 9, 165.65]], "batl": NaN}, {"timestamp": 1578773911996, "ltp": 9.8, "tv": 10196.51, "trd": NaN, "batb": NaN, "batl": [[0, 9.8, 53.41]]}, {"timestamp": 1578773913990, "ltp": 9.8, "tv": 10196.51, "trd": NaN, "batb": NaN, "batl": [[2, 10.5, 457.57]]}, {"timestamp": 1578773915001, "ltp": 9.8, "tv": 10196.51, "trd": NaN, "batb": NaN, "batl": [[1, 10, 94.19], [2, 10.5, 339.57]]}, {"timestamp": 1578773915987, "ltp": 9.8, "tv": 10196.51, "trd": NaN, "batb": NaN, "batl": [[0, 9.8, 20]]}, {"timestamp": 1578773916981, "ltp": 9.4, "tv": 10202.63, "trd": [[9.4, 165.96]], "batb": [[0, 9.4, 8.98]], "batl": NaN}, {"timestamp": 1578773918974, "ltp": 9.4, "tv": 10220.59, "trd": [[9.4, 183.92]], "batb": [[0, 9.2, 35.19], [1, 9, 165.65], [2, 8.8, 194.59]], "batl": [[0, 9.4, 76.14], [1, 9.8, 20], [2, 10, 94.19]]}, {"timestamp": 1578773919970, "ltp": 9.4, "tv": 10246.15, "trd": [[9.4, 209.47]], "batb": [[0, 9.2, 26.12]], "batl": [[0, 9.4, 148.48], [1, 9.6, 127.68], [2, 9.8, 20]]}, {"timestamp": 1578773921999, "ltp": 9.4, "tv": 10246.15, "trd": NaN, "batb": NaN, "batl": [[2, 9.8, 10.9]]}, {"timestamp": 1578773923985, "ltp": 9.4, "tv": 10271.7, "trd": [[9.4, 235.03]], "batb": NaN, "batl": [[0, 9.4, 135.71]]}, {"timestamp": 1578773925985, "ltp": 9.4, "tv": 10271.7, "trd": NaN, "batb": [[1, 9, 87.65]], "batl": NaN}, {"timestamp": 1578773926974, "ltp": 9.4, "tv": 10271.7, "trd": NaN, "batb": NaN, "batl": [[0, 9.4, 174.36]]}, {"timestamp": 1578773928022, "ltp": 9.4, "tv": 10271.7, "trd": NaN, "batb": NaN, "batl": [[1, 9.6, 174.33]]}, {"timestamp": 1578773929026, "ltp": 9.4, "tv": 10271.7, "trd": NaN, "batb": NaN, "batl": [[0, 9.4, 183.6]]}, {"timestamp": 1578773931020, "ltp": 9.4, "tv": 10297.28, "trd": [[9.4, 260.61]], "batb": NaN, "batl": [[0, 9.4, 170.81]]}, {"timestamp": 1578773933029, "ltp": 9.2, "tv": 10323.28, "trd": [[9.2, 43.02]], "batb": [[0, 9.2, 13.12]], "batl": [[1, 9.6, 232.33], [2, 9.8, 66.9]]}, {"timestamp": 1578773933994, "ltp": 9.2, "tv": 10323.28, "trd": NaN, "batb": [[1, 9, 19.77]], "batl": [[0, 9.4, 210.71]]}, {"timestamp": 1578773935038, "ltp": 9.4, "tv": 10348.86, "trd": [[9.4, 286.19]], "batb": NaN, "batl": [[0, 9.4, 197.92]]}, {"timestamp": 1578773937999, "ltp": 9.4, "tv": 10354.86, "trd": [[9.4, 292.19]], "batb": NaN, "batl": [[0, 9.4, 194.92]]}, {"timestamp": 1578773941006, "ltp": 9.4, "tv": 10354.86, "trd": NaN, "batb": NaN, "batl": [[2, 9.8, 78.73]]}, {"timestamp": 1578773942052, "ltp": 9.4, "tv": 10354.86, "trd": NaN, "batb": NaN, "batl": [[2, 9.8, 66.9]]}, {"timestamp": 1578773943007, "ltp": 9.4, "tv": 10380.44, "trd": [[9.4, 317.77]], "batb": NaN, "batl": [[0, 9.4, 182.13]]}, {"timestamp": 1578773944004, "ltp": 9.4, "tv": 10380.44, "trd": NaN, "batb": [[2, 8.8, 116.59]], "batl": NaN}, {"timestamp": 1578773945045, "ltp": 9.4, "tv": 10380.44, "trd": NaN, "batb": NaN, "batl": [[0, 9.4, 180.26]]}, {"timestamp": 1578773946042, "ltp": 9.4, "tv": 10406.02, "trd": [[9.4, 343.35]], "batb": NaN, "batl": [[0, 9.4, 167.48]]}, {"timestamp": 1578773947044, "ltp": 9.4, "tv": 10406.02, "trd": NaN, "batb": [[2, 8.8, 101.69]], "batl": NaN}, {"timestamp": 1578773949037, "ltp": 9.4, "tv": 10406.02, "trd": NaN, "batb": NaN, "batl": [[2, 9.8, 78.73]]}, {"timestamp": 1578773952017, "ltp": 9.2, "tv": 10409.76, "trd": [[9.2, 46.76]], "batb": [[0, 9.2, 11.25], [2, 8.8, 61.07]], "batl": NaN}, {"timestamp": 1578773953034, "ltp": 9.2, "tv": 10409.76, "trd": NaN, "batb": [[2, 8.8, 34.27]], "batl": NaN}, {"timestamp": 1578773954022, "ltp": 9.4, "tv": 10435.34, "trd": [[9.4, 368.93]], "batb": NaN, "batl": [[0, 9.4, 154.68]]}, {"timestamp": 1578773954959, "ltp": 9.4, "tv": 10444.59, "trd": [[9.4, 378.17]], "batb": NaN, "batl": [[0, 9.4, 150.06]]}, {"timestamp": 1578773957959, "ltp": 9.4, "tv": 10470.17, "trd": [[9.4, 403.76]], "batb": NaN, "batl": [[0, 9.4, 128.03], [2, 9.8, 66.9]]}, {"timestamp": 1578773958961, "ltp": 9.4, "tv": 10470.17, "trd": NaN, "batb": NaN, "batl": [[0, 9.4, 51.34]]}, {"timestamp": 1578773962954, "ltp": 9.2, "tv": 10492.67, "trd": [[9.2, 69.26]], "batb": [[0, 9, 19.77], [1, 8.8, 34.27], [2, 8.6, 177.84]], "batl": [[0, 9.2, 26.12], [1, 9.4, 51.34], [2, 9.6, 232.33]]}, {"timestamp": 1578773965050, "ltp": 9.2, "tv": 10518.25, "trd": [[9.2, 94.84]], "batb": NaN, "batl": [[0, 9.2, 13.33]]}, {"timestamp": 1578773965995, "ltp": 9.2, "tv": 10518.25, "trd": NaN, "batb": [[0, 9, 10.67]], "batl": [[2, 9.6, 243.96]]}, {"timestamp": 1578773966956, "ltp": 9.2, "tv": 10518.25, "trd": NaN, "batb": NaN, "batl": [[0, 9.4, 51.34], [1, 9.6, 271.33], [2, 9.8, 56]]}, {"timestamp": 1578773969054, "ltp": 9.4, "tv": 10518.43, "trd": [[9.4, 403.94]], "batb": NaN, "batl": [[0, 9.4, 79.83]]}, {"timestamp": 1578773970056, "ltp": 9.4, "tv": 10518.43, "trd": NaN, "batb": NaN, "batl": [[0, 9.4, 142.83]]}, {"timestamp": 1578773970990, "ltp": 9.4, "tv": 10518.43, "trd": NaN, "batb": NaN, "batl": [[0, 9.4, 180.86], [1, 9.6, 243.96], [2, 9.8, 60.84]]}, {"timestamp": 1578773971992, "ltp": 9.4, "tv": 10518.54, "trd": [[9.4, 404.05]], "batb": NaN, "batl": [[0, 9.2, 11.7], [1, 9.4, 180.81], [2, 9.6, 243.96]]}, {"timestamp": 1578773972981, "ltp": 9.4, "tv": 10518.54, "trd": NaN, "batb": NaN, "batl": [[1, 9.4, 189.67]]}, {"timestamp": 1578773975977, "ltp": 9.2, "tv": 10541.93, "trd": [[9.2, 118.24]], "batb": [[0, 9.2, 5.32], [1, 9, 134.84], [2, 8.8, 34.27]], "batl": [[0, 9.4, 189.67], [1, 9.6, 243.96], [2, 9.8, 228.88]]}, {"timestamp": 1578773977971, "ltp": 9.2, "tv": 10552.57, "trd": [[9.2, 128.88]], "batb": [[0, 9, 134.84], [1, 8.8, 34.27], [2, 8.6, 177.84]], "batl": NaN}, {"timestamp": 1578773980054, "ltp": 9.4, "tv": 10585.48, "trd": [[9.4, 436.95]], "batb": NaN, "batl": [[0, 9.4, 173.21]]}, {"timestamp": 1578773981987, "ltp": 9.0, "tv": 10698.87, "trd": [[9, 113.4]], "batb": [[0, 9, 78.14]], "batl": NaN}, {"timestamp": 1578773982995, "ltp": 9.0, "tv": 10698.87, "trd": NaN, "batb": [[1, 8.8, 62.79]], "batl": NaN}, {"timestamp": 1578773983982, "ltp": 9.4, "tv": 10712.49, "trd": [[9.4, 450.57]], "batb": [[1, 8.8, 103.42]], "batl": [[0, 9.4, 178.07]]}, {"timestamp": 1578773984979, "ltp": 9.4, "tv": 10712.49, "trd": NaN, "batb": NaN, "batl": [[0, 9.2, 1.53], [1, 9.4, 178.07], [2, 9.6, 243.96]]}, {"timestamp": 1578773986984, "ltp": 9.4, "tv": 10739.95, "trd": [[9.2, 132.39], [9.4, 474.51]], "batb": [[0, 9.2, 8.86], [1, 9, 78.14], [2, 8.8, 103.42]], "batl": [[0, 9.4, 166.11], [1, 9.6, 232.33], [2, 9.8, 228.88]]}, {"timestamp": 1578773988969, "ltp": 9.4, "tv": 10739.95, "trd": NaN, "batb": NaN, "batl": [[1, 9.6, 244.7]]}, {"timestamp": 1578773991010, "ltp": 9.4, "tv": 10772.85, "trd": [[9.4, 507.4]], "batb": NaN, "batl": [[0, 9.4, 149.66]]}, {"timestamp": 1578773992010, "ltp": 9.4, "tv": 10772.85, "trd": NaN, "batb": NaN, "batl": [[2, 9.8, 380.57]]}, {"timestamp": 1578773993989, "ltp": 9.2, "tv": 10794.1, "trd": [[9.2, 150.11], [9.4, 510.94]], "batb": [[0, 9, 78.14], [1, 8.8, 103.42], [2, 8.6, 93.84]], "batl": [[0, 9.2, 2.36], [1, 9.4, 147.89], [2, 9.6, 244.7]]}, {"timestamp": 1578773994982, "ltp": 9.2, "tv": 10794.1, "trd": NaN, "batb": NaN, "batl": [[0, 9.2, 5.42]]}, {"timestamp": 1578773996012, "ltp": 9.2, "tv": 10794.78, "trd": [[9.2, 150.79]], "batb": [[2, 8.6, 78.18]], "batl": [[0, 9.2, 5.08]]}, {"timestamp": 1578773998010, "ltp": 9.4, "tv": 10828.18, "trd": [[9.2, 160.95], [9.4, 534.18]], "batb": NaN, "batl": [[0, 9.4, 136.27], [1, 9.6, 244.7], [2, 9.8, 371.21]]}, {"timestamp": 1578773998994, "ltp": 9.4, "tv": 10828.18, "trd": NaN, "batb": NaN, "batl": [[0, 9.2, 4.05], [1, 9.4, 136.27], [2, 9.6, 244.7]]}, {"timestamp": 1578774000989, "ltp": 9.0, "tv": 10828.69, "trd": [[9, 113.91]], "batb": [[0, 9, 77.89]], "batl": NaN}, {"timestamp": 1578774003027, "ltp": 9.0, "tv": 10828.69, "trd": NaN, "batb": [[0, 9, 120.45]], "batl": NaN}, {"timestamp": 1578774003997, "ltp": 9.0, "tv": 10828.69, "trd": NaN, "batb": NaN, "batl": [[2, 9.6, 254.06]]}, {"timestamp": 1578774005003, "ltp": 9.0, "tv": 10828.69, "trd": NaN, "batb": NaN, "batl": [[2, 9.6, 263.42]]}, {"timestamp": 1578774006024, "ltp": 9.0, "tv": 10828.69, "trd": NaN, "batb": NaN, "batl": [[0, 9.2, 15.03]]}, {"timestamp": 1578774007023, "ltp": 9.2, "tv": 10828.99, "trd": [[9.2, 161.25]], "batb": NaN, "batl": [[0, 9.2, 14.88]]}, {"timestamp": 1578774008015, "ltp": 9.2, "tv": 10841.06, "trd": [[9, 125.95], [9.2, 161.28]], "batb": [[0, 9, 108.41]], "batl": [[0, 9.2, 14.86]]}, {"timestamp": 1578774009010, "ltp": 9.2, "tv": 10872.37, "trd": [[9.2, 192.59]], "batb": NaN, "batl": [[0, 9.4, 136.27], [1, 9.6, 263.42], [2, 9.8, 219.52]]}, {"timestamp": 1578774012022, "ltp": 9.0, "tv": 10873.39, "trd": [[9, 126.97]], "batb": [[0, 9, 107.9]], "batl": NaN}, {"timestamp": 1578774012910, "ltp": 9.2, "tv": 10889.84, "trd": [[9.2, 209.04]], "batb": NaN, "batl": NaN}, {"timestamp": 1578774014008, "ltp": 9.2, "tv": 10889.84, "trd": NaN, "batb": NaN, "batl": [[1, 9.6, 416.86]]}, {"timestamp": 1578774016016, "ltp": 9.2, "tv": 10889.84, "trd": NaN, "batb": NaN, "batl": [[0, 9.2, 36.44], [1, 9.4, 136.27], [2, 9.6, 416.86]]}, {"timestamp": 1578774019014, "ltp": 9.2, "tv": 10889.84, "trd": NaN, "batb": NaN, "batl": [[0, 9.2, 11.34]]}, {"timestamp": 1578774019955, "ltp": 9.2, "tv": 10889.84, "trd": NaN, "batb": NaN, "batl": [[0, 9.4, 136.27], [1, 9.6, 416.86], [2, 9.8, 219.52]]}, {"timestamp": 1578774021024, "ltp": 9.2, "tv": 10889.84, "trd": NaN, "batb": NaN, "batl": [[0, 9.2, 127.68], [1, 9.4, 136.27], [2, 9.6, 416.86]]}, {"timestamp": 1578774028044, "ltp": 9.2, "tv": 10889.84, "trd": NaN, "batb": NaN, "batl": [[0, 9.2, 195.68], 