{"info": {"id": "1.166703732", "eventId": "29632571", "eventName": "Over/Under 0.5 Goals", "marketType": "OVER_UNDER_05", "openDate": 1578772101023, "name": "Inter v Atalanta", "numberOfActiveRunner": 2, "countryCode": "", "sport": "TENNIS", "venue": "", "volume": {"total": 41315.59, "preMatch": 29607.87, "inPlay": 11707.72}, "winner": {"id": 5851483, "name": "Over 0.5 Goals", "status": "WINNER", "position": 2}, "delay": 7}, "runners": [{"id": 5851482, "name": "Under 0.5 Goals", "status": "LOSER", "position": 1, "inPlayOdds": 19.5, "inPlayTime": 1578772101023, "avgPrematch": 19.28, "closedOdds": 19.0, "maxPrematch": 21.0, "minPrematch": 17.5, "maxInPlay": 19.5, "minInPlay": 19.0, "inPlayIndex": 319, "lengthOdds": 399, "lengthOddsPrematch": 319, "lengthOddsInPlay": 80, "tradedVolume": 3768.89, "preMatchVolume": 2985.77, "inPlayVolume": 783.12}, {"id": 5851483, "name": "Over 0.5 Goals", "status": "WINNER", "position": 2, "inPlayOdds": 1.06, "inPlayTime": 1578772101023, "avgPrematch": 1.05, "closedOdds": 1.05, "maxPrematch": 1.06, "minPrematch": 1.04, "maxInPlay": 1.06, "minInPlay": 1.05, "inPlayIndex": 349, "lengthOdds": 437, "lengthOddsPrematch": 349, "lengthOddsInPlay": 88, "tradedVolume": 37546.7, "preMatchVolume": 26622.1, "inPlayVolume": 10924.6}], "marketUpdates": [{"timestamp": 1578513294362000000, "openDate": "2020-01-11T19:45:00.000Z", "status": "OPEN", "betDelay": 0, "inPlay": false, "complete": true}, {"timestamp": 1578772101023000000, "openDate": "2020-01-11T19:45:00.000Z", "status": "OPEN", "betDelay": 7, "inPlay": true, "complete": true}, {"timestamp": 1578772294860000000, "openDate": "2020-01-11T19:45:00.000Z", "status": "SUSPENDED", "betDelay": 7, "inPlay": true, "complete": true}, {"timestamp": 1578772415025000000, "openDate": "2020-01-11T19:45:00.000Z", "status": "CLOSED", "betDelay": 7, "inPlay": true, "complete": true}], "odds": [{"runnerId": 5851482, "odds": [{"timestamp": 1578755283459, "ltp": 17.5, "tv": 1.86, "trd": [[17.5, 1.87]], "batb": NaN, "batl": NaN}, {"timestamp": 1578759816982, "ltp": 17.5, "tv": 1.86, "trd": NaN, "batb": [[2, 1.01, 109.82]], "batl": NaN}, {"timestamp": 1578759817964, "ltp": 17.5, "tv": 1.86, "trd": NaN, "batb": [[2, 1.01, 107.39]], "batl": NaN}, {"timestamp": 1578759818797, "ltp": 17.5, "tv": 1.86, "trd": NaN, "batb": [[0, 14.5, 10.21], [2, 1.01, 107.18]], "batl": [[1, 1000, 2.64]]}, {"timestamp": 1578759820005, "ltp": 17.5, "tv": 1.86, "trd": NaN, "batb": NaN, "batl": [[1, 1000, 0.63]]}, {"timestamp": 1578759820976, "ltp": 17.5, "tv": 1.86, "trd": NaN, "batb": NaN, "batl": [[0, 55, 3.63], [1, 1000, 0]]}, {"timestamp": 1578762045037, "ltp": 17.5, "tv": 1.86, "trd": NaN, "batb": [[0, 18, 2.64], [1, 14.5, 10.21], [2, 1.02, 107.18]], "batl": NaN}, {"timestamp": 1578762055042, "ltp": 17.5, "tv": 1.86, "trd": NaN, "batb": [[1, 14, 10.21]], "batl": NaN}, {"timestamp": 1578762064732, "ltp": 17.5, "tv": 1.86, "trd": NaN, "batb": [[1, 13.5, 10.21]], "batl": NaN}, {"timestamp": 1578762455014, "ltp": 17.5, "tv": 1.86, "trd": NaN, "batb": [[1, 16, 2.63], [2, 13.5, 10]], "batl": NaN}, {"timestamp": 1578763040003, "ltp": 17.5, "tv": 1.86, "trd": NaN, "batb": [[1, 16, 2.42]], "batl": NaN}, {"timestamp": 1578763041899, "ltp": 17.5, "tv": 1.86, "trd": NaN, "batb": [[1, 16, 2.68]], "batl": NaN}, {"timestamp": 1578763042895, "ltp": 17.5, "tv": 1.86, "trd": NaN, "batb": NaN, "batl": [[0, 55, 3], [1, 1000, 2.64]]}, {"timestamp": 1578763043813, "ltp": 17.5, "tv": 1.86, "trd": NaN, "batb": NaN, "batl": [[1, 1000, 0.95]]}, {"timestamp": 1578763044442, "ltp": 17.5, "tv": 1.86, "trd": NaN, "batb": NaN, "batl": [[0, 55, 3.95], [1, 1000, 0]]}, {"timestamp": 1578763838110, "ltp": 17.5, "tv": 1.86, "trd": NaN, "batb": [[1, 13.5, 10.26], [2, 1.02, 107.18]], "batl": NaN}, {"timestamp": 1578763887310, "ltp": 17.5, "tv": 1.86, "trd": NaN, "batb": [[0, 13.5, 10.26], [1, 1.02, 107.18], [2, 1.01, 107.18]], "batl": NaN}, {"timestamp": 1578763945988, "ltp": 17.5, "tv": 1.86, "trd": NaN, "batb": [[0, 18, 2.64], [1, 13.5, 10.26], [2, 1.02, 107.18]], "batl": NaN}, {"timestamp": 1578764009878, "ltp": 17.5, "tv": 1.86, "trd": NaN, "batb": [[0, 13.5, 10.26], [1, 1.02, 107.18], [2, 1.01, 107.18]], "batl": NaN}, {"timestamp": 1578764070874, "ltp": 17.5, "tv": 1.86, "trd": NaN, "batb": [[0, 18, 2.64], [1, 13.5, 10.26], [2, 1.02, 107.18]], "batl": NaN}, {"timestamp": 1578764115941, "ltp": 17.5, "tv": 1.86, "trd": NaN, "batb": [[0, 18, 19.48]], "batl": NaN}, {"timestamp": 1578764119044, "ltp": 17.5, "tv": 1.86, "trd": NaN, "batb": [[1, 1.02, 107.44], [2, 1.01, 107.18]], "batl": NaN}, {"timestamp": 1578764614974, "ltp": 17.5, "tv": 1.86, "trd": NaN, "batb": NaN, "batl": [[0, 20, 22.2], [1, 55, 3.95]]}, {"timestamp": 1578764639003, "ltp": 17.5, "tv": 1.86, "trd": NaN, "batb": NaN, "batl": [[0, 20, 24.84]]}, {"timestamp": 1578764874438, "ltp": 17.5, "tv": 1.86, "trd": NaN, "batb": [[0, 18, 16.84]], "batl": [[0, 20, 22.2]]}, {"timestamp": 1578764883948, "ltp": 17.5, "tv": 1.86, "trd": NaN, "batb": [[0, 18, 19.48]], "batl": [[0, 20, 24.84]]}, {"timestamp": 1578765006896, "ltp": 17.5, "tv": 1.86, "trd": NaN, "batb": NaN, "batl": [[0, 20, 109.96]]}, {"timestamp": 1578765008000, "ltp": 17.5, "tv": 1.86, "trd": NaN, "batb": NaN, "batl": [[0, 19.5, 8.51], [1, 20, 109.96], [2, 55, 3.95]]}, {"timestamp": 1578765126528, "ltp": 19.5, "tv": 18.7, "trd": [[19.5, 16.84]], "batb": NaN, "batl": [[0, 20, 110.05], [1, 55, 3.95], [2, 55, 0]]}, {"timestamp": 1578765127925, "ltp": 19.5, "tv": 18.7, "trd": NaN, "batb": [[0, 18, 28.6]], "batl": [[0, 20, 109.96]]}, {"timestamp": 1578765256861, "ltp": 19.5, "tv": 18.7, "trd": NaN, "batb": NaN, "batl": [[0, 19.5, 22.2], [1, 20, 87.76], [2, 55, 3.95]]}, {"timestamp": 1578765690034, "ltp": 19.5, "tv": 18.7, "trd": NaN, "batb": NaN, "batl": [[1, 20, 85.12]]}, {"timestamp": 1578765751030, "ltp": 19.5, "tv": 18.7, "trd": NaN, "batb": NaN, "batl": [[0, 19, 22.2]]}, {"timestamp": 1578765803089, "ltp": 19.0, "tv": 30.95, "trd": [[19, 12.25]], "batb": NaN, "batl": [[0, 19, 16.08]]}, {"timestamp": 1578765970033, "ltp": 19.0, "tv": 30.95, "trd": NaN, "batb": NaN, "batl": [[1, 20, 103], [2, 21, 17.02]]}, {"timestamp": 1578765972005, "ltp": 19.0, "tv": 30.95, "trd": NaN, "batb": [[0, 18, 48.46], [1, 17.5, 20.43], [2, 15, 24.1]], "batl": NaN}, {"timestamp": 1578766190517, "ltp": 19.0, "tv": 63.11, "trd": [[19, 44.4]], "batb": NaN, "batl": [[0, 20, 103], [1, 21, 17.02], [2, 25, 15.25]]}, {"timestamp": 1578766321716, "ltp": 19.0, "tv": 63.11, "trd": NaN, "batb": [[0, 18.5, 22.2], [1, 18, 48.46], [2, 17.5, 20.43]], "batl": NaN}, {"timestamp": 1578766341050, "ltp": 20.0, "tv": 67.11, "trd": [[20, 4]], "batb": NaN, "batl": [[0, 20, 101]]}, {"timestamp": 1578766373888, "ltp": 20.0, "tv": 67.11, "trd": NaN, "batb": NaN, "batl": [[0, 19.5, 15], [1, 20, 101], [2, 21, 17.02]]}, {"timestamp": 1578766381888, "ltp": 20.0, "tv": 67.11, "trd": NaN, "batb": [[0, 19, 2.1], [1, 18.5, 22.2], [2, 18, 48.46]], "batl": NaN}, {"timestamp": 1578766566717, "ltp": 19.5, "tv": 90.38, "trd": [[19.5, 40.12]], "batb": NaN, "batl": [[0, 19.5, 3.36]]}, {"timestamp": 1578766567795, "ltp": 19.5, "tv": 90.38, "trd": NaN, "batb": NaN, "batl": [[1, 20, 83.12]]}, {"timestamp": 1578766568541, "ltp": 19.5, "tv": 93.74, "trd": [[19.5, 43.48]], "batb": NaN, "batl": [[0, 19.5, 1.68]]}, {"timestamp": 1578766571757, "ltp": 19.5, "tv": 96.76, "trd": [[19.5, 46.49]], "batb": [[2, 18, 45.82]], "batl": [[0, 20, 83.29], [1, 21, 17.02], [2, 25, 15.25]]}, {"timestamp": 1578766591042, "ltp": 19.5, "tv": 96.76, "trd": NaN, "batb": [[1, 18.5, 24.84]], "batl": NaN}, {"timestamp": 1578766628009, "ltp": 19.5, "tv": 96.76, "trd": NaN, "batb": [[1, 18.5, 22.2]], "batl": NaN}, {"timestamp": 1578766642726, "ltp": 19.5, "tv": 96.76, "trd": NaN, "batb": [[1, 18.5, 24.84]], "batl": NaN}, {"timestamp": 1578766732056, "ltp": 19.5, "tv": 96.76, "trd": NaN, "batb": [[0, 19, 36.55]], "batl": NaN}, {"timestamp": 1578766733755, "ltp": 19.5, "tv": 96.76, "trd": NaN, "batb": [[0, 19, 55.37], [1, 18.5, 44.16]], "batl": NaN}, {"timestamp": 1578766736026, "ltp": 19.5, "tv": 96.76, "trd": NaN, "batb": [[0, 19, 64.01], [2, 18, 36.7]], "batl": NaN}, {"timestamp": 1578766738844, "ltp": 19.5, "tv": 96.76, "trd": NaN, "batb": [[0, 19, 66.65], [1, 18.5, 41.52]], "batl": NaN}, {"timestamp": 1578767021210, "ltp": 19.5, "tv": 96.76, "trd": NaN, "batb": [[0, 19, 64.01]], "batl": NaN}, {"timestamp": 1578767060959, "ltp": 19.5, "tv": 96.76, "trd": NaN, "batb": [[0, 19, 66.65]], "batl": NaN}, {"timestamp": 1578767286823, "ltp": 19.5, "tv": 96.76, "trd": NaN, "batb": NaN, "batl": [[2, 25, 14.3]]}, {"timestamp": 1578767290031, "ltp": 19.5, "tv": 96.76, "trd": NaN, "batb": NaN, "batl": [[2, 25, 15.09]]}, {"timestamp": 1578767511593, "ltp": 19.0, "tv": 100.5, "trd": [[19, 48.15]], "batb": [[0, 19, 64.78]], "batl": NaN}, {"timestamp": 1578767581952, "ltp": 19.0, "tv": 100.5, "trd": NaN, "batb": NaN, "batl": [[0, 21, 17.19], [1, 25, 15.09], [2, 26, 13.75]]}, {"timestamp": 1578767583932, "ltp": 19.5, "tv": 100.84, "trd": [[19.5, 46.83]], "batb": [[0, 19.5, 30.45], [1, 19, 64.78], [2, 18.5, 41.52]], "batl": [[0, 21, 17.02]]}, {"timestamp": 1578767586948, "ltp": 19.5, "tv": 100.84, "trd": NaN, "batb": [[0, 19.5, 51.43], [1, 19, 62.14]], "batl": NaN}, {"timestamp": 1578767590847, "ltp": 19.5, "tv": 100.84, "trd": NaN, "batb": NaN, "batl": [[0, 21, 59.58]]}, {"timestamp": 1578767641925, "ltp": 19.5, "tv": 100.84, "trd": NaN, "batb": [[0, 20, 2.64], [1, 19.5, 48.79], [2, 19, 62.14]], "batl": NaN}, {"timestamp": 1578767646832, "ltp": 19.5, "tv": 100.84, "trd": NaN, "batb": NaN, "batl": [[0, 21, 62.22]]}, {"timestamp": 1578767658666, "ltp": 19.5, "tv": 100.84, "trd": NaN, "batb": [[0, 20, 19.48]], "batl": NaN}, {"timestamp": 1578767666988, "ltp": 19.5, "tv": 100.84, "trd": NaN, "batb": [[0, 20, 2.64], [1, 19.5, 65.63]], "batl": NaN}, {"timestamp": 1578767777104, "ltp": 19.5, "tv": 100.84, "trd": NaN, "batb": [[1, 19.5, 103.91]], "batl": NaN}, {"timestamp": 1578767778896, "ltp": 19.5, "tv": 100.84, "trd": NaN, "batb": [[0, 20, 10.84], [2, 19, 53.5]], "batl": NaN}, {"timestamp": 1578767955933, "ltp": 20.0, "tv": 120.84, "trd": [[20, 24]], "batb": [[0, 19.5, 115], [1, 19, 53.5], [2, 18.5, 41.52]], "batl": NaN}, {"timestamp": 1578767988033, "ltp": 20.0, "tv": 120.84, "trd": NaN, "batb": NaN, "batl": [[1, 22, 117.04], [2, 25, 14.3]]}, {"timestamp": 1578768001993, "ltp": 20.0, "tv": 122.53, "trd": [[20, 25.68]], "batb": [[0, 19.5, 114.16]], "batl": [[0, 20, 99.16], [1, 21, 62.22], [2, 22, 117.04]]}, {"timestamp": 1578768003862, "ltp": 20.0, "tv": 122.53, "trd": NaN, "batb": [[0, 19.5, 95.83]], "batl": NaN}, {"timestamp": 1578768040130, "ltp": 20.0, "tv": 122.53, "trd": NaN, "batb": [[0, 19.5, 96.9]], "batl": NaN}, {"timestamp": 1578768068008, "ltp": 20.0, "tv": 122.53, "trd": NaN, "batb": [[0, 19.5, 95.83]], "batl": [[0, 20, 101.8], [1, 21, 59.58]]}, {"timestamp": 1578768116974, "ltp": 20.0, "tv": 122.53, "trd": NaN, "batb": [[1, 19, 19.05]], "batl": NaN}, {"timestamp": 1578768233668, "ltp": 20.0, "tv": 122.53, "trd": NaN, "batb": [[0, 19.5, 96.93]], "batl": NaN}, {"timestamp": 1578768238966, "ltp": 20.0, "tv": 122.53, "trd": NaN, "batb": [[0, 19.5, 95.83]], "batl": NaN}, {"timestamp": 1578768242990, "ltp": 19.5, "tv": 153.9, "trd": [[19.5, 78.21]], "batb": [[0, 19.5, 80.14], [1, 18.5, 41.75], [2, 18, 19.86]], "batl": [[0, 20, 119.67]]}, {"timestamp": 1578768250767, "ltp": 19.5, "tv": 153.9, "trd": NaN, "batb": NaN, "batl": [[0, 20, 162.23]]}, {"timestamp": 1578768254962, "ltp": 19.5, "tv": 173.9, "trd": [[19.5, 98.21]], "batb": [[0, 19.5, 70.14]], "batl": NaN}, {"timestamp": 1578768256672, "ltp": 19.5, "tv": 179.8, "trd": [[19.5, 104.11]], "batb": [[0, 19.5, 67.19]], "batl": NaN}, {"timestamp": 1578768260082, "ltp": 19.5, "tv": 179.8, "trd": NaN, "batb": [[1, 19, 25.23], [2, 18.5, 41.52]], "batl": NaN}, {"timestamp": 1578768261885, "ltp": 19.5, "tv": 179.8, "trd": NaN, "batb": [[1, 19, 44.05]], "batl": NaN}, {"timestamp": 1578768264012, "ltp": 19.5, "tv": 179.8, "trd": NaN, "batb": NaN, "batl": [[0, 20, 144.36]]}, {"timestamp": 1578768291959, "ltp": 19.5, "tv": 179.8, "trd": NaN, "batb": [[0, 19.5, 68.31]], "batl": NaN}, {"timestamp": 1578768310908, "ltp": 19.5, "tv": 179.8, "trd": NaN, "batb": NaN, "batl": [[2, 22, 116.25]]}, {"timestamp": 1578768391973, "ltp": 19.5, "tv": 179.8, "trd": NaN, "batb": NaN, "batl": [[0, 20, 152.87]]}, {"timestamp": 1578768392966, "ltp": 19.5, "tv": 196.82, "trd": [[19.5, 121.13]], "batb": [[0, 19.5, 59.79]], "batl": [[1, 21, 68.1]]}, {"timestamp": 1578768411811, "ltp": 19.5, "tv": 205.17, "trd": [[19.5, 129.47]], "batb": [[0, 19.5, 55.62]], "batl": NaN}, {"timestamp": 1578768412858, "ltp": 19.5, "tv": 205.17, "trd": NaN, "batb": [[0, 19.5, 54.51]], "batl": NaN}, {"timestamp": 1578768471701, "ltp": 19.5, "tv": 224.06, "trd": [[19.5, 148.37]], "batb": [[0, 19.5, 45.06]], "batl": NaN}, {"timestamp": 1578768600038, "ltp": 19.5, "tv": 231.64, "trd": [[19.5, 155.95]], "batb": [[0, 19.5, 41.27]], "batl": NaN}, {"timestamp": 1578768607045, "ltp": 20.0, "tv": 256.14, "trd": [[20, 50.18]], "batb": NaN, "batl": [[0, 20, 140.62]]}, {"timestamp": 1578768607987, "ltp": 20.0, "tv": 256.14, "trd": NaN, "batb": [[0, 19.5, 54.7]], "batl": NaN}, {"timestamp": 1578768647010, "ltp": 19.5, "tv": 257.76, "trd": [[19.5, 157.57]], "batb": [[0, 19.5, 53.89]], "batl": NaN}, {"timestamp": 1578768718790, "ltp": 19.5, "tv": 257.76, "trd": NaN, "batb": NaN, "batl": [[1, 21, 72.21]]}, {"timestamp": 1578768817881, "ltp": 20.0, "tv": 500.36, "trd": [[20, 292.78]], "batb": NaN, "batl": [[0, 20, 19.32]]}, {"timestamp": 1578768818609, "ltp": 20.0, "tv": 500.36, "trd": NaN, "batb": [[0, 19.5, 143.02]], "batl": NaN}, {"timestamp": 1578768825794, "ltp": 20.0, "tv": 539.0, "trd": [[20, 331.42]], "batb": [[0, 20, 4.85], [1, 19.5, 143.02], [2, 19, 44.05]], "batl": [[0, 21, 74.48], [1, 22, 116.25], [2, 25, 14.3]]}, {"timestamp": 1578768828984, "ltp": 20.0, "tv": 539.0, "trd": NaN, "batb": [[1, 19.5, 161.35]], "batl": NaN}, {"timestamp": 1578768829812, "ltp": 20.0, "tv": 539.0, "trd": NaN, "batb": NaN, "batl": [[0, 21, 74.61]]}, {"timestamp": 1578768833806, "ltp": 20.0, "tv": 539.0, "trd": NaN, "batb": [[0, 20, 47.63]], "batl": NaN}, {"timestamp": 1578768973839, "ltp": 20.0, "tv": 543.48, "trd": [[20, 335.9]], "batb": [[0, 20, 45.39]], "batl": NaN}, {"timestamp": 1578768976042, "ltp": 20.0, "tv": 561.87, "trd": [[20, 354.29]], "batb": [[0, 20, 36.2]], "batl": NaN}, {"timestamp": 1578768992964, "ltp": 20.0, "tv": 573.49, "trd": [[20, 365.91]], "batb": [[0, 20, 30.39]], "batl": NaN}, {"timestamp": 1578768999941, "ltp": 20.0, "tv": 573.49, "trd": NaN, "batb": NaN, "batl": [[0, 21, 1074.61]]}, {"timestamp": 1578769012962, "ltp": 20.0, "tv": 578.39, "trd": [[20, 370.81]], "batb": [[0, 20, 27.94]], "batl": NaN}, {"timestamp": 1578769014958, "ltp": 20.0, "tv": 606.33, "trd": [[20, 398.75]], "batb": [[0, 20, 13.97]], "batl": NaN}, {"timestamp": 1578769016865, "ltp": 20.0, "tv": 620.31, "trd": [[20, 412.73]], "batb": [[0, 20, 6.98]], "batl": NaN}, {"timestamp": 1578769020985, "ltp": 20.0, "tv": 620.31, "trd": NaN, "batb": [[0, 19.5, 161.35], [1, 19, 44.05], [2, 18.5, 41.52]], "batl": [[0, 20, 2.32], [1, 21, 1074.61], [2, 22, 116.25]]}, {"timestamp": 1578769027890, "ltp": 20.0, "tv": 620.31, "trd": NaN, "batb": [[0, 19.5, 168.51]], "batl": NaN}, {"timestamp": 1578769033887, "ltp": 20.0, "tv": 620.31, "trd": NaN, "batb": NaN, "batl": [[0, 20, 44.88]]}, {"timestamp": 1578769035983, "ltp": 20.0, "tv": 620.31, "trd": NaN, "batb": [[0, 19.5, 150.18]], "batl": NaN}, {"timestamp": 1578769047029, "ltp": 19.5, "tv": 624.33, "trd": [[19.5, 161.59]], "batb": [[0, 19.5, 148.16]], "batl": NaN}, {"timestamp": 1578769089886, "ltp": 19.5, "tv": 624.33, "trd": NaN, "batb": NaN, "batl": [[0, 20, 42.56], [1, 21, 74.61]]}, {"timestamp": 1578769116041, "ltp": 20.0, "tv": 709.45, "trd": [[20, 497.85]], "batb": [[0, 19.5, 190.73]], "batl": [[0, 21, 74.61], [1, 22, 116.25], [2, 25, 14.3]]}, {"timestamp": 1578769127039, "ltp": 19.5, "tv": 713.06, "trd": [[19.5, 165.21]], "batb": [[0, 19.5, 188.92]], "batl": NaN}, {"timestamp": 1578769130925, "ltp": 21.0, "tv": 721.58, "trd": [[21, 8.51]], "batb": NaN, "batl": [[0, 21, 70.35]]}, {"timestamp": 1578769207948, "ltp": 21.0, "tv": 721.54, "trd": [[19, 48.13], [19.5, 165.18], [20, 497.85]], "batb": [[0, 19.5, 188.91], [2, 18.5, 41.52]], "batl": NaN}, {"timestamp": 1578769365939, "ltp": 21.0, "tv": 721.54, "trd": NaN, "batb": [[0, 19.5, 207.25]], "batl": NaN}, {"timestamp": 1578769367004, "ltp": 19.5, "tv": 722.92, "trd": [[19.5, 166.56]], "batb": [[0, 19.5, 206.56]], "batl": NaN}, {"timestamp": 1578769408634, "ltp": 19.5, "tv": 722.92, "trd": NaN, "batb": [[0, 19.5, 209.2]], "batl": [[0, 21, 70.22]]}, {"timestamp": 1578769416868, "ltp": 19.5, "tv": 722.92, "trd": NaN, "batb": [[0, 19.5, 206.56]], "batl": NaN}, {"timestamp": 1578769496170, "ltp": 19.5, "tv": 726.92, "trd": [[19.5, 170.56]], "batb": [[0, 19.5, 204.56]], "batl": NaN}, {"timestamp": 1578769531034, "ltp": 19.5, "tv": 726.92, "trd": NaN, "batb": [[0, 19.5, 186.22]], "batl": NaN}, {"timestamp": 1578769531994, "ltp": 19.5, "tv": 726.92, "trd": NaN, "batb": [[0, 19.5, 286.22]], "batl": NaN}, {"timestamp": 1578769585015, "ltp": 19.5, "tv": 726.92, "trd": NaN, "batb": NaN, "batl": [[0, 20, 38.3], [1, 21, 70.22], [2, 22, 116.25]]}, {"timestamp": 1578769611009, "ltp": 19.5, "tv": 726.92, "trd": NaN, "batb": [[0, 19.5, 197.09], [1, 19, 133.18]], "batl": [[0, 20, 40.98]]}, {"timestamp": 1578769693961, "ltp": 19.5, "tv": 728.9, "trd": [[19.5, 172.53]], "batb": [[0, 19.5, 196.11]], "batl": NaN}, {"timestamp": 1578769720995, "ltp": 19.5, "tv": 728.9, "trd": NaN, "batb": NaN, "batl": [[1, 21, 61.71]]}, {"timestamp": 1578769755868, "ltp": 19.5, "tv": 728.9, "trd": NaN, "batb": NaN, "batl": [[0, 20, 43.63]]}, {"timestamp": 1578769790696, "ltp": 19.5, "tv": 728.9, "trd": NaN, "batb": NaN, "batl": [[0, 20, 40.98]]}, {"timestamp": 1578769794900, "ltp": 19.5, "tv": 736.09, "trd": [[19.5, 179.73]], "batb": [[0, 19.5, 192.51]], "batl": NaN}, {"timestamp": 1578769813983, "ltp": 20.0, "tv": 739.5, "trd": [[20, 501.26]], "batb": NaN, "batl": [[0, 20, 39.28]]}, {"timestamp": 1578769823955, "ltp": 19.5, "tv": 743.92, "trd": [[19.5, 184.15]], "batb": [[0, 19.5, 190.3]], "batl": NaN}, {"timestamp": 1578769826540, "ltp": 19.5, "tv": 743.92, "trd": NaN, "batb": NaN, "batl": [[0, 20, 41.92]]}, {"timestamp": 1578769835965, "ltp": 19.5, "tv": 748.34, "trd": [[19.5, 188.58]], "batb": [[0, 19.5, 188.09]], "batl": NaN}, {"timestamp": 1578769838967, "ltp": 19.5, "tv": 748.34, "trd": NaN, "batb": NaN, "batl": [[0, 20, 58.76]]}, {"timestamp": 1578769843981, "ltp": 19.5, "tv": 754.64, "trd": [[19.5, 194.88]], "batb": [[0, 19.5, 184.93]], "batl": NaN}, {"timestamp": 1578769868908, "ltp": 19.5, "tv": 758.38, "trd": [[19.5, 198.62]], "batb": [[0, 19.5, 183.07]], "batl": NaN}, {"timestamp": 1578769887012, "ltp": 19.5, "tv": 758.38, "trd": NaN, "batb": NaN, "batl": [[0, 20, 74.07]]}, {"timestamp": 1578769912983, "ltp": 19.5, "tv": 763.6, "trd": [[19.5, 203.84]], "batb": [[0, 19.5, 180.46]], "batl": NaN}, {"timestamp": 1578769917695, "ltp": 19.5, "tv": 763.6, "trd": NaN, "batb": [[0, 19.5, 173.4]], "batl": NaN}, {"timestamp": 1578769948050, "ltp": 19.5, "tv": 763.6, "trd": NaN, "batb": NaN, "batl": [[1, 21, 57.6]]}, {"timestamp": 1578769953021, "ltp": 19.5, "tv": 770.33, "trd": [[19.5, 210.56]], "batb": [[0, 19.5, 170.04]], "batl": NaN}, {"timestamp": 1578770019053, "ltp": 19.5, "tv": 775.55, "trd": [[19.5, 215.78]], "batb": [[0, 19.5, 167.43]], "batl": NaN}, {"timestamp": 1578770039597, "ltp": 19.5, "tv": 775.92, "trd": [[19.5, 216.16]], "batb": [[0, 19.5, 167.24]], "batl": NaN}, {"timestamp": 1578770040935, "ltp": 19.5, "tv": 779.88, "trd": [[19.5, 220.12]], "batb": [[0, 19.5, 165.26]], "batl": NaN}, {"timestamp": 1578770052831, "ltp": 19.5, "tv": 779.88, "trd": NaN, "batb": NaN, "batl": [[0, 20, 104.49]]}, {"timestamp": 1578770062747, "ltp": 19.5, "tv": 779.88, "trd": NaN, "batb": [[0, 19.5, 167.9]], "batl": [[0, 20, 101.85]]}, {"timestamp": 1578770066055, "ltp": 19.5, "tv": 853.08, "trd": [[19.5, 293.32]], "batb": [[0, 19.5, 131.3]], "batl": [[0, 20, 65.24]]}, {"timestamp": 1578770083536, "ltp": 19.5, "tv": 853.08, "trd": NaN, "batb": [[0, 19.5, 128.66]], "batl": NaN}, {"timestamp": 1578770089990, "ltp": 19.5, "tv": 853.08, "trd": NaN, "batb": [[0, 19.5, 131.3]], "batl": NaN}, {"timestamp": 1578770281042, "ltp": 19.5, "tv": 853.83, "trd": [[19.5, 294.07]], "batb": [[0, 19.5, 130.93]], "batl": NaN}, {"timestamp": 1578770401983, "ltp": 20.0, "tv": 883.83, "trd": [[20, 531.26]], "batb": NaN, "batl": [[0, 20, 50.24], [1, 21, 55.33]]}, {"timestamp": 1578770406035, "ltp": 20.0, "tv": 883.83, "trd": NaN, "batb": NaN, "batl": [[1, 21, 225.57]]}, {"timestamp": 1578770438984, "ltp": 19.5, "tv": 887.24, "trd": [[19.5, 297.47]], "batb": [[0, 19.5, 129.23]], "batl": NaN}, {"timestamp": 1578770440988, "ltp": 19.5, "tv": 887.24, "trd": NaN, "batb": NaN, "batl": [[0, 20, 34.94]]}, {"timestamp": 1578770507952, "ltp": 19.5, "tv": 887.24, "trd": NaN, "batb": NaN, "batl": [[1, 21, 697.99]]}, {"timestamp": 1578770576612, "ltp": 19.5, "tv": 889.38, "trd": [[19.5, 299.61]], "batb": [[0, 19.5, 128.15]], "batl": NaN}, {"timestamp": 1578770633008, "ltp": 19.5, "tv": 889.38, "trd": NaN, "batb": [[0, 19.5, 125.51]], "batl": NaN}, {"timestamp": 1578770646014, "ltp": 19.5, "tv": 889.38, "trd": NaN, "batb": NaN, "batl": [[0, 20, 95.45]]}, {"timestamp": 1578770648046, "ltp": 19.5, "tv": 889.38, "trd": NaN, "batb": [[0, 19.5, 128.15]], "batl": NaN}, {"timestamp": 1578770694980, "ltp": 19.5, "tv": 889.38, "trd": NaN, "batb": NaN, "batl": [[0, 20, 122.23]]}, {"timestamp": 1578770722999, "ltp": 19.5, "tv": 889.38, "trd": NaN, "batb": [[0, 19.5, 125.51]], "batl": [[0, 20, 136.4]]}, {"timestamp": 1578770735998, "ltp": 19.5, "tv": 991.04, "trd": [[19.5, 401.27]], "batb": [[0, 19.5, 74.68]], "batl": NaN}, {"timestamp": 1578770738047, "ltp": 19.5, "tv": 991.04, "trd": NaN, "batb": NaN, "batl": [[0, 20, 124.87]]}, {"timestamp": 1578770745031, "ltp": 19.5, "tv": 1051.04, "trd": [[19.5, 461.27]], "batb": [[0, 19.5, 44.68]], "batl": NaN}, {"timestamp": 1578770746040, "ltp": 19.5, "tv": 1051.04, "trd": NaN, "batb": NaN, "batl": [[0, 20, 136.52]]}, {"timestamp": 1578770746935, "ltp": 19.5, "tv": 1051.04, "trd": NaN, "batb": NaN, "batl": [[0, 20, 221.64]]}, {"timestamp": 1578770751972, "ltp": 19.5, "tv": 1078.28, "trd": [[19.5, 488.51]], "batb": [[0, 19.5, 31.06]], "batl": NaN}, {"timestamp": 1578770763056, "ltp": 19.5, "tv": 1083.88, "trd": [[19.5, 494.11]], "batb": [[0, 19.5, 28.26]], "batl": NaN}, {"timestamp": 1578770765946, "ltp": 19.5, "tv": 1083.88, "trd": NaN, "batb": NaN, "batl": [[0, 20, 219]]}, {"timestamp": 1578770767969, "ltp": 19.5, "tv": 1083.88, "trd": NaN, "batb": NaN, "batl": [[0, 20, 188.58]]}, {"timestamp": 1578770776037, "ltp": 19.5, "tv": 1083.88, "trd": NaN, "batb": NaN, "batl": [[0, 20, 176.93]]}, {"timestamp": 1578770779878, "ltp": 19.5, "tv": 1083.88, "trd": NaN, "batb": NaN, "batl": [[0, 20, 189.45]]}, {"timestamp": 1578770786971, "ltp": 19.5, "tv": 1083.88, "trd": NaN, "batb": NaN, "batl": [[0, 20, 191.16]]}, {"timestamp": 1578770804999, "ltp": 19.5, "tv": 1083.88, "trd": NaN, "batb": NaN, "batl": [[0, 20, 193.8]]}, {"timestamp": 1578770809013, "ltp": 19.5, "tv": 1083.88, "trd": NaN, "batb": [[0, 19.5, 63.26]], "batl": NaN}, {"timestamp": 1578770811026, "ltp": 19.5, "tv": 1083.88, "trd": NaN, "batb": NaN, "batl": [[0, 20, 191.16]]}, {"timestamp": 1578770818008, "ltp": 20.0, "tv": 1165.28, "trd": [[20, 612.66]], "batb": NaN, "batl": [[0, 20, 150.46]]}, {"timestamp": 1578770820898, "ltp": 19.5, "tv": 1181.78, "trd": [[19.5, 510.61]], "batb": [[0, 19.5, 55.01]], "batl": NaN}, {"timestamp": 1578770826937, "ltp": 19.5, "tv": 1197.08, "trd": [[19.5, 525.92]], "batb": [[0, 19.5, 47.36]], "batl": NaN}, {"timestamp": 1578770830001, "ltp": 19.5, "tv": 1207.42, "trd": [[19.5, 536.26]], "batb": [[0, 19.5, 42.19]], "batl": NaN}, {"timestamp": 1578770831014, "ltp": 19.5, "tv": 1291.8, "trd": [[19.5, 620.64]], "batb": [[0, 19, 133.18], [1, 18.5, 41.52], [2, 18, 22.5]], "batl": [[0, 19.5, 29.31], [1, 20, 150.46], [2, 21, 697.99]]}, {"timestamp": 1578770846952, "ltp": 19.5, "tv": 1291.8, "trd": NaN, "batb": [[0, 19, 114.36]], "batl": NaN}, {"timestamp": 1578770881988, "ltp": 19.5, "tv": 1291.8, "trd": NaN, "batb": NaN, "batl": [[0, 19.5, 31.6]]}, {"timestamp": 1578770891008, "ltp": 19.0, "tv": 1295.54, "trd": [[19, 51.87]], "batb": [[0, 19, 112.49]], "batl": NaN}, {"timestamp": 1578770898020, "ltp": 19.0, "tv": 1298.42, "trd": [[19, 54.75]], "batb": [[0, 19, 111.05]], "batl": NaN}, {"timestamp": 1578770903941, "ltp": 19.0, "tv": 1298.42, "trd": NaN, "batb": [[0, 19, 193.75]], "batl": NaN}, {"timestamp": 1578770931944, "ltp": 19.0, "tv": 1685.92, "trd": [[19, 442.25]], "batb": [[0, 18.5, 41.52], [1, 18, 22.5], [2, 17.5, 20.43]], "batl": [[0, 19, 74.84], [1, 19.5, 31.6], [2, 20, 150.46]]}, {"timestamp": 1578770934054, "ltp": 19.0, "tv": 1685.92, "trd": NaN, "batb": [[0, 18.5, 22.2], [1, 18, 2.64]], "batl": NaN}, {"timestamp": 1578770935049, "ltp": 19.0, "tv": 1685.92, "trd": NaN, "batb": NaN, "batl": [[0, 19, 79.1]]}, {"timestamp": 1578770936050, "ltp": 19.0, "tv": 1685.92, "trd": NaN, "batb": NaN, "batl": [[1, 19.5, 34.25]]}, {"timestamp": 1578770936948, "ltp": 18.5, "tv": 1690.18, "trd": [[18.5, 4.26]], "batb": [[0, 18.5, 20.07]], "batl": NaN}, {"timestamp": 1578770941054, "ltp": 18.5, "tv": 1690.18, "trd": NaN, "batb": NaN, "batl": [[0, 19, 81.23]]}, {"timestamp": 1578770943974, "ltp": 18.5, "tv": 1690.18, "trd": NaN, "batb": NaN, "batl": [[1, 19.5, 50.84]]}, {"timestamp": 1578770944965, "ltp": 18.5, "tv": 1690.18, "trd": NaN, "batb": NaN, "batl": [[0, 19, 84.29]]}, {"timestamp": 1578770946976, "ltp": 18.5, "tv": 1690.18, "trd": NaN, "batb": NaN, "batl": [[2, 20, 126.13]]}, {"timestamp": 1578770950984, "ltp": 18.5, "tv": 1690.18, "trd": NaN, "batb": NaN, "batl": [[1, 19.5, 48.19]]}, {"timestamp": 1578770954985, "ltp": 18.5, "tv": 1696.3, "trd": [[18.5, 10.38]], "batb": [[0, 18.5, 17.01]], "batl": [[0, 19, 81.23]]}, {"timestamp": 1578770972017, "ltp": 18.5, "tv": 1700.04, "trd": [[18.5, 14.11]], "batb": [[0, 18.5, 15.14]], "batl": NaN}, {"timestamp": 1578771001007, "ltp": 18.5, "tv": 1700.04, "trd": NaN, "batb": [[0, 18.5, 126.14]], "batl": NaN}, {"timestamp": 1578771003019, "ltp": 18.5, "tv": 1700.04, "trd": NaN, "batb": [[1, 18, 22.5]], "batl": NaN}, {"timestamp": 1578771004976, "ltp": 18.5, "tv": 1700.04, "trd": NaN, "batb": [[1, 18, 144.5]], "batl": NaN}, {"timestamp": 1578771054001, "ltp": 19.0, "tv": 1869.29, "trd": [[18.5, 20.91], [19, 604.71]], "batb": [[0, 19, 29.77], [1, 18.5, 122.74], [2, 18, 144.5]], "batl": [[0, 19.5, 48.19], [1, 20, 126.13], [2, 21, 697.99]]}, {"timestamp": 1578771055963, "ltp": 19.0, "tv": 1869.29, "trd": NaN, "batb": [[1, 18.5, 142.06]], "batl": [[0, 19.5, 31.6]]}, {"timestamp": 1578771070026, "ltp": 19.0, "tv": 1869.29, "trd": NaN, "batb": [[0, 19, 229.77]], "batl": NaN}, {"timestamp": 1578771073029, "ltp": 19.0, "tv": 1873.03, "trd": [[19, 608.45]], "batb": [[0, 19, 227.9]], "batl": NaN}, {"timestamp": 1578771078939, "ltp": 19.0, "tv": 1873.03, "trd": NaN, "batb": [[0, 19, 230.54], [2, 18, 141.86]], "batl": NaN}, {"timestamp": 1578771099945, "ltp": 19.0, "tv": 1873.03, "trd": NaN, "batb": NaN, "batl": [[0, 19.5, 86.6]]}, {"timestamp": 1578771103970, "ltp": 19.0, "tv": 1873.03, "trd": NaN, "batb": NaN, "batl": [[0, 19.5, 31.6], [1, 20, 181.13]]}, {"timestamp": 1578771119867, "ltp": 19.0, "tv": 1873.79, "trd": [[19, 609.21]], "batb": [[0, 19, 230.16]], "batl": NaN}, {"timestamp": 1578771126987, "ltp": 19.0, "tv": 2026.86, "trd": [[19, 762.27]], "batb": [[0, 19, 153.63]], "batl": NaN}, {"timestamp": 1578771145960, "ltp": 19.0, "tv": 2030.46, "trd": [[19, 765.88]], "batb": [[0, 19, 151.83]], "batl": NaN}, {"timestamp": 1578771151762, "ltp": 19.0, "tv": 2030.46, "trd": NaN, "batb": [[1, 18.5, 146.32]], "batl": NaN}, {"timestamp": 1578771153860, "ltp": 19.0, "tv": 2030.46, "trd": NaN, "batb": [[2, 18, 146.11]], "batl": NaN}, {"timestamp": 1578771158864, "ltp": 19.0, "tv": 2031.54, "trd": [[19, 766.96]], "batb": [[0, 19, 151.29]], "batl": NaN}, {"timestamp": 1578771160980, "ltp": 19.0, "tv": 2031.54, "trd": NaN, "batb": [[0, 19, 176.83]], "batl": NaN}, {"timestamp": 1578771162964, "ltp": 19.0, "tv": 2036.92, "trd": [[19, 772.34]], "batb": [[0, 19, 174.14]], "batl": NaN}, {"timestamp": 1578771180006, "ltp": 19.0, "tv": 2036.92, "trd": NaN, "batb": [[0, 19, 172.97]], "batl": NaN}, {"timestamp": 1578771210976, "ltp": 19.0, "tv": 2045.44, "trd": [[19, 780.85]], "batb": [[0, 19, 168.71]], "batl": NaN}, {"timestamp": 1578771220010, "ltp": 19.0, "tv": 2055.44, "trd": [[19, 790.85]], "batb": [[0, 19, 163.71]], "batl": NaN}, {"timestamp": 1578771221872, "ltp": 19.0, "tv": 2055.44, "trd": NaN, "batb": [[0, 19, 162.24]], "batl": [[0, 19.5, 33.03]]}, {"timestamp": 1578771256027, "ltp": 19.5, "tv": 2063.44, "trd": [[19.5, 628.64]], "batb": NaN, "batl": [[0, 19.5, 29.03]]}, {"timestamp": 1578771259049, "ltp": 19.5, "tv": 2063.44, "trd": NaN, "batb": [[0, 19, 272.89]], "batl": NaN}, {"timestamp": 1578771272052, "ltp": 19.0, "tv": 2142.28, "trd": [[19, 869.7]], "batb": [[0, 19, 233.47]], "batl": NaN}, {"timestamp": 1578771314029, "ltp": 19.0, "tv": 2182.28, "trd": [[19, 909.7]], "batb": [[0, 19, 213.47]], "batl": NaN}, {"timestamp": 1578771323040, "ltp": 19.0, "tv": 2182.28, "trd": NaN, "batb": NaN, "batl": [[1, 20, 154.34]]}, {"timestamp": 1578771325972, "ltp": 19.0, "tv": 2182.28, "trd": NaN, "batb": [[0, 19, 214.94]], "batl": [[0, 19.5, 27.6]]}, {"timestamp": 1578771334963, "ltp": 19.0, "tv": 2235.86, "trd": [[19, 963.27]], "batb": [[0, 19, 188.15]], "batl": NaN}, {"timestamp": 1578771372033, "ltp": 19.0, "tv": 2239.26, "trd": [[19, 966.68]], "batb": [[0, 19, 186.45]], "batl": NaN}, {"timestamp": 1578771407976, "ltp": 19.5, "tv": 2250.48, "trd": [[19.5, 639.86]], "batb": NaN, "batl": [[0, 19.5, 21.99]]}, {"timestamp": 1578771418960, "ltp": 19.0, "tv": 2254.22, "trd": [[19, 970.41]], "batb": [[0, 19, 184.58]], "batl": NaN}, {"timestamp": 1578771490987, "ltp": 19.0, "tv": 2264.22, "trd": [[19, 980.41]], "batb": [[0, 19, 179.58]], "batl": NaN}, {"timestamp": 1578771494972, "ltp": 19.0, "tv": 2264.22, "trd": NaN, "batb": [[0, 19, 178.11]], "batl": NaN}, {"timestamp": 1578771530956, "ltp": 19.0, "tv": 2274.22, "trd": [[19, 990.41]], "batb": [[0, 19, 173.11]], "batl": NaN}, {"timestamp": 1578771544764, "ltp": 19.5, "tv": 2286.22, "trd": [[19.5, 651.86]], "batb": [[0, 19, 174.58]], "batl": [[0, 19.5, 15.99]]}, {"timestamp": 1578771558044, "ltp": 19.5, "tv": 2286.22, "trd": NaN, "batb": [[0, 19, 193.4]], "batl": NaN}, {"timestamp": 1578771560050, "ltp": 19.5, "tv": 2286.22, "trd": NaN, "batb": NaN, "batl": [[1, 20, 141.82]]}, {"timestamp": 1578771563977, "ltp": 19.5, "tv": 2286.22, "trd": NaN, "batb": NaN, "batl": [[1, 20, 155.58]]}, {"timestamp": 1578771569988, "ltp": 19.5, "tv": 2286.22, "trd": NaN, "batb": [[0, 19, 174.58]], "batl": NaN}, {"timestamp": 1578771590012, "ltp": 19.5, "tv": 2286.22, "trd": NaN, "batb": [[0, 19, 193.4]], "batl": NaN}, {"timestamp": 1578771593008, "ltp": 19.5, "tv": 2286.22, "trd": NaN, "batb": NaN, "batl": [[1, 20, 141.82]]}, {"timestamp": 1578771593910, "ltp": 19.5, "tv": 2307.31, "trd": [[19.5, 672.95]], "batb": NaN, "batl": [[0, 19.5, 5.45]]}, {"timestamp": 1578771603027, "ltp": 19.5, "tv": 2307.31, "trd": NaN, "batb": NaN, "batl": [[1, 20, 154.83]]}, {"timestamp": 1578771615047, "ltp": 19.5, "tv": 2309.24, "trd": [[19.5, 674.88]], "batb": NaN, "batl": [[0, 19.5, 4.48]]}, {"timestamp": 1578771616050, "ltp": 19.5, "tv": 2314.52, "trd": [[19.5, 680.16]], "batb": NaN, "batl": [[0, 19.5, 1.84]]}, {"timestamp": 1578771629981, "ltp": 19.0, "tv": 2318.26, "trd": [[19, 994.15]], "batb": [[0, 19, 191.53]], "batl": NaN}, {"timestamp": 1578771650884, "ltp": 19.0, "tv": 2318.28, "trd": [[19, 994.17]], "batb": [[0, 19, 191.52]], "batl": NaN}, {"timestamp": 1578771668014, "ltp": 19.0, "tv": 2318.28, "trd": NaN, "batb": NaN, "batl": [[1, 20, 141.82]]}, {"timestamp": 1578771696041, "ltp": 19.0, "tv": 2321.82, "trd": [[19, 997.71]], "batb": [[0, 19, 189.75]], "batl": NaN}, {"timestamp": 1578771703033, "ltp": 19.0, "tv": 2325.56, "trd": [[19, 1001.45]], "batb": [[0, 19, 187.88]], "batl": NaN}, {"timestamp": 1578771708052, "ltp": 20.0, "tv": 2347.56, "trd": [[19.5, 683.84], [20, 630.98]], "batb": NaN, "batl": [[0, 20, 132.66], [1, 21, 697.99], [2, 22, 116.25]]}, {"timestamp": 1578771708954, "ltp": 20.0, "tv": 2347.56, "trd": NaN, "batb": [[0, 19.5, 9.16], [1, 19, 187.88], [2, 18.5, 146.32]], "batl": NaN}, {"timestamp": 1578771710013, "ltp": 19.5, "tv": 2352.15, "trd": [[19.5, 688.44]], "batb": [[0, 19.5, 6.86]], "batl": NaN}, {"timestamp": 1578771713029, "ltp": 19.5, "tv": 2352.15, "trd": NaN, "batb": [[1, 19, 186.41]], "batl": NaN}, {"timestamp": 1578771724980, "ltp": 19.5, "tv": 2356.75, "trd": [[19.5, 693.03]], "batb": [[0, 19.5, 4.56]], "batl": NaN}, {"timestamp": 1578771732980, "ltp": 19.5, "tv": 2365.87, "trd": [[19.5, 702.16]], "batb": [[0, 19, 186.41], [1, 18.5, 146.32], [2, 18, 146.11]], "batl": [[0, 19.5, 7.58], [1, 20, 132.66], [2, 21, 697.99]]}, {"timestamp": 1578771733979, "ltp": 19.5, "tv": 2376.55, "trd": [[19.5, 712.84]], "batb": NaN, "batl": [[0, 19.5, 2.24]]}, {"timestamp": 1578771739992, "ltp": 19.5, "tv": 2378.75, "trd": [[19.5, 715.04]], "batb": NaN, "batl": [[0, 19.5, 1.14], [1, 20, 232.8]]}, {"timestamp": 1578771761012, "ltp": 19.5, "tv": 2378.75, "trd": NaN, "batb": [[0, 19, 167.59]], "batl": [[1, 20, 241.05]]}, {"timestamp": 1578771769998, "ltp": 19.5, "tv": 2378.75, "trd": NaN, "batb": NaN, "batl": [[0, 19.5, 13.79]]}, {"timestamp": 1578771775032, "ltp": 19.5, "tv": 2378.75, "trd": NaN, "batb": [[0, 19, 212.59]], "batl": NaN}, {"timestamp": 1578771776038, "ltp": 19.5, "tv": 2404.78, "trd": [[19.5, 741.06]], "batb": NaN, "batl": [[0, 20, 241.83], [1, 21, 697.99], [2, 22, 116.25]]}, {"timestamp": 1578771779053, "ltp": 19.5, "tv": 2404.78, "trd": NaN, "batb": [[0, 19, 214.3]], "batl": NaN}, {"timestamp": 1578771782040, "ltp": 19.5, "tv": 2406.32, "trd": [[19.5, 742.61]], "batb": [[0, 19.5, 6.88], [1, 19, 214.3], [2, 18.5, 146.32]], "batl": [[0, 20, 241.05]]}, {"timestamp": 1578771786025, "ltp": 19.5, "tv": 2406.32, "trd": NaN, "batb": [[2, 18.5, 142.06]], "batl": NaN}, {"timestamp": 1578771794042, "ltp": 19.5, "tv": 2408.91, "trd": [[19.5, 745.19]], "batb": [[0, 19.5, 5.59]], "batl": NaN}, {"timestamp": 1578771801041, "ltp": 19.5, "tv": 2417.68, "trd": [[19.5, 753.96]], "batb": [[0, 19.5, 1.2]], "batl": NaN}, {"timestamp": 1578771826009, "ltp": 19.5, "tv": 2417.68, "trd": NaN, "batb": [[0, 19.5, 46.2]], "batl": NaN}, {"timestamp": 1578771831025, "ltp": 19.5, "tv": 2417.68, "trd": NaN, "batb": [[0, 19.5, 48.95]], "batl": NaN}, {"timestamp": 1578771833014, "ltp": 19.5, "tv": 2451.72, "trd": [[19.5, 788.01]], "batb": [[0, 19.5, 43.41]], "batl": NaN}, {"timestamp": 1578771833911, "ltp": 19.5, "tv": 2485.77, "trd": [[19.5, 822.05]], "batb": [[0, 19.5, 26.39]], "batl": NaN}, {"timestamp": 1578771838004, "ltp": 19.5, "tv": 2490.61, "trd": [[19.5, 826.89]], "batb": [[0, 19.5, 23.97]], "batl": NaN}, {"timestamp": 1578771843959, "ltp": 19.5, "tv": 2490.61, "trd": NaN, "batb": NaN, "batl": [[0, 20, 243.47]]}, {"timestamp": 1578771845025, "ltp": 20.0, "tv": 2490.71, "trd": [[20, 631.08]], "batb": NaN, "batl": [[0, 20, 243.42]]}, {"timestamp": 1578771848032, "ltp": 20.0, "tv": 2496.71, "trd": [[20, 637.08]], "batb": NaN, "batl": [[0, 20, 240.42]]}, {"timestamp": 1578771849029, "ltp": 19.5, "tv": 2500.31, "trd": [[19.5, 830.5]], "batb": [[0, 19.5, 25.22]], "batl": NaN}, {"timestamp": 1578771860041, "ltp": 19.5, "tv": 2500.31, "trd": NaN, "batb": NaN, "batl": [[0, 20, 277.88]]}, {"timestamp": 1578771869978, "ltp": 19.5, "tv": 2512.71, "trd": [[19.5, 842.9]], "batb": [[0, 19.5, 19.02]], "batl": NaN}, {"timestamp": 1578771870992, "ltp": 19.5, "tv": 2550.75, "trd": [[19.5, 880.93]], "batb": [[0, 19, 214.3], [1, 18.5, 142.06], [2, 18, 141.86]], "batl": [[0, 19.5, 34.65], [1, 20, 277.88], [2, 21, 697.99]]}, {"timestamp": 1578771873994, "ltp": 19.5, "tv": 2550.79, "trd": [[19.5, 880.97]], "batb": NaN, "batl": [[0, 19.5, 34.63]]}, {"timestamp": 1578771891005, "ltp": 19.5, "tv": 2600.79, "trd": [[19.5, 930.97]], "batb": NaN, "batl": [[0, 19.5, 9.63]]}, {"timestamp": 1578771898013, "ltp": 19.0, "tv": 2604.53, "trd": [[19, 1005.19]], "batb": [[0, 19, 212.43]], "batl": NaN}, {"timestamp": 1578771901017, "ltp": 19.0, "tv": 2638.57, "trd": [[19, 1039.23]], "batb": [[0, 19, 195.41]], "batl": NaN}, {"timestamp": 1578771902023, "ltp": 19.5, "tv": 2649.82, "trd": [[19.5, 942.22]], "batb": NaN, "batl": [[0, 19.5, 4.01]]}, {"timestamp": 1578771908039, "ltp": 19.5, "tv": 2657.84, "trd": [[19.5, 950.24]], "batb": [[0, 19.5, 2.11], [1, 19, 195.41], [2, 18.5, 142.06]], "batl": [[0, 20, 240.42], [1, 21, 697.99], [2, 22, 116.25]]}, {"timestamp": 1578771909040, "ltp": 19.5, "tv": 2660.1, "trd": [[19.5, 952.5]], "batb": [[0, 19, 196.39], [1, 18.5, 142.06], [2, 18, 141.86]], "batl": NaN}, {"timestamp": 1578771910046, "ltp": 19.5, "tv": 2662.06, "trd": [[19.5, 954.46]], "batb": [[0, 19, 195.41]], "batl": [[0, 20, 241.15]]}, {"timestamp": 1578771917052, "ltp": 19.5, "tv": 2662.06, "trd": NaN, "batb": [[0, 19, 196.87]], "batl": NaN}, {"timestamp": 1578771926048, "ltp": 19.5, "tv": 2663.5, "trd": [[19.5, 955.9]], "batb": [[0, 19.5, 10.28], [1, 19, 196.87], [2, 18.5, 142.06]], "batl": [[0, 20, 240.42]]}, {"timestamp": 1578771927986, "ltp": 19.5, "tv": 2663.5, "trd": NaN, "batb": [[1, 19, 195.41]], "batl": NaN}, {"timestamp": 1578771934947, "ltp": 19.5, "tv": 2663.94, "trd": [[19.5, 956.35]], "batb": [[0, 19.5, 10.06]], "batl": NaN}, {"timestamp": 1578771938976, "ltp": 19.5, "tv": 2663.94, "trd": NaN, "batb": [[2, 18.5, 143.77]], "batl": NaN}, {"timestamp": 1578771942971, "ltp": 19.5, "tv": 2668.54, "trd": [[19.5, 960.94]], "batb": [[0, 19.5, 7.76]], "batl": NaN}, {"timestamp": 1578771943974, "ltp": 20.0, "tv": 2668.64, "trd": [[20, 637.18]], "batb": NaN, "batl": [[0, 20, 240.32]]}, {"timestamp": 1578771950972, "ltp": 19.5, "tv": 2672.64, "trd": [[19.5, 964.94]], "batb": [[0, 19.5, 5.76]], "batl": NaN}, {"timestamp": 1578771961992, "ltp": 19.5, "tv": 2672.64, "trd": NaN, "batb": [[0, 19.5, 25.76]], "batl": NaN}, {"timestamp": 1578771974005, "ltp": 19.5, "tv": 2672.64, "trd": NaN, "batb": [[0, 19.5, 60.2]], "batl": NaN}, {"timestamp": 1578771982009, "ltp": 19.5, "tv": 2672.64, "trd": NaN, "batb": NaN, "batl": [[0, 20, 242.02]]}, {"timestamp": 1578771990011, "ltp": 19.5, "tv": 2672.64, "trd": NaN, "batb": [[1, 19, 168.17]], "batl": NaN}, {"timestamp": 1578771994008, "ltp": 19.5, "tv": 2684.89, "trd": [[19.5, 977.18]], "batb": [[0, 19.5, 54.08]], "batl": NaN}, {"timestamp": 1578771994916, "ltp": 19.5, "tv": 2684.89, "trd": NaN, "batb": [[0, 19.5, 58.67]], "batl": NaN}, {"timestamp": 1578772005029, "ltp": 19.5, "tv": 2684.89, "trd": NaN, "batb": NaN, "batl": [[0, 20, 240.32]]}, {"timestamp": 1578772006048, "ltp": 19.5, "tv": 2688.29, "trd": [[19.5, 980.59]], "batb": [[0, 19.5, 56.97]], "batl": NaN}, {"timestamp": 1578772008046, "ltp": 19.5, "tv": 2788.29, "trd": [[19.5, 1080.59]], "batb": [[0, 19.5, 6.97]], "batl": NaN}, {"timestamp": 1578772014028, "ltp": 19.5, "tv": 2802.23, "trd": [[19.5, 1094.53]], "batb": [[0, 19, 168.17], [1, 18.5, 143.77], [2, 18, 19.86]], "batl": [[0, 19.5, 10.05], [1, 20, 240.32], [2, 21, 697.99]]}, {"timestamp": 1578772019054, "ltp": 19.0, "tv": 2854.27, "trd": [[19, 1091.27]], "batb": [[0, 19, 142.15]], "batl": NaN}, {"timestamp": 1578772021960, "ltp": 19.0, "tv": 2854.27, "trd": NaN, "batb": [[1, 18.5, 142.06], [2, 18, 21.56]], "batl": NaN}, {"timestamp": 1578772022960, "ltp": 19.0, "tv": 2854.27, "trd": NaN, "batb": NaN, "batl": [[0, 19.5, 110.05]]}, {"timestamp": 1578772023958, "ltp": 19.0, "tv": 2854.27, "trd": NaN, "batb": [[0, 19, 45]], "batl": [[0, 19.5, 262.3]]}, {"timestamp": 1578772026964, "ltp": 19.5, "tv": 2947.11, "trd": [[19.5, 1187.37]], "batb": NaN, "batl": [[0, 19.5, 215.87]]}, {"timestamp": 1578772029954, "ltp": 19.5, "tv": 2947.11, "trd": NaN, "batb": [[2, 18, 21.6]], "batl": NaN}, {"timestamp": 1578772031054, "ltp": 19.5, "tv": 2947.11, "trd": NaN, "batb": [[0, 19, 25]], "batl": NaN}, {"timestamp": 1578772033042, "ltp": 19.5, "tv": 2947.49, "trd": [[19.5, 1187.75]], "batb": NaN, "batl": [[0, 19.5, 215.68]]}, {"timestamp": 1578772059971, "ltp": 19.5, "tv": 2978.11, "trd": [[19.5, 1218.37]], "batb": NaN, "batl": [[0, 19.5, 200.37]]}, {"timestamp": 1578772063997, "ltp": 19.5, "tv": 2978.11, "trd": NaN, "batb": NaN, "batl": [[1, 20, 268.41]]}, {"timestamp": 1578772070001, "ltp": 19.5, "tv": 2985.77, "trd": [[19.5, 1226.02]], "batb": NaN, "batl": [[0, 19.5, 196.54]]}, {"timestamp": 1578772074020, "ltp": 19.5, "tv": 2985.77, "trd": NaN, "batb": [[0, 19, 80.33]], "batl": NaN}, {"timestamp": 1578772101023, "ltp": 19.5, "tv": 2985.77, "trd": NaN, "batb": [[0, 18, 1.74], [1, 10, 29.36], [2, 1.25, 144.01]], "batl": [[0, 19.5, 194.3], [1, 20, 1.7], [2, 21, 472.42]]}, {"timestamp": 1578772108019, "ltp": 19.5, "tv": 2985.77, "trd": NaN, "batb": [[0, 18.5, 19.32], [1, 18, 21.6], [2, 17.5, 20.43]], "batl": [[1, 20, 9.24], [2, 21, 479.9]]}, {"timestamp": 1578772108966, "ltp": 19.5, "tv": 2985.77, "trd": NaN, "batb": [[0, 18, 1.74], [1, 17.5, 29.01], [2, 17, 9.46]], "batl": [[1, 20, 28.09], [2, 21, 472.42]]}, {"timestamp": 1578772109962, "ltp": 19.5, "tv": 2985.77, "trd": NaN, "batb": [[1, 17.5, 39.96]], "batl": [[1, 20, 38.4]]}, {"timestamp": 1578772113015, "ltp": 19.5, "tv": 2985.77, "trd": NaN, "batb": [[0, 18, 10.54]], "batl": NaN}, {"timestamp": 1578772116004, "ltp": 19.5, "tv": 2985.77, "trd": NaN, "batb": [[0, 18.5, 7.93], [1, 18, 18.94], [2, 17.5, 48.87]], "batl": [[2, 21, 489.18]]}, {"timestamp": 1578772118011, "ltp": 19.5, "tv": 2985.77, "trd": NaN, "batb": [[0, 18.5, 33.47]], "batl": NaN}, {"timestamp": 1578772120976, "ltp": 19.5, "tv": 2985.77, "trd": NaN, "batb": [[1, 18, 38.96]], "batl": NaN}, {"timestamp": 1578772123020, "ltp": 19.5, "tv": 2985.77, "trd": NaN, "batb": [[0, 18.5, 97.37]], "batl": NaN}, {"timestamp": 1578772124032, "ltp": 19.5, "tv": 2985.77, "trd": NaN, "batb": [[0, 18.5, 105.56]], "batl": NaN}, {"timestamp": 1578772125024, "ltp": 19.5, "tv": 2985.77, "trd": NaN, "batb": [[2, 17.5, 50.99]], "batl": NaN}, {"timestamp": 1578772127024, "ltp": 19.5, "tv": 2985.77, "trd": NaN, "batb": [[0, 19, 55.33], [1, 18.5, 105.56], [2, 18, 58.82]], "batl": NaN}, {"timestamp": 1578772128017, "ltp": 19.0, "tv": 3023.14, "trd": [[19, 1128.64]], "batb": [[0, 19, 36.64]], "batl": NaN}, {"timestamp": 1578772131049, "ltp": 19.0, "tv": 3057.18, "trd": [[19, 1162.69]], "batb": [[0, 19, 19.62], [1, 18.5, 124.88]], "batl": NaN}, {"timestamp": 1578772134031, "ltp": 19.0, "tv": 3057.18, "trd": NaN, "batb": [[0, 19, 35.39]], "batl": NaN}, {"timestamp": 1578772135024, "ltp": 19.0, "tv": 3057.18, "trd": NaN, "batb": NaN, "batl": [[1, 20, 36.7]]}, {"timestamp": 1578772136011, "ltp": 19.0, "tv": 3057.18, "trd": NaN, "batb": [[2, 18, 70.56]], "batl": NaN}, {"timestamp": 1578772142048, "ltp": 19.0, "tv": 3057.18, "trd": NaN, "batb": [[0, 19, 135.39]], "batl": NaN}, {"timestamp": 1578772143047, "ltp": 19.0, "tv": 3060.59, "trd": [[19, 1166.1]], "batb": [[0, 19, 133.69]], "batl": NaN}, {"timestamp": 1578772144036, "ltp": 19.0, "tv": 3060.59, "trd": NaN, "batb": [[0, 19, 136.69]], "batl": NaN}, {"timestamp": 1578772154951, "ltp": 19.0, "tv": 3065.07, "trd": [[19, 1170.58]], "batb": [[0, 19, 134.45]], "batl": NaN}, {"timestamp": 1578772160968, "ltp": 19.0, "tv": 3065.07, "trd": NaN, "batb": [[1, 18.5, 99.34]], "batl": NaN}, {"timestamp": 1578772165013, "ltp": 19.0, "tv": 3065.07, "trd": NaN, "batb": [[1, 18.5, 118.67], [2, 18, 90.41]], "batl": [[1, 20, 54.57]]}, {"timestamp": 1578772172957, "ltp": 19.0, "tv": 3065.07, "trd": NaN, "batb": [[2, 18, 92.12]], "batl": NaN}, {"timestamp": 1578772176969, "ltp": 19.0, "tv": 3190.3, "trd": [[19, 1295.81]], "batb": [[0, 19, 71.83]], "batl": NaN}, {"timestamp": 1578772185006, "ltp": 19.0, "tv": 3190.3, "trd": NaN, "batb": NaN, "batl": [[2, 21, 514.33]]}, {"timestamp": 1578772185997, "ltp": 19.0, "tv": 3190.3, "trd": NaN, "batb": NaN, "batl": [[1, 20, 61.31], [2, 21, 589.8]]}, {"timestamp": 1578772187991, "ltp": 19.0, "tv": 3190.3, "trd": NaN, "batb": [[0, 19, 68.83]], "batl": NaN}, {"timestamp": 1578772188984, "ltp": 19.0, "tv": 3194.08, "trd": [[19, 1299.59]], "batb": [[0, 19, 66.94]], "batl": NaN}, {"timestamp": 1578772190967, "ltp": 19.5, "tv": 3229.58, "trd": [[19.5, 1261.53]], "batb": NaN, "batl": [[0, 19.5, 176.55]]}, {"timestamp": 1578772192015, "ltp": 19.5, "tv": 3229.58, "trd": NaN, "batb": NaN, "batl": [[2, 21, 585.54]]}, {"timestamp": 1578772196017, "ltp": 19.0, "tv": 3233.84, "trd": [[19, 1303.85]], "batb": [[0, 19, 64.81]], "batl": NaN}, {"timestamp": 1578772197996, "ltp": 19.0, "tv": 3260.4, "trd": [[19, 1330.41]], "batb": [[0, 19, 51.53]], "batl": NaN}, {"timestamp": 1578772199036, "ltp": 19.0, "tv": 3260.4, "trd": NaN, "batb": NaN, "batl": [[1, 20, 65.57]]}, {"timestamp": 1578772202021, "ltp": 19.5, "tv": 3261.28, "trd": [[19.5, 1262.41]], "batb": NaN, "batl": [[0, 19.5, 176.11]]}, {"timestamp": 1578772205038, "ltp": 19.5, "tv": 3261.28, "trd": NaN, "batb": [[0, 19, 77.68]], "batl": NaN}, {"timestamp": 1578772206035, "ltp": 19.5, "tv": 3261.28, "trd": NaN, "batb": [[2, 18, 88.67]], "batl": NaN}, {"timestamp": 1578772208015, "ltp": 19.5, "tv": 3261.28, "trd": NaN, "batb": [[0, 19, 51.53]], "batl": NaN}, {"timestamp": 1578772211013, "ltp": 19.0, "tv": 3266.38, "trd": [[19, 1335.51]], "batb": [[0, 19, 48.98]], "batl": NaN}, {"timestamp": 1578772214029, "ltp": 19.0, "tv": 3266.38, "trd": NaN, "batb": NaN, "batl": [[2, 21, 686.16]]}, {"timestamp": 1578772217010, "ltp": 19.0, "tv": 3266.38, "trd": NaN, "batb": [[1, 18.5, 122.92]], "batl": NaN}, {"timestamp": 1578772218010, "ltp": 19.5, "tv": 3618.6, "trd": [[19.5, 1614.63]], "batb": [[0, 19.5, 45.89], [1, 19, 48.98], [2, 18.5, 122.92]], "batl": [[0, 20, 65.57], [1, 21, 686.16], [2, 22, 52.58]]}, {"timestamp": 1578772219055, "ltp": 19.5, "tv": 3618.6, "trd": NaN, "batb": [[1, 19, 53.24]], "batl": NaN}, {"timestamp": 1578772221046, "ltp": 19.5, "tv": 3618.6, "trd": NaN, "batb": [[0, 19, 53.24], [1, 18.5, 122.92], [2, 18, 88.67]], "batl": [[2, 22, 27.58]]}, {"timestamp": 1578772223039, "ltp": 19.5, "tv": 3618.6, "trd": NaN, "batb": [[1, 18.5, 114.99]], "batl": NaN}, {"timestamp": 1578772224031, "ltp": 19.5, "tv": 3618.6, "trd": NaN, "batb": [[0, 19, 48.98], [1, 18.5, 110.74]], "batl": NaN}, {"timestamp": 1578772225023, "ltp": 19.0, "tv": 3623.2, "trd": [[19, 1340.11]], "batb": [[0, 19, 46.68]], "batl": NaN}, {"timestamp": 1578772230042, "ltp": 19.0, "tv": 3623.2, "trd": NaN, "batb": [[0, 19.5, 25.48], [1, 19, 46.68], [2, 18.5, 110.74]], "batl": NaN}, {"timestamp": 1578772232039, "ltp": 19.0, "tv": 3623.2, "trd": NaN, "batb": [[1, 19, 46.76]], "batl": NaN}, {"timestamp": 1578772233033, "ltp": 19.0, "tv": 3623.2, "trd": NaN, "batb": NaN, "batl": [[0, 20, 73.23]]}, {"timestamp": 1578772233979, "ltp": 19.5, "tv": 3623.27, "trd": [[19.5, 1614.7]], "batb": [[0, 19.5, 25.44], [1, 19, 146.76]], "batl": [[0, 20, 65.57]]}, {"timestamp": 1578772235048, "ltp": 19.5, "tv": 3623.27, "trd": NaN, "batb": NaN, "batl": [[1, 21, 714.16], [2, 22, 53.58]]}, {"timestamp": 1578772236982, "ltp": 19.5, "tv": 3637.64, "trd": [[19.5, 1628.97], [20, 637.28]], "batb": [[0, 19.5, 18.31]], "batl": [[0, 20, 65.52]]}, {"timestamp": 1578772237971, "ltp": 19.5, "tv": 3674.26, "trd": [[19.5, 1665.58]], "batb": [[0, 19, 146.76], [1, 18.5, 110.74], [2, 18, 88.67]], "batl": NaN}, {"timestamp": 1578772240961, "ltp": 19.5, "tv": 3674.26, "trd": NaN, "batb": [[0, 19, 171.76], [1, 18.5, 135.74]], "batl": NaN}, {"timestamp": 1578772241962, "ltp": 19.5, "tv": 3674.26, "trd": NaN, "batb": [[2, 18, 113.67]], "batl": NaN}, {"timestamp": 1578772245012, "ltp": 19.5, "tv": 3674.26, "trd": NaN, "batb": NaN, "batl": [[0, 19.5, 7.11], [1, 20, 65.52], [2, 21, 714.16]]}, {"timestamp": 1578772245958, "ltp": 19.5, "tv": 3674.26, "trd": NaN, "batb": NaN, "batl": [[0, 19.5, 60.78], [1, 20, 99.52]]}, {"timestamp": 1578772250050, "ltp": 19.5, "tv": 3674.36, "trd": [[19.5, 1665.68]], "batb": NaN, "batl": [[0, 19.5, 60.73]]}, {"timestamp": 1578772252005, "ltp": 19.5, "tv": 3674.36, "trd": NaN, "batb": NaN, "batl": [[1, 20, 107.18]]}, {"timestamp": 1578772252994, "ltp": 19.0, "tv": 3675.75, "trd": [[19, 1341.5]], "batb": [[0, 19, 171.06]], "batl": NaN}, {"timestamp": 1578772253994, "ltp": 19.0, "tv": 3705.19, "trd": [[19, 1370.94]], "batb": [[0, 19, 156.34]], "batl": NaN}, {"timestamp": 1578772255991, "ltp": 19.0, "tv": 3705.64, "trd": [[19, 1371.39]], "batb": [[0, 19, 156.11]], "batl": NaN}, {"timestamp": 1578772256986, "ltp": 19.0, "tv": 3705.64, "trd": NaN, "batb": [[2, 18, 116.16]], "batl": NaN}, {"timestamp": 1578772262972, "ltp": 19.0, "tv": 3705.64, "trd": NaN, "batb": [[2, 18, 107.76]], "batl": NaN}, {"timestamp": 1578772264028, "ltp": 19.0, "tv": 3705.64, "trd": NaN, "batb": NaN, "batl": [[2, 21, 512.92]]}, {"timestamp": 1578772265855, "ltp": 19.5, "tv": 3709.96, "trd": [[19, 1372.07], [19.5, 1669.32]], "batb": [[0, 19, 155.77]], "batl": [[0, 19.5, 58.91]]}, {"timestamp": 1578772270045, "ltp": 19.0, "tv": 3713.7, "trd": [[19, 1375.81]], "batb": [[0, 19, 153.9]], "batl": [[1, 20, 73.18]]}, {"timestamp": 1578772272003, "ltp": 19.0, "tv": 3713.7, "trd": NaN, "batb": NaN, "batl": [[2, 21, 714.16]]}, {"timestamp": 1578772276028, "ltp": 19.0, "tv": 3768.89, "trd": [[19, 1431]], "batb": [[0, 19, 126.3]], "batl": NaN}, {"timestamp": 1578772278020, "ltp": 19.0, "tv": 3768.89, "trd": NaN, "batb": NaN, "batl": [[0, 19.5, 53.67]]}, {"timestamp": 1578772282055, "ltp": 19.0, "tv": 3768.89, "trd": NaN, "batb": NaN, "batl": [[1, 20, 65.52]]}, {"timestamp": 1578772283045, "ltp": 19.0, "tv": 3768.89, "trd": NaN, "batb": NaN, "batl": [[0, 19.5, 63.7]]}, {"timestamp": 1578772293949, "ltp": 19.0, "tv": 3768.89, "trd": NaN, "batb": NaN, "batl": [[2, 21, 686.16]]}, {"timestamp": 1578772294860, "ltp": 19.0, "tv": 3768.89, "trd": NaN, "batb": [[1, 18.5, 88.9], [2, 18, 59.3]], "batl": [[1, 20, 17.05]]}, {"timestamp": 1578772296040, "ltp": 19.0, "tv": 3768.89, "trd": NaN, "batb": [[1, 18.5, 78.67], [2, 18, 48.03]], "batl": [[1, 21, 472.42], [2, 21, 0]]}, {"timestamp": 1578772315976, "ltp": 19.0, "tv": 3768.89, "trd": NaN, "batb": [[1, 18.5, 25]], "batl": [[0, 19.5, 10.03]]}, {"timestamp": 1578772328650, "ltp": 19.0, "tv": 3768.89, "trd": NaN, "batb": [[2, 18, 45.54]], "batl": NaN}, {"timestamp": 1578772337826, "ltp": 19.0, "tv": 3768.89, "trd": NaN, "batb": [[0, 19, 126.22]], "batl": NaN}, {"timestamp": 1578772347979, "ltp": 19.0, "tv": 3768.89, "trd": NaN, "batb": [[0, 18, 8.8], [1, 17, 3.45], [2, 10, 29.36]], "batl": [[0, 21, 472.42], [1, 21, 0]]}]}, {"runnerId": 5851483, "odds": [{"timestamp": 1578695049907, "ltp": 1.05, "tv": 0.39, "trd": [[1.05, 0.4]], "batb": [[0, 1.05, 4999.8]], "batl": NaN}, {"timestamp": 1578697322873, "ltp": 1.05, "tv": 0.39, "trd": NaN, "batb": [[1, 1.04, 26539.02], [2, 1.03, 27483.69]], "batl": [[0, 1.06, 4106.06], [1, 1.09, 1.7], [2, 1.1, 1.7]]}, {"timestamp": 1578698669947, "ltp": 1.05, "tv": 4.99, "trd": [[1.05, 4.99]], "batb": [[0, 1.05, 4997.5]], "batl": NaN}, {"timestamp": 1578703176969, "ltp": 1.05, "tv": 4.99, "trd": NaN, "batb": [[0, 1.04, 31536.52], [1, 1.03, 27483.69], [2, 1.03, 0]], "batl": NaN}, {"timestamp": 1578721243493, "ltp": 1.05, "tv": 4.99, "trd": NaN, "batb": [[0, 1.05, 13.78], [1, 1.04, 31536.52], [2, 1.03, 27483.69]], "batl": NaN}, {"timestamp": 1578721249465, "ltp": 1.05, "tv": 4.99, "trd": NaN, "batb": [[1, 1.04, 31551.83]], "batl": NaN}, {"timestamp": 1578721693923, "ltp": 1.05, "tv": 4.99, "trd": NaN, "batb": [[0, 1.05, 15.78]], "batl": NaN}, {"timestamp": 1578725720387, "ltp": 1.05, "tv": 4.99, "trd": NaN, "batb": NaN, "batl": [[2, 1.1, 4]]}, {"timestamp": 1578725724768, "ltp": 1.05, "tv": 4.99, "trd": NaN, "batb": NaN, "batl": [[2, 1.1, 4.08]]}, {"timestamp": 1578725728991, "ltp": 1.05, "tv": 4.99, "trd": NaN, "batb": NaN, "batl": [[2, 1.1, 1.7]]}, {"timestamp": 1578725729093, "ltp": 1.05, "tv": 5.16, "trd": [[1.05, 5.16]], "batb": [[0, 1.05, 15.7]], "batl": NaN}, {"timestamp": 1578727135702, "ltp": 1.05, "tv": 9.16, "trd": [[1.05, 9.16]], "batb": [[0, 1.05, 13.7]], "batl": NaN}, {"timestamp": 1578727380221, "ltp": 1.05, "tv": 13.15, "trd": [[1.05, 13.16]], "batb": [[0, 1.05, 11.7]], "batl": NaN}, {"timestamp": 1578733167434, "ltp": 1.05, "tv": 17.93, "trd": [[1.05, 17.94]], "batb": [[0, 1.05, 9.31]], "batl": NaN}, {"timestamp": 1578738458804, "ltp": 1.05, "tv": 36.55, "trd": [[1.05, 36.56]], "batb": [[0, 1.04, 31551.83], [1, 1.03, 27483.69], [2, 1.03, 0]], "batl": [[0, 1.05, 143.81], [1, 1.06, 4106.06], [2, 1.09, 1.7]]}, {"timestamp": 1578739150012, "ltp": 1.05, "tv": 179.93, "trd": [[1.05, 179.94]], "batb": NaN, "batl": [[0, 1.05, 72.12]]}, {"timestamp": 1578739348870, "ltp": 1.05, "tv": 214.92, "trd": [[1.05, 214.92]], "batb": NaN, "batl": [[0, 1.05, 54.62]]}, {"timestamp": 1578739709947, "ltp": 1.05, "tv": 269.09, "trd": [[1.05, 269.1]], "batb": NaN, "batl": [[0, 1.05, 27.54]]}, {"timestamp": 1578739943885, "ltp": 1.05, "tv": 286.07, "trd": [[1.05, 286.08]], "batb": NaN, "batl": [[0, 1.05, 19.05]]}, {"timestamp": 1578740336991, "ltp": 1.05, "tv": 323.85, "trd": [[1.05, 323.85]], "batb": NaN, "batl": [[0, 1.06, 4106.22], [1, 1.09, 1.7], [2, 1.1, 1.7]]}, {"timestamp": 1578741141765, "ltp": 1.04, "tv": 476.96, "trd": [[1.04, 153.12]], "batb": [[0, 1.04, 31475.28]], "batl": NaN}, {"timestamp": 1578741248546, "ltp": 1.04, "tv": 476.96, "trd": NaN, "batb": [[1, 1.03, 26483.69]], "batl": NaN}, {"timestamp": 1578741321397, "ltp": 1.04, "tv": 476.96, "trd": NaN, "batb": [[0, 1.04, 32225.28]], "batl": NaN}, {"timestamp": 1578741522988, "ltp": 1.04, "tv": 476.96, "trd": NaN, "batb": [[0, 1.04, 47225.28]], "batl": NaN}, {"timestamp": 1578742937669, "ltp": 1.04, "tv": 850.76, "trd": [[1.04, 526.92]], "batb": [[0, 1.04, 47038.37]], "batl": NaN}, {"timestamp": 1578745741810, "ltp": 1.04, "tv": 850.76, "trd": NaN, "batb": NaN, "batl": [[2, 1.1, 21.7]]}, {"timestamp": 1578746448531, "ltp": 1.04, "tv": 850.76, "trd": NaN, "batb": [[0, 1.04, 47045.46]], "batl": NaN}, {"timestamp": 1578747092910, "ltp": 1.04, "tv": 855.09, "trd": [[1.04, 527.24], [1.05, 327.85]], "batb": [[0, 1.04, 47045.3]], "batl": [[0, 1.06, 4106.06]]}, {"timestamp": 1578747519002, "ltp": 1.04, "tv": 855.09, "trd": NaN, "batb": [[0, 1.05, 1990.51], [1, 1.04, 47045.3], [2, 1.03, 26483.69]], "batl": NaN}, {"timestamp": 1578749466432, "ltp": 1.04, "tv": 855.09, "trd": NaN, "batb": NaN, "batl": [[2, 1.1, 24.76]]}, {"timestamp": 1578749480285, "ltp": 1.04, "tv": 855.09, "trd": NaN, "batb": NaN, "batl": [[2, 1.1, 26.45]]}, {"timestamp": 1578749491949, "ltp": 1.04, "tv": 855.09, "trd": NaN, "batb": NaN, "batl": [[2, 1.1, 23.39]]}, {"timestamp": 1578752310065, "ltp": 1.05, "tv": 858.82, "trd": [[1.05, 331.59]], "batb": [[0, 1.05, 1988.64]], "batl": NaN}, {"timestamp": 1578752846715, "ltp": 1.05, "tv": 858.82, "trd": NaN, "batb": [[0, 1.05, 8988.64]], "batl": NaN}, {"timestamp": 1578752852195, "ltp": 1.05, "tv": 858.82, "trd": NaN, "batb": [[0, 1.05, 10979.15]], "batl": NaN}, {"timestamp": 1578753052918, "ltp": 1.05, "tv": 870.03, "trd": [[1.05, 342.8]], "batb": [[0, 1.05, 10973.54]], "batl": NaN}, {"timestamp": 1578755283459, "ltp": 1.06, "tv": 900.89, "trd": [[1.06, 30.85]], "batb": NaN, "batl": [[0, 1.06, 4075.21]]}, {"timestamp": 1578756589048, "ltp": 1.06, "tv": 900.89, "trd": NaN, "batb": [[0, 1.05, 15973.54]], "batl": NaN}, {"timestamp": 1578756594175, "ltp": 1.06, "tv": 900.89, "trd": NaN, "batb": NaN, "batl": [[1, 1.07, 5000], [2, 1.09, 1.7]]}, {"timestamp": 1578757676992, "ltp": 1.05, "tv": 910.89, "trd": [[1.05, 352.8]], "batb": [[0, 1.05, 15968.54]], "batl": NaN}, {"timestamp": 1578757783970, "ltp": 1.05, "tv": 910.89, "trd": NaN, "batb": [[1, 1.04, 47239.98]], "batl": NaN}, {"timestamp": 1578758540943, "ltp": 1.05, "tv": 918.54, "trd": [[1.05, 360.46]], "batb": [[0, 1.05, 15964.71]], "batl": NaN}, {"timestamp": 1578759820976, "ltp": 1.05, "tv": 918.54, "trd": NaN, "batb": [[2, 1.03, 26493.19]], "batl": NaN}, {"timestamp": 1578760117035, "ltp": 1.05, "tv": 958.54, "trd": [[1.05, 400.45]], "batb": [[0, 1.05, 15944.72]], "batl": NaN}, {"timestamp": 1578761540675, "ltp": 1.05, "tv": 984.33, "trd": [[1.05, 426.24]], "batb": [[0, 1.05, 15931.83]], "batl": NaN}, {"timestamp": 1578761880851, "ltp": 1.05, "tv": 988.06, "trd": [[1.05, 429.98]], "batb": [[0, 1.05, 15929.96]], "batl": NaN}, {"timestamp": 1578762045037, "ltp": 1.05, "tv": 988.06, "trd": NaN, "batb": [[0, 1.05, 15961.61]], "batl": [[0, 1.06, 4106.86]]}, {"timestamp": 1578762079953, "ltp": 1.05, "tv": 988.06, "trd": NaN, "batb": NaN, "batl": [[1, 1.07, 5074.76]]}, {"timestamp": 1578763045599, "ltp": 1.05, "tv": 988.06, "trd": NaN, "batb": [[2, 1.03, 26493.45]], "batl": NaN}, {"timestamp": 1578763600777, "ltp": 1.05, "tv": 991.8, "trd": [[1.05, 433.72]], "batb": [[0, 1.05, 15959.74]], "batl": NaN}, {"timestamp": 1578763684617, "ltp": 1.05, "tv": 991.8, "trd": NaN, "batb": NaN, "batl": [[2, 1.08, 180]]}, {"timestamp": 1578763707972, "ltp": 1.05, "tv": 991.8, "trd": NaN, "batb": NaN, "batl": [[2, 1.08, 192.77]]}, {"timestamp": 1578763711355, "ltp": 1.05, "tv": 991.8, "trd": NaN, "batb": NaN, "batl": [[2, 1.08, 180]]}, {"timestamp": 1578763725978, "ltp": 1.05, "tv": 991.8, "trd": NaN, "batb": NaN, "batl": [[2, 1.08, 192.77]]}, {"timestamp": 1578763887310, "ltp": 1.05, "tv": 991.8, "trd": NaN, "batb": [[0, 1.05, 15928.09]], "batl": [[0, 1.06, 4075.21]]}, {"timestamp": 1578763945988, "ltp": 1.05, "tv": 991.8, "trd": NaN, "batb": [[0, 1.05, 15959.74]], "batl": [[0, 1.06, 4106.86]]}, {"timestamp": 1578764009878, "ltp": 1.05, "tv": 991.8, "trd": NaN, "batb": [[0, 1.05, 15928.09]], "batl": [[0, 1.06, 4075.21]]}, {"timestamp": 1578764070874, "ltp": 1.05, "tv": 991.8, "trd": NaN, "batb": [[0, 1.05, 15959.74]], "batl": [[0, 1.06, 4106.86]]}, {"timestamp": 1578764076870, "ltp": 1.06, "tv": 1017.34, "trd": [[1.06, 56.39]], "batb": NaN, "batl": [[0, 1.06, 4094.09]]}, {"timestamp": 1578764874438, "ltp": 1.06, "tv": 1017.34, "trd": NaN, "batb": [[0, 1.05, 15928.09]], "batl": [[0, 1.06, 4062.44]]}, {"timestamp": 1578764883948, "ltp": 1.06, "tv": 1017.34, "trd": NaN, "batb": [[0, 1.05, 15959.74]], "batl": [[0, 1.06, 4094.09]]}, {"timestamp": 1578765299749, "ltp": 1.06, "tv": 1030.16, "trd": [[1.06, 69.21]], "batb": NaN, "batl": [[0, 1.06, 4087.68]]}, {"timestamp": 1578765592938, "ltp": 1.05, "tv": 1033.89, "trd": [[1.05, 437.45]], "batb": [[0, 1.05, 15957.87]], "batl": NaN}, {"timestamp": 1578765970033, "ltp": 1.05, "tv": 1033.89, "trd": NaN, "batb": NaN, "batl": [[0, 1.06, 4424.96], [1, 1.07, 5408.88], [2, 1.08, 523.79]]}, {"timestamp": 1578765972005, "ltp": 1.05, "tv": 1033.89, "trd": NaN, "batb": [[0, 1.05, 16298.36], [1, 1.04, 47583.74], [2, 1.03, 26840.55]], "batl": NaN}, {"timestamp": 1578766413615, "ltp": 1.05, "tv": 1033.89, "trd": NaN, "batb": NaN, "batl": [[2, 1.08, 694.04]]}, {"timestamp": 1578766480182, "ltp": 1.05, "tv": 1033.89, "trd": NaN, "batb": NaN, "batl": [[0, 1.06, 5276.17]]}, {"timestamp": 1578766499009, "ltp": 1.05, "tv": 1041.89, "trd": [[1.05, 445.45]], "batb": [[0, 1.05, 16294.36]], "batl": NaN}, {"timestamp": 1578766571757, "ltp": 1.05, "tv": 1041.89, "trd": NaN, "batb": [[0, 1.05, 16262.71]], "batl": [[0, 1.06, 5244.52]]}, {"timestamp": 1578766580930, "ltp": 1.05, "tv": 1085.89, "trd": [[1.05, 489.45]], "batb": [[0, 1.05, 16240.71]], "batl": NaN}, {"timestamp": 1578766591042, "ltp": 1.05, "tv": 1085.89, "trd": NaN, "batb": [[0, 1.05, 16272.36]], "batl": [[0, 1.06, 5276.17]]}, {"timestamp": 1578766628009, "ltp": 1.05, "tv": 1085.89, "trd": NaN, "batb": [[0, 1.05, 16240.71]], "batl": [[0, 1.06, 5244.52]]}, {"timestamp": 1578766642726, "ltp": 1.05, "tv": 1085.89, "trd": NaN, "batb": [[0, 1.05, 16272.36]], "batl": [[0, 1.06, 5276.17]]}, {"timestamp": 1578766712948, "ltp": 1.05, "tv": 2773.89, "trd": [[1.05, 2177.45]], "batb": [[0, 1.05, 15428.36]], "batl": NaN}, {"timestamp": 1578766954033, "ltp": 1.05, "tv": 2773.89, "trd": NaN, "batb": [[1, 1.04, 47389.06]], "batl": NaN}, {"timestamp": 1578767002022, "ltp": 1.05, "tv": 2773.89, "trd": NaN, "batb": NaN, "batl": [[0, 1.06, 9720.17]]}, {"timestamp": 1578767005889, "ltp": 1.05, "tv": 2773.89, "trd": NaN, "batb": NaN, "batl": [[2, 1.08, 3194.04]]}, {"timestamp": 1578767016024, "ltp": 1.05, "tv": 2773.89, "trd": NaN, "batb": NaN, "batl": [[0, 1.06, 13220.17]]}, {"timestamp": 1578767021210, "ltp": 1.05, "tv": 2773.89, "trd": NaN, "batb": [[0, 1.05, 15396.71]], "batl": [[0, 1.06, 13188.52]]}, {"timestamp": 1578767060959, "ltp": 1.05, "tv": 2773.89, "trd": NaN, "batb": [[0, 1.05, 15428.36]], "batl": [[0, 1.06, 13220.17]]}, {"timestamp": 1578767122763, "ltp": 1.05, "tv": 2773.89, "trd": NaN, "batb": [[1, 1.04, 49552.25]], "batl": NaN}, {"timestamp": 1578767545012, "ltp": 1.05, "tv": 2782.4, "trd": [[1.05, 2185.96]], "batb": [[0, 1.05, 15424.1]], "batl": NaN}, {"timestamp": 1578767557020, "ltp": 1.05, "tv": 4782.4, "trd": [[1.05, 4185.96]], "batb": [[0, 1.05, 14424.1]], "batl": NaN}, {"timestamp": 1578767742679, "ltp": 1.05, "tv": 4925.41, "trd": [[1.05, 4328.97]], "batb": [[0, 1.05, 14352.6]], "batl": NaN}, {"timestamp": 1578767749497, "ltp": 1.05, "tv": 4929.77, "trd": [[1.05, 4333.33]], "batb": [[0, 1.05, 14350.42]], "batl": NaN}, {"timestamp": 1578767818199, "ltp": 1.05, "tv": 4943.55, "trd": [[1.05, 4347.11]], "batb": [[0, 1.05, 14343.53]], "batl": NaN}, {"timestamp": 1578767838033, "ltp": 1.05, "tv": 4947.28, "trd": [[1.05, 4350.84]], "batb": [[0, 1.05, 14341.66]], "batl": NaN}, {"timestamp": 1578767872970, "ltp": 1.05, "tv": 5712.86, "trd": [[1.05, 5116.42]], "batb": [[0, 1.05, 13958.87]], "batl": NaN}, {"timestamp": 1578767883783, "ltp": 1.05, "tv": 5755.95, "trd": [[1.05, 5159.51]], "batb": [[0, 1.05, 13937.33]], "batl": NaN}, {"timestamp": 1578767896708, "ltp": 1.05, "tv": 5823.59, "trd": [[1.05, 5227.15]], "batb": [[0, 1.05, 13903.51]], "batl": NaN}, {"timestamp": 1578767960029, "ltp": 1.05, "tv": 5823.59, "trd": NaN, "batb": NaN, "batl": [[0, 1.06, 13208.19]]}, {"timestamp": 1578768112978, "ltp": 1.05, "tv": 5826.99, "trd": [[1.05, 5230.55]], "batb": [[0, 1.05, 13901.81]], "batl": NaN}, {"timestamp": 1578768193930, "ltp": 1.05, "tv": 5826.99, "trd": NaN, "batb": [[0, 1.05, 15093.5]], "batl": NaN}, {"timestamp": 1578768310908, "ltp": 1.05, "tv": 5826.99, "trd": NaN, "batb": [[2, 1.03, 26830.79]], "batl": NaN}, {"timestamp": 1578768447889, "ltp": 1.05, "tv": 6599.25, "trd": [[1.05, 6002.81]], "batb": [[0, 1.05, 14707.37]], "batl": NaN}, {"timestamp": 1578768471701, "ltp": 1.05, "tv": 6599.25, "trd": NaN, "batb": [[0, 1.05, 14751.3]], "batl": NaN}, {"timestamp": 1578768505918, "ltp": 1.05, "tv": 6599.25, "trd": NaN, "batb": NaN, "batl": [[0, 1.06, 13378.43]]}, {"timestamp": 1578768527858, "ltp": 1.05, "tv": 6599.59, "trd": [[1.05, 6003.15]], "batb": [[0, 1.05, 14751.13]], "batl": NaN}, {"timestamp": 1578768532770, "ltp": 1.05, "tv": 6979.23, "trd": [[1.05, 6382.79]], "batb": [[0, 1.05, 14561.31]], "batl": NaN}, {"timestamp": 1578768553972, "ltp": 1.05, "tv": 6979.23, "trd": NaN, "batb": [[0, 1.05, 14565.21]], "batl": NaN}, {"timestamp": 1578768645605, "ltp": 1.05, "tv": 6985.21, "trd": [[1.05, 6388.77]], "batb": [[0, 1.05, 14562.22]], "batl": NaN}, {"timestamp": 1578768697940, "ltp": 1.05, "tv": 7158.27, "trd": [[1.05, 6561.83]], "batb": [[0, 1.05, 14475.69]], "batl": NaN}, {"timestamp": 1578768745898, "ltp": 1.05, "tv": 7158.27, "trd": NaN, "batb": [[0, 1.05, 14471.79]], "batl": NaN}, {"timestamp": 1578768764715, "ltp": 1.06, "tv": 7166.08, "trd": [[1.06, 77.02]], "batb": NaN, "batl": [[0, 1.06, 13374.53]]}, {"timestamp": 1578768817881, "ltp": 1.06, "tv": 7166.08, "trd": NaN, "batb": [[0, 1.05, 14427.86]], "batl": NaN}, {"timestamp": 1578768818609, "ltp": 1.06, "tv": 7166.08, "trd": NaN, "batb": NaN, "batl": [[0, 1.06, 13419.52]]}, {"timestamp": 1578768893016, "ltp": 1.06, "tv": 7166.08, "trd": NaN, "batb": NaN, "batl": [[2, 1.08, 3196.05]]}, {"timestamp": 1578768963929, "ltp": 1.05, "tv": 7170.67, "trd": [[1.05, 6566.42]], "batb": [[0, 1.05, 14425.56]], "batl": NaN}, {"timestamp": 1578768999941, "ltp": 1.05, "tv": 7170.67, "trd": NaN, "batb": [[0, 1.05, 14469.44]], "batl": NaN}, {"timestamp": 1578769020003, "ltp": 1.05, "tv": 7232.52, "trd": [[1.05, 6628.27]], "batb": [[0, 1.05, 14438.52]], "batl": NaN}, {"timestamp": 1578769041687, "ltp": 1.06, "tv": 7236.13, "trd": [[1.06, 80.63]], "batb": NaN, "batl": [[0, 1.06, 13417.71]]}, {"timestamp": 1578769069952, "ltp": 1.05, "tv": 7242.25, "trd": [[1.05, 6634.39]], "batb": [[0, 1.05, 14435.46]], "batl": NaN}, {"timestamp": 1578769072982, "ltp": 1.05, "tv": 7285.93, "trd": [[1.05, 6678.07]], "batb": [[0, 1.05, 14413.62]], "batl": NaN}, {"timestamp": 1578769080990, "ltp": 1.06, "tv": 7331.86, "trd": [[1.06, 126.56]], "batb": NaN, "batl": [[0, 1.06, 13394.75]]}, {"timestamp": 1578769085973, "ltp": 1.05, "tv": 7507.73, "trd": [[1.05, 6853.93]], "batb": [[0, 1.05, 14325.69]], "batl": NaN}, {"timestamp": 1578769089886, "ltp": 1.05, "tv": 7507.73, "trd": NaN, "batb": [[0, 1.05, 14281.81]], "batl": NaN}, {"timestamp": 1578769124939, "ltp": 1.05, "tv": 7592.85, "trd": [[1.05, 6939.05]], "batb": [[0, 1.05, 14239.25]], "batl": NaN}, {"timestamp": 1578769130925, "ltp": 1.05, "tv": 7592.85, "trd": NaN, "batb": NaN, "batl": [[0, 1.06, 13427.75]]}, {"timestamp": 1578769141047, "ltp": 1.05, "tv": 7596.59, "trd": [[1.05, 6942.79]], "batb": [[0, 1.05, 14237.38]], "batl": NaN}, {"timestamp": 1578769207948, "ltp": 1.05, "tv": 7600.18, "trd": [[1.04, 527.09], [1.05, 6946.56], [1.06, 126.53]], "batb": [[0, 1.05, 14234.52], [1, 1.04, 49548.81], [2, 1.03, 26827.27]], "batl": [[0, 1.06, 13427.57], [1, 1.07, 5408.86]]}, {"timestamp": 1578769282948, "ltp": 1.06, "tv": 7603.47, "trd": [[1.06, 129.82]], "batb": NaN, "batl": [[0, 1.06, 13425.92]]}, {"timestamp": 1578769292880, "ltp": 1.05, "tv": 8684.21, "trd": [[1.05, 8027.3]], "batb": [[0, 1.05, 13694.15]], "batl": NaN}, {"timestamp": 1578769423053, "ltp": 1.06, "tv": 8750.03, "trd": [[1.06, 195.64]], "batb": NaN, "batl": [[0, 1.06, 13393.01]]}, {"timestamp": 1578769428555, "ltp": 1.06, "tv": 8815.85, "trd": [[1.06, 261.46]], "batb": NaN, "batl": [[0, 1.06, 13360.1]]}, {"timestamp": 1578769481952, "ltp": 1.05, "tv": 9215.85, "trd": [[1.05, 8427.3]], "batb": [[0, 1.05, 13494.15]], "batl": NaN}, {"timestamp": 1578769505955, "ltp": 1.05, "tv": 9215.85, "trd": NaN, "batb": NaN, "batl": [[0, 1.06, 14211.31]]}, {"timestamp": 1578769526906, "ltp": 1.05, "tv": 9215.85, "trd": NaN, "batb": NaN, "batl": [[1, 1.07, 5411.36]]}, {"timestamp": 1578769532208, "ltp": 1.05, "tv": 9215.85, "trd": NaN, "batb": NaN, "batl": [[1, 1.07, 5408.86]]}, {"timestamp": 1578769558021, "ltp": 1.06, "tv": 9828.13, "trd": [[1.06, 873.73]], "batb": NaN, "batl": [[0, 1.06, 13905.17]]}, {"timestamp": 1578769574982, "ltp": 1.05, "tv": 9849.8, "trd": [[1.05, 8448.98]], "batb": [[0, 1.05, 13483.31]], "batl": NaN}, {"timestamp": 1578769602986, "ltp": 1.05, "tv": 9849.8, "trd": NaN, "batb": [[0, 1.05, 30490.81]], "batl": NaN}, {"timestamp": 1578769757960, "ltp": 1.05, "tv": 9849.88, "trd": [[1.05, 8449.06]], "batb": [[0, 1.05, 30490.77]], "batl": NaN}, {"timestamp": 1578769883030, "ltp": 1.05, "tv": 9859.07, "trd": [[1.05, 8458.24]], "batb": [[0, 1.05, 30486.18]], "batl": NaN}, {"timestamp": 1578769890730, "ltp": 1.05, "tv": 9859.07, "trd": NaN, "batb": [[0, 1.05, 32216.74]], "batl": NaN}, {"timestamp": 1578769921978, "ltp": 1.05, "tv": 9859.07, "trd": NaN, "batb": NaN, "batl": [[2, 1.08, 3219.01]]}, {"timestamp": 1578770069943, "ltp": 1.05, "tv": 9862.8, "trd": [[1.05, 8461.98]], "batb": [[0, 1.05, 32214.87]], "batl": NaN}, {"timestamp": 1578770083536, "ltp": 1.05, "tv": 9862.8, "trd": NaN, "batb": [[0, 1.05, 32183.16]], "batl": [[0, 1.06, 13885.46]]}, {"timestamp": 1578770089990, "ltp": 1.05, "tv": 9862.8, "trd": NaN, "batb": [[0, 1.05, 32214.87]], "batl": [[0, 1.06, 13917.17]]}, {"timestamp": 1578770114687, "ltp": 1.05, "tv": 9881.17, "trd": [[1.05, 8480.35]], "batb": [[0, 1.05, 32205.69]], "batl": NaN}, {"timestamp": 1578770122027, "ltp": 1.05, "tv": 9881.17, "trd": NaN, "batb": NaN, "batl": [[0, 1.06, 13926.35]]}, {"timestamp": 1578770132016, "ltp": 1.05, "tv": 9881.17, "trd": NaN, "batb": NaN, "batl": [[1, 1.07, 5418.04]]}, {"timestamp": 1578770179051, "ltp": 1.06, "tv": 9891.99, "trd": [[1.06, 884.56]], "batb": NaN, "batl": [[0, 1.06, 13920.94]]}, {"timestamp": 1578770240962, "ltp": 1.05, "tv": 9905.07, "trd": [[1.05, 8493.43]], "batb": [[0, 1.05, 32199.15]], "batl": NaN}, {"timestamp": 1578770266007, "ltp": 1.06, "tv": 9905.23, "trd": [[1.06, 884.72]], "batb": NaN, "batl": [[0, 1.06, 13920.86]]}, {"timestamp": 1578770301832, "ltp": 1.05, "tv": 9931.25, "trd": [[1.05, 8519.45]], "batb": [[0, 1.05, 32186.14]], "batl": NaN}, {"timestamp": 1578770334877, "ltp": 1.06, "tv": 9936.67, "trd": [[1.06, 890.13]], "batb": NaN, "batl": [[0, 1.06, 13918.16]]}, {"timestamp": 1578770339992, "ltp": 1.05, "tv": 9955.03, "trd": [[1.05, 8537.81]], "batb": [[0, 1.05, 32176.96]], "batl": NaN}, {"timestamp": 1578770345979, "ltp": 1.05, "tv": 9955.03, "trd": NaN, "batb": NaN, "batl": [[0, 1.06, 13927.34]]}, {"timestamp": 1578770359015, "ltp": 1.05, "tv": 9955.03, "trd": NaN, "batb": NaN, "batl": [[1, 1.07, 5428.76]]}, {"timestamp": 1578770407050, "ltp": 1.05, "tv": 10484.49, "trd": [[1.05, 9067.27]], "batb": [[0, 1.05, 31912.23]], "batl": NaN}, {"timestamp": 1578770507952, "ltp": 1.05, "tv": 10484.49, "trd": NaN, "batb": [[0, 1.05, 60285.57]], "batl": NaN}, {"timestamp": 1578770536914, "ltp": 1.05, "tv": 10484.49, "trd": NaN, "batb": NaN, "batl": [[1, 1.07, 5476.21]]}, {"timestamp": 1578770540796, "ltp": 1.05, "tv": 10489.09, "trd": [[1.05, 9071.87]], "batb": [[0, 1.05, 60283.27]], "batl": NaN}, {"timestamp": 1578770580974, "ltp": 1.05, "tv": 10495.89, "trd": [[1.05, 9078.67]], "batb": [[0, 1.05, 60279.87]], "batl": NaN}, {"timestamp": 1578770584049, "ltp": 1.05, "tv": 10695.89, "trd": [[1.05, 9278.67]], "batb": [[0, 1.05, 60179.87]], "batl": NaN}, {"timestamp": 1578770589959, "ltp": 1.05, "tv": 11105.71, "trd": [[1.05, 9688.49]], "batb": [[0, 1.05, 59974.96]], "batl": NaN}, {"timestamp": 1578770590973, "ltp": 1.05, "tv": 11105.71, "trd": NaN, "batb": NaN, "batl": [[1, 1.07, 5428.76]]}, {"timestamp": 1578770631900, "ltp": 1.05, "tv": 11151.63, "trd": [[1.05, 9734.41]], "batb": [[0, 1.05, 59952]], "batl": NaN}, {"timestamp": 1578770689996, "ltp": 1.05, "tv": 11161.63, "trd": [[1.05, 9744.41]], "batb": [[0, 1.05, 59947]], "batl": NaN}, {"timestamp": 1578770701008, "ltp": 1.05, "tv": 11161.63, "trd": NaN, "batb": [[1, 1.04, 49558.81]], "batl": NaN}, {"timestamp": 1578770718024, "ltp": 1.05, "tv": 11161.63, "trd": NaN, "batb": NaN, "batl": [[1, 1.07, 5439.78]]}, {"timestamp": 1578770731005, "ltp": 1.05, "tv": 11161.63, "trd": NaN, "batb": NaN, "batl": [[1, 1.07, 5641.52]]}, {"timestamp": 1578770776037, "ltp": 1.06, "tv": 11165.24, "trd": [[1.06, 893.74]], "batb": NaN, "batl": [[0, 1.06, 13925.53]]}, {"timestamp": 1578770786971, "ltp": 1.06, "tv": 11171.25, "trd": [[1.06, 899.74]], "batb": NaN, "batl": [[0, 1.06, 13922.53]]}, {"timestamp": 1578770790992, "ltp": 1.06, "tv": 11174.86, "trd": [[1.06, 903.35]], "batb": NaN, "batl": [[0, 1.06, 13920.73]]}, {"timestamp": 1578770820022, "ltp": 1.06, "tv": 11174.86, "trd": NaN, "batb": NaN, "batl": [[1, 1.07, 5801.89]]}, {"timestamp": 1578770821999, "ltp": 1.05, "tv": 11218.12, "trd": [[1.05, 9787.68]], "batb": [[0, 1.05, 59925.37]], "batl": NaN}, {"timestamp": 1578770830001, "ltp": 1.05, "tv": 11261.38, "trd": [[1.05, 9830.94]], "batb": [[0, 1.05, 59903.74]], "batl": NaN}, {"timestamp": 1578770836915, "ltp": 1.05, "tv": 11273.38, "trd": [[1.05, 9842.94]], "batb": [[0, 1.05, 59897.74]], "batl": NaN}, {"timestamp": 1578770856957, "ltp": 1.05, "tv": 11281.6, "trd": [[1.05, 9851.16]], "batb": [[0, 1.05, 59893.63]], "batl": NaN}, {"timestamp": 1578770900041, "ltp": 1.05, "tv": 11538.48, "trd": [[1.05, 10108.04]], "batb": [[0, 1.05, 59765.19]], "batl": NaN}, {"timestamp": 1578770903005, "ltp": 1.06, "tv": 11560.48, "trd": [[1.06, 925.35]], "batb": NaN, "batl": [[0, 1.06, 13909.73]]}, {"timestamp": 1578770920934, "ltp": 1.06, "tv": 11560.48, "trd": NaN, "batb": NaN, "batl": [[0, 1.06, 13961.65]]}, {"timestamp": 1578770932956, "ltp": 1.06, "tv": 11560.48, "trd": NaN, "batb": NaN, "batl": [[0, 1.06, 13916.66]]}, {"timestamp": 1578770953979, "ltp": 1.05, "tv": 11565.58, "trd": [[1.05, 10113.14]], "batb": [[0, 1.05, 59762.64]], "batl": NaN}, {"timestamp": 1578770960021, "ltp": 1.06, "tv": 13265.58, "trd": [[1.06, 2625.35]], "batb": [[1, 1.04, 49582.91]], "batl": [[0, 1.06, 13066.66]]}, {"timestamp": 1578770968993, "ltp": 1.06, "tv": 13265.58, "trd": NaN, "batb": NaN, "batl": [[0, 1.06, 13754.08]]}, {"timestamp": 1578770970009, "ltp": 1.06, "tv": 13265.58, "trd": NaN, "batb": NaN, "batl": [[2, 1.08, 3228.58]]}, {"timestamp": 1578770976022, "ltp": 1.06, "tv": 13465.58, "trd": [[1.06, 2825.35]], "batb": NaN, "batl": [[0, 1.06, 13654.08]]}, {"timestamp": 1578770977022, "ltp": 1.05, "tv": 13665.58, "trd": [[1.05, 10313.14]], "batb": [[0, 1.05, 59662.64], [1, 1.04, 49590.91]], "batl": NaN}, {"timestamp": 1578770982926, "ltp": 1.05, "tv": 13665.58, "trd": NaN, "batb": NaN, "batl": [[0, 1.06, 13668.02]]}, {"timestamp": 1578770983819, "ltp": 1.05, "tv": 13665.58, "trd": NaN, "batb": [[1, 1.04, 49590.81]], "batl": NaN}, {"timestamp": 1578770990955, "ltp": 1.05, "tv": 13665.58, "trd": NaN, "batb": [[1, 1.04, 49558.81]], "batl": NaN}, {"timestamp": 1578770997045, "ltp": 1.05, "tv": 13665.58, "trd": NaN, "batb": NaN, "batl": [[0, 1.06, 12816.81]]}, {"timestamp": 1578771001961, "ltp": 1.05, "tv": 13665.58, "trd": NaN, "batb": [[2, 1.03, 26831.41]], "batl": NaN}, {"timestamp": 1578771006029, "ltp": 1.05, "tv": 14201.33, "trd": [[1.05, 10848.88]], "batb": [[0, 1.05, 59394.77], [1, 1.04, 49567.52]], "batl": NaN}, {"timestamp": 1578771006988, "ltp": 1.05, "tv": 14201.33, "trd": NaN, "batb": [[1, 1.04, 49559.52]], "batl": NaN}, {"timestamp": 1578771013973, "ltp": 1.05, "tv": 14201.33, "trd": NaN, "batb": [[1, 1.04, 49751.52], [2, 1.03, 27025.41]], "batl": [[1, 1.07, 5988.89], [2, 1.08, 3413.58]]}, {"timestamp": 1578771018851, "ltp": 1.05, "tv": 14201.33, "trd": NaN, "batb": NaN, "batl": [[0, 1.06, 12802.87]]}, {"timestamp": 1578771033027, "ltp": 1.05, "tv": 14229.2, "trd": [[1.05, 10876.76]], "batb": [[0, 1.05, 59380.83]], "batl": NaN}, {"timestamp": 1578771037054, "ltp": 1.05, "tv": 14229.2, "trd": NaN, "batb": [[1, 1.04, 49750.81]], "batl": NaN}, {"timestamp": 1578771045981, "ltp": 1.06, "tv": 14229.59, "trd": [[1.06, 2825.74]], "batb": NaN, "batl": [[0, 1.06, 12802.68]]}, {"timestamp": 1578771052902, "ltp": 1.05, "tv": 14349.59, "trd": [[1.05, 10996.76]], "batb": [[0, 1.05, 59320.83]], "batl": NaN}, {"timestamp": 1578771054001, "ltp": 1.05, "tv": 14349.59, "trd": NaN, "batb": NaN, "batl": [[0, 1.06, 12903.64]]}, {"timestamp": 1578771054960, "ltp": 1.05, "tv": 14349.59, "trd": NaN, "batb": NaN, "batl": [[1, 1.07, 5787.16]]}, {"timestamp": 1578771059983, "ltp": 1.05, "tv": 14353.59, "trd": [[1.05, 11000.76]], "batb": [[0, 1.05, 59318.83]], "batl": NaN}, {"timestamp": 1578771066997, "ltp": 1.05, "tv": 14358.78, "trd": [[1.05, 11005.96]], "batb": [[0, 1.05, 59316.23]], "batl": NaN}, {"timestamp": 1578771077005, "ltp": 1.05, "tv": 14817.99, "trd": [[1.05, 11465.16]], "batb": [[0, 1.05, 59086.63]], "batl": NaN}, {"timestamp": 1578771080008, "ltp": 1.05, "tv": 14817.99, "trd": NaN, "batb": NaN, "batl": [[1, 1.07, 5790.57]]}, {"timestamp": 1578771085973, "ltp": 1.05, "tv": 15955.45, "trd": [[1.05, 12602.62]], "batb": [[0, 1.05, 58522.17], [1, 1.04, 49772.93]], "batl": NaN}, {"timestamp": 1578771088956, "ltp": 1.05, "tv": 15955.45, "trd": NaN, "batb": NaN, "batl": [[1, 1.07, 5790.74]]}, {"timestamp": 1578771089953, "ltp": 1.05, "tv": 15955.45, "trd": NaN, "batb": [[0, 1.05, 58522.09]], "batl": NaN}, {"timestamp": 1578771090996, "ltp": 1.05, "tv": 15955.45, "trd": NaN, "batb": [[0, 1.05, 58522.07], [1, 1.04, 49772.85]], "batl": NaN}, {"timestamp": 1578771097928, "ltp": 1.05, "tv": 15955.79, "trd": [[1.05, 12602.96]], "batb": [[0, 1.05, 58521.76], [1, 1.04, 49772.74]], "batl": [[1, 1.07, 5790.57]]}, {"timestamp": 1578771099945, "ltp": 1.05, "tv": 15955.79, "trd": NaN, "batb": [[0, 1.05, 58521.72]], "batl": NaN}, {"timestamp": 1578771101957, "ltp": 1.05, "tv": 15955.79, "trd": NaN, "batb": NaN, "batl": [[0, 1.06, 12966.89]]}, {"timestamp": 1578771102966, "ltp": 1.05, "tv": 15955.79, "trd": NaN, "batb": [[0, 1.05, 58521.67]], "batl": NaN}, {"timestamp": 1578771103970, "ltp": 1.05, "tv": 15955.79, "trd": NaN, "batb": [[0, 1.05, 58521.65]], "batl": [[1, 1.07, 5787.16]]}, {"timestamp": 1578771105982, "ltp": 1.06, "tv": 15957.15, "trd": [[1.06, 2827.09]], "batb": [[0, 1.05, 58521.61]], "batl": [[0, 1.06, 12966.21]]}, {"timestamp": 1578771107055, "ltp": 1.06, "tv": 15957.15, "trd": NaN, "batb": [[0, 1.05, 58521.59], [1, 1.04, 49763.59]], "batl": NaN}, {"timestamp": 1578771117014, "ltp": 1.06, "tv": 15957.15, "trd": NaN, "batb": [[0, 1.05, 58517.73], [1, 1.04, 49750.81]], "batl": NaN}, {"timestamp": 1578771117969, "ltp": 1.06, "tv": 15957.15, "trd": NaN, "batb": [[0, 1.05, 58521.4]], "batl": NaN}, {"timestamp": 1578771120977, "ltp": 1.06, "tv": 15957.15, "trd": NaN, "batb": [[0, 1.05, 58521.34]], "batl": NaN}, {"timestamp": 1578771152972, "ltp": 1.06, "tv": 15957.15, "trd": NaN, "batb": [[0, 1.05, 58517.73]], "batl": NaN}, {"timestamp": 1578771156039, "ltp": 1.06, "tv": 15957.15, "trd": NaN, "batb": [[0, 1.05, 58521.14]], "batl": NaN}, {"timestamp": 1578771157054, "ltp": 1.06, "tv": 15957.15, "trd": NaN, "batb": [[0, 1.05, 58517.73]], "batl": NaN}, {"timestamp": 1578771157959, "ltp": 1.06, "tv": 15957.15, "trd": NaN, "batb": [[0, 1.05, 58521.11]], "batl": NaN}, {"timestamp": 1578771158864, "ltp": 1.06, "tv": 15957.15, "trd": NaN, "batb": [[0, 1.05, 58517.73]], "batl": NaN}, {"timestamp": 1578771159978, "ltp": 1.06, "tv": 15957.15, "trd": NaN, "batb": [[0, 1.05, 58521.07]], "batl": NaN}, {"timestamp": 1578771160980, "ltp": 1.06, "tv": 16009.99, "trd": [[1.06, 2879.93]], "batb": [[0, 1.05, 58521.05]], "batl": [[0, 1.06, 12939.79]]}, {"timestamp": 1578771173905, "ltp": 1.06, "tv": 16010.8, "trd": [[1.06, 2880.75]], "batb": NaN, "batl": [[0, 1.06, 12939.38]]}, {"timestamp": 1578771175009, "ltp": 1.06, "tv": 16010.8, "trd": NaN, "batb": [[0, 1.05, 58520.96]], "batl": NaN}, {"timestamp": 1578771176019, "ltp": 1.06, "tv": 16010.8, "trd": NaN, "batb": [[0, 1.05, 58520.94]], "batl": NaN}, {"timestamp": 1578771178989, "ltp": 1.06, "tv": 16010.8, "trd": NaN, "batb": [[0, 1.05, 58520.88]], "batl": [[0, 1.06, 13830.01]]}, {"timestamp": 1578771180006, "ltp": 1.06, "tv": 16010.8, "trd": NaN, "batb": [[0, 1.05, 58520.86]], "batl": NaN}, {"timestamp": 1578771189942, "ltp": 1.06, "tv": 16018.54, "trd": [[1.06, 2888.49]], "batb": [[0, 1.05, 58517.73]], "batl": [[0, 1.06, 13826.14]]}, {"timestamp": 1578771191022, "ltp": 1.06, "tv": 16018.54, "trd": NaN, "batb": [[0, 1.05, 58520.68]], "batl": NaN}, {"timestamp": 1578771195885, "ltp": 1.06, "tv": 16018.54, "trd": NaN, "batb": [[0, 1.05, 58520.58]], "batl": NaN}, {"timestamp": 1578771196764, "ltp": 1.06, "tv": 16018.54, "trd": NaN, "batb": [[0, 1.05, 58517.73]], "batl": NaN}, {"timestamp": 1578771198049, "ltp": 1.06, "tv": 16018.54, "trd": NaN, "batb": [[0, 1.05, 58520.54]], "batl": NaN}, {"timestamp": 1578771211889, "ltp": 1.06, "tv": 16018.54, "trd": NaN, "batb": [[0, 1.05, 58520.3]], "batl": NaN}, {"timestamp": 1578771212992, "ltp": 1.06, "tv": 16018.54, "trd": NaN, "batb": [[0, 1.05, 58520.29]], "batl": NaN}, {"timestamp": 1578771220993, "ltp": 1.06, "tv": 16018.54, "trd": NaN, "batb": [[0, 1.05, 58517.73]], "batl": NaN}, {"timestamp": 1578771221872, "ltp": 1.06, "tv": 16018.54, "trd": NaN, "batb": [[0, 1.05, 58520.14]], "batl": NaN}, {"timestamp": 1578771231007, "ltp": 1.06, "tv": 16061.1, "trd": [[1.06, 2931.05]], "batb": [[0, 1.05, 58520.09]], "batl": [[0, 1.06, 13804.86]]}, {"timestamp": 1578771256027, "ltp": 1.06, "tv": 16061.1, "trd": NaN, "batb": [[0, 1.05, 58517.73]], "batl": NaN}, {"timestamp": 1578771263033, "ltp": 1.05, "tv": 16100.9, "trd": [[1.05, 12642.76]], "batb": [[0, 1.05, 58497.83]], "batl": NaN}, {"timestamp": 1578771270745, "ltp": 1.05, "tv": 16140.7, "trd": [[1.05, 12682.56]], "batb": [[0, 1.05, 58477.93]], "batl": NaN}, {"timestamp": 1578771272052, "ltp": 1.05, "tv": 16140.7, "trd": NaN, "batb": [[0, 1.05, 58479.99]], "batl": NaN}, {"timestamp": 1578771295018, "ltp": 1.05, "tv": 16140.7, "trd": NaN, "batb": [[0, 1.05, 58477.93]], "batl": NaN}, {"timestamp": 1578771310022, "ltp": 1.05, "tv": 16144.7, "trd": [[1.05, 12686.56]], "batb": [[0, 1.05, 58475.93]], "batl": NaN}, {"timestamp": 1578771332037, "ltp": 1.06, "tv": 16190.8, "trd": [[1.06, 2977.15]], "batb": NaN, "batl": [[0, 1.06, 13781.81]]}, {"timestamp": 1578771334963, "ltp": 1.06, "tv": 16190.8, "trd": NaN, "batb": [[1, 1.04, 49558.81]], "batl": NaN}, {"timestamp": 1578771342039, "ltp": 1.05, "tv": 17060.8, "trd": [[1.05, 13556.56]], "batb": [[0, 1.05, 58044.53], [1, 1.04, 49567.13]], "batl": NaN}, {"timestamp": 1578771343047, "ltp": 1.05, "tv": 17060.8, "trd": NaN, "batb": [[0, 1.05, 58044.52]], "batl": NaN}, {"timestamp": 1578771343985, "ltp": 1.05, "tv": 17060.8, "trd": NaN, "batb": [[0, 1.05, 58040.93], [1, 1.04, 49759.13]], "batl": NaN}, {"timestamp": 1578771354996, "ltp": 1.06, "tv": 17076.92, "trd": [[1.06, 2993.27]], "batb": NaN, "batl": [[0, 1.06, 13773.75]]}, {"timestamp": 1578771362985, "ltp": 1.06, "tv": 17076.92, "trd": NaN, "batb": [[1, 1.04, 49758.53]], "batl": NaN}, {"timestamp": 1578771372987, "ltp": 1.06, "tv": 17076.92, "trd": NaN, "batb": [[1, 1.04, 49750.81]], "batl": NaN}, {"timestamp": 1578771414053, "ltp": 1.06, "tv": 17107.53, "trd": [[1.06, 3023.88]], "batb": NaN, "batl": [[0, 1.06, 13758.44]]}, {"timestamp": 1578771448043, "ltp": 1.06, "tv": 17117.21, "trd": [[1.06, 3033.56]], "batb": NaN, "batl": [[0, 1.06, 13753.6]]}, {"timestamp": 1578771454020, "ltp": 1.05, "tv": 17237.33, "trd": [[1.05, 13676.68]], "batb": [[0, 1.05, 57980.87]], "batl": NaN}, {"timestamp": 1578771469965, "ltp": 1.05, "tv": 17277.33, "trd": [[1.05, 13716.68]], "batb": [[0, 1.05, 57960.87]], "batl": NaN}, {"timestamp": 1578771493002, "ltp": 1.06, "tv": 17279.27, "trd": [[1.06, 3035.5]], "batb": NaN, "batl": [[0, 1.06, 13752.63]]}, {"timestamp": 1578771496970, "ltp": 1.05, "tv": 17282.67, "trd": [[1.05, 13720.08]], "batb": [[0, 1.05, 57959.17]], "batl": NaN}, {"timestamp": 1578771502999, "ltp": 1.05, "tv": 18354.67, "trd": [[1.05, 14792.08]], "batb": [[0, 1.05, 57423.17]], "batl": NaN}, {"timestamp": 1578771504008, "ltp": 1.05, "tv": 18354.67, "trd": NaN, "batb": [[1, 1.04, 49762.36]], "batl": NaN}, {"timestamp": 1578771519031, "ltp": 1.05, "tv": 18354.67, "trd": NaN, "batb": NaN, "batl": [[1, 1.07, 5833.08]]}, {"timestamp": 1578771523051, "ltp": 1.05, "tv": 18354.67, "trd": NaN, "batb": [[1, 1.04, 49762.32]], "batl": NaN}, {"timestamp": 1578771528044, "ltp": 1.05, "tv": 18354.67, "trd": NaN, "batb": [[1, 1.04, 49762.25]], "batl": NaN}, {"timestamp": 1578771534046, "ltp": 1.05, "tv": 18354.67, "trd": NaN, "batb": [[1, 1.04, 49750.81]], "batl": NaN}, {"timestamp": 1578771536973, "ltp": 1.05, "tv": 18358.67, "trd": [[1.05, 14796.08]], "batb": [[0, 1.05, 57421.17]], "batl": NaN}, {"timestamp": 1578771542957, "ltp": 1.05, "tv": 18504.49, "trd": [[1.05, 14941.91]], "batb": [[0, 1.05, 57348.26]], "batl": NaN}, {"timestamp": 1578771551868, "ltp": 1.05, "tv": 18704.49, "trd": [[1.05, 15141.91]], "batb": [[0, 1.05, 57248.26]], "batl": NaN}, {"timestamp": 1578771574971, "ltp": 1.06, "tv": 18705.4, "trd": [[1.06, 3036.4]], "batb": NaN, "batl": [[0, 1.06, 13752.18]]}, {"timestamp": 1578771580910, "ltp": 1.05, "tv": 18841.4, "trd": [[1.05, 15277.91]], "batb": [[0, 1.05, 57180.26]], "batl": NaN}, {"timestamp": 1578771597018, "ltp": 1.06, "tv": 18858.2, "trd": [[1.06, 3053.2]], "batb": NaN, "batl": [[0, 1.06, 13743.78]]}, {"timestamp": 1578771599017, "ltp": 1.05, "tv": 18860.2, "trd": [[1.05, 15279.91]], "batb": [[0, 1.05, 57179.26]], "batl": NaN}, {"timestamp": 1578771602028, "ltp": 1.05, "tv": 18864.2, "trd": [[1.05, 15283.91]], "batb": [[0, 1.05, 57177.26]], "batl": NaN}, {"timestamp": 1578771603027, "ltp": 1.06, "tv": 19007.91, "trd": [[1.06, 3196.92]], "batb": NaN, "batl": [[0, 1.06, 13671.92]]}, {"timestamp": 1578771615047, "ltp": 1.05, "tv": 19011.65, "trd": [[1.05, 15287.65]], "batb": [[0, 1.05, 57175.39]], "batl": NaN}, {"timestamp": 1578771616952, "ltp": 1.05, "tv": 19012.51, "trd": [[1.05, 15288.51]], "batb": [[0, 1.05, 57174.96]], "batl": NaN}, {"timestamp": 1578771622034, "ltp": 1.05, "tv": 19876.46, "trd": [[1.05, 16152.45]], "batb": [[0, 1.05, 56742.99], [1, 1.04, 49761.51]], "batl": NaN}, {"timestamp": 1578771626959, "ltp": 1.05, "tv": 19876.46, "trd": NaN, "batb": [[1, 1.04, 49761.18]], "batl": NaN}, {"timestamp": 1578771629981, "ltp": 1.05, "tv": 19876.46, "trd": NaN, "batb": [[1, 1.04, 49761.1]], "batl": NaN}, {"timestamp": 1578771632961, "ltp": 1.05, "tv": 19876.46, "trd": NaN, "batb": [[1, 1.04, 49761.06]], "batl": NaN}, {"timestamp": 1578771633863, "ltp": 1.05, "tv": 19876.46, "trd": NaN, "batb": [[1, 1.04, 49758.18]], "batl": NaN}, {"timestamp": 1578771634875, "ltp": 1.05, "tv": 19876.46, "trd": NaN, "batb": [[0, 1.05, 56764.99]], "batl": NaN}, {"timestamp": 1578771644966, "ltp": 1.06, "tv": 19920.46, "trd": [[1.06, 3240.92]], "batb": [[0, 1.05, 56742.99]], "batl": [[0, 1.06, 13649.92]]}, {"timestamp": 1578771651995, "ltp": 1.06, "tv": 19932.46, "trd": [[1.06, 3252.92]], "batb": NaN, "batl": [[0, 1.06, 13643.92]]}, {"timestamp": 1578771653005, "ltp": 1.06, "tv": 19932.46, "trd": NaN, "batb": [[0, 1.05, 56748.65], [1, 1.04, 49750.81]], "batl": NaN}, {"timestamp": 1578771654003, "ltp": 1.06, "tv": 19932.46, "trd": NaN, "batb": NaN, "batl": [[0, 1.06, 13644.42]]}, {"timestamp": 1578771656013, "ltp": 1.05, "tv": 20030.05, "trd": [[1.05, 16250.05]], "batb": [[0, 1.05, 56699.85]], "batl": NaN}, {"timestamp": 1578771657017, "ltp": 1.05, "tv": 20030.05, "trd": NaN, "batb": NaN, "batl": [[2, 1.08, 3414.08]]}, {"timestamp": 1578771675046, "ltp": 1.05, "tv": 20030.05, "trd": NaN, "batb": NaN, "batl": [[1, 1.07, 5868.08]]}, {"timestamp": 1578771694031, "ltp": 1.06, "tv": 20034.05, "trd": [[1.06, 3256.92]], "batb": NaN, "batl": [[0, 1.06, 13642.42]]}, {"timestamp": 1578771700042, "ltp": 1.06, "tv": 20035.2, "trd": [[1.06, 3258.06]], "batb": NaN, "batl": [[0, 1.06, 13641.85]]}, {"timestamp": 1578771710949, "ltp": 1.06, "tv": 20035.2, "trd": NaN, "batb": NaN, "batl": [[0, 1.06, 13719.31]]}, {"timestamp": 1578771718056, "ltp": 1.05, "tv": 20048.82, "trd": [[1.05, 16263.67]], "batb": [[0, 1.05, 56693.04]], "batl": NaN}, {"timestamp": 1578771732980, "ltp": 1.05, "tv": 20048.82, "trd": NaN, "batb": NaN, "batl": [[0, 1.06, 13766.76]]}, {"timestamp": 1578771740993, "ltp": 1.05, "tv": 20064.12, "trd": [[1.05, 16278.97]], "batb": [[0, 1.05, 56685.39]], "batl": NaN}, {"timestamp": 1578771757005, "ltp": 1.05, "tv": 22972.44, "trd": [[1.05, 19187.28]], "batb": [[0, 1.05, 55231.23], [1, 1.04, 49790.81]], "batl": NaN}, {"timestamp": 1578771771007, "ltp": 1.05, "tv": 23170.43, "trd": [[1.05, 19385.28]], "batb": [[0, 1.05, 55132.23]], "batl": NaN}, {"timestamp": 1578771787046, "ltp": 1.06, "tv": 23174.04, "trd": [[1.06, 3261.67]], "batb": NaN, "batl": [[0, 1.06, 13764.96]]}, {"timestamp": 1578771788042, "ltp": 1.06, "tv": 23174.04, "trd": NaN, "batb": [[1, 1.04, 49750.81]], "batl": NaN}, {"timestamp": 1578771790022, "ltp": 1.06, "tv": 23174.49, "trd": [[1.06, 3262.12]], "batb": NaN, "batl": [[0, 1.06, 13764.73]]}, {"timestamp": 1578771806980, "ltp": 1.06, "tv": 23174.49, "trd": NaN, "batb": NaN, "batl": [[0, 1.06, 13792.82]]}, {"timestamp": 1578771815997, "ltp": 1.06, "tv": 23195.96, "trd": [[1.06, 3283.59]], "batb": NaN, "batl": [[0, 1.06, 13782.09]]}, {"timestamp": 1578771822007, "ltp": 1.06, "tv": 23195.96, "trd": NaN, "batb": NaN, "batl": [[0, 1.06, 13611.85]]}, {"timestamp": 1578771822998, "ltp": 1.05, "tv": 23536.44, "trd": [[1.05, 19725.77]], "batb": [[0, 1.05, 54961.99]], "batl": NaN}, {"timestamp": 1578771826009, "ltp": 1.06, "tv": 23554.47, "trd": [[1.06, 3301.61]], "batb": NaN, "batl": [[0, 1.06, 13602.84]]}, {"timestamp": 1578771831025, "ltp": 1.06, "tv": 23554.47, "trd": NaN, "batb": NaN, "batl": [[0, 1.06, 13501.88]]}, {"timestamp": 1578771845025, "ltp": 1.05, "tv": 23556.79, "trd": [[1.05, 19728.09]], "batb": [[0, 1.05, 54960.83]], "batl": NaN}, {"timestamp": 1578771850947, "ltp": 1.05, "tv": 23556.81, "trd": [[1.05, 19728.11]], "batb": [[0, 1.05, 54960.82]], "batl": NaN}, {"timestamp": 1578771857035, "ltp": 1.05, "tv": 23596.81, "trd": [[1.05, 19768.11]], "batb": [[0, 1.05, 54940.82]], "batl": NaN}, {"timestamp": 1578771860953, "ltp": 1.05, "tv": 23596.81, "trd": NaN, "batb": [[0, 1.05, 54942.82]], "batl": NaN}, {"timestamp": 1578771865045, "ltp": 1.06, "tv": 23601.31, "trd": [[1.06, 3306.12]], "batb": NaN, "batl": [[0, 1.06, 13499.63]]}, {"timestamp": 1578771866046, "ltp": 1.05, "tv": 23605.31, "trd": [[1.05, 19772.11]], "batb": [[0, 1.05, 54940.82]], "batl": NaN}, {"timestamp": 1578771872050, "ltp": 1.05, "tv": 23687.18, "trd": [[1.05, 19849.97], [1.06, 3310.12]], "batb": [[0, 1.05, 54901.89]], "batl": [[0, 1.06, 13497.63]]}, {"timestamp": 1578771882011, "ltp": 1.06, "tv": 23687.68, "trd": [[1.06, 3310.62]], "batb": NaN, "batl": [[0, 1.06, 13497.38]]}, {"timestamp": 1578771904031, "ltp": 1.06, "tv": 23688.3, "trd": [[1.06, 3311.24]], "batb": NaN, "batl": [[0, 1.06, 13497.07]]}, {"timestamp": 1578771904978, "ltp": 1.06, "tv": 23688.3, "trd": NaN, "batb": NaN, "batl": [[1, 1.07, 5681.08]]}, {"timestamp": 1578771918947, "ltp": 1.06, "tv": 23688.3, "trd": NaN, "batb": NaN, "batl": [[1, 1.07, 5868.08]]}, {"timestamp": 1578771921957, "ltp": 1.06, "tv": 23688.3, "trd": NaN, "batb": NaN, "batl": [[1, 1.07, 5681.08]]}, {"timestamp": 1578771924053, "ltp": 1.06, "tv": 24205.72, "trd": [[1.06, 3828.66]], "batb": NaN, "batl": [[0, 1.06, 13238.36], [1, 1.07, 5868.08]]}, {"timestamp": 1578771927047, "ltp": 1.06, "tv": 24205.72, "trd": NaN, "batb": NaN, "batl": [[1, 1.07, 5681.08]]}, {"timestamp": 1578771929047, "ltp": 1.06, "tv": 24210.16, "trd": [[1.06, 3833.09]], "batb": NaN, "batl": [[0, 1.06, 13236.14]]}, {"timestamp": 1578771941980, "ltp": 1.06, "tv": 24226.27, "trd": [[1.06, 3849.21]], "batb": NaN, "batl": [[0, 1.06, 13228.08]]}, {"timestamp": 1578771951964, "ltp": 1.06, "tv": 24226.27, "trd": NaN, "batb": NaN, "batl": [[1, 1.07, 5868.08]]}, {"timestamp": 1578771952954, "ltp": 1.06, "tv": 24226.27, "trd": NaN, "batb": NaN, "batl": [[0, 1.06, 13230.44]]}, {"timestamp": 1578771960991, "ltp": 1.05, "tv": 25899.04, "trd": [[1.05, 21522.74]], "batb": [[0, 1.05, 54065.5]], "batl": NaN}, {"timestamp": 1578771961992, "ltp": 1.05, "tv": 25899.04, "trd": NaN, "batb": [[1, 1.04, 49774.59]], "batl": NaN}, {"timestamp": 1578771964991, "ltp": 1.05, "tv": 25899.04, "trd": NaN, "batb": NaN, "batl": [[0, 1.06, 13232.81]]}, {"timestamp": 1578771973012, "ltp": 1.05, "tv": 25899.04, "trd": NaN, "batb": [[1, 1.04, 49774.27]], "batl": NaN}, {"timestamp": 1578771982009, "ltp": 1.05, "tv": 25899.04, "trd": NaN, "batb": NaN, "batl": [[0, 1.06, 13235.17]]}, {"timestamp": 1578771992010, "ltp": 1.05, "tv": 25899.04, "trd": NaN, "batb": [[1, 1.04, 49750.81]], "batl": NaN}, {"timestamp": 1578772003044, "ltp": 1.05, "tv": 25899.04, "trd": NaN, "batb": NaN, "batl": [[0, 1.06, 13237.54]]}, {"timestamp": 1578772012034, "ltp": 1.06, "tv": 25903.97, "trd": [[1.06, 3854.14]], "batb": NaN, "batl": [[0, 1.06, 13235.08]]}, {"timestamp": 1578772019054, "ltp": 1.06, "tv": 25903.97, "trd": NaN, "batb": NaN, "batl": [[0, 1.06, 13237.44]]}, {"timestamp": 1578772019746, "ltp": 1.06, "tv": 25905.74, "trd": [[1.06, 3855.91]], "batb": NaN, "batl": [[0, 1.06, 13236.55]]}, {"timestamp": 1578772022960, "ltp": 1.06, "tv": 25905.74, "trd": NaN, "batb": [[1, 1.04, 49000.81]], "batl": NaN}, {"timestamp": 1578772028960, "ltp": 1.06, "tv": 25915.18, "trd": [[1.05, 21530.4], [1.06, 3857.69]], "batb": [[0, 1.05, 54061.68]], "batl": [[0, 1.06, 13235.66]]}, {"timestamp": 1578772033042, "ltp": 1.06, "tv": 25922.18, "trd": [[1.06, 3864.7]], "batb": NaN, "batl": [[0, 1.06, 13232.16]]}, {"timestamp": 1578772033875, "ltp": 1.05, "tv": 25934.18, "trd": [[1.05, 21542.4]], "batb": [[0, 1.05, 54055.68]], "batl": [[1, 1.07, 5681.08]]}, {"timestamp": 1578772040047, "ltp": 1.05, "tv": 25947.91, "trd": [[1.05, 21554.35], [1.06, 3866.47]], "batb": [[0, 1.05, 54049.7]], "batl": [[0, 1.06, 13231.27]]}, {"timestamp": 1578772042768, "ltp": 1.05, "tv": 25947.91, "trd": NaN, "batb": NaN, "batl": [[0, 1.06, 13233.64]]}, {"timestamp": 1578772053858, "ltp": 1.05, "tv": 26586.0, "trd": [[1.05, 22192.43]], "batb": [[0, 1.05, 53730.66]], "batl": [[0, 1.06, 13236]]}, {"timestamp": 1578772054963, "ltp": 1.05, "tv": 26586.0, "trd": NaN, "batb": [[1, 1.04, 49004.41]], "batl": NaN}, {"timestamp": 1578772059971, "ltp": 1.05, "tv": 26586.0, "trd": NaN, "batb": [[1, 1.04, 49004.23]], "batl": NaN}, {"timestamp": 1578772060977, "ltp": 1.06, "tv": 26586.65, "trd": [[1.06, 3867.13]], "batb": NaN, "batl": [[0, 1.06, 13235.67]]}, {"timestamp": 1578772063997, "ltp": 1.06, "tv": 26586.65, "trd": NaN, "batb": [[1, 1.04, 49003.97]], "batl": [[0, 1.06, 13238.04]]}, {"timestamp": 1578772064986, "ltp": 1.06, "tv": 26586.65, "trd": NaN, "batb": [[1, 1.04, 49003.86]], "batl": NaN}, {"timestamp": 1578772066030, "ltp": 1.06, "tv": 26604.39, "trd": [[1.06, 3884.87]], "batb": NaN, "batl": [[0, 1.06, 13229.17]]}, {"timestamp": 1578772066887, "ltp": 1.06, "tv": 26616.37, "trd": [[1.06, 3896.85]], "batb": NaN, "batl": [[0, 1.06, 13223.18]]}, {"timestamp": 1578772070993, "ltp": 1.06, "tv": 26616.37, "trd": NaN, "batb": NaN, "batl": [[1, 1.07, 5868.08]]}, {"timestamp": 1578772077006, "ltp": 1.06, "tv": 26616.37, "trd": NaN, "batb": NaN, "batl": [[0, 1.06, 13225.54]]}, {"timestamp": 1578772086047, "ltp": 1.06, "tv": 26616.37, "trd": NaN, "batb": [[1, 1.04, 49000.81]], "batl": NaN}, {"timestamp": 1578772091030, "ltp": 1.06, "tv": 26617.18, "trd": [[1.06, 3897.65]], "batb": NaN, "batl": [[0, 1.06, 13225.14]]}, {"timestamp": 1578772098026, "ltp": 1.06, "tv": 26622.1, "trd": [[1.06, 3902.58]], "batb": [[1, 1.04, 48808.81], [2, 1.03, 26831.41]], "batl": [[0, 1.06, 13222.68], [1, 1.07, 5681.08], [2, 1.08, 3229.08]]}, {"timestamp": 1578772101023, "ltp": 1.06, "tv": 26622.1, "trd": NaN, "batb": [[0, 1.05, 53356.47], [1, 1.04, 33384.41], [2, 1.03, 11484.31]], "batl": [[0, 1.06, 12832.42], [1, 1.07, 5335.94], [2, 1.08, 2875.09]]}, {"timestamp": 1578772108019, "ltp": 1.06, "tv": 26622.1, "trd": NaN, "batb": [[0, 1.05, 53537.16], [1, 1.04, 33527.71], [2, 1.03, 11635.29]], "batl": [[0, 1.06, 13198.48], [1, 1.07, 5670.06], [2, 1.08, 3206.12]]}, {"timestamp": 1578772108966, "ltp": 1.06, "tv": 26622.1, "trd": NaN, "batb": [[0, 1.05, 53889.62], [1, 1.04, 33384.41], [2, 1.03, 11484.31]], "batl": [[0, 1.06, 13342.84], [1, 1.07, 5797.57], [2, 1.08, 3314.06]]}, {"timestamp": 1578772109962, "ltp": 1.06, "tv": 26622.1, "trd": NaN, "batb": [[0, 1.05, 54104.12]], "batl": [[0, 1.06, 13513.9], [1, 1.07, 5953.71], [2, 1.08, 3457.7]]}, {"timestamp": 1578772113015, "ltp": 1.06, "tv": 26622.1, "trd": NaN, "batb": NaN, "batl": [[1, 1.07, 5974.99]]}, {"timestamp": 1578772114004, "ltp": 1.06, "tv": 26622.1, "trd": NaN, "batb": [[1, 1.04, 33961.41], [2, 1.03, 12067.31]], "batl": [[2, 1.08, 3642.7]]}, {"timestamp": 1578772116004, "ltp": 1.05, "tv": 26622.83, "trd": [[1.05, 22193.17]], "batb": [[0, 1.05, 54188.87]], "batl": NaN}, {"timestamp": 1578772124032, "ltp": 1.05, "tv": 26633.55, "trd": [[1.05, 22203.88]], "batb": [[0, 1.05, 54183.52], [1, 1.04, 38461.41]], "batl": [[1, 1.07, 6853.71]]}, {"timestamp": 1578772126020, "ltp": 1.05, "tv": 26633.55, "trd": NaN, "batb": [[0, 1.05, 54336.59], [1, 1.04, 33463.91]], "batl": NaN}, {"timestamp": 1578772127024, "ltp": 1.05, "tv": 26633.55, "trd": NaN, "batb": [[0, 1.05, 54642.72]], "batl": NaN}, {"timestamp": 1578772128017, "ltp": 1.05, "tv": 26633.55, "trd": NaN, "batb": [[0, 1.05, 54719.26]], "batl": NaN}, {"timestamp": 1578772129988, "ltp": 1.05, "tv": 26633.55, "trd": NaN, "batb": NaN, "batl": [[0, 1.06, 13613.9]]}, {"timestamp": 1578772131049, "ltp": 1.05, "tv": 26633.55, "trd": NaN, "batb": NaN, "batl": [[1, 1.07, 6874.99]]}, {"timestamp": 1578772132044, "ltp": 1.05, "tv": 26633.55, "trd": NaN, "batb": [[0, 1.05, 54740.54]], "batl": NaN}, {"timestamp": 1578772134031, "ltp": 1.05, "tv": 26633.55, "trd": NaN, "batb": [[0, 1.05, 54804.39]], "batl": NaN}, {"timestamp": 1578772139014, "ltp": 1.05, "tv": 26663.55, "trd": [[1.05, 22233.88]], "batb": [[0, 1.05, 54725.54]], "batl": NaN}, {"timestamp": 1578772143047, "ltp": 1.06, "tv": 26664.01, "trd": [[1.06, 3903.04]], "batb": NaN, "batl": [[0, 1.06, 13613.67]]}, {"timestamp": 1578772144036, "ltp": 1.06, "tv": 26664.01, "trd": NaN, "batb": [[1, 1.04, 33807.67]], "batl": [[1, 1.07, 7209.1], [2, 1.08, 3973.73]]}, {"timestamp": 1578772146042, "ltp": 1.06, "tv": 26664.01, "trd": NaN, "batb": [[1, 1.04, 29307.67]], "batl": [[1, 1.07, 6309.1]]}, {"timestamp": 1578772147044, "ltp": 1.06, "tv": 26664.01, "trd": NaN, "batb": [[1, 1.04, 29322.67]], "batl": NaN}, {"timestamp": 1578772151035, "ltp": 1.06, "tv": 26664.01, "trd": NaN, "batb": NaN, "batl": [[0, 1.06, 14124.4]]}, {"timestamp": 1578772153020, "ltp": 1.06, "tv": 26665.78, "trd": [[1.06, 3904.81]], "batb": NaN, "batl": [[0, 1.06, 14123.52]]}, {"timestamp": 1578772153956, "ltp": 1.06, "tv": 26665.78, "trd": NaN, "batb": [[1, 1.04, 31572.67]], "batl": [[1, 1.07, 6759.1]]}, {"timestamp": 1578772154951, "ltp": 1.06, "tv": 26665.78, "trd": NaN, "batb": [[1, 1.04, 33822.67]], "batl": [[1, 1.07, 7212.1]]}, {"timestamp": 1578772161961, "ltp": 1.05, "tv": 26688.74, "trd": [[1.05, 22256.84]], "batb": [[0, 1.05, 54714.06]], "batl": NaN}, {"timestamp": 1578772164044, "ltp": 1.05, "tv": 26696.84, "trd": [[1.05, 22264.94]], "batb": [[0, 1.05, 54710.01]], "batl": NaN}, {"timestamp": 1578772165013, "ltp": 1.06, "tv": 26698.19, "trd": [[1.06, 3906.16]], "batb": [[0, 1.05, 55050.49]], "batl": [[0, 1.06, 14460.11]]}, {"timestamp": 1578772166034, "ltp": 1.06, "tv": 26704.32, "trd": [[1.06, 3912.29]], "batb": NaN, "batl": [[0, 1.06, 14457.05]]}, {"timestamp": 1578772166972, "ltp": 1.06, "tv": 26709.37, "trd": [[1.06, 3917.34]], "batb": NaN, "batl": [[0, 1.06, 14454.52]]}, {"timestamp": 1578772175975, "ltp": 1.06, "tv": 26714.3, "trd": [[1.06, 3922.27]], "batb": NaN, "batl": [[0, 1.06, 14452.06]]}, {"timestamp": 1578772177959, "ltp": 1.06, "tv": 26714.3, "trd": NaN, "batb": [[1, 1.04, 31572.67]], "batl": NaN}, {"timestamp": 1578772179996, "ltp": 1.06, "tv": 26714.3, "trd": NaN, "batb": [[0, 1.05, 55390.98]], "batl": NaN}, {"timestamp": 1578772180983, "ltp": 1.06, "tv": 26714.3, "trd": NaN, "batb": NaN, "batl": [[0, 1.06, 14454.43], [1, 1.07, 7190.82]]}, {"timestamp": 1578772185006, "ltp": 1.06, "tv": 26714.3, "trd": NaN, "batb": [[0, 1.05, 55894.09]], "batl": [[0, 1.06, 14500.25]]}, {"timestamp": 1578772185997, "ltp": 1.06, "tv": 26714.3, "trd": NaN, "batb": [[0, 1.05, 57403.49], [1, 1.04, 32779.67], [2, 1.03, 13308.31]], "batl": [[1, 1.07, 8347.82], [2, 1.08, 5120.73]]}, {"timestamp": 1578772187991, "ltp": 1.06, "tv": 26714.3, "trd": NaN, "batb": NaN, "batl": [[2, 1.08, 5142.01]]}, {"timestamp": 1578772192015, "ltp": 1.06, "tv": 26714.3, "trd": NaN, "batb": NaN, "batl": [[0, 1.06, 14511.47]]}, {"timestamp": 1578772193985, "ltp": 1.06, "tv": 26714.3, "trd": NaN, "batb": NaN, "batl": [[0, 1.06, 14529.49]]}, {"timestamp": 1578772197010, "ltp": 1.05, "tv": 26723.62, "trd": [[1.05, 22268.34], [1.06, 3928.18]], "batb": [[0, 1.05, 57401.79]], "batl": [[0, 1.06, 14526.53]]}, {"timestamp": 1578772199036, "ltp": 1.05, "tv": 26733.06, "trd": [[1.05, 22277.79]], "batb": [[0, 1.05, 57397.06]], "batl": NaN}, {"timestamp": 1578772202021, "ltp": 1.06, "tv": 26734.9, "trd": [[1.06, 3930.02]], "batb": NaN, "batl": [[0, 1.06, 14525.61]]}, {"timestamp": 1578772203998, "ltp": 1.05, "tv": 34550.7, "trd": [[1.05, 30093.59]], "batb": [[0, 1.05, 53489.16]], "batl": NaN}, {"timestamp": 1578772206035, "ltp": 1.05, "tv": 34550.7, "trd": NaN, "batb": [[1, 1.04, 30529.67]], "batl": [[0, 1.06, 14461.76]]}, {"timestamp": 1578772208015, "ltp": 1.06, "tv": 34560.7, "trd": [[1.06, 3940.02]], "batb": NaN, "batl": [[0, 1.06, 14456.76]]}, {"timestamp": 1578772214029, "ltp": 1.06, "tv": 34560.7, "trd": NaN, "batb": [[0, 1.05, 55501.67]], "batl": NaN}, {"timestamp": 1578772219055, "ltp": 1.06, "tv": 34560.7, "trd": NaN, "batb": [[0, 1.05, 55518.7]], "batl": [[0, 1.06, 14520.61]]}, {"timestamp": 1578772222038, "ltp": 1.06, "tv": 34577.08, "trd": [[1.06, 3956.4]], "batb": [[0, 1.05, 56668.7]], "batl": [[0, 1.06, 14512.42]]}, {"timestamp": 1578772223039, "ltp": 1.06, "tv": 35253.66, "trd": [[1.06, 4632.98]], "batb": [[0, 1.05, 55518.7]], "batl": [[0, 1.06, 14174.13]]}, {"timestamp": 1578772226954, "ltp": 1.06, "tv": 35253.66, "trd": NaN, "batb": NaN, "batl": [[0, 1.06, 14110.28]]}, {"timestamp": 1578772229043, "ltp": 1.06, "tv": 35253.66, "trd": NaN, "batb": NaN, "batl": [[0, 1.06, 14232.28]]}, {"timestamp": 1578772230042, "ltp": 1.06, "tv": 35253.66, "trd": NaN, "batb": [[0, 1.05, 55497.42], [1, 1.04, 19313.04], [2, 1.03, 1828.14]], "batl": [[2, 1.08, 5120.73]]}, {"timestamp": 1578772232039, "ltp": 1.06, "tv": 35291.97, "trd": [[1.06, 4671.28]], "batb": NaN, "batl": [[0, 1.06, 14213.13]]}, {"timestamp": 1578772235048, "ltp": 1.06, "tv": 35291.97, "trd": NaN, "batb": [[0, 1.05, 56660.42]], "batl": [[0, 1.06, 14276.98]]}, {"timestamp": 1578772236042, "ltp": 1.06, "tv": 35291.97, "trd": NaN, "batb": NaN, "batl": [[1, 1.07, 8352.82]]}, {"timestamp": 1578772236982, "ltp": 1.06, "tv": 35299.18, "trd": [[1.06, 4678.5]], "batb": [[0, 1.05, 56681.7]], "batl": [[0, 1.06, 14273.37], [2, 1.08, 5142.01]]}, {"timestamp": 1578772237971, "ltp": 1.06, "tv": 35344.18, "trd": [[1.05, 30096.73], [1.06, 4720.37]], "batb": [[0, 1.05, 56680.13]], "batl": [[0, 1.06, 14252.44]]}, {"timestamp": 1578772238964, "ltp": 1.06, "tv": 35347.58, "trd": [[1.06, 4723.77]], "batb": NaN, "batl": [[0, 1.06, 14250.74]]}, {"timestamp": 1578772239957, "ltp": 1.06, "tv": 35347.58, "trd": NaN, "batb": NaN, "batl": [[0, 1.06, 14186.89]]}, {"timestamp": 1578772240961, "ltp": 1.06, "tv": 35347.58, "trd": NaN, "batb": [[0, 1.05, 61680.13]], "batl": NaN}, {"timestamp": 1578772250050, "ltp": 1.06, "tv": 35350.99, "trd": [[1.06, 4727.17]], "batb": NaN, "batl": [[0, 1.06, 14185.19]]}, {"timestamp": 1578772252005, "ltp": 1.06, "tv": 35357.11, "trd": [[1.06, 4733.29]], "batb": NaN, "batl": [[0, 1.06, 14182.13]]}, {"timestamp": 1578772253994, "ltp": 1.06, "tv": 35373.35, "trd": [[1.06, 4749.53]], "batb": NaN, "batl": [[0, 1.06, 14174.01]]}, {"timestamp": 1578772257977, "ltp": 1.06, "tv": 35380.16, "trd": [[1.06, 4756.34]], "batb": NaN, "batl": [[0, 1.06, 14170.61]]}, {"timestamp": 1578772258971, "ltp": 1.06, "tv": 35399.9, "trd": [[1.06, 4776.08]], "batb": NaN, "batl": [[0, 1.06, 14160.74]]}, {"timestamp": 1578772259971, "ltp": 1.06, "tv": 35400.28, "trd": [[1.06, 4776.46]], "batb": NaN, "batl": [[0, 1.06, 14160.55]]}, {"timestamp": 1578772262019, "ltp": 1.05, "tv": 35476.81, "trd": [[1.05, 30173.27]], "batb": [[0, 1.05, 61641.86]], "batl": NaN}, {"timestamp": 1578772262972, "ltp": 1.05, "tv": 35476.81, "trd": NaN, "batb": NaN, "batl": [[0, 1.06, 14224.4]]}, {"timestamp": 1578772264028, "ltp": 1.05, "tv": 35476.81, "trd": NaN, "batb": [[0, 1.05, 57616.84]], "batl": [[1, 1.07, 7452.82]]}, {"timestamp": 1578772265855, "ltp": 1.06, "tv": 35817.3, "trd": [[1.06, 5116.94]], "batb": NaN, "batl": [[0, 1.06, 14054.16]]}, {"timestamp": 1578772267056, "ltp": 1.05, "tv": 35821.03, "trd": [[1.05, 30177]], "batb": [[0, 1.05, 57614.97]], "batl": NaN}, {"timestamp": 1578772270045, "ltp": 1.05, "tv": 35821.03, "trd": NaN, "batb": NaN, "batl": [[0, 1.06, 13990.31]]}, {"timestamp": 1578772272003, "ltp": 1.05, "tv": 35821.03, "trd": NaN, "batb": [[0, 1.05, 61639.99]], "batl": [[1, 1.07, 8352.82]]}, {"timestamp": 1578772273991, "ltp": 1.06, "tv": 36712.24, "trd": [[1.05, 31064.8], [1.06, 5120.34]], "batb": [[0, 1.05, 61196.09]], "batl": [[0, 1.06, 13988.61]]}, {"timestamp": 1578772275035, "ltp": 1.06, "tv": 36722.24, "trd": [[1.06, 5130.34]], "batb": NaN, "batl": [[0, 1.06, 13983.61]]}, {"timestamp": 1578772277034, "ltp": 1.06, "tv": 36722.24, "trd": NaN, "batb": NaN, "batl": [[1, 1.07, 9496.82]]}, {"timestamp": 1578772278020, "ltp": 1.06, "tv": 36722.24, "trd": NaN, "batb": NaN, "batl": [[0, 1.06, 13999.3]]}, {"timestamp": 1578772281005, "ltp": 1.06, "tv": 36723.6, "trd": [[1.06, 5131.71]], "batb": NaN, "batl": [[0, 1.06, 13998.62]]}, {"timestamp": 1578772288028, "ltp": 1.06, "tv": 36731.26, "trd": [[1.06, 5139.37]], "batb": NaN, "batl": [[0, 1.06, 13994.79]]}, {"timestamp": 1578772290015, "ltp": 1.05, "tv": 37542.97, "trd": [[1.05, 31876.51]], "batb": [[0, 1.05, 60790.24]], "batl": [[0, 1.06, 14009.79]]}, {"timestamp": 1578772290955, "ltp": 1.05, "tv": 37546.7, "trd": [[1.05, 31880.25]], "batb": [[0, 1.05, 60788.37]], "batl": NaN}, {"timestamp": 1578772293949, "ltp": 1.05, "tv": 37546.7, "trd": NaN, "batb": [[0, 1.05, 59625.37], [1, 1.04, 18106.04], [2, 1.03, 587.14]], "batl": [[1, 1.07, 8339.82], [2, 1.08, 3995.01]]}, {"timestamp": 1578772294860, "ltp": 1.05, "tv": 37546.7, "trd": NaN, "batb": [[0, 1.05, 58671.76], [1, 1.04, 17762.27]], "batl": [[0, 1.06, 13190.88], [1, 1.07, 7544.08], [2, 1.08, 3203.74]]}, {"timestamp": 1578772296040, "ltp": 1.05, "tv": 37546.7, "trd": NaN, "batb": [[0, 1.05, 54415.21], [1, 1.04, 17185.27], [2, 1.03, 4.14]], "batl": [[0, 1.06, 13019.82], [1, 1.07, 6487.94], [2, 1.08, 2875.09]]}, {"timestamp": 1578772305487, "ltp": 1.05, "tv": 37546.7, "trd": NaN, "batb": NaN, "batl": [[0, 1.06, 12942.36]]}, {"timestamp": 1578772313342, "ltp": 1.05, "tv": 37546.7, "trd": NaN, "batb": NaN, "batl": [[0, 1.06, 12931.15]]}, {"timestamp": 1578772314578, "ltp": 1.05, "tv": 37546.7, "trd": NaN, "batb": NaN, "batl": [[1, 1.07, 5343.94]]}, {"timestamp": 1578772328650, "ltp": 1.05, "tv": 37546.7, "trd": NaN, "batb": NaN, "batl": [[0, 1.06, 12926.42]]}, {"timestamp": 1578772347979, "ltp": 1.05, "tv": 37546.7, "trd": NaN, "batb": [[0, 1.05, 48853.05], [1, 1.04, 17170.27]], "batl": [[0, 1.06, 12136.58], [1, 1.07, 5335.94]]}]}]}