{"op":"mcm","clk":"4299625824","pt":1632581329464,"mc":[{"id":"1.188136695","rc":[{"batb":[[0,1.24,2139.94],[1,1.23,4171.82]],"batl":[[0,1.25,668.55],[1,1.26,1965.71],[2,1.27,1234.98]],"ltp":1.26,"tv":192210.75,"id":5300737},{"batb":[[0,4.8,174.53]],"ltp":4.8,"tv":31097.17,"id":2497008}]}]}
{"op":"mcm","clk":"4299626125","pt":1632581330536,"mc":[{"id":"1.188136695","rc":[{"trd":[[1.25,4439.67],[1.26,3703.6]],"batl":[[0,1.26,169.55],[1,1.27,1234.98],[2,1.28,290.47]],"ltp":1.26,"tv":194677.14,"id":5300737},{"trd":[[4.8,882.25],[5,617.58]],"batb":[[0,4.6,197.17],[1,4.5,590.17],[2,4.4,459.86]],"batl":[[0,5.2,11.25]],"ltp":4.8,"tv":32084.43,"id":2497008}],"tv":226761.57}]}
{"op":"mcm","clk":"4299626385","pt":1632581331653,"mc":[{"id":"1.188136695","rc":[{"trd":[[1.26,3703.99]],"batl":[[0,1.26,169.35]],"ltp":1.26,"tv":194677.53,"id":5300737},{"batl":[[2,5.8,13.72]],"ltp":4.8,"tv":32084.43,"id":2497008}],"tv":226761.96}]}
{"op":"mcm","clk":"4299626599","pt":1632581332463,"mc":[{"id":"1.188136695","rc":[{"batb":[[1,1.23,4405.62],[2,1.22,1633.63]],"ltp":1.26,"tv":194677.53,"id":5300737},{"batb":[[2,4.4,543.31]],"batl":[[1,5.3,87.11],[2,5.4,58.8]],"ltp":4.8,"tv":32084.43,"id":2497008}]}]}
{"op":"mcm","clk":"4299626893","pt":1632581333547,"mc":[{"id":"1.188136695","rc":[{"batb":[[0,1.24,2453.34]],"batl":[[0,1.25,10.54],[1,1.26,169.35],[2,1.27,1654.68]],"ltp":1.26,"tv":194677.53,"id":5300737}]}]}
{"op":"mcm","clk":"4299627093","pt":1632581334261,"mc":[{"id":"1.188136695","rc":[{"batb":[[0,4.7,385.89],[1,4.6,197.17],[2,4.5,590.17]],"ltp":4.8,"tv":32084.43,"id":2497008}]}]}
{"op":"mcm","clk":"4299627493","pt":1632581335829,"mc":[{"id":"1.188136695","rc":[{"trd":[[1.24,8604.19]],"batb":[[0,1.24,2216.09],[1,1.23,4593.28]],"batl":[[2,1.27,1235.02]],"ltp":1.24,"tv":195152.03,"id":5300737},{"batb":[[0,4.7,15.7],[2,4.5,615.88]],"batl":[[1,5.3,97.96]],"ltp":4.8,"tv":32084.43,"id":2497008}],"tv":227236.46}]}
{"op":"mcm","clk":"4299627735","pt":1632581336766,"mc":[{"id":"1.188136695","rc":[{"batb":[[0,1.24,1259.6],[1,1.23,423.06],[2,1.22,275.4]],"batl":[[2,1.28,103.64]],"ltp":1.24,"tv":195152.03,"id":5300737},{"batb":[[0,4.6,197.17],[1,4.5,164.23],[2,4.4,83.45]],"batl":[[0,5.3,97.96],[1,5.4,58.8],[2,5.5,91.5]],"ltp":4.8,"tv":32084.43,"id":2497008}]}]}
{"op":"mcm","clk":"4299627911","pt":1632581337462,"mc":[{"id":"1.188136695","rc":[{"batb":[[0,1.24,952.26]],"batl":[[1,1.26,302.96]],"ltp":1.24,"tv":195152.03,"id":5300737}]}]}
{"op":"mcm","clk":"4299628246","pt":1632581338657,"mc":[{"id":"1.188136695","rc":[{"batb":[[1,1.23,235.4]],"batl":[[1,1.28,13.64],[2,1.29,41.76]],"ltp":1.24,"tv":195152.03,"id":5300737},{"batb":[[1,4.5,138.52]],"batl":[[0,5.3,87.11]],"ltp":4.8,"tv":32084.43,"id":2497008}]}]}
{"op":"mcm","clk":"4299628557","pt":1632581339759,"mc":[{"id":"1.188136695","rc":[{"trd":[[1.25,4441.24]],"batb":[[2,1.22,3458.62]],"batl":[[0,1.25,9.76],[1,1.28,1315.13],[2,1.29,1158.83]],"ltp":1.25,"tv":195153.6,"id":5300737},{"batb":[[1,4.5,344.74],[2,4.4,83.89]],"batl":[[0,5.3,72.08]],"ltp":4.8,"tv":32084.43,"id":2497008}],"tv":227238.03}]}
{"op":"mcm","clk":"4299628764","pt":1632581340562,"mc":[{"id":"1.188136695","rc":[{"batb":[[1,1.23,1.61],[2,1.22,1309.89]],"batl":[[2,1.29,1117.07]],"ltp":1.25,"tv":195153.6,"id":5300737},{"batb":[[0,4.5,344.74],[1,4.4,83.89],[2,4.3,89.43]],"batl":[[0,5.8,13.72],[1,6.4,11.44],[2,6.6,5.64]],"ltp":4.8,"tv":32084.43,"id":2497008}]}]}
{"op":"mcm","clk":"4299629080","pt":1632581341756,"mc":[{"id":"1.188136695","rc":[{"trd":[[1.25,4442.59]],"batl":[[0,1.25,9.09]],"ltp":1.25,"tv":195154.94,"id":5300737}],"tv":227239.37}]}
{"op":"mcm","clk":"4299629353","pt":1632581342741,"mc":[{"id":"1.188136695","rc":[{"trd":[[1.25,4460.76]],"batb":[[0,1.26,423.76],[1,1.25,6.85],[2,1.24,952.26]],"batl":[[0,1.28,1315.13],[1,1.29,1117.07],[2,1.3,255.19]],"ltp":1.25,"tv":195173.12,"id":5300737}],"tv":227257.55}]}
{"op":"mcm","clk":"4299629607","pt":1632581343769,"mc":[{"id":"1.188136695","rc":[{"batb":[[1,1.25,1572.32],[2,1.24,3584.42]],"batl":[[2,1.3,261.32]],"ltp":1.25,"tv":195173.12,"id":5300737},{"trd":[[4.5,47.82]],"batb":[[0,4.5,335.65],[2,4.3,489.73]],"batl":[[0,5.6,40.21],[1,5.8,13.72],[2,6.4,11.44]],"ltp":4.5,"tv":32102.61,"id":2497008}],"tv":227275.73}]}
{"op":"mcm","clk":"4299629877","pt":1632581344751,"mc":[{"id":"1.188136695","rc":[{"trd":[[1.26,3709],[1.27,1867.64],[1.28,187.28]],"batb":[[0,1.26,1534.45],[1,1.25,1618.34]],"batl":[[0,1.28,1299.13]],"ltp":1.28,"tv":195212.47,"id":5300737},{"trd":[[4.5,54.56],[4.7,192.43]],"batb":[[0,4.5,349.21]],"batl":[[1,5.7,36.02],[2,5.8,13.72]],"ltp":4.5,"tv":32109.98,"id":2497008}],"tv":227322.45}]}
{"op":"mcm","clk":"4299630132","pt":1632581345753,"mc":[{"id":"1.188136695","rc":[{"trd":[[1.26,3784.17]],"batb":[[0,1.26,1496.87],[1,1.25,2570.6],[2,1.24,2632.16]],"batl":[[0,1.28,1342.33]],"ltp":1.26,"tv":195287.64,"id":5300737},{"batb":[[1,4.4,86.89]],"batl":[[0,5.6,40.56],[1,5.8,13.72],[2,6,1.71]],"ltp":4.5,"tv":32109.98,"id":2497008}],"tv":227397.62}]}
{"op":"mcm","clk":"4299630325","pt":1632581346558,"mc":[{"id":"1.188136695","rc":[{"trd":[[1.26,3875.01]],"batb":[[0,1.26,1451.45]],"ltp":1.26,"tv":195378.48,"id":5300737},{"batb":[[2,4.3,491.73]],"ltp":4.5,"tv":32109.98,"id":2497008}],"tv":227488.46}]}
{"op":"mcm","clk":"4299630517","pt":1632581347451,"mc":[{"id":"1.188136695","rc":[{"batb":[[0,1.27,57.36],[1,1.26,1944.63],[2,1.25,1618.34]],"batl":[[0,1.28,2772.58]],"ltp":1.26,"tv":195378.48,"id":5300737}]}]}
{"op":"mcm","clk":"4299630793","pt":1632581348648,"mc":[{"id":"1.188136695","rc":[{"batb":[[1,1.26,1606.37],[2,1.25,1591.77]],"ltp":1.26,"tv":195378.48,"id":5300737},{"batl":[[0,5.6,40.21]],"ltp":4.5,"tv":32109.98,"id":2497008}]}]}
{"op":"mcm","clk":"4299631024","pt":1632581349663,"mc":[{"id":"1.188136695","rc":[{"trd":[[1.27,1982.36]],"batb":[[0,1.26,1605.02],[1,1.25,1583.74],[2,1.24,2632.16]],"ltp":1.27,"tv":195493.2,"id":5300737},{"batb":[[0,4.5,573.55]],"batl":[[0,5,2.14],[1,5.6,40.21],[2,5.8,13.72]],"ltp":4.5,"tv":32109.98,"id":2497008}],"tv":227603.18}]}
{"op":"mcm","clk":"4299631220","pt":1632581350494,"mc":[{"id":"1.188136695","rc":[{"batb":[[1,1.25,1585.5]],"batl":[[0,1.27,85.71],[1,1.28,2772.58],[2,1.29,1117.07]],"ltp":1.27,"tv":195493.2,"id":5300737},{"batl":[[1,5.3,60.12],[2,5.4,59.74]],"ltp":4.5,"tv":32109.98,"id":2497008}]}]}
{"op":"mcm","clk":"4299631353","pt":1632581351187,"mc":[{"id":"1.188136695","rc":[{"trd":[[1.26,3880.01],[1.27,2037.98]],"batb":[[0,1.26,1602.52]],"batl":[[0,1.27,30.09]],"ltp":1.26,"tv":195553.82,"id":5300737},{"trd":[[4.7,207.46]],"ltp":4.7,"tv":32125.01,"id":2497008}],"tv":227678.83}]}
{"op":"mcm","clk":"4299631738","pt":1632581352755,"mc":[{"id":"1.188136695","rc":[{"trd":[[1.26,3916.05]],"batb":[[0,1.26,1584.5]],"batl":[[0,1.27,48.95],[1,1.28,4541.51]],"ltp":1.26,"tv":195589.86,"id":5300737},{"batb":[[0,4.6,25],[1,4.5,573.55],[2,4.4,86.89]],"batl":[[2,5.4,70.46]],"ltp":4.7,"tv":32125.01,"id":2497008}],"tv":227714.87}]}
{"op":"mcm","clk":"4299631908","pt":1632581353452,"mc":[{"id":"1.188136695","rc":[{"trd":[[1.27,2056.01]],"batl":[[0,1.27,39.93]],"ltp":1.27,"tv":195607.9,"id":5300737}],"tv":227732.91}]}
{"op":"mcm","clk":"4299632238","pt":1632581354697,"mc":[{"id":"1.188136695","rc":[{"batl":[[0,4.8,10],[1,5,2.14],[2,5.3,60.12]],"ltp":4.7,"tv":32125.01,"id":2497008}]}]}
{"op":"mcm","clk":"4299632366","pt":1632581355259,"mc":[{"id":"1.188136695","rc":[{"trd":[[1.27,2056.9]],"batb":[[1,1.25,1460.5]],"batl":[[0,1.27,39.49]],"ltp":1.27,"tv":195608.78,"id":5300737},{"batl":[[1,5,32.49]],"ltp":4.7,"tv":32125.01,"id":2497008}],"tv":227733.79}]}
{"op":"mcm","clk":"4299632703","pt":1632581356698,"mc":[{"id":"1.188136695","rc":[{"trd":[[1.27,2060.42]],"batl":[[0,1.27,37.73],[1,1.28,2862.58]],"ltp":1.27,"tv":195612.3,"id":5300737},{"batb":[[1,4.5,673.55]],"ltp":4.7,"tv":32125.01,"id":2497008}],"tv":227737.31}]}
{"op":"mcm","clk":"4299632809","pt":1632581357086,"mc":[{"id":"1.188136695","rc":[{"trd":[[1.27,2074.13]],"batl":[[0,1.27,30.87]],"ltp":1.27,"tv":195626.01,"id":5300737}],"tv":227751.02}]}
{"op":"mcm","clk":"4299633229","pt":1632581358584,"mc":[{"id":"1.188136695","rc":[{"trd":[[1.26,3916.09],[1.27,2078.69]],"batb":[[0,1.26,1584.48]],"batl":[[0,1.27,28.59]],"ltp":1.26,"tv":195630.61,"id":5300737},{"batb":[[1,4.5,449.21]],"ltp":4.7,"tv":32125.01,"id":2497008}],"tv":227755.62}]}
{"op":"mcm","clk":"4299633462","pt":1632581359480,"mc":[{"id":"1.188136695","rc":[{"trd":[[1.26,3916.26],[1.27,2079.83]],"batb":[[0,1.26,1584.4]],"batl":[[0,1.27,28.02]],"ltp":1.26,"tv":195631.92,"id":5300737}],"tv":227756.93}]}
{"op":"mcm","clk":"4299633831","pt":1632581360781,"mc":[{"id":"1.188136695","rc":[{"trd":[[1.26,3916.32],[1.27,2135.88]],"batb":[[0,1.27,54.15],[1,1.26,1584.36],[2,1.25,1453.65]],"batl":[[0,1.28,3413.71],[1,1.29,1769.34],[2,1.3,261.32]],"ltp":1.27,"tv":195688.03,"id":5300737},{"trd":[[4.8,882.95]],"batb":[[0,4.6,75],[1,4.5,605.97],[2,4.4,278.12]],"batl":[[0,4.8,9.65]],"ltp":4.8,"tv":32125.71,"id":2497008}],"tv":227813.74}]}
{"op":"mcm","clk":"4299634043","pt":1632581361705,"mc":[{"id":"1.188136695","rc":[{"trd":[[1.28,223.84]],"batb":[[1,1.26,2142.35],[2,1.25,2201.06]],"batl":[[0,1.28,3395.43]],"ltp":1.28,"tv":195724.6,"id":5300737},{"batb":[[0,4.6,125]],"batl":[[1,4.9,143.48],[2,5,219.34]],"ltp":4.8,"tv":32125.71,"id":2497008}],"tv":227850.31}]}
{"op":"mcm","clk":"4299634280","pt":1632581362687,"mc":[{"id":"1.188136695","rc":[{"batb":[[0,1.27,95.95]],"ltp":1.28,"tv":195724.6,"id":5300737}]}]}
{"op":"mcm","clk":"4299634499","pt":1632581363662,"mc":[{"id":"1.188136695","rc":[{"trd":[[1.26,4473.78],[1.27,2327.78]],"batb":[[0,1.26,1863.62],[1,1.25,2199.3],[2,1.24,2632.16]],"ltp":1.26,"tv":196473.96,"id":5300737}],"tv":228599.67}]}
{"op":"mcm","clk":"4299634629","pt":1632581364270,"mc":[{"id":"1.188136695","rc":[{"trd":[[1.26,4473.95]],"batb":[[0,1.26,1863.53]],"ltp":1.26,"tv":196474.13,"id":5300737},{"batl":[[2,5,217.2]],"ltp":4.8,"tv":32125.71,"id":2497008}],"tv":228599.84}]}
{"op":"mcm","clk":"4299634824","pt":1632581365016,"mc":[{"id":"1.188136695","rc":[{"trd":[[4.8,888.21]],"batl":[[0,4.8,7.02]],"ltp":4.8,"tv":32130.97,"id":2497008}],"tv":228605.1}]}
{"op":"mcm","clk":"4299635126","pt":1632581366184,"mc":[{"id":"1.188136695","rc":[{"trd":[[1.26,4491.99]],"batb":[[0,1.26,1854.51]],"batl":[[0,1.28,5021.52]],"ltp":1.26,"tv":196492.16,"id":5300737}],"tv":228623.13}]}
{"op":"mcm","clk":"4299635439","pt":1632581367490,"mc":[{"id":"1.188136695","rc":[{"trd":[[1.26,4492.78]],"batb":[[0,1.26,1854.12]],"ltp":1.26,"tv":196492.95,"id":5300737},{"batl":[[0,4.8,7.37]],"ltp":4.8,"tv":32130.97,"id":2497008}],"tv":228623.92}]}
{"op":"mcm","clk":"4299635780","pt":1632581368806,"mc":[{"id":"1.188136695","rc":[{"trd":[[1.26,4494.74],[1.27,2329.08],[1.28,373.84]],"batb":[[0,1.26,1853.14]],"batl":[[0,1.28,4946.52]],"ltp":1.28,"tv":196646.21,"id":5300737},{"trd":[[4.7,207.81]],"batb":[[2,4.4,277.68]],"batl":[[0,4.8,7.02]],"ltp":4.7,"tv":32131.32,"id":2497008}],"tv":228777.53}]}
{"op":"mcm","clk":"4299635992","pt":1632581369698,"mc":[{"id":"1.188136695","rc":[{"trd":[[1.28,401.12]],"batb":[[0,1.26,1854.07]],"batl":[[0,1.28,4932.88]],"ltp":1.28,"tv":196673.49,"id":5300737}],"tv":228804.81}]}
{"op":"mcm","clk":"4299636269","pt":1632581370699,"mc":[{"id":"1.188136695","rc":[{"trd":[[1.26,4513.16],[1.27,2333.75],[1.28,404.64]],"batb":[[0,1.27,3.6],[1,1.26,1843.93],[2,1.25,2199.3]],"batl":[[0,1.28,4931.12]],"ltp":1.27,"tv":196700.1,"id":5300737}],"tv":228831.42}]}
{"op":"mcm","clk":"4299636524","pt":1632581371799,"mc":[{"id":"1.188136695","rc":[{"batl":[[0,1.28,3305.03]],"ltp":1.27,"tv":196700.1,"id":5300737},{"batb":[[2,4.4,274.68]],"ltp":4.7,"tv":32131.32,"id":2497008}]}]}
{"op":"mcm","clk":"4299636738","pt":1632581372783,"mc":[{"id":"1.188136695","rc":[{"batl":[[0,1.28,3215.03]],"ltp":1.27,"tv":196700.1,"id":5300737},{"batb":[[0,4.6,100]],"ltp":4.7,"tv":32131.32,"id":2497008}]}]}
{"op":"mcm","clk":"4299636958","pt":1632581373821,"mc":[{"id":"1.188136695","rc":[{"trd":[[1.28,404.76]],"batl":[[0,1.28,3214.97]],"ltp":1.28,"tv":196700.22,"id":5300737}],"tv":228831.54}]}
{"op":"mcm","clk":"4299637428","pt":1632581375677,"mc":[{"id":"1.188136695","rc":[{"trd":[[1.28,435.84]],"batl":[[0,1.28,3199.43]],"ltp":1.28,"tv":196731.3,"id":5300737},{"batb":[[0,4.5,505.97],[1,4.4,274.68],[2,4.3,491.73]],"ltp":4.7,"tv":32131.32,"id":2497008}],"tv":228862.62}]}
{"op":"mcm","clk":"4299637628","pt":1632581376604,"mc":[{"id":"1.188136695","rc":[{"trd":[[1.28,471.3]],"batl":[[0,1.28,3181.7]],"ltp":1.28,"tv":196766.76,"id":5300737}],"tv":228898.08}]}
{"op":"mcm","clk":"4299637838","pt":1632581377621,"mc":[{"id":"1.188136695","rc":[{"trd":[[1.27,2340.95]],"batb":[[0,1.26,1843.93],[1,1.25,2199.3],[2,1.24,2632.16]],"batl":[[0,1.27,10.04],[1,1.28,3181.7],[2,1.29,1769.34]],"ltp":1.27,"tv":196773.96,"id":5300737}],"tv":228905.28}]}
{"op":"mcm","clk":"4299638144","pt":1632581378826,"mc":[{"id":"1.188136695","rc":[{"trd":[[1.26,4517.46],[1.28,478.5]],"batb":[[0,1.26,1833.33]],"batl":[[0,1.28,3268.1],[1,1.29,1769.34],[2,1.3,261.32]],"ltp":1.26,"tv":196785.45,"id":5300737},{"trd":[[4.8,888.84]],"batb":[[0,4.5,531.68]],"batl":[[0,4.8,6.71]],"ltp":4.8,"tv":32131.94,"id":2497008}],"tv":228917.4}]}
{"op":"mcm","clk":"4299638367","pt":1632581379805,"mc":[{"id":"1.188136695","rc":[{"trd":[[1.26,4518.66],[1.28,479.68]],"batb":[[0,1.26,1832.72]],"batl":[[0,1.28,3267.51]],"ltp":1.28,"tv":196787.83,"id":5300737}],"tv":228919.78}]}
{"op":"mcm","clk":"4299638621","pt":1632581380817,"mc":[{"id":"1.188136695","rc":[{"batb":[[1,1.25,793.43],[2,1.24,1156.75]],"batl":[[0,1.27,7.01],[1,1.28,2114.58],[2,1.29,652.27]],"ltp":1.28,"tv":196787.83,"id":5300737}]}]}
{"op":"mcm","clk":"4299638701","pt":1632581381131,"mc":[{"id":"1.188136695","rc":[{"trd":[[1.26,4523.36]],"batb":[[0,1.26,1830.38]],"ltp":1.26,"tv":196792.53,"id":5300737}],"tv":228924.47}]}
{"op":"mcm","clk":"4299639082","pt":1632581382708,"mc":[{"id":"1.188136695","rc":[{"trd":[[1.27,2360.13],[1.28,487.03]],"batl":[[0,1.28,2110.9],[1,1.29,652.27],[2,1.3,255.19]],"ltp":1.28,"tv":196819.07,"id":5300737}],"tv":228951.02}]}
{"op":"mcm","clk":"4299639301","pt":1632581383721,"mc":[{"id":"1.188136695","rc":[{"trd":[[1.26,4525.96]],"batb":[[0,1.26,1829.08]],"ltp":1.26,"tv":196821.67,"id":5300737}],"tv":228953.62}]}
{"op":"mcm","clk":"4299639709","pt":1632581385213,"mc":[{"id":"1.188136695","rc":[{"trd":[[1.26,4558.07]],"batb":[[0,1.26,1813.02]],"ltp":1.26,"tv":196853.79,"id":5300737}],"tv":228985.73}]}
{"op":"mcm","clk":"4299640293","pt":1632581387829,"mc":[{"id":"1.188136695","rc":[{"trd":[[1.26,4585.35],[1.28,493.05]],"batb":[[0,1.26,1799.38]],"batl":[[0,1.28,2107.89]],"ltp":1.28,"tv":196887.08,"id":5300737},{"batb":[[2,4.3,425.01]],"ltp":4.8,"tv":32131.94,"id":2497008}],"tv":229019.03}]}
{"op":"mcm","clk":"4299640508","pt":1632581388632,"mc":[{"id":"1.188136695","rc":[{"batb":[[0,1.23,2393.61],[1,1.22,1984.81],[2,1.21,2075.66]],"batl":[[0,1.28,90],[1,1.3,4.29],[2,1.32,119.6]],"ltp":1.28,"tv":196887.08,"id":5300737},{"batb":[[0,4.5,151.77],[1,4.3,4.3],[2,4.1,1]],"batl":[[1,5.2,10.97],[2,5.3,60.12]],"ltp":4.8,"tv":32131.94,"id":2497008}]}]}
{"op":"mcm","clk":"4299640690","pt":1632581389405,"mc":[{"id":"1.188136695","rc":[{"trd":[[1.27,2360.83],[1.28,493.13]],"batl":[[0,1.27,11.11],[1,1.28,89.96],[2,1.3,4.29]],"ltp":1.28,"tv":196887.86,"id":5300737}],"tv":229019.81}]}
{"op":"mcm","clk":"4299641016","pt":1632581390719,"mc":[{"id":"1.188136695","rc":[{"trd":[[1.26,4587.46],[1.27,2377.88]],"batl":[[0,1.27,2.59],[1,1.3,4.29],[2,1.32,119.6]],"ltp":1.27,"tv":196907.02,"id":5300737},{"trd":[[4.8,889.39]],"batb":[[0,4.5,126.06],[1,4.1,1],[2,4,273.35]],"batl":[[0,4.8,6.16],[1,5.3,60.12],[2,5.4,59.74]],"ltp":4.8,"tv":32132.49,"id":2497008}],"tv":229039.51}]}
{"op":"mcm","clk":"4299641229","pt":1632581391735,"mc":[{"id":"1.188136695","rc":[{"trd":[[1.27,2378.68]],"batb":[[0,1.23,1147.08],[1,1.22,3251.72]],"batl":[[0,1.27,2.19]],"ltp":1.27,"tv":196907.82,"id":5300737},{"batb":[[2,4,267.43]],"ltp":4.8,"tv":32132.49,"id":2497008}],"tv":229040.31}]}
{"op":"mcm","clk":"4299641459","pt":1632581392742,"mc":[{"id":"1.188136695","rc":[{"batb":[[0,1.23,402.61],[1,1.22,1633.08]],"ltp":1.27,"tv":196907.82,"id":5300737}]}]}
{"op":"mcm","clk":"4299641621","pt":1632581393446,"mc":[{"id":"1.188136695","rc":[{"trd":[[1.26,4596.03],[1.27,2383.06],[1.28,495.24]],"batl":[[0,1.3,4.29],[1,1.32,119.6],[2,1.34,189.59]],"ltp":1.26,"tv":196922.88,"id":5300737},{"trd":[[4.6,4.59],[4.8,891.64]],"batb":[[0,4.7,3.35],[1,4.5,126.06],[2,4.1,1]],"batl":[[0,4.8,3.91]],"ltp":4.8,"tv":32135.33,"id":2497008}],"tv":229058.22}]}
{"op":"mcm","clk":"4299641747","pt":1632581393948,"mc":[{"id":"1.188136695","rc":[{"batl":[[0,1.27,2.04],[1,1.3,4.29],[2,1.32,119.6]],"ltp":1.26,"tv":196922.88,"id":5300737}]}]}
{"op":"mcm","clk":"4299642118","pt":1632581395637,"mc":[{"id":"1.188136695","rc":[{"trd":[[1.27,2383.14]],"batb":[[0,1.26,1263.58],[1,1.25,1399.45],[2,1.23,402.61]],"batl":[[0,1.27,2],[1,1.29,1274.26],[2,1.3,1075.32]],"ltp":1.27,"tv":196922.96,"id":5300737},{"batb":[[0,4.5,126.06],[1,4.1,1],[2,4,267.43]],"ltp":4.8,"tv":32135.33,"id":2497008}],"tv":229058.29}]}
{"op":"mcm","clk":"4299642379","pt":1632581396720,"mc":[{"id":"1.188136695","rc":[{"trd":[[1.26,4600.73],[1.27,2387.13]],"batb":[[0,1.27,950.26],[1,1.26,1261.23],[2,1.25,1399.45]],"batl":[[0,1.29,1295.71],[1,1.3,1161.03],[2,1.32,119.6]],"ltp":1.27,"tv":196931.65,"id":5300737}],"tv":229066.98}]}
{"op":"mcm","clk":"4299642597","pt":1632581397763,"mc":[{"id":"1.188136695","rc":[{"batb":[[0,1.27,951.58],[1,1.23,402.61],[2,1.22,1633.08]],"batl":[[0,1.3,90],[1,1.32,119.6],[2,1.34,189.59]],"ltp":1.27,"tv":196931.65,"id":5300737}]}]}
{"op":"mcm","clk":"4299642766","pt":1632581398540,"mc":[{"id":"1.188136695","rc":[{"batb":[[0,1.28,34.55],[1,1.27,1.05],[2,1.23,402.61]],"ltp":1.27,"tv":196931.65,"id":5300737}]}]}
{"op":"mcm","clk":"4299643007","pt":1632581399738,"mc":[{"id":"1.188136695","rc":[{"trd":[[1.27,2393.78],[1.28,564.33]],"batb":[[0,1.27,4.74],[1,1.26,105.38]],"ltp":1.27,"tv":197007.39,"id":5300737}],"tv":229142.72}]}
{"op":"mcm","clk":"4299643248","pt":1632581400739,"mc":[{"id":"1.188136695","rc":[{"batb":[[1,1.24,50],[2,1.23,1146.07]],"batl":[[0,1.28,1.98],[1,1.3,90],[2,1.32,119.6]],"ltp":1.27,"tv":197007.39,"id":5300737}]}]}
{"op":"mcm","clk":"4299643348","pt":1632581401245,"mc":[{"id":"1.188136695","rc":[{"trd":[[1.27,2393.98]],"batb":[[0,1.27,8.15]],"batl":[[0,1.28,12.69]],"ltp":1.27,"tv":197007.59,"id":5300737}],"tv":229142.92}]}
{"op":"mcm","clk":"4299643690","pt":1632581402768,"mc":[{"id":"1.188136695","rc":[{"batb":[[0,1.27,6.39]],"batl":[[0,1.28,25.02]],"ltp":1.27,"tv":197007.59,"id":5300737}]}]}
{"op":"mcm","clk":"4299643914","pt":1632581403642,"mc":[{"id":"1.188136695","rc":[{"trd":[[1.26,4615.63],[1.27,2406.76]],"batb":[[0,1.24,50],[1,1.23,1064.8],[2,1.22,3251.72]],"ltp":1.26,"tv":197035.27,"id":5300737},{"trd":[[4.8,895.55]],"batl":[[0,5.3,60.12],[1,5.4,59.74],[2,5.5,95.59]],"ltp":4.8,"tv":32139.24,"id":2497008}],"tv":229174.51}]}
{"op":"mcm","clk":"4299644142","pt":1632581404765,"mc":[{"id":"1.188136695","rc":[{"trd":[[1.28,568.62]],"batl":[[0,1.25,12729.24],[1,1.27,2222],[2,1.28,22.87]],"ltp":1.28,"tv":197039.57,"id":5300737}],"tv":229178.81}]}
{"op":"mcm","clk":"4299644372","pt":1632581405641,"mc":[{"id":"1.188136695","rc":[{"batl":[[0,1.25,1404.63],[1,1.26,1280.97],[2,1.27,2222]],"ltp":1.28,"tv":197039.57,"id":5300737},{"trd":[[5,647.69]],"batb":[[0,5,141.2],[1,4.9,78.12],[2,4.8,78.12]],"ltp":5.0,"tv":32169.34,"id":2497008}],"tv":229208.92}]}
{"op":"mcm","clk":"4299644630","pt":1632581406751,"mc":[{"id":"1.188136695","rc":[{"batl":[[2,1.27,2321.32]],"ltp":1.28,"tv":197039.57,"id":5300737},{"trd":[[5,664.71]],"batb":[[0,5,300.69]],"ltp":5.0,"tv":32186.36,"id":2497008}],"tv":229225.94}]}
{"op":"mcm","clk":"4299644801","pt":1632581407570,"mc":[{"id":"1.188136695","rc":[{"trd":[[1.25,4474.78]],"batl":[[0,1.25,2349.88],[1,1.26,1370.97],[2,1.27,99.63]],"ltp":1.25,"tv":197053.59,"id":5300737},{"batb":[[1,4.9,101.19]],"ltp":5.0,"tv":32186.36,"id":2497008}],"tv":229239.96}]}
{"op":"mcm","clk":"4299645299","pt":1632581409557,"mc":[{"id":"1.188136695","rc":[{"trd":[[1.25,4569.01]],"batl":[[0,1.25,3017.28],[1,1.26,1280.97]],"ltp":1.25,"tv":197147.82,"id":5300737},{"batb":[[0,5,302.69],[1,4.9,103.19]],"ltp":5.0,"tv":32186.36,"id":2497008}],"tv":229334.19}]}
{"op":"mcm","clk":"4299645593","pt":1632581410773,"mc":[{"id":"1.188136695","rc":[{"trd":[[1.24,8607.61]],"batb":[[0,1.24,500.96]],"batl":[[0,1.25,4034.37],[1,1.26,2467.22],[2,1.27,796.47]],"ltp":1.24,"tv":197151.24,"id":5300737},{"batb":[[0,5,437.9],[1,4.9,80.12],[2,4.8,389.5]],"ltp":5.0,"tv":32186.36,"id":2497008}],"tv":229337.61}]}
{"op":"mcm","clk":"4299645665","pt":1632581411035,"mc":[{"id":"1.188136695","rc":[{"batb":[[0,1.24,452.67]],"ltp":1.24,"tv":197151.24,"id":5300737}]}]}
{"op":"mcm","clk":"4299646036","pt":1632581412757,"mc":[{"id":"1.188136695","rc":[{"batl":[[0,1.25,4124.37]],"ltp":1.24,"tv":197151.24,"id":5300737}]}]}
{"op":"mcm","clk":"4299646271","pt":1632581413740,"mc":[{"id":"1.188136695","rc":[{"trd":[[1.24,8976.15]],"batb":[[0,1.24,268.4]],"batl":[[0,1.25,2703.39]],"ltp":1.24,"tv":197519.78,"id":5300737},{"batb":[[1,4.9,103.19]],"ltp":5.0,"tv":32186.36,"id":2497008}],"tv":229706.15}]}
{"op":"mcm","clk":"4299646371","pt":1632581414178,"mc":[{"id":"1.188136695","rc":[{"trd":[[1.25,4665.59]],"batl":[[0,1.25,2655.1]],"ltp":1.25,"tv":197616.36,"id":5300737}],"tv":229802.73}]}
{"op":"mcm","clk":"4299646604","pt":1632581415143,"mc":[{"id":"1.188136695","rc":[{"trd":[[1.24,8976.49]],"batb":[[0,1.24,268.23]],"ltp":1.24,"tv":197616.71,"id":5300737}],"tv":229803.07}]}
{"op":"mcm","clk":"4299646964","pt":1632581416772,"mc":[{"id":"1.188136695","rc":[{"trd":[[1.25,4668.81]],"batb":[[0,1.24,83.95],[1,1.23,1582.64]],"batl":[[0,1.25,3182.02],[1,1.26,2557.22]],"ltp":1.25,"tv":197619.92,"id":5300737}],"tv":229806.29}]}
{"op":"mcm","clk":"4299647072","pt":1632581417257,"mc":[{"id":"1.188136695","rc":[{"trd":[[1.25,4682.83]],"batl":[[0,1.25,2646.48]],"ltp":1.25,"tv":197633.94,"id":5300737}],"tv":229820.31}]}
{"op":"mcm","clk":"4299647389","pt":1632581418674,"mc":[{"id":"1.188136695","rc":[{"trd":[[1.25,4689.88]],"batb":[[0,1.23,1582.64],[1,1.22,3251.72],[2,1.21,2394.11]],"batl":[[0,1.25,2642.95]],"ltp":1.25,"tv":197641.0,"id":5300737}],"tv":229827.37}]}
{"op":"mcm","clk":"4299647615","pt":1632581419647,"mc":[{"id":"1.188136695","rc":[{"trd":[[1.25,4697.54]],"batl":[[0,1.25,2639.12]],"ltp":1.25,"tv":197648.65,"id":5300737},{"batb":[[0,5,305.21],[1,4.9,25.07],[2,4.8,311.38]],"ltp":5.0,"tv":32186.36,"id":2497008}],"tv":229835.02}]}
{"op":"mcm","clk":"4299647811","pt":1632581420507,"mc":[{"id":"1.188136695","rc":[{"batb":[[0,1.22,13.64],[1,1.21,1460.98],[2,1.2,3508.96]],"batl":[[0,1.26,90],[1,1.28,10.85],[2,1.29,162.46]],"ltp":1.25,"tv":197648.65,"id":5300737},{"batb":[[0,4.9,23.07],[1,4.5,126.06],[2,4.4,222.28]],"batl":[[0,5.7,75.47],[1,5.8,69.44],[2,5.9,66.49]],"ltp":5.0,"tv":32186.36,"id":2497008}]}]}
{"op":"mcm","clk":"4299648059","pt":1632581421460,"mc":[{"id":"1.188136695","rc":[{"trd":[[1.25,4701.06]],"batb":[[1,1.21,1657.37]],"batl":[[0,1.28,10.85],[1,1.29,162.46],[2,1.3,244.42]],"ltp":1.25,"tv":197652.17,"id":5300737},{"batb":[[0,4.5,126.06],[1,4.4,222.28],[2,4.3,58.15]],"batl":[[0,5.7,65.1]],"ltp":5.0,"tv":32186.36,"id":2497008}],"tv":229838.54}]}
{"op":"mcm","clk":"4299648392","pt":1632581422784,"mc":[{"id":"1.188136695","rc":[{"trd":[[1.24,8980.67]],"batb":[[0,1.24,16.77],[1,1.22,13.64],[2,1.21,2266.83]],"batl":[[1,1.29,1189.48],[2,1.3,1319.52]],"ltp":1.24,"tv":197656.35,"id":5300737}],"tv":229842.72}]}
{"op":"mcm","clk":"4299648641","pt":1632581423649,"mc":[{"id":"1.188136695","rc":[{"batb":[[0,1.25,3.61],[1,1.24,120.48],[2,1.22,13.64]],"ltp":1.24,"tv":197656.35,"id":5300737}]}]}
{"op":"mcm","clk":"4299648893","pt":1632581424706,"mc":[{"id":"1.188136695","rc":[{"trd":[[1.25,4701.22]],"batb":[[0,1.25,7]],"batl":[[0,1.27,7.32],[1,1.28,10.54],[2,1.29,85.71]],"ltp":1.25,"tv":197656.51,"id":5300737}],"tv":229842.88}]}
{"op":"mcm","clk":"4299649174","pt":1632581425665,"mc":[{"id":"1.188136695","rc":[{"batb":[[0,1.25,11.21]],"ltp":1.25,"tv":197656.51,"id":5300737}]}]}
{"op":"mcm","clk":"4299649443","pt":1632581426676,"mc":[{"id":"1.188136695","rc":[{"trd":[[1.25,4718.37]],"batb":[[0,1.25,2.64],[2,1.22,15.53]],"ltp":1.25,"tv":197673.66,"id":5300737},{"batl":[[0,5.5,463.53],[1,5.7,65.1],[2,5.8,69.44]],"ltp":5.0,"tv":32186.36,"id":2497008}],"tv":229860.03}]}
{"op":"mcm","clk":"4299649599","pt":1632581427270,"mc":[{"id":"1.188136695","rc":[{"batb":[[2,1.23,1845.39]],"batl":[[0,1.26,1244.02],[1,1.27,1224.75],[2,1.28,22.87]],"ltp":1.25,"tv":197673.66,"id":5300737},{"batl":[[0,5.7,65.1],[1,5.8,69.44],[2,5.9,66.49]],"ltp":5.0,"tv":32186.36,"id":2497008}]}]}
{"op":"mcm","clk":"4299649980","pt":1632581428770,"mc":[{"id":"1.188136695","rc":[{"batb":[[1,1.24,1072.74]],"batl":[[0,1.26,1280.62]],"ltp":1.25,"tv":197673.66,"id":5300737},{"batb":[[0,4.6,26.91],[1,4.5,126.06],[2,4.4,222.28]],"batl":[[0,5.6,21.47],[1,5.7,65.1],[2,5.8,69.44]],"ltp":5.0,"tv":32186.36,"id":2497008}]}]}
{"op":"mcm","clk":"4299650194","pt":1632581429696,"mc":[{"id":"1.188136695","rc":[{"trd":[[1.26,4693.1]],"batl":[[0,1.26,1241.88]],"ltp":1.26,"tv":197751.14,"id":5300737}],"tv":229937.5}]}
{"op":"mcm","clk":"4299650413","pt":1632581430783,"mc":[{"id":"1.188136695","rc":[{"trd":[[1.24,8982.91],[1.25,4723.65]],"batb":[[0,1.24,119.35],[1,1.22,15.53],[2,1.21,318.45]],"batl":[[0,1.27,7.32],[1,1.28,22.87],[2,1.29,85.71]],"ltp":1.24,"tv":197758.66,"id":5300737},{"batb":[[0,4.5,126.06],[1,4.4,222.28],[2,4.3,58.15]],"batl":[[0,5.7,65.1],[1,5.8,69.44],[2,5.9,66.49]],"ltp":5.0,"tv":32186.36,"id":2497008}],"tv":229945.03}]}
{"op":"mcm","clk":"4299651003","pt":1632581433511,"mc":[{"id":"1.188136695","rc":[{"batb":[[2,1.21,1142.99]],"batl":[[2,1.29,1095.24]],"ltp":1.24,"tv":197758.66,"id":5300737}]}]}
{"op":"mcm","clk":"4299651241","pt":1632581434404,"mc":[{"id":"1.188136695","rc":[{"batl":[[0,1.25,2.81],[1,1.27,7.32],[2,1.28,22.87]],"ltp":1.24,"tv":197758.66,"id":5300737}]}]}
{"op":"mcm","clk":"4299651519","pt":1632581435470,"mc":[{"id":"1.188136695","rc":[{"trd":[[1.25,4724.33],[1.27,2407.39],[1.28,614.36]],"batb":[[0,1.28,3],[1,1.24,119.35],[2,1.22,15.53]],"batl":[[0,1.29,1095.24],[1,1.3,1319.51],[2,1.31,247.36]],"ltp":1.28,"tv":197805.7,"id":5300737}],"tv":229992.07}]}
{"op":"mcm","clk":"4299651727","pt":1632581436481,"mc":[{"id":"1.188136695","rc":[{"batb":[[1,1.26,7.01],[2,1.25,115.25]],"ltp":1.28,"tv":197805.7,"id":5300737}]}]}
{"op":"mcm","clk":"4299652173","pt":1632581438685,"mc":[{"id":"1.188136695","rc":[{"trd":[[1.28,620.36]],"batb":[[0,1.26,7.01],[1,1.25,115.25],[2,1.24,119.35]],"batl":[[0,1.29,1098.24]],"ltp":1.28,"tv":197811.7,"id":5300737}],"tv":229998.07}]}
{"op":"mcm","clk":"4299652694","pt":1632581440818,"mc":[{"id":"1.188136695","rc":[{"batb":[[0,1.26,7.36],[1,1.25,134.62]],"ltp":1.28,"tv":197811.7,"id":5300737}]}]}
{"op":"mcm","clk":"4299652901","pt":1632581441778,"mc":[{"id":"1.188136695","rc":[{"trd":[[1.26,4693.92],[1.27,2407.74]],"batb":[[0,1.26,6.19]],"ltp":1.26,"tv":197812.87,"id":5300737},{"trd":[[4.8,895.64],[4.9,4.21]],"ltp":4.9,"tv":32186.66,"id":2497008}],"tv":229999.54}]}
{"op":"mcm","clk":"4299653081","pt":1632581442701,"mc":[{"id":"1.188136695","rc":[{"batb":[[1,1.25,19.37],[2,1.24,15.64]],"batl":[[0,1.29,88.71],[1,1.3,4.29],[2,1.32,119.6]],"ltp":1.26,"tv":197812.87,"id":5300737},{"batb":[[2,4.1,1]],"ltp":4.9,"tv":32186.66,"id":2497008}]}]}
{"op":"mcm","clk":"4299653304","pt":1632581443727,"mc":[{"id":"1.188136695","rc":[{"trd":[[1.22,487.54],[1.24,9014.19],[1.25,4763.07],[1.26,4706.3]],"batb":[[0,1.21,1142.99],[1,1.2,5250.12],[2,1.19,1578.85]],"batl":[[0,1.28,8.03],[1,1.29,88.71],[2,1.3,4.29]],"ltp":1.22,"tv":197926.32,"id":5300737}],"tv":230112.99}]}
{"op":"mcm","clk":"4299653488","pt":1632581444612,"mc":[{"id":"1.188136695","rc":[{"batl":[[0,1.23,13676.22],[1,1.24,2222],[2,1.28,8.03]],"ltp":1.22,"tv":197926.32,"id":5300737},{"batb":[[0,5.2,1103.36],[1,5.1,1070.91],[2,5,1070.91]],"ltp":4.9,"tv":32186.66,"id":2497008}]}]}
{"op":"mcm","clk":"4299653715","pt":1632581445701,"mc":[{"id":"1.188136695","rc":[{"trd":[[1.23,3148.53]],"batl":[[0,1.23,1496.12],[1,1.24,3625.17],[2,1.26,12.34]],"ltp":1.23,"tv":198156.83,"id":5300737},{"batb":[[0,5.2,1158.53],[1,5.1,1124.46],[2,5,1124.46]],"batl":[[0,5.8,69.44],[1,5.9,66.49],[2,6,13.03]],"ltp":4.9,"tv":32186.66,"id":2497008}],"tv":230343.5}]}
{"op":"mcm","clk":"4299653989","pt":1632581446813,"mc":[{"id":"1.188136695","rc":[{"batb":[[2,1.19,3088.93]],"batl":[[0,1.23,2448.38],[1,1.24,1403.17],[2,1.26,6.32]],"ltp":1.23,"tv":198156.83,"id":5300737},{"trd":[[5.3,231.23]],"batb":[[0,5.3,136.67],[1,5.2,352.43],[2,5.1,321.28]],"ltp":5.3,"tv":32202.66,"id":2497008}],"tv":230359.5}]}
{"op":"mcm","clk":"4299654182","pt":1632581447717,"mc":[{"id":"1.188136695","rc":[{"trd":[[1.23,3152.75]],"batl":[[0,1.23,2488.13],[1,1.24,1493.17]],"ltp":1.23,"tv":198161.05,"id":5300737},{"trd":[[5.3,234.44]],"batb":[[0,5.3,135.06]],"ltp":5.3,"tv":32205.87,"id":2497008}],"tv":230366.93}]}
{"op":"mcm","clk":"4299654639","pt":1632581449806,"mc":[{"id":"1.188136695","rc":[{"batb":[[0,1.21,1603.07]],"batl":[[0,1.22,187.47],[1,1.23,3011.09],[2,1.24,1403.17]],"ltp":1.23,"tv":198161.05,"id":5300737},{"batb":[[0,5.3,137.06],[1,5.2,354.43]],"ltp":5.3,"tv":32205.87,"id":2497008}]}]}
{"op":"mcm","clk":"4299654831","pt":1632581450709,"mc":[{"id":"1.188136695","rc":[{"batl":[[1,1.23,4223.06],[2,1.24,2046.01]],"ltp":1.23,"tv":198161.05,"id":5300737},{"batb":[[0,5.3,262.97],[1,5.2,333.01],[2,5.1,477.58]],"ltp":5.3,"tv":32205.87,"id":2497008}]}]}
{"op":"mcm","clk":"4299655075","pt":1632581451734,"mc":[{"id":"1.188136695","rc":[{"batl":[[1,1.23,3907.58]],"ltp":1.23,"tv":198161.05,"id":5300737},{"batb":[[0,5.3,274.84]],"ltp":5.3,"tv":32205.87,"id":2497008}]}]}
{"op":"mcm","clk":"4299655202","pt":1632581452316,"mc":[{"id":"1.188136695","rc":[{"batb":[[2,1.19,3674.64]],"batl":[[1,1.23,3997.58]],"ltp":1.23,"tv":198161.05,"id":5300737}]}]}
{"op":"mcm","clk":"4299655514","pt":1632581453625,"mc":[{"id":"1.188136695","rc":[{"trd":[[1.22,520.3]],"batl":[[0,1.22,184.09]],"ltp":1.22,"tv":198193.81,"id":5300737},{"batb":[[0,5.5,2],[1,5.4,3],[2,5.3,295.77]],"ltp":5.3,"tv":32205.87,"id":2497008}],"tv":230399.68}]}
{"op":"mcm","clk":"4299656001","pt":1632581455730,"mc":[{"id":"1.188136695","rc":[{"trd":[[1.22,559.42]],"batl":[[0,1.22,164.53]],"ltp":1.22,"tv":198232.92,"id":5300737}],"tv":230438.8}]}
{"op":"mcm","clk":"4299656246","pt":1632581456828,"mc":[{"id":"1.188136695","rc":[{"batb":[[0,1.21,2000.27]],"batl":[[0,1.22,463.66],[1,1.23,4790.4]],"ltp":1.22,"tv":198232.92,"id":5300737},{"batb":[[0,5.5,68.35],[2,5.3,372.75]],"ltp":5.3,"tv":32205.87,"id":2497008}]}]}
{"op":"mcm","clk":"4299656458","pt":1632581457758,"mc":[{"id":"1.188136695","rc":[{"batb":[[0,1.21,1603.07]],"batl":[[1,1.23,4329.28],[2,1.24,2047.72]],"ltp":1.22,"tv":198232.92,"id":5300737}]}]}
{"op":"mcm","clk":"4299656560","pt":1632581458249,"mc":[{"id":"1.188136695","rc":[{"trd":[[1.22,560.05]],"batl":[[0,1.22,463.35]],"ltp":1.22,"tv":198233.55,"id":5300737},{"trd":[[5.5,12.5]],"batb":[[0,5.5,66.54]],"ltp":5.5,"tv":32209.5,"id":2497008}],"tv":230443.06}]}
{"op":"mcm","clk":"4299656849","pt":1632581459729,"mc":[{"id":"1.188136695","rc":[{"trd":[[1.21,2523.94],[1.22,589.27]],"batb":[[0,1.21,1602.98]],"batl":[[0,1.22,448.73]],"ltp":1.22,"tv":198262.95,"id":5300737},{"trd":[[5.5,16.11]],"batb":[[0,5.5,64.74]],"ltp":5.5,"tv":32213.1,"id":2497008}],"tv":230476.05}]}
{"op":"mcm","clk":"4299657086","pt":1632581460820,"mc":[{"id":"1.188136695","rc":[{"trd":[[1.22,634.23]],"batl":[[0,1.22,426.25]],"ltp":1.22,"tv":198307.91,"id":5300737}],"tv":230521.01}]}
{"op":"mcm","clk":"4299657334","pt":1632581461746,"mc":[{"id":"1.188136695","rc":[{"trd":[[1.22,638.93]],"batl":[[0,1.22,423.9]],"ltp":1.22,"tv":198312.6,"id":5300737}],"tv":230525.71}]}
{"op":"mcm","clk":"4299657533","pt":1632581462550,"mc":[{"id":"1.188136695","rc":[{"trd":[[1.22,641.72]],"batb":[[0,1.21,650.36],[1,1.2,1717.61],[2,1.19,3243.45]],"batl":[[0,1.22,110.37],[1,1.23,1556.22],[2,1.24,1.71]],"ltp":1.22,"tv":198315.4,"id":5300737},{"batb":[[0,5.3,20.93],[1,4.8,181.53],[2,4.5,126.06]],"batl":[[0,6,13.03],[1,6.4,20.67],[2,6.6,11.06]],"ltp":5.5,"tv":32213.1,"id":2497008}],"tv":230528.5}]}
{"op":"mcm","clk":"4299657708","pt":1632581463351,"mc":[{"id":"1.188136695","rc":[{"trd":[[1.21,2524.51]],"batb":[[0,1.21,650.08],[1,1.2,592.6]],"batl":[[1,1.23,1466.22]],"ltp":1.21,"tv":198315.96,"id":5300737},{"batb":[[0,4.8,181.53],[1,4.5,126.06],[2,4.1,1]],"batl":[[1,6.4,10.99]],"ltp":5.5,"tv":32213.1,"id":2497008}],"tv":230529.07}]}
{"op":"mcm","clk":"4299658339","pt":1632581465748,"mc":[{"id":"1.188136695","rc":[{"trd":[[1.22,643.3]],"batb":[[0,1.21,190.28],[2,1.19,5268.51]],"batl":[[0,1.24,1.71],[1,1.25,69.46],[2,1.26,1468.88]],"ltp":1.22,"tv":198317.54,"id":5300737},{"trd":[[5.5,16.46]],"batl":[[0,6,15.03]],"ltp":5.5,"tv":32213.45,"id":2497008}],"tv":230530.99}]}
{"op":"mcm","clk":"4299658544","pt":1632581466777,"mc":[{"id":"1.188136695","rc":[{"batb":[[1,1.2,594.74]],"ltp":1.22,"tv":198317.54,"id":5300737},{"batl":[[0,6,15.38]],"ltp":5.5,"tv":32213.45,"id":2497008}]}]}
{"op":"mcm","clk":"4299658713","pt":1632581467457,"mc":[{"id":"1.188136695","rc":[{"batb":[[0,1.22,3.4],[1,1.21,190.28],[2,1.2,594.74]],"ltp":1.22,"tv":198317.54,"id":5300737},{"batl":[[0,5.5,1.13],[1,6,15.03],[2,6.4,10.99]],"ltp":5.5,"tv":32213.45,"id":2497008}]}]}
{"op":"mcm","clk":"4299658946","pt":1632581468663,"mc":[{"id":"1.188136695","rc":[{"batb":[[0,1.22,4.02]],"ltp":1.22,"tv":198317.54,"id":5300737}]}]}
{"op":"mcm","clk":"4299659188","pt":1632581469756,"mc":[{"id":"1.188136695","rc":[{"batl":[[0,5.5,1.15]],"ltp":5.5,"tv":32213.45,"id":2497008}]}]}
{"op":"mcm","clk":"4299659522","pt":1632581471372,"mc":[{"id":"1.188136695","rc":[{"batl":[[1,1.26,1468.88],[2,1.27,1213.87]],"ltp":1.22,"tv":198317.54,"id":5300737}]}]}
{"op":"mcm","clk":"4299660252","pt":1632581474760,"mc":[{"id":"1.188136695","rc":[{"trd":[[1.23,3153.45],[1.24,9015.91],[1.25,4772.07],[1.26,4738.3]],"batb":[[0,1.24,1201.81],[1,1.23,2886.88],[2,1.22,3347.39]],"batl":[[0,1.26,1460.88],[1,1.27,1213.87],[2,1.28,19.51]],"ltp":1.23,"tv":198360.95,"id":5300737},{"trd":[[4.8,911.82],[5,670.46],[5.1,262.48]],"batb":[[0,4.8,175.44],[1,4.7,2],[2,4.5,508.56]],"batl":[[1,5.6,41.36],[2,6,15.03]],"ltp":5.0,"tv":32235.8,"id":2497008}],"tv":230596.76}]}
{"op":"mcm","clk":"4299660432","pt":1632581475667,"mc":[{"id":"1.188136695","rc":[{"trd":[[1.24,10920.43]],"batb":[[0,1.24,249.55],[1,1.23,2906.98]],"ltp":1.24,"tv":200265.47,"id":5300737},{"batb":[[0,4.8,190.61]],"batl":[[0,5.4,5.75],[1,5.5,1.15],[2,5.6,41.36]],"ltp":5.0,"tv":32235.8,"id":2497008}],"tv":232501.27}]}
{"op":"mcm","clk":"4299660660","pt":1632581476528,"mc":[{"id":"1.188136695","rc":[{"batb":[[0,1.24,251.9]],"batl":[[1,1.27,1303.87]],"ltp":1.24,"tv":200265.47,"id":5300737},{"batb":[[0,4.8,214.29]],"ltp":5.0,"tv":32235.8,"id":2497008}]}]}
{"op":"mcm","clk":"4299660788","pt":1632581477160,"mc":[{"id":"1.188136695","rc":[{"batl":[[0,1.26,1508.76]],"ltp":1.24,"tv":200265.47,"id":5300737}]}]}
{"op":"mcm","clk":"4299661122","pt":1632581478759,"mc":[{"id":"1.188136695","rc":[{"batb":[[0,1.24,721.87]],"batl":[[0,1.25,106.46],[1,1.26,2742.89],[2,1.27,1303.87]],"ltp":1.24,"tv":200265.47,"id":5300737},{"batl":[[0,5.4,3]],"ltp":5.0,"tv":32235.8,"id":2497008}]}]}
{"op":"mcm","clk":"4299661310","pt":1632581479571,"mc":[{"id":"1.188136695","rc":[{"batl":[[1,1.26,3223.73],[2,1.27,1844.71]],"ltp":1.24,"tv":200265.47,"id":5300737},{"batb":[[0,4.8,340.51],[1,4.7,148.14]],"batl":[[2,5.6,51.85]],"ltp":5.0,"tv":32235.8,"id":2497008}]}]}
{"op":"mcm","clk":"4299661558","pt":1632581480673,"mc":[{"id":"1.188136695","rc":[{"batl":[[1,1.26,4845.3]],"ltp":1.24,"tv":200265.47,"id":5300737}]}]}
{"op":"mcm","clk":"4299661688","pt":1632581481230,"mc":[{"id":"1.188136695","rc":[{"batb":[[0,1.24,1267.86],[1,1.23,3656.96],[2,1.22,3657.15]],"ltp":1.24,"tv":200265.47,"id":5300737},{"batl":[[0,5.2,130.2],[1,5.4,173.82],[2,5.5,1.15]],"ltp":5.0,"tv":32235.8,"id":2497008}]}]}
{"op":"mcm","clk":"4299662021","pt":1632581482762,"mc":[{"id":"1.188136695","rc":[{"batl":[[1,5.3,9.65],[2,5.4,173.82]],"ltp":5.0,"tv":32235.8,"id":2497008}]}]}
{"op":"mcm","clk":"4299662239","pt":1632581483793,"mc":[{"id":"1.188136695","rc":[{"trd":[[1.24,10921.44],[1.25,4772.13]],"batb":[[0,1.24,1267.35],[2,1.22,3656.73]],"batl":[[0,1.25,106.43],[1,1.26,3223.73]],"ltp":1.25,"tv":200266.55,"id":5300737}],"tv":232502.35}]}
{"op":"mcm","clk":"4299662421","pt":1632581484532,"mc":[{"id":"1.188136695","rc":[{"batb":[[2,1.22,3658.62]],"batl":[[0,1.25,642.13],[1,1.26,3867.43]],"ltp":1.25,"tv":200266.55,"id":5300737},{"batb":[[0,5,133.92],[1,4.8,509.47],[2,4.7,148.14]],"ltp":5.0,"tv":32235.8,"id":2497008}]}]}
{"op":"mcm","clk":"4299662742","pt":1632581485756,"mc":[{"id":"1.188136695","rc":[{"trd":[[1.24,10921.46]],"batb":[[0,1.24,1267.34]],"ltp":1.24,"tv":200266.57,"id":5300737}],"tv":232502.38}]}
{"op":"mcm","clk":"4299662860","pt":1632581486263,"mc":[{"id":"1.188136695","rc":[{"trd":[[1.24,10926.88]],"batb":[[0,1.24,1264.63],[1,1.23,3532.31]],"ltp":1.24,"tv":200271.99,"id":5300737}],"tv":232507.8}]}
{"op":"mcm","clk":"4299663203","pt":1632581487745,"mc":[{"id":"1.188136695","rc":[{"batl":[[0,1.25,1315.07]],"ltp":1.24,"tv":200271.99,"id":5300737},{"trd":[[5,670.87]],"batb":[[0,5,133.72]],"ltp":5.0,"tv":32236.21,"id":2497008}],"tv":232508.21}]}
{"op":"mcm","clk":"4299663361","pt":1632581488465,"mc":[{"id":"1.188136695","rc":[{"trd":[[1.24,10938.43]],"batb":[[0,1.24,1258.85]],"batl":[[0,1.25,1326.07]],"ltp":1.24,"tv":200283.54,"id":5300737},{"batb":[[0,5,3],[1,4.9,2],[2,4.8,509.47]],"ltp":5.0,"tv":32236.21,"id":2497008}],"tv":232519.76}]}
{"op":"mcm","clk":"4299663668","pt":1632581489748,"mc":[{"id":"1.188136695","rc":[{"trd":[[1.25,4915.18]],"batl":[[0,1.25,1254.55]],"ltp":1.25,"tv":200426.58,"id":5300737}],"tv":232662.8}]}
{"op":"mcm","clk":"4299663851","pt":1632581490553,"mc":[{"id":"1.188136695","rc":[{"trd":[[1.24,10943.13],[1.25,4915.81]],"batb":[[0,1.22,315.25],[1,1.21,2484.13],[2,1.2,1904.38]],"batl":[[0,1.24,16.51],[1,1.27,91.76],[2,1.28,13.29]],"ltp":1.24,"tv":200431.91,"id":5300737},{"batb":[[0,4.8,23.68],[1,4.5,126.06],[2,4.2,247.14]],"batl":[[0,5.5,1.15],[1,5.6,77.2],[2,5.7,61.26]],"ltp":5.0,"tv":32236.21,"id":2497008}],"tv":232668.13}]}
{"op":"mcm","clk":"4299664017","pt":1632581491256,"mc":[{"id":"1.188136695","rc":[{"trd":[[1.24,10943.64]],"batl":[[0,1.24,16.25]],"ltp":1.24,"tv":200432.42,"id":5300737}],"tv":232668.64}]}
{"op":"mcm","clk":"4299664193","pt":1632581492029,"mc":[{"id":"1.188136695","rc":[{"batb":[[1,1.21,2287.74]],"batl":[[0,1.24,19.76],[1,1.27,1.76]],"ltp":1.24,"tv":200432.42,"id":5300737},{"batb":[[0,4.5,126.06],[1,4.2,247.14],[2,4.1,85.49]],"batl":[[1,5.6,66.71]],"ltp":5.0,"tv":32236.21,"id":2497008}]}]}
{"op":"mcm","clk":"4299664589","pt":1632581493766,"mc":[{"id":"1.188136695","rc":[{"trd":[[1.24,10944.4]],"batb":[[1,1.21,2031.66],[2,1.2,5131.45]],"batl":[[0,1.24,19.38]],"ltp":1.24,"tv":200433.18,"id":5300737},{"batb":[[1,4.3,233.19]],"ltp":5.0,"tv":32236.21,"id":2497008}],"tv":232669.4}]}
{"op":"mcm","clk":"4299664890","pt":1632581495166,"mc":[{"id":"1.188136695","rc":[{"batb":[[1,1.21,421.42],[2,1.2,2734.63]],"ltp":1.24,"tv":200433.18,"id":5300737}]}]}
{"op":"mcm","clk":"4299665119","pt":1632581496353,"mc":[{"id":"1.188136695","rc":[{"trd":[[1.24,10945.8]],"batl":[[0,1.24,18.68]],"ltp":1.24,"tv":200434.58,"id":5300737}],"tv":232670.8}]}
{"op":"mcm","clk":"4299665308","pt":1632581497250,"mc":[{"id":"1.188136695","rc":[{"trd":[[1.24,10966.83]],"batl":[[0,1.24,8.16]],"ltp":1.24,"tv":200455.62,"id":5300737}],"tv":232691.84}]}
{"op":"mcm","clk":"4299665660","pt":1632581498758,"mc":[{"id":"1.188136695","rc":[{"trd":[[1.24,11015.37]],"batb":[[0,1.23,1605.51],[1,1.22,1955.93],[2,1.21,421.42]],"batl":[[0,1.26,1459.69],[1,1.27,1213.88]],"ltp":1.24,"tv":200504.16,"id":5300737}],"tv":232740.38}]}
{"op":"mcm","clk":"4299665807","pt":1632581499451,"mc":[{"id":"1.188136695","rc":[{"trd":[[1.26,4777.36]],"batb":[[0,1.23,1738.7],[2,1.21,423.56]],"batl":[[0,1.26,1420.63]],"ltp":1.26,"tv":200543.22,"id":5300737},{"trd":[[4.8,922.07]],"ltp":4.8,"tv":32246.47,"id":2497008}],"tv":232789.69}]}
{"op":"mcm","clk":"4299666000","pt":1632581500361,"mc":[{"id":"1.188136695","rc":[{"trd":[[1.25,4916.48]],"batb":[[0,1.23,1738.36]],"batl":[[0,1.26,1420.99]],"ltp":1.25,"tv":200543.9,"id":5300737}],"tv":232790.37}]}
{"op":"mcm","clk":"4299666261","pt":1632581501685,"mc":[{"id":"1.188136695","rc":[{"trd":[[1.24,11016.09],[1.25,4920.46]],"batb":[[0,1.24,13.64],[1,1.23,1738.36],[2,1.22,1955.93]],"batl":[[0,1.25,603.4],[1,1.26,1420.63],[2,1.27,1213.88]],"ltp":1.25,"tv":200548.59,"id":5300737}],"tv":232795.07}]}
{"op":"mcm","clk":"4299666481","pt":1632581502688,"mc":[{"id":"1.188136695","rc":[{"batb":[[1,1.23,183.07],[2,1.22,315.25]],"batl":[[0,1.26,47.88],[1,1.27,1.76],[2,1.28,13.29]],"ltp":1.25,"tv":200548.59,"id":5300737},{"batb":[[0,4.6,28.25],[1,4.5,126.06],[2,4.3,233.19]],"batl":[[0,5.4,5.75],[1,5.5,1.15],[2,5.6,66.71]],"ltp":4.8,"tv":32246.47,"id":2497008}]}]}
{"op":"mcm","clk":"4299666694","pt":1632581503566,"mc":[{"id":"1.188136695","rc":[{"batb":[[1,1.22,315.25],[2,1.21,423.56]],"batl":[[0,1.27,1.76],[1,1.28,13.29],[2,1.29,74.35]],"ltp":1.25,"tv":200548.59,"id":5300737},{"batb":[[0,4.5,126.06],[1,4.3,233.19],[2,4.1,85.49]],"batl":[[0,5.5,1.15],[1,5.6,66.71],[2,5.7,61.26]],"ltp":4.8,"tv":32246.47,"id":2497008}]}]}
{"op":"mcm","clk":"4299667072","pt":1632581505360,"mc":[{"id":"1.188136695","rc":[{"batb":[[2,1.21,1536.28]],"ltp":1.25,"tv":200548.59,"id":5300737}]}]}
{"op":"mcm","clk":"4299667375","pt":1632581506782,"mc":[{"id":"1.188136695","rc":[{"trd":[[1.24,11016.79]],"batb":[[0,1.24,13.29]],"batl":[[0,1.27,2.43]],"ltp":1.24,"tv":200549.29,"id":5300737}],"tv":232795.77}]}
{"op":"mcm","clk":"4299667866","pt":1632581508972,"mc":[{"id":"1.188136695","rc":[{"batb":[[0,1.24,13.8]],"ltp":1.24,"tv":200549.29,"id":5300737}]}]}
{"op":"mcm","clk":"4299668303","pt":1632581511090,"mc":[{"id":"1.188136695","rc":[{"trd":[[1.25,4921.8],[1.27,2411.26]],"batb":[[0,1.27,11.21],[1,1.24,13.8],[2,1.22,315.25]],"batl":[[0,1.28,13.29],[1,1.29,74.35],[2,1.3,799.62]],"ltp":1.27,"tv":200554.15,"id":5300737}],"tv":232800.63}]}
{"op":"mcm","clk":"4299668657","pt":1632581512806,"mc":[{"id":"1.188136695","rc":[{"trd":[[1.27,2412.66]],"batb":[[0,1.27,10.51],[1,1.26,80],[2,1.24,13.8]],"ltp":1.27,"tv":200555.55,"id":5300737}],"tv":232802.03}]}
{"op":"mcm","clk":"4299668905","pt":1632581513830,"mc":[{"id":"1.188136695","rc":[{"trd":[[1.27,2413.36]],"batb":[[0,1.27,10.16]],"batl":[[2,1.3,90]],"ltp":1.27,"tv":200556.25,"id":5300737},{"batb":[[2,4.1,1]],"ltp":4.8,"tv":32246.47,"id":2497008}],"tv":232802.73}]}
{"op":"mcm","clk":"4299669008","pt":1632581514299,"mc":[{"id":"1.188136695","rc":[{"trd":[[1.22,1278.97],[1.24,11044.39],[1.26,4937.36],[1.27,2433.67]],"batb":[[0,1.21,1467.57],[1,1.2,4556.41],[2,1.19,1735.9]],"batl":[[0,1.23,432.84],[1,1.24,2222],[2,1.28,13.29]],"ltp":1.22,"tv":201399.84,"id":5300737},{"trd":[[5.5,17.6]],"batl":[[0,5.6,66.71],[1,5.7,61.26],[2,5.8,91.68]],"ltp":5.5,"tv":32247.61,"id":2497008}],"tv":233647.46}]}
{"op":"mcm","clk":"4299669322","pt":1632581515800,"mc":[{"id":"1.188136695","rc":[{"trd":[[1.23,3202.59]],"batl":[[0,1.23,9656.29]],"ltp":1.23,"tv":201448.99,"id":5300737},{"trd":[[5.3,237.82]],"batb":[[0,5.3,1179.24],[1,5.2,589.62],[2,5.1,589.62]],"ltp":5.3,"tv":32251.0,"id":2497008}],"tv":233699.99}]}
{"op":"mcm","clk":"4299669555","pt":1632581516772,"mc":[{"id":"1.188136695","rc":[{"batl":[[0,1.23,1310.45],[1,1.24,3631.5],[2,1.26,6.32]],"ltp":1.23,"tv":201448.99,"id":5300737},{"trd":[[5.3,253.5]],"batb":[[0,5.3,843.35],[1,5.2,353.77],[2,5.1,353.77]],"batl":[[0,5.8,91.68],[1,6,2],[2,6.2,277.62]],"ltp":5.3,"tv":32266.68,"id":2497008}],"tv":233715.67}]}
{"op":"mcm","clk":"4299669778","pt":1632581517783,"mc":[{"id":"1.188136695","rc":[{"batb":[[0,1.21,1477.57],[1,1.2,4566.41]],"batl":[[1,1.24,1499.5],[2,1.26,147.22]],"ltp":1.23,"tv":201448.99,"id":5300737},{"batb":[[1,5.2,375.19]],"ltp":5.3,"tv":32266.68,"id":2497008}]}]}
{"op":"mcm","clk":"4299669953","pt":1632581518589,"mc":[{"id":"1.188136695","rc":[{"batb":[[0,1.22,132.85],[1,1.21,1477.57],[2,1.2,4566.41]],"ltp":1.23,"tv":201448.99,"id":5300737},{"trd":[[5.3,258]],"batb":[[0,5.3,841.1]],"ltp":5.3,"tv":32271.18,"id":2497008}],"tv":233720.17}]}
{"op":"mcm","clk":"4299670231","pt":1632581519762,"mc":[{"id":"1.188136695","rc":[{"batl":[[0,1.23,1836.72],[1,1.24,2168.05],[2,1.26,6.32]],"ltp":1.23,"tv":201448.99,"id":5300737},{"batb":[[0,5.3,963.23],[2,5.1,516.31]],"batl":[[0,5.8,103.64]],"ltp":5.3,"tv":32271.18,"id":2497008}]}]}
{"op":"mcm","clk":"4299670455","pt":1632581520779,"mc":[{"id":"1.188136695","rc":[{"trd":[[1.22,1349.84],[1.23,3229.87]],"batb":[[0,1.22,97.42],[1,1.21,1784.25]],"batl":[[0,1.23,2724.49],[1,1.24,2329.55]],"ltp":1.23,"tv":201547.13,"id":5300737},{"batb":[[0,5.3,976.14],[1,5.2,355.77]],"batl":[[0,5.8,109.23]],"ltp":5.3,"tv":32271.18,"id":2497008}],"tv":233818.31}]}
{"op":"mcm","clk":"4299670699","pt":1632581521797,"mc":[{"id":"1.188136695","rc":[{"batb":[[0,1.22,106.42]],"batl":[[1,1.24,2078.05]],"ltp":1.23,"tv":201547.13,"id":5300737},{"batl":[[0,5.8,103.64]],"ltp":5.3,"tv":32271.18,"id":2497008}]}]}
{"op":"mcm","clk":"4299670938","pt":1632581522709,"mc":[{"id":"1.188136695","rc":[{"trd":[[1.22,1369.12],[1.23,3243.89]],"batb":[[0,1.22,101.17]],"batl":[[0,1.23,2330.13]],"ltp":1.23,"tv":201580.43,"id":5300737},{"batl":[[0,5.6,3],[1,5.8,103.64],[2,6,2]],"ltp":5.3,"tv":32271.18,"id":2497008}],"tv":233851.61}]}
{"op":"mcm","clk":"4299671203","pt":1632581523792,"mc":[{"id":"1.188136695","rc":[{"trd":[[1.22,1393.77]],"batb":[[0,1.22,88.84],[2,1.2,4897.47]],"batl":[[0,1.23,2420.13]],"ltp":1.22,"tv":201605.08,"id":5300737},{"batl":[[2,6,53.26]],"ltp":5.3,"tv":32271.18,"id":2497008}],"tv":233876.26}]}
{"op":"mcm","clk":"4299671454","pt":1632581524811,"mc":[{"id":"1.188136695","rc":[{"trd":[[1.22,1403.13]],"batb":[[0,1.22,84.16]],"ltp":1.22,"tv":201614.44,"id":5300737},{"batb":[[0,5.3,997.07]],"ltp":5.3,"tv":32271.18,"id":2497008}],"tv":233885.62}]}
{"op":"mcm","clk":"4299671557","pt":1632581525194,"mc":[{"id":"1.188136695","rc":[{"batb":[[2,1.2,3937.27]],"ltp":1.22,"tv":201614.44,"id":5300737}]}]}
{"op":"mcm","clk":"4299671885","pt":1632581526590,"mc":[{"id":"1.188136695","rc":[{"trd":[[1.23,3245.43]],"batl":[[0,1.23,2419.36],[1,1.24,2079.77]],"ltp":1.23,"tv":201615.98,"id":5300737}],"tv":233887.16}]}
{"op":"mcm","clk":"4299672054","pt":1632581527403,"mc":[{"id":"1.188136695","rc":[{"trd":[[1.22,1603.13]],"batb":[[0,1.22,249.48],[1,1.21,1477.57]],"batl":[[2,1.25,39.56]],"ltp":1.22,"tv":201815.98,"id":5300737}],"tv":234087.16}]}
{"op":"mcm","clk":"4299672303","pt":1632581528780,"mc":[{"id":"1.188136695","rc":[{"trd":[[1.23,3250.61]],"batb":[[0,1.22,1016.94]],"batl":[[0,1.23,2416.77]],"ltp":1.23,"tv":201821.16,"id":5300737},{"trd":[[5.3,262.7]],"batb":[[0,5.3,417.54],[1,5.2,60.96],[2,5.1,221.5]],"ltp":5.3,"tv":32275.87,"id":2497008}],"tv":234097.04}]}
{"op":"mcm","clk":"4299672521","pt":1632581529814,"mc":[{"id":"1.188136695","rc":[{"trd":[[1.23,3263.25]],"batb":[[0,1.22,826.37],[1,1.21,2.14],[2,1.2,377.45]],"batl":[[0,1.23,118.78],[1,1.24,1.71]],"ltp":1.23,"tv":201833.8,"id":5300737},{"batb":[[0,5.3,20.93],[1,4.8,179.08],[2,4.7,73.57]],"batl":[[0,6,53.26],[1,6.2,76.51],[2,6.4,103.35]],"ltp":5.3,"tv":32275.87,"id":2497008}],"tv":234109.68}]}
{"op":"mcm","clk":"4299672714","pt":1632581530676,"mc":[{"id":"1.188136695","rc":[{"batb":[[0,1.22,967.8]],"ltp":1.23,"tv":201833.8,"id":5300737},{"trd":[[5.3,263.4]],"batb":[[0,5.3,20.58]],"ltp":5.3,"tv":32276.57,"id":2497008}],"tv":234110.38}]}
{"op":"mcm","clk":"4299672924","pt":1632581531691,"mc":[{"id":"1.188136695","rc":[{"trd":[[1.23,3263.95]],"batb":[[0,1.22,908.88]],"batl":[[0,1.24,1.71],[1,1.25,39.56],[2,1.27,216.3]],"ltp":1.23,"tv":201834.5,"id":5300737},{"batb":[[0,4.8,179.08],[1,4.7,73.57],[2,4.6,64.49]],"batl":[[2,6.4,93.67]],"ltp":5.3,"tv":32276.57,"id":2497008}],"tv":234111.08}]}
{"op":"mcm","clk":"4299673156","pt":1632581532740,"mc":[{"id":"1.188136695","rc":[{"batl":[[2,1.26,1300.46]],"ltp":1.23,"tv":201834.5,"id":5300737}]}]}
{"op":"mcm","clk":"4299673418","pt":1632581533803,"mc":[{"id":"1.188136695","rc":[{"trd":[[1.22,1611.02]],"batb":[[0,1.22,137.48]],"ltp":1.22,"tv":201842.39,"id":5300737}],"tv":234118.97}]}
{"op":"mcm","clk":"4299673641","pt":1632581534822,"mc":[{"id":"1.188136695","rc":[{"batb":[[0,1.22,137.72]],"batl":[[1,1.27,216.3],[2,1.28,293.46]],"ltp":1.22,"tv":201842.39,"id":5300737},{"batl":[[0,5.3,7.09],[1,6,53.26],[2,6.2,76.51]],"ltp":5.3,"tv":32276.57,"id":2497008}]}]}
{"op":"mcm","clk":"4299673832","pt":1632581535732,"mc":[{"id":"1.188136695","rc":[{"trd":[[1.22,1700.4],[1.23,3295.4]],"batb":[[0,1.22,92.79]],"ltp":1.22,"tv":201963.22,"id":5300737},{"trd":[[5.3,270.49]],"batl":[[0,6,53.26],[1,6.2,76.51],[2,6.4,93.67]],"ltp":5.3,"tv":32283.67,"id":2497008}],"tv":234246.89}]}
{"op":"mcm","clk":"4299674229","pt":1632581537610,"mc":[{"id":"1.188136695","rc":[{"batb":[[1,1.21,1950.3],[2,1.2,2699.63]],"batl":[[0,1.24,1563.15],[1,1.25,1326.18],[2,1.27,224.3]],"ltp":1.22,"tv":201963.22,"id":5300737},{"batb":[[0,4.8,182.08],[1,4.7,75.57]],"ltp":5.3,"tv":32283.67,"id":2497008}]}]}
{"op":"mcm","clk":"4299674759","pt":1632581539831,"mc":[{"id":"1.188136695","rc":[{"batb":[[1,1.21,2.14],[2,1.2,1157.69]],"batl":[[0,1.24,1.71],[1,1.27,224.3],[2,1.28,293.46]],"ltp":1.22,"tv":201963.22,"id":5300737}]}]}
{"op":"mcm","clk":"4299674990","pt":1632581540825,"mc":[{"id":"1.188136695","rc":[{"trd":[[1.22,1701.1]],"batb":[[0,1.22,92.44]],"ltp":1.22,"tv":201963.92,"id":5300737}],"tv":234247.59}]}
{"op":"mcm","clk":"4299675449","pt":1632581542721,"mc":[{"id":"1.188136695","rc":[{"trd":[[1.22,1740.1]],"batb":[[0,1.22,72.94]],"batl":[[1,1.26,1297.24],[2,1.27,1439.4]],"ltp":1.22,"tv":202002.92,"id":5300737}],"tv":234286.59}]}
{"op":"mcm","clk":"4299675521","pt":1632581543008,"mc":[{"id":"1.188136695","rc":[{"batl":[[1,1.26,1312.25]],"ltp":1.22,"tv":202002.92,"id":5300737}]}]}
{"op":"mcm","clk":"4299676063","pt":1632581545232,"mc":[{"id":"1.188136695","rc":[{"batb":[[0,1.23,1.05],[1,1.22,72.94],[2,1.21,2.14]],"ltp":1.22,"tv":202002.92,"id":5300737}]}]}
{"op":"mcm","clk":"4299676398","pt":1632581546621,"mc":[{"id":"1.188136695","rc":[{"trd":[[1.23,3295.65]],"batb":[[0,1.22,73.86],[1,1.21,2.14],[2,1.2,1157.69]],"ltp":1.23,"tv":202003.17,"id":5300737}],"tv":234286.85}]}
{"op":"mcm","clk":"4299676537","pt":1632581547325,"mc":[{"id":"1.188136695","rc":[{"batl":[[0,6,53.57]],"ltp":5.3,"tv":32283.67,"id":2497008}]}]}
{"op":"mcm","clk":"4299677194","pt":1632581550431,"mc":[{"id":"1.188136695","rc":[{"batb":[[0,1.22,72.94],[1,1.21,49.25]],"ltp":1.23,"tv":202003.17,"id":5300737},{"batb":[[1,4.7,73.57]],"ltp":5.3,"tv":32283.67,"id":2497008}]}]}
{"op":"mcm","clk":"4299677469","pt":1632581551731,"mc":[{"id":"1.188136695","rc":[{"trd":[[1.21,2623.01],[1.22,1885.98]],"batb":[[0,1.2,1157.69],[1,1.19,4335.71],[2,1.18,3256.05]],"batl":[[0,1.21,11.81],[1,1.24,1.71],[2,1.26,1312.25]],"ltp":1.21,"tv":202247.55,"id":5300737}],"tv":234531.23}]}
{"op":"mcm","clk":"4299677852","pt":1632581553536,"mc":[{"id":"1.188136695","rc":[{"batb":[[1,4.7,76.57]],"ltp":5.3,"tv":32283.67,"id":2497008}]}]}
{"op":"mcm","clk":"4299678199","pt":1632581555247,"mc":[{"id":"1.188136695","rc":[{"batb":[[1,1.19,4347.71]],"ltp":1.21,"tv":202247.55,"id":5300737}]}]}
{"op":"mcm","clk":"4299679053","pt":1632581559380,"mc":[{"id":"1.188136695","rc":[{"trd":[[1.21,2646.63],[1.24,11045.99]],"batb":[[0,1.23,233.23],[1,1.22,226.37],[2,1.21,240.01]],"batl":[[0,1.26,15.13],[1,1.27,216.3],[2,1.28,293.46]],"ltp":1.24,"tv":202272.78,"id":5300737},{"trd":[[5.1,262.87]],"batl":[[2,6.4,82.68]],"ltp":5.1,"tv":32284.06,"id":2497008}],"tv":234556.84}]}
{"op":"mcm","clk":"4299679355","pt":1632581560811,"mc":[{"id":"1.188136695","rc":[{"trd":[[1.24,11046.21],[1.26,4939.24]],"batb":[[2,1.21,1020.01]],"batl":[[0,1.26,14.07]],"ltp":1.26,"tv":202274.88,"id":5300737}],"tv":234558.94}]}
{"op":"mcm","clk":"4299679578","pt":1632581561651,"mc":[{"id":"1.188136695","rc":[{"batb":[[2,1.21,1024.72]],"batl":[[0,1.24,84.85],[1,1.26,14.07],[2,1.27,216.3]],"ltp":1.26,"tv":202274.88,"id":5300737}]}]}
{"op":"mcm","clk":"4299679791","pt":1632581562619,"mc":[{"id":"1.188136695","rc":[{"batb":[[2,1.21,1028.23]],"ltp":1.26,"tv":202274.88,"id":5300737}]}]}
{"op":"mcm","clk":"4299680014","pt":1632581563574,"mc":[{"id":"1.188136695","rc":[{"batb":[[2,1.21,1030.93]],"ltp":1.26,"tv":202274.88,"id":5300737}]}]}
{"op":"mcm","clk":"4299680134","pt":1632581564047,"mc":[{"id":"1.188136695","rc":[{"trd":[[1.23,3300.35]],"batb":[[0,1.23,230.88]],"ltp":1.23,"tv":202279.58,"id":5300737}],"tv":234563.64}]}
{"op":"mcm","clk":"4299680558","pt":1632581565744,"mc":[{"id":"1.188136695","rc":[{"batb":[[2,1.21,1033.06]],"ltp":1.23,"tv":202279.58,"id":5300737},{"batl":[[0,5.8,1.1],[1,6,53.26],[2,6.2,76.51]],"ltp":5.1,"tv":32284.06,"id":2497008}]}]}
{"op":"mcm","clk":"4299680759","pt":1632581566551,"mc":[{"id":"1.188136695","rc":[{"batb":[[2,1.21,1030.8]],"ltp":1.23,"tv":202279.58,"id":5300737},{"batb":[[1,4.7,73.57],[2,4.6,190.72]],"batl":[[0,5.7,1.14],[1,6,53.57]],"ltp":5.1,"tv":32284.06,"id":2497008}]}]}
{"op":"mcm","clk":"4299680964","pt":1632581567513,"mc":[{"id":"1.188136695","rc":[{"batb":[[2,1.21,1030.45]],"ltp":1.23,"tv":202279.58,"id":5300737}]}]}
{"op":"mcm","clk":"4299681136","pt":1632581568354,"mc":[{"id":"1.188136695","rc":[{"batb":[[2,1.21,1031.33]],"ltp":1.23,"tv":202279.58,"id":5300737}]}]}
{"op":"mcm","clk":"4299681422","pt":1632581569573,"mc":[{"id":"1.188136695","rc":[{"trd":[[1.24,11048.18]],"batl":[[0,1.24,83.87]],"ltp":1.24,"tv":202281.55,"id":5300737}],"tv":234565.61}]}
{"op":"mcm","clk":"4299681866","pt":1632581571669,"mc":[{"id":"1.188136695","rc":[{"trd":[[1.23,3412.55],[1.24,11048.89]],"batb":[[0,1.23,174.78],[1,1.22,228.26],[2,1.21,1029.57]],"batl":[[0,1.24,83.52],[1,1.26,11]],"ltp":1.24,"tv":202394.45,"id":5300737},{"batl":[[0,5.7,1.45]],"ltp":5.1,"tv":32284.06,"id":2497008}],"tv":234678.51}]}
{"op":"mcm","clk":"4299682509","pt":1632581574574,"mc":[{"id":"1.188136695","rc":[{"trd":[[1.21,4413.66],[1.22,2342.49],[1.23,3762.11]],"batb":[[0,1.21,139.72],[1,1.2,1157.69],[2,1.19,1489.72]],"ltp":1.21,"tv":204967.56,"id":5300737}],"tv":237251.63}]}
{"op":"mcm","clk":"4299682996","pt":1632581576809,"mc":[{"id":"1.188136695","rc":[{"batl":[[0,1.23,9.65],[1,1.24,83.52],[2,1.26,11]],"ltp":1.21,"tv":204967.56,"id":5300737}]}]}
{"op":"mcm","clk":"4299683178","pt":1632581577706,"mc":[{"id":"1.188136695","rc":[{"batb":[[2,1.19,303.1]],"ltp":1.21,"tv":204967.56,"id":5300737},{"batb":[[1,4.6,126.23],[2,4.1,1]],"ltp":5.1,"tv":32284.06,"id":2497008}]}]}
{"op":"mcm","clk":"4299683260","pt":1632581578096,"mc":[{"id":"1.188136695","rc":[{"batl":[[1,6,53.26]],"ltp":5.1,"tv":32284.06,"id":2497008}]}]}
{"op":"mcm","clk":"4299683808","pt":1632581580688,"mc":[{"id":"1.188136695","rc":[{"trd":[[1.21,4457.89],[1.23,3771.13]],"batb":[[0,1.21,111.49]],"batl":[[0,1.23,335.3],[1,1.24,89.94]],"ltp":1.21,"tv":205020.81,"id":5300737},{"trd":[[5.6,2.62],[5.7,68.51],[5.8,30.2]],"batb":[[0,5.5,260.8],[1,5.4,253.12],[2,5.3,253.12]],"batl":[[0,6,53.26],[1,6.2,76.51],[2,6.4,82.68]],"ltp":5.8,"tv":32289.51,"id":2497008}],"tv":237310.33}]}
{"op":"mcm","clk":"4299684024","pt":1632581581766,"mc":[{"id":"1.188136695","rc":[{"batl":[[0,1.22,90],[1,1.23,335.31],[2,1.24,89.94]],"ltp":1.21,"tv":205020.81,"id":5300737},{"trd":[[5.5,32.7]],"batb":[[0,5.7,125.81],[1,5.6,19.56],[2,5.5,253.25]],"ltp":5.5,"tv":32304.61,"id":2497008}],"tv":237325.43}]}
{"op":"mcm","clk":"4299684179","pt":1632581582478,"mc":[{"id":"1.188136695","rc":[{"trd":[[1.21,4680.88],[1.22,2349.51]],"batb":[[0,1.2,1157.69],[1,1.19,303.1],[2,1.18,1969.72]],"batl":[[0,1.21,22.46],[1,1.22,86.49],[2,1.23,5.15]],"ltp":1.21,"tv":205250.81,"id":5300737}],"tv":237555.43}]}
{"op":"mcm","clk":"4299684651","pt":1632581584385,"mc":[{"id":"1.188136695","rc":[{"trd":[[1.21,4725.79]],"batb":[[0,1.21,65.64],[1,1.2,1157.69],[2,1.19,303.1]],"batl":[[0,1.22,113.91],[1,1.23,78.84],[2,1.24,89.94]],"ltp":1.21,"tv":205295.73,"id":5300737},{"batb":[[0,5.7,127.81],[1,5.6,22.56],[2,5.5,256.25]],"batl":[[0,5.8,2],[1,6,53.26],[2,6.2,76.51]],"ltp":5.5,"tv":32304.61,"id":2497008}],"tv":237600.35}]}
{"op":"mcm","clk":"4299684931","pt":1632581585580,"mc":[{"id":"1.188136695","rc":[{"batb":[[1,1.2,1243.4],[2,1.19,315.1]],"batl":[[1,1.23,78.83],[2,1.24,91.66]],"ltp":1.21,"tv":205295.73,"id":5300737},{"batb":[[1,5.6,3]],"ltp":5.5,"tv":32304.61,"id":2497008}]}]}
{"op":"mcm","clk":"4299685130","pt":1632581586472,"mc":[{"id":"1.188136695","rc":[{"batb":[[1,1.2,463.16]],"ltp":1.21,"tv":205295.73,"id":5300737}]}]}
{"op":"mcm","clk":"4299685430","pt":1632581587790,"mc":[{"id":"1.188136695","rc":[{"trd":[[1.22,2351.61]],"batb":[[0,1.21,66.34]],"batl":[[0,1.22,116.37]],"ltp":1.22,"tv":205297.83,"id":5300737},{"trd":[[5.7,68.68]],"batb":[[0,5.7,127.73]],"ltp":5.7,"tv":32304.78,"id":2497008}],"tv":237602.62}]}
{"op":"mcm","clk":"4299685575","pt":1632581588490,"mc":[{"id":"1.188136695","rc":[{"batb":[[1,1.2,377.45]],"batl":[[2,1.24,8.14]],"ltp":1.22,"tv":205297.83,"id":5300737},{"batb":[[0,5.7,146.87]],"ltp":5.7,"tv":32304.78,"id":2497008}]}]}
{"op":"mcm","clk":"4299685812","pt":1632581589698,"mc":[{"id":"1.188136695","rc":[{"trd":[[1.21,4862.31],[1.22,2359.33]],"batb":[[0,1.21,771.18]],"batl":[[0,1.22,112.51]],"ltp":1.21,"tv":205442.07,"id":5300737},{"trd":[[5.7,68.97]],"batb":[[0,5.7,146.72]],"ltp":5.7,"tv":32305.07,"id":2497008}],"tv":237747.15}]}
{"op":"mcm","clk":"4299686013","pt":1632581590676,"mc":[{"id":"1.188136695","rc":[{"trd":[[1.21,4992.89],[1.22,2375.83]],"batb":[[0,1.21,725.16],[2,1.19,314.3]],"batl":[[0,1.22,104.26]],"ltp":1.21,"tv":205589.14,"id":5300737},{"trd":[[5.7,83.59]],"batb":[[0,5.7,139.41]],"ltp":5.7,"tv":32319.7,"id":2497008}],"tv":237908.84}]}
{"op":"mcm","clk":"4299686250","pt":1632581591699,"mc":[{"id":"1.188136695","rc":[{"trd":[[1.21,5152.89],[1.22,2383.85]],"batb":[[0,1.21,730.87]],"batl":[[0,1.22,100.25]],"ltp":1.21,"tv":205757.17,"id":5300737}],"tv":238076.87}]}
{"op":"mcm","clk":"4299686504","pt":1632581592802,"mc":[{"id":"1.188136695","rc":[{"trd":[[1.21,5198.89]],"batb":[[0,1.21,707.88]],"batl":[[0,1.22,145.28],[1,1.23,17.14]],"ltp":1.21,"tv":205803.16,"id":5300737}],"tv":238122.86}]}
{"op":"mcm","clk":"4299686760","pt":1632581593779,"mc":[{"id":"1.188136695","rc":[{"trd":[[1.21,5378.64]],"batb":[[0,1.21,618]],"batl":[[0,1.22,733.57],[1,1.23,652.27]],"ltp":1.21,"tv":205982.91,"id":5300737},{"batb":[[2,5.5,383.82]],"ltp":5.7,"tv":32319.7,"id":2497008}],"tv":238302.61}]}
{"op":"mcm","clk":"4299686852","pt":1632581594206,"mc":[{"id":"1.188136695","rc":[{"trd":[[1.22,2384.55]],"batl":[[0,1.22,98.64],[1,1.23,17.14]],"ltp":1.22,"tv":205983.61,"id":5300737},{"batb":[[0,5.7,120.27],[2,5.5,256.25]],"ltp":5.7,"tv":32319.7,"id":2497008}],"tv":238303.31}]}
{"op":"mcm","clk":"4299687218","pt":1632581595823,"mc":[{"id":"1.188136695","rc":[{"trd":[[1.22,2386.15]],"batl":[[0,1.22,97.84]],"ltp":1.22,"tv":205985.21,"id":5300737},{"trd":[[5.7,87.98]],"batb":[[0,5.7,118.08]],"ltp":5.7,"tv":32324.08,"id":2497008}],"tv":238309.3}]}
{"op":"mcm","clk":"4299687398","pt":1632581596734,"mc":[{"id":"1.188136695","rc":[{"trd":[[1.21,6073.14],[1.22,2392.33]],"batb":[[0,1.21,270.75]],"batl":[[0,1.22,94.75]],"ltp":1.22,"tv":206685.9,"id":5300737}],"tv":239009.99}]}
{"op":"mcm","clk":"4299687528","pt":1632581597328,"mc":[{"id":"1.188136695","rc":[{"trd":[[1.21,6252.14],[1.22,2392.47]],"batb":[[0,1.21,189.82]],"batl":[[0,1.22,98.69],[1,1.23,5.14]],"ltp":1.21,"tv":206865.04,"id":5300737},{"batb":[[1,5.5,273.25],[2,5.4,253.12]],"batl":[[1,6,51.26]],"ltp":5.7,"tv":32324.08,"id":2497008}],"tv":239189.13}]}
{"op":"mcm","clk":"4299687810","pt":1632581598787,"mc":[{"id":"1.188136695","rc":[{"trd":[[1.22,2562.85]],"batb":[[2,1.19,302.3]],"batl":[[0,1.22,13.5]],"ltp":1.22,"tv":207035.42,"id":5300737}],"tv":239359.51}]}
{"op":"mcm","clk":"4299687983","pt":1632581599694,"mc":[{"id":"1.188136695","rc":[{"trd":[[1.22,2567.2]],"batb":[[0,1.21,210.34]],"batl":[[0,1.22,11.33],[1,1.24,8.14],[2,1.25,12.03]],"ltp":1.22,"tv":207039.76,"id":5300737}],"tv":239363.85}]}
{"op":"mcm","clk":"4299688167","pt":1632581600823,"mc":[{"id":"1.188136695","rc":[{"trd":[[1.21,6254.25],[1.22,2608.24]],"batb":[[0,1.21,209.28]],"batl":[[0,1.24,8.14],[1,1.25,12.03],[2,1.27,236.83]],"ltp":1.21,"tv":207082.91,"id":5300737},{"trd":[[5.7,90.35]],"batb":[[0,5.7,115.85],[1,5.6,3],[2,5.5,273.25]],"ltp":5.7,"tv":32326.45,"id":2497008}],"tv":239409.37}]}
{"op":"mcm","clk":"4299688381","pt":1632581601820,"mc":[{"id":"1.188136695","rc":[{"trd":[[1.22,2678.92]],"ltp":1.22,"tv":207153.59,"id":5300737},{"trd":[[5.7,101.63]],"batb":[[0,5.7,104.57]],"ltp":5.7,"tv":32337.73,"id":2497008}],"tv":239491.32}]}
{"op":"mcm","clk":"4299688553","pt":1632581602604,"mc":[{"id":"1.188136695","rc":[{"batl":[[0,1.23,74.36],[1,1.24,8.14],[2,1.25,12.03]],"ltp":1.22,"tv":207153.59,"id":5300737},{"trd":[[5.7,101.96]],"batb":[[0,5.7,104.4],[2,5.5,253.25]],"ltp":5.7,"tv":32338.07,"id":2497008}],"tv":239491.66}]}
{"op":"mcm","clk":"4299688785","pt":1632581603723,"mc":[{"id":"1.188136695","rc":[{"trd":[[1.22,2681.2]],"batl":[[0,1.23,100],[1,1.24,2419.84]],"ltp":1.22,"tv":207155.88,"id":5300737},{"trd":[[5.7,102.45]],"batb":[[0,5.7,103.91]],"ltp":5.7,"tv":32338.55,"id":2497008}],"tv":239494.44}]}
{"op":"mcm","clk":"4299689006","pt":1632581604651,"mc":[{"id":"1.188136695","rc":[{"trd":[[1.22,2697.96]],"batl":[[0,1.22,513.95],[1,1.23,689.7],[2,1.24,8.14]],"ltp":1.22,"tv":207172.63,"id":5300737},{"trd":[[5.7,103.33]],"batb":[[0,5.7,103.03],[2,5.5,368.65]],"ltp":5.7,"tv":32339.43,"id":2497008}],"tv":239512.07}]}
{"op":"mcm","clk":"4299689216","pt":1632581605559,"mc":[{"id":"1.188136695","rc":[{"trd":[[1.22,3097.96]],"batl":[[0,1.22,313.95]],"ltp":1.22,"tv":207572.63,"id":5300737}],"tv":239912.07}]}
{"op":"mcm","clk":"4299689585","pt":1632581607426,"mc":[{"id":"1.188136695","rc":[{"trd":[[1.22,3149.81]],"batl":[[0,1.22,288.02]],"ltp":1.22,"tv":207624.48,"id":5300737}],"tv":239963.92}]}
{"op":"mcm","clk":"4299689799","pt":1632581608651,"mc":[{"id":"1.188136695","rc":[{"trd":[[1.22,3162.09]],"batl":[[0,1.22,281.88]],"ltp":1.22,"tv":207636.76,"id":5300737}],"tv":239976.2}]}
{"op":"mcm","clk":"4299689995","pt":1632581609739,"mc":[{"id":"1.188136695","rc":[{"trd":[[1.22,3165.41]],"batl":[[0,1.22,280.22]],"ltp":1.22,"tv":207640.08,"id":5300737}],"tv":239979.52}]}
{"op":"mcm","clk":"4299690318","pt":1632581611415,"mc":[{"id":"1.188136695","rc":[{"batb":[[1,1.2,367.45]],"ltp":1.22,"tv":207640.08,"id":5300737},{"trd":[[5.7,160.81]],"batb":[[0,5.7,74.29]],"ltp":5.7,"tv":32396.91,"id":2497008}],"tv":240037.0}]}
{"op":"mcm","clk":"4299690564","pt":1632581612747,"mc":[{"id":"1.188136695","rc":[{"batb":[[1,1.2,1099.43]],"ltp":1.22,"tv":207640.08,"id":5300737},{"trd":[[5.7,194.76]],"batb":[[0,5.7,57.32]],"batl":[[0,5.8,133.96],[1,6,197.65]],"ltp":5.7,"tv":32430.86,"id":2497008}],"tv":240070.95}]}
{"op":"mcm","clk":"4299690755","pt":1632581613764,"mc":[{"id":"1.188136695","rc":[{"trd":[[1.22,3166.92]],"batb":[[0,1.21,200.71]],"batl":[[0,1.22,279.46]],"ltp":1.22,"tv":207641.59,"id":5300737},{"batb":[[1,5.5,368.65],[2,5.4,253.12]],"ltp":5.7,"tv":32430.86,"id":2497008}],"tv":240072.46}]}
{"op":"mcm","clk":"4299690933","pt":1632581614728,"mc":[{"id":"1.188136695","rc":[{"trd":[[1.22,3167.59]],"batb":[[1,1.2,1112.43]],"batl":[[0,1.22,279.13]],"ltp":1.22,"tv":207642.26,"id":5300737},{"batb":[[1,5.5,115.4],[2,5.3,157.78]],"batl":[[0,5.8,2]],"ltp":5.7,"tv":32430.86,"id":2497008}],"tv":240073.13}]}
{"op":"mcm","clk":"4299691017","pt":1632581615123,"mc":[{"id":"1.188136695","rc":[{"batb":[[0,1.21,190.71],[1,1.2,36.39],[2,1.19,6.85]],"batl":[[0,1.23,90],[1,1.24,1.71],[2,1.25,12.03]],"ltp":1.22,"tv":207642.26,"id":5300737},{"batb":[[0,5.3,20.93],[1,5.1,161.58],[2,4.8,59.61]],"batl":[[0,6.4,9.68],[1,7,57.13],[2,7.2,60.77]],"ltp":5.7,"tv":32430.86,"id":2497008}]}]}
{"op":"mcm","clk":"4299691317","pt":1632581616820,"mc":[{"id":"1.188136695","rc":[{"trd":[[1.22,3187.59],[1.23,3960.34]],"batb":[[0,1.23,1091.13],[1,1.22,36.82],[2,1.21,190.71]],"batl":[[0,1.24,1.71],[1,1.25,12.03],[2,1.27,298.34]],"ltp":1.23,"tv":207851.47,"id":5300737},{"trd":[[5.4,7]],"batb":[[0,5.1,161.58],[1,4.8,59.61],[2,4.7,91.62]],"batl":[[0,7,57.13],[1,7.2,60.77],[2,7.4,71.9]],"ltp":5.4,"tv":32432.86,"id":2497008}],"tv":240284.34}]}
{"op":"mcm","clk":"4299691494","pt":1632581617821,"mc":[{"id":"1.188136695","rc":[{"batl":[[1,1.25,1618.03],[2,1.26,1264.5]],"ltp":1.23,"tv":207851.47,"id":5300737}]}]}
{"op":"mcm","clk":"4299691633","pt":1632581618562,"mc":[{"id":"1.188136695","rc":[{"batb":[[1,1.22,37.15],[2,1.21,185.08]],"batl":[[1,1.25,12.03],[2,1.27,298.34]],"ltp":1.23,"tv":207851.47,"id":5300737},{"batb":[[0,5,166.23],[1,4.8,59.26]],"ltp":5.4,"tv":32432.86,"id":2497008}]}]}
{"op":"mcm","clk":"4299691862","pt":1632581619633,"mc":[{"id":"1.188136695","rc":[{"trd":[[1.24,11050.6]],"batb":[[1,1.22,37.85],[2,1.21,99.36]],"batl":[[0,1.25,22.03],[1,1.27,298.34],[2,1.28,269.8]],"ltp":1.24,"tv":207853.18,"id":5300737},{"trd":[[5.1,263.29]],"batl":[[0,5.1,9.58],[1,7,57.13],[2,7.2,60.77]],"ltp":5.1,"tv":32433.28,"id":2497008}],"tv":240286.47}]}
{"op":"mcm","clk":"4299692241","pt":1632581621561,"mc":[{"id":"1.188136695","rc":[{"trd":[[1.21,6452.97],[1.22,3263.29],[1.23,6142.6],[1.24,11090]],"batb":[[0,1.2,44.96],[1,1.19,925.22],[2,1.18,2055.72]],"batl":[[0,1.21,1301.45],[1,1.22,1546.54],[2,1.23,50.8]],"ltp":1.21,"tv":210349.27,"id":5300737},{"trd":[[5.1,272.87]],"batb":[[0,5,169.23],[1,4.9,2],[2,4.8,59.26]],"batl":[[0,7,57.13],[1,7.2,60.77],[2,7.4,71.9]],"ltp":5.1,"tv":32442.86,"id":2497008}],"tv":242792.13}]}
{"op":"mcm","clk":"4299692697","pt":1632581623762,"mc":[{"id":"1.188136695","rc":[{"batb":[[0,1.2,55.02]],"ltp":1.21,"tv":210349.27,"id":5300737},{"batb":[[0,5.1,44.29],[1,5,169.23],[2,4.9,2]],"ltp":5.1,"tv":32442.86,"id":2497008}]}]}
{"op":"mcm","clk":"4299692786","pt":1632581624250,"mc":[{"id":"1.188136695","rc":[{"batl":[[0,6.8,18.97],[1,7,57.13],[2,7.2,60.77]],"ltp":5.1,"tv":32442.86,"id":2497008}]}]}
{"op":"mcm","clk":"4299693014","pt":1632581625540,"mc":[{"id":"1.188136695","rc":[{"batb":[[1,1.19,6.85],[2,1.18,1.89]],"batl":[[0,1.23,50.8],[1,1.25,401.03],[2,1.27,298.34]],"ltp":1.21,"tv":210349.27,"id":5300737},{"batb":[[0,5,169.23],[1,4.9,2],[2,4.8,59.26]],"batl":[[0,7,57.13],[1,7.2,60.77],[2,7.4,71.9]],"ltp":5.1,"tv":32442.86,"id":2497008}]}]}
{"op":"mcm","clk":"4299693157","pt":1632581626354,"mc":[{"id":"1.188136695","rc":[{"batl":[[1,1.25,22.03]],"ltp":1.21,"tv":210349.27,"id":5300737}]}]}
{"op":"mcm","clk":"4299693540","pt":1632581628342,"mc":[{"id":"1.188136695","rc":[{"trd":[[1.2,8566.98]],"batb":[[0,1.2,45.02]],"batl":[[1,1.25,1573.45],[2,1.26,1264.44]],"ltp":1.2,"tv":210369.27,"id":5300737}],"tv":242812.13}]}
{"op":"mcm","clk":"4299693826","pt":1632581629648,"mc":[{"id":"1.188136695","rc":[{"trd":[[1.23,6142.66]],"batb":[[0,1.21,46.87],[1,1.2,45.02],[2,1.19,6.85]],"batl":[[0,1.23,50.77]],"ltp":1.23,"tv":210369.33,"id":5300737}],"tv":242812.2}]}
{"op":"mcm","clk":"4299694095","pt":1632581631243,"mc":[{"id":"1.188136695","rc":[{"batb":[[0,1.21,13.59]],"ltp":1.23,"tv":210369.33,"id":5300737}]}]}
{"op":"mcm","clk":"4299694282","pt":1632581632368,"mc":[{"id":"1.188136695","rc":[{"batb":[[0,1.21,15.35]],"ltp":1.23,"tv":210369.33,"id":5300737}]}]}
{"op":"mcm","clk":"4299694517","pt":1632581633585,"mc":[{"id":"1.188136695","rc":[{"batb":[[0,1.21,15.82]],"ltp":1.23,"tv":210369.33,"id":5300737}]}]}
{"op":"mcm","clk":"4299694763","pt":1632581634663,"mc":[{"id":"1.188136695","rc":[{"batb":[[0,1.21,18.64],[1,1.2,34.96]],"batl":[[1,1.25,22.03],[2,1.27,61.51]],"ltp":1.23,"tv":210369.33,"id":5300737},{"batb":[[1,4.6,126.23],[2,4.1,1]],"ltp":5.1,"tv":32442.86,"id":2497008}]}]}
{"op":"mcm","clk":"4299694864","pt":1632581635257,"mc":[{"id":"1.188136695","rc":[{"trd":[[1.18,30905.45],[1.19,29734.03],[1.2,8636.89],[1.21,6490.25],[1.22,3267.07]],"batb":[[0,1.17,587.86],[1,1.16,2230.64],[2,1.15,4916.88]],"batl":[[0,1.18,465.24],[1,1.19,2159.66],[2,1.21,5]],"ltp":1.18,"tv":210497.78,"id":5300737}],"tv":242940.65}]}
{"op":"mcm","clk":"4299695101","pt":1632581636753,"mc":[{"id":"1.188136695","rc":[{"trd":[[1.18,30905.75]],"batb":[[0,1.17,229.2]],"batl":[[0,1.18,465.09]],"ltp":1.18,"tv":210498.09,"id":5300737},{"batb":[[0,6.4,44.82],[1,6.2,43.51],[2,6,43.51]],"batl":[[0,7.2,60.77],[1,7.4,71.9],[2,7.8,1]],"ltp":5.1,"tv":32442.86,"id":2497008}],"tv":242940.96}]}
{"op":"mcm","clk":"4299695279","pt":1632581637766,"mc":[{"id":"1.188136695","rc":[{"batl":[[0,1.18,1827.75],[1,1.19,3994.58],[2,1.21,11.58]],"ltp":1.18,"tv":210498.09,"id":5300737},{"batb":[[0,6.4,268.94],[1,6.2,261.04],[2,6,261.04]],"ltp":5.1,"tv":32442.86,"id":2497008}]}]}
{"op":"mcm","clk":"4299695458","pt":1632581638800,"mc":[{"id":"1.188136695","rc":[{"batb":[[0,1.17,245.2],[1,1.16,2246.64]],"batl":[[0,1.18,2831.53],[1,1.19,1834.92]],"ltp":1.18,"tv":210498.09,"id":5300737},{"trd":[[6.4,2394.02]],"batb":[[0,6.4,446.76]],"batl":[[0,7,2],[1,7.2,69.8],[2,7.4,71.9]],"ltp":6.4,"tv":32456.2,"id":2497008}],"tv":242954.3}]}
{"op":"mcm","clk":"4299695536","pt":1632581639178,"mc":[{"id":"1.188136695","rc":[{"batl":[[1,7.2,60.77]],"ltp":6.4,"tv":32456.2,"id":2497008}]}]}
{"op":"mcm","clk":"4299695822","pt":1632581640570,"mc":[{"id":"1.188136695","rc":[{"batl":[[0,1.18,3419.51],[1,1.19,2469.19]],"ltp":1.18,"tv":210498.09,"id":5300737},{"trd":[[6.4,2400.25]],"batb":[[0,6.4,552.05],[1,6.2,382.78]],"batl":[[1,7.2,69.57]],"ltp":6.4,"tv":32462.44,"id":2497008}],"tv":242960.53}]}
{"op":"mcm","clk":"4299696076","pt":1632581641785,"mc":[{"id":"1.188136695","rc":[{"trd":[[1.18,31088.82]],"batb":[[0,1.17,315.24]],"batl":[[0,1.18,4037.02],[1,1.19,2544.19]],"ltp":1.18,"tv":210681.15,"id":5300737},{"batb":[[0,6.6,42.96],[1,6.4,555.05],[2,6.2,385.78]],"ltp":6.4,"tv":32462.44,"id":2497008}],"tv":243143.6}]}
{"op":"mcm","clk":"4299696286","pt":1632581642699,"mc":[{"id":"1.188136695","rc":[{"trd":[[1.18,31089.77]],"batb":[[1,1.16,2310.71]],"batl":[[0,1.18,4036.54]],"ltp":1.18,"tv":210682.11,"id":5300737},{"batb":[[0,6.6,7.96]],"ltp":6.4,"tv":32462.44,"id":2497008}],"tv":243144.55}]}
{"op":"mcm","clk":"4299696497","pt":1632581643709,"mc":[{"id":"1.188136695","rc":[{"trd":[[1.18,31546.92]],"batl":[[0,1.18,3807.97]],"ltp":1.18,"tv":211139.25,"id":5300737},{"batl":[[0,7,10.2]],"ltp":6.4,"tv":32462.44,"id":2497008}],"tv":243601.7}]}
{"op":"mcm","clk":"4299696634","pt":1632581644370,"mc":[{"id":"1.188136695","rc":[{"trd":[[1.18,31550.26]],"batb":[[2,1.15,4810.99]],"batl":[[0,1.18,3703.26]],"ltp":1.18,"tv":211142.59,"id":5300737}],"tv":243605.04}]}
{"op":"mcm","clk":"4299696915","pt":1632581645789,"mc":[{"id":"1.188136695","rc":[{"trd":[[1.18,31631.81]],"batl":[[0,1.18,3662.48]],"ltp":1.18,"tv":211224.15,"id":5300737}],"tv":243686.59}]}
{"op":"mcm","clk":"4299697121","pt":1632581646774,"mc":[{"id":"1.188136695","rc":[{"trd":[[1.18,31653.01]],"batb":[[0,1.17,533.52]],"batl":[[0,1.18,3651.88],[1,1.19,2469.19]],"ltp":1.18,"tv":211245.35,"id":5300737},{"trd":[[6.4,2490.52],[6.6,617.94]],"batb":[[0,6.4,509.92],[1,6.2,385.78],[2,6,261.04]],"batl":[[0,6.8,2],[1,7,10.2],[2,7.2,69.57]],"ltp":6.4,"tv":32568.63,"id":2497008}],"tv":243813.98}]}
{"op":"mcm","clk":"4299697291","pt":1632581647690,"mc":[{"id":"1.188136695","rc":[{"trd":[[1.18,31716.76]],"batb":[[1,1.16,2415.68]],"batl":[[0,1.18,4208.33],[1,1.19,3240.59]],"ltp":1.18,"tv":211309.1,"id":5300737},{"batb":[[0,6.4,630.02],[1,6.2,533.84]],"ltp":6.4,"tv":32568.63,"id":2497008}],"tv":243877.73}]}
{"op":"mcm","clk":"4299697483","pt":1632581648786,"mc":[{"id":"1.188136695","rc":[{"trd":[[1.17,9512.39],[1.18,31785.42]],"batb":[[0,1.17,531.81],[1,1.16,3009.88],[2,1.15,5658.68]],"batl":[[0,1.18,4174]],"ltp":1.18,"tv":211381.18,"id":5300737},{"trd":[[6.4,2504.54]],"batb":[[0,6.4,623.01]],"ltp":6.4,"tv":32582.65,"id":2497008}],"tv":243963.83}]}
{"op":"mcm","clk":"4299697672","pt":1632581649812,"mc":[{"id":"1.188136695","rc":[{"trd":[[1.18,31785.59]],"batl":[[0,1.18,4266.12],[2,1.2,11.86]],"ltp":1.18,"tv":211381.35,"id":5300737}],"tv":243964.0}]}
{"op":"mcm","clk":"4299697828","pt":1632581650586,"mc":[{"id":"1.188136695","rc":[{"trd":[[1.18,31881.16]],"batl":[[0,1.18,4218.34]],"ltp":1.18,"tv":211476.92,"id":5300737},{"trd":[[6.4,2504.7]],"batb":[[0,6.4,622.93]],"ltp":6.4,"tv":32582.81,"id":2497008}],"tv":244059.73}]}
{"op":"mcm","clk":"4299698071","pt":1632581651820,"mc":[{"id":"1.188136695","rc":[{"trd":[[1.18,31893.61]],"batb":[[1,1.16,2993.88]],"batl":[[0,1.18,4212.11]],"ltp":1.18,"tv":211489.37,"id":5300737},{"batb":[[0,6.4,636.27]],"batl":[[0,6.8,11.34]],"ltp":6.4,"tv":32582.81,"id":2497008}],"tv":244072.19}]}
{"op":"mcm","clk":"4299698258","pt":1632581652799,"mc":[{"id":"1.188136695","rc":[{"trd":[[1.18,32914.07]],"batb":[[2,1.15,5398.33]],"batl":[[0,1.18,3701.88]],"ltp":1.18,"tv":212509.83,"id":5300737},{"trd":[[6.4,2511.6]],"batb":[[0,6.4,632.82]],"batl":[[1,7,8.2],[2,7.2,67.57]],"ltp":6.4,"tv":32589.71,"id":2497008}],"tv":245099.55}]}
{"op":"mcm","clk":"4299698393","pt":1632581653626,"mc":[{"id":"1.188136695","rc":[{"trd":[[1.18,32928.7]],"batl":[[0,1.18,3694.57]],"ltp":1.18,"tv":212524.46,"id":5300737}],"tv":245114.17}]}
{"op":"mcm","clk":"4299698570","pt":1632581654430,"mc":[{"id":"1.188136695","rc":[{"trd":[[1.17,9687.61],[1.18,32930.42]],"batb":[[0,1.17,700.47],[1,1.16,3006.88]],"batl":[[0,1.18,3601.51]],"ltp":1.18,"tv":212701.4,"id":5300737},{"batb":[[1,6.2,530.84]],"ltp":6.4,"tv":32589.71,"id":2497008}],"tv":245291.11}]}
{"op":"mcm","clk":"4299698817","pt":1632581655730,"mc":[{"id":"1.188136695","rc":[{"trd":[[1.17,9690.27],[1.18,33093.98]],"batb":[[0,1.17,699.14],[1,1.16,3264.99]],"batl":[[0,1.18,3868.53]],"ltp":1.18,"tv":212867.62,"id":5300737}],"tv":245457.34}]}
{"op":"mcm","clk":"4299698954","pt":1632581656429,"mc":[{"id":"1.188136695","rc":[{"trd":[[1.18,33094.36]],"batl":[[0,1.18,3868.34]],"ltp":1.18,"tv":212868.0,"id":5300737},{"trd":[[6.4,2511.79],[6.8,49.38]],"batb":[[0,6.4,632.73]],"batl":[[0,6.8,6.15]],"ltp":6.4,"tv":32600.68,"id":2497008}],"tv":245468.68}]}
{"op":"mcm","clk":"4299699186","pt":1632581657718,"mc":[{"id":"1.188136695","rc":[{"trd":[[1.18,33100.37]],"batb":[[1,1.16,2214.19],[2,1.15,4028.92]],"batl":[[0,1.18,2574.41],[1,1.19,1834.92]],"ltp":1.18,"tv":212874.01,"id":5300737},{"batb":[[0,6.4,187.49],[1,6.2,3],[2,5.7,124.04]],"batl":[[1,7.8,1],[2,8.4,45.66]],"ltp":6.4,"tv":32600.68,"id":2497008}],"tv":245474.7}]}
{"op":"mcm","clk":"4299699386","pt":1632581658807,"mc":[{"id":"1.188136695","rc":[{"trd":[[1.17,9876.25],[1.18,33103.89]],"batb":[[0,1.17,590.15],[1,1.16,103.35],[2,1.15,600]],"batl":[[0,1.18,1077.85],[1,1.2,11.86],[2,1.21,5]],"ltp":1.17,"tv":213063.51,"id":5300737},{"batb":[[0,5.7,124.04],[1,5.2,63.89],[2,5.1,87.31]],"ltp":6.4,"tv":32600.68,"id":2497008}],"tv":245664.2}]}
{"op":"mcm","clk":"4299699571","pt":1632581659625,"mc":[{"id":"1.188136695","rc":[{"trd":[[1.18,33107.41]],"batb":[[0,1.17,371.87]],"batl":[[0,1.18,125.59]],"ltp":1.18,"tv":213067.03,"id":5300737},{"batl":[[0,6.8,31.62]],"ltp":6.4,"tv":32600.68,"id":2497008}],"tv":245667.71}]}
{"op":"mcm","clk":"4299699798","pt":1632581660693,"mc":[{"id":"1.188136695","rc":[{"batb":[[0,1.18,2.15],[1,1.17,371.87],[2,1.16,103.35]],"batl":[[0,1.2,11.86],[1,1.21,5],[2,1.23,50.77]],"ltp":1.18,"tv":213067.03,"id":5300737},{"batl":[[0,6.4,20],[1,6.8,3.2],[2,7.8,1]],"ltp":6.4,"tv":32600.68,"id":2497008}]}]}
{"op":"mcm","clk":"4299700022","pt":1632581661718,"mc":[{"id":"1.188136695","rc":[{"batl":[[2,1.22,2074.45]],"ltp":1.18,"tv":213067.03,"id":5300737},{"batl":[[1,7.8,1.2],[2,8.4,45.66]],"ltp":6.4,"tv":32600.68,"id":2497008}]}]}
{"op":"mcm","clk":"4299700214","pt":1632581662733,"mc":[{"id":"1.188136695","rc":[{"trd":[[1.18,33130.63]],"batb":[[0,1.17,371.87],[1,1.16,103.35],[2,1.15,600]],"ltp":1.18,"tv":213090.25,"id":5300737},{"trd":[[6.4,2513.8]],"batl":[[0,6.4,17.99]],"ltp":6.4,"tv":32602.69,"id":2497008}],"tv":245692.95}]}
{"op":"mcm","clk":"4299700397","pt":1632581663617,"mc":[{"id":"1.188136695","rc":[{"batb":[[0,1.19,467.13],[1,1.18,2239.53],[2,1.17,371.87]],"batl":[[0,1.21,5],[1,1.22,2074.45],[2,1.23,1414.13]],"ltp":1.18,"tv":213090.25,"id":5300737},{"batl":[[0,7.8,1.2],[1,8.8,9.12],[2,9.8,1]],"ltp":6.4,"tv":32602.69,"id":2497008}]}]}
{"op":"mcm","clk":"4299700647","pt":1632581664755,"mc":[{"id":"1.188136695","rc":[{"batb":[[0,1.19,598.43],[1,1.18,2307.57],[2,1.17,437.52]],"ltp":1.18,"tv":213090.25,"id":5300737},{"batl":[[0,6.8,436.15],[1,7.8,1],[2,8.8,9.12]],"ltp":6.4,"tv":32602.69,"id":2497008}]}]}
{"op":"mcm","clk":"4299700877","pt":1632581665735,"mc":[{"id":"1.188136695","rc":[{"batb":[[0,1.19,16348.43],[2,1.17,367.49]],"ltp":1.18,"tv":213090.25,"id":5300737},{"trd":[[5.7,209.58]],"batb":[[0,5.7,116.63],[1,5.3,2165.1],[2,5.2,63.89]],"batl":[[0,6.2,925.4],[1,6.4,898.18],[2,6.6,898.38]],"ltp":5.7,"tv":32617.51,"id":2497008}],"tv":245707.77}]}
{"op":"mcm","clk":"4299701092","pt":1632581666740,"mc":[{"id":"1.188136695","rc":[{"batb":[[0,1.19,3196.07],[1,1.18,3299.96]],"ltp":1.18,"tv":213090.25,"id":5300737},{"batb":[[0,5.7,118.63],[1,5.6,2],[2,5.3,324.77]],"batl":[[0,6.2,231.35],[1,6.4,260.99],[2,6.6,224.75]],"ltp":5.7,"tv":32617.51,"id":2497008}]}]}
{"op":"mcm","clk":"4299701325","pt":1632581667818,"mc":[{"id":"1.188136695","rc":[{"batb":[[0,1.2,1161.5],[1,1.19,3196.07],[2,1.18,3299.96]],"ltp":1.18,"tv":213090.25,"id":5300737},{"batl":[[0,6,42.24],[1,6.2,231.35],[2,6.4,260.99]],"ltp":5.7,"tv":32617.51,"id":2497008}]}]}
{"op":"mcm","clk":"4299701336","pt":1632581667913,"mc":[{"id":"1.188136695","rc":[{"batb":[[1,1.19,3245.75]],"ltp":1.18,"tv":213090.25,"id":5300737},{"batb":[[0,5.7,128.07]],"ltp":5.7,"tv":32617.51,"id":2497008}]}]}
{"op":"mcm","clk":"4299701594","pt":1632581669226,"mc":[{"id":"1.188136695","rc":[{"batl":[[1,1.22,2625.58],[2,1.23,2079.25]],"ltp":1.18,"tv":213090.25,"id":5300737},{"batb":[[2,5.5,122.24]],"ltp":5.7,"tv":32617.51,"id":2497008}]}]}
{"op":"mcm","clk":"4299701871","pt":1632581670738,"mc":[{"id":"1.188136695","rc":[{"batb":[[1,1.19,2778.62],[2,1.18,3304.96]],"batl":[[0,1.21,789.19],[1,1.22,3650.57]],"ltp":1.18,"tv":213090.25,"id":5300737},{"batl":[[1,6.2,236.35]],"ltp":5.7,"tv":32617.51,"id":2497008}]}]}
{"op":"mcm","clk":"4299701965","pt":1632581671223,"mc":[{"id":"1.188136695","rc":[{"batb":[[1,1.19,3456.6],[2,1.18,4143.22]],"batl":[[1,1.22,3398.22]],"ltp":1.18,"tv":213090.25,"id":5300737},{"batl":[[1,6.2,233.35],[2,6.4,387.05]],"ltp":5.7,"tv":32617.51,"id":2497008}]}]}
{"op":"mcm","clk":"4299702195","pt":1632581672650,"mc":[{"id":"1.188136695","rc":[{"trd":[[1.2,8648.28]],"batb":[[0,1.2,1155.81]],"batl":[[1,1.22,3399.93]],"ltp":1.2,"tv":213101.64,"id":5300737}],"tv":245719.15}]}
{"op":"mcm","clk":"4299702256","pt":1632581673015,"mc":[{"id":"1.188136695","rc":[{"batb":[[0,1.2,1704.36],[1,1.19,4188.58]],"ltp":1.2,"tv":213101.64,"id":5300737},{"batl":[[0,6,151.95],[2,6.4,523.15]],"ltp":5.7,"tv":32617.51,"id":2497008}]}]}
{"op":"mcm","clk":"4299702795","pt":1632581675755,"mc":[{"id":"1.188136695","rc":[{"batb":[[0,1.2,752.49]],"batl":[[0,1.21,784.19]],"ltp":1.2,"tv":213101.64,"id":5300737}]}]}
{"op":"mcm","clk":"4299703129","pt":1632581677358,"mc":[{"id":"1.188136695","rc":[{"trd":[[1.21,7059.38]],"batl":[[0,1.21,499.63]],"ltp":1.21,"tv":213670.76,"id":5300737}],"tv":246288.28}]}
{"op":"mcm","clk":"4299703328","pt":1632581678485,"mc":[{"id":"1.188136695","rc":[{"batb":[[1,1.19,4063.58],[2,1.18,4125.69]],"batl":[[0,1.21,1048.19],[1,1.22,4122.48]],"ltp":1.21,"tv":213670.76,"id":5300737},{"batb":[[0,5.7,244.51],[2,5.5,282.51]],"ltp":5.7,"tv":32617.51,"id":2497008}]}]}
{"op":"mcm","clk":"4299703497","pt":1632581679452,"mc":[{"id":"1.188136695","rc":[{"batl":[[0,1.21,1049.24]],"ltp":1.21,"tv":213670.76,"id":5300737},{"batb":[[0,5.7,235.07],[1,5.5,282.51],[2,5.3,479.13]],"ltp":5.7,"tv":32617.51,"id":2497008}]}]}
{"op":"mcm","clk":"4299703690","pt":1632581680442,"mc":[{"id":"1.188136695","rc":[{"trd":[[1.21,7060.16]],"batl":[[0,1.21,1048.85]],"ltp":1.21,"tv":213671.54,"id":5300737}],"tv":246289.06}]}
{"op":"mcm","clk":"4299703927","pt":1632581681742,"mc":[{"id":"1.188136695","rc":[{"trd":[[1.21,7077.42]],"batb":[[0,1.2,201.62],[1,1.18,2.39],[2,1.17,45.56]],"batl":[[0,1.21,1.05],[1,1.22,1.71],[2,1.23,50.77]],"ltp":1.21,"tv":213688.8,"id":5300737},{"batb":[[0,5.1,182.51],[1,4.7,55.03],[2,4.6,218.87]],"batl":[[0,6,40.24],[1,7,51.24],[2,7.2,66.78]],"ltp":5.7,"tv":32617.51,"id":2497008}],"tv":246306.32}]}
{"op":"mcm","clk":"4299704147","pt":1632581682672,"mc":[{"id":"1.188136695","rc":[{"batb":[[0,5.6,2],[1,5.1,182.51],[2,4.7,55.03]],"ltp":5.7,"tv":32617.51,"id":2497008}]}]}
{"op":"mcm","clk":"4299704225","pt":1632581683090,"mc":[{"id":"1.188136695","rc":[{"batb":[[0,1.18,2.78],[1,1.17,45.56],[2,1.16,462.65]],"ltp":1.21,"tv":213688.8,"id":5300737},{"batb":[[0,5.1,160.56],[1,4.7,55.03],[2,4.6,218.87]],"batl":[[0,7,51.24],[1,7.2,66.78],[2,7.4,63.6]],"ltp":5.7,"tv":32617.51,"id":2497008}]}]}
{"op":"mcm","clk":"4299704541","pt":1632581684464,"mc":[{"id":"1.188136695","rc":[{"trd":[[1.21,7078.22]],"batl":[[0,1.21,11.65]],"ltp":1.21,"tv":213689.6,"id":5300737}],"tv":246307.12}]}
{"op":"mcm","clk":"4299704789","pt":1632581685677,"mc":[{"id":"1.188136695","rc":[{"trd":[[1.2,8649.04],[1.21,7082.22]],"batb":[[0,1.18,2.39]],"batl":[[0,1.2,10.14]],"ltp":1.2,"tv":213694.37,"id":5300737}],"tv":246311.88}]}
{"op":"mcm","clk":"4299704931","pt":1632581686370,"mc":[{"id":"1.188136695","rc":[{"batl":[[2,1.23,54.78]],"ltp":1.2,"tv":213694.37,"id":5300737}]}]}
{"op":"mcm","clk":"4299705494","pt":1632581689086,"mc":[{"id":"1.188136695","rc":[{"batb":[[2,1.16,103.35]],"ltp":1.2,"tv":213694.37,"id":5300737},{"batl":[[0,7.8,10.22],[1,8.8,9.12],[2,9.4,7.94]],"ltp":5.7,"tv":32617.51,"id":2497008}]}]}
{"op":"mcm","clk":"4299705847","pt":1632581690763,"mc":[{"id":"1.188136695","rc":[{"trd":[[1.2,8669.32],[1.22,3270.5],[1.23,6252.22],[1.24,11186.2]],"batb":[[0,1.24,20.12],[1,1.22,381.42],[2,1.21,2222]],"batl":[[0,1.25,1161.72],[1,1.26,1264],[2,1.27,203.63]],"ltp":1.24,"tv":213923.84,"id":5300737}],"tv":246541.35}]}
{"op":"mcm","clk":"4299705994","pt":1632581691460,"mc":[{"id":"1.188136695","rc":[{"batb":[[1,1.22,382.01]],"ltp":1.24,"tv":213923.84,"id":5300737},{"batl":[[0,5.5,52.16],[1,5.6,50.62],[2,5.7,50.62]],"ltp":5.7,"tv":32617.51,"id":2497008}]}]}
{"op":"mcm","clk":"4299706269","pt":1632581692770,"mc":[{"id":"1.188136695","rc":[{"batb":[[1,1.22,3456.31],[2,1.21,4143.67]],"batl":[[2,1.27,209.9]],"ltp":1.24,"tv":213923.84,"id":5300737},{"trd":[[5.1,297.19]],"batb":[[0,5.1,148.4],[1,4.7,421.26],[2,4.6,574.32]],"batl":[[0,5.5,312.96],[1,5.6,303.74],[2,5.7,303.74]],"ltp":5.1,"tv":32641.83,"id":2497008}],"tv":246565.67}]}
{"op":"mcm","clk":"4299706460","pt":1632581693788,"mc":[{"id":"1.188136695","rc":[{"trd":[[1.24,11226.44]],"batb":[[0,1.22,3650.12],[1,1.21,5448.21],[2,1.18,1623.57]],"batl":[[0,1.25,1216.77],[2,1.27,205.69]],"ltp":1.24,"tv":213964.08,"id":5300737},{"batb":[[0,5.1,150.4],[1,5,2.35],[2,4.7,420.91]],"batl":[[0,5.5,355.38]],"ltp":5.1,"tv":32641.83,"id":2497008}],"tv":246605.91}]}
{"op":"mcm","clk":"4299706669","pt":1632581694807,"mc":[{"id":"1.188136695","rc":[{"batb":[[1,1.21,3226.4],[2,1.2,41.54]],"batl":[[1,1.26,1325.51]],"ltp":1.24,"tv":213964.08,"id":5300737}]}]}
{"op":"mcm","clk":"4299706780","pt":1632581695493,"mc":[{"id":"1.188136695","rc":[{"batb":[[2,1.2,43.34]],"ltp":1.24,"tv":213964.08,"id":5300737},{"batl":[[0,5.5,312.96]],"ltp":5.1,"tv":32641.83,"id":2497008}]}]}
{"op":"mcm","clk":"4299707071","pt":1632581696795,"mc":[{"id":"1.188136695","rc":[{"batb":[[0,1.22,3719.17],[1,1.21,3239.4]],"batl":[[0,1.24,1.71],[1,1.25,1911.74],[2,1.26,1325.51]],"ltp":1.24,"tv":213964.08,"id":5300737}]}]}
{"op":"mcm","clk":"4299707245","pt":1632581697675,"mc":[{"id":"1.188136695","rc":[{"batb":[[2,1.2,1.8]],"batl":[[0,1.24,725.07]],"ltp":1.24,"tv":213964.08,"id":5300737},{"batl":[[0,5.5,324.31]],"ltp":5.1,"tv":32641.83,"id":2497008}]}]}
{"op":"mcm","clk":"4299707460","pt":1632581698674,"mc":[{"id":"1.188136695","rc":[{"batl":[[0,1.24,750.07]],"ltp":1.24,"tv":213964.08,"id":5300737},{"batl":[[0,5.4,42.9],[1,5.5,324.31],[2,5.6,303.74]],"ltp":5.1,"tv":32641.83,"id":2497008}]}]}
{"op":"mcm","clk":"4299707633","pt":1632581699482,"mc":[{"id":"1.188136695","rc":[{"batb":[[0,1.22,3718.58],[2,1.19,801.11]],"batl":[[0,1.24,750.42]],"ltp":1.24,"tv":213964.08,"id":5300737}]}]}
{"op":"mcm","clk":"4299707798","pt":1632581700392,"mc":[{"id":"1.188136695","rc":[{"batl":[[0,1.24,769.45]],"ltp":1.24,"tv":213964.08,"id":5300737}]}]}
{"op":"mcm","clk":"4299708119","pt":1632581701799,"mc":[{"id":"1.188136695","rc":[{"trd":[[1.23,6259.25]],"batb":[[0,1.22,3337.16]],"batl":[[0,1.23,61.05],[1,1.24,769.45],[2,1.25,1911.74]],"ltp":1.23,"tv":213971.1,"id":5300737}],"tv":246612.93}]}
{"op":"mcm","clk":"4299708212","pt":1632581702519,"mc":[{"id":"1.188136695","rc":[{"trd":[[1.23,6264.59]],"batl":[[0,1.23,58.38],[1,1.24,744.45]],"ltp":1.23,"tv":213976.44,"id":5300737}],"tv":246618.28}]}
{"op":"mcm","clk":"4299708520","pt":1632581703814,"mc":[{"id":"1.188136695","rc":[{"trd":[[1.23,6266.17]],"batl":[[0,1.23,100.45]],"ltp":1.23,"tv":213978.02,"id":5300737}],"tv":246619.85}]}
{"op":"mcm","clk":"4299708707","pt":1632581704706,"mc":[{"id":"1.188136695","rc":[{"trd":[[1.23,6370.42]],"batl":[[0,1.23,49.04]],"ltp":1.23,"tv":214082.27,"id":5300737},{"trd":[[5.3,275.73]],"ltp":5.3,"tv":32647.06,"id":2497008}],"tv":246729.34}]}
{"op":"mcm","clk":"4299709093","pt":1632581706675,"mc":[{"id":"1.188136695","rc":[{"trd":[[1.23,6468.5],[1.24,11226.81]],"batb":[[0,1.22,2384.9]],"batl":[[0,1.24,744.61],[1,1.25,1911.74],[2,1.26,1325.51]],"ltp":1.24,"tv":214180.72,"id":5300737},{"trd":[[5.4,11.54]],"batb":[[0,5.3,2],[1,5.2,2],[2,5.1,150.4]],"batl":[[0,5.4,40.63]],"ltp":5.4,"tv":32651.6,"id":2497008}],"tv":246832.33}]}
{"op":"mcm","clk":"4299709263","pt":1632581707584,"mc":[{"id":"1.188136695","rc":[{"batb":[[0,1.22,2382.97]],"batl":[[2,1.26,1398.64]],"ltp":1.24,"tv":214180.72,"id":5300737}]}]}
{"op":"mcm","clk":"4299709636","pt":1632581709690,"mc":[{"id":"1.188136695","rc":[{"trd":[[1.22,3502.64],[1.24,11236.21]],"batb":[[0,1.22,2266.9],[1,1.21,3226.4],[2,1.2,1.89]],"batl":[[0,1.24,739.91]],"ltp":1.24,"tv":214422.27,"id":5300737},{"batl":[[1,5.5,326.58]],"ltp":5.4,"tv":32651.6,"id":2497008}],"tv":247073.87}]}
{"op":"mcm","clk":"4299709777","pt":1632581710386,"mc":[{"id":"1.188136695","rc":[{"trd":[[1.24,11236.91]],"batb":[[0,1.23,118.66],[1,1.22,2266.9],[2,1.21,3226.4]],"batl":[[0,1.24,739.56]],"ltp":1.24,"tv":214422.97,"id":5300737},{"trd":[[5.3,279.63]],"batb":[[0,5.2,2],[1,5.1,150.4],[2,5,2]],"ltp":5.3,"tv":32655.5,"id":2497008}],"tv":247078.47}]}
{"op":"mcm","clk":"4299710030","pt":1632581711696,"mc":[{"id":"1.188136695","rc":[{"batb":[[0,1.23,119.26],[1,1.22,18],[2,1.21,1304.73]],"batl":[[0,1.24,19.72],[1,1.25,11],[2,1.26,134.64]],"ltp":1.24,"tv":214422.97,"id":5300737},{"batl":[[1,5.5,2.27],[2,6.2,50.22]],"ltp":5.3,"tv":32655.5,"id":2497008}]}]}
{"op":"mcm","clk":"4299710201","pt":1632581712399,"mc":[{"id":"1.188136695","rc":[{"trd":[[1.24,11242.55]],"batb":[[0,1.23,126.27],[1,1.21,11.19],[2,1.2,1.89]],"batl":[[0,1.24,3.08],[1,1.26,134.64],[2,1.27,952.26]],"ltp":1.24,"tv":214428.61,"id":5300737},{"trd":[[5.1,298.56]],"batb":[[0,4.6,325.85],[1,4.4,82.57],[2,4.3,77.97]],"ltp":5.1,"tv":32656.87,"id":2497008}],"tv":247085.48}]}
{"op":"mcm","clk":"4299710479","pt":1632581713683,"mc":[{"id":"1.188136695","rc":[{"trd":[[1.23,6619.35]],"batb":[[0,1.23,50.84],[1,1.2,2.08],[2,1.19,801.11]],"batl":[[0,1.24,2.73],[1,1.25,25],[2,1.26,134.64]],"ltp":1.23,"tv":214579.46,"id":5300737},{"batl":[[0,6.2,50.22],[1,6.4,75.47],[2,6.6,81.14]],"ltp":5.1,"tv":32656.87,"id":2497008}],"tv":247236.34}]}
{"op":"mcm","clk":"4299710696","pt":1632581714817,"mc":[{"id":"1.188136695","rc":[{"batb":[[0,1.23,238.5],[2,1.19,1765.85]],"ltp":1.23,"tv":214579.46,"id":5300737}]}]}
{"op":"mcm","clk":"4299710881","pt":1632581715725,"mc":[{"id":"1.188136695","rc":[{"batb":[[0,1.23,51.26]],"ltp":1.23,"tv":214579.46,"id":5300737}]}]}
{"op":"mcm","clk":"4299710986","pt":1632581716311,"mc":[{"id":"1.188136695","rc":[{"trd":[[1.23,6619.78]],"batb":[[0,1.23,51.05],[2,1.19,801.11]],"ltp":1.23,"tv":214579.89,"id":5300737}],"tv":247236.77}]}
{"op":"mcm","clk":"4299711207","pt":1632581717499,"mc":[{"id":"1.188136695","rc":[{"trd":[[1.24,11248.01]],"batb":[[0,1.23,47.59]],"batl":[[0,1.25,25],[1,1.26,134.64],[2,1.28,957.52]],"ltp":1.24,"tv":214585.35,"id":5300737}],"tv":247242.23}]}
{"op":"mcm","clk":"4299711332","pt":1632581718110,"mc":[{"id":"1.188136695","rc":[{"batb":[[0,1.23,40.58]],"ltp":1.24,"tv":214585.35,"id":5300737}]}]}
{"op":"mcm","clk":"4299711698","pt":1632581719815,"mc":[{"id":"1.188136695","rc":[{"trd":[[1.22,3669.18],[1.23,6699.29],[1.24,11248.84]],"batb":[[0,1.22,734.23],[1,1.21,1699.34],[2,1.2,1.89]],"batl":[[0,1.24,1014.25],[1,1.25,1355.12],[2,1.26,134.64]],"ltp":1.22,"tv":214832.22,"id":5300737},{"trd":[[5.2,37.52]],"ltp":5.2,"tv":32657.07,"id":2497008}],"tv":247489.3}]}
{"op":"mcm","clk":"4299711884","pt":1632581720706,"mc":[{"id":"1.188136695","rc":[{"trd":[[1.24,11251.25]],"batb":[[0,1.22,735.94],[1,1.21,1709.86]],"batl":[[0,1.24,1053.3]],"ltp":1.24,"tv":214834.63,"id":5300737},{"batb":[[0,4.7,37.63],[1,4.6,325.85],[2,4.4,82.57]],"batl":[[0,6,21.28],[1,6.2,50.22],[2,6.4,75.47]],"ltp":5.2,"tv":32657.07,"id":2497008}],"tv":247491.71}]}
{"op":"mcm","clk":"4299712091","pt":1632581721730,"mc":[{"id":"1.188136695","rc":[{"trd":[[1.24,11255.11]],"batb":[[1,1.21,1748.56]],"batl":[[0,1.24,1051.37]],"ltp":1.24,"tv":214838.49,"id":5300737}],"tv":247495.57}]}
{"op":"mcm","clk":"4299712516","pt":1632581723816,"mc":[{"id":"1.188136695","rc":[{"batb":[[0,1.22,1.71],[1,1.21,49.41]],"batl":[[0,1.23,1.76],[1,1.24,709.8],[2,1.25,25]],"ltp":1.24,"tv":214838.49,"id":5300737},{"batb":[[0,4.6,326.17],[1,4.4,82.57],[2,4.3,77.97]],"batl":[[0,6.2,50.22],[1,6.4,75.47],[2,6.6,81.14]],"ltp":5.2,"tv":32657.07,"id":2497008}]}]}
{"op":"mcm","clk":"4299712558","pt":1632581724032,"mc":[{"id":"1.188136695","rc":[{"batl":[[1,1.25,25],[2,1.26,134.64]],"ltp":1.24,"tv":214838.49,"id":5300737}]}]}
{"op":"mcm","clk":"4299713121","pt":1632581726630,"mc":[{"id":"1.188136695","rc":[{"batl":[[0,1.23,2.81]],"ltp":1.24,"tv":214838.49,"id":5300737}]}]}
{"op":"mcm","clk":"4299713335","pt":1632581727614,"mc":[{"id":"1.188136695","rc":[{"trd":[[1.23,6699.69]],"batl":[[0,1.23,2.61],[2,1.26,177.5]],"ltp":1.23,"tv":214838.89,"id":5300737}],"tv":247495.97}]}
{"op":"mcm","clk":"4299713738","pt":1632581729811,"mc":[{"id":"1.188136695","rc":[{"batb":[[0,1.24,4.76],[1,1.22,1.71],[2,1.21,49.41]],"batl":[[0,1.25,25],[1,1.26,177.5],[2,1.28,1873.77]],"ltp":1.23,"tv":214838.89,"id":5300737}]}]}
{"op":"mcm","clk":"4299714056","pt":1632581731532,"mc":[{"id":"1.188136695","rc":[{"trd":[[1.21,7181.04],[1.22,3672.6],[1.24,11264.63]],"batb":[[0,1.2,1.89],[1,1.19,1715.68],[2,1.18,4046.71]],"batl":[[0,1.22,1.06],[1,1.25,25],[2,1.26,177.5]],"ltp":1.21,"tv":214950.65,"id":5300737},{"batb":[[1,4.1,1],[2,3.8,1]],"ltp":5.2,"tv":32657.07,"id":2497008}],"tv":247607.73}]}
{"op":"mcm","clk":"4299714129","pt":1632581731907,"mc":[{"id":"1.188136695","rc":[{"trd":[[1.21,7181.28],[1.22,3673.21]],"batl":[[0,1.25,25.64],[1,1.26,177.5],[2,1.28,957.52]],"ltp":1.22,"tv":214951.5,"id":5300737}],"tv":247608.57}]}
{"op":"mcm","clk":"4299714442","pt":1632581733737,"mc":[{"id":"1.188136695","rc":[{"batl":[[0,1.21,14767.34],[1,1.22,467.77],[2,1.25,25]],"ltp":1.22,"tv":214951.5,"id":5300737},{"batb":[[0,5.5,1043.18],[1,5.4,1012.5],[2,5.3,1012.5]],"ltp":5.2,"tv":32657.07,"id":2497008}]}]}
{"op":"mcm","clk":"4299714641","pt":1632581734813,"mc":[{"id":"1.188136695","rc":[{"trd":[[1.21,7569.03]],"batb":[[1,1.19,1726.68],[2,1.18,4058.71]],"batl":[[0,1.21,3255.43],[1,1.22,2004.26],[2,1.23,6.48]],"ltp":1.21,"tv":215339.25,"id":5300737},{"trd":[[5.7,289.23]],"batb":[[0,5.5,312.96],[1,5.4,303.74],[2,5.3,303.74]],"batl":[[0,6.2,52.22]],"ltp":5.7,"tv":32736.71,"id":2497008}],"tv":248075.97}]}
{"op":"mcm","clk":"4299714776","pt":1632581735414,"mc":[{"id":"1.188136695","rc":[{"trd":[[1.21,7569.64]],"batl":[[0,1.21,3255.13]],"ltp":1.21,"tv":215339.86,"id":5300737},{"trd":[[5.8,44.74]],"batb":[[0,5.8,228.63],[1,5.5,312.96],[2,5.4,303.74]],"ltp":5.8,"tv":32751.25,"id":2497008}],"tv":248091.11}]}
{"op":"mcm","clk":"4299714983","pt":1632581736611,"mc":[{"id":"1.188136695","rc":[{"trd":[[1.21,7574.33]],"batb":[[1,1.19,1933.15]],"batl":[[0,1.21,2367.16]],"ltp":1.21,"tv":215344.55,"id":5300737}],"tv":248095.81}]}
{"op":"mcm","clk":"4299715110","pt":1632581737318,"mc":[{"id":"1.188136695","rc":[{"trd":[[1.21,7632.62]],"batl":[[0,1.21,2338.02]],"ltp":1.21,"tv":215402.84,"id":5300737}],"tv":248154.09}]}
{"op":"mcm","clk":"4299715422","pt":1632581738812,"mc":[{"id":"1.188136695","rc":[{"batl":[[0,1.21,3624.17],[1,1.22,2245.97]],"ltp":1.21,"tv":215402.84,"id":5300737},{"batb":[[0,5.8,231.63],[1,5.7,125.09],[2,5.5,470.19]],"ltp":5.8,"tv":32751.25,"id":2497008}]}]}
{"op":"mcm","clk":"4299715609","pt":1632581739727,"mc":[{"id":"1.188136695","rc":[{"trd":[[1.21,7633.46]],"batl":[[0,1.21,3751.95]],"ltp":1.21,"tv":215403.68,"id":5300737},{"batb":[[0,5.8,281.63]],"batl":[[0,6.2,91.68]],"ltp":5.8,"tv":32751.25,"id":2497008}],"tv":248154.94}]}
{"op":"mcm","clk":"4299715713","pt":1632581740214,"mc":[{"id":"1.188136695","rc":[{"trd":[[1.21,7642.03]],"batb":[[0,1.2,77.31]],"batl":[[0,1.21,2719.17]],"ltp":1.21,"tv":215412.25,"id":5300737},{"batb":[[0,5.8,241.04]],"ltp":5.8,"tv":32751.25,"id":2497008}],"tv":248163.51}]}
{"op":"mcm","clk":"4299716340","pt":1632581743640,"mc":[{"id":"1.188136695","rc":[{"trd":[[1.21,7643.09]],"batl":[[0,1.21,2718.99]],"ltp":1.21,"tv":215413.31,"id":5300737}],"tv":248164.57}]}
{"op":"mcm","clk":"4299716764","pt":1632581745723,"mc":[{"id":"1.188136695","rc":[{"trd":[[1.21,10053.48]],"batb":[[0,1.2,120.17]],"batl":[[0,1.21,1513.8]],"ltp":1.21,"tv":217823.7,"id":5300737}],"tv":250574.96}]}
{"op":"mcm","clk":"4299716949","pt":1632581746830,"mc":[{"id":"1.188136695","rc":[{"trd":[[1.2,8691.97],[1.21,10061.2]],"batb":[[0,1.2,108.85]],"batl":[[0,1.21,1509.94]],"ltp":1.21,"tv":217854.07,"id":5300737},{"trd":[[5.8,102.7]],"batb":[[0,5.8,212.06]],"ltp":5.8,"tv":32809.21,"id":2497008}],"tv":250663.29}]}
{"op":"mcm","clk":"4299717126","pt":1632581747739,"mc":[{"id":"1.188136695","rc":[{"trd":[[1.21,10082.24]],"batb":[[0,1.2,441.85],[2,1.18,4046.71]],"batl":[[0,1.21,1499.42]],"ltp":1.21,"tv":217875.11,"id":5300737}],"tv":250684.33}]}
{"op":"mcm","clk":"4299717327","pt":1632581748767,"mc":[{"id":"1.188136695","rc":[{"trd":[[1.21,10096.26]],"batb":[[0,1.2,442.69],[1,1.19,2465.24]],"batl":[[0,1.21,2204.13]],"ltp":1.21,"tv":217889.13,"id":5300737},{"batb":[[0,5.8,202.65]],"ltp":5.8,"tv":32809.21,"id":2497008}],"tv":250698.35}]}
{"op":"mcm","clk":"4299717461","pt":1632581749327,"mc":[{"id":"1.188136695","rc":[{"trd":[[1.21,10103.28]],"batl":[[0,1.21,2200.62]],"ltp":1.21,"tv":217896.15,"id":5300737}],"tv":250705.37}]}
{"op":"mcm","clk":"4299717733","pt":1632581750721,"mc":[{"id":"1.188136695","rc":[{"trd":[[1.21,10107.5]],"batl":[[0,1.21,2198.51]],"ltp":1.21,"tv":217900.37,"id":5300737},{"trd":[[5.8,102.71]],"batb":[[0,5.8,202.64]],"ltp":5.8,"tv":32809.23,"id":2497008}],"tv":250709.6}]}
{"op":"mcm","clk":"4299717876","pt":1632581751573,"mc":[{"id":"1.188136695","rc":[{"trd":[[1.2,8692.68]],"batb":[[0,1.2,442.34]],"batl":[[2,1.24,98.57]],"ltp":1.2,"tv":217901.07,"id":5300737},{"batb":[[1,5.7,122.09]],"ltp":5.8,"tv":32809.23,"id":2497008}],"tv":250710.31}]}
{"op":"mcm","clk":"4299718090","pt":1632581752747,"mc":[{"id":"1.188136695","rc":[{"trd":[[1.2,8694.37]],"batb":[[0,1.2,450.26]],"ltp":1.2,"tv":217902.76,"id":5300737}],"tv":250712.0}]}
{"op":"mcm","clk":"4299718253","pt":1632581753717,"mc":[{"id":"1.188136695","rc":[{"batb":[[1,1.19,217.47],[2,1.18,1618.16]],"batl":[[0,1.21,12.35],[1,1.24,99.21],[2,1.26,142.64]],"ltp":1.2,"tv":217902.76,"id":5300737},{"batb":[[1,5,169.05],[2,4.6,188.26]],"batl":[[0,6.2,41.46],[1,7.8,54.2],[2,8,52.34]],"ltp":5.8,"tv":32809.23,"id":2497008}]}]}
{"op":"mcm","clk":"4299718470","pt":1632581754742,"mc":[{"id":"1.188136695","rc":[{"trd":[[1.21,10107.85],[1.22,3673.85]],"batb":[[0,1.21,2.37],[1,1.2,450.26],[2,1.19,206.47]],"batl":[[0,1.24,100.29],[1,1.26,134.64],[2,1.28,1182.93]],"ltp":1.22,"tv":217903.75,"id":5300737},{"trd":[[5.2,37.8],[5.5,32.84],[5.7,289.3]],"batb":[[0,5.2,21.42],[1,5,167.05]],"batl":[[0,6.2,39.46]],"ltp":5.2,"tv":32809.72,"id":2497008}],"tv":250713.48}]}
{"op":"mcm","clk":"4299718523","pt":1632581755064,"mc":[{"id":"1.188136695","rc":[{"batb":[[2,1.18,2.39]],"batl":[[0,1.24,10.29]],"ltp":1.22,"tv":217903.75,"id":5300737},{"batb":[[0,5,167.05],[1,4.6,188.26],[2,4.5,93.42]],"batl":[[0,7.8,54.2],[1,8,52.34],[2,8.2,69.01]],"ltp":5.2,"tv":32809.72,"id":2497008}]}]}
{"op":"mcm","clk":"4299718845","pt":1632581756740,"mc":[{"id":"1.188136695","rc":[{"trd":[[1.2,8707.55],[1.21,10129.72]],"batb":[[0,1.2,443.67],[1,1.18,2.39],[2,1.17,45.56]],"batl":[[1,1.26,1509.22],[2,1.27,1194.18]],"ltp":1.2,"tv":217938.81,"id":5300737},{"batb":[[1,4.9,168.59],[2,4.6,188.26]],"ltp":5.2,"tv":32809.72,"id":2497008}],"tv":250748.54}]}
{"op":"mcm","clk":"4299718988","pt":1632581757450,"mc":[{"id":"1.188136695","rc":[{"batb":[[0,1.21,4.3],[1,1.2,443.67],[2,1.18,2.39]],"ltp":1.2,"tv":217938.81,"id":5300737},{"batb":[[0,4.9,169.22],[1,4.6,188.26],[2,4.5,93.42]],"ltp":5.2,"tv":32809.72,"id":2497008}]}]}
{"op":"mcm","clk":"4299719181","pt":1632581758453,"mc":[{"id":"1.188136695","rc":[{"trd":[[1.2,9594.89],[1.21,10139.12]],"batb":[[0,1.18,2.39],[1,1.17,45.56],[2,1.16,103.35]],"batl":[[0,1.2,68.25],[1,1.24,10.29],[2,1.26,1509.22]],"ltp":1.2,"tv":218835.55,"id":5300737},{"batl":[[0,7.8,1],[1,8.8,9.12],[2,9.8,1]],"ltp":5.2,"tv":32809.72,"id":2497008}],"tv":251645.27}]}
{"op":"mcm","clk":"4299719435","pt":1632581759755,"mc":[{"id":"1.188136695","rc":[{"trd":[[1.2,9731.39]],"batb":[[0,1.23,17839.63],[1,1.22,4527.44],[2,1.21,7153.03]],"batl":[[0,1.24,10.29],[1,1.26,1509.22],[2,1.27,1194.18]],"ltp":1.2,"tv":218972.05,"id":5300737}],"tv":251781.78}]}
{"op":"mcm","clk":"4299719568","pt":1632581760461,"mc":[{"id":"1.188136695","rc":[{"batb":[[0,1.23,233.23],[1,1.22,226.37],[2,1.21,2851.96]],"ltp":1.2,"tv":218972.05,"id":5300737}]}]}
{"op":"mcm","clk":"4299719811","pt":1632581761653,"mc":[{"id":"1.188136695","rc":[{"trd":[[1.24,11295.95],[1.26,4971.25]],"batb":[[0,1.24,123.48],[1,1.23,3014.78],[2,1.22,3551.43]],"batl":[[0,1.26,1493.22],[1,1.27,1200.45],[2,1.28,1182.93]],"ltp":1.24,"tv":219035.38,"id":5300737},{"trd":[[4.9,22.63],[5,671.49],[5.1,301.06],[5.3,280.25]],"batb":[[0,4.9,159.39],[2,4.5,475.92]],"batl":[[0,5.6,41.71],[1,7.8,1],[2,8.8,9.12]],"ltp":4.9,"tv":32831.89,"id":2497008}],"tv":251867.27}]}
{"op":"mcm","clk":"4299720037","pt":1632581762678,"mc":[{"id":"1.188136695","rc":[{"trd":[[1.24,11373.35]],"batb":[[0,1.24,84.78],[2,1.22,4893.39]],"ltp":1.24,"tv":219112.77,"id":5300737},{"batb":[[0,4.9,171.11],[2,4.5,685.01]],"batl":[[1,6.2,5],[2,7.8,1]],"ltp":4.9,"tv":32831.89,"id":2497008}],"tv":251944.66}]}
{"op":"mcm","clk":"4299720232","pt":1632581763598,"mc":[{"id":"1.188136695","rc":[{"batb":[[2,1.22,5085.27]],"batl":[[2,1.28,1272.93]],"ltp":1.24,"tv":219112.77,"id":5300737},{"batb":[[1,4.6,213.26]],"batl":[[0,5.5,43.02],[1,5.6,41.71],[2,6.6,1.71]],"ltp":4.9,"tv":32831.89,"id":2497008}]}]}
{"op":"mcm","clk":"4299720464","pt":1632581764690,"mc":[{"id":"1.188136695","rc":[{"batl":[[0,1.26,1559.24]],"ltp":1.24,"tv":219112.77,"id":5300737},{"batb":[[0,4.9,174.11],[1,4.8,2],[2,4.6,213.26]],"ltp":4.9,"tv":32831.89,"id":2497008}]}]}
{"op":"mcm","clk":"4299720557","pt":1632581765071,"mc":[{"id":"1.188136695","rc":[{"batb":[[2,1.22,4893.39]],"batl":[[0,1.26,2157.39]],"ltp":1.24,"tv":219112.77,"id":5300737}]}]}
{"op":"mcm","clk":"4299720911","pt":1632581766759,"mc":[{"id":"1.188136695","rc":[{"trd":[[1.24,11377.22]],"batb":[[0,1.23,3014.78],[1,1.22,4816.4],[2,1.21,1362.24]],"batl":[[0,1.24,22.53],[1,1.26,2711.09],[2,1.27,1835.58]],"ltp":1.24,"tv":219116.64,"id":5300737},{"trd":[[5.1,301.66]],"batb":[[1,4.8,147.34],[2,4.7,171.61]],"batl":[[0,5.6,41.71],[1,6.6,1.71],[2,7.8,1]],"ltp":5.1,"tv":32832.49,"id":2497008}],"tv":251949.13}]}
{"op":"mcm","clk":"4299721074","pt":1632581767558,"mc":[{"id":"1.188136695","rc":[{"batl":[[1,6.6,13.02]],"ltp":5.1,"tv":32832.49,"id":2497008}]}]}
{"op":"mcm","clk":"4299721255","pt":1632581768472,"mc":[{"id":"1.188136695","rc":[{"batb":[[0,1.23,3797.28],[1,1.22,5580.09]],"batl":[[0,1.24,24.88],[1,1.25,85.71],[2,1.26,2711.09]],"ltp":1.24,"tv":219116.64,"id":5300737},{"batb":[[0,5.1,9.41],[1,4.9,174.11],[2,4.8,147.34]],"batl":[[0,5.4,135.48],[1,5.6,208.09],[2,6,65.54]],"ltp":5.1,"tv":32832.49,"id":2497008}]}]}
{"op":"mcm","clk":"4299721523","pt":1632581769784,"mc":[{"id":"1.188136695","rc":[{"trd":[[1.23,6706.71],[1.24,11391.99]],"batb":[[0,1.23,3870.76]],"batl":[[0,1.24,18.46],[1,1.25,685.4]],"ltp":1.23,"tv":219138.43,"id":5300737},{"trd":[[5.1,324.07]],"batb":[[0,5.1,2],[1,5,2],[2,4.9,174.11]],"batl":[[0,5.4,178.38]],"ltp":5.1,"tv":32854.9,"id":2497008}],"tv":251993.33}]}
{"op":"mcm","clk":"4299721698","pt":1632581770579,"mc":[{"id":"1.188136695","rc":[{"batl":[[0,1.24,27.16]],"ltp":1.23,"tv":219138.43,"id":5300737},{"batl":[[1,5.6,211.09],[2,6,66.06]],"ltp":5.1,"tv":32854.9,"id":2497008}]}]}
{"op":"mcm","clk":"4299721957","pt":1632581771768,"mc":[{"id":"1.188136695","rc":[{"batb":[[2,1.21,1417.24]],"batl":[[0,1.24,35.11]],"ltp":1.23,"tv":219138.43,"id":5300737}]}]}
{"op":"mcm","clk":"4299722128","pt":1632581772678,"mc":[{"id":"1.188136695","rc":[{"trd":[[1.23,6723.43]],"batb":[[0,1.23,3862.4]],"batl":[[0,1.24,35.46]],"ltp":1.23,"tv":219155.15,"id":5300737}],"tv":252010.05}]}
{"op":"mcm","clk":"4299722301","pt":1632581773481,"mc":[{"id":"1.188136695","rc":[{"batl":[[0,1.24,35.11]],"ltp":1.23,"tv":219155.15,"id":5300737},{"batl":[[0,5.4,193.73]],"ltp":5.1,"tv":32854.9,"id":2497008}]}]}
{"op":"mcm","clk":"4299722527","pt":1632581774560,"mc":[{"id":"1.188136695","rc":[{"trd":[[1.24,11413.99]],"batb":[[2,1.21,1413.23]],"batl":[[0,1.24,24.11],[1,1.25,1275.1],[2,1.26,3413.07]],"ltp":1.24,"tv":219177.15,"id":5300737},{"batb":[[1,5,149.42]],"ltp":5.1,"tv":32854.9,"id":2497008}],"tv":252032.05}]}
{"op":"mcm","clk":"4299722752","pt":1632581775473,"mc":[{"id":"1.188136695","rc":[{"trd":[[1.24,11445.49]],"batl":[[0,1.24,9.06]],"ltp":1.24,"tv":219208.65,"id":5300737}],"tv":252063.56}]}
{"op":"mcm","clk":"4299723031","pt":1632581776686,"mc":[{"id":"1.188136695","rc":[{"batl":[[0,1.24,10.33]],"ltp":1.24,"tv":219208.65,"id":5300737}]}]}
{"op":"mcm","clk":"4299723183","pt":1632581777456,"mc":[{"id":"1.188136695","rc":[{"trd":[[1.24,11454.05]],"batb":[[1,1.22,5581.97]],"batl":[[0,1.24,6.05]],"ltp":1.24,"tv":219217.22,"id":5300737},{"batb":[[2,4.9,171.11]],"ltp":5.1,"tv":32854.9,"id":2497008}],"tv":252072.12}]}
{"op":"mcm","clk":"4299723426","pt":1632581778697,"mc":[{"id":"1.188136695","rc":[{"batb":[[0,1.23,187.66],[1,1.22,1.89],[2,1.21,55]],"batl":[[1,1.25,85.71],[2,1.26,127.64]],"ltp":1.24,"tv":219217.22,"id":5300737},{"batb":[[0,4.6,151.23],[1,4.5,209.09],[2,4.2,60.08]],"batl":[[0,5.4,42.9],[1,6,66.06],[2,6.2,60.39]],"ltp":5.1,"tv":32854.9,"id":2497008}]}]}
{"op":"mcm","clk":"4299723657","pt":1632581779818,"mc":[{"id":"1.188136695","rc":[{"trd":[[1.23,6728.12],[1.24,11460.79]],"batb":[[0,1.22,1.89],[1,1.21,55],[2,1.2,311.01]],"batl":[[0,1.24,2.68],[1,1.26,127.64],[2,1.27,1.76]],"ltp":1.23,"tv":219228.66,"id":5300737},{"batb":[[0,4.6,126.23]],"batl":[[0,6,66.06],[1,6.2,60.39],[2,6.4,62.01]],"ltp":5.1,"tv":32854.9,"id":2497008}],"tv":252083.56}]}
{"op":"mcm","clk":"4299723828","pt":1632581780585,"mc":[{"id":"1.188136695","rc":[{"trd":[[1.24,11466.15]],"batl":[[0,1.26,128.36],[1,1.27,1.76],[2,1.28,957.52]],"ltp":1.24,"tv":219234.01,"id":5300737}],"tv":252088.91}]}
{"op":"mcm","clk":"4299724058","pt":1632581781768,"mc":[{"id":"1.188136695","rc":[{"batl":[[0,1.23,5.04],[1,1.26,127.64],[2,1.27,1.76]],"ltp":1.24,"tv":219234.01,"id":5300737}]}]}
{"op":"mcm","clk":"4299724220","pt":1632581782620,"mc":[{"id":"1.188136695","rc":[{"trd":[[1.23,6729.8]],"batl":[[0,1.23,4.22],[1,1.26,127.99]],"ltp":1.23,"tv":219235.68,"id":5300737},{"trd":[[5.3,280.6]],"ltp":5.3,"tv":32855.25,"id":2497008}],"tv":252090.94}]}
{"op":"mcm","clk":"4299724379","pt":1632581783478,"mc":[{"id":"1.188136695","rc":[{"batb":[[1,1.21,55.7]],"ltp":1.23,"tv":219235.68,"id":5300737},{"batb":[[0,4.8,3],[1,4.7,3],[2,4.6,126.23]],"ltp":5.3,"tv":32855.25,"id":2497008}]}]}
{"op":"mcm","clk":"4299724634","pt":1632581784704,"mc":[{"id":"1.188136695","rc":[{"batb":[[1,1.21,57.38]],"batl":[[1,1.24,19.21],[2,1.26,127.64]],"ltp":1.23,"tv":219235.68,"id":5300737}]}]}
{"op":"mcm","clk":"4299724756","pt":1632581785288,"mc":[{"id":"1.188136695","rc":[{"trd":[[1.23,6741.07]],"batl":[[0,1.23,1.21]],"ltp":1.23,"tv":219246.96,"id":5300737}],"tv":252102.21}]}
{"op":"mcm","clk":"4299725016","pt":1632581786594,"mc":[{"id":"1.188136695","rc":[{"trd":[[1.22,3694.42],[1.23,6743.49],[1.24,11504.56]],"batb":[[0,1.24,92.12]],"batl":[[0,1.26,127.64],[1,1.27,1.76],[2,1.28,957.52]],"ltp":1.24,"tv":219308.36,"id":5300737}],"tv":252163.61}]}
{"op":"mcm","clk":"4299725520","pt":1632581789099,"mc":[{"id":"1.188136695","rc":[{"batb":[[0,4.9,260.7],[1,4.8,3],[2,4.7,3]],"ltp":5.3,"tv":32855.25,"id":2497008}]}]}
{"op":"mcm","clk":"4299725795","pt":1632581790542,"mc":[{"id":"1.188136695","rc":[{"trd":[[1.24,11505.26]],"batb":[[0,1.24,91.77]],"ltp":1.24,"tv":219309.06,"id":5300737}],"tv":252164.31}]}
{"op":"mcm","clk":"4299725931","pt":1632581791339,"mc":[{"id":"1.188136695","rc":[{"trd":[[1.26,5003.36]],"batb":[[1,1.23,7.51],[2,1.21,57.38]],"batl":[[0,1.26,111.58]],"ltp":1.26,"tv":219341.17,"id":5300737}],"tv":252196.43}]}
{"op":"mcm","clk":"4299726211","pt":1632581792734,"mc":[{"id":"1.188136695","rc":[{"batb":[[0,1.23,8.89],[1,1.21,57.38],[2,1.2,311.01]],"ltp":1.26,"tv":219341.17,"id":5300737}]}]}
{"op":"mcm","clk":"4299726623","pt":1632581794819,"mc":[{"id":"1.188136695","rc":[{"trd":[[1.21,10202.94],[1.23,6761.27]],"batb":[[0,1.21,2.38],[1,1.2,311.01],[2,1.19,326.44]],"ltp":1.21,"tv":219422.78,"id":5300737}],"tv":252278.03}]}
{"op":"mcm","clk":"4299726782","pt":1632581795622,"mc":[{"id":"1.188136695","rc":[{"trd":[[1.26,5008.06]],"batb":[[1,1.18,2117.76],[2,1.17,45.56]],"batl":[[0,1.26,109.24]],"ltp":1.26,"tv":219427.48,"id":5300737},{"batb":[[2,4.6,126.23]],"batl":[[0,6.6,11.83],[1,7.8,10.37],[2,8.8,1]],"ltp":5.3,"tv":32855.25,"id":2497008}],"tv":252282.73}]}
{"op":"mcm","clk":"4299727009","pt":1632581796798,"mc":[{"id":"1.188136695","rc":[{"trd":[[1.24,11512.69],[1.26,6240.35],[1.27,2448.53],[1.28,911.99]],"batb":[[0,1.24,2222],[1,1.21,2.03],[2,1.18,2117.76]],"batl":[[0,1.28,811.71],[1,1.29,3.51],[2,1.3,1478.91]],"ltp":1.28,"tv":220973.67,"id":5300737},{"trd":[[4.8,925.07],[4.9,283.33]],"batb":[[0,4.6,126.23],[1,4.5,209.09],[2,4.2,60.08]],"ltp":4.8,"tv":33118.95,"id":2497008}],"tv":254092.63}]}
{"op":"mcm","clk":"4299727215","pt":1632581797817,"mc":[{"id":"1.188136695","rc":[{"trd":[[1.26,6243.87],[1.27,2481.13]],"batb":[[0,1.27,836.4],[1,1.26,6575.18],[2,1.25,4640.62]],"ltp":1.27,"tv":221009.79,"id":5300737},{"trd":[[4.6,23.19]],"batb":[[0,4.6,116.93]],"batl":[[0,5.2,44.67],[1,6.6,11.83],[2,7.8,10.37]],"ltp":4.6,"tv":33137.55,"id":2497008}],"tv":254147.34}]}
{"op":"mcm","clk":"4299727435","pt":1632581798743,"mc":[{"id":"1.188136695","rc":[{"trd":[[1.27,2482.45]],"batb":[[0,1.27,835.08],[1,1.26,4112.26],[2,1.25,2417.53]],"batl":[[0,1.29,3.51],[1,1.3,1485.03],[2,1.31,1009.24]],"ltp":1.27,"tv":221011.11,"id":5300737},{"trd":[[4.8,925.42]],"batl":[[1,5.9,508.66],[2,6.6,11.31]],"ltp":4.8,"tv":33137.9,"id":2497008}],"tv":254149.01}]}
{"op":"mcm","clk":"4299727673","pt":1632581799830,"mc":[{"id":"1.188136695","rc":[{"trd":[[1.27,2771.85],[1.28,925.99]],"batb":[[0,1.27,690.38],[1,1.26,4291.11]],"batl":[[0,1.28,4],[1,1.29,3.51],[2,1.3,1485.03]],"ltp":1.27,"tv":221314.51,"id":5300737},{"trd":[[4.6,39.09]],"batb":[[0,4.6,109.03],[1,4.5,211.09]],"batl":[[0,4.8,46.16],[1,5.2,44.67],[2,5.8,2.23]],"ltp":4.6,"tv":33153.79,"id":2497008}],"tv":254468.31}]}
{"op":"mcm","clk":"4299727823","pt":1632581800642,"mc":[{"id":"1.188136695","rc":[{"trd":[[1.27,3146.18]],"batb":[[0,1.27,503.22],[1,1.26,4114.61]],"ltp":1.27,"tv":221688.84,"id":5300737},{"batl":[[0,5.2,44.67],[1,5.8,2.23],[2,6.6,11.31]],"ltp":4.6,"tv":33153.79,"id":2497008}],"tv":254842.64}]}
{"op":"mcm","clk":"4299728043","pt":1632581801729,"mc":[{"id":"1.188136695","rc":[{"trd":[[1.27,3332.5]],"batb":[[0,1.27,410.06]],"batl":[[1,1.29,12.51],[2,1.3,1080.68]],"ltp":1.27,"tv":221875.16,"id":5300737}],"tv":255028.96}]}
{"op":"mcm","clk":"4299728257","pt":1632581802751,"mc":[{"id":"1.188136695","rc":[{"batb":[[0,1.27,551.72]],"batl":[[1,1.29,922.18]],"ltp":1.27,"tv":221875.16,"id":5300737},{"batb":[[2,4.2,88.2]],"batl":[[0,4.9,10.02],[1,5.2,44.67],[2,5.8,2.23]],"ltp":4.6,"tv":33153.79,"id":2497008}]}]}
{"op":"mcm","clk":"4299728472","pt":1632581803739,"mc":[{"id":"1.188136695","rc":[{"batb":[[0,1.27,743.72],[1,1.26,4116.32],[2,1.25,2599.24]],"batl":[[1,1.29,1271.74],[2,1.3,1082.4]],"ltp":1.27,"tv":221875.16,"id":5300737},{"batl":[[0,5.2,44.67],[1,5.8,2.55],[2,6.6,11.31]],"ltp":4.6,"tv":33153.79,"id":2497008}]}]}
{"op":"mcm","clk":"4299728641","pt":1632581804566,"mc":[{"id":"1.188136695","rc":[{"trd":[[1.27,3349.64]],"batb":[[0,1.27,735.15],[1,1.26,3650.95],[2,1.25,2593.15]],"ltp":1.27,"tv":221892.3,"id":5300737}],"tv":255046.1}]}
{"op":"mcm","clk":"4299728860","pt":1632581805646,"mc":[{"id":"1.188136695","rc":[{"trd":[[1.28,943.63]],"batl":[[0,1.28,497.13],[1,1.29,1932.58]],"ltp":1.28,"tv":221909.94,"id":5300737},{"trd":[[4.6,46.86]],"batb":[[0,4.6,103.8],[1,4.5,352.49],[2,4.4,193.74]],"batl":[[0,5.1,25.33],[1,5.2,96.56],[2,5.3,61.97]],"ltp":4.6,"tv":33161.57,"id":2497008}],"tv":255071.51}]}
{"op":"mcm","clk":"4299729025","pt":1632581806538,"mc":[{"id":"1.188136695","rc":[{"batl":[[0,5.2,96.66],[1,5.3,61.97],[2,5.4,83.78]],"ltp":4.6,"tv":33161.57,"id":2497008}]}]}
{"op":"mcm","clk":"4299729229","pt":1632581807537,"mc":[{"id":"1.188136695","rc":[{"trd":[[1.27,3366.07]],"batb":[[0,1.27,736.94],[1,1.26,4190.08],[2,1.25,3235.99]],"ltp":1.27,"tv":221926.37,"id":5300737},{"batl":[[0,4.9,184.2],[1,5,160.71],[2,5.2,96.66]],"ltp":4.6,"tv":33161.57,"id":2497008}],"tv":255087.94}]}
{"op":"mcm","clk":"4299729454","pt":1632581808658,"mc":[{"id":"1.188136695","rc":[{"trd":[[1.27,3406.75]],"batb":[[0,1.27,716.6]],"batl":[[0,1.28,1107.37]],"ltp":1.27,"tv":221967.05,"id":5300737}],"tv":255128.62}]}
{"op":"mcm","clk":"4299729709","pt":1632581809775,"mc":[{"id":"1.188136695","rc":[{"trd":[[1.27,3414.94],[1.28,945.63]],"batb":[[0,1.27,712.51]],"batl":[[0,1.28,1106.37]],"ltp":1.27,"tv":221977.25,"id":5300737}],"tv":255138.82}]}
{"op":"mcm","clk":"4299729898","pt":1632581810752,"mc":[{"id":"1.188136695","rc":[{"trd":[[1.27,3454.04]],"batb":[[0,1.27,692.96],[1,1.26,4166.99]],"ltp":1.27,"tv":222016.34,"id":5300737},{"trd":[[4.6,62.86]],"batb":[[0,4.6,95.8]],"batl":[[1,5,170.71]],"ltp":4.6,"tv":33177.57,"id":2497008}],"tv":255193.92}]}
{"op":"mcm","clk":"4299730088","pt":1632581811760,"mc":[{"id":"1.188136695","rc":[{"trd":[[1.27,3472.35],[1.28,3515.55]],"batb":[[0,1.27,683.8],[1,1.26,4164.64]],"batl":[[0,1.29,1932.58],[1,1.3,1082.4],[2,1.31,90.35]],"ltp":1.27,"tv":224604.57,"id":5300737},{"trd":[[4.6,158.67]],"batb":[[0,4.5,352.49],[1,4.4,193.74],[2,4.2,60.08]],"ltp":4.6,"tv":33273.37,"id":2497008}],"tv":257877.95}]}
{"op":"mcm","clk":"4299730258","pt":1632581812651,"mc":[{"id":"1.188136695","rc":[{"trd":[[1.27,3484.24]],"batb":[[0,1.27,677.86]],"ltp":1.27,"tv":224616.46,"id":5300737},{"batl":[[0,4.8,21.15],[1,4.9,184.2],[2,5,170.71]],"ltp":4.6,"tv":33273.37,"id":2497008}],"tv":257889.84}]}
{"op":"mcm","clk":"4299730464","pt":1632581813660,"mc":[{"id":"1.188136695","rc":[{"trd":[[1.27,3487.76],[1.28,3516.39]],"batb":[[0,1.28,13.22],[1,1.27,754.93],[2,1.26,4164.64]],"ltp":1.28,"tv":224620.82,"id":5300737},{"batb":[[2,4.3,27.27]],"ltp":4.6,"tv":33273.37,"id":2497008}],"tv":257894.19}]}
{"op":"mcm","clk":"4299730727","pt":1632581814763,"mc":[{"id":"1.188136695","rc":[{"trd":[[1.28,3589.01]],"batb":[[0,1.27,878.24],[1,1.26,4164.64],[2,1.25,3235.99]],"batl":[[0,1.28,572.34],[1,1.29,1932.58],[2,1.3,1082.4]],"ltp":1.28,"tv":224693.44,"id":5300737},{"batb":[[1,4.4,196.74]],"ltp":4.6,"tv":33273.37,"id":2497008}],"tv":257966.81}]}
{"op":"mcm","clk":"4299730906","pt":1632581815565,"mc":[{"id":"1.188136695","rc":[{"trd":[[1.27,3509.16]],"batb":[[0,1.27,867.54]],"ltp":1.27,"tv":224714.84,"id":5300737}],"tv":257988.22}]}
{"op":"mcm","clk":"4299731143","pt":1632581816658,"mc":[{"id":"1.188136695","rc":[{"trd":[[1.27,3637.1]],"batb":[[0,1.27,1289.55],[1,1.26,4813.48],[2,1.25,3237.88]],"ltp":1.27,"tv":224842.78,"id":5300737},{"batb":[[0,4.6,2.93],[1,4.5,352.49],[2,4.4,196.74]],"batl":[[0,4.8,149.73],[1,4.9,351.04]],"ltp":4.6,"tv":33273.37,"id":2497008}],"tv":258116.15}]}
{"op":"mcm","clk":"4299731280","pt":1632581817367,"mc":[{"id":"1.188136695","rc":[{"trd":[[1.28,3593.7]],"batl":[[0,1.28,569.99]],"ltp":1.28,"tv":224847.47,"id":5300737}],"tv":258120.85}]}
{"op":"mcm","clk":"4299731553","pt":1632581818758,"mc":[{"id":"1.188136695","rc":[{"trd":[[1.27,3649.96],[1.28,3594.46]],"batb":[[0,1.27,1283.12],[1,1.26,5892.18],[2,1.25,2152.33]],"batl":[[0,1.28,569.61],[1,1.29,2121.72]],"ltp":1.27,"tv":224861.09,"id":5300737}],"tv":258134.47}]}
{"op":"mcm","clk":"4299731744","pt":1632581819781,"mc":[{"id":"1.188136695","rc":[{"trd":[[1.27,3667.56]],"batb":[[0,1.27,1274.32]],"ltp":1.27,"tv":224878.69,"id":5300737},{"batb":[[0,4.6,4.93]],"ltp":4.6,"tv":33273.37,"id":2497008}],"tv":258152.07}]}
{"op":"mcm","clk":"4299731870","pt":1632581820468,"mc":[{"id":"1.188136695","rc":[{"trd":[[1.27,3669.53],[1.28,3637.32]],"batb":[[0,1.27,1273.33]],"batl":[[0,1.28,548.18],[1,1.29,2224.12]],"ltp":1.27,"tv":224923.53,"id":5300737}],"tv":258196.9}]}
{"op":"mcm","clk":"4299732016","pt":1632581821186,"mc":[{"id":"1.188136695","rc":[{"trd":[[1.27,3870.85]],"batb":[[0,1.27,1172.67]],"ltp":1.27,"tv":225124.85,"id":5300737},{"trd":[[4.8,926.32]],"batl":[[0,4.8,149.28]],"ltp":4.8,"tv":33274.27,"id":2497008}],"tv":258399.12}]}
{"op":"mcm","clk":"4299732330","pt":1632581822569,"mc":[{"id":"1.188136695","rc":[{"trd":[[1.27,3872.47]],"batb":[[0,1.27,1171.86]],"batl":[[0,1.28,1040.17],[1,1.29,2807.82]],"ltp":1.27,"tv":225126.47,"id":5300737},{"batb":[[1,4.5,492.43],[2,4.4,367.87]],"ltp":4.8,"tv":33274.27,"id":2497008}],"tv":258400.74}]}
{"op":"mcm","clk":"4299732540","pt":1632581823771,"mc":[{"id":"1.188136695","rc":[{"trd":[[1.27,3872.66],[1.28,3637.98]],"batb":[[0,1.27,1171.77]],"batl":[[0,1.28,1054.54]],"ltp":1.27,"tv":225127.31,"id":5300737}],"tv":258401.59}]}
{"op":"mcm","clk":"4299732743","pt":1632581824467,"mc":[{"id":"1.188136695","rc":[{"trd":[[1.27,3873.36],[1.28,3639.58]],"batb":[[0,1.27,1302.45],[1,1.26,5889.73]],"batl":[[0,1.28,1053.74]],"ltp":1.27,"tv":225129.61,"id":5300737},{"trd":[[4.5,92.82],[4.6,168.52]],"batb":[[0,4.5,473.31],[1,4.4,367.87],[2,4.3,27.27]],"ltp":4.5,"tv":33322.39,"id":2497008}],"tv":258452.0}]}
{"op":"mcm","clk":"4299732930","pt":1632581825268,"mc":[{"id":"1.188136695","rc":[{"trd":[[1.27,3890.66],[1.28,3659.29]],"batb":[[0,1.27,1293.8]],"batl":[[0,1.28,1043.89]],"ltp":1.28,"tv":225166.62,"id":5300737}],"tv":258489.01}]}
{"op":"mcm","clk":"4299733139","pt":1632581826365,"mc":[{"id":"1.188136695","rc":[{"trd":[[1.28,3670.56]],"batl":[[0,1.28,1038.25]],"ltp":1.28,"tv":225177.89,"id":5300737}],"tv":258500.29}]}
{"op":"mcm","clk":"4299733406","pt":1632581827801,"mc":[{"id":"1.188136695","rc":[{"trd":[[1.28,3816.82]],"batl":[[0,1.28,965.12]],"ltp":1.28,"tv":225324.16,"id":5300737},{"batb":[[1,4.4,364.87]],"ltp":4.5,"tv":33322.39,"id":2497008}],"tv":258646.55}]}
{"op":"mcm","clk":"4299733620","pt":1632581828795,"mc":[{"id":"1.188136695","rc":[{"trd":[[1.27,3894.9],[1.28,3853.4]],"batb":[[0,1.27,1397.65]],"batl":[[0,1.28,954.83]],"ltp":1.28,"tv":225364.98,"id":5300737}],"tv":258687.37}]}
{"op":"mcm","clk":"4299733794","pt":1632581829692,"mc":[{"id":"1.188136695","rc":[{"trd":[[1.28,3911.94]],"batl":[[0,1.28,925.56]],"ltp":1.28,"tv":225423.51,"id":5300737}],"tv":258745.91}]}
{"op":"mcm","clk":"4299733998","pt":1632581830669,"mc":[{"id":"1.188136695","rc":[{"batb":[[1,4.4,367.87]],"ltp":4.5,"tv":33322.39,"id":2497008}]}]}
{"op":"mcm","clk":"4299734219","pt":1632581831758,"mc":[{"id":"1.188136695","rc":[{"trd":[[1.27,3900.3],[1.28,3911.98]],"batb":[[0,1.27,1394.95]],"batl":[[0,1.28,925.54]],"ltp":1.27,"tv":225428.95,"id":5300737}],"tv":258751.34}]}
{"op":"mcm","clk":"4299734421","pt":1632581832814,"mc":[{"id":"1.188136695","rc":[{"trd":[[1.27,3918.04],[1.28,3918.08]],"batb":[[0,1.27,1386.08]],"batl":[[0,1.28,922.49]],"ltp":1.27,"tv":225452.79,"id":5300737}],"tv":258775.18}]}
{"op":"mcm","clk":"4299734450","pt":1632581832891,"mc":[{"id":"1.188136695","rc":[{"trd":[[1.27,3922.34],[1.28,3932.1]],"batb":[[0,1.27,1383.93]],"batl":[[0,1.28,915.48]],"ltp":1.27,"tv":225471.11,"id":5300737}],"tv":258793.5}]}
{"op":"mcm","clk":"4299734783","pt":1632581834474,"mc":[{"id":"1.188136695","rc":[{"trd":[[1.27,3922.4],[1.28,3932.76]],"batb":[[0,1.27,1383.9]],"batl":[[0,1.28,915.15]],"ltp":1.27,"tv":225471.83,"id":5300737}],"tv":258794.22}]}
{"op":"mcm","clk":"4299735059","pt":1632581835775,"mc":[{"id":"1.188136695","rc":[{"trd":[[1.27,3924.1],[1.28,3947.04]],"batb":[[0,1.27,1383.05],[1,1.26,5886.6]],"batl":[[0,1.28,908.01]],"ltp":1.28,"tv":225487.81,"id":5300737},{"trd":[[4.5,205.5]],"batb":[[0,4.5,283.34],[1,4.4,583.13]],"ltp":4.5,"tv":33435.07,"id":2497008}],"tv":258922.88}]}
{"op":"mcm","clk":"4299735441","pt":1632581837705,"mc":[{"id":"1.188136695","rc":[{"trd":[[1.27,3959.53],[1.28,3950.64]],"batb":[[0,1.27,1365.33]],"batl":[[0,1.28,906.21],[1,1.29,2618.68]],"ltp":1.27,"tv":225526.84,"id":5300737},{"trd":[[4.5,206.9]],"batb":[[0,4.5,282.64]],"ltp":4.5,"tv":33436.47,"id":2497008}],"tv":258963.31}]}
{"op":"mcm","clk":"4299735905","pt":1632581839787,"mc":[{"id":"1.188136695","rc":[{"trd":[[1.27,3969.59],[1.28,3953.52]],"batb":[[0,1.27,1360.3]],"batl":[[0,1.28,904.77],[1,1.29,2619.34]],"ltp":1.28,"tv":225539.78,"id":5300737}],"tv":258976.25}]}
{"op":"mcm","clk":"4299736103","pt":1632581840772,"mc":[{"id":"1.188136695","rc":[{"trd":[[1.28,3955.62]],"batb":[[0,1.27,1254.33]],"batl":[[0,1.28,1094.34]],"ltp":1.28,"tv":225541.88,"id":5300737},{"trd":[[4.5,207.12]],"batb":[[0,4.5,282.53]],"batl":[[2,5,160.71]],"ltp":4.5,"tv":33436.68,"id":2497008}],"tv":258978.57}]}
{"op":"mcm","clk":"4299736254","pt":1632581841477,"mc":[{"id":"1.188136695","rc":[{"trd":[[1.28,3960.32]],"batl":[[0,1.28,1091.99],[1,1.29,2610.34]],"ltp":1.28,"tv":225546.58,"id":5300737}],"tv":258983.27}]}
{"op":"mcm","clk":"4299736393","pt":1632581842317,"mc":[{"id":"1.188136695","rc":[{"trd":[[1.28,3960.48]],"batb":[[0,1.27,1334.33]],"batl":[[0,1.28,1091.91]],"ltp":1.28,"tv":225546.74,"id":5300737}],"tv":258983.43}]}
{"op":"mcm","clk":"4299736652","pt":1632581843792,"mc":[{"id":"1.188136695","rc":[{"trd":[[1.27,3973.59],[1.28,4171.38]],"batb":[[0,1.27,1332.33]],"batl":[[0,1.28,986.46]],"ltp":1.28,"tv":225761.64,"id":5300737},{"batb":[[1,4.4,580.13]],"batl":[[1,4.9,305.47]],"ltp":4.5,"tv":33436.68,"id":2497008}],"tv":259198.33}]}
{"op":"mcm","clk":"4299736825","pt":1632581844696,"mc":[{"id":"1.188136695","rc":[{"trd":[[1.27,3994.25],[1.28,4172.08]],"batb":[[0,1.27,1322],[1,1.26,5877.21]],"batl":[[0,1.28,986.11]],"ltp":1.28,"tv":225783.0,"id":5300737}],"tv":259219.69}]}
{"op":"mcm","clk":"4299736871","pt":1632581844898,"mc":[{"id":"1.188136695","rc":[{"trd":[[1.28,4212.92]],"batl":[[0,1.28,965.69]],"ltp":1.28,"tv":225823.84,"id":5300737}],"tv":259260.53}]}
{"op":"mcm","clk":"4299737285","pt":1632581846819,"mc":[{"id":"1.188136695","rc":[{"trd":[[1.27,3997.77],[1.28,4233.96]],"batb":[[0,1.27,1320.24]],"batl":[[0,1.28,955.17]],"ltp":1.27,"tv":225848.4,"id":5300737}],"tv":259285.09}]}
{"op":"mcm","clk":"4299737469","pt":1632581847590,"mc":[{"id":"1.188136695","rc":[{"trd":[[1.27,4028.11]],"batb":[[0,1.27,1305.07]],"batl":[[2,1.3,1172.4]],"ltp":1.27,"tv":225878.74,"id":5300737},{"batb":[[1,4.4,583.13]],"batl":[[2,5,205.71]],"ltp":4.5,"tv":33436.68,"id":2497008}],"tv":259315.43}]}
{"op":"mcm","clk":"4299737566","pt":1632581848069,"mc":[{"id":"1.188136695","rc":[{"batb":[[1,1.26,5875.5],[2,1.25,2150.61]],"batl":[[1,1.29,2608.63],[2,1.3,1170.68]],"ltp":1.27,"tv":225878.74,"id":5300737}]}]}
{"op":"mcm","clk":"4299738117","pt":1632581850808,"mc":[{"id":"1.188136695","rc":[{"trd":[[1.27,4098.23],[1.28,4269.02]],"batb":[[0,1.27,840.95]],"batl":[[0,1.28,937.64],[1,1.29,2689.63]],"ltp":1.27,"tv":225983.92,"id":5300737}],"tv":259420.61}]}
{"op":"mcm","clk":"4299738206","pt":1632581851177,"mc":[{"id":"1.188136695","rc":[{"trd":[[4.5,208.79]],"batb":[[0,4.5,281.69]],"ltp":4.5,"tv":33438.36,"id":2497008}],"tv":259422.29}]}
{"op":"mcm","clk":"4299738544","pt":1632581852793,"mc":[{"id":"1.188136695","rc":[{"trd":[[4.5,261.88]],"batb":[[0,4.5,255.15]],"ltp":4.5,"tv":33491.45,"id":2497008}],"tv":259475.38}]}
{"op":"mcm","clk":"4299738625","pt":1632581853169,"mc":[{"id":"1.188136695","rc":[{"trd":[[1.27,4099.02]],"batb":[[0,1.27,840.56]],"ltp":1.27,"tv":225984.71,"id":5300737}],"tv":259476.16}]}
{"op":"mcm","clk":"4299738838","pt":1632581854203,"mc":[{"id":"1.188136695","rc":[{"batb":[[1,1.26,6375.67]],"ltp":1.27,"tv":225984.71,"id":5300737}]}]}
{"op":"mcm","clk":"4299739189","pt":1632581855814,"mc":[{"id":"1.188136695","rc":[{"trd":[[1.27,4124.28]],"batb":[[0,1.27,1342.68]],"ltp":1.27,"tv":226009.97,"id":5300737},{"batb":[[0,4.5,258.15]],"ltp":4.5,"tv":33491.45,"id":2497008}],"tv":259501.43}]}
{"op":"mcm","clk":"4299739214","pt":1632581855901,"mc":[{"id":"1.188136695","rc":[{"trd":[[1.28,4285.86]],"batl":[[0,1.28,929.22]],"ltp":1.28,"tv":226026.81,"id":5300737}],"tv":259518.26}]}
{"op":"mcm","clk":"4299739789","pt":1632581858509,"mc":[{"id":"1.188136695","rc":[{"trd":[[1.28,4432.12]],"batl":[[0,1.28,856.09]],"ltp":1.28,"tv":226173.07,"id":5300737}],"tv":259664.53}]}
{"op":"mcm","clk":"4299740214","pt":1632581860661,"mc":[{"id":"1.188136695","rc":[{"trd":[[1.27,4129.15]],"batb":[[0,1.27,1340.25]],"ltp":1.27,"tv":226177.94,"id":5300737}],"tv":259669.39}]}
{"op":"mcm","clk":"4299740421","pt":1632581861630,"mc":[{"id":"1.188136695","rc":[{"trd":[[1.28,4438.34]],"batl":[[0,1.28,852.98]],"ltp":1.28,"tv":226184.16,"id":5300737}],"tv":259675.61}]}
{"op":"mcm","clk":"4299740592","pt":1632581862437,"mc":[{"id":"1.188136695","rc":[{"trd":[[1.27,4129.85]],"batb":[[0,1.27,1339.9]],"ltp":1.27,"tv":226184.86,"id":5300737}],"tv":259676.31}]}
{"op":"mcm","clk":"4299740858","pt":1632581863503,"mc":[{"id":"1.188136695","rc":[{"trd":[[1.27,4133.85]],"batb":[[0,1.27,1337.9]],"ltp":1.27,"tv":226188.85,"id":5300737},{"batb":[[0,4.5,187.75]],"ltp":4.5,"tv":33491.45,"id":2497008}],"tv":259680.31}]}
{"op":"mcm","clk":"4299741049","pt":1632581864431,"mc":[{"id":"1.188136695","rc":[{"trd":[[1.28,4490.12]],"batl":[[0,1.28,827.09]],"ltp":1.28,"tv":226240.63,"id":5300737},{"batb":[[0,4.5,129.72]],"ltp":4.5,"tv":33491.45,"id":2497008}],"tv":259732.09}]}
{"op":"mcm","clk":"4299741685","pt":1632581867517,"mc":[{"id":"1.188136695","rc":[{"trd":[[1.28,4491.81]],"batl":[[0,1.28,826.24]],"ltp":1.28,"tv":226242.33,"id":5300737},{"trd":[[4.5,266.44]],"batb":[[0,4.5,127.45]],"ltp":4.5,"tv":33496.01,"id":2497008}],"tv":259738.34}]}
{"op":"mcm","clk":"4299741949","pt":1632581868812,"mc":[{"id":"1.188136695","rc":[{"trd":[[1.27,4134.58]],"batb":[[0,1.27,1337.53]],"batl":[[2,1.3,1166.4]],"ltp":1.27,"tv":226243.07,"id":5300737},{"batb":[[1,4.4,580.13]],"ltp":4.5,"tv":33496.01,"id":2497008}],"tv":259739.08}]}
{"op":"mcm","clk":"4299742021","pt":1632581869133,"mc":[{"id":"1.188136695","rc":[{"trd":[[1.27,4138.1]],"batb":[[0,1.27,1335.78]],"ltp":1.27,"tv":226246.58,"id":5300737}],"tv":259742.6}]}
{"op":"mcm","clk":"4299742291","pt":1632581870320,"mc":[{"id":"1.188136695","rc":[{"trd":[[4.5,267.14]],"batb":[[0,4.5,127.09]],"ltp":4.5,"tv":33496.71,"id":2497008}],"tv":259743.3}]}
{"op":"mcm","clk":"4299742561","pt":1632581871623,"mc":[{"id":"1.188136695","rc":[{"batl":[[2,1.3,1174.97]],"ltp":1.27,"tv":226246.58,"id":5300737},{"batb":[[1,4.4,582.13]],"ltp":4.5,"tv":33496.71,"id":2497008}]}]}
{"op":"mcm","clk":"4299742993","pt":1632581873643,"mc":[{"id":"1.188136695","rc":[{"trd":[[1.27,4146.69]],"batb":[[0,1.27,1331.48]],"batl":[[0,1.28,821.68]],"ltp":1.27,"tv":226255.17,"id":5300737}],"tv":259751.89}]}
{"op":"mcm","clk":"4299743145","pt":1632581874235,"mc":[{"id":"1.188136695","rc":[{"trd":[[1.28,4505.83]],"batl":[[0,1.28,814.67]],"ltp":1.28,"tv":226269.19,"id":5300737}],"tv":259765.91}]}
{"op":"mcm","clk":"4299743464","pt":1632581875749,"mc":[{"id":"1.188136695","rc":[{"trd":[[1.28,4509.83]],"batl":[[0,1.28,812.67]],"ltp":1.28,"tv":226273.19,"id":5300737}],"tv":259769.91}]}
{"op":"mcm","clk":"4299743522","pt":1632581876014,"mc":[{"id":"1.188136695","rc":[{"trd":[[1.27,4161.05]],"batb":[[0,1.27,1324.3]],"ltp":1.27,"tv":226287.55,"id":5300737}],"tv":259784.27}]}
{"op":"mcm","clk":"4299743844","pt":1632581877737,"mc":[{"id":"1.188136695","rc":[{"trd":[[1.28,4535.79]],"batl":[[0,1.28,799.69]],"ltp":1.28,"tv":226313.51,"id":5300737}],"tv":259810.22}]}
{"op":"mcm","clk":"4299744215","pt":1632581879726,"mc":[{"id":"1.188136695","rc":[{"trd":[[1.27,4161.12]],"batb":[[0,1.27,1324.26]],"ltp":1.27,"tv":226313.57,"id":5300737}],"tv":259810.29}]}
{"op":"mcm","clk":"4299744301","pt":1632581880103,"mc":[{"id":"1.188136695","rc":[{"batl":[[0,1.28,654.99]],"ltp":1.27,"tv":226313.57,"id":5300737}]}]}
{"op":"mcm","clk":"4299744638","pt":1632581881740,"mc":[{"id":"1.188136695","rc":[{"trd":[[1.28,5535.79]],"batl":[[0,1.28,154.99]],"ltp":1.28,"tv":227313.58,"id":5300737},{"trd":[[4.5,277.14]],"batb":[[0,4.6,4.33],[1,4.5,122.1],[2,4.4,582.13]],"ltp":4.5,"tv":33506.71,"id":2497008}],"tv":260820.29}]}
{"op":"mcm","clk":"4299744720","pt":1632581882145,"mc":[{"id":"1.188136695","rc":[{"trd":[[1.27,4165.81],[1.28,5549.96]],"batb":[[0,1.27,1321.92]],"batl":[[0,1.28,147.9]],"ltp":1.27,"tv":227332.45,"id":5300737}],"tv":260839.16}]}
{"op":"mcm","clk":"4299745000","pt":1632581883551,"mc":[{"id":"1.188136695","rc":[{"trd":[[1.28,5626.13]],"batl":[[0,1.28,109.82]],"ltp":1.28,"tv":227408.61,"id":5300737}],"tv":260915.33}]}
{"op":"mcm","clk":"4299745249","pt":1632581884750,"mc":[{"id":"1.188136695","rc":[{"trd":[[1.27,4174.59],[1.28,5634.55]],"batb":[[0,1.27,1317.53]],"batl":[[0,1.28,105.61]],"ltp":1.28,"tv":227425.81,"id":5300737},{"batb":[[2,4.4,580.13]],"ltp":4.5,"tv":33506.71,"id":2497008}],"tv":260932.53}]}
{"op":"mcm","clk":"4299745406","pt":1632581885437,"mc":[{"id":"1.188136695","rc":[{"trd":[[1.27,4177.97]],"batb":[[0,1.27,1315.84]],"batl":[[0,1.28,115.61],[2,1.3,1168.84]],"ltp":1.27,"tv":227429.19,"id":5300737}],"tv":260935.9}]}
{"op":"mcm","clk":"4299745552","pt":1632581886125,"mc":[{"id":"1.188136695","rc":[{"trd":[[1.28,5639.29]],"batl":[[0,1.28,113.24]],"ltp":1.28,"tv":227433.93,"id":5300737},{"batb":[[0,4.6,6.33]],"ltp":4.5,"tv":33506.71,"id":2497008}],"tv":260940.65}]}
{"op":"mcm","clk":"4299745732","pt":1632581886974,"mc":[{"id":"1.188136695","rc":[{"trd":[[1.28,5643.23]],"batl":[[0,1.28,111.27]],"ltp":1.28,"tv":227437.87,"id":5300737}],"tv":260944.59}]}
{"op":"mcm","clk":"4299745942","pt":1632581888166,"mc":[{"id":"1.188136695","rc":[{"trd":[[1.27,4181.49]],"batb":[[0,1.27,1314.08]],"ltp":1.27,"tv":227441.39,"id":5300737}],"tv":260948.1}]}
{"op":"mcm","clk":"4299746444","pt":1632581890965,"mc":[{"id":"1.188136695","rc":[{"trd":[[1.28,5678.29]],"batl":[[0,1.28,93.74]],"ltp":1.28,"tv":227476.45,"id":5300737}],"tv":260983.16}]}
{"op":"mcm","clk":"4299746764","pt":1632581892758,"mc":[{"id":"1.188136695","rc":[{"trd":[[4.6,181.18]],"batb":[[0,4.5,122.1],[1,4.4,580.13],[2,4.3,27.27]],"ltp":4.6,"tv":33519.36,"id":2497008}],"tv":260995.82}]}
{"op":"mcm","clk":"4299746954","pt":1632581893734,"mc":[{"id":"1.188136695","rc":[{"trd":[[1.28,5682.59]],"batb":[[0,1.27,1234.08]],"batl":[[0,1.28,91.59],[2,1.3,1160.27]],"ltp":1.28,"tv":227480.75,"id":5300737}],"tv":261000.12}]}
{"op":"mcm","clk":"4299747127","pt":1632581894660,"mc":[{"id":"1.188136695","rc":[{"batl":[[0,4.8,128.58]],"ltp":4.6,"tv":33519.36,"id":2497008}]}]}
{"op":"mcm","clk":"4299747342","pt":1632581895781,"mc":[{"id":"1.188136695","rc":[{"trd":[[1.28,5847.85]],"batl":[[0,1.28,8.96]],"ltp":1.28,"tv":227646.01,"id":5300737}],"tv":261165.38}]}
{"op":"mcm","clk":"4299747527","pt":1632581896760,"mc":[{"id":"1.188136695","rc":[{"trd":[[1.28,5851.37]],"batl":[[0,1.28,7.2]],"ltp":1.28,"tv":227649.53,"id":5300737},{"batb":[[1,4.4,583.13]],"ltp":4.6,"tv":33519.36,"id":2497008}],"tv":261168.9}]}
{"op":"mcm","clk":"4299747893","pt":1632581898746,"mc":[{"id":"1.188136695","rc":[{"trd":[[1.28,5861.89]],"batl":[[0,1.29,2689.63],[1,1.3,1160.27],[2,1.31,86.06]],"ltp":1.28,"tv":227660.05,"id":5300737}],"tv":261179.42}]}
{"op":"mcm","clk":"4299748050","pt":1632581899562,"mc":[{"id":"1.188136695","rc":[{"trd":[[1.27,4187.68]],"batb":[[0,1.27,1230.99]],"ltp":1.27,"tv":227666.24,"id":5300737}],"tv":261185.61}]}
{"op":"mcm","clk":"4299748243","pt":1632581900484,"mc":[{"id":"1.188136695","rc":[{"batb":[[0,1.27,1231.62]],"ltp":1.27,"tv":227666.24,"id":5300737}]}]}
{"op":"mcm","clk":"4299748514","pt":1632581901782,"mc":[{"id":"1.188136695","rc":[{"trd":[[1.27,4188.52],[1.28,5863.15]],"batb":[[0,1.27,1230.57],[1,1.26,5423.41]],"batl":[[0,1.29,2699.63]],"ltp":1.27,"tv":227668.34,"id":5300737}],"tv":261187.71}]}
{"op":"mcm","clk":"4299748618","pt":1632581902273,"mc":[{"id":"1.188136695","rc":[{"batb":[[0,1.28,1.71],[1,1.27,1230.57],[2,1.26,5423.41]],"ltp":1.27,"tv":227668.34,"id":5300737},{"trd":[[4.5,297.14]],"batb":[[0,4.5,112.09]],"ltp":4.5,"tv":33539.37,"id":2497008}],"tv":261207.71}]}
{"op":"mcm","clk":"4299748793","pt":1632581903233,"mc":[{"id":"1.188136695","rc":[{"batb":[[0,1.28,3.41]],"ltp":1.27,"tv":227668.34,"id":5300737},{"batl":[[0,4.8,140.14]],"ltp":4.5,"tv":33539.37,"id":2497008}]}]}
{"op":"mcm","clk":"4299749086","pt":1632581904795,"mc":[{"id":"1.188136695","rc":[{"batb":[[0,1.28,4.38]],"ltp":1.27,"tv":227668.34,"id":5300737},{"batb":[[0,4.5,3]],"ltp":4.5,"tv":33539.37,"id":2497008}]}]}
{"op":"mcm","clk":"4299749344","pt":1632581905771,"mc":[{"id":"1.188136695","rc":[{"trd":[[1.28,5870.18]],"batb":[[0,1.28,97.09]],"ltp":1.28,"tv":227675.37,"id":5300737}],"tv":261214.74}]}
{"op":"mcm","clk":"4299749924","pt":1632581908784,"mc":[{"id":"1.188136695","rc":[{"batb":[[1,1.27,1134.06],[2,1.26,5423.72]],"ltp":1.28,"tv":227675.37,"id":5300737}]}]}
{"op":"mcm","clk":"4299750036","pt":1632581909375,"mc":[{"id":"1.188136695","rc":[{"batb":[[1,4.4,580.13]],"ltp":4.5,"tv":33539.37,"id":2497008}]}]}
{"op":"mcm","clk":"4299750300","pt":1632581910804,"mc":[{"id":"1.188136695","rc":[{"batb":[[1,1.25,182.2],[2,1.24,1425.82]],"batl":[[0,1.29,4.17],[1,1.3,90.2]],"ltp":1.28,"tv":227675.37,"id":5300737},{"batb":[[0,4.3,27.27],[1,4.1,1],[2,3.9,356.22]],"batl":[[0,5,45],[1,5.2,52.08],[2,5.3,61.66]],"ltp":4.5,"tv":33539.37,"id":2497008}]}]}
{"op":"mcm","clk":"4299750519","pt":1632581911789,"mc":[{"id":"1.188136695","rc":[{"trd":[[1.29,4625.91]],"batb":[[0,1.29,4.6],[1,1.28,97.09],[2,1.25,2.2]],"batl":[[0,1.31,86.26],[1,1.32,119.25],[2,1.35,222.55]],"ltp":1.29,"tv":227676.69,"id":5300737},{"batb":[[0,4.1,1],[1,3.9,356.22],[2,3.85,90.1]],"batl":[[0,5.2,52.08],[1,5.3,61.66],[2,5.4,98.12]],"ltp":4.5,"tv":33539.37,"id":2497008}],"tv":261216.06}]}
{"op":"mcm","clk":"4299750718","pt":1632581912803,"mc":[{"id":"1.188136695","rc":[{"batb":[[1,1.28,96.69]],"ltp":1.29,"tv":227676.69,"id":5300737}]}]}
{"op":"mcm","clk":"4299750948","pt":1632581913780,"mc":[{"id":"1.188136695","rc":[{"batb":[[1,1.28,96.62]],"batl":[[2,1.35,1409.04]],"ltp":1.29,"tv":227676.69,"id":5300737},{"batb":[[1,3.9,62.66],[2,3.85,391.52]],"ltp":4.5,"tv":33539.37,"id":2497008}]}]}
{"op":"mcm","clk":"4299751124","pt":1632581914698,"mc":[{"id":"1.188136695","rc":[{"trd":[[1.28,5906.29],[1.29,4635.11]],"batb":[[0,1.28,88.56],[1,1.25,2.2],[2,1.24,2261.26]],"ltp":1.28,"tv":227722.01,"id":5300737}],"tv":261261.38}]}
{"op":"mcm","clk":"4299751368","pt":1632581915780,"mc":[{"id":"1.188136695","rc":[{"batb":[[0,1.29,8.76],[1,1.28,88.56],[2,1.25,2.2]],"batl":[[2,1.35,1.61]],"ltp":1.28,"tv":227722.01,"id":5300737},{"batb":[[1,3.85,301.42],[2,3.8,1]],"ltp":4.5,"tv":33539.37,"id":2497008}]}]}
{"op":"mcm","clk":"4299751587","pt":1632581916788,"mc":[{"id":"1.188136695","rc":[{"trd":[[1.25,4925.57],[1.26,6244.5],[1.28,6083.42],[1.29,4649.11]],"batb":[[0,1.24,2261.26],[1,1.23,2376.7],[2,1.22,300.08]],"batl":[[0,1.26,12809.16],[1,1.27,4517.72],[2,1.28,4387.19]],"ltp":1.25,"tv":227917.54,"id":5300737}],"tv":261456.91}]}
{"op":"mcm","clk":"4299751779","pt":1632581917713,"mc":[{"id":"1.188136695","rc":[{"batl":[[0,1.27,4985.31],[1,1.28,6609.19],[2,1.29,4384.84]],"ltp":1.25,"tv":227917.54,"id":5300737}]}]}
{"op":"mcm","clk":"4299752010","pt":1632581918800,"mc":[{"id":"1.188136695","rc":[{"batl":[[0,1.26,729.56],[1,1.27,6434.31],[2,1.28,6830.96]],"ltp":1.25,"tv":227917.54,"id":5300737}]}]}
{"op":"mcm","clk":"4299752244","pt":1632581919814,"mc":[{"id":"1.188136695","rc":[{"trd":[[1.26,6276.92]],"batb":[[2,1.22,1621.86]],"batl":[[0,1.26,697.14],[1,1.27,3046.02],[2,1.28,1320.33]],"ltp":1.26,"tv":227949.96,"id":5300737},{"trd":[[4.8,934.83]],"batb":[[0,4.7,209.4],[1,4.3,2],[2,4.2,243.34]],"ltp":4.8,"tv":33547.88,"id":2497008}],"tv":261497.84}]}
{"op":"mcm","clk":"4299752374","pt":1632581920502,"mc":[{"id":"1.188136695","rc":[{"batl":[[1,1.27,3136.02]],"ltp":1.26,"tv":227949.96,"id":5300737}]}]}
{"op":"mcm","clk":"4299752590","pt":1632581921703,"mc":[{"id":"1.188136695","rc":[{"trd":[[1.26,6277.62]],"batl":[[0,1.26,1649.05]],"ltp":1.26,"tv":227950.66,"id":5300737}],"tv":261498.54}]}
{"op":"mcm","clk":"4299752807","pt":1632581922809,"mc":[{"id":"1.188136695","rc":[{"trd":[[1.26,6301.32]],"batl":[[0,1.26,1636.35],[1,1.27,3613.43],[2,1.28,1946.89]],"ltp":1.26,"tv":227974.36,"id":5300737},{"trd":[[4.8,941.05]],"batb":[[0,4.8,3],[1,4.7,365.72],[2,4.5,178.21]],"ltp":4.8,"tv":33554.1,"id":2497008}],"tv":261528.46}]}
{"op":"mcm","clk":"4299753017","pt":1632581923818,"mc":[{"id":"1.188136695","rc":[{"trd":[[1.26,6321.18]],"batb":[[0,1.24,2917.75]],"batl":[[0,1.26,2272.49],[1,1.27,3146.3]],"ltp":1.26,"tv":227994.22,"id":5300737},{"batb":[[0,4.8,14.84]],"ltp":4.8,"tv":33554.1,"id":2497008}],"tv":261548.32}]}
{"op":"mcm","clk":"4299753164","pt":1632581924512,"mc":[{"id":"1.188136695","rc":[{"batl":[[0,1.26,2769.62],[1,1.27,3740.29]],"ltp":1.26,"tv":227994.22,"id":5300737},{"batb":[[0,4.8,145.34],[1,4.7,501.9]],"ltp":4.8,"tv":33554.1,"id":2497008}]}]}
{"op":"mcm","clk":"4299753416","pt":1632581925812,"mc":[{"id":"1.188136695","rc":[{"batb":[[2,1.22,2513.13]],"batl":[[0,1.26,2859.62],[1,1.27,2384.97],[2,1.28,631.44]],"ltp":1.26,"tv":227994.22,"id":5300737}]}]}
{"op":"mcm","clk":"4299753507","pt":1632581926306,"mc":[{"id":"1.188136695","rc":[{"trd":[[1.26,6324.64]],"batb":[[0,1.23,13.64],[1,1.22,2213.05],[2,1.21,1232.49]],"batl":[[0,1.26,1042.26],[1,1.28,5.34],[2,1.31,86.26]],"ltp":1.26,"tv":227997.68,"id":5300737},{"batb":[[0,4.2,243.34],[1,4.1,60.46],[2,4,71.58]],"batl":[[0,5.5,54.63],[1,5.6,137.77],[2,5.7,90.26]],"ltp":4.8,"tv":33554.1,"id":2497008}],"tv":261551.78}]}
{"op":"mcm","clk":"4299753768","pt":1632581927520,"mc":[{"id":"1.188136695","rc":[{"batb":[[0,4.8,23.68],[1,4.2,243.34],[2,4.1,60.46]],"ltp":4.8,"tv":33554.1,"id":2497008}]}]}
{"op":"mcm","clk":"4299753903","pt":1632581928324,"mc":[{"id":"1.188136695","rc":[{"trd":[[1.23,6788.55],[1.24,11513.08]],"batb":[[0,1.22,2213.05],[1,1.21,1232.49],[2,1.2,1933.64]],"batl":[[0,1.23,81.92],[1,1.26,952.26],[2,1.28,5.34]],"ltp":1.23,"tv":228025.35,"id":5300737},{"trd":[[5.1,324.17]],"batb":[[0,4.2,243.34],[1,4.1,60.46],[2,4,71.58]],"batl":[[0,5.5,54.54],[1,5.6,95.81]],"ltp":5.1,"tv":33554.19,"id":2497008}],"tv":261579.54}]}
{"op":"mcm","clk":"4299754156","pt":1632581929520,"mc":[{"id":"1.188136695","rc":[{"trd":[[1.23,6790.65]],"batb":[[0,1.22,2868.07],[1,1.21,2923.55]],"batl":[[0,1.23,80.87]],"ltp":1.23,"tv":228027.45,"id":5300737}],"tv":261581.64}]}
{"op":"mcm","clk":"4299754390","pt":1632581930710,"mc":[{"id":"1.188136695","rc":[{"trd":[[1.23,6790.79]],"batl":[[0,1.23,80.8],[1,1.28,2.81],[2,1.31,86.26]],"ltp":1.23,"tv":228027.58,"id":5300737},{"batb":[[1,4.1,1],[2,3.8,1]],"ltp":5.1,"tv":33554.19,"id":2497008}],"tv":261581.78}]}
{"op":"mcm","clk":"4299754506","pt":1632581931393,"mc":[{"id":"1.188136695","rc":[{"trd":[[1.23,6798.33]],"batl":[[0,1.23,77.03]],"ltp":1.23,"tv":228035.12,"id":5300737}],"tv":261589.32}]}
{"op":"mcm","clk":"4299754770","pt":1632581932802,"mc":[{"id":"1.188136695","rc":[{"trd":[[1.23,6799.42]],"batl":[[0,1.23,75.94],[1,1.25,2689.13],[2,1.28,2.81]],"ltp":1.23,"tv":228036.21,"id":5300737},{"trd":[[5.3,280.86]],"ltp":5.3,"tv":33554.44,"id":2497008}],"tv":261590.66}]}
{"op":"mcm","clk":"4299754964","pt":1632581933728,"mc":[{"id":"1.188136695","rc":[{"trd":[[1.23,6804.42]],"batl":[[0,1.23,73.44],[1,1.24,1159.13],[2,1.25,4019.25]],"ltp":1.23,"tv":228041.21,"id":5300737},{"batb":[[0,5.1,337.5],[1,5,327.58],[2,4.9,327.58]],"batl":[[0,5.6,95.81],[1,5.7,90.26],[2,5.9,291.73]],"ltp":5.3,"tv":33554.44,"id":2497008}],"tv":261595.66}]}
{"op":"mcm","clk":"4299755168","pt":1632581934702,"mc":[{"id":"1.188136695","rc":[{"trd":[[1.23,6916.82]],"batb":[[2,1.2,3366.36]],"batl":[[0,1.24,1159.13],[1,1.25,4019.25],[2,1.26,8]],"ltp":1.23,"tv":228153.62,"id":5300737},{"trd":[[5.3,288.86]],"batb":[[0,5.1,495.27]],"ltp":5.3,"tv":33562.44,"id":2497008}],"tv":261716.07}]}
{"op":"mcm","clk":"4299755238","pt":1632581935136,"mc":[{"id":"1.188136695","rc":[{"batb":[[0,5.2,21.42],[1,5.1,495.27],[2,5,327.58]],"ltp":5.3,"tv":33562.44,"id":2497008}]}]}
{"op":"mcm","clk":"4299755485","pt":1632581936428,"mc":[{"id":"1.188136695","rc":[{"batl":[[0,1.23,3.51],[1,1.24,1651.12],[2,1.25,4658.66]],"ltp":1.23,"tv":228153.62,"id":5300737},{"batb":[[1,5.1,614.89],[2,5,487.43]],"ltp":5.3,"tv":33562.44,"id":2497008}]}]}
{"op":"mcm","clk":"4299755714","pt":1632581937712,"mc":[{"id":"1.188136695","rc":[{"batb":[[0,1.22,3611.33]],"batl":[[0,1.23,15.51],[1,1.24,2435.61],[2,1.25,4191.53]],"ltp":1.23,"tv":228153.62,"id":5300737},{"batb":[[0,5.3,3],[1,5.2,24.42],[2,5.1,614.89]],"batl":[[0,5.6,97.81]],"ltp":5.3,"tv":33562.44,"id":2497008}]}]}
{"op":"mcm","clk":"4299755907","pt":1632581938735,"mc":[{"id":"1.188136695","rc":[{"trd":[[1.22,3711.96]],"batb":[[0,1.22,3602.56]],"batl":[[0,1.23,105.51]],"ltp":1.22,"tv":228171.16,"id":5300737},{"batb":[[2,5.1,669.6]],"ltp":5.3,"tv":33562.44,"id":2497008}],"tv":261733.61}]}
{"op":"mcm","clk":"4299756017","pt":1632581939328,"mc":[{"id":"1.188136695","rc":[{"trd":[[1.23,7127.84]],"batb":[[0,1.23,17.78],[1,1.22,3602.56],[2,1.21,2923.55]],"batl":[[0,1.24,2435.61],[1,1.25,1969.53],[2,1.26,8]],"ltp":1.23,"tv":228382.18,"id":5300737}],"tv":261944.63}]}
{"op":"mcm","clk":"4299756217","pt":1632581940525,"mc":[{"id":"1.188136695","rc":[{"batb":[[0,1.23,18.13],[2,1.21,3518.24]],"ltp":1.23,"tv":228382.18,"id":5300737},{"batl":[[2,5.8,13.12]],"ltp":5.3,"tv":33562.44,"id":2497008}]}]}
{"op":"mcm","clk":"4299756381","pt":1632581941331,"mc":[{"id":"1.188136695","rc":[{"batb":[[0,1.23,18.16]],"ltp":1.23,"tv":228382.18,"id":5300737}]}]}
{"op":"mcm","clk":"4299756631","pt":1632581942521,"mc":[{"id":"1.188136695","rc":[{"trd":[[1.24,11513.16]],"batb":[[2,1.21,2565.98]],"batl":[[0,1.24,2525.57]],"ltp":1.24,"tv":228382.26,"id":5300737}],"tv":261944.71}]}
{"op":"mcm","clk":"4299756901","pt":1632581943820,"mc":[{"id":"1.188136695","rc":[{"batb":[[0,1.23,19.92]],"ltp":1.24,"tv":228382.26,"id":5300737}]}]}
{"op":"mcm","clk":"4299757087","pt":1632581944610,"mc":[{"id":"1.188136695","rc":[{"batb":[[0,1.23,2.14]],"ltp":1.24,"tv":228382.26,"id":5300737}]}]}
{"op":"mcm","clk":"4299757479","pt":1632581946719,"mc":[{"id":"1.188136695","rc":[{"trd":[[5.3,292.38]],"batb":[[0,5.2,24.42],[1,5.1,669.6],[2,5,487.43]],"ltp":5.3,"tv":33565.96,"id":2497008}],"tv":261948.23}]}
{"op":"mcm","clk":"4299757611","pt":1632581947543,"mc":[{"id":"1.188136695","rc":[{"trd":[[1.23,7132.12]],"batb":[[0,1.23,5.42]],"ltp":1.23,"tv":228386.54,"id":5300737}],"tv":261952.5}]}
{"op":"mcm","clk":"4299758010","pt":1632581949629,"mc":[{"id":"1.188136695","rc":[{"trd":[[1.22,3761.98],[1.23,7132.82]],"batb":[[0,1.22,3577.55],[1,1.21,2565.98],[2,1.2,3686.85]],"ltp":1.22,"tv":228437.26,"id":5300737},{"batb":[[1,5.1,672.6]],"ltp":5.3,"tv":33565.96,"id":2497008}],"tv":262003.23}]}
{"op":"mcm","clk":"4299758221","pt":1632581950762,"mc":[{"id":"1.188136695","rc":[{"batb":[[0,1.23,2.54],[1,1.22,3577.55],[2,1.21,2565.98]],"batl":[[2,1.26,9.71]],"ltp":1.22,"tv":228437.26,"id":5300737}]}]}
{"op":"mcm","clk":"4299758430","pt":1632581951782,"mc":[{"id":"1.188136695","rc":[{"batb":[[0,1.23,6.07]],"ltp":1.22,"tv":228437.26,"id":5300737}]}]}
{"op":"mcm","clk":"4299758806","pt":1632581953773,"mc":[{"id":"1.188136695","rc":[{"trd":[[1.24,11516.68]],"batb":[[1,1.22,1288],[2,1.21,594.69]],"batl":[[0,1.24,90],[1,1.26,9.71],[2,1.28,256.34]],"ltp":1.24,"tv":228440.78,"id":5300737},{"batb":[[0,5.2,21.42],[1,5.1,157.77],[2,4.8,2]],"batl":[[0,5.8,13.12],[1,5.9,53.03],[2,6,78.03]],"ltp":5.3,"tv":33565.96,"id":2497008}],"tv":262006.75}]}
{"op":"mcm","clk":"4299758998","pt":1632581954735,"mc":[{"id":"1.188136695","rc":[{"trd":[[1.24,11520.1]],"batb":[[1,1.21,8.57],[2,1.2,3271.99]],"batl":[[0,1.26,1.71],[1,1.28,256.34],[2,1.29,274.84]],"ltp":1.24,"tv":228444.21,"id":5300737},{"batb":[[1,4.6,197.34],[2,4.5,55.94]],"batl":[[0,5.9,53.03],[1,6,78.03],[2,6.2,77.71]],"ltp":5.3,"tv":33565.96,"id":2497008}],"tv":262010.17}]}
{"op":"mcm","clk":"4299759207","pt":1632581955794,"mc":[{"id":"1.188136695","rc":[{"trd":[[1.21,10211.51],[1.23,7138.72]],"batb":[[0,1.2,3271.99],[1,1.19,1841.06],[2,1.18,1327.89]],"ltp":1.21,"tv":228458.67,"id":5300737},{"trd":[[5.4,12.88],[5.8,104.5],[5.9,19.78]],"batb":[[0,4.6,197.34],[1,4.5,55.94],[2,4.4,95.66]],"batl":[[0,5.9,45.13]],"ltp":5.9,"tv":33586.87,"id":2497008}],"tv":262045.55}]}
{"op":"mcm","clk":"4299759391","pt":1632581956790,"mc":[{"id":"1.188136695","rc":[{"batb":[[0,1.24,2.35],[1,1.2,4866.07],[2,1.19,3769.61]],"batl":[[1,1.27,1145.88],[2,1.28,1410.96]],"ltp":1.21,"tv":228458.67,"id":5300737}]}]}
{"op":"mcm","clk":"4299759576","pt":1632581957765,"mc":[{"id":"1.188136695","rc":[{"batb":[[0,1.24,9.36],[1,1.21,567.69],[2,1.2,4866.07]],"batl":[[2,1.28,1159.14]],"ltp":1.21,"tv":228458.67,"id":5300737},{"batb":[[1,4.1,1],[2,3.8,1]],"batl":[[0,5.2,1.3],[1,5.8,13.26],[2,5.9,44.14]],"ltp":5.9,"tv":33586.87,"id":2497008}]}]}
{"op":"mcm","clk":"4299759696","pt":1632581958405,"mc":[{"id":"1.188136695","rc":[{"batb":[[1,1.2,4866.07],[2,1.19,3769.61]],"batl":[[1,1.27,7.46],[2,1.28,4.06]],"ltp":1.21,"tv":228458.67,"id":5300737},{"batb":[[0,4.6,199.34],[1,4.5,3],[2,4.1,1]],"batl":[[0,5.2,2.63],[1,5.9,45.13],[2,6,78.03]],"ltp":5.9,"tv":33586.87,"id":2497008}]}]}
{"op":"mcm","clk":"4299759981","pt":1632581959787,"mc":[{"id":"1.188136695","rc":[{"trd":[[1.23,7154.06],[1.24,11538.82]],"batb":[[0,1.2,4873.07],[1,1.19,3776.61],[2,1.18,1327.89]],"batl":[[0,1.22,467.13],[1,1.23,2222],[2,1.26,1.71]],"ltp":1.23,"tv":228492.73,"id":5300737},{"trd":[[5.2,40.43],[5.3,293.36]],"batb":[[0,4.7,3],[1,4.6,199.34],[2,4.5,3]],"batl":[[0,5.9,47.14],[1,6,78.03],[2,6.2,77.71]],"ltp":5.3,"tv":33590.48,"id":2497008}],"tv":262083.22}]}
{"op":"mcm","clk":"4299760168","pt":1632581960659,"mc":[{"id":"1.188136695","rc":[{"batb":[[0,5.4,1115.62],[1,5.3,1082.81],[2,5.2,1082.81]],"ltp":5.3,"tv":33590.48,"id":2497008}]}]}
{"op":"mcm","clk":"4299760381","pt":1632581961775,"mc":[{"id":"1.188136695","rc":[{"trd":[[1.21,10219.51],[1.22,3788.36]],"batb":[[1,1.19,5298.69]],"batl":[[0,1.22,1040.2],[1,1.23,3699.24],[2,1.24,6.42]],"ltp":1.22,"tv":228527.11,"id":5300737},{"trd":[[5.5,38.69],[5.7,291],[5.8,110.5],[5.9,21.78]],"batb":[[0,5.4,457.32],[1,5.3,309.37],[2,5.2,309.37]],"batl":[[0,5.9,46.14]],"ltp":5.5,"tv":33606.04,"id":2497008}],"tv":262133.15}]}
{"op":"mcm","clk":"4299760598","pt":1632581962804,"mc":[{"id":"1.188136695","rc":[{"batl":[[0,1.22,1130.2],[1,1.23,3702.25]],"ltp":1.22,"tv":228527.11,"id":5300737},{"batb":[[0,5.5,20],[1,5.4,457.32],[2,5.3,309.37]],"ltp":5.5,"tv":33606.04,"id":2497008}]}]}
{"op":"mcm","clk":"4299760769","pt":1632581963691,"mc":[{"id":"1.188136695","rc":[{"batb":[[0,1.2,4917.79]],"batl":[[1,1.23,1480.25]],"ltp":1.22,"tv":228527.11,"id":5300737}]}]}
{"op":"mcm","clk":"4299760965","pt":1632581964596,"mc":[{"id":"1.188136695","rc":[{"batb":[[1,5.4,473.39]],"ltp":5.5,"tv":33606.04,"id":2497008}]}]}
{"op":"mcm","clk":"4299761230","pt":1632581965683,"mc":[{"id":"1.188136695","rc":[{"batb":[[0,1.2,5635.29]],"batl":[[0,1.22,2050.63],[1,1.23,1480.77]],"ltp":1.22,"tv":228527.11,"id":5300737},{"batb":[[0,5.5,23],[1,5.4,475.39]],"batl":[[2,6.2,91.6]],"ltp":5.5,"tv":33606.04,"id":2497008}]}]}
{"op":"mcm","clk":"4299761479","pt":1632581966684,"mc":[{"id":"1.188136695","rc":[{"batb":[[1,1.19,5302.2]],"batl":[[0,1.22,1974.74],[1,1.23,2195.6]],"ltp":1.22,"tv":228527.11,"id":5300737},{"batb":[[0,5.5,158.05],[2,5.3,475.27]],"batl":[[2,6.2,77.71]],"ltp":5.5,"tv":33606.04,"id":2497008}]}]}
{"op":"mcm","clk":"4299761680","pt":1632581967691,"mc":[{"id":"1.188136695","rc":[{"trd":[[1.22,3795.92]],"batl":[[0,1.22,1970.96]],"ltp":1.22,"tv":228534.67,"id":5300737}],"tv":262140.71}]}
{"op":"mcm","clk":"4299761904","pt":1632581968796,"mc":[{"id":"1.188136695","rc":[{"batb":[[0,1.2,5929.52],[1,1.19,5641.78],[2,1.18,1687.97]],"batl":[[0,1.21,2.54],[1,1.22,1970.96],[2,1.23,2195.6]],"ltp":1.22,"tv":228534.67,"id":5300737},{"trd":[[5.9,25.04]],"batb":[[1,5.4,459.32]],"batl":[[0,5.9,44.51],[1,6,131.02],[2,6.2,134.47]],"ltp":5.9,"tv":33609.29,"id":2497008}],"tv":262143.97}]}
{"op":"mcm","clk":"4299762356","pt":1632581970766,"mc":[{"id":"1.188136695","rc":[{"batb":[[1,1.19,5638.27]],"ltp":1.22,"tv":228534.67,"id":5300737}]}]}
{"op":"mcm","clk":"4299762571","pt":1632581971702,"mc":[{"id":"1.188136695","rc":[{"trd":[[1.21,10224.59],[1.22,3862.59]],"batb":[[0,1.2,1820.01],[1,1.19,5065.57],[2,1.18,1312.34]],"batl":[[0,1.22,102.18],[1,1.23,3.53],[2,1.26,218.72]],"ltp":1.22,"tv":228606.42,"id":5300737},{"batb":[[0,5.5,23],[1,5.4,2],[2,5,167.24]],"batl":[[0,5.9,3],[1,6,66.02],[2,6.2,56.76]],"ltp":5.9,"tv":33609.29,"id":2497008}],"tv":262215.72}]}
{"op":"mcm","clk":"4299762788","pt":1632581972793,"mc":[{"id":"1.188136695","rc":[{"trd":[[1.22,3881.27]],"batb":[[0,1.21,20],[1,1.2,1820.01],[2,1.19,5065.57]],"batl":[[0,1.23,3.53],[1,1.24,1.71]],"ltp":1.22,"tv":228625.1,"id":5300737},{"batb":[[0,5,167.24],[1,4.9,71.34],[2,4.8,84.37]],"batl":[[0,6,66.02],[1,6.2,56.76],[2,6.4,85.02]],"ltp":5.9,"tv":33609.29,"id":2497008}],"tv":262234.4}]}
{"op":"mcm","clk":"4299762962","pt":1632581973604,"mc":[{"id":"1.188136695","rc":[{"trd":[[1.21,10226.25]],"batb":[[0,1.21,20.22]],"batl":[[0,1.24,2.23],[1,1.26,218.72],[2,1.27,302.15]],"ltp":1.21,"tv":228626.76,"id":5300737}],"tv":262236.06}]}
{"op":"mcm","clk":"4299763228","pt":1632581974800,"mc":[{"id":"1.188136695","rc":[{"trd":[[1.21,10233.11],[1.22,3882.29]],"batb":[[0,1.21,16.79],[2,1.19,5078.57]],"batl":[[0,1.24,913.37],[1,1.25,1331.16],[2,1.26,218.72]],"ltp":1.21,"tv":228634.64,"id":5300737},{"batl":[[0,6,66.37]],"ltp":5.9,"tv":33609.29,"id":2497008}],"tv":262243.94}]}
{"op":"mcm","clk":"4299763314","pt":1632581975203,"mc":[{"id":"1.188136695","rc":[{"batb":[[2,1.19,4732.41]],"batl":[[1,1.26,218.72],[2,1.27,302.15]],"ltp":1.21,"tv":228634.64,"id":5300737},{"batl":[[0,6,68.37]],"ltp":5.9,"tv":33609.29,"id":2497008}]}]}
{"op":"mcm","clk":"4299763605","pt":1632581976491,"mc":[{"id":"1.188136695","rc":[{"batl":[[0,1.24,922.37],[1,1.25,9],[2,1.26,218.72]],"ltp":1.21,"tv":228634.64,"id":5300737},{"batb":[[0,5,169.24],[1,4.9,74.34]],"ltp":5.9,"tv":33609.29,"id":2497008}]}]}
{"op":"mcm","clk":"4299763772","pt":1632581977397,"mc":[{"id":"1.188136695","rc":[{"trd":[[1.21,10266.69],[1.22,3883.87]],"batb":[[0,1.2,1820.01],[1,1.19,4732.41],[2,1.18,360.08]],"batl":[[0,1.21,204.73],[1,1.24,922.37],[2,1.25,9]],"ltp":1.21,"tv":228669.8,"id":5300737},{"trd":[[5.5,39.04]],"batb":[[0,5.1,3],[1,5,169.24],[2,4.9,74.34]],"batl":[[0,6,68.02]],"ltp":5.5,"tv":33609.64,"id":2497008}],"tv":262279.45}]}
{"op":"mcm","clk":"4299764053","pt":1632581978809,"mc":[{"id":"1.188136695","rc":[{"trd":[[1.2,9733.33],[1.21,10267.64]],"batb":[[0,1.2,3967.24]],"batl":[[0,1.21,14334.02],[1,1.23,1581.1],[2,1.24,1390.36]],"ltp":1.21,"tv":228672.68,"id":5300737},{"trd":[[5.8,150.84]],"batb":[[0,5.8,6.77],[1,5.7,545.94],[2,5.6,13.47]],"ltp":5.8,"tv":33649.98,"id":2497008}],"tv":262322.67}]}
{"op":"mcm","clk":"4299764241","pt":1632581979728,"mc":[{"id":"1.188136695","rc":[{"batb":[[0,1.2,1819.04]],"batl":[[0,1.21,204.26],[1,1.24,922.37],[2,1.25,9]],"ltp":1.21,"tv":228672.68,"id":5300737}]}]}
{"op":"mcm","clk":"4299764466","pt":1632581980803,"mc":[{"id":"1.188136695","rc":[{"trd":[[1.21,10275.7]],"batl":[[0,1.21,200.22]],"ltp":1.21,"tv":228680.74,"id":5300737}],"tv":262330.73}]}
{"op":"mcm","clk":"4299764525","pt":1632581981137,"mc":[{"id":"1.188136695","rc":[{"trd":[[1.21,10315.7]],"batb":[[1,1.19,3362.63]],"batl":[[0,1.21,180.22],[1,1.24,10.71]],"ltp":1.21,"tv":228720.74,"id":5300737}],"tv":262370.73}]}
{"op":"mcm","clk":"4299765031","pt":1632581983629,"mc":[{"id":"1.188136695","rc":[{"batb":[[0,1.2,1526.78],[1,1.19,3023.25],[2,1.17,8.57]],"ltp":1.21,"tv":228720.74,"id":5300737},{"batl":[[0,6,15.03],[1,6.4,12.29],[2,7.8,1]],"ltp":5.8,"tv":33649.98,"id":2497008}]}]}
{"op":"mcm","clk":"4299765197","pt":1632581984444,"mc":[{"id":"1.188136695","rc":[{"trd":[[1.2,9734.39],[1.21,10322.72]],"batb":[[0,1.2,1526.25]],"batl":[[0,1.21,176.71]],"ltp":1.21,"tv":228728.82,"id":5300737},{"trd":[[5.8,158.16]],"batb":[[0,5.8,3.11]],"ltp":5.8,"tv":33657.3,"id":2497008}],"tv":262386.13}]}
{"op":"mcm","clk":"4299765433","pt":1632581985531,"mc":[{"id":"1.188136695","rc":[{"trd":[[1.21,10691.05],[1.22,4979.9]],"batb":[[0,1.2,8.97]],"batl":[[0,1.24,10.71],[1,1.25,9],[2,1.26,218.72]],"ltp":1.22,"tv":230193.18,"id":5300737},{"trd":[[5.7,524.75],[5.8,161.27]],"batb":[[0,5.7,312.19],[1,5.6,13.47],[2,5.1,3]],"batl":[[0,6,2]],"ltp":5.7,"tv":33894.16,"id":2497008}],"tv":264087.35}]}
{"op":"mcm","clk":"4299765676","pt":1632581986701,"mc":[{"id":"1.188136695","rc":[{"trd":[[1.22,6500.32],[1.24,11558.71]],"batb":[[0,1.22,937.9],[1,1.21,2225.67],[2,1.2,267.23]],"batl":[[0,1.24,889.02],[1,1.25,1346.52]],"ltp":1.24,"tv":231733.49,"id":5300737},{"trd":[[5.1,335.01],[5.6,16.09],[5.7,836.94]],"batb":[[0,5,169.24],[1,4.9,74.34],[2,4.8,84.37]],"batl":[[1,6.2,101.48],[2,6.4,12.29]],"ltp":5.1,"tv":34230.66,"id":2497008}],"tv":265964.15}]}
{"op":"mcm","clk":"4299765883","pt":1632581987740,"mc":[{"id":"1.188136695","rc":[{"batb":[[0,1.22,2209.71],[1,1.21,3607.93]],"ltp":1.24,"tv":231733.49,"id":5300737},{"batb":[[0,5,325.49],[1,4.9,152.46],[2,4.8,162.49]],"batl":[[0,5.8,3.02],[1,6,2],[2,6.2,101.48]],"ltp":5.1,"tv":34230.66,"id":2497008}]}]}
{"op":"mcm","clk":"4299766080","pt":1632581988826,"mc":[{"id":"1.188136695","rc":[{"batb":[[0,1.22,2211.47],[1,1.21,3676.06]],"batl":[[0,1.24,1019.45]],"ltp":1.24,"tv":231733.49,"id":5300737},{"batb":[[0,5.2,21.42],[1,5,325.49],[2,4.9,149.46]],"batl":[[0,6,2.35],[1,6.2,101.48],[2,6.4,12.29]],"ltp":5.1,"tv":34230.66,"id":2497008}]}]}
{"op":"mcm","clk":"4299766186","pt":1632581989245,"mc":[{"id":"1.188136695","rc":[{"batb":[[1,1.21,3678.65]],"ltp":1.24,"tv":231733.49,"id":5300737},{"batb":[[1,5.1,13.11],[2,5,325.49]],"ltp":5.1,"tv":34230.66,"id":2497008}]}]}
{"op":"mcm","clk":"4299766508","pt":1632581990806,"mc":[{"id":"1.188136695","rc":[{"trd":[[1.22,6503.26],[1.24,11558.79]],"batb":[[0,1.22,3132.45],[1,1.21,3680.96]],"batl":[[0,1.24,1938.98]],"ltp":1.24,"tv":231736.51,"id":5300737}],"tv":265967.18}]}
{"op":"mcm","clk":"4299766682","pt":1632581991735,"mc":[{"id":"1.188136695","rc":[{"batb":[[1,1.21,3681.31]],"ltp":1.24,"tv":231736.51,"id":5300737},{"batb":[[0,5.2,24.42],[1,5.1,16.11]],"batl":[[0,5.8,15.78],[1,6,2],[2,6.2,140.94]],"ltp":5.1,"tv":34230.66,"id":2497008}]}]}
{"op":"mcm","clk":"4299766863","pt":1632581992618,"mc":[{"id":"1.188136695","rc":[{"batb":[[1,1.21,3680.92]],"ltp":1.24,"tv":231736.51,"id":5300737},{"batl":[[0,6,2.35],[1,6.2,140.94],[2,6.4,12.29]],"ltp":5.1,"tv":34230.66,"id":2497008}]}]}
{"op":"mcm","clk":"4299767051","pt":1632581993620,"mc":[{"id":"1.188136695","rc":[{"trd":[[1.22,6503.3]],"batb":[[0,1.22,3132.43],[1,1.21,4512.22],[2,1.2,1149.37]],"batl":[[0,1.24,1939.49]],"ltp":1.22,"tv":231736.55,"id":5300737},{"batl":[[0,5.8,61.84],[1,5.9,58.36],[2,6,494.66]],"ltp":5.1,"tv":34230.66,"id":2497008}],"tv":265967.22}]}
{"op":"mcm","clk":"4299767488","pt":1632581995643,"mc":[{"id":"1.188136695","rc":[{"trd":[[1.23,7154.76]],"batl":[[0,1.23,14.78],[1,1.24,1938.98],[2,1.25,1346.52]],"ltp":1.23,"tv":231737.25,"id":5300737},{"batl":[[0,5.5,1.37],[1,5.8,61.84],[2,5.9,58.36]],"ltp":5.1,"tv":34230.66,"id":2497008}],"tv":265967.92}]}
{"op":"mcm","clk":"4299768103","pt":1632581998736,"mc":[{"id":"1.188136695","rc":[{"batb":[[0,1.22,1.76],[1,1.21,2224.14],[2,1.2,884.11]],"batl":[[0,1.23,23.78],[1,1.24,90],[2,1.26,1.71]],"ltp":1.23,"tv":231737.25,"id":5300737},{"batb":[[0,5.3,2],[1,5.2,21.42],[2,4.5,287.99]],"batl":[[1,5.7,15.43],[2,5.8,61.84]],"ltp":5.1,"tv":34230.66,"id":2497008}]}]}
{"op":"mcm","clk":"4299768311","pt":1632581999741,"mc":[{"id":"1.188136695","rc":[{"batb":[[2,1.2,886.3]],"batl":[[0,1.23,24.78]],"ltp":1.23,"tv":231737.25,"id":5300737},{"batb":[[0,5.2,21.42],[1,4.5,287.99],[2,4.4,64.96]],"batl":[[1,5.8,61.84],[2,5.9,58.36]],"ltp":5.1,"tv":34230.66,"id":2497008}]}]}
{"op":"mcm","clk":"4299768376","pt":1632582000068,"mc":[{"id":"1.188136695","rc":[{"batb":[[0,1.22,1.41]],"batl":[[1,1.26,1.71],[2,1.28,7.85]],"ltp":1.23,"tv":231737.25,"id":5300737},{"batb":[[0,4.5,287.99],[1,4.4,64.96],[2,4.3,80.15]],"ltp":5.1,"tv":34230.66,"id":2497008}]}]}
{"op":"mcm","clk":"4299768791","pt":1632582001760,"mc":[{"id":"1.188136695","rc":[{"batb":[[2,1.2,2733.91]],"batl":[[0,1.23,14.78],[2,1.27,995.74]],"ltp":1.23,"tv":231737.25,"id":5300737}]}]}
{"op":"mcm","clk":"4299769047","pt":1632582002759,"mc":[{"id":"1.188136695","rc":[{"batb":[[0,4.5,210.7],[1,4.1,1],[2,3.8,1]],"batl":[[0,5.5,54.47]],"ltp":5.1,"tv":34230.66,"id":2497008}]}]}
{"op":"mcm","clk":"4299769365","pt":1632582003742,"mc":[{"id":"1.188136695","rc":[{"trd":[[1.22,6509.71],[1.23,7156.27]],"batb":[[0,1.21,2224.14],[1,1.2,2733.91],[2,1.19,3480.23]],"batl":[[0,1.23,13.27],[2,1.28,7.85]],"ltp":1.22,"tv":231745.17,"id":5300737},{"trd":[[5.3,293.71],[5.5,39.84]],"batl":[[0,5.5,53.67]],"ltp":5.5,"tv":34231.81,"id":2497008}],"tv":265976.98}]}
{"op":"mcm","clk":"4299769663","pt":1632582004788,"mc":[{"id":"1.188136695","rc":[{"trd":[[1.22,6751.67]],"batl":[[0,1.22,2689.13],[1,1.23,13.27],[2,1.26,1.71]],"ltp":1.22,"tv":231987.13,"id":5300737},{"trd":[[5.5,93.51]],"batl":[[0,5.8,61.84],[1,5.9,58.36],[2,6,99.97]],"ltp":5.5,"tv":34285.48,"id":2497008}],"tv":266272.61}]}
{"op":"mcm","clk":"4299769928","pt":1632582005758,"mc":[{"id":"1.188136695","rc":[{"batl":[[1,1.23,1860.69],[2,1.24,1379.05]],"ltp":1.22,"tv":231987.13,"id":5300737},{"batb":[[0,5.4,318.74],[1,5.3,309.37],[2,5.2,309.37]],"ltp":5.5,"tv":34285.48,"id":2497008}]}]}
{"op":"mcm","clk":"4299770171","pt":1632582006759,"mc":[{"id":"1.188136695","rc":[{"trd":[[1.22,6794.14]],"batl":[[0,1.22,2650.52]],"ltp":1.22,"tv":232029.6,"id":5300737},{"trd":[[5.5,102.93]],"batb":[[2,5.2,457.08]],"ltp":5.5,"tv":34294.9,"id":2497008}],"tv":266324.5}]}
{"op":"mcm","clk":"4299770448","pt":1632582007815,"mc":[{"id":"1.188136695","rc":[{"trd":[[1.21,10723.05]],"batb":[[0,1.21,2208.14]],"batl":[[0,1.22,3.86],[1,1.23,3221.34]],"ltp":1.21,"tv":232061.6,"id":5300737},{"trd":[[5.8,169.27]],"batl":[[0,5.8,57.84]],"ltp":5.8,"tv":34302.9,"id":2497008}],"tv":266364.5}]}
{"op":"mcm","clk":"4299770892","pt":1632582009773,"mc":[{"id":"1.188136695","rc":[{"batb":[[0,1.21,2220.14],[1,1.2,2744.91]],"batl":[[1,1.23,3837.61],[2,1.24,2185.6]],"ltp":1.21,"tv":232061.6,"id":5300737},{"batb":[[0,5.5,3],[1,5.4,320.74],[2,5.3,452.39]],"batl":[[0,5.8,59.84]],"ltp":5.8,"tv":34302.9,"id":2497008}]}]}
{"op":"mcm","clk":"4299771133","pt":1632582010760,"mc":[{"id":"1.188136695","rc":[{"trd":[[1.21,10724.09]],"batb":[[0,1.21,3122.92],[1,1.2,2745.23],[2,1.19,3686.7]],"batl":[[0,1.22,896.25],[1,1.23,3431.9]],"ltp":1.21,"tv":232062.64,"id":5300737},{"batb":[[0,5.4,320.74],[1,5.3,452.39],[2,5.2,457.08]],"ltp":5.8,"tv":34302.9,"id":2497008}],"tv":266365.54}]}
{"op":"mcm","clk":"4299771400","pt":1632582011673,"mc":[{"id":"1.188136695","rc":[{"trd":[[1.22,6795.63]],"batl":[[0,1.22,901.14],[2,1.24,2275.6]],"ltp":1.22,"tv":232064.13,"id":5300737},{"trd":[[5.5,103.26]],"batb":[[0,5.4,332.87],[1,5.3,473.32]],"ltp":5.5,"tv":34303.23,"id":2497008}],"tv":266367.36}]}
{"op":"mcm","clk":"4299771578","pt":1632582012558,"mc":[{"id":"1.188136695","rc":[{"trd":[[1.22,6805.02]],"batl":[[0,1.23,3431.9],[1,1.24,2275.6],[2,1.26,1.71]],"ltp":1.22,"tv":232073.52,"id":5300737},{"trd":[[5.4,20.42],[5.5,104.68]],"batb":[[0,5.4,329.1]],"ltp":5.4,"tv":34312.19,"id":2497008}],"tv":266385.72}]}
{"op":"mcm","clk":"4299771815","pt":1632582013690,"mc":[{"id":"1.188136695","rc":[{"batb":[[0,1.22,18.86],[1,1.21,3122.91],[2,1.2,2745.23]],"ltp":1.22,"tv":232073.52,"id":5300737},{"batb":[[1,5.3,476.32]],"ltp":5.4,"tv":34312.19,"id":2497008}]}]}
{"op":"mcm","clk":"4299772018","pt":1632582014490,"mc":[{"id":"1.188136695","rc":[{"trd":[[1.22,6849.45]],"batb":[[0,1.21,3122.91],[1,1.2,2745.23],[2,1.19,3686.7]],"batl":[[0,1.22,930.04],[1,1.23,3431.9],[2,1.24,2275.6]],"ltp":1.22,"tv":232117.96,"id":5300737}],"tv":266430.15}]}
{"op":"mcm","clk":"4299772327","pt":1632582015793,"mc":[{"id":"1.188136695","rc":[{"trd":[[1.22,6903.9]],"batl":[[0,1.22,902.82],[1,1.23,4741.15]],"ltp":1.22,"tv":232172.4,"id":5300737}],"tv":266484.6}]}
{"op":"mcm","clk":"4299772555","pt":1632582016678,"mc":[{"id":"1.188136695","rc":[{"trd":[[1.22,6923.9]],"batl":[[0,1.22,892.82],[1,1.23,3443.9]],"ltp":1.22,"tv":232192.41,"id":5300737},{"batl":[[0,5.6,2],[1,5.8,59.84],[2,5.9,58.36]],"ltp":5.4,"tv":34312.19,"id":2497008}],"tv":266504.6}]}
{"op":"mcm","clk":"4299772703","pt":1632582017291,"mc":[{"id":"1.188136695","rc":[{"batb":[[0,1.21,3141.92]],"batl":[[0,1.23,3443.9],[1,1.24,2275.6],[2,1.26,1.71]],"ltp":1.22,"tv":232192.41,"id":5300737},{"batl":[[0,5.8,59.84],[1,5.9,58.36],[2,6,99.97]],"ltp":5.4,"tv":34312.19,"id":2497008}]}]}
{"op":"mcm","clk":"4299773150","pt":1632582018790,"mc":[{"id":"1.188136695","rc":[{"batb":[[0,1.21,3171.03]],"ltp":1.22,"tv":232192.41,"id":5300737}]}]}
{"op":"mcm","clk":"4299773392","pt":1632582019777,"mc":[{"id":"1.188136695","rc":[{"batb":[[0,1.21,3172.93]],"ltp":1.22,"tv":232192.41,"id":5300737},{"batl":[[0,5.5,5.12],[1,5.8,59.84],[2,5.9,58.36]],"ltp":5.4,"tv":34312.19,"id":2497008}]}]}
{"op":"mcm","clk":"4299773651","pt":1632582020781,"mc":[{"id":"1.188136695","rc":[{"batb":[[0,1.22,68.02],[1,1.21,3182.15],[2,1.2,2744.91]],"batl":[[0,1.23,5615.64]],"ltp":1.22,"tv":232192.41,"id":5300737},{"trd":[[5.5,133.17]],"batb":[[0,5.5,74.04],[1,5.4,441.38],[2,5.3,476.32]],"batl":[[0,5.8,59.84],[1,5.9,58.36],[2,6,99.97]],"ltp":5.5,"tv":34340.68,"id":2497008}],"tv":266533.09}]}
{"op":"mcm","clk":"4299773842","pt":1632582021688,"mc":[{"id":"1.188136695","rc":[{"batb":[[0,1.22,189.16]],"batl":[[0,1.23,5283.86]],"ltp":1.22,"tv":232192.41,"id":5300737},{"batb":[[0,5.4,441.38],[1,5.3,476.32],[2,5.2,457.08]],"ltp":5.5,"tv":34340.68,"id":2497008}]}]}
{"op":"mcm","clk":"4299774066","pt":1632582022674,"mc":[{"id":"1.188136695","rc":[{"batl":[[0,1.23,4331.6]],"ltp":1.22,"tv":232192.41,"id":5300737}]}]}
{"op":"mcm","clk":"4299774159","pt":1632582023164,"mc":[{"id":"1.188136695","rc":[{"batb":[[0,1.22,187.79],[2,1.2,2733.91]],"ltp":1.22,"tv":232192.41,"id":5300737}]}]}
{"op":"mcm","clk":"4299774537","pt":1632582024787,"mc":[{"id":"1.188136695","rc":[{"trd":[[1.23,7156.29]],"batb":[[0,1.22,196.36]],"batl":[[0,1.23,4331.59]],"ltp":1.23,"tv":232192.42,"id":5300737}],"tv":266533.1}]}
{"op":"mcm","clk":"4299774719","pt":1632582025508,"mc":[{"id":"1.188136695","rc":[{"batb":[[0,1.22,215.64]],"ltp":1.23,"tv":232192.42,"id":5300737},{"batl":[[0,5.7,10],[1,5.8,59.84],[2,5.9,58.36]],"ltp":5.5,"tv":34340.68,"id":2497008}]}]}
{"op":"mcm","clk":"4299774934","pt":1632582026482,"mc":[{"id":"1.188136695","rc":[{"batb":[[1,5.3,473.32]],"ltp":5.5,"tv":34340.68,"id":2497008}]}]}
{"op":"mcm","clk":"4299775154","pt":1632582027361,"mc":[{"id":"1.188136695","rc":[{"batb":[[0,1.22,215.47]],"ltp":1.23,"tv":232192.42,"id":5300737}]}]}
{"op":"mcm","clk":"4299775275","pt":1632582027966,"mc":[{"id":"1.188136695","rc":[{"batb":[[0,1.22,215.56]],"ltp":1.23,"tv":232192.42,"id":5300737}]}]}
{"op":"mcm","clk":"4299775643","pt":1632582029688,"mc":[{"id":"1.188136695","rc":[{"batb":[[0,1.22,215.64]],"ltp":1.23,"tv":232192.42,"id":5300737},{"batb":[[1,5.3,475.32]],"ltp":5.5,"tv":34340.68,"id":2497008}]}]}
{"op":"mcm","clk":"4299775828","pt":1632582030466,"mc":[{"id":"1.188136695","rc":[{"batb":[[1,1.21,3750.67]],"ltp":1.23,"tv":232192.42,"id":5300737},{"batl":[[0,5.6,58.28],[1,5.7,73.43],[2,5.8,59.84]],"ltp":5.5,"tv":34340.68,"id":2497008}]}]}
{"op":"mcm","clk":"4299776179","pt":1632582031772,"mc":[{"id":"1.188136695","rc":[{"trd":[[1.22,7043.91]],"batb":[[0,1.22,165.21],[2,1.2,2731.72]],"ltp":1.22,"tv":232312.43,"id":5300737},{"batl":[[0,5.6,60.28]],"ltp":5.5,"tv":34340.68,"id":2497008}],"tv":266653.11}]}
{"op":"mcm","clk":"4299776358","pt":1632582032587,"mc":[{"id":"1.188136695","rc":[{"trd":[[1.23,7195.72]],"batb":[[0,1.22,165.13]],"batl":[[0,1.23,4311.88]],"ltp":1.23,"tv":232351.86,"id":5300737}],"tv":266692.54}]}
{"op":"mcm","clk":"4299776640","pt":1632582033782,"mc":[{"id":"1.188136695","rc":[{"trd":[[1.23,7198.46]],"batb":[[0,1.22,155.52],[1,1.21,71.7],[2,1.2,1.97]],"batl":[[0,1.24,90],[1,1.26,1.71],[2,1.28,237.86]],"ltp":1.23,"tv":232354.6,"id":5300737},{"trd":[[5.4,20.54]],"batb":[[0,5.3,20.93],[1,4.7,186.86],[2,4.6,61.11]],"batl":[[0,5.7,10],[1,6.2,39.77],[2,6.8,62.54]],"ltp":5.4,"tv":34340.8,"id":2497008}],"tv":266695.4}]}
{"op":"mcm","clk":"4299776864","pt":1632582034786,"mc":[{"id":"1.188136695","rc":[{"batb":[[0,1.23,3.25],[1,1.22,219.1],[2,1.21,71.7]],"batl":[[0,1.26,1.71],[1,1.28,237.86],[2,1.29,234.16]],"ltp":1.23,"tv":232354.6,"id":5300737},{"batb":[[0,4.7,186.86],[1,4.6,61.11],[2,4.5,84.89]],"batl":[[1,6.8,62.85],[2,7,56.11]],"ltp":5.4,"tv":34340.8,"id":2497008}]}]}
{"op":"mcm","clk":"4299777347","pt":1632582036777,"mc":[{"id":"1.188136695","rc":[{"batb":[[0,1.23,8.38]],"batl":[[0,1.26,1260.46],[1,1.27,1207.67],[2,1.28,237.4]],"ltp":1.23,"tv":232354.6,"id":5300737},{"batb":[[0,4.8,182.55]],"batl":[[0,5.4,1.4],[1,5.7,10],[2,6.8,62.85]],"ltp":5.4,"tv":34340.8,"id":2497008}]}]}
{"op":"mcm","clk":"4299777586","pt":1632582037801,"mc":[{"id":"1.188136695","rc":[{"trd":[[1.22,7054.23],[1.23,7215.22]],"batb":[[0,1.23,21.14],[1,1.22,213.65]],"ltp":1.22,"tv":232381.69,"id":5300737}],"tv":266722.49}]}
{"op":"mcm","clk":"4299777815","pt":1632582038790,"mc":[{"id":"1.188136695","rc":[{"batb":[[0,1.23,28.47]],"batl":[[2,1.28,241.4]],"ltp":1.22,"tv":232381.69,"id":5300737},{"batb":[[1,4.7,2],[2,4.6,64.11]],"batl":[[0,5.4,1.75]],"ltp":5.4,"tv":34340.8,"id":2497008}]}]}
{"op":"mcm","clk":"4299778021","pt":1632582039701,"mc":[{"id":"1.188136695","rc":[{"batb":[[1,1.22,170.8]],"batl":[[0,1.26,1270.46],[2,1.28,239.05]],"ltp":1.22,"tv":232381.69,"id":5300737},{"batb":[[0,4.8,184.55]],"batl":[[0,5.4,4.49]],"ltp":5.4,"tv":34340.8,"id":2497008}]}]}
{"op":"mcm","clk":"4299778197","pt":1632582040589,"mc":[{"id":"1.188136695","rc":[{"batb":[[1,1.22,172.68]],"batl":[[0,1.25,20],[1,1.26,1270.46],[2,1.27,1207.67]],"ltp":1.22,"tv":232381.69,"id":5300737},{"batl":[[0,5.4,6.84]],"ltp":5.4,"tv":34340.8,"id":2497008}]}]}
{"op":"mcm","clk":"4299778327","pt":1632582041191,"mc":[{"id":"1.188136695","rc":[{"batl":[[0,5.4,4.1]],"ltp":5.4,"tv":34340.8,"id":2497008}]}]}
{"op":"mcm","clk":"4299778629","pt":1632582042657,"mc":[{"id":"1.188136695","rc":[{"trd":[[1.23,7255.22]],"batb":[[0,1.23,26],[1,1.22,172.6]],"batl":[[0,1.25,60]],"ltp":1.23,"tv":232421.69,"id":5300737}],"tv":266762.49}]}
{"op":"mcm","clk":"4299778813","pt":1632582043513,"mc":[{"id":"1.188136695","rc":[{"batb":[[0,1.23,24.86]],"batl":[[0,1.25,85]],"ltp":1.23,"tv":232421.69,"id":5300737}]}]}
{"op":"mcm","clk":"4299779029","pt":1632582044404,"mc":[{"id":"1.188136695","rc":[{"trd":[[1.25,4930.27]],"batl":[[0,1.25,90.65]],"ltp":1.25,"tv":232426.39,"id":5300737}],"tv":266767.19}]}
{"op":"mcm","clk":"4299779240","pt":1632582045218,"mc":[{"id":"1.188136695","rc":[{"batb":[[1,1.22,171.28]],"ltp":1.25,"tv":232426.39,"id":5300737}]}]}
{"op":"mcm","clk":"4299779418","pt":1632582045982,"mc":[{"id":"1.188136695","rc":[{"batl":[[1,6.8,62.85],[2,7,56.11]],"ltp":5.4,"tv":34340.8,"id":2497008}]}]}
{"op":"mcm","clk":"4299779869","pt":1632582047801,"mc":[{"id":"1.188136695","rc":[{"trd":[[1.23,7255.89]],"batb":[[0,1.23,24.52]],"ltp":1.23,"tv":232427.06,"id":5300737},{"batl":[[0,5.4,1.75]],"ltp":5.4,"tv":34340.8,"id":2497008}],"tv":266767.86}]}
{"op":"mcm","clk":"4299780331","pt":1632582049714,"mc":[{"id":"1.188136695","rc":[{"trd":[[1.25,4930.44]],"batl":[[0,1.25,90.57]],"ltp":1.25,"tv":232427.22,"id":5300737},{"batl":[[1,6.6,10.31],[2,6.8,62.54]],"ltp":5.4,"tv":34340.8,"id":2497008}],"tv":266768.03}]}
{"op":"mcm","clk":"4299780477","pt":1632582050303,"mc":[{"id":"1.188136695","rc":[{"trd":[[1.25,4932.85]],"batb":[[2,1.21,69.11]],"batl":[[0,1.25,88.58]],"ltp":1.25,"tv":232429.64,"id":5300737},{"trd":[[5,671.89]],"ltp":5.0,"tv":34341.19,"id":2497008}],"tv":266770.83}]}
{"op":"mcm","clk":"4299780698","pt":1632582051317,"mc":[{"id":"1.188136695","rc":[{"trd":[[1.25,4966.35]],"batl":[[0,1.25,56.49]],"ltp":1.25,"tv":232463.14,"id":5300737},{"trd":[[5,679.56]],"batb":[[1,4.6,61.11],[2,4.5,84.89]],"ltp":5.0,"tv":34348.86,"id":2497008}],"tv":266812.0}]}
{"op":"mcm","clk":"4299780956","pt":1632582052508,"mc":[{"id":"1.188136695","rc":[{"trd":[[1.25,5014.28]],"batb":[[1,1.22,149.97]],"batl":[[0,1.25,10.25]],"ltp":1.25,"tv":232511.07,"id":5300737},{"trd":[[5,690.69]],"ltp":5.0,"tv":34360.0,"id":2497008}],"tv":266871.07}]}
{"op":"mcm","clk":"4299781365","pt":1632582054425,"mc":[{"id":"1.188136695","rc":[{"trd":[[1.25,5018.14]],"batl":[[0,1.25,8.15]],"ltp":1.25,"tv":232514.93,"id":5300737},{"trd":[[5,690.78]],"ltp":5.0,"tv":34360.08,"id":2497008}],"tv":266875.01}]}
{"op":"mcm","clk":"4299781553","pt":1632582055192,"mc":[{"id":"1.188136695","rc":[{"trd":[[1.25,5018.31]],"batl":[[0,1.25,8.07]],"ltp":1.25,"tv":232515.09,"id":5300737}],"tv":266875.18}]}
{"op":"mcm","clk":"4299781890","pt":1632582056819,"mc":[{"id":"1.188136695","rc":[{"trd":[[1.25,5028.72]],"batl":[[0,1.26,11.71],[1,1.28,5.5],[2,1.32,119.8]],"ltp":1.25,"tv":232525.51,"id":5300737},{"trd":[[5,692.21]],"batb":[[1,4.1,1],[2,3.8,1]],"batl":[[0,5.4,2.67]],"ltp":5.0,"tv":34361.51,"id":2497008}],"tv":266887.03}]}
{"op":"mcm","clk":"4299782070","pt":1632582057796,"mc":[{"id":"1.188136695","rc":[{"trd":[[1.19,29734.43],[1.2,9783.42],[1.21,10862.31],[1.22,7361.91],[1.23,7304.94],[1.25,5032.4]],"batb":[[0,1.17,308.11],[1,1.16,5349],[2,1.15,1622.11]],"batl":[[0,1.2,2667.37],[1,1.22,6.04],[2,1.26,11.71]],"ltp":1.2,"tv":233073.56,"id":5300737},{"trd":[[5,693.13],[5.4,22.29],[6,331.82]],"batl":[[0,6.6,10],[1,6.8,62.54],[2,7,56.11]],"ltp":6.0,"tv":34364.49,"id":2497008}],"tv":267438.05}]}
{"op":"mcm","clk":"4299782213","pt":1632582058429,"mc":[{"id":"1.188136695","rc":[{"batb":[[0,6.4,44.82],[1,6.2,43.51],[2,6,43.51]],"batl":[[1,7,56.11],[2,7.2,77.71]],"ltp":6.0,"tv":34364.49,"id":2497008}]}]}
{"op":"mcm","clk":"4299782452","pt":1632582059629,"mc":[{"id":"1.188136695","rc":[{"trd":[[1.19,29739.32]],"batl":[[0,1.18,597.98],[1,1.19,1847.62],[2,1.2,2667.37]],"ltp":1.19,"tv":233078.44,"id":5300737},{"trd":[[6.4,2516.81]],"batb":[[0,6.4,266.98],[1,6.2,261.04],[2,6,261.04]],"ltp":6.4,"tv":34367.5,"id":2497008}],"tv":267445.95}]}
{"op":"mcm","clk":"4299782725","pt":1632582060819,"mc":[{"id":"1.188136695","rc":[{"batb":[[0,1.17,324.11],[1,1.16,5591]],"batl":[[2,1.2,467.13]],"ltp":1.19,"tv":233078.44,"id":5300737},{"trd":[[6.4,2529.71]],"batb":[[0,6.4,260.53],[1,6.2,458.21]],"ltp":6.4,"tv":34380.4,"id":2497008}],"tv":267458.85}]}
{"op":"mcm","clk":"4299782847","pt":1632582061317,"mc":[{"id":"1.188136695","rc":[{"trd":[[1.18,33159.89]],"batl":[[0,1.18,583.35],[1,1.19,1929.9]],"ltp":1.18,"tv":233107.7,"id":5300737},{"trd":[[6.4,2530.1]],"batb":[[0,6.4,271.38]],"ltp":6.4,"tv":34380.8,"id":2497008}],"tv":267488.5}]}
{"op":"mcm","clk":"4299783157","pt":1632582062634,"mc":[{"id":"1.188136695","rc":[{"batl":[[1,1.19,2882.16]],"ltp":1.18,"tv":233107.7,"id":5300737}]}]}
{"op":"mcm","clk":"4299783393","pt":1632582063647,"mc":[{"id":"1.188136695","rc":[{"trd":[[1.18,33209.89]],"batb":[[0,1.17,943.58]],"batl":[[0,1.18,1469.58]],"ltp":1.18,"tv":233157.7,"id":5300737},{"batb":[[0,6.4,274.38],[1,6.2,461.21]],"batl":[[0,6.6,2]],"ltp":6.4,"tv":34380.8,"id":2497008}],"tv":267538.5}]}
{"op":"mcm","clk":"4299783660","pt":1632582064741,"mc":[{"id":"1.188136695","rc":[{"trd":[[1.18,33229.89]],"batl":[[0,1.18,1459.58],[2,1.21,6.58]],"ltp":1.18,"tv":233177.7,"id":5300737}],"tv":267558.5}]}
{"op":"mcm","clk":"4299783842","pt":1632582065532,"mc":[{"id":"1.188136695","rc":[{"trd":[[1.17,11774.7]],"batb":[[0,1.16,5591],[1,1.15,1622.11],[2,1.14,50.7]],"batl":[[0,1.17,73.68],[1,1.18,1459.58],[2,1.19,1929.9]],"ltp":1.17,"tv":235076.14,"id":5300737},{"trd":[[6.6,619.94]],"batl":[[0,7,56.11],[1,7.2,77.71],[2,7.4,10.14]],"ltp":6.6,"tv":34382.8,"id":2497008}],"tv":269458.95}]}
{"op":"mcm","clk":"4299784098","pt":1632582066716,"mc":[{"id":"1.188136695","rc":[{"batb":[[0,1.16,6476.84]],"batl":[[2,1.19,2609.59]],"ltp":1.17,"tv":235076.14,"id":5300737},{"batb":[[1,6.2,591.67],[2,6,461.09]],"batl":[[0,7,58.11],[2,7.4,45.71]],"ltp":6.6,"tv":34382.8,"id":2497008}]}]}
{"op":"mcm","clk":"4299784324","pt":1632582067620,"mc":[{"id":"1.188136695","rc":[{"trd":[[1.17,11779.71]],"batl":[[0,1.17,71.18]],"ltp":1.17,"tv":235081.15,"id":5300737}],"tv":269463.96}]}
{"op":"mcm","clk":"4299784564","pt":1632582068716,"mc":[{"id":"1.188136695","rc":[{"trd":[[1.17,11910.44]],"batb":[[0,1.17,533.57],[1,1.16,7382.39],[2,1.15,1637.11]],"batl":[[0,1.18,1459.58],[1,1.19,2609.59],[2,1.2,910.26]],"ltp":1.17,"tv":235211.88,"id":5300737},{"trd":[[6.8,51.38]],"batl":[[0,7,157.24],[2,7.4,177.51]],"ltp":6.8,"tv":34384.8,"id":2497008}],"tv":269596.68}]}
{"op":"mcm","clk":"4299784717","pt":1632582069453,"mc":[{"id":"1.188136695","rc":[{"trd":[[1.17,12623.49],[1.18,33254.43]],"batb":[[0,1.17,177.05]],"batl":[[0,1.18,1447.31]],"ltp":1.17,"tv":235949.47,"id":5300737}],"tv":270334.27}]}
{"op":"mcm","clk":"4299785006","pt":1632582070800,"mc":[{"id":"1.188136695","rc":[{"trd":[[1.18,33273.97]],"batb":[[0,1.17,2]],"batl":[[0,1.18,2156.66],[1,1.19,3369.86]],"ltp":1.18,"tv":235969.01,"id":5300737},{"batb":[[0,6.4,406.97],[1,6.2,737.58]],"ltp":6.8,"tv":34384.8,"id":2497008}],"tv":270353.81}]}
{"op":"mcm","clk":"4299785186","pt":1632582071632,"mc":[{"id":"1.188136695","rc":[{"trd":[[1.18,33333.69]],"batl":[[0,1.18,2126.8]],"ltp":1.18,"tv":236028.73,"id":5300737},{"batl":[[0,7,58.11]],"ltp":6.8,"tv":34384.8,"id":2497008}],"tv":270413.54}]}
{"op":"mcm","clk":"4299785409","pt":1632582072612,"mc":[{"id":"1.188136695","rc":[{"trd":[[1.18,33377.51]],"batb":[[0,1.17,223.44]],"batl":[[0,1.18,2104.89],[2,1.2,1000.26]],"ltp":1.18,"tv":236072.55,"id":5300737},{"trd":[[6.4,2530.88]],"batb":[[0,6.4,406.58]],"ltp":6.4,"tv":34385.58,"id":2497008}],"tv":270458.14}]}
{"op":"mcm","clk":"4299785670","pt":1632582073806,"mc":[{"id":"1.188136695","rc":[{"trd":[[1.18,33387.33]],"batb":[[0,1.17,260.63]],"batl":[[0,1.18,2099.98]],"ltp":1.18,"tv":236082.37,"id":5300737}],"tv":270467.96}]}
{"op":"mcm","clk":"4299785824","pt":1632582074510,"mc":[{"id":"1.188136695","rc":[{"trd":[[1.18,33391.01]],"batb":[[0,1.17,271.63]],"batl":[[0,1.18,2098.14]],"ltp":1.18,"tv":236086.06,"id":5300737},{"trd":[[6.4,2531.58]],"batb":[[0,6.4,406.23]],"batl":[[0,7,58.46]],"ltp":6.4,"tv":34386.28,"id":2497008}],"tv":270472.34}]}
{"op":"mcm","clk":"4299785985","pt":1632582075124,"mc":[{"id":"1.188136695","rc":[{"batb":[[0,1.17,271.98]],"ltp":1.18,"tv":236086.06,"id":5300737},{"batl":[[0,7,66.66]],"ltp":6.4,"tv":34386.28,"id":2497008}]}]}
{"op":"mcm","clk":"4299786284","pt":1632582076534,"mc":[{"id":"1.188136695","rc":[{"trd":[[1.18,33648.15]],"batb":[[0,1.17,324.21]],"batl":[[0,1.18,1969.57]],"ltp":1.18,"tv":236343.19,"id":5300737},{"batb":[[1,6.2,734.58]],"ltp":6.4,"tv":34386.28,"id":2497008}],"tv":270729.48}]}
{"op":"mcm","clk":"4299786500","pt":1632582077544,"mc":[{"id":"1.188136695","rc":[{"batb":[[0,1.17,325.26],[2,1.15,1519.71]],"batl":[[0,1.18,1630.35]],"ltp":1.18,"tv":236343.19,"id":5300737},{"batl":[[0,6.8,1.72],[1,7,66.31],[2,7.2,77.71]],"ltp":6.4,"tv":34386.28,"id":2497008}]}]}
{"op":"mcm","clk":"4299786653","pt":1632582078258,"mc":[{"id":"1.188136695","rc":[{"trd":[[1.18,33667.97]],"batb":[[0,1.17,326.11]],"batl":[[0,1.18,1620.44]],"ltp":1.18,"tv":236363.01,"id":5300737},{"trd":[[6.4,2558.41]],"batb":[[0,6.4,392.82]],"batl":[[0,6.8,2.07]],"ltp":6.4,"tv":34413.1,"id":2497008}],"tv":270776.12}]}
{"op":"mcm","clk":"4299787002","pt":1632582079758,"mc":[{"id":"1.188136695","rc":[{"trd":[[1.18,33685.11]],"batb":[[0,1.17,331.62],[1,1.16,4840.05],[2,1.15,539.97]],"batl":[[0,1.18,1611.87],[1,1.19,1522.24]],"ltp":1.18,"tv":236380.16,"id":5300737},{"trd":[[6.4,2612.85]],"batb":[[0,6.4,146.64],[1,6.2,476.54],[2,6,200.05]],"batl":[[1,7,58.11]],"ltp":6.4,"tv":34467.54,"id":2497008}],"tv":270847.7}]}
{"op":"mcm","clk":"4299787166","pt":1632582080331,"mc":[{"id":"1.188136695","rc":[{"trd":[[1.18,33685.81]],"batb":[[0,1.18,3.01],[1,1.17,109.57],[2,1.16,328.35]],"batl":[[0,1.2,90],[1,1.23,3.01],[2,1.24,6104.89]],"ltp":1.18,"tv":236380.86,"id":5300737},{"batb":[[0,6,18],[1,5.5,130.97],[2,5.2,460.27]],"batl":[[1,7.4,35.57],[2,7.8,1]],"ltp":6.4,"tv":34467.54,"id":2497008}],"tv":270848.4}]}
{"op":"mcm","clk":"4299787489","pt":1632582081727,"mc":[{"id":"1.188136695","rc":[{"batb":[[0,1.18,5.05],[1,1.17,108.52],[2,1.16,103.35]],"batl":[[0,1.23,3.01],[1,1.24,6104.89],[2,1.25,318.62]],"ltp":1.18,"tv":236380.86,"id":5300737},{"batb":[[0,5.5,130.97],[1,5.2,460.27],[2,5.1,74.46]],"batl":[[0,7.8,1.35],[1,8.4,43.65],[2,8.6,51.21]],"ltp":6.4,"tv":34467.54,"id":2497008}]}]}
{"op":"mcm","clk":"4299787748","pt":1632582082756,"mc":[{"id":"1.188136695","rc":[{"batb":[[0,1.18,7.73],[1,1.17,108.87]],"ltp":1.18,"tv":236380.86,"id":5300737}]}]}
{"op":"mcm","clk":"4299788027","pt":1632582083812,"mc":[{"id":"1.188136695","rc":[{"trd":[[1.18,33691.51],[1.19,29743.32]],"batb":[[0,1.18,110.29],[1,1.17,106.9]],"batl":[[0,1.22,1147.36],[1,1.23,1463.22],[2,1.24,6104.89]],"ltp":1.18,"tv":236390.56,"id":5300737}],"tv":270858.1}]}
{"op":"mcm","clk":"4299788216","pt":1632582084717,"mc":[{"id":"1.188136695","rc":[{"batb":[[0,1.18,111.19],[1,1.17,69.72]],"batl":[[1,1.23,1466.22]],"ltp":1.18,"tv":236390.56,"id":5300737},{"batb":[[0,5.5,132.97],[1,5.4,2],[2,5.2,460.27]],"ltp":6.4,"tv":34467.54,"id":2497008}]}]}
{"op":"mcm","clk":"4299788455","pt":1632582085770,"mc":[{"id":"1.188136695","rc":[{"trd":[[1.18,33703.52]],"batb":[[0,1.18,107.47]],"ltp":1.18,"tv":236402.56,"id":5300737}],"tv":270870.11}]}
{"op":"mcm","clk":"4299788703","pt":1632582086762,"mc":[{"id":"1.188136695","rc":[{"batb":[[0,1.18,88.53]],"batl":[[0,1.22,1156.36]],"ltp":1.18,"tv":236402.56,"id":5300737}]}]}
{"op":"mcm","clk":"4299788949","pt":1632582087769,"mc":[{"id":"1.188136695","rc":[{"trd":[[1.17,12743.27],[1.18,33880.58]],"batb":[[0,1.16,103.35],[1,1.15,100.4],[2,1.14,50.7]],"batl":[[0,1.17,84.56],[1,1.22,1156.36],[2,1.23,1466.22]],"ltp":1.17,"tv":236699.41,"id":5300737},{"trd":[[6.8,51.73]],"batl":[[0,7.8,1]],"ltp":6.8,"tv":34467.89,"id":2497008}],"tv":271167.3}]}
{"op":"mcm","clk":"4299789182","pt":1632582088750,"mc":[{"id":"1.188136695","rc":[{"trd":[[1.17,12778.33]],"batl":[[0,1.17,67.03]],"ltp":1.17,"tv":236734.47,"id":5300737}],"tv":271202.36}]}
{"op":"mcm","clk":"4299789247","pt":1632582089069,"mc":[{"id":"1.188136695","rc":[{"trd":[[1.17,12783.47]],"batl":[[0,1.17,64.46]],"ltp":1.17,"tv":236739.61,"id":5300737}],"tv":271207.5}]}
{"op":"mcm","clk":"4299789585","pt":1632582090364,"mc":[{"id":"1.188136695","rc":[{"batl":[[0,1.22,1156.36],[1,1.23,1585.46],[2,1.24,6104.89]],"ltp":1.17,"tv":236739.61,"id":5300737}]}]}
{"op":"mcm","clk":"4299789866","pt":1632582091387,"mc":[{"id":"1.188136695","rc":[{"batl":[[0,1.22,9],[1,1.23,125.25],[2,1.24,5802.69]],"ltp":1.17,"tv":236739.61,"id":5300737}]}]}
{"op":"mcm","clk":"4299790190","pt":1632582092761,"mc":[{"id":"1.188136695","rc":[{"batb":[[2,1.14,70.7]],"ltp":1.17,"tv":236739.61,"id":5300737}]}]}
{"op":"mcm","clk":"4299790284","pt":1632582093152,"mc":[{"id":"1.188136695","rc":[{"trd":[[1.15,200.81],[1.16,206.7]],"batb":[[0,1.14,70.7],[1,1.13,401.61],[2,1.12,6822.77]],"batl":[[0,1.16,2585.78],[1,1.22,9],[2,1.23,125.25]],"ltp":1.15,"tv":237147.12,"id":5300737},{"batb":[[0,5.7,26.55],[1,5.5,132.97],[2,5.4,2]],"ltp":6.8,"tv":34467.89,"id":2497008}],"tv":271615.01}]}
{"op":"mcm","clk":"4299790669","pt":1632582094667,"mc":[{"id":"1.188136695","rc":[{"trd":[[1.14,166.28]],"batb":[[0,1.13,50],[1,1.12,6822.77],[2,1.11,2004.93]],"batl":[[0,1.14,1281.45],[1,1.15,2378.55],[2,1.16,2585.78]],"ltp":1.14,"tv":237313.4,"id":5300737},{"trd":[[7.8,1]],"batb":[[0,7.6,493.42],[1,7.4,1260.22],[2,7.2,246.71]],"batl":[[0,8.8,61.13],[1,9.4,7.89],[2,9.8,1]],"ltp":7.8,"tv":34468.89,"id":2497008}],"tv":271782.29}]}
{"op":"mcm","clk":"4299790947","pt":1632582095765,"mc":[{"id":"1.188136695","rc":[{"trd":[[1.14,167.48]],"batl":[[0,1.14,1280.85],[1,1.15,3330.81]],"ltp":1.14,"tv":237314.6,"id":5300737},{"trd":[[8,10.86]],"batb":[[0,8,106.52],[1,7.6,102.8],[2,7.4,1064.91]],"batl":[[1,9,86.8],[2,9.2,43.4]],"ltp":8.0,"tv":34479.75,"id":2497008}],"tv":271794.35}]}
{"op":"mcm","clk":"4299791186","pt":1632582096594,"mc":[{"id":"1.188136695","rc":[{"trd":[[1.14,193.96]],"batb":[[1,1.12,7082.57]],"batl":[[0,1.14,1145.28],[2,1.16,467.13]],"ltp":1.14,"tv":237341.08,"id":5300737}],"tv":271820.84}]}
{"op":"mcm","clk":"4299791443","pt":1632582097743,"mc":[{"id":"1.188136695","rc":[{"trd":[[1.14,227.14]],"batb":[[0,1.13,68],[1,1.12,7097.57]],"batl":[[0,1.14,1128.69]],"ltp":1.14,"tv":237374.26,"id":5300737},{"trd":[[8,11.17]],"batb":[[0,8,106.36]],"batl":[[0,8.4,2],[1,8.8,64.13],[2,9,86.8]],"ltp":8.0,"tv":34480.06,"id":2497008}],"tv":271854.33}]}
{"op":"mcm","clk":"4299791652","pt":1632582098669,"mc":[{"id":"1.188136695","rc":[{"trd":[[1.14,253.8]],"batl":[[0,1.14,2835.53],[1,1.15,4188.78]],"ltp":1.14,"tv":237400.92,"id":5300737},{"batb":[[0,8.2,7],[1,8,222.8],[2,7.8,2]],"ltp":8.0,"tv":34480.06,"id":2497008}],"tv":271880.99}]}
{"op":"mcm","clk":"4299791902","pt":1632582099676,"mc":[{"id":"1.188136695","rc":[{"batb":[[0,1.13,895.27],[1,1.12,8319.67]],"batl":[[0,1.14,3692.65],[2,1.16,90]],"ltp":1.14,"tv":237400.92,"id":5300737},{"batl":[[1,8.8,169.24]],"ltp":8.0,"tv":34480.06,"id":2497008}]}]}
{"op":"mcm","clk":"4299792129","pt":1632582100771,"mc":[{"id":"1.188136695","rc":[{"trd":[[1.13,1714.24]],"batb":[[0,1.13,38.15]],"ltp":1.13,"tv":239115.16,"id":5300737}],"tv":273595.22}]}
{"op":"mcm","clk":"4299792333","pt":1632582101772,"mc":[{"id":"1.188136695","rc":[{"trd":[[1.14,253.94]],"batb":[[0,1.13,48.15]],"batl":[[0,1.14,3692.58]],"ltp":1.14,"tv":239115.29,"id":5300737},{"batb":[[0,8.2,9]],"ltp":8.0,"tv":34480.06,"id":2497008}],"tv":273595.36}]}
{"op":"mcm","clk":"4299792583","pt":1632582102764,"mc":[{"id":"1.188136695","rc":[{"trd":[[1.14,515.3]],"batb":[[0,1.13,10]],"batl":[[0,1.14,3561.9],[1,1.15,3236.53]],"ltp":1.14,"tv":239376.65,"id":5300737}],"tv":273856.71}]}
{"op":"mcm","clk":"4299792711","pt":1632582103357,"mc":[{"id":"1.188136695","rc":[{"trd":[[1.14,543.67]],"batl":[[0,1.14,3547.71]],"ltp":1.14,"tv":239405.03,"id":5300737},{"trd":[[8,20.8],[8.2,18]],"batb":[[0,8,217.99],[1,7.8,2],[2,7.6,232.62]],"ltp":8.0,"tv":34507.69,"id":2497008}],"tv":273912.72}]}
{"op":"mcm","clk":"4299792963","pt":1632582104476,"mc":[{"id":"1.188136695","rc":[{"trd":[[1.14,547.19]],"batb":[[1,1.12,8502.04]],"batl":[[0,1.14,3545.95]],"ltp":1.14,"tv":239408.55,"id":5300737},{"trd":[[8,29.03]],"batb":[[0,8,213.87]],"ltp":8.0,"tv":34515.92,"id":2497008}],"tv":273924.47}]}
{"op":"mcm","clk":"4299793228","pt":1632582105685,"mc":[{"id":"1.188136695","rc":[{"trd":[[1.13,1718.24],[1.14,611.77]],"batb":[[0,1.13,8]],"batl":[[0,1.14,3513.66]],"ltp":1.14,"tv":239477.13,"id":5300737}],"tv":273993.05}]}
{"op":"mcm","clk":"4299793462","pt":1632582106677,"mc":[{"id":"1.188136695","rc":[{"trd":[[1.14,833.18]],"batb":[[0,1.13,33]],"batl":[[0,1.14,3501.16]],"ltp":1.14,"tv":239698.53,"id":5300737}],"tv":274214.46}]}
{"op":"mcm","clk":"4299793662","pt":1632582107537,"mc":[{"id":"1.188136695","rc":[{"trd":[[1.13,1736.52],[1.14,853.16]],"batb":[[0,1.13,23.86]],"batl":[[0,1.14,3491.17]],"ltp":1.14,"tv":239736.8,"id":5300737},{"batb":[[0,8.2,6.3],[1,8,213.87],[2,7.8,2]],"ltp":8.0,"tv":34515.92,"id":2497008}],"tv":274252.72}]}
{"op":"mcm","clk":"4299793931","pt":1632582108734,"mc":[{"id":"1.188136695","rc":[{"trd":[[1.13,1772.36],[1.14,1186.85]],"batb":[[0,1.13,5.94]],"batl":[[0,1.14,3324.32]],"ltp":1.14,"tv":240106.33,"id":5300737}],"tv":274622.25}]}
{"op":"mcm","clk":"4299794167","pt":1632582109668,"mc":[{"id":"1.188136695","rc":[{"trd":[[1.14,1190.52]],"batb":[[1,1.12,8613.58]],"batl":[[0,1.14,3411.04]],"ltp":1.14,"tv":240110.0,"id":5300737},{"trd":[[8.4,4],[8.8,42.16]],"batl":[[0,8.8,148.15],[1,9,86.8],[2,9.2,43.4]],"ltp":8.8,"tv":34562.08,"id":2497008}],"tv":274672.08}]}
{"op":"mcm","clk":"4299794425","pt":1632582110809,"mc":[{"id":"1.188136695","rc":[{"trd":[[1.14,1196.84]],"batl":[[0,1.14,3407.88]],"ltp":1.14,"tv":240116.32,"id":5300737},{"trd":[[8,67.71],[8.2,30.6]],"batb":[[0,8,194.53],[1,7.8,2],[2,7.6,232.62]],"batl":[[0,8.8,148.5]],"ltp":8.0,"tv":34613.36,"id":2497008}],"tv":274729.68}]}
{"op":"mcm","clk":"4299794637","pt":1632582111782,"mc":[{"id":"1.188136695","rc":[{"trd":[[1.14,1202.74]],"batb":[[0,1.13,20.94]],"batl":[[0,1.14,3404.93]],"ltp":1.14,"tv":240122.21,"id":5300737},{"trd":[[8.2,31.3]],"batb":[[1,7.6,232.62],[2,7.4,1078.97]],"batl":[[0,8.8,148.15]],"ltp":8.2,"tv":34614.06,"id":2497008}],"tv":274736.28}]}
{"op":"mcm","clk":"4299794809","pt":1632582112473,"mc":[{"id":"1.188136695","rc":[{"trd":[[1.13,1775.5],[1.14,1207.44]],"batb":[[0,1.13,19.37]],"batl":[[0,1.14,3733.54]],"ltp":1.14,"tv":240130.05,"id":5300737},{"trd":[[8,152.44]],"batb":[[0,8,152.17]],"ltp":8.0,"tv":34698.79,"id":2497008}],"tv":274828.85}]}
{"op":"mcm","clk":"4299795050","pt":1632582113477,"mc":[{"id":"1.188136695","rc":[{"trd":[[1.14,1235.22]],"batb":[[0,1.13,29.37]],"batl":[[0,1.14,3719.65]],"ltp":1.14,"tv":240157.83,"id":5300737}],"tv":274856.63}]}
{"op":"mcm","clk":"4299795346","pt":1632582114795,"mc":[{"id":"1.188136695","rc":[{"trd":[[1.14,1442.24]],"batb":[[1,1.12,8159.98]],"batl":[[0,1.14,3616.14]],"ltp":1.14,"tv":240364.85,"id":5300737},{"batb":[[1,7.8,2],[2,7.6,129.82]],"batl":[[0,8.2,20],[1,8.8,148.15],[2,9.4,169.66]],"ltp":8.0,"tv":34698.79,"id":2497008}],"tv":275063.65}]}
{"op":"mcm","clk":"4299795586","pt":1632582115773,"mc":[{"id":"1.188136695","rc":[{"trd":[[1.13,1853.32],[1.14,1538.61]],"batb":[[0,1.12,261.56],[1,1.11,858.12],[2,1.1,1065.9]],"batl":[[0,1.14,1033.93],[1,1.16,90],[2,1.17,13.64]],"ltp":1.13,"tv":240539.05,"id":5300737},{"trd":[[8.2,38.06]],"batb":[[0,7.4,14.06],[1,6.6,169.27],[2,6,58.52]],"batl":[[0,8.2,13.24],[1,9.4,31.05],[2,9.8,1]],"ltp":8.2,"tv":34705.55,"id":2497008}],"tv":275244.61}]}
{"op":"mcm","clk":"4299795751","pt":1632582116586,"mc":[{"id":"1.188136695","rc":[{"trd":[[1.14,1549.15]],"batl":[[0,1.14,803.66]],"ltp":1.14,"tv":240549.59,"id":5300737}],"tv":275255.15}]}
{"op":"mcm","clk":"4299795974","pt":1632582117604,"mc":[{"id":"1.188136695","rc":[{"trd":[[1.14,1576.82]],"batb":[[0,1.12,1.76]],"batl":[[0,1.14,789.83],[1,1.17,13.64],[2,1.2,322.89]],"ltp":1.14,"tv":240577.26,"id":5300737},{"batb":[[0,6.6,169.27],[1,6,58.52],[2,5.9,63.71]],"batl":[[1,9.8,1],[2,11.5,40.81]],"ltp":8.2,"tv":34705.55,"id":2497008}],"tv":275282.82}]}
{"op":"mcm","clk":"4299796207","pt":1632582118766,"mc":[{"id":"1.188136695","rc":[{"trd":[[1.14,1592.66]],"batl":[[0,1.14,781.91],[2,1.18,2402.7]],"ltp":1.14,"tv":240593.1,"id":5300737}],"tv":275298.66}]}
{"op":"mcm","clk":"4299796418","pt":1632582119788,"mc":[{"id":"1.188136695","rc":[{"batb":[[0,1.14,2.03],[1,1.12,1.76],[2,1.11,1]],"batl":[[0,1.17,13.64],[1,1.18,2402.7],[2,1.19,1156]],"ltp":1.14,"tv":240593.1,"id":5300737},{"batl":[[0,8.2,15.21]],"ltp":8.2,"tv":34705.55,"id":2497008}]}]}
{"op":"mcm","clk":"4299796645","pt":1632582120796,"mc":[{"id":"1.188136695","rc":[{"batb":[[0,1.14,19.17]],"ltp":1.14,"tv":240593.1,"id":5300737}]}]}
{"op":"mcm","clk":"4299796850","pt":1632582121697,"mc":[{"id":"1.188136695","rc":[{"batb":[[0,1.14,22.73]],"ltp":1.14,"tv":240593.1,"id":5300737}]}]}
{"op":"mcm","clk":"4299797071","pt":1632582122699,"mc":[{"id":"1.188136695","rc":[{"batb":[[0,1.14,30.44]],"batl":[[1,1.18,2403.05]],"ltp":1.14,"tv":240593.1,"id":5300737}]}]}
{"op":"mcm","clk":"4299797291","pt":1632582123788,"mc":[{"id":"1.188136695","rc":[{"batb":[[0,1.14,34.34]],"batl":[[1,1.23,122.6],[2,1.24,5802.69]],"ltp":1.14,"tv":240593.1,"id":5300737},{"batb":[[1,5.2,460.27],[2,5.1,1]],"ltp":8.2,"tv":34705.55,"id":2497008}]}]}
{"op":"mcm","clk":"4299797452","pt":1632582124598,"mc":[{"id":"1.188136695","rc":[{"trd":[[1.11,10.83],[1.12,88.36],[1.13,1963.69],[1.14,1663.74]],"batb":[[0,1.1,1065.9],[1,1.09,3577.73],[2,1.08,6057.24]],"batl":[[0,1.12,2499.04],[1,1.17,13.64],[2,1.23,122.6]],"ltp":1.11,"tv":240873.74,"id":5300737},{"trd":[[8.2,53.27],[9.8,1]],"batl":[[0,11.5,40.81],[1,12,46.85],[2,12.5,50.54]],"ltp":9.8,"tv":34721.76,"id":2497008}],"tv":275595.51}]}
{"op":"mcm","clk":"4299797673","pt":1632582125590,"mc":[{"id":"1.188136695","rc":[{"batl":[[1,1.13,61.51],[2,1.17,43.64]],"ltp":1.11,"tv":240873.74,"id":5300737},{"batb":[[0,10.5,27.32],[1,10,26.52],[2,9.8,26.52]],"ltp":9.8,"tv":34721.76,"id":2497008}]}]}
{"op":"mcm","clk":"4299797946","pt":1632582126795,"mc":[{"id":"1.188136695","rc":[{"batl":[[0,1.11,3598.15],[1,1.12,2499.04],[2,1.13,68.56]],"ltp":1.11,"tv":240873.74,"id":5300737},{"batb":[[0,10.5,163.93],[1,10,159.11],[2,9.8,159.11]],"ltp":9.8,"tv":34721.76,"id":2497008}]}]}
{"op":"mcm","clk":"4299798171","pt":1632582127803,"mc":[{"id":"1.188136695","rc":[{"trd":[[1.1,1089.9],[1.11,45.89]],"batb":[[0,1.09,3904.73],[1,1.08,6057.24],[2,1.07,3964.07]],"batl":[[0,1.11,4532.88],[1,1.12,467.13],[2,1.13,250.56]],"ltp":1.1,"tv":241998.71,"id":5300737},{"trd":[[11,121.51]],"batb":[[0,11,30.94],[1,10.5,163.93],[2,10,159.11]],"batl":[[1,12,73.98]],"ltp":11.0,"tv":34843.27,"id":2497008}],"tv":276841.98}]}
{"op":"mcm","clk":"4299798326","pt":1632582128609,"mc":[{"id":"1.188136695","rc":[{"trd":[[1.1,1098.47]],"batb":[[0,1.09,3604.73]],"batl":[[0,1.11,4659.27]],"ltp":1.1,"tv":242007.28,"id":5300737},{"trd":[[11,124.6]],"batb":[[0,11,28.96]],"batl":[[0,12,46.85],[1,12.5,50.54],[2,14,122.94]],"ltp":11.0,"tv":34846.36,"id":2497008}],"tv":276853.65}]}
{"op":"mcm","clk":"4299798396","pt":1632582128888,"mc":[{"id":"1.188136695","rc":[{"trd":[[1.1,1103.3]],"ltp":1.1,"tv":242012.11,"id":5300737},{"trd":[[11,125.08]],"batb":[[0,11,28.48]],"ltp":11.0,"tv":34846.85,"id":2497008}],"tv":276858.96}]}
{"op":"mcm","clk":"4299798817","pt":1632582130795,"mc":[{"id":"1.188136695","rc":[{"trd":[[1.1,1106.81]],"batb":[[0,1.09,4010.24],[1,1.08,6079.24]],"batl":[[0,1.1,952.26],[1,1.11,5683.98],[2,1.12,467.13]],"ltp":1.1,"tv":242015.62,"id":5300737},{"trd":[[11,125.43]],"batb":[[0,11,28.13]],"batl":[[0,11.5,2],[1,12,46.85],[2,12.5,50.54]],"ltp":11.0,"tv":34847.2,"id":2497008}],"tv":276862.82}]}
{"op":"mcm","clk":"4299799018","pt":1632582131816,"mc":[{"id":"1.188136695","rc":[{"trd":[[1.1,1166.81]],"batb":[[1,1.08,6397.43]],"batl":[[0,1.1,922.26],[1,1.11,4731.72],[2,1.13,99.05]],"ltp":1.1,"tv":242075.61,"id":5300737},{"batl":[[1,12,54.68],[2,12.5,77.07]],"ltp":11.0,"tv":34847.2,"id":2497008}],"tv":276922.82}]}
{"op":"mcm","clk":"4299799222","pt":1632582132745,"mc":[{"id":"1.188136695","rc":[{"trd":[[1.09,128.94],[1.1,1434.18]],"batb":[[0,1.09,3945.77]],"batl":[[0,1.1,788.57]],"ltp":1.1,"tv":242471.92,"id":5300737}],"tv":277319.12}]}
{"op":"mcm","clk":"4299799470","pt":1632582133814,"mc":[{"id":"1.188136695","rc":[{"trd":[[1.09,251.96]],"batb":[[0,1.09,3884.26],[1,1.08,19254.21],[2,1.07,4404.07]],"batl":[[0,1.1,798.61],[1,1.11,4746.35],[2,1.12,90]],"ltp":1.09,"tv":242594.94,"id":5300737}],"tv":277442.14}]}
{"op":"mcm","clk":"4299799699","pt":1632582134803,"mc":[{"id":"1.188136695","rc":[{"trd":[[1.1,1504.29]],"batb":[[0,1.09,3914.53]],"batl":[[0,1.1,763.55]],"ltp":1.1,"tv":242665.06,"id":5300737}],"tv":277512.26}]}
{"op":"mcm","clk":"4299799887","pt":1632582135622,"mc":[{"id":"1.188136695","rc":[{"trd":[[1.1,1541.58]],"batb":[[0,1.09,4049.09]],"batl":[[0,1.1,744.91]],"ltp":1.1,"tv":242702.35,"id":5300737},{"trd":[[11.5,4]],"batb":[[0,11,28.3]],"batl":[[0,12,54.68],[1,12.5,77.07],[2,14,122.94]],"ltp":11.5,"tv":34851.2,"id":2497008}],"tv":277553.55}]}
{"op":"mcm","clk":"4299800138","pt":1632582136831,"mc":[{"id":"1.188136695","rc":[{"trd":[[1.09,437.52],[1.1,3161.44]],"batb":[[0,1.09,3791.48]],"batl":[[0,1.11,5498.9],[1,1.12,941.12],[2,1.13,7.05]],"ltp":1.1,"tv":244507.77,"id":5300737},{"trd":[[11,138.26],[11.5,4.17]],"batb":[[0,11,15.31],[2,10,242.64]],"ltp":11.0,"tv":34864.19,"id":2497008}],"tv":279371.97}]}
{"op":"mcm","clk":"4299800331","pt":1632582137721,"mc":[{"id":"1.188136695","rc":[{"trd":[[1.1,3162.22]],"batb":[[0,1.09,3801.48],[1,1.08,6397.43]],"ltp":1.1,"tv":244508.55,"id":5300737},{"trd":[[11,138.34]],"batb":[[0,11,15.23]],"ltp":11.0,"tv":34864.27,"id":2497008}],"tv":279372.83}]}
{"op":"mcm","clk":"4299800558","pt":1632582138824,"mc":[{"id":"1.188136695","rc":[{"trd":[[1.09,679.4],[1.1,3178.47]],"batb":[[0,1.09,3732.71]],"ltp":1.1,"tv":244766.68,"id":5300737},{"trd":[[11,139.96]],"batb":[[0,11,13.6]],"ltp":11.0,"tv":34865.9,"id":2497008}],"tv":279632.58}]}
{"op":"mcm","clk":"4299800741","pt":1632582139609,"mc":[{"id":"1.188136695","rc":[{"trd":[[1.09,1402.58],[1.1,3457.37],[1.11,46.67]],"batb":[[0,1.09,4116.76]],"batl":[[0,1.11,5498.51],[1,1.12,1335.58],[2,1.13,419.55]],"ltp":1.11,"tv":245769.53,"id":5300737},{"trd":[[11,153.57]],"batb":[[0,10.5,163.93],[1,10,242.64],[2,9.8,159.11]],"ltp":11.0,"tv":34879.5,"id":2497008}],"tv":280649.04}]}
{"op":"mcm","clk":"4299800966","pt":1632582140629,"mc":[{"id":"1.188136695","rc":[{"trd":[[1.1,3554.31]],"batb":[[0,1.1,42.08],[1,1.09,4116.76],[2,1.08,6079.24]],"batl":[[0,1.11,5483.88]],"ltp":1.1,"tv":245866.47,"id":5300737},{"trd":[[11,163.26]],"batl":[[0,11,23.86],[1,12,54.68],[2,12.5,50.54]],"ltp":11.0,"tv":34889.19,"id":2497008}],"tv":280755.66}]}
{"op":"mcm","clk":"4299801199","pt":1632582141727,"mc":[{"id":"1.188136695","rc":[{"trd":[[1.1,3613.01]],"batb":[[0,1.1,17.03],[1,1.09,3320.95]],"ltp":1.1,"tv":245925.17,"id":5300737}],"tv":280814.37}]}
{"op":"mcm","clk":"4299801421","pt":1632582142727,"mc":[{"id":"1.188136695","rc":[{"trd":[[1.09,6212.16],[1.1,3880.03]],"batb":[[0,1.1,28.2],[1,1.09,916.16]],"batl":[[0,1.11,4740.96]],"ltp":1.09,"tv":251001.77,"id":5300737},{"trd":[[11,193.28]],"batb":[[0,10.5,175.67],[1,10,244.64]],"batl":[[0,12,54.88],[1,12.5,50.54],[2,14,122.94]],"ltp":11.0,"tv":34919.21,"id":2497008}],"tv":285920.98}]}
{"op":"mcm","clk":"4299801650","pt":1632582143823,"mc":[{"id":"1.188136695","rc":[{"trd":[[1.1,3934.27]],"batb":[[0,1.09,1189.51],[1,1.08,6057.24],[2,1.07,4392.39]],"batl":[[2,1.13,412.5]],"ltp":1.1,"tv":251056.02,"id":5300737},{"batl":[[0,12,81.81]],"ltp":11.0,"tv":34919.21,"id":2497008}],"tv":285975.23}]}
{"op":"mcm","clk":"4299801836","pt":1632582144831,"mc":[{"id":"1.188136695","rc":[{"trd":[[1.09,6383.46],[1.1,3934.97],[1.11,59.97]],"batb":[[0,1.09,803.51]],"batl":[[0,1.11,4734.31]],"ltp":1.11,"tv":251241.32,"id":5300737},{"batl":[[0,12,54.68]],"ltp":11.0,"tv":34919.21,"id":2497008}],"tv":286160.53}]}
{"op":"mcm","clk":"4299802056","pt":1632582145826,"mc":[{"id":"1.188136695","rc":[{"trd":[[1.1,3961.99]],"batb":[[0,1.09,12],[1,1.07,3787.89],[2,1.06,4121.68]],"batl":[[0,1.11,373],[1,1.12,484.46]],"ltp":1.1,"tv":251268.34,"id":5300737},{"batb":[[0,9.4,93.15],[1,9.2,7.64],[2,8,56.03]],"batl":[[0,12,1],[1,14.5,38.32],[2,15,34.42]],"ltp":11.0,"tv":34919.21,"id":2497008}],"tv":286187.55}]}
{"op":"mcm","clk":"4299802271","pt":1632582146738,"mc":[{"id":"1.188136695","rc":[{"trd":[[1.1,3970.16]],"batb":[[1,1.08,26],[2,1.07,3787.89]],"batl":[[0,1.1,853.03]],"ltp":1.1,"tv":251276.51,"id":5300737}],"tv":286195.72}]}
{"op":"mcm","clk":"4299802480","pt":1632582147631,"mc":[{"id":"1.188136695","rc":[{"trd":[[1.09,6389.26]],"batb":[[0,1.09,9.1],[1,1.07,3787.89],[2,1.06,4121.68]],"batl":[[1,1.12,394.46],[2,1.13,1269.62]],"ltp":1.09,"tv":251282.3,"id":5300737},{"batb":[[0,9.4,82.44]],"ltp":11.0,"tv":34919.21,"id":2497008}],"tv":286201.52}]}
{"op":"mcm","clk":"4299802739","pt":1632582148735,"mc":[{"id":"1.188136695","rc":[{"trd":[[1.09,6437.05],[1.1,3993.26]],"batb":[[0,1.07,4997.35],[1,1.06,13123.22],[2,1.05,10257.17]],"batl":[[0,1.1,847.46],[1,1.12,1829.76],[2,1.13,3659.93]],"ltp":1.1,"tv":251353.2,"id":5300737},{"trd":[[11,195.59],[12,2.69]],"batb":[[2,8.8,94.44]],"batl":[[0,14.5,38.32],[1,15,34.42],[2,15.5,50.11]],"ltp":11.0,"tv":34924.21,"id":2497008}],"tv":286277.41}]}
{"op":"mcm","clk":"4299802884","pt":1632582149444,"mc":[{"id":"1.188136695","rc":[{"trd":[[1.09,6437.12],[1.1,3994.6]],"batb":[[0,1.08,5.64],[1,1.07,4997.35],[2,1.06,13123.22]],"batl":[[0,1.1,871.57]],"ltp":1.1,"tv":251354.6,"id":5300737},{"batb":[[0,9.2,7.64],[1,8.8,94.44],[2,8,56.03]],"batl":[[2,15.5,47.42]],"ltp":11.0,"tv":34924.21,"id":2497008}],"tv":286278.82}]}
{"op":"mcm","clk":"4299803033","pt":1632582150149,"mc":[{"id":"1.188136695","rc":[{"trd":[[1.09,6437.96],[1.1,3998.54]],"batl":[[0,1.1,40.34]],"ltp":1.1,"tv":251359.39,"id":5300737}],"tv":286283.6}]}
{"op":"mcm","clk":"4299803356","pt":1632582151731,"mc":[{"id":"1.188136695","rc":[{"batb":[[1,1.07,5019.35],[2,1.06,13138.22]],"batl":[[0,1.09,34.82],[1,1.1,51.34],[2,1.12,1829.76]],"ltp":1.1,"tv":251359.39,"id":5300737},{"batl":[[0,14.5,40.32]],"ltp":11.0,"tv":34924.21,"id":2497008}]}]}
{"op":"mcm","clk":"4299803570","pt":1632582152726,"mc":[{"id":"1.188136695","rc":[{"trd":[[1.09,6474.33],[1.1,4025.06]],"batl":[[0,1.1,30.85],[1,1.12,1829.76],[2,1.13,3659.93]],"ltp":1.1,"tv":251422.28,"id":5300737},{"trd":[[11,197.57],[12,5.71]],"batl":[[2,15.5,50.43]],"ltp":11.0,"tv":34929.21,"id":2497008}],"tv":286351.49}]}
{"op":"mcm","clk":"4299803720","pt":1632582153535,"mc":[{"id":"1.188136695","rc":[{"trd":[[1.1,4086.76]],"batb":[[0,1.11,12],[1,1.09,14.63],[2,1.08,5.64]],"batl":[[0,1.12,1829.76],[1,1.13,3659.93],[2,1.14,353.75]],"ltp":1.1,"tv":251483.97,"id":5300737},{"batl":[[2,15.5,47.42]],"ltp":11.0,"tv":34929.21,"id":2497008}],"tv":286413.19}]}
{"op":"mcm","clk":"4299803803","pt":1632582153941,"mc":[{"id":"1.188136695","rc":[{"trd":[[1.09,6503.59],[1.11,83.97]],"batb":[[0,1.08,5.64],[1,1.07,5019.35],[2,1.06,13138.22]],"batl":[[0,1.09,25.46],[1,1.12,1829.76],[2,1.13,3659.93]],"ltp":1.09,"tv":251537.23,"id":5300737}],"tv":286466.44}]}
{"op":"mcm","clk":"4299804141","pt":1632582155534,"mc":[{"id":"1.188136695","rc":[{"trd":[[1.09,6520.33]],"batl":[[0,1.09,8.91]],"ltp":1.09,"tv":251553.97,"id":5300737},{"trd":[[12,7.19]],"ltp":12.0,"tv":34930.69,"id":2497008}],"tv":286484.67}]}
{"op":"mcm","clk":"4299804412","pt":1632582156762,"mc":[{"id":"1.188136695","rc":[{"trd":[[1.09,6538.16],[1.11,107.97]],"batb":[[0,1.11,21.36],[1,1.1,1.05],[2,1.08,5.64]],"batl":[[0,1.12,1829.76],[1,1.13,3659.93],[2,1.14,353.75]],"ltp":1.11,"tv":251595.8,"id":5300737}],"tv":286526.5}]}
{"op":"mcm","clk":"4299804646","pt":1632582157725,"mc":[{"id":"1.188136695","rc":[{"trd":[[1.11,113.45]],"batb":[[0,1.11,17.63],[1,1.1,13.13],[2,1.09,40.84]],"ltp":1.11,"tv":251601.29,"id":5300737},{"trd":[[10.5,0.21]],"ltp":10.5,"tv":34930.9,"id":2497008}],"tv":286532.19}]}
{"op":"mcm","clk":"4299804843","pt":1632582158751,"mc":[{"id":"1.188136695","rc":[{"trd":[[1.11,145.32]],"batb":[[0,1.11,1.51],[1,1.1,13.33]],"ltp":1.11,"tv":251633.15,"id":5300737},{"trd":[[10.5,0.25]],"ltp":10.5,"tv":34930.94,"id":2497008}],"tv":286564.1}]}
{"op":"mcm","clk":"4299805050","pt":1632582159638,"mc":[{"id":"1.188136695","rc":[{"trd":[[1.11,149.35]],"batb":[[0,1.1,15.3],[1,1.09,42.6],[2,1.08,5.64]],"ltp":1.11,"tv":251637.18,"id":5300737},{"batl":[[2,15.5,50.13]],"ltp":10.5,"tv":34930.94,"id":2497008}],"tv":286568.13}]}
{"op":"mcm","clk":"4299805248","pt":1632582160648,"mc":[{"id":"1.188136695","rc":[{"trd":[[1.1,4087.96]],"batb":[[0,1.11,5.26],[1,1.1,17.24],[2,1.09,42.6]],"ltp":1.1,"tv":251638.38,"id":5300737},{"batl":[[0,12,2],[1,14.5,40.32],[2,15,34.42]],"ltp":10.5,"tv":34930.94,"id":2497008}],"tv":286569.33}]}
{"op":"mcm","clk":"4299805719","pt":1632582162750,"mc":[{"id":"1.188136695","rc":[{"batb":[[1,1.1,17.94],[2,1.09,57.82]],"ltp":1.1,"tv":251638.38,"id":5300737},{"batl":[[0,11,15],[1,12,2],[2,14.5,40.32]],"ltp":10.5,"tv":34930.94,"id":2497008}]}]}
{"op":"mcm","clk":"4299805878","pt":1632582163544,"mc":[{"id":"1.188136695","rc":[{"trd":[[1.11,157.07]],"batb":[[0,1.1,17.94],[1,1.09,70.11],[2,1.08,5.64]],"batl":[[0,1.11,8.71],[1,1.13,857.12]],"ltp":1.11,"tv":251646.1,"id":5300737},{"batb":[[0,9.2,5.57],[2,8,2.58]],"ltp":10.5,"tv":34930.94,"id":2497008}],"tv":286577.05}]}
{"op":"mcm","clk":"4299806104","pt":1632582164581,"mc":[{"id":"1.188136695","rc":[{"trd":[[1.07,2039.93],[1.08,11.28],[1.09,6715.09],[1.1,4273.85]],"batb":[[0,1.07,3999.38],[1,1.06,13123.22],[2,1.05,4498.33]],"batl":[[0,1.09,2681.78],[1,1.11,8.71],[2,1.13,857.12]],"ltp":1.09,"tv":254060.12,"id":5300737},{"trd":[[11,212.57],[12,9.19]],"batl":[[0,14.5,40.32],[1,15,34.42],[2,15.5,47.42]],"ltp":12.0,"tv":34947.94,"id":2497008}],"tv":289008.07}]}
{"op":"mcm","clk":"4299806368","pt":1632582165745,"mc":[{"id":"1.188136695","rc":[{"trd":[[1.09,6725.16]],"batl":[[0,1.09,2676.74],[1,1.11,60.47]],"ltp":1.09,"tv":254070.2,"id":5300737},{"batb":[[0,13,22.07],[1,12.5,21.42],[2,12,21.42]],"batl":[[0,14.5,3]],"ltp":12.0,"tv":34947.94,"id":2497008}],"tv":289018.15}]}
{"op":"mcm","clk":"4299806572","pt":1632582166749,"mc":[{"id":"1.188136695","rc":[{"trd":[[1.08,15.97],[1.09,6732.18]],"batl":[[0,1.08,2760.78],[1,1.09,3872.43],[2,1.11,67.64]],"ltp":1.08,"tv":254081.92,"id":5300737},{"batb":[[0,14,83.96],[1,13,132.41],[2,12.5,128.51]],"ltp":12.0,"tv":34947.94,"id":2497008}],"tv":289029.86}]}
{"op":"mcm","clk":"4299806807","pt":1632582167789,"mc":[{"id":"1.188136695","rc":[{"batb":[[1,1.06,13133.22]],"batl":[[2,1.1,3000]],"ltp":1.08,"tv":254081.92,"id":5300737},{"trd":[[14,6.96]],"batb":[[0,14,80.48]],"ltp":14.0,"tv":34954.9,"id":2497008}],"tv":289036.82}]}
{"op":"mcm","clk":"4299807018","pt":1632582168745,"mc":[{"id":"1.188136695","rc":[{"batl":[[0,1.08,4776.61],[1,1.09,1199.2]],"ltp":1.08,"tv":254081.92,"id":5300737}]}]}
{"op":"mcm","clk":"4299807200","pt":1632582169575,"mc":[{"id":"1.188136695","rc":[{"trd":[[1.08,20.67]],"batl":[[0,1.08,5631.38]],"ltp":1.08,"tv":254086.61,"id":5300737}],"tv":289041.52}]}
{"op":"mcm","clk":"4299807428","pt":1632582170565,"mc":[{"id":"1.188136695","rc":[{"batb":[[0,1.07,4676.03]],"batl":[[0,1.08,6788.79],[2,1.1,55.11]],"ltp":1.08,"tv":254086.61,"id":5300737}]}]}
{"op":"mcm","clk":"4299807688","pt":1632582171768,"mc":[{"id":"1.188136695","rc":[{"trd":[[1.07,2391.95]],"batb":[[0,1.07,4608.79],[1,1.06,13502.35],[2,1.05,4500.04]],"batl":[[1,1.09,1200.91],[2,1.1,146.82]],"ltp":1.07,"tv":254438.64,"id":5300737},{"trd":[[14,12.02]],"batb":[[0,14,85.18]],"batl":[[1,15.5,47.42],[2,16.5,22.86]],"ltp":14.0,"tv":34959.96,"id":2497008}],"tv":289398.6}]}
{"op":"mcm","clk":"4299807868","pt":1632582172557,"mc":[{"id":"1.188136695","rc":[{"trd":[[1.08,24.19]],"batb":[[1,1.06,13492.04]],"batl":[[0,1.08,7446.03],[1,1.09,2131.74],[2,1.1,1136.79]],"ltp":1.08,"tv":254442.16,"id":5300737}],"tv":289402.12}]}
