{"op":"mcm","clk":"4289741094","pt":1632493206185,"mc":[{"id":"1.188075669","rc":[{"batb":[[2,1.35,35.47]],"batl":[[0,1.54,21.75],[1,1.57,22.5],[2,1.58,5]],"ltp":1.46,"tv":11200.51,"id":9631939},{"batb":[[0,2.9,169.13],[1,2.84,2.22],[2,2.74,2.52]],"batl":[[0,3.9,2],[1,3.95,3],[2,4.1,3]],"ltp":3.15,"tv":789.46,"id":9454286}]}]}
{"op":"mcm","clk":"4289741186","pt":1632493207186,"mc":[{"id":"1.188075669","rc":[{"batb":[[2,1.33,7]],"ltp":1.46,"tv":11200.51,"id":9631939},{"batl":[[0,3.95,3],[1,4.1,3],[2,4.2,4]],"ltp":3.15,"tv":789.46,"id":9454286}]}]}
{"op":"mcm","clk":"4289741268","pt":1632493208183,"mc":[{"id":"1.188075669","rc":[{"trd":[[1.45,138.39],[1.51,2119.06]],"batb":[[0,1.43,4.38],[1,1.33,7],[2,1.32,499.62]],"batl":[[0,1.45,102.18],[1,1.54,21.75],[2,1.57,22.5]],"ltp":1.45,"tv":11213.65,"id":9631939},{"batl":[[0,3.8,44.41],[1,3.95,3],[2,4.1,3]],"ltp":3.15,"tv":789.46,"id":9454286}],"tv":12003.12}]}
{"op":"mcm","clk":"4289741352","pt":1632493209084,"mc":[{"id":"1.188075669","rc":[{"batb":[[1,1.35,275.67],[2,1.34,297.61]],"batl":[[0,1.55,238.43],[1,1.56,152.34],[2,1.58,5]],"ltp":1.45,"tv":11213.65,"id":9631939},{"batb":[[1,2.74,2.52],[2,2.72,3]],"batl":[[0,3.95,3],[1,4.1,3],[2,4.2,4]],"ltp":3.15,"tv":789.46,"id":9454286}]}]}
{"op":"mcm","clk":"4289741443","pt":1632493210200,"mc":[{"id":"1.188075669","rc":[{"batb":[[1,1.35,310.54]],"batl":[[0,1.58,5],[1,1.76,4.63],[2,100,0.73]],"ltp":1.45,"tv":11213.65,"id":9631939},{"batl":[[0,3.9,2],[1,3.95,3],[2,4.1,3]],"ltp":3.15,"tv":789.46,"id":9454286}]}]}
{"op":"mcm","clk":"4289741531","pt":1632493211201,"mc":[{"id":"1.188075669","rc":[{"trd":[[1.35,59.04],[1.37,8.76],[1.43,331.47]],"batb":[[0,1.35,301.35],[1,1.34,297.61],[2,1.33,1280.83]],"batl":[[0,1.37,17.27],[1,1.38,2775.78],[2,1.39,932.03]],"ltp":1.37,"tv":11275.62,"id":9631939},{"batb":[[0,3.6,5.44],[1,3.5,129.8],[2,2.9,169.13]],"batl":[[1,4.1,3],[2,4.2,4]],"ltp":3.15,"tv":789.46,"id":9454286}],"tv":12065.08}]}
{"op":"mcm","clk":"4289741633","pt":1632493212202,"mc":[{"id":"1.188075669","rc":[{"trd":[[1.37,26.29]],"batb":[[2,1.33,1385.27]],"batl":[[0,1.37,8.51],[1,1.38,433.87]],"ltp":1.37,"tv":11293.14,"id":9631939},{"batb":[[0,3.75,89.67],[1,3.6,5.44],[2,3.5,129.8]],"batl":[[1,4,34.64],[2,4.1,3]],"ltp":3.15,"tv":789.46,"id":9454286}],"tv":12082.61}]}
{"op":"mcm","clk":"4289741736","pt":1632493213096,"mc":[{"id":"1.188075669","rc":[{"trd":[[1.37,39.43]],"batl":[[0,1.37,1.94]],"ltp":1.37,"tv":11306.28,"id":9631939}],"tv":12095.75}]}
{"op":"mcm","clk":"4289741845","pt":1632493214083,"mc":[{"id":"1.188075669","rc":[{"trd":[[1.37,45.75]],"batl":[[0,1.38,433.87],[1,1.39,932.03],[2,1.4,992.22]],"ltp":1.37,"tv":11312.61,"id":9631939},{"trd":[[3.75,0.89]],"batb":[[0,3.75,88.78],[2,3.55,3]],"ltp":3.75,"tv":790.35,"id":9454286}],"tv":12102.96}]}
{"op":"mcm","clk":"4289742091","pt":1632493216985,"mc":[{"id":"1.188075669","rc":[{"batb":[[0,1.36,259],[1,1.35,301.35],[2,1.34,297.61]],"batl":[[0,1.38,589.3]],"ltp":1.37,"tv":11312.61,"id":9631939}]}]}
{"op":"mcm","clk":"4289742128","pt":1632493217521,"mc":[{"id":"1.188075669","rc":[{"batl":[[0,1.38,482.93]],"ltp":1.37,"tv":11312.61,"id":9631939}]}]}
{"op":"mcm","clk":"4289742374","pt":1632493220199,"mc":[{"id":"1.188075669","rc":[{"batb":[[0,1.36,550]],"batl":[[2,1.4,1007.22]],"ltp":1.37,"tv":11312.61,"id":9631939}]}]}
{"op":"mcm","clk":"4289742469","pt":1632493221209,"mc":[{"id":"1.188075669","rc":[{"trd":[[1.37,49.27]],"batb":[[1,1.35,288.32]],"ltp":1.37,"tv":11316.12,"id":9631939},{"trd":[[3.75,2.18]],"batb":[[0,3.75,87.49]],"ltp":3.75,"tv":791.64,"id":9454286}],"tv":12107.76}]}
{"op":"mcm","clk":"4289742661","pt":1632493222993,"mc":[{"id":"1.188075669","rc":[{"batl":[[0,1.38,280.66]],"ltp":1.37,"tv":11316.12,"id":9631939}]}]}
{"op":"mcm","clk":"4289742778","pt":1632493224197,"mc":[{"id":"1.188075669","rc":[{"batb":[[0,1.36,567.02]],"batl":[[0,1.38,296.79]],"ltp":1.37,"tv":11316.12,"id":9631939}]}]}
{"op":"mcm","clk":"4289742796","pt":1632493224418,"mc":[{"id":"1.188075669","rc":[{"batb":[[0,1.36,550]],"batl":[[0,1.38,280.66]],"ltp":1.37,"tv":11316.12,"id":9631939}]}]}
{"op":"mcm","clk":"4289742944","pt":1632493226000,"mc":[{"id":"1.188075669","rc":[{"trd":[[1.36,1.68],[1.37,49.9]],"batb":[[0,1.36,549.16]],"ltp":1.36,"tv":11318.44,"id":9631939},{"trd":[[3.75,2.41]],"batb":[[0,3.75,87.26]],"ltp":3.75,"tv":791.87,"id":9454286}],"tv":12110.31}]}
{"op":"mcm","clk":"4289743228","pt":1632493229205,"mc":[{"id":"1.188075669","rc":[{"batb":[[1,1.33,104.44],[2,1.22,60.34]],"batl":[[0,1.4,15],[1,1.48,29.49],[2,1.52,28.51]],"ltp":1.36,"tv":11318.44,"id":9631939},{"batb":[[0,3.5,6],[1,3.2,130.84],[2,3.05,2.29]],"batl":[[0,4,34.64],[1,5.5,117.14],[2,5.6,2]],"ltp":3.75,"tv":791.87,"id":9454286}]}]}
{"op":"mcm","clk":"4289743322","pt":1632493230205,"mc":[{"id":"1.188075669","rc":[{"batb":[[0,1.22,60.73],[1,1.21,786.15],[2,1.17,144.01]],"batl":[[0,1.48,29.49],[1,1.52,28.51],[2,1.58,5]],"ltp":1.36,"tv":11318.44,"id":9631939},{"batb":[[0,3.2,130.84],[1,3.05,2.29],[2,2.92,2.44]],"batl":[[0,5.5,117.14],[1,5.6,2],[2,5.8,2]],"ltp":3.75,"tv":791.87,"id":9454286}]}]}
{"op":"mcm","clk":"4289743507","pt":1632493232002,"mc":[{"id":"1.188075669","rc":[{"batb":[[0,1.24,240.81],[1,1.23,477.24],[2,1.22,60.34]],"batl":[[0,1.47,211.77],[1,1.48,216.43],[2,1.52,28.51]],"ltp":1.36,"tv":11318.44,"id":9631939}]}]}
{"op":"mcm","clk":"4289743626","pt":1632493233218,"mc":[{"id":"1.188075669","rc":[{"batb":[[0,1.22,60.73],[1,1.21,786.15],[2,1.17,144.01]],"ltp":1.36,"tv":11318.44,"id":9631939}]}]}
{"op":"mcm","clk":"4289743751","pt":1632493234212,"mc":[{"id":"1.188075669","rc":[{"batb":[[0,1.44,8.76],[1,1.22,71.12],[2,1.21,798.15]],"ltp":1.36,"tv":11318.44,"id":9631939},{"batl":[[0,5.5,119.14]],"ltp":3.75,"tv":791.87,"id":9454286}]}]}
{"op":"mcm","clk":"4289743832","pt":1632493235112,"mc":[{"id":"1.188075669","rc":[{"batb":[[0,1.45,4.38],[1,1.44,8.76],[2,1.41,6.57]],"ltp":1.36,"tv":11318.44,"id":9631939},{"batl":[[0,5.2,3],[1,5.5,119.14],[2,5.6,2]],"ltp":3.75,"tv":791.87,"id":9454286}]}]}
{"op":"mcm","clk":"4289743938","pt":1632493236207,"mc":[{"id":"1.188075669","rc":[{"batb":[[2,1.43,4809.89]],"ltp":1.36,"tv":11318.44,"id":9631939},{"batb":[[1,3.15,4.7],[2,3.05,574.5]],"batl":[[0,3.25,7.2],[1,3.4,703.12],[2,3.45,272.98]],"ltp":3.75,"tv":791.87,"id":9454286}]}]}
{"op":"mcm","clk":"4289744036","pt":1632493237205,"mc":[{"id":"1.188075669","rc":[{"trd":[[1.44,511.15],[1.45,147.16]],"batb":[[0,1.45,2.19],[1,1.43,647.48],[2,1.42,227.37]],"batl":[[1,1.48,231.43]],"ltp":1.44,"tv":11352.71,"id":9631939},{"trd":[[3.25,10.94]],"batb":[[2,3.1,7.14]],"batl":[[0,3.25,3.66],[1,3.4,281.24]],"ltp":3.25,"tv":795.41,"id":9454286}],"tv":12148.13}]}
{"op":"mcm","clk":"4289744109","pt":1632493238132,"mc":[{"id":"1.188075669","rc":[{"batl":[[0,1.46,35.85],[1,1.47,211.77],[2,1.48,231.43]],"ltp":1.44,"tv":11352.71,"id":9631939}]}]}
{"op":"mcm","clk":"4289744278","pt":1632493240124,"mc":[{"id":"1.188075669","rc":[{"batb":[[0,1.45,283.19]],"ltp":1.44,"tv":11352.71,"id":9631939},{"trd":[[3.25,17.66]],"batl":[[0,3.4,281.54],[1,3.45,272.98],[2,3.5,272.98]],"ltp":3.25,"tv":802.13,"id":9454286}],"tv":12154.85}]}
{"op":"mcm","clk":"4289744366","pt":1632493241128,"mc":[{"id":"1.188075669","rc":[{"trd":[[1.45,184.94]],"batb":[[0,1.45,264.3]],"ltp":1.45,"tv":11390.49,"id":9631939}],"tv":12192.63}]}
{"op":"mcm","clk":"4289744646","pt":1632493245113,"mc":[{"id":"1.188075669","rc":[{"batl":[[2,3.5,310.92]],"ltp":3.25,"tv":802.13,"id":9454286}]}]}
{"op":"mcm","clk":"4289744834","pt":1632493247111,"mc":[{"id":"1.188075669","rc":[{"batb":[[1,3.1,7.14],[2,3.05,574.5]],"batl":[[0,3.4,281.24]],"ltp":3.25,"tv":802.13,"id":9454286}]}]}
{"op":"mcm","clk":"4289744919","pt":1632493248008,"mc":[{"id":"1.188075669","rc":[{"batb":[[1,1.43,288.65]],"ltp":1.45,"tv":11390.49,"id":9631939}]}]}
{"op":"mcm","clk":"4289745072","pt":1632493250041,"mc":[{"id":"1.188075669","rc":[{"batb":[[0,3.2,136.46]],"batl":[[0,3.3,5.96],[1,3.4,281.24],[2,3.45,272.98]],"ltp":3.25,"tv":802.13,"id":9454286}]}]}
{"op":"mcm","clk":"4289745091","pt":1632493250311,"mc":[{"id":"1.188075669","rc":[{"trd":[[1.45,186.2]],"batb":[[0,1.45,263.67]],"ltp":1.45,"tv":11391.75,"id":9631939},{"batb":[[0,3.2,130.84]],"batl":[[0,3.4,281.24],[1,3.45,272.98],[2,3.5,310.92]],"ltp":3.25,"tv":802.13,"id":9454286}],"tv":12193.89}]}
{"op":"mcm","clk":"4289745367","pt":1632493253241,"mc":[{"id":"1.188075669","rc":[{"batb":[[0,3.2,136.46]],"batl":[[0,3.3,5.96],[1,3.4,281.24],[2,3.45,272.98]],"ltp":3.25,"tv":802.13,"id":9454286}]}]}
{"op":"mcm","clk":"4289745583","pt":1632493256034,"mc":[{"id":"1.188075669","rc":[{"batb":[[0,1.4,94.86],[1,1.34,35.61],[2,1.32,459.23]],"batl":[[0,1.48,15],[1,1.51,34.5],[2,1.52,28.51]],"ltp":1.45,"tv":11391.75,"id":9631939},{"batb":[[0,3.1,7.14],[1,2.96,2.13],[2,2.94,165.08]],"batl":[[0,3.5,37.94],[1,3.95,2],[2,4.4,2]],"ltp":3.25,"tv":802.13,"id":9454286}]}]}
{"op":"mcm","clk":"4289745708","pt":1632493257439,"mc":[{"id":"1.188075669","rc":[{"batb":[[0,1.32,459.62],[1,1.3,38.18],[2,1.25,8]],"batl":[[0,1.52,28.51],[1,1.53,30.5],[2,1.58,5]],"ltp":1.45,"tv":11391.75,"id":9631939},{"batb":[[0,2.94,165.08],[1,2.92,2.44],[2,2.88,2.46]],"batl":[[0,4.4,2],[1,4.9,128.56],[2,5.2,3]],"ltp":3.25,"tv":802.13,"id":9454286}]}]}
{"op":"mcm","clk":"4289746018","pt":1632493261129,"mc":[{"id":"1.188075669","rc":[{"trd":[[1.37,50.68]],"batb":[[0,1.34,4],[1,1.33,6],[2,1.32,468.23]],"batl":[[0,1.35,1.8],[1,1.37,2.19],[2,1.38,2.19]],"ltp":1.37,"tv":11392.53,"id":9631939},{"batl":[[0,3.95,2],[1,4.2,2],[2,4.4,2]],"ltp":3.25,"tv":802.13,"id":9454286}],"tv":12194.66}]}
{"op":"mcm","clk":"4289746090","pt":1632493261967,"mc":[{"id":"1.188075669","rc":[{"trd":[[1.35,60.85],[1.37,52.87],[1.38,6.57],[1.39,4.38],[1.41,192.28]],"batb":[[0,1.41,327.84],[1,1.4,242.65],[2,1.34,4]],"batl":[[0,1.45,217.11],[1,1.46,197.5],[2,1.52,28.51]],"ltp":1.41,"tv":11416.24,"id":9631939},{"trd":[[3.55,1.72],[3.6,0.84],[3.7,0.81],[3.85,0.63]],"ltp":3.55,"tv":806.13,"id":9454286}],"tv":12222.38}]}
{"op":"mcm","clk":"4289746136","pt":1632493262441,"mc":[{"id":"1.188075669","rc":[{"trd":[[1.41,201.04]],"batb":[[0,1.41,323.46]],"ltp":1.41,"tv":11425.01,"id":9631939}],"tv":12231.14}]}
{"op":"mcm","clk":"4289746269","pt":1632493263966,"mc":[{"id":"1.188075669","rc":[{"trd":[[1.41,222.95]],"batb":[[0,1.41,312.51]],"batl":[[2,1.51,135.17]],"ltp":1.41,"tv":11446.91,"id":9631939},{"batb":[[0,2.96,69.1],[1,2.94,165.08],[2,2.92,2.44]],"batl":[[1,4,10],[2,4.2,2]],"ltp":3.55,"tv":806.13,"id":9454286}],"tv":12253.04}]}
{"op":"mcm","clk":"4289746361","pt":1632493265126,"mc":[{"id":"1.188075669","rc":[{"trd":[[1.35,65.23],[1.38,10.95],[1.42,1626.52]],"batb":[[0,1.34,4],[1,1.33,6],[2,1.32,468.23]],"batl":[[0,1.52,28.51],[1,1.53,30.5],[2,1.58,5]],"ltp":1.42,"tv":11464.43,"id":9631939},{"batb":[[0,2.94,165.08],[1,2.92,2.44],[2,2.88,2.46]],"batl":[[1,4.2,2],[2,4.4,2]],"ltp":3.55,"tv":806.13,"id":9454286}],"tv":12270.57}]}
{"op":"mcm","clk":"4289746446","pt":1632493266133,"mc":[{"id":"1.188075669","rc":[{"trd":[[1.34,4.38]],"batb":[[0,1.33,6],[1,1.32,468.23],[2,1.31,8]],"batl":[[0,1.34,2.19],[1,1.35,6.57],[2,1.36,2.19]],"ltp":1.34,"tv":11468.82,"id":9631939}],"tv":12274.95}]}
{"op":"mcm","clk":"4289746541","pt":1632493267174,"mc":[{"id":"1.188075669","rc":[{"batl":[[2,1.36,8.76]],"ltp":1.34,"tv":11468.82,"id":9631939}]}]}
{"op":"mcm","clk":"4289746653","pt":1632493268172,"mc":[{"id":"1.188075669","rc":[{"trd":[[1.34,8.76]],"batb":[[0,1.34,35.03],[1,1.33,6],[2,1.32,468.23]],"batl":[[0,1.35,6.57],[1,1.36,10.96],[2,1.37,4.38]],"ltp":1.34,"tv":11473.2,"id":9631939},{"batb":[[0,2.96,2.13],[1,2.94,165.08],[2,2.92,2.44]],"batl":[[0,3.95,4]],"ltp":3.55,"tv":806.13,"id":9454286}],"tv":12279.33}]}
{"op":"mcm","clk":"4289746743","pt":1632493269070,"mc":[{"id":"1.188075669","rc":[{"batb":[[0,1.34,363.62],[1,1.33,316.59]],"batl":[[1,1.36,15.34],[2,1.37,6.57]],"ltp":1.34,"tv":11473.2,"id":9631939},{"batb":[[0,2.94,165.08],[1,2.92,2.44],[2,2.88,2.46]],"batl":[[0,3.95,2]],"ltp":3.55,"tv":806.13,"id":9454286}]}]}
{"op":"mcm","clk":"4289746833","pt":1632493269967,"mc":[{"id":"1.188075669","rc":[{"batb":[[1,1.33,310.59]],"batl":[[1,1.36,24.1]],"ltp":1.34,"tv":11473.2,"id":9631939},{"batl":[[0,4.2,2],[1,4.4,2],[2,5.2,3]],"ltp":3.55,"tv":806.13,"id":9454286}]}]}
{"op":"mcm","clk":"4289746948","pt":1632493271135,"mc":[{"id":"1.188075669","rc":[{"trd":[[1.34,53.54]],"batb":[[0,1.34,359.26],[2,1.32,3936.17]],"batl":[[1,1.36,46.41]],"ltp":1.34,"tv":11517.98,"id":9631939},{"batb":[[0,3.65,1047.94],[1,3.6,1238.17],[2,3.55,1017.12]],"ltp":3.55,"tv":806.13,"id":9454286}],"tv":12324.11}]}
{"op":"mcm","clk":"4289747020","pt":1632493272135,"mc":[{"id":"1.188075669","rc":[{"trd":[[1.35,69.23]],"batb":[[2,1.32,1868.95]],"batl":[[0,1.35,4.57]],"ltp":1.35,"tv":11521.98,"id":9631939},{"batb":[[0,3.8,87.73],[1,3.65,261.98],[2,3.6,475.33]],"batl":[[0,4.2,35.54],[2,4.7,8.09]],"ltp":3.55,"tv":806.13,"id":9454286}],"tv":12328.11}]}
{"op":"mcm","clk":"4289747096","pt":1632493273035,"mc":[{"id":"1.188075669","rc":[{"batl":[[1,1.36,48.6]],"ltp":1.35,"tv":11521.98,"id":9631939},{"batl":[[0,4.1,10],[1,4.2,35.54],[2,4.4,2]],"ltp":3.55,"tv":806.13,"id":9454286}]}]}
{"op":"mcm","clk":"4289747169","pt":1632493273981,"mc":[{"id":"1.188075669","rc":[{"batl":[[1,1.36,50.8]],"ltp":1.35,"tv":11521.98,"id":9631939}]}]}
{"op":"mcm","clk":"4289747234","pt":1632493274776,"mc":[{"id":"1.188075669","rc":[{"trd":[[1.35,78.37]],"batb":[[0,1.34,359.89]],"batl":[[0,1.36,50.8],[1,1.37,6.57],[2,1.38,641.54]],"ltp":1.35,"tv":11531.12,"id":9631939},{"batl":[[0,3.85,3.05],[1,4.1,10],[2,4.2,35.54]],"ltp":3.55,"tv":806.13,"id":9454286}],"tv":12337.25}]}
{"op":"mcm","clk":"4289747356","pt":1632493276144,"mc":[{"id":"1.188075669","rc":[{"batl":[[0,4.1,10],[1,4.2,35.54],[2,4.4,2]],"ltp":3.55,"tv":806.13,"id":9454286}]}]}
{"op":"mcm","clk":"4289747429","pt":1632493276986,"mc":[{"id":"1.188075669","rc":[{"batb":[[0,1.35,1.02],[1,1.34,467.26],[2,1.33,310.59]],"batl":[[0,1.36,17.93],[1,1.38,641.54],[2,1.39,241.88]],"ltp":1.35,"tv":11531.12,"id":9631939}]}]}
{"op":"mcm","clk":"4289747706","pt":1632493279979,"mc":[{"id":"1.188075669","rc":[{"batb":[[1,1.34,540.26]],"ltp":1.35,"tv":11531.12,"id":9631939},{"batb":[[2,3.6,481.09]],"ltp":3.55,"tv":806.13,"id":9454286}]}]}
{"op":"mcm","clk":"4289748013","pt":1632493283183,"mc":[{"id":"1.188075669","rc":[{"batb":[[1,1.34,689.26]],"batl":[[1,1.38,442.03]],"ltp":1.35,"tv":11531.12,"id":9631939}]}]}
{"op":"mcm","clk":"4289748322","pt":1632493287062,"mc":[{"id":"1.188075669","rc":[{"batb":[[1,1.34,671.23]],"batl":[[0,1.38,442.03],[1,1.39,241.88],[2,1.46,34]],"ltp":1.35,"tv":11531.12,"id":9631939},{"batb":[[1,3.6,11.15],[2,3.25,126.28]],"batl":[[0,4.2,35.54],[1,4.4,2],[2,5.8,2]],"ltp":3.55,"tv":806.13,"id":9454286}]}]}
{"op":"mcm","clk":"4289748393","pt":1632493288064,"mc":[{"id":"1.188075669","rc":[{"batb":[[1,1.32,106.06],[2,1.21,802.18]],"batl":[[0,1.38,15],[1,1.46,34],[2,1.5,32.86]],"ltp":1.35,"tv":11531.12,"id":9631939},{"batb":[[0,3.6,5.76],[1,3.25,126.28],[2,3.15,11.06]],"batl":[[0,4.2,33.54],[1,5.8,2],[2,6,108.1]],"ltp":3.55,"tv":806.13,"id":9454286}]}]}
{"op":"mcm","clk":"4289748470","pt":1632493288964,"mc":[{"id":"1.188075669","rc":[{"batb":[[1,1.21,802.18],[2,1.17,144.01]],"batl":[[0,1.46,34],[1,1.5,32.86],[2,1.52,28.51]],"ltp":1.35,"tv":11531.12,"id":9631939},{"batb":[[0,3.25,126.28],[1,3.15,11.06],[2,3,12.5]],"batl":[[0,5.8,2],[1,6,108.1],[2,7,2]],"ltp":3.55,"tv":806.13,"id":9454286}]}]}
{"op":"mcm","clk":"4289748654","pt":1632493290903,"mc":[{"id":"1.188075669","rc":[{"batb":[[1,1.23,517.95],[2,1.22,511.59]],"batl":[[0,1.46,235.89],[1,1.47,192.38],[2,1.5,32.86]],"ltp":1.35,"tv":11531.12,"id":9631939}]}]}
{"op":"mcm","clk":"4289748727","pt":1632493291486,"mc":[{"id":"1.188075669","rc":[{"batb":[[0,1.21,802.57],[1,1.17,144.01],[2,1.16,76.28]],"batl":[[0,1.46,34],[1,1.5,32.86],[2,1.52,28.51]],"ltp":1.35,"tv":11531.12,"id":9631939},{"batl":[[0,5.8,4]],"ltp":3.55,"tv":806.13,"id":9454286}]}]}
{"op":"mcm","clk":"4289748870","pt":1632493293212,"mc":[{"id":"1.188075669","rc":[{"batb":[[0,1.44,2.19],[1,1.21,802.57],[2,1.17,144.01]],"ltp":1.35,"tv":11531.12,"id":9631939}]}]}
{"op":"mcm","clk":"4289748963","pt":1632493294210,"mc":[{"id":"1.188075669","rc":[{"trd":[[1.44,537.44]],"batb":[[0,1.43,2.19]],"ltp":1.44,"tv":11557.41,"id":9631939},{"batl":[[0,5.4,3],[1,5.8,4],[2,6,108.1]],"ltp":3.55,"tv":806.13,"id":9454286}],"tv":12363.54}]}
{"op":"mcm","clk":"4289749069","pt":1632493295211,"mc":[{"id":"1.188075669","rc":[{"trd":[[1.35,105.44],[1.43,335.85]],"batb":[[0,1.32,270.34],[1,1.31,334.48],[2,1.27,187.82]],"batl":[[0,1.35,260.25],[1,1.36,269.1],[2,1.46,34]],"ltp":1.35,"tv":11588.85,"id":9631939},{"batb":[[0,3.3,70.84],[1,3.25,126.28],[2,3.15,11.06]],"ltp":3.55,"tv":806.13,"id":9454286}],"tv":12394.99}]}
{"op":"mcm","clk":"4289749148","pt":1632493296104,"mc":[{"id":"1.188075669","rc":[{"trd":[[1.35,118.58]],"batb":[[0,1.39,2.19],[1,1.23,10],[2,1.22,10]],"batl":[[0,1.46,34],[1,1.5,32.86],[2,1.52,28.51]],"ltp":1.35,"tv":11602.0,"id":9631939},{"batb":[[0,3.25,126.28],[1,3.15,11.06],[2,3,12.5]],"ltp":3.55,"tv":806.13,"id":9454286}],"tv":12408.13}]}
{"op":"mcm","clk":"4289749233","pt":1632493297203,"mc":[{"id":"1.188075669","rc":[{"batb":[[1,1.38,2.19],[2,1.23,10]],"batl":[[0,1.45,225],[1,1.46,6.75],[2,1.5,6.67]],"ltp":1.35,"tv":11602.0,"id":9631939},{"batb":[[1,3.15,8.83]],"ltp":3.55,"tv":806.13,"id":9454286}]}]}
{"op":"mcm","clk":"4289749306","pt":1632493298091,"mc":[{"id":"1.188075669","rc":[{"trd":[[1.38,15.33],[1.39,8.76]],"batb":[[0,1.23,10],[1,1.22,10],[2,1.21,814.18]],"batl":[[0,1.35,165.62]],"ltp":1.38,"tv":11610.76,"id":9631939},{"batl":[[0,4.9,20],[1,5.4,3],[2,5.8,4]],"ltp":3.55,"tv":806.13,"id":9454286}],"tv":12416.89}]}
{"op":"mcm","clk":"4289749384","pt":1632493299201,"mc":[{"id":"1.188075669","rc":[{"batl":[[0,5.4,3],[1,5.8,4],[2,7,2]],"ltp":3.55,"tv":806.13,"id":9454286}]}]}
{"op":"mcm","clk":"4289749471","pt":1632493300202,"mc":[{"id":"1.188075669","rc":[{"trd":[[1.23,44.7]],"batb":[[0,1.23,509.11],[1,1.22,521.63]],"batl":[[0,1.25,24],[1,1.26,3931.13],[2,1.27,379.51]],"ltp":1.23,"tv":11655.46,"id":9631939},{"batb":[[0,4.8,199.22],[1,4.7,193.36],[2,4.6,193.36]],"batl":[[0,5.7,174.65],[1,5.8,166.82],[2,5.9,162.82]],"ltp":3.55,"tv":806.13,"id":9454286}],"tv":12461.59}]}
{"op":"mcm","clk":"4289749553","pt":1632493301203,"mc":[{"id":"1.188075669","rc":[{"batb":[[0,1.23,634.21]],"batl":[[1,1.26,1644.38]],"ltp":1.23,"tv":11655.46,"id":9631939},{"batb":[[0,5.1,87.31],[1,4.8,199.22],[2,4.7,193.36]],"batl":[[0,5.5,28.28],[1,5.7,174.65],[2,5.8,166.82]],"ltp":3.55,"tv":806.13,"id":9454286}]}]}
{"op":"mcm","clk":"4289749626","pt":1632493302098,"mc":[{"id":"1.188075669","rc":[{"batb":[[0,1.23,509.11]],"ltp":1.23,"tv":11655.46,"id":9631939}]}]}
{"op":"mcm","clk":"4289749709","pt":1632493303197,"mc":[{"id":"1.188075669","rc":[{"batb":[[1,1.22,571.05]],"batl":[[0,1.25,189.62]],"ltp":1.23,"tv":11655.46,"id":9631939},{"batl":[[0,5.7,174.65],[1,5.8,166.82],[2,5.9,162.82]],"ltp":3.55,"tv":806.13,"id":9454286}]}]}
{"op":"mcm","clk":"4289749776","pt":1632493303987,"mc":[{"id":"1.188075669","rc":[{"trd":[[1.25,128.04]],"batl":[[0,1.25,14.28]],"ltp":1.25,"tv":11783.5,"id":9631939}],"tv":12589.63}]}
{"op":"mcm","clk":"4289749879","pt":1632493305095,"mc":[{"id":"1.188075669","rc":[{"batb":[[1,1.22,698.97]],"ltp":1.25,"tv":11783.5,"id":9631939}]}]}
{"op":"mcm","clk":"4289749979","pt":1632493306096,"mc":[{"id":"1.188075669","rc":[{"batl":[[0,5.6,27.97],[1,5.7,174.65],[2,5.8,166.82]],"ltp":3.55,"tv":806.13,"id":9454286}]}]}
{"op":"mcm","clk":"4289750102","pt":1632493307199,"mc":[{"id":"1.188075669","rc":[{"batb":[[1,1.22,759.31],[2,1.21,802.18]],"ltp":1.25,"tv":11783.5,"id":9631939},{"batl":[[0,5.6,29.97]],"ltp":3.55,"tv":806.13,"id":9454286}]}]}
{"op":"mcm","clk":"4289750278","pt":1632493309217,"mc":[{"id":"1.188075669","rc":[{"batl":[[0,5.6,46.13]],"ltp":3.55,"tv":806.13,"id":9454286}]}]}
{"op":"mcm","clk":"4289750358","pt":1632493310012,"mc":[{"id":"1.188075669","rc":[{"batl":[[0,5.6,29.97],[1,5.7,167.76]],"ltp":3.55,"tv":806.13,"id":9454286}]}]}
{"op":"mcm","clk":"4289750521","pt":1632493311802,"mc":[{"id":"1.188075669","rc":[{"batl":[[1,1.26,1447.25]],"ltp":1.25,"tv":11783.5,"id":9631939}]}]}
{"op":"mcm","clk":"4289750643","pt":1632493313119,"mc":[{"id":"1.188075669","rc":[{"trd":[[1.24,0.68]],"batl":[[0,1.24,27.99],[1,1.25,14.28],[2,1.26,1447.25]],"ltp":1.24,"tv":11784.18,"id":9631939},{"batl":[[0,5.5,21.45],[1,5.6,29.97],[2,5.7,167.76]],"ltp":3.55,"tv":806.13,"id":9454286}],"tv":12590.31}]}
{"op":"mcm","clk":"4289750851","pt":1632493315013,"mc":[{"id":"1.188075669","rc":[{"trd":[[1.24,1.94]],"batl":[[0,1.24,27.36]],"ltp":1.24,"tv":11785.44,"id":9631939}],"tv":12591.57}]}
{"op":"mcm","clk":"4289750967","pt":1632493316221,"mc":[{"id":"1.188075669","rc":[{"trd":[[1.24,2.72]],"batl":[[0,1.24,26.97]],"ltp":1.24,"tv":11786.22,"id":9631939}],"tv":12592.35}]}
{"op":"mcm","clk":"4289751111","pt":1632493317807,"mc":[{"id":"1.188075669","rc":[{"batl":[[1,5.6,2]],"ltp":3.55,"tv":806.13,"id":9454286}]}]}
{"op":"mcm","clk":"4289751379","pt":1632493321026,"mc":[{"id":"1.188075669","rc":[{"batl":[[0,5.5,49.73]],"ltp":3.55,"tv":806.13,"id":9454286}]}]}
{"op":"mcm","clk":"4289751580","pt":1632493323239,"mc":[{"id":"1.188075669","rc":[{"batl":[[0,1.25,14.28],[1,1.26,1447.25],[2,1.27,379.51]],"ltp":1.24,"tv":11786.22,"id":9631939},{"batl":[[0,5.5,44.44]],"ltp":3.55,"tv":806.13,"id":9454286}]}]}
{"op":"mcm","clk":"4289751688","pt":1632493324356,"mc":[{"id":"1.188075669","rc":[{"trd":[[1.25,128.3]],"batl":[[0,1.25,14.15]],"ltp":1.25,"tv":11786.48,"id":9631939}],"tv":12592.61}]}
{"op":"mcm","clk":"4289752106","pt":1632493329142,"mc":[{"id":"1.188075669","rc":[{"batb":[[0,1.22,198.26],[1,1.21,53.69],[2,1.19,835.12]],"batl":[[0,1.28,15],[1,1.3,50.4],[2,1.32,43.72]],"ltp":1.25,"tv":11786.48,"id":9631939},{"batb":[[0,4.6,4.16],[1,4.4,119.95],[2,4.3,7.68]],"batl":[[0,5.5,28.28],[2,5.8,4]],"ltp":3.55,"tv":806.13,"id":9454286}]}]}
{"op":"mcm","clk":"4289752143","pt":1632493329558,"mc":[{"id":"1.188075669","rc":[{"batb":[[2,1.19,821.2]],"ltp":1.25,"tv":11786.48,"id":9631939}]}]}
{"op":"mcm","clk":"4289752220","pt":1632493330454,"mc":[{"id":"1.188075669","rc":[{"batb":[[0,1.22,10]],"batl":[[0,1.3,50.4],[1,1.32,43.72],[2,1.34,9]],"ltp":1.25,"tv":11786.48,"id":9631939},{"batb":[[0,4.4,119.95],[1,4.3,7.68],[2,4.1,7.64]],"batl":[[0,5.8,4],[1,7,2],[2,7.4,2]],"ltp":3.55,"tv":806.13,"id":9454286}]}]}
{"op":"mcm","clk":"4289752374","pt":1632493332139,"mc":[{"id":"1.188075669","rc":[{"batb":[[1,1.21,690.65],[2,1.2,514.25]],"batl":[[0,1.3,339.33],[1,1.31,324.42],[2,1.32,43.72]],"ltp":1.25,"tv":11786.48,"id":9631939}]}]}
{"op":"mcm","clk":"4289752435","pt":1632493332737,"mc":[{"id":"1.188075669","rc":[{"batb":[[1,1.21,53.69],[2,1.19,821.2]],"batl":[[0,1.3,50.4],[1,1.32,43.72],[2,1.34,9]],"ltp":1.25,"tv":11786.48,"id":9631939}]}]}
{"op":"mcm","clk":"4289752550","pt":1632493333939,"mc":[{"id":"1.188075669","rc":[{"batb":[[1,1.21,66.69]],"batl":[[0,1.3,57.4]],"ltp":1.25,"tv":11786.48,"id":9631939},{"batb":[[0,4.4,122.95],[1,4.3,9.68]],"batl":[[0,5.6,3],[1,5.8,4],[2,7,2]],"ltp":3.55,"tv":806.13,"id":9454286}]}]}
{"op":"mcm","clk":"4289752639","pt":1632493334850,"mc":[{"id":"1.188075669","rc":[{"batb":[[0,1.24,401.83],[1,1.23,485],[2,1.22,10]],"batl":[[0,1.27,474],[1,1.28,362.34],[2,1.3,57.4]],"ltp":1.25,"tv":11786.48,"id":9631939}]}]}
{"op":"mcm","clk":"4289752846","pt":1632493337151,"mc":[{"id":"1.188075669","rc":[{"batb":[[1,1.23,528.1],[2,1.22,68.84]],"ltp":1.25,"tv":11786.48,"id":9631939},{"batb":[[0,4.5,38.24],[1,4.4,122.95],[2,4.3,9.68]],"batl":[[0,5.6,5]],"ltp":3.55,"tv":806.13,"id":9454286}]}]}
{"op":"mcm","clk":"4289753020","pt":1632493338939,"mc":[{"id":"1.188075669","rc":[{"batb":[[0,1.22,10],[1,1.21,66.69],[2,1.19,821.2]],"batl":[[0,1.3,57.4],[1,1.32,43.72],[2,1.34,9]],"ltp":1.25,"tv":11786.48,"id":9631939},{"batb":[[0,4.4,122.95],[1,4.3,9.68],[2,4.1,7.64]],"batl":[[0,5.6,3]],"ltp":3.55,"tv":806.13,"id":9454286}]}]}
{"op":"mcm","clk":"4289753256","pt":1632493342181,"mc":[{"id":"1.188075669","rc":[{"batb":[[0,1.22,64.34],[1,1.21,703.65],[2,1.2,514.25]],"batl":[[0,1.29,9],[1,1.3,346.33],[2,1.31,324.42]],"ltp":1.25,"tv":11786.48,"id":9631939},{"batl":[[0,5.6,5]],"ltp":3.55,"tv":806.13,"id":9454286}]}]}
{"op":"mcm","clk":"4289753333","pt":1632493343076,"mc":[{"id":"1.188075669","rc":[{"batb":[[0,1.22,10],[1,1.21,66.69],[2,1.19,821.2]],"ltp":1.25,"tv":11786.48,"id":9631939},{"batl":[[0,5.5,2],[1,5.6,3],[2,5.8,4]],"ltp":3.55,"tv":806.13,"id":9454286}]}]}
{"op":"mcm","clk":"4289753486","pt":1632493345175,"mc":[{"id":"1.188075669","rc":[{"batb":[[0,1.27,7252.62],[1,1.26,1897.33],[2,1.25,2946.44]],"batl":[[0,1.28,19.54]],"ltp":1.25,"tv":11786.48,"id":9631939},{"batb":[[0,4.5,158.77],[1,4.4,119.95],[2,4.3,9.68]],"batl":[[0,4.8,5.58],[1,5.5,2],[2,5.6,8.36]],"ltp":3.55,"tv":806.13,"id":9454286}]}]}
{"op":"mcm","clk":"4289753593","pt":1632493346174,"mc":[{"id":"1.188075669","rc":[{"batb":[[0,1.27,1025.35],[1,1.26,1892],[2,1.25,736.62]],"batl":[[0,1.28,42.98]],"ltp":1.25,"tv":11786.48,"id":9631939},{"batl":[[0,4.8,36.35]],"ltp":3.55,"tv":806.13,"id":9454286}]}]}
{"op":"mcm","clk":"4289753684","pt":1632493346962,"mc":[{"id":"1.188075669","rc":[{"batl":[[1,1.29,45],[2,1.3,346.33]],"ltp":1.25,"tv":11786.48,"id":9631939},{"batb":[[1,4.4,136.77]],"batl":[[1,5.4,10],[2,5.5,2]],"ltp":3.55,"tv":806.13,"id":9454286}]}]}
{"op":"mcm","clk":"4289753777","pt":1632493347860,"mc":[{"id":"1.188075669","rc":[{"batb":[[1,1.26,1774.34]],"ltp":1.25,"tv":11786.48,"id":9631939},{"batl":[[0,4.8,5.58],[1,5.4,13]],"ltp":3.55,"tv":806.13,"id":9454286}]}]}
{"op":"mcm","clk":"4289753896","pt":1632493349073,"mc":[{"id":"1.188075669","rc":[{"trd":[[1.27,8.76]],"batb":[[0,1.27,1020.97]],"batl":[[2,1.3,339.98]],"ltp":1.27,"tv":11795.24,"id":9631939},{"batb":[[2,4.3,4]],"ltp":3.55,"tv":806.13,"id":9454286}],"tv":12601.37}]}
{"op":"mcm","clk":"4289754006","pt":1632493350179,"mc":[{"id":"1.188075669","rc":[{"trd":[[1.27,13.14]],"batb":[[0,1.27,1162.78]],"ltp":1.27,"tv":11799.62,"id":9631939}],"tv":12605.75}]}
{"op":"mcm","clk":"4289754086","pt":1632493351073,"mc":[{"id":"1.188075669","rc":[{"batl":[[0,4.8,36.35]],"ltp":3.55,"tv":806.13,"id":9454286}]}]}
{"op":"mcm","clk":"4289754233","pt":1632493352708,"mc":[{"id":"1.188075669","rc":[{"batb":[[2,1.25,782.19]],"ltp":1.27,"tv":11799.62,"id":9631939},{"batl":[[1,5,2],[2,5.2,2]],"ltp":3.55,"tv":806.13,"id":9454286}]}]}
{"op":"mcm","clk":"4289754337","pt":1632493353978,"mc":[{"id":"1.188075669","rc":[{"batb":[[0,1.27,1296.78]],"ltp":1.27,"tv":11799.62,"id":9631939}]}]}
{"op":"mcm","clk":"4289754377","pt":1632493354500,"mc":[{"id":"1.188075669","rc":[{"trd":[[1.28,8.44]],"batb":[[0,1.27,1412.25]],"batl":[[0,1.28,38.76]],"ltp":1.28,"tv":11808.06,"id":9631939}],"tv":12614.2}]}
{"op":"mcm","clk":"4289754592","pt":1632493357114,"mc":[{"id":"1.188075669","rc":[{"batb":[[0,1.27,843.22]],"ltp":1.28,"tv":11808.06,"id":9631939}]}]}
{"op":"mcm","clk":"4289754845","pt":1632493360115,"mc":[{"id":"1.188075669","rc":[{"batb":[[0,1.27,393.47],[1,1.25,45.57],[2,1.24,55.02]],"batl":[[0,1.33,15.63],[1,1.35,40.4],[2,1.38,42.5]],"ltp":1.28,"tv":11808.06,"id":9631939},{"batb":[[0,4.1,4.83],[1,3.85,6.97],[2,3.8,87.9]],"batl":[[0,4.8,30.77]],"ltp":3.55,"tv":806.13,"id":9454286}]}]}
{"op":"mcm","clk":"4289754927","pt":1632493361006,"mc":[{"id":"1.188075669","rc":[{"batb":[[0,1.27,115.47]],"batl":[[1,1.38,42.5],[2,1.76,4.63]],"ltp":1.28,"tv":11808.06,"id":9631939},{"batb":[[1,3.8,87.9],[2,3.6,9.49]],"ltp":3.55,"tv":806.13,"id":9454286}]}]}
{"op":"mcm","clk":"4289755025","pt":1632493362217,"mc":[{"id":"1.188075669","rc":[{"batb":[[0,1.24,55.02],[1,1.23,697.94],[2,1.21,53.69]],"batl":[[0,1.33,1.02]],"ltp":1.28,"tv":11808.06,"id":9631939},{"batb":[[0,3.8,87.9],[1,3.6,9.49],[2,2.9,382.66]],"batl":[[0,5.2,2],[1,5.4,3],[2,5.8,2]],"ltp":3.55,"tv":806.13,"id":9454286}]}]}
{"op":"mcm","clk":"4289755110","pt":1632493363216,"mc":[{"id":"1.188075669","rc":[{"batb":[[0,1.24,618.33],[1,1.23,1187.3]],"batl":[[1,1.37,399.24],[2,1.38,293.94]],"ltp":1.28,"tv":11808.06,"id":9631939}]}]}
{"op":"mcm","clk":"4289755182","pt":1632493364006,"mc":[{"id":"1.188075669","rc":[{"batb":[[0,1.24,55.02],[1,1.23,697.94]],"batl":[[0,1.27,90.55],[1,1.38,43.13],[2,1.76,4.63]],"ltp":1.28,"tv":11808.06,"id":9631939}]}]}
{"op":"mcm","clk":"4289755260","pt":1632493365002,"mc":[{"id":"1.188075669","rc":[{"batb":[[0,1.24,67.02]],"batl":[[1,1.36,7.63],[2,1.38,42.5]],"ltp":1.28,"tv":11808.06,"id":9631939},{"batb":[[0,4,3],[1,3.95,3],[2,3.8,90.9]],"batl":[[0,5.2,5]],"ltp":3.55,"tv":806.13,"id":9454286}]}]}
{"op":"mcm","clk":"4289755445","pt":1632493367214,"mc":[{"id":"1.188075669","rc":[{"batb":[[0,1.24,618.33],[1,1.23,1187.3],[2,1.22,485.26]],"batl":[[0,1.26,74.31],[1,1.27,2772.29],[2,1.28,1096.37]],"ltp":1.28,"tv":11808.06,"id":9631939},{"batb":[[0,4.8,8.36],[1,4.5,488.47],[2,4,3]],"batl":[[0,5.2,2],[2,5.5,173.86]],"ltp":3.55,"tv":806.13,"id":9454286}]}]}
{"op":"mcm","clk":"4289755529","pt":1632493368217,"mc":[{"id":"1.188075669","rc":[{"batb":[[1,1.23,1312.4]],"batl":[[0,1.25,4.38],[1,1.26,74.31],[2,1.27,1405.87]],"ltp":1.28,"tv":11808.06,"id":9631939},{"batb":[[0,4.8,107.06],[2,4.4,4.41]],"batl":[[0,5.2,31.27]],"ltp":3.55,"tv":806.13,"id":9454286}]}]}
{"op":"mcm","clk":"4289755539","pt":1632493368324,"mc":[{"id":"1.188075669","rc":[{"batl":[[2,1.27,1408.06]],"ltp":1.28,"tv":11808.06,"id":9631939}]}]}
{"op":"mcm","clk":"4289755663","pt":1632493370026,"mc":[{"id":"1.188075669","rc":[{"batb":[[0,1.24,633.53]],"batl":[[1,1.26,156.66]],"ltp":1.28,"tv":11808.06,"id":9631939},{"batb":[[1,4.6,3],[2,4.5,490.47]],"ltp":3.55,"tv":806.13,"id":9454286}]}]}
{"op":"mcm","clk":"4289755897","pt":1632493373020,"mc":[{"id":"1.188075669","rc":[{"batb":[[0,1.24,1070.53]],"ltp":1.28,"tv":11808.06,"id":9631939},{"batb":[[0,4.8,122.06]],"ltp":3.55,"tv":806.13,"id":9454286}]}]}
{"op":"mcm","clk":"4289755986","pt":1632493374132,"mc":[{"id":"1.188075669","rc":[{"batb":[[2,1.22,537.1]],"batl":[[2,1.27,1407.67]],"ltp":1.28,"tv":11808.06,"id":9631939}]}]}
{"op":"mcm","clk":"4289756128","pt":1632493376135,"mc":[{"id":"1.188075669","rc":[{"batb":[[0,1.24,1509.53]],"batl":[[0,1.26,156.66],[1,1.27,1405.48],[2,1.28,1096.37]],"ltp":1.28,"tv":11808.06,"id":9631939}]}]}
{"op":"mcm","clk":"4289756354","pt":1632493378907,"mc":[{"id":"1.188075669","rc":[{"trd":[[1.24,419.84]],"batb":[[0,1.24,1300.97]],"batl":[[1,1.27,1080.14]],"ltp":1.24,"tv":12225.19,"id":9631939}],"tv":13031.32}]}
{"op":"mcm","clk":"4289756468","pt":1632493380215,"mc":[{"id":"1.188075669","rc":[{"batb":[[0,1.24,1285.77],[2,1.22,51.84]],"batl":[[0,1.26,50.5],[1,1.27,703.67],[2,1.28,730.97]],"ltp":1.24,"tv":12225.19,"id":9631939},{"batb":[[0,4.8,107.06],[2,4.5,2]],"batl":[[2,5.5,86.93]],"ltp":3.55,"tv":806.13,"id":9454286}]}]}
{"op":"mcm","clk":"4289756555","pt":1632493381027,"mc":[{"id":"1.188075669","rc":[{"batb":[[0,1.23,178.73],[1,1.22,51.84],[2,1.21,53.69]],"batl":[[0,1.26,5.75],[1,1.29,15],[2,1.33,55.63]],"ltp":1.24,"tv":12225.19,"id":9631939},{"batb":[[0,4.8,4.48],[1,4.4,4.41],[2,4.1,145.56]],"batl":[[0,5.2,29.27],[1,5.4,2],[2,5.6,2]],"ltp":3.55,"tv":806.13,"id":9454286}]}]}
{"op":"mcm","clk":"4289756665","pt":1632493382030,"mc":[{"id":"1.188075669","rc":[{"batb":[[0,1.22,51.84],[1,1.2,783.66],[2,1.17,70.97]],"batl":[[1,1.33,55.63],[2,1.38,35.75]],"ltp":1.24,"tv":12225.19,"id":9631939},{"batb":[[1,4.1,145.56],[2,4,8.33]],"batl":[[0,5.6,2],[1,7,2],[2,7.2,93.85]],"ltp":3.55,"tv":806.13,"id":9454286}]}]}
{"op":"mcm","clk":"4289756859","pt":1632493384131,"mc":[{"id":"1.188075669","rc":[{"batb":[[0,1.22,385.11],[1,1.21,540.02],[2,1.2,783.66]],"batl":[[1,1.31,6.63],[2,1.32,249.84]],"ltp":1.24,"tv":12225.19,"id":9631939},{"batb":[[1,4.2,5.47],[2,4.1,145.56]],"ltp":3.55,"tv":806.13,"id":9454286}]}]}
{"op":"mcm","clk":"4289756935","pt":1632493385031,"mc":[{"id":"1.188075669","rc":[{"batb":[[0,1.22,391.11],[1,1.21,546.02]],"batl":[[1,1.32,249.84],[2,1.33,358.53]],"ltp":1.24,"tv":12225.19,"id":9631939},{"batb":[[1,4.1,145.56],[2,4,8.33]],"batl":[[0,5.6,4]],"ltp":3.55,"tv":806.13,"id":9454286}]}]}
{"op":"mcm","clk":"4289757274","pt":1632493388834,"mc":[{"id":"1.188075669","rc":[{"batb":[[0,1.22,385.11]],"batl":[[1,1.33,55.63],[2,1.38,35.75]],"ltp":1.24,"tv":12225.19,"id":9631939}]}]}
{"op":"mcm","clk":"4289757360","pt":1632493390130,"mc":[{"id":"1.188075669","rc":[{"batl":[[0,1.24,87],[1,1.26,5.75],[2,1.33,55.63]],"ltp":1.24,"tv":12225.19,"id":9631939},{"batl":[[2,7.4,2]],"ltp":3.55,"tv":806.13,"id":9454286}]}]}
{"op":"mcm","clk":"4289757456","pt":1632493391144,"mc":[{"id":"1.188075669","rc":[{"batl":[[0,1.23,543.87],[1,1.24,3569.28],[2,1.26,5.75]],"ltp":1.24,"tv":12225.19,"id":9631939},{"batb":[[0,5.1,750],[1,5,727.94],[2,4.9,727.94]],"batl":[[0,5.6,2],[1,5.7,6.68],[2,5.9,648.3]],"ltp":3.55,"tv":806.13,"id":9454286}]}]}
{"op":"mcm","clk":"4289757557","pt":1632493392146,"mc":[{"id":"1.188075669","rc":[{"trd":[[1.22,151.62],[1.23,54.7]],"batb":[[0,1.22,309.3]],"batl":[[0,1.23,538.87],[1,1.24,678.38],[2,1.25,422.39]],"ltp":1.22,"tv":12386.81,"id":9631939},{"batb":[[0,5.1,197.58],[1,5,181.98],[2,4.9,181.98]],"batl":[[2,5.9,162.08]],"ltp":3.55,"tv":806.13,"id":9454286}],"tv":13192.94}]}
{"op":"mcm","clk":"4289757643","pt":1632493393049,"mc":[{"id":"1.188075669","rc":[{"batl":[[1,1.24,738.14]],"ltp":1.22,"tv":12386.81,"id":9631939},{"batb":[[0,5.2,81.4],[1,5.1,197.58],[2,5,181.98]],"ltp":3.55,"tv":806.13,"id":9454286}]}]}
{"op":"mcm","clk":"4289757741","pt":1632493394025,"mc":[{"id":"1.188075669","rc":[{"batb":[[1,1.21,676.95],[2,1.2,797.66]],"ltp":1.22,"tv":12386.81,"id":9631939},{"batl":[[1,5.7,34.35]],"ltp":3.55,"tv":806.13,"id":9454286}]}]}
{"op":"mcm","clk":"4289757905","pt":1632493396138,"mc":[{"id":"1.188075669","rc":[{"batl":[[1,1.24,852.65]],"ltp":1.22,"tv":12386.81,"id":9631939},{"batb":[[0,5.2,103.8]],"batl":[[2,5.8,36.32]],"ltp":3.55,"tv":806.13,"id":9454286}]}]}
{"op":"mcm","clk":"4289757922","pt":1632493396344,"mc":[{"id":"1.188075669","rc":[{"batl":[[1,1.24,738.14]],"ltp":1.22,"tv":12386.81,"id":9631939},{"batl":[[2,5.9,162.08]],"ltp":3.55,"tv":806.13,"id":9454286}]}]}
{"op":"mcm","clk":"4289758117","pt":1632493398539,"mc":[{"id":"1.188075669","rc":[{"batb":[[1,1.21,731.64],[2,1.2,851.73]],"ltp":1.22,"tv":12386.81,"id":9631939},{"trd":[[5.6,2.74]],"batl":[[0,5.7,34.98],[1,5.8,2]],"ltp":5.6,"tv":808.87,"id":9454286}],"tv":13195.68}]}
{"op":"mcm","clk":"4289758317","pt":1632493400955,"mc":[{"id":"1.188075669","rc":[{"trd":[[1.22,194.26]],"batb":[[0,1.22,287.98]],"ltp":1.22,"tv":12429.45,"id":9631939}],"tv":13238.32}]}
{"op":"mcm","clk":"4289758566","pt":1632493404149,"mc":[{"id":"1.188075669","rc":[{"trd":[[1.22,198.96]],"batb":[[0,1.22,285.63]],"batl":[[1,1.24,486.43]],"ltp":1.22,"tv":12434.14,"id":9631939}],"tv":13243.01}]}
{"op":"mcm","clk":"4289758774","pt":1632493407059,"mc":[{"id":"1.188075669","rc":[{"batb":[[0,1.22,306.94],[2,1.2,837.73]],"ltp":1.22,"tv":12434.14,"id":9631939}]}]}
{"op":"mcm","clk":"4289758855","pt":1632493408092,"mc":[{"id":"1.188075669","rc":[{"batb":[[0,1.21,191.62],[1,1.2,54.07],[2,1.18,885.39]],"batl":[[0,1.24,92.73],[1,1.26,100.5],[2,1.28,87.18]],"ltp":1.22,"tv":12434.14,"id":9631939},{"batb":[[0,5.1,4.14],[1,4.9,3.84],[2,4.8,7.01]],"batl":[[0,5.7,27.67],[2,6,2]],"ltp":5.6,"tv":808.87,"id":9454286}]}]}
{"op":"mcm","clk":"4289758992","pt":1632493409574,"mc":[{"id":"1.188075669","rc":[{"batb":[[0,1.2,54.07],[1,1.18,885.39],[2,1.17,70.97]],"batl":[[1,1.26,85.5]],"ltp":1.22,"tv":12434.14,"id":9631939},{"batb":[[1,4.8,7.01],[2,4.6,110.17]],"batl":[[0,6,2],[1,7,2],[2,7.4,2]],"ltp":5.6,"tv":808.87,"id":9454286}]}]}
{"op":"mcm","clk":"4289759104","pt":1632493410966,"mc":[{"id":"1.188075669","rc":[{"batb":[[0,1.2,562.3],[1,1.19,613.6],[2,1.18,885.39]],"batl":[[2,1.28,392.05]],"ltp":1.22,"tv":12434.14,"id":9631939}]}]}
{"op":"mcm","clk":"4289759258","pt":1632493412765,"mc":[{"id":"1.188075669","rc":[{"batb":[[0,1.21,60.69],[1,1.2,562.3],[2,1.19,613.6]],"ltp":1.22,"tv":12434.14,"id":9631939},{"batl":[[0,5.8,2],[1,6,2],[2,7,2]],"ltp":5.6,"tv":808.87,"id":9454286}]}]}
{"op":"mcm","clk":"4289759334","pt":1632493413688,"mc":[{"id":"1.188075669","rc":[{"batb":[[0,1.2,562.3],[1,1.19,613.6],[2,1.18,885.39]],"batl":[[2,1.28,87.18]],"ltp":1.22,"tv":12434.14,"id":9631939},{"batl":[[0,6,2],[1,7,2],[2,7.4,2]],"ltp":5.6,"tv":808.87,"id":9454286}]}]}
{"op":"mcm","clk":"4289759506","pt":1632493416064,"mc":[{"id":"1.188075669","rc":[{"batl":[[0,1.22,24.59],[1,1.23,4147.02],[2,1.24,92.73]],"ltp":1.22,"tv":12434.14,"id":9631939},{"batb":[[0,5.7,107.67],[1,5.4,708.34],[2,5.3,687.5]],"batl":[[0,6,6.5],[1,6.4,693.02],[2,6.6,580.08]],"ltp":5.6,"tv":808.87,"id":9454286}]}]}
{"op":"mcm","clk":"4289759599","pt":1632493417170,"mc":[{"id":"1.188075669","rc":[{"batb":[[1,1.19,626.6],[2,1.18,1026.81]],"batl":[[0,1.22,306.22],[1,1.23,812.33]],"ltp":1.22,"tv":12434.14,"id":9631939},{"batb":[[1,5.6,68.75],[2,5.5,12.14]],"batl":[[1,6.4,270.59],[2,6.6,145.02]],"ltp":5.6,"tv":808.87,"id":9454286}]}]}
{"op":"mcm","clk":"4289759744","pt":1632493419091,"mc":[{"id":"1.188075669","rc":[{"batl":[[2,1.24,87]],"ltp":1.22,"tv":12434.14,"id":9631939}]}]}
{"op":"mcm","clk":"4289759910","pt":1632493421090,"mc":[{"id":"1.188075669","rc":[{"batl":[[0,1.22,489.51]],"ltp":1.22,"tv":12434.14,"id":9631939},{"batl":[[1,6.2,34.79],[2,6.4,270.59]],"ltp":5.6,"tv":808.87,"id":9454286}]}]}
{"op":"mcm","clk":"4289759933","pt":1632493421389,"mc":[{"id":"1.188075669","rc":[{"batl":[[0,1.22,390.8]],"ltp":1.22,"tv":12434.14,"id":9631939},{"batl":[[1,6.4,270.59],[2,6.6,145.02]],"ltp":5.6,"tv":808.87,"id":9454286}]}]}
{"op":"mcm","clk":"4289760066","pt":1632493422990,"mc":[{"id":"1.188075669","rc":[{"batb":[[0,1.2,674.3]],"ltp":1.22,"tv":12434.14,"id":9631939}]}]}
{"op":"mcm","clk":"4289760218","pt":1632493424200,"mc":[{"id":"1.188075669","rc":[{"batl":[[1,1.23,819.83],[2,1.24,93.48]],"ltp":1.22,"tv":12434.14,"id":9631939}]}]}
{"op":"mcm","clk":"4289760228","pt":1632493424305,"mc":[{"id":"1.188075669","rc":[{"batb":[[1,1.19,687.31]],"batl":[[1,1.23,920.33],[2,1.24,185.71]],"ltp":1.22,"tv":12434.14,"id":9631939},{"batl":[[1,6.4,272.59]],"ltp":5.6,"tv":808.87,"id":9454286}]}]}
{"op":"mcm","clk":"4289760389","pt":1632493426186,"mc":[{"id":"1.188075669","rc":[{"batb":[[0,1.2,786.3]],"ltp":1.22,"tv":12434.14,"id":9631939}]}]}
{"op":"mcm","clk":"4289760558","pt":1632493428093,"mc":[{"id":"1.188075669","rc":[{"batl":[[1,1.23,591.2]],"ltp":1.22,"tv":12434.14,"id":9631939}]}]}
{"op":"mcm","clk":"4289760719","pt":1632493429982,"mc":[{"id":"1.188075669","rc":[{"trd":[[1.22,202.1]],"batb":[[0,1.2,910.3]],"batl":[[0,1.22,389.23]],"ltp":1.22,"tv":12437.28,"id":9631939}],"tv":13246.15}]}
{"op":"mcm","clk":"4289761099","pt":1632493433998,"mc":[{"id":"1.188075669","rc":[{"batb":[[0,1.2,402.07],[1,1.19,605.9],[2,1.18,141.42]],"batl":[[0,1.22,5.75],[1,1.23,22.5]],"ltp":1.22,"tv":12437.28,"id":9631939},{"batb":[[0,5.5,4.24],[1,5.3,7.76],[2,5.2,83.51]],"batl":[[0,6,2],[1,6.4,27.81],[2,7,2]],"ltp":5.6,"tv":808.87,"id":9454286}]}]}
{"op":"mcm","clk":"4289761203","pt":1632493434995,"mc":[{"id":"1.188075669","rc":[{"batb":[[0,1.2,54.07]],"batl":[[1,1.23,15]],"ltp":1.22,"tv":12437.28,"id":9631939},{"batb":[[1,5.3,3.48]],"ltp":5.6,"tv":808.87,"id":9454286}]}]}
{"op":"mcm","clk":"4289761234","pt":1632493435312,"mc":[{"id":"1.188075669","rc":[{"batb":[[0,1.19,605.9],[1,1.17,1014.91],[2,1.16,76.28]],"batl":[[1,1.24,185.71],[2,1.26,79.75]],"ltp":1.22,"tv":12437.28,"id":9631939},{"batb":[[1,5.2,83.51],[2,5.1,6.58]],"batl":[[0,6.4,2],[1,7,2],[2,7.4,2]],"ltp":5.6,"tv":808.87,"id":9454286}]}]}
{"op":"mcm","clk":"4289761405","pt":1632493437201,"mc":[{"id":"1.188075669","rc":[{"batb":[[0,1.2,14],[1,1.19,502.46],[2,1.17,1014.91]],"batl":[[1,1.23,97.5],[2,1.24,185.71]],"ltp":1.22,"tv":12437.28,"id":9631939},{"batb":[[1,5.3,2.28],[2,5.2,83.51]],"batl":[[0,6,2],[1,6.4,2],[2,7,2]],"ltp":5.6,"tv":808.87,"id":9454286}]}]}
{"op":"mcm","clk":"4289761470","pt":1632493438022,"mc":[{"id":"1.188075669","rc":[{"batl":[[1,1.24,185.71],[2,1.26,79.75]],"ltp":1.22,"tv":12437.28,"id":9631939},{"batb":[[1,5.2,83.51],[2,5.1,6.58]],"ltp":5.6,"tv":808.87,"id":9454286}]}]}
{"op":"mcm","clk":"4289761559","pt":1632493439121,"mc":[{"id":"1.188075669","rc":[{"batb":[[2,1.18,6]],"ltp":1.22,"tv":12437.28,"id":9631939},{"batl":[[1,6.4,218.45]],"ltp":5.6,"tv":808.87,"id":9454286}]}]}
{"op":"mcm","clk":"4289761668","pt":1632493440195,"mc":[{"id":"1.188075669","rc":[{"batb":[[0,1.2,905.34]],"batl":[[1,1.23,440.64],[2,1.24,623.8]],"ltp":1.22,"tv":12437.28,"id":9631939},{"batl":[[1,6.4,4]],"ltp":5.6,"tv":808.87,"id":9454286}]}]}
{"op":"mcm","clk":"4289761741","pt":1632493441206,"mc":[{"id":"1.188075669","rc":[{"batb":[[0,1.2,951.39]],"batl":[[1,1.23,537.14]],"ltp":1.22,"tv":12437.28,"id":9631939},{"batb":[[0,5.5,13.39],[1,5.3,2.28],[2,5.2,83.51]],"batl":[[0,6,11.21]],"ltp":5.6,"tv":808.87,"id":9454286}]}]}
{"op":"mcm","clk":"4289761829","pt":1632493442204,"mc":[{"id":"1.188075669","rc":[{"batb":[[0,1.2,1018.91]],"batl":[[1,1.23,543.64]],"ltp":1.22,"tv":12437.28,"id":9631939},{"batb":[[1,5.3,6.86]],"batl":[[0,6,13.21]],"ltp":5.6,"tv":808.87,"id":9454286}]}]}
{"op":"mcm","clk":"4289761967","pt":1632493443926,"mc":[{"id":"1.188075669","rc":[{"batl":[[0,1.23,543.64],[1,1.24,623.8],[2,1.26,79.75]],"ltp":1.22,"tv":12437.28,"id":9631939},{"batb":[[0,5.3,6.86],[1,5.2,83.51],[2,5.1,6.58]],"ltp":5.6,"tv":808.87,"id":9454286}]}]}
{"op":"mcm","clk":"4289762117","pt":1632493446052,"mc":[{"id":"1.188075669","rc":[{"batb":[[0,1.2,334.52]],"batl":[[0,1.23,103],[1,1.24,185.71]],"ltp":1.22,"tv":12437.28,"id":9631939},{"batl":[[0,6,4]],"ltp":5.6,"tv":808.87,"id":9454286}]}]}
{"op":"mcm","clk":"4289762194","pt":1632493447144,"mc":[{"id":"1.188075669","rc":[{"batb":[[0,1.2,81.52]],"batl":[[0,1.24,185.71],[1,1.26,79.75],[2,1.28,81.09]],"ltp":1.22,"tv":12437.28,"id":9631939},{"batb":[[0,5.4,13.82]],"ltp":5.6,"tv":808.87,"id":9454286}]}]}
{"op":"mcm","clk":"4289762226","pt":1632493447400,"mc":[{"id":"1.188075669","rc":[{"batb":[[0,1.2,14]],"ltp":1.22,"tv":12437.28,"id":9631939},{"batb":[[0,5.2,83.51],[1,5.1,6.58],[2,4.8,2.38]],"batl":[[0,6,2]],"ltp":5.6,"tv":808.87,"id":9454286}]}]}
{"op":"mcm","clk":"4289762360","pt":1632493448930,"mc":[{"id":"1.188075669","rc":[{"batb":[[1,1.19,605.9],[2,1.18,645.42]],"batl":[[1,1.25,529.59],[2,1.26,476.41]],"ltp":1.22,"tv":12437.28,"id":9631939}]}]}
{"op":"mcm","clk":"4289762436","pt":1632493449927,"mc":[{"id":"1.188075669","rc":[{"batb":[[1,1.19,592.9]],"batl":[[0,1.24,195.71]],"ltp":1.22,"tv":12437.28,"id":9631939},{"batb":[[0,5.2,86.51],[1,5.1,9.58]],"ltp":5.6,"tv":808.87,"id":9454286}]}]}
{"op":"mcm","clk":"4289762590","pt":1632493452022,"mc":[{"id":"1.188075669","rc":[{"batb":[[0,1.22,1.95],[1,1.2,76.22],[2,1.19,592.9]],"ltp":1.22,"tv":12437.28,"id":9631939},{"batl":[[0,6,4],[1,6.4,2]],"ltp":5.6,"tv":808.87,"id":9454286}]}]}
{"op":"mcm","clk":"4289762692","pt":1632493453116,"mc":[{"id":"1.188075669","rc":[{"batb":[[1,1.2,14],[2,1.19,604.9]],"batl":[[0,1.23,99],[1,1.24,195.71],[2,1.25,529.59]],"ltp":1.22,"tv":12437.28,"id":9631939},{"batb":[[0,5.3,6.66],[1,5.2,86.51],[2,5.1,9.58]],"batl":[[0,6,2]],"ltp":5.6,"tv":808.87,"id":9454286}]}]}
{"op":"mcm","clk":"4289762717","pt":1632493453452,"mc":[{"id":"1.188075669","rc":[{"batl":[[0,1.24,103.48],[1,1.33,8.63],[2,1.76,4.63]],"ltp":1.22,"tv":12437.28,"id":9631939},{"batb":[[0,5.2,86.51],[1,5.1,9.58],[2,4.1,3]],"batl":[[2,9.8,76.64]],"ltp":5.6,"tv":808.87,"id":9454286}]}]}
{"op":"mcm","clk":"4289762933","pt":1632493456137,"mc":[{"id":"1.188075669","rc":[{"trd":[[1.22,206]],"batb":[[0,1.19,592.9],[1,1.18,639.42],[2,1.17,943.94]],"batl":[[0,1.21,6980.29],[1,1.22,2650.79],[2,1.24,97]],"ltp":1.22,"tv":12441.18,"id":9631939},{"batb":[[0,5.8,405.16],[1,5.7,202.58],[2,5.6,202.58]],"batl":[[0,6.2,3.53],[2,6.8,151.36]],"ltp":5.6,"tv":808.87,"id":9454286}],"tv":13250.06}]}
{"op":"mcm","clk":"4289763017","pt":1632493457135,"mc":[{"id":"1.188075669","rc":[{"batl":[[0,1.21,1610],[1,1.22,1273.05]],"ltp":1.22,"tv":12441.18,"id":9631939},{"batb":[[0,5.9,124.26],[1,5.8,81.04],[2,5.7,40.52]],"batl":[[2,6.8,358.72]],"ltp":5.6,"tv":808.87,"id":9454286}]}]}
{"op":"mcm","clk":"4289763094","pt":1632493458031,"mc":[{"id":"1.188075669","rc":[{"batb":[[2,1.17,1089.46]],"batl":[[1,1.22,1288.05],[2,1.23,130.7]],"ltp":1.22,"tv":12441.18,"id":9631939},{"batl":[[2,6.8,245.39]],"ltp":5.6,"tv":808.87,"id":9454286}]}]}
{"op":"mcm","clk":"4289763150","pt":1632493458658,"mc":[{"id":"1.188075669","rc":[{"batl":[[2,1.23,10]],"ltp":1.22,"tv":12441.18,"id":9631939}]}]}
{"op":"mcm","clk":"4289763486","pt":1632493462124,"mc":[{"id":"1.188075669","rc":[{"batl":[[0,1.21,1661.88]],"ltp":1.22,"tv":12441.18,"id":9631939}]}]}
{"op":"mcm","clk":"4289763630","pt":1632493464157,"mc":[{"id":"1.188075669","rc":[{"batb":[[0,1.19,715.9]],"ltp":1.22,"tv":12441.18,"id":9631939}]}]}
{"op":"mcm","clk":"4289763894","pt":1632493467151,"mc":[{"id":"1.188075669","rc":[{"trd":[[1.21,3.9]],"batl":[[0,1.21,1659.93]],"ltp":1.21,"tv":12445.09,"id":9631939}],"tv":13253.96}]}
{"op":"mcm","clk":"4289763962","pt":1632493467956,"mc":[{"id":"1.188075669","rc":[{"batb":[[0,1.19,817.9]],"batl":[[0,1.21,1198.76]],"ltp":1.21,"tv":12445.09,"id":9631939}]}]}
{"op":"mcm","clk":"4289764736","pt":1632493476189,"mc":[{"id":"1.188075669","rc":[{"batb":[[0,1.2,90.16],[1,1.19,817.9],[2,1.18,639.42]],"ltp":1.21,"tv":12445.09,"id":9631939}]}]}
{"op":"mcm","clk":"4289765038","pt":1632493479382,"mc":[{"id":"1.188075669","rc":[{"trd":[[1.2,22.3]],"batb":[[0,1.2,79.01]],"ltp":1.2,"tv":12467.39,"id":9631939}],"tv":13276.26}]}
{"op":"mcm","clk":"4289765350","pt":1632493482687,"mc":[{"id":"1.188075669","rc":[{"batb":[[1,1.19,996.9]],"batl":[[1,1.22,1333.05]],"ltp":1.2,"tv":12467.39,"id":9631939}]}]}
{"op":"mcm","clk":"4289765466","pt":1632493483997,"mc":[{"id":"1.188075669","rc":[{"batb":[[0,1.19,996.9],[1,1.18,639.42],[2,1.17,1089.46]],"ltp":1.2,"tv":12467.39,"id":9631939}]}]}
{"op":"mcm","clk":"4289766146","pt":1632493491675,"mc":[{"id":"1.188075669","rc":[{"trd":[[1.21,9.16]],"batl":[[0,1.21,1196.13]],"ltp":1.21,"tv":12472.65,"id":9631939}],"tv":13281.52}]}
{"op":"mcm","clk":"4289766467","pt":1632493495383,"mc":[{"id":"1.188075669","rc":[{"batb":[[2,1.17,1087.1]],"ltp":1.21,"tv":12472.65,"id":9631939}]}]}
{"op":"mcm","clk":"4289766883","pt":1632493500398,"mc":[{"id":"1.188075669","rc":[{"trd":[[1.21,167.3]],"batb":[[0,1.19,967.63]],"batl":[[0,1.21,1117.06]],"ltp":1.21,"tv":12630.79,"id":9631939}],"tv":13439.66}]}
{"op":"mcm","clk":"4289767142","pt":1632493503189,"mc":[{"id":"1.188075669","rc":[{"batl":[[0,1.21,1145.44]],"ltp":1.21,"tv":12630.79,"id":9631939}]}]}
{"op":"mcm","clk":"4289770640","pt":1632493543971,"mc":[{"id":"1.188075669","rc":[{"batb":[[0,1.17,145.52],[1,1.15,1071.65],[2,1.12,2.53]],"batl":[[0,1.22,60],[1,1.23,10],[2,1.24,87]],"ltp":1.21,"tv":12630.79,"id":9631939},{"batb":[[0,5.6,72.6],[1,5.3,2],[2,3,5.26]],"batl":[[0,6.8,24.91],[1,6.4,0],[2,6.8,0]],"ltp":5.6,"tv":808.87,"id":9454286}]}]}
{"op":"mcm","clk":"4289770746","pt":1632493545260,"mc":[{"id":"1.188075669","rc":[{"batb":[[0,1.15,1071.65],[1,1.12,2.53],[2,1.06,438.16]],"batl":[[0,1.23,10],[1,1.24,87],[2,1.76,5.26]],"ltp":1.21,"tv":12630.79,"id":9631939},{"batb":[[0,5.6,69.34]],"ltp":5.6,"tv":808.87,"id":9454286}]}]}
{"op":"mcm","clk":"4289770895","pt":1632493547163,"mc":[{"id":"1.188075669","rc":[{"batb":[[0,1.19,12],[1,1.18,13],[2,1.17,89.97]],"batl":[[0,1.22,6.25],[1,1.23,105],[2,1.24,87]],"ltp":1.21,"tv":12630.79,"id":9631939},{"batb":[[1,5.5,4.24],[2,5.3,8.76]],"batl":[[0,6.4,2],[1,6.6,2],[2,6.8,2]],"ltp":5.6,"tv":808.87,"id":9454286}]}]}
{"op":"mcm","clk":"4289771074","pt":1632493549170,"mc":[{"id":"1.188075669","rc":[{"batb":[[0,1.19,315.68],[1,1.18,659.38]],"batl":[[0,1.21,418.89],[1,1.22,492.52],[2,1.23,105]],"ltp":1.21,"tv":12630.79,"id":9631939}]}]}
{"op":"mcm","clk":"4289771151","pt":1632493549968,"mc":[{"id":"1.188075669","rc":[{"batb":[[0,1.19,374.68],[1,1.18,721.24]],"ltp":1.21,"tv":12630.79,"id":9631939},{"batl":[[1,6.6,4]],"ltp":5.6,"tv":808.87,"id":9454286}]}]}
{"op":"mcm","clk":"4289771206","pt":1632493550667,"mc":[{"id":"1.188075669","rc":[{"batl":[[0,1.21,450.14],[1,1.22,583.27]],"ltp":1.21,"tv":12630.79,"id":9631939},{"batb":[[0,5.7,14.65],[1,5.6,69.34],[2,5.5,6.48]],"batl":[[0,6.4,10.92]],"ltp":5.6,"tv":808.87,"id":9454286}]}]}
{"op":"mcm","clk":"4289771334","pt":1632493552067,"mc":[{"id":"1.188075669","rc":[{"batb":[[0,1.19,71],[1,1.18,74.86]],"batl":[[0,1.22,97],[1,1.23,105],[2,1.24,87]],"ltp":1.21,"tv":12630.79,"id":9631939},{"batb":[[0,5.6,69.34],[1,5.5,6.48],[2,5.3,8.76]],"batl":[[0,6.4,2]],"ltp":5.6,"tv":808.87,"id":9454286}]}]}
{"op":"mcm","clk":"4289771423","pt":1632493553177,"mc":[{"id":"1.188075669","rc":[{"batb":[[0,1.19,12]],"batl":[[0,1.23,105],[1,1.24,87],[2,1.76,5.26]],"ltp":1.21,"tv":12630.79,"id":9631939},{"batb":[[1,5.3,8.76],[2,3,5.26]],"batl":[[0,6.2,3],[1,6.4,2],[2,6.6,4]],"ltp":5.6,"tv":808.87,"id":9454286}]}]}
{"op":"mcm","clk":"4289771499","pt":1632493554181,"mc":[{"id":"1.188075669","rc":[{"batb":[[1,1.18,13]],"ltp":1.21,"tv":12630.79,"id":9631939},{"trd":[[5.6,10.16]],"batb":[[0,5.6,65.63]],"batl":[[2,6.6,2]],"ltp":5.6,"tv":816.29,"id":9454286}],"tv":13447.08}]}
{"op":"mcm","clk":"4289771553","pt":1632493554986,"mc":[{"id":"1.188075669","rc":[{"batb":[[2,1.17,896.16]],"batl":[[0,1.23,709.46],[1,1.24,521.22]],"ltp":1.21,"tv":12630.79,"id":9631939}]}]}
{"op":"mcm","clk":"4289771595","pt":1632493555512,"mc":[{"id":"1.188075669","rc":[{"batl":[[0,1.22,97],[1,1.23,709.46],[2,1.24,521.22]],"ltp":1.21,"tv":12630.79,"id":9631939},{"batb":[[1,5.5,6.56],[2,5.3,8.76]],"ltp":5.6,"tv":816.29,"id":9454286}]}]}
{"op":"mcm","clk":"4289771699","pt":1632493556876,"mc":[{"id":"1.188075669","rc":[{"batl":[[0,1.22,6.75],[1,1.23,16.5],[2,1.24,87]],"ltp":1.21,"tv":12630.79,"id":9631939},{"batb":[[1,5.5,4.24]],"ltp":5.6,"tv":816.29,"id":9454286}]}]}
{"op":"mcm","clk":"4289771991","pt":1632493559193,"mc":[{"id":"1.188075669","rc":[{"trd":[[1.19,24]],"batb":[[0,1.18,13],[1,1.17,896.16],[2,1.16,399.18]],"batl":[[0,1.19,687.26],[1,1.2,127.48],[2,1.22,6.75]],"ltp":1.19,"tv":12654.79,"id":9631939},{"trd":[[6.2,6],[6.4,1.74]],"batb":[[0,6,644.61],[1,5.9,618.76],[2,5.8,618.76]],"batl":[[0,6.4,1.13],[1,6.6,2],[2,6.8,7.23]],"ltp":6.4,"tv":824.03,"id":9454286}],"tv":13478.82}]}
{"op":"mcm","clk":"4289772094","pt":1632493560175,"mc":[{"id":"1.188075669","rc":[{"batb":[[0,1.17,896.16],[1,1.16,399.18],[2,1.15,1235.56]],"batl":[[1,1.2,774.14],[2,1.21,564.62]],"ltp":1.19,"tv":12654.79,"id":9631939},{"batb":[[0,6.4,101.73],[1,6,286.36],[2,5.9,154.7]],"batl":[[0,6.8,7.23],[1,7,4],[2,7.2,88.8]],"ltp":6.4,"tv":824.03,"id":9454286}]}]}
{"op":"mcm","clk":"4289772175","pt":1632493561208,"mc":[{"id":"1.188075669","rc":[{"batb":[[1,1.16,382.18],[2,1.15,1234.21]],"batl":[[2,1.21,538.37]],"ltp":1.19,"tv":12654.79,"id":9631939}]}]}
{"op":"mcm","clk":"4289772280","pt":1632493562206,"mc":[{"id":"1.188075669","rc":[{"batb":[[2,1.15,1225.21]],"batl":[[1,1.2,778.52],[2,1.21,540.56]],"ltp":1.19,"tv":12654.79,"id":9631939},{"batl":[[1,7,2]],"ltp":6.4,"tv":824.03,"id":9454286}]}]}
{"op":"mcm","clk":"4289772314","pt":1632493562582,"mc":[{"id":"1.188075669","rc":[{"batb":[[0,1.17,958.87]],"batl":[[2,1.21,544.94]],"ltp":1.19,"tv":12654.79,"id":9631939},{"batl":[[0,6.8,16.03]],"ltp":6.4,"tv":824.03,"id":9454286}]}]}
{"op":"mcm","clk":"4289772456","pt":1632493564193,"mc":[{"id":"1.188075669","rc":[{"batl":[[1,1.2,838.52]],"ltp":1.19,"tv":12654.79,"id":9631939},{"batb":[[1,6,289.36]],"ltp":6.4,"tv":824.03,"id":9454286}]}]}
{"op":"mcm","clk":"4289772632","pt":1632493565995,"mc":[{"id":"1.188075669","rc":[{"batb":[[0,1.17,1080.87]],"ltp":1.19,"tv":12654.79,"id":9631939}]}]}
{"op":"mcm","clk":"4289772673","pt":1632493566508,"mc":[{"id":"1.188075669","rc":[{"batb":[[1,1.16,460.46],[2,1.15,1304.84]],"batl":[[2,1.21,627.44]],"ltp":1.19,"tv":12654.79,"id":9631939}]}]}
{"op":"mcm","clk":"4289772831","pt":1632493568695,"mc":[{"id":"1.188075669","rc":[{"batl":[[1,1.2,834.14]],"ltp":1.19,"tv":12654.79,"id":9631939}]}]}
{"op":"mcm","clk":"4289772916","pt":1632493570002,"mc":[{"id":"1.188075669","rc":[{"batb":[[0,1.17,1228.87]],"batl":[[2,1.21,620.87]],"ltp":1.19,"tv":12654.79,"id":9631939},{"batl":[[0,6.8,10.8]],"ltp":6.4,"tv":824.03,"id":9454286}]}]}
{"op":"mcm","clk":"4289772995","pt":1632493571207,"mc":[{"id":"1.188075669","rc":[{"batb":[[0,1.16,371.65],[1,1.15,234.54],[2,1.13,1234.79]],"batl":[[0,1.2,60],[1,1.21,530.49],[2,1.22,94.5]],"ltp":1.19,"tv":12654.79,"id":9631939},{"batb":[[0,6,122.87],[1,5.7,2.02],[2,5.5,6.36]],"batl":[[0,7.4,2],[1,7.8,2],[2,7.2,0]],"ltp":6.4,"tv":824.03,"id":9454286}]}]}
{"op":"mcm","clk":"4289773142","pt":1632493573215,"mc":[{"id":"1.188075669","rc":[{"batb":[[1,1.15,79.63]],"batl":[[0,1.21,530.49],[1,1.22,94.5],[2,1.23,16.5]],"ltp":1.19,"tv":12654.79,"id":9631939},{"batb":[[0,6,119.87]],"ltp":6.4,"tv":824.03,"id":9454286}]}]}
{"op":"mcm","clk":"4289773203","pt":1632493574017,"mc":[{"id":"1.188075669","rc":[{"batb":[[1,1.15,874.86]],"batl":[[1,1.22,579.86]],"ltp":1.19,"tv":12654.79,"id":9631939}]}]}
{"op":"mcm","clk":"4289773237","pt":1632493574394,"mc":[{"id":"1.188075669","rc":[{"batb":[[0,1.16,14],[1,1.15,97.63]],"batl":[[0,1.21,447.99],[1,1.22,492.11]],"ltp":1.19,"tv":12654.79,"id":9631939},{"batb":[[1,5.5,6.36],[2,5.3,6.58]],"ltp":6.4,"tv":824.03,"id":9454286}]}]}
{"op":"mcm","clk":"4289773299","pt":1632493575502,"mc":[{"id":"1.188075669","rc":[{"batl":[[0,1.21,459.99]],"ltp":1.19,"tv":12654.79,"id":9631939}]}]}
{"op":"mcm","clk":"4289773401","pt":1632493577193,"mc":[{"id":"1.188075669","rc":[{"batb":[[0,1.18,2354.54],[1,1.17,199.16],[2,1.16,213.16]],"batl":[[0,1.2,298.11],[1,1.21,490.19],[2,1.22,492.11]],"ltp":1.19,"tv":12654.79,"id":9631939},{"batb":[[0,6,179.49]],"batl":[[0,6.8,92.59],[1,7.4,2],[2,7.6,3.95]],"ltp":6.4,"tv":824.03,"id":9454286}]}]}
{"op":"mcm","clk":"4289773490","pt":1632493578207,"mc":[{"id":"1.188075669","rc":[{"batb":[[0,1.19,272.03],[1,1.18,1720.6],[2,1.17,1164.86]],"batl":[[1,1.21,963.42],[2,1.22,686.33]],"ltp":1.19,"tv":12654.79,"id":9631939},{"batb":[[1,5.8,3.12],[2,5.7,68.33]],"batl":[[1,7,24.49],[2,7.4,2]],"ltp":6.4,"tv":824.03,"id":9454286}]}]}
{"op":"mcm","clk":"4289773617","pt":1632493580012,"mc":[{"id":"1.188075669","rc":[{"batb":[[2,1.17,1234.86]],"batl":[[1,1.21,1025.45]],"ltp":1.19,"tv":12654.79,"id":9631939},{"batl":[[0,6.6,3],[1,6.8,92.59],[2,7,24.49]],"ltp":6.4,"tv":824.03,"id":9454286}]}]}
{"op":"mcm","clk":"4289773903","pt":1632493584439,"mc":[{"id":"1.188075669","rc":[{"batb":[[1,1.18,1789.46],[2,1.17,1313.83]],"batl":[[1,1.21,1114.95],[2,1.22,774.08]],"ltp":1.19,"tv":12654.79,"id":9631939},{"batb":[[2,5.7,70.45]],"batl":[[0,6.6,5],[2,7,26.49]],"ltp":6.4,"tv":824.03,"id":9454286}]}]}
{"op":"mcm","clk":"4289774075","pt":1632493587135,"mc":[{"id":"1.188075669","rc":[{"batb":[[1,1.18,714.02],[2,1.17,1044.67]],"batl":[[0,1.21,597.49],[1,1.22,579.86],[2,1.23,16.5]],"ltp":1.19,"tv":12654.79,"id":9631939},{"batb":[[0,6,119.87]],"batl":[[1,7,26.49],[2,7.4,2]],"ltp":6.4,"tv":824.03,"id":9454286}]}]}
{"op":"mcm","clk":"4289774125","pt":1632493587719,"mc":[{"id":"1.188075669","rc":[{"batb":[[0,1.17,78.97],[1,1.16,164],[2,1.15,1200.21]],"batl":[[0,1.21,60],[1,1.22,363.4]],"ltp":1.19,"tv":12654.79,"id":9631939},{"batb":[[0,5.8,3.12],[1,5.7,68.33],[2,5.5,6.36]],"batl":[[0,7,26.49],[1,7.4,2],[2,7.8,2]],"ltp":6.4,"tv":824.03,"id":9454286}]}]}
{"op":"mcm","clk":"4289774157","pt":1632493588254,"mc":[{"id":"1.188075669","rc":[{"batb":[[1,1.16,14]],"batl":[[0,1.22,363.4],[1,1.23,16.5],[2,1.24,87]],"ltp":1.19,"tv":12654.79,"id":9631939},{"batb":[[0,5.7,68.33],[1,5.5,6.36],[2,5.3,6.58]],"batl":[[0,7,2]],"ltp":6.4,"tv":824.03,"id":9454286}]}]}
{"op":"mcm","clk":"4289774272","pt":1632493590154,"mc":[{"id":"1.188075669","rc":[{"batb":[[0,1.17,509.15],[1,1.16,759.28]],"batl":[[1,1.23,482.62]],"ltp":1.19,"tv":12654.79,"id":9631939}]}]}
{"op":"mcm","clk":"4289774338","pt":1632493591038,"mc":[{"id":"1.188075669","rc":[{"batb":[[0,1.17,521.15]],"batl":[[0,1.21,94.5],[1,1.22,363.4],[2,1.23,482.62]],"ltp":1.19,"tv":12654.79,"id":9631939},{"batb":[[0,5.7,70.45]],"batl":[[0,7,4]],"ltp":6.4,"tv":824.03,"id":9454286}]}]}
{"op":"mcm","clk":"4289774366","pt":1632493591422,"mc":[{"id":"1.188075669","rc":[{"batl":[[0,1.22,375.4],[1,1.23,482.62],[2,1.24,87]],"ltp":1.19,"tv":12654.79,"id":9631939},{"batb":[[0,5.7,68.33]],"ltp":6.4,"tv":824.03,"id":9454286}]}]}
{"op":"mcm","clk":"4289774571","pt":1632493594220,"mc":[{"id":"1.188075669","rc":[{"batb":[[0,1.18,65.86],[1,1.17,90.97],[2,1.16,14]],"ltp":1.19,"tv":12654.79,"id":9631939},{"batl":[[0,6.6,2],[1,7,4],[2,7.4,2]],"ltp":6.4,"tv":824.03,"id":9454286}]}]}
{"op":"mcm","clk":"4289774664","pt":1632493595128,"mc":[{"id":"1.188075669","rc":[{"batb":[[0,1.17,90.97],[1,1.16,14],[2,1.15,1200.21]],"batl":[[0,1.22,363.4]],"ltp":1.19,"tv":12654.79,"id":9631939},{"batl":[[0,7,4],[1,7.4,2],[2,7.8,2]],"ltp":6.4,"tv":824.03,"id":9454286}]}]}
{"op":"mcm","clk":"4289774679","pt":1632493595339,"mc":[{"id":"1.188075669","rc":[{"batl":[[0,1.19,6.57],[1,1.22,363.4],[2,1.23,482.62]],"ltp":1.19,"tv":12654.79,"id":9631939}]}]}
{"op":"mcm","clk":"4289774782","pt":1632493597140,"mc":[{"id":"1.188075669","rc":[{"trd":[[1.19,32.76]],"batb":[[0,1.2,405.48],[1,1.19,610.86],[2,1.18,724.77]],"batl":[[0,1.21,498.09],[1,1.22,398.04]],"ltp":1.19,"tv":12663.55,"id":9631939},{"trd":[[6.2,7.68]],"batl":[[0,6,5.89],[1,6.2,214.48],[2,6.4,37.9]],"ltp":6.2,"tv":825.71,"id":9454286}],"tv":13489.27}]}
{"op":"mcm","clk":"4289774867","pt":1632493598125,"mc":[{"id":"1.188075669","rc":[{"batb":[[2,1.18,1624.62]],"batl":[[1,1.22,422.63]],"ltp":1.19,"tv":12663.55,"id":9631939},{"batb":[[2,5.4,510.53]],"ltp":6.2,"tv":825.71,"id":9454286}]}]}
{"op":"mcm","clk":"4289774919","pt":1632493598932,"mc":[{"id":"1.188075669","rc":[{"batb":[[1,1.19,618.86],[2,1.18,1742.12]],"batl":[[2,1.23,542.62]],"ltp":1.19,"tv":12663.55,"id":9631939},{"batb":[[2,5.4,165.77]],"ltp":6.2,"tv":825.71,"id":9454286}]}]}
{"op":"mcm","clk":"4289775329","pt":1632493604943,"mc":[{"id":"1.188075669","rc":[{"batb":[[1,1.19,679.57],[2,1.18,1805.98]],"batl":[[0,1.21,598.59]],"ltp":1.19,"tv":12663.55,"id":9631939},{"batb":[[0,5.7,70.55]],"batl":[[2,6.4,39.9]],"ltp":6.2,"tv":825.71,"id":9454286}]}]}
{"op":"mcm","clk":"4289775369","pt":1632493605529,"mc":[{"id":"1.188075669","rc":[{"batb":[[2,1.18,1947.4]],"ltp":1.19,"tv":12663.55,"id":9631939}]}]}
{"op":"mcm","clk":"4289775839","pt":1632493613060,"mc":[{"id":"1.188075669","rc":[{"batb":[[0,1.19,60.71],[1,1.18,205.28],[2,1.17,78.97]],"batl":[[0,1.22,94.5],[1,1.23,262.85],[2,1.24,87]],"ltp":1.19,"tv":12663.55,"id":9631939},{"batb":[[0,5.5,6.36],[1,5.4,78.73],[2,5.3,6.58]],"batl":[[0,6.4,2],[1,6.6,27.35],[2,6.8,2]],"ltp":6.2,"tv":825.71,"id":9454286}]}]}
{"op":"mcm","clk":"4289775849","pt":1632493613268,"mc":[{"id":"1.188075669","rc":[{"batb":[[0,1.18,205.28],[1,1.17,78.97],[2,1.16,1001.38]],"batl":[[0,1.22,87.75]],"ltp":1.19,"tv":12663.55,"id":9631939},{"batb":[[0,5.5,2.12]],"batl":[[0,6.6,27.35],[1,6.8,2],[2,7,2]],"ltp":6.2,"tv":825.71,"id":9454286}]}]}
{"op":"mcm","clk":"4289775952","pt":1632493615053,"mc":[{"id":"1.188075669","rc":[{"trd":[[1.18,56.38]],"batb":[[0,1.18,35.67],[1,1.16,1001.38],[2,1.15,79.63]],"batl":[[1,1.23,202.85]],"ltp":1.18,"tv":12719.93,"id":9631939},{"batb":[[1,5.4,75.33]],"batl":[[0,6.6,2],[2,7.8,2]],"ltp":6.2,"tv":825.71,"id":9454286}],"tv":13545.65}]}
{"op":"mcm","clk":"4289776025","pt":1632493616170,"mc":[{"id":"1.188075669","rc":[{"batb":[[0,1.18,692.87],[1,1.17,522.29],[2,1.16,1001.38]],"batl":[[0,1.21,103.5],[1,1.22,100.75],[2,1.23,202.85]],"ltp":1.18,"tv":12719.93,"id":9631939},{"batb":[[0,5.7,2.42],[1,5.5,2.12],[2,5.4,75.33]],"ltp":6.2,"tv":825.71,"id":9454286}]}]}
{"op":"mcm","clk":"4289776067","pt":1632493616965,"mc":[{"id":"1.188075669","rc":[{"batb":[[0,1.18,35.67],[1,1.16,1001.38],[2,1.15,79.63]],"batl":[[0,1.22,100.75],[1,1.23,202.85],[2,1.24,87]],"ltp":1.18,"tv":12719.93,"id":9631939},{"batb":[[0,5.5,4.12],[1,5.4,78.33],[2,5.3,6.58]],"ltp":6.2,"tv":825.71,"id":9454286}]}]}
{"op":"mcm","clk":"4289776196","pt":1632493619066,"mc":[{"id":"1.188075669","rc":[{"batb":[[0,1.2,19.92],[1,1.18,35.67],[2,1.16,1001.38]],"batl":[[0,1.21,21.5],[1,1.22,100.75],[2,1.23,202.85]],"ltp":1.18,"tv":12719.93,"id":9631939},{"batl":[[0,6,20.9],[1,6.6,2],[2,6.8,2]],"ltp":6.2,"tv":825.71,"id":9454286}]}]}
{"op":"mcm","clk":"4289776267","pt":1632493620162,"mc":[{"id":"1.188075669","rc":[{"batb":[[0,1.2,204.44],[1,1.19,604.12],[2,1.18,35.67]],"batl":[[0,1.22,555.99],[1,1.23,477.52],[2,1.24,87]],"ltp":1.18,"tv":12719.93,"id":9631939},{"batl":[[0,6.6,2],[1,6.8,2],[2,7.8,2]],"ltp":6.2,"tv":825.71,"id":9454286}]}]}
{"op":"mcm","clk":"4289776332","pt":1632493621169,"mc":[{"id":"1.188075669","rc":[{"batb":[[1,1.19,731.56]],"batl":[[0,1.22,616.35]],"ltp":1.18,"tv":12719.93,"id":9631939},{"batb":[[0,5.6,10.91],[1,5.5,4.12],[2,5.4,78.33]],"batl":[[0,6.4,2],[1,6.6,2],[2,6.8,2]],"ltp":6.2,"tv":825.71,"id":9454286}]}]}
{"op":"mcm","clk":"4289776418","pt":1632493622181,"mc":[{"id":"1.188075669","rc":[{"batb":[[0,1.19,65.71],[1,1.18,35.67],[2,1.16,1001.38]],"batl":[[0,1.22,100.75],[1,1.23,202.85]],"ltp":1.18,"tv":12719.93,"id":9631939},{"batb":[[0,5.5,4.12],[1,5.4,78.33],[2,5.3,6.58]],"ltp":6.2,"tv":825.71,"id":9454286}]}]}
{"op":"mcm","clk":"4289776441","pt":1632493622469,"mc":[{"id":"1.188075669","rc":[{"batb":[[0,1.18,35.67],[1,1.16,1001.38],[2,1.15,79.63]],"ltp":1.18,"tv":12719.93,"id":9631939},{"batl":[[0,6.6,2],[1,6.8,2],[2,7.8,2]],"ltp":6.2,"tv":825.71,"id":9454286}]}]}
{"op":"mcm","clk":"4289776612","pt":1632493625090,"mc":[{"id":"1.188075669","rc":[{"batb":[[0,1.18,692.87],[1,1.17,522.29],[2,1.16,1001.38]],"batl":[[2,1.24,533.05]],"ltp":1.18,"tv":12719.93,"id":9631939}]}]}
{"op":"mcm","clk":"4289776744","pt":1632493626995,"mc":[{"id":"1.188075669","rc":[{"batl":[[0,1.21,103.5],[1,1.22,100.75],[2,1.23,202.85]],"ltp":1.18,"tv":12719.93,"id":9631939},{"batb":[[0,5.7,2.52],[1,5.5,4.12],[2,5.4,78.33]],"ltp":6.2,"tv":825.71,"id":9454286}]}]}
{"op":"mcm","clk":"4289776760","pt":1632493627278,"mc":[{"id":"1.188075669","rc":[{"batl":[[0,1.22,100.75],[1,1.23,202.85],[2,1.24,533.05]],"ltp":1.18,"tv":12719.93,"id":9631939},{"batb":[[0,5.5,4.12],[1,5.4,78.33],[2,5.3,6.58]],"ltp":6.2,"tv":825.71,"id":9454286}]}]}
{"op":"mcm","clk":"4289776960","pt":1632493630102,"mc":[{"id":"1.188075669","rc":[{"batl":[[1,1.23,6.5],[2,1.24,87]],"ltp":1.18,"tv":12719.93,"id":9631939},{"batb":[[1,5.4,75.33],[2,5.3,4.58]],"ltp":6.2,"tv":825.71,"id":9454286}]}]}
{"op":"mcm","clk":"4289777108","pt":1632493632202,"mc":[{"id":"1.188075669","rc":[{"batl":[[0,1.2,135.43],[1,1.21,704.02],[2,1.22,563.63]],"ltp":1.18,"tv":12719.93,"id":9631939},{"batb":[[0,6.2,92.99],[1,6,401.39],[2,5.9,195.84]],"batl":[[0,6.4,3.89],[1,6.6,2],[2,6.8,2]],"ltp":6.2,"tv":825.71,"id":9454286}]}]}
{"op":"mcm","clk":"4289777175","pt":1632493633184,"mc":[{"id":"1.188075669","rc":[{"batb":[[0,1.18,704.87],[1,1.17,538.29],[2,1.16,1151.38]],"batl":[[1,1.21,764.02]],"ltp":1.18,"tv":12719.93,"id":9631939},{"batb":[[1,6,201.17],[2,5.9,39.16]],"batl":[[1,6.6,4]],"ltp":6.2,"tv":825.71,"id":9454286}]}]}
{"op":"mcm","clk":"4289777236","pt":1632493634095,"mc":[{"id":"1.188075669","rc":[{"batb":[[0,1.18,754.85]],"batl":[[1,1.21,844.77]],"ltp":1.18,"tv":12719.93,"id":9631939},{"batl":[[1,6.6,14]],"ltp":6.2,"tv":825.71,"id":9454286}]}]}
{"op":"mcm","clk":"4289777554","pt":1632493638995,"mc":[{"id":"1.188075669","rc":[{"batb":[[0,1.18,866.85]],"ltp":1.18,"tv":12719.93,"id":9631939}]}]}
{"op":"mcm","clk":"4289777573","pt":1632493639416,"mc":[{"id":"1.188075669","rc":[{"batb":[[1,1.17,609.26],[2,1.16,1219.16]],"batl":[[1,1.21,941.27]],"ltp":1.18,"tv":12719.93,"id":9631939}]}]}
{"op":"mcm","clk":"4289777712","pt":1632493642200,"mc":[{"id":"1.188075669","rc":[{"batb":[[0,1.18,968.85]],"ltp":1.18,"tv":12719.93,"id":9631939}]}]}
{"op":"mcm","clk":"4289778017","pt":1632493647196,"mc":[{"id":"1.188075669","rc":[{"batb":[[0,1.18,226],[1,1.17,70.97]],"batl":[[0,1.21,156.5],[1,1.22,457.99],[2,1.23,6.5]],"ltp":1.18,"tv":12719.93,"id":9631939},{"batb":[[0,6,113.12],[1,5.8,3.12],[2,5.7,134.93]],"batl":[[0,6.6,2],[1,7,2],[2,7.2,24.09]],"ltp":6.2,"tv":825.71,"id":9454286}]}]}
{"op":"mcm","clk":"4289778092","pt":1632493648027,"mc":[{"id":"1.188075669","rc":[{"batb":[[0,1.17,70.97],[1,1.16,217.78],[2,1.15,79.63]],"ltp":1.18,"tv":12719.93,"id":9631939},{"batb":[[0,5.8,3.12],[1,5.7,134.93],[2,5.6,3]],"batl":[[0,7,2],[1,7.2,24.09],[2,7.4,2]],"ltp":6.2,"tv":825.71,"id":9454286}]}]}
{"op":"mcm","clk":"4289778135","pt":1632493648618,"mc":[{"id":"1.188075669","rc":[{"batb":[[0,1.16,67.78],[1,1.14,1184.35],[2,1.12,2.53]],"batl":[[0,1.21,96.5]],"ltp":1.18,"tv":12719.93,"id":9631939},{"batb":[[0,5.7,134.93],[1,5.6,3],[2,5.5,2.12]],"batl":[[0,7.4,2],[1,7.2,0],[2,7.4,0]],"ltp":6.2,"tv":825.71,"id":9454286}]}]}
{"op":"mcm","clk":"4289778223","pt":1632493650117,"mc":[{"id":"1.188075669","rc":[{"batb":[[0,1.16,709.18],[1,1.15,558.74],[2,1.14,1184.35]],"batl":[[2,1.23,470.4]],"ltp":1.18,"tv":12719.93,"id":9631939}]}]}
{"op":"mcm","clk":"4289778265","pt":1632493650705,"mc":[{"id":"1.188075669","rc":[{"batl":[[0,1.21,106.5]],"ltp":1.18,"tv":12719.93,"id":9631939},{"batb":[[0,5.8,2],[1,5.7,136.93],[2,5.6,3]],"ltp":6.2,"tv":825.71,"id":9454286}]}]}
{"op":"mcm","clk":"4289778337","pt":1632493651815,"mc":[{"id":"1.188075669","rc":[{"batb":[[0,1.16,725.18],[1,1.15,574.74]],"ltp":1.18,"tv":12719.93,"id":9631939},{"batl":[[0,7.4,4]],"ltp":6.2,"tv":825.71,"id":9454286}]}]}
{"op":"mcm","clk":"4289778483","pt":1632493654019,"mc":[{"id":"1.188075669","rc":[{"batl":[[0,1.2,116.78],[1,1.21,106.5],[2,1.22,457.99]],"ltp":1.18,"tv":12719.93,"id":9631939},{"batb":[[0,6,2.99],[1,5.8,2],[2,5.7,136.93]],"ltp":6.2,"tv":825.71,"id":9454286}]}]}
{"op":"mcm","clk":"4289778546","pt":1632493655026,"mc":[{"id":"1.188075669","rc":[{"batb":[[0,1.17,66.97],[1,1.16,83.78],[2,1.15,16]],"batl":[[0,1.21,106.5],[1,1.22,457.99],[2,1.23,470.4]],"ltp":1.18,"tv":12719.93,"id":9631939},{"batb":[[0,5.8,2],[1,5.7,136.93],[2,5.6,3]],"batl":[[0,7,2],[1,7.4,4]],"ltp":6.2,"tv":825.71,"id":9454286}]}]}
{"op":"mcm","clk":"4289778556","pt":1632493655303,"mc":[{"id":"1.188075669","rc":[{"batb":[[0,1.16,83.78],[1,1.15,16],[2,1.14,1184.35]],"ltp":1.18,"tv":12719.93,"id":9631939},{"batl":[[0,7.4,4],[1,7.4,0]],"ltp":6.2,"tv":825.71,"id":9454286}]}]}
{"op":"mcm","clk":"4289778721","pt":1632493658029,"mc":[{"id":"1.188075669","rc":[{"batb":[[0,1.2,310.62],[1,1.19,607.91],[2,1.18,673.91]],"batl":[[0,1.21,843.02],[1,1.22,444.99]],"ltp":1.18,"tv":12719.93,"id":9631939},{"batb":[[0,5.7,134.93],[1,5.5,2.12],[2,5.3,4.58]],"batl":[[0,6.2,83.93],[1,6.4,37.9],[2,6.6,37.9]],"ltp":6.2,"tv":825.71,"id":9454286}]}]}
{"op":"mcm","clk":"4289778791","pt":1632493659136,"mc":[{"id":"1.188075669","rc":[{"batb":[[2,1.18,1579.72]],"batl":[[1,1.22,469.58]],"ltp":1.18,"tv":12719.93,"id":9631939},{"batb":[[1,5.5,76.02],[2,5.4,87.04]],"ltp":6.2,"tv":825.71,"id":9454286}]}]}
{"op":"mcm","clk":"4289778832","pt":1632493659824,"mc":[{"id":"1.188075669","rc":[{"batl":[[1,1.22,529.58]],"ltp":1.18,"tv":12719.93,"id":9631939},{"batb":[[1,5.5,79.35]],"batl":[[2,6.6,63.25]],"ltp":6.2,"tv":825.71,"id":9454286}]}]}
{"op":"mcm","clk":"4289778899","pt":1632493660724,"mc":[{"id":"1.188075669","rc":[{"batb":[[1,1.19,620.91],[2,1.18,1592.72]],"ltp":1.18,"tv":12719.93,"id":9631939}]}]}
{"op":"mcm","clk":"4289779052","pt":1632493662839,"mc":[{"id":"1.188075669","rc":[{"batl":[[0,6.2,103.93]],"ltp":6.2,"tv":825.71,"id":9454286}]}]}
{"op":"mcm","clk":"4289779224","pt":1632493665130,"mc":[{"id":"1.188075669","rc":[{"batb":[[2,1.18,1661.58]],"batl":[[2,1.23,575.9]],"ltp":1.18,"tv":12719.93,"id":9631939},{"batl":[[2,6.6,65.25]],"ltp":6.2,"tv":825.71,"id":9454286}]}]}
{"op":"mcm","clk":"4289779768","pt":1632493674129,"mc":[{"id":"1.188075669","rc":[{"batb":[[2,1.18,974.67]],"batl":[[0,1.21,96.5],[1,1.22,504.99]],"ltp":1.18,"tv":12719.93,"id":9631939},{"batb":[[2,5.3,7.36]],"batl":[[0,6.6,27.35],[1,7,2],[2,7.4,4]],"ltp":6.2,"tv":825.71,"id":9454286}]}]}
{"op":"mcm","clk":"4289779808","pt":1632493674750,"mc":[{"id":"1.188075669","rc":[{"batb":[[0,1.17,217.49],[1,1.16,1082.41],[2,1.12,2.53]],"batl":[[0,1.22,60],[1,1.23,331.82],[2,1.24,87]],"ltp":1.18,"tv":12719.93,"id":9631939},{"batb":[[0,5.5,77.23],[1,5.3,7.36],[2,3,5.26]],"batl":[[0,6.6,25.35]],"ltp":6.2,"tv":825.71,"id":9454286}]}]}
{"op":"mcm","clk":"4289779840","pt":1632493675338,"mc":[{"id":"1.188075669","rc":[{"batb":[[0,1.17,71.97]],"batl":[[0,1.23,331.82],[1,1.24,87],[2,1.39,16.41]],"ltp":1.18,"tv":12719.93,"id":9631939},{"batb":[[0,5.5,73.9]],"batl":[[0,7,2],[1,7.4,4],[2,7.4,0]],"ltp":6.2,"tv":825.71,"id":9454286}]}]}
{"op":"mcm","clk":"4289780009","pt":1632493678043,"mc":[{"id":"1.188075669","rc":[{"batb":[[0,1.18,578.1],[1,1.17,773.13],[2,1.16,1099.41]],"batl":[[1,1.24,532.15]],"ltp":1.18,"tv":12719.93,"id":9631939},{"batl":[[0,6.6,5],[1,7,2],[2,7.4,4]],"ltp":6.2,"tv":825.71,"id":9454286}]}]}
{"op":"mcm","clk":"4289780055","pt":1632493678657,"mc":[{"id":"1.188075669","rc":[{"batb":[[0,1.18,545.29],[1,1.17,84.97]],"batl":[[0,1.23,342.82],[1,1.24,87]],"ltp":1.18,"tv":12719.93,"id":9631939},{"batl":[[1,7,5]],"ltp":6.2,"tv":825.71,"id":9454286}]}]}
{"op":"mcm","clk":"4289780263","pt":1632493681660,"mc":[{"id":"1.188075669","rc":[{"batb":[[0,1.19,709.13],[1,1.18,545.29],[2,1.17,84.97]],"batl":[[0,1.22,544.73],[1,1.23,581.41],[2,1.24,87]],"ltp":1.18,"tv":12719.93,"id":9631939}]}]}
{"op":"mcm","clk":"4289780329","pt":1632493682758,"mc":[{"id":"1.188075669","rc":[{"batl":[[2,1.39,16.41]],"ltp":1.18,"tv":12719.93,"id":9631939}]}]}
{"op":"mcm","clk":"4289780376","pt":1632493683751,"mc":[{"id":"1.188075669","rc":[{"batb":[[0,1.18,545.29],[1,1.17,84.97],[2,1.16,1099.41]],"batl":[[0,1.23,342.82],[1,1.39,16.41],[2,1.76,4.63]],"ltp":1.18,"tv":12719.93,"id":9631939}]}]}
{"op":"mcm","clk":"4289780502","pt":1632493685855,"mc":[{"id":"1.188075669","rc":[{"trd":[[1.18,230.38]],"batb":[[0,1.18,458.29]],"ltp":1.18,"tv":12893.93,"id":9631939}],"tv":13719.65}]}
{"op":"mcm","clk":"4289780542","pt":1632493686744,"mc":[{"id":"1.188075669","rc":[{"batb":[[0,1.18,491.1],[1,1.17,773.13]],"batl":[[1,1.24,445.15],[2,1.39,16.41]],"ltp":1.18,"tv":12893.93,"id":9631939}]}]}
{"op":"mcm","clk":"4289780731","pt":1632493689647,"mc":[{"id":"1.188075669","rc":[{"batb":[[0,1.18,530.02]],"batl":[[0,1.23,389.1]],"ltp":1.18,"tv":12893.93,"id":9631939}]}]}
{"op":"mcm","clk":"4289780808","pt":1632493690748,"mc":[{"id":"1.188075669","rc":[{"batb":[[1,1.17,760.13],[2,1.16,1082.41]],"batl":[[2,1.39,16.72]],"ltp":1.18,"tv":12893.93,"id":9631939},{"batl":[[0,6.6,2],[2,7.4,2]],"ltp":6.2,"tv":825.71,"id":9454286}]}]}
{"op":"mcm","clk":"4289780888","pt":1632493692057,"mc":[{"id":"1.188075669","rc":[{"batl":[[0,1.22,107.75],[1,1.23,389.1],[2,1.24,445.15]],"ltp":1.18,"tv":12893.93,"id":9631939},{"batb":[[0,5.5,76.41]],"ltp":6.2,"tv":825.71,"id":9454286}]}]}
{"op":"mcm","clk":"4289780910","pt":1632493692371,"mc":[{"id":"1.188075669","rc":[{"batl":[[0,1.23,389.1],[1,1.24,445.15],[2,1.39,16.72]],"ltp":1.18,"tv":12893.93,"id":9631939},{"batb":[[0,5.5,73.9]],"ltp":6.2,"tv":825.71,"id":9454286}]}]}
{"op":"mcm","clk":"4289781033","pt":1632493693981,"mc":[{"id":"1.188075669","rc":[{"batb":[[1,1.17,772.13]],"ltp":1.18,"tv":12893.93,"id":9631939},{"batl":[[0,6.6,5]],"ltp":6.2,"tv":825.71,"id":9454286}]}]}
{"op":"mcm","clk":"4289781351","pt":1632493699165,"mc":[{"id":"1.188075669","rc":[{"batl":[[0,1.22,99.75],[1,1.23,389.1],[2,1.24,445.15]],"ltp":1.18,"tv":12893.93,"id":9631939},{"batb":[[0,5.5,76.34]],"ltp":6.2,"tv":825.71,"id":9454286}]}]}
{"op":"mcm","clk":"4289781404","pt":1632493699988,"mc":[{"id":"1.188075669","rc":[{"batb":[[0,1.18,12],[1,1.17,83.97]],"batl":[[0,1.23,389.1],[1,1.24,445.15],[2,1.39,16.72]],"ltp":1.18,"tv":12893.93,"id":9631939},{"batb":[[0,5.5,73.9]],"batl":[[0,6.6,3]],"ltp":6.2,"tv":825.71,"id":9454286}]}]}
{"op":"mcm","clk":"4289781616","pt":1632493703162,"mc":[{"id":"1.188075669","rc":[{"batb":[[0,1.21,373.61],[1,1.2,575.91],[2,1.18,12]],"batl":[[0,1.22,698.25],[1,1.23,378.1],[2,1.24,445.15]],"ltp":1.18,"tv":12893.93,"id":9631939},{"batl":[[0,5.9,79.66],[1,6,172.81],[2,6.2,39.84]],"ltp":6.2,"tv":825.71,"id":9454286}]}]}
{"op":"mcm","clk":"4289781683","pt":1632493704171,"mc":[{"id":"1.188075669","rc":[{"batb":[[2,1.19,834.7]],"batl":[[1,1.23,402.49],[2,1.24,505.15]],"ltp":1.18,"tv":12893.93,"id":9631939},{"batb":[[2,5.2,93.95]],"ltp":6.2,"tv":825.71,"id":9454286}]}]}
{"op":"mcm","clk":"4289781727","pt":1632493704938,"mc":[{"id":"1.188075669","rc":[{"batb":[[2,1.19,894.7]],"batl":[[1,1.23,448.12]],"ltp":1.18,"tv":12893.93,"id":9631939}]}]}
{"op":"mcm","clk":"4289781806","pt":1632493706193,"mc":[{"id":"1.188075669","rc":[{"batb":[[2,1.19,907.7]],"ltp":1.18,"tv":12893.93,"id":9631939}]}]}
{"op":"mcm","clk":"4289781924","pt":1632493707977,"mc":[{"id":"1.188075669","rc":[{"batl":[[0,5.9,94.66]],"ltp":6.2,"tv":825.71,"id":9454286}]}]}
{"op":"mcm","clk":"4289782047","pt":1632493710167,"mc":[{"id":"1.188075669","rc":[{"batb":[[2,1.19,967.41]],"ltp":1.18,"tv":12893.93,"id":9631939}]}]}
{"op":"mcm","clk":"4289782086","pt":1632493710901,"mc":[{"id":"1.188075669","rc":[{"batb":[[2,1.19,1105.05]],"ltp":1.18,"tv":12893.93,"id":9631939},{"batl":[[2,6.2,66.15]],"ltp":6.2,"tv":825.71,"id":9454286}]}]}
{"op":"mcm","clk":"4289783840","pt":1632493737219,"mc":[{"id":"1.188075669","rc":[{"batb":[[0,1.21,357.18],[2,1.19,1045.05]],"batl":[[0,1.23,378.1],[1,1.24,505.15],[2,1.26,97.06]],"ltp":1.18,"tv":12893.93,"id":9631939},{"batb":[[2,5.2,3.57]],"batl":[[0,6.2,26.31],[1,6.4,2],[2,6.6,5]],"ltp":6.2,"tv":825.71,"id":9454286}]}]}
{"op":"mcm","clk":"4289783913","pt":1632493738214,"mc":[{"id":"1.188075669","rc":[{"batb":[[0,1.19,59.71],[1,1.18,72.86],[2,1.17,1018.94]],"batl":[[0,1.26,97.06],[1,1.28,95.65],[2,1.76,5.57]],"ltp":1.18,"tv":12893.93,"id":9631939},{"batb":[[0,4.8,2.53],[1,4.7,104.09],[2,4.5,2.68]],"batl":[[0,6.4,2],[1,6.6,5],[2,7,2]],"ltp":6.2,"tv":825.71,"id":9454286}]}]}
{"op":"mcm","clk":"4289783949","pt":1632493738834,"mc":[{"id":"1.188075669","rc":[{"batb":[[0,1.18,72.86],[1,1.17,1018.94],[2,1.16,67.78]],"batl":[[0,1.28,95.96],[1,1.76,5.57],[2,3.8,27.75]],"ltp":1.18,"tv":12893.93,"id":9631939},{"batb":[[0,4.7,104.09],[1,4.5,2.68],[2,3,5.26]],"batl":[[0,6.6,5],[1,7,2],[2,7.4,2]],"ltp":6.2,"tv":825.71,"id":9454286}]}]}
{"op":"mcm","clk":"4289784091","pt":1632493740910,"mc":[{"id":"1.188075669","rc":[{"batb":[[0,1.19,477.84],[1,1.18,728.09],[2,1.17,1018.94]],"batl":[[0,1.28,600.94],[1,1.29,350.95],[2,1.76,5.26]],"ltp":1.18,"tv":12893.93,"id":9631939}]}]}
{"op":"mcm","clk":"4289784174","pt":1632493742121,"mc":[{"id":"1.188075669","rc":[{"batb":[[0,1.19,64.71],[1,1.18,85.86],[2,1.17,1033.94]],"batl":[[0,1.26,100.56],[1,1.27,9.31],[2,1.28,104.34]],"ltp":1.18,"tv":12893.93,"id":9631939},{"batb":[[0,4.8,4.93],[1,4.7,106.09],[2,4.6,2]],"batl":[[0,6.4,4],[1,6.6,5],[2,7,2]],"ltp":6.2,"tv":825.71,"id":9454286}]}]}
{"op":"mcm","clk":"4289784245","pt":1632493743019,"mc":[{"id":"1.188075669","rc":[{"batb":[[0,1.18,85.86],[1,1.17,1033.94],[2,1.16,67.78]],"batl":[[0,1.26,9.31]],"ltp":1.18,"tv":12893.93,"id":9631939},{"batb":[[0,4.8,2]],"batl":[[0,6.4,2]],"ltp":6.2,"tv":825.71,"id":9454286}]}]}
{"op":"mcm","clk":"4289784320","pt":1632493744044,"mc":[{"id":"1.188075669","rc":[{"batl":[[0,6.2,218.27],[1,6.4,2],[2,6.6,5]],"ltp":6.2,"tv":825.71,"id":9454286}]}]}
{"op":"mcm","clk":"4289784355","pt":1632493744513,"mc":[{"id":"1.188075669","rc":[{"batb":[[0,1.22,234.49],[1,1.21,540.2],[2,1.18,85.86]],"batl":[[0,1.24,333.8],[1,1.25,422.9],[2,1.26,9]],"ltp":1.18,"tv":12893.93,"id":9631939},{"batl":[[0,6.4,2],[1,6.6,5],[2,7,2]],"ltp":6.2,"tv":825.71,"id":9454286}]}]}
{"op":"mcm","clk":"4289784457","pt":1632493745923,"mc":[{"id":"1.188075669","rc":[{"batb":[[2,1.19,197.46]],"batl":[[2,1.26,96.25]],"ltp":1.18,"tv":12893.93,"id":9631939},{"batb":[[0,4.9,24.65],[1,4.8,4.73],[2,4.7,106.09]],"batl":[[0,6.2,10],[1,6.4,4],[2,6.6,5]],"ltp":6.2,"tv":825.71,"id":9454286}]}]}
{"op":"mcm","clk":"4289784679","pt":1632493749222,"mc":[{"id":"1.188075669","rc":[{"batb":[[0,1.18,85.86],[1,1.17,1033.94],[2,1.16,67.78]],"batl":[[0,1.26,9.31],[1,1.27,9.31],[2,1.28,104.34]],"ltp":1.18,"tv":12893.93,"id":9631939},{"batb":[[0,4.8,2],[1,4.7,106.09],[2,4.6,2]],"batl":[[0,6.4,2],[1,6.6,5],[2,7,2]],"ltp":6.2,"tv":825.71,"id":9454286}]}]}
{"op":"mcm","clk":"4289784795","pt":1632493751361,"mc":[{"id":"1.188075669","rc":[{"batb":[[0,1.19,477.84],[1,1.18,741.09],[2,1.17,1033.94]],"batl":[[2,1.28,609.32]],"ltp":1.18,"tv":12893.93,"id":9631939}]}]}
{"op":"mcm","clk":"4289784887","pt":1632493752517,"mc":[{"id":"1.188075669","rc":[{"batb":[[0,1.19,544.55]],"ltp":1.18,"tv":12893.93,"id":9631939},{"batl":[[0,6.4,4]],"ltp":6.2,"tv":825.71,"id":9454286}]}]}
{"op":"mcm","clk":"4289785118","pt":1632493756139,"mc":[{"id":"1.188075669","rc":[{"batb":[[2,1.17,1018.94]],"batl":[[1,1.28,600.63],[2,1.29,350.95]],"ltp":1.18,"tv":12893.93,"id":9631939},{"batb":[[1,4.7,104.09],[2,4.5,2.68]],"batl":[[1,6.6,2]],"ltp":6.2,"tv":825.71,"id":9454286}]}]}
{"op":"mcm","clk":"4289785293","pt":1632493758551,"mc":[{"id":"1.188075669","rc":[{"batb":[[0,1.18,85.86],[1,1.17,1018.94],[2,1.16,67.78]],"ltp":1.18,"tv":12893.93,"id":9631939},{"batl":[[0,6.4,2]],"ltp":6.2,"tv":825.71,"id":9454286}]}]}
{"op":"mcm","clk":"4289785394","pt":1632493759972,"mc":[{"id":"1.188075669","rc":[{"batl":[[0,1.28,600.94],[1,1.29,350.95],[2,1.76,5.26]],"ltp":1.18,"tv":12893.93,"id":9631939},{"batb":[[0,4.7,104.09],[1,4.5,2.68],[2,3,5.26]],"ltp":6.2,"tv":825.71,"id":9454286}]}]}
{"op":"mcm","clk":"4289785471","pt":1632493761176,"mc":[{"id":"1.188075669","rc":[{"trd":[[1.25,128.92]],"batb":[[0,1.25,7463.59],[1,1.24,1234.92],[2,1.23,1871.22]],"batl":[[0,1.28,600.63]],"ltp":1.25,"tv":12894.55,"id":9631939},{"batb":[[0,4.8,162.36],[1,4.7,104.09],[2,4.5,2.68]],"batl":[[0,5,4.28],[1,5.5,122.83],[2,6,5]],"ltp":6.2,"tv":825.71,"id":9454286}],"tv":13720.27}]}
{"op":"mcm","clk":"4289785546","pt":1632493762168,"mc":[{"id":"1.188075669","rc":[{"batb":[[0,1.25,892.11],[2,1.23,1414.55]],"batl":[[0,1.26,23.81],[1,1.28,600.63],[2,1.29,350.95]],"ltp":1.25,"tv":12894.55,"id":9631939}]}]}
{"op":"mcm","clk":"4289785611","pt":1632493762864,"mc":[{"id":"1.188075669","rc":[{"batl":[[2,1.29,410.95]],"ltp":1.25,"tv":12894.55,"id":9631939},{"batb":[[2,4.5,6.96]],"batl":[[1,5.4,28.6],[2,5.5,122.83]],"ltp":6.2,"tv":825.71,"id":9454286}]}]}
{"op":"mcm","clk":"4289785649","pt":1632493763271,"mc":[{"id":"1.188075669","rc":[{"batl":[[1,1.28,664.55]],"ltp":1.25,"tv":12894.55,"id":9631939}]}]}
{"op":"mcm","clk":"4289785854","pt":1632493766168,"mc":[{"id":"1.188075669","rc":[{"batl":[[1,5.5,122.83],[2,5.9,10]],"ltp":6.2,"tv":825.71,"id":9454286}]}]}
{"op":"mcm","clk":"4289786013","pt":1632493769141,"mc":[{"id":"1.188075669","rc":[{"batl":[[2,5.8,2]],"ltp":6.2,"tv":825.71,"id":9454286}]}]}
{"op":"mcm","clk":"4289786054","pt":1632493769663,"mc":[{"id":"1.188075669","rc":[{"batb":[[2,1.23,1539.65]],"ltp":1.25,"tv":12894.55,"id":9631939},{"batl":[[1,5.3,28.93],[2,5.5,122.83]],"ltp":6.2,"tv":825.71,"id":9454286}]}]}
{"op":"mcm","clk":"4289786261","pt":1632493772882,"mc":[{"id":"1.188075669","rc":[{"batb":[[0,1.25,325.58]],"ltp":1.25,"tv":12894.55,"id":9631939}]}]}
{"op":"mcm","clk":"4289786324","pt":1632493773779,"mc":[{"id":"1.188075669","rc":[{"trd":[[1.25,129.7]],"batb":[[0,1.25,325.19]],"ltp":1.25,"tv":12895.33,"id":9631939}],"tv":13721.05}]}
{"op":"mcm","clk":"4289786873","pt":1632493782073,"mc":[{"id":"1.188075669","rc":[{"batb":[[0,1.23,791.17],[1,1.21,52.69],[2,1.2,775.65]],"batl":[[0,1.29,60.62],[1,1.32,93.11],[2,1.34,80.38]],"ltp":1.25,"tv":12895.33,"id":9631939},{"batb":[[0,4.7,104.09],[1,4.5,4.28],[2,4.1,2.94]],"batl":[[0,5.3,28.93],[1,5.8,2],[2,6.2,2]],"ltp":6.2,"tv":825.71,"id":9454286}]}]}
{"op":"mcm","clk":"4289786890","pt":1632493782385,"mc":[{"id":"1.188075669","rc":[{"batb":[[0,1.23,125.1]],"ltp":1.25,"tv":12895.33,"id":9631939},{"batb":[[0,4.5,4.28],[1,4.1,2.94],[2,3.9,165.68]],"ltp":6.2,"tv":825.71,"id":9454286}]}]}
{"op":"mcm","clk":"4289786972","pt":1632493783755,"mc":[{"id":"1.188075669","rc":[{"batb":[[0,1.2,775.65],[1,1.19,74.71],[2,1.18,72.86]],"batl":[[0,1.33,1.25],[1,1.34,79.75],[2,1.76,4.63]],"ltp":1.25,"tv":12895.33,"id":9631939},{"batb":[[0,3.9,165.68],[1,3,5.26],[2,2.8,382.14]],"batl":[[0,6.2,2],[1,6.4,2],[2,6.6,2]],"ltp":6.2,"tv":825.71,"id":9454286}]}]}
{"op":"mcm","clk":"4289787183","pt":1632493787009,"mc":[{"id":"1.188075669","rc":[{"batb":[[0,1.21,58.69],[1,1.2,787.65],[2,1.19,74.71]],"batl":[[0,1.31,8.62],[1,1.32,96.11],[2,1.34,88.38]],"ltp":1.25,"tv":12895.33,"id":9631939},{"batb":[[0,4.1,6.04],[1,4,3],[2,3.9,168.68]],"batl":[[0,5.8,2],[1,6,2],[2,6.2,2]],"ltp":6.2,"tv":825.71,"id":9454286}]}]}
{"op":"mcm","clk":"4289787263","pt":1632493788106,"mc":[{"id":"1.188075669","rc":[{"batb":[[0,1.26,398.52],[1,1.25,443.4],[2,1.2,787.65]],"batl":[[0,1.29,391.34],[1,1.3,338.91],[2,1.31,8]],"ltp":1.25,"tv":12895.33,"id":9631939},{"batb":[[0,4.1,3]],"batl":[[0,6,2],[1,6.2,2],[2,6.4,2]],"ltp":6.2,"tv":825.71,"id":9454286}]}]}
{"op":"mcm","clk":"4289787375","pt":1632493789685,"mc":[{"id":"1.188075669","rc":[{"batb":[[0,4.2,3],[1,4.1,3],[2,4,3]],"ltp":6.2,"tv":825.71,"id":9454286}]}]}
{"op":"mcm","clk":"4289787434","pt":1632493790592,"mc":[{"id":"1.188075669","rc":[{"batb":[[2,1.22,160.39]],"ltp":1.25,"tv":12895.33,"id":9631939},{"batb":[[1,4.1,6.14]],"batl":[[0,5.7,10],[1,5.8,2],[2,6,2]],"ltp":6.2,"tv":825.71,"id":9454286}]}]}
{"op":"mcm","clk":"4289787617","pt":1632493793212,"mc":[{"id":"1.188075669","rc":[{"batb":[[0,1.21,58.69],[1,1.2,787.65],[2,1.19,74.71]],"batl":[[0,1.31,8.62],[1,1.32,96.86],[2,1.34,88.38]],"ltp":1.25,"tv":12895.33,"id":9631939},{"batl":[[0,5.8,2],[1,6,2],[2,6.2,2]],"ltp":6.2,"tv":825.71,"id":9454286}]}]}
{"op":"mcm","clk":"4289787679","pt":1632493794005,"mc":[{"id":"1.188075669","rc":[{"batb":[[0,1.2,787.65],[1,1.19,74.71],[2,1.18,72.86]],"batl":[[1,1.32,10]],"ltp":1.25,"tv":12895.33,"id":9631939},{"batb":[[1,4.1,3]],"batl":[[0,6,2],[1,6.2,2],[2,6.4,2]],"ltp":6.2,"tv":825.71,"id":9454286}]}]}
{"op":"mcm","clk":"4289787823","pt":1632493796100,"mc":[{"id":"1.188075669","rc":[{"batb":[[0,1.22,414.37],[1,1.21,545.74],[2,1.2,787.65]],"batl":[[2,1.34,324.26]],"ltp":1.25,"tv":12895.33,"id":9631939}]}]}
{"op":"mcm","clk":"4289787906","pt":1632493797108,"mc":[{"id":"1.188075669","rc":[{"batb":[[1,1.21,599.43]],"ltp":1.25,"tv":12895.33,"id":9631939},{"batl":[[0,5.8,2],[1,6,2],[2,6.2,2]],"ltp":6.2,"tv":825.71,"id":9454286}]}]}
{"op":"mcm","clk":"4289788146","pt":1632493800600,"mc":[{"id":"1.188075669","rc":[{"batl":[[1,1.34,316.26],[2,1.35,283.23]],"ltp":1.25,"tv":12895.33,"id":9631939},{"batb":[[1,3.9,165.68],[2,2.8,382.14]],"batl":[[2,6.4,2]],"ltp":6.2,"tv":825.71,"id":9454286}]}]}
{"op":"mcm","clk":"4289788488","pt":1632493804211,"mc":[{"id":"1.188075669","rc":[{"batb":[[1,4.1,3],[2,3.9,165.68]],"ltp":6.2,"tv":825.71,"id":9454286}]}]}
{"op":"mcm","clk":"4289789244","pt":1632493815147,"mc":[{"id":"1.188075669","rc":[{"batb":[[1,4.1,6.04]],"ltp":6.2,"tv":825.71,"id":9454286}]}]}
{"op":"mcm","clk":"4289789262","pt":1632493815565,"mc":[{"id":"1.188075669","rc":[{"batb":[[1,4.1,3]],"ltp":6.2,"tv":825.71,"id":9454286}]}]}
{"op":"mcm","clk":"4289789502","pt":1632493819044,"mc":[{"id":"1.188075669","rc":[{"batb":[[1,3.9,165.68],[2,2.8,382.14]],"ltp":6.2,"tv":825.71,"id":9454286}]}]}
{"op":"mcm","clk":"4289789735","pt":1632493822078,"mc":[{"id":"1.188075669","rc":[{"batb":[[0,1.2,787.65],[1,1.19,64.71],[2,1.18,72.86]],"ltp":1.25,"tv":12895.33,"id":9631939},{"batb":[[1,4.1,3],[2,3.9,165.68]],"batl":[[0,6,2],[1,6.4,2],[2,6.6,2]],"ltp":6.2,"tv":825.71,"id":9454286}]}]}
{"op":"mcm","clk":"4289789899","pt":1632493824171,"mc":[{"id":"1.188075669","rc":[{"trd":[[1.27,13.76],[1.29,0.62],[1.31,16]],"batb":[[0,1.31,6040.1],[1,1.3,2942.3],[2,1.29,2855.76]],"batl":[[0,1.33,12.42],[1,1.34,315.63]],"ltp":1.31,"tv":12912.57,"id":9631939},{"trd":[[4.2,6]],"batb":[[0,4.1,3],[1,4,193.09]],"batl":[[0,4.2,3.91],[1,4.7,247.48],[2,5.1,5.88]],"ltp":4.2,"tv":831.71,"id":9454286}],"tv":13744.29}]}
{"op":"mcm","clk":"4289789987","pt":1632493825168,"mc":[{"id":"1.188075669","rc":[{"trd":[[1.31,61.8]],"batb":[[0,1.31,814.99],[1,1.3,1090.11],[2,1.29,713.94]],"ltp":1.31,"tv":12958.37,"id":9631939},{"batb":[[0,4,193.09],[1,3.9,165.68],[2,3.8,251.64]],"ltp":4.2,"tv":831.71,"id":9454286}],"tv":13790.09}]}
{"op":"mcm","clk":"4289790069","pt":1632493826163,"mc":[{"id":"1.188075669","rc":[{"batb":[[1,1.3,1580.89]],"ltp":1.31,"tv":12958.37,"id":9631939},{"batl":[[2,4.9,10]],"ltp":4.2,"tv":831.71,"id":9454286}]}]}
{"op":"mcm","clk":"4289790151","pt":1632493827158,"mc":[{"id":"1.188075669","rc":[{"batl":[[2,1.35,343.23]],"ltp":1.31,"tv":12958.37,"id":9631939},{"batb":[[2,3.85,5.26]],"batl":[[1,4.6,31.62],[2,4.7,247.48]],"ltp":4.2,"tv":831.71,"id":9454286}]}]}
{"op":"mcm","clk":"4289790213","pt":1632493828058,"mc":[{"id":"1.188075669","rc":[{"batl":[[2,1.35,283.23]],"ltp":1.31,"tv":12958.37,"id":9631939},{"batl":[[1,4.7,247.48],[2,4.9,10]],"ltp":4.2,"tv":831.71,"id":9454286}]}]}
{"op":"mcm","clk":"4289790296","pt":1632493829207,"mc":[{"id":"1.188075669","rc":[{"batl":[[0,1.32,22.48],[1,1.33,12.42],[2,1.34,315.63]],"ltp":1.31,"tv":12958.37,"id":9631939},{"batl":[[1,4.5,56.49],[2,4.7,247.48]],"ltp":4.2,"tv":831.71,"id":9454286}]}]}
{"op":"mcm","clk":"4289790335","pt":1632493829679,"mc":[{"id":"1.188075669","rc":[{"batl":[[0,1.33,12.42],[1,1.34,315.63],[2,1.35,283.23]],"ltp":1.31,"tv":12958.37,"id":9631939},{"batl":[[1,4.7,247.48],[2,4.9,10]],"ltp":4.2,"tv":831.71,"id":9454286}]}]}
{"op":"mcm","clk":"4289790471","pt":1632493831069,"mc":[{"id":"1.188075669","rc":[{"batb":[[0,1.31,922.99]],"batl":[[2,1.35,343.23]],"ltp":1.31,"tv":12958.37,"id":9631939},{"batl":[[1,4.6,31.62],[2,4.7,247.48]],"ltp":4.2,"tv":831.71,"id":9454286}]}]}
{"op":"mcm","clk":"4289790536","pt":1632493832083,"mc":[{"id":"1.188075669","rc":[{"batl":[[1,4.7,247.48],[2,4.9,10]],"ltp":4.2,"tv":831.71,"id":9454286}]}]}
{"op":"mcm","clk":"4289790712","pt":1632493834193,"mc":[{"id":"1.188075669","rc":[{"batb":[[0,1.31,1034.99]],"ltp":1.31,"tv":12958.37,"id":9631939}]}]}
{"op":"mcm","clk":"4289790752","pt":1632493834673,"mc":[{"id":"1.188075669","rc":[{"batl":[[0,1.34,316.26],[1,1.35,343.23],[2,1.41,87.5]],"ltp":1.31,"tv":12958.37,"id":9631939},{"batl":[[0,4.7,247.48],[1,5.1,5.88],[2,5.2,1.71]],"ltp":4.2,"tv":831.71,"id":9454286}]}]}
{"op":"mcm","clk":"4289790866","pt":1632493836203,"mc":[{"id":"1.188075669","rc":[{"batb":[[0,1.31,577.83],[2,1.29,825.35]],"ltp":1.31,"tv":12958.37,"id":9631939},{"batl":[[0,4.5,32.07],[1,4.7,247.48],[2,5.1,5.88]],"ltp":4.2,"tv":831.71,"id":9454286}]}]}
{"op":"mcm","clk":"4289790987","pt":1632493837910,"mc":[{"id":"1.188075669","rc":[{"batl":[[0,1.33,21.89],[1,1.34,357.63],[2,1.35,343.23]],"ltp":1.31,"tv":12958.37,"id":9631939},{"batl":[[0,4.2,3.91],[1,4.5,32.07],[2,4.6,30.81]],"ltp":4.2,"tv":831.71,"id":9454286}]}]}
{"op":"mcm","clk":"4289791734","pt":1632493848704,"mc":[{"id":"1.188075669","rc":[{"batb":[[0,1.31,691.83]],"ltp":1.31,"tv":12958.37,"id":9631939}]}]}
{"op":"mcm","clk":"4289792242","pt":1632493856198,"mc":[{"id":"1.188075669","rc":[{"batb":[[1,1.3,845.31],[2,1.29,111.41]],"batl":[[0,1.34,236.51],[1,1.35,343.23],[2,1.42,87.25]],"ltp":1.31,"tv":12958.37,"id":9631939},{"batb":[[0,3.9,162.22],[1,3.85,5.26],[2,3.35,4.27]],"batl":[[0,4.5,32.07],[1,6,2],[2,6.6,100.74]],"ltp":4.2,"tv":831.71,"id":9454286}]}]}
{"op":"mcm","clk":"4289792294","pt":1632493857133,"mc":[{"id":"1.188075669","rc":[{"trd":[[1.31,62.2]],"batb":[[0,1.29,111.41],[1,1.26,591.75],[2,1.2,12]],"batl":[[0,1.35,60.63],[1,1.42,87.25],[2,1.44,75.33]],"ltp":1.31,"tv":12958.77,"id":9631939},{"batb":[[0,3.85,5.26],[1,3.35,4.27],[2,3.25,128.56]],"ltp":4.2,"tv":831.71,"id":9454286}],"tv":13790.48}]}
{"op":"mcm","clk":"4289792326","pt":1632493857604,"mc":[{"id":"1.188075669","rc":[{"batb":[[0,1.26,591.75],[1,1.2,12],[2,1.12,2.53]],"batl":[[0,1.45,71.53],[1,1.76,4.63],[2,3.8,27.75]],"ltp":1.31,"tv":12958.77,"id":9631939},{"batb":[[0,3.25,124.59],[1,3.2,3.47],[2,2.8,382.14]],"batl":[[0,6,2],[1,6.6,100.74],[2,6.6,0]],"ltp":4.2,"tv":831.71,"id":9454286}]}]}
{"op":"mcm","clk":"4289792491","pt":1632493860014,"mc":[{"id":"1.188075669","rc":[{"batb":[[0,1.27,398.58],[1,1.26,1014.71],[2,1.2,12]],"batl":[[0,1.43,197.57],[1,1.44,212.83],[2,1.45,70.9]],"ltp":1.31,"tv":12958.77,"id":9631939}]}]}
{"op":"mcm","clk":"4289792542","pt":1632493860810,"mc":[{"id":"1.188075669","rc":[{"batb":[[0,1.26,591.75],[1,1.2,12],[2,1.12,2.53]],"batl":[[0,1.42,89.88],[1,1.45,75.9],[2,1.76,4.63]],"ltp":1.31,"tv":12958.77,"id":9631939},{"batb":[[0,3.35,6.87],[1,3.3,3],[2,3.25,127.59]],"ltp":4.2,"tv":831.71,"id":9454286}]}]}
{"op":"mcm","clk":"4289792568","pt":1632493861226,"mc":[{"id":"1.188075669","rc":[{"batl":[[0,1.42,7.63]],"ltp":1.31,"tv":12958.77,"id":9631939},{"batb":[[0,3.35,3]],"ltp":4.2,"tv":831.71,"id":9454286}]}]}
{"op":"mcm","clk":"4289792710","pt":1632493863118,"mc":[{"id":"1.188075669","rc":[{"batb":[[0,1.32,18.89],[1,1.26,591.75],[2,1.2,12]],"batl":[[0,1.35,19.93],[1,1.42,7],[2,1.43,8]],"ltp":1.31,"tv":12958.77,"id":9631939},{"batl":[[0,4.2,18.68],[1,6,2],[2,6.6,100.74]],"ltp":4.2,"tv":831.71,"id":9454286}]}]}
{"op":"mcm","clk":"4289792734","pt":1632493863535,"mc":[{"id":"1.188075669","rc":[{"trd":[[1.33,1.26]],"batb":[[0,1.33,218.98],[1,1.32,325.12],[2,1.26,591.75]],"batl":[[0,1.36,304.85],[1,1.37,263.42],[2,1.42,7]],"ltp":1.33,"tv":12960.03,"id":9631939},{"batl":[[0,6,2],[1,6.6,100.74],[2,6.6,0]],"ltp":4.2,"tv":831.71,"id":9454286}],"tv":13791.74}]}
{"op":"mcm","clk":"4289792854","pt":1632493865019,"mc":[{"id":"1.188075669","rc":[{"batb":[[2,1.27,169.33]],"batl":[[2,1.41,38.15]],"ltp":1.33,"tv":12960.03,"id":9631939},{"batb":[[0,3.4,15],[1,3.35,6.67],[2,3.3,3]],"batl":[[0,4.7,10],[1,6,2],[2,6.6,100.74]],"ltp":4.2,"tv":831.71,"id":9454286}]}]}
{"op":"mcm","clk":"4289792873","pt":1632493865332,"mc":[{"id":"1.188075669","rc":[{"batl":[[2,1.42,82.25]],"ltp":1.33,"tv":12960.03,"id":9631939}]}]}
{"op":"mcm","clk":"4289792986","pt":1632493867230,"mc":[{"id":"1.188075669","rc":[{"batb":[[0,1.33,219.76]],"ltp":1.33,"tv":12960.03,"id":9631939}]}]}
{"op":"mcm","clk":"4289793102","pt":1632493868842,"mc":[{"id":"1.188075669","rc":[{"batb":[[0,1.26,592.53],[1,1.2,12],[2,1.12,2.53]],"batl":[[0,1.42,7],[1,1.43,8],[2,1.45,75.9]],"ltp":1.33,"tv":12960.03,"id":9631939},{"batb":[[0,3.35,3],[1,3.3,3],[2,3.25,127.59]],"batl":[[0,6,2],[1,6.6,100.74],[2,6.6,0]],"ltp":4.2,"tv":831.71,"id":9454286}]}]}
{"op":"mcm","clk":"4289793357","pt":1632493872037,"mc":[{"id":"1.188075669","rc":[{"batb":[[0,1.27,399],[1,1.26,1014.71],[2,1.2,12]],"batl":[[0,1.42,81.25],[1,1.43,205.27],[2,1.44,212.83]],"ltp":1.33,"tv":12960.03,"id":9631939},{"batb":[[0,3.35,7.07]],"ltp":4.2,"tv":831.71,"id":9454286}]}]}
{"op":"mcm","clk":"4289793375","pt":1632493872357,"mc":[{"id":"1.188075669","rc":[{"batl":[[0,1.42,7]],"ltp":1.33,"tv":12960.03,"id":9631939},{"batb":[[0,3.35,3]],"ltp":4.2,"tv":831.71,"id":9454286}]}]}
{"op":"mcm","clk":"4289793662","pt":1632493875956,"mc":[{"id":"1.188075669","rc":[{"batb":[[0,1.26,592.53],[1,1.2,12],[2,1.12,2.53]],"batl":[[1,1.43,197.27]],"ltp":1.33,"tv":12960.03,"id":9631939},{"batb":[[1,3.25,124.59],[2,3.2,3.47]],"batl":[[1,6.6,0]],"ltp":4.2,"tv":831.71,"id":9454286}]}]}
{"op":"mcm","clk":"4289793812","pt":1632493878171,"mc":[{"id":"1.188075669","rc":[{"batb":[[0,1.4,175.93],[1,1.39,5428.54],[2,1.38,692.94]],"batl":[[0,1.43,197.27],[1,1.44,212.83],[2,1.45,730.38]],"ltp":1.33,"tv":12960.03,"id":9631939},{"batb":[[0,3.35,5.24],[1,3.3,219.75],[2,3.25,124.59]],"batl":[[0,3.5,4.8],[1,4.3,811.74],[2,5.8,440.98]],"ltp":4.2,"tv":831.71,"id":9454286}]}]}
{"op":"mcm","clk":"4289793903","pt":1632493879134,"mc":[{"id":"1.188075669","rc":[{"trd":[[1.4,86.96]],"batb":[[0,1.4,508.43],[1,1.39,663.59]],"ltp":1.4,"tv":13004.13,"id":9631939},{"batl":[[1,4.3,813.45],[2,6,2]],"ltp":4.2,"tv":831.71,"id":9454286}],"tv":13835.84}]}
{"op":"mcm","clk":"4289793988","pt":1632493880132,"mc":[{"id":"1.188075669","rc":[{"batl":[[1,1.44,272.83]],"ltp":1.4,"tv":13004.13,"id":9631939},{"batb":[[1,3.3,226.27],[2,3.25,127.59]],"batl":[[1,3.8,35.85],[2,4.1,10]],"ltp":4.2,"tv":831.71,"id":9454286}]}]}
{"op":"mcm","clk":"4289794056","pt":1632493881174,"mc":[{"id":"1.188075669","rc":[{"batl":[[0,1.43,234.11]],"ltp":1.4,"tv":13004.13,"id":9631939},{"batb":[[1,3.3,245.68]],"ltp":4.2,"tv":831.71,"id":9454286}]}]}
{"op":"mcm","clk":"4289794190","pt":1632493882857,"mc":[{"id":"1.188075669","rc":[{"trd":[[1.4,117.72]],"batb":[[0,1.4,493.05]],"ltp":1.4,"tv":13034.89,"id":9631939},{"batl":[[1,4.1,10],[2,4.3,813.45]],"ltp":4.2,"tv":831.71,"id":9454286}],"tv":13866.6}]}
{"op":"mcm","clk":"4289794392","pt":1632493886068,"mc":[{"id":"1.188075669","rc":[{"batb":[[0,1.41,213],[1,1.4,493.05],[2,1.39,663.59]],"ltp":1.4,"tv":13034.89,"id":9631939},{"batl":[[1,3.75,36.18],[2,4.1,12]],"ltp":4.2,"tv":831.71,"id":9454286}]}]}
{"op":"mcm","clk":"4289794602","pt":1632493889064,"mc":[{"id":"1.188075669","rc":[{"batb":[[0,3.3,245.68],[1,3.25,127.59],[2,3.2,6.47]],"batl":[[0,3.75,36.18],[1,4.1,2],[2,4.3,813.45]],"ltp":4.2,"tv":831.71,"id":9454286}]}]}
{"op":"mcm","clk":"4289794686","pt":1632493890056,"mc":[{"id":"1.188075669","rc":[{"trd":[[1.41,233.35]],"batb":[[0,1.41,207.8],[2,1.39,252.82]],"ltp":1.41,"tv":13045.29,"id":9631939},{"batl":[[2,4.3,811.74]],"ltp":4.2,"tv":831.71,"id":9454286}],"tv":13877.01}]}
{"op":"mcm","clk":"4289794811","pt":1632493891792,"mc":[{"id":"1.188075669","rc":[{"trd":[[1.41,234.91]],"batb":[[0,1.41,207.02]],"ltp":1.41,"tv":13046.85,"id":9631939},{"batb":[[0,3.4,5.03],[1,3.3,245.68],[2,3.25,127.59]],"batl":[[0,3.5,4.8],[1,3.75,36.18],[2,4.1,2]],"ltp":4.2,"tv":831.71,"id":9454286}],"tv":13878.57}]}
{"op":"mcm","clk":"4289794934","pt":1632493893063,"mc":[{"id":"1.188075669","rc":[{"batb":[[0,1.41,317.02]],"ltp":1.41,"tv":13046.85,"id":9631939},{"batl":[[1,3.7,25.82],[2,3.75,36.18]],"ltp":4.2,"tv":831.71,"id":9454286}]}]}
{"op":"mcm","clk":"4289795010","pt":1632493894161,"mc":[{"id":"1.188075669","rc":[{"batb":[[0,3.3,25.93],[1,3.25,127.59],[2,3.2,3.47]],"batl":[[0,3.7,25.82],[1,3.75,36.18],[2,4.1,2]],"ltp":4.2,"tv":831.71,"id":9454286}]}]}
{"op":"mcm","clk":"4289795078","pt":1632493895157,"mc":[{"id":"1.188075669","rc":[{"batb":[[0,1.36,2.35],[1,1.35,412.33],[2,1.33,37.31]],"batl":[[0,1.51,87.5],[1,1.53,71.5],[2,1.54,73.25]],"ltp":1.41,"tv":13046.85,"id":9631939},{"batb":[[0,2.96,4.63],[1,2.88,4.21],[2,2.86,70.1]],"batl":[[0,4.1,2],[1,4.4,2],[2,4.8,2]],"ltp":4.2,"tv":831.71,"id":9454286}]}]}
{"op":"mcm","clk":"4289795139","pt":1632493895997,"mc":[{"id":"1.188075669","rc":[{"batb":[[0,1.41,158.98],[1,1.36,2.35],[2,1.35,412.33]],"batl":[[0,1.53,71.5],[1,1.54,73.25],[2,1.76,4.63]],"ltp":1.41,"tv":13046.85,"id":9631939},{"batb":[[0,2.88,4.21],[1,2.86,70.1],[2,2.84,4.97]],"ltp":4.2,"tv":831.71,"id":9454286}]}]}
{"op":"mcm","clk":"4289795201","pt":1632493896790,"mc":[{"id":"1.188075669","rc":[{"batb":[[0,1.36,2.35],[1,1.35,412.33],[2,1.33,37.31]],"batl":[[0,1.53,71.81]],"ltp":1.41,"tv":13046.85,"id":9631939}]}]}
{"op":"mcm","clk":"4289795292","pt":1632493898156,"mc":[{"id":"1.188075669","rc":[{"batb":[[1,1.35,852.84],[2,1.34,304.86]],"batl":[[0,1.52,228.14],[1,1.53,238.51],[2,1.54,73.25]],"ltp":1.41,"tv":13046.85,"id":9631939}]}]}
{"op":"mcm","clk":"4289795360","pt":1632493899001,"mc":[{"id":"1.188075669","rc":[{"batl":[[0,1.52,230.14],[1,1.53,241.51]],"ltp":1.41,"tv":13046.85,"id":9631939},{"batb":[[0,2.88,7.21],[1,2.86,73.1]],"ltp":4.2,"tv":831.71,"id":9454286}]}]}
{"op":"mcm","clk":"4289795460","pt":1632493900574,"mc":[{"id":"1.188075669","rc":[{"batb":[[0,2.92,3],[1,2.9,3],[2,2.88,7.21]],"ltp":4.2,"tv":831.71,"id":9454286}]}]}
{"op":"mcm","clk":"4289795577","pt":1632493902204,"mc":[{"id":"1.188075669","rc":[{"batl":[[0,1.51,77.81],[1,1.52,229.83],[2,1.53,241.51]],"ltp":1.41,"tv":13046.85,"id":9631939},{"batb":[[0,2.96,4.38],[1,2.92,3],[2,2.9,3]],"ltp":4.2,"tv":831.71,"id":9454286}]}]}
{"op":"mcm","clk":"4289795595","pt":1632493902464,"mc":[{"id":"1.188075669","rc":[{"batl":[[0,1.52,230.14],[1,1.53,241.51],[2,1.54,73.25]],"ltp":1.41,"tv":13046.85,"id":9631939},{"batb":[[0,2.92,3],[1,2.9,3],[2,2.88,7.21]],"ltp":4.2,"tv":831.71,"id":9454286}]}]}
{"op":"mcm","clk":"4289796068","pt":1632493909183,"mc":[{"id":"1.188075669","rc":[{"batl":[[0,1.51,86.81],[1,1.52,229.83],[2,1.53,241.51]],"ltp":1.41,"tv":13046.85,"id":9631939},{"batb":[[0,2.96,4.63],[1,2.92,3],[2,2.9,3]],"ltp":4.2,"tv":831.71,"id":9454286}]}]}
{"op":"mcm","clk":"4289796092","pt":1632493909500,"mc":[{"id":"1.188075669","rc":[{"batl":[[0,1.52,230.14],[1,1.53,241.51],[2,1.54,73.25]],"ltp":1.41,"tv":13046.85,"id":9631939},{"batb":[[0,2.92,3],[1,2.9,3],[2,2.88,7.21]],"ltp":4.2,"tv":831.71,"id":9454286}]}]}
{"op":"mcm","clk":"4289796287","pt":1632493912184,"mc":[{"id":"1.188075669","rc":[{"batb":[[1,1.35,412.33],[2,1.33,37.31]],"batl":[[1,1.53,238.51]],"ltp":1.41,"tv":13046.85,"id":9631939},{"batb":[[2,2.88,4.21]],"ltp":4.2,"tv":831.71,"id":9454286}]}]}
{"op":"mcm","clk":"4289796359","pt":1632493913280,"mc":[{"id":"1.188075669","rc":[{"batb":[[1,2.88,4.21],[2,2.86,70.1]],"ltp":4.2,"tv":831.71,"id":9454286}]}]}
{"op":"mcm","clk":"4289796472","pt":1632493915216,"mc":[{"id":"1.188075669","rc":[{"trd":[[1.42,1627.14]],"batb":[[0,1.48,4880.47],[1,1.47,198.78],[2,1.37,2187.45]],"batl":[[0,1.52,227.83],[2,1.54,497.47]],"ltp":1.42,"tv":13047.47,"id":9631939},{"batb":[[0,2.92,5.15],[2,2.86,404.46]],"batl":[[0,3,6.28],[1,3.2,747.07],[2,3.25,290.04]],"ltp":4.2,"tv":831.71,"id":9454286}],"tv":13879.19}]}
{"op":"mcm","clk":"4289796535","pt":1632493916220,"mc":[{"id":"1.188075669","rc":[{"trd":[[1.48,377.5],[1.5,442.53]],"batb":[[0,1.5,269.26],[1,1.48,549.5],[2,1.47,198.78]],"ltp":1.48,"tv":13076.29,"id":9631939},{"trd":[[3,51.61]],"batl":[[0,3.2,298.82],[1,3.25,290.04],[2,3.3,290.04]],"ltp":3.0,"tv":837.99,"id":9454286}],"tv":13914.29}]}
{"op":"mcm","clk":"4289796604","pt":1632493917119,"mc":[{"id":"1.188075669","rc":[{"batl":[[0,1.52,265.91]],"ltp":1.48,"tv":13076.29,"id":9631939},{"batb":[[0,2.92,20.15]],"ltp":3.0,"tv":837.99,"id":9454286}]}]}
{"op":"mcm","clk":"4289796646","pt":1632493917903,"mc":[{"id":"1.188075669","rc":[{"batb":[[0,2.92,5.15]],"ltp":3.0,"tv":837.99,"id":9454286}]}]}
{"op":"mcm","clk":"4289796774","pt":1632493920001,"mc":[{"id":"1.188075669","rc":[{"batb":[[0,2.92,12.96]],"ltp":3.0,"tv":837.99,"id":9454286}]}]}
{"op":"mcm","clk":"4289796852","pt":1632493921110,"mc":[{"id":"1.188075669","rc":[{"batl":[[0,3.15,17.13],[1,3.2,298.82],[2,3.25,290.04]],"ltp":3.0,"tv":837.99,"id":9454286}]}]}
{"op":"mcm","clk":"4289796959","pt":1632493922908,"mc":[{"id":"1.188075669","rc":[{"batb":[[0,1.51,303],[1,1.5,269.26],[2,1.48,549.5]],"ltp":1.48,"tv":13076.29,"id":9631939}]}]}
{"op":"mcm","clk":"4289797031","pt":1632493924122,"mc":[{"id":"1.188075669","rc":[{"batb":[[2,1.49,270.19]],"batl":[[1,1.53,298.51]],"ltp":1.48,"tv":13076.29,"id":9631939},{"batb":[[0,2.92,33.34],[1,2.88,73.97]],"ltp":3.0,"tv":837.99,"id":9454286}]}]}
{"op":"mcm","clk":"4289797089","pt":1632493925015,"mc":[{"id":"1.188075669","rc":[{"trd":[[1.51,2119.45]],"batb":[[0,1.51,302.8],[1,1.49,270.19],[2,1.48,549.5]],"ltp":1.51,"tv":13076.69,"id":9631939},{"batb":[[2,2.86,334.36]],"ltp":3.0,"tv":837.99,"id":9454286}],"tv":13914.68}]}
{"op":"mcm","clk":"4289797157","pt":1632493926117,"mc":[{"id":"1.188075669","rc":[{"batb":[[0,2.92,28.19]],"ltp":3.0,"tv":837.99,"id":9454286}]}]}
{"op":"mcm","clk":"4289797186","pt":1632493926746,"mc":[{"id":"1.188075669","rc":[{"batb":[[2,1.48,184.94]],"ltp":1.51,"tv":13076.69,"id":9631939},{"batl":[[2,3.25,330.04]],"ltp":3.0,"tv":837.99,"id":9454286}]}]}
{"op":"mcm","clk":"4289797224","pt":1632493927326,"mc":[{"id":"1.188075669","rc":[{"trd":[[1.51,2120.07]],"batb":[[0,1.51,302.49]],"ltp":1.51,"tv":13077.31,"id":9631939}],"tv":13915.3}]}
{"op":"mcm","clk":"4289797324","pt":1632493928853,"mc":[{"id":"1.188075669","rc":[{"batb":[[0,2.96,5.68],[1,2.92,28.19],[2,2.88,73.97]],"batl":[[0,3.05,6.79],[1,3.15,17.13],[2,3.2,298.82]],"ltp":3.0,"tv":837.99,"id":9454286}]}]}
{"op":"mcm","clk":"4289797418","pt":1632493930019,"mc":[{"id":"1.188075669","rc":[{"batb":[[0,1.51,464.69]],"ltp":1.51,"tv":13077.31,"id":9631939}]}]}
{"op":"mcm","clk":"4289797558","pt":1632493932119,"mc":[{"id":"1.188075669","rc":[{"batb":[[2,2.9,68.5]],"ltp":3.0,"tv":837.99,"id":9454286}]}]}
{"op":"mcm","clk":"4289797860","pt":1632493935956,"mc":[{"id":"1.188075669","rc":[{"batb":[[1,2.92,20.38]],"ltp":3.0,"tv":837.99,"id":9454286}]}]}
{"op":"mcm","clk":"4289798101","pt":1632493939167,"mc":[{"id":"1.188075669","rc":[{"trd":[[1.51,2178.25],[1.52,2736.29]],"batb":[[0,1.51,435.6]],"batl":[[0,1.52,265.71]],"ltp":1.52,"tv":13135.88,"id":9631939}],"tv":13973.88}]}
{"op":"mcm","clk":"4289798389","pt":1632493942961,"mc":[{"id":"1.188075669","rc":[{"batb":[[0,1.51,685]],"ltp":1.52,"tv":13135.88,"id":9631939}]}]}
{"op":"mcm","clk":"4289798469","pt":1632493944273,"mc":[{"id":"1.188075669","rc":[{"trd":[[1.51,2179.03]],"batb":[[0,1.51,684.61]],"ltp":1.51,"tv":13136.66,"id":9631939}],"tv":13974.66}]}
{"op":"mcm","clk":"4289798920","pt":1632493951633,"mc":[{"id":"1.188075669","rc":[{"trd":[[1.51,2255.25]],"batb":[[0,1.51,646.5]],"ltp":1.51,"tv":13212.88,"id":9631939}],"tv":14050.88}]}
{"op":"mcm","clk":"4289800934","pt":1632493984108,"mc":[{"id":"1.188075669","rc":[{"trd":[[1.52,2736.69]],"batl":[[0,1.52,265.51]],"ltp":1.52,"tv":13213.28,"id":9631939}],"tv":14051.27}]}
{"op":"mcm","clk":"4289801420","pt":1632493991035,"mc":[{"id":"1.188075669","rc":[{"trd":[[1.51,2255.87]],"batb":[[0,1.51,646.19]],"ltp":1.51,"tv":13213.9,"id":9631939}],"tv":14051.89}]}
{"op":"mcm","clk":"4289802231","pt":1632494003871,"mc":[{"id":"1.188075669","rc":[{"trd":[[1.51,2396.58]],"batb":[[0,1.51,575.84]],"ltp":1.51,"tv":13354.6,"id":9631939}],"tv":14192.6}]}
{"op":"mcm","clk":"4289802519","pt":1632494008159,"mc":[{"id":"1.188075669","rc":[{"batb":[[0,1.4,349.32],[1,1.37,35.77],[2,1.32,39.17]],"batl":[[0,1.53,60],[1,1.55,87.9],[2,1.57,83.5]],"ltp":1.51,"tv":13354.6,"id":9631939},{"batb":[[0,2.86,8.06],[1,2.8,5.63],[2,2.74,5.02]],"batl":[[0,3.25,40],[1,3.75,2],[2,4.2,152.71]],"ltp":3.0,"tv":837.99,"id":9454286}]}]}
{"op":"mcm","clk":"4289802548","pt":1632494008576,"mc":[{"id":"1.188075669","rc":[{"batl":[[0,1.57,83.5],[1,1.76,4.63],[2,3.8,27.75]],"ltp":1.51,"tv":13354.6,"id":9631939},{"batb":[[0,2.74,5.02],[1,2.7,81.74],[2,2.38,389.23]],"batl":[[0,3.75,2],[1,4.2,152.71],[2,4.8,2]],"ltp":3.0,"tv":837.99,"id":9454286}]}]}
{"op":"mcm","clk":"4289802783","pt":1632494011163,"mc":[{"id":"1.188075669","rc":[{"batb":[[0,1.4,607.17],[1,1.39,254.04],[2,1.37,35.77]],"batl":[[1,1.58,239.09],[2,1.59,144.77]],"ltp":1.51,"tv":13354.6,"id":9631939}]}]}
{"op":"mcm","clk":"4289802836","pt":1632494011956,"mc":[{"id":"1.188075669","rc":[{"batb":[[0,1.4,349.32],[1,1.37,35.77],[2,1.32,39.17]],"batl":[[0,1.57,89.5]],"ltp":1.51,"tv":13354.6,"id":9631939},{"batb":[[0,2.74,8.02],[1,2.72,3],[2,2.7,81.74]],"ltp":3.0,"tv":837.99,"id":9454286}]}]}
{"op":"mcm","clk":"4289802975","pt":1632494013654,"mc":[{"id":"1.188075669","rc":[{"batl":[[0,1.57,83.5]],"ltp":1.51,"tv":13354.6,"id":9631939},{"batb":[[0,2.74,5.02],[1,2.7,81.74],[2,2,10.52]],"batl":[[1,4.2,2]],"ltp":3.0,"tv":837.99,"id":9454286}]}]}
{"op":"mcm","clk":"4289803087","pt":1632494015175,"mc":[{"id":"1.188075669","rc":[{"batb":[[0,1.53,506.82],[1,1.52,174.19],[2,1.4,349.32]],"batl":[[0,1.56,21.14],[1,1.57,83.5],[2,1.58,614.31]],"ltp":1.51,"tv":13354.6,"id":9631939},{"batl":[[0,2.88,7.24],[1,2.94,325.26],[2,2.96,315.7]],"ltp":3.0,"tv":837.99,"id":9454286}]}]}
{"op":"mcm","clk":"4289803150","pt":1632494016180,"mc":[{"id":"1.188075669","rc":[{"trd":[[1.55,364.72]],"batb":[[0,1.55,217.16],[1,1.53,506.82],[2,1.52,174.19]],"batl":[[0,1.56,14.14]],"ltp":1.55,"tv":13394.86,"id":9631939},{"batb":[[2,2.66,9.03]],"ltp":3.0,"tv":837.99,"id":9454286}],"tv":14232.86}]}
{"op":"mcm","clk":"4289803219","pt":1632494017064,"mc":[{"id":"1.188075669","rc":[{"batb":[[2,2.68,3]],"ltp":3.0,"tv":837.99,"id":9454286}]}]}
{"op":"mcm","clk":"4289803499","pt":1632494021214,"mc":[{"id":"1.188075669","rc":[{"batb":[[0,1.55,432.16]],"ltp":1.55,"tv":13394.86,"id":9631939}]}]}
{"op":"mcm","clk":"4289803532","pt":1632494021687,"mc":[{"id":"1.188075669","rc":[{"batb":[[2,2.68,8.36]],"ltp":3.0,"tv":837.99,"id":9454286}]}]}
{"op":"mcm","clk":"4289803738","pt":1632494024159,"mc":[{"id":"1.188075669","rc":[{"batb":[[0,1.55,553.16]],"ltp":1.55,"tv":13394.86,"id":9631939}]}]}
{"op":"mcm","clk":"4289803880","pt":1632494026398,"mc":[{"id":"1.188075669","rc":[{"batb":[[1,1.53,250.88]],"ltp":1.55,"tv":13394.86,"id":9631939}]}]}
{"op":"mcm","clk":"4289804162","pt":1632494030079,"mc":[{"id":"1.188075669","rc":[{"trd":[[1.55,365.34]],"batb":[[0,1.46,317.93],[1,1.43,26.43],[2,1.37,35.77]],"batl":[[0,1.6,60],[1,1.61,87.5],[2,1.76,4.63]],"ltp":1.55,"tv":13395.48,"id":9631939},{"batb":[[0,2.66,9.03],[1,2.62,6.04],[2,2.56,93.55]],"batl":[[0,3,42.42],[1,3.2,2.03],[2,3.35,2]],"ltp":3.0,"tv":837.99,"id":9454286}],"tv":14233.48}]}
{"op":"mcm","clk":"4289804263","pt":1632494031309,"mc":[{"id":"1.188075669","rc":[{"batl":[[0,1.61,87.5],[1,1.76,4.63],[2,3.8,27.75]],"ltp":1.55,"tv":13395.48,"id":9631939},{"batb":[[0,2.62,6.04],[1,2.56,93.55],[2,2.04,401.24]],"batl":[[0,3.2,2.03],[1,3.35,2],[2,3.45,3]],"ltp":3.0,"tv":837.99,"id":9454286}]}]}
{"op":"mcm","clk":"4289804437","pt":1632494033192,"mc":[{"id":"1.188075669","rc":[{"batb":[[0,1.5,84.85],[1,1.46,317.93],[2,1.43,26.43]],"batl":[[1,1.63,197.21],[2,1.64,129.9]],"ltp":1.55,"tv":13395.48,"id":9631939}]}]}
{"op":"mcm","clk":"4289804476","pt":1632494033728,"mc":[{"id":"1.188075669","rc":[{"batb":[[0,1.46,317.93],[1,1.43,26.43],[2,1.37,35.77]],"ltp":1.55,"tv":13395.48,"id":9631939}]}]}
{"op":"mcm","clk":"4289804544","pt":1632494034699,"mc":[{"id":"1.188075669","rc":[{"batl":[[0,1.61,93.5]],"ltp":1.55,"tv":13395.48,"id":9631939},{"batb":[[0,2.62,9.04],[1,2.6,3],[2,2.56,93.55]],"ltp":3.0,"tv":837.99,"id":9454286}]}]}
{"op":"mcm","clk":"4289804633","pt":1632494036106,"mc":[{"id":"1.188075669","rc":[{"batl":[[0,1.6,13.81],[1,1.61,87.5],[2,1.62,359.93]],"ltp":1.55,"tv":13395.48,"id":9631939},{"batb":[[0,2.62,6.04],[1,2.56,93.55],[2,2.04,401.24]],"batl":[[0,2.72,481.56],[1,2.74,86.4],[2,2.76,86.4]],"ltp":3.0,"tv":837.99,"id":9454286}]}]}
{"op":"mcm","clk":"4289804701","pt":1632494037199,"mc":[{"id":"1.188075669","rc":[{"trd":[[1.58,145.89]],"batb":[[0,1.59,211.99],[1,1.58,195],[2,1.57,153.67]],"batl":[[0,1.6,18.81]],"ltp":1.58,"tv":13434.7,"id":9631939},{"batb":[[2,2.54,185.04]],"ltp":3.0,"tv":837.99,"id":9454286}],"tv":14272.7}]}
{"op":"mcm","clk":"4289804736","pt":1632494037626,"mc":[{"id":"1.188075669","rc":[{"trd":[[1.6,26.95]],"batl":[[0,1.61,87.5],[1,1.62,359.93],[2,1.63,197.21]],"ltp":1.6,"tv":13448.51,"id":9631939},{"trd":[[2.62,11.45],[2.66,20.15]],"batb":[[0,2.62,1.66]],"ltp":2.62,"tv":855.06,"id":9454286}],"tv":14303.58}]}
{"op":"mcm","clk":"4289804867","pt":1632494039207,"mc":[{"id":"1.188075669","rc":[{"batb":[[2,2.54,189.04]],"ltp":2.62,"tv":855.06,"id":9454286}]}]}
{"op":"mcm","clk":"4289805020","pt":1632494041218,"mc":[{"id":"1.188075669","rc":[{"trd":[[1.59,9.03]],"batb":[[0,1.59,207.67]],"ltp":1.59,"tv":13457.15,"id":9631939}],"tv":14312.22}]}
{"op":"mcm","clk":"4289805080","pt":1632494042001,"mc":[{"id":"1.188075669","rc":[{"batb":[[0,1.59,360.67]],"ltp":1.59,"tv":13457.15,"id":9631939}]}]}
{"op":"mcm","clk":"4289805158","pt":1632494043111,"mc":[{"id":"1.188075669","rc":[{"batl":[[2,1.63,269.71]],"ltp":1.59,"tv":13457.15,"id":9631939},{"batb":[[1,2.58,5.56],[2,2.56,98.88]],"ltp":2.62,"tv":855.06,"id":9454286}]}]}
{"op":"mcm","clk":"4289805319","pt":1632494045215,"mc":[{"id":"1.188075669","rc":[{"batb":[[0,1.59,506.67]],"batl":[[1,1.63,269.71],[2,1.64,214.58]],"ltp":1.59,"tv":13457.15,"id":9631939},{"batl":[[0,2.72,239.16],[1,2.74,43.2],[2,2.76,43.2]],"ltp":2.62,"tv":855.06,"id":9454286}]}]}
{"op":"mcm","clk":"4289805385","pt":1632494046015,"mc":[{"id":"1.188075669","rc":[{"batb":[[0,1.55,80.9],[1,1.53,270.23],[2,1.5,23]],"batl":[[0,1.64,84.68],[1,1.76,4.63],[2,3.8,27.75]],"ltp":1.59,"tv":13457.15,"id":9631939},{"batb":[[0,2.56,5.33],[1,2.54,4],[2,2.52,4]],"batl":[[0,2.8,44.72],[1,2.9,2.45],[2,3,2.14]],"ltp":2.62,"tv":855.06,"id":9454286}]}]}
{"op":"mcm","clk":"4289805405","pt":1632494046329,"mc":[{"id":"1.188075669","rc":[{"batb":[[0,1.53,270.23],[1,1.5,23],[2,1.47,7]],"ltp":1.59,"tv":13457.15,"id":9631939},{"batl":[[0,2.9,2.45],[1,3,2.14],[2,3.2,2.03]],"ltp":2.62,"tv":855.06,"id":9454286}]}]}
{"op":"mcm","clk":"4289805561","pt":1632494049117,"mc":[{"id":"1.188075669","rc":[{"batl":[[0,1.63,79.5],[1,1.64,89.68],[2,1.76,4.63]],"ltp":1.59,"tv":13457.15,"id":9631939},{"batb":[[0,2.58,5.56],[1,2.56,8.33],[2,2.54,4]],"ltp":2.62,"tv":855.06,"id":9454286}]}]}
{"op":"mcm","clk":"4289805574","pt":1632494049331,"mc":[{"id":"1.188075669","rc":[{"batl":[[0,1.64,89.68],[1,1.76,4.63],[2,3.8,27.75]],"ltp":1.59,"tv":13457.15,"id":9631939},{"batb":[[0,2.56,8.33],[1,2.54,4],[2,2.52,4]],"ltp":2.62,"tv":855.06,"id":9454286}]}]}
{"op":"mcm","clk":"4289805678","pt":1632494050961,"mc":[{"id":"1.188075669","rc":[{"batb":[[0,1.57,175.7],[1,1.56,157.27],[2,1.53,270.23]],"batl":[[0,1.62,248.31],[1,1.63,132.53],[2,1.64,89.68]],"ltp":1.59,"tv":13457.15,"id":9631939},{"batb":[[1,2.44,106.37],[2,2.04,401.24]],"ltp":2.62,"tv":855.06,"id":9454286}]}]}
{"op":"mcm","clk":"4289805817","pt":1632494052748,"mc":[{"id":"1.188075669","rc":[{"batl":[[1,1.63,210.03]],"ltp":1.59,"tv":13457.15,"id":9631939},{"batb":[[0,2.58,5.56],[1,2.56,8.33],[2,2.44,106.37]],"ltp":2.62,"tv":855.06,"id":9454286}]}]}
{"op":"mcm","clk":"4289805934","pt":1632494053954,"mc":[{"id":"1.188075669","rc":[{"batb":[[0,1.53,270.23],[1,1.5,23],[2,1.47,7]],"batl":[[0,1.63,77.5],[1,1.64,89.68],[2,1.76,4.63]],"ltp":1.59,"tv":13457.15,"id":9631939},{"batb":[[2,2.54,4]],"ltp":2.62,"tv":855.06,"id":9454286}]}]}
{"op":"mcm","clk":"4289805955","pt":1632494054228,"mc":[{"id":"1.188075669","rc":[{"batl":[[0,1.64,89.68],[1,1.76,4.63],[2,3.8,27.75]],"ltp":1.59,"tv":13457.15,"id":9631939},{"batb":[[0,2.56,8.33],[1,2.54,4],[2,2.44,106.37]],"ltp":2.62,"tv":855.06,"id":9454286}]}]}
{"op":"mcm","clk":"4289806169","pt":1632494057043,"mc":[{"id":"1.188075669","rc":[{"batb":[[0,1.61,2.63],[1,1.53,270.23],[2,1.52,251.76]],"batl":[[1,1.67,190.37],[2,1.69,235.8]],"ltp":1.59,"tv":13457.15,"id":9631939}]}]}
{"op":"mcm","clk":"4289806444","pt":1632494060972,"mc":[{"id":"1.188075669","rc":[{"batl":[[0,1.63,84.5],[1,1.64,89.68],[2,1.67,190.37]],"ltp":1.59,"tv":13457.15,"id":9631939},{"batb":[[0,2.58,6.06],[1,2.56,8.33],[2,2.54,4]],"ltp":2.62,"tv":855.06,"id":9454286}]}]}
{"op":"mcm","clk":"4289806476","pt":1632494061344,"mc":[{"id":"1.188075669","rc":[{"batl":[[0,1.64,89.68],[1,1.67,190.37],[2,1.69,235.8]],"ltp":1.59,"tv":13457.15,"id":9631939},{"batb":[[0,2.56,8.33],[1,2.54,4],[2,2.44,106.37]],"ltp":2.62,"tv":855.06,"id":9454286}]}]}
{"op":"mcm","clk":"4289806726","pt":1632494064948,"mc":[{"id":"1.188075669","rc":[{"batb":[[2,1.5,23]],"ltp":1.59,"tv":13457.15,"id":9631939}]}]}
{"op":"mcm","clk":"4289806746","pt":1632494065251,"mc":[{"id":"1.188075669","rc":[{"batb":[[1,2.44,106.37],[2,2.04,401.24]],"ltp":2.62,"tv":855.06,"id":9454286}]}]}
{"op":"mcm","clk":"4289806895","pt":1632494068139,"mc":[{"id":"1.188075669","rc":[{"batb":[[0,1.62,844.57],[1,1.61,142.51],[2,1.53,270.23]],"batl":[[0,1.64,84.68],[1,1.66,493.44],[2,1.67,190.37]],"ltp":1.59,"tv":13457.15,"id":9631939},{"batb":[[0,2.56,5.33],[1,2.44,498.27],[2,2.42,380.38]],"batl":[[0,2.66,898.72],[1,2.68,348.92],[2,2.7,348.92]],"ltp":2.62,"tv":855.06,"id":9454286}]}]}
{"op":"mcm","clk":"4289806963","pt":1632494069183,"mc":[{"id":"1.188075669","rc":[{"trd":[[1.62,90.44],[1.64,199.09]],"batb":[[0,1.64,105.04],[1,1.62,372.75],[2,1.61,142.51]],"batl":[[0,1.66,493.44],[1,1.67,190.37],[2,1.69,235.8]],"ltp":1.64,"tv":13665.83,"id":9631939},{"batl":[[0,2.66,359.48],[2,2.7,394.93]],"ltp":2.62,"tv":855.06,"id":9454286}],"tv":14520.9}]}
{"op":"mcm","clk":"4289807149","pt":1632494071990,"mc":[{"id":"1.188075669","rc":[{"trd":[[2.56,10.66]],"batb":[[0,2.44,498.27],[1,2.42,380.38],[2,2.4,391.09]],"ltp":2.56,"tv":865.72,"id":9454286}],"tv":14531.56}]}
{"op":"mcm","clk":"4289807290","pt":1632494073961,"mc":[{"id":"1.188075669","rc":[{"batl":[[0,2.66,379.79]],"ltp":2.56,"tv":865.72,"id":9454286}]}]}
{"op":"mcm","clk":"4289807347","pt":1632494075166,"mc":[{"id":"1.188075669","rc":[{"batl":[[0,1.65,36.5],[1,1.66,527.69],[2,1.67,190.37]],"ltp":1.64,"tv":13665.83,"id":9631939},{"batb":[[0,2.52,3.24],[1,2.5,2.81],[2,2.46,30.4]],"ltp":2.56,"tv":865.72,"id":9454286}]}]}
{"op":"mcm","clk":"4289807422","pt":1632494076174,"mc":[{"id":"1.188075669","rc":[{"trd":[[1.65,73.78]],"batb":[[0,1.65,268.5],[1,1.64,105.04],[2,1.62,372.75]],"batl":[[0,1.66,527.69],[1,1.67,224.87],[2,1.69,235.8]],"ltp":1.65,"tv":13738.83,"id":9631939},{"batb":[[2,2.48,2.51]],"ltp":2.56,"tv":865.72,"id":9454286}],"tv":14604.56}]}
{"op":"mcm","clk":"4289807569","pt":1632494078380,"mc":[{"id":"1.188075669","rc":[{"batb":[[0,1.65,355.74]],"ltp":1.65,"tv":13738.83,"id":9631939}]}]}
{"op":"mcm","clk":"4289807652","pt":1632494079701,"mc":[{"id":"1.188075669","rc":[{"batb":[[2,1.62,177.1]],"batl":[[2,1.68,15.64]],"ltp":1.65,"tv":13738.83,"id":9631939}]}]}
{"op":"mcm","clk":"4289807851","pt":1632494083200,"mc":[{"id":"1.188075669","rc":[{"trd":[[2.52,6]],"batb":[[0,2.5,3.05],[1,2.48,2.51],[2,2.46,33.28]],"ltp":2.52,"tv":871.72,"id":9454286}],"tv":14610.56}]}
{"op":"mcm","clk":"4289807939","pt":1632494084613,"mc":[{"id":"1.188075669","rc":[{"trd":[[1.65,74.1]],"batb":[[0,1.65,355.58]],"ltp":1.65,"tv":13739.15,"id":9631939}],"tv":14610.88}]}
{"op":"mcm","clk":"4289808329","pt":1632494090200,"mc":[{"id":"1.188075669","rc":[{"batb":[[2,1.62,168.41]],"batl":[[0,1.66,34.25]],"ltp":1.65,"tv":13739.15,"id":9631939},{"batl":[[0,2.66,200.05],[1,2.68,174.46],[2,2.7,220.47]],"ltp":2.52,"tv":871.72,"id":9454286}]}]}
{"op":"mcm","clk":"4289808408","pt":1632494091179,"mc":[{"id":"1.188075669","rc":[{"batb":[[0,1.65,87.24],[1,1.6,77.45],[2,1.59,215.61]],"batl":[[0,1.68,15.64],[1,1.76,4.63],[2,1.68,0]],"ltp":1.65,"tv":13739.15,"id":9631939},{"batb":[[0,2.46,2.88],[1,2.4,10.71],[2,2.38,114.55]],"batl":[[0,2.7,46.01],[1,2.76,2.52],[2,2.9,2.45]],"ltp":2.52,"tv":871.72,"id":9454286}]}]}
{"op":"mcm","clk":"4289808513","pt":1632494092405,"mc":[{"id":"1.188075669","rc":[{"batb":[[1,1.59,215.61],[2,1.57,23.57]],"ltp":1.65,"tv":13739.15,"id":9631939},{"batb":[[1,2.38,114.55],[2,2.04,401.24]],"batl":[[0,2.76,2.52],[1,2.9,2.45],[2,3,2.14]],"ltp":2.52,"tv":871.72,"id":9454286}]}]}
{"op":"mcm","clk":"4289808648","pt":1632494094219,"mc":[{"id":"1.188075669","rc":[{"batb":[[1,1.58,159.46],[2,1.57,395.51]],"batl":[[0,1.67,23.5],[1,1.68,19.64],[2,1.7,218.72]],"ltp":1.65,"tv":13739.15,"id":9631939},{"batb":[[0,2.48,6.76],[1,2.46,5.88],[2,2.44,3]],"ltp":2.52,"tv":871.72,"id":9454286}]}]}
{"op":"mcm","clk":"4289808670","pt":1632494094494,"mc":[{"id":"1.188075669","rc":[{"batl":[[0,1.67,6]],"ltp":1.65,"tv":13739.15,"id":9631939},{"batb":[[0,2.48,4]],"ltp":2.52,"tv":871.72,"id":9454286}]}]}
{"op":"mcm","clk":"4289808941","pt":1632494098123,"mc":[{"id":"1.188075669","rc":[{"batb":[[1,1.57,242.05],[2,1.53,24.33]],"ltp":1.65,"tv":13739.15,"id":9631939}]}]}
{"op":"mcm","clk":"4289809044","pt":1632494099707,"mc":[{"id":"1.188075669","rc":[{"batl":[[0,1.68,15.64],[1,1.7,218.72],[2,1.72,222.15]],"ltp":1.65,"tv":13739.15,"id":9631939},{"batb":[[0,2.46,2.88],[1,2.4,112.78],[2,2.04,401.24]],"ltp":2.52,"tv":871.72,"id":9454286}]}]}
{"op":"mcm","clk":"4289809150","pt":1632494101199,"mc":[{"id":"1.188075669","rc":[{"batb":[[0,1.65,243.7],[1,1.64,244.29],[2,1.63,134.02]],"ltp":1.65,"tv":13739.15,"id":9631939},{"batb":[[0,2.5,203.1],[1,2.46,2.88],[2,2.4,112.78]],"batl":[[0,2.58,370.64],[1,2.6,359.74],[2,2.62,359.74]],"ltp":2.52,"tv":871.72,"id":9454286}]}]}
{"op":"mcm","clk":"4289809220","pt":1632494102221,"mc":[{"id":"1.188075669","rc":[{"trd":[[1.65,112.32]],"batb":[[0,1.66,180.27],[1,1.65,224.59],[2,1.64,244.29]],"ltp":1.65,"tv":13777.37,"id":9631939},{"batl":[[2,2.62,406.88]],"ltp":2.52,"tv":871.72,"id":9454286}],"tv":14649.1}]}
{"op":"mcm","clk":"4289809300","pt":1632494103201,"mc":[{"id":"1.188075669","rc":[{"batb":[[2,2.4,115.78]],"batl":[[2,2.62,359.74]],"ltp":2.52,"tv":871.72,"id":9454286}]}]}
{"op":"mcm","clk":"4289809490","pt":1632494106034,"mc":[{"id":"1.188075669","rc":[{"batl":[[2,1.72,282.15]],"ltp":1.65,"tv":13777.37,"id":9631939}]}]}
{"op":"mcm","clk":"4289809678","pt":1632494109028,"mc":[{"id":"1.188075669","rc":[{"batb":[[0,1.66,318.27],[1,1.65,156.46]],"ltp":1.65,"tv":13777.37,"id":9631939}]}]}
{"op":"mcm","clk":"4289809803","pt":1632494111116,"mc":[{"id":"1.188075669","rc":[{"trd":[[1.66,4.1]],"batb":[[0,1.66,318.17]],"ltp":1.66,"tv":13777.56,"id":9631939}],"tv":14649.29}]}
{"op":"mcm","clk":"4289809881","pt":1632494112529,"mc":[{"id":"1.188075669","rc":[{"batb":[[1,1.64,244.29],[2,1.63,134.02]],"ltp":1.66,"tv":13777.56,"id":9631939}]}]}
{"op":"mcm","clk":"4289810087","pt":1632494115932,"mc":[{"id":"1.188075669","rc":[{"trd":[[1.67,70.35]],"ltp":1.67,"tv":13847.92,"id":9631939},{"trd":[[2.5,47]],"batb":[[0,2.5,156.1]],"ltp":2.5,"tv":918.72,"id":9454286}],"tv":14766.64}]}
{"op":"mcm","clk":"4289810744","pt":1632494126170,"mc":[{"id":"1.188075669","rc":[{"trd":[[1.66,4.72]],"batb":[[0,1.66,317.86],[1,1.64,235.26]],"ltp":1.66,"tv":13848.54,"id":9631939}],"tv":14767.26}]}
{"op":"mcm","clk":"4289810928","pt":1632494128948,"mc":[{"id":"1.188075669","rc":[{"batb":[[0,1.66,138],[1,1.58,232.38],[2,1.55,23.19]],"batl":[[0,1.72,60],[1,1.76,4.63],[2,1.81,14.5]],"ltp":1.66,"tv":13848.54,"id":9631939},{"batb":[[0,2.22,2.93],[1,2.16,3.53],[2,2.14,155.13]],"batl":[[0,2.66,46.56],[1,2.74,2.75],[2,2.82,2.47]],"ltp":2.5,"tv":918.72,"id":9454286}]}]}
{"op":"mcm","clk":"4289810988","pt":1632494130047,"mc":[{"id":"1.188075669","rc":[{"batb":[[0,1.58,232.38],[1,1.55,23.19],[2,1.47,7]],"ltp":1.66,"tv":13848.54,"id":9631939}]}]}
{"op":"mcm","clk":"4289810996","pt":1632494130258,"mc":[{"id":"1.188075669","rc":[{"batl":[[0,1.76,4.63],[1,1.81,14.5],[2,1.86,15.25]],"ltp":1.66,"tv":13848.54,"id":9631939},{"batl":[[0,2.74,2.75],[1,2.82,2.47],[2,3.45,186.67]],"ltp":2.5,"tv":918.72,"id":9454286}]}]}
{"op":"mcm","clk":"4289811103","pt":1632494132149,"mc":[{"id":"1.188075669","rc":[{"batb":[[1,1.57,263.98],[2,1.56,157.7]],"batl":[[0,1.66,18.53],[1,1.76,4.63],[2,1.85,170.53]],"ltp":1.66,"tv":13848.54,"id":9631939},{"batb":[[0,2.16,3.53],[1,2.14,155.13],[2,2.04,401.24]],"ltp":2.5,"tv":918.72,"id":9454286}]}]}
{"op":"mcm","clk":"4289811140","pt":1632494132777,"mc":[{"id":"1.188075669","rc":[{"batl":[[2,1.86,15.25]],"ltp":1.66,"tv":13848.54,"id":9631939}]}]}
{"op":"mcm","clk":"4289811277","pt":1632494135185,"mc":[{"id":"1.188075669","rc":[{"batl":[[0,1.66,88.88]],"ltp":1.66,"tv":13848.54,"id":9631939}]}]}
{"op":"mcm","clk":"4289811345","pt":1632494136179,"mc":[{"id":"1.188075669","rc":[{"trd":[[1.58,166.91],[1.6,45.41]],"batb":[[0,1.58,221.87]],"batl":[[0,1.61,15.5],[1,1.62,335.03],[2,1.63,719.54]],"ltp":1.58,"tv":13888.02,"id":9631939},{"batb":[[0,2.62,3.33],[1,2.6,7.25],[2,2.46,771.61]],"batl":[[2,2.84,565.67]],"ltp":2.5,"tv":918.72,"id":9454286}],"tv":14806.74}]}
{"op":"mcm","clk":"4289811403","pt":1632494137177,"mc":[{"id":"1.188075669","rc":[{"batb":[[2,2.56,93.38]],"ltp":2.5,"tv":918.72,"id":9454286}]}]}
{"op":"mcm","clk":"4289811511","pt":1632494138589,"mc":[{"id":"1.188075669","rc":[{"batb":[[2,2.56,97.38]],"ltp":2.5,"tv":918.72,"id":9454286}]}]}
{"op":"mcm","clk":"4289811723","pt":1632494141998,"mc":[{"id":"1.188075669","rc":[{"batb":[[0,1.59,248],[1,1.58,221.87],[2,1.57,263.98]],"ltp":1.58,"tv":13888.02,"id":9631939}]}]}
{"op":"mcm","clk":"4289811863","pt":1632494143796,"mc":[{"id":"1.188075669","rc":[{"batb":[[2,2.56,106.99]],"ltp":2.5,"tv":918.72,"id":9454286}]}]}
{"op":"mcm","clk":"4289811965","pt":1632494145208,"mc":[{"id":"1.188075669","rc":[{"batb":[[0,1.59,380]],"ltp":1.58,"tv":13888.02,"id":9631939}]}]}
{"op":"mcm","clk":"4289811990","pt":1632494145577,"mc":[{"id":"1.188075669","rc":[{"batb":[[1,2.56,106.99],[2,2.54,3]],"ltp":2.5,"tv":918.72,"id":9454286}]}]}
{"op":"mcm","clk":"4289812081","pt":1632494147178,"mc":[{"id":"1.188075669","rc":[{"batb":[[1,1.58,201.81],[2,1.55,23.19]],"batl":[[0,1.64,60],[1,1.67,18.5],[2,1.7,15.25]],"ltp":1.58,"tv":13888.02,"id":9631939},{"batb":[[0,2.56,102.99],[1,2.48,2.51],[2,2.42,2.94]],"batl":[[0,2.82,2.47],[1,2.88,43.75],[2,2.9,2.05]],"ltp":2.5,"tv":918.72,"id":9454286}]}]}
{"op":"mcm","clk":"4289812147","pt":1632494148173,"mc":[{"id":"1.188075669","rc":[{"batb":[[1,1.55,23.19],[2,1.53,22.33]],"batl":[[0,1.67,18.5],[1,1.7,15.25],[2,1.76,4.63]],"ltp":1.58,"tv":13888.02,"id":9631939},{"batb":[[0,2.48,2.51],[1,2.42,2.94],[2,2.32,121.64]],"batl":[[1,2.9,2.05],[2,3.45,186.67]],"ltp":2.5,"tv":918.72,"id":9454286}]}]}
{"op":"mcm","clk":"4289812181","pt":1632494148687,"mc":[{"id":"1.188075669","rc":[{"batb":[[0,1.53,22.33],[1,1.52,244.46],[2,1.47,7]],"batl":[[0,1.7,15.25],[1,1.76,4.63],[2,1.86,15.25]],"ltp":1.58,"tv":13888.02,"id":9631939},{"batb":[[0,2.42,2.94],[1,2.32,121.64],[2,2.16,3.53]],"batl":[[0,2.9,2.05],[1,3.45,186.67],[2,3.45,0]],"ltp":2.5,"tv":918.72,"id":9454286}]}]}
{"op":"mcm","clk":"4289812287","pt":1632494150107,"mc":[{"id":"1.188075669","rc":[{"batb":[[1,1.52,532.35],[2,1.51,179.05]],"batl":[[1,1.73,172.11],[2,1.75,210.12]],"ltp":1.58,"tv":13888.02,"id":9631939}]}]}
{"op":"mcm","clk":"4289812353","pt":1632494150894,"mc":[{"id":"1.188075669","rc":[{"batl":[[0,1.58,91.46],[1,1.7,15.25],[2,1.76,4.63]],"ltp":1.58,"tv":13888.02,"id":9631939}]}]}
{"op":"mcm","clk":"4289812452","pt":1632494152203,"mc":[{"id":"1.188075669","rc":[{"batl":[[1,1.67,19.5],[2,1.7,20.25]],"ltp":1.58,"tv":13888.02,"id":9631939},{"batb":[[0,2.48,2.51],[1,2.42,6.94],[2,2.4,3]],"ltp":2.5,"tv":918.72,"id":9454286}]}]}
{"op":"mcm","clk":"4289812519","pt":1632494153195,"mc":[{"id":"1.188075669","rc":[{"trd":[[1.53,839.09]],"batb":[[0,1.53,2.06]],"batl":[[0,1.58,6843.1],[1,1.62,912.98],[2,1.67,19.5]],"ltp":1.53,"tv":13928.56,"id":9631939},{"batb":[[0,2.74,857.66],[1,2.72,428.82],[2,2.7,428.82]],"batl":[[0,2.84,9.21],[1,2.9,2.05],[2,2.96,206.42]],"ltp":2.5,"tv":918.72,"id":9454286}],"tv":14847.28}]}
{"op":"mcm","clk":"4289812583","pt":1632494154198,"mc":[{"id":"1.188075669","rc":[{"batb":[[0,1.52,532.35],[1,1.51,179.05],[2,1.49,268.76]],"batl":[[0,1.57,236.63],[1,1.58,714.46],[2,1.62,912.98]],"ltp":1.53,"tv":13928.56,"id":9631939},{"batb":[[0,2.74,252.76],[1,2.72,85.76],[2,2.7,85.76]],"batl":[[2,2.96,1000.34]],"ltp":2.5,"tv":918.72,"id":9454286}]}]}
{"op":"mcm","clk":"4289812636","pt":1632494155191,"mc":[{"id":"1.188075669","rc":[{"batl":[[0,1.57,271.53]],"ltp":1.53,"tv":13928.56,"id":9631939},{"batl":[[2,2.96,365.2]],"ltp":2.5,"tv":918.72,"id":9454286}]}]}
{"op":"mcm","clk":"4289812675","pt":1632494155743,"mc":[{"id":"1.188075669","rc":[{"batl":[[2,1.59,60]],"ltp":1.53,"tv":13928.56,"id":9631939},{"batb":[[2,2.7,94.58]],"ltp":2.5,"tv":918.72,"id":9454286}]}]}
{"op":"mcm","clk":"4289812726","pt":1632494156602,"mc":[{"id":"1.188075669","rc":[{"batl":[[2,1.59,78.53]],"ltp":1.53,"tv":13928.56,"id":9631939}]}]}
{"op":"mcm","clk":"4289812765","pt":1632494157328,"mc":[{"id":"1.188075669","rc":[{"batl":[[2,1.59,18.53]],"ltp":1.53,"tv":13928.56,"id":9631939}]}]}
{"op":"mcm","clk":"4289812859","pt":1632494159008,"mc":[{"id":"1.188075669","rc":[{"trd":[[1.54,69.98]],"batb":[[0,1.54,120],[1,1.52,532.35],[2,1.51,179.05]],"ltp":1.54,"tv":13941.45,"id":9631939},{"trd":[[2.84,14.64]],"batb":[[0,2.76,18.67],[1,2.74,252.76],[2,2.72,85.76]],"batl":[[0,2.84,2.22]],"ltp":2.84,"tv":925.71,"id":9454286}],"tv":14867.16}]}
{"op":"mcm","clk":"4289812974","pt":1632494160695,"mc":[{"id":"1.188075669","rc":[{"batb":[[1,1.52,554.59]],"batl":[[1,1.58,774.46]],"ltp":1.54,"tv":13941.45,"id":9631939},{"batl":[[2,2.94,2.25]],"ltp":2.84,"tv":925.71,"id":9454286}]}]}
{"op":"mcm","clk":"4289813041","pt":1632494161707,"mc":[{"id":"1.188075669","rc":[{"batb":[[1,2.74,261.38]],"ltp":2.84,"tv":925.71,"id":9454286}]}]}
{"op":"mcm","clk":"4289813124","pt":1632494163016,"mc":[{"id":"1.188075669","rc":[{"batb":[[0,1.54,186]],"ltp":1.54,"tv":13941.45,"id":9631939}]}]}
{"op":"mcm","clk":"4289813341","pt":1632494166223,"mc":[{"id":"1.188075669","rc":[{"batb":[[0,1.54,287]],"ltp":1.54,"tv":13941.45,"id":9631939}]}]}
{"op":"mcm","clk":"4289813405","pt":1632494167112,"mc":[{"id":"1.188075669","rc":[{"batb":[[1,1.52,22.24],[2,1.49,268.76]],"batl":[[0,1.58,60],[1,1.59,18.53],[2,1.61,22.91]],"ltp":1.54,"tv":13941.45,"id":9631939},{"batb":[[0,2.74,8.62],[1,2.62,2.62],[2,2.58,2.37]],"batl":[[0,2.94,2.25],[1,3.1,41.4],[2,3.45,3]],"ltp":2.84,"tv":925.71,"id":9454286}]}]}
{"op":"mcm","clk":"4289813459","pt":1632494168203,"mc":[{"id":"1.188075669","rc":[{"batb":[[0,1.52,22.24],[1,1.49,268.76],[2,1.47,7]],"batl":[[0,1.59,18.53],[1,1.61,22.91],[2,1.63,23.77]],"ltp":1.54,"tv":13941.45,"id":9631939},{"batb":[[0,2.62,2.62],[1,2.58,2.37],[2,2.54,95.41]],"batl":[[1,3.45,3],[2,3.9,161.11]],"ltp":2.84,"tv":925.71,"id":9454286}]}]}
{"op":"mcm","clk":"4289813510","pt":1632494168938,"mc":[{"id":"1.188075669","rc":[{"batl":[[0,1.63,23.77],[1,1.67,19.5],[2,1.7,20.25]],"ltp":1.54,"tv":13941.45,"id":9631939},{"batb":[[0,2.58,2.37],[1,2.54,95.41],[2,2.48,2.51]],"ltp":2.84,"tv":925.71,"id":9454286}]}]}
{"op":"mcm","clk":"4289813597","pt":1632494170138,"mc":[{"id":"1.188075669","rc":[{"batb":[[0,1.53,23.33],[1,1.52,22.24],[2,1.5,6]],"batl":[[0,1.54,91.46],[1,1.63,23.77],[2,1.64,241.66]],"ltp":1.54,"tv":13941.45,"id":9631939}]}]}
{"op":"mcm","clk":"4289813634","pt":1632494170612,"mc":[{"id":"1.188075669","rc":[{"batb":[[0,1.52,22.24],[1,1.5,6],[2,1.49,550.57]],"batl":[[2,1.67,19.5]],"ltp":1.54,"tv":13941.45,"id":9631939}]}]}
{"op":"mcm","clk":"4289813731","pt":1632494172118,"mc":[{"id":"1.188075669","rc":[{"batb":[[1,1.49,544.57],[2,1.48,194.02]],"batl":[[1,1.61,23.5],[2,1.63,28.77]],"ltp":1.54,"tv":13941.45,"id":9631939},{"batb":[[0,2.62,2.83],[1,2.58,5.37],[2,2.56,3]],"ltp":2.84,"tv":925.71,"id":9454286}]}]}
{"op":"mcm","clk":"4289813784","pt":1632494173213,"mc":[{"id":"1.188075669","rc":[{"trd":[[1.52,2777.79]],"batb":[[0,1.52,1.69]],"batl":[[1,1.55,25.5],[2,1.56,474.46]],"ltp":1.52,"tv":13982.55,"id":9631939},{"batb":[[0,2.88,4.95],[1,2.84,496.48],[2,2.82,349.1]],"batl":[[1,2.96,6.94],[2,3.05,201.83]],"ltp":2.84,"tv":925.71,"id":9454286}],"tv":14908.26}]}
{"op":"mcm","clk":"4289813852","pt":1632494174205,"mc":[{"id":"1.188075669","rc":[{"batb":[[0,1.49,544.57],[1,1.48,194.02],[2,1.47,7]],"batl":[[0,1.54,379.83],[1,1.55,218.68]],"ltp":1.52,"tv":13982.55,"id":9631939},{"batb":[[1,2.86,70.02],[2,2.84,165.5]],"batl":[[2,3.05,355.93]],"ltp":2.84,"tv":925.71,"id":9454286}]}]}
{"op":"mcm","clk":"4289813893","pt":1632494174830,"mc":[{"id":"1.188075669","rc":[{"batl":[[0,1.54,420.52]],"ltp":1.52,"tv":13982.55,"id":9631939}]}]}
{"op":"mcm","clk":"4289813989","pt":1632494176252,"mc":[{"id":"1.188075669","rc":[{"batl":[[1,1.55,158.68]],"ltp":1.52,"tv":13982.55,"id":9631939}]}]}
{"op":"mcm","clk":"4289814151","pt":1632494178141,"mc":[{"id":"1.188075669","rc":[{"batl":[[0,1.54,329.06]],"ltp":1.52,"tv":13982.55,"id":9631939}]}]}
{"op":"mcm","clk":"4289814217","pt":1632494179028,"mc":[{"id":"1.188075669","rc":[{"batb":[[0,1.51,123],[1,1.49,544.57],[2,1.48,194.02]],"ltp":1.52,"tv":13982.55,"id":9631939}]}]}
{"op":"mcm","clk":"4289814290","pt":1632494180126,"mc":[{"id":"1.188075669","rc":[{"batb":[[2,1.48,471.56]],"batl":[[0,1.54,389.06],[2,1.56,733.53]],"ltp":1.52,"tv":13982.55,"id":9631939}]}]}
{"op":"mcm","clk":"4289814316","pt":1632494180449,"mc":[{"id":"1.188075669","rc":[{"batb":[[0,1.51,146.48],[1,1.5,27],[2,1.49,544.57]],"ltp":1.52,"tv":13982.55,"id":9631939},{"batl":[[2,2.98,2.25]],"ltp":2.84,"tv":925.71,"id":9454286}]}]}
{"op":"mcm","clk":"4289814445","pt":1632494182066,"mc":[{"id":"1.188075669","rc":[{"trd":[[1.51,2433.64]],"batb":[[0,1.51,260.95]],"ltp":1.51,"tv":14019.61,"id":9631939},{"batb":[[1,2.86,78.08]],"ltp":2.84,"tv":925.71,"id":9454286}],"tv":14945.32}]}
{"op":"mcm","clk":"4289814540","pt":1632494183029,"mc":[{"id":"1.188075669","rc":[{"batl":[[0,1.52,2.63],[1,1.54,389.06],[2,1.55,158.68]],"ltp":1.51,"tv":14019.61,"id":9631939}]}]}
{"op":"mcm","clk":"4289814705","pt":1632494184964,"mc":[{"id":"1.188075669","rc":[{"batb":[[2,1.48,277.54]],"batl":[[1,1.54,60],[2,1.56,259.07]],"ltp":1.51,"tv":14019.61,"id":9631939},{"batb":[[0,2.86,8.06],[1,2.78,142.39],[2,2.76,187.9]],"batl":[[0,2.98,2.25],[1,3,2.16],[2,3.1,146.31]],"ltp":2.84,"tv":925.71,"id":9454286}]}]}
{"op":"mcm","clk":"4289814801","pt":1632494186068,"mc":[{"id":"1.188075669","rc":[{"batb":[[0,1.51,23.48]],"ltp":1.51,"tv":14019.61,"id":9631939}]}]}
{"op":"mcm","clk":"4289814840","pt":1632494186436,"mc":[{"id":"1.188075669","rc":[{"batb":[[0,1.5,27],[1,1.48,277.54],[2,1.47,358.42]],"batl":[[1,1.56,259.07],[2,1.57,298.84]],"ltp":1.51,"tv":14019.61,"id":9631939},{"batb":[[0,2.78,142.39],[1,2.76,187.9],[2,2.74,2.02]],"batl":[[0,3,2.16],[1,3.1,146.31],[2,3.15,133.99]],"ltp":2.84,"tv":925.71,"id":9454286}]}]}
{"op":"mcm","clk":"4289814986","pt":1632494188169,"mc":[{"id":"1.188075669","rc":[{"batb":[[0,1.5,30],[1,1.49,2],[2,1.48,277.54]],"batl":[[2,1.57,470.26]],"ltp":1.51,"tv":14019.61,"id":9631939}]}]}
{"op":"mcm","clk":"4289815030","pt":1632494188646,"mc":[{"id":"1.188075669","rc":[{"batl":[[0,1.51,140.71],[1,1.52,2.63],[2,1.56,259.07]],"ltp":1.51,"tv":14019.61,"id":9631939}]}]}
{"op":"mcm","clk":"4289815124","pt":1632494189951,"mc":[{"id":"1.188075669","rc":[{"trd":[[1.51,2474.6]],"batb":[[0,1.5,27],[1,1.48,277.54],[2,1.47,697.22]],"batl":[[0,1.51,120.23]],"ltp":1.51,"tv":14060.57,"id":9631939}],"tv":14986.28}]}
{"op":"mcm","clk":"4289815547","pt":1632494195780,"mc":[{"id":"1.188075669","rc":[{"batb":[[0,1.5,184]],"ltp":1.51,"tv":14060.57,"id":9631939}]}]}
{"op":"mcm","clk":"4289815678","pt":1632494197971,"mc":[{"id":"1.188075669","rc":[{"batl":[[0,2.98,2.25],[1,3,2.16],[2,3.1,146.31]],"ltp":2.84,"tv":925.71,"id":9454286}]}]}
{"op":"mcm","clk":"4289815725","pt":1632494198495,"mc":[{"id":"1.188075669","rc":[{"batl":[[0,3,2.16],[1,3.1,146.31],[2,3.15,133.99]],"ltp":2.84,"tv":925.71,"id":9454286}]}]}
{"op":"mcm","clk":"4289815950","pt":1632494202003,"mc":[{"id":"1.188075669","rc":[{"batb":[[0,1.5,27]],"batl":[[1,1.56,259.07],[2,1.57,470.26]],"ltp":1.51,"tv":14060.57,"id":9631939}]}]}
{"op":"mcm","clk":"4289816196","pt":1632494205757,"mc":[{"id":"1.188075669","rc":[{"batb":[[1,1.47,7],[2,1.46,286.98]],"ltp":1.51,"tv":14060.57,"id":9631939},{"batl":[[1,3.45,3],[2,3.9,161.11]],"ltp":2.84,"tv":925.71,"id":9454286}]}]}
{"op":"mcm","clk":"4289816457","pt":1632494209169,"mc":[{"id":"1.188075669","rc":[{"trd":[[1.51,2715.05]],"batb":[[0,1.53,438.19],[1,1.52,173.68],[2,1.5,27]],"batl":[[0,1.56,259.07],[1,1.57,470.26],[2,1.58,167.26]],"ltp":1.51,"tv":14301.02,"id":9631939},{"batl":[[0,2.84,8.64],[1,2.92,214.88],[2,2.98,320.9]],"ltp":2.84,"tv":925.71,"id":9454286}],"tv":15226.74}]}
{"op":"mcm","clk":"4289816524","pt":1632494210165,"mc":[{"id":"1.188075669","rc":[{"trd":[[1.53,847.77],[1.54,85.91]],"batb":[[0,1.53,675.36]],"ltp":1.53,"tv":14325.63,"id":9631939},{"trd":[[2.84,23.28]],"batl":[[0,2.92,214.88],[1,2.98,320.9],[2,3,313.62]],"ltp":2.84,"tv":934.35,"id":9454286}],"tv":15259.99}]}
{"op":"mcm","clk":"4289816552","pt":1632494210585,"mc":[{"id":"1.188075669","rc":[{"batb":[[2,1.51,44.58]],"ltp":1.53,"tv":14325.63,"id":9631939},{"batl":[[1,2.98,331.7]],"ltp":2.84,"tv":934.35,"id":9454286}]}]}
{"op":"mcm","clk":"4289816665","pt":1632494212007,"mc":[{"id":"1.188075669","rc":[{"batb":[[2,1.51,46.15]],"ltp":1.53,"tv":14325.63,"id":9631939}]}]}
{"op":"mcm","clk":"4289816843","pt":1632494213694,"mc":[{"id":"1.188075669","rc":[{"trd":[[1.53,866.51]],"batb":[[0,1.53,665.99]],"ltp":1.53,"tv":14344.37,"id":9631939}],"tv":15278.73}]}
{"op":"mcm","clk":"4289816923","pt":1632494215010,"mc":[{"id":"1.188075669","rc":[{"batb":[[0,1.54,286],[1,1.53,665.99],[2,1.52,173.68]],"ltp":1.53,"tv":14344.37,"id":9631939}]}]}
{"op":"mcm","clk":"4289817090","pt":1632494216584,"mc":[{"id":"1.188075669","rc":[{"batb":[[2,1.52,199.42]],"ltp":1.53,"tv":14344.37,"id":9631939},{"batl":[[1,2.94,2.08],[2,2.98,333.95]],"ltp":2.84,"tv":934.35,"id":9454286}]}]}
{"op":"mcm","clk":"4289817219","pt":1632494218516,"mc":[{"id":"1.188075669","rc":[{"batb":[[0,1.54,433]],"ltp":1.53,"tv":14344.37,"id":9631939}]}]}
{"op":"mcm","clk":"4289817300","pt":1632494219782,"mc":[{"id":"1.188075669","rc":[{"batb":[[1,1.53,689.32]],"batl":[[2,1.58,148.5]],"ltp":1.53,"tv":14344.37,"id":9631939},{"batl":[[0,2.9,2.15],[1,2.92,214.88],[2,2.94,2.08]],"ltp":2.84,"tv":934.35,"id":9454286}]}]}
{"op":"mcm","clk":"4289817354","pt":1632494220580,"mc":[{"id":"1.188075669","rc":[{"batb":[[1,1.53,430.73]],"ltp":1.53,"tv":14344.37,"id":9631939}]}]}
{"op":"mcm","clk":"4289817519","pt":1632494222503,"mc":[{"id":"1.188075669","rc":[{"batl":[[0,1.56,275.14]],"ltp":1.53,"tv":14344.37,"id":9631939},{"batl":[[0,2.88,6.29],[1,2.9,2.15],[2,2.92,214.88]],"ltp":2.84,"tv":934.35,"id":9454286}]}]}
{"op":"mcm","clk":"4289817843","pt":1632494227216,"mc":[{"id":"1.188075669","rc":[{"batl":[[0,1.56,259.07]],"ltp":1.53,"tv":14344.37,"id":9631939},{"batl":[[0,2.9,2.15],[1,2.94,2.08],[2,2.98,13.05]],"ltp":2.84,"tv":934.35,"id":9454286}]}]}
{"op":"mcm","clk":"4289817909","pt":1632494228125,"mc":[{"id":"1.188075669","rc":[{"batb":[[0,1.53,23.33],[1,1.52,25.74],[2,1.5,27]],"batl":[[0,1.59,60],[1,1.61,23.5],[2,1.63,28.77]],"ltp":1.53,"tv":14344.37,"id":9631939},{"batb":[[0,2.7,8.82],[1,2.62,2.83],[2,2.6,4]],"batl":[[2,3,2.16]],"ltp":2.84,"tv":934.35,"id":9454286}]}]}
{"op":"mcm","clk":"4289817930","pt":1632494228449,"mc":[{"id":"1.188075669","rc":[{"batb":[[0,1.52,25.74],[1,1.49,264.03],[2,1.47,7]],"batl":[[0,1.61,23.5],[1,1.63,5],[2,1.67,19.5]],"ltp":1.53,"tv":14344.37,"id":9631939},{"batb":[[0,2.62,2.83],[1,2.6,4],[2,2.54,96.59]],"batl":[[0,2.94,2.08],[1,3.45,3],[2,3.9,161.11]],"ltp":2.84,"tv":934.35,"id":9454286}]}]}
{"op":"mcm","clk":"4289818143","pt":1632494230945,"mc":[{"id":"1.188075669","rc":[{"batb":[[1,1.5,163.74],[2,1.49,452.06]],"batl":[[2,1.64,241.85]],"ltp":1.53,"tv":14344.37,"id":9631939}]}]}
{"op":"mcm","clk":"4289818234","pt":1632494232049,"mc":[{"id":"1.188075669","rc":[{"batb":[[1,1.49,264.03],[2,1.47,7]],"batl":[[0,1.6,5],[1,1.61,29.5],[2,1.63,5]],"ltp":1.53,"tv":14344.37,"id":9631939},{"batb":[[0,2.68,4],[1,2.66,3],[2,2.62,5.83]],"ltp":2.84,"tv":934.35,"id":9454286}]}]}
{"op":"mcm","clk":"4289818460","pt":1632494234762,"mc":[{"id":"1.188075669","rc":[{"batb":[[0,1.54,190.48],[1,1.53,169.46],[2,1.52,25.74]],"batl":[[0,1.58,134.88],[1,1.59,185.83],[2,1.6,5]],"ltp":1.53,"tv":14344.37,"id":9631939},{"batb":[[0,2.68,6.61]],"ltp":2.84,"tv":934.35,"id":9454286}]}]}
{"op":"mcm","clk":"4289818521","pt":1632494235356,"mc":[{"id":"1.188075669","rc":[{"batb":[[1,1.53,194.79]],"ltp":1.53,"tv":14344.37,"id":9631939},{"batl":[[0,2.9,2.15],[1,2.94,2.08],[2,3.45,3]],"ltp":2.84,"tv":934.35,"id":9454286}]}]}
{"op":"mcm","clk":"4289818627","pt":1632494236632,"mc":[{"id":"1.188075669","rc":[{"batb":[[1,1.53,227.06]],"batl":[[1,1.59,210.83]],"ltp":1.53,"tv":14344.37,"id":9631939},{"batb":[[0,2.7,20],[1,2.68,6.61],[2,2.66,3]],"ltp":2.84,"tv":934.35,"id":9454286}]}]}
{"op":"mcm","clk":"4289818910","pt":1632494241067,"mc":[{"id":"1.188075669","rc":[{"batb":[[0,1.52,25.74],[1,1.49,264.03],[2,1.47,7]],"batl":[[0,1.6,5],[1,1.61,29.5],[2,1.63,5]],"ltp":1.53,"tv":14344.37,"id":9631939},{"batb":[[0,2.68,4],[1,2.66,3],[2,2.62,5.83]],"batl":[[0,2.94,2.08],[1,3.45,3],[2,3.9,161.11]],"ltp":2.84,"tv":934.35,"id":9454286}]}]}
{"op":"mcm","clk":"4289819043","pt":1632494243134,"mc":[{"id":"1.188075669","rc":[{"batb":[[0,1.55,189],[1,1.52,25.74],[2,1.49,264.03]],"ltp":1.53,"tv":14344.37,"id":9631939}]}]}
{"op":"mcm","clk":"4289819106","pt":1632494243971,"mc":[{"id":"1.188075669","rc":[{"batb":[[0,1.52,25.74],[1,1.5,163.74],[2,1.49,452.06]],"batl":[[1,1.61,23.5],[2,1.76,4.63]],"ltp":1.53,"tv":14344.37,"id":9631939},{"batb":[[1,2.62,2.83],[2,2.54,96.59]],"ltp":2.84,"tv":934.35,"id":9454286}]}]}
{"op":"mcm","clk":"4289819309","pt":1632494247165,"mc":[{"id":"1.188075669","rc":[{"trd":[[1.52,2818.89]],"batb":[[0,1.52,5.19],[1,1.5,366.69]],"batl":[[0,1.54,447.49],[1,1.55,159.12],[2,1.56,264.18]],"ltp":1.52,"tv":14385.47,"id":9631939},{"batb":[[0,2.88,6.54],[1,2.84,8.47],[2,2.8,341.52]],"batl":[[1,2.96,5.47],[2,3,101.48]],"ltp":2.84,"tv":934.35,"id":9454286}],"tv":15319.83}]}
{"op":"mcm","clk":"4289819376","pt":1632494248161,"mc":[{"id":"1.188075669","rc":[{"batb":[[1,2.84,80.17]],"ltp":2.84,"tv":934.35,"id":9454286}]}]}
{"op":"mcm","clk":"4289819782","pt":1632494252884,"mc":[{"id":"1.188075669","rc":[{"batb":[[1,2.84,80]],"ltp":2.84,"tv":934.35,"id":9454286}]}]}
{"op":"mcm","clk":"4289819966","pt":1632494255068,"mc":[{"id":"1.188075669","rc":[{"trd":[[1.54,89.05]],"batb":[[0,1.52,212.19]],"batl":[[0,1.54,445.92]],"ltp":1.54,"tv":14388.61,"id":9631939}],"tv":15322.97}]}
{"op":"mcm","clk":"4289820116","pt":1632494257100,"mc":[{"id":"1.188075669","rc":[{"trd":[[1.52,2876.81]],"batb":[[0,1.52,183.23]],"ltp":1.52,"tv":14446.53,"id":9631939}],"tv":15380.89}]}
{"op":"mcm","clk":"4289820246","pt":1632494258566,"mc":[{"id":"1.188075669","rc":[{"trd":[[1.52,2896.81]],"batb":[[0,1.52,374.23]],"batl":[[0,1.54,263.06]],"ltp":1.52,"tv":14466.53,"id":9631939}],"tv":15400.89}]}
{"op":"mcm","clk":"4289820807","pt":1632494267098,"mc":[{"id":"1.188075669","rc":[{"trd":[[1.52,2916.81]],"batb":[[0,1.52,364.23]],"ltp":1.52,"tv":14486.53,"id":9631939}],"tv":15420.89}]}
{"op":"mcm","clk":"4289820822","pt":1632494267307,"mc":[{"id":"1.188075669","rc":[{"batl":[[0,1.53,11.5],[1,1.54,263.06],[2,1.55,159.12]],"ltp":1.52,"tv":14486.53,"id":9631939}]}]}
{"op":"mcm","clk":"4289824359","pt":1632494313489,"mc":[{"id":"1.188075669","rc":[{"trd":[[1.53,871.2]],"batl":[[0,1.53,9.16]],"ltp":1.53,"tv":14491.22,"id":9631939}],"tv":15425.58}]}
{"op":"mcm","clk":"4289824517","pt":1632494315861,"mc":[{"id":"1.188075669","rc":[{"trd":[[1.52,2921.5]],"batb":[[0,1.52,361.88]],"ltp":1.52,"tv":14495.92,"id":9631939}],"tv":15430.27}]}
{"op":"mcm","clk":"4289826252","pt":1632494340184,"mc":[{"id":"1.188075669","rc":[{"batb":[[1,1.5,163.74]],"batl":[[1,1.54,216.31]],"ltp":1.52,"tv":14495.92,"id":9631939},{"batb":[[0,2.84,71.53],[1,2.76,8.52],[2,2.72,3.34]],"batl":[[0,3.15,40.91],[1,3.35,121.54],[2,3.4,148.26]],"ltp":2.84,"tv":934.35,"id":9454286}]}]}
{"op":"mcm","clk":"4289826329","pt":1632494341086,"mc":[{"id":"1.188075669","rc":[{"batb":[[0,1.47,87.51],[1,1.43,301.3],[2,1.42,400.76]],"batl":[[1,1.57,60],[2,1.58,50.25]],"ltp":1.52,"tv":14495.92,"id":9631939},{"batb":[[0,2.76,8.52],[1,2.72,3.34],[2,2.68,4]],"ltp":2.84,"tv":934.35,"id":9454286}]}]}
{"op":"mcm","clk":"4289826345","pt":1632494341293,"mc":[{"id":"1.188075669","rc":[{"batb":[[0,1.43,301.3],[1,1.42,400.76],[2,1.4,379.78]],"batl":[[1,1.58,50.25],[2,1.6,60.76]],"ltp":1.52,"tv":14495.92,"id":9631939},{"batb":[[0,2.72,3.34],[1,2.68,4],[2,2.66,148.8]],"batl":[[0,3.35,121.54],[1,3.4,148.26],[2,3.45,3]],"ltp":2.84,"tv":934.35,"id":9454286}]}]}
{"op":"mcm","clk":"4289826544","pt":1632494343804,"mc":[{"id":"1.188075669","rc":[{"batb":[[2,1.4,753.35]],"ltp":1.52,"tv":14495.92,"id":9631939}]}]}
{"op":"mcm","clk":"4289826623","pt":1632494344705,"mc":[{"id":"1.188075669","rc":[{"batb":[[0,1.43,6],[1,1.42,6],[2,1.4,379.78]],"batl":[[1,1.6,60.76],[2,1.61,462.85]],"ltp":1.52,"tv":14495.92,"id":9631939},{"batb":[[0,2.68,4],[1,2.66,148.8],[2,2.64,254.84]],"batl":[[0,3.35,3],[1,3.45,3],[2,3.5,2]],"ltp":2.84,"tv":934.35,"id":9454286}]}]}
{"op":"mcm","clk":"4289826799","pt":1632494347123,"mc":[{"id":"1.188075669","rc":[{"trd":[[1.53,880.36]],"batl":[[0,1.6,60.76],[1,1.61,462.85],[2,1.62,460.82]],"ltp":1.53,"tv":14505.08,"id":9631939},{"trd":[[2.88,6.08]],"batl":[[0,2.84,673.41],[1,2.86,648.74],[2,2.88,653.61]],"ltp":2.88,"tv":939.22,"id":9454286}],"tv":15444.3}]}
{"op":"mcm","clk":"4289826882","pt":1632494348121,"mc":[{"id":"1.188075669","rc":[{"batb":[[0,1.56,192.01],[1,1.55,161.21],[2,1.43,6]],"batl":[[0,1.6,80.81],[2,1.62,741.69]],"ltp":1.53,"tv":14505.08,"id":9631939},{"batb":[[0,2.66,148.8],[1,2.64,254.84],[2,2.04,401.24]],"batl":[[0,2.78,5.37],[1,2.84,588.92],[2,2.86,326.8]],"ltp":2.88,"tv":939.22,"id":9454286}]}]}
{"op":"mcm","clk":"4289826950","pt":1632494348824,"mc":[{"id":"1.188075669","rc":[{"trd":[[1.56,188.5]],"batb":[[0,1.56,398.55],[2,1.47,283.35]],"ltp":1.56,"tv":14544.82,"id":9631939},{"batb":[[2,2.5,100.72]],"ltp":2.88,"tv":939.22,"id":9454286}],"tv":15484.04}]}
{"op":"mcm","clk":"4289827057","pt":1632494350508,"mc":[{"id":"1.188075669","rc":[{"batb":[[2,2.6,4]],"ltp":2.88,"tv":939.22,"id":9454286}]}]}
{"op":"mcm","clk":"4289827281","pt":1632494353032,"mc":[{"id":"1.188075669","rc":[{"batb":[[0,1.57,195],[1,1.56,398.55],[2,1.55,161.21]],"ltp":1.56,"tv":14544.82,"id":9631939}]}]}
{"op":"mcm","clk":"4289827547","pt":1632494356032,"mc":[{"id":"1.188075669","rc":[{"batb":[[0,1.57,404]],"batl":[[2,1.62,790.94]],"ltp":1.56,"tv":14544.82,"id":9631939},{"batb":[[2,2.6,7.99]],"ltp":2.88,"tv":939.22,"id":9454286}]}]}
{"op":"mcm","clk":"4289827646","pt":1632494357131,"mc":[{"id":"1.188075669","rc":[{"batl":[[1,2.84,633.15]],"ltp":2.88,"tv":939.22,"id":9454286}]}]}
{"op":"mcm","clk":"4289827976","pt":1632494361219,"mc":[{"id":"1.188075669","rc":[{"batl":[[0,1.6,55.76],[2,1.62,510.07]],"ltp":1.56,"tv":14544.82,"id":9631939},{"batl":[[0,2.84,212.58],[1,2.86,163.4],[2,2.88,163.4]],"ltp":2.88,"tv":939.22,"id":9454286}]}]}
{"op":"mcm","clk":"4289828065","pt":1632494362161,"mc":[{"id":"1.188075669","rc":[{"batb":[[0,1.54,81.64],[1,1.51,27.99],[2,1.48,24.51]],"batl":[[0,1.65,50.3],[1,1.76,4.63],[2,1.62,0]],"ltp":1.56,"tv":14544.82,"id":9631939},{"batb":[[0,2.6,4],[1,2.58,3],[2,2.52,3.74]],"batl":[[0,2.84,44.23],[1,2.98,2.25],[2,3.1,2.05]],"ltp":2.88,"tv":939.22,"id":9454286}]}]}
{"op":"mcm","clk":"4289828129","pt":1632494362842,"mc":[{"id":"1.188075669","rc":[{"batl":[[0,1.65,50.61]],"ltp":1.56,"tv":14544.82,"id":9631939},{"batb":[[1,2.52,3.74],[2,2.5,100.72]],"ltp":2.88,"tv":939.22,"id":9454286}]}]}
{"op":"mcm","clk":"4289828193","pt":1632494363525,"mc":[{"id":"1.188075669","rc":[{"batb":[[0,1.48,24.51],[1,1.47,283.35],[2,1.43,6]],"ltp":1.56,"tv":14544.82,"id":9631939},{"batl":[[0,3.1,2.05],[1,3.35,3],[2,3.5,2]],"ltp":2.88,"tv":939.22,"id":9454286}]}]}
{"op":"mcm","clk":"4289828300","pt":1632494365039,"mc":[{"id":"1.188075669","rc":[{"batb":[[1,1.47,591.37],[2,1.46,205.6]],"batl":[[0,1.61,6.31],[1,1.63,5],[2,1.65,50.3]],"ltp":1.56,"tv":14544.82,"id":9631939},{"batb":[[0,2.64,3],[1,2.62,4],[2,2.6,4]],"ltp":2.88,"tv":939.22,"id":9454286}]}]}
{"op":"mcm","clk":"4289828460","pt":1632494367032,"mc":[{"id":"1.188075669","rc":[{"batb":[[0,1.48,30.51],[1,1.47,598.37]],"ltp":1.56,"tv":14544.82,"id":9631939},{"batl":[[0,3.1,5.05]],"ltp":2.88,"tv":939.22,"id":9454286}]}]}
{"op":"mcm","clk":"4289828524","pt":1632494367875,"mc":[{"id":"1.188075669","rc":[{"batb":[[1,1.47,290.35],[2,1.43,6]],"ltp":1.56,"tv":14544.82,"id":9631939}]}]}
{"op":"mcm","clk":"4289828631","pt":1632494368981,"mc":[{"id":"1.188075669","rc":[{"batl":[[1,1.63,61.5]],"ltp":1.56,"tv":14544.82,"id":9631939}]}]}
{"op":"mcm","clk":"4289828671","pt":1632494369350,"mc":[{"id":"1.188075669","rc":[{"batl":[[1,1.63,5]],"ltp":1.56,"tv":14544.82,"id":9631939}]}]}
{"op":"mcm","clk":"4289828814","pt":1632494371081,"mc":[{"id":"1.188075669","rc":[{"trd":[[1.6,45.72],[1.61,25.68]],"batb":[[0,1.61,232.52],[1,1.6,143.45],[2,1.48,30.51]],"batl":[[0,1.64,19.58],[1,1.65,50.3],[2,1.66,131.4]],"ltp":1.61,"tv":14562.05,"id":9631939},{"trd":[[2.64,3],[2.66,20.34]],"batb":[[0,2.52,3.74],[1,2.5,283.83],[2,2.46,388.72]],"batl":[[0,2.66,6.79],[1,2.68,356.8],[2,2.7,346.32]],"ltp":2.64,"tv":942.41,"id":9454286}],"tv":15504.46}]}
{"op":"mcm","clk":"4289828903","pt":1632494372147,"mc":[{"id":"1.188075669","rc":[{"trd":[[1.61,64.38]],"batb":[[0,1.61,412.33],[1,1.6,220.9],[2,1.53,238.3]],"ltp":1.61,"tv":14600.75,"id":9631939}],"tv":15543.16}]}
{"op":"mcm","clk":"4289829079","pt":1632494374145,"mc":[{"id":"1.188075669","rc":[{"batb":[[2,2.46,391.72]],"ltp":2.64,"tv":942.41,"id":9454286}]}]}
{"op":"mcm","clk":"4289829134","pt":1632494374978,"mc":[{"id":"1.188075669","rc":[{"batl":[[2,1.66,149.14]],"ltp":1.61,"tv":14600.75,"id":9631939}]}]}
{"op":"mcm","clk":"4289829227","pt":1632494376099,"mc":[{"id":"1.188075669","rc":[{"batb":[[1,1.6,143.45]],"ltp":1.61,"tv":14600.75,"id":9631939},{"batl":[[0,2.64,46.85],[1,2.66,6.79],[2,2.68,356.8]],"ltp":2.64,"tv":942.41,"id":9454286}]}]}
{"op":"mcm","clk":"4289829325","pt":1632494377161,"mc":[{"id":"1.188075669","rc":[{"batl":[[1,2.66,32.04]],"ltp":2.64,"tv":942.41,"id":9454286}]}]}
{"op":"mcm","clk":"4289829393","pt":1632494378190,"mc":[{"id":"1.188075669","rc":[{"batb":[[0,1.61,468.33],[2,1.57,20.57]],"batl":[[2,1.66,200.89]],"ltp":1.61,"tv":14600.75,"id":9631939},{"batb":[[1,2.5,287.51]],"ltp":2.64,"tv":942.41,"id":9454286}]}]}
{"op":"mcm","clk":"4289829471","pt":1632494379188,"mc":[{"id":"1.188075669","rc":[{"batb":[[0,1.61,412.33]],"ltp":1.61,"tv":14600.75,"id":9631939}]}]}
{"op":"mcm","clk":"4289829481","pt":1632494379292,"mc":[{"id":"1.188075669","rc":[{"batb":[[0,1.62,76.2],[1,1.61,412.33],[2,1.6,143.45]],"ltp":1.61,"tv":14600.75,"id":9631939}]}]}
{"op":"mcm","clk":"4289829612","pt":1632494380767,"mc":[{"id":"1.188075669","rc":[{"batl":[[0,1.65,50.3],[1,1.66,200.89],[2,1.68,241.1]],"ltp":1.61,"tv":14600.75,"id":9631939},{"batl":[[1,2.66,25.25]],"ltp":2.64,"tv":942.41,"id":9454286}]}]}
{"op":"mcm","clk":"4289829821","pt":1632494383168,"mc":[{"id":"1.188075669","rc":[{"trd":[[1.62,90.84]],"batb":[[0,1.62,334]],"ltp":1.62,"tv":14601.14,"id":9631939}],"tv":15543.56}]}
{"op":"mcm","clk":"4289829847","pt":1632494383694,"mc":[{"id":"1.188075669","rc":[{"batl":[[0,1.64,19.88],[1,1.65,50.3],[2,1.66,200.89]],"ltp":1.62,"tv":14601.14,"id":9631939},{"batb":[[2,2.48,4.26]],"batl":[[1,2.66,32.04]],"ltp":2.64,"tv":942.41,"id":9454286}]}]}
{"op":"mcm","clk":"4289830143","pt":1632494387178,"mc":[{"id":"1.188075669","rc":[{"batb":[[1,1.57,20.57],[2,1.56,210.15]],"batl":[[0,1.67,49.5],[1,1.69,197.78],[2,1.7,215.76]],"ltp":1.62,"tv":14601.14,"id":9631939},{"batb":[[0,2.48,4.26],[1,2.46,3],[2,2.44,175.06]],"batl":[[1,2.76,2.52],[2,2.8,146.02]],"ltp":2.64,"tv":942.41,"id":9454286}]}]}
{"op":"mcm","clk":"4289830225","pt":1632494388178,"mc":[{"id":"1.188075669","rc":[{"batb":[[0,1.57,20.57],[1,1.56,210.15],[2,1.55,351.39]],"ltp":1.62,"tv":14601.14,"id":9631939},{"batl":[[0,2.76,2.52],[1,2.8,146.02],[2,2.82,146.65]],"ltp":2.64,"tv":942.41,"id":9454286}]}]}
{"op":"mcm","clk":"4289830298","pt":1632494388916,"mc":[{"id":"1.188075669","rc":[{"batb":[[0,1.56,210.15],[1,1.55,351.39],[2,1.53,238.3]],"batl":[[0,1.67,49.81]],"ltp":1.62,"tv":14601.14,"id":9631939},{"batl":[[0,2.8,146.02],[1,2.82,146.65],[2,3.1,5.05]],"ltp":2.64,"tv":942.41,"id":9454286}]}]}
{"op":"mcm","clk":"4289830386","pt":1632494390114,"mc":[{"id":"1.188075669","rc":[{"batb":[[1,1.55,486.18],[2,1.54,165.11]],"batl":[[0,1.66,4.31],[1,1.67,49.5],[2,1.69,197.78]],"ltp":1.62,"tv":14601.14,"id":9631939},{"batb":[[0,2.52,4],[1,2.5,3],[2,2.48,7.26]],"ltp":2.64,"tv":942.41,"id":9454286}]}]}
{"op":"mcm","clk":"4289830447","pt":1632494390804,"mc":[{"id":"1.188075669","rc":[{"batl":[[0,1.67,49.81],[1,1.69,197.78],[2,1.7,215.76]],"ltp":1.62,"tv":14601.14,"id":9631939},{"batb":[[0,2.48,4.26],[1,2.46,3],[2,2.44,175.06]],"ltp":2.64,"tv":942.41,"id":9454286}]}]}
{"op":"mcm","clk":"4289830668","pt":1632494393191,"mc":[{"id":"1.188075669","rc":[{"batb":[[0,1.57,6],[1,1.56,216.15],[2,1.55,486.18]],"ltp":1.62,"tv":14601.14,"id":9631939},{"batb":[[2,2.44,178.06]],"batl":[[0,2.78,3],[1,2.8,146.02],[2,2.82,146.65]],"ltp":2.64,"tv":942.41,"id":9454286}]}]}
{"op":"mcm","clk":"4289830733","pt":1632494393978,"mc":[{"id":"1.188075669","rc":[{"batl":[[0,1.66,54.56],[1,1.67,49.5],[2,1.69,197.78]],"ltp":1.62,"tv":14601.14,"id":9631939},{"batb":[[0,2.5,4.01],[1,2.48,4.26],[2,2.46,3]],"ltp":2.64,"tv":942.41,"id":9454286}]}]}
{"op":"mcm","clk":"4289830796","pt":1632494394921,"mc":[{"id":"1.188075669","rc":[{"batb":[[0,1.58,5],[1,1.57,6],[2,1.56,216.15]],"batl":[[0,1.67,49.81],[1,1.69,197.78],[2,1.7,215.76]],"ltp":1.62,"tv":14601.14,"id":9631939},{"batb":[[0,2.48,4.26],[1,2.46,3],[2,2.44,178.06]],"batl":[[0,2.74,3],[1,2.78,3],[2,2.8,146.02]],"ltp":2.64,"tv":942.41,"id":9454286}]}]}
{"op":"mcm","clk":"4289830986","pt":1632494397090,"mc":[{"id":"1.188075669","rc":[{"batl":[[1,2.76,4],[2,2.78,3]],"ltp":2.64,"tv":942.41,"id":9454286}]}]}
{"op":"mcm","clk":"4289831080","pt":1632494398094,"mc":[{"id":"1.188075669","rc":[{"batl":[[0,1.66,53.06],[1,1.67,49.5],[2,1.69,197.78]],"ltp":1.62,"tv":14601.14,"id":9631939},{"batb":[[0,2.5,4.22],[1,2.48,4.26],[2,2.46,3]],"batl":[[0,2.72,3],[1,2.74,3],[2,2.76,4]],"ltp":2.64,"tv":942.41,"id":9454286}]}]}
{"op":"mcm","clk":"4289831156","pt":1632494399097,"mc":[{"id":"1.188075669","rc":[{"batl":[[0,1.67,49.81],[1,1.69,197.78],[2,1.7,215.76]],"ltp":1.62,"tv":14601.14,"id":9631939},{"batb":[[0,2.48,4.26],[1,2.46,3],[2,2.44,178.06]],"ltp":2.64,"tv":942.41,"id":9454286}]}]}
{"op":"mcm","clk":"4289831388","pt":1632494402009,"mc":[{"id":"1.188075669","rc":[{"batb":[[0,1.56,210.15],[1,1.55,486.18],[2,1.54,165.11]],"ltp":1.62,"tv":14601.14,"id":9631939},{"batl":[[0,2.8,146.02],[1,2.82,146.65],[2,3.1,5.05]],"ltp":2.64,"tv":942.41,"id":9454286}]}]}
{"op":"mcm","clk":"4289831628","pt":1632494405140,"mc":[{"id":"1.188075669","rc":[{"batb":[[2,2.44,175.06]],"ltp":2.64,"tv":942.41,"id":9454286}]}]}
{"op":"mcm","clk":"4289831829","pt":1632494408108,"mc":[{"id":"1.188075669","rc":[{"batb":[[0,1.57,5],[1,1.56,216.15],[2,1.55,486.18]],"ltp":1.62,"tv":14601.14,"id":9631939},{"batl":[[0,2.78,3],[1,2.8,146.02],[2,2.82,146.65]],"ltp":2.64,"tv":942.41,"id":9454286}]}]}
{"op":"mcm","clk":"4289831933","pt":1632494409217,"mc":[{"id":"1.188075669","rc":[{"batb":[[2,2.44,178.06]],"ltp":2.64,"tv":942.41,"id":9454286}]}]}
{"op":"mcm","clk":"4289832001","pt":1632494410007,"mc":[{"id":"1.188075669","rc":[{"batb":[[0,1.58,6],[1,1.57,28.57],[2,1.56,216.15]],"ltp":1.62,"tv":14601.14,"id":9631939},{"batl":[[0,2.74,4],[1,2.76,2.77],[2,2.78,3]],"ltp":2.64,"tv":942.41,"id":9454286}]}]}
{"op":"mcm","clk":"4289832023","pt":1632494410320,"mc":[{"id":"1.188075669","rc":[{"batb":[[1,1.57,5]],"ltp":1.62,"tv":14601.14,"id":9631939},{"batl":[[1,2.78,3],[2,2.8,146.02]],"ltp":2.64,"tv":942.41,"id":9454286}]}]}
{"op":"mcm","clk":"4289832086","pt":1632494411322,"mc":[{"id":"1.188075669","rc":[{"batl":[[1,2.76,3],[2,2.78,3]],"ltp":2.64,"tv":942.41,"id":9454286}]}]}
{"op":"mcm","clk":"4289832230","pt":1632494413010,"mc":[{"id":"1.188075669","rc":[{"batb":[[0,1.56,210.15],[1,1.55,486.18],[2,1.54,165.11]],"ltp":1.62,"tv":14601.14,"id":9631939},{"batl":[[0,2.8,146.02],[1,2.82,146.65],[2,3.1,5.05]],"ltp":2.64,"tv":942.41,"id":9454286}]}]}
{"op":"mcm","clk":"4289832475","pt":1632494416218,"mc":[{"id":"1.188075669","rc":[{"batb":[[0,1.55,21.99],[1,1.53,238.3],[2,1.48,30.51]],"batl":[[0,1.66,58.06],[1,1.67,49.5],[2,1.69,197.78]],"ltp":1.62,"tv":14601.14,"id":9631939},{"batb":[[0,2.5,4.04],[1,2.48,4.26],[2,2.46,3]],"batl":[[0,2.82,2.25],[1,3.1,5.05],[2,3.45,183.67]],"ltp":2.64,"tv":942.41,"id":9454286}]}]}
{"op":"mcm","clk":"4289832536","pt":1632494417009,"mc":[{"id":"1.188075669","rc":[{"batb":[[0,1.57,19.71],[1,1.55,21.99],[2,1.53,238.3]],"batl":[[0,1.67,49.81],[1,1.69,197.78],[2,1.7,215.76]],"ltp":1.62,"tv":14601.14,"id":9631939},{"batb":[[0,2.48,4.26],[1,2.46,3],[2,2.44,178.06]],"batl":[[0,2.76,2.02],[1,2.82,2.25],[2,3.1,5.05]],"ltp":2.64,"tv":942.41,"id":9454286}]}]}
{"op":"mcm","clk":"4289832608","pt":1632494418036,"mc":[{"id":"1.188075669","rc":[{"batb":[[0,1.55,21.99],[1,1.53,238.3],[2,1.48,30.51]],"ltp":1.62,"tv":14601.14,"id":9631939},{"batb":[[1,2.44,175.06],[2,2.42,169.44]],"batl":[[0,2.82,2.25],[1,3.1,5.05],[2,3.45,183.67]],"ltp":2.64,"tv":942.41,"id":9454286}]}]}
{"op":"mcm","clk":"4289832697","pt":1632494419144,"mc":[{"id":"1.188075669","rc":[{"trd":[[1.62,91.15]],"batb":[[0,1.65,241.71],[1,1.64,131.25],[2,1.56,1732.61]],"batl":[[0,1.66,8.84],[1,1.67,49.5],[2,1.69,197.78]],"ltp":1.62,"tv":14601.45,"id":9631939},{"trd":[[2.6,0.19]],"batl":[[0,2.58,926.6],[1,2.6,371.69],[2,2.62,359.74]],"ltp":2.6,"tv":942.6,"id":9454286}],"tv":15544.06}]}
{"op":"mcm","clk":"4289832784","pt":1632494420038,"mc":[{"id":"1.188075669","rc":[{"trd":[[1.65,150.3],[1.66,22.4]],"batb":[[0,1.66,172.02],[1,1.65,222.72],[2,1.64,131.25]],"batl":[[0,1.67,54.5],[1,1.69,197.78],[2,1.7,471.29]],"ltp":1.66,"tv":14657.11,"id":9631939},{"batl":[[0,2.58,370.64]],"ltp":2.6,"tv":942.6,"id":9454286}],"tv":15599.72}]}
{"op":"mcm","clk":"4289832850","pt":1632494420715,"mc":[{"id":"1.188075669","rc":[{"batb":[[1,1.65,297.14]],"batl":[[0,1.67,49.5]],"ltp":1.66,"tv":14657.11,"id":9631939},{"batl":[[0,2.54,48.34],[1,2.58,370.64],[2,2.6,371.69]],"ltp":2.6,"tv":942.6,"id":9454286}]}]}
{"op":"mcm","clk":"4289832956","pt":1632494422023,"mc":[{"id":"1.188075669","rc":[{"batl":[[2,2.6,374.69]],"ltp":2.6,"tv":942.6,"id":9454286}]}]}
{"op":"mcm","clk":"4289833056","pt":1632494423127,"mc":[{"id":"1.188075669","rc":[{"batb":[[1,1.65,222.72]],"ltp":1.66,"tv":14657.11,"id":9631939}]}]}
{"op":"mcm","clk":"4289833302","pt":1632494426062,"mc":[{"id":"1.188075669","rc":[{"batb":[[0,1.66,369.87]],"ltp":1.66,"tv":14657.11,"id":9631939},{"batl":[[2,2.6,540.17]],"ltp":2.6,"tv":942.6,"id":9454286}]}]}
{"op":"mcm","clk":"4289833384","pt":1632494427059,"mc":[{"id":"1.188075669","rc":[{"batl":[[1,1.68,56.64],[2,1.69,250.28]],"ltp":1.66,"tv":14657.11,"id":9631939},{"batb":[[1,2.46,3.88],[2,2.44,178.73]],"batl":[[2,2.6,542.73]],"ltp":2.6,"tv":942.6,"id":9454286}]}]}
{"op":"mcm","clk":"4289833634","pt":1632494430173,"mc":[{"id":"1.188075669","rc":[{"batb":[[1,1.63,20.23],[2,1.62,229.69]],"batl":[[0,1.69,52.5],[1,1.72,182.54],[2,1.73,216.04]],"ltp":1.66,"tv":14657.11,"id":9631939},{"batb":[[0,2.4,112.36],[1,2.38,155.39],[2,2.36,170.03]],"batl":[[1,2.6,171.04],[2,2.62,200.47]],"ltp":2.6,"tv":942.6,"id":9454286}]}]}
{"op":"mcm","clk":"4289833703","pt":1632494431066,"mc":[{"id":"1.188075669","rc":[{"batb":[[0,1.63,20.23],[1,1.62,229.69],[2,1.61,275.98]],"ltp":1.66,"tv":14657.11,"id":9631939},{"batb":[[0,2.38,155.39],[1,2.36,170.03],[2,2.34,121.05]],"batl":[[1,2.6,168.04]],"ltp":2.6,"tv":942.6,"id":9454286}]}]}
{"op":"mcm","clk":"4289833736","pt":1632494431547,"mc":[{"id":"1.188075669","rc":[{"batb":[[0,1.62,229.69],[1,1.61,275.98],[2,1.6,204.31]],"batl":[[0,1.69,52.66]],"ltp":1.66,"tv":14657.11,"id":9631939},{"batl":[[0,2.6,165.48],[1,2.62,200.47],[2,2.64,2.43]],"ltp":2.6,"tv":942.6,"id":9454286}]}]}
{"op":"mcm","clk":"4289833950","pt":1632494434138,"mc":[{"id":"1.188075669","rc":[{"batb":[[1,1.61,424.97],[2,1.6,347.57]],"batl":[[0,1.69,56.66],[2,1.73,338]],"ltp":1.66,"tv":14657.11,"id":9631939},{"batb":[[0,2.44,7.92],[1,2.42,4],[2,2.38,155.39]],"ltp":2.6,"tv":942.6,"id":9454286}]}]}
{"op":"mcm","clk":"4289834018","pt":1632494435085,"mc":[{"id":"1.188075669","rc":[{"batb":[[1,1.61,275.98],[2,1.6,204.31]],"batl":[[2,1.73,216.04]],"ltp":1.66,"tv":14657.11,"id":9631939}]}]}
{"op":"mcm","clk":"4289834097","pt":1632494436049,"mc":[{"id":"1.188075669","rc":[{"batb":[[0,1.64,227.12],[1,1.63,134.21],[2,1.62,229.69]],"batl":[[1,1.7,227.64],[2,1.72,404.99]],"ltp":1.66,"tv":14657.11,"id":9631939}]}]}
{"op":"mcm","clk":"4289834150","pt":1632494436988,"mc":[{"id":"1.188075669","rc":[{"batl":[[0,1.68,48.8],[1,1.69,56.5],[2,1.7,227.64]],"ltp":1.66,"tv":14657.11,"id":9631939},{"batb":[[0,2.46,4.38],[1,2.44,7.92],[2,2.42,4]],"ltp":2.6,"tv":942.6,"id":9454286}]}]}
{"op":"mcm","clk":"4289834219","pt":1632494437847,"mc":[{"id":"1.188075669","rc":[{"batb":[[0,1.62,229.69],[1,1.61,275.98],[2,1.6,204.31]],"batl":[[0,1.69,56.66],[1,1.72,182.54],[2,1.73,216.04]],"ltp":1.66,"tv":14657.11,"id":9631939},{"batb":[[0,2.44,7.92],[1,2.42,4],[2,2.38,155.39]],"ltp":2.6,"tv":942.6,"id":9454286}]}]}
{"op":"mcm","clk":"4289834279","pt":1632494438793,"mc":[{"id":"1.188075669","rc":[{"trd":[[1.66,22.72]],"batl":[[0,1.69,56.5]],"ltp":1.66,"tv":14657.43,"id":9631939}],"tv":15600.04}]}
{"op":"mcm","clk":"4289834468","pt":1632494440962,"mc":[{"id":"1.188075669","rc":[{"batb":[[1,1.61,424.97],[2,1.6,347.57]],"batl":[[1,1.76,4.63],[2,1.73,0]],"ltp":1.66,"tv":14657.43,"id":9631939},{"batb":[[2,2.34,121.05]],"ltp":2.6,"tv":942.6,"id":9454286}]}]}
{"op":"mcm","clk":"4289834669","pt":1632494443686,"mc":[{"id":"1.188075669","rc":[{"trd":[[1.62,129.85]],"batb":[[0,1.62,210.34]],"batl":[[0,1.66,277.49],[1,1.67,572.6],[2,1.68,1392.21]],"ltp":1.62,"tv":14696.13,"id":9631939},{"trd":[[2.6,11.23]],"batb":[[0,2.5,14.72],[1,2.44,7.92],[2,2.42,4]],"batl":[[0,2.6,159.97]],"ltp":2.6,"tv":953.64,"id":9454286}],"tv":15649.77}]}
{"op":"mcm","clk":"4289834781","pt":1632494445160,"mc":[{"id":"1.188075669","rc":[{"batl":[[2,1.68,1440.22]],"ltp":1.62,"tv":14696.13,"id":9631939},{"batb":[[0,2.52,97.51],[1,2.5,14.72],[2,2.46,35.78]],"ltp":2.6,"tv":953.64,"id":9454286}]}]}
{"op":"mcm","clk":"4289834816","pt":1632494445482,"mc":[{"id":"1.188075669","rc":[{"batl":[[2,1.68,1392.21]],"ltp":1.62,"tv":14696.13,"id":9631939}]}]}
{"op":"mcm","clk":"4289835115","pt":1632494449008,"mc":[{"id":"1.188075669","rc":[{"batb":[[0,1.63,120],[1,1.62,210.34],[2,1.61,424.97]],"batl":[[0,1.66,325.5]],"ltp":1.62,"tv":14696.13,"id":9631939}]}]}
{"op":"mcm","clk":"4289835302","pt":1632494451119,"mc":[{"id":"1.188075669","rc":[{"batl":[[1,1.67,629.1],[2,1.68,1446.1]],"ltp":1.62,"tv":14696.13,"id":9631939},{"batb":[[2,2.48,3.76]],"ltp":2.6,"tv":953.64,"id":9454286}]}]}
{"op":"mcm","clk":"4289835506","pt":1632494453186,"mc":[{"id":"1.188075669","rc":[{"batb":[[0,1.63,181]],"ltp":1.62,"tv":14696.13,"id":9631939}]}]}
{"op":"mcm","clk":"4289835787","pt":1632494457096,"mc":[{"id":"1.188075669","rc":[{"batb":[[1,1.6,222.75],[2,1.58,97.34]],"batl":[[0,1.67,56.5],[1,1.68,53.89],[2,1.69,116.5]],"ltp":1.62,"tv":14696.13,"id":9631939},{"batb":[[1,2.48,3.76],[2,2.46,4.38]],"batl":[[0,2.68,2.17],[1,2.72,45.74],[2,2.74,2.25]],"ltp":2.6,"tv":953.64,"id":9454286}]}]}
{"op":"mcm","clk":"4289835876","pt":1632494457996,"mc":[{"id":"1.188075669","rc":[{"batb":[[0,1.6,18.44],[1,1.58,97.34],[2,1.55,27.99]],"batl":[[0,1.68,53.89],[1,1.69,64],[2,1.76,4.63]],"ltp":1.62,"tv":14696.13,"id":9631939},{"batb":[[0,2.46,4.38],[1,2.44,14.41],[2,2.42,108.57]],"ltp":2.6,"tv":953.64,"id":9454286}]}]}
{"op":"mcm","clk":"4289835902","pt":1632494458319,"mc":[{"id":"1.188075669","rc":[{"batb":[[0,1.58,18.56],[1,1.55,27.99],[2,1.52,243.28]],"batl":[[1,1.69,4]],"ltp":1.62,"tv":14696.13,"id":9631939},{"batb":[[1,2.44,4]],"batl":[[0,2.74,2.25],[1,2.8,3],[2,2.82,2.25]],"ltp":2.6,"tv":953.64,"id":9454286}]}]}
{"op":"mcm","clk":"4289836042","pt":1632494460096,"mc":[{"id":"1.188075669","rc":[{"batb":[[2,1.54,264.61]],"batl":[[2,1.7,177.4]],"ltp":1.62,"tv":14696.13,"id":9631939}]}]}
{"op":"mcm","clk":"4289836139","pt":1632494461207,"mc":[{"id":"1.188075669","rc":[{"batb":[[2,1.52,243.28]],"batl":[[0,1.67,6],[1,1.68,58.89],[2,1.69,4]],"ltp":1.62,"tv":14696.13,"id":9631939},{"batb":[[0,2.48,4],[1,2.46,7.38],[2,2.44,4]],"ltp":2.6,"tv":953.64,"id":9454286}]}]}
{"op":"mcm","clk":"4289836323","pt":1632494463213,"mc":[{"id":"1.188075669","rc":[{"batl":[[2,1.69,617.46]],"ltp":1.62,"tv":14696.13,"id":9631939}]}]}
{"op":"mcm","clk":"4289836401","pt":1632494464018,"mc":[{"id":"1.188075669","rc":[{"batl":[[2,1.69,4]],"ltp":1.62,"tv":14696.13,"id":9631939}]}]}
{"op":"mcm","clk":"4289836454","pt":1632494464699,"mc":[{"id":"1.188075669","rc":[{"batb":[[0,1.59,252.15],[1,1.58,169.1],[2,1.55,27.99]],"batl":[[0,1.64,149.65],[1,1.65,127.65],[2,1.67,6]],"ltp":1.62,"tv":14696.13,"id":9631939}]}]}
{"op":"mcm","clk":"4289836529","pt":1632494465591,"mc":[{"id":"1.188075669","rc":[{"batb":[[0,1.58,18.56],[1,1.55,27.99],[2,1.52,243.28]],"batl":[[0,1.67,6],[1,1.68,58.89],[2,1.69,4]],"ltp":1.62,"tv":14696.13,"id":9631939}]}]}
{"op":"mcm","clk":"4289836788","pt":1632494469008,"mc":[{"id":"1.188075669","rc":[{"batb":[[2,1.54,264.61]],"ltp":1.62,"tv":14696.13,"id":9631939}]}]}
{"op":"mcm","clk":"4289837033","pt":1632494472218,"mc":[{"id":"1.188075669","rc":[{"batb":[[0,1.6,22.99],[1,1.58,18.56],[2,1.55,21.99]],"ltp":1.62,"tv":14696.13,"id":9631939},{"batl":[[0,2.68,2.39],[1,2.74,2.25]],"ltp":2.6,"tv":953.64,"id":9454286}]}]}
{"op":"mcm","clk":"4289837120","pt":1632494473112,"mc":[{"id":"1.188075669","rc":[{"trd":[[1.57,41.36],[1.58,204.03]],"batb":[[0,1.55,21.99],[1,1.54,264.61],[2,1.53,170.24]],"batl":[[0,1.58,12.08],[1,1.59,2731.94],[2,1.6,739.67]],"ltp":1.57,"tv":14734.56,"id":9631939},{"trd":[[2.74,26.41]],"batb":[[0,2.6,11.84],[1,2.56,585.05],[2,2.5,297.11]],"batl":[[0,2.74,1.5],[1,2.82,2.25],[2,2.84,12.42]],"ltp":2.74,"tv":954.39,"id":9454286}],"tv":15688.95}]}
{"op":"mcm","clk":"4289837213","pt":1632494474209,"mc":[{"id":"1.188075669","rc":[{"batl":[[1,1.59,411.22]],"ltp":1.57,"tv":14734.56,"id":9631939},{"trd":[[2.74,29.41]],"batb":[[0,2.74,77.79],[1,2.62,9.25],[2,2.6,11.84]],"batl":[[0,2.82,2.25],[1,2.84,12.42],[2,2.92,241.46]],"ltp":2.74,"tv":957.39,"id":9454286}],"tv":15691.95}]}
{"op":"mcm","clk":"4289837242","pt":1632494474625,"mc":[{"id":"1.188075669","rc":[{"batb":[[0,1.54,264.61],[1,1.53,170.24],[2,1.52,243.28]],"ltp":1.57,"tv":14734.56,"id":9631939},{"batl":[[0,2.84,12.42],[1,2.92,241.46],[2,2.94,325.26]],"ltp":2.74,"tv":957.39,"id":9454286}]}]}
{"op":"mcm","clk":"4289837335","pt":1632494475829,"mc":[{"id":"1.188075669","rc":[{"batb":[[1,2.64,3],[2,2.62,12.25]],"ltp":2.74,"tv":957.39,"id":9454286}]}]}
{"op":"mcm","clk":"4289837517","pt":1632494478036,"mc":[{"id":"1.188075669","rc":[{"batb":[[0,1.55,191],[1,1.54,264.61],[2,1.53,170.24]],"ltp":1.57,"tv":14734.56,"id":9631939},{"batb":[[2,2.62,3]],"ltp":2.74,"tv":957.39,"id":9454286}]}]}
{"op":"mcm","clk":"4289837802","pt":1632494481252,"mc":[{"id":"1.188075669","rc":[{"batb":[[1,2.66,9.03],[2,2.64,3]],"ltp":2.74,"tv":957.39,"id":9454286}]}]}
{"op":"mcm","clk":"4289838092","pt":1632494484635,"mc":[{"id":"1.188075669","rc":[{"batl":[[1,1.59,211.16]],"ltp":1.57,"tv":14734.56,"id":9631939}]}]}
{"op":"mcm","clk":"4289838516","pt":1632494489955,"mc":[{"id":"1.188075669","rc":[{"trd":[[2.74,33.79]],"batb":[[0,2.74,75.6]],"ltp":2.74,"tv":961.77,"id":9454286}],"tv":15696.34}]}
{"op":"mcm","clk":"4289838805","pt":1632494493177,"mc":[{"id":"1.188075669","rc":[{"batb":[[0,1.5,84.85],[1,1.48,24.51],[2,1.47,26.84]],"batl":[[0,1.61,60],[1,1.66,5],[2,1.67,60.5]],"ltp":1.57,"tv":14734.56,"id":9631939},{"batb":[[0,2.66,9.03],[1,2.62,3],[2,2.52,97.51]],"batl":[[0,2.98,42.64],[1,3.1,2.05],[2,3.15,2.1]],"ltp":2.74,"tv":961.77,"id":9454286}]}]}
{"op":"mcm","clk":"4289838832","pt":1632494493457,"mc":[{"id":"1.188075669","rc":[{"batb":[[1,2.52,97.51],[2,2.48,4.51]],"ltp":2.74,"tv":961.77,"id":9454286}]}]}
{"op":"mcm","clk":"4289838926","pt":1632494494661,"mc":[{"id":"1.188075669","rc":[{"batb":[[0,1.45,27.41],[1,1.42,326.12],[2,1.4,31.31]],"batl":[[0,1.66,5],[1,1.67,60.5],[2,1.68,54.2]],"ltp":1.57,"tv":14734.56,"id":9631939},{"batb":[[0,2.52,97.51],[1,2.48,4.51],[2,2.46,4.38]],"batl":[[0,3.25,2],[1,3.5,2],[2,3.9,161.11]],"ltp":2.74,"tv":961.77,"id":9454286}]}]}
{"op":"mcm","clk":"4289839027","pt":1632494496092,"mc":[{"id":"1.188075669","rc":[{"batb":[[1,1.44,182.5],[2,1.43,223.81]],"batl":[[1,1.67,274.93]],"ltp":1.57,"tv":14734.56,"id":9631939}]}]}
{"op":"mcm","clk":"4289839163","pt":1632494498091,"mc":[{"id":"1.188075669","rc":[{"batb":[[0,1.46,6],[1,1.45,34.41],[2,1.44,6]],"batl":[[1,1.67,60.5]],"ltp":1.57,"tv":14734.56,"id":9631939},{"batb":[[0,2.52,100.51],[1,2.5,3],[2,2.48,4.51]],"batl":[[0,3.25,5]],"ltp":2.74,"tv":961.77,"id":9454286}]}]}
{"op":"mcm","clk":"4289839335","pt":1632494500182,"mc":[{"id":"1.188075669","rc":[{"batl":[[0,1.61,4],[1,1.66,5],[2,1.67,60.5]],"ltp":1.57,"tv":14734.56,"id":9631939}]}]}
{"op":"mcm","clk":"4289839388","pt":1632494500985,"mc":[{"id":"1.188075669","rc":[{"batb":[[0,1.52,231.14],[1,1.51,179.06],[2,1.46,6]],"batl":[[0,1.57,276.31],[1,1.58,148.27],[2,1.66,5]],"ltp":1.57,"tv":14734.56,"id":9631939}]}]}
{"op":"mcm","clk":"4289839486","pt":1632494501977,"mc":[{"id":"1.188075669","rc":[{"batb":[[2,1.47,30]],"batl":[[2,1.65,25]],"ltp":1.57,"tv":14734.56,"id":9631939},{"batb":[[0,2.54,73.58],[1,2.52,100.51],[2,2.5,3]],"batl":[[0,3.15,3],[1,3.2,27],[2,3.25,5]],"ltp":2.74,"tv":961.77,"id":9454286}]}]}
{"op":"mcm","clk":"4289839518","pt":1632494502278,"mc":[{"id":"1.188075669","rc":[{"batl":[[2,1.66,5]],"ltp":1.57,"tv":14734.56,"id":9631939},{"batl":[[1,3.2,2]],"ltp":2.74,"tv":961.77,"id":9454286}]}]}
{"op":"mcm","clk":"4289839627","pt":1632494503864,"mc":[{"id":"1.188075669","rc":[{"batb":[[0,1.46,6],[1,1.45,34.41],[2,1.44,6]],"batl":[[0,1.66,5],[1,1.67,60.5],[2,1.68,54.2]],"ltp":1.57,"tv":14734.56,"id":9631939},{"batb":[[0,2.52,100.51],[1,2.5,3],[2,2.48,4.51]],"ltp":2.74,"tv":961.77,"id":9454286}]}]}
{"op":"mcm","clk":"4289839864","pt":1632494507076,"mc":[{"id":"1.188075669","rc":[{"batb":[[0,1.48,27.26],[1,1.46,6],[2,1.45,34.41]],"batl":[[1,1.67,274.93]],"ltp":1.57,"tv":14734.56,"id":9631939},{"batl":[[0,3.1,2.05],[1,3.15,3],[2,3.2,2]],"ltp":2.74,"tv":961.77,"id":9454286}]}]}
{"op":"mcm","clk":"4289839903","pt":1632494507592,"mc":[{"id":"1.188075669","rc":[{"batb":[[0,1.46,6],[1,1.45,34.41],[2,1.44,6]],"batl":[[0,1.67,274.93],[1,1.68,54.2],[2,1.69,236.03]],"ltp":1.57,"tv":14734.56,"id":9631939},{"batb":[[0,2.52,97.51],[1,2.48,4.51],[2,2.46,4.38]],"batl":[[0,3.15,3],[1,3.2,2],[2,3.25,5]],"ltp":2.74,"tv":961.77,"id":9454286}]}]}
{"op":"mcm","clk":"4289840009","pt":1632494509190,"mc":[{"id":"1.188075669","rc":[{"batb":[[0,1.62,2704.33],[1,1.61,140.02],[2,1.47,1481.18]],"batl":[[0,1.64,13.82],[1,1.66,370.28],[2,1.67,274.93]],"ltp":1.57,"tv":14734.56,"id":9631939},{"batl":[[0,2.66,369.92],[1,2.68,348.92],[2,2.7,348.92]],"ltp":2.74,"tv":961.77,"id":9454286}]}]}
{"op":"mcm","clk":"4289840118","pt":1632494510192,"mc":[{"id":"1.188075669","rc":[{"trd":[[1.62,168.07]],"batb":[[0,1.62,328.6],[2,1.6,204.39]],"ltp":1.62,"tv":14772.78,"id":9631939}],"tv":15734.56}]}
{"op":"mcm","clk":"4289840196","pt":1632494511196,"mc":[{"id":"1.188075669","rc":[{"batl":[[2,1.67,304.61]],"ltp":1.62,"tv":14772.78,"id":9631939}]}]}
{"op":"mcm","clk":"4289840426","pt":1632494514092,"mc":[{"id":"1.188075669","rc":[{"batb":[[0,1.62,466.6]],"batl":[[1,1.66,430.28]],"ltp":1.62,"tv":14772.78,"id":9631939},{"batb":[[0,2.52,107.37]],"ltp":2.74,"tv":961.77,"id":9454286}]}]}
{"op":"mcm","clk":"4289840474","pt":1632494514670,"mc":[{"id":"1.188075669","rc":[{"batl":[[0,2.66,391.28]],"ltp":2.74,"tv":961.77,"id":9454286}]}]}
{"op":"mcm","clk":"4289840688","pt":1632494517193,"mc":[{"id":"1.188075669","rc":[{"batb":[[0,1.62,572.6]],"ltp":1.62,"tv":14772.78,"id":9631939}]}]}
{"op":"mcm","clk":"4289840969","pt":1632494520821,"mc":[{"id":"1.188075669","rc":[{"batb":[[0,1.62,388.55]],"ltp":1.62,"tv":14772.78,"id":9631939}]}]}
{"op":"mcm","clk":"4289841277","pt":1632494524032,"mc":[{"id":"1.188075669","rc":[{"batb":[[0,1.62,533.55]],"ltp":1.62,"tv":14772.78,"id":9631939}]}]}
{"op":"mcm","clk":"4289842473","pt":1632494537141,"mc":[{"id":"1.188075669","rc":[{"batl":[[0,1.66,60],[1,1.67,304.61],[2,1.68,54.2]],"ltp":1.62,"tv":14772.78,"id":9631939},{"batl":[[0,2.66,21.36],[1,2.74,2.48],[2,2.76,169.86]],"ltp":2.74,"tv":961.77,"id":9454286}]}]}
{"op":"mcm","clk":"4289842552","pt":1632494538042,"mc":[{"id":"1.188075669","rc":[{"batb":[[0,1.58,19.06],[1,1.57,210.58],[2,1.56,296.15]],"batl":[[1,1.76,4.94],[2,1.8,246.13]],"ltp":1.62,"tv":14772.78,"id":9631939},{"batb":[[0,2.52,9.86],[1,2.26,165.25],[2,2.24,357.47]],"batl":[[0,2.74,2.48],[1,2.76,169.86],[2,2.78,138.43]],"ltp":2.74,"tv":961.77,"id":9454286}]}]}
{"op":"mcm","clk":"4289842603","pt":1632494538661,"mc":[{"id":"1.188075669","rc":[{"batb":[[0,1.57,210.58],[1,1.56,296.15],[2,1.53,238.89]],"batl":[[0,1.76,4.94],[1,1.8,246.13],[2,1.81,267.98]],"ltp":1.62,"tv":14772.78,"id":9631939},{"batb":[[0,2.26,165.25],[1,2.24,357.47],[2,2.16,4.28]],"batl":[[0,2.76,169.86],[1,2.78,138.43],[2,2.8,2.32]],"ltp":2.74,"tv":961.77,"id":9454286}]}]}
{"op":"mcm","clk":"4289842794","pt":1632494541033,"mc":[{"id":"1.188075669","rc":[{"batb":[[2,1.55,258.83]],"batl":[[2,1.81,435.09]],"ltp":1.62,"tv":14772.78,"id":9631939},{"batb":[[0,2.28,129.57],[1,2.26,165.25],[2,2.24,357.47]],"ltp":2.74,"tv":961.77,"id":9454286}]}]}
{"op":"mcm","clk":"4289842867","pt":1632494541956,"mc":[{"id":"1.188075669","rc":[{"trd":[[1.68,0.62],[1.76,27.36],[1.77,2.73]],"batb":[[0,1.56,19.08],[1,1.53,238.89],[2,1.47,6]],"batl":[[0,1.8,246.13],[1,1.81,435.09],[2,1.83,182.69]],"ltp":1.77,"tv":14785.39,"id":9631939},{"trd":[[2.3,2.1]],"batb":[[0,2.28,132.47],[2,2.24,223.35]],"batl":[[0,2.74,2.48],[1,2.8,2.32],[2,3.15,3]],"ltp":2.3,"tv":963.87,"id":9454286}],"tv":15749.26}]}
{"op":"mcm","clk":"4289842883","pt":1632494542258,"mc":[{"id":"1.188075669","rc":[{"batb":[[0,2.28,131.57]],"batl":[[0,2.8,2.32],[1,3.15,3],[2,3.25,2]],"ltp":2.3,"tv":963.87,"id":9454286}]}]}
{"op":"mcm","clk":"4289843009","pt":1632494544058,"mc":[{"id":"1.188075669","rc":[{"batb":[[0,2.28,129.57]],"ltp":2.3,"tv":963.87,"id":9454286}]}]}
{"op":"mcm","clk":"4289843120","pt":1632494545148,"mc":[{"id":"1.188075669","rc":[{"batb":[[0,1.75,376.43],[1,1.73,217.01],[2,1.72,571.22]],"batl":[[0,1.77,5],[1,1.8,660.61],[2,1.81,435.09]],"ltp":1.77,"tv":14785.39,"id":9631939},{"batb":[[0,2.32,6.94],[1,2.28,129.57],[2,2.26,169.25]],"batl":[[0,2.46,233.93],[1,2.62,1.71],[2,2.8,13.03]],"ltp":2.3,"tv":963.87,"id":9454286}]}]}
{"op":"mcm","clk":"4289843201","pt":1632494545980,"mc":[{"id":"1.188075669","rc":[{"trd":[[1.75,65.45]],"batb":[[0,1.75,358.47],[2,1.72,730.57]],"batl":[[0,1.8,660.61],[1,1.81,435.09],[2,1.83,182.69]],"ltp":1.75,"tv":14821.31,"id":9631939},{"batb":[[2,2.26,165.25]],"ltp":2.3,"tv":963.87,"id":9454286}],"tv":15785.18}]}
{"op":"mcm","clk":"4289843296","pt":1632494547041,"mc":[{"id":"1.188075669","rc":[{"batl":[[1,1.81,495.09]],"ltp":1.75,"tv":14821.31,"id":9631939},{"batl":[[1,2.52,48.66],[2,2.62,1.71]],"ltp":2.3,"tv":963.87,"id":9454286}]}]}
{"op":"mcm","clk":"4289843350","pt":1632494547768,"mc":[{"id":"1.188075669","rc":[{"batl":[[1,1.81,435.09]],"ltp":1.75,"tv":14821.31,"id":9631939},{"batl":[[0,2.44,3],[1,2.46,233.93]],"ltp":2.3,"tv":963.87,"id":9454286}]}]}
{"op":"mcm","clk":"4289843489","pt":1632494550170,"mc":[{"id":"1.188075669","rc":[{"batl":[[0,2.44,46.65]],"ltp":2.3,"tv":963.87,"id":9454286}]}]}
{"op":"mcm","clk":"4289843559","pt":1632494551071,"mc":[{"id":"1.188075669","rc":[{"batb":[[0,1.75,890.47]],"batl":[[1,1.81,495.09]],"ltp":1.75,"tv":14821.31,"id":9631939},{"batl":[[0,2.44,3],[2,2.52,48.66]],"ltp":2.3,"tv":963.87,"id":9454286}]}]}
{"op":"mcm","clk":"4289843630","pt":1632494551962,"mc":[{"id":"1.188075669","rc":[{"batl":[[2,2.54,145.01]],"ltp":2.3,"tv":963.87,"id":9454286}]}]}
{"op":"mcm","clk":"4289843795","pt":1632494554182,"mc":[{"id":"1.188075669","rc":[{"batl":[[0,2.42,15],[1,2.44,3],[2,2.46,233.93]],"ltp":2.3,"tv":963.87,"id":9454286}]}]}
{"op":"mcm","clk":"4289843973","pt":1632494556590,"mc":[{"id":"1.188075669","rc":[{"batb":[[0,1.75,696.12]],"ltp":1.75,"tv":14821.31,"id":9631939}]}]}
{"op":"mcm","clk":"4289844067","pt":1632494557486,"mc":[{"id":"1.188075669","rc":[{"trd":[[1.75,66.39]],"batb":[[0,1.75,695.65]],"ltp":1.75,"tv":14822.25,"id":9631939}],"tv":15786.12}]}
{"op":"mcm","clk":"4289844177","pt":1632494559167,"mc":[{"id":"1.188075669","rc":[{"trd":[[2.28,132.19],[2.32,14.31]],"batb":[[0,2.28,63.47],[1,2.26,165.25],[2,2.24,235.44]],"ltp":2.28,"tv":1109.94,"id":9454286}],"tv":15932.2}]}
{"op":"mcm","clk":"4289844401","pt":1632494562070,"mc":[{"id":"1.188075669","rc":[{"trd":[[1.75,66.59]],"batb":[[0,1.65,225.4],[1,1.64,313.22],[2,1.62,193.76]],"batl":[[0,1.81,60],[1,2.02,201.32],[2,2.04,251.68]],"ltp":1.75,"tv":14822.45,"id":9631939},{"batb":[[0,2.24,12.09],[1,1.99,445.14],[2,1.98,249.97]],"batl":[[0,2.48,49.31],[1,2.54,145.01],[2,2.56,157.35]],"ltp":2.28,"tv":1109.94,"id":9454286}],"tv":15932.39}]}
{"op":"mcm","clk":"4289844495","pt":1632494563278,"mc":[{"id":"1.188075669","rc":[{"batl":[[0,2.02,201.32],[1,2.04,251.68],[2,2.1,4.45]],"ltp":1.75,"tv":14822.45,"id":9631939},{"batb":[[0,1.99,445.14],[1,1.98,249.97],[2,1.91,48.39]],"batl":[[0,2.54,145.01],[1,2.56,157.35],[2,3.15,204.05]],"ltp":2.28,"tv":1109.94,"id":9454286}]}]}
{"op":"mcm","clk":"4289844675","pt":1632494565194,"mc":[{"id":"1.188075669","rc":[{"batb":[[0,1.65,354.72],[1,1.64,633.83],[2,1.57,5]],"batl":[[1,2.04,353.63],[2,2.06,128.29]],"ltp":1.75,"tv":14822.45,"id":9631939},{"batb":[[0,2,4],[1,1.99,255.63],[2,1.98,249.97]],"ltp":2.28,"tv":1109.94,"id":9454286}]}]}
{"op":"mcm","clk":"4289844744","pt":1632494565989,"mc":[{"id":"1.188075669","rc":[{"batb":[[0,1.65,225.4],[1,1.64,502.77]],"batl":[[1,2.04,251.68],[2,2.1,4.45]],"ltp":1.75,"tv":14822.45,"id":9631939}]}]}
{"op":"mcm","clk":"4289844783","pt":1632494566603,"mc":[{"id":"1.188075669","rc":[{"batl":[[0,2.02,205.32]],"ltp":1.75,"tv":14822.45,"id":9631939},{"batb":[[2,1.98,254.97]],"ltp":2.28,"tv":1109.94,"id":9454286}]}]}
{"op":"mcm","clk":"4289844890","pt":1632494568181,"mc":[{"id":"1.188075669","rc":[{"batl":[[0,2,4],[1,2.02,205.32],[2,2.04,251.68]],"ltp":1.75,"tv":14822.45,"id":9631939}]}]}
{"op":"mcm","clk":"4289844971","pt":1632494569174,"mc":[{"id":"1.188075669","rc":[{"batb":[[0,1.79,148.38],[1,1.77,201.19],[2,1.65,225.4]],"batl":[[0,1.85,147.96],[1,1.87,170.96],[2,2,4]],"ltp":1.75,"tv":14822.45,"id":9631939}]}]}
{"op":"mcm","clk":"4289845018","pt":1632494569903,"mc":[{"id":"1.188075669","rc":[{"batb":[[2,1.66,124.72]],"batl":[[2,2,107.62]],"ltp":1.75,"tv":14822.45,"id":9631939},{"batb":[[0,2.02,20],[1,2,4],[2,1.99,255.63]],"batl":[[0,2.52,83.38],[1,2.54,145.01],[2,2.56,157.35]],"ltp":2.28,"tv":1109.94,"id":9454286}]}]}
{"op":"mcm","clk":"4289845266","pt":1632494572902,"mc":[{"id":"1.188075669","rc":[{"batb":[[0,1.65,225.4],[1,1.64,502.77],[2,1.57,5]],"batl":[[0,2,4],[1,2.02,205.32],[2,2.04,251.68]],"ltp":1.75,"tv":14822.45,"id":9631939},{"batb":[[0,2,4],[1,1.99,255.63],[2,1.98,254.97]],"batl":[[0,2.54,145.01],[1,2.56,157.35],[2,3.15,204.05]],"ltp":2.28,"tv":1109.94,"id":9454286}]}]}
{"op":"mcm","clk":"4289845495","pt":1632494576111,"mc":[{"id":"1.188075669","rc":[{"batb":[[0,1.65,354.72],[1,1.64,633.83]],"batl":[[0,1.99,4],[1,2,4],[2,2.02,205.32]],"ltp":1.75,"tv":14822.45,"id":9631939}]}]}
{"op":"mcm","clk":"4289845569","pt":1632494577014,"mc":[{"id":"1.188075669","rc":[{"batb":[[1,1.99,251.63]],"ltp":2.28,"tv":1109.94,"id":9454286}]}]}
{"op":"mcm","clk":"4289845591","pt":1632494577229,"mc":[{"id":"1.188075669","rc":[{"batb":[[0,1.64,189.55],[1,1.57,5],[2,1.3,176.04]],"ltp":1.75,"tv":14822.45,"id":9631939},{"batl":[[0,3.15,204.05],[1,810,0.07],[2,3.15,0]],"ltp":2.28,"tv":1109.94,"id":9454286}]}]}
{"op":"mcm","clk":"4289845737","pt":1632494579015,"mc":[{"id":"1.188075669","rc":[{"batl":[[0,810,0.07],[1,810,0]],"ltp":2.28,"tv":1109.94,"id":9454286}]}]}
{"op":"mcm","clk":"4289845837","pt":1632494580190,"mc":[{"id":"1.188075669","rc":[{"batb":[[0,1.96,2834.58],[1,1.93,495.46],[2,1.92,480.9]],"batl":[[0,2,5.56],[1,2.02,4.75],[2,2.04,656.37]],"ltp":1.75,"tv":14822.45,"id":9631939},{"batb":[[0,2,5.56],[1,1.99,48.51],[2,1.97,198.91]],"batl":[[0,2.04,200.28],[1,2.06,141.02],[2,2.42,12.4]],"ltp":2.28,"tv":1109.94,"id":9454286}]}]}
{"op":"mcm","clk":"4289845945","pt":1632494581192,"mc":[{"id":"1.188075669","rc":[{"trd":[[1.96,32.6]],"batb":[[0,1.97,106.2],[1,1.96,208.67],[2,1.93,495.46]],"batl":[[1,2.04,715.2],[2,2.1,4.45]],"ltp":1.96,"tv":14855.05,"id":9631939},{"batb":[[1,1.97,214.14],[2,1.96,117.45]],"batl":[[2,2.18,55.23]],"ltp":2.28,"tv":1109.94,"id":9454286}],"tv":15964.99}]}
{"op":"mcm","clk":"4289846098","pt":1632494582945,"mc":[{"id":"1.188075669","rc":[{"batl":[[1,2.04,656.37]],"ltp":1.96,"tv":14855.05,"id":9631939},{"batb":[[1,1.97,198.91]],"batl":[[2,2.26,102.56]],"ltp":2.28,"tv":1109.94,"id":9454286}]}]}
{"op":"mcm","clk":"4289846391","pt":1632494586108,"mc":[{"id":"1.188075669","rc":[{"batb":[[0,1.97,375.2]],"batl":[[1,2.04,715.2]],"ltp":1.96,"tv":14855.05,"id":9631939},{"batb":[[1,1.97,214.14]],"ltp":2.28,"tv":1109.94,"id":9454286}]}]}
{"op":"mcm","clk":"4289846485","pt":1632494587203,"mc":[{"id":"1.188075669","rc":[{"batl":[[2,2.24,183.4]],"ltp":2.28,"tv":1109.94,"id":9454286}]}]}
{"op":"mcm","clk":"4289846599","pt":1632494588823,"mc":[{"id":"1.188075669","rc":[{"trd":[[1.97,0.2]],"batb":[[0,1.97,375.11]],"ltp":1.97,"tv":14855.24,"id":9631939}],"tv":15965.19}]}
{"op":"mcm","clk":"4289846702","pt":1632494590031,"mc":[{"id":"1.188075669","rc":[{"batb":[[0,1.97,549.11]],"ltp":1.97,"tv":14855.24,"id":9631939}]}]}
{"op":"mcm","clk":"4289846903","pt":1632494592036,"mc":[{"id":"1.188075669","rc":[{"batb":[[1,1.93,495.46],[2,1.92,480.9]],"ltp":1.97,"tv":14855.24,"id":9631939}]}]}
{"op":"mcm","clk":"4289847611","pt":1632494600759,"mc":[{"id":"1.188075669","rc":[{"batb":[[0,1.82,136.15],[1,1.81,188.15],[2,1.8,277.13]],"batl":[[0,2.04,58.83],[1,2.36,159.88],[2,2.38,209.81]],"ltp":1.97,"tv":14855.24,"id":9631939},{"batb":[[0,1.97,15.23],[1,1.73,236.93],[2,1.72,389.4]],"batl":[[0,2.24,183.4],[1,2.26,194.15],[2,2.56,3]],"ltp":2.28,"tv":1109.94,"id":9454286}]}]}
{"op":"mcm","clk":"4289847755","pt":1632494602346,"mc":[{"id":"1.188075669","rc":[{"batl":[[0,2.36,159.88],[1,2.38,209.81],[2,2.5,3.91]],"ltp":1.97,"tv":14855.24,"id":9631939},{"batb":[[0,1.73,236.93],[1,1.72,389.4],[2,1.67,471.66]],"ltp":2.28,"tv":1109.94,"id":9454286}]}]}
{"op":"mcm","clk":"4289847928","pt":1632494604146,"mc":[{"id":"1.188075669","rc":[{"batb":[[2,1.71,168.76]],"batl":[[0,2.22,116.92],[1,2.24,284.14],[2,2.26,194.15]],"ltp":2.28,"tv":1109.94,"id":9454286}]}]}
{"op":"mcm","clk":"4289847969","pt":1632494604671,"mc":[{"id":"1.188075669","rc":[{"batl":[[0,2.5,3.91],[1,2.38,0],[2,2.5,0]],"ltp":1.97,"tv":14855.24,"id":9631939},{"batb":[[0,1.72,152.85],[1,1.67,471.66],[2,1.53,3.42]],"batl":[[0,2.24,183.4],[1,2.26,194.15],[2,2.56,3]],"ltp":2.28,"tv":1109.94,"id":9454286}]}]}
{"op":"mcm","clk":"4289848032","pt":1632494605570,"mc":[{"id":"1.188075669","rc":[{"batl":[[0,2.36,3],[1,2.5,3.91]],"ltp":1.97,"tv":14855.24,"id":9631939},{"batb":[[0,1.73,4],[1,1.72,156.85],[2,1.67,471.66]],"ltp":2.28,"tv":1109.94,"id":9454286}]}]}
{"op":"mcm","clk":"4289848149","pt":1632494607150,"mc":[{"id":"1.188075669","rc":[{"trd":[[1.82,34.88]],"batb":[[0,1.82,118.71]],"batl":[[0,1.85,63.3],[1,1.86,13.73],[2,1.89,485.31]],"ltp":1.82,"tv":14890.12,"id":9631939},{"batb":[[0,2.16,18.03],[1,2.12,2562.84],[2,2.1,1821.42]],"batl":[[0,2.24,195.79],[2,2.28,1677.64]],"ltp":2.28,"tv":1109.94,"id":9454286}],"tv":16000.07}]}
{"op":"mcm","clk":"4289848250","pt":1632494608162,"mc":[{"id":"1.188075669","rc":[{"batb":[[0,1.82,258.28],[2,1.8,467.59]],"batl":[[2,1.88,133.16]],"ltp":1.82,"tv":14890.12,"id":9631939},{"batb":[[1,2.12,216.79],[2,2.1,455.36]],"batl":[[2,2.28,419.4]],"ltp":2.28,"tv":1109.94,"id":9454286}]}]}
{"op":"mcm","clk":"4289848322","pt":1632494609041,"mc":[{"id":"1.188075669","rc":[{"batb":[[1,2.14,153.7],[2,2.12,216.79]],"ltp":2.28,"tv":1109.94,"id":9454286}]}]}
{"op":"mcm","clk":"4289848386","pt":1632494609944,"mc":[{"id":"1.188075669","rc":[{"trd":[[1.82,41.91]],"batb":[[0,1.82,254.76]],"ltp":1.82,"tv":14897.16,"id":9631939}],"tv":16007.1}]}
{"op":"mcm","clk":"4289848608","pt":1632494612343,"mc":[{"id":"1.188075669","rc":[{"batb":[[2,2.12,203.4]],"ltp":2.28,"tv":1109.94,"id":9454286}]}]}
{"op":"mcm","clk":"4289848886","pt":1632494615572,"mc":[{"id":"1.188075669","rc":[{"batl":[[2,1.88,193.16]],"ltp":1.82,"tv":14897.16,"id":9631939},{"batb":[[1,2.14,166.85]],"ltp":2.28,"tv":1109.94,"id":9454286}]}]}
{"op":"mcm","clk":"4289849012","pt":1632494616989,"mc":[{"id":"1.188075669","rc":[{"trd":[[1.85,100.2]],"batl":[[0,1.85,63.2]],"ltp":1.85,"tv":14897.35,"id":9631939}],"tv":16007.3}]}
{"op":"mcm","clk":"4289849206","pt":1632494619197,"mc":[{"id":"1.188075669","rc":[{"batb":[[2,2.1,459.36]],"ltp":2.28,"tv":1109.94,"id":9454286}]}]}
{"op":"mcm","clk":"4289849569","pt":1632494623193,"mc":[{"id":"1.188075669","rc":[{"batb":[[0,1.82,139.57],[1,1.8,190.46],[2,1.68,227.02]],"batl":[[0,1.88,193.16],[1,1.9,162.88],[2,2.18,168.48]],"ltp":1.85,"tv":14897.35,"id":9631939},{"batb":[[0,2.14,13.15],[1,1.84,211.17],[2,1.83,411.34]],"batl":[[0,2.48,152.45],[1,2.5,196.08],[2,2.56,3]],"ltp":2.28,"tv":1109.94,"id":9454286}]}]}
{"op":"mcm","clk":"4289849676","pt":1632494624200,"mc":[{"id":"1.188075669","rc":[{"batb":[[0,1.68,227.02],[1,1.67,498.44],[2,1.66,11.1]],"batl":[[0,2.18,168.48],[1,2.2,211.15],[2,2.22,5.25]],"ltp":1.85,"tv":14897.35,"id":9631939},{"batb":[[0,1.84,211.17],[1,1.83,411.01],[2,1.82,46.14]],"ltp":2.28,"tv":1109.94,"id":9454286}]}]}
{"op":"mcm","clk":"4289849849","pt":1632494626212,"mc":[{"id":"1.188075669","rc":[{"batb":[[0,1.82,146],[1,1.68,369.29],[2,1.67,498.44]],"batl":[[2,2.22,99.49]],"ltp":1.85,"tv":14897.35,"id":9631939}]}]}
{"op":"mcm","clk":"4289849903","pt":1632494626797,"mc":[{"id":"1.188075669","rc":[{"batb":[[0,1.68,369.29],[1,1.67,498.44],[2,1.66,260.91]],"ltp":1.85,"tv":14897.35,"id":9631939}]}]}
{"op":"mcm","clk":"4289849958","pt":1632494627375,"mc":[{"id":"1.188075669","rc":[{"batl":[[0,2.18,172.48]],"ltp":1.85,"tv":14897.35,"id":9631939},{"batb":[[0,1.84,215.17],[1,1.83,416.01]],"ltp":2.28,"tv":1109.94,"id":9454286}]}]}
{"op":"mcm","clk":"4289850560","pt":1632494635794,"mc":[{"id":"1.188075669","rc":[{"trd":[[1.84,56.28]],"batb":[[0,1.84,187.03]],"ltp":1.84,"tv":1166.23,"id":9454286}],"tv":16063.59}]}
{"op":"mcm","clk":"4289850679","pt":1632494637525,"mc":[{"id":"1.188075669","rc":[{"batl":[[0,2.18,4],[1,2.22,5.25],[2,2.34,8.25]],"ltp":1.85,"tv":14897.35,"id":9631939},{"batb":[[0,1.84,4],[1,1.83,129.85]],"ltp":1.84,"tv":1166.23,"id":9454286}]}]}
{"op":"mcm","clk":"4289850892","pt":1632494640120,"mc":[{"id":"1.188075669","rc":[{"trd":[[1.68,37.88]],"batb":[[0,1.68,350.66]],"batl":[[0,1.72,3559.63],[1,2.18,4],[2,2.22,5.25]],"ltp":1.68,"tv":14934.62,"id":9631939},{"batb":[[0,2.36,3213.3],[1,2.34,497.88],[2,2.32,497.88]],"batl":[[0,2.46,11.02],[1,2.48,152.45],[2,2.5,196.08]],"ltp":1.84,"tv":1166.23,"id":9454286}],"tv":16100.85}]}
{"op":"mcm","clk":"4289850960","pt":1632494641128,"mc":[{"id":"1.188075669","rc":[{"batb":[[0,1.68,142.27],[2,1.66,1676.57]],"batl":[[0,1.72,77.26],[1,1.73,153.57],[2,1.75,210.78]],"ltp":1.68,"tv":14934.62,"id":9631939},{"batb":[[0,2.38,130.42],[1,2.36,823.48],[2,2.34,99.58]],"ltp":1.84,"tv":1166.23,"id":9454286}]}]}
{"op":"mcm","clk":"4289851040","pt":1632494642029,"mc":[{"id":"1.188075669","rc":[{"batb":[[2,1.66,544.05]],"ltp":1.68,"tv":14934.62,"id":9631939},{"trd":[[2.38,56.28]],"batb":[[0,2.38,102.28]],"ltp":2.38,"tv":1222.51,"id":9454286}],"tv":16157.13}]}
{"op":"mcm","clk":"4289851381","pt":1632494646138,"mc":[{"id":"1.188075669","rc":[{"batb":[[0,1.69,133],[1,1.68,142.27],[2,1.67,498.44]],"ltp":1.68,"tv":14934.62,"id":9631939}]}]}
{"op":"mcm","clk":"4289851515","pt":1632494647924,"mc":[{"id":"1.188075669","rc":[{"trd":[[2.38,112.56]],"batb":[[0,2.38,74.14]],"ltp":2.38,"tv":1278.79,"id":9454286}],"tv":16213.41}]}
{"op":"mcm","clk":"4289851599","pt":1632494649021,"mc":[{"id":"1.188075669","rc":[{"batb":[[0,1.69,280]],"ltp":1.68,"tv":14934.62,"id":9631939}]}]}
{"op":"mcm","clk":"4289851639","pt":1632494649551,"mc":[{"id":"1.188075669","rc":[{"batl":[[1,1.73,213.57]],"ltp":1.68,"tv":14934.62,"id":9631939},{"batb":[[0,2.38,85]],"ltp":2.38,"tv":1278.79,"id":9454286}]}]}
{"op":"mcm","clk":"4289852343","pt":1632494658872,"mc":[{"id":"1.188075669","rc":[{"trd":[[1.72,30.31]],"batl":[[0,1.72,77.16]],"ltp":1.72,"tv":14934.81,"id":9631939}],"tv":16213.61}]}
{"op":"mcm","clk":"4289852584","pt":1632494662043,"mc":[{"id":"1.188075669","rc":[{"trd":[[1.69,0.78]],"batb":[[0,1.69,279.61]],"ltp":1.69,"tv":14935.59,"id":9631939}],"tv":16214.39}]}
{"op":"mcm","clk":"4289852646","pt":1632494662771,"mc":[{"id":"1.188075669","rc":[{"trd":[[1.69,181.1]],"batb":[[0,1.69,189.45]],"ltp":1.69,"tv":15115.91,"id":9631939}],"tv":16394.71}]}
{"op":"mcm","clk":"4289852845","pt":1632494665180,"mc":[{"id":"1.188075669","rc":[{"batb":[[1,1.67,178.92],[2,1.66,11.1]],"batl":[[0,1.73,60],[1,1.96,202.69],[2,1.97,179.91]],"ltp":1.69,"tv":15115.91,"id":9631939},{"batb":[[1,2.04,214.83],[2,2.02,235.68]],"batl":[[0,2.78,120.16],[1,2.8,178.74],[2,3.3,195.4]],"ltp":2.38,"tv":1278.79,"id":9454286}]}]}
{"op":"mcm","clk":"4289852920","pt":1632494666075,"mc":[{"id":"1.188075669","rc":[{"batb":[[0,1.66,11.1],[1,1.59,10.29],[2,1.56,505.66]],"ltp":1.69,"tv":15115.91,"id":9631939},{"batb":[[0,2.38,10.86]],"ltp":2.38,"tv":1278.79,"id":9454286}]}]}
{"op":"mcm","clk":"4289852937","pt":1632494666285,"mc":[{"id":"1.188075669","rc":[{"batl":[[0,1.96,202.69],[1,1.97,179.91],[2,2.04,4.38]],"ltp":1.69,"tv":15115.91,"id":9631939},{"batb":[[0,2.04,214.83],[1,2.02,235.68],[2,2,186.26]],"ltp":2.38,"tv":1278.79,"id":9454286}]}]}
{"op":"mcm","clk":"4289853088","pt":1632494668182,"mc":[{"id":"1.188075669","rc":[{"batb":[[2,1.57,226.07]],"batl":[[2,2,106.96]],"ltp":1.69,"tv":15115.91,"id":9631939},{"batl":[[0,2.64,46.85],[1,2.78,120.16],[2,2.8,178.74]],"ltp":2.38,"tv":1278.79,"id":9454286}]}]}
{"op":"mcm","clk":"4289853110","pt":1632494668454,"mc":[{"id":"1.188075669","rc":[{"batl":[[0,2.78,120.16],[1,2.8,178.74],[2,3.3,195.4]],"ltp":2.38,"tv":1278.79,"id":9454286}]}]}
{"op":"mcm","clk":"4289854383","pt":1632494685908,"mc":[{"id":"1.188075669","rc":[{"batl":[[2,2.04,4.38]],"ltp":1.69,"tv":15115.91,"id":9631939}]}]}
{"op":"mcm","clk":"4289854564","pt":1632494688901,"mc":[{"id":"1.188075669","rc":[{"batb":[[0,1.72,199.87],[1,1.7,230.45],[2,1.66,11.1]],"batl":[[0,1.78,161.89],[1,1.8,192.52],[2,1.96,202.69]],"ltp":1.69,"tv":15115.91,"id":9631939}]}]}
{"op":"mcm","clk":"4289854796","pt":1632494692221,"mc":[{"id":"1.188075669","rc":[{"batb":[[0,2.06,115.13],[1,2.04,214.83],[2,2.02,235.68]],"batl":[[0,2.68,82.89],[1,2.78,120.16],[2,2.8,178.74]],"ltp":2.38,"tv":1278.79,"id":9454286}]}]}
{"op":"mcm","clk":"4289854987","pt":1632494694896,"mc":[{"id":"1.188075669","rc":[{"batb":[[0,1.66,11.1],[1,1.59,10.29],[2,1.57,226.07]],"batl":[[0,1.96,202.69],[1,1.97,179.91],[2,2.04,4.38]],"ltp":1.69,"tv":15115.91,"id":9631939},{"batb":[[0,2.04,214.83],[1,2.02,235.68],[2,2,186.26]],"batl":[[0,2.78,120.16],[1,2.8,178.74],[2,3.3,195.4]],"ltp":2.38,"tv":1278.79,"id":9454286}]}]}
{"op":"mcm","clk":"4289855184","pt":1632494697833,"mc":[{"id":"1.188075669","rc":[{"batl":[[2,2,106.96]],"ltp":1.69,"tv":15115.91,"id":9631939}]}]}
{"op":"mcm","clk":"4289855564","pt":1632494702715,"mc":[{"id":"1.188075669","rc":[{"batl":[[0,3.3,195.4],[1,810,0.07],[2,3.3,0]],"ltp":2.38,"tv":1278.79,"id":9454286}]}]}
{"op":"mcm","clk":"4289855664","pt":1632494703728,"mc":[{"id":"1.188075669","rc":[{"batl":[[0,810,0.07],[1,810,0]],"ltp":2.38,"tv":1278.79,"id":9454286}]}]}
{"op":"mcm","clk":"4289855889","pt":1632494706113,"mc":[{"id":"1.188075669","rc":[{"batb":[[0,1.93,166],[1,1.91,658.68],[2,1.9,485.94]],"batl":[[0,1.96,4],[1,1.98,9.14]],"ltp":1.69,"tv":15115.91,"id":9631939},{"batb":[[0,2.04,4],[1,2.02,238.68]],"batl":[[0,2.06,6.52],[1,2.46,12.2],[2,2.5,1668.1]],"ltp":2.38,"tv":1278.79,"id":9454286}]}]}
{"op":"mcm","clk":"4289855952","pt":1632494707017,"mc":[{"id":"1.188075669","rc":[{"trd":[[1.93,19.12],[1.94,6.92]],"batb":[[0,1.93,268.97]],"batl":[[0,1.98,9.14],[1,2,106.96],[2,2.02,488.48]],"ltp":1.93,"tv":15141.95,"id":9631939},{"trd":[[2.06,6.52]],"batb":[[0,2.02,235.68],[1,2,186.26],[2,1.97,524.57]],"batl":[[0,2.4,1.71]],"ltp":2.06,"tv":1285.31,"id":9454286}],"tv":16427.27}]}
{"op":"mcm","clk":"4289856018","pt":1632494707805,"mc":[{"id":"1.188075669","rc":[{"batl":[[0,1.98,69.14]],"ltp":1.93,"tv":15141.95,"id":9631939},{"batb":[[0,2.02,250.38]],"batl":[[0,2.24,53.88],[1,2.4,1.71],[2,2.46,12.2]],"ltp":2.06,"tv":1285.31,"id":9454286}]}]}
{"op":"mcm","clk":"4289856113","pt":1632494709026,"mc":[{"id":"1.188075669","rc":[{"batb":[[2,1.97,489.4]],"ltp":2.06,"tv":1285.31,"id":9454286}]}]}
{"op":"mcm","clk":"4289856239","pt":1632494710750,"mc":[{"id":"1.188075669","rc":[{"batl":[[0,2.4,1.71],[1,2.46,12.2],[2,2.5,1668.1]],"ltp":2.06,"tv":1285.31,"id":9454286}]}]}
{"op":"mcm","clk":"4289856430","pt":1632494713138,"mc":[{"id":"1.188075669","rc":[{"trd":[[1.93,19.32]],"batb":[[0,1.93,268.87]],"ltp":1.93,"tv":15142.15,"id":9631939},{"batl":[[0,2.22,1186.37],[1,2.4,1.71],[2,2.46,12.2]],"ltp":2.06,"tv":1285.31,"id":9454286}],"tv":16427.47}]}
{"op":"mcm","clk":"4289856502","pt":1632494713923,"mc":[{"id":"1.188075669","rc":[{"batl":[[0,2.22,1167.58]],"ltp":2.06,"tv":1285.31,"id":9454286}]}]}
{"op":"mcm","clk":"4289856694","pt":1632494716545,"mc":[{"id":"1.188075669","rc":[{"batl":[[0,1.98,60]],"ltp":1.93,"tv":15142.15,"id":9631939},{"batl":[[0,2.2,73.11],[1,2.22,1167.58],[2,2.4,1.71]],"ltp":2.06,"tv":1285.31,"id":9454286}]}]}
{"op":"mcm","clk":"4289856743","pt":1632494717278,"mc":[{"id":"1.188075669","rc":[{"batl":[[2,2.46,12.2]],"ltp":2.06,"tv":1285.31,"id":9454286}]}]}
{"op":"mcm","clk":"4289856906","pt":1632494719866,"mc":[{"id":"1.188075669","rc":[{"batl":[[0,1.96,7.37],[1,1.98,60],[2,2,106.96]],"ltp":1.93,"tv":15142.15,"id":9631939},{"batl":[[0,2.08,7.45],[1,2.2,73.11],[2,2.22,54.32]],"ltp":2.06,"tv":1285.31,"id":9454286}]}]}
{"op":"mcm","clk":"4289856985","pt":1632494720965,"mc":[{"id":"1.188075669","rc":[{"trd":[[1.93,20]],"batb":[[0,1.93,268.53]],"ltp":1.93,"tv":15142.83,"id":9631939}],"tv":16428.15}]}
{"op":"mcm","clk":"4289857132","pt":1632494722783,"mc":[{"id":"1.188075669","rc":[{"batb":[[0,1.93,402.53]],"ltp":1.93,"tv":15142.83,"id":9631939}]}]}
{"op":"mcm","clk":"4289857556","pt":1632494727762,"mc":[{"id":"1.188075669","rc":[{"batb":[[0,1.69,171.92],[1,1.66,11.1],[2,1.59,10.29]],"batl":[[0,1.98,60],[1,3,2.27],[2,3.35,2.3]],"ltp":1.93,"tv":15142.83,"id":9631939},{"batb":[[0,2.02,14.7],[1,1.7,416.74],[2,1.59,200.18]],"batl":[[0,2.22,54.32],[1,2.82,235.47],[2,880,0.01]],"ltp":2.06,"tv":1285.31,"id":9454286}]}]}
{"op":"mcm","clk":"4289857703","pt":1632494729693,"mc":[{"id":"1.188075669","rc":[{"batl":[[0,3,2.27],[1,3.35,2.3],[2,3.35,0]],"ltp":1.93,"tv":15142.83,"id":9631939},{"batb":[[0,1.7,416.74],[1,1.59,200.18],[2,1.53,3.42]],"batl":[[0,2.82,235.47],[1,880,0.01],[2,880,0]],"ltp":2.06,"tv":1285.31,"id":9454286}]}]}
{"op":"mcm","clk":"4289857841","pt":1632494731155,"mc":[{"id":"1.188075669","rc":[{"trd":[[1.93,20.46]],"batb":[[0,1.69,346.96],[1,1.67,244.84],[2,1.66,11.1]],"batl":[[0,2.7,78.76],[1,2.74,119.39],[2,3,2.27]],"ltp":1.93,"tv":15143.29,"id":9631939},{"trd":[[2.06,6.95]],"ltp":2.06,"tv":1285.74,"id":9454286}],"tv":16429.03}]}
{"op":"mcm","clk":"4289857905","pt":1632494731994,"mc":[{"id":"1.188075669","rc":[{"batl":[[0,3,2.44],[1,3.35,2.3],[2,3,0]],"ltp":1.93,"tv":15143.29,"id":9631939}]}]}
{"op":"mcm","clk":"4289857991","pt":1632494733194,"mc":[{"id":"1.188075669","rc":[{"batl":[[0,1.93,0.17],[1,3.35,0]],"ltp":1.93,"tv":15143.29,"id":9631939},{"batb":[[0,1.59,200.18],[1,1.53,3.42],[2,1.43,40.43]],"batl":[[0,880,0.01],[1,880,0]],"ltp":2.06,"tv":1285.74,"id":9454286}]}]}
{"op":"mcm","clk":"4289858066","pt":1632494734204,"mc":[{"id":"1.188075669","rc":[{"trd":[[1.93,20.8]],"batb":[[2,1.59,10.29]],"ltp":1.93,"tv":15143.63,"id":9631939}],"tv":16429.37}]}
{"op":"mcm","clk":"4289858125","pt":1632494735190,"mc":[{"id":"1.188075669","rc":[{"trd":[[1.69,218.14]],"batb":[[0,1.7,10.08],[1,1.69,333.44],[2,1.68,5]],"batl":[[0,1.72,605.93],[1,1.75,217.13],[2,1.77,202.84]],"ltp":1.69,"tv":15180.67,"id":9631939},{"batb":[[0,2.38,14.46],[1,2.36,10.04],[2,2.32,202.58]],"batl":[[0,2.46,3],[1,2.56,309.59],[2,880,0.01]],"ltp":2.06,"tv":1285.74,"id":9454286}],"tv":16466.42}]}
{"op":"mcm","clk":"4289858185","pt":1632494736190,"mc":[{"id":"1.188075669","rc":[{"batb":[[1,1.69,328.44],[2,1.68,279.76]],"batl":[[2,1.76,60]],"ltp":1.69,"tv":15180.67,"id":9631939},{"batb":[[2,2.34,119.03]],"batl":[[0,2.56,309.59],[1,2.64,46.85],[2,2.86,1.71]],"ltp":2.06,"tv":1285.74,"id":9454286}]}]}
{"op":"mcm","clk":"4289858262","pt":1632494737760,"mc":[{"id":"1.188075669","rc":[{"batl":[[0,2.54,37.28],[1,2.56,309.59],[2,2.64,46.85]],"ltp":2.06,"tv":1285.74,"id":9454286}]}]}
{"op":"mcm","clk":"4289858426","pt":1632494740181,"mc":[{"id":"1.188075669","rc":[{"batl":[[2,1.77,202.84]],"ltp":1.69,"tv":15180.67,"id":9631939},{"batl":[[2,2.86,1.71]],"ltp":2.06,"tv":1285.74,"id":9454286}]}]}
{"op":"mcm","clk":"4289858488","pt":1632494741015,"mc":[{"id":"1.188075669","rc":[{"trd":[[1.72,540.29]],"batl":[[0,1.72,350.94]],"ltp":1.72,"tv":15690.65,"id":9631939}],"tv":16976.4}]}
{"op":"mcm","clk":"4289858549","pt":1632494741905,"mc":[{"id":"1.188075669","rc":[{"batl":[[2,2.76,129.13]],"ltp":2.06,"tv":1285.74,"id":9454286}]}]}
{"op":"mcm","clk":"4289858636","pt":1632494743109,"mc":[{"id":"1.188075669","rc":[{"trd":[[1.72,540.49]],"batl":[[0,1.72,350.84],[1,1.75,277.13]],"ltp":1.72,"tv":15690.85,"id":9631939},{"batb":[[2,2.34,130.22]],"batl":[[2,2.6,47.43]],"ltp":2.06,"tv":1285.74,"id":9454286}],"tv":16976.59}]}
{"op":"mcm","clk":"4289858730","pt":1632494744630,"mc":[{"id":"1.188075669","rc":[{"trd":[[1.7,58.02],[1.72,541.16]],"batb":[[0,1.7,209.08]],"batl":[[0,1.72,350.5]],"ltp":1.72,"tv":15701.52,"id":9631939}],"tv":16987.27}]}
{"op":"mcm","clk":"4289858939","pt":1632494748025,"mc":[{"id":"1.188075669","rc":[{"trd":[[1.72,542.42]],"batl":[[0,1.72,349.87]],"ltp":1.72,"tv":15702.78,"id":9631939}],"tv":16988.53}]}
{"op":"mcm","clk":"4289859142","pt":1632494751007,"mc":[{"id":"1.188075669","rc":[{"batb":[[0,1.59,6.89],[1,1.58,218.48],[2,1.57,216.56]],"batl":[[0,1.75,60],[1,1.97,229.56],[2,1.98,216.5]],"ltp":1.72,"tv":15702.78,"id":9631939},{"batb":[[0,2.34,11.19],[1,2.02,193.06],[2,2,183.64]],"batl":[[0,2.6,47.43],[1,2.76,129.13],[2,2.78,187.94]],"ltp":2.06,"tv":1285.74,"id":9454286}]}]}
{"op":"mcm","clk":"4289859177","pt":1632494751527,"mc":[{"id":"1.188075669","rc":[{"batl":[[1,1.97,231.91]],"ltp":1.72,"tv":15702.78,"id":9631939}]}]}
{"op":"mcm","clk":"4289859238","pt":1632494752315,"mc":[{"id":"1.188075669","rc":[{"batl":[[0,1.97,231.91],[1,1.98,216.5],[2,2.06,3.92]],"ltp":1.72,"tv":15702.78,"id":9631939},{"batb":[[0,2.02,193.06],[1,2,183.64],[2,1.98,194.61]],"batl":[[0,2.76,129.13],[1,2.78,187.94],[2,3.3,195.4]],"ltp":2.06,"tv":1285.74,"id":9454286}]}]}
{"op":"mcm","clk":"4289859428","pt":1632494754209,"mc":[{"id":"1.188075669","rc":[{"batb":[[0,1.62,76.2],[1,1.59,6.89],[2,1.58,218.48]],"batl":[[2,2.02,115.55]],"ltp":1.72,"tv":15702.78,"id":9631939},{"batb":[[2,1.99,193.93]],"ltp":2.06,"tv":1285.74,"id":9454286}]}]}
{"op":"mcm","clk":"4289859456","pt":1632494754519,"mc":[{"id":"1.188075669","rc":[{"batb":[[0,1.59,6.89],[1,1.58,218.48],[2,1.57,462.96]],"ltp":1.72,"tv":15702.78,"id":9631939}]}]}
{"op":"mcm","clk":"4289859532","pt":1632494755522,"mc":[{"id":"1.188075669","rc":[{"batb":[[0,1.59,12.89],[1,1.58,223.48]],"batl":[[0,1.97,235.91]],"ltp":1.72,"tv":15702.78,"id":9631939},{"batl":[[0,2.7,3],[1,2.76,129.13],[2,2.78,187.94]],"ltp":2.06,"tv":1285.74,"id":9454286}]}]}
{"op":"mcm","clk":"4289859686","pt":1632494757799,"mc":[{"id":"1.188075669","rc":[{"batb":[[2,1.3,176.04]],"ltp":1.72,"tv":15702.78,"id":9631939},{"batl":[[1,3.3,195.4],[2,880,0.01]],"ltp":2.06,"tv":1285.74,"id":9454286}]}]}
{"op":"mcm","clk":"4289859814","pt":1632494759790,"mc":[{"id":"1.188075669","rc":[{"batl":[[0,1.97,231.91]],"ltp":1.72,"tv":15702.78,"id":9631939},{"batl":[[1,880,0.01],[2,880,0]],"ltp":2.06,"tv":1285.74,"id":9454286}]}]}
{"op":"mcm","clk":"4289859920","pt":1632494761207,"mc":[{"id":"1.188075669","rc":[{"batb":[[0,1.95,143.95],[1,1.94,7.94],[2,1.93,153]],"batl":[[0,1.97,2.35],[1,1.98,9.67]],"ltp":1.72,"tv":15702.78,"id":9631939},{"batb":[[0,2,183.64],[1,1.99,193.93],[2,1.95,33.31]],"batl":[[0,2.3,1.71],[1,2.44,12.3],[2,2.5,1813.21]],"ltp":2.06,"tv":1285.74,"id":9454286}]}]}
{"op":"mcm","clk":"4289859997","pt":1632494762202,"mc":[{"id":"1.188075669","rc":[{"trd":[[1.95,32.78]],"batb":[[0,1.95,236.46]],"batl":[[2,1.99,60]],"ltp":1.95,"tv":15735.56,"id":9631939},{"batb":[[0,2,198.64]],"batl":[[0,2.24,53.88],[1,2.3,1.71],[2,2.44,12.3]],"ltp":2.06,"tv":1285.74,"id":9454286}],"tv":17021.31}]}
{"op":"mcm","clk":"4289860062","pt":1632494762939,"mc":[{"id":"1.188075669","rc":[{"batl":[[2,2.02,115.55]],"ltp":1.95,"tv":15735.56,"id":9631939},{"batl":[[0,2.28,15]],"ltp":2.06,"tv":1285.74,"id":9454286}]}]}
{"op":"mcm","clk":"4289860129","pt":1632494763727,"mc":[{"id":"1.188075669","rc":[{"batl":[[2,2.42,3]],"ltp":2.06,"tv":1285.74,"id":9454286}]}]}
{"op":"mcm","clk":"4289860325","pt":1632494766135,"mc":[{"id":"1.188075669","rc":[{"batb":[[0,1.95,341.46]],"batl":[[2,2.02,174.95]],"ltp":1.95,"tv":15735.56,"id":9631939},{"batl":[[0,2.22,54.32]],"ltp":2.06,"tv":1285.74,"id":9454286}]}]}
{"op":"mcm","clk":"4289860586","pt":1632494770010,"mc":[{"id":"1.188075669","rc":[{"trd":[[1.95,33.12]],"batb":[[0,1.95,341.29]],"ltp":1.95,"tv":15735.9,"id":9631939}],"tv":17021.65}]}
{"op":"mcm","clk":"4289860664","pt":1632494771209,"mc":[{"id":"1.188075669","rc":[{"batl":[[1,2.42,3],[2,2.44,12.3]],"ltp":2.06,"tv":1285.74,"id":9454286}]}]}
{"op":"mcm","clk":"4289860847","pt":1632494773827,"mc":[{"id":"1.188075669","rc":[{"trd":[[1.95,34.38]],"batb":[[0,1.95,340.66]],"ltp":1.95,"tv":15737.16,"id":9631939}],"tv":17022.91}]}
{"op":"mcm","clk":"4289860914","pt":1632494775023,"mc":[{"id":"1.188075669","rc":[{"batl":[[0,2.18,1326.85],[1,2.22,54.32],[2,2.42,3]],"ltp":2.06,"tv":1285.74,"id":9454286}]}]}
{"op":"mcm","clk":"4289860977","pt":1632494775971,"mc":[{"id":"1.188075669","rc":[{"trd":[[1.95,40.46]],"batb":[[0,1.95,337.62]],"ltp":1.95,"tv":15743.24,"id":9631939},{"batl":[[0,2.22,54.32],[1,2.42,3],[2,2.44,12.3]],"ltp":2.06,"tv":1285.74,"id":9454286}],"tv":17028.99}]}
{"op":"mcm","clk":"4289861084","pt":1632494777368,"mc":[{"id":"1.188075669","rc":[{"trd":[[1.95,44.36]],"batb":[[0,1.95,335.67]],"ltp":1.95,"tv":15747.14,"id":9631939}],"tv":17032.89}]}
{"op":"mcm","clk":"4289861304","pt":1632494780660,"mc":[{"id":"1.188075669","rc":[{"batl":[[2,2.02,187.88]],"ltp":1.95,"tv":15747.14,"id":9631939}]}]}
{"op":"mcm","clk":"4289861418","pt":1632494782173,"mc":[{"id":"1.188075669","rc":[{"batl":[[0,2.2,74.99],[1,2.22,54.32],[2,2.42,3]],"ltp":2.06,"tv":1285.74,"id":9454286}]}]}
{"op":"mcm","clk":"4289861495","pt":1632494783174,"mc":[{"id":"1.188075669","rc":[{"batb":[[0,1.71,166.86],[1,1.6,6],[2,1.59,6.89]],"batl":[[1,2.02,59.4],[2,3.05,2.3]],"ltp":1.95,"tv":15747.14,"id":9631939},{"batb":[[0,2,15],[1,1.58,204.9],[2,1.53,3.42]],"batl":[[0,2.22,54.32],[1,880,0.01],[2,2.42,0]],"ltp":2.06,"tv":1285.74,"id":9454286}]}]}
{"op":"mcm","clk":"4289861507","pt":1632494783279,"mc":[{"id":"1.188075669","rc":[{"batl":[[1,3.05,2.3],[2,3.4,2.19]],"ltp":1.95,"tv":15747.14,"id":9631939},{"batb":[[0,1.58,204.9],[1,1.53,3.42],[2,1.49,41.01]],"batl":[[0,880,0.01],[1,880,0]],"ltp":2.06,"tv":1285.74,"id":9454286}]}]}
{"op":"mcm","clk":"4289861714","pt":1632494785958,"mc":[{"id":"1.188075669","rc":[{"batb":[[1,1.7,194.69],[2,1.68,239.95]],"batl":[[1,2.74,127.12],[2,2.78,115.32]],"ltp":1.95,"tv":15747.14,"id":9631939}]}]}
{"op":"mcm","clk":"4289861904","pt":1632494788902,"mc":[{"id":"1.188075669","rc":[{"batl":[[1,2.74,0],[2,2.78,0]],"ltp":1.95,"tv":15747.14,"id":9631939},{"batb":[[2,1.42,43.44]],"ltp":2.06,"tv":1285.74,"id":9454286}]}]}
{"op":"mcm","clk":"4289862127","pt":1632494792097,"mc":[{"id":"1.188075669","rc":[{"trd":[[1.71,165.94]],"batb":[[0,1.71,148.46]],"batl":[[0,1.74,9.42],[1,1.76,187.58],[2,1.78,199.36]],"ltp":1.71,"tv":15783.94,"id":9631939},{"batb":[[0,2.3,415.76],[1,2.28,403.54],[2,2.26,403.54]],"batl":[[0,2.42,10.27],[1,880,0.01]],"ltp":2.06,"tv":1285.74,"id":9454286}],"tv":17069.69}]}
{"op":"mcm","clk":"4289862209","pt":1632494793198,"mc":[{"id":"1.188075669","rc":[{"batl":[[0,1.72,2.92],[1,1.74,9.42],[2,1.76,187.58]],"ltp":1.71,"tv":15783.94,"id":9631939},{"batb":[[0,2.32,123.07],[1,2.3,415.76],[2,2.28,415.25]],"batl":[[1,2.6,47.43],[2,2.66,1.71]],"ltp":2.06,"tv":1285.74,"id":9454286}]}]}
{"op":"mcm","clk":"4289862246","pt":1632494793777,"mc":[{"id":"1.188075669","rc":[{"batl":[[1,2.66,1.71],[2,2.9,10.34]],"ltp":2.06,"tv":1285.74,"id":9454286}]}]}
{"op":"mcm","clk":"4289862449","pt":1632494796658,"mc":[{"id":"1.188075669","rc":[{"batl":[[0,1.74,9.42],[1,1.76,187.58],[2,1.78,199.36]],"ltp":1.71,"tv":15783.94,"id":9631939},{"batb":[[2,2.28,403.54]],"batl":[[1,2.56,48.03],[2,2.66,1.71]],"ltp":2.06,"tv":1285.74,"id":9454286}]}]}
