{"op":"mcm","clk":"4289988901","pt":1632496230210,"mc":[{"id":"1.188075669","rc":[{"trd":[[1.88,253.73]],"batl":[[0,1.88,15.06]],"ltp":1.88,"tv":20454.54,"id":9631939}],"tv":26375.22}]}
{"op":"mcm","clk":"4289989009","pt":1632496231208,"mc":[{"id":"1.188075669","rc":[{"trd":[[1.88,265.12]],"batl":[[0,1.88,3.67]],"ltp":1.88,"tv":20465.93,"id":9631939},{"trd":[[2.12,144.27]],"ltp":2.12,"tv":5930.76,"id":9454286}],"tv":26396.69}]}
{"op":"mcm","clk":"4289989221","pt":1632496233575,"mc":[{"id":"1.188075669","rc":[{"trd":[[1.87,492.88]],"batb":[[0,1.87,284.73]],"ltp":1.87,"tv":20474.88,"id":9631939}],"tv":26405.64}]}
{"op":"mcm","clk":"4289989433","pt":1632496235993,"mc":[{"id":"1.188075669","rc":[{"trd":[[1.87,498.33]],"batb":[[0,1.87,282]],"ltp":1.87,"tv":20480.34,"id":9631939}],"tv":26411.1}]}
{"op":"mcm","clk":"4289989525","pt":1632496237005,"mc":[{"id":"1.188075669","rc":[{"trd":[[1.88,271.14],[1.89,173.91]],"batl":[[0,1.89,12.01],[1,1.9,216.7],[2,1.92,557.2]],"ltp":1.89,"tv":20488.47,"id":9631939},{"trd":[[2.12,147.33]],"ltp":2.12,"tv":5933.82,"id":9454286}],"tv":26422.3}]}
{"op":"mcm","clk":"4289990389","pt":1632496247499,"mc":[{"id":"1.188075669","rc":[{"batl":[[0,1.9,216.7],[1,1.92,557.2],[2,1.94,154.12]],"ltp":1.89,"tv":20488.47,"id":9631939},{"batl":[[0,2.22,54.32],[1,2.24,235.9],[2,2.26,138.25]],"ltp":2.12,"tv":5933.82,"id":9454286}]}]}
{"op":"mcm","clk":"4289990474","pt":1632496248638,"mc":[{"id":"1.188075669","rc":[{"batb":[[2,1.83,522.54]],"batl":[[1,1.92,391.35],[2,1.95,490.38]],"ltp":1.89,"tv":20488.47,"id":9631939}]}]}
{"op":"mcm","clk":"4289990597","pt":1632496250219,"mc":[{"id":"1.188075669","rc":[{"batb":[[2,1.82,66.25]],"batl":[[0,1.89,12.01],[1,1.9,216.7],[2,1.92,391.35]],"ltp":1.89,"tv":20488.47,"id":9631939},{"batl":[[0,2.2,14.51],[1,2.22,54.32],[2,2.24,235.9]],"ltp":2.12,"tv":5933.82,"id":9454286}]}]}
{"op":"mcm","clk":"4289990664","pt":1632496251112,"mc":[{"id":"1.188075669","rc":[{"batb":[[0,1.82,66.25],[1,1.8,139.36],[2,1.79,196.65]],"batl":[[0,1.99,4],[1,2.02,187.6],[2,2.04,183.14]],"ltp":1.89,"tv":20488.47,"id":9631939},{"batb":[[0,1.99,205.92],[1,1.98,237.22],[2,1.97,11.17]],"batl":[[0,2.22,54.32],[1,2.26,138.35],[2,2.28,189.37]],"ltp":2.12,"tv":5933.82,"id":9454286}]}]}
{"op":"mcm","clk":"4289990698","pt":1632496251528,"mc":[{"id":"1.188075669","rc":[{"batb":[[2,1.79,337.04]],"ltp":1.89,"tv":20488.47,"id":9631939}]}]}
{"op":"mcm","clk":"4289990751","pt":1632496252313,"mc":[{"id":"1.188075669","rc":[{"batb":[[0,1.8,139.36],[1,1.79,337.04],[2,1.78,223.76]],"ltp":1.89,"tv":20488.47,"id":9631939},{"batl":[[0,2.26,138.35],[1,2.28,189.37],[2,2.32,4]],"ltp":2.12,"tv":5933.82,"id":9454286}]}]}
{"op":"mcm","clk":"4289990869","pt":1632496253936,"mc":[{"id":"1.188075669","rc":[{"batb":[[0,1.79,337.04],[1,1.78,223.76],[2,1.77,343.65]],"ltp":1.89,"tv":20488.47,"id":9631939},{"batb":[[0,2,5],[1,1.99,209.92],[2,1.98,237.22]],"ltp":2.12,"tv":5933.82,"id":9454286}]}]}
{"op":"mcm","clk":"4289990917","pt":1632496254612,"mc":[{"id":"1.188075669","rc":[{"batb":[[0,1.79,337.08]],"ltp":1.89,"tv":20488.47,"id":9631939},{"batb":[[2,1.98,240.22]],"ltp":2.12,"tv":5933.82,"id":9454286}]}]}
{"op":"mcm","clk":"4289991176","pt":1632496257821,"mc":[{"id":"1.188075669","rc":[{"batl":[[1,2,11.72],[2,2.02,187.6]],"ltp":1.89,"tv":20488.47,"id":9631939},{"batb":[[0,2,15.84]],"ltp":2.12,"tv":5933.82,"id":9454286}]}]}
{"op":"mcm","clk":"4289991288","pt":1632496259163,"mc":[{"id":"1.188075669","rc":[{"batb":[[0,1.78,13.7],[1,1.77,141.21],[2,1.76,4]],"batl":[[1,2.02,187.6],[2,2.04,183.14]],"ltp":1.89,"tv":20488.47,"id":9631939},{"batb":[[0,2,5]],"batl":[[0,2.32,4.09],[1,2.34,3.25],[2,2.36,3.07]],"ltp":2.12,"tv":5933.82,"id":9454286}]}]}
{"op":"mcm","clk":"4289991297","pt":1632496259243,"mc":[{"id":"1.188075669","rc":[{"batb":[[0,1.77,141.25],[1,1.76,4],[2,1.75,17.87]],"ltp":1.89,"tv":20488.47,"id":9631939}]}]}
{"op":"mcm","clk":"4289991425","pt":1632496261126,"mc":[{"id":"1.188075669","rc":[{"batl":[[0,2.02,187.6],[1,2.04,183.14],[2,990,0.35]],"ltp":1.89,"tv":20488.47,"id":9631939},{"batb":[[0,1.99,205.92],[1,1.98,237.22],[2,1.97,11.17]],"ltp":2.12,"tv":5933.82,"id":9454286}]}]}
{"op":"mcm","clk":"4289991507","pt":1632496262177,"mc":[{"id":"1.188075669","rc":[{"batb":[[0,1.97,477.16],[1,1.93,32.13],[2,1.77,141.21]],"batl":[[0,2.02,10.92],[2,2.06,347.26]],"ltp":1.89,"tv":20488.47,"id":9631939},{"batb":[[0,1.97,11.17],[1,1.95,228.61],[2,1.93,153.75]],"batl":[[0,2.02,132.99],[1,2.04,376.25],[2,2.06,115.2]],"ltp":2.12,"tv":5933.82,"id":9454286}]}]}
{"op":"mcm","clk":"4289991580","pt":1632496263068,"mc":[{"id":"1.188075669","rc":[{"trd":[[1.98,15.15]],"batb":[[1,1.96,102.58],[2,1.93,32.13]],"ltp":1.98,"tv":20503.62,"id":9631939},{"trd":[[2.02,17.23]],"batb":[[2,1.93,397.27]],"batl":[[0,2.02,118.14]],"ltp":2.02,"tv":5948.67,"id":9454286}],"tv":26452.3}]}
{"op":"mcm","clk":"4289991661","pt":1632496263964,"mc":[{"id":"1.188075669","rc":[{"batb":[[2,1.93,94.34]],"ltp":1.98,"tv":20503.62,"id":9631939}]}]}
{"op":"mcm","clk":"4289991934","pt":1632496267163,"mc":[{"id":"1.188075669","rc":[{"batb":[[0,1.99,207],[1,1.97,477.16],[2,1.96,102.58]],"ltp":1.98,"tv":20503.62,"id":9631939}]}]}
{"op":"mcm","clk":"4289992293","pt":1632496271138,"mc":[{"id":"1.188075669","rc":[{"trd":[[1.99,4.12]],"batb":[[0,1.99,316.9]],"ltp":1.99,"tv":20503.82,"id":9631939},{"batl":[[2,2.06,173.47]],"ltp":2.02,"tv":5948.67,"id":9454286}],"tv":26452.49}]}
{"op":"mcm","clk":"4289992416","pt":1632496272444,"mc":[{"id":"1.188075669","rc":[{"trd":[[1.99,4.37]],"batb":[[0,1.99,316.77]],"ltp":1.99,"tv":20504.08,"id":9631939}],"tv":26452.75}]}
{"op":"mcm","clk":"4289992743","pt":1632496276083,"mc":[{"id":"1.188075669","rc":[{"batl":[[0,2.04,376.25],[1,2.06,173.47],[2,2.08,115.2]],"ltp":2.02,"tv":5948.67,"id":9454286}]}]}
{"op":"mcm","clk":"4289993004","pt":1632496279083,"mc":[{"id":"1.188075669","rc":[{"trd":[[2.02,0.3]],"batl":[[0,2.02,10.62]],"ltp":2.02,"tv":20504.38,"id":9631939},{"trd":[[1.98,0.31]],"batb":[[1,1.95,280.15]],"batl":[[0,2.04,458.78],[1,2.06,302.43]],"ltp":1.98,"tv":5948.98,"id":9454286}],"tv":26453.36}]}
{"op":"mcm","clk":"4289993098","pt":1632496280094,"mc":[{"id":"1.188075669","rc":[{"batb":[[0,1.95,61.55],[1,1.9,219.55],[2,1.89,256.94]],"batl":[[0,2.22,4.09],[1,2.24,196.9],[2,2.26,199.62]],"ltp":2.02,"tv":20504.38,"id":9631939},{"batb":[[0,1.88,63.96],[1,1.83,13.56],[2,1.82,14.64]],"batl":[[0,2.06,58.27],[1,2.12,176.79],[2,2.14,228.76]],"ltp":1.98,"tv":5948.98,"id":9454286}]}]}
{"op":"mcm","clk":"4289993271","pt":1632496281986,"mc":[{"id":"1.188075669","rc":[{"batb":[[0,1.9,219.55],[1,1.89,256.94],[2,1.87,119.7]],"batl":[[0,1.99,96.3],[1,2.24,197.25]],"ltp":2.02,"tv":20504.38,"id":9631939},{"batb":[[0,1.81,207.59],[1,1.8,300.67],[2,1.79,134.97]],"batl":[[0,2.12,176.79],[1,2.14,228.76],[2,2.18,3.25]],"ltp":1.98,"tv":5948.98,"id":9454286}]}]}
{"op":"mcm","clk":"4289993388","pt":1632496283188,"mc":[{"id":"1.188075669","rc":[{"batb":[[2,1.79,336.95]],"batl":[[1,2.14,364.39],[2,2.16,112.35]],"ltp":1.98,"tv":5948.98,"id":9454286}]}]}
{"op":"mcm","clk":"4289993580","pt":1632496285185,"mc":[{"id":"1.188075669","rc":[{"batl":[[0,1.99,90.16],[1,2.22,8.09],[2,2.24,200.9]],"ltp":2.02,"tv":20504.38,"id":9631939},{"batb":[[0,1.83,19.56],[1,1.82,17.64],[2,1.81,212.59]],"ltp":1.98,"tv":5948.98,"id":9454286}]}]}
{"op":"mcm","clk":"4289993643","pt":1632496285966,"mc":[{"id":"1.188075669","rc":[{"batl":[[0,1.99,90.55]],"ltp":2.02,"tv":20504.38,"id":9631939}]}]}
{"op":"mcm","clk":"4289993854","pt":1632496288002,"mc":[{"id":"1.188075669","rc":[{"batl":[[0,2.22,4.73],[1,2.24,4],[2,2.3,3.05]],"ltp":2.02,"tv":20504.38,"id":9631939},{"batb":[[0,1.83,5],[1,1.82,4],[2,1.81,5]],"batl":[[1,2.14,228.76],[2,2.18,3.25]],"ltp":1.98,"tv":5948.98,"id":9454286}]}]}
{"op":"mcm","clk":"4289994070","pt":1632496290187,"mc":[{"id":"1.188075669","rc":[{"trd":[[1.9,94.62]],"batb":[[0,1.9,203.77]],"batl":[[0,1.92,8.72],[1,1.96,1951.54],[2,1.97,1894.14]],"ltp":1.9,"tv":20535.94,"id":9631939},{"batb":[[0,2.04,2555.34],[1,1.83,5],[2,1.82,4]],"batl":[[2,2.16,17.25]],"ltp":1.98,"tv":5948.98,"id":9454286}],"tv":26484.93}]}
{"op":"mcm","clk":"4289994174","pt":1632496291185,"mc":[{"id":"1.188075669","rc":[{"batb":[[0,1.88,130.69],[1,1.87,119.7],[2,1.86,188.64]],"batl":[[0,1.93,2],[1,1.95,175.32],[2,1.96,487.88]],"ltp":1.9,"tv":20535.94,"id":9631939},{"batb":[[0,2.06,2],[1,2.04,378.85],[2,1.92,32.3]],"batl":[[0,2.14,228.76],[1,2.18,3.25],[2,2.2,257.9]],"ltp":1.98,"tv":5948.98,"id":9454286}]}]}
{"op":"mcm","clk":"4289994285","pt":1632496292185,"mc":[{"id":"1.188075669","rc":[{"batb":[[2,1.98,60.6]],"batl":[[1,2.18,58.48]],"ltp":1.98,"tv":5948.98,"id":9454286}]}]}
{"op":"mcm","clk":"4289994482","pt":1632496293974,"mc":[{"id":"1.188075669","rc":[{"batl":[[0,1.92,8.72],[1,1.93,2],[2,1.95,175.32]],"ltp":1.9,"tv":20535.94,"id":9631939},{"batl":[[1,2.16,17.25],[2,2.18,58.48]],"ltp":1.98,"tv":5948.98,"id":9454286}]}]}
{"op":"mcm","clk":"4289994585","pt":1632496295130,"mc":[{"id":"1.188075669","rc":[{"batl":[[0,2.1,20.03],[1,2.14,228.76],[2,2.16,17.25]],"ltp":1.98,"tv":5948.98,"id":9454286}]}]}
{"op":"mcm","clk":"4289994667","pt":1632496295915,"mc":[{"id":"1.188075669","rc":[{"batl":[[0,2.14,228.76],[1,2.16,17.25],[2,2.18,58.48]],"ltp":1.98,"tv":5948.98,"id":9454286}]}]}
{"op":"mcm","clk":"4289995110","pt":1632496298810,"mc":[{"id":"1.188075669","rc":[{"trd":[[1.88,275.83]],"batb":[[0,1.88,128.34]],"ltp":1.88,"tv":20540.63,"id":9631939}],"tv":26489.62}]}
{"op":"mcm","clk":"4289995415","pt":1632496301214,"mc":[{"id":"1.188075669","rc":[{"trd":[[1.92,11.47]],"batl":[[0,1.92,8.56]],"ltp":1.92,"tv":20540.95,"id":9631939}],"tv":26489.94}]}
{"op":"mcm","clk":"4289995509","pt":1632496302202,"mc":[{"id":"1.188075669","rc":[{"batb":[[1,2.04,176.05]],"ltp":1.98,"tv":5948.98,"id":9454286}]}]}
{"op":"mcm","clk":"4289996272","pt":1632496311014,"mc":[{"id":"1.188075669","rc":[{"batb":[[0,1.85,65.07],[1,1.82,16.14],[2,1.81,14.29]],"batl":[[0,2.02,59.4],[1,2.06,3.75],[2,2.08,205.08]],"ltp":1.92,"tv":20540.95,"id":9631939},{"batb":[[0,1.98,60.6],[1,1.95,12.11],[2,1.93,186.46]],"batl":[[0,2.18,55.23],[1,2.22,3.75],[2,2.26,160.6]],"ltp":1.98,"tv":5948.98,"id":9454286}]}]}
{"op":"mcm","clk":"4289996478","pt":1632496313148,"mc":[{"id":"1.188075669","rc":[{"batb":[[0,1.8,174.37],[1,1.79,403.44],[2,1.78,4]],"batl":[[0,2.08,205.08],[1,2.1,226.12],[2,2.12,3.21]],"ltp":1.92,"tv":20540.95,"id":9631939},{"batb":[[0,1.93,186.46],[1,1.92,205.48],[2,1.9,13.26]],"batl":[[0,2.26,160.6],[1,2.28,190.68],[2,2.5,281.33]],"ltp":1.98,"tv":5948.98,"id":9454286}]}]}
{"op":"mcm","clk":"4289996537","pt":1632496313830,"mc":[{"id":"1.188075669","rc":[{"batb":[[0,1.8,329.79],[2,1.78,202.66]],"batl":[[2,2.12,151.06]],"ltp":1.92,"tv":20540.95,"id":9631939}]}]}
{"op":"mcm","clk":"4289996677","pt":1632496315613,"mc":[{"id":"1.188075669","rc":[{"batl":[[0,2.06,4],[1,2.12,3.55],[2,2.22,4]],"ltp":1.92,"tv":20540.95,"id":9631939},{"batb":[[0,1.95,4],[1,1.94,5],[2,1.93,4]],"ltp":1.98,"tv":5948.98,"id":9454286}]}]}
{"op":"mcm","clk":"4289996751","pt":1632496316611,"mc":[{"id":"1.188075669","rc":[{"batb":[[0,1.8,333.79],[1,1.79,407.44]],"batl":[[1,2.08,3.34],[2,2.12,3.21]],"ltp":1.92,"tv":20540.95,"id":9631939},{"batl":[[0,2.26,164.6]],"ltp":1.98,"tv":5948.98,"id":9454286}]}]}
{"op":"mcm","clk":"4289996857","pt":1632496318224,"mc":[{"id":"1.188075669","rc":[{"batb":[[0,1.8,329.79],[1,1.79,403.44],[2,1.78,198.66]],"batl":[[0,1.84,16.3],[1,1.85,2],[2,1.86,1677.12]],"ltp":1.92,"tv":20540.95,"id":9631939},{"batb":[[0,2.16,2],[1,2.08,693.66],[2,1.95,4]],"batl":[[0,2.24,9.61],[1,2.26,160.5],[2,2.28,186.68]],"ltp":1.98,"tv":5948.98,"id":9454286}]}]}
{"op":"mcm","clk":"4289996941","pt":1632496319221,"mc":[{"id":"1.188075669","rc":[{"batl":[[1,1.86,282.14],[2,1.88,169.22]],"ltp":1.92,"tv":20540.95,"id":9631939},{"batb":[[0,2.14,153.19],[2,2,188.45]],"ltp":1.98,"tv":5948.98,"id":9454286}]}]}
{"op":"mcm","clk":"4289997018","pt":1632496320221,"mc":[{"id":"1.188075669","rc":[{"batb":[[2,1.78,266.59]],"ltp":1.92,"tv":20540.95,"id":9631939},{"batb":[[2,2.06,56.6]],"batl":[[2,2.28,239.71]],"ltp":1.98,"tv":5948.98,"id":9454286}]}]}
{"op":"mcm","clk":"4289997114","pt":1632496321223,"mc":[{"id":"1.188075669","rc":[{"batb":[[1,2.1,4],[2,2.08,697.66]],"ltp":1.98,"tv":5948.98,"id":9454286}]}]}
{"op":"mcm","clk":"4289997188","pt":1632496322010,"mc":[{"id":"1.188075669","rc":[{"batb":[[2,2.08,1627.74]],"ltp":1.98,"tv":5948.98,"id":9454286}]}]}
{"op":"mcm","clk":"4289997287","pt":1632496323013,"mc":[{"id":"1.188075669","rc":[{"batl":[[0,2.2,24.71],[1,2.24,9.61],[2,2.26,160.5]],"ltp":1.98,"tv":5948.98,"id":9454286}]}]}
{"op":"mcm","clk":"4289997389","pt":1632496324117,"mc":[{"id":"1.188075669","rc":[{"batb":[[0,1.8,450.79]],"ltp":1.92,"tv":20540.95,"id":9631939},{"batl":[[0,2.24,9.61],[1,2.26,160.5],[2,2.28,239.71]],"ltp":1.98,"tv":5948.98,"id":9454286}]}]}
{"op":"mcm","clk":"4289997471","pt":1632496325112,"mc":[{"id":"1.188075669","rc":[{"batb":[[2,1.78,281.75]],"ltp":1.92,"tv":20540.95,"id":9631939},{"batb":[[0,2.14,184.19],[2,2.08,701.22]],"ltp":1.98,"tv":5948.98,"id":9454286}]}]}
{"op":"mcm","clk":"4289997740","pt":1632496328137,"mc":[{"id":"1.188075669","rc":[{"batb":[[0,1.8,549.79]],"ltp":1.92,"tv":20540.95,"id":9631939}]}]}
{"op":"mcm","clk":"4289997904","pt":1632496330130,"mc":[{"id":"1.188075669","rc":[{"trd":[[1.84,36.24]],"batl":[[0,1.84,7.37],[1,1.86,150.4]],"ltp":1.84,"tv":20558.8,"id":9631939}],"tv":26507.79}]}
{"op":"mcm","clk":"4289997988","pt":1632496331220,"mc":[{"id":"1.188075669","rc":[{"batb":[[0,1.79,151.88],[1,1.78,83.09],[2,1.77,64.81]],"batl":[[0,1.92,14.31],[1,1.93,60],[2,1.95,204.37]],"ltp":1.84,"tv":20558.8,"id":9631939},{"batb":[[0,2.14,153.19],[2,2.08,7.56]],"batl":[[0,2.28,55.96],[1,2.3,3.65],[2,2.32,3.61]],"ltp":1.98,"tv":5948.98,"id":9454286}]}]}
{"op":"mcm","clk":"4289998076","pt":1632496332052,"mc":[{"id":"1.188075669","rc":[{"batb":[[0,1.78,83.09],[1,1.77,29.78],[2,1.76,15.23]],"batl":[[0,1.93,60],[1,1.95,204.37],[2,1.96,228.96]],"ltp":1.84,"tv":20558.8,"id":9631939},{"batb":[[0,2.06,226.35],[1,2.04,180.27],[2,2,188.45]],"batl":[[0,2.28,53.12]],"ltp":1.98,"tv":5948.98,"id":9454286}]}]}
{"op":"mcm","clk":"4289998133","pt":1632496332629,"mc":[{"id":"1.188075669","rc":[{"batb":[[0,1.77,11.41],[1,1.76,15.23],[2,1.75,238.02]],"batl":[[0,1.95,204.37],[1,1.96,228.96],[2,2.04,5]],"ltp":1.84,"tv":20558.8,"id":9631939},{"batb":[[0,2.06,169.75]],"batl":[[0,2.32,3.7],[1,2.34,180.14],[2,2.36,217.04]],"ltp":1.98,"tv":5948.98,"id":9454286}]}]}
{"op":"mcm","clk":"4289998206","pt":1632496333460,"mc":[{"id":"1.188075669","rc":[{"batb":[[0,1.77,11.54]],"ltp":1.84,"tv":20558.8,"id":9631939}]}]}
{"op":"mcm","clk":"4289998330","pt":1632496335041,"mc":[{"id":"1.188075669","rc":[{"batl":[[0,1.92,14.31],[1,1.95,204.37],[2,1.96,228.96]],"ltp":1.84,"tv":20558.8,"id":9631939},{"batb":[[0,2.08,3.56],[1,2.06,169.75],[2,2.04,184.64]],"ltp":1.98,"tv":5948.98,"id":9454286}]}]}
{"op":"mcm","clk":"4289998371","pt":1632496335556,"mc":[{"id":"1.188075669","rc":[{"batl":[[0,1.95,208.37],[1,1.96,228.96],[2,2.04,5]],"ltp":1.84,"tv":20558.8,"id":9631939},{"batb":[[0,2.06,172.75],[1,2.04,188.64],[2,2,188.45]],"ltp":1.98,"tv":5948.98,"id":9454286}]}]}
{"op":"mcm","clk":"4289998581","pt":1632496338175,"mc":[{"id":"1.188075669","rc":[{"batb":[[0,1.82,163.3],[1,1.8,191.59],[2,1.77,11.41]],"batl":[[0,1.89,192.68],[1,1.91,161.12],[2,1.95,208.37]],"ltp":1.84,"tv":20558.8,"id":9631939}]}]}
{"op":"mcm","clk":"4289998633","pt":1632496338748,"mc":[{"id":"1.188075669","rc":[{"batl":[[2,1.92,12.56]],"ltp":1.84,"tv":20558.8,"id":9631939},{"batb":[[0,2.08,4.06],[1,2.06,172.75],[2,2.04,188.64]],"ltp":1.98,"tv":5948.98,"id":9454286}]}]}
{"op":"mcm","clk":"4289998758","pt":1632496340164,"mc":[{"id":"1.188075669","rc":[{"batb":[[2,1.78,60.72]],"ltp":1.84,"tv":20558.8,"id":9631939},{"batl":[[0,2.3,3.14],[1,2.32,3.61],[2,2.34,180.14]],"ltp":1.98,"tv":5948.98,"id":9454286}]}]}
{"op":"mcm","clk":"4289998781","pt":1632496340481,"mc":[{"id":"1.188075669","rc":[{"batl":[[0,2.32,3.7],[1,2.34,180.14],[2,2.36,217.04]],"ltp":1.98,"tv":5948.98,"id":9454286}]}]}
{"op":"mcm","clk":"4289999011","pt":1632496342948,"mc":[{"id":"1.188075669","rc":[{"batl":[[0,1.89,249.46]],"ltp":1.84,"tv":20558.8,"id":9631939},{"batb":[[0,2.1,20.3],[1,2.08,4.06],[2,2.06,172.75]],"ltp":1.98,"tv":5948.98,"id":9454286}]}]}
{"op":"mcm","clk":"4289999192","pt":1632496345147,"mc":[{"id":"1.188075669","rc":[{"batb":[[0,1.77,11.54],[1,1.76,15.23],[2,1.75,238.02]],"batl":[[0,1.92,12.56],[1,1.95,208.37],[2,1.96,228.96]],"ltp":1.84,"tv":20558.8,"id":9631939},{"batb":[[0,2.08,4.06],[1,2.06,172.75],[2,2.04,188.64]],"ltp":1.98,"tv":5948.98,"id":9454286}]}]}
{"op":"mcm","clk":"4289999300","pt":1632496346144,"mc":[{"id":"1.188075669","rc":[{"batl":[[0,1.95,208.37],[1,1.96,228.96],[2,2.04,5]],"ltp":1.84,"tv":20558.8,"id":9631939},{"batb":[[0,2.06,172.75],[1,2.04,188.64],[2,2,188.45]],"batl":[[0,2.3,18.59],[1,2.32,3.61],[2,2.34,180.14]],"ltp":1.98,"tv":5948.98,"id":9454286}]}]}
{"op":"mcm","clk":"4289999323","pt":1632496346455,"mc":[{"id":"1.188075669","rc":[{"batl":[[0,2.32,3.7],[1,2.34,180.14],[2,2.36,217.04]],"ltp":1.98,"tv":5948.98,"id":9454286}]}]}
{"op":"mcm","clk":"4289999473","pt":1632496347979,"mc":[{"id":"1.188075669","rc":[{"batb":[[0,1.77,11.41]],"batl":[[2,1.98,124.81]],"ltp":1.84,"tv":20558.8,"id":9631939},{"batb":[[1,2.04,184.64]],"ltp":1.98,"tv":5948.98,"id":9454286}]}]}
{"op":"mcm","clk":"4289999559","pt":1632496348868,"mc":[{"id":"1.188075669","rc":[{"batb":[[2,1.75,2.92]],"batl":[[2,2.12,3.55]],"ltp":1.84,"tv":20558.8,"id":9631939},{"batl":[[1,2.5,281.33],[2,990,0.01]],"ltp":1.98,"tv":5948.98,"id":9454286}]}]}
{"op":"mcm","clk":"4289999750","pt":1632496351086,"mc":[{"id":"1.188075669","rc":[{"batb":[[0,1.92,9.31],[1,1.91,2731.5],[2,1.88,2034.58]],"batl":[[0,1.95,204.37],[1,1.96,237.85],[2,2,174.1]],"ltp":1.84,"tv":20558.8,"id":9631939},{"batb":[[0,2.06,169.75],[2,2,362.55]],"batl":[[0,2.16,295.16],[1,2.28,13.25],[2,2.3,3.25]],"ltp":1.98,"tv":5948.98,"id":9454286}]}]}
{"op":"mcm","clk":"4289999866","pt":1632496352196,"mc":[{"id":"1.188075669","rc":[{"batb":[[1,1.91,489.76],[2,1.89,164.05]],"batl":[[0,1.93,15.54],[1,1.95,11.5],[2,1.96,237.85]],"ltp":1.84,"tv":20558.8,"id":9631939},{"batb":[[0,2.04,184.64],[1,2,362.55],[2,1.99,480.52]],"batl":[[2,2.32,3.61]],"ltp":1.98,"tv":5948.98,"id":9454286}]}]}
{"op":"mcm","clk":"4289999955","pt":1632496353194,"mc":[{"id":"1.188075669","rc":[{"batl":[[0,2.16,350.86]],"ltp":1.98,"tv":5948.98,"id":9454286}]}]}
{"op":"mcm","clk":"4290000019","pt":1632496353981,"mc":[{"id":"1.188075669","rc":[{"batb":[[1,2,366.55],[2,1.99,485.52]],"batl":[[1,2.28,16.25]],"ltp":1.98,"tv":5948.98,"id":9454286}]}]}
{"op":"mcm","clk":"4290000137","pt":1632496355192,"mc":[{"id":"1.188075669","rc":[{"trd":[[1.92,15.47]],"batb":[[0,1.92,92.31]],"ltp":1.92,"tv":20562.8,"id":9631939}],"tv":26511.79}]}
{"op":"mcm","clk":"4290000246","pt":1632496356198,"mc":[{"id":"1.188075669","rc":[{"batl":[[0,2.08,34.05],[1,2.14,29.02],[2,2.16,295.16]],"ltp":1.98,"tv":5948.98,"id":9454286}]}]}
{"op":"mcm","clk":"4290000289","pt":1632496356576,"mc":[{"id":"1.188075669","rc":[{"batl":[[0,2.14,29.02],[1,2.16,295.16],[2,2.28,16.25]],"ltp":1.98,"tv":5948.98,"id":9454286}]}]}
{"op":"mcm","clk":"4290000482","pt":1632496358474,"mc":[{"id":"1.188075669","rc":[{"trd":[[1.93,20.99]],"batl":[[0,1.93,15.44]],"ltp":1.93,"tv":20563.0,"id":9631939},{"batl":[[2,2.22,191.16]],"ltp":1.98,"tv":5948.98,"id":9454286}],"tv":26511.98}]}
{"op":"mcm","clk":"4290000640","pt":1632496360217,"mc":[{"id":"1.188075669","rc":[{"batl":[[0,2.14,85.21]],"ltp":1.98,"tv":5948.98,"id":9454286}]}]}
{"op":"mcm","clk":"4290000721","pt":1632496361104,"mc":[{"id":"1.188075669","rc":[{"trd":[[1.92,20.16]],"batb":[[0,1.92,89.96]],"ltp":1.92,"tv":20567.69,"id":9631939}],"tv":26516.68}]}
{"op":"mcm","clk":"4290000926","pt":1632496363092,"mc":[{"id":"1.188075669","rc":[{"trd":[[1.92,24.86]],"batb":[[0,1.92,87.61],[1,1.91,272.97]],"ltp":1.92,"tv":20572.39,"id":9631939}],"tv":26521.37}]}
{"op":"mcm","clk":"4290001139","pt":1632496365610,"mc":[{"id":"1.188075669","rc":[{"batb":[[0,1.92,85]],"batl":[[2,1.96,228.96]],"ltp":1.92,"tv":20572.39,"id":9631939},{"batb":[[2,1.99,480.52]],"ltp":1.98,"tv":5948.98,"id":9454286}]}]}
{"op":"mcm","clk":"4290001404","pt":1632496368808,"mc":[{"id":"1.188075669","rc":[{"batb":[[0,2.06,7.68],[1,2.04,184.64],[2,2,366.55]],"batl":[[0,2.12,14.09],[1,2.14,85.21],[2,2.16,295.16]],"ltp":1.98,"tv":5948.98,"id":9454286}]}]}
{"op":"mcm","clk":"4290001606","pt":1632496371312,"mc":[{"id":"1.188075669","rc":[{"batb":[[0,2.04,184.64],[1,2,366.55],[2,1.99,484.52]],"batl":[[0,2.14,85.21],[1,2.16,295.16],[2,2.22,191.16]],"ltp":1.98,"tv":5948.98,"id":9454286}]}]}
{"op":"mcm","clk":"4290001945","pt":1632496375125,"mc":[{"id":"1.188075669","rc":[{"batb":[[0,1.93,3.79],[1,1.92,85],[2,1.88,63.96]],"batl":[[0,2.2,205.86],[1,2.22,210.64],[2,2.26,3.25]],"ltp":1.92,"tv":20572.39,"id":9631939},{"batb":[[0,1.84,187.7],[1,1.83,202.69],[2,1.81,128.9]],"batl":[[0,2.14,56.19],[1,2.22,187.41],[2,2.24,222.14]],"ltp":1.98,"tv":5948.98,"id":9454286}]}]}
{"op":"mcm","clk":"4290001955","pt":1632496375228,"mc":[{"id":"1.188075669","rc":[{"batb":[[1,1.88,63.96],[2,1.83,15.56]],"ltp":1.92,"tv":20572.39,"id":9631939}]}]}
{"op":"mcm","clk":"4290002046","pt":1632496376331,"mc":[{"id":"1.188075669","rc":[{"batb":[[1,1.83,15.56],[2,1.82,194.83]],"ltp":1.92,"tv":20572.39,"id":9631939},{"batl":[[0,2.22,187.41],[1,2.24,222.14],[2,2.26,3.52]],"ltp":1.98,"tv":5948.98,"id":9454286}]}]}
{"op":"mcm","clk":"4290002198","pt":1632496378020,"mc":[{"id":"1.188075669","rc":[{"batb":[[2,1.82,210.47]],"batl":[[0,2.18,3.34],[1,2.2,205.52],[2,2.22,314.64]],"ltp":1.92,"tv":20572.39,"id":9631939},{"batb":[[0,1.89,3],[1,1.88,3],[2,1.85,3]],"batl":[[0,2.22,191.16]],"ltp":1.98,"tv":5948.98,"id":9454286}]}]}
{"op":"mcm","clk":"4290002275","pt":1632496378807,"mc":[{"id":"1.188075669","rc":[{"batl":[[1,2.2,4],[2,2.26,3.25]],"ltp":1.92,"tv":20572.39,"id":9631939},{"batl":[[0,1.97,2.84],[1,2.22,191.16],[2,2.24,222.14]],"ltp":1.98,"tv":5948.98,"id":9454286}]}]}
{"op":"mcm","clk":"4290002537","pt":1632496382035,"mc":[{"id":"1.188075669","rc":[{"trd":[[1.93,28.57],[2.02,3.07]],"batb":[[0,1.82,210.47],[1,1.81,235.87],[2,1.8,361.36]],"batl":[[0,1.84,18.3],[1,1.86,19.76],[2,1.87,267.37]],"ltp":1.93,"tv":20582.74,"id":9631939},{"trd":[[1.97,2.84]],"batb":[[0,2.18,2],[1,1.89,3],[2,1.88,3]],"batl":[[0,2.22,191.16],[1,2.24,229.56],[2,2.26,3.52]],"ltp":1.97,"tv":5951.82,"id":9454286}],"tv":26534.56}]}
{"op":"mcm","clk":"4290002607","pt":1632496382869,"mc":[{"id":"1.188075669","rc":[{"batb":[[1,2.14,155.8],[2,1.98,195.11]],"ltp":1.97,"tv":5951.82,"id":9454286}]}]}
{"op":"mcm","clk":"4290002752","pt":1632496384765,"mc":[{"id":"1.188075669","rc":[{"trd":[[1.84,68.84]],"batl":[[0,1.84,2]],"ltp":1.84,"tv":20615.34,"id":9631939},{"trd":[[2.18,15.01]],"batb":[[0,2.18,1.61],[2,2.12,3]],"ltp":2.18,"tv":5952.6,"id":9454286}],"tv":26567.94}]}
{"op":"mcm","clk":"4290003458","pt":1632496392132,"mc":[{"id":"1.188075669","rc":[{"batl":[[1,1.87,164.48],[2,1.89,166.38]],"ltp":1.84,"tv":20615.34,"id":9631939},{"batl":[[1,2.24,222.14]],"ltp":2.18,"tv":5952.6,"id":9454286}]}]}
{"op":"mcm","clk":"4290003523","pt":1632496392867,"mc":[{"id":"1.188075669","rc":[{"batb":[[0,1.78,82.59],[1,1.77,28.78],[2,1.76,15.23]],"batl":[[0,1.96,13.12],[1,1.97,187.17],[2,1.98,199.32]],"ltp":1.84,"tv":20615.34,"id":9631939},{"batb":[[0,2.06,56.6],[1,2.04,220.17],[2,2.02,218.77]],"batl":[[0,2.28,53.12],[1,2.3,3.15],[2,2.32,3.61]],"ltp":2.18,"tv":5952.6,"id":9454286}]}]}
{"op":"mcm","clk":"4290003586","pt":1632496393550,"mc":[{"id":"1.188075669","rc":[{"batb":[[0,1.77,11.41],[1,1.76,15.23],[2,1.75,201.33]],"ltp":1.84,"tv":20615.34,"id":9631939},{"batb":[[0,2.04,220.17],[1,2.02,218.77],[2,1.98,195.11]],"batl":[[0,2.32,3.7],[1,2.34,196.46],[2,2.36,156.89]],"ltp":2.18,"tv":5952.6,"id":9454286}]}]}
{"op":"mcm","clk":"4290003785","pt":1632496395870,"mc":[{"id":"1.188075669","rc":[{"batb":[[0,1.77,11.72]],"ltp":1.84,"tv":20615.34,"id":9631939}]}]}
{"op":"mcm","clk":"4290003889","pt":1632496397078,"mc":[{"id":"1.188075669","rc":[{"batb":[[0,1.77,16.72],[1,1.76,20.23]],"ltp":1.84,"tv":20615.34,"id":9631939},{"batl":[[0,2.3,4.09],[1,2.32,7.61],[2,2.34,196.46]],"ltp":2.18,"tv":5952.6,"id":9454286}]}]}
{"op":"mcm","clk":"4290004041","pt":1632496399172,"mc":[{"id":"1.188075669","rc":[{"batb":[[0,2.06,3.58],[1,2.04,220.17],[2,2.02,218.77]],"ltp":2.18,"tv":5952.6,"id":9454286}]}]}
{"op":"mcm","clk":"4290004104","pt":1632496399959,"mc":[{"id":"1.188075669","rc":[{"batb":[[0,2.04,220.17],[1,2.02,218.77],[2,1.98,195.11]],"ltp":2.18,"tv":5952.6,"id":9454286}]}]}
{"op":"mcm","clk":"4290004310","pt":1632496402180,"mc":[{"id":"1.188075669","rc":[{"batl":[[0,2.12,3.34],[1,990,0.01],[2,1.98,0]],"ltp":1.84,"tv":20615.34,"id":9631939},{"batb":[[0,2.04,3.87],[1,1.98,195.11],[2,1.97,3]],"ltp":2.18,"tv":5952.6,"id":9454286}]}]}
{"op":"mcm","clk":"4290004410","pt":1632496403162,"mc":[{"id":"1.188075669","rc":[{"batl":[[0,1.93,12.07],[1,2.12,3.34],[2,990,0.01]],"ltp":1.84,"tv":20615.34,"id":9631939}]}]}
{"op":"mcm","clk":"4290004488","pt":1632496404103,"mc":[{"id":"1.188075669","rc":[{"batb":[[0,1.77,11.72],[1,1.76,15.23]],"batl":[[0,2.12,3.34],[1,990,0.01],[2,990,0]],"ltp":1.84,"tv":20615.34,"id":9631939},{"batl":[[0,2.32,3.7],[1,2.34,196.46],[2,2.36,156.89]],"ltp":2.18,"tv":5952.6,"id":9454286}]}]}
{"op":"mcm","clk":"4290004599","pt":1632496405052,"mc":[{"id":"1.188075669","rc":[{"trd":[[1.8,17.26],[1.84,69.46]],"batb":[[0,1.77,11.41]],"batl":[[0,1.78,7.72],[1,1.79,16.76],[2,1.8,1794.66]],"ltp":1.8,"tv":20616.08,"id":9631939},{"trd":[[2.24,13.87]],"batl":[[0,2.32,3.61]],"ltp":2.24,"tv":5952.69,"id":9454286}],"tv":26568.78}]}
{"op":"mcm","clk":"4290004716","pt":1632496406160,"mc":[{"id":"1.188075669","rc":[{"batl":[[2,1.8,265.27]],"ltp":1.8,"tv":20616.08,"id":9631939},{"batb":[[0,2.24,136.66],[1,2.16,149.14],[2,2.14,52.63]],"ltp":2.24,"tv":5952.69,"id":9454286}]}]}
{"op":"mcm","clk":"4290004934","pt":1632496408174,"mc":[{"id":"1.188075669","rc":[{"batb":[[2,2.08,4]],"ltp":2.24,"tv":5952.69,"id":9454286}]}]}
{"op":"mcm","clk":"4290005097","pt":1632496410169,"mc":[{"id":"1.188075669","rc":[{"trd":[[1.78,30.36]],"batl":[[0,1.79,16.76],[1,1.8,265.27],[2,1.81,528.32]],"ltp":1.78,"tv":20623.8,"id":9631939},{"trd":[[2.28,138.22]],"batb":[[0,2.24,160.8]],"ltp":2.28,"tv":5958.72,"id":9454286}],"tv":26582.53}]}
{"op":"mcm","clk":"4290005304","pt":1632496412202,"mc":[{"id":"1.188075669","rc":[{"batb":[[1,2.2,156.58],[2,2.18,213.28]],"ltp":2.28,"tv":5958.72,"id":9454286}]}]}
{"op":"mcm","clk":"4290005365","pt":1632496412907,"mc":[{"id":"1.188075669","rc":[{"batb":[[0,1.77,153.41]],"ltp":1.78,"tv":20623.8,"id":9631939}]}]}
{"op":"mcm","clk":"4290005640","pt":1632496416097,"mc":[{"id":"1.188075669","rc":[{"batb":[[0,1.77,490.41]],"ltp":1.78,"tv":20623.8,"id":9631939}]}]}
{"op":"mcm","clk":"4290005703","pt":1632496416883,"mc":[{"id":"1.188075669","rc":[{"batb":[[0,1.77,490.58]],"batl":[[1,1.8,133.39]],"ltp":1.78,"tv":20623.8,"id":9631939}]}]}
{"op":"mcm","clk":"4290005815","pt":1632496418091,"mc":[{"id":"1.188075669","rc":[{"trd":[[1.78,30.7]],"batb":[[0,1.77,490.41]],"batl":[[0,1.78,2.18],[1,1.79,16.76],[2,1.8,133.39]],"ltp":1.78,"tv":20624.14,"id":9631939}],"tv":26582.86}]}
{"op":"mcm","clk":"4290006239","pt":1632496423006,"mc":[{"id":"1.188075669","rc":[{"batb":[[1,1.76,27.5]],"batl":[[2,1.8,145.05]],"ltp":1.78,"tv":20624.14,"id":9631939}]}]}
{"op":"mcm","clk":"4290006482","pt":1632496425832,"mc":[{"id":"1.188075669","rc":[{"batl":[[0,1.79,16.76],[1,1.8,145.05],[2,1.81,528.32]],"ltp":1.78,"tv":20624.14,"id":9631939}]}]}
{"op":"mcm","clk":"4290006641","pt":1632496427815,"mc":[{"id":"1.188075669","rc":[{"batb":[[0,1.78,10.17],[1,1.77,490.41],[2,1.76,27.5]],"ltp":1.78,"tv":20624.14,"id":9631939}]}]}
{"op":"mcm","clk":"4290007304","pt":1632496435440,"mc":[{"id":"1.188075669","rc":[{"trd":[[1.78,42.67]],"batb":[[0,1.78,4.18]],"ltp":1.78,"tv":20636.11,"id":9631939}],"tv":26594.84}]}
{"op":"mcm","clk":"4290007552","pt":1632496438541,"mc":[{"id":"1.188075669","rc":[{"trd":[[1.78,51.03]],"batb":[[0,1.77,490.42],[1,1.76,27.5],[2,1.75,201.33]],"ltp":1.78,"tv":20644.46,"id":9631939}],"tv":26603.19}]}
{"op":"mcm","clk":"4290008637","pt":1632496450875,"mc":[{"id":"1.188075669","rc":[{"trd":[[1.77,105.2],[1.78,51.05]],"batb":[[0,1.77,440.43]],"ltp":1.77,"tv":20744.45,"id":9631939}],"tv":26703.18}]}
{"op":"mcm","clk":"4290008871","pt":1632496453443,"mc":[{"id":"1.188075669","rc":[{"trd":[[1.79,54.49]],"batl":[[0,1.79,14.81]],"ltp":1.79,"tv":20748.35,"id":9631939}],"tv":26707.08}]}
{"op":"mcm","clk":"4290010404","pt":1632496469969,"mc":[{"id":"1.188075669","rc":[{"batb":[[2,1.75,198.41]],"ltp":1.79,"tv":20748.35,"id":9631939}]}]}
{"op":"mcm","clk":"4290010664","pt":1632496473111,"mc":[{"id":"1.188075669","rc":[{"trd":[[1.79,60.34]],"batl":[[0,1.79,11.88]],"ltp":1.79,"tv":20754.2,"id":9631939}],"tv":26712.93}]}
{"op":"mcm","clk":"4290011186","pt":1632496478718,"mc":[{"id":"1.188075669","rc":[{"trd":[[1.77,113.74]],"batb":[[0,1.77,436.16]],"ltp":1.77,"tv":20762.74,"id":9631939}],"tv":26721.47}]}
{"op":"mcm","clk":"4290011640","pt":1632496483011,"mc":[{"id":"1.188075669","rc":[{"trd":[[1.77,114.44]],"batb":[[0,1.77,435.81]],"ltp":1.77,"tv":20763.45,"id":9631939}],"tv":26722.18}]}
{"op":"mcm","clk":"4290012896","pt":1632496496179,"mc":[{"id":"1.188075669","rc":[{"batb":[[0,1.74,17.52],[1,1.72,90.05],[2,1.7,257.95]],"batl":[[0,1.81,14.5],[1,1.82,15.25],[2,1.83,199.07]],"ltp":1.77,"tv":20763.45,"id":9631939},{"batb":[[0,2.22,3.34],[1,2.2,160.15]],"batl":[[0,2.36,2.82],[1,2.4,53.69],[2,2.42,130.38]],"ltp":2.28,"tv":5958.72,"id":9454286}]}]}
{"op":"mcm","clk":"4290012937","pt":1632496496542,"mc":[{"id":"1.188075669","rc":[{"batb":[[0,1.72,90.05],[1,1.7,257.95],[2,1.69,306.31]],"batl":[[0,1.82,15.25],[1,1.83,199.07],[2,1.84,272.87]],"ltp":1.77,"tv":20763.45,"id":9631939},{"batb":[[0,2.2,160.15],[1,2.18,213.28],[2,2.16,200.86]],"batl":[[0,2.4,53.69],[1,2.42,130.38],[2,2.44,213]],"ltp":2.28,"tv":5958.72,"id":9454286}]}]}
{"op":"mcm","clk":"4290013017","pt":1632496497228,"mc":[{"id":"1.188075669","rc":[{"batb":[[0,1.72,19.34]],"ltp":1.77,"tv":20763.45,"id":9631939},{"batb":[[2,2.16,149.14]],"batl":[[0,2.4,2.99]],"ltp":2.28,"tv":5958.72,"id":9454286}]}]}
{"op":"mcm","clk":"4290013129","pt":1632496498429,"mc":[{"id":"1.188075669","rc":[{"batb":[[2,1.69,469.37]],"batl":[[2,1.84,416.41]],"ltp":1.77,"tv":20763.45,"id":9631939}]}]}
{"op":"mcm","clk":"4290013297","pt":1632496500063,"mc":[{"id":"1.188075669","rc":[{"batb":[[0,1.72,25.34],[1,1.71,5],[2,1.7,257.95]],"ltp":1.77,"tv":20763.45,"id":9631939},{"batb":[[0,2.2,164.15],[1,2.18,216.28]],"batl":[[0,2.4,6.99]],"ltp":2.28,"tv":5958.72,"id":9454286}]}]}
{"op":"mcm","clk":"4290013340","pt":1632496500443,"mc":[{"id":"1.188075669","rc":[{"batb":[[2,1.67,173.43]],"ltp":1.77,"tv":20763.45,"id":9631939},{"batl":[[1,2.82,237.08],[2,990,0.01]],"ltp":2.28,"tv":5958.72,"id":9454286}]}]}
{"op":"mcm","clk":"4290013622","pt":1632496503055,"mc":[{"id":"1.188075669","rc":[{"batb":[[0,1.8,7.53],[1,1.78,2579.88],[2,1.76,258.49]],"batl":[[1,1.83,208.35]],"ltp":1.77,"tv":20763.45,"id":9631939},{"batl":[[1,2.46,12.2],[2,2.82,237.08]],"ltp":2.28,"tv":5958.72,"id":9454286}]}]}
{"op":"mcm","clk":"4290013745","pt":1632496504063,"mc":[{"id":"1.188075669","rc":[{"trd":[[1.78,92.32],[1.8,32.31]],"batb":[[0,1.78,485.31],[1,1.76,464.5],[2,1.75,581.87]],"batl":[[0,1.81,16.57],[1,1.82,15.25],[2,1.83,208.35]],"ltp":1.78,"tv":20819.77,"id":9631939},{"batb":[[0,2.2,160.15],[1,2.18,213.28]],"batl":[[0,2.4,425.65],[2,2.68,1.71]],"ltp":2.28,"tv":5958.72,"id":9454286}],"tv":26778.5}]}
{"op":"mcm","clk":"4290013823","pt":1632496504671,"mc":[{"id":"1.188075669","rc":[{"batl":[[0,2.38,34.95],[1,2.4,6.99],[2,2.46,12.2]],"ltp":2.28,"tv":5958.72,"id":9454286}]}]}
{"op":"mcm","clk":"4290013915","pt":1632496505561,"mc":[{"id":"1.188075669","rc":[{"batb":[[1,1.76,533.32]],"ltp":1.78,"tv":20819.77,"id":9631939},{"batl":[[0,2.32,52.22]],"ltp":2.28,"tv":5958.72,"id":9454286}]}]}
{"op":"mcm","clk":"4290013990","pt":1632496506250,"mc":[{"id":"1.188075669","rc":[{"batb":[[2,2.16,152.14]],"batl":[[1,2.38,3],[2,2.4,6.99]],"ltp":2.28,"tv":5958.72,"id":9454286}]}]}
{"op":"mcm","clk":"4290014161","pt":1632496508050,"mc":[{"id":"1.188075669","rc":[{"batl":[[0,2.24,23.23],[1,2.32,52.22],[2,2.38,3]],"ltp":2.28,"tv":5958.72,"id":9454286}]}]}
{"op":"mcm","clk":"4290014239","pt":1632496508732,"mc":[{"id":"1.188075669","rc":[{"batl":[[0,2.32,87.17],[1,2.38,3],[2,2.4,6.99]],"ltp":2.28,"tv":5958.72,"id":9454286}]}]}
{"op":"mcm","clk":"4290014355","pt":1632496510150,"mc":[{"id":"1.188075669","rc":[{"batb":[[0,1.79,113],[1,1.78,485.31],[2,1.76,533.32]],"ltp":1.78,"tv":20819.77,"id":9631939}]}]}
{"op":"mcm","clk":"4290014397","pt":1632496510732,"mc":[{"id":"1.188075669","rc":[{"batb":[[2,1.77,16.37]],"batl":[[2,1.83,223.85]],"ltp":1.78,"tv":20819.77,"id":9631939},{"batl":[[0,2.3,2.65],[1,2.32,241.79],[2,2.34,203.25]],"ltp":2.28,"tv":5958.72,"id":9454286}]}]}
{"op":"mcm","clk":"4290014513","pt":1632496511957,"mc":[{"id":"1.188075669","rc":[{"batb":[[1,1.78,501.97]],"ltp":1.78,"tv":20819.77,"id":9631939},{"batb":[[1,2.18,217.25]],"ltp":2.28,"tv":5958.72,"id":9454286}]}]}
{"op":"mcm","clk":"4290014711","pt":1632496514063,"mc":[{"id":"1.188075669","rc":[{"batl":[[2,1.83,214.57]],"ltp":1.78,"tv":20819.77,"id":9631939}]}]}
{"op":"mcm","clk":"4290014806","pt":1632496515167,"mc":[{"id":"1.188075669","rc":[{"batb":[[1,1.78,317.87]],"ltp":1.78,"tv":20819.77,"id":9631939}]}]}
{"op":"mcm","clk":"4290014982","pt":1632496517070,"mc":[{"id":"1.188075669","rc":[{"batl":[[0,1.82,15.25],[1,1.83,214.57],[2,1.84,431.94]],"ltp":1.78,"tv":20819.77,"id":9631939}]}]}
{"op":"mcm","clk":"4290015031","pt":1632496517647,"mc":[{"id":"1.188075669","rc":[{"batb":[[1,1.77,16.37],[2,1.76,85.8]],"batl":[[0,1.83,15.5],[1,1.88,169.15],[2,1.89,213.17]],"ltp":1.78,"tv":20819.77,"id":9631939},{"batb":[[0,2.2,3.57],[1,2.16,3],[2,2.14,147.78]],"batl":[[1,2.32,206.84]],"ltp":2.28,"tv":5958.72,"id":9454286}]}]}
{"op":"mcm","clk":"4290015106","pt":1632496518652,"mc":[{"id":"1.188075669","rc":[{"batb":[[0,1.76,16.98],[1,1.75,179.43],[2,1.74,304.46]],"ltp":1.78,"tv":20819.77,"id":9631939},{"batb":[[2,2.14,143.78]],"batl":[[0,2.32,154.62],[1,2.34,203.25],[2,2.38,3]],"ltp":2.28,"tv":5958.72,"id":9454286}]}]}
{"op":"mcm","clk":"4290015402","pt":1632496521978,"mc":[{"id":"1.188075669","rc":[{"batb":[[0,1.77,15.37],[1,1.76,16.98],[2,1.75,179.43]],"ltp":1.78,"tv":20819.77,"id":9631939},{"batl":[[0,2.3,3.15],[1,2.32,154.62],[2,2.34,203.25]],"ltp":2.28,"tv":5958.72,"id":9454286}]}]}
{"op":"mcm","clk":"4290015509","pt":1632496523086,"mc":[{"id":"1.188075669","rc":[{"batb":[[0,1.76,16.98],[1,1.75,179.43],[2,1.74,304.46]],"batl":[[1,1.86,547.07],[2,1.88,169.15]],"ltp":1.78,"tv":20819.77,"id":9631939},{"batl":[[0,2.32,154.62],[1,2.34,203.25],[2,2.38,3]],"ltp":2.28,"tv":5958.72,"id":9454286}]}]}
{"op":"mcm","clk":"4290015614","pt":1632496524155,"mc":[{"id":"1.188075669","rc":[{"batb":[[0,1.77,150.14],[1,1.76,16.98],[2,1.75,389.38]],"batl":[[0,1.82,15.75],[1,1.83,206.72],[2,1.85,177.65]],"ltp":1.78,"tv":20819.77,"id":9631939},{"batb":[[0,2.2,21.42]],"ltp":2.28,"tv":5958.72,"id":9454286}]}]}
{"op":"mcm","clk":"4290015638","pt":1632496524468,"mc":[{"id":"1.188075669","rc":[{"batl":[[0,1.83,206.72],[1,1.85,177.65],[2,1.88,169.15]],"ltp":1.78,"tv":20819.77,"id":9631939},{"batb":[[0,2.2,3.57]],"ltp":2.28,"tv":5958.72,"id":9454286}]}]}
{"op":"mcm","clk":"4290015792","pt":1632496526175,"mc":[{"id":"1.188075669","rc":[{"batb":[[0,1.76,16.98],[1,1.75,179.43],[2,1.74,304.46]],"batl":[[0,1.83,15.5],[1,1.88,169.15],[2,1.89,213.17]],"ltp":1.78,"tv":20819.77,"id":9631939}]}]}
{"op":"mcm","clk":"4290015982","pt":1632496528180,"mc":[{"id":"1.188075669","rc":[{"batl":[[1,1.96,4],[2,990,0.35]],"ltp":1.78,"tv":20819.77,"id":9631939},{"batb":[[2,2.12,159.18]],"ltp":2.28,"tv":5958.72,"id":9454286}]}]}
{"op":"mcm","clk":"4290016051","pt":1632496528870,"mc":[{"id":"1.188075669","rc":[{"batl":[[0,1.96,4],[1,990,0.35],[2,990,0]],"ltp":1.78,"tv":20819.77,"id":9631939},{"batb":[[0,2.16,3],[1,2.12,159.18],[2,1.67,414.47]],"ltp":2.28,"tv":5958.72,"id":9454286}]}]}
{"op":"mcm","clk":"4290016156","pt":1632496530195,"mc":[{"id":"1.188075669","rc":[{"batb":[[0,1.77,17.41],[1,1.76,16.98],[2,1.75,179.43]],"ltp":1.78,"tv":20819.77,"id":9631939},{"batl":[[0,2.3,3.05],[1,2.32,154.62],[2,2.34,203.25]],"ltp":2.28,"tv":5958.72,"id":9454286}]}]}
{"op":"mcm","clk":"4290016275","pt":1632496531199,"mc":[{"id":"1.188075669","rc":[{"trd":[[1.83,194.14]],"batb":[[0,1.76,16.98],[1,1.75,179.43],[2,1.74,299.46]],"batl":[[0,1.78,2220.64],[1,1.79,212.05],[2,1.8,1328.12]],"ltp":1.83,"tv":20819.85,"id":9631939},{"batl":[[0,2.32,3.11],[1,2.34,203.25],[2,2.36,7.27]],"ltp":2.28,"tv":5958.72,"id":9454286}],"tv":26778.58}]}
{"op":"mcm","clk":"4290016398","pt":1632496532159,"mc":[{"id":"1.188075669","rc":[{"batl":[[0,1.78,208.25],[2,1.8,531.24]],"ltp":1.83,"tv":20819.85,"id":9631939},{"batb":[[0,2.28,130.41],[1,2.2,143.07],[2,2.18,65.84]],"ltp":2.28,"tv":5958.72,"id":9454286}]}]}
{"op":"mcm","clk":"4290016481","pt":1632496533166,"mc":[{"id":"1.188075669","rc":[{"batb":[[2,2.18,68.84]],"ltp":2.28,"tv":5958.72,"id":9454286}]}]}
{"op":"mcm","clk":"4290016579","pt":1632496534174,"mc":[{"id":"1.188075669","rc":[{"batb":[[1,2.24,4],[2,2.22,4]],"ltp":2.28,"tv":5958.72,"id":9454286}]}]}
{"op":"mcm","clk":"4290016874","pt":1632496537181,"mc":[{"id":"1.188075669","rc":[{"batb":[[0,1.76,157.98]],"ltp":1.83,"tv":20819.85,"id":9631939}]}]}
{"op":"mcm","clk":"4290016970","pt":1632496538080,"mc":[{"id":"1.188075669","rc":[{"batb":[[2,2.22,7.34]],"ltp":2.28,"tv":5958.72,"id":9454286}]}]}
{"op":"mcm","clk":"4290017213","pt":1632496540412,"mc":[{"id":"1.188075669","rc":[{"batb":[[0,1.76,242.98]],"ltp":1.83,"tv":20819.85,"id":9631939}]}]}
{"op":"mcm","clk":"4290017445","pt":1632496542890,"mc":[{"id":"1.188075669","rc":[{"batl":[[0,1.78,34.76]],"ltp":1.83,"tv":20819.85,"id":9631939}]}]}
{"op":"mcm","clk":"4290017849","pt":1632496547210,"mc":[{"id":"1.188075669","rc":[{"batl":[[0,1.78,17.91],[2,1.8,265.62]],"ltp":1.83,"tv":20819.85,"id":9631939}]}]}
{"op":"mcm","clk":"4290017913","pt":1632496547686,"mc":[{"id":"1.188075669","rc":[{"batb":[[0,1.76,226],[1,1.72,19.34],[2,1.7,355.23]],"batl":[[0,1.83,222.73],[1,1.84,259.77],[2,990,0.35]],"ltp":1.83,"tv":20819.85,"id":9631939},{"batb":[[0,2.2,316.51],[1,2.18,237.83],[2,1.67,414.47]],"batl":[[0,2.4,2.99],[1,2.42,50.35],[2,2.44,144.29]],"ltp":2.28,"tv":5958.72,"id":9454286}]}]}
{"op":"mcm","clk":"4290018002","pt":1632496548589,"mc":[{"id":"1.188075669","rc":[{"batb":[[0,1.7,355.23],[1,1.69,262.54],[2,1.64,181.87]],"ltp":1.83,"tv":20819.85,"id":9631939},{"batl":[[0,2.42,50.35],[1,2.44,144.29],[2,2.46,147.25]],"ltp":2.28,"tv":5958.72,"id":9454286}]}]}
{"op":"mcm","clk":"4290018066","pt":1632496549327,"mc":[{"id":"1.188075669","rc":[{"batb":[[0,1.7,283.52]],"batl":[[1,1.84,199.77]],"ltp":1.83,"tv":20819.85,"id":9631939},{"batb":[[1,2.18,186.99]],"batl":[[0,2.44,144.29],[1,2.46,147.25],[2,2.82,237.08]],"ltp":2.28,"tv":5958.72,"id":9454286}]}]}
{"op":"mcm","clk":"4290018247","pt":1632496551027,"mc":[{"id":"1.188075669","rc":[{"batb":[[2,1.67,145.59]],"batl":[[0,1.81,14.5],[1,1.83,403.63],[2,1.84,199.77]],"ltp":1.83,"tv":20819.85,"id":9631939},{"batb":[[0,2.22,3.34],[1,2.2,316.51],[2,2.18,186.99]],"batl":[[0,2.38,3],[1,2.44,144.29],[2,2.46,147.25]],"ltp":2.28,"tv":5958.72,"id":9454286}]}]}
{"op":"mcm","clk":"4290018343","pt":1632496551918,"mc":[{"id":"1.188075669","rc":[{"batb":[[0,1.73,4],[1,1.72,21.09],[2,1.71,4]],"batl":[[0,1.83,403.63],[1,1.84,199.77],[2,1.85,177.6]],"ltp":1.83,"tv":20819.85,"id":9631939},{"batb":[[0,2.2,316.51],[1,2.18,186.99],[2,1.67,414.47]],"batl":[[1,2.4,6.69],[2,2.42,3]],"ltp":2.28,"tv":5958.72,"id":9454286}]}]}
{"op":"mcm","clk":"4290018402","pt":1632496552495,"mc":[{"id":"1.188075669","rc":[{"batb":[[1,1.72,4]],"ltp":1.83,"tv":20819.85,"id":9631939},{"batl":[[1,2.4,4]],"ltp":2.28,"tv":5958.72,"id":9454286}]}]}
{"op":"mcm","clk":"4290018673","pt":1632496555442,"mc":[{"id":"1.188075669","rc":[{"batb":[[1,1.72,21.84]],"ltp":1.83,"tv":20819.85,"id":9631939},{"batl":[[1,2.4,7.09]],"ltp":2.28,"tv":5958.72,"id":9454286}]}]}
{"op":"mcm","clk":"4290018772","pt":1632496556914,"mc":[{"id":"1.188075669","rc":[{"batb":[[1,1.72,4]],"ltp":1.83,"tv":20819.85,"id":9631939},{"batl":[[1,2.4,4]],"ltp":2.28,"tv":5958.72,"id":9454286}]}]}
{"op":"mcm","clk":"4290018873","pt":1632496558126,"mc":[{"id":"1.188075669","rc":[{"batb":[[0,1.77,131.26],[1,1.76,2552.77],[2,1.75,756.33]],"batl":[[0,1.8,7.69],[1,1.83,653.26],[2,1.84,199.77]],"ltp":1.83,"tv":20819.85,"id":9631939},{"batl":[[0,2.4,4],[1,2.42,3],[2,2.44,6.83]],"ltp":2.28,"tv":5958.72,"id":9454286}]}]}
{"op":"mcm","clk":"4290018953","pt":1632496559026,"mc":[{"id":"1.188075669","rc":[{"trd":[[1.77,115.54]],"batb":[[0,1.77,130.71],[1,1.76,363.2]],"batl":[[1,1.81,16.57],[2,1.83,653.26]],"ltp":1.77,"tv":20820.95,"id":9631939},{"batb":[[2,2.14,156.31]],"ltp":2.28,"tv":5958.72,"id":9454286}],"tv":26779.68}]}
{"op":"mcm","clk":"4290019056","pt":1632496560040,"mc":[{"id":"1.188075669","rc":[{"batl":[[2,1.83,683.72]],"ltp":1.77,"tv":20820.95,"id":9631939},{"batb":[[0,2.2,343.68],[1,2.18,190.99],[2,2.16,4]],"batl":[[0,2.36,51.44],[1,2.4,4],[2,2.42,3]],"ltp":2.28,"tv":5958.72,"id":9454286}]}]}
{"op":"mcm","clk":"4290019349","pt":1632496563144,"mc":[{"id":"1.188075669","rc":[{"trd":[[1.8,40]],"batl":[[0,1.81,16.57],[1,1.83,683.72],[2,1.84,199.77]],"ltp":1.8,"tv":20828.64,"id":9631939},{"trd":[[2.24,20.05]],"batl":[[0,2.34,21.66],[1,2.36,51.44],[2,2.4,4]],"ltp":2.24,"tv":5964.9,"id":9454286}],"tv":26793.55}]}
{"op":"mcm","clk":"4290019435","pt":1632496564151,"mc":[{"id":"1.188075669","rc":[{"batb":[[0,1.78,203],[1,1.77,130.71],[2,1.76,363.2]],"ltp":1.8,"tv":20828.64,"id":9631939},{"batl":[[2,2.44,6.83]],"ltp":2.24,"tv":5964.9,"id":9454286}]}]}
{"op":"mcm","clk":"4290019619","pt":1632496566053,"mc":[{"id":"1.188075669","rc":[{"batb":[[2,1.76,381.43]],"batl":[[1,1.82,17.25],[2,1.83,683.72]],"ltp":1.8,"tv":20828.64,"id":9631939},{"batb":[[2,2.16,213.2]],"batl":[[0,2.32,2.86],[1,2.34,24.41],[2,2.36,188.54]],"ltp":2.24,"tv":5964.9,"id":9454286}]}]}
{"op":"mcm","clk":"4290019729","pt":1632496567163,"mc":[{"id":"1.188075669","rc":[{"trd":[[1.78,93.28]],"batb":[[0,1.78,346.52],[1,1.77,146.08]],"ltp":1.78,"tv":20829.59,"id":9631939},{"batb":[[1,2.18,193.96],[2,2.16,216.73]],"batl":[[0,2.3,2.95],[1,2.32,2.86],[2,2.34,24.41]],"ltp":2.24,"tv":5964.9,"id":9454286}],"tv":26794.5}]}
{"op":"mcm","clk":"4290019986","pt":1632496569954,"mc":[{"id":"1.188075669","rc":[{"trd":[[1.78,94.22]],"batb":[[0,1.78,345.58],[2,1.76,180.13]],"ltp":1.78,"tv":20830.53,"id":9631939},{"trd":[[2.3,85.09]],"batl":[[0,2.32,2.86],[1,2.34,24.41],[2,2.36,191.36]],"ltp":2.3,"tv":5971.53,"id":9454286}],"tv":26802.07}]}
{"op":"mcm","clk":"4290020265","pt":1632496573146,"mc":[{"id":"1.188075669","rc":[{"batb":[[2,1.76,163.74]],"ltp":1.78,"tv":20830.53,"id":9631939}]}]}
{"op":"mcm","clk":"4290020343","pt":1632496574047,"mc":[{"id":"1.188075669","rc":[{"batb":[[1,1.76,163.74],[2,1.75,15.75]],"batl":[[0,1.83,14.5],[1,1.84,14.53],[2,1.85,16.7]],"ltp":1.78,"tv":20830.53,"id":9631939},{"batb":[[0,2.2,146.54],[1,2.18,2.97],[2,2.16,209.2]],"batl":[[1,2.34,2.75]],"ltp":2.3,"tv":5971.53,"id":9454286}]}]}
{"op":"mcm","clk":"4290020445","pt":1632496575143,"mc":[{"id":"1.188075669","rc":[{"batb":[[0,1.76,18.23],[1,1.75,15.75],[2,1.74,262.72]],"batl":[[1,1.86,174.73],[2,1.87,278.67]],"ltp":1.78,"tv":20830.53,"id":9631939},{"batb":[[0,2.2,3.47],[1,2.16,209.2],[2,2.14,398.33]],"ltp":2.3,"tv":5971.53,"id":9454286}]}]}
{"op":"mcm","clk":"4290020470","pt":1632496575457,"mc":[{"id":"1.188075669","rc":[{"batb":[[0,1.74,192.98],[1,1.73,267.8],[2,1.72,4]],"ltp":1.78,"tv":20830.53,"id":9631939},{"batl":[[0,2.36,139.92],[1,2.38,150.56],[2,2.44,6.83]],"ltp":2.3,"tv":5971.53,"id":9454286}]}]}
{"op":"mcm","clk":"4290020625","pt":1632496577068,"mc":[{"id":"1.188075669","rc":[{"batb":[[1,2.16,213.2]],"ltp":2.3,"tv":5971.53,"id":9454286}]}]}
{"op":"mcm","clk":"4290020833","pt":1632496578956,"mc":[{"id":"1.188075669","rc":[{"batb":[[0,1.74,196.98],[1,1.73,272.8]],"ltp":1.78,"tv":20830.53,"id":9631939},{"batl":[[0,2.36,143.92]],"ltp":2.3,"tv":5971.53,"id":9454286}]}]}
{"op":"mcm","clk":"4290020970","pt":1632496580174,"mc":[{"id":"1.188075669","rc":[{"batb":[[0,1.75,223.21],[1,1.74,196.98],[2,1.73,491.31]],"batl":[[0,1.82,203.4],[1,1.83,14.5],[2,1.84,180.58]],"ltp":1.78,"tv":20830.53,"id":9631939}]}]}
{"op":"mcm","clk":"4290021066","pt":1632496581061,"mc":[{"id":"1.188075669","rc":[{"trd":[[1.75,94.34]],"batb":[[0,1.75,209.54]],"batl":[[0,1.82,48.78],[2,1.86,174.73]],"ltp":1.75,"tv":20857.89,"id":9631939},{"batb":[[0,2.22,17.35],[1,2.2,3.47],[2,2.16,213.2]],"batl":[[0,2.36,165.09]],"ltp":2.3,"tv":5971.53,"id":9454286}],"tv":26829.43}]}
{"op":"mcm","clk":"4290021177","pt":1632496582162,"mc":[{"id":"1.188075669","rc":[{"batb":[[0,1.75,5],[2,1.73,272.8]],"batl":[[0,1.83,14.5],[1,1.86,174.73],[2,1.87,278.67]],"ltp":1.75,"tv":20857.89,"id":9631939},{"batb":[[0,2.2,3.47],[1,2.16,213.2],[2,2.14,398.33]],"batl":[[0,2.36,143.92]],"ltp":2.3,"tv":5971.53,"id":9454286}]}]}
{"op":"mcm","clk":"4290021271","pt":1632496583155,"mc":[{"id":"1.188075669","rc":[{"batb":[[0,1.78,92],[1,1.75,5],[2,1.74,196.98]],"ltp":1.75,"tv":20857.89,"id":9631939},{"batl":[[0,2.34,4],[1,2.36,143.92],[2,2.38,150.56]],"ltp":2.3,"tv":5971.53,"id":9454286}]}]}
{"op":"mcm","clk":"4290021352","pt":1632496584164,"mc":[{"id":"1.188075669","rc":[{"batb":[[0,1.75,5],[1,1.74,196.98],[2,1.73,272.8]],"ltp":1.75,"tv":20857.89,"id":9631939}]}]}
{"op":"mcm","clk":"4290021414","pt":1632496584747,"mc":[{"id":"1.188075669","rc":[{"batl":[[2,1.87,473.97]],"ltp":1.75,"tv":20857.89,"id":9631939}]}]}
{"op":"mcm","clk":"4290021532","pt":1632496585967,"mc":[{"id":"1.188075669","rc":[{"batb":[[0,1.76,15.48],[1,1.75,5],[2,1.74,196.98]],"ltp":1.75,"tv":20857.89,"id":9631939},{"batl":[[0,2.32,3.11],[1,2.34,4],[2,2.36,143.92]],"ltp":2.3,"tv":5971.53,"id":9454286}]}]}
{"op":"mcm","clk":"4290021570","pt":1632496586280,"mc":[{"id":"1.188075669","rc":[{"batb":[[0,1.75,5],[1,1.74,196.98],[2,1.73,272.8]],"ltp":1.75,"tv":20857.89,"id":9631939},{"batl":[[0,2.34,4],[1,2.36,143.92],[2,2.38,150.56]],"ltp":2.3,"tv":5971.53,"id":9454286}]}]}
{"op":"mcm","clk":"4290021756","pt":1632496587986,"mc":[{"id":"1.188075669","rc":[{"batl":[[0,1.82,16.25],[1,1.83,14.5],[2,1.86,174.73]],"ltp":1.75,"tv":20857.89,"id":9631939}]}]}
{"op":"mcm","clk":"4290021804","pt":1632496588400,"mc":[{"id":"1.188075669","rc":[{"batl":[[0,1.83,14.5],[1,1.86,174.73],[2,1.87,473.97]],"ltp":1.75,"tv":20857.89,"id":9631939}]}]}
{"op":"mcm","clk":"4290022171","pt":1632496592014,"mc":[{"id":"1.188075669","rc":[{"batb":[[1,1.74,192.98],[2,1.73,267.8]],"ltp":1.75,"tv":20857.89,"id":9631939},{"batl":[[1,2.36,139.92]],"ltp":2.3,"tv":5971.53,"id":9454286}]}]}
{"op":"mcm","clk":"4290022287","pt":1632496593070,"mc":[{"id":"1.188075669","rc":[{"batb":[[0,1.76,17.48],[1,1.75,5],[2,1.74,192.98]],"ltp":1.75,"tv":20857.89,"id":9631939},{"batl":[[0,2.32,3.11],[1,2.34,4],[2,2.36,139.92]],"ltp":2.3,"tv":5971.53,"id":9454286}]}]}
{"op":"mcm","clk":"4290022404","pt":1632496594192,"mc":[{"id":"1.188075669","rc":[{"trd":[[1.74,233.78],[1.75,104.34]],"batb":[[0,1.74,92.12],[1,1.73,267.8],[2,1.71,177.27]],"batl":[[2,1.87,278.67]],"ltp":1.74,"tv":21069.75,"id":9631939},{"batl":[[0,2.34,4],[1,2.36,139.92],[2,2.38,150.56]],"ltp":2.3,"tv":5971.53,"id":9454286}],"tv":27041.29}]}
{"op":"mcm","clk":"4290022488","pt":1632496595169,"mc":[{"id":"1.188075669","rc":[{"batb":[[0,1.74,96.12]],"batl":[[0,1.82,14.25],[1,1.83,14.5],[2,990,0.35]],"ltp":1.74,"tv":21069.75,"id":9631939},{"batb":[[1,2.16,4],[2,2.14,156.31]],"ltp":2.3,"tv":5971.53,"id":9454286}]}]}
{"op":"mcm","clk":"4290022585","pt":1632496596189,"mc":[{"id":"1.188075669","rc":[{"batl":[[0,1.83,14.5],[1,990,0.35],[2,990,0]],"ltp":1.74,"tv":21069.75,"id":9631939}]}]}
{"op":"mcm","clk":"4290022686","pt":1632496597186,"mc":[{"id":"1.188075669","rc":[{"trd":[[1.76,101.34]],"batb":[[0,1.74,16.02],[2,1.72,17.56]],"batl":[[0,1.77,2444.71],[1,1.78,539.56],[2,1.79,718.57]],"ltp":1.76,"tv":21086.51,"id":9631939},{"batb":[[0,2.28,2],[1,2.2,3.47],[2,2.16,4]],"batl":[[0,2.36,2.82],[1,2.38,150.56],[2,2.44,2.83]],"ltp":2.3,"tv":5971.53,"id":9454286}],"tv":27058.05}]}
{"op":"mcm","clk":"4290022767","pt":1632496598188,"mc":[{"id":"1.188075669","rc":[{"batl":[[0,1.77,389.25]],"ltp":1.76,"tv":21086.51,"id":9631939},{"batb":[[0,2.3,124.59],[1,2.28,2],[2,2.22,140.62]],"batl":[[2,2.44,52.83]],"ltp":2.3,"tv":5971.53,"id":9454286}]}]}
{"op":"mcm","clk":"4290022946","pt":1632496599989,"mc":[{"id":"1.188075669","rc":[{"batb":[[2,2.22,144.62]],"ltp":2.3,"tv":5971.53,"id":9454286}]}]}
{"op":"mcm","clk":"4290023299","pt":1632496603102,"mc":[{"id":"1.188075669","rc":[{"batb":[[0,1.74,110.02]],"batl":[[0,1.77,419.57]],"ltp":1.76,"tv":21086.51,"id":9631939},{"batb":[[0,2.3,147.48]],"ltp":2.3,"tv":5971.53,"id":9454286}]}]}
{"op":"mcm","clk":"4290023417","pt":1632496604213,"mc":[{"id":"1.188075669","rc":[{"batb":[[2,2.22,301.78]],"ltp":2.3,"tv":5971.53,"id":9454286}]}]}
{"op":"mcm","clk":"4290023503","pt":1632496605007,"mc":[{"id":"1.188075669","rc":[{"batb":[[2,2.22,305.62]],"ltp":2.3,"tv":5971.53,"id":9454286}]}]}
{"op":"mcm","clk":"4290023613","pt":1632496606121,"mc":[{"id":"1.188075669","rc":[{"batb":[[0,1.74,244.02]],"ltp":1.76,"tv":21086.51,"id":9631939}]}]}
{"op":"mcm","clk":"4290023786","pt":1632496607806,"mc":[{"id":"1.188075669","rc":[{"batb":[[2,1.71,177.27]],"ltp":1.76,"tv":21086.51,"id":9631939}]}]}
{"op":"mcm","clk":"4290023888","pt":1632496608906,"mc":[{"id":"1.188075669","rc":[{"batl":[[0,1.77,242.37]],"ltp":1.76,"tv":21086.51,"id":9631939}]}]}
{"op":"mcm","clk":"4290024023","pt":1632496610012,"mc":[{"id":"1.188075669","rc":[{"batb":[[0,1.74,256.73]],"batl":[[1,1.78,551.63]],"ltp":1.76,"tv":21086.51,"id":9631939}]}]}
{"op":"mcm","clk":"4290024927","pt":1632496619212,"mc":[{"id":"1.188075669","rc":[{"batb":[[0,1.74,228],[1,1.69,88.44],[2,1.68,18.11]],"batl":[[0,1.82,176.23],[1,1.83,325.77],[2,990,0.35]],"ltp":1.76,"tv":21086.51,"id":9631939},{"batb":[[0,2.22,297.78],[1,2.2,225.18],[2,1.67,414.47]],"batl":[[0,2.44,50],[1,2.46,3.25],[2,2.48,3.24]],"ltp":2.3,"tv":5971.53,"id":9454286}]}]}
{"op":"mcm","clk":"4290025021","pt":1632496620213,"mc":[{"id":"1.188075669","rc":[{"batb":[[0,1.69,16.21],[1,1.68,18.11],[2,1.67,212.05]],"batl":[[1,1.83,265.77]],"ltp":1.76,"tv":21086.51,"id":9631939},{"batb":[[1,2.2,175.18]],"batl":[[0,2.46,3.25],[1,2.48,3.24],[2,2.5,181.86]],"ltp":2.3,"tv":5971.53,"id":9454286}]}]}
{"op":"mcm","clk":"4290025058","pt":1632496620635,"mc":[{"id":"1.188075669","rc":[{"batb":[[0,1.67,212.05],[1,1.66,274.69],[2,1.62,192.92]],"ltp":1.76,"tv":21086.51,"id":9631939},{"batl":[[0,2.5,181.88],[1,2.52,200.19],[2,2.82,237.08]],"ltp":2.3,"tv":5971.53,"id":9454286}]}]}
{"op":"mcm","clk":"4290025388","pt":1632496624036,"mc":[{"id":"1.188075669","rc":[{"batb":[[0,1.67,217.05],[1,1.66,280.69]],"ltp":1.76,"tv":21086.51,"id":9631939},{"batb":[[2,1.01,139.76]],"batl":[[0,2.5,184.88]],"ltp":2.3,"tv":5971.53,"id":9454286}]}]}
{"op":"mcm","clk":"4290025491","pt":1632496625037,"mc":[{"id":"1.188075669","rc":[{"trd":[[1.76,101.36]],"batb":[[0,1.7,126.54],[1,1.68,241.22],[2,1.67,217.05]],"batl":[[0,1.75,150.82],[1,1.77,204.63],[2,1.82,176.23]],"ltp":1.76,"tv":21086.53,"id":9631939},{"trd":[[2.3,85.1]],"batl":[[0,2.5,184.86]],"ltp":2.3,"tv":5971.55,"id":9454286}],"tv":27058.09}]}
{"op":"mcm","clk":"4290025596","pt":1632496625931,"mc":[{"id":"1.188075669","rc":[{"batl":[[2,1.81,15.5]],"ltp":1.76,"tv":21086.53,"id":9631939},{"batb":[[0,2.22,301.21]],"ltp":2.3,"tv":5971.55,"id":9454286}]}]}
{"op":"mcm","clk":"4290025726","pt":1632496627143,"mc":[{"id":"1.188075669","rc":[{"batb":[[1,1.68,272.62]],"batl":[[2,1.81,83.58]],"ltp":1.76,"tv":21086.53,"id":9631939},{"batb":[[0,2.24,53.02],[1,2.22,301.21],[2,2.2,175.18]],"batl":[[0,2.48,23.82],[1,2.5,184.86],[2,2.52,200.19]],"ltp":2.3,"tv":5971.55,"id":9454286}]}]}
{"op":"mcm","clk":"4290025748","pt":1632496627348,"mc":[{"id":"1.188075669","rc":[{"batb":[[1,1.69,18.21],[2,1.68,272.62]],"ltp":1.76,"tv":21086.53,"id":9631939},{"batl":[[0,2.46,3.25],[1,2.48,23.82],[2,2.5,184.86]],"ltp":2.3,"tv":5971.55,"id":9454286}]}]}
{"op":"mcm","clk":"4290025916","pt":1632496628959,"mc":[{"id":"1.188075669","rc":[{"batb":[[0,1.67,217.05],[1,1.66,280.69],[2,1.62,192.92]],"batl":[[0,1.82,176.23],[1,1.83,265.77],[2,990,0.35]],"ltp":1.76,"tv":21086.53,"id":9631939},{"batb":[[0,2.22,297.78],[1,2.2,175.18],[2,1.74,409.02]],"batl":[[0,2.5,184.86],[1,2.52,200.19],[2,2.82,237.08]],"ltp":2.3,"tv":5971.55,"id":9454286}]}]}
{"op":"mcm","clk":"4290026156","pt":1632496631332,"mc":[{"id":"1.188075669","rc":[{"batb":[[2,1.64,194.73]],"batl":[[0,1.82,358.01],[2,1.84,180.68]],"ltp":1.76,"tv":21086.53,"id":9631939}]}]}
{"op":"mcm","clk":"4290026651","pt":1632496636139,"mc":[{"id":"1.188075669","rc":[{"batb":[[0,1.67,22.47],[1,1.62,192.92],[2,1.12,2.73]],"ltp":1.76,"tv":21086.53,"id":9631939},{"batl":[[0,2.5,5.57],[1,2.82,237.08],[2,990,0.01]],"ltp":2.3,"tv":5971.55,"id":9454286}]}]}
{"op":"mcm","clk":"4290026934","pt":1632496639156,"mc":[{"id":"1.188075669","rc":[{"batb":[[0,1.76,2218.59],[1,1.74,1037.16],[2,1.73,533.4]],"batl":[[1,1.83,611.41]],"ltp":1.76,"tv":21086.53,"id":9631939},{"batb":[[2,2.18,438.66]],"batl":[[0,2.28,10.85],[1,2.48,12.1],[2,2.5,5.57]],"ltp":2.3,"tv":5971.55,"id":9454286}]}]}
{"op":"mcm","clk":"4290027029","pt":1632496640141,"mc":[{"id":"1.188075669","rc":[{"batb":[[0,1.76,304.7],[1,1.75,147.79],[2,1.74,1037.16]],"batl":[[0,1.81,16.57],[1,1.82,358.01],[2,1.83,611.41]],"ltp":1.76,"tv":21086.53,"id":9631939},{"batl":[[1,2.4,50.7],[2,2.48,12.1]],"ltp":2.3,"tv":5971.55,"id":9454286}]}]}
{"op":"mcm","clk":"4290027227","pt":1632496642048,"mc":[{"id":"1.188075669","rc":[{"batl":[[1,1.82,386.23]],"ltp":1.76,"tv":21086.53,"id":9631939},{"batb":[[0,2.22,320.74]],"batl":[[2,2.48,39.95]],"ltp":2.3,"tv":5971.55,"id":9454286}]}]}
{"op":"mcm","clk":"4290027425","pt":1632496643958,"mc":[{"id":"1.188075669","rc":[{"batl":[[1,2.48,39.95],[2,2.5,5.57]],"ltp":2.3,"tv":5971.55,"id":9454286}]}]}
{"op":"mcm","clk":"4290027545","pt":1632496645165,"mc":[{"id":"1.188075669","rc":[{"batb":[[0,1.78,73],[1,1.76,304.7],[2,1.75,147.79]],"ltp":1.76,"tv":21086.53,"id":9631939}]}]}
{"op":"mcm","clk":"4290027646","pt":1632496646163,"mc":[{"id":"1.188075669","rc":[{"batl":[[1,2.38,148.6],[2,2.4,151.15]],"ltp":2.3,"tv":5971.55,"id":9454286}]}]}
{"op":"mcm","clk":"4290027740","pt":1632496647175,"mc":[{"id":"1.188075669","rc":[{"batb":[[1,1.76,320.68]],"ltp":1.76,"tv":21086.53,"id":9631939},{"batb":[[2,2.18,442.52]],"batl":[[1,2.32,2.86],[2,2.36,54.26]],"ltp":2.3,"tv":5971.55,"id":9454286}]}]}
{"op":"mcm","clk":"4290027858","pt":1632496648384,"mc":[{"id":"1.188075669","rc":[{"batb":[[0,1.78,136]],"ltp":1.76,"tv":21086.53,"id":9631939}]}]}
{"op":"mcm","clk":"4290028079","pt":1632496650783,"mc":[{"id":"1.188075669","rc":[{"batb":[[1,1.76,155.69]],"ltp":1.76,"tv":21086.53,"id":9631939}]}]}
{"op":"mcm","clk":"4290028210","pt":1632496652065,"mc":[{"id":"1.188075669","rc":[{"batb":[[0,1.78,216]],"ltp":1.76,"tv":21086.53,"id":9631939}]}]}
{"op":"mcm","clk":"4290028847","pt":1632496658175,"mc":[{"id":"1.188075669","rc":[{"batb":[[1,1.76,15.98]],"batl":[[0,1.83,14.5],[1,1.84,15.03],[2,1.86,223.28]],"ltp":1.76,"tv":21086.53,"id":9631939},{"batb":[[0,2.22,140.62],[1,2.2,3.47],[2,2.18,3.86]],"batl":[[0,2.32,2.86],[1,2.36,54.26],[2,2.38,148.6]],"ltp":2.3,"tv":5971.55,"id":9454286}]}]}
{"op":"mcm","clk":"4290028956","pt":1632496659181,"mc":[{"id":"1.188075669","rc":[{"batb":[[0,1.76,15.98],[1,1.74,15.02],[2,1.73,223.69]],"batl":[[0,1.84,15.03],[1,1.86,223.28],[2,1.87,234.1]],"ltp":1.76,"tv":21086.53,"id":9631939},{"batb":[[0,2.18,3.86],[1,2.16,143.37],[2,2.14,382.79]],"batl":[[1,2.36,2.82]],"ltp":2.3,"tv":5971.55,"id":9454286}]}]}
{"op":"mcm","clk":"4290028987","pt":1632496659486,"mc":[{"id":"1.188075669","rc":[{"batb":[[0,1.74,15.02],[1,1.73,223.69],[2,1.72,249.97]],"ltp":1.76,"tv":21086.53,"id":9631939},{"batl":[[0,2.36,2.82],[1,2.38,148.6],[2,2.4,151.15]],"ltp":2.3,"tv":5971.55,"id":9454286}]}]}
{"op":"mcm","clk":"4290029158","pt":1632496661077,"mc":[{"id":"1.188075669","rc":[{"batl":[[1,1.86,387.46]],"ltp":1.76,"tv":21086.53,"id":9631939}]}]}
{"op":"mcm","clk":"4290029344","pt":1632496662869,"mc":[{"id":"1.188075669","rc":[{"batb":[[0,1.74,19.02],[1,1.73,227.69]],"ltp":1.76,"tv":21086.53,"id":9631939},{"batl":[[0,2.36,5.82]],"ltp":2.3,"tv":5971.55,"id":9454286}]}]}
{"op":"mcm","clk":"4290029557","pt":1632496665096,"mc":[{"id":"1.188075669","rc":[{"batl":[[0,1.83,16.5],[1,1.84,15.03],[2,1.86,387.46]],"ltp":1.76,"tv":21086.53,"id":9631939},{"batb":[[0,2.2,3.27],[1,2.18,3.86],[2,2.16,143.37]],"ltp":2.3,"tv":5971.55,"id":9454286}]}]}
{"op":"mcm","clk":"4290029647","pt":1632496666093,"mc":[{"id":"1.188075669","rc":[{"batb":[[0,1.76,14.48],[1,1.74,19.02],[2,1.73,227.69]],"batl":[[0,1.84,15.03],[1,1.86,387.46],[2,1.87,234.1]],"ltp":1.76,"tv":21086.53,"id":9631939},{"batb":[[0,2.18,3.86],[1,2.16,143.37],[2,2.14,382.79]],"batl":[[0,2.32,3.61],[1,2.36,5.82],[2,2.38,148.6]],"ltp":2.3,"tv":5971.55,"id":9454286}]}]}
{"op":"mcm","clk":"4290029684","pt":1632496666466,"mc":[{"id":"1.188075669","rc":[{"batb":[[0,1.74,19.02],[1,1.73,227.69],[2,1.72,249.97]],"ltp":1.76,"tv":21086.53,"id":9631939},{"batl":[[0,2.36,5.82],[1,2.38,148.6],[2,2.4,151.15]],"ltp":2.3,"tv":5971.55,"id":9454286}]}]}
{"op":"mcm","clk":"4290030230","pt":1632496671811,"mc":[{"id":"1.188075669","rc":[{"batl":[[1,990,0.35],[2,1.87,0]],"ltp":1.76,"tv":21086.53,"id":9631939},{"batb":[[1,2.14,153.61],[2,1.74,409.02]],"ltp":2.3,"tv":5971.55,"id":9454286}]}]}
{"op":"mcm","clk":"4290030379","pt":1632496673203,"mc":[{"id":"1.188075669","rc":[{"batb":[[0,1.76,16.73],[1,1.74,15.02],[2,1.73,223.69]],"ltp":1.76,"tv":21086.53,"id":9631939},{"batb":[[2,1.01,139.76]],"batl":[[0,2.32,3.36],[1,2.36,2.82],[2,2.38,148.6]],"ltp":2.3,"tv":5971.55,"id":9454286}]}]}
{"op":"mcm","clk":"4290030409","pt":1632496673518,"mc":[{"id":"1.188075669","rc":[{"batb":[[0,1.74,15.02],[1,1.73,223.69],[2,1.72,249.97]],"ltp":1.76,"tv":21086.53,"id":9631939},{"batl":[[0,2.36,2.82],[1,2.38,148.6],[2,2.4,151.15]],"ltp":2.3,"tv":5971.55,"id":9454286}]}]}
{"op":"mcm","clk":"4290030568","pt":1632496675224,"mc":[{"id":"1.188075669","rc":[{"batb":[[1,1.7,151.17],[2,1.69,36.69]],"batl":[[0,1.75,293.88],[1,1.76,24.65],[2,1.77,211.51]],"ltp":1.76,"tv":21086.53,"id":9631939},{"batb":[[0,2.3,415.76],[1,2.28,405.59],[2,2.26,403.54]],"batl":[[0,2.36,8.75],[1,2.4,151.15],[2,2.46,181.96]],"ltp":2.3,"tv":5971.55,"id":9454286}]}]}
{"op":"mcm","clk":"4290030678","pt":1632496676205,"mc":[{"id":"1.188075669","rc":[{"batb":[[0,2.34,121.05],[1,2.3,415.76],[2,2.28,405.59]],"ltp":2.3,"tv":5971.55,"id":9454286}]}]}
{"op":"mcm","clk":"4290030976","pt":1632496679127,"mc":[{"id":"1.188075669","rc":[{"trd":[[1.75,457.54]],"batl":[[0,1.75,117.28]],"ltp":1.75,"tv":21439.73,"id":9631939}],"tv":27411.29}]}
{"op":"mcm","clk":"4290031064","pt":1632496679808,"mc":[{"id":"1.188075669","rc":[{"trd":[[2.34,16.61]],"batb":[[0,2.34,112.75]],"ltp":2.34,"tv":5988.17,"id":9454286}],"tv":27427.9}]}
{"op":"mcm","clk":"4290031382","pt":1632496682420,"mc":[{"id":"1.188075669","rc":[{"trd":[[1.74,243.78]],"batb":[[0,1.74,258.02]],"ltp":1.74,"tv":21449.73,"id":9631939}],"tv":27437.9}]}
{"op":"mcm","clk":"4290031816","pt":1632496686138,"mc":[{"id":"1.188075669","rc":[{"trd":[[1.74,262.38]],"batb":[[0,1.74,403.72]],"ltp":1.74,"tv":21468.33,"id":9631939}],"tv":27456.5}]}
{"op":"mcm","clk":"4290032327","pt":1632496690728,"mc":[{"id":"1.188075669","rc":[{"trd":[[1.75,462.24]],"batl":[[0,1.75,114.93]],"ltp":1.75,"tv":21473.02,"id":9631939}],"tv":27461.19}]}
{"op":"mcm","clk":"4290032595","pt":1632496693050,"mc":[{"id":"1.188075669","rc":[{"batl":[[1,1.77,211.51],[2,1.8,196.56]],"ltp":1.75,"tv":21473.02,"id":9631939},{"batb":[[1,2.28,2.05],[2,2.26,150.44]],"batl":[[0,2.36,2.82],[2,2.48,52.3]],"ltp":2.34,"tv":5988.17,"id":9454286}]}]}
{"op":"mcm","clk":"4290032666","pt":1632496693632,"mc":[{"id":"1.188075669","rc":[{"batb":[[0,1.74,403],[1,1.68,89.87],[2,1.67,17.47]],"batl":[[0,1.8,196.56],[1,1.81,221.44],[2,1.82,77.25]],"ltp":1.75,"tv":21473.02,"id":9631939},{"batb":[[0,2.26,150.44],[1,2.24,310.54],[2,2.22,49.18]],"batl":[[0,2.48,52.3],[1,2.5,2.57],[2,2.52,2.51]],"ltp":2.34,"tv":5988.17,"id":9454286}]}]}
{"op":"mcm","clk":"4290032809","pt":1632496694750,"mc":[{"id":"1.188075669","rc":[{"batb":[[0,1.66,20.28],[1,1.65,273.55],[2,1.64,311.24]],"batl":[[2,1.82,17.25]],"ltp":1.75,"tv":21473.02,"id":9631939},{"batb":[[2,2.2,3]],"batl":[[0,2.52,2.51],[1,2.54,169.86],[2,2.56,142.05]],"ltp":2.34,"tv":5988.17,"id":9454286}]}]}
{"op":"mcm","clk":"4290033014","pt":1632496696657,"mc":[{"id":"1.188075669","rc":[{"batb":[[2,2.2,6.42]],"ltp":2.34,"tv":5988.17,"id":9454286}]}]}
{"op":"mcm","clk":"4290033176","pt":1632496698145,"mc":[{"id":"1.188075669","rc":[{"batb":[[0,1.68,22.11],[1,1.67,5],[2,1.66,26.28]],"ltp":1.75,"tv":21473.02,"id":9631939},{"batl":[[0,2.48,5.99],[1,2.52,6.51],[2,2.54,169.86]],"ltp":2.34,"tv":5988.17,"id":9454286}]}]}
{"op":"mcm","clk":"4290033261","pt":1632496698941,"mc":[{"id":"1.188075669","rc":[{"batb":[[0,1.68,236.54],[2,1.66,278.39]],"batl":[[0,1.74,176.18],[1,1.76,208.31],[2,1.8,196.56]],"ltp":1.75,"tv":21473.02,"id":9631939},{"batl":[[0,2.48,3]],"ltp":2.34,"tv":5988.17,"id":9454286}]}]}
{"op":"mcm","clk":"4290033398","pt":1632496700349,"mc":[{"id":"1.188075669","rc":[{"batb":[[1,1.67,36.64]],"batl":[[2,1.79,63.03]],"ltp":1.75,"tv":21473.02,"id":9631939},{"batb":[[0,2.28,44.51],[1,2.26,150.44],[2,2.24,310.54]],"batl":[[1,2.5,12.55],[2,2.52,6.51]],"ltp":2.34,"tv":5988.17,"id":9454286}]}]}
{"op":"mcm","clk":"4290033569","pt":1632496701943,"mc":[{"id":"1.188075669","rc":[{"batb":[[0,1.68,24.36],[1,1.67,5],[2,1.66,26.28]],"batl":[[0,1.8,196.56],[1,1.81,221.44],[2,1.82,17.25]],"ltp":1.75,"tv":21473.02,"id":9631939},{"batb":[[0,2.26,150.44],[1,2.24,310.54],[2,2.2,6.42]],"batl":[[0,2.48,5.99],[1,2.52,6.51],[2,2.54,169.86]],"ltp":2.34,"tv":5988.17,"id":9454286}]}]}
{"op":"mcm","clk":"4290033603","pt":1632496702259,"mc":[{"id":"1.188075669","rc":[{"batb":[[0,1.68,5]],"ltp":1.75,"tv":21473.02,"id":9631939},{"batl":[[0,2.48,3]],"ltp":2.34,"tv":5988.17,"id":9454286}]}]}
{"op":"mcm","clk":"4290033823","pt":1632496704758,"mc":[{"id":"1.188075669","rc":[{"batl":[[1,1.81,430.63]],"ltp":1.75,"tv":21473.02,"id":9631939}]}]}
{"op":"mcm","clk":"4290034316","pt":1632496709152,"mc":[{"id":"1.188075669","rc":[{"batb":[[0,1.68,23.36]],"ltp":1.75,"tv":21473.02,"id":9631939},{"batl":[[0,2.48,5.49]],"ltp":2.34,"tv":5988.17,"id":9454286}]}]}
{"op":"mcm","clk":"4290034384","pt":1632496709772,"mc":[{"id":"1.188075669","rc":[{"batb":[[0,1.68,5],[1,1.66,20.28],[2,1.65,273.55]],"ltp":1.75,"tv":21473.02,"id":9631939},{"batl":[[0,2.48,3],[1,2.52,2.51]],"ltp":2.34,"tv":5988.17,"id":9454286}]}]}
{"op":"mcm","clk":"4290034669","pt":1632496712680,"mc":[{"id":"1.188075669","rc":[{"batb":[[1,1.67,5],[2,1.66,20.28]],"ltp":1.75,"tv":21473.02,"id":9631939},{"batl":[[2,2.92,226.83]],"ltp":2.34,"tv":5988.17,"id":9454286}]}]}
{"op":"mcm","clk":"4290034931","pt":1632496715174,"mc":[{"id":"1.188075669","rc":[{"batb":[[0,1.76,19.52],[1,1.75,2177.23],[2,1.73,218.13]],"ltp":1.75,"tv":21473.02,"id":9631939},{"batb":[[1,2.24,509.27]],"batl":[[0,2.48,17.84]],"ltp":2.34,"tv":5988.17,"id":9454286}]}]}
{"op":"mcm","clk":"4290035048","pt":1632496716183,"mc":[{"id":"1.188075669","rc":[{"batb":[[1,1.75,283.78],[2,1.74,151.59]],"batl":[[0,1.8,213.23]],"ltp":1.75,"tv":21473.02,"id":9631939},{"batl":[[0,2.38,51.07],[1,2.46,19],[2,2.48,17.84]],"ltp":2.34,"tv":5988.17,"id":9454286}]}]}
{"op":"mcm","clk":"4290035152","pt":1632496717078,"mc":[{"id":"1.188075669","rc":[{"batl":[[0,2.46,4],[1,2.48,17.84],[2,2.52,2.51]],"ltp":2.34,"tv":5988.17,"id":9454286}]}]}
{"op":"mcm","clk":"4290035369","pt":1632496719081,"mc":[{"id":"1.188075669","rc":[{"batb":[[0,1.76,95.52]],"batl":[[0,1.8,198.51]],"ltp":1.75,"tv":21473.02,"id":9631939},{"batb":[[1,2.24,505.75]],"ltp":2.34,"tv":5988.17,"id":9454286}]}]}
{"op":"mcm","clk":"4290035483","pt":1632496720096,"mc":[{"id":"1.188075669","rc":[{"trd":[[2.26,28.88]],"batb":[[0,2.26,136.03]],"batl":[[0,2.42,50.35],[1,2.46,4],[2,2.48,17.84]],"ltp":2.26,"tv":6016.99,"id":9454286}],"tv":27490.02}]}
{"op":"mcm","clk":"4290035736","pt":1632496722196,"mc":[{"id":"1.188075669","rc":[{"batb":[[0,1.76,155.52],[2,1.74,166.61]],"batl":[[1,1.81,444.55]],"ltp":1.75,"tv":21473.02,"id":9631939},{"batb":[[2,2.22,2.93]],"batl":[[0,2.36,3.07],[1,2.4,2.99],[2,2.42,50.35]],"ltp":2.26,"tv":6016.99,"id":9454286}]}]}
{"op":"mcm","clk":"4290035811","pt":1632496722984,"mc":[{"id":"1.188075669","rc":[{"batl":[[1,2.38,139.45],[2,2.4,210.54]],"ltp":2.26,"tv":6016.99,"id":9454286}]}]}
{"op":"mcm","clk":"4290035896","pt":1632496723685,"mc":[{"id":"1.188075669","rc":[{"trd":[[1.76,136.48]],"batb":[[0,1.76,137.95]],"ltp":1.76,"tv":21508.14,"id":9631939}],"tv":27525.14}]}
{"op":"mcm","clk":"4290036262","pt":1632496727200,"mc":[{"id":"1.188075669","rc":[{"trd":[[1.76,138.64]],"batb":[[0,1.76,136.87],[1,1.75,120.55]],"ltp":1.76,"tv":21510.3,"id":9631939}],"tv":27527.3}]}
{"op":"mcm","clk":"4290036551","pt":1632496730211,"mc":[{"id":"1.188075669","rc":[{"batl":[[0,1.8,215.39]],"ltp":1.76,"tv":21510.3,"id":9631939}]}]}
{"op":"mcm","clk":"4290036604","pt":1632496730591,"mc":[{"id":"1.188075669","rc":[{"batl":[[1,2.38,190.52]],"ltp":2.26,"tv":6016.99,"id":9454286}]}]}
{"op":"mcm","clk":"4290036932","pt":1632496733911,"mc":[{"id":"1.188075669","rc":[{"batb":[[0,1.76,136]],"ltp":1.76,"tv":21510.3,"id":9631939},{"batb":[[1,2.24,499.12]],"ltp":2.26,"tv":6016.99,"id":9454286}]}]}
{"op":"mcm","clk":"4290037539","pt":1632496739936,"mc":[{"id":"1.188075669","rc":[{"batb":[[2,1.74,180.27]],"batl":[[0,1.78,11.27],[1,1.8,215.39],[2,1.81,444.55]],"ltp":1.76,"tv":21510.3,"id":9631939}]}]}
{"op":"mcm","clk":"4290037732","pt":1632496742138,"mc":[{"id":"1.188075669","rc":[{"batb":[[2,1.74,166.61]],"batl":[[0,1.8,198.72],[1,1.81,444.55],[2,1.82,17.25]],"ltp":1.76,"tv":21510.3,"id":9631939},{"batb":[[1,2.24,307.02]],"ltp":2.26,"tv":6016.99,"id":9454286}]}]}
{"op":"mcm","clk":"4290037808","pt":1632496742930,"mc":[{"id":"1.188075669","rc":[{"batb":[[1,1.72,332.22],[2,1.71,242.93]],"batl":[[0,1.8,16.88],[1,1.83,14.5],[2,1.85,246.33]],"ltp":1.76,"tv":21510.3,"id":9631939},{"batb":[[0,2.2,3.42],[1,2.18,182.93],[2,2.16,348.27]],"batl":[[0,2.38,190.52],[1,2.4,180.95],[2,2.46,4]],"ltp":2.26,"tv":6016.99,"id":9454286}]}]}
{"op":"mcm","clk":"4290037836","pt":1632496743257,"mc":[{"id":"1.188075669","rc":[{"batb":[[0,1.72,261.51],[1,1.71,242.93],[2,1.69,4]],"ltp":1.76,"tv":21510.3,"id":9631939},{"batl":[[0,2.38,139.45]],"ltp":2.26,"tv":6016.99,"id":9454286}]}]}
{"op":"mcm","clk":"4290038020","pt":1632496745122,"mc":[{"id":"1.188075669","rc":[{"batb":[[0,1.76,202],[1,1.73,16.76],[2,1.72,261.51]],"batl":[[2,1.85,436.72]],"ltp":1.76,"tv":21510.3,"id":9631939},{"batl":[[0,2.38,142.28],[2,2.42,3.06]],"ltp":2.26,"tv":6016.99,"id":9454286}]}]}
{"op":"mcm","clk":"4290038068","pt":1632496745641,"mc":[{"id":"1.188075669","rc":[{"batb":[[0,1.72,261.51],[1,1.71,259.12],[2,1.69,142.95]],"ltp":1.76,"tv":21510.3,"id":9631939},{"batl":[[0,2.38,139.45]],"ltp":2.26,"tv":6016.99,"id":9454286}]}]}
{"op":"mcm","clk":"4290038171","pt":1632496746741,"mc":[{"id":"1.188075669","rc":[{"batb":[[0,1.72,266.51],[1,1.71,265.12]],"ltp":1.76,"tv":21510.3,"id":9631939},{"batl":[[0,2.38,143.45]],"ltp":2.26,"tv":6016.99,"id":9454286}]}]}
{"op":"mcm","clk":"4290038397","pt":1632496748943,"mc":[{"id":"1.188075669","rc":[{"batb":[[0,1.74,17.52],[1,1.72,266.51],[2,1.71,265.12]],"batl":[[2,990,0.35]],"ltp":1.76,"tv":21510.3,"id":9631939},{"batb":[[1,2.16,150.32],[2,1.74,409.02]],"batl":[[0,2.36,3.32],[1,2.38,143.45],[2,2.4,180.95]],"ltp":2.26,"tv":6016.99,"id":9454286}]}]}
{"op":"mcm","clk":"4290038583","pt":1632496750737,"mc":[{"id":"1.188075669","rc":[{"batb":[[0,1.72,261.51],[1,1.71,259.12],[2,1.69,138.95]],"ltp":1.76,"tv":21510.3,"id":9631939},{"batl":[[0,2.38,139.45],[1,2.4,180.95],[2,2.42,3.06]],"ltp":2.26,"tv":6016.99,"id":9454286}]}]}
{"op":"mcm","clk":"4290038722","pt":1632496752156,"mc":[{"id":"1.188075669","rc":[{"trd":[[1.72,587.18]],"batb":[[0,1.72,8.85],[1,1.71,16.19]],"batl":[[0,1.74,329.19],[1,1.76,768.82],[2,1.77,541.1]],"ltp":1.72,"tv":21527.28,"id":9631939},{"batb":[[0,2.32,242.62],[1,2.28,3.66],[2,2.2,3.42]],"batl":[[0,2.36,4],[1,2.4,2.99]],"ltp":2.26,"tv":6016.99,"id":9454286}],"tv":27544.28}]}
{"op":"mcm","clk":"4290038796","pt":1632496752861,"mc":[{"id":"1.188075669","rc":[{"batb":[[0,2.36,118.27],[1,2.32,242.62],[2,2.28,3.66]],"batl":[[0,2.4,2.99],[1,2.42,3.06],[2,2.46,11]],"ltp":2.26,"tv":6016.99,"id":9454286}]}]}
{"op":"mcm","clk":"4290039050","pt":1632496755144,"mc":[{"id":"1.188075669","rc":[{"trd":[[1.72,599.18],[1.74,1081.3]],"batb":[[0,1.72,2.85]],"batl":[[0,1.76,768.82],[1,1.77,541.1],[2,1.78,527.34]],"ltp":1.74,"tv":22358.2,"id":9631939},{"trd":[[2.36,118.44]],"batb":[[0,2.32,242.62],[1,2.28,3.66],[2,2.26,137.11]],"ltp":2.36,"tv":6135.26,"id":9454286}],"tv":28493.47}]}
{"op":"mcm","clk":"4290039144","pt":1632496755945,"mc":[{"id":"1.188075669","rc":[{"batl":[[0,1.76,560.37]],"ltp":1.74,"tv":22358.2,"id":9631939}]}]}
{"op":"mcm","clk":"4290039361","pt":1632496758141,"mc":[{"id":"1.188075669","rc":[{"batb":[[0,1.72,166.85]],"ltp":1.74,"tv":22358.2,"id":9631939}]}]}
{"op":"mcm","clk":"4290039429","pt":1632496758864,"mc":[{"id":"1.188075669","rc":[{"batb":[[2,1.69,223.22]],"batl":[[0,1.75,234.52],[1,1.76,560.37],[2,1.77,745.26]],"ltp":1.74,"tv":22358.2,"id":9631939},{"batb":[[0,2.34,23.54],[1,2.32,242.62],[2,2.28,169.63]],"ltp":2.36,"tv":6135.26,"id":9454286}]}]}
{"op":"mcm","clk":"4290039628","pt":1632496761049,"mc":[{"id":"1.188075669","rc":[{"batb":[[2,1.69,238.43]],"ltp":1.74,"tv":22358.2,"id":9631939},{"batl":[[2,2.46,14.25]],"ltp":2.36,"tv":6135.26,"id":9454286}]}]}
{"op":"mcm","clk":"4290039701","pt":1632496761870,"mc":[{"id":"1.188075669","rc":[{"batl":[[2,2.46,3.25]],"ltp":2.36,"tv":6135.26,"id":9454286}]}]}
{"op":"mcm","clk":"4290039981","pt":1632496764881,"mc":[{"id":"1.188075669","rc":[{"trd":[[1.72,604.18]],"batb":[[0,1.72,164.35]],"ltp":1.72,"tv":22363.2,"id":9631939},{"batb":[[0,2.36,7.38],[1,2.34,23.54],[2,2.32,242.62]],"batl":[[1,2.42,10.68]],"ltp":2.36,"tv":6135.26,"id":9454286}],"tv":28498.47}]}
{"op":"mcm","clk":"4290040316","pt":1632496768177,"mc":[{"id":"1.188075669","rc":[{"batb":[[0,1.72,109],[1,1.67,73.3],[2,1.66,20.28]],"batl":[[0,1.79,261.24],[1,1.8,344.36],[2,1.81,19.71]],"ltp":1.72,"tv":22363.2,"id":9631939},{"batb":[[0,2.28,165.97],[1,2.26,316.07],[2,2.24,51.65]],"batl":[[0,2.5,48.98],[1,2.52,2.51],[2,2.54,2.75]],"ltp":2.36,"tv":6135.26,"id":9454286}]}]}
{"op":"mcm","clk":"4290040338","pt":1632496768374,"mc":[{"id":"1.188075669","rc":[{"batb":[[0,1.67,73.3],[1,1.66,20.28],[2,1.65,19.73]],"batl":[[0,1.79,256.24]],"ltp":1.72,"tv":22363.2,"id":9631939},{"batb":[[1,2.26,312.07]],"ltp":2.36,"tv":6135.26,"id":9454286}]}]}
{"op":"mcm","clk":"4290040447","pt":1632496769502,"mc":[{"id":"1.188075669","rc":[{"batb":[[0,1.65,19.73],[1,1.64,296.78],[2,1.63,282.09]],"batl":[[1,1.8,284.36]],"ltp":1.72,"tv":22363.2,"id":9631939},{"batb":[[2,2.24,3.27]],"batl":[[0,2.54,2.75],[1,2.56,154.26],[2,2.58,154.89]],"ltp":2.36,"tv":6135.26,"id":9454286}]}]}
{"op":"mcm","clk":"4290040616","pt":1632496771186,"mc":[{"id":"1.188075669","rc":[{"batb":[[1,2.26,178.96],[2,2.24,139.42]],"ltp":2.36,"tv":6135.26,"id":9454286}]}]}
{"op":"mcm","clk":"4290040711","pt":1632496772000,"mc":[{"id":"1.188075669","rc":[{"batb":[[0,1.66,4],[1,1.65,19.73],[2,1.64,296.78]],"ltp":1.72,"tv":22363.2,"id":9631939}]}]}
{"op":"mcm","clk":"4290040825","pt":1632496773075,"mc":[{"id":"1.188075669","rc":[{"batb":[[1,1.65,24.73],[2,1.64,300.78]],"batl":[[0,1.79,826.97]],"ltp":1.72,"tv":22363.2,"id":9631939},{"batl":[[0,2.52,3],[1,2.54,5.75],[2,2.56,154.26]],"ltp":2.36,"tv":6135.26,"id":9454286}]}]}
{"op":"mcm","clk":"4290040894","pt":1632496773872,"mc":[{"id":"1.188075669","rc":[{"batb":[[0,1.68,176.34],[1,1.66,255.36],[2,1.65,24.73]],"batl":[[0,1.74,227.49],[1,1.76,207.68],[2,1.79,256.24]],"ltp":1.72,"tv":22363.2,"id":9631939}]}]}
{"op":"mcm","clk":"4290041017","pt":1632496775081,"mc":[{"id":"1.188075669","rc":[{"batb":[[1,1.67,19.47],[2,1.66,275.36]],"batl":[[2,1.78,85.3]],"ltp":1.72,"tv":22363.2,"id":9631939},{"batb":[[0,2.3,43.42],[1,2.28,169.13],[2,2.26,178.96]],"batl":[[0,2.5,2.75],[1,2.52,16.75],[2,2.54,5.75]],"ltp":2.36,"tv":6135.26,"id":9454286}]}]}
{"op":"mcm","clk":"4290041071","pt":1632496775701,"mc":[{"id":"1.188075669","rc":[{"batl":[[2,1.78,21.25]],"ltp":1.72,"tv":22363.2,"id":9631939}]}]}
{"op":"mcm","clk":"4290041269","pt":1632496778070,"mc":[{"id":"1.188075669","rc":[{"batb":[[0,1.66,4],[1,1.65,24.73],[2,1.64,300.78]],"batl":[[0,1.79,256.24],[1,1.8,284.36],[2,1.81,19.71]],"ltp":1.72,"tv":22363.2,"id":9631939},{"batb":[[0,2.28,165.97],[1,2.26,178.96],[2,2.24,139.42]],"batl":[[0,2.52,3],[1,2.54,5.75],[2,2.56,154.26]],"ltp":2.36,"tv":6135.26,"id":9454286}]}]}
{"op":"mcm","clk":"4290041389","pt":1632496779195,"mc":[{"id":"1.188075669","rc":[{"batb":[[0,1.74,1.41],[1,1.66,4],[2,1.65,24.73]],"ltp":1.72,"tv":22363.2,"id":9631939}]}]}
{"op":"mcm","clk":"4290041489","pt":1632496780192,"mc":[{"id":"1.188075669","rc":[{"batl":[[0,1.79,20.69],[1,1.8,36.35]],"ltp":1.72,"tv":22363.2,"id":9631939},{"batb":[[0,2.26,3.21],[1,2.24,139.42],[2,2.22,3.34]],"ltp":2.36,"tv":6135.26,"id":9454286}]}]}
{"op":"mcm","clk":"4290041544","pt":1632496780777,"mc":[{"id":"1.188075669","rc":[{"batl":[[0,1.8,16.88],[1,990,0.35],[2,1.81,0]],"ltp":1.72,"tv":22363.2,"id":9631939},{"batb":[[0,2.24,139.42],[1,1.74,409.02],[2,1.01,139.76]],"ltp":2.36,"tv":6135.26,"id":9454286}]}]}
{"op":"mcm","clk":"4290041677","pt":1632496782203,"mc":[{"id":"1.188075669","rc":[{"batb":[[1,1.65,19.73],[2,1.64,296.78]],"ltp":1.72,"tv":22363.2,"id":9631939},{"batb":[[1,1.01,139.76],[2,1.01,0]],"batl":[[0,2.54,2.75],[1,2.56,154.26],[2,2.58,154.89]],"ltp":2.36,"tv":6135.26,"id":9454286}]}]}
{"op":"mcm","clk":"4290041756","pt":1632496783099,"mc":[{"id":"1.188075669","rc":[{"trd":[[1.74,1084.12]],"batb":[[0,1.65,19.73],[1,1.64,296.78],[2,1.63,412.59]],"batl":[[0,1.68,2395.67],[1,1.69,1414.57],[2,1.7,1647.01]],"ltp":1.74,"tv":22366.02,"id":9631939},{"batb":[[0,2.5,7.32],[1,2.42,5.63],[2,2.24,139.42]],"batl":[[1,2.56,159.84]],"ltp":2.36,"tv":6135.26,"id":9454286}],"tv":28501.28}]}
{"op":"mcm","clk":"4290041852","pt":1632496784211,"mc":[{"id":"1.188075669","rc":[{"batl":[[0,1.68,389.95],[1,1.69,565.82],[2,1.7,823.23]],"ltp":1.74,"tv":22366.02,"id":9631939},{"batb":[[0,2.5,107.87],[2,2.36,44.11]],"ltp":2.36,"tv":6135.26,"id":9454286}]}]}
{"op":"mcm","clk":"4290042022","pt":1632496786003,"mc":[{"id":"1.188075669","rc":[{"batb":[[1,2.44,4],[2,2.42,9.63]],"ltp":2.36,"tv":6135.26,"id":9454286}]}]}
{"op":"mcm","clk":"4290042218","pt":1632496788117,"mc":[{"id":"1.188075669","rc":[{"batb":[[0,1.65,142.73]],"batl":[[0,1.68,424.2]],"ltp":1.74,"tv":22366.02,"id":9631939},{"trd":[[2.5,65.5]],"batb":[[0,2.5,98.62]],"ltp":2.5,"tv":6153.76,"id":9454286}],"tv":28519.78}]}
{"op":"mcm","clk":"4290042595","pt":1632496792137,"mc":[{"id":"1.188075669","rc":[{"batb":[[0,1.65,217.73]],"ltp":1.74,"tv":22366.02,"id":9631939}]}]}
{"op":"mcm","clk":"4290042632","pt":1632496792401,"mc":[{"id":"1.188075669","rc":[{"trd":[[1.67,70.52]],"ltp":1.67,"tv":22366.19,"id":9631939},{"trd":[[2.5,65.61]],"batb":[[0,2.5,98.51]],"ltp":2.5,"tv":6153.87,"id":9454286}],"tv":28520.06}]}
{"op":"mcm","clk":"4290042882","pt":1632496794912,"mc":[{"id":"1.188075669","rc":[{"batl":[[0,1.68,251.17]],"ltp":1.67,"tv":22366.19,"id":9631939}]}]}
{"op":"mcm","clk":"4290042922","pt":1632496795320,"mc":[{"id":"1.188075669","rc":[{"batb":[[0,1.65,328.73]],"ltp":1.67,"tv":22366.19,"id":9631939}]}]}
{"op":"mcm","clk":"4290043077","pt":1632496797128,"mc":[{"id":"1.188075669","rc":[{"batl":[[1,1.7,256.4],[2,1.74,321.1]],"ltp":1.67,"tv":22366.19,"id":9631939},{"batl":[[1,2.56,154.26]],"ltp":2.5,"tv":6153.87,"id":9454286}]}]}
{"op":"mcm","clk":"4290043130","pt":1632496797710,"mc":[{"id":"1.188075669","rc":[{"batb":[[0,1.65,309],[1,1.61,76.82],[2,1.58,20.56]],"batl":[[0,1.74,321.1],[1,1.75,228.11],[2,1.78,23.75]],"ltp":1.67,"tv":22366.19,"id":9631939},{"batb":[[0,2.36,189.23],[1,2.34,314.86],[2,2.32,3.14]],"batl":[[0,2.64,46.85],[1,2.74,2.48],[2,2.76,160.99]],"ltp":2.5,"tv":6153.87,"id":9454286}]}]}
{"op":"mcm","clk":"4290043189","pt":1632496798356,"mc":[{"id":"1.188075669","rc":[{"batb":[[0,1.58,20.56],[1,1.56,219.15],[2,1.55,345.85]],"batl":[[0,1.74,261.1]],"ltp":1.67,"tv":22366.19,"id":9631939},{"batb":[[0,2.36,145.12]],"batl":[[0,2.74,2.48],[1,2.76,160.99],[2,2.78,194.23]],"ltp":2.5,"tv":6153.87,"id":9454286}]}]}
{"op":"mcm","clk":"4290043384","pt":1632496800209,"mc":[{"id":"1.188075669","rc":[{"batb":[[2,1.55,483.54]],"batl":[[0,1.74,446.73],[2,1.76,207.89]],"ltp":1.67,"tv":22366.19,"id":9631939}]}]}
{"op":"mcm","clk":"4290043438","pt":1632496800737,"mc":[{"id":"1.188075669","rc":[{"batb":[[0,1.67,1.06],[2,1.55,345.85]],"batl":[[0,1.74,261.1],[2,1.78,23.75]],"ltp":1.67,"tv":22366.19,"id":9631939},{"batl":[[0,2.76,160.99],[1,2.78,194.23],[2,2.82,2.36]],"ltp":2.5,"tv":6153.87,"id":9454286}]}]}
{"op":"mcm","clk":"4290043510","pt":1632496801540,"mc":[{"id":"1.188075669","rc":[{"batb":[[1,1.58,6],[2,1.57,5]],"ltp":1.67,"tv":22366.19,"id":9631939},{"batl":[[0,2.74,3],[1,2.76,160.99],[2,2.78,194.23]],"ltp":2.5,"tv":6153.87,"id":9454286}]}]}
{"op":"mcm","clk":"4290043780","pt":1632496804123,"mc":[{"id":"1.188075669","rc":[{"trd":[[1.67,72.64]],"batb":[[0,1.61,180.32],[1,1.6,144.31],[2,1.58,27.56]],"batl":[[0,1.65,905.9],[1,1.66,192.09],[2,1.68,242.61]],"ltp":1.67,"tv":22368.3,"id":9631939},{"batl":[[0,2.74,5.25],[1,2.76,163.99]],"ltp":2.5,"tv":6153.87,"id":9454286}],"tv":28522.18}]}
{"op":"mcm","clk":"4290043858","pt":1632496804948,"mc":[{"id":"1.188075669","rc":[{"batb":[[0,1.58,27.56],[1,1.57,5],[2,1.56,224.15]],"batl":[[1,1.74,261.1],[2,1.75,228.11]],"ltp":1.67,"tv":22368.3,"id":9631939}]}]}
{"op":"mcm","clk":"4290043915","pt":1632496805424,"mc":[{"id":"1.188075669","rc":[{"batb":[[0,1.58,6]],"ltp":1.67,"tv":22368.3,"id":9631939},{"batl":[[0,2.74,3]],"ltp":2.5,"tv":6153.87,"id":9454286}]}]}
{"op":"mcm","clk":"4290044229","pt":1632496808124,"mc":[{"id":"1.188075669","rc":[{"batb":[[0,1.62,597],[1,1.58,6],[2,1.57,5]],"batl":[[1,1.71,1.76],[2,1.74,446.16]],"ltp":1.67,"tv":22368.3,"id":9631939}]}]}
{"op":"mcm","clk":"4290044307","pt":1632496809026,"mc":[{"id":"1.188075669","rc":[{"batb":[[0,1.58,6],[1,1.57,5],[2,1.56,224.15]],"ltp":1.67,"tv":22368.3,"id":9631939}]}]}
{"op":"mcm","clk":"4290044671","pt":1632496812556,"mc":[{"id":"1.188075669","rc":[{"trd":[[1.71,165.96]],"batl":[[0,1.71,1.75],[1,1.74,446.16],[2,1.75,228.11]],"ltp":1.71,"tv":22368.32,"id":9631939}],"tv":28522.2}]}
{"op":"mcm","clk":"4290044982","pt":1632496815960,"mc":[{"id":"1.188075669","rc":[{"trd":[[1.58,254.15]],"batb":[[0,1.57,5],[1,1.56,219.15],[2,1.55,484.17]],"batl":[[0,1.58,24.94],[1,1.71,1.75],[2,1.74,185.44]],"ltp":1.58,"tv":22418.44,"id":9631939},{"batb":[[0,2.34,119.45],[1,2.28,3.66],[2,2.26,3]],"batl":[[1,2.76,160.99]],"ltp":2.5,"tv":6153.87,"id":9454286}],"tv":28572.32}]}
{"op":"mcm","clk":"4290045012","pt":1632496816236,"mc":[{"id":"1.188075669","rc":[{"batl":[[2,1.78,3.38]],"ltp":1.58,"tv":22418.44,"id":9631939}]}]}
{"op":"mcm","clk":"4290045292","pt":1632496819155,"mc":[{"id":"1.188075669","rc":[{"trd":[[1.58,304.03]],"batb":[[1,1.56,226.15]],"batl":[[0,1.59,172.37],[1,1.6,162.07],[2,1.63,18.4]],"ltp":1.58,"tv":22468.32,"id":9631939},{"batb":[[0,2.64,362.22],[1,2.62,351.56],[2,2.6,351.56]],"batl":[[1,2.78,202.88],[2,2.82,2.36]],"ltp":2.5,"tv":6153.87,"id":9454286}],"tv":28622.2}]}
{"op":"mcm","clk":"4290045373","pt":1632496820224,"mc":[{"id":"1.188075669","rc":[{"trd":[[1.57,63.23]],"batb":[[0,1.56,219.15],[1,1.55,484.17],[2,1.54,206.13]],"ltp":1.57,"tv":22490.19,"id":9631939},{"trd":[[2.72,20.4],[2.74,39.79],[2.76,17.67]],"batb":[[0,2.76,58.44],[1,2.64,362.22],[2,2.62,351.56]],"batl":[[0,2.78,202.88],[1,2.82,2.36],[2,2.86,43.99]],"ltp":2.76,"tv":6180.29,"id":9454286}],"tv":28670.49}]}
{"op":"mcm","clk":"4290045458","pt":1632496821137,"mc":[{"id":"1.188075669","rc":[{"batl":[[2,2.9,340.08]],"ltp":2.76,"tv":6180.29,"id":9454286}]}]}
{"op":"mcm","clk":"4290045607","pt":1632496822457,"mc":[{"id":"1.188075669","rc":[{"trd":[[2.76,26.71]],"batb":[[0,2.76,53.92]],"ltp":2.76,"tv":6189.33,"id":9454286}],"tv":28679.53}]}
{"op":"mcm","clk":"4290045777","pt":1632496824155,"mc":[{"id":"1.188075669","rc":[{"trd":[[2.76,40.22]],"batb":[[0,2.76,47.16]],"ltp":2.76,"tv":6202.85,"id":9454286}],"tv":28693.04}]}
{"op":"mcm","clk":"4290045906","pt":1632496825773,"mc":[{"id":"1.188075669","rc":[{"batb":[[0,1.56,345.15],[2,1.54,483.17]],"batl":[[0,1.59,232.37],[2,1.62,204.6]],"ltp":1.57,"tv":22490.19,"id":9631939},{"batl":[[2,2.84,130.25]],"ltp":2.76,"tv":6202.85,"id":9454286}]}]}
{"op":"mcm","clk":"4290045995","pt":1632496826661,"mc":[{"id":"1.188075669","rc":[{"batl":[[0,1.58,40],[1,1.59,232.37],[2,1.6,162.07]],"ltp":1.57,"tv":22490.19,"id":9631939}]}]}
{"op":"mcm","clk":"4290046099","pt":1632496827671,"mc":[{"id":"1.188075669","rc":[{"batb":[[1,2.7,35.29],[2,2.64,362.22]],"ltp":2.76,"tv":6202.85,"id":9454286}]}]}
{"op":"mcm","clk":"4290046235","pt":1632496829141,"mc":[{"id":"1.188075669","rc":[{"batb":[[0,1.56,459.15]],"ltp":1.57,"tv":22490.19,"id":9631939}]}]}
{"op":"mcm","clk":"4290046362","pt":1632496830662,"mc":[{"id":"1.188075669","rc":[{"trd":[[1.56,234.46]],"batb":[[0,1.56,436.18]],"ltp":1.56,"tv":22536.16,"id":9631939}],"tv":28739.01}]}
{"op":"mcm","clk":"4290046631","pt":1632496833580,"mc":[{"id":"1.188075669","rc":[{"trd":[[1.56,1468.08]],"batb":[[0,1.55,484.17],[1,1.54,483.17],[2,1.53,597.4]],"batl":[[0,1.56,108.47],[1,1.58,40],[2,1.59,232.37]],"ltp":1.56,"tv":23769.78,"id":9631939},{"trd":[[2.78,209.03]],"batl":[[0,2.82,2.36],[1,2.84,130.25],[2,2.86,158.37]],"ltp":2.78,"tv":6405.73,"id":9454286}],"tv":30175.51}]}
{"op":"mcm","clk":"4290046969","pt":1632496837099,"mc":[{"id":"1.188075669","rc":[{"trd":[[1.55,375.34]],"batb":[[0,1.55,581.17]],"batl":[[1,1.59,232.37],[2,1.6,162.07]],"ltp":1.55,"tv":23779.78,"id":9631939}],"tv":30185.51}]}
{"op":"mcm","clk":"4290046997","pt":1632496837267,"mc":[{"id":"1.188075669","rc":[{"batb":[[2,1.53,619.73]],"ltp":1.55,"tv":23779.78,"id":9631939}]}]}
{"op":"mcm","clk":"4290047178","pt":1632496838997,"mc":[{"id":"1.188075669","rc":[{"trd":[[1.55,380.03]],"batb":[[0,1.55,578.83]],"ltp":1.55,"tv":23784.46,"id":9631939}],"tv":30190.2}]}
{"op":"mcm","clk":"4290047374","pt":1632496841083,"mc":[{"id":"1.188075669","rc":[{"batb":[[0,1.55,729.83]],"ltp":1.55,"tv":23784.46,"id":9631939}]}]}
{"op":"mcm","clk":"4290047588","pt":1632496843499,"mc":[{"id":"1.188075669","rc":[{"batl":[[2,1.6,143.08]],"ltp":1.55,"tv":23784.46,"id":9631939}]}]}
{"op":"mcm","clk":"4290047762","pt":1632496845391,"mc":[{"id":"1.188075669","rc":[{"trd":[[1.56,1623.1]],"batl":[[0,1.56,30.99]],"ltp":1.56,"tv":23939.49,"id":9631939}],"tv":30345.22}]}
{"op":"mcm","clk":"4290047873","pt":1632496846490,"mc":[{"id":"1.188075669","rc":[{"batl":[[1,1.58,16.77],[2,1.59,232.37]],"ltp":1.56,"tv":23939.49,"id":9631939},{"batl":[[1,2.84,140.04]],"ltp":2.78,"tv":6405.73,"id":9454286}]}]}
{"op":"mcm","clk":"4290048060","pt":1632496848396,"mc":[{"id":"1.188075669","rc":[{"trd":[[1.56,1648.31]],"batl":[[0,1.56,18.4]],"ltp":1.56,"tv":23964.69,"id":9631939}],"tv":30370.42}]}
{"op":"mcm","clk":"4290048675","pt":1632496855099,"mc":[{"id":"1.188075669","rc":[{"batb":[[0,1.55,591.51],[1,1.54,317.3]],"batl":[[1,1.59,60],[2,1.62,204.6]],"ltp":1.56,"tv":23964.69,"id":9631939},{"batb":[[2,2.6,251.5]],"batl":[[1,2.84,130.25]],"ltp":2.78,"tv":6405.73,"id":9454286}]}]}
{"op":"mcm","clk":"4290048779","pt":1632496856202,"mc":[{"id":"1.188075669","rc":[{"trd":[[1.55,439.75]],"batb":[[0,1.54,277.04],[1,1.53,372.66],[2,1.5,263.47]],"ltp":1.55,"tv":24024.41,"id":9631939},{"batb":[[0,2.7,35.29],[1,2.6,251.5],[2,2.58,168.14]],"batl":[[0,2.84,130.25],[1,2.86,158.37],[2,2.9,2.05]],"ltp":2.78,"tv":6405.73,"id":9454286}],"tv":30430.14}]}
{"op":"mcm","clk":"4290048788","pt":1632496856302,"mc":[{"id":"1.188075669","rc":[{"batl":[[1,1.62,204.6],[2,1.63,319.28]],"ltp":1.55,"tv":24024.41,"id":9631939},{"batb":[[0,2.6,251.5],[1,2.58,168.14],[2,2.56,2.58]],"ltp":2.78,"tv":6405.73,"id":9454286}]}]}
{"op":"mcm","clk":"4290048973","pt":1632496858091,"mc":[{"id":"1.188075669","rc":[{"batb":[[1,1.53,553.11],[2,1.52,175.17]],"batl":[[2,1.63,506.51]],"ltp":1.55,"tv":24024.41,"id":9631939}]}]}
{"op":"mcm","clk":"4290049083","pt":1632496859083,"mc":[{"id":"1.188075669","rc":[{"batl":[[1,1.78,3],[2,1.8,16.88]],"ltp":1.55,"tv":24024.41,"id":9631939},{"batb":[[0,2.6,89.84],[1,2.48,2.51],[2,2.26,3]],"ltp":2.78,"tv":6405.73,"id":9454286}]}]}
{"op":"mcm","clk":"4290049217","pt":1632496860500,"mc":[{"id":"1.188075669","rc":[{"batl":[[1,1.61,40],[2,1.78,3]],"ltp":1.55,"tv":24024.41,"id":9631939}]}]}
{"op":"mcm","clk":"4290049381","pt":1632496862197,"mc":[{"id":"1.188075669","rc":[{"batb":[[0,1.54,22.62],[2,1.52,215.96]],"batl":[[0,1.56,30.92],[1,1.57,317.31],[2,1.58,542.36]],"ltp":1.55,"tv":24024.41,"id":9631939},{"batb":[[0,2.7,354.16],[1,2.68,343.76],[2,2.66,343.76]],"batl":[[0,2.86,158.37],[1,2.88,8.14]],"ltp":2.78,"tv":6405.73,"id":9454286}]}]}
{"op":"mcm","clk":"4290049486","pt":1632496863184,"mc":[{"id":"1.188075669","rc":[{"batb":[[0,1.53,553.11],[1,1.52,215.96],[2,1.51,261.33]],"batl":[[1,1.57,377.31]],"ltp":1.55,"tv":24024.41,"id":9631939},{"batb":[[0,2.82,72.71],[1,2.76,34.09],[2,2.7,354.16]],"batl":[[0,2.86,156.12]],"ltp":2.78,"tv":6405.73,"id":9454286}]}]}
{"op":"mcm","clk":"4290049648","pt":1632496864829,"mc":[{"id":"1.188075669","rc":[{"batb":[[2,1.51,266.33]],"batl":[[0,1.55,40],[1,1.56,30.92],[2,1.57,377.31]],"ltp":1.55,"tv":24024.41,"id":9631939}]}]}
{"op":"mcm","clk":"4290049767","pt":1632496866132,"mc":[{"id":"1.188075669","rc":[{"batb":[[0,1.53,689.11]],"ltp":1.55,"tv":24024.41,"id":9631939}]}]}
{"op":"mcm","clk":"4290049841","pt":1632496866817,"mc":[{"id":"1.188075669","rc":[{"trd":[[2.82,11.92]],"batb":[[0,2.82,69.22]],"ltp":2.82,"tv":6412.73,"id":9454286}],"tv":30437.14}]}
{"op":"mcm","clk":"4290050035","pt":1632496869011,"mc":[{"id":"1.188075669","rc":[{"batb":[[1,1.52,531.36],[2,1.51,587.32]],"ltp":1.55,"tv":24024.41,"id":9631939}]}]}
{"op":"mcm","clk":"4290050167","pt":1632496870220,"mc":[{"id":"1.188075669","rc":[{"batb":[[0,1.53,293.33],[1,1.52,356.19]],"batl":[[0,1.55,40.94],[1,1.56,18.4],[2,1.57,60]],"ltp":1.55,"tv":24024.41,"id":9631939},{"batb":[[2,2.68,224.56]],"batl":[[0,2.9,2.05],[1,2.92,154.49],[2,2.94,130.83]],"ltp":2.82,"tv":6412.73,"id":9454286}]}]}
{"op":"mcm","clk":"4290050178","pt":1632496870324,"mc":[{"id":"1.188075669","rc":[{"batb":[[1,1.52,315.4],[2,1.51,325.98]],"ltp":1.55,"tv":24024.41,"id":9631939},{"batb":[[0,2.76,34.09],[1,2.68,224.56],[2,2.66,194.76]],"ltp":2.82,"tv":6412.73,"id":9454286}]}]}
{"op":"mcm","clk":"4290050347","pt":1632496871931,"mc":[{"id":"1.188075669","rc":[{"trd":[[1.54,89.3]],"batb":[[0,1.52,315.4],[1,1.51,325.98],[2,1.5,6.2]],"batl":[[0,1.55,40.81],[2,1.59,283.52]],"ltp":1.54,"tv":24024.66,"id":9631939},{"batb":[[0,2.68,224.56],[1,2.66,194.76],[2,2.56,3.08]],"batl":[[0,2.92,154.49],[1,2.94,130.83],[2,3.45,186.7]],"ltp":2.82,"tv":6412.73,"id":9454286}],"tv":30437.39}]}
{"op":"mcm","clk":"4290050487","pt":1632496873134,"mc":[{"id":"1.188075669","rc":[{"batb":[[1,1.51,585.22],[2,1.5,191.3]],"ltp":1.54,"tv":24024.66,"id":9631939},{"batl":[[0,2.9,3],[1,2.92,154.49],[2,2.94,130.83]],"ltp":2.82,"tv":6412.73,"id":9454286}]}]}
{"op":"mcm","clk":"4290050524","pt":1632496873396,"mc":[{"id":"1.188075669","rc":[{"batl":[[0,2.92,154.49],[1,2.94,130.83],[2,3.45,184.99]],"ltp":2.82,"tv":6412.73,"id":9454286}]}]}
{"op":"mcm","clk":"4290050696","pt":1632496875120,"mc":[{"id":"1.188075669","rc":[{"trd":[[1.54,90.92]],"batb":[[0,1.53,26.33],[1,1.52,322.4],[2,1.51,325.98]],"batl":[[0,1.56,18.4],[1,1.59,283.52],[2,1.6,272.35]],"ltp":1.54,"tv":24026.28,"id":9631939},{"batl":[[0,2.9,2.15],[1,2.92,157.49],[2,2.94,130.83]],"ltp":2.82,"tv":6412.73,"id":9454286}],"tv":30439.01}]}
{"op":"mcm","clk":"4290050710","pt":1632496875232,"mc":[{"id":"1.188075669","rc":[{"batb":[[0,1.52,322.4],[1,1.51,325.98],[2,1.5,6.2]],"ltp":1.54,"tv":24026.28,"id":9631939},{"batl":[[0,2.92,157.49],[1,2.94,130.83],[2,3.45,184.99]],"ltp":2.82,"tv":6412.73,"id":9454286}]}]}
{"op":"mcm","clk":"4290050861","pt":1632496877012,"mc":[{"id":"1.188075669","rc":[{"batl":[[1,2.94,490.66]],"ltp":2.82,"tv":6412.73,"id":9454286}]}]}
{"op":"mcm","clk":"4290050928","pt":1632496877907,"mc":[{"id":"1.188075669","rc":[{"batb":[[0,1.53,288.84],[1,1.52,498.22],[2,1.51,320.98]],"batl":[[1,1.58,204.9],[2,1.59,429.67]],"ltp":1.54,"tv":24026.28,"id":9631939},{"batl":[[1,2.94,130.83]],"ltp":2.82,"tv":6412.73,"id":9454286}]}]}
{"op":"mcm","clk":"4290051031","pt":1632496879131,"mc":[{"id":"1.188075669","rc":[{"batb":[[0,1.53,479.17],[1,1.52,539.17]],"ltp":1.54,"tv":24026.28,"id":9631939},{"batb":[[0,2.7,22.68],[1,2.68,224.56],[2,2.66,194.76]],"batl":[[0,2.9,19.81],[1,2.92,157.49],[2,2.94,130.83]],"ltp":2.82,"tv":6412.73,"id":9454286}]}]}
{"op":"mcm","clk":"4290051166","pt":1632496880446,"mc":[{"id":"1.188075669","rc":[{"batb":[[2,1.51,326.98]],"batl":[[1,1.57,40],[2,1.58,204.9]],"ltp":1.54,"tv":24026.28,"id":9631939}]}]}
{"op":"mcm","clk":"4290051311","pt":1632496882015,"mc":[{"id":"1.188075669","rc":[{"batb":[[0,1.53,190.33],[1,1.52,322.4]],"batl":[[2,1.59,283.52]],"ltp":1.54,"tv":24026.28,"id":9631939},{"batb":[[0,2.68,224.56],[1,2.66,194.76],[2,2.56,3.08]],"batl":[[0,2.9,2.45]],"ltp":2.82,"tv":6412.73,"id":9454286}]}]}
{"op":"mcm","clk":"4290051420","pt":1632496883221,"mc":[{"id":"1.188075669","rc":[{"batb":[[0,1.53,23.33]],"ltp":1.54,"tv":24026.28,"id":9631939}]}]}
{"op":"mcm","clk":"4290051489","pt":1632496883855,"mc":[{"id":"1.188075669","rc":[{"batb":[[0,1.52,322.4],[1,1.51,326.98],[2,1.48,276.71]],"ltp":1.54,"tv":24026.28,"id":9631939},{"batl":[[0,2.92,157.49],[1,2.94,130.83],[2,3.45,184.99]],"ltp":2.82,"tv":6412.73,"id":9454286}]}]}
{"op":"mcm","clk":"4290051595","pt":1632496885026,"mc":[{"id":"1.188075669","rc":[{"batb":[[1,1.51,586.22],[2,1.5,185.3]],"batl":[[0,1.53,5.32],[1,1.56,18.4],[2,1.57,40]],"ltp":1.54,"tv":24026.28,"id":9631939},{"batb":[[0,2.68,82.84],[1,2.56,3.08],[2,2.26,3]],"ltp":2.82,"tv":6412.73,"id":9454286}]}]}
{"op":"mcm","clk":"4290051805","pt":1632496887125,"mc":[{"id":"1.188075669","rc":[{"trd":[[1.53,891]],"batb":[[0,1.52,315.4],[1,1.51,580.22]],"batl":[[0,1.56,18.4],[1,1.78,3],[2,1.8,16.88]],"ltp":1.53,"tv":24036.92,"id":9631939},{"batl":[[0,2.92,154.49],[2,990,0.01]],"ltp":2.82,"tv":6412.73,"id":9454286}],"tv":30449.65}]}
{"op":"mcm","clk":"4290051895","pt":1632496888117,"mc":[{"id":"1.188075669","rc":[{"batb":[[2,1.5,426.68]],"batl":[[0,1.56,1379.02],[1,1.57,747.63],[2,1.58,594.94]],"ltp":1.53,"tv":24036.92,"id":9631939},{"batb":[[0,2.84,5.06],[1,2.7,23.94],[2,2.68,89.2]],"batl":[[0,2.92,161.76],[2,3,100.02]],"ltp":2.82,"tv":6412.73,"id":9454286}]}]}
{"op":"mcm","clk":"4290051993","pt":1632496888919,"mc":[{"id":"1.188075669","rc":[{"batl":[[0,1.56,1360.62]],"ltp":1.53,"tv":24036.92,"id":9631939},{"batb":[[0,2.9,68.67],[1,2.84,5.06],[2,2.76,77.19]],"batl":[[2,2.98,10.07]],"ltp":2.82,"tv":6412.73,"id":9454286}]}]}
{"op":"mcm","clk":"4290052116","pt":1632496890180,"mc":[{"id":"1.188075669","rc":[{"trd":[[1.53,896]],"batl":[[0,1.55,60],[1,1.56,1396.76],[2,1.57,747.63]],"ltp":1.53,"tv":24041.92,"id":9631939},{"trd":[[2.9,38.82]],"batb":[[0,2.9,63.03],[2,2.78,33.7]],"ltp":2.9,"tv":6421.36,"id":9454286}],"tv":30463.29}]}
{"op":"mcm","clk":"4290052180","pt":1632496890757,"mc":[{"id":"1.188075669","rc":[{"batl":[[0,1.54,40],[1,1.55,60],[2,1.56,1707.71]],"ltp":1.53,"tv":24041.92,"id":9631939}]}]}
{"op":"mcm","clk":"4290052320","pt":1632496892140,"mc":[{"id":"1.188075669","rc":[{"trd":[[1.52,2958.3]],"batb":[[0,1.52,499]],"batl":[[0,1.54,80]],"ltp":1.52,"tv":24078.72,"id":9631939}],"tv":30500.09}]}
{"op":"mcm","clk":"4290052398","pt":1632496893040,"mc":[{"id":"1.188075669","rc":[{"trd":[[2.9,42.82]],"batb":[[0,2.9,61.03],[2,2.76,77.19]],"ltp":2.9,"tv":6425.36,"id":9454286}],"tv":30504.09}]}
{"op":"mcm","clk":"4290052557","pt":1632496894950,"mc":[{"id":"1.188075669","rc":[{"batb":[[1,1.51,606.21],[2,1.5,731.15]],"batl":[[2,1.56,1396.76]],"ltp":1.52,"tv":24078.72,"id":9631939},{"batl":[[2,2.98,134.03]],"ltp":2.9,"tv":6425.36,"id":9454286}]}]}
{"op":"mcm","clk":"4290052681","pt":1632496896224,"mc":[{"id":"1.188075669","rc":[{"batb":[[2,2.82,32.96]],"ltp":2.9,"tv":6425.36,"id":9454286}]}]}
{"op":"mcm","clk":"4290052942","pt":1632496899025,"mc":[{"id":"1.188075669","rc":[{"trd":[[1.52,3488.44]],"batb":[[0,1.52,233.9]],"ltp":1.52,"tv":24608.86,"id":9631939}],"tv":31034.22}]}
{"op":"mcm","clk":"4290052998","pt":1632496899570,"mc":[{"id":"1.188075669","rc":[{"batl":[[2,1.56,1215.51]],"ltp":1.52,"tv":24608.86,"id":9631939}]}]}
{"op":"mcm","clk":"4290053104","pt":1632496900881,"mc":[{"id":"1.188075669","rc":[{"batb":[[0,1.52,227.49],[1,1.51,25.99],[2,1.5,489.76]],"batl":[[2,1.57,253.88]],"ltp":1.52,"tv":24608.86,"id":9631939},{"batb":[[0,2.82,32.96],[1,2.76,77.19],[2,2.74,165.87]],"batl":[[0,2.94,2.08],[1,2.98,123.96],[2,3,158.87]],"ltp":2.9,"tv":6425.36,"id":9454286}]}]}
{"op":"mcm","clk":"4290053185","pt":1632496901930,"mc":[{"id":"1.188075669","rc":[{"batb":[[0,1.51,25.99],[1,1.5,489.76],[2,1.49,303.46]],"ltp":1.52,"tv":24608.86,"id":9631939},{"batl":[[0,2.98,123.96],[1,3,158.87],[2,3.9,162.28]],"ltp":2.9,"tv":6425.36,"id":9454286}]}]}
{"op":"mcm","clk":"4290053236","pt":1632496902467,"mc":[{"id":"1.188075669","rc":[{"batb":[[0,1.53,70],[1,1.51,25.99],[2,1.5,489.76]],"batl":[[1,1.57,253.88],[2,1.58,241.22]],"ltp":1.52,"tv":24608.86,"id":9631939},{"batb":[[0,2.76,77.19],[1,2.74,165.87],[2,2.72,170.5]],"ltp":2.9,"tv":6425.36,"id":9454286}]}]}
{"op":"mcm","clk":"4290053370","pt":1632496904084,"mc":[{"id":"1.188075669","rc":[{"batb":[[2,1.5,494.76]],"ltp":1.52,"tv":24608.86,"id":9631939}]}]}
{"op":"mcm","clk":"4290053458","pt":1632496905037,"mc":[{"id":"1.188075669","rc":[{"batb":[[1,1.52,23.49],[2,1.51,25.99]],"ltp":1.52,"tv":24608.86,"id":9631939},{"batl":[[0,2.94,2.08],[1,2.98,123.96],[2,3,158.87]],"ltp":2.9,"tv":6425.36,"id":9454286}]}]}
{"op":"mcm","clk":"4290053702","pt":1632496907949,"mc":[{"id":"1.188075669","rc":[{"batb":[[1,2.74,168.87],[2,2.72,173.5]],"ltp":2.9,"tv":6425.36,"id":9454286}]}]}
{"op":"mcm","clk":"4290053799","pt":1632496909062,"mc":[{"id":"1.188075669","rc":[{"batb":[[0,1.53,230]],"ltp":1.52,"tv":24608.86,"id":9631939}]}]}
{"op":"mcm","clk":"4290053886","pt":1632496910054,"mc":[{"id":"1.188075669","rc":[{"batb":[[2,1.51,125.99]],"ltp":1.52,"tv":24608.86,"id":9631939}]}]}
{"op":"mcm","clk":"4290054048","pt":1632496911742,"mc":[{"id":"1.188075669","rc":[{"trd":[[1.53,896.02]],"batb":[[0,1.53,229.99]],"batl":[[0,1.54,40]],"ltp":1.53,"tv":24608.88,"id":9631939}],"tv":31034.24}]}
{"op":"mcm","clk":"4290054087","pt":1632496912265,"mc":[{"id":"1.188075669","rc":[{"batb":[[0,1.53,437.99]],"ltp":1.53,"tv":24608.88,"id":9631939}]}]}
{"op":"mcm","clk":"4290054378","pt":1632496915647,"mc":[{"id":"1.188075669","rc":[{"trd":[[1.54,91.04]],"batl":[[0,1.54,39.94]],"ltp":1.54,"tv":24608.99,"id":9631939}],"tv":31034.36}]}
{"op":"mcm","clk":"4290054531","pt":1632496916857,"mc":[{"id":"1.188075669","rc":[{"batb":[[0,1.53,69.99]],"ltp":1.54,"tv":24608.99,"id":9631939},{"batb":[[1,2.74,165.87],[2,2.72,170.5]],"ltp":2.9,"tv":6425.36,"id":9454286}]}]}
{"op":"mcm","clk":"4290054597","pt":1632496917646,"mc":[{"id":"1.188075669","rc":[{"batb":[[0,1.51,125.99],[1,1.5,489.76],[2,1.49,498.12]],"ltp":1.54,"tv":24608.99,"id":9631939},{"batl":[[0,2.98,123.96],[1,3,158.87],[2,3.9,162.28]],"ltp":2.9,"tv":6425.36,"id":9454286}]}]}
{"op":"mcm","clk":"4290054683","pt":1632496918757,"mc":[{"id":"1.188075669","rc":[{"trd":[[1.54,96.16]],"batl":[[0,1.54,37.38],[1,1.78,3],[2,1.8,16.88]],"ltp":1.54,"tv":24614.11,"id":9631939},{"batb":[[1,2.66,2.78],[2,2.26,3]],"ltp":2.9,"tv":6425.36,"id":9454286}],"tv":31039.48}]}
{"op":"mcm","clk":"4290054798","pt":1632496920066,"mc":[{"id":"1.188075669","rc":[{"batb":[[1,1.5,496.76]],"ltp":1.54,"tv":24614.11,"id":9631939}]}]}
{"op":"mcm","clk":"4290054890","pt":1632496921067,"mc":[{"id":"1.188075669","rc":[{"trd":[[1.54,170.92]],"batb":[[0,1.54,32.61],[1,1.51,125.99],[2,1.5,489.76]],"batl":[[0,1.78,3],[1,1.8,16.88],[2,990,0.35]],"ltp":1.54,"tv":24688.87,"id":9631939}],"tv":31114.24}]}
{"op":"mcm","clk":"4290054982","pt":1632496921995,"mc":[{"id":"1.188075669","rc":[{"trd":[[1.54,208.65]],"batb":[[0,1.51,125.99],[1,1.5,489.76],[2,1.49,534.74]],"batl":[[0,1.54,206.84],[1,1.55,160.57],[2,1.56,481.88]],"ltp":1.54,"tv":24726.6,"id":9631939},{"trd":[[2.86,17.56]],"batb":[[0,2.86,459.21],[1,2.84,82.16],[2,2.82,82.16]],"batl":[[0,2.96,7.2],[1,2.98,2.25],[2,3,158.87]],"ltp":2.86,"tv":6442.92,"id":9454286}],"tv":31169.53}]}
{"op":"mcm","clk":"4290055092","pt":1632496923201,"mc":[{"id":"1.188075669","rc":[{"batl":[[0,1.54,266.84]],"ltp":1.54,"tv":24726.6,"id":9631939},{"trd":[[2.96,102.01]],"batb":[[0,2.96,153.17],[1,2.86,491.46],[2,2.84,153.95]],"batl":[[0,2.98,2.25],[1,3,168.87],[2,3.05,217.17]],"ltp":2.96,"tv":6457.31,"id":9454286}],"tv":31183.92}]}
{"op":"mcm","clk":"4290055168","pt":1632496923994,"mc":[{"id":"1.188075669","rc":[{"batl":[[0,1.54,206.84]],"ltp":1.54,"tv":24726.6,"id":9631939},{"batb":[[1,2.86,459.21]],"ltp":2.96,"tv":6457.31,"id":9454286}]}]}
{"op":"mcm","clk":"4290055416","pt":1632496927059,"mc":[{"id":"1.188075669","rc":[{"trd":[[1.52,3588.44]],"batb":[[0,1.51,312.99]],"ltp":1.52,"tv":24826.6,"id":9631939},{"trd":[[2.96,153.32]],"batb":[[0,2.96,101.86]],"ltp":2.96,"tv":6508.62,"id":9454286}],"tv":31335.23}]}
{"op":"mcm","clk":"4290055572","pt":1632496928964,"mc":[{"id":"1.188075669","rc":[{"trd":[[1.51,2746.21]],"batb":[[0,1.51,297.41],[1,1.5,513.58],[2,1.49,789.6]],"batl":[[0,1.54,266.84],[1,1.55,424.85],[2,1.56,745.21]],"ltp":1.51,"tv":24857.76,"id":9631939},{"batl":[[1,3,171.03],[2,3.05,359.73]],"ltp":2.96,"tv":6508.62,"id":9454286}],"tv":31366.39}]}
{"op":"mcm","clk":"4290055688","pt":1632496930194,"mc":[{"id":"1.188075669","rc":[{"batb":[[0,1.51,508.41]],"batl":[[0,1.54,594.63]],"ltp":1.51,"tv":24857.76,"id":9631939},{"trd":[[2.96,183.06]],"batb":[[0,2.96,86.98]],"ltp":2.96,"tv":6538.36,"id":9454286}],"tv":31396.13}]}
{"op":"mcm","clk":"4290055725","pt":1632496930568,"mc":[{"id":"1.188075669","rc":[{"batl":[[0,1.53,60.79],[1,1.54,594.63],[2,1.55,424.85]],"ltp":1.51,"tv":24857.76,"id":9631939}]}]}
{"op":"mcm","clk":"4290055860","pt":1632496932089,"mc":[{"id":"1.188075669","rc":[{"trd":[[1.52,3589.22]],"batl":[[1,1.54,580.26]],"ltp":1.52,"tv":24858.54,"id":9631939},{"trd":[[2.96,183.46]],"batb":[[0,2.96,86.58]],"ltp":2.96,"tv":6538.76,"id":9454286}],"tv":31397.31}]}
{"op":"mcm","clk":"4290056125","pt":1632496935208,"mc":[{"id":"1.188075669","rc":[{"batl":[[0,1.53,59.08]],"ltp":1.52,"tv":24858.54,"id":9631939}]}]}
{"op":"mcm","clk":"4290056226","pt":1632496936209,"mc":[{"id":"1.188075669","rc":[{"batb":[[0,1.51,498],[1,1.5,209.12],[2,1.49,486.14]],"batl":[[1,1.54,252.47]],"ltp":1.52,"tv":24858.54,"id":9631939},{"batb":[[1,2.84,71.79],[2,2.82,184.03]],"batl":[[0,3,2.16],[1,3.05,142.56],[2,3.1,144.2]],"ltp":2.96,"tv":6538.76,"id":9454286}]}]}
{"op":"mcm","clk":"4290056319","pt":1632496937107,"mc":[{"id":"1.188075669","rc":[{"batb":[[0,1.51,100],[1,1.5,24.02],[2,1.49,254.87]],"batl":[[1,1.54,60],[2,1.55,264.28]],"ltp":1.52,"tv":24858.54,"id":9631939},{"batb":[[0,2.84,71.79],[1,2.82,184.03],[2,2.8,156.58]],"ltp":2.96,"tv":6538.76,"id":9454286}]}]}
{"op":"mcm","clk":"4290056428","pt":1632496938185,"mc":[{"id":"1.188075669","rc":[{"batb":[[0,1.51,303],[1,1.5,31.02]],"batl":[[1,1.55,264.28],[2,1.56,263.33]],"ltp":1.52,"tv":24858.54,"id":9631939},{"batb":[[0,2.88,10.74],[1,2.84,71.79],[2,2.82,151.07]],"batl":[[0,3,5.66]],"ltp":2.96,"tv":6538.76,"id":9454286}]}]}
{"op":"mcm","clk":"4290056513","pt":1632496939188,"mc":[{"id":"1.188075669","rc":[{"batb":[[0,1.51,100],[1,1.49,255.06],[2,1.48,334.75]],"batl":[[1,1.57,36.5],[2,1.78,3]],"ltp":1.52,"tv":24858.54,"id":9631939},{"batb":[[0,2.84,71.79],[1,2.78,3],[2,2.76,3]],"batl":[[0,3.05,142.56],[1,3.1,144.2],[2,3.9,162.28]],"ltp":2.96,"tv":6538.76,"id":9454286}]}]}
{"op":"mcm","clk":"4290056597","pt":1632496940190,"mc":[{"id":"1.188075669","rc":[{"batb":[[1,1.5,5.2],[2,1.49,259.87]],"ltp":1.52,"tv":24858.54,"id":9631939},{"batb":[[0,2.82,73.14]],"ltp":2.96,"tv":6538.76,"id":9454286}]}]}
{"op":"mcm","clk":"4290056787","pt":1632496942196,"mc":[{"id":"1.188075669","rc":[{"batb":[[1,1.49,255.06],[2,1.48,762.16]],"batl":[[0,1.52,17.31],[1,1.53,905.18],[2,1.54,516.16]],"ltp":1.52,"tv":24858.54,"id":9631939},{"batb":[[0,2.9,162.06],[1,2.88,81.04],[2,2.86,81.04]],"batl":[[0,3.05,290.44]],"ltp":2.96,"tv":6538.76,"id":9454286}]}]}
{"op":"mcm","clk":"4290056897","pt":1632496943206,"mc":[{"id":"1.188075669","rc":[{"batl":[[1,1.53,1000.18]],"ltp":1.52,"tv":24858.54,"id":9631939},{"batb":[[0,2.9,193.63]],"batl":[[0,3.05,300.28],[2,3.15,149.2]],"ltp":2.96,"tv":6538.76,"id":9454286}]}]}
{"op":"mcm","clk":"4290057001","pt":1632496944204,"mc":[{"id":"1.188075669","rc":[{"trd":[[1.5,442.72],[1.51,2846.21]],"batb":[[0,1.49,254.87],[1,1.48,762.16],[2,1.47,243.68]],"batl":[[0,1.51,1.71],[1,1.52,17.31],[2,1.53,940.18]],"ltp":1.5,"tv":24958.74,"id":9631939},{"trd":[[2.98,56.63],[3,51.7]],"batb":[[0,3,102.46],[1,2.9,162.06],[2,2.88,81.04]],"ltp":3.0,"tv":6589.49,"id":9454286}],"tv":31548.23}]}
{"op":"mcm","clk":"4290057171","pt":1632496946109,"mc":[{"id":"1.188075669","rc":[{"batl":[[0,1.52,17.31],[1,1.53,940.18],[2,1.54,516.16]],"ltp":1.5,"tv":24958.74,"id":9631939}]}]}
{"op":"mcm","clk":"4290057270","pt":1632496947223,"mc":[{"id":"1.188075669","rc":[{"batl":[[2,3.15,190.11]],"ltp":3.0,"tv":6589.49,"id":9454286}]}]}
{"op":"mcm","clk":"4290057332","pt":1632496947904,"mc":[{"id":"1.188075669","rc":[{"batl":[[0,1.52,57.31]],"ltp":1.5,"tv":24958.74,"id":9631939}]}]}
{"op":"mcm","clk":"4290057445","pt":1632496949215,"mc":[{"id":"1.188075669","rc":[{"trd":[[1.5,482.72]],"batl":[[1,1.53,881.1]],"ltp":1.5,"tv":24998.74,"id":9631939},{"trd":[[3,112.23]],"batb":[[0,3,62.21]],"ltp":3.0,"tv":6650.02,"id":9454286}],"tv":31648.76}]}
{"op":"mcm","clk":"4290057458","pt":1632496949319,"mc":[{"id":"1.188075669","rc":[{"batb":[[0,1.49,483.87]],"ltp":1.5,"tv":24998.74,"id":9631939}]}]}
{"op":"mcm","clk":"4290057636","pt":1632496951218,"mc":[{"id":"1.188075669","rc":[{"trd":[[3,131.68]],"batb":[[0,3,52.49]],"ltp":3.0,"tv":6669.47,"id":9454286}],"tv":31668.21}]}
{"op":"mcm","clk":"4290057803","pt":1632496953132,"mc":[{"id":"1.188075669","rc":[{"batb":[[0,1.49,637.87]],"batl":[[0,1.52,97.31]],"ltp":1.5,"tv":24998.74,"id":9631939},{"trd":[[3,133.25]],"batb":[[0,3,51.71]],"ltp":3.0,"tv":6671.04,"id":9454286}],"tv":31669.78}]}
{"op":"mcm","clk":"4290057883","pt":1632496953926,"mc":[{"id":"1.188075669","rc":[{"trd":[[1.49,323.33],[1.5,523.44]],"batb":[[0,1.49,637.77]],"ltp":1.5,"tv":25039.65,"id":9631939},{"trd":[[3,177.95]],"batb":[[0,3,19.18]],"ltp":3.0,"tv":6715.74,"id":9454286}],"tv":31755.39}]}
{"op":"mcm","clk":"4290058072","pt":1632496956140,"mc":[{"id":"1.188075669","rc":[{"trd":[[1.49,326.75],[1.5,561.83]],"batb":[[0,1.5,169.61],[1,1.49,845.06],[2,1.48,762.16]],"ltp":1.5,"tv":25081.46,"id":9631939},{"trd":[[3,197.13]],"batb":[[0,2.9,162.06],[1,2.88,81.04],[2,2.86,81.04]],"ltp":3.0,"tv":6734.92,"id":9454286}],"tv":31816.38}]}
{"op":"mcm","clk":"4290058152","pt":1632496957097,"mc":[{"id":"1.188075669","rc":[{"batl":[[0,1.51,40],[1,1.52,97.31],[2,1.53,881.1]],"ltp":1.5,"tv":25081.46,"id":9631939}]}]}
{"op":"mcm","clk":"4290058174","pt":1632496957414,"mc":[{"id":"1.188075669","rc":[{"trd":[[1.5,581.83]],"batb":[[0,1.5,159.61]],"ltp":1.5,"tv":25101.46,"id":9631939}],"tv":31836.38}]}
{"op":"mcm","clk":"4290058343","pt":1632496959209,"mc":[{"id":"1.188075669","rc":[{"batl":[[0,1.52,97.31],[1,1.53,881.1],[2,1.54,516.16]],"ltp":1.5,"tv":25101.46,"id":9631939},{"batb":[[0,2.96,160.53],[1,2.9,162.06],[2,2.88,81.04]],"ltp":3.0,"tv":6734.92,"id":9454286}]}]}
{"op":"mcm","clk":"4290058401","pt":1632496959838,"mc":[{"id":"1.188075669","rc":[{"batb":[[0,1.5,165.75]],"ltp":1.5,"tv":25101.46,"id":9631939}]}]}
{"op":"mcm","clk":"4290058592","pt":1632496961844,"mc":[{"id":"1.188075669","rc":[{"batl":[[0,1.52,137.31]],"ltp":1.5,"tv":25101.46,"id":9631939}]}]}
{"op":"mcm","clk":"4290059036","pt":1632496966512,"mc":[{"id":"1.188075669","rc":[{"trd":[[1.5,583.75]],"batb":[[0,1.5,163.83]],"ltp":1.5,"tv":25103.38,"id":9631939},{"trd":[[3,198.09]],"ltp":3.0,"tv":6735.88,"id":9454286}],"tv":31839.26}]}
{"op":"mcm","clk":"4290059402","pt":1632496970164,"mc":[{"id":"1.188075669","rc":[{"batb":[[0,1.5,157.69]],"ltp":1.5,"tv":25103.38,"id":9631939}]}]}
{"op":"mcm","clk":"4290059657","pt":1632496973037,"mc":[{"id":"1.188075669","rc":[{"batl":[[0,1.52,177.31]],"ltp":1.5,"tv":25103.38,"id":9631939}]}]}
{"op":"mcm","clk":"4290059711","pt":1632496973497,"mc":[{"id":"1.188075669","rc":[{"trd":[[1.52,3601.51]],"batl":[[0,1.52,171.16]],"ltp":1.52,"tv":25115.68,"id":9631939}],"tv":31851.56}]}
{"op":"mcm","clk":"4290059884","pt":1632496975460,"mc":[{"id":"1.188075669","rc":[{"trd":[[1.52,3602.68]],"batl":[[0,1.52,170.57]],"ltp":1.52,"tv":25116.85,"id":9631939}],"tv":31852.73}]}
{"op":"mcm","clk":"4290059977","pt":1632496976357,"mc":[{"id":"1.188075669","rc":[{"trd":[[2.96,183.7]],"batb":[[0,2.96,160.41]],"ltp":2.96,"tv":6736.11,"id":9454286}],"tv":31852.97}]}
{"op":"mcm","clk":"4290060708","pt":1632496983546,"mc":[{"id":"1.188075669","rc":[{"batl":[[0,1.52,160]],"ltp":1.52,"tv":25116.85,"id":9631939},{"batl":[[0,3.05,291.28]],"ltp":2.96,"tv":6736.11,"id":9454286}]}]}
{"op":"mcm","clk":"4290061057","pt":1632496986831,"mc":[{"id":"1.188075669","rc":[{"batb":[[0,1.5,180.7]],"ltp":1.52,"tv":25116.85,"id":9631939}]}]}
{"op":"mcm","clk":"4290061360","pt":1632496989575,"mc":[{"id":"1.188075669","rc":[{"batl":[[0,1.52,170.57]],"ltp":1.52,"tv":25116.85,"id":9631939},{"batl":[[0,3,5.6],[1,3.05,291.28],[2,3.1,144.2]],"ltp":2.96,"tv":6736.11,"id":9454286}]}]}
{"op":"mcm","clk":"4290061565","pt":1632496991679,"mc":[{"id":"1.188075669","rc":[{"trd":[[1.52,3605.02]],"batl":[[0,1.52,169.4]],"ltp":1.52,"tv":25119.19,"id":9631939},{"trd":[[2.96,184.24]],"batb":[[0,2.96,160.14]],"ltp":2.96,"tv":6736.66,"id":9454286}],"tv":31855.85}]}
{"op":"mcm","clk":"4290062025","pt":1632496996084,"mc":[{"id":"1.188075669","rc":[{"trd":[[1.52,3623.06]],"batl":[[0,1.52,160.38]],"ltp":1.52,"tv":25137.23,"id":9631939}],"tv":31873.89}]}
{"op":"mcm","clk":"4290062119","pt":1632496997075,"mc":[{"id":"1.188075669","rc":[{"batl":[[0,1.52,180.38]],"ltp":1.52,"tv":25137.23,"id":9631939}]}]}
{"op":"mcm","clk":"4290062928","pt":1632497005986,"mc":[{"id":"1.188075669","rc":[{"trd":[[1.52,3627.76]],"batl":[[0,1.52,178.03]],"ltp":1.52,"tv":25141.92,"id":9631939}],"tv":31878.58}]}
{"op":"mcm","clk":"4290063849","pt":1632497015477,"mc":[{"id":"1.188075669","rc":[{"batb":[[0,1.5,157.69]],"ltp":1.52,"tv":25141.92,"id":9631939}]}]}
{"op":"mcm","clk":"4290063969","pt":1632497016784,"mc":[{"id":"1.188075669","rc":[{"batl":[[0,1.52,138.03]],"ltp":1.52,"tv":25141.92,"id":9631939}]}]}
{"op":"mcm","clk":"4290064139","pt":1632497018579,"mc":[{"id":"1.188075669","rc":[{"batb":[[0,1.51,23.01],[1,1.5,157.69],[2,1.49,845.06]],"ltp":1.52,"tv":25141.92,"id":9631939}]}]}
{"op":"mcm","clk":"4290064294","pt":1632497020484,"mc":[{"id":"1.188075669","rc":[{"trd":[[1.51,2892.26]],"batb":[[0,1.5,157.69],[1,1.49,845.06],[2,1.48,762.16]],"batl":[[0,1.51,16.96],[1,1.52,138.03],[2,1.53,881.1]],"ltp":1.51,"tv":25187.97,"id":9631939}],"tv":31924.63}]}
{"op":"mcm","clk":"4290064413","pt":1632497021804,"mc":[{"id":"1.188075669","rc":[{"batb":[[1,1.49,1160.06]],"ltp":1.51,"tv":25187.97,"id":9631939}]}]}
{"op":"mcm","clk":"4290065040","pt":1632497028818,"mc":[{"id":"1.188075669","rc":[{"trd":[[1.5,626.54]],"batb":[[0,1.5,136.28]],"ltp":1.5,"tv":25230.77,"id":9631939}],"tv":31967.43}]}
{"op":"mcm","clk":"4290065274","pt":1632497031210,"mc":[{"id":"1.188075669","rc":[{"trd":[[1.51,2906.35]],"batl":[[0,1.51,9.91]],"ltp":1.51,"tv":25244.85,"id":9631939}],"tv":31981.51}]}
{"op":"mcm","clk":"4290065831","pt":1632497036901,"mc":[{"id":"1.188075669","rc":[{"batl":[[1,1.52,118.03]],"ltp":1.51,"tv":25244.85,"id":9631939}]}]}
{"op":"mcm","clk":"4290066057","pt":1632497039120,"mc":[{"id":"1.188075669","rc":[{"batl":[[2,1.53,846.1]],"ltp":1.51,"tv":25244.85,"id":9631939}]}]}
{"op":"mcm","clk":"4290066195","pt":1632497040556,"mc":[{"id":"1.188075669","rc":[{"batl":[[0,1.51,29.91]],"ltp":1.51,"tv":25244.85,"id":9631939}]}]}
{"op":"mcm","clk":"4290066435","pt":1632497043008,"mc":[{"id":"1.188075669","rc":[{"trd":[[1.5,635.34]],"batb":[[0,1.5,127.48]],"ltp":1.5,"tv":25253.65,"id":9631939},{"trd":[[3,213.69]],"batl":[[0,3.05,291.28],[1,3.1,144.2],[2,3.15,190.11]],"ltp":3.0,"tv":6752.26,"id":9454286}],"tv":32005.91}]}
{"op":"mcm","clk":"4290067031","pt":1632497049105,"mc":[{"id":"1.188075669","rc":[{"trd":[[1.51,2919.3]],"batl":[[0,1.51,23.43]],"ltp":1.51,"tv":25266.6,"id":9631939}],"tv":32018.87}]}
{"op":"mcm","clk":"4290067365","pt":1632497053155,"mc":[{"id":"1.188075669","rc":[{"batl":[[1,1.52,67.46]],"ltp":1.51,"tv":25266.6,"id":9631939},{"trd":[[2.96,188.63]],"batb":[[0,2.96,157.95]],"ltp":2.96,"tv":6756.64,"id":9454286}],"tv":32023.25}]}
{"op":"mcm","clk":"4290067381","pt":1632497053314,"mc":[{"id":"1.188075669","rc":[{"batl":[[0,1.51,43.43]],"ltp":1.51,"tv":25266.6,"id":9631939}]}]}
{"op":"mcm","clk":"4290067530","pt":1632497054944,"mc":[{"id":"1.188075669","rc":[{"batl":[[0,1.51,63.43]],"ltp":1.51,"tv":25266.6,"id":9631939}]}]}
{"op":"mcm","clk":"4290067637","pt":1632497056107,"mc":[{"id":"1.188075669","rc":[{"trd":[[2.96,193.31]],"batb":[[0,2.96,161.35]],"batl":[[0,3.05,298.13]],"ltp":2.96,"tv":6761.32,"id":9454286}],"tv":32027.93}]}
{"op":"mcm","clk":"4290067749","pt":1632497057714,"mc":[{"id":"1.188075669","rc":[{"batb":[[0,1.49,1160.06],[1,1.48,762.16],[2,1.47,535.21]],"ltp":1.51,"tv":25266.6,"id":9631939}]}]}
{"op":"mcm","clk":"4290067948","pt":1632497059835,"mc":[{"id":"1.188075669","rc":[{"batb":[[0,1.49,253.06]],"ltp":1.51,"tv":25266.6,"id":9631939}]}]}
{"op":"mcm","clk":"4290068026","pt":1632497060846,"mc":[{"id":"1.188075669","rc":[{"trd":[[1.51,3046.16],[1.52,3755.86]],"batl":[[0,1.52,3.41],[1,1.53,846.1],[2,1.54,516.16]],"ltp":1.52,"tv":25521.56,"id":9631939}],"tv":32282.89}]}
{"op":"mcm","clk":"4290068385","pt":1632497064928,"mc":[{"id":"1.188075669","rc":[{"batl":[[0,1.51,20],[1,1.52,3.41],[2,1.53,846.1]],"ltp":1.52,"tv":25521.56,"id":9631939}]}]}
{"op":"mcm","clk":"4290069526","pt":1632497078177,"mc":[{"id":"1.188075669","rc":[{"batb":[[0,1.48,41.89],[1,1.47,291.53],[2,1.46,88.46]],"batl":[[2,1.56,60]],"ltp":1.52,"tv":25521.56,"id":9631939},{"batb":[[0,2.96,155.61],[1,2.8,33.33],[2,2.7,81.23]],"batl":[[0,3.15,40.91],[1,3.5,138.19],[2,3.55,161.82]],"ltp":2.96,"tv":6761.32,"id":9454286}]}]}
{"op":"mcm","clk":"4290069564","pt":1632497078442,"mc":[{"id":"1.188075669","rc":[{"batb":[[0,1.46,88.46],[1,1.4,269.25],[2,1.39,360.15]],"ltp":1.52,"tv":25521.56,"id":9631939},{"batb":[[0,2.8,33.33],[1,2.7,81.23],[2,2.66,124.24]],"ltp":2.96,"tv":6761.32,"id":9454286}]}]}
{"op":"mcm","clk":"4290069649","pt":1632497079286,"mc":[{"id":"1.188075669","rc":[{"batb":[[0,1.4,269.25],[1,1.39,360.15],[2,1.37,392.08]],"batl":[[2,1.6,213.14]],"ltp":1.52,"tv":25521.56,"id":9631939},{"batb":[[0,2.7,81.23],[1,2.66,124.24],[2,2.64,192.53]],"batl":[[0,3.5,138.19],[1,3.55,161.82],[2,990,0.01]],"ltp":2.96,"tv":6761.32,"id":9454286}]}]}
{"op":"mcm","clk":"4290069851","pt":1632497081686,"mc":[{"id":"1.188075669","rc":[{"batb":[[2,1.37,386.35]],"batl":[[0,1.52,3.41],[1,1.6,213.14],[2,1.61,255.43]],"ltp":1.52,"tv":25521.56,"id":9631939},{"batb":[[0,2.68,82.75]],"ltp":2.96,"tv":6761.32,"id":9454286}]}]}
{"op":"mcm","clk":"4290069932","pt":1632497082476,"mc":[{"id":"1.188075669","rc":[{"batb":[[0,1.4,276.25],[1,1.39,368.15]],"ltp":1.52,"tv":25521.56,"id":9631939},{"batl":[[0,3.5,141.19]],"ltp":2.96,"tv":6761.32,"id":9454286}]}]}
{"op":"mcm","clk":"4290070099","pt":1632497084062,"mc":[{"id":"1.188075669","rc":[{"batb":[[0,1.46,400.19],[1,1.45,258.14],[2,1.4,276.25]],"batl":[[0,1.51,369.76],[1,1.52,211.67],[2,1.6,213.14]],"ltp":1.52,"tv":25521.56,"id":9631939}]}]}
{"op":"mcm","clk":"4290070272","pt":1632497085855,"mc":[{"id":"1.188075669","rc":[{"batb":[[2,1.41,111.08]],"batl":[[0,1.51,386.81]],"ltp":1.52,"tv":25521.56,"id":9631939},{"batb":[[0,2.7,76.67],[1,2.68,82.75],[2,2.66,124.24]],"batl":[[0,3.45,46.62],[1,3.5,141.19],[2,3.55,161.82]],"ltp":2.96,"tv":6761.32,"id":9454286}]}]}
{"op":"mcm","clk":"4290070349","pt":1632497086657,"mc":[{"id":"1.188075669","rc":[{"batb":[[0,1.4,276.25],[1,1.39,368.15],[2,1.37,386.35]],"batl":[[0,1.52,3.41],[1,1.58,10]],"ltp":1.52,"tv":25521.56,"id":9631939},{"batb":[[0,2.68,82.75],[1,2.66,124.24],[2,2.64,192.53]],"batl":[[0,3.5,141.19],[1,3.55,161.82],[2,990,0.01]],"ltp":2.96,"tv":6761.32,"id":9454286}]}]}
{"op":"mcm","clk":"4290070597","pt":1632497089159,"mc":[{"id":"1.188075669","rc":[{"batb":[[1,1.39,609.23],[2,1.38,319.79]],"ltp":1.52,"tv":25521.56,"id":9631939}]}]}
{"op":"mcm","clk":"4290070658","pt":1632497089862,"mc":[{"id":"1.188075669","rc":[{"batl":[[0,1.5,10]],"ltp":1.52,"tv":25521.56,"id":9631939}]}]}
{"op":"mcm","clk":"4290070992","pt":1632497093269,"mc":[{"id":"1.188075669","rc":[{"batl":[[2,1.78,3]],"ltp":1.52,"tv":25521.56,"id":9631939},{"batb":[[1,1.01,139.76],[2,2.64,0]],"ltp":2.96,"tv":6761.32,"id":9454286}]}]}
{"op":"mcm","clk":"4290071248","pt":1632497096201,"mc":[{"id":"1.188075669","rc":[{"batb":[[0,1.39,645.83],[1,1.38,834.69],[2,1.37,386.35]],"batl":[[0,1.42,3006.58],[1,1.43,267.99],[2,1.44,1660.15]],"ltp":1.52,"tv":25521.56,"id":9631939},{"batb":[[0,3.4,7.58],[1,3.35,8.07],[2,2.68,82.75]],"batl":[[0,3.55,169],[1,3.75,637.5],[2,3.8,247.5]],"ltp":2.96,"tv":6761.32,"id":9454286}]}]}
{"op":"mcm","clk":"4290071347","pt":1632497097169,"mc":[{"id":"1.188075669","rc":[{"batb":[[1,1.38,932.02]],"batl":[[0,1.42,442.57],[2,1.44,664.06]],"ltp":1.52,"tv":25521.56,"id":9631939},{"batb":[[0,3.45,111.1],[1,3.4,7.58],[2,3.1,28.57]],"batl":[[0,3.5,8.57],[1,3.55,169],[2,3.65,36.85]],"ltp":2.96,"tv":6761.32,"id":9454286}]}]}
{"op":"mcm","clk":"4290071619","pt":1632497100080,"mc":[{"id":"1.188075669","rc":[{"batb":[[0,1.39,871.83]],"ltp":1.52,"tv":25521.56,"id":9631939}]}]}
{"op":"mcm","clk":"4290071704","pt":1632497101095,"mc":[{"id":"1.188075669","rc":[{"batb":[[2,3.05,2]],"ltp":2.96,"tv":6761.32,"id":9454286}]}]}
{"op":"mcm","clk":"4290071930","pt":1632497103304,"mc":[{"id":"1.188075669","rc":[{"batb":[[0,1.39,1107.83]],"ltp":1.52,"tv":25521.56,"id":9631939}]}]}
{"op":"mcm","clk":"4290072328","pt":1632497107977,"mc":[{"id":"1.188075669","rc":[{"batl":[[0,1.42,226.47]],"ltp":1.52,"tv":25521.56,"id":9631939}]}]}
{"op":"mcm","clk":"4290072422","pt":1632497109180,"mc":[{"id":"1.188075669","rc":[{"batb":[[0,1.38,97.33],[1,1.29,312.75],[2,1.28,479.29]],"batl":[[0,1.46,60],[1,1.5,10],[2,1.51,308.19]],"ltp":1.52,"tv":25521.56,"id":9631939},{"batb":[[0,3,154.71],[1,2.96,118.71],[2,2.94,167.28]],"batl":[[0,3.65,36.85],[1,4.4,120.56],[2,4.5,108.53]],"ltp":2.96,"tv":6761.32,"id":9454286}]}]}
{"op":"mcm","clk":"4290072494","pt":1632497110284,"mc":[{"id":"1.188075669","rc":[{"batb":[[0,1.29,312.75],[1,1.28,479.29],[2,1.27,561.72]],"batl":[[0,1.5,10],[1,1.51,308.19],[2,1.52,312.87]],"ltp":1.52,"tv":25521.56,"id":9631939},{"batl":[[0,4.4,120.56],[1,4.5,108.53],[2,4.6,2]],"ltp":2.96,"tv":6761.32,"id":9454286}]}]}
{"op":"mcm","clk":"4290072623","pt":1632497112119,"mc":[{"id":"1.188075669","rc":[{"batb":[[0,1.29,585.68],[1,1.28,948.3]],"batl":[[1,1.51,595.49],[2,1.52,521.7]],"ltp":1.52,"tv":25521.56,"id":9631939},{"batb":[[0,3.15,27.9],[1,3,154.71],[2,2.96,118.71]],"ltp":2.96,"tv":6761.32,"id":9454286}]}]}
{"op":"mcm","clk":"4290072685","pt":1632497112910,"mc":[{"id":"1.188075669","rc":[{"batl":[[0,1.41,5],[1,1.5,10],[2,1.51,595.49]],"ltp":1.52,"tv":25521.56,"id":9631939},{"batb":[[0,3,154.71],[1,2.96,118.71],[2,2.94,167.28]],"ltp":2.96,"tv":6761.32,"id":9454286}]}]}
{"op":"mcm","clk":"4290072732","pt":1632497113492,"mc":[{"id":"1.188075669","rc":[{"trd":[[1.41,239.61]],"batb":[[0,1.29,322.75],[1,1.28,487.29]],"batl":[[0,1.41,2.65],[2,1.51,308.19]],"ltp":1.41,"tv":25526.26,"id":9631939},{"batl":[[0,4.4,122.56]],"ltp":2.96,"tv":6761.32,"id":9454286}],"tv":32287.58}]}
{"op":"mcm","clk":"4290072933","pt":1632497116215,"mc":[{"id":"1.188075669","rc":[{"batb":[[0,1.37,207.01],[1,1.36,342.15],[2,1.29,322.75]],"batl":[[0,1.4,309.89],[1,1.41,286.53],[2,1.5,10]],"ltp":1.41,"tv":25526.26,"id":9631939}]}]}
{"op":"mcm","clk":"4290073055","pt":1632497118009,"mc":[{"id":"1.188075669","rc":[{"batb":[[0,1.29,322.75],[1,1.28,487.29],[2,1.27,561.72]],"batl":[[0,1.41,2.65],[1,1.5,10],[2,1.51,308.19]],"ltp":1.41,"tv":25526.26,"id":9631939}]}]}
{"op":"mcm","clk":"4290073242","pt":1632497120215,"mc":[{"id":"1.188075669","rc":[{"trd":[[1.41,244.91]],"batb":[[0,1.41,156.34],[1,1.29,595.68],[2,1.28,956.3]],"batl":[[0,1.5,10],[1,1.51,327.8],[2,1.52,208.83]],"ltp":1.41,"tv":25531.56,"id":9631939},{"batb":[[1,2.96,2.38],[2,2.8,2.33]],"ltp":2.96,"tv":6761.32,"id":9454286}],"tv":32292.88}]}
{"op":"mcm","clk":"4290073321","pt":1632497121117,"mc":[{"id":"1.188075669","rc":[{"batb":[[1,1.29,585.68],[2,1.28,948.3]],"batl":[[1,1.51,40.5],[2,1.55,34.1]],"ltp":1.41,"tv":25531.56,"id":9631939},{"batl":[[0,4.4,120.56]],"ltp":2.96,"tv":6761.32,"id":9454286}]}]}
{"op":"mcm","clk":"4290073414","pt":1632497122124,"mc":[{"id":"1.188075669","rc":[{"trd":[[1.41,557.51]],"batb":[[0,1.29,652.22],[1,1.28,948.3],[2,1.27,561.72]],"batl":[[0,1.31,24.92],[1,1.32,3625.74],[2,1.33,1087.87]],"ltp":1.41,"tv":25844.16,"id":9631939},{"batb":[[0,4.1,6.94],[1,3,154.71],[2,2.96,2.38]],"ltp":2.96,"tv":6761.32,"id":9454286}],"tv":32605.48}]}
{"op":"mcm","clk":"4290073501","pt":1632497123124,"mc":[{"id":"1.188075669","rc":[{"batl":[[1,1.32,840.27]],"ltp":1.41,"tv":25844.16,"id":9631939},{"batb":[[0,4.2,132.86],[1,4.1,6.94],[2,3.65,68.49]],"batl":[[0,4.3,6.98],[1,4.4,120.56],[2,4.5,108.53]],"ltp":2.96,"tv":6761.32,"id":9454286}]}]}
{"op":"mcm","clk":"4290073600","pt":1632497124125,"mc":[{"id":"1.188075669","rc":[{"trd":[[4.2,73.05]],"batb":[[0,4.2,99.35]],"ltp":4.2,"tv":6828.37,"id":9454286}],"tv":32672.53}]}
{"op":"mcm","clk":"4290073682","pt":1632497125020,"mc":[{"id":"1.188075669","rc":[{"batb":[[0,1.29,763.63]],"ltp":1.41,"tv":25844.16,"id":9631939}]}]}
{"op":"mcm","clk":"4290073775","pt":1632497126126,"mc":[{"id":"1.188075669","rc":[{"batb":[[0,1.3,1256],[1,1.29,662.78],[2,1.28,948.3]],"ltp":1.41,"tv":25844.16,"id":9631939}]}]}
{"op":"mcm","clk":"4290073867","pt":1632497127128,"mc":[{"id":"1.188075669","rc":[{"batb":[[2,3.95,20.33]],"ltp":4.2,"tv":6828.37,"id":9454286}]}]}
{"op":"mcm","clk":"4290073947","pt":1632497128029,"mc":[{"id":"1.188075669","rc":[{"batl":[[0,1.31,89.08]],"ltp":1.41,"tv":25844.16,"id":9631939},{"batb":[[2,3.65,68.49]],"ltp":4.2,"tv":6828.37,"id":9454286}]}]}
{"op":"mcm","clk":"4290074023","pt":1632497128927,"mc":[{"id":"1.188075669","rc":[{"batl":[[0,1.31,153.23]],"ltp":1.41,"tv":25844.16,"id":9631939}]}]}
{"op":"mcm","clk":"4290074200","pt":1632497131033,"mc":[{"id":"1.188075669","rc":[{"trd":[[1.31,80.24]],"batl":[[0,1.31,144.21],[2,1.33,1147.87]],"ltp":1.31,"tv":25862.2,"id":9631939},{"trd":[[4.2,86.37]],"batb":[[0,4.2,92.69],[2,4,20]],"ltp":4.2,"tv":6841.69,"id":9454286}],"tv":32703.89}]}
{"op":"mcm","clk":"4290074322","pt":1632497132735,"mc":[{"id":"1.188075669","rc":[{"trd":[[1.3,20]],"batb":[[0,1.3,1246]],"ltp":1.3,"tv":25882.2,"id":9631939}],"tv":32723.89}]}
{"op":"mcm","clk":"4290074405","pt":1632497133952,"mc":[{"id":"1.188075669","rc":[{"batl":[[1,1.32,592.2]],"ltp":1.3,"tv":25882.2,"id":9631939}]}]}
{"op":"mcm","clk":"4290074758","pt":1632497138217,"mc":[{"id":"1.188075669","rc":[{"batb":[[1,1.28,46.66],[2,1.27,677.19]],"batl":[[0,1.31,128.31],[1,1.32,64.36],[2,1.33,60]],"ltp":1.3,"tv":25882.2,"id":9631939},{"batl":[[0,4.6,33.62],[1,5.2,2],[2,6,2]],"ltp":4.2,"tv":6841.69,"id":9454286}]}]}
{"op":"mcm","clk":"4290074848","pt":1632497139219,"mc":[{"id":"1.188075669","rc":[{"batb":[[0,1.2,59.92],[1,1.19,865.99],[2,1.16,66.53]],"batl":[[1,1.39,44.5],[2,1.42,41.75]],"ltp":1.3,"tv":25882.2,"id":9631939},{"batb":[[0,3.6,98.95],[1,3.55,2.08],[2,3.35,2.07]],"batl":[[0,6,2],[1,7.4,2],[2,990,0.01]],"ltp":4.2,"tv":6841.69,"id":9454286}]}]}
{"op":"mcm","clk":"4290074973","pt":1632497141116,"mc":[{"id":"1.188075669","rc":[{"batb":[[0,1.2,757.46],[1,1.19,1583.79]],"batl":[[1,1.39,357.08],[2,1.4,292.89]],"ltp":1.3,"tv":25882.2,"id":9631939}]}]}
{"op":"mcm","clk":"4290075028","pt":1632497141751,"mc":[{"id":"1.188075669","rc":[{"trd":[[1.31,84.92]],"batb":[[1,1.19,1567.43]],"batl":[[0,1.31,125.97]],"ltp":1.31,"tv":25886.89,"id":9631939},{"batb":[[0,3.55,103.81],[1,3.35,2.07],[2,2.96,2.38]],"ltp":4.2,"tv":6841.69,"id":9454286}],"tv":32728.58}]}
{"op":"mcm","clk":"4290075083","pt":1632497142436,"mc":[{"id":"1.188075669","rc":[{"batb":[[0,1.2,771.46],[1,1.19,1579.43]],"ltp":1.31,"tv":25886.89,"id":9631939},{"batl":[[0,6,5]],"ltp":4.2,"tv":6841.69,"id":9454286}]}]}
{"op":"mcm","clk":"4290075154","pt":1632497143541,"mc":[{"id":"1.188075669","rc":[{"trd":[[1.31,88.93]],"batl":[[0,1.31,123.97]],"ltp":1.31,"tv":25890.89,"id":9631939}],"tv":32732.58}]}
{"op":"mcm","clk":"4290075259","pt":1632497144640,"mc":[{"id":"1.188075669","rc":[{"batb":[[0,1.22,5],[1,1.21,10],[2,1.2,771.46]],"ltp":1.31,"tv":25890.89,"id":9631939}]}]}
{"op":"mcm","clk":"4290075435","pt":1632497146358,"mc":[{"id":"1.188075669","rc":[{"batb":[[1,1.21,22]],"ltp":1.31,"tv":25890.89,"id":9631939},{"batl":[[0,5.9,2],[1,6,5],[2,7.4,2]],"ltp":4.2,"tv":6841.69,"id":9454286}]}]}
{"op":"mcm","clk":"4290075597","pt":1632497148149,"mc":[{"id":"1.188075669","rc":[{"batb":[[1,1.21,10]],"ltp":1.31,"tv":25890.89,"id":9631939},{"batl":[[0,5.7,2],[1,5.9,2],[2,6,5]],"ltp":4.2,"tv":6841.69,"id":9454286}]}]}
{"op":"mcm","clk":"4290075770","pt":1632497150048,"mc":[{"id":"1.188075669","rc":[{"batb":[[0,1.22,25]],"ltp":1.31,"tv":25890.89,"id":9631939}]}]}
{"op":"mcm","clk":"4290075865","pt":1632497151160,"mc":[{"id":"1.188075669","rc":[{"batb":[[1,1.21,30],[2,1.2,73.92]],"ltp":1.31,"tv":25890.89,"id":9631939}]}]}
{"op":"mcm","clk":"4290075894","pt":1632497151473,"mc":[{"id":"1.188075669","rc":[{"batb":[[2,1.2,14]],"ltp":1.31,"tv":25890.89,"id":9631939},{"batl":[[2,6,3]],"ltp":4.2,"tv":6841.69,"id":9454286}]}]}
{"op":"mcm","clk":"4290075974","pt":1632497152373,"mc":[{"id":"1.188075669","rc":[{"batl":[[0,1.39,357.08],[1,1.4,292.89],[2,1.42,41.75]],"ltp":1.31,"tv":25890.89,"id":9631939}]}]}
{"op":"mcm","clk":"4290076156","pt":1632497154156,"mc":[{"id":"1.188075669","rc":[{"batb":[[0,1.36,9150.33],[1,1.35,1063.26],[2,1.34,687.5]],"batl":[[0,1.38,11.86],[1,1.39,357.08],[2,1.4,292.89]],"ltp":1.31,"tv":25890.89,"id":9631939},{"batb":[[1,3.45,277.18],[2,3.4,269.02]],"batl":[[0,3.7,8.11],[1,3.75,5.52],[2,5.6,2]],"ltp":4.2,"tv":6841.69,"id":9454286}]}]}
{"op":"mcm","clk":"4290076252","pt":1632497155051,"mc":[{"id":"1.188075669","rc":[{"batb":[[0,1.36,986.93],[1,1.35,1475.67]],"ltp":1.31,"tv":25890.89,"id":9631939},{"batl":[[2,4.7,1.71]],"ltp":4.2,"tv":6841.69,"id":9454286}]}]}
{"op":"mcm","clk":"4290076321","pt":1632497155841,"mc":[{"id":"1.188075669","rc":[{"batl":[[1,1.39,455.48]],"ltp":1.31,"tv":25890.89,"id":9631939},{"batb":[[0,3.55,120.44]],"batl":[[2,4.2,2]],"ltp":4.2,"tv":6841.69,"id":9454286}]}]}
{"op":"mcm","clk":"4290076526","pt":1632497158174,"mc":[{"id":"1.188075669","rc":[{"batb":[[0,1.37,201],[1,1.36,986.93],[2,1.35,1475.67]],"batl":[[1,1.39,410.98]],"ltp":1.31,"tv":25890.89,"id":9631939},{"batb":[[0,3.55,118.36]],"ltp":4.2,"tv":6841.69,"id":9454286}]}]}
{"op":"mcm","clk":"4290076617","pt":1632497159174,"mc":[{"id":"1.188075669","rc":[{"batb":[[0,3.55,141.88]],"ltp":4.2,"tv":6841.69,"id":9454286}]}]}
{"op":"mcm","clk":"4290076854","pt":1632497161654,"mc":[{"id":"1.188075669","rc":[{"trd":[[1.38,15.53]],"batb":[[0,1.37,355]],"batl":[[0,1.38,11.76]],"ltp":1.38,"tv":25891.09,"id":9631939}],"tv":32732.78}]}
{"op":"mcm","clk":"4290077386","pt":1632497166151,"mc":[{"id":"1.188075669","rc":[{"trd":[[1.37,564.45],[1.38,25.53]],"batb":[[0,1.37,99.04],[1,1.36,279.26]],"batl":[[0,1.38,6.76]],"ltp":1.37,"tv":26412.67,"id":9631939}],"tv":33254.36}]}
{"op":"mcm","clk":"4290077621","pt":1632497168163,"mc":[{"id":"1.188075669","rc":[{"batl":[[2,4.2,2.04]],"ltp":4.2,"tv":6841.69,"id":9454286}]}]}
{"op":"mcm","clk":"4290077951","pt":1632497171997,"mc":[{"id":"1.188075669","rc":[{"batb":[[1,1.24,668.52],[2,1.23,11]],"batl":[[0,1.39,60],[1,1.47,39.5],[2,1.5,41.17]],"ltp":1.37,"tv":26412.67,"id":9631939},{"batb":[[0,3.55,23.52],[1,3.1,2.24],[2,3.05,149.39]],"batl":[[0,990,0.04],[1,3.75,0],[2,4.2,0]],"ltp":4.2,"tv":6841.69,"id":9454286}]}]}
{"op":"mcm","clk":"4290078056","pt":1632497173161,"mc":[{"id":"1.188075669","rc":[{"batb":[[0,1.24,668.52],[1,1.23,11],[2,1.22,25]],"batl":[[0,1.47,39.5],[1,1.5,41.17],[2,1.51,40.5]],"ltp":1.37,"tv":26412.67,"id":9631939}]}]}
{"op":"mcm","clk":"4290078089","pt":1632497173470,"mc":[{"id":"1.188075669","rc":[{"batl":[[0,1.5,41.17],[1,1.51,40.5],[2,1.55,34.1]],"ltp":1.37,"tv":26412.67,"id":9631939},{"batb":[[0,3.05,149.39],[1,3,2.5],[2,2.96,2.38]],"ltp":4.2,"tv":6841.69,"id":9454286}]}]}
{"op":"mcm","clk":"4290078232","pt":1632497175000,"mc":[{"id":"1.188075669","rc":[{"batb":[[0,1.24,1258.38],[1,1.23,614.01]],"batl":[[0,1.49,229.01],[1,1.5,261.49],[2,1.51,40.5]],"ltp":1.37,"tv":26412.67,"id":9631939}]}]}
{"op":"mcm","clk":"4290078336","pt":1632497176163,"mc":[{"id":"1.188075669","rc":[{"batb":[[0,1.24,1259.01]],"batl":[[0,1.47,10],[1,1.49,229.01],[2,1.5,261.49]],"ltp":1.37,"tv":26412.67,"id":9631939}]}]}
{"op":"mcm","clk":"4290078352","pt":1632497176372,"mc":[{"id":"1.188075669","rc":[{"batb":[[0,1.24,1268.01]],"ltp":1.37,"tv":26412.67,"id":9631939},{"batl":[[0,5.2,2.04],[1,990,0.01]],"ltp":4.2,"tv":6841.69,"id":9454286}]}]}
{"op":"mcm","clk":"4290078680","pt":1632497180880,"mc":[{"id":"1.188075669","rc":[{"batb":[[0,1.24,1267.38]],"batl":[[1,1.5,41.17],[2,1.51,40.5]],"ltp":1.37,"tv":26412.67,"id":9631939}]}]}
{"op":"mcm","clk":"4290078947","pt":1632497184189,"mc":[{"id":"1.188075669","rc":[{"trd":[[1.31,89.05]],"batb":[[0,1.24,1308.38],[2,1.22,858.31]],"batl":[[0,1.26,28.16],[1,1.27,4166.73],[2,1.28,1181.51]],"ltp":1.31,"tv":26412.79,"id":9631939},{"trd":[[4.2,86.41]],"batb":[[0,4.7,6.52],[1,4.5,249.42],[2,3.05,149.39]],"batl":[[0,5.1,3.52],[1,5.5,173.86],[2,5.6,168.76]],"ltp":4.2,"tv":6841.72,"id":9454286}],"tv":33254.52}]}
{"op":"mcm","clk":"4290079043","pt":1632497185193,"mc":[{"id":"1.188075669","rc":[{"batb":[[2,1.22,833.31]],"batl":[[1,1.27,1560.72]],"ltp":1.31,"tv":26412.79,"id":9631939},{"batb":[[0,4.7,110.02],[2,3.9,163.48]],"batl":[[0,5,6],[1,5.1,3.52],[2,5.2,10.2]],"ltp":4.2,"tv":6841.72,"id":9454286}]}]}
{"op":"mcm","clk":"4290079061","pt":1632497185404,"mc":[{"id":"1.188075669","rc":[{"batb":[[1,1.23,739.11]],"ltp":1.31,"tv":26412.79,"id":9631939},{"batb":[[2,4.4,17.64]],"batl":[[2,5.2,39.47]],"ltp":4.2,"tv":6841.72,"id":9454286}]}]}
{"op":"mcm","clk":"4290079330","pt":1632497188208,"mc":[{"id":"1.188075669","rc":[{"batb":[[0,1.25,208],[1,1.24,1308.38],[2,1.23,739.11]],"ltp":1.31,"tv":26412.79,"id":9631939},{"batb":[[0,4.7,125.82]],"ltp":4.2,"tv":6841.72,"id":9454286}]}]}
{"op":"mcm","clk":"4290079411","pt":1632497189154,"mc":[{"id":"1.188075669","rc":[{"batb":[[2,3.9,163.48]],"ltp":4.2,"tv":6841.72,"id":9454286}]}]}
{"op":"mcm","clk":"4290079564","pt":1632497191099,"mc":[{"id":"1.188075669","rc":[{"batb":[[0,1.25,1623]],"ltp":1.31,"tv":26412.79,"id":9631939},{"batb":[[2,3.9,165.48]],"ltp":4.2,"tv":6841.72,"id":9454286}]}]}
{"op":"mcm","clk":"4290079675","pt":1632497192201,"mc":[{"id":"1.188075669","rc":[{"batb":[[1,4.5,266.56]],"ltp":4.2,"tv":6841.72,"id":9454286}]}]}
{"op":"mcm","clk":"4290079764","pt":1632497193208,"mc":[{"id":"1.188075669","rc":[{"trd":[[1.26,1.26]],"batl":[[0,1.26,27.53]],"ltp":1.26,"tv":26414.05,"id":9631939}],"tv":33255.78}]}
{"op":"mcm","clk":"4290079838","pt":1632497194103,"mc":[{"id":"1.188075669","rc":[{"trd":[[1.26,1.76]],"batl":[[0,1.26,27.28]],"ltp":1.26,"tv":26414.55,"id":9631939}],"tv":33256.28}]}
{"op":"mcm","clk":"4290079916","pt":1632497195005,"mc":[{"id":"1.188075669","rc":[{"trd":[[1.26,11.76]],"batl":[[0,1.26,22.28]],"ltp":1.26,"tv":26424.55,"id":9631939}],"tv":33266.28}]}
{"op":"mcm","clk":"4290079982","pt":1632497195706,"mc":[{"id":"1.188075669","rc":[{"batl":[[1,1.27,1336.05]],"ltp":1.26,"tv":26424.55,"id":9631939}]}]}
{"op":"mcm","clk":"4290080190","pt":1632497198213,"mc":[{"id":"1.188075669","rc":[{"trd":[[1.26,16.46]],"batl":[[0,1.26,19.93],[1,1.27,583.11],[2,1.28,450.71]],"ltp":1.26,"tv":26429.25,"id":9631939},{"batb":[[1,4.5,17.14]],"batl":[[0,5.1,3.52],[1,5.2,39.47],[2,6.6,101.44]],"ltp":4.2,"tv":6841.72,"id":9454286}],"tv":33270.98}]}
{"op":"mcm","clk":"4290080227","pt":1632497198688,"mc":[{"id":"1.188075669","rc":[{"batb":[[1,1.23,125.1],[2,1.15,1122.35]],"batl":[[0,1.29,60],[1,1.34,44.25],[2,1.37,39.5]],"ltp":1.26,"tv":26429.25,"id":9631939},{"batb":[[0,4.5,17.14],[1,3.9,165.48],[2,3.7,2.02]],"batl":[[0,5.2,29.27],[1,6.6,101.44],[2,990,0.01]],"ltp":4.2,"tv":6841.72,"id":9454286}]}]}
{"op":"mcm","clk":"4290080416","pt":1632497201009,"mc":[{"id":"1.188075669","rc":[{"batb":[[0,1.26,10.55],[1,1.15,1122.35],[2,1.12,2.53]],"batl":[[0,1.37,39.5],[1,1.47,10],[2,1.5,41.17]],"ltp":1.26,"tv":26429.25,"id":9631939},{"batb":[[0,3.9,163.48],[1,3.7,2.02],[2,3,2.5]],"batl":[[0,6.6,101.44],[1,990,0.01],[2,990,0]],"ltp":4.2,"tv":6841.72,"id":9454286}]}]}
{"op":"mcm","clk":"4290080468","pt":1632497201430,"mc":[{"id":"1.188075669","rc":[{"batb":[[1,1.16,356.13],[2,1.15,2101.1]],"batl":[[0,1.34,230.18],[1,1.35,347.51],[2,1.37,39.5]],"ltp":1.26,"tv":26429.25,"id":9631939}]}]}
{"op":"mcm","clk":"4290080585","pt":1632497202325,"mc":[{"id":"1.188075669","rc":[{"batb":[[1,1.15,1122.35],[2,1.12,2.53]],"ltp":1.26,"tv":26429.25,"id":9631939}]}]}
{"op":"mcm","clk":"4290080721","pt":1632497203911,"mc":[{"id":"1.188075669","rc":[{"batb":[[0,1.17,12],[1,1.16,13],[2,1.15,1122.35]],"batl":[[0,1.34,275.43]],"ltp":1.26,"tv":26429.25,"id":9631939},{"batb":[[0,3.9,165.48]],"ltp":4.2,"tv":6841.72,"id":9454286}]}]}
{"op":"mcm","clk":"4290080837","pt":1632497205121,"mc":[{"id":"1.188075669","rc":[{"batb":[[0,1.31,8409.72],[1,1.3,2942.3],[2,1.29,2855.76]],"batl":[[2,1.36,681.83]],"ltp":1.26,"tv":26429.25,"id":9631939},{"batb":[[1,3.8,1006.58],[2,3.75,976.98]],"batl":[[0,4.1,7.32],[1,4.4,187.26],[2,990,0.01]],"ltp":4.2,"tv":6841.72,"id":9454286}]}]}
{"op":"mcm","clk":"4290080928","pt":1632497206127,"mc":[{"id":"1.188075669","rc":[{"batb":[[0,1.31,1705.06],[1,1.3,1170.5],[2,1.29,713.94]],"batl":[[0,1.33,10],[1,1.34,275.43],[2,1.35,347.51]],"ltp":1.26,"tv":26429.25,"id":9631939},{"batb":[[1,3.8,251.64],[2,3.75,244.24]],"ltp":4.2,"tv":6841.72,"id":9454286}]}]}
{"op":"mcm","clk":"4290080997","pt":1632497206925,"mc":[{"id":"1.188075669","rc":[{"batl":[[0,1.34,275.43],[1,1.35,347.51],[2,1.36,681.83]],"ltp":1.26,"tv":26429.25,"id":9631939},{"batb":[[0,3.9,181.82]],"batl":[[2,4.9,44.98]],"ltp":4.2,"tv":6841.72,"id":9454286}]}]}
{"op":"mcm","clk":"4290081109","pt":1632497208132,"mc":[{"id":"1.188075669","rc":[{"batb":[[0,1.32,14.81],[1,1.31,1705.06],[2,1.3,1170.5]],"batl":[[0,1.34,298.43],[1,1.35,407.51]],"ltp":1.26,"tv":26429.25,"id":9631939},{"batb":[[1,3.85,21.05],[2,3.8,251.64]],"batl":[[2,4.5,32.07]],"ltp":4.2,"tv":6841.72,"id":9454286}]}]}
{"op":"mcm","clk":"4290081169","pt":1632497208723,"mc":[{"id":"1.188075669","rc":[{"batb":[[0,1.31,1705.06],[1,1.3,1170.5],[2,1.29,825.35]],"batl":[[0,1.34,230.18]],"ltp":1.26,"tv":26429.25,"id":9631939},{"batb":[[0,3.9,179.82]],"ltp":4.2,"tv":6841.72,"id":9454286}]}]}
{"op":"mcm","clk":"4290081302","pt":1632497210129,"mc":[{"id":"1.188075669","rc":[{"batb":[[0,1.32,173],[1,1.31,1705.06],[2,1.3,1170.5]],"ltp":1.26,"tv":26429.25,"id":9631939},{"trd":[[3.9,8.46]],"batb":[[0,3.9,175.59]],"ltp":3.9,"tv":6850.18,"id":9454286}],"tv":33279.43}]}
{"op":"mcm","clk":"4290081390","pt":1632497211129,"mc":[{"id":"1.188075669","rc":[{"trd":[[1.32,4]],"batb":[[0,1.32,171]],"ltp":1.32,"tv":26433.25,"id":9631939},{"batl":[[2,4.9,44.98]],"ltp":3.9,"tv":6850.18,"id":9454286}],"tv":33283.43}]}
{"op":"mcm","clk":"4290081460","pt":1632497211924,"mc":[{"id":"1.188075669","rc":[{"trd":[[1.32,17.68]],"batb":[[0,1.32,164.16]],"ltp":1.32,"tv":26446.93,"id":9631939}],"tv":33297.12}]}
{"op":"mcm","clk":"4290081663","pt":1632497213717,"mc":[{"id":"1.188075669","rc":[{"batb":[[0,1.32,315.16]],"ltp":1.32,"tv":26446.93,"id":9631939},{"batl":[[1,4.4,219.79]],"ltp":3.9,"tv":6850.18,"id":9454286}]}]}
{"op":"mcm","clk":"4290081914","pt":1632497217130,"mc":[{"id":"1.188075669","rc":[{"batb":[[1,1.31,1037.62]],"ltp":1.32,"tv":26446.93,"id":9631939}]}]}
{"op":"mcm","clk":"4290081938","pt":1632497217433,"mc":[{"id":"1.188075669","rc":[{"batb":[[0,1.32,329.97]],"batl":[[0,1.34,253.18]],"ltp":1.32,"tv":26446.93,"id":9631939}]}]}
{"op":"mcm","clk":"4290082113","pt":1632497220053,"mc":[{"id":"1.188075669","rc":[{"batb":[[0,1.32,315.16],[1,1.31,488.16],[2,1.29,111.41]],"batl":[[0,1.35,60],[1,1.46,37.25],[2,1.47,10]],"ltp":1.32,"tv":26446.93,"id":9631939},{"batb":[[0,3.9,159.25],[2,3.15,2.03]],"batl":[[0,4.4,32.53],[1,5.5,117.98],[2,6.8,2]],"ltp":3.9,"tv":6850.18,"id":9454286}]}]}
{"op":"mcm","clk":"4290082153","pt":1632497220643,"mc":[{"id":"1.188075669","rc":[{"trd":[[1.34,57.54]],"batb":[[0,1.32,315.51],[1,1.29,111.41],[2,1.26,2.81]],"ltp":1.34,"tv":26450.93,"id":9631939},{"batb":[[0,3.85,21.05],[1,3.15,2.03],[2,3.05,149.22]],"ltp":3.9,"tv":6850.18,"id":9454286}],"tv":33301.11}]}
{"op":"mcm","clk":"4290082262","pt":1632497221925,"mc":[{"id":"1.188075669","rc":[{"batb":[[0,1.26,3.16],[1,1.16,1060.69],[2,1.12,2.53]],"batl":[[0,1.47,10],[1,1.5,41.17],[2,1.51,40.5]],"ltp":1.34,"tv":26450.93,"id":9631939},{"batb":[[0,3.05,149.22],[1,3,2.5],[2,2.96,2.38]],"batl":[[0,6.8,2],[1,990,0.01],[2,6.8,0]],"ltp":3.9,"tv":6850.18,"id":9454286}]}]}
{"op":"mcm","clk":"4290082361","pt":1632497223032,"mc":[{"id":"1.188075669","rc":[{"batl":[[0,4.3,44.98],[1,6.8,2],[2,990,0.01]],"ltp":3.9,"tv":6850.18,"id":9454286}]}]}
{"op":"mcm","clk":"4290082390","pt":1632497223451,"mc":[{"id":"1.188075669","rc":[{"trd":[[1.34,58.24]],"batb":[[0,1.26,2.81]],"ltp":1.34,"tv":26451.63,"id":9631939},{"batl":[[0,6.8,2],[1,990,0.01],[2,990,0]],"ltp":3.9,"tv":6850.18,"id":9454286}],"tv":33301.81}]}
{"op":"mcm","clk":"4290082481","pt":1632497224925,"mc":[{"id":"1.188075669","rc":[{"batl":[[0,1.46,39.25],[1,1.47,10],[2,1.5,41.17]],"ltp":1.34,"tv":26451.63,"id":9631939},{"batb":[[0,3.15,2.23],[1,3.05,149.22],[2,3,2.5]],"ltp":3.9,"tv":6850.18,"id":9454286}]}]}
{"op":"mcm","clk":"4290082561","pt":1632497225937,"mc":[{"id":"1.188075669","rc":[{"batb":[[0,1.28,402.04],[1,1.27,511.85],[2,1.26,2.81]],"batl":[[0,1.31,455.14],[1,1.32,384.33],[2,1.33,20.5]],"ltp":1.34,"tv":26451.63,"id":9631939},{"batb":[[0,3.05,149.22],[1,3,2.5],[2,2.96,2.38]],"batl":[[0,4.6,18.06],[1,6.8,2],[2,990,0.01]],"ltp":3.9,"tv":6850.18,"id":9454286}]}]}
{"op":"mcm","clk":"4290082616","pt":1632497226668,"mc":[{"id":"1.188075669","rc":[{"batb":[[1,1.27,492.98]],"batl":[[2,1.46,5]],"ltp":1.34,"tv":26451.63,"id":9631939},{"batl":[[0,6.8,2],[1,990,0.01],[2,990,0]],"ltp":3.9,"tv":6850.18,"id":9454286}]}]}
{"op":"mcm","clk":"4290082696","pt":1632497227776,"mc":[{"id":"1.188075669","rc":[{"batb":[[1,1.27,507.03]],"ltp":1.34,"tv":26451.63,"id":9631939},{"batb":[[0,3.75,64.27],[1,3.05,149.22],[2,3,2.5]],"batl":[[0,5.4,10],[1,6.8,2],[2,990,0.01]],"ltp":3.9,"tv":6850.18,"id":9454286}]}]}
{"op":"mcm","clk":"4290082805","pt":1632497228974,"mc":[{"id":"1.188075669","rc":[{"batl":[[2,1.46,42.25]],"ltp":1.34,"tv":26451.63,"id":9631939},{"batb":[[0,3.75,10.15],[1,3.15,2.03],[2,3.05,149.22]],"batl":[[1,6,108.85],[2,6.8,2]],"ltp":3.9,"tv":6850.18,"id":9454286}]}]}
{"op":"mcm","clk":"4290082853","pt":1632497229558,"mc":[{"id":"1.188075669","rc":[{"trd":[[1.31,93.75]],"batl":[[0,1.31,452.79]],"ltp":1.31,"tv":26456.33,"id":9631939}],"tv":33306.51}]}
{"op":"mcm","clk":"4290082993","pt":1632497231152,"mc":[{"id":"1.188075669","rc":[{"batb":[[0,1.29,174],[1,1.26,2.81],[2,1.16,1060.69]],"batl":[[0,1.31,54.78],[1,1.46,5],[2,1.5,41.17]],"ltp":1.31,"tv":26456.33,"id":9631939},{"batb":[[0,3.05,149.22],[1,3,2.5],[2,2.96,2.38]],"batl":[[0,6,108.85],[1,6.8,2],[2,990,0.01]],"ltp":3.9,"tv":6850.18,"id":9454286}]}]}
{"op":"mcm","clk":"4290083014","pt":1632497231356,"mc":[{"id":"1.188075669","rc":[{"batb":[[0,1.26,2.81],[1,1.16,1060.69],[2,1.12,2.53]],"batl":[[0,1.46,5],[1,1.5,41.17],[2,1.51,40.5]],"ltp":1.31,"tv":26456.33,"id":9631939}]}]}
{"op":"mcm","clk":"4290083222","pt":1632497233962,"mc":[{"id":"1.188075669","rc":[{"batb":[[1,1.16,1868.28],[2,1.15,656.01]],"batl":[[0,1.46,40.75],[1,1.49,346.88],[2,1.5,260.6]],"ltp":1.31,"tv":26456.33,"id":9631939},{"batb":[[0,3.15,2.03],[1,3.05,149.22],[2,3,2.5]],"ltp":3.9,"tv":6850.18,"id":9454286}]}]}
{"op":"mcm","clk":"4290083250","pt":1632497234268,"mc":[{"id":"1.188075669","rc":[{"batl":[[0,1.46,5]],"ltp":1.31,"tv":26456.33,"id":9631939},{"batb":[[0,3.05,149.22],[1,3,2.5],[2,2.96,2.38]],"ltp":3.9,"tv":6850.18,"id":9454286}]}]}
{"op":"mcm","clk":"4290083662","pt":1632497238963,"mc":[{"id":"1.188075669","rc":[{"batl":[[1,1.5,41.17],[2,1.51,40.5]],"ltp":1.31,"tv":26456.33,"id":9631939}]}]}
{"op":"mcm","clk":"4290083701","pt":1632497239477,"mc":[{"id":"1.188075669","rc":[{"batb":[[0,1.31,2.35],[1,1.26,2.81],[2,1.16,1868.28]],"batl":[[1,1.58,10],[2,1.8,16.88]],"ltp":1.31,"tv":26456.33,"id":9631939},{"batb":[[2,2.52,386.62]],"ltp":3.9,"tv":6850.18,"id":9454286}]}]}
{"op":"mcm","clk":"4290083805","pt":1632497240982,"mc":[{"id":"1.188075669","rc":[{"batl":[[0,1.46,43.25]],"ltp":1.31,"tv":26456.33,"id":9631939},{"batb":[[0,3.15,2.03],[1,3.05,149.22],[2,3,2.5]],"ltp":3.9,"tv":6850.18,"id":9454286}]}]}
{"op":"mcm","clk":"4290083915","pt":1632497242152,"mc":[{"id":"1.188075669","rc":[{"trd":[[1.16,73.77],[1.26,22.09],[1.31,98.44]],"batb":[[0,1.16,1884.86],[1,1.15,656.01],[2,1.12,1720.39]],"batl":[[0,1.18,3956.73],[1,1.19,715.24],[2,1.22,24.59]],"ltp":1.16,"tv":26540.42,"id":9631939},{"batb":[[0,6.4,622.44],[1,6.2,145.02],[2,6,145.02]],"batl":[[0,8,126.07],[1,8.2,116.02],[2,8.4,116.02]],"ltp":3.9,"tv":6850.18,"id":9454286}],"tv":33390.61}]}
{"op":"mcm","clk":"4290084015","pt":1632497243161,"mc":[{"id":"1.188075669","rc":[{"batb":[[0,1.16,2034.86],[2,1.13,1300]],"batl":[[0,1.18,669.16]],"ltp":1.16,"tv":26540.42,"id":9631939},{"batb":[[0,6.4,501.49]],"batl":[[0,7.2,4.17],[1,8,126.07],[2,8.2,117.73]],"ltp":3.9,"tv":6850.18,"id":9454286}]}]}
{"op":"mcm","clk":"4290084104","pt":1632497244162,"mc":[{"id":"1.188075669","rc":[{"batb":[[0,1.16,1884.86]],"ltp":1.16,"tv":26540.42,"id":9631939},{"batb":[[2,6,148.02]],"ltp":3.9,"tv":6850.18,"id":9454286}]}]}
{"op":"mcm","clk":"4290084195","pt":1632497245067,"mc":[{"id":"1.188075669","rc":[{"batb":[[0,1.16,1928.36]],"batl":[[0,1.18,727.26]],"ltp":1.16,"tv":26540.42,"id":9631939},{"batb":[[0,6.6,9.12],[1,6.4,501.49],[2,6.2,145.02]],"batl":[[1,7.8,16.63],[2,8,126.07]],"ltp":3.9,"tv":6850.18,"id":9454286}]}]}
{"op":"mcm","clk":"4290084404","pt":1632497247163,"mc":[{"id":"1.188075669","rc":[{"batb":[[2,1.14,160.35]],"ltp":1.16,"tv":26540.42,"id":9631939}]}]}
{"op":"mcm","clk":"4290084490","pt":1632497248095,"mc":[{"id":"1.188075669","rc":[{"batl":[[1,7.8,39.63]],"ltp":3.9,"tv":6850.18,"id":9454286}]}]}
{"op":"mcm","clk":"4290084594","pt":1632497249154,"mc":[{"id":"1.188075669","rc":[{"batb":[[2,1.14,590.27]],"ltp":1.16,"tv":26540.42,"id":9631939},{"batl":[[2,8,208.56]],"ltp":3.9,"tv":6850.18,"id":9454286}]}]}
{"op":"mcm","clk":"4290084639","pt":1632497249791,"mc":[{"id":"1.188075669","rc":[{"batl":[[1,1.19,775.24]],"ltp":1.16,"tv":26540.42,"id":9631939}]}]}
{"op":"mcm","clk":"4290084768","pt":1632497251176,"mc":[{"id":"1.188075669","rc":[{"batb":[[0,1.16,904.54],[1,1.15,1719.39]],"ltp":1.16,"tv":26540.42,"id":9631939},{"batb":[[1,6.4,512.17]],"ltp":3.9,"tv":6850.18,"id":9454286}]}]}
{"op":"mcm","clk":"4290084854","pt":1632497252174,"mc":[{"id":"1.188075669","rc":[{"trd":[[1.18,230.72]],"batl":[[0,1.18,727.09]],"ltp":1.18,"tv":26540.76,"id":9631939},{"batl":[[2,8,202.01]],"ltp":3.9,"tv":6850.18,"id":9454286}],"tv":33390.95}]}
{"op":"mcm","clk":"4290085019","pt":1632497253873,"mc":[{"id":"1.188075669","rc":[{"batl":[[0,1.18,443.4]],"ltp":1.18,"tv":26540.76,"id":9631939}]}]}
{"op":"mcm","clk":"4290085111","pt":1632497255081,"mc":[{"id":"1.188075669","rc":[{"batl":[[0,1.17,40.87],[1,1.18,443.4],[2,1.19,775.24]],"ltp":1.18,"tv":26540.76,"id":9631939},{"batl":[[1,7.6,5.89],[2,7.8,39.63]],"ltp":3.9,"tv":6850.18,"id":9454286}]}]}
{"op":"mcm","clk":"4290085125","pt":1632497255298,"mc":[{"id":"1.188075669","rc":[{"trd":[[1.17,0.26]],"batl":[[0,1.17,40.74]],"ltp":1.17,"tv":26541.02,"id":9631939}],"tv":33391.21}]}
{"op":"mcm","clk":"4290085226","pt":1632497256562,"mc":[{"id":"1.188075669","rc":[{"trd":[[1.17,1.52]],"batl":[[0,1.17,40.11]],"ltp":1.17,"tv":26542.28,"id":9631939}],"tv":33392.47}]}
{"op":"mcm","clk":"4290085397","pt":1632497258680,"mc":[{"id":"1.188075669","rc":[{"trd":[[1.16,74.05]],"batb":[[0,1.16,904.4]],"ltp":1.16,"tv":26542.56,"id":9631939}],"tv":33392.75}]}
{"op":"mcm","clk":"4290085445","pt":1632497259366,"mc":[{"id":"1.188075669","rc":[{"trd":[[1.17,6.41]],"batl":[[0,1.17,35.22]],"ltp":1.17,"tv":26547.45,"id":9631939},{"trd":[[6.8,0.84]],"ltp":6.8,"tv":6851.02,"id":9454286}],"tv":33398.48}]}
{"op":"mcm","clk":"4290085661","pt":1632497262097,"mc":[{"id":"1.188075669","rc":[{"trd":[[1.16,254.37]],"batb":[[0,1.16,897.13]],"ltp":1.16,"tv":26727.77,"id":9631939}],"tv":33578.8}]}
{"op":"mcm","clk":"4290085747","pt":1632497263304,"mc":[{"id":"1.188075669","rc":[{"trd":[[1.17,11.88]],"batl":[[0,1.17,32.49]],"ltp":1.17,"tv":26733.24,"id":9631939}],"tv":33584.26}]}
{"op":"mcm","clk":"4290085900","pt":1632497265198,"mc":[{"id":"1.188075669","rc":[{"batb":[[0,1.16,875.21],[1,1.15,1781.57]],"batl":[[0,1.18,502.81],[1,1.19,775.24],[2,1.22,24.59]],"ltp":1.17,"tv":26733.24,"id":9631939},{"batb":[[1,6.4,263.27]],"batl":[[1,7.8,39.63],[2,8,202.01]],"ltp":6.8,"tv":6851.02,"id":9454286}]}]}
{"op":"mcm","clk":"4290085919","pt":1632497265512,"mc":[{"id":"1.188075669","rc":[{"batb":[[0,1.17,7.84],[1,1.16,875.21],[2,1.15,718.19]],"ltp":1.17,"tv":26733.24,"id":9631939},{"batb":[[1,6.4,160.53]],"ltp":6.8,"tv":6851.02,"id":9454286}]}]}
{"op":"mcm","clk":"4290085980","pt":1632497266378,"mc":[{"id":"1.188075669","rc":[{"trd":[[1.18,238.53]],"batl":[[0,1.18,498.9],[1,1.19,715.24]],"ltp":1.18,"tv":26741.05,"id":9631939},{"batb":[[1,6.4,149.42]],"batl":[[1,7.8,16.63]],"ltp":6.8,"tv":6851.02,"id":9454286}],"tv":33592.08}]}
{"op":"mcm","clk":"4290086343","pt":1632497270879,"mc":[{"id":"1.188075669","rc":[{"trd":[[1.18,335.91]],"batb":[[2,1.15,682.07]],"batl":[[0,1.18,450.18]],"ltp":1.18,"tv":26838.43,"id":9631939}],"tv":33689.45}]}
{"op":"mcm","clk":"4290086445","pt":1632497271886,"mc":[{"id":"1.188075669","rc":[{"trd":[[1.16,444.13],[1.17,27.55]],"batb":[[0,1.16,780.27],[1,1.15,682.07],[2,1.14,429.92]],"ltp":1.16,"tv":27043.86,"id":9631939}],"tv":33894.88}]}
{"op":"mcm","clk":"4290086599","pt":1632497273897,"mc":[{"id":"1.188075669","rc":[{"batb":[[0,1.16,816.08]],"ltp":1.16,"tv":27043.86,"id":9631939}]}]}
{"op":"mcm","clk":"4290086671","pt":1632497274900,"mc":[{"id":"1.188075669","rc":[{"batb":[[0,1.16,847.55],[1,1.15,746.09]],"batl":[[0,1.18,530.1]],"ltp":1.16,"tv":27043.86,"id":9631939}]}]}
{"op":"mcm","clk":"4290086987","pt":1632497279084,"mc":[{"id":"1.188075669","rc":[{"batb":[[0,1.16,126.39],[1,1.14,429.92],[2,1.13,1895.97]],"batl":[[0,1.18,58.1],[1,1.22,24.59],[2,1.25,343.25]],"ltp":1.16,"tv":27043.86,"id":9631939}]}]}
{"op":"mcm","clk":"4290087002","pt":1632497279295,"mc":[{"id":"1.188075669","rc":[{"batl":[[0,1.22,24.59],[1,1.25,343.25],[2,1.26,475.29]],"ltp":1.16,"tv":27043.86,"id":9631939}]}]}
{"op":"mcm","clk":"4290087244","pt":1632497282023,"mc":[{"id":"1.188075669","rc":[{"batb":[[2,1.13,3253.81]],"batl":[[1,1.24,478.56],[2,1.25,862.74]],"ltp":1.16,"tv":27043.86,"id":9631939}]}]}
{"op":"mcm","clk":"4290087379","pt":1632497283716,"mc":[{"id":"1.188075669","rc":[{"batl":[[1,8,202.01],[2,8.2,208.53]],"ltp":6.8,"tv":6851.02,"id":9454286}]}]}
{"op":"mcm","clk":"4290087556","pt":1632497286120,"mc":[{"id":"1.188075669","rc":[{"batl":[[0,1.18,58.1],[1,1.22,3024.59],[2,1.24,478.56]],"ltp":1.16,"tv":27043.86,"id":9631939}]}]}
{"op":"mcm","clk":"4290087625","pt":1632497287114,"mc":[{"id":"1.188075669","rc":[{"batl":[[0,1.22,24.59],[1,1.24,478.56],[2,1.25,862.74]],"ltp":1.16,"tv":27043.86,"id":9631939},{"batl":[[0,7.2,11.01]],"ltp":6.8,"tv":6851.02,"id":9454286}]}]}
{"op":"mcm","clk":"4290087734","pt":1632497288222,"mc":[{"id":"1.188075669","rc":[{"batl":[[0,1.24,478.56],[1,1.25,862.74],[2,1.26,475.29]],"ltp":1.16,"tv":27043.86,"id":9631939},{"batb":[[0,6,3],[1,5.1,86.8],[2,5,113.75]],"batl":[[0,8,82.49],[1,8.2,92.51],[2,9.8,77.11]],"ltp":6.8,"tv":6851.02,"id":9454286}]}]}
{"op":"mcm","clk":"4290087832","pt":1632497289190,"mc":[{"id":"1.188075669","rc":[{"batb":[[0,1.16,96.89],[1,1.15,13],[2,1.14,429.92]],"batl":[[2,1.26,472.29]],"ltp":1.16,"tv":27043.86,"id":9631939},{"batb":[[0,5.1,86.8],[1,5,113.75],[2,4.9,113.23]],"ltp":6.8,"tv":6851.02,"id":9454286}]}]}
{"op":"mcm","clk":"4290087884","pt":1632497289728,"mc":[{"id":"1.188075669","rc":[{"batb":[[0,1.16,82.89],[1,1.14,429.92],[2,1.13,3253.81]],"ltp":1.16,"tv":27043.86,"id":9631939}]}]}
{"op":"mcm","clk":"4290088071","pt":1632497291705,"mc":[{"id":"1.188075669","rc":[{"batl":[[2,9.4,2]],"ltp":6.8,"tv":6851.02,"id":9454286}]}]}
{"op":"mcm","clk":"4290088225","pt":1632497293539,"mc":[{"id":"1.188075669","rc":[{"batb":[[2,1.13,1895.97]],"batl":[[0,1.25,343.25],[1,1.26,472.29],[2,1.42,30.75]],"ltp":1.16,"tv":27043.86,"id":9631939}]}]}
{"op":"mcm","clk":"4290088311","pt":1632497294665,"mc":[{"id":"1.188075669","rc":[{"batb":[[0,1.18,10.55],[1,1.16,82.89],[2,1.14,429.92]],"ltp":1.16,"tv":27043.86,"id":9631939}]}]}
{"op":"mcm","clk":"4290088496","pt":1632497297142,"mc":[{"id":"1.188075669","rc":[{"trd":[[1.18,357.03]],"batb":[[0,1.17,731.29],[1,1.16,806.12]],"batl":[[0,1.19,364.79],[1,1.2,678.11],[2,1.25,343.25]],"ltp":1.18,"tv":27064.98,"id":9631939}],"tv":33916.01}]}
{"op":"mcm","clk":"4290088650","pt":1632497298915,"mc":[{"id":"1.188075669","rc":[{"batb":[[1,1.16,723.23]],"ltp":1.18,"tv":27064.98,"id":9631939},{"batb":[[0,5.4,46.3],[1,5.1,86.8],[2,5,113.75]],"batl":[[0,7.8,24.46],[1,8,82.49],[2,8.2,92.51]],"ltp":6.8,"tv":6851.02,"id":9454286}]}]}
{"op":"mcm","clk":"4290088756","pt":1632497300027,"mc":[{"id":"1.188075669","rc":[{"batb":[[0,1.17,780.98]],"ltp":1.18,"tv":27064.98,"id":9631939}]}]}
{"op":"mcm","clk":"4290088913","pt":1632497302078,"mc":[{"id":"1.188075669","rc":[{"batl":[[0,1.19,410.21]],"ltp":1.18,"tv":27064.98,"id":9631939}]}]}
{"op":"mcm","clk":"4290088961","pt":1632497302455,"mc":[{"id":"1.188075669","rc":[{"batb":[[0,1.14,514.27],[1,1.13,1895.97],[2,1.12,106.07]],"batl":[[0,1.25,343.25],[1,1.26,472.29],[2,1.42,30.75]],"ltp":1.18,"tv":27064.98,"id":9631939},{"batb":[[0,5.1,86.8],[1,5,113.75],[2,4.9,113.23]],"batl":[[0,8,82.49],[1,8.2,92.51],[2,9.4,2]],"ltp":6.8,"tv":6851.02,"id":9454286}]}]}
{"op":"mcm","clk":"4290089273","pt":1632497305424,"mc":[{"id":"1.188075669","rc":[{"batb":[[1,1.13,3253.81]],"batl":[[0,1.24,478.56],[1,1.25,862.74],[2,1.26,472.29]],"ltp":1.18,"tv":27064.98,"id":9631939}]}]}
{"op":"mcm","clk":"4290089408","pt":1632497307061,"mc":[{"id":"1.188075669","rc":[{"batb":[[0,1.14,84.35],[1,1.13,1300]],"ltp":1.18,"tv":27064.98,"id":9631939},{"batl":[[0,9.4,2],[1,9.8,77.11],[2,11,2]],"ltp":6.8,"tv":6851.02,"id":9454286}]}]}
{"op":"mcm","clk":"4290089507","pt":1632497308261,"mc":[{"id":"1.188075669","rc":[{"batl":[[1,11,2],[2,990,0.01]],"ltp":6.8,"tv":6851.02,"id":9454286}]}]}
{"op":"mcm","clk":"4290089648","pt":1632497310159,"mc":[{"id":"1.188075669","rc":[{"batb":[[0,1.22,272.38],[1,1.21,682.87],[2,1.18,778.14]],"ltp":1.18,"tv":27064.98,"id":9631939},{"batb":[[0,5.5,156.74],[1,5.1,86.8],[2,5,113.75]],"batl":[[0,5.8,86.21],[1,5.9,40.52],[2,6,42.23]],"ltp":6.8,"tv":6851.02,"id":9454286}]}]}
{"op":"mcm","clk":"4290089698","pt":1632497310745,"mc":[{"id":"1.188075669","rc":[{"batb":[[1,1.21,1434.14]],"ltp":1.18,"tv":27064.98,"id":9631939},{"batb":[[2,5,207.75]],"ltp":6.8,"tv":6851.02,"id":9454286}]}]}
{"op":"mcm","clk":"4290089831","pt":1632497312161,"mc":[{"id":"1.188075669","rc":[{"batb":[[2,1.18,1100.78]],"batl":[[0,1.24,586.72]],"ltp":1.18,"tv":27064.98,"id":9631939},{"batb":[[1,5.3,13.95],[2,5.2,9.9]],"ltp":6.8,"tv":6851.02,"id":9454286}]}]}
{"op":"mcm","clk":"4290089918","pt":1632497313164,"mc":[{"id":"1.188075669","rc":[{"batl":[[0,5.7,2],[1,5.8,86.21],[2,5.9,40.52]],"ltp":6.8,"tv":6851.02,"id":9454286}]}]}
{"op":"mcm","clk":"4290090055","pt":1632497314745,"mc":[{"id":"1.188075669","rc":[{"batb":[[2,1.18,959.36]],"ltp":1.18,"tv":27064.98,"id":9631939},{"batl":[[0,5.7,12.72]],"ltp":6.8,"tv":6851.02,"id":9454286}]}]}
{"op":"mcm","clk":"4290090150","pt":1632497315746,"mc":[{"id":"1.188075669","rc":[{"trd":[[1.22,226]],"batb":[[0,1.22,262.38]],"ltp":1.22,"tv":27084.98,"id":9631939}],"tv":33936.01}]}
{"op":"mcm","clk":"4290090600","pt":1632497321101,"mc":[{"id":"1.188075669","rc":[{"trd":[[5.5,28.72]],"batb":[[0,5.5,142.38]],"ltp":5.5,"tv":6879.74,"id":9454286}],"tv":33964.73}]}
{"op":"mcm","clk":"4290090643","pt":1632497321591,"mc":[{"id":"1.188075669","rc":[{"trd":[[1.23,54.79]],"ltp":1.23,"tv":27085.08,"id":9631939},{"trd":[[5.5,28.74]],"batb":[[0,5.5,142.36]],"ltp":5.5,"tv":6879.76,"id":9454286}],"tv":33964.84}]}
{"op":"mcm","clk":"4290091051","pt":1632497325902,"mc":[{"id":"1.188075669","rc":[{"trd":[[1.22,226.18],[1.23,104.79]],"batb":[[0,1.22,262.29]],"ltp":1.22,"tv":27135.26,"id":9631939},{"trd":[[5.5,39.92]],"batb":[[0,5.5,131.18]],"ltp":5.5,"tv":6890.94,"id":9454286}],"tv":34026.2}]}
{"op":"mcm","clk":"4290091148","pt":1632497326964,"mc":[{"id":"1.188075669","rc":[{"trd":[[1.23,104.81]],"batb":[[0,1.22,211.47]],"ltp":1.23,"tv":27135.28,"id":9631939}],"tv":34026.22}]}
{"op":"mcm","clk":"4290091254","pt":1632497328170,"mc":[{"id":"1.188075669","rc":[{"trd":[[1.23,119.29]],"batb":[[0,1.21,751.27],[1,1.18,181.22],[2,1.17,961.99]],"batl":[[0,1.24,108.16],[1,1.25,343.25]],"ltp":1.23,"tv":27149.76,"id":9631939},{"trd":[[5.5,43.16]],"batb":[[0,5.3,13.95],[1,5.2,9.9],[2,5.1,86.8]],"batl":[[1,6.4,25.81],[2,7.8,92.09]],"ltp":5.5,"tv":6894.18,"id":9454286}],"tv":34043.94}]}
{"op":"mcm","clk":"4290091359","pt":1632497329187,"mc":[{"id":"1.188075669","rc":[{"trd":[[1.24,421.1]],"batb":[[0,1.17,961.99],[1,1.15,83.63],[2,1.14,84.35]],"batl":[[0,1.22,3.9],[1,1.8,16.88],[2,3.8,27.75]],"ltp":1.24,"tv":27151.02,"id":9631939},{"batb":[[0,3.9,163.82],[1,3,386.29],[2,1.01,139.76]],"batl":[[0,7.8,92.09],[1,9.4,2],[2,11,2]],"ltp":5.5,"tv":6894.18,"id":9454286}],"tv":34045.2}]}
{"op":"mcm","clk":"4290091511","pt":1632497331183,"mc":[{"id":"1.188075669","rc":[{"batb":[[0,1.17,1920.1],[1,1.16,494.45],[2,1.15,83.63]],"batl":[[1,1.33,214.71],[2,1.34,362.57]],"ltp":1.24,"tv":27151.02,"id":9631939}]}]}
{"op":"mcm","clk":"4290091594","pt":1632497331877,"mc":[{"id":"1.188075669","rc":[{"batb":[[0,1.17,961.99],[1,1.15,83.63],[2,1.14,84.35]],"batl":[[1,1.36,33.82],[2,1.42,32.75]],"ltp":1.24,"tv":27151.02,"id":9631939},{"batb":[[1,3.75,2],[2,3,386.29]],"ltp":5.5,"tv":6894.18,"id":9454286}]}]}
{"op":"mcm","clk":"4290091662","pt":1632497332399,"mc":[{"id":"1.188075669","rc":[{"batb":[[0,3.9,165.82],[1,3.85,3],[2,3.75,2]],"ltp":5.5,"tv":6894.18,"id":9454286}]}]}
{"op":"mcm","clk":"4290091826","pt":1632497334191,"mc":[{"id":"1.188075669","rc":[{"trd":[[1.22,233.99]],"batb":[[0,1.23,609.99],[1,1.22,639.81],[2,1.17,961.99]],"batl":[[0,1.26,565.84],[1,1.27,472.23],[2,1.36,33.82]],"ltp":1.22,"tv":27158.83,"id":9631939},{"batl":[[0,7.8,2]],"ltp":5.5,"tv":6894.18,"id":9454286}],"tv":34053.01}]}
{"op":"mcm","clk":"4290091867","pt":1632497334610,"mc":[{"id":"1.188075669","rc":[{"batb":[[0,4,3],[1,3.95,3],[2,3.9,165.82]],"ltp":5.5,"tv":6894.18,"id":9454286}]}]}
{"op":"mcm","clk":"4290092018","pt":1632497336185,"mc":[{"id":"1.188075669","rc":[{"batb":[[2,1.19,194.04]],"ltp":1.22,"tv":27158.83,"id":9631939},{"batb":[[0,4.2,59.52],[1,4,3],[2,3.95,3]],"batl":[[0,6.2,35.57],[1,7.8,2],[2,9.4,2]],"ltp":5.5,"tv":6894.18,"id":9454286}]}]}
{"op":"mcm","clk":"4290092107","pt":1632497337086,"mc":[{"id":"1.188075669","rc":[{"batb":[[2,1.17,961.99]],"ltp":1.22,"tv":27158.83,"id":9631939},{"batb":[[0,4,3],[1,3.95,3],[2,3.9,165.82]],"batl":[[0,7.2,94.48]],"ltp":5.5,"tv":6894.18,"id":9454286}]}]}
{"op":"mcm","clk":"4290092133","pt":1632497337390,"mc":[{"id":"1.188075669","rc":[{"batl":[[0,1.26,618.75]],"ltp":1.22,"tv":27158.83,"id":9631939}]}]}
{"op":"mcm","clk":"4290092265","pt":1632497338918,"mc":[{"id":"1.188075669","rc":[{"batb":[[0,1.17,961.99],[1,1.15,83.63],[2,1.14,84.35]],"batl":[[0,1.36,33.82],[1,1.42,32.75],[2,1.44,29.83]],"ltp":1.22,"tv":27158.83,"id":9631939}]}]}
{"op":"mcm","clk":"4290092547","pt":1632497342078,"mc":[{"id":"1.188075669","rc":[{"batb":[[0,1.17,1917.37],[1,1.16,497.21],[2,1.15,83.63]],"batl":[[0,1.32,9],[1,1.33,217.12],[2,1.34,370.58]],"ltp":1.22,"tv":27158.83,"id":9631939}]}]}
{"op":"mcm","clk":"4290092663","pt":1632497343191,"mc":[{"id":"1.188075669","rc":[{"batl":[[0,1.33,217.12],[1,1.34,370.58],[2,1.36,33.82]],"ltp":1.22,"tv":27158.83,"id":9631939},{"batb":[[0,4.2,3],[1,4.1,3],[2,4,3]],"ltp":5.5,"tv":6894.18,"id":9454286}]}]}
{"op":"mcm","clk":"4290092838","pt":1632497345194,"mc":[{"id":"1.188075669","rc":[{"batl":[[0,1.33,9],[1,1.34,8]],"ltp":1.22,"tv":27158.83,"id":9631939}]}]}
{"op":"mcm","clk":"4290092919","pt":1632497346189,"mc":[{"id":"1.188075669","rc":[{"batl":[[0,1.32,10],[1,1.33,19],[2,1.34,8]],"ltp":1.22,"tv":27158.83,"id":9631939}]}]}
{"op":"mcm","clk":"4290092971","pt":1632497346832,"mc":[{"id":"1.188075669","rc":[{"batb":[[2,3.9,163.82]],"batl":[[0,7.8,2],[1,9.4,2],[2,11,2]],"ltp":5.5,"tv":6894.18,"id":9454286}]}]}
{"op":"mcm","clk":"4290093086","pt":1632497348196,"mc":[{"id":"1.188075669","rc":[{"batb":[[0,1.17,1970.37]],"batl":[[0,1.19,357.14],[1,1.2,845.94],[2,1.21,561.51]],"ltp":1.22,"tv":27158.83,"id":9631939},{"batb":[[0,6.4,3.72],[1,6.2,4.32],[2,6,159.38]],"batl":[[0,6.8,4.77],[1,7.6,125.82],[2,7.8,124.12]],"ltp":5.5,"tv":6894.18,"id":9454286}]}]}
{"op":"mcm","clk":"4290093189","pt":1632497349199,"mc":[{"id":"1.188075669","rc":[{"batb":[[2,1.15,238.54]],"batl":[[1,1.2,905.94]],"ltp":1.22,"tv":27158.83,"id":9631939},{"batb":[[2,6,291.92]],"batl":[[1,7,4.29],[2,7.2,1.71]],"ltp":5.5,"tv":6894.18,"id":9454286}]}]}
{"op":"mcm","clk":"4290093235","pt":1632497349607,"mc":[{"id":"1.188075669","rc":[{"batb":[[0,1.17,2033.62]],"ltp":1.22,"tv":27158.83,"id":9631939}]}]}
{"op":"mcm","clk":"4290093556","pt":1632497352810,"mc":[{"id":"1.188075669","rc":[{"batb":[[2,6,279.92]],"batl":[[0,6.8,18.02]],"ltp":5.5,"tv":6894.18,"id":9454286}]}]}
{"op":"mcm","clk":"4290093836","pt":1632497356005,"mc":[{"id":"1.188075669","rc":[{"batb":[[1,6.2,15.85]],"ltp":5.5,"tv":6894.18,"id":9454286}]}]}
{"op":"mcm","clk":"4290093887","pt":1632497356683,"mc":[{"id":"1.188075669","rc":[{"trd":[[1.19,41.04]],"batl":[[0,1.19,353]],"ltp":1.19,"tv":27167.11,"id":9631939},{"trd":[[6.4,2.64]],"batb":[[0,6.4,3.27]],"ltp":6.4,"tv":6895.08,"id":9454286}],"tv":34062.19}]}
{"op":"mcm","clk":"4290094091","pt":1632497358891,"mc":[{"id":"1.188075669","rc":[{"trd":[[1.19,41.12]],"batl":[[0,1.19,352.96]],"ltp":1.19,"tv":27167.18,"id":9631939},{"batl":[[2,7.4,23.71]],"ltp":6.4,"tv":6895.08,"id":9454286}],"tv":34062.27}]}
{"op":"mcm","clk":"4290094134","pt":1632497359414,"mc":[{"id":"1.188075669","rc":[{"batl":[[0,1.19,68.5]],"ltp":1.19,"tv":27167.18,"id":9631939}]}]}
{"op":"mcm","clk":"4290094226","pt":1632497360627,"mc":[{"id":"1.188075669","rc":[{"trd":[[1.17,27.94],[1.19,41.3]],"batb":[[0,1.17,2033.42]],"batl":[[0,1.19,68.41]],"ltp":1.17,"tv":27167.76,"id":9631939}],"tv":34062.84}]}
{"op":"mcm","clk":"4290094410","pt":1632497362835,"mc":[{"id":"1.188075669","rc":[{"trd":[[1.19,42.56]],"batl":[[0,1.19,67.78]],"ltp":1.19,"tv":27169.02,"id":9631939}],"tv":34064.1}]}
{"op":"mcm","clk":"4290094557","pt":1632497364619,"mc":[{"id":"1.188075669","rc":[{"trd":[[1.19,47.26]],"batb":[[0,1.17,1980.42]],"batl":[[0,1.19,65.43]],"ltp":1.19,"tv":27173.71,"id":9631939}],"tv":34068.8}]}
{"op":"mcm","clk":"4290094747","pt":1632497366975,"mc":[{"id":"1.188075669","rc":[{"trd":[[1.17,100.03]],"batb":[[0,1.17,1944.39]],"ltp":1.17,"tv":27245.8,"id":9631939},{"batb":[[0,6.2,15.85],[1,6,279.92],[2,5.9,154.7]],"batl":[[0,6.8,13.25]],"ltp":6.4,"tv":6895.08,"id":9454286}],"tv":34140.89}]}
{"op":"mcm","clk":"4290095031","pt":1632497370118,"mc":[{"id":"1.188075669","rc":[{"batb":[[0,1.15,154.91],[1,1.14,1309.19],[2,1.12,106.07]],"batl":[[0,1.2,60],[1,1.23,2.35],[2,1.26,42.25]],"ltp":1.17,"tv":27245.8,"id":9631939},{"batb":[[0,6.2,11.53],[1,4.8,2],[2,4.6,110.93]],"batl":[[0,7.4,23.71],[1,9.4,2],[2,9.8,77.11]],"ltp":6.4,"tv":6895.08,"id":9454286}]}]}
{"op":"mcm","clk":"4290095132","pt":1632497371326,"mc":[{"id":"1.188075669","rc":[{"batb":[[0,1.14,1309.19],[1,1.12,106.07],[2,1.11,108.59]],"batl":[[0,1.23,2.35],[1,1.26,42.25],[2,1.28,43.34]],"ltp":1.17,"tv":27245.8,"id":9631939},{"batb":[[0,4.8,2],[1,4.6,110.93],[2,4.4,2]],"batl":[[0,9.4,2],[1,9.8,77.11],[2,11,2]],"ltp":6.4,"tv":6895.08,"id":9454286}]}]}
{"op":"mcm","clk":"4290095276","pt":1632497373143,"mc":[{"id":"1.188075669","rc":[{"batb":[[0,1.14,847.2],[1,1.13,1957.9],[2,1.12,106.07]],"batl":[[2,1.27,330.31]],"ltp":1.17,"tv":27245.8,"id":9631939},{"batb":[[1,4.6,110.51]],"ltp":6.4,"tv":6895.08,"id":9454286}]}]}
{"op":"mcm","clk":"4290095301","pt":1632497373414,"mc":[{"id":"1.188075669","rc":[{"batl":[[2,1.28,43.34]],"ltp":1.17,"tv":27245.8,"id":9631939}]}]}
{"op":"mcm","clk":"4290095400","pt":1632497374529,"mc":[{"id":"1.188075669","rc":[{"batb":[[0,4.8,5],[1,4.7,3],[2,4.6,110.51]],"ltp":6.4,"tv":6895.08,"id":9454286}]}]}
{"op":"mcm","clk":"4290095539","pt":1632497376210,"mc":[{"id":"1.188075669","rc":[{"trd":[[1.19,47.32]],"batb":[[0,1.14,847.18]],"batl":[[0,1.16,4961.37],[1,1.23,2.35],[2,1.26,42.25]],"ltp":1.19,"tv":27245.86,"id":9631939},{"batb":[[0,7,546.42],[1,6.8,530.36],[2,6.6,530.36]],"batl":[[0,9.2,206.25],[1,9.4,208.25]],"ltp":6.4,"tv":6895.08,"id":9454286}],"tv":34140.95}]}
{"op":"mcm","clk":"4290095613","pt":1632497377160,"mc":[{"id":"1.188075669","rc":[{"batb":[[0,1.14,877.12],[1,1.13,2012.77],[2,1.12,839.38]],"batl":[[0,1.15,17.47],[1,1.16,1130.69],[2,1.17,783.36]],"ltp":1.19,"tv":27245.86,"id":9631939},{"batb":[[0,7.2,3.52],[1,7,218.09],[2,6.8,132.6]],"batl":[[0,8.6,1.71],[1,9,106.24],[2,9.2,103.12]],"ltp":6.4,"tv":6895.08,"id":9454286}]}]}
{"op":"mcm","clk":"4290095727","pt":1632497378215,"mc":[{"id":"1.188075669","rc":[{"batb":[[2,1.12,1012.58]],"batl":[[2,1.17,843.36]],"ltp":1.19,"tv":27245.86,"id":9631939},{"batb":[[1,7,228.09]],"batl":[[0,8.2,3.66],[1,8.6,1.71],[2,9,127.45]],"ltp":6.4,"tv":6895.08,"id":9454286}]}]}
{"op":"mcm","clk":"4290095797","pt":1632497378743,"mc":[{"id":"1.188075669","rc":[{"batb":[[0,1.14,928.66],[1,1.13,2015.77]],"ltp":1.19,"tv":27245.86,"id":9631939}]}]}
{"op":"mcm","clk":"4290096121","pt":1632497382121,"mc":[{"id":"1.188075669","rc":[{"batl":[[2,1.17,783.36]],"ltp":1.19,"tv":27245.86,"id":9631939},{"batb":[[0,7.4,7.25],[1,7.2,3.52],[2,7,218.09]],"batl":[[0,8.2,13.66]],"ltp":6.4,"tv":6895.08,"id":9454286}]}]}
{"op":"mcm","clk":"4290096272","pt":1632497383555,"mc":[{"id":"1.188075669","rc":[{"batb":[[2,1.12,1650.52]],"ltp":1.19,"tv":27245.86,"id":9631939}]}]}
{"op":"mcm","clk":"4290096365","pt":1632497384661,"mc":[{"id":"1.188075669","rc":[{"trd":[[1.15,15.67]],"batl":[[0,1.15,17.34],[1,1.16,1190.69]],"ltp":1.15,"tv":27246.12,"id":9631939},{"batb":[[1,7.2,13.19]],"ltp":6.4,"tv":6895.08,"id":9454286}],"tv":34141.21}]}
{"op":"mcm","clk":"4290096534","pt":1632497386613,"mc":[{"id":"1.188075669","rc":[{"trd":[[1.15,15.87]],"batl":[[0,1.15,17.24]],"ltp":1.15,"tv":27246.32,"id":9631939}],"tv":34141.41}]}
{"op":"mcm","clk":"4290096585","pt":1632497387249,"mc":[{"id":"1.188075669","rc":[{"batl":[[1,9,127.45],[2,9.2,179.05]],"ltp":6.4,"tv":6895.08,"id":9454286}]}]}
{"op":"mcm","clk":"4290096701","pt":1632497388671,"mc":[{"id":"1.188075669","rc":[{"batl":[[1,1.16,796.93]],"ltp":1.15,"tv":27246.32,"id":9631939},{"batb":[[0,7.2,13.19],[1,7,218.09],[2,6.8,132.6]],"ltp":6.4,"tv":6895.08,"id":9454286}]}]}
{"op":"mcm","clk":"4290096850","pt":1632497390159,"mc":[{"id":"1.188075669","rc":[{"batb":[[1,7,81.49],[2,6.2,2]],"batl":[[0,8.2,10],[1,9,21.21],[2,9.2,75.93]],"ltp":6.4,"tv":6895.08,"id":9454286}]}]}
{"op":"mcm","clk":"4290096912","pt":1632497390840,"mc":[{"id":"1.188075669","rc":[{"batb":[[0,1.15,9.38],[1,1.14,84.35],[2,1.12,813.67]],"batl":[[0,1.16,60],[1,1.19,58.5],[2,1.2,57.08]],"ltp":1.15,"tv":27246.32,"id":9631939},{"batb":[[0,7.2,9.67],[1,6.2,2],[2,5.7,2]],"batl":[[0,9,21.21],[1,9.2,75.93],[2,9.4,85.02]],"ltp":6.4,"tv":6895.08,"id":9454286}]}]}
{"op":"mcm","clk":"4290097114","pt":1632497393222,"mc":[{"id":"1.188075669","rc":[{"batb":[[2,1.12,1147.74]],"batl":[[0,1.21,485.49],[1,1.22,1066.39],[2,1.23,390.16]],"ltp":1.15,"tv":27246.32,"id":9631939},{"batb":[[0,5.7,2],[1,5.6,143.45],[2,5.5,110.15]],"batl":[[0,9.2,75.93],[1,9.4,85.02],[2,11,2]],"ltp":6.4,"tv":6895.08,"id":9454286}]}]}
{"op":"mcm","clk":"4290097228","pt":1632497394747,"mc":[{"id":"1.188075669","rc":[{"batb":[[0,1.15,59.38]],"ltp":1.15,"tv":27246.32,"id":9631939}]}]}
{"op":"mcm","clk":"4290097353","pt":1632497396169,"mc":[{"id":"1.188075669","rc":[{"batl":[[0,1.21,495.49]],"ltp":1.15,"tv":27246.32,"id":9631939},{"batb":[[0,5.7,5],[1,5.6,146.45]],"ltp":6.4,"tv":6895.08,"id":9454286}]}]}
{"op":"mcm","clk":"4290097427","pt":1632497397029,"mc":[{"id":"1.188075669","rc":[{"batb":[[0,1.15,9.38]],"batl":[[0,1.2,40],[1,1.21,495.49],[2,1.22,1066.39]],"ltp":1.15,"tv":27246.32,"id":9631939}]}]}
{"op":"mcm","clk":"4290097477","pt":1632497397664,"mc":[{"id":"1.188075669","rc":[{"batl":[[0,1.19,40],[1,1.2,40],[2,1.21,495.49]],"ltp":1.15,"tv":27246.32,"id":9631939}]}]}
{"op":"mcm","clk":"4290097733","pt":1632497400753,"mc":[{"id":"1.188075669","rc":[{"trd":[[1.15,34.64]],"batb":[[0,1.14,84.35],[1,1.12,1147.74],[2,1.11,3280.89]],"batl":[[0,1.19,40.61]],"ltp":1.15,"tv":27265.09,"id":9631939}],"tv":34160.18}]}
{"op":"mcm","clk":"4290097878","pt":1632497402152,"mc":[{"id":"1.188075669","rc":[{"batl":[[0,1.19,40]],"ltp":1.15,"tv":27265.09,"id":9631939}]}]}
{"op":"mcm","clk":"4290098405","pt":1632497407857,"mc":[{"id":"1.188075669","rc":[{"batl":[[2,1.21,70.5]],"ltp":1.15,"tv":27265.09,"id":9631939},{"batb":[[1,5.6,69.85],[2,3,386.29]],"ltp":6.4,"tv":6895.08,"id":9454286}]}]}
{"op":"mcm","clk":"4290098479","pt":1632497408491,"mc":[{"id":"1.188075669","rc":[{"batb":[[0,1.12,1147.74],[1,1.11,3280.89],[2,1.1,126.74]],"ltp":1.15,"tv":27265.09,"id":9631939}]}]}
{"op":"mcm","clk":"4290098649","pt":1632497410182,"mc":[{"id":"1.188075669","rc":[{"batb":[[2,1.01,139.76]],"ltp":6.4,"tv":6895.08,"id":9454286}]}]}
{"op":"mcm","clk":"4290098735","pt":1632497411079,"mc":[{"id":"1.188075669","rc":[{"batb":[[0,1.12,1171],[1,1.11,3336.76],[2,1.1,635.75]],"batl":[[0,1.13,1358.98],[1,1.14,1715.23],[2,1.15,284]],"ltp":1.15,"tv":27265.09,"id":9631939},{"batb":[[0,8.6,2.94],[1,7.8,122.6],[2,7.6,119]],"batl":[[0,9.4,85.02],[1,10.5,91.08],[2,11,141.28]],"ltp":6.4,"tv":6895.08,"id":9454286}]}]}
{"op":"mcm","clk":"4290098847","pt":1632497412192,"mc":[{"id":"1.188075669","rc":[{"batb":[[2,1.1,2372.12]],"batl":[[2,1.15,344]],"ltp":1.15,"tv":27265.09,"id":9631939},{"batb":[[1,8.4,57.02],[2,8,8.57]],"batl":[[1,9.6,3.12],[2,10.5,91.08]],"ltp":6.4,"tv":6895.08,"id":9454286}]}]}
{"op":"mcm","clk":"4290099015","pt":1632497414197,"mc":[{"id":"1.188075669","rc":[{"batb":[[2,8,10.57]],"batl":[[0,9.4,90.71]],"ltp":6.4,"tv":6895.08,"id":9454286}]}]}
{"op":"mcm","clk":"4290099096","pt":1632497415209,"mc":[{"id":"1.188075669","rc":[{"batb":[[2,8,2]],"ltp":6.4,"tv":6895.08,"id":9454286}]}]}
{"op":"mcm","clk":"4290099153","pt":1632497415791,"mc":[{"id":"1.188075669","rc":[{"trd":[[1.13,54.7]],"batl":[[0,1.13,1331.61],[2,1.15,284]],"ltp":1.13,"tv":27319.79,"id":9631939}],"tv":34214.88}]}
{"op":"mcm","clk":"4290099265","pt":1632497417115,"mc":[{"id":"1.188075669","rc":[{"trd":[[1.12,4]],"batb":[[0,1.12,1169]],"batl":[[1,1.14,1796.48],[2,1.15,367.9]],"ltp":1.12,"tv":27323.79,"id":9631939},{"batb":[[2,8,4]],"ltp":6.4,"tv":6895.08,"id":9454286}],"tv":34218.88}]}
{"op":"mcm","clk":"4290099372","pt":1632497418200,"mc":[{"id":"1.188075669","rc":[{"batb":[[1,1.11,3796.7],[2,1.1,3096.53]],"ltp":1.12,"tv":27323.79,"id":9631939},{"batl":[[2,9.8,51.71]],"ltp":6.4,"tv":6895.08,"id":9454286}]}]}
{"op":"mcm","clk":"4290099463","pt":1632497419119,"mc":[{"id":"1.188075669","rc":[{"trd":[[1.13,54.9]],"batb":[[1,1.11,3883.33]],"batl":[[0,1.13,1331.51],[1,1.14,1856.48]],"ltp":1.13,"tv":27323.99,"id":9631939},{"batb":[[1,8.4,65.12]],"ltp":6.4,"tv":6895.08,"id":9454286}],"tv":34219.08}]}
{"op":"mcm","clk":"4290099594","pt":1632497420805,"mc":[{"id":"1.188075669","rc":[{"batb":[[1,1.11,3796.7]],"ltp":1.13,"tv":27323.99,"id":9631939}]}]}
{"op":"mcm","clk":"4290099709","pt":1632497422080,"mc":[{"id":"1.188075669","rc":[{"trd":[[1.13,66.04]],"batl":[[0,1.13,1325.94]],"ltp":1.13,"tv":27335.13,"id":9631939}],"tv":34230.21}]}
{"op":"mcm","clk":"4290099770","pt":1632497422723,"mc":[{"id":"1.188075669","rc":[{"trd":[[1.13,173.07]],"batl":[[0,1.13,1272.42],[1,1.14,1341.21]],"ltp":1.13,"tv":27442.16,"id":9631939}],"tv":34337.25}]}
{"op":"mcm","clk":"4290100084","pt":1632497426028,"mc":[{"id":"1.188075669","rc":[{"batb":[[0,1.12,1145.74]],"ltp":1.13,"tv":27442.16,"id":9631939}]}]}
{"op":"mcm","clk":"4290100262","pt":1632497427925,"mc":[{"id":"1.188075669","rc":[{"batb":[[1,1.11,3740.83]],"ltp":1.13,"tv":27442.16,"id":9631939}]}]}
{"op":"mcm","clk":"4290100653","pt":1632497432202,"mc":[{"id":"1.188075669","rc":[{"trd":[[1.12,15.57]],"batb":[[0,1.12,1139.96]],"batl":[[1,1.14,1388.72]],"ltp":1.12,"tv":27453.73,"id":9631939},{"batl":[[0,9.2,5.35],[1,9.4,90.71],[2,9.6,3.12]],"ltp":6.4,"tv":6895.08,"id":9454286}],"tv":34348.82}]}
{"op":"mcm","clk":"4290100661","pt":1632497432302,"mc":[{"id":"1.188075669","rc":[{"batl":[[1,1.14,1341.21]],"ltp":1.12,"tv":27453.73,"id":9631939},{"batl":[[0,9.4,90.71],[1,9.6,3.12],[2,9.8,51.71]],"ltp":6.4,"tv":6895.08,"id":9454286}]}]}
{"op":"mcm","clk":"4290100949","pt":1632497435096,"mc":[{"id":"1.188075669","rc":[{"batb":[[0,1.11,2277.99],[1,1.1,2587.52],[2,1.09,122.61]],"batl":[[0,1.13,68.5],[1,1.14,141.25],[2,1.15,83.9]],"ltp":1.12,"tv":27453.73,"id":9631939},{"batl":[[0,9.8,51.71],[1,10,72.01],[2,11,2]],"ltp":6.4,"tv":6895.08,"id":9454286}]}]}
{"op":"mcm","clk":"4290100992","pt":1632497435517,"mc":[{"id":"1.188075669","rc":[{"batb":[[0,1.11,752.93],[1,1.1,2460.78]],"batl":[[0,1.14,141.25],[1,1.15,83.9],[2,1.17,538.05]],"ltp":1.12,"tv":27453.73,"id":9631939},{"batb":[[0,8.4,8.1],[1,8,2],[2,7.6,2]],"batl":[[2,12.5,2]],"ltp":6.4,"tv":6895.08,"id":9454286}]}]}
{"op":"mcm","clk":"4290101113","pt":1632497436932,"mc":[{"id":"1.188075669","rc":[{"batl":[[0,1.15,83.9],[1,1.17,538.05],[2,1.18,519.26]],"ltp":1.12,"tv":27453.73,"id":9631939},{"batb":[[0,7.6,2],[1,7,151.57],[2,6.8,108.45]],"ltp":6.4,"tv":6895.08,"id":9454286}]}]}
{"op":"mcm","clk":"4290101211","pt":1632497438035,"mc":[{"id":"1.188075669","rc":[{"batb":[[0,1.11,753.09],[1,1.1,3705.62]],"batl":[[1,1.16,625.64],[2,1.17,1343.65]],"ltp":1.12,"tv":27453.73,"id":9631939}]}]}
{"op":"mcm","clk":"4290101291","pt":1632497438727,"mc":[{"id":"1.188075669","rc":[{"batl":[[1,1.18,12],[2,1.8,17.51]],"ltp":1.12,"tv":27453.73,"id":9631939},{"batb":[[1,7,83.85],[2,3.35,376.68]],"ltp":6.4,"tv":6895.08,"id":9454286}]}]}
{"op":"mcm","clk":"4290101420","pt":1632497440111,"mc":[{"id":"1.188075669","rc":[{"batl":[[0,1.14,80.25],[1,1.15,83.9],[2,1.18,12]],"ltp":1.12,"tv":27453.73,"id":9631939},{"batb":[[0,8,2],[1,7.6,2],[2,7,83.85]],"ltp":6.4,"tv":6895.08,"id":9454286}]}]}
{"op":"mcm","clk":"4290101447","pt":1632497440428,"mc":[{"id":"1.188075669","rc":[{"batl":[[0,1.15,83.9],[1,1.18,12],[2,1.8,17.51]],"ltp":1.12,"tv":27453.73,"id":9631939},{"batb":[[0,7.6,2],[1,7,83.85],[2,3.35,376.68]],"ltp":6.4,"tv":6895.08,"id":9454286}]}]}
{"op":"mcm","clk":"4290101613","pt":1632497442108,"mc":[{"id":"1.188075669","rc":[{"batb":[[0,1.11,293.15],[1,1.1,3761.99]],"batl":[[0,1.12,2547.28],[1,1.13,1076.83],[2,1.15,83.9]],"ltp":1.12,"tv":27453.73,"id":9631939},{"batb":[[0,9.2,2.62],[1,9,52.22],[2,8.8,26.12]],"batl":[[0,10,5.94],[1,12,125.29]],"ltp":6.4,"tv":6895.08,"id":9454286}]}]}
{"op":"mcm","clk":"4290101705","pt":1632497443017,"mc":[{"id":"1.188075669","rc":[{"batb":[[1,1.1,4189.27],[2,1.09,336.25]],"batl":[[2,1.14,205.04]],"ltp":1.12,"tv":27453.73,"id":9631939},{"batb":[[1,9,99.71]],"batl":[[1,10.5,2.86],[2,12,125.29]],"ltp":6.4,"tv":6895.08,"id":9454286}]}]}
{"op":"mcm","clk":"4290101750","pt":1632497443645,"mc":[{"id":"1.188075669","rc":[{"batl":[[1,1.13,1095.83],[2,1.14,13]],"ltp":1.12,"tv":27453.73,"id":9631939}]}]}
{"op":"mcm","clk":"4290102006","pt":1632497446720,"mc":[{"id":"1.188075669","rc":[{"batb":[[1,1.1,4379]],"batl":[[0,1.12,2601.93],[1,1.13,1155.83]],"ltp":1.12,"tv":27453.73,"id":9631939},{"batb":[[0,9.4,10],[1,9.2,2.62],[2,9,99.71]],"batl":[[2,11,18.97]],"ltp":6.4,"tv":6895.08,"id":9454286}]}]}
{"op":"mcm","clk":"4290102133","pt":1632497448134,"mc":[{"id":"1.188075669","rc":[{"trd":[[1.11,0.32]],"batb":[[0,1.11,292.83]],"batl":[[2,1.14,105.25]],"ltp":1.11,"tv":27454.05,"id":9631939}],"tv":34349.13}]}
{"op":"mcm","clk":"4290102196","pt":1632497448773,"mc":[{"id":"1.188075669","rc":[{"batb":[[0,9.2,2.62],[1,9,99.71],[2,8.8,26.12]],"ltp":6.4,"tv":6895.08,"id":9454286}]}]}
{"op":"mcm","clk":"4290102426","pt":1632497451431,"mc":[{"id":"1.188075669","rc":[{"trd":[[1.12,20.26]],"batl":[[0,1.12,2599.58]],"ltp":1.12,"tv":27458.74,"id":9631939},{"batb":[[0,9.2,12.62]],"ltp":6.4,"tv":6895.08,"id":9454286}],"tv":34353.83}]}
{"op":"mcm","clk":"4290102647","pt":1632497453960,"mc":[{"id":"1.188075669","rc":[{"trd":[[1.12,117.14]],"batl":[[0,1.12,1734.78]],"ltp":1.12,"tv":27555.62,"id":9631939},{"trd":[[9.2,37.06]],"batb":[[0,9,99.71],[1,8.8,26.12],[2,8.6,132.08]],"ltp":9.2,"tv":6932.14,"id":9454286}],"tv":34487.77}]}
{"op":"mcm","clk":"4290102807","pt":1632497455655,"mc":[{"id":"1.188075669","rc":[{"trd":[[1.12,117.46]],"batl":[[0,1.12,1734.62],[2,1.14,92.25]],"ltp":1.12,"tv":27555.94,"id":9631939}],"tv":34488.09}]}
{"op":"mcm","clk":"4290102885","pt":1632497456650,"mc":[{"id":"1.188075669","rc":[{"trd":[[1.12,124.86]],"batl":[[0,1.12,1730.92]],"ltp":1.12,"tv":27563.34,"id":9631939}],"tv":34495.49}]}
{"op":"mcm","clk":"4290103032","pt":1632497457864,"mc":[{"id":"1.188075669","rc":[{"batb":[[0,9.2,6.62],[1,9,99.71],[2,8.8,26.12]],"ltp":9.2,"tv":6932.14,"id":9454286}]}]}
{"op":"mcm","clk":"4290103163","pt":1632497458962,"mc":[{"id":"1.188075669","rc":[{"trd":[[1.12,124.9]],"batl":[[0,1.12,1730.9]],"ltp":1.12,"tv":27563.38,"id":9631939}],"tv":34495.52}]}
{"op":"mcm","clk":"4290103243","pt":1632497459745,"mc":[{"id":"1.188075669","rc":[{"trd":[[1.12,141.02]],"batl":[[0,1.12,1722.84]],"ltp":1.12,"tv":27579.5,"id":9631939}],"tv":34511.65}]}
{"op":"mcm","clk":"4290103404","pt":1632497461375,"mc":[{"id":"1.188075669","rc":[{"trd":[[1.11,8.59]],"batb":[[0,1.11,288.69]],"ltp":1.11,"tv":27587.78,"id":9631939}],"tv":34519.93}]}
{"op":"mcm","clk":"4290103554","pt":1632497462967,"mc":[{"id":"1.188075669","rc":[{"trd":[[1.12,150.04]],"batl":[[0,1.12,1718.33]],"ltp":1.12,"tv":27596.8,"id":9631939}],"tv":34528.95}]}
{"op":"mcm","clk":"4290103837","pt":1632497465993,"mc":[{"id":"1.188075669","rc":[{"trd":[[1.12,388.4]],"batl":[[0,1.12,1599.15]],"ltp":1.12,"tv":27835.16,"id":9631939}],"tv":34767.31}]}
{"op":"mcm","clk":"4290104022","pt":1632497468174,"mc":[{"id":"1.188075669","rc":[{"batb":[[0,1.1,2650.51],[1,1.09,122.61],[2,1.08,834.76]],"batl":[[0,1.12,64.71],[1,1.13,79]],"ltp":1.12,"tv":27835.16,"id":9631939},{"batb":[[1,9,47.49],[2,8.6,7.89]],"batl":[[0,11,18.97],[1,12.5,64.07],[2,13,65.83]],"ltp":9.2,"tv":6932.14,"id":9454286}]}]}
{"op":"mcm","clk":"4290104079","pt":1632497468692,"mc":[{"id":"1.188075669","rc":[{"batb":[[0,1.1,189.73],[1,1.08,834.76],[2,1.07,3383.44]],"batl":[[0,1.13,60],[1,1.14,92.25],[2,1.15,83.9]],"ltp":1.12,"tv":27835.16,"id":9631939},{"batb":[[0,8.6,7.89],[1,8,63.58],[2,7.6,2]],"batl":[[1,12.5,62.07]],"ltp":9.2,"tv":6932.14,"id":9454286}]}]}
{"op":"mcm","clk":"4290104178","pt":1632497469584,"mc":[{"id":"1.188075669","rc":[{"batb":[[0,1.08,834.76],[1,1.07,3383.44],[2,1.06,184.08]],"batl":[[0,1.15,83.9],[1,1.16,379.92],[2,1.17,455.58]],"ltp":1.12,"tv":27835.16,"id":9631939},{"batb":[[0,8,61.58],[1,7.6,2],[2,7.4,87.66]],"batl":[[0,12.5,62.07],[1,13,65.83],[2,13.5,2]],"ltp":9.2,"tv":6932.14,"id":9454286}]}]}
{"op":"mcm","clk":"4290104301","pt":1632497471004,"mc":[{"id":"1.188075669","rc":[{"batb":[[0,1.08,2390.98]],"batl":[[0,1.14,488.68],[1,1.15,1018.45],[2,1.16,379.92]],"ltp":1.12,"tv":27835.16,"id":9631939}]}]}
{"op":"mcm","clk":"4290104467","pt":1632497472892,"mc":[{"id":"1.188075669","rc":[{"batb":[[0,1.08,2415.98],[1,1.07,3419.44]],"batl":[[0,1.14,567.43],[1,1.15,1035.45]],"ltp":1.12,"tv":27835.16,"id":9631939},{"batb":[[0,8,63.58]],"ltp":9.2,"tv":6932.14,"id":9454286}]}]}
{"op":"mcm","clk":"4290104680","pt":1632497475495,"mc":[{"id":"1.188075669","rc":[{"batb":[[0,1.12,3.52],[1,1.08,2415.98],[2,1.07,3419.44]],"ltp":1.12,"tv":27835.16,"id":9631939}]}]}
{"op":"mcm","clk":"4290104761","pt":1632497476500,"mc":[{"id":"1.188075669","rc":[{"batl":[[0,1.15,17],[1,1.8,17.51],[2,3.8,27.75]],"ltp":1.12,"tv":27835.16,"id":9631939},{"batb":[[0,8,61.58],[2,3.35,376.68]],"ltp":9.2,"tv":6932.14,"id":9454286}]}]}
{"op":"mcm","clk":"4290105026","pt":1632497479188,"mc":[{"id":"1.188075669","rc":[{"trd":[[1.12,395.44]],"batb":[[0,1.08,2415.98],[1,1.07,3477.39],[2,1.06,184.08]],"batl":[[0,1.1,11103.62],[1,1.11,2308.4],[2,1.13,26.55]],"ltp":1.12,"tv":27842.2,"id":9631939},{"batb":[[0,11,75.95],[1,10.5,44.76],[2,10,22.38]],"batl":[[0,13,65.83],[1,13.5,2],[2,15,110.26]],"ltp":9.2,"tv":6932.14,"id":9454286}],"tv":34774.34}]}
{"op":"mcm","clk":"4290105150","pt":1632497480195,"mc":[{"id":"1.188075669","rc":[{"batb":[[0,1.08,3063.29],[1,1.07,3694.99],[2,1.06,836.86]],"batl":[[0,1.1,2852.41],[1,1.11,746.02],[2,1.12,60]],"ltp":1.12,"tv":27842.2,"id":9631939},{"batb":[[0,11,151.2]],"batl":[[0,13,68.14],[1,13.5,18.97]],"ltp":9.2,"tv":6932.14,"id":9454286}]}]}
{"op":"mcm","clk":"4290105241","pt":1632497481207,"mc":[{"id":"1.188075669","rc":[{"batb":[[2,1.06,401.68]],"batl":[[2,1.12,64]],"ltp":1.12,"tv":27842.2,"id":9631939}]}]}
{"op":"mcm","clk":"4290105535","pt":1632497484224,"mc":[{"id":"1.188075669","rc":[{"batl":[[2,1.12,4]],"ltp":1.12,"tv":27842.2,"id":9631939},{"trd":[[11,5.22]],"batb":[[0,11,148.59]],"ltp":11.0,"tv":6937.36,"id":9454286}],"tv":34779.56}]}
{"op":"mcm","clk":"4290105597","pt":1632497485116,"mc":[{"id":"1.188075669","rc":[{"batb":[[1,1.07,3658.99]],"batl":[[0,1.1,2949.5]],"ltp":1.12,"tv":27842.2,"id":9631939},{"batb":[[0,11.5,4.71],[1,11,148.59],[2,10.5,44.76]],"ltp":11.0,"tv":6937.36,"id":9454286}]}]}
{"op":"mcm","clk":"4290105684","pt":1632497486431,"mc":[{"id":"1.188075669","rc":[{"batl":[[2,1.12,107.96]],"ltp":1.12,"tv":27842.2,"id":9631939}]}]}
{"op":"mcm","clk":"4290105780","pt":1632497487695,"mc":[{"id":"1.188075669","rc":[{"batl":[[1,1.11,806.02]],"ltp":1.12,"tv":27842.2,"id":9631939}]}]}
{"op":"mcm","clk":"4290106013","pt":1632497490224,"mc":[{"id":"1.188075669","rc":[{"trd":[[1.1,4.7]],"batl":[[0,1.1,2947.15]],"ltp":1.1,"tv":27846.89,"id":9631939}],"tv":34784.26}]}
{"op":"mcm","clk":"4290106078","pt":1632497491017,"mc":[{"id":"1.188075669","rc":[{"batl":[[0,1.1,2237.89]],"ltp":1.1,"tv":27846.89,"id":9631939}]}]}
{"op":"mcm","clk":"4290106158","pt":1632497492025,"mc":[{"id":"1.188075669","rc":[{"batb":[[0,1.08,212.13],[1,1.07,2324.41],[2,1.05,3602.21]],"batl":[[0,1.09,10],[1,1.11,60],[2,1.12,103.96]],"ltp":1.1,"tv":27846.89,"id":9631939},{"batb":[[0,11,75.25],[1,10,6.66],[2,9.2,47.47]],"batl":[[0,13.5,16.97],[1,21,56.67],[2,36,2]],"ltp":11.0,"tv":6937.36,"id":9454286}]}]}
{"op":"mcm","clk":"4290106243","pt":1632497493134,"mc":[{"id":"1.188075669","rc":[{"batb":[[1,1.05,3602.21],[2,1.04,293.62]],"batl":[[0,1.09,116.93]],"ltp":1.1,"tv":27846.89,"id":9631939},{"batb":[[0,10,6.66],[1,9.2,47.47],[2,8.6,2]],"ltp":11.0,"tv":6937.36,"id":9454286}]}]}
{"op":"mcm","clk":"4290106273","pt":1632497493409,"mc":[{"id":"1.188075669","rc":[{"batb":[[0,1.05,3602.21],[1,1.04,293.62],[2,1.03,436.83]],"batl":[[1,1.12,103.96],[2,1.13,93.5]],"ltp":1.1,"tv":27846.89,"id":9631939},{"batb":[[0,9.2,47.47],[1,8.6,2],[2,8.2,2]],"batl":[[0,21,56.67],[1,36,2],[2,990,0.01]],"ltp":11.0,"tv":6937.36,"id":9454286}]}]}
{"op":"mcm","clk":"4290106431","pt":1632497495317,"mc":[{"id":"1.188075669","rc":[{"trd":[[1.09,19.99]],"batl":[[0,1.09,31.83]],"ltp":1.09,"tv":27866.88,"id":9631939}],"tv":34804.25}]}
{"op":"mcm","clk":"4290106553","pt":1632497496947,"mc":[{"id":"1.188075669","rc":[{"batb":[[0,1.05,3643.21],[1,1.04,348.62]],"batl":[[1,1.11,30],[2,1.12,103.96]],"ltp":1.09,"tv":27866.88,"id":9631939},{"batl":[[0,21,58.67]],"ltp":11.0,"tv":6937.36,"id":9454286}]}]}
{"op":"mcm","clk":"4290106665","pt":1632497498215,"mc":[{"id":"1.188075669","rc":[{"batb":[[0,1.08,535.59],[1,1.07,1043.1],[2,1.06,30]],"batl":[[0,1.09,755.66],[1,1.1,823.26],[2,1.11,30]],"ltp":1.09,"tv":27866.88,"id":9631939},{"batl":[[0,18,2],[1,21,58.67],[2,36,2]],"ltp":11.0,"tv":6937.36,"id":9454286}]}]}
{"op":"mcm","clk":"4290106722","pt":1632497498848,"mc":[{"id":"1.188075669","rc":[{"batl":[[2,1.11,50]],"ltp":1.09,"tv":27866.88,"id":9631939}]}]}
{"op":"mcm","clk":"4290106839","pt":1632497500127,"mc":[{"id":"1.188075669","rc":[{"batb":[[0,1.06,30],[1,1.05,3643.21],[2,1.04,348.62]],"batl":[[0,1.09,31.83],[1,1.11,50],[2,1.12,103.96]],"ltp":1.09,"tv":27866.88,"id":9631939}]}]}
{"op":"mcm","clk":"4290106914","pt":1632497500857,"mc":[{"id":"1.188075669","rc":[{"batl":[[1,1.11,30],[2,1.13,93.5]],"ltp":1.09,"tv":27866.88,"id":9631939},{"batb":[[0,9.2,45.47]],"ltp":11.0,"tv":6937.36,"id":9454286}]}]}
{"op":"mcm","clk":"4290107037","pt":1632497502123,"mc":[{"id":"1.188075669","rc":[{"batb":[[0,1.08,224.73],[1,1.06,30],[2,1.05,3643.21]],"batl":[[0,1.09,48.94]],"ltp":1.09,"tv":27866.88,"id":9631939}]}]}
{"op":"mcm","clk":"4290107084","pt":1632497502646,"mc":[{"id":"1.188075669","rc":[{"batb":[[0,1.06,580.53],[1,1.05,4701.3],[2,1.04,348.62]],"batl":[[0,1.08,17.11],[1,1.09,48.94],[2,1.11,30]],"ltp":1.09,"tv":27866.88,"id":9631939}]}]}
{"op":"mcm","clk":"4290107187","pt":1632497504035,"mc":[{"id":"1.188075669","rc":[{"batb":[[0,9.2,47.47]],"ltp":11.0,"tv":6937.36,"id":9454286}]}]}
{"op":"mcm","clk":"4290107301","pt":1632497505147,"mc":[{"id":"1.188075669","rc":[{"batl":[[0,1.09,48.94],[1,1.11,20],[2,1.12,1048.7]],"ltp":1.09,"tv":27866.88,"id":9631939},{"batl":[[0,16,2],[1,18,2],[2,21,58.67]],"ltp":11.0,"tv":6937.36,"id":9454286}]}]}
{"op":"mcm","clk":"4290107350","pt":1632497505634,"mc":[{"id":"1.188075669","rc":[{"batl":[[2,1.12,1028.7]],"ltp":1.09,"tv":27866.88,"id":9631939}]}]}
{"op":"mcm","clk":"4290107463","pt":1632497506842,"mc":[{"id":"1.188075669","rc":[{"trd":[[1.09,27.02]],"batl":[[0,1.09,45.42]],"ltp":1.09,"tv":27873.92,"id":9631939}],"tv":34811.28}]}
{"op":"mcm","clk":"4290107510","pt":1632497507324,"mc":[{"id":"1.188075669","rc":[{"batl":[[1,1.11,10]],"ltp":1.09,"tv":27873.92,"id":9631939}]}]}
{"op":"mcm","clk":"4290107611","pt":1632497508730,"mc":[{"id":"1.188075669","rc":[{"batb":[[1,1.05,4660.3],[2,1.04,293.62]],"ltp":1.09,"tv":27873.92,"id":9631939}]}]}
{"op":"mcm","clk":"4290107814","pt":1632497511044,"mc":[{"id":"1.188075669","rc":[{"batl":[[2,1.12,125.71]],"ltp":1.09,"tv":27873.92,"id":9631939}]}]}
{"op":"mcm","clk":"4290107889","pt":1632497511829,"mc":[{"id":"1.188075669","rc":[{"batb":[[1,1.05,4707.3]],"batl":[[2,1.12,20]],"ltp":1.09,"tv":27873.92,"id":9631939},{"batb":[[0,9.2,45.47]],"batl":[[1,21,56.67],[2,36,2]],"ltp":11.0,"tv":6937.36,"id":9454286}]}]}
{"op":"mcm","clk":"4290107967","pt":1632497512570,"mc":[{"id":"1.188075669","rc":[{"batl":[[1,21,2]],"ltp":11.0,"tv":6937.36,"id":9454286}]}]}
{"op":"mcm","clk":"4290108085","pt":1632497514152,"mc":[{"id":"1.188075669","rc":[{"batb":[[1,1.05,5352.74],[2,1.04,353.24]],"batl":[[0,1.07,12209.11],[1,1.08,325.25],[2,1.09,45.42]],"ltp":1.09,"tv":27873.92,"id":9631939},{"batb":[[0,15,2],[1,14,170.76],[2,13.5,66.3]],"batl":[[0,17.5,3.95],[1,21,34.27],[2,22,43.46]],"ltp":11.0,"tv":6937.36,"id":9454286}]}]}
{"op":"mcm","clk":"4290108162","pt":1632497515059,"mc":[{"id":"1.188075669","rc":[{"trd":[[1.07,361.74]],"batb":[[1,1.05,5381.31]],"batl":[[0,1.07,3283.17]],"ltp":1.07,"tv":28235.66,"id":9631939},{"batb":[[0,15,40.8],[1,14,68.3]],"ltp":11.0,"tv":6937.36,"id":9454286}],"tv":35173.03}]}
{"op":"mcm","clk":"4290108213","pt":1632497515744,"mc":[{"id":"1.188075669","rc":[{"batb":[[1,1.05,5649.63]],"batl":[[2,1.09,60]],"ltp":1.07,"tv":28235.66,"id":9631939},{"batl":[[1,18.5,14.34],[2,21,34.27]],"ltp":11.0,"tv":6937.36,"id":9454286}]}]}
{"op":"mcm","clk":"4290108338","pt":1632497517072,"mc":[{"id":"1.188075669","rc":[{"batb":[[1,14.5,2],[2,14,70.3]],"ltp":11.0,"tv":6937.36,"id":9454286}]}]}
{"op":"mcm","clk":"4290108423","pt":1632497517966,"mc":[{"id":"1.188075669","rc":[{"batb":[[0,15.5,25],[1,15,40.8],[2,14.5,2]],"ltp":11.0,"tv":6937.36,"id":9454286}]}]}
{"op":"mcm","clk":"4290108524","pt":1632497519071,"mc":[{"id":"1.188075669","rc":[{"batl":[[0,1.07,3380.09]],"ltp":1.07,"tv":28235.66,"id":9631939},{"batb":[[0,15.5,5.65]],"ltp":11.0,"tv":6937.36,"id":9454286}]}]}
{"op":"mcm","clk":"4290108552","pt":1632497519442,"mc":[{"id":"1.188075669","rc":[{"trd":[[1.07,363.06]],"batl":[[0,1.07,3379.43]],"ltp":1.07,"tv":28236.98,"id":9631939}],"tv":35174.34}]}
{"op":"mcm","clk":"4290108631","pt":1632497520284,"mc":[{"id":"1.188075669","rc":[{"batl":[[2,1.09,197.5]],"ltp":1.07,"tv":28236.98,"id":9631939}]}]}
{"op":"mcm","clk":"4290108920","pt":1632497522980,"mc":[{"id":"1.188075669","rc":[{"trd":[[1.07,368.31]],"batb":[[0,1.06,600.53]],"batl":[[0,1.07,3376.8]],"ltp":1.07,"tv":28242.23,"id":9631939}],"tv":35179.6}]}
{"op":"mcm","clk":"4290108972","pt":1632497523454,"mc":[{"id":"1.188075669","rc":[{"batb":[[1,1.05,5602.63]],"ltp":1.07,"tv":28242.23,"id":9631939}]}]}
{"op":"mcm","clk":"4290109267","pt":1632497526158,"mc":[{"id":"1.188075669","rc":[{"trd":[[1.07,371.45]],"batb":[[2,1.04,393.24]],"batl":[[0,1.07,2805.5]],"ltp":1.07,"tv":28245.37,"id":9631939}],"tv":35182.74}]}
{"op":"mcm","clk":"4290109572","pt":1632497529154,"mc":[{"id":"1.188075669","rc":[{"trd":[[1.07,372.21]],"batl":[[0,1.07,2805.12]],"ltp":1.07,"tv":28246.13,"id":9631939}],"tv":35183.49}]}
{"op":"mcm","clk":"4290109774","pt":1632497531154,"mc":[{"id":"1.188075669","rc":[{"batb":[[2,1.04,333.62]],"ltp":1.07,"tv":28246.13,"id":9631939}]}]}
{"op":"mcm","clk":"4290109976","pt":1632497533158,"mc":[{"id":"1.188075669","rc":[{"batb":[[0,1.06,50],[1,1.05,3870.53]],"batl":[[0,1.07,165.42],[1,1.09,197.5],[2,1.1,132.25]],"ltp":1.07,"tv":28246.13,"id":9631939},{"batl":[[0,18.5,14.34],[1,21,2],[2,30,48.16]],"ltp":11.0,"tv":6937.36,"id":9454286}]}]}
{"op":"mcm","clk":"4290110035","pt":1632497533787,"mc":[{"id":"1.188075669","rc":[{"batb":[[0,1.06,20],[1,1.05,268.32],[2,1.04,40]],"batl":[[0,1.09,197.5],[1,1.1,132.25],[2,1.11,105.5]],"ltp":1.07,"tv":28246.13,"id":9631939},{"batb":[[0,13,5],[1,12,66.28],[2,11,2]],"batl":[[1,30,48.16],[2,36,2]],"ltp":11.0,"tv":6937.36,"id":9454286}]}]}
{"op":"mcm","clk":"4290110169","pt":1632497535166,"mc":[{"id":"1.188075669","rc":[{"batb":[[1,1.04,40],[2,1.03,436.83]],"batl":[[0,1.09,137.5]],"ltp":1.07,"tv":28246.13,"id":9631939},{"batb":[[0,12,66.28],[1,11,2],[2,8.6,2]],"batl":[[0,30,48.16],[1,36,2],[2,110,2]],"ltp":11.0,"tv":6937.36,"id":9454286}]}]}
{"op":"mcm","clk":"4290110285","pt":1632497536157,"mc":[{"id":"1.188075669","rc":[{"batb":[[2,1.03,2082.03]],"batl":[[0,1.09,1070.81],[1,1.1,611.68]],"ltp":1.07,"tv":28246.13,"id":9631939},{"batb":[[0,12,64.28]],"ltp":11.0,"tv":6937.36,"id":9454286}]}]}
{"op":"mcm","clk":"4290110528","pt":1632497538699,"mc":[{"id":"1.188075669","rc":[{"batl":[[0,1.09,1210.31],[1,1.1,632.68]],"ltp":1.07,"tv":28246.13,"id":9631939},{"batb":[[0,12,66.28]],"ltp":11.0,"tv":6937.36,"id":9454286}]}]}
{"op":"mcm","clk":"4290110705","pt":1632497540705,"mc":[{"id":"1.188075669","rc":[{"batb":[[0,1.04,40],[1,1.03,2082.03],[2,1.02,6395.98]],"ltp":1.07,"tv":28246.13,"id":9631939}]}]}
{"op":"mcm","clk":"4290110896","pt":1632497542865,"mc":[{"id":"1.188075669","rc":[{"batl":[[0,1.09,139.5],[1,1.1,153.25],[2,1.12,20]],"ltp":1.07,"tv":28246.13,"id":9631939},{"batb":[[2,3.85,376.57]],"ltp":11.0,"tv":6937.36,"id":9454286}]}]}
{"op":"mcm","clk":"4290110999","pt":1632497543874,"mc":[{"id":"1.188075669","rc":[{"batl":[[0,30,50.16]],"ltp":11.0,"tv":6937.36,"id":9454286}]}]}
{"op":"mcm","clk":"4290111067","pt":1632497544768,"mc":[{"id":"1.188075669","rc":[{"batl":[[0,30,2]],"ltp":11.0,"tv":6937.36,"id":9454286}]}]}
{"op":"mcm","clk":"4290111167","pt":1632497546081,"mc":[{"id":"1.188075669","rc":[{"batb":[[0,1.04,87],[1,1.03,2145.03]],"batl":[[0,1.05,3921.68],[1,1.07,28.04],[2,1.08,688]],"ltp":1.07,"tv":28246.13,"id":9631939},{"batb":[[0,21,119.88],[1,20,23.5],[2,19.5,11.76]],"batl":[[1,34,5.98],[2,36,2]],"ltp":11.0,"tv":6937.36,"id":9454286}]}]}
{"op":"mcm","clk":"4290111265","pt":1632497547190,"mc":[{"id":"1.188075669","rc":[{"batb":[[0,1.04,40],[1,1.03,2520.57]],"batl":[[1,1.07,88.04],[2,1.08,29]],"ltp":1.07,"tv":28246.13,"id":9631939},{"batb":[[0,22,27.63],[1,21,119.88],[2,20,23.5]],"batl":[[0,29,13.33],[1,30,2],[2,34,19.8]],"ltp":11.0,"tv":6937.36,"id":9454286}]}]}
{"op":"mcm","clk":"4290111301","pt":1632497547675,"mc":[{"id":"1.188075669","rc":[{"trd":[[1.05,1.1]],"batl":[[0,1.05,4159.23]],"ltp":1.05,"tv":28247.22,"id":9631939}],"tv":35184.59}]}
{"op":"mcm","clk":"4290111422","pt":1632497548892,"mc":[{"id":"1.188075669","rc":[{"batb":[[0,22,29.63],[1,21,121.88]],"ltp":11.0,"tv":6937.36,"id":9454286}]}]}
{"op":"mcm","clk":"4290111528","pt":1632497549894,"mc":[{"id":"1.188075669","rc":[{"batl":[[2,1.08,765.16]],"ltp":1.05,"tv":28247.22,"id":9631939}]}]}
{"op":"mcm","clk":"4290111611","pt":1632497550789,"mc":[{"id":"1.188075669","rc":[{"batb":[[0,1.04,50]],"batl":[[1,1.07,28.04],[2,1.08,29]],"ltp":1.05,"tv":28247.22,"id":9631939},{"batb":[[0,23,11.9],[1,22,29.63],[2,21,121.88]],"batl":[[0,28,2.93],[1,29,13.33],[2,30,2]],"ltp":11.0,"tv":6937.36,"id":9454286}]}]}
{"op":"mcm","clk":"4290111755","pt":1632497552283,"mc":[{"id":"1.188075669","rc":[{"batl":[[1,1.06,192.75],[2,1.07,199.54]],"ltp":1.05,"tv":28247.22,"id":9631939}]}]}
{"op":"mcm","clk":"4290111931","pt":1632497554004,"mc":[{"id":"1.188075669","rc":[{"batl":[[1,1.06,252.75]],"ltp":1.05,"tv":28247.22,"id":9631939}]}]}
{"op":"mcm","clk":"4290112234","pt":1632497557587,"mc":[{"id":"1.188075669","rc":[{"batl":[[0,1.05,3384.66]],"ltp":1.05,"tv":28247.22,"id":9631939}]}]}
{"op":"mcm","clk":"4290112562","pt":1632497561217,"mc":[{"id":"1.188075669","rc":[{"trd":[[1.05,5.79]],"batb":[[1,1.03,846.24]],"batl":[[0,1.05,308.4],[2,1.07,171.5]],"ltp":1.05,"tv":28251.92,"id":9631939},{"batb":[[2,21,2]],"batl":[[2,36,2]],"ltp":11.0,"tv":6937.36,"id":9454286}],"tv":35189.29}]}
{"op":"mcm","clk":"4290112607","pt":1632497561687,"mc":[{"id":"1.188075669","rc":[{"batb":[[0,1.05,10],[1,1.04,50],[2,1.03,346.41]],"batl":[[0,1.06,252.75],[1,1.07,171.5],[2,1.08,182.94]],"ltp":1.05,"tv":28251.92,"id":9631939},{"batb":[[0,18,3.52],[1,17.5,54.72],[2,15,2]],"batl":[[0,29,11.33],[1,55,2],[2,65,41.47]],"ltp":11.0,"tv":6937.36,"id":9454286}]}]}
{"op":"mcm","clk":"4290112689","pt":1632497562628,"mc":[{"id":"1.188075669","rc":[{"batb":[[2,1.02,592.24]],"batl":[[0,1.07,171.5],[1,1.08,182.94],[2,1.09,139.5]],"ltp":1.05,"tv":28251.92,"id":9631939},{"batb":[[0,17.5,52.72],[1,15,2],[2,12,2]],"batl":[[0,55,2],[1,65,41.47],[2,110,2]],"ltp":11.0,"tv":6937.36,"id":9454286}]}]}
{"op":"mcm","clk":"4290112811","pt":1632497564204,"mc":[{"id":"1.188075669","rc":[{"trd":[[1.04,60.02],[1.05,25.79]],"batb":[[0,1.04,19.99],[1,1.02,1661.33],[2,1.01,1340.64]],"batl":[[0,1.06,1598.64],[1,1.07,171.5],[2,1.08,182.94]],"ltp":1.04,"tv":28331.94,"id":9631939},{"batl":[[0,65,41.47],[1,110,2],[2,990,0.01]],"ltp":11.0,"tv":6937.36,"id":9454286}],"tv":35269.31}]}
{"op":"mcm","clk":"4290112853","pt":1632497564622,"mc":[{"id":"1.188075669","rc":[{"batb":[[0,1.01,1340.64],[1,1.02,0],[2,1.01,0]],"batl":[[0,1.07,171.5],[1,1.08,182.94],[2,1.09,139.5]],"ltp":1.04,"tv":28331.94,"id":9631939}]}]}
{"op":"mcm","clk":"4290113073","pt":1632497567049,"mc":[{"id":"1.188075669","rc":[{"trd":[[1.04,102.26]],"batb":[[0,1.03,1645.2],[1,1.01,1340.64]],"batl":[[0,1.04,857.24],[1,1.05,743.87],[2,1.07,171.5]],"ltp":1.04,"tv":28374.18,"id":9631939},{"batl":[[0,55,2],[1,65,41.47],[2,110,2]],"ltp":11.0,"tv":6937.36,"id":9454286}],"tv":35311.55}]}
{"op":"mcm","clk":"4290113137","pt":1632497567839,"mc":[{"id":"1.188075669","rc":[{"batb":[[0,1.03,1665.19],[1,1.02,619.24],[2,1.01,1566.64]],"ltp":1.04,"tv":28374.18,"id":9631939},{"batl":[[0,55,4],[1,65,43.47]],"ltp":11.0,"tv":6937.36,"id":9454286}]}]}
{"op":"mcm","clk":"4290113249","pt":1632497569207,"mc":[{"id":"1.188075669","rc":[{"batb":[[0,1.03,1645.2]],"batl":[[2,1.06,208.75]],"ltp":1.04,"tv":28374.18,"id":9631939},{"batb":[[0,23,10.87],[1,17.5,52.72],[2,15,2]],"batl":[[0,36,5.77],[1,55,4],[2,65,43.47]],"ltp":11.0,"tv":6937.36,"id":9454286}]}]}
{"op":"mcm","clk":"4290113327","pt":1632497569942,"mc":[{"id":"1.188075669","rc":[{"batb":[[0,1.02,20],[1,1.01,1566.64],[2,1.01,0]],"batl":[[0,1.07,171.5],[1,1.08,182.94],[2,1.09,139.5]],"ltp":1.04,"tv":28374.18,"id":9631939},{"batb":[[0,17.5,52.72],[1,15,2],[2,12,2]],"batl":[[0,55,2],[1,65,43.47],[2,110,2]],"ltp":11.0,"tv":6937.36,"id":9454286}]}]}
{"op":"mcm","clk":"4290113458","pt":1632497571209,"mc":[{"id":"1.188075669","rc":[{"batb":[[0,1.04,10],[1,1.02,20],[2,1.01,1566.64]],"ltp":1.04,"tv":28374.18,"id":9631939}]}]}
{"op":"mcm","clk":"4290113562","pt":1632497572212,"mc":[{"id":"1.188075669","rc":[{"trd":[[1.04,142.26]],"batb":[[0,1.02,20],[1,1.01,1566.64],[2,1.01,0]],"batl":[[2,1.13,3.52]],"ltp":1.04,"tv":28414.18,"id":9631939},{"batb":[[2,3.85,376.57]],"ltp":11.0,"tv":6937.36,"id":9454286}],"tv":35351.55}]}
{"op":"mcm","clk":"4290113640","pt":1632497573106,"mc":[{"id":"1.188075669","rc":[{"batb":[[0,1.02,2428.07]],"batl":[[0,1.06,200.25],[1,1.07,171.5],[2,1.08,182.94]],"ltp":1.04,"tv":28414.18,"id":9631939},{"batb":[[0,17.5,54.72]],"batl":[[0,55,4]],"ltp":11.0,"tv":6937.36,"id":9454286}]}]}
{"op":"mcm","clk":"4290113740","pt":1632497574214,"mc":[{"id":"1.188075669","rc":[{"batb":[[0,1.02,1760.33]],"ltp":1.04,"tv":28414.18,"id":9631939},{"batb":[[2,1.01,139.76]],"batl":[[0,55,2],[1,65,2]],"ltp":11.0,"tv":6937.36,"id":9454286}]}]}
{"op":"mcm","clk":"4290113829","pt":1632497575221,"mc":[{"id":"1.188075669","rc":[{"batl":[[0,1.03,1860.03],[1,1.04,10071.42],[2,1.05,1409.76]],"ltp":1.04,"tv":28414.18,"id":9631939},{"batb":[[0,28,16.78],[1,27,8.4],[2,26,8.4]],"batl":[[2,100,95.24]],"ltp":11.0,"tv":6937.36,"id":9454286}]}]}
{"op":"mcm","clk":"4290113922","pt":1632497576219,"mc":[{"id":"1.188075669","rc":[{"batb":[[0,1.02,2184.59],[1,1.01,1596.34]],"batl":[[1,1.04,799.32],[2,1.05,1469.76]],"ltp":1.04,"tv":28414.18,"id":9631939},{"batb":[[0,30,12.78],[1,28,16.78],[2,27,8.4]],"batl":[[0,42,9.37],[1,55,10.54],[2,60,4.28]],"ltp":11.0,"tv":6937.36,"id":9454286}]}]}
{"op":"mcm","clk":"4290113944","pt":1632497576429,"mc":[{"id":"1.188075669","rc":[{"batb":[[0,1.02,1917.26]],"batl":[[0,1.03,2102.75],[2,1.05,1409.76]],"ltp":1.04,"tv":28414.18,"id":9631939},{"batb":[[0,34,7.35],[1,30,12.78],[2,28,16.78]],"batl":[[0,50,2.86]],"ltp":11.0,"tv":6937.36,"id":9454286}]}]}
{"op":"mcm","clk":"4290114090","pt":1632497577932,"mc":[{"id":"1.188075669","rc":[{"batl":[[2,1.05,1459.76]],"ltp":1.04,"tv":28414.18,"id":9631939},{"batb":[[2,29,2]],"batl":[[0,50,2]],"ltp":11.0,"tv":6937.36,"id":9454286}]}]}
{"op":"mcm","clk":"4290114289","pt":1632497580039,"mc":[{"id":"1.188075669","rc":[{"batb":[[0,1.02,2341.52]],"batl":[[2,1.05,1519.76]],"ltp":1.04,"tv":28414.18,"id":9631939},{"batl":[[0,46,8.94],[1,48,2],[2,50,2]],"ltp":11.0,"tv":6937.36,"id":9454286}]}]}
{"op":"mcm","clk":"4290114689","pt":1632497584137,"mc":[{"id":"1.188075669","rc":[{"trd":[[1.02,100]],"batb":[[0,1.02,2291.52],[1,1.01,1378.22]],"ltp":1.02,"tv":28514.18,"id":9631939},{"batl":[[0,46,11.8]],"ltp":11.0,"tv":6937.36,"id":9454286}],"tv":35451.55}]}
{"op":"mcm","clk":"4290114968","pt":1632497586853,"mc":[{"id":"1.188075669","rc":[{"batb":[[0,1.02,2342.1]],"batl":[[1,1.05,1519.76],[2,1.06,200.25]],"ltp":1.02,"tv":28514.18,"id":9631939}]}]}
{"op":"mcm","clk":"4290115040","pt":1632497587539,"mc":[{"id":"1.188075669","rc":[{"trd":[[1.03,0.84]],"batl":[[0,1.03,2102.33]],"ltp":1.03,"tv":28515.02,"id":9631939}],"tv":35452.39}]}
{"op":"mcm","clk":"4290115336","pt":1632497590849,"mc":[{"id":"1.188075669","rc":[{"trd":[[1.03,1.22]],"batl":[[0,1.03,2102.14]],"ltp":1.03,"tv":28515.4,"id":9631939}],"tv":35452.76}]}
{"op":"mcm","clk":"4290115712","pt":1632497594959,"mc":[{"id":"1.188075669","rc":[{"trd":[[1.03,101.22]],"batl":[[0,1.03,2052.14]],"ltp":1.03,"tv":28615.4,"id":9631939},{"batl":[[2,55,8.54]],"ltp":11.0,"tv":6937.36,"id":9454286}],"tv":35552.76}]}
{"op":"mcm","clk":"4290115870","pt":1632497596937,"mc":[{"id":"1.188075669","rc":[{"trd":[[1.03,105.91]],"batl":[[0,1.03,2049.79]],"ltp":1.03,"tv":28620.09,"id":9631939}],"tv":35557.46}]}
{"op":"mcm","clk":"4290115934","pt":1632497597773,"mc":[{"id":"1.188075669","rc":[{"batl":[[0,1.03,1888.49]],"ltp":1.03,"tv":28620.09,"id":9631939}]}]}
{"op":"mcm","clk":"4290115996","pt":1632497598572,"mc":[{"id":"1.188075669","rc":[{"batb":[[0,30,12.78],[1,29,2],[2,28,16.78]],"batl":[[0,46,8.94]],"ltp":11.0,"tv":6937.36,"id":9454286}]}]}
{"op":"mcm","clk":"4290116166","pt":1632497600852,"mc":[{"id":"1.188075669","rc":[{"trd":[[1.02,110]],"batb":[[0,1.02,2337.1]],"ltp":1.02,"tv":28630.09,"id":9631939}],"tv":35567.46}]}
{"op":"mcm","clk":"4290116265","pt":1632497602052,"mc":[{"id":"1.188075669","rc":[{"batb":[[0,32,2],[1,30,14.78],[2,29,2]],"batl":[[0,44,1.32],[1,46,8.94],[2,48,2]],"ltp":11.0,"tv":6937.36,"id":9454286}]}]}
{"op":"mcm","clk":"4290116399","pt":1632497603744,"mc":[{"id":"1.188075669","rc":[{"batl":[[0,1.03,2049.79]],"ltp":1.02,"tv":28630.09,"id":9631939}]}]}
{"op":"mcm","clk":"4290116488","pt":1632497604961,"mc":[{"id":"1.188075669","rc":[{"batl":[[0,1.03,1888.49]],"ltp":1.02,"tv":28630.09,"id":9631939}]}]}
{"op":"mcm","clk":"4290116746","pt":1632497608065,"mc":[{"id":"1.188075669","rc":[{"trd":[[1.03,217.15]],"batl":[[0,1.03,1777.25]],"ltp":1.03,"tv":28741.33,"id":9631939},{"trd":[[34,3.37]],"ltp":34.0,"tv":6940.73,"id":9454286}],"tv":35682.07}]}
{"op":"mcm","clk":"4290117012","pt":1632497611159,"mc":[{"id":"1.188075669","rc":[{"batl":[[0,1.03,2049.79]],"ltp":1.03,"tv":28741.33,"id":9631939},{"batb":[[0,30,14.78],[1,29,2],[2,28,16.78]],"ltp":34.0,"tv":6940.73,"id":9454286}]}]}
{"op":"mcm","clk":"4290117410","pt":1632497615878,"mc":[{"id":"1.188075669","rc":[{"batb":[[1,28,16.78],[2,27,8.4]],"ltp":34.0,"tv":6940.73,"id":9454286}]}]}
{"op":"mcm","clk":"4290117697","pt":1632497619086,"mc":[{"id":"1.188075669","rc":[{"batb":[[0,38,2.46],[1,30,14.78],[2,28,16.78]],"ltp":34.0,"tv":6940.73,"id":9454286}]}]}
{"op":"mcm","clk":"4290117717","pt":1632497619352,"mc":[{"id":"1.188075669","rc":[{"batb":[[0,30,14.78],[1,28,16.78],[2,27,8.4]],"ltp":34.0,"tv":6940.73,"id":9454286}]}]}
{"op":"mcm","clk":"4290118014","pt":1632497622884,"mc":[{"id":"1.188075669","rc":[{"trd":[[38,0.58]],"ltp":38.0,"tv":6941.31,"id":9454286}],"tv":35682.65}]}
{"op":"mcm","clk":"4290118332","pt":1632497627071,"mc":[{"id":"1.188075669","rc":[{"batb":[[0,32,7.81],[1,30,14.78],[2,28,16.78]],"ltp":38.0,"tv":6941.31,"id":9454286}]}]}
{"op":"mcm","clk":"4290118811","pt":1632497632782,"mc":[{"id":"1.188075669","rc":[{"trd":[[44,0.04]],"batl":[[0,46,8.94],[1,48,2],[2,55,8.54]],"ltp":44.0,"tv":6941.35,"id":9454286}],"tv":35682.69}]}
{"op":"mcm","clk":"4290119156","pt":1632497636997,"mc":[{"id":"1.188075669","rc":[{"trd":[[1.02,153.91]],"batb":[[0,1.02,2315.13]],"ltp":1.02,"tv":28785.24,"id":9631939},{"batl":[[0,44,1.35],[1,46,8.94],[2,48,2]],"ltp":44.0,"tv":6941.35,"id":9454286}],"tv":35726.6}]}
{"op":"mcm","clk":"4290119416","pt":1632497640094,"mc":[{"id":"1.188075669","rc":[{"batb":[[0,1.02,2342.1]],"ltp":1.02,"tv":28785.24,"id":9631939}]}]}
{"op":"mcm","clk":"4290119648","pt":1632497642706,"mc":[{"id":"1.188075669","rc":[{"trd":[[1.03,221.85]],"batl":[[0,1.03,2047.44]],"ltp":1.03,"tv":28789.94,"id":9631939}],"tv":35731.29}]}
{"op":"mcm","clk":"4290121599","pt":1632497665053,"mc":[{"id":"1.188075669","rc":[{"batb":[[0,1.02,424.26],[1,1.01,1348.52]],"batl":[[0,1.05,110],[1,1.06,200.25],[2,1.13,3.52]],"ltp":1.03,"tv":28789.94,"id":9631939},{"batb":[[0,30,12.78],[1,22,27.79],[2,17.5,2]],"batl":[[0,46,8.94],[1,110,2],[2,520,36.18]],"ltp":44.0,"tv":6941.35,"id":9454286}]}]}
{"op":"mcm","clk":"4290121712","pt":1632497666211,"mc":[{"id":"1.188075669","rc":[{"batb":[[0,1.01,1348.52],[1,1.01,0]],"batl":[[0,1.05,267.3]],"ltp":1.03,"tv":28789.94,"id":9631939},{"batb":[[0,22,27.79],[1,21,2]],"batl":[[0,110,2],[1,520,36.18],[2,990,0.01]],"ltp":44.0,"tv":6941.35,"id":9454286}]}]}
{"op":"mcm","clk":"4290121737","pt":1632497666423,"mc":[{"id":"1.188075669","rc":[{"batl":[[0,1.05,50]],"ltp":1.03,"tv":28789.94,"id":9631939},{"batb":[[1,17.5,2],[2,4.4,375.15]],"ltp":44.0,"tv":6941.35,"id":9454286}]}]}
{"op":"mcm","clk":"4290121867","pt":1632497667955,"mc":[{"id":"1.188075669","rc":[{"batb":[[0,1.02,6],[1,1.01,3026.88]],"batl":[[0,1.05,1664.42]],"ltp":1.03,"tv":28789.94,"id":9631939}]}]}
{"op":"mcm","clk":"4290121932","pt":1632497668536,"mc":[{"id":"1.188075669","rc":[{"batl":[[0,1.05,50]],"ltp":1.03,"tv":28789.94,"id":9631939},{"batb":[[0,22,29.79],[1,21,2],[2,17.5,2]],"ltp":44.0,"tv":6941.35,"id":9454286}]}]}
{"op":"mcm","clk":"4290122023","pt":1632497669645,"mc":[{"id":"1.188075669","rc":[{"batb":[[1,1.01,3239.88]],"batl":[[0,1.05,306.1]],"ltp":1.03,"tv":28789.94,"id":9631939},{"batb":[[1,21,4]],"batl":[[1,990,0.01],[2,990,0]],"ltp":44.0,"tv":6941.35,"id":9454286}]}]}
{"op":"mcm","clk":"4290122286","pt":1632497671933,"mc":[{"id":"1.188075669","rc":[{"trd":[[1.02,165.92]],"batb":[[0,1.01,3239.88],[1,1.01,0]],"batl":[[0,1.02,3121.73],[1,1.03,1450.33],[2,1.04,28.85]],"ltp":1.02,"tv":28801.95,"id":9631939},{"batb":[[0,36,13.06],[1,34,8.52],[2,32,6.52]],"batl":[[0,100,34.77],[1,110,2],[2,990,0.01]],"ltp":44.0,"tv":6941.35,"id":9454286}],"tv":35743.31}]}
{"op":"mcm","clk":"4290122419","pt":1632497673041,"mc":[{"id":"1.188075669","rc":[{"trd":[[1.02,375.92]],"batl":[[0,1.02,3016.73],[1,1.03,1693.05]],"ltp":1.02,"tv":29011.95,"id":9631939},{"batb":[[0,46,5.43],[1,36,13.06],[2,34,8.52]],"batl":[[0,75,3.13],[1,90,5.22],[2,95,2.62]],"ltp":44.0,"tv":6941.35,"id":9454286}],"tv":35953.31}]}
{"op":"mcm","clk":"4290122481","pt":1632497673622,"mc":[{"id":"1.188075669","rc":[{"batb":[[0,1.01,3839.88]],"batl":[[1,1.03,1450.33],[2,1.04,88.85]],"ltp":1.02,"tv":29011.95,"id":9631939},{"batl":[[0,65,7.5]],"ltp":44.0,"tv":6941.35,"id":9454286}]}]}
{"op":"mcm","clk":"4290122570","pt":1632497674628,"mc":[{"id":"1.188075669","rc":[{"batb":[[0,1.01,4087.4]],"ltp":1.02,"tv":29011.95,"id":9631939},{"batl":[[2,95,4.62]],"ltp":44.0,"tv":6941.35,"id":9454286}]}]}
{"op":"mcm","clk":"4290122634","pt":1632497675525,"mc":[{"id":"1.188075669","rc":[{"batl":[[1,85,2],[2,90,5.22]],"ltp":44.0,"tv":6941.35,"id":9454286}]}]}
{"op":"mcm","clk":"4290122786","pt":1632497676742,"mc":[{"id":"1.188075669","rc":[{"batl":[[0,1.02,3259.45]],"ltp":1.02,"tv":29011.95,"id":9631939},{"batl":[[0,65,10.63],[1,70,2],[2,85,2]],"ltp":44.0,"tv":6941.35,"id":9454286}]}]}
