{"op":"mcm","clk":"4291919417","pt":1632511078541,"mc":[{"id":"1.188136695","marketDefinition":{"bspMarket":false,"turnInPlayEnabled":true,"persistenceEnabled":true,"marketBaseRate":5.0,"eventId":"30941535","eventTypeId":"2","numberOfWinners":1,"bettingType":"ODDS","marketType":"MATCH_ODDS","marketTime":"2021-09-25T13:30:00.000Z","suspendTime":"2021-09-25T13:30:00.000Z","bspReconciled":false,"complete":true,"inPlay":false,"crossMatching":true,"runnersVoidable":false,"numberOfActiveRunners":2,"betDelay":0,"status":"OPEN","runners":[{"status":"ACTIVE","sortPriority":1,"id":5300737,"name":"Anett Kontaveit"},{"status":"ACTIVE","sortPriority":2,"id":2497008,"name":"Petra Kvitova"}],"regulators":["MR_INT"],"discountAllowed":false,"timezone":"UTC","openDate":"2021-09-25T13:30:00.000Z","version":4053802986,"name":"Match Odds","eventName":"Kontaveit v Kvitova"},"rc":[{"batb":[[0,1.02,3658.18],[1,1.01,3683.18]],"ltp":0.0,"tv":0.0,"id":5300737},{"batb":[[0,1.02,3658.18],[1,1.01,3683.18]],"ltp":0.0,"tv":0.0,"id":2497008}]}]}
{"op":"mcm","clk":"4291919625","pt":1632511079859,"mc":[{"id":"1.188136695","marketDefinition":{"bspMarket":false,"turnInPlayEnabled":true,"persistenceEnabled":true,"marketBaseRate":5.0,"eventId":"30941535","eventTypeId":"2","numberOfWinners":1,"bettingType":"ODDS","marketType":"MATCH_ODDS","marketTime":"2021-09-25T13:30:00.000Z","suspendTime":"2021-09-25T13:30:00.000Z","bspReconciled":false,"complete":true,"inPlay":false,"crossMatching":true,"runnersVoidable":false,"numberOfActiveRunners":2,"betDelay":0,"status":"OPEN","runners":[{"status":"ACTIVE","sortPriority":1,"id":5300737,"name":"Anett Kontaveit"},{"status":"ACTIVE","sortPriority":2,"id":2497008,"name":"Petra Kvitova"}],"regulators":["MR_INT"],"discountAllowed":false,"timezone":"UTC","openDate":"2021-09-25T13:30:00.000Z","version":4053802986,"name":"Match Odds","eventName":"Kontaveit v Kvitova"}}]}
{"op":"mcm","clk":"4291919805","pt":1632511080897,"mc":[{"id":"1.188136695","marketDefinition":{"bspMarket":false,"turnInPlayEnabled":true,"persistenceEnabled":true,"marketBaseRate":5.0,"eventId":"30941535","eventTypeId":"2","numberOfWinners":1,"bettingType":"ODDS","marketType":"MATCH_ODDS","marketTime":"2021-09-25T13:30:00.000Z","suspendTime":"2021-09-25T13:30:00.000Z","bspReconciled":false,"complete":true,"inPlay":false,"crossMatching":true,"runnersVoidable":false,"numberOfActiveRunners":2,"betDelay":0,"status":"OPEN","runners":[{"status":"ACTIVE","sortPriority":1,"id":5300737,"name":"Anett Kontaveit"},{"status":"ACTIVE","sortPriority":2,"id":2497008,"name":"Petra Kvitova"}],"regulators":["MR_INT"],"discountAllowed":true,"timezone":"UTC","openDate":"2021-09-25T13:30:00.000Z","version":4053802986,"name":"Match Odds","eventName":"Kontaveit v Kvitova"}}]}
{"op":"mcm","clk":"4291953493","pt":1632511296536,"mc":[{"id":"1.188136695","rc":[{"batb":[[0,1.45,2926.54],[1,1.02,3658.18],[2,1.01,3683.18]],"ltp":0.0,"tv":0.0,"id":2497008}]}]}
{"op":"mcm","clk":"4291963933","pt":1632511361740,"mc":[{"id":"1.188136695","rc":[{"batb":[[0,1.06,1905.01],[1,1.05,1905.01],[2,1.02,3658.18]],"ltp":0.0,"tv":0.0,"id":5300737}]}]}
{"op":"mcm","clk":"4291964036","pt":1632511362440,"mc":[{"id":"1.188136695","rc":[{"batb":[[2,1.04,1905.01]],"ltp":0.0,"tv":0.0,"id":5300737}]}]}
{"op":"mcm","clk":"4291964383","pt":1632511364535,"mc":[{"id":"1.188136695","rc":[{"batb":[[0,1.09,1905.01],[1,1.08,1905.01],[2,1.06,1905.01]],"ltp":0.0,"tv":0.0,"id":5300737}]}]}
{"op":"mcm","clk":"4291964449","pt":1632511364924,"mc":[{"id":"1.188136695","rc":[{"batb":[[2,1.07,1905.01]],"ltp":0.0,"tv":0.0,"id":5300737}]}]}
{"op":"mcm","clk":"4291965369","pt":1632511370758,"mc":[{"id":"1.188136695","rc":[{"batb":[[1,1.1,1905.01],[2,1.02,3658.18]],"ltp":0.0,"tv":0.0,"id":2497008}]}]}
{"op":"mcm","clk":"4291965512","pt":1632511371645,"mc":[{"id":"1.188136695","rc":[{"batb":[[2,1.09,1905.01]],"ltp":0.0,"tv":0.0,"id":2497008}]}]}
{"op":"mcm","clk":"4291966341","pt":1632511376464,"mc":[{"id":"1.188136695","rc":[{"batb":[[1,1.11,1905.01],[2,1.1,1905.01]],"ltp":0.0,"tv":0.0,"id":2497008}]}]}
{"op":"mcm","clk":"4291966809","pt":1632511379535,"mc":[{"id":"1.188136695","rc":[{"batb":[[0,1.11,1905.01],[1,1.09,1905.01],[2,1.08,1905.01]],"ltp":0.0,"tv":0.0,"id":5300737}]}]}
{"op":"mcm","clk":"4291966953","pt":1632511380467,"mc":[{"id":"1.188136695","rc":[{"batb":[[1,1.1,1905.01],[2,1.09,1905.01]],"ltp":0.0,"tv":0.0,"id":5300737}]}]}
{"op":"mcm","clk":"4291968015","pt":1632511387270,"mc":[{"id":"1.188136695","rc":[{"batb":[[1,1.12,1238],[2,1.11,1905.01]],"ltp":0.0,"tv":0.0,"id":2497008}]}]}
{"op":"mcm","clk":"4291968775","pt":1632511392080,"mc":[{"id":"1.188136695","rc":[{"batb":[[0,1.12,1238],[1,1.11,1905.01],[2,1.1,1905.01]],"ltp":0.0,"tv":0.0,"id":5300737}]}]}
{"op":"mcm","clk":"4291971934","pt":1632511413406,"mc":[{"id":"1.188136695","rc":[{"batb":[[0,1.5,2926.54]],"ltp":0.0,"tv":0.0,"id":2497008}]}]}
{"op":"mcm","clk":"4291975148","pt":1632511435170,"mc":[{"id":"1.188136695","rc":[{"batb":[[0,1.25,915.28],[1,1.12,1238],[2,1.11,1905.01]],"ltp":0.0,"tv":0.0,"id":5300737}]}]}
{"op":"mcm","clk":"4292300958","pt":1632514241247,"mc":[{"id":"1.188136695","rc":[{"batb":[[0,1.25,915.08],[1,1.12,1237.47],[2,1.11,1904.19]],"batl":[[0,11,5]],"ltp":0.0,"tv":0.0,"id":5300737},{"batb":[[0,1.5,2925.9],[1,1.12,1237.47],[2,1.11,1904.19]],"ltp":0.0,"tv":0.0,"id":2497008}]}]}
{"op":"mcm","clk":"4292302431","pt":1632514256385,"mc":[{"id":"1.188136695","rc":[{"batb":[[0,1.26,6.78],[1,1.25,915.08],[2,1.12,1237.47]],"ltp":0.0,"tv":0.0,"id":5300737},{"batb":[[0,1.51,5.65],[1,1.5,2925.9],[2,1.12,1237.47]],"ltp":0.0,"tv":0.0,"id":2497008}]}]}
{"op":"mcm","clk":"4292312956","pt":1632514355414,"mc":[{"id":"1.188136695","rc":[{"batl":[[1,990,2.2]],"ltp":0.0,"tv":0.0,"id":5300737},{"batl":[[0,990,2.2]],"ltp":0.0,"tv":0.0,"id":2497008}]}]}
{"op":"mcm","clk":"4292364227","pt":1632514813429,"mc":[{"id":"1.188136695","rc":[{"batb":[[1,1.12,1237.47],[2,1.11,1904.19]],"ltp":0.0,"tv":0.0,"id":2497008}]}]}
{"op":"mcm","clk":"4292457750","pt":1632515742494,"mc":[{"id":"1.188136695","rc":[{"batb":[[0,1.65,110.64],[1,1.26,6.78],[2,1.25,915.08]],"ltp":0.0,"tv":0.0,"id":5300737},{"batb":[[0,1.53,126.88],[1,1.51,5.65],[2,1.12,1237.47]],"ltp":0.0,"tv":0.0,"id":2497008}]}]}
{"op":"mcm","clk":"4292457962","pt":1632515745085,"mc":[{"id":"1.188136695","rc":[{"batb":[[0,1.72,112.89]],"ltp":0.0,"tv":0.0,"id":5300737}]}]}
{"op":"mcm","clk":"4292621612","pt":1632518104634,"mc":[{"id":"1.188136695","rc":[{"batb":[[0,1.73,12],[1,1.72,112.89],[2,1.26,6.78]],"ltp":0.0,"tv":0.0,"id":5300737},{"batb":[[0,1.54,11.14],[1,1.53,126.88],[2,1.51,5.65]],"ltp":0.0,"tv":0.0,"id":2497008}]}]}
{"op":"mcm","clk":"4292621637","pt":1632518105047,"mc":[{"id":"1.188136695","rc":[{"batl":[[0,10.5,3.43],[1,11,5],[2,990,2.2]],"ltp":0.0,"tv":0.0,"id":5300737},{"batl":[[0,11.5,3.43],[1,990,2.2]],"ltp":0.0,"tv":0.0,"id":2497008}]}]}
{"op":"mcm","clk":"4292623404","pt":1632518142722,"mc":[{"id":"1.188136695","rc":[{"batb":[[0,1.85,98.62],[1,1.73,12]],"ltp":0.0,"tv":0.0,"id":5300737},{"batb":[[0,1.64,118.85],[1,1.54,11.14]],"ltp":0.0,"tv":0.0,"id":2497008}]}]}
{"op":"mcm","clk":"4292627850","pt":1632518238629,"mc":[{"id":"1.188136695","rc":[{"batb":[[1,1.26,6.78],[2,1.25,915.08]],"ltp":0.0,"tv":0.0,"id":5300737},{"batb":[[1,1.51,5.65],[2,1.12,1237.47]],"ltp":0.0,"tv":0.0,"id":2497008}]}]}
{"op":"mcm","clk":"4292640992","pt":1632518531674,"mc":[{"id":"1.188136695","rc":[{"batb":[[1,1.25,915.08],[2,1.12,1237.47]],"ltp":0.0,"tv":0.0,"id":5300737}]}]}
{"op":"mcm","clk":"4292641018","pt":1632518532085,"mc":[{"id":"1.188136695","rc":[{"batb":[[1,1.12,1237.47],[2,1.11,1904.19]],"ltp":0.0,"tv":0.0,"id":2497008}]}]}
{"op":"mcm","clk":"4292652670","pt":1632518753068,"mc":[{"id":"1.188136695","rc":[{"batb":[[0,1.25,915.08],[1,1.12,1237.47],[2,1.11,1904.19]],"ltp":0.0,"tv":0.0,"id":5300737},{"batb":[[0,1.12,1237.47],[1,1.11,1904.19],[2,1.1,1904.19]],"ltp":0.0,"tv":0.0,"id":2497008}]}]}
{"op":"mcm","clk":"4292658870","pt":1632518877792,"mc":[{"id":"1.188136695","rc":[{"batb":[[0,1.83,100.24],[1,1.26,15.43],[2,1.25,915.08]],"ltp":0.0,"tv":0.0,"id":5300737},{"batb":[[0,1.13,15.43],[1,1.12,1237.47],[2,1.11,1904.19]],"ltp":0.0,"tv":0.0,"id":2497008}]}]}
{"op":"mcm","clk":"4292658874","pt":1632518877893,"mc":[{"id":"1.188136695","rc":[{"batb":[[0,1.58,124.03],[1,1.13,15.43],[2,1.12,1237.47]],"ltp":0.0,"tv":0.0,"id":2497008}]}]}
{"op":"mcm","clk":"4292664856","pt":1632519005103,"mc":[{"id":"1.188136695","rc":[{"batb":[[1,1.25,915.08],[2,1.12,1237.47]],"ltp":0.0,"tv":0.0,"id":5300737},{"batb":[[1,1.12,1237.47],[2,1.11,1904.19]],"ltp":0.0,"tv":0.0,"id":2497008}]}]}
{"op":"mcm","clk":"4292671323","pt":1632519133994,"mc":[{"id":"1.188136695","rc":[{"batb":[[0,1.59,10.28],[1,1.58,124.03],[2,1.12,1237.47]],"ltp":0.0,"tv":0.0,"id":2497008}]}]}
{"op":"mcm","clk":"4292673707","pt":1632519178248,"mc":[{"id":"1.188136695","rc":[{"batb":[[0,1.6,122.39],[1,1.59,10.28]],"ltp":0.0,"tv":0.0,"id":2497008}]}]}
{"op":"mcm","clk":"4292678243","pt":1632519262394,"mc":[{"id":"1.188136695","rc":[{"batb":[[1,1.12,1237.47],[2,1.11,1904.19]],"ltp":0.0,"tv":0.0,"id":2497008}]}]}
{"op":"mcm","clk":"4292683209","pt":1632519358233,"mc":[{"id":"1.188136695","rc":[{"batl":[[0,2.22,85.7],[1,10.5,3.43],[2,11,5]],"ltp":0.0,"tv":0.0,"id":5300737}]}]}
{"op":"mcm","clk":"4292684739","pt":1632519386426,"mc":[{"id":"1.188136695","rc":[{"batl":[[1,11,5],[2,990,2.2]],"ltp":0.0,"tv":0.0,"id":5300737}]}]}
{"op":"mcm","clk":"4292687065","pt":1632519435768,"mc":[{"id":"1.188136695","rc":[{"batb":[[0,1.25,915.08],[1,1.12,1237.47],[2,1.11,1904.19]],"ltp":0.0,"tv":0.0,"id":5300737},{"batb":[[0,1.12,1237.47],[1,1.11,1904.19],[2,1.1,1904.19]],"ltp":0.0,"tv":0.0,"id":2497008}]}]}
{"op":"mcm","clk":"4292689335","pt":1632519477767,"mc":[{"id":"1.188136695","rc":[{"batb":[[0,1.64,167.8],[1,1.25,915.08],[2,1.12,1237.47]],"ltp":0.0,"tv":0.0,"id":5300737}]}]}
{"op":"mcm","clk":"4292689344","pt":1632519477921,"mc":[{"id":"1.188136695","rc":[{"batb":[[0,1.53,192.06],[1,1.12,1237.47],[2,1.11,1904.19]],"ltp":0.0,"tv":0.0,"id":2497008}]}]}
{"op":"mcm","clk":"4292690231","pt":1632519496666,"mc":[{"id":"1.188136695","rc":[{"batb":[[0,1.65,12.85],[1,1.64,167.8],[2,1.25,915.08]],"ltp":0.0,"tv":0.0,"id":5300737}]}]}
{"op":"mcm","clk":"4292690242","pt":1632519496971,"mc":[{"id":"1.188136695","rc":[{"batb":[[0,1.54,11.14],[1,1.53,192.06],[2,1.12,1237.47]],"ltp":0.0,"tv":0.0,"id":2497008}]}]}
{"op":"mcm","clk":"4292703837","pt":1632519778138,"mc":[{"id":"1.188136695","rc":[{"batb":[[0,1.74,158.1],[1,1.65,12.85]],"ltp":0.0,"tv":0.0,"id":5300737},{"batb":[[0,1.63,180.2],[1,1.54,11.14]],"ltp":0.0,"tv":0.0,"id":2497008}]}]}
{"op":"mcm","clk":"4292706389","pt":1632519827619,"mc":[{"id":"1.188136695","rc":[{"batb":[[1,1.12,1237.47],[2,1.11,1904.19]],"ltp":0.0,"tv":0.0,"id":2497008}]}]}
{"op":"mcm","clk":"4292706407","pt":1632519827928,"mc":[{"id":"1.188136695","rc":[{"batb":[[1,1.25,915.08],[2,1.12,1237.47]],"ltp":0.0,"tv":0.0,"id":5300737}]}]}
{"op":"mcm","clk":"4292723000","pt":1632520163965,"mc":[{"id":"1.188136695","rc":[{"batb":[[0,1.75,11.14],[1,1.74,158.1],[2,1.25,915.08]],"ltp":0.0,"tv":0.0,"id":5300737}]}]}
{"op":"mcm","clk":"4292734224","pt":1632520377815,"mc":[{"id":"1.188136695","rc":[{"batb":[[1,1.25,915.08],[2,1.12,1237.47]],"ltp":0.0,"tv":0.0,"id":5300737}]}]}
{"op":"mcm","clk":"4292734232","pt":1632520377923,"mc":[{"id":"1.188136695","rc":[{"batb":[[0,1.8,152.8],[1,1.75,11.14],[2,1.25,915.08]],"ltp":0.0,"tv":0.0,"id":5300737}]}]}
{"op":"mcm","clk":"4292736322","pt":1632520417369,"mc":[{"id":"1.188136695","rc":[{"batb":[[1,1.25,915.08],[2,1.12,1237.47]],"ltp":0.0,"tv":0.0,"id":5300737}]}]}
{"op":"mcm","clk":"4292737834","pt":1632520442742,"mc":[{"id":"1.188136695","rc":[{"batl":[[1,2.24,25],[2,11,5]],"ltp":0.0,"tv":0.0,"id":5300737},{"batl":[[0,2,25],[1,11.5,3.43],[2,990,2.2]],"ltp":0.0,"tv":0.0,"id":2497008}]}]}
{"op":"mcm","clk":"4292743540","pt":1632520543663,"mc":[{"id":"1.188136695","rc":[{"batb":[[0,1.81,10.28],[1,1.8,152.8],[2,1.25,915.08]],"ltp":0.0,"tv":0.0,"id":5300737},{"batl":[[1,990,2.2],[2,990,0]],"ltp":0.0,"tv":0.0,"id":2497008}]}]}
{"op":"mcm","clk":"4292751249","pt":1632520678109,"mc":[{"id":"1.188136695","rc":[{"batb":[[0,1.95,140.99],[1,1.81,10.28]],"ltp":0.0,"tv":0.0,"id":5300737}]}]}
{"op":"mcm","clk":"4292758101","pt":1632520795737,"mc":[{"id":"1.188136695","rc":[{"batb":[[1,1.25,915.08],[2,1.12,1237.47]],"ltp":0.0,"tv":0.0,"id":5300737}]}]}
{"op":"mcm","clk":"4292761271","pt":1632520840387,"mc":[{"id":"1.188136695","rc":[{"batb":[[0,2.04,32.36],[1,1.95,140.99],[2,1.25,914.87]],"batl":[[0,2.22,85.71]],"ltp":0.0,"tv":0.0,"id":5300737},{"batb":[[0,1.82,26.24],[1,1.63,180.2],[2,1.12,1237.68]],"ltp":0.0,"tv":0.0,"id":2497008}]}]}
{"op":"mcm","clk":"4292764534","pt":1632520894464,"mc":[{"id":"1.188136695","rc":[{"batb":[[0,1.95,140.99],[1,1.25,914.87],[2,1.12,1237.68]],"ltp":0.0,"tv":0.0,"id":5300737},{"batb":[[0,1.63,180.2],[1,1.12,1237.68],[2,1.11,1904.52]],"ltp":0.0,"tv":0.0,"id":2497008}]}]}
{"op":"mcm","clk":"4292790799","pt":1632521302175,"mc":[{"id":"1.188136695","rc":[{"batb":[[0,2.02,4],[1,2,4],[2,1.95,140.99]],"batl":[[0,2.2,3],[1,2.22,85.71],[2,2.24,25]],"ltp":0.0,"tv":0.0,"id":5300737},{"batb":[[0,1.82,5],[1,1.81,4],[2,1.63,180.2]],"batl":[[0,1.99,4],[1,2,25],[2,990,2.2]],"ltp":0.0,"tv":0.0,"id":2497008}]}]}
{"op":"mcm","clk":"4292797475","pt":1632521407688,"mc":[{"id":"1.188136695","rc":[{"batb":[[0,2.02,138.19],[1,1.25,914.87],[2,1.12,1237.68]],"ltp":0.0,"tv":0.0,"id":5300737},{"batb":[[0,1.83,157.59],[1,1.82,5],[2,1.12,1237.68]],"ltp":0.0,"tv":0.0,"id":2497008}]}]}
{"op":"mcm","clk":"4292871901","pt":1632522426666,"mc":[{"id":"1.188136695","rc":[{"trd":[[1.83,20]],"batb":[[0,1.82,5],[1,1.12,1237.68],[2,1.11,1904.52]],"ltp":1.83,"tv":20.0,"id":2497008}],"tv":20.0}]}
{"op":"mcm","clk":"4292897315","pt":1632522991079,"mc":[{"id":"1.188136695","rc":[{"batl":[[0,2.2,88.71],[1,2.24,25],[2,11,5]],"ltp":0.0,"tv":0.0,"id":5300737}]}]}
{"op":"mcm","clk":"4292900569","pt":1632523060482,"mc":[{"id":"1.188136695","rc":[{"batb":[[0,2.02,182.92]],"ltp":0.0,"tv":0.0,"id":5300737}]}]}
{"op":"mcm","clk":"4292925062","pt":1632523562858,"mc":[{"id":"1.188136695","rc":[{"trd":[[2.2,2.8]],"batl":[[0,2.2,85.91]],"ltp":2.2,"tv":2.8,"id":5300737},{"trd":[[1.83,23.36]],"ltp":1.83,"tv":23.36,"id":2497008}],"tv":26.16}]}
{"op":"mcm","clk":"4292953973","pt":1632524113471,"mc":[{"id":"1.188136695","rc":[{"batb":[[0,2.02,4]],"ltp":2.2,"tv":2.8,"id":5300737}]}]}
{"op":"mcm","clk":"4292954275","pt":1632524117472,"mc":[{"id":"1.188136695","rc":[{"batb":[[0,2.02,182.92]],"ltp":2.2,"tv":2.8,"id":5300737}]}]}
{"op":"mcm","clk":"4292961472","pt":1632524169615,"mc":[{"id":"1.188136695","rc":[{"batb":[[0,1.83,208.2],[1,1.82,5],[2,1.12,1237.68]],"ltp":1.83,"tv":23.36,"id":2497008}]}]}
{"op":"mcm","clk":"4292982827","pt":1632524480586,"mc":[{"id":"1.188136695","rc":[{"batb":[[0,2.04,3],[1,2.02,182.04],[2,1.25,914.87]],"batl":[[0,2.18,3],[1,2.2,85.91],[2,2.24,25]],"ltp":2.2,"tv":2.8,"id":5300737},{"batb":[[0,1.84,207.06],[1,1.83,5],[2,1.82,5]],"batl":[[0,1.98,4],[1,1.99,4],[2,2,25]],"ltp":1.83,"tv":23.36,"id":2497008}]}]}
{"op":"mcm","clk":"4292983258","pt":1632524486268,"mc":[{"id":"1.188136695","rc":[{"batb":[[1,2.02,4]],"ltp":2.2,"tv":2.8,"id":5300737},{"batb":[[0,1.83,5],[1,1.82,5],[2,1.12,1237.68]],"ltp":1.83,"tv":23.36,"id":2497008}]}]}
{"op":"mcm","clk":"4292983518","pt":1632524490103,"mc":[{"id":"1.188136695","rc":[{"batb":[[0,1.84,207.06],[1,1.83,5],[2,1.82,5]],"ltp":1.83,"tv":23.36,"id":2497008}]}]}
{"op":"mcm","clk":"4292994813","pt":1632524685654,"mc":[{"id":"1.188136695","rc":[{"batb":[[1,1.25,914.87],[2,1.12,1237.68]],"batl":[[0,2.16,85.71],[1,2.18,3]],"ltp":2.2,"tv":2.8,"id":5300737},{"batb":[[2,1.12,1237.68]],"batl":[[1,2,25],[2,990,2.2]],"ltp":1.83,"tv":23.36,"id":2497008}]}]}
{"op":"mcm","clk":"4292994876","pt":1632524686384,"mc":[{"id":"1.188136695","rc":[{"batb":[[0,1.83,5],[1,1.12,1237.68],[2,1.11,2626.21]],"ltp":1.83,"tv":23.36,"id":2497008}]}]}
{"op":"mcm","clk":"4292995091","pt":1632524690352,"mc":[{"id":"1.188136695","rc":[{"batb":[[0,1.84,207.06],[1,1.83,5],[2,1.12,1237.68]],"ltp":1.83,"tv":23.36,"id":2497008}]}]}
{"op":"mcm","clk":"4293032292","pt":1632525215785,"mc":[{"id":"1.188136695","rc":[{"batb":[[0,2,4],[1,1.99,4],[2,1.25,914.87]],"batl":[[0,2.14,3],[1,2.16,85.71],[2,2.18,3]],"ltp":2.2,"tv":2.8,"id":5300737},{"batb":[[0,1.87,3],[1,1.86,3],[2,1.83,5]],"batl":[[0,2,30],[1,990,2.2],[2,990,0]],"ltp":1.83,"tv":23.36,"id":2497008}]}]}
{"op":"mcm","clk":"4293032594","pt":1632525219871,"mc":[{"id":"1.188136695","rc":[{"batb":[[0,1.87,203.89]],"ltp":1.83,"tv":23.36,"id":2497008}]}]}
{"op":"mcm","clk":"4293082611","pt":1632525999576,"mc":[{"id":"1.188136695","rc":[{"batb":[[1,1.25,914.87],[2,1.12,1237.68]],"batl":[[2,2.24,25]],"ltp":2.2,"tv":2.8,"id":5300737},{"batb":[[0,1.87,3],[1,1.12,1237.68],[2,1.11,2626.21]],"ltp":1.83,"tv":23.36,"id":2497008}]}]}
{"op":"mcm","clk":"4293082914","pt":1632526004062,"mc":[{"id":"1.188136695","rc":[{"batb":[[0,1.87,203.89]],"ltp":1.83,"tv":23.36,"id":2497008}]}]}
{"op":"mcm","clk":"4293093784","pt":1632526160398,"mc":[{"id":"1.188136695","rc":[{"batb":[[0,2.02,35.57],[1,2,4],[2,1.25,914.87]],"ltp":2.2,"tv":2.8,"id":5300737},{"batl":[[0,1.99,60.31],[1,2,30],[2,990,2.2]],"ltp":1.83,"tv":23.36,"id":2497008}]}]}
{"op":"mcm","clk":"4293114182","pt":1632526497886,"mc":[{"id":"1.188136695","rc":[{"batb":[[0,1.87,3]],"ltp":1.83,"tv":23.36,"id":2497008}]}]}
{"op":"mcm","clk":"4293124802","pt":1632526648467,"mc":[{"id":"1.188136695","rc":[{"batl":[[0,2.16,85.71],[1,2.24,25],[2,11,5]],"ltp":2.2,"tv":2.8,"id":5300737},{"batb":[[0,1.5,455.8]],"batl":[[0,1.98,3],[1,1.99,60.31],[2,2,30]],"ltp":1.83,"tv":23.36,"id":2497008}]}]}
{"op":"mcm","clk":"4293127809","pt":1632526686740,"mc":[{"id":"1.188136695","rc":[{"batl":[[0,1.98,63.62],[1,2,25],[2,990,2.2]],"ltp":1.83,"tv":23.36,"id":2497008}]}]}
{"op":"mcm","clk":"4293130416","pt":1632526725080,"mc":[{"id":"1.188136695","rc":[{"batb":[[0,1.51,12.86],[1,1.5,455.8],[2,1.12,1237.68]],"ltp":1.83,"tv":23.36,"id":2497008}]}]}
{"op":"mcm","clk":"4293141801","pt":1632526894612,"mc":[{"id":"1.188136695","rc":[{"batb":[[0,2.04,42.86],[1,2.02,35.57],[2,2,4]],"batl":[[0,2.14,32.57],[1,2.16,85.71],[2,2.24,25]],"ltp":2.2,"tv":2.8,"id":5300737},{"batb":[[0,1.87,41.14],[1,1.51,12.86],[2,1.5,455.8]],"batl":[[0,1.97,51.43],[1,1.98,63.62],[2,2,25]],"ltp":1.83,"tv":23.36,"id":2497008}]}]}
{"op":"mcm","clk":"4293141843","pt":1632526895334,"mc":[{"id":"1.188136695","rc":[{"batb":[[1,1.52,376.42],[2,1.51,12.86]],"ltp":1.83,"tv":23.36,"id":2497008}]}]}
{"op":"mcm","clk":"4293143987","pt":1632526932747,"mc":[{"id":"1.188136695","rc":[{"batb":[[0,2.04,63.03],[1,2,4],[2,1.25,914.87]],"ltp":2.2,"tv":2.8,"id":5300737},{"batb":[[1,1.51,12.86],[2,1.12,1237.68]],"batl":[[0,1.97,78.7],[1,1.98,3]],"ltp":1.83,"tv":23.36,"id":2497008}]}]}
{"op":"mcm","clk":"4293146919","pt":1632526977029,"mc":[{"id":"1.188136695","rc":[{"batb":[[1,1.12,1237.68],[2,1.11,2626.21]],"ltp":1.83,"tv":23.36,"id":2497008}]}]}
{"op":"mcm","clk":"4293152439","pt":1632527065350,"mc":[{"id":"1.188136695","rc":[{"batl":[[0,1.96,67.49],[1,1.97,51.43],[2,1.98,3]],"ltp":1.83,"tv":23.36,"id":2497008}]}]}
{"op":"mcm","clk":"4293153336","pt":1632527080270,"mc":[{"id":"1.188136695","rc":[{"batb":[[0,2.04,244.21]],"ltp":2.2,"tv":2.8,"id":5300737}]}]}
{"op":"mcm","clk":"4293162193","pt":1632527235210,"mc":[{"id":"1.188136695","rc":[{"batl":[[0,1.95,33.43],[1,1.96,67.49]],"ltp":1.83,"tv":23.36,"id":2497008}]}]}
{"op":"mcm","clk":"4293179279","pt":1632527284182,"mc":[{"id":"1.188136695","rc":[{"batb":[[0,2.04,42.86]],"ltp":2.2,"tv":2.8,"id":5300737},{"batl":[[1,1.98,3],[2,2,25]],"ltp":1.83,"tv":23.36,"id":2497008}]}]}
{"op":"mcm","clk":"4293181806","pt":1632527327731,"mc":[{"id":"1.188136695","rc":[{"batb":[[0,2.04,244.21]],"ltp":2.2,"tv":2.8,"id":5300737}]}]}
{"op":"mcm","clk":"4293185649","pt":1632527404812,"mc":[{"id":"1.188136695","rc":[{"batl":[[0,1.98,3],[1,2,25],[2,990,2.2]],"ltp":1.83,"tv":23.36,"id":2497008}]}]}
{"op":"mcm","clk":"4293185663","pt":1632527405016,"mc":[{"id":"1.188136695","rc":[{"batl":[[0,1.96,42],[1,1.97,67.15],[2,1.98,3]],"ltp":1.83,"tv":23.36,"id":2497008}]}]}
{"op":"mcm","clk":"4293189375","pt":1632527478438,"mc":[{"id":"1.188136695","rc":[{"batl":[[0,1.96,109.49],[1,1.98,3],[2,2,25]],"ltp":1.83,"tv":23.36,"id":2497008}]}]}
{"op":"mcm","clk":"4293192997","pt":1632527555441,"mc":[{"id":"1.188136695","rc":[{"batb":[[0,1.88,17.49],[1,1.87,41.14],[2,1.12,1237.68]],"ltp":1.83,"tv":23.36,"id":2497008}]}]}
{"op":"mcm","clk":"4293193782","pt":1632527575179,"mc":[{"id":"1.188136695","rc":[{"batb":[[0,1.88,50.92],[1,1.12,1237.68],[2,1.11,2626.21]],"ltp":1.83,"tv":23.36,"id":2497008}]}]}
{"op":"mcm","clk":"4293213114","pt":1632527960625,"mc":[{"id":"1.188136695","rc":[{"trd":[[2.04,6.91]],"batb":[[0,2.04,240.75]],"ltp":2.04,"tv":9.71,"id":5300737}],"tv":33.07}]}
{"op":"mcm","clk":"4293225070","pt":1632528180033,"mc":[{"id":"1.188136695","rc":[{"batb":[[0,2.04,101.06]],"ltp":2.04,"tv":9.71,"id":5300737}]}]}
{"op":"mcm","clk":"4293229292","pt":1632528265095,"mc":[{"id":"1.188136695","rc":[{"batb":[[0,2.04,106.2]],"ltp":2.04,"tv":9.71,"id":5300737}]}]}
{"op":"mcm","clk":"4293249110","pt":1632528626485,"mc":[{"id":"1.188136695","rc":[{"trd":[[2.04,10.91]],"batb":[[0,2.04,104.21],[1,1.25,914.87],[2,1.12,1237.68]],"ltp":2.04,"tv":13.7,"id":5300737},{"batl":[[1,2,25],[2,990,2.2]],"ltp":1.83,"tv":23.36,"id":2497008}],"tv":37.07}]}
{"op":"mcm","clk":"4293252184","pt":1632528679439,"mc":[{"id":"1.188136695","rc":[{"batb":[[0,2.04,42.55]],"ltp":2.04,"tv":13.7,"id":5300737}]}]}
{"op":"mcm","clk":"4293357994","pt":1632530400770,"mc":[{"id":"1.188136695","rc":[{"trd":[[2.04,153.46]],"batb":[[0,1.73,974.85]],"ltp":2.04,"tv":156.25,"id":5300737},{"trd":[[1.96,59.81]],"batl":[[0,1.96,49.68]],"ltp":1.96,"tv":83.17,"id":2497008}],"tv":239.42}]}
{"op":"mcm","clk":"4293358017","pt":1632530401281,"mc":[{"id":"1.188136695","rc":[{"batl":[[0,1.99,27.68]],"ltp":1.96,"tv":83.17,"id":2497008}]}]}
{"op":"mcm","clk":"4293358096","pt":1632530402780,"mc":[{"id":"1.188136695","rc":[{"batb":[[0,2,32.57],[1,1.73,974.85],[2,1.25,914.87]],"batl":[[0,2.14,84]],"ltp":2.04,"tv":156.25,"id":5300737},{"batb":[[0,1.88,103.21]],"batl":[[1,2,59.28]],"ltp":1.96,"tv":83.17,"id":2497008}]}]}
{"op":"mcm","clk":"4293358128","pt":1632530403293,"mc":[{"id":"1.188136695","rc":[{"batl":[[0,2,59.28],[1,990,2.2],[2,990,0]],"ltp":1.96,"tv":83.17,"id":2497008}]}]}
{"op":"mcm","clk":"4293362694","pt":1632530479464,"mc":[{"id":"1.188136695","rc":[{"batb":[[0,2,722.6],[1,1.25,914.87],[2,1.12,1237.68]],"ltp":2.04,"tv":156.25,"id":5300737},{"batl":[[0,2,97.67]],"ltp":1.96,"tv":83.17,"id":2497008}]}]}
{"op":"mcm","clk":"4293365383","pt":1632530522761,"mc":[{"id":"1.188136695","rc":[{"batb":[[0,2,32.57]],"ltp":2.04,"tv":156.25,"id":5300737}]}]}
{"op":"mcm","clk":"4293365409","pt":1632530523070,"mc":[{"id":"1.188136695","rc":[{"batb":[[0,2,216.35]],"ltp":2.04,"tv":156.25,"id":5300737}]}]}
{"op":"mcm","clk":"4293365753","pt":1632530528484,"mc":[{"id":"1.188136695","rc":[{"batb":[[0,2,664.7]],"ltp":2.04,"tv":156.25,"id":5300737}]}]}
{"op":"mcm","clk":"4293379087","pt":1632530743260,"mc":[{"id":"1.188136695","rc":[{"batb":[[0,1.89,17.49],[1,1.88,85.71],[2,1.12,1237.68]],"ltp":1.96,"tv":83.17,"id":2497008}]}]}
{"op":"mcm","clk":"4293383659","pt":1632530823129,"mc":[{"id":"1.188136695","rc":[{"batb":[[0,1.9,67.71],[1,1.89,17.49]],"ltp":1.96,"tv":83.17,"id":2497008}]}]}
{"op":"mcm","clk":"4293387020","pt":1632530879761,"mc":[{"id":"1.188136695","rc":[{"batb":[[0,2,568.43]],"ltp":2.04,"tv":156.25,"id":5300737},{"trd":[[1.9,17.35]],"batb":[[0,1.9,59.04]],"batl":[[0,2,59.28]],"ltp":1.9,"tv":100.51,"id":2497008}],"tv":256.77}]}
{"op":"mcm","clk":"4293387381","pt":1632530886630,"mc":[{"id":"1.188136695","rc":[{"batb":[[0,2,160.2]],"ltp":2.04,"tv":156.25,"id":5300737}]}]}
{"op":"mcm","clk":"4293387670","pt":1632530892049,"mc":[{"id":"1.188136695","rc":[{"batb":[[0,2,650.4]],"ltp":2.04,"tv":156.25,"id":5300737}]}]}
{"op":"mcm","clk":"4293389272","pt":1632530922804,"mc":[{"id":"1.188136695","rc":[{"batl":[[0,2.16,85.71],[1,2.24,25],[2,11,5]],"ltp":2.04,"tv":156.25,"id":5300737}]}]}
{"op":"mcm","clk":"4293389309","pt":1632530923317,"mc":[{"id":"1.188136695","rc":[{"batl":[[0,2.1,49.71],[1,2.16,85.71],[2,2.24,25]],"ltp":2.04,"tv":156.25,"id":5300737},{"batb":[[0,1.9,67.61]],"ltp":1.9,"tv":100.51,"id":2497008}]}]}
{"op":"mcm","clk":"4293392275","pt":1632530978972,"mc":[{"id":"1.188136695","rc":[{"trd":[[2.1,14.78]],"batl":[[0,2.1,42.32]],"ltp":2.1,"tv":171.03,"id":5300737}],"tv":271.55}]}
{"op":"mcm","clk":"4293393000","pt":1632530992787,"mc":[{"id":"1.188136695","rc":[{"batb":[[0,1.9,59.04]],"ltp":1.9,"tv":100.51,"id":2497008}]}]}
{"op":"mcm","clk":"4293393018","pt":1632530993099,"mc":[{"id":"1.188136695","rc":[{"batb":[[0,2,660.69]],"ltp":2.1,"tv":171.03,"id":5300737},{"batl":[[0,2,66.14]],"ltp":1.9,"tv":100.51,"id":2497008}]}]}
{"op":"mcm","clk":"4293400841","pt":1632531159437,"mc":[{"id":"1.188136695","rc":[{"batl":[[0,1.98,90],[1,2,66.14],[2,990,2.2]],"ltp":1.9,"tv":100.51,"id":2497008}]}]}
{"op":"mcm","clk":"4293401720","pt":1632531178159,"mc":[{"id":"1.188136695","rc":[{"batb":[[0,2,118.97]],"ltp":2.1,"tv":171.03,"id":5300737}]}]}
{"op":"mcm","clk":"4293402061","pt":1632531183353,"mc":[{"id":"1.188136695","rc":[{"batb":[[0,2,647.61]],"ltp":2.1,"tv":171.03,"id":5300737}]}]}
{"op":"mcm","clk":"4293404925","pt":1632531243063,"mc":[{"id":"1.188136695","rc":[{"batl":[[1,1.99,34.28],[2,2,25]],"ltp":1.9,"tv":100.51,"id":2497008}]}]}
{"op":"mcm","clk":"4293416737","pt":1632531500602,"mc":[{"id":"1.188136695","rc":[{"batb":[[0,2,118.97]],"ltp":2.1,"tv":171.03,"id":5300737}]}]}
{"op":"mcm","clk":"4293417030","pt":1632531505735,"mc":[{"id":"1.188136695","rc":[{"batb":[[0,2,647.61]],"ltp":2.1,"tv":171.03,"id":5300737}]}]}
{"op":"mcm","clk":"4293426297","pt":1632531678664,"mc":[{"id":"1.188136695","rc":[{"batb":[[2,1.87,15.82]],"ltp":1.9,"tv":100.51,"id":2497008}]}]}
{"op":"mcm","clk":"4293426470","pt":1632531681449,"mc":[{"id":"1.188136695","rc":[{"batb":[[0,2,118.97]],"ltp":2.1,"tv":171.03,"id":5300737}]}]}
{"op":"mcm","clk":"4293426766","pt":1632531686752,"mc":[{"id":"1.188136695","rc":[{"batb":[[0,2,647.61]],"ltp":2.1,"tv":171.03,"id":5300737}]}]}
{"op":"mcm","clk":"4293431969","pt":1632531783315,"mc":[{"id":"1.188136695","rc":[{"batb":[[0,2,118.97]],"ltp":2.1,"tv":171.03,"id":5300737}]}]}
{"op":"mcm","clk":"4293432344","pt":1632531788696,"mc":[{"id":"1.188136695","rc":[{"batb":[[0,2,647.61]],"ltp":2.1,"tv":171.03,"id":5300737}]}]}
{"op":"mcm","clk":"4293438355","pt":1632531908601,"mc":[{"id":"1.188136695","rc":[{"batb":[[0,2,118.96]],"ltp":2.1,"tv":171.03,"id":5300737}]}]}
{"op":"mcm","clk":"4293438669","pt":1632531913683,"mc":[{"id":"1.188136695","rc":[{"batb":[[0,2,42.86]],"ltp":2.1,"tv":171.03,"id":5300737}]}]}
{"op":"mcm","clk":"4293438682","pt":1632531913888,"mc":[{"id":"1.188136695","rc":[{"batb":[[0,2,647.61]],"ltp":2.1,"tv":171.03,"id":5300737}]}]}
{"op":"mcm","clk":"4293443587","pt":1632532002821,"mc":[{"id":"1.188136695","rc":[{"batb":[[0,2,118.96]],"ltp":2.1,"tv":171.03,"id":5300737}]}]}
{"op":"mcm","clk":"4293443863","pt":1632532007942,"mc":[{"id":"1.188136695","rc":[{"batb":[[0,2,647.61]],"ltp":2.1,"tv":171.03,"id":5300737}]}]}
{"op":"mcm","clk":"4293449643","pt":1632532125671,"mc":[{"id":"1.188136695","rc":[{"batb":[[0,2,983.52]],"ltp":2.1,"tv":171.03,"id":5300737}]}]}
{"op":"mcm","clk":"4293456989","pt":1632532271295,"mc":[{"id":"1.188136695","rc":[{"batb":[[0,2,118.96]],"ltp":2.1,"tv":171.03,"id":5300737}]}]}
{"op":"mcm","clk":"4293457255","pt":1632532276470,"mc":[{"id":"1.188136695","rc":[{"batb":[[0,2,954.06]],"ltp":2.1,"tv":171.03,"id":5300737}]}]}
{"op":"mcm","clk":"4293490454","pt":1632532700333,"mc":[{"id":"1.188136695","rc":[{"batb":[[0,2,118.96]],"ltp":2.1,"tv":171.03,"id":5300737}]}]}
{"op":"mcm","clk":"4293490691","pt":1632532705532,"mc":[{"id":"1.188136695","rc":[{"batb":[[0,2,985.62]],"ltp":2.1,"tv":171.03,"id":5300737}]}]}
{"op":"mcm","clk":"4293504650","pt":1632532995824,"mc":[{"id":"1.188136695","rc":[{"batb":[[0,2,118.96]],"ltp":2.1,"tv":171.03,"id":5300737}]}]}
{"op":"mcm","clk":"4293504926","pt":1632533001152,"mc":[{"id":"1.188136695","rc":[{"batb":[[0,2,981.41]],"ltp":2.1,"tv":171.03,"id":5300737}]}]}
{"op":"mcm","clk":"4293512958","pt":1632533163536,"mc":[{"id":"1.188136695","rc":[{"batb":[[0,2,42.86]],"ltp":2.1,"tv":171.03,"id":5300737}]}]}
{"op":"mcm","clk":"4293512979","pt":1632533163900,"mc":[{"id":"1.188136695","rc":[{"batb":[[0,2,118.96]],"ltp":2.1,"tv":171.03,"id":5300737}]}]}
{"op":"mcm","clk":"4293513228","pt":1632533168826,"mc":[{"id":"1.188136695","rc":[{"batb":[[0,2,981.41]],"ltp":2.1,"tv":171.03,"id":5300737}]}]}
{"op":"mcm","clk":"4293526667","pt":1632533446306,"mc":[{"id":"1.188136695","rc":[{"batb":[[0,2,118.96]],"ltp":2.1,"tv":171.03,"id":5300737}]}]}
{"op":"mcm","clk":"4293526944","pt":1632533451822,"mc":[{"id":"1.188136695","rc":[{"batb":[[0,2,986.32]],"ltp":2.1,"tv":171.03,"id":5300737}]}]}
{"op":"mcm","clk":"4293535939","pt":1632533635450,"mc":[{"id":"1.188136695","rc":[{"batb":[[0,2,118.96]],"ltp":2.1,"tv":171.03,"id":5300737}]}]}
{"op":"mcm","clk":"4293536209","pt":1632533640674,"mc":[{"id":"1.188136695","rc":[{"batb":[[0,2,986.32]],"ltp":2.1,"tv":171.03,"id":5300737}]}]}
{"op":"mcm","clk":"4293546172","pt":1632533829473,"mc":[{"id":"1.188136695","rc":[{"batb":[[0,2,42.86]],"ltp":2.1,"tv":171.03,"id":5300737}]}]}
{"op":"mcm","clk":"4293546203","pt":1632533829886,"mc":[{"id":"1.188136695","rc":[{"batb":[[0,2,118.96]],"ltp":2.1,"tv":171.03,"id":5300737}]}]}
{"op":"mcm","clk":"4293546483","pt":1632533835095,"mc":[{"id":"1.188136695","rc":[{"batb":[[0,2,986.32]],"ltp":2.1,"tv":171.03,"id":5300737}]}]}
{"op":"mcm","clk":"4293551297","pt":1632533920046,"mc":[{"id":"1.188136695","rc":[{"batb":[[0,1.91,17.49],[1,1.9,59.04]],"ltp":1.9,"tv":100.51,"id":2497008}]}]}
{"op":"mcm","clk":"4293552322","pt":1632533937754,"mc":[{"id":"1.188136695","rc":[{"batb":[[0,2,42.86]],"ltp":2.1,"tv":171.03,"id":5300737}]}]}
{"op":"mcm","clk":"4293552347","pt":1632533938160,"mc":[{"id":"1.188136695","rc":[{"batb":[[0,2,1321.87]],"ltp":2.1,"tv":171.03,"id":5300737}]}]}
{"op":"mcm","clk":"4293558374","pt":1632534044726,"mc":[{"id":"1.188136695","rc":[{"batb":[[1,1.87,15.82],[2,1.12,1237.68]],"ltp":1.9,"tv":100.51,"id":2497008}]}]}
{"op":"mcm","clk":"4293558389","pt":1632534044932,"mc":[{"id":"1.188136695","rc":[{"batb":[[0,1.92,32.57],[1,1.91,17.49],[2,1.87,15.82]],"ltp":1.9,"tv":100.51,"id":2497008}]}]}
{"op":"mcm","clk":"4293560269","pt":1632534079690,"mc":[{"id":"1.188136695","rc":[{"trd":[[1.92,18.33]],"batb":[[0,1.92,23.41]],"ltp":1.92,"tv":118.84,"id":2497008}],"tv":289.87}]}
{"op":"mcm","clk":"4293563514","pt":1632534145100,"mc":[{"id":"1.188136695","rc":[{"batb":[[0,2,1269.73]],"ltp":2.1,"tv":171.03,"id":5300737}]}]}
{"op":"mcm","clk":"4293563947","pt":1632534154722,"mc":[{"id":"1.188136695","rc":[{"batl":[[1,2,25],[2,990,2.2]],"ltp":1.92,"tv":118.84,"id":2497008}]}]}
{"op":"mcm","clk":"4293563975","pt":1632534155131,"mc":[{"id":"1.188136695","rc":[{"batb":[[0,1.92,33.69]],"batl":[[0,1.98,114]],"ltp":1.92,"tv":118.84,"id":2497008}]}]}
{"op":"mcm","clk":"4293566680","pt":1632534207550,"mc":[{"id":"1.188136695","rc":[{"batb":[[0,2,103.92]],"ltp":2.1,"tv":171.03,"id":5300737}]}]}
{"op":"mcm","clk":"4293566935","pt":1632534212710,"mc":[{"id":"1.188136695","rc":[{"batb":[[0,2,42.86]],"ltp":2.1,"tv":171.03,"id":5300737}]}]}
{"op":"mcm","clk":"4293566949","pt":1632534212916,"mc":[{"id":"1.188136695","rc":[{"batb":[[0,2,1320.69]],"ltp":2.1,"tv":171.03,"id":5300737}]}]}
{"op":"mcm","clk":"4293571346","pt":1632534310490,"mc":[{"id":"1.188136695","rc":[{"batb":[[0,2,103.92]],"ltp":2.1,"tv":171.03,"id":5300737}]}]}
{"op":"mcm","clk":"4293571588","pt":1632534315509,"mc":[{"id":"1.188136695","rc":[{"batb":[[0,2,1320.69]],"ltp":2.1,"tv":171.03,"id":5300737}]}]}
{"op":"mcm","clk":"4293581208","pt":1632534538257,"mc":[{"id":"1.188136695","rc":[{"batb":[[0,2,103.92]],"ltp":2.1,"tv":171.03,"id":5300737}]}]}
{"op":"mcm","clk":"4293581429","pt":1632534543284,"mc":[{"id":"1.188136695","rc":[{"batb":[[0,2,1320.69]],"ltp":2.1,"tv":171.03,"id":5300737}]}]}
{"op":"mcm","clk":"4293591222","pt":1632534816720,"mc":[{"id":"1.188136695","rc":[{"batb":[[0,2,42.86]],"ltp":2.1,"tv":171.03,"id":5300737}]}]}
{"op":"mcm","clk":"4293591245","pt":1632534817238,"mc":[{"id":"1.188136695","rc":[{"batb":[[0,2,103.92]],"ltp":2.1,"tv":171.03,"id":5300737}]}]}
{"op":"mcm","clk":"4293591419","pt":1632534822335,"mc":[{"id":"1.188136695","rc":[{"batb":[[0,2,1320.69]],"ltp":2.1,"tv":171.03,"id":5300737}]}]}
{"op":"mcm","clk":"4293602967","pt":1632535134331,"mc":[{"id":"1.188136695","rc":[{"batb":[[0,2,103.92]],"ltp":2.1,"tv":171.03,"id":5300737}]}]}
{"op":"mcm","clk":"4293603171","pt":1632535139727,"mc":[{"id":"1.188136695","rc":[{"batb":[[0,2,1320.69]],"ltp":2.1,"tv":171.03,"id":5300737}]}]}
{"op":"mcm","clk":"4293610732","pt":1632535294360,"mc":[{"id":"1.188136695","rc":[{"batb":[[0,2,103.92]],"ltp":2.1,"tv":171.03,"id":5300737}]}]}
{"op":"mcm","clk":"4293611036","pt":1632535299758,"mc":[{"id":"1.188136695","rc":[{"batb":[[0,2,42.86]],"ltp":2.1,"tv":171.03,"id":5300737}]}]}
{"op":"mcm","clk":"4293611046","pt":1632535299863,"mc":[{"id":"1.188136695","rc":[{"batb":[[0,2,1320.69]],"ltp":2.1,"tv":171.03,"id":5300737}]}]}
{"op":"mcm","clk":"4293635434","pt":1632535939677,"mc":[{"id":"1.188136695","rc":[{"batb":[[0,2,103.92]],"ltp":2.1,"tv":171.03,"id":5300737}]}]}
{"op":"mcm","clk":"4293635678","pt":1632535945175,"mc":[{"id":"1.188136695","rc":[{"batb":[[0,2,1320.69]],"ltp":2.1,"tv":171.03,"id":5300737}]}]}
{"op":"mcm","clk":"4293639440","pt":1632536053819,"mc":[{"id":"1.188136695","rc":[{"batb":[[0,2,42.86]],"ltp":2.1,"tv":171.03,"id":5300737}]}]}
{"op":"mcm","clk":"4293639447","pt":1632536053919,"mc":[{"id":"1.188136695","rc":[{"batb":[[0,2,103.92]],"ltp":2.1,"tv":171.03,"id":5300737}]}]}
{"op":"mcm","clk":"4293639616","pt":1632536059609,"mc":[{"id":"1.188136695","rc":[{"batb":[[0,2,1321.39]],"ltp":2.1,"tv":171.03,"id":5300737}]}]}
{"op":"mcm","clk":"4293640654","pt":1632536088729,"mc":[{"id":"1.188136695","rc":[{"batb":[[0,2,42.86]],"ltp":2.1,"tv":171.03,"id":5300737}]}]}
{"op":"mcm","clk":"4293640657","pt":1632536088832,"mc":[{"id":"1.188136695","rc":[{"batb":[[0,2,103.92]],"ltp":2.1,"tv":171.03,"id":5300737}]}]}
{"op":"mcm","clk":"4293640725","pt":1632536090739,"mc":[{"id":"1.188136695","rc":[{"batb":[[0,2,61.06]],"ltp":2.1,"tv":171.03,"id":5300737},{"batl":[[0,1.98,90]],"ltp":1.92,"tv":118.84,"id":2497008}]}]}
{"op":"mcm","clk":"4293640732","pt":1632536090943,"mc":[{"id":"1.188136695","rc":[{"batb":[[1,1.99,4],[2,1.98,4]],"ltp":2.1,"tv":171.03,"id":5300737},{"batb":[[2,1.9,4]],"ltp":1.92,"tv":118.84,"id":2497008}]}]}
{"op":"mcm","clk":"4293641236","pt":1632536106778,"mc":[{"id":"1.188136695","rc":[{"batb":[[0,2,104.77],[2,1.25,914.87]],"ltp":2.1,"tv":171.03,"id":5300737},{"batl":[[0,1.98,114.86]],"ltp":1.92,"tv":118.84,"id":2497008}]}]}
{"op":"mcm","clk":"4293641600","pt":1632536117701,"mc":[{"id":"1.188136695","rc":[{"batb":[[0,2,61.06]],"batl":[[0,2.16,85.71],[1,2.24,25],[2,990,2.2]],"ltp":2.1,"tv":171.03,"id":5300737},{"batb":[[0,1.91,17.49],[1,1.9,4],[2,1.87,15.82]],"batl":[[0,1.98,90]],"ltp":1.92,"tv":118.84,"id":2497008}]}]}
{"op":"mcm","clk":"4293643117","pt":1632536164625,"mc":[{"id":"1.188136695","rc":[{"batb":[[0,2,103.92]],"batl":[[0,2.1,42],[1,2.16,85.71],[2,2.24,25]],"ltp":2.1,"tv":171.03,"id":5300737},{"batb":[[0,1.92,34.28],[1,1.91,17.49],[2,1.9,4]],"batl":[[0,1.98,117.43]],"ltp":1.92,"tv":118.84,"id":2497008}]}]}
{"op":"mcm","clk":"4293643779","pt":1632536182371,"mc":[{"id":"1.188136695","rc":[{"batl":[[0,1.98,90],[1,1.99,32.57],[2,2,25]],"ltp":1.92,"tv":118.84,"id":2497008}]}]}
{"op":"mcm","clk":"4293647350","pt":1632536280904,"mc":[{"id":"1.188136695","rc":[{"batb":[[0,2,42.86]],"ltp":2.1,"tv":171.03,"id":5300737}]}]}
{"op":"mcm","clk":"4293760803","pt":1632538881243,"mc":[{"id":"1.188136695","rc":[{"batb":[[1,1.25,914.87],[2,1.12,1237.68]],"ltp":2.1,"tv":171.03,"id":5300737},{"batb":[[2,1.12,1237.68]],"ltp":1.92,"tv":118.84,"id":2497008}]}]}
{"op":"mcm","clk":"4293764980","pt":1632538981094,"mc":[{"id":"1.188136695","rc":[{"batb":[[0,2.04,16.48],[1,2,42.86],[2,1.25,914.87]],"ltp":2.1,"tv":171.03,"id":5300737},{"batb":[[2,1.87,20.25]],"ltp":1.92,"tv":118.84,"id":2497008}]}]}
{"op":"mcm","clk":"4293865651","pt":1632541250073,"mc":[{"id":"1.188136695","rc":[{"batb":[[1,1.25,914.87],[2,1.12,1237.68]],"ltp":2.1,"tv":171.03,"id":5300737},{"batl":[[1,2,25],[2,990,2.2]],"ltp":1.92,"tv":118.84,"id":2497008}]}]}
{"op":"mcm","clk":"4293869224","pt":1632541330768,"mc":[{"id":"1.188136695","rc":[{"batb":[[1,2,44.57],[2,1.25,914.87]],"ltp":2.1,"tv":171.03,"id":5300737},{"batl":[[1,1.99,35.14],[2,2,25]],"ltp":1.92,"tv":118.84,"id":2497008}]}]}
{"op":"mcm","clk":"4294048504","pt":1632544708230,"mc":[{"id":"1.188136695","rc":[{"trd":[[1.92,21.75]],"batb":[[0,1.92,32.57]],"ltp":1.92,"tv":122.27,"id":2497008}],"tv":293.3}]}
{"op":"mcm","clk":"4294108068","pt":1632546014055,"mc":[{"id":"1.188136695","rc":[{"batl":[[0,2.08,6.12],[1,2.1,42],[2,2.16,85.71]],"ltp":2.1,"tv":171.03,"id":5300737}]}]}
{"op":"mcm","clk":"4294161931","pt":1632547060679,"mc":[{"id":"1.188136695","rc":[{"trd":[[1.92,51]],"batb":[[0,1.92,17.95]],"ltp":1.92,"tv":151.52,"id":2497008}],"tv":322.55}]}
{"op":"mcm","clk":"4294165290","pt":1632547134764,"mc":[{"id":"1.188136695","rc":[{"batb":[[1,1.25,914.87],[2,1.12,1237.68]],"ltp":2.1,"tv":171.03,"id":5300737},{"batb":[[0,1.91,17.49],[1,1.87,20.25],[2,1.12,1237.68]],"batl":[[1,2,25],[2,990,2.2]],"ltp":1.92,"tv":151.52,"id":2497008}]}]}
{"op":"mcm","clk":"4294165312","pt":1632547135174,"mc":[{"id":"1.188136695","rc":[{"batb":[[1,2.02,36],[2,1.25,914.87]],"batl":[[1,2.1,33.43]],"ltp":2.1,"tv":171.03,"id":5300737},{"batb":[[0,1.91,50.06]],"batl":[[0,1.98,122.57]],"ltp":1.92,"tv":151.52,"id":2497008}]}]}
{"op":"mcm","clk":"4294241023","pt":1632548429638,"mc":[{"id":"1.188136695","rc":[{"trd":[[2.04,156.27]],"batb":[[0,2.04,15.08]],"ltp":2.04,"tv":173.84,"id":5300737}],"tv":325.36}]}
{"op":"mcm","clk":"4294283154","pt":1632548927992,"mc":[{"id":"1.188136695","rc":[{"batl":[[2,2.3,5.85]],"ltp":1.92,"tv":151.52,"id":2497008}]}]}
{"op":"mcm","clk":"4294283775","pt":1632548939183,"mc":[{"id":"1.188136695","rc":[{"batb":[[2,1.6,7.31]],"ltp":1.92,"tv":151.52,"id":2497008}]}]}
{"op":"mcm","clk":"4294301802","pt":1632549314427,"mc":[{"id":"1.188136695","rc":[{"batb":[[2,1.31,35.39]],"ltp":2.04,"tv":173.84,"id":5300737}]}]}
{"op":"mcm","clk":"4294322075","pt":1632549717341,"mc":[{"id":"1.188136695","rc":[{"trd":[[2.04,161.74]],"batb":[[0,2.04,12.34]],"ltp":2.04,"tv":179.31,"id":5300737}],"tv":330.83}]}
{"op":"mcm","clk":"4294352872","pt":1632550176729,"mc":[{"id":"1.188136695","rc":[{"trd":[[2.04,181.74]],"batb":[[0,2.04,2.34]],"ltp":2.04,"tv":199.31,"id":5300737},{"batb":[[1,1.6,7.31],[2,1.28,39.18]],"ltp":1.92,"tv":151.52,"id":2497008}],"tv":350.84}]}
{"op":"mcm","clk":"4294352888","pt":1632550176935,"mc":[{"id":"1.188136695","rc":[{"batb":[[0,2.02,36],[1,1.31,35.39],[2,1.25,914.87]],"ltp":2.04,"tv":199.31,"id":5300737}]}]}
{"op":"mcm","clk":"4294417234","pt":1632550954424,"mc":[{"id":"1.188136695","rc":[{"batl":[[0,2.04,292.53],[1,2.08,6.12],[2,2.1,33.43]],"ltp":2.04,"tv":199.31,"id":5300737}]}]}
{"op":"mcm","clk":"4294418900","pt":1632550977444,"mc":[{"id":"1.188136695","rc":[{"trd":[[2.04,189.71]],"batl":[[0,2.04,288.54]],"ltp":2.04,"tv":207.28,"id":5300737}],"tv":358.81}]}
{"op":"mcm","clk":"4294600555","pt":1632553545672,"mc":[{"id":"1.188136695","rc":[{"batb":[[0,1.91,1593.52]],"ltp":1.92,"tv":151.52,"id":2497008}]}]}
{"op":"mcm","clk":"4294601144","pt":1632553551807,"mc":[{"id":"1.188136695","rc":[{"batb":[[0,1.31,35.39],[1,1.25,914.87],[2,1.12,1237.68]],"ltp":2.04,"tv":207.28,"id":5300737},{"batl":[[0,1.98,90]],"ltp":1.92,"tv":151.52,"id":2497008}]}]}
{"op":"mcm","clk":"4294601173","pt":1632553552126,"mc":[{"id":"1.188136695","rc":[{"batb":[[0,1.63,2261.37],[1,1.31,35.39],[2,1.25,914.87]],"ltp":2.04,"tv":207.28,"id":5300737}]}]}
{"op":"mcm","clk":"4294605929","pt":1632553598771,"mc":[{"id":"1.188136695","rc":[{"batb":[[0,2.02,32.57],[1,1.63,2261.37],[2,1.31,35.39]],"ltp":2.04,"tv":207.28,"id":5300737},{"batl":[[0,1.98,126]],"ltp":1.92,"tv":151.52,"id":2497008}]}]}
{"op":"mcm","clk":"4294605946","pt":1632553598975,"mc":[{"id":"1.188136695","rc":[{"batb":[[1,1.31,35.39],[2,1.25,914.87]],"ltp":2.04,"tv":207.28,"id":5300737}]}]}
{"op":"mcm","clk":"4294626980","pt":1632553818794,"mc":[{"id":"1.188136695","rc":[{"batb":[[0,1.91,50.06]],"ltp":1.92,"tv":151.52,"id":2497008}]}]}
{"op":"mcm","clk":"4294627130","pt":1632553820099,"mc":[{"id":"1.188136695","rc":[{"batl":[[2,2.16,85.71]],"ltp":2.04,"tv":207.28,"id":5300737},{"batb":[[0,1.91,17.49]],"ltp":1.92,"tv":151.52,"id":2497008}]}]}
{"op":"mcm","clk":"4294627510","pt":1632553823395,"mc":[{"id":"1.188136695","rc":[{"batb":[[0,1.91,1254.41]],"ltp":1.92,"tv":151.52,"id":2497008}]}]}
{"op":"mcm","clk":"4294638549","pt":1632553928840,"mc":[{"id":"1.188136695","rc":[{"batl":[[2,2.1,35.14]],"ltp":2.04,"tv":207.28,"id":5300737},{"batb":[[0,1.91,1290.41]],"ltp":1.92,"tv":151.52,"id":2497008}]}]}
{"op":"mcm","clk":"4294689432","pt":1632554358357,"mc":[{"id":"1.188136695","rc":[{"trd":[[2.04,478.25]],"batl":[[0,2.08,6.12],[1,2.1,35.14],[2,2.16,85.71]],"ltp":2.04,"tv":495.83,"id":5300737},{"trd":[[1.96,360.13]],"batl":[[0,1.96,761.59],[1,1.98,126],[2,2,25]],"ltp":1.96,"tv":451.84,"id":2497008}],"tv":947.67}]}
{"op":"mcm","clk":"4294691356","pt":1632554376789,"mc":[{"id":"1.188136695","rc":[{"trd":[[2.08,6.12]],"batl":[[0,2.1,35.14],[1,2.16,85.71],[2,2.24,25]],"ltp":2.08,"tv":501.94,"id":5300737},{"trd":[[1.92,332.67]],"batb":[[0,1.91,53.49]],"batl":[[0,1.92,617.44]],"ltp":1.92,"tv":733.5,"id":2497008}],"tv":1235.45}]}
{"op":"mcm","clk":"4294691505","pt":1632554378505,"mc":[{"id":"1.188136695","rc":[{"trd":[[1.92,474.51]],"batl":[[0,1.92,546.52]],"ltp":1.92,"tv":875.34,"id":2497008}],"tv":1377.29}]}
{"op":"mcm","clk":"4294691551","pt":1632554379280,"mc":[{"id":"1.188136695","rc":[{"trd":[[1.92,1299.64]],"batl":[[0,1.92,133.96]],"ltp":1.92,"tv":1700.47,"id":2497008}],"tv":2202.41}]}
{"op":"mcm","clk":"4294691872","pt":1632554382708,"mc":[{"id":"1.188136695","rc":[{"batb":[[1,1.99,4],[2,1.98,4]],"ltp":2.08,"tv":501.94,"id":5300737},{"trd":[[1.92,1330.8]],"batb":[[1,1.9,4],[2,1.89,5]],"batl":[[0,1.92,118.38]],"ltp":1.92,"tv":1731.63,"id":2497008}],"tv":2233.58}]}
{"op":"mcm","clk":"4294692071","pt":1632554384478,"mc":[{"id":"1.188136695","rc":[{"batl":[[0,2.16,401.56],[1,2.24,25],[2,5.7,219.68]],"ltp":2.08,"tv":501.94,"id":5300737},{"batb":[[0,1.91,17.49]],"ltp":1.92,"tv":1731.63,"id":2497008}]}]}
{"op":"mcm","clk":"4294692144","pt":1632554385201,"mc":[{"id":"1.188136695","rc":[{"batl":[[0,2.16,85.71]],"ltp":2.08,"tv":501.94,"id":5300737}]}]}
{"op":"mcm","clk":"4294692373","pt":1632554387490,"mc":[{"id":"1.188136695","rc":[{"trd":[[1.91,34.99]],"batb":[[0,1.9,4],[1,1.89,5],[2,1.6,7.31]],"batl":[[0,1.91,100.88]],"ltp":1.91,"tv":1766.62,"id":2497008}],"tv":2268.57}]}
{"op":"mcm","clk":"4294693583","pt":1632554400819,"mc":[{"id":"1.188136695","rc":[{"batb":[[0,2.02,148.21],[2,1.31,35.39]],"ltp":2.08,"tv":501.94,"id":5300737},{"batb":[[1,1.6,7.31],[2,1.28,39.18]],"ltp":1.91,"tv":1766.62,"id":2497008}]}]}
{"op":"mcm","clk":"4294694473","pt":1632554409825,"mc":[{"id":"1.188136695","rc":[{"batb":[[0,2.02,32.57]],"ltp":2.08,"tv":501.94,"id":5300737},{"trd":[[1.9,25.35]],"batb":[[0,1.6,7.31],[1,1.28,39.18],[2,1.12,1237.68]],"batl":[[0,1.9,96.88],[1,1.97,61.78],[2,1.98,126]],"ltp":1.9,"tv":1774.62,"id":2497008}],"tv":2276.57}]}
{"op":"mcm","clk":"4294694480","pt":1632554409932,"mc":[{"id":"1.188136695","rc":[{"batb":[[0,1.61,1946.41],[1,1.6,7.31],[2,1.28,39.18]],"batl":[[1,1.98,126],[2,2,25]],"ltp":1.9,"tv":1774.62,"id":2497008}]}]}
{"op":"mcm","clk":"4294694641","pt":1632554411951,"mc":[{"id":"1.188136695","rc":[{"trd":[[2.1,17.78]],"ltp":2.1,"tv":504.94,"id":5300737},{"trd":[[1.9,28.66]],"batl":[[0,1.9,93.57]],"ltp":1.9,"tv":1777.93,"id":2497008}],"tv":2282.88}]}
{"op":"mcm","clk":"4294696824","pt":1632554434765,"mc":[{"id":"1.188136695","rc":[{"batl":[[0,1.98,126],[1,2,25],[2,2.3,5.85]],"ltp":1.9,"tv":1777.93,"id":2497008}]}]}
{"op":"mcm","clk":"4294696860","pt":1632554435178,"mc":[{"id":"1.188136695","rc":[{"trd":[[2.16,80.58]],"batl":[[0,2.16,5.13]],"ltp":2.16,"tv":585.52,"id":5300737},{"trd":[[1.86,93.57]],"ltp":1.86,"tv":1871.5,"id":2497008}],"tv":2457.03}]}
{"op":"mcm","clk":"4294700581","pt":1632554480736,"mc":[{"id":"1.188136695","rc":[{"batl":[[0,2.14,70.28],[1,2.16,5.13],[2,2.24,25]],"ltp":2.16,"tv":585.52,"id":5300737},{"batb":[[0,1.87,85.71],[1,1.61,1946.41],[2,1.6,7.31]],"ltp":1.86,"tv":1871.5,"id":2497008}]}]}
{"op":"mcm","clk":"4294709787","pt":1632554591286,"mc":[{"id":"1.188136695","rc":[{"batb":[[0,1.88,1588.17],[1,1.87,85.71]],"ltp":1.86,"tv":1871.5,"id":2497008}]}]}
{"op":"mcm","clk":"4294719710","pt":1632554701139,"mc":[{"id":"1.188136695","rc":[{"batl":[[0,2.14,171.37]],"ltp":2.16,"tv":585.52,"id":5300737},{"batb":[[0,1.89,58.28],[1,1.88,1588.17]],"ltp":1.86,"tv":1871.5,"id":2497008}]}]}
{"op":"mcm","clk":"4294728260","pt":1632554783751,"mc":[{"id":"1.188136695","rc":[{"batb":[[1,1.6,7.31],[2,1.28,39.18]],"ltp":1.86,"tv":1871.5,"id":2497008}]}]}
{"op":"mcm","clk":"4294728272","pt":1632554783858,"mc":[{"id":"1.188136695","rc":[{"batb":[[0,1.89,87.53]],"ltp":1.86,"tv":1871.5,"id":2497008}]}]}
{"op":"mcm","clk":"4294734663","pt":1632554842723,"mc":[{"id":"1.188136695","rc":[{"batb":[[0,2.04,292.53],[1,2.02,32.57],[2,1.99,4]],"ltp":2.16,"tv":585.52,"id":5300737}]}]}
{"op":"mcm","clk":"4294760989","pt":1632555108289,"mc":[{"id":"1.188136695","rc":[{"batb":[[0,1.9,42.86],[1,1.89,87.53],[2,1.6,7.31]],"ltp":1.86,"tv":1871.5,"id":2497008}]}]}
{"op":"mcm","clk":"4294764075","pt":1632555136136,"mc":[{"id":"1.188136695","rc":[{"batl":[[1,2.24,25],[2,5.7,219.68]],"ltp":2.16,"tv":585.52,"id":5300737}]}]}
{"op":"mcm","clk":"4294764631","pt":1632555140714,"mc":[{"id":"1.188136695","rc":[{"batl":[[0,2.14,101.09]],"ltp":2.16,"tv":585.52,"id":5300737},{"batb":[[1,1.89,29.25]],"ltp":1.86,"tv":1871.5,"id":2497008}]}]}
{"op":"mcm","clk":"4294764677","pt":1632555141135,"mc":[{"id":"1.188136695","rc":[{"batl":[[0,2.1,35.14]],"ltp":2.16,"tv":585.52,"id":5300737},{"batb":[[0,1.91,35.14],[1,1.9,42.86]],"ltp":1.86,"tv":1871.5,"id":2497008}]}]}
{"op":"mcm","clk":"4294769041","pt":1632555180671,"mc":[{"id":"1.188136695","rc":[{"batb":[[0,1.92,4.07],[1,1.91,35.14],[2,1.9,42.86]],"batl":[[0,1.96,3.12],[1,1.98,126],[2,2,25]],"ltp":1.86,"tv":1871.5,"id":2497008}]}]}
{"op":"mcm","clk":"4294770194","pt":1632555190009,"mc":[{"id":"1.188136695","rc":[{"batb":[[0,2.06,81.43],[1,2.04,292.53],[2,2.02,32.57]],"ltp":2.16,"tv":585.52,"id":5300737}]}]}
{"op":"mcm","clk":"4294772580","pt":1632555210730,"mc":[{"id":"1.188136695","rc":[{"batb":[[0,2.04,292.53],[1,2.02,32.57],[2,1.99,4]],"ltp":2.16,"tv":585.52,"id":5300737}]}]}
{"op":"mcm","clk":"4294772973","pt":1632555213759,"mc":[{"id":"1.188136695","rc":[{"trd":[[2.1,123.74],[2.12,11.94]],"batl":[[0,2.24,25],[1,5.7,219.68],[2,990,2.2]],"ltp":2.12,"tv":703.42,"id":5300737},{"trd":[[1.9,41.98],[1.91,70.13],[1.92,1334.87]],"batb":[[0,1.9,29.54],[1,1.6,7.31],[2,1.28,39.18]],"ltp":1.9,"tv":1924.04,"id":2497008}],"tv":2627.46}]}
{"op":"mcm","clk":"4294772992","pt":1632555213915,"mc":[{"id":"1.188136695","rc":[{"batl":[[0,2.22,487.43],[1,2.24,25],[2,5.7,219.68]],"ltp":2.12,"tv":703.42,"id":5300737}]}]}
{"op":"mcm","clk":"4294773188","pt":1632555215636,"mc":[{"id":"1.188136695","rc":[{"batb":[[1,1.99,4],[2,1.7,21.24]],"ltp":2.12,"tv":703.42,"id":5300737},{"batl":[[1,1.98,90]],"ltp":1.9,"tv":1924.04,"id":2497008}]}]}
{"op":"mcm","clk":"4294773290","pt":1632555216633,"mc":[{"id":"1.188136695","rc":[{"batb":[[0,2.06,34.28],[1,2.04,292.53],[2,1.99,4]],"batl":[[0,2.14,35.14],[1,2.22,487.43],[2,2.24,25]],"ltp":2.12,"tv":703.42,"id":5300737},{"batb":[[1,1.88,33.43],[2,1.6,7.31]],"batl":[[0,1.94,33.43],[1,1.96,3.12],[2,1.98,90]],"ltp":1.9,"tv":1924.04,"id":2497008}]}]}
{"op":"mcm","clk":"4294780624","pt":1632555284238,"mc":[{"id":"1.188136695","rc":[{"batl":[[1,2.24,25],[2,5.7,219.68]],"ltp":2.12,"tv":703.42,"id":5300737}]}]}
{"op":"mcm","clk":"4294813414","pt":1632555575740,"mc":[{"id":"1.188136695","rc":[{"trd":[[1.9,101.06]],"batb":[[0,1.88,33.43],[1,1.6,7.31],[2,1.36,21.76]],"batl":[[0,1.94,33.89]],"ltp":1.9,"tv":1983.11,"id":2497008}],"tv":2686.54}]}
{"op":"mcm","clk":"4294813437","pt":1632555575951,"mc":[{"id":"1.188136695","rc":[{"batb":[[0,1.88,1695.7]],"ltp":1.9,"tv":1983.11,"id":2497008}]}]}
{"op":"mcm","clk":"4294814250","pt":1632555583243,"mc":[{"id":"1.188136695","rc":[{"batl":[[2,1.98,60]],"ltp":1.9,"tv":1983.11,"id":2497008}]}]}
{"op":"mcm","clk":"4294815142","pt":1632555590761,"mc":[{"id":"1.188136695","rc":[{"batl":[[0,1.93,60.46],[1,1.94,33.43],[2,1.96,3.12]],"ltp":1.9,"tv":1983.11,"id":2497008}]}]}
{"op":"mcm","clk":"4294826569","pt":1632555691703,"mc":[{"id":"1.188136695","rc":[{"trd":[[1.88,135.28]],"batb":[[0,1.88,1628.06]],"ltp":1.88,"tv":2118.39,"id":2497008}],"tv":2821.82}]}
{"op":"mcm","clk":"4294826715","pt":1632555692788,"mc":[{"id":"1.188136695","rc":[{"batb":[[0,1.6,7.31],[1,1.36,21.76],[2,1.28,39.18]],"ltp":1.88,"tv":2118.39,"id":2497008}]}]}
{"op":"mcm","clk":"4294826749","pt":1632555692995,"mc":[{"id":"1.188136695","rc":[{"batb":[[0,1.67,625.36],[1,1.6,7.31],[2,1.36,21.76]],"ltp":1.88,"tv":2118.39,"id":2497008}]}]}
{"op":"mcm","clk":"4294831581","pt":1632555737568,"mc":[{"id":"1.188136695","rc":[{"batb":[[0,2.06,58.28]],"batl":[[0,2.22,664.23]],"ltp":2.12,"tv":703.42,"id":5300737},{"batb":[[0,1.86,42.86],[1,1.67,625.36],[2,1.6,7.31]],"batl":[[0,1.92,36],[1,1.93,60.46]],"ltp":1.88,"tv":2118.39,"id":2497008}]}]}
{"op":"mcm","clk":"4294834678","pt":1632555767448,"mc":[{"id":"1.188136695","rc":[{"batb":[[0,2.08,36],[1,2.06,28.52],[2,2.04,292.53]],"batl":[[0,2.16,32.57],[1,2.22,587.95],[2,2.24,25]],"ltp":2.12,"tv":703.42,"id":5300737},{"batb":[[0,1.82,84]],"ltp":1.88,"tv":2118.39,"id":2497008}]}]}
{"op":"mcm","clk":"4294839060","pt":1632555806684,"mc":[{"id":"1.188136695","rc":[{"batl":[[0,2.22,587.95],[1,2.24,25],[2,5.7,219.68]],"ltp":2.12,"tv":703.42,"id":5300737},{"batb":[[0,1.67,625.36],[1,1.6,7.31],[2,1.36,21.76]],"ltp":1.88,"tv":2118.39,"id":2497008}]}]}
{"op":"mcm","clk":"4294839086","pt":1632555806892,"mc":[{"id":"1.188136695","rc":[{"batb":[[1,2.04,292.53],[2,1.99,4]],"batl":[[0,2.2,61.71],[1,2.22,587.95],[2,2.24,25]],"ltp":2.12,"tv":703.42,"id":5300737},{"batb":[[0,1.86,43.71],[1,1.67,625.36],[2,1.6,7.31]],"ltp":1.88,"tv":2118.39,"id":2497008}]}]}
{"op":"mcm","clk":"4294841291","pt":1632555830670,"mc":[{"id":"1.188136695","rc":[{"batl":[[0,2.18,564.06],[1,2.2,61.71]],"ltp":2.12,"tv":703.42,"id":5300737},{"batb":[[0,1.86,423.37],[1,1.6,7.31],[2,1.36,21.76]],"ltp":1.88,"tv":2118.39,"id":2497008}]}]}
{"op":"mcm","clk":"4294844073","pt":1632555859119,"mc":[{"id":"1.188136695","rc":[{"batl":[[0,2.16,33.43],[1,2.18,564.06]],"ltp":2.12,"tv":703.42,"id":5300737}]}]}
{"op":"mcm","clk":"4294875621","pt":1632556159298,"mc":[{"id":"1.188136695","rc":[{"batl":[[0,2.16,165.59],[1,2.24,25],[2,5.7,219.68]],"ltp":2.12,"tv":703.42,"id":5300737}]}]}
{"op":"mcm","clk":"4294890426","pt":1632556235126,"mc":[{"id":"1.188136695","rc":[{"batb":[[1,1.83,38.53],[2,1.6,7.31]],"ltp":1.88,"tv":2118.39,"id":2497008}]}]}
{"op":"mcm","clk":"4294910548","pt":1632556381359,"mc":[{"id":"1.188136695","rc":[{"batl":[[0,2.14,8.57],[1,2.16,165.59],[2,2.24,25]],"ltp":2.12,"tv":703.42,"id":5300737},{"batb":[[0,1.87,8.98],[1,1.86,423.37],[2,1.83,38.53]],"ltp":1.88,"tv":2118.39,"id":2497008}]}]}
{"op":"mcm","clk":"4294913510","pt":1632556408692,"mc":[{"id":"1.188136695","rc":[{"batb":[[1,1.86,43.71]],"ltp":1.88,"tv":2118.39,"id":2497008}]}]}
{"op":"mcm","clk":"4294919037","pt":1632556459093,"mc":[{"id":"1.188136695","rc":[{"batl":[[1,2.16,33.43]],"ltp":2.12,"tv":703.42,"id":5300737}]}]}
{"op":"mcm","clk":"4294919187","pt":1632556460397,"mc":[{"id":"1.188136695","rc":[{"batl":[[0,2.16,165.59],[1,2.24,25],[2,5.7,219.68]],"ltp":2.12,"tv":703.42,"id":5300737},{"batb":[[0,1.86,425.99],[1,1.83,38.53],[2,1.6,7.31]],"ltp":1.88,"tv":2118.39,"id":2497008}]}]}
{"op":"mcm","clk":"4294947904","pt":1632556740807,"mc":[{"id":"1.188136695","rc":[{"batl":[[0,2.14,8.57],[1,2.16,165.59],[2,2.24,25]],"ltp":2.12,"tv":703.42,"id":5300737},{"batb":[[0,1.87,9.57],[1,1.86,425.99],[2,1.83,38.53]],"ltp":1.88,"tv":2118.39,"id":2497008}]}]}
{"op":"mcm","clk":"4294950070","pt":1632556760453,"mc":[{"id":"1.188136695","rc":[{"batl":[[1,2.16,33.43]],"ltp":2.12,"tv":703.42,"id":5300737},{"batb":[[1,1.86,43.71]],"ltp":1.88,"tv":2118.39,"id":2497008}]}]}
{"op":"mcm","clk":"4294950189","pt":1632556761751,"mc":[{"id":"1.188136695","rc":[{"batl":[[0,2.16,33.43],[1,2.24,25],[2,5.7,219.68]],"ltp":2.12,"tv":703.42,"id":5300737},{"batb":[[0,1.86,43.71],[1,1.83,38.53],[2,1.6,7.31]],"ltp":1.88,"tv":2118.39,"id":2497008}]}]}
{"op":"mcm","clk":"4294950203","pt":1632556761955,"mc":[{"id":"1.188136695","rc":[{"batl":[[0,2.16,165.59]],"ltp":2.12,"tv":703.42,"id":5300737},{"batb":[[0,1.86,425.99]],"ltp":1.88,"tv":2118.39,"id":2497008}]}]}
{"op":"mcm","clk":"4294954353","pt":1632556801223,"mc":[{"id":"1.188136695","rc":[{"batl":[[0,2.14,8.57],[1,2.16,165.59],[2,2.24,25]],"ltp":2.12,"tv":703.42,"id":5300737},{"batb":[[0,1.87,9.19],[1,1.86,425.99],[2,1.83,38.53]],"ltp":1.88,"tv":2118.39,"id":2497008}]}]}
{"op":"mcm","clk":"4294959044","pt":1632556836591,"mc":[{"id":"1.188136695","rc":[{"batl":[[1,2.16,33.43]],"ltp":2.12,"tv":703.42,"id":5300737}]}]}
{"op":"mcm","clk":"4294959161","pt":1632556837785,"mc":[{"id":"1.188136695","rc":[{"batl":[[0,2.16,165.59],[1,2.24,25],[2,5.7,219.68]],"ltp":2.12,"tv":703.42,"id":5300737}]}]}
{"op":"mcm","clk":"4294959179","pt":1632556837946,"mc":[{"id":"1.188136695","rc":[{"batb":[[1,1.86,43.71]],"ltp":1.88,"tv":2118.39,"id":2497008}]}]}
{"op":"mcm","clk":"4294975984","pt":1632556972039,"mc":[{"id":"1.188136695","rc":[{"trd":[[2.08,46.11]],"batb":[[0,2.08,16]],"ltp":2.08,"tv":743.42,"id":5300737}],"tv":2861.82}]}
{"op":"mcm","clk":"4294977989","pt":1632556990365,"mc":[{"id":"1.188136695","rc":[{"batb":[[0,2.06,43.71],[1,2.04,533.74]],"batl":[[0,2.16,175.02]],"ltp":2.08,"tv":743.42,"id":5300737},{"batb":[[0,1.87,51.19],[1,1.83,38.53],[2,1.6,7.31]],"batl":[[0,1.93,96.46],[1,1.96,3.12],[2,2,25]],"ltp":1.88,"tv":2118.39,"id":2497008}]}]}
{"op":"mcm","clk":"4295002254","pt":1632557208394,"mc":[{"id":"1.188136695","rc":[{"batb":[[1,2.04,292.53]],"ltp":2.08,"tv":743.42,"id":5300737}]}]}
{"op":"mcm","clk":"4295055491","pt":1632557640529,"mc":[{"id":"1.188136695","rc":[{"batl":[[0,2.14,8.57],[1,2.16,175.02],[2,2.24,25]],"ltp":2.08,"tv":743.42,"id":5300737}]}]}
{"op":"mcm","clk":"4295084909","pt":1632557889859,"mc":[{"id":"1.188136695","rc":[{"batl":[[1,2.16,42.86]],"ltp":2.08,"tv":743.42,"id":5300737}]}]}
{"op":"mcm","clk":"4295085041","pt":1632557891263,"mc":[{"id":"1.188136695","rc":[{"batl":[[0,2.16,175.02],[1,2.24,25],[2,5.7,219.68]],"ltp":2.08,"tv":743.42,"id":5300737},{"batb":[[0,1.87,42]],"ltp":1.88,"tv":2118.39,"id":2497008}]}]}
{"op":"mcm","clk":"4295088799","pt":1632557926209,"mc":[{"id":"1.188136695","rc":[{"batb":[[0,1.88,2.54],[1,1.87,42],[2,1.83,38.53]],"ltp":1.88,"tv":2118.39,"id":2497008}]}]}
{"op":"mcm","clk":"4295122905","pt":1632558270802,"mc":[{"id":"1.188136695","rc":[{"batb":[[0,1.88,4.54]],"ltp":1.88,"tv":2118.39,"id":2497008}]}]}
{"op":"mcm","clk":"4295125987","pt":1632558300566,"mc":[{"id":"1.188136695","rc":[{"batl":[[0,2.14,8.57],[1,2.16,175.02],[2,2.24,25]],"ltp":2.08,"tv":743.42,"id":5300737},{"batb":[[1,1.87,52.45]],"ltp":1.88,"tv":2118.39,"id":2497008}]}]}
{"op":"mcm","clk":"4295136501","pt":1632558396167,"mc":[{"id":"1.188136695","rc":[{"batl":[[1,2.16,42.86]],"ltp":2.08,"tv":743.42,"id":5300737}]}]}
{"op":"mcm","clk":"4295136648","pt":1632558397646,"mc":[{"id":"1.188136695","rc":[{"batl":[[0,2.16,42.86],[1,2.24,25],[2,5.7,219.68]],"ltp":2.08,"tv":743.42,"id":5300737},{"batb":[[1,1.87,42]],"ltp":1.88,"tv":2118.39,"id":2497008}]}]}
{"op":"mcm","clk":"4295136689","pt":1632558397932,"mc":[{"id":"1.188136695","rc":[{"batl":[[0,2.16,175.02]],"ltp":2.08,"tv":743.42,"id":5300737}]}]}
{"op":"mcm","clk":"4295146576","pt":1632558480896,"mc":[{"id":"1.188136695","rc":[{"batl":[[0,2.14,8.57],[1,2.16,175.02],[2,2.24,25]],"ltp":2.08,"tv":743.42,"id":5300737},{"batb":[[1,1.87,52.71]],"ltp":1.88,"tv":2118.39,"id":2497008}]}]}
{"op":"mcm","clk":"4295180267","pt":1632558697848,"mc":[{"id":"1.188136695","rc":[{"batl":[[1,2.16,42.86]],"ltp":2.08,"tv":743.42,"id":5300737}]}]}
{"op":"mcm","clk":"4295180580","pt":1632558699723,"mc":[{"id":"1.188136695","rc":[{"batl":[[0,2.16,42.86],[1,2.24,25],[2,5.7,219.68]],"ltp":2.08,"tv":743.42,"id":5300737},{"batb":[[1,1.87,42]],"ltp":1.88,"tv":2118.39,"id":2497008}]}]}
{"op":"mcm","clk":"4295180606","pt":1632558699932,"mc":[{"id":"1.188136695","rc":[{"batl":[[0,2.16,175.02]],"ltp":2.08,"tv":743.42,"id":5300737}]}]}
{"op":"mcm","clk":"4295180904","pt":1632558701807,"mc":[{"id":"1.188136695","rc":[{"trd":[[2.06,40]],"batb":[[0,2.06,23.72]],"ltp":2.06,"tv":783.42,"id":5300737}],"tv":2901.81}]}
{"op":"mcm","clk":"4295184028","pt":1632558721435,"mc":[{"id":"1.188136695","rc":[{"batb":[[0,2.06,34.86]],"batl":[[0,2.14,42],[1,2.16,132.16],[2,2.24,25]],"ltp":2.06,"tv":783.42,"id":5300737},{"batb":[[0,1.88,45.68],[1,1.83,38.53],[2,1.6,7.31]],"batl":[[0,1.93,60.46],[1,1.94,34.28],[2,1.96,3.12]],"ltp":1.88,"tv":2118.39,"id":2497008}]}]}
{"op":"mcm","clk":"4295189097","pt":1632558751479,"mc":[{"id":"1.188136695","rc":[{"batl":[[1,2.24,25],[2,5.7,219.68]],"ltp":2.06,"tv":783.42,"id":5300737}]}]}
{"op":"mcm","clk":"4295217754","pt":1632558934635,"mc":[{"id":"1.188136695","rc":[{"trd":[[2.06,43.99]],"batb":[[0,2.06,32.86]],"ltp":2.06,"tv":787.41,"id":5300737}],"tv":2905.81}]}
{"op":"mcm","clk":"4295223249","pt":1632558971181,"mc":[{"id":"1.188136695","rc":[{"batl":[[1,1.95,41.14]],"ltp":1.88,"tv":2118.39,"id":2497008}]}]}
{"op":"mcm","clk":"4295242550","pt":1632559098671,"mc":[{"id":"1.188136695","rc":[{"trd":[[2.14,26.55]],"batl":[[0,2.14,28.72]],"ltp":2.14,"tv":813.97,"id":5300737}],"tv":2932.36}]}
{"op":"mcm","clk":"4295250100","pt":1632559151522,"mc":[{"id":"1.188136695","rc":[{"batb":[[0,2.06,43.15]],"batl":[[0,2.14,34.72]],"ltp":2.14,"tv":813.97,"id":5300737},{"batb":[[0,1.88,40.54]],"batl":[[1,1.94,42]],"ltp":1.88,"tv":2118.39,"id":2497008}]}]}
{"op":"mcm","clk":"4295254457","pt":1632559181178,"mc":[{"id":"1.188136695","rc":[{"batb":[[2,1.91,35.14]],"ltp":2.14,"tv":813.97,"id":5300737},{"batb":[[0,1.88,35.39]],"ltp":1.88,"tv":2118.39,"id":2497008}]}]}
{"op":"mcm","clk":"4295260333","pt":1632559221220,"mc":[{"id":"1.188136695","rc":[{"batb":[[0,1.88,30.25]],"ltp":1.88,"tv":2118.39,"id":2497008}]}]}
{"op":"mcm","clk":"4295267370","pt":1632559271607,"mc":[{"id":"1.188136695","rc":[{"batb":[[0,1.88,39.68]],"ltp":1.88,"tv":2118.39,"id":2497008}]}]}
{"op":"mcm","clk":"4295289836","pt":1632559425144,"mc":[{"id":"1.188136695","rc":[{"trd":[[2.06,56.3]],"batb":[[0,2.06,36.99]],"ltp":2.06,"tv":826.27,"id":5300737}],"tv":2944.67}]}
{"op":"mcm","clk":"4295297872","pt":1632559481816,"mc":[{"id":"1.188136695","rc":[{"batb":[[0,2.04,574.69],[1,1.91,35.14],[2,1.7,21.24]],"batl":[[0,2.22,597.34]],"ltp":2.06,"tv":826.27,"id":5300737},{"batb":[[0,1.88,4.54]],"batl":[[1,1.96,3.12],[2,2,25]],"ltp":1.88,"tv":2118.39,"id":2497008}]}]}
{"op":"mcm","clk":"4295297974","pt":1632559482499,"mc":[{"id":"1.188136695","rc":[{"batb":[[0,1.88,10.54]],"ltp":1.88,"tv":2118.39,"id":2497008}]}]}
{"op":"mcm","clk":"4295298956","pt":1632559489246,"mc":[{"id":"1.188136695","rc":[{"batl":[[0,2.12,51.29]],"ltp":2.06,"tv":826.27,"id":5300737}]}]}
{"op":"mcm","clk":"4295300559","pt":1632559500735,"mc":[{"id":"1.188136695","rc":[{"batl":[[1,1.96,13.58]],"ltp":1.88,"tv":2118.39,"id":2497008}]}]}
{"op":"mcm","clk":"4295302111","pt":1632559511749,"mc":[{"id":"1.188136695","rc":[{"batb":[[0,2.06,35.14],[1,2.04,574.69],[2,1.91,35.14]],"batl":[[1,2.14,32.57],[2,2.24,25]],"ltp":2.06,"tv":826.27,"id":5300737},{"batb":[[0,1.88,45.68]],"batl":[[1,1.94,35.14],[2,1.96,13.58]],"ltp":1.88,"tv":2118.39,"id":2497008}]}]}
{"op":"mcm","clk":"4295302415","pt":1632559513753,"mc":[{"id":"1.188136695","rc":[{"batl":[[2,1.96,3.12]],"ltp":1.88,"tv":2118.39,"id":2497008}]}]}
{"op":"mcm","clk":"4295311796","pt":1632559583660,"mc":[{"id":"1.188136695","rc":[{"batb":[[1,2.04,292.53]],"ltp":2.06,"tv":826.27,"id":5300737}]}]}
{"op":"mcm","clk":"4295437682","pt":1632560510374,"mc":[{"id":"1.188136695","rc":[{"batl":[[0,1.92,42.86],[1,1.93,60.46],[2,1.94,35.14]],"ltp":1.88,"tv":2118.39,"id":2497008}]}]}
{"op":"mcm","clk":"4295438753","pt":1632560518854,"mc":[{"id":"1.188136695","rc":[{"batl":[[1,1.93,103.32]],"ltp":1.88,"tv":2118.39,"id":2497008}]}]}
{"op":"mcm","clk":"4295443050","pt":1632560549642,"mc":[{"id":"1.188136695","rc":[{"batl":[[0,1.91,13.18],[1,1.92,42.86],[2,1.93,103.32]],"ltp":1.88,"tv":2118.39,"id":2497008}]}]}
{"op":"mcm","clk":"4295500347","pt":1632560950985,"mc":[{"id":"1.188136695","rc":[{"batb":[[0,2.06,58.11]],"ltp":2.06,"tv":826.27,"id":5300737}]}]}
{"op":"mcm","clk":"4295544814","pt":1632561240633,"mc":[{"id":"1.188136695","rc":[{"batb":[[0,2.1,5.46],[1,2.06,58.11],[2,2.04,292.53]],"batl":[[1,2.14,36.57]],"ltp":2.06,"tv":826.27,"id":5300737},{"batb":[[0,1.89,6],[1,1.88,45.68],[2,1.83,38.53]],"batl":[[0,1.91,18.18]],"ltp":1.88,"tv":2118.39,"id":2497008}]}]}
{"op":"mcm","clk":"4295546562","pt":1632561251063,"mc":[{"id":"1.188136695","rc":[{"batb":[[1,2.06,35.14]],"ltp":2.06,"tv":826.27,"id":5300737}]}]}
{"op":"mcm","clk":"4295588293","pt":1632561543352,"mc":[{"id":"1.188136695","rc":[{"batl":[[1,2.14,46.86]],"ltp":2.06,"tv":826.27,"id":5300737}]}]}
{"op":"mcm","clk":"4295608325","pt":1632561696705,"mc":[{"id":"1.188136695","rc":[{"trd":[[2.1,147.42]],"batb":[[0,2.06,74.45],[1,2.04,292.53],[2,1.91,35.14]],"batl":[[0,2.1,103.16],[1,2.12,58.29],[2,2.14,48.86]],"ltp":2.1,"tv":849.95,"id":5300737},{"batb":[[0,1.89,9]],"batl":[[0,1.91,13.18],[1,1.92,47.86]],"ltp":1.88,"tv":2118.39,"id":2497008}],"tv":2968.35}]}
{"op":"mcm","clk":"4295608354","pt":1632561696870,"mc":[{"id":"1.188136695","rc":[{"batb":[[0,2.08,6],[1,2.06,74.45],[2,2.04,292.53]],"ltp":2.1,"tv":849.95,"id":5300737},{"batb":[[0,1.9,12],[1,1.89,9],[2,1.88,45.68]],"ltp":1.88,"tv":2118.39,"id":2497008}]}]}
{"op":"mcm","clk":"4295611508","pt":1632561720805,"mc":[{"id":"1.188136695","rc":[{"batb":[[0,2.06,74.45],[1,2.04,292.53],[2,1.91,35.14]],"batl":[[1,2.12,51.29],[2,2.14,42.86]],"ltp":2.1,"tv":849.95,"id":5300737},{"trd":[[1.91,90]],"batb":[[0,1.88,45.68],[1,1.83,38.53],[2,1.6,7.31]],"batl":[[0,1.91,3.25],[1,1.92,51.5]],"ltp":1.91,"tv":2138.26,"id":2497008}],"tv":2988.21}]}
{"op":"mcm","clk":"4295738327","pt":1632562717794,"mc":[{"id":"1.188136695","rc":[{"batb":[[0,2.08,7],[1,2.06,81.45],[2,2.04,299.53]],"batl":[[1,2.12,61.29]],"ltp":2.1,"tv":849.95,"id":5300737},{"trd":[[1.91,96.49],[1.92,1425.42]],"batb":[[0,1.91,1263.28],[1,1.9,12],[2,1.89,10]],"batl":[[0,1.92,12.23],[1,1.93,103.32],[2,1.94,35.14]],"ltp":1.92,"tv":2235.3,"id":2497008}],"tv":3085.25}]}
{"op":"mcm","clk":"4295738393","pt":1632562718311,"mc":[{"id":"1.188136695","rc":[{"batl":[[0,2.1,113.16]],"ltp":2.1,"tv":849.95,"id":5300737},{"batb":[[0,1.91,1275.28]],"batl":[[0,1.92,6.23],[1,1.93,109.32]],"ltp":1.92,"tv":2235.3,"id":2497008}]}]}
{"op":"mcm","clk":"4295747150","pt":1632562783518,"mc":[{"id":"1.188136695","rc":[{"batb":[[1,2.06,42.14]],"ltp":2.1,"tv":849.95,"id":5300737}]}]}
{"op":"mcm","clk":"4295749418","pt":1632562799163,"mc":[{"id":"1.188136695","rc":[{"batb":[[0,2.08,28],[1,2.06,63.14],[2,2.04,320.53]],"batl":[[0,2.1,130.16],[1,2.12,76.29],[2,2.14,65.86]],"ltp":2.1,"tv":849.95,"id":5300737},{"batb":[[0,1.91,1299.28],[1,1.9,34],[2,1.89,31]],"batl":[[1,1.93,127.32]],"ltp":1.92,"tv":2235.3,"id":2497008}]}]}
{"op":"mcm","clk":"4295768064","pt":1632562938509,"mc":[{"id":"1.188136695","rc":[{"trd":[[2.08,51.42]],"batb":[[0,2.08,25.35]],"ltp":2.08,"tv":855.25,"id":5300737}],"tv":3090.56}]}
{"op":"mcm","clk":"4295790178","pt":1632563117267,"mc":[{"id":"1.188136695","rc":[{"trd":[[2.08,51.62]],"batb":[[0,2.08,25.25]],"ltp":2.08,"tv":855.45,"id":5300737}],"tv":3090.76}]}
{"op":"mcm","clk":"4295845518","pt":1632563561820,"mc":[{"id":"1.188136695","rc":[{"batb":[[0,2.08,44.49]],"ltp":2.08,"tv":855.45,"id":5300737}]}]}
{"op":"mcm","clk":"4295913457","pt":1632564132403,"mc":[{"id":"1.188136695","rc":[{"trd":[[1.91,116.5]],"batb":[[0,1.91,1289.28]],"ltp":1.91,"tv":2255.3,"id":2497008}],"tv":3110.76}]}
{"op":"mcm","clk":"4295968001","pt":1632564473943,"mc":[{"id":"1.188136695","rc":[{"trd":[[1.91,370.15]],"batb":[[0,1.91,1162.45]],"ltp":1.91,"tv":2508.96,"id":2497008}],"tv":3364.42}]}
{"op":"mcm","clk":"4295971012","pt":1632564490674,"mc":[{"id":"1.188136695","rc":[{"trd":[[1.92,1427.13]],"batl":[[0,1.92,5.37]],"ltp":1.92,"tv":2510.67,"id":2497008}],"tv":3366.13}]}
{"op":"mcm","clk":"4295996696","pt":1632564662674,"mc":[{"id":"1.188136695","rc":[{"trd":[[1.92,1437.88]],"batb":[[0,1.92,423.19],[1,1.91,1162.45],[2,1.9,34]],"batl":[[0,1.93,127.32],[1,1.94,35.14],[2,1.96,3.12]],"ltp":1.92,"tv":2521.42,"id":2497008}],"tv":3376.88}]}
{"op":"mcm","clk":"4295996765","pt":1632564663053,"mc":[{"id":"1.188136695","rc":[{"batb":[[0,2.08,19.24]],"ltp":2.08,"tv":855.45,"id":5300737},{"batl":[[1,1.94,62.5],[2,1.95,27]],"ltp":1.92,"tv":2521.42,"id":2497008}]}]}
{"op":"mcm","clk":"4295997192","pt":1632564666073,"mc":[{"id":"1.188136695","rc":[{"batb":[[1,1.91,1591.01]],"ltp":1.92,"tv":2521.42,"id":2497008}]}]}
{"op":"mcm","clk":"4295997552","pt":1632564668570,"mc":[{"id":"1.188136695","rc":[{"batb":[[2,1.9,462.56]],"ltp":1.92,"tv":2521.42,"id":2497008}]}]}
{"op":"mcm","clk":"4296047221","pt":1632565042241,"mc":[{"id":"1.188136695","rc":[{"batl":[[0,2.1,27]],"ltp":2.08,"tv":855.45,"id":5300737}]}]}
{"op":"mcm","clk":"4296048214","pt":1632565050688,"mc":[{"id":"1.188136695","rc":[{"batb":[[0,2.06,63.14],[1,2.04,320.53],[2,2.02,28.65]],"ltp":2.08,"tv":855.45,"id":5300737}]}]}
{"op":"mcm","clk":"4296048258","pt":1632565050959,"mc":[{"id":"1.188136695","rc":[{"batb":[[0,2.06,85.14],[1,2.04,342.53],[2,2.02,50]],"batl":[[0,2.1,45],[1,2.12,94.29],[2,2.14,82.86]],"ltp":2.08,"tv":855.45,"id":5300737},{"batb":[[0,1.92,483.19],[1,1.91,1612.01],[2,1.9,482.56]],"batl":[[0,1.93,103.32],[2,1.95,43]],"ltp":1.92,"tv":2521.42,"id":2497008}]}]}
{"op":"mcm","clk":"4296049304","pt":1632565058058,"mc":[{"id":"1.188136695","rc":[{"batb":[[0,2.06,104.56]],"ltp":2.08,"tv":855.45,"id":5300737}]}]}
{"op":"mcm","clk":"4296050018","pt":1632565062992,"mc":[{"id":"1.188136695","rc":[{"batl":[[0,2.08,53.16],[1,2.1,45],[2,2.12,94.29]],"ltp":2.08,"tv":855.45,"id":5300737}]}]}
{"op":"mcm","clk":"4296065562","pt":1632565072981,"mc":[{"id":"1.188136695","rc":[{"batb":[[0,2.06,54.56],[1,2.04,292.53],[2,1.7,21.24]],"batl":[[1,2.12,51.29],[2,2.14,42.86]],"ltp":2.08,"tv":855.45,"id":5300737},{"batb":[[0,1.92,423.19],[1,1.91,1555.01],[2,1.9,428.56]],"batl":[[1,1.94,35.14],[2,1.96,3.12]],"ltp":1.92,"tv":2521.42,"id":2497008}]}]}
{"op":"mcm","clk":"4296066982","pt":1632565083704,"mc":[{"id":"1.188136695","rc":[{"trd":[[2.08,70.52]],"batl":[[0,2.08,43.71]],"ltp":2.08,"tv":874.36,"id":5300737}],"tv":3395.78}]}
{"op":"mcm","clk":"4296069752","pt":1632565104434,"mc":[{"id":"1.188136695","rc":[{"batb":[[0,2.06,104.56]],"batl":[[1,2.1,45],[2,2.12,51.29]],"ltp":2.08,"tv":874.36,"id":5300737},{"batb":[[0,1.92,483.19]],"batl":[[2,1.95,42]],"ltp":1.92,"tv":2521.42,"id":2497008}]}]}
{"op":"mcm","clk":"4296072466","pt":1632565124765,"mc":[{"id":"1.188136695","rc":[{"batl":[[1,1.94,77.74]],"ltp":1.92,"tv":2521.42,"id":2497008}]}]}
{"op":"mcm","clk":"4296077337","pt":1632565162337,"mc":[{"id":"1.188136695","rc":[{"batb":[[1,2.04,340.53],[2,2.02,48.61]],"ltp":2.08,"tv":874.36,"id":5300737},{"batb":[[1,1.91,1610.01],[2,1.9,480.56]],"ltp":1.92,"tv":2521.42,"id":2497008}]}]}
{"op":"mcm","clk":"4296080531","pt":1632565187671,"mc":[{"id":"1.188136695","rc":[{"batb":[[0,2.06,54.56],[1,2.04,292.53],[2,1.7,21.24]],"batl":[[1,2.12,51.29],[2,2.14,42.86]],"ltp":2.08,"tv":874.36,"id":5300737},{"batb":[[0,1.92,423.19],[1,1.91,1555.01],[2,1.9,428.56]],"batl":[[1,1.94,35.14],[2,1.96,3.12]],"ltp":1.92,"tv":2521.42,"id":2497008}]}]}
{"op":"mcm","clk":"4296085985","pt":1632565227337,"mc":[{"id":"1.188136695","rc":[{"batb":[[0,2.06,100.56]],"batl":[[1,2.1,42],[2,2.12,51.29]],"ltp":2.08,"tv":874.36,"id":5300737},{"batb":[[0,1.92,479.19]],"batl":[[2,1.95,39]],"ltp":1.92,"tv":2521.42,"id":2497008}]}]}
{"op":"mcm","clk":"4296088768","pt":1632565247678,"mc":[{"id":"1.188136695","rc":[{"batl":[[1,1.94,74.48]],"ltp":1.92,"tv":2521.42,"id":2497008}]}]}
{"op":"mcm","clk":"4296092902","pt":1632565279551,"mc":[{"id":"1.188136695","rc":[{"batl":[[0,2.1,42],[1,2.12,51.29],[2,2.24,25]],"ltp":2.08,"tv":874.36,"id":5300737}]}]}
{"op":"mcm","clk":"4296093719","pt":1632565286248,"mc":[{"id":"1.188136695","rc":[{"batb":[[1,2.04,339.53],[2,2.02,47.37]],"batl":[[1,2.12,91.29],[2,2.14,37]],"ltp":2.08,"tv":874.36,"id":5300737},{"batb":[[1,1.91,1608.01],[2,1.9,478.56]],"ltp":1.92,"tv":2521.42,"id":2497008}]}]}
{"op":"mcm","clk":"4296096749","pt":1632565311584,"mc":[{"id":"1.188136695","rc":[{"batb":[[0,2.06,54.56],[1,2.04,292.53],[2,1.7,21.24]],"batl":[[0,2.12,51.29],[1,2.24,25],[2,5.7,219.68]],"ltp":2.08,"tv":874.36,"id":5300737},{"batb":[[0,1.92,423.19],[1,1.91,1555.01],[2,1.9,428.56]],"batl":[[1,1.94,35.14],[2,1.96,3.12]],"ltp":1.92,"tv":2521.42,"id":2497008}]}]}
{"op":"mcm","clk":"4296104117","pt":1632565370148,"mc":[{"id":"1.188136695","rc":[{"batb":[[0,2.06,100.56],[2,2.02,4]],"batl":[[0,2.1,42],[1,2.12,51.29],[2,2.14,41.14]],"ltp":2.08,"tv":874.36,"id":5300737},{"batb":[[0,1.92,479.19]],"batl":[[1,1.94,74.56]],"ltp":1.92,"tv":2521.42,"id":2497008}]}]}
{"op":"mcm","clk":"4296104617","pt":1632565373770,"mc":[{"id":"1.188136695","rc":[{"trd":[[2.06,143.72]],"batb":[[0,2.06,56.85],[1,2.04,339.53],[2,2.02,51.42]],"batl":[[1,2.12,91.29],[2,2.14,78.14]],"ltp":2.06,"tv":961.78,"id":5300737},{"batb":[[1,1.91,1608.01],[2,1.9,478.56]],"ltp":1.92,"tv":2521.42,"id":2497008}],"tv":3483.2}]}
{"op":"mcm","clk":"4296117448","pt":1632565479812,"mc":[{"id":"1.188136695","rc":[{"batl":[[2,2.14,37]],"ltp":2.06,"tv":961.78,"id":5300737},{"batl":[[1,1.94,39.42]],"ltp":1.92,"tv":2521.42,"id":2497008}]}]}
{"op":"mcm","clk":"4296117537","pt":1632565480603,"mc":[{"id":"1.188136695","rc":[{"batb":[[1,2.04,372.1]],"batl":[[1,2.12,135]],"ltp":2.06,"tv":961.78,"id":5300737},{"batb":[[2,1.9,514.56]],"batl":[[2,1.96,39.12]],"ltp":1.92,"tv":2521.42,"id":2497008}]}]}
{"op":"mcm","clk":"4296126915","pt":1632565557740,"mc":[{"id":"1.188136695","rc":[{"trd":[[1.93,206.63]],"batb":[[0,1.93,1023.13],[1,1.92,479.19],[2,1.91,481.56]],"batl":[[0,1.94,39.42],[1,1.96,39.12],[2,2,25]],"ltp":1.93,"tv":2728.05,"id":2497008}],"tv":3689.84}]}
{"op":"mcm","clk":"4296126940","pt":1632565557951,"mc":[{"id":"1.188136695","rc":[{"batb":[[0,2.06,10.85]],"batl":[[0,2.08,46],[1,2.1,42],[2,2.12,135]],"ltp":2.06,"tv":961.78,"id":5300737},{"batb":[[0,1.93,1083.13]],"batl":[[0,1.95,42],[1,1.96,82.64],[2,1.97,43]],"ltp":1.93,"tv":2728.05,"id":2497008}]}]}
{"op":"mcm","clk":"4296127690","pt":1632565563220,"mc":[{"id":"1.188136695","rc":[{"batb":[[0,2.04,386.31],[1,2.02,51.42],[2,2,47.42]],"batl":[[0,2.06,46.52],[1,2.08,46],[2,2.1,42]],"ltp":2.06,"tv":961.78,"id":5300737},{"batb":[[0,1.94,59.52],[1,1.93,1083.13],[2,1.92,479.19]],"batl":[[0,1.96,39.12],[1,1.97,43],[2,2,25]],"ltp":1.93,"tv":2728.05,"id":2497008}]}]}
{"op":"mcm","clk":"4296128364","pt":1632565568744,"mc":[{"id":"1.188136695","rc":[{"batb":[[0,2.04,397.27]],"ltp":2.06,"tv":961.78,"id":5300737}]}]}
{"op":"mcm","clk":"4296129277","pt":1632565576664,"mc":[{"id":"1.188136695","rc":[{"batb":[[0,1.94,1082.65],[1,1.93,60]],"ltp":1.93,"tv":2728.05,"id":2497008}]}]}
{"op":"mcm","clk":"4296130235","pt":1632565584436,"mc":[{"id":"1.188136695","rc":[{"trd":[[2.06,169.58]],"batb":[[0,2.04,350.27],[1,2.02,4],[2,1.7,21.24]],"batl":[[0,2.06,33.59]],"ltp":2.06,"tv":987.64,"id":5300737}],"tv":3715.7}]}
{"op":"mcm","clk":"4296132053","pt":1632565599572,"mc":[{"id":"1.188136695","rc":[{"batb":[[0,1.95,1023.13],[1,1.94,59.52],[2,1.93,60]],"ltp":1.93,"tv":2728.05,"id":2497008}]}]}
{"op":"mcm","clk":"4296133561","pt":1632565612090,"mc":[{"id":"1.188136695","rc":[{"batb":[[1,2.02,55.55]],"ltp":2.06,"tv":987.64,"id":5300737},{"batb":[[0,1.95,1077.13]],"ltp":1.93,"tv":2728.05,"id":2497008}]}]}
{"op":"mcm","clk":"4296142048","pt":1632565684179,"mc":[{"id":"1.188136695","rc":[{"trd":[[1.95,14.16]],"batb":[[0,1.95,1070.05]],"ltp":1.95,"tv":2742.21,"id":2497008}],"tv":3729.86}]}
{"op":"mcm","clk":"4296156733","pt":1632565812611,"mc":[{"id":"1.188136695","rc":[{"batb":[[0,2.04,336.06]],"ltp":2.06,"tv":987.64,"id":5300737}]}]}
{"op":"mcm","clk":"4296176824","pt":1632565972724,"mc":[{"id":"1.188136695","rc":[{"batb":[[0,2.04,303.49]],"ltp":2.06,"tv":987.64,"id":5300737},{"batl":[[0,1.96,3.12]],"ltp":1.95,"tv":2742.21,"id":2497008}]}]}
{"op":"mcm","clk":"4296180330","pt":1632566000794,"mc":[{"id":"1.188136695","rc":[{"batb":[[0,2.04,337.77]],"ltp":2.06,"tv":987.64,"id":5300737},{"batl":[[0,1.96,37.4]],"ltp":1.95,"tv":2742.21,"id":2497008}]}]}
{"op":"mcm","clk":"4296192248","pt":1632566096917,"mc":[{"id":"1.188136695","rc":[{"trd":[[1.95,24.16]],"batb":[[0,1.95,1065.06]],"ltp":1.95,"tv":2752.21,"id":2497008}],"tv":3739.86}]}
{"op":"mcm","clk":"4296283192","pt":1632566828981,"mc":[{"id":"1.188136695","rc":[{"trd":[[1.95,29.3]],"batb":[[0,1.95,1062.49]],"ltp":1.95,"tv":2757.35,"id":2497008}],"tv":3745.0}]}
{"op":"mcm","clk":"4296323887","pt":1632567167011,"mc":[{"id":"1.188136695","rc":[{"trd":[[1.95,36.62]],"batb":[[0,1.95,1058.83]],"ltp":1.95,"tv":2764.67,"id":2497008}],"tv":3752.32}]}
{"op":"mcm","clk":"4296342929","pt":1632567342336,"mc":[{"id":"1.188136695","rc":[{"trd":[[2.04,628.26]],"batb":[[0,2.04,262.77],[1,2.02,51.55]],"ltp":2.04,"tv":1137.65,"id":5300737}],"tv":3902.32}]}
{"op":"mcm","clk":"4296348512","pt":1632567397597,"mc":[{"id":"1.188136695","rc":[{"batl":[[2,2,32.31]],"ltp":1.95,"tv":2764.67,"id":2497008}]}]}
{"op":"mcm","clk":"4296362081","pt":1632567525192,"mc":[{"id":"1.188136695","rc":[{"batl":[[2,2,34.31]],"ltp":1.95,"tv":2764.67,"id":2497008}]}]}
{"op":"mcm","clk":"4296374937","pt":1632567625940,"mc":[{"id":"1.188136695","rc":[{"trd":[[1.95,329.96]],"batb":[[0,1.95,912.16]],"ltp":1.95,"tv":3058.01,"id":2497008}],"tv":4195.66}]}
{"op":"mcm","clk":"4296380973","pt":1632567662856,"mc":[{"id":"1.188136695","rc":[{"trd":[[1.95,860.91]],"batb":[[0,1.95,646.68]],"ltp":1.95,"tv":3588.96,"id":2497008}],"tv":4726.61}]}
{"op":"mcm","clk":"4296421626","pt":1632567920187,"mc":[{"id":"1.188136695","rc":[{"trd":[[2.06,173.58]],"batl":[[0,2.06,31.59]],"ltp":2.06,"tv":1141.65,"id":5300737}],"tv":4730.61}]}
{"op":"mcm","clk":"4296526634","pt":1632568571287,"mc":[{"id":"1.188136695","rc":[{"batb":[[1,2.02,27]],"batl":[[1,2.08,21],[2,2.1,21]],"ltp":2.06,"tv":1141.65,"id":5300737},{"trd":[[1.96,434.94]],"batb":[[0,1.96,248.02],[1,1.95,620.68],[2,1.94,28]],"batl":[[0,1.97,22],[1,1.98,22.53],[2,1.99,22]],"ltp":1.96,"tv":3663.77,"id":2497008}],"tv":4805.42}]}
{"op":"mcm","clk":"4296527615","pt":1632568578676,"mc":[{"id":"1.188136695","rc":[{"batl":[[0,2.06,47.06]],"ltp":2.06,"tv":1141.65,"id":5300737}]}]}
{"op":"mcm","clk":"4296528742","pt":1632568586603,"mc":[{"id":"1.188136695","rc":[{"trd":[[1.96,450.72]],"batb":[[0,1.96,240.12]],"ltp":1.96,"tv":3679.56,"id":2497008}],"tv":4821.21}]}
{"op":"mcm","clk":"4296536077","pt":1632568637428,"mc":[{"id":"1.188136695","rc":[{"trd":[[1.96,451.53]],"batb":[[0,1.96,239.72]],"ltp":1.96,"tv":3680.36,"id":2497008}],"tv":4822.01}]}
{"op":"mcm","clk":"4296536871","pt":1632568642744,"mc":[{"id":"1.188136695","rc":[{"batb":[[0,2.04,228.48],[1,2.02,69.86]],"batl":[[2,2.1,63]],"ltp":2.06,"tv":1141.65,"id":5300737},{"batl":[[1,1.98,63.67]],"ltp":1.96,"tv":3680.36,"id":2497008}]}]}
{"op":"mcm","clk":"4296540573","pt":1632568669555,"mc":[{"id":"1.188136695","rc":[{"batb":[[2,1.94,70.86]],"ltp":1.96,"tv":3680.36,"id":2497008}]}]}
{"op":"mcm","clk":"4296582677","pt":1632568967697,"mc":[{"id":"1.188136695","rc":[{"trd":[[2.06,193.09]],"batl":[[0,2.06,37.31]],"ltp":2.06,"tv":1161.15,"id":5300737}],"tv":4841.52}]}
{"op":"mcm","clk":"4296610300","pt":1632569176476,"mc":[{"id":"1.188136695","rc":[{"trd":[[1.96,457.2]],"batb":[[0,1.96,236.88]],"ltp":1.96,"tv":3686.04,"id":2497008}],"tv":4847.2}]}
{"op":"mcm","clk":"4296662463","pt":1632569538316,"mc":[{"id":"1.188136695","rc":[{"trd":[[1.96,513.93]],"batb":[[0,1.96,208.52]],"ltp":1.96,"tv":3742.76,"id":2497008}],"tv":4903.92}]}
{"op":"mcm","clk":"4296689327","pt":1632569694873,"mc":[{"id":"1.188136695","rc":[{"batb":[[0,2.04,10.96]],"ltp":2.06,"tv":1161.15,"id":5300737}]}]}
{"op":"mcm","clk":"4296690025","pt":1632569698790,"mc":[{"id":"1.188136695","rc":[{"batb":[[0,2.02,2890.15],[1,2,29],[2,1.99,25.49]],"ltp":2.06,"tv":1161.15,"id":5300737},{"trd":[[1.96,601.4]],"batb":[[0,1.96,164.78]],"batl":[[0,1.98,65.14],[1,1.99,22],[2,2,34.31]],"ltp":1.96,"tv":3830.24,"id":2497008}],"tv":4991.4}]}
{"op":"mcm","clk":"4296690057","pt":1632569698959,"mc":[{"id":"1.188136695","rc":[{"batl":[[0,1.97,25.49],[1,1.98,65.14],[2,1.99,22]],"ltp":1.96,"tv":3830.24,"id":2497008}]}]}
{"op":"mcm","clk":"4296691012","pt":1632569703981,"mc":[{"id":"1.188136695","rc":[{"batb":[[0,2.02,2901.21]],"ltp":2.06,"tv":1161.15,"id":5300737}]}]}
{"op":"mcm","clk":"4296692326","pt":1632569711403,"mc":[{"id":"1.188136695","rc":[{"batb":[[0,2.04,217.52],[1,2.02,82.92],[2,2,29]],"ltp":2.06,"tv":1161.15,"id":5300737}]}]}
{"op":"mcm","clk":"4296693031","pt":1632569715303,"mc":[{"id":"1.188136695","rc":[{"batb":[[1,2.02,71.86]],"ltp":2.06,"tv":1161.15,"id":5300737}]}]}
{"op":"mcm","clk":"4296694027","pt":1632569721101,"mc":[{"id":"1.188136695","rc":[{"batb":[[0,2.04,228.48]],"ltp":2.06,"tv":1161.15,"id":5300737}]}]}
{"op":"mcm","clk":"4296762958","pt":1632570119914,"mc":[{"id":"1.188136695","rc":[{"trd":[[2.04,645.4]],"batb":[[0,2.04,219.91]],"ltp":2.04,"tv":1178.29,"id":5300737}],"tv":5008.54}]}
{"op":"mcm","clk":"4296764016","pt":1632570125629,"mc":[{"id":"1.188136695","rc":[{"batb":[[1,1.95,28]],"ltp":1.96,"tv":3830.24,"id":2497008}]}]}
{"op":"mcm","clk":"4296764207","pt":1632570126732,"mc":[{"id":"1.188136695","rc":[{"trd":[[2.04,865.31]],"batb":[[0,2.02,3007.66],[1,2,29],[2,1.99,25.49]],"ltp":2.04,"tv":1398.21,"id":5300737},{"trd":[[1.97,1029.72]],"batl":[[0,1.98,65.14],[1,1.99,22],[2,2,58.31]],"ltp":1.97,"tv":4859.96,"id":2497008}],"tv":6258.17}]}
{"op":"mcm","clk":"4296764367","pt":1632570127533,"mc":[{"id":"1.188136695","rc":[{"batb":[[0,2.02,71.86]],"ltp":2.04,"tv":1398.21,"id":5300737},{"batb":[[0,1.96,196.78]],"ltp":1.97,"tv":4859.96,"id":2497008}]}]}
{"op":"mcm","clk":"4296765275","pt":1632570132744,"mc":[{"id":"1.188136695","rc":[{"batb":[[0,2,3291.62],[1,1.99,25.49],[2,1.98,30.39]],"ltp":2.04,"tv":1398.21,"id":5300737},{"batl":[[0,1.99,22],[1,2,58.31],[2,2.3,5.85]],"ltp":1.97,"tv":4859.96,"id":2497008}]}]}
{"op":"mcm","clk":"4296765880","pt":1632570136419,"mc":[{"id":"1.188136695","rc":[{"batb":[[0,1.96,164.78],[1,1.95,31.86],[2,1.94,42.86]],"ltp":1.97,"tv":4859.96,"id":2497008}]}]}
{"op":"mcm","clk":"4296767150","pt":1632570144247,"mc":[{"id":"1.188136695","rc":[{"batl":[[0,2.06,21.84]],"ltp":2.04,"tv":1398.21,"id":5300737}]}]}
{"op":"mcm","clk":"4296767788","pt":1632570147970,"mc":[{"id":"1.188136695","rc":[{"trd":[[1.96,691.78]],"batb":[[0,1.96,119.59]],"ltp":1.96,"tv":4950.33,"id":2497008}],"tv":6348.55}]}
{"op":"mcm","clk":"4296769757","pt":1632570158740,"mc":[{"id":"1.188136695","rc":[{"batb":[[0,2.02,42.86],[1,2,3291.62],[2,1.99,25.49]],"ltp":2.04,"tv":1398.21,"id":5300737},{"batl":[[0,1.98,44.57],[1,1.99,22],[2,2,58.31]],"ltp":1.96,"tv":4950.33,"id":2497008}]}]}
{"op":"mcm","clk":"4296769806","pt":1632570159051,"mc":[{"id":"1.188136695","rc":[{"batb":[[0,2.02,86.86],[2,1.99,44]],"batl":[[0,2.06,36],[1,2.08,36],[2,2.1,77]],"ltp":2.04,"tv":1398.21,"id":5300737},{"batb":[[2,1.94,89.86]],"batl":[[0,1.98,80.98],[1,1.99,36]],"ltp":1.96,"tv":4950.33,"id":2497008}]}]}
{"op":"mcm","clk":"4296773287","pt":1632570179572,"mc":[{"id":"1.188136695","rc":[{"batb":[[1,2,56]],"ltp":2.04,"tv":1398.21,"id":5300737},{"batb":[[1,1.95,92.27]],"batl":[[2,2,81.31]],"ltp":1.96,"tv":4950.33,"id":2497008}]}]}
{"op":"mcm","clk":"4296773342","pt":1632570179886,"mc":[{"id":"1.188136695","rc":[{"batb":[[0,1.96,183.59]],"ltp":1.96,"tv":4950.33,"id":2497008}]}]}
{"op":"mcm","clk":"4296776809","pt":1632570200525,"mc":[{"id":"1.188136695","rc":[{"batb":[[1,1.95,60.41]],"ltp":1.96,"tv":4950.33,"id":2497008}]}]}
{"op":"mcm","clk":"4296778556","pt":1632570210935,"mc":[{"id":"1.188136695","rc":[{"batl":[[0,2.04,48.44],[1,2.06,36],[2,2.08,36]],"ltp":2.04,"tv":1398.21,"id":5300737}]}]}
{"op":"mcm","clk":"4296782079","pt":1632570231305,"mc":[{"id":"1.188136695","rc":[{"batb":[[0,2.02,42.86]],"ltp":2.04,"tv":1398.21,"id":5300737},{"batl":[[0,1.98,44.57]],"ltp":1.96,"tv":4950.33,"id":2497008}]}]}
{"op":"mcm","clk":"4296787676","pt":1632570262682,"mc":[{"id":"1.188136695","rc":[{"batb":[[1,2,30]],"batl":[[0,2.04,25]],"ltp":2.04,"tv":1398.21,"id":5300737},{"batb":[[0,1.96,151.59],[1,1.95,32]],"batl":[[2,2,59.31]],"ltp":1.96,"tv":4950.33,"id":2497008}]}]}
{"op":"mcm","clk":"4296797007","pt":1632570315749,"mc":[{"id":"1.188136695","rc":[{"batb":[[2,1.94,47]],"ltp":1.96,"tv":4950.33,"id":2497008}]}]}
{"op":"mcm","clk":"4296814769","pt":1632570415741,"mc":[{"id":"1.188136695","rc":[{"batb":[[0,2.02,13.55],[1,2,55.64],[2,1.99,14]],"batl":[[0,2.06,12],[1,2.08,11],[2,2.1,53]],"ltp":2.04,"tv":1398.21,"id":5300737},{"batb":[[0,1.96,119.59],[1,1.95,14],[2,1.94,14]],"batl":[[0,1.99,11.55],[1,2,34.31],[2,2.02,11]],"ltp":1.96,"tv":4950.33,"id":2497008}]}]}
{"op":"mcm","clk":"4296814899","pt":1632570416526,"mc":[{"id":"1.188136695","rc":[{"batb":[[1,2,2752.01]],"ltp":2.04,"tv":1398.21,"id":5300737},{"batl":[[1,2,45.31]],"ltp":1.96,"tv":4950.33,"id":2497008}]}]}
{"op":"mcm","clk":"4296815530","pt":1632570420287,"mc":[{"id":"1.188136695","rc":[{"batb":[[1,2,2709.37]],"ltp":2.04,"tv":1398.21,"id":5300737}]}]}
{"op":"mcm","clk":"4296815739","pt":1632570421482,"mc":[{"id":"1.188136695","rc":[{"batl":[[0,1.99,27.56]],"ltp":1.96,"tv":4950.33,"id":2497008}]}]}
{"op":"mcm","clk":"4296817771","pt":1632570433593,"mc":[{"id":"1.188136695","rc":[{"batb":[[2,1.94,45.86]],"ltp":1.96,"tv":4950.33,"id":2497008}]}]}
{"op":"mcm","clk":"4296819326","pt":1632570442818,"mc":[{"id":"1.188136695","rc":[{"batb":[[1,2,13]],"ltp":2.04,"tv":1398.21,"id":5300737}]}]}
{"op":"mcm","clk":"4296819371","pt":1632570443131,"mc":[{"id":"1.188136695","rc":[{"batb":[[0,2,13],[1,1.99,14],[2,1.98,14]],"batl":[[0,2.04,16.57],[1,2.06,12],[2,2.08,11]],"ltp":2.04,"tv":1398.21,"id":5300737},{"batb":[[0,1.97,21.57],[1,1.96,119.59],[2,1.95,14]],"ltp":1.96,"tv":4950.33,"id":2497008}]}]}
{"op":"mcm","clk":"4296820106","pt":1632570446608,"mc":[{"id":"1.188136695","rc":[{"batb":[[0,2,2715.87]],"ltp":2.04,"tv":1398.21,"id":5300737}]}]}
{"op":"mcm","clk":"4296820166","pt":1632570446870,"mc":[{"id":"1.188136695","rc":[{"batb":[[0,2.02,39.57],[1,2,2742.87],[2,1.99,40]],"batl":[[0,2.06,33],[1,2.08,32],[2,2.1,73]],"ltp":2.04,"tv":1398.21,"id":5300737},{"batb":[[0,1.96,119.59],[1,1.95,42],[2,1.94,73.86]],"batl":[[0,1.99,48.01],[1,2,67.31],[2,2.02,33]],"ltp":1.96,"tv":4950.33,"id":2497008}]}]}
{"op":"mcm","clk":"4296841732","pt":1632570489949,"mc":[{"id":"1.188136695","rc":[{"batb":[[1,2,40]],"ltp":2.04,"tv":1398.21,"id":5300737}]}]}
{"op":"mcm","clk":"4296841914","pt":1632570491164,"mc":[{"id":"1.188136695","rc":[{"batb":[[0,2.02,84.14]],"ltp":2.04,"tv":1398.21,"id":5300737},{"batl":[[0,1.98,42],[1,1.99,48.01],[2,2,67.31]],"ltp":1.96,"tv":4950.33,"id":2497008}]}]}
{"op":"mcm","clk":"4296842056","pt":1632570492063,"mc":[{"id":"1.188136695","rc":[{"batl":[[0,2.04,37.6],[1,2.06,33],[2,2.08,32]],"ltp":2.04,"tv":1398.21,"id":5300737},{"batb":[[0,1.96,166.59]],"ltp":1.96,"tv":4950.33,"id":2497008}]}]}
{"op":"mcm","clk":"4296845449","pt":1632570512451,"mc":[{"id":"1.188136695","rc":[{"batb":[[0,2.02,44.57]],"ltp":2.04,"tv":1398.21,"id":5300737},{"batb":[[2,1.94,42]],"ltp":1.96,"tv":4950.33,"id":2497008}]}]}
{"op":"mcm","clk":"4296846458","pt":1632570519258,"mc":[{"id":"1.188136695","rc":[{"batb":[[0,1.97,50.61],[1,1.96,166.59],[2,1.95,42]],"batl":[[1,1.99,32]],"ltp":1.96,"tv":4950.33,"id":2497008}]}]}
{"op":"mcm","clk":"4296856251","pt":1632570578527,"mc":[{"id":"1.188136695","rc":[{"trd":[[2.04,885.11]],"batl":[[0,2.04,27.7]],"ltp":2.04,"tv":1418.01,"id":5300737}],"tv":6368.35}]}
{"op":"mcm","clk":"4296964085","pt":1632571166349,"mc":[{"id":"1.188136695","rc":[{"trd":[[1.97,1035.03]],"batb":[[0,1.97,47.96]],"ltp":1.97,"tv":4955.64,"id":2497008}],"tv":6373.65}]}
{"op":"mcm","clk":"4297018515","pt":1632571424518,"mc":[{"id":"1.188136695","rc":[{"trd":[[2.02,10]],"batb":[[0,2.02,39.57]],"ltp":2.02,"tv":1428.0,"id":5300737}],"tv":6383.65}]}
{"op":"mcm","clk":"4297031361","pt":1632571481775,"mc":[{"id":"1.188136695","rc":[{"batl":[[0,1.98,32.57]],"ltp":1.97,"tv":4955.64,"id":2497008}]}]}
{"op":"mcm","clk":"4297037777","pt":1632571511806,"mc":[{"id":"1.188136695","rc":[{"batb":[[0,2.02,33.57]],"ltp":2.02,"tv":1428.0,"id":5300737}]}]}
{"op":"mcm","clk":"4297076494","pt":1632571690282,"mc":[{"id":"1.188136695","rc":[{"batb":[[1,2,50.53]],"ltp":2.02,"tv":1428.0,"id":5300737},{"batb":[[2,1.95,50]],"ltp":1.97,"tv":4955.64,"id":2497008}]}]}
{"op":"mcm","clk":"4297084425","pt":1632571725719,"mc":[{"id":"1.188136695","rc":[{"trd":[[2.02,109.07]],"batb":[[0,2,2850.06],[1,1.99,40],[2,1.98,40]],"batl":[[0,2.02,332.5],[1,2.04,27.7],[2,2.06,33]],"ltp":2.02,"tv":1527.08,"id":5300737},{"trd":[[1.98,32.57]],"batl":[[0,1.99,32],[1,2,67.31],[2,2.02,33]],"ltp":1.98,"tv":4988.21,"id":2497008}],"tv":6515.29}]}
{"op":"mcm","clk":"4297084676","pt":1632571726822,"mc":[{"id":"1.188136695","rc":[{"batb":[[0,2,2824.06],[1,1.99,14],[2,1.98,63.57]],"batl":[[1,2.04,9],[2,2.06,50.14]],"ltp":2.02,"tv":1527.08,"id":5300737},{"batb":[[0,1.97,11],[1,1.96,130.59],[2,1.95,62.71]],"batl":[[0,1.99,12],[1,2,34.31],[2,2.02,55.71]],"ltp":1.98,"tv":4988.21,"id":2497008}]}]}
{"op":"mcm","clk":"4297084842","pt":1632571727626,"mc":[{"id":"1.188136695","rc":[{"trd":[[2.02,184.23]],"batl":[[0,2.02,294.92]],"ltp":2.02,"tv":1602.23,"id":5300737}],"tv":6590.45}]}
{"op":"mcm","clk":"4297086895","pt":1632571737200,"mc":[{"id":"1.188136695","rc":[{"batb":[[0,2,2855.92]],"ltp":2.02,"tv":1602.23,"id":5300737}]}]}
{"op":"mcm","clk":"4297091004","pt":1632571755755,"mc":[{"id":"1.188136695","rc":[{"trd":[[2,589.84],[2.02,194.05]],"batb":[[0,2.02,18.72],[1,2,55.86],[2,1.99,14]],"batl":[[0,2.04,16.63],[1,2.06,57.14],[2,2.08,16]],"ltp":2.02,"tv":2201.9,"id":5300737},{"batb":[[0,1.96,139.59],[1,1.95,63.71],[2,1.94,21]],"batl":[[0,1.98,20.63],[1,1.99,20],[2,2,34.31]],"ltp":1.98,"tv":4988.21,"id":2497008}],"tv":7190.11}]}
{"op":"mcm","clk":"4297091178","pt":1632571756463,"mc":[{"id":"1.188136695","rc":[{"batb":[[0,2,55.86],[1,1.99,14],[2,1.98,13]],"batl":[[1,2.06,16]],"ltp":2.02,"tv":2201.9,"id":5300737},{"batb":[[0,1.97,20.63],[1,1.96,139.59],[2,1.95,20]],"batl":[[0,2,52.31],[1,2.02,12],[2,2.3,5.85]],"ltp":1.98,"tv":4988.21,"id":2497008}]}]}
{"op":"mcm","clk":"4297091431","pt":1632571757638,"mc":[{"id":"1.188136695","rc":[{"batl":[[0,2.04,57.77]],"ltp":2.02,"tv":2201.9,"id":5300737},{"batb":[[1,1.96,191.02]],"batl":[[2,2.04,49.71]],"ltp":1.98,"tv":4988.21,"id":2497008}]}]}
{"op":"mcm","clk":"4297092769","pt":1632571764579,"mc":[{"id":"1.188136695","rc":[{"batl":[[0,2.04,58.63]],"ltp":2.02,"tv":2201.9,"id":5300737},{"batb":[[1,1.96,189.31]],"batl":[[2,2.04,51.43]],"ltp":1.98,"tv":4988.21,"id":2497008}]}]}
{"op":"mcm","clk":"4297094284","pt":1632571772074,"mc":[{"id":"1.188136695","rc":[{"batb":[[0,2,24]],"ltp":2.02,"tv":2201.9,"id":5300737}]}]}
{"op":"mcm","clk":"4297096747","pt":1632571782787,"mc":[{"id":"1.188136695","rc":[{"batb":[[0,1.97,43.63]],"ltp":1.98,"tv":4988.21,"id":2497008}]}]}
{"op":"mcm","clk":"4297103543","pt":1632571814646,"mc":[{"id":"1.188136695","rc":[{"batl":[[0,2,69.22]],"ltp":1.98,"tv":4988.21,"id":2497008}]}]}
{"op":"mcm","clk":"4297118475","pt":1632571885310,"mc":[{"id":"1.188136695","rc":[{"trd":[[2,593.84]],"batb":[[0,2,22]],"ltp":2.0,"tv":2205.9,"id":5300737}],"tv":7194.11}]}
{"op":"mcm","clk":"4297199172","pt":1632572237012,"mc":[{"id":"1.188136695","rc":[{"trd":[[1.97,1047.77]],"batb":[[0,1.97,37.26]],"ltp":1.97,"tv":5000.95,"id":2497008}],"tv":7206.85}]}
{"op":"mcm","clk":"4297210750","pt":1632572290287,"mc":[{"id":"1.188136695","rc":[{"batb":[[1,1.99,23.72]],"ltp":2.0,"tv":2205.9,"id":5300737},{"batb":[[2,1.95,32.57]],"ltp":1.97,"tv":5000.95,"id":2497008}]}]}
{"op":"mcm","clk":"4297256245","pt":1632572492772,"mc":[{"id":"1.188136695","rc":[{"batl":[[0,1.99,16.91],[1,2,52.31],[2,2.02,12]],"ltp":1.97,"tv":5000.95,"id":2497008}]}]}
{"op":"mcm","clk":"4297258296","pt":1632572501418,"mc":[{"id":"1.188136695","rc":[{"batb":[[0,1.97,14.26]],"ltp":1.97,"tv":5000.95,"id":2497008}]}]}
{"op":"mcm","clk":"4297354322","pt":1632572964892,"mc":[{"id":"1.188136695","rc":[{"trd":[[2.04,911.65]],"batl":[[0,2.04,45.36]],"ltp":2.04,"tv":2232.44,"id":5300737}],"tv":7233.4}]}
{"op":"mcm","clk":"4297362966","pt":1632573007756,"mc":[{"id":"1.188136695","rc":[{"batl":[[0,2.04,49],[1,2.06,8],[2,2.08,9]],"ltp":2.04,"tv":2232.44,"id":5300737},{"trd":[[1.96,697.62],[1.97,1076.29]],"batb":[[0,1.97,9],[1,1.96,176.38],[2,1.95,23.57]],"ltp":1.96,"tv":5035.32,"id":2497008}],"tv":7267.76}]}
{"op":"mcm","clk":"4297363027","pt":1632573008056,"mc":[{"id":"1.188136695","rc":[{"batb":[[0,2,23.33],[1,1.99,25.04]],"batl":[[0,2.04,50.3],[1,2.06,9.3]],"ltp":2.04,"tv":2232.44,"id":5300737},{"batb":[[1,1.96,179.24]],"batl":[[2,2.02,14.85]],"ltp":1.96,"tv":5035.32,"id":2497008}]}]}
{"op":"mcm","clk":"4297363803","pt":1632573011753,"mc":[{"id":"1.188136695","rc":[{"batb":[[0,2,65.97],[2,1.98,14.34]],"batl":[[2,2.08,10.31]],"ltp":2.04,"tv":2232.44,"id":5300737}]}]}
{"op":"mcm","clk":"4297402484","pt":1632573196787,"mc":[{"id":"1.188136695","rc":[{"trd":[[1.97,1093.28]],"batb":[[0,1.97,2.15]],"batl":[[0,1.99,18.54]],"ltp":1.97,"tv":5052.31,"id":2497008}],"tv":7284.76}]}
{"op":"mcm","clk":"4297402581","pt":1632573197104,"mc":[{"id":"1.188136695","rc":[{"batl":[[0,2.04,43.3],[1,2.06,1.3],[2,2.08,1.31]],"ltp":2.04,"tv":2232.44,"id":5300737},{"batb":[[0,1.97,1.65],[1,1.96,169.24],[2,1.95,14.22]],"batl":[[0,1.99,43.97]],"ltp":1.97,"tv":5052.31,"id":2497008}]}]}
{"op":"mcm","clk":"4297445505","pt":1632573390622,"mc":[{"id":"1.188136695","rc":[{"batb":[[2,1.95,1.65]],"ltp":1.97,"tv":5052.31,"id":2497008}]}]}
{"op":"mcm","clk":"4297486039","pt":1632573573684,"mc":[{"id":"1.188136695","rc":[{"trd":[[2,614.23]],"batb":[[0,2,53.97]],"batl":[[0,2.04,58.3]],"ltp":2.0,"tv":2252.83,"id":5300737},{"trd":[[1.99,87.94],[2,125.01]],"batb":[[0,1.97,20.29],[1,1.96,52.57]],"batl":[[0,2,8],[1,2.02,14.85],[2,2.04,51.43]],"ltp":2.0,"tv":5265.26,"id":2497008}],"tv":7518.1}]}
{"op":"mcm","clk":"4297486266","pt":1632573574756,"mc":[{"id":"1.188136695","rc":[{"batb":[[0,2,11.33]],"batl":[[0,2.02,15.64],[1,2.04,58.3],[2,2.06,1.3]],"ltp":2.0,"tv":2252.83,"id":5300737}]}]}
{"op":"mcm","clk":"4297486372","pt":1632573575252,"mc":[{"id":"1.188136695","rc":[{"batb":[[0,1.98,19.57],[1,1.97,20.29],[2,1.96,52.57]],"ltp":2.0,"tv":5265.26,"id":2497008}]}]}
{"op":"mcm","clk":"4297488282","pt":1632573584274,"mc":[{"id":"1.188136695","rc":[{"batb":[[1,1.99,41.05]],"ltp":2.0,"tv":2252.83,"id":5300737}]}]}
{"op":"mcm","clk":"4297495407","pt":1632573615707,"mc":[{"id":"1.188136695","rc":[{"batb":[[0,1.99,5],[1,1.98,24.57],[2,1.97,39.83]],"ltp":2.0,"tv":5265.26,"id":2497008}]}]}
{"op":"mcm","clk":"4297495573","pt":1632573616303,"mc":[{"id":"1.188136695","rc":[{"batb":[[0,1.99,5.95]],"ltp":2.0,"tv":5265.26,"id":2497008}]}]}
{"op":"mcm","clk":"4297495898","pt":1632573617711,"mc":[{"id":"1.188136695","rc":[{"batb":[[0,1.99,34.05],[1,1.98,14.34],[2,1.97,1.48]],"ltp":2.0,"tv":2252.83,"id":5300737},{"batl":[[0,2.02,5],[1,2.3,5.85],[2,2.34,2.19]],"ltp":2.0,"tv":5265.26,"id":2497008}]}]}
{"op":"mcm","clk":"4297496037","pt":1632573618332,"mc":[{"id":"1.188136695","rc":[{"batb":[[0,1.99,33.75]],"batl":[[0,2.02,16.65]],"ltp":2.0,"tv":2252.83,"id":5300737},{"batb":[[0,1.99,21.29],[2,1.97,29.19]],"ltp":2.0,"tv":5265.26,"id":2497008}]}]}
{"op":"mcm","clk":"4297496325","pt":1632573619504,"mc":[{"id":"1.188136695","rc":[{"batb":[[0,1.99,17.74]],"ltp":2.0,"tv":2252.83,"id":5300737},{"batl":[[1,2.3,19.7]],"ltp":2.0,"tv":5265.26,"id":2497008}]}]}
{"op":"mcm","clk":"4297503877","pt":1632573652660,"mc":[{"id":"1.188136695","rc":[{"batb":[[0,1.99,10.74],[1,1.98,6.34]],"ltp":2.0,"tv":2252.83,"id":5300737},{"batb":[[1,1.98,10.93]],"ltp":2.0,"tv":5265.26,"id":2497008}]}]}
{"op":"mcm","clk":"4297506024","pt":1632573663367,"mc":[{"id":"1.188136695","rc":[{"batb":[[2,1.97,9.65]],"ltp":2.0,"tv":5265.26,"id":2497008}]}]}
{"op":"mcm","clk":"4297511684","pt":1632573690696,"mc":[{"id":"1.188136695","rc":[{"batb":[[0,1.98,5],[1,1.97,1.48],[2,1.93,27.65]],"batl":[[1,2.04,51.3]],"ltp":2.0,"tv":2252.83,"id":5300737},{"batl":[[0,2.04,3]],"ltp":2.0,"tv":5265.26,"id":2497008}]}]}
{"op":"mcm","clk":"4297511797","pt":1632573691400,"mc":[{"id":"1.188136695","rc":[{"batb":[[1,1.79,32.54],[2,1.78,16.01]],"ltp":2.0,"tv":2252.83,"id":5300737}]}]}
{"op":"mcm","clk":"4297512614","pt":1632573695690,"mc":[{"id":"1.188136695","rc":[{"batb":[[0,1.95,4.38],[2,1.7,21.24]],"ltp":2.0,"tv":2252.83,"id":5300737}]}]}
{"op":"mcm","clk":"4297512758","pt":1632573696392,"mc":[{"id":"1.188136695","rc":[{"batb":[[1,1.77,33.39]],"ltp":2.0,"tv":2252.83,"id":5300737}]}]}
{"op":"mcm","clk":"4297513309","pt":1632573698829,"mc":[{"id":"1.188136695","rc":[{"batl":[[1,2.3,5.85]],"ltp":2.0,"tv":5265.26,"id":2497008}]}]}
{"op":"mcm","clk":"4297515441","pt":1632573708745,"mc":[{"id":"1.188136695","rc":[{"batb":[[0,1.97,41.14],[1,1.95,4.38],[2,1.77,33.39]],"ltp":2.0,"tv":2252.83,"id":5300737},{"batl":[[0,2.04,53.57]],"ltp":2.0,"tv":5265.26,"id":2497008}]}]}
{"op":"mcm","clk":"4297515587","pt":1632573709446,"mc":[{"id":"1.188136695","rc":[{"batb":[[0,1.97,45.14],[2,1.93,27.65]],"ltp":2.0,"tv":2252.83,"id":5300737}]}]}
{"op":"mcm","clk":"4297517537","pt":1632573718931,"mc":[{"id":"1.188136695","rc":[{"batb":[[2,1.97,30.63]],"ltp":2.0,"tv":5265.26,"id":2497008}]}]}
{"op":"mcm","clk":"4297528776","pt":1632573774402,"mc":[{"id":"1.188136695","rc":[{"batb":[[0,1.97,61.31]],"ltp":2.0,"tv":2252.83,"id":5300737}]}]}
{"op":"mcm","clk":"4297539813","pt":1632573826244,"mc":[{"id":"1.188136695","rc":[{"batl":[[0,2.04,3],[1,2.1,126],[2,2.3,5.85]],"ltp":2.0,"tv":5265.26,"id":2497008}]}]}
{"op":"mcm","clk":"4297541040","pt":1632573832260,"mc":[{"id":"1.188136695","rc":[{"batl":[[1,2.08,15.32],[2,2.1,126]],"ltp":2.0,"tv":5265.26,"id":2497008}]}]}
{"op":"mcm","clk":"4297541770","pt":1632573835696,"mc":[{"id":"1.188136695","rc":[{"batb":[[0,1.97,45.14]],"ltp":2.0,"tv":2252.83,"id":5300737}]}]}
{"op":"mcm","clk":"4297551419","pt":1632573881748,"mc":[{"id":"1.188136695","rc":[{"batb":[[0,1.99,27.29]],"ltp":2.0,"tv":5265.26,"id":2497008}]}]}
{"op":"mcm","clk":"4297564835","pt":1632573943828,"mc":[{"id":"1.188136695","rc":[{"batb":[[0,1.98,6.23],[1,1.97,45.14],[2,1.95,4.38]],"batl":[[0,2,4],[1,2.02,16.65],[2,2.04,51.3]],"ltp":2.0,"tv":2252.83,"id":5300737},{"batb":[[0,2,4.63],[1,1.99,27.29],[2,1.98,10.93]],"batl":[[0,2.04,56.14],[2,2.3,5.85]],"ltp":2.0,"tv":5265.26,"id":2497008}]}]}
{"op":"mcm","clk":"4297564982","pt":1632573944535,"mc":[{"id":"1.188136695","rc":[{"batl":[[0,2,16.51],[1,2.02,10.01]],"ltp":2.0,"tv":2252.83,"id":5300737},{"batb":[[0,2,18.14]],"ltp":2.0,"tv":5265.26,"id":2497008}]}]}
{"op":"mcm","clk":"4297574556","pt":1632573990986,"mc":[{"id":"1.188136695","rc":[{"batl":[[0,2,12.51]],"ltp":2.0,"tv":2252.83,"id":5300737},{"batb":[[0,2,14.14],[2,1.98,15.93]],"ltp":2.0,"tv":5265.26,"id":2497008}]}]}
{"op":"mcm","clk":"4297575335","pt":1632573994762,"mc":[{"id":"1.188136695","rc":[{"batl":[[1,2.3,5.85],[2,2.34,2.19]],"ltp":2.0,"tv":5265.26,"id":2497008}]}]}
{"op":"mcm","clk":"4297575352","pt":1632573994857,"mc":[{"id":"1.188136695","rc":[{"batb":[[1,1.97,61.31]],"ltp":2.0,"tv":2252.83,"id":5300737},{"batb":[[1,1.99,48.27]],"ltp":2.0,"tv":5265.26,"id":2497008}]}]}
{"op":"mcm","clk":"4297631273","pt":1632574295759,"mc":[{"id":"1.188136695","rc":[{"batb":[[0,1.97,20.89],[1,1.95,4.38],[2,1.94,53.14]],"batl":[[1,2.02,61.44],[2,2.04,9.3]],"ltp":2.0,"tv":2252.83,"id":5300737},{"batb":[[1,1.99,84.42]],"batl":[[0,2.04,3],[1,2.06,43.71],[2,2.3,5.85]],"ltp":2.0,"tv":5265.26,"id":2497008}]}]}
{"op":"mcm","clk":"4297631389","pt":1632574296366,"mc":[{"id":"1.188136695","rc":[{"batb":[[0,1.97,20.17]],"ltp":2.0,"tv":2252.83,"id":5300737}]}]}
{"op":"mcm","clk":"4297632273","pt":1632574301763,"mc":[{"id":"1.188136695","rc":[{"batb":[[0,1.96,6.17]],"ltp":2.0,"tv":2252.83,"id":5300737}]}]}
{"op":"mcm","clk":"4297632347","pt":1632574302150,"mc":[{"id":"1.188136695","rc":[{"batb":[[0,1.96,5.38],[1,1.95,5.18],[2,1.94,53.94]],"ltp":2.0,"tv":2252.83,"id":5300737}]}]}
{"op":"mcm","clk":"4297698556","pt":1632574645041,"mc":[{"id":"1.188136695","rc":[{"trd":[[1.96,10]],"batb":[[0,1.95,5.56],[1,1.94,53.94],[2,1.91,28.26]],"ltp":1.96,"tv":2262.83,"id":5300737}],"tv":7528.1}]}
{"op":"mcm","clk":"4297742474","pt":1632574817771,"mc":[{"id":"1.188136695","rc":[{"batb":[[0,1.96,41.52],[1,1.95,5.18],[2,1.91,29.06]],"batl":[[1,2.02,43.44]],"ltp":1.96,"tv":2262.83,"id":5300737},{"batb":[[1,1.99,43.27],[2,1.98,57.93]],"batl":[[1,2.06,59.14]],"ltp":2.0,"tv":5265.26,"id":2497008}]}]}
{"op":"mcm","clk":"4297742549","pt":1632574818072,"mc":[{"id":"1.188136695","rc":[{"batb":[[0,1.96,42.33]],"ltp":1.96,"tv":2262.83,"id":5300737}]}]}
{"op":"mcm","clk":"4297746585","pt":1632574830990,"mc":[{"id":"1.188136695","rc":[{"trd":[[2,135.01]],"batb":[[0,2,9.14]],"ltp":2.0,"tv":5275.26,"id":2497008}],"tv":7538.1}]}
{"op":"mcm","clk":"4297748387","pt":1632574837685,"mc":[{"id":"1.188136695","rc":[{"batb":[[0,1.96,1.19]],"ltp":1.96,"tv":2262.83,"id":5300737},{"batl":[[1,2.3,5.85],[2,2.34,2.19]],"ltp":2.0,"tv":5275.26,"id":2497008}]}]}
{"op":"mcm","clk":"4297748608","pt":1632574838375,"mc":[{"id":"1.188136695","rc":[{"batb":[[0,1.95,4.38],[1,1.77,34.19],[2,1.7,21.24]],"ltp":1.96,"tv":2262.83,"id":5300737},{"batb":[[0,2,9.9]],"batl":[[0,2.06,17.12]],"ltp":2.0,"tv":5275.26,"id":2497008}]}]}
{"op":"mcm","clk":"4297754219","pt":1632574858789,"mc":[{"id":"1.188136695","rc":[{"batb":[[0,1.94,79.55],[1,1.77,33.39]],"batl":[[0,2,13.07]],"ltp":1.96,"tv":2262.83,"id":5300737}]}]}
{"op":"mcm","clk":"4297754367","pt":1632574859314,"mc":[{"id":"1.188136695","rc":[{"batb":[[0,1.95,5.93],[1,1.94,79.55],[2,1.91,28.26]],"ltp":1.96,"tv":2262.83,"id":5300737}]}]}
{"op":"mcm","clk":"4297758009","pt":1632574873637,"mc":[{"id":"1.188136695","rc":[{"batb":[[0,1.97,6.13],[1,1.96,41.9],[2,1.95,5.93]],"batl":[[0,2,12.51]],"ltp":1.96,"tv":2262.83,"id":5300737},{"batl":[[0,2.04,4.37],[1,2.06,77.12],[2,2.3,5.85]],"ltp":2.0,"tv":5275.26,"id":2497008}]}]}
{"op":"mcm","clk":"4297766948","pt":1632574907474,"mc":[{"id":"1.188136695","rc":[{"batl":[[0,2.04,19.99],[1,2.06,64]],"ltp":2.0,"tv":5275.26,"id":2497008}]}]}
{"op":"mcm","clk":"4297790124","pt":1632574991538,"mc":[{"id":"1.188136695","rc":[{"batb":[[2,1.95,22.58]],"ltp":1.96,"tv":2262.83,"id":5300737},{"batb":[[1,1.99,52.29]],"ltp":2.0,"tv":5275.26,"id":2497008}]}]}
{"op":"mcm","clk":"4297802760","pt":1632575033462,"mc":[{"id":"1.188136695","rc":[{"batb":[[1,1.96,58.15]],"ltp":1.96,"tv":2262.83,"id":5300737}]}]}
{"op":"mcm","clk":"4297804397","pt":1632575039186,"mc":[{"id":"1.188136695","rc":[{"batb":[[1,1.96,41.9],[2,1.95,38.83]],"ltp":1.96,"tv":2262.83,"id":5300737}]}]}
{"op":"mcm","clk":"4297812571","pt":1632575069233,"mc":[{"id":"1.188136695","rc":[{"trd":[[2,633.09]],"batl":[[0,2,3.08],[1,2.02,42.43]],"ltp":2.0,"tv":2281.69,"id":5300737}],"tv":7556.96}]}
{"op":"mcm","clk":"4297813222","pt":1632575071744,"mc":[{"id":"1.188136695","rc":[{"trd":[[2,636.17]],"batb":[[2,1.95,22.58]],"batl":[[0,2.02,42.43],[1,2.04,9.3],[2,2.06,1.3]],"ltp":2.0,"tv":2284.77,"id":5300737},{"trd":[[2,157.89]],"batb":[[0,1.99,52.29],[1,1.98,57.93],[2,1.97,9.65]],"batl":[[0,2,1314.41],[1,2.04,19.99],[2,2.06,64]],"ltp":2.0,"tv":5298.14,"id":2497008}],"tv":7582.92}]}
{"op":"mcm","clk":"4297813367","pt":1632575072236,"mc":[{"id":"1.188136695","rc":[{"trd":[[2,641.17]],"batb":[[0,2,7],[1,1.97,6.13],[2,1.96,58.15]],"batl":[[0,2.02,38.1]],"ltp":2.0,"tv":2289.77,"id":5300737},{"trd":[[2,174.89]],"batb":[[0,1.99,36]],"batl":[[0,2,1309.41]],"ltp":2.0,"tv":5315.14,"id":2497008}],"tv":7604.92}]}
{"op":"mcm","clk":"4297815717","pt":1632575081268,"mc":[{"id":"1.188136695","rc":[{"batb":[[0,1.99,15.02]],"ltp":2.0,"tv":5315.14,"id":2497008}]}]}
{"op":"mcm","clk":"4297818426","pt":1632575091664,"mc":[{"id":"1.188136695","rc":[{"trd":[[2,650.86]],"batb":[[0,2,2.16]],"ltp":2.0,"tv":2299.45,"id":5300737},{"batb":[[0,1.99,6]],"ltp":2.0,"tv":5315.14,"id":2497008}],"tv":7614.6}]}
{"op":"mcm","clk":"4297819489","pt":1632575095774,"mc":[{"id":"1.188136695","rc":[{"batl":[[0,2,1311.41]],"ltp":2.0,"tv":5315.14,"id":2497008}]}]}
{"op":"mcm","clk":"4297824140","pt":1632575112958,"mc":[{"id":"1.188136695","rc":[{"batb":[[2,1.96,41.9]],"ltp":2.0,"tv":2299.45,"id":5300737},{"batl":[[1,2.04,4.37]],"ltp":2.0,"tv":5315.14,"id":2497008}]}]}
{"op":"mcm","clk":"4297830220","pt":1632575134166,"mc":[{"id":"1.188136695","rc":[{"batb":[[1,1.97,50.13]],"ltp":2.0,"tv":2299.45,"id":5300737}]}]}
{"op":"mcm","clk":"4297841418","pt":1632575173615,"mc":[{"id":"1.188136695","rc":[{"batl":[[0,2.02,45.81]],"ltp":2.0,"tv":2299.45,"id":5300737}]}]}
{"op":"mcm","clk":"4297871553","pt":1632575282674,"mc":[{"id":"1.188136695","rc":[{"trd":[[1.99,101.2]],"batb":[[0,1.98,57.93],[1,1.97,9.65],[2,1.96,5.08]],"batl":[[0,1.99,1296.78],[1,2,8],[2,2.04,4.37]],"ltp":1.99,"tv":5328.4,"id":2497008}],"tv":7627.86}]}
{"op":"mcm","clk":"4297871767","pt":1632575283360,"mc":[{"id":"1.188136695","rc":[{"batb":[[0,2,32],[1,1.99,33.89],[2,1.97,73.76]],"batl":[[0,2.02,41.14],[1,2.04,24.3]],"ltp":2.0,"tv":2299.45,"id":5300737},{"batb":[[0,1.98,47],[1,1.97,30.65]],"batl":[[0,1.99,1322.78],[1,2,28],[2,2.04,23]],"ltp":1.99,"tv":5328.4,"id":2497008}]}]}
{"op":"mcm","clk":"4297874463","pt":1632575292851,"mc":[{"id":"1.188136695","rc":[{"trd":[[1.99,111.45]],"batl":[[0,1.99,1317.65]],"ltp":1.99,"tv":5338.65,"id":2497008}],"tv":7638.11}]}
{"op":"mcm","clk":"4297875978","pt":1632575297774,"mc":[{"id":"1.188136695","rc":[{"trd":[[2.02,258.19]],"batb":[[0,2,33.34]],"batl":[[0,2.04,59.78],[1,2.06,1.3],[2,2.08,1.31]],"ltp":2.02,"tv":2363.59,"id":5300737},{"trd":[[1.97,3475.06],[1.98,168.54]],"batb":[[0,1.96,2.22],[1,1.93,1.86],[2,1.92,451.78]],"batl":[[0,2,28],[1,2.04,23],[2,2.06,83]],"ltp":1.97,"tv":7856.4,"id":2497008}],"tv":10219.99}]}
{"op":"mcm","clk":"4297876256","pt":1632575298758,"mc":[{"id":"1.188136695","rc":[{"batb":[[0,2,61.34]],"batl":[[0,2.04,36.78]],"ltp":2.02,"tv":2363.59,"id":5300737},{"batb":[[0,1.96,58.34]],"batl":[[0,2,57]],"ltp":1.97,"tv":7856.4,"id":2497008}]}]}
{"op":"mcm","clk":"4297876555","pt":1632575299749,"mc":[{"id":"1.188136695","rc":[{"batb":[[2,1.98,59.14]],"batl":[[1,2.06,44.16]],"ltp":2.02,"tv":2363.59,"id":5300737},{"batb":[[1,1.94,50.64],[2,1.92,452.71]],"batl":[[1,2.02,61.71],[2,2.04,23]],"ltp":1.97,"tv":7856.4,"id":2497008}]}]}
{"op":"mcm","clk":"4297876718","pt":1632575300357,"mc":[{"id":"1.188136695","rc":[{"batb":[[2,1.98,60.51]],"batl":[[0,2.04,1.3]],"ltp":2.02,"tv":2363.59,"id":5300737},{"batb":[[0,1.96,2.22],[2,1.92,424.76]],"batl":[[0,2,58.15]],"ltp":1.97,"tv":7856.4,"id":2497008}]}]}
{"op":"mcm","clk":"4297878280","pt":1632575306168,"mc":[{"id":"1.188136695","rc":[{"batb":[[1,1.95,17.36],[2,1.94,50.64]],"ltp":1.97,"tv":7856.4,"id":2497008}]}]}
{"op":"mcm","clk":"4297880019","pt":1632575312768,"mc":[{"id":"1.188136695","rc":[{"batb":[[1,1.95,18.69]],"batl":[[0,1.99,17.33],[1,2,58.15],[2,2.02,63.03]],"ltp":1.97,"tv":7856.4,"id":2497008}]}]}
{"op":"mcm","clk":"4297880098","pt":1632575313052,"mc":[{"id":"1.188136695","rc":[{"batb":[[0,2.02,60.21],[1,2,61.34],[2,1.99,33.89]],"batl":[[0,2.06,44.16],[1,2.08,1.31],[2,2.1,11.49]],"ltp":2.02,"tv":2363.59,"id":5300737},{"batl":[[0,1.99,71.94]],"ltp":1.97,"tv":7856.4,"id":2497008}]}]}
{"op":"mcm","clk":"4297881997","pt":1632575320381,"mc":[{"id":"1.188136695","rc":[{"batb":[[1,1.95,1.33]],"ltp":1.97,"tv":7856.4,"id":2497008}]}]}
{"op":"mcm","clk":"4297888654","pt":1632575345732,"mc":[{"id":"1.188136695","rc":[{"batb":[[0,2.02,75.98]],"ltp":2.02,"tv":2363.59,"id":5300737},{"batl":[[0,1.99,55.93]],"ltp":1.97,"tv":7856.4,"id":2497008}]}]}
{"op":"mcm","clk":"4297888820","pt":1632575346358,"mc":[{"id":"1.188136695","rc":[{"batb":[[1,2,34.34],[2,1.99,18.3]],"ltp":2.02,"tv":2363.59,"id":5300737},{"batl":[[0,1.98,64.27],[1,1.99,31.32],[2,2,17.15]],"ltp":1.97,"tv":7856.4,"id":2497008}]}]}
{"op":"mcm","clk":"4297892107","pt":1632575358781,"mc":[{"id":"1.188136695","rc":[{"batl":[[0,1.98,48.26]],"ltp":1.97,"tv":7856.4,"id":2497008}]}]}
{"op":"mcm","clk":"4297893759","pt":1632575364582,"mc":[{"id":"1.188136695","rc":[{"batb":[[0,2.02,60.21]],"ltp":2.02,"tv":2363.59,"id":5300737}]}]}
{"op":"mcm","clk":"4297901390","pt":1632575392832,"mc":[{"id":"1.188136695","rc":[{"trd":[[1.98,179.02]],"batl":[[0,1.98,43.02]],"ltp":1.98,"tv":7866.87,"id":2497008}],"tv":10230.47}]}
{"op":"mcm","clk":"4297925497","pt":1632575480786,"mc":[{"id":"1.188136695","rc":[{"batb":[[2,1.99,69.73]],"ltp":2.02,"tv":2363.59,"id":5300737}]}]}
{"op":"mcm","clk":"4297928981","pt":1632575494779,"mc":[{"id":"1.188136695","rc":[{"batb":[[0,2.02,1.6],[2,1.99,18.3]],"batl":[[0,2.06,113.42]],"ltp":2.02,"tv":2363.59,"id":5300737},{"batb":[[0,1.96,53.65],[2,1.93,1.86]],"batl":[[2,2,11.15]],"ltp":1.98,"tv":7866.87,"id":2497008}]}]}
{"op":"mcm","clk":"4297929448","pt":1632575496490,"mc":[{"id":"1.188136695","rc":[{"batl":[[0,1.98,1.63],[2,2,23.15]],"ltp":1.98,"tv":7866.87,"id":2497008}]}]}
{"op":"mcm","clk":"4297934708","pt":1632575516752,"mc":[{"id":"1.188136695","rc":[{"batb":[[1,1.95,17.67]],"ltp":1.98,"tv":7866.87,"id":2497008}]}]}
{"op":"mcm","clk":"4297957454","pt":1632575600792,"mc":[{"id":"1.188136695","rc":[{"trd":[[2.02,259.79]],"batb":[[0,2,34.34],[1,1.99,18.3],[2,1.98,1.37]],"ltp":2.02,"tv":2365.19,"id":5300737},{"trd":[[1.98,182.28],[1.99,186.57]],"batl":[[0,2,22],[1,2.02,1.32],[2,2.04,68.47]],"ltp":1.99,"tv":7945.25,"id":2497008}],"tv":10310.45}]}
{"op":"mcm","clk":"4297957735","pt":1632575601666,"mc":[{"id":"1.188136695","rc":[{"batb":[[0,1.96,54.36]],"batl":[[0,1.99,28.41],[1,2,22],[2,2.02,1.32]],"ltp":1.99,"tv":7945.25,"id":2497008}]}]}
{"op":"mcm","clk":"4297963484","pt":1632575622001,"mc":[{"id":"1.188136695","rc":[{"batl":[[0,2,22],[1,2.02,1.32],[2,2.04,68.47]],"ltp":1.99,"tv":7945.25,"id":2497008}]}]}
{"op":"mcm","clk":"4297969690","pt":1632575645458,"mc":[{"id":"1.188136695","rc":[{"batb":[[1,1.95,1.33]],"ltp":1.99,"tv":7945.25,"id":2497008}]}]}
{"op":"mcm","clk":"4297969970","pt":1632575646556,"mc":[{"id":"1.188136695","rc":[{"batl":[[0,2,20]],"ltp":1.99,"tv":7945.25,"id":2497008}]}]}
{"op":"mcm","clk":"4297973152","pt":1632575657659,"mc":[{"id":"1.188136695","rc":[{"trd":[[1.96,701.62]],"batb":[[0,1.96,52.36]],"ltp":1.96,"tv":7949.25,"id":2497008}],"tv":10314.45}]}
{"op":"mcm","clk":"4297990079","pt":1632575719781,"mc":[{"id":"1.188136695","rc":[{"batl":[[2,2.04,80]],"ltp":1.96,"tv":7949.25,"id":2497008}]}]}
{"op":"mcm","clk":"4297991443","pt":1632575724694,"mc":[{"id":"1.188136695","rc":[{"trd":[[2,690.86]],"batb":[[0,2,14.34]],"ltp":2.0,"tv":2405.19,"id":5300737}],"tv":10354.45}]}
{"op":"mcm","clk":"4298004849","pt":1632575771644,"mc":[{"id":"1.188136695","rc":[{"batb":[[0,2.02,34.51],[1,2,23.34],[2,1.99,18.3]],"ltp":2.0,"tv":2405.19,"id":5300737},{"batl":[[0,1.99,20],[1,2,20],[2,2.02,1.32]],"ltp":1.96,"tv":7949.25,"id":2497008}]}]}
{"op":"mcm","clk":"4298016292","pt":1632575814207,"mc":[{"id":"1.188136695","rc":[{"batl":[[2,2.02,1.47]],"ltp":1.96,"tv":7949.25,"id":2497008}]}]}
{"op":"mcm","clk":"4298018127","pt":1632575820810,"mc":[{"id":"1.188136695","rc":[{"trd":[[2.02,359.79]],"batb":[[0,2,23.34],[1,1.99,18.3],[2,1.98,1.37]],"ltp":2.02,"tv":2505.2,"id":5300737}],"tv":10454.45}]}
{"op":"mcm","clk":"4298018383","pt":1632575821712,"mc":[{"id":"1.188136695","rc":[{"batl":[[0,2,21.04],[1,2.02,1.47],[2,2.04,80]],"ltp":1.96,"tv":7949.25,"id":2497008}]}]}
{"op":"mcm","clk":"4298019732","pt":1632575826400,"mc":[{"id":"1.188136695","rc":[{"batl":[[1,2.08,1.41]],"ltp":2.02,"tv":2505.2,"id":5300737}]}]}
{"op":"mcm","clk":"4298051874","pt":1632575888804,"mc":[{"id":"1.188136695","rc":[{"batb":[[0,1.96,2372.27]],"ltp":1.96,"tv":7949.25,"id":2497008}]}]}
{"op":"mcm","clk":"4298051929","pt":1632575889024,"mc":[{"id":"1.188136695","rc":[{"batl":[[0,2,20],[1,2.04,80.15],[2,2.06,1.63]],"ltp":1.96,"tv":7949.25,"id":2497008}]}]}
{"op":"mcm","clk":"4298053432","pt":1632575893714,"mc":[{"id":"1.188136695","rc":[{"batl":[[0,2.04,4],[1,2.06,113.42],[2,2.08,1.41]],"ltp":2.02,"tv":2505.2,"id":5300737},{"batb":[[0,1.97,4],[1,1.96,2376.27],[2,1.95,1.33]],"batl":[[1,2.04,21]],"ltp":1.96,"tv":7949.25,"id":2497008}]}]}
{"op":"mcm","clk":"4298053740","pt":1632575894749,"mc":[{"id":"1.188136695","rc":[{"batb":[[0,2,1.34],[1,1.99,32.3]],"batl":[[0,2.04,15.64]],"ltp":2.02,"tv":2505.2,"id":5300737},{"batb":[[0,1.97,20.46]],"batl":[[1,2.04,29]],"ltp":1.96,"tv":7949.25,"id":2497008}]}]}
{"op":"mcm","clk":"4298053945","pt":1632575895411,"mc":[{"id":"1.188136695","rc":[{"trd":[[1.97,3508.16]],"batb":[[0,1.97,3.91]],"ltp":1.97,"tv":7982.36,"id":2497008}],"tv":10487.56}]}
{"op":"mcm","clk":"4298055856","pt":1632575901739,"mc":[{"id":"1.188136695","rc":[{"trd":[[2,692.2]],"batb":[[0,1.98,36.6],[1,1.97,76.76],[2,1.95,28.4]],"batl":[[0,2.02,21.6],[1,2.04,26.04],[2,2.06,113.42]],"ltp":2.0,"tv":2506.54,"id":5300737},{"trd":[[2,216.23]],"batb":[[0,1.97,18]],"batl":[[0,2.02,27.01],[1,2.04,38.86]],"ltp":2.0,"tv":8023.69,"id":2497008}],"tv":10530.23}]}
{"op":"mcm","clk":"4298055971","pt":1632575902118,"mc":[{"id":"1.188136695","rc":[{"batb":[[1,1.97,76]],"batl":[[0,2.02,22.7],[2,2.06,79.3]],"ltp":2.0,"tv":2506.54,"id":5300737},{"batb":[[0,1.99,27.6],[1,1.97,18],[2,1.96,2376.27]],"ltp":2.0,"tv":8023.69,"id":2497008}]}]}
{"op":"mcm","clk":"4298056175","pt":1632575902842,"mc":[{"id":"1.188136695","rc":[{"batb":[[2,1.95,1.33]],"ltp":2.0,"tv":2506.54,"id":5300737}]}]}
{"op":"mcm","clk":"4298057320","pt":1632575906730,"mc":[{"id":"1.188136695","rc":[{"batb":[[2,1.96,56.36]],"ltp":2.0,"tv":8023.69,"id":2497008}]}]}
{"op":"mcm","clk":"4298058479","pt":1632575910685,"mc":[{"id":"1.188136695","rc":[{"trd":[[1.99,219.67]],"batb":[[0,1.96,2884.42],[1,1.95,1.33],[2,1.93,29.51]],"batl":[[0,2.02,41.41]],"ltp":1.99,"tv":8056.79,"id":2497008}],"tv":10563.33}]}
{"op":"mcm","clk":"4298058800","pt":1632575911753,"mc":[{"id":"1.188136695","rc":[{"batb":[[2,1.94,28.28]],"ltp":1.99,"tv":8056.79,"id":2497008}]}]}
{"op":"mcm","clk":"4298059926","pt":1632575915445,"mc":[{"id":"1.188136695","rc":[{"batb":[[1,1.97,129.14]],"ltp":2.0,"tv":2506.54,"id":5300737},{"batl":[[1,2.04,99.71]],"ltp":1.99,"tv":8056.79,"id":2497008}]}]}
{"op":"mcm","clk":"4298063504","pt":1632575927760,"mc":[{"id":"1.188136695","rc":[{"batb":[[2,1.95,28.4]],"batl":[[0,2.02,1.1],[1,2.04,28.66],[2,2.06,101.3]],"ltp":2.0,"tv":2506.54,"id":5300737},{"batb":[[0,1.98,29.62],[1,1.96,2802.7],[2,1.95,30.95]],"ltp":1.99,"tv":8056.79,"id":2497008}]}]}
{"op":"mcm","clk":"4298063782","pt":1632575928765,"mc":[{"id":"1.188136695","rc":[{"trd":[[1.98,12.3]],"batb":[[0,1.98,30.45],[2,1.95,1.33]],"ltp":1.98,"tv":2518.84,"id":5300737}],"tv":10575.63}]}
{"op":"mcm","clk":"4298067435","pt":1632575942194,"mc":[{"id":"1.188136695","rc":[{"batb":[[1,1.96,56.36]],"ltp":1.99,"tv":8056.79,"id":2497008}]}]}
{"op":"mcm","clk":"4298069345","pt":1632575949804,"mc":[{"id":"1.188136695","rc":[{"trd":[[2.02,360.89]],"batl":[[0,2.04,28.66],[1,2.06,101.3],[2,2.08,1.41]],"ltp":2.02,"tv":2519.94,"id":5300737},{"trd":[[1.98,242.64]],"batb":[[0,1.96,56.36],[1,1.95,30.95],[2,1.93,29.51]],"batl":[[0,1.98,148],[1,2.02,41.41],[2,2.04,99.71]],"ltp":1.98,"tv":8117.16,"id":2497008}],"tv":10637.1}]}
{"op":"mcm","clk":"4298069599","pt":1632575950793,"mc":[{"id":"1.188136695","rc":[{"batb":[[0,2.02,50],[1,1.99,13.54],[2,1.98,31.86]],"batl":[[0,2.04,17.34]],"ltp":2.02,"tv":2519.94,"id":5300737},{"trd":[[1.98,353.57]],"batb":[[0,1.97,13.82],[1,1.96,2895.94],[2,1.95,30.95]],"batl":[[0,1.98,138.53],[1,2.02,25.41]],"ltp":1.98,"tv":8228.08,"id":2497008}],"tv":10748.02}]}
{"op":"mcm","clk":"4298069764","pt":1632575951502,"mc":[{"id":"1.188136695","rc":[{"batb":[[0,2,51.63]],"batl":[[0,2.04,36.34]],"ltp":2.02,"tv":2519.94,"id":5300737},{"batb":[[1,1.96,2921.94]],"batl":[[0,1.98,92.53],[1,1.99,45.63],[2,2.02,25.41]],"ltp":1.98,"tv":8228.08,"id":2497008}]}]}
{"op":"mcm","clk":"4298069916","pt":1632575952007,"mc":[{"id":"1.188136695","rc":[{"batb":[[0,2,65.23],[1,1.99,14.99]],"batl":[[0,2.04,37.76]],"ltp":2.02,"tv":2519.94,"id":5300737},{"trd":[[1.98,481.67]],"batl":[[0,1.98,28.48]],"ltp":1.98,"tv":8356.18,"id":2497008}],"tv":10876.13}]}
{"op":"mcm","clk":"4298074335","pt":1632575969819,"mc":[{"id":"1.188136695","rc":[{"batb":[[0,1.99,14.99],[1,1.98,1.41],[2,1.97,98.55]],"ltp":2.02,"tv":2519.94,"id":5300737},{"batb":[[1,1.96,96.1]],"batl":[[0,2.02,127.39],[1,2.04,73.71],[2,2.06,1.63]],"ltp":1.98,"tv":8356.18,"id":2497008}]}]}
{"op":"mcm","clk":"4298075814","pt":1632575976004,"mc":[{"id":"1.188136695","rc":[{"batl":[[0,2.02,2.41]],"ltp":1.98,"tv":8356.18,"id":2497008}]}]}
{"op":"mcm","clk":"4298076488","pt":1632575978726,"mc":[{"id":"1.188136695","rc":[{"batb":[[0,1.99,71.63]],"ltp":2.02,"tv":2519.94,"id":5300737},{"trd":[[1.97,3564.73]],"batb":[[0,1.96,96.1],[1,1.95,30.95],[2,1.93,29.51]],"batl":[[0,2.02,53.05]],"ltp":1.97,"tv":8412.76,"id":2497008}],"tv":10932.7}]}
{"op":"mcm","clk":"4298076511","pt":1632575978838,"mc":[{"id":"1.188136695","rc":[{"batb":[[0,1.96,2906.21]],"ltp":1.97,"tv":8412.76,"id":2497008}]}]}
{"op":"mcm","clk":"4298076787","pt":1632575979841,"mc":[{"id":"1.188136695","rc":[{"batb":[[2,1.93,1.86]],"ltp":1.97,"tv":8412.76,"id":2497008}]}]}
{"op":"mcm","clk":"4298082541","pt":1632576002644,"mc":[{"id":"1.188136695","rc":[{"batl":[[0,2.04,24.42]],"ltp":2.02,"tv":2519.94,"id":5300737},{"batb":[[0,1.96,2892.47]],"ltp":1.97,"tv":8412.76,"id":2497008}]}]}
{"op":"mcm","clk":"4298088731","pt":1632576024762,"mc":[{"id":"1.188136695","rc":[{"trd":[[1.99,40]],"batb":[[0,1.99,63.34],[1,1.98,64.75]],"batl":[[0,2.02,31.34],[1,2.04,36.42],[2,2.06,101.3]],"ltp":1.99,"tv":2559.94,"id":5300737},{"batb":[[0,1.97,40.33],[1,1.96,2908.47],[2,1.95,30.95]],"ltp":1.97,"tv":8412.76,"id":2497008}],"tv":10972.7}]}
{"op":"mcm","clk":"4298088849","pt":1632576025180,"mc":[{"id":"1.188136695","rc":[{"batb":[[0,1.98,64.75],[1,1.97,98.55],[2,1.95,1.33]],"batl":[[2,2.06,116.3]],"ltp":1.99,"tv":2559.94,"id":5300737},{"batb":[[0,1.98,43.34],[1,1.97,40.33],[2,1.96,2908.47]],"ltp":1.97,"tv":8412.76,"id":2497008}]}]}
{"op":"mcm","clk":"4298091422","pt":1632576034792,"mc":[{"id":"1.188136695","rc":[{"batb":[[2,1.96,98.36]],"ltp":1.97,"tv":8412.76,"id":2497008}]}]}
{"op":"mcm","clk":"4298095766","pt":1632576050728,"mc":[{"id":"1.188136695","rc":[{"trd":[[1.98,57.34]],"batb":[[0,1.98,42.23]],"ltp":1.98,"tv":2604.98,"id":5300737}],"tv":11017.74}]}
{"op":"mcm","clk":"4298095835","pt":1632576050935,"mc":[{"id":"1.188136695","rc":[{"batb":[[1,1.97,97.14]],"batl":[[0,2.02,32.95]],"ltp":1.98,"tv":2604.98,"id":5300737}]}]}
{"op":"mcm","clk":"4298101305","pt":1632576071613,"mc":[{"id":"1.188136695","rc":[{"trd":[[1.98,567.39]],"batb":[[0,1.97,40.81],[1,1.96,98.36],[2,1.95,30.95]],"ltp":1.98,"tv":8498.48,"id":2497008}],"tv":11103.46}]}
{"op":"mcm","clk":"4298101457","pt":1632576072116,"mc":[{"id":"1.188136695","rc":[{"batl":[[0,2.02,1.61],[1,2.04,18.42],[2,2.06,94.3]],"ltp":1.98,"tv":2604.98,"id":5300737},{"batb":[[0,1.98,17],[1,1.97,19],[2,1.96,77.36]],"ltp":1.98,"tv":8498.48,"id":2497008}]}]}
{"op":"mcm","clk":"4298106798","pt":1632576093238,"mc":[{"id":"1.188136695","rc":[{"batb":[[0,1.97,20.46],[1,1.96,77.36],[2,1.95,30.95]],"ltp":1.98,"tv":8498.48,"id":2497008}]}]}
{"op":"mcm","clk":"4298112933","pt":1632576116676,"mc":[{"id":"1.188136695","rc":[{"batl":[[1,2.04,5.42],[2,2.06,79.3]],"ltp":1.98,"tv":2604.98,"id":5300737},{"batb":[[0,1.97,1.46],[1,1.96,56.36],[2,1.95,1.33]],"ltp":1.98,"tv":8498.48,"id":2497008}]}]}
{"op":"mcm","clk":"4298113210","pt":1632576117884,"mc":[{"id":"1.188136695","rc":[{"batb":[[2,1.95,28.4]],"ltp":1.98,"tv":2604.98,"id":5300737}]}]}
{"op":"mcm","clk":"4298115370","pt":1632576126574,"mc":[{"id":"1.188136695","rc":[{"batl":[[1,2.04,57.7],[2,2.06,1.3]],"ltp":1.98,"tv":2604.98,"id":5300737}]}]}
{"op":"mcm","clk":"4298126863","pt":1632576170845,"mc":[{"id":"1.188136695","rc":[{"trd":[[1.98,91.62]],"batb":[[0,1.98,25.09]],"ltp":1.98,"tv":2639.26,"id":5300737}],"tv":11137.74}]}
{"op":"mcm","clk":"4298127898","pt":1632576174780,"mc":[{"id":"1.188136695","rc":[{"batb":[[0,1.97,21.86]],"ltp":1.98,"tv":8498.48,"id":2497008}]}]}
{"op":"mcm","clk":"4298127941","pt":1632576174936,"mc":[{"id":"1.188136695","rc":[{"batb":[[2,1.95,1.33]],"ltp":1.98,"tv":2639.26,"id":5300737}]}]}
{"op":"mcm","clk":"4298132938","pt":1632576194251,"mc":[{"id":"1.188136695","rc":[{"trd":[[2.02,362.5]],"batl":[[0,2.04,57.7],[1,2.06,1.3],[2,2.08,1.41]],"ltp":2.02,"tv":2640.87,"id":5300737},{"trd":[[1.97,3577.08],[1.98,569.03]],"batb":[[0,1.97,15.69],[1,1.96,55.65]],"ltp":1.97,"tv":8512.46,"id":2497008}],"tv":11153.34}]}
{"op":"mcm","clk":"4298133114","pt":1632576194961,"mc":[{"id":"1.188136695","rc":[{"batb":[[2,1.95,28.4]],"ltp":2.02,"tv":2640.87,"id":5300737}]}]}
{"op":"mcm","clk":"4298145366","pt":1632576246453,"mc":[{"id":"1.188136695","rc":[{"batb":[[0,1.97,2737.53]],"ltp":1.97,"tv":8512.46,"id":2497008}]}]}
{"op":"mcm","clk":"4298145797","pt":1632576248461,"mc":[{"id":"1.188136695","rc":[{"batb":[[2,1.95,1.33]],"batl":[[0,2.02,4.82],[1,2.04,57.7],[2,2.06,1.3]],"ltp":2.02,"tv":2640.87,"id":5300737},{"batb":[[0,1.98,4],[1,1.97,2740.53],[2,1.96,55.65]],"ltp":1.97,"tv":8512.46,"id":2497008}]}]}
{"op":"mcm","clk":"4298146538","pt":1632576251558,"mc":[{"id":"1.188136695","rc":[{"batb":[[1,1.97,44]],"batl":[[1,2.04,90.27]],"ltp":2.02,"tv":2640.87,"id":5300737},{"batb":[[2,1.96,89.07]],"batl":[[1,2.04,12.86]],"ltp":1.97,"tv":8512.46,"id":2497008}]}]}
{"op":"mcm","clk":"4298147891","pt":1632576257643,"mc":[{"id":"1.188136695","rc":[{"batl":[[0,2.02,15.51]],"ltp":2.02,"tv":2640.87,"id":5300737}]}]}
{"op":"mcm","clk":"4298148148","pt":1632576258754,"mc":[{"id":"1.188136695","rc":[{"batb":[[0,1.99,7.85],[1,1.98,25.09],[2,1.97,44]],"ltp":2.02,"tv":2640.87,"id":5300737},{"batb":[[1,1.97,18.69]],"ltp":1.97,"tv":8512.46,"id":2497008}]}]}
{"op":"mcm","clk":"4298148351","pt":1632576259677,"mc":[{"id":"1.188136695","rc":[{"batb":[[0,1.99,52.32]],"batl":[[1,2.04,108.27]],"ltp":2.02,"tv":2640.87,"id":5300737},{"batb":[[0,1.98,28.47]],"ltp":1.97,"tv":8512.46,"id":2497008}]}]}
{"op":"mcm","clk":"4298148619","pt":1632576260967,"mc":[{"id":"1.188136695","rc":[{"trd":[[1.98,588.15]],"batb":[[0,1.98,18.91]],"ltp":1.98,"tv":8531.58,"id":2497008}],"tv":11172.45}]}
{"op":"mcm","clk":"4298153880","pt":1632576283802,"mc":[{"id":"1.188136695","rc":[{"trd":[[2.02,373.37]],"batl":[[0,2.02,4.63],[1,2.04,104.27]],"ltp":2.02,"tv":2651.74,"id":5300737},{"trd":[[1.98,637.06]],"batb":[[0,1.97,18.69],[1,1.96,85.07],[2,1.95,1.33]],"ltp":1.98,"tv":8580.49,"id":2497008}],"tv":11232.23}]}
{"op":"mcm","clk":"4298153936","pt":1632576284071,"mc":[{"id":"1.188136695","rc":[{"batb":[[1,1.98,44]],"batl":[[1,2.04,86.27]],"ltp":2.02,"tv":2651.74,"id":5300737},{"batb":[[0,1.97,2790.45]],"ltp":1.98,"tv":8580.49,"id":2497008}]}]}
{"op":"mcm","clk":"4298163157","pt":1632576322564,"mc":[{"id":"1.188136695","rc":[{"trd":[[1.99,144.64]],"batb":[[0,1.98,44],[1,1.97,44],[2,1.95,28.4]],"ltp":1.99,"tv":2756.38,"id":5300737},{"batb":[[0,1.99,2235.25],[1,1.97,18.69],[2,1.96,85.07]],"ltp":1.98,"tv":8580.49,"id":2497008}],"tv":11336.88}]}
{"op":"mcm","clk":"4298163432","pt":1632576323727,"mc":[{"id":"1.188136695","rc":[{"batb":[[0,1.97,92.5],[1,1.95,1.33],[2,1.94,42.67]],"batl":[[0,2,29.5],[1,2.02,29.11],[2,2.04,86.27]],"ltp":1.99,"tv":2756.38,"id":5300737},{"batb":[[0,2,33.5],[1,1.99,2269.73],[2,1.97,18.69]],"batl":[[0,2.04,53],[1,2.06,1.63],[2,2.08,60.86]],"ltp":1.98,"tv":8580.49,"id":2497008}]}]}
{"op":"mcm","clk":"4298163680","pt":1632576324778,"mc":[{"id":"1.188136695","rc":[{"batb":[[2,1.93,4.26]],"ltp":1.99,"tv":2756.38,"id":5300737},{"batl":[[2,2.3,5.85]],"ltp":1.98,"tv":8580.49,"id":2497008}]}]}
{"op":"mcm","clk":"4298170148","pt":1632576352193,"mc":[{"id":"1.188136695","rc":[{"batb":[[0,2,2735.25],[1,1.99,30.48],[2,1.97,15.69]],"batl":[[0,2.04,51.67]],"ltp":1.98,"tv":8580.49,"id":2497008}]}]}
{"op":"mcm","clk":"4298172333","pt":1632576361704,"mc":[{"id":"1.188136695","rc":[{"batb":[[2,1.94,43.53]],"ltp":1.99,"tv":2756.38,"id":5300737},{"batb":[[2,1.98,69.43]],"batl":[[2,2.08,59.14]],"ltp":1.98,"tv":8580.49,"id":2497008}]}]}
{"op":"mcm","clk":"4298173006","pt":1632576364209,"mc":[{"id":"1.188136695","rc":[{"batb":[[0,2,43.35]],"batl":[[0,2.04,53.07]],"ltp":1.98,"tv":8580.49,"id":2497008}]}]}
{"op":"mcm","clk":"4298196323","pt":1632576459649,"mc":[{"id":"1.188136695","rc":[{"trd":[[2,693.8]],"batl":[[0,2,28.7],[1,2.02,30.34]],"ltp":2.0,"tv":2757.99,"id":5300737}],"tv":11338.48}]}
{"op":"mcm","clk":"4298197126","pt":1632576462642,"mc":[{"id":"1.188136695","rc":[{"batb":[[0,1.97,69]],"batl":[[0,2,4.2],[1,2.02,5.86]],"ltp":2.0,"tv":2757.99,"id":5300737},{"batb":[[0,2,12.85],[1,1.98,69.43],[2,1.97,15.69]],"batl":[[0,2.04,35.07]],"ltp":1.98,"tv":8580.49,"id":2497008}]}]}
{"op":"mcm","clk":"4298197344","pt":1632576463452,"mc":[{"id":"1.188136695","rc":[{"batb":[[0,1.98,24.58],[1,1.97,70.18],[2,1.95,1.33]],"batl":[[1,2.02,4.63]],"ltp":2.0,"tv":2757.99,"id":5300737},{"batl":[[0,2.02,23.73],[1,2.04,34.93],[2,2.06,1.63]],"ltp":1.98,"tv":8580.49,"id":2497008}]}]}
{"op":"mcm","clk":"4298199354","pt":1632576471350,"mc":[{"id":"1.188136695","rc":[{"batl":[[1,2.02,74.06],[2,2.04,1.42]],"ltp":2.0,"tv":2757.99,"id":5300737},{"batb":[[1,1.99,53.14]],"ltp":1.98,"tv":8580.49,"id":2497008}]}]}
{"op":"mcm","clk":"4298200086","pt":1632576474584,"mc":[{"id":"1.188136695","rc":[{"trd":[[2,697.86]],"batl":[[0,2.02,74.2],[1,2.04,1.42],[2,2.06,1.3]],"ltp":2.0,"tv":2762.05,"id":5300737},{"trd":[[2,245.99]],"batb":[[0,1.99,53.14],[1,1.97,15.69],[2,1.95,1.55]],"ltp":2.0,"tv":8610.25,"id":2497008}],"tv":11372.3}]}
{"op":"mcm","clk":"4298200276","pt":1632576474923,"mc":[{"id":"1.188136695","rc":[{"batb":[[1,1.97,69]],"ltp":2.0,"tv":2762.05,"id":5300737},{"batb":[[0,1.99,2781.07]],"ltp":2.0,"tv":8610.25,"id":2497008}]}]}
{"op":"mcm","clk":"4298206731","pt":1632576499793,"mc":[{"id":"1.188136695","rc":[{"batb":[[0,2,293.99],[1,1.99,2781.07],[2,1.97,15.69]],"ltp":2.0,"tv":8610.25,"id":2497008}]}]}
{"op":"mcm","clk":"4298206887","pt":1632576500498,"mc":[{"id":"1.188136695","rc":[{"batb":[[0,1.97,112],[1,1.94,44.1],[2,1.93,31.24]],"batl":[[0,1.99,40.6],[1,2,59.14],[2,2.02,75.15]],"ltp":2.0,"tv":2762.05,"id":5300737},{"batb":[[0,2,342.99],[1,1.99,2783.1]],"batl":[[0,2.04,69.07],[1,2.06,1.63],[2,2.08,59.14]],"ltp":2.0,"tv":8610.25,"id":2497008}]}]}
{"op":"mcm","clk":"4298207214","pt":1632576501813,"mc":[{"id":"1.188136695","rc":[{"batb":[[2,1.93,3.59]],"ltp":2.0,"tv":2762.05,"id":5300737},{"batl":[[0,2.02,12.89],[1,2.04,68.93],[2,2.06,1.63]],"ltp":2.0,"tv":8610.25,"id":2497008}]}]}
{"op":"mcm","clk":"4298208688","pt":1632576507711,"mc":[{"id":"1.188136695","rc":[{"batl":[[0,2.04,81.82],[1,2.06,1.63],[2,2.08,59.14]],"ltp":2.0,"tv":8610.25,"id":2497008}]}]}
{"op":"mcm","clk":"4298208733","pt":1632576507912,"mc":[{"id":"1.188136695","rc":[{"batb":[[0,1.97,44],[1,1.96,72.6],[2,1.94,44.1]],"ltp":2.0,"tv":2762.05,"id":5300737}]}]}
{"op":"mcm","clk":"4298210277","pt":1632576513813,"mc":[{"id":"1.188136695","rc":[{"trd":[[2,254.21]],"batb":[[0,2,338.88],[1,1.99,55.17]],"ltp":2.0,"tv":8618.48,"id":2497008}],"tv":11380.53}]}
{"op":"mcm","clk":"4298212577","pt":1632576522518,"mc":[{"id":"1.188136695","rc":[{"batl":[[0,2.04,69.07],[2,2.08,71.88]],"ltp":2.0,"tv":8618.48,"id":2497008}]}]}
{"op":"mcm","clk":"4298212912","pt":1632576523624,"mc":[{"id":"1.188136695","rc":[{"trd":[[1.99,225.84],[2,744.45]],"batl":[[0,2,35.84],[1,2.02,75.15],[2,2.04,1.42]],"ltp":2.0,"tv":2889.84,"id":5300737}],"tv":11508.32}]}
{"op":"mcm","clk":"4298212972","pt":1632576523839,"mc":[{"id":"1.188136695","rc":[{"batb":[[1,1.96,73.84]],"ltp":2.0,"tv":2889.84,"id":5300737}]}]}
{"op":"mcm","clk":"4298217293","pt":1632576540553,"mc":[{"id":"1.188136695","rc":[{"batb":[[0,1.97,104.62],[1,1.96,44],[2,1.94,42.86]],"batl":[[0,2,18],[1,2.02,74.06],[2,2.1,10.72]],"ltp":2.0,"tv":2889.84,"id":5300737},{"batb":[[0,2,312.88],[1,1.99,53.14]],"batl":[[0,2.02,3.47],[1,2.04,67.53]],"ltp":2.0,"tv":8618.48,"id":2497008}]}]}
{"op":"mcm","clk":"4298217368","pt":1632576540869,"mc":[{"id":"1.188136695","rc":[{"batl":[[0,2,20.23]],"ltp":2.0,"tv":2889.84,"id":5300737}]}]}
{"op":"mcm","clk":"4298218359","pt":1632576544774,"mc":[{"id":"1.188136695","rc":[{"batl":[[2,2.08,59.14]],"ltp":2.0,"tv":8618.48,"id":2497008}]}]}
{"op":"mcm","clk":"4298219349","pt":1632576548478,"mc":[{"id":"1.188136695","rc":[{"batl":[[0,1.99,5.24],[1,2,18],[2,2.02,74.06]],"ltp":2.0,"tv":2889.84,"id":5300737}]}]}
{"op":"mcm","clk":"4298222706","pt":1632576561990,"mc":[{"id":"1.188136695","rc":[{"batl":[[1,2.02,74.06],[2,2.1,10.72]],"ltp":2.0,"tv":2889.84,"id":5300737},{"batb":[[0,2,289.88]],"ltp":2.0,"tv":8618.48,"id":2497008}]}]}
{"op":"mcm","clk":"4298222963","pt":1632576562993,"mc":[{"id":"1.188136695","rc":[{"batl":[[0,1.99,2.24]],"ltp":2.0,"tv":2889.84,"id":5300737}]}]}
{"op":"mcm","clk":"4298226057","pt":1632576575321,"mc":[{"id":"1.188136695","rc":[{"batl":[[1,2,3],[2,2.02,74.06]],"ltp":2.0,"tv":2889.84,"id":5300737}]}]}
{"op":"mcm","clk":"4298231226","pt":1632576595151,"mc":[{"id":"1.188136695","rc":[{"batl":[[0,1.99,4.24]],"ltp":2.0,"tv":2889.84,"id":5300737},{"batl":[[0,2.02,5.47]],"ltp":2.0,"tv":8618.48,"id":2497008}]}]}
{"op":"mcm","clk":"4298249116","pt":1632576659501,"mc":[{"id":"1.188136695","rc":[{"trd":[[1.98,97.2]],"batl":[[0,1.99,4.5]],"ltp":1.98,"tv":2895.42,"id":5300737},{"trd":[[2.02,5.47]],"batl":[[0,2.04,67.53],[1,2.08,59.14],[2,2.1,12.74]],"ltp":2.02,"tv":8623.94,"id":2497008}],"tv":11519.37}]}
{"op":"mcm","clk":"4298249379","pt":1632576660194,"mc":[{"id":"1.188136695","rc":[{"trd":[[1.98,102.22]],"batb":[[0,1.97,44]],"batl":[[0,1.99,2]],"ltp":1.98,"tv":2900.44,"id":5300737}],"tv":11524.39}]}
{"op":"mcm","clk":"4298258677","pt":1632576692505,"mc":[{"id":"1.188136695","rc":[{"batl":[[2,2.02,69.43]],"ltp":1.98,"tv":2900.44,"id":5300737}]}]}
{"op":"mcm","clk":"4298261096","pt":1632576700813,"mc":[{"id":"1.188136695","rc":[{"batl":[[0,1.99,6.63]],"ltp":1.98,"tv":2900.44,"id":5300737}]}]}
{"op":"mcm","clk":"4298270762","pt":1632576733051,"mc":[{"id":"1.188136695","rc":[{"trd":[[1.99,233.84]],"batl":[[0,1.99,2.63]],"ltp":1.99,"tv":2908.44,"id":5300737}],"tv":11532.39}]}
{"op":"mcm","clk":"4298275609","pt":1632576749670,"mc":[{"id":"1.188136695","rc":[{"batb":[[0,2,3022.04]],"ltp":2.02,"tv":8623.94,"id":2497008}]}]}
{"op":"mcm","clk":"4298278865","pt":1632576760770,"mc":[{"id":"1.188136695","rc":[{"batl":[[0,1.99,3.44]],"ltp":1.99,"tv":2908.44,"id":5300737}]}]}
{"op":"mcm","clk":"4298279034","pt":1632576761325,"mc":[{"id":"1.188136695","rc":[{"batb":[[0,2.02,5],[1,2,3026.04],[2,1.99,53.14]],"ltp":2.02,"tv":8623.94,"id":2497008}]}]}
{"op":"mcm","clk":"4298282203","pt":1632576772326,"mc":[{"id":"1.188136695","rc":[{"batb":[[1,1.96,87]],"batl":[[0,1.99,42.86]],"ltp":1.99,"tv":2908.44,"id":5300737},{"batb":[[1,2,342.88]],"ltp":2.02,"tv":8623.94,"id":2497008}]}]}
{"op":"mcm","clk":"4298288208","pt":1632576792550,"mc":[{"id":"1.188136695","rc":[{"batb":[[1,1.94,42.86],[2,1.93,2.91]],"batl":[[0,1.99,3.44]],"ltp":1.99,"tv":2908.44,"id":5300737},{"batb":[[1,2,293.88]],"batl":[[0,2.04,11.53]],"ltp":2.02,"tv":8623.94,"id":2497008}]}]}
{"op":"mcm","clk":"4298288575","pt":1632576793738,"mc":[{"id":"1.188136695","rc":[{"trd":[[2.02,15.47]],"batb":[[0,2,3286.94],[1,1.99,53.14],[2,1.97,15.69]],"ltp":2.02,"tv":8633.94,"id":2497008}],"tv":11542.39}]}
{"op":"mcm","clk":"4298299098","pt":1632576829111,"mc":[{"id":"1.188136695","rc":[{"trd":[[1.99,235.97]],"batl":[[0,1.99,2.37]],"ltp":1.99,"tv":2910.57,"id":5300737}],"tv":11544.51}]}
{"op":"mcm","clk":"4298319844","pt":1632576898910,"mc":[{"id":"1.188136695","rc":[{"trd":[[2,597.06]],"batb":[[0,2,3115.51]],"ltp":2.0,"tv":8976.79,"id":2497008}],"tv":11887.36}]}
{"op":"mcm","clk":"4298327852","pt":1632576924729,"mc":[{"id":"1.188136695","rc":[{"trd":[[2,1979.37]],"batb":[[0,2,2424.36]],"ltp":2.0,"tv":10359.1,"id":2497008}],"tv":13269.67}]}
{"op":"mcm","clk":"4298328161","pt":1632576925652,"mc":[{"id":"1.188136695","rc":[{"batb":[[1,1.96,100.5],[2,1.94,42.86]],"batl":[[0,1.99,52.87]],"ltp":1.99,"tv":2910.57,"id":5300737},{"batb":[[0,2,62]],"batl":[[0,2.04,96.03]],"ltp":2.0,"tv":10359.1,"id":2497008}]}]}
{"op":"mcm","clk":"4298328399","pt":1632576926358,"mc":[{"id":"1.188136695","rc":[{"batb":[[0,1.97,144.5]],"ltp":1.99,"tv":2910.57,"id":5300737},{"trd":[[2.04,31.51]],"batl":[[0,2.04,80.27]],"ltp":2.04,"tv":10390.61,"id":2497008}],"tv":13301.18}]}
{"op":"mcm","clk":"4298329363","pt":1632576929646,"mc":[{"id":"1.188136695","rc":[{"batb":[[0,1.97,44],[1,1.94,42.86],[2,1.93,2.91]],"batl":[[0,1.99,2.37],[1,2,7]],"ltp":1.99,"tv":2910.57,"id":5300737},{"batb":[[0,2,63.93],[1,1.99,57.14]],"batl":[[0,2.08,59.14],[1,2.1,12.74],[2,2.3,5.85]],"ltp":2.04,"tv":10390.61,"id":2497008}]}]}
{"op":"mcm","clk":"4298329469","pt":1632576929964,"mc":[{"id":"1.188136695","rc":[{"batl":[[0,2.08,311.1]],"ltp":2.04,"tv":10390.61,"id":2497008}]}]}
{"op":"mcm","clk":"4298331277","pt":1632576935828,"mc":[{"id":"1.188136695","rc":[{"batb":[[0,2,4]],"ltp":2.04,"tv":10390.61,"id":2497008}]}]}
{"op":"mcm","clk":"4298339224","pt":1632576961475,"mc":[{"id":"1.188136695","rc":[{"batb":[[1,1.99,53.14]],"ltp":2.04,"tv":10390.61,"id":2497008}]}]}
{"op":"mcm","clk":"4298343296","pt":1632576975491,"mc":[{"id":"1.188136695","rc":[{"batb":[[0,1.97,86.52]],"ltp":1.99,"tv":2910.57,"id":5300737},{"batl":[[0,2.04,38.52],[1,2.08,59.14],[2,2.1,12.74]],"ltp":2.04,"tv":10390.61,"id":2497008}]}]}
{"op":"mcm","clk":"4298344831","pt":1632576980978,"mc":[{"id":"1.188136695","rc":[{"trd":[[2,1979.61]],"batb":[[0,2,3.88]],"ltp":2.0,"tv":10390.85,"id":2497008}],"tv":13301.42}]}
{"op":"mcm","clk":"4298348989","pt":1632576996029,"mc":[{"id":"1.188136695","rc":[{"trd":[[1.97,1.22]],"batb":[[0,1.97,85.91]],"ltp":1.97,"tv":2911.79,"id":5300737}],"tv":13302.64}]}
{"op":"mcm","clk":"4298367625","pt":1632577060194,"mc":[{"id":"1.188136695","marketDefinition":{"bspMarket":false,"turnInPlayEnabled":true,"persistenceEnabled":true,"marketBaseRate":5.0,"eventId":"30941535","eventTypeId":"2","numberOfWinners":1,"bettingType":"ODDS","marketType":"MATCH_ODDS","marketTime":"2021-09-25T13:45:00.000Z","suspendTime":"2021-09-25T13:45:00.000Z","bspReconciled":false,"complete":true,"inPlay":false,"crossMatching":true,"runnersVoidable":false,"numberOfActiveRunners":2,"betDelay":0,"status":"OPEN","runners":[{"status":"ACTIVE","sortPriority":1,"id":5300737,"name":"Anett Kontaveit"},{"status":"ACTIVE","sortPriority":2,"id":2497008,"name":"Petra Kvitova"}],"regulators":["MR_INT"],"discountAllowed":true,"timezone":"UTC","openDate":"2021-09-25T13:30:00.000Z","version":4055235509,"name":"Match Odds","eventName":"Kontaveit v Kvitova"}}]}
{"op":"mcm","clk":"4298368554","pt":1632577063238,"mc":[{"id":"1.188136695","marketDefinition":{"bspMarket":false,"turnInPlayEnabled":true,"persistenceEnabled":true,"marketBaseRate":5.0,"eventId":"30941535","eventTypeId":"2","numberOfWinners":1,"bettingType":"ODDS","marketType":"MATCH_ODDS","marketTime":"2021-09-25T13:45:00.000Z","suspendTime":"2021-09-25T13:45:00.000Z","bspReconciled":false,"complete":true,"inPlay":false,"crossMatching":true,"runnersVoidable":false,"numberOfActiveRunners":2,"betDelay":0,"status":"OPEN","runners":[{"status":"ACTIVE","sortPriority":1,"id":5300737,"name":"Anett Kontaveit"},{"status":"ACTIVE","sortPriority":2,"id":2497008,"name":"Petra Kvitova"}],"regulators":["MR_INT"],"discountAllowed":true,"timezone":"UTC","openDate":"2021-09-25T13:45:00.000Z","version":4055235509,"name":"Match Odds","eventName":"Kontaveit v Kvitova"}}]}
{"op":"mcm","clk":"4298395495","pt":1632577157664,"mc":[{"id":"1.188136695","rc":[{"batl":[[0,2.02,3.88],[1,2.04,38.52],[2,2.08,59.14]],"ltp":2.0,"tv":10390.85,"id":2497008}]}]}
{"op":"mcm","clk":"4298395781","pt":1632577158686,"mc":[{"id":"1.188136695","rc":[{"batb":[[1,1.96,35.08],[2,1.94,42.86]],"ltp":1.97,"tv":2911.79,"id":5300737},{"batb":[[1,1.99,54.15]],"batl":[[0,2.02,30.51],[1,2.04,17]],"ltp":2.0,"tv":10390.85,"id":2497008}]}]}
{"op":"mcm","clk":"4298401184","pt":1632577177826,"mc":[{"id":"1.188136695","rc":[{"trd":[[1.99,240.72]],"batb":[[0,1.99,27.35],[1,1.97,85.91],[2,1.96,35.08]],"batl":[[0,2,3],[1,2.02,69.43],[2,2.1,10.62]],"ltp":1.99,"tv":2916.54,"id":5300737},{"trd":[[2,1987.37]],"batb":[[0,1.99,59.15],[1,1.98,4.02]],"batl":[[0,2.02,26.63]],"ltp":2.0,"tv":10398.61,"id":2497008}],"tv":13315.16}]}
{"op":"mcm","clk":"4298401419","pt":1632577178710,"mc":[{"id":"1.188136695","rc":[{"batb":[[1,1.98,33.64],[2,1.97,64.39]],"ltp":1.99,"tv":2916.54,"id":5300737}]}]}
{"op":"mcm","clk":"4298407559","pt":1632577200944,"mc":[{"id":"1.188136695","rc":[{"batb":[[1,1.98,1.02]],"ltp":2.0,"tv":10398.61,"id":2497008}]}]}
{"op":"mcm","clk":"4298410431","pt":1632577210804,"mc":[{"id":"1.188136695","rc":[{"trd":[[2,745.23]],"batl":[[0,2,2.61]],"ltp":2.0,"tv":2917.32,"id":5300737}],"tv":13315.94}]}
{"op":"mcm","clk":"4298410547","pt":1632577211232,"mc":[{"id":"1.188136695","rc":[{"batb":[[0,1.99,29.13],[1,1.98,35.42]],"ltp":2.0,"tv":2917.32,"id":5300737}]}]}
{"op":"mcm","clk":"4298412738","pt":1632577218757,"mc":[{"id":"1.188136695","rc":[{"trd":[[2,748.16]],"batb":[[2,1.97,66.18]],"batl":[[0,2.02,69.43],[1,2.1,10.62],[2,2.12,51.29]],"ltp":2.0,"tv":2920.24,"id":5300737},{"trd":[[1.99,337.98],[2,1990.3]],"batb":[[0,1.98,1.02],[1,1.97,15.69],[2,1.94,27.57]],"batl":[[0,1.99,254.6],[1,2.02,26.63],[2,2.04,17]],"ltp":1.99,"tv":10519.84,"id":2497008}],"tv":13440.09}]}
{"op":"mcm","clk":"4298413019","pt":1632577219744,"mc":[{"id":"1.188136695","rc":[{"batb":[[0,2,33.76],[1,1.99,29.13],[2,1.98,9.78]],"batl":[[0,2.1,10.62],[1,2.12,51.29],[2,2.24,25]],"ltp":2.0,"tv":2920.24,"id":5300737},{"batb":[[0,1.97,2950.36],[1,1.92,466.23],[2,1.91,428.56]],"batl":[[0,1.99,281.6],[1,2.02,6],[2,2.04,7]],"ltp":1.99,"tv":10519.84,"id":2497008}]}]}
{"op":"mcm","clk":"4298413271","pt":1632577220629,"mc":[{"id":"1.188136695","rc":[{"batl":[[0,2.04,69.43],[1,2.08,1.72],[2,2.1,10.62]],"ltp":2.0,"tv":2920.24,"id":5300737},{"batb":[[0,1.97,3000.07]],"batl":[[0,1.99,254.6],[1,2,27.34],[2,2.02,17]],"ltp":1.99,"tv":10519.84,"id":2497008}]}]}
{"op":"mcm","clk":"4298413532","pt":1632577221654,"mc":[{"id":"1.188136695","rc":[{"batl":[[0,2.04,137.76]],"ltp":2.0,"tv":2920.24,"id":5300737}]}]}
{"op":"mcm","clk":"4298420832","pt":1632577247382,"mc":[{"id":"1.188136695","rc":[{"batb":[[0,1.97,77.66]],"ltp":1.99,"tv":10519.84,"id":2497008}]}]}
{"op":"mcm","clk":"4298422354","pt":1632577252509,"mc":[{"id":"1.188136695","rc":[{"batl":[[0,2.04,68.33]],"ltp":2.0,"tv":2920.24,"id":5300737},{"batb":[[0,1.97,27.95]],"batl":[[0,1.99,281.6],[1,2,17],[2,2.02,6]],"ltp":1.99,"tv":10519.84,"id":2497008}]}]}
{"op":"mcm","clk":"4298432990","pt":1632577290755,"mc":[{"id":"1.188136695","rc":[{"batl":[[0,2.04,137.76]],"ltp":2.0,"tv":2920.24,"id":5300737},{"batb":[[0,1.97,77.66]],"ltp":1.99,"tv":10519.84,"id":2497008}]}]}
{"op":"mcm","clk":"4298433224","pt":1632577291693,"mc":[{"id":"1.188136695","rc":[{"batb":[[0,2,102.01]],"ltp":2.0,"tv":2920.24,"id":5300737}]}]}
{"op":"mcm","clk":"4298433773","pt":1632577293671,"mc":[{"id":"1.188136695","rc":[{"trd":[[1.99,358.36]],"batl":[[0,1.99,271.41]],"ltp":1.99,"tv":10540.22,"id":2497008}],"tv":13460.47}]}
{"op":"mcm","clk":"4298433944","pt":1632577294275,"mc":[{"id":"1.188136695","rc":[{"batl":[[0,2.04,69.43]],"ltp":2.0,"tv":2920.24,"id":5300737},{"batb":[[0,1.97,65.4]],"ltp":1.99,"tv":10540.22,"id":2497008}]}]}
{"op":"mcm","clk":"4298435503","pt":1632577300358,"mc":[{"id":"1.188136695","rc":[{"trd":[[2,751.92]],"batb":[[0,2,100.13]],"ltp":2.0,"tv":2924.01,"id":5300737}],"tv":13464.24}]}
{"op":"mcm","clk":"4298437742","pt":1632577309673,"mc":[{"id":"1.188136695","rc":[{"batl":[[0,1.99,27]],"ltp":1.99,"tv":10540.22,"id":2497008}]}]}
{"op":"mcm","clk":"4298437892","pt":1632577310379,"mc":[{"id":"1.188136695","rc":[{"batb":[[0,2,102.01],[1,1.99,49.13]],"ltp":2.0,"tv":2924.01,"id":5300737},{"batb":[[0,1.98,34.28],[1,1.97,65.4],[2,1.92,466.23]],"batl":[[0,2,27],[1,2.02,26],[2,2.04,48.86]],"ltp":1.99,"tv":10540.22,"id":2497008}]}]}
{"op":"mcm","clk":"4298438405","pt":1632577312581,"mc":[{"id":"1.188136695","rc":[{"batb":[[0,2,33.76]],"ltp":2.0,"tv":2924.01,"id":5300737}]}]}
{"op":"mcm","clk":"4298438921","pt":1632577314702,"mc":[{"id":"1.188136695","rc":[{"batb":[[0,2.02,32],[1,2,21.76],[2,1.99,37.13]],"ltp":2.0,"tv":2924.01,"id":5300737},{"trd":[[1.97,3707.88],[1.98,705.63]],"batb":[[0,1.93,2901.3],[1,1.92,466.01],[2,1.91,428.56]],"batl":[[0,1.97,151.64],[1,1.98,27.39],[2,2,7]],"ltp":1.97,"tv":10739.6,"id":2497008}],"tv":13663.61}]}
{"op":"mcm","clk":"4298439196","pt":1632577315777,"mc":[{"id":"1.188136695","rc":[{"batl":[[0,2.06,69.43],[1,2.08,323.52]],"ltp":2.0,"tv":2924.01,"id":5300737},{"trd":[[1.97,3743.16]],"batb":[[0,1.95,61.08],[1,1.93,2901.08],[2,1.92,438.06]],"batl":[[0,1.97,134]],"ltp":1.97,"tv":10774.88,"id":2497008}],"tv":13698.89}]}
{"op":"mcm","clk":"4298443425","pt":1632577331738,"mc":[{"id":"1.188136695","rc":[{"batb":[[0,2.02,33.92]],"batl":[[0,2.06,202.53],[1,2.1,10.62],[2,2.12,51.29]],"ltp":2.0,"tv":2924.01,"id":5300737},{"batb":[[1,1.92,438.06],[2,1.91,428.56]],"ltp":1.97,"tv":10774.88,"id":2497008}]}]}
{"op":"mcm","clk":"4298450391","pt":1632577359140,"mc":[{"id":"1.188136695","rc":[{"batl":[[0,2.06,204.47]],"ltp":2.0,"tv":2924.01,"id":5300737}]}]}
{"op":"mcm","clk":"4298451040","pt":1632577361761,"mc":[{"id":"1.188136695","rc":[{"batb":[[0,2.02,91.72]],"ltp":2.0,"tv":2924.01,"id":5300737}]}]}
{"op":"mcm","clk":"4298458248","pt":1632577390508,"mc":[{"id":"1.188136695","rc":[{"batl":[[0,2.06,204.37]],"ltp":2.0,"tv":2924.01,"id":5300737}]}]}
{"op":"mcm","clk":"4298458332","pt":1632577390918,"mc":[{"id":"1.188136695","rc":[{"batl":[[0,2.06,202.53]],"ltp":2.0,"tv":2924.01,"id":5300737}]}]}
{"op":"mcm","clk":"4298459023","pt":1632577393818,"mc":[{"id":"1.188136695","rc":[{"trd":[[1.97,3764.31]],"batl":[[0,1.97,123.43]],"ltp":1.97,"tv":10796.03,"id":2497008}],"tv":13720.05}]}
{"op":"mcm","clk":"4298459169","pt":1632577394419,"mc":[{"id":"1.188136695","rc":[{"batl":[[0,2.06,69.43]],"ltp":2.0,"tv":2924.01,"id":5300737}]}]}
{"op":"mcm","clk":"4298465008","pt":1632577417881,"mc":[{"id":"1.188136695","rc":[{"trd":[[2.02,383.61]],"batb":[[0,2.02,86.6]],"ltp":2.02,"tv":2934.25,"id":5300737}],"tv":13730.28}]}
{"op":"mcm","clk":"4298469247","pt":1632577435707,"mc":[{"id":"1.188136695","rc":[{"trd":[[2.02,384.09]],"batb":[[0,2.02,86.36]],"ltp":2.02,"tv":2934.72,"id":5300737}],"tv":13730.76}]}
{"op":"mcm","clk":"4298470331","pt":1632577440249,"mc":[{"id":"1.188136695","rc":[{"batb":[[0,2.02,84.44],[1,2,20],[2,1.99,35.35]],"ltp":2.02,"tv":2934.72,"id":5300737}]}]}
{"op":"mcm","clk":"4298474161","pt":1632577454828,"mc":[{"id":"1.188136695","rc":[{"batb":[[0,2.04,32.47],[1,2.02,84.44],[2,2,8]],"ltp":2.02,"tv":2934.72,"id":5300737},{"trd":[[1.95,999.52],[1.96,702.06]],"batb":[[0,1.92,1069.02],[1,1.91,428.56],[2,1.9,465.47]],"batl":[[0,1.96,27.47],[1,1.97,150.43],[2,1.98,7]],"ltp":1.95,"tv":10935.08,"id":2497008}],"tv":13869.81}]}
{"op":"mcm","clk":"4298474382","pt":1632577455659,"mc":[{"id":"1.188136695","rc":[{"batb":[[2,2,57.71]],"batl":[[0,2.08,58.28],[1,2.1,797.91]],"ltp":2.02,"tv":2934.72,"id":5300737},{"batb":[[0,1.93,2979.08],[1,1.92,438.06],[2,1.91,428.56]],"ltp":1.95,"tv":10935.08,"id":2497008}]}]}
{"op":"mcm","clk":"4298474545","pt":1632577456253,"mc":[{"id":"1.188136695","rc":[{"batb":[[0,2.02,84.44],[1,2,69.71],[2,1.99,35.35]],"ltp":2.02,"tv":2934.72,"id":5300737},{"batl":[[0,1.97,150.43],[1,1.98,17],[2,2,516.13]],"ltp":1.95,"tv":10935.08,"id":2497008}]}]}
{"op":"mcm","clk":"4298478243","pt":1632577470355,"mc":[{"id":"1.188136695","rc":[{"batb":[[0,1.94,995.97],[1,1.93,2979.08],[2,1.92,438.06]],"batl":[[0,1.97,123.43],[1,2,509.13],[2,2.3,5.85]],"ltp":1.95,"tv":10935.08,"id":2497008}]}]}
{"op":"mcm","clk":"4298478480","pt":1632577471367,"mc":[{"id":"1.188136695","rc":[{"batl":[[0,2.08,98.31],[1,2.1,10.62]],"ltp":2.02,"tv":2934.72,"id":5300737}]}]}
{"op":"mcm","clk":"4298479543","pt":1632577475441,"mc":[{"id":"1.188136695","rc":[{"batb":[[2,1.99,8]],"ltp":2.02,"tv":2934.72,"id":5300737}]}]}
{"op":"mcm","clk":"4298482295","pt":1632577485790,"mc":[{"id":"1.188136695","rc":[{"batb":[[1,2,20]],"batl":[[0,2.08,40.03]],"ltp":2.02,"tv":2934.72,"id":5300737},{"batb":[[1,1.92,438.06],[2,1.9,465.47]],"batl":[[1,2,455.99]],"ltp":1.95,"tv":10935.08,"id":2497008}]}]}
{"op":"mcm","clk":"4298482502","pt":1632577486559,"mc":[{"id":"1.188136695","rc":[{"batb":[[1,2,69.71]],"batl":[[0,2.08,100.89]],"ltp":2.02,"tv":2934.72,"id":5300737},{"batb":[[0,1.94,3915.57],[1,1.93,59.14],[2,1.92,438.06]],"batl":[[1,1.99,27],[2,2,507.41]],"ltp":1.95,"tv":10935.08,"id":2497008}]}]}
{"op":"mcm","clk":"4298482590","pt":1632577486982,"mc":[{"id":"1.188136695","rc":[{"batb":[[0,2.02,26.64]],"ltp":2.02,"tv":2934.72,"id":5300737}]}]}
{"op":"mcm","clk":"4298486056","pt":1632577500788,"mc":[{"id":"1.188136695","rc":[{"batb":[[1,2,20]],"batl":[[0,2.08,40.03]],"ltp":2.02,"tv":2934.72,"id":5300737},{"batb":[[1,1.92,438.06],[2,1.9,465.47]],"batl":[[2,2,455.99]],"ltp":1.95,"tv":10935.08,"id":2497008}]}]}
{"op":"mcm","clk":"4298500712","pt":1632577559450,"mc":[{"id":"1.188136695","rc":[{"batb":[[0,1.95,256.44],[1,1.94,3915.57],[2,1.92,438.06]],"ltp":1.95,"tv":10935.08,"id":2497008}]}]}
{"op":"mcm","clk":"4298500824","pt":1632577560054,"mc":[{"id":"1.188136695","rc":[{"batl":[[1,1.98,27.52],[2,1.99,27]],"ltp":1.95,"tv":10935.08,"id":2497008}]}]}
{"op":"mcm","clk":"4298510148","pt":1632577599111,"mc":[{"id":"1.188136695","rc":[{"batl":[[0,2.08,40.13]],"ltp":2.02,"tv":2934.72,"id":5300737}]}]}
{"op":"mcm","clk":"4298516771","pt":1632577626110,"mc":[{"id":"1.188136695","rc":[{"trd":[[1.94,703.45],[1.95,1512.4]],"batb":[[0,1.94,3563.84],[1,1.92,438.06],[2,1.9,494.04]],"ltp":1.94,"tv":12151.42,"id":2497008}],"tv":15086.14}]}
{"op":"mcm","clk":"4298517011","pt":1632577627004,"mc":[{"id":"1.188136695","rc":[{"batb":[[2,1.9,465.47]],"ltp":1.94,"tv":12151.42,"id":2497008}]}]}
{"op":"mcm","clk":"4298524706","pt":1632577659793,"mc":[{"id":"1.188136695","marketDefinition":{"bspMarket":false,"turnInPlayEnabled":true,"persistenceEnabled":true,"marketBaseRate":5.0,"eventId":"30941535","eventTypeId":"2","numberOfWinners":1,"bettingType":"ODDS","marketType":"MATCH_ODDS","marketTime":"2021-09-25T14:00:00.000Z","suspendTime":"2021-09-25T14:00:00.000Z","bspReconciled":false,"complete":true,"inPlay":false,"crossMatching":true,"runnersVoidable":false,"numberOfActiveRunners":2,"betDelay":0,"status":"OPEN","runners":[{"status":"ACTIVE","sortPriority":1,"id":5300737,"name":"Anett Kontaveit"},{"status":"ACTIVE","sortPriority":2,"id":2497008,"name":"Petra Kvitova"}],"regulators":["MR_INT"],"discountAllowed":true,"timezone":"UTC","openDate":"2021-09-25T13:45:00.000Z","version":4055271143,"name":"Match Odds","eventName":"Kontaveit v Kvitova"}}]}
{"op":"mcm","clk":"4298525178","pt":1632577661781,"mc":[{"id":"1.188136695","marketDefinition":{"bspMarket":false,"turnInPlayEnabled":true,"persistenceEnabled":true,"marketBaseRate":5.0,"eventId":"30941535","eventTypeId":"2","numberOfWinners":1,"bettingType":"ODDS","marketType":"MATCH_ODDS","marketTime":"2021-09-25T14:00:00.000Z","suspendTime":"2021-09-25T14:00:00.000Z","bspReconciled":false,"complete":true,"inPlay":false,"crossMatching":true,"runnersVoidable":false,"numberOfActiveRunners":2,"betDelay":0,"status":"OPEN","runners":[{"status":"ACTIVE","sortPriority":1,"id":5300737,"name":"Anett Kontaveit"},{"status":"ACTIVE","sortPriority":2,"id":2497008,"name":"Petra Kvitova"}],"regulators":["MR_INT"],"discountAllowed":true,"timezone":"UTC","openDate":"2021-09-25T14:00:00.000Z","version":4055271143,"name":"Match Odds","eventName":"Kontaveit v Kvitova"}}]}
{"op":"mcm","clk":"4298528763","pt":1632577677661,"mc":[{"id":"1.188136695","rc":[{"batl":[[0,2.1,973.25],[1,2.12,51.29],[2,2.24,25]],"ltp":2.02,"tv":2934.72,"id":5300737},{"batl":[[0,1.98,27.52],[1,1.99,27],[2,2,455.99]],"ltp":1.94,"tv":12151.42,"id":2497008}]}]}
{"op":"mcm","clk":"4298530030","pt":1632577683283,"mc":[{"id":"1.188136695","rc":[{"trd":[[1.94,954.78]],"batb":[[0,1.94,3438.18]],"ltp":1.94,"tv":12402.74,"id":2497008}],"tv":15337.47}]}
{"op":"mcm","clk":"4298530219","pt":1632577684070,"mc":[{"id":"1.188136695","rc":[{"trd":[[1.94,1006.21]],"batb":[[0,1.94,3412.47]],"ltp":1.94,"tv":12454.17,"id":2497008}],"tv":15388.9}]}
{"op":"mcm","clk":"4298530538","pt":1632577685376,"mc":[{"id":"1.188136695","rc":[{"trd":[[2.02,439.25]],"batb":[[0,2,20],[1,1.99,17],[2,1.98,8]],"ltp":2.02,"tv":2989.88,"id":5300737},{"trd":[[1.98,707.55]],"batl":[[0,1.99,27],[1,2,455.99],[2,2.3,5.85]],"ltp":1.98,"tv":12456.09,"id":2497008}],"tv":15445.98}]}
{"op":"mcm","clk":"4298530805","pt":1632577686601,"mc":[{"id":"1.188136695","rc":[{"batb":[[2,1.9,494.04]],"batl":[[0,1.99,24.59],[1,2,479.99]],"ltp":1.98,"tv":12456.09,"id":2497008}]}]}
{"op":"mcm","clk":"4298532199","pt":1632577692815,"mc":[{"id":"1.188136695","rc":[{"batb":[[0,2.04,25.6],[1,2,8],[2,1.99,8]],"ltp":2.02,"tv":2989.88,"id":5300737},{"trd":[[1.95,1517.54]],"batb":[[0,1.94,492.87]],"batl":[[0,1.96,24.68],[1,1.99,7],[2,2,462.99]],"ltp":1.95,"tv":12461.23,"id":2497008}],"tv":15451.12}]}
{"op":"mcm","clk":"4298532262","pt":1632577693099,"mc":[{"id":"1.188136695","rc":[{"batb":[[0,1.94,3640.92],[2,1.9,465.47]],"ltp":1.95,"tv":12461.23,"id":2497008}]}]}
{"op":"mcm","clk":"4298532849","pt":1632577695513,"mc":[{"id":"1.188136695","rc":[{"batl":[[0,2.1,36.33]],"ltp":2.02,"tv":2989.88,"id":5300737},{"trd":[[1.95,1517.71],[1.96,716.52]],"batl":[[0,1.96,17.37]],"ltp":1.96,"tv":12475.86,"id":2497008}],"tv":15465.75}]}
{"op":"mcm","clk":"4298533128","pt":1632577696729,"mc":[{"id":"1.188136695","rc":[{"batb":[[0,2.02,22.6],[1,2,15]],"batl":[[0,2.1,45.07]],"ltp":2.02,"tv":2989.88,"id":5300737},{"batl":[[0,1.97,21.6]],"ltp":1.96,"tv":12475.86,"id":2497008}]}]}
{"op":"mcm","clk":"4298533253","pt":1632577697190,"mc":[{"id":"1.188136695","rc":[{"batl":[[0,1.99,21],[1,2,469.99],[2,2.3,5.85]],"ltp":1.96,"tv":12475.86,"id":2497008}]}]}
{"op":"mcm","clk":"4298533563","pt":1632577698508,"mc":[{"id":"1.188136695","rc":[{"batb":[[0,1.97,268.51],[1,1.96,26.78],[2,1.95,27.07]],"ltp":2.02,"tv":2989.88,"id":5300737},{"batb":[[2,1.9,494.04]],"ltp":1.96,"tv":12475.86,"id":2497008}]}]}
{"op":"mcm","clk":"4298533788","pt":1632577699401,"mc":[{"id":"1.188136695","rc":[{"batb":[[0,1.97,242],[1,1.96,28.1]],"ltp":2.02,"tv":2989.88,"id":5300737},{"batl":[[0,2,455.99],[1,2.3,5.85],[2,2.42,7.31]],"ltp":1.96,"tv":12475.86,"id":2497008}]}]}
{"op":"mcm","clk":"4298543379","pt":1632577741770,"mc":[{"id":"1.188136695","rc":[{"batb":[[0,2,23],[1,1.97,44.72],[2,1.96,28.1]],"ltp":2.02,"tv":2989.88,"id":5300737},{"batb":[[0,1.95,256.44],[1,1.94,3640.92],[2,1.92,438.06]],"batl":[[0,2,476.99]],"ltp":1.96,"tv":12475.86,"id":2497008}]}]}
{"op":"mcm","clk":"4298543452","pt":1632577742048,"mc":[{"id":"1.188136695","rc":[{"batb":[[2,1.96,1.32]],"ltp":2.02,"tv":2989.88,"id":5300737}]}]}
{"op":"mcm","clk":"4298545833","pt":1632577752764,"mc":[{"id":"1.188136695","rc":[{"batb":[[0,2,43]],"batl":[[0,2.04,20.63],[1,2.1,45.07],[2,2.12,51.29]],"ltp":2.02,"tv":2989.88,"id":5300737},{"batb":[[0,1.96,26.63],[1,1.95,256.44],[2,1.94,492.87]],"batl":[[0,1.99,37],[1,2,476.99],[2,2.3,5.85]],"ltp":1.96,"tv":12475.86,"id":2497008}]}]}
{"op":"mcm","clk":"4298545895","pt":1632577753095,"mc":[{"id":"1.188136695","rc":[{"batl":[[1,2.1,10.72]],"ltp":2.02,"tv":2989.88,"id":5300737}]}]}
{"op":"mcm","clk":"4298547332","pt":1632577759573,"mc":[{"id":"1.188136695","rc":[{"batl":[[2,2.3,6.64]],"ltp":1.96,"tv":12475.86,"id":2497008}]}]}
{"op":"mcm","clk":"4298548903","pt":1632577766399,"mc":[{"id":"1.188136695","rc":[{"batl":[[1,2.1,10.62]],"ltp":2.02,"tv":2989.88,"id":5300737}]}]}
{"op":"mcm","clk":"4298555090","pt":1632577794435,"mc":[{"id":"1.188136695","rc":[{"batb":[[0,1.97,289.44],[1,1.96,26.63]],"batl":[[1,2,490.99]],"ltp":1.96,"tv":12475.86,"id":2497008}]}]}
{"op":"mcm","clk":"4298570863","pt":1632577866058,"mc":[{"id":"1.188136695","rc":[{"batl":[[0,1.98,21.95],[1,1.99,37],[2,2,490.99]],"ltp":1.96,"tv":12475.86,"id":2497008}]}]}
{"op":"mcm","clk":"4298581852","pt":1632577919815,"mc":[{"id":"1.188136695","rc":[{"trd":[[1.98,751.45],[1.99,493.08]],"batb":[[0,1.99,2615.56],[1,1.97,289.44],[2,1.96,26.63]],"batl":[[0,2,490.99],[1,2.3,6.64],[2,2.42,7.31]],"ltp":1.99,"tv":12654.48,"id":2497008}],"tv":15644.37}]}
{"op":"mcm","clk":"4298582041","pt":1632577920816,"mc":[{"id":"1.188136695","rc":[{"batb":[[0,1.99,37.62]],"batl":[[0,2.02,27],[1,2.04,20.63],[2,2.1,10.62]],"ltp":2.02,"tv":2989.88,"id":5300737},{"batb":[[0,1.99,2649.56]],"batl":[[0,2,455.99],[1,2.02,26.39],[2,2.3,6.64]],"ltp":1.99,"tv":12654.48,"id":2497008}]}]}
{"op":"mcm","clk":"4298582166","pt":1632577921417,"mc":[{"id":"1.188136695","rc":[{"trd":[[1.99,561.64]],"batb":[[0,1.99,2615.28]],"ltp":1.99,"tv":12723.04,"id":2497008}],"tv":15712.93}]}
{"op":"mcm","clk":"4298587048","pt":1632577945558,"mc":[{"id":"1.188136695","rc":[{"trd":[[2,769.96]],"ltp":2.0,"tv":3007.92,"id":5300737},{"trd":[[2,2008.34]],"batl":[[0,2,437.94]],"ltp":2.0,"tv":12741.09,"id":2497008}],"tv":15749.02}]}
{"op":"mcm","clk":"4298593207","pt":1632577975535,"mc":[{"id":"1.188136695","rc":[{"batb":[[1,1.97,33]],"ltp":2.0,"tv":12741.09,"id":2497008}]}]}
{"op":"mcm","clk":"4298593865","pt":1632577978419,"mc":[{"id":"1.188136695","rc":[{"trd":[[2,2058.25]],"batl":[[0,2,412.99]],"ltp":2.0,"tv":12790.99,"id":2497008}],"tv":15798.92}]}
{"op":"mcm","clk":"4298594836","pt":1632577982243,"mc":[{"id":"1.188136695","rc":[{"trd":[[2,898.18]],"ltp":2.0,"tv":3136.15,"id":5300737},{"trd":[[2,2186.47]],"batl":[[0,2,284.77]],"ltp":2.0,"tv":12919.22,"id":2497008}],"tv":16055.37}]}
{"op":"mcm","clk":"4298595055","pt":1632577983140,"mc":[{"id":"1.188136695","rc":[{"batb":[[1,1.98,35.43],[2,1.97,33]],"ltp":2.0,"tv":12919.22,"id":2497008}]}]}
{"op":"mcm","clk":"4298596476","pt":1632577989760,"mc":[{"id":"1.188136695","rc":[{"trd":[[2,1026.4]],"ltp":2.0,"tv":3264.37,"id":5300737},{"trd":[[2,2314.7]],"batl":[[0,2,156.54]],"ltp":2.0,"tv":13047.44,"id":2497008}],"tv":16311.81}]}
{"op":"mcm","clk":"4298596648","pt":1632577990436,"mc":[{"id":"1.188136695","rc":[{"batb":[[0,1.99,82.23]],"batl":[[0,2.02,74],[1,2.04,70],[2,2.06,65.43]],"ltp":2.0,"tv":3264.37,"id":5300737},{"batb":[[0,1.99,2672.28],[1,1.98,122.86],[2,1.97,82]],"batl":[[1,2.02,64]],"ltp":2.0,"tv":13047.44,"id":2497008}]}]}
{"op":"mcm","clk":"4298597618","pt":1632577994869,"mc":[{"id":"1.188136695","rc":[{"trd":[[1.99,587.48]],"batb":[[0,1.99,2659.36]],"ltp":1.99,"tv":13073.28,"id":2497008}],"tv":16337.65}]}
{"op":"mcm","clk":"4298598866","pt":1632578000581,"mc":[{"id":"1.188136695","rc":[{"trd":[[2,1154.62]],"ltp":2.0,"tv":3392.59,"id":5300737},{"trd":[[2,2442.92]],"batl":[[0,2,28.32]],"ltp":2.0,"tv":13201.5,"id":2497008}],"tv":16594.1}]}
{"op":"mcm","clk":"4298605046","pt":1632578029594,"mc":[{"id":"1.188136695","rc":[{"batb":[[0,2,13.68],[1,1.99,82.23],[2,1.97,44.72]],"batl":[[1,2.04,72.32]],"ltp":2.0,"tv":3392.59,"id":5300737}]}]}
{"op":"mcm","clk":"4298606881","pt":1632578038682,"mc":[{"id":"1.188136695","rc":[{"trd":[[2,1210.31]],"batb":[[0,1.98,81.46],[1,1.97,44.72],[2,1.96,1.32]],"batl":[[0,2,289.44],[1,2.02,74],[2,2.04,72.32]],"ltp":2.0,"tv":3448.27,"id":5300737},{"trd":[[2,2471.24]],"batb":[[0,2,91],[1,1.99,2659.36],[2,1.98,122.86]],"batl":[[0,2.02,64],[1,2.04,65.46],[2,2.06,66.25]],"ltp":2.0,"tv":13229.82,"id":2497008}],"tv":16678.1}]}
{"op":"mcm","clk":"4298607058","pt":1632578039595,"mc":[{"id":"1.188136695","rc":[{"batb":[[0,2,96.31]],"ltp":2.0,"tv":13229.82,"id":2497008}]}]}
{"op":"mcm","clk":"4298608734","pt":1632578047797,"mc":[{"id":"1.188136695","rc":[{"batb":[[0,1.97,127.18],[1,1.96,1.32],[2,1.93,30.56]],"ltp":2.0,"tv":3448.27,"id":5300737},{"batb":[[0,2,91]],"batl":[[0,2.04,65.46],[1,2.06,66.25],[2,2.08,65.46]],"ltp":2.0,"tv":13229.82,"id":2497008}]}]}
{"op":"mcm","clk":"4298608810","pt":1632578048231,"mc":[{"id":"1.188136695","rc":[{"batb":[[0,1.97,136.21],[1,1.96,83.46],[2,1.93,2.91]],"batl":[[0,1.99,75.46],[1,2,289.44],[2,2.02,74]],"ltp":2.0,"tv":3448.27,"id":5300737},{"batl":[[0,2.04,173.85]],"ltp":2.0,"tv":13229.82,"id":2497008}]}]}
{"op":"mcm","clk":"4298614417","pt":1632578078174,"mc":[{"id":"1.188136695","rc":[{"batb":[[1,1.99,91]],"ltp":2.0,"tv":13229.82,"id":2497008}]}]}
{"op":"mcm","clk":"4298617684","pt":1632578095021,"mc":[{"id":"1.188136695","rc":[{"trd":[[1.99,264.66]],"batb":[[0,1.97,53.75],[1,1.93,2.91],[2,1.92,27.95]],"batl":[[0,2,214.44],[1,2.04,2.32],[2,2.1,10.62]],"ltp":1.99,"tv":3472.21,"id":5300737},{"batb":[[0,1.98,35.43],[1,1.95,27.07],[2,1.94,492.87]],"batl":[[0,2.04,108.39],[1,2.3,6.64],[2,2.42,7.31]],"ltp":2.0,"tv":13229.82,"id":2497008}],"tv":16702.03}]}
{"op":"mcm","clk":"4298618140","pt":1632578097399,"mc":[{"id":"1.188136695","rc":[{"batb":[[0,1.97,43.39]],"ltp":1.99,"tv":3472.21,"id":5300737},{"batl":[[0,2.26,145.03],[1,2.3,5.85]],"ltp":2.0,"tv":13229.82,"id":2497008}]}]}
{"op":"mcm","clk":"4298627050","pt":1632578139263,"mc":[{"id":"1.188136695","rc":[{"batl":[[0,2.04,79.08],[1,2.3,6.64]],"ltp":2.0,"tv":13229.82,"id":2497008}]}]}
{"op":"mcm","clk":"4298628592","pt":1632578146736,"mc":[{"id":"1.188136695","rc":[{"batb":[[0,1.98,16.67]],"ltp":2.0,"tv":13229.82,"id":2497008}]}]}
{"op":"mcm","clk":"4298630197","pt":1632578155086,"mc":[{"id":"1.188136695","rc":[{"batl":[[1,2.06,23.99],[2,2.3,5.85]],"ltp":2.0,"tv":13229.82,"id":2497008}]}]}
{"op":"mcm","clk":"4298635057","pt":1632578178306,"mc":[{"id":"1.188136695","rc":[{"trd":[[1.97,1.42]],"batb":[[0,1.97,43.29]],"ltp":1.97,"tv":3472.41,"id":5300737}],"tv":16702.23}]}
{"op":"mcm","clk":"4298639011","pt":1632578198048,"mc":[{"id":"1.188136695","rc":[{"trd":[[1.97,9.76]],"batb":[[0,1.97,39.12]],"ltp":1.97,"tv":3480.75,"id":5300737}],"tv":16710.58}]}
{"op":"mcm","clk":"4298640946","pt":1632578207436,"mc":[{"id":"1.188136695","rc":[{"batb":[[0,1.97,77.69]],"ltp":1.97,"tv":3480.75,"id":5300737}]}]}
{"op":"mcm","clk":"4298642462","pt":1632578214866,"mc":[{"id":"1.188136695","rc":[{"trd":[[2,1214.59]],"batl":[[0,2,210.15]],"ltp":2.0,"tv":3485.04,"id":5300737},{"trd":[[2,2475.53]],"ltp":2.0,"tv":13234.11,"id":2497008}],"tv":16719.15}]}
{"op":"mcm","clk":"4298643832","pt":1632578221174,"mc":[{"id":"1.188136695","rc":[{"trd":[[1.97,17.79]],"batb":[[0,1.97,73.68]],"ltp":1.97,"tv":3493.06,"id":5300737}],"tv":16727.17}]}
{"op":"mcm","clk":"4298649342","pt":1632578246828,"mc":[{"id":"1.188136695","rc":[{"trd":[[2,1634.91]],"batb":[[0,2,279.25],[1,1.97,73.68],[2,1.93,2.91]],"batl":[[0,2.04,7.13],[1,2.1,10.62],[2,2.12,51.29]],"ltp":2.0,"tv":3913.37,"id":5300737}],"tv":17147.48}]}
{"op":"mcm","clk":"4298649542","pt":1632578247715,"mc":[{"id":"1.188136695","rc":[{"batb":[[2,1.95,27.07]],"ltp":2.0,"tv":3913.37,"id":5300737},{"batb":[[1,1.94,492.87],[2,1.92,466.01]],"batl":[[0,2.04,106.54]],"ltp":2.0,"tv":13234.11,"id":2497008}]}]}
{"op":"mcm","clk":"4298651145","pt":1632578255034,"mc":[{"id":"1.188136695","rc":[{"batb":[[1,1.94,428.56],[2,1.92,385.67]],"ltp":2.0,"tv":13234.11,"id":2497008}]}]}
{"op":"mcm","clk":"4298654914","pt":1632578271949,"mc":[{"id":"1.188136695","rc":[{"batb":[[0,1.98,204.38]],"ltp":2.0,"tv":13234.11,"id":2497008}]}]}
{"op":"mcm","clk":"4298656492","pt":1632578279175,"mc":[{"id":"1.188136695","rc":[{"batb":[[0,1.98,688.65]],"ltp":2.0,"tv":13234.11,"id":2497008}]}]}
{"op":"mcm","clk":"4298657199","pt":1632578282490,"mc":[{"id":"1.188136695","rc":[{"batb":[[0,1.98,204.38],[1,1.96,484.27],[2,1.94,428.56]],"ltp":2.0,"tv":13234.11,"id":2497008}]}]}
{"op":"mcm","clk":"4298666818","pt":1632578326558,"mc":[{"id":"1.188136695","rc":[{"trd":[[1.98,1152.88]],"batb":[[0,1.98,3.66]],"ltp":1.98,"tv":13635.54,"id":2497008}],"tv":17548.91}]}
{"op":"mcm","clk":"4298667065","pt":1632578327741,"mc":[{"id":"1.188136695","rc":[{"batb":[[0,2.02,14],[1,2,279.25],[2,1.97,73.68]],"ltp":2.0,"tv":3913.37,"id":5300737}]}]}
{"op":"mcm","clk":"4298669866","pt":1632578340586,"mc":[{"id":"1.188136695","rc":[{"batb":[[1,2,277.99]],"ltp":2.0,"tv":3913.37,"id":5300737}]}]}
{"op":"mcm","clk":"4298674371","pt":1632578358871,"mc":[{"id":"1.188136695","rc":[{"trd":[[1.98,1156.9]],"batb":[[0,1.98,1.65]],"ltp":1.98,"tv":13639.55,"id":2497008}],"tv":17552.93}]}
{"op":"mcm","clk":"4298679503","pt":1632578380500,"mc":[{"id":"1.188136695","rc":[{"trd":[[1.96,773.22],[1.98,1160.2]],"batb":[[0,1.96,464.63],[1,1.94,428.56],[2,1.92,357.72]],"ltp":1.96,"tv":13699.56,"id":2497008}],"tv":17612.94}]}
{"op":"mcm","clk":"4298680883","pt":1632578386697,"mc":[{"id":"1.188136695","rc":[{"trd":[[2.02,467.24]],"batb":[[0,2,277.99],[1,1.97,73.68],[2,1.95,27.07]],"batl":[[0,2.02,174.46],[1,2.04,7.13],[2,2.1,10.62]],"ltp":2.02,"tv":3941.37,"id":5300737}],"tv":17640.93}]}
{"op":"mcm","clk":"4298681119","pt":1632578387743,"mc":[{"id":"1.188136695","rc":[{"trd":[[2.02,550.76]],"batl":[[0,2.02,132.7]],"ltp":2.02,"tv":4024.89,"id":5300737},{"batb":[[0,1.97,26.2],[1,1.96,464.63],[2,1.94,428.56]],"ltp":1.96,"tv":13699.56,"id":2497008}],"tv":17724.45}]}
{"op":"mcm","clk":"4298684708","pt":1632578401711,"mc":[{"id":"1.188136695","rc":[{"batb":[[1,1.96,455.92]],"ltp":1.96,"tv":13699.56,"id":2497008}]}]}
{"op":"mcm","clk":"4298692275","pt":1632578424551,"mc":[{"id":"1.188136695","rc":[{"trd":[[2,1754.9]],"batb":[[0,2,217.99]],"batl":[[1,2.1,10.62],[2,2.12,51.29]],"ltp":2.0,"tv":4144.88,"id":5300737},{"batb":[[0,1.97,60.14]],"ltp":1.96,"tv":13699.56,"id":2497008}],"tv":17844.45}]}
{"op":"mcm","clk":"4298695352","pt":1632578437488,"mc":[{"id":"1.188136695","rc":[{"trd":[[2,1774.91]],"batb":[[0,2,207.99]],"ltp":2.0,"tv":4164.89,"id":5300737}],"tv":17864.45}]}
{"op":"mcm","clk":"4298701251","pt":1632578456567,"mc":[{"id":"1.188136695","rc":[{"trd":[[2.02,683.46]],"batl":[[0,2.1,10.62],[1,2.12,51.29],[2,2.24,25]],"ltp":2.02,"tv":4297.59,"id":5300737},{"trd":[[1.98,1295.58]],"batl":[[0,1.98,130.09],[1,2.04,79.08],[2,2.06,23.99]],"ltp":1.98,"tv":13834.94,"id":2497008}],"tv":18132.53}]}
{"op":"mcm","clk":"4298701513","pt":1632578457610,"mc":[{"id":"1.188136695","rc":[{"batl":[[0,2.08,1301.4],[1,2.1,10.62],[2,2.12,51.29]],"ltp":2.02,"tv":4297.59,"id":5300737}]}]}
{"op":"mcm","clk":"4298701805","pt":1632578458614,"mc":[{"id":"1.188136695","rc":[{"batb":[[0,2.02,43.78],[1,2,207.99],[2,1.97,73.68]],"batl":[[0,2.08,1806.76]],"ltp":2.02,"tv":4297.59,"id":5300737}]}]}
{"op":"mcm","clk":"4298702218","pt":1632578459585,"mc":[{"id":"1.188136695","rc":[{"batb":[[0,1.96,464.63],[1,1.94,428.56],[2,1.92,357.72]],"ltp":1.98,"tv":13834.94,"id":2497008}]}]}
{"op":"mcm","clk":"4298706677","pt":1632578474597,"mc":[{"id":"1.188136695","rc":[{"batl":[[0,2.04,293.25]],"ltp":2.02,"tv":4297.59,"id":5300737},{"batb":[[0,1.97,45.33],[1,1.96,464.63],[2,1.94,428.56]],"ltp":1.98,"tv":13834.94,"id":2497008}]}]}
{"op":"mcm","clk":"4298708730","pt":1632578480791,"mc":[{"id":"1.188136695","rc":[{"trd":[[2.02,703.46]],"batb":[[0,2.02,33.78]],"ltp":2.02,"tv":4317.58,"id":5300737}],"tv":18152.53}]}
{"op":"mcm","clk":"4298710307","pt":1632578486500,"mc":[{"id":"1.188136695","rc":[{"batb":[[1,1.96,455.92]],"ltp":1.98,"tv":13834.94,"id":2497008}]}]}
{"op":"mcm","clk":"4298710774","pt":1632578488116,"mc":[{"id":"1.188136695","rc":[{"batb":[[0,1.97,74.52]],"ltp":1.98,"tv":13834.94,"id":2497008}]}]}
{"op":"mcm","clk":"4298711936","pt":1632578492128,"mc":[{"id":"1.188136695","rc":[{"trd":[[2.02,723.46]],"batb":[[0,2.02,23.78]],"ltp":2.02,"tv":4337.58,"id":5300737}],"tv":18172.53}]}
{"op":"mcm","clk":"4298712640","pt":1632578494674,"mc":[{"id":"1.188136695","rc":[{"batb":[[2,1.98,16.17]],"ltp":2.02,"tv":4337.58,"id":5300737},{"trd":[[1.98,1323.35]],"batb":[[0,1.97,82.16]],"batl":[[0,1.98,116.21]],"ltp":1.98,"tv":13862.71,"id":2497008}],"tv":18200.3}]}
{"op":"mcm","clk":"4298712896","pt":1632578495492,"mc":[{"id":"1.188136695","rc":[{"trd":[[1.98,1346.91]],"batl":[[0,1.98,104.43]],"ltp":1.98,"tv":13886.27,"id":2497008}],"tv":18223.85}]}
{"op":"mcm","clk":"4298713583","pt":1632578497607,"mc":[{"id":"1.188136695","rc":[{"batb":[[0,2,207.99],[1,1.98,16.17],[2,1.97,73.68]],"ltp":2.02,"tv":4337.58,"id":5300737},{"trd":[[1.98,1387.72]],"batl":[[0,1.98,84.03]],"ltp":1.98,"tv":13927.08,"id":2497008}],"tv":18264.66}]}
{"op":"mcm","clk":"4298715523","pt":1632578504251,"mc":[{"id":"1.188136695","rc":[{"batl":[[0,2.04,286.12]],"ltp":2.02,"tv":4337.58,"id":5300737}]}]}
{"op":"mcm","clk":"4298716458","pt":1632578507162,"mc":[{"id":"1.188136695","rc":[{"trd":[[1.97,3766.45]],"batb":[[0,1.97,81.09]],"ltp":1.97,"tv":13929.21,"id":2497008}],"tv":18266.8}]}
{"op":"mcm","clk":"4298717289","pt":1632578510149,"mc":[{"id":"1.188136695","rc":[{"trd":[[1.98,1389.28]],"batl":[[0,1.98,83.25]],"ltp":1.98,"tv":13930.77,"id":2497008}],"tv":18268.36}]}
{"op":"mcm","clk":"4298717782","pt":1632578511873,"mc":[{"id":"1.188136695","rc":[{"trd":[[1.97,3775.24]],"batb":[[0,1.97,76.69]],"ltp":1.97,"tv":13939.56,"id":2497008}],"tv":18277.15}]}
{"op":"mcm","clk":"4298720596","pt":1632578522662,"mc":[{"id":"1.188136695","rc":[{"trd":[[1.98,1474.99]],"batl":[[0,1.98,40.4]],"ltp":1.98,"tv":14025.27,"id":2497008}],"tv":18362.86}]}
{"op":"mcm","clk":"4298720657","pt":1632578522880,"mc":[{"id":"1.188136695","rc":[{"trd":[[1.98,1514.99]],"batl":[[0,1.98,20.39]],"ltp":1.98,"tv":14065.27,"id":2497008}],"tv":18402.86}]}
{"op":"mcm","clk":"4298721080","pt":1632578524350,"mc":[{"id":"1.188136695","rc":[{"batb":[[0,1.97,101.47]],"ltp":1.98,"tv":14065.27,"id":2497008}]}]}
{"op":"mcm","clk":"4298722374","pt":1632578529227,"mc":[{"id":"1.188136695","rc":[{"batl":[[1,1.99,71.15],[2,2.04,79.08]],"ltp":1.98,"tv":14065.27,"id":2497008}]}]}
{"op":"mcm","clk":"4298723253","pt":1632578532422,"mc":[{"id":"1.188136695","rc":[{"batb":[[0,2,465.12]],"ltp":2.02,"tv":4337.58,"id":5300737}]}]}
{"op":"mcm","clk":"4298723432","pt":1632578532976,"mc":[{"id":"1.188136695","rc":[{"batb":[[0,2,545.44],[1,1.99,43.87],[2,1.98,16.17]],"ltp":2.02,"tv":4337.58,"id":5300737}]}]}
{"op":"mcm","clk":"4298725963","pt":1632578541716,"mc":[{"id":"1.188136695","rc":[{"batb":[[1,1.96,483.35]],"ltp":1.98,"tv":14065.27,"id":2497008}]}]}
{"op":"mcm","clk":"4298728288","pt":1632578549402,"mc":[{"id":"1.188136695","rc":[{"trd":[[1.96,1710.82],[1.97,3978.19]],"batb":[[0,1.96,14.55],[1,1.94,428.56],[2,1.92,357.72]],"ltp":1.96,"tv":15205.83,"id":2497008}],"tv":19543.41}]}
{"op":"mcm","clk":"4298728655","pt":1632578550622,"mc":[{"id":"1.188136695","rc":[{"batb":[[0,2.02,96.84],[1,2,545.44],[2,1.99,43.87]],"ltp":2.02,"tv":4337.58,"id":5300737},{"batb":[[1,1.95,11.47],[2,1.94,428.56]],"ltp":1.96,"tv":15205.83,"id":2497008}]}]}
{"op":"mcm","clk":"4298729286","pt":1632578552737,"mc":[{"id":"1.188136695","rc":[{"trd":[[2.04,1103.45]],"batb":[[0,2,465.12],[1,1.98,16.17],[2,1.97,73.68]],"batl":[[0,2.04,190.22]],"ltp":2.04,"tv":4529.38,"id":5300737}],"tv":19735.21}]}
{"op":"mcm","clk":"4298731704","pt":1632578560929,"mc":[{"id":"1.188136695","rc":[{"batb":[[0,2.02,35.11],[1,2,465.12],[2,1.98,16.17]],"ltp":2.04,"tv":4529.38,"id":5300737}]}]}
{"op":"mcm","clk":"4298737182","pt":1632578579548,"mc":[{"id":"1.188136695","rc":[{"batl":[[0,2.04,371.14]],"ltp":2.04,"tv":4529.38,"id":5300737}]}]}
{"op":"mcm","clk":"4298738704","pt":1632578584780,"mc":[{"id":"1.188136695","rc":[{"batb":[[0,1.97,87.3],[1,1.96,73.12],[2,1.95,11.47]],"ltp":1.96,"tv":15205.83,"id":2497008}]}]}
{"op":"mcm","clk":"4298739793","pt":1632578588577,"mc":[{"id":"1.188136695","rc":[{"batb":[[1,1.96,28.67]],"ltp":1.96,"tv":15205.83,"id":2497008}]}]}
{"op":"mcm","clk":"4298741482","pt":1632578594367,"mc":[{"id":"1.188136695","rc":[{"batb":[[2,1.98,22.25]],"ltp":2.04,"tv":4529.38,"id":5300737}]}]}
{"op":"mcm","clk":"4298745122","pt":1632578606694,"mc":[{"id":"1.188136695","rc":[{"trd":[[2.02,813.67]],"batb":[[0,2,465.12],[1,1.98,22.25],[2,1.97,38.57]],"batl":[[0,2.02,2514.8],[1,2.04,371.14],[2,2.1,10.62]],"ltp":2.02,"tv":4619.59,"id":5300737},{"trd":[[1.98,1535.38]],"batb":[[0,1.98,92.14],[1,1.97,87.3],[2,1.96,28.67]],"batl":[[0,1.99,71.15],[1,2.04,79.08],[2,2.06,23.99]],"ltp":1.98,"tv":15226.22,"id":2497008}],"tv":19845.81}]}
{"op":"mcm","clk":"4298748209","pt":1632578617815,"mc":[{"id":"1.188136695","rc":[{"trd":[[2.02,892.14]],"batb":[[0,2,556.34]],"batl":[[0,2.02,2436.33]],"ltp":2.02,"tv":4698.06,"id":5300737},{"trd":[[1.98,1799.72]],"batb":[[0,1.97,87.3],[1,1.96,28.67],[2,1.95,11.47]],"ltp":1.98,"tv":15490.56,"id":2497008}],"tv":20188.62}]}
{"op":"mcm","clk":"4298751803","pt":1632578631248,"mc":[{"id":"1.188136695","rc":[{"trd":[[2.02,2572.43]],"batl":[[0,2.02,756.04]],"ltp":2.02,"tv":6378.35,"id":5300737},{"trd":[[1.98,3513.95]],"batb":[[0,1.97,50.86]],"ltp":1.98,"tv":17204.79,"id":2497008}],"tv":23583.14}]}
{"op":"mcm","clk":"4298752312","pt":1632578632912,"mc":[{"id":"1.188136695","rc":[{"batl":[[0,2.02,756.67]],"ltp":2.02,"tv":6378.35,"id":5300737}]}]}
{"op":"mcm","clk":"4298752685","pt":1632578634317,"mc":[{"id":"1.188136695","rc":[{"batb":[[0,1.97,31.48]],"ltp":1.98,"tv":17204.79,"id":2497008}]}]}
{"op":"mcm","clk":"4298759479","pt":1632578658746,"mc":[{"id":"1.188136695","rc":[{"trd":[[1.99,729.78]],"batb":[[0,1.99,14.56],[1,1.97,31.48],[2,1.96,28.67]],"batl":[[0,2.04,286.15],[1,2.06,23.99],[2,2.3,5.85]],"ltp":1.99,"tv":17347.09,"id":2497008}],"tv":23725.44}]}
{"op":"mcm","clk":"4298759570","pt":1632578659069,"mc":[{"id":"1.188136695","rc":[{"batb":[[2,1.96,14.55]],"ltp":1.99,"tv":17347.09,"id":2497008}]}]}
{"op":"mcm","clk":"4298761998","pt":1632578667667,"mc":[{"id":"1.188136695","rc":[{"trd":[[1.99,739.77]],"batb":[[0,1.99,9.57],[1,1.97,12.83]],"ltp":1.99,"tv":17357.09,"id":2497008}],"tv":23735.44}]}
{"op":"mcm","clk":"4298768116","pt":1632578686937,"mc":[{"id":"1.188136695","rc":[{"trd":[[2,1862.9]],"batb":[[0,2,512.34]],"ltp":2.0,"tv":6466.34,"id":5300737}],"tv":23823.43}]}
{"op":"mcm","clk":"4298770451","pt":1632578693830,"mc":[{"id":"1.188136695","rc":[{"batb":[[1,1.98,16.17]],"ltp":2.0,"tv":6466.34,"id":5300737},{"trd":[[1.99,755.8]],"batb":[[0,1.99,1.55]],"ltp":1.99,"tv":17373.11,"id":2497008}],"tv":23839.46}]}
{"op":"mcm","clk":"4298770625","pt":1632578694328,"mc":[{"id":"1.188136695","rc":[{"batb":[[1,1.97,25.93]],"ltp":1.99,"tv":17373.11,"id":2497008}]}]}
{"op":"mcm","clk":"4298771083","pt":1632578695623,"mc":[{"id":"1.188136695","rc":[{"batl":[[0,2.04,140.57]],"ltp":1.99,"tv":17373.11,"id":2497008}]}]}
{"op":"mcm","clk":"4298771457","pt":1632578696733,"mc":[{"id":"1.188136695","rc":[{"trd":[[1.99,758.9]],"batb":[[0,1.97,25.93],[1,1.96,14.55],[2,1.95,18.01]],"batl":[[0,1.99,794.88],[1,2.04,79.08],[2,2.06,23.99]],"ltp":1.99,"tv":17376.22,"id":2497008}],"tv":23842.56}]}
{"op":"mcm","clk":"4298772469","pt":1632578699745,"mc":[{"id":"1.188136695","rc":[{"trd":[[2.02,3329.1]],"batl":[[0,2.04,371.14],[1,2.1,10.62],[2,2.12,51.29]],"ltp":2.02,"tv":7223.01,"id":5300737},{"trd":[[1.98,4285.91]],"batl":[[0,1.98,22.93],[1,2.04,432.61]],"ltp":1.98,"tv":18148.17,"id":2497008}],"tv":25371.19}]}
{"op":"mcm","clk":"4298772808","pt":1632578700774,"mc":[{"id":"1.188136695","rc":[{"batl":[[1,2.04,79.08]],"ltp":1.98,"tv":18148.17,"id":2497008}]}]}
{"op":"mcm","clk":"4298773111","pt":1632578701754,"mc":[{"id":"1.188136695","rc":[{"batb":[[0,2.02,90.31],[1,2,512.34],[2,1.98,16.17]],"ltp":2.02,"tv":7223.01,"id":5300737}]}]}
{"op":"mcm","clk":"4298773429","pt":1632578702738,"mc":[{"id":"1.188136695","rc":[{"trd":[[2.02,3519.41]],"batb":[[0,2,497.02],[1,1.98,16.17],[2,1.97,38.57]],"ltp":2.02,"tv":7413.32,"id":5300737},{"trd":[[1.98,4295.8]],"batb":[[0,1.96,14.55],[1,1.95,18.01],[2,1.94,428.56]],"batl":[[0,1.98,13.04]],"ltp":1.98,"tv":18158.06,"id":2497008}],"tv":25571.39}]}
{"op":"mcm","clk":"4298773753","pt":1632578703736,"mc":[{"id":"1.188136695","rc":[{"trd":[[1.98,4315.79]],"batl":[[0,1.98,3.04]],"ltp":1.98,"tv":18178.06,"id":2497008}],"tv":25591.38}]}
{"op":"mcm","clk":"4298774042","pt":1632578704727,"mc":[{"id":"1.188136695","rc":[{"batb":[[0,1.96,94.46]],"batl":[[0,1.97,3.04]],"ltp":1.98,"tv":18178.06,"id":2497008}]}]}
{"op":"mcm","clk":"4298774260","pt":1632578705444,"mc":[{"id":"1.188136695","rc":[{"batb":[[0,2,421.13]],"ltp":2.02,"tv":7413.32,"id":5300737}]}]}
{"op":"mcm","clk":"4298775027","pt":1632578707749,"mc":[{"id":"1.188136695","rc":[{"trd":[[2,1915.6]],"batb":[[0,2,394.78]],"ltp":2.0,"tv":7466.02,"id":5300737},{"trd":[[1.96,1716.9]],"batb":[[0,1.96,91.42]],"batl":[[0,2.04,432.64],[1,2.06,23.99],[2,2.3,5.85]],"ltp":1.96,"tv":18184.14,"id":2497008}],"tv":25650.17}]}
{"op":"mcm","clk":"4298775440","pt":1632578708915,"mc":[{"id":"1.188136695","rc":[{"batb":[[0,1.97,32.54],[1,1.96,91.42],[2,1.95,18.01]],"ltp":1.96,"tv":18184.14,"id":2497008}]}]}
{"op":"mcm","clk":"4298777255","pt":1632578714648,"mc":[{"id":"1.188136695","rc":[{"batl":[[0,2.02,38.57],[1,2.04,371.14],[2,2.1,10.62]],"ltp":2.0,"tv":7466.02,"id":5300737},{"batb":[[0,1.97,87.19]],"ltp":1.96,"tv":18184.14,"id":2497008}]}]}
{"op":"mcm","clk":"4298778160","pt":1632578717674,"mc":[{"id":"1.188136695","rc":[{"batl":[[0,2.04,371.14],[1,2.1,10.62],[2,2.12,51.29]],"ltp":2.0,"tv":7466.02,"id":5300737}]}]}
{"op":"mcm","clk":"4298780456","pt":1632578725168,"mc":[{"id":"1.188136695","rc":[{"trd":[[2,1992.74]],"batb":[[0,2,356.21]],"ltp":2.0,"tv":7543.16,"id":5300737}],"tv":25727.31}]}
{"op":"mcm","clk":"4298785400","pt":1632578740340,"mc":[{"id":"1.188136695","rc":[{"batb":[[1,1.96,274.3]],"ltp":1.96,"tv":18184.14,"id":2497008}]}]}
{"op":"mcm","clk":"4298786421","pt":1632578743600,"mc":[{"id":"1.188136695","rc":[{"batl":[[0,2.04,339.93]],"ltp":1.96,"tv":18184.14,"id":2497008}]}]}
{"op":"mcm","clk":"4298787995","pt":1632578748594,"mc":[{"id":"1.188136695","rc":[{"batb":[[0,1.98,25.71],[1,1.97,87.19],[2,1.96,274.3]],"ltp":1.96,"tv":18184.14,"id":2497008}]}]}
{"op":"mcm","clk":"4298788854","pt":1632578751427,"mc":[{"id":"1.188136695","rc":[{"batl":[[0,2.02,135.42],[1,2.04,371.14],[2,2.1,10.62]],"ltp":2.0,"tv":7543.16,"id":5300737}]}]}
{"op":"mcm","clk":"4298791003","pt":1632578758106,"mc":[{"id":"1.188136695","rc":[{"trd":[[2,2080.61]],"batb":[[0,2,312.27]],"ltp":2.0,"tv":7631.03,"id":5300737}],"tv":25815.18}]}
{"op":"mcm","clk":"4298791538","pt":1632578759822,"mc":[{"id":"1.188136695","rc":[{"batb":[[2,1.96,91.42]],"ltp":1.96,"tv":18184.14,"id":2497008}]}]}
{"op":"mcm","clk":"4298792281","pt":1632578762236,"mc":[{"id":"1.188136695","rc":[{"batl":[[0,2.02,139.71]],"ltp":2.0,"tv":7631.03,"id":5300737}]}]}
{"op":"mcm","clk":"4298795581","pt":1632578772649,"mc":[{"id":"1.188136695","rc":[{"batl":[[0,2.04,510.85],[1,2.1,10.62],[2,2.12,51.29]],"ltp":2.0,"tv":7631.03,"id":5300737}]}]}
{"op":"mcm","clk":"4298795957","pt":1632578773723,"mc":[{"id":"1.188136695","rc":[{"trd":[[2,2080.82]],"batb":[[0,2,312.17]],"ltp":2.0,"tv":7631.24,"id":5300737}],"tv":25815.38}]}
{"op":"mcm","clk":"4298796884","pt":1632578776750,"mc":[{"id":"1.188136695","rc":[{"batl":[[0,2.02,139.71],[1,2.04,371.14],[2,2.1,10.62]],"ltp":2.0,"tv":7631.24,"id":5300737}]}]}
{"op":"mcm","clk":"4298800617","pt":1632578788767,"mc":[{"id":"1.188136695","rc":[{"trd":[[2,2705.16]],"batb":[[0,1.98,16.17],[1,1.97,38.57],[2,1.96,182.8]],"batl":[[0,2,8.97],[1,2.02,139.71],[2,2.04,371.14]],"ltp":2.0,"tv":8255.58,"id":5300737}],"tv":26439.72}]}
{"op":"mcm","clk":"4298800878","pt":1632578789635,"mc":[{"id":"1.188136695","rc":[{"batl":[[0,2.04,140.57]],"ltp":1.96,"tv":18184.14,"id":2497008}]}]}
{"op":"mcm","clk":"4298801216","pt":1632578790781,"mc":[{"id":"1.188136695","rc":[{"batl":[[0,2.04,113.36]],"ltp":1.96,"tv":18184.14,"id":2497008}]}]}
{"op":"mcm","clk":"4298802386","pt":1632578794670,"mc":[{"id":"1.188136695","rc":[{"trd":[[2,2720.4]],"batb":[[0,1.97,56.44],[1,1.96,182.8],[2,1.94,10.62]],"batl":[[0,2.02,139.71],[1,2.04,371.14],[2,2.1,10.62]],"ltp":2.0,"tv":8270.82,"id":5300737},{"trd":[[2,2478.23]],"batb":[[0,1.98,36.11]],"ltp":2.0,"tv":18186.85,"id":2497008}],"tv":26457.67}]}
{"op":"mcm","clk":"4298802515","pt":1632578795073,"mc":[{"id":"1.188136695","rc":[{"batb":[[0,1.97,52.01]],"ltp":2.0,"tv":8270.82,"id":5300737},{"batl":[[0,2.04,79.08]],"ltp":2.0,"tv":18186.85,"id":2497008}]}]}
{"op":"mcm","clk":"4298802978","pt":1632578796684,"mc":[{"id":"1.188136695","rc":[{"trd":[[2,2478.59]],"batl":[[0,2,4.11],[1,2.04,79.08],[2,2.06,23.99]],"ltp":2.0,"tv":18187.21,"id":2497008}],"tv":26458.03}]}
{"op":"mcm","clk":"4298803042","pt":1632578796880,"mc":[{"id":"1.188136695","rc":[{"trd":[[2,2486.81]],"batl":[[0,2.04,79.08],[1,2.06,23.99],[2,2.3,5.85]],"ltp":2.0,"tv":18195.42,"id":2497008}],"tv":26466.25}]}
{"op":"mcm","clk":"4298804274","pt":1632578800778,"mc":[{"id":"1.188136695","rc":[{"batl":[[0,2,139.71]],"ltp":2.0,"tv":8270.82,"id":5300737}]}]}
{"op":"mcm","clk":"4298804839","pt":1632578802828,"mc":[{"id":"1.188136695","rc":[{"trd":[[2,2805.51]],"batl":[[0,2,97.15]],"ltp":2.0,"tv":8355.93,"id":5300737}],"tv":26551.36}]}
{"op":"mcm","clk":"4298805174","pt":1632578803614,"mc":[{"id":"1.188136695","rc":[{"batb":[[2,1.96,11.5]],"ltp":2.0,"tv":18195.42,"id":2497008}]}]}
{"op":"mcm","clk":"4298805443","pt":1632578804468,"mc":[{"id":"1.188136695","rc":[{"batb":[[0,2,71.2],[1,1.98,36.11],[2,1.97,87.19]],"ltp":2.0,"tv":18195.42,"id":2497008}]}]}
{"op":"mcm","clk":"4298808412","pt":1632578813786,"mc":[{"id":"1.188136695","rc":[{"trd":[[2,3071.02]],"batb":[[0,2,90.72],[1,1.97,52.01],[2,1.96,182.8]],"batl":[[0,2.04,371.14],[1,2.1,10.62],[2,2.12,51.29]],"ltp":2.0,"tv":8621.44,"id":5300737},{"trd":[[2,2558.01]],"batb":[[0,1.98,36.11],[1,1.97,44.71],[2,1.96,11.5]],"ltp":2.0,"tv":18266.62,"id":2497008}],"tv":26888.07}]}
{"op":"mcm","clk":"4298808659","pt":1632578814609,"mc":[{"id":"1.188136695","rc":[{"batl":[[0,2.04,100.25]],"ltp":2.0,"tv":18266.62,"id":2497008}]}]}
{"op":"mcm","clk":"4298811215","pt":1632578823020,"mc":[{"id":"1.188136695","rc":[{"trd":[[2,3091.2]],"batb":[[0,2,80.63]],"ltp":2.0,"tv":8641.62,"id":5300737}],"tv":26908.25}]}
{"op":"mcm","clk":"4298811816","pt":1632578824935,"mc":[{"id":"1.188136695","rc":[{"trd":[[2,3095.2]],"batb":[[0,2,78.63]],"ltp":2.0,"tv":8645.62,"id":5300737}],"tv":26912.25}]}
{"op":"mcm","clk":"4298813324","pt":1632578829808,"mc":[{"id":"1.188136695","rc":[{"batb":[[0,2,548.3]],"ltp":2.0,"tv":8645.62,"id":5300737}]}]}
{"op":"mcm","clk":"4298813540","pt":1632578830540,"mc":[{"id":"1.188136695","rc":[{"batl":[[1,2.1,13.26]],"ltp":2.0,"tv":8645.62,"id":5300737}]}]}
{"op":"mcm","clk":"4298814121","pt":1632578832432,"mc":[{"id":"1.188136695","rc":[{"trd":[[2,3898.06]],"batb":[[0,2,146.87]],"ltp":2.0,"tv":9448.48,"id":5300737}],"tv":27715.11}]}
{"op":"mcm","clk":"4298814662","pt":1632578834013,"mc":[{"id":"1.188136695","rc":[{"batl":[[0,2.04,593.73]],"ltp":2.0,"tv":9448.48,"id":5300737}]}]}
{"op":"mcm","clk":"4298815840","pt":1632578837814,"mc":[{"id":"1.188136695","rc":[{"batl":[[0,2.02,19.7],[1,2.04,593.73],[2,2.1,13.26]],"ltp":2.0,"tv":9448.48,"id":5300737},{"trd":[[1.98,4350.94]],"batb":[[0,1.98,18.54]],"ltp":1.98,"tv":18301.77,"id":2497008}],"tv":27750.25}]}
{"op":"mcm","clk":"4298816798","pt":1632578840733,"mc":[{"id":"1.188136695","rc":[{"batb":[[2,1.95,211.81]],"ltp":2.0,"tv":9448.48,"id":5300737},{"batb":[[2,1.96,193.12]],"ltp":1.98,"tv":18301.77,"id":2497008}]}]}
{"op":"mcm","clk":"4298819315","pt":1632578848651,"mc":[{"id":"1.188136695","rc":[{"trd":[[2.02,3526.72]],"batl":[[0,2.02,12.39]],"ltp":2.02,"tv":9455.79,"id":5300737},{"trd":[[1.98,4395.48]],"batb":[[0,1.97,44.71],[1,1.96,193.12],[2,1.94,428.56]],"ltp":1.98,"tv":18346.31,"id":2497008}],"tv":27802.1}]}
{"op":"mcm","clk":"4298819519","pt":1632578849384,"mc":[{"id":"1.188136695","rc":[{"batl":[[1,2.04,371.14]],"ltp":2.02,"tv":9455.79,"id":5300737},{"batb":[[0,1.97,51.63]],"ltp":1.98,"tv":18346.31,"id":2497008}]}]}
{"op":"mcm","clk":"4298819711","pt":1632578849962,"mc":[{"id":"1.188136695","rc":[{"batb":[[0,1.97,106.54]],"ltp":1.98,"tv":18346.31,"id":2497008}]}]}
{"op":"mcm","clk":"4298822357","pt":1632578858465,"mc":[{"id":"1.188136695","rc":[{"trd":[[2,3920]],"batb":[[0,2,135.9]],"ltp":2.0,"tv":9477.73,"id":5300737}],"tv":27824.04}]}
{"op":"mcm","clk":"4298826869","pt":1632578872596,"mc":[{"id":"1.188136695","rc":[{"trd":[[2,4191.8]],"batb":[[0,1.97,52.01],[1,1.95,211.81],[2,1.94,10.62]],"batl":[[0,2,114.1],[1,2.02,12.39],[2,2.04,371.14]],"ltp":2.0,"tv":9749.53,"id":5300737}],"tv":28095.84}]}
{"op":"mcm","clk":"4298827104","pt":1632578873318,"mc":[{"id":"1.188136695","rc":[{"batb":[[0,1.97,62.92],[1,1.95,184.74]],"batl":[[0,2,412.4]],"ltp":2.0,"tv":9749.53,"id":5300737},{"batb":[[0,1.97,130.06],[2,1.95,27.07]],"ltp":1.98,"tv":18346.31,"id":2497008}]}]}
{"op":"mcm","clk":"4298829686","pt":1632578881097,"mc":[{"id":"1.188136695","rc":[{"batl":[[0,2,285.6]],"ltp":2.0,"tv":9749.53,"id":5300737}]}]}
{"op":"mcm","clk":"4298834116","pt":1632578894324,"mc":[{"id":"1.188136695","rc":[{"trd":[[2,4199.12]],"batb":[[0,1.98,10.96],[1,1.97,49.48],[2,1.95,184.74]],"batl":[[0,2,278.28]],"ltp":2.0,"tv":9756.85,"id":5300737},{"trd":[[2,2565.33]],"batb":[[0,1.97,136.01]],"ltp":2.0,"tv":18353.63,"id":2497008}],"tv":28110.48}]}
{"op":"mcm","clk":"4298834529","pt":1632578895595,"mc":[{"id":"1.188136695","rc":[{"batb":[[1,1.97,38.57]],"ltp":2.0,"tv":9756.85,"id":5300737},{"batl":[[0,2.04,79.08]],"ltp":2.0,"tv":18353.63,"id":2497008}]}]}
{"op":"mcm","clk":"4298835270","pt":1632578897829,"mc":[{"id":"1.188136695","rc":[{"trd":[[1.97,296.93],[1.98,124.15]],"batb":[[0,1.96,11.99],[1,1.95,349.28],[2,1.94,10.62]],"ltp":1.97,"tv":10057.92,"id":5300737}],"tv":28411.56}]}
{"op":"mcm","clk":"4298835617","pt":1632578898818,"mc":[{"id":"1.188136695","rc":[{"batl":[[0,1.97,4],[1,2,278.28],[2,2.02,12.39]],"ltp":1.97,"tv":10057.92,"id":5300737},{"batb":[[0,1.99,117.76],[1,1.98,64.64],[2,1.97,36.39]],"ltp":2.0,"tv":18353.63,"id":2497008}]}]}
{"op":"mcm","clk":"4298835948","pt":1632578899822,"mc":[{"id":"1.188136695","rc":[{"batb":[[1,1.95,184.74]],"ltp":1.97,"tv":10057.92,"id":5300737}]}]}
{"op":"mcm","clk":"4298838809","pt":1632578908635,"mc":[{"id":"1.188136695","rc":[{"batb":[[2,1.97,12.87]],"ltp":2.0,"tv":18353.63,"id":2497008}]}]}
{"op":"mcm","clk":"4298839136","pt":1632578909728,"mc":[{"id":"1.188136695","rc":[{"batb":[[0,1.99,133.23]],"ltp":2.0,"tv":18353.63,"id":2497008}]}]}
{"op":"mcm","clk":"4298839411","pt":1632578910633,"mc":[{"id":"1.188136695","rc":[{"batl":[[0,1.98,4]],"ltp":1.97,"tv":10057.92,"id":5300737},{"batb":[[0,2,44],[1,1.99,116.62],[2,1.98,64.64]],"ltp":2.0,"tv":18353.63,"id":2497008}]}]}
{"op":"mcm","clk":"4298839575","pt":1632578911145,"mc":[{"id":"1.188136695","rc":[{"batb":[[1,1.99,101.15]],"ltp":2.0,"tv":18353.63,"id":2497008}]}]}
{"op":"mcm","clk":"4298842393","pt":1632578919948,"mc":[{"id":"1.188136695","rc":[{"trd":[[1.98,126.39]],"batl":[[0,1.98,1.76]],"ltp":1.98,"tv":10060.16,"id":5300737},{"trd":[[2.02,17.66]],"ltp":2.02,"tv":18355.82,"id":2497008}],"tv":28415.99}]}
{"op":"mcm","clk":"4298844100","pt":1632578925283,"mc":[{"id":"1.188136695","rc":[{"trd":[[1.96,14]],"batb":[[0,1.96,9.99]],"ltp":1.96,"tv":10064.16,"id":5300737}],"tv":28419.99}]}
{"op":"mcm","clk":"4298844525","pt":1632578926587,"mc":[{"id":"1.188136695","rc":[{"batb":[[0,2,24.21]],"ltp":2.02,"tv":18355.82,"id":2497008}]}]}
{"op":"mcm","clk":"4298845449","pt":1632578929500,"mc":[{"id":"1.188136695","rc":[{"batb":[[0,1.97,38.57],[1,1.96,9.99],[2,1.95,184.74]],"ltp":1.96,"tv":10064.16,"id":5300737}]}]}
{"op":"mcm","clk":"4298845823","pt":1632578930678,"mc":[{"id":"1.188136695","rc":[{"batl":[[0,2.06,23.99],[1,2.3,5.85],[2,2.42,7.31]],"ltp":2.02,"tv":18355.82,"id":2497008}]}]}
{"op":"mcm","clk":"4298846261","pt":1632578932098,"mc":[{"id":"1.188136695","rc":[{"trd":[[1.97,330.76]],"batb":[[0,1.97,21.66]],"ltp":1.97,"tv":10097.98,"id":5300737}],"tv":28453.81}]}
{"op":"mcm","clk":"4298846733","pt":1632578933705,"mc":[{"id":"1.188136695","rc":[{"batl":[[0,2.3,6.64],[1,2.42,7.31],[2,2.62,2.65]],"ltp":2.02,"tv":18355.82,"id":2497008}]}]}
{"op":"mcm","clk":"4298846820","pt":1632578934012,"mc":[{"id":"1.188136695","rc":[{"batl":[[0,2.28,520.35],[1,2.3,5.85],[2,2.42,7.31]],"ltp":2.02,"tv":18355.82,"id":2497008}]}]}
{"op":"mcm","clk":"4298847227","pt":1632578935317,"mc":[{"id":"1.188136695","rc":[{"batb":[[0,2,32.33]],"ltp":2.02,"tv":18355.82,"id":2497008}]}]}
{"op":"mcm","clk":"4298848367","pt":1632578938710,"mc":[{"id":"1.188136695","rc":[{"trd":[[1.96,33.98],[1.97,374.07]],"batb":[[0,1.95,184.74],[1,1.94,10.62],[2,1.93,2.91]],"batl":[[0,1.96,95.15],[1,1.98,1.76],[2,2,278.28]],"ltp":1.96,"tv":10161.29,"id":5300737}],"tv":28517.11}]}
{"op":"mcm","clk":"4298848657","pt":1632578939600,"mc":[{"id":"1.188136695","rc":[{"trd":[[1.96,112.44]],"batb":[[2,1.93,20.63]],"batl":[[0,1.96,55.92]],"ltp":1.96,"tv":10239.75,"id":5300737}],"tv":28595.57}]}
{"op":"mcm","clk":"4298848967","pt":1632578940606,"mc":[{"id":"1.188136695","rc":[{"batb":[[1,1.97,39.38],[2,1.96,193.12]],"ltp":2.02,"tv":18355.82,"id":2497008}]}]}
{"op":"mcm","clk":"4298849192","pt":1632578941295,"mc":[{"id":"1.188136695","rc":[{"batb":[[0,1.97,278.94],[1,1.96,193.12],[2,1.95,27.07]],"ltp":2.02,"tv":18355.82,"id":2497008}]}]}
{"op":"mcm","clk":"4298849810","pt":1632578943272,"mc":[{"id":"1.188136695","rc":[{"batl":[[0,2.26,544.8]],"ltp":2.02,"tv":18355.82,"id":2497008}]}]}
{"op":"mcm","clk":"4298854472","pt":1632578958725,"mc":[{"id":"1.188136695","rc":[{"batl":[[0,1.98,1.76],[1,2,278.28],[2,2.02,12.39]],"ltp":1.96,"tv":10239.75,"id":5300737}]}]}
{"op":"mcm","clk":"4298854898","pt":1632578960125,"mc":[{"id":"1.188136695","rc":[{"trd":[[1.95,227.99]],"batb":[[0,1.95,70.75]],"ltp":1.95,"tv":10467.74,"id":5300737},{"batb":[[0,1.97,252.43]],"ltp":2.02,"tv":18355.82,"id":2497008}],"tv":28823.57}]}
{"op":"mcm","clk":"4298855340","pt":1632578961655,"mc":[{"id":"1.188136695","rc":[{"batb":[[0,1.94,3206.42],[1,1.93,20.63],[2,1.91,28.26]],"ltp":1.95,"tv":10467.74,"id":5300737},{"batb":[[0,1.98,359.85],[1,1.97,252.43],[2,1.96,11.5]],"ltp":2.02,"tv":18355.82,"id":2497008}]}]}
{"op":"mcm","clk":"4298855645","pt":1632578962620,"mc":[{"id":"1.188136695","rc":[{"batb":[[2,1.9,33.57]],"ltp":1.95,"tv":10467.74,"id":5300737},{"batb":[[2,1.96,38.29]],"ltp":2.02,"tv":18355.82,"id":2497008}]}]}
{"op":"mcm","clk":"4298856009","pt":1632578963794,"mc":[{"id":"1.188136695","rc":[{"batb":[[0,1.94,3195.8]],"ltp":1.95,"tv":10467.74,"id":5300737}]}]}
{"op":"mcm","clk":"4298856285","pt":1632578964550,"mc":[{"id":"1.188136695","rc":[{"batb":[[0,1.94,2517.78]],"ltp":1.95,"tv":10467.74,"id":5300737}]}]}
{"op":"mcm","clk":"4298858312","pt":1632578971449,"mc":[{"id":"1.188136695","rc":[{"batb":[[0,1.94,2517.62]],"ltp":1.95,"tv":10467.74,"id":5300737},{"batb":[[0,1.98,362.79],[1,1.97,12.87]],"ltp":2.02,"tv":18355.82,"id":2497008}]}]}
{"op":"mcm","clk":"4298860748","pt":1632578979668,"mc":[{"id":"1.188136695","rc":[{"trd":[[1.94,111.84]],"batb":[[0,1.94,2461.7]],"ltp":1.94,"tv":10579.58,"id":5300737}],"tv":28935.41}]}
{"op":"mcm","clk":"4298861277","pt":1632578981473,"mc":[{"id":"1.188136695","rc":[{"batb":[[0,1.99,358.5],[1,1.98,2.94],[2,1.97,12.87]],"ltp":2.02,"tv":18355.82,"id":2497008}]}]}
{"op":"mcm","clk":"4298861985","pt":1632578983773,"mc":[{"id":"1.188136695","rc":[{"batb":[[0,1.95,5.31],[1,1.94,2461.7],[2,1.93,20.63]],"ltp":1.94,"tv":10579.58,"id":5300737},{"batl":[[0,2.3,6.64],[1,2.42,7.31],[2,2.62,2.65]],"ltp":2.02,"tv":18355.82,"id":2497008}]}]}
{"op":"mcm","clk":"4298862056","pt":1632578983961,"mc":[{"id":"1.188136695","rc":[{"batl":[[0,2.22,624.02],[1,2.3,5.85],[2,2.42,7.31]],"ltp":2.02,"tv":18355.82,"id":2497008}]}]}
{"op":"mcm","clk":"4298865087","pt":1632578994162,"mc":[{"id":"1.188136695","rc":[{"batb":[[0,1.95,12.71],[1,1.94,130.35],[2,1.93,2.91]],"ltp":1.94,"tv":10579.58,"id":5300737},{"batb":[[0,2,16.62],[1,1.99,358.5],[2,1.96,38.29]],"ltp":2.02,"tv":18355.82,"id":2497008}]}]}
{"op":"mcm","clk":"4298867259","pt":1632579001601,"mc":[{"id":"1.188136695","rc":[{"trd":[[1.98,128.15],[2,4210.77]],"batl":[[0,2,266.63],[1,2.02,12.39],[2,2.04,371.14]],"ltp":2.0,"tv":10592.99,"id":5300737},{"trd":[[2,2610.22],[2.02,19.39]],"batb":[[0,1.99,358.5],[1,1.97,17.73]],"ltp":2.0,"tv":18402.44,"id":2497008}],"tv":28995.44}]}
{"op":"mcm","clk":"4298867643","pt":1632579002785,"mc":[{"id":"1.188136695","rc":[{"batl":[[0,2.2,647.8]],"ltp":2.0,"tv":18402.44,"id":2497008}]}]}
{"op":"mcm","clk":"4298873980","pt":1632579022617,"mc":[{"id":"1.188136695","rc":[{"batl":[[0,2.04,2.14],[1,2.3,6.64]],"ltp":2.0,"tv":18402.44,"id":2497008}]}]}
{"op":"mcm","clk":"4298876532","pt":1632579030643,"mc":[{"id":"1.188136695","rc":[{"trd":[[1.96,112.74]],"ltp":1.96,"tv":10593.29,"id":5300737},{"trd":[[2.04,31.8]],"batl":[[0,2.04,1.85]],"ltp":2.04,"tv":18402.73,"id":2497008}],"tv":28996.02}]}
{"op":"mcm","clk":"4298881383","pt":1632579045973,"mc":[{"id":"1.188136695","rc":[{"batl":[[0,2,406.63]],"ltp":1.96,"tv":10593.29,"id":5300737}]}]}
{"op":"mcm","clk":"4298882254","pt":1632579048668,"mc":[{"id":"1.188136695","rc":[{"trd":[[1.95,253.41],[1.96,114.67]],"batb":[[0,1.94,130.35],[1,1.93,2.91],[2,1.9,33.57]],"batl":[[0,1.95,7.08],[1,2,406.63],[2,2.02,12.39]],"ltp":1.95,"tv":10620.62,"id":5300737},{"trd":[[2.04,33.65]],"batl":[[0,2.3,6.64],[1,2.42,7.31],[2,2.62,2.65]],"ltp":2.04,"tv":18404.58,"id":2497008}],"tv":29025.21}]}
{"op":"mcm","clk":"4298882444","pt":1632579049331,"mc":[{"id":"1.188136695","rc":[{"trd":[[1.95,267.56]],"batb":[[0,1.95,15.12],[1,1.94,3055.66],[2,1.93,2.91]],"batl":[[0,2,406.63],[1,2.02,12.39],[2,2.04,371.14]],"ltp":1.95,"tv":10634.78,"id":5300737},{"batl":[[0,2.26,634.21],[1,2.3,5.85],[2,2.42,7.31]],"ltp":2.04,"tv":18404.58,"id":2497008}],"tv":29039.37}]}
{"op":"mcm","clk":"4298887358","pt":1632579064342,"mc":[{"id":"1.188136695","rc":[{"batb":[[1,1.94,130.35]],"ltp":1.95,"tv":10634.78,"id":5300737}]}]}
{"op":"mcm","clk":"4298894583","pt":1632579085726,"mc":[{"id":"1.188136695","rc":[{"trd":[[2,4215.77]],"batl":[[0,2,401.63]],"ltp":2.0,"tv":10639.78,"id":5300737},{"trd":[[2,2615.22]],"ltp":2.0,"tv":18409.58,"id":2497008}],"tv":29049.37}]}
{"op":"mcm","clk":"4298897698","pt":1632579095666,"mc":[{"id":"1.188136695","rc":[{"trd":[[1.95,310.8]],"batb":[[0,1.94,3014.7],[1,1.93,2.91],[2,1.9,33.57]],"batl":[[0,1.95,14.95],[1,2,401.63],[2,2.02,12.39]],"ltp":1.95,"tv":10683.02,"id":5300737}],"tv":29092.6}]}
{"op":"mcm","clk":"4298897900","pt":1632579096383,"mc":[{"id":"1.188136695","rc":[{"trd":[[1.95,329.42]],"batb":[[2,1.91,24.01]],"batl":[[0,1.95,5.64]],"ltp":1.95,"tv":10701.64,"id":5300737},{"batb":[[0,2.02,11.57],[1,1.99,358.5]],"ltp":2.0,"tv":18409.58,"id":2497008}],"tv":29111.22}]}
{"op":"mcm","clk":"4298901650","pt":1632579109494,"mc":[{"id":"1.188136695","rc":[{"batb":[[0,1.94,3014.96]],"ltp":1.95,"tv":10701.64,"id":5300737}]}]}
{"op":"mcm","clk":"4298901830","pt":1632579110082,"mc":[{"id":"1.188136695","rc":[{"batb":[[2,1.97,26.51]],"ltp":2.0,"tv":18409.58,"id":2497008}]}]}
{"op":"mcm","clk":"4298905483","pt":1632579121626,"mc":[{"id":"1.188136695","rc":[{"trd":[[1.95,333.94]],"batl":[[0,1.95,1.12]],"ltp":1.95,"tv":10706.16,"id":5300737},{"trd":[[2.04,37.97]],"ltp":2.04,"tv":18413.9,"id":2497008}],"tv":29120.06}]}
{"op":"mcm","clk":"4298906011","pt":1632579123147,"mc":[{"id":"1.188136695","rc":[{"batb":[[2,1.96,38.29]],"ltp":2.04,"tv":18413.9,"id":2497008}]}]}
{"op":"mcm","clk":"4298908541","pt":1632579131236,"mc":[{"id":"1.188136695","rc":[{"batb":[[0,1.94,3014.7]],"ltp":1.95,"tv":10706.16,"id":5300737}]}]}
{"op":"mcm","clk":"4298917162","pt":1632579156734,"mc":[{"id":"1.188136695","rc":[{"trd":[[1.95,335.06],[2,4617.4]],"batl":[[0,2.02,12.39],[1,2.04,371.14],[2,2.1,13.26]],"ltp":2.0,"tv":11108.91,"id":5300737},{"trd":[[2,3034.61],[2.02,42.53],[2.04,39.04]],"batb":[[0,1.99,358.5],[1,1.96,38.29],[2,1.95,27.07]],"batl":[[0,2,107.81],[1,2.26,634.21],[2,2.3,5.85]],"ltp":2.0,"tv":18857.5,"id":2497008}],"tv":29966.41}]}
{"op":"mcm","clk":"4298917392","pt":1632579157361,"mc":[{"id":"1.188136695","rc":[{"trd":[[2,4628.92]],"batl":[[0,2.02,25.8]],"ltp":2.0,"tv":11120.43,"id":5300737},{"trd":[[2,3151.12]],"batl":[[0,2,43.79],[1,2.3,6.64],[2,2.42,7.31]],"ltp":2.0,"tv":18974.01,"id":2497008}],"tv":30094.45}]}
{"op":"mcm","clk":"4298917603","pt":1632579158070,"mc":[{"id":"1.188136695","rc":[{"batb":[[0,1.95,22.07],[1,1.94,3042.05],[2,1.93,2.91]],"batl":[[0,2.02,12.39]],"ltp":2.0,"tv":11120.43,"id":5300737},{"batb":[[1,1.97,16.71],[2,1.96,11.5]],"ltp":2.0,"tv":18974.01,"id":2497008}]}]}
{"op":"mcm","clk":"4298919282","pt":1632579163046,"mc":[{"id":"1.188136695","rc":[{"trd":[[1.95,336.34]],"batb":[[0,1.95,20.79]],"ltp":1.95,"tv":11121.72,"id":5300737},{"trd":[[2,3238.7],[2.06,2.8]],"batl":[[0,2.22,703.63],[1,2.3,5.85]],"ltp":2.06,"tv":19064.39,"id":2497008}],"tv":30186.11}]}
{"op":"mcm","clk":"4298919627","pt":1632579164057,"mc":[{"id":"1.188136695","rc":[{"batb":[[1,1.94,3014.7]],"ltp":1.95,"tv":11121.72,"id":5300737}]}]}
{"op":"mcm","clk":"4298922524","pt":1632579173173,"mc":[{"id":"1.188136695","rc":[{"trd":[[1.94,190.26],[1.95,377.91]],"batb":[[0,1.94,2975.48],[1,1.93,2.91],[2,1.92,27.95]],"ltp":1.94,"tv":11241.72,"id":5300737}],"tv":30306.11}]}
{"op":"mcm","clk":"4298923032","pt":1632579174685,"mc":[{"id":"1.188136695","rc":[{"batb":[[0,1.94,3072.12],[2,1.91,28.26]],"ltp":1.94,"tv":11241.72,"id":5300737},{"batb":[[0,1.99,357.4],[1,1.96,11.5],[2,1.95,27.07]],"ltp":2.06,"tv":19064.39,"id":2497008}]}]}
{"op":"mcm","clk":"4298923365","pt":1632579175686,"mc":[{"id":"1.188136695","rc":[{"batb":[[2,1.92,20.01]],"batl":[[0,2.02,24.79]],"ltp":1.94,"tv":11241.72,"id":5300737},{"batb":[[0,2,19.53],[1,1.99,357.4],[2,1.96,11.5]],"batl":[[0,2.2,639.71]],"ltp":2.06,"tv":19064.39,"id":2497008}]}]}
{"op":"mcm","clk":"4298923492","pt":1632579176081,"mc":[{"id":"1.188136695","rc":[{"batb":[[2,1.96,38.29]],"ltp":2.06,"tv":19064.39,"id":2497008}]}]}
{"op":"mcm","clk":"4298926896","pt":1632579186641,"mc":[{"id":"1.188136695","rc":[{"trd":[[2,3278.03]],"batb":[[0,1.99,357.4],[1,1.97,18.33]],"ltp":2.0,"tv":19103.72,"id":2497008}],"tv":30345.44}]}
{"op":"mcm","clk":"4298927062","pt":1632579187102,"mc":[{"id":"1.188136695","rc":[{"batb":[[2,1.96,11.5]],"ltp":2.0,"tv":19103.72,"id":2497008}]}]}
{"op":"mcm","clk":"4298927634","pt":1632579188815,"mc":[{"id":"1.188136695","rc":[{"batb":[[0,1.97,20.07],[1,1.94,187.77],[2,1.93,2.91]],"ltp":1.94,"tv":11241.72,"id":5300737},{"batl":[[0,2.2,640.7]],"ltp":2.0,"tv":19103.72,"id":2497008}]}]}
{"op":"mcm","clk":"4298927881","pt":1632579189523,"mc":[{"id":"1.188136695","rc":[{"batl":[[0,2.02,12.39]],"ltp":1.94,"tv":11241.72,"id":5300737}]}]}
{"op":"mcm","clk":"4298932202","pt":1632579202400,"mc":[{"id":"1.188136695","rc":[{"batl":[[0,2.2,639.71]],"ltp":2.0,"tv":19103.72,"id":2497008}]}]}
{"op":"mcm","clk":"4298932431","pt":1632579203115,"mc":[{"id":"1.188136695","rc":[{"batb":[[2,1.93,30.56]],"ltp":1.94,"tv":11241.72,"id":5300737}]}]}
{"op":"mcm","clk":"4298936070","pt":1632579213937,"mc":[{"id":"1.188136695","rc":[{"trd":[[1.99,764.75]],"batb":[[0,1.99,354.47]],"ltp":1.99,"tv":19109.57,"id":2497008}],"tv":30351.29}]}
{"op":"mcm","clk":"4298938215","pt":1632579220360,"mc":[{"id":"1.188136695","rc":[{"trd":[[1.99,785.31]],"batb":[[0,1.99,344.19]],"ltp":1.99,"tv":19130.13,"id":2497008}],"tv":30371.85}]}
{"op":"mcm","clk":"4298939676","pt":1632579224952,"mc":[{"id":"1.188136695","rc":[{"batb":[[1,1.94,187.53]],"ltp":1.94,"tv":11241.72,"id":5300737},{"batb":[[0,2,66],[1,1.99,344.19],[2,1.97,18.33]],"ltp":1.99,"tv":19130.13,"id":2497008}]}]}
{"op":"mcm","clk":"4298940042","pt":1632579226144,"mc":[{"id":"1.188136695","rc":[{"batb":[[2,1.93,2.91]],"ltp":1.94,"tv":11241.72,"id":5300737}]}]}
{"op":"mcm","clk":"4298943736","pt":1632579237267,"mc":[{"id":"1.188136695","rc":[{"batb":[[0,1.97,18.1]],"ltp":1.94,"tv":11241.72,"id":5300737}]}]}
{"op":"mcm","clk":"4298947018","pt":1632579246586,"mc":[{"id":"1.188136695","rc":[{"batb":[[2,1.93,799.34]],"ltp":1.94,"tv":11241.72,"id":5300737}]}]}
{"op":"mcm","clk":"4298947653","pt":1632579248283,"mc":[{"id":"1.188136695","rc":[{"trd":[[2,3278.43]],"batb":[[0,2,65.8]],"ltp":2.0,"tv":19130.53,"id":2497008}],"tv":30372.25}]}
{"op":"mcm","clk":"4298957809","pt":1632579276603,"mc":[{"id":"1.188136695","rc":[{"batl":[[0,2.2,639.91]],"ltp":2.0,"tv":19130.53,"id":2497008}]}]}
{"op":"mcm","clk":"4298962887","pt":1632579289458,"mc":[{"id":"1.188136695","rc":[{"trd":[[2,3378.43]],"batb":[[0,2,15.8]],"ltp":2.0,"tv":19230.53,"id":2497008}],"tv":30472.25}]}
{"op":"mcm","clk":"4298963413","pt":1632579290829,"mc":[{"id":"1.188136695","rc":[{"batb":[[2,1.96,11.5]],"ltp":2.0,"tv":19230.53,"id":2497008}]}]}
{"op":"mcm","clk":"4298964105","pt":1632579292630,"mc":[{"id":"1.188136695","rc":[{"batl":[[1,2.04,374.29]],"ltp":1.94,"tv":11241.72,"id":5300737}]}]}
{"op":"mcm","clk":"4298968918","pt":1632579305362,"mc":[{"id":"1.188136695","rc":[{"trd":[[2,3385.29]],"batb":[[0,2,12.37]],"ltp":2.0,"tv":19237.39,"id":2497008}],"tv":30479.11}]}
{"op":"mcm","clk":"4298969218","pt":1632579306201,"mc":[{"id":"1.188136695","rc":[{"batb":[[2,1.93,826.99]],"ltp":1.94,"tv":11241.72,"id":5300737}]}]}
{"op":"mcm","clk":"4298971813","pt":1632579312660,"mc":[{"id":"1.188136695","rc":[{"trd":[[1.97,417.74]],"batb":[[0,1.94,3236.82],[1,1.93,826.99],[2,1.92,27.95]],"batl":[[0,1.97,80.75],[1,2.02,12.39],[2,2.04,374.29]],"ltp":1.97,"tv":11285.38,"id":5300737}],"tv":30522.77}]}
{"op":"mcm","clk":"4298972003","pt":1632579313138,"mc":[{"id":"1.188136695","rc":[{"batb":[[1,1.93,799.34],[2,1.9,5]],"ltp":1.97,"tv":11285.38,"id":5300737},{"batb":[[2,1.97,26.51]],"ltp":2.0,"tv":19237.39,"id":2497008}]}]}
{"op":"mcm","clk":"4298972650","pt":1632579314785,"mc":[{"id":"1.188136695","rc":[{"batb":[[0,1.95,183.98],[1,1.94,3236.82],[2,1.93,799.34]],"ltp":1.97,"tv":11285.38,"id":5300737},{"batb":[[0,2,194.74]],"ltp":2.0,"tv":19237.39,"id":2497008}]}]}
{"op":"mcm","clk":"4298972876","pt":1632579315347,"mc":[{"id":"1.188136695","rc":[{"trd":[[1.97,579.23],[2,4628.93]],"batb":[[1,1.94,187.53]],"batl":[[0,2.02,12.39],[1,2.04,374.29],[2,2.1,13.26]],"ltp":2.0,"tv":11446.88,"id":5300737},{"trd":[[2,3385.3]],"batb":[[0,2,194.74],[1,1.96,38.29],[2,1.95,27.07]],"ltp":2.0,"tv":19237.4,"id":2497008}],"tv":30684.28}]}
{"op":"mcm","clk":"4298973225","pt":1632579316283,"mc":[{"id":"1.188136695","rc":[{"batb":[[1,1.96,11.5]],"ltp":2.0,"tv":19237.4,"id":2497008}]}]}
{"op":"mcm","clk":"4298976515","pt":1632579325575,"mc":[{"id":"1.188136695","rc":[{"batb":[[0,1.96,181.7],[1,1.95,183.98],[2,1.94,187.53]],"ltp":2.0,"tv":11446.88,"id":5300737},{"batb":[[0,2,12.36],[1,1.99,184.66],[2,1.96,11.5]],"ltp":2.0,"tv":19237.4,"id":2497008}]}]}
{"op":"mcm","clk":"4298977096","pt":1632579327263,"mc":[{"id":"1.188136695","rc":[{"batl":[[1,2.04,1374.29]],"ltp":2.0,"tv":11446.88,"id":5300737}]}]}
{"op":"mcm","clk":"4298978222","pt":1632579330491,"mc":[{"id":"1.188136695","rc":[{"batl":[[0,2.02,69.58]],"ltp":2.0,"tv":11446.88,"id":5300737}]}]}
{"op":"mcm","clk":"4298979021","pt":1632579332682,"mc":[{"id":"1.188136695","rc":[{"batl":[[0,2.14,964.6],[1,2.3,6.05]],"ltp":2.0,"tv":19237.4,"id":2497008}]}]}
{"op":"mcm","clk":"4298979198","pt":1632579333202,"mc":[{"id":"1.188136695","rc":[{"batl":[[0,2.02,12.39]],"ltp":2.0,"tv":11446.88,"id":5300737},{"batl":[[0,2.12,617.89]],"ltp":2.0,"tv":19237.4,"id":2497008}]}]}
{"op":"mcm","clk":"4298981398","pt":1632579339279,"mc":[{"id":"1.188136695","rc":[{"trd":[[1.96,204.19]],"batb":[[0,1.96,136.94]],"ltp":1.96,"tv":11536.4,"id":5300737}],"tv":30773.8}]}
{"op":"mcm","clk":"4298981718","pt":1632579340199,"mc":[{"id":"1.188136695","rc":[{"batb":[[1,1.93,799.34],[2,1.92,27.95]],"ltp":1.96,"tv":11536.4,"id":5300737},{"batb":[[1,1.99,183.98]],"ltp":2.0,"tv":19237.4,"id":2497008}]}]}
{"op":"mcm","clk":"4298983267","pt":1632579344720,"mc":[{"id":"1.188136695","rc":[{"batl":[[0,2.3,6.05],[1,2.42,7.31],[2,2.62,2.65]],"ltp":2.0,"tv":19237.4,"id":2497008}]}]}
{"op":"mcm","clk":"4298983346","pt":1632579344910,"mc":[{"id":"1.188136695","rc":[{"batl":[[0,2.08,493.29],[1,2.3,6.05],[2,2.42,7.31]],"ltp":2.0,"tv":19237.4,"id":2497008}]}]}
{"op":"mcm","clk":"4298986169","pt":1632579353123,"mc":[{"id":"1.188136695","rc":[{"batl":[[0,1.98,20],[1,2.02,12.39],[2,2.04,1374.29]],"ltp":1.96,"tv":11536.4,"id":5300737}]}]}
{"op":"mcm","clk":"4298986507","pt":1632579354197,"mc":[{"id":"1.188136695","rc":[{"batb":[[2,1.9,33.57]],"ltp":1.96,"tv":11536.4,"id":5300737},{"batb":[[2,1.96,38.29]],"ltp":2.0,"tv":19237.4,"id":2497008}]}]}
{"op":"mcm","clk":"4298991747","pt":1632579369157,"mc":[{"id":"1.188136695","rc":[{"trd":[[1.96,205.72]],"batb":[[0,1.96,136.18]],"ltp":1.96,"tv":11537.93,"id":5300737}],"tv":30775.33}]}
{"op":"mcm","clk":"4298992107","pt":1632579370125,"mc":[{"id":"1.188136695","rc":[{"trd":[[1.98,168.14],[2,4628.94]],"batl":[[0,2.02,12.39],[1,2.04,1374.29],[2,2.1,13.26]],"ltp":2.0,"tv":11577.93,"id":5300737},{"trd":[[2,3385.31]],"batb":[[0,2,12.35]],"ltp":2.0,"tv":19237.41,"id":2497008}],"tv":30815.35}]}
{"op":"mcm","clk":"4298992517","pt":1632579371227,"mc":[{"id":"1.188136695","rc":[{"batl":[[0,2,70.45],[1,2.02,12.39],[2,2.04,1374.29]],"ltp":2.0,"tv":11577.93,"id":5300737},{"batb":[[2,1.96,11.5]],"ltp":2.0,"tv":19237.41,"id":2497008}]}]}
{"op":"mcm","clk":"4298992890","pt":1632579372245,"mc":[{"id":"1.188136695","rc":[{"batb":[[2,1.91,28.26]],"ltp":2.0,"tv":11577.93,"id":5300737}]}]}
{"op":"mcm","clk":"4298995774","pt":1632579380345,"mc":[{"id":"1.188136695","rc":[{"batb":[[1,1.99,183.48]],"ltp":2.0,"tv":19237.41,"id":2497008}]}]}
{"op":"mcm","clk":"4298996993","pt":1632579383615,"mc":[{"id":"1.188136695","rc":[{"trd":[[2,3388.74]],"batb":[[0,2,10.64]],"ltp":2.0,"tv":19240.83,"id":2497008}],"tv":30818.77}]}
{"op":"mcm","clk":"4299003340","pt":1632579400805,"mc":[{"id":"1.188136695","rc":[{"trd":[[1.96,482.07]],"batb":[[0,1.93,939.74],[1,1.91,28.26],[2,1.9,33.57]],"batl":[[0,1.96,137.02],[1,2,70.45],[2,2.02,12.39]],"ltp":1.96,"tv":11854.29,"id":5300737}],"tv":31095.13}]}
{"op":"mcm","clk":"4299003772","pt":1632579401786,"mc":[{"id":"1.188136695","rc":[{"batb":[[0,1.95,183.56],[1,1.93,939.74],[2,1.9,5]],"ltp":1.96,"tv":11854.29,"id":5300737},{"batb":[[0,2,193.44],[1,1.98,26.24]],"ltp":2.0,"tv":19240.83,"id":2497008}]}]}
{"op":"mcm","clk":"4299003968","pt":1632579402295,"mc":[{"id":"1.188136695","rc":[{"batb":[[1,1.96,11.5],[2,1.95,27.07]],"ltp":2.0,"tv":19240.83,"id":2497008}]}]}
{"op":"mcm","clk":"4299006085","pt":1632579408140,"mc":[{"id":"1.188136695","rc":[{"batb":[[1,1.93,799.34]],"ltp":1.96,"tv":11854.29,"id":5300737}]}]}
{"op":"mcm","clk":"4299009827","pt":1632579417234,"mc":[{"id":"1.188136695","rc":[{"trd":[[1.95,381.33]],"batb":[[0,1.95,180.15]],"ltp":1.95,"tv":11857.7,"id":5300737},{"trd":[[2.06,6.03]],"ltp":2.06,"tv":19244.07,"id":2497008}],"tv":31101.78}]}
{"op":"mcm","clk":"4299010373","pt":1632579418700,"mc":[{"id":"1.188136695","rc":[{"batl":[[2,2.04,1374.29]],"ltp":1.95,"tv":11857.7,"id":5300737},{"batb":[[1,1.97,26.51],[2,1.96,11.5]],"ltp":2.06,"tv":19244.07,"id":2497008}]}]}
