{"op":"mcm","clk":"4220448760","pt":1631418621951,"mc":[{"id":"1.187528277","rc":[{"trd":[[1.41,78135.2]],"batl":[[0,1.41,451.56]],"ltp":1.41,"tv":144035.36,"id":2249229}],"tv":179154.19}]}
{"op":"mcm","clk":"4220449084","pt":1631418628663,"mc":[{"id":"1.187528277","rc":[{"trd":[[1.41,78279.8]],"batl":[[0,1.41,379.26]],"ltp":1.41,"tv":144179.96,"id":2249229}],"tv":179298.79}]}
{"op":"mcm","clk":"4220452155","pt":1631418717462,"mc":[{"id":"1.187528277","rc":[{"trd":[[3.4,15145.35]],"batb":[[0,3.4,2180.98]],"ltp":3.4,"tv":35191.12,"id":19924831}],"tv":179371.09}]}
{"op":"mcm","clk":"4220453578","pt":1631418758624,"mc":[{"id":"1.187528277","rc":[{"trd":[[1.41,78453.32]],"batl":[[0,1.41,292.5]],"ltp":1.41,"tv":144353.49,"id":2249229}],"tv":179544.61}]}
{"op":"mcm","clk":"4220460145","pt":1631418952021,"mc":[{"id":"1.187528277","rc":[{"trd":[[1.41,79038.33]],"batb":[[0,1.41,792.02],[1,1.4,13864.07],[2,1.39,10544.85]],"batl":[[0,1.42,15861.51],[1,1.43,1405.37],[2,1.44,6180.26]],"ltp":1.41,"tv":144938.49,"id":2249229}],"tv":180129.61}]}
{"op":"mcm","clk":"4220460822","pt":1631418973665,"mc":[{"id":"1.187528277","rc":[{"batb":[[2,1.39,10092.82]],"ltp":1.41,"tv":144938.49,"id":2249229}]}]}
{"op":"mcm","clk":"4220460864","pt":1631418974950,"mc":[{"id":"1.187528277","rc":[{"batb":[[1,1.4,13638.93]],"ltp":1.41,"tv":144938.49,"id":2249229}]}]}
{"op":"mcm","clk":"4220460926","pt":1631418976547,"mc":[{"id":"1.187528277","rc":[{"batl":[[0,3.45,407.02]],"ltp":3.4,"tv":35191.12,"id":19924831},{"batb":[[0,1.41,855.55]],"batl":[[1,1.43,1857.4]],"ltp":1.41,"tv":144938.49,"id":2249229}]}]}
{"op":"mcm","clk":"4220463223","pt":1631419051089,"mc":[{"id":"1.187528277","rc":[{"batl":[[0,3.45,417.92]],"ltp":3.4,"tv":35191.12,"id":19924831}]}]}
{"op":"mcm","clk":"4220471736","pt":1631419241915,"mc":[{"id":"1.187528277","rc":[{"trd":[[1.41,80749.43]],"batb":[[0,1.4,13638.93],[1,1.39,10092.82],[2,1.38,15893.65]],"ltp":1.41,"tv":146649.59,"id":2249229}],"tv":181840.71}]}
{"op":"mcm","clk":"4220472136","pt":1631419254341,"mc":[{"id":"1.187528277","rc":[{"trd":[[1.42,41464.89]],"batl":[[0,1.42,9978.91]],"ltp":1.42,"tv":158414.54,"id":2249229}],"tv":193605.66}]}
{"op":"mcm","clk":"4220472680","pt":1631419267669,"mc":[{"id":"1.187528277","rc":[{"batb":[[0,1.4,16191.58]],"ltp":1.42,"tv":158414.54,"id":2249229}]}]}
{"op":"mcm","clk":"4220473589","pt":1631419288682,"mc":[{"id":"1.187528277","rc":[{"batb":[[1,1.39,10544.85]],"ltp":1.42,"tv":158414.54,"id":2249229}]}]}
{"op":"mcm","clk":"4220473632","pt":1631419289706,"mc":[{"id":"1.187528277","rc":[{"batb":[[1,3.35,2345.53]],"ltp":3.4,"tv":35191.12,"id":19924831},{"batb":[[0,1.4,16388.75]],"batl":[[0,1.42,9987.99]],"ltp":1.42,"tv":158414.54,"id":2249229}]}]}
{"op":"mcm","clk":"4220473654","pt":1631419290379,"mc":[{"id":"1.187528277","rc":[{"batb":[[0,3.4,2192.3]],"batl":[[0,3.45,407.02]],"ltp":3.4,"tv":35191.12,"id":19924831}]}]}
{"op":"mcm","clk":"4220473676","pt":1631419290893,"mc":[{"id":"1.187528277","rc":[{"batl":[[0,3.45,367.1]],"ltp":3.4,"tv":35191.12,"id":19924831}]}]}
{"op":"mcm","clk":"4220473730","pt":1631419291820,"mc":[{"id":"1.187528277","rc":[{"batl":[[1,3.5,355.37]],"ltp":3.4,"tv":35191.12,"id":19924831}]}]}
{"op":"mcm","clk":"4220473877","pt":1631419295491,"mc":[{"id":"1.187528277","rc":[{"trd":[[3.45,2230.45]],"batb":[[0,3.4,2245.24]],"batl":[[0,3.5,355.37],[1,3.6,2],[2,5.2,5.32]],"ltp":3.45,"tv":35925.31,"id":19924831}],"tv":194339.85}]}
{"op":"mcm","clk":"4220476892","pt":1631419365689,"mc":[{"id":"1.187528277","rc":[{"batb":[[1,3.35,2378.12]],"ltp":3.45,"tv":35925.31,"id":19924831},{"batb":[[0,1.4,16309.9]],"ltp":1.42,"tv":158414.54,"id":2249229}]}]}
{"op":"mcm","clk":"4220476917","pt":1631419366513,"mc":[{"id":"1.187528277","rc":[{"batb":[[0,3.4,2277.16]],"batl":[[0,3.5,324.74]],"ltp":3.45,"tv":35925.31,"id":19924831}]}]}
{"op":"mcm","clk":"4220479203","pt":1631419424985,"mc":[{"id":"1.187528277","rc":[{"batb":[[0,1.4,16948.07]],"ltp":1.42,"tv":158414.54,"id":2249229}]}]}
{"op":"mcm","clk":"4220479244","pt":1631419426065,"mc":[{"id":"1.187528277","rc":[{"batb":[[0,1.4,17586.23]],"ltp":1.42,"tv":158414.54,"id":2249229}]}]}
{"op":"mcm","clk":"4220479352","pt":1631419429563,"mc":[{"id":"1.187528277","rc":[{"batb":[[0,1.4,18224.39]],"ltp":1.42,"tv":158414.54,"id":2249229}]}]}
{"op":"mcm","clk":"4220499657","pt":1631419976694,"mc":[{"id":"1.187528277","rc":[{"batb":[[0,3.4,2477.16]],"ltp":3.45,"tv":35925.31,"id":19924831}]}]}
{"op":"mcm","clk":"4220502018","pt":1631420033757,"mc":[{"id":"1.187528277","rc":[{"trd":[[1.42,43240.93]],"batl":[[0,1.42,9099.95]],"ltp":1.42,"tv":160190.58,"id":2249229}],"tv":196115.89}]}
{"op":"mcm","clk":"4220503877","pt":1631420076415,"mc":[{"id":"1.187528277","rc":[{"batb":[[0,1.4,18862.55]],"ltp":1.42,"tv":160190.58,"id":2249229}]}]}
{"op":"mcm","clk":"4220504073","pt":1631420081424,"mc":[{"id":"1.187528277","rc":[{"batb":[[0,1.4,19500.72]],"ltp":1.42,"tv":160190.58,"id":2249229}]}]}
{"op":"mcm","clk":"4220504573","pt":1631420094351,"mc":[{"id":"1.187528277","rc":[{"trd":[[3.5,420.4]],"batl":[[0,3.5,312.4]],"ltp":3.5,"tv":35949.97,"id":19924831}],"tv":196140.56}]}
{"op":"mcm","clk":"4220506091","pt":1631420125291,"mc":[{"id":"1.187528277","rc":[{"batb":[[1,3.35,2413.99],[2,3.3,84.48]],"batl":[[0,3.5,324.36]],"ltp":3.5,"tv":35949.97,"id":19924831},{"batb":[[0,1.4,19492.17]],"batl":[[1,1.43,1862.53]],"ltp":1.42,"tv":160190.58,"id":2249229}]}]}
{"op":"mcm","clk":"4220508265","pt":1631420173344,"mc":[{"id":"1.187528277","rc":[{"batl":[[0,1.42,10699.95]],"ltp":1.42,"tv":160190.58,"id":2249229}]}]}
{"op":"mcm","clk":"4220508634","pt":1631420182297,"mc":[{"id":"1.187528277","rc":[{"batb":[[0,3.45,675.39],[1,3.4,2477.16],[2,3.35,2413.99]],"ltp":3.5,"tv":35949.97,"id":19924831}]}]}
{"op":"mcm","clk":"4220508910","pt":1631420188567,"mc":[{"id":"1.187528277","rc":[{"batb":[[0,3.4,2477.16],[1,3.35,2413.99],[2,3.3,84.48]],"ltp":3.5,"tv":35949.97,"id":19924831}]}]}
{"op":"mcm","clk":"4220509348","pt":1631420197882,"mc":[{"id":"1.187528277","rc":[{"batl":[[0,1.42,9099.95],[1,1.43,3462.53]],"ltp":1.42,"tv":160190.58,"id":2249229}]}]}
{"op":"mcm","clk":"4220513846","pt":1631420305824,"mc":[{"id":"1.187528277","rc":[{"batl":[[1,3.6,454.03]],"ltp":3.5,"tv":35949.97,"id":19924831}]}]}
{"op":"mcm","clk":"4220521212","pt":1631420497742,"mc":[{"id":"1.187528277","rc":[{"batl":[[0,1.41,1200],[1,1.42,9099.95],[2,1.43,3462.53]],"ltp":1.42,"tv":160190.58,"id":2249229}]}]}
{"op":"mcm","clk":"4220521923","pt":1631420515446,"mc":[{"id":"1.187528277","rc":[{"batl":[[2,1.43,3010.49]],"ltp":1.42,"tv":160190.58,"id":2249229}]}]}
{"op":"mcm","clk":"4220521937","pt":1631420515958,"mc":[{"id":"1.187528277","rc":[{"batl":[[0,1.41,1286.62]],"ltp":1.42,"tv":160190.58,"id":2249229}]}]}
{"op":"mcm","clk":"4220531812","pt":1631420742650,"mc":[{"id":"1.187528277","rc":[{"batl":[[0,1.41,1315.41]],"ltp":1.42,"tv":160190.58,"id":2249229}]}]}
{"op":"mcm","clk":"4220532390","pt":1631420755280,"mc":[{"id":"1.187528277","rc":[{"batl":[[0,3.5,314.96]],"ltp":3.5,"tv":35949.97,"id":19924831},{"batb":[[0,1.4,19414.46],[1,1.39,10665.27]],"ltp":1.42,"tv":160190.58,"id":2249229}]}]}
{"op":"mcm","clk":"4220537516","pt":1631420879675,"mc":[{"id":"1.187528277","rc":[{"batb":[[1,1.39,10638.68]],"ltp":1.42,"tv":160190.58,"id":2249229}]}]}
{"op":"mcm","clk":"4220537547","pt":1631420880355,"mc":[{"id":"1.187528277","rc":[{"batb":[[0,1.4,19296.13]],"ltp":1.42,"tv":160190.58,"id":2249229}]}]}
{"op":"mcm","clk":"4220537592","pt":1631420881655,"mc":[{"id":"1.187528277","rc":[{"batb":[[0,1.4,19246.37]],"batl":[[0,1.41,1418.15]],"ltp":1.42,"tv":160190.58,"id":2249229}]}]}
{"op":"mcm","clk":"4220537611","pt":1631420882171,"mc":[{"id":"1.187528277","rc":[{"batl":[[1,1.42,9090.86]],"ltp":1.42,"tv":160190.58,"id":2249229}]}]}
{"op":"mcm","clk":"4220537653","pt":1631420883461,"mc":[{"id":"1.187528277","rc":[{"batb":[[1,3.35,2427.33]],"ltp":3.5,"tv":35949.97,"id":19924831},{"batl":[[1,1.42,9073.36]],"ltp":1.42,"tv":160190.58,"id":2249229}]}]}
{"op":"mcm","clk":"4220537681","pt":1631420884592,"mc":[{"id":"1.187528277","rc":[{"batb":[[0,3.4,2509.57]],"batl":[[0,3.5,243]],"ltp":3.5,"tv":35949.97,"id":19924831}]}]}
{"op":"mcm","clk":"4220537697","pt":1631420885266,"mc":[{"id":"1.187528277","rc":[{"batl":[[1,3.6,427.44]],"ltp":3.5,"tv":35949.97,"id":19924831}]}]}
{"op":"mcm","clk":"4220546766","pt":1631421114381,"mc":[{"id":"1.187528277","rc":[{"batb":[[2,1.38,15848.89]],"ltp":1.42,"tv":160190.58,"id":2249229}]}]}
{"op":"mcm","clk":"4220557257","pt":1631421286656,"mc":[{"id":"1.187528277","rc":[{"trd":[[1.4,9184.77]],"batb":[[0,1.4,19227.37]],"ltp":1.4,"tv":160228.58,"id":2249229}],"tv":196178.56}]}
{"op":"mcm","clk":"4220557281","pt":1631421286966,"mc":[{"id":"1.187528277","rc":[{"batb":[[1,3.35,2430.33],[2,3.3,86.48]],"ltp":3.5,"tv":35949.97,"id":19924831}]}]}
{"op":"mcm","clk":"4220559555","pt":1631421382186,"mc":[{"id":"1.187528277","rc":[{"batb":[[2,3.3,84.48]],"ltp":3.5,"tv":35949.97,"id":19924831},{"trd":[[1.41,80999.43]],"batl":[[0,1.41,1293.15]],"ltp":1.41,"tv":160478.58,"id":2249229}],"tv":196428.56}]}
{"op":"mcm","clk":"4220559861","pt":1631421394706,"mc":[{"id":"1.187528277","rc":[{"trd":[[3.5,451.27]],"batl":[[0,3.5,227.56]],"ltp":3.5,"tv":35980.84,"id":19924831}],"tv":196459.43}]}
{"op":"mcm","clk":"4220561921","pt":1631421467890,"mc":[{"id":"1.187528277","rc":[{"batl":[[0,1.41,1297.77]],"ltp":1.41,"tv":160478.58,"id":2249229}]}]}
{"op":"mcm","clk":"4220562101","pt":1631421473393,"mc":[{"id":"1.187528277","rc":[{"trd":[[3.5,483.67]],"batl":[[0,3.5,211.36]],"ltp":3.5,"tv":36013.25,"id":19924831}],"tv":196491.84}]}
{"op":"mcm","clk":"4220562793","pt":1631421495631,"mc":[{"id":"1.187528277","rc":[{"batl":[[0,3.5,199.4]],"ltp":3.5,"tv":36013.25,"id":19924831}]}]}
{"op":"mcm","clk":"4220562799","pt":1631421495837,"mc":[{"id":"1.187528277","rc":[{"batb":[[1,3.35,2438.01]],"batl":[[1,3.55,41.85],[2,3.6,427.44]],"ltp":3.5,"tv":36013.25,"id":19924831},{"batl":[[2,1.43,3065.15]],"ltp":1.41,"tv":160478.58,"id":2249229}]}]}
{"op":"mcm","clk":"4220564421","pt":1631421551322,"mc":[{"id":"1.187528277","rc":[{"batl":[[2,3.6,2]],"ltp":3.5,"tv":36013.25,"id":19924831}]}]}
{"op":"mcm","clk":"4220564466","pt":1631421552720,"mc":[{"id":"1.187528277","rc":[{"batb":[[0,3.4,2519.94],[1,3.35,2448.6]],"ltp":3.5,"tv":36013.25,"id":19924831},{"batb":[[0,1.4,19201.77]],"ltp":1.41,"tv":160478.58,"id":2249229}]}]}
{"op":"mcm","clk":"4220564492","pt":1631421553440,"mc":[{"id":"1.187528277","rc":[{"batl":[[0,3.5,209.52],[1,3.55,48.12]],"ltp":3.5,"tv":36013.25,"id":19924831}]}]}
{"op":"mcm","clk":"4220565592","pt":1631421594577,"mc":[{"id":"1.187528277","rc":[{"trd":[[1.41,81005.06]],"batl":[[0,1.41,1294.95]],"ltp":1.41,"tv":160484.22,"id":2249229}],"tv":196497.48}]}
{"op":"mcm","clk":"4220569304","pt":1631421782555,"mc":[{"id":"1.187528277","rc":[{"batl":[[0,1.41,1319.95]],"ltp":1.41,"tv":160484.22,"id":2249229}]}]}
{"op":"mcm","clk":"4220570323","pt":1631421845121,"mc":[{"id":"1.187528277","rc":[{"batl":[[0,1.41,1323.96]],"ltp":1.41,"tv":160484.22,"id":2249229}]}]}
{"op":"mcm","clk":"4220585186","pt":1631422160980,"mc":[{"id":"1.187528277","rc":[{"batl":[[0,1.41,2923.96],[2,1.43,1465.15]],"ltp":1.41,"tv":160484.22,"id":2249229}]}]}
{"op":"mcm","clk":"4220588013","pt":1631422209357,"mc":[{"id":"1.187528277","rc":[{"batl":[[0,1.41,1323.96],[1,1.42,10673.36]],"ltp":1.41,"tv":160484.22,"id":2249229}]}]}
{"op":"mcm","clk":"4220604774","pt":1631422597516,"mc":[{"id":"1.187528277","rc":[{"batl":[[0,1.41,2923.96],[1,1.42,9073.36]],"ltp":1.41,"tv":160484.22,"id":2249229}]}]}
{"op":"mcm","clk":"4220607760","pt":1631422675268,"mc":[{"id":"1.187528277","rc":[{"batl":[[0,1.41,2940.31]],"ltp":1.41,"tv":160484.22,"id":2249229}]}]}
{"op":"mcm","clk":"4220613938","pt":1631422829655,"mc":[{"id":"1.187528277","rc":[{"trd":[[3.4,15154.14]],"batb":[[0,3.4,2515.54]],"ltp":3.4,"tv":36022.04,"id":19924831}],"tv":196506.27}]}
{"op":"mcm","clk":"4220613940","pt":1631422829751,"mc":[{"id":"1.187528277","rc":[{"batl":[[0,3.5,260.94]],"ltp":3.4,"tv":36022.04,"id":19924831}]}]}
{"op":"mcm","clk":"4220617102","pt":1631422884424,"mc":[{"id":"1.187528277","rc":[{"batl":[[1,3.55,42.15]],"ltp":3.4,"tv":36022.04,"id":19924831},{"batl":[[1,1.42,9151.93],[2,1.43,1326.8]],"ltp":1.41,"tv":160484.22,"id":2249229}]}]}
{"op":"mcm","clk":"4220618786","pt":1631422913673,"mc":[{"id":"1.187528277","rc":[{"batl":[[1,1.42,9073.36]],"ltp":1.41,"tv":160484.22,"id":2249229}]}]}
{"op":"mcm","clk":"4220618831","pt":1631422914708,"mc":[{"id":"1.187528277","rc":[{"batl":[[2,1.43,1458.32]],"ltp":1.41,"tv":160484.22,"id":2249229}]}]}
{"op":"mcm","clk":"4220618978","pt":1631422916677,"mc":[{"id":"1.187528277","rc":[{"batl":[[1,3.55,6.28]],"ltp":3.4,"tv":36022.04,"id":19924831}]}]}
{"op":"mcm","clk":"4220619016","pt":1631422917195,"mc":[{"id":"1.187528277","rc":[{"batb":[[1,3.35,2440.06]],"batl":[[0,3.5,286.56]],"ltp":3.4,"tv":36022.04,"id":19924831}]}]}
{"op":"mcm","clk":"4220619396","pt":1631422924311,"mc":[{"id":"1.187528277","rc":[{"batb":[[1,3.35,2446.03]],"batl":[[0,3.5,260.94],[1,3.55,48.12]],"ltp":3.4,"tv":36022.04,"id":19924831}]}]}
{"op":"mcm","clk":"4220620901","pt":1631422949838,"mc":[{"id":"1.187528277","rc":[{"trd":[[3.4,15454.15]],"batb":[[0,3.4,2365.54]],"ltp":3.4,"tv":36322.05,"id":19924831}],"tv":196806.27}]}
{"op":"mcm","clk":"4220637079","pt":1631423235208,"mc":[{"id":"1.187528277","rc":[{"batb":[[0,1.4,18563.61]],"ltp":1.41,"tv":160484.22,"id":2249229}]}]}
{"op":"mcm","clk":"4220649343","pt":1631423476854,"mc":[{"id":"1.187528277","rc":[{"trd":[[1.4,9314.12]],"batb":[[0,1.4,18498.93]],"ltp":1.4,"tv":160613.58,"id":2249229}],"tv":196935.63}]}
{"op":"mcm","clk":"4220679346","pt":1631423905624,"mc":[{"id":"1.187528277","rc":[{"batb":[[1,1.39,10655.35]],"ltp":1.4,"tv":160613.58,"id":2249229}]}]}
{"op":"mcm","clk":"4220690568","pt":1631424162396,"mc":[{"id":"1.187528277","rc":[{"batl":[[2,1.43,1471.04]],"ltp":1.4,"tv":160613.58,"id":2249229}]}]}
{"op":"mcm","clk":"4220693592","pt":1631424231739,"mc":[{"id":"1.187528277","rc":[{"trd":[[1.4,10377.69]],"batb":[[0,1.4,17967.16]],"ltp":1.4,"tv":161677.15,"id":2249229}],"tv":197999.2}]}
{"op":"mcm","clk":"4220695170","pt":1631424264474,"mc":[{"id":"1.187528277","rc":[{"trd":[[1.41,81031.65]],"batl":[[0,1.41,2927.02]],"ltp":1.41,"tv":161703.74,"id":2249229}],"tv":198025.79}]}
{"op":"mcm","clk":"4220699345","pt":1631424358331,"mc":[{"id":"1.187528277","rc":[{"batl":[[0,3.5,550.14]],"ltp":3.4,"tv":36322.05,"id":19924831}]}]}
{"op":"mcm","clk":"4220705112","pt":1631424495662,"mc":[{"id":"1.187528277","rc":[{"trd":[[1.4,10389.7]],"batb":[[0,1.4,17961.16]],"ltp":1.4,"tv":161715.74,"id":2249229}],"tv":198037.79}]}
{"op":"mcm","clk":"4220706139","pt":1631424521231,"mc":[{"id":"1.187528277","rc":[{"batb":[[1,3.35,2438.35]],"batl":[[0,3.5,577.47],[1,3.55,6.28]],"ltp":3.4,"tv":36322.05,"id":19924831}]}]}
{"op":"mcm","clk":"4220708277","pt":1631424579019,"mc":[{"id":"1.187528277","rc":[{"batl":[[1,3.6,2],[2,5.2,5.32]],"ltp":3.4,"tv":36322.05,"id":19924831}]}]}
{"op":"mcm","clk":"4220711646","pt":1631424645107,"mc":[{"id":"1.187528277","rc":[{"batl":[[1,3.6,427.44]],"ltp":3.4,"tv":36322.05,"id":19924831}]}]}
{"op":"mcm","clk":"4220718661","pt":1631424798996,"mc":[{"id":"1.187528277","rc":[{"batb":[[0,1.4,18156.41]],"ltp":1.4,"tv":161715.74,"id":2249229}]}]}
{"op":"mcm","clk":"4220719279","pt":1631424812659,"mc":[{"id":"1.187528277","rc":[{"batl":[[0,3.5,665.42]],"ltp":3.4,"tv":36322.05,"id":19924831}]}]}
{"op":"mcm","clk":"4220720764","pt":1631424843950,"mc":[{"id":"1.187528277","rc":[{"batb":[[0,1.4,13051.11],[1,1.39,15760.65]],"ltp":1.4,"tv":161715.74,"id":2249229}]}]}
{"op":"mcm","clk":"4220722039","pt":1631424870178,"mc":[{"id":"1.187528277","rc":[{"batl":[[1,1.42,11626]],"ltp":1.4,"tv":161715.74,"id":2249229}]}]}
{"op":"mcm","clk":"4220723986","pt":1631424913867,"mc":[{"id":"1.187528277","rc":[{"trd":[[3.5,606.88]],"batl":[[0,3.5,603.82]],"ltp":3.5,"tv":36445.25,"id":19924831}],"tv":198161.0}]}
{"op":"mcm","clk":"4220724649","pt":1631424932352,"mc":[{"id":"1.187528277","rc":[{"batb":[[1,1.39,10655.35],[2,1.38,20954.18]],"ltp":1.4,"tv":161715.74,"id":2249229}]}]}
{"op":"mcm","clk":"4220725743","pt":1631424959522,"mc":[{"id":"1.187528277","rc":[{"batl":[[1,1.42,14178.65]],"ltp":1.4,"tv":161715.74,"id":2249229}]}]}
{"op":"mcm","clk":"4220726486","pt":1631424977444,"mc":[{"id":"1.187528277","rc":[{"batb":[[0,1.4,12972.5]],"ltp":1.4,"tv":161715.74,"id":2249229}]}]}
{"op":"mcm","clk":"4220726519","pt":1631424978520,"mc":[{"id":"1.187528277","rc":[{"batb":[[1,3.35,2470.84]],"ltp":3.5,"tv":36445.25,"id":19924831},{"batl":[[0,1.41,3003.71]],"ltp":1.4,"tv":161715.74,"id":2249229}]}]}
{"op":"mcm","clk":"4220726555","pt":1631424979242,"mc":[{"id":"1.187528277","rc":[{"batb":[[0,3.4,2397.35]],"batl":[[0,3.5,634.88]],"ltp":3.5,"tv":36445.25,"id":19924831}]}]}
{"op":"mcm","clk":"4220753592","pt":1631425653992,"mc":[{"id":"1.187528277","rc":[{"batl":[[2,1.43,1599.15]],"ltp":1.4,"tv":161715.74,"id":2249229}]}]}
{"op":"mcm","clk":"4220754119","pt":1631425672333,"mc":[{"id":"1.187528277","rc":[{"trd":[[3.5,645.02]],"batl":[[0,3.5,615.81]],"ltp":3.5,"tv":36483.39,"id":19924831}],"tv":198199.14}]}
{"op":"mcm","clk":"4220757843","pt":1631425797712,"mc":[{"id":"1.187528277","rc":[{"batb":[[1,3.35,2480.9]],"ltp":3.5,"tv":36483.39,"id":19924831},{"batb":[[0,1.4,12948.17]],"batl":[[0,1.41,3027.45]],"ltp":1.4,"tv":161715.74,"id":2249229}]}]}
{"op":"mcm","clk":"4220757863","pt":1631425798389,"mc":[{"id":"1.187528277","rc":[{"batb":[[0,3.4,2407.2]],"batl":[[0,3.5,625.42]],"ltp":3.5,"tv":36483.39,"id":19924831}]}]}
{"op":"mcm","clk":"4220762805","pt":1631425957616,"mc":[{"id":"1.187528277","rc":[{"batl":[[0,3.45,15],[1,3.5,625.42],[2,3.6,427.44]],"ltp":3.5,"tv":36483.39,"id":19924831}]}]}
{"op":"mcm","clk":"4220763822","pt":1631425986634,"mc":[{"id":"1.187528277","rc":[{"batl":[[2,3.6,2]],"ltp":3.5,"tv":36483.39,"id":19924831}]}]}
{"op":"mcm","clk":"4220764900","pt":1631426023544,"mc":[{"id":"1.187528277","rc":[{"trd":[[1.41,81035.65]],"batl":[[0,1.41,3025.45]],"ltp":1.41,"tv":161719.74,"id":2249229}],"tv":198203.14}]}
{"op":"mcm","clk":"4220768781","pt":1631426150351,"mc":[{"id":"1.187528277","rc":[{"trd":[[3.4,15613.68]],"batb":[[0,3.4,2327.44]],"ltp":3.4,"tv":36642.92,"id":19924831}],"tv":198362.67}]}
{"op":"mcm","clk":"4220773526","pt":1631426289116,"mc":[{"id":"1.187528277","rc":[{"trd":[[1.4,10619.39]],"batb":[[0,1.4,12833.33]],"ltp":1.4,"tv":161949.43,"id":2249229}],"tv":198592.36}]}
{"op":"mcm","clk":"4220779439","pt":1631426442698,"mc":[{"id":"1.187528277","rc":[{"batb":[[1,3.35,2447.59]],"ltp":3.4,"tv":36642.92,"id":19924831},{"batb":[[1,1.39,10534.93]],"ltp":1.4,"tv":161949.43,"id":2249229}]}]}
{"op":"mcm","clk":"4220779463","pt":1631426443313,"mc":[{"id":"1.187528277","rc":[{"batb":[[2,3.3,125.48]],"batl":[[1,3.5,633.11]],"ltp":3.4,"tv":36642.92,"id":19924831},{"batb":[[0,1.4,12917.02]],"batl":[[2,1.43,1552.17]],"ltp":1.4,"tv":161949.43,"id":2249229}]}]}
{"op":"mcm","clk":"4220779548","pt":1631426445518,"mc":[{"id":"1.187528277","rc":[{"batl":[[1,3.5,641.65]],"ltp":3.4,"tv":36642.92,"id":19924831},{"batb":[[0,1.4,12970.83]],"batl":[[2,1.43,1467.62]],"ltp":1.4,"tv":161949.43,"id":2249229}]}]}
{"op":"mcm","clk":"4220792068","pt":1631426701521,"mc":[{"id":"1.187528277","rc":[{"batb":[[1,3.35,2444.59]],"ltp":3.4,"tv":36642.92,"id":19924831}]}]}
{"op":"mcm","clk":"4220792594","pt":1631426709721,"mc":[{"id":"1.187528277","rc":[{"trd":[[3.4,15624.31]],"batb":[[0,3.4,2322.13]],"ltp":3.4,"tv":36653.56,"id":19924831}],"tv":198602.99}]}
{"op":"mcm","clk":"4220794139","pt":1631426737707,"mc":[{"id":"1.187528277","rc":[{"batl":[[1,3.5,598.09]],"ltp":3.4,"tv":36653.56,"id":19924831}]}]}
{"op":"mcm","clk":"4220794173","pt":1631426738215,"mc":[{"id":"1.187528277","rc":[{"batb":[[2,3.3,117.79]],"batl":[[0,3.45,38.91]],"ltp":3.4,"tv":36653.56,"id":19924831}]}]}
{"op":"mcm","clk":"4220797420","pt":1631426789020,"mc":[{"id":"1.187528277","rc":[{"trd":[[1.4,10624.07]],"batb":[[0,1.4,12968.49]],"ltp":1.4,"tv":161954.11,"id":2249229}],"tv":198607.67}]}
{"op":"mcm","clk":"4220802817","pt":1631426883687,"mc":[{"id":"1.187528277","rc":[{"trd":[[1.41,87086.53]],"batb":[[0,1.41,26974.57],[1,1.4,12968.49],[2,1.39,10534.93]],"batl":[[0,1.42,14178.65],[1,1.43,1467.62],[2,1.44,7064.68]],"ltp":1.41,"tv":168004.99,"id":2249229}],"tv":204658.55}]}
{"op":"mcm","clk":"4220802835","pt":1631426883845,"mc":[{"id":"1.187528277","rc":[{"batb":[[0,3.4,2269.19]],"batl":[[0,3.45,91.08]],"ltp":3.4,"tv":36653.56,"id":19924831}]}]}
{"op":"mcm","clk":"4220803634","pt":1631426895769,"mc":[{"id":"1.187528277","rc":[{"batl":[[1,3.5,510.14]],"ltp":3.4,"tv":36653.56,"id":19924831}]}]}
{"op":"mcm","clk":"4220803867","pt":1631426899190,"mc":[{"id":"1.187528277","rc":[{"batb":[[1,1.4,12773.24]],"ltp":1.41,"tv":168004.99,"id":2249229}]}]}
{"op":"mcm","clk":"4220804244","pt":1631426904681,"mc":[{"id":"1.187528277","rc":[{"batl":[[0,3.45,380.29]],"ltp":3.4,"tv":36653.56,"id":19924831}]}]}
{"op":"mcm","clk":"4220804368","pt":1631426906697,"mc":[{"id":"1.187528277","rc":[{"batl":[[0,3.45,556.19]],"ltp":3.4,"tv":36653.56,"id":19924831}]}]}
{"op":"mcm","clk":"4220805520","pt":1631426925655,"mc":[{"id":"1.187528277","rc":[{"batb":[[2,1.39,10109.49]],"ltp":1.41,"tv":168004.99,"id":2249229}]}]}
{"op":"mcm","clk":"4220805568","pt":1631426926632,"mc":[{"id":"1.187528277","rc":[{"batb":[[1,1.4,12924.95]],"batl":[[1,1.43,1893.06]],"ltp":1.41,"tv":168004.99,"id":2249229}]}]}
{"op":"mcm","clk":"4220805579","pt":1631426927052,"mc":[{"id":"1.187528277","rc":[{"batb":[[1,3.35,2434.53]],"ltp":3.4,"tv":36653.56,"id":19924831}]}]}
{"op":"mcm","clk":"4220805654","pt":1631426928455,"mc":[{"id":"1.187528277","rc":[{"batb":[[1,3.35,2391.46]],"ltp":3.4,"tv":36653.56,"id":19924831}]}]}
{"op":"mcm","clk":"4220805736","pt":1631426929646,"mc":[{"id":"1.187528277","rc":[{"batb":[[0,3.4,2259.34],[1,3.35,2378.12]],"ltp":3.4,"tv":36653.56,"id":19924831}]}]}
{"op":"mcm","clk":"4220805792","pt":1631426930635,"mc":[{"id":"1.187528277","rc":[{"batb":[[0,3.4,2217.15]],"ltp":3.4,"tv":36653.56,"id":19924831}]}]}
{"op":"mcm","clk":"4220805820","pt":1631426931252,"mc":[{"id":"1.187528277","rc":[{"batb":[[0,3.4,2202.71]],"ltp":3.4,"tv":36653.56,"id":19924831}]}]}
{"op":"mcm","clk":"4220805914","pt":1631426932656,"mc":[{"id":"1.187528277","rc":[{"batl":[[0,3.45,688.59],[1,3.5,573.96]],"ltp":3.4,"tv":36653.56,"id":19924831}]}]}
{"op":"mcm","clk":"4220822980","pt":1631427216144,"mc":[{"id":"1.187528277","rc":[{"trd":[[3.4,15634.32]],"batb":[[0,3.4,2197.71]],"ltp":3.4,"tv":36663.56,"id":19924831}],"tv":204668.56}]}
{"op":"mcm","clk":"4220826499","pt":1631427274760,"mc":[{"id":"1.187528277","rc":[{"trd":[[1.41,87192.89]],"batb":[[0,1.41,26921.39]],"ltp":1.41,"tv":168111.35,"id":2249229}],"tv":204774.92}]}
{"op":"mcm","clk":"4220826659","pt":1631427277661,"mc":[{"id":"1.187528277","rc":[{"batl":[[2,1.44,7112.51]],"ltp":1.41,"tv":168111.35,"id":2249229}]}]}
{"op":"mcm","clk":"4220836657","pt":1631427435400,"mc":[{"id":"1.187528277","rc":[{"batb":[[0,3.4,2250.65]],"batl":[[0,3.45,636.42]],"ltp":3.4,"tv":36663.56,"id":19924831},{"batb":[[0,1.4,12924.95],[1,1.39,10109.49],[2,1.38,20954.18]],"ltp":1.41,"tv":168111.35,"id":2249229}]}]}
{"op":"mcm","clk":"4220837501","pt":1631427448339,"mc":[{"id":"1.187528277","rc":[{"batb":[[0,1.4,12935.04],[1,1.39,10534.93]],"ltp":1.41,"tv":168111.35,"id":2249229}]}]}
{"op":"mcm","clk":"4220837963","pt":1631427456062,"mc":[{"id":"1.187528277","rc":[{"batl":[[0,1.41,3079.2],[1,1.42,14178.65],[2,1.43,1893.06]],"ltp":1.41,"tv":168111.35,"id":2249229}]}]}
{"op":"mcm","clk":"4220840625","pt":1631427500721,"mc":[{"id":"1.187528277","rc":[{"batl":[[2,1.43,1467.62]],"ltp":1.41,"tv":168111.35,"id":2249229}]}]}
{"op":"mcm","clk":"4220840654","pt":1631427501340,"mc":[{"id":"1.187528277","rc":[{"batl":[[0,1.41,3236.1]],"ltp":1.41,"tv":168111.35,"id":2249229}]}]}
{"op":"mcm","clk":"4220842264","pt":1631427525698,"mc":[{"id":"1.187528277","rc":[{"batl":[[0,3.45,460.52]],"ltp":3.4,"tv":36663.56,"id":19924831}]}]}
{"op":"mcm","clk":"4220842467","pt":1631427528802,"mc":[{"id":"1.187528277","rc":[{"batl":[[0,3.45,372.57]],"ltp":3.4,"tv":36663.56,"id":19924831}]}]}
{"op":"mcm","clk":"4220842783","pt":1631427532594,"mc":[{"id":"1.187528277","rc":[{"trd":[[1.4,10704.07]],"batb":[[0,1.4,12895.04]],"ltp":1.4,"tv":168191.36,"id":2249229}],"tv":204854.92}]}
{"op":"mcm","clk":"4220846286","pt":1631427586688,"mc":[{"id":"1.187528277","rc":[{"trd":[[1.4,10746.23]],"batb":[[0,1.4,12873.96]],"ltp":1.4,"tv":168233.51,"id":2249229}],"tv":204897.08}]}
{"op":"mcm","clk":"4220852100","pt":1631427687069,"mc":[{"id":"1.187528277","rc":[{"trd":[[1.4,10921.84]],"batb":[[0,1.4,12786.16]],"ltp":1.4,"tv":168409.12,"id":2249229}],"tv":205072.69}]}
{"op":"mcm","clk":"4220866758","pt":1631427990655,"mc":[{"id":"1.187528277","rc":[{"trd":[[1.4,12592.9]],"batb":[[0,1.4,11950.63]],"ltp":1.4,"tv":170080.18,"id":2249229}],"tv":206743.74}]}
{"op":"mcm","clk":"4220866775","pt":1631427991064,"mc":[{"id":"1.187528277","rc":[{"batl":[[0,1.41,3316.7]],"ltp":1.4,"tv":170080.18,"id":2249229}]}]}
{"op":"mcm","clk":"4220867675","pt":1631428010713,"mc":[{"id":"1.187528277","rc":[{"batb":[[0,1.4,12082.55]],"ltp":1.4,"tv":170080.18,"id":2249229}]}]}
{"op":"mcm","clk":"4220868184","pt":1631428023048,"mc":[{"id":"1.187528277","rc":[{"batl":[[0,3.45,83.37]],"ltp":3.4,"tv":36663.56,"id":19924831}]}]}
{"op":"mcm","clk":"4220869035","pt":1631428043764,"mc":[{"id":"1.187528277","rc":[{"batl":[[0,3.45,51.42]],"ltp":3.4,"tv":36663.56,"id":19924831}]}]}
{"op":"mcm","clk":"4220869081","pt":1631428044739,"mc":[{"id":"1.187528277","rc":[{"trd":[[3.4,15764.46]],"batb":[[0,3.4,2185.58]],"ltp":3.4,"tv":36793.7,"id":19924831}],"tv":206873.89}]}
{"op":"mcm","clk":"4220869327","pt":1631428050141,"mc":[{"id":"1.187528277","rc":[{"trd":[[1.41,87235.59]],"batl":[[0,1.41,3295.35]],"ltp":1.41,"tv":170122.88,"id":2249229}],"tv":206916.59}]}
{"op":"mcm","clk":"4220869838","pt":1631428062354,"mc":[{"id":"1.187528277","rc":[{"batl":[[1,3.5,501.66]],"ltp":3.4,"tv":36793.7,"id":19924831}]}]}
{"op":"mcm","clk":"4220870394","pt":1631428075583,"mc":[{"id":"1.187528277","rc":[{"batl":[[2,3.6,291.21]],"ltp":3.4,"tv":36793.7,"id":19924831}]}]}
{"op":"mcm","clk":"4220870847","pt":1631428088038,"mc":[{"id":"1.187528277","rc":[{"batl":[[0,3.45,46.62]],"ltp":3.4,"tv":36793.7,"id":19924831}]}]}
{"op":"mcm","clk":"4220870939","pt":1631428090614,"mc":[{"id":"1.187528277","rc":[{"batl":[[1,1.42,14238.44]],"ltp":1.41,"tv":170122.88,"id":2249229}]}]}
{"op":"mcm","clk":"4220872823","pt":1631428137135,"mc":[{"id":"1.187528277","rc":[{"trd":[[3.45,2254.97]],"batl":[[0,3.45,34.36]],"ltp":3.45,"tv":36818.22,"id":19924831},{"batb":[[0,1.4,12052.55],[1,1.39,10504.93]],"batl":[[1,1.42,14178.65],[2,1.43,1437.62]],"ltp":1.41,"tv":170122.88,"id":2249229}],"tv":206941.11}]}
{"op":"mcm","clk":"4220876591","pt":1631428221994,"mc":[{"id":"1.187528277","rc":[{"trd":[[1.41,87241.11]],"batl":[[0,1.41,3292.59]],"ltp":1.41,"tv":170128.4,"id":2249229}],"tv":206946.62}]}
{"op":"mcm","clk":"4220883202","pt":1631428358945,"mc":[{"id":"1.187528277","rc":[{"trd":[[3.4,15797.62]],"batb":[[0,3.4,2169]],"ltp":3.4,"tv":36851.38,"id":19924831}],"tv":206979.78}]}
{"op":"mcm","clk":"4220890251","pt":1631428484485,"mc":[{"id":"1.187528277","rc":[{"trd":[[1.4,12598.21]],"batb":[[0,1.4,12049.89]],"batl":[[0,1.41,3295.23]],"ltp":1.4,"tv":170133.72,"id":2249229}],"tv":206985.1}]}
{"op":"mcm","clk":"4220902793","pt":1631428742007,"mc":[{"id":"1.187528277","rc":[{"batb":[[0,1.4,12055.15]],"ltp":1.4,"tv":170133.72,"id":2249229}]}]}
{"op":"mcm","clk":"4220907181","pt":1631428819835,"mc":[{"id":"1.187528277","rc":[{"trd":[[3.45,2291.21]],"batl":[[0,3.45,16.24]],"ltp":3.45,"tv":36887.62,"id":19924831}],"tv":207021.34}]}
{"op":"mcm","clk":"4220908580","pt":1631428843317,"mc":[{"id":"1.187528277","rc":[{"batl":[[0,3.45,8.53]],"ltp":3.45,"tv":36887.62,"id":19924831}]}]}
{"op":"mcm","clk":"4220909092","pt":1631428852932,"mc":[{"id":"1.187528277","rc":[{"trd":[[3.45,2308.28]],"batb":[[0,3.45,682.81],[1,3.4,2169],[2,3.35,2378.12]],"batl":[[0,3.5,501.66],[1,3.6,291.21],[2,5.2,5.32]],"ltp":3.45,"tv":36904.68,"id":19924831}],"tv":207038.4}]}
{"op":"mcm","clk":"4220911516","pt":1631428898116,"mc":[{"id":"1.187528277","rc":[{"batl":[[0,3.5,534.11]],"ltp":3.45,"tv":36904.68,"id":19924831},{"batb":[[0,1.4,12003.91]],"batl":[[2,1.43,1522.17]],"ltp":1.4,"tv":170133.72,"id":2249229}]}]}
{"op":"mcm","clk":"4220912416","pt":1631428914968,"mc":[{"id":"1.187528277","rc":[{"batb":[[2,3.35,2369.12]],"ltp":3.45,"tv":36904.68,"id":19924831}]}]}
{"op":"mcm","clk":"4220912489","pt":1631428916262,"mc":[{"id":"1.187528277","rc":[{"batb":[[2,3.35,2352.68]],"ltp":3.45,"tv":36904.68,"id":19924831}]}]}
{"op":"mcm","clk":"4220912547","pt":1631428917250,"mc":[{"id":"1.187528277","rc":[{"batb":[[2,3.35,2291.99]],"ltp":3.45,"tv":36904.68,"id":19924831}]}]}
{"op":"mcm","clk":"4220912633","pt":1631428918641,"mc":[{"id":"1.187528277","rc":[{"batb":[[2,3.35,2250.78]],"ltp":3.45,"tv":36904.68,"id":19924831}]}]}
{"op":"mcm","clk":"4220912660","pt":1631428919157,"mc":[{"id":"1.187528277","rc":[{"batb":[[2,3.35,2205.06]],"ltp":3.45,"tv":36904.68,"id":19924831}]}]}
{"op":"mcm","clk":"4220912718","pt":1631428920239,"mc":[{"id":"1.187528277","rc":[{"batb":[[2,3.35,2088.58]],"ltp":3.45,"tv":36904.68,"id":19924831}]}]}
{"op":"mcm","clk":"4220912771","pt":1631428921485,"mc":[{"id":"1.187528277","rc":[{"batb":[[2,3.35,2062.94]],"ltp":3.45,"tv":36904.68,"id":19924831}]}]}
{"op":"mcm","clk":"4220912811","pt":1631428922260,"mc":[{"id":"1.187528277","rc":[{"batb":[[2,3.35,2024.34]],"ltp":3.45,"tv":36904.68,"id":19924831}]}]}
{"op":"mcm","clk":"4220912876","pt":1631428923343,"mc":[{"id":"1.187528277","rc":[{"batb":[[0,1.4,12015.88]],"ltp":1.4,"tv":170133.72,"id":2249229}]}]}
{"op":"mcm","clk":"4220912891","pt":1631428923756,"mc":[{"id":"1.187528277","rc":[{"batb":[[1,3.4,2171.97]],"ltp":3.45,"tv":36904.68,"id":19924831}]}]}
{"op":"mcm","clk":"4220913604","pt":1631428937694,"mc":[{"id":"1.187528277","rc":[{"trd":[[3.5,1861.94]],"batb":[[0,3.4,2171.97],[1,3.35,2024.34],[2,3.3,134.02]],"batl":[[0,3.55,50.7],[1,3.6,424.09]],"ltp":3.5,"tv":38121.61,"id":19924831},{"trd":[[1.4,12969.9]],"batb":[[0,1.4,11644.2]],"ltp":1.4,"tv":170505.4,"id":2249229}],"tv":208627.01}]}
{"op":"mcm","clk":"4220913618","pt":1631428938002,"mc":[{"id":"1.187528277","rc":[{"batl":[[0,1.41,3544.62]],"ltp":1.4,"tv":170505.4,"id":2249229}]}]}
{"op":"mcm","clk":"4220914397","pt":1631428953686,"mc":[{"id":"1.187528277","rc":[{"batl":[[0,3.5,48.37],[1,3.55,50.7],[2,3.6,424.09]],"ltp":3.5,"tv":38121.61,"id":19924831}]}]}
{"op":"mcm","clk":"4220914409","pt":1631428953891,"mc":[{"id":"1.187528277","rc":[{"trd":[[3.5,1883.21]],"batl":[[0,3.5,89.16],[2,3.6,291.21]],"ltp":3.5,"tv":38142.88,"id":19924831}],"tv":208648.28}]}
{"op":"mcm","clk":"4220915115","pt":1631428967694,"mc":[{"id":"1.187528277","rc":[{"batb":[[2,3.3,84.48]],"ltp":3.5,"tv":38142.88,"id":19924831},{"batb":[[0,1.4,11557.94]],"ltp":1.4,"tv":170505.4,"id":2249229}]}]}
{"op":"mcm","clk":"4220915130","pt":1631428967903,"mc":[{"id":"1.187528277","rc":[{"batb":[[1,3.35,2066.19]],"batl":[[1,3.55,86.57]],"ltp":3.5,"tv":38142.88,"id":19924831},{"batb":[[1,1.39,10628.77]],"batl":[[2,1.43,1559.75]],"ltp":1.4,"tv":170505.4,"id":2249229}]}]}
{"op":"mcm","clk":"4220915309","pt":1631428971680,"mc":[{"id":"1.187528277","rc":[{"batl":[[0,3.5,177.11]],"ltp":3.5,"tv":38142.88,"id":19924831}]}]}
{"op":"mcm","clk":"4220915436","pt":1631428974828,"mc":[{"id":"1.187528277","rc":[{"trd":[[1.41,87293.89]],"batl":[[0,1.41,3518.23]],"ltp":1.41,"tv":170558.18,"id":2249229}],"tv":208701.07}]}
{"op":"mcm","clk":"4220916388","pt":1631428991625,"mc":[{"id":"1.187528277","rc":[{"batb":[[0,3.45,10.78],[1,3.4,2171.97],[2,3.35,2066.19]],"ltp":3.5,"tv":38142.88,"id":19924831}]}]}
{"op":"mcm","clk":"4220916765","pt":1631428998734,"mc":[{"id":"1.187528277","rc":[{"batb":[[0,1.4,11426.02]],"ltp":1.41,"tv":170558.18,"id":2249229}]}]}
{"op":"mcm","clk":"4220916848","pt":1631428999976,"mc":[{"id":"1.187528277","rc":[{"trd":[[3.5,1893.85]],"batl":[[0,3.5,171.79]],"ltp":3.5,"tv":38153.51,"id":19924831}],"tv":208711.7}]}
{"op":"mcm","clk":"4220917149","pt":1631429005714,"mc":[{"id":"1.187528277","rc":[{"batb":[[0,1.4,11403.95]],"ltp":1.41,"tv":170558.18,"id":2249229}]}]}
{"op":"mcm","clk":"4220917187","pt":1631429006358,"mc":[{"id":"1.187528277","rc":[{"batb":[[0,1.4,11252.24]],"ltp":1.41,"tv":170558.18,"id":2249229}]}]}
{"op":"mcm","clk":"4220917265","pt":1631429007651,"mc":[{"id":"1.187528277","rc":[{"batb":[[1,3.4,2293]],"ltp":3.5,"tv":38153.51,"id":19924831},{"batb":[[0,1.4,11131.34]],"batl":[[0,1.41,3786.77]],"ltp":1.41,"tv":170558.18,"id":2249229}]}]}
{"op":"mcm","clk":"4220917299","pt":1631429008267,"mc":[{"id":"1.187528277","rc":[{"batl":[[0,3.5,286.09],[1,3.55,99.56]],"ltp":3.5,"tv":38153.51,"id":19924831}]}]}
{"op":"mcm","clk":"4220917435","pt":1631429010692,"mc":[{"id":"1.187528277","rc":[{"batl":[[0,3.5,418.01]],"ltp":3.5,"tv":38153.51,"id":19924831}]}]}
{"op":"mcm","clk":"4220920375","pt":1631429065416,"mc":[{"id":"1.187528277","rc":[{"trd":[[3.5,2027.35]],"batb":[[0,3.45,62.95],[2,3.35,2027.58]],"batl":[[0,3.5,351.26]],"ltp":3.5,"tv":38287.02,"id":19924831},{"batl":[[0,1.41,3914.42],[1,1.42,14051.89],[2,1.43,1475.82]],"ltp":1.41,"tv":170558.18,"id":2249229}],"tv":208845.2}]}
{"op":"mcm","clk":"4220922211","pt":1631429097644,"mc":[{"id":"1.187528277","rc":[{"batb":[[0,3.45,114.84]],"ltp":3.5,"tv":38287.02,"id":19924831}]}]}
{"op":"mcm","clk":"4220923478","pt":1631429117692,"mc":[{"id":"1.187528277","rc":[{"batl":[[0,3.5,439.21]],"ltp":3.5,"tv":38287.02,"id":19924831}]}]}
{"op":"mcm","clk":"4220923603","pt":1631429119506,"mc":[{"id":"1.187528277","rc":[{"trd":[[1.4,13274.16]],"batb":[[0,1.4,10979.21]],"ltp":1.4,"tv":170862.44,"id":2249229}],"tv":209149.46}]}
{"op":"mcm","clk":"4220925197","pt":1631429144628,"mc":[{"id":"1.187528277","rc":[{"batb":[[0,3.45,132.07]],"ltp":3.5,"tv":38287.02,"id":19924831}]}]}
{"op":"mcm","clk":"4220945063","pt":1631429296659,"mc":[{"id":"1.187528277","rc":[{"trd":[[1.4,13286.47]],"batb":[[0,1.4,10973.06]],"ltp":1.4,"tv":170874.76,"id":2249229}],"tv":209161.78}]}
{"op":"mcm","clk":"4220945927","pt":1631429310681,"mc":[{"id":"1.187528277","rc":[{"trd":[[1.41,87306.21]],"batl":[[0,1.41,3908.26]],"ltp":1.41,"tv":170887.08,"id":2249229}],"tv":209174.1}]}
{"op":"mcm","clk":"4220947772","pt":1631429340550,"mc":[{"id":"1.187528277","rc":[{"trd":[[1.4,13360.38]],"batb":[[0,1.4,10936.1]],"ltp":1.4,"tv":170960.98,"id":2249229}],"tv":209248.0}]}
{"op":"mcm","clk":"4220948214","pt":1631429348163,"mc":[{"id":"1.187528277","rc":[{"batb":[[1,3.4,2720.02]],"ltp":3.5,"tv":38287.02,"id":19924831}]}]}
{"op":"mcm","clk":"4220952852","pt":1631429427333,"mc":[{"id":"1.187528277","rc":[{"batb":[[1,3.4,2920.02]],"ltp":3.5,"tv":38287.02,"id":19924831}]}]}
{"op":"mcm","clk":"4220954015","pt":1631429449340,"mc":[{"id":"1.187528277","rc":[{"trd":[[1.41,87314.75]],"batl":[[0,1.41,3903.99]],"ltp":1.41,"tv":170969.52,"id":2249229}],"tv":209256.54}]}
{"op":"mcm","clk":"4220954073","pt":1631429450166,"mc":[{"id":"1.187528277","rc":[{"trd":[[1.4,13394.54]],"batb":[[0,1.4,10919.02]],"ltp":1.4,"tv":171003.69,"id":2249229}],"tv":209290.71}]}
{"op":"mcm","clk":"4220963267","pt":1631429608754,"mc":[{"id":"1.187528277","rc":[{"trd":[[3.45,2342.48]],"batb":[[0,3.45,114.97]],"ltp":3.45,"tv":38321.22,"id":19924831}],"tv":209324.92}]}
{"op":"mcm","clk":"4220964068","pt":1631429622396,"mc":[{"id":"1.187528277","rc":[{"batb":[[0,1.4,10946.02]],"ltp":1.4,"tv":171003.69,"id":2249229}]}]}
{"op":"mcm","clk":"4220968378","pt":1631429698727,"mc":[{"id":"1.187528277","rc":[{"trd":[[3.5,2061.39]],"batl":[[0,3.5,422.19]],"ltp":3.5,"tv":38355.26,"id":19924831}],"tv":209358.95}]}
{"op":"mcm","clk":"4220968985","pt":1631429708574,"mc":[{"id":"1.187528277","rc":[{"trd":[[1.41,87479.58]],"batl":[[0,1.41,3821.57]],"ltp":1.41,"tv":171168.52,"id":2249229}],"tv":209523.79}]}
{"op":"mcm","clk":"4220969002","pt":1631429708781,"mc":[{"id":"1.187528277","rc":[{"batl":[[0,3.5,473.54]],"ltp":3.5,"tv":38355.26,"id":19924831}]}]}
{"op":"mcm","clk":"4220974816","pt":1631429817655,"mc":[{"id":"1.187528277","rc":[{"trd":[[1.4,13399.86]],"batb":[[0,1.4,10943.36]],"ltp":1.4,"tv":171173.84,"id":2249229}],"tv":209529.1}]}
{"op":"mcm","clk":"4220977569","pt":1631429865226,"mc":[{"id":"1.187528277","rc":[{"trd":[[3.5,2096.88]],"batl":[[0,3.5,455.8]],"ltp":3.5,"tv":38390.75,"id":19924831}],"tv":209564.59}]}
{"op":"mcm","clk":"4220980985","pt":1631429934638,"mc":[{"id":"1.187528277","rc":[{"trd":[[3.5,2147.93]],"batl":[[0,3.5,430.27]],"ltp":3.5,"tv":38441.8,"id":19924831}],"tv":209615.64}]}
{"op":"mcm","clk":"4220981083","pt":1631429936644,"mc":[{"id":"1.187528277","rc":[{"batb":[[0,3.45,123.76]],"ltp":3.5,"tv":38441.8,"id":19924831}]}]}
{"op":"mcm","clk":"4220981368","pt":1631429942554,"mc":[{"id":"1.187528277","rc":[{"trd":[[3.5,2183.45]],"batl":[[0,3.5,412.51]],"ltp":3.5,"tv":38477.32,"id":19924831}],"tv":209651.16}]}
{"op":"mcm","clk":"4220982483","pt":1631429966703,"mc":[{"id":"1.187528277","rc":[{"batb":[[0,3.45,184.45]],"ltp":3.5,"tv":38477.32,"id":19924831}]}]}
{"op":"mcm","clk":"4220982964","pt":1631429977387,"mc":[{"id":"1.187528277","rc":[{"batb":[[0,3.45,194.89]],"ltp":3.5,"tv":38477.32,"id":19924831},{"trd":[[1.41,87536.86]],"batl":[[0,1.41,3792.93]],"ltp":1.41,"tv":171231.12,"id":2249229}],"tv":209708.44}]}
{"op":"mcm","clk":"4220983479","pt":1631429988654,"mc":[{"id":"1.187528277","rc":[{"batb":[[0,3.45,208.08]],"ltp":3.5,"tv":38477.32,"id":19924831}]}]}
{"op":"mcm","clk":"4220984067","pt":1631430001077,"mc":[{"id":"1.187528277","rc":[{"batb":[[0,3.45,427.87]],"ltp":3.5,"tv":38477.32,"id":19924831}]}]}
{"op":"mcm","clk":"4220985451","pt":1631430023620,"mc":[{"id":"1.187528277","rc":[{"batb":[[0,1.4,10945.36]],"ltp":1.41,"tv":171231.12,"id":2249229}]}]}
{"op":"mcm","clk":"4220985630","pt":1631430026719,"mc":[{"id":"1.187528277","rc":[{"batb":[[0,3.45,456.9],[2,3.35,2019.89]],"batl":[[0,3.5,436.42],[1,3.55,63.69]],"ltp":3.5,"tv":38477.32,"id":19924831},{"batl":[[2,1.43,1439.95]],"ltp":1.41,"tv":171231.12,"id":2249229}]}]}
{"op":"mcm","clk":"4220986914","pt":1631430048549,"mc":[{"id":"1.187528277","rc":[{"batb":[[0,3.45,497.77]],"ltp":3.5,"tv":38477.32,"id":19924831}]}]}
{"op":"mcm","clk":"4220987428","pt":1631430056243,"mc":[{"id":"1.187528277","rc":[{"batb":[[2,3.35,2013.06]],"batl":[[0,3.5,446.67]],"ltp":3.5,"tv":38477.32,"id":19924831},{"batb":[[0,1.4,11023.94],[1,1.39,10504.93]],"ltp":1.41,"tv":171231.12,"id":2249229}]}]}
{"op":"mcm","clk":"4220991466","pt":1631430119512,"mc":[{"id":"1.187528277","rc":[{"batb":[[0,3.45,503.9]],"ltp":3.5,"tv":38477.32,"id":19924831}]}]}
{"op":"mcm","clk":"4220995849","pt":1631430178652,"mc":[{"id":"1.187528277","rc":[{"batb":[[0,1.4,11523.94]],"ltp":1.41,"tv":171231.12,"id":2249229}]}]}
{"op":"mcm","clk":"4220999269","pt":1631430224728,"mc":[{"id":"1.187528277","rc":[{"trd":[[3.5,2230.25]],"batl":[[0,3.5,423.28]],"ltp":3.5,"tv":38524.12,"id":19924831}],"tv":209755.24}]}
{"op":"mcm","clk":"4221022202","pt":1631430549531,"mc":[{"id":"1.187528277","rc":[{"trd":[[3.45,2362.48]],"batb":[[0,3.45,493.9]],"ltp":3.45,"tv":38544.12,"id":19924831}],"tv":209775.24}]}
{"op":"mcm","clk":"4221022270","pt":1631430550758,"mc":[{"id":"1.187528277","rc":[{"trd":[[3.5,2265.77]],"batl":[[0,3.5,405.51]],"ltp":3.5,"tv":38579.65,"id":19924831}],"tv":209810.77}]}
{"op":"mcm","clk":"4221023261","pt":1631430564057,"mc":[{"id":"1.187528277","rc":[{"batb":[[1,1.39,17893.41]],"ltp":1.41,"tv":171231.12,"id":2249229}]}]}
{"op":"mcm","clk":"4221024238","pt":1631430578481,"mc":[{"id":"1.187528277","rc":[{"trd":[[3.5,2673.95]],"batl":[[0,3.5,201.42]],"ltp":3.5,"tv":38987.83,"id":19924831}],"tv":210218.95}]}
{"op":"mcm","clk":"4221024272","pt":1631430578848,"mc":[{"id":"1.187528277","rc":[{"batb":[[2,1.38,29810.38]],"ltp":1.41,"tv":171231.12,"id":2249229}]}]}
{"op":"mcm","clk":"4221025307","pt":1631430594627,"mc":[{"id":"1.187528277","rc":[{"batb":[[0,1.4,11379.59]],"ltp":1.41,"tv":171231.12,"id":2249229}]}]}
{"op":"mcm","clk":"4221025376","pt":1631430595453,"mc":[{"id":"1.187528277","rc":[{"batb":[[1,3.4,2979.31]],"batl":[[0,3.5,258.8]],"ltp":3.5,"tv":38987.83,"id":19924831}]}]}
{"op":"mcm","clk":"4221028162","pt":1631430636477,"mc":[{"id":"1.187528277","rc":[{"trd":[[1.4,13409.43]],"batb":[[0,1.4,11374.81]],"ltp":1.4,"tv":171240.68,"id":2249229}],"tv":210228.52}]}
{"op":"mcm","clk":"4221029791","pt":1631430658652,"mc":[{"id":"1.187528277","rc":[{"batb":[[0,3.45,563.29]],"ltp":3.5,"tv":38987.83,"id":19924831}]}]}
{"op":"mcm","clk":"4221034234","pt":1631430718069,"mc":[{"id":"1.187528277","rc":[{"batb":[[2,3.35,1985.73]],"ltp":3.5,"tv":38987.83,"id":19924831},{"batb":[[0,1.4,11383.35]],"ltp":1.4,"tv":171240.68,"id":2249229}]}]}
{"op":"mcm","clk":"4221035504","pt":1631430733395,"mc":[{"id":"1.187528277","rc":[{"batb":[[0,3.45,573.12]],"ltp":3.5,"tv":38987.83,"id":19924831},{"trd":[[1.4,14047.57]],"batb":[[0,1.4,11064.29]],"ltp":1.4,"tv":171878.83,"id":2249229}],"tv":210866.66}]}
{"op":"mcm","clk":"4221036540","pt":1631430745709,"mc":[{"id":"1.187528277","rc":[{"trd":[[1.41,87595.36]],"batl":[[0,1.41,3763.68]],"ltp":1.41,"tv":171937.33,"id":2249229}],"tv":210925.16}]}
{"op":"mcm","clk":"4221036752","pt":1631430748400,"mc":[{"id":"1.187528277","rc":[{"batb":[[2,3.35,2020.74]],"ltp":3.5,"tv":38987.83,"id":19924831},{"batb":[[0,1.4,11054.9]],"ltp":1.41,"tv":171937.33,"id":2249229}]}]}
{"op":"mcm","clk":"4221040023","pt":1631430791110,"mc":[{"id":"1.187528277","rc":[{"trd":[[3.45,2368.28]],"batb":[[0,3.45,570.22]],"ltp":3.45,"tv":38993.63,"id":19924831}],"tv":210930.96}]}
{"op":"mcm","clk":"4221041270","pt":1631430806338,"mc":[{"id":"1.187528277","rc":[{"trd":[[1.4,14063.57]],"batb":[[0,1.4,11046.89]],"ltp":1.4,"tv":171953.33,"id":2249229}],"tv":210946.96}]}
{"op":"mcm","clk":"4221042455","pt":1631430821313,"mc":[{"id":"1.187528277","rc":[{"trd":[[3.45,2373.6]],"batb":[[0,3.45,567.56]],"ltp":3.45,"tv":38998.95,"id":19924831}],"tv":210952.28}]}
{"op":"mcm","clk":"4221042635","pt":1631430823701,"mc":[{"id":"1.187528277","rc":[{"trd":[[1.4,14169.93]],"batb":[[0,1.4,10993.71]],"ltp":1.4,"tv":172059.69,"id":2249229}],"tv":211058.64}]}
{"op":"mcm","clk":"4221047752","pt":1631430887954,"mc":[{"id":"1.187528277","rc":[{"batl":[[0,1.41,3773.68]],"ltp":1.4,"tv":172059.69,"id":2249229}]}]}
{"op":"mcm","clk":"4221048553","pt":1631430898181,"mc":[{"id":"1.187528277","rc":[{"batb":[[0,1.4,11003.71]],"ltp":1.4,"tv":172059.69,"id":2249229}]}]}
{"op":"mcm","clk":"4221049811","pt":1631430913163,"mc":[{"id":"1.187528277","rc":[{"batl":[[0,1.41,3793.68]],"ltp":1.4,"tv":172059.69,"id":2249229}]}]}
{"op":"mcm","clk":"4221050772","pt":1631430925021,"mc":[{"id":"1.187528277","rc":[{"batb":[[0,1.4,11023.71]],"ltp":1.4,"tv":172059.69,"id":2249229}]}]}
{"op":"mcm","clk":"4221068428","pt":1631431131841,"mc":[{"id":"1.187528277","rc":[{"trd":[[1.4,14173.93]],"batb":[[0,1.4,11021.71]],"ltp":1.4,"tv":172063.69,"id":2249229}],"tv":211062.64}]}
{"op":"mcm","clk":"4221076039","pt":1631431218285,"mc":[{"id":"1.187528277","rc":[{"trd":[[1.4,14573.93]],"batb":[[0,1.4,10821.71]],"ltp":1.4,"tv":172463.69,"id":2249229}],"tv":211462.64}]}
{"op":"mcm","clk":"4221088512","pt":1631431350454,"mc":[{"id":"1.187528277","rc":[{"trd":[[3.45,2393.6]],"batb":[[0,3.45,557.56]],"ltp":3.45,"tv":39018.95,"id":19924831}],"tv":211482.64}]}
{"op":"mcm","clk":"4221100295","pt":1631431479451,"mc":[{"id":"1.187528277","rc":[{"trd":[[3.5,2709.47]],"batl":[[0,3.5,241.04]],"ltp":3.5,"tv":39054.47,"id":19924831}],"tv":211518.16}]}
{"op":"mcm","clk":"4221104395","pt":1631431521025,"mc":[{"id":"1.187528277","rc":[{"batl":[[0,1.41,5404.41]],"ltp":1.4,"tv":172463.69,"id":2249229}]}]}
{"op":"mcm","clk":"4221104908","pt":1631431526955,"mc":[{"id":"1.187528277","rc":[{"batl":[[0,3.5,233.35]],"ltp":3.5,"tv":39054.47,"id":19924831}]}]}
{"op":"mcm","clk":"4221105377","pt":1631431531954,"mc":[{"id":"1.187528277","rc":[{"trd":[[3.5,2744.99]],"batl":[[0,3.5,215.6]],"ltp":3.5,"tv":39089.98,"id":19924831}],"tv":211553.68}]}
{"op":"mcm","clk":"4221110425","pt":1631431587248,"mc":[{"id":"1.187528277","rc":[{"trd":[[3.45,2433.6]],"batb":[[0,3.45,537.56]],"ltp":3.45,"tv":39129.98,"id":19924831}],"tv":211593.68}]}
{"op":"mcm","clk":"4221127238","pt":1631431778145,"mc":[{"id":"1.187528277","rc":[{"batb":[[0,1.4,10744],[1,1.39,18030.91]],"batl":[[2,1.43,1483.51]],"ltp":1.4,"tv":172463.69,"id":2249229}]}]}
{"op":"mcm","clk":"4221127333","pt":1631431779282,"mc":[{"id":"1.187528277","rc":[{"trd":[[1.4,14733.93]],"batb":[[0,1.4,10664]],"ltp":1.4,"tv":172623.69,"id":2249229}],"tv":211753.68}]}
{"op":"mcm","clk":"4221128238","pt":1631431791619,"mc":[{"id":"1.187528277","rc":[{"trd":[[3.45,2470.83]],"batb":[[0,3.45,518.95]],"ltp":3.45,"tv":39167.21,"id":19924831}],"tv":211790.9}]}
{"op":"mcm","clk":"4221131025","pt":1631431819703,"mc":[{"id":"1.187528277","rc":[{"batb":[[0,3.45,512.3]],"ltp":3.45,"tv":39167.21,"id":19924831}]}]}
{"op":"mcm","clk":"4221131792","pt":1631431828645,"mc":[{"id":"1.187528277","rc":[{"batl":[[0,3.5,144.58]],"ltp":3.45,"tv":39167.21,"id":19924831}]}]}
{"op":"mcm","clk":"4221134917","pt":1631431864687,"mc":[{"id":"1.187528277","rc":[{"batb":[[0,3.45,548.35]],"ltp":3.45,"tv":39167.21,"id":19924831}]}]}
{"op":"mcm","clk":"4221136102","pt":1631431878547,"mc":[{"id":"1.187528277","rc":[{"batb":[[0,3.45,552.76]],"ltp":3.45,"tv":39167.21,"id":19924831}]}]}
{"op":"mcm","clk":"4221136737","pt":1631431885632,"mc":[{"id":"1.187528277","rc":[{"batb":[[1,3.4,3235.52]],"ltp":3.45,"tv":39167.21,"id":19924831}]}]}
{"op":"mcm","clk":"4221138154","pt":1631431903064,"mc":[{"id":"1.187528277","rc":[{"batb":[[2,3.35,2362.36]],"ltp":3.45,"tv":39167.21,"id":19924831}]}]}
{"op":"mcm","clk":"4221150494","pt":1631432042603,"mc":[{"id":"1.187528277","rc":[{"trd":[[3.5,2794.17]],"batl":[[0,3.5,119.99]],"ltp":3.5,"tv":39216.39,"id":19924831}],"tv":211840.08}]}
{"op":"mcm","clk":"4221150522","pt":1631432042808,"mc":[{"id":"1.187528277","rc":[{"batb":[[0,3.45,604.93]],"ltp":3.5,"tv":39216.39,"id":19924831}]}]}
{"op":"mcm","clk":"4221153896","pt":1631432075563,"mc":[{"id":"1.187528277","rc":[{"batb":[[0,3.45,613.42]],"ltp":3.5,"tv":39216.39,"id":19924831}]}]}
{"op":"mcm","clk":"4221155096","pt":1631432088296,"mc":[{"id":"1.187528277","rc":[{"trd":[[3.45,2490.23]],"batb":[[0,3.45,603.72]],"ltp":3.45,"tv":39235.79,"id":19924831}],"tv":211859.48}]}
{"op":"mcm","clk":"4221156391","pt":1631432101972,"mc":[{"id":"1.187528277","rc":[{"batl":[[0,1.41,5878.4]],"ltp":1.4,"tv":172623.69,"id":2249229}]}]}
{"op":"mcm","clk":"4221173872","pt":1631432278212,"mc":[{"id":"1.187528277","rc":[{"batl":[[0,3.5,83.86]],"ltp":3.45,"tv":39235.79,"id":19924831},{"batb":[[1,1.39,10642.43]],"ltp":1.4,"tv":172623.69,"id":2249229}]}]}
{"op":"mcm","clk":"4221175227","pt":1631432289848,"mc":[{"id":"1.187528277","rc":[{"trd":[[3.45,2567.09]],"batb":[[0,3.45,565.29]],"ltp":3.45,"tv":39312.65,"id":19924831}],"tv":211936.34}]}
{"op":"mcm","clk":"4221176812","pt":1631432304379,"mc":[{"id":"1.187528277","rc":[{"batb":[[1,3.4,3228.07]],"ltp":3.45,"tv":39312.65,"id":19924831}]}]}
{"op":"mcm","clk":"4221176866","pt":1631432304890,"mc":[{"id":"1.187528277","rc":[{"batb":[[0,3.45,573.9]],"ltp":3.45,"tv":39312.65,"id":19924831}]}]}
{"op":"mcm","clk":"4221186625","pt":1631432401672,"mc":[{"id":"1.187528277","rc":[{"batb":[[0,3.45,655.45]],"ltp":3.45,"tv":39312.65,"id":19924831}]}]}
{"op":"mcm","clk":"4221190814","pt":1631432440984,"mc":[{"id":"1.187528277","rc":[{"batb":[[0,3.45,668.97]],"ltp":3.45,"tv":39312.65,"id":19924831}]}]}
{"op":"mcm","clk":"4221197154","pt":1631432497860,"mc":[{"id":"1.187528277","rc":[{"trd":[[1.4,14751.52]],"batb":[[0,1.4,10655.2]],"ltp":1.4,"tv":172641.28,"id":2249229}],"tv":211953.93}]}
{"op":"mcm","clk":"4221199428","pt":1631432518411,"mc":[{"id":"1.187528277","rc":[{"batl":[[0,3.5,89.84]],"ltp":3.45,"tv":39312.65,"id":19924831},{"batb":[[0,1.4,10731.21],[1,1.39,10504.93]],"batl":[[2,1.43,1439.1]],"ltp":1.4,"tv":172641.28,"id":2249229}]}]}
{"op":"mcm","clk":"4221201425","pt":1631432535028,"mc":[{"id":"1.187528277","rc":[{"trd":[[1.4,14953.26]],"batb":[[0,1.4,10630.35]],"ltp":1.4,"tv":172843.01,"id":2249229}],"tv":212155.67}]}
{"op":"mcm","clk":"4221213233","pt":1631432646572,"mc":[{"id":"1.187528277","rc":[{"batb":[[1,3.4,2971.86]],"ltp":3.45,"tv":39312.65,"id":19924831}]}]}
{"op":"mcm","clk":"4221213368","pt":1631432647760,"mc":[{"id":"1.187528277","rc":[{"batb":[[2,3.35,2020.74]],"ltp":3.45,"tv":39312.65,"id":19924831}]}]}
{"op":"mcm","clk":"4221225966","pt":1631432777573,"mc":[{"id":"1.187528277","rc":[{"trd":[[1.4,14959.26]],"batb":[[0,1.4,10627.35]],"ltp":1.4,"tv":172849.01,"id":2249229}],"tv":212161.67}]}
{"op":"mcm","clk":"4221235599","pt":1631432882645,"mc":[{"id":"1.187528277","rc":[{"trd":[[1.41,87751.38]],"batl":[[0,1.41,5800.39]],"ltp":1.41,"tv":173005.03,"id":2249229}],"tv":212317.69}]}
{"op":"mcm","clk":"4221243599","pt":1631432971162,"mc":[{"id":"1.187528277","rc":[{"trd":[[1.4,14964.26]],"batb":[[0,1.4,10624.85]],"ltp":1.4,"tv":173010.03,"id":2249229}],"tv":212322.69}]}
{"op":"mcm","clk":"4221248731","pt":1631433025641,"mc":[{"id":"1.187528277","rc":[{"trd":[[3.5,2859.85]],"batl":[[0,3.5,56.99]],"ltp":3.5,"tv":39378.33,"id":19924831}],"tv":212388.37}]}
{"op":"mcm","clk":"4221249909","pt":1631433038287,"mc":[{"id":"1.187528277","rc":[{"batb":[[2,3.35,2029.28]],"batl":[[0,3.5,51.02],[1,3.55,97.85]],"ltp":3.5,"tv":39378.33,"id":19924831},{"batb":[[0,1.4,10548.84],[1,1.39,10591.19]],"batl":[[1,1.42,14128.76],[2,1.43,1353.69]],"ltp":1.4,"tv":173010.03,"id":2249229}]}]}
{"op":"mcm","clk":"4221250787","pt":1631433049103,"mc":[{"id":"1.187528277","rc":[{"batb":[[1,3.4,2975.16]],"ltp":3.5,"tv":39378.33,"id":19924831}]}]}
{"op":"mcm","clk":"4221264423","pt":1631433206620,"mc":[{"id":"1.187528277","rc":[{"trd":[[1.41,87829.96]],"batl":[[0,1.41,5761.1]],"ltp":1.41,"tv":173088.61,"id":2249229}],"tv":212466.95}]}
{"op":"mcm","clk":"4221271492","pt":1631433294640,"mc":[{"id":"1.187528277","rc":[{"batl":[[1,1.42,43528.76]],"ltp":1.41,"tv":173088.61,"id":2249229}]}]}
{"op":"mcm","clk":"4221271508","pt":1631433294847,"mc":[{"id":"1.187528277","rc":[{"batb":[[0,1.4,10420.27]],"ltp":1.41,"tv":173088.61,"id":2249229}]}]}
{"op":"mcm","clk":"4221272663","pt":1631433307679,"mc":[{"id":"1.187528277","rc":[{"batl":[[0,1.41,35161.1],[1,1.42,14128.76]],"ltp":1.41,"tv":173088.61,"id":2249229}]}]}
{"op":"mcm","clk":"4221275804","pt":1631433346656,"mc":[{"id":"1.187528277","rc":[{"trd":[[3.5,2998.82]],"batl":[[0,3.55,97.85],[1,3.6,291.21],[2,5.2,5.32]],"ltp":3.5,"tv":39517.3,"id":19924831},{"trd":[[1.4,15056.6]],"batb":[[0,1.4,10327.93]],"ltp":1.4,"tv":173180.95,"id":2249229}],"tv":212698.25}]}
{"op":"mcm","clk":"4221276207","pt":1631433351632,"mc":[{"id":"1.187528277","rc":[{"batl":[[0,1.41,5761.1]],"ltp":1.4,"tv":173180.95,"id":2249229}]}]}
{"op":"mcm","clk":"4221276225","pt":1631433351839,"mc":[{"id":"1.187528277","rc":[{"batl":[[1,1.42,43528.76]],"ltp":1.4,"tv":173180.95,"id":2249229}]}]}
{"op":"mcm","clk":"4221276616","pt":1631433356686,"mc":[{"id":"1.187528277","rc":[{"trd":[[3.5,3086.77]],"ltp":3.5,"tv":39605.25,"id":19924831},{"trd":[[1.4,15276.47]],"batb":[[0,1.4,10108.05]],"ltp":1.4,"tv":173400.82,"id":2249229}],"tv":213006.08}]}
{"op":"mcm","clk":"4221277668","pt":1631433368823,"mc":[{"id":"1.187528277","rc":[{"batb":[[1,1.39,14776]],"ltp":1.4,"tv":173400.82,"id":2249229}]}]}
{"op":"mcm","clk":"4221279195","pt":1631433385968,"mc":[{"id":"1.187528277","rc":[{"batb":[[0,1.4,14292.87]],"ltp":1.4,"tv":173400.82,"id":2249229}]}]}
{"op":"mcm","clk":"4221280480","pt":1631433400373,"mc":[{"id":"1.187528277","rc":[{"batb":[[1,3.4,3001.62]],"ltp":3.5,"tv":39605.25,"id":19924831}]}]}
{"op":"mcm","clk":"4221284619","pt":1631433446838,"mc":[{"id":"1.187528277","rc":[{"batl":[[0,3.5,87.95],[1,3.55,97.85],[2,3.6,291.21]],"ltp":3.5,"tv":39605.25,"id":19924831}]}]}
{"op":"mcm","clk":"4221287313","pt":1631433475777,"mc":[{"id":"1.187528277","rc":[{"batb":[[1,1.39,16477.52]],"ltp":1.4,"tv":173400.82,"id":2249229}]}]}
{"op":"mcm","clk":"4221287497","pt":1631433478304,"mc":[{"id":"1.187528277","rc":[{"batb":[[1,1.39,18179.03]],"ltp":1.4,"tv":173400.82,"id":2249229}]}]}
{"op":"mcm","clk":"4221292826","pt":1631433539112,"mc":[{"id":"1.187528277","rc":[{"batb":[[1,1.39,19004.6]],"ltp":1.4,"tv":173400.82,"id":2249229}]}]}
{"op":"mcm","clk":"4221300691","pt":1631433625280,"mc":[{"id":"1.187528277","rc":[{"trd":[[1.4,15286.47]],"batb":[[0,1.4,14287.87]],"ltp":1.4,"tv":173410.82,"id":2249229}],"tv":213016.07}]}
{"op":"mcm","clk":"4221304319","pt":1631433657409,"mc":[{"id":"1.187528277","rc":[{"batl":[[0,3.5,119.55]],"ltp":3.5,"tv":39605.25,"id":19924831}]}]}
{"op":"mcm","clk":"4221311256","pt":1631433723546,"mc":[{"id":"1.187528277","rc":[{"trd":[[3.45,2647.48]],"batb":[[0,3.45,628.78]],"ltp":3.45,"tv":39685.64,"id":19924831}],"tv":213096.46}]}
{"op":"mcm","clk":"4221313561","pt":1631433748219,"mc":[{"id":"1.187528277","rc":[{"trd":[[1.4,15296.46]],"batb":[[0,1.4,14282.88]],"ltp":1.4,"tv":173420.82,"id":2249229}],"tv":213106.46}]}
{"op":"mcm","clk":"4221314297","pt":1631433755134,"mc":[{"id":"1.187528277","rc":[{"trd":[[1.41,87917.07]],"batl":[[0,1.41,5717.54]],"ltp":1.41,"tv":173507.93,"id":2249229}],"tv":213193.58}]}
{"op":"mcm","clk":"4221331054","pt":1631433935541,"mc":[{"id":"1.187528277","rc":[{"trd":[[3.5,3139.95]],"batl":[[0,3.5,92.96]],"ltp":3.5,"tv":39738.82,"id":19924831}],"tv":213246.76}]}
{"op":"mcm","clk":"4221331414","pt":1631433939332,"mc":[{"id":"1.187528277","rc":[{"trd":[[1.4,15300.46]],"batb":[[0,1.4,14280.88]],"ltp":1.4,"tv":173511.93,"id":2249229}],"tv":213250.75}]}
{"op":"mcm","clk":"4221332494","pt":1631433951643,"mc":[{"id":"1.187528277","rc":[{"batl":[[0,3.5,180.91]],"ltp":3.5,"tv":39738.82,"id":19924831}]}]}
{"op":"mcm","clk":"4221333102","pt":1631433958972,"mc":[{"id":"1.187528277","rc":[{"batl":[[0,1.41,5744.13]],"ltp":1.4,"tv":173511.93,"id":2249229}]}]}
{"op":"mcm","clk":"4221334745","pt":1631433978224,"mc":[{"id":"1.187528277","rc":[{"trd":[[1.41,87951.24]],"batl":[[0,1.41,5727.05]],"ltp":1.41,"tv":173546.09,"id":2249229}],"tv":213284.91}]}
{"op":"mcm","clk":"4221346009","pt":1631434100951,"mc":[{"id":"1.187528277","rc":[{"trd":[[1.4,15336.61]],"batb":[[0,1.4,14262.81]],"ltp":1.4,"tv":173582.24,"id":2249229}],"tv":213321.06}]}
{"op":"mcm","clk":"4221358331","pt":1631434228693,"mc":[{"id":"1.187528277","rc":[{"batb":[[1,1.39,19037.05]],"ltp":1.4,"tv":173582.24,"id":2249229}]}]}
{"op":"mcm","clk":"4221360751","pt":1631434254955,"mc":[{"id":"1.187528277","rc":[{"trd":[[1.4,15364.26]],"batb":[[0,1.4,14248.98]],"ltp":1.4,"tv":173609.89,"id":2249229}],"tv":213348.72}]}
{"op":"mcm","clk":"4221364354","pt":1631434295144,"mc":[{"id":"1.187528277","rc":[{"trd":[[3.45,2753.84]],"batb":[[0,3.45,575.6]],"ltp":3.45,"tv":39845.18,"id":19924831}],"tv":213455.07}]}
{"op":"mcm","clk":"4221365687","pt":1631434310746,"mc":[{"id":"1.187528277","rc":[{"batb":[[1,3.4,2994.92]],"ltp":3.45,"tv":39845.18,"id":19924831}]}]}
{"op":"mcm","clk":"4221367416","pt":1631434331351,"mc":[{"id":"1.187528277","rc":[{"batl":[[2,1.43,1378.69]],"ltp":1.4,"tv":173609.89,"id":2249229}]}]}
{"op":"mcm","clk":"4221368884","pt":1631434348992,"mc":[{"id":"1.187528277","rc":[{"batb":[[2,3.35,5079.68]],"ltp":3.45,"tv":39845.18,"id":19924831}]}]}
{"op":"mcm","clk":"4221369910","pt":1631434360726,"mc":[{"id":"1.187528277","rc":[{"batb":[[1,3.4,4738.83]],"ltp":3.45,"tv":39845.18,"id":19924831}]}]}
{"op":"mcm","clk":"4221370441","pt":1631434366712,"mc":[{"id":"1.187528277","rc":[{"trd":[[3.5,3164.05]],"batl":[[0,3.5,168.86]],"ltp":3.5,"tv":39869.27,"id":19924831}],"tv":213479.17}]}
{"op":"mcm","clk":"4221372224","pt":1631434387426,"mc":[{"id":"1.187528277","rc":[{"batl":[[1,1.42,44677.2]],"ltp":1.4,"tv":173609.89,"id":2249229}]}]}
{"op":"mcm","clk":"4221379057","pt":1631434461695,"mc":[{"id":"1.187528277","rc":[{"batl":[[0,3.5,151.79]],"ltp":3.5,"tv":39869.27,"id":19924831}]}]}
{"op":"mcm","clk":"4221381886","pt":1631434494036,"mc":[{"id":"1.187528277","rc":[{"trd":[[3.45,2813.84]],"batb":[[0,3.45,545.6]],"ltp":3.45,"tv":39929.27,"id":19924831}],"tv":213539.17}]}
{"op":"mcm","clk":"4221382156","pt":1631434496638,"mc":[{"id":"1.187528277","rc":[{"batl":[[0,1.41,5735.59]],"ltp":1.4,"tv":173609.89,"id":2249229}]}]}
{"op":"mcm","clk":"4221382935","pt":1631434503952,"mc":[{"id":"1.187528277","rc":[{"trd":[[1.41,88036.64]],"batl":[[0,1.41,5692.89]],"ltp":1.41,"tv":173695.29,"id":2249229}],"tv":213624.57}]}
{"op":"mcm","clk":"4221385174","pt":1631434526806,"mc":[{"id":"1.187528277","rc":[{"trd":[[3.45,2867.02]],"batb":[[0,3.45,519.01]],"ltp":3.45,"tv":39982.45,"id":19924831}],"tv":213677.75}]}
{"op":"mcm","clk":"4221388289","pt":1631434558951,"mc":[{"id":"1.187528277","rc":[{"batb":[[0,3.45,511.65]],"ltp":3.45,"tv":39982.45,"id":19924831},{"batb":[[1,1.39,19003.74]],"ltp":1.41,"tv":173695.29,"id":2249229}]}]}
{"op":"mcm","clk":"4221391255","pt":1631434588716,"mc":[{"id":"1.187528277","rc":[{"batb":[[1,1.39,19036.2]],"batl":[[1,1.42,44600.34],[2,1.43,1513.63]],"ltp":1.41,"tv":173695.29,"id":2249229}]}]}
{"op":"mcm","clk":"4221391961","pt":1631434596650,"mc":[{"id":"1.187528277","rc":[{"batl":[[1,3.55,104.68]],"ltp":3.45,"tv":39982.45,"id":19924831}]}]}
{"op":"mcm","clk":"4221393648","pt":1631434612649,"mc":[{"id":"1.187528277","rc":[{"batl":[[1,3.55,107.4]],"ltp":3.45,"tv":39982.45,"id":19924831}]}]}
{"op":"mcm","clk":"4221413747","pt":1631434708966,"mc":[{"id":"1.187528277","rc":[{"trd":[[1.4,15366.39]],"batb":[[0,1.4,14247.91]],"ltp":1.4,"tv":173697.43,"id":2249229}],"tv":213679.88}]}
{"op":"mcm","clk":"4221414633","pt":1631434717970,"mc":[{"id":"1.187528277","rc":[{"trd":[[1.41,88038.76]],"batl":[[0,1.41,5691.83]],"ltp":1.41,"tv":173699.55,"id":2249229}],"tv":213682.0}]}
{"op":"mcm","clk":"4221419920","pt":1631434768746,"mc":[{"id":"1.187528277","rc":[{"trd":[[1.41,88144.33]],"batl":[[0,1.41,5639.05]],"ltp":1.41,"tv":173805.12,"id":2249229}],"tv":213787.57}]}
{"op":"mcm","clk":"4221439197","pt":1631434956204,"mc":[{"id":"1.187528277","rc":[{"trd":[[3.45,2873.02]],"batb":[[0,3.45,508.65]],"ltp":3.45,"tv":39988.45,"id":19924831}],"tv":213793.57}]}
{"op":"mcm","clk":"4221441149","pt":1631434975341,"mc":[{"id":"1.187528277","rc":[{"trd":[[1.41,88197.51]],"batl":[[0,1.41,5612.46]],"ltp":1.41,"tv":173858.3,"id":2249229}],"tv":213846.75}]}
{"op":"mcm","clk":"4221443319","pt":1631434996727,"mc":[{"id":"1.187528277","rc":[{"trd":[[3.45,2901.72]],"batb":[[0,3.45,494.3]],"ltp":3.45,"tv":40017.15,"id":19924831}],"tv":213875.45}]}
{"op":"mcm","clk":"4221445678","pt":1631435019684,"mc":[{"id":"1.187528277","rc":[{"batb":[[0,3.45,498.87],[2,3.35,5069.43]],"batl":[[0,3.5,178.27],[1,3.55,66.4]],"ltp":3.45,"tv":40017.15,"id":19924831},{"batl":[[2,1.43,1465.81]],"ltp":1.41,"tv":173858.3,"id":2249229}]}]}
{"op":"mcm","clk":"4221448653","pt":1631435049899,"mc":[{"id":"1.187528277","rc":[{"trd":[[3.5,3173.05]],"batb":[[0,3.45,494.3]],"batl":[[0,3.5,173.76]],"ltp":3.5,"tv":40026.16,"id":19924831}],"tv":213884.46}]}
{"op":"mcm","clk":"4221449924","pt":1631435062558,"mc":[{"id":"1.187528277","rc":[{"trd":[[3.45,3060.19]],"batb":[[0,3.45,415.06]],"ltp":3.45,"tv":40184.64,"id":19924831}],"tv":214042.94}]}
{"op":"mcm","clk":"4221451911","pt":1631435083479,"mc":[{"id":"1.187528277","rc":[{"batb":[[0,3.45,408.9]],"ltp":3.45,"tv":40184.64,"id":19924831}]}]}
{"op":"mcm","clk":"4221452020","pt":1631435084691,"mc":[{"id":"1.187528277","rc":[{"trd":[[3.4,27172.2],[3.45,3860.77]],"batb":[[0,3.35,5069.43],[1,3.3,84.48],[2,3.25,6]],"ltp":3.4,"tv":52359.79,"id":19924831},{"trd":[[1.41,92771.71]],"batl":[[0,1.41,1038.26]],"ltp":1.41,"tv":178432.49,"id":2249229}],"tv":230792.29}]}
{"op":"mcm","clk":"4221452123","pt":1631435085625,"mc":[{"id":"1.187528277","rc":[{"batl":[[0,3.5,225.18],[1,3.55,63.69]],"ltp":3.4,"tv":52359.79,"id":19924831},{"batb":[[0,1.4,14711.48]],"ltp":1.41,"tv":178432.49,"id":2249229}]}]}
{"op":"mcm","clk":"4221452223","pt":1631435086515,"mc":[{"id":"1.187528277","rc":[{"trd":[[1.41,94847.83]],"batl":[[0,1.42,44600.54],[1,1.43,1465.81],[2,1.44,6947.57]],"ltp":1.41,"tv":180508.62,"id":2249229}],"tv":232868.42}]}
{"op":"mcm","clk":"4221452343","pt":1631435087610,"mc":[{"id":"1.187528277","rc":[{"batb":[[0,3.4,141.59],[1,3.35,5069.43],[2,3.3,84.48]],"batl":[[0,3.45,36.85],[1,3.5,225.18],[2,3.55,63.69]],"ltp":3.4,"tv":52359.79,"id":19924831},{"batb":[[0,1.4,18793.11]],"ltp":1.41,"tv":180508.62,"id":2249229}]}]}
{"op":"mcm","clk":"4221452455","pt":1631435088498,"mc":[{"id":"1.187528277","rc":[{"trd":[[3.4,27455.47]],"batb":[[0,3.4,141.68]],"batl":[[0,3.45,89.02],[2,3.55,12.99]],"ltp":3.4,"tv":52643.06,"id":19924831},{"trd":[[1.41,94848.03],[1.42,93917.52]],"batb":[[0,1.41,454.48],[1,1.4,14711.48],[2,1.39,19036.2]],"batl":[[0,1.42,19261.7]],"ltp":1.42,"tv":231185.4,"id":2249229}],"tv":283828.46}]}
{"op":"mcm","clk":"4221452549","pt":1631435089335,"mc":[{"id":"1.187528277","rc":[{"trd":[[1.42,94058.26]],"batl":[[0,1.42,19191.33]],"ltp":1.42,"tv":231326.14,"id":2249229}],"tv":283969.21}]}
{"op":"mcm","clk":"4221452638","pt":1631435090326,"mc":[{"id":"1.187528277","rc":[{"trd":[[1.42,94331.2]],"batl":[[0,1.42,19054.86]],"ltp":1.42,"tv":231599.08,"id":2249229}],"tv":284242.15}]}
{"op":"mcm","clk":"4221453061","pt":1631435094388,"mc":[{"id":"1.187528277","rc":[{"batb":[[0,1.41,1479.33]],"ltp":1.42,"tv":231599.08,"id":2249229}]}]}
{"op":"mcm","clk":"4221453220","pt":1631435096005,"mc":[{"id":"1.187528277","rc":[{"trd":[[3.4,27513.85]],"batb":[[0,3.4,112.49]],"ltp":3.4,"tv":52701.44,"id":19924831}],"tv":284300.53}]}
{"op":"mcm","clk":"4221453646","pt":1631435100434,"mc":[{"id":"1.187528277","rc":[{"trd":[[3.4,27688.99]],"batb":[[0,3.4,24.91]],"ltp":3.4,"tv":52876.59,"id":19924831}],"tv":284475.68}]}
{"op":"mcm","clk":"4221453832","pt":1631435102004,"mc":[{"id":"1.187528277","rc":[{"trd":[[3.4,27802.22]],"batb":[[0,3.35,5069.43],[1,3.3,84.48],[2,3.25,6]],"ltp":3.4,"tv":52989.81,"id":19924831}],"tv":284588.9}]}
{"op":"mcm","clk":"4221454417","pt":1631435108051,"mc":[{"id":"1.187528277","rc":[{"batb":[[0,3.4,49.59],[1,3.35,5069.43],[2,3.3,84.48]],"ltp":3.4,"tv":52989.81,"id":19924831},{"batb":[[0,1.41,1598.9]],"ltp":1.42,"tv":231599.08,"id":2249229}]}]}
{"op":"mcm","clk":"4221454571","pt":1631435109520,"mc":[{"id":"1.187528277","rc":[{"trd":[[3.4,27860.61]],"batb":[[0,3.4,20.39]],"ltp":3.4,"tv":53048.2,"id":19924831}],"tv":284647.29}]}
{"op":"mcm","clk":"4221454699","pt":1631435110815,"mc":[{"id":"1.187528277","rc":[{"trd":[[3.4,27901.39]],"batb":[[0,3.35,5069.43],[1,3.3,84.48],[2,3.25,6]],"batl":[[0,3.4,149.54],[1,3.45,89.02],[2,3.5,225.18]],"ltp":3.4,"tv":53088.99,"id":19924831}],"tv":284688.08}]}
{"op":"mcm","clk":"4221455125","pt":1631435115299,"mc":[{"id":"1.187528277","rc":[{"batl":[[0,3.45,89.02],[1,3.5,225.18],[2,3.55,12.99]],"ltp":3.4,"tv":53088.99,"id":19924831}]}]}
{"op":"mcm","clk":"4221458098","pt":1631435145726,"mc":[{"id":"1.187528277","rc":[{"batb":[[0,3.4,8.8],[1,3.35,5069.43],[2,3.3,84.48]],"ltp":3.4,"tv":53088.99,"id":19924831}]}]}
{"op":"mcm","clk":"4221458412","pt":1631435149423,"mc":[{"id":"1.187528277","rc":[{"batl":[[2,3.6,291.21]],"ltp":3.4,"tv":53088.99,"id":19924831},{"batb":[[2,1.39,18610.76]],"ltp":1.42,"tv":231599.08,"id":2249229}]}]}
{"op":"mcm","clk":"4221458518","pt":1631435150716,"mc":[{"id":"1.187528277","rc":[{"batb":[[0,1.41,1838.74],[1,1.4,15128.43]],"batl":[[0,1.42,19232.37]],"ltp":1.42,"tv":231599.08,"id":2249229}]}]}
{"op":"mcm","clk":"4221458583","pt":1631435151461,"mc":[{"id":"1.187528277","rc":[{"batb":[[1,3.35,5222.74]],"ltp":3.4,"tv":53088.99,"id":19924831},{"batl":[[1,1.43,1891.25]],"ltp":1.42,"tv":231599.08,"id":2249229}]}]}
{"op":"mcm","clk":"4221458615","pt":1631435151819,"mc":[{"id":"1.187528277","rc":[{"batl":[[0,3.45,200.4]],"ltp":3.4,"tv":53088.99,"id":19924831}]}]}
{"op":"mcm","clk":"4221463916","pt":1631435206473,"mc":[{"id":"1.187528277","rc":[{"batb":[[0,1.41,1874.71]],"ltp":1.42,"tv":231599.08,"id":2249229}]}]}
{"op":"mcm","clk":"4221463953","pt":1631435206840,"mc":[{"id":"1.187528277","rc":[{"batl":[[0,3.45,231.81]],"ltp":3.4,"tv":53088.99,"id":19924831}]}]}
{"op":"mcm","clk":"4221465516","pt":1631435222598,"mc":[{"id":"1.187528277","rc":[{"batb":[[0,1.41,2356.71]],"ltp":1.42,"tv":231599.08,"id":2249229}]}]}
{"op":"mcm","clk":"4221465964","pt":1631435227466,"mc":[{"id":"1.187528277","rc":[{"trd":[[3.4,27917.4]],"batb":[[0,3.35,5223.53],[1,3.3,84.48],[2,3.25,6]],"ltp":3.4,"tv":53104.99,"id":19924831}],"tv":284704.08}]}
{"op":"mcm","clk":"4221467189","pt":1631435240635,"mc":[{"id":"1.187528277","rc":[{"batb":[[0,3.4,11.35],[1,3.35,5222.74],[2,3.3,84.48]],"ltp":3.4,"tv":53104.99,"id":19924831}]}]}
{"op":"mcm","clk":"4221467448","pt":1631435243439,"mc":[{"id":"1.187528277","rc":[{"batb":[[0,3.4,211.35]],"ltp":3.4,"tv":53104.99,"id":19924831}]}]}
{"op":"mcm","clk":"4221467665","pt":1631435245627,"mc":[{"id":"1.187528277","rc":[{"trd":[[1.42,94485.2]],"batl":[[0,1.42,19155.37]],"ltp":1.42,"tv":231753.08,"id":2249229}],"tv":284858.08}]}
{"op":"mcm","clk":"4221468632","pt":1631435255366,"mc":[{"id":"1.187528277","rc":[{"batb":[[0,1.41,2434.4]],"ltp":1.42,"tv":231753.08,"id":2249229}]}]}
{"op":"mcm","clk":"4221468675","pt":1631435255728,"mc":[{"id":"1.187528277","rc":[{"batl":[[0,3.45,268.27]],"ltp":3.4,"tv":53104.99,"id":19924831}]}]}
{"op":"mcm","clk":"4221469489","pt":1631435264286,"mc":[{"id":"1.187528277","rc":[{"trd":[[1.42,94587.3]],"batl":[[0,1.42,19104.32]],"ltp":1.42,"tv":231855.19,"id":2249229}],"tv":284960.18}]}
{"op":"mcm","clk":"4221473767","pt":1631435307334,"mc":[{"id":"1.187528277","rc":[{"batb":[[0,1.41,2437.85]],"ltp":1.42,"tv":231855.19,"id":2249229}]}]}
{"op":"mcm","clk":"4221473815","pt":1631435307748,"mc":[{"id":"1.187528277","rc":[{"batl":[[0,3.45,278.5]],"ltp":3.4,"tv":53104.99,"id":19924831}]}]}
{"op":"mcm","clk":"4221477532","pt":1631435344614,"mc":[{"id":"1.187528277","rc":[{"trd":[[1.41,95002.25]],"batb":[[0,1.41,2360.74]],"batl":[[0,1.42,19182.72]],"ltp":1.41,"tv":232009.41,"id":2249229}],"tv":285114.4}]}
{"op":"mcm","clk":"4221478072","pt":1631435349853,"mc":[{"id":"1.187528277","rc":[{"trd":[[3.4,28017.4]],"batb":[[0,3.4,161.34]],"ltp":3.4,"tv":53205.0,"id":19924831}],"tv":285214.41}]}
{"op":"mcm","clk":"4221480414","pt":1631435372734,"mc":[{"id":"1.187528277","rc":[{"batl":[[1,3.5,137.23]],"ltp":3.4,"tv":53205.0,"id":19924831}]}]}
{"op":"mcm","clk":"4221480595","pt":1631435374720,"mc":[{"id":"1.187528277","rc":[{"batl":[[1,3.5,109.49]],"ltp":3.4,"tv":53205.0,"id":19924831}]}]}
{"op":"mcm","clk":"4221481045","pt":1631435379438,"mc":[{"id":"1.187528277","rc":[{"batb":[[0,1.41,6565.91]],"batl":[[0,1.42,19104.32]],"ltp":1.41,"tv":232009.41,"id":2249229}]}]}
{"op":"mcm","clk":"4221481456","pt":1631435383547,"mc":[{"id":"1.187528277","rc":[{"trd":[[3.4,28339.87]],"batb":[[0,3.35,5222.85],[1,3.3,84.48],[2,3.25,6]],"ltp":3.4,"tv":53527.46,"id":19924831}],"tv":285536.87}]}
{"op":"mcm","clk":"4221481843","pt":1631435387646,"mc":[{"id":"1.187528277","rc":[{"trd":[[3.4,28340.09]],"batb":[[0,3.35,5222.74]],"batl":[[0,3.4,137.97],[1,3.45,278.5],[2,3.5,109.49]],"ltp":3.4,"tv":53527.68,"id":19924831}],"tv":285537.09}]}
{"op":"mcm","clk":"4221482313","pt":1631435392434,"mc":[{"id":"1.187528277","rc":[{"batb":[[0,3.35,3628.49]],"ltp":3.4,"tv":53527.68,"id":19924831}]}]}
{"op":"mcm","clk":"4221483101","pt":1631435400857,"mc":[{"id":"1.187528277","rc":[{"batb":[[1,3.3,1540.63]],"ltp":3.4,"tv":53527.68,"id":19924831}]}]}
{"op":"mcm","clk":"4221484081","pt":1631435409963,"mc":[{"id":"1.187528277","rc":[{"batl":[[0,3.4,131.05]],"ltp":3.4,"tv":53527.68,"id":19924831}]}]}
{"op":"mcm","clk":"4221484718","pt":1631435416685,"mc":[{"id":"1.187528277","rc":[{"trd":[[1.41,95039.43]],"batb":[[0,1.41,6547.32]],"ltp":1.41,"tv":232046.59,"id":2249229}],"tv":285574.27}]}
{"op":"mcm","clk":"4221487161","pt":1631435440616,"mc":[{"id":"1.187528277","rc":[{"batb":[[1,3.3,1893.75]],"batl":[[0,3.4,150.7]],"ltp":3.4,"tv":53527.68,"id":19924831},{"batl":[[0,1.42,19111.15]],"ltp":1.41,"tv":232046.59,"id":2249229}]}]}
{"op":"mcm","clk":"4221487219","pt":1631435441029,"mc":[{"id":"1.187528277","rc":[{"batl":[[1,3.45,325.58]],"ltp":3.4,"tv":53527.68,"id":19924831}]}]}
{"op":"mcm","clk":"4221487542","pt":1631435444756,"mc":[{"id":"1.187528277","rc":[{"batl":[[0,3.4,157.99]],"ltp":3.4,"tv":53527.68,"id":19924831}]}]}
{"op":"mcm","clk":"4221489667","pt":1631435465959,"mc":[{"id":"1.187528277","rc":[{"batb":[[2,1.39,25999.23]],"ltp":1.41,"tv":232046.59,"id":2249229}]}]}
{"op":"mcm","clk":"4221490144","pt":1631435470181,"mc":[{"id":"1.187528277","rc":[{"batb":[[1,1.4,22516.9]],"ltp":1.41,"tv":232046.59,"id":2249229}]}]}
{"op":"mcm","clk":"4221491625","pt":1631435483258,"mc":[{"id":"1.187528277","rc":[{"batb":[[0,1.41,8871.09]],"ltp":1.41,"tv":232046.59,"id":2249229}]}]}
{"op":"mcm","clk":"4221492265","pt":1631435489540,"mc":[{"id":"1.187528277","rc":[{"batb":[[0,1.41,9353.09]],"ltp":1.41,"tv":232046.59,"id":2249229}]}]}
{"op":"mcm","clk":"4221495186","pt":1631435519789,"mc":[{"id":"1.187528277","rc":[{"batl":[[0,3.4,162.03]],"ltp":3.4,"tv":53527.68,"id":19924831}]}]}
{"op":"mcm","clk":"4221497431","pt":1631435542359,"mc":[{"id":"1.187528277","rc":[{"batb":[[0,1.41,13537.9]],"ltp":1.41,"tv":232046.59,"id":2249229}]}]}
{"op":"mcm","clk":"4221497765","pt":1631435546065,"mc":[{"id":"1.187528277","rc":[{"batl":[[0,3.4,214.97]],"ltp":3.4,"tv":53527.68,"id":19924831},{"trd":[[1.42,132809.59]],"batb":[[0,1.42,17138.86],[1,1.41,13537.9],[2,1.4,22516.9]],"batl":[[0,1.43,1891.25],[1,1.44,6947.57],[2,1.45,682.41]],"ltp":1.42,"tv":270268.88,"id":2249229}],"tv":323796.56}]}
{"op":"mcm","clk":"4221498337","pt":1631435552035,"mc":[{"id":"1.187528277","rc":[{"trd":[[3.35,6896.77]],"batb":[[0,3.35,3625.3]],"ltp":3.35,"tv":53534.06,"id":19924831}],"tv":323802.94}]}
{"op":"mcm","clk":"4221498516","pt":1631435554061,"mc":[{"id":"1.187528277","rc":[{"batb":[[0,3.35,2169.16]],"ltp":3.35,"tv":53534.06,"id":19924831}]}]}
{"op":"mcm","clk":"4221499041","pt":1631435559666,"mc":[{"id":"1.187528277","rc":[{"trd":[[3.35,7195.8]],"batb":[[0,3.35,2019.64]],"ltp":3.35,"tv":53833.09,"id":19924831},{"trd":[[1.43,21322.85]],"batl":[[0,1.43,1864.66]],"ltp":1.43,"tv":270322.06,"id":2249229}],"tv":324155.15}]}
{"op":"mcm","clk":"4221499098","pt":1631435560244,"mc":[{"id":"1.187528277","rc":[{"batb":[[0,3.35,1986.33],[1,3.3,1934.75]],"batl":[[2,3.5,76.01]],"ltp":3.35,"tv":53833.09,"id":19924831},{"batb":[[0,1.42,17265.62],[2,1.4,22524.98]],"batl":[[0,1.43,1777.54],[1,1.44,7084.21]],"ltp":1.43,"tv":270322.06,"id":2249229}]}]}
{"op":"mcm","clk":"4221499279","pt":1631435562153,"mc":[{"id":"1.187528277","rc":[{"trd":[[3.35,7307.22]],"batb":[[0,3.35,1930.62]],"ltp":3.35,"tv":53944.51,"id":19924831}],"tv":324266.57}]}
{"op":"mcm","clk":"4221499508","pt":1631435564382,"mc":[{"id":"1.187528277","rc":[{"trd":[[3.35,10519.83]],"batb":[[0,3.35,324.32]],"ltp":3.35,"tv":57157.12,"id":19924831}],"tv":327479.18}]}
{"op":"mcm","clk":"4221499576","pt":1631435565165,"mc":[{"id":"1.187528277","rc":[{"batb":[[2,1.4,22099.54]],"ltp":1.43,"tv":270322.06,"id":2249229}]}]}
{"op":"mcm","clk":"4221499708","pt":1631435566561,"mc":[{"id":"1.187528277","rc":[{"batb":[[1,1.41,13606.39]],"batl":[[1,1.44,7509.65]],"ltp":1.43,"tv":270322.06,"id":2249229}]}]}
{"op":"mcm","clk":"4221499785","pt":1631435567598,"mc":[{"id":"1.187528277","rc":[{"batb":[[0,3.35,283.4],[1,3.3,1894.19]],"ltp":3.35,"tv":57157.12,"id":19924831}]}]}
{"op":"mcm","clk":"4221499865","pt":1631435568388,"mc":[{"id":"1.187528277","rc":[{"batl":[[0,3.4,276.16],[1,3.45,363.66]],"ltp":3.35,"tv":57157.12,"id":19924831}]}]}
{"op":"mcm","clk":"4221500765","pt":1631435576696,"mc":[{"id":"1.187528277","rc":[{"trd":[[3.35,10695.73]],"batb":[[0,3.35,195.45]],"ltp":3.35,"tv":57333.02,"id":19924831}],"tv":327655.08}]}
{"op":"mcm","clk":"4221501944","pt":1631435588607,"mc":[{"id":"1.187528277","rc":[{"trd":[[3.35,10797.8]],"batb":[[0,3.35,144.41],[2,3.25,1749.91]],"ltp":3.35,"tv":57435.09,"id":19924831},{"batl":[[0,1.43,1897.11]],"ltp":1.43,"tv":270322.06,"id":2249229}],"tv":327757.15}]}
{"op":"mcm","clk":"4221503404","pt":1631435602652,"mc":[{"id":"1.187528277","rc":[{"batl":[[0,1.43,2108.19]],"ltp":1.43,"tv":270322.06,"id":2249229}]}]}
{"op":"mcm","clk":"4221506270","pt":1631435630607,"mc":[{"id":"1.187528277","rc":[{"batb":[[0,1.42,17351.02]],"batl":[[0,1.43,2049.73]],"ltp":1.43,"tv":270322.06,"id":2249229}]}]}
{"op":"mcm","clk":"4221506387","pt":1631435631598,"mc":[{"id":"1.187528277","rc":[{"batb":[[0,3.35,53.68]],"batl":[[1,3.45,344.69]],"ltp":3.35,"tv":57435.09,"id":19924831},{"trd":[[1.43,21376.03]],"batl":[[0,1.43,2023.14]],"ltp":1.43,"tv":270375.24,"id":2249229}],"tv":327810.33}]}
{"op":"mcm","clk":"4221506443","pt":1631435632117,"mc":[{"id":"1.187528277","rc":[{"trd":[[3.35,10905.16]],"batb":[[0,3.3,1894.19],[1,3.25,1749.91],[2,3.2,21]],"batl":[[0,3.35,143.75],[1,3.4,276.16],[2,3.45,274.63]],"ltp":3.35,"tv":57542.45,"id":19924831},{"batb":[[1,1.41,13574.44]],"ltp":1.43,"tv":270375.24,"id":2249229}],"tv":327917.69}]}
{"op":"mcm","clk":"4221510322","pt":1631435670365,"mc":[{"id":"1.187528277","rc":[{"trd":[[1.42,133075.48]],"batb":[[0,1.42,17218.08]],"ltp":1.42,"tv":270641.13,"id":2249229}],"tv":328183.58}]}
{"op":"mcm","clk":"4221510665","pt":1631435673685,"mc":[{"id":"1.187528277","rc":[{"batb":[[0,1.42,31678.35]],"ltp":1.42,"tv":270641.13,"id":2249229}]}]}
{"op":"mcm","clk":"4221510956","pt":1631435676767,"mc":[{"id":"1.187528277","rc":[{"batb":[[0,1.42,17218.08]],"ltp":1.42,"tv":270641.13,"id":2249229}]}]}
{"op":"mcm","clk":"4221511517","pt":1631435682384,"mc":[{"id":"1.187528277","rc":[{"batl":[[2,3.45,238.17]],"ltp":3.35,"tv":57542.45,"id":19924831}]}]}
{"op":"mcm","clk":"4221511617","pt":1631435683377,"mc":[{"id":"1.187528277","rc":[{"batl":[[2,3.45,196.53]],"ltp":3.35,"tv":57542.45,"id":19924831}]}]}
{"op":"mcm","clk":"4221511704","pt":1631435684377,"mc":[{"id":"1.187528277","rc":[{"batl":[[2,3.45,38.08]],"ltp":3.35,"tv":57542.45,"id":19924831}]}]}
{"op":"mcm","clk":"4221511775","pt":1631435685471,"mc":[{"id":"1.187528277","rc":[{"batl":[[2,3.5,76.01]],"ltp":3.35,"tv":57542.45,"id":19924831},{"batl":[[0,1.43,1959.63]],"ltp":1.42,"tv":270641.13,"id":2249229}]}]}
{"op":"mcm","clk":"4221511855","pt":1631435686406,"mc":[{"id":"1.187528277","rc":[{"batb":[[0,3.3,1882.06]],"ltp":3.35,"tv":57542.45,"id":19924831}]}]}
{"op":"mcm","clk":"4221511901","pt":1631435686879,"mc":[{"id":"1.187528277","rc":[{"batl":[[1,3.4,287.78]],"ltp":3.35,"tv":57542.45,"id":19924831}]}]}
{"op":"mcm","clk":"4221513471","pt":1631435700506,"mc":[{"id":"1.187528277","rc":[{"trd":[[1.42,135075.48]],"batb":[[0,1.42,16218.08]],"ltp":1.42,"tv":272641.13,"id":2249229}],"tv":330183.58}]}
{"op":"mcm","clk":"4221518051","pt":1631435744465,"mc":[{"id":"1.187528277","rc":[{"trd":[[3.3,10028.95]],"batb":[[0,3.3,1872.06]],"ltp":3.3,"tv":57562.45,"id":19924831}],"tv":330203.58}]}
{"op":"mcm","clk":"4221518186","pt":1631435745973,"mc":[{"id":"1.187528277","rc":[{"batl":[[1,3.4,323.93]],"ltp":3.3,"tv":57562.45,"id":19924831}]}]}
{"op":"mcm","clk":"4221519234","pt":1631435756912,"mc":[{"id":"1.187528277","rc":[{"trd":[[3.3,10038.95]],"batb":[[0,3.3,1867.06]],"ltp":3.3,"tv":57572.45,"id":19924831}],"tv":330213.58}]}
{"op":"mcm","clk":"4221519675","pt":1631435760847,"mc":[{"id":"1.187528277","rc":[{"trd":[[1.43,21429.21]],"batl":[[0,1.43,1933.04]],"ltp":1.43,"tv":272694.31,"id":2249229}],"tv":330266.76}]}
{"op":"mcm","clk":"4221521181","pt":1631435775411,"mc":[{"id":"1.187528277","rc":[{"batb":[[1,1.41,17844.66]],"ltp":1.43,"tv":272694.31,"id":2249229}]}]}
{"op":"mcm","clk":"4221521755","pt":1631435781638,"mc":[{"id":"1.187528277","rc":[{"trd":[[3.35,10953.5]],"batl":[[0,3.35,119.58]],"ltp":3.35,"tv":57620.79,"id":19924831}],"tv":330315.1}]}
{"op":"mcm","clk":"4221521769","pt":1631435781840,"mc":[{"id":"1.187528277","rc":[{"batb":[[0,3.3,1908.73]],"ltp":3.35,"tv":57620.79,"id":19924831}]}]}
{"op":"mcm","clk":"4221523010","pt":1631435793874,"mc":[{"id":"1.187528277","rc":[{"batl":[[0,1.43,1919.52]],"ltp":1.43,"tv":272694.31,"id":2249229}]}]}
{"op":"mcm","clk":"4221523264","pt":1631435796990,"mc":[{"id":"1.187528277","rc":[{"batb":[[0,1.42,30678.35]],"ltp":1.43,"tv":272694.31,"id":2249229}]}]}
{"op":"mcm","clk":"4221524003","pt":1631435804677,"mc":[{"id":"1.187528277","rc":[{"trd":[[3.3,10068.95]],"batb":[[0,3.3,1893.73]],"ltp":3.3,"tv":57650.79,"id":19924831}],"tv":330345.1}]}
{"op":"mcm","clk":"4221524052","pt":1631435805200,"mc":[{"id":"1.187528277","rc":[{"batb":[[0,3.3,1898.31]],"ltp":3.3,"tv":57650.79,"id":19924831},{"batb":[[0,1.42,30691.8],[2,1.4,22077.77]],"ltp":1.43,"tv":272694.31,"id":2249229}]}]}
{"op":"mcm","clk":"4221524686","pt":1631435811704,"mc":[{"id":"1.187528277","rc":[{"batl":[[0,3.35,948.58]],"ltp":3.3,"tv":57650.79,"id":19924831}]}]}
{"op":"mcm","clk":"4221526026","pt":1631435824600,"mc":[{"id":"1.187528277","rc":[{"batl":[[0,1.43,1299.29]],"ltp":1.43,"tv":272694.31,"id":2249229}]}]}
{"op":"mcm","clk":"4221528284","pt":1631435845649,"mc":[{"id":"1.187528277","rc":[{"batb":[[0,3.3,1856.64]],"ltp":3.3,"tv":57650.79,"id":19924831},{"trd":[[1.43,24027.78]],"batb":[[0,1.43,307.26],[1,1.42,30691.8],[2,1.41,17844.66]],"batl":[[0,1.44,7618.24],[1,1.45,682.41],[2,1.46,549.83]],"ltp":1.43,"tv":275292.88,"id":2249229}],"tv":332943.67}]}
{"op":"mcm","clk":"4221528448","pt":1631435847142,"mc":[{"id":"1.187528277","rc":[{"batb":[[0,1.42,30691.8],[1,1.41,17844.66],[2,1.4,22077.77]],"ltp":1.43,"tv":275292.88,"id":2249229}]}]}
{"op":"mcm","clk":"4221529330","pt":1631435855660,"mc":[{"id":"1.187528277","rc":[{"trd":[[3.35,11143.5]],"batl":[[0,3.35,907.32]],"ltp":3.35,"tv":57840.79,"id":19924831}],"tv":333133.67}]}
{"op":"mcm","clk":"4221529517","pt":1631435857673,"mc":[{"id":"1.187528277","rc":[{"batb":[[0,1.42,30776.13]],"ltp":1.43,"tv":275292.88,"id":2249229}]}]}
{"op":"mcm","clk":"4221529588","pt":1631435858363,"mc":[{"id":"1.187528277","rc":[{"batl":[[0,1.44,7917.93],[1,1.45,1107.85]],"ltp":1.43,"tv":275292.88,"id":2249229}]}]}
{"op":"mcm","clk":"4221529722","pt":1631435859664,"mc":[{"id":"1.187528277","rc":[{"batb":[[0,3.3,1793.62]],"batl":[[1,3.4,384.33]],"ltp":3.35,"tv":57840.79,"id":19924831}]}]}
{"op":"mcm","clk":"4221529989","pt":1631435862368,"mc":[{"id":"1.187528277","rc":[{"trd":[[3.35,11149.46]],"batl":[[0,3.35,904.34]],"ltp":3.35,"tv":57846.75,"id":19924831}],"tv":333139.63}]}
{"op":"mcm","clk":"4221531750","pt":1631435879692,"mc":[{"id":"1.187528277","rc":[{"batl":[[0,1.43,16.31],[1,1.44,7917.93],[2,1.45,1107.85]],"ltp":1.43,"tv":275292.88,"id":2249229}]}]}
{"op":"mcm","clk":"4221531860","pt":1631435880899,"mc":[{"id":"1.187528277","rc":[{"trd":[[3.35,11339.46]],"batl":[[0,3.35,809.34]],"ltp":3.35,"tv":58036.75,"id":19924831}],"tv":333329.63}]}
{"op":"mcm","clk":"4221534800","pt":1631435910366,"mc":[{"id":"1.187528277","rc":[{"batb":[[0,3.3,337.47]],"ltp":3.35,"tv":58036.75,"id":19924831}]}]}
{"op":"mcm","clk":"4221536785","pt":1631435931340,"mc":[{"id":"1.187528277","rc":[{"trd":[[1.43,24060.39]],"batb":[[0,1.43,63.95],[1,1.42,30776.13],[2,1.41,17844.66]],"batl":[[0,1.44,7917.93],[1,1.45,1107.85],[2,1.46,549.83]],"ltp":1.43,"tv":275325.49,"id":2249229}],"tv":333362.24}]}
{"op":"mcm","clk":"4221536898","pt":1631435932435,"mc":[{"id":"1.187528277","rc":[{"batb":[[0,1.42,30776.13],[1,1.41,17844.66],[2,1.4,22077.77]],"ltp":1.43,"tv":275325.49,"id":2249229}]}]}
{"op":"mcm","clk":"4221537189","pt":1631435935312,"mc":[{"id":"1.187528277","rc":[{"batb":[[1,1.41,17601.37]],"ltp":1.43,"tv":275325.49,"id":2249229}]}]}
{"op":"mcm","clk":"4221537288","pt":1631435936405,"mc":[{"id":"1.187528277","rc":[{"batb":[[1,1.41,17496.91]],"ltp":1.43,"tv":275325.49,"id":2249229}]}]}
{"op":"mcm","clk":"4221537368","pt":1631435936924,"mc":[{"id":"1.187528277","rc":[{"batb":[[1,1.41,17419.22]],"ltp":1.43,"tv":275325.49,"id":2249229}]}]}
{"op":"mcm","clk":"4221537476","pt":1631435937916,"mc":[{"id":"1.187528277","rc":[{"batb":[[0,3.3,150.68]],"ltp":3.35,"tv":58036.75,"id":19924831}]}]}
{"op":"mcm","clk":"4221539207","pt":1631435956868,"mc":[{"id":"1.187528277","rc":[{"batl":[[0,1.44,8344.95]],"ltp":1.43,"tv":275325.49,"id":2249229}]}]}
{"op":"mcm","clk":"4221541552","pt":1631435980241,"mc":[{"id":"1.187528277","rc":[{"trd":[[1.44,5528.4]],"batl":[[0,1.44,8318.37]],"ltp":1.44,"tv":275378.66,"id":2249229}],"tv":333415.42}]}
{"op":"mcm","clk":"4221542841","pt":1631435992717,"mc":[{"id":"1.187528277","rc":[{"batb":[[1,1.41,17844.66]],"ltp":1.44,"tv":275378.66,"id":2249229}]}]}
{"op":"mcm","clk":"4221542917","pt":1631435993449,"mc":[{"id":"1.187528277","rc":[{"batb":[[0,3.3,122.66]],"ltp":3.35,"tv":58036.75,"id":19924831}]}]}
{"op":"mcm","clk":"4221544773","pt":1631436010767,"mc":[{"id":"1.187528277","rc":[{"batb":[[0,1.43,400],[1,1.42,30776.13],[2,1.41,17844.66]],"ltp":1.44,"tv":275378.66,"id":2249229}]}]}
{"op":"mcm","clk":"4221545824","pt":1631436020707,"mc":[{"id":"1.187528277","rc":[{"batb":[[0,1.43,458.1]],"ltp":1.44,"tv":275378.66,"id":2249229}]}]}
{"op":"mcm","clk":"4221546496","pt":1631436027680,"mc":[{"id":"1.187528277","rc":[{"batl":[[1,3.4,253.28]],"ltp":3.35,"tv":58036.75,"id":19924831}]}]}
{"op":"mcm","clk":"4221546714","pt":1631436029700,"mc":[{"id":"1.187528277","rc":[{"batb":[[0,3.3,155.96]],"batl":[[1,3.4,245.99]],"ltp":3.35,"tv":58036.75,"id":19924831},{"batb":[[0,1.43,534.97]],"ltp":1.44,"tv":275378.66,"id":2249229}]}]}
{"op":"mcm","clk":"4221548689","pt":1631436047653,"mc":[{"id":"1.187528277","rc":[{"batb":[[1,3.25,1769.91]],"ltp":3.35,"tv":58036.75,"id":19924831},{"batb":[[2,1.41,17419.22]],"ltp":1.44,"tv":275378.66,"id":2249229}]}]}
{"op":"mcm","clk":"4221549028","pt":1631436050659,"mc":[{"id":"1.187528277","rc":[{"batb":[[0,3.3,305.96]],"ltp":3.35,"tv":58036.75,"id":19924831}]}]}
{"op":"mcm","clk":"4221549681","pt":1631436056854,"mc":[{"id":"1.187528277","rc":[{"batb":[[1,3.25,1919.91]],"ltp":3.35,"tv":58036.75,"id":19924831}]}]}
{"op":"mcm","clk":"4221551510","pt":1631436072667,"mc":[{"id":"1.187528277","rc":[{"batb":[[0,3.3,360.5]],"batl":[[0,3.35,755.61]],"ltp":3.35,"tv":58036.75,"id":19924831},{"trd":[[1.43,25130.32]],"batb":[[0,1.42,30776.13],[1,1.41,17419.22],[2,1.4,22077.77]],"batl":[[0,1.43,7765.04],[1,1.44,8318.37],[2,1.45,1107.85]],"ltp":1.43,"tv":276448.59,"id":2249229}],"tv":334485.34}]}
{"op":"mcm","clk":"4221552260","pt":1631436078807,"mc":[{"id":"1.187528277","rc":[{"batb":[[0,3.3,760.5]],"ltp":3.35,"tv":58036.75,"id":19924831}]}]}
{"op":"mcm","clk":"4221556412","pt":1631436113277,"mc":[{"id":"1.187528277","rc":[{"batl":[[2,1.45,682.41]],"ltp":1.43,"tv":276448.59,"id":2249229}]}]}
{"op":"mcm","clk":"4221556583","pt":1631436114586,"mc":[{"id":"1.187528277","rc":[{"batb":[[1,1.41,17844.66]],"batl":[[0,1.43,8178.97],[1,1.44,8018.68]],"ltp":1.43,"tv":276448.59,"id":2249229}]}]}
{"op":"mcm","clk":"4221556639","pt":1631436115062,"mc":[{"id":"1.187528277","rc":[{"batb":[[1,3.25,2345.35]],"ltp":3.35,"tv":58036.75,"id":19924831}]}]}
{"op":"mcm","clk":"4221556911","pt":1631436117376,"mc":[{"id":"1.187528277","rc":[{"batl":[[0,1.43,9117.14]],"ltp":1.43,"tv":276448.59,"id":2249229}]}]}
{"op":"mcm","clk":"4221558259","pt":1631436128092,"mc":[{"id":"1.187528277","rc":[{"batb":[[0,3.3,2504.41]],"ltp":3.35,"tv":58036.75,"id":19924831}]}]}
{"op":"mcm","clk":"4221559592","pt":1631436138346,"mc":[{"id":"1.187528277","rc":[{"trd":[[3.3,10091.8]],"batb":[[0,3.3,2492.98]],"ltp":3.3,"tv":58059.6,"id":19924831}],"tv":334508.2}]}
{"op":"mcm","clk":"4221559696","pt":1631436139240,"mc":[{"id":"1.187528277","rc":[{"batb":[[0,3.3,2488.41],[1,3.25,2360.18]],"ltp":3.3,"tv":58059.6,"id":19924831}]}]}
{"op":"mcm","clk":"4221560596","pt":1631436147123,"mc":[{"id":"1.187528277","rc":[{"batl":[[0,3.4,245.99],[1,3.5,76.01],[2,3.6,291.21]],"ltp":3.3,"tv":58059.6,"id":19924831}]}]}
{"op":"mcm","clk":"4221563897","pt":1631436176263,"mc":[{"id":"1.187528277","rc":[{"batl":[[2,1.45,4867.23]],"ltp":1.43,"tv":276448.59,"id":2249229}]}]}
{"op":"mcm","clk":"4221565695","pt":1631436190669,"mc":[{"id":"1.187528277","rc":[{"batl":[[0,3.4,333.94]],"ltp":3.3,"tv":58059.6,"id":19924831}]}]}
{"op":"mcm","clk":"4221566263","pt":1631436195405,"mc":[{"id":"1.187528277","rc":[{"batl":[[1,1.44,8099.81]],"ltp":1.43,"tv":276448.59,"id":2249229}]}]}
{"op":"mcm","clk":"4221566838","pt":1631436200547,"mc":[{"id":"1.187528277","rc":[{"batl":[[1,3.45,345.18],[2,3.5,76.01]],"ltp":3.3,"tv":58059.6,"id":19924831}]}]}
{"op":"mcm","clk":"4221567279","pt":1631436204443,"mc":[{"id":"1.187528277","rc":[{"batl":[[2,3.5,104.93]],"ltp":3.3,"tv":58059.6,"id":19924831}]}]}
{"op":"mcm","clk":"4221567546","pt":1631436207041,"mc":[{"id":"1.187528277","rc":[{"trd":[[1.43,29728.68]],"batl":[[0,1.43,6817.96]],"ltp":1.43,"tv":281046.95,"id":2249229}],"tv":339106.56}]}
{"op":"mcm","clk":"4221570099","pt":1631436228891,"mc":[{"id":"1.187528277","rc":[{"batl":[[0,3.35,51.04],[1,3.4,333.94],[2,3.45,345.18]],"ltp":3.3,"tv":58059.6,"id":19924831},{"batl":[[0,1.43,6937.52]],"ltp":1.43,"tv":281046.95,"id":2249229}]}]}
{"op":"mcm","clk":"4221572890","pt":1631436254114,"mc":[{"id":"1.187528277","rc":[{"trd":[[1.43,29769.48]],"batl":[[0,1.43,6917.12]],"ltp":1.43,"tv":281087.75,"id":2249229}],"tv":339147.36}]}
{"op":"mcm","clk":"4221576428","pt":1631436282507,"mc":[{"id":"1.187528277","rc":[{"batl":[[0,3.35,819.44]],"ltp":3.3,"tv":58059.6,"id":19924831}]}]}
{"op":"mcm","clk":"4221577093","pt":1631436287790,"mc":[{"id":"1.187528277","rc":[{"batb":[[2,1.4,22362.16]],"ltp":1.43,"tv":281087.75,"id":2249229}]}]}
{"op":"mcm","clk":"4221577281","pt":1631436289404,"mc":[{"id":"1.187528277","rc":[{"batl":[[1,1.44,9248.26]],"ltp":1.43,"tv":281087.75,"id":2249229}]}]}
{"op":"mcm","clk":"4221578929","pt":1631436301745,"mc":[{"id":"1.187528277","rc":[{"batl":[[2,3.5,104.93]],"ltp":3.3,"tv":58059.6,"id":19924831}]}]}
{"op":"mcm","clk":"4221579883","pt":1631436308652,"mc":[{"id":"1.187528277","rc":[{"batb":[[0,3.3,2540.76]],"ltp":3.3,"tv":58059.6,"id":19924831}]}]}
{"op":"mcm","clk":"4221579898","pt":1631436308757,"mc":[{"id":"1.187528277","rc":[{"batb":[[0,3.3,2488.41]],"ltp":3.3,"tv":58059.6,"id":19924831}]}]}
{"op":"mcm","clk":"4221581695","pt":1631436323857,"mc":[{"id":"1.187528277","rc":[{"trd":[[3.3,10184.44]],"batb":[[0,3.3,2442.09]],"ltp":3.3,"tv":58152.24,"id":19924831}],"tv":339240.0}]}
{"op":"mcm","clk":"4221586936","pt":1631436368428,"mc":[{"id":"1.187528277","rc":[{"batl":[[0,1.43,6970.3]],"ltp":1.43,"tv":281087.75,"id":2249229}]}]}
{"op":"mcm","clk":"4221588023","pt":1631436377182,"mc":[{"id":"1.187528277","rc":[{"batb":[[0,1.42,30779.99]],"ltp":1.43,"tv":281087.75,"id":2249229}]}]}
{"op":"mcm","clk":"4221589447","pt":1631436389683,"mc":[{"id":"1.187528277","rc":[{"batl":[[1,3.4,245.99]],"ltp":3.3,"tv":58152.24,"id":19924831}]}]}
{"op":"mcm","clk":"4221589705","pt":1631436391978,"mc":[{"id":"1.187528277","rc":[{"batl":[[0,1.43,6917.12],[2,1.45,4920.41]],"ltp":1.43,"tv":281087.75,"id":2249229}]}]}
{"op":"mcm","clk":"4221589995","pt":1631436394581,"mc":[{"id":"1.187528277","rc":[{"trd":[[1.43,29773.48]],"batl":[[0,1.43,6915.12]],"ltp":1.43,"tv":281091.75,"id":2249229}],"tv":339244.0}]}
{"op":"mcm","clk":"4221591979","pt":1631436411499,"mc":[{"id":"1.187528277","rc":[{"batb":[[0,3.3,2942.09]],"ltp":3.3,"tv":58152.24,"id":19924831}]}]}
{"op":"mcm","clk":"4221596963","pt":1631436457854,"mc":[{"id":"1.187528277","rc":[{"batl":[[0,1.43,6968.3],[2,1.45,4867.23]],"ltp":1.43,"tv":281091.75,"id":2249229}]}]}
{"op":"mcm","clk":"4221599195","pt":1631436477810,"mc":[{"id":"1.187528277","rc":[{"trd":[[3.3,10194.44]],"batb":[[0,3.3,2937.09]],"ltp":3.3,"tv":58162.24,"id":19924831}],"tv":339253.99}]}
{"op":"mcm","clk":"4221601737","pt":1631436501757,"mc":[{"id":"1.187528277","rc":[{"trd":[[1.42,135162.24]],"batb":[[0,1.42,30736.61]],"ltp":1.42,"tv":281178.51,"id":2249229}],"tv":339340.76}]}
{"op":"mcm","clk":"4221602515","pt":1631436509661,"mc":[{"id":"1.187528277","rc":[{"trd":[[1.42,135168.24]],"batb":[[0,1.42,30733.61]],"ltp":1.42,"tv":281184.51,"id":2249229}],"tv":339346.76}]}
{"op":"mcm","clk":"4221606849","pt":1631436550760,"mc":[{"id":"1.187528277","rc":[{"trd":[[3.35,11427.42]],"batl":[[0,3.35,775.45]],"ltp":3.35,"tv":58250.2,"id":19924831}],"tv":339434.72}]}
{"op":"mcm","clk":"4221608317","pt":1631436563484,"mc":[{"id":"1.187528277","rc":[{"batb":[[0,1.42,30739.51]],"ltp":1.42,"tv":281184.51,"id":2249229}]}]}
{"op":"mcm","clk":"4221608395","pt":1631436564219,"mc":[{"id":"1.187528277","rc":[{"batl":[[1,3.4,249.96]],"ltp":3.35,"tv":58250.2,"id":19924831}]}]}
{"op":"mcm","clk":"4221610162","pt":1631436580935,"mc":[{"id":"1.187528277","rc":[{"trd":[[1.42,135188.24]],"batb":[[0,1.42,30729.51]],"ltp":1.42,"tv":281204.51,"id":2249229}],"tv":339454.72}]}
{"op":"mcm","clk":"4221617644","pt":1631436651872,"mc":[{"id":"1.187528277","rc":[{"batb":[[0,3.3,2940.45]],"ltp":3.35,"tv":58250.2,"id":19924831}]}]}
{"op":"mcm","clk":"4221619824","pt":1631436672517,"mc":[{"id":"1.187528277","rc":[{"trd":[[1.42,135198.88]],"batb":[[0,1.42,30724.19]],"ltp":1.42,"tv":281215.15,"id":2249229}],"tv":339465.36}]}
{"op":"mcm","clk":"4221627437","pt":1631436744317,"mc":[{"id":"1.187528277","rc":[{"trd":[[3.35,11527]],"batl":[[0,3.35,725.67]],"ltp":3.35,"tv":58349.77,"id":19924831}],"tv":339564.93}]}
{"op":"mcm","clk":"4221632735","pt":1631436793399,"mc":[{"id":"1.187528277","rc":[{"trd":[[3.35,11576.78]],"batl":[[0,3.35,700.78]],"ltp":3.35,"tv":58399.56,"id":19924831}],"tv":339614.72}]}
{"op":"mcm","clk":"4221634894","pt":1631436815242,"mc":[{"id":"1.187528277","rc":[{"trd":[[1.42,138318.88]],"batb":[[0,1.42,29164.19]],"ltp":1.42,"tv":284335.15,"id":2249229}],"tv":342734.72}]}
{"op":"mcm","clk":"4221641972","pt":1631436883904,"mc":[{"id":"1.187528277","rc":[{"trd":[[1.43,30273.48]],"batl":[[0,1.43,6718.3]],"ltp":1.43,"tv":284835.15,"id":2249229}],"tv":343234.72}]}
{"op":"mcm","clk":"4221642671","pt":1631436890890,"mc":[{"id":"1.187528277","rc":[{"batl":[[1,1.44,9498.26]],"ltp":1.43,"tv":284835.15,"id":2249229}]}]}
{"op":"mcm","clk":"4221643470","pt":1631436899618,"mc":[{"id":"1.187528277","rc":[{"trd":[[3.3,10247.62]],"batb":[[0,3.3,2913.86]],"ltp":3.3,"tv":58452.74,"id":19924831}],"tv":343287.9}]}
{"op":"mcm","clk":"4221646941","pt":1631436934384,"mc":[{"id":"1.187528277","rc":[{"trd":[[1.43,30277.48]],"batl":[[0,1.43,6716.3]],"ltp":1.43,"tv":284839.15,"id":2249229}],"tv":343291.9}]}
{"op":"mcm","clk":"4221649434","pt":1631436960324,"mc":[{"id":"1.187528277","rc":[{"batb":[[0,3.3,2920.69]],"batl":[[2,3.45,35.02]],"ltp":3.3,"tv":58452.74,"id":19924831},{"batl":[[1,1.44,9448.73]],"ltp":1.43,"tv":284839.15,"id":2249229}]}]}
{"op":"mcm","clk":"4221650025","pt":1631436966437,"mc":[{"id":"1.187528277","rc":[{"batb":[[0,1.42,29181.14]],"batl":[[0,1.43,6690.21]],"ltp":1.43,"tv":284839.15,"id":2249229}]}]}
{"op":"mcm","clk":"4221650109","pt":1631436967225,"mc":[{"id":"1.187528277","rc":[{"batl":[[1,3.4,256.85]],"ltp":3.3,"tv":58452.74,"id":19924831}]}]}
{"op":"mcm","clk":"4221661810","pt":1631437089589,"mc":[{"id":"1.187528277","rc":[{"batb":[[0,3.3,3420.69]],"ltp":3.3,"tv":58452.74,"id":19924831}]}]}
{"op":"mcm","clk":"4221662465","pt":1631437095717,"mc":[{"id":"1.187528277","rc":[{"batl":[[0,1.43,6052.05]],"ltp":1.43,"tv":284839.15,"id":2249229}]}]}
{"op":"mcm","clk":"4221670061","pt":1631437175661,"mc":[{"id":"1.187528277","rc":[{"trd":[[3.35,11586.76]],"batl":[[0,3.35,695.79]],"ltp":3.35,"tv":58462.72,"id":19924831}],"tv":343301.88}]}
{"op":"mcm","clk":"4221671031","pt":1631437184679,"mc":[{"id":"1.187528277","rc":[{"trd":[[3.35,11621.94]],"batl":[[0,3.35,678.2]],"ltp":3.35,"tv":58497.9,"id":19924831}],"tv":343337.06}]}
{"op":"mcm","clk":"4221683100","pt":1631437286227,"mc":[{"id":"1.187528277","rc":[{"trd":[[1.43,30331.42]],"batl":[[0,1.43,6025.08]],"ltp":1.43,"tv":284893.1,"id":2249229}],"tv":343391.0}]}
{"op":"mcm","clk":"4221683314","pt":1631437287706,"mc":[{"id":"1.187528277","rc":[{"batb":[[0,3.3,4219.69],[1,3.25,3159.18],[2,3.2,820]],"batl":[[0,3.35,1311.57],[1,3.4,889.85],[2,3.45,668.02]],"ltp":3.35,"tv":58497.9,"id":19924831},{"batb":[[0,1.42,31037.14],[1,1.41,19700.66],[2,1.4,24218.16]],"batl":[[1,1.44,10924.73]],"ltp":1.43,"tv":284893.1,"id":2249229}]}]}
{"op":"mcm","clk":"4221698956","pt":1631437424701,"mc":[{"id":"1.187528277","rc":[{"trd":[[1.42,138338.88]],"batb":[[0,1.42,31027.14]],"ltp":1.42,"tv":284913.1,"id":2249229}],"tv":343411.0}]}
{"op":"mcm","clk":"4221700051","pt":1631437434783,"mc":[{"id":"1.187528277","rc":[{"trd":[[1.42,139338.88]],"batb":[[0,1.42,30527.14]],"ltp":1.42,"tv":285913.1,"id":2249229}],"tv":344411.0}]}
{"op":"mcm","clk":"4221710561","pt":1631437529899,"mc":[{"id":"1.187528277","rc":[{"trd":[[1.43,30383.71]],"batl":[[0,1.43,5998.94]],"ltp":1.43,"tv":285965.38,"id":2249229}],"tv":344463.28}]}
{"op":"mcm","clk":"4221711400","pt":1631437537028,"mc":[{"id":"1.187528277","rc":[{"trd":[[1.42,139657.95]],"batb":[[0,1.42,30367.61]],"ltp":1.42,"tv":286284.45,"id":2249229}],"tv":344782.35}]}
{"op":"mcm","clk":"4221716107","pt":1631437581970,"mc":[{"id":"1.187528277","rc":[{"trd":[[3.35,11628.76]],"batl":[[0,3.35,1308.16]],"ltp":3.35,"tv":58504.72,"id":19924831}],"tv":344789.17}]}
{"op":"mcm","clk":"4221726345","pt":1631437677176,"mc":[{"id":"1.187528277","rc":[{"trd":[[3.35,11716.72]],"batl":[[0,3.35,1264.18]],"ltp":3.35,"tv":58592.69,"id":19924831}],"tv":344877.14}]}
{"op":"mcm","clk":"4221741006","pt":1631437818701,"mc":[{"id":"1.187528277","rc":[{"batl":[[1,3.4,853.7]],"ltp":3.35,"tv":58592.69,"id":19924831}]}]}
{"op":"mcm","clk":"4221741019","pt":1631437818805,"mc":[{"id":"1.187528277","rc":[{"batl":[[2,3.45,704.17]],"ltp":3.35,"tv":58592.69,"id":19924831}]}]}
{"op":"mcm","clk":"4221745280","pt":1631437856485,"mc":[{"id":"1.187528277","rc":[{"trd":[[1.43,30542.49]],"batl":[[0,1.43,5919.55]],"ltp":1.43,"tv":286443.23,"id":2249229}],"tv":345035.93}]}
{"op":"mcm","clk":"4221751452","pt":1631437913547,"mc":[{"id":"1.187528277","rc":[{"trd":[[3.3,10287.62]],"batb":[[0,3.3,4199.69]],"ltp":3.3,"tv":58632.69,"id":19924831}],"tv":345075.93}]}
{"op":"mcm","clk":"4221752030","pt":1631437919365,"mc":[{"id":"1.187528277","rc":[{"batb":[[0,3.3,4184.12]],"batl":[[2,3.45,669.15]],"ltp":3.3,"tv":58632.69,"id":19924831},{"batb":[[2,1.4,24081.52]],"batl":[[1,1.44,10837.62]],"ltp":1.43,"tv":286443.23,"id":2249229}]}]}
{"op":"mcm","clk":"4221752100","pt":1631437919986,"mc":[{"id":"1.187528277","rc":[{"batb":[[1,3.25,3202.73]],"batl":[[2,3.45,675.98]],"ltp":3.3,"tv":58632.69,"id":19924831},{"batb":[[1,1.41,19784.36]],"ltp":1.43,"tv":286443.23,"id":2249229}]}]}
{"op":"mcm","clk":"4221755557","pt":1631437949629,"mc":[{"id":"1.187528277","rc":[{"batl":[[2,3.45,711]],"ltp":3.3,"tv":58632.69,"id":19924831},{"batl":[[1,1.44,10914.48]],"ltp":1.43,"tv":286443.23,"id":2249229}]}]}
{"op":"mcm","clk":"4221760627","pt":1631437995628,"mc":[{"id":"1.187528277","rc":[{"trd":[[3.3,10307.62]],"batb":[[0,3.3,4174.12]],"ltp":3.3,"tv":58652.69,"id":19924831}],"tv":345095.93}]}
{"op":"mcm","clk":"4221761069","pt":1631437999531,"mc":[{"id":"1.187528277","rc":[{"trd":[[1.43,30768.08]],"batl":[[0,1.43,5806.76]],"ltp":1.43,"tv":286668.82,"id":2249229}],"tv":345321.51}]}
{"op":"mcm","clk":"4221761117","pt":1631437999803,"mc":[{"id":"1.187528277","rc":[{"trd":[[1.43,30790.3]],"batl":[[0,1.43,5795.65]],"ltp":1.43,"tv":286691.04,"id":2249229}],"tv":345343.73}]}
{"op":"mcm","clk":"4221761843","pt":1631438006386,"mc":[{"id":"1.187528277","rc":[{"trd":[[1.43,31590.3]],"batl":[[0,1.43,5395.65]],"ltp":1.43,"tv":287491.04,"id":2249229}],"tv":346143.73}]}
{"op":"mcm","clk":"4221762492","pt":1631438011461,"mc":[{"id":"1.187528277","rc":[{"trd":[[3.35,11722.11]],"batl":[[0,3.35,1261.49]],"ltp":3.35,"tv":58658.07,"id":19924831}],"tv":346149.11}]}
{"op":"mcm","clk":"4221764434","pt":1631438028674,"mc":[{"id":"1.187528277","rc":[{"trd":[[1.43,31643.48]],"batl":[[0,1.43,5369.06]],"ltp":1.43,"tv":287544.22,"id":2249229}],"tv":346202.29}]}
{"op":"mcm","clk":"4221765763","pt":1631438040538,"mc":[{"id":"1.187528277","rc":[{"batl":[[1,1.44,10837.62],[2,1.45,4990.21]],"ltp":1.43,"tv":287544.22,"id":2249229}]}]}
{"op":"mcm","clk":"4221768598","pt":1631438062528,"mc":[{"id":"1.187528277","rc":[{"trd":[[1.42,139663.27]],"batb":[[0,1.42,30364.95]],"ltp":1.42,"tv":287549.54,"id":2249229}],"tv":346207.61}]}
{"op":"mcm","clk":"4221769565","pt":1631438069877,"mc":[{"id":"1.187528277","rc":[{"batl":[[0,1.43,7077.15]],"ltp":1.42,"tv":287549.54,"id":2249229}]}]}
{"op":"mcm","clk":"4221776546","pt":1631438125055,"mc":[{"id":"1.187528277","rc":[{"batb":[[0,1.42,30630.95]],"ltp":1.42,"tv":287549.54,"id":2249229}]}]}
{"op":"mcm","clk":"4221777871","pt":1631438135740,"mc":[{"id":"1.187528277","rc":[{"batl":[[1,1.44,11103.62]],"ltp":1.42,"tv":287549.54,"id":2249229}]}]}
{"op":"mcm","clk":"4221784540","pt":1631438190221,"mc":[{"id":"1.187528277","rc":[{"trd":[[1.43,31822.52]],"batl":[[0,1.43,6987.63]],"ltp":1.43,"tv":287728.58,"id":2249229}],"tv":346386.65}]}
{"op":"mcm","clk":"4221784619","pt":1631438190847,"mc":[{"id":"1.187528277","rc":[{"trd":[[1.43,31840.14]],"batl":[[0,1.43,6978.82]],"ltp":1.43,"tv":287746.2,"id":2249229}],"tv":346404.28}]}
{"op":"mcm","clk":"4221786223","pt":1631438204738,"mc":[{"id":"1.187528277","rc":[{"trd":[[3.35,11782.11]],"batl":[[0,3.35,1231.49]],"ltp":3.35,"tv":58718.07,"id":19924831}],"tv":346464.28}]}
{"op":"mcm","clk":"4221790983","pt":1631438243733,"mc":[{"id":"1.187528277","rc":[{"trd":[[1.43,31855.36]],"batl":[[0,1.43,6971.21]],"ltp":1.43,"tv":287761.42,"id":2249229}],"tv":346479.49}]}
{"op":"mcm","clk":"4221792497","pt":1631438256677,"mc":[{"id":"1.187528277","rc":[{"trd":[[3.3,10382.08]],"batb":[[0,3.3,4136.9]],"ltp":3.3,"tv":58792.52,"id":19924831}],"tv":346553.95}]}
{"op":"mcm","clk":"4221794270","pt":1631438270677,"mc":[{"id":"1.187528277","rc":[{"trd":[[3.35,14245.09]],"batb":[[0,3.35,3768.51],[1,3.3,4438.9],[2,3.25,3391.73]],"batl":[[0,3.4,876.7],[1,3.45,750],[2,3.5,747.52]],"ltp":3.35,"tv":61255.5,"id":19924831},{"batb":[[0,1.42,30729.95],[1,1.41,19921.36],[2,1.4,24255.52]],"batl":[[0,1.43,9112.21],[1,1.44,11507.62],[2,1.45,6609.21]],"ltp":1.43,"tv":287761.42,"id":2249229}],"tv":349016.93}]}
{"op":"mcm","clk":"4221796007","pt":1631438284834,"mc":[{"id":"1.187528277","rc":[{"batl":[[0,3.4,964.65]],"ltp":3.35,"tv":61255.5,"id":19924831}]}]}
{"op":"mcm","clk":"4221796732","pt":1631438291005,"mc":[{"id":"1.187528277","rc":[{"trd":[[1.42,139801.53]],"batb":[[0,1.42,30660.82]],"ltp":1.42,"tv":287899.68,"id":2249229}],"tv":349155.19}]}
{"op":"mcm","clk":"4221797584","pt":1631438298673,"mc":[{"id":"1.187528277","rc":[{"batl":[[0,3.4,876.7]],"ltp":3.35,"tv":61255.5,"id":19924831}]}]}
{"op":"mcm","clk":"4221800826","pt":1631438326687,"mc":[{"id":"1.187528277","rc":[{"trd":[[3.35,14271.09]],"batb":[[0,3.35,3755.51]],"ltp":3.35,"tv":61281.5,"id":19924831}],"tv":349181.19}]}
{"op":"mcm","clk":"4221801544","pt":1631438332685,"mc":[{"id":"1.187528277","rc":[{"batb":[[2,3.25,2966.29]],"ltp":3.35,"tv":61281.5,"id":19924831},{"batb":[[0,1.42,30664.71]],"ltp":1.42,"tv":287899.68,"id":2249229}]}]}
{"op":"mcm","clk":"4221801630","pt":1631438333470,"mc":[{"id":"1.187528277","rc":[{"batb":[[0,3.35,3783.96],[1,3.3,4665.69]],"ltp":3.35,"tv":61281.5,"id":19924831}]}]}
{"op":"mcm","clk":"4221801679","pt":1631438333880,"mc":[{"id":"1.187528277","rc":[{"batl":[[1,3.45,1105.15]],"ltp":3.35,"tv":61281.5,"id":19924831}]}]}
{"op":"mcm","clk":"4221803204","pt":1631438347599,"mc":[{"id":"1.187528277","rc":[{"trd":[[1.43,31908.54]],"batl":[[0,1.43,9085.62]],"ltp":1.43,"tv":287952.86,"id":2249229}],"tv":349234.37}]}
{"op":"mcm","clk":"4221821607","pt":1631438495868,"mc":[{"id":"1.187528277","rc":[{"trd":[[1.42,139804.95]],"batb":[[0,1.42,30663]],"ltp":1.42,"tv":287956.28,"id":2249229}],"tv":349237.79}]}
{"op":"mcm","clk":"4221838750","pt":1631438641742,"mc":[{"id":"1.187528277","rc":[{"trd":[[3.35,14272.09]],"batb":[[0,3.35,3783.46]],"ltp":3.35,"tv":61282.5,"id":19924831}],"tv":349238.79}]}
{"op":"mcm","clk":"4221841221","pt":1631438661916,"mc":[{"id":"1.187528277","rc":[{"batb":[[1,3.3,4165.69]],"ltp":3.35,"tv":61282.5,"id":19924831}]}]}
{"op":"mcm","clk":"4221841501","pt":1631438664039,"mc":[{"id":"1.187528277","rc":[{"batb":[[1,3.3,3665.69]],"ltp":3.35,"tv":61282.5,"id":19924831}]}]}
{"op":"mcm","clk":"4221844573","pt":1631438691003,"mc":[{"id":"1.187528277","rc":[{"batl":[[1,1.44,11585.33],[2,1.45,6486.23]],"ltp":1.42,"tv":287956.28,"id":2249229}]}]}
{"op":"mcm","clk":"4221860276","pt":1631438831672,"mc":[{"id":"1.187528277","rc":[{"batl":[[2,3.5,715.92]],"ltp":3.35,"tv":61282.5,"id":19924831}]}]}
{"op":"mcm","clk":"4221861227","pt":1631438839906,"mc":[{"id":"1.187528277","rc":[{"batl":[[0,3.4,911.72]],"ltp":3.35,"tv":61282.5,"id":19924831}]}]}
{"op":"mcm","clk":"4221868289","pt":1631438903190,"mc":[{"id":"1.187528277","rc":[{"batl":[[0,3.4,1200.92]],"ltp":3.35,"tv":61282.5,"id":19924831}]}]}
{"op":"mcm","clk":"4221872006","pt":1631438937981,"mc":[{"id":"1.187528277","rc":[{"trd":[[1.42,139807.71]],"batb":[[0,1.42,30661.62]],"ltp":1.42,"tv":287959.04,"id":2249229}],"tv":349241.55}]}
{"op":"mcm","clk":"4221872430","pt":1631438942250,"mc":[{"id":"1.187528277","rc":[{"batb":[[0,1.42,31006.15]],"ltp":1.42,"tv":287959.04,"id":2249229}]}]}
{"op":"mcm","clk":"4221875080","pt":1631438969218,"mc":[{"id":"1.187528277","rc":[{"trd":[[3.35,14322.09]],"batb":[[0,3.35,3758.46]],"ltp":3.35,"tv":61332.5,"id":19924831}],"tv":349291.55}]}
{"op":"mcm","clk":"4221878385","pt":1631439001332,"mc":[{"id":"1.187528277","rc":[{"trd":[[1.42,139819.19]],"batb":[[0,1.42,31000.41]],"ltp":1.42,"tv":287970.52,"id":2249229}],"tv":349303.03}]}
{"op":"mcm","clk":"4221878841","pt":1631439004935,"mc":[{"id":"1.187528277","rc":[{"batl":[[0,1.43,9185.62]],"ltp":1.42,"tv":287970.52,"id":2249229}]}]}
{"op":"mcm","clk":"4221880178","pt":1631439017585,"mc":[{"id":"1.187528277","rc":[{"trd":[[3.35,14392.12]],"batb":[[0,3.35,3723.44]],"batl":[[0,3.4,1165.91]],"ltp":3.35,"tv":61402.54,"id":19924831}],"tv":349373.06}]}
{"op":"mcm","clk":"4221880784","pt":1631439023671,"mc":[{"id":"1.187528277","rc":[{"trd":[[1.42,139826.09]],"batb":[[0,1.42,30996.96]],"ltp":1.42,"tv":287977.42,"id":2249229}],"tv":349379.97}]}
{"op":"mcm","clk":"4221885190","pt":1631439062534,"mc":[{"id":"1.187528277","rc":[{"batb":[[0,1.42,31196.96]],"ltp":1.42,"tv":287977.42,"id":2249229}]}]}
{"op":"mcm","clk":"4221899580","pt":1631439194655,"mc":[{"id":"1.187528277","rc":[{"trd":[[1.43,32227.61]],"batl":[[0,1.43,9026.09]],"ltp":1.43,"tv":288296.49,"id":2249229}],"tv":349699.04}]}
{"op":"mcm","clk":"4221900666","pt":1631439204168,"mc":[{"id":"1.187528277","rc":[{"trd":[[1.43,32231.03]],"batl":[[0,1.43,9024.38]],"ltp":1.43,"tv":288299.91,"id":2249229}],"tv":349702.45}]}
{"op":"mcm","clk":"4221905765","pt":1631439246425,"mc":[{"id":"1.187528277","rc":[{"trd":[[3.4,28350.72]],"batl":[[0,3.4,1160.59]],"ltp":3.4,"tv":61413.17,"id":19924831}],"tv":349713.09}]}
{"op":"mcm","clk":"4221909764","pt":1631439278578,"mc":[{"id":"1.187528277","rc":[{"batb":[[0,3.35,3726.14],[1,3.3,3668.45]],"ltp":3.4,"tv":61413.17,"id":19924831}]}]}
{"op":"mcm","clk":"4221921693","pt":1631439373233,"mc":[{"id":"1.187528277","rc":[{"batb":[[2,1.4,25963.6]],"ltp":1.43,"tv":288299.91,"id":2249229}]}]}
{"op":"mcm","clk":"4221929741","pt":1631439436920,"mc":[{"id":"1.187528277","rc":[{"batb":[[1,1.41,21629.44]],"ltp":1.43,"tv":288299.91,"id":2249229}]}]}
{"op":"mcm","clk":"4221930944","pt":1631439445405,"mc":[{"id":"1.187528277","rc":[{"batb":[[0,1.42,32051.01]],"ltp":1.43,"tv":288299.91,"id":2249229}]}]}
{"op":"mcm","clk":"4221935780","pt":1631439484598,"mc":[{"id":"1.187528277","rc":[{"batl":[[1,1.44,11319.33]],"ltp":1.43,"tv":288299.91,"id":2249229}]}]}
{"op":"mcm","clk":"4221935984","pt":1631439486078,"mc":[{"id":"1.187528277","rc":[{"trd":[[1.43,32369.03]],"batl":[[0,1.43,8955.38]],"ltp":1.43,"tv":288437.91,"id":2249229}],"tv":349851.09}]}
{"op":"mcm","clk":"4221936900","pt":1631439492911,"mc":[{"id":"1.187528277","rc":[{"batl":[[0,1.43,8972.9]],"ltp":1.43,"tv":288437.91,"id":2249229}]}]}
{"op":"mcm","clk":"4221937290","pt":1631439495695,"mc":[{"id":"1.187528277","rc":[{"batl":[[1,1.44,11069.33]],"ltp":1.43,"tv":288437.91,"id":2249229}]}]}
{"op":"mcm","clk":"4221943033","pt":1631439541954,"mc":[{"id":"1.187528277","rc":[{"trd":[[3.35,14397.52]],"batb":[[0,3.35,3723.44]],"ltp":3.35,"tv":61418.58,"id":19924831}],"tv":349856.49}]}
{"op":"mcm","clk":"4221950526","pt":1631439600232,"mc":[{"id":"1.187528277","rc":[{"batl":[[0,1.43,12019.68]],"ltp":1.43,"tv":288437.91,"id":2249229}]}]}
{"op":"mcm","clk":"4221960570","pt":1631439679049,"mc":[{"id":"1.187528277","rc":[{"trd":[[3.35,14447.52]],"batb":[[0,3.35,3698.44]],"ltp":3.35,"tv":61468.58,"id":19924831}],"tv":349906.49}]}
{"op":"mcm","clk":"4221968367","pt":1631439738737,"mc":[{"id":"1.187528277","rc":[{"trd":[[1.43,33448.02]],"batl":[[0,1.43,11480.2]],"ltp":1.43,"tv":289516.9,"id":2249229}],"tv":350985.48}]}
{"op":"mcm","clk":"4221976862","pt":1631439801478,"mc":[{"id":"1.187528277","rc":[{"trd":[[3.35,14515.66]],"batb":[[0,3.35,3664.37]],"ltp":3.35,"tv":61536.72,"id":19924831},{"batb":[[2,1.4,25878.6]],"batl":[[1,1.44,11059.33]],"ltp":1.43,"tv":289516.9,"id":2249229}],"tv":351053.62}]}
{"op":"mcm","clk":"4221977131","pt":1631439803299,"mc":[{"id":"1.187528277","rc":[{"trd":[[1.43,33448.04]],"batl":[[0,1.43,11480.19]],"ltp":1.43,"tv":289516.92,"id":2249229}],"tv":351053.64}]}
{"op":"mcm","clk":"4221978416","pt":1631439812209,"mc":[{"id":"1.187528277","rc":[{"batl":[[0,1.43,11530.19]],"ltp":1.43,"tv":289516.92,"id":2249229}]}]}
{"op":"mcm","clk":"4221979086","pt":1631439817591,"mc":[{"id":"1.187528277","rc":[{"batb":[[0,1.42,32101.01]],"ltp":1.43,"tv":289516.92,"id":2249229}]}]}
{"op":"mcm","clk":"4221981124","pt":1631439833215,"mc":[{"id":"1.187528277","rc":[{"trd":[[1.42,139866.09]],"batb":[[0,1.42,32081.01]],"ltp":1.42,"tv":289556.92,"id":2249229}],"tv":351093.64}]}
{"op":"mcm","clk":"4221982158","pt":1631439840837,"mc":[{"id":"1.187528277","rc":[{"batb":[[1,1.41,21649.44]],"ltp":1.42,"tv":289556.92,"id":2249229}]}]}
{"op":"mcm","clk":"4221982938","pt":1631439846946,"mc":[{"id":"1.187528277","rc":[{"batl":[[0,1.43,11550.19]],"ltp":1.42,"tv":289556.92,"id":2249229}]}]}
{"op":"mcm","clk":"4221983487","pt":1631439850856,"mc":[{"id":"1.187528277","rc":[{"batb":[[0,1.42,32101.01]],"ltp":1.42,"tv":289556.92,"id":2249229}]}]}
{"op":"mcm","clk":"4221984235","pt":1631439856347,"mc":[{"id":"1.187528277","rc":[{"trd":[[1.42,139906.09]],"batb":[[0,1.42,32081.01]],"ltp":1.42,"tv":289596.92,"id":2249229}],"tv":351133.64}]}
{"op":"mcm","clk":"4221985116","pt":1631439863184,"mc":[{"id":"1.187528277","rc":[{"trd":[[1.43,33469.31]],"batb":[[1,1.41,21669.44]],"batl":[[0,1.43,11539.55]],"ltp":1.43,"tv":289618.2,"id":2249229}],"tv":351154.92}]}
{"op":"mcm","clk":"4221990847","pt":1631439904013,"mc":[{"id":"1.187528277","rc":[{"trd":[[3.35,14521.66]],"batb":[[0,3.35,3661.37]],"ltp":3.35,"tv":61542.72,"id":19924831}],"tv":351160.92}]}
{"op":"mcm","clk":"4221998064","pt":1631439953803,"mc":[{"id":"1.187528277","rc":[{"batl":[[0,1.43,12688]],"ltp":1.43,"tv":289618.2,"id":2249229}]}]}
{"op":"mcm","clk":"4222025053","pt":1631440071356,"mc":[{"id":"1.187528277","rc":[{"batl":[[0,1.43,13326.16]],"ltp":1.43,"tv":289618.2,"id":2249229}]}]}
{"op":"mcm","clk":"4222028151","pt":1631440094073,"mc":[{"id":"1.187528277","rc":[{"trd":[[1.43,33517.17]],"batl":[[0,1.43,13302.23]],"ltp":1.43,"tv":289666.06,"id":2249229}],"tv":351208.78}]}
{"op":"mcm","clk":"4222042068","pt":1631440204113,"mc":[{"id":"1.187528277","rc":[{"trd":[[3.35,14541.66]],"batb":[[0,3.35,3651.37]],"ltp":3.35,"tv":61562.72,"id":19924831}],"tv":351228.78}]}
{"op":"mcm","clk":"4222042686","pt":1631440209404,"mc":[{"id":"1.187528277","rc":[{"trd":[[3.35,14548.34]],"batb":[[0,3.35,3648.03]],"ltp":3.35,"tv":61569.4,"id":19924831}],"tv":351235.46}]}
{"op":"mcm","clk":"4222042737","pt":1631440209882,"mc":[{"id":"1.187528277","rc":[{"trd":[[3.4,28360.72]],"batl":[[0,3.4,1155.59]],"ltp":3.4,"tv":61579.39,"id":19924831}],"tv":351245.46}]}
{"op":"mcm","clk":"4222046290","pt":1631440240456,"mc":[{"id":"1.187528277","rc":[{"batb":[[0,1.42,32077.12]],"batl":[[0,1.43,13310.56]],"ltp":1.43,"tv":289666.06,"id":2249229}]}]}
{"op":"mcm","clk":"4222046377","pt":1631440241139,"mc":[{"id":"1.187528277","rc":[{"batl":[[0,3.4,1160.09],[1,3.45,1100.13]],"ltp":3.4,"tv":61579.39,"id":19924831}]}]}
{"op":"mcm","clk":"4222056151","pt":1631440314807,"mc":[{"id":"1.187528277","rc":[{"trd":[[1.42,139913.15]],"batb":[[0,1.42,32073.59]],"ltp":1.42,"tv":289673.12,"id":2249229}],"tv":351252.52}]}
{"op":"mcm","clk":"4222058001","pt":1631440331350,"mc":[{"id":"1.187528277","rc":[{"batb":[[0,1.42,17613.32]],"ltp":1.42,"tv":289673.12,"id":2249229}]}]}
{"op":"mcm","clk":"4222058131","pt":1631440332443,"mc":[{"id":"1.187528277","rc":[{"batb":[[0,1.42,15658.32]],"ltp":1.42,"tv":289673.12,"id":2249229}]}]}
{"op":"mcm","clk":"4222063886","pt":1631440378198,"mc":[{"id":"1.187528277","rc":[{"batb":[[0,1.42,16042.64]],"ltp":1.42,"tv":289673.12,"id":2249229}]}]}
{"op":"mcm","clk":"4222070191","pt":1631440429908,"mc":[{"id":"1.187528277","rc":[{"batb":[[0,1.42,16069.23]],"ltp":1.42,"tv":289673.12,"id":2249229}]}]}
{"op":"mcm","clk":"4222074199","pt":1631440462033,"mc":[{"id":"1.187528277","rc":[{"batb":[[0,3.35,3651.39],[1,3.3,3665.08]],"ltp":3.4,"tv":61579.39,"id":19924831},{"trd":[[1.42,139933.15]],"batb":[[0,1.42,16059.23]],"ltp":1.42,"tv":289693.12,"id":2249229}],"tv":351272.52}]}
{"op":"mcm","clk":"4222076778","pt":1631440484273,"mc":[{"id":"1.187528277","rc":[{"batl":[[0,1.43,13332.78]],"ltp":1.42,"tv":289693.12,"id":2249229}]}]}
{"op":"mcm","clk":"4222076926","pt":1631440485690,"mc":[{"id":"1.187528277","rc":[{"trd":[[3.4,28366.59]],"batl":[[0,3.4,1157.16]],"ltp":3.4,"tv":61585.27,"id":19924831}],"tv":351278.39}]}
{"op":"mcm","clk":"4222077952","pt":1631440494404,"mc":[{"id":"1.187528277","rc":[{"batb":[[0,1.42,16047.15]],"ltp":1.42,"tv":289693.12,"id":2249229}]}]}
{"op":"mcm","clk":"4222078083","pt":1631440495504,"mc":[{"id":"1.187528277","rc":[{"batb":[[0,3.35,3655.43],[1,3.3,3669.2]],"ltp":3.4,"tv":61585.27,"id":19924831},{"batl":[[0,1.43,13336.23]],"ltp":1.42,"tv":289693.12,"id":2249229}]}]}
{"op":"mcm","clk":"4222087246","pt":1631440565305,"mc":[{"id":"1.187528277","rc":[{"batb":[[0,1.42,16072.15]],"ltp":1.42,"tv":289693.12,"id":2249229}]}]}
{"op":"mcm","clk":"4222092458","pt":1631440604954,"mc":[{"id":"1.187528277","rc":[{"trd":[[3.35,14637.24]],"batb":[[0,3.35,3610.98]],"ltp":3.35,"tv":61674.16,"id":19924831}],"tv":351367.29}]}
{"op":"mcm","clk":"4222102843","pt":1631440684545,"mc":[{"id":"1.187528277","rc":[{"trd":[[3.4,28409.14]],"batl":[[0,3.4,1135.88]],"ltp":3.4,"tv":61716.71,"id":19924831}],"tv":351409.83}]}
{"op":"mcm","clk":"4222108195","pt":1631440725421,"mc":[{"id":"1.187528277","rc":[{"batb":[[0,1.42,16067.27]],"batl":[[0,1.43,13348.53]],"ltp":1.42,"tv":289693.12,"id":2249229}]}]}
{"op":"mcm","clk":"4222108310","pt":1631440726474,"mc":[{"id":"1.187528277","rc":[{"batb":[[0,3.35,3616.28],[1,3.3,3674.62]],"batl":[[0,3.4,1142.61]],"ltp":3.4,"tv":61716.71,"id":19924831}]}]}
{"op":"mcm","clk":"4222108338","pt":1631440726787,"mc":[{"id":"1.187528277","rc":[{"batl":[[1,3.45,1093.61]],"ltp":3.4,"tv":61716.71,"id":19924831}]}]}
{"op":"mcm","clk":"4222112335","pt":1631440758131,"mc":[{"id":"1.187528277","rc":[{"trd":[[1.42,140133.15]],"batb":[[0,1.42,15967.27]],"ltp":1.42,"tv":289893.12,"id":2249229}],"tv":351609.83}]}
{"op":"mcm","clk":"4222122116","pt":1631440823716,"mc":[{"id":"1.187528277","rc":[{"trd":[[1.42,140155.14]],"batb":[[0,1.42,15956.28]],"ltp":1.42,"tv":289915.1,"id":2249229}],"tv":351631.82}]}
{"op":"mcm","clk":"4222127854","pt":1631440862372,"mc":[{"id":"1.187528277","rc":[{"batl":[[1,3.45,1095.31]],"ltp":3.4,"tv":61716.71,"id":19924831}]}]}
{"op":"mcm","clk":"4222128322","pt":1631440865205,"mc":[{"id":"1.187528277","rc":[{"trd":[[3.35,15237.24]],"batb":[[0,3.35,3316.28]],"ltp":3.35,"tv":62316.71,"id":19924831}],"tv":352231.82}]}
{"op":"mcm","clk":"4222138047","pt":1631440924263,"mc":[{"id":"1.187528277","rc":[{"batl":[[0,1.43,12710.37]],"ltp":1.42,"tv":289915.1,"id":2249229}]}]}
{"op":"mcm","clk":"4222139132","pt":1631440930753,"mc":[{"id":"1.187528277","rc":[{"trd":[[1.42,140192.71]],"batb":[[0,1.42,15937.49]],"ltp":1.42,"tv":289952.68,"id":2249229}],"tv":352269.4}]}
{"op":"mcm","clk":"4222155552","pt":1631441037000,"mc":[{"id":"1.187528277","rc":[{"trd":[[3.35,16091.28]],"batb":[[0,3.35,2889.26]],"ltp":3.35,"tv":63170.75,"id":19924831}],"tv":353123.44}]}
{"op":"mcm","clk":"4222158768","pt":1631441056722,"mc":[{"id":"1.187528277","rc":[{"trd":[[1.42,140240.58]],"batb":[[0,1.42,15913.56]],"ltp":1.42,"tv":290000.54,"id":2249229}],"tv":353171.3}]}
{"op":"mcm","clk":"4222182305","pt":1631441198641,"mc":[{"id":"1.187528277","rc":[{"trd":[[3.35,16094.7]],"batb":[[0,3.35,2887.55]],"ltp":3.35,"tv":63174.17,"id":19924831}],"tv":353174.72}]}
{"op":"mcm","clk":"4222191860","pt":1631441254497,"mc":[{"id":"1.187528277","rc":[{"trd":[[3.35,16116.7]],"batb":[[0,3.35,2876.55]],"ltp":3.35,"tv":63196.17,"id":19924831}],"tv":353196.72}]}
{"op":"mcm","clk":"4222232568","pt":1631441501522,"mc":[{"id":"1.187528277","rc":[{"batl":[[0,1.43,12730.37]],"ltp":1.42,"tv":290000.54,"id":2249229}]}]}
{"op":"mcm","clk":"4222233294","pt":1631441505892,"mc":[{"id":"1.187528277","rc":[{"batb":[[0,1.42,15933.56]],"ltp":1.42,"tv":290000.54,"id":2249229}]}]}
{"op":"mcm","clk":"4222253484","pt":1631441625318,"mc":[{"id":"1.187528277","rc":[{"trd":[[1.43,33588.03]],"batl":[[0,1.43,12694.94]],"ltp":1.43,"tv":290071.4,"id":2249229}],"tv":353267.58}]}
{"op":"mcm","clk":"4222259484","pt":1631441657222,"mc":[{"id":"1.187528277","rc":[{"trd":[[1.42,140290.58]],"batb":[[0,1.42,15908.56]],"ltp":1.42,"tv":290121.4,"id":2249229}],"tv":353317.58}]}
{"op":"mcm","clk":"4222261608","pt":1631441668818,"mc":[{"id":"1.187528277","rc":[{"batl":[[1,3.45,1210.49]],"ltp":3.35,"tv":63196.17,"id":19924831}]}]}
{"op":"mcm","clk":"4222271564","pt":1631441724416,"mc":[{"id":"1.187528277","rc":[{"trd":[[3.35,16135.48]],"batb":[[0,3.35,2867.16]],"ltp":3.35,"tv":63214.96,"id":19924831}],"tv":353336.36}]}
{"op":"mcm","clk":"4222276082","pt":1631441748414,"mc":[{"id":"1.187528277","rc":[{"trd":[[3.4,28438.42]],"batl":[[0,3.4,1127.97]],"ltp":3.4,"tv":63244.23,"id":19924831},{"batb":[[0,1.42,15781.8]],"ltp":1.42,"tv":290121.4,"id":2249229}],"tv":353365.64}]}
{"op":"mcm","clk":"4222276285","pt":1631441749521,"mc":[{"id":"1.187528277","rc":[{"batb":[[1,3.3,3727.8]],"ltp":3.4,"tv":63244.23,"id":19924831}]}]}
{"op":"mcm","clk":"4222278745","pt":1631441761654,"mc":[{"id":"1.187528277","rc":[{"batb":[[1,3.3,3674.62]],"ltp":3.4,"tv":63244.23,"id":19924831}]}]}
{"op":"mcm","clk":"4222278771","pt":1631441761760,"mc":[{"id":"1.187528277","rc":[{"batb":[[0,3.35,2920.34]],"ltp":3.4,"tv":63244.23,"id":19924831}]}]}
{"op":"mcm","clk":"4222280472","pt":1631441770550,"mc":[{"id":"1.187528277","rc":[{"batb":[[0,3.35,2867.16]],"ltp":3.4,"tv":63244.23,"id":19924831}]}]}
{"op":"mcm","clk":"4222283449","pt":1631441786757,"mc":[{"id":"1.187528277","rc":[{"trd":[[1.43,33643.03]],"batl":[[0,1.43,12667.44]],"ltp":1.43,"tv":290176.4,"id":2249229}],"tv":353420.64}]}
{"op":"mcm","clk":"4222284377","pt":1631441792002,"mc":[{"id":"1.187528277","rc":[{"trd":[[3.35,16955.5]],"batb":[[0,3.35,2457.16]],"ltp":3.35,"tv":64064.25,"id":19924831}],"tv":354240.66}]}
{"op":"mcm","clk":"4222287078","pt":1631441807437,"mc":[{"id":"1.187528277","rc":[{"batl":[[0,1.43,12752.84]],"ltp":1.43,"tv":290176.4,"id":2249229}]}]}
{"op":"mcm","clk":"4222294614","pt":1631441851368,"mc":[{"id":"1.187528277","rc":[{"trd":[[1.42,140324.58]],"batb":[[0,1.42,15764.8]],"ltp":1.42,"tv":290210.4,"id":2249229}],"tv":354274.66}]}
{"op":"mcm","clk":"4222315107","pt":1631441970641,"mc":[{"id":"1.187528277","rc":[{"trd":[[1.42,141324.58]],"batb":[[0,1.42,15264.8]],"ltp":1.42,"tv":291210.4,"id":2249229}],"tv":355274.66}]}
{"op":"mcm","clk":"4222316481","pt":1631441978665,"mc":[{"id":"1.187528277","rc":[{"trd":[[1.43,34243.03]],"batl":[[0,1.43,12452.84]],"ltp":1.43,"tv":291810.4,"id":2249229}],"tv":355874.66}]}
{"op":"mcm","clk":"4222318120","pt":1631441987970,"mc":[{"id":"1.187528277","rc":[{"trd":[[1.42,141328.58]],"batb":[[0,1.42,15262.8]],"ltp":1.42,"tv":291814.4,"id":2249229}],"tv":355878.66}]}
{"op":"mcm","clk":"4222318384","pt":1631441989455,"mc":[{"id":"1.187528277","rc":[{"batb":[[0,1.42,15954.04]],"ltp":1.42,"tv":291814.4,"id":2249229}]}]}
{"op":"mcm","clk":"4222318433","pt":1631441989770,"mc":[{"id":"1.187528277","rc":[{"batb":[[0,1.42,15262.8]],"ltp":1.42,"tv":291814.4,"id":2249229}]}]}
{"op":"mcm","clk":"4222321546","pt":1631442006375,"mc":[{"id":"1.187528277","rc":[{"trd":[[1.42,141334.92]],"batb":[[0,1.42,15259.63]],"ltp":1.42,"tv":291820.75,"id":2249229}],"tv":355885.0}]}
{"op":"mcm","clk":"4222324993","pt":1631442025634,"mc":[{"id":"1.187528277","rc":[{"trd":[[3.4,28544.78]],"batl":[[0,3.4,1074.79]],"ltp":3.4,"tv":64170.61,"id":19924831},{"batb":[[0,1.42,15950.87]],"ltp":1.42,"tv":291820.75,"id":2249229}],"tv":355991.36}]}
{"op":"mcm","clk":"4222325035","pt":1631442025905,"mc":[{"id":"1.187528277","rc":[{"batl":[[0,3.4,1127.73]],"ltp":3.4,"tv":64170.61,"id":19924831},{"batb":[[0,1.42,15259.63]],"ltp":1.42,"tv":291820.75,"id":2249229}]}]}
{"op":"mcm","clk":"4222325315","pt":1631442027490,"mc":[{"id":"1.187528277","rc":[{"trd":[[1.42,141414.92]],"batb":[[0,1.42,15219.63]],"ltp":1.42,"tv":291900.75,"id":2249229}],"tv":356071.36}]}
{"op":"mcm","clk":"4222334139","pt":1631442076388,"mc":[{"id":"1.187528277","rc":[{"batb":[[0,1.42,15213.73]],"ltp":1.42,"tv":291900.75,"id":2249229}]}]}
{"op":"mcm","clk":"4222334311","pt":1631442077490,"mc":[{"id":"1.187528277","rc":[{"batb":[[0,1.42,15180.94]],"ltp":1.42,"tv":291900.75,"id":2249229}]}]}
{"op":"mcm","clk":"4222334487","pt":1631442078493,"mc":[{"id":"1.187528277","rc":[{"batb":[[1,3.3,3687.96]],"ltp":3.4,"tv":64170.61,"id":19924831},{"batl":[[0,1.43,12466.36]],"ltp":1.42,"tv":291900.75,"id":2249229}]}]}
{"op":"mcm","clk":"4222334672","pt":1631442079491,"mc":[{"id":"1.187528277","rc":[{"batb":[[0,3.35,2470.22]],"batl":[[0,3.4,1140.65],[1,3.45,1197.96]],"ltp":3.4,"tv":64170.61,"id":19924831}]}]}
{"op":"mcm","clk":"4222335518","pt":1631442084121,"mc":[{"id":"1.187528277","rc":[{"trd":[[3.4,28553.32]],"batl":[[0,3.4,1136.38]],"ltp":3.4,"tv":64179.15,"id":19924831}],"tv":356079.9}]}
{"op":"mcm","clk":"4222350428","pt":1631442167575,"mc":[{"id":"1.187528277","rc":[{"batb":[[0,3.35,2472.39]],"ltp":3.4,"tv":64179.15,"id":19924831}]}]}
{"op":"mcm","clk":"4222350590","pt":1631442168590,"mc":[{"id":"1.187528277","rc":[{"trd":[[1.42,141454.92]],"batb":[[0,1.42,15160.94]],"ltp":1.42,"tv":291940.75,"id":2249229}],"tv":356119.9}]}
{"op":"mcm","clk":"4222353433","pt":1631442185224,"mc":[{"id":"1.187528277","rc":[{"batb":[[0,1.42,15273.68]],"ltp":1.42,"tv":291940.75,"id":2249229}]}]}
{"op":"mcm","clk":"4222369034","pt":1631442271108,"mc":[{"id":"1.187528277","rc":[{"batb":[[0,1.42,15434.24]],"ltp":1.42,"tv":291940.75,"id":2249229}]}]}
{"op":"mcm","clk":"4222369679","pt":1631442274344,"mc":[{"id":"1.187528277","rc":[{"trd":[[3.35,17155.5]],"batb":[[0,3.35,2372.39]],"ltp":3.35,"tv":64379.15,"id":19924831}],"tv":356319.9}]}
{"op":"mcm","clk":"4222374681","pt":1631442301631,"mc":[{"id":"1.187528277","rc":[{"batb":[[0,1.42,16125.48]],"ltp":1.42,"tv":291940.75,"id":2249229}]}]}
{"op":"mcm","clk":"4222374711","pt":1631442301744,"mc":[{"id":"1.187528277","rc":[{"batb":[[0,1.42,15434.24]],"ltp":1.42,"tv":291940.75,"id":2249229}]}]}
{"op":"mcm","clk":"4222378379","pt":1631442321215,"mc":[{"id":"1.187528277","rc":[{"trd":[[1.42,141489.96]],"batb":[[0,1.42,15416.72]],"batl":[[0,1.43,12448.84]],"ltp":1.42,"tv":291975.79,"id":2249229}],"tv":356354.94}]}
{"op":"mcm","clk":"4222386076","pt":1631442361618,"mc":[{"id":"1.187528277","rc":[{"trd":[[3.35,17497.12]],"batb":[[0,3.35,2201.58]],"ltp":3.35,"tv":64720.77,"id":19924831},{"batb":[[0,1.42,16107.96]],"ltp":1.42,"tv":291975.79,"id":2249229}],"tv":356696.56}]}
{"op":"mcm","clk":"4222386108","pt":1631442361828,"mc":[{"id":"1.187528277","rc":[{"batb":[[0,1.42,15416.72]],"ltp":1.42,"tv":291975.79,"id":2249229}]}]}
{"op":"mcm","clk":"4222386310","pt":1631442362831,"mc":[{"id":"1.187528277","rc":[{"trd":[[1.42,141501.06]],"batb":[[0,1.42,15411.17]],"ltp":1.42,"tv":291986.88,"id":2249229}],"tv":356707.66}]}
{"op":"mcm","clk":"4222391359","pt":1631442390683,"mc":[{"id":"1.187528277","rc":[{"batb":[[0,1.42,16436.02]],"ltp":1.42,"tv":291986.88,"id":2249229}]}]}
{"op":"mcm","clk":"4222392413","pt":1631442396567,"mc":[{"id":"1.187528277","rc":[{"batl":[[2,1.45,6528.93]],"ltp":1.42,"tv":291986.88,"id":2249229}]}]}
{"op":"mcm","clk":"4222397768","pt":1631442425507,"mc":[{"id":"1.187528277","rc":[{"batb":[[0,1.42,15923.59]],"ltp":1.42,"tv":291986.88,"id":2249229}]}]}
{"op":"mcm","clk":"4222409314","pt":1631442490550,"mc":[{"id":"1.187528277","rc":[{"trd":[[3.35,17557.12]],"batb":[[0,3.35,2171.58]],"ltp":3.35,"tv":64780.77,"id":19924831}],"tv":356767.66}]}
{"op":"mcm","clk":"4222419898","pt":1631442545496,"mc":[{"id":"1.187528277","rc":[{"batb":[[0,1.42,16423.59],[2,1.4,25378.6]],"ltp":1.42,"tv":291986.88,"id":2249229}]}]}
{"op":"mcm","clk":"4222420515","pt":1631442548684,"mc":[{"id":"1.187528277","rc":[{"batb":[[0,1.42,17108.39]],"ltp":1.42,"tv":291986.88,"id":2249229}]}]}
{"op":"mcm","clk":"4222420532","pt":1631442548791,"mc":[{"id":"1.187528277","rc":[{"batb":[[0,1.42,16423.59]],"ltp":1.42,"tv":291986.88,"id":2249229}]}]}
{"op":"mcm","clk":"4222421206","pt":1631442552419,"mc":[{"id":"1.187528277","rc":[{"trd":[[1.42,141579.64]],"batb":[[0,1.42,16384.3]],"ltp":1.42,"tv":292065.46,"id":2249229}],"tv":356846.24}]}
{"op":"mcm","clk":"4222421967","pt":1631442556201,"mc":[{"id":"1.187528277","rc":[{"batb":[[0,1.42,16134.3]],"ltp":1.42,"tv":292065.46,"id":2249229}]}]}
{"op":"mcm","clk":"4222434347","pt":1631442619694,"mc":[{"id":"1.187528277","rc":[{"trd":[[1.42,141583.64]],"batb":[[0,1.42,16132.3]],"ltp":1.42,"tv":292069.46,"id":2249229}],"tv":356850.24}]}
{"op":"mcm","clk":"4222442886","pt":1631442664720,"mc":[{"id":"1.187528277","rc":[{"trd":[[3.35,18411.16]],"batb":[[0,3.35,1744.56]],"ltp":3.35,"tv":65634.81,"id":19924831}],"tv":357704.28}]}
{"op":"mcm","clk":"4222448536","pt":1631442695622,"mc":[{"id":"1.187528277","rc":[{"trd":[[3.35,18470.95]],"batb":[[0,3.35,1714.67]],"ltp":3.35,"tv":65694.59,"id":19924831}],"tv":357764.06}]}
{"op":"mcm","clk":"4222449661","pt":1631442701916,"mc":[{"id":"1.187528277","rc":[{"trd":[[3.35,18532.44]],"batb":[[0,3.35,1683.92]],"ltp":3.35,"tv":65756.09,"id":19924831}],"tv":357825.55}]}
{"op":"mcm","clk":"4222455012","pt":1631442729545,"mc":[{"id":"1.187528277","rc":[{"trd":[[1.42,141640.03]],"batb":[[0,1.42,16788.9]],"ltp":1.42,"tv":292125.86,"id":2249229}],"tv":357881.95}]}
{"op":"mcm","clk":"4222455056","pt":1631442729753,"mc":[{"id":"1.187528277","rc":[{"batb":[[0,1.42,16104.1]],"ltp":1.42,"tv":292125.86,"id":2249229}]}]}
{"op":"mcm","clk":"4222456114","pt":1631442735362,"mc":[{"id":"1.187528277","rc":[{"trd":[[3.35,18575.14]],"batb":[[0,3.35,1662.57]],"ltp":3.35,"tv":65798.79,"id":19924831}],"tv":357924.65}]}
{"op":"mcm","clk":"4222467006","pt":1631442797518,"mc":[{"id":"1.187528277","rc":[{"trd":[[1.42,142494.08]],"batb":[[0,1.42,15677.08]],"ltp":1.42,"tv":292979.9,"id":2249229}],"tv":358778.7}]}
{"op":"mcm","clk":"4222474869","pt":1631442844421,"mc":[{"id":"1.187528277","rc":[{"trd":[[1.43,34274.94]],"batl":[[0,1.43,12432.89]],"ltp":1.43,"tv":293011.8,"id":2249229}],"tv":358810.6}]}
{"op":"mcm","clk":"4222475733","pt":1631442849538,"mc":[{"id":"1.187528277","rc":[{"trd":[[1.42,142694.08]],"batb":[[0,1.42,15577.08]],"ltp":1.42,"tv":293211.8,"id":2249229}],"tv":359010.6}]}
{"op":"mcm","clk":"4222488732","pt":1631442919651,"mc":[{"id":"1.187528277","rc":[{"trd":[[1.42,142722.53]],"batb":[[0,1.42,16243.3]],"ltp":1.42,"tv":293240.26,"id":2249229}],"tv":359039.06}]}
{"op":"mcm","clk":"4222489607","pt":1631442923743,"mc":[{"id":"1.187528277","rc":[{"trd":[[3.4,28561.89]],"batl":[[0,3.4,1132.09]],"ltp":3.4,"tv":65807.36,"id":19924831}],"tv":359047.63}]}
{"op":"mcm","clk":"4222490430","pt":1631442927644,"mc":[{"id":"1.187528277","rc":[{"trd":[[3.35,18595.74]],"batb":[[0,3.35,1652.27]],"ltp":3.35,"tv":65827.96,"id":19924831}],"tv":359068.23}]}
{"op":"mcm","clk":"4222494406","pt":1631442948449,"mc":[{"id":"1.187528277","rc":[{"batl":[[0,3.4,1232.09]],"ltp":3.35,"tv":65827.96,"id":19924831}]}]}
{"op":"mcm","clk":"4222494824","pt":1631442950668,"mc":[{"id":"1.187528277","rc":[{"batb":[[0,1.42,16923.75]],"ltp":1.42,"tv":293240.26,"id":2249229}]}]}
{"op":"mcm","clk":"4222494979","pt":1631442951561,"mc":[{"id":"1.187528277","rc":[{"batb":[[0,3.35,1656.62],[1,3.3,3692.4]],"batl":[[0,3.4,1236.39]],"ltp":3.35,"tv":65827.96,"id":19924831},{"batb":[[0,1.42,16243.3]],"ltp":1.42,"tv":293240.26,"id":2249229}]}]}
{"op":"mcm","clk":"4222495858","pt":1631442956364,"mc":[{"id":"1.187528277","rc":[{"batb":[[0,1.42,15562.85]],"ltp":1.42,"tv":293240.26,"id":2249229}]}]}
{"op":"mcm","clk":"4222496504","pt":1631442960486,"mc":[{"id":"1.187528277","rc":[{"batl":[[0,3.4,1492.61]],"ltp":3.35,"tv":65827.96,"id":19924831}]}]}
{"op":"mcm","clk":"4222496797","pt":1631442962282,"mc":[{"id":"1.187528277","rc":[{"trd":[[3.35,19074.35]],"batb":[[0,3.35,1417.32]],"ltp":3.35,"tv":66306.57,"id":19924831}],"tv":359546.84}]}
{"op":"mcm","clk":"4222501988","pt":1631442991511,"mc":[{"id":"1.187528277","rc":[{"trd":[[1.42,142732.53]],"batb":[[0,1.42,15557.85]],"ltp":1.42,"tv":293250.26,"id":2249229}],"tv":359556.84}]}
{"op":"mcm","clk":"4222505684","pt":1631443012359,"mc":[{"id":"1.187528277","rc":[{"batb":[[0,1.42,31624.66]],"ltp":1.42,"tv":293250.26,"id":2249229}]}]}
{"op":"mcm","clk":"4222508667","pt":1631443028151,"mc":[{"id":"1.187528277","rc":[{"batl":[[0,3.4,1516.52],[1,3.45,1156.12]],"ltp":3.35,"tv":66306.57,"id":19924831},{"batl":[[1,1.44,10981.62],[2,1.45,6660.45]],"ltp":1.42,"tv":293250.26,"id":2249229}]}]}
{"op":"mcm","clk":"4222511201","pt":1631443043683,"mc":[{"id":"1.187528277","rc":[{"batb":[[0,1.42,32305.11]],"ltp":1.42,"tv":293250.26,"id":2249229}]}]}
{"op":"mcm","clk":"4222511238","pt":1631443043894,"mc":[{"id":"1.187528277","rc":[{"batb":[[0,1.42,31624.66]],"ltp":1.42,"tv":293250.26,"id":2249229}]}]}
{"op":"mcm","clk":"4222520083","pt":1631443094994,"mc":[{"id":"1.187528277","rc":[{"batb":[[2,1.4,25381.26]],"ltp":1.42,"tv":293250.26,"id":2249229}]}]}
{"op":"mcm","clk":"4222522513","pt":1631443109615,"mc":[{"id":"1.187528277","rc":[{"batb":[[2,1.4,25383.41]],"ltp":1.42,"tv":293250.26,"id":2249229}]}]}
{"op":"mcm","clk":"4222523834","pt":1631443117590,"mc":[{"id":"1.187528277","rc":[{"trd":[[1.43,34279.24]],"batb":[[0,1.42,32305.11],[2,1.4,25381.26]],"batl":[[0,1.43,12430.74]],"ltp":1.43,"tv":293254.56,"id":2249229}],"tv":359561.14}]}
{"op":"mcm","clk":"4222523871","pt":1631443117801,"mc":[{"id":"1.187528277","rc":[{"batb":[[0,1.42,31624.66]],"ltp":1.43,"tv":293254.56,"id":2249229}]}]}
{"op":"mcm","clk":"4222524717","pt":1631443122620,"mc":[{"id":"1.187528277","rc":[{"trd":[[1.43,34779.24]],"batb":[[0,1.42,32055.11],[2,1.4,25378.6]],"batl":[[0,1.43,12180.74]],"ltp":1.43,"tv":293754.56,"id":2249229}],"tv":360061.14}]}
{"op":"mcm","clk":"4222524739","pt":1631443122728,"mc":[{"id":"1.187528277","rc":[{"batb":[[0,1.42,31374.66]],"ltp":1.43,"tv":293754.56,"id":2249229}]}]}
{"op":"mcm","clk":"4222526315","pt":1631443131611,"mc":[{"id":"1.187528277","rc":[{"trd":[[1.43,34879.24]],"batl":[[0,1.43,12130.74]],"ltp":1.43,"tv":293854.56,"id":2249229}],"tv":360161.14}]}
{"op":"mcm","clk":"4222528551","pt":1631443144519,"mc":[{"id":"1.187528277","rc":[{"batb":[[0,1.42,32055.11]],"ltp":1.43,"tv":293854.56,"id":2249229}]}]}
{"op":"mcm","clk":"4222528589","pt":1631443144732,"mc":[{"id":"1.187528277","rc":[{"batb":[[0,1.42,31374.66]],"ltp":1.43,"tv":293854.56,"id":2249229}]}]}
{"op":"mcm","clk":"4222532780","pt":1631443171775,"mc":[{"id":"1.187528277","rc":[{"trd":[[3.35,19094.35]],"batb":[[0,3.35,1407.32]],"ltp":3.35,"tv":66326.57,"id":19924831}],"tv":360181.14}]}
{"op":"mcm","clk":"4222533180","pt":1631443174474,"mc":[{"id":"1.187528277","rc":[{"batb":[[0,1.42,32055.11]],"ltp":1.43,"tv":293854.56,"id":2249229}]}]}
{"op":"mcm","clk":"4222533221","pt":1631443174739,"mc":[{"id":"1.187528277","rc":[{"batb":[[0,1.42,31374.66]],"ltp":1.43,"tv":293854.56,"id":2249229}]}]}
{"op":"mcm","clk":"4222538459","pt":1631443207821,"mc":[{"id":"1.187528277","rc":[{"batl":[[0,3.4,1260.31]],"ltp":3.35,"tv":66326.57,"id":19924831}]}]}
{"op":"mcm","clk":"4222543954","pt":1631443238525,"mc":[{"id":"1.187528277","rc":[{"trd":[[3.35,19948.4]],"batb":[[0,3.35,980.3]],"ltp":3.35,"tv":67180.61,"id":19924831}],"tv":361035.18}]}
{"op":"mcm","clk":"4222577248","pt":1631443424551,"mc":[{"id":"1.187528277","rc":[{"trd":[[1.42,142752.53]],"batb":[[0,1.42,31364.66]],"ltp":1.42,"tv":293874.56,"id":2249229}],"tv":361055.18}]}
{"op":"mcm","clk":"4222592880","pt":1631443512601,"mc":[{"id":"1.187528277","rc":[{"trd":[[1.42,142759.77]],"batb":[[0,1.42,31361.04]],"ltp":1.42,"tv":293881.8,"id":2249229}],"tv":361062.42}]}
{"op":"mcm","clk":"4222597794","pt":1631443541562,"mc":[{"id":"1.187528277","rc":[{"batb":[[0,1.42,32050.84]],"ltp":1.42,"tv":293881.8,"id":2249229}]}]}
{"op":"mcm","clk":"4222597830","pt":1631443541729,"mc":[{"id":"1.187528277","rc":[{"batb":[[0,1.42,31361.04]],"ltp":1.42,"tv":293881.8,"id":2249229}]}]}
{"op":"mcm","clk":"4222602586","pt":1631443567893,"mc":[{"id":"1.187528277","rc":[{"trd":[[3.35,19968.4]],"batb":[[0,3.35,970.3]],"ltp":3.35,"tv":67200.61,"id":19924831}],"tv":361082.42}]}
{"op":"mcm","clk":"4222606670","pt":1631443591746,"mc":[{"id":"1.187528277","rc":[{"trd":[[3.4,28631]],"batl":[[0,3.4,1225.75]],"ltp":3.4,"tv":67269.73,"id":19924831}],"tv":361151.53}]}
{"op":"mcm","clk":"4222612639","pt":1631443628610,"mc":[{"id":"1.187528277","rc":[{"batb":[[0,1.42,31309.09]],"ltp":1.42,"tv":293881.8,"id":2249229}]}]}
{"op":"mcm","clk":"4222612816","pt":1631443629618,"mc":[{"id":"1.187528277","rc":[{"batb":[[0,3.35,987.85],[1,3.3,3710.34]],"ltp":3.4,"tv":67269.73,"id":19924831}]}]}
{"op":"mcm","clk":"4222612951","pt":1631443630525,"mc":[{"id":"1.187528277","rc":[{"trd":[[3.4,28921]],"batl":[[0,3.4,1098.11],[1,3.45,1135.11]],"ltp":3.4,"tv":67559.73,"id":19924831}],"tv":361441.53}]}
{"op":"mcm","clk":"4222621611","pt":1631443683570,"mc":[{"id":"1.187528277","rc":[{"batb":[[0,3.35,1026.08],[1,3.3,3749.4]],"ltp":3.4,"tv":67559.73,"id":19924831}]}]}
{"op":"mcm","clk":"4222621732","pt":1631443684294,"mc":[{"id":"1.187528277","rc":[{"batl":[[0,3.4,1135.92],[1,3.45,1098.44]],"ltp":3.4,"tv":67559.73,"id":19924831}]}]}
{"op":"mcm","clk":"4222621931","pt":1631443685572,"mc":[{"id":"1.187528277","rc":[{"batb":[[0,1.42,31998.89]],"ltp":1.42,"tv":293881.8,"id":2249229}]}]}
{"op":"mcm","clk":"4222621965","pt":1631443685776,"mc":[{"id":"1.187528277","rc":[{"batb":[[0,1.42,31309.09]],"ltp":1.42,"tv":293881.8,"id":2249229}]}]}
{"op":"mcm","clk":"4222634781","pt":1631443767703,"mc":[{"id":"1.187528277","rc":[{"batb":[[0,1.42,31998.89]],"ltp":1.42,"tv":293881.8,"id":2249229}]}]}
{"op":"mcm","clk":"4222634815","pt":1631443767918,"mc":[{"id":"1.187528277","rc":[{"batb":[[0,1.42,31309.09]],"ltp":1.42,"tv":293881.8,"id":2249229}]}]}
{"op":"mcm","clk":"4222636212","pt":1631443777132,"mc":[{"id":"1.187528277","rc":[{"trd":[[3.35,21995.73]],"batb":[[0,3.35,12.42]],"ltp":3.35,"tv":69587.06,"id":19924831}],"tv":363468.86}]}
{"op":"mcm","clk":"4222641857","pt":1631443816660,"mc":[{"id":"1.187528277","rc":[{"batb":[[0,1.42,31998.89]],"batl":[[0,1.43,11458.33]],"ltp":1.42,"tv":293881.8,"id":2249229}]}]}
{"op":"mcm","clk":"4222641885","pt":1631443816855,"mc":[{"id":"1.187528277","rc":[{"batb":[[0,1.42,31309.09]],"ltp":1.42,"tv":293881.8,"id":2249229}]}]}
{"op":"mcm","clk":"4222642857","pt":1631443823482,"mc":[{"id":"1.187528277","rc":[{"batb":[[1,3.3,3710.34]],"ltp":3.35,"tv":69587.06,"id":19924831},{"batb":[[0,1.42,31338.65]],"ltp":1.42,"tv":293881.8,"id":2249229}]}]}
{"op":"mcm","clk":"4222643007","pt":1631443824489,"mc":[{"id":"1.187528277","rc":[{"batb":[[0,3.3,3697.61],[1,3.25,2966.29],[2,3.2,895]],"ltp":3.35,"tv":69587.06,"id":19924831}]}]}
{"op":"mcm","clk":"4222643163","pt":1631443825464,"mc":[{"id":"1.187528277","rc":[{"batl":[[0,3.4,1185.56],[1,3.45,1147.06]],"ltp":3.35,"tv":69587.06,"id":19924831},{"batb":[[0,1.42,33605.65]],"batl":[[0,1.43,9317.33]],"ltp":1.42,"tv":293881.8,"id":2249229}]}]}
{"op":"mcm","clk":"4222650949","pt":1631443879349,"mc":[{"id":"1.187528277","rc":[{"batl":[[0,3.35,10],[1,3.4,1185.56],[2,3.45,1147.06]],"ltp":3.35,"tv":69587.06,"id":19924831}]}]}
{"op":"mcm","clk":"4222652066","pt":1631443887770,"mc":[{"id":"1.187528277","rc":[{"trd":[[3.35,21995.76]],"batl":[[0,3.35,9.98]],"ltp":3.35,"tv":69587.1,"id":19924831}],"tv":363468.9}]}
{"op":"mcm","clk":"4222653340","pt":1631443897565,"mc":[{"id":"1.187528277","rc":[{"batl":[[2,3.45,825.04]],"ltp":3.35,"tv":69587.1,"id":19924831}]}]}
{"op":"mcm","clk":"4222654411","pt":1631443905703,"mc":[{"id":"1.187528277","rc":[{"batb":[[0,1.42,34295.45]],"ltp":1.42,"tv":293881.8,"id":2249229}]}]}
{"op":"mcm","clk":"4222654435","pt":1631443905886,"mc":[{"id":"1.187528277","rc":[{"batb":[[0,1.42,33605.65]],"ltp":1.42,"tv":293881.8,"id":2249229}]}]}
{"op":"mcm","clk":"4222666733","pt":1631443997713,"mc":[{"id":"1.187528277","rc":[{"trd":[[3.35,22015.72]],"batb":[[0,3.35,23.44],[1,3.3,3697.61],[2,3.25,2966.29]],"batl":[[0,3.4,1185.56],[1,3.45,825.04],[2,3.5,715.92]],"ltp":3.35,"tv":69607.06,"id":19924831}],"tv":363488.86}]}
{"op":"mcm","clk":"4222666844","pt":1631443998609,"mc":[{"id":"1.187528277","rc":[{"batb":[[0,1.42,34295.45]],"batl":[[0,1.43,11771.33]],"ltp":1.42,"tv":293881.8,"id":2249229}]}]}
{"op":"mcm","clk":"4222666864","pt":1631443998820,"mc":[{"id":"1.187528277","rc":[{"batb":[[0,1.42,33605.65]],"ltp":1.42,"tv":293881.8,"id":2249229}]}]}
{"op":"mcm","clk":"4222671000","pt":1631444029471,"mc":[{"id":"1.187528277","rc":[{"batb":[[0,3.35,26.96]],"ltp":3.35,"tv":69607.06,"id":19924831}]}]}
{"op":"mcm","clk":"4222671137","pt":1631444030473,"mc":[{"id":"1.187528277","rc":[{"batb":[[2,3.25,2987.29]],"ltp":3.35,"tv":69607.06,"id":19924831}]}]}
{"op":"mcm","clk":"4222671328","pt":1631444031587,"mc":[{"id":"1.187528277","rc":[{"batb":[[0,1.42,34295.45]],"ltp":1.42,"tv":293881.8,"id":2249229}]}]}
{"op":"mcm","clk":"4222671355","pt":1631444031804,"mc":[{"id":"1.187528277","rc":[{"batb":[[0,1.42,33605.65]],"ltp":1.42,"tv":293881.8,"id":2249229}]}]}
{"op":"mcm","clk":"4222674020","pt":1631444049697,"mc":[{"id":"1.187528277","rc":[{"trd":[[1.42,142990.91]],"batb":[[0,1.42,34179.88]],"ltp":1.42,"tv":294112.94,"id":2249229}],"tv":363720.0}]}
{"op":"mcm","clk":"4222674037","pt":1631444049803,"mc":[{"id":"1.187528277","rc":[{"batb":[[0,1.42,33490.08]],"ltp":1.42,"tv":294112.94,"id":2249229}]}]}
{"op":"mcm","clk":"4222692376","pt":1631444174539,"mc":[{"id":"1.187528277","rc":[{"batb":[[0,1.42,34179.88]],"ltp":1.42,"tv":294112.94,"id":2249229}]}]}
{"op":"mcm","clk":"4222692498","pt":1631444175483,"mc":[{"id":"1.187528277","rc":[{"batb":[[1,3.3,3708.46],[2,3.25,2972.46]],"ltp":3.35,"tv":69607.06,"id":19924831},{"batb":[[0,1.42,33476.63],[2,1.4,25406.12]],"ltp":1.42,"tv":294112.94,"id":2249229}]}]}
{"op":"mcm","clk":"4222697234","pt":1631444209631,"mc":[{"id":"1.187528277","rc":[{"trd":[[3.4,28925.2]],"batl":[[0,3.4,1183.46]],"ltp":3.4,"tv":69611.26,"id":19924831}],"tv":363724.2}]}
{"op":"mcm","clk":"4222701843","pt":1631444240684,"mc":[{"id":"1.187528277","rc":[{"batb":[[0,1.42,32964.21]],"ltp":1.42,"tv":294112.94,"id":2249229}]}]}
{"op":"mcm","clk":"4222703223","pt":1631444249690,"mc":[{"id":"1.187528277","rc":[{"trd":[[3.35,22069.64]],"batb":[[0,3.3,3708.46],[1,3.25,2972.46],[2,3.2,874]],"batl":[[0,3.35,186.55],[1,3.4,1183.46],[2,3.45,825.04]],"ltp":3.35,"tv":69665.18,"id":19924831}],"tv":363778.12}]}
{"op":"mcm","clk":"4222703354","pt":1631444250582,"mc":[{"id":"1.187528277","rc":[{"batb":[[0,1.42,33628.96]],"batl":[[0,1.43,9317.33]],"ltp":1.42,"tv":294112.94,"id":2249229}]}]}
{"op":"mcm","clk":"4222703384","pt":1631444250795,"mc":[{"id":"1.187528277","rc":[{"batb":[[0,1.42,32964.21]],"ltp":1.42,"tv":294112.94,"id":2249229}]}]}
{"op":"mcm","clk":"4222716491","pt":1631444343448,"mc":[{"id":"1.187528277","rc":[{"trd":[[3.35,22077.79]],"batl":[[0,3.35,182.48]],"ltp":3.35,"tv":69673.32,"id":19924831}],"tv":363786.26}]}
{"op":"mcm","clk":"4222720008","pt":1631444364756,"mc":[{"id":"1.187528277","rc":[{"trd":[[3.35,22086.01]],"batl":[[0,3.35,178.37]],"ltp":3.35,"tv":69681.54,"id":19924831}],"tv":363794.48}]}
{"op":"mcm","clk":"4222724508","pt":1631444392611,"mc":[{"id":"1.187528277","rc":[{"batb":[[0,1.42,33634.88]],"ltp":1.42,"tv":294112.94,"id":2249229}]}]}
{"op":"mcm","clk":"4222724555","pt":1631444392880,"mc":[{"id":"1.187528277","rc":[{"batb":[[0,1.42,32964.21]],"ltp":1.42,"tv":294112.94,"id":2249229}]}]}
{"op":"mcm","clk":"4222728944","pt":1631444418432,"mc":[{"id":"1.187528277","rc":[{"batb":[[0,1.42,33634.88]],"ltp":1.42,"tv":294112.94,"id":2249229}]}]}
{"op":"mcm","clk":"4222729010","pt":1631444418749,"mc":[{"id":"1.187528277","rc":[{"batb":[[0,1.42,32964.21]],"ltp":1.42,"tv":294112.94,"id":2249229}]}]}
{"op":"mcm","clk":"4222732639","pt":1631444437466,"mc":[{"id":"1.187528277","rc":[{"batl":[[2,1.45,6713.63]],"ltp":1.42,"tv":294112.94,"id":2249229}]}]}
{"op":"mcm","clk":"4222744262","pt":1631444500983,"mc":[{"id":"1.187528277","rc":[{"batl":[[0,1.43,9327.33]],"ltp":1.42,"tv":294112.94,"id":2249229}]}]}
{"op":"mcm","clk":"4222745025","pt":1631444505184,"mc":[{"id":"1.187528277","rc":[{"batb":[[0,1.42,32974.21]],"ltp":1.42,"tv":294112.94,"id":2249229}]}]}
{"op":"mcm","clk":"4222765189","pt":1631444621720,"mc":[{"id":"1.187528277","rc":[{"trd":[[1.43,34887.94]],"batl":[[0,1.43,9322.98]],"ltp":1.43,"tv":294121.64,"id":2249229}],"tv":363803.19}]}
{"op":"mcm","clk":"4222770008","pt":1631444648368,"mc":[{"id":"1.187528277","rc":[{"trd":[[1.42,142998.91]],"batb":[[0,1.42,32970.21]],"ltp":1.42,"tv":294129.64,"id":2249229}],"tv":363811.19}]}
{"op":"mcm","clk":"4222782275","pt":1631444714454,"mc":[{"id":"1.187528277","rc":[{"trd":[[1.43,34941.88]],"batl":[[0,1.43,9296.01]],"ltp":1.43,"tv":294183.58,"id":2249229}],"tv":363865.13}]}
{"op":"mcm","clk":"4222790139","pt":1631444756919,"mc":[{"id":"1.187528277","rc":[{"trd":[[3.3,10392.72]],"batb":[[0,3.3,3703.14]],"ltp":3.3,"tv":69692.18,"id":19924831}],"tv":363875.77}]}
{"op":"mcm","clk":"4222797553","pt":1631444796185,"mc":[{"id":"1.187528277","rc":[{"trd":[[3.3,10457.62]],"batb":[[0,3.3,3670.69]],"ltp":3.3,"tv":69757.08,"id":19924831}],"tv":363940.67}]}
{"op":"mcm","clk":"4222804435","pt":1631444831622,"mc":[{"id":"1.187528277","rc":[{"batb":[[0,1.42,33640.88]],"ltp":1.43,"tv":294183.58,"id":2249229}]}]}
{"op":"mcm","clk":"4222804467","pt":1631444831835,"mc":[{"id":"1.187528277","rc":[{"batb":[[0,1.42,32970.21]],"ltp":1.43,"tv":294183.58,"id":2249229}]}]}
{"op":"mcm","clk":"4222805820","pt":1631444838934,"mc":[{"id":"1.187528277","rc":[{"trd":[[3.3,10737.62]],"batb":[[0,3.3,3530.69]],"ltp":3.3,"tv":70037.08,"id":19924831}],"tv":364220.67}]}
{"op":"mcm","clk":"4222820082","pt":1631444915651,"mc":[{"id":"1.187528277","rc":[{"trd":[[1.42,143158.45]],"batb":[[0,1.42,32890.44]],"ltp":1.42,"tv":294343.12,"id":2249229}],"tv":364380.21}]}
{"op":"mcm","clk":"4222829030","pt":1631444963712,"mc":[{"id":"1.187528277","rc":[{"trd":[[1.42,143488.41]],"batb":[[0,1.42,32725.46]],"ltp":1.42,"tv":294673.08,"id":2249229}],"tv":364710.17}]}
{"op":"mcm","clk":"4222834578","pt":1631444996749,"mc":[{"id":"1.187528277","rc":[{"trd":[[1.43,34949.88]],"batl":[[0,1.43,9292.01]],"ltp":1.43,"tv":294681.08,"id":2249229}],"tv":364718.17}]}
{"op":"mcm","clk":"4222846935","pt":1631445064699,"mc":[{"id":"1.187528277","rc":[{"trd":[[3.35,22118.97]],"batl":[[0,3.35,161.88]],"ltp":3.35,"tv":70070.05,"id":19924831}],"tv":364751.13}]}
{"op":"mcm","clk":"4222847123","pt":1631445065708,"mc":[{"id":"1.187528277","rc":[{"batb":[[0,1.42,33388.59]],"ltp":1.43,"tv":294681.08,"id":2249229}]}]}
{"op":"mcm","clk":"4222847158","pt":1631445065876,"mc":[{"id":"1.187528277","rc":[{"batb":[[0,1.42,32725.46]],"ltp":1.43,"tv":294681.08,"id":2249229}]}]}
{"op":"mcm","clk":"4222850093","pt":1631445082082,"mc":[{"id":"1.187528277","rc":[{"batl":[[0,1.43,9342.01]],"ltp":1.43,"tv":294681.08,"id":2249229}]}]}
{"op":"mcm","clk":"4222851465","pt":1631445089199,"mc":[{"id":"1.187528277","rc":[{"batb":[[0,1.42,32775.46]],"ltp":1.43,"tv":294681.08,"id":2249229}]}]}
{"op":"mcm","clk":"4222852167","pt":1631445092714,"mc":[{"id":"1.187528277","rc":[{"trd":[[3.35,22151.93]],"batl":[[0,3.35,145.4]],"ltp":3.35,"tv":70103.01,"id":19924831}],"tv":364784.1}]}
{"op":"mcm","clk":"4222852451","pt":1631445094227,"mc":[{"id":"1.187528277","rc":[{"batb":[[0,1.42,33438.59]],"ltp":1.43,"tv":294681.08,"id":2249229}]}]}
{"op":"mcm","clk":"4222852613","pt":1631445095092,"mc":[{"id":"1.187528277","rc":[{"batb":[[0,1.42,32775.46]],"ltp":1.43,"tv":294681.08,"id":2249229}]}]}
{"op":"mcm","clk":"4222854810","pt":1631445107219,"mc":[{"id":"1.187528277","rc":[{"trd":[[1.42,143491.61]],"batb":[[0,1.42,33436.99]],"ltp":1.42,"tv":294684.28,"id":2249229}],"tv":364787.3}]}
{"op":"mcm","clk":"4222855007","pt":1631445108191,"mc":[{"id":"1.187528277","rc":[{"batb":[[0,1.42,32773.86]],"ltp":1.42,"tv":294684.28,"id":2249229}]}]}
{"op":"mcm","clk":"4222859052","pt":1631445129339,"mc":[{"id":"1.187528277","rc":[{"trd":[[1.43,36569.92]],"batl":[[0,1.43,8531.99]],"ltp":1.43,"tv":296304.32,"id":2249229}],"tv":366407.33}]}
{"op":"mcm","clk":"4222862470","pt":1631445148079,"mc":[{"id":"1.187528277","rc":[{"trd":[[3.3,10742.74]],"batb":[[0,3.3,3528.13]],"ltp":3.3,"tv":70108.13,"id":19924831}],"tv":366412.46}]}
{"op":"mcm","clk":"4222864711","pt":1631445160018,"mc":[{"id":"1.187528277","rc":[{"trd":[[1.43,36639.06]],"batl":[[0,1.43,8497.42]],"ltp":1.43,"tv":296373.45,"id":2249229}],"tv":366481.59}]}
{"op":"mcm","clk":"4222870472","pt":1631445190516,"mc":[{"id":"1.187528277","rc":[{"trd":[[1.42,143497.17]],"batb":[[0,1.42,32771.08]],"ltp":1.42,"tv":296379.01,"id":2249229}],"tv":366487.15}]}
{"op":"mcm","clk":"4222872627","pt":1631445202636,"mc":[{"id":"1.187528277","rc":[{"batb":[[0,1.42,33250.71]],"ltp":1.42,"tv":296379.01,"id":2249229}]}]}
{"op":"mcm","clk":"4222872667","pt":1631445202846,"mc":[{"id":"1.187528277","rc":[{"batb":[[0,1.42,32771.08]],"ltp":1.42,"tv":296379.01,"id":2249229}]}]}
{"op":"mcm","clk":"4222886717","pt":1631445279422,"mc":[{"id":"1.187528277","rc":[{"trd":[[1.42,157380.75]],"batb":[[0,1.42,25829.29]],"ltp":1.42,"tv":310262.59,"id":2249229}],"tv":380370.73}]}
{"op":"mcm","clk":"4222889828","pt":1631445295894,"mc":[{"id":"1.187528277","rc":[{"batb":[[0,1.42,26308.92]],"ltp":1.42,"tv":310262.59,"id":2249229}]}]}
{"op":"mcm","clk":"4222890026","pt":1631445296771,"mc":[{"id":"1.187528277","rc":[{"batb":[[0,1.42,25829.29]],"ltp":1.42,"tv":310262.59,"id":2249229}]}]}
{"op":"mcm","clk":"4222902171","pt":1631445360258,"mc":[{"id":"1.187528277","rc":[{"trd":[[1.42,157593.46]],"batb":[[0,1.42,25722.94]],"ltp":1.42,"tv":310475.3,"id":2249229}],"tv":380583.44}]}
{"op":"mcm","clk":"4222935224","pt":1631445478853,"mc":[{"id":"1.187528277","rc":[{"trd":[[1.43,37984.2]],"batl":[[0,1.43,7824.85]],"ltp":1.43,"tv":311820.44,"id":2249229}],"tv":381928.58}]}
{"op":"mcm","clk":"4222935686","pt":1631445481221,"mc":[{"id":"1.187528277","rc":[{"batb":[[0,1.42,26202.57]],"ltp":1.43,"tv":311820.44,"id":2249229}]}]}
{"op":"mcm","clk":"4222936029","pt":1631445482931,"mc":[{"id":"1.187528277","rc":[{"batb":[[0,1.42,25722.94]],"ltp":1.43,"tv":311820.44,"id":2249229}]}]}
{"op":"mcm","clk":"4222936283","pt":1631445484337,"mc":[{"id":"1.187528277","rc":[{"batb":[[0,1.42,26202.57]],"ltp":1.43,"tv":311820.44,"id":2249229}]}]}
{"op":"mcm","clk":"4222936489","pt":1631445485321,"mc":[{"id":"1.187528277","rc":[{"batb":[[0,1.42,25722.94]],"ltp":1.43,"tv":311820.44,"id":2249229}]}]}
{"op":"mcm","clk":"4222942803","pt":1631445519421,"mc":[{"id":"1.187528277","rc":[{"trd":[[3.35,22442.73]],"batb":[[0,3.35,15.11],[1,3.3,3528.13],[2,3.25,2972.46]],"batl":[[0,3.4,1183.46],[1,3.45,825.04],[2,3.5,715.92]],"ltp":3.35,"tv":70398.93,"id":19924831}],"tv":382219.38}]}
{"op":"mcm","clk":"4222943013","pt":1631445520593,"mc":[{"id":"1.187528277","rc":[{"batl":[[0,1.43,10280.85]],"ltp":1.43,"tv":311820.44,"id":2249229}]}]}
{"op":"mcm","clk":"4222943782","pt":1631445524786,"mc":[{"id":"1.187528277","rc":[{"batl":[[0,1.43,10304.78]],"ltp":1.43,"tv":311820.44,"id":2249229}]}]}
{"op":"mcm","clk":"4222945185","pt":1631445532260,"mc":[{"id":"1.187528277","rc":[{"batb":[[0,1.42,25727.11]],"ltp":1.43,"tv":311820.44,"id":2249229}]}]}
{"op":"mcm","clk":"4222946049","pt":1631445536887,"mc":[{"id":"1.187528277","rc":[{"batb":[[0,3.35,17.77]],"ltp":3.35,"tv":70398.93,"id":19924831}]}]}
{"op":"mcm","clk":"4222946464","pt":1631445539118,"mc":[{"id":"1.187528277","rc":[{"batb":[[0,1.42,26206.74]],"ltp":1.43,"tv":311820.44,"id":2249229}]}]}
{"op":"mcm","clk":"4222946603","pt":1631445539923,"mc":[{"id":"1.187528277","rc":[{"batb":[[0,1.42,25727.11]],"ltp":1.43,"tv":311820.44,"id":2249229}]}]}
{"op":"mcm","clk":"4222946883","pt":1631445541328,"mc":[{"id":"1.187528277","rc":[{"batb":[[0,1.42,26206.74]],"ltp":1.43,"tv":311820.44,"id":2249229}]}]}
{"op":"mcm","clk":"4222947034","pt":1631445542081,"mc":[{"id":"1.187528277","rc":[{"batb":[[0,1.42,25727.11]],"ltp":1.43,"tv":311820.44,"id":2249229}]}]}
{"op":"mcm","clk":"4222947992","pt":1631445547394,"mc":[{"id":"1.187528277","rc":[{"trd":[[1.42,157613.46]],"batb":[[0,1.42,26196.74]],"ltp":1.42,"tv":311840.44,"id":2249229}],"tv":382239.38}]}
{"op":"mcm","clk":"4222948232","pt":1631445548625,"mc":[{"id":"1.187528277","rc":[{"batb":[[0,1.42,25717.11]],"ltp":1.42,"tv":311840.44,"id":2249229}]}]}
{"op":"mcm","clk":"4222954580","pt":1631445581245,"mc":[{"id":"1.187528277","rc":[{"batb":[[0,3.35,20.43]],"ltp":3.35,"tv":70398.93,"id":19924831}]}]}
{"op":"mcm","clk":"4222965540","pt":1631445638172,"mc":[{"id":"1.187528277","rc":[{"batl":[[0,3.4,1159.54],[1,3.45,866.03]],"ltp":3.35,"tv":70398.93,"id":19924831},{"batl":[[1,1.44,11059.33],[2,1.45,6582.11]],"ltp":1.42,"tv":311840.44,"id":2249229}]}]}
{"op":"mcm","clk":"4222970450","pt":1631445663326,"mc":[{"id":"1.187528277","rc":[{"trd":[[1.42,157666.64]],"batb":[[0,1.42,26090.72]],"ltp":1.42,"tv":311893.62,"id":2249229}],"tv":382292.56}]}
{"op":"mcm","clk":"4222970587","pt":1631445664034,"mc":[{"id":"1.187528277","rc":[{"batb":[[0,1.42,25690.52]],"ltp":1.42,"tv":311893.62,"id":2249229}]}]}
{"op":"mcm","clk":"4222978132","pt":1631445703563,"mc":[{"id":"1.187528277","rc":[{"batb":[[0,1.42,26090.72]],"ltp":1.42,"tv":311893.62,"id":2249229}]}]}
{"op":"mcm","clk":"4222978257","pt":1631445704254,"mc":[{"id":"1.187528277","rc":[{"batb":[[0,1.42,25690.52]],"ltp":1.42,"tv":311893.62,"id":2249229}]}]}
{"op":"mcm","clk":"4222996563","pt":1631445803028,"mc":[{"id":"1.187528277","rc":[{"batb":[[0,1.42,26090.72]],"ltp":1.42,"tv":311893.62,"id":2249229}]}]}
{"op":"mcm","clk":"4222996736","pt":1631445803998,"mc":[{"id":"1.187528277","rc":[{"batb":[[0,1.42,25690.52]],"ltp":1.42,"tv":311893.62,"id":2249229}]}]}
{"op":"mcm","clk":"4223001889","pt":1631445832325,"mc":[{"id":"1.187528277","rc":[{"batl":[[1,3.45,1189.74]],"ltp":3.35,"tv":70398.93,"id":19924831}]}]}
{"op":"mcm","clk":"4223004479","pt":1631445846350,"mc":[{"id":"1.187528277","rc":[{"trd":[[1.43,46505.87]],"batl":[[0,1.43,6043.94]],"ltp":1.43,"tv":320415.29,"id":2249229}],"tv":390814.23}]}
{"op":"mcm","clk":"4223004678","pt":1631445847373,"mc":[{"id":"1.187528277","rc":[{"batb":[[0,1.42,25946.35]],"ltp":1.43,"tv":320415.29,"id":2249229}]}]}
{"op":"mcm","clk":"4223013775","pt":1631445894613,"mc":[{"id":"1.187528277","rc":[{"trd":[[3.35,22483.6]],"batb":[[0,3.3,3528.13],[1,3.25,2972.46],[2,3.2,874]],"batl":[[0,3.35,1224.73],[1,3.4,1159.54],[2,3.45,1153.59]],"ltp":3.35,"tv":70439.8,"id":19924831},{"batb":[[0,1.42,26073.11]],"batl":[[0,1.43,3587.94]],"ltp":1.43,"tv":320415.29,"id":2249229}],"tv":390855.1}]}
{"op":"mcm","clk":"4223014073","pt":1631445896302,"mc":[{"id":"1.187528277","rc":[{"batl":[[2,3.45,829.88]],"ltp":3.35,"tv":70439.8,"id":19924831},{"batb":[[0,1.42,26270.22]],"ltp":1.43,"tv":320415.29,"id":2249229}]}]}
{"op":"mcm","clk":"4223014322","pt":1631445897528,"mc":[{"id":"1.187528277","rc":[{"batb":[[0,3.3,3522.92]],"ltp":3.35,"tv":70439.8,"id":19924831},{"batl":[[0,1.43,3817.79]],"ltp":1.43,"tv":320415.29,"id":2249229}]}]}
{"op":"mcm","clk":"4223014605","pt":1631445898710,"mc":[{"id":"1.187528277","rc":[{"batb":[[0,3.3,3505.14]],"ltp":3.35,"tv":70439.8,"id":19924831}]}]}
{"op":"mcm","clk":"4223014734","pt":1631445899334,"mc":[{"id":"1.187528277","rc":[{"batb":[[0,3.3,3499.71]],"ltp":3.35,"tv":70439.8,"id":19924831}]}]}
{"op":"mcm","clk":"4223015003","pt":1631445900621,"mc":[{"id":"1.187528277","rc":[{"batb":[[0,3.3,3492.84]],"ltp":3.35,"tv":70439.8,"id":19924831}]}]}
{"op":"mcm","clk":"4223015252","pt":1631445901640,"mc":[{"id":"1.187528277","rc":[{"batb":[[0,3.3,3439.82]],"ltp":3.35,"tv":70439.8,"id":19924831},{"batb":[[0,1.42,26670.42]],"ltp":1.43,"tv":320415.29,"id":2249229}]}]}
{"op":"mcm","clk":"4223015375","pt":1631445902246,"mc":[{"id":"1.187528277","rc":[{"batl":[[0,3.35,1249.98],[1,3.4,1244.18]],"ltp":3.35,"tv":70439.8,"id":19924831},{"batb":[[0,1.42,26270.22]],"ltp":1.43,"tv":320415.29,"id":2249229}]}]}
{"op":"mcm","clk":"4223016156","pt":1631445905852,"mc":[{"id":"1.187528277","rc":[{"trd":[[1.42,157693.22]],"batb":[[0,1.42,26256.93]],"ltp":1.42,"tv":320441.88,"id":2249229}],"tv":390881.68}]}
{"op":"mcm","clk":"4223017677","pt":1631445912998,"mc":[{"id":"1.187528277","rc":[{"batb":[[0,1.42,26657.13]],"ltp":1.42,"tv":320441.88,"id":2249229}]}]}
{"op":"mcm","clk":"4223017824","pt":1631445913742,"mc":[{"id":"1.187528277","rc":[{"batb":[[0,1.42,26256.93]],"ltp":1.42,"tv":320441.88,"id":2249229}]}]}
{"op":"mcm","clk":"4223018827","pt":1631445918634,"mc":[{"id":"1.187528277","rc":[{"batl":[[0,1.43,3865.64]],"ltp":1.42,"tv":320441.88,"id":2249229}]}]}
{"op":"mcm","clk":"4223018951","pt":1631445919325,"mc":[{"id":"1.187528277","rc":[{"batl":[[0,3.35,1303.71]],"ltp":3.35,"tv":70439.8,"id":19924831},{"trd":[[1.43,54140.9]],"batl":[[0,1.43,48.12]],"ltp":1.43,"tv":328076.91,"id":2249229}],"tv":398516.72}]}
{"op":"mcm","clk":"4223019308","pt":1631445921240,"mc":[{"id":"1.187528277","rc":[{"batb":[[0,1.42,28392.2]],"ltp":1.43,"tv":328076.91,"id":2249229}]}]}
{"op":"mcm","clk":"4223021123","pt":1631445930240,"mc":[{"id":"1.187528277","rc":[{"batl":[[1,1.44,17024.2]],"ltp":1.43,"tv":328076.91,"id":2249229}]}]}
{"op":"mcm","clk":"4223021404","pt":1631445931573,"mc":[{"id":"1.187528277","rc":[{"trd":[[1.43,54237.14]],"batb":[[0,1.43,96.48],[1,1.42,28392.2],[2,1.41,21669.44]],"batl":[[0,1.44,17024.2],[1,1.45,6582.11],[2,1.46,2434.83]],"ltp":1.43,"tv":328173.16,"id":2249229}],"tv":398612.96}]}
{"op":"mcm","clk":"4223021486","pt":1631445931954,"mc":[{"id":"1.187528277","rc":[{"batl":[[0,3.35,2058.71]],"ltp":3.35,"tv":70439.8,"id":19924831}]}]}
{"op":"mcm","clk":"4223024975","pt":1631445951182,"mc":[{"id":"1.187528277","rc":[{"trd":[[3.35,22530.4]],"batl":[[0,3.35,2035.31]],"ltp":3.35,"tv":70486.6,"id":19924831}],"tv":398659.76}]}
{"op":"mcm","clk":"4223028091","pt":1631445967720,"mc":[{"id":"1.187528277","rc":[{"batb":[[1,1.42,28528.62],[2,1.41,21244]],"batl":[[0,1.44,17220.4]],"ltp":1.43,"tv":328173.16,"id":2249229}]}]}
{"op":"mcm","clk":"4223028464","pt":1631445969491,"mc":[{"id":"1.187528277","rc":[{"batb":[[0,3.3,3381.59]],"batl":[[0,3.35,2092.3]],"ltp":3.35,"tv":70486.6,"id":19924831}]}]}
{"op":"mcm","clk":"4223028540","pt":1631445969806,"mc":[{"id":"1.187528277","rc":[{"batl":[[1,3.4,1299.98]],"ltp":3.35,"tv":70486.6,"id":19924831}]}]}
{"op":"mcm","clk":"4223029527","pt":1631445975077,"mc":[{"id":"1.187528277","rc":[{"trd":[[1.43,54430.11]],"batb":[[0,1.42,28528.62],[1,1.41,21244],[2,1.4,25406.12]],"batl":[[0,1.44,17220.71]],"ltp":1.43,"tv":328366.12,"id":2249229}],"tv":398852.72}]}
{"op":"mcm","clk":"4223030380","pt":1631445979704,"mc":[{"id":"1.187528277","rc":[{"batl":[[0,1.43,55.14],[1,1.44,17220.4],[2,1.45,6582.11]],"ltp":1.43,"tv":328366.12,"id":2249229}]}]}
{"op":"mcm","clk":"4223030646","pt":1631445981330,"mc":[{"id":"1.187528277","rc":[{"batl":[[0,1.43,54.84]],"ltp":1.43,"tv":328366.12,"id":2249229}]}]}
{"op":"mcm","clk":"4223031597","pt":1631445986715,"mc":[{"id":"1.187528277","rc":[{"batb":[[0,1.42,28750.62]],"ltp":1.43,"tv":328366.12,"id":2249229}]}]}
{"op":"mcm","clk":"4223033511","pt":1631445996760,"mc":[{"id":"1.187528277","rc":[{"batl":[[1,1.44,17442.4]],"ltp":1.43,"tv":328366.12,"id":2249229}]}]}
{"op":"mcm","clk":"4223034489","pt":1631446002424,"mc":[{"id":"1.187528277","rc":[{"batb":[[0,1.42,29150.82]],"ltp":1.43,"tv":328366.12,"id":2249229}]}]}
{"op":"mcm","clk":"4223034591","pt":1631446003059,"mc":[{"id":"1.187528277","rc":[{"batb":[[0,1.42,28750.62]],"ltp":1.43,"tv":328366.12,"id":2249229}]}]}
{"op":"mcm","clk":"4223035474","pt":1631446007747,"mc":[{"id":"1.187528277","rc":[{"batl":[[0,3.35,2133.35]],"ltp":3.35,"tv":70486.6,"id":19924831}]}]}
{"op":"mcm","clk":"4223040955","pt":1631446036473,"mc":[{"id":"1.187528277","rc":[{"batb":[[1,1.41,21669.44]],"batl":[[0,1.43,63.06]],"ltp":1.43,"tv":328366.12,"id":2249229}]}]}
{"op":"mcm","clk":"4223041045","pt":1631446037007,"mc":[{"id":"1.187528277","rc":[{"batl":[[1,1.44,17246.2]],"ltp":1.43,"tv":328366.12,"id":2249229}]}]}
{"op":"mcm","clk":"4223041290","pt":1631446038397,"mc":[{"id":"1.187528277","rc":[{"batb":[[0,1.42,29150.82]],"ltp":1.43,"tv":328366.12,"id":2249229}]}]}
{"op":"mcm","clk":"4223041423","pt":1631446039090,"mc":[{"id":"1.187528277","rc":[{"batb":[[0,1.42,28750.62]],"ltp":1.43,"tv":328366.12,"id":2249229}]}]}
{"op":"mcm","clk":"4223042410","pt":1631446044600,"mc":[{"id":"1.187528277","rc":[{"batb":[[2,3.2,2617.91]],"ltp":3.35,"tv":70486.6,"id":19924831}]}]}
{"op":"mcm","clk":"4223055819","pt":1631446116350,"mc":[{"id":"1.187528277","rc":[{"trd":[[1.43,54556.24]],"batb":[[0,1.43,36.93],[1,1.42,28750.62],[2,1.41,21669.44]],"batl":[[0,1.44,17246.2],[1,1.45,6582.11],[2,1.46,2434.83]],"ltp":1.43,"tv":328492.25,"id":2249229}],"tv":398978.86}]}
{"op":"mcm","clk":"4223055908","pt":1631446116888,"mc":[{"id":"1.187528277","rc":[{"batb":[[0,1.43,40.42]],"ltp":1.43,"tv":328492.25,"id":2249229}]}]}
{"op":"mcm","clk":"4223060038","pt":1631446142351,"mc":[{"id":"1.187528277","rc":[{"batb":[[0,1.43,140.42]],"ltp":1.43,"tv":328492.25,"id":2249229}]}]}
{"op":"mcm","clk":"4223061216","pt":1631446146908,"mc":[{"id":"1.187528277","rc":[{"batl":[[0,3.35,2163.2]],"ltp":3.35,"tv":70486.6,"id":19924831},{"batl":[[0,1.44,17315.64]],"ltp":1.43,"tv":328492.25,"id":2249229}]}]}
{"op":"mcm","clk":"4223067730","pt":1631446171546,"mc":[{"id":"1.187528277","rc":[{"batb":[[2,1.41,21244]],"ltp":1.43,"tv":328492.25,"id":2249229}]}]}
{"op":"mcm","clk":"4223067928","pt":1631446172453,"mc":[{"id":"1.187528277","rc":[{"batb":[[1,1.42,28754.86]],"batl":[[0,1.44,17507.8]],"ltp":1.43,"tv":328492.25,"id":2249229}]}]}
{"op":"mcm","clk":"4223068694","pt":1631446176142,"mc":[{"id":"1.187528277","rc":[{"trd":[[1.43,54785.94]],"batb":[[0,1.43,25.57]],"ltp":1.43,"tv":328721.95,"id":2249229}],"tv":399208.55}]}
{"op":"mcm","clk":"4223074613","pt":1631446205709,"mc":[{"id":"1.187528277","rc":[{"trd":[[1.43,54837.08]],"batb":[[0,1.42,28754.86],[1,1.41,21244],[2,1.4,25406.12]],"batl":[[0,1.43,46.73],[1,1.44,17507.8],[2,1.45,6582.11]],"ltp":1.43,"tv":328773.09,"id":2249229}],"tv":399259.69}]}
{"op":"mcm","clk":"4223074691","pt":1631446206097,"mc":[{"id":"1.187528277","rc":[{"batb":[[0,3.3,3411.89]],"batl":[[0,3.35,2133.35]],"ltp":3.35,"tv":70486.6,"id":19924831},{"batb":[[0,1.42,28825.28]],"batl":[[1,1.44,17438.36]],"ltp":1.43,"tv":328773.09,"id":2249229}]}]}
{"op":"mcm","clk":"4223078535","pt":1631446223645,"mc":[{"id":"1.187528277","rc":[{"batb":[[0,1.42,29225.48]],"ltp":1.43,"tv":328773.09,"id":2249229}]}]}
{"op":"mcm","clk":"4223078570","pt":1631446223856,"mc":[{"id":"1.187528277","rc":[{"batb":[[0,1.42,28825.28]],"ltp":1.43,"tv":328773.09,"id":2249229}]}]}
{"op":"mcm","clk":"4223078789","pt":1631446224932,"mc":[{"id":"1.187528277","rc":[{"batb":[[0,1.42,28835.42]],"ltp":1.43,"tv":328773.09,"id":2249229}]}]}
{"op":"mcm","clk":"4223080416","pt":1631446233551,"mc":[{"id":"1.187528277","rc":[{"batb":[[1,1.41,21669.44]],"batl":[[0,1.43,53.74]],"ltp":1.43,"tv":328773.09,"id":2249229}]}]}
{"op":"mcm","clk":"4223080505","pt":1631446233972,"mc":[{"id":"1.187528277","rc":[{"batl":[[1,1.44,17246.2]],"ltp":1.43,"tv":328773.09,"id":2249229}]}]}
{"op":"mcm","clk":"4223081820","pt":1631446240476,"mc":[{"id":"1.187528277","rc":[{"trd":[[3.3,10913.55]],"batb":[[0,3.3,3326.49]],"ltp":3.3,"tv":70657.4,"id":19924831}],"tv":399430.5}]}
{"op":"mcm","clk":"4223082107","pt":1631446241964,"mc":[{"id":"1.187528277","rc":[{"batb":[[0,1.42,29235.62]],"ltp":1.43,"tv":328773.09,"id":2249229}]}]}
{"op":"mcm","clk":"4223082359","pt":1631446243041,"mc":[{"id":"1.187528277","rc":[{"batb":[[0,1.42,28835.42]],"ltp":1.43,"tv":328773.09,"id":2249229}]}]}
{"op":"mcm","clk":"4223082833","pt":1631446245451,"mc":[{"id":"1.187528277","rc":[{"batb":[[0,1.42,29235.62]],"ltp":1.43,"tv":328773.09,"id":2249229}]}]}
{"op":"mcm","clk":"4223082915","pt":1631446245872,"mc":[{"id":"1.187528277","rc":[{"batb":[[0,1.42,28835.42]],"ltp":1.43,"tv":328773.09,"id":2249229}]}]}
{"op":"mcm","clk":"4223092670","pt":1631446295462,"mc":[{"id":"1.187528277","rc":[{"trd":[[3.35,22547.82]],"batl":[[0,3.35,2124.64]],"ltp":3.35,"tv":70674.83,"id":19924831}],"tv":399447.92}]}
{"op":"mcm","clk":"4223092812","pt":1631446296186,"mc":[{"id":"1.187528277","rc":[{"batb":[[0,1.42,29235.62]],"ltp":1.43,"tv":328773.09,"id":2249229}]}]}
{"op":"mcm","clk":"4223092999","pt":1631446296854,"mc":[{"id":"1.187528277","rc":[{"batb":[[0,1.42,28835.42]],"ltp":1.43,"tv":328773.09,"id":2249229}]}]}
{"op":"mcm","clk":"4223093284","pt":1631446298248,"mc":[{"id":"1.187528277","rc":[{"trd":[[1.42,157695.26]],"batb":[[0,1.42,28834.4]],"ltp":1.42,"tv":328775.13,"id":2249229}],"tv":399449.96}]}
{"op":"mcm","clk":"4223098618","pt":1631446322903,"mc":[{"id":"1.187528277","rc":[{"batl":[[0,1.43,74.12]],"ltp":1.42,"tv":328775.13,"id":2249229}]}]}
{"op":"mcm","clk":"4223102565","pt":1631446343494,"mc":[{"id":"1.187528277","rc":[{"batl":[[0,1.43,78.24]],"ltp":1.42,"tv":328775.13,"id":2249229}]}]}
{"op":"mcm","clk":"4223129440","pt":1631446480679,"mc":[{"id":"1.187528277","rc":[{"batl":[[0,3.35,2117.78]],"ltp":3.35,"tv":70674.83,"id":19924831}]}]}
{"op":"mcm","clk":"4223130725","pt":1631446487289,"mc":[{"id":"1.187528277","rc":[{"trd":[[1.43,54993.55]],"batl":[[0,1.44,17246.2],[1,1.45,6582.11],[2,1.46,2434.83]],"ltp":1.43,"tv":328931.59,"id":2249229}],"tv":399606.42}]}
{"op":"mcm","clk":"4223130833","pt":1631446487887,"mc":[{"id":"1.187528277","rc":[{"batb":[[0,3.3,3296.19]],"ltp":3.35,"tv":70674.83,"id":19924831},{"batl":[[0,1.44,17315.64]],"ltp":1.43,"tv":328931.59,"id":2249229}]}]}
{"op":"mcm","clk":"4223131948","pt":1631446493625,"mc":[{"id":"1.187528277","rc":[{"batb":[[0,1.43,72.3],[1,1.42,28834.4],[2,1.41,21669.44]],"ltp":1.43,"tv":328931.59,"id":2249229}]}]}
{"op":"mcm","clk":"4223132009","pt":1631446493898,"mc":[{"id":"1.187528277","rc":[{"batl":[[0,3.35,2147.63]],"ltp":3.35,"tv":70674.83,"id":19924831},{"batb":[[1,1.42,28763.98]],"ltp":1.43,"tv":328931.59,"id":2249229}]}]}
{"op":"mcm","clk":"4223132485","pt":1631446496407,"mc":[{"id":"1.187528277","rc":[{"batb":[[2,1.41,21244]],"ltp":1.43,"tv":328931.59,"id":2249229}]}]}
{"op":"mcm","clk":"4223132662","pt":1631446497315,"mc":[{"id":"1.187528277","rc":[{"batb":[[1,1.42,28769.7]],"batl":[[0,1.44,17502.34]],"ltp":1.43,"tv":328931.59,"id":2249229}]}]}
{"op":"mcm","clk":"4223132871","pt":1631446498527,"mc":[{"id":"1.187528277","rc":[{"batl":[[0,3.35,2151.74]],"ltp":3.35,"tv":70674.83,"id":19924831}]}]}
{"op":"mcm","clk":"4223132960","pt":1631446498911,"mc":[{"id":"1.187528277","rc":[{"batl":[[1,3.4,1304]],"ltp":3.35,"tv":70674.83,"id":19924831}]}]}
{"op":"mcm","clk":"4223133405","pt":1631446501429,"mc":[{"id":"1.187528277","rc":[{"trd":[[3.3,11361.06]],"batb":[[0,3.3,3072.43]],"ltp":3.3,"tv":71122.35,"id":19924831}],"tv":400053.94}]}
{"op":"mcm","clk":"4223134836","pt":1631446508724,"mc":[{"id":"1.187528277","rc":[{"trd":[[3.3,11389.06]],"batb":[[0,3.3,3058.43]],"ltp":3.3,"tv":71150.35,"id":19924831}],"tv":400081.94}]}
{"op":"mcm","clk":"4223136262","pt":1631446516251,"mc":[{"id":"1.187528277","rc":[{"batb":[[2,1.41,41244]],"ltp":1.43,"tv":328931.59,"id":2249229}]}]}
{"op":"mcm","clk":"4223141353","pt":1631446541354,"mc":[{"id":"1.187528277","rc":[{"trd":[[1.43,55137.54]],"batb":[[0,1.42,28770],[1,1.41,41244],[2,1.4,45406.12]],"ltp":1.43,"tv":329075.59,"id":2249229}],"tv":400225.94}]}
{"op":"mcm","clk":"4223141461","pt":1631446541839,"mc":[{"id":"1.187528277","rc":[{"batl":[[0,3.35,2121.89]],"ltp":3.3,"tv":71150.35,"id":19924831},{"batb":[[0,1.42,28840.42]],"ltp":1.43,"tv":329075.59,"id":2249229}]}]}
{"op":"mcm","clk":"4223144907","pt":1631446558669,"mc":[{"id":"1.187528277","rc":[{"batl":[[0,3.35,2115.03]],"ltp":3.3,"tv":71150.35,"id":19924831}]}]}
{"op":"mcm","clk":"4223147267","pt":1631446569481,"mc":[{"id":"1.187528277","rc":[{"trd":[[3.35,22654.18]],"batl":[[0,3.35,2061.85]],"ltp":3.35,"tv":71256.7,"id":19924831}],"tv":400332.3}]}
{"op":"mcm","clk":"4223150135","pt":1631446583710,"mc":[{"id":"1.187528277","rc":[{"trd":[[1.43,55138.15]],"batb":[[0,1.42,28840.12]],"batl":[[0,1.43,156.41],[1,1.44,17502.34],[2,1.45,6582.11]],"ltp":1.43,"tv":329076.2,"id":2249229}],"tv":400332.91}]}
{"op":"mcm","clk":"4223150222","pt":1631446584229,"mc":[{"id":"1.187528277","rc":[{"batb":[[0,3.3,3088.73]],"ltp":3.35,"tv":71256.7,"id":19924831},{"batl":[[1,1.44,17432.9]],"ltp":1.43,"tv":329076.2,"id":2249229}]}]}
{"op":"mcm","clk":"4223153120","pt":1631446598233,"mc":[{"id":"1.187528277","rc":[{"batb":[[0,1.42,29240.32]],"ltp":1.43,"tv":329076.2,"id":2249229}]}]}
{"op":"mcm","clk":"4223153246","pt":1631446598934,"mc":[{"id":"1.187528277","rc":[{"batb":[[0,1.42,28840.12]],"ltp":1.43,"tv":329076.2,"id":2249229}]}]}
{"op":"mcm","clk":"4223155741","pt":1631446610647,"mc":[{"id":"1.187528277","rc":[{"batl":[[0,1.43,179.87],[1,1.44,17246.2]],"ltp":1.43,"tv":329076.2,"id":2249229}]}]}
{"op":"mcm","clk":"4223159449","pt":1631446629664,"mc":[{"id":"1.187528277","rc":[{"trd":[[1.42,157700.53]],"batb":[[0,1.42,28837.48]],"ltp":1.42,"tv":329081.48,"id":2249229}],"tv":400338.18}]}
{"op":"mcm","clk":"4223161532","pt":1631446640654,"mc":[{"id":"1.187528277","rc":[{"batb":[[0,1.42,29101.33]],"ltp":1.42,"tv":329081.48,"id":2249229}]}]}
{"op":"mcm","clk":"4223170449","pt":1631446686925,"mc":[{"id":"1.187528277","rc":[{"batl":[[0,1.43,183.38]],"ltp":1.42,"tv":329081.48,"id":2249229}]}]}
{"op":"mcm","clk":"4223170739","pt":1631446688224,"mc":[{"id":"1.187528277","rc":[{"batb":[[0,1.42,29501.53]],"ltp":1.42,"tv":329081.48,"id":2249229}]}]}
{"op":"mcm","clk":"4223170854","pt":1631446688831,"mc":[{"id":"1.187528277","rc":[{"batb":[[0,1.42,29101.33]],"ltp":1.42,"tv":329081.48,"id":2249229}]}]}
{"op":"mcm","clk":"4223177150","pt":1631446723383,"mc":[{"id":"1.187528277","rc":[{"trd":[[1.42,157705.85]],"batb":[[0,1.42,29098.67]],"ltp":1.42,"tv":329086.79,"id":2249229}],"tv":400343.5}]}
{"op":"mcm","clk":"4223177469","pt":1631446725180,"mc":[{"id":"1.187528277","rc":[{"trd":[[1.42,157725.85]],"batb":[[0,1.42,29088.67]],"ltp":1.42,"tv":329106.79,"id":2249229}],"tv":400363.5}]}
{"op":"mcm","clk":"4223185489","pt":1631446769251,"mc":[{"id":"1.187528277","rc":[{"trd":[[3.3,11689.07]],"batb":[[0,3.3,2938.73]],"ltp":3.3,"tv":71556.71,"id":19924831}],"tv":400663.51}]}
{"op":"mcm","clk":"4223187181","pt":1631446778065,"mc":[{"id":"1.187528277","rc":[{"trd":[[3.3,11742.24]],"batb":[[0,3.3,2912.14]],"ltp":3.3,"tv":71609.88,"id":19924831}],"tv":400716.68}]}
{"op":"mcm","clk":"4223188688","pt":1631446786290,"mc":[{"id":"1.187528277","rc":[{"batl":[[0,1.43,255.69]],"ltp":1.42,"tv":329106.79,"id":2249229}]}]}
{"op":"mcm","clk":"4223189066","pt":1631446788370,"mc":[{"id":"1.187528277","rc":[{"batb":[[0,1.42,29488.87]],"ltp":1.42,"tv":329106.79,"id":2249229}]}]}
{"op":"mcm","clk":"4223189457","pt":1631446790443,"mc":[{"id":"1.187528277","rc":[{"batb":[[0,1.42,29088.67]],"ltp":1.42,"tv":329106.79,"id":2249229}]}]}
{"op":"mcm","clk":"4223189926","pt":1631446793052,"mc":[{"id":"1.187528277","rc":[{"batl":[[0,1.43,267.06]],"ltp":1.42,"tv":329106.79,"id":2249229}]}]}
{"op":"mcm","clk":"4223195674","pt":1631446822517,"mc":[{"id":"1.187528277","rc":[{"trd":[[1.42,157765.85]],"batb":[[0,1.42,29468.87]],"ltp":1.42,"tv":329146.79,"id":2249229}],"tv":400756.68}]}
{"op":"mcm","clk":"4223195757","pt":1631446822906,"mc":[{"id":"1.187528277","rc":[{"batb":[[0,1.42,29068.67]],"ltp":1.42,"tv":329146.79,"id":2249229}]}]}
{"op":"mcm","clk":"4223204314","pt":1631446864576,"mc":[{"id":"1.187528277","rc":[{"trd":[[1.43,55672.26]],"batb":[[0,1.43,610.69],[1,1.42,29068.67],[2,1.41,41244]],"batl":[[0,1.44,17246.2],[1,1.45,6582.11],[2,1.46,2434.83]],"ltp":1.43,"tv":329680.91,"id":2249229}],"tv":401290.79}]}
{"op":"mcm","clk":"4223204394","pt":1631446864960,"mc":[{"id":"1.187528277","rc":[{"batb":[[0,3.3,2881.84]],"batl":[[0,3.35,2091.7]],"ltp":3.3,"tv":71609.88,"id":19924831},{"batb":[[1,1.42,28998.25]],"batl":[[0,1.44,17315.64]],"ltp":1.43,"tv":329680.91,"id":2249229}]}]}
{"op":"mcm","clk":"4223204585","pt":1631446865869,"mc":[{"id":"1.187528277","rc":[{"batb":[[0,3.3,1780.84]],"ltp":3.3,"tv":71609.88,"id":19924831}]}]}
{"op":"mcm","clk":"4223206459","pt":1631446875179,"mc":[{"id":"1.187528277","rc":[{"batb":[[0,3.3,2367.93]],"ltp":3.3,"tv":71609.88,"id":19924831}]}]}
{"op":"mcm","clk":"4223207821","pt":1631446881680,"mc":[{"id":"1.187528277","rc":[{"batb":[[1,1.42,29017.99]],"batl":[[0,1.44,17483.5]],"ltp":1.43,"tv":329680.91,"id":2249229}]}]}
{"op":"mcm","clk":"4223208185","pt":1631446883494,"mc":[{"id":"1.187528277","rc":[{"batb":[[0,3.3,2355.41]],"batl":[[0,3.35,2099.84]],"ltp":3.3,"tv":71609.88,"id":19924831}]}]}
{"op":"mcm","clk":"4223208242","pt":1631446883763,"mc":[{"id":"1.187528277","rc":[{"batl":[[1,3.4,1311.97]],"ltp":3.3,"tv":71609.88,"id":19924831}]}]}
{"op":"mcm","clk":"4223217300","pt":1631446928324,"mc":[{"id":"1.187528277","rc":[{"batl":[[0,1.44,19191.59]],"ltp":1.43,"tv":329680.91,"id":2249229}]}]}
{"op":"mcm","clk":"4223218208","pt":1631446932936,"mc":[{"id":"1.187528277","rc":[{"batb":[[1,1.42,29872.04]],"ltp":1.43,"tv":329680.91,"id":2249229}]}]}
{"op":"mcm","clk":"4223222290","pt":1631446954082,"mc":[{"id":"1.187528277","rc":[{"trd":[[1.43,55676.27]],"batb":[[0,1.43,608.68]],"ltp":1.43,"tv":329684.91,"id":2249229}],"tv":401294.8}]}
{"op":"mcm","clk":"4223223131","pt":1631446958456,"mc":[{"id":"1.187528277","rc":[{"trd":[[1.43,55682.02]],"batb":[[0,1.43,605.81]],"ltp":1.43,"tv":329690.67,"id":2249229}],"tv":401300.55}]}
{"op":"mcm","clk":"4223224651","pt":1631446965789,"mc":[{"id":"1.187528277","rc":[{"trd":[[1.44,5560.31]],"batl":[[0,1.44,19175.63]],"ltp":1.44,"tv":329722.58,"id":2249229}],"tv":401332.46}]}
{"op":"mcm","clk":"4223230349","pt":1631446993259,"mc":[{"id":"1.187528277","rc":[{"batb":[[0,1.43,712.17]],"ltp":1.44,"tv":329722.58,"id":2249229}]}]}
{"op":"mcm","clk":"4223235047","pt":1631447017823,"mc":[{"id":"1.187528277","rc":[{"trd":[[1.43,55889.59]],"batb":[[0,1.43,608.38]],"ltp":1.43,"tv":329930.14,"id":2249229}],"tv":401540.02}]}
{"op":"mcm","clk":"4223265609","pt":1631447171706,"mc":[{"id":"1.187528277","rc":[{"batb":[[0,3.3,3704.25]],"batl":[[0,3.35,2069.99]],"ltp":3.3,"tv":71609.88,"id":19924831},{"trd":[[1.43,57106.34]],"batb":[[0,1.42,29942.46],[1,1.41,41244],[2,1.4,45406.12]],"batl":[[0,1.43,8391.63],[1,1.44,19106.19],[2,1.45,6582.11]],"ltp":1.43,"tv":331146.89,"id":2249229}],"tv":402756.78}]}
{"op":"mcm","clk":"4223265708","pt":1631447172198,"mc":[{"id":"1.187528277","rc":[{"batl":[[0,3.35,2016.26]],"ltp":3.3,"tv":71609.88,"id":19924831},{"trd":[[1.43,57522.59]],"batl":[[0,1.43,8183.51]],"ltp":1.43,"tv":331563.14,"id":2249229}],"tv":403173.03}]}
{"op":"mcm","clk":"4223270628","pt":1631447197340,"mc":[{"id":"1.187528277","rc":[{"batl":[[0,3.35,1962.47]],"ltp":3.3,"tv":71609.88,"id":19924831},{"batl":[[0,1.43,8303.08]],"ltp":1.43,"tv":331563.14,"id":2249229}]}]}
{"op":"mcm","clk":"4223274948","pt":1631447221577,"mc":[{"id":"1.187528277","rc":[{"batl":[[1,1.44,18938.33]],"ltp":1.43,"tv":331563.14,"id":2249229}]}]}
{"op":"mcm","clk":"4223283713","pt":1631447269548,"mc":[{"id":"1.187528277","rc":[{"batl":[[0,1.43,8407.87]],"ltp":1.43,"tv":331563.14,"id":2249229}]}]}
{"op":"mcm","clk":"4223289885","pt":1631447300985,"mc":[{"id":"1.187528277","rc":[{"batb":[[0,1.42,29946.97]],"ltp":1.43,"tv":331563.14,"id":2249229}]}]}
{"op":"mcm","clk":"4223302367","pt":1631447363553,"mc":[{"id":"1.187528277","rc":[{"trd":[[1.42,158409.8]],"batb":[[0,1.42,30036.63]],"ltp":1.42,"tv":332207.09,"id":2249229}],"tv":403816.98}]}
{"op":"mcm","clk":"4223302461","pt":1631447364146,"mc":[{"id":"1.187528277","rc":[{"batb":[[0,1.42,29625]],"ltp":1.42,"tv":332207.09,"id":2249229}]}]}
{"op":"mcm","clk":"4223313398","pt":1631447423609,"mc":[{"id":"1.187528277","rc":[{"trd":[[1.43,57531.72]],"batl":[[0,1.43,8398.74]],"ltp":1.43,"tv":332216.22,"id":2249229}],"tv":403826.11}]}
{"op":"mcm","clk":"4223315574","pt":1631447435853,"mc":[{"id":"1.187528277","rc":[{"trd":[[3.35,22686.95]],"batl":[[0,3.35,1946.08]],"ltp":3.35,"tv":71642.65,"id":19924831}],"tv":403858.87}]}
{"op":"mcm","clk":"4223315809","pt":1631447437140,"mc":[{"id":"1.187528277","rc":[{"batb":[[0,1.42,30028.46]],"ltp":1.43,"tv":332216.22,"id":2249229}]}]}
{"op":"mcm","clk":"4223315956","pt":1631447437857,"mc":[{"id":"1.187528277","rc":[{"batb":[[0,1.42,29625]],"ltp":1.43,"tv":332216.22,"id":2249229}]}]}
{"op":"mcm","clk":"4223319531","pt":1631447457142,"mc":[{"id":"1.187528277","rc":[{"batb":[[0,1.42,30028.46]],"ltp":1.43,"tv":332216.22,"id":2249229}]}]}
{"op":"mcm","clk":"4223319751","pt":1631447458471,"mc":[{"id":"1.187528277","rc":[{"batb":[[0,1.42,29625]],"ltp":1.43,"tv":332216.22,"id":2249229}]}]}
{"op":"mcm","clk":"4223322448","pt":1631447473557,"mc":[{"id":"1.187528277","rc":[{"batb":[[0,1.42,30773.45]],"ltp":1.43,"tv":332216.22,"id":2249229}]}]}
{"op":"mcm","clk":"4223326314","pt":1631447495522,"mc":[{"id":"1.187528277","rc":[{"batb":[[0,1.42,31176.91]],"ltp":1.43,"tv":332216.22,"id":2249229}]}]}
{"op":"mcm","clk":"4223326443","pt":1631447496314,"mc":[{"id":"1.187528277","rc":[{"batb":[[0,1.42,30773.45]],"ltp":1.43,"tv":332216.22,"id":2249229}]}]}
{"op":"mcm","clk":"4223327505","pt":1631447502805,"mc":[{"id":"1.187528277","rc":[{"trd":[[1.43,59371.72]],"batl":[[0,1.43,7478.74]],"ltp":1.43,"tv":334056.22,"id":2249229}],"tv":405698.87}]}
{"op":"mcm","clk":"4223329222","pt":1631447513709,"mc":[{"id":"1.187528277","rc":[{"batb":[[0,1.42,31255.45],[1,1.41,40762]],"ltp":1.43,"tv":334056.22,"id":2249229}]}]}
{"op":"mcm","clk":"4223331411","pt":1631447526341,"mc":[{"id":"1.187528277","rc":[{"batb":[[0,3.3,4104.25]],"ltp":3.35,"tv":71642.65,"id":19924831}]}]}
{"op":"mcm","clk":"4223331605","pt":1631447527459,"mc":[{"id":"1.187528277","rc":[{"batb":[[0,1.42,31658.91]],"ltp":1.43,"tv":334056.22,"id":2249229}]}]}
{"op":"mcm","clk":"4223331691","pt":1631447527945,"mc":[{"id":"1.187528277","rc":[{"batb":[[0,1.42,31255.45]],"ltp":1.43,"tv":334056.22,"id":2249229}]}]}
{"op":"mcm","clk":"4223332120","pt":1631447530674,"mc":[{"id":"1.187528277","rc":[{"trd":[[3.3,11752.25]],"batb":[[0,3.3,4099.25]],"ltp":3.3,"tv":71652.65,"id":19924831},{"batb":[[0,1.42,31658.91]],"ltp":1.43,"tv":334056.22,"id":2249229}],"tv":405708.88}]}
{"op":"mcm","clk":"4223332235","pt":1631447531370,"mc":[{"id":"1.187528277","rc":[{"batb":[[0,1.42,31255.45]],"ltp":1.43,"tv":334056.22,"id":2249229}]}]}
{"op":"mcm","clk":"4223339123","pt":1631447572708,"mc":[{"id":"1.187528277","rc":[{"trd":[[1.43,59430.22]],"batl":[[0,1.43,7449.49]],"ltp":1.43,"tv":334114.72,"id":2249229}],"tv":405767.38}]}
{"op":"mcm","clk":"4223339458","pt":1631447574617,"mc":[{"id":"1.187528277","rc":[{"batb":[[0,1.42,31658.91]],"ltp":1.43,"tv":334114.72,"id":2249229}]}]}
{"op":"mcm","clk":"4223339622","pt":1631447575325,"mc":[{"id":"1.187528277","rc":[{"batb":[[0,1.42,31255.45]],"ltp":1.43,"tv":334114.72,"id":2249229}]}]}
{"op":"mcm","clk":"4223341805","pt":1631447588827,"mc":[{"id":"1.187528277","rc":[{"batl":[[0,1.43,7521.79]],"ltp":1.43,"tv":334114.72,"id":2249229}]}]}
{"op":"mcm","clk":"4223342007","pt":1631447590150,"mc":[{"id":"1.187528277","rc":[{"batb":[[0,1.42,31658.91]],"ltp":1.43,"tv":334114.72,"id":2249229}]}]}
{"op":"mcm","clk":"4223342159","pt":1631447591047,"mc":[{"id":"1.187528277","rc":[{"batb":[[0,1.42,31255.45]],"ltp":1.43,"tv":334114.72,"id":2249229}]}]}
{"op":"mcm","clk":"4223342664","pt":1631447594145,"mc":[{"id":"1.187528277","rc":[{"trd":[[1.42,158413.93]],"batb":[[0,1.42,31253.38]],"ltp":1.42,"tv":334118.86,"id":2249229}],"tv":405771.51}]}
{"op":"mcm","clk":"4223343585","pt":1631447599545,"mc":[{"id":"1.187528277","rc":[{"trd":[[1.43,59642.93]],"batb":[[0,1.42,31656.84]],"batl":[[0,1.43,7415.44]],"ltp":1.43,"tv":334331.57,"id":2249229}],"tv":405984.22}]}
{"op":"mcm","clk":"4223343680","pt":1631447600174,"mc":[{"id":"1.187528277","rc":[{"batb":[[0,1.42,31253.38]],"ltp":1.43,"tv":334331.57,"id":2249229}]}]}
{"op":"mcm","clk":"4223347152","pt":1631447622283,"mc":[{"id":"1.187528277","rc":[{"trd":[[1.43,59709.94]],"batl":[[0,1.43,7381.94]],"ltp":1.43,"tv":334398.57,"id":2249229}],"tv":406051.23}]}
{"op":"mcm","clk":"4223353760","pt":1631447662522,"mc":[{"id":"1.187528277","rc":[{"batb":[[0,1.42,31656.84]],"ltp":1.43,"tv":334398.57,"id":2249229}]}]}
{"op":"mcm","clk":"4223353789","pt":1631447662723,"mc":[{"id":"1.187528277","rc":[{"batb":[[0,1.42,31253.38]],"ltp":1.43,"tv":334398.57,"id":2249229}]}]}
{"op":"mcm","clk":"4223354580","pt":1631447667645,"mc":[{"id":"1.187528277","rc":[{"trd":[[3.35,22696.95]],"batl":[[0,3.35,1941.08]],"ltp":3.35,"tv":71662.66,"id":19924831}],"tv":406061.23}]}
{"op":"mcm","clk":"4223354883","pt":1631447669635,"mc":[{"id":"1.187528277","rc":[{"batb":[[0,1.42,31656.84]],"ltp":1.43,"tv":334398.57,"id":2249229}]}]}
{"op":"mcm","clk":"4223354993","pt":1631447670360,"mc":[{"id":"1.187528277","rc":[{"batb":[[0,1.42,31253.38]],"ltp":1.43,"tv":334398.57,"id":2249229}]}]}
{"op":"mcm","clk":"4223356053","pt":1631447677037,"mc":[{"id":"1.187528277","rc":[{"batl":[[1,1.44,18991.51],[2,1.45,6528.93]],"ltp":1.43,"tv":334398.57,"id":2249229}]}]}
{"op":"mcm","clk":"4223360443","pt":1631447705657,"mc":[{"id":"1.187528277","rc":[{"batl":[[0,1.43,7384.6]],"ltp":1.43,"tv":334398.57,"id":2249229}]}]}
{"op":"mcm","clk":"4223360609","pt":1631447706513,"mc":[{"id":"1.187528277","rc":[{"batb":[[0,1.42,31656.84]],"ltp":1.43,"tv":334398.57,"id":2249229}]}]}
{"op":"mcm","clk":"4223360713","pt":1631447707150,"mc":[{"id":"1.187528277","rc":[{"batb":[[0,1.42,31253.38]],"ltp":1.43,"tv":334398.57,"id":2249229}]}]}
{"op":"mcm","clk":"4223361585","pt":1631447712561,"mc":[{"id":"1.187528277","rc":[{"trd":[[3.35,23228.74]],"batl":[[0,3.35,1675.19]],"ltp":3.35,"tv":72194.44,"id":19924831}],"tv":406593.02}]}
{"op":"mcm","clk":"4223362292","pt":1631447717076,"mc":[{"id":"1.187528277","rc":[{"trd":[[1.43,59714.04]],"batl":[[0,1.43,7382.55]],"ltp":1.43,"tv":334402.67,"id":2249229}],"tv":406597.12}]}
{"op":"mcm","clk":"4223362532","pt":1631447718543,"mc":[{"id":"1.187528277","rc":[{"batb":[[0,1.42,31656.84]],"ltp":1.43,"tv":334402.67,"id":2249229}]}]}
{"op":"mcm","clk":"4223362638","pt":1631447719273,"mc":[{"id":"1.187528277","rc":[{"batb":[[0,1.42,31253.38]],"ltp":1.43,"tv":334402.67,"id":2249229}]}]}
{"op":"mcm","clk":"4223367104","pt":1631447747664,"mc":[{"id":"1.187528277","rc":[{"batb":[[0,1.42,31656.84]],"batl":[[0,1.43,9126.46]],"ltp":1.43,"tv":334402.67,"id":2249229}]}]}
{"op":"mcm","clk":"4223367149","pt":1631447747977,"mc":[{"id":"1.187528277","rc":[{"batb":[[0,1.42,31253.38]],"ltp":1.43,"tv":334402.67,"id":2249229}]}]}
{"op":"mcm","clk":"4223375602","pt":1631447800251,"mc":[{"id":"1.187528277","rc":[{"batl":[[2,3.45,880.49]],"ltp":3.35,"tv":72194.44,"id":19924831}]}]}
{"op":"mcm","clk":"4223376867","pt":1631447807636,"mc":[{"id":"1.187528277","rc":[{"trd":[[1.42,158433.93]],"batb":[[0,1.42,31243.38]],"ltp":1.42,"tv":334422.67,"id":2249229}],"tv":406617.12}]}
{"op":"mcm","clk":"4223382082","pt":1631447840489,"mc":[{"id":"1.187528277","rc":[{"batb":[[0,1.42,31646.84]],"ltp":1.42,"tv":334422.67,"id":2249229}]}]}
{"op":"mcm","clk":"4223382175","pt":1631447841096,"mc":[{"id":"1.187528277","rc":[{"batb":[[0,1.42,31243.38]],"ltp":1.42,"tv":334422.67,"id":2249229}]}]}
{"op":"mcm","clk":"4223392281","pt":1631447907872,"mc":[{"id":"1.187528277","rc":[{"batl":[[0,1.43,9139.23]],"ltp":1.42,"tv":334422.67,"id":2249229}]}]}
{"op":"mcm","clk":"4223392487","pt":1631447909385,"mc":[{"id":"1.187528277","rc":[{"batb":[[0,1.42,31646.84]],"ltp":1.42,"tv":334422.67,"id":2249229}]}]}
{"op":"mcm","clk":"4223392604","pt":1631447910162,"mc":[{"id":"1.187528277","rc":[{"batb":[[0,1.42,31243.38]],"ltp":1.42,"tv":334422.67,"id":2249229}]}]}
{"op":"mcm","clk":"4223397342","pt":1631447940506,"mc":[{"id":"1.187528277","rc":[{"trd":[[3.3,11786.41]],"batb":[[0,3.3,4082.17]],"ltp":3.3,"tv":72228.6,"id":19924831},{"trd":[[1.42,158459.46]],"batb":[[0,1.42,31230.62]],"batl":[[0,1.43,9126.46]],"ltp":1.42,"tv":334448.19,"id":2249229}],"tv":406676.8}]}
{"op":"mcm","clk":"4223402821","pt":1631447973458,"mc":[{"id":"1.187528277","rc":[{"batb":[[0,1.42,31634.08]],"ltp":1.42,"tv":334448.19,"id":2249229}]}]}
{"op":"mcm","clk":"4223402897","pt":1631447973946,"mc":[{"id":"1.187528277","rc":[{"batb":[[0,1.42,31230.62]],"ltp":1.42,"tv":334448.19,"id":2249229}]}]}
{"op":"mcm","clk":"4223409631","pt":1631448011190,"mc":[{"id":"1.187528277","rc":[{"trd":[[1.42,158471.46]],"batb":[[0,1.42,31224.62]],"ltp":1.42,"tv":334460.19,"id":2249229}],"tv":406688.8}]}
{"op":"mcm","clk":"4223409950","pt":1631448012656,"mc":[{"id":"1.187528277","rc":[{"batb":[[0,1.42,31628.08]],"ltp":1.42,"tv":334460.19,"id":2249229}]}]}
{"op":"mcm","clk":"4223410317","pt":1631448014045,"mc":[{"id":"1.187528277","rc":[{"batb":[[0,1.42,31224.62]],"ltp":1.42,"tv":334460.19,"id":2249229}]}]}
{"op":"mcm","clk":"4223418735","pt":1631448056577,"mc":[{"id":"1.187528277","rc":[{"batb":[[1,3.25,2979.3]],"ltp":3.3,"tv":72228.6,"id":19924831},{"batb":[[0,1.42,31628.08]],"batl":[[1,1.44,18998.34]],"ltp":1.42,"tv":334460.19,"id":2249229}]}]}
{"op":"mcm","clk":"4223419105","pt":1631448058658,"mc":[{"id":"1.187528277","rc":[{"batb":[[0,1.42,31224.62]],"ltp":1.42,"tv":334460.19,"id":2249229}]}]}
{"op":"mcm","clk":"4223424008","pt":1631448083386,"mc":[{"id":"1.187528277","rc":[{"batb":[[0,1.42,31628.08]],"ltp":1.42,"tv":334460.19,"id":2249229}]}]}
{"op":"mcm","clk":"4223424286","pt":1631448084751,"mc":[{"id":"1.187528277","rc":[{"batb":[[0,1.42,31224.62]],"ltp":1.42,"tv":334460.19,"id":2249229}]}]}
{"op":"mcm","clk":"4223428151","pt":1631448104287,"mc":[{"id":"1.187528277","rc":[{"batb":[[0,1.42,31628.08]],"ltp":1.42,"tv":334460.19,"id":2249229}]}]}
{"op":"mcm","clk":"4223428237","pt":1631448104766,"mc":[{"id":"1.187528277","rc":[{"batb":[[0,1.42,31224.62]],"ltp":1.42,"tv":334460.19,"id":2249229}]}]}
{"op":"mcm","clk":"4223440949","pt":1631448170839,"mc":[{"id":"1.187528277","rc":[{"trd":[[1.43,59741.92]],"batl":[[0,1.43,9112.52]],"ltp":1.43,"tv":334488.07,"id":2249229}],"tv":406716.68}]}
{"op":"mcm","clk":"4223447137","pt":1631448203559,"mc":[{"id":"1.187528277","rc":[{"trd":[[1.42,158481.46]],"batb":[[0,1.42,31219.62]],"ltp":1.42,"tv":334498.07,"id":2249229}],"tv":406726.68}]}
{"op":"mcm","clk":"4223448751","pt":1631448210717,"mc":[{"id":"1.187528277","rc":[{"trd":[[1.43,77967.44]],"batb":[[0,1.43,193],[1,1.42,31219.62],[2,1.41,40762]],"batl":[[0,1.44,18998.34],[1,1.45,6528.93],[2,1.46,2434.83]],"ltp":1.43,"tv":352723.59,"id":2249229}],"tv":424952.2}]}
{"op":"mcm","clk":"4223448832","pt":1631448211100,"mc":[{"id":"1.187528277","rc":[{"batb":[[0,3.3,3997.33]],"batl":[[0,3.35,1758.77]],"ltp":3.3,"tv":72228.6,"id":19924831},{"batb":[[1,1.42,31149.2]],"batl":[[0,1.44,19067.78]],"ltp":1.43,"tv":352723.59,"id":2249229}]}]}
{"op":"mcm","clk":"4223451575","pt":1631448223518,"mc":[{"id":"1.187528277","rc":[{"trd":[[1.43,78353.43]],"batb":[[0,1.42,31149.2],[1,1.41,40762],[2,1.4,45406.12]],"batl":[[0,1.43,47.77],[1,1.44,19067.78],[2,1.45,6528.93]],"ltp":1.43,"tv":353109.59,"id":2249229}],"tv":425338.2}]}
{"op":"mcm","clk":"4223451797","pt":1631448224704,"mc":[{"id":"1.187528277","rc":[{"batb":[[0,3.3,4027.63]],"batl":[[0,3.35,1728.92]],"ltp":3.3,"tv":72228.6,"id":19924831},{"trd":[[1.43,78448.97]],"batb":[[0,1.42,31219.62]],"batl":[[0,1.44,18998.34],[1,1.45,6528.93],[2,1.46,2434.83]],"ltp":1.43,"tv":353205.12,"id":2249229}],"tv":425433.73}]}
{"op":"mcm","clk":"4223451869","pt":1631448225148,"mc":[{"id":"1.187528277","rc":[{"batb":[[0,3.3,3997.33]],"ltp":3.3,"tv":72228.6,"id":19924831},{"batl":[[0,1.44,19067.78]],"ltp":1.43,"tv":353205.12,"id":2249229}]}]}
{"op":"mcm","clk":"4223465242","pt":1631448292421,"mc":[{"id":"1.187528277","rc":[{"batl":[[0,3.35,1758.77]],"ltp":3.3,"tv":72228.6,"id":19924831},{"batb":[[0,1.43,6.97],[1,1.42,31149.2],[2,1.41,40762]],"ltp":1.43,"tv":353205.12,"id":2249229}]}]}
{"op":"mcm","clk":"4223466093","pt":1631448297093,"mc":[{"id":"1.187528277","rc":[{"batb":[[0,1.43,79.27]],"ltp":1.43,"tv":353205.12,"id":2249229}]}]}
{"op":"mcm","clk":"4223468411","pt":1631448308541,"mc":[{"id":"1.187528277","rc":[{"batb":[[0,1.43,151.57]],"ltp":1.43,"tv":353205.12,"id":2249229}]}]}
{"op":"mcm","clk":"4223471553","pt":1631448324347,"mc":[{"id":"1.187528277","rc":[{"batb":[[0,3.3,4027.63]],"batl":[[0,3.35,1728.92]],"ltp":3.3,"tv":72228.6,"id":19924831},{"trd":[[1.43,78752.11]],"batb":[[0,1.42,31219.62],[1,1.41,40762],[2,1.4,45406.12]],"batl":[[0,1.43,169.45],[1,1.44,18998.34],[2,1.45,6528.93]],"ltp":1.43,"tv":353508.27,"id":2249229}],"tv":425736.88}]}
{"op":"mcm","clk":"4223473727","pt":1631448335578,"mc":[{"id":"1.187528277","rc":[{"batb":[[0,3.3,4061.22]],"ltp":3.3,"tv":72228.6,"id":19924831}]}]}
{"op":"mcm","clk":"4223479120","pt":1631448364418,"mc":[{"id":"1.187528277","rc":[{"trd":[[3.35,23277.08]],"batl":[[0,3.35,1704.75]],"ltp":3.35,"tv":72276.94,"id":19924831}],"tv":425785.22}]}
{"op":"mcm","clk":"4223480895","pt":1631448373314,"mc":[{"id":"1.187528277","rc":[{"batl":[[0,3.35,2408.48]],"ltp":3.35,"tv":72276.94,"id":19924831}]}]}
{"op":"mcm","clk":"4223492646","pt":1631448435699,"mc":[{"id":"1.187528277","rc":[{"trd":[[3.35,23310.05]],"batl":[[0,3.35,2392]],"ltp":3.35,"tv":72309.91,"id":19924831}],"tv":425818.19}]}
{"op":"mcm","clk":"4223500457","pt":1631448479143,"mc":[{"id":"1.187528277","rc":[{"trd":[[3.35,24121.99]],"batl":[[0,3.35,1986.03]],"ltp":3.35,"tv":73121.85,"id":19924831}],"tv":426630.13}]}
{"op":"mcm","clk":"4223500725","pt":1631448480745,"mc":[{"id":"1.187528277","rc":[{"batl":[[0,1.43,241.75]],"ltp":1.43,"tv":353508.27,"id":2249229}]}]}
{"op":"mcm","clk":"4223504455","pt":1631448502572,"mc":[{"id":"1.187528277","rc":[{"trd":[[1.42,158501.46]],"batb":[[0,1.42,31209.62]],"ltp":1.42,"tv":353528.27,"id":2249229}],"tv":426650.13}]}
{"op":"mcm","clk":"4223506297","pt":1631448513802,"mc":[{"id":"1.187528277","rc":[{"trd":[[3.35,24168.79]],"batl":[[0,3.35,1962.63]],"ltp":3.35,"tv":73168.65,"id":19924831}],"tv":426696.92}]}
{"op":"mcm","clk":"4223513482","pt":1631448552034,"mc":[{"id":"1.187528277","rc":[{"trd":[[3.3,11871.81]],"batb":[[0,3.3,4018.52]],"ltp":3.3,"tv":73254.05,"id":19924831}],"tv":426782.33}]}
{"op":"mcm","clk":"4223523477","pt":1631448606876,"mc":[{"id":"1.187528277","rc":[{"batb":[[0,3.3,3984.93]],"ltp":3.3,"tv":73254.05,"id":19924831}]}]}
{"op":"mcm","clk":"4223526544","pt":1631448624609,"mc":[{"id":"1.187528277","rc":[{"batl":[[0,1.43,251.75]],"ltp":1.42,"tv":353528.27,"id":2249229}]}]}
{"op":"mcm","clk":"4223527441","pt":1631448629307,"mc":[{"id":"1.187528277","rc":[{"batb":[[0,1.42,31219.62]],"ltp":1.42,"tv":353528.27,"id":2249229}]}]}
{"op":"mcm","clk":"4223529920","pt":1631448642305,"mc":[{"id":"1.187528277","rc":[{"batl":[[0,1.43,261.75]],"ltp":1.42,"tv":353528.27,"id":2249229}]}]}
{"op":"mcm","clk":"4223530729","pt":1631448646618,"mc":[{"id":"1.187528277","rc":[{"batb":[[0,1.42,31229.62]],"ltp":1.42,"tv":353528.27,"id":2249229}]}]}
{"op":"mcm","clk":"4223538637","pt":1631448689345,"mc":[{"id":"1.187528277","rc":[{"trd":[[3.3,12018.71]],"batb":[[0,3.3,3911.48]],"ltp":3.3,"tv":73400.95,"id":19924831}],"tv":426929.23}]}
{"op":"mcm","clk":"4223549342","pt":1631448747564,"mc":[{"id":"1.187528277","rc":[{"trd":[[1.42,160108.2]],"batb":[[0,1.42,30426.27]],"ltp":1.42,"tv":355135.01,"id":2249229}],"tv":428535.96}]}
{"op":"mcm","clk":"4223554262","pt":1631448771470,"mc":[{"id":"1.187528277","rc":[{"batl":[[0,3.35,3128.13]],"ltp":3.3,"tv":73400.95,"id":19924831}]}]}
{"op":"mcm","clk":"4223557694","pt":1631448789115,"mc":[{"id":"1.187528277","rc":[{"batl":[[0,1.43,314.93],[1,1.44,18945.16]],"ltp":1.42,"tv":355135.01,"id":2249229}]}]}
{"op":"mcm","clk":"4223558345","pt":1631448792530,"mc":[{"id":"1.187528277","rc":[{"trd":[[1.42,161933.16]],"batb":[[0,1.42,29513.79]],"ltp":1.42,"tv":356959.97,"id":2249229}],"tv":430360.92}]}
{"op":"mcm","clk":"4223566172","pt":1631448832770,"mc":[{"id":"1.187528277","rc":[{"trd":[[1.42,161959.16]],"batb":[[0,1.42,29500.79]],"ltp":1.42,"tv":356985.97,"id":2249229}],"tv":430386.92}]}
{"op":"mcm","clk":"4223578722","pt":1631448895744,"mc":[{"id":"1.187528277","rc":[{"trd":[[1.42,163959.16]],"batb":[[0,1.42,28500.79]],"ltp":1.42,"tv":358985.97,"id":2249229}],"tv":432386.92}]}
{"op":"mcm","clk":"4223613870","pt":1631449081970,"mc":[{"id":"1.187528277","rc":[{"trd":[[1.43,78758.11]],"batl":[[0,1.43,311.93]],"ltp":1.43,"tv":358991.97,"id":2249229}],"tv":432392.92}]}
{"op":"mcm","clk":"4223614239","pt":1631449084179,"mc":[{"id":"1.187528277","rc":[{"batb":[[0,1.42,28518.94]],"ltp":1.43,"tv":358991.97,"id":2249229}]}]}
{"op":"mcm","clk":"4223614444","pt":1631449085466,"mc":[{"id":"1.187528277","rc":[{"batb":[[0,1.42,28500.79]],"ltp":1.43,"tv":358991.97,"id":2249229}]}]}
{"op":"mcm","clk":"4223614649","pt":1631449086678,"mc":[{"id":"1.187528277","rc":[{"batb":[[0,1.42,28518.94]],"ltp":1.43,"tv":358991.97,"id":2249229}]}]}
{"op":"mcm","clk":"4223614837","pt":1631449087797,"mc":[{"id":"1.187528277","rc":[{"batb":[[0,1.42,28500.79]],"ltp":1.43,"tv":358991.97,"id":2249229}]}]}
{"op":"mcm","clk":"4223617169","pt":1631449101419,"mc":[{"id":"1.187528277","rc":[{"batb":[[0,1.42,28518.94]],"ltp":1.43,"tv":358991.97,"id":2249229}]}]}
{"op":"mcm","clk":"4223617374","pt":1631449102591,"mc":[{"id":"1.187528277","rc":[{"batb":[[0,1.42,28500.79]],"ltp":1.43,"tv":358991.97,"id":2249229}]}]}
{"op":"mcm","clk":"4223620186","pt":1631449118626,"mc":[{"id":"1.187528277","rc":[{"trd":[[1.42,163988.26]],"batb":[[0,1.42,28504.39]],"ltp":1.42,"tv":359021.07,"id":2249229}],"tv":432422.02}]}
{"op":"mcm","clk":"4223620288","pt":1631449119212,"mc":[{"id":"1.187528277","rc":[{"batb":[[0,1.42,28486.24]],"ltp":1.42,"tv":359021.07,"id":2249229}]}]}
{"op":"mcm","clk":"4223620512","pt":1631449120607,"mc":[{"id":"1.187528277","rc":[{"trd":[[3.3,15634.86]],"batb":[[0,3.3,2103.45],[1,3.25,2991.2]],"ltp":3.3,"tv":77017.1,"id":19924831},{"batb":[[0,1.42,28507.6],[2,1.4,45378.6]],"ltp":1.42,"tv":359021.07,"id":2249229}],"tv":436038.18}]}
{"op":"mcm","clk":"4223620676","pt":1631449121607,"mc":[{"id":"1.187528277","rc":[{"batb":[[0,1.42,28525.75]],"ltp":1.42,"tv":359021.07,"id":2249229}]}]}
{"op":"mcm","clk":"4223620786","pt":1631449122202,"mc":[{"id":"1.187528277","rc":[{"batb":[[0,1.42,28507.6]],"ltp":1.42,"tv":359021.07,"id":2249229}]}]}
{"op":"mcm","clk":"4223633604","pt":1631449200693,"mc":[{"id":"1.187528277","rc":[{"batb":[[0,1.42,28525.75]],"ltp":1.42,"tv":359021.07,"id":2249229}]}]}
{"op":"mcm","clk":"4223633712","pt":1631449201330,"mc":[{"id":"1.187528277","rc":[{"batb":[[0,1.42,28507.6]],"ltp":1.42,"tv":359021.07,"id":2249229}]}]}
{"op":"mcm","clk":"4223633823","pt":1631449201923,"mc":[{"id":"1.187528277","rc":[{"batb":[[0,1.42,28125.6]],"ltp":1.42,"tv":359021.07,"id":2249229}]}]}
{"op":"mcm","clk":"4223634581","pt":1631449205918,"mc":[{"id":"1.187528277","rc":[{"trd":[[1.43,78836.91]],"batl":[[0,1.43,272.53]],"ltp":1.43,"tv":359099.86,"id":2249229}],"tv":436116.97}]}
{"op":"mcm","clk":"4223634942","pt":1631449208034,"mc":[{"id":"1.187528277","rc":[{"batb":[[0,1.42,28143.75]],"ltp":1.43,"tv":359099.86,"id":2249229}]}]}
{"op":"mcm","clk":"4223635425","pt":1631449210629,"mc":[{"id":"1.187528277","rc":[{"batb":[[0,1.42,28125.6]],"ltp":1.43,"tv":359099.86,"id":2249229}]}]}
{"op":"mcm","clk":"4223635585","pt":1631449211510,"mc":[{"id":"1.187528277","rc":[{"batb":[[0,1.42,28143.75]],"ltp":1.43,"tv":359099.86,"id":2249229}]}]}
{"op":"mcm","clk":"4223635754","pt":1631449212405,"mc":[{"id":"1.187528277","rc":[{"batb":[[0,1.42,28125.6]],"ltp":1.43,"tv":359099.86,"id":2249229}]}]}
{"op":"mcm","clk":"4223636083","pt":1631449214317,"mc":[{"id":"1.187528277","rc":[{"batb":[[0,1.42,28143.75]],"ltp":1.43,"tv":359099.86,"id":2249229}]}]}
{"op":"mcm","clk":"4223636267","pt":1631449215437,"mc":[{"id":"1.187528277","rc":[{"batb":[[0,1.42,28125.6]],"ltp":1.43,"tv":359099.86,"id":2249229}]}]}
{"op":"mcm","clk":"4223637110","pt":1631449220325,"mc":[{"id":"1.187528277","rc":[{"batb":[[0,3.3,809.15]],"batl":[[0,3.35,3157.98]],"ltp":3.3,"tv":77017.1,"id":19924831},{"trd":[[1.43,79381.97]],"batb":[[0,1.43,1029.47],[1,1.42,28055.18],[2,1.41,40762]],"batl":[[0,1.44,19014.6],[1,1.45,6528.93],[2,1.46,2434.83]],"ltp":1.43,"tv":359644.92,"id":2249229}],"tv":436662.03}]}
{"op":"mcm","clk":"4223639434","pt":1631449233448,"mc":[{"id":"1.187528277","rc":[{"trd":[[1.43,80233.31]],"batb":[[0,1.43,603.81]],"ltp":1.43,"tv":360496.27,"id":2249229}],"tv":437513.37}]}
{"op":"mcm","clk":"4223640389","pt":1631449238940,"mc":[{"id":"1.187528277","rc":[{"batb":[[0,3.3,860.97]],"ltp":3.3,"tv":77017.1,"id":19924831},{"batb":[[0,1.43,723.38]],"ltp":1.43,"tv":360496.27,"id":2249229}]}]}
{"op":"mcm","clk":"4223641110","pt":1631449243362,"mc":[{"id":"1.187528277","rc":[{"batb":[[0,1.43,867.98]],"ltp":1.43,"tv":360496.27,"id":2249229}]}]}
{"op":"mcm","clk":"4223643677","pt":1631449258681,"mc":[{"id":"1.187528277","rc":[{"trd":[[1.43,80426.44]],"batb":[[0,1.43,771.42]],"ltp":1.43,"tv":360689.39,"id":2249229}],"tv":437706.5}]}
{"op":"mcm","clk":"4223646610","pt":1631449275077,"mc":[{"id":"1.187528277","rc":[{"batb":[[0,1.43,699.12]],"ltp":1.43,"tv":360689.39,"id":2249229}]}]}
{"op":"mcm","clk":"4223655265","pt":1631449326789,"mc":[{"id":"1.187528277","rc":[{"trd":[[3.3,16144.31]],"batb":[[0,3.3,606.25]],"ltp":3.3,"tv":77526.56,"id":19924831}],"tv":438215.95}]}
{"op":"mcm","clk":"4223661444","pt":1631449361628,"mc":[{"id":"1.187528277","rc":[{"batb":[[0,3.3,2212.79]],"ltp":3.3,"tv":77526.56,"id":19924831}]}]}
{"op":"mcm","clk":"4223662586","pt":1631449368241,"mc":[{"id":"1.187528277","rc":[{"trd":[[1.43,80441.58]],"batb":[[0,1.43,691.55]],"ltp":1.43,"tv":360704.53,"id":2249229}],"tv":438231.09}]}
{"op":"mcm","clk":"4223670146","pt":1631449414004,"mc":[{"id":"1.187528277","rc":[{"batb":[[0,1.43,4806.15]],"ltp":1.43,"tv":360704.53,"id":2249229}]}]}
{"op":"mcm","clk":"4223673687","pt":1631449435934,"mc":[{"id":"1.187528277","rc":[{"batb":[[0,1.43,5161.15]],"ltp":1.43,"tv":360704.53,"id":2249229}]}]}
{"op":"mcm","clk":"4223690742","pt":1631449533560,"mc":[{"id":"1.187528277","rc":[{"trd":[[3.3,16250.67]],"batb":[[0,3.3,2159.61]],"ltp":3.3,"tv":77632.91,"id":19924831}],"tv":438337.45}]}
{"op":"mcm","clk":"4223694220","pt":1631449553269,"mc":[{"id":"1.187528277","rc":[{"batl":[[2,3.45,829.88]],"ltp":3.3,"tv":77632.91,"id":19924831},{"trd":[[1.43,80577.78]],"batb":[[0,1.43,5093.05]],"ltp":1.43,"tv":360840.73,"id":2249229}],"tv":438473.65}]}
{"op":"mcm","clk":"4223697299","pt":1631449572296,"mc":[{"id":"1.187528277","rc":[{"batb":[[0,1.43,5391.97]],"ltp":1.43,"tv":360840.73,"id":2249229}]}]}
{"op":"mcm","clk":"4223704294","pt":1631449614676,"mc":[{"id":"1.187528277","rc":[{"trd":[[1.44,5666.67]],"batl":[[0,1.44,18961.42]],"ltp":1.44,"tv":360947.09,"id":2249229}],"tv":438580.01}]}
{"op":"mcm","clk":"4223705309","pt":1631449620898,"mc":[{"id":"1.187528277","rc":[{"trd":[[3.3,16357.03]],"batb":[[0,3.3,2106.43]],"ltp":3.3,"tv":77739.27,"id":19924831}],"tv":438686.37}]}
{"op":"mcm","clk":"4223718374","pt":1631449701704,"mc":[{"id":"1.187528277","rc":[{"trd":[[1.44,5966.68]],"batl":[[0,1.44,18811.42]],"ltp":1.44,"tv":361247.1,"id":2249229}],"tv":438986.37}]}
{"op":"mcm","clk":"4223718408","pt":1631449701907,"mc":[{"id":"1.187528277","rc":[{"trd":[[1.44,6166.67]],"batl":[[0,1.44,18711.42]],"ltp":1.44,"tv":361447.1,"id":2249229}],"tv":439186.37}]}
{"op":"mcm","clk":"4223719920","pt":1631449710614,"mc":[{"id":"1.187528277","rc":[{"trd":[[1.44,6217.73]],"batl":[[0,1.44,18685.9]],"ltp":1.44,"tv":361498.15,"id":2249229}],"tv":439237.42}]}
{"op":"mcm","clk":"4223728349","pt":1631449760610,"mc":[{"id":"1.187528277","rc":[{"trd":[[3.3,16377.03]],"batb":[[0,3.3,2096.43]],"ltp":3.3,"tv":77759.27,"id":19924831}],"tv":439257.42}]}
{"op":"mcm","clk":"4223733541","pt":1631449793449,"mc":[{"id":"1.187528277","rc":[{"trd":[[3.3,16447.03]],"batb":[[0,3.3,2061.43]],"ltp":3.3,"tv":77829.27,"id":19924831}],"tv":439327.42}]}
{"op":"mcm","clk":"4223740511","pt":1631449836226,"mc":[{"id":"1.187528277","rc":[{"trd":[[1.43,80585.22]],"batb":[[0,1.43,5388.25]],"ltp":1.43,"tv":361505.58,"id":2249229}],"tv":439334.86}]}
{"op":"mcm","clk":"4223745547","pt":1631449864770,"mc":[{"id":"1.187528277","rc":[{"batb":[[0,1.43,5516.35]],"batl":[[1,1.45,6657.03]],"ltp":1.43,"tv":361505.58,"id":2249229}]}]}
{"op":"mcm","clk":"4223772851","pt":1631450018827,"mc":[{"id":"1.187528277","rc":[{"batb":[[0,1.43,6962.38]],"ltp":1.43,"tv":361505.58,"id":2249229}]}]}
{"op":"mcm","clk":"4223775542","pt":1631450032595,"mc":[{"id":"1.187528277","rc":[{"batb":[[0,3.3,3410.27]],"batl":[[0,3.35,3128.13]],"ltp":3.3,"tv":77829.27,"id":19924831},{"trd":[[1.43,94509.98]],"batb":[[0,1.42,28125.6],[1,1.41,40762],[2,1.4,45378.6]],"batl":[[0,1.43,10118.5],[1,1.44,18616.46],[2,1.45,6657.03]],"ltp":1.43,"tv":375430.35,"id":2249229}],"tv":453259.62}]}
{"op":"mcm","clk":"4223776629","pt":1631450038440,"mc":[{"id":"1.187528277","rc":[{"batb":[[0,1.42,28143.75]],"ltp":1.43,"tv":375430.35,"id":2249229}]}]}
{"op":"mcm","clk":"4223776762","pt":1631450039123,"mc":[{"id":"1.187528277","rc":[{"batb":[[0,1.42,28225.6]],"ltp":1.43,"tv":375430.35,"id":2249229}]}]}
{"op":"mcm","clk":"4223778883","pt":1631450051339,"mc":[{"id":"1.187528277","rc":[{"batb":[[0,1.42,28243.75]],"ltp":1.43,"tv":375430.35,"id":2249229}]}]}
{"op":"mcm","clk":"4223778953","pt":1631450051722,"mc":[{"id":"1.187528277","rc":[{"batb":[[0,1.42,28225.6]],"ltp":1.43,"tv":375430.35,"id":2249229}]}]}
{"op":"mcm","clk":"4223779827","pt":1631450056648,"mc":[{"id":"1.187528277","rc":[{"batb":[[0,1.42,28243.75]],"ltp":1.43,"tv":375430.35,"id":2249229}]}]}
{"op":"mcm","clk":"4223779975","pt":1631450057455,"mc":[{"id":"1.187528277","rc":[{"batb":[[0,1.42,28225.6]],"ltp":1.43,"tv":375430.35,"id":2249229}]}]}
{"op":"mcm","clk":"4223786400","pt":1631450095285,"mc":[{"id":"1.187528277","rc":[{"trd":[[1.42,164283.8]],"batb":[[0,1.42,28077.83]],"ltp":1.42,"tv":375725.89,"id":2249229}],"tv":453555.16}]}
{"op":"mcm","clk":"4223786661","pt":1631450096796,"mc":[{"id":"1.187528277","rc":[{"batb":[[0,1.42,28095.98]],"ltp":1.42,"tv":375725.89,"id":2249229}]}]}
{"op":"mcm","clk":"4223786901","pt":1631450098101,"mc":[{"id":"1.187528277","rc":[{"batb":[[0,1.42,28077.83]],"ltp":1.42,"tv":375725.89,"id":2249229}]}]}
{"op":"mcm","clk":"4223787907","pt":1631450103506,"mc":[{"id":"1.187528277","rc":[{"batb":[[0,1.42,28095.98]],"ltp":1.42,"tv":375725.89,"id":2249229}]}]}
{"op":"mcm","clk":"4223788023","pt":1631450104223,"mc":[{"id":"1.187528277","rc":[{"batb":[[0,1.42,28077.83]],"ltp":1.42,"tv":375725.89,"id":2249229}]}]}
{"op":"mcm","clk":"4223793488","pt":1631450133987,"mc":[{"id":"1.187528277","rc":[{"batb":[[0,1.42,28095.98]],"ltp":1.42,"tv":375725.89,"id":2249229}]}]}
{"op":"mcm","clk":"4223793635","pt":1631450134863,"mc":[{"id":"1.187528277","rc":[{"batb":[[0,1.42,28077.83]],"ltp":1.42,"tv":375725.89,"id":2249229}]}]}
{"op":"mcm","clk":"4223798942","pt":1631450163717,"mc":[{"id":"1.187528277","rc":[{"batb":[[0,1.42,28095.98]],"ltp":1.42,"tv":375725.89,"id":2249229}]}]}
{"op":"mcm","clk":"4223799141","pt":1631450164706,"mc":[{"id":"1.187528277","rc":[{"batb":[[0,1.42,28077.83]],"ltp":1.42,"tv":375725.89,"id":2249229}]}]}
{"op":"mcm","clk":"4223804844","pt":1631450194386,"mc":[{"id":"1.187528277","rc":[{"batl":[[0,1.43,10263.1]],"ltp":1.42,"tv":375725.89,"id":2249229}]}]}
{"op":"mcm","clk":"4223806230","pt":1631450201582,"mc":[{"id":"1.187528277","rc":[{"trd":[[3.35,24215.58]],"batl":[[0,3.35,3104.73]],"ltp":3.35,"tv":77876.07,"id":19924831}],"tv":453601.96}]}
{"op":"mcm","clk":"4223808067","pt":1631450211393,"mc":[{"id":"1.187528277","rc":[{"batl":[[0,3.35,3350.56]],"ltp":3.35,"tv":77876.07,"id":19924831}]}]}
{"op":"mcm","clk":"4223808438","pt":1631450213196,"mc":[{"id":"1.187528277","rc":[{"batb":[[0,1.42,28095.98]],"ltp":1.42,"tv":375725.89,"id":2249229}]}]}
{"op":"mcm","clk":"4223808582","pt":1631450213920,"mc":[{"id":"1.187528277","rc":[{"batb":[[0,1.42,28077.83]],"ltp":1.42,"tv":375725.89,"id":2249229}]}]}
{"op":"mcm","clk":"4223810218","pt":1631450222112,"mc":[{"id":"1.187528277","rc":[{"trd":[[1.43,95304.43]],"batl":[[0,1.43,9865.88]],"ltp":1.43,"tv":376520.33,"id":2249229}],"tv":454396.41}]}
{"op":"mcm","clk":"4223810485","pt":1631450223513,"mc":[{"id":"1.187528277","rc":[{"batb":[[0,1.42,28095.98]],"ltp":1.43,"tv":376520.33,"id":2249229}]}]}
{"op":"mcm","clk":"4223810601","pt":1631450224125,"mc":[{"id":"1.187528277","rc":[{"trd":[[3.35,24241.29]],"batl":[[0,3.35,3337.7]],"ltp":3.35,"tv":77901.78,"id":19924831},{"batb":[[0,1.42,28077.83]],"ltp":1.43,"tv":376520.33,"id":2249229}],"tv":454422.12}]}
{"op":"mcm","clk":"4223811565","pt":1631450228539,"mc":[{"id":"1.187528277","rc":[{"trd":[[1.43,95703.27]],"batl":[[0,1.43,9666.46]],"ltp":1.43,"tv":376919.18,"id":2249229}],"tv":454820.96}]}
{"op":"mcm","clk":"4223812002","pt":1631450230555,"mc":[{"id":"1.187528277","rc":[{"batb":[[0,1.42,28095.98]],"ltp":1.43,"tv":376919.18,"id":2249229}]}]}
{"op":"mcm","clk":"4223812171","pt":1631450231433,"mc":[{"id":"1.187528277","rc":[{"batb":[[0,1.42,28077.83]],"ltp":1.43,"tv":376919.18,"id":2249229}]}]}
{"op":"mcm","clk":"4223812378","pt":1631450232416,"mc":[{"id":"1.187528277","rc":[{"batb":[[0,1.42,28095.98]],"ltp":1.43,"tv":376919.18,"id":2249229}]}]}
{"op":"mcm","clk":"4223812476","pt":1631450232941,"mc":[{"id":"1.187528277","rc":[{"batb":[[0,1.42,28077.83]],"ltp":1.43,"tv":376919.18,"id":2249229}]}]}
{"op":"mcm","clk":"4223814939","pt":1631450244482,"mc":[{"id":"1.187528277","rc":[{"batl":[[0,1.43,9686.46]],"ltp":1.43,"tv":376919.18,"id":2249229}]}]}
{"op":"mcm","clk":"4223815840","pt":1631450249452,"mc":[{"id":"1.187528277","rc":[{"batb":[[0,1.42,28115.98]],"ltp":1.43,"tv":376919.18,"id":2249229}]}]}
{"op":"mcm","clk":"4223815993","pt":1631450250356,"mc":[{"id":"1.187528277","rc":[{"batb":[[0,1.42,28097.83]],"ltp":1.43,"tv":376919.18,"id":2249229}]}]}
{"op":"mcm","clk":"4223818191","pt":1631450263249,"mc":[{"id":"1.187528277","rc":[{"batl":[[0,1.43,9696.46]],"ltp":1.43,"tv":376919.18,"id":2249229}]}]}
{"op":"mcm","clk":"4223819209","pt":1631450268476,"mc":[{"id":"1.187528277","rc":[{"batb":[[0,1.42,28107.83]],"ltp":1.43,"tv":376919.18,"id":2249229}]}]}
{"op":"mcm","clk":"4223819581","pt":1631450270302,"mc":[{"id":"1.187528277","rc":[{"batb":[[0,1.42,28125.98]],"ltp":1.43,"tv":376919.18,"id":2249229}]}]}
{"op":"mcm","clk":"4223819726","pt":1631450270957,"mc":[{"id":"1.187528277","rc":[{"batb":[[0,1.42,28107.83]],"ltp":1.43,"tv":376919.18,"id":2249229}]}]}
{"op":"mcm","clk":"4223821793","pt":1631450281598,"mc":[{"id":"1.187528277","rc":[{"trd":[[3.35,24289.63]],"batl":[[0,3.35,3313.53]],"ltp":3.35,"tv":77950.12,"id":19924831},{"batb":[[0,1.42,28125.98]],"ltp":1.43,"tv":376919.18,"id":2249229}],"tv":454869.3}]}
{"op":"mcm","clk":"4223821826","pt":1631450281778,"mc":[{"id":"1.187528277","rc":[{"batb":[[0,1.42,28107.83]],"ltp":1.43,"tv":376919.18,"id":2249229}]}]}
