{"op":"mcm","clk":"4214578258","pt":1631364515472,"mc":[{"id":"1.187528277","rc":[{"trd":[[1.44,4015.49]],"batl":[[0,1.44,5903.26]],"ltp":1.44,"tv":33225.76,"id":2249229}],"tv":41288.19}]}
{"op":"mcm","clk":"4214579600","pt":1631364521174,"mc":[{"id":"1.187528277","rc":[{"trd":[[1.44,4029.9]],"batl":[[0,1.44,5896.05]],"ltp":1.44,"tv":33240.18,"id":2249229}],"tv":41302.61}]}
{"op":"mcm","clk":"4214594579","pt":1631364589110,"mc":[{"id":"1.187528277","rc":[{"trd":[[1.44,4115.31]],"batl":[[0,1.44,5853.35]],"ltp":1.44,"tv":33325.58,"id":2249229}],"tv":41388.02}]}
{"op":"mcm","clk":"4214611862","pt":1631364671582,"mc":[{"id":"1.187528277","rc":[{"trd":[[1.44,4159.72]],"batl":[[0,1.44,5831.14]],"ltp":1.44,"tv":33369.99,"id":2249229}],"tv":41432.43}]}
{"op":"mcm","clk":"4214621422","pt":1631364720888,"mc":[{"id":"1.187528277","rc":[{"batb":[[0,1.43,833.18]],"ltp":1.44,"tv":33369.99,"id":2249229}]}]}
{"op":"mcm","clk":"4214621809","pt":1631364722808,"mc":[{"id":"1.187528277","rc":[{"batl":[[0,3.3,3348.7]],"ltp":3.25,"tv":8062.43,"id":19924831}]}]}
{"op":"mcm","clk":"4214625744","pt":1631364743466,"mc":[{"id":"1.187528277","rc":[{"trd":[[1.44,4202.42]],"batl":[[0,1.44,5809.79]],"ltp":1.44,"tv":33412.69,"id":2249229}],"tv":41475.13}]}
{"op":"mcm","clk":"4214629444","pt":1631364762592,"mc":[{"id":"1.187528277","rc":[{"trd":[[1.44,4303.3]],"batl":[[0,1.44,5759.35]],"ltp":1.44,"tv":33513.57,"id":2249229}],"tv":41576.01}]}
{"op":"mcm","clk":"4214629640","pt":1631364763669,"mc":[{"id":"1.187528277","rc":[{"trd":[[3.3,3335.7]],"batl":[[0,3.3,3336.37]],"ltp":3.3,"tv":8087.09,"id":19924831}],"tv":41600.67}]}
{"op":"mcm","clk":"4214640904","pt":1631364828395,"mc":[{"id":"1.187528277","rc":[{"batl":[[0,1.44,5874.11],[1,1.45,1612.07]],"ltp":1.44,"tv":33513.57,"id":2249229}]}]}
{"op":"mcm","clk":"4214641117","pt":1631364829719,"mc":[{"id":"1.187528277","rc":[{"batb":[[1,3.2,253.09]],"batl":[[1,3.35,60.33]],"ltp":3.3,"tv":8087.09,"id":19924831}]}]}
{"op":"mcm","clk":"4214650331","pt":1631364883777,"mc":[{"id":"1.187528277","rc":[{"trd":[[1.44,4317.66]],"batl":[[0,1.44,5866.93]],"ltp":1.44,"tv":33527.94,"id":2249229}],"tv":41615.03}]}
{"op":"mcm","clk":"4214653264","pt":1631364899530,"mc":[{"id":"1.187528277","rc":[{"batb":[[1,3.2,287.62]],"ltp":3.3,"tv":8087.09,"id":19924831},{"batb":[[1,1.42,1617.72]],"batl":[[1,1.45,1650.88]],"ltp":1.44,"tv":33527.94,"id":2249229}]}]}
{"op":"mcm","clk":"4214668469","pt":1631364982468,"mc":[{"id":"1.187528277","rc":[{"batl":[[1,1.45,1656.7]],"ltp":1.44,"tv":33527.94,"id":2249229}]}]}
{"op":"mcm","clk":"4214668524","pt":1631364982786,"mc":[{"id":"1.187528277","rc":[{"batb":[[1,3.2,295.44]],"ltp":3.3,"tv":8087.09,"id":19924831}]}]}
{"op":"mcm","clk":"4214674199","pt":1631365018581,"mc":[{"id":"1.187528277","rc":[{"trd":[[1.44,4331.67]],"batl":[[0,1.44,5859.93]],"ltp":1.44,"tv":33541.94,"id":2249229}],"tv":41629.04}]}
{"op":"mcm","clk":"4214678536","pt":1631365044159,"mc":[{"id":"1.187528277","rc":[{"trd":[[3.3,3336.05]],"batl":[[0,3.3,3336.2]],"ltp":3.3,"tv":8087.43,"id":19924831}],"tv":41629.38}]}
{"op":"mcm","clk":"4214680377","pt":1631365055512,"mc":[{"id":"1.187528277","rc":[{"trd":[[3.25,1159.9]],"batb":[[0,3.25,121.25]],"ltp":3.25,"tv":8287.43,"id":19924831}],"tv":41829.38}]}
{"op":"mcm","clk":"4214683732","pt":1631365075878,"mc":[{"id":"1.187528277","rc":[{"trd":[[1.44,4707.67]],"batl":[[0,1.44,5671.93]],"ltp":1.44,"tv":33917.94,"id":2249229}],"tv":42205.38}]}
{"op":"mcm","clk":"4214684419","pt":1631365080188,"mc":[{"id":"1.187528277","rc":[{"batb":[[0,1.43,859.77],[2,1.41,2559.41]],"ltp":1.44,"tv":33917.94,"id":2249229}]}]}
{"op":"mcm","clk":"4214684728","pt":1631365081983,"mc":[{"id":"1.187528277","rc":[{"batb":[[0,3.25,271.25]],"ltp":3.25,"tv":8287.43,"id":19924831}]}]}
{"op":"mcm","clk":"4214693746","pt":1631365135719,"mc":[{"id":"1.187528277","rc":[{"batl":[[1,3.35,64.1]],"ltp":3.25,"tv":8287.43,"id":19924831},{"batl":[[1,1.45,1693]],"ltp":1.44,"tv":33917.94,"id":2249229}]}]}
{"op":"mcm","clk":"4214704682","pt":1631365193774,"mc":[{"id":"1.187528277","rc":[{"batb":[[0,1.43,1004.37]],"ltp":1.44,"tv":33917.94,"id":2249229}]}]}
{"op":"mcm","clk":"4214709502","pt":1631365216368,"mc":[{"id":"1.187528277","rc":[{"batl":[[1,1.45,1698.45]],"ltp":1.44,"tv":33917.94,"id":2249229}]}]}
{"op":"mcm","clk":"4214709730","pt":1631365217554,"mc":[{"id":"1.187528277","rc":[{"batl":[[1,3.35,73.93]],"ltp":3.25,"tv":8287.43,"id":19924831}]}]}
{"op":"mcm","clk":"4214723386","pt":1631365283595,"mc":[{"id":"1.187528277","rc":[{"batb":[[1,1.42,1623.43]],"ltp":1.44,"tv":33917.94,"id":2249229}]}]}
{"op":"mcm","clk":"4214737714","pt":1631365353976,"mc":[{"id":"1.187528277","rc":[{"batb":[[0,1.43,2504.37]],"ltp":1.44,"tv":33917.94,"id":2249229}]}]}
{"op":"mcm","clk":"4214759152","pt":1631365442721,"mc":[{"id":"1.187528277","rc":[{"trd":[[3.3,6549.12]],"batl":[[0,3.3,1729.66]],"ltp":3.3,"tv":11500.51,"id":19924831}],"tv":45418.45}]}
{"op":"mcm","clk":"4214766837","pt":1631365473333,"mc":[{"id":"1.187528277","rc":[{"batl":[[1,3.35,171.44]],"ltp":3.3,"tv":11500.51,"id":19924831}]}]}
{"op":"mcm","clk":"4214783943","pt":1631365542603,"mc":[{"id":"1.187528277","rc":[{"trd":[[1.43,16105.08]],"batb":[[0,1.43,1504.35]],"ltp":1.43,"tv":35917.96,"id":2249229}],"tv":47418.47}]}
{"op":"mcm","clk":"4214784045","pt":1631365543005,"mc":[{"id":"1.187528277","rc":[{"batb":[[1,1.42,1644.41]],"ltp":1.43,"tv":35917.96,"id":2249229}]}]}
{"op":"mcm","clk":"4214793993","pt":1631365581672,"mc":[{"id":"1.187528277","rc":[{"batb":[[0,1.43,1678.71],[1,1.42,1682.93]],"ltp":1.43,"tv":35917.96,"id":2249229}]}]}
{"op":"mcm","clk":"4214794210","pt":1631365582506,"mc":[{"id":"1.187528277","rc":[{"batb":[[1,3.2,299.85]],"ltp":3.3,"tv":11500.51,"id":19924831},{"batl":[[0,1.44,5847.91]],"ltp":1.43,"tv":35917.96,"id":2249229}]}]}
{"op":"mcm","clk":"4214794382","pt":1631365583221,"mc":[{"id":"1.187528277","rc":[{"batl":[[0,3.3,1666.99]],"ltp":3.3,"tv":11500.51,"id":19924831}]}]}
{"op":"mcm","clk":"4214794682","pt":1631365584477,"mc":[{"id":"1.187528277","rc":[{"batl":[[0,3.3,1653.15],[1,3.35,122.04]],"ltp":3.3,"tv":11500.51,"id":19924831}]}]}
{"op":"mcm","clk":"4214797124","pt":1631365594478,"mc":[{"id":"1.187528277","rc":[{"trd":[[3.3,6837.12]],"batl":[[0,3.3,1509.15]],"ltp":3.3,"tv":11788.51,"id":19924831}],"tv":47706.47}]}
{"op":"mcm","clk":"4214802002","pt":1631365612903,"mc":[{"id":"1.187528277","rc":[{"batb":[[0,1.43,2011.71]],"ltp":1.43,"tv":35917.96,"id":2249229}]}]}
{"op":"mcm","clk":"4214811141","pt":1631365647677,"mc":[{"id":"1.187528277","rc":[{"trd":[[3.3,6961.48]],"batl":[[0,3.3,1446.97]],"ltp":3.3,"tv":11912.87,"id":19924831}],"tv":47830.83}]}
{"op":"mcm","clk":"4214811717","pt":1631365650132,"mc":[{"id":"1.187528277","rc":[{"trd":[[3.25,1203.9]],"batb":[[0,3.25,249.25]],"ltp":3.25,"tv":11956.87,"id":19924831}],"tv":47874.83}]}
{"op":"mcm","clk":"4214813541","pt":1631365657042,"mc":[{"id":"1.187528277","rc":[{"batb":[[0,1.43,2084.01]],"ltp":1.43,"tv":35917.96,"id":2249229}]}]}
{"op":"mcm","clk":"4214814793","pt":1631365662252,"mc":[{"id":"1.187528277","rc":[{"trd":[[1.44,4807.66]],"batl":[[0,1.44,5797.92]],"ltp":1.44,"tv":36017.95,"id":2249229}],"tv":47974.82}]}
{"op":"mcm","clk":"4214815018","pt":1631365663156,"mc":[{"id":"1.187528277","rc":[{"trd":[[3.3,6965.2]],"batl":[[0,3.3,1445.11]],"ltp":3.3,"tv":11960.59,"id":19924831}],"tv":47978.54}]}
{"op":"mcm","clk":"4214818070","pt":1631365675156,"mc":[{"id":"1.187528277","rc":[{"batb":[[1,1.42,1671.22]],"ltp":1.44,"tv":36017.95,"id":2249229}]}]}
{"op":"mcm","clk":"4214818294","pt":1631365676079,"mc":[{"id":"1.187528277","rc":[{"trd":[[3.3,7027.38]],"batl":[[0,3.3,1414.02],[1,3.35,151.74]],"ltp":3.3,"tv":12022.77,"id":19924831}],"tv":48040.72}]}
{"op":"mcm","clk":"4214830194","pt":1631365725612,"mc":[{"id":"1.187528277","rc":[{"batb":[[1,3.2,287.4]],"ltp":3.3,"tv":12022.77,"id":19924831},{"batb":[[1,1.42,1650.23]],"ltp":1.44,"tv":36017.95,"id":2249229}]}]}
{"op":"mcm","clk":"4214835167","pt":1631365746666,"mc":[{"id":"1.187528277","rc":[{"batb":[[0,1.43,2120.16]],"ltp":1.44,"tv":36017.95,"id":2249229}]}]}
{"op":"mcm","clk":"4214839880","pt":1631365765709,"mc":[{"id":"1.187528277","rc":[{"batb":[[1,1.42,1655.84]],"ltp":1.44,"tv":36017.95,"id":2249229}]}]}
{"op":"mcm","clk":"4214840055","pt":1631365766445,"mc":[{"id":"1.187528277","rc":[{"batl":[[1,3.35,158.51]],"ltp":3.3,"tv":12022.77,"id":19924831}]}]}
{"op":"mcm","clk":"4214862095","pt":1631365852324,"mc":[{"id":"1.187528277","rc":[{"batb":[[1,1.42,1659.08]],"ltp":1.44,"tv":36017.95,"id":2249229}]}]}
{"op":"mcm","clk":"4214863516","pt":1631365857747,"mc":[{"id":"1.187528277","rc":[{"trd":[[1.44,4938.65]],"batl":[[0,1.44,5732.42]],"ltp":1.44,"tv":36148.94,"id":2249229}],"tv":48171.72}]}
{"op":"mcm","clk":"4214867515","pt":1631365873171,"mc":[{"id":"1.187528277","rc":[{"trd":[[1.44,4948.78]],"batl":[[0,1.44,5727.36]],"ltp":1.44,"tv":36159.07,"id":2249229}],"tv":48181.84}]}
{"op":"mcm","clk":"4214900293","pt":1631366000713,"mc":[{"id":"1.187528277","rc":[{"batb":[[1,1.42,1668.48]],"ltp":1.44,"tv":36159.07,"id":2249229}]}]}
{"op":"mcm","clk":"4214913330","pt":1631366052623,"mc":[{"id":"1.187528277","rc":[{"trd":[[3.25,1219.9]],"batb":[[0,3.25,241.25]],"ltp":3.25,"tv":12038.77,"id":19924831}],"tv":48197.84}]}
{"op":"mcm","clk":"4214974299","pt":1631366295719,"mc":[{"id":"1.187528277","rc":[{"batb":[[1,3.2,278.86]],"ltp":3.25,"tv":12038.77,"id":19924831},{"batl":[[1,1.45,1692.47]],"ltp":1.44,"tv":36159.07,"id":2249229}]}]}
{"op":"mcm","clk":"4215011393","pt":1631366440975,"mc":[{"id":"1.187528277","rc":[{"trd":[[3.25,1237.5]],"batb":[[0,3.25,232.45]],"ltp":3.25,"tv":12056.36,"id":19924831}],"tv":48215.44}]}
{"op":"mcm","clk":"4215022676","pt":1631366484575,"mc":[{"id":"1.187528277","rc":[{"batl":[[1,1.45,1687.02]],"ltp":1.44,"tv":36159.07,"id":2249229}]}]}
{"op":"mcm","clk":"4215034402","pt":1631366531471,"mc":[{"id":"1.187528277","rc":[{"trd":[[1.44,5022.77]],"batl":[[0,1.44,5690.36]],"ltp":1.44,"tv":36233.07,"id":2249229}],"tv":48289.43}]}
{"op":"mcm","clk":"4215040753","pt":1631366558248,"mc":[{"id":"1.187528277","rc":[{"trd":[[3.3,9855.41]],"batb":[[0,3.3,2656.87],[1,3.25,232.45],[2,3.2,222.61]],"batl":[[0,3.35,158.51],[1,3.4,96.5],[2,3.45,150]],"ltp":3.3,"tv":14884.39,"id":19924831},{"trd":[[1.43,16365.56]],"batb":[[0,1.43,1989.92]],"batl":[[0,1.44,5815.36]],"ltp":1.43,"tv":36493.55,"id":2249229}],"tv":51377.95}]}
{"op":"mcm","clk":"4215044713","pt":1631366574545,"mc":[{"id":"1.187528277","rc":[{"trd":[[1.43,16626.05]],"batb":[[0,1.43,1859.68],[1,1.42,1621.57]],"ltp":1.43,"tv":36754.03,"id":2249229}],"tv":51638.43}]}
{"op":"mcm","clk":"4215047190","pt":1631366584674,"mc":[{"id":"1.187528277","rc":[{"batb":[[1,3.25,259.78],[2,3.2,180.76]],"batl":[[1,3.4,86.25]],"ltp":3.3,"tv":14884.39,"id":19924831},{"batb":[[1,1.42,1535.31],[2,1.41,2692.65]],"batl":[[1,1.45,1693]],"ltp":1.43,"tv":36754.03,"id":2249229}]}]}
{"op":"mcm","clk":"4215054726","pt":1631366614642,"mc":[{"id":"1.187528277","rc":[{"batb":[[1,3.25,232.45]],"batl":[[1,3.4,52.94]],"ltp":3.3,"tv":14884.39,"id":19924831},{"batb":[[2,1.41,2559.41]],"batl":[[1,1.45,1609.3]],"ltp":1.43,"tv":36754.03,"id":2249229}]}]}
{"op":"mcm","clk":"4215055671","pt":1631366618424,"mc":[{"id":"1.187528277","rc":[{"batb":[[2,3.2,146.22]],"ltp":3.3,"tv":14884.39,"id":19924831}]}]}
{"op":"mcm","clk":"4215055924","pt":1631366619404,"mc":[{"id":"1.187528277","rc":[{"batb":[[2,3.2,134]],"ltp":3.3,"tv":14884.39,"id":19924831}]}]}
{"op":"mcm","clk":"4215056244","pt":1631366620613,"mc":[{"id":"1.187528277","rc":[{"batb":[[2,3.2,21]],"ltp":3.3,"tv":14884.39,"id":19924831}]}]}
{"op":"mcm","clk":"4215056363","pt":1631366621045,"mc":[{"id":"1.187528277","rc":[{"batb":[[1,1.42,1532.07]],"ltp":1.43,"tv":36754.03,"id":2249229}]}]}
{"op":"mcm","clk":"4215056688","pt":1631366622298,"mc":[{"id":"1.187528277","rc":[{"batb":[[1,1.42,1526.46]],"batl":[[0,1.44,5821.67]],"ltp":1.43,"tv":36754.03,"id":2249229}]}]}
{"op":"mcm","clk":"4215056978","pt":1631366623697,"mc":[{"id":"1.187528277","rc":[{"batb":[[1,3.25,486.64]],"ltp":3.3,"tv":14884.39,"id":19924831},{"batl":[[1,1.45,1589.15]],"ltp":1.43,"tv":36754.03,"id":2249229}]}]}
{"op":"mcm","clk":"4215057106","pt":1631366624190,"mc":[{"id":"1.187528277","rc":[{"batl":[[0,3.35,151.74]],"ltp":3.3,"tv":14884.39,"id":19924831}]}]}
{"op":"mcm","clk":"4215057408","pt":1631366625429,"mc":[{"id":"1.187528277","rc":[{"batl":[[0,3.35,142.85],[1,3.4,157.06]],"ltp":3.3,"tv":14884.39,"id":19924831}]}]}
{"op":"mcm","clk":"4215064476","pt":1631366654962,"mc":[{"id":"1.187528277","rc":[{"batb":[[0,3.3,54.54]],"ltp":3.3,"tv":14884.39,"id":19924831},{"batl":[[0,1.44,5696.67]],"ltp":1.43,"tv":36754.03,"id":2249229}]}]}
{"op":"mcm","clk":"4215068429","pt":1631366670593,"mc":[{"id":"1.187528277","rc":[{"batb":[[0,3.25,486.64],[1,3.2,21],[2,2.78,22.83]],"batl":[[0,3.35,196.58]],"ltp":3.3,"tv":14884.39,"id":19924831},{"batl":[[0,1.44,696.67]],"ltp":1.43,"tv":36754.03,"id":2249229}]}]}
{"op":"mcm","clk":"4215069307","pt":1631366674305,"mc":[{"id":"1.187528277","rc":[{"trd":[[1.43,19766.05]],"batb":[[0,1.43,289.67]],"ltp":1.43,"tv":39894.04,"id":2249229}],"tv":54778.43}]}
{"op":"mcm","clk":"4215074466","pt":1631366695450,"mc":[{"id":"1.187528277","rc":[{"batl":[[0,3.3,54.54],[1,3.35,196.58],[2,3.4,157.06]],"ltp":3.3,"tv":14884.39,"id":19924831},{"batb":[[0,1.43,3489.67]],"ltp":1.43,"tv":39894.04,"id":2249229}]}]}
{"op":"mcm","clk":"4215076983","pt":1631366705800,"mc":[{"id":"1.187528277","rc":[{"trd":[[1.44,5023.13]],"batl":[[0,1.44,696.49]],"ltp":1.44,"tv":39894.4,"id":2249229}],"tv":54778.79}]}
{"op":"mcm","clk":"4215081918","pt":1631366724648,"mc":[{"id":"1.187528277","rc":[{"trd":[[3.3,9860.87]],"batl":[[0,3.3,51.81]],"ltp":3.3,"tv":14889.85,"id":19924831}],"tv":54784.25}]}
{"op":"mcm","clk":"4215086107","pt":1631366741485,"mc":[{"id":"1.187528277","rc":[{"batl":[[2,3.4,52.94]],"ltp":3.3,"tv":14889.85,"id":19924831}]}]}
{"op":"mcm","clk":"4215086439","pt":1631366742707,"mc":[{"id":"1.187528277","rc":[{"batl":[[0,3.35,196.58],[1,3.4,52.94],[2,3.45,150]],"ltp":3.3,"tv":14889.85,"id":19924831},{"batb":[[0,1.43,289.67]],"batl":[[0,1.44,821.49]],"ltp":1.44,"tv":39894.4,"id":2249229}]}]}
{"op":"mcm","clk":"4215086637","pt":1631366743459,"mc":[{"id":"1.187528277","rc":[{"batb":[[1,1.42,1529.37]],"ltp":1.44,"tv":39894.4,"id":2249229}]}]}
{"op":"mcm","clk":"4215086843","pt":1631366744362,"mc":[{"id":"1.187528277","rc":[{"batb":[[0,1.43,371.11]],"batl":[[0,1.44,815.18]],"ltp":1.44,"tv":39894.4,"id":2249229}]}]}
{"op":"mcm","clk":"4215087174","pt":1631366745564,"mc":[{"id":"1.187528277","rc":[{"batl":[[0,1.44,524.44]],"ltp":1.44,"tv":39894.4,"id":2249229}]}]}
{"op":"mcm","clk":"4215087453","pt":1631366746691,"mc":[{"id":"1.187528277","rc":[{"batb":[[0,1.43,496.98]],"batl":[[0,1.44,487.64],[1,1.45,1671.59]],"ltp":1.44,"tv":39894.4,"id":2249229}]}]}
{"op":"mcm","clk":"4215087631","pt":1631366747405,"mc":[{"id":"1.187528277","rc":[{"batb":[[0,3.25,351.74],[1,3.2,132.16]],"ltp":3.3,"tv":14889.85,"id":19924831}]}]}
{"op":"mcm","clk":"4215087890","pt":1631366748291,"mc":[{"id":"1.187528277","rc":[{"batl":[[0,3.35,257.96]],"ltp":3.3,"tv":14889.85,"id":19924831}]}]}
{"op":"mcm","clk":"4215095003","pt":1631366776212,"mc":[{"id":"1.187528277","rc":[{"batb":[[0,3.25,378.21]],"batl":[[1,3.4,85.39]],"ltp":3.3,"tv":14889.85,"id":19924831},{"batb":[[2,1.41,2692.65]],"batl":[[1,1.45,1755.28]],"ltp":1.44,"tv":39894.4,"id":2249229}]}]}
{"op":"mcm","clk":"4215099828","pt":1631366795353,"mc":[{"id":"1.187528277","rc":[{"batb":[[0,3.25,392.73]],"batl":[[1,3.4,52.94],[2,3.45,193.56]],"ltp":3.3,"tv":14889.85,"id":19924831},{"batb":[[2,1.41,2644.82]],"batl":[[1,1.45,1797.99]],"ltp":1.44,"tv":39894.4,"id":2249229}]}]}
{"op":"mcm","clk":"4215110970","pt":1631366838588,"mc":[{"id":"1.187528277","rc":[{"batb":[[1,1.42,1551.53]],"batl":[[0,1.44,459.92]],"ltp":1.44,"tv":39894.4,"id":2249229}]}]}
{"op":"mcm","clk":"4215111198","pt":1631366839485,"mc":[{"id":"1.187528277","rc":[{"batb":[[0,3.25,364.77],[1,3.2,163.03]],"ltp":3.3,"tv":14889.85,"id":19924831}]}]}
{"op":"mcm","clk":"4215111435","pt":1631366840486,"mc":[{"id":"1.187528277","rc":[{"batl":[[0,3.35,175.77]],"ltp":3.3,"tv":14889.85,"id":19924831}]}]}
{"op":"mcm","clk":"4215111741","pt":1631366841573,"mc":[{"id":"1.187528277","rc":[{"batl":[[0,3.35,127.66],[1,3.4,156.69]],"ltp":3.3,"tv":14889.85,"id":19924831}]}]}
{"op":"mcm","clk":"4215122811","pt":1631366882753,"mc":[{"id":"1.187528277","rc":[{"batb":[[0,1.43,460.83]],"ltp":1.44,"tv":39894.4,"id":2249229}]}]}
{"op":"mcm","clk":"4215134983","pt":1631366931411,"mc":[{"id":"1.187528277","rc":[{"batb":[[1,1.42,1526.46]],"ltp":1.44,"tv":39894.4,"id":2249229}]}]}
{"op":"mcm","clk":"4215135211","pt":1631366932220,"mc":[{"id":"1.187528277","rc":[{"batb":[[1,1.42,1508.74]],"ltp":1.44,"tv":39894.4,"id":2249229}]}]}
{"op":"mcm","clk":"4215135571","pt":1631366933623,"mc":[{"id":"1.187528277","rc":[{"batb":[[0,3.25,358.72],[1,3.2,167.66]],"ltp":3.3,"tv":14889.85,"id":19924831},{"batb":[[0,1.43,448.51]],"ltp":1.44,"tv":39894.4,"id":2249229}]}]}
{"op":"mcm","clk":"4215135732","pt":1631366934260,"mc":[{"id":"1.187528277","rc":[{"batl":[[0,3.35,117.83]],"ltp":3.3,"tv":14889.85,"id":19924831}]}]}
{"op":"mcm","clk":"4215136071","pt":1631366935619,"mc":[{"id":"1.187528277","rc":[{"batl":[[0,3.35,100.25]],"ltp":3.3,"tv":14889.85,"id":19924831}]}]}
{"op":"mcm","clk":"4215136207","pt":1631366936218,"mc":[{"id":"1.187528277","rc":[{"batl":[[1,3.4,173.64]],"ltp":3.3,"tv":14889.85,"id":19924831}]}]}
{"op":"mcm","clk":"4215141169","pt":1631366956256,"mc":[{"id":"1.187528277","rc":[{"batb":[[0,3.3,66],[1,3.25,358.72],[2,3.2,167.66]],"ltp":3.3,"tv":14889.85,"id":19924831}]}]}
{"op":"mcm","clk":"4215161602","pt":1631367031207,"mc":[{"id":"1.187528277","rc":[{"batb":[[2,3.2,56.5]],"ltp":3.3,"tv":14889.85,"id":19924831}]}]}
{"op":"mcm","clk":"4215161877","pt":1631367032348,"mc":[{"id":"1.187528277","rc":[{"batb":[[2,3.2,21]],"ltp":3.3,"tv":14889.85,"id":19924831}]}]}
{"op":"mcm","clk":"4215162746","pt":1631367035627,"mc":[{"id":"1.187528277","rc":[{"batb":[[1,1.42,1499.66]],"batl":[[0,1.44,474.85]],"ltp":1.44,"tv":39894.4,"id":2249229}]}]}
{"op":"mcm","clk":"4215162984","pt":1631367036535,"mc":[{"id":"1.187528277","rc":[{"batb":[[0,3.3,75.9]],"ltp":3.3,"tv":14889.85,"id":19924831},{"batl":[[1,1.45,1786.31]],"ltp":1.44,"tv":39894.4,"id":2249229}]}]}
{"op":"mcm","clk":"4215182393","pt":1631367106490,"mc":[{"id":"1.187528277","rc":[{"batl":[[0,1.44,480.49]],"ltp":1.44,"tv":39894.4,"id":2249229}]}]}
{"op":"mcm","clk":"4215191349","pt":1631367138153,"mc":[{"id":"1.187528277","rc":[{"batl":[[0,3.35,244.85]],"ltp":3.3,"tv":14889.85,"id":19924831}]}]}
{"op":"mcm","clk":"4215194073","pt":1631367147051,"mc":[{"id":"1.187528277","rc":[{"batl":[[1,3.4,318.25]],"ltp":3.3,"tv":14889.85,"id":19924831}]}]}
{"op":"mcm","clk":"4215197632","pt":1631367161012,"mc":[{"id":"1.187528277","rc":[{"batl":[[2,3.45,338.16]],"ltp":3.3,"tv":14889.85,"id":19924831}]}]}
{"op":"mcm","clk":"4215206934","pt":1631367197487,"mc":[{"id":"1.187528277","rc":[{"batl":[[0,3.35,263.78]],"ltp":3.3,"tv":14889.85,"id":19924831},{"batb":[[1,1.42,1542.43]],"ltp":1.44,"tv":39894.4,"id":2249229}]}]}
{"op":"mcm","clk":"4215207045","pt":1631367197882,"mc":[{"id":"1.187528277","rc":[{"batl":[[1,3.4,339.23]],"ltp":3.3,"tv":14889.85,"id":19924831}]}]}
{"op":"mcm","clk":"4215229608","pt":1631367286354,"mc":[{"id":"1.187528277","rc":[{"batl":[[0,3.35,266.62]],"ltp":3.3,"tv":14889.85,"id":19924831},{"batb":[[1,1.42,1555.55]],"ltp":1.44,"tv":39894.4,"id":2249229}]}]}
{"op":"mcm","clk":"4215229718","pt":1631367286774,"mc":[{"id":"1.187528277","rc":[{"batl":[[1,3.4,345.05]],"ltp":3.3,"tv":14889.85,"id":19924831}]}]}
{"op":"mcm","clk":"4215247960","pt":1631367353888,"mc":[{"id":"1.187528277","rc":[{"trd":[[3.3,9910.87]],"batb":[[0,3.3,50.9]],"ltp":3.3,"tv":14939.85,"id":19924831}],"tv":54834.25}]}
{"op":"mcm","clk":"4215257598","pt":1631367390660,"mc":[{"id":"1.187528277","rc":[{"batb":[[1,1.42,1558.52]],"ltp":1.44,"tv":39894.4,"id":2249229}]}]}
{"op":"mcm","clk":"4215279858","pt":1631367468668,"mc":[{"id":"1.187528277","rc":[{"batl":[[1,3.4,365.05]],"ltp":3.3,"tv":14939.85,"id":19924831}]}]}
{"op":"mcm","clk":"4215289668","pt":1631367500248,"mc":[{"id":"1.187528277","rc":[{"batl":[[1,3.4,369.94]],"ltp":3.3,"tv":14939.85,"id":19924831}]}]}
{"op":"mcm","clk":"4215342153","pt":1631367692551,"mc":[{"id":"1.187528277","rc":[{"trd":[[1.43,20145.25]],"batb":[[0,1.43,258.92]],"ltp":1.43,"tv":40273.6,"id":2249229}],"tv":55213.45}]}
{"op":"mcm","clk":"4215352049","pt":1631367729260,"mc":[{"id":"1.187528277","rc":[{"batb":[[0,3.3,129.9]],"ltp":3.3,"tv":14939.85,"id":19924831}]}]}
{"op":"mcm","clk":"4215372647","pt":1631367806648,"mc":[{"id":"1.187528277","rc":[{"batb":[[0,1.43,228.63]],"batl":[[0,1.44,499.89]],"ltp":1.43,"tv":40273.6,"id":2249229}]}]}
{"op":"mcm","clk":"4215372824","pt":1631367807329,"mc":[{"id":"1.187528277","rc":[{"batb":[[0,3.3,139.49]],"batl":[[0,3.35,263.78]],"ltp":3.3,"tv":14939.85,"id":19924831}]}]}
{"op":"mcm","clk":"4215372977","pt":1631367807933,"mc":[{"id":"1.187528277","rc":[{"batl":[[0,3.35,254.91]],"ltp":3.3,"tv":14939.85,"id":19924831}]}]}
{"op":"mcm","clk":"4215409226","pt":1631367906124,"mc":[{"id":"1.187528277","rc":[{"batl":[[0,1.44,506.1]],"ltp":1.43,"tv":40273.6,"id":2249229}]}]}
{"op":"mcm","clk":"4215458551","pt":1631368106509,"mc":[{"id":"1.187528277","rc":[{"trd":[[1.43,20403.25]],"batb":[[0,1.43,99.63]],"ltp":1.43,"tv":40531.59,"id":2249229}],"tv":55471.45}]}
{"op":"mcm","clk":"4215461656","pt":1631368120117,"mc":[{"id":"1.187528277","rc":[{"trd":[[3.3,9920.87]],"batb":[[0,3.3,134.49]],"ltp":3.3,"tv":14949.85,"id":19924831}],"tv":55481.45}]}
{"op":"mcm","clk":"4215476058","pt":1631368170426,"mc":[{"id":"1.187528277","rc":[{"trd":[[1.43,20601.25]],"batb":[[0,1.43,40.9],[1,1.42,1607.15]],"ltp":1.43,"tv":40729.59,"id":2249229}],"tv":55679.45}]}
{"op":"mcm","clk":"4215481471","pt":1631368188361,"mc":[{"id":"1.187528277","rc":[{"trd":[[1.43,20681.25]],"batb":[[0,1.42,1608.05],[1,1.41,2644.82],[2,1.4,5936.81]],"ltp":1.43,"tv":40809.59,"id":2249229}],"tv":55759.45}]}
{"op":"mcm","clk":"4215482330","pt":1631368191529,"mc":[{"id":"1.187528277","rc":[{"batb":[[0,3.3,189.03]],"ltp":3.3,"tv":14949.85,"id":19924831},{"batb":[[0,1.43,7.04],[1,1.42,1610.74],[2,1.41,2644.82]],"ltp":1.43,"tv":40809.59,"id":2249229}]}]}
{"op":"mcm","clk":"4215482611","pt":1631368192463,"mc":[{"id":"1.187528277","rc":[{"batl":[[0,3.35,239.19]],"ltp":3.3,"tv":14949.85,"id":19924831}]}]}
{"op":"mcm","clk":"4215482807","pt":1631368193260,"mc":[{"id":"1.187528277","rc":[{"batl":[[1,3.4,373.72]],"ltp":3.3,"tv":14949.85,"id":19924831},{"trd":[[1.44,5075.25]],"batl":[[0,1.44,480.04]],"ltp":1.44,"tv":40861.71,"id":2249229}],"tv":55811.56}]}
{"op":"mcm","clk":"4215492622","pt":1631368225417,"mc":[{"id":"1.187528277","rc":[{"batl":[[0,3.35,185.46],[1,3.4,320.78]],"ltp":3.3,"tv":14949.85,"id":19924831},{"trd":[[1.43,20695.25]],"batb":[[0,1.42,1610.78],[1,1.41,2644.82],[2,1.4,5936.81]],"ltp":1.43,"tv":40875.71,"id":2249229}],"tv":55825.56}]}
{"op":"mcm","clk":"4215511714","pt":1631368292314,"mc":[{"id":"1.187528277","rc":[{"batb":[[0,1.42,1610.74]],"ltp":1.43,"tv":40875.71,"id":2249229}]}]}
{"op":"mcm","clk":"4215512729","pt":1631368296309,"mc":[{"id":"1.187528277","rc":[{"batb":[[0,1.42,1607.15],[1,1.41,3128.76]],"ltp":1.43,"tv":40875.71,"id":2249229}]}]}
{"op":"mcm","clk":"4215512970","pt":1631368297335,"mc":[{"id":"1.187528277","rc":[{"batb":[[0,1.42,1591.06]],"ltp":1.43,"tv":40875.71,"id":2249229}]}]}
{"op":"mcm","clk":"4215513183","pt":1631368298208,"mc":[{"id":"1.187528277","rc":[{"batb":[[0,3.3,197.9]],"ltp":3.3,"tv":14949.85,"id":19924831},{"batl":[[0,1.44,494.09]],"ltp":1.43,"tv":40875.71,"id":2249229}]}]}
{"op":"mcm","clk":"4215513561","pt":1631368299708,"mc":[{"id":"1.187528277","rc":[{"batl":[[0,3.35,173.98],[1,3.4,317]],"ltp":3.3,"tv":14949.85,"id":19924831}]}]}
{"op":"mcm","clk":"4215535389","pt":1631368385611,"mc":[{"id":"1.187528277","rc":[{"batl":[[0,1.44,499.25]],"ltp":1.43,"tv":40875.71,"id":2249229}]}]}
{"op":"mcm","clk":"4215535493","pt":1631368386001,"mc":[{"id":"1.187528277","rc":[{"batl":[[1,3.4,312.11]],"ltp":3.3,"tv":14949.85,"id":19924831}]}]}
{"op":"mcm","clk":"4215549916","pt":1631368440584,"mc":[{"id":"1.187528277","rc":[{"trd":[[1.44,5117.95]],"batl":[[0,1.44,477.9]],"ltp":1.44,"tv":40918.41,"id":2249229}],"tv":55868.27}]}
{"op":"mcm","clk":"4215558321","pt":1631368471637,"mc":[{"id":"1.187528277","rc":[{"batb":[[0,1.42,1542.43]],"ltp":1.44,"tv":40918.41,"id":2249229}]}]}
{"op":"mcm","clk":"4215558445","pt":1631368472170,"mc":[{"id":"1.187528277","rc":[{"batb":[[0,1.42,1591.06]],"batl":[[0,1.44,492.82]],"ltp":1.44,"tv":40918.41,"id":2249229}]}]}
{"op":"mcm","clk":"4215574925","pt":1631368531444,"mc":[{"id":"1.187528277","rc":[{"batb":[[0,1.42,1542.43]],"ltp":1.44,"tv":40918.41,"id":2249229}]}]}
{"op":"mcm","clk":"4215580961","pt":1631368553802,"mc":[{"id":"1.187528277","rc":[{"batb":[[0,1.42,1523.77]],"ltp":1.44,"tv":40918.41,"id":2249229}]}]}
{"op":"mcm","clk":"4215592951","pt":1631368601751,"mc":[{"id":"1.187528277","rc":[{"trd":[[1.44,5170.64]],"batl":[[0,1.44,466.48]],"ltp":1.44,"tv":40971.1,"id":2249229}],"tv":55920.95}]}
{"op":"mcm","clk":"4215605421","pt":1631368651259,"mc":[{"id":"1.187528277","rc":[{"trd":[[1.42,13843.24]],"batb":[[0,1.42,1522.39]],"ltp":1.42,"tv":40973.85,"id":2249229}],"tv":55923.7}]}
{"op":"mcm","clk":"4215605965","pt":1631368653516,"mc":[{"id":"1.187528277","rc":[{"batl":[[1,3.4,306.29]],"ltp":3.3,"tv":14949.85,"id":19924831},{"batl":[[0,1.44,470.87]],"ltp":1.42,"tv":40973.85,"id":2249229}]}]}
{"op":"mcm","clk":"4215671615","pt":1631368865044,"mc":[{"id":"1.187528277","rc":[{"batb":[[0,1.42,1542.41]],"ltp":1.42,"tv":40973.85,"id":2249229}]}]}
{"op":"mcm","clk":"4215683813","pt":1631368902309,"mc":[{"id":"1.187528277","rc":[{"batb":[[0,1.42,1522.39]],"ltp":1.42,"tv":40973.85,"id":2249229}]}]}
{"op":"mcm","clk":"4215683942","pt":1631368902761,"mc":[{"id":"1.187528277","rc":[{"batb":[[0,1.42,1558.12]],"ltp":1.42,"tv":40973.85,"id":2249229}]}]}
{"op":"mcm","clk":"4215690850","pt":1631368922909,"mc":[{"id":"1.187528277","rc":[{"batb":[[0,1.43,43.98],[1,1.42,1558.12],[2,1.41,3128.76]],"ltp":1.42,"tv":40973.85,"id":2249229}]}]}
{"op":"mcm","clk":"4215695049","pt":1631368935183,"mc":[{"id":"1.187528277","rc":[{"batb":[[1,1.42,1522.39]],"ltp":1.42,"tv":40973.85,"id":2249229}]}]}
{"op":"mcm","clk":"4215699328","pt":1631368948011,"mc":[{"id":"1.187528277","rc":[{"batb":[[2,1.41,2644.82]],"ltp":1.42,"tv":40973.85,"id":2249229}]}]}
{"op":"mcm","clk":"4215699943","pt":1631368949618,"mc":[{"id":"1.187528277","rc":[{"batb":[[0,1.43,50.57]],"ltp":1.42,"tv":40973.85,"id":2249229}]}]}
{"op":"mcm","clk":"4215734524","pt":1631369040410,"mc":[{"id":"1.187528277","rc":[{"batb":[[1,3.25,370.86]],"ltp":3.3,"tv":14949.85,"id":19924831},{"batb":[[1,1.42,1543.38]],"ltp":1.42,"tv":40973.85,"id":2249229}]}]}
{"op":"mcm","clk":"4215800083","pt":1631369233612,"mc":[{"id":"1.187528277","rc":[{"batl":[[0,1.44,1870.87]],"ltp":1.42,"tv":40973.85,"id":2249229}]}]}
{"op":"mcm","clk":"4215803033","pt":1631369241376,"mc":[{"id":"1.187528277","rc":[{"batl":[[0,1.44,2081.54]],"ltp":1.42,"tv":40973.85,"id":2249229}]}]}
{"op":"mcm","clk":"4215803150","pt":1631369241835,"mc":[{"id":"1.187528277","rc":[{"batb":[[1,3.25,465.55]],"ltp":3.3,"tv":14949.85,"id":19924831}]}]}
{"op":"mcm","clk":"4215805473","pt":1631369248420,"mc":[{"id":"1.187528277","rc":[{"batb":[[0,1.43,1450.57]],"ltp":1.42,"tv":40973.85,"id":2249229}]}]}
{"op":"mcm","clk":"4215809761","pt":1631369260348,"mc":[{"id":"1.187528277","rc":[{"batb":[[0,1.43,1452.74]],"ltp":1.42,"tv":40973.85,"id":2249229}]}]}
{"op":"mcm","clk":"4215821232","pt":1631369290278,"mc":[{"id":"1.187528277","rc":[{"trd":[[3.3,9930.87]],"batb":[[0,3.3,192.9]],"ltp":3.3,"tv":14959.85,"id":19924831}],"tv":55933.7}]}
{"op":"mcm","clk":"4215835819","pt":1631369326535,"mc":[{"id":"1.187528277","rc":[{"batb":[[0,1.43,1515.68]],"batl":[[0,1.44,2111.41],[1,1.45,1820.47]],"ltp":1.42,"tv":40973.85,"id":2249229}]}]}
{"op":"mcm","clk":"4215836124","pt":1631369327241,"mc":[{"id":"1.187528277","rc":[{"batb":[[1,3.25,493.75]],"batl":[[0,3.35,263.72]],"ltp":3.3,"tv":14959.85,"id":19924831}]}]}
{"op":"mcm","clk":"4215849697","pt":1631369364384,"mc":[{"id":"1.187528277","rc":[{"trd":[[1.44,5256.04]],"batl":[[0,1.44,2068.71]],"ltp":1.44,"tv":41059.25,"id":2249229}],"tv":56019.11}]}
{"op":"mcm","clk":"4215864166","pt":1631369406389,"mc":[{"id":"1.187528277","rc":[{"batb":[[1,1.42,1575.27]],"ltp":1.44,"tv":41059.25,"id":2249229}]}]}
{"op":"mcm","clk":"4215864620","pt":1631369407580,"mc":[{"id":"1.187528277","rc":[{"batb":[[1,3.25,497.13]],"batl":[[0,3.35,281.21]],"ltp":3.3,"tv":14959.85,"id":19924831},{"batl":[[1,1.45,1835.07]],"ltp":1.44,"tv":41059.25,"id":2249229}]}]}
{"op":"mcm","clk":"4215890186","pt":1631369481721,"mc":[{"id":"1.187528277","rc":[{"batb":[[1,1.42,1586.25]],"batl":[[1,1.45,1838.4]],"ltp":1.44,"tv":41059.25,"id":2249229}]}]}
{"op":"mcm","clk":"4215890287","pt":1631369482055,"mc":[{"id":"1.187528277","rc":[{"batl":[[1,3.4,309.23]],"ltp":3.3,"tv":14959.85,"id":19924831}]}]}
{"op":"mcm","clk":"4215931902","pt":1631369591915,"mc":[{"id":"1.187528277","rc":[{"trd":[[1.44,5284.78]],"batl":[[0,1.44,2054.34]],"ltp":1.44,"tv":41087.99,"id":2249229}],"tv":56047.85}]}
{"op":"mcm","clk":"4215974587","pt":1631369705914,"mc":[{"id":"1.187528277","rc":[{"batl":[[1,3.4,311.23]],"ltp":3.3,"tv":14959.85,"id":19924831}]}]}
{"op":"mcm","clk":"4216171405","pt":1631370196766,"mc":[{"id":"1.187528277","rc":[{"trd":[[1.44,5328.34]],"batl":[[0,1.44,2032.56]],"ltp":1.44,"tv":41131.55,"id":2249229}],"tv":56091.41}]}
{"op":"mcm","clk":"4216256223","pt":1631370436901,"mc":[{"id":"1.187528277","rc":[{"batl":[[0,3.35,301.21],[1,3.4,291.23]],"ltp":3.3,"tv":14959.85,"id":19924831}]}]}
{"op":"mcm","clk":"4216260505","pt":1631370446147,"mc":[{"id":"1.187528277","rc":[{"batb":[[1,1.42,1594.97]],"ltp":1.44,"tv":41131.55,"id":2249229}]}]}
{"op":"mcm","clk":"4216260782","pt":1631370446730,"mc":[{"id":"1.187528277","rc":[{"batl":[[0,3.35,306.83]],"ltp":3.3,"tv":14959.85,"id":19924831}]}]}
{"op":"mcm","clk":"4216291564","pt":1631370527051,"mc":[{"id":"1.187528277","rc":[{"batb":[[1,1.42,1598.27]],"ltp":1.44,"tv":41131.55,"id":2249229}]}]}
{"op":"mcm","clk":"4216339594","pt":1631370659407,"mc":[{"id":"1.187528277","rc":[{"trd":[[1.43,20699.25]],"batb":[[0,1.43,1513.68]],"ltp":1.43,"tv":41135.55,"id":2249229}],"tv":56095.41}]}
{"op":"mcm","clk":"4216392711","pt":1631370805988,"mc":[{"id":"1.187528277","rc":[{"trd":[[1.44,5475.23]],"batl":[[0,1.44,1959.12]],"ltp":1.44,"tv":41282.44,"id":2249229}],"tv":56242.3}]}
{"op":"mcm","clk":"4216433479","pt":1631370917595,"mc":[{"id":"1.187528277","rc":[{"batb":[[0,1.43,1529.05]],"ltp":1.44,"tv":41282.44,"id":2249229}]}]}
{"op":"mcm","clk":"4216433791","pt":1631370918520,"mc":[{"id":"1.187528277","rc":[{"batb":[[1,3.25,493.75]],"ltp":3.3,"tv":14959.85,"id":19924831},{"batl":[[0,1.44,1971.11]],"ltp":1.44,"tv":41282.44,"id":2249229}]}]}
{"op":"mcm","clk":"4216471158","pt":1631371018545,"mc":[{"id":"1.187528277","rc":[{"batb":[[0,1.43,1729.05]],"ltp":1.44,"tv":41282.44,"id":2249229}]}]}
{"op":"mcm","clk":"4216488079","pt":1631371062978,"mc":[{"id":"1.187528277","rc":[{"batl":[[0,3.35,321.34]],"ltp":3.3,"tv":14959.85,"id":19924831}]}]}
{"op":"mcm","clk":"4216499865","pt":1631371096037,"mc":[{"id":"1.187528277","rc":[{"batb":[[0,3.3,218.42]],"ltp":3.3,"tv":14959.85,"id":19924831}]}]}
{"op":"mcm","clk":"4216520741","pt":1631371149496,"mc":[{"id":"1.187528277","rc":[{"batb":[[1,1.42,1603.9]],"batl":[[0,1.44,1981.68]],"ltp":1.44,"tv":41282.44,"id":2249229}]}]}
{"op":"mcm","clk":"4216520928","pt":1631371149979,"mc":[{"id":"1.187528277","rc":[{"batb":[[0,3.3,222.83]],"ltp":3.3,"tv":14959.85,"id":19924831}]}]}
{"op":"mcm","clk":"4216545130","pt":1631371222915,"mc":[{"id":"1.187528277","rc":[{"batl":[[0,1.44,1984.79]],"ltp":1.44,"tv":41282.44,"id":2249229}]}]}
{"op":"mcm","clk":"4216590896","pt":1631371359435,"mc":[{"id":"1.187528277","rc":[{"trd":[[3.35,3141.3]],"batl":[[0,3.35,316.34]],"ltp":3.35,"tv":14969.85,"id":19924831}],"tv":56252.3}]}
{"op":"mcm","clk":"4216613816","pt":1631371423018,"mc":[{"id":"1.187528277","rc":[{"batl":[[0,3.35,322.77]],"ltp":3.35,"tv":14969.85,"id":19924831}]}]}
{"op":"mcm","clk":"4216617642","pt":1631371434338,"mc":[{"id":"1.187528277","rc":[{"trd":[[3.35,3147.75]],"batl":[[0,3.35,319.54]],"ltp":3.35,"tv":14976.29,"id":19924831}],"tv":56258.74}]}
{"op":"mcm","clk":"4216630802","pt":1631371475013,"mc":[{"id":"1.187528277","rc":[{"batb":[[0,1.43,329.05]],"batl":[[0,1.44,584.79]],"ltp":1.44,"tv":41282.44,"id":2249229}]}]}
{"op":"mcm","clk":"4216644070","pt":1631371516702,"mc":[{"id":"1.187528277","rc":[{"batb":[[0,1.43,293.5]],"ltp":1.44,"tv":41282.44,"id":2249229}]}]}
{"op":"mcm","clk":"4216644283","pt":1631371517331,"mc":[{"id":"1.187528277","rc":[{"batl":[[0,1.44,581.68]],"ltp":1.44,"tv":41282.44,"id":2249229}]}]}
{"op":"mcm","clk":"4216644529","pt":1631371518409,"mc":[{"id":"1.187528277","rc":[{"batl":[[0,1.44,571.11]],"ltp":1.44,"tv":41282.44,"id":2249229}]}]}
{"op":"mcm","clk":"4216644765","pt":1631371519087,"mc":[{"id":"1.187528277","rc":[{"batl":[[0,1.44,559.12]],"ltp":1.44,"tv":41282.44,"id":2249229}]}]}
{"op":"mcm","clk":"4216645232","pt":1631371520382,"mc":[{"id":"1.187528277","rc":[{"batl":[[0,1.44,375.25]],"ltp":1.44,"tv":41282.44,"id":2249229}]}]}
{"op":"mcm","clk":"4216645675","pt":1631371521721,"mc":[{"id":"1.187528277","rc":[{"batb":[[1,3.25,398.51]],"ltp":3.35,"tv":14976.29,"id":19924831}]}]}
{"op":"mcm","clk":"4216645893","pt":1631371522395,"mc":[{"id":"1.187528277","rc":[{"batl":[[0,3.35,313.12]],"ltp":3.35,"tv":14976.29,"id":19924831}]}]}
{"op":"mcm","clk":"4216646293","pt":1631371523664,"mc":[{"id":"1.187528277","rc":[{"batl":[[0,3.35,292.99]],"ltp":3.35,"tv":14976.29,"id":19924831}]}]}
{"op":"mcm","clk":"4216646507","pt":1631371524395,"mc":[{"id":"1.187528277","rc":[{"batl":[[0,3.35,275.5]],"ltp":3.35,"tv":14976.29,"id":19924831}]}]}
{"op":"mcm","clk":"4216646757","pt":1631371525224,"mc":[{"id":"1.187528277","rc":[{"batl":[[0,3.35,233.6]],"ltp":3.35,"tv":14976.29,"id":19924831}]}]}
{"op":"mcm","clk":"4216676427","pt":1631371624509,"mc":[{"id":"1.187528277","rc":[{"batb":[[1,1.42,1598.27]],"ltp":1.44,"tv":41282.44,"id":2249229}]}]}
{"op":"mcm","clk":"4216676753","pt":1631371625597,"mc":[{"id":"1.187528277","rc":[{"batb":[[1,1.42,1586.25]],"ltp":1.44,"tv":41282.44,"id":2249229}]}]}
{"op":"mcm","clk":"4216676907","pt":1631371626214,"mc":[{"id":"1.187528277","rc":[{"batb":[[1,1.42,1575.27]],"ltp":1.44,"tv":41282.44,"id":2249229}]}]}
{"op":"mcm","clk":"4216677311","pt":1631371627541,"mc":[{"id":"1.187528277","rc":[{"batl":[[0,1.44,343.82],[1,1.45,1835.07]],"ltp":1.44,"tv":41282.44,"id":2249229}]}]}
{"op":"mcm","clk":"4216677666","pt":1631371628587,"mc":[{"id":"1.187528277","rc":[{"batl":[[1,1.45,1805.75]],"ltp":1.44,"tv":41282.44,"id":2249229}]}]}
{"op":"mcm","clk":"4216677834","pt":1631371629220,"mc":[{"id":"1.187528277","rc":[{"batb":[[1,3.25,370.86]],"ltp":3.35,"tv":14976.29,"id":19924831}]}]}
{"op":"mcm","clk":"4216677991","pt":1631371629744,"mc":[{"id":"1.187528277","rc":[{"batl":[[0,3.35,218.44]],"ltp":3.35,"tv":14976.29,"id":19924831}]}]}
{"op":"mcm","clk":"4216698223","pt":1631371700716,"mc":[{"id":"1.187528277","rc":[{"batb":[[1,3.25,364.06]],"ltp":3.35,"tv":14976.29,"id":19924831},{"batl":[[1,1.45,1791.55]],"ltp":1.44,"tv":41282.44,"id":2249229}]}]}
{"op":"mcm","clk":"4216720520","pt":1631371789759,"mc":[{"id":"1.187528277","rc":[{"trd":[[1.43,20842.6]],"batb":[[0,1.43,179.85]],"ltp":1.43,"tv":41425.79,"id":2249229}],"tv":56402.09}]}
{"op":"mcm","clk":"4216746485","pt":1631371895591,"mc":[{"id":"1.187528277","rc":[{"trd":[[3.3,9970.87]],"batb":[[0,3.3,202.83]],"ltp":3.3,"tv":15016.29,"id":19924831},{"batb":[[0,1.43,206.83]],"ltp":1.43,"tv":41425.79,"id":2249229}],"tv":56442.09}]}
{"op":"mcm","clk":"4216746543","pt":1631371895918,"mc":[{"id":"1.187528277","rc":[{"batl":[[0,3.35,208.89]],"ltp":3.3,"tv":15016.29,"id":19924831}]}]}
{"op":"mcm","clk":"4216765952","pt":1631371978477,"mc":[{"id":"1.187528277","rc":[{"batb":[[1,1.42,1560.66]],"ltp":1.43,"tv":41425.79,"id":2249229}]}]}
{"op":"mcm","clk":"4216766135","pt":1631371979387,"mc":[{"id":"1.187528277","rc":[{"batb":[[0,1.43,210.88]],"batl":[[0,1.44,332.23]],"ltp":1.43,"tv":41425.79,"id":2249229}]}]}
{"op":"mcm","clk":"4216845987","pt":1631372343922,"mc":[{"id":"1.187528277","rc":[{"trd":[[1.43,21242.6]],"batb":[[0,1.43,10.88]],"ltp":1.43,"tv":41825.79,"id":2249229}],"tv":56842.09}]}
{"op":"mcm","clk":"4216851001","pt":1631372368455,"mc":[{"id":"1.187528277","rc":[{"trd":[[3.3,10002.97]],"batb":[[0,3.3,186.78]],"ltp":3.3,"tv":15048.4,"id":19924831},{"batb":[[0,1.43,30.77]],"ltp":1.43,"tv":41825.79,"id":2249229}],"tv":56874.19}]}
{"op":"mcm","clk":"4216851216","pt":1631372369465,"mc":[{"id":"1.187528277","rc":[{"trd":[[3.3,10008.95]],"batb":[[0,3.3,183.79]],"ltp":3.3,"tv":15054.37,"id":19924831},{"batb":[[0,1.43,10.88]],"ltp":1.43,"tv":41825.79,"id":2249229}],"tv":56880.17}]}
{"op":"mcm","clk":"4216854664","pt":1631372387274,"mc":[{"id":"1.187528277","rc":[{"batb":[[0,3.3,186.64]],"batl":[[0,3.35,196.63]],"ltp":3.3,"tv":15054.37,"id":19924831}]}]}
{"op":"mcm","clk":"4216894191","pt":1631372558474,"mc":[{"id":"1.187528277","rc":[{"batb":[[0,1.43,13.53]],"ltp":1.43,"tv":41825.79,"id":2249229}]}]}
{"op":"mcm","clk":"4216898564","pt":1631372576605,"mc":[{"id":"1.187528277","rc":[{"trd":[[3.35,3152.75]],"batl":[[0,3.35,194.13]],"ltp":3.35,"tv":15059.37,"id":19924831}],"tv":56885.17}]}
{"op":"mcm","clk":"4216906175","pt":1631372609519,"mc":[{"id":"1.187528277","rc":[{"batl":[[0,1.44,864.03]],"ltp":1.43,"tv":41825.79,"id":2249229}]}]}
{"op":"mcm","clk":"4216915122","pt":1631372646593,"mc":[{"id":"1.187528277","rc":[{"trd":[[3.35,3346.88]],"batb":[[0,3.35,53.73],[1,3.3,186.64],[2,3.25,308.68]],"batl":[[0,3.4,291.23],[1,3.45,338.16],[2,3.5,25]],"ltp":3.35,"tv":15253.51,"id":19924831},{"trd":[[1.42,17422.52],[1.43,21269.67]],"batb":[[0,1.41,2666.56],[1,1.4,5936.81],[2,1.39,6190.77]],"batl":[[0,1.42,13078.94],[1,1.44,864.03],[2,1.45,1791.55]],"ltp":1.42,"tv":45432.15,"id":2249229}],"tv":60685.66}]}
{"op":"mcm","clk":"4216919287","pt":1631372664708,"mc":[{"id":"1.187528277","rc":[{"batl":[[1,1.44,846.12]],"ltp":1.42,"tv":45432.15,"id":2249229}]}]}
{"op":"mcm","clk":"4216919445","pt":1631372665412,"mc":[{"id":"1.187528277","rc":[{"batl":[[1,1.44,831.2]],"ltp":1.42,"tv":45432.15,"id":2249229}]}]}
{"op":"mcm","clk":"4216919596","pt":1631372666012,"mc":[{"id":"1.187528277","rc":[{"batl":[[2,1.45,1785.73]],"ltp":1.42,"tv":45432.15,"id":2249229}]}]}
{"op":"mcm","clk":"4216919859","pt":1631372667263,"mc":[{"id":"1.187528277","rc":[{"batl":[[1,1.44,826.04],[2,1.45,1780.49]],"ltp":1.42,"tv":45432.15,"id":2249229}]}]}
{"op":"mcm","clk":"4216920062","pt":1631372668368,"mc":[{"id":"1.187528277","rc":[{"batl":[[1,1.44,820.39],[2,1.45,1764.33]],"ltp":1.42,"tv":45432.15,"id":2249229}]}]}
{"op":"mcm","clk":"4216920315","pt":1631372669568,"mc":[{"id":"1.187528277","rc":[{"batl":[[1,1.44,792.69]],"ltp":1.42,"tv":45432.15,"id":2249229}]}]}
{"op":"mcm","clk":"4216920454","pt":1631372670263,"mc":[{"id":"1.187528277","rc":[{"batl":[[1,1.44,788.3]],"ltp":1.42,"tv":45432.15,"id":2249229}]}]}
{"op":"mcm","clk":"4216920652","pt":1631372671036,"mc":[{"id":"1.187528277","rc":[{"batl":[[1,1.44,768.35]],"ltp":1.42,"tv":45432.15,"id":2249229}]}]}
{"op":"mcm","clk":"4216921023","pt":1631372672674,"mc":[{"id":"1.187528277","rc":[{"batl":[[2,1.45,1434.81]],"ltp":1.42,"tv":45432.15,"id":2249229}]}]}
{"op":"mcm","clk":"4216921223","pt":1631372673480,"mc":[{"id":"1.187528277","rc":[{"batl":[[2,1.45,1396]],"ltp":1.42,"tv":45432.15,"id":2249229}]}]}
{"op":"mcm","clk":"4216921384","pt":1631372674161,"mc":[{"id":"1.187528277","rc":[{"batl":[[1,1.44,762.14]],"ltp":1.42,"tv":45432.15,"id":2249229}]}]}
{"op":"mcm","clk":"4216921743","pt":1631372675668,"mc":[{"id":"1.187528277","rc":[{"batb":[[2,3.25,230.2]],"ltp":3.35,"tv":15253.51,"id":19924831},{"batl":[[1,1.44,742.74]],"ltp":1.42,"tv":45432.15,"id":2249229}]}]}
{"op":"mcm","clk":"4216922311","pt":1631372677683,"mc":[{"id":"1.187528277","rc":[{"batb":[[0,1.41,3171.89],[1,1.4,6388.84]],"batl":[[1,1.43,18.88],[2,1.44,742.74]],"ltp":1.42,"tv":45432.15,"id":2249229}]}]}
{"op":"mcm","clk":"4216922475","pt":1631372678490,"mc":[{"id":"1.187528277","rc":[{"batl":[[0,3.4,288.29]],"ltp":3.35,"tv":15253.51,"id":19924831}]}]}
{"op":"mcm","clk":"4216922749","pt":1631372679583,"mc":[{"id":"1.187528277","rc":[{"trd":[[3.4,1156.22]],"batb":[[0,3.4,23.71],[1,3.35,53.73],[2,3.3,186.64]],"batl":[[0,3.45,338.16],[1,3.5,25],[2,9.8,6.16]],"ltp":3.4,"tv":15788.1,"id":19924831}],"tv":61220.26}]}
{"op":"mcm","clk":"4216923107","pt":1631372680985,"mc":[{"id":"1.187528277","rc":[{"batl":[[0,3.45,552.35]],"ltp":3.4,"tv":15788.1,"id":19924831}]}]}
{"op":"mcm","clk":"4216923354","pt":1631372681990,"mc":[{"id":"1.187528277","rc":[{"batb":[[0,3.35,53.73],[1,3.3,186.64],[2,3.25,230.2]],"ltp":3.4,"tv":15788.1,"id":19924831}]}]}
{"op":"mcm","clk":"4216925086","pt":1631372688696,"mc":[{"id":"1.187528277","rc":[{"batb":[[0,1.41,3760.89]],"ltp":1.42,"tv":45432.15,"id":2249229}]}]}
{"op":"mcm","clk":"4216932768","pt":1631372719247,"mc":[{"id":"1.187528277","rc":[{"batl":[[2,1.44,913.54]],"ltp":1.42,"tv":45432.15,"id":2249229}]}]}
{"op":"mcm","clk":"4216947021","pt":1631372776556,"mc":[{"id":"1.187528277","rc":[{"batb":[[0,3.4,287.04],[1,3.35,53.73],[2,3.3,186.64]],"ltp":3.4,"tv":15788.1,"id":19924831}]}]}
{"op":"mcm","clk":"4216947753","pt":1631372779584,"mc":[{"id":"1.187528277","rc":[{"batb":[[0,1.41,3819.7]],"batl":[[1,1.43,21.71]],"ltp":1.42,"tv":45432.15,"id":2249229}]}]}
{"op":"mcm","clk":"4216947928","pt":1631372780372,"mc":[{"id":"1.187528277","rc":[{"batl":[[0,3.45,651.57],[1,3.5,412.08]],"ltp":3.4,"tv":15788.1,"id":19924831}]}]}
{"op":"mcm","clk":"4216958406","pt":1631372822104,"mc":[{"id":"1.187528277","rc":[{"batb":[[1,3.35,79.26],[2,3.3,161.11]],"ltp":3.4,"tv":15788.1,"id":19924831}]}]}
{"op":"mcm","clk":"4216959627","pt":1631372826880,"mc":[{"id":"1.187528277","rc":[{"batb":[[1,3.35,78.72]],"ltp":3.4,"tv":15788.1,"id":19924831}]}]}
{"op":"mcm","clk":"4216965030","pt":1631372848667,"mc":[{"id":"1.187528277","rc":[{"batb":[[2,3.3,147.83]],"ltp":3.4,"tv":15788.1,"id":19924831}]}]}
{"op":"mcm","clk":"4216965323","pt":1631372849653,"mc":[{"id":"1.187528277","rc":[{"batb":[[2,3.3,144.98]],"ltp":3.4,"tv":15788.1,"id":19924831}]}]}
{"op":"mcm","clk":"4216965546","pt":1631372850552,"mc":[{"id":"1.187528277","rc":[{"batb":[[2,3.3,133.54]],"ltp":3.4,"tv":15788.1,"id":19924831}]}]}
{"op":"mcm","clk":"4216966267","pt":1631372853501,"mc":[{"id":"1.187528277","rc":[{"batb":[[0,1.41,3828.52]],"batl":[[1,1.43,30.92]],"ltp":1.42,"tv":45432.15,"id":2249229}]}]}
{"op":"mcm","clk":"4216966437","pt":1631372854165,"mc":[{"id":"1.187528277","rc":[{"batl":[[0,3.45,670.06],[1,3.5,470.14]],"ltp":3.4,"tv":15788.1,"id":19924831}]}]}
{"op":"mcm","clk":"4216992739","pt":1631372951193,"mc":[{"id":"1.187528277","rc":[{"batl":[[0,3.45,673.37],[1,3.5,477.03]],"ltp":3.4,"tv":15788.1,"id":19924831}]}]}
{"op":"mcm","clk":"4217025668","pt":1631373073916,"mc":[{"id":"1.187528277","rc":[{"batb":[[0,1.41,3683.91]],"ltp":1.42,"tv":45432.15,"id":2249229}]}]}
{"op":"mcm","clk":"4217047965","pt":1631373158125,"mc":[{"id":"1.187528277","rc":[{"batb":[[0,1.41,3675.1]],"ltp":1.42,"tv":45432.15,"id":2249229}]}]}
{"op":"mcm","clk":"4217048327","pt":1631373159419,"mc":[{"id":"1.187528277","rc":[{"batl":[[0,3.45,665]],"ltp":3.4,"tv":15788.1,"id":19924831}]}]}
{"op":"mcm","clk":"4217074939","pt":1631373253970,"mc":[{"id":"1.187528277","rc":[{"batb":[[0,1.41,4823.54]],"ltp":1.42,"tv":45432.15,"id":2249229}]}]}
{"op":"mcm","clk":"4217077928","pt":1631373263699,"mc":[{"id":"1.187528277","rc":[{"batb":[[0,1.41,4982.94]],"ltp":1.42,"tv":45432.15,"id":2249229}]}]}
{"op":"mcm","clk":"4217078053","pt":1631373264088,"mc":[{"id":"1.187528277","rc":[{"batl":[[0,3.45,733.61]],"ltp":3.4,"tv":15788.1,"id":19924831}]}]}
{"op":"mcm","clk":"4217098415","pt":1631373338691,"mc":[{"id":"1.187528277","rc":[{"batl":[[0,3.45,753.68]],"ltp":3.4,"tv":15788.1,"id":19924831},{"batb":[[0,1.41,5006.85]],"ltp":1.42,"tv":45432.15,"id":2249229}]}]}
{"op":"mcm","clk":"4217121386","pt":1631373425628,"mc":[{"id":"1.187528277","rc":[{"batl":[[0,3.45,758.15]],"ltp":3.4,"tv":15788.1,"id":19924831},{"batb":[[0,1.41,5010.44]],"ltp":1.42,"tv":45432.15,"id":2249229}]}]}
{"op":"mcm","clk":"4217128627","pt":1631373453471,"mc":[{"id":"1.187528277","rc":[{"batb":[[1,1.4,5665.82]],"ltp":1.42,"tv":45432.15,"id":2249229}]}]}
{"op":"mcm","clk":"4217153457","pt":1631373548677,"mc":[{"id":"1.187528277","rc":[{"batl":[[1,1.43,730.92]],"ltp":1.42,"tv":45432.15,"id":2249229}]}]}
{"op":"mcm","clk":"4217163624","pt":1631373587545,"mc":[{"id":"1.187528277","rc":[{"batl":[[1,3.5,470.14]],"ltp":3.4,"tv":15788.1,"id":19924831},{"batl":[[1,1.43,837.3]],"ltp":1.42,"tv":45432.15,"id":2249229}]}]}
{"op":"mcm","clk":"4217163770","pt":1631373588045,"mc":[{"id":"1.187528277","rc":[{"batl":[[1,3.5,436.5]],"ltp":3.4,"tv":15788.1,"id":19924831}]}]}
{"op":"mcm","clk":"4217169561","pt":1631373610296,"mc":[{"id":"1.187528277","rc":[{"trd":[[3.4,1162.22]],"batb":[[0,3.4,284.04]],"ltp":3.4,"tv":15794.1,"id":19924831}],"tv":61226.26}]}
{"op":"mcm","clk":"4217182849","pt":1631373660675,"mc":[{"id":"1.187528277","rc":[{"trd":[[1.42,17507.92]],"batl":[[0,1.42,13036.24]],"ltp":1.42,"tv":45517.55,"id":2249229}],"tv":61311.66}]}
{"op":"mcm","clk":"4217185654","pt":1631373671665,"mc":[{"id":"1.187528277","rc":[{"batl":[[1,1.43,853.26]],"ltp":1.42,"tv":45517.55,"id":2249229}]}]}
{"op":"mcm","clk":"4217185765","pt":1631373672099,"mc":[{"id":"1.187528277","rc":[{"batl":[[1,3.5,430.42]],"ltp":3.4,"tv":15794.1,"id":19924831}]}]}
{"op":"mcm","clk":"4217200629","pt":1631373733249,"mc":[{"id":"1.187528277","rc":[{"trd":[[3.4,1333.03]],"batb":[[0,3.4,198.63]],"ltp":3.4,"tv":15964.91,"id":19924831}],"tv":61482.47}]}
{"op":"mcm","clk":"4217233866","pt":1631373872666,"mc":[{"id":"1.187528277","rc":[{"trd":[[1.41,1134.95]],"batb":[[0,1.41,4910.44]],"ltp":1.41,"tv":45717.55,"id":2249229}],"tv":61682.47}]}
{"op":"mcm","clk":"4217240076","pt":1631373898051,"mc":[{"id":"1.187528277","rc":[{"batl":[[2,1.44,381.74]],"ltp":1.41,"tv":45717.55,"id":2249229}]}]}
{"op":"mcm","clk":"4217259641","pt":1631373978258,"mc":[{"id":"1.187528277","rc":[{"batb":[[0,1.41,4906.85]],"ltp":1.41,"tv":45717.55,"id":2249229}]}]}
{"op":"mcm","clk":"4217259780","pt":1631373979004,"mc":[{"id":"1.187528277","rc":[{"batl":[[0,3.45,753.68]],"ltp":3.4,"tv":15964.91,"id":19924831},{"trd":[[1.41,1410.5]],"batb":[[0,1.41,4769.08]],"ltp":1.41,"tv":45993.1,"id":2249229}],"tv":61958.01}]}
{"op":"mcm","clk":"4217260415","pt":1631373981547,"mc":[{"id":"1.187528277","rc":[{"trd":[[1.42,17670.19]],"batl":[[0,1.42,12955.11]],"ltp":1.42,"tv":46155.36,"id":2249229}],"tv":62120.28}]}
{"op":"mcm","clk":"4217279033","pt":1631374059481,"mc":[{"id":"1.187528277","rc":[{"batb":[[0,1.41,4745.17]],"ltp":1.42,"tv":46155.36,"id":2249229}]}]}
{"op":"mcm","clk":"4217279174","pt":1631374060183,"mc":[{"id":"1.187528277","rc":[{"batl":[[0,3.45,743.57]],"ltp":3.4,"tv":15964.91,"id":19924831}]}]}
{"op":"mcm","clk":"4217281598","pt":1631374070804,"mc":[{"id":"1.187528277","rc":[{"trd":[[3.4,1333.65]],"batb":[[0,3.4,198.32]],"ltp":3.4,"tv":15965.53,"id":19924831}],"tv":62120.9}]}
{"op":"mcm","clk":"4217309304","pt":1631374190351,"mc":[{"id":"1.187528277","rc":[{"batb":[[0,1.41,4733.41]],"ltp":1.42,"tv":46155.36,"id":2249229}]}]}
{"op":"mcm","clk":"4217359863","pt":1631374419055,"mc":[{"id":"1.187528277","rc":[{"trd":[[1.42,17687.27]],"batl":[[0,1.42,12946.57]],"ltp":1.42,"tv":46172.44,"id":2249229}],"tv":62137.98}]}
{"op":"mcm","clk":"4217365028","pt":1631374445678,"mc":[{"id":"1.187528277","rc":[{"batb":[[0,1.41,4734.15]],"ltp":1.42,"tv":46172.44,"id":2249229}]}]}
{"op":"mcm","clk":"4217432611","pt":1631374746168,"mc":[{"id":"1.187528277","rc":[{"batb":[[0,1.41,4734.67]],"ltp":1.42,"tv":46172.44,"id":2249229}]}]}
{"op":"mcm","clk":"4217437195","pt":1631374765382,"mc":[{"id":"1.187528277","rc":[{"trd":[[1.42,18037.43]],"batl":[[0,1.42,12771.49]],"ltp":1.42,"tv":46522.6,"id":2249229}],"tv":62488.14}]}
{"op":"mcm","clk":"4217525958","pt":1631375169259,"mc":[{"id":"1.187528277","rc":[{"trd":[[1.42,18045.97]],"batl":[[0,1.42,12767.22]],"ltp":1.42,"tv":46531.14,"id":2249229}],"tv":62496.68}]}
{"op":"mcm","clk":"4217536759","pt":1631375223007,"mc":[{"id":"1.187528277","rc":[{"trd":[[1.42,18063.05]],"batl":[[0,1.42,12758.68]],"ltp":1.42,"tv":46548.22,"id":2249229}],"tv":62513.76}]}
{"op":"mcm","clk":"4217541416","pt":1631375245512,"mc":[{"id":"1.187528277","rc":[{"trd":[[1.41,1642.49]],"batb":[[0,1.41,4618.67]],"ltp":1.41,"tv":46780.22,"id":2249229}],"tv":62745.75}]}
{"op":"mcm","clk":"4217543291","pt":1631375254515,"mc":[{"id":"1.187528277","rc":[{"batb":[[0,1.41,4599.7]],"ltp":1.41,"tv":46780.22,"id":2249229}]}]}
{"op":"mcm","clk":"4217543444","pt":1631375255105,"mc":[{"id":"1.187528277","rc":[{"batl":[[0,3.45,733.61]],"ltp":3.4,"tv":15965.53,"id":19924831}]}]}
{"op":"mcm","clk":"4217586589","pt":1631375402240,"mc":[{"id":"1.187528277","rc":[{"trd":[[3.4,1353.65]],"batb":[[0,3.4,188.32]],"ltp":3.4,"tv":15985.53,"id":19924831}],"tv":62765.75}]}
{"op":"mcm","clk":"4217593592","pt":1631375438788,"mc":[{"id":"1.187528277","rc":[{"trd":[[3.4,1453.66]],"batb":[[0,3.4,138.32]],"ltp":3.4,"tv":16085.53,"id":19924831}],"tv":62865.76}]}
{"op":"mcm","clk":"4217603627","pt":1631375496572,"mc":[{"id":"1.187528277","rc":[{"trd":[[1.41,2496.54]],"batb":[[0,1.41,4172.68]],"ltp":1.41,"tv":47634.26,"id":2249229}],"tv":63719.8}]}
{"op":"mcm","clk":"4217603813","pt":1631375497482,"mc":[{"id":"1.187528277","rc":[{"trd":[[1.41,3350.58]],"batb":[[0,1.41,3745.65]],"ltp":1.41,"tv":48488.31,"id":2249229}],"tv":64573.85}]}
{"op":"mcm","clk":"4217605184","pt":1631375505689,"mc":[{"id":"1.187528277","rc":[{"batl":[[0,3.45,677.83]],"ltp":3.4,"tv":16085.53,"id":19924831},{"batb":[[0,1.41,3616.99]],"ltp":1.41,"tv":48488.31,"id":2249229}]}]}
{"op":"mcm","clk":"4217608258","pt":1631375523928,"mc":[{"id":"1.187528277","rc":[{"trd":[[3.45,79.22]],"batl":[[0,3.45,647.19]],"ltp":3.45,"tv":16146.82,"id":19924831}],"tv":64635.13}]}
{"op":"mcm","clk":"4217621292","pt":1631375598540,"mc":[{"id":"1.187528277","rc":[{"batb":[[0,1.41,3595.4]],"ltp":1.41,"tv":48488.31,"id":2249229}]}]}
{"op":"mcm","clk":"4217621473","pt":1631375599527,"mc":[{"id":"1.187528277","rc":[{"batl":[[0,3.45,626.33]],"ltp":3.45,"tv":16146.82,"id":19924831}]}]}
{"op":"mcm","clk":"4217624171","pt":1631375616831,"mc":[{"id":"1.187528277","rc":[{"trd":[[1.42,18077.69]],"batl":[[0,1.42,12751.36]],"ltp":1.42,"tv":48502.95,"id":2249229}],"tv":64649.77}]}
{"op":"mcm","clk":"4217658828","pt":1631375831096,"mc":[{"id":"1.187528277","rc":[{"batl":[[0,1.42,12633.71]],"ltp":1.42,"tv":48502.95,"id":2249229}]}]}
{"op":"mcm","clk":"4217663097","pt":1631375855647,"mc":[{"id":"1.187528277","rc":[{"batb":[[2,3.3,54.54]],"ltp":3.45,"tv":16146.82,"id":19924831}]}]}
{"op":"mcm","clk":"4217670488","pt":1631375899423,"mc":[{"id":"1.187528277","rc":[{"trd":[[1.41,3376.58]],"batb":[[0,1.41,3582.41]],"ltp":1.41,"tv":48528.95,"id":2249229}],"tv":64675.77}]}
{"op":"mcm","clk":"4217677118","pt":1631375944887,"mc":[{"id":"1.187528277","rc":[{"trd":[[3.4,1473.65]],"batb":[[0,3.4,128.32]],"ltp":3.4,"tv":16166.82,"id":19924831}],"tv":64695.77}]}
{"op":"mcm","clk":"4217678828","pt":1631375955525,"mc":[{"id":"1.187528277","rc":[{"batb":[[2,3.3,74.54]],"ltp":3.4,"tv":16166.82,"id":19924831}]}]}
{"op":"mcm","clk":"4217680095","pt":1631375963914,"mc":[{"id":"1.187528277","rc":[{"batl":[[0,3.45,620.93]],"ltp":3.4,"tv":16166.82,"id":19924831}]}]}
{"op":"mcm","clk":"4217725688","pt":1631376233054,"mc":[{"id":"1.187528277","rc":[{"trd":[[1.42,18081.11]],"batl":[[0,1.42,12632]],"ltp":1.42,"tv":48532.36,"id":2249229}],"tv":64699.19}]}
{"op":"mcm","clk":"4217730960","pt":1631376266722,"mc":[{"id":"1.187528277","rc":[{"batb":[[0,1.41,3795.92]],"ltp":1.42,"tv":48532.36,"id":2249229}]}]}
{"op":"mcm","clk":"4217732594","pt":1631376276751,"mc":[{"id":"1.187528277","rc":[{"batl":[[2,1.44,509.85]],"ltp":1.42,"tv":48532.36,"id":2249229}]}]}
{"op":"mcm","clk":"4217745974","pt":1631376361512,"mc":[{"id":"1.187528277","rc":[{"batb":[[0,1.41,3822.76]],"ltp":1.42,"tv":48532.36,"id":2249229}]}]}
{"op":"mcm","clk":"4217746035","pt":1631376361893,"mc":[{"id":"1.187528277","rc":[{"batl":[[0,3.45,633.36]],"ltp":3.4,"tv":16166.82,"id":19924831}]}]}
{"op":"mcm","clk":"4217762765","pt":1631376469388,"mc":[{"id":"1.187528277","rc":[{"batb":[[1,3.35,505.75]],"ltp":3.4,"tv":16166.82,"id":19924831},{"batl":[[0,1.42,12758.76]],"ltp":1.42,"tv":48532.36,"id":2249229}]}]}
{"op":"mcm","clk":"4217765752","pt":1631376488640,"mc":[{"id":"1.187528277","rc":[{"batb":[[0,1.41,3826.78]],"ltp":1.42,"tv":48532.36,"id":2249229}]}]}
{"op":"mcm","clk":"4217765851","pt":1631376489326,"mc":[{"id":"1.187528277","rc":[{"batl":[[0,3.45,636.87]],"ltp":3.4,"tv":16166.82,"id":19924831},{"batl":[[1,1.43,981.73]],"ltp":1.42,"tv":48532.36,"id":2249229}]}]}
{"op":"mcm","clk":"4217773862","pt":1631376538887,"mc":[{"id":"1.187528277","rc":[{"trd":[[3.4,1478.93]],"batb":[[0,3.4,125.68]],"ltp":3.4,"tv":16172.09,"id":19924831}],"tv":64704.46}]}
{"op":"mcm","clk":"4217780362","pt":1631376580085,"mc":[{"id":"1.187528277","rc":[{"trd":[[1.42,18115.97]],"batl":[[0,1.42,12741.33]],"ltp":1.42,"tv":48567.22,"id":2249229}],"tv":64739.32}]}
{"op":"mcm","clk":"4217797789","pt":1631376696709,"mc":[{"id":"1.187528277","rc":[{"trd":[[1.41,3499.71]],"batb":[[0,1.41,3765.21]],"ltp":1.41,"tv":48690.36,"id":2249229}],"tv":64862.46}]}
{"op":"mcm","clk":"4217849470","pt":1631381838648,"mc":[{"id":"1.187528277","rc":[{"batl":[[0,3.45,593.32]],"ltp":3.4,"tv":16172.09,"id":19924831}]}]}
{"op":"mcm","clk":"4217849487","pt":1631381839366,"mc":[{"id":"1.187528277","rc":[{"trd":[[3.4,1548.96]],"batb":[[0,3.4,90.67]],"ltp":3.4,"tv":16242.13,"id":19924831},{"batb":[[0,1.41,3800.23]],"ltp":1.41,"tv":48690.36,"id":2249229}],"tv":64932.49}]}
{"op":"mcm","clk":"4217849839","pt":1631381853766,"mc":[{"id":"1.187528277","rc":[{"batb":[[1,3.35,507.45]],"ltp":3.4,"tv":16242.13,"id":19924831}]}]}
{"op":"mcm","clk":"4217849877","pt":1631381855668,"mc":[{"id":"1.187528277","rc":[{"batb":[[1,3.35,505.75]],"ltp":3.4,"tv":16242.13,"id":19924831}]}]}
{"op":"mcm","clk":"4217850357","pt":1631381878103,"mc":[{"id":"1.187528277","rc":[{"trd":[[1.41,3509.71]],"batb":[[0,1.41,3795.23]],"ltp":1.41,"tv":48700.35,"id":2249229}],"tv":64942.48}]}
{"op":"mcm","clk":"4217850586","pt":1631381886992,"mc":[{"id":"1.187528277","rc":[{"trd":[[3.4,1576.52]],"batb":[[0,3.4,129.83],[2,3.3,20]],"ltp":3.4,"tv":16269.68,"id":19924831},{"batl":[[2,1.44,384.85]],"ltp":1.41,"tv":48700.35,"id":2249229}],"tv":64970.04}]}
{"op":"mcm","clk":"4217850702","pt":1631381892131,"mc":[{"id":"1.187528277","rc":[{"batl":[[0,1.42,12746.33]],"ltp":1.41,"tv":48700.35,"id":2249229}]}]}
{"op":"mcm","clk":"4217851241","pt":1631381905433,"mc":[{"id":"1.187528277","rc":[{"batl":[[0,3.45,589.81]],"ltp":3.4,"tv":16269.68,"id":19924831}]}]}
{"op":"mcm","clk":"4217856190","pt":1631381930691,"mc":[{"id":"1.187528277","rc":[{"trd":[[3.45,109.26]],"batl":[[0,3.45,574.79]],"ltp":3.45,"tv":16299.73,"id":19924831}],"tv":65000.08}]}
{"op":"mcm","clk":"4217858194","pt":1631381949701,"mc":[{"id":"1.187528277","rc":[{"batb":[[0,1.41,3751.68]],"ltp":1.41,"tv":48700.35,"id":2249229}]}]}
{"op":"mcm","clk":"4217858206","pt":1631381949804,"mc":[{"id":"1.187528277","rc":[{"batb":[[2,3.3,47.33]],"batl":[[0,3.45,608.95]],"ltp":3.45,"tv":16299.73,"id":19924831},{"batl":[[2,1.44,470.25]],"ltp":1.41,"tv":48700.35,"id":2249229}]}]}
{"op":"mcm","clk":"4217878843","pt":1631382214642,"mc":[{"id":"1.187528277","rc":[{"trd":[[1.41,3513.71]],"batb":[[0,1.41,3749.68]],"ltp":1.41,"tv":48704.35,"id":2249229}],"tv":65004.08}]}
{"op":"mcm","clk":"4217889122","pt":1631382324724,"mc":[{"id":"1.187528277","rc":[{"trd":[[1.41,4129.36]],"batb":[[0,1.41,3441.86]],"ltp":1.41,"tv":49320.0,"id":2249229}],"tv":65619.73}]}
{"op":"mcm","clk":"4217894533","pt":1631382379707,"mc":[{"id":"1.187528277","rc":[{"batb":[[0,1.41,3410.99]],"ltp":1.41,"tv":49320.0,"id":2249229}]}]}
{"op":"mcm","clk":"4217894627","pt":1631382380715,"mc":[{"id":"1.187528277","rc":[{"batl":[[0,3.45,596.52]],"ltp":3.45,"tv":16299.73,"id":19924831},{"batb":[[0,1.41,3384.72]],"ltp":1.41,"tv":49320.0,"id":2249229}]}]}
{"op":"mcm","clk":"4217894669","pt":1631382381234,"mc":[{"id":"1.187528277","rc":[{"batl":[[0,3.45,585.45]],"ltp":3.45,"tv":16299.73,"id":19924831}]}]}
{"op":"mcm","clk":"4217895958","pt":1631382394775,"mc":[{"id":"1.187528277","rc":[{"batb":[[0,1.41,3884.72]],"ltp":1.41,"tv":49320.0,"id":2249229}]}]}
{"op":"mcm","clk":"4217908036","pt":1631382512041,"mc":[{"id":"1.187528277","rc":[{"batl":[[0,3.45,609.07]],"ltp":3.45,"tv":16299.73,"id":19924831},{"batb":[[0,1.41,3951.15]],"ltp":1.41,"tv":49320.0,"id":2249229}]}]}
{"op":"mcm","clk":"4217908288","pt":1631382513725,"mc":[{"id":"1.187528277","rc":[{"trd":[[1.42,18189.35]],"batl":[[0,1.42,12709.64]],"ltp":1.42,"tv":49393.38,"id":2249229}],"tv":65693.11}]}
{"op":"mcm","clk":"4217915608","pt":1631382580820,"mc":[{"id":"1.187528277","rc":[{"batb":[[0,1.41,4201.15]],"ltp":1.42,"tv":49393.38,"id":2249229}]}]}
{"op":"mcm","clk":"4217923152","pt":1631382653223,"mc":[{"id":"1.187528277","rc":[{"batl":[[0,3.45,632.01]],"ltp":3.45,"tv":16299.73,"id":19924831},{"batb":[[0,1.41,4248.62]],"ltp":1.42,"tv":49393.38,"id":2249229}]}]}
{"op":"mcm","clk":"4217923973","pt":1631382660323,"mc":[{"id":"1.187528277","rc":[{"batb":[[2,3.3,20]],"batl":[[0,3.45,641.41]],"ltp":3.45,"tv":16299.73,"id":19924831},{"batb":[[0,1.41,4256.3]],"ltp":1.42,"tv":49393.38,"id":2249229}]}]}
{"op":"mcm","clk":"4217935878","pt":1631382785374,"mc":[{"id":"1.187528277","rc":[{"batb":[[0,1.41,4264.57]],"ltp":1.42,"tv":49393.38,"id":2249229}]}]}
{"op":"mcm","clk":"4217935922","pt":1631382785754,"mc":[{"id":"1.187528277","rc":[{"batl":[[0,3.45,649.64]],"ltp":3.45,"tv":16299.73,"id":19924831}]}]}
{"op":"mcm","clk":"4217951496","pt":1631382974277,"mc":[{"id":"1.187528277","rc":[{"batl":[[1,1.43,1081.73]],"ltp":1.42,"tv":49393.38,"id":2249229}]}]}
{"op":"mcm","clk":"4217951775","pt":1631382978069,"mc":[{"id":"1.187528277","rc":[{"batl":[[2,1.44,570.25]],"ltp":1.42,"tv":49393.38,"id":2249229}]}]}
{"op":"mcm","clk":"4217952451","pt":1631382987004,"mc":[{"id":"1.187528277","rc":[{"batl":[[0,1.42,12809.64]],"ltp":1.42,"tv":49393.38,"id":2249229}]}]}
{"op":"mcm","clk":"4217953664","pt":1631383005108,"mc":[{"id":"1.187528277","rc":[{"trd":[[1.41,4163.8]],"batb":[[0,1.41,4247.35]],"ltp":1.41,"tv":49427.82,"id":2249229}],"tv":65727.55}]}
{"op":"mcm","clk":"4217954256","pt":1631383013623,"mc":[{"id":"1.187528277","rc":[{"trd":[[3.4,1672.52]],"batb":[[0,3.4,81.82]],"ltp":3.4,"tv":16395.73,"id":19924831}],"tv":65823.55}]}
{"op":"mcm","clk":"4217966714","pt":1631383145594,"mc":[{"id":"1.187528277","rc":[{"trd":[[1.41,4169.31]],"batb":[[0,1.41,4244.59]],"ltp":1.41,"tv":49433.33,"id":2249229}],"tv":65829.06}]}
{"op":"mcm","clk":"4217981120","pt":1631383294955,"mc":[{"id":"1.187528277","rc":[{"trd":[[1.41,5108.61]],"batb":[[0,1.41,3774.95]],"ltp":1.41,"tv":50372.63,"id":2249229}],"tv":66768.36}]}
{"op":"mcm","clk":"4217984833","pt":1631383328728,"mc":[{"id":"1.187528277","rc":[{"trd":[[1.42,18264.55]],"batl":[[0,1.42,12772.04]],"ltp":1.42,"tv":50447.83,"id":2249229}],"tv":66843.56}]}
{"op":"mcm","clk":"4217991328","pt":1631383390476,"mc":[{"id":"1.187528277","rc":[{"batb":[[0,1.41,3766.68]],"ltp":1.42,"tv":50447.83,"id":2249229}]}]}
{"op":"mcm","clk":"4217991433","pt":1631383391491,"mc":[{"id":"1.187528277","rc":[{"batb":[[0,1.41,3702.74]],"ltp":1.42,"tv":50447.83,"id":2249229}]}]}
{"op":"mcm","clk":"4217991565","pt":1631383392604,"mc":[{"id":"1.187528277","rc":[{"batl":[[0,3.45,621.37]],"ltp":3.4,"tv":16395.73,"id":19924831}]}]}
{"op":"mcm","clk":"4218007523","pt":1631383523342,"mc":[{"id":"1.187528277","rc":[{"batl":[[0,3.45,618.47]],"ltp":3.4,"tv":16395.73,"id":19924831},{"trd":[[1.41,8816.89]],"batb":[[0,1.41,1848.59]],"ltp":1.41,"tv":54156.12,"id":2249229}],"tv":70551.85}]}
{"op":"mcm","clk":"4218007590","pt":1631383523817,"mc":[{"id":"1.187528277","rc":[{"batl":[[0,3.45,612.7]],"ltp":3.4,"tv":16395.73,"id":19924831}]}]}
{"op":"mcm","clk":"4218010686","pt":1631383548472,"mc":[{"id":"1.187528277","rc":[{"batb":[[0,3.4,131.41]],"ltp":3.4,"tv":16395.73,"id":19924831},{"batb":[[0,1.41,1968.15]],"ltp":1.41,"tv":54156.12,"id":2249229}]}]}
{"op":"mcm","clk":"4218020431","pt":1631383619544,"mc":[{"id":"1.187528277","rc":[{"batb":[[0,1.41,1925.45]],"ltp":1.41,"tv":54156.12,"id":2249229}]}]}
{"op":"mcm","clk":"4218020572","pt":1631383620670,"mc":[{"id":"1.187528277","rc":[{"batb":[[2,3.3,54.16]],"batl":[[0,3.45,602.45]],"ltp":3.4,"tv":16395.73,"id":19924831},{"batb":[[1,1.4,5802.47]],"ltp":1.41,"tv":54156.12,"id":2249229}]}]}
{"op":"mcm","clk":"4218025562","pt":1631383661546,"mc":[{"id":"1.187528277","rc":[{"batb":[[1,3.35,587.48]],"ltp":3.4,"tv":16395.73,"id":19924831},{"batb":[[0,1.41,2164.3]],"batl":[[1,1.43,1139.98]],"ltp":1.41,"tv":54156.12,"id":2249229}]}]}
{"op":"mcm","clk":"4218025670","pt":1631383662440,"mc":[{"id":"1.187528277","rc":[{"batl":[[0,3.45,496.44]],"ltp":3.4,"tv":16395.73,"id":19924831}]}]}
{"op":"mcm","clk":"4218025765","pt":1631383663339,"mc":[{"id":"1.187528277","rc":[{"batl":[[0,3.45,490.66],[1,3.5,437.71]],"ltp":3.4,"tv":16395.73,"id":19924831}]}]}
{"op":"mcm","clk":"4218026437","pt":1631383668939,"mc":[{"id":"1.187528277","rc":[{"batb":[[0,1.41,4018.43]],"ltp":1.41,"tv":54156.12,"id":2249229}]}]}
{"op":"mcm","clk":"4218039106","pt":1631383775721,"mc":[{"id":"1.187528277","rc":[{"batb":[[0,1.41,4332.38]],"ltp":1.41,"tv":54156.12,"id":2249229}]}]}
{"op":"mcm","clk":"4218039183","pt":1631383776413,"mc":[{"id":"1.187528277","rc":[{"batl":[[0,3.45,602.2]],"ltp":3.4,"tv":16395.73,"id":19924831},{"batl":[[1,1.43,1177.44]],"ltp":1.41,"tv":54156.12,"id":2249229}]}]}
{"op":"mcm","clk":"4218044600","pt":1631383824119,"mc":[{"id":"1.187528277","rc":[{"trd":[[1.42,18364.55]],"batl":[[0,1.42,12722.04]],"ltp":1.42,"tv":54256.12,"id":2249229}],"tv":70651.85}]}
{"op":"mcm","clk":"4218054332","pt":1631383897594,"mc":[{"id":"1.187528277","rc":[{"batl":[[1,1.43,1183.06]],"ltp":1.42,"tv":54256.12,"id":2249229}]}]}
{"op":"mcm","clk":"4218054383","pt":1631383898020,"mc":[{"id":"1.187528277","rc":[{"batl":[[0,3.45,626.54]],"ltp":3.4,"tv":16395.73,"id":19924831}]}]}
{"op":"mcm","clk":"4218056123","pt":1631383912813,"mc":[{"id":"1.187528277","rc":[{"trd":[[1.42,18374.55]],"batl":[[0,1.42,12717.04]],"ltp":1.42,"tv":54266.12,"id":2249229}],"tv":70661.85}]}
{"op":"mcm","clk":"4218078926","pt":1631384095241,"mc":[{"id":"1.187528277","rc":[{"trd":[[3.4,1676.3]],"batb":[[0,3.4,129.52]],"ltp":3.4,"tv":16399.5,"id":19924831}],"tv":70665.63}]}
{"op":"mcm","clk":"4218082892","pt":1631384126611,"mc":[{"id":"1.187528277","rc":[{"trd":[[1.42,18574.55]],"batl":[[0,1.42,12617.04]],"ltp":1.42,"tv":54466.12,"id":2249229}],"tv":70865.63}]}
{"op":"mcm","clk":"4218109545","pt":1631384330689,"mc":[{"id":"1.187528277","rc":[{"trd":[[3.45,110.14]],"batl":[[0,3.45,626.1]],"ltp":3.45,"tv":16400.38,"id":19924831}],"tv":70866.5}]}
{"op":"mcm","clk":"4218110165","pt":1631384335289,"mc":[{"id":"1.187528277","rc":[{"trd":[[3.4,1693.22]],"batb":[[0,3.4,121.06]],"ltp":3.4,"tv":16417.29,"id":19924831}],"tv":70883.42}]}
{"op":"mcm","clk":"4218145373","pt":1631384564968,"mc":[{"id":"1.187528277","rc":[{"trd":[[1.41,9016.89]],"batb":[[0,1.41,4232.38]],"ltp":1.41,"tv":54666.12,"id":2249229}],"tv":71083.42}]}
{"op":"mcm","clk":"4218177599","pt":1631384792728,"mc":[{"id":"1.187528277","rc":[{"trd":[[1.41,9018.51]],"batb":[[0,1.41,4231.58]],"ltp":1.41,"tv":54667.74,"id":2249229}],"tv":71085.03}]}
{"op":"mcm","clk":"4218197210","pt":1631384943403,"mc":[{"id":"1.187528277","rc":[{"trd":[[3.4,1778.8]],"batb":[[0,3.4,78.28]],"ltp":3.4,"tv":16502.88,"id":19924831}],"tv":71170.62}]}
{"op":"mcm","clk":"4218201836","pt":1631384981461,"mc":[{"id":"1.187528277","rc":[{"trd":[[3.4,1842.19]],"batb":[[0,3.4,99.52]],"ltp":3.4,"tv":16566.27,"id":19924831},{"batl":[[0,1.42,12490.28]],"ltp":1.41,"tv":54667.74,"id":2249229}],"tv":71234.01}]}
{"op":"mcm","clk":"4218210711","pt":1631385051434,"mc":[{"id":"1.187528277","rc":[{"trd":[[1.42,18603.71]],"batl":[[0,1.42,12475.7]],"ltp":1.42,"tv":54696.9,"id":2249229}],"tv":71263.17}]}
{"op":"mcm","clk":"4218227659","pt":1631385185980,"mc":[{"id":"1.187528277","rc":[{"batb":[[0,1.41,4232.34]],"ltp":1.42,"tv":54696.9,"id":2249229}]}]}
{"op":"mcm","clk":"4218239996","pt":1631385273825,"mc":[{"id":"1.187528277","rc":[{"trd":[[1.41,12784.85]],"batb":[[0,1.41,2349.17]],"ltp":1.41,"tv":58463.23,"id":2249229}],"tv":75029.5}]}
{"op":"mcm","clk":"4218252880","pt":1631385373426,"mc":[{"id":"1.187528277","rc":[{"batb":[[0,1.41,2207.27]],"ltp":1.41,"tv":58463.23,"id":2249229}]}]}
{"op":"mcm","clk":"4218253041","pt":1631385374598,"mc":[{"id":"1.187528277","rc":[{"batb":[[1,3.35,610.49]],"batl":[[0,3.45,601.76]],"ltp":3.4,"tv":16566.27,"id":19924831},{"batl":[[0,1.42,12521.76]],"ltp":1.41,"tv":58463.23,"id":2249229}]}]}
{"op":"mcm","clk":"4218253106","pt":1631385375123,"mc":[{"id":"1.187528277","rc":[{"batl":[[0,3.45,519.74]],"ltp":3.4,"tv":16566.27,"id":19924831}]}]}
{"op":"mcm","clk":"4218270394","pt":1631385497504,"mc":[{"id":"1.187528277","rc":[{"batb":[[0,1.41,2185.98]],"batl":[[1,1.43,1191.99]],"ltp":1.41,"tv":58463.23,"id":2249229}]}]}
{"op":"mcm","clk":"4218270445","pt":1631385497929,"mc":[{"id":"1.187528277","rc":[{"batl":[[0,3.45,495.08]],"ltp":3.4,"tv":16566.27,"id":19924831}]}]}
{"op":"mcm","clk":"4218288225","pt":1631385632327,"mc":[{"id":"1.187528277","rc":[{"batl":[[0,3.45,490.22]],"ltp":3.4,"tv":16566.27,"id":19924831}]}]}
{"op":"mcm","clk":"4218288931","pt":1631385637531,"mc":[{"id":"1.187528277","rc":[{"trd":[[3.4,1964.99]],"batb":[[0,3.4,38.12]],"ltp":3.4,"tv":16689.07,"id":19924831}],"tv":75152.3}]}
{"op":"mcm","clk":"4218296649","pt":1631385696071,"mc":[{"id":"1.187528277","rc":[{"trd":[[1.42,18603.73]],"batl":[[0,1.42,12521.75]],"ltp":1.42,"tv":58463.25,"id":2249229}],"tv":75152.32}]}
{"op":"mcm","clk":"4218303853","pt":1631385750194,"mc":[{"id":"1.187528277","rc":[{"batb":[[0,3.4,87.71]],"ltp":3.4,"tv":16689.07,"id":19924831},{"batb":[[0,1.41,2305.54]],"ltp":1.42,"tv":58463.25,"id":2249229}]}]}
{"op":"mcm","clk":"4218305345","pt":1631385760683,"mc":[{"id":"1.187528277","rc":[{"batb":[[0,1.41,2320.29]],"ltp":1.42,"tv":58463.25,"id":2249229}]}]}
{"op":"mcm","clk":"4218305392","pt":1631385760998,"mc":[{"id":"1.187528277","rc":[{"batl":[[0,3.45,496.68]],"ltp":3.4,"tv":16689.07,"id":19924831}]}]}
{"op":"mcm","clk":"4218308134","pt":1631385781941,"mc":[{"id":"1.187528277","rc":[{"batb":[[0,1.41,2452.66]],"ltp":1.42,"tv":58463.25,"id":2249229}]}]}
{"op":"mcm","clk":"4218309905","pt":1631385795960,"mc":[{"id":"1.187528277","rc":[{"trd":[[1.41,12787.6]],"batb":[[0,1.41,2451.29]],"ltp":1.41,"tv":58466.01,"id":2249229}],"tv":75155.08}]}
{"op":"mcm","clk":"4218318408","pt":1631385861079,"mc":[{"id":"1.187528277","rc":[{"trd":[[1.41,15239.61]],"batb":[[0,1.41,1225.28]],"ltp":1.41,"tv":60918.01,"id":2249229}],"tv":77607.09}]}
{"op":"mcm","clk":"4218321864","pt":1631385884588,"mc":[{"id":"1.187528277","rc":[{"batb":[[1,3.35,648.73]],"ltp":3.4,"tv":16689.07,"id":19924831},{"batb":[[0,1.41,1243.57]],"batl":[[0,1.42,12610.49]],"ltp":1.41,"tv":60918.01,"id":2249229}]}]}
{"op":"mcm","clk":"4218322012","pt":1631385885697,"mc":[{"id":"1.187528277","rc":[{"batl":[[0,3.45,431.43]],"ltp":3.4,"tv":16689.07,"id":19924831}]}]}
{"op":"mcm","clk":"4218323624","pt":1631385896893,"mc":[{"id":"1.187528277","rc":[{"trd":[[1.42,19483.23]],"batl":[[0,1.42,12170.74]],"ltp":1.42,"tv":61797.52,"id":2249229}],"tv":78486.59}]}
{"op":"mcm","clk":"4218327094","pt":1631385921832,"mc":[{"id":"1.187528277","rc":[{"trd":[[1.42,19571.19]],"batl":[[0,1.42,12126.76]],"ltp":1.42,"tv":61885.47,"id":2249229}],"tv":78574.54}]}
{"op":"mcm","clk":"4218328936","pt":1631385928737,"mc":[{"id":"1.187528277","rc":[{"trd":[[1.42,19659.14]],"batl":[[0,1.42,12082.78]],"ltp":1.42,"tv":61973.43,"id":2249229}],"tv":78662.5}]}
{"op":"mcm","clk":"4218332005","pt":1631385949679,"mc":[{"id":"1.187528277","rc":[{"trd":[[1.41,17726.73]],"batb":[[0,1.4,5802.47],[1,1.39,6190.77],[2,1.38,6976.68]],"batl":[[0,1.41,1256.44],[1,1.42,12082.78],[2,1.43,1191.99]],"ltp":1.41,"tv":64460.55,"id":2249229}],"tv":81149.63}]}
{"op":"mcm","clk":"4218342257","pt":1631386034572,"mc":[{"id":"1.187528277","rc":[{"batl":[[2,1.43,1130.9]],"ltp":1.41,"tv":64460.55,"id":2249229}]}]}
{"op":"mcm","clk":"4218342355","pt":1631386035301,"mc":[{"id":"1.187528277","rc":[{"batl":[[2,1.43,1002.43]],"ltp":1.41,"tv":64460.55,"id":2249229}]}]}
{"op":"mcm","clk":"4218342482","pt":1631386036300,"mc":[{"id":"1.187528277","rc":[{"batl":[[2,1.43,949.01]],"ltp":1.41,"tv":64460.55,"id":2249229}]}]}
{"op":"mcm","clk":"4218342601","pt":1631386037198,"mc":[{"id":"1.187528277","rc":[{"batl":[[2,1.43,921.2]],"ltp":1.41,"tv":64460.55,"id":2249229}]}]}
{"op":"mcm","clk":"4218342719","pt":1631386038308,"mc":[{"id":"1.187528277","rc":[{"batl":[[2,1.43,805.62]],"ltp":1.41,"tv":64460.55,"id":2249229}]}]}
{"op":"mcm","clk":"4218342792","pt":1631386038791,"mc":[{"id":"1.187528277","rc":[{"batl":[[2,1.43,800]],"ltp":1.41,"tv":64460.55,"id":2249229}]}]}
{"op":"mcm","clk":"4218343138","pt":1631386041504,"mc":[{"id":"1.187528277","rc":[{"batb":[[0,1.4,6334.84],[1,1.39,6642.8]],"batl":[[1,1.42,12169.46]],"ltp":1.41,"tv":64460.55,"id":2249229}]}]}
{"op":"mcm","clk":"4218343226","pt":1631386042190,"mc":[{"id":"1.187528277","rc":[{"batb":[[1,3.35,688.38]],"batl":[[0,3.45,346.53]],"ltp":3.4,"tv":16689.07,"id":19924831}]}]}
{"op":"mcm","clk":"4218345279","pt":1631386057812,"mc":[{"id":"1.187528277","rc":[{"batl":[[0,1.41,3809.09]],"ltp":1.41,"tv":64460.55,"id":2249229}]}]}
{"op":"mcm","clk":"4218346036","pt":1631386064240,"mc":[{"id":"1.187528277","rc":[{"batl":[[0,1.41,6361.74]],"ltp":1.41,"tv":64460.55,"id":2249229}]}]}
{"op":"mcm","clk":"4218366674","pt":1631386140541,"mc":[{"id":"1.187528277","rc":[{"trd":[[1.41,17728.89]],"batl":[[0,1.41,6360.66]],"ltp":1.41,"tv":64462.71,"id":2249229}],"tv":81151.78}]}
{"op":"mcm","clk":"4218368016","pt":1631386152673,"mc":[{"id":"1.187528277","rc":[{"batb":[[0,3.4,116.63]],"ltp":3.4,"tv":16689.07,"id":19924831}]}]}
{"op":"mcm","clk":"4218369204","pt":1631386162383,"mc":[{"id":"1.187528277","rc":[{"batl":[[0,1.41,6386.77]],"ltp":1.41,"tv":64462.71,"id":2249229}]}]}
{"op":"mcm","clk":"4218370281","pt":1631386171381,"mc":[{"id":"1.187528277","rc":[{"batl":[[0,3.45,333.79],[1,3.5,470.75]],"ltp":3.4,"tv":16689.07,"id":19924831}]}]}
{"op":"mcm","clk":"4218386011","pt":1631386303041,"mc":[{"id":"1.187528277","rc":[{"batl":[[1,3.5,475.7]],"ltp":3.4,"tv":16689.07,"id":19924831}]}]}
{"op":"mcm","clk":"4218386211","pt":1631386304925,"mc":[{"id":"1.187528277","rc":[{"batb":[[0,1.4,6145.24]],"ltp":1.41,"tv":64462.71,"id":2249229}]}]}
{"op":"mcm","clk":"4218388754","pt":1631386326695,"mc":[{"id":"1.187528277","rc":[{"batb":[[0,1.4,3253.19]],"ltp":1.41,"tv":64462.71,"id":2249229}]}]}
{"op":"mcm","clk":"4218388781","pt":1631386326906,"mc":[{"id":"1.187528277","rc":[{"batb":[[2,1.38,9868.74]],"batl":[[0,1.41,6514.42]],"ltp":1.41,"tv":64462.71,"id":2249229}]}]}
{"op":"mcm","clk":"4218398323","pt":1631386415065,"mc":[{"id":"1.187528277","rc":[{"batb":[[0,3.4,366.63]],"ltp":3.4,"tv":16689.07,"id":19924831}]}]}
{"op":"mcm","clk":"4218399977","pt":1631386430543,"mc":[{"id":"1.187528277","rc":[{"batb":[[0,1.4,3058.53]],"ltp":1.41,"tv":64462.71,"id":2249229}]}]}
{"op":"mcm","clk":"4218400074","pt":1631386431548,"mc":[{"id":"1.187528277","rc":[{"batl":[[1,3.5,437.71]],"ltp":3.4,"tv":16689.07,"id":19924831}]}]}
{"op":"mcm","clk":"4218400170","pt":1631386432443,"mc":[{"id":"1.187528277","rc":[{"batl":[[1,3.5,412.08]],"ltp":3.4,"tv":16689.07,"id":19924831}]}]}
{"op":"mcm","clk":"4218400238","pt":1631386433065,"mc":[{"id":"1.187528277","rc":[{"batl":[[1,3.5,291.54]],"ltp":3.4,"tv":16689.07,"id":19924831}]}]}
{"op":"mcm","clk":"4218406000","pt":1631386493477,"mc":[{"id":"1.187528277","rc":[{"trd":[[1.4,29.76]],"batb":[[0,1.4,3054.26]],"ltp":1.4,"tv":64471.25,"id":2249229}],"tv":81160.32}]}
{"op":"mcm","clk":"4218409268","pt":1631386529718,"mc":[{"id":"1.187528277","rc":[{"trd":[[1.4,111.8]],"batb":[[0,1.4,3013.24]],"ltp":1.4,"tv":64553.29,"id":2249229}],"tv":81242.36}]}
{"op":"mcm","clk":"4218411232","pt":1631386550551,"mc":[{"id":"1.187528277","rc":[{"trd":[[3.45,167.98]],"batl":[[0,3.45,304.87]],"ltp":3.45,"tv":16746.91,"id":19924831}],"tv":81300.2}]}
{"op":"mcm","clk":"4218412487","pt":1631386564157,"mc":[{"id":"1.187528277","rc":[{"batl":[[0,3.45,160.27]],"ltp":3.45,"tv":16746.91,"id":19924831}]}]}
{"op":"mcm","clk":"4218412658","pt":1631386565672,"mc":[{"id":"1.187528277","rc":[{"trd":[[1.41,17752.61]],"batb":[[0,1.4,2897.51]],"batl":[[0,1.41,6502.56]],"ltp":1.41,"tv":64577.01,"id":2249229}],"tv":81323.92}]}
{"op":"mcm","clk":"4218412728","pt":1631386566372,"mc":[{"id":"1.187528277","rc":[{"batl":[[0,3.45,154.02],[1,3.5,249.53]],"ltp":3.45,"tv":16746.91,"id":19924831}]}]}
{"op":"mcm","clk":"4218413325","pt":1631386573273,"mc":[{"id":"1.187528277","rc":[{"batb":[[0,3.4,655.83]],"ltp":3.45,"tv":16746.91,"id":19924831}]}]}
{"op":"mcm","clk":"4218419470","pt":1631386638432,"mc":[{"id":"1.187528277","rc":[{"batb":[[0,3.4,1082.85]],"ltp":3.45,"tv":16746.91,"id":19924831}]}]}
{"op":"mcm","clk":"4218422140","pt":1631386669654,"mc":[{"id":"1.187528277","rc":[{"batl":[[0,3.45,144.62]],"ltp":3.45,"tv":16746.91,"id":19924831}]}]}
{"op":"mcm","clk":"4218424149","pt":1631386691424,"mc":[{"id":"1.187528277","rc":[{"batb":[[0,1.4,2805.16]],"ltp":1.41,"tv":64577.01,"id":2249229}]}]}
{"op":"mcm","clk":"4218424252","pt":1631386692420,"mc":[{"id":"1.187528277","rc":[{"batl":[[0,3.45,120.59],[1,3.5,236.28]],"ltp":3.45,"tv":16746.91,"id":19924831}]}]}
{"op":"mcm","clk":"4218435801","pt":1631386818713,"mc":[{"id":"1.187528277","rc":[{"batl":[[1,3.5,228.75]],"ltp":3.45,"tv":16746.91,"id":19924831},{"batb":[[0,1.4,2777.45]],"ltp":1.41,"tv":64577.01,"id":2249229}]}]}
{"op":"mcm","clk":"4218441088","pt":1631386869555,"mc":[{"id":"1.187528277","rc":[{"batb":[[1,3.35,701.74]],"ltp":3.45,"tv":16746.91,"id":19924831},{"batb":[[0,1.4,2799.9]],"ltp":1.41,"tv":64577.01,"id":2249229}]}]}
{"op":"mcm","clk":"4218441219","pt":1631386870767,"mc":[{"id":"1.187528277","rc":[{"batb":[[0,1.4,4056.22]],"ltp":1.41,"tv":64577.01,"id":2249229}]}]}
{"op":"mcm","clk":"4218449676","pt":1631386945423,"mc":[{"id":"1.187528277","rc":[{"batb":[[0,1.4,4241.06]],"ltp":1.41,"tv":64577.01,"id":2249229}]}]}
{"op":"mcm","clk":"4218449746","pt":1631386945799,"mc":[{"id":"1.187528277","rc":[{"batl":[[1,3.5,302.69]],"ltp":3.45,"tv":16746.91,"id":19924831}]}]}
{"op":"mcm","clk":"4218452068","pt":1631386965030,"mc":[{"id":"1.187528277","rc":[{"trd":[[3.4,1973.25]],"batb":[[0,3.4,1078.72]],"ltp":3.4,"tv":16755.17,"id":19924831}],"tv":81332.19}]}
{"op":"mcm","clk":"4218464466","pt":1631387059416,"mc":[{"id":"1.187528277","rc":[{"batb":[[0,1.4,4296.51]],"ltp":1.41,"tv":64577.01,"id":2249229}]}]}
{"op":"mcm","clk":"4218464511","pt":1631387059786,"mc":[{"id":"1.187528277","rc":[{"batl":[[1,3.5,324.87]],"ltp":3.4,"tv":16755.17,"id":19924831}]}]}
{"op":"mcm","clk":"4218477328","pt":1631387162581,"mc":[{"id":"1.187528277","rc":[{"trd":[[1.41,17812.61]],"batl":[[0,1.41,6472.56]],"ltp":1.41,"tv":64637.01,"id":2249229}],"tv":81392.19}]}
{"op":"mcm","clk":"4218480233","pt":1631387186544,"mc":[{"id":"1.187528277","rc":[{"batb":[[0,1.4,4313.15]],"ltp":1.41,"tv":64637.01,"id":2249229}]}]}
{"op":"mcm","clk":"4218480278","pt":1631387186918,"mc":[{"id":"1.187528277","rc":[{"batl":[[1,3.5,331.52]],"ltp":3.4,"tv":16755.17,"id":19924831}]}]}
{"op":"mcm","clk":"4218495350","pt":1631387306661,"mc":[{"id":"1.187528277","rc":[{"batb":[[0,1.4,4318.13]],"ltp":1.41,"tv":64637.01,"id":2249229}]}]}
{"op":"mcm","clk":"4218503261","pt":1631387369382,"mc":[{"id":"1.187528277","rc":[{"trd":[[3.45,176.81]],"batl":[[0,3.45,116.17]],"ltp":3.45,"tv":16764.01,"id":19924831}],"tv":81401.02}]}
{"op":"mcm","clk":"4218515158","pt":1631387445771,"mc":[{"id":"1.187528277","rc":[{"trd":[[1.4,130.19]],"batb":[[0,1.4,4308.94]],"ltp":1.4,"tv":64655.41,"id":2249229}],"tv":81419.42}]}
{"op":"mcm","clk":"4218519988","pt":1631387487205,"mc":[{"id":"1.187528277","rc":[{"trd":[[3.4,1990]],"batb":[[0,3.4,1070.35]],"ltp":3.4,"tv":16780.75,"id":19924831}],"tv":81436.16}]}
{"op":"mcm","clk":"4218531082","pt":1631387577637,"mc":[{"id":"1.187528277","rc":[{"trd":[[3.45,239.53]],"batl":[[0,3.45,84.81]],"ltp":3.45,"tv":16843.47,"id":19924831}],"tv":81498.89}]}
{"op":"mcm","clk":"4218543777","pt":1631387675587,"mc":[{"id":"1.187528277","rc":[{"batl":[[0,3.45,75.83]],"ltp":3.45,"tv":16843.47,"id":19924831},{"batb":[[0,1.4,4303.95]],"ltp":1.4,"tv":64655.41,"id":2249229}]}]}
{"op":"mcm","clk":"4218559356","pt":1631387806715,"mc":[{"id":"1.187528277","rc":[{"batb":[[0,1.4,4291.01]],"ltp":1.4,"tv":64655.41,"id":2249229}]}]}
{"op":"mcm","clk":"4218566232","pt":1631387871130,"mc":[{"id":"1.187528277","rc":[{"batl":[[1,3.5,356.52]],"ltp":3.45,"tv":16843.47,"id":19924831}]}]}
{"op":"mcm","clk":"4218572068","pt":1631387923395,"mc":[{"id":"1.187528277","rc":[{"batl":[[1,3.5,360.94]],"ltp":3.45,"tv":16843.47,"id":19924831},{"batb":[[0,1.4,4298.45]],"ltp":1.4,"tv":64655.41,"id":2249229}]}]}
{"op":"mcm","clk":"4218578995","pt":1631387980863,"mc":[{"id":"1.187528277","rc":[{"trd":[[3.4,1994]],"batb":[[0,3.4,1068.35]],"ltp":3.4,"tv":16847.47,"id":19924831}],"tv":81502.89}]}
{"op":"mcm","clk":"4218579301","pt":1631387983365,"mc":[{"id":"1.187528277","rc":[{"trd":[[1.4,138.19]],"batb":[[0,1.4,4294.45]],"ltp":1.4,"tv":64663.4,"id":2249229}],"tv":81510.88}]}
{"op":"mcm","clk":"4218581756","pt":1631388004901,"mc":[{"id":"1.187528277","rc":[{"trd":[[3.4,2000]],"batb":[[0,3.4,1065.35]],"ltp":3.4,"tv":16853.47,"id":19924831}],"tv":81516.88}]}
{"op":"mcm","clk":"4218599909","pt":1631388170499,"mc":[{"id":"1.187528277","rc":[{"batl":[[0,1.41,6344.91],[1,1.42,326.48]],"ltp":1.4,"tv":64663.4,"id":2249229}]}]}
{"op":"mcm","clk":"4218612503","pt":1631388294626,"mc":[{"id":"1.187528277","rc":[{"batb":[[1,3.35,645.13]],"ltp":3.4,"tv":16853.47,"id":19924831}]}]}
{"op":"mcm","clk":"4218623002","pt":1631388416748,"mc":[{"id":"1.187528277","rc":[{"batb":[[1,3.35,636.64]],"ltp":3.4,"tv":16853.47,"id":19924831}]}]}
{"op":"mcm","clk":"4218625142","pt":1631388446393,"mc":[{"id":"1.187528277","rc":[{"batb":[[0,3.4,1036.43]],"ltp":3.4,"tv":16853.47,"id":19924831}]}]}
{"op":"mcm","clk":"4218629746","pt":1631388514434,"mc":[{"id":"1.187528277","rc":[{"trd":[[3.4,2159.99]],"batb":[[0,3.4,1009.38]],"ltp":3.4,"tv":17013.47,"id":19924831}],"tv":81676.88}]}
{"op":"mcm","clk":"4218634441","pt":1631388594898,"mc":[{"id":"1.187528277","rc":[{"trd":[[1.41,17862.61]],"batl":[[0,1.41,6319.91]],"ltp":1.41,"tv":64713.4,"id":2249229}],"tv":81726.88}]}
{"op":"mcm","clk":"4218635694","pt":1631388614529,"mc":[{"id":"1.187528277","rc":[{"trd":[[1.4,436.93]],"batb":[[0,1.4,4145.08]],"ltp":1.4,"tv":65012.14,"id":2249229}],"tv":82025.62}]}
{"op":"mcm","clk":"4218638098","pt":1631388655735,"mc":[{"id":"1.187528277","rc":[{"trd":[[1.41,17881.55]],"batl":[[0,1.41,6310.44]],"ltp":1.41,"tv":65031.09,"id":2249229}],"tv":82044.56}]}
{"op":"mcm","clk":"4218638662","pt":1631388665651,"mc":[{"id":"1.187528277","rc":[{"batb":[[0,1.4,4137.65]],"ltp":1.41,"tv":65031.09,"id":2249229}]}]}
{"op":"mcm","clk":"4218638693","pt":1631388666131,"mc":[{"id":"1.187528277","rc":[{"batb":[[0,1.4,4133.95]],"ltp":1.41,"tv":65031.09,"id":2249229}]}]}
{"op":"mcm","clk":"4218638728","pt":1631388666755,"mc":[{"id":"1.187528277","rc":[{"batl":[[1,3.5,356.52]],"ltp":3.4,"tv":17013.47,"id":19924831}]}]}
{"op":"mcm","clk":"4218647018","pt":1631388786236,"mc":[{"id":"1.187528277","rc":[{"batb":[[0,1.4,4134.46]],"ltp":1.41,"tv":65031.09,"id":2249229}]}]}
{"op":"mcm","clk":"4218647340","pt":1631388790239,"mc":[{"id":"1.187528277","rc":[{"batb":[[0,1.4,4122.03]],"ltp":1.41,"tv":65031.09,"id":2249229}]}]}
{"op":"mcm","clk":"4218647386","pt":1631388790863,"mc":[{"id":"1.187528277","rc":[{"batl":[[1,3.5,349.87]],"ltp":3.4,"tv":17013.47,"id":19924831}]}]}
{"op":"mcm","clk":"4218652036","pt":1631388845345,"mc":[{"id":"1.187528277","rc":[{"trd":[[1.4,442.93]],"batb":[[0,1.4,4119.03]],"ltp":1.4,"tv":65037.09,"id":2249229}],"tv":82050.56}]}
{"op":"mcm","clk":"4218655079","pt":1631388881485,"mc":[{"id":"1.187528277","rc":[{"trd":[[3.45,268.45]],"batl":[[0,3.45,61.37]],"ltp":3.45,"tv":17042.39,"id":19924831}],"tv":82079.48}]}
{"op":"mcm","clk":"4218666272","pt":1631389013078,"mc":[{"id":"1.187528277","rc":[{"trd":[[1.41,17964.87]],"batl":[[0,1.41,6268.78]],"ltp":1.41,"tv":65120.41,"id":2249229}],"tv":82162.8}]}
{"op":"mcm","clk":"4218687429","pt":1631389253854,"mc":[{"id":"1.187528277","rc":[{"batb":[[0,1.4,4428.88]],"ltp":1.41,"tv":65120.41,"id":2249229}]}]}
{"op":"mcm","clk":"4218688249","pt":1631389262400,"mc":[{"id":"1.187528277","rc":[{"batl":[[1,3.5,368.21]],"ltp":3.45,"tv":17042.39,"id":19924831},{"batb":[[0,1.4,4465.28]],"ltp":1.41,"tv":65120.41,"id":2249229}]}]}
{"op":"mcm","clk":"4218699774","pt":1631389386720,"mc":[{"id":"1.187528277","rc":[{"batl":[[1,3.5,373.15]],"ltp":3.45,"tv":17042.39,"id":19924831},{"batb":[[0,1.4,4477.62]],"ltp":1.41,"tv":65120.41,"id":2249229}]}]}
{"op":"mcm","clk":"4218709083","pt":1631389508353,"mc":[{"id":"1.187528277","rc":[{"batb":[[0,1.4,4481.32]],"ltp":1.41,"tv":65120.41,"id":2249229}]}]}
{"op":"mcm","clk":"4218715521","pt":1631389575844,"mc":[{"id":"1.187528277","rc":[{"batb":[[0,1.4,4493.32]],"ltp":1.41,"tv":65120.41,"id":2249229}]}]}
{"op":"mcm","clk":"4218715635","pt":1631389577046,"mc":[{"id":"1.187528277","rc":[{"batb":[[1,1.39,6654.8]],"ltp":1.41,"tv":65120.41,"id":2249229}]}]}
{"op":"mcm","clk":"4218716055","pt":1631389582940,"mc":[{"id":"1.187528277","rc":[{"batb":[[0,3.4,1015.38]],"ltp":3.45,"tv":17042.39,"id":19924831}]}]}
{"op":"mcm","clk":"4218716116","pt":1631389583763,"mc":[{"id":"1.187528277","rc":[{"batb":[[1,3.35,642.64]],"ltp":3.45,"tv":17042.39,"id":19924831}]}]}
{"op":"mcm","clk":"4218731288","pt":1631389768578,"mc":[{"id":"1.187528277","rc":[{"batb":[[0,1.4,4542.41]],"ltp":1.41,"tv":65120.41,"id":2249229}]}]}
{"op":"mcm","clk":"4218731331","pt":1631389768946,"mc":[{"id":"1.187528277","rc":[{"batb":[[0,1.4,4493.32]],"ltp":1.41,"tv":65120.41,"id":2249229}]}]}
{"op":"mcm","clk":"4218733870","pt":1631389798153,"mc":[{"id":"1.187528277","rc":[{"batl":[[1,3.5,348.15]],"ltp":3.45,"tv":17042.39,"id":19924831}]}]}
{"op":"mcm","clk":"4218745937","pt":1631389949039,"mc":[{"id":"1.187528277","rc":[{"trd":[[3.4,2175.99]],"batb":[[0,3.4,1007.38]],"ltp":3.4,"tv":17058.39,"id":19924831}],"tv":82178.8}]}
{"op":"mcm","clk":"4218763381","pt":1631390170222,"mc":[{"id":"1.187528277","rc":[{"trd":[[1.41,18008.87]],"batl":[[0,1.41,6246.78]],"ltp":1.41,"tv":65164.41,"id":2249229}],"tv":82222.8}]}
{"op":"mcm","clk":"4218789758","pt":1631390506089,"mc":[{"id":"1.187528277","rc":[{"trd":[[3.4,2195.99]],"batb":[[0,3.4,997.38]],"ltp":3.4,"tv":17078.39,"id":19924831}],"tv":82242.8}]}
{"op":"mcm","clk":"4218791252","pt":1631390520015,"mc":[{"id":"1.187528277","rc":[{"trd":[[3.4,2199.99]],"batb":[[0,3.4,995.38]],"ltp":3.4,"tv":17082.39,"id":19924831}],"tv":82246.8}]}
{"op":"mcm","clk":"4218793642","pt":1631390543343,"mc":[{"id":"1.187528277","rc":[{"trd":[[1.41,18068.87]],"batl":[[0,1.41,6216.78]],"ltp":1.41,"tv":65224.41,"id":2249229}],"tv":82306.8}]}
{"op":"mcm","clk":"4218805934","pt":1631390692607,"mc":[{"id":"1.187528277","rc":[{"trd":[[1.4,482.93]],"batb":[[0,1.4,4473.32]],"ltp":1.4,"tv":65264.41,"id":2249229}],"tv":82346.8}]}
{"op":"mcm","clk":"4218808281","pt":1631390718495,"mc":[{"id":"1.187528277","rc":[{"batb":[[0,1.4,4497.71]],"ltp":1.4,"tv":65264.41,"id":2249229}]}]}
{"op":"mcm","clk":"4218808308","pt":1631390718807,"mc":[{"id":"1.187528277","rc":[{"batb":[[0,1.4,4473.32]],"ltp":1.4,"tv":65264.41,"id":2249229}]}]}
{"op":"mcm","clk":"4218817429","pt":1631390822508,"mc":[{"id":"1.187528277","rc":[{"batb":[[0,1.4,5315.37]],"ltp":1.4,"tv":65264.41,"id":2249229}]}]}
{"op":"mcm","clk":"4218817458","pt":1631390822932,"mc":[{"id":"1.187528277","rc":[{"batb":[[0,1.4,4473.32]],"ltp":1.4,"tv":65264.41,"id":2249229}]}]}
{"op":"mcm","clk":"4218822954","pt":1631390888631,"mc":[{"id":"1.187528277","rc":[{"trd":[[1.4,505.8]],"batb":[[0,1.4,4461.89]],"ltp":1.4,"tv":65287.27,"id":2249229}],"tv":82369.67}]}
{"op":"mcm","clk":"4218835581","pt":1631391019547,"mc":[{"id":"1.187528277","rc":[{"trd":[[1.41,18087.66]],"batl":[[0,1.41,6207.39]],"ltp":1.41,"tv":65306.05,"id":2249229}],"tv":82388.45}]}
{"op":"mcm","clk":"4218843508","pt":1631391101526,"mc":[{"id":"1.187528277","rc":[{"batb":[[1,1.39,6782.91]],"batl":[[1,1.42,454.59]],"ltp":1.41,"tv":65306.05,"id":2249229}]}]}
{"op":"mcm","clk":"4218843735","pt":1631391103910,"mc":[{"id":"1.187528277","rc":[{"trd":[[1.41,18125.24]],"batl":[[0,1.41,6188.6]],"ltp":1.41,"tv":65343.63,"id":2249229}],"tv":82426.03}]}
{"op":"mcm","clk":"4218848493","pt":1631391151860,"mc":[{"id":"1.187528277","rc":[{"batb":[[1,3.35,650.41]],"ltp":3.4,"tv":17082.39,"id":19924831}]}]}
{"op":"mcm","clk":"4218851205","pt":1631391182006,"mc":[{"id":"1.187528277","rc":[{"trd":[[1.4,4505.8]],"batb":[[0,1.4,2461.89]],"ltp":1.4,"tv":69343.64,"id":2249229}],"tv":86426.03}]}
{"op":"mcm","clk":"4218852760","pt":1631391197409,"mc":[{"id":"1.187528277","rc":[{"batb":[[2,1.38,11868.74]],"ltp":1.4,"tv":69343.64,"id":2249229}]}]}
{"op":"mcm","clk":"4218859655","pt":1631391265473,"mc":[{"id":"1.187528277","rc":[{"batb":[[0,1.4,2445.85]],"ltp":1.4,"tv":69343.64,"id":2249229}]}]}
{"op":"mcm","clk":"4218859756","pt":1631391266584,"mc":[{"id":"1.187528277","rc":[{"batb":[[0,1.4,2366.42]],"ltp":1.4,"tv":69343.64,"id":2249229}]}]}
{"op":"mcm","clk":"4218859837","pt":1631391267492,"mc":[{"id":"1.187528277","rc":[{"batb":[[0,1.4,2260.31]],"batl":[[1,1.42,508.13]],"ltp":1.4,"tv":69343.64,"id":2249229}]}]}
{"op":"mcm","clk":"4218859935","pt":1631391268394,"mc":[{"id":"1.187528277","rc":[{"batl":[[1,3.5,324.87]],"ltp":3.4,"tv":17082.39,"id":19924831}]}]}
{"op":"mcm","clk":"4218860037","pt":1631391269398,"mc":[{"id":"1.187528277","rc":[{"batl":[[1,3.5,228.75]],"ltp":3.4,"tv":17082.39,"id":19924831}]}]}
{"op":"mcm","clk":"4218861260","pt":1631391282199,"mc":[{"id":"1.187528277","rc":[{"trd":[[1.41,18196.91]],"batl":[[0,1.41,6152.76]],"ltp":1.41,"tv":69415.31,"id":2249229}],"tv":86497.71}]}
{"op":"mcm","clk":"4218862924","pt":1631391298797,"mc":[{"id":"1.187528277","rc":[{"trd":[[3.45,298.82]],"batl":[[0,3.45,46.19]],"ltp":3.45,"tv":17112.75,"id":19924831}],"tv":86528.07}]}
{"op":"mcm","clk":"4218869548","pt":1631391368594,"mc":[{"id":"1.187528277","rc":[{"trd":[[3.45,391.21]],"batb":[[0,3.45,227.68],[1,3.4,995.38],[2,3.35,650.41]],"batl":[[0,3.5,228.75],[1,9.8,6.16],[2,9.8,0]],"ltp":3.45,"tv":17205.14,"id":19924831}],"tv":86620.46}]}
{"op":"mcm","clk":"4218869569","pt":1631391368834,"mc":[{"id":"1.187528277","rc":[{"batb":[[0,3.45,279.85]],"ltp":3.45,"tv":17205.14,"id":19924831}]}]}
{"op":"mcm","clk":"4218870939","pt":1631391382364,"mc":[{"id":"1.187528277","rc":[{"batb":[[2,3.35,627.4]],"ltp":3.45,"tv":17205.14,"id":19924831}]}]}
{"op":"mcm","clk":"4218871049","pt":1631391383461,"mc":[{"id":"1.187528277","rc":[{"batb":[[2,3.35,537.9]],"ltp":3.45,"tv":17205.14,"id":19924831}]}]}
{"op":"mcm","clk":"4218871123","pt":1631391384170,"mc":[{"id":"1.187528277","rc":[{"batb":[[2,3.35,525.11]],"ltp":3.45,"tv":17205.14,"id":19924831}]}]}
{"op":"mcm","clk":"4218871641","pt":1631391389570,"mc":[{"id":"1.187528277","rc":[{"batb":[[0,1.4,2162.6]],"ltp":1.41,"tv":69415.31,"id":2249229}]}]}
{"op":"mcm","clk":"4218871714","pt":1631391390404,"mc":[{"id":"1.187528277","rc":[{"batb":[[1,3.4,1001.63]],"ltp":3.45,"tv":17205.14,"id":19924831},{"batl":[[1,1.42,514.99]],"ltp":1.41,"tv":69415.31,"id":2249229}]}]}
{"op":"mcm","clk":"4218871802","pt":1631391391303,"mc":[{"id":"1.187528277","rc":[{"batl":[[0,3.5,194.93],[1,3.6,392.84],[2,9.8,6.16]],"ltp":3.45,"tv":17205.14,"id":19924831}]}]}
{"op":"mcm","clk":"4218872939","pt":1631391402298,"mc":[{"id":"1.187528277","rc":[{"batb":[[2,3.35,551.59]],"batl":[[0,3.5,230.8]],"ltp":3.45,"tv":17205.14,"id":19924831},{"batb":[[0,1.4,2110.51]],"batl":[[2,1.43,883.7]],"ltp":1.41,"tv":69415.31,"id":2249229}]}]}
{"op":"mcm","clk":"4218895005","pt":1631391513385,"mc":[{"id":"1.187528277","rc":[{"batl":[[0,3.5,222.12]],"ltp":3.45,"tv":17205.14,"id":19924831},{"batb":[[0,1.4,2088.81]],"ltp":1.41,"tv":69415.31,"id":2249229}]}]}
{"op":"mcm","clk":"4218895054","pt":1631391514019,"mc":[{"id":"1.187528277","rc":[{"batl":[[1,3.6,451.77]],"ltp":3.45,"tv":17205.14,"id":19924831}]}]}
{"op":"mcm","clk":"4218895188","pt":1631391515695,"mc":[{"id":"1.187528277","rc":[{"trd":[[1.4,5473.27]],"batb":[[0,1.4,1605.06]],"ltp":1.4,"tv":70382.79,"id":2249229}],"tv":87587.94}]}
{"op":"mcm","clk":"4218895328","pt":1631391517585,"mc":[{"id":"1.187528277","rc":[{"batb":[[2,3.35,525.11]],"batl":[[0,3.5,186.25]],"ltp":3.45,"tv":17205.14,"id":19924831},{"batl":[[2,1.43,800]],"ltp":1.4,"tv":70382.79,"id":2249229}]}]}
{"op":"mcm","clk":"4218895399","pt":1631391518487,"mc":[{"id":"1.187528277","rc":[{"batb":[[2,3.35,542.19]],"batl":[[1,3.55,33.31],[2,3.6,451.77]],"ltp":3.45,"tv":17205.14,"id":19924831},{"batb":[[1,1.39,6904.18]],"batl":[[1,1.42,591.86]],"ltp":1.4,"tv":70382.79,"id":2249229}]}]}
{"op":"mcm","clk":"4218895586","pt":1631391520687,"mc":[{"id":"1.187528277","rc":[{"trd":[[1.4,6440.73]],"batb":[[0,1.4,1121.33]],"ltp":1.4,"tv":71350.25,"id":2249229}],"tv":88555.4}]}
{"op":"mcm","clk":"4218895675","pt":1631391521684,"mc":[{"id":"1.187528277","rc":[{"batb":[[1,1.39,6927.38]],"ltp":1.4,"tv":71350.25,"id":2249229}]}]}
{"op":"mcm","clk":"4218896331","pt":1631391529731,"mc":[{"id":"1.187528277","rc":[{"trd":[[1.4,7408.19]],"batb":[[0,1.4,637.6]],"ltp":1.4,"tv":72317.7,"id":2249229}],"tv":89522.85}]}
{"op":"mcm","clk":"4218897834","pt":1631391547584,"mc":[{"id":"1.187528277","rc":[{"batb":[[2,3.35,569.52]],"ltp":3.45,"tv":17205.14,"id":19924831}]}]}
{"op":"mcm","clk":"4218904753","pt":1631391619609,"mc":[{"id":"1.187528277","rc":[{"batl":[[2,9.8,6.16]],"ltp":3.45,"tv":17205.14,"id":19924831}]}]}
{"op":"mcm","clk":"4218905602","pt":1631391623599,"mc":[{"id":"1.187528277","rc":[{"batb":[[0,1.4,803.09]],"batl":[[1,1.42,758.49]],"ltp":1.4,"tv":72317.7,"id":2249229}]}]}
{"op":"mcm","clk":"4218905710","pt":1631391624605,"mc":[{"id":"1.187528277","rc":[{"batb":[[1,3.4,1085.26]],"batl":[[0,3.5,91.19]],"ltp":3.45,"tv":17205.14,"id":19924831}]}]}
{"op":"mcm","clk":"4218905765","pt":1631391625074,"mc":[{"id":"1.187528277","rc":[{"batb":[[2,3.35,515.79]],"batl":[[1,3.55,38.3]],"ltp":3.45,"tv":17205.14,"id":19924831},{"batl":[[0,1.41,6280.41]],"ltp":1.4,"tv":72317.7,"id":2249229}]}]}
{"op":"mcm","clk":"4218910569","pt":1631391680213,"mc":[{"id":"1.187528277","rc":[{"trd":[[3.45,398.44]],"batb":[[0,3.45,276.23]],"ltp":3.45,"tv":17212.38,"id":19924831}],"tv":89530.09}]}
{"op":"mcm","clk":"4218915392","pt":1631391742048,"mc":[{"id":"1.187528277","rc":[{"batl":[[1,1.42,762]],"ltp":1.4,"tv":72317.7,"id":2249229}]}]}
{"op":"mcm","clk":"4218918636","pt":1631391783701,"mc":[{"id":"1.187528277","rc":[{"batb":[[1,1.39,7306.58]],"ltp":1.4,"tv":72317.7,"id":2249229}]}]}
{"op":"mcm","clk":"4218932194","pt":1631391991855,"mc":[{"id":"1.187528277","rc":[{"batl":[[2,3.6,36.15]],"ltp":3.45,"tv":17212.38,"id":19924831}]}]}
{"op":"mcm","clk":"4218933217","pt":1631392008604,"mc":[{"id":"1.187528277","rc":[{"batb":[[0,1.4,1408.88]],"ltp":1.4,"tv":72317.7,"id":2249229}]}]}
{"op":"mcm","clk":"4218933235","pt":1631392008929,"mc":[{"id":"1.187528277","rc":[{"batb":[[0,1.4,803.09]],"ltp":1.4,"tv":72317.7,"id":2249229}]}]}
{"op":"mcm","clk":"4218950177","pt":1631392287136,"mc":[{"id":"1.187528277","rc":[{"batb":[[0,3.45,476.23]],"ltp":3.45,"tv":17212.38,"id":19924831}]}]}
{"op":"mcm","clk":"4218950599","pt":1631392295151,"mc":[{"id":"1.187528277","rc":[{"batb":[[1,1.39,7371.58]],"ltp":1.4,"tv":72317.7,"id":2249229}]}]}
{"op":"mcm","clk":"4218950647","pt":1631392295986,"mc":[{"id":"1.187528277","rc":[{"batb":[[0,1.4,2511.17]],"ltp":1.4,"tv":72317.7,"id":2249229}]}]}
{"op":"mcm","clk":"4218954334","pt":1631392364669,"mc":[{"id":"1.187528277","rc":[{"batl":[[0,3.5,189.35]],"ltp":3.45,"tv":17212.38,"id":19924831},{"batb":[[0,1.4,3362.35]],"batl":[[0,1.41,6152.76]],"ltp":1.4,"tv":72317.7,"id":2249229}]}]}
{"op":"mcm","clk":"4218954342","pt":1631392364775,"mc":[{"id":"1.187528277","rc":[{"batb":[[0,1.4,2756.56]],"ltp":1.4,"tv":72317.7,"id":2249229}]}]}
{"op":"mcm","clk":"4218955587","pt":1631392385785,"mc":[{"id":"1.187528277","rc":[{"batb":[[0,1.4,2757.07]],"ltp":1.4,"tv":72317.7,"id":2249229}]}]}
{"op":"mcm","clk":"4218956647","pt":1631392404660,"mc":[{"id":"1.187528277","rc":[{"trd":[[1.4,7418.19]],"batb":[[0,1.4,2752.07]],"ltp":1.4,"tv":72327.7,"id":2249229}],"tv":89540.09}]}
{"op":"mcm","clk":"4218957881","pt":1631392425596,"mc":[{"id":"1.187528277","rc":[{"batb":[[0,1.4,2825.01]],"ltp":1.4,"tv":72327.7,"id":2249229}]}]}
{"op":"mcm","clk":"4218957902","pt":1631392425855,"mc":[{"id":"1.187528277","rc":[{"batl":[[0,3.5,218.53]],"ltp":3.45,"tv":17212.38,"id":19924831}]}]}
{"op":"mcm","clk":"4218960167","pt":1631392467812,"mc":[{"id":"1.187528277","rc":[{"batb":[[0,1.4,3160.01]],"ltp":1.4,"tv":72327.7,"id":2249229}]}]}
{"op":"mcm","clk":"4218960257","pt":1631392469727,"mc":[{"id":"1.187528277","rc":[{"batb":[[1,1.39,7715.17]],"ltp":1.4,"tv":72327.7,"id":2249229}]}]}
{"op":"mcm","clk":"4218960363","pt":1631392471809,"mc":[{"id":"1.187528277","rc":[{"batb":[[2,1.38,12221.37]],"ltp":1.4,"tv":72327.7,"id":2249229}]}]}
{"op":"mcm","clk":"4218960994","pt":1631392484459,"mc":[{"id":"1.187528277","rc":[{"batb":[[0,1.4,3232.15]],"ltp":1.4,"tv":72327.7,"id":2249229}]}]}
{"op":"mcm","clk":"4218961016","pt":1631392484830,"mc":[{"id":"1.187528277","rc":[{"batl":[[0,3.5,247.38]],"ltp":3.45,"tv":17212.38,"id":19924831}]}]}
{"op":"mcm","clk":"4218964034","pt":1631392543524,"mc":[{"id":"1.187528277","rc":[{"batb":[[0,1.4,3253.79]],"ltp":1.4,"tv":72327.7,"id":2249229}]}]}
{"op":"mcm","clk":"4218964056","pt":1631392543936,"mc":[{"id":"1.187528277","rc":[{"batl":[[0,3.5,256.04]],"ltp":3.45,"tv":17212.38,"id":19924831}]}]}
{"op":"mcm","clk":"4218967258","pt":1631392603285,"mc":[{"id":"1.187528277","rc":[{"batb":[[0,1.4,3260.28]],"ltp":1.4,"tv":72327.7,"id":2249229}]}]}
{"op":"mcm","clk":"4218969280","pt":1631392640147,"mc":[{"id":"1.187528277","rc":[{"batl":[[0,1.41,8705.41]],"ltp":1.4,"tv":72327.7,"id":2249229}]}]}
{"op":"mcm","clk":"4218970473","pt":1631392661177,"mc":[{"id":"1.187528277","rc":[{"batl":[[0,3.5,259.02]],"ltp":3.45,"tv":17212.38,"id":19924831}]}]}
{"op":"mcm","clk":"4218972222","pt":1631392693202,"mc":[{"id":"1.187528277","rc":[{"batb":[[0,3.45,500.17]],"ltp":3.45,"tv":17212.38,"id":19924831}]}]}
{"op":"mcm","clk":"4218972996","pt":1631392706001,"mc":[{"id":"1.187528277","rc":[{"batb":[[0,3.45,500.7]],"ltp":3.45,"tv":17212.38,"id":19924831}]}]}
{"op":"mcm","clk":"4218982264","pt":1631392867639,"mc":[{"id":"1.187528277","rc":[{"trd":[[1.4,7432.33]],"batb":[[0,1.4,3253.21]],"ltp":1.4,"tv":72341.85,"id":2249229}],"tv":89554.23}]}
{"op":"mcm","clk":"4218986082","pt":1631392933680,"mc":[{"id":"1.187528277","rc":[{"trd":[[1.41,18199.67]],"batl":[[0,1.41,8704.03]],"ltp":1.41,"tv":72344.6,"id":2249229}],"tv":89556.98}]}
{"op":"mcm","clk":"4218987082","pt":1631392948724,"mc":[{"id":"1.187528277","rc":[{"trd":[[1.4,7529.07]],"batb":[[0,1.4,3204.84]],"ltp":1.4,"tv":72441.35,"id":2249229}],"tv":89653.73}]}
{"op":"mcm","clk":"4219006424","pt":1631393252495,"mc":[{"id":"1.187528277","rc":[{"batb":[[0,1.4,3810.63]],"ltp":1.4,"tv":72441.35,"id":2249229}]}]}
{"op":"mcm","clk":"4219006445","pt":1631393252803,"mc":[{"id":"1.187528277","rc":[{"batb":[[0,1.4,3204.84]],"ltp":1.4,"tv":72441.35,"id":2249229}]}]}
{"op":"mcm","clk":"4219010295","pt":1631393314513,"mc":[{"id":"1.187528277","rc":[{"trd":[[1.41,18206.51]],"batl":[[0,1.41,8700.61]],"ltp":1.41,"tv":72448.18,"id":2249229}],"tv":89660.56}]}
{"op":"mcm","clk":"4219010932","pt":1631393323652,"mc":[{"id":"1.187528277","rc":[{"trd":[[3.5,17.9]],"batl":[[0,3.5,251.91]],"ltp":3.5,"tv":17226.59,"id":19924831}],"tv":89674.78}]}
{"op":"mcm","clk":"4219014858","pt":1631393391243,"mc":[{"id":"1.187528277","rc":[{"batl":[[0,3.5,315.73]],"ltp":3.5,"tv":17226.59,"id":19924831}]}]}
{"op":"mcm","clk":"4219018045","pt":1631393452219,"mc":[{"id":"1.187528277","rc":[{"batl":[[0,3.5,321.36]],"ltp":3.5,"tv":17226.59,"id":19924831},{"batb":[[0,1.4,3219.88]],"ltp":1.41,"tv":72448.18,"id":2249229}]}]}
{"op":"mcm","clk":"4219021117","pt":1631393507506,"mc":[{"id":"1.187528277","rc":[{"trd":[[3.45,468.73]],"batb":[[0,3.45,465.55]],"ltp":3.45,"tv":17296.88,"id":19924831},{"batb":[[0,1.4,3884.92]],"ltp":1.41,"tv":72448.18,"id":2249229}],"tv":89745.07}]}
{"op":"mcm","clk":"4219021131","pt":1631393507764,"mc":[{"id":"1.187528277","rc":[{"batb":[[0,1.4,3219.88]],"ltp":1.41,"tv":72448.18,"id":2249229}]}]}
{"op":"mcm","clk":"4219022750","pt":1631393535622,"mc":[{"id":"1.187528277","rc":[{"trd":[[3.5,395.73]],"batb":[[0,3.45,276.63]],"batl":[[0,3.5,132.44]],"ltp":3.5,"tv":17674.72,"id":19924831}],"tv":90122.9}]}
{"op":"mcm","clk":"4219024365","pt":1631393562476,"mc":[{"id":"1.187528277","rc":[{"batb":[[0,1.4,3198.35]],"ltp":1.41,"tv":72448.18,"id":2249229}]}]}
{"op":"mcm","clk":"4219024452","pt":1631393563610,"mc":[{"id":"1.187528277","rc":[{"batb":[[0,1.4,3122.1]],"ltp":1.41,"tv":72448.18,"id":2249229}]}]}
{"op":"mcm","clk":"4219024515","pt":1631393564385,"mc":[{"id":"1.187528277","rc":[{"batb":[[1,3.4,1173.97]],"ltp":3.5,"tv":17674.72,"id":19924831},{"batl":[[0,1.41,8854.57]],"ltp":1.41,"tv":72448.18,"id":2249229}]}]}
{"op":"mcm","clk":"4219024542","pt":1631393564796,"mc":[{"id":"1.187528277","rc":[{"batl":[[0,3.5,276.88]],"ltp":3.5,"tv":17674.72,"id":19924831}]}]}
{"op":"mcm","clk":"4219025729","pt":1631393584315,"mc":[{"id":"1.187528277","rc":[{"trd":[[1.4,7562.14]],"batb":[[0,1.4,3105.57]],"ltp":1.4,"tv":72481.24,"id":2249229}],"tv":90155.97}]}
{"op":"mcm","clk":"4219030944","pt":1631393676265,"mc":[{"id":"1.187528277","rc":[{"batl":[[0,3.5,291.68]],"ltp":3.5,"tv":17674.72,"id":19924831}]}]}
{"op":"mcm","clk":"4219035621","pt":1631393757046,"mc":[{"id":"1.187528277","rc":[{"trd":[[1.41,18250.92]],"batl":[[0,1.41,8832.36]],"ltp":1.41,"tv":72525.66,"id":2249229}],"tv":90200.38}]}
{"op":"mcm","clk":"4219035784","pt":1631393760489,"mc":[{"id":"1.187528277","rc":[{"batl":[[0,1.41,11385.01]],"ltp":1.41,"tv":72525.66,"id":2249229}]}]}
{"op":"mcm","clk":"4219047220","pt":1631393988726,"mc":[{"id":"1.187528277","rc":[{"trd":[[1.41,18420.12]],"batl":[[0,1.41,11300.41]],"ltp":1.41,"tv":72694.86,"id":2249229}],"tv":90369.58}]}
{"op":"mcm","clk":"4219047480","pt":1631393993832,"mc":[{"id":"1.187528277","rc":[{"batb":[[0,3.45,376.63]],"ltp":3.5,"tv":17674.72,"id":19924831}]}]}
{"op":"mcm","clk":"4219048928","pt":1631394017789,"mc":[{"id":"1.187528277","rc":[{"trd":[[1.41,18420.16]],"batl":[[0,1.41,11300.39]],"ltp":1.41,"tv":72694.89,"id":2249229}],"tv":90369.62}]}
{"op":"mcm","clk":"4219055118","pt":1631394123463,"mc":[{"id":"1.187528277","rc":[{"trd":[[1.41,18428.7]],"batl":[[0,1.41,11296.12]],"ltp":1.41,"tv":72703.43,"id":2249229}],"tv":90378.16}]}
{"op":"mcm","clk":"4219057178","pt":1631394159182,"mc":[{"id":"1.187528277","rc":[{"trd":[[3.45,496.23]],"batb":[[0,3.45,362.88]],"ltp":3.45,"tv":17702.21,"id":19924831}],"tv":90405.65}]}
{"op":"mcm","clk":"4219059560","pt":1631394199978,"mc":[{"id":"1.187528277","rc":[{"trd":[[1.4,8362.14]],"batb":[[0,1.4,2705.57]],"ltp":1.4,"tv":73503.43,"id":2249229}],"tv":91205.65}]}
{"op":"mcm","clk":"4219061064","pt":1631394228271,"mc":[{"id":"1.187528277","rc":[{"trd":[[1.4,8682.14]],"batb":[[0,1.4,2545.57]],"ltp":1.4,"tv":73823.43,"id":2249229}],"tv":91525.65}]}
{"op":"mcm","clk":"4219062750","pt":1631394260424,"mc":[{"id":"1.187528277","rc":[{"trd":[[1.41,18442.36]],"batl":[[0,1.41,11289.29]],"ltp":1.41,"tv":73837.1,"id":2249229}],"tv":91539.31}]}
{"op":"mcm","clk":"4219062991","pt":1631394265132,"mc":[{"id":"1.187528277","rc":[{"batl":[[0,3.5,276.88]],"ltp":3.45,"tv":17702.21,"id":19924831}]}]}
{"op":"mcm","clk":"4219063017","pt":1631394265748,"mc":[{"id":"1.187528277","rc":[{"batl":[[0,3.5,260.3]],"ltp":3.45,"tv":17702.21,"id":19924831}]}]}
{"op":"mcm","clk":"4219064621","pt":1631394293477,"mc":[{"id":"1.187528277","rc":[{"batl":[[2,3.6,38.15]],"ltp":3.45,"tv":17702.21,"id":19924831}]}]}
{"op":"mcm","clk":"4219069329","pt":1631394377188,"mc":[{"id":"1.187528277","rc":[{"batb":[[0,1.4,2528.05]],"ltp":1.41,"tv":73837.1,"id":2249229}]}]}
{"op":"mcm","clk":"4219070653","pt":1631394401836,"mc":[{"id":"1.187528277","rc":[{"trd":[[1.41,18527.76]],"batl":[[0,1.41,11246.59]],"ltp":1.41,"tv":73922.5,"id":2249229}],"tv":91624.72}]}
{"op":"mcm","clk":"4219075091","pt":1631394487662,"mc":[{"id":"1.187528277","rc":[{"trd":[[1.41,18528.1]],"batl":[[0,1.41,11246.42]],"ltp":1.41,"tv":73922.84,"id":2249229}],"tv":91625.06}]}
{"op":"mcm","clk":"4219075749","pt":1631394500149,"mc":[{"id":"1.187528277","rc":[{"batl":[[0,3.5,254.54]],"ltp":3.45,"tv":17702.21,"id":19924831}]}]}
{"op":"mcm","clk":"4219080226","pt":1631394582747,"mc":[{"id":"1.187528277","rc":[{"batb":[[1,1.39,7868.23]],"ltp":1.41,"tv":73922.84,"id":2249229}]}]}
{"op":"mcm","clk":"4219084832","pt":1631394662948,"mc":[{"id":"1.187528277","rc":[{"trd":[[3.45,498.99]],"batb":[[0,3.45,361.5]],"ltp":3.45,"tv":17704.97,"id":19924831}],"tv":91627.82}]}
{"op":"mcm","clk":"4219085519","pt":1631394675995,"mc":[{"id":"1.187528277","rc":[{"trd":[[1.41,18570.8]],"batl":[[0,1.41,11225.07]],"ltp":1.41,"tv":73965.54,"id":2249229}],"tv":91670.52}]}
{"op":"mcm","clk":"4219087239","pt":1631394707378,"mc":[{"id":"1.187528277","rc":[{"trd":[[1.41,18601.55]],"batl":[[0,1.41,11209.7]],"ltp":1.41,"tv":73996.28,"id":2249229}],"tv":91701.26}]}
{"op":"mcm","clk":"4219095613","pt":1631394850206,"mc":[{"id":"1.187528277","rc":[{"batb":[[1,1.39,8295.25]],"ltp":1.41,"tv":73996.28,"id":2249229}]}]}
{"op":"mcm","clk":"4219097411","pt":1631394882872,"mc":[{"id":"1.187528277","rc":[{"trd":[[3.45,533.15]],"batb":[[0,3.45,344.42]],"ltp":3.45,"tv":17739.13,"id":19924831}],"tv":91735.42}]}
{"op":"mcm","clk":"4219102759","pt":1631394971583,"mc":[{"id":"1.187528277","rc":[{"trd":[[1.41,18686.95]],"batl":[[0,1.41,11167]],"ltp":1.41,"tv":74081.69,"id":2249229}],"tv":91820.82}]}
{"op":"mcm","clk":"4219103783","pt":1631394987430,"mc":[{"id":"1.187528277","rc":[{"trd":[[1.41,18697.03]],"batl":[[0,1.41,11161.96]],"ltp":1.41,"tv":74091.77,"id":2249229}],"tv":91830.9}]}
{"op":"mcm","clk":"4219106211","pt":1631395033589,"mc":[{"id":"1.187528277","rc":[{"batb":[[0,1.4,3133.84]],"ltp":1.41,"tv":74091.77,"id":2249229}]}]}
{"op":"mcm","clk":"4219106230","pt":1631395033900,"mc":[{"id":"1.187528277","rc":[{"trd":[[1.41,19038.65]],"batb":[[0,1.4,2528.05]],"batl":[[0,1.41,10991.15]],"ltp":1.41,"tv":74433.38,"id":2249229}],"tv":92172.52}]}
{"op":"mcm","clk":"4219109238","pt":1631395087473,"mc":[{"id":"1.187528277","rc":[{"trd":[[3.45,618.55]],"batb":[[0,3.45,353.89]],"ltp":3.45,"tv":17824.53,"id":19924831}],"tv":92257.92}]}
{"op":"mcm","clk":"4219110372","pt":1631395106796,"mc":[{"id":"1.187528277","rc":[{"trd":[[3.45,818.55]],"batb":[[0,3.45,253.89]],"ltp":3.45,"tv":18024.53,"id":19924831}],"tv":92457.92}]}
{"op":"mcm","clk":"4219111047","pt":1631395117413,"mc":[{"id":"1.187528277","rc":[{"batb":[[0,3.45,259.02]],"ltp":3.45,"tv":18024.53,"id":19924831},{"batb":[[0,1.4,2540.68]],"ltp":1.41,"tv":74433.38,"id":2249229}]}]}
{"op":"mcm","clk":"4219113904","pt":1631395168739,"mc":[{"id":"1.187528277","rc":[{"batb":[[0,1.4,3263.69]],"ltp":1.41,"tv":74433.38,"id":2249229}]}]}
{"op":"mcm","clk":"4219114259","pt":1631395174996,"mc":[{"id":"1.187528277","rc":[{"trd":[[1.4,8725.48]],"batb":[[0,1.4,3242.02]],"ltp":1.4,"tv":74476.73,"id":2249229}],"tv":92501.27}]}
{"op":"mcm","clk":"4219115683","pt":1631395198715,"mc":[{"id":"1.187528277","rc":[{"batb":[[1,3.4,1178.34]],"ltp":3.45,"tv":18024.53,"id":19924831},{"batb":[[0,1.4,3269.95]],"batl":[[0,1.41,11001.52]],"ltp":1.4,"tv":74476.73,"id":2249229}]}]}
{"op":"mcm","clk":"4219115707","pt":1631395199131,"mc":[{"id":"1.187528277","rc":[{"batl":[[0,3.5,296.52]],"ltp":3.45,"tv":18024.53,"id":19924831}]}]}
{"op":"mcm","clk":"4219115884","pt":1631395202132,"mc":[{"id":"1.187528277","rc":[{"trd":[[3.45,918.55]],"batb":[[0,3.45,209.02]],"ltp":3.45,"tv":18124.53,"id":19924831}],"tv":92601.27}]}
{"op":"mcm","clk":"4219117831","pt":1631395237552,"mc":[{"id":"1.187528277","rc":[{"trd":[[3.45,1377.16]],"batb":[[0,3.4,1178.34],[1,3.35,515.79],[2,3.3,20]],"batl":[[0,3.45,670.7],[1,3.5,296.52],[2,3.55,38.3]],"ltp":3.45,"tv":18583.14,"id":19924831},{"batb":[[0,1.4,3398.52]],"ltp":1.4,"tv":74476.73,"id":2249229}],"tv":93059.87}]}
{"op":"mcm","clk":"4219117876","pt":1631395238434,"mc":[{"id":"1.187528277","rc":[{"trd":[[1.4,9125.49]],"batb":[[0,1.4,3198.51]],"ltp":1.4,"tv":74876.74,"id":2249229}],"tv":93459.89}]}
{"op":"mcm","clk":"4219122072","pt":1631395315260,"mc":[{"id":"1.187528277","rc":[{"batl":[[2,3.55,33.31]],"ltp":3.45,"tv":18583.14,"id":19924831}]}]}
{"op":"mcm","clk":"4219122466","pt":1631395322699,"mc":[{"id":"1.187528277","rc":[{"batb":[[0,1.4,3861.74]],"batl":[[0,1.41,11086.39]],"ltp":1.4,"tv":74876.74,"id":2249229}]}]}
{"op":"mcm","clk":"4219122522","pt":1631395323582,"mc":[{"id":"1.187528277","rc":[{"batb":[[0,3.4,1205.97],[1,3.35,641.61]],"batl":[[0,3.45,687.97]],"ltp":3.45,"tv":18583.14,"id":19924831},{"batb":[[0,1.4,3255.95]],"ltp":1.4,"tv":74876.74,"id":2249229}]}]}
{"op":"mcm","clk":"4219122562","pt":1631395324153,"mc":[{"id":"1.187528277","rc":[{"batl":[[1,3.5,290.49]],"ltp":3.45,"tv":18583.14,"id":19924831}]}]}
{"op":"mcm","clk":"4219126763","pt":1631395402021,"mc":[{"id":"1.187528277","rc":[{"batb":[[0,1.4,3405.95]],"ltp":1.4,"tv":74876.74,"id":2249229}]}]}
{"op":"mcm","clk":"4219126838","pt":1631395403732,"mc":[{"id":"1.187528277","rc":[{"batb":[[0,1.4,3255.95]],"ltp":1.4,"tv":74876.74,"id":2249229}]}]}
{"op":"mcm","clk":"4219127315","pt":1631395412407,"mc":[{"id":"1.187528277","rc":[{"batb":[[0,1.4,3505.95]],"ltp":1.4,"tv":74876.74,"id":2249229}]}]}
{"op":"mcm","clk":"4219128190","pt":1631395429378,"mc":[{"id":"1.187528277","rc":[{"trd":[[1.41,19124.05]],"batl":[[0,1.41,11043.69]],"ltp":1.41,"tv":74962.14,"id":2249229}],"tv":93545.29}]}
{"op":"mcm","clk":"4219129227","pt":1631395449991,"mc":[{"id":"1.187528277","rc":[{"batb":[[1,3.35,660.49]],"ltp":3.45,"tv":18583.14,"id":19924831}]}]}
{"op":"mcm","clk":"4219130347","pt":1631395471813,"mc":[{"id":"1.187528277","rc":[{"trd":[[1.4,9146.76]],"batb":[[0,1.4,3495.32]],"ltp":1.4,"tv":74983.41,"id":2249229}],"tv":93566.56}]}
{"op":"mcm","clk":"4219132354","pt":1631395508068,"mc":[{"id":"1.187528277","rc":[{"batb":[[0,1.4,4228.32]],"ltp":1.4,"tv":74983.41,"id":2249229}]}]}
{"op":"mcm","clk":"4219134337","pt":1631395544239,"mc":[{"id":"1.187528277","rc":[{"trd":[[3.45,1383.34]],"batl":[[0,3.45,684.88]],"ltp":3.45,"tv":18589.32,"id":19924831}],"tv":93572.74}]}
{"op":"mcm","clk":"4219135361","pt":1631395563770,"mc":[{"id":"1.187528277","rc":[{"batb":[[1,3.35,663.31]],"ltp":3.45,"tv":18589.32,"id":19924831}]}]}
{"op":"mcm","clk":"4219135947","pt":1631395575777,"mc":[{"id":"1.187528277","rc":[{"batb":[[0,1.4,4300.62]],"ltp":1.4,"tv":74983.41,"id":2249229}]}]}
{"op":"mcm","clk":"4219136750","pt":1631395591941,"mc":[{"id":"1.187528277","rc":[{"batb":[[0,1.4,4228.32]],"ltp":1.4,"tv":74983.41,"id":2249229}]}]}
{"op":"mcm","clk":"4219136940","pt":1631395596019,"mc":[{"id":"1.187528277","rc":[{"batb":[[0,1.4,10633.65]],"ltp":1.4,"tv":74983.41,"id":2249229}]}]}
{"op":"mcm","clk":"4219137922","pt":1631395615394,"mc":[{"id":"1.187528277","rc":[{"batl":[[0,3.45,737.05]],"ltp":3.45,"tv":18589.32,"id":19924831},{"batl":[[0,1.41,833.1],[1,1.42,10972.6]],"ltp":1.4,"tv":74983.41,"id":2249229}]}]}
{"op":"mcm","clk":"4219143459","pt":1631395692147,"mc":[{"id":"1.187528277","rc":[{"batl":[[0,1.41,748.22]],"ltp":1.4,"tv":74983.41,"id":2249229}]}]}
{"op":"mcm","clk":"4219143577","pt":1631395693427,"mc":[{"id":"1.187528277","rc":[{"batl":[[0,1.41,708.86]],"ltp":1.4,"tv":74983.41,"id":2249229}]}]}
{"op":"mcm","clk":"4219143631","pt":1631395693936,"mc":[{"id":"1.187528277","rc":[{"batb":[[1,3.35,938.46]],"ltp":3.45,"tv":18589.32,"id":19924831}]}]}
{"op":"mcm","clk":"4219153528","pt":1631395806516,"mc":[{"id":"1.187528277","rc":[{"batl":[[0,1.41,690.23]],"ltp":1.4,"tv":74983.41,"id":2249229}]}]}
{"op":"mcm","clk":"4219159381","pt":1631395878921,"mc":[{"id":"1.187528277","rc":[{"trd":[[1.41,19378.49]],"batl":[[0,1.41,5.22]],"ltp":1.41,"tv":75237.86,"id":2249229}],"tv":93827.18}]}
{"op":"mcm","clk":"4219160214","pt":1631395889935,"mc":[{"id":"1.187528277","rc":[{"trd":[[1.41,19388.93]],"batb":[[0,1.41,680.43],[1,1.4,10633.65],[2,1.39,8295.25]],"batl":[[0,1.42,11057.12],[1,1.43,800],[2,1.44,484.85]],"ltp":1.41,"tv":75248.3,"id":2249229}],"tv":93837.62}]}
{"op":"mcm","clk":"4219162454","pt":1631395921613,"mc":[{"id":"1.187528277","rc":[{"batb":[[2,1.39,7843.22]],"ltp":1.41,"tv":75248.3,"id":2249229}]}]}
{"op":"mcm","clk":"4219162888","pt":1631395928398,"mc":[{"id":"1.187528277","rc":[{"batb":[[1,1.4,10681.71]],"batl":[[1,1.43,1249.78]],"ltp":1.41,"tv":75248.3,"id":2249229}]}]}
{"op":"mcm","clk":"4219162955","pt":1631395929389,"mc":[{"id":"1.187528277","rc":[{"batb":[[0,3.4,1178.34],[1,3.35,914.75]],"ltp":3.45,"tv":18589.32,"id":19924831}]}]}
{"op":"mcm","clk":"4219163001","pt":1631395930217,"mc":[{"id":"1.187528277","rc":[{"batl":[[0,3.45,759.8],[1,3.5,312.78]],"ltp":3.45,"tv":18589.32,"id":19924831}]}]}
{"op":"mcm","clk":"4219171678","pt":1631396044183,"mc":[{"id":"1.187528277","rc":[{"batb":[[0,3.4,1173.97]],"ltp":3.45,"tv":18589.32,"id":19924831}]}]}
{"op":"mcm","clk":"4219172539","pt":1631396055606,"mc":[{"id":"1.187528277","rc":[{"trd":[[1.41,19391.69]],"batb":[[0,1.41,679.05]],"ltp":1.41,"tv":75251.06,"id":2249229}],"tv":93840.38}]}
{"op":"mcm","clk":"4219177158","pt":1631396116781,"mc":[{"id":"1.187528277","rc":[{"batb":[[0,1.41,688.65]],"ltp":1.41,"tv":75251.06,"id":2249229}]}]}
{"op":"mcm","clk":"4219179948","pt":1631396151764,"mc":[{"id":"1.187528277","rc":[{"batb":[[0,1.41,1421.65]],"ltp":1.41,"tv":75251.06,"id":2249229}]}]}
{"op":"mcm","clk":"4219180378","pt":1631396157482,"mc":[{"id":"1.187528277","rc":[{"batb":[[0,3.4,746.95]],"ltp":3.45,"tv":18589.32,"id":19924831}]}]}
{"op":"mcm","clk":"4219180456","pt":1631396158468,"mc":[{"id":"1.187528277","rc":[{"batb":[[1,3.35,487.72]],"ltp":3.45,"tv":18589.32,"id":19924831},{"batl":[[0,1.42,10972.6]],"ltp":1.41,"tv":75251.06,"id":2249229}]}]}
{"op":"mcm","clk":"4219181794","pt":1631396175611,"mc":[{"id":"1.187528277","rc":[{"batb":[[0,3.4,680.4]],"ltp":3.45,"tv":18589.32,"id":19924831},{"batl":[[1,1.43,1158.85]],"ltp":1.41,"tv":75251.06,"id":2249229}]}]}
{"op":"mcm","clk":"4219182202","pt":1631396181420,"mc":[{"id":"1.187528277","rc":[{"batb":[[1,1.4,10431.71]],"ltp":1.41,"tv":75251.06,"id":2249229}]}]}
{"op":"mcm","clk":"4219188594","pt":1631396274530,"mc":[{"id":"1.187528277","rc":[{"batl":[[2,3.6,38.15]],"ltp":3.45,"tv":18589.32,"id":19924831},{"batb":[[2,1.39,7721.94]],"batl":[[0,1.42,10895.73]],"ltp":1.41,"tv":75251.06,"id":2249229}]}]}
{"op":"mcm","clk":"4219188626","pt":1631396275048,"mc":[{"id":"1.187528277","rc":[{"batb":[[1,3.35,470.64]],"batl":[[1,3.5,346.95]],"ltp":3.45,"tv":18589.32,"id":19924831},{"batb":[[1,1.4,10516.26]],"batl":[[1,1.43,1244.26]],"ltp":1.41,"tv":75251.06,"id":2249229}]}]}
{"op":"mcm","clk":"4219189625","pt":1631396289055,"mc":[{"id":"1.187528277","rc":[{"batb":[[0,3.4,670.41]],"ltp":3.45,"tv":18589.32,"id":19924831}]}]}
{"op":"mcm","clk":"4219199015","pt":1631396423768,"mc":[{"id":"1.187528277","rc":[{"trd":[[1.42,19677.94]],"batl":[[0,1.42,10886.33]],"ltp":1.42,"tv":75269.85,"id":2249229}],"tv":93859.18}]}
{"op":"mcm","clk":"4219203292","pt":1631396482843,"mc":[{"id":"1.187528277","rc":[{"trd":[[1.42,19763.34]],"batl":[[0,1.42,10843.63]],"ltp":1.42,"tv":75355.25,"id":2249229}],"tv":93944.58}]}
{"op":"mcm","clk":"4219208525","pt":1631396559845,"mc":[{"id":"1.187528277","rc":[{"batl":[[2,1.44,618.85]],"ltp":1.42,"tv":75355.25,"id":2249229}]}]}
{"op":"mcm","clk":"4219217037","pt":1631396687638,"mc":[{"id":"1.187528277","rc":[{"trd":[[1.42,19829.96]],"batl":[[0,1.42,10810.32]],"ltp":1.42,"tv":75421.87,"id":2249229}],"tv":94011.2}]}
{"op":"mcm","clk":"4219217961","pt":1631396702661,"mc":[{"id":"1.187528277","rc":[{"batb":[[0,3.4,617.47]],"ltp":3.45,"tv":18589.32,"id":19924831},{"batb":[[0,1.41,5759.73]],"ltp":1.42,"tv":75421.87,"id":2249229}]}]}
{"op":"mcm","clk":"4219222916","pt":1631396758727,"mc":[{"id":"1.187528277","rc":[{"trd":[[3.4,2399.99]],"batb":[[0,3.4,517.47]],"ltp":3.4,"tv":18789.32,"id":19924831}],"tv":94211.2}]}
{"op":"mcm","clk":"4219224285","pt":1631396780393,"mc":[{"id":"1.187528277","rc":[{"batb":[[0,3.4,493.04]],"ltp":3.4,"tv":18789.32,"id":19924831}]}]}
{"op":"mcm","clk":"4219224867","pt":1631396789009,"mc":[{"id":"1.187528277","rc":[{"trd":[[3.4,2599.99]],"batb":[[0,3.4,393.04]],"ltp":3.4,"tv":18989.32,"id":19924831}],"tv":94411.2}]}
{"op":"mcm","clk":"4219225122","pt":1631396793093,"mc":[{"id":"1.187528277","rc":[{"batb":[[2,1.39,7342.75]],"ltp":1.42,"tv":75421.87,"id":2249229}]}]}
{"op":"mcm","clk":"4219225563","pt":1631396801425,"mc":[{"id":"1.187528277","rc":[{"batb":[[0,1.41,7205.76]],"ltp":1.42,"tv":75421.87,"id":2249229}]}]}
{"op":"mcm","clk":"4219241808","pt":1631396901439,"mc":[{"id":"1.187528277","rc":[{"batb":[[0,3.4,374.37]],"ltp":3.4,"tv":18989.32,"id":19924831}]}]}
{"op":"mcm","clk":"4219250744","pt":1631397053975,"mc":[{"id":"1.187528277","rc":[{"trd":[[1.42,19870.95]],"batl":[[0,1.42,10789.83]],"ltp":1.42,"tv":75462.86,"id":2249229}],"tv":94452.19}]}
{"op":"mcm","clk":"4219250943","pt":1631397057578,"mc":[{"id":"1.187528277","rc":[{"trd":[[1.41,19791.69]],"batb":[[0,1.41,7005.76]],"ltp":1.41,"tv":75862.86,"id":2249229}],"tv":94852.19}]}
{"op":"mcm","clk":"4219255657","pt":1631397127686,"mc":[{"id":"1.187528277","rc":[{"trd":[[1.42,20294.56]],"batl":[[0,1.42,10578.02]],"ltp":1.42,"tv":76286.47,"id":2249229}],"tv":95275.8}]}
{"op":"mcm","clk":"4219257457","pt":1631397155626,"mc":[{"id":"1.187528277","rc":[{"batb":[[1,3.35,425.22]],"ltp":3.4,"tv":18989.32,"id":19924831},{"batl":[[0,1.42,10790.73]],"ltp":1.42,"tv":76286.47,"id":2249229}]}]}
{"op":"mcm","clk":"4219257509","pt":1631397156403,"mc":[{"id":"1.187528277","rc":[{"batl":[[0,3.45,803.38],[1,3.5,389.64]],"ltp":3.4,"tv":18989.32,"id":19924831}]}]}
{"op":"mcm","clk":"4219257857","pt":1631397161614,"mc":[{"id":"1.187528277","rc":[{"trd":[[3.45,1388.7]],"batl":[[0,3.45,800.7]],"ltp":3.45,"tv":18994.69,"id":19924831}],"tv":95281.16}]}
{"op":"mcm","clk":"4219265216","pt":1631397281115,"mc":[{"id":"1.187528277","rc":[{"batl":[[1,1.43,1221.47]],"ltp":1.42,"tv":76286.47,"id":2249229}]}]}
{"op":"mcm","clk":"4219265534","pt":1631397286134,"mc":[{"id":"1.187528277","rc":[{"trd":[[1.41,19808.79]],"batb":[[0,1.41,6997.21]],"ltp":1.41,"tv":76303.57,"id":2249229}],"tv":95298.26}]}
{"op":"mcm","clk":"4219267767","pt":1631397326851,"mc":[{"id":"1.187528277","rc":[{"batb":[[1,1.4,14854.34]],"ltp":1.41,"tv":76303.57,"id":2249229}]}]}
{"op":"mcm","clk":"4219270987","pt":1631397380979,"mc":[{"id":"1.187528277","rc":[{"batl":[[2,3.6,2]],"ltp":3.45,"tv":18994.69,"id":19924831}]}]}
{"op":"mcm","clk":"4219272548","pt":1631397410245,"mc":[{"id":"1.187528277","rc":[{"batb":[[2,1.39,10234.08]],"ltp":1.41,"tv":76303.57,"id":2249229}]}]}
{"op":"mcm","clk":"4219274023","pt":1631397438364,"mc":[{"id":"1.187528277","rc":[{"trd":[[3.4,2727.62]],"batb":[[0,3.4,310.56]],"batl":[[1,3.5,325.83]],"ltp":3.4,"tv":19122.32,"id":19924831}],"tv":95425.89}]}
{"op":"mcm","clk":"4219278583","pt":1631397525709,"mc":[{"id":"1.187528277","rc":[{"batb":[[0,3.4,298.19]],"ltp":3.4,"tv":19122.32,"id":19924831}]}]}
{"op":"mcm","clk":"4219324468","pt":1631398291091,"mc":[{"id":"1.187528277","rc":[{"trd":[[3.4,2744.7]],"batb":[[0,3.4,289.65]],"ltp":3.4,"tv":19139.4,"id":19924831}],"tv":95442.97}]}
{"op":"mcm","clk":"4219326138","pt":1631398320344,"mc":[{"id":"1.187528277","rc":[{"trd":[[1.42,20354.56]],"batl":[[0,1.42,10760.73]],"ltp":1.42,"tv":76363.57,"id":2249229}],"tv":95502.97}]}
{"op":"mcm","clk":"4219327202","pt":1631398339081,"mc":[{"id":"1.187528277","rc":[{"trd":[[1.42,20397.94]],"batl":[[0,1.42,10739.04]],"ltp":1.42,"tv":76406.95,"id":2249229}],"tv":95546.35}]}
{"op":"mcm","clk":"4219328009","pt":1631398353018,"mc":[{"id":"1.187528277","rc":[{"batb":[[0,1.41,7720.22]],"ltp":1.42,"tv":76406.95,"id":2249229}]}]}
{"op":"mcm","clk":"4219329826","pt":1631398383762,"mc":[{"id":"1.187528277","rc":[{"trd":[[1.41,19908.79]],"batb":[[0,1.41,7670.22]],"ltp":1.41,"tv":76506.95,"id":2249229}],"tv":95646.35}]}
{"op":"mcm","clk":"4219329972","pt":1631398386589,"mc":[{"id":"1.187528277","rc":[{"trd":[[3.45,1395.26]],"batl":[[0,3.45,797.42]],"ltp":3.45,"tv":19145.96,"id":19924831},{"batl":[[0,1.42,10747.81]],"ltp":1.41,"tv":76506.95,"id":2249229}],"tv":95652.91}]}
{"op":"mcm","clk":"4219333750","pt":1631398447257,"mc":[{"id":"1.187528277","rc":[{"batb":[[1,3.35,432.05]],"batl":[[1,3.5,315.58]],"ltp":3.45,"tv":19145.96,"id":19924831},{"batb":[[1,1.4,14769.79],[2,1.39,10362.18]],"ltp":1.41,"tv":76506.95,"id":2249229}]}]}
{"op":"mcm","clk":"4219334953","pt":1631398469900,"mc":[{"id":"1.187528277","rc":[{"trd":[[3.45,1402.3]],"batl":[[0,3.45,793.9]],"ltp":3.45,"tv":19153.0,"id":19924831}],"tv":95659.96}]}
{"op":"mcm","clk":"4219335665","pt":1631398482020,"mc":[{"id":"1.187528277","rc":[{"trd":[[3.4,2944.7]],"batb":[[0,3.4,189.65]],"ltp":3.4,"tv":19353.0,"id":19924831}],"tv":95859.96}]}
{"op":"mcm","clk":"4219335864","pt":1631398485436,"mc":[{"id":"1.187528277","rc":[{"trd":[[1.42,20440.64]],"batl":[[0,1.42,10726.46]],"ltp":1.42,"tv":76549.66,"id":2249229}],"tv":95902.66}]}
{"op":"mcm","clk":"4219336612","pt":1631398499135,"mc":[{"id":"1.187528277","rc":[{"batl":[[2,1.44,484.85]],"ltp":1.42,"tv":76549.66,"id":2249229}]}]}
{"op":"mcm","clk":"4219336887","pt":1631398505165,"mc":[{"id":"1.187528277","rc":[{"trd":[[1.41,19948.79]],"batb":[[0,1.41,7650.22]],"ltp":1.41,"tv":76589.66,"id":2249229}],"tv":95942.66}]}
{"op":"mcm","clk":"4219336978","pt":1631398506669,"mc":[{"id":"1.187528277","rc":[{"batb":[[0,1.41,7977.05]],"ltp":1.41,"tv":76589.66,"id":2249229}]}]}
{"op":"mcm","clk":"4219337086","pt":1631398508539,"mc":[{"id":"1.187528277","rc":[{"trd":[[3.4,2956.7]],"batb":[[0,3.4,183.65]],"ltp":3.4,"tv":19365.0,"id":19924831}],"tv":95954.66}]}
{"op":"mcm","clk":"4219337577","pt":1631398518261,"mc":[{"id":"1.187528277","rc":[{"batb":[[1,3.35,407.05]],"ltp":3.4,"tv":19365.0,"id":19924831}]}]}
{"op":"mcm","clk":"4219337845","pt":1631398523472,"mc":[{"id":"1.187528277","rc":[{"trd":[[3.4,2996.7]],"batb":[[0,3.4,163.65]],"ltp":3.4,"tv":19405.0,"id":19924831}],"tv":95994.66}]}
{"op":"mcm","clk":"4219337999","pt":1631398526311,"mc":[{"id":"1.187528277","rc":[{"trd":[[1.41,19955.23]],"batb":[[0,1.41,7973.83]],"ltp":1.41,"tv":76596.1,"id":2249229}],"tv":96001.1}]}
{"op":"mcm","clk":"4219338030","pt":1631398526987,"mc":[{"id":"1.187528277","rc":[{"trd":[[1.41,19978.41]],"batb":[[0,1.41,7962.24]],"ltp":1.41,"tv":76619.28,"id":2249229}],"tv":96024.28}]}
{"op":"mcm","clk":"4219338493","pt":1631398535389,"mc":[{"id":"1.187528277","rc":[{"trd":[[1.41,20390.85]],"batb":[[0,1.41,7756.02]],"ltp":1.41,"tv":77031.72,"id":2249229}],"tv":96436.72}]}
{"op":"mcm","clk":"4219339197","pt":1631398547594,"mc":[{"id":"1.187528277","rc":[{"batb":[[0,3.4,141.61]],"ltp":3.4,"tv":19405.0,"id":19924831},{"batb":[[0,1.41,7856.02]],"ltp":1.41,"tv":77031.72,"id":2249229}]}]}
{"op":"mcm","clk":"4219339407","pt":1631398551020,"mc":[{"id":"1.187528277","rc":[{"trd":[[1.42,20744.31]],"batl":[[0,1.42,10574.62]],"ltp":1.42,"tv":77335.39,"id":2249229}],"tv":96740.39}]}
{"op":"mcm","clk":"4219340156","pt":1631398563296,"mc":[{"id":"1.187528277","rc":[{"batb":[[0,3.4,863.9]],"ltp":3.4,"tv":19405.0,"id":19924831}]}]}
{"op":"mcm","clk":"4219341106","pt":1631398579618,"mc":[{"id":"1.187528277","rc":[{"batb":[[0,1.41,8381.02]],"ltp":1.42,"tv":77335.39,"id":2249229}]}]}
{"op":"mcm","clk":"4219341267","pt":1631398582531,"mc":[{"id":"1.187528277","rc":[{"trd":[[3.4,3056.7]],"batb":[[0,3.4,833.9]],"ltp":3.4,"tv":19464.99,"id":19924831}],"tv":96800.39}]}
{"op":"mcm","clk":"4219343321","pt":1631398621473,"mc":[{"id":"1.187528277","rc":[{"trd":[[3.4,3073.62]],"batb":[[0,3.4,825.44]],"ltp":3.4,"tv":19481.91,"id":19924831}],"tv":96817.31}]}
{"op":"mcm","clk":"4219343917","pt":1631398632992,"mc":[{"id":"1.187528277","rc":[{"trd":[[3.4,4660.65]],"batb":[[0,3.4,31.93]],"ltp":3.4,"tv":21068.95,"id":19924831}],"tv":98404.34}]}
{"op":"mcm","clk":"4219344687","pt":1631398646015,"mc":[{"id":"1.187528277","rc":[{"trd":[[1.41,21842.72]],"batb":[[0,1.41,7655.09]],"ltp":1.41,"tv":78787.26,"id":2249229}],"tv":99856.21}]}
{"op":"mcm","clk":"4219345528","pt":1631398662624,"mc":[{"id":"1.187528277","rc":[{"trd":[[1.41,22165.66]],"batb":[[0,1.41,7493.62]],"ltp":1.41,"tv":79110.2,"id":2249229}],"tv":100179.15}]}
{"op":"mcm","clk":"4219346490","pt":1631398682175,"mc":[{"id":"1.187528277","rc":[{"batb":[[0,1.41,9983.7]],"ltp":1.41,"tv":79110.2,"id":2249229}]}]}
{"op":"mcm","clk":"4219346831","pt":1631398687998,"mc":[{"id":"1.187528277","rc":[{"batb":[[0,3.4,915.45]],"ltp":3.4,"tv":21068.95,"id":19924831}]}]}
{"op":"mcm","clk":"4219347038","pt":1631398691582,"mc":[{"id":"1.187528277","rc":[{"batb":[[1,1.4,14902.17]],"batl":[[1,1.43,1353.84]],"ltp":1.41,"tv":79110.2,"id":2249229}]}]}
{"op":"mcm","clk":"4219347695","pt":1631398704798,"mc":[{"id":"1.187528277","rc":[{"trd":[[3.4,4689.69]],"batb":[[0,3.4,900.93]],"ltp":3.4,"tv":21097.98,"id":19924831}],"tv":100208.19}]}
{"op":"mcm","clk":"4219348551","pt":1631398721637,"mc":[{"id":"1.187528277","rc":[{"batb":[[0,1.41,10019.64]],"ltp":1.41,"tv":79110.2,"id":2249229}]}]}
{"op":"mcm","clk":"4219348578","pt":1631398722312,"mc":[{"id":"1.187528277","rc":[{"batl":[[0,1.42,10662.62],[1,1.43,1363.89]],"ltp":1.41,"tv":79110.2,"id":2249229}]}]}
{"op":"mcm","clk":"4219348644","pt":1631398723404,"mc":[{"id":"1.187528277","rc":[{"batb":[[0,3.4,1011.29],[1,3.35,373.84]],"batl":[[0,3.45,825.76]],"ltp":3.4,"tv":21097.98,"id":19924831}]}]}
{"op":"mcm","clk":"4219348674","pt":1631398723817,"mc":[{"id":"1.187528277","rc":[{"batl":[[1,3.5,346.81]],"ltp":3.4,"tv":21097.98,"id":19924831}]}]}
{"op":"mcm","clk":"4219349013","pt":1631398729826,"mc":[{"id":"1.187528277","rc":[{"batl":[[0,1.42,13215.27]],"ltp":1.41,"tv":79110.2,"id":2249229}]}]}
{"op":"mcm","clk":"4219349871","pt":1631398747656,"mc":[{"id":"1.187528277","rc":[{"batb":[[0,1.41,11727.73]],"ltp":1.41,"tv":79110.2,"id":2249229}]}]}
{"op":"mcm","clk":"4219350256","pt":1631398755355,"mc":[{"id":"1.187528277","rc":[{"trd":[[3.4,4809.25]],"batb":[[0,3.4,951.51]],"ltp":3.4,"tv":21217.55,"id":19924831}],"tv":100327.75}]}
{"op":"mcm","clk":"4219350381","pt":1631398757987,"mc":[{"id":"1.187528277","rc":[{"trd":[[3.4,5387.66]],"batb":[[0,3.4,662.31]],"ltp":3.4,"tv":21795.96,"id":19924831}],"tv":100906.16}]}
{"op":"mcm","clk":"4219351927","pt":1631398787829,"mc":[{"id":"1.187528277","rc":[{"batl":[[0,3.45,1025.76]],"ltp":3.4,"tv":21795.96,"id":19924831}]}]}
{"op":"mcm","clk":"4219357119","pt":1631398890884,"mc":[{"id":"1.187528277","rc":[{"trd":[[1.42,20812.32]],"batl":[[0,1.42,13181.27]],"ltp":1.42,"tv":79178.2,"id":2249229}],"tv":100974.16}]}
{"op":"mcm","clk":"4219359374","pt":1631398937011,"mc":[{"id":"1.187528277","rc":[{"trd":[[3.4,6712.27]],"batb":[[0,3.35,373.84],[1,3.3,20],[2,3.25,6]],"batl":[[0,3.4,2137.7],[1,3.45,1025.76],[2,3.5,346.81]],"ltp":3.4,"tv":23120.57,"id":19924831},{"batb":[[0,1.41,11855.38]],"ltp":1.42,"tv":79178.2,"id":2249229}],"tv":102298.77}]}
{"op":"mcm","clk":"4219359482","pt":1631398939702,"mc":[{"id":"1.187528277","rc":[{"batl":[[0,3.45,1025.76],[1,3.5,346.81],[2,3.6,2]],"ltp":3.4,"tv":23120.57,"id":19924831}]}]}
{"op":"mcm","clk":"4219359509","pt":1631398940116,"mc":[{"id":"1.187528277","rc":[{"batl":[[0,3.45,3163.46]],"ltp":3.4,"tv":23120.57,"id":19924831}]}]}
{"op":"mcm","clk":"4219360995","pt":1631398968175,"mc":[{"id":"1.187528277","rc":[{"batb":[[0,1.41,11996.88]],"ltp":1.42,"tv":79178.2,"id":2249229}]}]}
{"op":"mcm","clk":"4219361061","pt":1631398969301,"mc":[{"id":"1.187528277","rc":[{"batb":[[1,3.3,111.65]],"ltp":3.4,"tv":23120.57,"id":19924831}]}]}
{"op":"mcm","clk":"4219361149","pt":1631398970706,"mc":[{"id":"1.187528277","rc":[{"batb":[[0,3.35,308.41]],"batl":[[0,3.45,3226.21],[1,3.5,408.3]],"ltp":3.4,"tv":23120.57,"id":19924831}]}]}
{"op":"mcm","clk":"4219361321","pt":1631398973508,"mc":[{"id":"1.187528277","rc":[{"batl":[[0,3.4,5],[1,3.45,3226.21],[2,3.5,408.3]],"ltp":3.4,"tv":23120.57,"id":19924831}]}]}
{"op":"mcm","clk":"4219365025","pt":1631399046998,"mc":[{"id":"1.187528277","rc":[{"trd":[[3.35,3356.88]],"batb":[[0,3.35,303.42]],"ltp":3.35,"tv":23130.56,"id":19924831}],"tv":102308.77}]}
{"op":"mcm","clk":"4219365073","pt":1631399048083,"mc":[{"id":"1.187528277","rc":[{"batb":[[0,1.41,12007.5],[2,1.39,10338.99]],"ltp":1.42,"tv":79178.2,"id":2249229}]}]}
{"op":"mcm","clk":"4219365726","pt":1631399062614,"mc":[{"id":"1.187528277","rc":[{"batb":[[0,1.41,12012.5]],"ltp":1.42,"tv":79178.2,"id":2249229}]}]}
{"op":"mcm","clk":"4219366172","pt":1631399071928,"mc":[{"id":"1.187528277","rc":[{"batb":[[0,1.41,12017.5]],"ltp":1.42,"tv":79178.2,"id":2249229}]}]}
{"op":"mcm","clk":"4219366429","pt":1631399077030,"mc":[{"id":"1.187528277","rc":[{"batl":[[0,1.42,15681.27]],"ltp":1.42,"tv":79178.2,"id":2249229}]}]}
{"op":"mcm","clk":"4219367145","pt":1631399090998,"mc":[{"id":"1.187528277","rc":[{"trd":[[1.41,22465.66]],"batb":[[0,1.41,11867.5]],"ltp":1.41,"tv":79478.2,"id":2249229}],"tv":102608.77}]}
{"op":"mcm","clk":"4219367426","pt":1631399096612,"mc":[{"id":"1.187528277","rc":[{"batl":[[2,3.5,346.81]],"ltp":3.35,"tv":23130.56,"id":19924831}]}]}
{"op":"mcm","clk":"4219367443","pt":1631399096921,"mc":[{"id":"1.187528277","rc":[{"batl":[[2,3.5,310.86]],"ltp":3.35,"tv":23130.56,"id":19924831}]}]}
{"op":"mcm","clk":"4219367513","pt":1631399098486,"mc":[{"id":"1.187528277","rc":[{"batl":[[2,3.5,274]],"ltp":3.35,"tv":23130.56,"id":19924831}]}]}
{"op":"mcm","clk":"4219367545","pt":1631399099214,"mc":[{"id":"1.187528277","rc":[{"batl":[[2,3.5,151.9]],"ltp":3.35,"tv":23130.56,"id":19924831}]}]}
{"op":"mcm","clk":"4219367597","pt":1631399100393,"mc":[{"id":"1.187528277","rc":[{"batl":[[2,3.5,106.21]],"ltp":3.35,"tv":23130.56,"id":19924831}]}]}
{"op":"mcm","clk":"4219367668","pt":1631399101689,"mc":[{"id":"1.187528277","rc":[{"batl":[[2,3.5,75.26]],"ltp":3.35,"tv":23130.56,"id":19924831}]}]}
{"op":"mcm","clk":"4219367789","pt":1631399103616,"mc":[{"id":"1.187528277","rc":[{"trd":[[3.4,6722.27]],"batb":[[0,3.4,75.25],[1,3.35,303.42],[2,3.3,111.65]],"batl":[[0,3.45,3226.21],[1,3.5,52.76],[2,3.6,2]],"ltp":3.4,"tv":23140.56,"id":19924831}],"tv":102618.77}]}
{"op":"mcm","clk":"4219367828","pt":1631399104129,"mc":[{"id":"1.187528277","rc":[{"batl":[[1,3.5,23.91]],"ltp":3.4,"tv":23140.56,"id":19924831}]}]}
{"op":"mcm","clk":"4219368152","pt":1631399110612,"mc":[{"id":"1.187528277","rc":[{"batl":[[1,1.43,1328.99]],"ltp":1.41,"tv":79478.2,"id":2249229}]}]}
{"op":"mcm","clk":"4219368169","pt":1631399111025,"mc":[{"id":"1.187528277","rc":[{"batb":[[2,3.3,125.4]],"ltp":3.4,"tv":23140.56,"id":19924831}]}]}
{"op":"mcm","clk":"4219369213","pt":1631399128532,"mc":[{"id":"1.187528277","rc":[{"batl":[[1,1.43,1466.37]],"ltp":1.41,"tv":79478.2,"id":2249229}]}]}
{"op":"mcm","clk":"4219370299","pt":1631399149079,"mc":[{"id":"1.187528277","rc":[{"trd":[[1.41,22679.54]],"batb":[[0,1.41,11760.56]],"ltp":1.41,"tv":79692.08,"id":2249229}],"tv":102832.65}]}
{"op":"mcm","clk":"4219372844","pt":1631399198544,"mc":[{"id":"1.187528277","rc":[{"trd":[[3.4,6762.27]],"batb":[[0,3.4,55.25],[2,3.3,20]],"ltp":3.4,"tv":23180.56,"id":19924831}],"tv":102872.65}]}
{"op":"mcm","clk":"4219373027","pt":1631399201673,"mc":[{"id":"1.187528277","rc":[{"batb":[[0,1.41,11770.47]],"batl":[[0,1.42,15661.7]],"ltp":1.41,"tv":79692.08,"id":2249229}]}]}
{"op":"mcm","clk":"4219373076","pt":1631399202557,"mc":[{"id":"1.187528277","rc":[{"batb":[[0,3.4,66.54]],"ltp":3.4,"tv":23180.56,"id":19924831},{"batl":[[1,1.43,1481.74]],"ltp":1.41,"tv":79692.08,"id":2249229}]}]}
{"op":"mcm","clk":"4219373091","pt":1631399202863,"mc":[{"id":"1.187528277","rc":[{"batl":[[1,3.5,406.68]],"ltp":3.4,"tv":23180.56,"id":19924831}]}]}
{"op":"mcm","clk":"4219375404","pt":1631399249323,"mc":[{"id":"1.187528277","rc":[{"batb":[[0,3.4,788.83]],"ltp":3.4,"tv":23180.56,"id":19924831}]}]}
{"op":"mcm","clk":"4219378735","pt":1631399307937,"mc":[{"id":"1.187528277","rc":[{"batb":[[0,3.4,825.54]],"ltp":3.4,"tv":23180.56,"id":19924831}]}]}
{"op":"mcm","clk":"4219388298","pt":1631399491975,"mc":[{"id":"1.187528277","rc":[{"trd":[[1.41,22847.02]],"batb":[[0,1.41,11686.73]],"ltp":1.41,"tv":79859.56,"id":2249229}],"tv":103040.13}]}
{"op":"mcm","clk":"4219394517","pt":1631399618298,"mc":[{"id":"1.187528277","rc":[{"trd":[[1.41,23049.46]],"batb":[[0,1.41,11585.5]],"ltp":1.41,"tv":80062.0,"id":2249229}],"tv":103242.57}]}
{"op":"mcm","clk":"4219398338","pt":1631399698575,"mc":[{"id":"1.187528277","rc":[{"trd":[[3.4,6789.72]],"batb":[[0,3.4,811.82]],"ltp":3.4,"tv":23208.01,"id":19924831}],"tv":103270.02}]}
{"op":"mcm","clk":"4219399074","pt":1631399712705,"mc":[{"id":"1.187528277","rc":[{"trd":[[1.42,20822.95]],"batl":[[0,1.42,15656.38]],"ltp":1.42,"tv":80072.64,"id":2249229}],"tv":103280.65}]}
{"op":"mcm","clk":"4219399588","pt":1631399722910,"mc":[{"id":"1.187528277","rc":[{"batb":[[0,1.41,11588.21]],"ltp":1.42,"tv":80072.64,"id":2249229}]}]}
{"op":"mcm","clk":"4219401013","pt":1631399756537,"mc":[{"id":"1.187528277","rc":[{"batl":[[0,1.42,15686.38]],"ltp":1.42,"tv":80072.64,"id":2249229}]}]}
{"op":"mcm","clk":"4219401092","pt":1631399758026,"mc":[{"id":"1.187528277","rc":[{"batl":[[1,1.43,1511.74]],"ltp":1.42,"tv":80072.64,"id":2249229}]}]}
{"op":"mcm","clk":"4219401144","pt":1631399759361,"mc":[{"id":"1.187528277","rc":[{"batl":[[2,1.44,514.85]],"ltp":1.42,"tv":80072.64,"id":2249229}]}]}
{"op":"mcm","clk":"4219401256","pt":1631399762145,"mc":[{"id":"1.187528277","rc":[{"trd":[[1.41,23077.46]],"batb":[[0,1.41,11574.21]],"ltp":1.41,"tv":80100.64,"id":2249229}],"tv":103308.65}]}
{"op":"mcm","clk":"4219401428","pt":1631399766159,"mc":[{"id":"1.187528277","rc":[{"batb":[[0,1.41,11604.21]],"ltp":1.41,"tv":80100.64,"id":2249229}]}]}
{"op":"mcm","clk":"4219401503","pt":1631399767658,"mc":[{"id":"1.187528277","rc":[{"batb":[[1,1.4,14932.17]],"ltp":1.41,"tv":80100.64,"id":2249229}]}]}
{"op":"mcm","clk":"4219401593","pt":1631399769669,"mc":[{"id":"1.187528277","rc":[{"trd":[[1.41,24377.46]],"batb":[[0,1.41,10954.2],[2,1.39,10368.99]],"ltp":1.41,"tv":81400.64,"id":2249229}],"tv":104608.65}]}
{"op":"mcm","clk":"4219402343","pt":1631399786672,"mc":[{"id":"1.187528277","rc":[{"trd":[[1.41,24382.95]],"batb":[[0,1.41,10951.46]],"ltp":1.41,"tv":81406.12,"id":2249229}],"tv":104614.14}]}
{"op":"mcm","clk":"4219403381","pt":1631399807244,"mc":[{"id":"1.187528277","rc":[{"trd":[[1.41,24694.94]],"batb":[[0,1.41,10795.47]],"ltp":1.41,"tv":81718.12,"id":2249229}],"tv":104926.13}]}
{"op":"mcm","clk":"4219404167","pt":1631399825051,"mc":[{"id":"1.187528277","rc":[{"batl":[[0,1.42,15689.07],[1,1.43,1518.55]],"ltp":1.41,"tv":81718.12,"id":2249229}]}]}
{"op":"mcm","clk":"4219405844","pt":1631399865003,"mc":[{"id":"1.187528277","rc":[{"trd":[[1.42,21001.97]],"batl":[[0,1.42,15599.56]],"ltp":1.42,"tv":81897.13,"id":2249229}],"tv":105105.14}]}
{"op":"mcm","clk":"4219406873","pt":1631399895554,"mc":[{"id":"1.187528277","rc":[{"trd":[[3.4,6863.22]],"batb":[[0,3.4,775.06]],"ltp":3.4,"tv":23281.51,"id":19924831}],"tv":105178.65}]}
{"op":"mcm","clk":"4219407203","pt":1631399904587,"mc":[{"id":"1.187528277","rc":[{"batb":[[1,3.35,284.9]],"ltp":3.4,"tv":23281.51,"id":19924831},{"batb":[[0,1.41,10840.9]],"batl":[[0,1.42,15644.71]],"ltp":1.42,"tv":81897.13,"id":2249229}]}]}
{"op":"mcm","clk":"4219407241","pt":1631399905459,"mc":[{"id":"1.187528277","rc":[{"batb":[[0,3.4,755.23]],"batl":[[0,3.45,3243.98]],"ltp":3.4,"tv":23281.51,"id":19924831}]}]}
{"op":"mcm","clk":"4219407253","pt":1631399905870,"mc":[{"id":"1.187528277","rc":[{"batl":[[1,3.5,425.72]],"ltp":3.4,"tv":23281.51,"id":19924831}]}]}
{"op":"mcm","clk":"4219408285","pt":1631399933705,"mc":[{"id":"1.187528277","rc":[{"trd":[[1.41,24706.51]],"batb":[[0,1.41,10835.12]],"ltp":1.41,"tv":81908.7,"id":2249229}],"tv":105190.21}]}
{"op":"mcm","clk":"4219409854","pt":1631399978468,"mc":[{"id":"1.187528277","rc":[{"trd":[[3.4,7717.27]],"batb":[[0,3.4,528.21]],"ltp":3.4,"tv":24135.56,"id":19924831},{"batb":[[0,1.41,11317.12]],"ltp":1.41,"tv":81908.7,"id":2249229}],"tv":106044.26}]}
{"op":"mcm","clk":"4219409950","pt":1631399981411,"mc":[{"id":"1.187528277","rc":[{"trd":[[1.41,24816.51]],"batb":[[0,1.41,11262.12]],"ltp":1.41,"tv":82018.7,"id":2249229}],"tv":106154.26}]}
{"op":"mcm","clk":"4219410333","pt":1631399992013,"mc":[{"id":"1.187528277","rc":[{"trd":[[1.41,24856.51]],"batb":[[0,1.41,11242.12]],"ltp":1.41,"tv":82058.7,"id":2249229}],"tv":106194.26}]}
{"op":"mcm","clk":"4219410436","pt":1631399994399,"mc":[{"id":"1.187528277","rc":[{"trd":[[1.41,24866.51]],"batb":[[0,1.41,11250.83]],"batl":[[0,1.42,15631.32]],"ltp":1.41,"tv":82068.7,"id":2249229}],"tv":106204.26}]}
{"op":"mcm","clk":"4219410466","pt":1631399995632,"mc":[{"id":"1.187528277","rc":[{"batb":[[0,3.4,533.84],[1,3.35,279.13]],"ltp":3.4,"tv":24135.56,"id":19924831}]}]}
{"op":"mcm","clk":"4219410506","pt":1631399996716,"mc":[{"id":"1.187528277","rc":[{"batl":[[0,3.45,3249.52],[1,3.5,431.14]],"ltp":3.4,"tv":24135.56,"id":19924831},{"trd":[[1.41,24870.51]],"batb":[[0,1.41,11248.83]],"ltp":1.41,"tv":82072.7,"id":2249229}],"tv":106208.26}]}
{"op":"mcm","clk":"4219411797","pt":1631400026046,"mc":[{"id":"1.187528277","rc":[{"trd":[[3.4,8037.27]],"batb":[[0,3.4,373.84]],"ltp":3.4,"tv":24455.56,"id":19924831}],"tv":106528.27}]}
{"op":"mcm","clk":"4219412809","pt":1631400049166,"mc":[{"id":"1.187528277","rc":[{"trd":[[3.4,8117.27]],"batb":[[0,3.4,333.84]],"ltp":3.4,"tv":24535.56,"id":19924831}],"tv":106608.26}]}
{"op":"mcm","clk":"4219413278","pt":1631400060398,"mc":[{"id":"1.187528277","rc":[{"trd":[[1.41,25870.51]],"batb":[[0,1.41,10748.83]],"ltp":1.41,"tv":83072.7,"id":2249229}],"tv":107608.26}]}
{"op":"mcm","clk":"4219414642","pt":1631400089240,"mc":[{"id":"1.187528277","rc":[{"trd":[[3.4,8715.26]],"batb":[[0,3.4,34.84]],"ltp":3.4,"tv":25133.56,"id":19924831}],"tv":108206.26}]}
{"op":"mcm","clk":"4219415089","pt":1631400100662,"mc":[{"id":"1.187528277","rc":[{"batb":[[1,3.35,270.49]],"ltp":3.4,"tv":25133.56,"id":19924831},{"batb":[[0,1.41,10769.35]],"batl":[[0,1.42,15611.29]],"ltp":1.41,"tv":83072.7,"id":2249229}]}]}
{"op":"mcm","clk":"4219415131","pt":1631400101446,"mc":[{"id":"1.187528277","rc":[{"batl":[[0,3.45,3257.8],[1,3.5,439.26]],"ltp":3.4,"tv":25133.56,"id":19924831}]}]}
{"op":"mcm","clk":"4219415346","pt":1631400106409,"mc":[{"id":"1.187528277","rc":[{"trd":[[1.41,25910.51]],"batb":[[0,1.41,10749.35]],"ltp":1.41,"tv":83112.7,"id":2249229}],"tv":108246.26}]}
{"op":"mcm","clk":"4219416019","pt":1631400122751,"mc":[{"id":"1.187528277","rc":[{"batl":[[2,1.44,2306.48]],"ltp":1.41,"tv":83112.7,"id":2249229}]}]}
{"op":"mcm","clk":"4219416296","pt":1631400128450,"mc":[{"id":"1.187528277","rc":[{"trd":[[3.4,8784.95]],"batb":[[0,3.35,270.49],[1,3.3,20],[2,3.25,6]],"batl":[[0,3.4,516.24],[1,3.45,3257.8],[2,3.5,439.26]],"ltp":3.4,"tv":25203.24,"id":19924831}],"tv":108315.95}]}
{"op":"mcm","clk":"4219416759","pt":1631400138339,"mc":[{"id":"1.187528277","rc":[{"batb":[[0,1.41,15873.61]],"ltp":1.41,"tv":83112.7,"id":2249229}]}]}
{"op":"mcm","clk":"4219416810","pt":1631400139475,"mc":[{"id":"1.187528277","rc":[{"batl":[[0,3.4,546.24]],"ltp":3.4,"tv":25203.24,"id":19924831},{"trd":[[1.41,25950.51]],"batb":[[0,1.41,16576.63]],"ltp":1.41,"tv":83152.7,"id":2249229}],"tv":108355.94}]}
{"op":"mcm","clk":"4219416942","pt":1631400142267,"mc":[{"id":"1.187528277","rc":[{"batl":[[0,3.4,566.24]],"ltp":3.4,"tv":25203.24,"id":19924831}]}]}
{"op":"mcm","clk":"4219417025","pt":1631400144277,"mc":[{"id":"1.187528277","rc":[{"batl":[[0,3.4,575.24]],"ltp":3.4,"tv":25203.24,"id":19924831}]}]}
{"op":"mcm","clk":"4219417104","pt":1631400146337,"mc":[{"id":"1.187528277","rc":[{"batl":[[0,3.4,555.24]],"ltp":3.4,"tv":25203.24,"id":19924831}]}]}
{"op":"mcm","clk":"4219417617","pt":1631400157396,"mc":[{"id":"1.187528277","rc":[{"trd":[[3.35,3376.88]],"batb":[[0,3.35,260.5]],"ltp":3.35,"tv":25223.24,"id":19924831},{"batb":[[0,1.41,17661.15]],"ltp":1.41,"tv":83152.7,"id":2249229}],"tv":108375.94}]}
{"op":"mcm","clk":"4219417636","pt":1631400157907,"mc":[{"id":"1.187528277","rc":[{"batb":[[1,3.3,32.37]],"ltp":3.35,"tv":25223.24,"id":19924831},{"batb":[[0,1.41,17672.51]],"ltp":1.41,"tv":83152.7,"id":2249229}]}]}
{"op":"mcm","clk":"4219418588","pt":1631400178701,"mc":[{"id":"1.187528277","rc":[{"batl":[[2,3.5,412.11]],"ltp":3.35,"tv":25223.24,"id":19924831}]}]}
{"op":"mcm","clk":"4219418608","pt":1631400179416,"mc":[{"id":"1.187528277","rc":[{"batl":[[2,3.5,29.34]],"ltp":3.35,"tv":25223.24,"id":19924831}]}]}
{"op":"mcm","clk":"4219418629","pt":1631400180093,"mc":[{"id":"1.187528277","rc":[{"batl":[[2,3.5,23.91]],"ltp":3.35,"tv":25223.24,"id":19924831}]}]}
{"op":"mcm","clk":"4219418701","pt":1631400182532,"mc":[{"id":"1.187528277","rc":[{"batb":[[1,3.3,135.93]],"ltp":3.35,"tv":25223.24,"id":19924831},{"batl":[[1,1.43,1511.74]],"ltp":1.41,"tv":83152.7,"id":2249229}]}]}
{"op":"mcm","clk":"4219418713","pt":1631400182794,"mc":[{"id":"1.187528277","rc":[{"batl":[[1,3.45,3262.06]],"ltp":3.35,"tv":25223.24,"id":19924831}]}]}
{"op":"mcm","clk":"4219419447","pt":1631400200827,"mc":[{"id":"1.187528277","rc":[{"trd":[[1.42,21010.23]],"batl":[[0,1.42,15607.16]],"ltp":1.42,"tv":83160.96,"id":2249229}],"tv":108384.21}]}
{"op":"mcm","clk":"4219419569","pt":1631400204343,"mc":[{"id":"1.187528277","rc":[{"trd":[[3.4,8901.4]],"batb":[[0,3.35,314.23]],"batl":[[0,3.4,497.02]],"ltp":3.4,"tv":25339.69,"id":19924831}],"tv":108500.66}]}
{"op":"mcm","clk":"4219419894","pt":1631400212551,"mc":[{"id":"1.187528277","rc":[{"trd":[[3.4,8904.85]],"batl":[[0,3.4,495.29]],"ltp":3.4,"tv":25343.14,"id":19924831}],"tv":108504.11}]}
{"op":"mcm","clk":"4219420357","pt":1631400223236,"mc":[{"id":"1.187528277","rc":[{"trd":[[1.42,21017.94]],"batl":[[0,1.42,15603.3]],"ltp":1.42,"tv":83168.68,"id":2249229}],"tv":108511.82}]}
{"op":"mcm","clk":"4219421058","pt":1631400240940,"mc":[{"id":"1.187528277","rc":[{"trd":[[1.41,26450.52]],"batb":[[0,1.41,17422.5]],"ltp":1.41,"tv":83668.68,"id":2249229}],"tv":109011.83}]}
{"op":"mcm","clk":"4219421947","pt":1631400260525,"mc":[{"id":"1.187528277","rc":[{"batb":[[1,3.3,151.02]],"ltp":3.4,"tv":25343.14,"id":19924831},{"batl":[[0,1.42,15609.36],[1,1.43,1522.34]],"ltp":1.41,"tv":83668.68,"id":2249229}]}]}
{"op":"mcm","clk":"4219421987","pt":1631400261512,"mc":[{"id":"1.187528277","rc":[{"batb":[[0,3.35,308.08]],"batl":[[0,3.4,499.43]],"ltp":3.4,"tv":25343.14,"id":19924831}]}]}
{"op":"mcm","clk":"4219423227","pt":1631400290693,"mc":[{"id":"1.187528277","rc":[{"trd":[[3.35,4141.25]],"batb":[[0,3.35,35.82]],"batl":[[0,3.4,43.13]],"ltp":3.35,"tv":26107.51,"id":19924831},{"trd":[[1.42,21367.64]],"batl":[[0,1.42,15259.66]],"ltp":1.42,"tv":84018.38,"id":2249229}],"tv":110125.9}]}
{"op":"mcm","clk":"4219424008","pt":1631400309513,"mc":[{"id":"1.187528277","rc":[{"batb":[[0,3.35,913.56]],"ltp":3.35,"tv":26107.51,"id":19924831}]}]}
{"op":"mcm","clk":"4219424369","pt":1631400318059,"mc":[{"id":"1.187528277","rc":[{"trd":[[1.41,26524.51]],"batb":[[0,1.41,17385.51]],"ltp":1.41,"tv":84092.38,"id":2249229}],"tv":110199.89}]}
{"op":"mcm","clk":"4219424429","pt":1631400320643,"mc":[{"id":"1.187528277","rc":[{"batb":[[1,3.3,194.57]],"batl":[[2,3.5,42.7]],"ltp":3.35,"tv":26107.51,"id":19924831},{"batb":[[1,1.4,15062.84],[2,1.39,10240.88]],"batl":[[1,1.43,1436.94],[2,1.44,2424.33]],"ltp":1.41,"tv":84092.38,"id":2249229}]}]}
{"op":"mcm","clk":"4219424772","pt":1631400329153,"mc":[{"id":"1.187528277","rc":[{"trd":[[1.41,28524.51]],"batb":[[0,1.41,16385.51]],"ltp":1.41,"tv":86092.38,"id":2249229}],"tv":112199.89}]}
{"op":"mcm","clk":"4219425201","pt":1631400341259,"mc":[{"id":"1.187528277","rc":[{"batb":[[0,1.41,16651.6]],"batl":[[0,1.42,15253.61]],"ltp":1.41,"tv":86092.38,"id":2249229}]}]}
{"op":"mcm","clk":"4219425250","pt":1631400342454,"mc":[{"id":"1.187528277","rc":[{"batl":[[0,1.42,15239.19]],"ltp":1.41,"tv":86092.38,"id":2249229}]}]}
{"op":"mcm","clk":"4219425292","pt":1631400343691,"mc":[{"id":"1.187528277","rc":[{"batl":[[0,1.42,15161.98]],"ltp":1.41,"tv":86092.38,"id":2249229}]}]}
{"op":"mcm","clk":"4219425321","pt":1631400344569,"mc":[{"id":"1.187528277","rc":[{"batl":[[0,1.42,15007.56],[1,1.43,1551.79]],"ltp":1.41,"tv":86092.38,"id":2249229}]}]}
{"op":"mcm","clk":"4219425355","pt":1631400345593,"mc":[{"id":"1.187528277","rc":[{"batb":[[0,3.35,1019.9],[1,3.3,198.51]],"batl":[[1,3.45,3368.7]],"ltp":3.35,"tv":26107.51,"id":19924831}]}]}
{"op":"mcm","clk":"4219425800","pt":1631400357478,"mc":[{"id":"1.187528277","rc":[{"batl":[[2,1.44,3741.67]],"ltp":1.41,"tv":86092.38,"id":2249229}]}]}
{"op":"mcm","clk":"4219425868","pt":1631400359393,"mc":[{"id":"1.187528277","rc":[{"trd":[[3.4,8909.97]],"batl":[[0,3.4,40.57]],"ltp":3.4,"tv":26112.63,"id":19924831}],"tv":112205.01}]}
{"op":"mcm","clk":"4219426637","pt":1631400382107,"mc":[{"id":"1.187528277","rc":[{"trd":[[1.41,28898.51]],"batb":[[0,1.41,16464.6]],"ltp":1.41,"tv":86466.38,"id":2249229}],"tv":112579.02}]}
{"op":"mcm","clk":"4219427872","pt":1631400415184,"mc":[{"id":"1.187528277","rc":[{"trd":[[1.41,33398.51]],"batb":[[0,1.41,14214.6]],"ltp":1.41,"tv":90966.37,"id":2249229}],"tv":117079.01}]}
{"op":"mcm","clk":"4219428021","pt":1631400418685,"mc":[{"id":"1.187528277","rc":[{"batb":[[1,3.3,206.57]],"ltp":3.4,"tv":26112.63,"id":19924831}]}]}
{"op":"mcm","clk":"4219428547","pt":1631400433722,"mc":[{"id":"1.187528277","rc":[{"batl":[[2,1.44,6288.12]],"ltp":1.41,"tv":90966.37,"id":2249229}]}]}
{"op":"mcm","clk":"4219428988","pt":1631400450005,"mc":[{"id":"1.187528277","rc":[{"batb":[[0,1.41,9090.34],[2,1.39,15365.14]],"ltp":1.41,"tv":90966.37,"id":2249229}]}]}
{"op":"mcm","clk":"4219429295","pt":1631400459128,"mc":[{"id":"1.187528277","rc":[{"batl":[[0,1.42,20131.83]],"ltp":1.41,"tv":90966.37,"id":2249229}]}]}
{"op":"mcm","clk":"4219429955","pt":1631400474238,"mc":[{"id":"1.187528277","rc":[{"batb":[[0,1.41,8005.82]],"ltp":1.41,"tv":90966.37,"id":2249229}]}]}
{"op":"mcm","clk":"4219432779","pt":1631400542867,"mc":[{"id":"1.187528277","rc":[{"trd":[[3.4,8911.46]],"batl":[[0,3.4,39.82]],"ltp":3.4,"tv":26114.13,"id":19924831}],"tv":117080.51}]}
{"op":"mcm","clk":"4219433688","pt":1631400564619,"mc":[{"id":"1.187528277","rc":[{"trd":[[1.42,22495.01]],"batl":[[0,1.42,19568.13]],"ltp":1.42,"tv":92093.74,"id":2249229}],"tv":118207.88}]}
{"op":"mcm","clk":"4219434488","pt":1631400584067,"mc":[{"id":"1.187528277","rc":[{"trd":[[3.4,8991.1]],"batb":[[0,3.4,249.39],[1,3.35,1019.9],[2,3.3,206.57]],"batl":[[0,3.45,3368.7],[1,3.5,42.7],[2,3.6,2]],"ltp":3.4,"tv":26193.77,"id":19924831}],"tv":118287.51}]}
{"op":"mcm","clk":"4219437435","pt":1631400665684,"mc":[{"id":"1.187528277","rc":[{"batb":[[2,3.3,103]],"ltp":3.4,"tv":26193.77,"id":19924831}]}]}
{"op":"mcm","clk":"4219437455","pt":1631400666357,"mc":[{"id":"1.187528277","rc":[{"batb":[[2,3.3,94.95]],"ltp":3.4,"tv":26193.77,"id":19924831}]}]}
{"op":"mcm","clk":"4219437477","pt":1631400667074,"mc":[{"id":"1.187528277","rc":[{"batb":[[2,3.3,91.01]],"ltp":3.4,"tv":26193.77,"id":19924831}]}]}
{"op":"mcm","clk":"4219437494","pt":1631400667746,"mc":[{"id":"1.187528277","rc":[{"batb":[[2,3.3,75.92]],"ltp":3.4,"tv":26193.77,"id":19924831}]}]}
{"op":"mcm","clk":"4219437861","pt":1631400676595,"mc":[{"id":"1.187528277","rc":[{"batb":[[1,3.35,1023.09]],"ltp":3.4,"tv":26193.77,"id":19924831}]}]}
{"op":"mcm","clk":"4219437879","pt":1631400677061,"mc":[{"id":"1.187528277","rc":[{"batl":[[1,3.5,494.73]],"ltp":3.4,"tv":26193.77,"id":19924831}]}]}
{"op":"mcm","clk":"4219438481","pt":1631400693210,"mc":[{"id":"1.187528277","rc":[{"batl":[[1,3.5,509.68]],"ltp":3.4,"tv":26193.77,"id":19924831}]}]}
{"op":"mcm","clk":"4219439240","pt":1631400716587,"mc":[{"id":"1.187528277","rc":[{"trd":[[3.4,9020.99]],"batb":[[0,3.4,234.44]],"batl":[[1,3.5,494.73]],"ltp":3.4,"tv":26223.66,"id":19924831}],"tv":118317.4}]}
{"op":"mcm","clk":"4219440168","pt":1631400744724,"mc":[{"id":"1.187528277","rc":[{"trd":[[3.4,9489.01]],"batb":[[0,3.35,1023.52],[1,3.3,75.92],[2,3.25,6]],"ltp":3.4,"tv":26691.68,"id":19924831}],"tv":118785.42}]}
{"op":"mcm","clk":"4219440275","pt":1631400748421,"mc":[{"id":"1.187528277","rc":[{"trd":[[3.4,9489.87]],"batb":[[0,3.35,1023.09]],"batl":[[0,3.4,49.57],[1,3.45,3368.7],[2,3.5,494.73]],"ltp":3.4,"tv":26692.54,"id":19924831}],"tv":118786.29}]}
{"op":"mcm","clk":"4219440815","pt":1631400761545,"mc":[{"id":"1.187528277","rc":[{"batl":[[1,3.45,1231]],"ltp":3.4,"tv":26692.54,"id":19924831}]}]}
{"op":"mcm","clk":"4219443727","pt":1631400852660,"mc":[{"id":"1.187528277","rc":[{"batl":[[2,3.5,42.7]],"ltp":3.4,"tv":26692.54,"id":19924831}]}]}
{"op":"mcm","clk":"4219443834","pt":1631400856564,"mc":[{"id":"1.187528277","rc":[{"batb":[[1,3.3,188.18]],"batl":[[0,3.4,57]],"ltp":3.4,"tv":26692.54,"id":19924831},{"batl":[[0,1.42,19573.08]],"ltp":1.42,"tv":92093.74,"id":2249229}]}]}
{"op":"mcm","clk":"4219444898","pt":1631400889796,"mc":[{"id":"1.187528277","rc":[{"trd":[[3.4,9603.88]],"batb":[[0,3.4,209.56],[1,3.35,1023.09],[2,3.3,188.18]],"batl":[[0,3.45,1231],[1,3.5,42.7],[2,3.6,2]],"ltp":3.4,"tv":26806.55,"id":19924831}],"tv":118900.29}]}
{"op":"mcm","clk":"4219445381","pt":1631400903219,"mc":[{"id":"1.187528277","rc":[{"batb":[[0,1.41,24072.62]],"ltp":1.42,"tv":92093.74,"id":2249229}]}]}
{"op":"mcm","clk":"4219449501","pt":1631401020101,"mc":[{"id":"1.187528277","rc":[{"batb":[[2,3.3,75.92]],"ltp":3.4,"tv":26806.55,"id":19924831}]}]}
{"op":"mcm","clk":"4219449689","pt":1631401024676,"mc":[{"id":"1.187528277","rc":[{"batl":[[0,1.42,19575.82]],"ltp":1.42,"tv":92093.74,"id":2249229}]}]}
{"op":"mcm","clk":"4219449721","pt":1631401025495,"mc":[{"id":"1.187528277","rc":[{"batb":[[1,3.35,1026.89]],"batl":[[0,3.45,1224.29]],"ltp":3.4,"tv":26806.55,"id":19924831}]}]}
{"op":"mcm","clk":"4219449738","pt":1631401026003,"mc":[{"id":"1.187528277","rc":[{"batl":[[1,3.5,494.73]],"ltp":3.4,"tv":26806.55,"id":19924831}]}]}
{"op":"mcm","clk":"4219450815","pt":1631401053943,"mc":[{"id":"1.187528277","rc":[{"trd":[[3.4,9714.14]],"batb":[[0,3.4,154.43]],"ltp":3.4,"tv":26916.81,"id":19924831},{"batl":[[0,1.42,14451.56]],"ltp":1.42,"tv":92093.74,"id":2249229}],"tv":119010.55}]}
{"op":"mcm","clk":"4219451704","pt":1631401079592,"mc":[{"id":"1.187528277","rc":[{"trd":[[3.4,9789.14]],"batb":[[0,3.4,116.93]],"ltp":3.4,"tv":26991.81,"id":19924831}],"tv":119085.55}]}
{"op":"mcm","clk":"4219452677","pt":1631401106655,"mc":[{"id":"1.187528277","rc":[{"batl":[[2,1.44,6170.26]],"ltp":1.42,"tv":92093.74,"id":2249229}]}]}
{"op":"mcm","clk":"4219452702","pt":1631401107125,"mc":[{"id":"1.187528277","rc":[{"batb":[[1,1.4,14294.56]],"batl":[[1,1.43,1618.41]],"ltp":1.42,"tv":92093.74,"id":2249229}]}]}
{"op":"mcm","clk":"4219453544","pt":1631401130185,"mc":[{"id":"1.187528277","rc":[{"trd":[[1.41,33418.51]],"batb":[[0,1.41,24062.63]],"ltp":1.41,"tv":92113.74,"id":2249229}],"tv":119105.55}]}
{"op":"mcm","clk":"4219457737","pt":1631401236445,"mc":[{"id":"1.187528277","rc":[{"trd":[[3.45,1408.86]],"batl":[[0,3.45,1221.01]],"ltp":3.45,"tv":26998.37,"id":19924831}],"tv":119112.11}]}
{"op":"mcm","clk":"4219458857","pt":1631401261101,"mc":[{"id":"1.187528277","rc":[{"trd":[[3.45,1496.26]],"batl":[[0,3.45,1177.31]],"ltp":3.45,"tv":27085.77,"id":19924831}],"tv":119199.52}]}
{"op":"mcm","clk":"4219464667","pt":1631401391912,"mc":[{"id":"1.187528277","rc":[{"trd":[[1.41,34264.48]],"batb":[[0,1.41,23639.64]],"ltp":1.41,"tv":92959.71,"id":2249229}],"tv":120045.49}]}
{"op":"mcm","clk":"4219465482","pt":1631401412108,"mc":[{"id":"1.187528277","rc":[{"trd":[[1.41,34284.48]],"batb":[[0,1.41,23629.64]],"ltp":1.41,"tv":92979.71,"id":2249229}],"tv":120065.49}]}
{"op":"mcm","clk":"4219465743","pt":1631401419221,"mc":[{"id":"1.187528277","rc":[{"trd":[[3.4,9899.4]],"batb":[[0,3.4,61.8]],"ltp":3.4,"tv":27196.03,"id":19924831},{"batl":[[0,1.42,2595.99],[1,1.43,13473.98]],"ltp":1.41,"tv":92979.71,"id":2249229}],"tv":120175.74}]}
{"op":"mcm","clk":"4219466010","pt":1631401426768,"mc":[{"id":"1.187528277","rc":[{"batl":[[0,1.42,95.99]],"ltp":1.41,"tv":92979.71,"id":2249229}]}]}
{"op":"mcm","clk":"4219466094","pt":1631401428769,"mc":[{"id":"1.187528277","rc":[{"batl":[[1,1.43,15973.98]],"ltp":1.41,"tv":92979.71,"id":2249229}]}]}
{"op":"mcm","clk":"4219466437","pt":1631401436986,"mc":[{"id":"1.187528277","rc":[{"batl":[[2,1.44,11294.52]],"ltp":1.41,"tv":92979.71,"id":2249229}]}]}
{"op":"mcm","clk":"4219466726","pt":1631401443693,"mc":[{"id":"1.187528277","rc":[{"batb":[[2,1.39,10240.88]],"ltp":1.41,"tv":92979.71,"id":2249229}]}]}
{"op":"mcm","clk":"4219466738","pt":1631401443899,"mc":[{"id":"1.187528277","rc":[{"trd":[[1.41,34294.48]],"batb":[[0,1.41,28748.9]],"ltp":1.41,"tv":92989.71,"id":2249229}],"tv":120185.75}]}
{"op":"mcm","clk":"4219468341","pt":1631401479331,"mc":[{"id":"1.187528277","rc":[{"trd":[[3.4,9961.2]],"batb":[[0,3.35,1026.89],[1,3.3,75.92],[2,3.25,6]],"batl":[[0,3.4,52.94],[1,3.45,1125.14],[2,3.5,494.73]],"ltp":3.4,"tv":27257.83,"id":19924831},{"trd":[[1.42,22834.95]],"batb":[[0,1.42,790.47],[1,1.41,28748.9],[2,1.4,14165.99]],"batl":[[0,1.43,16057.91],[1,1.44,11294.52],[2,1.45,1403.6]],"ltp":1.42,"tv":93329.66,"id":2249229}],"tv":120587.49}]}
{"op":"mcm","clk":"4219468372","pt":1631401479944,"mc":[{"id":"1.187528277","rc":[{"batb":[[1,1.41,28779.11]],"ltp":1.42,"tv":93329.66,"id":2249229}]}]}
{"op":"mcm","clk":"4219468721","pt":1631401487961,"mc":[{"id":"1.187528277","rc":[{"batb":[[0,1.42,1390.47]],"ltp":1.42,"tv":93329.66,"id":2249229}]}]}
{"op":"mcm","clk":"4219469039","pt":1631401494362,"mc":[{"id":"1.187528277","rc":[{"batb":[[2,1.4,13847.66]],"ltp":1.42,"tv":93329.66,"id":2249229}]}]}
{"op":"mcm","clk":"4219469076","pt":1631401495441,"mc":[{"id":"1.187528277","rc":[{"batb":[[2,1.4,13771.66]],"ltp":1.42,"tv":93329.66,"id":2249229}]}]}
{"op":"mcm","clk":"4219469122","pt":1631401496471,"mc":[{"id":"1.187528277","rc":[{"batl":[[2,3.5,42.7]],"ltp":3.4,"tv":27257.83,"id":19924831},{"batb":[[2,1.4,13714.22]],"ltp":1.42,"tv":93329.66,"id":2249229}]}]}
{"op":"mcm","clk":"4219469352","pt":1631401501588,"mc":[{"id":"1.187528277","rc":[{"batb":[[1,1.41,28695.34]],"batl":[[1,1.44,11746.56]],"ltp":1.42,"tv":93329.66,"id":2249229}]}]}
{"op":"mcm","clk":"4219469390","pt":1631401502267,"mc":[{"id":"1.187528277","rc":[{"batb":[[0,3.35,1023.09],[1,3.3,394.29]],"ltp":3.4,"tv":27257.83,"id":19924831}]}]}
{"op":"mcm","clk":"4219469458","pt":1631401503554,"mc":[{"id":"1.187528277","rc":[{"batb":[[0,3.35,1011.26]],"ltp":3.4,"tv":27257.83,"id":19924831}]}]}
{"op":"mcm","clk":"4219469517","pt":1631401504390,"mc":[{"id":"1.187528277","rc":[{"batl":[[0,3.4,147.99],[1,3.45,1140.14]],"ltp":3.4,"tv":27257.83,"id":19924831}]}]}
{"op":"mcm","clk":"4219470632","pt":1631401531839,"mc":[{"id":"1.187528277","rc":[{"trd":[[3.4,9965.98]],"batl":[[0,3.4,145.6]],"ltp":3.4,"tv":27262.61,"id":19924831}],"tv":120592.27}]}
{"op":"mcm","clk":"4219473310","pt":1631401595832,"mc":[{"id":"1.187528277","rc":[{"trd":[[3.35,4147.25]],"batb":[[0,3.35,1008.26]],"ltp":3.35,"tv":27268.61,"id":19924831}],"tv":120598.27}]}
{"op":"mcm","clk":"4219474004","pt":1631401611416,"mc":[{"id":"1.187528277","rc":[{"trd":[[3.35,4247.25]],"batb":[[0,3.35,958.26]],"ltp":3.35,"tv":27368.61,"id":19924831}],"tv":120698.27}]}
{"op":"mcm","clk":"4219477854","pt":1631401693418,"mc":[{"id":"1.187528277","rc":[{"batl":[[0,3.4,159.5]],"ltp":3.35,"tv":27368.61,"id":19924831}]}]}
{"op":"mcm","clk":"4219481317","pt":1631401761047,"mc":[{"id":"1.187528277","rc":[{"trd":[[1.42,23034.96]],"batb":[[0,1.42,1290.46]],"ltp":1.42,"tv":93529.66,"id":2249229}],"tv":120898.28}]}
{"op":"mcm","clk":"4219483102","pt":1631401795776,"mc":[{"id":"1.187528277","rc":[{"trd":[[3.4,10031.96]],"batl":[[0,3.4,126.51]],"ltp":3.4,"tv":27434.59,"id":19924831}],"tv":120964.25}]}
{"op":"mcm","clk":"4219484764","pt":1631401825400,"mc":[{"id":"1.187528277","rc":[{"batl":[[0,3.4,117.38]],"ltp":3.4,"tv":27434.59,"id":19924831}]}]}
{"op":"mcm","clk":"4219487774","pt":1631401887774,"mc":[{"id":"1.187528277","rc":[{"batb":[[0,1.42,1330.99]],"ltp":1.42,"tv":93529.66,"id":2249229}]}]}
{"op":"mcm","clk":"4219487953","pt":1631401891550,"mc":[{"id":"1.187528277","rc":[{"batb":[[0,3.35,97.7]],"ltp":3.4,"tv":27434.59,"id":19924831}]}]}
{"op":"mcm","clk":"4219488194","pt":1631401896458,"mc":[{"id":"1.187528277","rc":[{"batb":[[1,3.3,1272.02]],"ltp":3.4,"tv":27434.59,"id":19924831}]}]}
{"op":"mcm","clk":"4219488429","pt":1631401901083,"mc":[{"id":"1.187528277","rc":[{"trd":[[1.42,23234.96]],"batb":[[0,1.42,1230.98]],"ltp":1.42,"tv":93729.67,"id":2249229}],"tv":121164.26}]}
{"op":"mcm","clk":"4219489368","pt":1631401923134,"mc":[{"id":"1.187528277","rc":[{"batb":[[2,3.25,883.74]],"ltp":3.4,"tv":27434.59,"id":19924831}]}]}
{"op":"mcm","clk":"4219490537","pt":1631401950460,"mc":[{"id":"1.187528277","rc":[{"batb":[[1,3.3,394.29]],"ltp":3.4,"tv":27434.59,"id":19924831}]}]}
{"op":"mcm","clk":"4219490644","pt":1631401952481,"mc":[{"id":"1.187528277","rc":[{"batb":[[2,3.25,6]],"ltp":3.4,"tv":27434.59,"id":19924831}]}]}
{"op":"mcm","clk":"4219491656","pt":1631401976084,"mc":[{"id":"1.187528277","rc":[{"trd":[[1.42,23330.73]],"batb":[[0,1.42,1183.1]],"ltp":1.42,"tv":93825.43,"id":2249229}],"tv":121260.02}]}
{"op":"mcm","clk":"4219492546","pt":1631401995337,"mc":[{"id":"1.187528277","rc":[{"trd":[[1.42,25330.75]],"batb":[[0,1.42,183.07]],"ltp":1.42,"tv":95825.46,"id":2249229}],"tv":123260.05}]}
{"op":"mcm","clk":"4219493692","pt":1631402019872,"mc":[{"id":"1.187528277","rc":[{"batl":[[0,1.43,16078.58]],"ltp":1.42,"tv":95825.46,"id":2249229}]}]}
{"op":"mcm","clk":"4219494392","pt":1631402035018,"mc":[{"id":"1.187528277","rc":[{"batb":[[0,1.42,188.07],[1,1.41,28690.34]],"ltp":1.42,"tv":95825.46,"id":2249229}]}]}
{"op":"mcm","clk":"4219495292","pt":1631402054515,"mc":[{"id":"1.187528277","rc":[{"batb":[[0,3.35,14.66]],"batl":[[0,3.4,112.61]],"ltp":3.4,"tv":27434.59,"id":19924831}]}]}
{"op":"mcm","clk":"4219495318","pt":1631402055133,"mc":[{"id":"1.187528277","rc":[{"batl":[[0,3.4,46.95]],"ltp":3.4,"tv":27434.59,"id":19924831}]}]}
{"op":"mcm","clk":"4219498338","pt":1631402118327,"mc":[{"id":"1.187528277","rc":[{"trd":[[1.42,25590.75]],"batb":[[0,1.42,58.07]],"ltp":1.42,"tv":96085.46,"id":2249229}],"tv":123520.05}]}
{"op":"mcm","clk":"4219498361","pt":1631402118847,"mc":[{"id":"1.187528277","rc":[{"batb":[[0,3.35,159.29]],"batl":[[0,3.4,387.82]],"ltp":3.4,"tv":27434.59,"id":19924831}]}]}
{"op":"mcm","clk":"4219499507","pt":1631402145450,"mc":[{"id":"1.187528277","rc":[{"trd":[[1.42,25706.91]],"batb":[[0,1.41,28690.34],[1,1.4,13714.22],[2,1.39,10240.88]],"batl":[[0,1.42,13.5],[1,1.43,16078.58],[2,1.44,11746.56]],"ltp":1.42,"tv":96201.61,"id":2249229}],"tv":123636.2}]}
{"op":"mcm","clk":"4219499875","pt":1631402154464,"mc":[{"id":"1.187528277","rc":[{"batb":[[0,3.35,881.58]],"ltp":3.4,"tv":27434.59,"id":19924831}]}]}
{"op":"mcm","clk":"4219501362","pt":1631402190187,"mc":[{"id":"1.187528277","rc":[{"batl":[[2,1.44,11294.52]],"ltp":1.42,"tv":96201.61,"id":2249229}]}]}
{"op":"mcm","clk":"4219501515","pt":1631402193503,"mc":[{"id":"1.187528277","rc":[{"batb":[[0,1.41,28793.75],[1,1.4,14166.25]],"ltp":1.42,"tv":96201.61,"id":2249229}]}]}
{"op":"mcm","clk":"4219501540","pt":1631402194082,"mc":[{"id":"1.187528277","rc":[{"batb":[[0,3.35,965.12]],"batl":[[0,3.4,416.61]],"ltp":3.4,"tv":27434.59,"id":19924831}]}]}
{"op":"mcm","clk":"4219503593","pt":1631402242366,"mc":[{"id":"1.187528277","rc":[{"trd":[[1.41,34414.48]],"batb":[[0,1.41,28733.75]],"ltp":1.41,"tv":96321.61,"id":2249229}],"tv":123756.2}]}
{"op":"mcm","clk":"4219519569","pt":1631402360981,"mc":[{"id":"1.187528277","rc":[{"batl":[[0,3.4,420.93]],"ltp":3.4,"tv":27434.59,"id":19924831}]}]}
{"op":"mcm","clk":"4219524868","pt":1631402468595,"mc":[{"id":"1.187528277","rc":[{"trd":[[3.35,4287.24]],"batb":[[0,3.35,945.13]],"ltp":3.35,"tv":27474.58,"id":19924831}],"tv":123796.2}]}
{"op":"mcm","clk":"4219526766","pt":1631402506126,"mc":[{"id":"1.187528277","rc":[{"trd":[[1.41,34514.49]],"batb":[[0,1.41,28683.74]],"ltp":1.41,"tv":96421.62,"id":2249229}],"tv":123896.2}]}
{"op":"mcm","clk":"4219527547","pt":1631402521444,"mc":[{"id":"1.187528277","rc":[{"batb":[[0,1.41,28701.49]],"ltp":1.41,"tv":96421.62,"id":2249229}]}]}
{"op":"mcm","clk":"4219527589","pt":1631402522478,"mc":[{"id":"1.187528277","rc":[{"batb":[[0,3.35,952.43],[1,3.3,387.28]],"ltp":3.35,"tv":27474.58,"id":19924831}]}]}
{"op":"mcm","clk":"4219527607","pt":1631402522843,"mc":[{"id":"1.187528277","rc":[{"batl":[[1,3.45,1146.71]],"ltp":3.35,"tv":27474.58,"id":19924831}]}]}
{"op":"mcm","clk":"4219531088","pt":1631402596186,"mc":[{"id":"1.187528277","rc":[{"trd":[[1.41,35522.48]],"batb":[[0,1.41,28197.49]],"batl":[[0,1.42,149.16]],"ltp":1.41,"tv":97429.61,"id":2249229}],"tv":124904.2}]}
{"op":"mcm","clk":"4219534681","pt":1631402679428,"mc":[{"id":"1.187528277","rc":[{"batl":[[0,1.42,170.96]],"ltp":1.41,"tv":97429.61,"id":2249229}]}]}
{"op":"mcm","clk":"4219552141","pt":1631403076339,"mc":[{"id":"1.187528277","rc":[{"trd":[[1.41,35571.28]],"batb":[[0,1.41,28173.09]],"ltp":1.41,"tv":97478.41,"id":2249229}],"tv":124953.0}]}
{"op":"mcm","clk":"4219552157","pt":1631403076758,"mc":[{"id":"1.187528277","rc":[{"batl":[[0,1.42,195.19]],"ltp":1.41,"tv":97478.41,"id":2249229}]}]}
{"op":"mcm","clk":"4219554711","pt":1631403131145,"mc":[{"id":"1.187528277","rc":[{"trd":[[1.42,25806.91]],"batl":[[0,1.42,145.19]],"ltp":1.42,"tv":97578.41,"id":2249229}],"tv":125053.0}]}
{"op":"mcm","clk":"4219554988","pt":1631403138116,"mc":[{"id":"1.187528277","rc":[{"batb":[[0,3.35,1006.16]],"ltp":3.35,"tv":27474.58,"id":19924831},{"batl":[[0,1.42,2645.19],[1,1.43,13578.58]],"ltp":1.42,"tv":97578.41,"id":2249229}]}]}
{"op":"mcm","clk":"4219555048","pt":1631403139513,"mc":[{"id":"1.187528277","rc":[{"batb":[[0,3.35,866.86]],"batl":[[0,3.4,80.05]],"ltp":3.35,"tv":27474.58,"id":19924831}]}]}
{"op":"mcm","clk":"4219555124","pt":1631403140923,"mc":[{"id":"1.187528277","rc":[{"batl":[[0,3.4,85.31]],"ltp":3.35,"tv":27474.58,"id":19924831}]}]}
{"op":"mcm","clk":"4219555607","pt":1631403152458,"mc":[{"id":"1.187528277","rc":[{"batl":[[0,3.4,80.99]],"ltp":3.35,"tv":27474.58,"id":19924831}]}]}
{"op":"mcm","clk":"4219555659","pt":1631403153455,"mc":[{"id":"1.187528277","rc":[{"batl":[[0,3.4,35.62]],"ltp":3.35,"tv":27474.58,"id":19924831},{"batb":[[2,1.39,10087.82]],"ltp":1.42,"tv":97578.41,"id":2249229}]}]}
{"op":"mcm","clk":"4219556336","pt":1631403170088,"mc":[{"id":"1.187528277","rc":[{"trd":[[1.42,26041.61]],"batl":[[0,1.42,2527.84]],"ltp":1.42,"tv":97813.12,"id":2249229}],"tv":125287.7}]}
{"op":"mcm","clk":"4219556796","pt":1631403180339,"mc":[{"id":"1.187528277","rc":[{"batl":[[0,3.4,2034.62]],"ltp":3.35,"tv":27474.58,"id":19924831}]}]}
{"op":"mcm","clk":"4219557745","pt":1631403198984,"mc":[{"id":"1.187528277","rc":[{"batl":[[0,1.42,3250.85]],"ltp":1.42,"tv":97813.12,"id":2249229}]}]}
{"op":"mcm","clk":"4219558056","pt":1631403207699,"mc":[{"id":"1.187528277","rc":[{"batl":[[0,3.4,2210.52]],"ltp":3.35,"tv":27474.58,"id":19924831}]}]}
{"op":"mcm","clk":"4219558193","pt":1631403211498,"mc":[{"id":"1.187528277","rc":[{"batb":[[0,3.35,3276.67]],"ltp":3.35,"tv":27474.58,"id":19924831}]}]}
{"op":"mcm","clk":"4219558305","pt":1631403214703,"mc":[{"id":"1.187528277","rc":[{"batl":[[0,3.4,2386.42]],"ltp":3.35,"tv":27474.58,"id":19924831}]}]}
{"op":"mcm","clk":"4219558683","pt":1631403224500,"mc":[{"id":"1.187528277","rc":[{"trd":[[3.4,10037.28]],"batl":[[0,3.4,2383.76]],"ltp":3.4,"tv":27479.9,"id":19924831}],"tv":125293.02}]}
{"op":"mcm","clk":"4219560610","pt":1631403276686,"mc":[{"id":"1.187528277","rc":[{"batl":[[2,3.6,2]],"ltp":3.4,"tv":27479.9,"id":19924831},{"batl":[[1,1.43,13511.96]],"ltp":1.42,"tv":97813.12,"id":2249229}]}]}
{"op":"mcm","clk":"4219560634","pt":1631403277256,"mc":[{"id":"1.187528277","rc":[{"batb":[[1,3.3,378.74]],"batl":[[1,3.45,1172.33]],"ltp":3.4,"tv":27479.9,"id":19924831},{"batb":[[1,1.4,14211.51]],"batl":[[2,1.44,11414.94]],"ltp":1.42,"tv":97813.12,"id":2249229}]}]}
{"op":"mcm","clk":"4219563402","pt":1631403350783,"mc":[{"id":"1.187528277","rc":[{"batl":[[1,1.43,14419.75]],"ltp":1.42,"tv":97813.12,"id":2249229}]}]}
{"op":"mcm","clk":"4219563662","pt":1631403358391,"mc":[{"id":"1.187528277","rc":[{"batb":[[0,1.41,28182.42]],"batl":[[0,1.42,3259.94]],"ltp":1.42,"tv":97813.12,"id":2249229}]}]}
{"op":"mcm","clk":"4219563697","pt":1631403359478,"mc":[{"id":"1.187528277","rc":[{"batl":[[0,3.4,2501.25],[1,3.45,1176.04]],"ltp":3.4,"tv":27479.9,"id":19924831}]}]}
{"op":"mcm","clk":"4219566242","pt":1631403426637,"mc":[{"id":"1.187528277","rc":[{"batl":[[0,3.4,2486.35]],"ltp":3.4,"tv":27479.9,"id":19924831},{"batl":[[0,1.42,16023.3],[1,1.43,1656.39]],"ltp":1.42,"tv":97813.12,"id":2249229}]}]}
{"op":"mcm","clk":"4219567952","pt":1631403472790,"mc":[{"id":"1.187528277","rc":[{"batb":[[0,1.41,28174.73]],"ltp":1.42,"tv":97813.12,"id":2249229}]}]}
{"op":"mcm","clk":"4219568448","pt":1631403485457,"mc":[{"id":"1.187528277","rc":[{"batl":[[0,1.42,16746.31]],"ltp":1.42,"tv":97813.12,"id":2249229}]}]}
{"op":"mcm","clk":"4219569232","pt":1631403503629,"mc":[{"id":"1.187528277","rc":[{"batl":[[2,1.44,11378.22]],"ltp":1.42,"tv":97813.12,"id":2249229}]}]}
{"op":"mcm","clk":"4219569251","pt":1631403504045,"mc":[{"id":"1.187528277","rc":[{"batl":[[1,3.45,1186.29]],"ltp":3.4,"tv":27479.9,"id":19924831}]}]}
{"op":"mcm","clk":"4219569599","pt":1631403514254,"mc":[{"id":"1.187528277","rc":[{"batb":[[1,3.3,371.06]],"ltp":3.4,"tv":27479.9,"id":19924831},{"batb":[[0,1.41,28251.59],[1,1.4,14080.84]],"ltp":1.42,"tv":97813.12,"id":2249229}]}]}
{"op":"mcm","clk":"4219569895","pt":1631403521191,"mc":[{"id":"1.187528277","rc":[{"batb":[[1,3.3,359.95]],"ltp":3.4,"tv":27479.9,"id":19924831}]}]}
{"op":"mcm","clk":"4219570259","pt":1631403532698,"mc":[{"id":"1.187528277","rc":[{"batb":[[1,3.3,221.35]],"ltp":3.4,"tv":27479.9,"id":19924831}]}]}
{"op":"mcm","clk":"4219570377","pt":1631403535902,"mc":[{"id":"1.187528277","rc":[{"trd":[[3.35,5509.54]],"batb":[[0,3.35,2665.52]],"batl":[[1,3.45,575.14]],"ltp":3.35,"tv":28702.2,"id":19924831}],"tv":126515.32}]}
{"op":"mcm","clk":"4219570905","pt":1631403550038,"mc":[{"id":"1.187528277","rc":[{"trd":[[3.35,6709.55]],"batb":[[0,3.35,2065.51]],"ltp":3.35,"tv":29902.2,"id":19924831}],"tv":127715.32}]}
{"op":"mcm","clk":"4219573310","pt":1631403624632,"mc":[{"id":"1.187528277","rc":[{"batl":[[0,3.4,2310.45]],"ltp":3.35,"tv":29902.2,"id":19924831}]}]}
{"op":"mcm","clk":"4219573347","pt":1631403625764,"mc":[{"id":"1.187528277","rc":[{"batl":[[0,3.4,2134.55]],"ltp":3.35,"tv":29902.2,"id":19924831}]}]}
{"op":"mcm","clk":"4219573757","pt":1631403637762,"mc":[{"id":"1.187528277","rc":[{"trd":[[1.42,26861.09]],"batl":[[0,1.42,16336.57]],"ltp":1.42,"tv":98632.6,"id":2249229}],"tv":128534.8}]}
{"op":"mcm","clk":"4219574209","pt":1631403651193,"mc":[{"id":"1.187528277","rc":[{"trd":[[1.41,35730.35]],"batb":[[0,1.41,28172.06]],"batl":[[0,1.42,16415.54]],"ltp":1.41,"tv":98791.66,"id":2249229}],"tv":128693.87}]}
{"op":"mcm","clk":"4219574265","pt":1631403652278,"mc":[{"id":"1.187528277","rc":[{"batb":[[0,1.41,28283.84]],"ltp":1.41,"tv":98791.66,"id":2249229}]}]}
{"op":"mcm","clk":"4219574328","pt":1631403653571,"mc":[{"id":"1.187528277","rc":[{"batb":[[0,3.35,2106.15],[1,3.3,200.56]],"ltp":3.35,"tv":29902.2,"id":19924831}]}]}
{"op":"mcm","clk":"4219574358","pt":1631403654194,"mc":[{"id":"1.187528277","rc":[{"batl":[[0,3.4,2179.92],[1,3.45,619.59]],"ltp":3.35,"tv":29902.2,"id":19924831}]}]}
{"op":"mcm","clk":"4219575166","pt":1631403675449,"mc":[{"id":"1.187528277","rc":[{"trd":[[3.4,10057.28]],"batb":[[0,3.35,2144.76]],"batl":[[0,3.4,2169.92]],"ltp":3.4,"tv":29922.21,"id":19924831}],"tv":128713.87}]}
{"op":"mcm","clk":"4219576238","pt":1631403707462,"mc":[{"id":"1.187528277","rc":[{"batl":[[1,1.43,6780.65],[2,1.44,6253.96]],"ltp":1.41,"tv":98791.66,"id":2249229}]}]}
{"op":"mcm","clk":"4219577631","pt":1631403746481,"mc":[{"id":"1.187528277","rc":[{"batb":[[0,1.41,23159.58]],"batl":[[1,1.43,1656.39]],"ltp":1.41,"tv":98791.66,"id":2249229}]}]}
{"op":"mcm","clk":"4219579629","pt":1631403802697,"mc":[{"id":"1.187528277","rc":[{"batb":[[0,3.35,2149.85]],"batl":[[0,3.4,2174.94]],"ltp":3.4,"tv":29922.21,"id":19924831},{"batb":[[0,1.41,23147.29]],"ltp":1.41,"tv":98791.66,"id":2249229}]}]}
{"op":"mcm","clk":"4219579642","pt":1631403803108,"mc":[{"id":"1.187528277","rc":[{"batl":[[1,3.45,614.7]],"ltp":3.4,"tv":29922.21,"id":19924831}]}]}
{"op":"mcm","clk":"4219596995","pt":1631404242133,"mc":[{"id":"1.187528277","rc":[{"trd":[[3.4,10099.82]],"batl":[[0,3.4,2153.66]],"ltp":3.4,"tv":29964.75,"id":19924831}],"tv":128756.41}]}
{"op":"mcm","clk":"4219598553","pt":1631404280263,"mc":[{"id":"1.187528277","rc":[{"batl":[[1,1.43,1635.72]],"ltp":1.41,"tv":98791.66,"id":2249229}]}]}
{"op":"mcm","clk":"4219601797","pt":1631404359468,"mc":[{"id":"1.187528277","rc":[{"trd":[[1.41,35768.51]],"batb":[[0,1.41,23128.21]],"ltp":1.41,"tv":98829.82,"id":2249229}],"tv":128794.57}]}
{"op":"mcm","clk":"4219601815","pt":1631404359977,"mc":[{"id":"1.187528277","rc":[{"batl":[[0,1.42,16434.48]],"ltp":1.41,"tv":98829.82,"id":2249229}]}]}
{"op":"mcm","clk":"4219614477","pt":1631404720587,"mc":[{"id":"1.187528277","rc":[{"trd":[[1.41,35788.51]],"batb":[[0,1.41,23118.21]],"batl":[[0,1.42,16444.41]],"ltp":1.41,"tv":98849.82,"id":2249229}],"tv":128814.57}]}
{"op":"mcm","clk":"4219623953","pt":1631404922714,"mc":[{"id":"1.187528277","rc":[{"trd":[[3.35,6829.55]],"batb":[[0,3.35,2089.85]],"ltp":3.35,"tv":30084.76,"id":19924831}],"tv":128934.58}]}
{"op":"mcm","clk":"4219633086","pt":1631405098167,"mc":[{"id":"1.187528277","rc":[{"trd":[[1.42,27143.09]],"batl":[[0,1.42,16303.41]],"ltp":1.42,"tv":99131.82,"id":2249229}],"tv":129216.58}]}
{"op":"mcm","clk":"4219659447","pt":1631405594055,"mc":[{"id":"1.187528277","rc":[{"trd":[[1.42,27261.96]],"batl":[[0,1.42,16243.98]],"ltp":1.42,"tv":99250.68,"id":2249229}],"tv":129335.44}]}
{"op":"mcm","clk":"4219663420","pt":1631405660578,"mc":[{"id":"1.187528277","rc":[{"batb":[[1,3.3,226.09]],"ltp":3.35,"tv":30084.76,"id":19924831}]}]}
{"op":"mcm","clk":"4219665961","pt":1631405704352,"mc":[{"id":"1.187528277","rc":[{"trd":[[1.41,35808.51]],"batb":[[0,1.41,23108.21]],"batl":[[0,1.42,16253.91]],"ltp":1.41,"tv":99270.68,"id":2249229}],"tv":129355.44}]}
{"op":"mcm","clk":"4219682072","pt":1631405998114,"mc":[{"id":"1.187528277","rc":[{"trd":[[1.42,28316.86]],"batb":[[0,1.41,22583.21],[1,1.4,13347.84]],"batl":[[0,1.42,15726.46]],"ltp":1.42,"tv":100325.58,"id":2249229}],"tv":130410.34}]}
{"op":"mcm","clk":"4219687235","pt":1631406087487,"mc":[{"id":"1.187528277","rc":[{"trd":[[1.42,29274.08]],"batl":[[0,1.42,15247.86]],"ltp":1.42,"tv":101282.8,"id":2249229}],"tv":131367.57}]}
{"op":"mcm","clk":"4219695570","pt":1631406245250,"mc":[{"id":"1.187528277","rc":[{"trd":[[3.4,10150.62]],"batl":[[0,3.4,2128.26]],"ltp":3.4,"tv":30135.55,"id":19924831}],"tv":131418.36}]}
{"op":"mcm","clk":"4219697762","pt":1631406285604,"mc":[{"id":"1.187528277","rc":[{"batb":[[0,3.35,2535.99]],"ltp":3.4,"tv":30135.55,"id":19924831}]}]}
{"op":"mcm","clk":"4219697783","pt":1631406285862,"mc":[{"id":"1.187528277","rc":[{"batb":[[0,3.35,2089.85]],"ltp":3.4,"tv":30135.55,"id":19924831}]}]}
{"op":"mcm","clk":"4219701536","pt":1631406347584,"mc":[{"id":"1.187528277","rc":[{"trd":[[3.4,10201.68]],"batl":[[0,3.4,2102.73]],"ltp":3.4,"tv":30186.61,"id":19924831}],"tv":131469.42}]}
{"op":"mcm","clk":"4219702056","pt":1631406357765,"mc":[{"id":"1.187528277","rc":[{"batl":[[0,1.42,15257.86]],"ltp":1.42,"tv":101282.8,"id":2249229}]}]}
{"op":"mcm","clk":"4219702360","pt":1631406364405,"mc":[{"id":"1.187528277","rc":[{"trd":[[1.41,35828.51]],"batb":[[0,1.41,22573.21]],"batl":[[0,1.42,15257.79]],"ltp":1.41,"tv":101302.8,"id":2249229}],"tv":131489.42}]}
{"op":"mcm","clk":"4219732718","pt":1631406908085,"mc":[{"id":"1.187528277","rc":[{"batb":[[0,3.35,2100.49]],"ltp":3.4,"tv":30186.61,"id":19924831}]}]}
{"op":"mcm","clk":"4219743061","pt":1631407111512,"mc":[{"id":"1.187528277","rc":[{"batb":[[0,3.35,2546.63]],"ltp":3.4,"tv":30186.61,"id":19924831},{"trd":[[1.41,35848.77]],"batb":[[0,1.41,22563.08]],"ltp":1.41,"tv":101323.07,"id":2249229}],"tv":131509.68}]}
{"op":"mcm","clk":"4219743089","pt":1631407111929,"mc":[{"id":"1.187528277","rc":[{"batb":[[0,3.35,2100.49]],"ltp":3.4,"tv":30186.61,"id":19924831},{"batl":[[0,1.42,15267.85]],"ltp":1.41,"tv":101323.07,"id":2249229}]}]}
{"op":"mcm","clk":"4219773760","pt":1631407601687,"mc":[{"id":"1.187528277","rc":[{"trd":[[3.35,6849.05]],"batb":[[0,3.35,2090.74]],"ltp":3.35,"tv":30206.1,"id":19924831}],"tv":131529.18}]}
{"op":"mcm","clk":"4219791565","pt":1631407722582,"mc":[{"id":"1.187528277","rc":[{"batb":[[1,3.3,198.76]],"batl":[[1,3.45,578.83]],"ltp":3.35,"tv":30206.1,"id":19924831},{"batb":[[0,1.41,22486.22]],"batl":[[2,1.44,6170.26]],"ltp":1.41,"tv":101323.07,"id":2249229}]}]}
{"op":"mcm","clk":"4219797950","pt":1631407824523,"mc":[{"id":"1.187528277","rc":[{"batb":[[0,3.35,2536.88],[1,3.3,250.88]],"ltp":3.35,"tv":30206.1,"id":19924831}]}]}
{"op":"mcm","clk":"4219797971","pt":1631407824735,"mc":[{"id":"1.187528277","rc":[{"batb":[[0,3.35,2090.74]],"ltp":3.35,"tv":30206.1,"id":19924831}]}]}
{"op":"mcm","clk":"4219798337","pt":1631407830555,"mc":[{"id":"1.187528277","rc":[{"batb":[[1,3.3,285.89]],"batl":[[1,3.45,606.16]],"ltp":3.35,"tv":30206.1,"id":19924831},{"batb":[[1,1.4,13472.53]],"batl":[[2,1.44,6300.93]],"ltp":1.41,"tv":101323.07,"id":2249229}]}]}
{"op":"mcm","clk":"4219799558","pt":1631407851571,"mc":[{"id":"1.187528277","rc":[{"trd":[[3.4,10282.32]],"batl":[[0,3.4,2062.41]],"ltp":3.4,"tv":30286.75,"id":19924831}],"tv":131609.82}]}
{"op":"mcm","clk":"4219801852","pt":1631407893889,"mc":[{"id":"1.187528277","rc":[{"batb":[[1,3.3,294.23]],"ltp":3.4,"tv":30286.75,"id":19924831}]}]}
{"op":"mcm","clk":"4219804495","pt":1631407948720,"mc":[{"id":"1.187528277","rc":[{"trd":[[1.41,36207.79]],"batb":[[0,1.41,22306.71]],"ltp":1.41,"tv":101682.09,"id":2249229}],"tv":131968.84}]}
{"op":"mcm","clk":"4219804516","pt":1631407949230,"mc":[{"id":"1.187528277","rc":[{"batl":[[0,1.42,15294.73]],"ltp":1.41,"tv":101682.09,"id":2249229}]}]}
{"op":"mcm","clk":"4219813447","pt":1631408119612,"mc":[{"id":"1.187528277","rc":[{"batb":[[1,3.3,301.92]],"batl":[[1,3.45,578.83],[2,3.5,42.7]],"ltp":3.4,"tv":30286.75,"id":19924831}]}]}
{"op":"mcm","clk":"4219813924","pt":1631408128223,"mc":[{"id":"1.187528277","rc":[{"trd":[[1.41,36314.15]],"batb":[[0,1.41,22253.53]],"ltp":1.41,"tv":101788.45,"id":2249229}],"tv":132075.2}]}
{"op":"mcm","clk":"4219817034","pt":1631408186154,"mc":[{"id":"1.187528277","rc":[{"batl":[[0,1.42,15394.73]],"ltp":1.41,"tv":101788.45,"id":2249229}]}]}
{"op":"mcm","clk":"4219818919","pt":1631408220805,"mc":[{"id":"1.187528277","rc":[{"trd":[[3.4,10362.32]],"batl":[[0,3.4,2022.41]],"ltp":3.4,"tv":30366.75,"id":19924831}],"tv":132155.2}]}
{"op":"mcm","clk":"4219821692","pt":1631408274632,"mc":[{"id":"1.187528277","rc":[{"trd":[[1.41,36420.5]],"batb":[[0,1.41,22200.35]],"ltp":1.41,"tv":101894.8,"id":2249229}],"tv":132261.56}]}
{"op":"mcm","clk":"4219823813","pt":1631408320696,"mc":[{"id":"1.187528277","rc":[{"trd":[[1.41,37771.73]],"batb":[[0,1.41,21524.74]],"ltp":1.41,"tv":103246.03,"id":2249229}],"tv":133612.78}]}
{"op":"mcm","clk":"4219824756","pt":1631408339047,"mc":[{"id":"1.187528277","rc":[{"batl":[[0,1.42,15447.91]],"ltp":1.41,"tv":103246.03,"id":2249229}]}]}
{"op":"mcm","clk":"4219828445","pt":1631408398304,"mc":[{"id":"1.187528277","rc":[{"trd":[[1.41,37825.74]],"batb":[[0,1.41,21497.74]],"ltp":1.41,"tv":103300.04,"id":2249229}],"tv":133666.79}]}
{"op":"mcm","clk":"4219831061","pt":1631408433668,"mc":[{"id":"1.187528277","rc":[{"trd":[[1.41,37831.06]],"batb":[[0,1.41,21495.08]],"ltp":1.41,"tv":103305.35,"id":2249229}],"tv":133672.11}]}
{"op":"mcm","clk":"4219846197","pt":1631408673286,"mc":[{"id":"1.187528277","rc":[{"trd":[[3.4,11102.39]],"batl":[[0,3.4,1652.39]],"ltp":3.4,"tv":31106.81,"id":19924831}],"tv":134412.17}]}
{"op":"mcm","clk":"4219846369","pt":1631408675786,"mc":[{"id":"1.187528277","rc":[{"trd":[[3.35,6865.42]],"batb":[[0,3.35,2082.55]],"ltp":3.35,"tv":31123.18,"id":19924831}],"tv":134428.54}]}
{"op":"mcm","clk":"4219874589","pt":1631409054151,"mc":[{"id":"1.187528277","rc":[{"trd":[[1.41,37838.29]],"batb":[[0,1.41,21491.46]],"ltp":1.41,"tv":103312.58,"id":2249229}],"tv":134435.77}]}
{"op":"mcm","clk":"4219878303","pt":1631409102681,"mc":[{"id":"1.187528277","rc":[{"trd":[[1.41,37849.81]],"batb":[[0,1.41,21485.7]],"ltp":1.41,"tv":103324.11,"id":2249229}],"tv":134447.29}]}
{"op":"mcm","clk":"4219880332","pt":1631409130696,"mc":[{"id":"1.187528277","rc":[{"batb":[[0,3.35,2528.69]],"batl":[[2,3.6,2]],"ltp":3.35,"tv":31123.18,"id":19924831}]}]}
{"op":"mcm","clk":"4219880366","pt":1631409131112,"mc":[{"id":"1.187528277","rc":[{"batb":[[0,3.35,2082.55],[1,3.3,291.67]],"batl":[[1,3.45,602.74]],"ltp":3.35,"tv":31123.18,"id":19924831}]}]}
{"op":"mcm","clk":"4219886463","pt":1631409208533,"mc":[{"id":"1.187528277","rc":[{"trd":[[1.41,37956.16]],"batb":[[0,1.41,21432.52]],"batl":[[0,1.42,15394.73]],"ltp":1.41,"tv":103430.46,"id":2249229}],"tv":134553.65}]}
{"op":"mcm","clk":"4219896230","pt":1631409341988,"mc":[{"id":"1.187528277","rc":[{"trd":[[1.41,37958.92]],"batb":[[0,1.41,21431.15]],"ltp":1.41,"tv":103433.22,"id":2249229}],"tv":134556.4}]}
{"op":"mcm","clk":"4219917206","pt":1631409623418,"mc":[{"id":"1.187528277","rc":[{"trd":[[1.41,37964.24]],"batb":[[0,1.41,21428.49]],"ltp":1.41,"tv":103438.54,"id":2249229}],"tv":134561.72}]}
{"op":"mcm","clk":"4219945208","pt":1631409980653,"mc":[{"id":"1.187528277","rc":[{"batl":[[1,3.45,578.83]],"ltp":3.35,"tv":31123.18,"id":19924831}]}]}
{"op":"mcm","clk":"4219945238","pt":1631409981068,"mc":[{"id":"1.187528277","rc":[{"batb":[[1,3.3,301.92]],"batl":[[2,3.5,44.41]],"ltp":3.35,"tv":31123.18,"id":19924831},{"batb":[[1,1.4,13434.1]],"ltp":1.41,"tv":103438.54,"id":2249229}]}]}
{"op":"mcm","clk":"4219967386","pt":1631410272678,"mc":[{"id":"1.187528277","rc":[{"trd":[[1.41,43282.11]],"batb":[[0,1.41,18769.62]],"ltp":1.41,"tv":108756.41,"id":2249229}],"tv":139879.6}]}
{"op":"mcm","clk":"4219971011","pt":1631410323598,"mc":[{"id":"1.187528277","rc":[{"batb":[[0,1.41,18783.82]],"ltp":1.41,"tv":108756.41,"id":2249229}]}]}
{"op":"mcm","clk":"4219971066","pt":1631410324369,"mc":[{"id":"1.187528277","rc":[{"batb":[[0,3.35,2091.56]],"batl":[[0,3.4,1647.37]],"ltp":3.35,"tv":31123.18,"id":19924831}]}]}
{"op":"mcm","clk":"4219971106","pt":1631410324995,"mc":[{"id":"1.187528277","rc":[{"batl":[[1,3.45,570.19]],"ltp":3.35,"tv":31123.18,"id":19924831}]}]}
{"op":"mcm","clk":"4219975983","pt":1631410393161,"mc":[{"id":"1.187528277","rc":[{"trd":[[3.35,6875.42]],"batb":[[0,3.35,2086.56]],"ltp":3.35,"tv":31133.18,"id":19924831}],"tv":139889.6}]}
{"op":"mcm","clk":"4219976231","pt":1631410396022,"mc":[{"id":"1.187528277","rc":[{"trd":[[1.41,43321.4]],"batb":[[0,1.41,18764.18]],"ltp":1.41,"tv":108795.7,"id":2249229}],"tv":139928.89}]}
{"op":"mcm","clk":"4219988938","pt":1631410568926,"mc":[{"id":"1.187528277","rc":[{"batb":[[1,1.4,13433.59]],"ltp":1.41,"tv":108795.7,"id":2249229}]}]}
{"op":"mcm","clk":"4219989074","pt":1631410571058,"mc":[{"id":"1.187528277","rc":[{"trd":[[1.41,43326.44]],"batb":[[0,1.41,18761.66]],"ltp":1.41,"tv":108800.74,"id":2249229}],"tv":139933.93}]}
{"op":"mcm","clk":"4219999082","pt":1631410715898,"mc":[{"id":"1.187528277","rc":[{"trd":[[3.35,6886.05]],"batb":[[0,3.35,2081.25]],"ltp":3.35,"tv":31143.82,"id":19924831}],"tv":139944.56}]}
{"op":"mcm","clk":"4220026469","pt":1631411134820,"mc":[{"id":"1.187528277","rc":[{"trd":[[3.4,11104.5]],"batl":[[0,3.4,1646.31]],"ltp":3.4,"tv":31145.93,"id":19924831}],"tv":139946.68}]}
{"op":"mcm","clk":"4220032957","pt":1631411234274,"mc":[{"id":"1.187528277","rc":[{"batl":[[0,1.42,15444.73]],"ltp":1.41,"tv":108800.74,"id":2249229}]}]}
{"op":"mcm","clk":"4220033410","pt":1631411242685,"mc":[{"id":"1.187528277","rc":[{"batb":[[0,1.41,18811.66]],"ltp":1.41,"tv":108800.74,"id":2249229}]}]}
{"op":"mcm","clk":"4220033783","pt":1631411248798,"mc":[{"id":"1.187528277","rc":[{"trd":[[1.41,43376.44]],"batb":[[0,1.41,18786.66]],"ltp":1.41,"tv":108850.74,"id":2249229}],"tv":139996.67}]}
{"op":"mcm","clk":"4220034327","pt":1631411257942,"mc":[{"id":"1.187528277","rc":[{"batb":[[0,1.41,18811.66]],"ltp":1.41,"tv":108850.74,"id":2249229}]}]}
{"op":"mcm","clk":"4220036350","pt":1631411288986,"mc":[{"id":"1.187528277","rc":[{"batl":[[0,1.42,15494.73]],"ltp":1.41,"tv":108850.74,"id":2249229}]}]}
{"op":"mcm","clk":"4220036901","pt":1631411297799,"mc":[{"id":"1.187528277","rc":[{"batb":[[0,1.41,18861.66]],"ltp":1.41,"tv":108850.74,"id":2249229}]}]}
{"op":"mcm","clk":"4220037287","pt":1631411303881,"mc":[{"id":"1.187528277","rc":[{"trd":[[1.41,43426.44]],"batb":[[0,1.41,18836.67]],"ltp":1.41,"tv":108900.74,"id":2249229}],"tv":140046.67}]}
{"op":"mcm","clk":"4220037698","pt":1631411310982,"mc":[{"id":"1.187528277","rc":[{"batb":[[1,1.4,13458.59]],"ltp":1.41,"tv":108900.74,"id":2249229}]}]}
{"op":"mcm","clk":"4220039845","pt":1631411348124,"mc":[{"id":"1.187528277","rc":[{"batl":[[2,1.44,6310.93]],"ltp":1.41,"tv":108900.74,"id":2249229}]}]}
{"op":"mcm","clk":"4220040182","pt":1631411354658,"mc":[{"id":"1.187528277","rc":[{"batb":[[1,1.4,13468.59]],"ltp":1.41,"tv":108900.74,"id":2249229}]}]}
{"op":"mcm","clk":"4220040474","pt":1631411360490,"mc":[{"id":"1.187528277","rc":[{"batl":[[1,1.43,1645.72]],"ltp":1.41,"tv":108900.74,"id":2249229}]}]}
{"op":"mcm","clk":"4220040810","pt":1631411366665,"mc":[{"id":"1.187528277","rc":[{"batb":[[1,1.4,13478.59]],"ltp":1.41,"tv":108900.74,"id":2249229}]}]}
{"op":"mcm","clk":"4220041807","pt":1631411385527,"mc":[{"id":"1.187528277","rc":[{"batb":[[1,3.3,304.97]],"ltp":3.4,"tv":31145.93,"id":19924831}]}]}
{"op":"mcm","clk":"4220042248","pt":1631411393845,"mc":[{"id":"1.187528277","rc":[{"trd":[[1.41,43436.43]],"batb":[[0,1.41,18831.67]],"ltp":1.41,"tv":108910.73,"id":2249229}],"tv":140056.67}]}
{"op":"mcm","clk":"4220042579","pt":1631411400433,"mc":[{"id":"1.187528277","rc":[{"batb":[[2,1.39,10092.82]],"ltp":1.41,"tv":108910.73,"id":2249229}]}]}
{"op":"mcm","clk":"4220042950","pt":1631411407056,"mc":[{"id":"1.187528277","rc":[{"batl":[[1,1.43,1650.72]],"ltp":1.41,"tv":108910.73,"id":2249229}]}]}
{"op":"mcm","clk":"4220043161","pt":1631411411153,"mc":[{"id":"1.187528277","rc":[{"trd":[[1.42,29284.08]],"batl":[[0,1.42,15489.73]],"ltp":1.42,"tv":108920.73,"id":2249229}],"tv":140066.67}]}
{"op":"mcm","clk":"4220043676","pt":1631411419856,"mc":[{"id":"1.187528277","rc":[{"batl":[[0,1.42,15499.73]],"ltp":1.42,"tv":108920.73,"id":2249229}]}]}
{"op":"mcm","clk":"4220044006","pt":1631411425045,"mc":[{"id":"1.187528277","rc":[{"batb":[[0,1.41,18841.67]],"ltp":1.42,"tv":108920.73,"id":2249229}]}]}
{"op":"mcm","clk":"4220045380","pt":1631411447489,"mc":[{"id":"1.187528277","rc":[{"trd":[[1.41,43456.43]],"batb":[[0,1.41,18831.67]],"ltp":1.41,"tv":108940.73,"id":2249229}],"tv":140086.67}]}
{"op":"mcm","clk":"4220045684","pt":1631411452715,"mc":[{"id":"1.187528277","rc":[{"batb":[[1,1.4,13488.59]],"ltp":1.41,"tv":108940.73,"id":2249229}]}]}
{"op":"mcm","clk":"4220050454","pt":1631411541891,"mc":[{"id":"1.187528277","rc":[{"trd":[[1.42,29596.16]],"batl":[[0,1.42,15343.69]],"ltp":1.42,"tv":109252.82,"id":2249229}],"tv":140398.76}]}
{"op":"mcm","clk":"4220062544","pt":1631411780642,"mc":[{"id":"1.187528277","rc":[{"batb":[[0,3.35,2527.39]],"ltp":3.4,"tv":31145.93,"id":19924831}]}]}
{"op":"mcm","clk":"4220062549","pt":1631411780745,"mc":[{"id":"1.187528277","rc":[{"batb":[[0,3.35,2081.25]],"ltp":3.4,"tv":31145.93,"id":19924831}]}]}
{"op":"mcm","clk":"4220078652","pt":1631412057710,"mc":[{"id":"1.187528277","rc":[{"trd":[[3.4,11108.5]],"batl":[[0,3.4,1644.31]],"ltp":3.4,"tv":31149.93,"id":19924831}],"tv":140402.76}]}
{"op":"mcm","clk":"4220095526","pt":1631412356133,"mc":[{"id":"1.187528277","rc":[{"trd":[[3.4,11159.3]],"batl":[[0,3.4,1618.91]],"ltp":3.4,"tv":31200.73,"id":19924831}],"tv":140453.55}]}
{"op":"mcm","clk":"4220099554","pt":1631412424833,"mc":[{"id":"1.187528277","rc":[{"batb":[[0,3.35,2084.03]],"ltp":3.4,"tv":31200.73,"id":19924831}]}]}
{"op":"mcm","clk":"4220100030","pt":1631412433718,"mc":[{"id":"1.187528277","rc":[{"batb":[[0,3.35,2081.25]],"ltp":3.4,"tv":31200.73,"id":19924831}]}]}
{"op":"mcm","clk":"4220100034","pt":1631412433819,"mc":[{"id":"1.187528277","rc":[{"trd":[[3.4,11164.88]],"batl":[[0,3.4,1616.12]],"ltp":3.4,"tv":31206.31,"id":19924831}],"tv":140459.13}]}
{"op":"mcm","clk":"4220108060","pt":1631412563509,"mc":[{"id":"1.187528277","rc":[{"trd":[[3.35,6890.39]],"batb":[[0,3.35,2079.08]],"ltp":3.35,"tv":31210.65,"id":19924831}],"tv":140463.47}]}
{"op":"mcm","clk":"4220115558","pt":1631412675377,"mc":[{"id":"1.187528277","rc":[{"trd":[[1.41,43678.43]],"batb":[[0,1.41,18720.67]],"ltp":1.41,"tv":109474.82,"id":2249229}],"tv":140685.47}]}
{"op":"mcm","clk":"4220121761","pt":1631412776301,"mc":[{"id":"1.187528277","rc":[{"trd":[[3.4,11189.34]],"batl":[[0,3.4,1603.89]],"ltp":3.4,"tv":31235.11,"id":19924831}],"tv":140709.93}]}
{"op":"mcm","clk":"4220130776","pt":1631412914423,"mc":[{"id":"1.187528277","rc":[{"batl":[[0,3.4,1628.89]],"ltp":3.4,"tv":31235.11,"id":19924831},{"batb":[[0,1.41,18770.67]],"ltp":1.41,"tv":109474.82,"id":2249229}]}]}
{"op":"mcm","clk":"4220131258","pt":1631412920749,"mc":[{"id":"1.187528277","rc":[{"trd":[[1.41,43683.75]],"batb":[[0,1.41,18768.01]],"ltp":1.41,"tv":109480.13,"id":2249229}],"tv":140715.25}]}
{"op":"mcm","clk":"4220132866","pt":1631412942572,"mc":[{"id":"1.187528277","rc":[{"trd":[[1.41,43689.06]],"batb":[[0,1.41,18765.36]],"ltp":1.41,"tv":109485.45,"id":2249229}],"tv":140720.56}]}
{"op":"mcm","clk":"4220133194","pt":1631412947273,"mc":[{"id":"1.187528277","rc":[{"trd":[[1.42,29596.42]],"batl":[[0,1.42,15343.56]],"ltp":1.42,"tv":109485.7,"id":2249229}],"tv":140720.82}]}
{"op":"mcm","clk":"4220165863","pt":1631413232065,"mc":[{"id":"1.187528277","rc":[{"trd":[[1.41,43716.62]],"batb":[[0,1.41,18751.58]],"ltp":1.41,"tv":109513.26,"id":2249229}],"tv":140748.37}]}
{"op":"mcm","clk":"4220178660","pt":1631413396869,"mc":[{"id":"1.187528277","rc":[{"trd":[[1.42,29604.96]],"batl":[[0,1.42,15339.29]],"ltp":1.42,"tv":109521.8,"id":2249229}],"tv":140756.91}]}
{"op":"mcm","clk":"4220237665","pt":1631414206556,"mc":[{"id":"1.187528277","rc":[{"trd":[[1.41,43744.17]],"batb":[[0,1.41,18737.8]],"ltp":1.41,"tv":109549.35,"id":2249229}],"tv":140784.47}]}
{"op":"mcm","clk":"4220239920","pt":1631414245615,"mc":[{"id":"1.187528277","rc":[{"batl":[[1,1.43,1729.3],[2,1.44,6180.26]],"ltp":1.41,"tv":109549.35,"id":2249229}]}]}
{"op":"mcm","clk":"4220240370","pt":1631414253840,"mc":[{"id":"1.187528277","rc":[{"trd":[[1.41,44984.86]],"batb":[[0,1.41,18117.46]],"ltp":1.41,"tv":110790.05,"id":2249229}],"tv":142025.16}]}
{"op":"mcm","clk":"4220243874","pt":1631414307701,"mc":[{"id":"1.187528277","rc":[{"batb":[[0,1.41,18156.29]],"ltp":1.41,"tv":110790.05,"id":2249229}]}]}
{"op":"mcm","clk":"4220243933","pt":1631414308376,"mc":[{"id":"1.187528277","rc":[{"batb":[[0,3.35,2095.79],[1,3.3,310.86]],"ltp":3.4,"tv":31235.11,"id":19924831}]}]}
{"op":"mcm","clk":"4220244022","pt":1631414309413,"mc":[{"id":"1.187528277","rc":[{"batl":[[0,3.4,1611.52],[1,3.45,554.16]],"ltp":3.4,"tv":31235.11,"id":19924831}]}]}
{"op":"mcm","clk":"4220255098","pt":1631414484633,"mc":[{"id":"1.187528277","rc":[{"batb":[[0,3.35,2541.88]],"ltp":3.4,"tv":31235.11,"id":19924831}]}]}
{"op":"mcm","clk":"4220255117","pt":1631414484941,"mc":[{"id":"1.187528277","rc":[{"batb":[[0,3.35,2095.79]],"ltp":3.4,"tv":31235.11,"id":19924831}]}]}
{"op":"mcm","clk":"4220261754","pt":1631414605033,"mc":[{"id":"1.187528277","rc":[{"trd":[[3.4,11240.14]],"batl":[[0,3.4,1586.12]],"ltp":3.4,"tv":31285.91,"id":19924831}],"tv":142075.96}]}
{"op":"mcm","clk":"4220263122","pt":1631414628153,"mc":[{"id":"1.187528277","rc":[{"trd":[[1.41,45031]],"batb":[[0,1.41,18133.22]],"ltp":1.41,"tv":110836.19,"id":2249229}],"tv":142122.1}]}
{"op":"mcm","clk":"4220264825","pt":1631414656718,"mc":[{"id":"1.187528277","rc":[{"batb":[[0,3.35,2100.66]],"ltp":3.4,"tv":31285.91,"id":19924831},{"batb":[[0,1.41,18144.53]],"ltp":1.41,"tv":110836.19,"id":2249229}]}]}
{"op":"mcm","clk":"4220279064","pt":1631414946482,"mc":[{"id":"1.187528277","rc":[{"trd":[[1.41,45670.21]],"batb":[[0,1.41,17824.94]],"ltp":1.41,"tv":111475.39,"id":2249229}],"tv":142761.31}]}
{"op":"mcm","clk":"4220279110","pt":1631414947359,"mc":[{"id":"1.187528277","rc":[{"batb":[[0,1.41,17821.28],[1,1.4,13510.36]],"ltp":1.41,"tv":111475.39,"id":2249229}]}]}
{"op":"mcm","clk":"4220281274","pt":1631414991632,"mc":[{"id":"1.187528277","rc":[{"batb":[[0,3.35,2121.21]],"ltp":3.4,"tv":31285.91,"id":19924831},{"batb":[[0,1.41,17869.03]],"batl":[[0,1.42,15366.2]],"ltp":1.41,"tv":111475.39,"id":2249229}]}]}
{"op":"mcm","clk":"4220281317","pt":1631414992669,"mc":[{"id":"1.187528277","rc":[{"batl":[[0,3.4,1561.23],[1,3.45,539.27]],"ltp":3.4,"tv":31285.91,"id":19924831}]}]}
{"op":"mcm","clk":"4220281345","pt":1631414993240,"mc":[{"id":"1.187528277","rc":[{"batl":[[1,3.45,535.56]],"ltp":3.4,"tv":31285.91,"id":19924831}]}]}
{"op":"mcm","clk":"4220281379","pt":1631414994063,"mc":[{"id":"1.187528277","rc":[{"batl":[[1,3.45,528.99]],"ltp":3.4,"tv":31285.91,"id":19924831}]}]}
{"op":"mcm","clk":"4220291089","pt":1631415227081,"mc":[{"id":"1.187528277","rc":[{"trd":[[3.4,11290.94]],"batl":[[0,3.4,1535.83]],"ltp":3.4,"tv":31336.71,"id":19924831}],"tv":142812.11}]}
{"op":"mcm","clk":"4220293526","pt":1631415297164,"mc":[{"id":"1.187528277","rc":[{"trd":[[1.41,45776.57]],"batb":[[0,1.41,17815.85]],"ltp":1.41,"tv":111581.75,"id":2249229}],"tv":142918.47}]}
{"op":"mcm","clk":"4220297820","pt":1631415426296,"mc":[{"id":"1.187528277","rc":[{"trd":[[1.41,45790.35]],"batb":[[0,1.41,17808.96]],"ltp":1.41,"tv":111595.53,"id":2249229}],"tv":142932.24}]}
{"op":"mcm","clk":"4220300048","pt":1631415493704,"mc":[{"id":"1.187528277","rc":[{"batb":[[0,3.35,2573.97]],"ltp":3.4,"tv":31336.71,"id":19924831}]}]}
{"op":"mcm","clk":"4220300058","pt":1631415493903,"mc":[{"id":"1.187528277","rc":[{"batb":[[0,3.35,2121.21]],"ltp":3.4,"tv":31336.71,"id":19924831}]}]}
{"op":"mcm","clk":"4220307276","pt":1631415693930,"mc":[{"id":"1.187528277","rc":[{"trd":[[1.41,51789.63]],"batb":[[0,1.41,14809.31]],"ltp":1.41,"tv":117594.81,"id":2249229}],"tv":148931.53}]}
{"op":"mcm","clk":"4220311345","pt":1631415781599,"mc":[{"id":"1.187528277","rc":[{"batb":[[0,1.41,14915.56]],"batl":[[0,1.42,15473.88]],"ltp":1.41,"tv":117594.81,"id":2249229}]}]}
{"op":"mcm","clk":"4220311395","pt":1631415782604,"mc":[{"id":"1.187528277","rc":[{"batb":[[0,3.35,2166.93]],"batl":[[0,3.4,1532.73]],"ltp":3.4,"tv":31336.71,"id":19924831}]}]}
{"op":"mcm","clk":"4220311427","pt":1631415783273,"mc":[{"id":"1.187528277","rc":[{"batl":[[0,3.4,1491.06]],"ltp":3.4,"tv":31336.71,"id":19924831}]}]}
{"op":"mcm","clk":"4220311458","pt":1631415784092,"mc":[{"id":"1.187528277","rc":[{"batl":[[1,3.45,513.99]],"ltp":3.4,"tv":31336.71,"id":19924831}]}]}
{"op":"mcm","clk":"4220311498","pt":1631415784868,"mc":[{"id":"1.187528277","rc":[{"batl":[[1,3.45,485.92]],"ltp":3.4,"tv":31336.71,"id":19924831}]}]}
{"op":"mcm","clk":"4220313582","pt":1631415823557,"mc":[{"id":"1.187528277","rc":[{"trd":[[3.4,14273.06]],"batb":[[0,3.35,2167.45]],"batl":[[0,3.45,485.92],[1,3.5,44.41],[2,3.6,2]],"ltp":3.4,"tv":34318.82,"id":19924831}],"tv":151913.64}]}
{"op":"mcm","clk":"4220314465","pt":1631415839670,"mc":[{"id":"1.187528277","rc":[{"batb":[[0,3.35,2166.93]],"ltp":3.4,"tv":34318.82,"id":19924831}]}]}
{"op":"mcm","clk":"4220315940","pt":1631415869407,"mc":[{"id":"1.187528277","rc":[{"batb":[[0,1.41,14822.43]],"batl":[[0,1.42,15564.79]],"ltp":1.41,"tv":117594.81,"id":2249229}]}]}
{"op":"mcm","clk":"4220315996","pt":1631415870644,"mc":[{"id":"1.187528277","rc":[{"batb":[[0,3.35,2205.53]],"batl":[[0,3.45,448.89]],"ltp":3.4,"tv":34318.82,"id":19924831}]}]}
{"op":"mcm","clk":"4220316021","pt":1631415871110,"mc":[{"id":"1.187528277","rc":[{"batl":[[1,3.5,496.44]],"ltp":3.4,"tv":34318.82,"id":19924831}]}]}
{"op":"mcm","clk":"4220318105","pt":1631415925327,"mc":[{"id":"1.187528277","rc":[{"trd":[[1.41,51791.43]],"batb":[[0,1.41,14821.53]],"ltp":1.41,"tv":117596.61,"id":2249229}],"tv":151915.44}]}
{"op":"mcm","clk":"4220318522","pt":1631415935223,"mc":[{"id":"1.187528277","rc":[{"trd":[[1.41,51808.48]],"batb":[[0,1.41,14813.01]],"ltp":1.41,"tv":117613.66,"id":2249229}],"tv":151932.49}]}
{"op":"mcm","clk":"4220326599","pt":1631416123946,"mc":[{"id":"1.187528277","rc":[{"batb":[[0,1.41,17035.01]],"ltp":1.41,"tv":117613.66,"id":2249229}]}]}
{"op":"mcm","clk":"4220327724","pt":1631416147376,"mc":[{"id":"1.187528277","rc":[{"trd":[[1.42,29657.36]],"batl":[[0,1.42,15538.59]],"ltp":1.42,"tv":117666.06,"id":2249229}],"tv":151984.89}]}
{"op":"mcm","clk":"4220333051","pt":1631416260538,"mc":[{"id":"1.187528277","rc":[{"trd":[[1.41,63765.09]],"batb":[[0,1.41,11056.7]],"ltp":1.41,"tv":129622.68,"id":2249229}],"tv":163941.5}]}
{"op":"mcm","clk":"4220343193","pt":1631416448489,"mc":[{"id":"1.187528277","rc":[{"trd":[[1.41,67217.14]],"batb":[[0,1.41,9330.68]],"ltp":1.41,"tv":133074.72,"id":2249229}],"tv":167393.55}]}
{"op":"mcm","clk":"4220346192","pt":1631416498241,"mc":[{"id":"1.187528277","rc":[{"batb":[[0,3.35,2231.06],[1,3.3,285.34]],"ltp":3.4,"tv":34318.82,"id":19924831},{"trd":[[1.41,72801.97]],"batb":[[0,1.4,13510.36],[1,1.39,10092.82],[2,1.38,15893.65]],"batl":[[0,1.41,309.98],[1,1.42,15538.59],[2,1.43,1729.3]],"ltp":1.41,"tv":138659.55,"id":2249229}],"tv":172978.38}]}
{"op":"mcm","clk":"4220346305","pt":1631416500142,"mc":[{"id":"1.187528277","rc":[{"batl":[[0,1.42,15538.59],[1,1.43,1729.3],[2,1.44,6180.26]],"ltp":1.41,"tv":138659.55,"id":2249229}]}]}
{"op":"mcm","clk":"4220346700","pt":1631416505865,"mc":[{"id":"1.187528277","rc":[{"batb":[[0,3.35,2230.53]],"ltp":3.4,"tv":34318.82,"id":19924831}]}]}
{"op":"mcm","clk":"4220348386","pt":1631416533484,"mc":[{"id":"1.187528277","rc":[{"batb":[[0,3.35,2306.36]],"ltp":3.4,"tv":34318.82,"id":19924831},{"batl":[[0,1.42,15710.54]],"ltp":1.41,"tv":138659.55,"id":2249229}]}]}
{"op":"mcm","clk":"4220348452","pt":1631416534620,"mc":[{"id":"1.187528277","rc":[{"batl":[[0,3.45,409.8]],"ltp":3.4,"tv":34318.82,"id":19924831}]}]}
{"op":"mcm","clk":"4220348491","pt":1631416535290,"mc":[{"id":"1.187528277","rc":[{"batl":[[0,3.45,401.52]],"ltp":3.4,"tv":34318.82,"id":19924831}]}]}
{"op":"mcm","clk":"4220348539","pt":1631416536111,"mc":[{"id":"1.187528277","rc":[{"batl":[[0,3.45,395.98]],"ltp":3.4,"tv":34318.82,"id":19924831}]}]}
{"op":"mcm","clk":"4220348618","pt":1631416537499,"mc":[{"id":"1.187528277","rc":[{"batl":[[0,3.45,315.46]],"ltp":3.4,"tv":34318.82,"id":19924831}]}]}
{"op":"mcm","clk":"4220348713","pt":1631416539504,"mc":[{"id":"1.187528277","rc":[{"batl":[[0,3.45,267.33]],"ltp":3.4,"tv":34318.82,"id":19924831}]}]}
{"op":"mcm","clk":"4220348743","pt":1631416540117,"mc":[{"id":"1.187528277","rc":[{"batl":[[1,3.5,426.79]],"ltp":3.4,"tv":34318.82,"id":19924831}]}]}
{"op":"mcm","clk":"4220350405","pt":1631416573879,"mc":[{"id":"1.187528277","rc":[{"batb":[[0,1.41,222],[1,1.4,13510.36],[2,1.39,10092.82]],"ltp":1.41,"tv":138659.55,"id":2249229}]}]}
{"op":"mcm","clk":"4220352297","pt":1631416613803,"mc":[{"id":"1.187528277","rc":[{"batb":[[0,3.4,49.59],[1,3.35,2306.36],[2,3.3,285.34]],"ltp":3.4,"tv":34318.82,"id":19924831},{"batb":[[0,1.41,341.57]],"ltp":1.41,"tv":138659.55,"id":2249229}]}]}
{"op":"mcm","clk":"4220352358","pt":1631416615106,"mc":[{"id":"1.187528277","rc":[{"batb":[[2,3.3,279.45]],"ltp":3.4,"tv":34318.82,"id":19924831}]}]}
{"op":"mcm","clk":"4220352423","pt":1631416616339,"mc":[{"id":"1.187528277","rc":[{"batb":[[2,3.3,268.05]],"ltp":3.4,"tv":34318.82,"id":19924831}]}]}
{"op":"mcm","clk":"4220352495","pt":1631416617631,"mc":[{"id":"1.187528277","rc":[{"batb":[[2,3.3,127.19]],"ltp":3.4,"tv":34318.82,"id":19924831},{"batb":[[0,1.41,392.8]],"ltp":1.41,"tv":138659.55,"id":2249229}]}]}
{"op":"mcm","clk":"4220352532","pt":1631416618407,"mc":[{"id":"1.187528277","rc":[{"batb":[[0,3.4,57.03]],"batl":[[0,3.45,261.04]],"ltp":3.4,"tv":34318.82,"id":19924831}]}]}
{"op":"mcm","clk":"4220354077","pt":1631416648468,"mc":[{"id":"1.187528277","rc":[{"batb":[[0,3.4,2466.83]],"ltp":3.4,"tv":34318.82,"id":19924831},{"batl":[[0,1.42,15837.3]],"ltp":1.41,"tv":138659.55,"id":2249229}]}]}
{"op":"mcm","clk":"4220355887","pt":1631416684173,"mc":[{"id":"1.187528277","rc":[{"batb":[[0,3.4,2508.67]],"ltp":3.4,"tv":34318.82,"id":19924831},{"batb":[[0,1.41,400.48]],"ltp":1.41,"tv":138659.55,"id":2249229}]}]}
{"op":"mcm","clk":"4220359366","pt":1631416749599,"mc":[{"id":"1.187528277","rc":[{"batl":[[0,3.45,263.71]],"ltp":3.4,"tv":34318.82,"id":19924831}]}]}
{"op":"mcm","clk":"4220361228","pt":1631416786187,"mc":[{"id":"1.187528277","rc":[{"batb":[[0,1.41,800.48]],"ltp":1.41,"tv":138659.55,"id":2249229}]}]}
{"op":"mcm","clk":"4220362589","pt":1631416810603,"mc":[{"id":"1.187528277","rc":[{"batl":[[0,3.45,288.63]],"ltp":3.4,"tv":34318.82,"id":19924831},{"batb":[[0,1.41,861.64]],"ltp":1.41,"tv":138659.55,"id":2249229}]}]}
{"op":"mcm","clk":"4220366712","pt":1631416885487,"mc":[{"id":"1.187528277","rc":[{"trd":[[1.41,72812.61]],"batb":[[0,1.41,856.32]],"ltp":1.41,"tv":138670.19,"id":2249229}],"tv":172989.02}]}
{"op":"mcm","clk":"4220366768","pt":1631416886580,"mc":[{"id":"1.187528277","rc":[{"batl":[[0,3.45,296.12]],"ltp":3.4,"tv":34318.82,"id":19924831},{"batb":[[0,1.41,865.49]],"ltp":1.41,"tv":138670.19,"id":2249229}]}]}
{"op":"mcm","clk":"4220371968","pt":1631416986556,"mc":[{"id":"1.187528277","rc":[{"trd":[[1.41,72929.6]],"batb":[[0,1.41,806.99]],"ltp":1.41,"tv":138787.19,"id":2249229}],"tv":173106.02}]}
{"op":"mcm","clk":"4220377601","pt":1631417099318,"mc":[{"id":"1.187528277","rc":[{"trd":[[1.42,29668]],"batl":[[0,1.42,15831.98]],"ltp":1.42,"tv":138797.83,"id":2249229}],"tv":173116.65}]}
{"op":"mcm","clk":"4220381692","pt":1631417185087,"mc":[{"id":"1.187528277","rc":[{"batl":[[1,3.5,415.68]],"ltp":3.4,"tv":34318.82,"id":19924831}]}]}
{"op":"mcm","clk":"4220396546","pt":1631417557014,"mc":[{"id":"1.187528277","rc":[{"batl":[[1,1.43,1857.4]],"ltp":1.42,"tv":138797.83,"id":2249229}]}]}
{"op":"mcm","clk":"4220397805","pt":1631417595585,"mc":[{"id":"1.187528277","rc":[{"trd":[[3.4,15073.05]],"batb":[[0,3.4,2108.67]],"ltp":3.4,"tv":35118.82,"id":19924831}],"tv":173916.65}]}
{"op":"mcm","clk":"4220399275","pt":1631417634514,"mc":[{"id":"1.187528277","rc":[{"batb":[[0,3.4,2112.39]],"batl":[[1,3.5,418.42]],"ltp":3.4,"tv":35118.82,"id":19924831},{"batl":[[0,1.42,15818.12]],"ltp":1.42,"tv":138797.83,"id":2249229}]}]}
{"op":"mcm","clk":"4220399490","pt":1631417639918,"mc":[{"id":"1.187528277","rc":[{"batb":[[0,1.41,2413.53]],"ltp":1.42,"tv":138797.83,"id":2249229}]}]}
{"op":"mcm","clk":"4220402302","pt":1631417706402,"mc":[{"id":"1.187528277","rc":[{"batb":[[0,1.41,2477.54]],"ltp":1.42,"tv":138797.83,"id":2249229}]}]}
{"op":"mcm","clk":"4220402317","pt":1631417706814,"mc":[{"id":"1.187528277","rc":[{"batl":[[0,3.45,378.95]],"ltp":3.4,"tv":35118.82,"id":19924831}]}]}
{"op":"mcm","clk":"4220406015","pt":1631417812534,"mc":[{"id":"1.187528277","rc":[{"trd":[[1.41,72984.71]],"batb":[[0,1.41,2449.99]],"ltp":1.41,"tv":138852.93,"id":2249229}],"tv":173971.75}]}
{"op":"mcm","clk":"4220407358","pt":1631417856110,"mc":[{"id":"1.187528277","rc":[{"batb":[[0,3.4,2137.38],[1,3.35,2281.37]],"ltp":3.4,"tv":35118.82,"id":19924831}]}]}
{"op":"mcm","clk":"4220408625","pt":1631417894932,"mc":[{"id":"1.187528277","rc":[{"trd":[[1.41,72989.05]],"batb":[[0,1.41,2447.82]],"ltp":1.41,"tv":138857.27,"id":2249229}],"tv":173976.09}]}
{"op":"mcm","clk":"4220410140","pt":1631417945865,"mc":[{"id":"1.187528277","rc":[{"trd":[[1.42,29699.94]],"batl":[[0,1.42,15802.15]],"ltp":1.42,"tv":138889.21,"id":2249229}],"tv":174008.03}]}
{"op":"mcm","clk":"4220416127","pt":1631418109445,"mc":[{"id":"1.187528277","rc":[{"trd":[[1.41,72993.05]],"batb":[[0,1.41,2445.82]],"ltp":1.41,"tv":138893.21,"id":2249229}],"tv":174012.03}]}
{"op":"mcm","clk":"4220422425","pt":1631418244001,"mc":[{"id":"1.187528277","rc":[{"batl":[[0,3.45,483.36]],"ltp":3.4,"tv":35118.82,"id":19924831}]}]}
{"op":"mcm","clk":"4220425543","pt":1631418318211,"mc":[{"id":"1.187528277","rc":[{"trd":[[1.41,75038.31]],"batb":[[0,1.41,1423.21]],"ltp":1.41,"tv":140938.47,"id":2249229}],"tv":176057.29}]}
{"op":"mcm","clk":"4220427004","pt":1631418350469,"mc":[{"id":"1.187528277","rc":[{"batb":[[1,3.35,2305.87]],"ltp":3.4,"tv":35118.82,"id":19924831},{"batb":[[0,1.41,1487.31]],"batl":[[0,1.42,15861.51]],"ltp":1.41,"tv":140938.47,"id":2249229}]}]}
{"op":"mcm","clk":"4220427043","pt":1631418351239,"mc":[{"id":"1.187528277","rc":[{"batb":[[0,3.4,2164.22]],"batl":[[0,3.45,457.07]],"ltp":3.4,"tv":35118.82,"id":19924831}]}]}
{"op":"mcm","clk":"4220427124","pt":1631418352679,"mc":[{"id":"1.187528277","rc":[{"batl":[[1,3.5,392.65]],"ltp":3.4,"tv":35118.82,"id":19924831}]}]}
{"op":"mcm","clk":"4220428578","pt":1631418384959,"mc":[{"id":"1.187528277","rc":[{"trd":[[1.41,78012.92]],"batb":[[0,1.4,13638.93],[1,1.39,10092.82],[2,1.38,15893.65]],"batl":[[0,1.41,512.7],[1,1.42,15861.51],[2,1.43,1857.4]],"ltp":1.41,"tv":143913.08,"id":2249229}],"tv":179031.9}]}
{"op":"mcm","clk":"4220430534","pt":1631418433628,"mc":[{"id":"1.187528277","rc":[{"batl":[[2,1.43,1842.03]],"ltp":1.41,"tv":143913.08,"id":2249229}]}]}
{"op":"mcm","clk":"4220430559","pt":1631418434201,"mc":[{"id":"1.187528277","rc":[{"batl":[[2,1.43,1530.83]],"ltp":1.41,"tv":143913.08,"id":2249229}]}]}
{"op":"mcm","clk":"4220430612","pt":1631418435633,"mc":[{"id":"1.187528277","rc":[{"batl":[[2,1.43,1405.37]],"ltp":1.41,"tv":143913.08,"id":2249229}]}]}
{"op":"mcm","clk":"4220430640","pt":1631418436512,"mc":[{"id":"1.187528277","rc":[{"batb":[[0,1.4,13864.07],[1,1.39,10544.85]],"ltp":1.41,"tv":143913.08,"id":2249229}]}]}
{"op":"mcm","clk":"4220430684","pt":1631418437595,"mc":[{"id":"1.187528277","rc":[{"batb":[[0,3.4,2191.73],[1,3.35,2333.97]],"batl":[[0,3.45,400.53]],"ltp":3.4,"tv":35118.82,"id":19924831}]}]}
{"op":"mcm","clk":"4220430699","pt":1631418438110,"mc":[{"id":"1.187528277","rc":[{"batl":[[0,3.45,393.04]],"ltp":3.4,"tv":35118.82,"id":19924831}]}]}
{"op":"mcm","clk":"4220430744","pt":1631418439237,"mc":[{"id":"1.187528277","rc":[{"batl":[[0,3.45,372.97],[1,3.5,366.24]],"ltp":3.4,"tv":35118.82,"id":19924831}]}]}
{"op":"mcm","clk":"4220431655","pt":1631418463456,"mc":[{"id":"1.187528277","rc":[{"batb":[[0,3.4,2217.13]],"ltp":3.4,"tv":35118.82,"id":19924831}]}]}
{"op":"mcm","clk":"4220443123","pt":1631418482784,"mc":[{"id":"1.187528277","rc":[{"trd":[[1.41,78065.7]],"batl":[[0,1.41,486.31]],"ltp":1.41,"tv":143965.86,"id":2249229}],"tv":179084.69}]}
{"op":"mcm","clk":"4220444743","pt":1631418521567,"mc":[{"id":"1.187528277","rc":[{"batl":[[0,3.45,368.12]],"ltp":3.4,"tv":35118.82,"id":19924831}]}]}
{"op":"mcm","clk":"4220444767","pt":1631418522088,"mc":[{"id":"1.187528277","rc":[{"batl":[[0,3.45,365.45]],"ltp":3.4,"tv":35118.82,"id":19924831}]}]}
{"op":"mcm","clk":"4220444787","pt":1631418522763,"mc":[{"id":"1.187528277","rc":[{"batl":[[0,3.45,360.36]],"ltp":3.4,"tv":35118.82,"id":19924831}]}]}
