{"op":"mcm","clk":"4299314408","pt":1632580360319,"mc":[{"id":"1.188136695","rc":[{"batl":[[1,1.35,10.93]],"ltp":1.32,"tv":89789.42,"id":5300737}]}]}
{"op":"mcm","clk":"4299314822","pt":1632580361739,"mc":[{"id":"1.188136695","rc":[{"batb":[[0,1.3,404.14],[1,1.29,1205.69],[2,1.28,2543.19]],"batl":[[0,1.35,10.93],[1,1.38,142.25],[2,1.39,1053.04]],"ltp":1.32,"tv":89789.42,"id":5300737},{"batb":[[0,3.65,184.49],[1,3.6,6.14],[2,3.55,2.42]],"ltp":4.1,"tv":24292.85,"id":2497008}]}]}
{"op":"mcm","clk":"4299315170","pt":1632580362629,"mc":[{"id":"1.188136695","rc":[{"batb":[[0,1.33,10],[1,1.32,10.04],[2,1.3,403.38]],"batl":[[1,1.36,151.82],[2,1.38,142.25]],"ltp":1.32,"tv":89789.42,"id":5300737},{"batb":[[0,3.75,5.63],[1,3.65,184.49],[2,3.6,6.14]],"ltp":4.1,"tv":24292.85,"id":2497008}]}]}
{"op":"mcm","clk":"4299315486","pt":1632580363736,"mc":[{"id":"1.188136695","rc":[{"trd":[[1.32,2306.02],[1.33,487.24]],"batb":[[0,1.3,403.38],[1,1.29,1196.47],[2,1.28,2543.19]],"batl":[[0,1.31,2201.96],[1,1.32,432.84],[2,1.35,10.93]],"ltp":1.32,"tv":89829.5,"id":5300737},{"batb":[[0,3.65,184.49],[1,3.6,6.14],[2,3.55,2.42]],"ltp":4.1,"tv":24292.85,"id":2497008}],"tv":114122.35}]}
{"op":"mcm","clk":"4299315747","pt":1632580364672,"mc":[{"id":"1.188136695","rc":[{"batl":[[1,1.32,11796.71],[2,1.33,4313.91]],"ltp":1.32,"tv":89829.5,"id":5300737},{"batb":[[0,3.7,4.33],[1,3.65,184.49],[2,3.6,6.14]],"ltp":4.1,"tv":24292.85,"id":2497008}]}]}
{"op":"mcm","clk":"4299316103","pt":1632580365614,"mc":[{"id":"1.188136695","rc":[{"batl":[[0,1.31,30.5],[1,1.32,433.65],[2,1.33,1294.18]],"ltp":1.32,"tv":89829.5,"id":5300737},{"batb":[[0,4.2,3.17],[1,4,2],[2,3.7,4.33]],"ltp":4.1,"tv":24292.85,"id":2497008}]}]}
{"op":"mcm","clk":"4299316457","pt":1632580366829,"mc":[{"id":"1.188136695","rc":[{"trd":[[1.31,872.99],[1.32,2689.64]],"batl":[[0,1.32,1545.98],[1,1.33,2240.48],[2,1.34,1263.11]],"ltp":1.32,"tv":90251.81,"id":5300737},{"trd":[[4.2,75.39]],"batb":[[0,4.2,255.68],[1,4,32],[2,3.9,159.38]],"ltp":4.2,"tv":24306.15,"id":2497008}],"tv":114557.96}]}
{"op":"mcm","clk":"4299317305","pt":1632580369830,"mc":[{"id":"1.188136695","rc":[{"trd":[[1.31,892.99]],"batb":[[0,1.3,484.77],[1,1.29,1275.7]],"batl":[[0,1.31,128.18],[1,1.32,1992.6],[2,1.33,2479.72]],"ltp":1.31,"tv":90271.81,"id":5300737},{"batl":[[0,4.4,90.82]],"ltp":4.2,"tv":24306.15,"id":2497008}],"tv":114577.96}]}
{"op":"mcm","clk":"4299317568","pt":1632580370764,"mc":[{"id":"1.188136695","rc":[{"batb":[[0,1.3,486.65]],"batl":[[1,1.32,2230.6],[2,1.33,2314.72]],"ltp":1.31,"tv":90271.81,"id":5300737},{"batb":[[1,4,2]],"batl":[[0,4.4,76.09]],"ltp":4.2,"tv":24306.15,"id":2497008}]}]}
{"op":"mcm","clk":"4299317854","pt":1632580371760,"mc":[{"id":"1.188136695","rc":[{"batl":[[1,1.32,1989.56]],"ltp":1.31,"tv":90271.81,"id":5300737},{"trd":[[4.2,75.58]],"batb":[[0,4.2,255.59]],"ltp":4.2,"tv":24306.34,"id":2497008}],"tv":114578.15}]}
{"op":"mcm","clk":"4299318108","pt":1632580372647,"mc":[{"id":"1.188136695","rc":[{"trd":[[4.2,395.84]],"batb":[[0,4.2,95.46]],"ltp":4.2,"tv":24626.6,"id":2497008}],"tv":114898.41}]}
{"op":"mcm","clk":"4299318372","pt":1632580373570,"mc":[{"id":"1.188136695","rc":[{"batl":[[2,1.33,2404.72]],"ltp":1.31,"tv":90271.81,"id":5300737},{"batb":[[1,4.1,29.03],[2,4,2]],"ltp":4.2,"tv":24626.6,"id":2497008}]}]}
{"op":"mcm","clk":"4299318783","pt":1632580374879,"mc":[{"id":"1.188136695","rc":[{"batl":[[2,1.33,2330.48]],"ltp":1.31,"tv":90271.81,"id":5300737}]}]}
{"op":"mcm","clk":"4299319373","pt":1632580376754,"mc":[{"id":"1.188136695","rc":[{"trd":[[1.3,6894.42]],"batb":[[0,1.3,486.58],[1,1.29,1196.47]],"batl":[[1,1.32,2429.32],[2,1.33,2858.46]],"ltp":1.3,"tv":90271.96,"id":5300737},{"batb":[[1,4.1,170.87],[2,4,177.55]],"ltp":4.2,"tv":24626.6,"id":2497008}],"tv":114898.56}]}
{"op":"mcm","clk":"4299319701","pt":1632580377730,"mc":[{"id":"1.188136695","rc":[{"trd":[[1.31,895]],"batl":[[0,1.31,133.33]],"ltp":1.31,"tv":90273.96,"id":5300737}],"tv":114900.56}]}
{"op":"mcm","clk":"4299319860","pt":1632580378346,"mc":[{"id":"1.188136695","rc":[{"trd":[[1.31,1161.65]],"batb":[[0,1.31,95.76],[1,1.3,486.58],[2,1.29,1196.47]],"batl":[[0,1.32,2429.32],[1,1.33,2858.46],[2,1.34,1406.86]],"ltp":1.31,"tv":90540.62,"id":5300737}],"tv":115167.22}]}
{"op":"mcm","clk":"4299320348","pt":1632580380268,"mc":[{"id":"1.188136695","rc":[{"batb":[[1,1.3,993.14],[2,1.29,1893.3]],"ltp":1.31,"tv":90540.62,"id":5300737},{"batl":[[0,4.4,225.76],[1,4.5,287.17]],"ltp":4.2,"tv":24626.6,"id":2497008}]}]}
{"op":"mcm","clk":"4299320716","pt":1632580381681,"mc":[{"id":"1.188136695","rc":[{"batb":[[1,1.3,486.58],[2,1.29,784.08]],"batl":[[0,1.32,1947.81],[1,1.33,1036.3],[2,1.34,7]],"ltp":1.31,"tv":90540.62,"id":5300737},{"batb":[[1,4.1,29.03],[2,4,2]],"batl":[[0,4.7,72.82],[1,4.8,72.5],[2,4.9,107.74]],"ltp":4.2,"tv":24626.6,"id":2497008}]}]}
{"op":"mcm","clk":"4299321074","pt":1632580382768,"mc":[{"id":"1.188136695","rc":[{"batb":[[2,1.28,20.42]],"batl":[[0,1.32,60.96],[1,1.35,149.3],[2,1.36,152.24]],"ltp":1.31,"tv":90540.62,"id":5300737},{"batb":[[0,3.9,159.38],[1,3.85,5.37],[2,3.75,5.87]],"batl":[[0,4.7,70.82]],"ltp":4.2,"tv":24626.6,"id":2497008}]}]}
{"op":"mcm","clk":"4299321554","pt":1632580384462,"mc":[{"id":"1.188136695","rc":[{"trd":[[1.31,1164.45]],"batb":[[0,1.31,94.36]],"ltp":1.31,"tv":90543.41,"id":5300737}],"tv":115170.02}]}
{"op":"mcm","clk":"4299321964","pt":1632580385776,"mc":[{"id":"1.188136695","rc":[{"batl":[[1,1.34,144.25],[2,1.35,149.3]],"ltp":1.31,"tv":90543.41,"id":5300737},{"batb":[[0,3.9,5.76],[2,3.75,170.66]],"ltp":4.2,"tv":24626.6,"id":2497008}]}]}
{"op":"mcm","clk":"4299322055","pt":1632580386061,"mc":[{"id":"1.188136695","rc":[{"trd":[[1.31,1219.27]],"batb":[[0,1.31,66.95]],"ltp":1.31,"tv":90598.24,"id":5300737}],"tv":115224.84}]}
{"op":"mcm","clk":"4299322571","pt":1632580387656,"mc":[{"id":"1.188136695","rc":[{"trd":[[1.28,70.4],[1.3,7867.58],[1.31,1353.17]],"batb":[[0,1.31,1.76],[1,1.27,815.68],[2,1.26,3837.08]],"ltp":1.28,"tv":91746.14,"id":5300737}],"tv":116372.74}]}
{"op":"mcm","clk":"4299322781","pt":1632580388381,"mc":[{"id":"1.188136695","rc":[{"batb":[[0,1.31,2.11]],"ltp":1.28,"tv":91746.14,"id":5300737}]}]}
{"op":"mcm","clk":"4299324200","pt":1632580392790,"mc":[{"id":"1.188136695","rc":[{"batb":[[1,1.27,295.47],[2,1.26,2324.9]],"batl":[[0,1.36,152.24],[1,1.37,367.15],[2,1.38,398.29]],"ltp":1.28,"tv":91746.14,"id":5300737},{"batb":[[0,3.75,170.66],[1,3.7,83.08],[2,3.65,79.2]],"batl":[[2,4.9,103.79]],"ltp":4.2,"tv":24626.6,"id":2497008}]}]}
{"op":"mcm","clk":"4299324440","pt":1632580393581,"mc":[{"id":"1.188136695","rc":[{"batb":[[0,1.31,2.14]],"ltp":1.28,"tv":91746.14,"id":5300737}]}]}
{"op":"mcm","clk":"4299325116","pt":1632580395791,"mc":[{"id":"1.188136695","rc":[{"batb":[[0,1.32,7.34],[1,1.31,1.79],[2,1.27,295.47]],"ltp":1.28,"tv":91746.14,"id":5300737}]}]}
{"op":"mcm","clk":"4299325410","pt":1632580396698,"mc":[{"id":"1.188136695","rc":[{"trd":[[1.31,1356.75],[1.32,2704.32]],"batb":[[0,1.27,295.47],[1,1.26,2324.9],[2,1.25,1245.08]],"batl":[[0,1.31,90.87],[1,1.36,154.24],[2,1.37,367.15]],"ltp":1.31,"tv":91764.4,"id":5300737},{"batb":[[0,3.75,173.66],[1,3.7,86.08]],"batl":[[0,4.7,111.35]],"ltp":4.2,"tv":24626.6,"id":2497008}],"tv":116391.0}]}
{"op":"mcm","clk":"4299326724","pt":1632580400398,"mc":[{"id":"1.188136695","rc":[{"batb":[[0,1.28,20],[1,1.27,360.52],[2,1.26,2324.9]],"batl":[[1,1.35,2.5],[2,1.36,152.24]],"ltp":1.31,"tv":91764.4,"id":5300737},{"batb":[[0,3.8,86.3],[1,3.75,170.66],[2,3.7,83.08]],"ltp":4.2,"tv":24626.6,"id":2497008}]}]}
{"op":"mcm","clk":"4299327215","pt":1632580401772,"mc":[{"id":"1.188136695","rc":[{"trd":[[1.31,1381.45]],"batl":[[0,1.31,79.57]],"ltp":1.31,"tv":91789.1,"id":5300737}],"tv":116415.7}]}
{"op":"mcm","clk":"4299327469","pt":1632580402618,"mc":[{"id":"1.188136695","rc":[{"trd":[[1.31,1401.45]],"batb":[[1,1.27,295.47]],"batl":[[0,1.31,69.57]],"ltp":1.31,"tv":91809.1,"id":5300737},{"batl":[[0,4.7,70.82]],"ltp":4.2,"tv":24626.6,"id":2497008}],"tv":116435.7}]}
{"op":"mcm","clk":"4299327770","pt":1632580403591,"mc":[{"id":"1.188136695","rc":[{"batb":[[0,3.75,170.66],[1,3.7,83.08],[2,3.65,79.2]],"ltp":4.2,"tv":24626.6,"id":2497008}]}]}
{"op":"mcm","clk":"4299328686","pt":1632580406386,"mc":[{"id":"1.188136695","rc":[{"batl":[[0,1.29,2222],[1,1.3,432.84],[2,1.31,69.57]],"ltp":1.31,"tv":91809.1,"id":5300737},{"batb":[[0,3.8,21.24],[1,3.75,170.66],[2,3.7,83.08]],"ltp":4.2,"tv":24626.6,"id":2497008}]}]}
{"op":"mcm","clk":"4299329056","pt":1632580407496,"mc":[{"id":"1.188136695","rc":[{"batb":[[0,1.27,295.47],[1,1.26,2324.9],[2,1.25,1245.08]],"ltp":1.31,"tv":91809.1,"id":5300737},{"batb":[[0,3.8,46.25]],"ltp":4.2,"tv":24626.6,"id":2497008}]}]}
{"op":"mcm","clk":"4299329491","pt":1632580408793,"mc":[{"id":"1.188136695","rc":[{"trd":[[1.29,4610.31]],"batl":[[0,1.29,2221.08]],"ltp":1.29,"tv":91810.37,"id":5300737},{"trd":[[4.4,59.61]],"batb":[[0,3.8,21.24]],"ltp":4.4,"tv":24626.76,"id":2497008}],"tv":116437.14}]}
{"op":"mcm","clk":"4299329664","pt":1632580409390,"mc":[{"id":"1.188136695","rc":[{"trd":[[1.29,4612.07]],"batl":[[0,1.3,432.84],[1,1.31,69.57],[2,1.35,2.5]],"ltp":1.29,"tv":91812.13,"id":5300737}],"tv":116438.9}]}
{"op":"mcm","clk":"4299330439","pt":1632580411788,"mc":[{"id":"1.188136695","rc":[{"batb":[[0,1.29,5.91],[1,1.27,295.47],[2,1.26,2324.9]],"batl":[[0,1.31,69.57],[1,1.33,952.26]],"ltp":1.29,"tv":91812.13,"id":5300737}]}]}
{"op":"mcm","clk":"4299330780","pt":1632580412801,"mc":[{"id":"1.188136695","rc":[{"batb":[[1,1.27,284.37]],"batl":[[1,1.35,2.5],[2,1.36,152.24]],"ltp":1.29,"tv":91812.13,"id":5300737},{"batb":[[2,3.7,10.65]],"ltp":4.4,"tv":24626.76,"id":2497008}]}]}
{"op":"mcm","clk":"4299331080","pt":1632580413694,"mc":[{"id":"1.188136695","rc":[{"trd":[[1.29,4623.89],[1.31,1402.85]],"batb":[[0,1.28,6.12]],"batl":[[0,1.31,287.86],[1,1.32,212.55],[2,1.33,212.55]],"ltp":1.29,"tv":91825.35,"id":5300737}],"tv":116452.11}]}
{"op":"mcm","clk":"4299331376","pt":1632580414716,"mc":[{"id":"1.188136695","rc":[{"trd":[[1.28,82.64]],"batb":[[0,1.26,2324.9],[1,1.25,1245.08],[2,1.24,952.26]],"batl":[[0,1.28,210.22],[1,1.31,287.86],[2,1.32,212.55]],"ltp":1.28,"tv":91837.59,"id":5300737},{"batl":[[0,4.8,72.5],[1,4.9,103.79],[2,5.4,5.24]],"ltp":4.4,"tv":24626.76,"id":2497008}],"tv":116464.35}]}
{"op":"mcm","clk":"4299331723","pt":1632580415804,"mc":[{"id":"1.188136695","rc":[{"trd":[[1.28,97.91]],"batl":[[0,1.28,202.58],[1,1.31,1382.8],[2,1.32,1275.29]],"ltp":1.28,"tv":91852.86,"id":5300737},{"batl":[[2,5,344.26]],"ltp":4.4,"tv":24626.76,"id":2497008}],"tv":116479.63}]}
{"op":"mcm","clk":"4299332025","pt":1632580416802,"mc":[{"id":"1.188136695","rc":[{"trd":[[1.28,131.38]],"batb":[[0,1.26,1997.21],[1,1.25,964.59],[2,1.24,2087.52]],"batl":[[0,1.29,90],[1,1.31,68.87],[2,1.32,8]],"ltp":1.28,"tv":91886.33,"id":5300737},{"trd":[[4.5,9.52]],"batb":[[0,4.4,224.06],[1,4.3,27.27],[2,4.2,2]],"batl":[[0,4.9,1],[1,5.4,5.24],[2,5.9,2.71]],"ltp":4.5,"tv":24636.28,"id":2497008}],"tv":116522.62}]}
{"op":"mcm","clk":"4299332353","pt":1632580417712,"mc":[{"id":"1.188136695","rc":[{"trd":[[1.29,4624.59]],"batb":[[0,1.26,953.66]],"batl":[[0,1.31,68.87],[1,1.35,2.5],[2,1.37,138.5]],"ltp":1.29,"tv":91887.03,"id":5300737},{"batb":[[0,4,282.65],[1,3.8,21.24],[2,3.7,10.65]],"ltp":4.5,"tv":24636.28,"id":2497008}],"tv":116523.32}]}
{"op":"mcm","clk":"4299332500","pt":1632580418208,"mc":[{"id":"1.188136695","rc":[{"trd":[[1.3,7868.38]],"batb":[[0,1.26,953.26]],"batl":[[0,1.28,9.6],[1,1.31,68.87],[2,1.35,2.5]],"ltp":1.3,"tv":91887.83,"id":5300737}],"tv":116524.12}]}
{"op":"mcm","clk":"4299333007","pt":1632580419825,"mc":[{"id":"1.188136695","rc":[{"trd":[[1.28,150.58],[1.31,1453.77]],"batb":[[0,1.26,1]],"batl":[[0,1.28,27.56],[1,1.29,54.68],[2,1.3,79.57]],"ltp":1.31,"tv":91957.95,"id":5300737},{"batl":[[1,5.3,10.85],[2,5.4,5.24]],"ltp":4.5,"tv":24636.28,"id":2497008}],"tv":116594.24}]}
{"op":"mcm","clk":"4299333179","pt":1632580420374,"mc":[{"id":"1.188136695","rc":[{"trd":[[1.28,155.28]],"batb":[[0,1.27,59.53],[1,1.26,1],[2,1.25,1789.37]],"batl":[[0,1.28,25.21]],"ltp":1.28,"tv":91962.65,"id":5300737},{"batl":[[1,5.4,5.24],[2,5.9,2.71]],"ltp":4.5,"tv":24636.28,"id":2497008}],"tv":116598.94}]}
{"op":"mcm","clk":"4299333471","pt":1632580421802,"mc":[{"id":"1.188136695","rc":[{"trd":[[1.26,2],[1.27,119.06]],"batb":[[0,1.25,1824.43],[1,1.24,3540.88],[2,1.23,1160.89]],"batl":[[0,1.26,36.51],[1,1.28,25.21],[2,1.29,54.68]],"ltp":1.26,"tv":92083.71,"id":5300737},{"batb":[[2,3.7,4.33]],"ltp":4.5,"tv":24636.28,"id":2497008}],"tv":116720.0}]}
{"op":"mcm","clk":"4299333882","pt":1632580422439,"mc":[{"id":"1.188136695","rc":[{"trd":[[1.26,7]],"batb":[[0,1.25,872.17]],"batl":[[0,1.26,34.01]],"ltp":1.26,"tv":92088.71,"id":5300737}],"tv":116725.0}]}
{"op":"mcm","clk":"4299334352","pt":1632580423734,"mc":[{"id":"1.188136695","rc":[{"batl":[[1,1.28,2680.05]],"ltp":1.26,"tv":92088.71,"id":5300737},{"batb":[[0,4.5,63.75],[1,4.4,61.88],[2,4.3,61.88]],"ltp":4.5,"tv":24636.28,"id":2497008}]}]}
{"op":"mcm","clk":"4299334713","pt":1632580424827,"mc":[{"id":"1.188136695","rc":[{"batb":[[0,4.7,4],[1,4.5,382.5],[2,4.4,371.26]],"batl":[[1,5.3,324.77],[2,5.4,320.46]],"ltp":4.5,"tv":24636.28,"id":2497008}]}]}
{"op":"mcm","clk":"4299335020","pt":1632580425734,"mc":[{"id":"1.188136695","rc":[{"trd":[[1.26,41.01]],"batb":[[2,1.23,2379.18]],"batl":[[0,1.27,644.74],[1,1.28,3917.02],[2,1.3,8]],"ltp":1.26,"tv":92122.72,"id":5300737},{"trd":[[4.7,0.32],[4.8,8.93]],"batb":[[0,4.7,1.84],[1,4.6,223.1],[2,4.5,382.5]],"ltp":4.7,"tv":24645.53,"id":2497008}],"tv":116768.26}]}
{"op":"mcm","clk":"4299335333","pt":1632580426753,"mc":[{"id":"1.188136695","rc":[{"batl":[[1,1.28,1605.02]],"ltp":1.26,"tv":92122.72,"id":5300737}]}]}
{"op":"mcm","clk":"4299336050","pt":1632580428831,"mc":[{"id":"1.188136695","rc":[{"batb":[[0,1.26,80.82],[1,1.25,872.17],[2,1.24,3540.88]],"batl":[[0,1.27,859.23],[1,1.28,1773.85],[2,1.29,683.98]],"ltp":1.26,"tv":92122.72,"id":5300737},{"batb":[[1,4.6,198.1],[2,4.5,537.31]],"ltp":4.7,"tv":24645.53,"id":2497008}]}]}
{"op":"mcm","clk":"4299336305","pt":1632580429656,"mc":[{"id":"1.188136695","rc":[{"batl":[[0,1.27,1311.67]],"ltp":1.26,"tv":92122.72,"id":5300737}]}]}
{"op":"mcm","clk":"4299336500","pt":1632580430326,"mc":[{"id":"1.188136695","rc":[{"batb":[[0,1.26,81.17],[1,1.25,1376.16],[2,1.24,4161.44]],"ltp":1.26,"tv":92122.72,"id":5300737},{"batl":[[1,5,126],[2,5.2,147.97]],"ltp":4.7,"tv":24645.53,"id":2497008}]}]}
{"op":"mcm","clk":"4299336949","pt":1632580431738,"mc":[{"id":"1.188136695","rc":[{"batb":[[2,1.24,4397.33]],"batl":[[0,1.27,1796.8],[1,1.28,2340.41]],"ltp":1.26,"tv":92122.72,"id":5300737},{"batb":[[0,4.7,132.93],[2,4.5,698.46]],"batl":[[2,5.1,59.52]],"ltp":4.7,"tv":24645.53,"id":2497008}]}]}
{"op":"mcm","clk":"4299337284","pt":1632580432749,"mc":[{"id":"1.188136695","rc":[{"batb":[[0,1.26,84.68]],"ltp":1.26,"tv":92122.72,"id":5300737},{"batb":[[0,4.7,157.25]],"ltp":4.7,"tv":24645.53,"id":2497008}]}]}
{"op":"mcm","clk":"4299337923","pt":1632580434652,"mc":[{"id":"1.188136695","rc":[{"trd":[[1.27,127.08]],"batb":[[1,1.25,47.39],[2,1.24,1188.15]],"batl":[[0,1.27,304.49],[1,1.3,8],[2,1.31,198.57]],"ltp":1.27,"tv":92130.74,"id":5300737},{"batb":[[0,4.7,26.16],[1,4.3,234.46],[2,4.2,85.24]],"batl":[[1,5.1,59.52],[2,5.2,66.46]],"ltp":4.7,"tv":24645.53,"id":2497008}],"tv":116776.28}]}
{"op":"mcm","clk":"4299338263","pt":1632580435732,"mc":[{"id":"1.188136695","rc":[{"trd":[[1.26,75.46]],"batb":[[0,1.25,104.03],[1,1.24,1188.15],[2,1.23,2650.13]],"batl":[[0,1.26,70.27],[1,1.27,388.02]],"ltp":1.26,"tv":92165.19,"id":5300737},{"batb":[[0,4.3,234.46],[1,4.2,85.24],[2,4.1,93.61]],"ltp":4.7,"tv":24645.53,"id":2497008}],"tv":116810.73}]}
{"op":"mcm","clk":"4299338317","pt":1632580435941,"mc":[{"id":"1.188136695","rc":[{"trd":[[1.26,76.16]],"batl":[[0,1.26,147.68],[1,1.27,74.02]],"ltp":1.26,"tv":92165.89,"id":5300737}],"tv":116811.43}]}
{"op":"mcm","clk":"4299339173","pt":1632580438766,"mc":[{"id":"1.188136695","rc":[{"trd":[[1.26,78.18]],"batb":[[0,1.25,164.03]],"batl":[[0,1.26,145.65]],"ltp":1.26,"tv":92167.92,"id":5300737},{"trd":[[4.8,9.46]],"ltp":4.8,"tv":24646.06,"id":2497008}],"tv":116813.98}]}
{"op":"mcm","clk":"4299339477","pt":1632580439649,"mc":[{"id":"1.188136695","rc":[{"batb":[[2,1.23,4646.38]],"batl":[[2,1.3,1527.92]],"ltp":1.26,"tv":92167.92,"id":5300737}]}]}
{"op":"mcm","clk":"4299339768","pt":1632580440658,"mc":[{"id":"1.188136695","rc":[{"trd":[[1.26,78.89]],"batb":[[0,1.25,107.39]],"batl":[[0,1.26,145.3]],"ltp":1.26,"tv":92168.62,"id":5300737},{"batb":[[1,3.8,21.24],[2,3.7,4.33]],"ltp":4.8,"tv":24646.06,"id":2497008}],"tv":116814.69}]}
{"op":"mcm","clk":"4299339879","pt":1632580441058,"mc":[{"id":"1.188136695","rc":[{"batl":[[2,1.31,1.4]],"ltp":1.26,"tv":92168.62,"id":5300737}]}]}
{"op":"mcm","clk":"4299340440","pt":1632580442759,"mc":[{"id":"1.188136695","rc":[{"trd":[[1.26,83.4]],"batl":[[0,1.26,2623.21],[1,1.27,1353.64],[2,1.28,1240.08]],"ltp":1.26,"tv":92173.13,"id":5300737}],"tv":116819.2}]}
{"op":"mcm","clk":"4299340735","pt":1632580443645,"mc":[{"id":"1.188136695","rc":[{"trd":[[1.26,179.08]],"batb":[[1,1.24,235.9]],"batl":[[0,1.26,3071.39],[1,1.27,2134.87],[2,1.28,1488.1]],"ltp":1.26,"tv":92268.81,"id":5300737},{"trd":[[4.9,2]],"batb":[[0,4.9,3],[1,4.3,234.46],[2,3.8,21.24]],"batl":[[0,5.1,59.52],[1,5.2,66.46],[2,5.3,95.09]],"ltp":4.9,"tv":24648.06,"id":2497008}],"tv":116916.88}]}
{"op":"mcm","clk":"4299341097","pt":1632580444756,"mc":[{"id":"1.188136695","rc":[{"batl":[[0,1.26,1791.08],[1,1.27,2165.04],[2,1.28,310.02]],"ltp":1.26,"tv":92268.81,"id":5300737},{"trd":[[4.8,24.86],[4.9,4]],"batb":[[0,4.8,170.62],[1,4.6,199.71]],"ltp":4.8,"tv":24665.46,"id":2497008}],"tv":116934.28}]}
{"op":"mcm","clk":"4299342095","pt":1632580447761,"mc":[{"id":"1.188136695","rc":[{"trd":[[1.25,90],[1.26,180.68]],"batb":[[0,1.25,86.53]],"batl":[[0,1.26,2908.31]],"ltp":1.26,"tv":92360.42,"id":5300737},{"trd":[[5,22.5]],"ltp":5.0,"tv":24687.96,"id":2497008}],"tv":117048.39}]}
{"op":"mcm","clk":"4299342427","pt":1632580448828,"mc":[{"id":"1.188136695","rc":[{"batl":[[0,1.26,3295.26],[1,1.27,2255.04]],"ltp":1.26,"tv":92360.42,"id":5300737},{"batb":[[0,4.8,183.53]],"ltp":5.0,"tv":24687.96,"id":2497008}]}]}
{"op":"mcm","clk":"4299342681","pt":1632580449661,"mc":[{"id":"1.188136695","rc":[{"trd":[[1.26,182.68]],"batl":[[0,1.26,3773.39],[1,1.27,2778.74]],"ltp":1.26,"tv":92362.42,"id":5300737},{"trd":[[4.8,24.88]],"batb":[[0,4.8,309.28],[1,4.7,141.51],[2,4.6,199.71]],"ltp":4.8,"tv":24687.98,"id":2497008}],"tv":117050.4}]}
{"op":"mcm","clk":"4299343062","pt":1632580450752,"mc":[{"id":"1.188136695","rc":[{"trd":[[1.25,263.07]],"batb":[[0,1.23,4870.96],[1,1.22,3894.65],[2,1.21,3054.01]],"batl":[[0,1.25,341.62],[1,1.26,3773.39],[2,1.27,2778.74]],"ltp":1.25,"tv":92535.48,"id":5300737},{"batb":[[1,4.7,165.83]],"batl":[[0,5.2,66.46],[1,5.3,164.96],[2,5.4,74.86]],"ltp":4.8,"tv":24687.98,"id":2497008}],"tv":117223.47}]}
{"op":"mcm","clk":"4299343813","pt":1632580452753,"mc":[{"id":"1.188136695","rc":[{"trd":[[1.25,271.64]],"batb":[[0,1.24,75.12],[1,1.23,4870.96],[2,1.22,3894.65]],"batl":[[0,1.25,436.8],[1,1.26,2722.87]],"ltp":1.25,"tv":92544.06,"id":5300737}],"tv":117232.04}]}
{"op":"mcm","clk":"4299344149","pt":1632580453769,"mc":[{"id":"1.188136695","rc":[{"trd":[[1.25,285.66]],"batb":[[1,1.23,4929.64]],"batl":[[0,1.25,429.79]],"ltp":1.25,"tv":92558.08,"id":5300737}],"tv":117246.06}]}
{"op":"mcm","clk":"4299344709","pt":1632580455556,"mc":[{"id":"1.188136695","rc":[{"batb":[[2,1.22,4123.99]],"batl":[[1,1.26,2890.62]],"ltp":1.25,"tv":92558.08,"id":5300737},{"batb":[[0,4.8,314.01]],"ltp":4.8,"tv":24687.98,"id":2497008}]}]}
{"op":"mcm","clk":"4299345109","pt":1632580456749,"mc":[{"id":"1.188136695","rc":[{"batb":[[0,1.24,1027.38]],"batl":[[0,1.25,684.61],[1,1.26,2823.11]],"ltp":1.25,"tv":92558.08,"id":5300737}]}]}
{"op":"mcm","clk":"4299345453","pt":1632580457786,"mc":[{"id":"1.188136695","rc":[{"batl":[[0,1.25,1020.61]],"ltp":1.25,"tv":92558.08,"id":5300737}]}]}
{"op":"mcm","clk":"4299346039","pt":1632580459556,"mc":[{"id":"1.188136695","rc":[{"trd":[[1.24,1.4],[1.25,288.46]],"batb":[[0,1.24,1026.67]],"batl":[[0,1.25,1019.21]],"ltp":1.25,"tv":92562.28,"id":5300737}],"tv":117250.27}]}
{"op":"mcm","clk":"4299346247","pt":1632580460202,"mc":[{"id":"1.188136695","rc":[{"batb":[[0,1.24,74.42]],"ltp":1.25,"tv":92562.28,"id":5300737}]}]}
{"op":"mcm","clk":"4299346764","pt":1632580461749,"mc":[{"id":"1.188136695","rc":[{"trd":[[1.24,34.66]],"batb":[[0,1.24,57.79]],"batl":[[0,1.25,1019.12]],"ltp":1.24,"tv":92595.54,"id":5300737}],"tv":117283.52}]}
{"op":"mcm","clk":"4299347628","pt":1632580464551,"mc":[{"id":"1.188136695","rc":[{"trd":[[1.25,338.46]],"batl":[[0,1.25,994.12]],"ltp":1.25,"tv":92645.54,"id":5300737}],"tv":117333.52}]}
{"op":"mcm","clk":"4299348029","pt":1632580465806,"mc":[{"id":"1.188136695","rc":[{"trd":[[1.25,342.9]],"batb":[[0,1.24,115.41]],"batl":[[0,1.25,991.9]],"ltp":1.25,"tv":92649.98,"id":5300737}],"tv":117337.96}]}
{"op":"mcm","clk":"4299348316","pt":1632580466638,"mc":[{"id":"1.188136695","rc":[{"trd":[[1.25,346.28]],"batl":[[0,1.25,990.21]],"ltp":1.25,"tv":92653.36,"id":5300737},{"trd":[[5.2,20]],"batl":[[0,5.2,56.46]],"ltp":5.2,"tv":24707.98,"id":2497008}],"tv":117361.34}]}
{"op":"mcm","clk":"4299348482","pt":1632580467182,"mc":[{"id":"1.188136695","rc":[{"trd":[[1.25,349.08]],"batl":[[0,1.25,987.41]],"ltp":1.25,"tv":92656.16,"id":5300737},{"trd":[[5,23.2]],"ltp":5.0,"tv":24708.68,"id":2497008}],"tv":117364.84}]}
{"op":"mcm","clk":"4299348987","pt":1632580468741,"mc":[{"id":"1.188136695","rc":[{"trd":[[1.25,352.18]],"batb":[[1,1.23,5041.03]],"batl":[[0,1.25,985.69]],"ltp":1.25,"tv":92659.26,"id":5300737},{"trd":[[5,23.28]],"ltp":5.0,"tv":24708.77,"id":2497008}],"tv":117368.03}]}
{"op":"mcm","clk":"4299349284","pt":1632580469753,"mc":[{"id":"1.188136695","rc":[{"trd":[[1.25,355.31]],"batb":[[1,1.23,1176.83],[2,1.22,2905.96]],"batl":[[0,1.25,352.64],[1,1.26,243.71],[2,1.27,787.38]],"ltp":1.25,"tv":92662.39,"id":5300737},{"batb":[[0,4.8,4.73],[1,4.7,24.32]],"batl":[[0,5.3,69.87],[1,5.4,70.62],[2,5.5,97.6]],"ltp":5.0,"tv":24708.77,"id":2497008}],"tv":117371.16}]}
{"op":"mcm","clk":"4299349591","pt":1632580470791,"mc":[{"id":"1.188136695","rc":[{"trd":[[1.25,395.71]],"batb":[[2,1.22,2714.08]],"batl":[[0,1.25,332.24],[2,1.27,697.38]],"ltp":1.25,"tv":92702.79,"id":5300737},{"trd":[[5,23.39]],"batb":[[1,4.6,199.71],[2,4.4,80.41]],"batl":[[2,5.5,87]],"ltp":5.0,"tv":24708.87,"id":2497008}],"tv":117411.66}]}
{"op":"mcm","clk":"4299349686","pt":1632580471075,"mc":[{"id":"1.188136695","rc":[{"trd":[[1.25,397.82]],"batl":[[0,1.25,330.13]],"ltp":1.25,"tv":92704.9,"id":5300737},{"trd":[[5,23.91]],"ltp":5.0,"tv":24709.39,"id":2497008}],"tv":117414.29}]}
{"op":"mcm","clk":"4299350258","pt":1632580472756,"mc":[{"id":"1.188136695","rc":[{"trd":[[1.25,406.27]],"batl":[[0,1.25,325.9]],"ltp":1.25,"tv":92713.35,"id":5300737}],"tv":117422.75}]}
{"op":"mcm","clk":"4299350601","pt":1632580473766,"mc":[{"id":"1.188136695","rc":[{"trd":[[1.25,464.78]],"batl":[[0,1.25,267.4]],"ltp":1.25,"tv":92771.86,"id":5300737},{"trd":[[5,38.54]],"ltp":5.0,"tv":24724.02,"id":2497008}],"tv":117495.88}]}
{"op":"mcm","clk":"4299351546","pt":1632580476891,"mc":[{"id":"1.188136695","rc":[{"trd":[[1.25,488.55]],"batl":[[0,1.25,255.51]],"ltp":1.25,"tv":92795.63,"id":5300737}],"tv":117519.65}]}
{"op":"mcm","clk":"4299352163","pt":1632580478694,"mc":[{"id":"1.188136695","rc":[{"batl":[[2,1.3,4.29]],"ltp":1.25,"tv":92795.63,"id":5300737},{"batb":[[2,3.8,21.24]],"ltp":5.0,"tv":24724.02,"id":2497008}]}]}
{"op":"mcm","clk":"4299352488","pt":1632580479769,"mc":[{"id":"1.188136695","rc":[{"trd":[[1.25,493.25]],"batb":[[0,1.24,57.63],[1,1.23,224.57]],"batl":[[0,1.25,253.16],[1,1.26,75.96]],"ltp":1.25,"tv":92800.33,"id":5300737}],"tv":117524.35}]}
{"op":"mcm","clk":"4299353121","pt":1632580481784,"mc":[{"id":"1.188136695","rc":[{"trd":[[1.24,149.92],[1.25,497.95]],"batb":[[0,1.22,2714.08],[1,1.21,4677.39],[2,1.2,1209.76]],"batl":[[0,1.24,1262.81],[1,1.25,4617.95],[2,1.26,390.98]],"ltp":1.24,"tv":92920.28,"id":5300737},{"batb":[[0,5.1,2],[1,4.8,4.73],[2,4.6,199.71]],"batl":[[0,5.4,1],[1,5.5,87],[2,5.6,3.41]],"ltp":5.0,"tv":24724.02,"id":2497008}],"tv":117644.3}]}
{"op":"mcm","clk":"4299353456","pt":1632580482783,"mc":[{"id":"1.188136695","rc":[{"trd":[[1.24,176.7]],"batl":[[0,1.24,1236.03],[1,1.25,4768.33]],"ltp":1.24,"tv":92947.06,"id":5300737},{"trd":[[5.1,118.1]],"batb":[[0,5.1,101.44],[1,4.9,197.05],[2,4.8,30.41]],"ltp":5.1,"tv":24842.12,"id":2497008}],"tv":117789.19}]}
{"op":"mcm","clk":"4299353657","pt":1632580483395,"mc":[{"id":"1.188136695","rc":[{"batl":[[0,1.24,2188.29],[2,1.26,315.02]],"ltp":1.24,"tv":92947.06,"id":5300737},{"trd":[[5.1,121.62]],"batb":[[0,5.1,99.68],[1,4.9,176.2]],"ltp":5.1,"tv":24845.64,"id":2497008}],"tv":117792.71}]}
{"op":"mcm","clk":"4299354106","pt":1632580484789,"mc":[{"id":"1.188136695","rc":[{"trd":[[1.24,220.27]],"batl":[[0,1.24,2166.51]],"ltp":1.24,"tv":92990.63,"id":5300737}],"tv":117836.27}]}
{"op":"mcm","clk":"4299354405","pt":1632580485687,"mc":[{"id":"1.188136695","rc":[{"batb":[[0,1.22,2767.65],[1,1.21,4690.39],[2,1.2,1411]],"ltp":1.24,"tv":92990.63,"id":5300737}]}]}
{"op":"mcm","clk":"4299354716","pt":1632580486779,"mc":[{"id":"1.188136695","rc":[{"batb":[[0,1.22,2944.86],[1,1.21,4757.55]],"batl":[[0,1.23,87.74],[1,1.24,2779.27],[2,1.25,4829.35]],"ltp":1.24,"tv":92990.63,"id":5300737},{"batb":[[0,5.1,109.45],[2,4.8,6.73]],"ltp":5.1,"tv":24845.64,"id":2497008}]}]}
{"op":"mcm","clk":"4299355042","pt":1632580487797,"mc":[{"id":"1.188136695","rc":[{"trd":[[1.23,6.82]],"batl":[[0,1.23,84.33],[1,1.24,3325.25],[2,1.25,5452.47]],"ltp":1.23,"tv":92997.45,"id":5300737},{"batb":[[0,5.1,242.19],[1,5,155.78],[2,4.9,176.2]],"ltp":5.1,"tv":24845.64,"id":2497008}],"tv":117843.1}]}
{"op":"mcm","clk":"4299355253","pt":1632580488507,"mc":[{"id":"1.188136695","rc":[{"batb":[[1,1.21,4988.75],[2,1.2,1701.89]],"batl":[[2,1.25,5660.21]],"ltp":1.23,"tv":92997.45,"id":5300737},{"batb":[[1,5,159.94],[2,4.9,179.2]],"ltp":5.1,"tv":24845.64,"id":2497008}]}]}
{"op":"mcm","clk":"4299355955","pt":1632580490675,"mc":[{"id":"1.188136695","rc":[{"batb":[[1,1.21,4921.59]],"batl":[[2,1.25,5599.2]],"ltp":1.23,"tv":92997.45,"id":5300737},{"batb":[[1,5,182.44]],"ltp":5.1,"tv":24845.64,"id":2497008}]}]}
{"op":"mcm","clk":"4299356558","pt":1632580492771,"mc":[{"id":"1.188136695","rc":[{"trd":[[1.23,10.34]],"batl":[[0,1.23,82.57],[1,1.24,2373],[2,1.25,5651.77]],"ltp":1.23,"tv":93000.97,"id":5300737}],"tv":117846.62}]}
{"op":"mcm","clk":"4299356898","pt":1632580493799,"mc":[{"id":"1.188136695","rc":[{"trd":[[1.22,42.64]],"batb":[[0,1.22,2923.55]],"batl":[[0,1.23,506.57]],"ltp":1.22,"tv":93043.61,"id":5300737}],"tv":117889.25}]}
{"op":"mcm","clk":"4299357089","pt":1632580494388,"mc":[{"id":"1.188136695","rc":[{"trd":[[1.23,24.17]],"batl":[[0,1.23,499.66]],"ltp":1.23,"tv":93057.44,"id":5300737}],"tv":117903.08}]}
{"op":"mcm","clk":"4299357559","pt":1632580495801,"mc":[{"id":"1.188136695","rc":[{"batb":[[0,1.22,998.26],[1,1.21,1197.46]],"batl":[[0,1.23,75.66],[1,1.24,60.76],[2,1.25,601.13]],"ltp":1.23,"tv":93057.44,"id":5300737},{"batb":[[0,5,26.66],[1,4.9,179.2],[2,4.8,2]],"batl":[[1,5.7,49.66],[2,5.8,72.98]],"ltp":5.1,"tv":24845.64,"id":2497008}]}]}
{"op":"mcm","clk":"4299357842","pt":1632580496722,"mc":[{"id":"1.188136695","rc":[{"trd":[[1.22,42.82],[1.23,35.8]],"batb":[[0,1.22,988.16],[1,1.21,1184.46],[2,1.2,1500.65]],"batl":[[0,1.23,64.28],[2,1.25,511.13]],"ltp":1.23,"tv":93069.25,"id":5300737},{"trd":[[5.3,2.58]],"batb":[[0,5,4.16]],"batl":[[1,5.7,49.98]],"ltp":5.3,"tv":24848.22,"id":2497008}],"tv":117917.48}]}
{"op":"mcm","clk":"4299358158","pt":1632580497732,"mc":[{"id":"1.188136695","rc":[{"trd":[[1.22,212.57],[1.23,39.32]],"batb":[[0,1.22,903.29]],"batl":[[0,1.23,62.53]],"ltp":1.22,"tv":93242.51,"id":5300737}],"tv":118090.74}]}
{"op":"mcm","clk":"4299358508","pt":1632580498790,"mc":[{"id":"1.188136695","rc":[{"trd":[[1.22,213.27]],"batb":[[0,1.22,57.32],[2,1.2,3690.59]],"ltp":1.22,"tv":93243.21,"id":5300737},{"batb":[[1,4.9,3],[2,4.8,180.74]],"batl":[[1,5.6,2.31],[2,5.7,49.66]],"ltp":5.3,"tv":24848.22,"id":2497008}],"tv":118091.44}]}
{"op":"mcm","clk":"4299358653","pt":1632580499285,"mc":[{"id":"1.188136695","rc":[{"trd":[[1.23,42.12]],"batl":[[0,1.23,61.13],[1,1.24,148.75]],"ltp":1.23,"tv":93246.01,"id":5300737},{"batb":[[2,4.8,178.74]],"batl":[[1,5.7,49.98],[2,5.8,72.98]],"ltp":5.3,"tv":24848.22,"id":2497008}],"tv":118094.24}]}
{"op":"mcm","clk":"4299359142","pt":1632580500819,"mc":[{"id":"1.188136695","rc":[{"batb":[[0,1.22,57.65],[1,1.21,953.26],[2,1.2,1209.76]],"batl":[[0,1.24,87.99],[1,1.25,303.39],[2,1.26,1372.13]],"ltp":1.23,"tv":93246.01,"id":5300737},{"batl":[[1,5.9,1.31],[2,6,3.82]],"ltp":5.3,"tv":24848.22,"id":2497008}]}]}
{"op":"mcm","clk":"4299359455","pt":1632580501829,"mc":[{"id":"1.188136695","rc":[{"trd":[[1.24,396.24]],"batb":[[0,1.23,5.72],[1,1.22,57.32],[2,1.21,953.26]],"batl":[[0,1.25,303.39],[1,1.26,1372.13],[2,1.27,1212.58]],"ltp":1.24,"tv":93421.99,"id":5300737},{"batb":[[0,5.1,4.54],[1,5,4.16],[2,4.9,3]],"ltp":5.3,"tv":24848.22,"id":2497008}],"tv":118270.22}]}
{"op":"mcm","clk":"4299359786","pt":1632580502829,"mc":[{"id":"1.188136695","rc":[{"trd":[[1.22,245.82],[1.23,53.56]],"batb":[[0,1.23,4664.63],[1,1.22,4568.48],[2,1.21,5480.7]],"ltp":1.22,"tv":93465.98,"id":5300737},{"batb":[[0,5,4.16],[1,4.9,3],[2,4.8,178.74]],"ltp":5.3,"tv":24848.22,"id":2497008}],"tv":118314.21}]}
{"op":"mcm","clk":"4299359967","pt":1632580503326,"mc":[{"id":"1.188136695","rc":[{"trd":[[1.23,73.56],[1.25,516.11]],"batb":[[0,1.23,1389.39],[1,1.22,1399.27],[2,1.21,2311.49]],"batl":[[0,1.25,285.22]],"ltp":1.23,"tv":93504.15,"id":5300737},{"trd":[[5,51.4]],"batb":[[0,4.9,3],[1,4.8,178.74],[2,4.6,75]],"ltp":5.0,"tv":24861.08,"id":2497008}],"tv":118365.23}]}
{"op":"mcm","clk":"4299360398","pt":1632580504720,"mc":[{"id":"1.188136695","rc":[{"batb":[[0,1.23,4297.08],[1,1.22,3194.22],[2,1.21,3681.6]],"batl":[[2,1.27,1302.58]],"ltp":1.23,"tv":93504.15,"id":5300737},{"batb":[[2,4.7,24.32]],"batl":[[0,5.3,2],[1,5.4,1],[2,5.6,10.8]],"ltp":5.0,"tv":24861.08,"id":2497008}]}]}
{"op":"mcm","clk":"4299360775","pt":1632580505827,"mc":[{"id":"1.188136695","rc":[{"batb":[[0,1.23,4354.06],[1,1.22,5980.67]],"batl":[[0,1.25,466.08]],"ltp":1.23,"tv":93504.15,"id":5300737},{"batl":[[0,5.3,7]],"ltp":5.0,"tv":24861.08,"id":2497008}]}]}
{"op":"mcm","clk":"4299361337","pt":1632580507720,"mc":[{"id":"1.188136695","rc":[{"batb":[[0,1.23,4800.9],[1,1.22,5975.67]],"batl":[[0,1.24,76.64],[1,1.25,1261.27],[2,1.26,1372.13]],"ltp":1.23,"tv":93504.15,"id":5300737},{"batb":[[0,4.8,178.74],[1,4.7,24.32],[2,4.6,276.74]],"ltp":5.0,"tv":24861.08,"id":2497008}]}]}
{"op":"mcm","clk":"4299361549","pt":1632580508304,"mc":[{"id":"1.188136695","rc":[{"trd":[[1.24,423.61]],"batb":[[1,1.22,3246.48]],"batl":[[0,1.24,62.96],[2,1.26,1433.02]],"ltp":1.24,"tv":93531.51,"id":5300737}],"tv":118392.6}]}
{"op":"mcm","clk":"4299361841","pt":1632580509223,"mc":[{"id":"1.188136695","rc":[{"batb":[[0,1.23,4801.33]],"ltp":1.24,"tv":93531.51,"id":5300737}]}]}
{"op":"mcm","clk":"4299362276","pt":1632580510522,"mc":[{"id":"1.188136695","rc":[{"batb":[[1,1.22,3503.81],[2,1.21,4248.4]],"batl":[[1,1.25,1480.25],[2,1.26,1622.77]],"ltp":1.24,"tv":93531.51,"id":5300737},{"batb":[[0,4.8,182.67]],"batl":[[1,5.4,70.78],[2,5.5,71.58]],"ltp":5.0,"tv":24861.08,"id":2497008}]}]}
{"op":"mcm","clk":"4299362715","pt":1632580511738,"mc":[{"id":"1.188136695","rc":[{"batl":[[0,1.24,253.82],[1,1.25,1539.39]],"ltp":1.24,"tv":93531.51,"id":5300737},{"batb":[[0,4.8,196.83]],"ltp":5.0,"tv":24861.08,"id":2497008}]}]}
{"op":"mcm","clk":"4299362924","pt":1632580512445,"mc":[{"id":"1.188136695","rc":[{"trd":[[1.24,437.89]],"batb":[[1,1.22,3446.55]],"batl":[[0,1.24,246.68],[1,1.25,2037.38],[2,1.26,2158.43]],"ltp":1.24,"tv":93545.79,"id":5300737},{"batb":[[0,5,124.5],[1,4.8,353.43],[2,4.7,24.32]],"ltp":5.0,"tv":24861.08,"id":2497008}],"tv":118406.88}]}
{"op":"mcm","clk":"4299363389","pt":1632580513731,"mc":[{"id":"1.188136695","rc":[{"trd":[[1.24,523.6]],"batl":[[0,1.24,203.82]],"ltp":1.24,"tv":93631.5,"id":5300737}],"tv":118492.59}]}
{"op":"mcm","clk":"4299363604","pt":1632580514451,"mc":[{"id":"1.188136695","rc":[{"trd":[[1.24,524.72]],"batb":[[0,1.23,5423.6],[1,1.22,4319.96]],"batl":[[0,1.24,203.26]],"ltp":1.24,"tv":93632.62,"id":5300737},{"batl":[[1,5.4,212.51]],"ltp":5.0,"tv":24861.08,"id":2497008}],"tv":118493.7}]}
{"op":"mcm","clk":"4299363739","pt":1632580514847,"mc":[{"id":"1.188136695","rc":[{"batl":[[0,1.24,251.05]],"ltp":1.24,"tv":93632.62,"id":5300737}]}]}
{"op":"mcm","clk":"4299364082","pt":1632580515967,"mc":[{"id":"1.188136695","rc":[{"trd":[[1.23,80.58]],"batb":[[0,1.23,5420.09]],"ltp":1.23,"tv":93639.64,"id":5300737}],"tv":118500.72}]}
{"op":"mcm","clk":"4299364712","pt":1632580517758,"mc":[{"id":"1.188136695","rc":[{"trd":[[1.24,539]],"batb":[[0,1.23,84.37],[1,1.22,1227.32],[2,1.21,2890.17]],"batl":[[0,1.24,243.91],[1,1.25,816.96],[2,1.26,189.75]],"ltp":1.24,"tv":93653.92,"id":5300737},{"batb":[[0,4.8,3.93],[1,4.7,24.32],[2,4.6,201.74]],"batl":[[0,5.3,2],[1,5.4,70.78]],"ltp":5.0,"tv":24861.08,"id":2497008}],"tv":118515.0}]}
{"op":"mcm","clk":"4299365051","pt":1632580518763,"mc":[{"id":"1.188136695","rc":[{"trd":[[1.24,540.8]],"batb":[[1,1.22,1035.44],[2,1.21,2882.17]],"batl":[[0,1.24,243.01]],"ltp":1.24,"tv":93655.72,"id":5300737},{"batb":[[1,4.6,201.74],[2,4.5,68.13]],"batl":[[0,5.4,70.78],[1,5.5,71.58],[2,5.6,73.7]],"ltp":5.0,"tv":24861.08,"id":2497008}],"tv":118516.81}]}
{"op":"mcm","clk":"4299365090","pt":1632580518867,"mc":[{"id":"1.188136695","rc":[{"batl":[[1,1.25,576.96]],"ltp":1.24,"tv":93655.72,"id":5300737}]}]}
{"op":"mcm","clk":"4299365784","pt":1632580520762,"mc":[{"id":"1.188136695","rc":[{"trd":[[1.23,81.2]],"batb":[[0,1.23,84.06],[2,1.21,4588.62]],"ltp":1.23,"tv":93656.34,"id":5300737},{"batb":[[0,5,3.94],[1,4.8,3.93],[2,4.7,194.21]],"ltp":5.0,"tv":24861.08,"id":2497008}],"tv":118517.43}]}
{"op":"mcm","clk":"4299366080","pt":1632580521597,"mc":[{"id":"1.188136695","rc":[{"trd":[[1.24,542.24]],"batb":[[0,1.23,3.05],[2,1.21,1520.05]],"batl":[[0,1.24,241.57]],"ltp":1.24,"tv":93657.78,"id":5300737},{"trd":[[5.1,121.97]],"ltp":5.1,"tv":24861.43,"id":2497008}],"tv":118519.22}]}
{"op":"mcm","clk":"4299366423","pt":1632580522566,"mc":[{"id":"1.188136695","rc":[{"batl":[[0,5.4,71.09]],"ltp":5.1,"tv":24861.43,"id":2497008}]}]}
{"op":"mcm","clk":"4299366781","pt":1632580523667,"mc":[{"id":"1.188136695","rc":[{"trd":[[1.24,545.75]],"batl":[[0,1.24,260.54]],"ltp":1.24,"tv":93661.3,"id":5300737},{"batb":[[0,5.2,21.12],[1,5,3.94],[2,4.8,3.93]],"batl":[[0,5.3,20.26],[1,5.4,70.78],[2,5.5,71.58]],"ltp":5.1,"tv":24861.43,"id":2497008}],"tv":118522.74}]}
{"op":"mcm","clk":"4299366877","pt":1632580523907,"mc":[{"id":"1.188136695","rc":[{"batl":[[0,1.24,239.81]],"ltp":1.24,"tv":93661.3,"id":5300737},{"batb":[[0,5,3.94],[1,4.8,3.93],[2,4.7,194.21]],"batl":[[0,5.4,71.09],[1,5.5,71.58],[2,5.6,73.7]],"ltp":5.1,"tv":24861.43,"id":2497008}]}]}
{"op":"mcm","clk":"4299367562","pt":1632580525673,"mc":[{"id":"1.188136695","rc":[{"trd":[[1.24,560.03]],"batl":[[0,1.24,1184.93]],"ltp":1.24,"tv":93675.58,"id":5300737}],"tv":118537.02}]}
{"op":"mcm","clk":"4299367908","pt":1632580526741,"mc":[{"id":"1.188136695","rc":[{"batb":[[0,1.23,1211.44],[1,1.22,1882.94]],"batl":[[0,1.24,1438.93],[1,1.25,1118.75],[2,1.26,1476.1]],"ltp":1.24,"tv":93675.58,"id":5300737},{"batl":[[0,5.4,82.68]],"ltp":5.1,"tv":24861.43,"id":2497008}]}]}
{"op":"mcm","clk":"4299368022","pt":1632580527067,"mc":[{"id":"1.188136695","rc":[{"trd":[[1.23,159.15]],"batb":[[0,1.23,1172.46]],"batl":[[0,1.24,486.67]],"ltp":1.23,"tv":93753.53,"id":5300737}],"tv":118614.97}]}
{"op":"mcm","clk":"4299368594","pt":1632580528765,"mc":[{"id":"1.188136695","rc":[{"batb":[[1,1.22,2489.06]],"batl":[[0,1.24,1383.1],[1,1.25,1045.99]],"ltp":1.23,"tv":93753.53,"id":5300737}]}]}
{"op":"mcm","clk":"4299368926","pt":1632580529793,"mc":[{"id":"1.188136695","rc":[{"batb":[[0,1.22,1035.44],[1,1.21,1520.05],[2,1.2,2982.01]],"batl":[[0,1.24,232.67],[1,1.25,504.2],[2,1.26,189.75]],"ltp":1.23,"tv":93753.53,"id":5300737},{"batl":[[0,5.4,71.09]],"ltp":5.1,"tv":24861.43,"id":2497008}]}]}
{"op":"mcm","clk":"4299369433","pt":1632580531304,"mc":[{"id":"1.188136695","rc":[{"trd":[[1.24,560.74]],"batl":[[0,1.24,232.32]],"ltp":1.24,"tv":93754.24,"id":5300737}],"tv":118615.67}]}
{"op":"mcm","clk":"4299370227","pt":1632580533678,"mc":[{"id":"1.188136695","rc":[{"batb":[[1,1.21,3226.5]],"ltp":1.24,"tv":93754.24,"id":5300737}]}]}
{"op":"mcm","clk":"4299370870","pt":1632580535580,"mc":[{"id":"1.188136695","rc":[{"trd":[[1.24,567.76]],"batb":[[0,1.22,778.11],[1,1.21,2902.4],[2,1.2,2606.71]],"batl":[[0,1.24,228.81]],"ltp":1.24,"tv":93761.26,"id":5300737},{"batl":[[0,5.4,1.31],[1,5.8,3.82],[2,5.9,1]],"ltp":5.1,"tv":24861.43,"id":2497008}],"tv":118622.7}]}
{"op":"mcm","clk":"4299370966","pt":1632580535912,"mc":[{"id":"1.188136695","rc":[{"trd":[[1.24,567.96]],"batb":[[0,1.21,1195.95],[1,1.2,2606.71],[2,1.19,1210.09]],"batl":[[0,1.24,228.7]],"ltp":1.24,"tv":93761.46,"id":5300737}],"tv":118622.9}]}
{"op":"mcm","clk":"4299371446","pt":1632580537376,"mc":[{"id":"1.188136695","rc":[{"trd":[[1.24,1025.37],[1.25,1540.27],[1.26,562.18]],"batb":[[0,1.24,1.76],[1,1.21,1195.95],[2,1.2,2606.71]],"batl":[[0,1.27,811.42],[1,1.28,1184.09],[2,1.29,191.21]],"ltp":1.26,"tv":95622.54,"id":5300737},{"trd":[[5,55.34]],"batb":[[0,4.8,3.93],[1,4.7,194.21],[2,4.5,68.13]],"ltp":5.0,"tv":24865.37,"id":2497008}],"tv":120487.91}]}
{"op":"mcm","clk":"4299371863","pt":1632580538799,"mc":[{"id":"1.188136695","rc":[{"batb":[[0,1.24,2777.18],[1,1.22,3.43],[2,1.21,1195.95]],"ltp":1.26,"tv":95622.54,"id":5300737},{"trd":[[4.7,10.64],[4.8,32.74]],"batb":[[0,4.7,189.05],[1,4.5,68.13],[2,4.4,79.61]],"batl":[[0,5,156.25],[1,5.1,80.35],[2,5.2,78.12]],"ltp":4.7,"tv":24883.55,"id":2497008}],"tv":120506.09}]}
{"op":"mcm","clk":"4299372169","pt":1632580539814,"mc":[{"id":"1.188136695","rc":[{"batb":[[0,1.25,653.22],[1,1.24,5378.99],[2,1.23,187.66]],"batl":[[2,1.29,796.83]],"ltp":1.26,"tv":95622.54,"id":5300737},{"batb":[[1,4.5,305.13]],"batl":[[1,5.1,82.35]],"ltp":4.7,"tv":24883.55,"id":2497008}]}]}
{"op":"mcm","clk":"4299372326","pt":1632580540279,"mc":[{"id":"1.188136695","rc":[{"batl":[[0,1.27,816.42],[1,1.28,1274.09]],"ltp":1.26,"tv":95622.54,"id":5300737}]}]}
{"op":"mcm","clk":"4299372840","pt":1632580541810,"mc":[{"id":"1.188136695","rc":[{"batb":[[1,1.24,5387.79]],"ltp":1.26,"tv":95622.54,"id":5300737},{"batb":[[0,4.8,3],[1,4.7,191.05],[2,4.6,2]],"ltp":4.7,"tv":24883.55,"id":2497008}]}]}
{"op":"mcm","clk":"4299373139","pt":1632580542605,"mc":[{"id":"1.188136695","rc":[{"batb":[[0,1.25,725],[1,1.24,5389.55]],"batl":[[0,1.27,882.16]],"ltp":1.26,"tv":95622.54,"id":5300737}]}]}
{"op":"mcm","clk":"4299373441","pt":1632580543491,"mc":[{"id":"1.188136695","rc":[{"batb":[[0,1.25,1284.94],[2,1.23,12485.45]],"batl":[[0,1.27,1735]],"ltp":1.26,"tv":95622.54,"id":5300737}]}]}
{"op":"mcm","clk":"4299373876","pt":1632580544787,"mc":[{"id":"1.188136695","rc":[{"trd":[[1.27,127.87]],"batb":[[2,1.23,13437.71]],"batl":[[0,1.27,1729.6]],"ltp":1.27,"tv":95623.33,"id":5300737},{"batb":[[0,4.7,189.05],[1,4.5,305.13],[2,4.4,79.61]],"ltp":4.7,"tv":24883.55,"id":2497008}],"tv":120506.88}]}
{"op":"mcm","clk":"4299374189","pt":1632580545792,"mc":[{"id":"1.188136695","rc":[{"batb":[[1,1.24,5649.99],[2,1.23,13720.44]],"batl":[[0,1.27,1929.1],[1,1.28,1432.93]],"ltp":1.27,"tv":95623.33,"id":5300737},{"batb":[[0,4.7,193.67],[1,4.5,309.79]],"batl":[[1,5.1,150.06],[2,5.2,144.38]],"ltp":4.7,"tv":24883.55,"id":2497008}]}]}
{"op":"mcm","clk":"4299374534","pt":1632580546809,"mc":[{"id":"1.188136695","rc":[{"trd":[[1.25,1548.3]],"batb":[[0,1.25,1280.93],[2,1.23,1422.66]],"batl":[[0,1.27,2070.1]],"ltp":1.25,"tv":95631.35,"id":5300737}],"tv":120514.91}]}
{"op":"mcm","clk":"4299374802","pt":1632580547727,"mc":[{"id":"1.188136695","rc":[{"batb":[[2,1.23,470.4]],"ltp":1.25,"tv":95631.35,"id":5300737}]}]}
{"op":"mcm","clk":"4299375778","pt":1632580550711,"mc":[{"id":"1.188136695","rc":[{"trd":[[1.25,1617.34],[1.27,133.49]],"batb":[[0,1.25,1246.41]],"batl":[[0,1.27,2478.28],[1,1.28,2117.77]],"ltp":1.25,"tv":95706.01,"id":5300737},{"trd":[[5,56.04]],"batb":[[0,4.7,342.82],[1,4.5,504.59]],"batl":[[0,5,155.9]],"ltp":5.0,"tv":24884.25,"id":2497008}],"tv":120590.27}]}
{"op":"mcm","clk":"4299376444","pt":1632580552706,"mc":[{"id":"1.188136695","rc":[{"batb":[[0,1.25,1846.4],[1,1.24,4090.61]],"batl":[[2,1.29,675.71]],"ltp":1.25,"tv":95706.01,"id":5300737},{"batl":[[0,5,275],[1,5.1,132.91],[2,5.2,302.08]],"ltp":5.0,"tv":24884.25,"id":2497008}]}]}
{"op":"mcm","clk":"4299376736","pt":1632580553503,"mc":[{"id":"1.188136695","rc":[{"trd":[[1.25,2242.34],[1.26,563.88],[1.27,902.81]],"batb":[[0,1.25,61.47],[1,1.24,262.19]],"batl":[[0,1.26,504.15],[1,1.27,265.23],[2,1.28,262.48]],"ltp":1.26,"tv":97102.03,"id":5300737},{"trd":[[5,212.29]],"batb":[[0,4.7,4.62],[1,4.5,241.66],[2,4.2,66.44]],"batl":[[0,5.1,68.41],[1,5.2,66.26],[2,5.3,100.6]],"ltp":5.0,"tv":25040.5,"id":2497008}],"tv":122142.53}]}
{"op":"mcm","clk":"4299377127","pt":1632580554639,"mc":[{"id":"1.188136695","rc":[{"trd":[[1.27,1064.81]],"batb":[[2,1.23,282.74]],"batl":[[0,1.28,172.48],[1,1.3,6.05],[2,1.31,209.54]],"ltp":1.27,"tv":97264.03,"id":5300737},{"batb":[[0,4.5,215.95],[1,4.2,66.44],[2,4.1,100.22]],"batl":[[2,5.3,89.75]],"ltp":5.0,"tv":25040.5,"id":2497008}],"tv":122304.54}]}
{"op":"mcm","clk":"4299377744","pt":1632580556640,"mc":[{"id":"1.188136695","rc":[{"batb":[[2,1.23,1514.45]],"batl":[[0,1.27,10],[1,1.28,172.48],[2,1.29,1129.53]],"ltp":1.27,"tv":97264.03,"id":5300737},{"batb":[[0,4.7,2],[1,4.6,2],[2,4.5,215.95]],"ltp":5.0,"tv":25040.5,"id":2497008}]}]}
{"op":"mcm","clk":"4299378130","pt":1632580557727,"mc":[{"id":"1.188136695","rc":[{"batb":[[0,1.26,133.33],[1,1.25,61.47],[2,1.24,262.19]],"batl":[[1,1.28,735.85]],"ltp":1.27,"tv":97264.03,"id":5300737},{"batb":[[2,4.5,218.95]],"batl":[[2,5.3,89.43]],"ltp":5.0,"tv":25040.5,"id":2497008}]}]}
{"op":"mcm","clk":"4299378325","pt":1632580558307,"mc":[{"id":"1.188136695","rc":[{"trd":[[1.27,1066.91]],"batl":[[0,1.27,8.95]],"ltp":1.27,"tv":97266.13,"id":5300737}],"tv":122306.64}]}
{"op":"mcm","clk":"4299378807","pt":1632580559719,"mc":[{"id":"1.188136695","rc":[{"trd":[[1.27,1076.39]],"batb":[[0,1.27,1.76],[1,1.26,133.33]],"batl":[[0,1.28,180.48],[1,1.3,6.05],[2,1.36,13.28]],"ltp":1.27,"tv":97275.61,"id":5300737},{"trd":[[4.5,29.64],[4.6,4],[4.7,16.92]],"batb":[[0,4.5,208.89],[1,4.4,3],[2,3.55,2.42]],"ltp":4.5,"tv":25070.9,"id":2497008}],"tv":122346.52}]}
{"op":"mcm","clk":"4299379089","pt":1632580560709,"mc":[{"id":"1.188136695","rc":[{"trd":[[1.26,830.54],[1.27,1592.55]],"batb":[[0,1.24,262.19],[1,1.23,1514.45],[2,1.22,4454.09]],"ltp":1.26,"tv":98058.43,"id":5300737},{"trd":[[4.7,155.44]],"ltp":4.7,"tv":25209.42,"id":2497008}],"tv":123267.86}]}
{"op":"mcm","clk":"4299379480","pt":1632580561828,"mc":[{"id":"1.188136695","rc":[{"trd":[[1.27,1594.65]],"batb":[[0,1.23,1514.45],[1,1.22,4454.09],[2,1.21,1195.95]],"ltp":1.27,"tv":98060.53,"id":5300737},{"batb":[[0,4.8,1195.31],[1,4.7,1160.15],[2,4.6,1160.15]],"batl":[[0,5.3,90.13],[1,5.4,1],[2,5.6,5.71]],"ltp":4.7,"tv":25209.42,"id":2497008}],"tv":123269.96}]}
{"op":"mcm","clk":"4299379834","pt":1632580562828,"mc":[{"id":"1.188136695","rc":[{"batl":[[0,1.25,513.66],[1,1.26,1290.77],[2,1.28,2371.04]],"ltp":1.27,"tv":98060.53,"id":5300737},{"batb":[[0,4.8,358.6],[1,4.7,348.05],[2,4.6,348.05]],"ltp":4.7,"tv":25209.42,"id":2497008}]}]}
{"op":"mcm","clk":"4299380126","pt":1632580563768,"mc":[{"id":"1.188136695","rc":[{"batb":[[1,1.22,4452.15]],"batl":[[2,1.28,180.48]],"ltp":1.27,"tv":98060.53,"id":5300737},{"trd":[[5,229.69]],"batb":[[0,5,158.03],[1,4.8,358.6],[2,4.7,538.04]],"batl":[[2,5.5,10.6]],"ltp":5.0,"tv":25226.82,"id":2497008}],"tv":123287.36}]}
{"op":"mcm","clk":"4299380417","pt":1632580564828,"mc":[{"id":"1.188136695","rc":[{"trd":[[1.25,2247.41]],"batl":[[0,1.25,511.12]],"ltp":1.25,"tv":98065.61,"id":5300737}],"tv":123292.44}]}
{"op":"mcm","clk":"4299380714","pt":1632580565444,"mc":[{"id":"1.188136695","rc":[{"batb":[[0,1.23,1568.95],[1,1.22,4463.15],[2,1.21,1392.34]],"batl":[[1,1.26,1291.12],[2,1.27,85.04]],"ltp":1.25,"tv":98065.61,"id":5300737},{"batb":[[1,4.9,10.99],[2,4.8,358.6]],"ltp":5.0,"tv":25226.82,"id":2497008}]}]}
{"op":"mcm","clk":"4299381128","pt":1632580566818,"mc":[{"id":"1.188136695","rc":[{"batb":[[0,1.24,56.93],[1,1.23,1642.21],[2,1.22,4463.15]],"batl":[[0,1.25,589.04],[2,1.27,175.04]],"ltp":1.25,"tv":98065.61,"id":5300737},{"trd":[[5,230.32]],"batb":[[0,5,157.72]],"ltp":5.0,"tv":25227.45,"id":2497008}],"tv":123293.07}]}
{"op":"mcm","clk":"4299381398","pt":1632580567638,"mc":[{"id":"1.188136695","rc":[{"batb":[[1,1.23,2150.3],[2,1.22,4534.79]],"batl":[[0,1.25,1412.34],[1,1.26,1357.98]],"ltp":1.25,"tv":98065.61,"id":5300737},{"trd":[[5,232.42]],"batb":[[0,5,156.67]],"ltp":5.0,"tv":25229.55,"id":2497008}],"tv":123295.17}]}
{"op":"mcm","clk":"4299381651","pt":1632580568428,"mc":[{"id":"1.188136695","rc":[{"batb":[[0,1.24,57.28]],"ltp":1.25,"tv":98065.61,"id":5300737}]}]}
{"op":"mcm","clk":"4299382053","pt":1632580569644,"mc":[{"id":"1.188136695","rc":[{"trd":[[1.25,2248.99]],"batb":[[0,1.24,57.32],[2,1.22,4807.75]],"batl":[[0,1.25,1411.55],[1,1.26,1357.63]],"ltp":1.25,"tv":98067.19,"id":5300737},{"batb":[[2,4.8,382.28]],"batl":[[2,5.5,66.03]],"ltp":5.0,"tv":25229.55,"id":2497008}],"tv":123296.75}]}
{"op":"mcm","clk":"4299382378","pt":1632580570604,"mc":[{"id":"1.188136695","rc":[{"batb":[[0,1.24,61.6]],"batl":[[1,1.26,1547.88]],"ltp":1.25,"tv":98067.19,"id":5300737},{"batb":[[2,4.8,386.26]],"ltp":5.0,"tv":25229.55,"id":2497008}]}]}
{"op":"mcm","clk":"4299382659","pt":1632580571537,"mc":[{"id":"1.188136695","rc":[{"batb":[[2,1.22,4736.11]],"batl":[[1,1.26,2059.57],[2,1.27,789.59]],"ltp":1.25,"tv":98067.19,"id":5300737},{"batb":[[2,4.8,538.12]],"ltp":5.0,"tv":25229.55,"id":2497008}]}]}
{"op":"mcm","clk":"4299383063","pt":1632580572753,"mc":[{"id":"1.188136695","rc":[{"trd":[[1.25,2252.77]],"batl":[[0,1.25,1995.07],[1,1.26,2784.7]],"ltp":1.25,"tv":98070.96,"id":5300737},{"batb":[[0,5,303.02],[2,4.8,728.46]],"ltp":5.0,"tv":25229.55,"id":2497008}],"tv":123300.52}]}
{"op":"mcm","clk":"4299383404","pt":1632580573747,"mc":[{"id":"1.188136695","rc":[{"trd":[[1.25,2343.93]],"batl":[[0,1.25,2205.49]],"ltp":1.25,"tv":98162.12,"id":5300737},{"trd":[[5,235.47]],"batb":[[0,5,301.49]],"ltp":5.0,"tv":25232.61,"id":2497008}],"tv":123394.74}]}
{"op":"mcm","clk":"4299383697","pt":1632580574660,"mc":[{"id":"1.188136695","rc":[{"trd":[[1.25,2345.54]],"batl":[[0,1.25,1741.83]],"ltp":1.25,"tv":98163.73,"id":5300737}],"tv":123396.35}]}
{"op":"mcm","clk":"4299384049","pt":1632580575731,"mc":[{"id":"1.188136695","rc":[{"trd":[[5,236.87]],"batb":[[0,5,300.79]],"ltp":5.0,"tv":25234.01,"id":2497008}],"tv":123397.75}]}
{"op":"mcm","clk":"4299384500","pt":1632580577259,"mc":[{"id":"1.188136695","rc":[{"batb":[[2,1.22,4725.11]],"batl":[[1,1.26,3273.18],[2,1.27,1994.74]],"ltp":1.25,"tv":98163.73,"id":5300737}]}]}
{"op":"mcm","clk":"4299385163","pt":1632580579371,"mc":[{"id":"1.188136695","rc":[{"trd":[[1.24,1151.44],[1.25,2349.05]],"batb":[[0,1.23,2150.3],[1,1.22,3772.86],[2,1.21,1677.69]],"batl":[[0,1.24,260.62],[1,1.25,1740.07],[2,1.26,3273.18]],"ltp":1.24,"tv":98293.32,"id":5300737},{"trd":[[5.1,122.67]],"batl":[[0,5.3,89.43]],"ltp":5.1,"tv":25234.71,"id":2497008}],"tv":123528.03}]}
{"op":"mcm","clk":"4299385552","pt":1632580580484,"mc":[{"id":"1.188136695","rc":[{"trd":[[1.23,159.55]],"batb":[[0,1.23,2150.1],[1,1.22,3782.86]],"ltp":1.23,"tv":98293.71,"id":5300737}],"tv":123528.42}]}
{"op":"mcm","clk":"4299385937","pt":1632580581668,"mc":[{"id":"1.188136695","rc":[{"batb":[[0,1.23,73.26],[1,1.22,272.97],[2,1.21,1435]],"batl":[[1,1.25,331.36],[2,1.26,190.25]],"ltp":1.23,"tv":98293.71,"id":5300737},{"batb":[[0,4.8,27.66],[1,4.7,189.99],[2,4.5,221.4]],"batl":[[0,5.4,1],[1,5.5,66.03],[2,5.6,80.38]],"ltp":5.1,"tv":25234.71,"id":2497008}]}]}
{"op":"mcm","clk":"4299386262","pt":1632580582657,"mc":[{"id":"1.188136695","rc":[{"batb":[[2,1.21,1238.61]],"batl":[[1,1.25,75.36]],"ltp":1.23,"tv":98293.71,"id":5300737},{"batb":[[0,4.8,3.98]],"batl":[[1,5.5,55.43]],"ltp":5.1,"tv":25234.71,"id":2497008}]}]}
{"op":"mcm","clk":"4299386588","pt":1632580583726,"mc":[{"id":"1.188136695","rc":[{"trd":[[1.24,1160.87]],"batl":[[0,1.24,355.91]],"ltp":1.24,"tv":98303.14,"id":5300737}],"tv":123537.85}]}
{"op":"mcm","clk":"4299386930","pt":1632580584763,"mc":[{"id":"1.188136695","rc":[{"batb":[[2,1.21,2881.26]],"batl":[[0,1.24,359.42]],"ltp":1.24,"tv":98303.14,"id":5300737},{"batb":[[1,4.7,194.91]],"ltp":5.1,"tv":25234.71,"id":2497008}]}]}
{"op":"mcm","clk":"4299387520","pt":1632580586566,"mc":[{"id":"1.188136695","rc":[{"batl":[[0,1.24,259.42]],"ltp":1.24,"tv":98303.14,"id":5300737}]}]}
{"op":"mcm","clk":"4299387910","pt":1632580587749,"mc":[{"id":"1.188136695","rc":[{"trd":[[1.24,1420.29]],"batb":[[0,1.24,2520.16],[1,1.23,1333.34],[2,1.22,1533.05]],"batl":[[0,1.25,75.36],[1,1.26,190.25],[2,1.27,1120.84]],"ltp":1.24,"tv":98562.56,"id":5300737},{"trd":[[5.1,185.74]],"batl":[[0,5.1,982.08],[1,5.4,538.34],[2,5.5,55.43]],"ltp":5.1,"tv":25297.78,"id":2497008}],"tv":123860.34}]}
{"op":"mcm","clk":"4299388246","pt":1632580588776,"mc":[{"id":"1.188136695","rc":[{"trd":[[1.25,2352.57]],"batb":[[1,1.23,1260.08]],"batl":[[0,1.25,73.6]],"ltp":1.25,"tv":98566.07,"id":5300737},{"batl":[[0,5.4,27.87],[1,5.5,55.43],[2,5.6,80.38]],"ltp":5.1,"tv":25297.78,"id":2497008}],"tv":123863.86}]}
{"op":"mcm","clk":"4299388587","pt":1632580589754,"mc":[{"id":"1.188136695","rc":[{"trd":[[1.24,1650.03]],"batb":[[0,1.24,2405.99]],"batl":[[2,1.27,190.21]],"ltp":1.24,"tv":98795.81,"id":5300737}],"tv":124093.6}]}
{"op":"mcm","clk":"4299388828","pt":1632580590402,"mc":[{"id":"1.188136695","rc":[{"batb":[[0,1.24,2407.68]],"ltp":1.24,"tv":98795.81,"id":5300737}]}]}
{"op":"mcm","clk":"4299389047","pt":1632580591090,"mc":[{"id":"1.188136695","rc":[{"batb":[[2,4.5,216.74]],"ltp":5.1,"tv":25297.78,"id":2497008}]}]}
{"op":"mcm","clk":"4299389921","pt":1632580593818,"mc":[{"id":"1.188136695","rc":[{"trd":[[1.25,2411.08]],"batl":[[0,1.25,15.09]],"ltp":1.25,"tv":98854.32,"id":5300737},{"trd":[[5,251.5]],"ltp":5.0,"tv":25312.41,"id":2497008}],"tv":124166.73}]}
{"op":"mcm","clk":"4299390245","pt":1632580594608,"mc":[{"id":"1.188136695","rc":[{"trd":[[1.24,1655.88]],"batb":[[0,1.24,2409.02]],"ltp":1.24,"tv":98860.18,"id":5300737}],"tv":124172.59}]}
{"op":"mcm","clk":"4299390861","pt":1632580596387,"mc":[{"id":"1.188136695","rc":[{"batb":[[0,1.24,2408.32]],"ltp":1.24,"tv":98860.18,"id":5300737}]}]}
{"op":"mcm","clk":"4299391257","pt":1632580597549,"mc":[{"id":"1.188136695","rc":[{"batb":[[0,1.24,5108.92]],"ltp":1.24,"tv":98860.18,"id":5300737}]}]}
{"op":"mcm","clk":"4299391690","pt":1632580598801,"mc":[{"id":"1.188136695","rc":[{"trd":[[1.24,1753.88],[1.25,2411.78]],"batb":[[0,1.24,5059.92]],"batl":[[0,1.25,14.74]],"ltp":1.24,"tv":98958.88,"id":5300737}],"tv":124271.29}]}
{"op":"mcm","clk":"4299393174","pt":1632580603303,"mc":[{"id":"1.188136695","rc":[{"trd":[[1.24,1934.87],[1.25,2431.17]],"batb":[[0,1.24,4969.43]],"batl":[[0,1.26,190.25],[1,1.27,190.21],[2,1.28,15.99]],"ltp":1.24,"tv":99159.25,"id":5300737},{"trd":[[5,256.35]],"ltp":5.0,"tv":25317.25,"id":2497008}],"tv":124476.51}]}
{"op":"mcm","clk":"4299393982","pt":1632580605679,"mc":[{"id":"1.188136695","rc":[{"batb":[[0,1.25,1.08],[1,1.24,4969.43],[2,1.23,1260.08]],"ltp":1.24,"tv":99159.25,"id":5300737}]}]}
{"op":"mcm","clk":"4299394299","pt":1632580606674,"mc":[{"id":"1.188136695","rc":[{"trd":[[1.26,834.3]],"batl":[[0,1.26,188.37]],"ltp":1.26,"tv":99163.01,"id":5300737},{"batl":[[0,5.1,38.16],[1,5.4,27.87],[2,5.5,55.43]],"ltp":5.0,"tv":25317.25,"id":2497008}],"tv":124480.27}]}
{"op":"mcm","clk":"4299394437","pt":1632580607109,"mc":[{"id":"1.188136695","rc":[{"batb":[[0,1.25,17.04]],"ltp":1.26,"tv":99163.01,"id":5300737}]}]}
{"op":"mcm","clk":"4299394715","pt":1632580607979,"mc":[{"id":"1.188136695","rc":[{"batb":[[0,1.25,17.74]],"ltp":1.26,"tv":99163.01,"id":5300737}]}]}
{"op":"mcm","clk":"4299395827","pt":1632580611501,"mc":[{"id":"1.188136695","rc":[{"trd":[[1.26,1211.04]],"batb":[[0,1.25,1.78]],"batl":[[0,1.27,190.21],[1,1.28,15.99],[2,1.29,258]],"ltp":1.26,"tv":99539.75,"id":5300737},{"batb":[[0,4.7,194.91],[1,4.5,216.74],[2,4.4,94.15]],"ltp":5.0,"tv":25317.25,"id":2497008}],"tv":124857.01}]}
{"op":"mcm","clk":"4299396352","pt":1632580613244,"mc":[{"id":"1.188136695","rc":[{"batb":[[0,1.25,3.18]],"ltp":1.26,"tv":99539.75,"id":5300737}]}]}
{"op":"mcm","clk":"4299396626","pt":1632580614128,"mc":[{"id":"1.188136695","rc":[{"batl":[[2,1.29,244.78]],"ltp":1.26,"tv":99539.75,"id":5300737},{"batl":[[2,5.9,1]],"ltp":5.0,"tv":25317.25,"id":2497008}]}]}
{"op":"mcm","clk":"4299397446","pt":1632580616601,"mc":[{"id":"1.188136695","rc":[{"batb":[[1,1.24,7489.59],[2,1.23,2520.16]],"ltp":1.26,"tv":99539.75,"id":5300737},{"trd":[[4.7,173.62]],"batb":[[0,4.7,185.82]],"batl":[[1,5.4,602.36]],"ltp":4.7,"tv":25335.43,"id":2497008}],"tv":124875.19}]}
{"op":"mcm","clk":"4299397821","pt":1632580617729,"mc":[{"id":"1.188136695","rc":[{"trd":[[1.24,1937.27],[1.25,2437.53]],"batb":[[0,1.24,6637.46],[1,1.23,1512.1],[2,1.22,2775.93]],"ltp":1.24,"tv":99548.52,"id":5300737},{"batb":[[1,4.6,1358.7],[2,4.5,1108.15]],"batl":[[0,5.1,40.16],[1,5.4,142.77]],"ltp":4.7,"tv":25335.43,"id":2497008}],"tv":124883.96}]}
{"op":"mcm","clk":"4299398144","pt":1632580618713,"mc":[{"id":"1.188136695","rc":[{"trd":[[1.24,1949.79]],"batb":[[0,1.24,4369.53],[1,1.23,502.68],[2,1.22,1578.85]],"batl":[[1,1.28,105.99]],"ltp":1.24,"tv":99561.04,"id":5300737},{"batb":[[1,4.6,169.84],[2,4.5,539.42]],"batl":[[1,5.3,10.85],[2,5.4,142.77]],"ltp":4.7,"tv":25335.43,"id":2497008}],"tv":124896.48}]}
{"op":"mcm","clk":"4299398412","pt":1632580619599,"mc":[{"id":"1.188136695","rc":[{"batb":[[0,1.25,10.52],[1,1.24,4369.53],[2,1.23,502.68]],"ltp":1.24,"tv":99561.04,"id":5300737}]}]}
{"op":"mcm","clk":"4299398616","pt":1632580620178,"mc":[{"id":"1.188136695","rc":[{"trd":[[1.25,2535.96]],"batb":[[0,1.24,4369.53],[1,1.23,502.68],[2,1.22,1578.85]],"batl":[[0,1.25,73.78],[1,1.27,190.21],[2,1.28,105.99]],"ltp":1.25,"tv":99659.47,"id":5300737},{"batb":[[1,4.6,170.19]],"ltp":4.7,"tv":25335.43,"id":2497008}],"tv":124994.91}]}
{"op":"mcm","clk":"4299399149","pt":1632580621811,"mc":[{"id":"1.188136695","rc":[{"trd":[[1.25,2683.52],[1.26,1242.95]],"batb":[[0,1.25,78.85],[1,1.24,4426.79],[2,1.23,502.68]],"batl":[[0,1.26,51.93],[1,1.27,260.35]],"ltp":1.26,"tv":99838.94,"id":5300737}],"tv":125174.38}]}
{"op":"mcm","clk":"4299400148","pt":1632580624782,"mc":[{"id":"1.188136695","rc":[{"batb":[[2,1.23,800.44]],"batl":[[0,1.26,247.93]],"ltp":1.26,"tv":99838.94,"id":5300737},{"batl":[[1,5.3,75.09],[2,5.4,218.96]],"ltp":4.7,"tv":25335.43,"id":2497008}]}]}
{"op":"mcm","clk":"4299400447","pt":1632580625721,"mc":[{"id":"1.188136695","rc":[{"trd":[[1.26,1328.66]],"batb":[[0,1.25,147.06],[1,1.24,2757.56],[2,1.23,485.42]],"batl":[[0,1.26,269.9]],"ltp":1.26,"tv":99924.65,"id":5300737},{"batb":[[0,4.7,4.92],[1,4.5,376.63],[2,4.3,77.4]],"batl":[[0,5.1,38.16],[2,5.4,77.19]],"ltp":4.7,"tv":25335.43,"id":2497008}],"tv":125260.09}]}
{"op":"mcm","clk":"4299400774","pt":1632580626787,"mc":[{"id":"1.188136695","rc":[{"batb":[[0,1.25,78.85],[1,1.24,2700.3],[2,1.23,297.76]],"batl":[[0,1.26,73.9],[1,1.27,492.84],[2,1.28,549.12]],"ltp":1.26,"tv":99924.65,"id":5300737},{"batb":[[0,4.7,132.71],[1,4.5,502.56]],"batl":[[1,5.3,64.24]],"ltp":4.7,"tv":25335.43,"id":2497008}]}]}
{"op":"mcm","clk":"4299401091","pt":1632580627707,"mc":[{"id":"1.188136695","rc":[{"trd":[[1.26,1331.33]],"batl":[[0,1.26,71.24],[1,1.27,1.71],[2,1.28,15.99]],"ltp":1.26,"tv":99927.32,"id":5300737},{"trd":[[4.8,33.44]],"batb":[[0,4.5,350.92],[1,4.3,77.4],[2,4.2,88.86]],"ltp":4.8,"tv":25336.13,"id":2497008}],"tv":125263.46}]}
{"op":"mcm","clk":"4299401390","pt":1632580628666,"mc":[{"id":"1.188136695","rc":[{"trd":[[1.25,2688.22],[1.26,1336.4]],"batb":[[0,1.25,76.5],[2,1.23,1447.9]],"batl":[[0,1.26,68.7]],"ltp":1.26,"tv":99937.09,"id":5300737}],"tv":125273.23}]}
{"op":"mcm","clk":"4299401905","pt":1632580630323,"mc":[{"id":"1.188136695","rc":[{"batb":[[0,1.24,2700.3],[1,1.23,1447.9],[2,1.22,3205.73]],"ltp":1.26,"tv":99937.09,"id":5300737},{"batb":[[1,3.55,2.42],[2,3.3,1]],"ltp":4.8,"tv":25336.13,"id":2497008}]}]}
{"op":"mcm","clk":"4299402661","pt":1632580632735,"mc":[{"id":"1.188136695","rc":[{"trd":[[1.26,1340.4]],"batl":[[0,1.26,66.7]],"ltp":1.26,"tv":99941.08,"id":5300737},{"batb":[[0,4.8,2390.62],[1,4.7,2320.3],[2,4.6,2320.65]],"ltp":4.8,"tv":25336.13,"id":2497008}],"tv":125277.22}]}
{"op":"mcm","clk":"4299402993","pt":1632580633735,"mc":[{"id":"1.188136695","rc":[{"trd":[[1.25,2743.02]],"batl":[[0,1.25,544.14],[1,1.26,1355.26],[2,1.27,1.71]],"ltp":1.25,"tv":99995.88,"id":5300737},{"trd":[[5,265.05]],"batb":[[0,4.9,170.79],[1,4.8,358.6],[2,4.7,540.15]],"ltp":5.0,"tv":25344.83,"id":2497008}],"tv":125340.72}]}
{"op":"mcm","clk":"4299403315","pt":1632580634740,"mc":[{"id":"1.188136695","rc":[{"batl":[[1,1.26,1378.56]],"ltp":1.25,"tv":99995.88,"id":5300737},{"batb":[[1,4.8,382.28]],"ltp":5.0,"tv":25344.83,"id":2497008}]}]}
{"op":"mcm","clk":"4299403537","pt":1632580635435,"mc":[{"id":"1.188136695","rc":[{"batl":[[1,1.26,1432.76]],"ltp":1.25,"tv":99995.88,"id":5300737}]}]}
{"op":"mcm","clk":"4299404249","pt":1632580637701,"mc":[{"id":"1.188136695","rc":[{"batb":[[0,1.24,3086.49],[1,1.23,1518.46]],"batl":[[0,1.25,613.64],[1,1.26,2615.96],[2,1.27,853.67]],"ltp":1.25,"tv":99995.88,"id":5300737},{"batb":[[1,4.8,510.98],[2,4.7,708.75]],"batl":[[1,5.3,78.51]],"ltp":5.0,"tv":25344.83,"id":2497008}]}]}
{"op":"mcm","clk":"4299404597","pt":1632580638721,"mc":[{"id":"1.188136695","rc":[{"trd":[[1.25,2753.96]],"batl":[[0,1.25,608.17],[2,1.27,625.7]],"ltp":1.25,"tv":100006.82,"id":5300737},{"batb":[[0,4.9,200.89]],"batl":[[1,5.3,64.24]],"ltp":5.0,"tv":25344.83,"id":2497008}],"tv":125351.66}]}
{"op":"mcm","clk":"4299404797","pt":1632580639667,"mc":[{"id":"1.188136695","rc":[{"batb":[[0,1.24,3679.62],[1,1.23,2174.16]],"ltp":1.25,"tv":100006.82,"id":5300737},{"trd":[[5.1,196.24]],"batb":[[0,4.9,181.78]],"batl":[[0,5.1,32.91],[1,5.2,141.43],[2,5.3,64.24]],"ltp":5.1,"tv":25355.33,"id":2497008}],"tv":125362.16}]}
{"op":"mcm","clk":"4299405084","pt":1632580640246,"mc":[{"id":"1.188136695","rc":[{"trd":[[1.25,2772.56]],"batb":[[1,1.23,2459.02],[2,1.22,3573.69]],"batl":[[0,1.25,607.87]],"ltp":1.25,"tv":100025.42,"id":5300737},{"batb":[[0,5,2],[1,4.9,184.78],[2,4.8,510.98]],"ltp":5.1,"tv":25355.33,"id":2497008}],"tv":125380.76}]}
{"op":"mcm","clk":"4299405595","pt":1632580641817,"mc":[{"id":"1.188136695","rc":[{"batb":[[0,1.24,3759.17]],"batl":[[0,1.25,680.57]],"ltp":1.25,"tv":100025.42,"id":5300737}]}]}
{"op":"mcm","clk":"4299405864","pt":1632580642806,"mc":[{"id":"1.188136695","rc":[{"trd":[[1.25,2776.56]],"batb":[[0,1.24,3679.62],[1,1.23,2388.46]],"batl":[[0,1.25,1553.85],[1,1.26,3156.26]],"ltp":1.25,"tv":100029.42,"id":5300737},{"trd":[[5,270.05]],"batb":[[0,5,135],[2,4.8,669.82]],"ltp":5.0,"tv":25360.33,"id":2497008}],"tv":125389.76}]}
{"op":"mcm","clk":"4299406435","pt":1632580644439,"mc":[{"id":"1.188136695","rc":[{"trd":[[1.25,2780.08]],"batl":[[0,1.25,1552.09]],"ltp":1.25,"tv":100032.94,"id":5300737}],"tv":125393.28}]}
{"op":"mcm","clk":"4299406814","pt":1632580645547,"mc":[{"id":"1.188136695","rc":[{"trd":[[1.25,2784.64]],"batl":[[0,1.25,1549.81]],"ltp":1.25,"tv":100037.5,"id":5300737},{"trd":[[5.1,261.72]],"batb":[[2,4.8,671.82]],"batl":[[0,5.2,141.6],[1,5.3,64.24],[2,5.4,295.12]],"ltp":5.1,"tv":25425.81,"id":2497008}],"tv":125463.32}]}
{"op":"mcm","clk":"4299407173","pt":1632580646467,"mc":[{"id":"1.188136695","rc":[{"batl":[[0,1.25,2263.14]],"ltp":1.25,"tv":100037.5,"id":5300737}]}]}
{"op":"mcm","clk":"4299408014","pt":1632580648829,"mc":[{"id":"1.188136695","rc":[{"batl":[[1,1.26,3102.06]],"ltp":1.25,"tv":100037.5,"id":5300737},{"trd":[[5,271.73]],"batb":[[0,5,134.16],[1,4.9,173.79],[2,4.8,313.22]],"ltp":5.0,"tv":25427.5,"id":2497008}],"tv":125465.0}]}
{"op":"mcm","clk":"4299408175","pt":1632580649366,"mc":[{"id":"1.188136695","rc":[{"batb":[[0,1.24,2848.76],[1,1.23,284.86],[2,1.22,367.96]],"batl":[[0,1.25,488.5],[1,1.26,90],[2,1.27,1.71]],"ltp":1.25,"tv":100037.5,"id":5300737},{"batb":[[0,4.9,3],[1,4.8,25.68],[2,4.7,192.1]],"batl":[[0,5.4,69.75],[1,5.5,62.41],[2,5.6,81.09]],"ltp":5.0,"tv":25427.5,"id":2497008}]}]}
{"op":"mcm","clk":"4299408597","pt":1632580650649,"mc":[{"id":"1.188136695","rc":[{"batl":[[0,1.25,69.5],[1,1.27,1.71],[2,1.28,15.99]],"ltp":1.25,"tv":100037.5,"id":5300737},{"batb":[[0,4.7,192.1],[1,4.5,138.52],[2,4.4,82.33]],"ltp":5.0,"tv":25427.5,"id":2497008}]}]}
{"op":"mcm","clk":"4299409237","pt":1632580652748,"mc":[{"id":"1.188136695","rc":[{"trd":[[1.25,2827.42]],"batl":[[0,1.25,48.1],[1,1.27,991.77],[2,1.28,1185]],"ltp":1.25,"tv":100080.29,"id":5300737}],"tv":125507.79}]}
{"op":"mcm","clk":"4299409535","pt":1632580653662,"mc":[{"id":"1.188136695","rc":[{"trd":[[1.25,2828.81]],"batb":[[0,1.24,2700.3]],"batl":[[0,1.25,47.41]],"ltp":1.25,"tv":100081.67,"id":5300737}],"tv":125509.17}]}
{"op":"mcm","clk":"4299409632","pt":1632580653965,"mc":[{"id":"1.188136695","rc":[{"batl":[[1,1.27,1.71],[2,1.28,15.99]],"ltp":1.25,"tv":100081.67,"id":5300737}]}]}
{"op":"mcm","clk":"4299410179","pt":1632580655670,"mc":[{"id":"1.188136695","rc":[{"batb":[[0,4.7,192.45]],"ltp":5.0,"tv":25427.5,"id":2497008}]}]}
{"op":"mcm","clk":"4299410230","pt":1632580655834,"mc":[{"id":"1.188136695","rc":[{"trd":[[1.24,2224.07]],"batb":[[0,1.24,2563.16]],"ltp":1.24,"tv":100355.95,"id":5300737}],"tv":125783.45}]}
{"op":"mcm","clk":"4299410863","pt":1632580657753,"mc":[{"id":"1.188136695","rc":[{"trd":[[1.25,2849.53]],"batl":[[0,1.25,37.04]],"ltp":1.25,"tv":100376.67,"id":5300737}],"tv":125804.17}]}
{"op":"mcm","clk":"4299411190","pt":1632580658785,"mc":[{"id":"1.188136695","rc":[{"batb":[[1,1.23,898.17],[2,1.22,1980.72]],"batl":[[0,1.25,1126.65],[1,1.26,1276.32],[2,1.27,1.71]],"ltp":1.25,"tv":100376.67,"id":5300737},{"batb":[[0,4.7,194.45],[1,4.6,2],[2,4.5,138.52]],"ltp":5.0,"tv":25427.5,"id":2497008}]}]}
{"op":"mcm","clk":"4299411265","pt":1632580658965,"mc":[{"id":"1.188136695","rc":[{"trd":[[1.25,2851.05]],"batb":[[1,1.23,284.86],[2,1.22,367.96]],"batl":[[0,1.25,294.28],[1,1.27,1.71],[2,1.28,15.99]],"ltp":1.25,"tv":100378.2,"id":5300737}],"tv":125805.7}]}
{"op":"mcm","clk":"4299411899","pt":1632580660761,"mc":[{"id":"1.188136695","rc":[{"trd":[[1.25,2925.02],[1.27,1765.3]],"batb":[[0,1.24,3027.28]],"batl":[[0,1.26,707.39],[1,1.28,15.99],[2,1.29,8.63]],"ltp":1.27,"tv":100622.8,"id":5300737},{"trd":[[5,272.08]],"batb":[[0,4.7,194.1]],"ltp":5.0,"tv":25427.85,"id":2497008}],"tv":126050.65}]}
{"op":"mcm","clk":"4299412218","pt":1632580661761,"mc":[{"id":"1.188136695","rc":[{"batb":[[0,1.24,2559.65]],"batl":[[0,1.27,49.22]],"ltp":1.27,"tv":100622.8,"id":5300737}]}]}
{"op":"mcm","clk":"4299413287","pt":1632580664747,"mc":[{"id":"1.188136695","rc":[{"batl":[[0,1.27,1047.39],[1,1.28,1194]],"ltp":1.27,"tv":100622.8,"id":5300737}]}]}
{"op":"mcm","clk":"4299413429","pt":1632580665163,"mc":[{"id":"1.188136695","rc":[{"batb":[[0,1.24,2559.75]],"ltp":1.27,"tv":100622.8,"id":5300737}]}]}
{"op":"mcm","clk":"4299413983","pt":1632580666775,"mc":[{"id":"1.188136695","rc":[{"batb":[[1,1.21,965.5],[2,1.2,2389.78]],"ltp":1.27,"tv":100622.8,"id":5300737},{"batl":[[0,5.4,1.17],[1,5.9,1],[2,6.6,2.91]],"ltp":5.0,"tv":25427.85,"id":2497008}]}]}
{"op":"mcm","clk":"4299414504","pt":1632580668264,"mc":[{"id":"1.188136695","rc":[{"trd":[[1.24,2225.33],[1.25,2925.12]],"batb":[[0,1.24,2558.39]],"ltp":1.24,"tv":100624.16,"id":5300737},{"trd":[[5,272.11],[5.1,262.06],[5.2,20.3]],"batl":[[0,5.4,1]],"ltp":5.2,"tv":25428.51,"id":2497008}],"tv":126052.68}]}
{"op":"mcm","clk":"4299414987","pt":1632580669776,"mc":[{"id":"1.188136695","rc":[{"batb":[[0,1.24,20228.3],[1,1.23,2651.04],[2,1.22,1131.86]],"batl":[[0,1.27,1039.39],[1,1.28,1185]],"ltp":1.24,"tv":100624.16,"id":5300737},{"trd":[[4.7,191.8]],"batb":[[0,4.7,183.01],[1,4.5,521.02],[2,4.4,453.59]],"ltp":4.7,"tv":25446.69,"id":2497008}],"tv":126070.86}]}
{"op":"mcm","clk":"4299415328","pt":1632580670771,"mc":[{"id":"1.188136695","rc":[{"batb":[[0,1.24,5770.24],[1,1.23,2838.7],[2,1.22,2417.88]],"batl":[[1,1.28,1275]],"ltp":1.24,"tv":100624.16,"id":5300737},{"batb":[[1,4.6,25],[2,4.5,732.91]],"batl":[[0,5.1,2],[1,5.4,11.72],[2,5.9,1]],"ltp":4.7,"tv":25446.69,"id":2497008}]}]}
{"op":"mcm","clk":"4299415960","pt":1632580672755,"mc":[{"id":"1.188136695","rc":[{"trd":[[1.27,1865.29]],"batb":[[0,1.25,1.89],[1,1.24,5831.26],[2,1.23,2838.7]],"batl":[[0,1.27,989.39]],"ltp":1.27,"tv":100724.16,"id":5300737},{"batl":[[0,5.1,4]],"ltp":4.7,"tv":25446.69,"id":2497008}],"tv":126170.86}]}
{"op":"mcm","clk":"4299416324","pt":1632580673781,"mc":[{"id":"1.188136695","rc":[{"batb":[[0,1.25,343.82]],"batl":[[0,1.26,63.36],[1,1.27,1050.22],[2,1.28,1275]],"ltp":1.27,"tv":100724.16,"id":5300737}]}]}
{"op":"mcm","clk":"4299416564","pt":1632580674568,"mc":[{"id":"1.188136695","rc":[{"batb":[[1,1.24,5890.91]],"ltp":1.27,"tv":100724.16,"id":5300737}]}]}
{"op":"mcm","clk":"4299416712","pt":1632580675044,"mc":[{"id":"1.188136695","rc":[{"batb":[[0,1.25,878.9]],"batl":[[1,1.27,1825.24]],"ltp":1.27,"tv":100724.16,"id":5300737}]}]}
{"op":"mcm","clk":"4299417221","pt":1632580676663,"mc":[{"id":"1.188136695","rc":[{"trd":[[1.25,2942.26]],"batb":[[0,1.25,870.32],[2,1.23,3131.61]],"ltp":1.25,"tv":100741.3,"id":5300737},{"batl":[[1,5.3,54.58],[2,5.4,89.97]],"ltp":4.7,"tv":25446.69,"id":2497008}],"tv":126188.0}]}
{"op":"mcm","clk":"4299417740","pt":1632580678601,"mc":[{"id":"1.188136695","rc":[{"batb":[[0,1.26,208.33],[1,1.25,603.15],[2,1.24,5831.26]],"batl":[[0,1.27,1825.24],[1,1.28,1275],[2,1.29,8.63]],"ltp":1.25,"tv":100741.3,"id":5300737}]}]}
{"op":"mcm","clk":"4299418069","pt":1632580679684,"mc":[{"id":"1.188136695","rc":[{"trd":[[1.26,1343.91]],"batb":[[0,1.26,206.57]],"ltp":1.26,"tv":100744.82,"id":5300737},{"batl":[[0,5.1,15.81]],"ltp":4.7,"tv":25446.69,"id":2497008}],"tv":126191.52}]}
{"op":"mcm","clk":"4299418793","pt":1632580681791,"mc":[{"id":"1.188136695","rc":[{"trd":[[1.26,1757.06]],"batb":[[0,1.25,603.15],[1,1.24,5706.26],[2,1.23,3131.61]],"ltp":1.26,"tv":101157.96,"id":5300737}],"tv":126604.66}]}
{"op":"mcm","clk":"4299419080","pt":1632580682596,"mc":[{"id":"1.188136695","rc":[{"batb":[[0,1.25,604.55]],"batl":[[1,1.28,1830.41],[2,1.29,656.61]],"ltp":1.26,"tv":101157.96,"id":5300737},{"batb":[[2,4.5,890.89]],"ltp":4.7,"tv":25446.69,"id":2497008}]}]}
{"op":"mcm","clk":"4299419480","pt":1632580683795,"mc":[{"id":"1.188136695","rc":[{"batb":[[0,1.26,1.97],[1,1.25,604.55],[2,1.24,5706.26]],"batl":[[0,1.27,2629.65],[1,1.28,2486.33]],"ltp":1.26,"tv":101157.96,"id":5300737},{"batb":[[0,4.7,323.35],[2,4.5,1078.13]],"batl":[[0,4.8,2.93],[1,5.1,15.81],[2,5.3,54.58]],"ltp":4.7,"tv":25446.69,"id":2497008}]}]}
{"op":"mcm","clk":"4299419706","pt":1632580684493,"mc":[{"id":"1.188136695","rc":[{"batb":[[1,1.25,1186.54],[2,1.24,6525.66]],"ltp":1.26,"tv":101157.96,"id":5300737},{"batl":[[1,5,145.5],[2,5.1,15.81]],"ltp":4.7,"tv":25446.69,"id":2497008}]}]}
{"op":"mcm","clk":"4299420109","pt":1632580685745,"mc":[{"id":"1.188136695","rc":[{"trd":[[1.26,1757.76]],"batb":[[0,1.26,1.62]],"batl":[[2,1.29,647.98]],"ltp":1.26,"tv":101158.66,"id":5300737}],"tv":126605.36}]}
{"op":"mcm","clk":"4299420462","pt":1632580686797,"mc":[{"id":"1.188136695","rc":[{"trd":[[1.26,1772.14]],"batb":[[0,1.25,1186.54],[1,1.24,6525.66],[2,1.23,3131.61]],"batl":[[0,1.26,698.1],[1,1.27,2629.65],[2,1.28,2486.33]],"ltp":1.26,"tv":101173.04,"id":5300737},{"trd":[[4.8,36.36]],"batl":[[0,5,145.5],[1,5.1,15.81],[2,5.2,195.39]],"ltp":4.8,"tv":25449.62,"id":2497008}],"tv":126622.66}]}
{"op":"mcm","clk":"4299421147","pt":1632580688817,"mc":[{"id":"1.188136695","rc":[{"batl":[[1,1.27,3930.49]],"ltp":1.26,"tv":101173.04,"id":5300737}]}]}
{"op":"mcm","clk":"4299421387","pt":1632580689595,"mc":[{"id":"1.188136695","rc":[{"batl":[[0,1.26,698.79],[1,1.27,2568.82]],"ltp":1.26,"tv":101173.04,"id":5300737}]}]}
{"op":"mcm","clk":"4299421742","pt":1632580690624,"mc":[{"id":"1.188136695","rc":[{"batb":[[0,1.25,604.55],[1,1.24,5645.24],[2,1.23,1965.45]],"batl":[[1,1.27,2051.12],[2,1.28,1272.65]],"ltp":1.26,"tv":101173.04,"id":5300737},{"batb":[[0,4.7,183.01],[2,4.5,350.41]],"batl":[[0,5.1,4],[1,5.3,54.58],[2,5.4,89.97]],"ltp":4.8,"tv":25449.62,"id":2497008}]}]}
{"op":"mcm","clk":"4299422085","pt":1632580691736,"mc":[{"id":"1.188136695","rc":[{"batb":[[0,1.25,69.47],[1,1.24,2558.39],[2,1.23,1563.81]],"batl":[[0,1.26,83.53],[1,1.27,286.71],[2,1.28,103.64]],"ltp":1.26,"tv":101173.04,"id":5300737},{"batb":[[0,4.6,25],[1,4.5,350.41],[2,4.3,70.35]],"batl":[[0,5.1,2]],"ltp":4.8,"tv":25449.62,"id":2497008}]}]}
{"op":"mcm","clk":"4299422241","pt":1632580692127,"mc":[{"id":"1.188136695","rc":[{"batb":[[2,1.23,1376.15]],"batl":[[1,1.27,1.71],[2,1.28,13.64]],"ltp":1.26,"tv":101173.04,"id":5300737},{"batb":[[0,4.5,350.41],[1,4.3,70.35],[2,4.2,81.98]],"batl":[[0,5.3,54.58],[1,5.4,79.25],[2,5.5,92.84]],"ltp":4.8,"tv":25449.62,"id":2497008}]}]}
{"op":"mcm","clk":"4299422601","pt":1632580693305,"mc":[{"id":"1.188136695","rc":[{"batb":[[1,4.3,70.67]],"ltp":4.8,"tv":25449.62,"id":2497008}]}]}
{"op":"mcm","clk":"4299422971","pt":1632580694532,"mc":[{"id":"1.188136695","rc":[{"trd":[[1.26,1793.17]],"batl":[[0,1.26,73.01]],"ltp":1.26,"tv":101194.08,"id":5300737}],"tv":126643.7}]}
{"op":"mcm","clk":"4299423170","pt":1632580695120,"mc":[{"id":"1.188136695","rc":[{"batb":[[0,1.25,1.4]],"batl":[[0,1.26,73.21]],"ltp":1.26,"tv":101194.08,"id":5300737}]}]}
{"op":"mcm","clk":"4299424030","pt":1632580697767,"mc":[{"id":"1.188136695","rc":[{"batl":[[2,1.28,1967.43]],"ltp":1.26,"tv":101194.08,"id":5300737}]}]}
{"op":"mcm","clk":"4299424276","pt":1632580698328,"mc":[{"id":"1.188136695","rc":[{"batl":[[0,1.26,92.96],[2,1.28,13.64]],"ltp":1.26,"tv":101194.08,"id":5300737},{"batb":[[0,4.9,19.46],[1,4.5,350.41],[2,4.3,70.67]],"batl":[[0,5,20.2],[1,5.3,54.58],[2,5.4,79.25]],"ltp":4.8,"tv":25449.62,"id":2497008}]}]}
{"op":"mcm","clk":"4299424688","pt":1632580699622,"mc":[{"id":"1.188136695","rc":[{"trd":[[1.26,1868.77]],"batl":[[0,1.26,35.5]],"ltp":1.26,"tv":101269.68,"id":5300737},{"batb":[[0,4.6,18.25]],"batl":[[0,5.2,13.59]],"ltp":4.8,"tv":25449.62,"id":2497008}],"tv":126719.3}]}
{"op":"mcm","clk":"4299425007","pt":1632580700732,"mc":[{"id":"1.188136695","rc":[{"batb":[[0,1.24,2558.39],[1,1.23,1376.15],[2,1.22,2578.77]],"batl":[[0,1.25,2.53],[1,1.26,37.85],[2,1.27,1.71]],"ltp":1.26,"tv":101269.68,"id":5300737}]}]}
{"op":"mcm","clk":"4299425152","pt":1632580701130,"mc":[{"id":"1.188136695","rc":[{"batb":[[0,1.24,4009.08],[1,1.23,1843.51]],"batl":[[1,1.26,271.85],[2,1.27,1419.36]],"ltp":1.26,"tv":101269.68,"id":5300737}]}]}
{"op":"mcm","clk":"4299425600","pt":1632580702524,"mc":[{"id":"1.188136695","rc":[{"trd":[[1.25,2947.32]],"batb":[[0,1.25,282.37],[1,1.24,4298.55],[2,1.23,1843.51]],"batl":[[0,1.26,875.93],[1,1.27,1419.36],[2,1.28,1173.83]],"ltp":1.25,"tv":101274.74,"id":5300737}],"tv":126724.36}]}
{"op":"mcm","clk":"4299425914","pt":1632580703663,"mc":[{"id":"1.188136695","rc":[{"batb":[[0,1.24,2558.39],[1,1.23,1376.15],[2,1.22,2578.77]],"batl":[[0,1.26,271.85],[1,1.27,1.71],[2,1.28,13.64]],"ltp":1.25,"tv":101274.74,"id":5300737},{"batb":[[0,4.5,350.41],[1,4.3,70.67],[2,4.2,81.98]],"batl":[[0,5.3,54.58],[1,5.4,79.25],[2,5.5,92.84]],"ltp":4.8,"tv":25449.62,"id":2497008}]}]}
{"op":"mcm","clk":"4299426092","pt":1632580704244,"mc":[{"id":"1.188136695","rc":[{"batl":[[0,1.26,37.85]],"ltp":1.25,"tv":101274.74,"id":5300737}]}]}
{"op":"mcm","clk":"4299426537","pt":1632580705645,"mc":[{"id":"1.188136695","rc":[{"trd":[[1.26,1870.88]],"batl":[[0,1.25,8.63],[1,1.26,36.79],[2,1.27,1.71]],"ltp":1.26,"tv":101276.84,"id":5300737}],"tv":126726.46}]}
{"op":"mcm","clk":"4299426875","pt":1632580706666,"mc":[{"id":"1.188136695","rc":[{"trd":[[1.25,2948.84]],"batb":[[2,1.22,4204.4]],"batl":[[0,1.25,7.87]],"ltp":1.25,"tv":101278.36,"id":5300737}],"tv":126727.99}]}
{"op":"mcm","clk":"4299427211","pt":1632580707742,"mc":[{"id":"1.188136695","rc":[{"batb":[[1,3.55,3.11],[2,3.3,1]],"ltp":4.8,"tv":25449.62,"id":2497008}]}]}
{"op":"mcm","clk":"4299427496","pt":1632580708629,"mc":[{"id":"1.188136695","rc":[{"trd":[[1.25,2950.28]],"batl":[[0,1.25,7.15]],"ltp":1.25,"tv":101279.8,"id":5300737}],"tv":126729.43}]}
{"op":"mcm","clk":"4299427829","pt":1632580709771,"mc":[{"id":"1.188136695","rc":[{"trd":[[1.25,3005.11]],"batl":[[0,1.25,66.92],[1,1.26,2516.95],[2,1.27,1241.79]],"ltp":1.25,"tv":101334.63,"id":5300737},{"trd":[[5,285.81]],"ltp":5.0,"tv":25463.33,"id":2497008}],"tv":126797.97}]}
{"op":"mcm","clk":"4299428086","pt":1632580710647,"mc":[{"id":"1.188136695","rc":[{"batb":[[2,1.22,3252.14]],"batl":[[0,1.25,2747.22],[1,1.26,4997.11],[2,1.27,2481.87]],"ltp":1.25,"tv":101334.63,"id":5300737}]}]}
{"op":"mcm","clk":"4299428489","pt":1632580711746,"mc":[{"id":"1.188136695","rc":[{"trd":[[1.25,3039.91]],"batl":[[0,1.25,1316.54],[1,1.26,2033.05],[2,1.27,311.73]],"ltp":1.25,"tv":101369.43,"id":5300737},{"trd":[[5,294.51]],"batb":[[0,5,164.79],[1,4.8,23.68],[2,4.7,195.2]],"batl":[[2,5.5,234.89]],"ltp":5.0,"tv":25472.03,"id":2497008}],"tv":126841.47}]}
{"op":"mcm","clk":"4299428779","pt":1632580712628,"mc":[{"id":"1.188136695","rc":[{"trd":[[1.25,3138.35]],"batl":[[0,1.25,1267.32]],"ltp":1.25,"tv":101467.87,"id":5300737}],"tv":126939.9}]}
{"op":"mcm","clk":"4299428985","pt":1632580713309,"mc":[{"id":"1.188136695","rc":[{"batl":[[0,1.25,1217.45]],"ltp":1.25,"tv":101467.87,"id":5300737}]}]}
{"op":"mcm","clk":"4299429424","pt":1632580714623,"mc":[{"id":"1.188136695","rc":[{"batb":[[0,1.24,2957.58]],"batl":[[0,1.25,1886.8],[1,1.26,2110.39]],"ltp":1.25,"tv":101467.87,"id":5300737},{"batb":[[0,5,167.79],[1,4.9,2],[2,4.8,23.68]],"ltp":5.0,"tv":25472.03,"id":2497008}]}]}
{"op":"mcm","clk":"4299429694","pt":1632580715452,"mc":[{"id":"1.188136695","rc":[{"batb":[[1,1.23,1444.05]],"batl":[[0,1.25,1878.8]],"ltp":1.25,"tv":101467.87,"id":5300737},{"batb":[[0,5,164.79],[1,4.8,23.68],[2,4.7,195.2]],"ltp":5.0,"tv":25472.03,"id":2497008}]}]}
{"op":"mcm","clk":"4299430107","pt":1632580716728,"mc":[{"id":"1.188136695","rc":[{"trd":[[1.24,2264.43]],"batb":[[0,1.24,3433.45],[1,1.23,2070.61]],"batl":[[0,1.25,2470.21],[1,1.26,2788.37]],"ltp":1.24,"tv":101506.97,"id":5300737},{"batb":[[0,5,312.64],[1,4.8,177.96]],"batl":[[0,5.2,118.14],[1,5.3,54.58],[2,5.4,221.96]],"ltp":5.0,"tv":25472.03,"id":2497008}],"tv":126979.0}]}
{"op":"mcm","clk":"4299430434","pt":1632580717645,"mc":[{"id":"1.188136695","rc":[{"batb":[[1,1.23,2355.38],[2,1.22,3624.55]],"ltp":1.24,"tv":101506.97,"id":5300737},{"batl":[[2,5.4,284.33]],"ltp":5.0,"tv":25472.03,"id":2497008}]}]}
{"op":"mcm","clk":"4299431115","pt":1632580719684,"mc":[{"id":"1.188136695","rc":[{"trd":[[1.24,2334.51]],"batb":[[0,1.24,3398.41]],"batl":[[0,1.25,2930.21]],"ltp":1.24,"tv":101577.04,"id":5300737},{"batb":[[1,4.9,23.07],[2,4.8,177.96]],"ltp":5.0,"tv":25472.03,"id":2497008}],"tv":127049.07}]}
{"op":"mcm","clk":"4299431446","pt":1632580720871,"mc":[{"id":"1.188136695","rc":[{"batb":[[1,1.23,2287.48]],"batl":[[1,1.26,2711.03]],"ltp":1.24,"tv":101577.04,"id":5300737}]}]}
{"op":"mcm","clk":"4299432006","pt":1632580722560,"mc":[{"id":"1.188136695","rc":[{"trd":[[1.25,3138.97]],"batl":[[0,1.25,2856.77]],"ltp":1.25,"tv":101577.67,"id":5300737},{"trd":[[5,335.21]],"batb":[[0,5,292.29]],"ltp":5.0,"tv":25512.73,"id":2497008}],"tv":127090.4}]}
{"op":"mcm","clk":"4299432461","pt":1632580723730,"mc":[{"id":"1.188136695","rc":[{"trd":[[1.24,2376.3]],"batb":[[0,1.24,3377.51]],"ltp":1.24,"tv":101619.47,"id":5300737}],"tv":127132.2}]}
{"op":"mcm","clk":"4299433038","pt":1632580725764,"mc":[{"id":"1.188136695","rc":[{"trd":[[1.24,2522.57]],"batb":[[0,1.24,3304.38]],"ltp":1.24,"tv":101765.73,"id":5300737}],"tv":127278.46}]}
{"op":"mcm","clk":"4299434044","pt":1632580728863,"mc":[{"id":"1.188136695","rc":[{"trd":[[5,444.86]],"batb":[[0,5,237.47]],"ltp":5.0,"tv":25622.38,"id":2497008}],"tv":127388.11}]}
{"op":"mcm","clk":"4299434616","pt":1632580730745,"mc":[{"id":"1.188136695","rc":[{"batb":[[0,1.24,2541.61],[1,1.23,284.78],[2,1.22,372.41]],"batl":[[0,1.25,526.41],[1,1.26,126.59],[2,1.27,1.71]],"ltp":1.24,"tv":101765.73,"id":5300737},{"batb":[[0,4.9,23.07],[1,4.7,195.2],[2,4.5,138.52]],"batl":[[0,5.4,63.37],[1,5.5,75.61],[2,5.6,92.31]],"ltp":5.0,"tv":25622.38,"id":2497008}]}]}
{"op":"mcm","clk":"4299434914","pt":1632580731760,"mc":[{"id":"1.188136695","rc":[{"trd":[[1.24,2539.71]],"batb":[[0,1.24,2533.04]],"batl":[[0,1.25,66.41],[1,1.26,36.59]],"ltp":1.24,"tv":101782.87,"id":5300737},{"batb":[[0,4.7,193.2],[1,4.5,138.52],[2,4.4,73.89]],"ltp":5.0,"tv":25622.38,"id":2497008}],"tv":127405.25}]}
{"op":"mcm","clk":"4299435527","pt":1632580733767,"mc":[{"id":"1.188136695","rc":[{"trd":[[1.24,2564.81],[1.25,3143.17]],"batb":[[0,1.24,2520.49]],"batl":[[0,1.25,62.21],[2,1.27,1073.96]],"ltp":1.24,"tv":101812.17,"id":5300737},{"trd":[[5,445.91]],"batb":[[0,4.6,196.92]],"ltp":5.0,"tv":25623.43,"id":2497008}],"tv":127435.6}]}
{"op":"mcm","clk":"4299436027","pt":1632580735361,"mc":[{"id":"1.188136695","rc":[{"trd":[[1.25,3208.19]],"batl":[[0,1.25,29.7]],"ltp":1.25,"tv":101877.19,"id":5300737}],"tv":127500.62}]}
{"op":"mcm","clk":"4299436703","pt":1632580737668,"mc":[{"id":"1.188136695","rc":[{"trd":[[1.24,2565.21],[1.25,3208.7]],"batb":[[0,1.24,2520.29]],"batl":[[0,1.25,29.44]],"ltp":1.25,"tv":101878.1,"id":5300737}],"tv":127501.53}]}
{"op":"mcm","clk":"4299436892","pt":1632580738268,"mc":[{"id":"1.188136695","rc":[{"batl":[[2,1.27,1123.18]],"ltp":1.25,"tv":101878.1,"id":5300737}]}]}
{"op":"mcm","clk":"4299437211","pt":1632580739296,"mc":[{"id":"1.188136695","rc":[{"batb":[[0,1.24,2388.45]],"batl":[[2,1.27,50.93]],"ltp":1.25,"tv":101878.1,"id":5300737},{"batb":[[2,3.55,2.73]],"ltp":5.0,"tv":25623.43,"id":2497008}]}]}
{"op":"mcm","clk":"4299437553","pt":1632580740454,"mc":[{"id":"1.188136695","rc":[{"trd":[[1.24,7342.1]],"batb":[[0,1.23,284.78],[1,1.22,372.41],[2,1.21,2834.32]],"ltp":1.24,"tv":106654.99,"id":5300737}],"tv":132278.42}]}
{"op":"mcm","clk":"4299437974","pt":1632580741778,"mc":[{"id":"1.188136695","rc":[{"trd":[[1.23,249.1]],"batb":[[0,1.21,2834.32],[1,1.2,4557.39],[2,1.19,952.38]],"ltp":1.23,"tv":106744.55,"id":5300737},{"batb":[[0,5.2,55.17],[1,5.1,53.55],[2,5,53.55]],"batl":[[0,5.4,1],[1,5.6,92.31],[2,5.9,1]],"ltp":5.0,"tv":25623.43,"id":2497008}],"tv":132367.98}]}
{"op":"mcm","clk":"4299438300","pt":1632580742786,"mc":[{"id":"1.188136695","rc":[{"batl":[[0,1.23,686.99],[1,1.24,1417.86],[2,1.26,3.12]],"ltp":1.23,"tv":106744.55,"id":5300737},{"batb":[[0,5.2,331.01],[1,5.1,321.28],[2,5,321.28]],"batl":[[1,5.9,1],[2,6,7.64]],"ltp":5.0,"tv":25623.43,"id":2497008}]}]}
{"op":"mcm","clk":"4299438619","pt":1632580743754,"mc":[{"id":"1.188136695","rc":[{"trd":[[1.23,284.26]],"batl":[[0,1.23,1604.09]],"ltp":1.23,"tv":106779.71,"id":5300737},{"trd":[[5.3,10.74]],"batb":[[0,5.3,142.55],[1,5.2,331.01],[2,5.1,343.23]],"ltp":5.3,"tv":25631.59,"id":2497008}],"tv":132411.3}]}
{"op":"mcm","clk":"4299438807","pt":1632580744365,"mc":[{"id":"1.188136695","rc":[{"batl":[[1,1.24,1478.84]],"ltp":1.23,"tv":106779.71,"id":5300737}]}]}
{"op":"mcm","clk":"4299439247","pt":1632580745781,"mc":[{"id":"1.188136695","rc":[{"trd":[[1.23,530.26]],"batb":[[0,1.21,2895.69],[1,1.2,4567.39],[2,1.19,1158.85]],"batl":[[0,1.23,1481.09]],"ltp":1.23,"tv":107025.71,"id":5300737},{"batl":[[1,5.8,2],[2,5.9,1]],"ltp":5.3,"tv":25631.59,"id":2497008}],"tv":132657.3}]}
{"op":"mcm","clk":"4299439526","pt":1632580746582,"mc":[{"id":"1.188136695","rc":[{"batb":[[0,1.22,96.46],[1,1.21,3646.7],[2,1.2,4567.39]],"batl":[[0,1.23,2455.19],[1,1.24,1547.93],[2,1.27,51.7]],"ltp":1.23,"tv":107025.71,"id":5300737},{"trd":[[5.3,19.53],[5.4,2]],"batb":[[0,5.3,141.16],[1,5.2,334.01]],"batl":[[0,5.8,2],[1,5.9,1],[2,6,7.64]],"ltp":5.4,"tv":25642.37,"id":2497008}],"tv":132668.09}]}
{"op":"mcm","clk":"4299439869","pt":1632580747582,"mc":[{"id":"1.188136695","rc":[{"batb":[[2,1.2,4623.7]],"batl":[[0,1.23,2451.19]],"ltp":1.23,"tv":107025.71,"id":5300737},{"batb":[[0,5.3,138.16],[1,5.2,331.01],[2,5.1,321.28]],"ltp":5.4,"tv":25642.37,"id":2497008}]}]}
{"op":"mcm","clk":"4299440548","pt":1632580749798,"mc":[{"id":"1.188136695","rc":[{"trd":[[1.23,630.26]],"batb":[[2,1.2,4900.77]],"batl":[[0,1.23,2401.19],[2,1.27,270.46]],"ltp":1.23,"tv":107125.71,"id":5300737},{"batl":[[0,5.8,12],[2,6,70.37]],"ltp":5.4,"tv":25642.37,"id":2497008}],"tv":132768.09}]}
{"op":"mcm","clk":"4299440856","pt":1632580750759,"mc":[{"id":"1.188136695","rc":[{"batl":[[0,1.23,2853.19],[1,1.24,1638.28]],"ltp":1.23,"tv":107125.71,"id":5300737},{"batb":[[1,5.2,352.43]],"ltp":5.4,"tv":25642.37,"id":2497008}]}]}
{"op":"mcm","clk":"4299441150","pt":1632580751699,"mc":[{"id":"1.188136695","rc":[{"trd":[[1.22,272.78]],"batb":[[0,1.22,82.98]],"batl":[[2,1.27,259.94]],"ltp":1.22,"tv":107152.67,"id":5300737}],"tv":132795.05}]}
{"op":"mcm","clk":"4299441501","pt":1632580752769,"mc":[{"id":"1.188136695","rc":[{"batb":[[2,1.2,4844.46]],"batl":[[0,1.23,3492.6],[1,1.24,2385.17],[2,1.27,221.24]],"ltp":1.22,"tv":107152.67,"id":5300737},{"batb":[[0,5.3,286.54],[2,5.1,519.67]],"ltp":5.4,"tv":25642.37,"id":2497008}]}]}
{"op":"mcm","clk":"4299441778","pt":1632580753717,"mc":[{"id":"1.188136695","rc":[{"trd":[[1.22,314.96]],"batb":[[0,1.22,61.89],[1,1.21,4225.26],[2,1.2,5533.58]],"batl":[[2,1.27,220.55]],"ltp":1.22,"tv":107194.85,"id":5300737},{"batl":[[0,5.8,132.69],[2,6,208.2]],"ltp":5.4,"tv":25642.37,"id":2497008}],"tv":132837.22}]}
{"op":"mcm","clk":"4299441974","pt":1632580754278,"mc":[{"id":"1.188136695","rc":[{"batl":[[2,1.26,11.48]],"ltp":1.22,"tv":107194.85,"id":5300737}]}]}
{"op":"mcm","clk":"4299443018","pt":1632580757584,"mc":[{"id":"1.188136695","rc":[{"trd":[[1.22,375.92]],"batb":[[0,1.22,31.41],[2,1.2,5523.58]],"ltp":1.22,"tv":107255.8,"id":5300737}],"tv":132898.18}]}
{"op":"mcm","clk":"4299443107","pt":1632580757868,"mc":[{"id":"1.188136695","rc":[{"trd":[[1.23,650.26]],"batl":[[0,1.23,3482.6]],"ltp":1.23,"tv":107275.8,"id":5300737}],"tv":132918.18}]}
{"op":"mcm","clk":"4299443642","pt":1632580759618,"mc":[{"id":"1.188136695","rc":[{"trd":[[1.21,7.3],[1.22,438.74]],"batb":[[0,1.21,4221.61],[1,1.2,5523.58],[2,1.19,1813.21]],"ltp":1.21,"tv":107345.93,"id":5300737}],"tv":132988.3}]}
{"op":"mcm","clk":"4299443960","pt":1632580760686,"mc":[{"id":"1.188136695","rc":[{"batb":[[0,1.21,1029.47],[1,1.2,1234.89]],"batl":[[0,1.23,1479.22],[1,1.24,90.35]],"ltp":1.21,"tv":107345.93,"id":5300737},{"batb":[[0,5.2,21.42],[1,4.9,171.98],[2,4.8,73.06]],"batl":[[0,5.8,2],[2,6,62.73]],"ltp":5.4,"tv":25642.37,"id":2497008}]}]}
{"op":"mcm","clk":"4299444304","pt":1632580761699,"mc":[{"id":"1.188136695","rc":[{"batb":[[0,1.21,66.86],[2,1.19,1606.74]],"batl":[[1,1.26,11.83],[2,1.27,220.47]],"ltp":1.21,"tv":107345.93,"id":5300737},{"batb":[[0,4.9,171.98],[1,4.8,73.06],[2,4.7,74.85]],"batl":[[0,5.9,1],[1,6,62.73],[2,6.2,70.81]],"ltp":5.4,"tv":25642.37,"id":2497008}]}]}
{"op":"mcm","clk":"4299444601","pt":1632580762697,"mc":[{"id":"1.188136695","rc":[{"batb":[[1,1.2,282.63]],"batl":[[0,1.23,1027.22]],"ltp":1.21,"tv":107345.93,"id":5300737}]}]}
{"op":"mcm","clk":"4299444928","pt":1632580763805,"mc":[{"id":"1.188136695","rc":[{"batb":[[2,1.19,2952.29]],"batl":[[1,1.25,702.53],[2,1.26,1297.2]],"ltp":1.21,"tv":107345.93,"id":5300737}]}]}
{"op":"mcm","clk":"4299445502","pt":1632580765693,"mc":[{"id":"1.188136695","rc":[{"batb":[[0,1.2,282.63],[1,1.19,1606.74],[2,1.18,1642.59]],"batl":[[1,1.26,11.48],[2,1.27,220.47]],"ltp":1.21,"tv":107345.93,"id":5300737}]}]}
{"op":"mcm","clk":"4299445728","pt":1632580766395,"mc":[{"id":"1.188136695","rc":[{"batl":[[0,1.21,2193.94],[1,1.23,1027.22],[2,1.26,11.39]],"ltp":1.21,"tv":107345.93,"id":5300737}]}]}
{"op":"mcm","clk":"4299446077","pt":1632580767645,"mc":[{"id":"1.188136695","rc":[{"trd":[[1.21,57.3]],"batl":[[0,1.21,2168.94],[1,1.23,74.96]],"ltp":1.21,"tv":107395.93,"id":5300737}],"tv":133038.31}]}
{"op":"mcm","clk":"4299446457","pt":1632580768796,"mc":[{"id":"1.188136695","rc":[{"trd":[[1.21,1530.63]],"batb":[[0,1.2,2092.74],[1,1.19,654.48]],"batl":[[0,1.21,1385.81],[1,1.22,137.14],[2,1.23,1379.87]],"ltp":1.21,"tv":108869.26,"id":5300737},{"trd":[[5.7,19.73]],"ltp":5.7,"tv":25662.1,"id":2497008}],"tv":134531.36}]}
{"op":"mcm","clk":"4299446754","pt":1632580769815,"mc":[{"id":"1.188136695","rc":[{"batb":[[0,1.2,2164.74]],"ltp":1.21,"tv":108869.26,"id":5300737},{"batb":[[0,5,28.01],[1,4.9,171.98],[2,4.8,73.06]],"batl":[[0,5.9,6]],"ltp":5.7,"tv":25662.1,"id":2497008}]}]}
{"op":"mcm","clk":"4299447302","pt":1632580771728,"mc":[{"id":"1.188136695","rc":[{"trd":[[1.21,1550.63]],"batl":[[0,1.21,1375.81],[1,1.23,1304.91],[2,1.24,1400.58]],"ltp":1.21,"tv":108889.25,"id":5300737}],"tv":134551.36}]}
{"op":"mcm","clk":"4299447591","pt":1632580772710,"mc":[{"id":"1.188136695","rc":[{"batb":[[0,1.2,2092.74]],"ltp":1.21,"tv":108889.25,"id":5300737},{"batb":[[0,4.9,171.98],[1,4.8,73.06],[2,4.7,74.85]],"batl":[[0,5.9,1]],"ltp":5.7,"tv":25662.1,"id":2497008}]}]}
{"op":"mcm","clk":"4299447893","pt":1632580773727,"mc":[{"id":"1.188136695","rc":[{"batb":[[0,1.2,282.63],[1,1.19,1652.17]],"batl":[[1,1.26,11.39],[2,1.27,220.47]],"ltp":1.21,"tv":108889.25,"id":5300737}]}]}
{"op":"mcm","clk":"4299448845","pt":1632580776820,"mc":[{"id":"1.188136695","rc":[{"trd":[[1.21,1552.65]],"batb":[[2,1.18,3712.37]],"batl":[[0,1.21,1373.78],[1,1.25,1016.79],[2,1.26,1297.7]],"ltp":1.21,"tv":108891.28,"id":5300737},{"trd":[[5.7,20.16]],"ltp":5.7,"tv":25662.53,"id":2497008}],"tv":134553.82}]}
{"op":"mcm","clk":"4299449633","pt":1632580779452,"mc":[{"id":"1.188136695","rc":[{"trd":[[1.21,1562.98]],"batl":[[0,1.21,1363.45]],"ltp":1.21,"tv":108901.61,"id":5300737},{"trd":[[5.7,22.35]],"ltp":5.7,"tv":25664.73,"id":2497008}],"tv":134566.34}]}
{"op":"mcm","clk":"4299450103","pt":1632580780822,"mc":[{"id":"1.188136695","rc":[{"trd":[[1.2,172.06]],"batb":[[0,1.2,196.61]],"ltp":1.2,"tv":109073.67,"id":5300737}],"tv":134738.4}]}
{"op":"mcm","clk":"4299450716","pt":1632580782614,"mc":[{"id":"1.188136695","rc":[{"batb":[[0,1.19,1652.17],[1,1.18,3431.01],[2,1.17,2009.82]],"batl":[[1,1.26,11.39],[2,1.27,1.71]],"ltp":1.2,"tv":109073.67,"id":5300737},{"batb":[[1,4.5,138.52],[2,3.55,3.73]],"batl":[[1,6.2,70.81],[2,6.4,65.65]],"ltp":5.7,"tv":25664.73,"id":2497008}]}]}
{"op":"mcm","clk":"4299451397","pt":1632580784728,"mc":[{"id":"1.188136695","rc":[{"trd":[[1.21,1563.69]],"batl":[[0,1.21,1363.1]],"ltp":1.21,"tv":109074.37,"id":5300737},{"batb":[[0,5.5,1095.34],[1,5.4,1063.12],[2,5.3,1063.12]],"ltp":5.7,"tv":25664.73,"id":2497008}],"tv":134739.1}]}
{"op":"mcm","clk":"4299451706","pt":1632580785718,"mc":[{"id":"1.188136695","rc":[{"trd":[[1.21,1633.8]],"batb":[[0,1.19,1666.17],[1,1.18,3443.01]],"batl":[[0,1.21,2711.48],[1,1.22,1558.64],[2,1.26,11.39]],"ltp":1.21,"tv":109144.49,"id":5300737},{"trd":[[5.9,2],[6,15.38]],"batb":[[0,6,209.62],[1,5.6,127.84],[2,5.5,312.96]],"batl":[[0,6.2,70.81],[1,6.4,65.65],[2,6.8,254.13]],"ltp":6.0,"tv":25682.11,"id":2497008}],"tv":134826.6}]}
{"op":"mcm","clk":"4299452040","pt":1632580786753,"mc":[{"id":"1.188136695","rc":[{"trd":[[1.2,174.52]],"batb":[[2,1.17,2228.1]],"batl":[[1,1.22,1648.64]],"ltp":1.2,"tv":109146.95,"id":5300737},{"trd":[[6,15.87]],"batb":[[0,6,209.13],[2,5.5,332.96]],"batl":[[0,6.4,65.65],[1,6.8,263.47],[2,7,249.95]],"ltp":6.0,"tv":25682.6,"id":2497008}],"tv":134829.55}]}
{"op":"mcm","clk":"4299452359","pt":1632580787723,"mc":[{"id":"1.188136695","rc":[{"batb":[[0,1.19,1709.55]],"batl":[[0,1.2,952.26],[1,1.21,3663.74],[2,1.22,1558.64]],"ltp":1.2,"tv":109146.95,"id":5300737}]}]}
{"op":"mcm","clk":"4299452682","pt":1632580788725,"mc":[{"id":"1.188136695","rc":[{"trd":[[1.2,175.22]],"batl":[[0,1.2,951.91]],"ltp":1.2,"tv":109147.65,"id":5300737}],"tv":134830.25}]}
{"op":"mcm","clk":"4299452987","pt":1632580789744,"mc":[{"id":"1.188136695","rc":[{"batb":[[0,1.19,2670.6]],"batl":[[0,1.2,956.37],[1,1.21,5142.03],[2,1.22,2295.76]],"ltp":1.2,"tv":109147.65,"id":5300737},{"trd":[[6,26.65]],"batb":[[0,6,203.74],[1,5.7,133.37],[2,5.6,127.84]],"batl":[[0,6.4,77.55]],"ltp":6.0,"tv":25693.38,"id":2497008}],"tv":134841.03}]}
{"op":"mcm","clk":"4299453306","pt":1632580790732,"mc":[{"id":"1.188136695","rc":[{"batb":[[0,1.19,3020.6],[1,1.18,4143.01]],"batl":[[0,1.2,1194.26],[1,1.21,5232.03]],"ltp":1.2,"tv":109147.65,"id":5300737}]}]}
{"op":"mcm","clk":"4299453650","pt":1632580791746,"mc":[{"id":"1.188136695","rc":[{"trd":[[1.19,4285.6]],"batb":[[0,1.19,877.8]],"batl":[[0,1.2,1195.97]],"ltp":1.19,"tv":113433.25,"id":5300737}],"tv":139126.63}]}
{"op":"mcm","clk":"4299453942","pt":1632580792730,"mc":[{"id":"1.188136695","rc":[{"batb":[[1,1.18,4394.18],[2,1.17,2652.55]],"ltp":1.19,"tv":113433.25,"id":5300737},{"batb":[[1,5.8,18.75],[2,5.7,133.37]],"batl":[[0,6.4,135.51],[1,6.6,68.05],[2,6.8,321.33]],"ltp":6.0,"tv":25693.38,"id":2497008}]}]}
{"op":"mcm","clk":"4299454253","pt":1632580793720,"mc":[{"id":"1.188136695","rc":[{"trd":[[1.19,4312.62],[1.2,192.36]],"batb":[[0,1.19,1214.29]],"batl":[[0,1.2,1182.94]],"ltp":1.2,"tv":113477.41,"id":5300737}],"tv":139170.79}]}
{"op":"mcm","clk":"4299454545","pt":1632580794748,"mc":[{"id":"1.188136695","rc":[{"batb":[[0,1.19,1792.17],[1,1.18,6056.37]],"batl":[[1,1.21,5644.91]],"ltp":1.2,"tv":113477.41,"id":5300737},{"batb":[[0,5.9,225.58]],"ltp":6.0,"tv":25693.38,"id":2497008}]}]}
{"op":"mcm","clk":"4299455105","pt":1632580796472,"mc":[{"id":"1.188136695","rc":[{"trd":[[1.19,4456.54],[1.2,262.48]],"batb":[[0,1.19,1720.21]],"batl":[[0,1.2,1152.29]],"ltp":1.19,"tv":113691.45,"id":5300737},{"batb":[[0,6,150],[1,5.9,225.58],[2,5.8,18.75]],"ltp":6.0,"tv":25693.38,"id":2497008}],"tv":139384.83}]}
{"op":"mcm","clk":"4299455628","pt":1632580798351,"mc":[{"id":"1.188136695","rc":[{"batb":[[2,1.17,2434.27]],"batl":[[0,1.2,1777.97],[1,1.21,6219.18]],"ltp":1.19,"tv":113691.45,"id":5300737},{"batb":[[0,6,274.11],[2,5.7,274.37]],"batl":[[2,6.8,311.99]],"ltp":6.0,"tv":25693.38,"id":2497008}]}]}
{"op":"mcm","clk":"4299456022","pt":1632580799662,"mc":[{"id":"1.188136695","rc":[{"batb":[[0,1.19,1730.21],[1,1.18,17958.93]],"batl":[[0,1.2,2692.84]],"ltp":1.19,"tv":113691.45,"id":5300737},{"trd":[[6,32.51]],"batb":[[0,6,271.18]],"ltp":6.0,"tv":25699.23,"id":2497008}],"tv":139390.69}]}
{"op":"mcm","clk":"4299456673","pt":1632580801729,"mc":[{"id":"1.188136695","rc":[{"trd":[[1.2,264.98]],"batl":[[0,1.2,2691.59],[1,1.21,6309.18]],"ltp":1.2,"tv":113693.95,"id":5300737},{"batb":[[2,5.8,18.75]],"ltp":6.0,"tv":25699.23,"id":2497008}],"tv":139393.19}]}
{"op":"mcm","clk":"4299457332","pt":1632580803768,"mc":[{"id":"1.188136695","rc":[{"trd":[[1.19,4476.74]],"batb":[[0,1.19,1710.11]],"ltp":1.19,"tv":113714.16,"id":5300737}],"tv":139413.4}]}
{"op":"mcm","clk":"4299457544","pt":1632580804370,"mc":[{"id":"1.188136695","rc":[{"trd":[[1.2,266.68]],"batb":[[2,1.17,2652.55]],"batl":[[0,1.2,2690.74]],"ltp":1.2,"tv":113715.85,"id":5300737}],"tv":139415.09}]}
{"op":"mcm","clk":"4299458020","pt":1632580805660,"mc":[{"id":"1.188136695","rc":[{"trd":[[1.2,336.8]],"batl":[[0,1.2,2655.68]],"ltp":1.2,"tv":113785.97,"id":5300737}],"tv":139485.21}]}
{"op":"mcm","clk":"4299458673","pt":1632580807767,"mc":[{"id":"1.188136695","rc":[{"batb":[[0,6,421.18]],"ltp":6.0,"tv":25699.23,"id":2497008}]}]}
{"op":"mcm","clk":"4299458958","pt":1632580808749,"mc":[{"id":"1.188136695","rc":[{"trd":[[1.2,343.52]],"batl":[[0,1.2,2652.32]],"ltp":1.2,"tv":113792.69,"id":5300737}],"tv":139491.93}]}
{"op":"mcm","clk":"4299459590","pt":1632580810666,"mc":[{"id":"1.188136695","rc":[{"trd":[[1.19,4477.44],[1.2,413.64]],"batb":[[0,1.19,1709.76]],"batl":[[0,1.2,2617.26]],"ltp":1.2,"tv":113863.51,"id":5300737}],"tv":139562.75}]}
{"op":"mcm","clk":"4299459943","pt":1632580811651,"mc":[{"id":"1.188136695","rc":[{"trd":[[1.19,4521.3],[1.2,414.9]],"batb":[[0,1.19,1687.83]],"batl":[[0,1.2,2616.63],[1,1.21,4981.14]],"ltp":1.19,"tv":113908.64,"id":5300737}],"tv":139607.88}]}
{"op":"mcm","clk":"4299460233","pt":1632580812670,"mc":[{"id":"1.188136695","rc":[{"trd":[[1.19,7344.04]],"batb":[[0,1.18,17958.93],[1,1.17,2652.55],[2,1.16,1301.25]],"ltp":1.19,"tv":116731.38,"id":5300737}],"tv":142430.61}]}
{"op":"mcm","clk":"4299460492","pt":1632580813481,"mc":[{"id":"1.188136695","rc":[{"trd":[[1.18,3.43],[1.19,7347.56]],"batb":[[0,1.18,17957.22]],"batl":[[0,1.19,198.24],[1,1.2,2616.63],[2,1.21,4981.14]],"ltp":1.19,"tv":116738.32,"id":5300737}],"tv":142437.56}]}
{"op":"mcm","clk":"4299460799","pt":1632580814466,"mc":[{"id":"1.188136695","rc":[{"trd":[[1.19,7351.08]],"batl":[[0,1.19,1524.52]],"ltp":1.19,"tv":116741.84,"id":5300737}],"tv":142441.08}]}
{"op":"mcm","clk":"4299461131","pt":1632580815565,"mc":[{"id":"1.188136695","rc":[{"trd":[[1.18,7.43],[1.19,8062.88]],"batb":[[0,1.18,19216.56],[1,1.17,3700.74]],"batl":[[0,1.19,1168.62],[2,1.21,5105.2]],"ltp":1.19,"tv":117457.64,"id":5300737}],"tv":143156.88}]}
{"op":"mcm","clk":"4299461443","pt":1632580816495,"mc":[{"id":"1.188136695","rc":[{"trd":[[1.19,9116.72]],"batb":[[0,1.18,19295.99]],"batl":[[0,1.19,641.7]],"ltp":1.19,"tv":118511.48,"id":5300737}],"tv":144210.72}]}
{"op":"mcm","clk":"4299461845","pt":1632580817686,"mc":[{"id":"1.188136695","rc":[{"trd":[[1.19,9123.99]],"batl":[[0,1.19,638.06]],"ltp":1.19,"tv":118518.75,"id":5300737}],"tv":144217.99}]}
{"op":"mcm","clk":"4299462299","pt":1632580818971,"mc":[{"id":"1.188136695","rc":[{"batb":[[0,6.2,150],[1,6,421.18],[2,5.9,225.58]],"ltp":6.0,"tv":25699.23,"id":2497008}]}]}
{"op":"mcm","clk":"4299462819","pt":1632580820600,"mc":[{"id":"1.188136695","rc":[{"trd":[[1.19,9131.5]],"batl":[[0,1.19,634.31]],"ltp":1.19,"tv":118526.26,"id":5300737}],"tv":144225.5}]}
{"op":"mcm","clk":"4299462954","pt":1632580820993,"mc":[{"id":"1.188136695","rc":[{"trd":[[1.19,9134.93]],"batl":[[0,1.19,632.59]],"ltp":1.19,"tv":118529.69,"id":5300737}],"tv":144228.93}]}
{"op":"mcm","clk":"4299463248","pt":1632580821861,"mc":[{"id":"1.188136695","rc":[{"batb":[[0,6.2,300]],"ltp":6.0,"tv":25699.23,"id":2497008}]}]}
{"op":"mcm","clk":"4299463739","pt":1632580823405,"mc":[{"id":"1.188136695","rc":[{"trd":[[1.18,12.49],[1.19,9137.03]],"batb":[[0,1.18,19293.46]],"batl":[[0,1.19,631.54]],"ltp":1.18,"tv":118536.85,"id":5300737}],"tv":144236.09}]}
{"op":"mcm","clk":"4299464154","pt":1632580824591,"mc":[{"id":"1.188136695","rc":[{"trd":[[1.19,9140.27]],"batl":[[0,1.19,629.93]],"ltp":1.19,"tv":118540.09,"id":5300737},{"trd":[[6.2,169.02]],"batb":[[0,6.2,215.49]],"ltp":6.2,"tv":25868.25,"id":2497008}],"tv":144408.35}]}
{"op":"mcm","clk":"4299464418","pt":1632580825385,"mc":[{"id":"1.188136695","rc":[{"trd":[[1.18,202.1],[1.19,9210.39]],"batb":[[0,1.18,19198.65]],"batl":[[0,1.19,600.04]],"ltp":1.18,"tv":118799.83,"id":5300737},{"trd":[[6.2,169.68]],"batb":[[0,6.2,215.16]],"ltp":6.2,"tv":25868.91,"id":2497008}],"tv":144668.75}]}
{"op":"mcm","clk":"4299464840","pt":1632580826697,"mc":[{"id":"1.188136695","rc":[{"trd":[[1.19,9408.15]],"batl":[[0,1.19,501.16]],"ltp":1.19,"tv":118997.59,"id":5300737}],"tv":144866.51}]}
{"op":"mcm","clk":"4299465404","pt":1632580828395,"mc":[{"id":"1.188136695","rc":[{"trd":[[1.19,9824.91]],"batl":[[0,1.19,292.77],[1,1.2,2611.5]],"ltp":1.19,"tv":119414.35,"id":5300737}],"tv":145283.26}]}
{"op":"mcm","clk":"4299466019","pt":1632580830368,"mc":[{"id":"1.188136695","rc":[{"trd":[[1.19,9826.09]],"batl":[[0,1.19,292.18]],"ltp":1.19,"tv":119415.53,"id":5300737}],"tv":145284.45}]}
{"op":"mcm","clk":"4299466400","pt":1632580831943,"mc":[{"id":"1.188136695","rc":[{"trd":[[6.2,170.38]],"batb":[[0,6.2,214.81]],"ltp":6.2,"tv":25869.61,"id":2497008}],"tv":145285.15}]}
{"op":"mcm","clk":"4299467533","pt":1632580834812,"mc":[{"id":"1.188136695","rc":[{"trd":[[1.19,9928.46]],"batl":[[0,1.19,241]],"ltp":1.19,"tv":119517.9,"id":5300737},{"batl":[[0,6.4,18.99]],"ltp":6.2,"tv":25869.61,"id":2497008}],"tv":145387.51}]}
{"op":"mcm","clk":"4299468149","pt":1632580836592,"mc":[{"id":"1.188136695","rc":[{"trd":[[1.18,257.58],[1.19,9963.52]],"batb":[[0,1.18,19170.92]],"batl":[[0,1.19,223.47]],"ltp":1.19,"tv":119608.43,"id":5300737}],"tv":145478.05}]}
{"op":"mcm","clk":"4299468543","pt":1632580837823,"mc":[{"id":"1.188136695","rc":[{"trd":[[1.19,9964.3]],"batl":[[0,1.19,223.08]],"ltp":1.19,"tv":119609.21,"id":5300737}],"tv":145478.83}]}
{"op":"mcm","clk":"4299468848","pt":1632580838813,"mc":[{"id":"1.188136695","rc":[{"batl":[[0,1.19,223.25]],"ltp":1.19,"tv":119609.21,"id":5300737}]}]}
{"op":"mcm","clk":"4299469135","pt":1632580839700,"mc":[{"id":"1.188136695","rc":[{"batl":[[1,1.2,2607.1]],"ltp":1.19,"tv":119609.21,"id":5300737}]}]}
{"op":"mcm","clk":"4299470362","pt":1632580843515,"mc":[{"id":"1.188136695","rc":[{"batl":[[2,1.21,4152.94]],"ltp":1.19,"tv":119609.21,"id":5300737}]}]}
{"op":"mcm","clk":"4299470823","pt":1632580845006,"mc":[{"id":"1.188136695","rc":[{"batb":[[1,1.17,16305.42]],"ltp":1.19,"tv":119609.21,"id":5300737}]}]}
{"op":"mcm","clk":"4299471844","pt":1632580848350,"mc":[{"id":"1.188136695","rc":[{"trd":[[1.19,10084.42]],"batl":[[0,1.19,163.19]],"ltp":1.19,"tv":119729.33,"id":5300737},{"trd":[[6.2,184.1]],"batb":[[0,6.2,207.95]],"ltp":6.2,"tv":25883.33,"id":2497008}],"tv":145612.67}]}
{"op":"mcm","clk":"4299472314","pt":1632580849828,"mc":[{"id":"1.188136695","rc":[{"trd":[[1.18,258.28]],"batb":[[0,1.18,19170.57]],"ltp":1.18,"tv":119730.03,"id":5300737}],"tv":145613.37}]}
{"op":"mcm","clk":"4299472720","pt":1632580851111,"mc":[{"id":"1.188136695","rc":[{"trd":[[1.18,561.64],[1.19,10085.42]],"batb":[[0,1.18,19018.88]],"batl":[[0,1.19,162.69]],"ltp":1.18,"tv":120034.4,"id":5300737}],"tv":145917.73}]}
{"op":"mcm","clk":"4299473703","pt":1632580854417,"mc":[{"id":"1.188136695","rc":[{"trd":[[1.18,578.79]],"batb":[[0,1.18,19010.31]],"ltp":1.18,"tv":120051.54,"id":5300737}],"tv":145934.87}]}
{"op":"mcm","clk":"4299473980","pt":1632580855312,"mc":[{"id":"1.188136695","rc":[{"trd":[[6.2,198.72]],"batb":[[0,6.2,200.64]],"ltp":6.2,"tv":25897.95,"id":2497008}],"tv":145949.5}]}
{"op":"mcm","clk":"4299474528","pt":1632580857101,"mc":[{"id":"1.188136695","rc":[{"batl":[[0,1.19,638.39]],"ltp":1.18,"tv":120051.54,"id":5300737}]}]}
{"op":"mcm","clk":"4299474812","pt":1632580858144,"mc":[{"id":"1.188136695","rc":[{"trd":[[1.19,10090.42]],"batl":[[0,1.19,635.89]],"ltp":1.19,"tv":120056.54,"id":5300737}],"tv":145954.5}]}
{"op":"mcm","clk":"4299475278","pt":1632580859646,"mc":[{"id":"1.188136695","rc":[{"trd":[[1.18,584.43]],"batb":[[0,1.18,19007.49]],"ltp":1.18,"tv":120062.18,"id":5300737}],"tv":145960.14}]}
{"op":"mcm","clk":"4299475553","pt":1632580860607,"mc":[{"id":"1.188136695","rc":[{"trd":[[1.19,10090.65]],"batl":[[0,1.19,635.77]],"ltp":1.19,"tv":120062.41,"id":5300737}],"tv":145960.37}]}
{"op":"mcm","clk":"4299475910","pt":1632580861636,"mc":[{"id":"1.188136695","rc":[{"trd":[[1.19,10092.65]],"batl":[[0,1.19,634.77]],"ltp":1.19,"tv":120064.41,"id":5300737}],"tv":145962.37}]}
{"op":"mcm","clk":"4299476734","pt":1632580864401,"mc":[{"id":"1.188136695","rc":[{"trd":[[1.18,593.89],[1.19,10095.19]],"batb":[[0,1.18,19002.76]],"batl":[[0,1.19,637.96]],"ltp":1.19,"tv":120076.41,"id":5300737}],"tv":145974.37}]}
{"op":"mcm","clk":"4299477501","pt":1632580866730,"mc":[{"id":"1.188136695","rc":[{"trd":[[1.19,10150.58]],"batl":[[0,1.19,610.26]],"ltp":1.19,"tv":120131.8,"id":5300737}],"tv":146029.76}]}
{"op":"mcm","clk":"4299478136","pt":1632580868825,"mc":[{"id":"1.188136695","rc":[{"batb":[[0,1.18,19079.94]],"batl":[[0,1.19,673.24]],"ltp":1.19,"tv":120131.8,"id":5300737}]}]}
{"op":"mcm","clk":"4299478390","pt":1632580869614,"mc":[{"id":"1.188136695","rc":[{"trd":[[1.18,595.8],[1.19,10279.83]],"batb":[[0,1.18,19078.98]],"batl":[[0,1.19,608.62]],"ltp":1.19,"tv":120262.97,"id":5300737}],"tv":146160.93}]}
{"op":"mcm","clk":"4299478485","pt":1632580869928,"mc":[{"id":"1.188136695","rc":[{"trd":[[6.2,238.72]],"batb":[[0,6.2,180.64]],"ltp":6.2,"tv":25937.95,"id":2497008}],"tv":146200.93}]}
{"op":"mcm","clk":"4299478846","pt":1632580871038,"mc":[{"id":"1.188136695","rc":[{"trd":[[1.19,10283.36]],"batl":[[0,1.19,606.86]],"ltp":1.19,"tv":120266.49,"id":5300737}],"tv":146204.45}]}
{"op":"mcm","clk":"4299479775","pt":1632580874014,"mc":[{"id":"1.188136695","rc":[{"trd":[[1.19,10284.03]],"batl":[[0,1.19,606.52]],"ltp":1.19,"tv":120267.17,"id":5300737}],"tv":146205.12}]}
{"op":"mcm","clk":"4299480263","pt":1632580875648,"mc":[{"id":"1.188136695","rc":[{"trd":[[1.19,10289.66]],"batl":[[0,1.19,603.7]],"ltp":1.19,"tv":120272.8,"id":5300737}],"tv":146210.76}]}
{"op":"mcm","clk":"4299480608","pt":1632580876632,"mc":[{"id":"1.188136695","rc":[{"trd":[[1.19,10327.37]],"batb":[[0,1.18,19325.34]],"batl":[[0,1.19,584.85],[2,1.21,4379.44]],"ltp":1.19,"tv":120310.51,"id":5300737},{"batl":[[1,6.6,71.31]],"ltp":6.2,"tv":25937.95,"id":2497008}],"tv":146248.47}]}
{"op":"mcm","clk":"4299480787","pt":1632580877251,"mc":[{"id":"1.188136695","rc":[{"trd":[[1.19,10329.07]],"batl":[[0,1.19,584],[2,1.21,4152.94]],"ltp":1.19,"tv":120312.2,"id":5300737}],"tv":146250.16}]}
{"op":"mcm","clk":"4299481465","pt":1632580879430,"mc":[{"id":"1.188136695","rc":[{"trd":[[1.18,617.75]],"batb":[[0,1.18,19314.37]],"batl":[[0,1.19,583.83]],"ltp":1.18,"tv":120334.15,"id":5300737}],"tv":146272.1}]}
{"op":"mcm","clk":"4299481835","pt":1632580880634,"mc":[{"id":"1.188136695","rc":[{"trd":[[1.18,641.54]],"batb":[[0,1.18,19302.48]],"ltp":1.18,"tv":120357.94,"id":5300737},{"trd":[[6.2,239.11]],"batb":[[0,6.2,180.44]],"ltp":6.2,"tv":25938.35,"id":2497008}],"tv":146296.29}]}
{"op":"mcm","clk":"4299482531","pt":1632580882738,"mc":[{"id":"1.188136695","rc":[{"trd":[[1.19,10330.47]],"batb":[[0,1.18,19223.05]],"batl":[[0,1.19,583.13]],"ltp":1.19,"tv":120359.34,"id":5300737},{"batl":[[0,6.4,7.09]],"ltp":6.2,"tv":25938.35,"id":2497008}],"tv":146297.7}]}
{"op":"mcm","clk":"4299482714","pt":1632580883443,"mc":[{"id":"1.188136695","rc":[{"trd":[[1.19,10344.49]],"batl":[[0,1.19,576.12]],"ltp":1.19,"tv":120373.37,"id":5300737}],"tv":146311.72}]}
{"op":"mcm","clk":"4299482914","pt":1632580884143,"mc":[{"id":"1.188136695","rc":[{"trd":[[1.19,10345.5]],"batl":[[0,1.19,575.61]],"ltp":1.19,"tv":120374.38,"id":5300737}],"tv":146312.73}]}
{"op":"mcm","clk":"4299483606","pt":1632580886248,"mc":[{"id":"1.188136695","rc":[{"trd":[[1.19,10386.09]],"batl":[[0,1.19,555.32]],"ltp":1.19,"tv":120414.96,"id":5300737}],"tv":146353.31}]}
{"op":"mcm","clk":"4299484058","pt":1632580887744,"mc":[{"id":"1.188136695","rc":[{"trd":[[1.19,10386.29]],"batl":[[0,1.19,555.22]],"ltp":1.19,"tv":120415.16,"id":5300737}],"tv":146353.52}]}
{"op":"mcm","clk":"4299484341","pt":1632580888639,"mc":[{"id":"1.188136695","rc":[{"batl":[[1,1.2,2917.79]],"ltp":1.19,"tv":120415.16,"id":5300737}]}]}
{"op":"mcm","clk":"4299484528","pt":1632580889249,"mc":[{"id":"1.188136695","rc":[{"trd":[[1.18,769.76]],"batb":[[0,1.18,19158.93]],"ltp":1.18,"tv":120543.39,"id":5300737}],"tv":146481.74}]}
{"op":"mcm","clk":"4299485256","pt":1632580891733,"mc":[{"id":"1.188136695","rc":[{"batb":[[0,1.18,19238.36]],"ltp":1.18,"tv":120543.39,"id":5300737},{"trd":[[6.2,239.3]],"batb":[[0,6.2,180.35]],"batl":[[0,6.4,17.55]],"ltp":6.2,"tv":25938.53,"id":2497008}],"tv":146481.92}]}
{"op":"mcm","clk":"4299485397","pt":1632580892264,"mc":[{"id":"1.188136695","rc":[{"batl":[[0,1.19,1232.31]],"ltp":1.18,"tv":120543.39,"id":5300737}]}]}
{"op":"mcm","clk":"4299485737","pt":1632580893342,"mc":[{"id":"1.188136695","rc":[{"trd":[[1.19,10415.54]],"batl":[[0,1.19,1217.68]],"ltp":1.19,"tv":120572.64,"id":5300737}],"tv":146511.18}]}
{"op":"mcm","clk":"4299486477","pt":1632580895773,"mc":[{"id":"1.188136695","rc":[{"batb":[[1,1.17,3700.74]],"ltp":1.19,"tv":120572.64,"id":5300737}]}]}
{"op":"mcm","clk":"4299487100","pt":1632580897677,"mc":[{"id":"1.188136695","rc":[{"batb":[[0,1.18,16274.93]],"batl":[[1,1.2,1556.28],[2,1.21,2010.38]],"ltp":1.19,"tv":120572.64,"id":5300737},{"batb":[[1,6,297.07],[2,5.8,18.75]],"batl":[[0,6.6,71.31],[1,6.8,58.86],[2,7,13.45]],"ltp":6.2,"tv":25938.53,"id":2497008}]}]}
{"op":"mcm","clk":"4299487429","pt":1632580898756,"mc":[{"id":"1.188136695","rc":[{"trd":[[1.19,10429.56]],"batb":[[0,1.18,14927.59],[1,1.17,3482.46]],"batl":[[0,1.19,1210.67],[1,1.2,1227.28],[2,1.21,222.5]],"ltp":1.19,"tv":120586.66,"id":5300737},{"batb":[[2,5.7,3.22]],"batl":[[2,7,4.27]],"ltp":6.2,"tv":25938.53,"id":2497008}],"tv":146525.2}]}
{"op":"mcm","clk":"4299487551","pt":1632580899162,"mc":[{"id":"1.188136695","rc":[{"batb":[[0,1.18,3023.17]],"ltp":1.19,"tv":120586.66,"id":5300737}]}]}
{"op":"mcm","clk":"4299487886","pt":1632580900250,"mc":[{"id":"1.188136695","rc":[{"batb":[[1,5.7,3.22],[2,5.5,131.98]],"ltp":6.2,"tv":25938.53,"id":2497008}]}]}
{"op":"mcm","clk":"4299488343","pt":1632580901686,"mc":[{"id":"1.188136695","rc":[{"batb":[[0,1.18,2323.17],[1,1.17,4673.18]],"ltp":1.19,"tv":120586.66,"id":5300737}]}]}
{"op":"mcm","clk":"4299488588","pt":1632580902826,"mc":[{"id":"1.188136695","rc":[{"trd":[[1.19,10437.45]],"batl":[[0,1.19,1143.75]],"ltp":1.19,"tv":120594.55,"id":5300737}],"tv":146533.08}]}
{"op":"mcm","clk":"4299488802","pt":1632580903260,"mc":[{"id":"1.188136695","rc":[{"trd":[[1.18,773.34]],"batb":[[0,1.18,2321.38],[1,1.17,2434.27]],"ltp":1.18,"tv":120598.13,"id":5300737}],"tv":146536.66}]}
{"op":"mcm","clk":"4299489286","pt":1632580904801,"mc":[{"id":"1.188136695","rc":[{"batb":[[0,1.18,1755.79]],"ltp":1.18,"tv":120598.13,"id":5300737},{"batl":[[1,6.8,467.85]],"ltp":6.2,"tv":25938.53,"id":2497008}]}]}
{"op":"mcm","clk":"4299489582","pt":1632580905709,"mc":[{"id":"1.188136695","rc":[{"trd":[[1.19,10438.43]],"batl":[[0,1.19,1143.26]],"ltp":1.19,"tv":120599.11,"id":5300737},{"batb":[[0,5.7,3.22],[1,5.5,131.98],[2,5.3,74.29]],"batl":[[1,6.8,58.86]],"ltp":6.2,"tv":25938.53,"id":2497008}],"tv":146537.64}]}
{"op":"mcm","clk":"4299489944","pt":1632580906765,"mc":[{"id":"1.188136695","rc":[{"trd":[[1.19,10534.73]],"batl":[[0,1.19,1090.65]],"ltp":1.19,"tv":120695.41,"id":5300737},{"batl":[[0,6.4,12.7],[1,6.6,71.31],[2,6.8,58.86]],"ltp":6.2,"tv":25938.53,"id":2497008}],"tv":146633.95}]}
{"op":"mcm","clk":"4299490223","pt":1632580907671,"mc":[{"id":"1.188136695","rc":[{"trd":[[1.19,12457.33]],"batb":[[0,1.18,2664.19]],"batl":[[0,1.19,129.35],[2,1.21,1671.41]],"ltp":1.19,"tv":122618.01,"id":5300737}],"tv":148556.55}]}
{"op":"mcm","clk":"4299490567","pt":1632580908806,"mc":[{"id":"1.188136695","rc":[{"batb":[[0,1.18,1347.57]],"batl":[[2,1.21,222.5]],"ltp":1.19,"tv":122618.01,"id":5300737},{"batl":[[0,6.6,71.31],[1,6.8,58.86],[2,7,4.27]],"ltp":6.2,"tv":25938.53,"id":2497008}]}]}
{"op":"mcm","clk":"4299490740","pt":1632580909390,"mc":[{"id":"1.188136695","rc":[{"trd":[[1.18,780.66]],"batb":[[0,1.18,1343.91]],"ltp":1.18,"tv":122625.33,"id":5300737},{"batb":[[0,6.2,79.05],[1,5.7,3.22],[2,5.5,131.98]],"ltp":6.2,"tv":25938.53,"id":2497008}],"tv":148563.86}]}
{"op":"mcm","clk":"4299491152","pt":1632580910693,"mc":[{"id":"1.188136695","rc":[{"trd":[[1.19,12471.35]],"batl":[[0,1.19,122.34]],"ltp":1.19,"tv":122639.35,"id":5300737},{"batb":[[0,5.7,3.22],[1,5.5,131.98],[2,5.3,74.29]],"ltp":6.2,"tv":25938.53,"id":2497008}],"tv":148577.88}]}
{"op":"mcm","clk":"4299491446","pt":1632580911603,"mc":[{"id":"1.188136695","rc":[{"trd":[[1.19,12471.55]],"batl":[[0,1.19,122.24]],"ltp":1.19,"tv":122639.55,"id":5300737}],"tv":148578.09}]}
{"op":"mcm","clk":"4299491745","pt":1632580912611,"mc":[{"id":"1.188136695","rc":[{"trd":[[1.19,12475.98]],"batl":[[0,1.19,119.78],[1,1.2,312.4]],"ltp":1.19,"tv":122643.98,"id":5300737},{"trd":[[6.2,239.39]],"ltp":6.2,"tv":25938.63,"id":2497008}],"tv":148582.61}]}
{"op":"mcm","clk":"4299492096","pt":1632580913793,"mc":[{"id":"1.188136695","rc":[{"batb":[[1,1.17,4672.99]],"ltp":1.19,"tv":122643.98,"id":5300737},{"batb":[[0,6,81.68],[1,5.7,3.22],[2,5.5,131.98]],"ltp":6.2,"tv":25938.63,"id":2497008}]}]}
{"op":"mcm","clk":"4299492292","pt":1632580914420,"mc":[{"id":"1.188136695","rc":[{"trd":[[1.19,12715.55]],"batb":[[0,1.19,13.07],[1,1.18,1343.91],[2,1.17,4672.99]],"batl":[[0,1.2,312.4],[1,1.21,222.5],[2,1.22,1718.59]],"ltp":1.19,"tv":122883.54,"id":5300737},{"batb":[[0,5.7,3.22],[1,5.5,131.98],[2,5.3,74.29]],"ltp":6.2,"tv":25938.63,"id":2497008}],"tv":148822.17}]}
{"op":"mcm","clk":"4299492651","pt":1632580915627,"mc":[{"id":"1.188136695","rc":[{"batb":[[1,1.18,1092.74],[2,1.17,2009.82]],"batl":[[1,1.22,1718.59],[2,1.23,1495.29]],"ltp":1.19,"tv":122883.54,"id":5300737},{"batl":[[0,6.6,3.26],[1,6.8,1]],"ltp":6.2,"tv":25938.63,"id":2497008}]}]}
{"op":"mcm","clk":"4299492803","pt":1632580916140,"mc":[{"id":"1.188136695","rc":[{"batb":[[0,1.19,17.85]],"ltp":1.19,"tv":122883.54,"id":5300737}]}]}
{"op":"mcm","clk":"4299493259","pt":1632580917716,"mc":[{"id":"1.188136695","rc":[{"batb":[[0,1.19,18.27]],"ltp":1.19,"tv":122883.54,"id":5300737}]}]}
{"op":"mcm","clk":"4299493594","pt":1632580918741,"mc":[{"id":"1.188136695","rc":[{"trd":[[1.2,454.1]],"batb":[[0,1.19,3298.43],[1,1.18,4641.16],[2,1.17,2338.08]],"batl":[[0,1.2,273.2],[1,1.21,405.03],[2,1.22,1718.59]],"ltp":1.2,"tv":122922.74,"id":5300737},{"trd":[[6,40.35]],"batl":[[0,6.4,10.24],[1,6.6,3.26],[2,6.8,3]],"ltp":6.0,"tv":25946.47,"id":2497008}],"tv":148869.21}]}
{"op":"mcm","clk":"4299493933","pt":1632580919816,"mc":[{"id":"1.188136695","rc":[{"batb":[[0,1.19,5734.47],[1,1.18,6435.32],[2,1.17,641.23]],"ltp":1.2,"tv":122922.74,"id":5300737},{"batb":[[1,5.5,274.03],[2,5.4,91.47]],"batl":[[0,6.4,19.92]],"ltp":6.0,"tv":25946.47,"id":2497008}]}]}
{"op":"mcm","clk":"4299494231","pt":1632580920716,"mc":[{"id":"1.188136695","rc":[{"trd":[[1.2,757.81]],"batb":[[0,1.19,5747.47]],"batl":[[0,1.2,116.35]],"ltp":1.2,"tv":123226.45,"id":5300737},{"trd":[[6,42.35]],"batl":[[0,6.4,29.75]],"ltp":6.0,"tv":25948.47,"id":2497008}],"tv":149174.92}]}
{"op":"mcm","clk":"4299494557","pt":1632580921730,"mc":[{"id":"1.188136695","rc":[{"trd":[[1.19,12845.55]],"batb":[[0,1.19,5682.63]],"ltp":1.19,"tv":123356.45,"id":5300737}],"tv":149304.93}]}
{"op":"mcm","clk":"4299494870","pt":1632580922699,"mc":[{"id":"1.188136695","rc":[{"batb":[[0,1.19,5843.58]],"batl":[[0,1.2,194.66],[1,1.21,1518.26]],"ltp":1.19,"tv":123356.45,"id":5300737}]}]}
{"op":"mcm","clk":"4299495273","pt":1632580923822,"mc":[{"id":"1.188136695","rc":[{"trd":[[1.2,789.56]],"batb":[[1,1.18,6508.68]],"batl":[[0,1.2,162.91],[1,1.21,2089.96],[2,1.22,2486.57]],"ltp":1.2,"tv":123388.2,"id":5300737},{"trd":[[6,48.7]],"batb":[[0,5.7,124.58],[1,5.5,444.38]],"batl":[[0,6.2,16.3],[1,6.4,29.75],[2,6.6,3.26]],"ltp":6.0,"tv":25954.82,"id":2497008}],"tv":149343.03}]}
{"op":"mcm","clk":"4299495523","pt":1632580924616,"mc":[{"id":"1.188136695","rc":[{"batb":[[0,1.19,6519.84],[1,1.18,7383.8]],"ltp":1.2,"tv":123388.2,"id":5300737},{"batl":[[0,6.2,28],[1,6.4,155.49],[2,6.6,159.72]],"ltp":6.0,"tv":25954.82,"id":2497008}]}]}
{"op":"mcm","clk":"4299495895","pt":1632580925826,"mc":[{"id":"1.188136695","rc":[{"trd":[[1.2,790.36]],"batb":[[0,1.19,6863.5],[1,1.18,7783.41],[2,1.17,1132.47]],"batl":[[0,1.2,417.99],[1,1.21,2938.87],[2,1.22,3140.55]],"ltp":1.2,"tv":123389.01,"id":5300737},{"batb":[[0,6,3.74],[1,5.7,250.12],[2,5.5,589.44]],"batl":[[1,6.4,347.55],[2,6.6,219.37]],"ltp":6.0,"tv":25954.82,"id":2497008}],"tv":149343.83}]}
{"op":"mcm","clk":"4299496098","pt":1632580926417,"mc":[{"id":"1.188136695","rc":[{"trd":[[1.19,12846.95]],"batb":[[0,1.19,21829.34]],"ltp":1.19,"tv":123390.41,"id":5300737},{"batl":[[1,6.4,647.55]],"ltp":6.0,"tv":25954.82,"id":2497008}],"tv":149345.23}]}
{"op":"mcm","clk":"4299496408","pt":1632580927414,"mc":[{"id":"1.188136695","rc":[{"trd":[[1.2,792.12]],"batl":[[0,1.2,417.11]],"ltp":1.2,"tv":123392.17,"id":5300737}],"tv":149346.99}]}
{"op":"mcm","clk":"4299496835","pt":1632580928756,"mc":[{"id":"1.188136695","rc":[{"trd":[[1.2,1561.12]],"batb":[[1,1.18,7710.04]],"batl":[[0,1.2,127.75]],"ltp":1.2,"tv":124161.17,"id":5300737}],"tv":150115.99}]}
{"op":"mcm","clk":"4299497123","pt":1632580929630,"mc":[{"id":"1.188136695","rc":[{"batl":[[0,1.2,184.53],[1,1.21,2858.7]],"ltp":1.2,"tv":124161.17,"id":5300737}]}]}
{"op":"mcm","clk":"4299497877","pt":1632580931831,"mc":[{"id":"1.188136695","rc":[{"trd":[[1.2,1948.89]],"batb":[[0,1.2,321.75],[1,1.19,21829.34],[2,1.18,7710.04]],"batl":[[0,1.21,2858.7],[1,1.22,3140.55],[2,1.23,1585.29]],"ltp":1.2,"tv":124548.93,"id":5300737},{"trd":[[6,52.44]],"batb":[[0,5.7,250.12],[1,5.5,589.44],[2,5.4,91.47]],"batl":[[0,6.2,16.3],[1,6.4,197.55]],"ltp":6.0,"tv":25958.56,"id":2497008}],"tv":150507.49}]}
{"op":"mcm","clk":"4299498189","pt":1632580932717,"mc":[{"id":"1.188136695","rc":[{"batb":[[0,1.2,10],[1,1.19,16321.68],[2,1.18,3526.54]],"batl":[[0,1.21,662.53],[1,1.23,1090.54],[2,1.24,210.89]],"ltp":1.2,"tv":124548.93,"id":5300737},{"batb":[[0,5.7,3.22],[1,5.4,20.45],[2,5.2,53.54]],"batl":[[0,6.4,61.57],[1,6.6,62.91],[2,6.8,86.69]],"ltp":6.0,"tv":25958.56,"id":2497008}]}]}
{"op":"mcm","clk":"4299498529","pt":1632580933655,"mc":[{"id":"1.188136695","rc":[{"batb":[[0,1.2,10.28],[1,1.19,1421.88],[2,1.18,3314.41]],"batl":[[1,1.23,1000.54]],"ltp":1.2,"tv":124548.93,"id":5300737},{"batb":[[1,5.2,53.54],[2,5.1,220.48]],"batl":[[0,6.4,51.89],[2,6.8,84.69]],"ltp":6.0,"tv":25958.56,"id":2497008}]}]}
{"op":"mcm","clk":"4299498876","pt":1632580934716,"mc":[{"id":"1.188136695","rc":[{"batl":[[0,6,3],[1,6.4,51.89],[2,6.6,62.91]],"ltp":6.0,"tv":25958.56,"id":2497008}]}]}
{"op":"mcm","clk":"4299499202","pt":1632580935570,"mc":[{"id":"1.188136695","rc":[{"trd":[[1.2,2006.01]],"batb":[[0,1.19,1421.88],[1,1.18,4331.13],[2,1.17,804.21]],"batl":[[2,1.24,1650.75]],"ltp":1.2,"tv":124606.06,"id":5300737},{"trd":[[5.8,11.7]],"batl":[[0,6.4,51.89],[1,6.6,62.91],[2,6.8,84.69]],"ltp":5.8,"tv":25970.26,"id":2497008}],"tv":150576.32}]}
{"op":"mcm","clk":"4299499576","pt":1632580936630,"mc":[{"id":"1.188136695","rc":[{"batb":[[1,1.18,4333.01]],"batl":[[0,1.21,671.53],[1,1.22,204.25],[2,1.23,1000.54]],"ltp":1.2,"tv":124606.06,"id":5300737},{"batb":[[0,5.7,5.22],[1,5.6,2],[2,5.5,3.7]],"batl":[[0,6,2.35],[1,6.4,51.89],[2,6.6,62.91]],"ltp":5.8,"tv":25970.26,"id":2497008}]}]}
{"op":"mcm","clk":"4299499952","pt":1632580937658,"mc":[{"id":"1.188136695","rc":[{"batb":[[0,1.19,1429.88]],"ltp":1.2,"tv":124606.06,"id":5300737}]}]}
{"op":"mcm","clk":"4299500306","pt":1632580938722,"mc":[{"id":"1.188136695","rc":[{"trd":[[1.19,12858.53],[1.2,2017.75]],"batb":[[0,1.19,1361.31],[1,1.18,16237.44]],"batl":[[1,1.25,952.26],[2,1.27,12.81]],"ltp":1.19,"tv":124629.38,"id":5300737},{"trd":[[6,54.79]],"batl":[[0,6.4,51.89],[1,6.6,62.91],[2,6.8,84.69]],"ltp":6.0,"tv":25972.61,"id":2497008}],"tv":150601.99}]}
{"op":"mcm","clk":"4299500565","pt":1632580939538,"mc":[{"id":"1.188136695","rc":[{"batl":[[2,1.26,952.26]],"ltp":1.19,"tv":124629.38,"id":5300737}]}]}
{"op":"mcm","clk":"4299500729","pt":1632580940060,"mc":[{"id":"1.188136695","rc":[{"trd":[[1.19,15429.89]],"batb":[[0,1.19,75.63]],"batl":[[0,1.21,257.5]],"ltp":1.19,"tv":127200.73,"id":5300737},{"batb":[[0,5.7,3.22],[1,5.5,3.7],[2,5.1,158.03]],"ltp":6.0,"tv":25972.61,"id":2497008}],"tv":153173.34}]}
{"op":"mcm","clk":"4299501488","pt":1632580942794,"mc":[{"id":"1.188136695","rc":[{"trd":[[1.21,1634.14]],"batb":[[0,1.2,7.2],[2,1.17,2496.58]],"batl":[[0,1.21,1681.52],[1,1.22,1584.21],[2,1.25,952.26]],"ltp":1.21,"tv":127201.07,"id":5300737},{"trd":[[5.8,27.08]],"batb":[[0,5.8,127.01],[1,5.7,192.49],[2,5.6,67.35]],"batl":[[2,6.8,636.16]],"ltp":5.8,"tv":25987.99,"id":2497008}],"tv":153189.06}]}
{"op":"mcm","clk":"4299501937","pt":1632580943715,"mc":[{"id":"1.188136695","rc":[{"batb":[[0,1.2,7.1],[1,1.19,636.19],[2,1.18,16237.44]],"batl":[[0,1.21,2191.36]],"ltp":1.21,"tv":127201.07,"id":5300737},{"batb":[[0,5.8,145.76],[1,5.7,202.08]],"batl":[[0,6.2,2],[1,6.4,64.67],[2,6.6,62.91]],"ltp":5.8,"tv":25987.99,"id":2497008}]}]}
{"op":"mcm","clk":"4299502203","pt":1632580944531,"mc":[{"id":"1.188136695","rc":[{"batl":[[0,1.21,2711.63],[1,1.22,2382.19],[2,1.23,398.45]],"ltp":1.21,"tv":127201.07,"id":5300737},{"batb":[[0,5.8,127.01],[1,5.7,331.63]],"ltp":5.8,"tv":25987.99,"id":2497008}]}]}
{"op":"mcm","clk":"4299502604","pt":1632580945764,"mc":[{"id":"1.188136695","rc":[{"batb":[[0,1.2,142.2],[1,1.19,717.01]],"batl":[[0,1.21,2778.81]],"ltp":1.21,"tv":127201.07,"id":5300737}]}]}
{"op":"mcm","clk":"4299502922","pt":1632580946648,"mc":[{"id":"1.188136695","rc":[{"batb":[[0,1.2,142.55],[1,1.19,1585.52],[2,1.18,16295.58]],"batl":[[0,1.21,3811.87],[1,1.22,2783.9]],"ltp":1.21,"tv":127201.07,"id":5300737},{"batl":[[0,6.2,2.16]],"ltp":5.8,"tv":25987.99,"id":2497008}]}]}
{"op":"mcm","clk":"4299503266","pt":1632580947724,"mc":[{"id":"1.188136695","rc":[{"trd":[[1.2,2303.63]],"batb":[[0,1.19,1585.52],[1,1.18,16295.58],[2,1.17,2496.58]],"batl":[[0,1.2,882.21],[1,1.21,4632.99],[2,1.22,2783.9]],"ltp":1.2,"tv":127486.95,"id":5300737},{"trd":[[6,54.94]],"batb":[[0,6,123.43],[1,5.8,145.76],[2,5.7,486.83]],"batl":[[0,6.2,2]],"ltp":6.0,"tv":25988.14,"id":2497008}],"tv":153475.1}]}
{"op":"mcm","clk":"4299503629","pt":1632580948830,"mc":[{"id":"1.188136695","rc":[{"batb":[[0,1.19,1908.45],[1,1.18,4791.27],[2,1.17,2941.22]],"batl":[[1,1.21,5132.99],[2,1.22,2975.15]],"ltp":1.2,"tv":127486.95,"id":5300737},{"batl":[[1,6.4,119.82],[2,6.6,119.9]],"ltp":6.0,"tv":25988.14,"id":2497008}]}]}
{"op":"mcm","clk":"4299504209","pt":1632580950752,"mc":[{"id":"1.188136695","rc":[{"batb":[[1,1.18,5117.62]],"batl":[[0,1.2,1923.88],[1,1.21,5065.81]],"ltp":1.2,"tv":127486.95,"id":5300737}]}]}
{"op":"mcm","clk":"4299504491","pt":1632580951535,"mc":[{"id":"1.188136695","rc":[{"batb":[[1,1.18,5798.18],[2,1.17,3891.76]],"batl":[[0,1.2,1962.57]],"ltp":1.2,"tv":127486.95,"id":5300737},{"batl":[[2,6.6,241.56]],"ltp":6.0,"tv":25988.14,"id":2497008}]}]}
{"op":"mcm","clk":"4299504866","pt":1632580952748,"mc":[{"id":"1.188136695","rc":[{"batb":[[1,1.18,5413.68]],"batl":[[0,1.2,1419.48]],"ltp":1.2,"tv":127486.95,"id":5300737}]}]}
{"op":"mcm","clk":"4299504959","pt":1632580953063,"mc":[{"id":"1.188136695","rc":[{"batb":[[0,1.19,2472.44],[1,1.18,6076.23]],"batl":[[0,1.2,1429.99]],"ltp":1.2,"tv":127486.95,"id":5300737},{"batl":[[1,6.4,224.68],[2,6.6,360.02]],"ltp":6.0,"tv":25988.14,"id":2497008}]}]}
{"op":"mcm","clk":"4299505462","pt":1632580954636,"mc":[{"id":"1.188136695","rc":[{"trd":[[1.2,2637.37]],"batl":[[0,1.2,1263.12]],"ltp":1.2,"tv":127820.69,"id":5300737},{"batb":[[0,5.8,145.76],[1,5.7,486.83],[2,5.6,67.35]],"ltp":6.0,"tv":25988.14,"id":2497008}],"tv":153808.84}]}
{"op":"mcm","clk":"4299505516","pt":1632580954844,"mc":[{"id":"1.188136695","rc":[{"batb":[[0,6,150],[1,5.8,145.76],[2,5.7,486.83]],"ltp":6.0,"tv":25988.14,"id":2497008}]}]}
{"op":"mcm","clk":"4299506358","pt":1632580957704,"mc":[{"id":"1.188136695","rc":[{"trd":[[1.2,2662.61]],"batb":[[0,1.19,422.6],[1,1.18,1589.71],[2,1.17,2449.98]],"batl":[[0,1.2,214.99],[1,1.21,847.33],[2,1.22,1776.47]],"ltp":1.2,"tv":127845.94,"id":5300737},{"batb":[[0,5.8,18.75],[1,5.7,3.22],[2,5.5,3.7]],"batl":[[0,6.4,55.15],[1,6.6,56.99],[2,6.8,57.56]],"ltp":6.0,"tv":25988.14,"id":2497008}],"tv":153834.08}]}
{"op":"mcm","clk":"4299506652","pt":1632580958662,"mc":[{"id":"1.188136695","rc":[{"trd":[[1.2,2670.3]],"batl":[[0,1.2,211.15],[1,1.21,257.33]],"ltp":1.2,"tv":127853.62,"id":5300737},{"batb":[[0,5.7,3.22],[1,5.5,3.7],[2,5.3,144.41]],"ltp":6.0,"tv":25988.14,"id":2497008}],"tv":153841.77}]}
{"op":"mcm","clk":"4299507212","pt":1632580960576,"mc":[{"id":"1.188136695","rc":[{"batb":[[2,1.17,4721.6]],"ltp":1.2,"tv":127853.62,"id":5300737},{"batb":[[0,5.8,2],[1,5.7,5.22],[2,5.5,3.7]],"ltp":6.0,"tv":25988.14,"id":2497008}]}]}
{"op":"mcm","clk":"4299507718","pt":1632580962175,"mc":[{"id":"1.188136695","rc":[{"batb":[[1,1.18,1608.56]],"ltp":1.2,"tv":127853.62,"id":5300737}]}]}
{"op":"mcm","clk":"4299508250","pt":1632580963767,"mc":[{"id":"1.188136695","rc":[{"batl":[[0,1.2,215.56]],"ltp":1.2,"tv":127853.62,"id":5300737}]}]}
{"op":"mcm","clk":"4299508377","pt":1632580964163,"mc":[{"id":"1.188136695","rc":[{"trd":[[1.2,2740.82]],"batl":[[0,1.2,180.3]],"ltp":1.2,"tv":127924.14,"id":5300737}],"tv":153912.29}]}
{"op":"mcm","clk":"4299508863","pt":1632580965759,"mc":[{"id":"1.188136695","rc":[{"batb":[[0,1.19,341.78]],"batl":[[2,1.22,592.96]],"ltp":1.2,"tv":127924.14,"id":5300737}]}]}
{"op":"mcm","clk":"4299509195","pt":1632580966791,"mc":[{"id":"1.188136695","rc":[{"trd":[[1.2,2810.94]],"batb":[[2,1.17,4723.95]],"batl":[[0,1.2,153.13],[1,1.22,401.71],[2,1.23,398.45]],"ltp":1.2,"tv":127994.26,"id":5300737},{"batb":[[2,5.3,144.41]],"ltp":6.0,"tv":25988.14,"id":2497008}],"tv":153982.41}]}
{"op":"mcm","clk":"4299509407","pt":1632580967460,"mc":[{"id":"1.188136695","rc":[{"trd":[[1.19,15452.43]],"batb":[[0,1.19,7.59]],"ltp":1.19,"tv":128016.8,"id":5300737},{"batb":[[0,6,26.04],[1,5.9,13.02],[2,5.8,498.05]],"batl":[[0,6.6,56.99],[1,6.8,57.56],[2,7.4,5.54]],"ltp":6.0,"tv":25988.14,"id":2497008}],"tv":154004.95}]}
{"op":"mcm","clk":"4299509771","pt":1632580968571,"mc":[{"id":"1.188136695","rc":[{"batl":[[0,1.2,1654.15],[1,1.21,1684.6],[2,1.22,401.71]],"ltp":1.19,"tv":128016.8,"id":5300737},{"batb":[[0,6,130.21],[1,5.9,65.1],[2,5.8,654.57]],"ltp":6.0,"tv":25988.14,"id":2497008}]}]}
{"op":"mcm","clk":"4299510137","pt":1632580969764,"mc":[{"id":"1.188136695","rc":[{"trd":[[1.2,3240.15]],"batl":[[0,1.2,1529.55]],"ltp":1.2,"tv":128446.01,"id":5300737},{"trd":[[6,70.82]],"batb":[[0,6,359.51]],"batl":[[2,7,111.61]],"ltp":6.0,"tv":26004.02,"id":2497008}],"tv":154450.04}]}
{"op":"mcm","clk":"4299510341","pt":1632580970485,"mc":[{"id":"1.188136695","rc":[{"trd":[[1.2,3241.84]],"batl":[[0,1.2,1528.7]],"ltp":1.2,"tv":128447.71,"id":5300737},{"batb":[[2,5.8,892.11]],"ltp":6.0,"tv":26004.02,"id":2497008}],"tv":154451.73}]}
{"op":"mcm","clk":"4299510777","pt":1632580971743,"mc":[{"id":"1.188136695","rc":[{"batl":[[0,1.2,2480.96]],"ltp":1.2,"tv":128447.71,"id":5300737},{"batl":[[0,6.6,68.97]],"ltp":6.0,"tv":26004.02,"id":2497008}]}]}
{"op":"mcm","clk":"4299511039","pt":1632580972685,"mc":[{"id":"1.188136695","rc":[{"batb":[[0,1.19,82.23],[1,1.18,1687.04]],"batl":[[0,1.2,2566.43]],"ltp":1.2,"tv":128447.71,"id":5300737},{"batb":[[0,6,511.51],[1,5.9,67.1],[2,5.8,652.57]],"batl":[[0,6.6,71.97]],"ltp":6.0,"tv":26004.02,"id":2497008}]}]}
{"op":"mcm","clk":"4299511332","pt":1632580973580,"mc":[{"id":"1.188136695","rc":[{"trd":[[1.2,3247.54]],"batb":[[1,1.18,2562.76],[2,1.17,17328.63]],"batl":[[0,1.2,3312.83],[1,1.21,2433.72]],"ltp":1.2,"tv":128453.41,"id":5300737},{"trd":[[6,71.52]],"batb":[[0,6,642.53],[1,5.9,65.1]],"ltp":6.0,"tv":26004.72,"id":2497008}],"tv":154458.13}]}
{"op":"mcm","clk":"4299511690","pt":1632580974740,"mc":[{"id":"1.188136695","rc":[{"trd":[[1.19,15616.9]],"batb":[[0,1.18,2562.76],[1,1.17,17328.63],[2,1.16,3173.68]],"batl":[[0,1.19,550.2],[1,1.2,3706.83],[2,1.21,2433.72]],"ltp":1.19,"tv":128617.87,"id":5300737}],"tv":154622.6}]}
{"op":"mcm","clk":"4299511998","pt":1632580975761,"mc":[{"id":"1.188136695","rc":[{"batb":[[0,1.18,3484.06],[1,1.17,18346.58],[2,1.16,3615.51]],"ltp":1.19,"tv":128617.87,"id":5300737},{"batl":[[0,6.4,2],[1,6.6,227.31],[2,6.8,115.94]],"ltp":6.0,"tv":26004.72,"id":2497008}]}]}
{"op":"mcm","clk":"4299512305","pt":1632580976721,"mc":[{"id":"1.188136695","rc":[{"batb":[[2,1.16,3617.86]],"batl":[[0,1.2,3969.96],[1,1.21,2666.22],[2,1.22,401.71]],"ltp":1.19,"tv":128617.87,"id":5300737},{"batb":[[0,6,645.86]],"ltp":6.0,"tv":26004.72,"id":2497008}]}]}
{"op":"mcm","clk":"4299512586","pt":1632580977586,"mc":[{"id":"1.188136695","rc":[{"trd":[[1.19,15648.46]],"batb":[[0,1.18,3544.74]],"batl":[[0,1.19,1034.64],[1,1.2,3969.96],[2,1.21,2666.22]],"ltp":1.19,"tv":128649.43,"id":5300737}],"tv":154654.16}]}
{"op":"mcm","clk":"4299512976","pt":1632580978749,"mc":[{"id":"1.188136695","rc":[{"batl":[[1,1.2,3891.49]],"ltp":1.19,"tv":128649.43,"id":5300737}]}]}
{"op":"mcm","clk":"4299513272","pt":1632580979773,"mc":[{"id":"1.188136695","rc":[{"trd":[[1.19,15718.58]],"batl":[[0,1.19,1060.63]],"ltp":1.19,"tv":128719.55,"id":5300737}],"tv":154724.28}]}
{"op":"mcm","clk":"4299513572","pt":1632580980737,"mc":[{"id":"1.188136695","rc":[{"trd":[[1.19,15845.86]],"batl":[[0,1.19,996.99]],"ltp":1.19,"tv":128846.83,"id":5300737}],"tv":154851.56}]}
{"op":"mcm","clk":"4299514247","pt":1632580982757,"mc":[{"id":"1.188136695","rc":[{"batb":[[0,1.18,2494.25],[1,1.17,17222.24]],"batl":[[1,1.2,3224.65],[2,1.21,1917.1]],"ltp":1.19,"tv":128846.83,"id":5300737},{"batb":[[0,6,390.57],[1,5.7,3.22],[2,5.6,127.93]],"batl":[[1,6.6,52.92],[2,6.8,59.38]],"ltp":6.0,"tv":26004.72,"id":2497008}]}]}
{"op":"mcm","clk":"4299514405","pt":1632580983291,"mc":[{"id":"1.188136695","rc":[{"batb":[[0,1.18,449.68],[1,1.17,14907.08]],"batl":[[0,1.19,61.05],[1,1.2,747.13],[2,1.21,1210.85]],"ltp":1.19,"tv":128846.83,"id":5300737},{"batb":[[0,6,171.33]],"batl":[[0,6.6,49.92],[1,6.8,59.38],[2,7,62.51]],"ltp":6.0,"tv":26004.72,"id":2497008}]}]}
{"op":"mcm","clk":"4299514840","pt":1632580984688,"mc":[{"id":"1.188136695","rc":[{"batl":[[1,1.21,1210.85],[2,1.22,412.23]],"ltp":1.19,"tv":128846.83,"id":5300737},{"batb":[[0,6,150]],"ltp":6.0,"tv":26004.72,"id":2497008}]}]}
{"op":"mcm","clk":"4299515490","pt":1632580986786,"mc":[{"id":"1.188136695","rc":[{"batb":[[2,1.16,3450.41]],"batl":[[0,1.21,1210.85],[1,1.22,2012.92],[2,1.23,666.96]],"ltp":1.19,"tv":128846.83,"id":5300737},{"batb":[[2,5.5,133.59]],"ltp":6.0,"tv":26004.72,"id":2497008}]}]}
{"op":"mcm","clk":"4299515776","pt":1632580987816,"mc":[{"id":"1.188136695","rc":[{"batb":[[2,1.16,1802.46]],"batl":[[1,1.22,401.71]],"ltp":1.19,"tv":128846.83,"id":5300737},{"batb":[[0,5.7,3.22],[1,5.5,133.59],[2,5.3,56.08]],"ltp":6.0,"tv":26004.72,"id":2497008}]}]}
{"op":"mcm","clk":"4299516009","pt":1632580988581,"mc":[{"id":"1.188136695","rc":[{"batl":[[0,1.2,243.38],[1,1.21,1210.85],[2,1.22,401.71]],"ltp":1.19,"tv":128846.83,"id":5300737},{"batb":[[0,6,3.33],[1,5.7,3.22],[2,5.5,133.59]],"ltp":6.0,"tv":26004.72,"id":2497008}]}]}
{"op":"mcm","clk":"4299516324","pt":1632580989677,"mc":[{"id":"1.188136695","rc":[{"batb":[[0,1.19,18.9],[1,1.18,449.68],[2,1.17,14907.08]],"batl":[[0,1.21,1210.85],[1,1.22,401.71],[2,1.23,666.96]],"ltp":1.19,"tv":128846.83,"id":5300737},{"batb":[[0,5.7,3.22],[1,5.5,133.59],[2,5.3,56.08]],"ltp":6.0,"tv":26004.72,"id":2497008}]}]}
{"op":"mcm","clk":"4299517010","pt":1632580991782,"mc":[{"id":"1.188136695","rc":[{"batb":[[0,1.19,19.48],[1,1.18,519.66]],"batl":[[0,1.21,1282.37]],"ltp":1.19,"tv":128846.83,"id":5300737},{"batb":[[0,5.8,10.58],[1,5.7,5.22],[2,5.6,3]],"batl":[[0,6.4,8.7],[1,6.6,49.92],[2,6.8,59.38]],"ltp":6.0,"tv":26004.72,"id":2497008}]}]}
{"op":"mcm","clk":"4299517317","pt":1632580992768,"mc":[{"id":"1.188136695","rc":[{"trd":[[1.19,15852.88],[1.2,3248.7]],"batb":[[0,1.19,15.39],[1,1.18,2102.82]],"batl":[[0,1.2,1301.1],[1,1.21,1945.54],[2,1.22,401.71]],"ltp":1.19,"tv":128855.01,"id":5300737},{"batb":[[0,5.7,5.22],[1,5.6,3],[2,5.5,133.59]],"batl":[[0,6.6,50.23],[1,6.8,59.38],[2,7,62.51]],"ltp":6.0,"tv":26004.72,"id":2497008}],"tv":154859.73}]}
{"op":"mcm","clk":"4299517469","pt":1632580993176,"mc":[{"id":"1.188136695","rc":[{"batb":[[1,1.18,449.68]],"batl":[[0,1.21,1224.85],[1,1.22,401.71],[2,1.23,666.96]],"ltp":1.19,"tv":128855.01,"id":5300737}]}]}
{"op":"mcm","clk":"4299517912","pt":1632580994524,"mc":[{"id":"1.188136695","rc":[{"batl":[[1,1.22,2012.92]],"ltp":1.19,"tv":128855.01,"id":5300737}]}]}
{"op":"mcm","clk":"4299518227","pt":1632580995592,"mc":[{"id":"1.188136695","rc":[{"batb":[[0,6,3.33],[1,5.7,5.22],[2,5.6,3]],"ltp":6.0,"tv":26004.72,"id":2497008}]}]}
{"op":"mcm","clk":"4299518543","pt":1632580996598,"mc":[{"id":"1.188136695","rc":[{"batb":[[0,1.19,10.13],[1,1.18,371.2]],"batl":[[0,1.21,14],[1,1.22,401.71],[2,1.23,398.45]],"ltp":1.19,"tv":128855.01,"id":5300737},{"batb":[[0,5.7,5.22],[1,5.6,3],[2,5.5,133.59]],"ltp":6.0,"tv":26004.72,"id":2497008}]}]}
{"op":"mcm","clk":"4299518918","pt":1632580997767,"mc":[{"id":"1.188136695","rc":[{"trd":[[1.21,1661.42]],"batl":[[0,1.22,402.07],[1,1.23,398.45],[2,1.25,952.26]],"ltp":1.21,"tv":128882.29,"id":5300737}],"tv":154887.01}]}
{"op":"mcm","clk":"4299519226","pt":1632580998708,"mc":[{"id":"1.188136695","rc":[{"trd":[[1.19,15873.14]],"batb":[[0,1.18,39.6],[1,1.17,14907.08],[2,1.16,3450.41]],"batl":[[0,1.19,131.3],[1,1.2,2514.17],[2,1.21,66.01]],"ltp":1.19,"tv":128902.55,"id":5300737},{"batl":[[0,6.8,59.69],[1,7,62.51],[2,7.4,5.54]],"ltp":6.0,"tv":26004.72,"id":2497008}],"tv":154907.27}]}
{"op":"mcm","clk":"4299519546","pt":1632580999711,"mc":[{"id":"1.188136695","rc":[{"batl":[[0,1.19,1687.4],[1,1.2,5092.97],[2,1.21,328.62]],"ltp":1.19,"tv":128902.55,"id":5300737}]}]}
{"op":"mcm","clk":"4299519889","pt":1632581000734,"mc":[{"id":"1.188136695","rc":[{"batb":[[1,1.17,16672.17],[2,1.16,5310.36]],"ltp":1.19,"tv":128902.55,"id":5300737},{"trd":[[6.2,254.21]],"batb":[[0,6.2,197.71],[1,5.7,246.02],[2,5.6,3]],"batl":[[2,7.2,108.51]],"ltp":6.2,"tv":26019.54,"id":2497008}],"tv":154922.09}]}
{"op":"mcm","clk":"4299520413","pt":1632581002215,"mc":[{"id":"1.188136695","rc":[{"batl":[[0,1.19,2639.66]],"ltp":1.19,"tv":128902.55,"id":5300737},{"batb":[[1,5.8,19.61],[2,5.7,246.02]],"batl":[[0,6.8,70.9]],"ltp":6.2,"tv":26019.54,"id":2497008}]}]}
{"op":"mcm","clk":"4299520902","pt":1632581003707,"mc":[{"id":"1.188136695","rc":[{"trd":[[1.19,15883.66]],"batb":[[0,1.18,100.4],[1,1.17,17298.84]],"batl":[[0,1.19,4364.25],[1,1.2,5764.95]],"ltp":1.19,"tv":128913.07,"id":5300737},{"batb":[[0,6.2,314.35],[1,6,134.4],[2,5.8,19.61]],"ltp":6.2,"tv":26019.54,"id":2497008}],"tv":154932.61}]}
{"op":"mcm","clk":"4299521161","pt":1632581004525,"mc":[{"id":"1.188136695","rc":[{"batb":[[2,1.16,18702.84]],"ltp":1.19,"tv":128913.07,"id":5300737}]}]}
{"op":"mcm","clk":"4299521491","pt":1632581005530,"mc":[{"id":"1.188136695","rc":[{"trd":[[1.19,15885.19]],"batl":[[0,1.19,4363.48],[2,1.21,581.12]],"ltp":1.19,"tv":128914.6,"id":5300737},{"batb":[[1,6,138.14]],"ltp":6.2,"tv":26019.54,"id":2497008}],"tv":154934.15}]}
{"op":"mcm","clk":"4299521816","pt":1632581006527,"mc":[{"id":"1.188136695","rc":[{"trd":[[1.19,15886.59]],"batb":[[1,1.17,17580.17],[2,1.16,18999.02]],"batl":[[0,1.19,4362.78]],"ltp":1.19,"tv":128916.0,"id":5300737},{"batl":[[0,6.8,132.54],[1,7,121.9],[2,7.2,180.73]],"ltp":6.2,"tv":26019.54,"id":2497008}],"tv":154935.55}]}
{"op":"mcm","clk":"4299522528","pt":1632581008726,"mc":[{"id":"1.188136695","rc":[{"trd":[[1.19,15886.66]],"batl":[[0,1.19,4362.75]],"ltp":1.19,"tv":128916.07,"id":5300737}],"tv":154935.61}]}
{"op":"mcm","clk":"4299522870","pt":1632581009817,"mc":[{"id":"1.188136695","rc":[{"trd":[[1.17,751.5],[1.18,981.47],[1.19,15914.44]],"batb":[[0,1.17,17204.42],[1,1.16,18999.02],[2,1.15,1874.79]],"batl":[[0,1.19,4185],[1,1.2,2472.61],[2,1.21,252.86]],"ltp":1.19,"tv":129896.16,"id":5300737},{"batl":[[2,7.2,72.22]],"ltp":6.2,"tv":26019.54,"id":2497008}],"tv":155915.71}]}
{"op":"mcm","clk":"4299523190","pt":1632581010806,"mc":[{"id":"1.188136695","rc":[{"batb":[[0,1.17,356.84],[1,1.16,18249.37]],"batl":[[0,1.19,1023.99],[1,1.2,876.85]],"ltp":1.19,"tv":129896.16,"id":5300737},{"batb":[[0,6,3.74],[1,5.7,246.02],[2,5.5,65.76]],"batl":[[0,6.8,62.95],[1,7,59.39]],"ltp":6.2,"tv":26019.54,"id":2497008}]}]}
{"op":"mcm","clk":"4299523447","pt":1632581011499,"mc":[{"id":"1.188136695","rc":[{"batl":[[0,1.19,1037.63]],"ltp":1.19,"tv":129896.16,"id":5300737}]}]}
{"op":"mcm","clk":"4299523814","pt":1632581012714,"mc":[{"id":"1.188136695","rc":[{"trd":[[1.19,16044.42]],"batb":[[0,1.18,513.07],[1,1.17,433.24],[2,1.16,18249.37]],"batl":[[0,1.19,972.64]],"ltp":1.19,"tv":130026.13,"id":5300737}],"tv":156045.68}]}
{"op":"mcm","clk":"4299524029","pt":1632581013409,"mc":[{"id":"1.188136695","rc":[{"trd":[[1.19,16064.63]],"batb":[[0,1.18,515.07],[1,1.17,356.84]],"batl":[[0,1.19,962.54],[1,1.2,1139.08]],"ltp":1.19,"tv":130046.34,"id":5300737}],"tv":156065.89}]}
{"op":"mcm","clk":"4299524403","pt":1632581014723,"mc":[{"id":"1.188136695","rc":[{"batb":[[0,1.18,513.07],[1,1.17,283.68]],"batl":[[1,1.21,252.86],[2,1.22,401.71]],"ltp":1.19,"tv":130046.34,"id":5300737},{"batb":[[0,5.7,246.02],[1,4.5,138.52],[2,3.8,1]],"ltp":6.2,"tv":26019.54,"id":2497008}]}]}
{"op":"mcm","clk":"4299524581","pt":1632581015334,"mc":[{"id":"1.188136695","rc":[{"batb":[[2,1.16,19153.26]],"ltp":1.19,"tv":130046.34,"id":5300737}]}]}
{"op":"mcm","clk":"4299524923","pt":1632581016597,"mc":[{"id":"1.188136695","rc":[{"trd":[[1.19,16077.98]],"batb":[[1,1.17,1235.94]],"batl":[[0,1.19,955.86]],"ltp":1.19,"tv":130059.7,"id":5300737}],"tv":156079.25}]}
{"op":"mcm","clk":"4299525291","pt":1632581017813,"mc":[{"id":"1.188136695","rc":[{"trd":[[1.18,2007.6]],"batb":[[0,1.17,283.68],[1,1.16,19153.26],[2,1.15,2582.12]],"batl":[[0,1.18,429.29],[1,1.19,2882.47],[2,1.2,3176.49]],"ltp":1.18,"tv":131085.84,"id":5300737},{"batb":[[0,6.4,122.07],[1,6.2,61.04],[2,6,61.04]],"ltp":6.2,"tv":26019.54,"id":2497008}],"tv":157105.38}]}
{"op":"mcm","clk":"4299525649","pt":1632581019754,"mc":[{"id":"1.188136695","rc":[{"trd":[[1.18,2007.72]],"batb":[[0,1.17,4.35],[2,1.15,2360.28]],"batl":[[0,1.18,429.23],[1,1.19,2936.72]],"ltp":1.18,"tv":131085.96,"id":5300737},{"trd":[[6.4,14.54]],"batb":[[0,6.4,303.94]],"batl":[[0,6.8,1.31]],"ltp":6.4,"tv":26034.08,"id":2497008}],"tv":157120.04}]}
{"op":"mcm","clk":"4299526159","pt":1632581020744,"mc":[{"id":"1.188136695","rc":[{"trd":[[1.18,2027.72]],"batb":[[0,1.17,1054.35]],"batl":[[0,1.18,656.18],[2,1.2,3851.04]],"ltp":1.18,"tv":131105.96,"id":5300737},{"batb":[[2,6,195.95]],"ltp":6.4,"tv":26034.08,"id":2497008}],"tv":157140.04}]}
{"op":"mcm","clk":"4299526506","pt":1632581021710,"mc":[{"id":"1.188136695","rc":[{"batb":[[1,1.16,19374]],"batl":[[0,1.18,1143.47],[1,1.19,2864.99]],"ltp":1.18,"tv":131105.96,"id":5300737}]}]}
{"op":"mcm","clk":"4299526820","pt":1632581022811,"mc":[{"id":"1.188136695","rc":[{"batb":[[1,1.16,20218.03]],"batl":[[0,1.18,2202.79],[1,1.19,3490.69],[2,1.2,4584.74]],"ltp":1.18,"tv":131105.96,"id":5300737},{"batb":[[1,6.2,181.13],[2,6,342.69]],"ltp":6.4,"tv":26034.08,"id":2497008}]}]}
{"op":"mcm","clk":"4299527069","pt":1632581023736,"mc":[{"id":"1.188136695","rc":[{"trd":[[1.18,2077.72]],"batb":[[0,1.17,2664.25],[1,1.16,21108.57]],"batl":[[0,1.18,2177.79]],"ltp":1.18,"tv":131155.96,"id":5300737},{"batl":[[1,7,168.12]],"ltp":6.4,"tv":26034.08,"id":2497008}],"tv":157190.04}]}
{"op":"mcm","clk":"4299527347","pt":1632581024716,"mc":[{"id":"1.188136695","rc":[{"trd":[[1.17,758.36]],"batb":[[0,1.17,2873.68]],"batl":[[2,1.2,4586.45]],"ltp":1.17,"tv":131162.81,"id":5300737}],"tv":157196.9}]}
{"op":"mcm","clk":"4299527701","pt":1632581025811,"mc":[{"id":"1.188136695","rc":[{"batl":[[1,1.19,4072.67],[2,1.2,5218.15]],"ltp":1.17,"tv":131162.81,"id":5300737},{"batb":[[1,6.2,292.83],[2,6,469.03]],"ltp":6.4,"tv":26034.08,"id":2497008}]}]}
{"op":"mcm","clk":"4299528036","pt":1632581026810,"mc":[{"id":"1.188136695","rc":[{"batb":[[0,1.17,3500.23],[1,1.16,21867.12]],"batl":[[0,1.18,2636.79]],"ltp":1.17,"tv":131162.81,"id":5300737},{"batl":[[1,7,272.85]],"ltp":6.4,"tv":26034.08,"id":2497008}]}]}
{"op":"mcm","clk":"4299528297","pt":1632581027649,"mc":[{"id":"1.188136695","rc":[{"trd":[[6.4,194.54]],"batb":[[0,6.4,213.94]],"ltp":6.4,"tv":26214.08,"id":2497008}],"tv":157376.9}]}
{"op":"mcm","clk":"4299528626","pt":1632581028725,"mc":[{"id":"1.188136695","rc":[{"trd":[[1.17,2758.36]],"batb":[[0,1.17,2500.23],[2,1.15,1408.02]],"ltp":1.17,"tv":133162.81,"id":5300737}],"tv":159376.9}]}
{"op":"mcm","clk":"4299528949","pt":1632581029818,"mc":[{"id":"1.188136695","rc":[{"trd":[[1.18,2079.82]],"batb":[[0,1.17,2543.7]],"batl":[[0,1.18,2635.74]],"ltp":1.18,"tv":133164.91,"id":5300737},{"batb":[[0,6.4,513.94]],"ltp":6.4,"tv":26214.08,"id":2497008}],"tv":159379.0}]}
{"op":"mcm","clk":"4299529216","pt":1632581030749,"mc":[{"id":"1.188136695","rc":[{"trd":[[1.18,2083.99]],"batl":[[0,1.18,2633.66]],"ltp":1.18,"tv":133169.08,"id":5300737}],"tv":159383.17}]}
{"op":"mcm","clk":"4299529474","pt":1632581031526,"mc":[{"id":"1.188136695","rc":[{"trd":[[1.18,2101.05]],"batb":[[0,1.17,2550.71]],"batl":[[0,1.18,2625.13]],"ltp":1.18,"tv":133186.14,"id":5300737},{"batl":[[0,6.8,1.1]],"ltp":6.4,"tv":26214.08,"id":2497008}],"tv":159400.23}]}
{"op":"mcm","clk":"4299529852","pt":1632581032736,"mc":[{"id":"1.188136695","rc":[{"trd":[[1.18,2870.67]],"batl":[[0,1.18,3230.93]],"ltp":1.18,"tv":133955.75,"id":5300737},{"trd":[[6.4,195.22],[6.6,0.2]],"batb":[[0,6.6,38.23],[1,6.4,513.6],[2,6.2,292.83]],"batl":[[0,6.8,1.45]],"ltp":6.6,"tv":26214.96,"id":2497008}],"tv":160170.72}]}
{"op":"mcm","clk":"4299530173","pt":1632581033726,"mc":[{"id":"1.188136695","rc":[{"trd":[[1.17,2762.36]],"batb":[[0,1.17,2548.71],[2,1.15,1295.56]],"batl":[[0,1.18,2933.45]],"ltp":1.17,"tv":133959.75,"id":5300737}],"tv":160174.72}]}
{"op":"mcm","clk":"4299530485","pt":1632581034732,"mc":[{"id":"1.188136695","rc":[{"trd":[[1.17,2816.84],[1.18,3007.69]],"batb":[[0,1.17,2521.47],[1,1.16,34895.32]],"batl":[[0,1.18,1870.82]],"ltp":1.17,"tv":134151.26,"id":5300737}],"tv":160366.22}]}
{"op":"mcm","clk":"4299530758","pt":1632581035628,"mc":[{"id":"1.188136695","rc":[{"trd":[[1.17,2830.86],[1.18,3239.05]],"batb":[[0,1.17,2514.46]],"batl":[[0,1.18,1296.13]],"ltp":1.17,"tv":134396.64,"id":5300737}],"tv":160611.61}]}
{"op":"mcm","clk":"4299531054","pt":1632581036623,"mc":[{"id":"1.188136695","rc":[{"trd":[[1.18,3248.07]],"batb":[[1,1.16,35006.82]],"batl":[[0,1.18,1291.62],[1,1.19,4516.6],[2,1.2,6373.91]],"ltp":1.18,"tv":134405.66,"id":5300737},{"trd":[[6.6,32.97]],"batb":[[0,6.6,21.85]],"batl":[[0,6.8,14.63]],"ltp":6.6,"tv":26247.73,"id":2497008}],"tv":160653.4}]}
{"op":"mcm","clk":"4299531326","pt":1632581037624,"mc":[{"id":"1.188136695","rc":[{"trd":[[1.18,3268.08]],"batb":[[1,1.16,34054.56]],"batl":[[0,1.18,1281.62]],"ltp":1.18,"tv":134425.67,"id":5300737}],"tv":160673.4}]}
{"op":"mcm","clk":"4299531679","pt":1632581038732,"mc":[{"id":"1.188136695","rc":[{"trd":[[1.17,2937.05],[1.18,3275.94]],"batb":[[0,1.17,2461.37]],"batl":[[0,1.18,1277.69],[1,1.19,5567.02]],"ltp":1.18,"tv":134539.72,"id":5300737},{"trd":[[6.6,35.07],[6.8,29.26],[7,23.84]],"batb":[[0,6.6,170.8]],"batl":[[0,7,260.92],[1,7.2,72.22],[2,7.4,364.07]],"ltp":6.6,"tv":26302.93,"id":2497008}],"tv":160842.66}]}
{"op":"mcm","clk":"4299531998","pt":1632581039824,"mc":[{"id":"1.188136695","rc":[{"trd":[[1.18,3463.81]],"batb":[[0,1.17,2454.36]],"batl":[[0,1.18,1183.76]],"ltp":1.18,"tv":134727.59,"id":5300737},{"trd":[[6.6,35.77]],"batb":[[0,6.6,170.44]],"ltp":6.6,"tv":26303.63,"id":2497008}],"tv":161031.22}]}
{"op":"mcm","clk":"4299532207","pt":1632581040544,"mc":[{"id":"1.188136695","rc":[{"trd":[[1.17,3084.61],[1.18,3468.52]],"batb":[[0,1.17,2380.58]],"batl":[[0,1.18,1181.4]],"ltp":1.18,"tv":134879.86,"id":5300737},{"trd":[[6.6,36.35]],"batb":[[0,6.6,170.16]],"ltp":6.6,"tv":26304.21,"id":2497008}],"tv":161184.07}]}
{"op":"mcm","clk":"4299532576","pt":1632581041755,"mc":[{"id":"1.188136695","rc":[{"trd":[[1.18,3477.8]],"batl":[[0,1.18,1176.76]],"ltp":1.18,"tv":134889.14,"id":5300737},{"batl":[[0,7,270.87]],"ltp":6.6,"tv":26304.21,"id":2497008}],"tv":161193.35}]}
{"op":"mcm","clk":"4299532751","pt":1632581042253,"mc":[{"id":"1.188136695","rc":[{"trd":[[1.18,3512.86]],"batl":[[0,1.18,1159.23]],"ltp":1.18,"tv":134924.2,"id":5300737}],"tv":161228.41}]}
{"op":"mcm","clk":"4299533214","pt":1632581043779,"mc":[{"id":"1.188136695","rc":[{"trd":[[1.18,3524.82]],"batl":[[0,1.18,1153.25]],"ltp":1.18,"tv":134936.17,"id":5300737},{"trd":[[6.6,39.72]],"batb":[[0,6.6,168.47]],"ltp":6.6,"tv":26307.58,"id":2497008}],"tv":161243.75}]}
{"op":"mcm","clk":"4299533559","pt":1632581044739,"mc":[{"id":"1.188136695","rc":[{"trd":[[1.18,3596.37]],"batb":[[1,1.16,31170.48],[2,1.15,545.7]],"batl":[[0,1.18,1117.47],[1,1.19,4111.35],[2,1.2,5218.15]],"ltp":1.18,"tv":135007.72,"id":5300737}],"tv":161315.3}]}
{"op":"mcm","clk":"4299533868","pt":1632581045776,"mc":[{"id":"1.188136695","rc":[{"trd":[[1.18,3698.23]],"batb":[[0,1.17,2337.11],[1,1.16,31172.83]],"batl":[[0,1.18,1066.54],[1,1.19,4057.1]],"ltp":1.18,"tv":135109.58,"id":5300737},{"batl":[[0,7,260.92]],"ltp":6.6,"tv":26307.58,"id":2497008}],"tv":161417.16}]}
{"op":"mcm","clk":"4299534122","pt":1632581046454,"mc":[{"id":"1.188136695","rc":[{"trd":[[1.18,3713.23]],"batl":[[0,1.18,1059.05]],"ltp":1.18,"tv":135124.57,"id":5300737},{"trd":[[6.6,40.12]],"batb":[[0,6.6,168.27]],"ltp":6.6,"tv":26307.98,"id":2497008}],"tv":161432.56}]}
{"op":"mcm","clk":"4299534430","pt":1632581047511,"mc":[{"id":"1.188136695","rc":[{"trd":[[1.18,3734.32]],"batb":[[0,1.17,3194.23],[1,1.16,18144.63]],"batl":[[0,1.18,1687.06],[1,1.19,4735.94]],"ltp":1.18,"tv":135145.66,"id":5300737},{"trd":[[6.6,41.68]],"batb":[[0,6.6,167.49],[1,6.4,631.33],[2,6.2,423.12]],"ltp":6.6,"tv":26309.54,"id":2497008}],"tv":161455.2}]}
{"op":"mcm","clk":"4299534807","pt":1632581048754,"mc":[{"id":"1.188136695","rc":[{"trd":[[1.17,3411.34],[1.18,3774.64]],"batb":[[0,1.17,3030.86],[1,1.16,21028.71],[2,1.15,1295.56]],"batl":[[0,1.18,1666.9],[1,1.19,6427.64],[2,1.2,6373.91]],"ltp":1.18,"tv":135512.71,"id":5300737}],"tv":161822.26}]}
{"op":"mcm","clk":"4299535090","pt":1632581049656,"mc":[{"id":"1.188136695","rc":[{"trd":[[1.18,3780.82]],"batl":[[0,1.18,1663.81]],"ltp":1.18,"tv":135518.89,"id":5300737},{"trd":[[6.6,59.2]],"batb":[[0,6.6,158.73]],"ltp":6.6,"tv":26327.06,"id":2497008}],"tv":161845.96}]}
{"op":"mcm","clk":"4299535440","pt":1632581050766,"mc":[{"id":"1.188136695","rc":[{"trd":[[1.18,3787.84]],"batl":[[0,1.18,1660.3]],"ltp":1.18,"tv":135525.91,"id":5300737},{"trd":[[6.6,61.16]],"batb":[[0,6.6,157.75]],"ltp":6.6,"tv":26329.02,"id":2497008}],"tv":161854.94}]}
{"op":"mcm","clk":"4299535774","pt":1632581051806,"mc":[{"id":"1.188136695","rc":[{"trd":[[1.18,3802.3]],"batl":[[0,1.18,1653.07]],"ltp":1.18,"tv":135540.37,"id":5300737},{"trd":[[6.6,62.56]],"batb":[[0,6.6,157.05]],"batl":[[0,6.8,3.46],[1,7,260.92],[2,7.2,72.22]],"ltp":6.6,"tv":26330.42,"id":2497008}],"tv":161870.8}]}
{"op":"mcm","clk":"4299536029","pt":1632581052681,"mc":[{"id":"1.188136695","rc":[{"trd":[[1.17,3414.77]],"batb":[[0,1.17,3029.15]],"ltp":1.17,"tv":135543.8,"id":5300737}],"tv":161874.23}]}
{"op":"mcm","clk":"4299536271","pt":1632581053575,"mc":[{"id":"1.188136695","rc":[{"trd":[[1.18,3861.38]],"batl":[[0,1.18,1623.53]],"ltp":1.18,"tv":135602.88,"id":5300737}],"tv":161933.31}]}
{"op":"mcm","clk":"4299536598","pt":1632581054680,"mc":[{"id":"1.188136695","rc":[{"trd":[[1.18,3898.14]],"batb":[[0,1.17,3944.02],[1,1.16,18144.63],[2,1.15,545.7]],"batl":[[0,1.18,1605.15],[1,1.19,4057.1],[2,1.2,5218.15]],"ltp":1.18,"tv":135639.64,"id":5300737}],"tv":161970.06}]}
{"op":"mcm","clk":"4299536945","pt":1632581055780,"mc":[{"id":"1.188136695","rc":[{"trd":[[1.18,3916.22]],"batl":[[0,1.18,1596.11]],"ltp":1.18,"tv":135657.72,"id":5300737},{"trd":[[6.6,64.52]],"batb":[[0,6.6,156.07]],"batl":[[1,7,710.92]],"ltp":6.6,"tv":26332.38,"id":2497008}],"tv":161990.11}]}
{"op":"mcm","clk":"4299537220","pt":1632581056560,"mc":[{"id":"1.188136695","rc":[{"trd":[[1.17,3501.45],[1.18,3956.22]],"batb":[[0,1.17,3900.68]],"batl":[[0,1.18,1589.75]],"ltp":1.18,"tv":135784.4,"id":5300737}],"tv":162116.78}]}
{"op":"mcm","clk":"4299537582","pt":1632581057769,"mc":[{"id":"1.188136695","rc":[{"trd":[[1.18,3964.7]],"batl":[[0,1.18,1585.51]],"ltp":1.18,"tv":135792.88,"id":5300737}],"tv":162125.26}]}
{"op":"mcm","clk":"4299537806","pt":1632581058486,"mc":[{"id":"1.188136695","rc":[{"trd":[[1.18,4009.82]],"batl":[[0,1.18,1562.95]],"ltp":1.18,"tv":135838.0,"id":5300737}],"tv":162170.38}]}
{"op":"mcm","clk":"4299538184","pt":1632581059808,"mc":[{"id":"1.188136695","rc":[{"trd":[[1.17,3501.91],[1.18,4025.18]],"batb":[[0,1.17,3900.45]],"batl":[[0,1.18,1616.71]],"ltp":1.18,"tv":135853.81,"id":5300737}],"tv":162186.2}]}
{"op":"mcm","clk":"4299538828","pt":1632581061762,"mc":[{"id":"1.188136695","rc":[{"trd":[[1.18,4027.28]],"batl":[[0,1.18,1615.66]],"ltp":1.18,"tv":135855.91,"id":5300737}],"tv":162188.3}]}
{"op":"mcm","clk":"4299539092","pt":1632581062702,"mc":[{"id":"1.188136695","rc":[{"trd":[[1.17,3506.83],[1.18,4028.97]],"batb":[[0,1.17,3897.99]],"batl":[[0,1.18,1614.81]],"ltp":1.17,"tv":135862.53,"id":5300737}],"tv":162194.92}]}
{"op":"mcm","clk":"4299539340","pt":1632581063597,"mc":[{"id":"1.188136695","rc":[{"trd":[[1.18,4032.19]],"batl":[[0,1.18,1613.2]],"ltp":1.18,"tv":135865.75,"id":5300737}],"tv":162198.13}]}
{"op":"mcm","clk":"4299539685","pt":1632581064793,"mc":[{"id":"1.188136695","rc":[{"trd":[[1.18,4032.89]],"batl":[[0,1.18,1612.85]],"ltp":1.18,"tv":135866.45,"id":5300737},{"trd":[[6.6,70.37]],"batb":[[0,6.6,153.15]],"ltp":6.6,"tv":26338.23,"id":2497008}],"tv":162204.68}]}
{"op":"mcm","clk":"4299539936","pt":1632581065572,"mc":[{"id":"1.188136695","rc":[{"trd":[[1.18,4041.34]],"batb":[[0,1.17,3901.5],[1,1.16,4752.16]],"batl":[[0,1.18,1669.42]],"ltp":1.18,"tv":135874.9,"id":5300737},{"trd":[[6.6,71.52]],"batb":[[0,6.6,152.57]],"ltp":6.6,"tv":26339.38,"id":2497008}],"tv":162214.28}]}
{"op":"mcm","clk":"4299540215","pt":1632581066507,"mc":[{"id":"1.188136695","rc":[{"trd":[[1.17,8212.71],[1.18,4044.29]],"batb":[[0,1.17,1548.56]],"batl":[[0,1.18,1667.95]],"ltp":1.18,"tv":140583.72,"id":5300737}],"tv":166923.11}]}
{"op":"mcm","clk":"4299540455","pt":1632581067382,"mc":[{"id":"1.188136695","rc":[{"trd":[[1.18,4057.09]],"batl":[[0,1.18,1661.55]],"ltp":1.18,"tv":140596.52,"id":5300737}],"tv":166935.91}]}
{"op":"mcm","clk":"4299540800","pt":1632581068496,"mc":[{"id":"1.188136695","rc":[{"trd":[[1.18,4096.03]],"batl":[[0,1.18,1642.08]],"ltp":1.18,"tv":140635.46,"id":5300737},{"trd":[[6.6,71.55]],"batb":[[0,6.6,152.56]],"ltp":6.6,"tv":26339.41,"id":2497008}],"tv":166974.88}]}
{"op":"mcm","clk":"4299540965","pt":1632581068943,"mc":[{"id":"1.188136695","rc":[{"batl":[[1,7,260.92]],"ltp":6.6,"tv":26339.41,"id":2497008}]}]}
{"op":"mcm","clk":"4299541484","pt":1632581070688,"mc":[{"id":"1.188136695","rc":[{"trd":[[1.18,4347.06]],"batl":[[0,1.18,1516.56]],"ltp":1.18,"tv":140886.5,"id":5300737},{"trd":[[6.6,272.26]],"batb":[[0,6.6,52.2]],"ltp":6.6,"tv":26540.12,"id":2497008}],"tv":167426.62}]}
{"op":"mcm","clk":"4299541732","pt":1632581071510,"mc":[{"id":"1.188136695","rc":[{"batl":[[0,1.18,1455.12]],"ltp":1.18,"tv":140886.5,"id":5300737}]}]}
{"op":"mcm","clk":"4299542144","pt":1632581072794,"mc":[{"id":"1.188136695","rc":[{"trd":[[1.18,4548.24]],"batl":[[0,1.18,1354.53]],"ltp":1.18,"tv":141087.68,"id":5300737},{"trd":[[6.6,273.86]],"batb":[[0,6.6,51.4]],"ltp":6.6,"tv":26541.72,"id":2497008}],"tv":167629.4}]}
{"op":"mcm","clk":"4299542305","pt":1632581073386,"mc":[{"id":"1.188136695","rc":[{"trd":[[1.18,4567.56]],"batl":[[0,1.18,1768.36]],"ltp":1.18,"tv":141107.0,"id":5300737}],"tv":167648.72}]}
{"op":"mcm","clk":"4299542732","pt":1632581074787,"mc":[{"id":"1.188136695","rc":[{"trd":[[1.18,4569.59]],"batl":[[0,1.18,1767.35]],"ltp":1.18,"tv":141109.02,"id":5300737}],"tv":167650.75}]}
{"op":"mcm","clk":"4299543019","pt":1632581075818,"mc":[{"id":"1.188136695","rc":[{"trd":[[1.17,8336.65],[1.18,4607.95]],"batb":[[0,1.17,1486.59]],"batl":[[0,1.18,1748.17]],"ltp":1.18,"tv":141271.32,"id":5300737}],"tv":167813.05}]}
{"op":"mcm","clk":"4299543274","pt":1632581076692,"mc":[{"id":"1.188136695","rc":[{"trd":[[1.18,4608.89]],"batb":[[1,1.16,4751.4]],"batl":[[0,1.18,1747.7]],"ltp":1.18,"tv":141272.27,"id":5300737},{"trd":[[6.6,278.04]],"batb":[[0,6.6,49.31]],"batl":[[1,7,261.02]],"ltp":6.6,"tv":26545.9,"id":2497008}],"tv":167818.17}]}
{"op":"mcm","clk":"4299543621","pt":1632581077807,"mc":[{"id":"1.188136695","rc":[{"trd":[[1.18,4612.47]],"batl":[[0,1.18,1745.91]],"ltp":1.18,"tv":141275.85,"id":5300737}],"tv":167821.75}]}
{"op":"mcm","clk":"4299543796","pt":1632581078395,"mc":[{"id":"1.188136695","rc":[{"trd":[[1.18,4628.59]],"batl":[[0,1.18,1737.85]],"ltp":1.18,"tv":141291.97,"id":5300737},{"trd":[[6.6,284.78]],"batb":[[0,6.6,45.94]],"ltp":6.6,"tv":26552.64,"id":2497008}],"tv":167844.61}]}
{"op":"mcm","clk":"4299544657","pt":1632581081409,"mc":[{"id":"1.188136695","rc":[{"trd":[[1.18,4629.09]],"batl":[[0,1.18,1737.6]],"ltp":1.18,"tv":141292.47,"id":5300737}],"tv":167845.11}]}
{"op":"mcm","clk":"4299545033","pt":1632581082718,"mc":[{"id":"1.188136695","rc":[{"trd":[[1.18,4645.31]],"batl":[[0,1.18,1729.49]],"ltp":1.18,"tv":141308.69,"id":5300737},{"trd":[[6.6,284.86]],"batb":[[0,6.6,45.9]],"ltp":6.6,"tv":26552.72,"id":2497008}],"tv":167861.41}]}
{"op":"mcm","clk":"4299545138","pt":1632581083118,"mc":[{"id":"1.188136695","rc":[{"trd":[[1.18,4651.93]],"batl":[[0,1.18,1726.18]],"ltp":1.18,"tv":141315.31,"id":5300737}],"tv":167868.03}]}
{"op":"mcm","clk":"4299545574","pt":1632581084705,"mc":[{"id":"1.188136695","rc":[{"trd":[[1.17,8548.61]],"batb":[[0,1.17,1380.61]],"ltp":1.17,"tv":141527.27,"id":5300737},{"batb":[[1,6.4,630.65]],"batl":[[1,7,261.34]],"ltp":6.6,"tv":26552.72,"id":2497008}],"tv":168080.0}]}
{"op":"mcm","clk":"4299546199","pt":1632581086819,"mc":[{"id":"1.188136695","rc":[{"trd":[[1.18,4722.05]],"batl":[[0,1.18,1691.12]],"ltp":1.18,"tv":141597.39,"id":5300737},{"trd":[[6.6,313]],"batb":[[0,6.6,31.83]],"ltp":6.6,"tv":26580.86,"id":2497008}],"tv":168178.25}]}
{"op":"mcm","clk":"4299546501","pt":1632581087809,"mc":[{"id":"1.188136695","rc":[{"trd":[[6.6,353]],"batb":[[0,6.6,11.83]],"ltp":6.6,"tv":26620.86,"id":2497008}],"tv":168218.25}]}
{"op":"mcm","clk":"4299546628","pt":1632581088239,"mc":[{"id":"1.188136695","rc":[{"trd":[[1.18,4729.86]],"batl":[[0,1.18,1687.22]],"ltp":1.18,"tv":141605.2,"id":5300737}],"tv":168226.06}]}
{"op":"mcm","clk":"4299547041","pt":1632581089617,"mc":[{"id":"1.188136695","rc":[{"trd":[[1.18,5589.86]],"batl":[[0,1.18,1257.22]],"ltp":1.18,"tv":142465.2,"id":5300737}],"tv":169086.06}]}
{"op":"mcm","clk":"4299547300","pt":1632581090644,"mc":[{"id":"1.188136695","rc":[{"trd":[[1.17,8680.57],[1.18,5594.93]],"batb":[[0,1.17,1314.63]],"batl":[[0,1.18,1254.68]],"ltp":1.17,"tv":142602.23,"id":5300737},{"trd":[[6.6,367.62]],"batb":[[0,6.6,4.52]],"ltp":6.6,"tv":26635.48,"id":2497008}],"tv":169237.72}]}
{"op":"mcm","clk":"4299547907","pt":1632581092827,"mc":[{"id":"1.188136695","rc":[{"trd":[[1.18,5604.06]],"batl":[[0,1.18,1250.12]],"ltp":1.18,"tv":142611.36,"id":5300737},{"trd":[[6.6,376.66]],"batb":[[0,6.4,630.65],[1,6.2,423.12],[2,6,469.03]],"batl":[[0,6.8,4.03]],"ltp":6.6,"tv":26644.52,"id":2497008}],"tv":169255.88}]}
{"op":"mcm","clk":"4299548206","pt":1632581093793,"mc":[{"id":"1.188136695","rc":[{"trd":[[1.18,5605.66]],"batb":[[0,1.17,1349.63]],"batl":[[0,1.18,1249.32]],"ltp":1.18,"tv":142612.96,"id":5300737},{"batl":[[0,6.8,4.38]],"ltp":6.6,"tv":26644.52,"id":2497008}],"tv":169257.49}]}
{"op":"mcm","clk":"4299548727","pt":1632581095730,"mc":[{"id":"1.188136695","rc":[{"trd":[[1.18,5616.18]],"batb":[[1,1.16,4718.59]],"batl":[[0,1.18,1244.06]],"ltp":1.18,"tv":142623.48,"id":5300737},{"trd":[[6.4,299.98]],"batb":[[0,6.4,389.81],[1,6.2,617.84]],"ltp":6.4,"tv":26749.28,"id":2497008}],"tv":169372.77}]}
{"op":"mcm","clk":"4299549294","pt":1632581097630,"mc":[{"id":"1.188136695","rc":[{"batb":[[1,1.16,3828.05]],"ltp":1.18,"tv":142623.48,"id":5300737},{"trd":[[6.6,448.94]],"batl":[[0,6.6,14.35],[1,6.8,3.46],[2,7,261.34]],"ltp":6.6,"tv":26821.56,"id":2497008}],"tv":169445.05}]}
{"op":"mcm","clk":"4299549464","pt":1632581098220,"mc":[{"id":"1.188136695","rc":[{"trd":[[1.18,5623.2]],"batl":[[0,1.18,1240.55]],"ltp":1.18,"tv":142630.5,"id":5300737}],"tv":169452.07}]}
{"op":"mcm","clk":"4299549813","pt":1632581099437,"mc":[{"id":"1.188136695","rc":[{"trd":[[1.18,5629.18]],"batb":[[0,1.17,1986.47],[1,1.16,4723.74]],"batl":[[0,1.18,1237.56]],"ltp":1.18,"tv":142636.48,"id":5300737},{"batl":[[2,7,367.77]],"ltp":6.6,"tv":26821.56,"id":2497008}],"tv":169458.05}]}
{"op":"mcm","clk":"4299550187","pt":1632581100760,"mc":[{"id":"1.188136695","rc":[{"trd":[[1.18,7344.26]],"batl":[[0,1.18,377.48]],"ltp":1.18,"tv":144351.56,"id":5300737}],"tv":171173.13}]}
{"op":"mcm","clk":"4299550435","pt":1632581101557,"mc":[{"id":"1.188136695","rc":[{"trd":[[1.18,7348.04]],"batb":[[0,1.17,2148.71]],"batl":[[0,1.18,537.95]],"ltp":1.18,"tv":144355.34,"id":5300737}],"tv":171176.91}]}
{"op":"mcm","clk":"4299550690","pt":1632581102347,"mc":[{"id":"1.188136695","rc":[{"trd":[[1.18,7350.3]],"batl":[[0,1.18,536.82]],"ltp":1.18,"tv":144357.6,"id":5300737}],"tv":171179.17}]}
{"op":"mcm","clk":"4299551122","pt":1632581103736,"mc":[{"id":"1.188136695","rc":[{"trd":[[1.17,8700.87]],"batb":[[0,1.17,2291.31]],"ltp":1.17,"tv":144377.9,"id":5300737},{"trd":[[6.6,449.82]],"batl":[[0,6.6,13.91]],"ltp":6.6,"tv":26822.44,"id":2497008}],"tv":171200.34}]}
{"op":"mcm","clk":"4299551360","pt":1632581104461,"mc":[{"id":"1.188136695","rc":[{"trd":[[1.18,7402.24]],"batl":[[0,1.18,510.85]],"ltp":1.18,"tv":144429.83,"id":5300737},{"trd":[[6.4,331.54]],"batb":[[0,6.4,374.03],[1,6.2,616.32]],"ltp":6.4,"tv":26854.0,"id":2497008}],"tv":171283.84}]}
{"op":"mcm","clk":"4299552043","pt":1632581106641,"mc":[{"id":"1.188136695","rc":[{"trd":[[1.18,7913.17]],"batl":[[0,1.19,4057.1],[1,1.2,5218.15],[2,1.21,985.34]],"ltp":1.18,"tv":144940.76,"id":5300737},{"trd":[[6.2,714.26],[6.4,1173.76]],"batb":[[0,6.2,386.3],[1,6,469.03],[2,5.9,2]],"ltp":6.2,"tv":28156.27,"id":2497008}],"tv":173097.04}]}
{"op":"mcm","clk":"4299552658","pt":1632581108765,"mc":[{"id":"1.188136695","rc":[{"trd":[[1.18,7913.32]],"batb":[[0,1.18,2926.78],[1,1.17,2129.07],[2,1.16,4723.74]],"ltp":1.18,"tv":144940.92,"id":5300737}],"tv":173097.2}]}
{"op":"mcm","clk":"4299552934","pt":1632581109655,"mc":[{"id":"1.188136695","rc":[{"batb":[[0,1.18,2930.29],[1,1.17,1976.32]],"batl":[[0,1.19,3475.12]],"ltp":1.18,"tv":144940.92,"id":5300737},{"batl":[[0,6.4,2.35],[1,6.6,13.91],[2,6.8,3.46]],"ltp":6.2,"tv":28156.27,"id":2497008}]}]}
{"op":"mcm","clk":"4299553198","pt":1632581110546,"mc":[{"id":"1.188136695","rc":[{"batb":[[0,1.18,4734.63]],"ltp":1.18,"tv":144940.92,"id":5300737}]}]}
{"op":"mcm","clk":"4299553446","pt":1632581111247,"mc":[{"id":"1.188136695","rc":[{"batb":[[0,1.18,6361.77]],"ltp":1.18,"tv":144940.92,"id":5300737},{"batl":[[0,6.4,75.48]],"ltp":6.2,"tv":28156.27,"id":2497008}]}]}
{"op":"mcm","clk":"4299554020","pt":1632581113248,"mc":[{"id":"1.188136695","rc":[{"batb":[[0,1.18,185.19]],"ltp":1.18,"tv":144940.92,"id":5300737}]}]}
{"op":"mcm","clk":"4299554503","pt":1632581114824,"mc":[{"id":"1.188136695","rc":[{"trd":[[1.18,7919.41]],"batb":[[0,1.18,186.06]],"ltp":1.18,"tv":144947.0,"id":5300737},{"batl":[[0,6.4,375.48]],"ltp":6.2,"tv":28156.27,"id":2497008}],"tv":173103.28}]}
{"op":"mcm","clk":"4299554741","pt":1632581115685,"mc":[{"id":"1.188136695","rc":[{"batb":[[0,1.18,832.26],[1,1.17,2811.15]],"ltp":1.18,"tv":144947.0,"id":5300737},{"batl":[[1,6.6,127]],"ltp":6.2,"tv":28156.27,"id":2497008}]}]}
{"op":"mcm","clk":"4299555035","pt":1632581116650,"mc":[{"id":"1.188136695","rc":[{"batb":[[0,1.18,842.01]],"ltp":1.18,"tv":144947.0,"id":5300737},{"batl":[[0,6.4,75.48]],"ltp":6.2,"tv":28156.27,"id":2497008}]}]}
{"op":"mcm","clk":"4299555353","pt":1632581117778,"mc":[{"id":"1.188136695","rc":[{"batb":[[0,1.18,852.14]],"ltp":1.18,"tv":144947.0,"id":5300737},{"batl":[[0,6.4,75.89]],"ltp":6.2,"tv":28156.27,"id":2497008}]}]}
{"op":"mcm","clk":"4299555926","pt":1632581119675,"mc":[{"id":"1.188136695","rc":[{"batb":[[0,1.18,854.07]],"ltp":1.18,"tv":144947.0,"id":5300737},{"trd":[[6.4,1174.46]],"batl":[[0,6.4,75.54]],"ltp":6.4,"tv":28156.97,"id":2497008}],"tv":173103.98}]}
{"op":"mcm","clk":"4299556163","pt":1632581120462,"mc":[{"id":"1.188136695","rc":[{"trd":[[1.19,21875.54]],"batb":[[0,1.18,2470.69]],"batl":[[0,1.19,576.34]],"ltp":1.19,"tv":150744.57,"id":5300737},{"trd":[[6.2,714.55]],"batb":[[0,6.2,386.15]],"ltp":6.2,"tv":28157.26,"id":2497008}],"tv":178901.83}]}
{"op":"mcm","clk":"4299556823","pt":1632581122579,"mc":[{"id":"1.188136695","rc":[{"trd":[[1.19,21882.56]],"batl":[[0,1.19,572.83]],"ltp":1.19,"tv":150751.59,"id":5300737}],"tv":178908.85}]}
{"op":"mcm","clk":"4299557153","pt":1632581123671,"mc":[{"id":"1.188136695","rc":[{"trd":[[1.19,21907.91]],"batb":[[0,1.18,3865.13]],"batl":[[0,1.19,560.16],[1,1.2,6246.19]],"ltp":1.19,"tv":150776.93,"id":5300737},{"trd":[[6.2,860.81]],"batb":[[0,6.2,313.02]],"ltp":6.2,"tv":28303.52,"id":2497008}],"tv":179080.46}]}
{"op":"mcm","clk":"4299557723","pt":1632581125670,"mc":[{"id":"1.188136695","rc":[{"trd":[[1.19,23028.23]],"batb":[[0,1.19,1055.06],[1,1.18,4744.14],[2,1.17,2811.15]],"batl":[[0,1.2,6246.19],[1,1.21,985.34],[2,1.22,8]],"ltp":1.19,"tv":151897.25,"id":5300737}],"tv":180200.78}]}
{"op":"mcm","clk":"4299557907","pt":1632581126284,"mc":[{"id":"1.188136695","rc":[{"batb":[[0,1.19,1.75],[1,1.18,4743.75]],"ltp":1.19,"tv":151897.25,"id":5300737}]}]}
{"op":"mcm","clk":"4299558338","pt":1632581127775,"mc":[{"id":"1.188136695","rc":[{"trd":[[1.18,7923.97]],"batb":[[0,1.19,1.76],[1,1.18,3879.92]],"batl":[[0,1.2,5512.49]],"ltp":1.18,"tv":151901.81,"id":5300737}],"tv":180205.34}]}
{"op":"mcm","clk":"4299558576","pt":1632581128674,"mc":[{"id":"1.188136695","rc":[{"trd":[[6.2,862.4]],"batb":[[0,6.2,312.23]],"ltp":6.2,"tv":28305.12,"id":2497008}],"tv":180206.93}]}
{"op":"mcm","clk":"4299558757","pt":1632581129382,"mc":[{"id":"1.188136695","rc":[{"batb":[[0,1.19,875.76]],"ltp":1.18,"tv":151901.81,"id":5300737}]}]}
{"op":"mcm","clk":"4299559173","pt":1632581130794,"mc":[{"id":"1.188136695","rc":[{"batb":[[1,1.18,4282.47]],"ltp":1.18,"tv":151901.81,"id":5300737}]}]}
{"op":"mcm","clk":"4299559420","pt":1632581131586,"mc":[{"id":"1.188136695","rc":[{"batb":[[0,1.19,879.27]],"ltp":1.18,"tv":151901.81,"id":5300737},{"trd":[[6.2,1486.85]],"batb":[[0,6,469.03],[1,5.9,2],[2,5.7,279.61]],"batl":[[0,6.2,116.34],[1,6.4,75.54],[2,6.6,127]],"ltp":6.2,"tv":28929.56,"id":2497008}],"tv":180831.38}]}
{"op":"mcm","clk":"4299559700","pt":1632581132597,"mc":[{"id":"1.188136695","rc":[{"trd":[[1.19,23396.87]],"batb":[[0,1.19,698.46]],"ltp":1.19,"tv":152270.45,"id":5300737}],"tv":181200.02}]}
{"op":"mcm","clk":"4299559905","pt":1632581133272,"mc":[{"id":"1.188136695","rc":[{"batb":[[0,1.19,698.92],[1,1.18,4270.15]],"ltp":1.19,"tv":152270.45,"id":5300737},{"batl":[[0,6.2,116.69]],"ltp":6.2,"tv":28929.56,"id":2497008}]}]}
{"op":"mcm","clk":"4299560089","pt":1632581133987,"mc":[{"id":"1.188136695","rc":[{"batl":[[0,6.2,120.97]],"ltp":6.2,"tv":28929.56,"id":2497008}]}]}
{"op":"mcm","clk":"4299560595","pt":1632581135777,"mc":[{"id":"1.188136695","rc":[{"trd":[[1.2,3254.22]],"batb":[[0,1.19,695.41]],"batl":[[0,1.2,5509.73]],"ltp":1.2,"tv":152275.97,"id":5300737}],"tv":181205.54}]}
{"op":"mcm","clk":"4299560882","pt":1632581136756,"mc":[{"id":"1.188136695","rc":[{"trd":[[1.2,3324.34]],"batb":[[0,1.19,710.35]],"batl":[[0,1.2,5474.67]],"ltp":1.2,"tv":152346.09,"id":5300737},{"batl":[[0,6.2,116.69]],"ltp":6.2,"tv":28929.56,"id":2497008}],"tv":181275.66}]}
{"op":"mcm","clk":"4299561160","pt":1632581137680,"mc":[{"id":"1.188136695","rc":[{"batb":[[1,1.18,4275.84]],"ltp":1.2,"tv":152346.09,"id":5300737}]}]}
{"op":"mcm","clk":"4299561391","pt":1632581138494,"mc":[{"id":"1.188136695","rc":[{"batb":[[0,1.19,712.88]],"ltp":1.2,"tv":152346.09,"id":5300737}]}]}
{"op":"mcm","clk":"4299561581","pt":1632581139374,"mc":[{"id":"1.188136695","rc":[{"trd":[[1.19,23405.08]],"batb":[[0,1.19,708.78]],"ltp":1.19,"tv":152354.3,"id":5300737}],"tv":181283.87}]}
{"op":"mcm","clk":"4299561957","pt":1632581140494,"mc":[{"id":"1.188136695","rc":[{"trd":[[1.2,3337.27]],"batb":[[0,1.19,1762.09]],"batl":[[0,1.2,5468.2]],"ltp":1.2,"tv":152367.24,"id":5300737}],"tv":181296.81}]}
{"op":"mcm","clk":"4299562074","pt":1632581140876,"mc":[{"id":"1.188136695","rc":[{"trd":[[1.2,3437.27]],"batl":[[0,1.2,5418.2]],"ltp":1.2,"tv":152467.24,"id":5300737},{"batl":[[0,6.2,116.34]],"ltp":6.2,"tv":28929.56,"id":2497008}],"tv":181396.81}]}
{"op":"mcm","clk":"4299562867","pt":1632581143602,"mc":[{"id":"1.188136695","rc":[{"batb":[[0,1.19,2812.51]],"ltp":1.2,"tv":152467.24,"id":5300737},{"trd":[[6,91.84]],"batb":[[0,6,458.87]],"ltp":6.0,"tv":28949.88,"id":2497008}],"tv":181417.12}]}
{"op":"mcm","clk":"4299563199","pt":1632581144801,"mc":[{"id":"1.188136695","rc":[{"trd":[[6,93.24]],"batb":[[0,6,458.17]],"batl":[[0,6.4,75.54],[1,6.6,127],[2,6.8,3.46]],"ltp":6.0,"tv":28951.28,"id":2497008}],"tv":181418.52}]}
{"op":"mcm","clk":"4299563232","pt":1632581144890,"mc":[{"id":"1.188136695","rc":[{"trd":[[1.19,25405.08]],"batb":[[0,1.19,1812.51]],"ltp":1.19,"tv":154467.24,"id":5300737},{"batb":[[0,6,311.43]],"ltp":6.0,"tv":28951.28,"id":2497008}],"tv":183418.52}]}
{"op":"mcm","clk":"4299564023","pt":1632581147701,"mc":[{"id":"1.188136695","rc":[{"trd":[[1.19,25407.46]],"batb":[[0,1.19,1811.32]],"ltp":1.19,"tv":154469.61,"id":5300737},{"trd":[[6,325.91]],"batb":[[0,6,195.1]],"ltp":6.0,"tv":29183.95,"id":2497008}],"tv":183653.57}]}
{"op":"mcm","clk":"4299564228","pt":1632581148377,"mc":[{"id":"1.188136695","rc":[{"trd":[[1.2,3440.7]],"batb":[[0,1.19,1821.84],[1,1.18,4274.79]],"batl":[[0,1.2,5416.49]],"ltp":1.2,"tv":154473.04,"id":5300737}],"tv":183656.99}]}
{"op":"mcm","clk":"4299564492","pt":1632581149415,"mc":[{"id":"1.188136695","rc":[{"trd":[[1.2,3447.72]],"batl":[[0,1.2,5412.98]],"ltp":1.2,"tv":154480.06,"id":5300737}],"tv":183664.01}]}
{"op":"mcm","clk":"4299565026","pt":1632581151382,"mc":[{"id":"1.188136695","rc":[{"trd":[[1.19,25434.74]],"batb":[[0,1.19,1808.2]],"ltp":1.19,"tv":154507.34,"id":5300737}],"tv":183691.29}]}
{"op":"mcm","clk":"4299565385","pt":1632581152810,"mc":[{"id":"1.188136695","rc":[{"trd":[[1.2,3468.26]],"batl":[[0,1.2,5402.71]],"ltp":1.2,"tv":154527.88,"id":5300737}],"tv":183711.83}]}
{"op":"mcm","clk":"4299566164","pt":1632581155721,"mc":[{"id":"1.188136695","rc":[{"trd":[[1.2,3505.22]],"batl":[[0,1.2,5384.23]],"ltp":1.2,"tv":154564.84,"id":5300737},{"batl":[[0,6.4,75.89]],"ltp":6.0,"tv":29183.95,"id":2497008}],"tv":183748.79}]}
{"op":"mcm","clk":"4299566341","pt":1632581156411,"mc":[{"id":"1.188136695","rc":[{"trd":[[1.2,3506.06]],"batl":[[0,1.2,5383.81]],"ltp":1.2,"tv":154565.68,"id":5300737}],"tv":183749.63}]}
{"op":"mcm","clk":"4299566469","pt":1632581156842,"mc":[{"id":"1.188136695","rc":[{"batl":[[0,1.2,4752.12]],"ltp":1.2,"tv":154565.68,"id":5300737}]}]}
{"op":"mcm","clk":"4299566804","pt":1632581158120,"mc":[{"id":"1.188136695","rc":[{"batb":[[0,6,68.76]],"ltp":6.0,"tv":29183.95,"id":2497008}]}]}
{"op":"mcm","clk":"4299567738","pt":1632581161505,"mc":[{"id":"1.188136695","rc":[{"trd":[[1.2,3541.12]],"batl":[[0,1.2,4734.59]],"ltp":1.2,"tv":154600.74,"id":5300737},{"batl":[[0,6.4,75.54]],"ltp":6.0,"tv":29183.95,"id":2497008}],"tv":183784.69}]}
{"op":"mcm","clk":"4299567960","pt":1632581162244,"mc":[{"id":"1.188136695","rc":[{"trd":[[1.2,3551.64]],"batl":[[0,1.2,4729.33]],"ltp":1.2,"tv":154611.26,"id":5300737}],"tv":183795.21}]}
{"op":"mcm","clk":"4299568435","pt":1632581163813,"mc":[{"id":"1.188136695","rc":[{"trd":[[6,331.17]],"batb":[[0,6,66.13]],"ltp":6.0,"tv":29189.21,"id":2497008}],"tv":183800.48}]}
{"op":"mcm","clk":"4299568845","pt":1632581165332,"mc":[{"id":"1.188136695","rc":[{"trd":[[1.2,3559.86]],"batl":[[0,1.2,4725.22]],"ltp":1.2,"tv":154619.48,"id":5300737}],"tv":183808.69}]}
{"op":"mcm","clk":"4299569716","pt":1632581168523,"mc":[{"id":"1.188136695","rc":[{"trd":[[1.2,3968.45]],"batl":[[0,1.2,4520.92]],"ltp":1.2,"tv":155028.07,"id":5300737}],"tv":184217.29}]}
{"op":"mcm","clk":"4299570013","pt":1632581169613,"mc":[{"id":"1.188136695","rc":[{"trd":[[1.19,29051.14]],"batb":[[0,1.18,4274.79],[1,1.17,2811.15],[2,1.16,6956.44]],"batl":[[0,1.19,436.42],[1,1.2,5676.68],[2,1.21,985.34]],"ltp":1.19,"tv":158644.47,"id":5300737}],"tv":187833.69}]}
{"op":"mcm","clk":"4299570283","pt":1632581170720,"mc":[{"id":"1.188136695","rc":[{"trd":[[1.19,29051.16]],"batl":[[0,1.19,436.41]],"ltp":1.19,"tv":158644.49,"id":5300737}],"tv":187833.71}]}
{"op":"mcm","clk":"4299570595","pt":1632581171807,"mc":[{"id":"1.188136695","rc":[{"trd":[[1.19,29053.26]],"batl":[[0,1.19,435.36]],"ltp":1.19,"tv":158646.59,"id":5300737}],"tv":187835.81}]}
{"op":"mcm","clk":"4299570766","pt":1632581172508,"mc":[{"id":"1.188136695","rc":[{"trd":[[1.19,29053.42]],"batb":[[1,1.17,4194]],"batl":[[0,1.19,1481.33],[1,1.2,6270.84]],"ltp":1.19,"tv":158646.76,"id":5300737}],"tv":187835.97}]}
{"op":"mcm","clk":"4299570957","pt":1632581173320,"mc":[{"id":"1.188136695","rc":[{"trd":[[1.19,29058.12]],"batb":[[2,1.16,19887.78]],"batl":[[0,1.19,1478.98]],"ltp":1.19,"tv":158651.46,"id":5300737}],"tv":187840.67}]}
{"op":"mcm","clk":"4299571322","pt":1632581174723,"mc":[{"id":"1.188136695","rc":[{"batb":[[0,6.2,2.69],[1,6,366.13],[2,5.9,2]],"ltp":6.0,"tv":29189.21,"id":2497008}]}]}
{"op":"mcm","clk":"4299571576","pt":1632581175718,"mc":[{"id":"1.188136695","rc":[{"trd":[[1.19,29110.94]],"batl":[[0,1.19,15776.86]],"ltp":1.19,"tv":158704.28,"id":5300737}],"tv":187893.49}]}
{"op":"mcm","clk":"4299571840","pt":1632581176620,"mc":[{"id":"1.188136695","rc":[{"trd":[[1.19,29143.39]],"batb":[[0,1.18,4267.47]],"batl":[[0,1.19,15744.41],[1,1.2,6909.39],[2,1.21,1659.89]],"ltp":1.19,"tv":158736.73,"id":5300737},{"trd":[[6.2,1498.46]],"batb":[[0,6,493.84],[1,5.9,2],[2,5.7,422.8]],"ltp":6.2,"tv":29200.82,"id":2497008}],"tv":187937.56}]}
{"op":"mcm","clk":"4299572086","pt":1632581177544,"mc":[{"id":"1.188136695","rc":[{"trd":[[1.19,29173.56]],"batl":[[0,1.19,15714.24]],"ltp":1.19,"tv":158766.9,"id":5300737},{"trd":[[6.2,1504.25]],"ltp":6.2,"tv":29206.62,"id":2497008}],"tv":187973.52}]}
{"op":"mcm","clk":"4299572191","pt":1632581177924,"mc":[{"id":"1.188136695","rc":[{"batb":[[0,6,193.84]],"ltp":6.2,"tv":29206.62,"id":2497008}]}]}
{"op":"mcm","clk":"4299572660","pt":1632581179738,"mc":[{"id":"1.188136695","rc":[{"trd":[[1.19,29322.11]],"batl":[[0,1.19,15565.69]],"ltp":1.19,"tv":158915.45,"id":5300737},{"trd":[[6.2,1532.76]],"ltp":6.2,"tv":29235.13,"id":2497008}],"tv":188150.58}]}
{"op":"mcm","clk":"4299572962","pt":1632581180715,"mc":[{"id":"1.188136695","rc":[{"trd":[[1.19,29325.63]],"batb":[[1,1.17,4713.69],[2,1.16,19783.56]],"batl":[[0,1.19,15563.93]],"ltp":1.19,"tv":158918.97,"id":5300737}],"tv":188154.1}]}
{"op":"mcm","clk":"4299573138","pt":1632581181330,"mc":[{"id":"1.188136695","rc":[{"trd":[[1.19,29379.59]],"batl":[[0,1.19,15527.75]],"ltp":1.19,"tv":158972.93,"id":5300737},{"trd":[[6.2,1707.72]],"batb":[[0,6.2,214.29],[1,6,193.84],[2,5.9,2]],"ltp":6.2,"tv":29410.08,"id":2497008}],"tv":188383.02}]}
{"op":"mcm","clk":"4299573474","pt":1632581182545,"mc":[{"id":"1.188136695","rc":[{"trd":[[1.19,29379.93]],"batl":[[0,1.19,15527.58]],"ltp":1.19,"tv":158973.27,"id":5300737},{"trd":[[6.2,1711.5]],"batb":[[0,6.2,212.4]],"ltp":6.2,"tv":29413.86,"id":2497008}],"tv":188387.14}]}
{"op":"mcm","clk":"4299573743","pt":1632581183633,"mc":[{"id":"1.188136695","rc":[{"trd":[[1.18,9809.64]],"batb":[[0,1.18,3324.63],[1,1.17,4817.02]],"batl":[[0,1.19,15667.22]],"ltp":1.18,"tv":160858.94,"id":5300737},{"trd":[[6.4,1325.55]],"batb":[[0,6.4,24.46],[1,6.2,212.4],[2,6,193.84]],"batl":[[0,6.6,127],[1,6.8,3.46],[2,7,506.99]],"ltp":6.4,"tv":29564.95,"id":2497008}],"tv":190423.89}]}
{"op":"mcm","clk":"4299574011","pt":1632581184717,"mc":[{"id":"1.188136695","rc":[{"batl":[[0,1.19,16322.05],[1,1.2,7721.94]],"ltp":1.18,"tv":160858.94,"id":5300737},{"batb":[[0,6.2,338.08],[1,6,356.35],[2,5.9,2]],"ltp":6.4,"tv":29564.95,"id":2497008}]}]}
{"op":"mcm","clk":"4299574280","pt":1632581185616,"mc":[{"id":"1.188136695","rc":[{"trd":[[1.18,9810.96]],"batb":[[0,1.18,3323.97]],"ltp":1.18,"tv":160860.26,"id":5300737},{"batl":[[1,6.8,3.77]],"ltp":6.4,"tv":29564.95,"id":2497008}],"tv":190425.21}]}
{"op":"mcm","clk":"4299574619","pt":1632581186721,"mc":[{"id":"1.188136695","rc":[{"trd":[[1.19,29414.45]],"batl":[[0,1.19,16349.88]],"ltp":1.19,"tv":160894.78,"id":5300737},{"batb":[[0,6.2,348.75]],"ltp":6.4,"tv":29564.95,"id":2497008}],"tv":190459.73}]}
{"op":"mcm","clk":"4299574846","pt":1632581187646,"mc":[{"id":"1.188136695","rc":[{"trd":[[1.18,10076.66],[1.19,29414.51]],"batb":[[0,1.18,3191.12]],"batl":[[0,1.19,16349.85]],"ltp":1.18,"tv":161160.54,"id":5300737},{"trd":[[6.2,1712.66]],"batb":[[0,6.2,348.17]],"ltp":6.2,"tv":29566.1,"id":2497008}],"tv":190726.65}]}
{"op":"mcm","clk":"4299575068","pt":1632581188521,"mc":[{"id":"1.188136695","rc":[{"trd":[[1.19,29419.63]],"batl":[[0,1.19,16347.29]],"ltp":1.19,"tv":161165.66,"id":5300737}],"tv":190731.77}]}
{"op":"mcm","clk":"4299575350","pt":1632581189560,"mc":[{"id":"1.188136695","rc":[{"trd":[[1.19,29469.95]],"batl":[[0,1.19,16322.13]],"ltp":1.19,"tv":161215.98,"id":5300737},{"batb":[[0,6.2,398.17]],"ltp":6.2,"tv":29566.1,"id":2497008}],"tv":190782.09}]}
{"op":"mcm","clk":"4299575582","pt":1632581190449,"mc":[{"id":"1.188136695","rc":[{"batl":[[0,1.19,17000.12],[1,1.2,8479.63]],"ltp":1.19,"tv":161215.98,"id":5300737},{"trd":[[6.2,1713.73]],"batb":[[0,6.2,527.76],[1,6,507.89]],"ltp":6.2,"tv":29567.18,"id":2497008}],"tv":190783.16}]}
{"op":"mcm","clk":"4299575937","pt":1632581191646,"mc":[{"id":"1.188136695","rc":[{"trd":[[1.19,29533.07]],"batl":[[0,1.19,16968.56]],"ltp":1.19,"tv":161279.1,"id":5300737},{"trd":[[6.2,1718.12]],"batb":[[0,6.2,525.57]],"ltp":6.2,"tv":29571.56,"id":2497008}],"tv":190850.67}]}
{"op":"mcm","clk":"4299576203","pt":1632581192632,"mc":[{"id":"1.188136695","rc":[{"trd":[[1.19,29619.53]],"batl":[[0,1.19,16925.33]],"ltp":1.19,"tv":161365.56,"id":5300737},{"batb":[[1,6,356.35]],"ltp":6.2,"tv":29571.56,"id":2497008}],"tv":190937.13}]}
{"op":"mcm","clk":"4299576242","pt":1632581192841,"mc":[{"id":"1.188136695","rc":[{"batb":[[1,6,193.84]],"ltp":6.2,"tv":29571.56,"id":2497008}]}]}
{"op":"mcm","clk":"4299576691","pt":1632581194548,"mc":[{"id":"1.188136695","rc":[{"trd":[[1.19,29619.61]],"batl":[[0,1.19,16925.29]],"ltp":1.19,"tv":161365.64,"id":5300737}],"tv":190937.21}]}
{"op":"mcm","clk":"4299576864","pt":1632581195135,"mc":[{"id":"1.188136695","rc":[{"trd":[[1.19,29646.89]],"batl":[[0,1.19,16911.65]],"ltp":1.19,"tv":161392.92,"id":5300737},{"trd":[[6.6,459.82]],"batl":[[0,6.6,122]],"ltp":6.6,"tv":29581.56,"id":2497008}],"tv":190974.49}]}
{"op":"mcm","clk":"4299577058","pt":1632581195837,"mc":[{"id":"1.188136695","rc":[{"trd":[[1.19,29647.55]],"batl":[[0,1.19,16999.08]],"ltp":1.19,"tv":161393.58,"id":5300737}],"tv":190975.15}]}
{"op":"mcm","clk":"4299577526","pt":1632581197567,"mc":[{"id":"1.188136695","rc":[{"trd":[[1.19,29682.07]],"batl":[[0,1.19,16981.82]],"ltp":1.19,"tv":161428.1,"id":5300737}],"tv":191009.67}]}
{"op":"mcm","clk":"4299577684","pt":1632581198153,"mc":[{"id":"1.188136695","rc":[{"batl":[[0,1.19,3707.95]],"ltp":1.19,"tv":161428.1,"id":5300737}]}]}
{"op":"mcm","clk":"4299577991","pt":1632581199452,"mc":[{"id":"1.188136695","rc":[{"trd":[[1.19,29682.58]],"batl":[[0,1.19,3707.7]],"ltp":1.19,"tv":161428.61,"id":5300737}],"tv":191010.18}]}
{"op":"mcm","clk":"4299578461","pt":1632581201261,"mc":[{"id":"1.188136695","rc":[{"trd":[[1.18,16458.9]],"batb":[[0,1.17,4817.02],[1,1.16,19783.56],[2,1.15,545.7]],"batl":[[0,1.18,10082.75],[1,1.19,3707.7],[2,1.2,8479.63]],"ltp":1.18,"tv":167810.85,"id":5300737}],"tv":197392.41}]}
{"op":"mcm","clk":"4299579091","pt":1632581203653,"mc":[{"id":"1.188136695","rc":[{"trd":[[1.18,16489.68]],"batl":[[0,1.18,10066.41]],"ltp":1.18,"tv":167841.63,"id":5300737},{"trd":[[6.4,1325.9]],"ltp":6.4,"tv":29581.91,"id":2497008}],"tv":197423.55}]}
{"op":"mcm","clk":"4299579398","pt":1632581204736,"mc":[{"id":"1.188136695","rc":[{"trd":[[1.18,16524.75]],"batb":[[0,1.17,4865.93]],"batl":[[0,1.18,11108.19]],"ltp":1.18,"tv":167876.69,"id":5300737},{"batl":[[0,6.6,8.91]],"ltp":6.4,"tv":29581.91,"id":2497008}],"tv":197458.61}]}
{"op":"mcm","clk":"4299579672","pt":1632581205770,"mc":[{"id":"1.188136695","rc":[{"trd":[[1.18,16527.91]],"batb":[[0,1.17,3951.06]],"batl":[[0,1.18,11106.61]],"ltp":1.18,"tv":167879.85,"id":5300737}],"tv":197461.77}]}
{"op":"mcm","clk":"4299579963","pt":1632581206765,"mc":[{"id":"1.188136695","rc":[{"trd":[[6.6,477.64]],"batb":[[0,6.6,123.35],[1,6.2,621.41],[2,6,193.84]],"batl":[[0,6.8,3.77],[1,7,506.99],[2,7.2,72.22]],"ltp":6.6,"tv":29599.73,"id":2497008}],"tv":197479.59}]}
{"op":"mcm","clk":"4299580116","pt":1632581207370,"mc":[{"id":"1.188136695","rc":[{"trd":[[1.18,16534.15]],"batl":[[0,1.18,11103.49]],"ltp":1.18,"tv":167886.1,"id":5300737}],"tv":197485.83}]}
{"op":"mcm","clk":"4299580353","pt":1632581208263,"mc":[{"id":"1.188136695","rc":[{"batb":[[1,6.4,100],[2,6.2,491.28]],"ltp":6.6,"tv":29599.73,"id":2497008}]}]}
{"op":"mcm","clk":"4299580763","pt":1632581209770,"mc":[{"id":"1.188136695","rc":[{"trd":[[1.18,16561.43]],"batl":[[0,1.18,11089.85]],"ltp":1.18,"tv":167913.38,"id":5300737}],"tv":197513.11}]}
{"op":"mcm","clk":"4299580853","pt":1632581210072,"mc":[{"id":"1.188136695","rc":[{"trd":[[1.18,16571.35]],"batl":[[0,1.18,11084.89]],"ltp":1.18,"tv":167923.3,"id":5300737}],"tv":197523.03}]}
{"op":"mcm","clk":"4299581362","pt":1632581211771,"mc":[{"id":"1.188136695","rc":[{"trd":[[1.17,8838.15],[1.18,16652.05]],"batb":[[0,1.17,3882.42]],"batl":[[0,1.18,11044.54]],"ltp":1.17,"tv":168141.28,"id":5300737}],"tv":197741.02}]}
{"op":"mcm","clk":"4299581472","pt":1632581212187,"mc":[{"id":"1.188136695","rc":[{"trd":[[1.18,16679.33]],"batl":[[0,1.18,11030.9]],"ltp":1.18,"tv":168168.56,"id":5300737},{"batb":[[2,6.2,395.44]],"ltp":6.6,"tv":29599.73,"id":2497008}],"tv":197768.3}]}
{"op":"mcm","clk":"4299581733","pt":1632581213236,"mc":[{"id":"1.188136695","rc":[{"trd":[[1.18,16692.06]],"batl":[[0,1.18,11024.54]],"ltp":1.18,"tv":168181.29,"id":5300737}],"tv":197781.02}]}
{"op":"mcm","clk":"4299582156","pt":1632581214760,"mc":[{"id":"1.188136695","rc":[{"trd":[[1.18,16702.58]],"batl":[[0,1.18,11019.28]],"ltp":1.18,"tv":168191.81,"id":5300737},{"trd":[[6.6,581.52]],"batb":[[0,6.6,71.41]],"ltp":6.6,"tv":29703.62,"id":2497008}],"tv":197895.43}]}
{"op":"mcm","clk":"4299582660","pt":1632581216691,"mc":[{"id":"1.188136695","rc":[{"trd":[[1.18,16714.4]],"batl":[[0,1.18,11013.37]],"ltp":1.18,"tv":168203.63,"id":5300737}],"tv":197907.25}]}
{"op":"mcm","clk":"4299582937","pt":1632581217775,"mc":[{"id":"1.188136695","rc":[{"trd":[[1.18,16755.2]],"batb":[[2,1.15,1045.7]],"batl":[[0,1.18,10992.96]],"ltp":1.18,"tv":168244.43,"id":5300737},{"trd":[[6.6,583.32]],"batb":[[0,6.6,70.51]],"ltp":6.6,"tv":29705.42,"id":2497008}],"tv":197949.85}]}
{"op":"mcm","clk":"4299583462","pt":1632581219673,"mc":[{"id":"1.188136695","rc":[{"trd":[[1.18,16759.92]],"batl":[[0,1.18,10990.6]],"ltp":1.18,"tv":168249.15,"id":5300737}],"tv":197954.57}]}
{"op":"mcm","clk":"4299583733","pt":1632581220687,"mc":[{"id":"1.188136695","rc":[{"trd":[[1.18,16760.62]],"batl":[[0,1.18,10990.25]],"ltp":1.18,"tv":168249.85,"id":5300737}],"tv":197955.27}]}
{"op":"mcm","clk":"4299584276","pt":1632581222579,"mc":[{"id":"1.188136695","rc":[{"trd":[[1.18,16810.62]],"batl":[[0,1.18,10965.25]],"ltp":1.18,"tv":168299.85,"id":5300737},{"batl":[[0,6.8,3.46]],"ltp":6.6,"tv":29705.42,"id":2497008}],"tv":198005.27}]}
{"op":"mcm","clk":"4299584434","pt":1632581223201,"mc":[{"id":"1.188136695","rc":[{"trd":[[1.18,16814.14]],"batl":[[0,1.18,10963.49]],"ltp":1.18,"tv":168303.37,"id":5300737}],"tv":198008.79}]}
{"op":"mcm","clk":"4299585050","pt":1632581225487,"mc":[{"id":"1.188136695","rc":[{"trd":[[1.18,16814.93]],"batb":[[0,1.17,4382.42]],"batl":[[0,1.18,10963.1]],"ltp":1.18,"tv":168304.15,"id":5300737}],"tv":198009.57}]}
{"op":"mcm","clk":"4299585301","pt":1632581226591,"mc":[{"id":"1.188136695","rc":[{"trd":[[1.18,16828.63]],"batl":[[0,1.18,10956.25]],"ltp":1.18,"tv":168317.86,"id":5300737}],"tv":198023.28}]}
{"op":"mcm","clk":"4299585424","pt":1632581227092,"mc":[{"id":"1.188136695","rc":[{"trd":[[1.18,16852.02]],"batl":[[0,1.18,10944.55]],"ltp":1.18,"tv":168341.25,"id":5300737}],"tv":198046.67}]}
{"op":"mcm","clk":"4299585871","pt":1632581228790,"mc":[{"id":"1.188136695","rc":[{"trd":[[1.18,16860.05]],"batl":[[0,1.18,10940.53],[1,1.19,3745.45]],"ltp":1.18,"tv":168349.28,"id":5300737},{"trd":[[6.6,591.9]],"batb":[[0,6.6,66.22]],"ltp":6.6,"tv":29713.99,"id":2497008}],"tv":198063.28}]}
{"op":"mcm","clk":"4299585982","pt":1632581229202,"mc":[{"id":"1.188136695","rc":[{"trd":[[1.18,16868.51]],"batl":[[0,1.18,10936.31]],"ltp":1.18,"tv":168357.73,"id":5300737}],"tv":198071.73}]}
{"op":"mcm","clk":"4299586314","pt":1632581230394,"mc":[{"id":"1.188136695","rc":[{"trd":[[1.18,16880.53]],"batl":[[0,1.18,10930.3]],"ltp":1.18,"tv":168369.76,"id":5300737}],"tv":198083.75}]}
{"op":"mcm","clk":"4299586879","pt":1632581232690,"mc":[{"id":"1.188136695","rc":[{"batl":[[0,6.8,3.77]],"ltp":6.6,"tv":29713.99,"id":2497008}]}]}
{"op":"mcm","clk":"4299587329","pt":1632581234390,"mc":[{"id":"1.188136695","rc":[{"trd":[[1.18,16882.89]],"batl":[[0,1.18,10929.11]],"ltp":1.18,"tv":168372.12,"id":5300737}],"tv":198086.12}]}
{"op":"mcm","clk":"4299587663","pt":1632581235697,"mc":[{"id":"1.188136695","rc":[{"trd":[[1.18,16883.95]],"batl":[[0,1.18,10928.58]],"ltp":1.18,"tv":168373.18,"id":5300737}],"tv":198087.18}]}
{"op":"mcm","clk":"4299588242","pt":1632581237804,"mc":[{"id":"1.188136695","rc":[{"trd":[[1.18,16895.67]],"batb":[[1,1.16,6852.22]],"batl":[[0,1.18,10922.73]],"ltp":1.18,"tv":168384.9,"id":5300737}],"tv":198098.89}]}
{"op":"mcm","clk":"4299588497","pt":1632581238800,"mc":[{"id":"1.188136695","rc":[{"trd":[[1.18,16913.21]],"batl":[[0,1.18,10913.96],[2,1.2,7667.08]],"ltp":1.18,"tv":168402.44,"id":5300737},{"batb":[[2,6.2,136.35]],"ltp":6.6,"tv":29713.99,"id":2497008}],"tv":198116.44}]}
{"op":"mcm","clk":"4299588755","pt":1632581239792,"mc":[{"id":"1.188136695","rc":[{"trd":[[1.18,16914.05]],"batl":[[0,1.18,10913.54],[2,1.2,6909.39]],"ltp":1.18,"tv":168403.28,"id":5300737}],"tv":198117.28}]}
{"op":"mcm","clk":"4299588908","pt":1632581240505,"mc":[{"id":"1.188136695","rc":[{"trd":[[1.17,8873.21]],"batb":[[0,1.17,4364.89]],"ltp":1.17,"tv":168438.34,"id":5300737}],"tv":198152.33}]}
{"op":"mcm","clk":"4299589112","pt":1632581241326,"mc":[{"id":"1.188136695","rc":[{"trd":[[1.18,16921.07]],"batl":[[0,1.18,10910.03]],"ltp":1.18,"tv":168445.36,"id":5300737}],"tv":198159.35}]}
{"op":"mcm","clk":"4299589530","pt":1632581242807,"mc":[{"id":"1.188136695","rc":[{"trd":[[1.18,16924.02]],"batl":[[0,1.18,10908.55]],"ltp":1.18,"tv":168448.31,"id":5300737}],"tv":198162.3}]}
{"op":"mcm","clk":"4299590043","pt":1632581244829,"mc":[{"id":"1.188136695","rc":[{"trd":[[1.18,16924.8]],"batl":[[0,1.18,10908.16]],"ltp":1.18,"tv":168449.08,"id":5300737}],"tv":198163.08}]}
{"op":"mcm","clk":"4299590283","pt":1632581245604,"mc":[{"id":"1.188136695","rc":[{"trd":[[1.18,16925.5]],"batl":[[0,1.18,10907.81]],"ltp":1.18,"tv":168449.78,"id":5300737},{"trd":[[6.8,36.8]],"batb":[[0,6.8,46.23],[1,6.6,66.22],[2,6.4,100]],"batl":[[0,7,506.99],[1,7.2,72.22],[2,7.4,504.47]],"ltp":6.8,"tv":29721.53,"id":2497008}],"tv":198171.32}]}
{"op":"mcm","clk":"4299590442","pt":1632581246212,"mc":[{"id":"1.188136695","rc":[{"trd":[[1.18,16995.62]],"batl":[[0,1.18,10872.75]],"ltp":1.18,"tv":168519.9,"id":5300737},{"trd":[[6.8,38.6]],"batb":[[0,6.6,66.22],[1,6.4,100],[2,6.2,136.35]],"ltp":6.8,"tv":29723.33,"id":2497008}],"tv":198243.24}]}
{"op":"mcm","clk":"4299590881","pt":1632581247828,"mc":[{"id":"1.188136695","rc":[{"trd":[[1.18,17195.62]],"batl":[[0,1.18,10772.75],[2,1.2,4092.78]],"ltp":1.18,"tv":168719.9,"id":5300737},{"trd":[[6.6,593.24]],"batb":[[0,6.6,65.55]],"batl":[[0,7,400.55],[2,7.4,398.9]],"ltp":6.6,"tv":29724.67,"id":2497008}],"tv":198444.58}]}
{"op":"mcm","clk":"4299591096","pt":1632581248602,"mc":[{"id":"1.188136695","rc":[{"trd":[[1.18,17199.13]],"batb":[[0,1.17,538.51],[1,1.16,105.7],[2,1.15,600]],"batl":[[0,1.18,9711.68],[1,1.19,37.75],[2,1.2,1.71]],"ltp":1.18,"tv":168723.42,"id":5300737},{"batb":[[2,5.9,2]],"batl":[[0,6.8,3],[1,7,10.86],[2,7.8,1]],"ltp":6.6,"tv":29724.67,"id":2497008}],"tv":198448.1}]}
{"op":"mcm","clk":"4299591405","pt":1632581249806,"mc":[{"id":"1.188136695","rc":[{"batl":[[1,1.19,420.35],[2,1.2,466.7]],"ltp":1.18,"tv":168723.42,"id":5300737},{"trd":[[6.6,602.02]],"batb":[[0,6.6,61.16],[1,6.4,71.14],[2,6.2,90]],"batl":[[0,7.8,1.1],[1,8,55.46],[2,8.2,55.95]],"ltp":6.6,"tv":29733.45,"id":2497008}],"tv":198456.88}]}
{"op":"mcm","clk":"4299591639","pt":1632581250732,"mc":[{"id":"1.188136695","rc":[{"trd":[[1.18,17200.03]],"batl":[[0,1.18,9711.22],[1,1.19,37.75],[2,1.2,1.71]],"ltp":1.18,"tv":168724.32,"id":5300737},{"batb":[[1,5.7,124.04],[2,5.4,70.76]],"ltp":6.6,"tv":29733.45,"id":2497008}],"tv":198457.78}]}
{"op":"mcm","clk":"4299591840","pt":1632581251530,"mc":[{"id":"1.188136695","rc":[{"batb":[[0,5.7,3.22],[1,5.5,135.37]],"ltp":6.6,"tv":29733.45,"id":2497008}]}]}
{"op":"mcm","clk":"4299592021","pt":1632581252229,"mc":[{"id":"1.188136695","rc":[{"trd":[[1.18,17200.87]],"batl":[[0,1.18,9710.8]],"ltp":1.18,"tv":168725.16,"id":5300737}],"tv":198458.61}]}
{"op":"mcm","clk":"4299592217","pt":1632581252904,"mc":[{"id":"1.188136695","rc":[{"trd":[[1.18,17209.89]],"batl":[[0,1.18,9706.3]],"ltp":1.18,"tv":168734.18,"id":5300737}],"tv":198467.63}]}
{"op":"mcm","clk":"4299592564","pt":1632581254118,"mc":[{"id":"1.188136695","rc":[{"trd":[[1.18,17217.77]],"batl":[[0,1.18,9702.36]],"ltp":1.18,"tv":168742.06,"id":5300737}],"tv":198475.51}]}
{"op":"mcm","clk":"4299592968","pt":1632581255645,"mc":[{"id":"1.188136695","rc":[{"trd":[[1.17,9508.97],[1.18,17221.23]],"batb":[[0,1.17,220.63]],"batl":[[0,1.18,9700.63]],"ltp":1.17,"tv":169381.28,"id":5300737},{"batl":[[0,6.6,5.64],[1,7.8,1.1],[2,8,55.46]],"ltp":6.6,"tv":29733.45,"id":2497008}],"tv":199114.73}]}
{"op":"mcm","clk":"4299593539","pt":1632581257824,"mc":[{"id":"1.188136695","rc":[{"trd":[[1.18,17260.54]],"batl":[[0,1.18,9680.98]],"ltp":1.18,"tv":169420.58,"id":5300737}],"tv":199154.04}]}
{"op":"mcm","clk":"4299593738","pt":1632581258663,"mc":[{"id":"1.188136695","rc":[{"trd":[[1.18,17264.76]],"batl":[[0,1.18,9678.87]],"ltp":1.18,"tv":169424.8,"id":5300737},{"batl":[[2,8.8,1]],"ltp":6.6,"tv":29733.45,"id":2497008}],"tv":199158.26}]}
{"op":"mcm","clk":"4299594060","pt":1632581259824,"mc":[{"id":"1.188136695","rc":[{"trd":[[1.18,25180.86]],"batl":[[0,1.18,5720.81]],"ltp":1.18,"tv":177340.91,"id":5300737}],"tv":207074.36}]}
{"op":"mcm","clk":"4299594274","pt":1632581260746,"mc":[{"id":"1.188136695","rc":[{"trd":[[1.18,30901.68],[1.19,29720.33],[1.2,3970.17]],"batl":[[0,1.22,1759.86],[1,1.23,1709.04],[2,1.24,283.96]],"ltp":1.2,"tv":183101.19,"id":5300737},{"trd":[[5.5,8.88],[5.7,28.79],[6,331.51],[6.2,1725.37],[6.4,2380.68]],"batb":[[0,5.5,130.93],[1,5.4,70.76],[2,5.3,2238.26]],"batl":[[0,6.2,971.67],[1,6.4,898.18],[2,6.6,948.73]],"ltp":5.5,"tv":30811.14,"id":2497008}],"tv":213912.34}]}
{"op":"mcm","clk":"4299594560","pt":1632581261729,"mc":[{"id":"1.188136695","rc":[{"batb":[[0,1.2,1460.79],[1,1.19,2332.95],[2,1.18,1215.07]],"ltp":1.2,"tv":183101.19,"id":5300737},{"batb":[[2,5.3,397.93]],"batl":[[0,6.2,277.62],[1,6.4,224.55],[2,6.6,275.1]],"ltp":5.5,"tv":30811.14,"id":2497008}]}]}
{"op":"mcm","clk":"4299594855","pt":1632581262823,"mc":[{"id":"1.188136695","rc":[{"batb":[[1,1.19,3416.95],[2,1.18,2144.65]],"ltp":1.2,"tv":183101.19,"id":5300737},{"batl":[[0,6.2,279.62]],"ltp":5.5,"tv":30811.14,"id":2497008}]}]}
{"op":"mcm","clk":"4299595125","pt":1632581263823,"mc":[{"id":"1.188136695","rc":[{"batb":[[0,1.2,1465.79],[1,1.19,3285.21],[2,1.18,1352.36]],"ltp":1.2,"tv":183101.19,"id":5300737},{"batb":[[0,5.7,45.71],[1,5.5,130.93],[2,5.4,70.76]],"ltp":5.5,"tv":30811.14,"id":2497008}]}]}
{"op":"mcm","clk":"4299595160","pt":1632581263927,"mc":[{"id":"1.188136695","rc":[{"batl":[[0,1.22,1815.33]],"ltp":1.2,"tv":183101.19,"id":5300737},{"batb":[[1,5.6,9.88],[2,5.5,130.93]],"ltp":5.5,"tv":30811.14,"id":2497008}]}]}
{"op":"mcm","clk":"4299595590","pt":1632581265521,"mc":[{"id":"1.188136695","rc":[{"batb":[[0,1.21,158.33],[1,1.2,1870.49],[2,1.19,3285.21]],"batl":[[0,1.22,2998.74]],"ltp":1.2,"tv":183101.19,"id":5300737},{"batl":[[1,6.4,355.82]],"ltp":5.5,"tv":30811.14,"id":2497008}]}]}
{"op":"mcm","clk":"4299609616","pt":1632581266197,"mc":[{"id":"1.188136695","rc":[{"batb":[[1,1.2,2001.13]],"ltp":1.2,"tv":183101.19,"id":5300737},{"batl":[[0,6.2,295.44]],"ltp":5.5,"tv":30811.14,"id":2497008}]}]}
{"op":"mcm","clk":"4299609945","pt":1632581267459,"mc":[{"id":"1.188136695","rc":[{"trd":[[1.2,7972.43],[1.21,1978.08]],"batb":[[0,1.19,3285.21],[1,1.18,1351.57],[2,1.17,2325.98]],"batl":[[0,1.2,231.16],[1,1.22,2998.74],[2,1.23,1709.04]],"ltp":1.2,"tv":187420.11,"id":5300737}],"tv":218231.26}]}
{"op":"mcm","clk":"4299610205","pt":1632581268550,"mc":[{"id":"1.188136695","rc":[{"trd":[[1.2,8450.82]],"batb":[[0,1.2,333.36],[1,1.19,3113.78],[2,1.18,1607.47]],"batl":[[0,1.22,2998.74],[1,1.23,1909.54],[2,1.24,475.19]],"ltp":1.2,"tv":187898.5,"id":5300737},{"batl":[[0,6,114.51],[1,6.2,295.44],[2,6.4,370.29]],"ltp":5.5,"tv":30811.14,"id":2497008}],"tv":218709.64}]}
{"op":"mcm","clk":"4299610473","pt":1632581269742,"mc":[{"id":"1.188136695","rc":[{"batb":[[0,1.21,10],[1,1.2,333.36],[2,1.19,3113.78]],"batl":[[0,1.22,3619.3],[1,1.23,2566.95]],"ltp":1.2,"tv":187898.5,"id":5300737},{"batb":[[2,5.5,268.57]],"ltp":5.5,"tv":30811.14,"id":2497008}]}]}
{"op":"mcm","clk":"4299610604","pt":1632581270339,"mc":[{"id":"1.188136695","rc":[{"batl":[[2,6.4,369.73]],"ltp":5.5,"tv":30811.14,"id":2497008}]}]}
{"op":"mcm","clk":"4299610771","pt":1632581271352,"mc":[{"id":"1.188136695","rc":[{"trd":[[1.21,1980.79],[1.22,447.32]],"batb":[[0,1.21,7.29]],"batl":[[0,1.22,3615.01]],"ltp":1.21,"tv":187909.78,"id":5300737},{"trd":[[5.8,27.65]],"ltp":5.8,"tv":30811.71,"id":2497008}],"tv":218721.5}]}
{"op":"mcm","clk":"4299611233","pt":1632581273251,"mc":[{"id":"1.188136695","rc":[{"batb":[[0,1.21,181.04]],"batl":[[0,1.22,3796.67]],"ltp":1.21,"tv":187909.78,"id":5300737}]}]}
{"op":"mcm","clk":"4299611717","pt":1632581275445,"mc":[{"id":"1.188136695","rc":[{"batl":[[0,6,80.37]],"ltp":5.8,"tv":30811.71,"id":2497008}]}]}
{"op":"mcm","clk":"4299612010","pt":1632581276696,"mc":[{"id":"1.188136695","rc":[{"trd":[[1.2,8546.98],[1.21,2342.87]],"batb":[[0,1.18,306.38],[1,1.17,2294.01],[2,1.16,516.91]],"batl":[[0,1.22,1365.07],[1,1.24,191.23],[2,1.25,6.37]],"ltp":1.2,"tv":188368.02,"id":5300737},{"batb":[[0,5.5,130.93],[1,5.1,4.44],[2,5,164.28]],"batl":[[0,6.6,58.27],[1,6.8,49.83],[2,7,72.41]],"ltp":5.8,"tv":30811.71,"id":2497008}],"tv":219179.73}]}
{"op":"mcm","clk":"4299612243","pt":1632581277456,"mc":[{"id":"1.188136695","rc":[{"batb":[[0,1.18,290.38]],"batl":[[0,1.24,191.23],[1,1.26,408.51],[2,1.27,342.68]],"ltp":1.2,"tv":188368.02,"id":5300737},{"batb":[[0,5.1,4.44],[1,5,164.28],[2,4.8,66.02]],"batl":[[0,5.7,1.24],[1,6.6,58.27],[2,6.8,49.83]],"ltp":5.8,"tv":30811.71,"id":2497008}]}]}
{"op":"mcm","clk":"4299612393","pt":1632581277948,"mc":[{"id":"1.188136695","rc":[{"batl":[[0,1.26,408.51],[1,1.27,342.68],[2,1.28,311.01]],"ltp":1.2,"tv":188368.02,"id":5300737},{"batb":[[0,5,164.28],[1,4.8,66.02],[2,4.7,77.38]],"ltp":5.8,"tv":30811.71,"id":2497008}]}]}
{"op":"mcm","clk":"4299612858","pt":1632581279768,"mc":[{"id":"1.188136695","rc":[{"trd":[[1.21,2348.72]],"batb":[[1,1.17,3216.42],[2,1.16,2891.4]],"batl":[[0,1.21,1027.21],[1,1.22,10],[2,1.24,921.54]],"ltp":1.21,"tv":188373.87,"id":5300737},{"trd":[[5.7,30.03]],"batb":[[0,5.5,3],[1,5.4,2],[2,5,164.28]],"batl":[[0,6.6,58.27],[1,6.8,49.83],[2,7,72.41]],"ltp":5.7,"tv":30812.95,"id":2497008}],"tv":219186.82}]}
{"op":"mcm","clk":"4299613106","pt":1632581280763,"mc":[{"id":"1.188136695","rc":[{"batb":[[0,1.18,262.36],[1,1.17,537.64],[2,1.16,2348.2]],"batl":[[0,1.21,4.01],[2,1.23,6]],"ltp":1.21,"tv":188373.87,"id":5300737},{"batb":[[2,5.2,152.61]],"ltp":5.7,"tv":30812.95,"id":2497008}]}]}
{"op":"mcm","clk":"4299613333","pt":1632581281662,"mc":[{"id":"1.188136695","rc":[{"trd":[[1.21,2353.45]],"batl":[[0,1.22,10.18],[1,1.23,6],[2,1.24,5]],"ltp":1.21,"tv":188378.6,"id":5300737},{"trd":[[5.7,30.59]],"ltp":5.7,"tv":30813.51,"id":2497008}],"tv":219192.12}]}
{"op":"mcm","clk":"4299613496","pt":1632581282264,"mc":[{"id":"1.188136695","rc":[{"trd":[[1.21,2353.64]],"batl":[[0,1.22,10]],"ltp":1.21,"tv":188378.79,"id":5300737},{"trd":[[5.7,30.63]],"batl":[[0,5.7,35.6],[1,6.6,58.27],[2,6.8,49.83]],"ltp":5.7,"tv":30813.54,"id":2497008}],"tv":219192.34}]}
{"op":"mcm","clk":"4299613890","pt":1632581283692,"mc":[{"id":"1.188136695","rc":[{"trd":[[1.21,2521.33]],"batb":[[0,1.19,1252.16],[1,1.18,2346.15],[2,1.17,537.64]],"batl":[[0,1.21,992.52],[1,1.22,1579.27],[2,1.23,6]],"ltp":1.21,"tv":188546.48,"id":5300737},{"trd":[[5.7,66.23]],"batl":[[0,6.6,58.27],[1,6.8,49.83],[2,7,72.41]],"ltp":5.7,"tv":30849.14,"id":2497008}],"tv":219395.63}]}
{"op":"mcm","clk":"4299614162","pt":1632581284694,"mc":[{"id":"1.188136695","rc":[{"trd":[[1.21,2522.03]],"batb":[[0,1.19,1295.18]],"batl":[[0,1.21,992.17],[1,1.22,2531.53]],"ltp":1.21,"tv":188547.18,"id":5300737},{"batb":[[0,5.6,14.97],[1,5.5,3],[2,5.4,2]],"batl":[[0,6.4,11.81],[1,6.6,58.27],[2,6.8,49.83]],"ltp":5.7,"tv":30849.14,"id":2497008}],"tv":219396.33}]}
{"op":"mcm","clk":"4299614440","pt":1632581285649,"mc":[{"id":"1.188136695","rc":[{"batb":[[1,1.18,2348.04]],"batl":[[1,1.22,2582.43]],"ltp":1.21,"tv":188547.18,"id":5300737}]}]}
{"op":"mcm","clk":"4299614710","pt":1632581286674,"mc":[{"id":"1.188136695","rc":[{"batb":[[0,5.6,2]],"ltp":5.7,"tv":30849.14,"id":2497008}]}]}
{"op":"mcm","clk":"4299615005","pt":1632581287767,"mc":[{"id":"1.188136695","rc":[{"batb":[[0,1.18,264.25],[1,1.17,537.64],[2,1.16,2348.2]],"batl":[[0,1.21,1130.03],[1,1.22,10]],"ltp":1.21,"tv":188547.18,"id":5300737},{"batl":[[0,6.6,58.27],[1,6.8,49.83],[2,7,72.41]],"ltp":5.7,"tv":30849.14,"id":2497008}]}]}
{"op":"mcm","clk":"4299615074","pt":1632581288081,"mc":[{"id":"1.188136695","rc":[{"batb":[[0,1.2,100],[1,1.18,264.25],[2,1.17,537.64]],"batl":[[0,1.22,10.87],[1,1.23,6],[2,1.24,210.98]],"ltp":1.21,"tv":188547.18,"id":5300737}]}]}
{"op":"mcm","clk":"4299615470","pt":1632581289565,"mc":[{"id":"1.188136695","rc":[{"trd":[[1.21,2523.77]],"batb":[[0,1.21,29.13],[1,1.2,100],[2,1.18,264.25]],"batl":[[0,1.22,10]],"ltp":1.21,"tv":188548.92,"id":5300737},{"batb":[[0,5.7,14.97],[1,5.6,2],[2,5.5,3]],"ltp":5.7,"tv":30849.14,"id":2497008}],"tv":219398.07}]}
{"op":"mcm","clk":"4299615750","pt":1632581290689,"mc":[{"id":"1.188136695","rc":[{"batl":[[2,1.24,1064.42]],"ltp":1.21,"tv":188548.92,"id":5300737},{"batb":[[0,5.6,2],[1,5.5,3],[2,5.4,2]],"ltp":5.7,"tv":30849.14,"id":2497008}]}]}
{"op":"mcm","clk":"4299616300","pt":1632581292781,"mc":[{"id":"1.188136695","rc":[{"batb":[[0,1.21,51.68],[2,1.18,4.07]],"ltp":1.21,"tv":188548.92,"id":5300737},{"batb":[[1,5.2,152.61],[2,5.1,6.54]],"batl":[[0,6.6,5.83],[1,7.8,6.17],[2,8.8,1]],"ltp":5.7,"tv":30849.14,"id":2497008}]}]}
{"op":"mcm","clk":"4299616422","pt":1632581293275,"mc":[{"id":"1.188136695","rc":[{"batl":[[0,1.24,1059.42],[1,1.25,1586.52],[2,1.26,408.51]],"ltp":1.21,"tv":188548.92,"id":5300737},{"batb":[[2,5.1,3.54]],"ltp":5.7,"tv":30849.14,"id":2497008}]}]}
{"op":"mcm","clk":"4299616799","pt":1632581294682,"mc":[{"id":"1.188136695","rc":[{"trd":[[1.22,456.5]],"batb":[[0,1.23,432.84],[1,1.21,2273.68],[2,1.2,100]],"batl":[[1,1.25,1581.52]],"ltp":1.22,"tv":188558.1,"id":5300737},{"trd":[[5.6,2]],"batb":[[0,5.2,152.61],[1,5.1,3.54],[2,4.8,66.02]],"ltp":5.6,"tv":30851.14,"id":2497008}],"tv":219409.25}]}
{"op":"mcm","clk":"4299617122","pt":1632581295784,"mc":[{"id":"1.188136695","rc":[{"batb":[[1,1.22,1159.85],[2,1.21,5426.93]],"ltp":1.22,"tv":188558.1,"id":5300737},{"trd":[[5.2,37.32]],"batb":[[0,5.2,144.1],[2,4.8,424.62]],"batl":[[0,6.4,20.94],[1,6.6,5.64],[2,6.8,1.71]],"ltp":5.2,"tv":30868.16,"id":2497008}],"tv":219426.27}]}
{"op":"mcm","clk":"4299617389","pt":1632581296772,"mc":[{"id":"1.188136695","rc":[{"trd":[[1.23,700.37]],"batb":[[0,1.23,403.4],[2,1.21,6777.63]],"batl":[[0,1.24,1070.42]],"ltp":1.23,"tv":188608.21,"id":5300737},{"trd":[[5.4,4]],"batb":[[2,4.9,175.95]],"batl":[[0,5.3,2],[1,6.4,20.94],[2,6.6,5.64]],"ltp":5.4,"tv":30870.16,"id":2497008}],"tv":219478.38}]}
{"op":"mcm","clk":"4299617621","pt":1632581297581,"mc":[{"id":"1.188136695","rc":[{"trd":[[1.23,704.76]],"batb":[[0,1.23,1351.27],[2,1.21,6852.92]],"batl":[[0,1.24,1059.42]],"ltp":1.23,"tv":188612.6,"id":5300737},{"trd":[[5.3,23.53],[5.4,5]],"batb":[[0,5.2,147.1],[1,5.1,6.54]],"batl":[[0,6.4,50.14],[1,6.6,5.64],[2,6.8,1.71]],"ltp":5.4,"tv":30875.16,"id":2497008}],"tv":219487.77}]}
{"op":"mcm","clk":"4299617907","pt":1632581298787,"mc":[{"id":"1.188136695","rc":[{"batb":[[0,1.23,952.26],[1,1.22,1164.03],[2,1.21,4630.92]],"batl":[[0,1.24,853.44]],"ltp":1.23,"tv":188612.6,"id":5300737},{"batb":[[0,5.2,144.1],[1,4.9,175.95],[2,4.8,424.62]],"batl":[[0,5.6,18.79],[1,6.4,20.94],[2,6.6,5.64]],"ltp":5.4,"tv":30875.16,"id":2497008}]}]}
{"op":"mcm","clk":"4299618147","pt":1632581299799,"mc":[{"id":"1.188136695","rc":[{"batb":[[0,1.23,276.21]],"batl":[[0,1.24,2497.86]],"ltp":1.23,"tv":188612.6,"id":5300737}]}]}
{"op":"mcm","clk":"4299618323","pt":1632581300480,"mc":[{"id":"1.188136695","rc":[{"batb":[[1,1.22,1167.24]],"batl":[[2,1.26,406.8]],"ltp":1.23,"tv":188612.6,"id":5300737}]}]}
{"op":"mcm","clk":"4299618598","pt":1632581301580,"mc":[{"id":"1.188136695","rc":[{"trd":[[1.24,7513.72]],"batl":[[0,1.24,2412.05]],"ltp":1.24,"tv":188784.22,"id":5300737}],"tv":219659.39}]}
{"op":"mcm","clk":"4299618845","pt":1632581302481,"mc":[{"id":"1.188136695","rc":[{"trd":[[1.24,7713.72]],"batl":[[0,1.24,2312.05]],"ltp":1.24,"tv":188984.22,"id":5300737},{"batb":[[1,5,4.53],[2,4.9,175.95]],"batl":[[1,5.8,57.19],[2,5.9,60.05]],"ltp":5.4,"tv":30875.16,"id":2497008}],"tv":219859.39}]}
{"op":"mcm","clk":"4299619074","pt":1632581303390,"mc":[{"id":"1.188136695","rc":[{"trd":[[1.23,908.81]],"batb":[[0,1.23,678.17],[1,1.22,1726.18],[2,1.21,4629.48]],"ltp":1.23,"tv":189188.27,"id":5300737},{"batl":[[0,5.4,114.79],[1,5.6,141.47],[2,5.8,57.19]],"ltp":5.4,"tv":30875.16,"id":2497008}],"tv":220063.44}]}
{"op":"mcm","clk":"4299619342","pt":1632581304484,"mc":[{"id":"1.188136695","rc":[{"batb":[[1,1.22,1739.82]],"batl":[[0,1.24,2820.32],[1,1.25,2180.65]],"ltp":1.23,"tv":189188.27,"id":5300737},{"batb":[[1,5.1,123.58],[2,5,154.31]],"batl":[[1,5.6,170.67],[2,5.8,56.99]],"ltp":5.4,"tv":30875.16,"id":2497008}]}]}
{"op":"mcm","clk":"4299619705","pt":1632581305777,"mc":[{"id":"1.188136695","rc":[{"trd":[[1.23,1254.67]],"batb":[[0,1.23,505.24],[2,1.21,4606.93]],"ltp":1.23,"tv":189534.13,"id":5300737},{"batl":[[1,5.6,166.91]],"ltp":5.4,"tv":30875.16,"id":2497008}],"tv":220409.3}]}
{"op":"mcm","clk":"4299619943","pt":1632581306681,"mc":[{"id":"1.188136695","rc":[{"trd":[[1.23,1255.07]],"batb":[[0,1.23,505.04],[1,1.22,1739.62]],"batl":[[0,1.24,2927.44]],"ltp":1.23,"tv":189534.53,"id":5300737}],"tv":220409.7}]}
{"op":"mcm","clk":"4299620195","pt":1632581307704,"mc":[{"id":"1.188136695","rc":[{"trd":[[1.24,7714.23]],"batb":[[0,1.23,764.35],[1,1.22,1614.62]],"batl":[[0,1.24,3184.33]],"ltp":1.24,"tv":189535.03,"id":5300737}],"tv":220410.2}]}
{"op":"mcm","clk":"4299620277","pt":1632581307986,"mc":[{"id":"1.188136695","rc":[{"batb":[[0,1.23,260.37]],"batl":[[0,1.24,2927.19]],"ltp":1.24,"tv":189535.03,"id":5300737}]}]}
{"op":"mcm","clk":"4299620717","pt":1632581309798,"mc":[{"id":"1.188136695","rc":[{"trd":[[1.23,1775.8]],"batb":[[0,1.22,1611.62],[1,1.21,4531.64],[2,1.2,1673.53]],"batl":[[0,1.23,984.13],[1,1.24,2927.19],[2,1.25,2180.65]],"ltp":1.23,"tv":190055.76,"id":5300737},{"batl":[[1,5.6,151.88]],"ltp":5.4,"tv":30875.16,"id":2497008}],"tv":220930.93}]}
{"op":"mcm","clk":"4299620923","pt":1632581310715,"mc":[{"id":"1.188136695","rc":[{"trd":[[1.23,1775.97]],"batl":[[0,1.23,984.04],[1,1.24,2639.1]],"ltp":1.23,"tv":190055.94,"id":5300737}],"tv":220931.1}]}
{"op":"mcm","clk":"4299621204","pt":1632581311795,"mc":[{"id":"1.188136695","rc":[{"trd":[[1.23,1804.76]],"batl":[[0,1.23,968.9]],"ltp":1.23,"tv":190084.72,"id":5300737},{"trd":[[5.3,23.88]],"batl":[[0,5.6,133.27],[1,5.8,56.99],[2,5.9,60.05]],"ltp":5.3,"tv":30875.51,"id":2497008}],"tv":220960.24}]}
{"op":"mcm","clk":"4299621458","pt":1632581312680,"mc":[{"id":"1.188136695","rc":[{"trd":[[1.23,1805.6]],"batl":[[0,1.23,1984.74]],"ltp":1.23,"tv":190085.56,"id":5300737}],"tv":220961.08}]}
{"op":"mcm","clk":"4299621695","pt":1632581313709,"mc":[{"id":"1.188136695","rc":[{"trd":[[1.23,1973.61]],"batb":[[0,1.22,13.64],[1,1.21,29.13],[2,1.2,292.85]],"batl":[[0,1.23,883.79],[1,1.24,458.76],[2,1.25,227.58]],"ltp":1.23,"tv":190253.57,"id":5300737},{"trd":[[5.3,24.19]],"batb":[[0,5.1,4.14],[1,5,4.53],[2,4.9,175.95]],"batl":[[0,5.8,56.99],[1,5.9,60.05],[2,6,74.71]],"ltp":5.3,"tv":30875.83,"id":2497008}],"tv":221129.41}]}
{"op":"mcm","clk":"4299621747","pt":1632581313918,"mc":[{"id":"1.188136695","rc":[{"batb":[[2,1.2,284.85]],"ltp":1.23,"tv":190253.57,"id":5300737}]}]}
{"op":"mcm","clk":"4299622242","pt":1632581315820,"mc":[{"id":"1.188136695","rc":[{"trd":[[1.23,2026.13]],"batl":[[0,1.23,857.53]],"ltp":1.23,"tv":190306.09,"id":5300737}],"tv":221181.92}]}
{"op":"mcm","clk":"4299622461","pt":1632581316726,"mc":[{"id":"1.188136695","rc":[{"trd":[[1.23,2033.15]],"batb":[[2,1.2,935.94]],"batl":[[0,1.23,854.02]],"ltp":1.23,"tv":190313.12,"id":5300737},{"batl":[[0,5.7,2],[1,5.8,56.99],[2,5.9,60.05]],"ltp":5.3,"tv":30875.83,"id":2497008}],"tv":221188.95}]}
{"op":"mcm","clk":"4299622621","pt":1632581317491,"mc":[{"id":"1.188136695","rc":[{"trd":[[1.23,2033.99]],"batb":[[1,1.2,935.94],[2,1.19,3872.33]],"batl":[[0,1.23,853.6]],"ltp":1.23,"tv":190313.96,"id":5300737},{"batb":[[2,4.8,180.99]],"batl":[[0,5.8,56.99],[1,5.9,60.05],[2,6,74.71]],"ltp":5.3,"tv":30875.83,"id":2497008}],"tv":221189.79}]}
{"op":"mcm","clk":"4299622958","pt":1632581318713,"mc":[{"id":"1.188136695","rc":[{"trd":[[1.23,2111.04]],"batl":[[0,1.23,806.98]],"ltp":1.23,"tv":190391.01,"id":5300737},{"trd":[[5.3,27.95]],"ltp":5.3,"tv":30879.58,"id":2497008}],"tv":221270.6}]}
{"op":"mcm","clk":"4299623202","pt":1632581319621,"mc":[{"id":"1.188136695","rc":[{"trd":[[1.23,2918.02]],"batl":[[0,1.25,227.58],[1,1.26,906.26],[2,1.27,1280.17]],"ltp":1.23,"tv":191197.98,"id":5300737},{"trd":[[5.3,215.23]],"batb":[[0,5,4.53],[1,4.8,180.99],[2,4.5,207.67]],"batl":[[0,5.2,812.72],[1,5.8,56.99],[2,5.9,60.05]],"ltp":5.3,"tv":31066.86,"id":2497008}],"tv":222264.85}]}
{"op":"mcm","clk":"4299623489","pt":1632581320713,"mc":[{"id":"1.188136695","rc":[{"trd":[[1.25,3771.12]],"batb":[[0,1.24,2654.84],[1,1.22,13.64],[2,1.2,935.94]],"batl":[[0,1.26,906.26],[1,1.27,1280.17],[2,1.28,290.47]],"ltp":1.25,"tv":191760.41,"id":5300737},{"trd":[[5,450.44]],"batb":[[0,4.8,180.99],[1,4.5,207.67],[2,4.4,88.6]],"ltp":5.0,"tv":31071.39,"id":2497008}],"tv":222831.8}]}
{"op":"mcm","clk":"4299623666","pt":1632581321359,"mc":[{"id":"1.188136695","rc":[{"batb":[[1,1.22,14.31]],"ltp":1.25,"tv":191760.41,"id":5300737}]}]}
{"op":"mcm","clk":"4299623980","pt":1632581322560,"mc":[{"id":"1.188136695","rc":[{"batb":[[1,1.23,237.92],[2,1.22,240.01]],"batl":[[1,1.27,1234.98]],"ltp":1.25,"tv":191760.41,"id":5300737},{"batl":[[1,5.3,15.03],[2,6.6,12.15]],"ltp":5.0,"tv":31071.39,"id":2497008}]}]}
{"op":"mcm","clk":"4299624257","pt":1632581323629,"mc":[{"id":"1.188136695","rc":[{"trd":[[1.24,8129.69]],"batb":[[0,1.24,432.84]],"batl":[[0,1.25,217.94],[1,1.26,731.01],[2,1.27,1234.98]],"ltp":1.24,"tv":192175.87,"id":5300737},{"batb":[[0,5,4.84],[1,4.8,176.71],[2,4.5,207.67]],"ltp":5.0,"tv":31071.39,"id":2497008}],"tv":223247.26}]}
{"op":"mcm","clk":"4299624550","pt":1632581324734,"mc":[{"id":"1.188136695","rc":[{"batb":[[1,1.23,239.12]],"batl":[[0,1.26,731.01],[1,1.27,1234.98],[2,1.28,290.47]],"ltp":1.24,"tv":192175.87,"id":5300737},{"batb":[[0,4.8,176.71],[1,4.5,207.67],[2,4.4,88.6]],"ltp":5.0,"tv":31071.39,"id":2497008}]}]}
{"op":"mcm","clk":"4299624812","pt":1632581325723,"mc":[{"id":"1.188136695","rc":[{"trd":[[1.26,1902.88]],"batb":[[0,1.24,1313.18],[1,1.23,4175.83],[2,1.22,1371.87]],"batl":[[0,1.25,65.04],[1,1.26,715.01],[2,1.27,1234.98]],"ltp":1.26,"tv":192207.87,"id":5300737},{"trd":[[4.8,62.14]],"batb":[[0,4.9,22.02],[1,4.8,163.82],[2,4.6,197.17]],"batl":[[2,6.2,1.71]],"ltp":4.8,"tv":31097.17,"id":2497008}],"tv":223305.04}]}
{"op":"mcm","clk":"4299624949","pt":1632581326304,"mc":[{"id":"1.188136695","rc":[{"batb":[[0,1.24,1832.6]],"batl":[[0,1.26,715.01],[1,1.27,1234.98],[2,1.28,290.47]],"ltp":1.26,"tv":192207.87,"id":5300737},{"batb":[[0,4.8,163.82],[1,4.6,197.17],[2,4.5,590.17]],"ltp":4.8,"tv":31097.17,"id":2497008}]}]}
{"op":"mcm","clk":"4299625352","pt":1632581327823,"mc":[{"id":"1.188136695","rc":[{"trd":[[1.26,1905.76]],"batl":[[0,1.26,713.57]],"ltp":1.26,"tv":192210.75,"id":5300737},{"batl":[[0,5.2,9.25]],"ltp":4.8,"tv":31097.17,"id":2497008}],"tv":223307.92}]}
