{"op":"mcm","clk":"4299011423","pt":1632579421827,"mc":[{"id":"1.188136695","rc":[{"trd":[[1.96,619.09],[2,4699.39]],"batl":[[0,2.04,1573.86],[1,2.1,13.26],[2,2.12,51.29]],"ltp":2.0,"tv":12065.18,"id":5300737},{"trd":[[2,3846.06],[2.04,170.68]],"batb":[[0,1.97,137.16],[1,1.96,11.5],[2,1.95,27.07]],"batl":[[0,2,36.11],[1,2.04,1205.46],[2,2.3,6.05]],"ltp":2.0,"tv":19833.04,"id":2497008}],"tv":31898.22}]}
{"op":"mcm","clk":"4299011662","pt":1632579422531,"mc":[{"id":"1.188136695","rc":[{"batb":[[0,1.95,207.21]],"ltp":2.0,"tv":12065.18,"id":5300737},{"batb":[[0,1.97,82.45],[2,1.94,428.56]],"ltp":2.0,"tv":19833.04,"id":2497008}]}]}
{"op":"mcm","clk":"4299012452","pt":1632579424536,"mc":[{"id":"1.188136695","rc":[{"batl":[[0,2.04,1383.64]],"ltp":2.0,"tv":12065.18,"id":5300737}]}]}
{"op":"mcm","clk":"4299013926","pt":1632579428452,"mc":[{"id":"1.188136695","rc":[{"batb":[[0,1.96,182.12],[1,1.95,207.21],[2,1.93,799.34]],"ltp":2.0,"tv":12065.18,"id":5300737},{"batb":[[0,1.99,184.24],[1,1.97,82.45],[2,1.96,11.5]],"ltp":2.0,"tv":19833.04,"id":2497008}]}]}
{"op":"mcm","clk":"4299014250","pt":1632579429361,"mc":[{"id":"1.188136695","rc":[{"trd":[[1.96,718.29],[2,4735.5]],"batb":[[0,1.96,132.52],[1,1.95,180.15],[2,1.94,27.35]],"ltp":1.96,"tv":12200.49,"id":5300737},{"trd":[[2,3882.17]],"batl":[[0,2.04,1205.46],[1,2.3,6.05],[2,2.42,7.31]],"ltp":2.0,"tv":19869.15,"id":2497008}],"tv":32069.64}]}
{"op":"mcm","clk":"4299014605","pt":1632579430367,"mc":[{"id":"1.188136695","rc":[{"batb":[[2,1.93,799.34]],"ltp":1.96,"tv":12200.49,"id":5300737}]}]}
{"op":"mcm","clk":"4299015782","pt":1632579433799,"mc":[{"id":"1.188136695","rc":[{"batb":[[0,1.96,205.65]],"batl":[[0,2.04,1184.07]],"ltp":1.96,"tv":12200.49,"id":5300737}]}]}
{"op":"mcm","clk":"4299016026","pt":1632579434421,"mc":[{"id":"1.188136695","rc":[{"batb":[[0,1.96,132.52]],"batl":[[0,2.04,1337.6]],"ltp":1.96,"tv":12200.49,"id":5300737},{"batl":[[0,2.04,1447.58]],"ltp":2.0,"tv":19869.15,"id":2497008}]}]}
{"op":"mcm","clk":"4299017625","pt":1632579438813,"mc":[{"id":"1.188136695","rc":[{"batb":[[1,1.93,799.34],[2,1.92,27.95]],"ltp":1.96,"tv":12200.49,"id":5300737},{"batb":[[0,1.99,273.89],[1,1.96,11.5],[2,1.95,27.07]],"ltp":2.0,"tv":19869.15,"id":2497008}]}]}
{"op":"mcm","clk":"4299017926","pt":1632579439633,"mc":[{"id":"1.188136695","rc":[{"batb":[[1,1.98,138],[2,1.96,11.5]],"batl":[[0,2.04,1205.46]],"ltp":2.0,"tv":19869.15,"id":2497008}]}]}
{"op":"mcm","clk":"4299020409","pt":1632579445896,"mc":[{"id":"1.188136695","rc":[{"trd":[[1.96,769.03]],"batb":[[0,1.96,107.16]],"ltp":1.96,"tv":12251.22,"id":5300737}],"tv":32120.37}]}
{"op":"mcm","clk":"4299021720","pt":1632579448709,"mc":[{"id":"1.188136695","rc":[{"batb":[[0,2,183.05],[1,1.99,90.41],[2,1.98,138]],"ltp":2.0,"tv":19869.15,"id":2497008}]}]}
{"op":"mcm","clk":"4299022245","pt":1632579449798,"mc":[{"id":"1.188136695","rc":[{"batl":[[0,2.04,1184.07]],"ltp":1.96,"tv":12251.22,"id":5300737},{"batb":[[1,1.98,138],[2,1.96,11.5]],"ltp":2.0,"tv":19869.15,"id":2497008}]}]}
{"op":"mcm","clk":"4299025059","pt":1632579457049,"mc":[{"id":"1.188136695","rc":[{"batb":[[0,1.96,189.28]],"ltp":1.96,"tv":12251.22,"id":5300737},{"batl":[[0,2.04,1213.59]],"ltp":2.0,"tv":19869.15,"id":2497008}]}]}
{"op":"mcm","clk":"4299025498","pt":1632579458442,"mc":[{"id":"1.188136695","rc":[{"trd":[[1.96,772.39]],"batb":[[0,1.96,187.59]],"ltp":1.96,"tv":12254.59,"id":5300737}],"tv":32123.74}]}
{"op":"mcm","clk":"4299025837","pt":1632579459470,"mc":[{"id":"1.188136695","rc":[{"trd":[[1.96,855.13]],"batb":[[0,1.96,183.32]],"ltp":1.96,"tv":12337.33,"id":5300737}],"tv":32206.48}]}
{"op":"mcm","clk":"4299027243","pt":1632579463763,"mc":[{"id":"1.188136695","rc":[{"trd":[[2,4737.26]],"ltp":2.0,"tv":12339.09,"id":5300737},{"trd":[[2,3883.93]],"batb":[[0,2,181.29]],"ltp":2.0,"tv":19870.91,"id":2497008}],"tv":32210.0}]}
{"op":"mcm","clk":"4299027548","pt":1632579464754,"mc":[{"id":"1.188136695","rc":[{"trd":[[2,4742.26]],"ltp":2.0,"tv":12344.09,"id":5300737},{"trd":[[1.99,798.62],[2,4246.52]],"batb":[[0,1.98,138],[1,1.96,11.5],[2,1.95,27.07]],"batl":[[0,1.99,51.66],[1,2.04,1205.46],[2,2.3,6.05]],"ltp":1.99,"tv":20246.8,"id":2497008}],"tv":32590.89}]}
{"op":"mcm","clk":"4299027747","pt":1632579465394,"mc":[{"id":"1.188136695","rc":[{"batb":[[0,2,7.51],[1,1.96,183.32],[2,1.93,799.34]],"ltp":2.0,"tv":12344.09,"id":5300737},{"trd":[[1.99,802.62]],"batb":[[2,1.94,428.56]],"batl":[[0,1.99,49.65]],"ltp":1.99,"tv":20250.8,"id":2497008}],"tv":32594.89}]}
{"op":"mcm","clk":"4299028062","pt":1632579466383,"mc":[{"id":"1.188136695","rc":[{"batb":[[2,1.95,27.07]],"ltp":2.0,"tv":12344.09,"id":5300737}]}]}
{"op":"mcm","clk":"4299028870","pt":1632579468761,"mc":[{"id":"1.188136695","rc":[{"trd":[[1.99,901.93]],"batl":[[0,2.04,1232.77],[1,2.3,6.05],[2,2.42,7.31]],"ltp":1.99,"tv":20350.11,"id":2497008}],"tv":32694.2}]}
{"op":"mcm","clk":"4299029185","pt":1632579469684,"mc":[{"id":"1.188136695","rc":[{"batb":[[1,1.96,181.11],[2,1.93,826.99]],"ltp":2.0,"tv":12344.09,"id":5300737},{"batb":[[1,1.97,185.25],[2,1.96,11.5]],"ltp":1.99,"tv":20350.11,"id":2497008}]}]}
{"op":"mcm","clk":"4299029352","pt":1632579470193,"mc":[{"id":"1.188136695","rc":[{"batb":[[0,2,8.21]],"ltp":2.0,"tv":12344.09,"id":5300737}]}]}
{"op":"mcm","clk":"4299030679","pt":1632579474698,"mc":[{"id":"1.188136695","rc":[{"trd":[[1.99,268.65],[2,4759.29]],"batb":[[0,1.96,181.11],[1,1.93,826.99],[2,1.92,27.95]],"batl":[[0,1.99,28.77],[1,2.04,1184.07],[2,2.1,13.26]],"ltp":1.99,"tv":12365.11,"id":5300737},{"trd":[[2,4248.52]],"ltp":2.0,"tv":20352.11,"id":2497008}],"tv":32717.22}]}
{"op":"mcm","clk":"4299030875","pt":1632579475302,"mc":[{"id":"1.188136695","rc":[{"batb":[[1,1.93,799.34]],"ltp":1.99,"tv":12365.11,"id":5300737}]}]}
{"op":"mcm","clk":"4299031243","pt":1632579476501,"mc":[{"id":"1.188136695","rc":[{"batl":[[1,2,433.37],[2,2.04,1184.07]],"ltp":1.99,"tv":12365.11,"id":5300737}]}]}
{"op":"mcm","clk":"4299031858","pt":1632579478472,"mc":[{"id":"1.188136695","rc":[{"batl":[[1,2,447.01]],"ltp":1.99,"tv":12365.11,"id":5300737}]}]}
{"op":"mcm","clk":"4299032487","pt":1632579480591,"mc":[{"id":"1.188136695","rc":[{"trd":[[1.99,271.95]],"batl":[[0,1.99,25.47]],"ltp":1.99,"tv":12368.41,"id":5300737},{"trd":[[2,4251.8]],"ltp":2.0,"tv":20355.39,"id":2497008}],"tv":32723.8}]}
{"op":"mcm","clk":"4299032728","pt":1632579481330,"mc":[{"id":"1.188136695","rc":[{"trd":[[1.99,272.79]],"batl":[[0,1.99,25.05]],"ltp":1.99,"tv":12369.25,"id":5300737}],"tv":32724.64}]}
{"op":"mcm","clk":"4299033020","pt":1632579482116,"mc":[{"id":"1.188136695","rc":[{"trd":[[1.96,862.15]],"batb":[[0,1.96,177.6]],"ltp":1.96,"tv":12376.27,"id":5300737}],"tv":32731.66}]}
{"op":"mcm","clk":"4299033449","pt":1632579483396,"mc":[{"id":"1.188136695","rc":[{"trd":[[1.99,285.6]],"batl":[[0,1.99,18.65]],"ltp":1.99,"tv":12389.07,"id":5300737}],"tv":32744.47}]}
{"op":"mcm","clk":"4299033884","pt":1632579484686,"mc":[{"id":"1.188136695","marketDefinition":{"bspMarket":false,"turnInPlayEnabled":true,"persistenceEnabled":true,"marketBaseRate":5.0,"eventId":"30941535","eventTypeId":"2","numberOfWinners":1,"bettingType":"ODDS","marketType":"MATCH_ODDS","marketTime":"2021-09-25T14:00:00.000Z","suspendTime":"2021-09-25T14:00:00.000Z","bspReconciled":false,"complete":true,"inPlay":false,"crossMatching":true,"runnersVoidable":false,"numberOfActiveRunners":2,"betDelay":0,"status":"OPEN","runners":[{"status":"ACTIVE","sortPriority":1,"id":5300737,"name":"Anett Kontaveit"},{"status":"ACTIVE","sortPriority":2,"id":2497008,"name":"Petra Kvitova"}],"regulators":["MR_INT"],"discountAllowed":true,"timezone":"UTC","openDate":"2021-09-25T14:00:00.000Z","version":4055271143,"name":"Match Odds","eventName":"Kontaveit v Kvitova"},"rc":[{"trd":[[1.99,285.95]],"batb":[[0,1.93,799.34],[1,1.92,27.95],[2,1.9,5]],"batl":[[0,1.99,18.3],[1,2,553.2]],"ltp":1.99,"tv":12389.43,"id":5300737},{"trd":[[2,4252.15]],"batb":[[1,1.96,11.5],[2,1.95,27.07]],"ltp":2.0,"tv":20355.74,"id":2497008}],"tv":32745.17}]}
{"op":"mcm","clk":"4299034213","pt":1632579485640,"mc":[{"id":"1.188136695","marketDefinition":{"bspMarket":false,"turnInPlayEnabled":true,"persistenceEnabled":true,"marketBaseRate":5.0,"eventId":"30941535","eventTypeId":"2","numberOfWinners":1,"bettingType":"ODDS","marketType":"MATCH_ODDS","marketTime":"2021-09-25T14:00:00.000Z","suspendTime":"2021-09-25T14:00:00.000Z","bspReconciled":false,"complete":true,"inPlay":true,"crossMatching":true,"runnersVoidable":false,"numberOfActiveRunners":2,"betDelay":3,"status":"OPEN","runners":[{"status":"ACTIVE","sortPriority":1,"id":5300737,"name":"Anett Kontaveit"},{"status":"ACTIVE","sortPriority":2,"id":2497008,"name":"Petra Kvitova"}],"regulators":["MR_INT"],"discountAllowed":true,"timezone":"UTC","openDate":"2021-09-25T14:00:00.000Z","version":4055663365,"name":"Match Odds","eventName":"Kontaveit v Kvitova"},"rc":[{"batb":[[0,1.93,796.43],[1,1.88,16.91],[2,1.7,21.93]],"batl":[[0,2.04,3.15],[1,2.1,13.26],[2,2.32,9.2]],"ltp":1.99,"tv":12389.43,"id":5300737},{"batb":[[0,1.93,21.43],[1,1.92,12.22],[2,1.91,21.43]],"batl":[[0,2.3,6.05],[1,4,0.86],[2,2.42,0]],"ltp":2.0,"tv":20355.74,"id":2497008}]}]}
{"op":"mcm","clk":"4299035017","pt":1632579487788,"mc":[{"id":"1.188136695","rc":[{"batb":[[0,1.92,12.22],[1,1.91,21.43],[2,1.9,16.91]],"ltp":2.0,"tv":20355.74,"id":2497008}]}]}
{"op":"mcm","clk":"4299035324","pt":1632579488709,"mc":[{"id":"1.188136695","rc":[{"batl":[[0,2,2.63],[1,2.3,6.05],[2,4,0.86]],"ltp":2.0,"tv":20355.74,"id":2497008}]}]}
{"op":"mcm","clk":"4299035614","pt":1632579489602,"mc":[{"id":"1.188136695","rc":[{"batl":[[0,2,3.62]],"ltp":2.0,"tv":20355.74,"id":2497008}]}]}
{"op":"mcm","clk":"4299035805","pt":1632579490211,"mc":[{"id":"1.188136695","rc":[{"trd":[[2,4762.91]],"batl":[[0,1.96,165.47],[1,2.04,3.15],[2,2.1,13.26]],"ltp":2.0,"tv":12393.04,"id":5300737},{"trd":[[2,4255.76]],"batl":[[0,2.3,6.05],[1,4,0.86],[2,4,0]],"ltp":2.0,"tv":20359.35,"id":2497008}],"tv":32752.4}]}
{"op":"mcm","clk":"4299036324","pt":1632579491676,"mc":[{"id":"1.188136695","rc":[{"trd":[[1.93,894.02]],"batb":[[0,1.93,349.42]],"ltp":1.93,"tv":13287.06,"id":5300737}],"tv":33646.42}]}
{"op":"mcm","clk":"4299036529","pt":1632579492321,"mc":[{"id":"1.188136695","rc":[{"trd":[[1.93,1592.86]],"batb":[[0,1.88,16.91],[1,1.7,21.93],[2,1.65,110]],"batl":[[0,1.93,169.14],[1,1.96,165.47],[2,2.04,3.15]],"ltp":1.93,"tv":13985.9,"id":5300737},{"batb":[[0,2.04,2222],[1,1.92,12.22],[2,1.91,21.43]],"ltp":2.0,"tv":20359.35,"id":2497008}],"tv":34345.26}]}
{"op":"mcm","clk":"4299037010","pt":1632579493810,"mc":[{"id":"1.188136695","rc":[{"batl":[[0,1.91,6327.42],[1,1.93,169.14],[2,1.96,165.47]],"ltp":1.93,"tv":13985.9,"id":5300737}]}]}
{"op":"mcm","clk":"4299037308","pt":1632579494814,"mc":[{"id":"1.188136695","rc":[{"batl":[[0,1.96,165.47],[1,2.04,3.15],[2,2.1,13.26]],"ltp":1.93,"tv":13985.9,"id":5300737}]}]}
{"op":"mcm","clk":"4299037556","pt":1632579495527,"mc":[{"id":"1.188136695","rc":[{"batb":[[1,1.85,217.38],[2,1.72,274.55]],"ltp":1.93,"tv":13985.9,"id":5300737},{"batb":[[0,2.08,307.51],[1,2.04,2222],[2,1.98,360.1]],"ltp":2.0,"tv":20359.35,"id":2497008}]}]}
{"op":"mcm","clk":"4299037825","pt":1632579496316,"mc":[{"id":"1.188136695","rc":[{"batb":[[1,1.98,360.1],[2,1.96,93.67]],"ltp":2.0,"tv":20359.35,"id":2497008}]}]}
{"op":"mcm","clk":"4299038272","pt":1632579497715,"mc":[{"id":"1.188136695","rc":[{"trd":[[1.88,33.64]],"batb":[[0,1.85,217.47],[1,1.72,274.55],[2,1.7,21.24]],"ltp":1.88,"tv":14019.54,"id":5300737},{"trd":[[2.08,3.96]],"batb":[[0,2.08,305.53]],"ltp":2.08,"tv":20363.31,"id":2497008}],"tv":34382.86}]}
{"op":"mcm","clk":"4299038615","pt":1632579498721,"mc":[{"id":"1.188136695","rc":[{"trd":[[1.88,67.93]],"batb":[[0,1.89,146.87],[1,1.85,217.38],[2,1.72,274.55]],"batl":[[0,1.95,158.88],[1,1.96,165.47],[2,2.04,3.15]],"ltp":1.88,"tv":14053.84,"id":5300737}],"tv":34417.15}]}
{"op":"mcm","clk":"4299038883","pt":1632579499534,"mc":[{"id":"1.188136695","rc":[{"trd":[[1.89,88.08]],"batb":[[0,1.89,102.83]],"batl":[[1,1.96,200.47]],"ltp":1.89,"tv":14141.92,"id":5300737}],"tv":34505.23}]}
{"op":"mcm","clk":"4299039628","pt":1632579501710,"mc":[{"id":"1.188136695","rc":[{"batb":[[0,1.86,157.93]],"ltp":1.89,"tv":14141.92,"id":5300737},{"trd":[[2.08,45.61]],"batb":[[0,2.08,284.71]],"ltp":2.08,"tv":20404.96,"id":2497008}],"tv":34546.88}]}
{"op":"mcm","clk":"4299040032","pt":1632579502781,"mc":[{"id":"1.188136695","rc":[{"trd":[[1.9,27.28]],"batb":[[0,1.9,137.24],[1,1.86,157.93],[2,1.85,217.38]],"ltp":1.9,"tv":14169.2,"id":5300737}],"tv":34574.16}]}
{"op":"mcm","clk":"4299040395","pt":1632579503740,"mc":[{"id":"1.188136695","rc":[{"batb":[[0,1.9,342.85]],"ltp":1.9,"tv":14169.2,"id":5300737}]}]}
{"op":"mcm","clk":"4299041792","pt":1632579507554,"mc":[{"id":"1.188136695","rc":[{"batb":[[0,1.9,463.52]],"ltp":1.9,"tv":14169.2,"id":5300737}]}]}
{"op":"mcm","clk":"4299042214","pt":1632579508717,"mc":[{"id":"1.188136695","rc":[{"trd":[[1.9,98.03]],"batb":[[0,1.9,307.47],[1,1.72,274.55],[2,1.7,21.24]],"batl":[[0,1.96,200.47],[1,2.04,3.15],[2,2.1,13.26]],"ltp":1.9,"tv":14239.94,"id":5300737},{"batb":[[0,1.98,360.1],[1,1.96,93.67],[2,1.92,97.93]],"ltp":2.08,"tv":20404.96,"id":2497008}],"tv":34644.91}]}
{"op":"mcm","clk":"4299042525","pt":1632579509640,"mc":[{"id":"1.188136695","rc":[{"batb":[[0,1.93,5.26],[1,1.9,307.47],[2,1.72,274.55]],"ltp":1.9,"tv":14239.94,"id":5300737}]}]}
{"op":"mcm","clk":"4299042928","pt":1632579510727,"mc":[{"id":"1.188136695","rc":[{"trd":[[1.9,712.97],[1.93,1603.38]],"batb":[[0,1.72,274.55],[1,1.7,21.24],[2,1.65,110]],"batl":[[0,1.87,146.91],[1,1.96,200.47],[2,2.04,3.15]],"ltp":1.9,"tv":14865.4,"id":5300737}],"tv":35270.37}]}
{"op":"mcm","clk":"4299043257","pt":1632579511608,"mc":[{"id":"1.188136695","rc":[{"batb":[[0,1.73,271.17],[1,1.72,273.86],[2,1.7,21.24]],"ltp":1.9,"tv":14865.4,"id":5300737}]}]}
{"op":"mcm","clk":"4299043617","pt":1632579512647,"mc":[{"id":"1.188136695","rc":[{"batb":[[1,1.7,21.24],[2,1.65,110]],"batl":[[1,1.9,46.48],[2,1.96,200.47]],"ltp":1.9,"tv":14865.4,"id":5300737},{"batb":[[0,1.98,182.46]],"ltp":2.08,"tv":20404.96,"id":2497008}]}]}
{"op":"mcm","clk":"4299043925","pt":1632579513532,"mc":[{"id":"1.188136695","rc":[{"batl":[[1,1.9,593.66]],"ltp":1.9,"tv":14865.4,"id":5300737}]}]}
{"op":"mcm","clk":"4299044379","pt":1632579514783,"mc":[{"id":"1.188136695","rc":[{"batb":[[0,1.78,5.69],[1,1.77,4],[2,1.76,5]],"ltp":1.9,"tv":14865.4,"id":5300737},{"batl":[[0,2.28,4.2],[1,2.3,9.85],[2,4,0.86]],"ltp":2.08,"tv":20404.96,"id":2497008}]}]}
{"op":"mcm","clk":"4299044621","pt":1632579515447,"mc":[{"id":"1.188136695","rc":[{"trd":[[1.87,1.76]],"batl":[[0,1.87,146.03]],"ltp":1.87,"tv":14867.16,"id":5300737}],"tv":35272.13}]}
{"op":"mcm","clk":"4299045269","pt":1632579517246,"mc":[{"id":"1.188136695","rc":[{"batb":[[0,1.83,570.19],[1,1.81,569.8],[2,1.78,5]],"batl":[[1,1.9,1017.34],[2,1.92,480.34]],"ltp":1.87,"tv":14867.16,"id":5300737}]}]}
{"op":"mcm","clk":"4299045641","pt":1632579518350,"mc":[{"id":"1.188136695","rc":[{"batl":[[1,1.9,1017.69]],"ltp":1.87,"tv":14867.16,"id":5300737}]}]}
{"op":"mcm","clk":"4299046004","pt":1632579519496,"mc":[{"id":"1.188136695","rc":[{"batb":[[0,1.78,5.69],[1,1.77,4],[2,1.76,5]],"batl":[[1,1.9,525.48],[2,1.96,200.47]],"ltp":1.87,"tv":14867.16,"id":5300737}]}]}
{"op":"mcm","clk":"4299046473","pt":1632579520869,"mc":[{"id":"1.188136695","rc":[{"trd":[[1.87,32.66]],"batl":[[0,1.87,115.13]],"ltp":1.87,"tv":14898.06,"id":5300737},{"trd":[[2.14,27]],"ltp":2.14,"tv":20431.96,"id":2497008}],"tv":35330.03}]}
{"op":"mcm","clk":"4299047006","pt":1632579522488,"mc":[{"id":"1.188136695","rc":[{"trd":[[1.87,33.3]],"batl":[[0,1.87,114.49]],"ltp":1.87,"tv":14898.7,"id":5300737},{"trd":[[2.14,27.56]],"ltp":2.14,"tv":20432.52,"id":2497008}],"tv":35331.23}]}
{"op":"mcm","clk":"4299047404","pt":1632579523777,"mc":[{"id":"1.188136695","rc":[{"batl":[[1,1.9,525.13]],"ltp":1.87,"tv":14898.7,"id":5300737}]}]}
{"op":"mcm","clk":"4299047502","pt":1632579524077,"mc":[{"id":"1.188136695","rc":[{"trd":[[1.87,97.13]],"batl":[[0,1.87,50.66]],"ltp":1.87,"tv":14962.53,"id":5300737},{"trd":[[2.14,83.33]],"ltp":2.14,"tv":20488.3,"id":2497008}],"tv":35450.83}]}
{"op":"mcm","clk":"4299048349","pt":1632579526578,"mc":[{"id":"1.188136695","rc":[{"trd":[[1.83,3.76],[1.84,1.38]],"batb":[[0,1.78,5]],"batl":[[0,1.83,475.96],[1,1.87,50.66],[2,1.9,525.13]],"ltp":1.83,"tv":14967.67,"id":5300737},{"trd":[[2.2,0.2]],"batl":[[0,2.28,4]],"ltp":2.2,"tv":20488.49,"id":2497008}],"tv":35456.17}]}
{"op":"mcm","clk":"4299048589","pt":1632579527260,"mc":[{"id":"1.188136695","rc":[{"batb":[[1,1.74,450.99],[2,1.73,270.48]],"ltp":1.83,"tv":14967.67,"id":5300737},{"batl":[[1,2.3,5.85]],"ltp":2.2,"tv":20488.49,"id":2497008}]}]}
{"op":"mcm","clk":"4299049058","pt":1632579528570,"mc":[{"id":"1.188136695","rc":[{"trd":[[1.78,5.13]],"batb":[[0,1.74,450.99],[1,1.73,270.48],[2,1.72,675.22]],"batl":[[0,1.78,513.43],[1,1.8,2222],[2,1.83,475.96]],"ltp":1.78,"tv":14972.79,"id":5300737},{"trd":[[2.28,4]],"batl":[[0,2.3,5.85],[1,4,0.86],[2,4,0]],"ltp":2.28,"tv":20492.49,"id":2497008}],"tv":35465.29}]}
{"op":"mcm","clk":"4299049443","pt":1632579529763,"mc":[{"id":"1.188136695","rc":[{"batl":[[2,1.81,6694.26]],"ltp":1.78,"tv":14972.79,"id":5300737}]}]}
{"op":"mcm","clk":"4299049776","pt":1632579530777,"mc":[{"id":"1.188136695","rc":[{"trd":[[1.78,5.83]],"batl":[[0,1.78,513.08],[1,1.8,2813.26],[2,1.82,567.34]],"ltp":1.78,"tv":14973.49,"id":5300737},{"batb":[[0,1.99,2431.35],[1,1.98,182.46],[2,1.96,93.67]],"ltp":2.28,"tv":20492.49,"id":2497008}],"tv":35465.99}]}
{"op":"mcm","clk":"4299050120","pt":1632579531770,"mc":[{"id":"1.188136695","rc":[{"trd":[[1.78,39.89]],"batl":[[0,1.78,496.05]],"ltp":1.78,"tv":15007.56,"id":5300737},{"batb":[[0,2.26,243.51],[1,2.12,288.99],[2,1.98,182.46]],"batl":[[0,2.3,9.85],[1,2.38,16.81],[2,4,0.86]],"ltp":2.28,"tv":20492.49,"id":2497008}],"tv":35500.05}]}
{"op":"mcm","clk":"4299050810","pt":1632579533684,"mc":[{"id":"1.188136695","rc":[{"batl":[[0,1.78,496.4],[1,1.8,591.26]],"ltp":1.78,"tv":15007.56,"id":5300737}]}]}
{"op":"mcm","clk":"4299051114","pt":1632579534599,"mc":[{"id":"1.188136695","rc":[{"trd":[[1.78,239.89]],"batb":[[0,1.76,4],[1,1.75,5],[2,1.74,450.99]],"batl":[[0,1.78,401.4]],"ltp":1.78,"tv":15207.56,"id":5300737},{"batb":[[0,2.28,4],[1,2.26,246.51],[2,2.12,288.99]],"ltp":2.28,"tv":20492.49,"id":2497008}],"tv":35700.05}]}
{"op":"mcm","clk":"4299051533","pt":1632579535790,"mc":[{"id":"1.188136695","rc":[{"trd":[[1.75,48.26],[1.76,20.87],[1.78,274.95]],"batb":[[0,1.75,109.68],[1,1.74,450.99],[2,1.73,270.48]],"batl":[[0,1.78,532.18]],"ltp":1.75,"tv":15311.74,"id":5300737},{"trd":[[2.3,9.85]],"batl":[[0,2.38,16.81],[1,4,0.86],[2,4,0]],"ltp":2.3,"tv":20502.34,"id":2497008}],"tv":35814.09}]}
{"op":"mcm","clk":"4299051568","pt":1632579535915,"mc":[{"id":"1.188136695","rc":[{"batl":[[0,1.78,153.66]],"ltp":1.75,"tv":15311.74,"id":5300737}]}]}
{"op":"mcm","clk":"4299052159","pt":1632579537825,"mc":[{"id":"1.188136695","rc":[{"batl":[[0,1.78,153.31]],"ltp":1.75,"tv":15311.74,"id":5300737},{"trd":[[2.28,8.46]],"batb":[[0,2.28,1.77]],"ltp":2.28,"tv":20506.8,"id":2497008}],"tv":35818.55}]}
{"op":"mcm","clk":"4299052438","pt":1632579538681,"mc":[{"id":"1.188136695","rc":[{"batl":[[0,1.76,2.35],[1,1.78,362.31],[2,1.8,591.26]],"ltp":1.75,"tv":15311.74,"id":5300737},{"batb":[[0,2.26,246.51],[1,2.12,288.99],[2,1.98,182.46]],"ltp":2.28,"tv":20506.8,"id":2497008}]}]}
{"op":"mcm","clk":"4299052571","pt":1632579539118,"mc":[{"id":"1.188136695","rc":[{"batb":[[1,1.74,455.99]],"ltp":1.75,"tv":15311.74,"id":5300737},{"batl":[[0,2.32,3],[1,2.34,3],[2,2.38,16.81]],"ltp":2.28,"tv":20506.8,"id":2497008}]}]}
{"op":"mcm","clk":"4299053415","pt":1632579541596,"mc":[{"id":"1.188136695","rc":[{"trd":[[1.75,185.32],[1.76,30.21],[1.78,280.07]],"batb":[[0,1.75,41.15],[1,1.74,566.11]],"batl":[[0,1.77,149.01],[1,1.78,359.75]],"ltp":1.76,"tv":15463.26,"id":5300737},{"batb":[[1,2.24,4],[2,2.12,288.99]],"batl":[[1,2.34,68.27]],"ltp":2.28,"tv":20506.8,"id":2497008}],"tv":35970.07}]}
{"op":"mcm","clk":"4299053541","pt":1632579542093,"mc":[{"id":"1.188136695","rc":[{"trd":[[1.74,46.8],[1.75,271.6]],"batb":[[0,1.74,542.71],[1,1.73,270.48],[2,1.72,675.22]],"ltp":1.74,"tv":15596.35,"id":5300737},{"trd":[[2.32,3]],"batl":[[0,2.34,68.27],[1,2.38,16.81],[2,4,0.86]],"ltp":2.32,"tv":20509.8,"id":2497008}],"tv":36106.15}]}
{"op":"mcm","clk":"4299054111","pt":1632579543700,"mc":[{"id":"1.188136695","rc":[{"batb":[[0,1.76,151.71],[1,1.74,542.71],[2,1.73,270.48]],"ltp":1.74,"tv":15596.35,"id":5300737}]}]}
{"op":"mcm","clk":"4299054380","pt":1632579544520,"mc":[{"id":"1.188136695","rc":[{"trd":[[1.77,2.27]],"batl":[[0,1.77,151.74]],"ltp":1.77,"tv":15598.62,"id":5300737},{"trd":[[2.28,10.22]],"ltp":2.28,"tv":20511.56,"id":2497008}],"tv":36110.18}]}
{"op":"mcm","clk":"4299054769","pt":1632579545589,"mc":[{"id":"1.188136695","rc":[{"trd":[[1.77,20.23]],"batb":[[2,1.73,275.48]],"batl":[[0,1.77,142.76]],"ltp":1.77,"tv":15616.58,"id":5300737},{"batl":[[0,2.34,3]],"ltp":2.28,"tv":20511.56,"id":2497008}],"tv":36128.14}]}
{"op":"mcm","clk":"4299055506","pt":1632579547808,"mc":[{"id":"1.188136695","rc":[{"batb":[[1,1.7,21.24],[2,1.65,125]],"batl":[[0,1.87,50.66],[1,1.9,46.48],[2,1.96,200.47]],"ltp":1.77,"tv":15616.58,"id":5300737},{"batb":[[0,2.12,288.99],[1,1.96,93.67],[2,1.92,97.93]],"batl":[[0,4,0.86],[1,2.38,0],[2,4,0]],"ltp":2.28,"tv":20511.56,"id":2497008}]}]}
{"op":"mcm","clk":"4299055797","pt":1632579548783,"mc":[{"id":"1.188136695","rc":[{"trd":[[1.76,30.91]],"batb":[[0,1.76,156.36],[1,1.75,5],[2,1.7,21.24]],"ltp":1.76,"tv":15617.28,"id":5300737},{"batb":[[0,2.28,4],[1,2.12,288.99],[2,1.96,93.67]],"ltp":2.28,"tv":20511.56,"id":2497008}],"tv":36128.85}]}
{"op":"mcm","clk":"4299055956","pt":1632579549213,"mc":[{"id":"1.188136695","rc":[{"batb":[[0,1.76,151.36],[1,1.7,21.24],[2,1.65,125]],"ltp":1.76,"tv":15617.28,"id":5300737},{"batb":[[0,2.12,288.99],[1,1.96,93.67],[2,1.92,97.93]],"batl":[[0,2.28,17.32],[1,4,0.86]],"ltp":2.28,"tv":20511.56,"id":2497008}]}]}
{"op":"mcm","clk":"4299056441","pt":1632579550782,"mc":[{"id":"1.188136695","rc":[{"trd":[[1.78,282.41]],"batl":[[1,1.89,545.05],[2,1.9,46.48]],"ltp":1.78,"tv":15619.63,"id":5300737},{"trd":[[2.28,12.05]],"batl":[[0,2.28,15.48]],"ltp":2.28,"tv":20513.4,"id":2497008}],"tv":36133.03}]}
{"op":"mcm","clk":"4299057071","pt":1632579552809,"mc":[{"id":"1.188136695","rc":[{"trd":[[1.76,190.19],[1.78,303.3]],"batb":[[0,1.76,71.72]],"ltp":1.76,"tv":15799.8,"id":5300737},{"trd":[[2.28,27.54]],"batl":[[0,4,0.86],[1,4,0]],"ltp":2.28,"tv":20528.88,"id":2497008}],"tv":36328.68}]}
{"op":"mcm","clk":"4299058301","pt":1632579556626,"mc":[{"id":"1.188136695","rc":[{"trd":[[1.76,209.89]],"batb":[[0,1.76,61.87]],"ltp":1.76,"tv":15819.5,"id":5300737}],"tv":36348.38}]}
{"op":"mcm","clk":"4299059019","pt":1632579558817,"mc":[{"id":"1.188136695","rc":[{"batl":[[1,1.9,46.48],[2,1.96,200.47]],"ltp":1.76,"tv":15819.5,"id":5300737}]}]}
{"op":"mcm","clk":"4299059104","pt":1632579559002,"mc":[{"id":"1.188136695","rc":[{"batb":[[0,1.7,21.24],[1,1.65,125],[2,1.64,15]],"ltp":1.76,"tv":15819.5,"id":5300737}]}]}
{"op":"mcm","clk":"4299059621","pt":1632579560633,"mc":[{"id":"1.188136695","rc":[{"trd":[[1.7,42.48]],"batb":[[0,1.65,125],[1,1.64,15],[2,1.63,697.43]],"batl":[[0,1.68,2200.76],[1,1.69,518.56],[2,1.87,50.66]],"ltp":1.7,"tv":15861.98,"id":5300737}],"tv":36390.86}]}
{"op":"mcm","clk":"4299060082","pt":1632579561719,"mc":[{"id":"1.188136695","rc":[{"batl":[[0,1.68,2588.12],[1,1.69,1537.05],[2,1.7,1699.71]],"ltp":1.7,"tv":15861.98,"id":5300737},{"batl":[[0,2.66,647.09],[1,2.68,628.06],[2,2.7,628.06]],"ltp":2.28,"tv":20528.88,"id":2497008}]}]}
{"op":"mcm","clk":"4299060497","pt":1632579562809,"mc":[{"id":"1.188136695","rc":[{"batb":[[0,1.65,115]],"ltp":1.7,"tv":15861.98,"id":5300737},{"batb":[[0,2.5,185.42],[1,2.38,214.84],[2,2.12,288.99]],"batl":[[0,2.56,15.62],[1,2.66,647.09],[2,2.68,628.06]],"ltp":2.28,"tv":20528.88,"id":2497008}]}]}
{"op":"mcm","clk":"4299060929","pt":1632579563727,"mc":[{"id":"1.188136695","rc":[{"batb":[[0,1.65,119],[1,1.64,20]],"batl":[[0,1.68,387.36]],"ltp":1.7,"tv":15861.98,"id":5300737},{"batb":[[2,1.96,93.67]],"batl":[[0,2.54,4],[1,2.56,15.62],[2,2.66,647.09]],"ltp":2.28,"tv":20528.88,"id":2497008}]}]}
{"op":"mcm","clk":"4299061232","pt":1632579564539,"mc":[{"id":"1.188136695","rc":[{"batl":[[1,1.69,1367.3],[2,1.7,1534.95]],"ltp":1.7,"tv":15861.98,"id":5300737},{"batl":[[2,2.66,539.24]],"ltp":2.28,"tv":20528.88,"id":2497008}]}]}
{"op":"mcm","clk":"4299062022","pt":1632579566709,"mc":[{"id":"1.188136695","rc":[{"batl":[[0,1.68,533.15]],"ltp":1.7,"tv":15861.98,"id":5300737},{"batb":[[2,2.22,2459.01]],"ltp":2.28,"tv":20528.88,"id":2497008}]}]}
{"op":"mcm","clk":"4299062337","pt":1632579567666,"mc":[{"id":"1.188136695","rc":[{"batb":[[2,1.63,1050.16]],"batl":[[0,1.66,1904.52],[1,1.68,533.15],[2,1.69,1367.3]],"ltp":1.7,"tv":15861.98,"id":5300737},{"batl":[[2,2.58,222.85]],"ltp":2.28,"tv":20528.88,"id":2497008}]}]}
{"op":"mcm","clk":"4299062736","pt":1632579568792,"mc":[{"id":"1.188136695","rc":[{"batl":[[1,1.67,247],[2,1.68,533.15]],"ltp":1.7,"tv":15861.98,"id":5300737},{"batb":[[1,2.46,227.14],[2,2.42,2.94]],"ltp":2.28,"tv":20528.88,"id":2497008}]}]}
{"op":"mcm","clk":"4299062945","pt":1632579569419,"mc":[{"id":"1.188136695","rc":[{"trd":[[1.66,85.03]],"batl":[[0,1.66,1862],[1,1.67,605.28]],"ltp":1.66,"tv":15947.01,"id":5300737},{"batb":[[1,2.48,241.25],[2,2.46,227.14]],"ltp":2.28,"tv":20528.88,"id":2497008}],"tv":36475.89}]}
{"op":"mcm","clk":"4299063354","pt":1632579570821,"mc":[{"id":"1.188136695","rc":[{"trd":[[1.65,105.98]],"batb":[[0,1.65,66.01]],"batl":[[0,1.66,2020.32]],"ltp":1.65,"tv":16052.99,"id":5300737},{"trd":[[2.5,135.54]],"batb":[[0,2.5,117.65]],"ltp":2.5,"tv":20664.42,"id":2497008}],"tv":36717.42}]}
{"op":"mcm","clk":"4299063514","pt":1632579571370,"mc":[{"id":"1.188136695","rc":[{"trd":[[1.66,285.03]],"batl":[[0,1.66,1920.32]],"ltp":1.66,"tv":16252.99,"id":5300737}],"tv":36917.42}]}
{"op":"mcm","clk":"4299063913","pt":1632579572753,"mc":[{"id":"1.188136695","rc":[{"trd":[[1.66,967.58]],"batb":[[0,1.65,108.78]],"batl":[[0,1.66,1579.05]],"ltp":1.66,"tv":16935.53,"id":5300737}],"tv":37599.96}]}
{"op":"mcm","clk":"4299064227","pt":1632579573487,"mc":[{"id":"1.188136695","rc":[{"trd":[[1.65,125.08],[1.66,1367.58]],"batb":[[0,1.65,99.23]],"batl":[[0,1.66,1379.05]],"ltp":1.66,"tv":17354.63,"id":5300737}],"tv":38019.06}]}
{"op":"mcm","clk":"4299064657","pt":1632579574819,"mc":[{"id":"1.188136695","rc":[{"trd":[[1.65,334.06],[1.66,1568.2]],"batb":[[0,1.64,62.82],[1,1.63,1050.16],[2,1.62,425.42]],"batl":[[0,1.66,158.01],[1,1.67,908.09]],"ltp":1.66,"tv":17764.24,"id":5300737},{"batb":[[0,2.5,319.93]],"ltp":2.5,"tv":20664.42,"id":2497008}],"tv":38428.67}]}
{"op":"mcm","clk":"4299064903","pt":1632579575612,"mc":[{"id":"1.188136695","rc":[{"batb":[[0,1.65,442.68],[1,1.64,62.82],[2,1.63,1050.16]],"ltp":1.66,"tv":17764.24,"id":5300737}]}]}
{"op":"mcm","clk":"4299065251","pt":1632579576693,"mc":[{"id":"1.188136695","rc":[{"trd":[[1.63,2654.27],[1.64,156.22],[1.65,1219.43],[1.66,1662.48]],"batb":[[0,1.62,425.42],[1,1.61,344.71],[2,1.6,34.28]],"batl":[[0,1.63,1269.8],[1,1.66,110.87],[2,1.67,908.09]],"ltp":1.63,"tv":21554.37,"id":5300737},{"trd":[[2.54,4],[2.56,15.62],[2.58,222.85]],"batl":[[0,2.66,539.24],[1,2.68,525.52],[2,2.7,523.38]],"ltp":2.58,"tv":20906.9,"id":2497008}],"tv":42461.27}]}
{"op":"mcm","clk":"4299065464","pt":1632579577413,"mc":[{"id":"1.188136695","rc":[{"trd":[[1.63,2863.49]],"batl":[[0,1.63,1165.18],[2,1.67,1102.17]],"ltp":1.63,"tv":21763.59,"id":5300737}],"tv":42670.49}]}
{"op":"mcm","clk":"4299065874","pt":1632579578591,"mc":[{"id":"1.188136695","rc":[{"trd":[[1.63,3210.93]],"batl":[[0,1.63,991.46],[1,1.65,5.21],[2,1.66,110.87]],"ltp":1.63,"tv":22111.03,"id":5300737}],"tv":43017.93}]}
{"op":"mcm","clk":"4299066229","pt":1632579579797,"mc":[{"id":"1.188136695","rc":[{"trd":[[1.63,3490.26]],"batb":[[0,1.62,618.46],[1,1.61,350.71],[2,1.6,349.2]],"batl":[[0,1.63,848.63]],"ltp":1.63,"tv":22390.36,"id":5300737},{"trd":[[2.58,226.85]],"batl":[[0,2.6,3],[1,2.62,3],[2,2.64,167.67]],"ltp":2.58,"tv":20910.9,"id":2497008}],"tv":43301.26}]}
{"op":"mcm","clk":"4299066537","pt":1632579580751,"mc":[{"id":"1.188136695","rc":[{"trd":[[1.63,4299.48]],"batb":[[0,1.62,430.42]],"batl":[[0,1.63,444.02],[1,1.66,110.87],[2,1.67,1102.17]],"ltp":1.63,"tv":23199.58,"id":5300737}],"tv":44110.48}]}
{"op":"mcm","clk":"4299066795","pt":1632579581541,"mc":[{"id":"1.188136695","rc":[{"trd":[[1.63,4302.63]],"batl":[[0,1.63,442.44]],"ltp":1.63,"tv":23202.74,"id":5300737}],"tv":44113.64}]}
{"op":"mcm","clk":"4299067197","pt":1632579582636,"mc":[{"id":"1.188136695","rc":[{"trd":[[1.63,4522.36]],"batl":[[0,1.63,589.71],[1,1.64,215.3],[2,1.66,110.87]],"ltp":1.63,"tv":23422.47,"id":5300737}],"tv":44333.37}]}
{"op":"mcm","clk":"4299067593","pt":1632579583831,"mc":[{"id":"1.188136695","rc":[{"trd":[[1.63,4611.2]],"batb":[[0,1.62,666.31],[1,1.61,437.54],[2,1.6,34.28]],"batl":[[0,1.63,545.3],[1,1.65,100],[2,1.67,717.29]],"ltp":1.63,"tv":23511.3,"id":5300737},{"batb":[[0,2.44,2.67],[1,2.38,214.84],[2,2.36,112.08]],"batl":[[2,2.76,101.46]],"ltp":2.58,"tv":20910.9,"id":2497008}],"tv":44422.2}]}
{"op":"mcm","clk":"4299067882","pt":1632579584822,"mc":[{"id":"1.188136695","rc":[{"trd":[[1.63,4666.26]],"batb":[[0,1.62,5],[1,1.6,34.28],[2,1.57,180.88]],"batl":[[0,1.63,517.77],[1,1.65,102.36],[2,1.69,19.5]],"ltp":1.63,"tv":23566.36,"id":5300737},{"batl":[[0,2.76,101.46],[1,2.78,94.33],[2,2.8,133.82]],"ltp":2.58,"tv":20910.9,"id":2497008}],"tv":44477.26}]}
{"op":"mcm","clk":"4299068193","pt":1632579585824,"mc":[{"id":"1.188136695","rc":[{"trd":[[1.62,10]],"batb":[[0,1.6,34.28],[1,1.57,180.88],[2,1.56,204.38]],"batl":[[0,1.62,3584.86],[1,1.63,517.77],[2,1.65,102.36]],"ltp":1.62,"tv":23576.36,"id":5300737},{"batb":[[1,2.38,217.8]],"ltp":2.58,"tv":20910.9,"id":2497008}],"tv":44487.27}]}
{"op":"mcm","clk":"4299068528","pt":1632579586811,"mc":[{"id":"1.188136695","rc":[{"trd":[[1.62,819.38]],"batl":[[0,1.62,3180.17]],"ltp":1.62,"tv":24385.74,"id":5300737}],"tv":45296.65}]}
{"op":"mcm","clk":"4299068656","pt":1632579587203,"mc":[{"id":"1.188136695","rc":[{"trd":[[1.62,872.48]],"batl":[[0,1.62,3153.62],[2,1.65,2.36]],"ltp":1.62,"tv":24438.84,"id":5300737},{"batb":[[1,2.38,2.96]],"ltp":2.58,"tv":20910.9,"id":2497008}],"tv":45349.74}]}
{"op":"mcm","clk":"4299069328","pt":1632579589336,"mc":[{"id":"1.188136695","rc":[{"batl":[[2,1.69,19.5]],"ltp":1.62,"tv":24438.84,"id":5300737}]}]}
{"op":"mcm","clk":"4299069702","pt":1632579590608,"mc":[{"id":"1.188136695","rc":[{"trd":[[1.62,874.1]],"batl":[[0,1.62,3252.81]],"ltp":1.62,"tv":24440.46,"id":5300737}],"tv":45351.36}]}
{"op":"mcm","clk":"4299070005","pt":1632579591656,"mc":[{"id":"1.188136695","rc":[{"batb":[[1,1.55,21.39],[2,1.54,414.38]],"batl":[[0,1.62,3252.71],[2,1.7,17.25]],"ltp":1.62,"tv":24440.46,"id":5300737},{"batb":[[0,2.38,2.96],[1,2.36,112.08],[2,2.34,354.79]],"batl":[[0,2.82,2.75],[1,4,0.86],[2,2.8,0]],"ltp":2.58,"tv":20910.9,"id":2497008}]}]}
{"op":"mcm","clk":"4299070362","pt":1632579592717,"mc":[{"id":"1.188136695","rc":[{"trd":[[1.62,7379.52],[1.63,5701.8]],"batb":[[0,1.68,1451.43],[1,1.67,518.56],[2,1.6,34.28]],"batl":[[0,1.72,16.91],[1,1.73,564.27],[2,1.74,128.17]],"ltp":1.63,"tv":31981.42,"id":5300737}],"tv":52892.32}]}
{"op":"mcm","clk":"4299070691","pt":1632579593737,"mc":[{"id":"1.188136695","rc":[{"batb":[[2,1.65,1988.64]],"ltp":1.63,"tv":31981.42,"id":5300737},{"batl":[[0,2.46,16.26],[1,2.6,2109.76],[2,2.82,2.75]],"ltp":2.58,"tv":20910.9,"id":2497008}]}]}
{"op":"mcm","clk":"4299071016","pt":1632579594740,"mc":[{"id":"1.188136695","rc":[{"batb":[[1,1.67,1247.69],[2,1.66,386.42]],"batl":[[1,1.73,2370.63],[2,1.74,1031.35]],"ltp":1.63,"tv":31981.42,"id":5300737},{"batl":[[1,2.6,1275.74]],"ltp":2.58,"tv":20910.9,"id":2497008}]}]}
{"op":"mcm","clk":"4299071329","pt":1632579595686,"mc":[{"id":"1.188136695","rc":[{"trd":[[1.68,17.24]],"batb":[[0,1.68,1442.81],[1,1.67,1550.97]],"batl":[[1,1.73,1015.86],[2,1.74,353.97]],"ltp":1.68,"tv":31998.67,"id":5300737},{"batb":[[1,2.36,326.58],[2,2.34,138.08]],"batl":[[2,2.8,1.71]],"ltp":2.58,"tv":20910.9,"id":2497008}],"tv":52909.57}]}
{"op":"mcm","clk":"4299071764","pt":1632579596815,"mc":[{"id":"1.188136695","rc":[{"trd":[[1.68,26.84]],"batb":[[0,1.67,1550.97],[1,1.66,386.42],[2,1.65,473.49]],"ltp":1.68,"tv":32008.26,"id":5300737},{"trd":[[2.46,6.55]],"batl":[[0,2.46,9.71]],"ltp":2.46,"tv":20917.45,"id":2497008}],"tv":52925.71}]}
{"op":"mcm","clk":"4299072067","pt":1632579597774,"mc":[{"id":"1.188136695","rc":[{"trd":[[1.66,1693.02],[1.67,3101.94],[1.68,41.06]],"batb":[[0,1.66,371.15],[1,1.65,473.49],[2,1.64,236.74]],"ltp":1.66,"tv":35154.97,"id":5300737},{"trd":[[2.46,16.26]],"batl":[[0,2.6,1275.74],[1,2.8,1.71],[2,2.82,2.75]],"ltp":2.46,"tv":20927.16,"id":2497008}],"tv":56082.13}]}
{"op":"mcm","clk":"4299072424","pt":1632579598766,"mc":[{"id":"1.188136695","rc":[{"batl":[[0,1.71,208.55],[1,1.72,16.91],[2,1.73,506.4]],"ltp":1.66,"tv":35154.97,"id":5300737},{"batb":[[0,2.38,5.96],[1,2.36,329.58]],"batl":[[0,2.48,39.67],[1,2.6,1275.74],[2,2.8,1.71]],"ltp":2.46,"tv":20927.16,"id":2497008}]}]}
{"op":"mcm","clk":"4299072791","pt":1632579599821,"mc":[{"id":"1.188136695","rc":[{"batb":[[0,1.67,293.87],[1,1.66,377.15],[2,1.65,473.49]],"batl":[[2,1.73,802.15]],"ltp":1.66,"tv":35154.97,"id":5300737},{"batb":[[1,2.36,586.56],[2,2.34,441.45]],"batl":[[0,2.6,1275.74],[1,2.8,1.71],[2,2.82,2.75]],"ltp":2.46,"tv":20927.16,"id":2497008}]}]}
{"op":"mcm","clk":"4299073098","pt":1632579600731,"mc":[{"id":"1.188136695","rc":[{"batb":[[0,1.66,377.15],[1,1.65,473.49],[2,1.64,236.74]],"ltp":1.66,"tv":35154.97,"id":5300737},{"batb":[[2,2.34,444.67]],"batl":[[1,2.8,4.18]],"ltp":2.46,"tv":20927.16,"id":2497008}]}]}
{"op":"mcm","clk":"4299073402","pt":1632579601629,"mc":[{"id":"1.188136695","rc":[{"trd":[[1.67,3951.7]],"batb":[[1,1.65,479.49]],"batl":[[0,1.67,2482.25],[1,1.71,208.55],[2,1.72,846.83]],"ltp":1.67,"tv":36004.72,"id":5300737},{"trd":[[2.48,4]],"batb":[[0,2.38,223.38],[1,2.36,838.5]],"batl":[[0,2.52,4],[1,2.6,1275.74],[2,2.7,102.39]],"ltp":2.48,"tv":20931.16,"id":2497008}],"tv":56935.89}]}
{"op":"mcm","clk":"4299073708","pt":1632579602557,"mc":[{"id":"1.188136695","rc":[{"trd":[[1.65,1958.31],[1.66,2447.32]],"batb":[[0,1.65,110.05],[1,1.64,236.74],[2,1.63,236.74]],"ltp":1.65,"tv":37497.9,"id":5300737}],"tv":58429.07}]}
{"op":"mcm","clk":"4299074113","pt":1632579603672,"mc":[{"id":"1.188136695","rc":[{"batl":[[1,1.7,201],[2,1.71,225.05]],"ltp":1.65,"tv":37497.9,"id":5300737},{"batb":[[0,2.4,2.91],[1,2.38,223.38],[2,2.36,838.5]],"batl":[[0,2.5,4],[1,2.52,4],[2,2.6,1275.74]],"ltp":2.48,"tv":20931.16,"id":2497008}]}]}
{"op":"mcm","clk":"4299074423","pt":1632579604539,"mc":[{"id":"1.188136695","rc":[{"batl":[[0,1.68,211.05]],"ltp":1.65,"tv":37497.9,"id":5300737}]}]}
{"op":"mcm","clk":"4299074836","pt":1632579605764,"mc":[{"id":"1.188136695","rc":[{"batb":[[0,1.66,261.21],[1,1.65,505.95],[2,1.64,241.74]],"batl":[[0,1.7,201],[1,1.71,225.05],[2,1.72,488.78]],"ltp":1.65,"tv":37497.9,"id":5300737},{"batb":[[0,2.4,125.48],[1,2.38,387.09],[2,2.36,841.68]],"ltp":2.48,"tv":20931.16,"id":2497008}]}]}
{"op":"mcm","clk":"4299075031","pt":1632579606269,"mc":[{"id":"1.188136695","rc":[{"batb":[[0,1.66,476.2]],"batl":[[0,1.68,169.08],[1,1.7,201],[2,1.71,737.81]],"ltp":1.65,"tv":37497.9,"id":5300737},{"batl":[[2,2.58,197.14]],"ltp":2.48,"tv":20931.16,"id":2497008}]}]}
{"op":"mcm","clk":"4299075555","pt":1632579607703,"mc":[{"id":"1.188136695","rc":[{"batl":[[0,1.67,99],[1,1.68,169.08],[2,1.7,201]],"ltp":1.65,"tv":37497.9,"id":5300737}]}]}
{"op":"mcm","clk":"4299075907","pt":1632579608660,"mc":[{"id":"1.188136695","rc":[{"batl":[[0,1.67,10.15],[1,1.68,513.23],[2,1.69,397.99]],"ltp":1.65,"tv":37497.9,"id":5300737},{"batb":[[0,2.48,233.14],[1,2.46,273.42],[2,2.4,125.48]],"ltp":2.48,"tv":20931.16,"id":2497008}]}]}
{"op":"mcm","clk":"4299076170","pt":1632579609469,"mc":[{"id":"1.188136695","rc":[{"batl":[[1,1.68,742.39]],"ltp":1.65,"tv":37497.9,"id":5300737},{"batb":[[0,2.46,273.42],[1,2.4,125.48],[2,2.38,387.09]],"ltp":2.48,"tv":20931.16,"id":2497008}]}]}
{"op":"mcm","clk":"4299076572","pt":1632579610769,"mc":[{"id":"1.188136695","rc":[{"trd":[[1.67,3951.72]],"batl":[[0,1.67,10.14],[1,1.68,732.31]],"ltp":1.67,"tv":37497.92,"id":5300737}],"tv":58429.08}]}
{"op":"mcm","clk":"4299076807","pt":1632579611475,"mc":[{"id":"1.188136695","rc":[{"trd":[[1.66,2452.02]],"batb":[[0,1.66,473.85]],"ltp":1.66,"tv":37502.62,"id":5300737}],"tv":58433.78}]}
{"op":"mcm","clk":"4299077215","pt":1632579612797,"mc":[{"id":"1.188136695","rc":[{"trd":[[1.66,2522.14],[1.67,3952.42]],"batb":[[0,1.66,438.79],[1,1.65,401.9],[2,1.64,5]],"batl":[[0,1.67,9.79],[1,1.68,514.27],[2,1.71,512.76]],"ltp":1.67,"tv":37573.44,"id":5300737},{"batb":[[0,2.38,3],[1,2.36,3.18],[2,2.34,3.22]],"batl":[[2,2.7,102.39]],"ltp":2.48,"tv":20931.16,"id":2497008}],"tv":58504.6}]}
{"op":"mcm","clk":"4299077422","pt":1632579613379,"mc":[{"id":"1.188136695","rc":[{"trd":[[1.66,2540.16]],"batb":[[0,1.6,34.28],[1,1.58,137.34],[2,1.57,228.6]],"batl":[[0,1.66,27.98],[1,1.67,9.79],[2,1.68,514.27]],"ltp":1.66,"tv":37591.46,"id":5300737},{"trd":[[2.5,139.54]],"batb":[[0,2.36,3.18],[1,2.34,3.22],[2,2.32,3.39]],"batl":[[0,2.7,102.39],[1,2.72,127.88],[2,2.74,126.06]],"ltp":2.5,"tv":20935.16,"id":2497008}],"tv":58526.62}]}
{"op":"mcm","clk":"4299078118","pt":1632579615666,"mc":[{"id":"1.188136695","rc":[{"trd":[[1.66,2541.52]],"batl":[[0,1.66,26.62]],"ltp":1.66,"tv":37592.82,"id":5300737},{"trd":[[2.5,140.44]],"ltp":2.5,"tv":20936.06,"id":2497008}],"tv":58528.88}]}
{"op":"mcm","clk":"4299078946","pt":1632579618221,"mc":[{"id":"1.188136695","rc":[{"batl":[[1,1.68,514.27],[2,1.73,15.87]],"ltp":1.66,"tv":37592.82,"id":5300737}]}]}
{"op":"mcm","clk":"4299079444","pt":1632579619728,"mc":[{"id":"1.188136695","rc":[{"trd":[[1.66,2545.52]],"batl":[[0,1.66,24.62],[1,1.68,534.41]],"ltp":1.66,"tv":37596.82,"id":5300737},{"batb":[[0,2.48,21.26],[1,2.36,3.18],[2,2.34,3.22]],"batl":[[0,2.54,19.75],[1,2.7,102.39],[2,2.72,127.88]],"ltp":2.5,"tv":20936.06,"id":2497008}],"tv":58532.88}]}
{"op":"mcm","clk":"4299079610","pt":1632579620204,"mc":[{"id":"1.188136695","rc":[{"batb":[[0,1.64,415.8],[1,1.63,413.64],[2,1.6,34.28]],"batl":[[1,1.68,514.27],[2,1.69,637.74]],"ltp":1.66,"tv":37596.82,"id":5300737},{"batb":[[0,2.36,3.18],[1,2.34,3.22],[2,2.32,3.39]],"batl":[[0,2.8,2.47],[1,2.82,2.75],[2,2.98,2.75]],"ltp":2.5,"tv":20936.06,"id":2497008}]}]}
{"op":"mcm","clk":"4299079988","pt":1632579621377,"mc":[{"id":"1.188136695","rc":[{"trd":[[1.64,175.8]],"batb":[[0,1.64,406.01]],"ltp":1.64,"tv":37616.4,"id":5300737}],"tv":58552.46}]}
{"op":"mcm","clk":"4299080749","pt":1632579623607,"mc":[{"id":"1.188136695","rc":[{"trd":[[1.66,2554.09]],"batl":[[0,1.66,20.33]],"ltp":1.66,"tv":37624.98,"id":5300737}],"tv":58561.04}]}
{"op":"mcm","clk":"4299081166","pt":1632579624670,"mc":[{"id":"1.188136695","rc":[{"batb":[[0,1.6,34.28],[1,1.56,22.83],[2,1.55,423.94]],"batl":[[2,1.73,15.87]],"ltp":1.66,"tv":37624.98,"id":5300737}]}]}
{"op":"mcm","clk":"4299081470","pt":1632579625574,"mc":[{"id":"1.188136695","rc":[{"trd":[[1.66,2558.09]],"batl":[[0,1.66,18.33]],"ltp":1.66,"tv":37628.98,"id":5300737}],"tv":58565.04}]}
{"op":"mcm","clk":"4299082154","pt":1632579627817,"mc":[{"id":"1.188136695","rc":[{"batb":[[1,1.56,461.77],[2,1.55,923.8]],"ltp":1.66,"tv":37628.98,"id":5300737}]}]}
{"op":"mcm","clk":"4299082181","pt":1632579627865,"mc":[{"id":"1.188136695","rc":[{"batb":[[2,1.55,902.41]],"ltp":1.66,"tv":37628.98,"id":5300737},{"batb":[[1,2.3,2.98],[2,2.26,255.68]],"batl":[[1,2.98,2.75],[2,4,0.86]],"ltp":2.5,"tv":20936.06,"id":2497008}]}]}
{"op":"mcm","clk":"4299082570","pt":1632579629192,"mc":[{"id":"1.188136695","rc":[{"trd":[[1.6,68.56]],"batb":[[0,1.56,461.77],[1,1.55,902.41],[2,1.51,24.99]],"batl":[[0,1.59,518.56],[1,1.6,2187.72],[2,1.66,18.33]],"ltp":1.6,"tv":37697.54,"id":5300737}],"tv":58633.6}]}
{"op":"mcm","clk":"4299083040","pt":1632579630680,"mc":[{"id":"1.188136695","rc":[{"batb":[[0,2.66,293.7],[1,2.64,146.85],[2,2.62,146.85]],"ltp":2.5,"tv":20936.06,"id":2497008}]}]}
{"op":"mcm","clk":"4299083367","pt":1632579631790,"mc":[{"id":"1.188136695","rc":[{"trd":[[1.59,25.35]],"batb":[[2,1.54,507.3]],"batl":[[0,1.59,493.2],[1,1.6,2697.93],[2,1.61,431.59]],"ltp":1.59,"tv":37722.9,"id":5300737},{"trd":[[2.68,15.04]],"batb":[[0,2.72,154.56],[1,2.66,293.7],[2,2.64,146.85]],"batl":[[2,3.05,1.71]],"ltp":2.68,"tv":20951.1,"id":2497008}],"tv":58674.0}]}
{"op":"mcm","clk":"4299083575","pt":1632579632493,"mc":[{"id":"1.188136695","rc":[{"batb":[[0,1.56,467.77],[1,1.55,907.41]],"ltp":1.59,"tv":37722.9,"id":5300737},{"batl":[[0,2.8,5.47]],"ltp":2.68,"tv":20951.1,"id":2497008}]}]}
{"op":"mcm","clk":"4299084270","pt":1632579634757,"mc":[{"id":"1.188136695","rc":[{"batl":[[0,1.58,212.5],[1,1.59,493.2],[2,1.6,2697.93]],"ltp":1.59,"tv":37722.9,"id":5300737}]}]}
{"op":"mcm","clk":"4299084543","pt":1632579635571,"mc":[{"id":"1.188136695","rc":[{"batl":[[2,1.6,510.21]],"ltp":1.59,"tv":37722.9,"id":5300737},{"trd":[[2.72,65.84]],"batb":[[0,2.72,121.64]],"ltp":2.72,"tv":21016.94,"id":2497008}],"tv":58739.84}]}
{"op":"mcm","clk":"4299084885","pt":1632579636673,"mc":[{"id":"1.188136695","rc":[{"trd":[[1.58,20]],"batl":[[0,1.58,202.5]],"ltp":1.58,"tv":37742.9,"id":5300737}],"tv":58759.84}]}
{"op":"mcm","clk":"4299085175","pt":1632579637676,"mc":[{"id":"1.188136695","rc":[{"batb":[[0,1.57,82],[1,1.56,467.77],[2,1.55,907.41]],"ltp":1.58,"tv":37742.9,"id":5300737},{"batl":[[1,2.98,84.68],[2,3,107.42]],"ltp":2.72,"tv":21016.94,"id":2497008}]}]}
{"op":"mcm","clk":"4299085509","pt":1632579638770,"mc":[{"id":"1.188136695","rc":[{"trd":[[1.58,120]],"batb":[[2,1.55,1311.52]],"batl":[[0,1.58,152.5]],"ltp":1.58,"tv":37842.9,"id":5300737},{"batl":[[0,2.8,229.18],[1,2.82,241.71],[2,2.98,84.68]],"ltp":2.72,"tv":21016.94,"id":2497008}],"tv":58859.84}]}
{"op":"mcm","clk":"4299085795","pt":1632579639803,"mc":[{"id":"1.188136695","rc":[{"trd":[[1.58,121.56]],"batb":[[2,1.55,1309.75]],"batl":[[0,1.58,151.72]],"ltp":1.58,"tv":37844.46,"id":5300737}],"tv":58861.4}]}
{"op":"mcm","clk":"4299086109","pt":1632579640799,"mc":[{"id":"1.188136695","rc":[{"trd":[[1.57,174],[1.58,326.26]],"batb":[[0,1.56,467.77],[1,1.55,1309.75],[2,1.54,949.9]],"batl":[[0,1.57,2553.36],[1,1.59,219.3]],"ltp":1.57,"tv":38223.15,"id":5300737},{"batl":[[0,2.76,3],[1,2.8,430.74],[2,2.82,241.71]],"ltp":2.72,"tv":21016.94,"id":2497008}],"tv":59240.09}]}
{"op":"mcm","clk":"4299086392","pt":1632579641683,"mc":[{"id":"1.188136695","rc":[{"trd":[[1.57,374]],"batl":[[0,1.57,2453.36],[1,1.58,256],[2,1.59,219.3]],"ltp":1.57,"tv":38423.15,"id":5300737},{"batl":[[1,2.8,229.18]],"ltp":2.72,"tv":21016.94,"id":2497008}],"tv":59440.09}]}
{"op":"mcm","clk":"4299086710","pt":1632579642697,"mc":[{"id":"1.188136695","rc":[{"trd":[[1.57,399.48]],"batl":[[0,1.57,2437.88]],"ltp":1.57,"tv":38448.63,"id":5300737},{"trd":[[2.74,3.14]],"ltp":2.74,"tv":21020.07,"id":2497008}],"tv":59468.71}]}
{"op":"mcm","clk":"4299087039","pt":1632579643693,"mc":[{"id":"1.188136695","rc":[{"trd":[[1.57,408.26]],"batl":[[0,1.57,2433.49]],"ltp":1.57,"tv":38457.41,"id":5300737}],"tv":59477.49}]}
{"op":"mcm","clk":"4299087220","pt":1632579644297,"mc":[{"id":"1.188136695","rc":[{"trd":[[1.57,416.88]],"batl":[[0,1.57,2631.3],[1,1.58,456.84]],"ltp":1.57,"tv":38466.03,"id":5300737},{"batb":[[1,2.68,209.99],[2,2.66,550.84]],"ltp":2.74,"tv":21020.07,"id":2497008}],"tv":59486.11}]}
{"op":"mcm","clk":"4299087689","pt":1632579645787,"mc":[{"id":"1.188136695","rc":[{"trd":[[1.57,1315.81]],"batb":[[0,1.56,512.56],[1,1.55,1371.58]],"batl":[[0,1.57,2181.83]],"ltp":1.57,"tv":39364.96,"id":5300737}],"tv":60385.04}]}
{"op":"mcm","clk":"4299087861","pt":1632579646266,"mc":[{"id":"1.188136695","rc":[{"trd":[[1.57,1398.53]],"batl":[[0,1.57,2099.11]],"ltp":1.57,"tv":39447.68,"id":5300737},{"trd":[[2.74,50.53]],"ltp":2.74,"tv":21067.47,"id":2497008}],"tv":60515.16}]}
{"op":"mcm","clk":"4299088151","pt":1632579647217,"mc":[{"id":"1.188136695","rc":[{"trd":[[1.57,1402.42]],"batb":[[0,1.56,517.02]],"batl":[[0,1.57,2095.22],[1,1.58,846.27],[2,1.59,679.7]],"ltp":1.57,"tv":39451.57,"id":5300737},{"trd":[[2.74,52.76]],"batb":[[0,2.74,224.57],[1,2.72,390.77],[2,2.68,209.99]],"ltp":2.74,"tv":21069.7,"id":2497008}],"tv":60521.28}]}
{"op":"mcm","clk":"4299088578","pt":1632579648499,"mc":[{"id":"1.188136695","rc":[{"trd":[[1.57,1407.12]],"batb":[[1,1.55,1378.58]],"batl":[[0,1.57,2092.87]],"ltp":1.57,"tv":39456.27,"id":5300737},{"batb":[[2,2.66,550.84]],"ltp":2.74,"tv":21069.7,"id":2497008}],"tv":60525.98}]}
{"op":"mcm","clk":"4299088958","pt":1632579649782,"mc":[{"id":"1.188136695","rc":[{"trd":[[1.57,1408.3]],"batl":[[0,1.57,2117.28]],"ltp":1.57,"tv":39457.45,"id":5300737}],"tv":60527.16}]}
{"op":"mcm","clk":"4299089241","pt":1632579650695,"mc":[{"id":"1.188136695","rc":[{"batb":[[0,1.56,547.02],[1,1.55,3283.09]],"ltp":1.57,"tv":39457.45,"id":5300737},{"trd":[[2.76,6]],"batl":[[0,2.8,229.18],[1,2.82,241.71],[2,2.98,84.68]],"ltp":2.76,"tv":21075.7,"id":2497008}],"tv":60533.16}]}
{"op":"mcm","clk":"4299089458","pt":1632579651481,"mc":[{"id":"1.188136695","rc":[{"trd":[[1.57,1486.32]],"batl":[[0,1.57,2078.27]],"ltp":1.57,"tv":39535.47,"id":5300737}],"tv":60611.18}]}
{"op":"mcm","clk":"4299089738","pt":1632579652494,"mc":[{"id":"1.188136695","rc":[{"trd":[[1.56,21.72],[1.57,1577.48]],"batb":[[0,1.56,536.16]],"batl":[[0,1.57,2032.69]],"ltp":1.57,"tv":39648.35,"id":5300737}],"tv":60724.06}]}
{"op":"mcm","clk":"4299090288","pt":1632579654288,"mc":[{"id":"1.188136695","rc":[{"trd":[[1.57,1597.48]],"batl":[[0,1.57,2022.69]],"ltp":1.57,"tv":39668.36,"id":5300737},{"trd":[[2.74,56.19]],"batb":[[0,2.74,222.85]],"ltp":2.74,"tv":21079.13,"id":2497008}],"tv":60747.49}]}
{"op":"mcm","clk":"4299090486","pt":1632579654907,"mc":[{"id":"1.188136695","rc":[{"trd":[[1.57,1598.89]],"batl":[[0,1.57,2021.99]],"ltp":1.57,"tv":39669.76,"id":5300737}],"tv":60748.89}]}
{"op":"mcm","clk":"4299091113","pt":1632579656780,"mc":[{"id":"1.188136695","rc":[{"trd":[[1.57,1831.09]],"batl":[[0,1.57,1905.88]],"ltp":1.57,"tv":39901.97,"id":5300737},{"trd":[[2.74,70.64]],"batb":[[0,2.74,215.63]],"ltp":2.74,"tv":21093.58,"id":2497008}],"tv":60995.55}]}
{"op":"mcm","clk":"4299091277","pt":1632579657272,"mc":[{"id":"1.188136695","rc":[{"trd":[[1.56,27.44]],"batb":[[0,1.56,533.3]],"ltp":1.56,"tv":39907.69,"id":5300737},{"batl":[[0,2.8,229.68]],"ltp":2.74,"tv":21093.58,"id":2497008}],"tv":61001.27}]}
{"op":"mcm","clk":"4299092967","pt":1632579662809,"mc":[{"id":"1.188136695","rc":[{"trd":[[1.57,2189.48]],"batb":[[1,1.55,3276.09]],"batl":[[0,1.57,1726.68]],"ltp":1.57,"tv":40266.08,"id":5300737}],"tv":61359.66}]}
{"op":"mcm","clk":"4299093275","pt":1632579663735,"mc":[{"id":"1.188136695","rc":[{"trd":[[1.56,29.12]],"batb":[[0,1.56,532.46]],"ltp":1.56,"tv":40267.76,"id":5300737}],"tv":61361.34}]}
{"op":"mcm","clk":"4299093493","pt":1632579664395,"mc":[{"id":"1.188136695","rc":[{"batb":[[0,1.56,502.46]],"ltp":1.56,"tv":40267.76,"id":5300737}]}]}
{"op":"mcm","clk":"4299093866","pt":1632579665557,"mc":[{"id":"1.188136695","rc":[{"trd":[[1.56,56.4],[1.57,2199.48]],"batb":[[0,1.56,488.82]],"batl":[[0,1.57,1721.69]],"ltp":1.56,"tv":40305.04,"id":5300737},{"trd":[[2.74,76.64]],"batb":[[0,2.74,212.63]],"ltp":2.74,"tv":21099.58,"id":2497008}],"tv":61404.62}]}
{"op":"mcm","clk":"4299094044","pt":1632579666132,"mc":[{"id":"1.188136695","rc":[{"trd":[[1.57,3186.02]],"batl":[[0,1.57,1228.41]],"ltp":1.57,"tv":41291.58,"id":5300737}],"tv":62391.16}]}
{"op":"mcm","clk":"4299094550","pt":1632579667739,"mc":[{"id":"1.188136695","rc":[{"trd":[[1.56,160.4],[1.57,3188.34]],"batb":[[0,1.56,55.25],[1,1.55,871.72]],"batl":[[0,1.57,1227.26]],"ltp":1.57,"tv":41397.9,"id":5300737}],"tv":62497.48}]}
{"op":"mcm","clk":"4299095485","pt":1632579670562,"mc":[{"id":"1.188136695","rc":[{"trd":[[1.57,3202.36]],"batl":[[0,1.57,1220.25]],"ltp":1.57,"tv":41411.92,"id":5300737}],"tv":62511.5}]}
{"op":"mcm","clk":"4299095790","pt":1632579671454,"mc":[{"id":"1.188136695","rc":[{"trd":[[1.56,160.78]],"batb":[[0,1.56,55.06]],"ltp":1.56,"tv":41412.3,"id":5300737},{"batl":[[0,2.76,8.46],[1,2.8,229.18],[2,2.82,241.71]],"ltp":2.74,"tv":21099.58,"id":2497008}],"tv":62511.88}]}
{"op":"mcm","clk":"4299096561","pt":1632579673819,"mc":[{"id":"1.188136695","rc":[{"trd":[[1.56,161.88],[1.57,3211.03]],"batb":[[0,1.56,9.72]],"batl":[[0,1.57,1215.91]],"ltp":1.57,"tv":41422.07,"id":5300737}],"tv":62521.65}]}
{"op":"mcm","clk":"4299096674","pt":1632579674242,"mc":[{"id":"1.188136695","rc":[{"trd":[[1.55,2047.04],[1.56,196.28]],"batb":[[0,1.54,949.9],[1,1.53,11088.92],[2,1.52,253.65]],"ltp":1.55,"tv":43503.51,"id":5300737},{"trd":[[2.76,14.46],[2.8,168.07]],"batl":[[0,2.8,61.1],[1,2.82,241.71],[2,2.98,84.68]],"ltp":2.8,"tv":21276.11,"id":2497008}],"tv":64779.62}]}
{"op":"mcm","clk":"4299097505","pt":1632579676806,"mc":[{"id":"1.188136695","rc":[{"trd":[[1.57,3223.43]],"batb":[[0,1.51,513.76],[1,1.5,1230.93],[2,1.49,232.6]],"batl":[[0,1.57,1007.59],[1,1.58,256],[2,1.6,46.48]],"ltp":1.57,"tv":43515.9,"id":5300737},{"trd":[[2.74,77.65]],"batb":[[0,2.48,293.99],[1,2.46,132.36],[2,2.44,153.66]],"batl":[[0,2.98,84.68],[1,3,107.42],[2,3.05,120.15]],"ltp":2.74,"tv":21277.12,"id":2497008}],"tv":64793.03}]}
{"op":"mcm","clk":"4299097790","pt":1632579677764,"mc":[{"id":"1.188136695","rc":[{"trd":[[1.56,208.28]],"batl":[[1,1.6,46.48],[2,1.67,168.44]],"ltp":1.56,"tv":43527.9,"id":5300737}],"tv":64805.03}]}
{"op":"mcm","clk":"4299098085","pt":1632579678658,"mc":[{"id":"1.188136695","rc":[{"trd":[[1.57,3227.05]],"batl":[[0,1.57,1004.28]],"ltp":1.57,"tv":43531.53,"id":5300737},{"trd":[[2.74,79.37]],"ltp":2.74,"tv":21278.83,"id":2497008}],"tv":64810.36}]}
{"op":"mcm","clk":"4299098415","pt":1632579679823,"mc":[{"id":"1.188136695","rc":[{"trd":[[1.57,3233.05]],"batb":[[0,1.52,23.24],[1,1.51,513.76],[2,1.5,1256.67]],"batl":[[0,1.57,1001.28],[2,1.67,186.94]],"ltp":1.57,"tv":43537.53,"id":5300737},{"batb":[[0,2.5,192.69],[1,2.48,296.75],[2,2.46,132.36]],"batl":[[0,2.94,2.25],[1,2.98,84.68],[2,3,109.44]],"ltp":2.74,"tv":21278.83,"id":2497008}],"tv":64816.36}]}
{"op":"mcm","clk":"4299098734","pt":1632579680827,"mc":[{"id":"1.188136695","rc":[{"trd":[[1.57,3284.58]],"batb":[[0,1.57,209.13],[1,1.51,6],[2,1.5,237.23]],"batl":[[0,1.6,46.48],[1,1.67,186.94],[2,1.68,177.73]],"ltp":1.57,"tv":43589.05,"id":5300737},{"trd":[[2.74,93.37]],"batb":[[1,2.48,100.76]],"batl":[[0,2.98,84.93],[1,3,109.44],[2,3.05,122.25]],"ltp":2.74,"tv":21292.83,"id":2497008}],"tv":64881.89}]}
{"op":"mcm","clk":"4299099003","pt":1632579681719,"mc":[{"id":"1.188136695","rc":[{"trd":[[1.57,3286.5]],"batb":[[0,1.57,208.17]],"ltp":1.57,"tv":43590.97,"id":5300737}],"tv":64883.81}]}
{"op":"mcm","clk":"4299099066","pt":1632579681936,"mc":[{"id":"1.188136695","rc":[{"trd":[[1.57,3293.52]],"batb":[[0,1.57,204.66]],"ltp":1.57,"tv":43597.99,"id":5300737}],"tv":64890.83}]}
{"op":"mcm","clk":"4299099623","pt":1632579683761,"mc":[{"id":"1.188136695","rc":[{"batb":[[1,1.52,25.74],[2,1.51,6]],"ltp":1.57,"tv":43597.99,"id":5300737},{"batl":[[0,2.94,5.25],[1,2.98,84.93],[2,3,109.44]],"ltp":2.74,"tv":21292.83,"id":2497008}]}]}
{"op":"mcm","clk":"4299099934","pt":1632579684574,"mc":[{"id":"1.188136695","rc":[{"trd":[[1.57,3549.5]],"batb":[[0,1.57,742.23],[1,1.56,1440.94],[2,1.52,25.74]],"batl":[[1,1.62,678.01],[2,1.63,412.29]],"ltp":1.57,"tv":43853.97,"id":5300737}],"tv":65146.81}]}
{"op":"mcm","clk":"4299100318","pt":1632579685759,"mc":[{"id":"1.188136695","rc":[{"batl":[[0,1.6,115.48]],"ltp":1.57,"tv":43853.97,"id":5300737}]}]}
{"op":"mcm","clk":"4299100653","pt":1632579686739,"mc":[{"id":"1.188136695","rc":[{"batb":[[0,1.57,76.67],[1,1.52,25.74],[2,1.51,6]],"batl":[[0,1.6,46.48],[1,1.67,186.94],[2,1.68,177.73]],"ltp":1.57,"tv":43853.97,"id":5300737}]}]}
{"op":"mcm","clk":"4299100977","pt":1632579687773,"mc":[{"id":"1.188136695","rc":[{"batb":[[0,1.58,275.41],[1,1.57,76.67],[2,1.52,25.74]],"batl":[[0,1.6,466.52]],"ltp":1.57,"tv":43853.97,"id":5300737}]}]}
{"op":"mcm","clk":"4299101048","pt":1632579687939,"mc":[{"id":"1.188136695","rc":[{"batb":[[0,1.57,76.67],[1,1.52,25.74],[2,1.51,6]],"batl":[[0,1.6,46.48]],"ltp":1.57,"tv":43853.97,"id":5300737}]}]}
{"op":"mcm","clk":"4299101614","pt":1632579689649,"mc":[{"id":"1.188136695","rc":[{"trd":[[1.57,3555.5]],"batb":[[0,1.57,73.67],[1,1.52,59.74],[2,1.51,494.77]],"ltp":1.57,"tv":43859.97,"id":5300737}],"tv":65152.81}]}
{"op":"mcm","clk":"4299101808","pt":1632579690303,"mc":[{"id":"1.188136695","rc":[{"batb":[[2,1.51,528.77]],"ltp":1.57,"tv":43859.97,"id":5300737}]}]}
{"op":"mcm","clk":"4299102550","pt":1632579692667,"mc":[{"id":"1.188136695","rc":[{"trd":[[1.6,161.52]],"batl":[[0,1.67,186.94],[1,1.68,177.73],[2,1.69,882.57]],"ltp":1.6,"tv":43952.93,"id":5300737}],"tv":65245.77}]}
{"op":"mcm","clk":"4299102913","pt":1632579693783,"mc":[{"id":"1.188136695","rc":[{"batb":[[0,1.6,2.55],[1,1.57,73.67],[2,1.52,69.74]],"ltp":1.6,"tv":43952.93,"id":5300737}]}]}
{"op":"mcm","clk":"4299103153","pt":1632579694569,"mc":[{"id":"1.188136695","rc":[{"trd":[[1.57,3702.84],[1.6,166.62]],"batb":[[0,1.52,54],[1,1.51,528.77],[2,1.5,801.96]],"batl":[[0,1.53,4084.97],[1,1.67,186.94],[2,1.68,177.73]],"ltp":1.57,"tv":44105.37,"id":5300737},{"batb":[[0,2.9,1077.58],[1,2.88,538.79],[2,2.86,538.79]],"batl":[[0,2.94,3]],"ltp":2.74,"tv":21292.83,"id":2497008}],"tv":65398.2}]}
{"op":"mcm","clk":"4299103469","pt":1632579695582,"mc":[{"id":"1.188136695","rc":[{"batb":[[0,2.9,53.88],[1,2.88,26.94],[2,2.86,26.94]],"batl":[[1,2.98,81.93]],"ltp":2.74,"tv":21292.83,"id":2497008}]}]}
{"op":"mcm","clk":"4299103774","pt":1632579696573,"mc":[{"id":"1.188136695","rc":[{"batb":[[1,1.51,40],[2,1.5,232.23]],"batl":[[1,1.67,168.44]],"ltp":1.57,"tv":44105.37,"id":5300737}]}]}
{"op":"mcm","clk":"4299104123","pt":1632579697781,"mc":[{"id":"1.188136695","rc":[{"trd":[[1.53,424.79]],"batl":[[0,1.53,3680.85]],"ltp":1.53,"tv":44530.15,"id":5300737},{"trd":[[2.88,257.59],[2.9,107.76]],"batb":[[0,2.86,26.94],[1,2.5,192.69],[2,2.48,98]],"ltp":2.88,"tv":21658.18,"id":2497008}],"tv":66188.34}]}
{"op":"mcm","clk":"4299104320","pt":1632579698375,"mc":[{"id":"1.188136695","rc":[{"trd":[[1.53,443.13]],"batl":[[0,1.53,3662.51]],"ltp":1.53,"tv":44548.49,"id":5300737},{"trd":[[2.88,267.33]],"ltp":2.88,"tv":21667.93,"id":2497008}],"tv":66216.42}]}
{"op":"mcm","clk":"4299104734","pt":1632579699762,"mc":[{"id":"1.188136695","rc":[{"trd":[[1.53,483.13]],"batl":[[0,1.53,3642.51]],"ltp":1.53,"tv":44588.49,"id":5300737}],"tv":66256.42}]}
{"op":"mcm","clk":"4299105640","pt":1632579702682,"mc":[{"id":"1.188136695","rc":[{"batb":[[0,1.52,34]],"ltp":1.53,"tv":44588.49,"id":5300737}]}]}
{"op":"mcm","clk":"4299105722","pt":1632579702976,"mc":[{"id":"1.188136695","rc":[{"trd":[[1.53,523.13]],"batl":[[0,1.53,3622.51]],"ltp":1.53,"tv":44628.49,"id":5300737}],"tv":66296.42}]}
{"op":"mcm","clk":"4299106354","pt":1632579704985,"mc":[{"id":"1.188136695","rc":[{"trd":[[1.53,530.15]],"batl":[[0,1.53,3619]],"ltp":1.53,"tv":44635.51,"id":5300737}],"tv":66303.44}]}
{"op":"mcm","clk":"4299106718","pt":1632579706097,"mc":[{"id":"1.188136695","rc":[{"trd":[[1.52,68]],"batb":[[0,1.51,60],[1,1.5,232.23],[2,1.49,719.51]],"batl":[[0,1.52,187.83],[1,1.53,3619],[2,1.67,168.44]],"ltp":1.52,"tv":44703.51,"id":5300737}],"tv":66371.44}]}
{"op":"mcm","clk":"4299107524","pt":1632579708603,"mc":[{"id":"1.188136695","rc":[{"trd":[[1.52,69.6]],"batl":[[0,1.52,184.68]],"ltp":1.52,"tv":44705.12,"id":5300737}],"tv":66373.05}]}
{"op":"mcm","clk":"4299107796","pt":1632579709577,"mc":[{"id":"1.188136695","rc":[{"trd":[[1.52,81.6]],"batb":[[0,1.51,40],[1,1.5,239.23]],"batl":[[0,1.52,178.68],[2,1.64,20]],"ltp":1.52,"tv":44717.12,"id":5300737}],"tv":66385.05}]}
{"op":"mcm","clk":"4299108914","pt":1632579713291,"mc":[{"id":"1.188136695","rc":[{"trd":[[1.52,82.39]],"batl":[[0,1.52,178.29]],"ltp":1.52,"tv":44717.9,"id":5300737}],"tv":66385.83}]}
{"op":"mcm","clk":"4299109249","pt":1632579714392,"mc":[{"id":"1.188136695","rc":[{"trd":[[1.52,91.4]],"batl":[[0,1.52,173.78]],"ltp":1.52,"tv":44726.92,"id":5300737}],"tv":66394.85}]}
{"op":"mcm","clk":"4299109673","pt":1632579715812,"mc":[{"id":"1.188136695","rc":[{"trd":[[1.52,95.33]],"batl":[[0,1.52,171.82]],"ltp":1.52,"tv":44730.84,"id":5300737}],"tv":66398.77}]}
{"op":"mcm","clk":"4299109765","pt":1632579716107,"mc":[{"id":"1.188136695","rc":[{"trd":[[1.52,152.06]],"batl":[[0,1.52,143.45]],"ltp":1.52,"tv":44787.57,"id":5300737}],"tv":66455.5}]}
{"op":"mcm","clk":"4299110806","pt":1632579719694,"mc":[{"id":"1.188136695","rc":[{"trd":[[1.52,153.08]],"batb":[[0,1.51,6]],"batl":[[0,1.52,142.43]],"ltp":1.52,"tv":44788.59,"id":5300737},{"trd":[[2.92,0.53],[2.94,6]],"batb":[[0,2.94,45.94],[1,2.86,26.94],[2,2.5,192.69]],"batl":[[0,2.98,81.93],[1,3,109.44],[2,3.05,122.25]],"ltp":2.94,"tv":21674.46,"id":2497008}],"tv":66463.05}]}
{"op":"mcm","clk":"4299111266","pt":1632579721216,"mc":[{"id":"1.188136695","rc":[{"trd":[[1.52,160.1]],"batl":[[0,1.52,138.92]],"ltp":1.52,"tv":44795.61,"id":5300737}],"tv":66470.07}]}
{"op":"mcm","clk":"4299111532","pt":1632579722172,"mc":[{"id":"1.188136695","rc":[{"trd":[[1.5,860.12],[1.51,12]],"batb":[[0,1.49,719.51],[1,1.48,228.48],[2,1.42,1.76]],"ltp":1.5,"tv":45667.73,"id":5300737},{"trd":[[2.98,81.93],[3,109.44]],"batl":[[0,3.05,122.25],[1,4,0.86],[2,3.05,0]],"ltp":3.0,"tv":21865.83,"id":2497008}],"tv":67533.56}]}
{"op":"mcm","clk":"4299112327","pt":1632579724409,"mc":[{"id":"1.188136695","rc":[{"batb":[[0,2.86,26.94],[1,2.5,192.69],[2,2.38,2.96]],"ltp":3.0,"tv":21865.83,"id":2497008}]}]}
{"op":"mcm","clk":"4299112772","pt":1632579725578,"mc":[{"id":"1.188136695","rc":[{"batb":[[0,1.51,7],[1,1.5,6],[2,1.49,725.51]],"batl":[[0,1.52,136.57]],"ltp":1.5,"tv":45667.73,"id":5300737},{"batl":[[0,3.05,126.25]],"ltp":3.0,"tv":21865.83,"id":2497008}]}]}
{"op":"mcm","clk":"4299112886","pt":1632579725968,"mc":[{"id":"1.188136695","rc":[{"batb":[[0,1.49,725.51],[1,1.48,234.48],[2,1.42,1.76]],"ltp":1.5,"tv":45667.73,"id":5300737}]}]}
{"op":"mcm","clk":"4299113483","pt":1632579727801,"mc":[{"id":"1.188136695","rc":[{"batl":[[1,1.53,7703.97],[2,1.56,6]],"ltp":1.5,"tv":45667.73,"id":5300737},{"batb":[[0,2.9,1077.58],[1,2.88,538.79],[2,2.86,565.73]],"batl":[[1,3.4,1.71],[2,4,0.86]],"ltp":3.0,"tv":21865.83,"id":2497008}]}]}
{"op":"mcm","clk":"4299113687","pt":1632579728443,"mc":[{"id":"1.188136695","rc":[{"trd":[[1.52,196.12]],"batb":[[2,1.47,531.46]],"batl":[[0,1.52,104.84],[1,1.53,4435.99]],"ltp":1.52,"tv":45703.75,"id":5300737},{"trd":[[2.92,31.96]],"batb":[[0,2.92,121.89],[1,2.9,215.52],[2,2.88,107.76]],"ltp":2.92,"tv":21897.26,"id":2497008}],"tv":67601.02}]}
{"op":"mcm","clk":"4299114122","pt":1632579729628,"mc":[{"id":"1.188136695","rc":[{"batb":[[0,1.49,31.01],[1,1.48,6],[2,1.46,513.98]],"batl":[[0,1.51,89.71],[1,1.52,104.84]],"ltp":1.52,"tv":45703.75,"id":5300737},{"batb":[[0,2.76,4],[1,2.68,160.48],[2,2.2,4]],"batl":[[0,3.05,6.1]],"ltp":2.92,"tv":21897.26,"id":2497008}]}]}
{"op":"mcm","clk":"4299114310","pt":1632579730131,"mc":[{"id":"1.188136695","rc":[{"batb":[[0,1.49,6],[2,1.46,512.12]],"batl":[[2,1.64,20]],"ltp":1.52,"tv":45703.75,"id":5300737},{"batb":[[0,2.68,160.48],[1,2.2,4],[2,2.14,17.32]],"batl":[[0,3.05,4]],"ltp":2.92,"tv":21897.26,"id":2497008}]}]}
{"op":"mcm","clk":"4299114664","pt":1632579731153,"mc":[{"id":"1.188136695","rc":[{"trd":[[1.51,14]],"batl":[[0,1.51,88.71]],"ltp":1.51,"tv":45705.75,"id":5300737}],"tv":67603.02}]}
{"op":"mcm","clk":"4299115129","pt":1632579732609,"mc":[{"id":"1.188136695","rc":[{"trd":[[1.49,12]],"batb":[[0,1.48,6],[1,1.47,564.85],[2,1.46,1149.99]],"batl":[[0,1.49,45.76],[1,1.51,88.71],[2,1.52,104.84]],"ltp":1.49,"tv":45717.75,"id":5300737}],"tv":67615.02}]}
{"op":"mcm","clk":"4299115489","pt":1632579733707,"mc":[{"id":"1.188136695","rc":[{"trd":[[1.49,19.02]],"batl":[[0,1.49,42.25],[1,1.5,20]],"ltp":1.49,"tv":45724.77,"id":5300737},{"batl":[[2,1000,2.86]],"ltp":2.92,"tv":21897.26,"id":2497008}],"tv":67622.04}]}
{"op":"mcm","clk":"4299115705","pt":1632579734423,"mc":[{"id":"1.188136695","rc":[{"batl":[[2,4,0.86]],"ltp":2.92,"tv":21897.26,"id":2497008}]}]}
{"op":"mcm","clk":"4299116179","pt":1632579735809,"mc":[{"id":"1.188136695","rc":[{"trd":[[1.48,20.25]],"batb":[[0,1.47,572.85],[1,1.46,1149.99],[2,1.42,1.76]],"ltp":1.48,"tv":45745.02,"id":5300737},{"trd":[[3.05,4]],"batl":[[0,3.4,1.71],[1,4,0.86],[2,4,0]],"ltp":3.05,"tv":21901.26,"id":2497008}],"tv":67646.28}]}
{"op":"mcm","clk":"4299116510","pt":1632579736810,"mc":[{"id":"1.188136695","rc":[{"trd":[[1.47,917.12]],"batb":[[0,1.47,114.29]],"batl":[[0,1.49,2264.25]],"ltp":1.47,"tv":46662.13,"id":5300737}],"tv":68563.4}]}
{"op":"mcm","clk":"4299116830","pt":1632579737797,"mc":[{"id":"1.188136695","rc":[{"trd":[[1.49,23.02]],"batb":[[0,1.47,8]],"batl":[[0,1.49,2262.25],[1,1.52,293.57],[2,1.53,183.18]],"ltp":1.49,"tv":46666.13,"id":5300737},{"batl":[[0,5.4,1.86],[1,5.9,1],[2,1000,2]],"ltp":3.05,"tv":21901.26,"id":2497008}],"tv":68567.4}]}
{"op":"mcm","clk":"4299117084","pt":1632579738665,"mc":[{"id":"1.188136695","rc":[{"trd":[[1.49,29.94]],"batl":[[0,1.49,2257.03],[1,1.51,566.04],[2,1.52,4068.24]],"ltp":1.49,"tv":46673.05,"id":5300737},{"batb":[[0,2.96,6],[1,2.68,160.48],[2,2.2,4]],"batl":[[0,3.25,1853.66],[1,3.3,1799.13],[2,3.35,1799.13]],"ltp":3.05,"tv":21901.26,"id":2497008}],"tv":68574.32}]}
{"op":"mcm","clk":"4299117502","pt":1632579739813,"mc":[{"id":"1.188136695","rc":[{"trd":[[1.47,933.12],[1.49,2062.4]],"batb":[[0,1.46,1155.99],[1,1.43,556.26]],"batl":[[0,1.47,944.26],[1,1.49,1227.01],[2,1.51,559.04]],"ltp":1.47,"tv":48721.51,"id":5300737},{"trd":[[3,123.14],[3.05,5.4]],"batb":[[0,3.05,290.49],[1,2.96,3],[2,2.86,135.7]],"batl":[[0,3.15,3],[1,3.25,529.62],[2,3.3,514.03]],"ltp":3.05,"tv":21916.36,"id":2497008}],"tv":70637.88}]}
{"op":"mcm","clk":"4299117807","pt":1632579740830,"mc":[{"id":"1.188136695","rc":[{"batb":[[0,1.46,1530.64],[1,1.45,661.58],[2,1.43,556.26]],"batl":[[1,1.48,40],[2,1.49,1227.01]],"ltp":1.47,"tv":48721.51,"id":5300737}]}]}
{"op":"mcm","clk":"4299118117","pt":1632579741821,"mc":[{"id":"1.188136695","rc":[{"batl":[[0,1.48,40],[1,1.49,1227.01],[2,1.5,441.92]],"ltp":1.47,"tv":48721.51,"id":5300737}]}]}
{"op":"mcm","clk":"4299118276","pt":1632579742346,"mc":[{"id":"1.188136695","rc":[{"trd":[[1.48,21.05]],"batb":[[0,1.47,282.89],[1,1.46,1530.64],[2,1.45,661.58]],"batl":[[0,1.48,39.6],[1,1.49,441.73]],"ltp":1.48,"tv":48722.31,"id":5300737}],"tv":70638.68}]}
{"op":"mcm","clk":"4299118717","pt":1632579743691,"mc":[{"id":"1.188136695","rc":[{"batb":[[1,1.46,1823.83],[2,1.45,667.58]],"batl":[[0,1.48,484.54],[1,1.49,450.52],[2,1.5,851.62]],"ltp":1.48,"tv":48722.31,"id":5300737},{"trd":[[3.05,46.5]],"batb":[[0,3.05,269.94],[1,3,204.85],[2,2.96,246.98]],"ltp":3.05,"tv":21957.46,"id":2497008}],"tv":70679.78}]}
{"op":"mcm","clk":"4299119057","pt":1632579744751,"mc":[{"id":"1.188136695","rc":[{"trd":[[1.48,35.07]],"batl":[[0,1.48,477.53]],"ltp":1.48,"tv":48736.33,"id":5300737}],"tv":70693.8}]}
{"op":"mcm","clk":"4299119349","pt":1632579745653,"mc":[{"id":"1.188136695","rc":[{"batb":[[0,1.47,332.89]],"ltp":1.48,"tv":48736.33,"id":5300737}]}]}
{"op":"mcm","clk":"4299119720","pt":1632579746651,"mc":[{"id":"1.188136695","rc":[{"batl":[[1,1.49,806.22],[2,1.5,1250.18]],"ltp":1.48,"tv":48736.33,"id":5300737},{"batb":[[1,3,580.79]],"ltp":3.05,"tv":21957.46,"id":2497008}]}]}
{"op":"mcm","clk":"4299119924","pt":1632579747249,"mc":[{"id":"1.188136695","rc":[{"trd":[[1.48,49.07]],"batb":[[0,1.47,282.89]],"batl":[[0,1.48,470.53]],"ltp":1.48,"tv":48750.33,"id":5300737},{"trd":[[3.05,52.5]],"batb":[[0,3.05,266.94]],"ltp":3.05,"tv":21963.46,"id":2497008}],"tv":70713.8}]}
{"op":"mcm","clk":"4299120414","pt":1632579748820,"mc":[{"id":"1.188136695","rc":[{"batb":[[0,1.47,568.31]],"batl":[[0,1.48,233.59]],"ltp":1.48,"tv":48750.33,"id":5300737}]}]}
{"op":"mcm","clk":"4299120652","pt":1632579749579,"mc":[{"id":"1.188136695","rc":[{"trd":[[1.47,1124.54],[1.48,149.07]],"batb":[[0,1.47,479.3],[1,1.46,2183.82],[2,1.45,1095.28]],"batl":[[0,1.48,183.59]],"ltp":1.48,"tv":49041.75,"id":5300737},{"batb":[[1,3,404.13]],"batl":[[1,3.2,165.24],[2,3.25,720.44]],"ltp":3.05,"tv":21963.46,"id":2497008}],"tv":71005.22}]}
{"op":"mcm","clk":"4299121041","pt":1632579750661,"mc":[{"id":"1.188136695","rc":[{"trd":[[1.48,170.11]],"batl":[[0,1.48,173.07]],"ltp":1.48,"tv":49062.79,"id":5300737},{"batb":[[1,3,204.85]],"ltp":3.05,"tv":21963.46,"id":2497008}],"tv":71026.26}]}
{"op":"mcm","clk":"4299121424","pt":1632579751787,"mc":[{"id":"1.188136695","rc":[{"trd":[[1.48,178.68]],"batb":[[0,1.47,292.47],[1,1.46,1538.69],[2,1.45,667.58]],"batl":[[0,1.48,168.78],[1,1.49,377.23],[2,1.5,911.62]],"ltp":1.48,"tv":49071.37,"id":5300737},{"batb":[[0,3.05,446.94],[1,3,234.85],[2,2.96,3]],"batl":[[1,3.2,1],[2,3.35,78.3]],"ltp":3.05,"tv":21963.46,"id":2497008}],"tv":71034.84}]}
{"op":"mcm","clk":"4299121789","pt":1632579752788,"mc":[{"id":"1.188136695","rc":[{"trd":[[1.47,1505.1],[1.48,1256.06],[1.49,2077.96]],"batb":[[0,1.49,10.76],[1,1.48,239.34],[2,1.47,96.19]],"batl":[[0,1.54,184.86],[1,1.55,220.12],[2,1.56,228.33]],"ltp":1.49,"tv":50544.87,"id":5300737},{"trd":[[3,124.14],[3.05,53.5]],"batb":[[0,2.86,237.61],[1,2.84,103.99],[2,2.82,106.15]],"batl":[[0,3.2,1],[1,3.35,78.3],[2,3.4,89.47]],"ltp":3.0,"tv":21965.46,"id":2497008}],"tv":72510.33}]}
{"op":"mcm","clk":"4299122080","pt":1632579753770,"mc":[{"id":"1.188136695","rc":[{"batb":[[1,1.48,243.35]],"ltp":1.49,"tv":50544.87,"id":5300737}]}]}
{"op":"mcm","clk":"4299122297","pt":1632579754431,"mc":[{"id":"1.188136695","rc":[{"trd":[[2.86,2]],"batb":[[0,2.86,236.61]],"ltp":2.86,"tv":21967.46,"id":2497008}],"tv":72512.34}]}
{"op":"mcm","clk":"4299122682","pt":1632579755754,"mc":[{"id":"1.188136695","rc":[{"batb":[[2,1.47,95.84]],"batl":[[1,1.55,713.18],[2,1.56,714.66]],"ltp":1.49,"tv":50544.87,"id":5300737},{"batl":[[1,3.25,3],[2,3.35,78.3]],"ltp":2.86,"tv":21967.46,"id":2497008}]}]}
{"op":"mcm","clk":"4299122979","pt":1632579756688,"mc":[{"id":"1.188136695","rc":[{"trd":[[1.49,2101.49]],"batb":[[0,1.48,243.35],[1,1.47,95.84],[2,1.46,8.05]],"batl":[[0,1.49,183.46],[1,1.54,184.86],[2,1.55,220.12]],"ltp":1.49,"tv":50568.4,"id":5300737},{"trd":[[3,125.14]],"ltp":3.0,"tv":21968.46,"id":2497008}],"tv":72536.87}]}
{"op":"mcm","clk":"4299123314","pt":1632579757787,"mc":[{"id":"1.188136695","rc":[{"batb":[[0,1.48,245.11]],"batl":[[0,1.49,546.51]],"ltp":1.49,"tv":50568.4,"id":5300737}]}]}
{"op":"mcm","clk":"4299123592","pt":1632579758584,"mc":[{"id":"1.188136695","rc":[{"trd":[[1.48,1309.2]],"batb":[[0,1.48,218.54]],"ltp":1.48,"tv":50621.54,"id":5300737}],"tv":72590.01}]}
{"op":"mcm","clk":"4299123975","pt":1632579759792,"mc":[{"id":"1.188136695","rc":[{"trd":[[1.49,2191.49]],"batb":[[0,1.48,236.07]],"batl":[[0,1.49,614.51]],"ltp":1.49,"tv":50711.54,"id":5300737}],"tv":72680.01}]}
{"op":"mcm","clk":"4299124296","pt":1632579760758,"mc":[{"id":"1.188136695","rc":[{"trd":[[1.49,2195.52]],"batb":[[1,1.47,1021.46],[2,1.46,649.81]],"batl":[[0,1.49,579.53],[1,1.51,466.33],[2,1.52,537.69]],"ltp":1.49,"tv":50715.57,"id":5300737},{"trd":[[3,127.14]],"ltp":3.0,"tv":21970.46,"id":2497008}],"tv":72686.03}]}
{"op":"mcm","clk":"4299124594","pt":1632579761558,"mc":[{"id":"1.188136695","rc":[{"trd":[[1.48,1518.88]],"batb":[[0,1.48,131.23]],"batl":[[0,1.49,113]],"ltp":1.48,"tv":50925.24,"id":5300737}],"tv":72895.71}]}
{"op":"mcm","clk":"4299124976","pt":1632579762786,"mc":[{"id":"1.188136695","rc":[{"trd":[[1.48,1552.52],[1.49,2197.53]],"batb":[[0,1.48,114.41],[1,1.47,95.84],[2,1.46,8.05]],"batl":[[0,1.54,184.86],[1,1.55,220.12],[2,1.56,228.33]],"ltp":1.49,"tv":50960.89,"id":5300737},{"trd":[[3,128.14]],"batl":[[0,3.2,1.83]],"ltp":3.0,"tv":21971.46,"id":2497008}],"tv":72932.36}]}
{"op":"mcm","clk":"4299125339","pt":1632579763757,"mc":[{"id":"1.188136695","rc":[{"batb":[[0,1.48,110.4]],"ltp":1.49,"tv":50960.89,"id":5300737}]}]}
{"op":"mcm","clk":"4299125606","pt":1632579764752,"mc":[{"id":"1.188136695","rc":[{"trd":[[1.48,1733.81]],"batb":[[0,1.48,19.75]],"ltp":1.48,"tv":51142.19,"id":5300737},{"trd":[[2.86,4]],"batb":[[0,2.86,235.61]],"ltp":2.86,"tv":21973.46,"id":2497008}],"tv":73115.66}]}
{"op":"mcm","clk":"4299125978","pt":1632579765782,"mc":[{"id":"1.188136695","rc":[{"batl":[[1,1.55,713.18],[2,1.56,714.66]],"ltp":1.48,"tv":51142.19,"id":5300737}]}]}
{"op":"mcm","clk":"4299126584","pt":1632579767673,"mc":[{"id":"1.188136695","rc":[{"trd":[[1.48,1749.87],[1.54,2]],"batb":[[0,1.48,11.72]],"batl":[[0,1.54,183.86]],"ltp":1.54,"tv":51160.25,"id":5300737}],"tv":73133.72}]}
{"op":"mcm","clk":"4299126923","pt":1632579768753,"mc":[{"id":"1.188136695","rc":[{"trd":[[1.54,4.01]],"batl":[[0,1.54,182.86]],"ltp":1.54,"tv":51162.25,"id":5300737},{"trd":[[2.86,6]],"batb":[[0,2.86,234.61]],"batl":[[0,3.05,43.68],[1,3.2,1],[2,3.25,3]],"ltp":2.86,"tv":21975.46,"id":2497008}],"tv":73137.72}]}
{"op":"mcm","clk":"4299127212","pt":1632579769808,"mc":[{"id":"1.188136695","rc":[{"batb":[[0,1.49,1.15],[1,1.48,11.72],[2,1.47,95.84]],"ltp":1.54,"tv":51162.25,"id":5300737}]}]}
{"op":"mcm","clk":"4299127518","pt":1632579770801,"mc":[{"id":"1.188136695","rc":[{"trd":[[1.49,2199.13],[1.54,6.01]],"batb":[[0,1.48,5.86],[1,1.46,8.75],[2,1.45,6]],"batl":[[0,1.54,181.85]],"ltp":1.54,"tv":51165.86,"id":5300737},{"trd":[[3.05,56.24]],"batl":[[0,3.05,42.32]],"ltp":3.05,"tv":21978.2,"id":2497008}],"tv":73144.06}]}
{"op":"mcm","clk":"4299127807","pt":1632579771822,"mc":[{"id":"1.188136695","rc":[{"batl":[[0,1.64,20],[1,1.84,2],[2,2.04,3.15]],"ltp":1.54,"tv":51165.86,"id":5300737},{"batb":[[0,2.86,132.7],[1,2.2,4],[2,2.14,17.32]],"ltp":3.05,"tv":21978.2,"id":2497008}]}]}
{"op":"mcm","clk":"4299128152","pt":1632579772810,"mc":[{"id":"1.188136695","rc":[{"trd":[[1.45,14.2],[1.46,16.1],[1.47,1506.5],[1.48,1848.8],[1.54,6.41]],"batb":[[0,1.44,532.96],[1,1.43,1472.58],[2,1.42,215.62]],"batl":[[0,1.45,450.36],[1,1.46,2213.25],[2,1.48,412.15]],"ltp":1.45,"tv":51296.89,"id":5300737},{"trd":[[2.86,6.22],[3.05,98.55],[3.2,1]],"batb":[[0,2.86,132.49]],"batl":[[0,3.25,3],[1,3.35,78.3],[2,3.4,89.47]],"ltp":3.2,"tv":22021.73,"id":2497008}],"tv":73318.63}]}
{"op":"mcm","clk":"4299128501","pt":1632579773812,"mc":[{"id":"1.188136695","rc":[{"batl":[[2,1.47,6189.74]],"ltp":1.45,"tv":51296.89,"id":5300737},{"batb":[[0,3.05,1881.15],[1,3,1825.82],[2,2.98,1825.82]],"ltp":3.2,"tv":22021.73,"id":2497008}]}]}
{"op":"mcm","clk":"4299128802","pt":1632579774805,"mc":[{"id":"1.188136695","rc":[{"trd":[[1.45,359.05]],"batl":[[0,1.45,277.93],[2,1.47,952.26]],"ltp":1.45,"tv":51641.74,"id":5300737},{"batb":[[0,3.05,564.35],[1,3,547.74],[2,2.98,547.74]],"batl":[[2,3.4,595.73]],"ltp":3.2,"tv":22021.73,"id":2497008}],"tv":73663.48}]}
{"op":"mcm","clk":"4299129191","pt":1632579775797,"mc":[{"id":"1.188136695","rc":[{"trd":[[1.44,34.88],[1.45,486.01]],"batb":[[0,1.44,518.08],[1,1.43,1479.24]],"batl":[[0,1.45,196.67],[1,1.48,1430.59],[2,1.49,578.26]],"ltp":1.45,"tv":51803.57,"id":5300737},{"trd":[[3.2,17.11],[3.25,6],[3.3,3]],"batb":[[0,3.15,263.29],[1,3.05,564.35],[2,3,846.2]],"batl":[[0,3.35,78.3],[1,3.4,595.73],[2,3.45,618.11]],"ltp":3.2,"tv":22046.84,"id":2497008}],"tv":73850.42}]}
{"op":"mcm","clk":"4299129436","pt":1632579776605,"mc":[{"id":"1.188136695","rc":[{"trd":[[1.45,488.01]],"batl":[[0,1.45,195.67],[1,1.48,1065.09]],"ltp":1.45,"tv":51805.58,"id":5300737}],"tv":73852.42}]}
{"op":"mcm","clk":"4299129824","pt":1632579777702,"mc":[{"id":"1.188136695","rc":[{"batl":[[0,1.48,1065.09],[1,1.49,578.26],[2,1.52,40]],"ltp":1.45,"tv":51805.58,"id":5300737}]}]}
{"op":"mcm","clk":"4299130204","pt":1632579778829,"mc":[{"id":"1.188136695","rc":[{"trd":[[1.46,18.1]],"batb":[[0,1.44,867.74]],"batl":[[0,1.46,343.87],[1,1.48,1065.09],[2,1.49,578.26]],"ltp":1.46,"tv":51807.58,"id":5300737},{"batl":[[0,3.3,2],[1,3.35,78.3],[2,3.4,595.73]],"ltp":3.2,"tv":22046.84,"id":2497008}],"tv":73854.42}]}
{"op":"mcm","clk":"4299130479","pt":1632579779582,"mc":[{"id":"1.188136695","rc":[{"trd":[[1.44,62.9]],"batb":[[0,1.44,853.73]],"ltp":1.44,"tv":51835.6,"id":5300737}],"tv":73882.45}]}
{"op":"mcm","clk":"4299130793","pt":1632579780655,"mc":[{"id":"1.188136695","rc":[{"batb":[[0,1.45,342.08],[1,1.44,853.73],[2,1.43,1479.24]],"batl":[[0,1.47,337.43]],"ltp":1.44,"tv":51835.6,"id":5300737}]}]}
{"op":"mcm","clk":"4299131223","pt":1632579781795,"mc":[{"id":"1.188136695","rc":[{"batb":[[0,1.45,346.09],[2,1.43,1509.67]],"ltp":1.44,"tv":51835.6,"id":5300737},{"batb":[[2,3,940.74]],"batl":[[1,3.35,80.3],[2,3.4,682.65]],"ltp":3.2,"tv":22046.84,"id":2497008}]}]}
{"op":"mcm","clk":"4299131532","pt":1632579782686,"mc":[{"id":"1.188136695","rc":[{"batb":[[0,1.45,353.85],[1,1.44,880.65]],"ltp":1.44,"tv":51835.6,"id":5300737},{"batl":[[0,3.3,4.05]],"ltp":3.2,"tv":22046.84,"id":2497008}]}]}
{"op":"mcm","clk":"4299131863","pt":1632579783741,"mc":[{"id":"1.188136695","rc":[{"trd":[[1.47,1508.5]],"batl":[[0,1.47,336.43]],"ltp":1.47,"tv":51837.6,"id":5300737},{"batl":[[0,3.25,3],[1,3.3,4.05],[2,3.35,80.3]],"ltp":3.2,"tv":22046.84,"id":2497008}],"tv":73884.45}]}
{"op":"mcm","clk":"4299132247","pt":1632579784802,"mc":[{"id":"1.188136695","rc":[{"batb":[[0,1.45,354.37],[1,1.44,900.65]],"batl":[[0,1.47,890.13],[1,1.48,1556.22]],"ltp":1.47,"tv":51837.6,"id":5300737},{"batb":[[1,3.1,182.89],[2,3.05,802.66]],"ltp":3.2,"tv":22046.84,"id":2497008}]}]}
{"op":"mcm","clk":"4299132911","pt":1632579786821,"mc":[{"id":"1.188136695","rc":[{"batb":[[0,1.45,29.54],[1,1.44,52.92],[2,1.43,37.43]],"batl":[[0,1.48,46.65],[1,1.5,194.8],[2,1.51,239.12]],"ltp":1.47,"tv":51837.6,"id":5300737},{"batb":[[0,3,393],[1,2.98,98.25],[2,2.96,104.05]],"batl":[[0,3.25,2],[2,3.35,2]],"ltp":3.2,"tv":22046.84,"id":2497008}]}]}
{"op":"mcm","clk":"4299133230","pt":1632579787794,"mc":[{"id":"1.188136695","rc":[{"trd":[[1.45,495.03]],"batb":[[0,1.45,1.02],[2,1.43,7]],"ltp":1.45,"tv":51844.62,"id":5300737},{"batl":[[0,3.3,4.05],[1,3.4,86.91],[2,3.45,93.83]],"ltp":3.2,"tv":22046.84,"id":2497008}],"tv":73891.47}]}
{"op":"mcm","clk":"4299133533","pt":1632579788809,"mc":[{"id":"1.188136695","rc":[{"batb":[[2,1.42,230.75]],"ltp":1.45,"tv":51844.62,"id":5300737}]}]}
{"op":"mcm","clk":"4299133884","pt":1632579789794,"mc":[{"id":"1.188136695","rc":[{"batb":[[0,1.45,285.92],[2,1.42,903.25]],"batl":[[2,1.51,1159.05]],"ltp":1.45,"tv":51844.62,"id":5300737}]}]}
{"op":"mcm","clk":"4299134220","pt":1632579790715,"mc":[{"id":"1.188136695","rc":[{"batb":[[0,1.44,53.42],[1,1.42,903.25],[2,1.41,1586.53]],"batl":[[1,1.51,948.43],[2,1.52,574.97]],"ltp":1.45,"tv":51844.62,"id":5300737},{"batb":[[0,3,301.46],[1,2.96,2.38],[2,2.84,2.22]],"ltp":3.2,"tv":22046.84,"id":2497008}]}]}
{"op":"mcm","clk":"4299134536","pt":1632579791624,"mc":[{"id":"1.188136695","rc":[{"trd":[[1.43,21.35],[1.44,168.74],[1.45,496.04]],"batb":[[0,1.42,699.7],[1,1.41,1586.53],[2,1.4,278.53]],"batl":[[0,1.43,2206.65],[1,1.44,458.56],[2,1.45,12.86]],"ltp":1.43,"tv":51972.82,"id":5300737},{"trd":[[3.3,7.05]],"batb":[[0,3,298.46]],"batl":[[0,3.4,86.91],[1,3.45,93.83],[2,3.5,91.04]],"ltp":3.3,"tv":22050.89,"id":2497008}],"tv":74023.72}]}
{"op":"mcm","clk":"4299134900","pt":1632579792831,"mc":[{"id":"1.188136695","rc":[{"batb":[[1,1.41,1636.53]],"batl":[[0,1.43,2216.79],[2,1.45,121.49]],"ltp":1.43,"tv":51972.82,"id":5300737},{"batb":[[0,3.2,845.87],[1,3,298.46],[2,2.96,2.38]],"ltp":3.3,"tv":22050.89,"id":2497008}]}]}
{"op":"mcm","clk":"4299135227","pt":1632579793827,"mc":[{"id":"1.188136695","rc":[{"batb":[[2,1.4,1507.99]],"batl":[[0,1.43,10.14]],"ltp":1.43,"tv":51972.82,"id":5300737},{"batb":[[1,3,303.46]],"ltp":3.3,"tv":22050.89,"id":2497008}]}]}
{"op":"mcm","clk":"4299135543","pt":1632579794726,"mc":[{"id":"1.188136695","rc":[{"trd":[[1.42,28],[1.43,34.71],[1.45,513.6]],"batb":[[0,1.42,685.7]],"batl":[[0,1.45,112.71],[1,1.46,1149.68],[2,1.47,1640.59]],"ltp":1.42,"tv":52031.74,"id":5300737},{"trd":[[3.2,42.91],[3.3,10.05],[3.4,12]],"batb":[[0,3.25,243],[1,3.2,832.97],[2,3.1,273.94]],"batl":[[0,3.4,80.91]],"ltp":3.4,"tv":22091.69,"id":2497008}],"tv":74123.43}]}
{"op":"mcm","clk":"4299135915","pt":1632579795744,"mc":[{"id":"1.188136695","rc":[{"trd":[[1.45,517.11]],"batb":[[0,1.42,692.7]],"batl":[[0,1.45,108.63]],"ltp":1.45,"tv":52035.26,"id":5300737},{"batl":[[0,3.3,3],[1,3.4,80.91],[2,3.45,93.83]],"ltp":3.4,"tv":22091.69,"id":2497008}],"tv":74126.95}]}
{"op":"mcm","clk":"4299136555","pt":1632579797637,"mc":[{"id":"1.188136695","rc":[{"trd":[[1.45,529.11]],"batb":[[0,1.44,5],[1,1.42,692.7],[2,1.41,1586.53]],"batl":[[0,1.45,102.63]],"ltp":1.45,"tv":52047.26,"id":5300737}],"tv":74138.95}]}
{"op":"mcm","clk":"4299136886","pt":1632579798636,"mc":[{"id":"1.188136695","rc":[{"batb":[[0,1.44,39],[1,1.43,378.85],[2,1.42,1018.12]],"batl":[[0,1.45,421.31]],"ltp":1.45,"tv":52047.26,"id":5300737},{"trd":[[3.25,18]],"batb":[[0,3.25,237]],"ltp":3.25,"tv":22103.69,"id":2497008}],"tv":74150.95}]}
{"op":"mcm","clk":"4299137214","pt":1632579799647,"mc":[{"id":"1.188136695","rc":[{"batb":[[0,1.44,107]],"ltp":1.45,"tv":52047.26,"id":5300737},{"trd":[[3.25,20.37]],"batb":[[0,3.25,235.82]],"batl":[[0,3.3,4.33]],"ltp":3.25,"tv":22106.06,"id":2497008}],"tv":74153.32}]}
{"op":"mcm","clk":"4299137628","pt":1632579800830,"mc":[{"id":"1.188136695","rc":[{"batb":[[0,1.44,211.67],[1,1.43,689.34],[2,1.42,1068.12]],"ltp":1.45,"tv":52047.26,"id":5300737}]}]}
{"op":"mcm","clk":"4299137922","pt":1632579801726,"mc":[{"id":"1.188136695","rc":[{"trd":[[1.45,537.69]],"batl":[[0,1.45,821.58],[1,1.46,1617.67]],"ltp":1.45,"tv":52055.83,"id":5300737},{"batb":[[1,3.2,1016.28],[2,3.15,216.9]],"ltp":3.25,"tv":22106.06,"id":2497008}],"tv":74161.89}]}
{"op":"mcm","clk":"4299138245","pt":1632579802743,"mc":[{"id":"1.188136695","rc":[{"trd":[[1.44,194.46]],"batb":[[0,1.44,266.81],[1,1.43,312.84],[2,1.42,1073.89]],"ltp":1.44,"tv":52081.55,"id":5300737},{"trd":[[3.25,24.46]],"batb":[[0,3.25,233.77]],"ltp":3.25,"tv":22110.16,"id":2497008}],"tv":74191.71}]}
{"op":"mcm","clk":"4299138533","pt":1632579803557,"mc":[{"id":"1.188136695","rc":[{"batb":[[1,1.43,541.7]],"batl":[[1,1.46,1893.51]],"ltp":1.44,"tv":52081.55,"id":5300737}]}]}
{"op":"mcm","clk":"4299138965","pt":1632579804766,"mc":[{"id":"1.188136695","rc":[{"batb":[[0,1.44,733.12],[1,1.43,542.05]],"batl":[[0,1.45,1062.58]],"ltp":1.44,"tv":52081.55,"id":5300737}]}]}
{"op":"mcm","clk":"4299139318","pt":1632579805781,"mc":[{"id":"1.188136695","rc":[{"trd":[[1.45,1295.38]],"batb":[[1,1.43,744.14],[2,1.42,1260.47]],"batl":[[0,1.45,683.74],[1,1.46,1820.76]],"ltp":1.45,"tv":52839.24,"id":5300737},{"trd":[[3.25,26.23]],"batb":[[0,3.25,234.45]],"batl":[[0,3.3,91.76],[1,3.35,100.28],[2,3.4,80.91]],"ltp":3.25,"tv":22111.92,"id":2497008}],"tv":74951.16}]}
{"op":"mcm","clk":"4299139636","pt":1632579806653,"mc":[{"id":"1.188136695","rc":[{"trd":[[1.45,1301.38]],"batb":[[0,1.44,738.12]],"batl":[[0,1.45,680.74]],"ltp":1.45,"tv":52845.24,"id":5300737},{"trd":[[3.25,35.35]],"batb":[[0,3.25,229.9]],"ltp":3.25,"tv":22121.04,"id":2497008}],"tv":74966.28}]}
{"op":"mcm","clk":"4299139983","pt":1632579807714,"mc":[{"id":"1.188136695","rc":[{"trd":[[1.45,1338.96]],"batb":[[1,1.43,737.23]],"batl":[[0,1.45,661.95]],"ltp":1.45,"tv":52882.81,"id":5300737}],"tv":75003.86}]}
{"op":"mcm","clk":"4299140301","pt":1632579808779,"mc":[{"id":"1.188136695","rc":[{"trd":[[1.45,1340]],"batb":[[0,1.44,788.12]],"batl":[[0,1.45,661.43]],"ltp":1.45,"tv":52883.85,"id":5300737},{"trd":[[3.25,38.04]],"batb":[[0,3.25,228.55]],"ltp":3.25,"tv":22123.74,"id":2497008}],"tv":75007.59}]}
{"op":"mcm","clk":"4299140633","pt":1632579809758,"mc":[{"id":"1.188136695","rc":[{"trd":[[1.45,1341.8]],"batb":[[1,1.43,736.88]],"batl":[[0,1.45,660.53]],"ltp":1.45,"tv":52885.65,"id":5300737},{"trd":[[3.25,43.89]],"batb":[[0,3.25,225.62]],"ltp":3.25,"tv":22129.59,"id":2497008}],"tv":75015.25}]}
{"op":"mcm","clk":"4299141318","pt":1632579811762,"mc":[{"id":"1.188136695","rc":[{"trd":[[1.45,1382.46]],"batb":[[0,1.44,795.12],[1,1.43,735.93]],"batl":[[0,1.45,640.2]],"ltp":1.45,"tv":52926.32,"id":5300737},{"trd":[[3.25,53.81]],"batb":[[0,3.25,220.66]],"ltp":3.25,"tv":22139.5,"id":2497008}],"tv":75065.83}]}
{"op":"mcm","clk":"4299141638","pt":1632579812752,"mc":[{"id":"1.188136695","rc":[{"batb":[[0,1.44,745.12]],"ltp":1.45,"tv":52926.32,"id":5300737},{"trd":[[3.25,59.81]],"batb":[[0,3.25,217.66]],"batl":[[0,3.3,90.98]],"ltp":3.25,"tv":22145.5,"id":2497008}],"tv":75071.83}]}
{"op":"mcm","clk":"4299141981","pt":1632579813805,"mc":[{"id":"1.188136695","rc":[{"trd":[[3.25,103.81]],"batb":[[0,3.25,195.66]],"ltp":3.25,"tv":22189.5,"id":2497008}],"tv":75115.83}]}
{"op":"mcm","clk":"4299142328","pt":1632579814750,"mc":[{"id":"1.188136695","rc":[{"trd":[[1.44,196.56],[1.45,1389.48]],"batb":[[0,1.44,744.07]],"batl":[[0,1.45,636.69]],"ltp":1.45,"tv":52935.44,"id":5300737}],"tv":75124.95}]}
{"op":"mcm","clk":"4299142676","pt":1632579815757,"mc":[{"id":"1.188136695","rc":[{"trd":[[1.45,1500.19]],"batl":[[0,1.45,708.15]],"ltp":1.45,"tv":53046.14,"id":5300737}],"tv":75235.65}]}
{"op":"mcm","clk":"4299143002","pt":1632579816750,"mc":[{"id":"1.188136695","rc":[{"trd":[[1.45,1502.98]],"batl":[[0,1.45,706.75]],"ltp":1.45,"tv":53048.94,"id":5300737}],"tv":75238.45}]}
{"op":"mcm","clk":"4299143310","pt":1632579817658,"mc":[{"id":"1.188136695","rc":[{"trd":[[3.25,104.51]],"batb":[[0,3.25,195.31]],"ltp":3.25,"tv":22190.2,"id":2497008}],"tv":75239.15}]}
{"op":"mcm","clk":"4299143679","pt":1632579818794,"mc":[{"id":"1.188136695","rc":[{"trd":[[1.45,1538.98]],"batb":[[0,1.44,745.83]],"batl":[[0,1.45,688.75]],"ltp":1.45,"tv":53084.94,"id":5300737}],"tv":75275.15}]}
{"op":"mcm","clk":"4299144041","pt":1632579819759,"mc":[{"id":"1.188136695","rc":[{"trd":[[1.44,727.51]],"batb":[[0,1.44,204.33],[1,1.43,230.6],[2,1.42,12.77]],"batl":[[0,1.48,46.65],[1,1.5,191.93],[2,1.51,220.25]],"ltp":1.44,"tv":53615.89,"id":5300737},{"trd":[[3.25,106.08]],"batb":[[0,3.1,274.73],[1,3,77.77],[2,2.98,112.48]],"batl":[[0,3.3,3.55],[1,3.45,1],[2,3.5,2.01]],"ltp":3.25,"tv":22191.77,"id":2497008}],"tv":75807.66}]}
{"op":"mcm","clk":"4299144381","pt":1632579820659,"mc":[{"id":"1.188136695","rc":[{"batb":[[0,1.44,197.33],[2,1.42,5.77]],"ltp":1.44,"tv":53615.89,"id":5300737},{"trd":[[3.25,107.65]],"batb":[[0,3.1,273.94]],"batl":[[0,3.25,5.01],[1,3.45,1.55]],"ltp":3.25,"tv":22193.34,"id":2497008}],"tv":75809.24}]}
{"op":"mcm","clk":"4299144637","pt":1632579821367,"mc":[{"id":"1.188136695","rc":[{"batb":[[0,1.44,197.68]],"ltp":1.44,"tv":53615.89,"id":5300737}]}]}
{"op":"mcm","clk":"4299145014","pt":1632579822475,"mc":[{"id":"1.188136695","rc":[{"trd":[[1.44,740.02],[1.45,1539.68]],"batb":[[0,1.44,191.07],[1,1.43,230.25]],"batl":[[1,1.49,628.29],[2,1.5,757.86]],"ltp":1.44,"tv":53629.1,"id":5300737},{"trd":[[3.1,6]],"batb":[[0,3.1,270.94]],"batl":[[0,3.2,3],[1,3.25,14.74],[2,3.45,1.55]],"ltp":3.1,"tv":22199.34,"id":2497008}],"tv":75828.45}]}
{"op":"mcm","clk":"4299145467","pt":1632579823753,"mc":[{"id":"1.188136695","rc":[{"batl":[[0,1.47,20],[1,1.48,46.65],[2,1.49,46.5]],"ltp":1.44,"tv":53629.1,"id":5300737},{"batl":[[0,3.25,14.74],[1,3.45,1.55],[2,3.5,2.01]],"ltp":3.1,"tv":22199.34,"id":2497008}]}]}
{"op":"mcm","clk":"4299145863","pt":1632579824772,"mc":[{"id":"1.188136695","rc":[{"batb":[[1,1.43,228.85]],"ltp":1.44,"tv":53629.1,"id":5300737},{"batl":[[0,3.25,67.84]],"ltp":3.1,"tv":22199.34,"id":2497008}]}]}
{"op":"mcm","clk":"4299146165","pt":1632579825650,"mc":[{"id":"1.188136695","rc":[{"batl":[[0,1.46,40.25],[1,1.47,20],[2,1.48,60.29]],"ltp":1.44,"tv":53629.1,"id":5300737},{"batb":[[0,3.2,40.27],[1,3.1,270.94],[2,3,80.38]],"batl":[[1,3.3,42.8],[2,3.45,1]],"ltp":3.1,"tv":22199.34,"id":2497008}]}]}
{"op":"mcm","clk":"4299146568","pt":1632579826755,"mc":[{"id":"1.188136695","rc":[{"batb":[[0,1.45,2.88],[1,1.44,191.07],[2,1.43,228.85]],"batl":[[0,1.47,20],[1,1.48,60.29],[2,1.49,46.5]],"ltp":1.44,"tv":53629.1,"id":5300737},{"batb":[[0,3.1,270.94],[1,3,77.77],[2,2.98,112.48]],"batl":[[0,3.25,69.6],[1,3.45,1.55],[2,3.5,2.01]],"ltp":3.1,"tv":22199.34,"id":2497008}]}]}
{"op":"mcm","clk":"4299146890","pt":1632579827642,"mc":[{"id":"1.188136695","rc":[{"trd":[[1.44,832.91],[1.45,1545.44]],"batb":[[0,1.44,144.63],[1,1.43,228.85],[2,1.42,5.77]],"batl":[[0,1.47,40]],"ltp":1.44,"tv":53727.75,"id":5300737}],"tv":75927.1}]}
{"op":"mcm","clk":"4299147032","pt":1632579828077,"mc":[{"id":"1.188136695","rc":[{"batl":[[0,1.45,1009.46],[1,1.46,628.54],[2,1.47,40]],"ltp":1.44,"tv":53727.75,"id":5300737}]}]}
{"op":"mcm","clk":"4299147615","pt":1632579829740,"mc":[{"id":"1.188136695","rc":[{"batl":[[2,1.47,225]],"ltp":1.44,"tv":53727.75,"id":5300737}]}]}
{"op":"mcm","clk":"4299147940","pt":1632579830776,"mc":[{"id":"1.188136695","rc":[{"trd":[[1.44,853.38],[1.45,2104.52]],"batb":[[0,1.44,134.39]],"batl":[[0,1.45,729.92]],"ltp":1.44,"tv":54307.29,"id":5300737}],"tv":76506.64}]}
{"op":"mcm","clk":"4299148284","pt":1632579831780,"mc":[{"id":"1.188136695","rc":[{"batl":[[2,1.47,40]],"ltp":1.44,"tv":54307.29,"id":5300737}]}]}
{"op":"mcm","clk":"4299148645","pt":1632579832737,"mc":[{"id":"1.188136695","rc":[{"batl":[[0,1.47,40],[1,1.48,60.29],[2,1.49,46.5]],"ltp":1.44,"tv":54307.29,"id":5300737},{"batl":[[0,3.25,59.87]],"ltp":3.1,"tv":22199.34,"id":2497008}]}]}
{"op":"mcm","clk":"4299148838","pt":1632579833351,"mc":[{"id":"1.188136695","rc":[{"trd":[[1.45,2119.6]],"ltp":1.45,"tv":54322.38,"id":5300737},{"trd":[[3.2,43.12]],"ltp":3.2,"tv":22199.56,"id":2497008}],"tv":76521.94}]}
{"op":"mcm","clk":"4299149275","pt":1632579834554,"mc":[{"id":"1.188136695","rc":[{"trd":[[1.47,1510.6]],"batl":[[0,1.47,38.95]],"ltp":1.47,"tv":54324.48,"id":5300737}],"tv":76524.04}]}
{"op":"mcm","clk":"4299149429","pt":1632579835092,"mc":[{"id":"1.188136695","rc":[{"batl":[[2,1.49,513.86]],"ltp":1.47,"tv":54324.48,"id":5300737},{"batl":[[0,3.25,58.11]],"ltp":3.2,"tv":22199.56,"id":2497008}]}]}
{"op":"mcm","clk":"4299149996","pt":1632579836752,"mc":[{"id":"1.188136695","rc":[{"trd":[[1.47,1537.88]],"batb":[[0,1.45,26.55],[1,1.44,134.39],[2,1.43,228.85]],"batl":[[0,1.47,25.31]],"ltp":1.47,"tv":54351.76,"id":5300737},{"batb":[[1,3,80.27]],"batl":[[0,3.2,9.73],[1,3.25,58.11],[2,3.45,1.55]],"ltp":3.2,"tv":22199.56,"id":2497008}],"tv":76551.32}]}
{"op":"mcm","clk":"4299150359","pt":1632579837758,"mc":[{"id":"1.188136695","rc":[{"batb":[[0,1.45,142.28]],"ltp":1.47,"tv":54351.76,"id":5300737},{"batb":[[1,3,77.77]],"ltp":3.2,"tv":22199.56,"id":2497008}]}]}
{"op":"mcm","clk":"4299151041","pt":1632579839683,"mc":[{"id":"1.188136695","rc":[{"trd":[[1.45,2138.46]],"batb":[[0,1.45,132.85]],"ltp":1.45,"tv":54370.62,"id":5300737}],"tv":76570.18}]}
{"op":"mcm","clk":"4299151318","pt":1632579840462,"mc":[{"id":"1.188136695","rc":[{"trd":[[1.45,2139.16]],"batb":[[0,1.45,136.01]],"ltp":1.45,"tv":54371.32,"id":5300737}],"tv":76570.88}]}
{"op":"mcm","clk":"4299151740","pt":1632579841695,"mc":[{"id":"1.188136695","rc":[{"trd":[[1.47,1588.5]],"batb":[[0,1.46,458.56],[1,1.45,135.66],[2,1.44,2356.39]],"batl":[[0,1.48,60.29],[1,1.49,513.86],[2,1.5,757.82]],"ltp":1.47,"tv":54421.94,"id":5300737}],"tv":76621.5}]}
{"op":"mcm","clk":"4299152520","pt":1632579843693,"mc":[{"id":"1.188136695","rc":[{"batb":[[1,3,80.27]],"batl":[[2,3.3,87.48]],"ltp":3.2,"tv":22199.56,"id":2497008}]}]}
{"op":"mcm","clk":"4299152916","pt":1632579844796,"mc":[{"id":"1.188136695","rc":[{"batb":[[1,1.45,1069.02],[2,1.44,3032.48]],"ltp":1.47,"tv":54421.94,"id":5300737},{"trd":[[3.1,33.02]],"batb":[[0,3.1,257.43],[1,3,77.77]],"batl":[[1,3.25,5.01],[2,3.3,522.14]],"ltp":3.1,"tv":22226.58,"id":2497008}],"tv":76648.52}]}
{"op":"mcm","clk":"4299153300","pt":1632579845810,"mc":[{"id":"1.188136695","rc":[{"batb":[[0,1.47,8.03],[1,1.46,458.56],[2,1.45,1069.02]],"ltp":1.47,"tv":54421.94,"id":5300737},{"trd":[[3.1,33.22]],"batb":[[0,3.1,257.34],[2,2.98,234.82]],"batl":[[1,3.25,5.56]],"ltp":3.1,"tv":22226.78,"id":2497008}],"tv":76648.72}]}
{"op":"mcm","clk":"4299153838","pt":1632579847398,"mc":[{"id":"1.188136695","rc":[{"batl":[[0,3.15,53.1],[1,3.2,9.73],[2,3.25,5.56]],"ltp":3.1,"tv":22226.78,"id":2497008}]}]}
{"op":"mcm","clk":"4299154310","pt":1632579848707,"mc":[{"id":"1.188136695","rc":[{"trd":[[1.48,2022.13]],"batb":[[2,1.45,1068.16]],"batl":[[0,1.48,7]],"ltp":1.48,"tv":54595.26,"id":5300737},{"trd":[[3.1,66.82]],"batb":[[0,3.1,230.94],[1,3.05,4],[2,3,77.77]],"batl":[[1,3.2,12.73]],"ltp":3.1,"tv":22260.38,"id":2497008}],"tv":76855.65}]}
{"op":"mcm","clk":"4299154577","pt":1632579849509,"mc":[{"id":"1.188136695","rc":[{"batb":[[0,1.47,14.03],[1,1.46,465.56]],"ltp":1.48,"tv":54595.26,"id":5300737},{"batl":[[0,3.15,56.1],[2,3.25,5.01]],"ltp":3.1,"tv":22260.38,"id":2497008}]}]}
{"op":"mcm","clk":"4299154814","pt":1632579850201,"mc":[{"id":"1.188136695","rc":[{"trd":[[1.46,300.98],[1.47,1616.55]],"batb":[[0,1.46,585.33],[1,1.45,1068.16],[2,1.44,1349.51]],"batl":[[0,1.48,264.68]],"ltp":1.46,"tv":54906.2,"id":5300737}],"tv":77166.59}]}
{"op":"mcm","clk":"4299155334","pt":1632579851806,"mc":[{"id":"1.188136695","rc":[{"batb":[[0,1.47,253.59],[1,1.46,268.21],[2,1.45,1068.16]],"batl":[[0,1.48,257.68],[1,1.49,770.04]],"ltp":1.46,"tv":54906.2,"id":5300737},{"batb":[[0,3.1,227.94],[1,3,77.77],[2,2.98,234.82]],"ltp":3.1,"tv":22260.38,"id":2497008}]}]}
{"op":"mcm","clk":"4299155363","pt":1632579851869,"mc":[{"id":"1.188136695","rc":[{"batl":[[1,1.49,764.04]],"ltp":1.46,"tv":54906.2,"id":5300737},{"trd":[[3.1,67.52]],"batb":[[0,3.1,227.59]],"ltp":3.1,"tv":22261.08,"id":2497008}],"tv":77167.29}]}
{"op":"mcm","clk":"4299155986","pt":1632579853726,"mc":[{"id":"1.188136695","rc":[{"batb":[[0,1.46,268.21],[1,1.45,1068.16],[2,1.44,1379.93]],"batl":[[0,1.48,807.95],[1,1.49,1275.74]],"ltp":1.46,"tv":54906.2,"id":5300737},{"batb":[[1,3.05,185.49],[2,3,331.92]],"ltp":3.1,"tv":22261.08,"id":2497008}]}]}
{"op":"mcm","clk":"4299156250","pt":1632579854407,"mc":[{"id":"1.188136695","rc":[{"trd":[[1.48,2034.83]],"batb":[[0,1.46,694.2],[1,1.45,1628.71]],"batl":[[0,1.48,801.6]],"ltp":1.48,"tv":54918.9,"id":5300737},{"trd":[[3.1,73.52]],"batb":[[0,3.1,224.6]],"batl":[[1,3.2,207.08],[2,3.25,255.1]],"ltp":3.1,"tv":22267.08,"id":2497008}],"tv":77185.99}]}
{"op":"mcm","clk":"4299157264","pt":1632579857316,"mc":[{"id":"1.188136695","rc":[{"batl":[[1,3.2,197.35]],"ltp":3.1,"tv":22267.08,"id":2497008}]}]}
{"op":"mcm","clk":"4299157739","pt":1632579858806,"mc":[{"id":"1.188136695","rc":[{"batb":[[0,1.45,1063.16],[1,1.44,1373.93],[2,1.43,215.57]],"batl":[[0,1.48,168],[1,1.49,467.36],[2,1.5,565.89]],"ltp":1.48,"tv":54918.9,"id":5300737},{"batb":[[1,2.98,122.35],[2,2.96,2.38]],"batl":[[0,3.15,53.1],[1,3.25,5.01],[2,3.3,2.05]],"ltp":3.1,"tv":22267.08,"id":2497008}]}]}
{"op":"mcm","clk":"4299158109","pt":1632579859797,"mc":[{"id":"1.188136695","rc":[{"batb":[[0,1.45,16.77],[1,1.44,158.05]],"batl":[[0,1.51,28.5],[1,1.53,43.5],[2,1.54,161.82]],"ltp":1.48,"tv":54918.9,"id":5300737},{"trd":[[3.15,0.7]],"batb":[[0,2.98,122.35],[1,2.96,2.38],[2,2.88,2.71]],"batl":[[0,3.15,52.75]],"ltp":3.15,"tv":22267.78,"id":2497008}],"tv":77186.69}]}
{"op":"mcm","clk":"4299158449","pt":1632579860794,"mc":[{"id":"1.188136695","rc":[{"batb":[[0,1.48,11.27],[1,1.45,16.77],[2,1.44,158.05]],"ltp":1.48,"tv":54918.9,"id":5300737},{"batl":[[0,3.1,9.73]],"ltp":3.15,"tv":22267.78,"id":2497008}]}]}
{"op":"mcm","clk":"4299158748","pt":1632579861713,"mc":[{"id":"1.188136695","rc":[{"batb":[[0,1.48,12.22]],"batl":[[0,1.51,33.5]],"ltp":1.48,"tv":54918.9,"id":5300737}]}]}
{"op":"mcm","clk":"4299159098","pt":1632579862754,"mc":[{"id":"1.188136695","rc":[{"batl":[[0,1.51,5]],"ltp":1.48,"tv":54918.9,"id":5300737},{"batb":[[1,2.88,2.71],[2,2.84,87.6]],"ltp":3.15,"tv":22267.78,"id":2497008}]}]}
{"op":"mcm","clk":"4299159220","pt":1632579863109,"mc":[{"id":"1.188136695","rc":[{"batl":[[0,3.1,67.36]],"ltp":3.15,"tv":22267.78,"id":2497008}]}]}
{"op":"mcm","clk":"4299159819","pt":1632579864807,"mc":[{"id":"1.188136695","rc":[{"batb":[[0,1.48,16.08]],"ltp":1.48,"tv":54918.9,"id":5300737},{"batl":[[0,3.1,120.1]],"ltp":3.15,"tv":22267.78,"id":2497008}]}]}
{"op":"mcm","clk":"4299160047","pt":1632579865531,"mc":[{"id":"1.188136695","rc":[{"trd":[[1.48,2066.99]],"batb":[[0,1.45,16.77],[1,1.44,158.05],[2,1.43,215.57]],"batl":[[0,1.51,52.5]],"ltp":1.48,"tv":54951.06,"id":5300737},{"trd":[[3.1,114]],"batb":[[1,2.96,2.63],[2,2.88,2.71]],"batl":[[0,3.1,99.86]],"ltp":3.1,"tv":22308.26,"id":2497008}],"tv":77259.33}]}
{"op":"mcm","clk":"4299160391","pt":1632579866510,"mc":[{"id":"1.188136695","rc":[{"trd":[[1.47,1651.96]],"ltp":1.47,"tv":54986.47,"id":5300737},{"trd":[[3.1,130.79]],"batl":[[0,3.1,83.07]],"ltp":3.1,"tv":22325.05,"id":2497008}],"tv":77311.53}]}
{"op":"mcm","clk":"4299160809","pt":1632579867824,"mc":[{"id":"1.188136695","rc":[{"batb":[[0,1.48,2.55],[1,1.45,503.22],[2,1.44,834.78]],"batl":[[0,1.49,996.28],[1,1.5,562.34],[2,1.51,52.5]],"ltp":1.47,"tv":54986.47,"id":5300737}]}]}
{"op":"mcm","clk":"4299161547","pt":1632579870331,"mc":[{"id":"1.188136695","rc":[{"trd":[[1.49,2228.39]],"batb":[[1,1.45,16.77],[2,1.44,158.05]],"batl":[[0,1.51,52.5],[1,1.53,43.5],[2,1.54,161.82]],"ltp":1.49,"tv":55015.73,"id":5300737}],"tv":77340.79}]}
{"op":"mcm","clk":"4299161983","pt":1632579871710,"mc":[{"id":"1.188136695","rc":[{"trd":[[1.48,2072.08],[1.51,84.12]],"batb":[[0,1.45,16.77],[1,1.44,158.05],[2,1.43,215.57]],"batl":[[0,1.49,239]],"ltp":1.51,"tv":55090.95,"id":5300737},{"batb":[[1,2.88,2.71],[2,2.84,87.6]],"ltp":3.1,"tv":22325.05,"id":2497008}],"tv":77416.0}]}
{"op":"mcm","clk":"4299162266","pt":1632579872630,"mc":[{"id":"1.188136695","rc":[{"batb":[[0,1.48,88.06],[1,1.45,16.77],[2,1.44,158.05]],"batl":[[0,1.53,43.5],[1,1.54,161.82],[2,1.55,165.24]],"ltp":1.51,"tv":55090.95,"id":5300737},{"batl":[[0,3.1,30.33]],"ltp":3.1,"tv":22325.05,"id":2497008}]}]}
{"op":"mcm","clk":"4299162616","pt":1632579873772,"mc":[{"id":"1.188136695","rc":[{"trd":[[1.48,2078.94],[1.51,85.88]],"batb":[[0,1.48,84.63]],"batl":[[0,1.53,803.12],[1,1.54,670.56]],"ltp":1.48,"tv":55099.56,"id":5300737},{"trd":[[2.98,86.29]],"batb":[[0,2.98,119.72]],"ltp":2.98,"tv":22329.41,"id":2497008}],"tv":77428.98}]}
{"op":"mcm","clk":"4299162974","pt":1632579874821,"mc":[{"id":"1.188136695","rc":[{"trd":[[1.48,2189.05]],"batb":[[0,1.48,29.58]],"batl":[[0,1.52,6],[1,1.53,803.12],[2,1.54,670.56]],"ltp":1.48,"tv":55209.68,"id":5300737},{"batb":[[1,2.96,2.13],[2,2.88,2.71]],"ltp":2.98,"tv":22329.41,"id":2497008}],"tv":77539.09}]}
{"op":"mcm","clk":"4299163071","pt":1632579875154,"mc":[{"id":"1.188136695","rc":[{"batb":[[1,2.88,2.71],[2,2.84,87.6]],"batl":[[0,3,52.75],[1,3.1,30.33],[2,3.25,5.01]],"ltp":2.98,"tv":22329.41,"id":2497008}]}]}
{"op":"mcm","clk":"4299163537","pt":1632579876642,"mc":[{"id":"1.188136695","rc":[{"batb":[[0,1.49,69.85],[1,1.48,29.58],[2,1.45,16.77]],"batl":[[0,1.51,5],[1,1.52,6],[2,1.53,803.12]],"ltp":1.48,"tv":55209.68,"id":5300737}]}]}
{"op":"mcm","clk":"4299163853","pt":1632579877647,"mc":[{"id":"1.188136695","rc":[{"trd":[[1.5,861.72]],"ltp":1.5,"tv":55211.28,"id":5300737},{"trd":[[3,128.94]],"batb":[[2,2.62,1]],"batl":[[0,3,51.94]],"ltp":3.0,"tv":22330.21,"id":2497008}],"tv":77541.5}]}
{"op":"mcm","clk":"4299164231","pt":1632579878820,"mc":[{"id":"1.188136695","rc":[{"trd":[[1.44,1180.79],[1.45,2172.7],[1.47,1715.91],[1.48,2248.21],[1.49,2368.09]],"batb":[[0,1.43,215.57],[1,1.42,227.69],[2,1.41,1313.46]],"batl":[[2,1.54,20]],"ltp":1.44,"tv":55835.04,"id":5300737},{"trd":[[3.1,161.12],[3.25,112.66]],"batl":[[0,3.3,2.05],[1,3.35,78.11],[2,3.4,83.42]],"ltp":3.25,"tv":22365.54,"id":2497008}],"tv":78200.59}]}
{"op":"mcm","clk":"4299164404","pt":1632579879424,"mc":[{"id":"1.188136695","rc":[{"batb":[[0,1.42,227.69],[1,1.41,1313.46],[2,1.4,1408.97]],"batl":[[0,1.45,432.84],[1,1.46,2222],[2,1.51,5]],"ltp":1.44,"tv":55835.04,"id":5300737},{"batl":[[0,3.35,78.11],[1,3.4,83.42],[2,3.45,100.83]],"ltp":3.25,"tv":22365.54,"id":2497008}]}]}
{"op":"mcm","clk":"4299164832","pt":1632579880754,"mc":[{"id":"1.188136695","rc":[{"batb":[[0,1.42,30.71]],"batl":[[0,1.45,470.54],[1,1.46,3.51],[2,1.47,1170.91]],"ltp":1.44,"tv":55835.04,"id":5300737},{"batb":[[0,3.2,5.67],[1,2.98,119.72],[2,2.88,2.71]],"batl":[[0,3.4,83.42],[1,3.45,100.83],[2,3.5,2.01]],"ltp":3.25,"tv":22365.54,"id":2497008}]}]}
{"op":"mcm","clk":"4299165196","pt":1632579881722,"mc":[{"id":"1.188136695","rc":[{"trd":[[1.45,2274.81]],"batb":[[2,1.4,1408.8]],"batl":[[0,1.45,1138.31],[1,1.46,633.05]],"ltp":1.45,"tv":55937.16,"id":5300737},{"trd":[[3.2,100.74],[3.3,35.45]],"batb":[[0,3.3,224.3],[1,3.2,3],[2,3.1,272.93]],"ltp":3.3,"tv":22448.56,"id":2497008}],"tv":78385.72}]}
{"op":"mcm","clk":"4299165535","pt":1632579882736,"mc":[{"id":"1.188136695","rc":[{"batb":[[0,1.43,5],[1,1.42,36.71],[2,1.41,1319.46]],"ltp":1.45,"tv":55937.16,"id":5300737}]}]}
{"op":"mcm","clk":"4299165857","pt":1632579883648,"mc":[{"id":"1.188136695","rc":[{"batl":[[0,1.45,2090.57]],"ltp":1.45,"tv":55937.16,"id":5300737},{"batl":[[0,3.35,3],[1,3.4,85.42],[2,3.45,100.83]],"ltp":3.3,"tv":22448.56,"id":2497008}]}]}
{"op":"mcm","clk":"4299166231","pt":1632579884736,"mc":[{"id":"1.188136695","rc":[{"batl":[[0,1.44,6],[1,1.45,807.58],[2,1.46,1053.04]],"ltp":1.45,"tv":55937.16,"id":5300737},{"batb":[[2,3.15,194.66]],"ltp":3.3,"tv":22448.56,"id":2497008}]}]}
{"op":"mcm","clk":"4299166526","pt":1632579885659,"mc":[{"id":"1.188136695","rc":[{"batb":[[0,1.43,245.6],[1,1.42,1231.23]],"batl":[[0,1.44,244.89],[1,1.45,1044.86]],"ltp":1.45,"tv":55937.16,"id":5300737}]}]}
{"op":"mcm","clk":"4299166644","pt":1632579886032,"mc":[{"id":"1.188136695","rc":[{"trd":[[1.44,1182.89]],"batl":[[0,1.44,243.84],[1,1.45,1503.42],[2,1.46,1556.17]],"ltp":1.44,"tv":55939.26,"id":5300737},{"batb":[[1,3.2,210.78],[2,3.15,427.85]],"ltp":3.3,"tv":22448.56,"id":2497008}],"tv":78387.82}]}
{"op":"mcm","clk":"4299167196","pt":1632579887645,"mc":[{"id":"1.188136695","rc":[{"trd":[[1.44,1440.02]],"batl":[[0,1.44,115.28]],"ltp":1.44,"tv":56196.38,"id":5300737},{"trd":[[3.3,38.88]],"batb":[[0,3.3,222.58]],"ltp":3.3,"tv":22451.99,"id":2497008}],"tv":78648.38}]}
{"op":"mcm","clk":"4299167538","pt":1632579888664,"mc":[{"id":"1.188136695","rc":[{"trd":[[1.44,1443.54]],"batl":[[0,1.44,113.52]],"ltp":1.44,"tv":56199.9,"id":5300737}],"tv":78651.9}]}
{"op":"mcm","clk":"4299167938","pt":1632579889744,"mc":[{"id":"1.188136695","rc":[{"trd":[[3.3,83.94]],"batb":[[0,3.3,200.05]],"ltp":3.3,"tv":22497.05,"id":2497008}],"tv":78696.96}]}
{"op":"mcm","clk":"4299168226","pt":1632579890641,"mc":[{"id":"1.188136695","rc":[{"batb":[[1,1.42,278.97]],"batl":[[0,1.44,488.94],[1,1.45,1957.69]],"ltp":1.44,"tv":56199.9,"id":5300737},{"batb":[[1,3.25,166.33],[2,3.2,416.62]],"ltp":3.3,"tv":22497.05,"id":2497008}]}]}
{"op":"mcm","clk":"4299168486","pt":1632579891432,"mc":[{"id":"1.188136695","rc":[{"trd":[[1.44,1450.56]],"batl":[[0,1.44,485.43]],"ltp":1.44,"tv":56206.92,"id":5300737},{"trd":[[3.3,85.05]],"batb":[[0,3.3,199.5]],"ltp":3.3,"tv":22498.16,"id":2497008}],"tv":78705.09}]}
{"op":"mcm","clk":"4299168931","pt":1632579892736,"mc":[{"id":"1.188136695","rc":[{"trd":[[1.44,1466.49]],"batb":[[0,1.43,396.45]],"batl":[[0,1.44,783.46]],"ltp":1.44,"tv":56222.86,"id":5300737},{"trd":[[3.3,89.05]],"batb":[[0,3.3,197.5]],"ltp":3.3,"tv":22502.16,"id":2497008}],"tv":78725.03}]}
{"op":"mcm","clk":"4299169414","pt":1632579894252,"mc":[{"id":"1.188136695","rc":[{"trd":[[1.44,1478.03]],"batl":[[0,1.44,777.69]],"ltp":1.44,"tv":56234.4,"id":5300737}],"tv":78736.57}]}
{"op":"mcm","clk":"4299169781","pt":1632579895296,"mc":[{"id":"1.188136695","rc":[{"trd":[[1.44,1578.03]],"batb":[[1,1.42,272.97],[2,1.41,1313.46]],"batl":[[0,1.44,727.69]],"ltp":1.44,"tv":56334.4,"id":5300737}],"tv":78836.57}]}
{"op":"mcm","clk":"4299170236","pt":1632579896650,"mc":[{"id":"1.188136695","rc":[{"trd":[[1.44,1633.41]],"batl":[[0,1.44,700]],"ltp":1.44,"tv":56389.78,"id":5300737}],"tv":78891.95}]}
{"op":"mcm","clk":"4299170595","pt":1632579897768,"mc":[{"id":"1.188136695","rc":[{"trd":[[1.44,1647.29]],"batl":[[0,1.44,693.06]],"ltp":1.44,"tv":56403.66,"id":5300737},{"trd":[[3.3,92.5]],"batb":[[0,3.3,195.77]],"batl":[[1,3.4,83.42]],"ltp":3.3,"tv":22505.6,"id":2497008}],"tv":78909.27}]}
{"op":"mcm","clk":"4299170918","pt":1632579898754,"mc":[{"id":"1.188136695","rc":[{"batb":[[0,1.43,155.85],[1,1.42,38.71]],"batl":[[0,1.44,681.42],[1,1.45,1720.41]],"ltp":1.44,"tv":56403.66,"id":5300737},{"trd":[[3.3,112.5]],"batb":[[0,3.3,185.77]],"ltp":3.3,"tv":22525.6,"id":2497008}],"tv":78929.27}]}
{"op":"mcm","clk":"4299171253","pt":1632579899744,"mc":[{"id":"1.188136695","rc":[{"batb":[[0,1.43,150.85],[1,1.42,5.77],[2,1.41,1]],"batl":[[0,1.44,313],[1,1.46,3.51],[2,1.47,45.5]],"ltp":1.44,"tv":56403.66,"id":5300737},{"batb":[[0,3.1,275.27],[1,3,81.11],[2,2.98,91.17]],"batl":[[0,3.45,1.17],[1,3.65,2],[2,3.7,76.75]],"ltp":3.3,"tv":22525.6,"id":2497008}]}]}
{"op":"mcm","clk":"4299171374","pt":1632579900162,"mc":[{"id":"1.188136695","rc":[{"trd":[[1.43,57.74]],"batb":[[0,1.44,4.01],[1,1.43,127.82],[2,1.42,5.77]],"batl":[[0,1.46,3.51],[1,1.48,36.62],[2,1.49,40.5]],"ltp":1.43,"tv":56426.69,"id":5300737},{"trd":[[3.3,112.83],[3.35,9.83]],"batb":[[0,3.1,272.93]],"batl":[[0,3.45,1]],"ltp":3.35,"tv":22535.77,"id":2497008}],"tv":78962.47}]}
{"op":"mcm","clk":"4299171892","pt":1632579901714,"mc":[{"id":"1.188136695","rc":[{"batb":[[0,1.44,17.65]],"ltp":1.43,"tv":56426.69,"id":5300737}]}]}
{"op":"mcm","clk":"4299172167","pt":1632579902474,"mc":[{"id":"1.188136695","rc":[{"trd":[[1.46,304.49]],"batb":[[0,1.44,38.69]],"batl":[[0,1.48,36.62],[1,1.49,643.91],[2,1.5,763.29]],"ltp":1.46,"tv":56430.2,"id":5300737},{"trd":[[3.1,163.86],[3.15,2.33]],"batb":[[0,3.05,275.47]],"ltp":3.1,"tv":22540.14,"id":2497008}],"tv":78970.35}]}
{"op":"mcm","clk":"4299172617","pt":1632579903768,"mc":[{"id":"1.188136695","rc":[{"batl":[[0,1.47,43.5],[1,1.48,36.62],[2,1.49,643.91]],"ltp":1.46,"tv":56430.2,"id":5300737},{"batb":[[0,3.1,2.14],[1,3.05,275.47],[2,3,81.11]],"ltp":3.1,"tv":22540.14,"id":2497008}]}]}
{"op":"mcm","clk":"4299172775","pt":1632579904250,"mc":[{"id":"1.188136695","rc":[{"batl":[[0,1.48,36.62],[1,1.49,643.91],[2,1.5,763.29]],"ltp":1.46,"tv":56430.2,"id":5300737},{"batb":[[0,3.05,275.47],[1,3,81.11],[2,2.98,91.17]],"ltp":3.1,"tv":22540.14,"id":2497008}]}]}
{"op":"mcm","clk":"4299173183","pt":1632579905577,"mc":[{"id":"1.188136695","rc":[{"batl":[[1,1.49,40.5],[2,1.5,198.41]],"ltp":1.46,"tv":56430.2,"id":5300737},{"batb":[[1,3,78.61]],"batl":[[1,3.7,76.75],[2,3.75,93.75]],"ltp":3.1,"tv":22540.14,"id":2497008}]}]}
{"op":"mcm","clk":"4299173569","pt":1632579906723,"mc":[{"id":"1.188136695","rc":[{"batb":[[0,1.46,13.04],[1,1.44,38.69],[2,1.43,127.82]],"ltp":1.46,"tv":56430.2,"id":5300737}]}]}
{"op":"mcm","clk":"4299173895","pt":1632579907770,"mc":[{"id":"1.188136695","rc":[{"batl":[[0,1.47,45.5],[1,1.48,36.62],[2,1.49,40.5]],"ltp":1.46,"tv":56430.2,"id":5300737},{"batb":[[0,3.1,2.14],[1,3.05,275.47],[2,3,78.61]],"ltp":3.1,"tv":22540.14,"id":2497008}]}]}
{"op":"mcm","clk":"4299174088","pt":1632579908483,"mc":[{"id":"1.188136695","rc":[{"trd":[[1.45,2764.37],[1.46,330.57]],"batb":[[0,1.44,38.69],[1,1.43,127.82],[2,1.42,5.77]],"batl":[[0,1.45,496.88],[1,1.46,629.54],[2,1.47,116.72]],"ltp":1.45,"tv":56945.84,"id":5300737},{"batb":[[0,3.05,275.47],[1,3,78.61],[2,2.98,91.17]],"ltp":3.1,"tv":22540.14,"id":2497008}],"tv":79485.99}]}
{"op":"mcm","clk":"4299174518","pt":1632579909755,"mc":[{"id":"1.188136695","rc":[{"batb":[[0,1.44,17.65]],"ltp":1.45,"tv":56945.84,"id":5300737}]}]}
{"op":"mcm","clk":"4299174785","pt":1632579910647,"mc":[{"id":"1.188136695","rc":[{"trd":[[1.45,3218.39]],"batb":[[0,1.44,13.64]],"batl":[[0,1.45,269.87]],"ltp":1.45,"tv":57399.86,"id":5300737}],"tv":79940.01}]}
{"op":"mcm","clk":"4299175142","pt":1632579911553,"mc":[{"id":"1.188136695","rc":[{"batb":[[1,1.43,344.78]],"batl":[[0,1.45,483.84]],"ltp":1.45,"tv":57399.86,"id":5300737}]}]}
{"op":"mcm","clk":"4299175505","pt":1632579912649,"mc":[{"id":"1.188136695","rc":[{"batb":[[0,1.44,13.99]],"batl":[[0,1.45,633.14]],"ltp":1.45,"tv":57399.86,"id":5300737}]}]}
{"op":"mcm","clk":"4299175873","pt":1632579913766,"mc":[{"id":"1.188136695","rc":[{"trd":[[1.45,3652.39]],"batb":[[1,1.43,127.82],[2,1.42,502.12]],"batl":[[0,1.45,132.64],[1,1.48,36.62],[2,1.49,40.5]],"ltp":1.45,"tv":57833.86,"id":5300737}],"tv":80374.01}]}
{"op":"mcm","clk":"4299176030","pt":1632579914262,"mc":[{"id":"1.188136695","rc":[{"batb":[[2,1.42,5.77]],"batl":[[0,1.48,36.62],[1,1.49,40.5],[2,1.5,198.41]],"ltp":1.45,"tv":57833.86,"id":5300737}]}]}
{"op":"mcm","clk":"4299176301","pt":1632579915065,"mc":[{"id":"1.188136695","rc":[{"batb":[[1,1.42,5.77],[2,1.41,1]],"ltp":1.45,"tv":57833.86,"id":5300737}]}]}
{"op":"mcm","clk":"4299177475","pt":1632579918680,"mc":[{"id":"1.188136695","rc":[{"batb":[[0,1.45,2.65],[1,1.44,13.99],[2,1.42,5.77]],"batl":[[2,1.5,1078.35]],"ltp":1.45,"tv":57833.86,"id":5300737}]}]}
{"op":"mcm","clk":"4299177678","pt":1632579919389,"mc":[{"id":"1.188136695","rc":[{"batl":[[2,1.5,198.41]],"ltp":1.45,"tv":57833.86,"id":5300737},{"batl":[[0,3.2,3.72],[1,3.45,1],[2,3.7,76.75]],"ltp":3.1,"tv":22540.14,"id":2497008}]}]}
{"op":"mcm","clk":"4299178454","pt":1632579921671,"mc":[{"id":"1.188136695","rc":[{"batb":[[0,3.05,281.27]],"ltp":3.1,"tv":22540.14,"id":2497008}]}]}
{"op":"mcm","clk":"4299179067","pt":1632579923552,"mc":[{"id":"1.188136695","rc":[{"batb":[[0,1.46,17.26],[1,1.45,5.11],[2,1.44,13.99]],"ltp":1.45,"tv":57833.86,"id":5300737}]}]}
{"op":"mcm","clk":"4299179335","pt":1632579924368,"mc":[{"id":"1.188136695","rc":[{"trd":[[1.44,1726.56],[1.45,3670.81],[1.46,365.09]],"batb":[[0,1.42,5.77],[1,1.41,583.75],[2,1.4,767.14]],"batl":[[0,1.44,451.89],[1,1.45,647.43],[2,1.48,36.62]],"ltp":1.44,"tv":57966.06,"id":5300737},{"trd":[[3.2,104.45]],"batl":[[0,3.45,1],[1,3.7,76.75],[2,3.75,93.75]],"ltp":3.2,"tv":22543.85,"id":2497008}],"tv":80509.92}]}
{"op":"mcm","clk":"4299179603","pt":1632579925201,"mc":[{"id":"1.188136695","rc":[{"trd":[[1.44,1736.56]],"batl":[[0,1.44,446.89]],"ltp":1.44,"tv":57976.06,"id":5300737}],"tv":80519.92}]}
{"op":"mcm","clk":"4299180099","pt":1632579926777,"mc":[{"id":"1.188136695","rc":[{"trd":[[1.44,1737.26]],"batb":[[1,1.41,1],[2,1.4,2]],"batl":[[0,1.48,229.29],[1,1.49,40.5],[2,1.5,198.41]],"ltp":1.44,"tv":57976.76,"id":5300737}],"tv":80520.62}]}
{"op":"mcm","clk":"4299180419","pt":1632579927825,"mc":[{"id":"1.188136695","rc":[{"batl":[[0,1.44,108],[1,1.48,36.62],[2,1.49,40.5]],"ltp":1.44,"tv":57976.76,"id":5300737}]}]}
{"op":"mcm","clk":"4299180486","pt":1632579927998,"mc":[{"id":"1.188136695","rc":[{"batl":[[0,1.48,36.62],[1,1.49,40.5],[2,1.5,198.41]],"ltp":1.44,"tv":57976.76,"id":5300737}]}]}
{"op":"mcm","clk":"4299181132","pt":1632579929738,"mc":[{"id":"1.188136695","rc":[{"batl":[[0,1.48,34.86]],"ltp":1.44,"tv":57976.76,"id":5300737},{"batl":[[1,3.7,1],[2,3.9,2]],"ltp":3.2,"tv":22543.85,"id":2497008}]}]}
{"op":"mcm","clk":"4299181462","pt":1632579930793,"mc":[{"id":"1.188136695","rc":[{"trd":[[1.48,2282.03]],"batl":[[0,1.48,17.95]],"ltp":1.48,"tv":58010.58,"id":5300737}],"tv":80554.44}]}
{"op":"mcm","clk":"4299181779","pt":1632579931804,"mc":[{"id":"1.188136695","rc":[{"batb":[[0,1.46,432.84],[1,1.44,2222.3],[2,1.42,5.77]],"batl":[[2,1.5,1047.69]],"ltp":1.48,"tv":58010.58,"id":5300737}]}]}
{"op":"mcm","clk":"4299182113","pt":1632579932822,"mc":[{"id":"1.188136695","rc":[{"batb":[[0,1.47,531.46],[1,1.46,1267.26],[2,1.45,920.88]],"ltp":1.48,"tv":58010.58,"id":5300737},{"trd":[[3.05,125.57]],"batb":[[0,3.05,267.76]],"ltp":3.05,"tv":22570.87,"id":2497008}],"tv":80581.46}]}
{"op":"mcm","clk":"4299182438","pt":1632579933712,"mc":[{"id":"1.188136695","rc":[{"batb":[[0,1.47,1483.72]],"ltp":1.48,"tv":58010.58,"id":5300737},{"batb":[[2,2.98,214.95]],"batl":[[0,3.35,3],[1,3.45,1],[2,3.7,1]],"ltp":3.05,"tv":22570.87,"id":2497008}]}]}
{"op":"mcm","clk":"4299183142","pt":1632579935807,"mc":[{"id":"1.188136695","rc":[{"trd":[[3.05,132.59]],"batb":[[0,3.05,264.25]],"ltp":3.05,"tv":22577.89,"id":2497008}],"tv":80588.48}]}
{"op":"mcm","clk":"4299183441","pt":1632579936732,"mc":[{"id":"1.188136695","rc":[{"batl":[[0,1.48,22.95]],"ltp":1.48,"tv":58010.58,"id":5300737},{"batb":[[0,3.05,267.25],[1,3,81.61]],"ltp":3.05,"tv":22577.89,"id":2497008}]}]}
{"op":"mcm","clk":"4299183800","pt":1632579937748,"mc":[{"id":"1.188136695","rc":[{"trd":[[1.48,2307.03]],"batb":[[1,1.46,834.42],[2,1.45,920.58]],"batl":[[0,1.48,5.45],[1,1.49,230.09]],"ltp":1.48,"tv":58035.58,"id":5300737},{"batb":[[0,3.05,264.25],[1,3,78.61]],"ltp":3.05,"tv":22577.89,"id":2497008}],"tv":80613.48}]}
{"op":"mcm","clk":"4299184455","pt":1632579939725,"mc":[{"id":"1.188136695","rc":[{"batb":[[1,1.46,1215.37],[2,1.45,1399.14]],"ltp":1.48,"tv":58035.58,"id":5300737},{"batl":[[0,3.15,176.57],[1,3.2,216.85],[2,3.35,86.38]],"ltp":3.05,"tv":22577.89,"id":2497008}]}]}
{"op":"mcm","clk":"4299184747","pt":1632579940622,"mc":[{"id":"1.188136695","rc":[{"batb":[[0,1.47,576.19]],"ltp":1.48,"tv":58035.58,"id":5300737}]}]}
{"op":"mcm","clk":"4299185008","pt":1632579941521,"mc":[{"id":"1.188136695","rc":[{"trd":[[1.47,1920.61]],"batb":[[0,1.47,473.84]],"batl":[[1,1.49,588.01],[2,1.5,1457.39]],"ltp":1.47,"tv":58240.28,"id":5300737},{"batb":[[0,3.05,439.1],[1,3,283.47]],"ltp":3.05,"tv":22577.89,"id":2497008}],"tv":80818.18}]}
{"op":"mcm","clk":"4299185155","pt":1632579941902,"mc":[{"id":"1.188136695","rc":[{"trd":[[1.47,1923.83]],"batb":[[0,1.47,472.23]],"ltp":1.47,"tv":58243.5,"id":5300737}],"tv":80821.39}]}
{"op":"mcm","clk":"4299185775","pt":1632579943829,"mc":[{"id":"1.188136695","rc":[{"batl":[[0,1.48,374.45]],"ltp":1.47,"tv":58243.5,"id":5300737}]}]}
{"op":"mcm","clk":"4299186765","pt":1632579946639,"mc":[{"id":"1.188136695","rc":[{"batb":[[2,1.45,1412.78]],"ltp":1.47,"tv":58243.5,"id":5300737},{"trd":[[3.05,142.59]],"batb":[[0,3.05,434.1]],"ltp":3.05,"tv":22587.9,"id":2497008}],"tv":80831.4}]}
{"op":"mcm","clk":"4299187141","pt":1632579947731,"mc":[{"id":"1.188136695","rc":[{"trd":[[1.47,1927.27]],"batb":[[0,1.47,470.51]],"batl":[[0,1.48,590]],"ltp":1.47,"tv":58246.94,"id":5300737}],"tv":80834.84}]}
{"op":"mcm","clk":"4299187500","pt":1632579948721,"mc":[{"id":"1.188136695","rc":[{"trd":[[1.48,2340.13]],"batl":[[0,1.48,573.45]],"ltp":1.48,"tv":58280.04,"id":5300737}],"tv":80867.94}]}
{"op":"mcm","clk":"4299187811","pt":1632579949766,"mc":[{"id":"1.188136695","rc":[{"trd":[[1.48,2347.15]],"batb":[[0,1.46,568.69],[1,1.45,668.49],[2,1.44,536.71]],"batl":[[0,1.48,354.39],[1,1.49,40.5],[2,1.5,849.28]],"ltp":1.48,"tv":58287.06,"id":5300737},{"batb":[[0,3.05,259.25],[1,2.98,123.78],[2,2.8,109.91]],"batl":[[0,3.35,86.38],[1,3.4,96.84],[2,3.45,125.19]],"ltp":3.05,"tv":22587.9,"id":2497008}],"tv":80874.96}]}
{"op":"mcm","clk":"4299188136","pt":1632579950721,"mc":[{"id":"1.188136695","rc":[{"trd":[[1.46,434.13]],"batb":[[0,1.45,13.64],[1,1.44,1.76],[2,1.43,204.05]],"batl":[[0,1.54,20],[1,1.56,190.8],[2,1.57,220.86]],"ltp":1.46,"tv":58356.1,"id":5300737},{"batb":[[0,3.05,5.8]],"batl":[[0,3.35,83.38]],"ltp":3.05,"tv":22587.9,"id":2497008}],"tv":80944.0}]}
{"op":"mcm","clk":"4299188449","pt":1632579951721,"mc":[{"id":"1.188136695","rc":[{"trd":[[1.47,1927.58]],"ltp":1.47,"tv":58356.41,"id":5300737},{"trd":[[3.05,145.17],[3.1,164]],"batb":[[0,3.05,4.51]],"ltp":3.05,"tv":22590.62,"id":2497008}],"tv":80947.04}]}
{"op":"mcm","clk":"4299188970","pt":1632579953341,"mc":[{"id":"1.188136695","rc":[{"batl":[[0,1.47,18.86],[1,1.54,884.02],[2,1.55,493.78]],"ltp":1.47,"tv":58356.41,"id":5300737},{"batb":[[1,2.96,124.04]],"ltp":3.05,"tv":22590.62,"id":2497008}]}]}
{"op":"mcm","clk":"4299189667","pt":1632579955523,"mc":[{"id":"1.188136695","rc":[{"trd":[[1.47,1942.8]],"batl":[[0,1.47,11.25]],"ltp":1.47,"tv":58371.63,"id":5300737}],"tv":80962.26}]}
{"op":"mcm","clk":"4299192183","pt":1632579963368,"mc":[{"id":"1.188136695","rc":[{"batl":[[0,1.54,20],[1,1.64,20],[2,1.69,1]],"ltp":1.47,"tv":58371.63,"id":5300737},{"batb":[[2,2.8,1.73]],"ltp":3.05,"tv":22590.62,"id":2497008}]}]}
{"op":"mcm","clk":"4299192598","pt":1632579964378,"mc":[{"id":"1.188136695","rc":[{"trd":[[1.45,3698.09]],"batb":[[0,1.44,1.76],[1,1.43,204.05],[2,1.42,232.92]],"batl":[[0,1.46,2654.84],[1,1.54,20],[2,1.64,20]],"ltp":1.45,"tv":58398.91,"id":5300737}],"tv":80989.53}]}
{"op":"mcm","clk":"4299193299","pt":1632579966555,"mc":[{"id":"1.188136695","rc":[{"batb":[[1,1.42,232.92],[2,1.41,1165.72]],"batl":[[0,1.45,992.14],[1,1.46,3287.45],[2,1.47,1170.91]],"ltp":1.45,"tv":58398.91,"id":5300737},{"batb":[[0,3.2,3],[1,3.05,4.51],[2,2.96,124.04]],"batl":[[0,3.4,96.84],[1,3.45,125.19],[2,3.7,1]],"ltp":3.05,"tv":22590.62,"id":2497008}]}]}
{"op":"mcm","clk":"4299193600","pt":1632579967552,"mc":[{"id":"1.188136695","rc":[{"trd":[[1.44,1739.02],[1.45,3719.5]],"batb":[[0,1.42,232.92],[1,1.41,1165.72],[2,1.4,1381.38]],"batl":[[0,1.45,970.73]],"ltp":1.44,"tv":58422.08,"id":5300737},{"trd":[[3.2,120.15],[3.3,113.6]],"batb":[[0,3.3,230.73],[1,3.05,280.91],[2,2.8,1.73]],"ltp":3.3,"tv":22607.09,"id":2497008}],"tv":81029.17}]}
{"op":"mcm","clk":"4299193955","pt":1632579968756,"mc":[{"id":"1.188136695","rc":[{"trd":[[1.44,1766.17]],"batl":[[1,1.46,1065.45]],"ltp":1.44,"tv":58449.23,"id":5300737},{"trd":[[3.3,125.45]],"batb":[[0,3.3,218.88]],"ltp":3.3,"tv":22618.94,"id":2497008}],"tv":81068.17}]}
{"op":"mcm","clk":"4299194623","pt":1632579970763,"mc":[{"id":"1.188136695","rc":[{"batb":[[0,1.43,58.58],[1,1.42,232.92],[2,1.41,1165.72]],"batl":[[0,1.44,223.24],[1,1.45,970.73],[2,1.46,632.61]],"ltp":1.44,"tv":58449.23,"id":5300737},{"trd":[[3.3,129.19]],"batb":[[0,3.3,217.01],[1,3.1,3],[2,3.05,280.91]],"ltp":3.3,"tv":22622.68,"id":2497008}],"tv":81071.91}]}
{"op":"mcm","clk":"4299194795","pt":1632579971253,"mc":[{"id":"1.188136695","rc":[{"batb":[[2,3.05,282.91]],"ltp":3.3,"tv":22622.68,"id":2497008}]}]}
{"op":"mcm","clk":"4299195291","pt":1632579972755,"mc":[{"id":"1.188136695","rc":[{"batl":[[0,1.44,338.24],[1,1.45,1364.15],[2,1.46,1068.88]],"ltp":1.44,"tv":58449.23,"id":5300737},{"batb":[[1,3.2,178.26],[2,3.15,202.2]],"ltp":3.3,"tv":22622.68,"id":2497008}]}]}
{"op":"mcm","clk":"4299195555","pt":1632579973350,"mc":[{"id":"1.188136695","rc":[{"trd":[[1.44,1766.75]],"batl":[[0,1.44,337.95]],"ltp":1.44,"tv":58449.81,"id":5300737}],"tv":81072.49}]}
{"op":"mcm","clk":"4299195948","pt":1632579974575,"mc":[{"id":"1.188136695","rc":[{"trd":[[1.44,1852.46]],"batl":[[0,1.44,295.09]],"ltp":1.44,"tv":58535.52,"id":5300737}],"tv":81158.2}]}
{"op":"mcm","clk":"4299196284","pt":1632579975675,"mc":[{"id":"1.188136695","rc":[{"trd":[[1.44,1860.49]],"batl":[[0,1.44,291.08]],"ltp":1.44,"tv":58543.55,"id":5300737},{"trd":[[3.3,485.89]],"batb":[[0,3.3,38.66]],"ltp":3.3,"tv":22979.38,"id":2497008}],"tv":81522.93}]}
{"op":"mcm","clk":"4299196413","pt":1632579976064,"mc":[{"id":"1.188136695","rc":[{"trd":[[1.44,1870.85]],"batb":[[1,1.42,333.57]],"batl":[[0,1.44,285.9]],"ltp":1.44,"tv":58553.91,"id":5300737},{"trd":[[3.3,520.17]],"batb":[[0,3.3,21.52]],"ltp":3.3,"tv":23013.66,"id":2497008}],"tv":81567.57}]}
{"op":"mcm","clk":"4299196907","pt":1632579977564,"mc":[{"id":"1.188136695","rc":[{"trd":[[1.43,77.74],[1.44,1946.93]],"batb":[[0,1.43,48.58]],"batl":[[0,1.44,209.82]],"ltp":1.43,"tv":58649.99,"id":5300737},{"trd":[[3.25,146.37],[3.3,563.21]],"batb":[[0,3.2,178.26],[1,3.15,202.2],[2,3.1,3]],"ltp":3.25,"tv":23090.41,"id":2497008}],"tv":81740.4}]}
{"op":"mcm","clk":"4299197193","pt":1632579978485,"mc":[{"id":"1.188136695","rc":[{"batb":[[0,1.43,128.58]],"batl":[[1,1.45,1317.67]],"ltp":1.43,"tv":58649.99,"id":5300737}]}]}
{"op":"mcm","clk":"4299197559","pt":1632579979604,"mc":[{"id":"1.188136695","rc":[{"trd":[[1.44,1947.53]],"batl":[[0,1.44,674.08]],"ltp":1.44,"tv":58650.59,"id":5300737}],"tv":81741.01}]}
{"op":"mcm","clk":"4299197914","pt":1632579980686,"mc":[{"id":"1.188136695","rc":[{"trd":[[1.43,77.86]],"batb":[[0,1.43,128.46]],"ltp":1.43,"tv":58650.71,"id":5300737},{"trd":[[3.35,9.88]],"ltp":3.35,"tv":23090.46,"id":2497008}],"tv":81741.18}]}
{"op":"mcm","clk":"4299198095","pt":1632579981315,"mc":[{"id":"1.188136695","rc":[{"trd":[[1.44,1957.25]],"batl":[[0,1.44,669.22]],"ltp":1.44,"tv":58660.43,"id":5300737}],"tv":81750.9}]}
{"op":"mcm","clk":"4299198424","pt":1632579982381,"mc":[{"id":"1.188136695","rc":[{"trd":[[1.43,99.82]],"batb":[[0,1.43,37.48]],"ltp":1.43,"tv":58682.39,"id":5300737},{"batl":[[0,3.3,2],[1,3.4,96.84],[2,3.45,125.19]],"ltp":3.35,"tv":23090.46,"id":2497008}],"tv":81772.86}]}
{"op":"mcm","clk":"4299198838","pt":1632579983796,"mc":[{"id":"1.188136695","rc":[{"trd":[[1.44,2008.17]],"batl":[[0,1.44,643.76]],"ltp":1.44,"tv":58733.32,"id":5300737},{"batl":[[0,3.3,7]],"ltp":3.35,"tv":23090.46,"id":2497008}],"tv":81823.78}]}
{"op":"mcm","clk":"4299199502","pt":1632579985770,"mc":[{"id":"1.188136695","rc":[{"trd":[[1.43,99.99],[1.44,2015.95]],"batb":[[0,1.43,37.4]],"batl":[[0,1.44,635.98]],"ltp":1.43,"tv":58741.26,"id":5300737},{"trd":[[3.25,149.82]],"ltp":3.25,"tv":23093.91,"id":2497008}],"tv":81835.17}]}
{"op":"mcm","clk":"4299199759","pt":1632579986608,"mc":[{"id":"1.188136695","rc":[{"batb":[[0,1.42,5.77],[1,1.41,1],[2,1.4,2]],"batl":[[0,1.44,579.56],[1,1.48,42.74],[2,1.51,241.01]],"ltp":1.43,"tv":58741.26,"id":5300737},{"batb":[[0,3.05,283.2],[1,2.96,110.08],[2,2.94,124.7]],"batl":[[1,3.45,1],[2,3.7,1]],"ltp":3.25,"tv":23093.91,"id":2497008}]}]}
{"op":"mcm","clk":"4299200086","pt":1632579987695,"mc":[{"id":"1.188136695","rc":[{"trd":[[1.44,2021.95]],"batl":[[0,1.44,461.56]],"ltp":1.44,"tv":58747.26,"id":5300737},{"batl":[[0,3.3,5]],"ltp":3.25,"tv":23093.91,"id":2497008}],"tv":81841.17}]}
{"op":"mcm","clk":"4299200412","pt":1632579988585,"mc":[{"id":"1.188136695","rc":[{"trd":[[1.43,111.53],[1.44,2026.65]],"batl":[[0,1.43,23.52],[1,1.44,459.21],[2,1.48,42.74]],"ltp":1.43,"tv":58763.5,"id":5300737},{"trd":[[3.3,568.21]],"batl":[[0,3.45,1],[1,3.7,1],[2,3.8,65.66]],"ltp":3.3,"tv":23098.91,"id":2497008}],"tv":81862.41}]}
{"op":"mcm","clk":"4299200717","pt":1632579989708,"mc":[{"id":"1.188136695","rc":[{"batb":[[0,3.05,6.8],[1,2.98,286.63],[2,2.96,110.08]],"ltp":3.3,"tv":23098.91,"id":2497008}]}]}
{"op":"mcm","clk":"4299200867","pt":1632579990172,"mc":[{"id":"1.188136695","rc":[{"trd":[[1.43,135.05],[1.44,2128.31]],"batl":[[0,1.44,357.56],[1,1.48,42.74],[2,1.5,698.17]],"ltp":1.44,"tv":58888.67,"id":5300737},{"trd":[[3.25,194.86],[3.3,578.4]],"ltp":3.25,"tv":23154.14,"id":2497008}],"tv":82042.82}]}
{"op":"mcm","clk":"4299201376","pt":1632579991689,"mc":[{"id":"1.188136695","rc":[{"trd":[[1.44,2131.82]],"batl":[[0,1.44,355.8]],"ltp":1.44,"tv":58892.19,"id":5300737}],"tv":82046.33}]}
{"op":"mcm","clk":"4299201875","pt":1632579993477,"mc":[{"id":"1.188136695","rc":[{"batl":[[0,3.45,1.12]],"ltp":3.25,"tv":23154.14,"id":2497008}]}]}
{"op":"mcm","clk":"4299202215","pt":1632579994498,"mc":[{"id":"1.188136695","rc":[{"trd":[[1.44,2487.34]],"batl":[[0,1.44,178.04]],"ltp":1.44,"tv":59247.71,"id":5300737}],"tv":82401.85}]}
{"op":"mcm","clk":"4299202616","pt":1632579995789,"mc":[{"id":"1.188136695","rc":[{"trd":[[1.44,2507.25]],"batl":[[0,1.44,168.09]],"ltp":1.44,"tv":59267.61,"id":5300737}],"tv":82421.76}]}
{"op":"mcm","clk":"4299203249","pt":1632579997799,"mc":[{"id":"1.188136695","rc":[{"trd":[[1.44,2511.46]],"batb":[[1,1.41,181.85]],"batl":[[0,1.44,165.98]],"ltp":1.44,"tv":59271.83,"id":5300737}],"tv":82425.97}]}
{"op":"mcm","clk":"4299203356","pt":1632579998188,"mc":[{"id":"1.188136695","rc":[{"batb":[[1,1.41,1]],"ltp":1.44,"tv":59271.83,"id":5300737}]}]}
{"op":"mcm","clk":"4299203805","pt":1632579999806,"mc":[{"id":"1.188136695","rc":[{"trd":[[1.44,2839.46]],"batb":[[0,1.46,11775.84],[1,1.45,271.18],[2,1.43,2222]],"batl":[[0,1.5,698.17],[1,1.51,788.47],[2,1.52,217.2]],"ltp":1.44,"tv":59599.82,"id":5300737},{"trd":[[3.25,196.62]],"batb":[[0,3.05,4.51]],"batl":[[0,3.25,1765.39],[1,3.3,1713.58],[2,3.35,1713.46]],"ltp":3.25,"tv":23155.9,"id":2497008}],"tv":82755.73}]}
{"op":"mcm","clk":"4299204021","pt":1632580000514,"mc":[{"id":"1.188136695","rc":[{"batb":[[0,1.46,11738.58],[2,1.43,2222.7]],"ltp":1.44,"tv":59599.82,"id":5300737}]}]}
{"op":"mcm","clk":"4299204457","pt":1632580001827,"mc":[{"id":"1.188136695","rc":[{"trd":[[1.46,469.19]],"batb":[[0,1.46,11721.05],[1,1.42,6.47],[2,1.41,1]],"ltp":1.46,"tv":59634.88,"id":5300737},{"batl":[[0,3.25,88.27],[1,3.3,85.79],[2,3.35,85.67]],"ltp":3.25,"tv":23155.9,"id":2497008}],"tv":82790.79}]}
{"op":"mcm","clk":"4299204733","pt":1632580002715,"mc":[{"id":"1.188136695","rc":[{"batb":[[1,1.44,11.22],[2,1.42,5.77]],"batl":[[0,1.48,37.99],[1,1.49,7],[2,1.5,698.17]],"ltp":1.46,"tv":59634.88,"id":5300737},{"batb":[[0,3.05,7]],"ltp":3.25,"tv":23155.9,"id":2497008}]}]}
{"op":"mcm","clk":"4299204862","pt":1632580003098,"mc":[{"id":"1.188136695","rc":[{"batb":[[0,1.48,13.64],[1,1.46,11721.05],[2,1.44,11.22]],"batl":[[0,1.49,7],[1,1.5,698.17],[2,1.51,788.47]],"ltp":1.46,"tv":59634.88,"id":5300737},{"batb":[[0,3.05,4.51]],"ltp":3.25,"tv":23155.9,"id":2497008}]}]}
{"op":"mcm","clk":"4299205431","pt":1632580004789,"mc":[{"id":"1.188136695","rc":[{"trd":[[1.49,2375.09],[1.5,872.96]],"batb":[[0,1.48,20.64],[1,1.46,821.97],[2,1.45,656.16]],"batl":[[0,1.5,686.93],[1,1.51,788.47],[2,1.52,1349.6]],"ltp":1.5,"tv":59653.12,"id":5300737},{"trd":[[3,138.04],[3.05,154.19]],"batb":[[0,2.98,286.63],[1,2.96,110.08],[2,2.94,124.7]],"batl":[[0,3.2,3],[1,3.25,529.62],[2,3.3,514.15]],"ltp":3.0,"tv":23174.02,"id":2497008}],"tv":82827.15}]}
{"op":"mcm","clk":"4299205749","pt":1632580005790,"mc":[{"id":"1.188136695","rc":[{"batb":[[1,1.46,1340.61]],"batl":[[0,1.5,709.43]],"ltp":1.5,"tv":59653.12,"id":5300737},{"batb":[[0,3,11.25],[1,2.98,286.63],[2,2.96,110.08]],"ltp":3.0,"tv":23174.02,"id":2497008}]}]}
{"op":"mcm","clk":"4299206079","pt":1632580006804,"mc":[{"id":"1.188136695","rc":[{"batb":[[1,1.47,10],[2,1.46,1380.47]],"batl":[[0,1.49,1085.11],[1,1.5,709.43],[2,1.51,788.47]],"ltp":1.5,"tv":59653.12,"id":5300737},{"batl":[[0,3.2,24.83],[1,3.25,533.13]],"ltp":3.0,"tv":23174.02,"id":2497008}]}]}
{"op":"mcm","clk":"4299206714","pt":1632580008814,"mc":[{"id":"1.188136695","rc":[{"trd":[[1.49,2375.89]],"batb":[[1,1.47,914.26]],"batl":[[0,1.49,1084.71],[1,1.5,935.08]],"ltp":1.49,"tv":59653.93,"id":5300737}],"tv":82827.95}]}
{"op":"mcm","clk":"4299206860","pt":1632580009319,"mc":[{"id":"1.188136695","rc":[{"batb":[[1,1.47,1490.44]],"batl":[[0,1.49,1310.88],[1,1.5,1337.93],[2,1.51,1326.74]],"ltp":1.49,"tv":59653.93,"id":5300737},{"batb":[[0,3,212.67],[2,2.96,384.66]],"ltp":3.0,"tv":23174.02,"id":2497008}]}]}
{"op":"mcm","clk":"4299207165","pt":1632580010390,"mc":[{"id":"1.188136695","rc":[{"trd":[[1.48,2431.79],[1.49,2395.91]],"batb":[[0,1.47,1490.44],[1,1.46,1380.47],[2,1.45,656.16]],"batl":[[0,1.48,429.42],[1,1.49,1300.87],[2,1.5,1337.93]],"ltp":1.48,"tv":59758.58,"id":5300737},{"trd":[[3.05,175.23]],"ltp":3.05,"tv":23195.06,"id":2497008}],"tv":82953.64}]}
{"op":"mcm","clk":"4299207543","pt":1632580011700,"mc":[{"id":"1.188136695","rc":[{"batb":[[0,1.47,2442.7],[1,1.46,1815.04],[2,1.45,1233.09]],"batl":[[1,1.49,1557.87]],"ltp":1.48,"tv":59758.58,"id":5300737},{"batl":[[0,3.15,201.42],[1,3.2,286.25],[2,3.25,533.13]],"ltp":3.05,"tv":23195.06,"id":2497008}]}]}
{"op":"mcm","clk":"4299207856","pt":1632580012807,"mc":[{"id":"1.188136695","rc":[{"batl":[[0,1.48,431.02]],"ltp":1.48,"tv":59758.58,"id":5300737}]}]}
{"op":"mcm","clk":"4299208054","pt":1632580013529,"mc":[{"id":"1.188136695","rc":[{"trd":[[1.48,2432.05]],"batl":[[0,1.48,430.9]],"ltp":1.48,"tv":59758.83,"id":5300737},{"batl":[[2,3.25,529.62]],"ltp":3.05,"tv":23195.06,"id":2497008}],"tv":82953.9}]}
{"op":"mcm","clk":"4299208393","pt":1632580014613,"mc":[{"id":"1.188136695","rc":[{"trd":[[1.47,1963.93],[1.48,2447.85]],"batb":[[0,1.47,2432.14]],"batl":[[0,1.48,498.11]],"ltp":1.48,"tv":59795.76,"id":5300737},{"trd":[[3.05,175.58]],"ltp":3.05,"tv":23195.41,"id":2497008}],"tv":82991.18}]}
{"op":"mcm","clk":"4299209024","pt":1632580016817,"mc":[{"id":"1.188136695","rc":[{"trd":[[1.47,4664.93]],"batb":[[0,1.47,129.37],[1,1.46,1721.88]],"batl":[[0,1.48,498.46],[1,1.49,1912.27],[2,1.5,1716.77]],"ltp":1.47,"tv":62496.77,"id":5300737},{"batb":[[0,3.05,173.14],[1,3,402.1],[2,2.98,286.63]],"ltp":3.05,"tv":23195.41,"id":2497008}],"tv":85692.18}]}
{"op":"mcm","clk":"4299209262","pt":1632580017749,"mc":[{"id":"1.188136695","rc":[{"batl":[[0,1.48,533.52]],"ltp":1.47,"tv":62496.77,"id":5300737}]}]}
{"op":"mcm","clk":"4299209454","pt":1632580018448,"mc":[{"id":"1.188136695","rc":[{"batl":[[0,1.48,460.39],[2,1.5,1723.08]],"ltp":1.47,"tv":62496.77,"id":5300737},{"trd":[[3.05,176.28],[3.15,36.62]],"batb":[[0,3.05,172.79]],"batl":[[0,3.15,184.28]],"ltp":3.15,"tv":23230.4,"id":2497008}],"tv":85727.17}]}
{"op":"mcm","clk":"4299209589","pt":1632580018938,"mc":[{"id":"1.188136695","rc":[{"trd":[[1.48,2450.65]],"batl":[[0,1.48,458.99]],"ltp":1.48,"tv":62499.57,"id":5300737}],"tv":85729.97}]}
{"op":"mcm","clk":"4299210165","pt":1632580020827,"mc":[{"id":"1.188136695","rc":[{"trd":[[1.48,2451.42]],"batb":[[1,1.46,2040.79]],"batl":[[0,1.48,458.61]],"ltp":1.48,"tv":62500.34,"id":5300737}],"tv":85730.74}]}
{"op":"mcm","clk":"4299210386","pt":1632580021616,"mc":[{"id":"1.188136695","rc":[{"trd":[[1.47,4811.2]],"batb":[[0,1.47,56.24],[1,1.46,1566.36],[2,1.45,656.16]],"batl":[[0,1.48,459.31],[1,1.49,1557.87],[2,1.5,941.39]],"ltp":1.47,"tv":62646.6,"id":5300737},{"batb":[[0,3,11.25],[1,2.98,286.63],[2,2.96,2.38]],"batl":[[0,3.2,3],[1,3.4,89.22],[2,3.45,123.12]],"ltp":3.15,"tv":23230.4,"id":2497008}],"tv":85877.0}]}
{"op":"mcm","clk":"4299210714","pt":1632580022829,"mc":[{"id":"1.188136695","rc":[{"batb":[[0,1.44,15.03],[1,1.42,257.89],[2,1.41,883.69]],"batl":[[0,1.48,210.39],[1,1.49,1074.7],[2,1.5,6.31]],"ltp":1.47,"tv":62646.6,"id":5300737},{"batb":[[0,2.96,2.38],[1,2.92,2.69],[2,2.88,2.46]],"batl":[[0,3.4,89.22],[1,3.45,108.75],[2,3.5,98.18]],"ltp":3.15,"tv":23230.4,"id":2497008}]}]}
{"op":"mcm","clk":"4299210988","pt":1632580023753,"mc":[{"id":"1.188136695","rc":[{"trd":[[1.48,2472.46]],"batl":[[0,1.48,200.39],[1,1.5,6.31],[2,1.51,40.5]],"ltp":1.48,"tv":62667.64,"id":5300737}],"tv":85898.04}]}
{"op":"mcm","clk":"4299211350","pt":1632580024830,"mc":[{"id":"1.188136695","rc":[{"batb":[[2,1.41,1516.39]],"batl":[[0,1.48,199.69]],"ltp":1.48,"tv":62667.64,"id":5300737}]}]}
{"op":"mcm","clk":"4299211622","pt":1632580025723,"mc":[{"id":"1.188136695","rc":[{"trd":[[1.47,4812.12],[1.48,2479.57]],"batb":[[2,1.41,879.97]],"batl":[[0,1.48,192.06]],"ltp":1.48,"tv":62675.67,"id":5300737},{"trd":[[3.05,179.73],[3.1,164.06]],"ltp":3.05,"tv":23233.91,"id":2497008}],"tv":85909.58}]}
{"op":"mcm","clk":"4299211877","pt":1632580026739,"mc":[{"id":"1.188136695","rc":[{"trd":[[1.48,2671.63]],"batl":[[0,1.5,6.31],[1,1.53,42.5],[2,1.55,155.78]],"ltp":1.48,"tv":62867.73,"id":5300737},{"trd":[[3.05,272.93]],"batb":[[0,2.88,2.46],[1,2.84,129.79],[2,2.8,102.68]],"batl":[[0,3.05,63.8],[1,3.4,89.22],[2,3.45,108.75]],"ltp":3.05,"tv":23327.11,"id":2497008}],"tv":86194.84}]}
{"op":"mcm","clk":"4299212194","pt":1632580027720,"mc":[{"id":"1.188136695","rc":[{"trd":[[1.48,2803.11]],"batl":[[0,1.47,49.37],[1,1.5,6.31],[2,1.53,42.5]],"ltp":1.48,"tv":62999.21,"id":5300737},{"trd":[[3.05,336.73]],"batl":[[0,3.4,89.22],[1,3.45,108.75],[2,3.5,98.18]],"ltp":3.05,"tv":23390.91,"id":2497008}],"tv":86390.13}]}
{"op":"mcm","clk":"4299212436","pt":1632580028529,"mc":[{"id":"1.188136695","rc":[{"trd":[[1.47,4815.91]],"batl":[[0,1.47,292.42]],"ltp":1.47,"tv":63003.01,"id":5300737},{"trd":[[3.1,165.86]],"ltp":3.1,"tv":23392.71,"id":2497008}],"tv":86395.72}]}
{"op":"mcm","clk":"4299212812","pt":1632580029733,"mc":[{"id":"1.188136695","rc":[{"trd":[[1.47,4834.17]],"batb":[[0,1.45,695.49],[1,1.44,690.78],[2,1.42,257.89]],"batl":[[0,1.46,361.7],[1,1.47,274.17],[2,1.49,789.26]],"ltp":1.47,"tv":63021.27,"id":5300737},{"trd":[[3.1,174.52]],"ltp":3.1,"tv":23401.36,"id":2497008}],"tv":86422.64}]}
{"op":"mcm","clk":"4299213130","pt":1632580030736,"mc":[{"id":"1.188136695","rc":[{"trd":[[1.46,609.39]],"batb":[[0,1.45,734.02]],"batl":[[0,1.46,61.7]],"ltp":1.46,"tv":63161.46,"id":5300737},{"trd":[[3.15,91.85]],"batb":[[0,2.96,2.63],[1,2.88,2.46],[2,2.84,129.79]],"ltp":3.15,"tv":23456.59,"id":2497008}],"tv":86618.06}]}
{"op":"mcm","clk":"4299213430","pt":1632580031754,"mc":[{"id":"1.188136695","rc":[{"trd":[[1.46,612.9]],"batl":[[0,1.47,386.17],[1,1.48,1.76]],"ltp":1.46,"tv":63164.98,"id":5300737}],"tv":86621.58}]}
{"op":"mcm","clk":"4299213551","pt":1632580032246,"mc":[{"id":"1.188136695","rc":[{"batb":[[0,1.45,962.11]],"batl":[[0,1.47,736.92]],"ltp":1.46,"tv":63164.98,"id":5300737}]}]}
{"op":"mcm","clk":"4299213845","pt":1632580033266,"mc":[{"id":"1.188136695","rc":[{"batl":[[0,1.46,347.56],[1,1.47,736.92],[2,1.48,1.76]],"ltp":1.46,"tv":63164.98,"id":5300737}]}]}
{"op":"mcm","clk":"4299214252","pt":1632580034753,"mc":[{"id":"1.188136695","rc":[{"batl":[[0,1.47,528.75],[1,1.48,1.76],[2,1.49,789.26]],"ltp":1.46,"tv":63164.98,"id":5300737},{"batb":[[0,2.98,13.15],[1,2.96,2.63],[2,2.88,2.46]],"ltp":3.15,"tv":23456.59,"id":2497008}]}]}
{"op":"mcm","clk":"4299214403","pt":1632580035265,"mc":[{"id":"1.188136695","rc":[{"trd":[[1.47,4836.71]],"batb":[[0,1.45,266.62],[1,1.44,15.03]],"batl":[[0,1.47,527.48],[2,1.5,37.86]],"ltp":1.47,"tv":63167.51,"id":5300737}],"tv":86624.11}]}
{"op":"mcm","clk":"4299215022","pt":1632580037596,"mc":[{"id":"1.188136695","rc":[{"batb":[[0,1.46,27.43]],"batl":[[0,1.47,176.73],[2,1.5,6.31]],"ltp":1.47,"tv":63167.51,"id":5300737},{"batb":[[0,2.96,2.63],[1,2.88,2.46],[2,2.84,129.79]],"ltp":3.15,"tv":23456.59,"id":2497008}]}]}
{"op":"mcm","clk":"4299215216","pt":1632580038247,"mc":[{"id":"1.188136695","rc":[{"batl":[[0,1.47,64.73]],"ltp":1.47,"tv":63167.51,"id":5300737}]}]}
{"op":"mcm","clk":"4299215517","pt":1632580039298,"mc":[{"id":"1.188136695","rc":[{"trd":[[1.47,4837.44]],"batl":[[0,1.47,63.99]],"ltp":1.47,"tv":63168.25,"id":5300737},{"trd":[[3.1,174.87]],"ltp":3.1,"tv":23456.94,"id":2497008}],"tv":86625.2}]}
{"op":"mcm","clk":"4299215978","pt":1632580040890,"mc":[{"id":"1.188136695","rc":[{"trd":[[1.46,628.84]],"batb":[[0,1.46,19.46]],"ltp":1.46,"tv":63184.19,"id":5300737}],"tv":86641.14}]}
{"op":"mcm","clk":"4299216813","pt":1632580043771,"mc":[{"id":"1.188136695","rc":[{"trd":[[1.47,4840.96]],"batb":[[0,1.44,15.03],[1,1.42,257.89],[2,1.41,1512.67]],"batl":[[0,1.47,62.24]],"ltp":1.47,"tv":63187.71,"id":5300737}],"tv":86644.66}]}
{"op":"mcm","clk":"4299217133","pt":1632580044792,"mc":[{"id":"1.188136695","rc":[{"batl":[[0,1.45,2222],[1,1.47,62.24],[2,1.48,1.76]],"ltp":1.47,"tv":63187.71,"id":5300737}]}]}
{"op":"mcm","clk":"4299217380","pt":1632580045649,"mc":[{"id":"1.188136695","rc":[{"trd":[[1.44,2869.52],[1.45,3719.59]],"batb":[[0,1.42,257.89],[1,1.41,1512.67],[2,1.4,994.23]],"batl":[[0,1.44,5992.05],[1,1.45,2221.91],[2,1.46,432.84]],"ltp":1.44,"tv":63217.86,"id":5300737},{"trd":[[3.2,120.2]],"ltp":3.2,"tv":23456.99,"id":2497008}],"tv":86674.85}]}
{"op":"mcm","clk":"4299217706","pt":1632580046651,"mc":[{"id":"1.188136695","rc":[{"trd":[[1.44,2875.41]],"batb":[[0,1.42,5.77]],"batl":[[0,1.44,564.03],[1,1.45,828.49],[2,1.46,439.84]],"ltp":1.44,"tv":63223.75,"id":5300737},{"trd":[[3.25,219.41]],"batl":[[0,3.4,87.18]],"ltp":3.25,"tv":23479.78,"id":2497008}],"tv":86703.53}]}
{"op":"mcm","clk":"4299217969","pt":1632580047731,"mc":[{"id":"1.188136695","rc":[{"batl":[[1,1.45,647.64]],"ltp":1.44,"tv":63223.75,"id":5300737},{"batb":[[0,3.2,246.54],[1,3,282.82],[2,2.96,2.63]],"ltp":3.25,"tv":23479.78,"id":2497008}]}]}
{"op":"mcm","clk":"4299218281","pt":1632580048766,"mc":[{"id":"1.188136695","rc":[{"trd":[[1.44,3000.06]],"batl":[[0,1.44,439.38]],"ltp":1.44,"tv":63348.4,"id":5300737},{"trd":[[3.25,274.64]],"ltp":3.25,"tv":23535.01,"id":2497008}],"tv":86883.41}]}
{"op":"mcm","clk":"4299218534","pt":1632580049673,"mc":[{"id":"1.188136695","rc":[{"batb":[[0,1.42,374.47],[1,1.41,1518.67]],"ltp":1.44,"tv":63348.4,"id":5300737},{"batl":[[0,3.4,90.18]],"ltp":3.25,"tv":23535.01,"id":2497008}]}]}
{"op":"mcm","clk":"4299218863","pt":1632580050780,"mc":[{"id":"1.188136695","rc":[{"trd":[[1.44,3001.64]],"batb":[[0,1.42,1241.63]],"batl":[[0,1.44,737.56],[1,1.45,1026.1],[2,1.46,643.68]],"ltp":1.44,"tv":63349.98,"id":5300737},{"trd":[[3.25,275.34]],"batb":[[0,3.25,171.85],[1,3.2,485.25],[2,3.15,3]],"batl":[[0,3.4,111.04]],"ltp":3.25,"tv":23535.71,"id":2497008}],"tv":86885.69}]}
{"op":"mcm","clk":"4299219157","pt":1632580051798,"mc":[{"id":"1.188136695","rc":[{"batb":[[0,1.42,1306.99]],"batl":[[2,1.46,523.61]],"ltp":1.44,"tv":63349.98,"id":5300737},{"batl":[[0,3.4,90.18]],"ltp":3.25,"tv":23535.71,"id":2497008}]}]}
{"op":"mcm","clk":"4299219458","pt":1632580052780,"mc":[{"id":"1.188136695","rc":[{"trd":[[1.43,135.32]],"batb":[[0,1.42,1234.63],[1,1.41,1512.67]],"batl":[[0,1.43,903.99],[1,1.44,732.56],[2,1.45,1026.1]],"ltp":1.43,"tv":63350.25,"id":5300737},{"trd":[[3.3,578.52]],"batb":[[0,3.25,168.85],[1,3.2,487.57],[2,3,282.82]],"batl":[[0,3.4,87.06]],"ltp":3.3,"tv":23535.83,"id":2497008}],"tv":86886.08}]}
{"op":"mcm","clk":"4299219587","pt":1632580053188,"mc":[{"id":"1.188136695","rc":[{"trd":[[1.43,1613.16]],"batl":[[0,1.43,526.77]],"ltp":1.43,"tv":64828.1,"id":5300737},{"batb":[[2,3.05,2.09]],"ltp":3.3,"tv":23535.83,"id":2497008}],"tv":88363.93}]}
{"op":"mcm","clk":"4299219905","pt":1632580054264,"mc":[{"id":"1.188136695","rc":[{"trd":[[1.43,1786.95]],"batl":[[0,1.43,439.87],[1,1.44,755.06]],"ltp":1.43,"tv":65001.88,"id":5300737}],"tv":88537.71}]}
{"op":"mcm","clk":"4299220274","pt":1632580055519,"mc":[{"id":"1.188136695","rc":[{"trd":[[1.43,1787.99]],"batl":[[0,1.43,439.35]],"ltp":1.43,"tv":65002.93,"id":5300737},{"batb":[[0,3.25,178.85]],"ltp":3.3,"tv":23535.83,"id":2497008}],"tv":88538.76}]}
{"op":"mcm","clk":"4299220647","pt":1632580056783,"mc":[{"id":"1.188136695","rc":[{"batl":[[0,1.43,737.97]],"ltp":1.43,"tv":65002.93,"id":5300737},{"batb":[[2,3.1,2.14]],"ltp":3.3,"tv":23535.83,"id":2497008}]}]}
{"op":"mcm","clk":"4299220973","pt":1632580057793,"mc":[{"id":"1.188136695","rc":[{"batl":[[0,1.43,1075.97]],"ltp":1.43,"tv":65002.93,"id":5300737}]}]}
{"op":"mcm","clk":"4299221219","pt":1632580058489,"mc":[{"id":"1.188136695","rc":[{"trd":[[1.43,1967.71]],"batl":[[0,1.43,986.11]],"ltp":1.43,"tv":65182.64,"id":5300737}],"tv":88718.47}]}
{"op":"mcm","clk":"4299221686","pt":1632580060094,"mc":[{"id":"1.188136695","rc":[{"trd":[[1.42,88]],"batb":[[0,1.42,1204.63]],"ltp":1.42,"tv":65242.64,"id":5300737}],"tv":88778.47}]}
{"op":"mcm","clk":"4299221969","pt":1632580060997,"mc":[{"id":"1.188136695","rc":[{"trd":[[1.43,2002.77]],"batl":[[0,1.43,968.58]],"ltp":1.43,"tv":65277.7,"id":5300737}],"tv":88813.53}]}
{"op":"mcm","clk":"4299222443","pt":1632580062400,"mc":[{"id":"1.188136695","rc":[{"trd":[[1.43,2037.83]],"batl":[[0,1.43,951.05]],"ltp":1.43,"tv":65312.76,"id":5300737}],"tv":88848.59}]}
{"op":"mcm","clk":"4299223101","pt":1632580064503,"mc":[{"id":"1.188136695","rc":[{"trd":[[1.43,2102.3]],"batl":[[0,1.43,886.75]],"ltp":1.43,"tv":65377.23,"id":5300737},{"trd":[[3.3,606.31]],"ltp":3.3,"tv":23563.62,"id":2497008}],"tv":88940.85}]}
{"op":"mcm","clk":"4299223395","pt":1632580065419,"mc":[{"id":"1.188136695","rc":[{"trd":[[1.43,2123.24]],"batl":[[0,1.43,865.8]],"ltp":1.43,"tv":65398.18,"id":5300737},{"trd":[[3.3,615.39]],"ltp":3.3,"tv":23572.7,"id":2497008}],"tv":88970.88}]}
{"op":"mcm","clk":"4299223844","pt":1632580066830,"mc":[{"id":"1.188136695","rc":[{"trd":[[1.43,3418.37]],"batl":[[0,1.43,206.48]],"ltp":1.43,"tv":66693.3,"id":5300737},{"trd":[[3.3,625.59]],"ltp":3.3,"tv":23582.89,"id":2497008}],"tv":90276.19}]}
{"op":"mcm","clk":"4299224214","pt":1632580067818,"mc":[{"id":"1.188136695","rc":[{"trd":[[1.43,3422.59]],"batb":[[0,1.42,1060.88],[1,1.41,1],[2,1.4,2]],"batl":[[0,1.44,22.5],[1,1.47,26.5],[2,1.48,28.5]],"ltp":1.43,"tv":66697.52,"id":5300737},{"batb":[[0,3.25,10],[1,3.1,2.14],[2,3.05,2.09]],"batl":[[0,3.45,1],[1,3.7,1],[2,3.8,69.57]],"ltp":3.3,"tv":23582.89,"id":2497008}],"tv":90280.41}]}
{"op":"mcm","clk":"4299224516","pt":1632580068762,"mc":[{"id":"1.188136695","rc":[{"batb":[[0,1.43,4.29]],"batl":[[0,1.47,26.5],[1,1.48,28.5],[2,1.5,33.18]],"ltp":1.43,"tv":66697.52,"id":5300737},{"batb":[[0,3.1,2.14],[1,3.05,2.09],[2,3,285.32]],"ltp":3.3,"tv":23582.89,"id":2497008}]}]}
{"op":"mcm","clk":"4299224744","pt":1632580069422,"mc":[{"id":"1.188136695","rc":[{"batl":[[0,1.48,1.76],[1,1.5,33.18],[2,1.51,252.76]],"ltp":1.43,"tv":66697.52,"id":5300737},{"batb":[[0,3,285.32],[1,2.98,78.78],[2,2.96,95.56]],"ltp":3.3,"tv":23582.89,"id":2497008}]}]}
{"op":"mcm","clk":"4299225157","pt":1632580070824,"mc":[{"id":"1.188136695","rc":[{"batl":[[1,1.5,894.5],[2,1.51,799.02]],"ltp":1.43,"tv":66697.52,"id":5300737}]}]}
{"op":"mcm","clk":"4299225454","pt":1632580071801,"mc":[{"id":"1.188136695","rc":[{"trd":[[1.43,3430.69]],"batb":[[0,1.41,1.23],[1,1.4,2],[2,1.36,256.97]],"ltp":1.43,"tv":66705.62,"id":5300737}],"tv":90288.52}]}
{"op":"mcm","clk":"4299225754","pt":1632580072687,"mc":[{"id":"1.188136695","rc":[{"batb":[[0,1.43,17.76],[1,1.41,1],[2,1.4,2]],"batl":[[0,1.47,28.5],[1,1.48,1.76],[2,1.49,4]],"ltp":1.43,"tv":66705.62,"id":5300737},{"batb":[[0,3.1,2.24],[1,3,288.32],[2,2.98,82.78]],"batl":[[2,3.9,2]],"ltp":3.3,"tv":23582.89,"id":2497008}]}]}
{"op":"mcm","clk":"4299226071","pt":1632580073755,"mc":[{"id":"1.188136695","rc":[{"batb":[[0,1.44,432.84],[1,1.43,2240.11],[2,1.41,1]],"batl":[[0,1.48,1.76],[1,1.5,894.5],[2,1.51,799.02]],"ltp":1.43,"tv":66705.62,"id":5300737},{"batb":[[0,3,288.32],[1,2.98,82.78],[2,2.96,95.56]],"ltp":3.3,"tv":23582.89,"id":2497008}]}]}
{"op":"mcm","clk":"4299226412","pt":1632580074818,"mc":[{"id":"1.188136695","rc":[{"batl":[[0,3.25,1765.39],[1,3.3,1713.46],[2,3.35,1713.46]],"ltp":3.3,"tv":23582.89,"id":2497008}]}]}
{"op":"mcm","clk":"4299226703","pt":1632580075698,"mc":[{"id":"1.188136695","rc":[{"trd":[[1.48,2804.87]],"batb":[[0,1.46,14],[1,1.44,432.84],[2,1.43,2240.11]],"batl":[[0,1.5,894.5],[1,1.51,799.02],[2,1.52,7753.62]],"ltp":1.48,"tv":66707.38,"id":5300737},{"trd":[[3,163.56],[3.05,337.58]],"batb":[[0,3,275.56]],"batl":[[0,3.15,6],[1,3.25,529.62],[2,3.3,514.03]],"ltp":3.0,"tv":23609.26,"id":2497008}],"tv":90316.65}]}
{"op":"mcm","clk":"4299227000","pt":1632580076809,"mc":[{"id":"1.188136695","rc":[{"batb":[[0,1.46,1093.83],[1,1.45,654.69],[2,1.44,432.84]],"batl":[[0,1.49,90],[1,1.5,899.5],[2,1.51,799.02]],"ltp":1.48,"tv":66707.38,"id":5300737},{"batb":[[0,3.05,10.97],[1,3,275.56],[2,2.98,82.78]],"ltp":3.0,"tv":23609.26,"id":2497008}]}]}
{"op":"mcm","clk":"4299227293","pt":1632580077816,"mc":[{"id":"1.188136695","rc":[{"trd":[[1.46,1352.25],[1.48,3166.58]],"batb":[[0,1.48,771.41],[1,1.46,725.13],[2,1.45,654.69]],"ltp":1.48,"tv":67792.49,"id":5300737},{"batl":[[0,3.15,3]],"ltp":3.0,"tv":23609.26,"id":2497008}],"tv":91401.76}]}
{"op":"mcm","clk":"4299227557","pt":1632580078730,"mc":[{"id":"1.188136695","rc":[{"trd":[[1.48,3538.28]],"batb":[[0,1.48,585.56],[1,1.46,524.13],[2,1.45,704.8]],"batl":[[1,1.5,602.85],[2,1.51,252.76]],"ltp":1.48,"tv":68164.19,"id":5300737},{"batl":[[1,3.2,19.64],[2,3.25,529.62]],"ltp":3.0,"tv":23609.26,"id":2497008}],"tv":91773.46}]}
{"op":"mcm","clk":"4299227816","pt":1632580079507,"mc":[{"id":"1.188136695","rc":[{"batb":[[0,1.46,524.13],[1,1.45,654.69],[2,1.44,432.84]],"ltp":1.48,"tv":68164.19,"id":5300737}]}]}
{"op":"mcm","clk":"4299228219","pt":1632580080717,"mc":[{"id":"1.188136695","rc":[{"trd":[[1.47,4849.08]],"batb":[[0,1.47,331.95],[1,1.46,531.13],[2,1.45,659.69]],"batl":[[0,1.48,331.56],[1,1.49,421.5],[2,1.5,602.85]],"ltp":1.47,"tv":68172.31,"id":5300737},{"batb":[[0,3.05,13.97]],"ltp":3.0,"tv":23609.26,"id":2497008}],"tv":91781.58}]}
{"op":"mcm","clk":"4299228562","pt":1632580081826,"mc":[{"id":"1.188136695","rc":[{"batb":[[0,1.47,1597.91],[1,1.46,524.13],[2,1.45,1069.15]],"batl":[[1,1.49,1225.66],[2,1.5,597.85]],"ltp":1.47,"tv":68172.31,"id":5300737},{"trd":[[3.15,97.77]],"batb":[[0,3.05,10.97],[1,3,272.56],[2,2.98,78.78]],"batl":[[0,3.25,529.66],[1,3.3,514.03],[2,3.35,514.03]],"ltp":3.15,"tv":23615.18,"id":2497008}],"tv":91787.5}]}
{"op":"mcm","clk":"4299228902","pt":1632580082820,"mc":[{"id":"1.188136695","rc":[{"trd":[[1.48,3545.28]],"batb":[[0,1.47,2550.17],[1,1.46,574.24]],"batl":[[0,1.48,413.77],[1,1.49,1954.03]],"ltp":1.48,"tv":68179.31,"id":5300737}],"tv":91794.49}]}
{"op":"mcm","clk":"4299229149","pt":1632580083634,"mc":[{"id":"1.188136695","rc":[{"trd":[[1.48,3569.76]],"batl":[[0,1.48,406.53],[1,1.49,2496.58]],"ltp":1.48,"tv":68203.79,"id":5300737},{"trd":[[3.05,357.96]],"batb":[[0,3,273.34],[1,2.98,78.78],[2,2.96,95.56]],"ltp":3.05,"tv":23635.55,"id":2497008}],"tv":91839.35}]}
{"op":"mcm","clk":"4299229396","pt":1632580084450,"mc":[{"id":"1.188136695","rc":[{"batl":[[0,3.2,19.68],[1,3.25,529.62],[2,3.3,514.03]],"ltp":3.05,"tv":23635.55,"id":2497008}]}]}
{"op":"mcm","clk":"4299229794","pt":1632580085731,"mc":[{"id":"1.188136695","rc":[{"batl":[[0,1.48,758.53]],"ltp":1.48,"tv":68203.79,"id":5300737},{"batb":[[0,3.05,325.77],[1,3,272.56],[2,2.98,78.78]],"ltp":3.05,"tv":23635.55,"id":2497008}]}]}
{"op":"mcm","clk":"4299230101","pt":1632580086739,"mc":[{"id":"1.188136695","rc":[{"trd":[[1.47,6345.08],[1.48,3576.75]],"batb":[[0,1.47,849.91]],"batl":[[0,1.48,755.83],[1,1.49,1230.62]],"ltp":1.48,"tv":69706.79,"id":5300737},{"batl":[[0,3.25,529.66],[1,3.3,514.03],[2,3.35,514.03]],"ltp":3.05,"tv":23635.55,"id":2497008}],"tv":93342.35}]}
{"op":"mcm","clk":"4299230377","pt":1632580087640,"mc":[{"id":"1.188136695","rc":[{"trd":[[1.48,3594.57]],"batl":[[0,1.48,746.92]],"ltp":1.48,"tv":69724.61,"id":5300737},{"trd":[[3.05,358.66]],"batb":[[0,3.05,325.42],[1,3,315.68]],"batl":[[0,3.15,15.42],[1,3.25,529.62],[2,3.3,514.03]],"ltp":3.05,"tv":23636.25,"id":2497008}],"tv":93360.87}]}
{"op":"mcm","clk":"4299230743","pt":1632580088731,"mc":[{"id":"1.188136695","rc":[{"trd":[[1.48,3608.56]],"batl":[[0,1.48,920.78],[1,1.49,866.38]],"ltp":1.48,"tv":69738.6,"id":5300737},{"batb":[[0,3,316.11],[1,2.98,78.78],[2,2.96,95.56]],"ltp":3.05,"tv":23636.25,"id":2497008}],"tv":93374.86}]}
{"op":"mcm","clk":"4299231066","pt":1632580089722,"mc":[{"id":"1.188136695","rc":[{"trd":[[1.48,3609.14]],"batb":[[0,1.47,1044.47]],"batl":[[0,1.48,1282.19]],"ltp":1.48,"tv":69739.18,"id":5300737},{"batl":[[1,3.2,19.64],[2,3.25,529.62]],"ltp":3.05,"tv":23636.25,"id":2497008}],"tv":93375.44}]}
{"op":"mcm","clk":"4299231302","pt":1632580090458,"mc":[{"id":"1.188136695","rc":[{"batl":[[0,1.48,2005.6]],"ltp":1.48,"tv":69739.18,"id":5300737}]}]}
{"op":"mcm","clk":"4299231729","pt":1632580091830,"mc":[{"id":"1.188136695","rc":[{"batb":[[0,1.47,849.91],[1,1.42,269.12],[2,1.41,813.63]],"batl":[[0,1.48,1709.48],[1,1.49,90],[2,1.5,6.31]],"ltp":1.48,"tv":69739.18,"id":5300737},{"batb":[[0,3,43.55],[1,2.96,2.63],[2,2.92,2.19]],"batl":[[1,3.4,83.49],[2,3.45,126.52]],"ltp":3.05,"tv":23636.25,"id":2497008}]}]}
{"op":"mcm","clk":"4299232019","pt":1632580092743,"mc":[{"id":"1.188136695","rc":[{"batb":[[0,1.42,269.12],[1,1.41,813.63],[2,1.4,324.56]],"batl":[[0,1.48,5.92],[1,1.5,6.31],[2,1.51,400.9]],"ltp":1.48,"tv":69739.18,"id":5300737},{"batb":[[0,2.96,2.63],[1,2.92,2.19],[2,2.88,128.19]],"batl":[[0,3.15,15.38],[2,3.45,112.15]],"ltp":3.05,"tv":23636.25,"id":2497008}]}]}
{"op":"mcm","clk":"4299232317","pt":1632580093636,"mc":[{"id":"1.188136695","rc":[{"trd":[[1.48,3609.72]],"batl":[[0,1.48,5.51]],"ltp":1.48,"tv":69739.76,"id":5300737}],"tv":93376.01}]}
{"op":"mcm","clk":"4299232411","pt":1632580093940,"mc":[{"id":"1.188136695","rc":[{"batl":[[0,1.48,5.86]],"ltp":1.48,"tv":69739.76,"id":5300737}]}]}
{"op":"mcm","clk":"4299232819","pt":1632580095256,"mc":[{"id":"1.188136695","rc":[{"batb":[[2,1.4,1377.9]],"ltp":1.48,"tv":69739.76,"id":5300737}]}]}
{"op":"mcm","clk":"4299233244","pt":1632580096544,"mc":[{"id":"1.188136695","rc":[{"batb":[[2,1.4,324.56]],"ltp":1.48,"tv":69739.76,"id":5300737}]}]}
{"op":"mcm","clk":"4299233602","pt":1632580097643,"mc":[{"id":"1.188136695","rc":[{"batl":[[0,1.47,1.15],[1,1.48,5.51],[2,1.5,6.31]],"ltp":1.48,"tv":69739.76,"id":5300737}]}]}
{"op":"mcm","clk":"4299233924","pt":1632580098736,"mc":[{"id":"1.188136695","rc":[{"batl":[[1,1.48,713.22]],"ltp":1.48,"tv":69739.76,"id":5300737}]}]}
{"op":"mcm","clk":"4299234191","pt":1632580099522,"mc":[{"id":"1.188136695","rc":[{"trd":[[1.47,6345.78]],"batl":[[0,1.47,136.77]],"ltp":1.47,"tv":69740.46,"id":5300737}],"tv":93376.71}]}
{"op":"mcm","clk":"4299234415","pt":1632580100341,"mc":[{"id":"1.188136695","rc":[{"batb":[[0,1.44,1041.68],[1,1.43,700.8],[2,1.42,268.88]],"batl":[[1,1.48,880.96],[2,1.49,579.45]],"ltp":1.47,"tv":69740.46,"id":5300737},{"batb":[[0,2.98,13.15],[1,2.96,2.63],[2,2.92,2.19]],"ltp":3.05,"tv":23636.25,"id":2497008}]}]}
{"op":"mcm","clk":"4299234991","pt":1632580102341,"mc":[{"id":"1.188136695","rc":[{"trd":[[1.46,1385.43]],"batb":[[1,1.43,929.44]],"batl":[[0,1.46,325.24],[1,1.47,136.77],[2,1.48,880.96]],"ltp":1.46,"tv":69773.64,"id":5300737},{"trd":[[3.15,113.14]],"batl":[[0,3.4,83.49],[1,3.45,112.15],[2,3.5,111.3]],"ltp":3.15,"tv":23651.63,"id":2497008}],"tv":93425.27}]}
{"op":"mcm","clk":"4299235434","pt":1632580103752,"mc":[{"id":"1.188136695","rc":[{"batb":[[1,1.43,700.8]],"batl":[[0,1.47,136.77],[1,1.48,880.96],[2,1.49,579.45]],"ltp":1.46,"tv":69773.64,"id":5300737},{"batb":[[0,2.96,2.63],[1,2.92,2.19],[2,2.88,128.19]],"ltp":3.15,"tv":23651.63,"id":2497008}]}]}
{"op":"mcm","clk":"4299235757","pt":1632580104747,"mc":[{"id":"1.188136695","rc":[{"batb":[[0,1.42,269.12],[1,1.41,813.63],[2,1.4,324.56]],"batl":[[0,1.46,1.76],[1,1.47,136.77],[2,1.5,7.11]],"ltp":1.46,"tv":69773.64,"id":5300737}]}]}
{"op":"mcm","clk":"4299236096","pt":1632580105735,"mc":[{"id":"1.188136695","rc":[{"batl":[[0,1.46,1.41]],"ltp":1.46,"tv":69773.64,"id":5300737}]}]}
{"op":"mcm","clk":"4299236389","pt":1632580106754,"mc":[{"id":"1.188136695","rc":[{"trd":[[1.47,6356.98]],"batb":[[2,1.4,1377.9]],"batl":[[0,1.47,131.17],[1,1.5,7.11],[2,1.51,400.9]],"ltp":1.47,"tv":69784.84,"id":5300737}],"tv":93436.47}]}
{"op":"mcm","clk":"4299237224","pt":1632580109580,"mc":[{"id":"1.188136695","rc":[{"trd":[[1.47,6358.08]],"batb":[[0,1.42,275.12],[1,1.41,819.63]],"batl":[[0,1.47,130.62]],"ltp":1.47,"tv":69785.94,"id":5300737},{"batl":[[0,3.4,85.49]],"ltp":3.15,"tv":23651.63,"id":2497008}],"tv":93437.57}]}
{"op":"mcm","clk":"4299237442","pt":1632580110247,"mc":[{"id":"1.188136695","rc":[{"batb":[[0,1.43,1.03],[1,1.42,274.88],[2,1.41,819.63]],"ltp":1.47,"tv":69785.94,"id":5300737}]}]}
{"op":"mcm","clk":"4299237735","pt":1632580111145,"mc":[{"id":"1.188136695","rc":[{"trd":[[1.46,1387.03]],"batb":[[0,1.42,275.12],[1,1.41,819.63],[2,1.4,1377.9]],"batl":[[0,1.46,2654.04],[1,1.47,130.62],[2,1.5,7.11]],"ltp":1.46,"tv":69787.54,"id":5300737}],"tv":93439.17}]}
{"op":"mcm","clk":"4299238207","pt":1632580112760,"mc":[{"id":"1.188136695","rc":[{"batl":[[0,1.44,7870.74],[1,1.45,3956.9],[2,1.46,6494.56]],"ltp":1.46,"tv":69787.54,"id":5300737}]}]}
{"op":"mcm","clk":"4299238495","pt":1632580113825,"mc":[{"id":"1.188136695","rc":[{"batb":[[0,1.41,813.87],[1,1.4,1377.9],[2,1.39,829.56]],"batl":[[0,1.45,197.85],[1,1.46,2846.07],[2,1.47,322.65]],"ltp":1.46,"tv":69787.54,"id":5300737},{"batl":[[0,3.45,112.15],[1,3.5,111.3],[2,3.6,2]],"ltp":3.15,"tv":23651.63,"id":2497008}]}]}
{"op":"mcm","clk":"4299238828","pt":1632580114786,"mc":[{"id":"1.188136695","rc":[{"trd":[[1.45,3720.26]],"batl":[[0,1.44,14.08],[1,1.45,1186.73],[2,1.46,1585]],"ltp":1.45,"tv":69788.22,"id":5300737},{"batb":[[0,3.25,2.05],[1,2.96,2.63],[2,2.92,2.19]],"ltp":3.15,"tv":23651.63,"id":2497008}],"tv":93439.85}]}
{"op":"mcm","clk":"4299239153","pt":1632580115805,"mc":[{"id":"1.188136695","rc":[{"trd":[[1.41,1.66],[1.43,3431.15],[1.44,3086.23]],"batb":[[0,1.41,812.8]],"batl":[[0,1.44,772.54],[1,1.45,1832.66]],"ltp":1.44,"tv":69874.94,"id":5300737},{"trd":[[3.25,295.89]],"batb":[[0,3.2,234.8],[1,3,280.79],[2,2.96,2.63]],"ltp":3.25,"tv":23672.18,"id":2497008}],"tv":93547.12}]}
{"op":"mcm","clk":"4299239457","pt":1632580116698,"mc":[{"id":"1.188136695","rc":[{"batl":[[1,1.45,1922.66]],"ltp":1.44,"tv":69874.94,"id":5300737},{"batb":[[0,3.25,40],[1,3.2,234.8],[2,3,280.79]],"ltp":3.25,"tv":23672.18,"id":2497008}]}]}
{"op":"mcm","clk":"4299239829","pt":1632580117774,"mc":[{"id":"1.188136695","rc":[{"trd":[[1.44,3086.57]],"batb":[[0,1.42,723.41],[1,1.41,812.8],[2,1.4,1377.9]],"batl":[[0,1.44,772.37]],"ltp":1.44,"tv":69875.28,"id":5300737},{"batl":[[0,3.45,126.5]],"ltp":3.25,"tv":23672.18,"id":2497008}],"tv":93547.46}]}
{"op":"mcm","clk":"4299240161","pt":1632580118813,"mc":[{"id":"1.188136695","rc":[{"trd":[[1.42,89.94]],"batb":[[0,1.42,903.29]],"batl":[[1,1.45,1832.66]],"ltp":1.42,"tv":69877.22,"id":5300737}],"tv":93549.4}]}
{"op":"mcm","clk":"4299240491","pt":1632580119787,"mc":[{"id":"1.188136695","rc":[{"trd":[[1.44,3090.8]],"batb":[[0,1.42,1217.32],[1,1.41,882.59]],"batl":[[0,1.43,779.3],[1,1.44,848.25],[2,1.45,1832.66]],"ltp":1.44,"tv":69881.44,"id":5300737}],"tv":93553.63}]}
{"op":"mcm","clk":"4299240801","pt":1632580120771,"mc":[{"id":"1.188136695","rc":[{"trd":[[1.42,107.65],[1.43,3431.83]],"batb":[[0,1.42,1393.92]],"batl":[[0,1.43,1864.08],[1,1.44,1191.96]],"ltp":1.42,"tv":69899.82,"id":5300737}],"tv":93572.0}]}
{"op":"mcm","clk":"4299240992","pt":1632580121479,"mc":[{"id":"1.188136695","rc":[{"trd":[[1.43,3432.53]],"batb":[[0,1.42,1208.46]],"batl":[[0,1.43,1863.73]],"ltp":1.43,"tv":69900.52,"id":5300737}],"tv":93572.7}]}
{"op":"mcm","clk":"4299241422","pt":1632580122778,"mc":[{"id":"1.188136695","rc":[{"trd":[[1.43,3433.2]],"batb":[[0,1.42,1671.31],[1,1.41,1435.43]],"batl":[[0,1.43,2155.39],[1,1.44,1652.23],[2,1.45,2254.36]],"ltp":1.43,"tv":69901.19,"id":5300737},{"batb":[[0,3.25,204.05],[1,3.2,425.88],[2,3.05,2.09]],"batl":[[0,3.4,193.3],[1,3.45,352.43],[2,3.5,111.3]],"ltp":3.25,"tv":23672.18,"id":2497008}],"tv":93573.37}]}
{"op":"mcm","clk":"4299241742","pt":1632580123777,"mc":[{"id":"1.188136695","rc":[{"batb":[[0,1.42,1676.31]],"ltp":1.43,"tv":69901.19,"id":5300737},{"batb":[[2,3.1,2.04]],"batl":[[0,3.35,2],[1,3.4,193.3],[2,3.45,352.43]],"ltp":3.25,"tv":23672.18,"id":2497008}]}]}
{"op":"mcm","clk":"4299241995","pt":1632580124692,"mc":[{"id":"1.188136695","rc":[{"batb":[[1,1.41,1365.65]],"batl":[[1,1.44,1967.09],[2,1.45,2759.62]],"ltp":1.43,"tv":69901.19,"id":5300737},{"batb":[[0,3.3,171.42],[1,3.25,429.47],[2,3.2,425.88]],"ltp":3.25,"tv":23672.18,"id":2497008}]}]}
{"op":"mcm","clk":"4299242303","pt":1632580125636,"mc":[{"id":"1.188136695","rc":[{"trd":[[1.43,3896.75]],"batl":[[0,1.43,1923.62]],"ltp":1.43,"tv":70364.74,"id":5300737}],"tv":94036.93}]}
{"op":"mcm","clk":"4299242864","pt":1632580127603,"mc":[{"id":"1.188136695","rc":[{"trd":[[1.43,4068.18]],"batb":[[0,1.42,1671.31]],"batl":[[0,1.43,1837.9]],"ltp":1.43,"tv":70536.17,"id":5300737},{"batb":[[1,3.25,164.05]],"ltp":3.25,"tv":23672.18,"id":2497008}],"tv":94208.35}]}
{"op":"mcm","clk":"4299243199","pt":1632580128732,"mc":[{"id":"1.188136695","rc":[{"trd":[[1.43,4376.37]],"batl":[[0,1.43,1683.8],[1,1.44,1574.25]],"ltp":1.43,"tv":70844.36,"id":5300737}],"tv":94516.54}]}
{"op":"mcm","clk":"4299243372","pt":1632580129216,"mc":[{"id":"1.188136695","rc":[{"trd":[[1.42,119.68]],"batb":[[0,1.42,1665.29]],"batl":[[2,1.45,2254.36]],"ltp":1.42,"tv":70856.4,"id":5300737}],"tv":94528.58}]}
{"op":"mcm","clk":"4299243832","pt":1632580130590,"mc":[{"id":"1.188136695","rc":[{"trd":[[1.43,4386.37]],"batb":[[0,1.42,776.87]],"batl":[[0,1.43,412.84]],"ltp":1.43,"tv":70866.4,"id":5300737},{"batb":[[0,3.3,210.55]],"ltp":3.25,"tv":23672.18,"id":2497008}],"tv":94538.58}]}
{"op":"mcm","clk":"4299244031","pt":1632580131276,"mc":[{"id":"1.188136695","rc":[{"trd":[[1.43,4389.89]],"batl":[[0,1.43,411.08]],"ltp":1.43,"tv":70869.92,"id":5300737}],"tv":94542.1}]}
{"op":"mcm","clk":"4299244343","pt":1632580132370,"mc":[{"id":"1.188136695","rc":[{"trd":[[3.3,797.01]],"batb":[[0,3.3,124.84]],"ltp":3.3,"tv":23843.6,"id":2497008}],"tv":94713.53}]}
{"op":"mcm","clk":"4299244766","pt":1632580133806,"mc":[{"id":"1.188136695","rc":[{"trd":[[1.43,5152.47]],"batl":[[0,1.43,29.79]],"ltp":1.43,"tv":71632.5,"id":5300737},{"trd":[[3.3,853.61]],"batb":[[0,3.3,96.54]],"ltp":3.3,"tv":23900.21,"id":2497008}],"tv":95532.71}]}
{"op":"mcm","clk":"4299245074","pt":1632580134805,"mc":[{"id":"1.188136695","rc":[{"batb":[[1,1.41,1158.48],[2,1.4,1055.34]],"batl":[[2,1.45,1067.63]],"ltp":1.43,"tv":71632.5,"id":5300737},{"batl":[[2,3.45,227.25]],"ltp":3.3,"tv":23900.21,"id":2497008}]}]}
{"op":"mcm","clk":"4299245373","pt":1632580135799,"mc":[{"id":"1.188136695","rc":[{"trd":[[1.43,5153.87]],"batb":[[0,1.4,2.17],[1,1.39,12.1],[2,1.36,176.19]],"batl":[[0,1.44,90],[1,1.47,154.12],[2,1.48,114.2]],"ltp":1.43,"tv":71633.9,"id":5300737},{"batb":[[0,3.3,39.13],[1,3.1,2.04],[2,3.05,2.09]],"batl":[[1,3.45,1.31],[2,3.7,1]],"ltp":3.3,"tv":23900.21,"id":2497008}],"tv":95534.11}]}
{"op":"mcm","clk":"4299245627","pt":1632580136736,"mc":[{"id":"1.188136695","rc":[{"trd":[[1.44,3118.08]],"batl":[[0,1.43,262.21]],"ltp":1.44,"tv":71661.18,"id":5300737},{"batb":[[0,3.1,2.04],[1,3.05,2.09],[2,3,283.29]],"batl":[[1,3.45,1]],"ltp":3.3,"tv":23900.21,"id":2497008}],"tv":95561.39}]}
{"op":"mcm","clk":"4299245710","pt":1632580136996,"mc":[{"id":"1.188136695","rc":[{"trd":[[1.43,5157.41]],"batl":[[0,1.47,154.12],[1,1.48,114.2],[2,1.49,13.1]],"ltp":1.43,"tv":71664.72,"id":5300737},{"batl":[[0,3.45,1],[1,3.7,1],[2,3.8,71.17]],"ltp":3.3,"tv":23900.21,"id":2497008}],"tv":95564.93}]}
{"op":"mcm","clk":"4299246159","pt":1632580138602,"mc":[{"id":"1.188136695","rc":[{"batb":[[0,1.43,8],[1,1.4,2.17],[2,1.39,12.1]],"batl":[[2,1.49,622.01]],"ltp":1.43,"tv":71664.72,"id":5300737}]}]}
{"op":"mcm","clk":"4299246422","pt":1632580139387,"mc":[{"id":"1.188136695","rc":[{"trd":[[1.44,3118.1]],"batb":[[0,1.43,11.51]],"ltp":1.44,"tv":71664.74,"id":5300737}],"tv":95564.95}]}
{"op":"mcm","clk":"4299246649","pt":1632580140104,"mc":[{"id":"1.188136695","rc":[{"batb":[[2,1.36,176.19]],"ltp":1.44,"tv":71664.74,"id":5300737}]}]}
{"op":"mcm","clk":"4299247156","pt":1632580141725,"mc":[{"id":"1.188136695","rc":[{"batl":[[0,1.46,5],[1,1.47,154.12],[2,1.48,114.2]],"ltp":1.44,"tv":71664.74,"id":5300737}]}]}
{"op":"mcm","clk":"4299247491","pt":1632580142828,"mc":[{"id":"1.188136695","rc":[{"trd":[[1.4,9.17],[1.41,2],[1.42,124.51],[1.43,5180.43]],"batb":[[0,1.36,176.19],[1,1.35,1028.91],[2,1.34,335.27]],"batl":[[0,1.42,7.93],[1,1.44,20.58],[2,1.46,1515.68]],"ltp":1.42,"tv":71702.11,"id":5300737},{"trd":[[3.35,11.93],[3.45,1],[3.5,1.08]],"batb":[[0,3.3,21.18],[1,3.1,2.04],[2,3.05,2.09]],"batl":[[0,3.45,20.9]],"ltp":3.35,"tv":23904.34,"id":2497008}],"tv":95606.45}]}
{"op":"mcm","clk":"4299247752","pt":1632580143627,"mc":[{"id":"1.188136695","rc":[{"batl":[[1,1.46,10],[2,1.47,154.12]],"ltp":1.42,"tv":71702.11,"id":5300737},{"batb":[[0,3.1,2.04],[1,3.05,2.09],[2,3,283.29]],"batl":[[0,3.7,1],[1,3.8,71.17],[2,3.85,98.53]],"ltp":3.35,"tv":23904.34,"id":2497008}]}]}
{"op":"mcm","clk":"4299248084","pt":1632580144613,"mc":[{"id":"1.188136695","rc":[{"trd":[[1.42,140.37]],"batb":[[0,1.43,13.59],[1,1.41,12.56],[2,1.36,176.19]],"batl":[[0,1.46,10],[1,1.47,154.12],[2,1.48,114.2]],"ltp":1.42,"tv":71717.97,"id":5300737},{"batb":[[0,3.15,10.2],[1,3.1,2.04],[2,3.05,2.09]],"ltp":3.35,"tv":23904.34,"id":2497008}],"tv":95622.31}]}
{"op":"mcm","clk":"4299248399","pt":1632580145809,"mc":[{"id":"1.188136695","rc":[{"trd":[[1.43,5209.15]],"batb":[[0,1.41,12.56],[1,1.39,913.73],[2,1.38,822.38]],"batl":[[0,1.43,1001.97],[1,1.44,663.08],[2,1.46,10]],"ltp":1.43,"tv":71746.68,"id":5300737},{"trd":[[3.3,854.27]],"batl":[[0,3.65,5],[1,3.7,1],[2,3.8,71.17]],"ltp":3.3,"tv":23905.0,"id":2497008}],"tv":95651.68}]}
{"op":"mcm","clk":"4299248706","pt":1632580146813,"mc":[{"id":"1.188136695","rc":[{"trd":[[1.41,27.12],[1.42,143.2]],"batb":[[0,1.37,444.42],[1,1.36,176.19],[2,1.35,1028.91]],"batl":[[0,1.41,416.42],[1,1.46,10],[2,1.47,154.12]],"ltp":1.41,"tv":71774.63,"id":5300737},{"trd":[[3.35,13.13]],"batb":[[0,3.1,2.04],[1,3.05,2.09],[2,3,283.29]],"batl":[[0,3.7,1],[1,3.8,71.17],[2,3.85,98.53]],"ltp":3.35,"tv":23906.2,"id":2497008}],"tv":95680.83}]}
{"op":"mcm","clk":"4299248986","pt":1632580147727,"mc":[{"id":"1.188136695","rc":[{"batb":[[0,1.36,176.19],[1,1.35,1028.91],[2,1.34,335.27]],"batl":[[0,1.46,10],[1,1.47,154.12],[2,1.48,114.2]],"ltp":1.41,"tv":71774.63,"id":5300737}]}]}
{"op":"mcm","clk":"4299249051","pt":1632580147939,"mc":[{"id":"1.188136695","rc":[{"batl":[[0,3.7,1.87]],"ltp":3.35,"tv":23906.2,"id":2497008}]}]}
{"op":"mcm","clk":"4299249371","pt":1632580149063,"mc":[{"id":"1.188136695","rc":[{"trd":[[1.46,1387.29]],"batl":[[0,1.46,9.87]],"ltp":1.46,"tv":71774.88,"id":5300737}],"tv":95681.09}]}
{"op":"mcm","clk":"4299250097","pt":1632580151529,"mc":[{"id":"1.188136695","rc":[{"trd":[[1.46,1388.81]],"batb":[[2,1.34,1646.86]],"batl":[[0,1.46,9.11]],"ltp":1.46,"tv":71776.4,"id":5300737}],"tv":95682.61}]}
{"op":"mcm","clk":"4299250839","pt":1632580154053,"mc":[{"id":"1.188136695","rc":[{"trd":[[1.43,5211.15]],"batl":[[0,1.4,432.84],[1,1.42,2222],[2,1.46,9.11]],"ltp":1.43,"tv":71778.41,"id":5300737},{"trd":[[3.3,855.14]],"batl":[[0,3.7,1]],"ltp":3.3,"tv":23907.07,"id":2497008}],"tv":95685.48}]}
{"op":"mcm","clk":"4299251362","pt":1632580155818,"mc":[{"id":"1.188136695","rc":[{"trd":[[1.37,2.7]],"batb":[[0,1.36,1]],"batl":[[0,1.37,47.3],[1,1.38,1193.04],[2,1.39,773.08]],"ltp":1.37,"tv":71781.11,"id":5300737},{"trd":[[3.7,1]],"batb":[[0,3.65,471.58],[1,3.6,459.7],[2,3.55,457.7]],"batl":[[0,3.85,98.53],[1,3.9,91.19],[2,3.95,1]],"ltp":3.7,"tv":23908.07,"id":2497008}],"tv":95689.18}]}
{"op":"mcm","clk":"4299251594","pt":1632580156638,"mc":[{"id":"1.188136695","rc":[{"trd":[[1.37,33.57]],"batl":[[0,1.37,16.43],[2,1.39,863.08]],"ltp":1.37,"tv":71811.98,"id":5300737},{"trd":[[3.7,12.43]],"batb":[[1,3.6,639.37]],"ltp":3.7,"tv":23919.5,"id":2497008}],"tv":95731.48}]}
{"op":"mcm","clk":"4299251924","pt":1632580157830,"mc":[{"id":"1.188136695","rc":[{"batb":[[1,3.6,673.98]],"ltp":3.7,"tv":23919.5,"id":2497008}]}]}
{"op":"mcm","clk":"4299252239","pt":1632580158815,"mc":[{"id":"1.188136695","rc":[{"trd":[[1.37,37.11]],"batl":[[0,1.38,1193.04],[1,1.39,863.08],[2,1.4,432.84]],"ltp":1.37,"tv":71815.52,"id":5300737},{"trd":[[3.7,13.48]],"ltp":3.7,"tv":23920.55,"id":2497008}],"tv":95736.07}]}
{"op":"mcm","clk":"4299252467","pt":1632580159544,"mc":[{"id":"1.188136695","rc":[{"batb":[[0,1.36,63.39],[1,1.35,1090.01]],"batl":[[0,1.37,68.18],[1,1.38,1193.04],[2,1.39,773.08]],"ltp":1.37,"tv":71815.52,"id":5300737}]}]}
{"op":"mcm","clk":"4299252826","pt":1632580160727,"mc":[{"id":"1.188136695","rc":[{"batb":[[1,1.35,1517.04],[2,1.34,1712.78]],"batl":[[0,1.37,488.98],[1,1.38,1260.68]],"ltp":1.37,"tv":71815.52,"id":5300737},{"batb":[[1,3.6,639.37]],"ltp":3.7,"tv":23920.55,"id":2497008}]}]}
{"op":"mcm","clk":"4299253121","pt":1632580161824,"mc":[{"id":"1.188136695","rc":[{"trd":[[1.37,68.69]],"batb":[[0,1.36,143.39]],"batl":[[0,1.37,473.19]],"ltp":1.37,"tv":71847.1,"id":5300737}],"tv":95767.65}]}
{"op":"mcm","clk":"4299253330","pt":1632580162634,"mc":[{"id":"1.188136695","rc":[{"batb":[[0,1.36,544.04]],"batl":[[1,1.38,1745.53]],"ltp":1.37,"tv":71847.1,"id":5300737}]}]}
{"op":"mcm","clk":"4299253692","pt":1632580163819,"mc":[{"id":"1.188136695","rc":[{"trd":[[1.37,75.81]],"batl":[[0,1.37,466.06]],"ltp":1.37,"tv":71854.22,"id":5300737},{"trd":[[3.7,16.12]],"batb":[[0,3.65,505.54]],"ltp":3.7,"tv":23923.18,"id":2497008}],"tv":95777.41}]}
{"op":"mcm","clk":"4299254009","pt":1632580164765,"mc":[{"id":"1.188136695","rc":[{"trd":[[1.35,10.74],[1.36,1088.09]],"batb":[[0,1.35,1511.67],[1,1.34,1646.86],[2,1.33,990.92]],"batl":[[0,1.37,525.98],[1,1.38,2071.31],[2,1.39,1229.92]],"ltp":1.35,"tv":72953.04,"id":5300737},{"batb":[[1,3.6,790.18],[2,3.55,636.57]],"ltp":3.7,"tv":23923.18,"id":2497008}],"tv":96876.23}]}
{"op":"mcm","clk":"4299254288","pt":1632580165565,"mc":[{"id":"1.188136695","rc":[{"trd":[[1.37,82.83]],"batl":[[0,1.37,931.31],[1,1.38,2585.58]],"ltp":1.37,"tv":72960.07,"id":5300737},{"batb":[[0,3.7,151.38],[1,3.65,505.54],[2,3.6,987.32]],"ltp":3.7,"tv":23923.18,"id":2497008}],"tv":96883.26}]}
{"op":"mcm","clk":"4299254555","pt":1632580166348,"mc":[{"id":"1.188136695","rc":[{"trd":[[1.37,101.57]],"batl":[[0,1.37,921.94]],"ltp":1.37,"tv":72978.8,"id":5300737}],"tv":96901.99}]}
{"op":"mcm","clk":"4299255033","pt":1632580167831,"mc":[{"id":"1.188136695","rc":[{"trd":[[1.37,201.46]],"batb":[[0,1.36,443.13],[1,1.35,2061.08],[2,1.34,1646.86]],"batl":[[0,1.37,872],[1,1.38,2526.96]],"ltp":1.37,"tv":73078.7,"id":5300737},{"batl":[[0,3.8,158.59],[1,3.85,98.53],[2,3.9,281.37]],"ltp":3.7,"tv":23923.18,"id":2497008}],"tv":97001.88}]}
{"op":"mcm","clk":"4299255297","pt":1632580168763,"mc":[{"id":"1.188136695","rc":[{"trd":[[1.36,1886.15],[1.37,204.98]],"batb":[[0,1.35,2061.08],[1,1.34,1646.86],[2,1.33,990.92]],"batl":[[0,1.36,635],[1,1.37,870.24],[2,1.38,2526.96]],"ltp":1.36,"tv":73880.28,"id":5300737}],"tv":97803.47}]}
{"op":"mcm","clk":"4299255570","pt":1632580169655,"mc":[{"id":"1.188136695","rc":[{"trd":[[1.36,1903.03]],"batl":[[0,1.36,626.56]],"ltp":1.36,"tv":73897.16,"id":5300737},{"batl":[[1,3.9,281.37],[2,3.95,1]],"ltp":3.7,"tv":23923.18,"id":2497008}],"tv":97820.35}]}
{"op":"mcm","clk":"4299255864","pt":1632580170549,"mc":[{"id":"1.188136695","rc":[{"trd":[[1.36,2337.47]],"batl":[[0,1.36,409.34]],"ltp":1.36,"tv":74331.6,"id":5300737}],"tv":98254.79}]}
{"op":"mcm","clk":"4299256248","pt":1632580171647,"mc":[{"id":"1.188136695","rc":[{"trd":[[1.36,2338.17]],"batl":[[0,1.36,408.99]],"ltp":1.36,"tv":74332.3,"id":5300737},{"batl":[[0,3.9,281.37],[1,3.95,1],[2,4.3,2.86]],"ltp":3.7,"tv":23923.18,"id":2497008}],"tv":98255.49}]}
{"op":"mcm","clk":"4299256377","pt":1632580172043,"mc":[{"id":"1.188136695","rc":[{"trd":[[1.36,2346.59]],"batl":[[0,1.36,404.78]],"ltp":1.36,"tv":74340.72,"id":5300737}],"tv":98263.91}]}
{"op":"mcm","clk":"4299257276","pt":1632580175029,"mc":[{"id":"1.188136695","rc":[{"trd":[[1.36,2366.59]],"batl":[[0,1.36,406.78]],"ltp":1.36,"tv":74360.72,"id":5300737},{"batl":[[0,3.9,295.79]],"ltp":3.7,"tv":23923.18,"id":2497008}],"tv":98283.91}]}
{"op":"mcm","clk":"4299257792","pt":1632580176725,"mc":[{"id":"1.188136695","rc":[{"trd":[[1.35,214.74],[1.36,2381.31]],"batb":[[0,1.35,1959.08]],"batl":[[0,1.36,629.64],[1,1.37,810.33]],"ltp":1.35,"tv":74579.44,"id":5300737}],"tv":98502.63}]}
{"op":"mcm","clk":"4299258086","pt":1632580177770,"mc":[{"id":"1.188136695","rc":[{"trd":[[1.36,2391.31]],"batb":[[0,1.35,1154.59],[1,1.34,1311.59]],"batl":[[0,1.36,624.64],[1,1.37,401.48],[2,1.38,1614.94]],"ltp":1.36,"tv":74589.44,"id":5300737},{"batb":[[0,3.65,33.96],[1,3.6,179.67],[2,3.5,3]],"batl":[[0,3.95,1],[1,4.4,1.86],[2,4.5,71.19]],"ltp":3.7,"tv":23923.18,"id":2497008}],"tv":98512.63}]}
{"op":"mcm","clk":"4299258347","pt":1632580178751,"mc":[{"id":"1.188136695","rc":[{"trd":[[1.36,2411.62]],"batb":[[0,1.35,61.1],[1,1.31,1],[2,1.3,17.53]],"batl":[[0,1.36,12],[1,1.38,90],[2,1.41,43.43]],"ltp":1.36,"tv":74609.75,"id":5300737},{"trd":[[3.75,2.64]],"batb":[[1,3.4,2.01],[2,3.35,2]],"ltp":3.75,"tv":23925.82,"id":2497008}],"tv":98535.57}]}
{"op":"mcm","clk":"4299258619","pt":1632580179722,"mc":[{"id":"1.188136695","rc":[{"batb":[[0,1.31,1],[1,1.3,17.53],[2,1.28,279.95]],"batl":[[1,1.41,43.43],[2,1.42,30.25]],"ltp":1.36,"tv":74609.75,"id":5300737},{"batb":[[0,3.4,2.01],[1,3.35,2],[2,3.25,304.79]],"ltp":3.75,"tv":23925.82,"id":2497008}]}]}
{"op":"mcm","clk":"4299258929","pt":1632580180739,"mc":[{"id":"1.188136695","rc":[{"batb":[[0,1.36,8.63],[1,1.31,1],[2,1.3,17.53]],"batl":[[0,1.41,10.93],[1,1.44,27.58],[2,1.45,238.31]],"ltp":1.36,"tv":74609.75,"id":5300737},{"batb":[[0,3.25,304.79],[1,3.2,91.42],[2,3.15,123.84]],"ltp":3.75,"tv":23925.82,"id":2497008}]}]}
{"op":"mcm","clk":"4299259233","pt":1632580181763,"mc":[{"id":"1.188136695","rc":[{"batb":[[0,1.36,27.49]],"batl":[[1,1.44,950.93],[2,1.45,882.87]],"ltp":1.36,"tv":74609.75,"id":5300737},{"batb":[[0,3.25,71.51],[1,3.2,327.99]],"batl":[[0,3.75,1.33],[1,3.95,1],[2,4.4,1.86]],"ltp":3.75,"tv":23925.82,"id":2497008}]}]}
{"op":"mcm","clk":"4299259452","pt":1632580182469,"mc":[{"id":"1.188136695","rc":[{"batb":[[0,1.36,32.41]],"ltp":1.36,"tv":74609.75,"id":5300737}]}]}
{"op":"mcm","clk":"4299259803","pt":1632580183646,"mc":[{"id":"1.188136695","rc":[{"trd":[[1.36,2459.63]],"batb":[[0,1.36,8.69]],"ltp":1.36,"tv":74657.76,"id":5300737}],"tv":98583.58}]}
{"op":"mcm","clk":"4299260076","pt":1632580184458,"mc":[{"id":"1.188136695","rc":[{"batl":[[0,3.95,1],[1,4.4,1.86],[2,4.5,71.19]],"ltp":3.75,"tv":23925.82,"id":2497008}]}]}
{"op":"mcm","clk":"4299260384","pt":1632580185453,"mc":[{"id":"1.188136695","rc":[{"batb":[[0,1.36,5.21]],"batl":[[0,1.4,10],[1,1.41,10.93],[2,1.44,950.93]],"ltp":1.36,"tv":74657.76,"id":5300737}]}]}
{"op":"mcm","clk":"4299260774","pt":1632580186762,"mc":[{"id":"1.188136695","rc":[{"batl":[[1,1.41,42.43],[2,1.47,130.62]],"ltp":1.36,"tv":74657.76,"id":5300737},{"batb":[[0,3.4,2.01],[1,3.25,2.01],[2,3.2,236.57]],"batl":[[0,3.95,1.3]],"ltp":3.75,"tv":23925.82,"id":2497008}]}]}
{"op":"mcm","clk":"4299261098","pt":1632580187739,"mc":[{"id":"1.188136695","rc":[{"batb":[[0,1.36,5.04]],"batl":[[0,1.39,20],[1,1.4,10],[2,1.41,10.93]],"ltp":1.36,"tv":74657.76,"id":5300737},{"batb":[[0,3.25,2.01],[1,3.2,236.57],[2,2.82,1]],"ltp":3.75,"tv":23925.82,"id":2497008}]}]}
{"op":"mcm","clk":"4299261413","pt":1632580188790,"mc":[{"id":"1.188136695","rc":[{"trd":[[1.31,2],[1.33,5.55],[1.36,2470.94]],"batb":[[0,1.3,17.53],[1,1.28,1002.8],[2,1.27,2512.68]],"batl":[[0,1.35,2222],[1,1.39,20],[2,1.4,10]],"ltp":1.31,"tv":74676.63,"id":5300737},{"trd":[[3.75,3.29],[3.95,1],[4,0.86]],"batl":[[0,4.4,1],[1,4.5,71.19],[2,4.6,68.41]],"ltp":4.0,"tv":23928.33,"id":2497008}],"tv":98604.96}]}
{"op":"mcm","clk":"4299261721","pt":1632580189787,"mc":[{"id":"1.188136695","rc":[{"batl":[[0,1.31,1488.28],[1,1.32,2289.11],[2,1.33,1282.18]],"ltp":1.31,"tv":74676.63,"id":5300737}]}]}
{"op":"mcm","clk":"4299261965","pt":1632580190658,"mc":[{"id":"1.188136695","rc":[{"batl":[[0,1.31,2440.54]],"ltp":1.31,"tv":74676.63,"id":5300737},{"trd":[[4.2,20]],"batb":[[0,4.2,233.42],[1,3.85,151.6],[2,3.65,3]],"ltp":4.2,"tv":23948.33,"id":2497008}],"tv":98624.96}]}
{"op":"mcm","clk":"4299262531","pt":1632580192706,"mc":[{"id":"1.188136695","rc":[{"batl":[[0,4.4,4]],"ltp":4.2,"tv":23948.33,"id":2497008}]}]}
{"op":"mcm","clk":"4299262853","pt":1632580193762,"mc":[{"id":"1.188136695","rc":[{"trd":[[1.31,202]],"batb":[[0,1.3,26.53],[1,1.29,8],[2,1.28,1002.8]],"batl":[[0,1.31,2349.54]],"ltp":1.31,"tv":74876.63,"id":5300737},{"batb":[[0,4.2,235.42],[1,4.1,2],[2,3.85,151.6]],"ltp":4.2,"tv":23948.33,"id":2497008}],"tv":98824.96}]}
{"op":"mcm","clk":"4299263143","pt":1632580194686,"mc":[{"id":"1.188136695","rc":[{"trd":[[1.31,602]],"batb":[[1,1.29,812.11]],"batl":[[0,1.31,2610.81]],"ltp":1.31,"tv":75276.63,"id":5300737},{"batb":[[0,4.2,250.52]],"ltp":4.2,"tv":23948.33,"id":2497008}],"tv":99224.96}]}
{"op":"mcm","clk":"4299263479","pt":1632580195797,"mc":[{"id":"1.188136695","rc":[{"trd":[[1.31,607]],"batb":[[1,1.29,853.89]],"batl":[[0,1.31,2608.31]],"ltp":1.31,"tv":75281.63,"id":5300737},{"batl":[[1,4.5,83.21]],"ltp":4.2,"tv":23948.33,"id":2497008}],"tv":99229.96}]}
{"op":"mcm","clk":"4299263761","pt":1632580196686,"mc":[{"id":"1.188136695","rc":[{"trd":[[1.31,645.7]],"batl":[[0,1.31,2588.96],[2,1.33,1288.18]],"ltp":1.31,"tv":75320.33,"id":5300737},{"trd":[[4.2,25.85]],"batb":[[0,4.2,247.6]],"ltp":4.2,"tv":23954.18,"id":2497008}],"tv":99274.51}]}
{"op":"mcm","clk":"4299264087","pt":1632580197827,"mc":[{"id":"1.188136695","rc":[{"batb":[[1,1.29,952.98],[2,1.28,1089.78]],"batl":[[0,1.31,2951.1],[2,1.33,1282.18]],"ltp":1.31,"tv":75320.33,"id":5300737},{"batl":[[0,4.4,25.54],[1,4.5,71.19]],"ltp":4.2,"tv":23954.18,"id":2497008}]}]}
{"op":"mcm","clk":"4299264359","pt":1632580198778,"mc":[{"id":"1.188136695","rc":[{"trd":[[1.31,655.41]],"batl":[[0,1.31,2946.25],[2,1.33,1265.63]],"ltp":1.31,"tv":75330.03,"id":5300737},{"batl":[[0,4.4,4]],"ltp":4.2,"tv":23954.18,"id":2497008}],"tv":99284.22}]}
{"op":"mcm","clk":"4299264535","pt":1632580199396,"mc":[{"id":"1.188136695","rc":[{"trd":[[1.3,3.42],[1.31,655.99]],"batb":[[0,1.3,24.82]],"batl":[[0,1.31,2945.96]],"ltp":1.31,"tv":75334.03,"id":5300737}],"tv":99288.22}]}
{"op":"mcm","clk":"4299264857","pt":1632580200497,"mc":[{"id":"1.188136695","rc":[{"trd":[[1.31,684.24]],"batl":[[0,1.31,2931.83]],"ltp":1.31,"tv":75362.29,"id":5300737},{"batl":[[0,4.4,16.2]],"ltp":4.2,"tv":23954.18,"id":2497008}],"tv":99316.47}]}
{"op":"mcm","clk":"4299265227","pt":1632580201598,"mc":[{"id":"1.188136695","rc":[{"trd":[[1.31,684.94]],"batl":[[0,1.31,2931.48]],"ltp":1.31,"tv":75362.99,"id":5300737}],"tv":99317.17}]}
{"op":"mcm","clk":"4299265633","pt":1632580202711,"mc":[{"id":"1.188136695","rc":[{"trd":[[1.31,713.52]],"batb":[[0,1.3,250.24]],"batl":[[0,1.31,2917.19]],"ltp":1.31,"tv":75391.56,"id":5300737}],"tv":99345.75}]}
{"op":"mcm","clk":"4299265993","pt":1632580203680,"mc":[{"id":"1.188136695","rc":[{"trd":[[1.31,744.44]],"batb":[[1,1.29,148.87]],"batl":[[0,1.31,2983.47]],"ltp":1.31,"tv":75422.49,"id":5300737}],"tv":99376.67}]}
{"op":"mcm","clk":"4299266181","pt":1632580204289,"mc":[{"id":"1.188136695","rc":[{"trd":[[1.3,17.42]],"batb":[[0,1.3,243.24]],"ltp":1.3,"tv":75436.49,"id":5300737}],"tv":99390.67}]}
{"op":"mcm","clk":"4299266650","pt":1632580205723,"mc":[{"id":"1.188136695","rc":[{"trd":[[1.3,180.79],[1.31,749.36]],"batb":[[0,1.3,161.56]],"batl":[[0,1.31,2981.01]],"ltp":1.31,"tv":75604.77,"id":5300737},{"trd":[[4.2,61.31]],"batb":[[0,4.2,229.87]],"batl":[[0,4.4,47.24]],"ltp":4.2,"tv":23989.64,"id":2497008}],"tv":99594.42}]}
{"op":"mcm","clk":"4299267042","pt":1632580206810,"mc":[{"id":"1.188136695","rc":[{"trd":[[1.31,760.9]],"batb":[[0,1.3,959.48]],"batl":[[0,1.31,2987.22]],"ltp":1.31,"tv":75616.31,"id":5300737},{"batb":[[1,3.85,151.6],[2,3.8,80.83]],"batl":[[0,4.3,2],[1,4.4,16.2],[2,4.5,71.19]],"ltp":4.2,"tv":23989.64,"id":2497008}],"tv":99605.96}]}
{"op":"mcm","clk":"4299267173","pt":1632580207306,"mc":[{"id":"1.188136695","rc":[{"trd":[[1.3,184.8],[1.31,761.6]],"batb":[[0,1.3,957.48]],"batl":[[0,1.31,2986.87]],"ltp":1.31,"tv":75621.03,"id":5300737}],"tv":99610.67}]}
{"op":"mcm","clk":"4299267609","pt":1632580208695,"mc":[{"id":"1.188136695","rc":[{"trd":[[1.3,655.17],[1.31,770.8]],"batb":[[0,1.3,781.39]],"batl":[[0,1.31,2982.27]],"ltp":1.3,"tv":76100.59,"id":5300737}],"tv":100090.24}]}
{"op":"mcm","clk":"4299267904","pt":1632580209622,"mc":[{"id":"1.188136695","rc":[{"trd":[[1.31,777.82]],"batl":[[0,1.31,2978.76]],"ltp":1.31,"tv":76107.61,"id":5300737},{"trd":[[4.2,62.09]],"batb":[[0,4.2,229.48],[1,4.1,2],[2,3.9,31.03]],"batl":[[0,4.3,4]],"ltp":4.2,"tv":23990.42,"id":2497008}],"tv":100098.04}]}
{"op":"mcm","clk":"4299268214","pt":1632580210729,"mc":[{"id":"1.188136695","rc":[{"trd":[[1.3,662.19],[1.31,808.52]],"batb":[[0,1.3,777.88],[2,1.28,1192.6]],"batl":[[0,1.31,2963.41]],"ltp":1.3,"tv":76145.34,"id":5300737}],"tv":100135.77}]}
{"op":"mcm","clk":"4299268524","pt":1632580211770,"mc":[{"id":"1.188136695","rc":[{"trd":[[1.31,834.24]],"batl":[[0,1.31,2938.57]],"ltp":1.31,"tv":76171.06,"id":5300737}],"tv":100161.48}]}
{"op":"mcm","clk":"4299268856","pt":1632580212734,"mc":[{"id":"1.188136695","rc":[{"trd":[[1.3,3210.79],[1.31,834.3]],"batb":[[0,1.29,800.28],[1,1.28,1192.6],[2,1.27,2761.46]],"batl":[[0,1.3,973.5],[1,1.31,2938.54],[2,1.32,2289.11]],"ltp":1.3,"tv":78719.71,"id":5300737},{"trd":[[4.3,4]],"batl":[[0,4.4,157.25],[1,4.5,257.92],[2,4.6,68.41]],"ltp":4.3,"tv":23994.42,"id":2497008}],"tv":102714.14}]}
{"op":"mcm","clk":"4299269118","pt":1632580213656,"mc":[{"id":"1.188136695","rc":[{"trd":[[1.3,3260.79]],"batl":[[0,1.3,948.5],[2,1.32,2726.24]],"ltp":1.3,"tv":78769.71,"id":5300737},{"batb":[[1,4.1,142.73],[2,4,180.96]],"ltp":4.3,"tv":23994.42,"id":2497008}],"tv":102764.14}]}
{"op":"mcm","clk":"4299269314","pt":1632580214601,"mc":[{"id":"1.188136695","rc":[{"batl":[[0,1.3,960.48]],"ltp":1.3,"tv":78769.71,"id":5300737}]}]}
{"op":"mcm","clk":"4299269699","pt":1632580215549,"mc":[{"id":"1.188136695","rc":[{"trd":[[1.3,3806.85]],"batl":[[0,1.3,687.45]],"ltp":1.3,"tv":79315.77,"id":5300737}],"tv":103310.2}]}
{"op":"mcm","clk":"4299270101","pt":1632580216658,"mc":[{"id":"1.188136695","rc":[{"trd":[[1.3,3810.28]],"batb":[[1,1.28,1200.6]],"batl":[[0,1.3,685.74]],"ltp":1.3,"tv":79319.2,"id":5300737}],"tv":103313.62}]}
{"op":"mcm","clk":"4299270339","pt":1632580217384,"mc":[{"id":"1.188136695","rc":[{"trd":[[1.3,3814.35]],"batl":[[0,1.3,781.67]],"ltp":1.3,"tv":79323.27,"id":5300737},{"trd":[[4.3,5.23]],"batl":[[0,4.4,16.2]],"ltp":4.3,"tv":23995.65,"id":2497008}],"tv":103318.92}]}
{"op":"mcm","clk":"4299270805","pt":1632580218680,"mc":[{"id":"1.188136695","rc":[{"trd":[[1.3,3824.35]],"batl":[[0,1.3,1338.68],[1,1.31,3373.1],[2,1.32,3257.65]],"ltp":1.3,"tv":79333.27,"id":5300737},{"batb":[[0,4.2,365.01],[1,4.1,313.81]],"ltp":4.3,"tv":23995.65,"id":2497008}],"tv":103328.92}]}
{"op":"mcm","clk":"4299271174","pt":1632580219668,"mc":[{"id":"1.188136695","rc":[{"batl":[[0,1.3,1335.17]],"ltp":1.3,"tv":79333.27,"id":5300737}]}]}
{"op":"mcm","clk":"4299271857","pt":1632580221655,"mc":[{"id":"1.188136695","rc":[{"trd":[[1.29,866.6],[1.3,5405.87]],"batb":[[0,1.29,366.98]],"batl":[[0,1.3,544.41]],"ltp":1.29,"tv":81781.39,"id":5300737},{"batl":[[0,4.4,4]],"ltp":4.3,"tv":23995.65,"id":2497008}],"tv":105777.05}]}
{"op":"mcm","clk":"4299272189","pt":1632580222548,"mc":[{"id":"1.188136695","rc":[{"trd":[[1.3,5606.15]],"batl":[[0,1.3,444.27],[1,1.31,3364.1]],"ltp":1.3,"tv":81981.67,"id":5300737},{"batb":[[0,4.2,363.01],[1,4.1,311.81]],"ltp":4.3,"tv":23995.65,"id":2497008}],"tv":105977.33}]}
{"op":"mcm","clk":"4299272513","pt":1632580223663,"mc":[{"id":"1.188136695","rc":[{"trd":[[1.3,5609.58]],"batb":[[1,1.28,2178.35],[2,1.27,1779.82]],"batl":[[0,1.3,442.56]],"ltp":1.3,"tv":81985.1,"id":5300737}],"tv":105980.75}]}
{"op":"mcm","clk":"4299272827","pt":1632580224656,"mc":[{"id":"1.188136695","rc":[{"batb":[[0,1.29,375.98],[2,1.27,1953.02]],"ltp":1.3,"tv":81985.1,"id":5300737}]}]}
{"op":"mcm","clk":"4299273106","pt":1632580225568,"mc":[{"id":"1.188136695","rc":[{"trd":[[1.3,5634.6]],"batl":[[0,1.3,941.01]],"ltp":1.3,"tv":82010.12,"id":5300737},{"trd":[[4.3,7.23]],"batl":[[2,4.6,80.26]],"ltp":4.3,"tv":23997.65,"id":2497008}],"tv":106007.78}]}
{"op":"mcm","clk":"4299273358","pt":1632580226393,"mc":[{"id":"1.188136695","rc":[{"trd":[[1.3,5638.6]],"batl":[[0,1.3,939.01]],"ltp":1.3,"tv":82014.12,"id":5300737}],"tv":106011.78}]}
{"op":"mcm","clk":"4299273783","pt":1632580227693,"mc":[{"id":"1.188136695","rc":[{"trd":[[1.3,5654.38]],"batl":[[0,1.3,923.23]],"ltp":1.3,"tv":82029.9,"id":5300737},{"trd":[[4.3,12]],"ltp":4.3,"tv":24002.42,"id":2497008}],"tv":106032.33}]}
{"op":"mcm","clk":"4299274082","pt":1632580228687,"mc":[{"id":"1.188136695","rc":[{"trd":[[1.3,5667.38]],"batl":[[0,1.3,916.73]],"ltp":1.3,"tv":82042.9,"id":5300737}],"tv":106045.33}]}
{"op":"mcm","clk":"4299274356","pt":1632580229558,"mc":[{"id":"1.188136695","rc":[{"trd":[[1.29,1632.2],[1.3,5670.76]],"batb":[[0,1.28,2178.35],[1,1.27,1953.02],[2,1.26,2631.66]],"batl":[[0,1.29,110.38],[1,1.3,935.04],[2,1.31,3364.1]],"ltp":1.29,"tv":82811.89,"id":5300737},{"trd":[[4.4,4]],"batl":[[0,4.5,257.92],[1,4.6,80.26],[2,4.7,165.36]],"ltp":4.4,"tv":24006.42,"id":2497008}],"tv":106818.31}]}
{"op":"mcm","clk":"4299274680","pt":1632580230649,"mc":[{"id":"1.188136695","rc":[{"trd":[[1.29,1638.2]],"batl":[[0,1.29,107.38]],"ltp":1.29,"tv":82817.89,"id":5300737},{"batl":[[0,4.5,186.73]],"ltp":4.4,"tv":24006.42,"id":2497008}],"tv":106824.31}]}
{"op":"mcm","clk":"4299274958","pt":1632580231585,"mc":[{"id":"1.188136695","rc":[{"trd":[[1.29,1852.96],[1.3,5943.06]],"batl":[[0,1.3,798.89],[1,1.31,3364.1],[2,1.32,3257.65]],"ltp":1.3,"tv":83304.95,"id":5300737}],"tv":107311.37}]}
{"op":"mcm","clk":"4299275294","pt":1632580232676,"mc":[{"id":"1.188136695","rc":[{"trd":[[1.3,5957.1]],"batl":[[0,1.3,791.87]],"ltp":1.3,"tv":83318.99,"id":5300737},{"batl":[[0,4.4,3],[1,4.5,186.73],[2,4.6,80.26]],"ltp":4.4,"tv":24006.42,"id":2497008}],"tv":107325.41}]}
{"op":"mcm","clk":"4299275505","pt":1632580233385,"mc":[{"id":"1.188136695","rc":[{"batl":[[0,1.3,891.87]],"ltp":1.3,"tv":83318.99,"id":5300737}]}]}
{"op":"mcm","clk":"4299275901","pt":1632580234676,"mc":[{"id":"1.188136695","rc":[{"trd":[[1.29,1863.2],[1.3,5958.28]],"batb":[[0,1.28,2347.21]],"batl":[[0,1.29,374.43],[1,1.3,891.28],[2,1.31,3364.1]],"ltp":1.29,"tv":83330.4,"id":5300737},{"trd":[[4.4,7]],"batl":[[0,4.5,186.73],[1,4.6,80.26],[2,4.7,165.36]],"ltp":4.4,"tv":24009.42,"id":2497008}],"tv":107339.83}]}
{"op":"mcm","clk":"4299276213","pt":1632580235688,"mc":[{"id":"1.188136695","rc":[{"trd":[[1.29,1863.54]],"batl":[[0,1.29,374.09],[1,1.3,1438.12],[2,1.31,4032.65]],"ltp":1.29,"tv":83330.75,"id":5300737},{"trd":[[4.4,7.1]],"batb":[[0,4.3,165.32],[1,4.2,571.53],[2,4.1,311.81]],"ltp":4.4,"tv":24009.52,"id":2497008}],"tv":107340.27}]}
{"op":"mcm","clk":"4299276563","pt":1632580236794,"mc":[{"id":"1.188136695","rc":[{"trd":[[1.29,2008.7]],"batl":[[0,1.29,301.33]],"ltp":1.29,"tv":83475.91,"id":5300737},{"trd":[[4.4,7.21]],"batl":[[0,4.6,80.26],[1,4.7,165.36],[2,4.8,430.96]],"ltp":4.4,"tv":24009.63,"id":2497008}],"tv":107485.54}]}
{"op":"mcm","clk":"4299276836","pt":1632580237678,"mc":[{"id":"1.188136695","rc":[{"trd":[[1.28,29.56]],"batb":[[0,1.28,2332.43],[1,1.27,1779.82]],"ltp":1.28,"tv":83505.47,"id":5300737},{"batl":[[0,4.6,68.41]],"ltp":4.4,"tv":24009.63,"id":2497008}],"tv":107515.1}]}
{"op":"mcm","clk":"4299277137","pt":1632580238771,"mc":[{"id":"1.188136695","rc":[{"trd":[[1.29,2124.65]],"batb":[[0,1.28,2328.54],[2,1.26,2628.2]],"batl":[[0,1.29,243.35],[1,1.3,1444.62]],"ltp":1.29,"tv":83621.42,"id":5300737}],"tv":107631.05}]}
{"op":"mcm","clk":"4299277382","pt":1632580239581,"mc":[{"id":"1.188136695","rc":[{"trd":[[1.29,2140.91]],"batl":[[0,1.29,235.22]],"ltp":1.29,"tv":83637.67,"id":5300737}],"tv":107647.31}]}
{"op":"mcm","clk":"4299277739","pt":1632580240769,"mc":[{"id":"1.188136695","rc":[{"batb":[[2,1.26,2804.7]],"ltp":1.29,"tv":83637.67,"id":5300737},{"batb":[[2,4.1,340.84]],"batl":[[0,4.6,80.27],[2,4.8,442.5]],"ltp":4.4,"tv":24009.63,"id":2497008}]}]}
{"op":"mcm","clk":"4299277830","pt":1632580241088,"mc":[{"id":"1.188136695","rc":[{"batb":[[1,4.2,363.01]],"ltp":4.4,"tv":24009.63,"id":2497008}]}]}
{"op":"mcm","clk":"4299278369","pt":1632580242790,"mc":[{"id":"1.188136695","rc":[{"trd":[[1.29,2141.83]],"batb":[[2,1.26,13510.11]],"batl":[[0,1.29,234.76],[1,1.3,1630.28],[2,1.31,4243.66]],"ltp":1.29,"tv":83638.6,"id":5300737},{"batb":[[0,4.4,54.86],[1,4.3,229.6],[2,4.2,363.01]],"ltp":4.4,"tv":24009.63,"id":2497008}],"tv":107648.23}]}
{"op":"mcm","clk":"4299278522","pt":1632580243296,"mc":[{"id":"1.188136695","rc":[{"batl":[[1,1.3,1116.01]],"ltp":1.29,"tv":83638.6,"id":5300737}]}]}
{"op":"mcm","clk":"4299278923","pt":1632580244685,"mc":[{"id":"1.188136695","rc":[{"batb":[[1,4.3,146.52]],"ltp":4.4,"tv":24009.63,"id":2497008}]}]}
{"op":"mcm","clk":"4299279331","pt":1632580246103,"mc":[{"id":"1.188136695","rc":[{"trd":[[1.29,2611.35]],"batb":[[0,1.29,633.19],[1,1.28,2324.57],[2,1.27,1779.82]],"batl":[[0,1.3,1116.01],[1,1.31,4243.66],[2,1.32,3257.65]],"ltp":1.29,"tv":84108.12,"id":5300737}],"tv":108117.75}]}
{"op":"mcm","clk":"4299279828","pt":1632580247691,"mc":[{"id":"1.188136695","rc":[{"trd":[[1.29,3212.54]],"batb":[[0,1.29,332.6]],"batl":[[2,1.32,3347.65]],"ltp":1.29,"tv":84709.3,"id":5300737},{"trd":[[4.4,13.21]],"batb":[[0,4.4,51.86]],"ltp":4.4,"tv":24015.63,"id":2497008}],"tv":108724.93}]}
{"op":"mcm","clk":"4299280114","pt":1632580248613,"mc":[{"id":"1.188136695","rc":[{"trd":[[1.29,3258.54]],"batb":[[0,1.29,309.6]],"batl":[[1,1.31,4032.65]],"ltp":1.29,"tv":84755.3,"id":5300737}],"tv":108770.93}]}
{"op":"mcm","clk":"4299280347","pt":1632580249408,"mc":[{"id":"1.188136695","rc":[{"trd":[[1.29,3269.06],[1.3,5972.28]],"batb":[[0,1.29,517.04]],"batl":[[0,1.3,1109.01]],"ltp":1.3,"tv":84779.82,"id":5300737}],"tv":108795.45}]}
{"op":"mcm","clk":"4299280745","pt":1632580250806,"mc":[{"id":"1.188136695","rc":[{"batb":[[0,1.29,519.05]],"ltp":1.3,"tv":84779.82,"id":5300737}]}]}
{"op":"mcm","clk":"4299280936","pt":1632580251371,"mc":[{"id":"1.188136695","rc":[{"trd":[[1.29,3424.08]],"batb":[[0,1.29,441.54]],"ltp":1.29,"tv":84934.84,"id":5300737}],"tv":108950.47}]}
{"op":"mcm","clk":"4299281245","pt":1632580252593,"mc":[{"id":"1.188136695","rc":[{"batb":[[0,1.29,458.8]],"ltp":1.29,"tv":84934.84,"id":5300737}]}]}
{"op":"mcm","clk":"4299281619","pt":1632580253804,"mc":[{"id":"1.188136695","rc":[{"trd":[[1.3,6006.48]],"batb":[[0,1.29,466.8]],"batl":[[0,1.3,1091.91]],"ltp":1.3,"tv":84969.04,"id":5300737}],"tv":108984.67}]}
{"op":"mcm","clk":"4299282213","pt":1632580255797,"mc":[{"id":"1.188136695","rc":[{"trd":[[1.3,6007.18]],"batl":[[0,1.3,1091.56]],"ltp":1.3,"tv":84969.74,"id":5300737}],"tv":108985.37}]}
{"op":"mcm","clk":"4299282500","pt":1632580256791,"mc":[{"id":"1.188136695","rc":[{"batb":[[0,1.29,456.79],[1,1.28,2316.57]],"ltp":1.3,"tv":84969.74,"id":5300737}]}]}
{"op":"mcm","clk":"4299284310","pt":1632580263198,"mc":[{"id":"1.188136695","rc":[{"trd":[[1.3,6010.7]],"batl":[[0,1.3,1089.8]],"ltp":1.3,"tv":84973.26,"id":5300737}],"tv":108988.89}]}
{"op":"mcm","clk":"4299284736","pt":1632580264723,"mc":[{"id":"1.188136695","rc":[{"trd":[[4.4,28.84]],"batb":[[0,4.4,44.04]],"ltp":4.4,"tv":24031.26,"id":2497008}],"tv":109004.53}]}
{"op":"mcm","clk":"4299285757","pt":1632580268291,"mc":[{"id":"1.188136695","rc":[{"batb":[[1,1.28,2404.73]],"ltp":1.3,"tv":84973.26,"id":5300737}]}]}
{"op":"mcm","clk":"4299286513","pt":1632580270727,"mc":[{"id":"1.188136695","rc":[{"trd":[[1.3,6011.68]],"batl":[[0,1.3,1089.31]],"ltp":1.3,"tv":84974.24,"id":5300737},{"trd":[[4.4,34.69]],"batb":[[0,4.4,41.12]],"ltp":4.4,"tv":24037.11,"id":2497008}],"tv":109011.35}]}
{"op":"mcm","clk":"4299286626","pt":1632580271118,"mc":[{"id":"1.188136695","rc":[{"trd":[[1.29,3524.08]],"batb":[[0,1.29,406.79]],"ltp":1.29,"tv":85074.24,"id":5300737}],"tv":109111.35}]}
{"op":"mcm","clk":"4299286992","pt":1632580272215,"mc":[{"id":"1.188136695","rc":[{"batb":[[0,1.29,481.82]],"batl":[[0,1.3,1161.11]],"ltp":1.29,"tv":85074.24,"id":5300737}]}]}
{"op":"mcm","clk":"4299287506","pt":1632580273808,"mc":[{"id":"1.188136695","rc":[{"batb":[[0,1.29,493.35]],"ltp":1.29,"tv":85074.24,"id":5300737},{"trd":[[4.4,35.39]],"batb":[[0,4.4,40.76]],"ltp":4.4,"tv":24037.81,"id":2497008}],"tv":109112.05}]}
{"op":"mcm","clk":"4299288080","pt":1632580275707,"mc":[{"id":"1.188136695","rc":[{"trd":[[1.29,3528.01]],"batb":[[0,1.29,491.38]],"ltp":1.29,"tv":85078.17,"id":5300737}],"tv":109115.99}]}
{"op":"mcm","clk":"4299288774","pt":1632580277741,"mc":[{"id":"1.188136695","rc":[{"trd":[[1.29,4033.71],[1.3,6014.28]],"batb":[[0,1.29,238.53]],"batl":[[0,1.3,1159.81]],"ltp":1.29,"tv":85586.48,"id":5300737}],"tv":109624.29}]}
{"op":"mcm","clk":"4299288831","pt":1632580277934,"mc":[{"id":"1.188136695","rc":[{"trd":[[1.29,4034.12]],"batb":[[0,1.29,238.33]],"ltp":1.29,"tv":85586.88,"id":5300737}],"tv":109624.7}]}
{"op":"mcm","clk":"4299289405","pt":1632580279612,"mc":[{"id":"1.188136695","rc":[{"trd":[[1.29,4376.96]],"batb":[[0,1.29,66.9]],"ltp":1.29,"tv":85929.73,"id":5300737}],"tv":109967.54}]}
{"op":"mcm","clk":"4299289477","pt":1632580279844,"mc":[{"id":"1.188136695","rc":[{"batb":[[2,1.27,1825.69]],"ltp":1.29,"tv":85929.73,"id":5300737},{"batl":[[2,4.8,444.5]],"ltp":4.4,"tv":24037.81,"id":2497008}]}]}
{"op":"mcm","clk":"4299290010","pt":1632580281521,"mc":[{"id":"1.188136695","rc":[{"trd":[[4.4,36.28]],"batb":[[0,4.4,40.32]],"ltp":4.4,"tv":24038.71,"id":2497008}],"tv":109968.44}]}
{"op":"mcm","clk":"4299290680","pt":1632580283431,"mc":[{"id":"1.188136695","rc":[{"trd":[[1.3,6022.5]],"batl":[[0,1.3,1155.7]],"ltp":1.3,"tv":85937.94,"id":5300737},{"trd":[[4.4,37.07]],"batb":[[0,4.4,39.92]],"ltp":4.4,"tv":24039.49,"id":2497008}],"tv":109977.44}]}
{"op":"mcm","clk":"4299291084","pt":1632580284627,"mc":[{"id":"1.188136695","rc":[{"trd":[[1.3,6022.66]],"batl":[[0,1.3,1155.62]],"ltp":1.3,"tv":85938.11,"id":5300737}],"tv":109977.61}]}
{"op":"mcm","clk":"4299291191","pt":1632580284922,"mc":[{"id":"1.188136695","rc":[{"trd":[[1.3,6029.68]],"batl":[[0,1.3,1152.11]],"ltp":1.3,"tv":85945.13,"id":5300737}],"tv":109984.63}]}
{"op":"mcm","clk":"4299291671","pt":1632580286367,"mc":[{"id":"1.188136695","rc":[{"trd":[[1.3,6029.76]],"batb":[[1,1.28,2425.15]],"batl":[[0,1.3,1152.07]],"ltp":1.3,"tv":85945.21,"id":5300737}],"tv":109984.71}]}
{"op":"mcm","clk":"4299292103","pt":1632580287731,"mc":[{"id":"1.188136695","rc":[{"trd":[[1.3,6030.1]],"batl":[[0,1.3,1151.9],[1,1.31,3982.65]],"ltp":1.3,"tv":85945.55,"id":5300737},{"batb":[[2,4.2,347.91]],"batl":[[0,4.6,68.41]],"ltp":4.4,"tv":24039.49,"id":2497008}],"tv":109985.05}]}
{"op":"mcm","clk":"4299292256","pt":1632580288341,"mc":[{"id":"1.188136695","rc":[{"batl":[[1,1.31,3030.39]],"ltp":1.3,"tv":85945.55,"id":5300737}]}]}
{"op":"mcm","clk":"4299292409","pt":1632580288842,"mc":[{"id":"1.188136695","rc":[{"trd":[[1.3,6037.12]],"batl":[[0,1.3,1148.39]],"ltp":1.3,"tv":85952.57,"id":5300737}],"tv":109992.07}]}
{"op":"mcm","clk":"4299292938","pt":1632580290730,"mc":[{"id":"1.188136695","rc":[{"batl":[[0,1.3,1128.39]],"ltp":1.3,"tv":85952.57,"id":5300737},{"trd":[[4.4,37.77]],"batb":[[0,4.4,39.57]],"ltp":4.4,"tv":24040.19,"id":2497008}],"tv":109992.77}]}
{"op":"mcm","clk":"4299293085","pt":1632580291220,"mc":[{"id":"1.188136695","rc":[{"batb":[[0,4.3,146.52],[1,4.2,347.91],[2,4.1,340.84]],"ltp":4.4,"tv":24040.19,"id":2497008}]}]}
{"op":"mcm","clk":"4299294087","pt":1632580294715,"mc":[{"id":"1.188136695","rc":[{"trd":[[1.29,4416.96]],"batb":[[0,1.29,46.91]],"ltp":1.29,"tv":85992.57,"id":5300737}],"tv":110032.76}]}
{"op":"mcm","clk":"4299294307","pt":1632580295520,"mc":[{"id":"1.188136695","rc":[{"trd":[[1.3,6044.18]],"batl":[[0,1.3,1124.86]],"ltp":1.3,"tv":85999.62,"id":5300737},{"batl":[[0,4.5,150],[1,4.6,81.01],[2,4.7,165.36]],"ltp":4.4,"tv":24040.19,"id":2497008}],"tv":110039.82}]}
{"op":"mcm","clk":"4299294652","pt":1632580296745,"mc":[{"id":"1.188136695","rc":[{"trd":[[1.29,4417.15]],"batb":[[0,1.29,46.81]],"ltp":1.29,"tv":85999.81,"id":5300737},{"batb":[[0,4.3,296.52]],"ltp":4.4,"tv":24040.19,"id":2497008}],"tv":110040.01}]}
{"op":"mcm","clk":"4299294778","pt":1632580297141,"mc":[{"id":"1.188136695","rc":[{"batb":[[0,4.3,446.52]],"ltp":4.4,"tv":24040.19,"id":2497008}]}]}
{"op":"mcm","clk":"4299295153","pt":1632580298391,"mc":[{"id":"1.188136695","rc":[{"trd":[[1.3,6044.58]],"batl":[[0,1.3,1124.66]],"ltp":1.3,"tv":86000.21,"id":5300737}],"tv":110040.41}]}
{"op":"mcm","clk":"4299295486","pt":1632580299458,"mc":[{"id":"1.188136695","rc":[{"trd":[[1.3,6045.28]],"batl":[[0,1.3,1124.31]],"ltp":1.3,"tv":86000.91,"id":5300737}],"tv":110041.11}]}
{"op":"mcm","clk":"4299295844","pt":1632580300653,"mc":[{"id":"1.188136695","rc":[{"trd":[[1.29,4501.22]],"batb":[[0,1.29,4.77]],"ltp":1.29,"tv":86084.98,"id":5300737}],"tv":110125.18}]}
{"op":"mcm","clk":"4299296011","pt":1632580301261,"mc":[{"id":"1.188136695","rc":[{"batl":[[0,4.6,81.01],[1,4.7,165.36],[2,4.8,444.5]],"ltp":4.4,"tv":24040.19,"id":2497008}]}]}
{"op":"mcm","clk":"4299296429","pt":1632580302563,"mc":[{"id":"1.188136695","rc":[{"batl":[[1,1.31,2948.65]],"ltp":1.29,"tv":86084.98,"id":5300737}]}]}
{"op":"mcm","clk":"4299297136","pt":1632580304729,"mc":[{"id":"1.188136695","rc":[{"trd":[[1.3,6045.78]],"batl":[[0,1.3,1124.06]],"ltp":1.3,"tv":86085.49,"id":5300737},{"batb":[[0,4.3,146.52]],"ltp":4.4,"tv":24040.19,"id":2497008}],"tv":110125.69}]}
{"op":"mcm","clk":"4299297491","pt":1632580305756,"mc":[{"id":"1.188136695","rc":[{"batb":[[1,1.28,2198.04],[2,1.27,1561.46]],"batl":[[0,1.3,391.56],[1,1.31,1845.54],[2,1.32,1075.13]],"ltp":1.3,"tv":86085.49,"id":5300737},{"batb":[[0,4.2,212.38],[1,4.1,29.03],[2,4,2]],"batl":[[0,4.6,2],[1,4.7,68.79],[2,4.8,85.9]],"ltp":4.4,"tv":24040.19,"id":2497008}]}]}
{"op":"mcm","clk":"4299297799","pt":1632580306547,"mc":[{"id":"1.188136695","rc":[{"batb":[[1,1.28,20.42],[2,1.27,299.13]],"batl":[[0,1.3,178.3],[1,1.31,247],[2,1.32,90]],"ltp":1.3,"tv":86085.49,"id":5300737},{"batb":[[0,4.1,29.03],[1,4,2],[2,3.9,10]],"batl":[[0,4.7,68.79],[1,4.8,85.9],[2,4.9,91.09]],"ltp":4.4,"tv":24040.19,"id":2497008}]}]}
{"op":"mcm","clk":"4299298130","pt":1632580307678,"mc":[{"id":"1.188136695","rc":[{"batl":[[1,1.33,36.5],[2,1.35,39.9]],"ltp":1.3,"tv":86085.49,"id":5300737},{"batb":[[0,4,2],[1,3.9,10],[2,3.85,153.6]],"batl":[[0,4.4,26.55],[1,4.7,68.79],[2,4.8,74.36]],"ltp":4.4,"tv":24040.19,"id":2497008}]}]}
{"op":"mcm","clk":"4299298699","pt":1632580309738,"mc":[{"id":"1.188136695","rc":[{"batl":[[2,1.34,663.77]],"ltp":1.3,"tv":86085.49,"id":5300737},{"batl":[[1,4.7,70.79]],"ltp":4.4,"tv":24040.19,"id":2497008}]}]}
{"op":"mcm","clk":"4299298786","pt":1632580310047,"mc":[{"id":"1.188136695","rc":[{"batb":[[1,1.28,62.58]],"ltp":1.3,"tv":86085.49,"id":5300737},{"batl":[[1,4.6,2],[2,4.7,70.79]],"ltp":4.4,"tv":24040.19,"id":2497008}]}]}
{"op":"mcm","clk":"4299299494","pt":1632580312535,"mc":[{"id":"1.188136695","rc":[{"batb":[[0,1.29,11.78]],"ltp":1.3,"tv":86085.49,"id":5300737}]}]}
{"op":"mcm","clk":"4299299874","pt":1632580313605,"mc":[{"id":"1.188136695","rc":[{"trd":[[1.3,6050.3]],"batl":[[0,1.3,176.04]],"ltp":1.3,"tv":86090.0,"id":5300737},{"batl":[[0,4.4,29.47]],"ltp":4.4,"tv":24040.19,"id":2497008}],"tv":110130.2}]}
{"op":"mcm","clk":"4299300210","pt":1632580314772,"mc":[{"id":"1.188136695","rc":[{"trd":[[1.3,6051.7]],"batl":[[0,1.3,103.54]],"ltp":1.3,"tv":86091.4,"id":5300737}],"tv":110131.6}]}
{"op":"mcm","clk":"4299300301","pt":1632580315065,"mc":[{"id":"1.188136695","rc":[{"trd":[[1.3,6056.78]],"batl":[[0,1.3,101],[2,1.35,39.9]],"ltp":1.3,"tv":86096.48,"id":5300737}],"tv":110136.68}]}
{"op":"mcm","clk":"4299301053","pt":1632580317673,"mc":[{"id":"1.188136695","rc":[{"trd":[[1.29,4598.72]],"batb":[[0,1.28,20.42],[1,1.27,299.13],[2,1.26,2259.04]],"batl":[[0,1.3,138.35]],"ltp":1.29,"tv":86193.98,"id":5300737},{"trd":[[4.4,59.44]],"batb":[[0,4.3,42.28],[1,4,2],[2,3.9,10]],"batl":[[0,4.4,7.8],[1,4.5,36.07]],"ltp":4.4,"tv":24061.87,"id":2497008}],"tv":110255.85}]}
{"op":"mcm","clk":"4299301194","pt":1632580318173,"mc":[{"id":"1.188136695","rc":[{"trd":[[1.3,6084.19]],"batb":[[0,1.29,602.02],[1,1.28,1219.09],[2,1.27,299.13]],"batl":[[0,1.3,87.29],[1,1.32,1472.91],[2,1.33,980.07]],"ltp":1.3,"tv":86221.39,"id":5300737},{"batb":[[0,4,2],[1,3.9,10],[2,3.85,153.6]],"batl":[[1,4.7,70.79],[2,4.8,74.36]],"ltp":4.4,"tv":24061.87,"id":2497008}],"tv":110283.26}]}
{"op":"mcm","clk":"4299301515","pt":1632580319375,"mc":[{"id":"1.188136695","rc":[{"batl":[[1,1.32,1482.18]],"ltp":1.3,"tv":86221.39,"id":5300737},{"batb":[[0,4.1,10],[1,4,2],[2,3.9,10]],"ltp":4.4,"tv":24061.87,"id":2497008}]}]}
{"op":"mcm","clk":"4299301853","pt":1632580320586,"mc":[{"id":"1.188136695","rc":[{"trd":[[1.3,6171.48]],"batb":[[1,1.28,1275.19]],"batl":[[0,1.32,1482.18],[1,1.33,980.07],[2,1.35,39.9]],"ltp":1.3,"tv":86308.68,"id":5300737},{"trd":[[4.3,38.39]],"batl":[[0,4.3,73.61],[1,4.4,7.8],[2,4.7,70.79]],"ltp":4.3,"tv":24088.26,"id":2497008}],"tv":110396.94}]}
{"op":"mcm","clk":"4299301977","pt":1632580321046,"mc":[{"id":"1.188136695","rc":[{"trd":[[1.29,4609.04],[1.3,6414.96]],"batb":[[0,1.29,596.86],[1,1.28,1317.85]],"ltp":1.29,"tv":86562.48,"id":5300737},{"trd":[[4.3,112]],"batl":[[0,4.4,7.8],[1,4.6,2]],"ltp":4.3,"tv":24161.87,"id":2497008}],"tv":110724.35}]}
{"op":"mcm","clk":"4299302451","pt":1632580322666,"mc":[{"id":"1.188136695","rc":[{"batb":[[0,1.3,641.1],[1,1.29,596.86],[2,1.28,1261.75]],"ltp":1.29,"tv":86562.48,"id":5300737},{"batb":[[0,4,2],[1,3.9,10],[2,3.85,153.6]],"ltp":4.3,"tv":24161.87,"id":2497008}]}]}
{"op":"mcm","clk":"4299302706","pt":1632580323452,"mc":[{"id":"1.188136695","rc":[{"trd":[[1.3,6417.72]],"batb":[[0,1.3,639.92],[1,1.28,63.08],[2,1.27,299.13]],"batl":[[0,1.32,9.27],[1,1.35,39.9],[2,1.36,231.16]],"ltp":1.3,"tv":86565.24,"id":5300737},{"batb":[[0,3.9,10],[1,3.85,153.6],[2,3.8,80.83]],"ltp":4.3,"tv":24161.87,"id":2497008}],"tv":110727.11}]}
{"op":"mcm","clk":"4299303130","pt":1632580324776,"mc":[{"id":"1.188136695","rc":[{"batl":[[0,1.31,249],[1,1.32,9.27],[2,1.35,39.9]],"ltp":1.3,"tv":86565.24,"id":5300737}]}]}
{"op":"mcm","clk":"4299303309","pt":1632580325364,"mc":[{"id":"1.188136695","rc":[{"batb":[[0,1.3,641.65]],"batl":[[0,1.32,9.27],[1,1.35,39.9],[2,1.36,231.16]],"ltp":1.3,"tv":86565.24,"id":5300737},{"batb":[[0,4,2],[1,3.95,3],[2,3.9,10]],"ltp":4.3,"tv":24161.87,"id":2497008}]}]}
{"op":"mcm","clk":"4299303677","pt":1632580326474,"mc":[{"id":"1.188136695","rc":[{"batl":[[1,1.33,39.5],[2,1.35,39.9]],"ltp":1.3,"tv":86565.24,"id":5300737},{"batb":[[0,4,4]],"ltp":4.3,"tv":24161.87,"id":2497008}]}]}
{"op":"mcm","clk":"4299303976","pt":1632580327460,"mc":[{"id":"1.188136695","rc":[{"batl":[[1,1.34,665.86],[2,1.35,927.95]],"ltp":1.3,"tv":86565.24,"id":5300737},{"batb":[[0,4,2]],"ltp":4.3,"tv":24161.87,"id":2497008}]}]}
{"op":"mcm","clk":"4299304372","pt":1632580328783,"mc":[{"id":"1.188136695","rc":[{"batb":[[0,1.3,5055.11],[1,1.29,4283.65],[2,1.28,4346.73]],"batl":[[0,1.34,665.86],[1,1.35,927.95],[2,1.36,231.16]],"ltp":1.3,"tv":86565.24,"id":5300737},{"batl":[[2,4.7,2]],"ltp":4.3,"tv":24161.87,"id":2497008}]}]}
{"op":"mcm","clk":"4299304412","pt":1632580328898,"mc":[{"id":"1.188136695","rc":[{"batb":[[0,1.3,862.32],[1,1.29,214.18],[2,1.28,277.26]],"ltp":1.3,"tv":86565.24,"id":5300737}]}]}
{"op":"mcm","clk":"4299305304","pt":1632580331784,"mc":[{"id":"1.188136695","rc":[{"batb":[[0,1.3,1965.68],[1,1.29,1285.09],[2,1.28,1348.17]],"ltp":1.3,"tv":86565.24,"id":5300737},{"trd":[[3.9,11.34],[3.95,7],[4,4.86]],"batb":[[0,3.9,4.33],[1,3.85,153.6],[2,3.8,1666.19]],"ltp":3.9,"tv":24183.21,"id":2497008}],"tv":110748.45}]}
{"op":"mcm","clk":"4299305612","pt":1632580332799,"mc":[{"id":"1.188136695","rc":[{"trd":[[1.3,6445.13]],"batb":[[0,1.32,828.6],[1,1.31,1277.77],[2,1.3,3062.52]],"batl":[[1,1.35,1017.95]],"ltp":1.3,"tv":86592.66,"id":5300737},{"batb":[[1,3.85,185.17],[2,3.8,533.79]],"batl":[[0,4.3,18.85],[1,4.4,7.8],[2,4.5,14.02]],"ltp":3.9,"tv":24183.21,"id":2497008}],"tv":110775.87}]}
{"op":"mcm","clk":"4299305861","pt":1632580333626,"mc":[{"id":"1.188136695","rc":[{"batb":[[1,1.31,2230.03]],"ltp":1.3,"tv":86592.66,"id":5300737}]}]}
{"op":"mcm","clk":"4299306260","pt":1632580334781,"mc":[{"id":"1.188136695","rc":[{"trd":[[1.32,46.06]],"batb":[[0,1.32,806]],"ltp":1.32,"tv":86638.72,"id":5300737}],"tv":110821.93}]}
{"op":"mcm","clk":"4299306575","pt":1632580335776,"mc":[{"id":"1.188136695","rc":[{"batb":[[0,1.32,862.66],[1,1.31,2349.84]],"batl":[[0,1.33,72.78],[1,1.34,1178.84],[2,1.35,1088.91]],"ltp":1.32,"tv":86638.72,"id":5300737}]}]}
{"op":"mcm","clk":"4299306772","pt":1632580336412,"mc":[{"id":"1.188136695","rc":[{"batl":[[1,4.4,2.93]],"ltp":3.9,"tv":24183.21,"id":2497008}]}]}
{"op":"mcm","clk":"4299307121","pt":1632580337400,"mc":[{"id":"1.188136695","rc":[{"batl":[[1,1.34,1826.21]],"ltp":1.32,"tv":86638.72,"id":5300737},{"batl":[[0,4.5,14.02],[1,4.6,2],[2,4.7,2]],"ltp":3.9,"tv":24183.21,"id":2497008}]}]}
{"op":"mcm","clk":"4299307593","pt":1632580338794,"mc":[{"id":"1.188136695","rc":[{"trd":[[1.32,1333.35]],"batb":[[0,1.32,219.02],[1,1.31,2309.84],[2,1.3,3072.52]],"batl":[[0,1.33,290.28],[1,1.34,1178.84]],"ltp":1.32,"tv":87926.0,"id":5300737},{"batl":[[0,4.4,76.09],[1,4.5,101.43],[2,4.6,103.85]],"ltp":3.9,"tv":24183.21,"id":2497008}],"tv":112109.21}]}
{"op":"mcm","clk":"4299307942","pt":1632580339787,"mc":[{"id":"1.188136695","rc":[{"batb":[[1,1.31,1357.58]],"ltp":1.32,"tv":87926.0,"id":5300737}]}]}
{"op":"mcm","clk":"4299308251","pt":1632580340717,"mc":[{"id":"1.188136695","rc":[{"batl":[[2,1.35,1017.95]],"ltp":1.32,"tv":87926.0,"id":5300737},{"batl":[[0,4.2,12.22],[1,4.3,2.93],[2,4.4,76.09]],"ltp":3.9,"tv":24183.21,"id":2497008}]}]}
{"op":"mcm","clk":"4299308584","pt":1632580341769,"mc":[{"id":"1.188136695","rc":[{"trd":[[1.33,167.55]],"batb":[[0,1.32,218.59]],"batl":[[0,1.33,619.54]],"ltp":1.33,"tv":88088.0,"id":5300737},{"trd":[[4,25.47]],"ltp":4.0,"tv":24203.82,"id":2497008}],"tv":112291.83}]}
{"op":"mcm","clk":"4299308945","pt":1632580342814,"mc":[{"id":"1.188136695","rc":[{"trd":[[1.32,1336.56]],"batb":[[0,1.32,216.98],[1,1.31,1287.77]],"batl":[[0,1.33,694.95],[1,1.34,1123.02]],"ltp":1.32,"tv":88091.21,"id":5300737}],"tv":112295.04}]}
{"op":"mcm","clk":"4299309233","pt":1632580343579,"mc":[{"id":"1.188136695","rc":[{"trd":[[1.32,1343.58],[1.33,168.6]],"batb":[[0,1.32,213.47]],"batl":[[0,1.33,693.9]],"ltp":1.33,"tv":88099.28,"id":5300737},{"trd":[[4,25.82]],"ltp":4.0,"tv":24204.17,"id":2497008}],"tv":112303.46}]}
{"op":"mcm","clk":"4299309707","pt":1632580345125,"mc":[{"id":"1.188136695","rc":[{"trd":[[1.32,1413.7]],"batb":[[0,1.32,178.41]],"ltp":1.32,"tv":88169.4,"id":5300737}],"tv":112373.58}]}
{"op":"mcm","clk":"4299310481","pt":1632580347541,"mc":[{"id":"1.188136695","rc":[{"trd":[[1.32,1519.92],[1.33,208.6]],"batb":[[0,1.32,125.3]],"batl":[[0,1.33,673.9]],"ltp":1.32,"tv":88315.62,"id":5300737}],"tv":112519.8}]}
{"op":"mcm","clk":"4299310848","pt":1632580348734,"mc":[{"id":"1.188136695","rc":[{"batb":[[1,1.31,1232.64],[2,1.3,1738.49]],"batl":[[2,1.35,978.05]],"ltp":1.32,"tv":88315.62,"id":5300737},{"batb":[[1,3.85,183.17],[2,3.75,5.99]],"batl":[[0,4.3,2.93],[1,4.4,76.09],[2,4.5,101.43]],"ltp":4.0,"tv":24204.17,"id":2497008}]}]}
{"op":"mcm","clk":"4299311206","pt":1632580349829,"mc":[{"id":"1.188136695","rc":[{"trd":[[1.33,209.46]],"batb":[[0,1.32,56.66],[1,1.3,627.94],[2,1.29,1341.78]],"batl":[[0,1.33,75.41],[1,1.36,153.99],[2,1.37,123.5]],"ltp":1.33,"tv":88316.48,"id":5300737},{"batb":[[1,3.75,5.99],[2,3.7,5.72]],"batl":[[2,4.5,87.41]],"ltp":4.0,"tv":24204.17,"id":2497008}],"tv":112520.66}]}
{"op":"mcm","clk":"4299311516","pt":1632580350803,"mc":[{"id":"1.188136695","rc":[{"batl":[[1,1.36,13.42],[2,1.38,142.25]],"ltp":1.33,"tv":88316.48,"id":5300737},{"batb":[[1,3.6,6.14],[2,3.55,2.42]],"batl":[[0,4.4,76.09],[1,4.5,87.41],[2,4.6,103.85]],"ltp":4.0,"tv":24204.17,"id":2497008}]}]}
{"op":"mcm","clk":"4299311653","pt":1632580351299,"mc":[{"id":"1.188136695","rc":[{"batb":[[0,1.3,627.94],[1,1.29,1341.78],[2,1.28,387.88]],"batl":[[0,1.36,13.42],[1,1.38,142.25],[2,1.4,242.47]],"ltp":1.33,"tv":88316.48,"id":5300737},{"batl":[[0,4,85.71],[1,4.4,76.09],[2,4.5,87.41]],"ltp":4.0,"tv":24204.17,"id":2497008}]}]}
{"op":"mcm","clk":"4299312087","pt":1632580352596,"mc":[{"id":"1.188136695","rc":[{"trd":[[1.3,6894.26],[1.32,1520.05],[1.33,467.24]],"batb":[[0,1.3,403.38],[1,1.29,421.61],[2,1.28,1341.02]],"batl":[[0,1.32,192.9]],"ltp":1.3,"tv":89023.52,"id":5300737},{"trd":[[4,111.53],[4.1,0.04]],"batb":[[1,3.65,184.49],[2,3.6,6.14]],"batl":[[0,4.4,76.09],[1,4.5,87.41],[2,4.6,103.85]],"ltp":4.1,"tv":24289.92,"id":2497008}],"tv":113313.45}]}
{"op":"mcm","clk":"4299312477","pt":1632580353817,"mc":[{"id":"1.188136695","rc":[{"batl":[[0,1.32,227.96],[1,1.36,144.07],[2,1.38,142.25]],"ltp":1.3,"tv":89023.52,"id":5300737},{"batb":[[1,3.75,6.07],[2,3.65,184.49]],"ltp":4.1,"tv":24289.92,"id":2497008}]}]}
{"op":"mcm","clk":"4299312749","pt":1632580354794,"mc":[{"id":"1.188136695","rc":[{"trd":[[1.32,1529.14]],"batl":[[0,1.32,218.87]],"ltp":1.32,"tv":89032.61,"id":5300737},{"trd":[[4.1,2.97]],"batl":[[0,4.4,613.68]],"ltp":4.1,"tv":24292.85,"id":2497008}],"tv":113325.47}]}
{"op":"mcm","clk":"4299313070","pt":1632580355829,"mc":[{"id":"1.188136695","rc":[{"trd":[[1.32,1914.84]],"batl":[[0,1.32,185.55],[1,1.38,142.25],[2,1.4,242.47]],"ltp":1.32,"tv":89418.32,"id":5300737},{"batb":[[1,3.65,184.49],[2,3.6,6.14]],"batl":[[0,4.4,76.09]],"ltp":4.1,"tv":24292.85,"id":2497008}],"tv":113711.17}]}
{"op":"mcm","clk":"4299313362","pt":1632580356825,"mc":[{"id":"1.188136695","rc":[{"trd":[[1.32,2285.94]],"batb":[[0,1.33,766.71],[1,1.3,403.38],[2,1.29,421.61]],"batl":[[0,1.35,10.93]],"ltp":1.32,"tv":89789.42,"id":5300737}],"tv":114082.27}]}
{"op":"mcm","clk":"4299313656","pt":1632580357741,"mc":[{"id":"1.188136695","rc":[{"batb":[[1,1.32,1006.25],[2,1.31,1062.13]],"batl":[[0,1.35,788.42],[1,1.36,855.49],[2,1.38,142.25]],"ltp":1.32,"tv":89789.42,"id":5300737}]}]}
{"op":"mcm","clk":"4299313945","pt":1632580358731,"mc":[{"id":"1.188136695","rc":[{"batb":[[0,1.3,403.38],[1,1.29,421.61],[2,1.28,1341.02]],"batl":[[0,1.35,10.93],[1,1.38,142.25],[2,1.4,242.47]],"ltp":1.32,"tv":89789.42,"id":5300737}]}]}
{"op":"mcm","clk":"4299314246","pt":1632580359811,"mc":[{"id":"1.188136695","rc":[{"batl":[[0,1.34,184.16],[1,1.35,227.93],[2,1.38,142.25]],"ltp":1.32,"tv":89789.42,"id":5300737}]}]}
