{"op":"mcm","clk":"4210098064","pt":1631330837213,"mc":[{"id":"1.187528277","marketDefinition":{"bspMarket":false,"turnInPlayEnabled":true,"persistenceEnabled":true,"marketBaseRate":5.0,"eventId":"30891863","eventTypeId":"2","numberOfWinners":1,"bettingType":"ODDS","marketType":"MATCH_ODDS","marketTime":"2021-09-12T15:00:00.000Z","suspendTime":"2021-09-12T15:00:00.000Z","bspReconciled":false,"complete":true,"inPlay":false,"crossMatching":true,"runnersVoidable":false,"numberOfActiveRunners":2,"betDelay":0,"status":"OPEN","runners":[{"status":"ACTIVE","sortPriority":1,"id":2249229,"name":"Novak Djokovic"},{"status":"ACTIVE","sortPriority":2,"id":19924831,"name":"Daniil Medvedev"}],"regulators":["MR_INT"],"countryCode":"US","discountAllowed":false,"timezone":"UTC","openDate":"2021-09-12T15:00:00.000Z","version":4023427524,"name":"Match Odds","eventName":"Djokovic v Medvedev"},"rc":[{"batb":[[0,1.07,7230.14],[1,1.06,7230.14],[2,1.05,7230.14]],"ltp":0.0,"tv":0.0,"id":19924831},{"batb":[[0,1.07,7230.14],[1,1.06,7230.14],[2,1.05,7230.14]],"ltp":0.0,"tv":0.0,"id":2249229}]}]}
{"op":"mcm","clk":"4210098201","pt":1631330838736,"mc":[{"id":"1.187528277","marketDefinition":{"bspMarket":false,"turnInPlayEnabled":true,"persistenceEnabled":true,"marketBaseRate":5.0,"eventId":"30891863","eventTypeId":"2","numberOfWinners":1,"bettingType":"ODDS","marketType":"MATCH_ODDS","marketTime":"2021-09-12T15:00:00.000Z","suspendTime":"2021-09-12T15:00:00.000Z","bspReconciled":false,"complete":true,"inPlay":false,"crossMatching":true,"runnersVoidable":false,"numberOfActiveRunners":2,"betDelay":0,"status":"OPEN","runners":[{"status":"ACTIVE","sortPriority":1,"id":2249229,"name":"Novak Djokovic"},{"status":"ACTIVE","sortPriority":2,"id":19924831,"name":"Daniil Medvedev"}],"regulators":["MR_INT"],"countryCode":"US","discountAllowed":true,"timezone":"UTC","openDate":"2021-09-12T15:00:00.000Z","version":4023427524,"name":"Match Odds","eventName":"Djokovic v Medvedev"}}]}
{"op":"mcm","clk":"4210107345","pt":1631330953373,"mc":[{"id":"1.187528277","rc":[{"batb":[[2,1.05,13014.24]],"ltp":0.0,"tv":0.0,"id":2249229}]}]}
{"op":"mcm","clk":"4210107450","pt":1631330954559,"mc":[{"id":"1.187528277","rc":[{"batb":[[0,1.09,5784.11],[1,1.08,5784.11],[2,1.07,13014.24]],"ltp":0.0,"tv":0.0,"id":2249229}]}]}
{"op":"mcm","clk":"4210107522","pt":1631330955492,"mc":[{"id":"1.187528277","rc":[{"batb":[[0,1.11,5784.11],[1,1.1,5784.11],[2,1.09,5784.11]],"ltp":0.0,"tv":0.0,"id":2249229}]}]}
{"op":"mcm","clk":"4210107870","pt":1631330959667,"mc":[{"id":"1.187528277","rc":[{"batb":[[2,1.05,13014.24]],"ltp":0.0,"tv":0.0,"id":19924831}]}]}
{"op":"mcm","clk":"4210107936","pt":1631330960502,"mc":[{"id":"1.187528277","rc":[{"batb":[[0,1.08,5784.11],[1,1.07,13014.24],[2,1.06,13014.24]],"ltp":0.0,"tv":0.0,"id":19924831},{"batb":[[0,1.12,1897.69],[1,1.11,5784.11],[2,1.1,5784.11]],"ltp":0.0,"tv":0.0,"id":2249229}]}]}
{"op":"mcm","clk":"4210108030","pt":1631330961620,"mc":[{"id":"1.187528277","rc":[{"batb":[[0,1.11,5784.11],[1,1.1,5784.11],[2,1.09,5784.11]],"ltp":0.0,"tv":0.0,"id":19924831},{"batb":[[1,1.11,7681.79],[2,1.1,7681.79]],"ltp":0.0,"tv":0.0,"id":2249229}]}]}
{"op":"mcm","clk":"4210108308","pt":1631330964927,"mc":[{"id":"1.187528277","rc":[{"batb":[[0,1.13,1897.69],[1,1.12,1897.69],[2,1.11,7681.79]],"ltp":0.0,"tv":0.0,"id":2249229}]}]}
{"op":"mcm","clk":"4210108710","pt":1631330970652,"mc":[{"id":"1.187528277","rc":[{"batb":[[0,2.66,413.89],[1,1.11,5784.11],[2,1.1,5784.11]],"ltp":0.0,"tv":0.0,"id":19924831},{"batb":[[0,1.23,996.72],[1,1.13,1897.69],[2,1.12,1897.69]],"ltp":0.0,"tv":0.0,"id":2249229}]}]}
{"op":"mcm","clk":"4210108836","pt":1631330972352,"mc":[{"id":"1.187528277","rc":[{"batb":[[1,1.13,1897.69],[2,1.11,5784.11]],"ltp":0.0,"tv":0.0,"id":19924831}]}]}
{"op":"mcm","clk":"4210108912","pt":1631330973543,"mc":[{"id":"1.187528277","rc":[{"batb":[[2,1.12,1897.69]],"ltp":0.0,"tv":0.0,"id":19924831}]}]}
{"op":"mcm","clk":"4210109727","pt":1631330985150,"mc":[{"id":"1.187528277","rc":[{"batb":[[0,1.24,3615.07],[1,1.23,996.72],[2,1.13,1897.69]],"ltp":0.0,"tv":0.0,"id":2249229}]}]}
{"op":"mcm","clk":"4210110055","pt":1631330990348,"mc":[{"id":"1.187528277","rc":[{"batb":[[0,1.3,3233],[1,1.24,3615.07],[2,1.23,996.72]],"ltp":0.0,"tv":0.0,"id":2249229}]}]}
{"op":"mcm","clk":"4210110305","pt":1631330994199,"mc":[{"id":"1.187528277","rc":[{"batb":[[0,1.33,170.81],[1,1.3,3233],[2,1.24,3615.07]],"ltp":0.0,"tv":0.0,"id":2249229}]}]}
{"op":"mcm","clk":"4210112025","pt":1631331017647,"mc":[{"id":"1.187528277","rc":[{"batb":[[1,1.5,3615.07],[2,1.13,1897.69]],"ltp":0.0,"tv":0.0,"id":19924831}]}]}
{"op":"mcm","clk":"4210112203","pt":1631331020059,"mc":[{"id":"1.187528277","rc":[{"batb":[[0,1.35,906.79],[1,1.33,170.81],[2,1.3,3233]],"batl":[[0,1.59,3233]],"ltp":0.0,"tv":0.0,"id":2249229}]}]}
{"op":"mcm","clk":"4210112491","pt":1631331024261,"mc":[{"id":"1.187528277","rc":[{"batb":[[0,1.36,3233],[1,1.35,906.79],[2,1.33,170.81]],"ltp":0.0,"tv":0.0,"id":2249229}]}]}
{"op":"mcm","clk":"4210112738","pt":1631331027664,"mc":[{"id":"1.187528277","rc":[{"batl":[[0,1.57,189.6],[1,1.59,3233]],"ltp":0.0,"tv":0.0,"id":2249229}]}]}
{"op":"mcm","clk":"4210112756","pt":1631331027972,"mc":[{"id":"1.187528277","rc":[{"batb":[[0,1.37,170.81],[1,1.36,3233],[2,1.35,906.79]],"ltp":0.0,"tv":0.0,"id":2249229}]}]}
{"op":"mcm","clk":"4210113091","pt":1631331032603,"mc":[{"id":"1.187528277","rc":[{"batb":[[0,1.38,3233],[1,1.37,170.81]],"ltp":0.0,"tv":0.0,"id":2249229}]}]}
{"op":"mcm","clk":"4210113282","pt":1631331035286,"mc":[{"id":"1.187528277","rc":[{"batb":[[0,1.39,880.31],[1,1.38,3233],[2,1.37,170.81]],"batl":[[0,1.57,1465.92]],"ltp":0.0,"tv":0.0,"id":2249229}]}]}
{"op":"mcm","clk":"4210113366","pt":1631331036387,"mc":[{"id":"1.187528277","rc":[{"batl":[[0,1.56,3233],[1,1.57,2742.25]],"ltp":0.0,"tv":0.0,"id":2249229}]}]}
{"op":"mcm","clk":"4210113595","pt":1631331039718,"mc":[{"id":"1.187528277","rc":[{"batb":[[1,1.37,170.81],[2,1.24,3615.07]],"ltp":0.0,"tv":0.0,"id":2249229}]}]}
{"op":"mcm","clk":"4210113601","pt":1631331039772,"mc":[{"id":"1.187528277","rc":[{"batb":[[0,1.4,3233],[1,1.39,880.31],[2,1.37,170.81]],"ltp":0.0,"tv":0.0,"id":2249229}]}]}
{"op":"mcm","clk":"4210113770","pt":1631331042097,"mc":[{"id":"1.187528277","rc":[{"batb":[[0,1.4,3446.51]],"batl":[[0,1.56,4509.32]],"ltp":0.0,"tv":0.0,"id":2249229}]}]}
{"op":"mcm","clk":"4210113831","pt":1631331042920,"mc":[{"id":"1.187528277","rc":[{"batb":[[2,1.38,213.51]],"ltp":0.0,"tv":0.0,"id":2249229}]}]}
{"op":"mcm","clk":"4210113973","pt":1631331045289,"mc":[{"id":"1.187528277","rc":[{"batb":[[0,1.41,213.51],[1,1.4,3446.51],[2,1.39,880.31]],"ltp":0.0,"tv":0.0,"id":2249229}]}]}
{"op":"mcm","clk":"4210114506","pt":1631331052408,"mc":[{"id":"1.187528277","rc":[{"batb":[[2,1.39,213.51]],"batl":[[1,1.57,189.6]],"ltp":0.0,"tv":0.0,"id":2249229}]}]}
{"op":"mcm","clk":"4210114761","pt":1631331056297,"mc":[{"id":"1.187528277","rc":[{"batl":[[0,1.56,5785.65]],"ltp":0.0,"tv":0.0,"id":2249229}]}]}
{"op":"mcm","clk":"4210116783","pt":1631331081996,"mc":[{"id":"1.187528277","rc":[{"batb":[[1,1.51,256.21],[2,1.5,3615.07]],"ltp":0.0,"tv":0.0,"id":19924831}]}]}
{"op":"mcm","clk":"4210116938","pt":1631331083712,"mc":[{"id":"1.187528277","rc":[{"batb":[[1,1.5,3615.07],[2,1.13,1897.69]],"ltp":0.0,"tv":0.0,"id":19924831}]}]}
{"op":"mcm","clk":"4210118539","pt":1631331104749,"mc":[{"id":"1.187528277","rc":[{"batl":[[0,1.55,93.07],[1,1.56,5785.65],[2,1.57,189.6]],"ltp":0.0,"tv":0.0,"id":2249229}]}]}
{"op":"mcm","clk":"4210118723","pt":1631331107374,"mc":[{"id":"1.187528277","rc":[{"batl":[[0,1.55,2645.71],[1,1.56,3233]],"ltp":0.0,"tv":0.0,"id":2249229}]}]}
{"op":"mcm","clk":"4210119212","pt":1631331113673,"mc":[{"id":"1.187528277","rc":[{"batl":[[0,1.55,3922.04]],"ltp":0.0,"tv":0.0,"id":2249229}]}]}
{"op":"mcm","clk":"4210121948","pt":1631331147891,"mc":[{"id":"1.187528277","rc":[{"batl":[[0,1.49,1708.09],[1,1.55,3922.04],[2,1.56,3233]],"ltp":0.0,"tv":0.0,"id":2249229}]}]}
{"op":"mcm","clk":"4210122081","pt":1631331149608,"mc":[{"id":"1.187528277","rc":[{"batl":[[0,1.49,3416.18]],"ltp":0.0,"tv":0.0,"id":2249229}]}]}
{"op":"mcm","clk":"4210124148","pt":1631331175625,"mc":[{"id":"1.187528277","rc":[{"batl":[[0,1.48,3233],[1,1.49,3416.18],[2,1.55,3922.04]],"ltp":0.0,"tv":0.0,"id":2249229}]}]}
{"op":"mcm","clk":"4210124450","pt":1631331179402,"mc":[{"id":"1.187528277","rc":[{"batb":[[0,1.41,923.51]],"ltp":0.0,"tv":0.0,"id":2249229}]}]}
{"op":"mcm","clk":"4210125747","pt":1631331194602,"mc":[{"id":"1.187528277","rc":[{"batb":[[0,3.1,401.27],[1,2.66,413.89],[2,1.5,3615.07]],"ltp":0.0,"tv":0.0,"id":19924831}]}]}
{"op":"mcm","clk":"4210126719","pt":1631331206297,"mc":[{"id":"1.187528277","rc":[{"batl":[[0,1.47,401.27],[1,1.48,3233],[2,1.49,3416.18]],"ltp":0.0,"tv":0.0,"id":2249229}]}]}
{"op":"mcm","clk":"4210128765","pt":1631331231635,"mc":[{"id":"1.187528277","rc":[{"batb":[[0,1.42,3233],[1,1.41,923.51],[2,1.4,213.51]],"ltp":0.0,"tv":0.0,"id":2249229}]}]}
{"op":"mcm","clk":"4210129744","pt":1631331244740,"mc":[{"id":"1.187528277","rc":[{"batb":[[1,1.41,213.51]],"ltp":0.0,"tv":0.0,"id":2249229}]}]}
{"op":"mcm","clk":"4210131222","pt":1631331263650,"mc":[{"id":"1.187528277","rc":[{"batl":[[0,1.46,1708.09],[1,1.47,401.27],[2,1.48,3233]],"ltp":0.0,"tv":0.0,"id":2249229}]}]}
{"op":"mcm","clk":"4210131834","pt":1631331270747,"mc":[{"id":"1.187528277","rc":[{"batb":[[1,1.5,3615.07],[2,1.13,1897.69]],"ltp":0.0,"tv":0.0,"id":19924831}]}]}
{"op":"mcm","clk":"4210132846","pt":1631331282685,"mc":[{"id":"1.187528277","rc":[{"batb":[[0,3.2,401.27]],"ltp":0.0,"tv":0.0,"id":19924831}]}]}
{"op":"mcm","clk":"4210132853","pt":1631331282733,"mc":[{"id":"1.187528277","rc":[{"batb":[[1,2.32,476],[2,1.5,3615.07]],"ltp":0.0,"tv":0.0,"id":19924831}]}]}
{"op":"mcm","clk":"4210133721","pt":1631331292500,"mc":[{"id":"1.187528277","rc":[{"batl":[[0,1.45,401.27],[1,1.46,1708.09]],"ltp":0.0,"tv":0.0,"id":2249229}]}]}
{"op":"mcm","clk":"4210138489","pt":1631331351270,"mc":[{"id":"1.187528277","rc":[{"batb":[[1,1.24,3615.07],[2,1.13,1897.69]],"ltp":0.0,"tv":0.0,"id":2249229}]}]}
{"op":"mcm","clk":"4210139936","pt":1631331369585,"mc":[{"id":"1.187528277","rc":[{"batb":[[1,1.33,472.29],[2,1.24,3615.07]],"ltp":0.0,"tv":0.0,"id":2249229}]}]}
{"op":"mcm","clk":"4210140336","pt":1631331374488,"mc":[{"id":"1.187528277","rc":[{"batb":[[1,1.5,3615.07],[2,1.13,1897.69]],"batl":[[0,3.35,123]],"ltp":0.0,"tv":0.0,"id":19924831}]}]}
{"op":"mcm","clk":"4210142803","pt":1631331404255,"mc":[{"id":"1.187528277","rc":[{"batb":[[0,1.4,3233],[1,1.34,913.66],[2,1.33,472.29]],"ltp":0.0,"tv":0.0,"id":2249229}]}]}
{"op":"mcm","clk":"4210148127","pt":1631331471243,"mc":[{"id":"1.187528277","rc":[{"batb":[[0,1.41,86.26],[1,1.4,3233]],"ltp":0.0,"tv":0.0,"id":2249229}]}]}
{"op":"mcm","clk":"4210151755","pt":1631331522882,"mc":[{"id":"1.187528277","rc":[{"batl":[[1,1.48,3233],[2,1.55,3922.04]],"ltp":0.0,"tv":0.0,"id":2249229}]}]}
{"op":"mcm","clk":"4210155745","pt":1631331580069,"mc":[{"id":"1.187528277","rc":[{"batb":[[2,1.37,5.32]],"ltp":0.0,"tv":0.0,"id":2249229}]}]}
{"op":"mcm","clk":"4210155968","pt":1631331583279,"mc":[{"id":"1.187528277","rc":[{"batl":[[0,3.45,123]],"ltp":0.0,"tv":0.0,"id":19924831}]}]}
{"op":"mcm","clk":"4210160208","pt":1631331643374,"mc":[{"id":"1.187528277","rc":[{"batl":[[0,1.45,1677.6]],"ltp":0.0,"tv":0.0,"id":2249229}]}]}
{"op":"mcm","clk":"4210167703","pt":1631331747842,"mc":[{"id":"1.187528277","rc":[{"batl":[[0,1.44,200],[1,1.45,1677.6],[2,1.48,3233]],"ltp":0.0,"tv":0.0,"id":2249229}]}]}
{"op":"mcm","clk":"4210170356","pt":1631331783246,"mc":[{"id":"1.187528277","rc":[{"batl":[[0,3.45,75]],"ltp":0.0,"tv":0.0,"id":19924831}]}]}
{"op":"mcm","clk":"4210170621","pt":1631331786553,"mc":[{"id":"1.187528277","rc":[{"batb":[[1,1.37,5.32],[2,1.33,472.29]],"batl":[[2,1.55,3922.04]],"ltp":0.0,"tv":0.0,"id":2249229}]}]}
{"op":"mcm","clk":"4210176941","pt":1631331869016,"mc":[{"id":"1.187528277","rc":[{"trd":[[3.25,39.29]],"ltp":3.25,"tv":39.28,"id":19924831},{"trd":[[1.44,88.67]],"batl":[[0,1.44,111.33]],"ltp":1.44,"tv":88.67,"id":2249229}],"tv":127.95}]}
{"op":"mcm","clk":"4210183970","pt":1631331959995,"mc":[{"id":"1.187528277","rc":[{"trd":[[3.25,88.39]],"ltp":3.25,"tv":88.39,"id":19924831},{"trd":[[1.44,199.5]],"batl":[[0,1.45,1678.1],[1,1.55,3922.04],[2,1.57,189.6]],"ltp":1.44,"tv":199.5,"id":2249229}],"tv":287.89}]}
{"op":"mcm","clk":"4210187479","pt":1631332002527,"mc":[{"id":"1.187528277","rc":[{"trd":[[1.44,200.5]],"batb":[[0,1.44,255.71],[1,1.41,86.26],[2,1.37,5.32]],"batl":[[0,1.45,1677.6]],"ltp":1.44,"tv":200.5,"id":2249229}],"tv":288.89}]}
{"op":"mcm","clk":"4210188681","pt":1631332017940,"mc":[{"id":"1.187528277","rc":[{"batb":[[1,1.43,256.21],[2,1.41,86.26]],"ltp":1.44,"tv":200.5,"id":2249229}]}]}
{"op":"mcm","clk":"4210189017","pt":1631332022571,"mc":[{"id":"1.187528277","rc":[{"trd":[[1.44,711.92]],"batb":[[0,1.43,256.21],[1,1.41,86.26],[2,1.37,5.32]],"batl":[[0,1.44,171.31],[1,1.45,1677.6],[2,1.55,3922.04]],"ltp":1.44,"tv":711.92,"id":2249229}],"tv":800.31}]}
{"op":"mcm","clk":"4210189653","pt":1631332031567,"mc":[{"id":"1.187528277","rc":[{"batb":[[1,1.42,256.21],[2,1.41,86.26]],"ltp":1.44,"tv":711.92,"id":2249229}]}]}
{"op":"mcm","clk":"4210207945","pt":1631332069472,"mc":[{"id":"1.187528277","rc":[{"batl":[[0,1.45,1677.6],[1,1.55,3922.04],[2,1.57,189.6]],"ltp":1.44,"tv":711.92,"id":2249229}]}]}
{"op":"mcm","clk":"4210209690","pt":1631332092682,"mc":[{"id":"1.187528277","rc":[{"batb":[[0,1.44,219.88],[1,1.43,256.21],[2,1.42,256.21]],"ltp":1.44,"tv":711.92,"id":2249229}]}]}
{"op":"mcm","clk":"4210210611","pt":1631332104735,"mc":[{"id":"1.187528277","rc":[{"batb":[[1,1.43,454.1]],"ltp":1.44,"tv":711.92,"id":2249229}]}]}
{"op":"mcm","clk":"4210211320","pt":1631332113662,"mc":[{"id":"1.187528277","rc":[{"trd":[[1.44,1144.28]],"batb":[[0,1.44,3.69]],"ltp":1.44,"tv":1144.28,"id":2249229}],"tv":1232.67}]}
{"op":"mcm","clk":"4210211569","pt":1631332116774,"mc":[{"id":"1.187528277","rc":[{"batb":[[2,1.42,476.09]],"ltp":1.44,"tv":1144.28,"id":2249229}]}]}
{"op":"mcm","clk":"4210212656","pt":1631332131800,"mc":[{"id":"1.187528277","rc":[{"trd":[[1.44,1151.68]],"batb":[[0,1.43,454.1],[1,1.42,476.09],[2,1.41,86.26]],"batl":[[0,1.44,423.32],[1,1.45,1677.6],[2,1.55,3922.04]],"ltp":1.44,"tv":1151.67,"id":2249229}],"tv":1240.07}]}
{"op":"mcm","clk":"4210213521","pt":1631332143935,"mc":[{"id":"1.187528277","rc":[{"batl":[[2,1.48,249.38]],"ltp":1.44,"tv":1151.67,"id":2249229}]}]}
{"op":"mcm","clk":"4210214668","pt":1631332160668,"mc":[{"id":"1.187528277","rc":[{"batl":[[2,1.47,215.48]],"ltp":1.44,"tv":1151.67,"id":2249229}]}]}
{"op":"mcm","clk":"4210218888","pt":1631332224515,"mc":[{"id":"1.187528277","rc":[{"trd":[[3.35,5.32]],"ltp":3.35,"tv":93.71,"id":19924831},{"trd":[[1.43,12.46]],"batb":[[0,1.43,441.64]],"ltp":1.43,"tv":1164.13,"id":2249229}],"tv":1257.84}]}
{"op":"mcm","clk":"4210233992","pt":1631332430841,"mc":[{"id":"1.187528277","rc":[{"batb":[[0,1.43,641.64]],"ltp":1.43,"tv":1164.13,"id":2249229}]}]}
{"op":"mcm","clk":"4210235981","pt":1631332459366,"mc":[{"id":"1.187528277","rc":[{"batb":[[0,1.43,441.64],[1,1.42,676.09]],"ltp":1.43,"tv":1164.13,"id":2249229}]}]}
{"op":"mcm","clk":"4210248486","pt":1631332644349,"mc":[{"id":"1.187528277","rc":[{"batb":[[0,3.2,760.15]],"ltp":3.35,"tv":93.71,"id":19924831}]}]}
{"op":"mcm","clk":"4210249202","pt":1631332654984,"mc":[{"id":"1.187528277","rc":[{"batb":[[0,3.2,401.27]],"ltp":3.35,"tv":93.71,"id":19924831}]}]}
{"op":"mcm","clk":"4210272475","pt":1631332944483,"mc":[{"id":"1.187528277","rc":[{"batb":[[0,3.2,758.66]],"ltp":3.35,"tv":93.71,"id":19924831}]}]}
{"op":"mcm","clk":"4210274534","pt":1631332977777,"mc":[{"id":"1.187528277","rc":[{"batl":[[1,1.45,1704.19]],"ltp":1.43,"tv":1164.13,"id":2249229}]}]}
{"op":"mcm","clk":"4210277160","pt":1631333024174,"mc":[{"id":"1.187528277","rc":[{"trd":[[1.43,881.53]],"batb":[[0,1.43,7.11]],"ltp":1.43,"tv":2033.2,"id":2249229}],"tv":2126.91}]}
{"op":"mcm","clk":"4210282053","pt":1631333104663,"mc":[{"id":"1.187528277","rc":[{"batl":[[0,1.45,1704.19],[1,1.47,215.48],[2,1.48,1525.71]],"ltp":1.43,"tv":2033.2,"id":2249229}]}]}
{"op":"mcm","clk":"4210282300","pt":1631333108487,"mc":[{"id":"1.187528277","rc":[{"batb":[[0,1.43,268.32]],"ltp":1.43,"tv":2033.2,"id":2249229}]}]}
{"op":"mcm","clk":"4210283293","pt":1631333124369,"mc":[{"id":"1.187528277","rc":[{"batl":[[0,1.44,393.32],[1,1.45,1704.19],[2,1.47,215.48]],"ltp":1.43,"tv":2033.2,"id":2249229}]}]}
{"op":"mcm","clk":"4210289564","pt":1631333230677,"mc":[{"id":"1.187528277","rc":[{"trd":[[1.43,1266.17]],"batb":[[0,1.43,76]],"ltp":1.43,"tv":2417.84,"id":2249229}],"tv":2511.55}]}
{"op":"mcm","clk":"4210290416","pt":1631333243212,"mc":[{"id":"1.187528277","rc":[{"trd":[[1.43,1409.33]],"batb":[[0,1.43,4.42]],"ltp":1.43,"tv":2561.0,"id":2249229}],"tv":2654.71}]}
{"op":"mcm","clk":"4210293425","pt":1631333290695,"mc":[{"id":"1.187528277","rc":[{"trd":[[1.42,1351.94],[1.43,1418.18]],"batb":[[0,1.41,86.38],[1,1.4,85.4],[2,1.37,5.32]],"ltp":1.42,"tv":3921.79,"id":2249229}],"tv":4015.5}]}
{"op":"mcm","clk":"4210293557","pt":1631333292630,"mc":[{"id":"1.187528277","rc":[{"batb":[[0,3.2,401.27]],"ltp":3.35,"tv":93.71,"id":19924831}]}]}
{"op":"mcm","clk":"4210298123","pt":1631333369024,"mc":[{"id":"1.187528277","rc":[{"batl":[[0,1.44,820.34]],"ltp":1.42,"tv":3921.79,"id":2249229}]}]}
{"op":"mcm","clk":"4210298580","pt":1631333376143,"mc":[{"id":"1.187528277","rc":[{"batb":[[0,1.5,3615.07],[1,1.13,1897.69],[2,1.12,1897.69]],"ltp":3.35,"tv":93.71,"id":19924831},{"batl":[[0,1.44,427.02],[1,1.45,1302.91]],"ltp":1.42,"tv":3921.79,"id":2249229}]}]}
{"op":"mcm","clk":"4210298790","pt":1631333379097,"mc":[{"id":"1.187528277","rc":[{"batb":[[0,3,10.2],[1,1.5,3615.07],[2,1.13,1897.69]],"ltp":3.35,"tv":93.71,"id":19924831}]}]}
{"op":"mcm","clk":"4210299872","pt":1631333398249,"mc":[{"id":"1.187528277","rc":[{"batl":[[0,1.43,100],[1,1.44,427.02],[2,1.45,1302.91]],"ltp":1.42,"tv":3921.79,"id":2249229}]}]}
{"op":"mcm","clk":"4210300237","pt":1631333403783,"mc":[{"id":"1.187528277","rc":[{"batl":[[1,1.44,527.02]],"ltp":1.42,"tv":3921.79,"id":2249229}]}]}
{"op":"mcm","clk":"4210304788","pt":1631333481331,"mc":[{"id":"1.187528277","rc":[{"batb":[[0,1.4,85.52],[1,1.39,86.26]],"ltp":1.42,"tv":3921.79,"id":2249229}]}]}
{"op":"mcm","clk":"4210306134","pt":1631333503488,"mc":[{"id":"1.187528277","rc":[{"batb":[[1,1.37,5.32],[2,1.36,56.67]],"ltp":1.42,"tv":3921.79,"id":2249229}]}]}
{"op":"mcm","clk":"4210306379","pt":1631333507980,"mc":[{"id":"1.187528277","rc":[{"batb":[[0,1.37,927.11],[1,1.36,56.67],[2,1.33,472.29]],"ltp":1.42,"tv":3921.79,"id":2249229}]}]}
{"op":"mcm","clk":"4210308821","pt":1631333554927,"mc":[{"id":"1.187528277","rc":[{"batb":[[0,1.38,3.13],[1,1.37,926.99],[2,1.36,56.67]],"ltp":1.42,"tv":3921.79,"id":2249229}]}]}
{"op":"mcm","clk":"4210309318","pt":1631333567672,"mc":[{"id":"1.187528277","rc":[{"batb":[[0,1.38,74.02],[1,1.37,5.32]],"ltp":1.42,"tv":3921.79,"id":2249229}]}]}
{"op":"mcm","clk":"4210310810","pt":1631333601892,"mc":[{"id":"1.187528277","rc":[{"trd":[[1.38,52.94],[1.42,1352.18]],"batb":[[0,1.38,47.43]],"ltp":1.38,"tv":3974.97,"id":2249229}],"tv":4068.68}]}
{"op":"mcm","clk":"4210311383","pt":1631333614479,"mc":[{"id":"1.187528277","rc":[{"batb":[[0,1.38,945.25]],"ltp":1.38,"tv":3974.97,"id":2249229}]}]}
{"op":"mcm","clk":"4210311408","pt":1631333614899,"mc":[{"id":"1.187528277","rc":[{"trd":[[1.38,58.25]],"batb":[[0,1.38,942.59]],"ltp":1.38,"tv":3980.29,"id":2249229}],"tv":4074.0}]}
{"op":"mcm","clk":"4210311728","pt":1631333621705,"mc":[{"id":"1.187528277","rc":[{"batb":[[0,1.38,44.77]],"ltp":1.38,"tv":3980.29,"id":2249229}]}]}
{"op":"mcm","clk":"4210311735","pt":1631333621787,"mc":[{"id":"1.187528277","rc":[{"batb":[[0,1.38,1391.5]],"ltp":1.38,"tv":3980.29,"id":2249229}]}]}
{"op":"mcm","clk":"4210311933","pt":1631333625617,"mc":[{"id":"1.187528277","rc":[{"batb":[[0,1.39,845.5],[1,1.38,1391.5],[2,1.37,5.32]],"ltp":1.38,"tv":3980.29,"id":2249229}]}]}
{"op":"mcm","clk":"4210314470","pt":1631333674426,"mc":[{"id":"1.187528277","rc":[{"batb":[[1,1.38,44.77]],"batl":[[0,1.42,3.06],[1,1.43,100],[2,1.44,527.02]],"ltp":1.38,"tv":3980.29,"id":2249229}]}]}
{"op":"mcm","clk":"4210314700","pt":1631333678156,"mc":[{"id":"1.187528277","rc":[{"batb":[[0,1.38,1391.5],[1,1.37,5.32],[2,1.36,56.67]],"batl":[[2,1.44,100]],"ltp":1.38,"tv":3980.29,"id":2249229}]}]}
{"op":"mcm","clk":"4210314801","pt":1631333680071,"mc":[{"id":"1.187528277","rc":[{"batb":[[2,1.33,472.29]],"ltp":1.38,"tv":3980.29,"id":2249229}]}]}
{"op":"mcm","clk":"4210315076","pt":1631333684351,"mc":[{"id":"1.187528277","rc":[{"batb":[[0,1.39,35.33],[1,1.38,1391.5],[2,1.37,5.32]],"ltp":1.38,"tv":3980.29,"id":2249229}]}]}
{"op":"mcm","clk":"4210315458","pt":1631333691499,"mc":[{"id":"1.187528277","rc":[{"batb":[[1,1.38,1427.75]],"ltp":1.38,"tv":3980.29,"id":2249229}]}]}
{"op":"mcm","clk":"4210315685","pt":1631333695683,"mc":[{"id":"1.187528277","rc":[{"batb":[[0,3.05,547.8],[1,3,10.2],[2,1.5,3615.07]],"batl":[[0,3.6,8.54]],"ltp":3.35,"tv":93.71,"id":19924831},{"batb":[[0,1.39,44.59],[1,1.38,81.02]],"ltp":1.38,"tv":3980.29,"id":2249229}]}]}
{"op":"mcm","clk":"4210315870","pt":1631333700125,"mc":[{"id":"1.187528277","rc":[{"batb":[[1,1.5,3615.07],[2,1.13,1897.69]],"ltp":3.35,"tv":93.71,"id":19924831}]}]}
{"op":"mcm","clk":"4210315996","pt":1631333701906,"mc":[{"id":"1.187528277","rc":[{"batb":[[1,1.38,99.15]],"ltp":1.38,"tv":3980.29,"id":2249229}]}]}
{"op":"mcm","clk":"4210352919","pt":1631334331469,"mc":[{"id":"1.187528277","rc":[{"trd":[[1.42,1358.3]],"batb":[[0,1.39,45.15]],"batl":[[0,1.43,100],[1,1.44,100],[2,1.45,26.59]],"ltp":1.42,"tv":3986.41,"id":2249229}],"tv":4080.12}]}
{"op":"mcm","clk":"4210353267","pt":1631334337976,"mc":[{"id":"1.187528277","rc":[{"batl":[[2,1.45,664.75]],"ltp":1.42,"tv":3986.41,"id":2249229}]}]}
{"op":"mcm","clk":"4210353469","pt":1631334341493,"mc":[{"id":"1.187528277","rc":[{"batl":[[2,1.45,26.59]],"ltp":1.42,"tv":3986.41,"id":2249229}]}]}
{"op":"mcm","clk":"4210355701","pt":1631334380157,"mc":[{"id":"1.187528277","rc":[{"batb":[[0,1.4,6.57],[1,1.39,44.59],[2,1.38,99.15]],"ltp":1.42,"tv":3986.41,"id":2249229}]}]}
{"op":"mcm","clk":"4210365447","pt":1631334565145,"mc":[{"id":"1.187528277","rc":[{"trd":[[1.4,12.02],[1.42,1359.41]],"batb":[[0,1.39,44.59],[1,1.38,99.15],[2,1.37,5.32]],"batl":[[0,1.4,6.73],[1,1.43,100],[2,1.44,100]],"ltp":1.4,"tv":3999.54,"id":2249229}],"tv":4093.25}]}
{"op":"mcm","clk":"4210365521","pt":1631334566636,"mc":[{"id":"1.187528277","rc":[{"batl":[[1,1.42,8.76],[2,1.43,100]],"ltp":1.4,"tv":3999.54,"id":2249229}]}]}
{"op":"mcm","clk":"4210365612","pt":1631334568133,"mc":[{"id":"1.187528277","rc":[{"batl":[[1,1.43,100],[2,1.44,100]],"ltp":1.4,"tv":3999.54,"id":2249229}]}]}
{"op":"mcm","clk":"4210366540","pt":1631334585681,"mc":[{"id":"1.187528277","rc":[{"trd":[[1.39,13.45]],"batb":[[0,1.39,37.86]],"batl":[[0,1.43,100],[1,1.44,100],[2,1.45,26.59]],"ltp":1.39,"tv":4013.0,"id":2249229}],"tv":4106.71}]}
{"op":"mcm","clk":"4210368172","pt":1631334614021,"mc":[{"id":"1.187528277","rc":[{"batl":[[0,1.42,6.06],[1,1.43,100],[2,1.44,100]],"ltp":1.39,"tv":4013.0,"id":2249229}]}]}
{"op":"mcm","clk":"4210370433","pt":1631334655109,"mc":[{"id":"1.187528277","rc":[{"batl":[[0,1.42,14.77]],"ltp":1.39,"tv":4013.0,"id":2249229}]}]}
{"op":"mcm","clk":"4210370527","pt":1631334656811,"mc":[{"id":"1.187528277","rc":[{"batl":[[0,1.42,6.06]],"ltp":1.39,"tv":4013.0,"id":2249229}]}]}
{"op":"mcm","clk":"4210375774","pt":1631334742571,"mc":[{"id":"1.187528277","rc":[{"batl":[[0,1.42,14.77]],"ltp":1.39,"tv":4013.0,"id":2249229}]}]}
{"op":"mcm","clk":"4210375858","pt":1631334744215,"mc":[{"id":"1.187528277","rc":[{"batl":[[0,1.42,6.06]],"ltp":1.39,"tv":4013.0,"id":2249229}]}]}
{"op":"mcm","clk":"4210376035","pt":1631334747991,"mc":[{"id":"1.187528277","rc":[{"batb":[[0,3.35,17.08]],"batl":[[0,3.55,17.08]],"ltp":3.35,"tv":93.71,"id":19924831},{"batb":[[0,1.39,96.79]],"batl":[[1,1.43,158.07]],"ltp":1.39,"tv":4013.0,"id":2249229}]}]}
{"op":"mcm","clk":"4210376176","pt":1631334750407,"mc":[{"id":"1.187528277","rc":[{"batb":[[1,3,10.2],[2,1.5,3615.07]],"ltp":3.35,"tv":93.71,"id":19924831}]}]}
{"op":"mcm","clk":"4210376944","pt":1631334765439,"mc":[{"id":"1.187528277","rc":[{"trd":[[3.55,16.94]],"batl":[[0,3.55,0.14]],"ltp":3.55,"tv":110.65,"id":19924831},{"trd":[[1.39,250.31]],"batb":[[0,1.38,1749.7],[1,1.37,5.32],[2,1.36,56.67]],"ltp":1.39,"tv":4249.85,"id":2249229}],"tv":4360.51}]}
{"op":"mcm","clk":"4210377006","pt":1631334766624,"mc":[{"id":"1.187528277","rc":[{"batl":[[0,3.6,8.68]],"ltp":3.55,"tv":110.65,"id":19924831},{"batl":[[0,1.42,15.13]],"ltp":1.39,"tv":4249.85,"id":2249229}]}]}
{"op":"mcm","clk":"4210377052","pt":1631334767343,"mc":[{"id":"1.187528277","rc":[{"batb":[[0,3.35,43.56]],"batl":[[0,3.6,8.54],[1,3.65,26.48]],"ltp":3.55,"tv":110.65,"id":19924831},{"batb":[[0,1.38,1800.95]],"batl":[[0,1.41,50.39],[1,1.42,15.13],[2,1.43,100]],"ltp":1.39,"tv":4249.85,"id":2249229}]}]}
{"op":"mcm","clk":"4210377172","pt":1631334770054,"mc":[{"id":"1.187528277","rc":[{"batb":[[2,1.33,472.29]],"ltp":1.39,"tv":4249.85,"id":2249229}]}]}
{"op":"mcm","clk":"4210379533","pt":1631334816633,"mc":[{"id":"1.187528277","rc":[{"batb":[[0,3,10.2],[1,1.5,3615.07],[2,1.13,1897.69]],"ltp":3.55,"tv":110.65,"id":19924831}]}]}
{"op":"mcm","clk":"4210379586","pt":1631334817665,"mc":[{"id":"1.187528277","rc":[{"batb":[[0,3.45,17.93],[1,3,10.2],[2,1.5,3615.07]],"ltp":3.55,"tv":110.65,"id":19924831},{"batl":[[1,1.42,6.06]],"ltp":1.39,"tv":4249.85,"id":2249229}]}]}
{"op":"mcm","clk":"4210379603","pt":1631334817974,"mc":[{"id":"1.187528277","rc":[{"trd":[[3.5,3.68]],"ltp":3.5,"tv":114.33,"id":19924831},{"trd":[[1.4,21.22]],"ltp":1.4,"tv":4259.05,"id":2249229}],"tv":4373.39}]}
{"op":"mcm","clk":"4210379687","pt":1631334819466,"mc":[{"id":"1.187528277","rc":[{"batb":[[0,1.39,16.16],[1,1.38,1800.95],[2,1.37,5.32]],"ltp":1.4,"tv":4259.05,"id":2249229}]}]}
{"op":"mcm","clk":"4210379733","pt":1631334820243,"mc":[{"id":"1.187528277","rc":[{"batb":[[1,1.5,3615.07],[2,1.13,1897.69]],"ltp":3.5,"tv":114.33,"id":19924831}]}]}
{"op":"mcm","clk":"4210379777","pt":1631334820969,"mc":[{"id":"1.187528277","marketDefinition":{"bspMarket":false,"turnInPlayEnabled":true,"persistenceEnabled":true,"marketBaseRate":5.0,"eventId":"30891863","eventTypeId":"2","numberOfWinners":1,"bettingType":"ODDS","marketType":"MATCH_ODDS","marketTime":"2021-09-12T20:00:00.000Z","suspendTime":"2021-09-12T20:00:00.000Z","bspReconciled":false,"complete":true,"inPlay":false,"crossMatching":true,"runnersVoidable":false,"numberOfActiveRunners":2,"betDelay":0,"status":"OPEN","runners":[{"status":"ACTIVE","sortPriority":1,"id":2249229,"name":"Novak Djokovic"},{"status":"ACTIVE","sortPriority":2,"id":19924831,"name":"Daniil Medvedev"}],"regulators":["MR_INT"],"countryCode":"US","discountAllowed":true,"timezone":"UTC","openDate":"2021-09-12T15:00:00.000Z","version":4023449846,"name":"Match Odds","eventName":"Djokovic v Medvedev"}}]}
{"op":"mcm","clk":"4210380045","pt":1631334824468,"mc":[{"id":"1.187528277","marketDefinition":{"bspMarket":false,"turnInPlayEnabled":true,"persistenceEnabled":true,"marketBaseRate":5.0,"eventId":"30891863","eventTypeId":"2","numberOfWinners":1,"bettingType":"ODDS","marketType":"MATCH_ODDS","marketTime":"2021-09-12T20:00:00.000Z","suspendTime":"2021-09-12T20:00:00.000Z","bspReconciled":false,"complete":true,"inPlay":false,"crossMatching":true,"runnersVoidable":false,"numberOfActiveRunners":2,"betDelay":0,"status":"OPEN","runners":[{"status":"ACTIVE","sortPriority":1,"id":2249229,"name":"Novak Djokovic"},{"status":"ACTIVE","sortPriority":2,"id":19924831,"name":"Daniil Medvedev"}],"regulators":["MR_INT"],"countryCode":"US","discountAllowed":true,"timezone":"Europe/London","openDate":"2021-09-12T20:00:00.000Z","version":4023449846,"name":"Match Odds","eventName":"Djokovic @ Medvedev"}}]}
{"op":"mcm","clk":"4210380478","pt":1631334833383,"mc":[{"id":"1.187528277","rc":[{"batb":[[1,1.38,150.4]],"ltp":1.4,"tv":4259.05,"id":2249229}]}]}
{"op":"mcm","clk":"4210380518","pt":1631334834203,"mc":[{"id":"1.187528277","rc":[{"batl":[[0,3.65,26.48],[1,3.65,0]],"ltp":3.5,"tv":114.33,"id":19924831}]}]}
{"op":"mcm","clk":"4210384557","pt":1631334912933,"mc":[{"id":"1.187528277","rc":[{"batb":[[0,1.4,170.81],[1,1.39,16.16],[2,1.38,150.4]],"ltp":1.4,"tv":4259.05,"id":2249229}]}]}
{"op":"mcm","clk":"4210384619","pt":1631334914222,"mc":[{"id":"1.187528277","rc":[{"batb":[[1,1.38,150.4],[2,1.37,5.32]],"ltp":1.4,"tv":4259.05,"id":2249229}]}]}
{"op":"mcm","clk":"4210386768","pt":1631334957704,"mc":[{"id":"1.187528277","rc":[{"trd":[[3.45,17.87]],"batb":[[0,1.5,3615.14],[1,1.13,1897.69],[2,1.12,1897.69]],"ltp":3.45,"tv":132.2,"id":19924831},{"trd":[[1.41,144.5]],"batl":[[0,1.42,6.06],[1,1.43,100],[2,1.44,100]],"ltp":1.41,"tv":4403.55,"id":2249229}],"tv":4535.75}]}
{"op":"mcm","clk":"4210386811","pt":1631334958582,"mc":[{"id":"1.187528277","rc":[{"trd":[[3.45,17.93]],"batb":[[0,2.42,692.94],[1,1.5,3615.07],[2,1.13,1897.69]],"ltp":3.45,"tv":132.27,"id":19924831},{"trd":[[1.41,144.67]],"batb":[[0,1.41,10.47],[1,1.4,170.81],[2,1.38,150.4]],"batl":[[0,1.42,14.86]],"ltp":1.41,"tv":4403.72,"id":2249229}],"tv":4535.99}]}
{"op":"mcm","clk":"4210386866","pt":1631334959710,"mc":[{"id":"1.187528277","rc":[{"batl":[[0,1.42,6.06]],"ltp":1.41,"tv":4403.72,"id":2249229}]}]}
{"op":"mcm","clk":"4210386922","pt":1631334960694,"mc":[{"id":"1.187528277","rc":[{"batb":[[0,3,10.2],[1,2.42,692.94],[2,1.5,3615.07]],"ltp":3.45,"tv":132.27,"id":19924831}]}]}
{"op":"mcm","clk":"4210387296","pt":1631334967425,"mc":[{"id":"1.187528277","rc":[{"batb":[[0,3.35,27.33],[1,3,10.2]],"batl":[[0,3.55,24.77]],"ltp":3.45,"tv":132.27,"id":19924831},{"batb":[[2,1.39,68.32]],"batl":[[1,1.43,167.47]],"ltp":1.41,"tv":4403.72,"id":2249229}]}]}
{"op":"mcm","clk":"4210387488","pt":1631334970823,"mc":[{"id":"1.187528277","rc":[{"batb":[[1,1.5,3615.07],[2,1.13,1897.69]],"ltp":3.45,"tv":132.27,"id":19924831}]}]}
{"op":"mcm","clk":"4210390250","pt":1631335025144,"mc":[{"id":"1.187528277","rc":[{"batb":[[0,1.41,138.58]],"ltp":1.41,"tv":4403.72,"id":2249229}]}]}
{"op":"mcm","clk":"4210417691","pt":1631335598869,"mc":[{"id":"1.187528277","rc":[{"batl":[[1,9.8,224.27]],"ltp":3.45,"tv":132.27,"id":19924831}]}]}
{"op":"mcm","clk":"4210424214","pt":1631335716368,"mc":[{"id":"1.187528277","rc":[{"trd":[[3.35,102.74]],"batb":[[0,2.64,640.1]],"ltp":3.35,"tv":229.69,"id":19924831},{"trd":[[1.42,1365.47]],"batl":[[0,1.43,167.47],[1,1.44,100],[2,1.45,1174.81]],"ltp":1.42,"tv":4409.78,"id":2249229}],"tv":4639.47}]}
{"op":"mcm","clk":"4210424393","pt":1631335719273,"mc":[{"id":"1.187528277","rc":[{"batb":[[0,3,10.2],[1,2.64,640.1],[2,1.5,3615.07]],"ltp":3.35,"tv":229.69,"id":19924831}]}]}
{"op":"mcm","clk":"4210425014","pt":1631335731664,"mc":[{"id":"1.187528277","rc":[{"batb":[[1,1.5,3615.07],[2,1.13,1897.69]],"ltp":3.35,"tv":229.69,"id":19924831}]}]}
{"op":"mcm","clk":"4210425022","pt":1631335731765,"mc":[{"id":"1.187528277","rc":[{"batb":[[0,3.05,553.56],[1,3,10.2],[2,1.5,3615.07]],"ltp":3.35,"tv":229.69,"id":19924831}]}]}
{"op":"mcm","clk":"4210425155","pt":1631335734394,"mc":[{"id":"1.187528277","rc":[{"batb":[[1,1.5,3615.07],[2,1.13,1897.69]],"ltp":3.35,"tv":229.69,"id":19924831}]}]}
{"op":"mcm","clk":"4210429823","pt":1631335816652,"mc":[{"id":"1.187528277","rc":[{"batl":[[0,9.8,224.27],[1,9.8,0]],"ltp":3.35,"tv":229.69,"id":19924831},{"batb":[[2,1.38,99.15]],"batl":[[0,1.43,100]],"ltp":1.42,"tv":4409.78,"id":2249229}]}]}
{"op":"mcm","clk":"4210429883","pt":1631335817427,"mc":[{"id":"1.187528277","rc":[{"batb":[[0,3.3,26.48]],"batl":[[0,3.5,23.91],[1,9.8,224.27]],"ltp":3.35,"tv":229.69,"id":19924831},{"batb":[[1,1.4,231.45]],"batl":[[1,1.44,170.03]],"ltp":1.42,"tv":4409.78,"id":2249229}]}]}
{"op":"mcm","clk":"4210429917","pt":1631335818044,"mc":[{"id":"1.187528277","rc":[{"batl":[[0,3.45,8.54],[1,3.5,23.91],[2,9.8,224.27]],"ltp":3.35,"tv":229.69,"id":19924831}]}]}
{"op":"mcm","clk":"4210430020","pt":1631335819639,"mc":[{"id":"1.187528277","rc":[{"batb":[[1,3,10.2],[2,1.5,3615.07]],"ltp":3.35,"tv":229.69,"id":19924831}]}]}
{"op":"mcm","clk":"4210439441","pt":1631336008958,"mc":[{"id":"1.187528277","rc":[{"batb":[[0,1.42,2],[1,1.41,138.58],[2,1.4,231.45]],"ltp":1.42,"tv":4409.78,"id":2249229}]}]}
{"op":"mcm","clk":"4210440354","pt":1631336027500,"mc":[{"id":"1.187528277","rc":[{"batb":[[2,1.5,3617.07]],"ltp":3.35,"tv":229.69,"id":19924831}]}]}
{"op":"mcm","clk":"4210457088","pt":1631336339266,"mc":[{"id":"1.187528277","rc":[{"batl":[[0,1.43,300.27]],"ltp":1.42,"tv":4409.78,"id":2249229}]}]}
{"op":"mcm","clk":"4210462113","pt":1631336414280,"mc":[{"id":"1.187528277","rc":[{"batb":[[0,3.3,42.98]],"ltp":3.35,"tv":229.69,"id":19924831},{"batb":[[2,1.4,264.7]],"ltp":1.42,"tv":4409.78,"id":2249229}]}]}
{"op":"mcm","clk":"4210464932","pt":1631336452270,"mc":[{"id":"1.187528277","rc":[{"trd":[[1.43,1425.42]],"batl":[[0,1.43,296.65]],"ltp":1.43,"tv":4417.01,"id":2249229}],"tv":4646.71}]}
{"op":"mcm","clk":"4210465128","pt":1631336454968,"mc":[{"id":"1.187528277","rc":[{"batb":[[0,1.42,5.62]],"ltp":1.43,"tv":4417.01,"id":2249229}]}]}
{"op":"mcm","clk":"4210470273","pt":1631336534889,"mc":[{"id":"1.187528277","rc":[{"batl":[[0,3.45,158.54]],"ltp":3.35,"tv":229.69,"id":19924831}]}]}
{"op":"mcm","clk":"4210502489","pt":1631337120672,"mc":[{"id":"1.187528277","rc":[{"trd":[[1.42,1376.71]],"batb":[[0,1.41,138.58],[1,1.4,264.7],[2,1.39,200.27]],"batl":[[0,1.42,154.89],[1,1.43,296.65],[2,1.44,170.03]],"ltp":1.42,"tv":4428.24,"id":2249229}],"tv":4657.94}]}
{"op":"mcm","clk":"4210503849","pt":1631337144596,"mc":[{"id":"1.187528277","rc":[{"trd":[[3.35,168.4]],"batl":[[0,3.35,19.75],[1,3.45,158.54],[2,3.5,23.91]],"ltp":3.35,"tv":295.35,"id":19924831},{"trd":[[1.42,1531.6]],"batl":[[0,1.43,296.65],[1,1.44,170.03],[2,1.45,1174.81]],"ltp":1.42,"tv":4583.14,"id":2249229}],"tv":4878.49}]}
{"op":"mcm","clk":"4210506343","pt":1631337184820,"mc":[{"id":"1.187528277","rc":[{"trd":[[3.35,207.89]],"batb":[[0,3.35,60.51],[1,3.3,42.98],[2,3,10.2]],"batl":[[0,3.45,158.54],[1,3.5,23.91],[2,9.8,224.27]],"ltp":3.35,"tv":334.84,"id":19924831}],"tv":4917.98}]}
{"op":"mcm","clk":"4210506409","pt":1631337186536,"mc":[{"id":"1.187528277","rc":[{"batb":[[2,1.5,3617.07]],"ltp":3.35,"tv":334.84,"id":19924831}]}]}
{"op":"mcm","clk":"4210508373","pt":1631337227775,"mc":[{"id":"1.187528277","rc":[{"trd":[[3.35,243.07]],"batb":[[0,3.35,42.92]],"ltp":3.35,"tv":370.02,"id":19924831}],"tv":4953.16}]}
{"op":"mcm","clk":"4210518368","pt":1631337435059,"mc":[{"id":"1.187528277","rc":[{"batl":[[0,1.42,343.54],[1,1.43,296.65],[2,1.44,170.03]],"ltp":1.42,"tv":4583.14,"id":2249229}]}]}
{"op":"mcm","clk":"4210540449","pt":1631337586007,"mc":[{"id":"1.187528277","rc":[{"batl":[[0,1.42,350.43]],"ltp":1.42,"tv":4583.14,"id":2249229}]}]}
{"op":"mcm","clk":"4210540507","pt":1631337587244,"mc":[{"id":"1.187528277","rc":[{"batl":[[0,1.42,357.32]],"ltp":1.42,"tv":4583.14,"id":2249229}]}]}
{"op":"mcm","clk":"4210540894","pt":1631337595757,"mc":[{"id":"1.187528277","rc":[{"batl":[[0,1.42,343.54]],"ltp":1.42,"tv":4583.14,"id":2249229}]}]}
{"op":"mcm","clk":"4210541842","pt":1631337615278,"mc":[{"id":"1.187528277","rc":[{"batl":[[0,1.42,350.43]],"ltp":1.42,"tv":4583.14,"id":2249229}]}]}
{"op":"mcm","clk":"4210541962","pt":1631337617754,"mc":[{"id":"1.187528277","rc":[{"batl":[[0,1.42,343.54]],"ltp":1.42,"tv":4583.14,"id":2249229}]}]}
{"op":"mcm","clk":"4210542042","pt":1631337619557,"mc":[{"id":"1.187528277","rc":[{"trd":[[1.41,158.45]],"batb":[[0,1.41,131.69]],"ltp":1.41,"tv":4596.92,"id":2249229}],"tv":4966.94}]}
{"op":"mcm","clk":"4210542325","pt":1631337624767,"mc":[{"id":"1.187528277","rc":[{"batl":[[0,1.42,350.43]],"ltp":1.41,"tv":4596.92,"id":2249229}]}]}
{"op":"mcm","clk":"4210542512","pt":1631337628475,"mc":[{"id":"1.187528277","rc":[{"trd":[[1.41,172.23]],"batb":[[0,1.41,124.79]],"ltp":1.41,"tv":4610.7,"id":2249229}],"tv":4980.72}]}
{"op":"mcm","clk":"4210542585","pt":1631337629567,"mc":[{"id":"1.187528277","rc":[{"batl":[[0,1.42,361]],"ltp":1.41,"tv":4610.7,"id":2249229}]}]}
{"op":"mcm","clk":"4210543361","pt":1631337645655,"mc":[{"id":"1.187528277","rc":[{"batl":[[0,1.42,354.11]],"ltp":1.41,"tv":4610.7,"id":2249229}]}]}
{"op":"mcm","clk":"4210558366","pt":1631337943119,"mc":[{"id":"1.187528277","rc":[{"batl":[[0,1.42,247.22]],"ltp":1.41,"tv":4610.7,"id":2249229}]}]}
{"op":"mcm","clk":"4210573272","pt":1631338197033,"mc":[{"id":"1.187528277","rc":[{"trd":[[1.41,225.4]],"batb":[[0,1.41,98.21]],"ltp":1.41,"tv":4663.87,"id":2249229}],"tv":5033.9}]}
{"op":"mcm","clk":"4210577044","pt":1631338252855,"mc":[{"id":"1.187528277","rc":[{"trd":[[1.42,1571.6]],"batl":[[0,1.42,227.22]],"ltp":1.42,"tv":4703.87,"id":2249229}],"tv":5073.9}]}
{"op":"mcm","clk":"4210586730","pt":1631338412458,"mc":[{"id":"1.187528277","rc":[{"batl":[[0,1.42,247.22]],"ltp":1.42,"tv":4703.87,"id":2249229}]}]}
{"op":"mcm","clk":"4210597260","pt":1631338616235,"mc":[{"id":"1.187528277","rc":[{"batl":[[0,1.42,131.08]],"ltp":1.42,"tv":4703.87,"id":2249229}]}]}
{"op":"mcm","clk":"4210602210","pt":1631338710854,"mc":[{"id":"1.187528277","rc":[{"batb":[[0,3.4,35.03],[1,3.35,42.92],[2,3.3,42.98]],"ltp":3.35,"tv":370.02,"id":19924831},{"batl":[[0,1.42,214.96]],"ltp":1.42,"tv":4703.87,"id":2249229}]}]}
{"op":"mcm","clk":"4210602524","pt":1631338717377,"mc":[{"id":"1.187528277","rc":[{"batl":[[0,1.42,415.23],[1,1.43,96.38]],"ltp":1.42,"tv":4703.87,"id":2249229}]}]}
{"op":"mcm","clk":"4210603053","pt":1631338729574,"mc":[{"id":"1.187528277","rc":[{"batl":[[0,1.42,214.96],[1,1.43,296.65]],"ltp":1.42,"tv":4703.87,"id":2249229}]}]}
{"op":"mcm","clk":"4210603958","pt":1631338749629,"mc":[{"id":"1.187528277","rc":[{"trd":[[1.41,421.1]],"batb":[[0,1.4,265.06],[1,1.39,200.27],[2,1.38,81.02]],"ltp":1.41,"tv":4899.57,"id":2249229}],"tv":5269.6}]}
{"op":"mcm","clk":"4210606440","pt":1631338803704,"mc":[{"id":"1.187528277","rc":[{"batl":[[0,1.42,415.23],[1,1.43,96.38]],"ltp":1.41,"tv":4899.57,"id":2249229}]}]}
{"op":"mcm","clk":"4210607531","pt":1631338826701,"mc":[{"id":"1.187528277","rc":[{"batb":[[2,3.3,33.58]],"batl":[[1,9.8,224.27],[2,9.8,0]],"ltp":3.35,"tv":370.02,"id":19924831},{"batl":[[2,1.44,159.78]],"ltp":1.41,"tv":4899.57,"id":2249229}]}]}
{"op":"mcm","clk":"4210607544","pt":1631338826866,"mc":[{"id":"1.187528277","rc":[{"batl":[[0,3.45,175.62]],"ltp":3.35,"tv":370.02,"id":19924831},{"batb":[[0,1.4,282.14]],"ltp":1.41,"tv":4899.57,"id":2249229}]}]}
{"op":"mcm","clk":"4210607625","pt":1631338828708,"mc":[{"id":"1.187528277","rc":[{"batb":[[2,3.3,41.27]],"ltp":3.35,"tv":370.02,"id":19924831},{"batb":[[0,1.4,273.6]],"batl":[[2,1.44,167.47]],"ltp":1.41,"tv":4899.57,"id":2249229}]}]}
{"op":"mcm","clk":"4210612104","pt":1631338921214,"mc":[{"id":"1.187528277","rc":[{"trd":[[3.4,70.06]],"batb":[[0,3.35,76.48],[1,3.3,41.27],[2,1.5,3617.07]],"batl":[[0,3.4,18.15],[1,3.45,175.62],[2,9.8,224.27]],"ltp":3.4,"tv":440.08,"id":19924831},{"batb":[[0,1.41,80.1],[1,1.4,273.24],[2,1.39,200.27]],"ltp":1.41,"tv":4899.57,"id":2249229}],"tv":5339.66}]}
{"op":"mcm","clk":"4210617488","pt":1631339034705,"mc":[{"id":"1.187528277","rc":[{"batb":[[1,1.4,339.35]],"ltp":1.41,"tv":4899.57,"id":2249229}]}]}
{"op":"mcm","clk":"4210617516","pt":1631339035277,"mc":[{"id":"1.187528277","rc":[{"batb":[[0,1.41,98.68]],"batl":[[0,1.42,469.76]],"ltp":1.41,"tv":4899.57,"id":2249229}]}]}
{"op":"mcm","clk":"4210617560","pt":1631339036350,"mc":[{"id":"1.187528277","rc":[{"batb":[[0,3.35,108.77],[1,3.3,53.72]],"ltp":3.4,"tv":440.08,"id":19924831},{"batl":[[1,1.43,137.71]],"ltp":1.41,"tv":4899.57,"id":2249229}]}]}
{"op":"mcm","clk":"4210617579","pt":1631339036762,"mc":[{"id":"1.187528277","rc":[{"batl":[[1,3.45,206.33]],"ltp":3.4,"tv":440.08,"id":19924831}]}]}
{"op":"mcm","clk":"4210619412","pt":1631339079675,"mc":[{"id":"1.187528277","rc":[{"trd":[[3.35,588.32]],"batb":[[0,3.3,53.72],[1,1.5,3617.07],[2,1.13,1897.69]],"ltp":3.35,"tv":785.33,"id":19924831},{"trd":[[1.42,1872.87]],"batl":[[0,1.42,168.49]],"ltp":1.42,"tv":5200.84,"id":2249229}],"tv":5986.18}]}
{"op":"mcm","clk":"4210619419","pt":1631339079778,"mc":[{"id":"1.187528277","rc":[{"batb":[[0,3.35,20.7],[1,3.3,53.72],[2,1.5,3617.07]],"batl":[[0,3.4,56.17]],"ltp":3.35,"tv":785.33,"id":19924831}]}]}
{"op":"mcm","clk":"4210619950","pt":1631339092709,"mc":[{"id":"1.187528277","rc":[{"batl":[[0,1.42,54.53]],"ltp":1.42,"tv":5200.84,"id":2249229}]}]}
{"op":"mcm","clk":"4210620339","pt":1631339101197,"mc":[{"id":"1.187528277","rc":[{"batb":[[0,1.41,184.99]],"ltp":1.42,"tv":5200.84,"id":2249229}]}]}
{"op":"mcm","clk":"4210620615","pt":1631339106625,"mc":[{"id":"1.187528277","rc":[{"trd":[[1.42,1981.93]],"batb":[[0,1.42,78.8],[1,1.41,98.68],[2,1.4,339.35]],"batl":[[0,1.43,186.21],[1,1.44,167.47],[2,1.45,1174.81]],"ltp":1.42,"tv":5309.9,"id":2249229}],"tv":6095.24}]}
{"op":"mcm","clk":"4210620673","pt":1631339108127,"mc":[{"id":"1.187528277","rc":[{"trd":[[3.4,117.39]],"batl":[[0,3.4,32.51],[1,3.45,197.79]],"ltp":3.4,"tv":832.65,"id":19924831}],"tv":6142.56}]}
{"op":"mcm","clk":"4210620791","pt":1631339110602,"mc":[{"id":"1.187528277","rc":[{"batl":[[0,3.4,41.05]],"ltp":3.4,"tv":832.65,"id":19924831}]}]}
{"op":"mcm","clk":"4210621052","pt":1631339116633,"mc":[{"id":"1.187528277","rc":[{"batb":[[1,1.41,109.75],[2,1.4,273.24]],"batl":[[0,1.43,439.27]],"ltp":1.42,"tv":5309.9,"id":2249229}]}]}
{"op":"mcm","clk":"4210621106","pt":1631339117714,"mc":[{"id":"1.187528277","rc":[{"batb":[[1,3.3,61.43]],"ltp":3.4,"tv":832.65,"id":19924831},{"batb":[[0,1.42,43.61]],"batl":[[1,1.44,211.06]],"ltp":1.42,"tv":5309.9,"id":2249229}]}]}
{"op":"mcm","clk":"4210621131","pt":1631339118533,"mc":[{"id":"1.187528277","rc":[{"batb":[[0,3.35,23.81]],"batl":[[0,3.4,52.14]],"ltp":3.4,"tv":832.65,"id":19924831}]}]}
{"op":"mcm","clk":"4210621146","pt":1631339118842,"mc":[{"id":"1.187528277","rc":[{"batl":[[1,3.45,202.8]],"ltp":3.4,"tv":832.65,"id":19924831}]}]}
{"op":"mcm","clk":"4210624847","pt":1631339195711,"mc":[{"id":"1.187528277","rc":[{"batb":[[1,1.41,115.42]],"batl":[[0,1.43,472.19],[1,1.44,220.25]],"ltp":1.42,"tv":5309.9,"id":2249229}]}]}
{"op":"mcm","clk":"4210624861","pt":1631339196021,"mc":[{"id":"1.187528277","rc":[{"batb":[[1,3.3,79.04]],"ltp":3.4,"tv":832.65,"id":19924831}]}]}
{"op":"mcm","clk":"4210628053","pt":1631339261710,"mc":[{"id":"1.187528277","rc":[{"batl":[[1,1.44,227.67]],"ltp":1.42,"tv":5309.9,"id":2249229}]}]}
{"op":"mcm","clk":"4210628672","pt":1631339274621,"mc":[{"id":"1.187528277","rc":[{"batl":[[0,1.43,219.14]],"ltp":1.42,"tv":5309.9,"id":2249229}]}]}
{"op":"mcm","clk":"4210631257","pt":1631339327654,"mc":[{"id":"1.187528277","rc":[{"batb":[[1,3.3,67.37]],"ltp":3.4,"tv":832.65,"id":19924831},{"batb":[[0,1.42,106.63]],"batl":[[0,1.43,186.21]],"ltp":1.42,"tv":5309.9,"id":2249229}]}]}
{"op":"mcm","clk":"4210635590","pt":1631339415508,"mc":[{"id":"1.187528277","rc":[{"batl":[[0,3.4,55.55]],"ltp":3.4,"tv":832.65,"id":19924831}]}]}
{"op":"mcm","clk":"4210645605","pt":1631339613926,"mc":[{"id":"1.187528277","rc":[{"trd":[[1.43,1470.52]],"batl":[[0,1.43,163.66]],"ltp":1.43,"tv":5355.0,"id":2249229}],"tv":6187.66}]}
{"op":"mcm","clk":"4210646573","pt":1631339637124,"mc":[{"id":"1.187528277","rc":[{"batb":[[1,3.3,61.43]],"ltp":3.4,"tv":832.65,"id":19924831}]}]}
{"op":"mcm","clk":"4210648909","pt":1631339685320,"mc":[{"id":"1.187528277","rc":[{"batl":[[0,3.4,23.04]],"ltp":3.4,"tv":832.65,"id":19924831},{"trd":[[1.42,2195.18]],"batb":[[0,1.41,123.94],[1,1.4,273.24],[2,1.39,200.27]],"batl":[[0,1.42,651.1],[1,1.43,163.66],[2,1.44,227.67]],"ltp":1.42,"tv":5568.25,"id":2249229}],"tv":6400.91}]}
{"op":"mcm","clk":"4210648931","pt":1631339685934,"mc":[{"id":"1.187528277","rc":[{"batl":[[0,3.4,14.5]],"ltp":3.4,"tv":832.65,"id":19924831}]}]}
{"op":"mcm","clk":"4210648988","pt":1631339687436,"mc":[{"id":"1.187528277","rc":[{"batl":[[0,3.4,49.17]],"ltp":3.4,"tv":832.65,"id":19924831},{"batl":[[0,1.43,163.66],[1,1.44,227.67],[2,1.45,1174.81]],"ltp":1.42,"tv":5568.25,"id":2249229}]}]}
{"op":"mcm","clk":"4210649028","pt":1631339688215,"mc":[{"id":"1.187528277","rc":[{"batl":[[0,3.4,57.71]],"ltp":3.4,"tv":832.65,"id":19924831}]}]}
{"op":"mcm","clk":"4210649520","pt":1631339700554,"mc":[{"id":"1.187528277","rc":[{"batb":[[1,1.4,339.35]],"ltp":1.42,"tv":5568.25,"id":2249229}]}]}
{"op":"mcm","clk":"4210649568","pt":1631339701665,"mc":[{"id":"1.187528277","rc":[{"batl":[[0,3.4,54.3]],"ltp":3.4,"tv":832.65,"id":19924831},{"batb":[[0,1.41,128.08]],"ltp":1.42,"tv":5568.25,"id":2249229}]}]}
{"op":"mcm","clk":"4210652266","pt":1631339746738,"mc":[{"id":"1.187528277","rc":[{"batb":[[0,3.35,43.81]],"ltp":3.4,"tv":832.65,"id":19924831}]}]}
{"op":"mcm","clk":"4210652436","pt":1631339749841,"mc":[{"id":"1.187528277","rc":[{"batb":[[0,3.35,47.27]],"ltp":3.4,"tv":832.65,"id":19924831}]}]}
{"op":"mcm","clk":"4210656876","pt":1631339839834,"mc":[{"id":"1.187528277","rc":[{"batl":[[0,1.43,270.02]],"ltp":1.42,"tv":5568.25,"id":2249229}]}]}
{"op":"mcm","clk":"4210657417","pt":1631339849720,"mc":[{"id":"1.187528277","rc":[{"batl":[[0,1.43,285.81]],"ltp":1.42,"tv":5568.25,"id":2249229}]}]}
{"op":"mcm","clk":"4210657456","pt":1631339850128,"mc":[{"id":"1.187528277","rc":[{"batb":[[1,3.3,68.03]],"ltp":3.4,"tv":832.65,"id":19924831}]}]}
{"op":"mcm","clk":"4210661135","pt":1631339930202,"mc":[{"id":"1.187528277","marketDefinition":{"bspMarket":false,"turnInPlayEnabled":true,"persistenceEnabled":true,"marketBaseRate":5.0,"eventId":"30891863","eventTypeId":"2","numberOfWinners":1,"bettingType":"ODDS","marketType":"MATCH_ODDS","marketTime":"2021-09-12T20:00:00.000Z","suspendTime":"2021-09-12T20:00:00.000Z","bspReconciled":false,"complete":true,"inPlay":false,"crossMatching":true,"runnersVoidable":false,"numberOfActiveRunners":2,"betDelay":0,"status":"SUSPENDED","runners":[{"status":"ACTIVE","sortPriority":1,"id":2249229,"name":"Novak Djokovic"},{"status":"ACTIVE","sortPriority":2,"id":19924831,"name":"Daniil Medvedev"}],"regulators":["MR_INT"],"discountAllowed":true,"timezone":"Europe/London","openDate":"2021-09-12T20:00:00.000Z","version":4023467671,"name":"Match Odds","eventName":"Djokovic v Medvedev"},"rc":[{"batb":[[0,3.35,26.57]],"batl":[[0,3.4,19.63]],"ltp":3.4,"tv":832.65,"id":19924831},{"batb":[[0,1.41,39.82]],"batl":[[0,1.43,237.31]],"ltp":1.42,"tv":5568.25,"id":2249229}]}]}
{"op":"mcm","clk":"4210661520","pt":1631339939435,"mc":[{"id":"1.187528277","marketDefinition":{"bspMarket":false,"turnInPlayEnabled":true,"persistenceEnabled":true,"marketBaseRate":5.0,"eventId":"30891863","eventTypeId":"2","numberOfWinners":1,"bettingType":"ODDS","marketType":"MATCH_ODDS","marketTime":"2021-09-12T20:00:00.000Z","suspendTime":"2021-09-12T20:00:00.000Z","bspReconciled":false,"complete":true,"inPlay":false,"crossMatching":true,"runnersVoidable":false,"numberOfActiveRunners":2,"betDelay":0,"status":"OPEN","runners":[{"status":"ACTIVE","sortPriority":1,"id":2249229,"name":"Novak Djokovic"},{"status":"ACTIVE","sortPriority":2,"id":19924831,"name":"Daniil Medvedev"}],"regulators":["MR_INT"],"discountAllowed":true,"timezone":"Europe/London","openDate":"2021-09-12T20:00:00.000Z","version":4023468035,"name":"Match Odds","eventName":"Djokovic v Medvedev"},"rc":[{"batb":[[0,3.35,64.35]],"ltp":3.4,"tv":832.65,"id":19924831},{"batb":[[0,1.41,129.59]],"batl":[[0,1.43,325.83]],"ltp":1.42,"tv":5568.25,"id":2249229}]}]}
{"op":"mcm","clk":"4210662392","pt":1631339956458,"mc":[{"id":"1.187528277","rc":[{"batb":[[0,1.41,125.45]],"ltp":1.42,"tv":5568.25,"id":2249229}]}]}
{"op":"mcm","clk":"4210662453","pt":1631339957437,"mc":[{"id":"1.187528277","rc":[{"batb":[[1,3.3,72.65]],"ltp":3.4,"tv":832.65,"id":19924831},{"batl":[[0,1.43,340.2]],"ltp":1.42,"tv":5568.25,"id":2249229}]}]}
{"op":"mcm","clk":"4210662486","pt":1631339957953,"mc":[{"id":"1.187528277","rc":[{"batl":[[0,3.4,11.49]],"ltp":3.4,"tv":832.65,"id":19924831}]}]}
{"op":"mcm","clk":"4210666282","pt":1631340014805,"mc":[{"id":"1.187528277","rc":[{"batb":[[0,1.41,119.78]],"ltp":1.42,"tv":5568.25,"id":2249229}]}]}
{"op":"mcm","clk":"4210673711","pt":1631340116117,"mc":[{"id":"1.187528277","rc":[{"batl":[[1,1.44,355.78]],"ltp":1.42,"tv":5568.25,"id":2249229}]}]}
{"op":"mcm","clk":"4210675089","pt":1631340134507,"mc":[{"id":"1.187528277","rc":[{"batl":[[1,1.44,361.68]],"ltp":1.42,"tv":5568.25,"id":2249229}]}]}
{"op":"mcm","clk":"4210681409","pt":1631340216875,"mc":[{"id":"1.187528277","rc":[{"batb":[[2,1.38,81.02]],"ltp":1.42,"tv":5568.25,"id":2249229}]}]}
{"op":"mcm","clk":"4210682760","pt":1631340236003,"mc":[{"id":"1.187528277","rc":[{"trd":[[1.41,424.56]],"batb":[[0,1.41,118.05]],"ltp":1.41,"tv":5571.7,"id":2249229}],"tv":6404.36}]}
{"op":"mcm","clk":"4210694698","pt":1631340411826,"mc":[{"id":"1.187528277","rc":[{"trd":[[3.35,598.32]],"batb":[[0,3.35,59.36]],"ltp":3.35,"tv":842.65,"id":19924831}],"tv":6414.36}]}
{"op":"mcm","clk":"4210705050","pt":1631340554518,"mc":[{"id":"1.187528277","rc":[{"trd":[[3.35,628.32]],"batb":[[0,3.35,44.36]],"ltp":3.35,"tv":872.65,"id":19924831}],"tv":6444.36}]}
{"op":"mcm","clk":"4210734696","pt":1631340997496,"mc":[{"id":"1.187528277","rc":[{"batl":[[1,1.44,711.68]],"ltp":1.41,"tv":5571.7,"id":2249229}]}]}
{"op":"mcm","clk":"4210741354","pt":1631341090589,"mc":[{"id":"1.187528277","rc":[{"trd":[[3.3,228.29],[3.35,717.03]],"batb":[[0,2.36,21.61],[1,2.34,1514.43],[2,1.51,33.78]],"batl":[[0,3.4,41.61]],"ltp":3.3,"tv":1189.66,"id":19924831},{"trd":[[1.43,1662.04]],"batl":[[0,1.43,148.68]],"ltp":1.43,"tv":5763.23,"id":2249229}],"tv":6952.89}]}
{"op":"mcm","clk":"4210741396","pt":1631341091267,"mc":[{"id":"1.187528277","rc":[{"batb":[[1,1.4,306.09]],"ltp":1.43,"tv":5763.23,"id":2249229}]}]}
{"op":"mcm","clk":"4210741467","pt":1631341092663,"mc":[{"id":"1.187528277","rc":[{"batb":[[0,3.05,16.72],[1,3,10.2],[2,2.36,21.61]],"ltp":3.3,"tv":1189.66,"id":19924831}]}]}
{"op":"mcm","clk":"4210741816","pt":1631341097652,"mc":[{"id":"1.187528277","rc":[{"batb":[[0,1.41,122.53]],"batl":[[0,1.43,134.3]],"ltp":1.43,"tv":5763.23,"id":2249229}]}]}
{"op":"mcm","clk":"4210741871","pt":1631341098478,"mc":[{"id":"1.187528277","rc":[{"batb":[[0,3.3,25.12],[1,3.25,47.3],[2,3.05,16.72]],"ltp":3.3,"tv":1189.66,"id":19924831}]}]}
{"op":"mcm","clk":"4210741903","pt":1631341098846,"mc":[{"id":"1.187528277","rc":[{"batl":[[0,3.4,44.9]],"ltp":3.3,"tv":1189.66,"id":19924831}]}]}
{"op":"mcm","clk":"4210742700","pt":1631341109660,"mc":[{"id":"1.187528277","rc":[{"trd":[[3.3,268.29]],"batb":[[0,3.3,5.12],[2,3,10.2]],"ltp":3.3,"tv":1229.66,"id":19924831},{"batb":[[0,1.42,19.67],[1,1.41,122.53],[2,1.4,306.09]],"batl":[[0,1.43,103.41]],"ltp":1.43,"tv":5763.23,"id":2249229}],"tv":6992.89}]}
{"op":"mcm","clk":"4210742708","pt":1631341109765,"mc":[{"id":"1.187528277","rc":[{"batb":[[0,1.42,63.46]],"ltp":1.43,"tv":5763.23,"id":2249229}]}]}
{"op":"mcm","clk":"4210743952","pt":1631341128493,"mc":[{"id":"1.187528277","rc":[{"batb":[[1,3.25,73.77]],"batl":[[1,3.45,209.63]],"ltp":3.3,"tv":1229.66,"id":19924831},{"batb":[[1,1.41,183.17],[2,1.4,236.91]],"batl":[[1,1.44,644.21],[2,1.45,1253.38]],"ltp":1.43,"tv":5763.23,"id":2249229}]}]}
{"op":"mcm","clk":"4210744336","pt":1631341134640,"mc":[{"id":"1.187528277","rc":[{"batl":[[0,3.35,53.73],[1,3.4,44.9],[2,3.45,209.63]],"ltp":3.3,"tv":1229.66,"id":19924831},{"trd":[[1.43,1868.84]],"batb":[[0,1.42,2523.87]],"batl":[[0,1.44,644.22],[1,1.45,1253.38],[2,1.46,328.81]],"ltp":1.43,"tv":5970.03,"id":2249229}],"tv":7199.69}]}
{"op":"mcm","clk":"4210744493","pt":1631341136711,"mc":[{"id":"1.187528277","rc":[{"batb":[[0,1.43,125.87],[1,1.42,2523.87],[2,1.41,183.17]],"batl":[[0,1.44,644.21]],"ltp":1.43,"tv":5970.03,"id":2249229}]}]}
{"op":"mcm","clk":"4210744515","pt":1631341137123,"mc":[{"id":"1.187528277","rc":[{"batb":[[2,1.5,3617.07]],"ltp":3.3,"tv":1229.66,"id":19924831}]}]}
{"op":"mcm","clk":"4210744617","pt":1631341138827,"mc":[{"id":"1.187528277","rc":[{"batl":[[1,3.4,36.36]],"ltp":3.3,"tv":1229.66,"id":19924831}]}]}
{"op":"mcm","clk":"4210745362","pt":1631341151625,"mc":[{"id":"1.187528277","rc":[{"batl":[[0,3.35,23.16]],"ltp":3.3,"tv":1229.66,"id":19924831},{"batb":[[0,1.43,82.39],[2,1.41,172.1]],"ltp":1.43,"tv":5970.03,"id":2249229}]}]}
{"op":"mcm","clk":"4210745417","pt":1631341152447,"mc":[{"id":"1.187528277","rc":[{"batl":[[0,3.35,35.46]],"ltp":3.3,"tv":1229.66,"id":19924831},{"batb":[[2,1.41,150.41]],"ltp":1.43,"tv":5970.03,"id":2249229}]}]}
{"op":"mcm","clk":"4210745476","pt":1631341153706,"mc":[{"id":"1.187528277","rc":[{"batl":[[2,3.45,173.91]],"ltp":3.3,"tv":1229.66,"id":19924831}]}]}
{"op":"mcm","clk":"4210745555","pt":1631341154688,"mc":[{"id":"1.187528277","rc":[{"batb":[[1,1.42,2589.97]],"batl":[[0,1.44,668.9]],"ltp":1.43,"tv":5970.03,"id":2249229}]}]}
{"op":"mcm","clk":"4210745602","pt":1631341155511,"mc":[{"id":"1.187528277","rc":[{"batl":[[0,3.35,51.58]],"ltp":3.3,"tv":1229.66,"id":19924831},{"batl":[[1,1.45,1319.48]],"ltp":1.43,"tv":5970.03,"id":2249229}]}]}
{"op":"mcm","clk":"4210745624","pt":1631341155815,"mc":[{"id":"1.187528277","rc":[{"batl":[[1,3.4,86.68]],"ltp":3.3,"tv":1229.66,"id":19924831}]}]}
{"op":"mcm","clk":"4210747168","pt":1631341180629,"mc":[{"id":"1.187528277","rc":[{"trd":[[1.43,1888.84]],"batb":[[0,1.43,72.39],[1,1.42,129.56]],"ltp":1.43,"tv":5990.03,"id":2249229}],"tv":7219.69}]}
{"op":"mcm","clk":"4210747226","pt":1631341181419,"mc":[{"id":"1.187528277","rc":[{"batl":[[0,3.35,82.15]],"ltp":3.3,"tv":1229.66,"id":19924831},{"batb":[[0,1.43,82.39],[1,1.42,2589.97]],"ltp":1.43,"tv":5990.03,"id":2249229}]}]}
{"op":"mcm","clk":"4210748752","pt":1631341204592,"mc":[{"id":"1.187528277","rc":[{"batb":[[0,3.3,10.32]],"batl":[[0,3.35,28.42]],"ltp":3.3,"tv":1229.66,"id":19924831},{"trd":[[1.43,1892.84]],"batb":[[0,1.42,2589.97],[1,1.41,150.41],[2,1.4,170.81]],"batl":[[0,1.43,12],[1,1.44,668.9],[2,1.45,1319.48]],"ltp":1.43,"tv":5994.03,"id":2249229}],"tv":7223.69}]}
{"op":"mcm","clk":"4210748786","pt":1631341204961,"mc":[{"id":"1.187528277","rc":[{"batb":[[0,3.3,5.12],[1,3.25,79.05]],"batl":[[0,3.35,82.15]],"ltp":3.3,"tv":1229.66,"id":19924831},{"batb":[[0,1.43,82.39],[1,1.42,2589.97],[2,1.41,150.41]],"batl":[[0,1.44,668.9],[1,1.45,1319.48],[2,1.46,328.81]],"ltp":1.43,"tv":5994.03,"id":2249229}]}]}
{"op":"mcm","clk":"4210749938","pt":1631341220623,"mc":[{"id":"1.187528277","rc":[{"batb":[[0,3.3,10.32]],"batl":[[0,3.35,28.42]],"ltp":3.3,"tv":1229.66,"id":19924831},{"batb":[[0,1.42,129.56],[1,1.41,150.41],[2,1.4,170.81]],"batl":[[0,1.43,12],[1,1.44,668.9],[2,1.45,1319.48]],"ltp":1.43,"tv":5994.03,"id":2249229}]}]}
{"op":"mcm","clk":"4210749971","pt":1631341220942,"mc":[{"id":"1.187528277","rc":[{"batb":[[0,3.3,5.12]],"batl":[[0,3.35,82.15]],"ltp":3.3,"tv":1229.66,"id":19924831},{"batb":[[0,1.43,82.39],[1,1.42,2589.97],[2,1.41,150.41]],"batl":[[0,1.44,668.9],[1,1.45,1319.48],[2,1.46,328.81]],"ltp":1.43,"tv":5994.03,"id":2249229}]}]}
{"op":"mcm","clk":"4210755635","pt":1631341301605,"mc":[{"id":"1.187528277","rc":[{"batl":[[0,1.44,880.39]],"ltp":1.43,"tv":5994.03,"id":2249229}]}]}
{"op":"mcm","clk":"4210755706","pt":1631341302589,"mc":[{"id":"1.187528277","rc":[{"batl":[[0,1.44,892.3]],"ltp":1.43,"tv":5994.03,"id":2249229}]}]}
{"op":"mcm","clk":"4210758940","pt":1631341351715,"mc":[{"id":"1.187528277","rc":[{"batb":[[0,1.42,2589.97],[1,1.41,150.41],[2,1.4,170.81]],"batl":[[0,1.43,12],[1,1.44,892.3],[2,1.45,1319.48]],"ltp":1.43,"tv":5994.03,"id":2249229}]}]}
{"op":"mcm","clk":"4210758966","pt":1631341352034,"mc":[{"id":"1.187528277","rc":[{"batb":[[0,1.43,82.39],[1,1.42,2589.97],[2,1.41,150.41]],"batl":[[0,1.44,892.3],[1,1.45,1319.48],[2,1.46,328.81]],"ltp":1.43,"tv":5994.03,"id":2249229}]}]}
{"op":"mcm","clk":"4210760935","pt":1631341382637,"mc":[{"id":"1.187528277","rc":[{"batb":[[0,3.3,10.32]],"batl":[[0,3.35,28.42]],"ltp":3.3,"tv":1229.66,"id":19924831},{"batb":[[0,1.42,2589.97],[1,1.41,150.41],[2,1.4,170.81]],"batl":[[0,1.43,12],[1,1.44,892.3],[2,1.45,1319.48]],"ltp":1.43,"tv":5994.03,"id":2249229}]}]}
{"op":"mcm","clk":"4210760975","pt":1631341383157,"mc":[{"id":"1.187528277","rc":[{"batb":[[0,3.3,5.12]],"batl":[[0,3.35,82.15]],"ltp":3.3,"tv":1229.66,"id":19924831},{"batb":[[0,1.43,82.39],[1,1.42,2589.97],[2,1.41,150.41]],"batl":[[0,1.44,892.3],[1,1.45,1319.48],[2,1.46,328.81]],"ltp":1.43,"tv":5994.03,"id":2249229}]}]}
{"op":"mcm","clk":"4210763726","pt":1631341427529,"mc":[{"id":"1.187528277","rc":[{"batb":[[0,3.3,10.32]],"batl":[[0,3.35,28.42]],"ltp":3.3,"tv":1229.66,"id":19924831},{"batb":[[0,1.42,129.56],[1,1.41,150.41],[2,1.4,170.81]],"ltp":1.43,"tv":5994.03,"id":2249229}]}]}
{"op":"mcm","clk":"4210763779","pt":1631341428165,"mc":[{"id":"1.187528277","rc":[{"batb":[[0,3.3,5.12]],"batl":[[0,3.35,82.15]],"ltp":3.3,"tv":1229.66,"id":19924831},{"batb":[[0,1.43,82.39],[1,1.42,2589.97],[2,1.41,150.41]],"ltp":1.43,"tv":5994.03,"id":2249229}]}]}
{"op":"mcm","clk":"4210763878","pt":1631341429566,"mc":[{"id":"1.187528277","rc":[{"batb":[[1,1.42,2553.36],[2,1.41,204.32]],"ltp":1.43,"tv":5994.03,"id":2249229}]}]}
{"op":"mcm","clk":"4210763927","pt":1631341430136,"mc":[{"id":"1.187528277","rc":[{"batl":[[0,3.35,70.29]],"ltp":3.3,"tv":1229.66,"id":19924831}]}]}
{"op":"mcm","clk":"4210763969","pt":1631341430758,"mc":[{"id":"1.187528277","rc":[{"batl":[[1,3.4,51.24]],"ltp":3.3,"tv":1229.66,"id":19924831}]}]}
{"op":"mcm","clk":"4210767258","pt":1631341483629,"mc":[{"id":"1.187528277","rc":[{"trd":[[3.35,750.16]],"batb":[[0,3.3,10.32]],"batl":[[0,3.4,51.24],[1,3.45,173.91],[2,9.8,224.27]],"ltp":3.35,"tv":1262.78,"id":19924831},{"batb":[[0,1.42,2589.97],[1,1.41,150.41],[2,1.4,170.81]],"batl":[[0,1.43,12],[1,1.44,892.3],[2,1.45,1319.48]],"ltp":1.43,"tv":5994.03,"id":2249229}],"tv":7256.82}]}
{"op":"mcm","clk":"4210767292","pt":1631341484345,"mc":[{"id":"1.187528277","rc":[{"batb":[[0,3.3,5.12]],"batl":[[0,3.35,34.72],[1,3.4,86.68],[2,3.45,173.91]],"ltp":3.35,"tv":1262.78,"id":19924831},{"batb":[[0,1.43,82.39],[1,1.42,2589.97],[2,1.41,150.41]],"batl":[[0,1.44,892.3],[1,1.45,1319.48],[2,1.46,328.81]],"ltp":1.43,"tv":5994.03,"id":2249229}]}]}
{"op":"mcm","clk":"4210767337","pt":1631341484920,"mc":[{"id":"1.187528277","rc":[{"batb":[[0,3.3,17.61]],"ltp":3.35,"tv":1262.78,"id":19924831}]}]}
{"op":"mcm","clk":"4210770098","pt":1631341520683,"mc":[{"id":"1.187528277","rc":[{"batb":[[0,3.3,22.81]],"batl":[[0,3.35,11.56]],"ltp":3.35,"tv":1262.78,"id":19924831},{"batb":[[0,1.42,2589.97],[1,1.41,150.41],[2,1.4,170.81]],"batl":[[0,1.43,12],[1,1.44,892.3],[2,1.45,1319.48]],"ltp":1.43,"tv":5994.03,"id":2249229}]}]}
{"op":"mcm","clk":"4210770128","pt":1631341521099,"mc":[{"id":"1.187528277","rc":[{"batb":[[0,3.3,17.61]],"batl":[[0,3.35,65.29]],"ltp":3.35,"tv":1262.78,"id":19924831},{"batb":[[0,1.43,82.39],[1,1.42,2589.97],[2,1.41,150.41]],"batl":[[0,1.44,892.3],[1,1.45,1319.48],[2,1.46,328.81]],"ltp":1.43,"tv":5994.03,"id":2249229}]}]}
{"op":"mcm","clk":"4210770899","pt":1631341532511,"mc":[{"id":"1.187528277","rc":[{"batl":[[0,1.44,897.21]],"ltp":1.43,"tv":5994.03,"id":2249229}]}]}
{"op":"mcm","clk":"4210770976","pt":1631341533703,"mc":[{"id":"1.187528277","rc":[{"batl":[[0,3.35,68.8]],"ltp":3.35,"tv":1262.78,"id":19924831},{"batb":[[0,1.42,2589.97],[1,1.41,150.41],[2,1.4,170.81]],"batl":[[0,1.43,12],[1,1.44,897.21],[2,1.45,1319.48]],"ltp":1.43,"tv":5994.03,"id":2249229}]}]}
{"op":"mcm","clk":"4210771009","pt":1631341534114,"mc":[{"id":"1.187528277","rc":[{"batb":[[0,1.43,82.39],[1,1.42,2589.97],[2,1.41,150.41]],"batl":[[0,1.44,897.21],[1,1.45,1319.48],[2,1.46,328.81]],"ltp":1.43,"tv":5994.03,"id":2249229}]}]}
{"op":"mcm","clk":"4210772094","pt":1631341549519,"mc":[{"id":"1.187528277","rc":[{"batb":[[0,3.3,22.81]],"batl":[[0,3.35,15.07]],"ltp":3.35,"tv":1262.78,"id":19924831},{"batb":[[0,1.42,129.56],[1,1.41,150.41],[2,1.4,170.81]],"ltp":1.43,"tv":5994.03,"id":2249229}]}]}
{"op":"mcm","clk":"4210772147","pt":1631341550244,"mc":[{"id":"1.187528277","rc":[{"batb":[[0,3.3,17.61]],"batl":[[0,3.35,68.8]],"ltp":3.35,"tv":1262.78,"id":19924831},{"batb":[[0,1.43,82.39],[1,1.42,2589.97],[2,1.41,150.41]],"ltp":1.43,"tv":5994.03,"id":2249229}]}]}
{"op":"mcm","clk":"4210774849","pt":1631341591721,"mc":[{"id":"1.187528277","rc":[{"batb":[[1,1.42,129.56]],"ltp":1.43,"tv":5994.03,"id":2249229}]}]}
{"op":"mcm","clk":"4210774927","pt":1631341592549,"mc":[{"id":"1.187528277","rc":[{"batb":[[1,1.42,2589.97]],"ltp":1.43,"tv":5994.03,"id":2249229}]}]}
{"op":"mcm","clk":"4210777134","pt":1631341622670,"mc":[{"id":"1.187528277","rc":[{"batb":[[1,1.42,129.56]],"ltp":1.43,"tv":5994.03,"id":2249229}]}]}
{"op":"mcm","clk":"4210777185","pt":1631341623388,"mc":[{"id":"1.187528277","rc":[{"batb":[[1,1.42,2589.97]],"ltp":1.43,"tv":5994.03,"id":2249229}]}]}
{"op":"mcm","clk":"4210785365","pt":1631341746685,"mc":[{"id":"1.187528277","rc":[{"trd":[[1.43,1896.84]],"batb":[[0,1.43,80.39],[1,1.42,129.56]],"ltp":1.43,"tv":5998.03,"id":2249229}],"tv":7260.82}]}
{"op":"mcm","clk":"4210785437","pt":1631341747476,"mc":[{"id":"1.187528277","rc":[{"batb":[[0,1.43,82.39],[1,1.42,2589.97]],"ltp":1.43,"tv":5998.03,"id":2249229}]}]}
{"op":"mcm","clk":"4210791187","pt":1631341831110,"mc":[{"id":"1.187528277","rc":[{"trd":[[1.43,2061.62]],"batb":[[0,1.42,2589.97],[1,1.41,150.41],[2,1.4,170.81]],"batl":[[0,1.43,405.27],[1,1.44,897.21],[2,1.45,1319.48]],"ltp":1.43,"tv":6162.81,"id":2249229}],"tv":7425.6}]}
{"op":"mcm","clk":"4210791703","pt":1631341839225,"mc":[{"id":"1.187528277","rc":[{"batb":[[0,3.3,59.38]],"ltp":3.35,"tv":1262.78,"id":19924831},{"batl":[[0,1.43,892.93]],"ltp":1.43,"tv":6162.81,"id":2249229}]}]}
{"op":"mcm","clk":"4210792226","pt":1631341847856,"mc":[{"id":"1.187528277","rc":[{"batl":[[0,1.43,1380.59]],"ltp":1.43,"tv":6162.81,"id":2249229}]}]}
{"op":"mcm","clk":"4210792618","pt":1631341853361,"mc":[{"id":"1.187528277","rc":[{"batb":[[1,1.41,204.32]],"batl":[[2,1.45,1253.38]],"ltp":1.43,"tv":6162.81,"id":2249229}]}]}
{"op":"mcm","clk":"4210792675","pt":1631341854181,"mc":[{"id":"1.187528277","rc":[{"batl":[[0,1.43,1389.55],[1,1.44,892.3]],"ltp":1.43,"tv":6162.81,"id":2249229}]}]}
{"op":"mcm","clk":"4210792740","pt":1631341855277,"mc":[{"id":"1.187528277","rc":[{"batb":[[0,3.3,64.28]],"ltp":3.35,"tv":1262.78,"id":19924831},{"batl":[[1,1.44,867.61]],"ltp":1.43,"tv":6162.81,"id":2249229}]}]}
{"op":"mcm","clk":"4210792814","pt":1631341856466,"mc":[{"id":"1.187528277","rc":[{"batl":[[0,1.43,1877.21]],"ltp":1.43,"tv":6162.81,"id":2249229}]}]}
{"op":"mcm","clk":"4210793515","pt":1631341867410,"mc":[{"id":"1.187528277","rc":[{"batl":[[0,3.35,15.07]],"ltp":3.35,"tv":1262.78,"id":19924831},{"batl":[[0,1.43,2364.87]],"ltp":1.43,"tv":6162.81,"id":2249229}]}]}
{"op":"mcm","clk":"4210793782","pt":1631341870805,"mc":[{"id":"1.187528277","rc":[{"batl":[[0,1.43,1877.21]],"ltp":1.43,"tv":6162.81,"id":2249229}]}]}
{"op":"mcm","clk":"4210796193","pt":1631341906583,"mc":[{"id":"1.187528277","rc":[{"batb":[[1,1.41,212.41]],"ltp":1.43,"tv":6162.81,"id":2249229}]}]}
{"op":"mcm","clk":"4210796262","pt":1631341907462,"mc":[{"id":"1.187528277","rc":[{"batl":[[0,3.4,86.68],[1,3.45,173.91],[2,9.8,224.27]],"ltp":3.35,"tv":1262.78,"id":19924831}]}]}
{"op":"mcm","clk":"4210796412","pt":1631341909649,"mc":[{"id":"1.187528277","rc":[{"batb":[[0,1.42,129.56]],"ltp":1.43,"tv":6162.81,"id":2249229}]}]}
{"op":"mcm","clk":"4210796434","pt":1631341909959,"mc":[{"id":"1.187528277","rc":[{"batl":[[0,3.35,53.73],[1,3.4,109.5],[2,3.45,173.91]],"ltp":3.35,"tv":1262.78,"id":19924831},{"batb":[[0,1.42,3412.38]],"ltp":1.43,"tv":6162.81,"id":2249229}]}]}
{"op":"mcm","clk":"4210796799","pt":1631341915582,"mc":[{"id":"1.187528277","rc":[{"batl":[[0,3.4,109.5],[1,3.45,173.91],[2,9.8,224.27]],"ltp":3.35,"tv":1262.78,"id":19924831},{"trd":[[1.42,5995.18]],"batb":[[0,1.42,1512.38]],"ltp":1.42,"tv":9962.81,"id":2249229}],"tv":11225.6}]}
{"op":"mcm","clk":"4210796878","pt":1631341916561,"mc":[{"id":"1.187528277","rc":[{"batb":[[0,3.35,29.46],[1,3.3,64.28],[2,3.25,79.05]],"ltp":3.35,"tv":1262.78,"id":19924831},{"batb":[[0,1.42,904.15]],"ltp":1.42,"tv":9962.81,"id":2249229}]}]}
{"op":"mcm","clk":"4210797001","pt":1631341918572,"mc":[{"id":"1.187528277","rc":[{"batl":[[0,3.4,56.56]],"ltp":3.35,"tv":1262.78,"id":19924831},{"batb":[[0,1.42,38.36]],"batl":[[0,1.43,1949.09]],"ltp":1.42,"tv":9962.81,"id":2249229}]}]}
{"op":"mcm","clk":"4210797270","pt":1631341922580,"mc":[{"id":"1.187528277","rc":[{"trd":[[3.4,244.22]],"batl":[[0,3.45,173.91],[1,9.8,224.27],[2,9.8,0]],"ltp":3.4,"tv":1389.61,"id":19924831},{"trd":[[1.42,6028]],"batb":[[0,1.42,5.53]],"ltp":1.42,"tv":9995.63,"id":2249229}],"tv":11385.25}]}
{"op":"mcm","clk":"4210800246","pt":1631341965207,"mc":[{"id":"1.187528277","rc":[{"batb":[[2,3.25,31.76]],"ltp":3.4,"tv":1389.61,"id":19924831}]}]}
{"op":"mcm","clk":"4210800373","pt":1631341967581,"mc":[{"id":"1.187528277","rc":[{"batb":[[1,1.41,182.27]],"ltp":1.42,"tv":9995.63,"id":2249229}]}]}
{"op":"mcm","clk":"4210800412","pt":1631341968507,"mc":[{"id":"1.187528277","rc":[{"batb":[[1,3.3,107.71]],"ltp":3.4,"tv":1389.61,"id":19924831},{"batl":[[0,1.43,2049.53]],"ltp":1.42,"tv":9995.63,"id":2249229}]}]}
{"op":"mcm","clk":"4210800481","pt":1631341969605,"mc":[{"id":"1.187528277","rc":[{"batb":[[0,3.35,33.88]],"batl":[[0,3.45,213.37],[1,3.5,10.25],[2,9.8,224.27]],"ltp":3.4,"tv":1389.61,"id":19924831}]}]}
{"op":"mcm","clk":"4210802578","pt":1631342006204,"mc":[{"id":"1.187528277","rc":[{"trd":[[3.35,784.32]],"batb":[[0,3.35,16.8]],"ltp":3.35,"tv":1423.78,"id":19924831}],"tv":11419.41}]}
{"op":"mcm","clk":"4210803562","pt":1631342022451,"mc":[{"id":"1.187528277","rc":[{"batl":[[0,3.45,217.33]],"ltp":3.35,"tv":1423.78,"id":19924831}]}]}
{"op":"mcm","clk":"4210813509","pt":1631342208714,"mc":[{"id":"1.187528277","rc":[{"batb":[[2,3.25,5.28]],"ltp":3.35,"tv":1423.78,"id":19924831},{"batb":[[1,1.41,162.62]],"batl":[[2,1.45,1174.81]],"ltp":1.42,"tv":9995.63,"id":2249229}]}]}
{"op":"mcm","clk":"4210813527","pt":1631342209024,"mc":[{"id":"1.187528277","rc":[{"batb":[[1,3.3,125.65]],"ltp":3.35,"tv":1423.78,"id":19924831},{"batl":[[1,1.44,927.39]],"ltp":1.42,"tv":9995.63,"id":2249229}]}]}
{"op":"mcm","clk":"4210813628","pt":1631342210628,"mc":[{"id":"1.187528277","rc":[{"batl":[[0,3.45,211.35]],"ltp":3.35,"tv":1423.78,"id":19924831},{"batb":[[1,1.41,121.63]],"ltp":1.42,"tv":9995.63,"id":2249229}]}]}
{"op":"mcm","clk":"4210813640","pt":1631342210840,"mc":[{"id":"1.187528277","rc":[{"batb":[[2,1.4,245.96]],"batl":[[1,1.44,935.94]],"ltp":1.42,"tv":9995.63,"id":2249229}]}]}
{"op":"mcm","clk":"4210814071","pt":1631342218666,"mc":[{"id":"1.187528277","rc":[{"batl":[[0,3.45,193.42]],"ltp":3.35,"tv":1423.78,"id":19924831},{"batb":[[2,1.4,240.84]],"ltp":1.42,"tv":9995.63,"id":2249229}]}]}
{"op":"mcm","clk":"4210814081","pt":1631342218875,"mc":[{"id":"1.187528277","rc":[{"batb":[[1,3.3,132.48]],"batl":[[1,3.5,35.87]],"ltp":3.35,"tv":1423.78,"id":19924831},{"batl":[[1,1.44,944.48]],"ltp":1.42,"tv":9995.63,"id":2249229}]}]}
{"op":"mcm","clk":"4210815509","pt":1631342247497,"mc":[{"id":"1.187528277","rc":[{"batb":[[1,1.41,108.02]],"ltp":1.42,"tv":9995.63,"id":2249229}]}]}
{"op":"mcm","clk":"4210815551","pt":1631342248528,"mc":[{"id":"1.187528277","rc":[{"batl":[[0,3.45,189.45],[1,3.5,45.45]],"ltp":3.35,"tv":1423.78,"id":19924831}]}]}
{"op":"mcm","clk":"4210818462","pt":1631342308154,"mc":[{"id":"1.187528277","rc":[{"batb":[[2,1.4,385.44]],"ltp":1.42,"tv":9995.63,"id":2249229}]}]}
{"op":"mcm","clk":"4210818961","pt":1631342317150,"mc":[{"id":"1.187528277","rc":[{"batl":[[0,3.45,226.37]],"ltp":3.35,"tv":1423.78,"id":19924831}]}]}
{"op":"mcm","clk":"4210819966","pt":1631342335814,"mc":[{"id":"1.187528277","rc":[{"batl":[[0,3.45,189.45]],"ltp":3.35,"tv":1423.78,"id":19924831}]}]}
{"op":"mcm","clk":"4210820869","pt":1631342354134,"mc":[{"id":"1.187528277","rc":[{"batl":[[1,3.5,55.57]],"ltp":3.35,"tv":1423.78,"id":19924831}]}]}
{"op":"mcm","clk":"4210829973","pt":1631342513659,"mc":[{"id":"1.187528277","rc":[{"batl":[[1,1.44,867.61]],"ltp":1.42,"tv":9995.63,"id":2249229}]}]}
{"op":"mcm","clk":"4210829992","pt":1631342514068,"mc":[{"id":"1.187528277","rc":[{"batb":[[1,3.3,140.17]],"ltp":3.35,"tv":1423.78,"id":19924831},{"batb":[[2,1.4,373.49]],"batl":[[0,1.43,2099.06]],"ltp":1.42,"tv":9995.63,"id":2249229}]}]}
{"op":"mcm","clk":"4210835717","pt":1631342605017,"mc":[{"id":"1.187528277","rc":[{"trd":[[3.35,791.16]],"batb":[[0,3.35,13.38]],"ltp":3.35,"tv":1430.62,"id":19924831}],"tv":11426.25}]}
{"op":"mcm","clk":"4210837186","pt":1631342627361,"mc":[{"id":"1.187528277","rc":[{"batl":[[0,3.45,241.62]],"ltp":3.35,"tv":1430.62,"id":19924831},{"batb":[[1,1.41,795.52]],"ltp":1.42,"tv":9995.63,"id":2249229}]}]}
{"op":"mcm","clk":"4210838287","pt":1631342644467,"mc":[{"id":"1.187528277","rc":[{"batb":[[1,1.41,840.11]],"ltp":1.42,"tv":9995.63,"id":2249229}]}]}
{"op":"mcm","clk":"4210878337","pt":1631343095665,"mc":[{"id":"1.187528277","rc":[{"trd":[[3.35,817.76]],"batb":[[0,3.3,140.25],[1,3.25,5.28],[2,1.5,3617.07]],"batl":[[0,3.4,52.94],[1,3.45,241.62],[2,3.5,55.57]],"ltp":3.35,"tv":1457.21,"id":19924831},{"batb":[[0,1.42,2473.37]],"batl":[[0,1.43,2027.18]],"ltp":1.42,"tv":9995.63,"id":2249229}],"tv":11452.85}]}
{"op":"mcm","clk":"4210880107","pt":1631343127551,"mc":[{"id":"1.187528277","rc":[{"batl":[[2,3.5,45.32]],"ltp":3.35,"tv":1457.21,"id":19924831}]}]}
{"op":"mcm","clk":"4210880137","pt":1631343128224,"mc":[{"id":"1.187528277","rc":[{"batl":[[2,3.5,35.2]],"ltp":3.35,"tv":1457.21,"id":19924831}]}]}
{"op":"mcm","clk":"4210880197","pt":1631343129320,"mc":[{"id":"1.187528277","rc":[{"batb":[[0,3.3,140.17]],"batl":[[2,3.5,25.62]],"ltp":3.35,"tv":1457.21,"id":19924831}]}]}
{"op":"mcm","clk":"4210880271","pt":1631343130667,"mc":[{"id":"1.187528277","rc":[{"batl":[[0,1.43,2013.54]],"ltp":1.42,"tv":9995.63,"id":2249229}]}]}
{"op":"mcm","clk":"4210880319","pt":1631343131546,"mc":[{"id":"1.187528277","rc":[{"batb":[[0,3.3,134.08],[1,3.25,63.74]],"ltp":3.35,"tv":1457.21,"id":19924831}]}]}
{"op":"mcm","clk":"4210880367","pt":1631343132328,"mc":[{"id":"1.187528277","rc":[{"batl":[[0,3.4,67.97],[1,3.45,245.8]],"ltp":3.35,"tv":1457.21,"id":19924831}]}]}
{"op":"mcm","clk":"4210882222","pt":1631343171552,"mc":[{"id":"1.187528277","rc":[{"batl":[[0,3.4,104.12]],"ltp":3.35,"tv":1457.21,"id":19924831}]}]}
{"op":"mcm","clk":"4210882318","pt":1631343173673,"mc":[{"id":"1.187528277","rc":[{"batb":[[1,3.25,69.1]],"ltp":3.35,"tv":1457.21,"id":19924831}]}]}
{"op":"mcm","clk":"4210882404","pt":1631343175573,"mc":[{"id":"1.187528277","rc":[{"batb":[[0,3.3,304.89]],"ltp":3.35,"tv":1457.21,"id":19924831},{"batb":[[1,1.41,984.71]],"ltp":1.42,"tv":9995.63,"id":2249229}]}]}
{"op":"mcm","clk":"4210890579","pt":1631343356675,"mc":[{"id":"1.187528277","rc":[{"batb":[[0,3.35,2.81],[1,3.3,304.89],[2,3.25,69.1]],"ltp":3.35,"tv":1457.21,"id":19924831}]}]}
{"op":"mcm","clk":"4210896724","pt":1631343477388,"mc":[{"id":"1.187528277","rc":[{"trd":[[3.35,823.22]],"batb":[[0,3.3,304.98],[1,3.25,69.1],[2,1.5,3617.07]],"ltp":3.35,"tv":1462.68,"id":19924831}],"tv":11458.31}]}
{"op":"mcm","clk":"4210904725","pt":1631343617638,"mc":[{"id":"1.187528277","rc":[{"batb":[[1,3.25,82.15]],"ltp":3.35,"tv":1462.68,"id":19924831},{"batb":[[0,1.42,2492.86]],"ltp":1.42,"tv":9995.63,"id":2249229}]}]}
{"op":"mcm","clk":"4210916611","pt":1631343725479,"mc":[{"id":"1.187528277","rc":[{"batb":[[1,1.41,1107.25]],"ltp":1.42,"tv":9995.63,"id":2249229}]}]}
{"op":"mcm","clk":"4210916771","pt":1631343726485,"mc":[{"id":"1.187528277","rc":[{"batb":[[0,1.42,2667.24]],"batl":[[0,1.43,2156.53],[1,1.44,1036.46]],"ltp":1.42,"tv":9995.63,"id":2249229}]}]}
{"op":"mcm","clk":"4210916935","pt":1631343727688,"mc":[{"id":"1.187528277","rc":[{"batb":[[0,3.3,434.23],[1,3.25,88.32]],"ltp":3.35,"tv":1462.68,"id":19924831}]}]}
{"op":"mcm","clk":"4210917035","pt":1631343728418,"mc":[{"id":"1.187528277","rc":[{"batl":[[0,3.4,227.29],[1,3.45,299.4]],"ltp":3.35,"tv":1462.68,"id":19924831},{"batb":[[0,1.42,2794]],"ltp":1.42,"tv":9995.63,"id":2249229}]}]}
{"op":"mcm","clk":"4210928502","pt":1631343802600,"mc":[{"id":"1.187528277","rc":[{"batb":[[1,3.25,100.47]],"ltp":3.35,"tv":1462.68,"id":19924831},{"batb":[[1,1.41,1170.18]],"batl":[[1,1.44,1106.22]],"ltp":1.42,"tv":9995.63,"id":2249229}]}]}
{"op":"mcm","clk":"4210928721","pt":1631343803698,"mc":[{"id":"1.187528277","rc":[{"batb":[[0,3.3,438.87]],"batl":[[1,3.45,314.96]],"ltp":3.35,"tv":1462.68,"id":19924831}]}]}
{"op":"mcm","clk":"4210938480","pt":1631343869224,"mc":[{"id":"1.187528277","rc":[{"trd":[[1.43,2082.9]],"batl":[[0,1.43,2145.89]],"ltp":1.43,"tv":10016.91,"id":2249229}],"tv":11479.59}]}
{"op":"mcm","clk":"4210940298","pt":1631343880934,"mc":[{"id":"1.187528277","rc":[{"trd":[[1.43,2104.65]],"batl":[[0,1.43,2135.02]],"ltp":1.43,"tv":10038.66,"id":2249229}],"tv":11501.34}]}
{"op":"mcm","clk":"4210940755","pt":1631343883618,"mc":[{"id":"1.187528277","rc":[{"batb":[[1,1.41,1179.62]],"ltp":1.43,"tv":10038.66,"id":2249229}]}]}
{"op":"mcm","clk":"4210940879","pt":1631343884401,"mc":[{"id":"1.187528277","rc":[{"batb":[[1,3.25,106.93]],"ltp":3.35,"tv":1462.68,"id":19924831},{"batl":[[1,1.44,1118.28]],"ltp":1.43,"tv":10038.66,"id":2249229}]}]}
{"op":"mcm","clk":"4210940943","pt":1631343884821,"mc":[{"id":"1.187528277","rc":[{"batl":[[1,3.45,321.15]],"ltp":3.35,"tv":1462.68,"id":19924831}]}]}
{"op":"mcm","clk":"4210951520","pt":1631343952680,"mc":[{"id":"1.187528277","rc":[{"trd":[[1.42,6038.64]],"batb":[[0,1.42,2788.68]],"ltp":1.42,"tv":10049.3,"id":2249229}],"tv":11511.98}]}
{"op":"mcm","clk":"4210951702","pt":1631343953775,"mc":[{"id":"1.187528277","rc":[{"batb":[[0,1.42,2788.46]],"ltp":1.42,"tv":10049.3,"id":2249229}]}]}
{"op":"mcm","clk":"4210960597","pt":1631344010328,"mc":[{"id":"1.187528277","rc":[{"batb":[[0,3.3,538.87]],"ltp":3.35,"tv":1462.68,"id":19924831}]}]}
{"op":"mcm","clk":"4210964363","pt":1631344034294,"mc":[{"id":"1.187528277","rc":[{"batb":[[0,3.35,11.76],[1,3.3,538.79],[2,3.25,106.93]],"ltp":3.35,"tv":1462.68,"id":19924831},{"trd":[[1.42,6070.36]],"batb":[[0,1.42,320.62]],"batl":[[0,1.43,2162.39]],"ltp":1.42,"tv":10081.02,"id":2249229}],"tv":11543.7}]}
{"op":"mcm","clk":"4210964825","pt":1631344037202,"mc":[{"id":"1.187528277","rc":[{"batb":[[2,3.25,100.76]],"ltp":3.35,"tv":1462.68,"id":19924831}]}]}
{"op":"mcm","clk":"4210964980","pt":1631344038299,"mc":[{"id":"1.187528277","rc":[{"batb":[[2,3.25,82.15]],"ltp":3.35,"tv":1462.68,"id":19924831}]}]}
{"op":"mcm","clk":"4210965127","pt":1631344039389,"mc":[{"id":"1.187528277","rc":[{"batb":[[2,3.25,18.34]],"ltp":3.35,"tv":1462.68,"id":19924831}]}]}
{"op":"mcm","clk":"4210965249","pt":1631344040281,"mc":[{"id":"1.187528277","rc":[{"batb":[[0,1.42,194.34]],"ltp":1.42,"tv":10081.02,"id":2249229}]}]}
{"op":"mcm","clk":"4210965366","pt":1631344041165,"mc":[{"id":"1.187528277","rc":[{"batl":[[0,3.4,143.27]],"ltp":3.35,"tv":1462.68,"id":19924831},{"batl":[[1,1.44,1124.33]],"ltp":1.42,"tv":10081.02,"id":2249229}]}]}
{"op":"mcm","clk":"4210965517","pt":1631344042096,"mc":[{"id":"1.187528277","rc":[{"trd":[[1.42,6176.72]],"batb":[[0,1.42,141.16]],"ltp":1.42,"tv":10187.37,"id":2249229}],"tv":11650.05}]}
{"op":"mcm","clk":"4210966773","pt":1631344049311,"mc":[{"id":"1.187528277","rc":[{"batl":[[0,3.4,107.12]],"ltp":3.35,"tv":1462.68,"id":19924831}]}]}
{"op":"mcm","clk":"4210976302","pt":1631344108344,"mc":[{"id":"1.187528277","rc":[{"trd":[[3.35,846.62]],"batb":[[0,3.3,538.85],[1,3.25,13.06],[2,1.5,3617.07]],"ltp":3.35,"tv":1486.08,"id":19924831},{"batl":[[1,1.44,1112.42]],"ltp":1.42,"tv":10187.37,"id":2249229}],"tv":11673.46}]}
{"op":"mcm","clk":"4210978124","pt":1631344119643,"mc":[{"id":"1.187528277","rc":[{"batb":[[0,3.35,53.73],[1,3.3,538.79],[2,3.25,13.06]],"batl":[[0,3.4,54.18]],"ltp":3.35,"tv":1486.08,"id":19924831},{"trd":[[1.42,6459.04]],"batb":[[0,1.41,1179.62],[1,1.4,373.49],[2,1.39,144.6]],"batl":[[0,1.42,196.84],[1,1.43,2162.39],[2,1.44,1112.42]],"ltp":1.42,"tv":10469.7,"id":2249229}],"tv":11955.78}]}
{"op":"mcm","clk":"4210978313","pt":1631344120652,"mc":[{"id":"1.187528277","rc":[{"trd":[[1.42,6472.58]],"batb":[[0,1.41,1137.57]],"batl":[[0,1.42,190.07]],"ltp":1.42,"tv":10483.24,"id":2249229}],"tv":11969.32}]}
{"op":"mcm","clk":"4210978420","pt":1631344121344,"mc":[{"id":"1.187528277","rc":[{"batb":[[2,3.25,88.95]],"ltp":3.35,"tv":1486.08,"id":19924831},{"batl":[[1,1.43,2179.13]],"ltp":1.42,"tv":10483.24,"id":2249229}]}]}
{"op":"mcm","clk":"4210978640","pt":1631344122448,"mc":[{"id":"1.187528277","rc":[{"batb":[[1,3.3,546.06]],"batl":[[0,3.4,24.91]],"ltp":3.35,"tv":1486.08,"id":19924831}]}]}
{"op":"mcm","clk":"4210979305","pt":1631344126064,"mc":[{"id":"1.187528277","rc":[{"trd":[[1.42,6565.84]],"batl":[[0,1.42,143.44]],"ltp":1.42,"tv":10576.5,"id":2249229}],"tv":12062.58}]}
{"op":"mcm","clk":"4210980103","pt":1631344131382,"mc":[{"id":"1.187528277","rc":[{"trd":[[3.35,954.08]],"batb":[[0,3.3,546.06],[1,3.25,88.95],[2,1.5,3617.07]],"batl":[[0,3.4,77.85]],"ltp":3.35,"tv":1593.54,"id":19924831},{"trd":[[1.42,6852.72]],"batl":[[0,1.43,2179.13],[1,1.44,1112.42],[2,1.45,1174.81]],"ltp":1.42,"tv":10863.38,"id":2249229}],"tv":12456.92}]}
{"op":"mcm","clk":"4210990271","pt":1631344195400,"mc":[{"id":"1.187528277","rc":[{"batb":[[1,1.4,557.83]],"ltp":1.42,"tv":10863.38,"id":2249229}]}]}
{"op":"mcm","clk":"4210990473","pt":1631344196611,"mc":[{"id":"1.187528277","rc":[{"batb":[[1,3.25,100.33]],"ltp":3.35,"tv":1593.54,"id":19924831},{"batb":[[0,1.41,1120.67]],"batl":[[0,1.43,2189.69]],"ltp":1.42,"tv":10863.38,"id":2249229}]}]}
{"op":"mcm","clk":"4210990571","pt":1631344197442,"mc":[{"id":"1.187528277","rc":[{"batb":[[0,3.3,550.63]],"batl":[[0,3.4,67.97]],"ltp":3.35,"tv":1593.54,"id":19924831}]}]}
{"op":"mcm","clk":"4211006523","pt":1631344300234,"mc":[{"id":"1.187528277","rc":[{"batb":[[1,1.4,585.48]],"ltp":1.42,"tv":10863.38,"id":2249229}]}]}
{"op":"mcm","clk":"4211018634","pt":1631344384746,"mc":[{"id":"1.187528277","rc":[{"batb":[[1,1.4,589.63]],"ltp":1.42,"tv":10863.38,"id":2249229}]}]}
{"op":"mcm","clk":"4211021863","pt":1631344407203,"mc":[{"id":"1.187528277","rc":[{"batl":[[0,3.4,83.91]],"ltp":3.35,"tv":1593.54,"id":19924831}]}]}
{"op":"mcm","clk":"4211028596","pt":1631344456679,"mc":[{"id":"1.187528277","rc":[{"batl":[[0,1.43,2140.15]],"ltp":1.42,"tv":10863.38,"id":2249229}]}]}
{"op":"mcm","clk":"4211028652","pt":1631344457050,"mc":[{"id":"1.187528277","rc":[{"batb":[[0,3.3,544.65]],"ltp":3.35,"tv":1593.54,"id":19924831},{"batb":[[1,1.4,599.88]],"batl":[[1,1.44,1189.29]],"ltp":1.42,"tv":10863.38,"id":2249229}]}]}
{"op":"mcm","clk":"4211033940","pt":1631344496215,"mc":[{"id":"1.187528277","rc":[{"batb":[[1,3.25,107.15]],"ltp":3.35,"tv":1593.54,"id":19924831}]}]}
{"op":"mcm","clk":"4211059647","pt":1631344678951,"mc":[{"id":"1.187528277","rc":[{"batb":[[0,1.42,26.59],[1,1.41,1120.67],[2,1.4,599.88]],"ltp":1.42,"tv":10863.38,"id":2249229}]}]}
{"op":"mcm","clk":"4211065203","pt":1631344715370,"mc":[{"id":"1.187528277","rc":[{"batb":[[2,1.4,415.53]],"ltp":1.42,"tv":10863.38,"id":2249229}]}]}
{"op":"mcm","clk":"4211065409","pt":1631344716577,"mc":[{"id":"1.187528277","rc":[{"batb":[[2,1.4,383.73]],"ltp":1.42,"tv":10863.38,"id":2249229}]}]}
{"op":"mcm","clk":"4211065513","pt":1631344717264,"mc":[{"id":"1.187528277","rc":[{"batb":[[0,1.42,30.58]],"ltp":1.42,"tv":10863.38,"id":2249229}]}]}
{"op":"mcm","clk":"4211072603","pt":1631344764608,"mc":[{"id":"1.187528277","rc":[{"batb":[[0,1.42,31.55]],"ltp":1.42,"tv":10863.38,"id":2249229}]}]}
{"op":"mcm","clk":"4211079664","pt":1631344813550,"mc":[{"id":"1.187528277","rc":[{"trd":[[1.43,2155.7]],"batl":[[0,1.43,2114.63]],"ltp":1.43,"tv":10914.43,"id":2249229}],"tv":12507.98}]}
{"op":"mcm","clk":"4211080013","pt":1631344815742,"mc":[{"id":"1.187528277","rc":[{"batb":[[0,1.42,79.55]],"ltp":1.43,"tv":10914.43,"id":2249229}]}]}
{"op":"mcm","clk":"4211091765","pt":1631344892584,"mc":[{"id":"1.187528277","rc":[{"batb":[[0,1.42,87.49]],"ltp":1.43,"tv":10914.43,"id":2249229}]}]}
{"op":"mcm","clk":"4211101319","pt":1631344953075,"mc":[{"id":"1.187528277","rc":[{"batl":[[0,3.4,86.94]],"ltp":3.35,"tv":1593.54,"id":19924831}]}]}
{"op":"mcm","clk":"4211122363","pt":1631345087328,"mc":[{"id":"1.187528277","rc":[{"batl":[[1,3.45,339.08],[2,9.8,224.27]],"ltp":3.35,"tv":1593.54,"id":19924831},{"batb":[[2,1.4,390.57]],"batl":[[1,1.44,1179.89]],"ltp":1.43,"tv":10914.43,"id":2249229}]}]}
{"op":"mcm","clk":"4211125856","pt":1631345108965,"mc":[{"id":"1.187528277","rc":[{"batb":[[0,1.42,140.67]],"ltp":1.43,"tv":10914.43,"id":2249229}]}]}
{"op":"mcm","clk":"4211131232","pt":1631345143315,"mc":[{"id":"1.187528277","rc":[{"batb":[[0,1.42,87.49]],"ltp":1.43,"tv":10914.43,"id":2249229}]}]}
{"op":"mcm","clk":"4211147237","pt":1631345242659,"mc":[{"id":"1.187528277","rc":[{"batl":[[0,3.35,341.62],[1,3.4,86.94],[2,3.45,339.08]],"ltp":3.35,"tv":1593.54,"id":19924831}]}]}
{"op":"mcm","clk":"4211147377","pt":1631345243449,"mc":[{"id":"1.187528277","rc":[{"batl":[[1,3.4,71.01]],"ltp":3.35,"tv":1593.54,"id":19924831},{"batb":[[0,1.42,214.25]],"batl":[[0,1.43,2087.26]],"ltp":1.43,"tv":10914.43,"id":2249229}]}]}
{"op":"mcm","clk":"4211147676","pt":1631345245473,"mc":[{"id":"1.187528277","rc":[{"trd":[[1.42,7082.19]],"batb":[[0,1.42,99.52]],"ltp":1.42,"tv":11143.9,"id":2249229}],"tv":12737.44}]}
{"op":"mcm","clk":"4211148362","pt":1631345250456,"mc":[{"id":"1.187528277","rc":[{"trd":[[1.42,7085.6]],"batb":[[0,1.42,97.81]],"ltp":1.42,"tv":11147.31,"id":2249229}],"tv":12740.86}]}
{"op":"mcm","clk":"4211155118","pt":1631345297499,"mc":[{"id":"1.187528277","rc":[{"trd":[[1.43,2335.25]],"batl":[[0,1.43,1997.48]],"ltp":1.43,"tv":11326.87,"id":2249229}],"tv":12920.41}]}
{"op":"mcm","clk":"4211156629","pt":1631345307528,"mc":[{"id":"1.187528277","rc":[{"batl":[[2,3.45,299.63]],"ltp":3.35,"tv":1593.54,"id":19924831}]}]}
{"op":"mcm","clk":"4211156779","pt":1631345308634,"mc":[{"id":"1.187528277","rc":[{"batl":[[2,3.45,277.89]],"ltp":3.35,"tv":1593.54,"id":19924831}]}]}
{"op":"mcm","clk":"4211156936","pt":1631345309619,"mc":[{"id":"1.187528277","rc":[{"batl":[[2,3.45,220.1]],"ltp":3.35,"tv":1593.54,"id":19924831}]}]}
{"op":"mcm","clk":"4211157151","pt":1631345311459,"mc":[{"id":"1.187528277","rc":[{"batb":[[0,1.42,233.37]],"ltp":1.43,"tv":11326.87,"id":2249229}]}]}
{"op":"mcm","clk":"4211157184","pt":1631345311791,"mc":[{"id":"1.187528277","rc":[{"batl":[[0,1.43,2003.37]],"ltp":1.43,"tv":11326.87,"id":2249229}]}]}
{"op":"mcm","clk":"4211158104","pt":1631345317852,"mc":[{"id":"1.187528277","rc":[{"trd":[[3.35,1054.09]],"batl":[[0,3.35,291.61]],"ltp":3.35,"tv":1693.54,"id":19924831}],"tv":13020.42}]}
{"op":"mcm","clk":"4211158665","pt":1631345322142,"mc":[{"id":"1.187528277","rc":[{"batb":[[0,1.42,351.37]],"ltp":1.43,"tv":11326.87,"id":2249229}]}]}
{"op":"mcm","clk":"4211166135","pt":1631345375428,"mc":[{"id":"1.187528277","rc":[{"batb":[[0,1.42,356.21]],"ltp":1.43,"tv":11326.87,"id":2249229}]}]}
{"op":"mcm","clk":"4211166171","pt":1631345375738,"mc":[{"id":"1.187528277","rc":[{"batl":[[1,3.4,85.6]],"ltp":3.35,"tv":1693.54,"id":19924831}]}]}
{"op":"mcm","clk":"4211176608","pt":1631345449191,"mc":[{"id":"1.187528277","rc":[{"trd":[[3.35,1637.31]],"batb":[[0,3.35,146.25],[1,3.3,544.65],[2,3.25,107.15]],"batl":[[0,3.4,85.6],[1,3.45,220.1],[2,9.8,224.27]],"ltp":3.35,"tv":2276.77,"id":19924831},{"batl":[[0,1.43,2032.27]],"ltp":1.43,"tv":11326.87,"id":2249229}],"tv":13603.64}]}
{"op":"mcm","clk":"4211177358","pt":1631345454534,"mc":[{"id":"1.187528277","rc":[{"batb":[[2,3.25,95.77]],"ltp":3.35,"tv":2276.77,"id":19924831}]}]}
{"op":"mcm","clk":"4211177430","pt":1631345455008,"mc":[{"id":"1.187528277","rc":[{"batb":[[2,3.25,19.88]],"ltp":3.35,"tv":2276.77,"id":19924831}]}]}
{"op":"mcm","clk":"4211177514","pt":1631345455736,"mc":[{"id":"1.187528277","rc":[{"batb":[[2,3.25,13.06]],"ltp":3.35,"tv":2276.77,"id":19924831}]}]}
{"op":"mcm","clk":"4211178025","pt":1631345459502,"mc":[{"id":"1.187528277","rc":[{"batb":[[0,1.42,351.37]],"ltp":1.43,"tv":11326.87,"id":2249229}]}]}
{"op":"mcm","clk":"4211178134","pt":1631345460438,"mc":[{"id":"1.187528277","rc":[{"batb":[[0,3.35,168.19]],"ltp":3.35,"tv":2276.77,"id":19924831},{"batb":[[0,1.42,269.24]],"ltp":1.43,"tv":11326.87,"id":2249229}]}]}
{"op":"mcm","clk":"4211178175","pt":1631345460804,"mc":[{"id":"1.187528277","rc":[{"batl":[[1,3.45,321.82]],"ltp":3.35,"tv":2276.77,"id":19924831}]}]}
{"op":"mcm","clk":"4211185130","pt":1631345510414,"mc":[{"id":"1.187528277","rc":[{"batb":[[0,1.42,256.2]],"batl":[[0,1.43,2026.38]],"ltp":1.43,"tv":11326.87,"id":2249229}]}]}
{"op":"mcm","clk":"4211185277","pt":1631345511512,"mc":[{"id":"1.187528277","rc":[{"batb":[[1,3.3,540.09]],"ltp":3.35,"tv":2276.77,"id":19924831},{"batl":[[0,1.43,2015.82]],"ltp":1.43,"tv":11326.87,"id":2249229}]}]}
{"op":"mcm","clk":"4211185434","pt":1631345512514,"mc":[{"id":"1.187528277","rc":[{"batb":[[0,3.35,171.48],[1,3.3,532.81]],"ltp":3.35,"tv":2276.77,"id":19924831}]}]}
{"op":"mcm","clk":"4211185500","pt":1631345512929,"mc":[{"id":"1.187528277","rc":[{"batl":[[1,3.45,337.08]],"ltp":3.35,"tv":2276.77,"id":19924831}]}]}
{"op":"mcm","clk":"4211197575","pt":1631345608595,"mc":[{"id":"1.187528277","rc":[{"trd":[[3.35,1979.91]],"batb":[[0,3.3,532.99],[1,3.25,13.06],[2,1.5,3617.07]],"ltp":3.35,"tv":2619.36,"id":19924831}],"tv":13946.24}]}
{"op":"mcm","clk":"4211197600","pt":1631345608800,"mc":[{"id":"1.187528277","rc":[{"batb":[[0,3.3,491.22]],"ltp":3.35,"tv":2619.36,"id":19924831}]}]}
{"op":"mcm","clk":"4211202524","pt":1631345649540,"mc":[{"id":"1.187528277","rc":[{"batb":[[0,3.3,491.04]],"ltp":3.35,"tv":2619.36,"id":19924831},{"batl":[[0,1.43,1999.08]],"ltp":1.43,"tv":11326.87,"id":2249229}]}]}
{"op":"mcm","clk":"4211202636","pt":1631345650538,"mc":[{"id":"1.187528277","rc":[{"batb":[[1,3.25,93.43]],"ltp":3.35,"tv":2619.36,"id":19924831},{"batl":[[0,1.43,1981.15]],"ltp":1.43,"tv":11326.87,"id":2249229}]}]}
{"op":"mcm","clk":"4211202727","pt":1631345651330,"mc":[{"id":"1.187528277","rc":[{"batb":[[0,3.3,477.12]],"ltp":3.35,"tv":2619.36,"id":19924831}]}]}
{"op":"mcm","clk":"4211209446","pt":1631345707573,"mc":[{"id":"1.187528277","rc":[{"batb":[[1,3.25,105.49]],"ltp":3.35,"tv":2619.36,"id":19924831}]}]}
{"op":"mcm","clk":"4211217511","pt":1631345775779,"mc":[{"id":"1.187528277","rc":[{"batl":[[0,3.35,85.4],[1,3.4,85.6],[2,3.45,337.08]],"ltp":3.35,"tv":2619.36,"id":19924831}]}]}
{"op":"mcm","clk":"4211218128","pt":1631345781590,"mc":[{"id":"1.187528277","rc":[{"batl":[[2,3.45,220.1]],"ltp":3.35,"tv":2619.36,"id":19924831}]}]}
{"op":"mcm","clk":"4211218332","pt":1631345782904,"mc":[{"id":"1.187528277","rc":[{"batb":[[0,1.42,284.46]],"ltp":1.43,"tv":11326.87,"id":2249229}]}]}
{"op":"mcm","clk":"4211219496","pt":1631345790898,"mc":[{"id":"1.187528277","rc":[{"batb":[[0,3.3,501.66]],"ltp":3.35,"tv":2619.36,"id":19924831}]}]}
{"op":"mcm","clk":"4211226836","pt":1631345850018,"mc":[{"id":"1.187528277","rc":[{"batb":[[0,1.42,288.7]],"ltp":1.43,"tv":11326.87,"id":2249229}]}]}
{"op":"mcm","clk":"4211242076","pt":1631345975843,"mc":[{"id":"1.187528277","rc":[{"batb":[[1,1.41,1248.78]],"batl":[[1,1.44,1308]],"ltp":1.43,"tv":11326.87,"id":2249229}]}]}
{"op":"mcm","clk":"4211245525","pt":1631346004268,"mc":[{"id":"1.187528277","rc":[{"batb":[[1,3.25,115.81]],"ltp":3.35,"tv":2619.36,"id":19924831},{"batb":[[1,1.41,1268.26]],"ltp":1.43,"tv":11326.87,"id":2249229}]}]}
{"op":"mcm","clk":"4211250607","pt":1631346041860,"mc":[{"id":"1.187528277","rc":[{"batb":[[0,3.3,330.85]],"ltp":3.35,"tv":2619.36,"id":19924831}]}]}
{"op":"mcm","clk":"4211250993","pt":1631346044345,"mc":[{"id":"1.187528277","rc":[{"trd":[[3.3,278.29]],"batb":[[0,3.3,325.85]],"ltp":3.3,"tv":2629.36,"id":19924831},{"batb":[[1,1.41,1271.19]],"batl":[[1,1.44,1301.94]],"ltp":1.43,"tv":11326.87,"id":2249229}],"tv":13956.24}]}
{"op":"mcm","clk":"4211262280","pt":1631346128568,"mc":[{"id":"1.187528277","rc":[{"batl":[[1,1.44,1311.94]],"ltp":1.43,"tv":11326.87,"id":2249229}]}]}
{"op":"mcm","clk":"4211289531","pt":1631346353370,"mc":[{"id":"1.187528277","rc":[{"batb":[[0,3.3,330.16]],"ltp":3.3,"tv":2629.36,"id":19924831},{"trd":[[1.42,7105.6]],"batb":[[0,1.42,278.7]],"ltp":1.42,"tv":11346.87,"id":2249229}],"tv":13976.24}]}
{"op":"mcm","clk":"4211291471","pt":1631346370300,"mc":[{"id":"1.187528277","rc":[{"trd":[[1.43,2339.25]],"batl":[[0,1.43,1979.16]],"ltp":1.43,"tv":11350.87,"id":2249229}],"tv":13980.24}]}
{"op":"mcm","clk":"4211302065","pt":1631346454219,"mc":[{"id":"1.187528277","rc":[{"batl":[[0,3.35,135.4]],"ltp":3.3,"tv":2629.36,"id":19924831}]}]}
{"op":"mcm","clk":"4211302920","pt":1631346461529,"mc":[{"id":"1.187528277","rc":[{"batb":[[0,3.3,334.46]],"ltp":3.3,"tv":2629.36,"id":19924831},{"trd":[[1.42,7125.6]],"batb":[[0,1.42,268.7]],"ltp":1.42,"tv":11370.87,"id":2249229}],"tv":14000.24}]}
{"op":"mcm","clk":"4211303361","pt":1631346464342,"mc":[{"id":"1.187528277","rc":[{"batb":[[0,1.42,285.53]],"ltp":1.42,"tv":11370.87,"id":2249229}]}]}
{"op":"mcm","clk":"4211312506","pt":1631346539371,"mc":[{"id":"1.187528277","rc":[{"batl":[[1,1.44,1323.05]],"ltp":1.42,"tv":11370.87,"id":2249229}]}]}
{"op":"mcm","clk":"4211321264","pt":1631346609988,"mc":[{"id":"1.187528277","rc":[{"batb":[[2,1.4,402.52]],"ltp":1.42,"tv":11370.87,"id":2249229}]}]}
{"op":"mcm","clk":"4211336162","pt":1631346747442,"mc":[{"id":"1.187528277","rc":[{"trd":[[1.43,2392.43]],"batl":[[0,1.43,1952.57]],"ltp":1.43,"tv":11424.04,"id":2249229}],"tv":14053.41}]}
{"op":"mcm","clk":"4211341102","pt":1631346791434,"mc":[{"id":"1.187528277","rc":[{"trd":[[3.3,331.47]],"batb":[[0,3.3,307.87]],"ltp":3.3,"tv":2682.54,"id":19924831}],"tv":14106.59}]}
{"op":"mcm","clk":"4211342407","pt":1631346803872,"mc":[{"id":"1.187528277","rc":[{"trd":[[3.3,352.74]],"batb":[[0,3.3,297.24]],"ltp":3.3,"tv":2703.81,"id":19924831}],"tv":14127.86}]}
{"op":"mcm","clk":"4211345031","pt":1631346830397,"mc":[{"id":"1.187528277","rc":[{"batl":[[0,1.43,1918.24],[1,1.44,1310.98]],"ltp":1.43,"tv":11424.04,"id":2249229}]}]}
{"op":"mcm","clk":"4211345069","pt":1631346830811,"mc":[{"id":"1.187528277","rc":[{"batb":[[0,3.3,312.06]],"ltp":3.3,"tv":2703.81,"id":19924831}]}]}
{"op":"mcm","clk":"4211350356","pt":1631346875640,"mc":[{"id":"1.187528277","rc":[{"trd":[[3.3,397.98]],"batb":[[0,3.3,289.44]],"ltp":3.3,"tv":2749.06,"id":19924831}],"tv":14173.11}]}
{"op":"mcm","clk":"4211354449","pt":1631346908620,"mc":[{"id":"1.187528277","rc":[{"batb":[[0,3.3,298.23]],"ltp":3.3,"tv":2749.06,"id":19924831},{"batl":[[0,1.43,1897.88]],"ltp":1.43,"tv":11424.04,"id":2249229}]}]}
{"op":"mcm","clk":"4211354498","pt":1631346909036,"mc":[{"id":"1.187528277","rc":[{"batl":[[0,3.35,142.89]],"ltp":3.3,"tv":2749.06,"id":19924831}]}]}
{"op":"mcm","clk":"4211358095","pt":1631346939643,"mc":[{"id":"1.187528277","rc":[{"batl":[[1,1.44,1302.44]],"ltp":1.43,"tv":11424.04,"id":2249229}]}]}
{"op":"mcm","clk":"4211358141","pt":1631346940264,"mc":[{"id":"1.187528277","rc":[{"batl":[[2,3.45,226.08]],"ltp":3.3,"tv":2749.06,"id":19924831}]}]}
{"op":"mcm","clk":"4211358594","pt":1631346943679,"mc":[{"id":"1.187528277","rc":[{"batb":[[0,1.42,289.21]],"ltp":1.43,"tv":11424.04,"id":2249229}]}]}
{"op":"mcm","clk":"4211361712","pt":1631346970703,"mc":[{"id":"1.187528277","rc":[{"trd":[[3.35,2265.68]],"batb":[[0,3.35,660.18],[1,3.3,298.23],[2,3.25,115.81]],"batl":[[0,3.4,85.6],[1,3.45,226.08],[2,9.8,224.27]],"ltp":3.35,"tv":3034.83,"id":19924831},{"batb":[[0,1.42,211.4]],"ltp":1.43,"tv":11424.04,"id":2249229}],"tv":14458.88}]}
{"op":"mcm","clk":"4211363419","pt":1631346984711,"mc":[{"id":"1.187528277","rc":[{"batb":[[2,3.25,13.06]],"ltp":3.35,"tv":3034.83,"id":19924831}]}]}
{"op":"mcm","clk":"4211363503","pt":1631346985434,"mc":[{"id":"1.187528277","rc":[{"batb":[[0,1.42,207.72]],"ltp":1.43,"tv":11424.04,"id":2249229}]}]}
{"op":"mcm","clk":"4211363605","pt":1631346986217,"mc":[{"id":"1.187528277","rc":[{"batb":[[0,1.42,186.65]],"ltp":1.43,"tv":11424.04,"id":2249229}]}]}
{"op":"mcm","clk":"4211363760","pt":1631346987513,"mc":[{"id":"1.187528277","rc":[{"batb":[[1,3.3,301.89]],"ltp":3.35,"tv":3034.83,"id":19924831},{"batb":[[0,1.42,158.39]],"batl":[[0,1.43,1907.47]],"ltp":1.43,"tv":11424.04,"id":2249229}]}]}
{"op":"mcm","clk":"4211363875","pt":1631346988447,"mc":[{"id":"1.187528277","rc":[{"batl":[[0,3.4,79.02],[1,3.45,337.93]],"ltp":3.35,"tv":3034.83,"id":19924831}]}]}
{"op":"mcm","clk":"4211366414","pt":1631347009937,"mc":[{"id":"1.187528277","rc":[{"batb":[[1,3.3,307.01]],"ltp":3.35,"tv":3034.83,"id":19924831}]}]}
{"op":"mcm","clk":"4211368725","pt":1631347028428,"mc":[{"id":"1.187528277","rc":[{"batl":[[1,3.45,354.7]],"ltp":3.35,"tv":3034.83,"id":19924831},{"batb":[[0,1.42,141.76]],"ltp":1.43,"tv":11424.04,"id":2249229}]}]}
{"op":"mcm","clk":"4211368768","pt":1631347028799,"mc":[{"id":"1.187528277","rc":[{"trd":[[1.43,2446.56]],"batl":[[0,1.43,1880.41]],"ltp":1.43,"tv":11478.18,"id":2249229}],"tv":14513.01}]}
{"op":"mcm","clk":"4211370848","pt":1631347045626,"mc":[{"id":"1.187528277","rc":[{"trd":[[1.42,7129.02]],"batb":[[0,1.42,140.05]],"ltp":1.42,"tv":11481.59,"id":2249229}],"tv":14516.43}]}
{"op":"mcm","clk":"4211371740","pt":1631347053847,"mc":[{"id":"1.187528277","rc":[{"batb":[[0,3.35,8.48]],"ltp":3.35,"tv":3034.83,"id":19924831},{"batb":[[0,1.42,266.81]],"ltp":1.42,"tv":11481.59,"id":2249229}]}]}
{"op":"mcm","clk":"4211373330","pt":1631347067580,"mc":[{"id":"1.187528277","rc":[{"batb":[[0,1.42,284.78]],"ltp":1.42,"tv":11481.59,"id":2249229}]}]}
{"op":"mcm","clk":"4211379181","pt":1631347113433,"mc":[{"id":"1.187528277","rc":[{"batb":[[0,1.42,287.48]],"ltp":1.42,"tv":11481.59,"id":2249229}]}]}
{"op":"mcm","clk":"4211379240","pt":1631347113848,"mc":[{"id":"1.187528277","rc":[{"batl":[[0,3.4,82.64]],"ltp":3.35,"tv":3034.83,"id":19924831}]}]}
{"op":"mcm","clk":"4211399612","pt":1631347251490,"mc":[{"id":"1.187528277","rc":[{"batb":[[1,1.41,1292.62]],"ltp":1.42,"tv":11481.59,"id":2249229}]}]}
{"op":"mcm","clk":"4211406558","pt":1631347293638,"mc":[{"id":"1.187528277","rc":[{"trd":[[3.35,2282.64]],"batb":[[0,3.3,307.01],[1,3.25,13.06],[2,1.5,3617.07]],"batl":[[0,3.35,16.52],[1,3.4,82.64],[2,3.45,354.7]],"ltp":3.35,"tv":3051.79,"id":19924831}],"tv":14533.39}]}
{"op":"mcm","clk":"4211406592","pt":1631347293815,"mc":[{"id":"1.187528277","rc":[{"batb":[[0,3.3,298.4]],"ltp":3.35,"tv":3051.79,"id":19924831}]}]}
{"op":"mcm","clk":"4211406767","pt":1631347294818,"mc":[{"id":"1.187528277","rc":[{"batl":[[2,3.45,358.53]],"ltp":3.35,"tv":3051.79,"id":19924831}]}]}
{"op":"mcm","clk":"4211407434","pt":1631347299232,"mc":[{"id":"1.187528277","rc":[{"trd":[[3.3,431.02]],"batb":[[0,3.3,281.88]],"batl":[[0,3.4,82.64],[1,3.45,358.53],[2,9.8,224.27]],"ltp":3.3,"tv":3084.83,"id":19924831}],"tv":14566.43}]}
{"op":"mcm","clk":"4211416740","pt":1631347360466,"mc":[{"id":"1.187528277","rc":[{"batb":[[0,3.3,271.79],[1,3.25,48.93]],"batl":[[1,3.45,367.07]],"ltp":3.3,"tv":3084.83,"id":19924831},{"batb":[[1,1.41,1360.95],[2,1.4,315.41]],"batl":[[1,1.44,1285.36]],"ltp":1.42,"tv":11481.59,"id":2249229}]}]}
{"op":"mcm","clk":"4211420072","pt":1631347384539,"mc":[{"id":"1.187528277","rc":[{"batb":[[1,1.41,1373.77]],"batl":[[1,1.44,1266.89]],"ltp":1.42,"tv":11481.59,"id":2249229}]}]}
{"op":"mcm","clk":"4211420186","pt":1631347385432,"mc":[{"id":"1.187528277","rc":[{"batb":[[1,3.25,141.7]],"batl":[[1,3.45,373.12]],"ltp":3.3,"tv":3084.83,"id":19924831}]}]}
{"op":"mcm","clk":"4211431057","pt":1631347463978,"mc":[{"id":"1.187528277","rc":[{"batb":[[1,3.25,154.38]],"ltp":3.3,"tv":3084.83,"id":19924831}]}]}
{"op":"mcm","clk":"4211432032","pt":1631347470579,"mc":[{"id":"1.187528277","rc":[{"trd":[[3.3,433.78]],"batb":[[0,3.3,270.41]],"ltp":3.3,"tv":3087.59,"id":19924831}],"tv":14569.18}]}
{"op":"mcm","clk":"4211435300","pt":1631347494360,"mc":[{"id":"1.187528277","rc":[{"trd":[[3.3,493.78]],"batb":[[0,3.3,240.41]],"ltp":3.3,"tv":3147.59,"id":19924831}],"tv":14629.19}]}
{"op":"mcm","clk":"4211443405","pt":1631347549559,"mc":[{"id":"1.187528277","rc":[{"batl":[[0,1.43,1844.21]],"ltp":1.42,"tv":11481.59,"id":2249229}]}]}
{"op":"mcm","clk":"4211443479","pt":1631347550172,"mc":[{"id":"1.187528277","rc":[{"batl":[[1,1.44,1253.33]],"ltp":1.42,"tv":11481.59,"id":2249229}]}]}
{"op":"mcm","clk":"4211443577","pt":1631347550742,"mc":[{"id":"1.187528277","rc":[{"batb":[[0,3.3,256.57]],"ltp":3.3,"tv":3147.59,"id":19924831}]}]}
{"op":"mcm","clk":"4211454658","pt":1631347626619,"mc":[{"id":"1.187528277","rc":[{"batl":[[1,1.44,1256.85]],"ltp":1.42,"tv":11481.59,"id":2249229}]}]}
{"op":"mcm","clk":"4211484643","pt":1631347823802,"mc":[{"id":"1.187528277","rc":[{"trd":[[3.3,578.38]],"batb":[[0,3.3,214.27]],"ltp":3.3,"tv":3232.19,"id":19924831}],"tv":14713.78}]}
{"op":"mcm","clk":"4211488291","pt":1631347847136,"mc":[{"id":"1.187528277","rc":[{"batl":[[0,3.4,99.38]],"ltp":3.3,"tv":3232.19,"id":19924831}]}]}
{"op":"mcm","clk":"4211493839","pt":1631347880431,"mc":[{"id":"1.187528277","rc":[{"batb":[[1,3.25,144.99]],"batl":[[0,3.4,116.46],[1,3.45,340.66]],"ltp":3.3,"tv":3232.19,"id":19924831},{"batb":[[1,1.41,1383.17]],"batl":[[1,1.44,1203.9],[2,1.45,1251.67]],"ltp":1.42,"tv":11481.59,"id":2249229}]}]}
{"op":"mcm","clk":"4211497493","pt":1631347902537,"mc":[{"id":"1.187528277","rc":[{"batb":[[1,1.41,1398.74]],"batl":[[0,1.43,1800.44]],"ltp":1.42,"tv":11481.59,"id":2249229}]}]}
{"op":"mcm","clk":"4211497591","pt":1631347903151,"mc":[{"id":"1.187528277","rc":[{"batl":[[1,1.44,1200.38]],"ltp":1.42,"tv":11481.59,"id":2249229}]}]}
{"op":"mcm","clk":"4211497832","pt":1631347904529,"mc":[{"id":"1.187528277","rc":[{"batb":[[0,3.3,235.35]],"batl":[[0,3.4,122.25]],"ltp":3.3,"tv":3232.19,"id":19924831},{"batl":[[1,1.44,1181.94]],"ltp":1.42,"tv":11481.59,"id":2249229}]}]}
{"op":"mcm","clk":"4211505488","pt":1631347950423,"mc":[{"id":"1.187528277","rc":[{"batl":[[2,1.45,1258.5]],"ltp":1.42,"tv":11481.59,"id":2249229}]}]}
{"op":"mcm","clk":"4211512267","pt":1631347988341,"mc":[{"id":"1.187528277","rc":[{"batb":[[1,1.41,1403.17]],"ltp":1.42,"tv":11481.59,"id":2249229}]}]}
{"op":"mcm","clk":"4211512426","pt":1631347989247,"mc":[{"id":"1.187528277","rc":[{"batb":[[1,3.25,139.84]],"ltp":3.3,"tv":3232.19,"id":19924831},{"batl":[[1,1.44,1185.9]],"ltp":1.42,"tv":11481.59,"id":2249229}]}]}
{"op":"mcm","clk":"4211515519","pt":1631348007794,"mc":[{"id":"1.187528277","rc":[{"batb":[[0,1.42,472.62]],"ltp":1.42,"tv":11481.59,"id":2249229}]}]}
{"op":"mcm","clk":"4211525297","pt":1631348069640,"mc":[{"id":"1.187528277","rc":[{"batl":[[0,3.4,105.17]],"ltp":3.3,"tv":3232.19,"id":19924831},{"batl":[[2,1.45,1174.81]],"ltp":1.42,"tv":11481.59,"id":2249229}]}]}
{"op":"mcm","clk":"4211525366","pt":1631348070009,"mc":[{"id":"1.187528277","rc":[{"batb":[[1,3.25,147.52]],"batl":[[1,3.45,376.53]],"ltp":3.3,"tv":3232.19,"id":19924831},{"batb":[[1,1.41,1392.92]],"batl":[[1,1.44,1236.29]],"ltp":1.42,"tv":11481.59,"id":2249229}]}]}
{"op":"mcm","clk":"4211527094","pt":1631348080340,"mc":[{"id":"1.187528277","rc":[{"batb":[[0,1.42,500.79]],"batl":[[1,1.44,1244.44]],"ltp":1.42,"tv":11481.59,"id":2249229}]}]}
{"op":"mcm","clk":"4211527263","pt":1631348081431,"mc":[{"id":"1.187528277","rc":[{"batb":[[1,3.25,151.51]],"batl":[[0,3.4,115.07],[1,3.45,379.91]],"ltp":3.3,"tv":3232.19,"id":19924831}]}]}
{"op":"mcm","clk":"4211530427","pt":1631348100359,"mc":[{"id":"1.187528277","rc":[{"batb":[[1,3.25,143.83]],"batl":[[0,3.4,138.98],[1,3.45,344.04]],"ltp":3.3,"tv":3232.19,"id":19924831},{"batb":[[1,1.41,1411.71]],"batl":[[1,1.44,1194.05],[2,1.45,1243.98]],"ltp":1.42,"tv":11481.59,"id":2249229}]}]}
{"op":"mcm","clk":"4211540986","pt":1631348162548,"mc":[{"id":"1.187528277","rc":[{"batb":[[1,1.41,1419.71]],"ltp":1.42,"tv":11481.59,"id":2249229}]}]}
{"op":"mcm","clk":"4211541182","pt":1631348163503,"mc":[{"id":"1.187528277","rc":[{"batl":[[0,3.4,145.82]],"ltp":3.3,"tv":3232.19,"id":19924831},{"batb":[[0,1.42,505.02]],"ltp":1.42,"tv":11481.59,"id":2249229}]}]}
{"op":"mcm","clk":"4211544084","pt":1631348180021,"mc":[{"id":"1.187528277","rc":[{"batb":[[1,1.41,1683.56]],"batl":[[0,1.43,1771.54]],"ltp":1.42,"tv":11481.59,"id":2249229}]}]}
{"op":"mcm","clk":"4211548414","pt":1631348205250,"mc":[{"id":"1.187528277","rc":[{"batl":[[2,3.5,25]],"ltp":3.3,"tv":3232.19,"id":19924831}]}]}
{"op":"mcm","clk":"4211557108","pt":1631348254664,"mc":[{"id":"1.187528277","rc":[{"batl":[[1,3.45,356.99]],"ltp":3.3,"tv":3232.19,"id":19924831},{"batb":[[1,1.41,1726.81]],"ltp":1.42,"tv":11481.59,"id":2249229}]}]}
{"op":"mcm","clk":"4211583989","pt":1631348324449,"mc":[{"id":"1.187528277","rc":[{"batl":[[1,3.45,361.58]],"ltp":3.3,"tv":3232.19,"id":19924831},{"batb":[[1,1.41,1733.3]],"ltp":1.42,"tv":11481.59,"id":2249229}]}]}
{"op":"mcm","clk":"4211594622","pt":1631348393706,"mc":[{"id":"1.187528277","rc":[{"batl":[[2,1.45,1250.82]],"ltp":1.42,"tv":11481.59,"id":2249229}]}]}
{"op":"mcm","clk":"4211596254","pt":1631348403803,"mc":[{"id":"1.187528277","rc":[{"batb":[[0,1.42,465.77]],"ltp":1.42,"tv":11481.59,"id":2249229}]}]}
{"op":"mcm","clk":"4211622973","pt":1631348573971,"mc":[{"id":"1.187528277","rc":[{"batl":[[2,1.45,1242.28]],"ltp":1.42,"tv":11481.59,"id":2249229}]}]}
{"op":"mcm","clk":"4211625665","pt":1631348590772,"mc":[{"id":"1.187528277","rc":[{"batl":[[2,1.45,1337.07]],"ltp":1.42,"tv":11481.59,"id":2249229}]}]}
{"op":"mcm","clk":"4211631264","pt":1631348622320,"mc":[{"id":"1.187528277","rc":[{"trd":[[3.3,595.13]],"batb":[[0,3.3,226.98]],"ltp":3.3,"tv":3248.94,"id":19924831}],"tv":14730.53}]}
{"op":"mcm","clk":"4211634162","pt":1631348639546,"mc":[{"id":"1.187528277","rc":[{"batb":[[0,3.3,231.15]],"ltp":3.3,"tv":3248.94,"id":19924831},{"batl":[[0,1.43,1756.8]],"ltp":1.42,"tv":11481.59,"id":2249229}]}]}
{"op":"mcm","clk":"4211652122","pt":1631348747542,"mc":[{"id":"1.187528277","rc":[{"batb":[[1,3.25,136.19]],"ltp":3.3,"tv":3248.94,"id":19924831}]}]}
{"op":"mcm","clk":"4211652157","pt":1631348747748,"mc":[{"id":"1.187528277","rc":[{"batb":[[1,3.25,130.77]],"ltp":3.3,"tv":3248.94,"id":19924831}]}]}
{"op":"mcm","clk":"4211653256","pt":1631348754344,"mc":[{"id":"1.187528277","rc":[{"batb":[[1,3.25,104.29],[2,3.2,25.62]],"batl":[[0,3.4,165.47]],"ltp":3.3,"tv":3248.94,"id":19924831},{"batb":[[0,1.42,552.88],[1,1.41,1647.04]],"batl":[[2,1.45,1269.6]],"ltp":1.42,"tv":11481.59,"id":2249229}]}]}
{"op":"mcm","clk":"4211657937","pt":1631348783713,"mc":[{"id":"1.187528277","rc":[{"batb":[[0,1.42,560.69]],"ltp":1.42,"tv":11481.59,"id":2249229}]}]}
{"op":"mcm","clk":"4211658116","pt":1631348784704,"mc":[{"id":"1.187528277","rc":[{"batb":[[1,3.25,92.77]],"ltp":3.3,"tv":3248.94,"id":19924831}]}]}
{"op":"mcm","clk":"4211658207","pt":1631348785284,"mc":[{"id":"1.187528277","rc":[{"batl":[[0,3.4,172.7]],"ltp":3.3,"tv":3248.94,"id":19924831}]}]}
{"op":"mcm","clk":"4211664989","pt":1631348827552,"mc":[{"id":"1.187528277","rc":[{"trd":[[1.42,8250.39]],"batb":[[0,1.41,1647.04],[1,1.4,315.41],[2,1.39,144.6]],"batl":[[0,1.42,1439.32],[1,1.43,1756.8],[2,1.44,1194.05]],"ltp":1.42,"tv":12602.96,"id":2249229}],"tv":15851.91}]}
{"op":"mcm","clk":"4211665180","pt":1631348828664,"mc":[{"id":"1.187528277","rc":[{"batb":[[0,3.35,53.73],[1,3.3,231.15],[2,3.25,92.77]],"batl":[[0,3.4,129.14]],"ltp":3.3,"tv":3248.94,"id":19924831},{"trd":[[1.42,8941.65]],"batb":[[0,1.41,4975.64]],"batl":[[0,1.42,1093.69]],"ltp":1.42,"tv":13294.22,"id":2249229}],"tv":16543.17}]}
{"op":"mcm","clk":"4211665327","pt":1631348829557,"mc":[{"id":"1.187528277","rc":[{"batb":[[2,3.25,120.1]],"ltp":3.3,"tv":3248.94,"id":19924831},{"batb":[[0,1.41,5060.19]],"ltp":1.42,"tv":13294.22,"id":2249229}]}]}
{"op":"mcm","clk":"4211667172","pt":1631348842056,"mc":[{"id":"1.187528277","rc":[{"batl":[[2,1.44,1025.21]],"ltp":1.42,"tv":13294.22,"id":2249229}]}]}
{"op":"mcm","clk":"4211667413","pt":1631348843573,"mc":[{"id":"1.187528277","rc":[{"batl":[[2,1.44,1007.86]],"ltp":1.42,"tv":13294.22,"id":2249229}]}]}
{"op":"mcm","clk":"4211667570","pt":1631348844571,"mc":[{"id":"1.187528277","rc":[{"batl":[[2,1.44,984.62]],"ltp":1.42,"tv":13294.22,"id":2249229}]}]}
{"op":"mcm","clk":"4211667666","pt":1631348845258,"mc":[{"id":"1.187528277","rc":[{"batl":[[2,1.44,977.19]],"ltp":1.42,"tv":13294.22,"id":2249229}]}]}
{"op":"mcm","clk":"4211667889","pt":1631348846673,"mc":[{"id":"1.187528277","rc":[{"batl":[[2,1.44,927.71]],"ltp":1.42,"tv":13294.22,"id":2249229}]}]}
{"op":"mcm","clk":"4211667968","pt":1631348847255,"mc":[{"id":"1.187528277","rc":[{"batb":[[2,3.25,27.33]],"ltp":3.3,"tv":3248.94,"id":19924831}]}]}
{"op":"mcm","clk":"4211668152","pt":1631348848551,"mc":[{"id":"1.187528277","rc":[{"batb":[[0,1.41,5409.68],[1,1.4,505.75]],"ltp":1.42,"tv":13294.22,"id":2249229}]}]}
{"op":"mcm","clk":"4211668287","pt":1631348849381,"mc":[{"id":"1.187528277","rc":[{"batb":[[1,3.3,248.67]],"ltp":3.3,"tv":3248.94,"id":19924831},{"batl":[[1,1.43,1800.02]],"ltp":1.42,"tv":13294.22,"id":2249229}]}]}
{"op":"mcm","clk":"4211668441","pt":1631348850277,"mc":[{"id":"1.187528277","rc":[{"batl":[[0,3.4,115.07]],"ltp":3.3,"tv":3248.94,"id":19924831}]}]}
{"op":"mcm","clk":"4211668578","pt":1631348851276,"mc":[{"id":"1.187528277","rc":[{"batl":[[0,3.4,99.38]],"ltp":3.3,"tv":3248.94,"id":19924831}]}]}
{"op":"mcm","clk":"4211668766","pt":1631348852383,"mc":[{"id":"1.187528277","rc":[{"batl":[[0,3.4,87.75]],"ltp":3.3,"tv":3248.94,"id":19924831}]}]}
{"op":"mcm","clk":"4211668847","pt":1631348852858,"mc":[{"id":"1.187528277","rc":[{"batl":[[1,3.45,508.1]],"ltp":3.3,"tv":3248.94,"id":19924831}]}]}
{"op":"mcm","clk":"4211669753","pt":1631348858781,"mc":[{"id":"1.187528277","rc":[{"batl":[[0,3.4,114.23]],"ltp":3.3,"tv":3248.94,"id":19924831}]}]}
{"op":"mcm","clk":"4211670370","pt":1631348862686,"mc":[{"id":"1.187528277","rc":[{"batb":[[0,3.3,303.21],[1,3.25,27.33],[2,1.5,3617.07]],"ltp":3.3,"tv":3248.94,"id":19924831},{"trd":[[1.42,10455.25]],"batl":[[0,1.42,336.89]],"ltp":1.42,"tv":14807.82,"id":2249229}],"tv":18056.77}]}
{"op":"mcm","clk":"4211670385","pt":1631348862793,"mc":[{"id":"1.187528277","rc":[{"trd":[[1.42,10771.52]],"batl":[[0,1.42,178.76]],"ltp":1.42,"tv":15124.09,"id":2249229}],"tv":18373.03}]}
{"op":"mcm","clk":"4211673121","pt":1631348880505,"mc":[{"id":"1.187528277","rc":[{"trd":[[1.42,10987.9]],"batl":[[0,1.42,70.57]],"ltp":1.42,"tv":15340.47,"id":2249229}],"tv":18589.41}]}
{"op":"mcm","clk":"4211677456","pt":1631348908375,"mc":[{"id":"1.187528277","rc":[{"batb":[[1,1.4,588.47]],"ltp":1.42,"tv":15340.47,"id":2249229}]}]}
{"op":"mcm","clk":"4211692309","pt":1631349001591,"mc":[{"id":"1.187528277","rc":[{"batb":[[1,1.4,600.87]],"ltp":1.42,"tv":15340.47,"id":2249229}]}]}
{"op":"mcm","clk":"4211693706","pt":1631349009389,"mc":[{"id":"1.187528277","rc":[{"trd":[[3.4,268.1]],"batl":[[0,3.4,102.29]],"ltp":3.4,"tv":3272.82,"id":19924831}],"tv":18613.29}]}
{"op":"mcm","clk":"4211695743","pt":1631349022053,"mc":[{"id":"1.187528277","rc":[{"trd":[[3.35,2309.23]],"ltp":3.35,"tv":3299.41,"id":19924831},{"trd":[[1.42,11050.63]],"batl":[[0,1.42,7.84]],"ltp":1.42,"tv":15403.2,"id":2249229}],"tv":18702.61}]}
{"op":"mcm","clk":"4211714839","pt":1631349135656,"mc":[{"id":"1.187528277","rc":[{"batb":[[0,1.41,5395.01]],"ltp":1.42,"tv":15403.2,"id":2249229}]}]}
{"op":"mcm","clk":"4211714979","pt":1631349136544,"mc":[{"id":"1.187528277","rc":[{"batb":[[0,3.3,309.42]],"ltp":3.35,"tv":3299.41,"id":19924831},{"batl":[[1,1.43,1814]],"ltp":1.42,"tv":15403.2,"id":2249229}]}]}
{"op":"mcm","clk":"4211715097","pt":1631349137446,"mc":[{"id":"1.187528277","rc":[{"batl":[[0,3.4,111.51],[1,3.45,502.27]],"ltp":3.35,"tv":3299.41,"id":19924831}]}]}
{"op":"mcm","clk":"4211720502","pt":1631349170316,"mc":[{"id":"1.187528277","rc":[{"trd":[[1.42,11066.3]],"batb":[[0,1.42,172.1],[1,1.41,5395.01],[2,1.4,600.87]],"batl":[[0,1.43,1814],[1,1.44,927.71],[2,1.45,1354.16]],"ltp":1.42,"tv":15418.88,"id":2249229}],"tv":18718.29}]}
{"op":"mcm","clk":"4211722261","pt":1631349180635,"mc":[{"id":"1.187528277","rc":[{"batb":[[0,3.35,53.73],[1,3.3,309.42],[2,3.25,27.33]],"ltp":3.35,"tv":3299.41,"id":19924831},{"batb":[[1,1.41,2066.41],[2,1.4,398.12]],"ltp":1.42,"tv":15418.88,"id":2249229}]}]}
{"op":"mcm","clk":"4211722279","pt":1631349180743,"mc":[{"id":"1.187528277","rc":[{"batb":[[2,1.4,315.41]],"ltp":1.42,"tv":15418.88,"id":2249229}]}]}
{"op":"mcm","clk":"4211722622","pt":1631349182701,"mc":[{"id":"1.187528277","rc":[{"batb":[[0,1.42,197.92],[1,1.41,1731.59]],"ltp":1.42,"tv":15418.88,"id":2249229}]}]}
{"op":"mcm","clk":"4211722756","pt":1631349183350,"mc":[{"id":"1.187528277","rc":[{"batb":[[2,3.25,93.09]],"ltp":3.35,"tv":3299.41,"id":19924831},{"batl":[[1,1.44,1173.22]],"ltp":1.42,"tv":15418.88,"id":2249229}]}]}
{"op":"mcm","clk":"4211722822","pt":1631349183759,"mc":[{"id":"1.187528277","rc":[{"batl":[[0,3.4,123.67]],"ltp":3.35,"tv":3299.41,"id":19924831}]}]}
{"op":"mcm","clk":"4211726256","pt":1631349205892,"mc":[{"id":"1.187528277","rc":[{"batb":[[0,1.42,152.57]],"ltp":1.42,"tv":15418.88,"id":2249229}]}]}
{"op":"mcm","clk":"4211728219","pt":1631349217639,"mc":[{"id":"1.187528277","rc":[{"trd":[[1.43,2536.97]],"batl":[[0,1.43,1768.8]],"ltp":1.43,"tv":15509.29,"id":2249229}],"tv":18808.7}]}
{"op":"mcm","clk":"4211731281","pt":1631349236575,"mc":[{"id":"1.187528277","rc":[{"batb":[[2,3.25,27.33]],"ltp":3.35,"tv":3299.41,"id":19924831},{"batl":[[1,1.44,1210.05]],"ltp":1.43,"tv":15509.29,"id":2249229}]}]}
{"op":"mcm","clk":"4211731392","pt":1631349237202,"mc":[{"id":"1.187528277","rc":[{"batl":[[1,3.45,383.66]],"ltp":3.35,"tv":3299.41,"id":19924831},{"batb":[[0,1.42,25.81]],"ltp":1.43,"tv":15509.29,"id":2249229}]}]}
{"op":"mcm","clk":"4211743902","pt":1631349318531,"mc":[{"id":"1.187528277","rc":[{"batb":[[0,1.42,3.87]],"batl":[[1,1.44,1215.57]],"ltp":1.43,"tv":15509.29,"id":2249229}]}]}
{"op":"mcm","clk":"4211744067","pt":1631349319643,"mc":[{"id":"1.187528277","rc":[{"batl":[[0,3.4,116.33],[1,3.45,365.87]],"ltp":3.35,"tv":3299.41,"id":19924831}]}]}
{"op":"mcm","clk":"4211776504","pt":1631349545745,"mc":[{"id":"1.187528277","rc":[{"trd":[[1.42,11074.05]],"batb":[[0,1.41,1731.59],[1,1.4,315.41],[2,1.39,144.6]],"batl":[[0,1.42,189.38],[1,1.43,1768.8],[2,1.44,1215.57]],"ltp":1.42,"tv":15517.03,"id":2249229}],"tv":18816.44}]}
{"op":"mcm","clk":"4211778006","pt":1631349556573,"mc":[{"id":"1.187528277","rc":[{"batl":[[0,3.4,63.39]],"ltp":3.35,"tv":3299.41,"id":19924831},{"trd":[[1.41,803.31]],"batb":[[0,1.41,1669.87]],"batl":[[0,1.43,1894.67],[1,1.44,1215.57],[2,1.45,1354.16]],"ltp":1.41,"tv":15895.78,"id":2249229}],"tv":19195.19}]}
{"op":"mcm","clk":"4211779488","pt":1631349566550,"mc":[{"id":"1.187528277","rc":[{"batb":[[0,3.35,68.08]],"batl":[[0,3.4,84.73]],"ltp":3.35,"tv":3299.41,"id":19924831}]}]}
{"op":"mcm","clk":"4211780233","pt":1631349571330,"mc":[{"id":"1.187528277","rc":[{"batb":[[1,1.4,507.34]],"ltp":1.41,"tv":15895.78,"id":2249229}]}]}
{"op":"mcm","clk":"4211780386","pt":1631349572371,"mc":[{"id":"1.187528277","rc":[{"batb":[[0,1.41,1663.38]],"ltp":1.41,"tv":15895.78,"id":2249229}]}]}
{"op":"mcm","clk":"4211780500","pt":1631349573059,"mc":[{"id":"1.187528277","rc":[{"batl":[[0,1.43,1905.42]],"ltp":1.41,"tv":15895.78,"id":2249229}]}]}
{"op":"mcm","clk":"4211780772","pt":1631349574638,"mc":[{"id":"1.187528277","rc":[{"trd":[[3.35,2330.51]],"batb":[[0,3.35,57.44],[1,3.3,314.2]],"batl":[[0,3.4,79.91]],"ltp":3.35,"tv":3320.68,"id":19924831}],"tv":19216.47}]}
{"op":"mcm","clk":"4211780850","pt":1631349575162,"mc":[{"id":"1.187528277","rc":[{"batl":[[1,3.45,361.58]],"ltp":3.35,"tv":3320.68,"id":19924831}]}]}
{"op":"mcm","clk":"4211782532","pt":1631349585681,"mc":[{"id":"1.187528277","rc":[{"batl":[[0,1.43,1779.55]],"ltp":1.41,"tv":15895.78,"id":2249229}]}]}
{"op":"mcm","clk":"4211784818","pt":1631349600579,"mc":[{"id":"1.187528277","rc":[{"batb":[[0,3.35,71.88]],"batl":[[0,3.4,108.06]],"ltp":3.35,"tv":3320.68,"id":19924831}]}]}
{"op":"mcm","clk":"4211784991","pt":1631349601993,"mc":[{"id":"1.187528277","rc":[{"batb":[[0,3.35,57.53]],"ltp":3.35,"tv":3320.68,"id":19924831}]}]}
{"op":"mcm","clk":"4211789838","pt":1631349635633,"mc":[{"id":"1.187528277","rc":[{"batb":[[0,3.35,323.43]],"ltp":3.35,"tv":3320.68,"id":19924831}]}]}
{"op":"mcm","clk":"4211789866","pt":1631349635841,"mc":[{"id":"1.187528277","rc":[{"batl":[[0,1.43,1905.42]],"ltp":1.41,"tv":15895.78,"id":2249229}]}]}
{"op":"mcm","clk":"4211790131","pt":1631349637529,"mc":[{"id":"1.187528277","rc":[{"batl":[[0,3.4,79.91]],"ltp":3.35,"tv":3320.68,"id":19924831}]}]}
{"op":"mcm","clk":"4211790277","pt":1631349638632,"mc":[{"id":"1.187528277","rc":[{"batl":[[0,3.4,58.57]],"ltp":3.35,"tv":3320.68,"id":19924831}]}]}
{"op":"mcm","clk":"4211790354","pt":1631349639210,"mc":[{"id":"1.187528277","rc":[{"batb":[[1,1.4,534.54]],"ltp":1.41,"tv":15895.78,"id":2249229}]}]}
{"op":"mcm","clk":"4211790783","pt":1631349642151,"mc":[{"id":"1.187528277","rc":[{"batl":[[0,1.43,1894.67]],"ltp":1.41,"tv":15895.78,"id":2249229}]}]}
{"op":"mcm","clk":"4211790894","pt":1631349642832,"mc":[{"id":"1.187528277","rc":[{"batl":[[0,1.43,1880.68]],"ltp":1.41,"tv":15895.78,"id":2249229}]}]}
{"op":"mcm","clk":"4211791050","pt":1631349643827,"mc":[{"id":"1.187528277","rc":[{"batb":[[1,3.3,309.42]],"ltp":3.35,"tv":3320.68,"id":19924831}]}]}
{"op":"mcm","clk":"4211791267","pt":1631349645242,"mc":[{"id":"1.187528277","rc":[{"batb":[[1,3.3,297.33]],"ltp":3.35,"tv":3320.68,"id":19924831}]}]}
{"op":"mcm","clk":"4211795893","pt":1631349675395,"mc":[{"id":"1.187528277","rc":[{"batb":[[2,3.25,35.87]],"batl":[[0,3.4,32.09],[1,3.45,395.74]],"ltp":3.35,"tv":3320.68,"id":19924831},{"batl":[[1,1.44,1275.36],[2,1.45,1269.6]],"ltp":1.41,"tv":15895.78,"id":2249229}]}]}
{"op":"mcm","clk":"4211800297","pt":1631349705423,"mc":[{"id":"1.187528277","rc":[{"batb":[[2,1.5,3617.07]],"batl":[[1,3.45,361.58]],"ltp":3.35,"tv":3320.68,"id":19924831},{"batb":[[0,1.41,1578.83]],"batl":[[1,1.44,1215.57]],"ltp":1.41,"tv":15895.78,"id":2249229}]}]}
{"op":"mcm","clk":"4211804051","pt":1631349731591,"mc":[{"id":"1.187528277","rc":[{"batb":[[1,1.4,538.62]],"ltp":1.41,"tv":15895.78,"id":2249229}]}]}
{"op":"mcm","clk":"4211804241","pt":1631349732701,"mc":[{"id":"1.187528277","rc":[{"batl":[[0,3.4,22.87]],"ltp":3.35,"tv":3320.68,"id":19924831},{"batb":[[0,1.41,1540.23]],"ltp":1.41,"tv":15895.78,"id":2249229}]}]}
{"op":"mcm","clk":"4211804327","pt":1631349733171,"mc":[{"id":"1.187528277","rc":[{"batl":[[1,3.45,356.99]],"ltp":3.35,"tv":3320.68,"id":19924831}]}]}
{"op":"mcm","clk":"4211815063","pt":1631349804843,"mc":[{"id":"1.187528277","rc":[{"batb":[[2,3.25,33.31]],"batl":[[1,3.45,390.3]],"ltp":3.35,"tv":3320.68,"id":19924831},{"batb":[[0,1.41,1625.63]],"batl":[[1,1.44,1275.36]],"ltp":1.41,"tv":15895.78,"id":2249229}]}]}
{"op":"mcm","clk":"4211816096","pt":1631349811415,"mc":[{"id":"1.187528277","rc":[{"batb":[[0,1.41,1629.32],[1,1.4,549.85]],"ltp":1.41,"tv":15895.78,"id":2249229}]}]}
{"op":"mcm","clk":"4211816219","pt":1631349812141,"mc":[{"id":"1.187528277","rc":[{"batl":[[1,3.45,393.68]],"ltp":3.35,"tv":3320.68,"id":19924831},{"batl":[[1,1.44,1279.98]],"ltp":1.41,"tv":15895.78,"id":2249229}]}]}
{"op":"mcm","clk":"4211819969","pt":1631349836641,"mc":[{"id":"1.187528277","rc":[{"batb":[[0,1.42,17],[1,1.41,1629.32],[2,1.4,549.85]],"ltp":1.41,"tv":15895.78,"id":2249229}]}]}
{"op":"mcm","clk":"4211820004","pt":1631349836851,"mc":[{"id":"1.187528277","rc":[{"trd":[[1.42,11108.05]],"batb":[[0,1.41,1629.32],[1,1.4,549.85],[2,1.39,144.6]],"ltp":1.42,"tv":15929.78,"id":2249229}],"tv":19250.47}]}
{"op":"mcm","clk":"4211824620","pt":1631349866530,"mc":[{"id":"1.187528277","rc":[{"batb":[[1,1.4,552.79]],"ltp":1.42,"tv":15929.78,"id":2249229}]}]}
{"op":"mcm","clk":"4211826915","pt":1631349882156,"mc":[{"id":"1.187528277","rc":[{"trd":[[1.43,2696.51]],"batl":[[0,1.43,1800.92]],"ltp":1.43,"tv":16089.32,"id":2249229}],"tv":19410.01}]}
{"op":"mcm","clk":"4211843788","pt":1631349987734,"mc":[{"id":"1.187528277","rc":[{"batb":[[0,1.41,1666.07]],"ltp":1.43,"tv":16089.32,"id":2249229}]}]}
{"op":"mcm","clk":"4211850230","pt":1631350030514,"mc":[{"id":"1.187528277","rc":[{"batb":[[0,1.41,1672.13]],"ltp":1.43,"tv":16089.32,"id":2249229}]}]}
{"op":"mcm","clk":"4211850275","pt":1631350030933,"mc":[{"id":"1.187528277","rc":[{"batl":[[1,3.45,396.67]],"ltp":3.35,"tv":3320.68,"id":19924831}]}]}
{"op":"mcm","clk":"4211853858","pt":1631350055395,"mc":[{"id":"1.187528277","rc":[{"trd":[[3.35,2402.25]],"batb":[[0,3.35,287.56],[2,3.2,25.62]],"batl":[[0,3.4,75.81],[1,3.45,363.36]],"ltp":3.35,"tv":3392.42,"id":19924831},{"batb":[[0,1.42,121.27],[1,1.41,1586.73],[2,1.4,552.79]],"batl":[[1,1.44,1220.2]],"ltp":1.43,"tv":16089.32,"id":2249229}],"tv":19481.75}]}
{"op":"mcm","clk":"4211854063","pt":1631350057119,"mc":[{"id":"1.187528277","rc":[{"batb":[[1,1.41,1549.98]],"ltp":1.43,"tv":16089.32,"id":2249229}]}]}
{"op":"mcm","clk":"4211857276","pt":1631350079566,"mc":[{"id":"1.187528277","rc":[{"batb":[[2,1.4,538.62]],"ltp":1.43,"tv":16089.32,"id":2249229}]}]}
{"op":"mcm","clk":"4211857428","pt":1631350080564,"mc":[{"id":"1.187528277","rc":[{"batb":[[2,1.4,346.7]],"ltp":1.43,"tv":16089.32,"id":2249229}]}]}
{"op":"mcm","clk":"4211857589","pt":1631350081669,"mc":[{"id":"1.187528277","rc":[{"batb":[[2,1.4,315.41]],"ltp":1.43,"tv":16089.32,"id":2249229}]}]}
{"op":"mcm","clk":"4211857762","pt":1631350082665,"mc":[{"id":"1.187528277","rc":[{"batl":[[0,3.4,88.66]],"ltp":3.35,"tv":3392.42,"id":19924831},{"batb":[[0,1.42,139.47]],"ltp":1.43,"tv":16089.32,"id":2249229}]}]}
{"op":"mcm","clk":"4211857893","pt":1631350083452,"mc":[{"id":"1.187528277","rc":[{"batl":[[1,3.45,356.99]],"ltp":3.35,"tv":3392.42,"id":19924831}]}]}
{"op":"mcm","clk":"4211857960","pt":1631350083973,"mc":[{"id":"1.187528277","rc":[{"batl":[[1,3.45,351.7]],"ltp":3.35,"tv":3392.42,"id":19924831}]}]}
{"op":"mcm","clk":"4211858224","pt":1631350085452,"mc":[{"id":"1.187528277","rc":[{"batb":[[2,3.2,51.24]],"batl":[[0,3.4,122.82]],"ltp":3.35,"tv":3392.42,"id":19924831},{"batb":[[0,1.42,84.81]],"batl":[[2,1.45,1355.86]],"ltp":1.43,"tv":16089.32,"id":2249229}]}]}
{"op":"mcm","clk":"4211861820","pt":1631350109655,"mc":[{"id":"1.187528277","rc":[{"trd":[[1.42,11277.67]],"batb":[[0,1.41,1549.98],[1,1.4,315.41],[2,1.39,144.6]],"batl":[[0,1.42,25.13],[1,1.43,1800.92],[2,1.44,1220.2]],"ltp":1.42,"tv":16258.94,"id":2249229}],"tv":19651.37}]}
{"op":"mcm","clk":"4211861889","pt":1631350110076,"mc":[{"id":"1.187528277","rc":[{"batb":[[0,1.41,4023.93]],"batl":[[1,1.43,1675.05]],"ltp":1.42,"tv":16258.94,"id":2249229}]}]}
{"op":"mcm","clk":"4211862139","pt":1631350111687,"mc":[{"id":"1.187528277","rc":[{"batb":[[0,1.41,1586.73]],"ltp":1.42,"tv":16258.94,"id":2249229}]}]}
{"op":"mcm","clk":"4211862487","pt":1631350113483,"mc":[{"id":"1.187528277","rc":[{"batb":[[2,3.25,42.7]],"batl":[[0,3.4,35.72],[1,3.45,393.54]],"ltp":3.35,"tv":3392.42,"id":19924831},{"batb":[[0,1.41,1670.43]],"ltp":1.42,"tv":16258.94,"id":2249229}]}]}
{"op":"mcm","clk":"4211863293","pt":1631350118679,"mc":[{"id":"1.187528277","rc":[{"batl":[[0,1.43,1675.05],[1,1.44,1220.2],[2,1.45,1318.29]],"ltp":1.42,"tv":16258.94,"id":2249229}]}]}
{"op":"mcm","clk":"4211863320","pt":1631350118886,"mc":[{"id":"1.187528277","rc":[{"batl":[[0,1.42,25.13],[1,1.43,1780.49],[2,1.44,1220.2]],"ltp":1.42,"tv":16258.94,"id":2249229}]}]}
{"op":"mcm","clk":"4211866865","pt":1631350140743,"mc":[{"id":"1.187528277","rc":[{"trd":[[1.41,891.26]],"batb":[[0,1.41,1626.45]],"ltp":1.41,"tv":16346.89,"id":2249229}],"tv":19739.32}]}
{"op":"mcm","clk":"4211867444","pt":1631350144351,"mc":[{"id":"1.187528277","rc":[{"batl":[[2,1.44,937.85]],"ltp":1.41,"tv":16346.89,"id":2249229}]}]}
{"op":"mcm","clk":"4211867600","pt":1631350145352,"mc":[{"id":"1.187528277","rc":[{"batl":[[2,1.44,927.71]],"ltp":1.41,"tv":16346.89,"id":2249229}]}]}
{"op":"mcm","clk":"4211867752","pt":1631350146428,"mc":[{"id":"1.187528277","rc":[{"batb":[[1,1.4,517.57]],"batl":[[1,1.43,1790.57]],"ltp":1.41,"tv":16346.89,"id":2249229}]}]}
{"op":"mcm","clk":"4211867936","pt":1631350147624,"mc":[{"id":"1.187528277","rc":[{"batb":[[1,3.3,301.28]],"batl":[[0,3.4,22.87],[1,3.45,402.76]],"ltp":3.35,"tv":3392.42,"id":19924831}]}]}
{"op":"mcm","clk":"4211869412","pt":1631350157680,"mc":[{"id":"1.187528277","rc":[{"trd":[[1.41,934.95]],"batb":[[0,1.41,1604.61]],"ltp":1.41,"tv":16390.58,"id":2249229}],"tv":19783.01}]}
{"op":"mcm","clk":"4211875888","pt":1631350203674,"mc":[{"id":"1.187528277","rc":[{"trd":[[1.42,11297.67]],"batl":[[0,1.42,15.13]],"ltp":1.42,"tv":16410.58,"id":2249229}],"tv":19803.01}]}
{"op":"mcm","clk":"4211876197","pt":1631350205672,"mc":[{"id":"1.187528277","rc":[{"batb":[[1,1.4,551.3]],"ltp":1.42,"tv":16410.58,"id":2249229}]}]}
{"op":"mcm","clk":"4211879304","pt":1631350227393,"mc":[{"id":"1.187528277","rc":[{"batl":[[0,3.4,75.81]],"ltp":3.35,"tv":3392.42,"id":19924831},{"trd":[[1.42,11327.93]],"batb":[[0,1.42,38.05],[1,1.41,1604.61],[2,1.4,551.3]],"batl":[[0,1.43,1790.57],[1,1.44,927.71],[2,1.45,1399.42]],"ltp":1.42,"tv":16440.85,"id":2249229}],"tv":19833.28}]}
{"op":"mcm","clk":"4211879386","pt":1631350228071,"mc":[{"id":"1.187528277","rc":[{"batb":[[1,1.41,1567.86]],"ltp":1.42,"tv":16440.85,"id":2249229}]}]}
{"op":"mcm","clk":"4211883095","pt":1631350253341,"mc":[{"id":"1.187528277","rc":[{"batb":[[2,1.4,315.41]],"ltp":1.42,"tv":16440.85,"id":2249229}]}]}
{"op":"mcm","clk":"4211883222","pt":1631350254343,"mc":[{"id":"1.187528277","rc":[{"batb":[[0,1.42,43.75],[1,1.41,1572.27]],"ltp":1.42,"tv":16440.85,"id":2249229}]}]}
{"op":"mcm","clk":"4211883357","pt":1631350255327,"mc":[{"id":"1.187528277","rc":[{"batl":[[0,3.4,83.45]],"ltp":3.35,"tv":3392.42,"id":19924831},{"batb":[[1,1.41,1550.83]],"batl":[[1,1.44,1170.42]],"ltp":1.42,"tv":16440.85,"id":2249229}]}]}
{"op":"mcm","clk":"4211883632","pt":1631350257419,"mc":[{"id":"1.187528277","rc":[{"trd":[[3.35,2456.05]],"batb":[[0,3.35,298.45]],"batl":[[0,3.4,97.67]],"ltp":3.35,"tv":3446.22,"id":19924831},{"batb":[[0,1.42,78.77]],"ltp":1.42,"tv":16440.85,"id":2249229}],"tv":19887.08}]}
{"op":"mcm","clk":"4211883745","pt":1631350258460,"mc":[{"id":"1.187528277","rc":[{"batb":[[0,1.42,43.75]],"ltp":1.42,"tv":16440.85,"id":2249229}]}]}
{"op":"mcm","clk":"4211891542","pt":1631350311452,"mc":[{"id":"1.187528277","rc":[{"batb":[[1,1.41,1556.19]],"batl":[[1,1.44,1206.83]],"ltp":1.42,"tv":16440.85,"id":2249229}]}]}
{"op":"mcm","clk":"4211891589","pt":1631350311866,"mc":[{"id":"1.187528277","rc":[{"batl":[[0,3.4,101.31]],"ltp":3.35,"tv":3446.22,"id":19924831}]}]}
{"op":"mcm","clk":"4211900613","pt":1631350379233,"mc":[{"id":"1.187528277","rc":[{"batl":[[1,1.44,1212.29]],"ltp":1.42,"tv":16440.85,"id":2249229}]}]}
{"op":"mcm","clk":"4211936676","pt":1631350639304,"mc":[{"id":"1.187528277","rc":[{"batb":[[0,1.42,56.06]],"ltp":1.42,"tv":16440.85,"id":2249229}]}]}
{"op":"mcm","clk":"4211940356","pt":1631350665329,"mc":[{"id":"1.187528277","rc":[{"batb":[[1,1.41,1582.78]],"ltp":1.42,"tv":16440.85,"id":2249229}]}]}
{"op":"mcm","clk":"4211942564","pt":1631350681149,"mc":[{"id":"1.187528277","rc":[{"batb":[[0,1.42,58.76],[1,1.41,1588.88]],"ltp":1.42,"tv":16440.85,"id":2249229}]}]}
{"op":"mcm","clk":"4211979985","pt":1631350931023,"mc":[{"id":"1.187528277","rc":[{"trd":[[1.42,11347.94]],"batb":[[0,1.42,48.76]],"ltp":1.42,"tv":16460.85,"id":2249229}],"tv":19907.08}]}
{"op":"mcm","clk":"4212020021","pt":1631351167262,"mc":[{"id":"1.187528277","rc":[{"trd":[[3.35,2457]],"batb":[[0,3.35,297.98]],"ltp":3.35,"tv":3447.17,"id":19924831}],"tv":19908.03}]}
{"op":"mcm","clk":"4212026949","pt":1631351205306,"mc":[{"id":"1.187528277","rc":[{"batb":[[0,1.42,233.9]],"ltp":1.42,"tv":16460.85,"id":2249229}]}]}
{"op":"mcm","clk":"4212034703","pt":1631351246582,"mc":[{"id":"1.187528277","rc":[{"batb":[[0,1.42,260.58]],"ltp":1.42,"tv":16460.85,"id":2249229}]}]}
{"op":"mcm","clk":"4212034764","pt":1631351246849,"mc":[{"id":"1.187528277","rc":[{"batl":[[0,3.4,113.77]],"ltp":3.35,"tv":3447.17,"id":19924831}]}]}
{"op":"mcm","clk":"4212044096","pt":1631351303507,"mc":[{"id":"1.187528277","rc":[{"batl":[[0,3.4,117.31]],"ltp":3.35,"tv":3447.17,"id":19924831},{"batb":[[0,1.42,264.58],[1,1.41,1594.31]],"ltp":1.42,"tv":16460.85,"id":2249229}]}]}
{"op":"mcm","clk":"4212054280","pt":1631351364291,"mc":[{"id":"1.187528277","rc":[{"trd":[[3.35,2749.2]],"batb":[[0,3.35,151.87]],"ltp":3.35,"tv":3739.38,"id":19924831}],"tv":20200.23}]}
{"op":"mcm","clk":"4212054552","pt":1631351365677,"mc":[{"id":"1.187528277","rc":[{"batb":[[0,1.42,79.44]],"ltp":1.42,"tv":16460.85,"id":2249229}]}]}
{"op":"mcm","clk":"4212056728","pt":1631351377827,"mc":[{"id":"1.187528277","rc":[{"trd":[[3.35,2908.74]],"batb":[[0,3.35,72.1]],"ltp":3.35,"tv":3898.92,"id":19924831}],"tv":20359.77}]}
{"op":"mcm","clk":"4212059611","pt":1631351394345,"mc":[{"id":"1.187528277","rc":[{"batb":[[1,3.3,472.09]],"ltp":3.35,"tv":3898.92,"id":19924831}]}]}
{"op":"mcm","clk":"4212065375","pt":1631351427015,"mc":[{"id":"1.187528277","rc":[{"batb":[[0,1.42,75.44]],"ltp":1.42,"tv":16460.85,"id":2249229}]}]}
{"op":"mcm","clk":"4212065670","pt":1631351428602,"mc":[{"id":"1.187528277","rc":[{"batl":[[0,3.4,113.77]],"ltp":3.35,"tv":3898.92,"id":19924831},{"batb":[[0,1.42,52.27]],"batl":[[1,1.44,1220.2]],"ltp":1.42,"tv":16460.85,"id":2249229}]}]}
{"op":"mcm","clk":"4212065757","pt":1631351429125,"mc":[{"id":"1.187528277","rc":[{"batl":[[0,3.4,106.49]],"ltp":3.35,"tv":3898.92,"id":19924831}]}]}
{"op":"mcm","clk":"4212065970","pt":1631351430499,"mc":[{"id":"1.187528277","rc":[{"trd":[[3.35,2918.74]],"batb":[[0,3.35,67.1]],"ltp":3.35,"tv":3908.92,"id":19924831}],"tv":20369.77}]}
{"op":"mcm","clk":"4212066189","pt":1631351431711,"mc":[{"id":"1.187528277","rc":[{"batb":[[0,1.42,584.19]],"ltp":1.42,"tv":16460.85,"id":2249229}]}]}
{"op":"mcm","clk":"4212071939","pt":1631351465682,"mc":[{"id":"1.187528277","rc":[{"batb":[[0,1.42,595.94]],"ltp":1.42,"tv":16460.85,"id":2249229}]}]}
{"op":"mcm","clk":"4212077024","pt":1631351494696,"mc":[{"id":"1.187528277","rc":[{"batb":[[0,1.42,673.42]],"ltp":1.42,"tv":16460.85,"id":2249229}]}]}
{"op":"mcm","clk":"4212077123","pt":1631351495237,"mc":[{"id":"1.187528277","rc":[{"batb":[[0,3.35,29.31]],"batl":[[0,3.4,137.22]],"ltp":3.35,"tv":3908.92,"id":19924831},{"batl":[[0,1.43,1685.13]],"ltp":1.42,"tv":16460.85,"id":2249229}]}]}
{"op":"mcm","clk":"4212079501","pt":1631351508332,"mc":[{"id":"1.187528277","rc":[{"batb":[[0,3.3,472.09],[1,3.25,42.7],[2,1.5,3617.07]],"ltp":3.35,"tv":3908.92,"id":19924831}]}]}
{"op":"mcm","clk":"4212086684","pt":1631351550848,"mc":[{"id":"1.187528277","rc":[{"trd":[[1.42,11547.94]],"batb":[[0,1.42,573.41]],"ltp":1.42,"tv":16660.86,"id":2249229}],"tv":20569.78}]}
{"op":"mcm","clk":"4212091901","pt":1631351582672,"mc":[{"id":"1.187528277","rc":[{"batb":[[0,1.42,581.95],[1,1.41,1603.6]],"batl":[[0,1.43,1689.56]],"ltp":1.42,"tv":16660.86,"id":2249229}]}]}
{"op":"mcm","clk":"4212092078","pt":1631351583683,"mc":[{"id":"1.187528277","rc":[{"batb":[[0,3.3,474.94],[1,3.25,130.2]],"batl":[[0,3.4,140.42]],"ltp":3.35,"tv":3908.92,"id":19924831}]}]}
{"op":"mcm","clk":"4212106802","pt":1631351673590,"mc":[{"id":"1.187528277","rc":[{"batb":[[1,3.25,143.33]],"ltp":3.35,"tv":3908.92,"id":19924831}]}]}
{"op":"mcm","clk":"4212107158","pt":1631351676062,"mc":[{"id":"1.187528277","rc":[{"trd":[[1.43,2717.78]],"batl":[[0,1.43,1678.93]],"ltp":1.43,"tv":16682.13,"id":2249229}],"tv":20591.05}]}
{"op":"mcm","clk":"4212136350","pt":1631351857458,"mc":[{"id":"1.187528277","rc":[{"batl":[[0,3.35,4],[1,3.4,140.42],[2,3.45,350.59]],"ltp":3.35,"tv":3908.92,"id":19924831},{"batb":[[0,1.42,708.71]],"ltp":1.43,"tv":16682.13,"id":2249229}]}]}
{"op":"mcm","clk":"4212142320","pt":1631351893351,"mc":[{"id":"1.187528277","rc":[{"batl":[[2,3.45,347.21]],"ltp":3.35,"tv":3908.92,"id":19924831}]}]}
{"op":"mcm","clk":"4212142541","pt":1631351894514,"mc":[{"id":"1.187528277","rc":[{"batl":[[2,3.45,337.33]],"ltp":3.35,"tv":3908.92,"id":19924831}]}]}
{"op":"mcm","clk":"4212142742","pt":1631351895528,"mc":[{"id":"1.187528277","rc":[{"batl":[[2,3.45,328.12]],"ltp":3.35,"tv":3908.92,"id":19924831}]}]}
{"op":"mcm","clk":"4212142912","pt":1631351896556,"mc":[{"id":"1.187528277","rc":[{"batl":[[2,3.45,199.5]],"ltp":3.35,"tv":3908.92,"id":19924831}]}]}
{"op":"mcm","clk":"4212143109","pt":1631351897720,"mc":[{"id":"1.187528277","rc":[{"batl":[[2,3.45,191.85]],"ltp":3.35,"tv":3908.92,"id":19924831},{"batb":[[0,1.42,730.42]],"ltp":1.43,"tv":16682.13,"id":2249229}]}]}
{"op":"mcm","clk":"4212143168","pt":1631351898054,"mc":[{"id":"1.187528277","rc":[{"batl":[[1,3.4,149.38]],"ltp":3.35,"tv":3908.92,"id":19924831}]}]}
{"op":"mcm","clk":"4212155803","pt":1631351971715,"mc":[{"id":"1.187528277","rc":[{"batb":[[1,1.41,1607.32]],"ltp":1.43,"tv":16682.13,"id":2249229}]}]}
{"op":"mcm","clk":"4212155894","pt":1631351972397,"mc":[{"id":"1.187528277","rc":[{"batl":[[1,3.4,152.08]],"ltp":3.35,"tv":3908.92,"id":19924831},{"batb":[[0,1.42,733.67]],"ltp":1.43,"tv":16682.13,"id":2249229}]}]}
{"op":"mcm","clk":"4212168406","pt":1631352042194,"mc":[{"id":"1.187528277","rc":[{"batb":[[0,1.42,752.67]],"ltp":1.43,"tv":16682.13,"id":2249229}]}]}
{"op":"mcm","clk":"4212173003","pt":1631352067214,"mc":[{"id":"1.187528277","rc":[{"batb":[[0,1.42,756.01]],"ltp":1.43,"tv":16682.13,"id":2249229}]}]}
{"op":"mcm","clk":"4212195487","pt":1631352186703,"mc":[{"id":"1.187528277","rc":[{"batb":[[2,2.78,22.83]],"ltp":3.35,"tv":3908.92,"id":19924831}]}]}
{"op":"mcm","clk":"4212216767","pt":1631352309165,"mc":[{"id":"1.187528277","rc":[{"trd":[[3.3,1097.56]],"batb":[[0,3.3,223.72]],"ltp":3.3,"tv":4411.35,"id":19924831}],"tv":21093.48}]}
{"op":"mcm","clk":"4212218546","pt":1631352319397,"mc":[{"id":"1.187528277","rc":[{"batl":[[0,1.43,1674.5]],"ltp":1.43,"tv":16682.13,"id":2249229}]}]}
{"op":"mcm","clk":"4212218750","pt":1631352320568,"mc":[{"id":"1.187528277","rc":[{"batl":[[0,1.43,1621.2]],"ltp":1.43,"tv":16682.13,"id":2249229}]}]}
{"op":"mcm","clk":"4212218849","pt":1631352321202,"mc":[{"id":"1.187528277","rc":[{"batl":[[0,1.43,1549.14]],"ltp":1.43,"tv":16682.13,"id":2249229}]}]}
{"op":"mcm","clk":"4212219049","pt":1631352322370,"mc":[{"id":"1.187528277","rc":[{"batl":[[1,1.44,1206.83]],"ltp":1.43,"tv":16682.13,"id":2249229}]}]}
{"op":"mcm","clk":"4212219268","pt":1631352323588,"mc":[{"id":"1.187528277","rc":[{"batb":[[0,3.3,282.66]],"ltp":3.3,"tv":4411.35,"id":19924831},{"batl":[[1,1.44,1187.64]],"ltp":1.43,"tv":16682.13,"id":2249229}]}]}
{"op":"mcm","clk":"4212225144","pt":1631352358064,"mc":[{"id":"1.187528277","rc":[{"trd":[[3.3,1101.56]],"batb":[[0,3.3,280.66]],"ltp":3.3,"tv":4415.35,"id":19924831}],"tv":21097.48}]}
{"op":"mcm","clk":"4212229957","pt":1631352388931,"mc":[{"id":"1.187528277","rc":[{"batl":[[1,1.44,1202.33]],"ltp":1.43,"tv":16682.13,"id":2249229}]}]}
{"op":"mcm","clk":"4212230973","pt":1631352395125,"mc":[{"id":"1.187528277","rc":[{"trd":[[1.43,3177.77]],"batl":[[0,1.43,1319.15]],"ltp":1.43,"tv":17142.12,"id":2249229}],"tv":21557.47}]}
{"op":"mcm","clk":"4212235578","pt":1631352422668,"mc":[{"id":"1.187528277","rc":[{"batb":[[0,3.3,380.66]],"ltp":3.3,"tv":4415.35,"id":19924831}]}]}
{"op":"mcm","clk":"4212240613","pt":1631352451006,"mc":[{"id":"1.187528277","rc":[{"batl":[[1,1.44,1220.2]],"ltp":1.43,"tv":17142.12,"id":2249229}]}]}
{"op":"mcm","clk":"4212249361","pt":1631352501642,"mc":[{"id":"1.187528277","rc":[{"trd":[[1.42,11572.12]],"batb":[[0,1.42,743.93]],"ltp":1.42,"tv":17166.3,"id":2249229}],"tv":21581.65}]}
{"op":"mcm","clk":"4212326149","pt":1631352947817,"mc":[{"id":"1.187528277","rc":[{"trd":[[1.43,3214.57]],"batl":[[0,1.43,1300.75]],"ltp":1.43,"tv":17203.09,"id":2249229}],"tv":21618.45}]}
{"op":"mcm","clk":"4212402935","pt":1631353360981,"mc":[{"id":"1.187528277","rc":[{"trd":[[1.42,11672.12]],"batb":[[0,1.42,693.92]],"ltp":1.42,"tv":17303.1,"id":2249229}],"tv":21718.45}]}
{"op":"mcm","clk":"4212406914","pt":1631353384129,"mc":[{"id":"1.187528277","rc":[{"trd":[[3.3,1122.84]],"batb":[[0,3.3,370.02]],"ltp":3.3,"tv":4436.62,"id":19924831}],"tv":21739.73}]}
{"op":"mcm","clk":"4212433674","pt":1631353540272,"mc":[{"id":"1.187528277","rc":[{"trd":[[3.3,1128.21]],"batb":[[0,3.3,367.33]],"ltp":3.3,"tv":4442.0,"id":19924831}],"tv":21745.1}]}
{"op":"mcm","clk":"4212443365","pt":1631353604676,"mc":[{"id":"1.187528277","rc":[{"batb":[[1,3.25,124.54]],"batl":[[1,3.4,185.39],[2,3.45,150]],"ltp":3.3,"tv":4442.0,"id":19924831},{"batb":[[1,1.41,1659.41]],"batl":[[2,1.45,1355.01]],"ltp":1.42,"tv":17303.1,"id":2249229}]}]}
{"op":"mcm","clk":"4212443484","pt":1631353605265,"mc":[{"id":"1.187528277","rc":[{"batb":[[1,3.25,117.71]],"batl":[[1,3.4,219.55]],"ltp":3.3,"tv":4442.0,"id":19924831},{"batb":[[1,1.41,1707.24]],"ltp":1.42,"tv":17303.1,"id":2249229}]}]}
{"op":"mcm","clk":"4212443714","pt":1631353606562,"mc":[{"id":"1.187528277","rc":[{"batl":[[1,3.4,185.39]],"ltp":3.3,"tv":4442.0,"id":19924831},{"batb":[[1,1.41,1623.54]],"ltp":1.42,"tv":17303.1,"id":2249229}]}]}
{"op":"mcm","clk":"4212444897","pt":1631353614071,"mc":[{"id":"1.187528277","rc":[{"batb":[[1,3.25,138.21]],"batl":[[1,3.4,178.56]],"ltp":3.3,"tv":4442.0,"id":19924831},{"batl":[[2,1.45,1391.73]],"ltp":1.42,"tv":17303.1,"id":2249229}]}]}
{"op":"mcm","clk":"4212446788","pt":1631353625631,"mc":[{"id":"1.187528277","rc":[{"batb":[[1,1.41,1609.88]],"ltp":1.42,"tv":17303.1,"id":2249229}]}]}
{"op":"mcm","clk":"4212449403","pt":1631353643064,"mc":[{"id":"1.187528277","rc":[{"batb":[[1,3.25,143.33]],"ltp":3.3,"tv":4442.0,"id":19924831}]}]}
{"op":"mcm","clk":"4212473561","pt":1631353704741,"mc":[{"id":"1.187528277","rc":[{"trd":[[3.35,2926.74]],"batb":[[0,3.35,2.67],[1,3.3,367.33],[2,3.25,143.33]],"batl":[[0,3.4,178.56],[1,3.45,150],[2,3.5,25]],"ltp":3.35,"tv":4450.0,"id":19924831}],"tv":21753.1}]}
{"op":"mcm","clk":"4212474422","pt":1631353710718,"mc":[{"id":"1.187528277","rc":[{"batb":[[0,3.3,367.33],[1,3.25,143.33],[2,2.78,22.83]],"ltp":3.35,"tv":4450.0,"id":19924831}]}]}
{"op":"mcm","clk":"4212474438","pt":1631353710835,"mc":[{"id":"1.187528277","rc":[{"trd":[[3.4,273.45]],"batl":[[0,3.4,175.88]],"ltp":3.4,"tv":4455.35,"id":19924831}],"tv":21758.45}]}
{"op":"mcm","clk":"4212482367","pt":1631353764708,"mc":[{"id":"1.187528277","rc":[{"batl":[[0,3.4,180.24],[1,3.45,271.19]],"ltp":3.4,"tv":4455.35,"id":19924831}]}]}
{"op":"mcm","clk":"4212489509","pt":1631353812718,"mc":[{"id":"1.187528277","rc":[{"batl":[[0,3.4,153.77],[1,3.45,333.78]],"ltp":3.4,"tv":4455.35,"id":19924831},{"batl":[[1,1.44,1296.21],[2,1.45,1269.6]],"ltp":1.42,"tv":17303.1,"id":2249229}]}]}
{"op":"mcm","clk":"4212494167","pt":1631353843358,"mc":[{"id":"1.187528277","rc":[{"batb":[[1,3.25,150.35]],"batl":[[1,3.45,343.17]],"ltp":3.4,"tv":4455.35,"id":19924831}]}]}
{"op":"mcm","clk":"4212506349","pt":1631353908687,"mc":[{"id":"1.187528277","rc":[{"trd":[[1.43,3307.93]],"batl":[[0,1.43,1254.07]],"ltp":1.43,"tv":17396.46,"id":2249229}],"tv":21851.82}]}
{"op":"mcm","clk":"4212526251","pt":1631354023124,"mc":[{"id":"1.187528277","rc":[{"trd":[[1.42,11676.12]],"batb":[[0,1.42,691.92]],"ltp":1.42,"tv":17400.46,"id":2249229}],"tv":21855.82}]}
{"op":"mcm","clk":"4212564092","pt":1631354276632,"mc":[{"id":"1.187528277","rc":[{"trd":[[1.43,3455.12]],"batl":[[0,1.43,1180.48]],"ltp":1.43,"tv":17547.65,"id":2249229}],"tv":22003.0}]}
{"op":"mcm","clk":"4212579364","pt":1631354379028,"mc":[{"id":"1.187528277","rc":[{"trd":[[3.4,521.44]],"batl":[[0,3.4,82.71]],"ltp":3.4,"tv":4703.34,"id":19924831},{"batb":[[0,1.42,565.16]],"ltp":1.43,"tv":17547.65,"id":2249229}],"tv":22251.0}]}
{"op":"mcm","clk":"4212580785","pt":1631354388446,"mc":[{"id":"1.187528277","rc":[{"trd":[[3.3,1148.21]],"batb":[[0,3.3,357.33]],"ltp":3.3,"tv":4723.34,"id":19924831}],"tv":22271.0}]}
{"op":"mcm","clk":"4212581362","pt":1631354392677,"mc":[{"id":"1.187528277","rc":[{"trd":[[1.43,3461.96]],"batl":[[0,1.43,1177.05]],"ltp":1.43,"tv":17554.5,"id":2249229}],"tv":22277.84}]}
{"op":"mcm","clk":"4212582093","pt":1631354398602,"mc":[{"id":"1.187528277","rc":[{"batb":[[1,1.41,1596.87]],"ltp":1.43,"tv":17554.5,"id":2249229}]}]}
{"op":"mcm","clk":"4212582233","pt":1631354399609,"mc":[{"id":"1.187528277","rc":[{"batb":[[0,1.42,558.57]],"ltp":1.43,"tv":17554.5,"id":2249229}]}]}
{"op":"mcm","clk":"4212582407","pt":1631354400584,"mc":[{"id":"1.187528277","rc":[{"batb":[[0,1.42,536.86]],"batl":[[0,1.43,1221.2]],"ltp":1.43,"tv":17554.5,"id":2249229}]}]}
{"op":"mcm","clk":"4212582633","pt":1631354401368,"mc":[{"id":"1.187528277","rc":[{"batb":[[0,3.3,379.43]],"batl":[[0,3.4,100.75]],"ltp":3.3,"tv":4723.34,"id":19924831}]}]}
{"op":"mcm","clk":"4212588131","pt":1631354431789,"mc":[{"id":"1.187528277","rc":[{"batb":[[0,3.35,6.48],[1,3.3,379.43],[2,3.25,150.35]],"ltp":3.3,"tv":4723.34,"id":19924831}]}]}
{"op":"mcm","clk":"4212589964","pt":1631354442448,"mc":[{"id":"1.187528277","rc":[{"batb":[[2,3.25,143.33]],"ltp":3.3,"tv":4723.34,"id":19924831}]}]}
{"op":"mcm","clk":"4212590158","pt":1631354443618,"mc":[{"id":"1.187528277","rc":[{"batb":[[2,3.25,42.7]],"ltp":3.3,"tv":4723.34,"id":19924831}]}]}
{"op":"mcm","clk":"4212592282","pt":1631354458563,"mc":[{"id":"1.187528277","rc":[{"trd":[[1.43,3532.95]],"batl":[[0,1.43,1185.7]],"ltp":1.43,"tv":17625.48,"id":2249229}],"tv":22348.83}]}
{"op":"mcm","clk":"4212592393","pt":1631354459255,"mc":[{"id":"1.187528277","rc":[{"batb":[[2,3.25,52.92]],"ltp":3.3,"tv":4723.34,"id":19924831},{"batb":[[0,1.42,560.99]],"ltp":1.43,"tv":17625.48,"id":2249229}]}]}
{"op":"mcm","clk":"4212607818","pt":1631354551889,"mc":[{"id":"1.187528277","rc":[{"trd":[[1.43,3572.24]],"batl":[[0,1.43,1166.06]],"ltp":1.43,"tv":17664.77,"id":2249229}],"tv":22388.12}]}
{"op":"mcm","clk":"4212622696","pt":1631354646586,"mc":[{"id":"1.187528277","rc":[{"trd":[[1.43,3616.65]],"batl":[[0,1.43,1143.85]],"ltp":1.43,"tv":17709.18,"id":2249229}],"tv":22432.53}]}
{"op":"mcm","clk":"4212624192","pt":1631354655721,"mc":[{"id":"1.187528277","rc":[{"trd":[[1.42,12140.96]],"batb":[[0,1.42,328.57]],"ltp":1.42,"tv":18174.01,"id":2249229}],"tv":22897.36}]}
{"op":"mcm","clk":"4212624228","pt":1631354655930,"mc":[{"id":"1.187528277","rc":[{"batl":[[0,1.43,1269.72]],"ltp":1.42,"tv":18174.01,"id":2249229}]}]}
{"op":"mcm","clk":"4212625783","pt":1631354664529,"mc":[{"id":"1.187528277","rc":[{"batb":[[0,1.42,320.03]],"ltp":1.42,"tv":18174.01,"id":2249229}]}]}
{"op":"mcm","clk":"4212625956","pt":1631354665500,"mc":[{"id":"1.187528277","rc":[{"batl":[[0,3.4,88.63]],"ltp":3.3,"tv":4723.34,"id":19924831},{"batb":[[0,1.42,291.84]],"ltp":1.42,"tv":18174.01,"id":2249229}]}]}
{"op":"mcm","clk":"4212637920","pt":1631354738145,"mc":[{"id":"1.187528277","rc":[{"trd":[[1.43,3631.17]],"batl":[[0,1.43,1262.46]],"ltp":1.43,"tv":18188.53,"id":2249229}],"tv":22911.88}]}
{"op":"mcm","clk":"4212638892","pt":1631354744065,"mc":[{"id":"1.187528277","rc":[{"trd":[[1.43,3716.57]],"batl":[[0,1.43,1219.76]],"ltp":1.43,"tv":18273.94,"id":2249229}],"tv":22997.28}]}
{"op":"mcm","clk":"4212666307","pt":1631354901650,"mc":[{"id":"1.187528277","rc":[{"trd":[[1.43,3803.69]],"batl":[[0,1.43,1176.21]],"ltp":1.43,"tv":18361.05,"id":2249229}],"tv":23084.4}]}
{"op":"mcm","clk":"4212667140","pt":1631354906533,"mc":[{"id":"1.187528277","rc":[{"trd":[[1.43,3890.8]],"batl":[[0,1.43,1132.65]],"ltp":1.43,"tv":18448.16,"id":2249229}],"tv":23171.51}]}
{"op":"mcm","clk":"4212669434","pt":1631354918885,"mc":[{"id":"1.187528277","rc":[{"trd":[[3.35,2939.34]],"batb":[[0,3.3,379.6],[1,3.25,52.92],[2,2.78,22.83]],"ltp":3.35,"tv":4735.94,"id":19924831},{"batb":[[0,1.42,384.41]],"ltp":1.43,"tv":18448.16,"id":2249229}],"tv":23184.11}]}
{"op":"mcm","clk":"4212670678","pt":1631354924897,"mc":[{"id":"1.187528277","rc":[{"trd":[[1.43,3976.2]],"batl":[[0,1.43,1089.95]],"ltp":1.43,"tv":18533.57,"id":2249229}],"tv":23269.51}]}
{"op":"mcm","clk":"4212673582","pt":1631354939503,"mc":[{"id":"1.187528277","rc":[{"trd":[[1.43,4063.31]],"batl":[[0,1.43,1046.39]],"ltp":1.43,"tv":18620.68,"id":2249229}],"tv":23356.63}]}
{"op":"mcm","clk":"4212676162","pt":1631354952867,"mc":[{"id":"1.187528277","rc":[{"trd":[[1.43,4150.43]],"batl":[[0,1.43,1002.83]],"ltp":1.43,"tv":18707.79,"id":2249229}],"tv":23443.74}]}
{"op":"mcm","clk":"4212676894","pt":1631354956574,"mc":[{"id":"1.187528277","rc":[{"batb":[[1,3.25,147]],"ltp":3.35,"tv":4735.94,"id":19924831},{"batb":[[0,1.42,392.79]],"ltp":1.43,"tv":18707.79,"id":2249229}]}]}
{"op":"mcm","clk":"4212680381","pt":1631354974836,"mc":[{"id":"1.187528277","rc":[{"trd":[[1.43,4237.54]],"batl":[[0,1.43,959.28]],"ltp":1.43,"tv":18794.9,"id":2249229}],"tv":23530.85}]}
{"op":"mcm","clk":"4212682631","pt":1631354988127,"mc":[{"id":"1.187528277","rc":[{"batb":[[1,3.25,161.12]],"ltp":3.35,"tv":4735.94,"id":19924831}]}]}
{"op":"mcm","clk":"4212682999","pt":1631354990228,"mc":[{"id":"1.187528277","rc":[{"trd":[[3.3,1151.87],[3.35,2939.69]],"batb":[[0,3.3,377.6]],"ltp":3.3,"tv":4739.95,"id":19924831}],"tv":23534.86}]}
{"op":"mcm","clk":"4212683937","pt":1631354995561,"mc":[{"id":"1.187528277","rc":[{"batb":[[0,1.42,347.04]],"ltp":1.43,"tv":18794.9,"id":2249229}]}]}
{"op":"mcm","clk":"4212701138","pt":1631355092700,"mc":[{"id":"1.187528277","rc":[{"trd":[[1.43,4322.94]],"batl":[[0,1.43,916.58]],"ltp":1.43,"tv":18880.31,"id":2249229}],"tv":23620.26}]}
{"op":"mcm","clk":"4212702286","pt":1631355098746,"mc":[{"id":"1.187528277","rc":[{"trd":[[1.42,12311.77]],"batb":[[0,1.42,261.63]],"ltp":1.42,"tv":19051.12,"id":2249229}],"tv":23791.07}]}
{"op":"mcm","clk":"4212703261","pt":1631355103534,"mc":[{"id":"1.187528277","rc":[{"batb":[[1,3.25,142.33]],"batl":[[0,3.4,122.8],[1,3.45,298.76]],"ltp":3.3,"tv":4739.95,"id":19924831},{"batb":[[1,1.41,1637.01]],"batl":[[1,1.44,1220.2],[2,1.45,1354.16]],"ltp":1.42,"tv":19051.12,"id":2249229}]}]}
{"op":"mcm","clk":"4212704264","pt":1631355108353,"mc":[{"id":"1.187528277","rc":[{"batb":[[1,1.41,1647.49]],"ltp":1.42,"tv":19051.12,"id":2249229}]}]}
{"op":"mcm","clk":"4212704454","pt":1631355109254,"mc":[{"id":"1.187528277","rc":[{"batb":[[1,3.25,136.57]],"ltp":3.3,"tv":4739.95,"id":19924831},{"batb":[[0,1.42,253.26]],"ltp":1.42,"tv":19051.12,"id":2249229}]}]}
{"op":"mcm","clk":"4212715670","pt":1631355168333,"mc":[{"id":"1.187528277","rc":[{"batb":[[0,3.3,206.79]],"ltp":3.3,"tv":4739.95,"id":19924831},{"batb":[[0,1.42,380.02]],"ltp":1.42,"tv":19051.12,"id":2249229}]}]}
{"op":"mcm","clk":"4212721391","pt":1631355199593,"mc":[{"id":"1.187528277","rc":[{"batb":[[0,1.42,387.73]],"batl":[[1,1.44,1202.33]],"ltp":1.42,"tv":19051.12,"id":2249229}]}]}
{"op":"mcm","clk":"4212721558","pt":1631355200611,"mc":[{"id":"1.187528277","rc":[{"batl":[[0,3.4,129.33]],"ltp":3.3,"tv":4739.95,"id":19924831},{"batl":[[1,1.44,1187.64]],"ltp":1.42,"tv":19051.12,"id":2249229}]}]}
{"op":"mcm","clk":"4212722475","pt":1631355205903,"mc":[{"id":"1.187528277","rc":[{"trd":[[1.43,4410.06]],"batl":[[0,1.43,873.02]],"ltp":1.43,"tv":19138.23,"id":2249229}],"tv":23878.19}]}
{"op":"mcm","clk":"4212729407","pt":1631355243575,"mc":[{"id":"1.187528277","rc":[{"trd":[[1.43,4686.77]],"batl":[[0,1.43,734.66]],"ltp":1.43,"tv":19414.94,"id":2249229}],"tv":24154.9}]}
{"op":"mcm","clk":"4212730492","pt":1631355249555,"mc":[{"id":"1.187528277","rc":[{"trd":[[1.43,4756.8]],"batl":[[0,1.43,699.65]],"ltp":1.43,"tv":19484.97,"id":2249229}],"tv":24224.93}]}
{"op":"mcm","clk":"4212733303","pt":1631355264577,"mc":[{"id":"1.187528277","rc":[{"batb":[[0,3.3,195.44]],"ltp":3.3,"tv":4739.95,"id":19924831}]}]}
{"op":"mcm","clk":"4212736296","pt":1631355282610,"mc":[{"id":"1.187528277","rc":[{"batb":[[0,1.42,487.73]],"ltp":1.43,"tv":19484.97,"id":2249229}]}]}
{"op":"mcm","clk":"4212736326","pt":1631355282827,"mc":[{"id":"1.187528277","rc":[{"batl":[[0,1.43,573.78]],"ltp":1.43,"tv":19484.97,"id":2249229}]}]}
{"op":"mcm","clk":"4212738644","pt":1631355297233,"mc":[{"id":"1.187528277","rc":[{"batb":[[0,1.42,503.89]],"ltp":1.43,"tv":19484.97,"id":2249229}]}]}
{"op":"mcm","clk":"4212738840","pt":1631355298431,"mc":[{"id":"1.187528277","rc":[{"batb":[[0,3.3,184.69]],"ltp":3.3,"tv":4739.95,"id":19924831},{"batl":[[1,1.44,1170.42]],"ltp":1.43,"tv":19484.97,"id":2249229}]}]}
{"op":"mcm","clk":"4212738929","pt":1631355298960,"mc":[{"id":"1.187528277","rc":[{"batl":[[0,3.4,137.05]],"ltp":3.3,"tv":4739.95,"id":19924831}]}]}
{"op":"mcm","clk":"4212747516","pt":1631355345934,"mc":[{"id":"1.187528277","rc":[{"trd":[[1.42,12491.78]],"batb":[[0,1.42,413.88]],"ltp":1.42,"tv":19664.98,"id":2249229}],"tv":24404.93}]}
{"op":"mcm","clk":"4212802229","pt":1631355663165,"mc":[{"id":"1.187528277","rc":[{"trd":[[1.43,4761.92]],"batl":[[0,1.43,571.22]],"ltp":1.43,"tv":19670.11,"id":2249229}],"tv":24410.06}]}
{"op":"mcm","clk":"4212812359","pt":1631355723904,"mc":[{"id":"1.187528277","rc":[{"trd":[[3.3,1157.19]],"batb":[[0,3.3,182.03]],"ltp":3.3,"tv":4745.27,"id":19924831}],"tv":24415.38}]}
{"op":"mcm","clk":"4212835208","pt":1631355859991,"mc":[{"id":"1.187528277","rc":[{"trd":[[1.43,4847.33]],"batl":[[0,1.43,528.52]],"ltp":1.43,"tv":19755.51,"id":2249229}],"tv":24500.78}]}
{"op":"mcm","clk":"4212836688","pt":1631355868899,"mc":[{"id":"1.187528277","rc":[{"batb":[[0,1.42,1209.2]],"batl":[[0,1.43,532.99]],"ltp":1.43,"tv":19755.51,"id":2249229}]}]}
{"op":"mcm","clk":"4212842802","pt":1631355906485,"mc":[{"id":"1.187528277","rc":[{"batb":[[0,1.42,1317.42]],"ltp":1.43,"tv":19755.51,"id":2249229}]}]}
{"op":"mcm","clk":"4212842913","pt":1631355907172,"mc":[{"id":"1.187528277","rc":[{"batl":[[0,3.4,183.41]],"ltp":3.3,"tv":4745.27,"id":19924831}]}]}
{"op":"mcm","clk":"4212848304","pt":1631355939669,"mc":[{"id":"1.187528277","rc":[{"batl":[[0,3.4,197.15]],"ltp":3.3,"tv":4745.27,"id":19924831},{"batb":[[0,1.42,1333.65]],"ltp":1.43,"tv":19755.51,"id":2249229}]}]}
{"op":"mcm","clk":"4212850724","pt":1631355954225,"mc":[{"id":"1.187528277","rc":[{"batb":[[1,3.25,112.66],[2,3.2,52.95]],"batl":[[0,3.4,205.69]],"ltp":3.3,"tv":4745.27,"id":19924831},{"batb":[[0,1.42,1409.66],[1,1.41,1521.09]],"ltp":1.43,"tv":19755.51,"id":2249229}]}]}
{"op":"mcm","clk":"4212853946","pt":1631355973261,"mc":[{"id":"1.187528277","rc":[{"batb":[[1,3.25,104.3]],"ltp":3.3,"tv":4745.27,"id":19924831},{"batb":[[0,1.42,1423.5]],"ltp":1.43,"tv":19755.51,"id":2249229}]}]}
{"op":"mcm","clk":"4212854171","pt":1631355974380,"mc":[{"id":"1.187528277","rc":[{"batl":[[0,3.35,53.73],[1,3.4,214.81],[2,3.45,289.37]],"ltp":3.3,"tv":4745.27,"id":19924831},{"batb":[[1,1.41,1393.44]],"ltp":1.43,"tv":19755.51,"id":2249229}]}]}
{"op":"mcm","clk":"4212859419","pt":1631356006632,"mc":[{"id":"1.187528277","rc":[{"batl":[[2,3.45,150]],"ltp":3.3,"tv":4745.27,"id":19924831}]}]}
{"op":"mcm","clk":"4212859567","pt":1631356007696,"mc":[{"id":"1.187528277","rc":[{"batl":[[0,3.35,61.79]],"ltp":3.3,"tv":4745.27,"id":19924831},{"batb":[[0,1.42,1444.59]],"ltp":1.43,"tv":19755.51,"id":2249229}]}]}
{"op":"mcm","clk":"4212865217","pt":1631356041538,"mc":[{"id":"1.187528277","rc":[{"batl":[[1,3.4,218.36]],"ltp":3.3,"tv":4745.27,"id":19924831},{"batb":[[0,1.42,1450.6]],"ltp":1.43,"tv":19755.51,"id":2249229}]}]}
{"op":"mcm","clk":"4212878260","pt":1631356121673,"mc":[{"id":"1.187528277","rc":[{"trd":[[1.43,5487.33]],"batb":[[0,1.42,1415.13]],"batl":[[0,1.43,212.99]],"ltp":1.43,"tv":20395.51,"id":2249229}],"tv":25140.78}]}
{"op":"mcm","clk":"4212880764","pt":1631356137390,"mc":[{"id":"1.187528277","rc":[{"batl":[[0,1.43,208.51]],"ltp":1.43,"tv":20395.51,"id":2249229}]}]}
{"op":"mcm","clk":"4212880913","pt":1631356138397,"mc":[{"id":"1.187528277","rc":[{"batb":[[0,3.3,157.44]],"ltp":3.3,"tv":4745.27,"id":19924831},{"batl":[[0,1.43,196.32]],"ltp":1.43,"tv":20395.51,"id":2249229}]}]}
{"op":"mcm","clk":"4212886061","pt":1631356169171,"mc":[{"id":"1.187528277","rc":[{"batl":[[1,1.44,1157.39]],"ltp":1.43,"tv":20395.51,"id":2249229}]}]}
{"op":"mcm","clk":"4212894463","pt":1631356215852,"mc":[{"id":"1.187528277","rc":[{"trd":[[1.43,5574.44]],"batl":[[0,1.43,152.76]],"ltp":1.43,"tv":20482.62,"id":2249229}],"tv":25227.9}]}
{"op":"mcm","clk":"4212897184","pt":1631356230885,"mc":[{"id":"1.187528277","rc":[{"batb":[[0,3.3,149.84]],"ltp":3.3,"tv":4745.27,"id":19924831}]}]}
{"op":"mcm","clk":"4212912855","pt":1631356320424,"mc":[{"id":"1.187528277","rc":[{"trd":[[3.3,1522.25]],"batb":[[0,3.25,143.25],[1,3.2,52.95],[2,2.78,22.83]],"ltp":3.3,"tv":5110.32,"id":19924831},{"trd":[[1.43,5725.33]],"batl":[[0,1.43,1.87]],"ltp":1.43,"tv":20633.51,"id":2249229}],"tv":25743.84}]}
{"op":"mcm","clk":"4212913955","pt":1631356326354,"mc":[{"id":"1.187528277","rc":[{"batl":[[1,3.4,165.42]],"ltp":3.3,"tv":5110.32,"id":19924831},{"batb":[[0,1.43,125.87],[1,1.42,1415.13],[2,1.41,1393.44]],"batl":[[0,1.44,1157.39],[1,1.45,1354.16],[2,1.46,744.63]],"ltp":1.43,"tv":20633.51,"id":2249229}]}]}
{"op":"mcm","clk":"4212914174","pt":1631356327650,"mc":[{"id":"1.187528277","rc":[{"batb":[[1,3.2,152.93]],"ltp":3.3,"tv":5110.32,"id":19924831},{"batl":[[0,1.44,1101.59],[1,1.45,1605.44]],"ltp":1.43,"tv":20633.51,"id":2249229}]}]}
{"op":"mcm","clk":"4212914244","pt":1631356328041,"mc":[{"id":"1.187528277","rc":[{"batb":[[0,3.3,38.36],[1,3.25,147.7],[2,3.2,152.93]],"ltp":3.3,"tv":5110.32,"id":19924831}]}]}
{"op":"mcm","clk":"4212915817","pt":1631356336912,"mc":[{"id":"1.187528277","rc":[{"trd":[[3.3,1597.4]],"batb":[[0,3.25,148.48],[1,3.2,152.93],[2,2.78,22.83]],"ltp":3.3,"tv":5185.48,"id":19924831}],"tv":25819.0}]}
{"op":"mcm","clk":"4212916195","pt":1631356339008,"mc":[{"id":"1.187528277","rc":[{"batb":[[1,1.42,1403.78]],"ltp":1.43,"tv":20633.51,"id":2249229}]}]}
{"op":"mcm","clk":"4212917830","pt":1631356348519,"mc":[{"id":"1.187528277","rc":[{"trd":[[3.25,837.41],[3.3,1598.96]],"batb":[[0,3.2,152.93],[1,2.78,22.83],[2,1.5,3617.07]],"ltp":3.25,"tv":5936.06,"id":19924831},{"trd":[[1.44,2175.49]],"batl":[[0,1.44,77.78]],"ltp":1.44,"tv":21657.33,"id":2249229}],"tv":27593.39}]}
{"op":"mcm","clk":"4212917982","pt":1631356349320,"mc":[{"id":"1.187528277","rc":[{"batb":[[0,3.2,165.09]],"ltp":3.25,"tv":5936.06,"id":19924831}]}]}
{"op":"mcm","clk":"4212918194","pt":1631356350606,"mc":[{"id":"1.187528277","rc":[{"batb":[[2,2.74,13.31]],"ltp":3.25,"tv":5936.06,"id":19924831}]}]}
{"op":"mcm","clk":"4212920250","pt":1631356361439,"mc":[{"id":"1.187528277","rc":[{"batb":[[2,1.41,1387.38]],"ltp":1.44,"tv":21657.33,"id":2249229}]}]}
{"op":"mcm","clk":"4212920433","pt":1631356362597,"mc":[{"id":"1.187528277","rc":[{"batb":[[2,1.41,1367.39]],"ltp":1.44,"tv":21657.33,"id":2249229}]}]}
{"op":"mcm","clk":"4212920632","pt":1631356363664,"mc":[{"id":"1.187528277","rc":[{"batb":[[2,1.41,1312.32]],"ltp":1.44,"tv":21657.33,"id":2249229}]}]}
{"op":"mcm","clk":"4212920811","pt":1631356364645,"mc":[{"id":"1.187528277","rc":[{"batb":[[2,1.41,1299.89]],"ltp":1.44,"tv":21657.33,"id":2249229}]}]}
{"op":"mcm","clk":"4212920996","pt":1631356365660,"mc":[{"id":"1.187528277","rc":[{"batb":[[2,1.41,1280.96]],"ltp":1.44,"tv":21657.33,"id":2249229}]}]}
{"op":"mcm","clk":"4212921178","pt":1631356366679,"mc":[{"id":"1.187528277","rc":[{"batb":[[2,1.41,1138.94]],"ltp":1.44,"tv":21657.33,"id":2249229}]}]}
{"op":"mcm","clk":"4212921331","pt":1631356367589,"mc":[{"id":"1.187528277","rc":[{"batb":[[2,1.41,1122.59]],"ltp":1.44,"tv":21657.33,"id":2249229}]}]}
{"op":"mcm","clk":"4212921413","pt":1631356368076,"mc":[{"id":"1.187528277","rc":[{"batb":[[2,1.41,1117.24]],"ltp":1.44,"tv":21657.33,"id":2249229}]}]}
{"op":"mcm","clk":"4212921604","pt":1631356369302,"mc":[{"id":"1.187528277","rc":[{"batb":[[2,1.41,1113.55]],"ltp":1.44,"tv":21657.33,"id":2249229}]}]}
{"op":"mcm","clk":"4212921787","pt":1631356370272,"mc":[{"id":"1.187528277","rc":[{"batb":[[2,1.41,1103.48]],"ltp":1.44,"tv":21657.33,"id":2249229}]}]}
{"op":"mcm","clk":"4212921966","pt":1631356371280,"mc":[{"id":"1.187528277","rc":[{"batb":[[0,1.43,144.75]],"batl":[[0,1.44,11.67]],"ltp":1.44,"tv":21657.33,"id":2249229}]}]}
{"op":"mcm","clk":"4212922208","pt":1631356372715,"mc":[{"id":"1.187528277","rc":[{"batb":[[0,3.25,16.79],[1,3.2,198.98],[2,2.78,22.83]],"batl":[[0,3.35,71.06]],"ltp":3.25,"tv":5936.06,"id":19924831}]}]}
{"op":"mcm","clk":"4212922321","pt":1631356373270,"mc":[{"id":"1.187528277","rc":[{"batl":[[1,3.4,152.75]],"ltp":3.25,"tv":5936.06,"id":19924831}]}]}
{"op":"mcm","clk":"4212922547","pt":1631356374494,"mc":[{"id":"1.187528277","rc":[{"batb":[[0,1.43,344.75]],"ltp":1.44,"tv":21657.33,"id":2249229}]}]}
{"op":"mcm","clk":"4212922911","pt":1631356376697,"mc":[{"id":"1.187528277","rc":[{"batb":[[0,3.25,5.17]],"ltp":3.25,"tv":5936.06,"id":19924831}]}]}
{"op":"mcm","clk":"4212922953","pt":1631356376918,"mc":[{"id":"1.187528277","rc":[{"batb":[[0,3.25,16.79]],"ltp":3.25,"tv":5936.06,"id":19924831}]}]}
{"op":"mcm","clk":"4212923754","pt":1631356381570,"mc":[{"id":"1.187528277","rc":[{"batb":[[0,3.25,43.77]],"batl":[[0,3.3,73.21],[1,3.35,71.06],[2,3.4,152.75]],"ltp":3.25,"tv":5936.06,"id":19924831},{"batb":[[1,1.42,1303.78]],"ltp":1.44,"tv":21657.33,"id":2249229}]}]}
{"op":"mcm","clk":"4212927625","pt":1631356405093,"mc":[{"id":"1.187528277","rc":[{"batb":[[0,1.43,1198.79]],"ltp":1.44,"tv":21657.33,"id":2249229}]}]}
{"op":"mcm","clk":"4212928040","pt":1631356407566,"mc":[{"id":"1.187528277","rc":[{"batl":[[0,3.3,123.06]],"ltp":3.25,"tv":5936.06,"id":19924831},{"batb":[[1,1.42,2157.82]],"ltp":1.44,"tv":21657.33,"id":2249229}]}]}
{"op":"mcm","clk":"4212928169","pt":1631356408259,"mc":[{"id":"1.187528277","rc":[{"batl":[[2,3.4,148.39]],"ltp":3.25,"tv":5936.06,"id":19924831}]}]}
{"op":"mcm","clk":"4212928402","pt":1631356409660,"mc":[{"id":"1.187528277","rc":[{"batl":[[2,3.4,83.75]],"ltp":3.25,"tv":5936.06,"id":19924831}]}]}
{"op":"mcm","clk":"4212928554","pt":1631356410680,"mc":[{"id":"1.187528277","rc":[{"batl":[[2,3.4,71.6]],"ltp":3.25,"tv":5936.06,"id":19924831},{"batb":[[2,1.41,1957.52]],"ltp":1.44,"tv":21657.33,"id":2249229}]}]}
{"op":"mcm","clk":"4212928729","pt":1631356411692,"mc":[{"id":"1.187528277","rc":[{"batl":[[2,3.4,51.33]],"ltp":3.25,"tv":5936.06,"id":19924831}]}]}
{"op":"mcm","clk":"4212928898","pt":1631356412600,"mc":[{"id":"1.187528277","rc":[{"batl":[[2,3.4,42.7]],"ltp":3.25,"tv":5936.06,"id":19924831}]}]}
{"op":"mcm","clk":"4212929228","pt":1631356414671,"mc":[{"id":"1.187528277","rc":[{"batb":[[1,1.42,2139.98]],"ltp":1.44,"tv":21657.33,"id":2249229}]}]}
{"op":"mcm","clk":"4212929362","pt":1631356415471,"mc":[{"id":"1.187528277","rc":[{"batb":[[0,1.43,1355.26]],"batl":[[1,1.45,1609.69]],"ltp":1.44,"tv":21657.33,"id":2249229}]}]}
{"op":"mcm","clk":"4212929540","pt":1631356416481,"mc":[{"id":"1.187528277","rc":[{"batb":[[1,3.2,204.07]],"batl":[[0,3.3,133.28]],"ltp":3.25,"tv":5936.06,"id":19924831}]}]}
{"op":"mcm","clk":"4212929581","pt":1631356416806,"mc":[{"id":"1.187528277","rc":[{"batl":[[1,3.35,141.15]],"ltp":3.25,"tv":5936.06,"id":19924831}]}]}
{"op":"mcm","clk":"4212931671","pt":1631356429535,"mc":[{"id":"1.187528277","rc":[{"batb":[[0,1.43,501.22],[1,1.42,1285.94],[2,1.41,1103.48]],"ltp":1.44,"tv":21657.33,"id":2249229}]}]}
{"op":"mcm","clk":"4212932101","pt":1631356431923,"mc":[{"id":"1.187528277","rc":[{"batb":[[0,1.43,2209.31]],"ltp":1.44,"tv":21657.33,"id":2249229}]}]}
{"op":"mcm","clk":"4212932709","pt":1631356435427,"mc":[{"id":"1.187528277","rc":[{"batb":[[1,1.42,2994.03]],"ltp":1.44,"tv":21657.33,"id":2249229}]}]}
{"op":"mcm","clk":"4212933728","pt":1631356441735,"mc":[{"id":"1.187528277","rc":[{"batb":[[2,1.41,2811.57]],"ltp":1.44,"tv":21657.33,"id":2249229}]}]}
{"op":"mcm","clk":"4212935736","pt":1631356452375,"mc":[{"id":"1.187528277","rc":[{"batl":[[1,3.35,193.88]],"ltp":3.25,"tv":5936.06,"id":19924831},{"batb":[[1,1.42,3065.8]],"ltp":1.44,"tv":21657.33,"id":2249229}]}]}
{"op":"mcm","clk":"4212942057","pt":1631356487907,"mc":[{"id":"1.187528277","rc":[{"trd":[[1.44,2198.83]],"batb":[[0,1.44,978.28],[1,1.43,2209.31],[2,1.42,3065.8]],"batl":[[0,1.45,1609.69],[1,1.46,744.63],[2,1.5,25]],"ltp":1.44,"tv":21680.66,"id":2249229}],"tv":27616.73}]}
{"op":"mcm","clk":"4212942269","pt":1631356489139,"mc":[{"id":"1.187528277","rc":[{"batb":[[0,3.25,16.79]],"ltp":3.25,"tv":5936.06,"id":19924831}]}]}
{"op":"mcm","clk":"4212948372","pt":1631356523617,"mc":[{"id":"1.187528277","rc":[{"batb":[[2,1.42,3042.7]],"ltp":1.44,"tv":21680.66,"id":2249229}]}]}
{"op":"mcm","clk":"4212948563","pt":1631356524656,"mc":[{"id":"1.187528277","rc":[{"batb":[[2,1.42,2954.77]],"ltp":1.44,"tv":21680.66,"id":2249229}]}]}
{"op":"mcm","clk":"4212948723","pt":1631356525587,"mc":[{"id":"1.187528277","rc":[{"batb":[[2,1.42,2830.32]],"ltp":1.44,"tv":21680.66,"id":2249229}]}]}
{"op":"mcm","clk":"4212948937","pt":1631356526655,"mc":[{"id":"1.187528277","rc":[{"batb":[[2,1.42,2773.31]],"ltp":1.44,"tv":21680.66,"id":2249229}]}]}
{"op":"mcm","clk":"4212949115","pt":1631356527618,"mc":[{"id":"1.187528277","rc":[{"batb":[[1,1.43,2217.25]],"batl":[[1,1.46,923.42]],"ltp":1.44,"tv":21680.66,"id":2249229}]}]}
{"op":"mcm","clk":"4212951603","pt":1631356541529,"mc":[{"id":"1.187528277","rc":[{"batb":[[2,1.42,1978]],"ltp":1.44,"tv":21680.66,"id":2249229}]}]}
{"op":"mcm","clk":"4212955524","pt":1631356563095,"mc":[{"id":"1.187528277","rc":[{"batl":[[1,1.46,950.24]],"ltp":1.44,"tv":21680.66,"id":2249229}]}]}
{"op":"mcm","clk":"4212961827","pt":1631356598664,"mc":[{"id":"1.187528277","rc":[{"batl":[[1,1.46,954.26]],"ltp":1.44,"tv":21680.66,"id":2249229}]}]}
{"op":"mcm","clk":"4212963193","pt":1631356606986,"mc":[{"id":"1.187528277","rc":[{"trd":[[1.44,2227.55]],"batb":[[0,1.44,963.92]],"ltp":1.44,"tv":21709.39,"id":2249229}],"tv":27645.45}]}
{"op":"mcm","clk":"4212964352","pt":1631356614010,"mc":[{"id":"1.187528277","rc":[{"trd":[[3.25,857.41]],"batb":[[0,3.25,6.79]],"ltp":3.25,"tv":5956.06,"id":19924831}],"tv":27665.45}]}
{"op":"mcm","clk":"4212967267","pt":1631356630717,"mc":[{"id":"1.187528277","rc":[{"batl":[[0,3.3,137.98]],"ltp":3.25,"tv":5956.06,"id":19924831},{"batb":[[1,1.43,2223.25]],"batl":[[0,1.45,1605.44]],"ltp":1.44,"tv":21709.39,"id":2249229}]}]}
{"op":"mcm","clk":"4212967336","pt":1631356631106,"mc":[{"id":"1.187528277","rc":[{"batl":[[1,3.35,198.47]],"ltp":3.25,"tv":5956.06,"id":19924831}]}]}
{"op":"mcm","clk":"4212968604","pt":1631356638724,"mc":[{"id":"1.187528277","rc":[{"batb":[[2,3,835.53]],"ltp":3.25,"tv":5956.06,"id":19924831}]}]}
{"op":"mcm","clk":"4212969632","pt":1631356644920,"mc":[{"id":"1.187528277","rc":[{"batb":[[2,3,844.32]],"ltp":3.25,"tv":5956.06,"id":19924831}]}]}
{"op":"mcm","clk":"4212974436","pt":1631356673065,"mc":[{"id":"1.187528277","rc":[{"batb":[[2,3,846.96]],"ltp":3.25,"tv":5956.06,"id":19924831}]}]}
{"op":"mcm","clk":"4212975840","pt":1631356681694,"mc":[{"id":"1.187528277","rc":[{"batb":[[2,2.78,22.83]],"ltp":3.25,"tv":5956.06,"id":19924831}]}]}
{"op":"mcm","clk":"4212975875","pt":1631356681898,"mc":[{"id":"1.187528277","rc":[{"batb":[[2,3,847.84]],"ltp":3.25,"tv":5956.06,"id":19924831}]}]}
{"op":"mcm","clk":"4212984429","pt":1631356730332,"mc":[{"id":"1.187528277","rc":[{"batb":[[0,1.43,2223.25],[1,1.42,1978],[2,1.41,2811.57]],"ltp":1.44,"tv":21709.39,"id":2249229}]}]}
{"op":"mcm","clk":"4212984933","pt":1631356733107,"mc":[{"id":"1.187528277","rc":[{"batb":[[0,1.44,52.65],[1,1.43,2223.25],[2,1.42,1978]],"ltp":1.44,"tv":21709.39,"id":2249229}]}]}
{"op":"mcm","clk":"4212987409","pt":1631356747776,"mc":[{"id":"1.187528277","rc":[{"batb":[[2,2.78,22.83]],"ltp":3.25,"tv":5956.06,"id":19924831}]}]}
{"op":"mcm","clk":"4212994833","pt":1631356791023,"mc":[{"id":"1.187528277","rc":[{"trd":[[3.3,1874.93]],"batl":[[0,3.35,198.47],[1,3.4,42.7],[2,3.45,150]],"ltp":3.3,"tv":6232.03,"id":19924831},{"trd":[[1.43,5725.39],[1.44,2332.83]],"batb":[[0,1.43,2223.22],[1,1.42,1978],[2,1.41,2811.57]],"ltp":1.43,"tv":21814.72,"id":2249229}],"tv":28046.75}]}
{"op":"mcm","clk":"4212995154","pt":1631356792708,"mc":[{"id":"1.187528277","rc":[{"batb":[[0,3.25,76.36]],"ltp":3.3,"tv":6232.03,"id":19924831}]}]}
{"op":"mcm","clk":"4213000045","pt":1631356820552,"mc":[{"id":"1.187528277","rc":[{"batl":[[0,1.44,500],[1,1.45,1605.44],[2,1.46,954.26]],"ltp":1.43,"tv":21814.72,"id":2249229}]}]}
{"op":"mcm","clk":"4213000195","pt":1631356821349,"mc":[{"id":"1.187528277","rc":[{"batb":[[1,1.42,2270.49]],"ltp":1.43,"tv":21814.72,"id":2249229}]}]}
{"op":"mcm","clk":"4213000435","pt":1631356822477,"mc":[{"id":"1.187528277","rc":[{"batb":[[0,1.43,2209.28]],"ltp":1.43,"tv":21814.72,"id":2249229}]}]}
{"op":"mcm","clk":"4213000580","pt":1631356823363,"mc":[{"id":"1.187528277","rc":[{"batb":[[0,3.25,87.82]],"ltp":3.3,"tv":6232.03,"id":19924831},{"batl":[[1,1.45,1620.65]],"ltp":1.43,"tv":21814.72,"id":2249229}]}]}
{"op":"mcm","clk":"4213000760","pt":1631356824387,"mc":[{"id":"1.187528277","rc":[{"batl":[[0,3.35,193.88],[1,3.4,173.03]],"ltp":3.3,"tv":6232.03,"id":19924831}]}]}
{"op":"mcm","clk":"4213008652","pt":1631356867308,"mc":[{"id":"1.187528277","rc":[{"batl":[[2,1.46,950.24]],"ltp":1.43,"tv":21814.72,"id":2249229}]}]}
{"op":"mcm","clk":"4213008862","pt":1631356868430,"mc":[{"id":"1.187528277","rc":[{"batl":[[2,1.46,744.63]],"ltp":1.43,"tv":21814.72,"id":2249229}]}]}
{"op":"mcm","clk":"4213009096","pt":1631356869514,"mc":[{"id":"1.187528277","rc":[{"batl":[[0,1.44,575],[1,1.45,1626.78]],"ltp":1.43,"tv":21814.72,"id":2249229}]}]}
{"op":"mcm","clk":"4213009254","pt":1631356870302,"mc":[{"id":"1.187528277","rc":[{"batb":[[0,3.25,122.77]],"batl":[[1,3.4,210.9]],"ltp":3.3,"tv":6232.03,"id":19924831}]}]}
{"op":"mcm","clk":"4213017403","pt":1631356915528,"mc":[{"id":"1.187528277","rc":[{"batl":[[0,1.44,586.25],[1,1.45,1639.45]],"ltp":1.43,"tv":21814.72,"id":2249229}]}]}
{"op":"mcm","clk":"4213017530","pt":1631356916226,"mc":[{"id":"1.187528277","rc":[{"batb":[[0,3.25,132.99]],"batl":[[1,3.4,216.57]],"ltp":3.3,"tv":6232.03,"id":19924831}]}]}
{"op":"mcm","clk":"4213025469","pt":1631356957405,"mc":[{"id":"1.187528277","rc":[{"batl":[[1,1.45,1644.78]],"ltp":1.43,"tv":21814.72,"id":2249229}]}]}
{"op":"mcm","clk":"4213025540","pt":1631356957795,"mc":[{"id":"1.187528277","rc":[{"batb":[[1,3.2,207.14]],"ltp":3.3,"tv":6232.03,"id":19924831}]}]}
{"op":"mcm","clk":"4213037431","pt":1631357024664,"mc":[{"id":"1.187528277","rc":[{"batb":[[1,3.2,195.19]],"ltp":3.3,"tv":6232.03,"id":19924831},{"batl":[[1,1.45,1636.24]],"ltp":1.43,"tv":21814.72,"id":2249229}]}]}
{"op":"mcm","clk":"4213037483","pt":1631357024932,"mc":[{"id":"1.187528277","rc":[{"batb":[[1,1.42,2279.88]],"ltp":1.43,"tv":21814.72,"id":2249229}]}]}
{"op":"mcm","clk":"4213048911","pt":1631357086266,"mc":[{"id":"1.187528277","rc":[{"batl":[[0,3.3,154.54],[1,3.35,193.88],[2,3.4,216.57]],"ltp":3.3,"tv":6232.03,"id":19924831}]}]}
{"op":"mcm","clk":"4213050619","pt":1631357095681,"mc":[{"id":"1.187528277","rc":[{"batl":[[2,3.4,173.03]],"ltp":3.3,"tv":6232.03,"id":19924831}]}]}
{"op":"mcm","clk":"4213050704","pt":1631357096206,"mc":[{"id":"1.187528277","rc":[{"batl":[[2,3.4,42.7]],"ltp":3.3,"tv":6232.03,"id":19924831}]}]}
{"op":"mcm","clk":"4213051069","pt":1631357098297,"mc":[{"id":"1.187528277","rc":[{"batl":[[0,3.3,162.4]],"ltp":3.3,"tv":6232.03,"id":19924831}]}]}
{"op":"mcm","clk":"4213067126","pt":1631357186717,"mc":[{"id":"1.187528277","rc":[{"trd":[[1.44,2439.95]],"batl":[[0,1.44,532.69]],"ltp":1.44,"tv":21921.84,"id":2249229}],"tv":28153.88}]}
{"op":"mcm","clk":"4213085866","pt":1631357295685,"mc":[{"id":"1.187528277","rc":[{"trd":[[1.44,2899.95]],"batl":[[0,1.44,302.69]],"ltp":1.44,"tv":22381.84,"id":2249229}],"tv":28613.88}]}
{"op":"mcm","clk":"4213086413","pt":1631357299080,"mc":[{"id":"1.187528277","rc":[{"batl":[[0,3.3,62.4]],"ltp":3.3,"tv":6232.03,"id":19924831}]}]}
{"op":"mcm","clk":"4213092127","pt":1631357335657,"mc":[{"id":"1.187528277","rc":[{"batb":[[0,3.25,122.77]],"ltp":3.3,"tv":6232.03,"id":19924831},{"batl":[[0,1.44,261.85]],"ltp":1.44,"tv":22381.84,"id":2249229}]}]}
{"op":"mcm","clk":"4213092237","pt":1631357336395,"mc":[{"id":"1.187528277","rc":[{"batb":[[0,3.25,116.43]],"ltp":3.3,"tv":6232.03,"id":19924831}]}]}
{"op":"mcm","clk":"4213097574","pt":1631357369498,"mc":[{"id":"1.187528277","rc":[{"batb":[[0,1.43,2380.09]],"ltp":1.44,"tv":22381.84,"id":2249229}]}]}
{"op":"mcm","clk":"4213097847","pt":1631357371277,"mc":[{"id":"1.187528277","rc":[{"batb":[[0,3.25,111.23]],"ltp":3.3,"tv":6232.03,"id":19924831}]}]}
{"op":"mcm","clk":"4213102498","pt":1631357401138,"mc":[{"id":"1.187528277","rc":[{"batl":[[0,1.44,1115.89]],"ltp":1.44,"tv":22381.84,"id":2249229}]}]}
{"op":"mcm","clk":"4213103283","pt":1631357406122,"mc":[{"id":"1.187528277","rc":[{"batb":[[0,3.25,167.21]],"ltp":3.3,"tv":6232.03,"id":19924831},{"batl":[[0,1.44,1237.87]],"ltp":1.44,"tv":22381.84,"id":2249229}]}]}
{"op":"mcm","clk":"4213107491","pt":1631357432887,"mc":[{"id":"1.187528277","rc":[{"trd":[[3.3,1999.62]],"batl":[[0,3.3,54.59]],"ltp":3.3,"tv":6356.72,"id":19924831}],"tv":28738.57}]}
{"op":"mcm","clk":"4213108077","pt":1631357436501,"mc":[{"id":"1.187528277","rc":[{"batb":[[0,1.43,2365.37]],"batl":[[0,1.44,1256.16]],"ltp":1.44,"tv":22381.84,"id":2249229}]}]}
{"op":"mcm","clk":"4213108266","pt":1631357437584,"mc":[{"id":"1.187528277","rc":[{"batl":[[0,3.3,58.51],[1,3.35,187.75]],"ltp":3.3,"tv":6356.72,"id":19924831}]}]}
{"op":"mcm","clk":"4213113652","pt":1631357471276,"mc":[{"id":"1.187528277","rc":[{"batl":[[0,1.44,1258.91]],"ltp":1.44,"tv":22381.84,"id":2249229}]}]}
{"op":"mcm","clk":"4213119753","pt":1631357513184,"mc":[{"id":"1.187528277","rc":[{"trd":[[3.3,2057.97]],"batb":[[0,3.25,222.59]],"batl":[[0,3.35,187.92],[1,3.4,42.7],[2,3.45,150]],"ltp":3.3,"tv":6415.06,"id":19924831},{"trd":[[1.43,10590.76]],"batb":[[0,1.42,2368.29],[1,1.41,2811.57],[2,1.4,2023.5]],"ltp":1.43,"tv":27247.22,"id":2249229}],"tv":33662.28}]}
{"op":"mcm","clk":"4213122375","pt":1631357533707,"mc":[{"id":"1.187528277","rc":[{"batl":[[0,3.35,187.75]],"ltp":3.3,"tv":6415.06,"id":19924831},{"batb":[[1,1.41,3104.06]],"ltp":1.43,"tv":27247.22,"id":2249229}]}]}
{"op":"mcm","clk":"4213122501","pt":1631357534506,"mc":[{"id":"1.187528277","rc":[{"batb":[[0,3.25,248.8]],"batl":[[0,3.35,141.15]],"ltp":3.3,"tv":6415.06,"id":19924831}]}]}
{"op":"mcm","clk":"4213122643","pt":1631357535608,"mc":[{"id":"1.187528277","rc":[{"batl":[[0,3.35,81.92],[1,3.4,197.47]],"ltp":3.3,"tv":6415.06,"id":19924831}]}]}
{"op":"mcm","clk":"4213127030","pt":1631357567515,"mc":[{"id":"1.187528277","rc":[{"batb":[[0,3.25,252.73]],"batl":[[0,3.35,71.06]],"ltp":3.3,"tv":6415.06,"id":19924831}]}]}
{"op":"mcm","clk":"4213127180","pt":1631357568597,"mc":[{"id":"1.187528277","rc":[{"batl":[[0,3.35,66.02],[1,3.4,220.69]],"ltp":3.3,"tv":6415.06,"id":19924831}]}]}
{"op":"mcm","clk":"4213129779","pt":1631357587343,"mc":[{"id":"1.187528277","rc":[{"batb":[[0,1.42,2338.43]],"ltp":1.43,"tv":27247.22,"id":2249229}]}]}
{"op":"mcm","clk":"4213130769","pt":1631357594637,"mc":[{"id":"1.187528277","rc":[{"trd":[[1.44,2942.65]],"batl":[[0,1.44,1237.56]],"ltp":1.44,"tv":27289.92,"id":2249229}],"tv":33704.98}]}
{"op":"mcm","clk":"4213136777","pt":1631357641721,"mc":[{"id":"1.187528277","rc":[{"batb":[[0,3.3,28.51],[1,3.25,252.73],[2,3.2,195.19]],"ltp":3.3,"tv":6415.06,"id":19924831}]}]}
{"op":"mcm","clk":"4213137630","pt":1631357647616,"mc":[{"id":"1.187528277","rc":[{"batb":[[2,3.2,95.2]],"ltp":3.3,"tv":6415.06,"id":19924831}]}]}
{"op":"mcm","clk":"4213137708","pt":1631357648249,"mc":[{"id":"1.187528277","rc":[{"batb":[[2,3.2,90.12]],"ltp":3.3,"tv":6415.06,"id":19924831}]}]}
{"op":"mcm","clk":"4213137862","pt":1631357649309,"mc":[{"id":"1.187528277","rc":[{"batb":[[2,3.2,53.15]],"ltp":3.3,"tv":6415.06,"id":19924831}]}]}
{"op":"mcm","clk":"4213137996","pt":1631357650404,"mc":[{"id":"1.187528277","rc":[{"batb":[[0,3.3,32.78]],"ltp":3.3,"tv":6415.06,"id":19924831},{"batl":[[0,1.44,1244.57]],"ltp":1.44,"tv":27289.92,"id":2249229}]}]}
{"op":"mcm","clk":"4213141886","pt":1631357680981,"mc":[{"id":"1.187528277","rc":[{"trd":[[1.44,3115.17]],"batl":[[0,1.44,1158.31]],"ltp":1.44,"tv":27462.43,"id":2249229}],"tv":33877.5}]}
{"op":"mcm","clk":"4213142714","pt":1631357686974,"mc":[{"id":"1.187528277","rc":[{"batb":[[1,3.25,248.8]],"ltp":3.3,"tv":6415.06,"id":19924831}]}]}
{"op":"mcm","clk":"4213147604","pt":1631357718446,"mc":[{"id":"1.187528277","rc":[{"trd":[[1.44,3285.97]],"batl":[[0,1.44,1072.91]],"ltp":1.44,"tv":27633.24,"id":2249229}],"tv":34048.31}]}
{"op":"mcm","clk":"4213148592","pt":1631357725583,"mc":[{"id":"1.187528277","rc":[{"batl":[[0,1.44,1065.9]],"ltp":1.44,"tv":27633.24,"id":2249229}]}]}
{"op":"mcm","clk":"4213148686","pt":1631357726260,"mc":[{"id":"1.187528277","rc":[{"batl":[[0,1.44,1063.15]],"ltp":1.44,"tv":27633.24,"id":2249229}]}]}
{"op":"mcm","clk":"4213148802","pt":1631357727174,"mc":[{"id":"1.187528277","rc":[{"batb":[[1,3.25,240.37]],"ltp":3.3,"tv":6415.06,"id":19924831},{"batl":[[0,1.44,1049.68]],"ltp":1.44,"tv":27633.24,"id":2249229}]}]}
{"op":"mcm","clk":"4213161706","pt":1631357819326,"mc":[{"id":"1.187528277","rc":[{"trd":[[1.44,3373.09]],"batl":[[0,1.44,1006.12]],"ltp":1.44,"tv":27720.35,"id":2249229}],"tv":34135.42}]}
{"op":"mcm","clk":"4213164184","pt":1631357834473,"mc":[{"id":"1.187528277","rc":[{"batl":[[0,1.44,1016.23]],"ltp":1.44,"tv":27720.35,"id":2249229}]}]}
{"op":"mcm","clk":"4213164244","pt":1631357834852,"mc":[{"id":"1.187528277","rc":[{"batb":[[1,3.25,234.67]],"ltp":3.3,"tv":6415.06,"id":19924831}]}]}
{"op":"mcm","clk":"4213169773","pt":1631357872520,"mc":[{"id":"1.187528277","rc":[{"trd":[[3.3,2074.07]],"batb":[[0,3.3,24.73]],"ltp":3.3,"tv":6431.17,"id":19924831}],"tv":34151.52}]}
{"op":"mcm","clk":"4213178608","pt":1631357930713,"mc":[{"id":"1.187528277","rc":[{"batb":[[0,3.3,124.73]],"ltp":3.3,"tv":6431.17,"id":19924831}]}]}
{"op":"mcm","clk":"4213178719","pt":1631357931398,"mc":[{"id":"1.187528277","rc":[{"batb":[[1,3.25,215.71]],"ltp":3.3,"tv":6431.17,"id":19924831},{"batl":[[0,1.44,1141.23]],"ltp":1.44,"tv":27720.35,"id":2249229}]}]}
{"op":"mcm","clk":"4213180805","pt":1631357944440,"mc":[{"id":"1.187528277","rc":[{"batl":[[0,1.44,1193.1]],"ltp":1.44,"tv":27720.35,"id":2249229}]}]}
{"op":"mcm","clk":"4213180913","pt":1631357945238,"mc":[{"id":"1.187528277","rc":[{"batb":[[0,3.3,139.16],[1,3.25,220.99]],"ltp":3.3,"tv":6431.17,"id":19924831}]}]}
{"op":"mcm","clk":"4213186893","pt":1631357984543,"mc":[{"id":"1.187528277","rc":[{"batl":[[0,1.44,1205.85]],"ltp":1.44,"tv":27720.35,"id":2249229}]}]}
{"op":"mcm","clk":"4213186932","pt":1631357984805,"mc":[{"id":"1.187528277","rc":[{"batb":[[1,3.25,225.23]],"ltp":3.3,"tv":6431.17,"id":19924831}]}]}
{"op":"mcm","clk":"4213188798","pt":1631357996746,"mc":[{"id":"1.187528277","rc":[{"batb":[[1,1.41,2840.21]],"ltp":1.44,"tv":27720.35,"id":2249229}]}]}
{"op":"mcm","clk":"4213194267","pt":1631358027039,"mc":[{"id":"1.187528277","rc":[{"batl":[[0,1.44,1672.62]],"ltp":1.44,"tv":27720.35,"id":2249229}]}]}
{"op":"mcm","clk":"4213195976","pt":1631358034786,"mc":[{"id":"1.187528277","rc":[{"batb":[[0,1.42,2279.88]],"ltp":1.44,"tv":27720.35,"id":2249229}]}]}
{"op":"mcm","clk":"4213202403","pt":1631358059432,"mc":[{"id":"1.187528277","rc":[{"batb":[[1,3.25,257.74]],"ltp":3.3,"tv":6431.17,"id":19924831},{"batl":[[0,1.44,1714.95]],"ltp":1.44,"tv":27720.35,"id":2249229}]}]}
{"op":"mcm","clk":"4213204884","pt":1631358067429,"mc":[{"id":"1.187528277","rc":[{"batl":[[0,1.44,1715.03]],"ltp":1.44,"tv":27720.35,"id":2249229}]}]}
{"op":"mcm","clk":"4213214831","pt":1631358100520,"mc":[{"id":"1.187528277","rc":[{"batb":[[1,3.25,265.43]],"ltp":3.3,"tv":6431.17,"id":19924831}]}]}
{"op":"mcm","clk":"4213220779","pt":1631358136166,"mc":[{"id":"1.187528277","rc":[{"trd":[[1.44,3458.5]],"batl":[[0,1.44,1672.32]],"ltp":1.44,"tv":27805.76,"id":2249229}],"tv":34236.93}]}
{"op":"mcm","clk":"4213221134","pt":1631358138247,"mc":[{"id":"1.187528277","rc":[{"batl":[[0,1.44,1685.16]],"ltp":1.44,"tv":27805.76,"id":2249229}]}]}
{"op":"mcm","clk":"4213227419","pt":1631358175341,"mc":[{"id":"1.187528277","rc":[{"batb":[[2,3.2,74.15]],"ltp":3.3,"tv":6431.17,"id":19924831}]}]}
{"op":"mcm","clk":"4213235996","pt":1631358227217,"mc":[{"id":"1.187528277","rc":[{"trd":[[1.42,12497.09]],"batb":[[0,1.42,2277.22]],"ltp":1.42,"tv":27811.08,"id":2249229}],"tv":34242.25}]}
{"op":"mcm","clk":"4213243341","pt":1631358272098,"mc":[{"id":"1.187528277","rc":[{"batb":[[0,1.42,2311.7]],"ltp":1.42,"tv":27811.08,"id":2249229}]}]}
{"op":"mcm","clk":"4213255089","pt":1631358317690,"mc":[{"id":"1.187528277","rc":[{"batl":[[0,1.44,1687.81]],"ltp":1.42,"tv":27811.08,"id":2249229}]}]}
{"op":"mcm","clk":"4213259089","pt":1631358333137,"mc":[{"id":"1.187528277","rc":[{"batb":[[0,1.42,2314.9]],"ltp":1.42,"tv":27811.08,"id":2249229}]}]}
{"op":"mcm","clk":"4213283498","pt":1631358440524,"mc":[{"id":"1.187528277","rc":[{"batl":[[0,3.35,106.02]],"ltp":3.3,"tv":6431.17,"id":19924831}]}]}
{"op":"mcm","clk":"4213289052","pt":1631358465857,"mc":[{"id":"1.187528277","rc":[{"batl":[[0,3.35,109.63]],"ltp":3.3,"tv":6431.17,"id":19924831}]}]}
{"op":"mcm","clk":"4213326066","pt":1631358621450,"mc":[{"id":"1.187528277","rc":[{"batb":[[1,3.25,290.2],[2,3.2,33.15]],"batl":[[1,3.4,212.15]],"ltp":3.3,"tv":6431.17,"id":19924831},{"batb":[[0,1.42,2229.49],[1,1.41,2969.17]],"batl":[[1,1.45,1646.49]],"ltp":1.42,"tv":27811.08,"id":2249229}]}]}
{"op":"mcm","clk":"4213331254","pt":1631358644435,"mc":[{"id":"1.187528277","rc":[{"batb":[[1,3.25,293.26]],"batl":[[1,3.4,205.66]],"ltp":3.3,"tv":6431.17,"id":19924831}]}]}
{"op":"mcm","clk":"4213333366","pt":1631358654060,"mc":[{"id":"1.187528277","rc":[{"batb":[[1,3.25,268.5],[2,3.2,75]],"batl":[[0,3.35,134.4],[1,3.4,171.5]],"ltp":3.3,"tv":6431.17,"id":19924831},{"batb":[[0,1.42,2314.04],[1,1.41,2840.21]],"batl":[[1,1.45,1560.23],[2,1.46,866.76]],"ltp":1.42,"tv":27811.08,"id":2249229}]}]}
{"op":"mcm","clk":"4213333609","pt":1631358655120,"mc":[{"id":"1.187528277","rc":[{"batb":[[0,1.42,2279.56]],"ltp":1.42,"tv":27811.08,"id":2249229}]}]}
{"op":"mcm","clk":"4213333777","pt":1631358655922,"mc":[{"id":"1.187528277","rc":[{"batb":[[0,1.42,2314.04]],"ltp":1.42,"tv":27811.08,"id":2249229}]}]}
{"op":"mcm","clk":"4213340315","pt":1631358683591,"mc":[{"id":"1.187528277","rc":[{"batl":[[0,3.35,138.66]],"ltp":3.3,"tv":6431.17,"id":19924831}]}]}
{"op":"mcm","clk":"4213348273","pt":1631358719808,"mc":[{"id":"1.187528277","rc":[{"trd":[[3.3,2158.67]],"batb":[[0,3.3,96.86]],"ltp":3.3,"tv":6515.76,"id":19924831}],"tv":34326.85}]}
{"op":"mcm","clk":"4213348689","pt":1631358721480,"mc":[{"id":"1.187528277","rc":[{"batl":[[0,3.35,148.35]],"ltp":3.3,"tv":6515.76,"id":19924831}]}]}
{"op":"mcm","clk":"4213368564","pt":1631358809220,"mc":[{"id":"1.187528277","rc":[{"batb":[[0,1.43,40],[1,1.42,2314.04],[2,1.41,2840.21]],"ltp":1.42,"tv":27811.08,"id":2249229}]}]}
{"op":"mcm","clk":"4213372831","pt":1631358827675,"mc":[{"id":"1.187528277","rc":[{"batb":[[1,1.42,2258.29],[2,1.41,2547.72]],"ltp":1.42,"tv":27811.08,"id":2249229}]}]}
{"op":"mcm","clk":"4213373039","pt":1631358828599,"mc":[{"id":"1.187528277","rc":[{"batb":[[0,1.43,46]],"batl":[[0,1.44,1674.98]],"ltp":1.42,"tv":27811.08,"id":2249229}]}]}
{"op":"mcm","clk":"4213373172","pt":1631358829187,"mc":[{"id":"1.187528277","rc":[{"batl":[[0,1.44,1632.66]],"ltp":1.42,"tv":27811.08,"id":2249229}]}]}
{"op":"mcm","clk":"4213373505","pt":1631358830467,"mc":[{"id":"1.187528277","rc":[{"batl":[[1,1.45,1542.23]],"ltp":1.42,"tv":27811.08,"id":2249229}]}]}
{"op":"mcm","clk":"4213373742","pt":1631358831485,"mc":[{"id":"1.187528277","rc":[{"batb":[[1,3.25,257.74]],"ltp":3.3,"tv":6515.76,"id":19924831}]}]}
{"op":"mcm","clk":"4213374039","pt":1631358832673,"mc":[{"id":"1.187528277","rc":[{"batb":[[0,3.3,91.82]],"batl":[[0,3.35,153]],"ltp":3.3,"tv":6515.76,"id":19924831}]}]}
{"op":"mcm","clk":"4213379885","pt":1631358857714,"mc":[{"id":"1.187528277","rc":[{"batb":[[1,3.25,250.95]],"ltp":3.3,"tv":6515.76,"id":19924831}]}]}
{"op":"mcm","clk":"4213379938","pt":1631358857923,"mc":[{"id":"1.187528277","rc":[{"batb":[[0,3.3,98.61]],"ltp":3.3,"tv":6515.76,"id":19924831}]}]}
{"op":"mcm","clk":"4213385324","pt":1631358880645,"mc":[{"id":"1.187528277","rc":[{"trd":[[1.43,10642.82]],"batb":[[0,1.43,19.97]],"ltp":1.43,"tv":27863.14,"id":2249229}],"tv":34378.91}]}
{"op":"mcm","clk":"4213391252","pt":1631358905485,"mc":[{"id":"1.187528277","rc":[{"batb":[[2,3.2,85.25]],"batl":[[0,3.35,128.24],[1,3.4,212.49]],"ltp":3.3,"tv":6515.76,"id":19924831},{"batb":[[1,1.42,2251.46]],"batl":[[1,1.45,1627.63],[2,1.46,744.63]],"ltp":1.43,"tv":27863.14,"id":2249229}]}]}
{"op":"mcm","clk":"4213396105","pt":1631358926693,"mc":[{"id":"1.187528277","rc":[{"batb":[[1,1.42,2258.29]],"ltp":1.43,"tv":27863.14,"id":2249229}]}]}
{"op":"mcm","clk":"4213396291","pt":1631358927500,"mc":[{"id":"1.187528277","rc":[{"batb":[[1,3.25,284.25],[2,3.2,33.15]],"batl":[[1,3.4,204.8]],"ltp":3.3,"tv":6515.76,"id":19924831},{"batb":[[1,1.42,2173.74],[2,1.41,2684.36]],"ltp":1.43,"tv":27863.14,"id":2249229}]}]}
{"op":"mcm","clk":"4213396510","pt":1631358928633,"mc":[{"id":"1.187528277","rc":[{"batb":[[1,3.25,292.8]],"batl":[[1,3.4,188.58]],"ltp":3.3,"tv":6515.76,"id":19924831},{"batb":[[2,1.41,2631.41]],"batl":[[1,1.45,1672.04]],"ltp":1.43,"tv":27863.14,"id":2249229}]}]}
{"op":"mcm","clk":"4213396717","pt":1631358929623,"mc":[{"id":"1.187528277","rc":[{"batl":[[1,3.4,171.5]],"ltp":3.3,"tv":6515.76,"id":19924831},{"batl":[[1,1.45,1542.23]],"ltp":1.43,"tv":27863.14,"id":2249229}]}]}
{"op":"mcm","clk":"4213396829","pt":1631358930056,"mc":[{"id":"1.187528277","rc":[{"batl":[[2,3.45,191.85]],"ltp":3.3,"tv":6515.76,"id":19924831},{"batl":[[0,1.44,1710.38]],"ltp":1.43,"tv":27863.14,"id":2249229}]}]}
{"op":"mcm","clk":"4213397309","pt":1631358932227,"mc":[{"id":"1.187528277","rc":[{"batb":[[1,3.25,284.25]],"batl":[[2,3.45,150]],"ltp":3.3,"tv":6515.76,"id":19924831},{"batb":[[2,1.41,2682.65]],"batl":[[0,1.44,1632.66]],"ltp":1.43,"tv":27863.14,"id":2249229}]}]}
{"op":"mcm","clk":"4213398818","pt":1631358939504,"mc":[{"id":"1.187528277","rc":[{"batl":[[1,3.4,161.9]],"ltp":3.3,"tv":6515.76,"id":19924831}]}]}
{"op":"mcm","clk":"4213399450","pt":1631358942245,"mc":[{"id":"1.187528277","rc":[{"batb":[[0,3.3,153.15]],"batl":[[0,3.35,74.51]],"ltp":3.3,"tv":6515.76,"id":19924831},{"trd":[[1.43,10682.76]],"batb":[[0,1.42,2173.74],[1,1.41,2682.65],[2,1.4,2023.5]],"batl":[[0,1.43,2480.03],[1,1.44,1632.66],[2,1.45,1542.23]],"ltp":1.43,"tv":27903.08,"id":2249229}],"tv":34418.85}]}
{"op":"mcm","clk":"4213405655","pt":1631358968262,"mc":[{"id":"1.187528277","rc":[{"batl":[[1,3.4,195.21]],"ltp":3.3,"tv":6515.76,"id":19924831},{"batl":[[2,1.45,1629.34]],"ltp":1.43,"tv":27903.08,"id":2249229}]}]}
{"op":"mcm","clk":"4213410113","pt":1631358987687,"mc":[{"id":"1.187528277","rc":[{"batl":[[2,1.45,1362.85]],"ltp":1.43,"tv":27903.08,"id":2249229}]}]}
{"op":"mcm","clk":"4213410264","pt":1631358988384,"mc":[{"id":"1.187528277","rc":[{"batl":[[2,1.45,1356.72]],"ltp":1.43,"tv":27903.08,"id":2249229}]}]}
{"op":"mcm","clk":"4213410728","pt":1631358990562,"mc":[{"id":"1.187528277","rc":[{"batb":[[1,1.41,2953.87]],"ltp":1.43,"tv":27903.08,"id":2249229}]}]}
{"op":"mcm","clk":"4213410962","pt":1631358991689,"mc":[{"id":"1.187528277","rc":[{"batl":[[0,3.35,65.59]],"ltp":3.3,"tv":6515.76,"id":19924831}]}]}
{"op":"mcm","clk":"4213411087","pt":1631358992373,"mc":[{"id":"1.187528277","rc":[{"batl":[[1,3.4,198.77]],"ltp":3.3,"tv":6515.76,"id":19924831}]}]}
{"op":"mcm","clk":"4213414243","pt":1631359006960,"mc":[{"id":"1.187528277","rc":[{"batl":[[1,1.44,796.05]],"ltp":1.43,"tv":27903.08,"id":2249229}]}]}
{"op":"mcm","clk":"4213421785","pt":1631359039085,"mc":[{"id":"1.187528277","rc":[{"batl":[[1,1.44,783.31]],"ltp":1.43,"tv":27903.08,"id":2249229}]}]}
{"op":"mcm","clk":"4213422098","pt":1631359040289,"mc":[{"id":"1.187528277","rc":[{"batb":[[1,3.25,251.75]],"ltp":3.3,"tv":6515.76,"id":19924831},{"batl":[[1,1.44,766.58]],"ltp":1.43,"tv":27903.08,"id":2249229}]}]}
{"op":"mcm","clk":"4213422342","pt":1631359041392,"mc":[{"id":"1.187528277","rc":[{"batb":[[1,3.25,242.23]],"ltp":3.3,"tv":6515.76,"id":19924831}]}]}
{"op":"mcm","clk":"4213422605","pt":1631359042408,"mc":[{"id":"1.187528277","rc":[{"batb":[[1,3.25,234.85]],"ltp":3.3,"tv":6515.76,"id":19924831}]}]}
{"op":"mcm","clk":"4213422892","pt":1631359043695,"mc":[{"id":"1.187528277","rc":[{"batl":[[0,3.35,61.98]],"ltp":3.3,"tv":6515.76,"id":19924831}]}]}
{"op":"mcm","clk":"4213446723","pt":1631359083687,"mc":[{"id":"1.187528277","rc":[{"batb":[[0,3.3,146.36]],"ltp":3.3,"tv":6515.76,"id":19924831}]}]}
{"op":"mcm","clk":"4213446757","pt":1631359083892,"mc":[{"id":"1.187528277","rc":[{"trd":[[3.35,2953.27]],"batl":[[0,3.35,55.19]],"ltp":3.35,"tv":6529.35,"id":19924831}],"tv":34432.43}]}
{"op":"mcm","clk":"4213448864","pt":1631359093697,"mc":[{"id":"1.187528277","rc":[{"trd":[[1.42,12524.98]],"batb":[[0,1.42,2159.8]],"ltp":1.42,"tv":27930.97,"id":2249229}],"tv":34460.32}]}
{"op":"mcm","clk":"4213448986","pt":1631359094295,"mc":[{"id":"1.187528277","rc":[{"batb":[[1,3.25,230.15]],"ltp":3.35,"tv":6529.35,"id":19924831}]}]}
{"op":"mcm","clk":"4213449193","pt":1631359095155,"mc":[{"id":"1.187528277","rc":[{"batb":[[0,3.3,150.82]],"batl":[[0,3.35,57.97]],"ltp":3.35,"tv":6529.35,"id":19924831}]}]}
{"op":"mcm","clk":"4213456282","pt":1631359126771,"mc":[{"id":"1.187528277","rc":[{"batb":[[0,1.42,3659.8]],"ltp":1.42,"tv":27930.97,"id":2249229}]}]}
{"op":"mcm","clk":"4213457344","pt":1631359131422,"mc":[{"id":"1.187528277","rc":[{"batl":[[1,1.44,937.38]],"ltp":1.42,"tv":27930.97,"id":2249229}]}]}
{"op":"mcm","clk":"4213459810","pt":1631359142613,"mc":[{"id":"1.187528277","rc":[{"batl":[[1,1.44,957.78]],"ltp":1.42,"tv":27930.97,"id":2249229}]}]}
{"op":"mcm","clk":"4213459974","pt":1631359143329,"mc":[{"id":"1.187528277","rc":[{"batb":[[1,3.25,236.13]],"batl":[[1,3.4,257.17]],"ltp":3.35,"tv":6529.35,"id":19924831}]}]}
{"op":"mcm","clk":"4213478805","pt":1631359223288,"mc":[{"id":"1.187528277","rc":[{"batl":[[1,1.44,960.84]],"ltp":1.42,"tv":27930.97,"id":2249229}]}]}
{"op":"mcm","clk":"4213499716","pt":1631359319106,"mc":[{"id":"1.187528277","rc":[{"batl":[[0,1.43,2580.03]],"ltp":1.42,"tv":27930.97,"id":2249229}]}]}
{"op":"mcm","clk":"4213500920","pt":1631359325121,"mc":[{"id":"1.187528277","rc":[{"trd":[[1.43,10699.84]],"batl":[[0,1.43,2571.49]],"ltp":1.43,"tv":27948.05,"id":2249229}],"tv":34477.4}]}
{"op":"mcm","clk":"4213502590","pt":1631359332847,"mc":[{"id":"1.187528277","rc":[{"batl":[[1,1.44,1060.84]],"ltp":1.43,"tv":27948.05,"id":2249229}]}]}
{"op":"mcm","clk":"4213503320","pt":1631359336472,"mc":[{"id":"1.187528277","rc":[{"batb":[[1,3.25,245.23]],"ltp":3.35,"tv":6529.35,"id":19924831},{"batl":[[1,1.44,1076.3]],"ltp":1.43,"tv":27948.05,"id":2249229}]}]}
{"op":"mcm","clk":"4213544349","pt":1631359541544,"mc":[{"id":"1.187528277","rc":[{"batl":[[0,3.35,79.32]],"ltp":3.35,"tv":6529.35,"id":19924831}]}]}
{"op":"mcm","clk":"4213549345","pt":1631359566374,"mc":[{"id":"1.187528277","rc":[{"trd":[[1.43,10743.4]],"batl":[[0,1.43,2549.71]],"ltp":1.43,"tv":27991.61,"id":2249229}],"tv":34520.96}]}
{"op":"mcm","clk":"4213554909","pt":1631359593176,"mc":[{"id":"1.187528277","rc":[{"batl":[[0,3.35,82.94]],"ltp":3.35,"tv":6529.35,"id":19924831}]}]}
{"op":"mcm","clk":"4213583617","pt":1631359738328,"mc":[{"id":"1.187528277","rc":[{"trd":[[1.43,11090.14]],"batl":[[0,1.43,2376.34]],"ltp":1.43,"tv":28338.35,"id":2249229}],"tv":34867.7}]}
{"op":"mcm","clk":"4213597405","pt":1631359812927,"mc":[{"id":"1.187528277","rc":[{"trd":[[1.43,11262.66]],"batl":[[0,1.43,2290.08]],"ltp":1.43,"tv":28510.87,"id":2249229}],"tv":35040.22}]}
{"op":"mcm","clk":"4213600643","pt":1631359829257,"mc":[{"id":"1.187528277","rc":[{"batb":[[1,3.25,239.25]],"ltp":3.35,"tv":6529.35,"id":19924831}]}]}
{"op":"mcm","clk":"4213601653","pt":1631359833980,"mc":[{"id":"1.187528277","rc":[{"trd":[[1.43,11362.66]],"batl":[[0,1.43,2240.08]],"ltp":1.43,"tv":28610.87,"id":2249229}],"tv":35140.22}]}
{"op":"mcm","clk":"4213619624","pt":1631359930113,"mc":[{"id":"1.187528277","rc":[{"batb":[[0,1.42,2159.8]],"ltp":1.43,"tv":28610.87,"id":2249229}]}]}
{"op":"mcm","clk":"4213627746","pt":1631359975527,"mc":[{"id":"1.187528277","rc":[{"batl":[[1,3.4,207.19]],"ltp":3.35,"tv":6529.35,"id":19924831}]}]}
{"op":"mcm","clk":"4213636061","pt":1631360021890,"mc":[{"id":"1.187528277","rc":[{"batl":[[1,3.4,198.77]],"ltp":3.35,"tv":6529.35,"id":19924831}]}]}
{"op":"mcm","clk":"4213676142","pt":1631360240734,"mc":[{"id":"1.187528277","rc":[{"trd":[[1.43,11415.84]],"batl":[[0,1.43,2213.49]],"ltp":1.43,"tv":28664.05,"id":2249229}],"tv":35193.4}]}
{"op":"mcm","clk":"4213754847","pt":1631360651482,"mc":[{"id":"1.187528277","rc":[{"trd":[[1.42,12606.97]],"batb":[[0,1.42,2118.81]],"ltp":1.42,"tv":28746.03,"id":2249229}],"tv":35275.38}]}
{"op":"mcm","clk":"4213754931","pt":1631360651860,"mc":[{"id":"1.187528277","rc":[{"batb":[[0,1.42,2135.08]],"ltp":1.42,"tv":28746.03,"id":2249229}]}]}
{"op":"mcm","clk":"4213818887","pt":1631360975681,"mc":[{"id":"1.187528277","rc":[{"batb":[[2,1.4,2132.14]],"ltp":1.42,"tv":28746.03,"id":2249229}]}]}
{"op":"mcm","clk":"4213825190","pt":1631361011220,"mc":[{"id":"1.187528277","rc":[{"trd":[[3.3,2170.89]],"batb":[[0,3.3,144.71]],"ltp":3.3,"tv":6541.57,"id":19924831},{"trd":[[1.43,11430.36]],"batl":[[0,1.43,2206.23]],"ltp":1.43,"tv":28760.55,"id":2249229}],"tv":35302.12}]}
{"op":"mcm","clk":"4213850738","pt":1631361167454,"mc":[{"id":"1.187528277","rc":[{"trd":[[1.43,11458.36]],"batl":[[0,1.43,2192.23]],"ltp":1.43,"tv":28788.55,"id":2249229}],"tv":35330.12}]}
{"op":"mcm","clk":"4213866352","pt":1631361275083,"mc":[{"id":"1.187528277","rc":[{"trd":[[3.35,3001.13]],"batl":[[0,3.35,59.01]],"ltp":3.35,"tv":6589.43,"id":19924831}],"tv":35377.98}]}
{"op":"mcm","clk":"4213867669","pt":1631361284306,"mc":[{"id":"1.187528277","rc":[{"batb":[[0,3.3,147.51]],"ltp":3.35,"tv":6589.43,"id":19924831}]}]}
{"op":"mcm","clk":"4213870612","pt":1631361304206,"mc":[{"id":"1.187528277","rc":[{"batb":[[0,1.42,2127.3]],"ltp":1.43,"tv":28788.55,"id":2249229}]}]}
{"op":"mcm","clk":"4213873216","pt":1631361320129,"mc":[{"id":"1.187528277","rc":[{"batb":[[1,1.41,2992.16]],"ltp":1.43,"tv":28788.55,"id":2249229}]}]}
{"op":"mcm","clk":"4213876541","pt":1631361343639,"mc":[{"id":"1.187528277","rc":[{"trd":[[3.35,3033.09]],"batl":[[0,3.35,43.03]],"ltp":3.35,"tv":6621.39,"id":19924831}],"tv":35409.94}]}
{"op":"mcm","clk":"4213876819","pt":1631361345234,"mc":[{"id":"1.187528277","rc":[{"trd":[[3.35,3119.16]],"batb":[[0,3.35,6.07],[1,3.3,147.51],[2,3.25,188.63]],"batl":[[0,3.4,251.71],[1,3.45,150],[2,3.5,25]],"ltp":3.35,"tv":6707.45,"id":19924831}],"tv":35496.01}]}
{"op":"mcm","clk":"4213877280","pt":1631361348071,"mc":[{"id":"1.187528277","rc":[{"batb":[[2,3.25,177.18]],"ltp":3.35,"tv":6707.45,"id":19924831}]}]}
{"op":"mcm","clk":"4213877559","pt":1631361349658,"mc":[{"id":"1.187528277","rc":[{"batb":[[2,3.25,162.1]],"ltp":3.35,"tv":6707.45,"id":19924831}]}]}
{"op":"mcm","clk":"4213877732","pt":1631361350677,"mc":[{"id":"1.187528277","rc":[{"batb":[[2,3.25,82.71]],"ltp":3.35,"tv":6707.45,"id":19924831}]}]}
{"op":"mcm","clk":"4213878194","pt":1631361353579,"mc":[{"id":"1.187528277","rc":[{"batb":[[1,3.3,150.18]],"batl":[[0,3.4,257.28]],"ltp":3.35,"tv":6707.45,"id":19924831}]}]}
{"op":"mcm","clk":"4213878255","pt":1631361353965,"mc":[{"id":"1.187528277","rc":[{"batl":[[1,3.45,355.93]],"ltp":3.35,"tv":6707.45,"id":19924831}]}]}
{"op":"mcm","clk":"4213880676","pt":1631361369570,"mc":[{"id":"1.187528277","rc":[{"batb":[[2,1.4,5747.21]],"ltp":1.43,"tv":28788.55,"id":2249229}]}]}
{"op":"mcm","clk":"4213881360","pt":1631361373843,"mc":[{"id":"1.187528277","rc":[{"trd":[[1.43,11472.88]],"batl":[[0,1.43,2184.97]],"ltp":1.43,"tv":28803.07,"id":2249229}],"tv":35510.53}]}
{"op":"mcm","clk":"4213889140","pt":1631361425688,"mc":[{"id":"1.187528277","rc":[{"batl":[[1,3.45,386.82]],"ltp":3.35,"tv":6707.45,"id":19924831}]}]}
{"op":"mcm","clk":"4213898046","pt":1631361485980,"mc":[{"id":"1.187528277","rc":[{"batl":[[1,3.45,391.45]],"ltp":3.35,"tv":6707.45,"id":19924831}]}]}
{"op":"mcm","clk":"4213899571","pt":1631361496057,"mc":[{"id":"1.187528277","rc":[{"trd":[[1.43,11530.98]],"batl":[[0,1.43,2155.92]],"ltp":1.43,"tv":28861.17,"id":2249229}],"tv":35568.63}]}
{"op":"mcm","clk":"4213952098","pt":1631361774275,"mc":[{"id":"1.187528277","rc":[{"batb":[[1,1.41,3523.96]],"ltp":1.43,"tv":28861.17,"id":2249229}]}]}
{"op":"mcm","clk":"4213953332","pt":1631361781055,"mc":[{"id":"1.187528277","rc":[{"batb":[[2,1.4,6810.81]],"ltp":1.43,"tv":28861.17,"id":2249229}]}]}
{"op":"mcm","clk":"4213958836","pt":1631361808323,"mc":[{"id":"1.187528277","rc":[{"trd":[[3.4,593.18]],"batl":[[0,3.4,221.41]],"ltp":3.4,"tv":6779.19,"id":19924831}],"tv":35640.37}]}
{"op":"mcm","clk":"4213962846","pt":1631361827644,"mc":[{"id":"1.187528277","rc":[{"batl":[[0,3.4,252.73]],"ltp":3.4,"tv":6779.19,"id":19924831}]}]}
{"op":"mcm","clk":"4213962916","pt":1631361828064,"mc":[{"id":"1.187528277","rc":[{"batl":[[1,3.45,421.22]],"ltp":3.4,"tv":6779.19,"id":19924831}]}]}
{"op":"mcm","clk":"4213968596","pt":1631361856330,"mc":[{"id":"1.187528277","rc":[{"trd":[[1.43,11548.98]],"batl":[[0,1.43,2146.92]],"ltp":1.43,"tv":28879.17,"id":2249229}],"tv":35658.37}]}
{"op":"mcm","clk":"4213968896","pt":1631361857844,"mc":[{"id":"1.187528277","rc":[{"trd":[[1.43,11578.02]],"batl":[[0,1.43,2132.4]],"ltp":1.43,"tv":28908.21,"id":2249229}],"tv":35687.41}]}
{"op":"mcm","clk":"4213975251","pt":1631361888700,"mc":[{"id":"1.187528277","rc":[{"batb":[[2,3.25,91.25]],"ltp":3.4,"tv":6779.19,"id":19924831}]}]}
{"op":"mcm","clk":"4213980578","pt":1631361914170,"mc":[{"id":"1.187528277","rc":[{"trd":[[3.4,609.78]],"batl":[[0,3.4,244.43]],"ltp":3.4,"tv":6795.8,"id":19924831}],"tv":35704.01}]}
{"op":"mcm","clk":"4213981877","pt":1631361920363,"mc":[{"id":"1.187528277","rc":[{"batb":[[1,3.3,173.11]],"batl":[[0,3.4,256.18]],"ltp":3.4,"tv":6795.8,"id":19924831}]}]}
{"op":"mcm","clk":"4214003340","pt":1631362026741,"mc":[{"id":"1.187528277","rc":[{"batl":[[1,1.44,1086.28]],"ltp":1.43,"tv":28908.21,"id":2249229}]}]}
{"op":"mcm","clk":"4214018455","pt":1631362099293,"mc":[{"id":"1.187528277","rc":[{"trd":[[1.43,11636.12]],"batl":[[0,1.43,2103.35]],"ltp":1.43,"tv":28966.31,"id":2249229}],"tv":35762.11}]}
{"op":"mcm","clk":"4214019776","pt":1631362105507,"mc":[{"id":"1.187528277","rc":[{"trd":[[1.42,12628.23]],"batb":[[0,1.42,2116.68]],"ltp":1.42,"tv":28987.58,"id":2249229}],"tv":35783.38}]}
{"op":"mcm","clk":"4214019875","pt":1631362105995,"mc":[{"id":"1.187528277","rc":[{"batb":[[1,3.3,183.03]],"ltp":3.4,"tv":6795.8,"id":19924831},{"batb":[[0,1.42,2108.18],[1,1.41,3550.04]],"ltp":1.42,"tv":28987.58,"id":2249229}]}]}
{"op":"mcm","clk":"4214031113","pt":1631362157169,"mc":[{"id":"1.187528277","rc":[{"batl":[[1,1.44,1091.19]],"ltp":1.42,"tv":28987.58,"id":2249229}]}]}
{"op":"mcm","clk":"4214045708","pt":1631362220924,"mc":[{"id":"1.187528277","rc":[{"trd":[[1.43,11650.64]],"batl":[[0,1.43,2096.09]],"ltp":1.43,"tv":29002.1,"id":2249229}],"tv":35797.9}]}
{"op":"mcm","clk":"4214057111","pt":1631362269725,"mc":[{"id":"1.187528277","rc":[{"trd":[[1.43,11658.04]],"batl":[[0,1.43,2092.39]],"ltp":1.43,"tv":29009.5,"id":2249229}],"tv":35805.3}]}
{"op":"mcm","clk":"4214071606","pt":1631362329424,"mc":[{"id":"1.187528277","rc":[{"trd":[[1.43,11914.25]],"batl":[[0,1.43,1964.28],[1,1.44,1219.3]],"ltp":1.43,"tv":29265.71,"id":2249229}],"tv":36061.51}]}
{"op":"mcm","clk":"4214073347","pt":1631362336457,"mc":[{"id":"1.187528277","rc":[{"batl":[[1,1.44,1239.25]],"ltp":1.43,"tv":29265.71,"id":2249229}]}]}
{"op":"mcm","clk":"4214099376","pt":1631362442825,"mc":[{"id":"1.187528277","rc":[{"batl":[[1,1.44,1242.24]],"ltp":1.43,"tv":29265.71,"id":2249229}]}]}
{"op":"mcm","clk":"4214100211","pt":1631362446499,"mc":[{"id":"1.187528277","rc":[{"trd":[[3.35,3123.15]],"batb":[[0,3.35,4.07]],"ltp":3.35,"tv":6799.8,"id":19924831}],"tv":36065.51}]}
{"op":"mcm","clk":"4214104005","pt":1631362462424,"mc":[{"id":"1.187528277","rc":[{"trd":[[3.4,615.71]],"batl":[[0,3.4,253.22]],"ltp":3.4,"tv":6805.72,"id":19924831}],"tv":36071.43}]}
{"op":"mcm","clk":"4214106153","pt":1631362471121,"mc":[{"id":"1.187528277","rc":[{"trd":[[1.43,11928.77]],"batl":[[0,1.43,1957.02]],"ltp":1.43,"tv":29280.23,"id":2249229}],"tv":36085.95}]}
{"op":"mcm","clk":"4214119136","pt":1631362525667,"mc":[{"id":"1.187528277","rc":[{"batl":[[0,3.4,256.3],[2,3.5,45]],"ltp":3.4,"tv":6805.72,"id":19924831}]}]}
{"op":"mcm","clk":"4214163118","pt":1631362707102,"mc":[{"id":"1.187528277","rc":[{"trd":[[1.42,12668.23]],"batb":[[0,1.42,2088.18]],"ltp":1.42,"tv":29320.23,"id":2249229}],"tv":36125.95}]}
{"op":"mcm","clk":"4214265174","pt":1631363194336,"mc":[{"id":"1.187528277","rc":[{"trd":[[1.43,11943.29]],"batl":[[0,1.43,1949.76]],"ltp":1.43,"tv":29334.75,"id":2249229}],"tv":36140.47}]}
{"op":"mcm","clk":"4214275523","pt":1631363235541,"mc":[{"id":"1.187528277","rc":[{"batb":[[1,3.3,173.11]],"ltp":3.4,"tv":6805.72,"id":19924831}]}]}
{"op":"mcm","clk":"4214275814","pt":1631363236530,"mc":[{"id":"1.187528277","rc":[{"trd":[[1.43,11972.4]],"batb":[[0,1.42,2096.56],[1,1.41,3523.96]],"batl":[[0,1.43,1935.21]],"ltp":1.43,"tv":29363.85,"id":2249229}],"tv":36169.58}]}
{"op":"mcm","clk":"4214275937","pt":1631363236931,"mc":[{"id":"1.187528277","rc":[{"batb":[[1,3.3,183.1]],"ltp":3.4,"tv":6805.72,"id":19924831},{"batb":[[0,1.42,2088.18],[1,1.41,3549.92]],"ltp":1.43,"tv":29363.85,"id":2249229}]}]}
{"op":"mcm","clk":"4214288307","pt":1631363288615,"mc":[{"id":"1.187528277","rc":[{"batb":[[2,3.25,55.38]],"batl":[[0,3.4,222.99]],"ltp":3.4,"tv":6805.72,"id":19924831},{"batb":[[1,1.41,3414.98]],"batl":[[2,1.45,1269.6]],"ltp":1.43,"tv":29363.85,"id":2249229}]}]}
{"op":"mcm","clk":"4214288378","pt":1631363288894,"mc":[{"id":"1.187528277","rc":[{"trd":[[3.35,3131.3]],"batb":[[0,3.3,183.1],[1,3.25,55.38],[2,3.2,21]],"batl":[[0,3.35,38.63],[1,3.4,222.99],[2,3.45,421.22]],"ltp":3.35,"tv":6813.86,"id":19924831},{"trd":[[1.43,12127.83]],"batl":[[0,1.43,1857.49]],"ltp":1.43,"tv":29519.29,"id":2249229}],"tv":36333.16}]}
{"op":"mcm","clk":"4214289145","pt":1631363292521,"mc":[{"id":"1.187528277","rc":[{"batb":[[2,3.2,71.39]],"batl":[[0,3.4,232.39],[1,3.45,421.22],[2,3.5,45]],"ltp":3.35,"tv":6813.86,"id":19924831},{"batb":[[0,1.42,2165.04]],"ltp":1.43,"tv":29519.29,"id":2249229}]}]}
{"op":"mcm","clk":"4214290792","pt":1631363299515,"mc":[{"id":"1.187528277","rc":[{"batl":[[0,3.4,266.55]],"ltp":3.35,"tv":6813.86,"id":19924831},{"batl":[[2,1.45,1353.3]],"ltp":1.43,"tv":29519.29,"id":2249229}]}]}
{"op":"mcm","clk":"4214298830","pt":1631363334675,"mc":[{"id":"1.187528277","rc":[{"batl":[[0,3.4,272.11]],"ltp":3.35,"tv":6813.86,"id":19924831}]}]}
{"op":"mcm","clk":"4214343159","pt":1631363531334,"mc":[{"id":"1.187528277","rc":[{"trd":[[1.42,13468.23]],"batb":[[0,1.42,1811.95]],"ltp":1.42,"tv":30319.29,"id":2249229}],"tv":37133.16}]}
{"op":"mcm","clk":"4214354006","pt":1631363580008,"mc":[{"id":"1.187528277","rc":[{"trd":[[1.42,13840.48]],"batb":[[0,1.42,1625.83]],"ltp":1.42,"tv":30691.55,"id":2249229}],"tv":37505.42}]}
{"op":"mcm","clk":"4214357963","pt":1631363598696,"mc":[{"id":"1.187528277","rc":[{"batb":[[0,1.42,1598.48]],"ltp":1.42,"tv":30691.55,"id":2249229}]}]}
{"op":"mcm","clk":"4214358418","pt":1631363600587,"mc":[{"id":"1.187528277","rc":[{"batl":[[0,3.4,263.47]],"ltp":3.35,"tv":6813.86,"id":19924831}]}]}
{"op":"mcm","clk":"4214358662","pt":1631363601685,"mc":[{"id":"1.187528277","rc":[{"batl":[[0,3.4,239.17]],"ltp":3.35,"tv":6813.86,"id":19924831}]}]}
{"op":"mcm","clk":"4214374368","pt":1631363670399,"mc":[{"id":"1.187528277","rc":[{"batl":[[0,3.4,232.51]],"ltp":3.35,"tv":6813.86,"id":19924831}]}]}
{"op":"mcm","clk":"4214426298","pt":1631363909935,"mc":[{"id":"1.187528277","rc":[{"trd":[[1.43,12191.03]],"batl":[[0,1.43,1825.89]],"ltp":1.43,"tv":30754.75,"id":2249229}],"tv":37568.62}]}
{"op":"mcm","clk":"4214439819","pt":1631363971969,"mc":[{"id":"1.187528277","rc":[{"trd":[[3.4,621.63]],"batl":[[0,3.4,229.55]],"ltp":3.4,"tv":6819.79,"id":19924831}],"tv":37574.54}]}
{"op":"mcm","clk":"4214448088","pt":1631364009515,"mc":[{"id":"1.187528277","rc":[{"batb":[[0,3.3,186.65]],"ltp":3.4,"tv":6819.79,"id":19924831}]}]}
{"op":"mcm","clk":"4214454437","pt":1631364037150,"mc":[{"id":"1.187528277","rc":[{"trd":[[1.43,12205.55]],"batl":[[0,1.43,1818.63]],"ltp":1.43,"tv":30769.27,"id":2249229}],"tv":37589.06}]}
{"op":"mcm","clk":"4214481902","pt":1631364157612,"mc":[{"id":"1.187528277","rc":[{"batb":[[1,1.41,2883.18],[2,1.4,5747.21]],"ltp":1.43,"tv":30769.27,"id":2249229}]}]}
{"op":"mcm","clk":"4214482449","pt":1631364159920,"mc":[{"id":"1.187528277","rc":[{"batl":[[0,1.43,1834.6]],"ltp":1.43,"tv":30769.27,"id":2249229}]}]}
{"op":"mcm","clk":"4214485797","pt":1631364175132,"mc":[{"id":"1.187528277","rc":[{"batl":[[1,3.45,391.45]],"ltp":3.4,"tv":6819.79,"id":19924831}]}]}
{"op":"mcm","clk":"4214489427","pt":1631364190868,"mc":[{"id":"1.187528277","rc":[{"trd":[[1.43,12249.97]],"batl":[[0,1.43,1812.39]],"ltp":1.43,"tv":30813.68,"id":2249229}],"tv":37633.47}]}
{"op":"mcm","clk":"4214503812","pt":1631364252513,"mc":[{"id":"1.187528277","rc":[{"batl":[[1,3.45,386.82]],"ltp":3.4,"tv":6819.79,"id":19924831}]}]}
{"op":"mcm","clk":"4214505898","pt":1631364261798,"mc":[{"id":"1.187528277","rc":[{"trd":[[1.43,12335.37]],"batl":[[0,1.43,1769.69]],"ltp":1.43,"tv":30899.08,"id":2249229}],"tv":37718.87}]}
{"op":"mcm","clk":"4214507878","pt":1631364270712,"mc":[{"id":"1.187528277","rc":[{"trd":[[3.3,3311.04]],"batb":[[0,3.25,11.73],[1,3.2,127.64],[2,2.78,22.83]],"batl":[[0,3.3,3268.49],[1,3.4,229.55],[2,3.45,386.82]],"ltp":3.3,"tv":7959.94,"id":19924831},{"trd":[[1.43,14105.06]],"batb":[[0,1.43,125.87],[1,1.42,1598.48],[2,1.41,2883.18]],"batl":[[0,1.44,1117.24],[1,1.45,1353.3],[2,1.46,744.63]],"ltp":1.43,"tv":32668.77,"id":2249229}],"tv":40628.72}]}
{"op":"mcm","clk":"4214514165","pt":1631364297177,"mc":[{"id":"1.187528277","rc":[{"batb":[[0,1.43,458.87]],"ltp":1.43,"tv":32668.77,"id":2249229}]}]}
{"op":"mcm","clk":"4214515982","pt":1631364303573,"mc":[{"id":"1.187528277","rc":[{"trd":[[1.44,3810.51]],"batl":[[0,1.44,941.22]],"ltp":1.44,"tv":33020.79,"id":2249229}],"tv":40980.74}]}
{"op":"mcm","clk":"4214516488","pt":1631364305243,"mc":[{"id":"1.187528277","rc":[{"batb":[[0,3.25,67.11]],"ltp":3.3,"tv":7959.94,"id":19924831},{"batl":[[0,1.44,5941.22]],"ltp":1.44,"tv":33020.79,"id":2249229}]}]}
{"op":"mcm","clk":"4214517737","pt":1631364310713,"mc":[{"id":"1.187528277","rc":[{"batb":[[0,3.25,217.11]],"ltp":3.3,"tv":7959.94,"id":19924831}]}]}
{"op":"mcm","clk":"4214522551","pt":1631364332538,"mc":[{"id":"1.187528277","rc":[{"batl":[[1,3.4,225.99]],"ltp":3.3,"tv":7959.94,"id":19924831},{"batb":[[2,1.41,2611.96]],"ltp":1.44,"tv":33020.79,"id":2249229}]}]}
{"op":"mcm","clk":"4214522762","pt":1631364333460,"mc":[{"id":"1.187528277","rc":[{"batl":[[1,3.4,218.86]],"ltp":3.3,"tv":7959.94,"id":19924831}]}]}
{"op":"mcm","clk":"4214522948","pt":1631364334270,"mc":[{"id":"1.187528277","rc":[{"batl":[[1,3.4,213.29]],"ltp":3.3,"tv":7959.94,"id":19924831}]}]}
{"op":"mcm","clk":"4214523209","pt":1631364335249,"mc":[{"id":"1.187528277","rc":[{"batl":[[1,3.4,96.5]],"ltp":3.3,"tv":7959.94,"id":19924831}]}]}
{"op":"mcm","clk":"4214523431","pt":1631364336244,"mc":[{"id":"1.187528277","rc":[{"batl":[[2,3.45,150]],"ltp":3.3,"tv":7959.94,"id":19924831}]}]}
{"op":"mcm","clk":"4214523768","pt":1631364337641,"mc":[{"id":"1.187528277","rc":[{"batb":[[0,1.43,637.87]],"batl":[[0,1.44,6005.74]],"ltp":1.44,"tv":33020.79,"id":2249229}]}]}
{"op":"mcm","clk":"4214524251","pt":1631364339661,"mc":[{"id":"1.187528277","rc":[{"batl":[[0,3.3,3286.03],[1,3.35,29.38],[2,3.4,96.5]],"ltp":3.3,"tv":7959.94,"id":19924831}]}]}
{"op":"mcm","clk":"4214531646","pt":1631364370692,"mc":[{"id":"1.187528277","rc":[{"trd":[[3.25,959.9]],"batb":[[0,3.25,165.87]],"ltp":3.25,"tv":8062.43,"id":19924831},{"batb":[[2,1.41,2586]],"ltp":1.44,"tv":33020.79,"id":2249229}],"tv":41083.22}]}
{"op":"mcm","clk":"4214531705","pt":1631364371018,"mc":[{"id":"1.187528277","rc":[{"batb":[[1,3.2,140.09]],"ltp":3.25,"tv":8062.43,"id":19924831},{"batb":[[0,1.43,657.74]],"ltp":1.44,"tv":33020.79,"id":2249229}]}]}
{"op":"mcm","clk":"4214540776","pt":1631364410662,"mc":[{"id":"1.187528277","rc":[{"batb":[[1,1.42,1604.78]],"ltp":1.44,"tv":33020.79,"id":2249229}]}]}
{"op":"mcm","clk":"4214541111","pt":1631364412266,"mc":[{"id":"1.187528277","rc":[{"batl":[[1,3.35,46.52]],"ltp":3.25,"tv":8062.43,"id":19924831}]}]}
{"op":"mcm","clk":"4214546366","pt":1631364435819,"mc":[{"id":"1.187528277","rc":[{"trd":[[1.44,3887.38]],"batl":[[0,1.44,5967.31]],"ltp":1.44,"tv":33097.65,"id":2249229}],"tv":41160.09}]}
{"op":"mcm","clk":"4214571534","pt":1631364484521,"mc":[{"id":"1.187528277","rc":[{"batb":[[1,1.42,1611.79]],"ltp":1.44,"tv":33097.65,"id":2249229}]}]}
{"op":"mcm","clk":"4214573168","pt":1631364491846,"mc":[{"id":"1.187528277","rc":[{"trd":[[1.44,3930.08]],"batl":[[0,1.44,5945.96]],"ltp":1.44,"tv":33140.36,"id":2249229}],"tv":41202.79}]}
