{"op":"mcm","clk":"4289862668","pt":1632494799895,"mc":[{"id":"1.188075669","rc":[{"trd":[[1.74,31.93]],"batb":[[0,1.72,229],[1,1.71,148.46],[2,1.7,194.69]],"batl":[[0,1.74,8.79],[1,1.76,247.58]],"ltp":1.74,"tv":15785.2,"id":9631939},{"batb":[[1,2.3,427.29]],"ltp":2.06,"tv":1285.74,"id":9454286}],"tv":17070.95}]}
{"op":"mcm","clk":"4289862873","pt":1632494802887,"mc":[{"id":"1.188075669","rc":[{"batb":[[0,1.72,319.16]],"ltp":1.74,"tv":15785.2,"id":9631939},{"batl":[[2,2.68,137.92]],"ltp":2.06,"tv":1285.74,"id":9454286}]}]}
{"op":"mcm","clk":"4289863223","pt":1632494807198,"mc":[{"id":"1.188075669","rc":[{"batb":[[0,1.72,229.17]],"batl":[[0,1.76,247.58],[1,1.78,199.36],[2,1.97,2.35]],"ltp":1.74,"tv":15785.2,"id":9631939},{"batb":[[1,2.3,11.53],[2,1.98,215.83]],"batl":[[0,2.56,48.03],[1,2.68,137.92],[2,2.7,194.17]],"ltp":2.06,"tv":1285.74,"id":9454286}]}]}
{"op":"mcm","clk":"4289863287","pt":1632494807987,"mc":[{"id":"1.188075669","rc":[{"batb":[[0,1.6,6.17],[1,1.59,418.72],[2,1.58,280.01]],"batl":[[0,1.76,60],[1,1.97,2.35],[2,2.02,164.29]],"ltp":1.74,"tv":15785.2,"id":9631939},{"batb":[[0,2.3,11.53],[1,1.98,215.83],[2,1.97,397.3]],"ltp":2.06,"tv":1285.74,"id":9454286}]}]}
{"op":"mcm","clk":"4289863330","pt":1632494808570,"mc":[{"id":"1.188075669","rc":[{"batb":[[0,1.59,418.89],[1,1.58,280.01],[2,1.3,176.04]],"batl":[[0,1.97,2.35],[1,2.02,164.29],[2,2.04,190.8]],"ltp":1.74,"tv":15785.2,"id":9631939},{"batb":[[0,1.98,215.83],[1,1.97,397.3],[2,1.95,38.51]],"batl":[[0,2.68,137.92],[1,2.7,194.17],[2,3.15,204.05]],"ltp":2.06,"tv":1285.74,"id":9454286}]}]}
{"op":"mcm","clk":"4289863420","pt":1632494810197,"mc":[{"id":"1.188075669","rc":[{"batl":[[0,2.56,521.83],[1,2.68,137.92],[2,2.7,194.17]],"ltp":2.06,"tv":1285.74,"id":9454286}]}]}
{"op":"mcm","clk":"4289863498","pt":1632494811186,"mc":[{"id":"1.188075669","rc":[{"batb":[[0,1.65,6.17],[1,1.64,5],[2,1.59,418.72]],"ltp":1.74,"tv":15785.2,"id":9631939},{"batl":[[0,2.54,3]],"ltp":2.06,"tv":1285.74,"id":9454286}]}]}
{"op":"mcm","clk":"4289863575","pt":1632494812019,"mc":[{"id":"1.188075669","rc":[{"batb":[[0,1.59,418.72],[1,1.58,280.01],[2,1.3,176.04]],"batl":[[0,1.97,6.35]],"ltp":1.74,"tv":15785.2,"id":9631939},{"batl":[[0,2.68,137.92],[1,2.7,194.17],[2,3.15,204.05]],"ltp":2.06,"tv":1285.74,"id":9454286}]}]}
{"op":"mcm","clk":"4289863632","pt":1632494812808,"mc":[{"id":"1.188075669","rc":[{"batb":[[0,1.75,153.16],[1,1.73,217],[2,1.59,418.72]],"batl":[[0,1.81,177.7],[1,1.83,182.69],[2,1.97,6.35]],"ltp":1.74,"tv":15785.2,"id":9631939}]}]}
{"op":"mcm","clk":"4289863849","pt":1632494815912,"mc":[{"id":"1.188075669","rc":[{"batb":[[2,1.62,138.55]],"batl":[[2,1.96,31.75]],"ltp":1.74,"tv":15785.2,"id":9631939},{"batb":[[0,2.02,115],[1,1.98,215.83],[2,1.97,397.3]],"batl":[[0,2.62,87.27],[1,2.68,137.92],[2,2.7,194.17]],"ltp":2.06,"tv":1285.74,"id":9454286}]}]}
{"op":"mcm","clk":"4289863980","pt":1632494818195,"mc":[{"id":"1.188075669","rc":[{"batb":[[2,1.59,418.72]],"batl":[[2,1.97,6.35]],"ltp":1.74,"tv":15785.2,"id":9631939},{"batb":[[0,1.98,215.83],[1,1.97,397.3],[2,1.95,38.51]],"batl":[[0,2.68,137.92],[1,2.7,194.17],[2,3.15,204.05]],"ltp":2.06,"tv":1285.74,"id":9454286}]}]}
{"op":"mcm","clk":"4289863988","pt":1632494818300,"mc":[{"id":"1.188075669","rc":[{"batb":[[0,1.59,418.72],[1,1.58,280.01],[2,1.3,176.04]],"batl":[[0,1.97,6.35],[1,2.02,164.29],[2,2.04,190.8]],"ltp":1.74,"tv":15785.2,"id":9631939}]}]}
{"op":"mcm","clk":"4289864113","pt":1632494820499,"mc":[{"id":"1.188075669","rc":[{"batl":[[0,1.72,45.08],[1,1.97,6.35],[2,2.02,164.29]],"ltp":1.74,"tv":15785.2,"id":9631939}]}]}
{"op":"mcm","clk":"4289864165","pt":1632494821332,"mc":[{"id":"1.188075669","rc":[{"batb":[[1,1.58,506.46],[2,1.57,153.98]],"ltp":1.74,"tv":15785.2,"id":9631939}]}]}
{"op":"mcm","clk":"4289864337","pt":1632494823314,"mc":[{"id":"1.188075669","rc":[{"batl":[[0,1.97,6.35],[1,2.02,164.29],[2,2.04,324.1]],"ltp":1.74,"tv":15785.2,"id":9631939}]}]}
{"op":"mcm","clk":"4289864436","pt":1632494824826,"mc":[{"id":"1.188075669","rc":[{"batb":[[0,1.59,214.94],[1,1.3,176.04],[2,1.2,394.35]],"batl":[[2,2.04,190.8]],"ltp":1.74,"tv":15785.2,"id":9631939},{"batl":[[0,3.15,204.05],[1,880,0.01],[2,3.15,0]],"ltp":2.06,"tv":1285.74,"id":9454286}]}]}
{"op":"mcm","clk":"4289864471","pt":1632494825408,"mc":[{"id":"1.188075669","rc":[{"batl":[[0,1.6,2.19],[1,1.97,6.35],[2,2.02,164.29]],"ltp":1.74,"tv":15785.2,"id":9631939}]}]}
{"op":"mcm","clk":"4289864529","pt":1632494826234,"mc":[{"id":"1.188075669","rc":[{"batl":[[0,880,0.01],[1,880,0]],"ltp":2.06,"tv":1285.74,"id":9454286}]}]}
{"op":"mcm","clk":"4289864678","pt":1632494828024,"mc":[{"id":"1.188075669","rc":[{"batb":[[0,1.93,495.46],[1,1.92,480.9],[2,1.91,480.9]],"batl":[[0,1.97,2.35],[1,2,3.56]],"ltp":1.74,"tv":15785.2,"id":9631939},{"batb":[[0,2.02,4],[1,2,7.56],[2,1.98,215.83]],"batl":[[0,2.04,177.75],[1,2.06,128.33],[2,2.42,12.4]],"ltp":2.06,"tv":1285.74,"id":9454286}]}]}
{"op":"mcm","clk":"4289864770","pt":1632494829122,"mc":[{"id":"1.188075669","rc":[{"trd":[[1.96,48.9],[1.97,4.9]],"batb":[[0,1.97,104.02],[1,1.93,495.46],[2,1.92,480.9]],"batl":[[0,2,3.56],[1,2.02,164.29],[2,2.04,190.8]],"ltp":1.97,"tv":15806.21,"id":9631939},{"trd":[[2.04,15.66]],"batb":[[0,2,3.56],[1,1.98,215.83],[2,1.97,397.3]],"batl":[[0,2.04,162.09],[2,2.34,1.71]],"ltp":2.04,"tv":1301.4,"id":9454286}],"tv":17107.61}]}
{"op":"mcm","clk":"4289864843","pt":1632494830121,"mc":[{"id":"1.188075669","rc":[{"batl":[[2,2.04,249.63]],"ltp":1.97,"tv":15806.21,"id":9631939},{"batb":[[2,1.97,412.53]],"batl":[[2,2.18,55.23]],"ltp":2.04,"tv":1301.4,"id":9454286}]}]}
{"op":"mcm","clk":"4289864981","pt":1632494831634,"mc":[{"id":"1.188075669","rc":[{"batl":[[0,2.18,55.23],[1,2.34,1.71],[2,2.42,12.4]],"ltp":2.04,"tv":1301.4,"id":9454286}]}]}
{"op":"mcm","clk":"4289865098","pt":1632494832935,"mc":[{"id":"1.188075669","rc":[{"batl":[[0,2.34,1.71],[1,2.42,12.4],[2,2.46,1825.38]],"ltp":2.04,"tv":1301.4,"id":9454286}]}]}
{"op":"mcm","clk":"4289865284","pt":1632494835025,"mc":[{"id":"1.188075669","rc":[{"batb":[[0,1.97,375.02],[1,1.96,167.6],[2,1.94,150.63]],"batl":[[2,2.04,401.64]],"ltp":1.97,"tv":15806.21,"id":9631939},{"batl":[[0,2.16,69.37],[1,2.18,1682.92],[2,2.34,1.71]],"ltp":2.04,"tv":1301.4,"id":9454286}]}]}
{"op":"mcm","clk":"4289865361","pt":1632494836168,"mc":[{"id":"1.188075669","rc":[{"batl":[[0,2.16,125.07]],"ltp":2.04,"tv":1301.4,"id":9454286}]}]}
{"op":"mcm","clk":"4289865425","pt":1632494837165,"mc":[{"id":"1.188075669","rc":[{"batl":[[0,2.16,55.7]],"ltp":2.04,"tv":1301.4,"id":9454286}]}]}
{"op":"mcm","clk":"4289865560","pt":1632494839146,"mc":[{"id":"1.188075669","rc":[{"batb":[[0,1.97,104.02]],"batl":[[0,2.02,164.29],[1,2.04,401.64],[2,2.06,132.52]],"ltp":1.97,"tv":15806.21,"id":9631939},{"batb":[[0,1.98,215.83],[1,1.97,412.53],[2,1.95,38.51]],"batl":[[2,2.42,12.4]],"ltp":2.04,"tv":1301.4,"id":9454286}]}]}
{"op":"mcm","clk":"4289865618","pt":1632494840141,"mc":[{"id":"1.188075669","rc":[{"batl":[[0,2.14,69.37],[1,2.16,55.7]],"ltp":2.04,"tv":1301.4,"id":9454286}]}]}
{"op":"mcm","clk":"4289865746","pt":1632494841866,"mc":[{"id":"1.188075669","rc":[{"batl":[[0,1.98,7.96],[1,2.02,164.29],[2,2.04,401.64]],"ltp":1.97,"tv":15806.21,"id":9631939},{"batl":[[0,2.06,7.67]],"ltp":2.04,"tv":1301.4,"id":9454286}]}]}
{"op":"mcm","clk":"4289865833","pt":1632494843068,"mc":[{"id":"1.188075669","rc":[{"trd":[[1.97,5.09]],"batb":[[0,1.97,103.93]],"ltp":1.97,"tv":15806.39,"id":9631939}],"tv":17107.8}]}
{"op":"mcm","clk":"4289865951","pt":1632494844945,"mc":[{"id":"1.188075669","rc":[{"batl":[[0,2.06,77.04],[1,2.42,12.4],[2,2.46,1825.38]],"ltp":2.04,"tv":1301.4,"id":9454286}]}]}
{"op":"mcm","clk":"4289866027","pt":1632494846150,"mc":[{"id":"1.188075669","rc":[{"trd":[[1.97,6.35]],"batb":[[0,1.97,592.3]],"ltp":1.97,"tv":15807.66,"id":9631939},{"batl":[[0,2.06,36.77]],"ltp":2.04,"tv":1301.4,"id":9454286}],"tv":17109.06}]}
{"op":"mcm","clk":"4289866138","pt":1632494847861,"mc":[{"id":"1.188075669","rc":[{"batl":[[1,2.14,56.19],[2,2.42,12.4]],"ltp":2.04,"tv":1301.4,"id":9454286}]}]}
{"op":"mcm","clk":"4289866348","pt":1632494851152,"mc":[{"id":"1.188075669","rc":[{"batb":[[0,1.97,103.3]],"batl":[[0,2.04,210.84],[1,2.06,128.27],[2,3.05,2.3]],"ltp":1.97,"tv":15807.66,"id":9631939},{"batb":[[0,1.97,213.97],[1,1.67,417.19],[2,1.57,210.05]],"batl":[[0,2.14,56.19],[1,2.72,245.93],[2,880,0.01]],"ltp":2.04,"tv":1301.4,"id":9454286}]}]}
{"op":"mcm","clk":"4289866364","pt":1632494851364,"mc":[{"id":"1.188075669","rc":[{"batb":[[0,1.72,161.79],[1,1.4,131.45],[2,1.3,176.04]],"batl":[[0,2.04,58.83],[1,3.05,2.3],[2,3.4,2.19]],"ltp":1.97,"tv":15807.66,"id":9631939},{"batb":[[0,1.97,15.23]],"ltp":2.04,"tv":1301.4,"id":9454286}]}]}
{"op":"mcm","clk":"4289866478","pt":1632494852771,"mc":[{"id":"1.188075669","rc":[{"batl":[[0,1.97,2.35]],"ltp":1.97,"tv":15807.66,"id":9631939},{"batb":[[0,1.67,417.19],[1,1.57,210.05],[2,1.53,3.42]],"batl":[[0,2.72,245.93],[1,880,0.01],[2,880,0]],"ltp":2.04,"tv":1301.4,"id":9454286}]}]}
{"op":"mcm","clk":"4289866650","pt":1632494855074,"mc":[{"id":"1.188075669","rc":[{"batl":[[0,1.97,2.44]],"ltp":1.97,"tv":15807.66,"id":9631939},{"batl":[[0,880,0.01],[1,880,0]],"ltp":2.04,"tv":1301.4,"id":9454286}]}]}
{"op":"mcm","clk":"4289866723","pt":1632494856066,"mc":[{"id":"1.188075669","rc":[{"trd":[[1.97,8.79]],"batb":[[0,1.94,18.42],[1,1.72,161.79],[2,1.4,131.45]],"batl":[[0,2.08,21.44]],"ltp":1.97,"tv":15810.09,"id":9631939},{"trd":[[2.02,2.38]],"batb":[[0,1.87,148.26],[1,1.85,175.24],[2,1.67,417.19]],"batl":[[0,1.94,168.51],[1,1.96,149.06],[2,2.08,18.44]],"ltp":2.02,"tv":1303.78,"id":9454286}],"tv":17113.88}]}
{"op":"mcm","clk":"4289866764","pt":1632494856493,"mc":[{"id":"1.188075669","rc":[{"batb":[[0,1.72,161.79],[1,1.4,131.45],[2,1.3,176.04]],"batl":[[0,3.05,2.3],[1,3.4,2.19],[2,3.4,0]],"ltp":1.97,"tv":15810.09,"id":9631939},{"batl":[[2,880,0.01]],"ltp":2.02,"tv":1303.78,"id":9454286}]}]}
{"op":"mcm","clk":"4289866863","pt":1632494857663,"mc":[{"id":"1.188075669","rc":[{"batb":[[0,1.88,119.23],[1,1.72,161.79],[2,1.4,131.45]],"ltp":1.97,"tv":15810.09,"id":9631939},{"batb":[[2,1.72,133.72]],"batl":[[2,2.14,106.23]],"ltp":2.02,"tv":1303.78,"id":9454286}]}]}
{"op":"mcm","clk":"4289866964","pt":1632494858970,"mc":[{"id":"1.188075669","rc":[{"batl":[[0,2.38,11.5],[1,3.05,2.3],[2,3.4,2.19]],"ltp":1.97,"tv":15810.09,"id":9631939},{"trd":[[1.94,4.42]],"batl":[[0,1.94,166.3]],"ltp":1.94,"tv":1308.2,"id":9454286}],"tv":17118.3}]}
{"op":"mcm","clk":"4289867053","pt":1632494860586,"mc":[{"id":"1.188075669","rc":[{"trd":[[2.06,2.19]],"ltp":2.06,"tv":15812.29,"id":9631939},{"trd":[[1.94,6.75]],"batl":[[0,1.94,163.97]],"ltp":1.94,"tv":1310.53,"id":9454286}],"tv":17122.82}]}
{"op":"mcm","clk":"4289867126","pt":1632494861683,"mc":[{"id":"1.188075669","rc":[{"batb":[[0,1.72,161.79],[1,1.4,131.45],[2,1.3,176.04]],"batl":[[0,3.05,2.3],[1,3.4,2.19],[2,3.4,0]],"ltp":2.06,"tv":15812.29,"id":9631939},{"batb":[[0,1.67,417.19],[1,1.57,210.05],[2,1.53,3.42]],"batl":[[0,2.6,262.24],[1,880,0.01],[2,2.14,0]],"ltp":1.94,"tv":1310.53,"id":9454286}]}]}
{"op":"mcm","clk":"4289867331","pt":1632494864578,"mc":[{"id":"1.188075669","rc":[{"batb":[[1,1.57,390.31],[2,1.56,159.91]],"batl":[[0,2.4,107.1],[1,2.44,160.33],[2,2.6,262.24]],"ltp":1.94,"tv":1310.53,"id":9454286}]}]}
{"op":"mcm","clk":"4289882164","pt":1632494868711,"mc":[{"id":"1.188075669","rc":[{"batl":[[0,2.6,262.24],[1,880,0.01],[2,2.6,0]],"ltp":1.94,"tv":1310.53,"id":9454286}]}]}
{"op":"mcm","clk":"4289882238","pt":1632494870211,"mc":[{"id":"1.188075669","rc":[{"trd":[[1.67,5.41]],"batb":[[0,1.67,414.49]],"ltp":1.67,"tv":1315.94,"id":9454286}],"tv":17128.23}]}
{"op":"mcm","clk":"4289882281","pt":1632494870921,"mc":[{"id":"1.188075669","rc":[{"batb":[[0,1.57,390.31],[1,1.56,159.91],[2,1.53,3.42]],"batl":[[0,880,0.01],[1,880,0]],"ltp":1.67,"tv":1315.94,"id":9454286}]}]}
{"op":"mcm","clk":"4289882329","pt":1632494871918,"mc":[{"id":"1.188075669","rc":[{"batb":[[0,2.6,367.78],[1,2.58,356.96],[2,2.56,356.96]],"batl":[[0,2.78,13.22],[1,2.84,336.7],[2,2.86,326.8]],"ltp":2.06,"tv":15812.29,"id":9631939},{"batl":[[0,1.6,10.92],[1,1.62,258.47],[2,1.63,136.1]],"ltp":1.67,"tv":1315.94,"id":9454286}]}]}
{"op":"mcm","clk":"4289882472","pt":1632494873189,"mc":[{"id":"1.188075669","rc":[{"trd":[[2.6,11.86],[2.66,6.57]],"batb":[[0,2.62,94.56],[1,2.6,361.85],[2,2.58,356.96]],"batl":[[0,2.66,46.56],[1,2.78,13.22],[2,2.84,336.7]],"ltp":2.6,"tv":15830.72,"id":9631939},{"trd":[[1.6,10.92]],"batl":[[0,1.62,258.47],[1,1.63,136.1],[2,1.74,60]],"ltp":1.6,"tv":1326.86,"id":9454286}],"tv":17157.58}]}
{"op":"mcm","clk":"4289882528","pt":1632494874024,"mc":[{"id":"1.188075669","rc":[{"batl":[[0,2.78,13.22],[1,2.84,336.7],[2,2.86,326.8]],"ltp":2.6,"tv":15830.72,"id":9631939},{"batl":[[0,1.62,242.68],[2,1.75,137.49]],"ltp":1.6,"tv":1326.86,"id":9454286}]}]}
{"op":"mcm","clk":"4289882638","pt":1632494875697,"mc":[{"id":"1.188075669","rc":[{"batl":[[2,1.67,4]],"ltp":1.6,"tv":1326.86,"id":9454286}]}]}
{"op":"mcm","clk":"4289882704","pt":1632494876899,"mc":[{"id":"1.188075669","rc":[{"trd":[[2.62,4.38]],"batb":[[0,2.62,92.37]],"batl":[[0,2.78,32.49]],"ltp":2.62,"tv":15835.1,"id":9631939},{"batb":[[0,1.57,408.23]],"ltp":1.6,"tv":1326.86,"id":9454286}],"tv":17161.96}]}
{"op":"mcm","clk":"4289882753","pt":1632494877633,"mc":[{"id":"1.188075669","rc":[{"trd":[[1.57,27.72]],"batb":[[0,1.57,394.2]],"ltp":1.57,"tv":1354.58,"id":9454286}],"tv":17189.68}]}
{"op":"mcm","clk":"4289883112","pt":1632494883032,"mc":[{"id":"1.188075669","rc":[{"batl":[[0,2.84,336.7],[1,2.86,326.8],[2,2.88,326.8]],"ltp":2.62,"tv":15835.1,"id":9631939}]}]}
{"op":"mcm","clk":"4289883199","pt":1632494884142,"mc":[{"id":"1.188075669","rc":[{"trd":[[1.57,27.92]],"batb":[[0,1.57,394.1]],"ltp":1.57,"tv":1354.77,"id":9454286}],"tv":17189.87}]}
{"op":"mcm","clk":"4289883348","pt":1632494886049,"mc":[{"id":"1.188075669","rc":[{"trd":[[2.72,9.5]],"batl":[[0,2.82,26.73],[1,2.84,336.7],[2,2.86,326.8]],"ltp":2.72,"tv":15844.6,"id":9631939},{"trd":[[1.57,35.22],[1.58,16.35]],"batb":[[0,1.57,390.45]],"batl":[[0,1.62,259.15]],"ltp":1.57,"tv":1378.42,"id":9454286}],"tv":17223.02}]}
{"op":"mcm","clk":"4289883387","pt":1632494886627,"mc":[{"id":"1.188075669","rc":[{"trd":[[1.62,1.26]],"batl":[[0,1.62,258.52]],"ltp":1.62,"tv":1379.68,"id":9454286}],"tv":17224.28}]}
{"op":"mcm","clk":"4289883703","pt":1632494890915,"mc":[{"id":"1.188075669","rc":[{"trd":[[2.62,46.59]],"batb":[[0,2.62,71.27]],"ltp":2.62,"tv":15886.81,"id":9631939}],"tv":17266.5}]}
{"op":"mcm","clk":"4289884049","pt":1632494896120,"mc":[{"id":"1.188075669","rc":[{"batl":[[0,1.62,242.05]],"ltp":1.62,"tv":1379.68,"id":9454286}]}]}
{"op":"mcm","clk":"4289884112","pt":1632494897061,"mc":[{"id":"1.188075669","rc":[{"batb":[[0,2.6,456.67],[1,2.58,356.96],[2,2.56,356.96]],"ltp":2.62,"tv":15886.81,"id":9631939}]}]}
{"op":"mcm","clk":"4289884131","pt":1632494897320,"mc":[{"id":"1.188075669","rc":[{"trd":[[1.62,5.96]],"batl":[[0,1.62,239.7]],"ltp":1.62,"tv":1384.38,"id":9454286}],"tv":17271.19}]}
{"op":"mcm","clk":"4289884247","pt":1632494899047,"mc":[{"id":"1.188075669","rc":[{"batl":[[0,2.78,10.21],[1,2.82,26.73],[2,2.84,336.7]],"ltp":2.62,"tv":15886.81,"id":9631939},{"trd":[[1.62,13.76]],"batl":[[0,1.6,16.16],[1,1.62,235.8],[2,1.63,136.1]],"ltp":1.62,"tv":1392.18,"id":9454286}],"tv":17278.99}]}
{"op":"mcm","clk":"4289884311","pt":1632494900147,"mc":[{"id":"1.188075669","rc":[{"batb":[[0,2.6,557.27]],"batl":[[1,2.84,336.7],[2,2.86,326.8]],"ltp":2.62,"tv":15886.81,"id":9631939},{"trd":[[1.6,12.1]],"batl":[[0,1.6,15.57]],"ltp":1.6,"tv":1393.36,"id":9454286}],"tv":17280.17}]}
{"op":"mcm","clk":"4289884327","pt":1632494900355,"mc":[{"id":"1.188075669","rc":[{"batb":[[0,2.6,476.99]],"ltp":2.62,"tv":15886.81,"id":9631939}]}]}
{"op":"mcm","clk":"4289884522","pt":1632494903029,"mc":[{"id":"1.188075669","rc":[{"batl":[[0,1.6,478.57]],"ltp":1.6,"tv":1393.36,"id":9454286}]}]}
{"op":"mcm","clk":"4289884839","pt":1632494908174,"mc":[{"id":"1.188075669","rc":[{"trd":[[2.66,6.66]],"ltp":2.66,"tv":15886.9,"id":9631939},{"trd":[[1.6,12.26]],"batl":[[0,1.6,478.41]],"ltp":1.6,"tv":1393.52,"id":9454286}],"tv":17280.42}]}
{"op":"mcm","clk":"4289884895","pt":1632494909055,"mc":[{"id":"1.188075669","rc":[{"trd":[[1.6,12.59]],"batl":[[0,1.6,478.24]],"ltp":1.6,"tv":1393.85,"id":9454286}],"tv":17280.76}]}
{"op":"mcm","clk":"4289884946","pt":1632494910046,"mc":[{"id":"1.188075669","rc":[{"batl":[[0,2.78,26.73]],"ltp":2.66,"tv":15886.9,"id":9631939},{"batl":[[0,1.6,463]],"ltp":1.6,"tv":1393.85,"id":9454286}]}]}
{"op":"mcm","clk":"4289884959","pt":1632494910358,"mc":[{"id":"1.188075669","rc":[{"batl":[[0,2.84,336.7],[1,2.86,326.8],[2,2.88,326.8]],"ltp":2.66,"tv":15886.9,"id":9631939}]}]}
{"op":"mcm","clk":"4289885144","pt":1632494912988,"mc":[{"id":"1.188075669","rc":[{"batl":[[0,2.78,10.74],[1,2.84,336.7],[2,2.86,326.8]],"ltp":2.66,"tv":15886.9,"id":9631939},{"trd":[[1.57,359.79]],"batb":[[0,1.57,228.16]],"batl":[[0,1.6,478.24]],"ltp":1.57,"tv":1718.43,"id":9454286}],"tv":17605.34}]}
{"op":"mcm","clk":"4289885208","pt":1632494913768,"mc":[{"id":"1.188075669","rc":[{"batl":[[1,2.82,105.91],[2,2.84,336.7]],"ltp":2.66,"tv":15886.9,"id":9631939}]}]}
{"op":"mcm","clk":"4289885250","pt":1632494914292,"mc":[{"id":"1.188075669","rc":[{"batl":[[1,2.84,336.7],[2,2.86,326.8]],"ltp":2.66,"tv":15886.9,"id":9631939}]}]}
{"op":"mcm","clk":"4289885430","pt":1632494917201,"mc":[{"id":"1.188075669","rc":[{"batb":[[0,2.64,92.88],[1,2.6,382.17],[2,2.58,356.96]],"ltp":2.66,"tv":15886.9,"id":9631939},{"trd":[[1.6,12.67]],"batb":[[0,1.57,411.38]],"batl":[[0,1.6,478.2]],"ltp":1.6,"tv":1718.51,"id":9454286}],"tv":17605.42}]}
{"op":"mcm","clk":"4289885500","pt":1632494918505,"mc":[{"id":"1.188075669","rc":[{"batl":[[0,2.84,336.7],[1,2.86,326.8],[2,2.88,326.8]],"ltp":2.66,"tv":15886.9,"id":9631939},{"trd":[[1.6,13.45]],"batl":[[0,1.6,462.57]],"ltp":1.6,"tv":1719.29,"id":9454286}],"tv":17606.2}]}
{"op":"mcm","clk":"4289885605","pt":1632494920263,"mc":[{"id":"1.188075669","rc":[{"batl":[[0,2.82,26.73],[1,2.84,336.7],[2,2.86,326.8]],"ltp":2.66,"tv":15886.9,"id":9631939}]}]}
{"op":"mcm","clk":"4289885674","pt":1632494921614,"mc":[{"id":"1.188075669","rc":[{"batl":[[0,2.84,336.7],[1,2.86,326.8],[2,2.88,326.8]],"ltp":2.66,"tv":15886.9,"id":9631939}]}]}
{"op":"mcm","clk":"4289885785","pt":1632494923221,"mc":[{"id":"1.188075669","rc":[{"trd":[[1.6,14.07]],"batl":[[0,1.6,462.26]],"ltp":1.6,"tv":1719.91,"id":9454286}],"tv":17606.82}]}
{"op":"mcm","clk":"4289885844","pt":1632494924218,"mc":[{"id":"1.188075669","rc":[{"trd":[[2.66,6.68]],"ltp":2.66,"tv":15886.92,"id":9631939},{"trd":[[1.57,492.87],[1.6,14.1]],"batb":[[0,1.57,344.84]],"batl":[[0,1.6,462.23]],"ltp":1.6,"tv":1853.02,"id":9454286}],"tv":17739.95}]}
{"op":"mcm","clk":"4289885886","pt":1632494924792,"mc":[{"id":"1.188075669","rc":[{"batb":[[0,2.64,92.54]],"batl":[[0,2.78,37.47],[1,2.84,336.7],[2,2.86,326.8]],"ltp":2.66,"tv":15886.92,"id":9631939},{"batl":[[0,1.6,477.47]],"ltp":1.6,"tv":1853.02,"id":9454286}]}]}
{"op":"mcm","clk":"4289886040","pt":1632494927183,"mc":[{"id":"1.188075669","rc":[{"batb":[[0,1.57,365.13]],"batl":[[1,1.62,258.46]],"ltp":1.6,"tv":1853.02,"id":9454286}]}]}
{"op":"mcm","clk":"4289886488","pt":1632494933112,"mc":[{"id":"1.188075669","rc":[{"trd":[[1.6,16.84]],"batl":[[0,1.6,476.1]],"ltp":1.6,"tv":1855.76,"id":9454286}],"tv":17742.68}]}
{"op":"mcm","clk":"4289887227","pt":1632494944136,"mc":[{"id":"1.188075669","rc":[{"trd":[[1.6,51.06]],"batl":[[0,1.6,458.99]],"ltp":1.6,"tv":1889.98,"id":9454286}],"tv":17776.9}]}
{"op":"mcm","clk":"4289887271","pt":1632494944918,"mc":[{"id":"1.188075669","rc":[{"trd":[[1.6,53.4]],"batl":[[0,1.6,457.82]],"ltp":1.6,"tv":1892.32,"id":9454286}],"tv":17779.24}]}
{"op":"mcm","clk":"4289888268","pt":1632494960179,"mc":[{"id":"1.188075669","rc":[{"batb":[[1,2.6,20.32],[2,2.54,3]],"batl":[[0,2.78,26.73],[1,3.05,2.3],[2,3.4,2.19]],"ltp":2.66,"tv":15886.92,"id":9631939},{"batl":[[0,1.6,442.58]],"ltp":1.6,"tv":1892.32,"id":9454286}]}]}
{"op":"mcm","clk":"4289888357","pt":1632494961171,"mc":[{"id":"1.188075669","rc":[{"batb":[[0,2.32,131.93],[1,1.12,2.53],[2,1.11,2.86]],"batl":[[0,3.05,2.3],[1,990,0.01],[2,3.4,0]],"ltp":2.66,"tv":15886.92,"id":9631939},{"batb":[[0,1.53,3.42],[1,1.5,252.73],[2,1.49,43.01]],"batl":[[0,1.98,30.45],[1,2.22,334.98],[2,990,0.01]],"ltp":1.6,"tv":1892.32,"id":9454286}]}]}
{"op":"mcm","clk":"4289888565","pt":1632494963945,"mc":[{"id":"1.188075669","rc":[{"batb":[[1,2.2,3.67],[2,1.12,2.53]],"batl":[[0,3,6.24]],"ltp":2.66,"tv":15886.92,"id":9631939},{"batb":[[1,1.5,485.75],[2,1.49,193.81]],"batl":[[0,1.76,141.97],[1,1.77,14.5],[2,1.78,202.87]],"ltp":1.6,"tv":1892.32,"id":9454286}]}]}
{"op":"mcm","clk":"4289888629","pt":1632494964769,"mc":[{"id":"1.188075669","rc":[{"batb":[[0,2.32,134.93],[1,2.3,4],[2,2.2,3.67]],"ltp":2.66,"tv":15886.92,"id":9631939},{"batl":[[0,1.76,3],[2,1.83,14.5]],"ltp":1.6,"tv":1892.32,"id":9454286}]}]}
{"op":"mcm","clk":"4289888788","pt":1632494967074,"mc":[{"id":"1.188075669","rc":[{"batb":[[2,2.28,3.66]],"ltp":2.66,"tv":15886.92,"id":9631939}]}]}
{"op":"mcm","clk":"4289888860","pt":1632494968190,"mc":[{"id":"1.188075669","rc":[{"batb":[[0,2.88,6.87],[1,2.8,341.52],[2,2.78,331.48]],"batl":[[0,2.96,4.89],[1,3,3.24],[2,3.1,308.46]],"ltp":2.66,"tv":15886.92,"id":9631939},{"batl":[[0,1.54,222.7],[1,1.55,164.22],[2,1.56,511.66]],"ltp":1.6,"tv":1892.32,"id":9454286}]}]}
{"op":"mcm","clk":"4289888935","pt":1632494969178,"mc":[{"id":"1.188075669","rc":[{"trd":[[2.86,9.7],[2.88,13.74]],"batb":[[0,2.86,70.56]],"ltp":2.86,"tv":15910.36,"id":9631939}],"tv":17802.68}]}
{"op":"mcm","clk":"4289888986","pt":1632494969875,"mc":[{"id":"1.188075669","rc":[{"batl":[[0,2.94,43.07],[1,2.96,4.89],[2,3,3.24]],"ltp":2.86,"tv":15910.36,"id":9631939},{"batb":[[1,1.51,21],[2,1.5,485.75]],"ltp":1.6,"tv":1892.32,"id":9454286}]}]}
{"op":"mcm","clk":"4289889070","pt":1632494970986,"mc":[{"id":"1.188075669","rc":[{"trd":[[1.53,6.84]],"batb":[[0,1.51,21],[1,1.5,485.75],[2,1.49,200.81]],"ltp":1.53,"tv":1899.16,"id":9454286}],"tv":17809.53}]}
{"op":"mcm","clk":"4289889276","pt":1632494973970,"mc":[{"id":"1.188075669","rc":[{"batl":[[0,1.54,360.7]],"ltp":1.53,"tv":1899.16,"id":9454286}]}]}
{"op":"mcm","clk":"4289889349","pt":1632494975081,"mc":[{"id":"1.188075669","rc":[{"batb":[[2,1.49,252.82]],"batl":[[0,1.54,222.7]],"ltp":1.53,"tv":1899.16,"id":9454286}]}]}
{"op":"mcm","clk":"4289889483","pt":1632494977191,"mc":[{"id":"1.188075669","rc":[{"batl":[[0,1.53,378],[1,1.54,222.7],[2,1.55,164.22]],"ltp":1.53,"tv":1899.16,"id":9454286}]}]}
{"op":"mcm","clk":"4289889578","pt":1632494978915,"mc":[{"id":"1.188075669","rc":[{"batl":[[1,3,3.24],[2,3.05,3.3]],"ltp":2.86,"tv":15910.36,"id":9631939},{"trd":[[1.53,7.03]],"batl":[[0,1.53,377.91]],"ltp":1.53,"tv":1899.34,"id":9454286}],"tv":17809.71}]}
{"op":"mcm","clk":"4289889708","pt":1632494981103,"mc":[{"id":"1.188075669","rc":[{"batb":[[1,2.62,37.03],[2,2.58,167.1]],"ltp":2.86,"tv":15910.36,"id":9631939}]}]}
{"op":"mcm","clk":"4289889796","pt":1632494982102,"mc":[{"id":"1.188075669","rc":[{"batb":[[0,2.62,37.03],[1,2.58,167.1],[2,2.56,206.96]],"batl":[[1,3.15,114.18],[2,3.2,148.42]],"ltp":2.86,"tv":15910.36,"id":9631939},{"batb":[[1,1.48,5],[2,1.47,52.67]],"batl":[[0,1.62,60],[1,1.63,20.77],[2,1.64,267.03]],"ltp":1.53,"tv":1899.34,"id":9454286}]}]}
{"op":"mcm","clk":"4289889842","pt":1632494982696,"mc":[{"id":"1.188075669","rc":[{"batb":[[0,2.58,164.23],[1,2.56,206.96],[2,2.54,102.32]],"batl":[[0,3.15,111.08],[1,3.2,148.42],[2,3.25,3.06]],"ltp":2.86,"tv":15910.36,"id":9631939},{"batb":[[0,1.48,5],[1,1.46,800.64],[2,1.45,435.52]],"batl":[[0,1.64,267.03],[1,1.65,218.42],[2,1.66,19.25]],"ltp":1.53,"tv":1899.34,"id":9454286}]}]}
{"op":"mcm","clk":"4289889943","pt":1632494984180,"mc":[{"id":"1.188075669","rc":[{"batb":[[2,1.45,729.41]],"batl":[[1,1.65,453.65],[2,1.66,146.9]],"ltp":1.53,"tv":1899.34,"id":9454286}]}]}
{"op":"mcm","clk":"4289889984","pt":1632494984803,"mc":[{"id":"1.188075669","rc":[{"batl":[[1,1.65,218.42],[2,1.66,19.25]],"ltp":1.53,"tv":1899.34,"id":9454286}]}]}
{"op":"mcm","clk":"4289890074","pt":1632494986110,"mc":[{"id":"1.188075669","rc":[{"batb":[[0,2.8,18.78],[1,2.58,166.91],[2,2.56,206.96]],"batl":[[0,2.94,19.75],[1,3.1,3],[2,3.15,114.18]],"ltp":2.86,"tv":15910.36,"id":9631939},{"batb":[[0,1.52,153.36],[1,1.51,183.39],[2,1.48,5]],"batl":[[0,1.55,18.5],[1,1.56,213.64],[2,1.57,156.45]],"ltp":1.53,"tv":1899.34,"id":9454286}]}]}
{"op":"mcm","clk":"4289890161","pt":1632494987213,"mc":[{"id":"1.188075669","rc":[{"batb":[[0,2.6,58.26],[1,2.58,164.23]],"batl":[[0,3.1,3],[1,3.15,111.08],[2,3.2,148.42]],"ltp":2.86,"tv":15910.36,"id":9631939},{"batb":[[2,1.49,25]],"batl":[[0,1.56,213.64],[1,1.57,156.45],[2,1.63,98.01]],"ltp":1.53,"tv":1899.34,"id":9454286}]}]}
{"op":"mcm","clk":"4289890340","pt":1632494989733,"mc":[{"id":"1.188075669","rc":[{"batb":[[0,2.58,164.23],[1,2.56,206.96],[2,2.54,102.32]],"ltp":2.86,"tv":15910.36,"id":9631939},{"batb":[[0,1.48,5],[1,1.47,7],[2,1.46,800.64]],"batl":[[0,1.64,267.03],[1,1.65,218.42],[2,1.66,19.25]],"ltp":1.53,"tv":1899.34,"id":9454286}]}]}
{"op":"mcm","clk":"4289890574","pt":1632494993007,"mc":[{"id":"1.188075669","rc":[{"batb":[[0,2.58,166.79]],"batl":[[1,3.15,114.38]],"ltp":2.86,"tv":15910.36,"id":9631939},{"batb":[[1,1.47,63.67]],"batl":[[0,1.63,19.5],[1,1.64,267.03],[2,1.65,451.83]],"ltp":1.53,"tv":1899.34,"id":9454286}]}]}
{"op":"mcm","clk":"4289890631","pt":1632494994005,"mc":[{"id":"1.188075669","rc":[{"batb":[[0,2.54,102.32],[1,2.5,2.79],[2,2.48,2.76]],"batl":[[1,3.15,111.08]],"ltp":2.86,"tv":15910.36,"id":9631939},{"batb":[[1,1.47,7]],"batl":[[0,1.52,48.26],[1,1.66,19.25],[2,1.67,16.5]],"ltp":1.53,"tv":1899.34,"id":9454286}]}]}
{"op":"mcm","clk":"4289890675","pt":1632494994618,"mc":[{"id":"1.188075669","rc":[{"batb":[[1,2.48,2.76],[2,2.34,4]],"ltp":2.86,"tv":15910.36,"id":9631939},{"batl":[[0,1.49,2.19],[1,1.52,48.26]],"ltp":1.53,"tv":1899.34,"id":9454286}]}]}
{"op":"mcm","clk":"4289890710","pt":1632494995417,"mc":[{"id":"1.188075669","rc":[{"batb":[[2,1.46,357.04]],"ltp":1.53,"tv":1899.34,"id":9454286}]}]}
{"op":"mcm","clk":"4289890806","pt":1632494997124,"mc":[{"id":"1.188075669","rc":[{"batb":[[0,3,322.84],[1,2.98,309.38],[2,2.96,309.38]],"batl":[[0,3.1,7.91]],"ltp":2.86,"tv":15910.36,"id":9631939},{"trd":[[1.48,10]],"batb":[[0,1.47,7],[1,1.46,357.04],[2,1.45,729.41]],"batl":[[0,1.48,151.44],[1,1.49,194.55],[2,1.5,8.16]],"ltp":1.48,"tv":1909.34,"id":9454286}],"tv":17819.71}]}
{"op":"mcm","clk":"4289890871","pt":1632494998219,"mc":[{"id":"1.188075669","rc":[{"trd":[[3.05,11.03]],"batb":[[0,3.05,158.93],[1,3,322.84],[2,2.98,309.38]],"batl":[[2,3.2,188.87]],"ltp":3.05,"tv":15921.39,"id":9631939},{"trd":[[1.48,32.73]],"batb":[[1,1.46,379.15]],"batl":[[0,1.49,192.36],[1,1.5,8.16],[2,1.52,48.26]],"ltp":1.48,"tv":1932.07,"id":9454286}],"tv":17853.47}]}
{"op":"mcm","clk":"4289890926","pt":1632494999038,"mc":[{"id":"1.188075669","rc":[{"batl":[[0,3.1,4.91]],"ltp":3.05,"tv":15921.39,"id":9631939},{"batb":[[0,1.46,379.15],[1,1.45,729.41],[2,1.44,605.12]],"batl":[[2,1.56,1370.77]],"ltp":1.48,"tv":1932.07,"id":9454286}]}]}
{"op":"mcm","clk":"4289890993","pt":1632495000214,"mc":[{"id":"1.188075669","rc":[{"batb":[[0,1.46,386.15]],"batl":[[2,1.56,1310.77]],"ltp":1.48,"tv":1932.07,"id":9454286}]}]}
{"op":"mcm","clk":"4289891063","pt":1632495001216,"mc":[{"id":"1.188075669","rc":[{"batb":[[1,3,346.46]],"ltp":3.05,"tv":15921.39,"id":9631939},{"batb":[[0,1.46,379.15],[1,1.45,885.46]],"batl":[[0,1.48,139],[1,1.49,366.28],[2,1.5,194.13]],"ltp":1.48,"tv":1932.07,"id":9454286}]}]}
{"op":"mcm","clk":"4289891118","pt":1632495002037,"mc":[{"id":"1.188075669","rc":[{"batb":[[2,1.44,611.12]],"ltp":1.48,"tv":1932.07,"id":9454286}]}]}
{"op":"mcm","clk":"4289891264","pt":1632495004044,"mc":[{"id":"1.188075669","rc":[{"trd":[[3.05,11.81]],"batb":[[0,3.05,158.54]],"ltp":3.05,"tv":15922.17,"id":9631939},{"trd":[[1.48,39.63]],"batl":[[0,1.48,443.55]],"ltp":1.48,"tv":1938.97,"id":9454286}],"tv":17861.15}]}
{"op":"mcm","clk":"4289891340","pt":1632495005125,"mc":[{"id":"1.188075669","rc":[{"trd":[[3.05,25.84]],"batb":[[0,3.05,151.52]],"batl":[[1,3.2,188.87],[2,3.25,3.06]],"ltp":3.05,"tv":15936.2,"id":9631939},{"batb":[[2,1.44,668.54]],"ltp":1.48,"tv":1938.97,"id":9454286}],"tv":17875.18}]}
{"op":"mcm","clk":"4289891456","pt":1632495007124,"mc":[{"id":"1.188075669","rc":[{"trd":[[1.48,47.27]],"batl":[[0,1.48,439.73]],"ltp":1.48,"tv":1946.61,"id":9454286}],"tv":17882.82}]}
{"op":"mcm","clk":"4289891774","pt":1632495011943,"mc":[{"id":"1.188075669","rc":[{"batl":[[1,3.2,148.42]],"ltp":3.05,"tv":15936.2,"id":9631939},{"batb":[[0,1.46,357.04]],"ltp":1.48,"tv":1946.61,"id":9454286}]}]}
{"op":"mcm","clk":"4289892005","pt":1632495015169,"mc":[{"id":"1.188075669","rc":[{"batb":[[0,2.84,2.22],[1,2.8,215.76],[2,2.78,187.83]],"batl":[[0,3.25,43.06],[1,3.3,121.92],[2,3.35,150.88]],"ltp":3.05,"tv":15936.2,"id":9631939},{"batb":[[0,1.45,53.01],[1,1.44,86.03],[2,1.43,282.57]],"batl":[[0,1.54,24.75],[1,1.56,277.46],[2,1.57,314.56]],"ltp":1.48,"tv":1946.61,"id":9454286}]}]}
{"op":"mcm","clk":"4289892025","pt":1632495015378,"mc":[{"id":"1.188075669","rc":[{"batb":[[0,2.8,215.76],[1,2.78,187.83],[2,2.58,2.87]],"batl":[[0,3.25,40]],"ltp":3.05,"tv":15936.2,"id":9631939},{"batb":[[0,1.44,86.03],[1,1.43,282.57],[2,1.42,346.42]],"batl":[[0,1.56,277.46],[1,1.57,314.56],[2,1.63,17.5]],"ltp":1.48,"tv":1946.61,"id":9454286}]}]}
{"op":"mcm","clk":"4289892127","pt":1632495016744,"mc":[{"id":"1.188075669","rc":[{"batl":[[0,3.3,121.92],[1,3.35,150.88],[2,990,0.01]],"ltp":3.05,"tv":15936.2,"id":9631939},{"batb":[[0,1.44,63.42]],"batl":[[0,1.47,57.91],[1,1.56,277.46],[2,1.57,314.56]],"ltp":1.48,"tv":1946.61,"id":9454286}]}]}
{"op":"mcm","clk":"4289892230","pt":1632495018044,"mc":[{"id":"1.188075669","rc":[{"batb":[[0,2.88,31.91],[1,2.8,215.76],[2,2.78,187.83]],"ltp":3.05,"tv":15936.2,"id":9631939},{"batl":[[1,1.55,172.87],[2,1.56,437.89]],"ltp":1.48,"tv":1946.61,"id":9454286}]}]}
{"op":"mcm","clk":"4289892291","pt":1632495018969,"mc":[{"id":"1.188075669","rc":[{"batb":[[0,2.84,2.22],[1,2.8,219.76],[2,2.78,190.83]],"ltp":3.05,"tv":15936.2,"id":9631939},{"trd":[[1.47,4.69]],"batb":[[1,1.43,289.57]],"batl":[[0,1.47,55.57],[1,1.54,22.25],[2,1.55,172.87]],"ltp":1.47,"tv":1951.3,"id":9454286}],"tv":17887.51}]}
{"op":"mcm","clk":"4289892358","pt":1632495019956,"mc":[{"id":"1.188075669","rc":[{"batl":[[0,3.3,124.92]],"ltp":3.05,"tv":15936.2,"id":9631939},{"batl":[[2,1.56,283.46]],"ltp":1.47,"tv":1951.3,"id":9454286}]}]}
{"op":"mcm","clk":"4289892511","pt":1632495021948,"mc":[{"id":"1.188075669","rc":[{"batb":[[0,2.8,219.76],[1,2.78,190.83],[2,2.58,2.87]],"batl":[[0,3.25,2.78],[1,3.3,124.92],[2,3.35,150.88]],"ltp":3.05,"tv":15936.2,"id":9631939},{"trd":[[1.54,4.38]],"batb":[[0,1.45,54.81],[1,1.44,63.42],[2,1.43,289.57]],"batl":[[0,1.56,283.46],[1,1.57,314.56],[2,1.63,17.5]],"ltp":1.54,"tv":1955.68,"id":9454286}],"tv":17891.89}]}
{"op":"mcm","clk":"4289892597","pt":1632495023185,"mc":[{"id":"1.188075669","rc":[{"batb":[[0,3,20.74],[1,2.8,219.76],[2,2.78,190.83]],"batl":[[0,3.15,18.1]],"ltp":3.05,"tv":15936.2,"id":9631939},{"batb":[[0,1.46,202.23],[1,1.45,217.51],[2,1.44,63.42]],"batl":[[0,1.49,18.99],[1,1.5,268.9],[2,1.51,181.51]],"ltp":1.54,"tv":1955.68,"id":9454286}]}]}
{"op":"mcm","clk":"4289892660","pt":1632495023969,"mc":[{"id":"1.188075669","rc":[{"batb":[[0,2.8,219.76],[1,2.78,190.83],[2,2.58,2.87]],"batl":[[0,3.25,23.27]],"ltp":3.05,"tv":15936.2,"id":9631939},{"batb":[[1,1.45,261.33]],"batl":[[0,1.5,268.9],[1,1.51,181.51],[2,1.56,283.46]],"ltp":1.54,"tv":1955.68,"id":9454286}]}]}
{"op":"mcm","clk":"4289892726","pt":1632495024964,"mc":[{"id":"1.188075669","rc":[{"batl":[[2,1.53,65.78]],"ltp":1.54,"tv":1955.68,"id":9454286}]}]}
{"op":"mcm","clk":"4289892780","pt":1632495025857,"mc":[{"id":"1.188075669","rc":[{"batl":[[0,3.25,3.02]],"ltp":3.05,"tv":15936.2,"id":9631939},{"batb":[[1,1.45,322.74]],"ltp":1.54,"tv":1955.68,"id":9454286}]}]}
{"op":"mcm","clk":"4289892852","pt":1632495027197,"mc":[{"id":"1.188075669","rc":[{"batb":[[0,2.82,48.94],[1,2.8,219.76],[2,2.78,190.83]],"ltp":3.05,"tv":15936.2,"id":9631939}]}]}
{"op":"mcm","clk":"4289892908","pt":1632495028084,"mc":[{"id":"1.188075669","rc":[{"batb":[[0,2.8,219.76],[1,2.78,190.83],[2,2.58,2.87]],"batl":[[0,3.3,124.92],[1,3.35,150.88],[2,990,0.01]],"ltp":3.05,"tv":15936.2,"id":9631939},{"batb":[[0,1.44,63.42],[1,1.43,289.57],[2,1.42,346.42]],"batl":[[0,1.56,283.46],[1,1.57,314.56],[2,1.63,17.5]],"ltp":1.54,"tv":1955.68,"id":9454286}]}]}
{"op":"mcm","clk":"4289892978","pt":1632495029179,"mc":[{"id":"1.188075669","rc":[{"batl":[[0,3.2,23.27],[1,3.3,124.92],[2,3.35,150.88]],"ltp":3.05,"tv":15936.2,"id":9631939},{"batb":[[0,1.47,2.35],[1,1.44,63.42],[2,1.43,289.57]],"batl":[[0,1.49,119],[1,1.56,283.46],[2,1.57,314.56]],"ltp":1.54,"tv":1955.68,"id":9454286}]}]}
{"op":"mcm","clk":"4289893018","pt":1632495029861,"mc":[{"id":"1.188075669","rc":[{"batl":[[0,3.3,6.15],[1,990,0.01],[2,3.35,0]],"ltp":3.05,"tv":15936.2,"id":9631939},{"batb":[[2,1.43,7]],"batl":[[0,1.56,283.46],[1,1.57,314.56],[2,1.63,17.5]],"ltp":1.54,"tv":1955.68,"id":9454286}]}]}
{"op":"mcm","clk":"4289893077","pt":1632495030992,"mc":[{"id":"1.188075669","rc":[{"batb":[[0,2.8,215.76],[1,2.78,187.83]],"ltp":3.05,"tv":15936.2,"id":9631939},{"batb":[[2,1.41,328.73]],"batl":[[0,1.55,172.87],[1,1.56,437.89],[2,1.57,314.56]],"ltp":1.54,"tv":1955.68,"id":9454286}]}]}
{"op":"mcm","clk":"4289893162","pt":1632495032164,"mc":[{"id":"1.188075669","rc":[{"batb":[[1,1.45,3],[2,1.44,63.42]],"ltp":1.54,"tv":1955.68,"id":9454286}]}]}
{"op":"mcm","clk":"4289893240","pt":1632495033199,"mc":[{"id":"1.188075669","rc":[{"trd":[[2.8,19],[2.84,4.44]],"batb":[[0,2.8,206.26],[1,2.78,361.44]],"batl":[[0,2.88,7.52],[1,2.98,10.25],[2,3.05,243.09]],"ltp":2.8,"tv":15959.64,"id":9631939},{"batb":[[0,1.51,272.74],[1,1.5,188.69],[2,1.49,641.78]],"batl":[[1,1.56,450.95],[2,1.57,923.64]],"ltp":1.54,"tv":1955.68,"id":9454286}],"tv":17915.33}]}
{"op":"mcm","clk":"4289893308","pt":1632495034196,"mc":[{"id":"1.188075669","rc":[{"batl":[[2,3,42.42]],"ltp":2.8,"tv":15959.64,"id":9631939},{"batb":[[0,1.51,515.77],[1,1.5,209.9]],"ltp":1.54,"tv":1955.68,"id":9454286}]}]}
{"op":"mcm","clk":"4289893436","pt":1632495035969,"mc":[{"id":"1.188075669","rc":[{"batl":[[2,3,45.42]],"ltp":2.8,"tv":15959.64,"id":9631939},{"batb":[[1,1.5,215.9],[2,1.49,648.78]],"ltp":1.54,"tv":1955.68,"id":9454286}]}]}
{"op":"mcm","clk":"4289893568","pt":1632495037881,"mc":[{"id":"1.188075669","rc":[{"batl":[[2,3,3]],"ltp":2.8,"tv":15959.64,"id":9631939},{"batb":[[1,1.5,194.69]],"ltp":1.54,"tv":1955.68,"id":9454286}]}]}
{"op":"mcm","clk":"4289893629","pt":1632495038976,"mc":[{"id":"1.188075669","rc":[{"batl":[[0,1.54,280],[1,1.55,172.87],[2,1.56,450.95]],"ltp":1.54,"tv":1955.68,"id":9454286}]}]}
{"op":"mcm","clk":"4289893749","pt":1632495041133,"mc":[{"id":"1.188075669","rc":[{"batl":[[1,2.94,43.07],[2,2.98,10.25]],"ltp":2.8,"tv":15959.64,"id":9631939},{"batb":[[0,1.51,536.77]],"ltp":1.54,"tv":1955.68,"id":9454286}]}]}
{"op":"mcm","clk":"4289894010","pt":1632495045222,"mc":[{"id":"1.188075669","rc":[{"trd":[[2.88,21.26]],"batl":[[0,2.94,43.07],[1,2.98,10.25],[2,3,3]],"ltp":2.88,"tv":15967.16,"id":9631939},{"trd":[[1.53,21.18]],"batl":[[0,1.53,14.8],[1,1.54,280],[2,1.55,172.87]],"ltp":1.53,"tv":1969.84,"id":9454286}],"tv":17937.0}]}
{"op":"mcm","clk":"4289894059","pt":1632495046014,"mc":[{"id":"1.188075669","rc":[{"batl":[[1,1.55,172.87],[2,1.56,450.95]],"ltp":1.53,"tv":1969.84,"id":9454286}]}]}
{"op":"mcm","clk":"4289894113","pt":1632495046796,"mc":[{"id":"1.188075669","rc":[{"trd":[[1.53,50.79]],"batb":[[0,1.54,120.45],[1,1.51,536.77],[2,1.5,194.69]],"batl":[[0,1.55,172.87],[1,1.56,450.95],[2,1.57,923.64]],"ltp":1.53,"tv":1999.44,"id":9454286}],"tv":17966.61}]}
{"op":"mcm","clk":"4289894197","pt":1632495048032,"mc":[{"id":"1.188075669","rc":[{"trd":[[1.51,221.88],[1.54,245.28]],"batb":[[0,1.51,425.83],[1,1.5,194.69],[2,1.49,648.78]],"ltp":1.51,"tv":2462.22,"id":9454286}],"tv":18429.39}]}
{"op":"mcm","clk":"4289894212","pt":1632495048310,"mc":[{"id":"1.188075669","rc":[{"batb":[[2,1.49,641.78]],"ltp":1.51,"tv":2462.22,"id":9454286}]}]}
{"op":"mcm","clk":"4289894275","pt":1632495049236,"mc":[{"id":"1.188075669","rc":[{"batb":[[2,2.6,2.99]],"ltp":2.88,"tv":15967.16,"id":9631939}]}]}
{"op":"mcm","clk":"4289894431","pt":1632495051525,"mc":[{"id":"1.188075669","rc":[{"batb":[[2,1.49,648.78]],"batl":[[0,1.55,206.36]],"ltp":1.51,"tv":2462.22,"id":9454286}]}]}
{"op":"mcm","clk":"4289894650","pt":1632495055022,"mc":[{"id":"1.188075669","rc":[{"batb":[[0,2.58,2.87],[1,2.52,158.46],[2,2.5,182.01]],"batl":[[1,3.15,3.1],[2,3.2,131.92]],"ltp":2.88,"tv":15967.16,"id":9631939},{"batb":[[0,1.51,21],[1,1.47,60.02],[2,1.46,56.88]],"batl":[[0,1.63,17.5],[1,1.66,259.14],[2,1.67,268.35]],"ltp":1.51,"tv":2462.22,"id":9454286}]}]}
{"op":"mcm","clk":"4289894712","pt":1632495056163,"mc":[{"id":"1.188075669","rc":[{"batb":[[0,2.52,158.46],[1,2.5,182.01],[2,2.48,2.76]],"ltp":2.88,"tv":15967.16,"id":9631939},{"batl":[[0,1.66,259.14],[1,1.67,268.35],[2,1.98,16.27]],"ltp":1.51,"tv":2462.22,"id":9454286}]}]}
{"op":"mcm","clk":"4289894763","pt":1632495056931,"mc":[{"id":"1.188075669","rc":[{"batl":[[0,3.2,128.79],[1,3.25,150.36],[2,3.3,3.15]],"ltp":2.88,"tv":15967.16,"id":9631939},{"batb":[[0,1.54,2.19],[1,1.47,2.35],[2,1.45,585.47]],"ltp":1.51,"tv":2462.22,"id":9454286}]}]}
{"op":"mcm","clk":"4289894841","pt":1632495057955,"mc":[{"id":"1.188075669","rc":[{"batl":[[2,1.68,194.48]],"ltp":1.51,"tv":2462.22,"id":9454286}]}]}
{"op":"mcm","clk":"4289894922","pt":1632495059023,"mc":[{"id":"1.188075669","rc":[{"batb":[[0,2.52,161.46],[1,2.5,186.01]],"ltp":2.88,"tv":15967.16,"id":9631939},{"batl":[[0,1.66,263.14]],"ltp":1.51,"tv":2462.22,"id":9454286}]}]}
{"op":"mcm","clk":"4289895002","pt":1632495060154,"mc":[{"id":"1.188075669","rc":[{"batb":[[0,2.52,3],[1,2.5,4]],"batl":[[0,3.2,131.79]],"ltp":2.88,"tv":15967.16,"id":9631939},{"batb":[[0,1.47,2.35],[1,1.45,585.47],[2,1.44,696.78]],"batl":[[0,1.66,4],[1,1.67,16.5],[2,1.98,16.27]],"ltp":1.51,"tv":2462.22,"id":9454286}]}]}
{"op":"mcm","clk":"4289895222","pt":1632495063159,"mc":[{"id":"1.188075669","rc":[{"batb":[[0,3.05,319.33],[1,3,466.35],[2,2.98,304.3]],"batl":[[0,3.15,9.82],[1,3.2,128.79],[2,3.25,314.81]],"ltp":2.88,"tv":15967.16,"id":9631939},{"batl":[[0,1.48,165.74],[1,1.49,192.41],[2,1.56,1213.55]],"ltp":1.51,"tv":2462.22,"id":9454286}]}]}
{"op":"mcm","clk":"4289895289","pt":1632495064073,"mc":[{"id":"1.188075669","rc":[{"trd":[[3.05,47.74]],"batb":[[0,3.05,308.38]],"batl":[[0,3.15,6.82]],"ltp":3.05,"tv":15989.06,"id":9631939},{"batl":[[2,1.51,27.37]],"ltp":1.51,"tv":2462.22,"id":9454286}],"tv":18451.29}]}
{"op":"mcm","clk":"4289895357","pt":1632495065049,"mc":[{"id":"1.188075669","rc":[{"batl":[[2,3.25,354.81]],"ltp":3.05,"tv":15989.06,"id":9631939},{"batb":[[0,1.45,585.47],[1,1.44,719.39],[2,1.43,232.61]],"ltp":1.51,"tv":2462.22,"id":9454286}]}]}
{"op":"mcm","clk":"4289895377","pt":1632495065469,"mc":[{"id":"1.188075669","rc":[{"batb":[[1,1.44,726.39],[2,1.43,238.61]],"ltp":1.51,"tv":2462.22,"id":9454286}]}]}
{"op":"mcm","clk":"4289895629","pt":1632495069551,"mc":[{"id":"1.188075669","rc":[{"batb":[[2,1.43,549.65]],"ltp":1.51,"tv":2462.22,"id":9454286}]}]}
{"op":"mcm","clk":"4289895721","pt":1632495070756,"mc":[{"id":"1.188075669","rc":[{"trd":[[3.15,1.07]],"batl":[[0,3.15,5.75]],"ltp":3.15,"tv":15990.13,"id":9631939},{"trd":[[1.46,2.31]],"batb":[[2,1.43,580.08]],"batl":[[2,1.51,51.87]],"ltp":1.46,"tv":2464.53,"id":9454286}],"tv":18454.67}]}
{"op":"mcm","clk":"4289895849","pt":1632495073052,"mc":[{"id":"1.188075669","rc":[{"trd":[[1.48,59.55]],"batl":[[0,1.48,159.6]],"ltp":1.48,"tv":2476.81,"id":9454286}],"tv":18466.95}]}
{"op":"mcm","clk":"4289895859","pt":1632495073260,"mc":[{"id":"1.188075669","rc":[{"trd":[[1.48,67.39]],"batl":[[0,1.48,155.68]],"ltp":1.48,"tv":2484.65,"id":9454286}],"tv":18474.79}]}
{"op":"mcm","clk":"4289896044","pt":1632495076210,"mc":[{"id":"1.188075669","rc":[{"batl":[[2,1.51,24.5]],"ltp":1.48,"tv":2484.65,"id":9454286}]}]}
{"op":"mcm","clk":"4289896049","pt":1632495076264,"mc":[{"id":"1.188075669","rc":[{"trd":[[1.48,72.09]],"batl":[[0,1.48,153.33]],"ltp":1.48,"tv":2489.35,"id":9454286}],"tv":18479.49}]}
{"op":"mcm","clk":"4289896177","pt":1632495078159,"mc":[{"id":"1.188075669","rc":[{"batb":[[0,2.96,2.13],[1,2.88,2.21],[2,2.84,136.47]],"batl":[[0,3.25,40],[1,3.3,3.15],[2,3.35,131.6]],"ltp":3.15,"tv":15990.13,"id":9631939},{"batb":[[0,1.44,87.03],[1,1.43,341.47],[2,1.42,652.96]],"batl":[[0,1.51,24.5],[1,1.53,23.5],[2,1.54,331.76]],"ltp":1.48,"tv":2489.35,"id":9454286}]}]}
{"op":"mcm","clk":"4289896262","pt":1632495079194,"mc":[{"id":"1.188075669","rc":[{"batb":[[0,2.88,2.21],[1,2.84,136.47],[2,2.82,177.04]],"batl":[[0,3.3,3.15],[1,3.35,131.6],[2,3.4,162.29]],"ltp":3.15,"tv":15990.13,"id":9631939},{"batb":[[0,1.44,64.42]],"batl":[[0,1.53,23.5],[1,1.54,271.76],[2,1.55,331.54]],"ltp":1.48,"tv":2489.35,"id":9454286}]}]}
{"op":"mcm","clk":"4289896304","pt":1632495079664,"mc":[{"id":"1.188075669","rc":[{"batl":[[0,3.35,131.6],[1,3.4,162.29],[2,990,0.01]],"ltp":3.15,"tv":15990.13,"id":9631939},{"batb":[[0,1.44,7]],"batl":[[0,1.46,2.35],[1,1.47,27.37],[2,1.53,23.5]],"ltp":1.48,"tv":2489.35,"id":9454286}]}]}
{"op":"mcm","clk":"4289896504","pt":1632495081877,"mc":[{"id":"1.188075669","rc":[{"batb":[[1,1.43,348.47]],"ltp":1.48,"tv":2489.35,"id":9454286}]}]}
{"op":"mcm","clk":"4289896586","pt":1632495082974,"mc":[{"id":"1.188075669","rc":[{"batl":[[0,3.3,3],[1,3.35,134.6],[2,3.4,162.29]],"ltp":3.15,"tv":15990.13,"id":9631939}]}]}
{"op":"mcm","clk":"4289896666","pt":1632495084077,"mc":[{"id":"1.188075669","rc":[{"trd":[[3.15,2.16]],"ltp":3.15,"tv":15991.22,"id":9631939},{"trd":[[1.46,4.65],[1.47,9.07]],"batb":[[0,1.46,173.61],[1,1.45,217.5],[2,1.44,7]],"batl":[[0,1.47,25.18],[1,1.5,296.74],[2,1.51,181.51]],"ltp":1.47,"tv":2496.08,"id":9454286}],"tv":18487.3}]}
{"op":"mcm","clk":"4289896732","pt":1632495085075,"mc":[{"id":"1.188075669","rc":[{"trd":[[1.47,59.44]],"batb":[[0,1.48,26.03],[1,1.46,173.61],[2,1.45,217.5]],"batl":[[0,1.5,296.74],[1,1.51,181.51],[2,1.53,23.5]],"ltp":1.47,"tv":2546.44,"id":9454286}],"tv":18537.67}]}
{"op":"mcm","clk":"4289896820","pt":1632495086183,"mc":[{"id":"1.188075669","rc":[{"batb":[[0,2.96,2.13],[1,2.88,2.21],[2,2.84,136.47]],"batl":[[0,3.3,5.15]],"ltp":3.15,"tv":15991.22,"id":9631939},{"batb":[[1,1.44,39.67],[2,1.43,348.47]],"batl":[[0,1.51,22.01],[1,1.53,23.5],[2,1.54,271.76]],"ltp":1.47,"tv":2546.44,"id":9454286}]}]}
{"op":"mcm","clk":"4289896842","pt":1632495086482,"mc":[{"id":"1.188075669","rc":[{"batb":[[0,2.88,2.21],[1,2.84,136.47],[2,2.82,177.04]],"batl":[[0,3.3,3]],"ltp":3.15,"tv":15991.22,"id":9631939},{"batb":[[1,1.44,7]],"batl":[[0,1.53,23.5],[1,1.54,271.76],[2,1.55,331.54]],"ltp":1.47,"tv":2546.44,"id":9454286}]}]}
{"op":"mcm","clk":"4289897025","pt":1632495088997,"mc":[{"id":"1.188075669","rc":[{"batl":[[2,1.55,567.58]],"ltp":1.47,"tv":2546.44,"id":9454286}]}]}
{"op":"mcm","clk":"4289897100","pt":1632495090096,"mc":[{"id":"1.188075669","rc":[{"batb":[[1,1.44,21.92]],"ltp":1.47,"tv":2546.44,"id":9454286}]}]}
{"op":"mcm","clk":"4289897116","pt":1632495090409,"mc":[{"id":"1.188075669","rc":[{"batb":[[1,1.44,22.01]],"ltp":1.47,"tv":2546.44,"id":9454286}]}]}
{"op":"mcm","clk":"4289897327","pt":1632495093687,"mc":[{"id":"1.188075669","rc":[{"batb":[[2,1.43,341.47]],"ltp":1.47,"tv":2546.44,"id":9454286}]}]}
{"op":"mcm","clk":"4289897396","pt":1632495094819,"mc":[{"id":"1.188075669","rc":[{"batl":[[1,3.35,131.6]],"ltp":3.15,"tv":15991.22,"id":9631939},{"batb":[[0,1.52,2.19],[1,1.48,26.03],[2,1.44,22.01]],"ltp":1.47,"tv":2546.44,"id":9454286}]}]}
{"op":"mcm","clk":"4289897548","pt":1632495097125,"mc":[{"id":"1.188075669","rc":[{"batb":[[0,2.96,2.38],[1,2.88,2.21],[2,2.84,136.47]],"batl":[[0,3.3,5.05]],"ltp":3.15,"tv":15991.22,"id":9631939},{"batb":[[0,1.48,26.03],[1,1.44,51.18],[2,1.43,341.47]],"batl":[[0,1.51,23.5],[1,1.53,23.5],[2,1.54,271.76]],"ltp":1.47,"tv":2546.44,"id":9454286}]}]}
{"op":"mcm","clk":"4289897556","pt":1632495097231,"mc":[{"id":"1.188075669","rc":[{"batb":[[0,2.88,2.21],[1,2.84,136.47],[2,2.82,177.04]],"batl":[[0,3.3,3],[1,3.35,2.1],[2,990,0.01]],"ltp":3.15,"tv":15991.22,"id":9631939},{"batb":[[1,1.44,22.01],[2,1.43,30.43]],"batl":[[0,1.53,23.5],[1,1.54,271.76],[2,1.55,567.58]],"ltp":1.47,"tv":2546.44,"id":9454286}]}]}
{"op":"mcm","clk":"4289897755","pt":1632495100009,"mc":[{"id":"1.188075669","rc":[{"trd":[[2.88,35.1]],"batb":[[0,2.84,142.59],[1,2.82,177.04],[2,2.78,81.07]],"batl":[[0,2.92,6.07],[1,3,5.24],[2,3.3,3]],"ltp":2.88,"tv":16005.06,"id":9631939},{"trd":[[1.53,68.52]],"batb":[[0,1.51,146.26],[1,1.5,219.98],[2,1.48,1630.48]],"batl":[[0,1.53,5.77],[2,1.55,565.58]],"ltp":1.53,"tv":2564.17,"id":9454286}],"tv":18569.24}]}
{"op":"mcm","clk":"4289897839","pt":1632495101208,"mc":[{"id":"1.188075669","rc":[{"batl":[[2,3.05,41.9]],"ltp":2.88,"tv":16005.06,"id":9631939},{"batb":[[0,1.52,238.98],[1,1.51,146.26],[2,1.5,219.98]],"ltp":1.53,"tv":2564.17,"id":9454286}]}]}
{"op":"mcm","clk":"4289897890","pt":1632495101934,"mc":[{"id":"1.188075669","rc":[{"batl":[[2,3.1,1.71]],"ltp":2.88,"tv":16005.06,"id":9631939}]}]}
{"op":"mcm","clk":"4289898066","pt":1632495104037,"mc":[{"id":"1.188075669","rc":[{"trd":[[1.53,80.06]],"batl":[[0,1.54,271.76],[1,1.55,565.58],[2,1.56,160.3]],"ltp":1.53,"tv":2575.71,"id":9454286}],"tv":18580.78}]}
{"op":"mcm","clk":"4289898352","pt":1632495107720,"mc":[{"id":"1.188075669","rc":[{"trd":[[1.52,4.24]],"batb":[[0,1.52,236.86]],"ltp":1.52,"tv":2579.95,"id":9454286}],"tv":18585.01}]}
{"op":"mcm","clk":"4289898428","pt":1632495108516,"mc":[{"id":"1.188075669","rc":[{"batl":[[1,2.96,42.85],[2,3,5.24]],"ltp":2.88,"tv":16005.06,"id":9631939},{"batb":[[1,1.51,167.26]],"ltp":1.52,"tv":2579.95,"id":9454286}]}]}
{"op":"mcm","clk":"4289899240","pt":1632495119846,"mc":[{"id":"1.188075669","rc":[{"batb":[[0,1.53,2.35],[1,1.52,236.86],[2,1.51,167.26]],"ltp":1.52,"tv":2579.95,"id":9454286}]}]}
{"op":"mcm","clk":"4289899364","pt":1632495121569,"mc":[{"id":"1.188075669","rc":[{"trd":[[1.54,251.61]],"batl":[[0,1.54,268.6]],"ltp":1.54,"tv":2586.28,"id":9454286}],"tv":18591.34}]}
{"op":"mcm","clk":"4289899547","pt":1632495124148,"mc":[{"id":"1.188075669","rc":[{"batb":[[0,2.78,81.07],[1,2.72,3],[2,2.7,4]],"batl":[[0,2.96,42.85],[1,3,5.24],[2,3.25,137.81]],"ltp":2.88,"tv":16005.06,"id":9631939},{"batl":[[0,1.55,236.04],[1,1.56,160.3],[2,1.64,17.68]],"ltp":1.54,"tv":2586.28,"id":9454286}]}]}
{"op":"mcm","clk":"4289899624","pt":1632495125139,"mc":[{"id":"1.188075669","rc":[{"batb":[[0,2.48,141.86],[1,2.46,148.84],[2,2.44,3.42]],"batl":[[1,3.25,137.81],[2,3.3,129.47]],"ltp":2.88,"tv":16005.06,"id":9631939},{"batb":[[1,1.51,21],[2,1.48,26.03]],"batl":[[0,1.68,224.38],[1,1.69,331.86],[2,2.1,372.06]],"ltp":1.54,"tv":2586.28,"id":9454286}]}]}
{"op":"mcm","clk":"4289899712","pt":1632495126133,"mc":[{"id":"1.188075669","rc":[{"batl":[[0,3.25,137.81],[1,3.3,129.47],[2,3.35,2.1]],"ltp":2.88,"tv":16005.06,"id":9631939},{"batb":[[1,1.48,26.03],[2,1.45,288.72]],"ltp":1.54,"tv":2586.28,"id":9454286}]}]}
{"op":"mcm","clk":"4289899856","pt":1632495127963,"mc":[{"id":"1.188075669","rc":[{"batb":[[0,2.44,3.42],[1,2.42,118.18],[2,1.12,2.53]],"batl":[[1,3.3,127.22],[2,3.45,2.1]],"ltp":2.88,"tv":16005.06,"id":9631939},{"batb":[[0,1.54,2.35],[1,1.53,2.35],[2,1.48,26.03]],"batl":[[0,1.69,19.5],[1,2.1,372.06],[2,990,0.01]],"ltp":1.54,"tv":2586.28,"id":9454286}]}]}
{"op":"mcm","clk":"4289899912","pt":1632495128783,"mc":[{"id":"1.188075669","rc":[{"batb":[[0,2.48,3],[1,2.46,3],[2,2.44,3.42]],"ltp":2.88,"tv":16005.06,"id":9631939},{"batl":[[0,1.68,2],[1,1.69,19.5],[2,2.1,372.06]],"ltp":1.54,"tv":2586.28,"id":9454286}]}]}
{"op":"mcm","clk":"4289899984","pt":1632495130190,"mc":[{"id":"1.188075669","rc":[{"batb":[[0,3.05,770.48],[1,3,465.11],[2,2.98,385.24]],"ltp":2.88,"tv":16005.06,"id":9631939},{"trd":[[1.48,124.15],[1.53,84.75],[1.54,256.31]],"batb":[[0,1.46,13.6],[1,1.45,288.72],[2,1.44,1036.42]],"batl":[[0,1.48,4378.1],[1,1.5,159.75],[2,1.66,18.07]],"ltp":1.48,"tv":2647.73,"id":9454286}],"tv":18652.8}]}
{"op":"mcm","clk":"4289900066","pt":1632495131182,"mc":[{"id":"1.188075669","rc":[{"trd":[[3.1,10.71]],"batb":[[0,3.05,311.51],[1,3,156.91],[2,2.98,77.04]],"batl":[[1,3.3,124.22]],"ltp":3.1,"tv":16015.77,"id":9631939},{"trd":[[1.47,82.03],[1.48,128.85]],"batb":[[1,1.44,1079.58],[2,1.43,1945.99]],"batl":[[0,1.47,229.09],[1,1.48,207.46],[2,1.5,159.75]],"ltp":1.47,"tv":2675.02,"id":9454286}],"tv":18690.79}]}
{"op":"mcm","clk":"4289900140","pt":1632495132179,"mc":[{"id":"1.188075669","rc":[{"batl":[[1,3.3,163.78],[2,3.4,1.71]],"ltp":3.1,"tv":16015.77,"id":9631939},{"batb":[[2,1.43,631.31]],"ltp":1.47,"tv":2675.02,"id":9454286}]}]}
{"op":"mcm","clk":"4289900184","pt":1632495132756,"mc":[{"id":"1.188075669","rc":[{"batl":[[1,3.3,124.22]],"ltp":3.1,"tv":16015.77,"id":9631939}]}]}
{"op":"mcm","clk":"4289900248","pt":1632495133799,"mc":[{"id":"1.188075669","rc":[{"batb":[[1,3,160.91],[2,2.98,80.04]],"ltp":3.1,"tv":16015.77,"id":9631939},{"batb":[[2,1.43,635.75]],"ltp":1.47,"tv":2675.02,"id":9454286}]}]}
{"op":"mcm","clk":"4289900408","pt":1632495135983,"mc":[{"id":"1.188075669","rc":[{"batb":[[0,3.05,335.09]],"batl":[[1,3.3,163.78]],"ltp":3.1,"tv":16015.77,"id":9631939}]}]}
{"op":"mcm","clk":"4289900470","pt":1632495136874,"mc":[{"id":"1.188075669","rc":[{"batb":[[2,1.43,645.4]],"ltp":1.47,"tv":2675.02,"id":9454286}]}]}
{"op":"mcm","clk":"4289900551","pt":1632495138079,"mc":[{"id":"1.188075669","rc":[{"trd":[[1.46,115.19]],"batb":[[0,1.44,1079.58],[1,1.43,645.4],[2,1.42,402.2]],"batl":[[0,1.46,87.3],[1,1.47,229.09],[2,1.48,207.46]],"ltp":1.46,"tv":2785.56,"id":9454286}],"tv":18801.33}]}
{"op":"mcm","clk":"4289900716","pt":1632495140180,"mc":[{"id":"1.188075669","rc":[{"trd":[[1.46,158.15]],"batl":[[0,1.46,65.82]],"ltp":1.46,"tv":2828.51,"id":9454286}],"tv":18844.29}]}
{"op":"mcm","clk":"4289900842","pt":1632495142113,"mc":[{"id":"1.188075669","rc":[{"batl":[[2,3.45,2.1]],"ltp":3.1,"tv":16015.77,"id":9631939},{"trd":[[1.46,164.15]],"batl":[[0,1.46,62.82]],"ltp":1.46,"tv":2834.52,"id":9454286}],"tv":18850.29}]}
{"op":"mcm","clk":"4289900857","pt":1632495142320,"mc":[{"id":"1.188075669","rc":[{"trd":[[1.46,192.3]],"batl":[[0,1.46,48.74]],"ltp":1.46,"tv":2862.66,"id":9454286}],"tv":18878.44}]}
{"op":"mcm","clk":"4289901017","pt":1632495144913,"mc":[{"id":"1.188075669","rc":[{"trd":[[3.15,2.25]],"ltp":3.15,"tv":16015.86,"id":9631939},{"trd":[[1.46,192.49]],"batl":[[0,1.46,48.55]],"ltp":1.46,"tv":2862.86,"id":9454286}],"tv":18878.73}]}
{"op":"mcm","clk":"4289901087","pt":1632495145904,"mc":[{"id":"1.188075669","rc":[{"batb":[[2,2.98,77.04]],"ltp":3.15,"tv":16015.86,"id":9631939},{"trd":[[1.44,3.82],[1.45,0.18],[1.46,289.59],[1.47,166.15]],"batb":[[0,1.44,1077.57]],"batl":[[0,1.47,187.03],[1,1.48,207.46],[2,1.5,159.75]],"ltp":1.47,"tv":3048.08,"id":9454286}],"tv":19063.95}]}
{"op":"mcm","clk":"4289901109","pt":1632495146268,"mc":[{"id":"1.188075669","rc":[{"batb":[[0,1.46,25],[1,1.44,1077.57],[2,1.43,645.4]],"ltp":1.47,"tv":3048.08,"id":9454286}]}]}
{"op":"mcm","clk":"4289901249","pt":1632495148214,"mc":[{"id":"1.188075669","rc":[{"trd":[[1.47,170.84]],"batl":[[0,1.47,184.68]],"ltp":1.47,"tv":3052.78,"id":9454286}],"tv":19068.64}]}
{"op":"mcm","clk":"4289901309","pt":1632495149107,"mc":[{"id":"1.188075669","rc":[{"batb":[[2,2.98,80.04]],"ltp":3.15,"tv":16015.86,"id":9631939},{"batb":[[0,1.46,26.57],[2,1.43,684.08]],"batl":[[0,1.47,213.6],[1,1.48,197.17]],"ltp":1.47,"tv":3052.78,"id":9454286}]}]}
{"op":"mcm","clk":"4289901468","pt":1632495151824,"mc":[{"id":"1.188075669","rc":[{"batl":[[0,3.15,72.54],[1,3.25,137.81],[2,3.3,163.78]],"ltp":3.15,"tv":16015.86,"id":9631939},{"batb":[[1,1.45,12.65],[2,1.44,1077.57]],"batl":[[0,1.47,225.71]],"ltp":1.47,"tv":3052.78,"id":9454286}]}]}
{"op":"mcm","clk":"4289901575","pt":1632495153741,"mc":[{"id":"1.188075669","rc":[{"batl":[[0,3.15,74.89]],"ltp":3.15,"tv":16015.86,"id":9631939}]}]}
{"op":"mcm","clk":"4289901683","pt":1632495155124,"mc":[{"id":"1.188075669","rc":[{"trd":[[1.47,210.84]],"batl":[[0,1.47,205.71]],"ltp":1.47,"tv":3092.78,"id":9454286}],"tv":19108.64}]}
{"op":"mcm","clk":"4289901895","pt":1632495159049,"mc":[{"id":"1.188075669","rc":[{"batl":[[0,3.15,2.35]],"ltp":3.15,"tv":16015.86,"id":9631939},{"trd":[[1.47,211.16]],"batl":[[0,1.47,205.55]],"ltp":1.47,"tv":3093.09,"id":9454286}],"tv":19108.96}]}
{"op":"mcm","clk":"4289902113","pt":1632495162131,"mc":[{"id":"1.188075669","rc":[{"trd":[[3.1,83.25]],"batb":[[2,2.98,77.04]],"ltp":3.1,"tv":16088.4,"id":9631939},{"trd":[[1.47,364.14]],"batl":[[0,1.47,12.11]],"ltp":1.47,"tv":3246.07,"id":9454286}],"tv":19334.48}]}
{"op":"mcm","clk":"4289902189","pt":1632495163221,"mc":[{"id":"1.188075669","rc":[{"trd":[[3.15,4.6]],"batl":[[0,3.25,137.81],[1,3.3,163.78],[2,3.45,2.1]],"ltp":3.15,"tv":16090.75,"id":9631939},{"trd":[[1.46,349.5]],"batb":[[0,1.45,12.65],[1,1.44,1077.57],[2,1.43,591.45]],"batl":[[0,1.46,9.73],[1,1.47,12.11],[2,1.48,197.17]],"ltp":1.46,"tv":3305.98,"id":9454286}],"tv":19396.73}]}
{"op":"mcm","clk":"4289902204","pt":1632495163436,"mc":[{"id":"1.188075669","rc":[{"batb":[[1,3,156.91]],"ltp":3.15,"tv":16090.75,"id":9631939}]}]}
{"op":"mcm","clk":"4289902305","pt":1632495165067,"mc":[{"id":"1.188075669","rc":[{"batb":[[2,2.98,79.04]],"ltp":3.15,"tv":16090.75,"id":9631939},{"batb":[[1,1.44,1268.65]],"batl":[[2,1.48,315.36]],"ltp":1.46,"tv":3305.98,"id":9454286}]}]}
{"op":"mcm","clk":"4289902326","pt":1632495165319,"mc":[{"id":"1.188075669","rc":[{"batl":[[0,1.46,4.57]],"ltp":1.46,"tv":3305.98,"id":9454286}]}]}
{"op":"mcm","clk":"4289902989","pt":1632495177669,"mc":[{"id":"1.188075669","rc":[{"batb":[[2,2.98,77.04]],"ltp":3.15,"tv":16090.75,"id":9631939},{"batb":[[0,1.46,13.76],[1,1.45,12.65],[2,1.44,1268.65]],"batl":[[0,1.47,12.11],[1,1.48,315.36],[2,1.49,190.45]],"ltp":1.46,"tv":3305.98,"id":9454286}]}]}
{"op":"mcm","clk":"4289903060","pt":1632495178933,"mc":[{"id":"1.188075669","rc":[{"batb":[[0,1.46,14.93]],"ltp":1.46,"tv":3305.98,"id":9454286}]}]}
{"op":"mcm","clk":"4289903141","pt":1632495180137,"mc":[{"id":"1.188075669","rc":[{"trd":[[3.15,31.97]],"ltp":3.15,"tv":16118.12,"id":9631939},{"trd":[[1.46,438.42]],"batb":[[0,1.45,12.65],[1,1.44,1268.65],[2,1.43,591.45]],"batl":[[0,1.46,435.01],[1,1.47,12.11],[2,1.48,315.36]],"ltp":1.46,"tv":3394.9,"id":9454286}],"tv":19513.03}]}
{"op":"mcm","clk":"4289903438","pt":1632495184072,"mc":[{"id":"1.188075669","rc":[{"batl":[[0,1.46,686]],"ltp":1.46,"tv":3394.9,"id":9454286}]}]}
{"op":"mcm","clk":"4289903585","pt":1632495186070,"mc":[{"id":"1.188075669","rc":[{"batb":[[0,1.45,13]],"ltp":1.46,"tv":3394.9,"id":9454286}]}]}
{"op":"mcm","clk":"4289903729","pt":1632495188267,"mc":[{"id":"1.188075669","rc":[{"trd":[[3.15,32.2]],"ltp":3.15,"tv":16118.35,"id":9631939},{"trd":[[1.46,438.93]],"batl":[[0,1.46,685.49]],"ltp":1.46,"tv":3395.41,"id":9454286}],"tv":19513.77}]}
{"op":"mcm","clk":"4289903833","pt":1632495189988,"mc":[{"id":"1.188075669","rc":[{"trd":[[1.46,453.85]],"batl":[[0,1.46,678.03]],"ltp":1.46,"tv":3410.33,"id":9454286}],"tv":19528.69}]}
{"op":"mcm","clk":"4289903910","pt":1632495190983,"mc":[{"id":"1.188075669","rc":[{"trd":[[1.45,26.18]],"batb":[[0,1.44,1268.65],[1,1.43,591.45],[2,1.42,164.34]],"batl":[[0,1.45,10.74],[1,1.46,678.03],[2,1.47,12.11]],"ltp":1.45,"tv":3436.32,"id":9454286}],"tv":19554.68}]}
{"op":"mcm","clk":"4289903951","pt":1632495191498,"mc":[{"id":"1.188075669","rc":[{"trd":[[3.15,37.78],[3.2,3.8]],"ltp":3.15,"tv":16127.74,"id":9631939},{"trd":[[1.45,39.26],[1.46,465.88]],"batl":[[0,1.46,666],[1,1.47,12.11],[2,1.48,315.36]],"ltp":1.46,"tv":3461.44,"id":9454286}],"tv":19589.18}]}
{"op":"mcm","clk":"4289904064","pt":1632495193172,"mc":[{"id":"1.188075669","rc":[{"trd":[[1.46,470.57]],"batl":[[0,1.46,663.65]],"ltp":1.46,"tv":3466.13,"id":9454286}],"tv":19593.87}]}
{"op":"mcm","clk":"4289904072","pt":1632495193280,"mc":[{"id":"1.188075669","rc":[{"trd":[[1.46,477.47]],"batl":[[0,1.46,660.2]],"ltp":1.46,"tv":3473.03,"id":9454286}],"tv":19600.77}]}
{"op":"mcm","clk":"4289904230","pt":1632495195707,"mc":[{"id":"1.188075669","rc":[{"trd":[[1.46,477.66]],"batl":[[0,1.46,660.11]],"ltp":1.46,"tv":3473.22,"id":9454286}],"tv":19600.96}]}
{"op":"mcm","clk":"4289904407","pt":1632495198321,"mc":[{"id":"1.188075669","rc":[{"trd":[[1.44,8.87]],"batb":[[0,1.44,1266.13]],"ltp":1.44,"tv":3478.26,"id":9454286}],"tv":19606.0}]}
{"op":"mcm","clk":"4289904604","pt":1632495201103,"mc":[{"id":"1.188075669","rc":[{"batl":[[1,1.48,315.36],[2,1.49,190.45]],"ltp":1.44,"tv":3478.26,"id":9454286}]}]}
{"op":"mcm","clk":"4289904826","pt":1632495204092,"mc":[{"id":"1.188075669","rc":[{"batb":[[0,1.44,1279.26]],"batl":[[0,1.46,672.67]],"ltp":1.44,"tv":3478.26,"id":9454286}]}]}
{"op":"mcm","clk":"4289904880","pt":1632495204823,"mc":[{"id":"1.188075669","rc":[{"trd":[[1.46,507.66]],"batb":[[0,1.44,1266.13]],"batl":[[0,1.46,645.11]],"ltp":1.46,"tv":3508.26,"id":9454286}],"tv":19636.0}]}
{"op":"mcm","clk":"4289905022","pt":1632495207277,"mc":[{"id":"1.188075669","rc":[{"batb":[[0,1.44,1279.26]],"batl":[[0,1.46,657.67]],"ltp":1.46,"tv":3508.26,"id":9454286}]}]}
{"op":"mcm","clk":"4289905209","pt":1632495210594,"mc":[{"id":"1.188075669","rc":[{"trd":[[3.15,38.64]],"ltp":3.15,"tv":16128.59,"id":9631939},{"trd":[[1.46,509.51]],"batl":[[0,1.46,655.82]],"ltp":1.46,"tv":3510.11,"id":9454286}],"tv":19638.71}]}
{"op":"mcm","clk":"4289905479","pt":1632495214812,"mc":[{"id":"1.188075669","rc":[{"trd":[[1.46,511.19]],"batl":[[0,1.46,654.98]],"ltp":1.46,"tv":3511.8,"id":9454286}],"tv":19640.39}]}
{"op":"mcm","clk":"4289905541","pt":1632495215806,"mc":[{"id":"1.188075669","rc":[{"trd":[[3.15,39.42]],"ltp":3.15,"tv":16129.37,"id":9631939},{"trd":[[1.46,512.87]],"batl":[[0,1.46,653.3]],"ltp":1.46,"tv":3513.48,"id":9454286}],"tv":19642.85}]}
{"op":"mcm","clk":"4289906253","pt":1632495227133,"mc":[{"id":"1.188075669","rc":[{"batb":[[1,1.43,581.8]],"ltp":1.46,"tv":3513.48,"id":9454286}]}]}
{"op":"mcm","clk":"4289906336","pt":1632495228131,"mc":[{"id":"1.188075669","rc":[{"batb":[[0,3.05,311.51]],"ltp":3.15,"tv":16129.37,"id":9631939}]}]}
{"op":"mcm","clk":"4289906504","pt":1632495230120,"mc":[{"id":"1.188075669","rc":[{"trd":[[1.46,514.67]],"batl":[[0,1.46,652.4]],"ltp":1.46,"tv":3515.28,"id":9454286}],"tv":19644.65}]}
{"op":"mcm","clk":"4289906849","pt":1632495234312,"mc":[{"id":"1.188075669","rc":[{"trd":[[1.46,521.71]],"batl":[[0,1.46,648.88]],"ltp":1.46,"tv":3522.31,"id":9454286}],"tv":19651.69}]}
{"op":"mcm","clk":"4289907142","pt":1632495238056,"mc":[{"id":"1.188075669","rc":[{"trd":[[3.15,92.37]],"ltp":3.15,"tv":16182.32,"id":9631939},{"trd":[[1.46,635.95]],"batl":[[0,1.46,534.64]],"ltp":1.46,"tv":3636.55,"id":9454286}],"tv":19818.88}]}
{"op":"mcm","clk":"4289907371","pt":1632495241154,"mc":[{"id":"1.188075669","rc":[{"batl":[[0,3.25,153.77]],"ltp":3.15,"tv":16182.32,"id":9631939},{"batb":[[0,1.44,1322.1]],"ltp":1.46,"tv":3636.55,"id":9454286}]}]}
{"op":"mcm","clk":"4289907395","pt":1632495241468,"mc":[{"id":"1.188075669","rc":[{"trd":[[1.46,668.71]],"batl":[[0,1.46,518.26]],"ltp":1.46,"tv":3669.31,"id":9454286}],"tv":19851.64}]}
{"op":"mcm","clk":"4289907621","pt":1632495244870,"mc":[{"id":"1.188075669","rc":[{"trd":[[1.46,701.99]],"batl":[[0,1.46,501.62]],"ltp":1.46,"tv":3702.59,"id":9454286}],"tv":19884.92}]}
{"op":"mcm","clk":"4289907803","pt":1632495247963,"mc":[{"id":"1.188075669","rc":[{"batl":[[0,1.46,12.56]],"ltp":1.46,"tv":3702.59,"id":9454286}]}]}
{"op":"mcm","clk":"4289907872","pt":1632495248969,"mc":[{"id":"1.188075669","rc":[{"trd":[[1.46,706.68]],"batl":[[0,1.46,10.21]],"ltp":1.46,"tv":3707.29,"id":9454286}],"tv":19889.62}]}
{"op":"mcm","clk":"4289908073","pt":1632495251939,"mc":[{"id":"1.188075669","rc":[{"trd":[[1.46,711.38]],"batl":[[0,1.46,7.86]],"ltp":1.46,"tv":3711.98,"id":9454286}],"tv":19894.31}]}
{"op":"mcm","clk":"4289908205","pt":1632495254176,"mc":[{"id":"1.188075669","rc":[{"trd":[[1.46,716.07]],"batl":[[0,1.46,5.51]],"ltp":1.46,"tv":3716.68,"id":9454286}],"tv":19899.01}]}
{"op":"mcm","clk":"4289908267","pt":1632495255172,"mc":[{"id":"1.188075669","rc":[{"trd":[[3.15,94.92]],"batl":[[0,3.15,27.45],[1,3.25,153.77],[2,3.3,163.78]],"ltp":3.15,"tv":16184.87,"id":9631939},{"trd":[[1.46,721.58]],"batl":[[0,1.48,315.36],[1,1.49,190.45],[2,1.5,159.75]],"ltp":1.46,"tv":3722.19,"id":9454286}],"tv":19907.07}]}
{"op":"mcm","clk":"4289908413","pt":1632495257168,"mc":[{"id":"1.188075669","rc":[{"batb":[[0,3.05,157.41],[1,2.94,3],[2,2.92,155.11]],"ltp":3.15,"tv":16184.87,"id":9631939},{"batb":[[0,1.44,938.37],[1,1.43,253.12],[2,1.41,51.54]],"batl":[[2,1.52,280.34]],"ltp":1.46,"tv":3722.19,"id":9454286}]}]}
{"op":"mcm","clk":"4289908458","pt":1632495257694,"mc":[{"id":"1.188075669","rc":[{"batb":[[0,2.94,3],[1,2.92,158.11],[2,2.9,276.77]],"batl":[[1,3.3,39.56],[2,3.6,101.38]],"ltp":3.15,"tv":16184.87,"id":9631939},{"batb":[[0,1.44,10.48],[1,1.43,22.87],[2,1.41,9.65]],"batl":[[0,1.52,280.34],[1,1.53,270.54],[2,1.68,2]],"ltp":1.46,"tv":3722.19,"id":9454286}]}]}
{"op":"mcm","clk":"4289908506","pt":1632495258310,"mc":[{"id":"1.188075669","rc":[{"batb":[[2,2.9,245.2]],"batl":[[1,3.6,101.38],[2,3.65,159.92]],"ltp":3.15,"tv":16184.87,"id":9631939},{"batb":[[1,1.41,9.65],[2,1.39,307.86]],"batl":[[0,1.52,220.34]],"ltp":1.46,"tv":3722.19,"id":9454286}]}]}
{"op":"mcm","clk":"4289908701","pt":1632495260983,"mc":[{"id":"1.188075669","rc":[{"batl":[[0,1.51,7],[1,1.52,374.1],[2,1.53,443.09]],"ltp":1.46,"tv":3722.19,"id":9454286}]}]}
{"op":"mcm","clk":"4289908772","pt":1632495262074,"mc":[{"id":"1.188075669","rc":[{"batl":[[0,3.15,29.99]],"ltp":3.15,"tv":16184.87,"id":9631939}]}]}
{"op":"mcm","clk":"4289908804","pt":1632495262653,"mc":[{"id":"1.188075669","rc":[{"batl":[[1,4.3,68.9],[2,990,0.01]],"ltp":3.15,"tv":16184.87,"id":9631939},{"batb":[[2,1.37,366.04]],"ltp":1.46,"tv":3722.19,"id":9454286}]}]}
{"op":"mcm","clk":"4289908867","pt":1632495263692,"mc":[{"id":"1.188075669","rc":[{"batb":[[0,2.96,3],[1,2.94,3],[2,2.92,158.11]],"ltp":3.15,"tv":16184.87,"id":9631939}]}]}
{"op":"mcm","clk":"4289909044","pt":1632495266075,"mc":[{"id":"1.188075669","rc":[{"trd":[[2.92,22.38]],"batb":[[0,2.92,143.92],[1,2.9,245.2],[2,2.86,334.36]],"batl":[[0,3.1,7.45],[1,3.15,29.8],[2,3.2,298.82]],"ltp":2.92,"tv":16207.25,"id":9631939},{"batb":[[0,1.48,989.24],[1,1.47,205.18],[2,1.44,10.48]],"batl":[[0,1.52,367.1],[1,1.53,443.09],[2,1.54,301.58]],"ltp":1.46,"tv":3722.19,"id":9454286}],"tv":19929.45}]}
{"op":"mcm","clk":"4289909130","pt":1632495267179,"mc":[{"id":"1.188075669","rc":[{"batl":[[0,3.1,32.03],[1,3.15,70.71]],"ltp":2.92,"tv":16207.25,"id":9631939},{"batb":[[0,1.49,260.57],[1,1.48,989.24],[2,1.47,227.05]],"ltp":1.46,"tv":3722.19,"id":9454286}]}]}
{"op":"mcm","clk":"4289909209","pt":1632495268181,"mc":[{"id":"1.188075669","rc":[{"batl":[[0,3.1,10.45]],"ltp":2.92,"tv":16207.25,"id":9631939},{"batb":[[2,1.47,234.05]],"ltp":1.46,"tv":3722.19,"id":9454286}]}]}
{"op":"mcm","clk":"4289909327","pt":1632495270081,"mc":[{"id":"1.188075669","rc":[{"batl":[[0,1.51,233],[1,1.52,367.1],[2,1.53,443.09]],"ltp":1.46,"tv":3722.19,"id":9454286}]}]}
{"op":"mcm","clk":"4289909377","pt":1632495270759,"mc":[{"id":"1.188075669","rc":[{"batl":[[0,3.05,24.58],[1,3.1,10.45],[2,3.15,29.8]],"ltp":2.92,"tv":16207.25,"id":9631939},{"batb":[[2,1.47,212.18]],"ltp":1.46,"tv":3722.19,"id":9454286}]}]}
{"op":"mcm","clk":"4289909477","pt":1632495271985,"mc":[{"id":"1.188075669","rc":[{"batb":[[0,2.96,6.13],[1,2.92,143.92],[2,2.9,245.2]],"batl":[[0,3.05,30.87]],"ltp":2.92,"tv":16207.25,"id":9631939}]}]}
{"op":"mcm","clk":"4289909522","pt":1632495272680,"mc":[{"id":"1.188075669","rc":[{"trd":[[2.96,0.4]],"batb":[[0,2.96,5.93]],"ltp":2.96,"tv":16207.65,"id":9631939}],"tv":19929.84}]}
{"op":"mcm","clk":"4289909630","pt":1632495273983,"mc":[{"id":"1.188075669","rc":[{"batl":[[1,3.1,51.85]],"ltp":2.96,"tv":16207.65,"id":9631939},{"trd":[[1.51,255.54]],"batb":[[1,1.48,1010.89]],"batl":[[0,1.51,341.17],[2,1.53,468.59]],"ltp":1.51,"tv":3755.85,"id":9454286}],"tv":19963.5}]}
{"op":"mcm","clk":"4289909790","pt":1632495276913,"mc":[{"id":"1.188075669","rc":[{"trd":[[1.51,288.5]],"batl":[[0,1.51,324.69]],"ltp":1.51,"tv":3788.81,"id":9454286}],"tv":19996.46}]}
{"op":"mcm","clk":"4289909851","pt":1632495277975,"mc":[{"id":"1.188075669","rc":[{"trd":[[1.49,0.62]],"batb":[[0,1.49,260.26],[1,1.48,742.39]],"ltp":1.49,"tv":3789.43,"id":9454286}],"tv":19997.08}]}
{"op":"mcm","clk":"4289909934","pt":1632495279169,"mc":[{"id":"1.188075669","rc":[{"batb":[[0,2.9,72.97],[1,2.88,2.21],[2,2.84,2.47]],"batl":[[0,3.1,48.85],[1,3.15,29.8],[2,3.3,2.05]],"ltp":2.96,"tv":16207.65,"id":9631939},{"batb":[[1,1.48,68.41],[2,1.44,57.9]],"batl":[[1,1.53,25.5],[2,1.54,23.25]],"ltp":1.49,"tv":3789.43,"id":9454286}]}]}
{"op":"mcm","clk":"4289910003","pt":1632495280106,"mc":[{"id":"1.188075669","rc":[{"batb":[[0,2.88,2.21],[1,2.84,2.47],[2,2.76,83.09]],"batl":[[0,3.1,41.4]],"ltp":2.96,"tv":16207.65,"id":9631939},{"trd":[[1.51,294.9]],"batb":[[0,1.48,21.65],[1,1.44,57.9],[2,1.43,310.85]],"batl":[[0,1.53,25.5],[1,1.54,23.25],[2,1.68,2]],"ltp":1.51,"tv":3795.83,"id":9454286}],"tv":20003.48}]}
{"op":"mcm","clk":"4289910024","pt":1632495280369,"mc":[{"id":"1.188075669","rc":[{"batb":[[0,2.84,2.47],[1,2.76,83.09],[2,1.12,2.53]],"batl":[[0,3.15,29.8],[1,3.3,2.05],[2,3.4,2.19]],"ltp":2.96,"tv":16207.65,"id":9631939},{"batb":[[0,1.44,57.9],[1,1.43,310.85],[2,1.42,43.94]],"batl":[[0,1.54,23.25],[1,1.68,2],[2,1.89,445.56]],"ltp":1.51,"tv":3795.83,"id":9454286}]}]}
{"op":"mcm","clk":"4289910148","pt":1632495282218,"mc":[{"id":"1.188075669","rc":[{"batl":[[0,3.15,2.35],[1,3.4,2.19],[2,4.3,68.9]],"ltp":2.96,"tv":16207.65,"id":9631939},{"batb":[[0,1.44,10.48],[2,1.42,330.99]],"batl":[[1,1.57,273.98],[2,1.58,152.12]],"ltp":1.51,"tv":3795.83,"id":9454286}]}]}
{"op":"mcm","clk":"4289910234","pt":1632495283201,"mc":[{"id":"1.188075669","rc":[{"batb":[[2,1.42,43.94]],"batl":[[1,1.68,2],[2,1.89,445.56]],"ltp":1.51,"tv":3795.83,"id":9454286}]}]}
{"op":"mcm","clk":"4289910290","pt":1632495284016,"mc":[{"id":"1.188075669","rc":[{"batb":[[0,2.88,2.21],[1,2.84,2.47],[2,2.76,83.09]],"batl":[[0,3.4,2.19],[1,4.3,68.9],[2,990,0.01]],"ltp":2.96,"tv":16207.65,"id":9631939},{"batl":[[0,1.53,22.5],[1,1.54,23.25],[2,1.68,2]],"ltp":1.51,"tv":3795.83,"id":9454286}]}]}
{"op":"mcm","clk":"4289910367","pt":1632495285019,"mc":[{"id":"1.188075669","rc":[{"batb":[[0,2.84,2.47],[1,2.76,83.09],[2,1.12,2.53]],"batl":[[0,2.96,27.45],[1,3.4,2.19],[2,4.3,68.9]],"ltp":2.96,"tv":16207.65,"id":9631939},{"batl":[[0,1.54,23.25],[1,1.68,2],[2,990,0.01]],"ltp":1.51,"tv":3795.83,"id":9454286}]}]}
{"op":"mcm","clk":"4289910458","pt":1632495286220,"mc":[{"id":"1.188075669","rc":[{"trd":[[2.96,27.85]],"batb":[[0,3,20],[1,2.84,2.47],[2,2.76,83.09]],"batl":[[0,3.1,19.85],[1,3.3,2.15],[2,3.4,2.19]],"ltp":2.96,"tv":16235.1,"id":9631939},{"trd":[[1.51,348.71]],"batb":[[0,1.47,237.31],[1,1.46,210.83],[2,1.44,54.9]],"batl":[[0,1.5,19.59],[1,1.51,158.52],[2,1.52,176.62]],"ltp":1.51,"tv":3849.64,"id":9454286}],"tv":20084.74}]}
{"op":"mcm","clk":"4289910530","pt":1632495287206,"mc":[{"id":"1.188075669","rc":[{"batb":[[0,2.84,2.47],[1,2.76,83.09],[2,1.12,2.53]],"batl":[[0,3.3,5.15],[1,3.4,2.19],[2,4.3,68.9]],"ltp":2.96,"tv":16235.1,"id":9631939},{"batb":[[2,1.44,61.9]],"batl":[[0,1.51,158.52],[1,1.52,176.62],[2,1.54,23.25]],"ltp":1.51,"tv":3849.64,"id":9454286}]}]}
{"op":"mcm","clk":"4289910584","pt":1632495288101,"mc":[{"id":"1.188075669","rc":[{"batb":[[0,2.88,2.21],[1,2.84,2.47],[2,2.76,83.09]],"ltp":2.96,"tv":16235.1,"id":9631939},{"batl":[[2,1.53,57.01]],"ltp":1.51,"tv":3849.64,"id":9454286}]}]}
{"op":"mcm","clk":"4289910713","pt":1632495290099,"mc":[{"id":"1.188075669","rc":[{"batb":[[0,1.47,267.89],[1,1.46,369.82]],"batl":[[0,1.51,182.6]],"ltp":1.51,"tv":3849.64,"id":9454286}]}]}
{"op":"mcm","clk":"4289910791","pt":1632495291221,"mc":[{"id":"1.188075669","rc":[{"batb":[[0,2.88,14.56]],"ltp":2.96,"tv":16235.1,"id":9631939},{"trd":[[1.51,366.75]],"batb":[[0,1.47,320.29]],"batl":[[0,1.51,173.58]],"ltp":1.51,"tv":3867.68,"id":9454286}],"tv":20102.78}]}
{"op":"mcm","clk":"4289910859","pt":1632495291994,"mc":[{"id":"1.188075669","rc":[{"batl":[[0,3.25,25.75],[1,3.3,5.15],[2,3.4,2.19]],"ltp":2.96,"tv":16235.1,"id":9631939},{"batl":[[0,1.5,149],[1,1.51,173.58],[2,1.52,176.62]],"ltp":1.51,"tv":3867.68,"id":9454286}]}]}
{"op":"mcm","clk":"4289910920","pt":1632495293111,"mc":[{"id":"1.188075669","rc":[{"batb":[[0,2.88,2.21]],"batl":[[0,3.3,5.15],[1,3.4,2.19],[2,4.3,68.9]],"ltp":2.96,"tv":16235.1,"id":9631939},{"batb":[[0,1.46,158.99],[1,1.44,61.9],[2,1.43,316.85]],"batl":[[0,1.53,21.5],[1,1.54,23.25],[2,1.68,2]],"ltp":1.51,"tv":3867.68,"id":9454286}]}]}
{"op":"mcm","clk":"4289910934","pt":1632495293426,"mc":[{"id":"1.188075669","rc":[{"batb":[[0,2.84,2.47],[1,2.76,83.09],[2,1.12,2.53]],"ltp":2.96,"tv":16235.1,"id":9631939},{"batl":[[0,1.54,23.25],[1,1.68,2],[2,990,0.01]],"ltp":1.51,"tv":3867.68,"id":9454286}]}]}
{"op":"mcm","clk":"4289911021","pt":1632495295199,"mc":[{"id":"1.188075669","rc":[{"batl":[[0,1.54,23.56]],"ltp":1.51,"tv":3867.68,"id":9454286}]}]}
{"op":"mcm","clk":"4289911039","pt":1632495295619,"mc":[{"id":"1.188075669","rc":[{"batl":[[1,1.57,240.58],[2,1.58,152.1]],"ltp":1.51,"tv":3867.68,"id":9454286}]}]}
{"op":"mcm","clk":"4289911266","pt":1632495299112,"mc":[{"id":"1.188075669","rc":[{"trd":[[2.84,18.45]],"batb":[[0,2.84,6.24],[2,2.66,91.02]],"batl":[[0,2.92,6.05],[1,2.98,320.9],[2,3,311.46]],"ltp":2.84,"tv":16249.11,"id":9631939},{"trd":[[1.52,4.86],[1.54,273.04]],"batb":[[0,1.53,233.83],[1,1.52,550.59],[2,1.51,224.55]],"batl":[[0,1.54,6.52],[2,1.58,533.64]],"ltp":1.54,"tv":3885.03,"id":9454286}],"tv":20134.14}]}
{"op":"mcm","clk":"4289911438","pt":1632495301132,"mc":[{"id":"1.188075669","rc":[{"batl":[[1,2.96,2.35],[2,2.98,320.9]],"ltp":2.84,"tv":16249.11,"id":9631939},{"trd":[[1.54,281.66]],"batb":[[2,1.51,226.9]],"batl":[[0,1.57,240.58],[1,1.58,533.64],[2,1.59,601.42]],"ltp":1.54,"tv":3893.65,"id":9454286}],"tv":20142.76}]}
{"op":"mcm","clk":"4289911482","pt":1632495301722,"mc":[{"id":"1.188075669","rc":[{"trd":[[2.84,30.93]],"batb":[[0,2.76,83.09],[1,2.66,91.02],[2,2.64,4]],"ltp":2.84,"tv":16261.59,"id":9631939}],"tv":20155.24}]}
{"op":"mcm","clk":"4289911562","pt":1632495302899,"mc":[{"id":"1.188075669","rc":[{"batl":[[0,2.9,25.75],[1,2.92,6.05],[2,2.96,2.35]],"ltp":2.84,"tv":16261.59,"id":9631939}]}]}
{"op":"mcm","clk":"4289911655","pt":1632495304118,"mc":[{"id":"1.188075669","rc":[{"batb":[[0,1.53,234.07]],"ltp":1.54,"tv":3893.65,"id":9454286}]}]}
{"op":"mcm","clk":"4289911740","pt":1632495305009,"mc":[{"id":"1.188075669","rc":[{"batl":[[0,1.56,154],[1,1.57,240.58],[2,1.58,533.64]],"ltp":1.54,"tv":3893.65,"id":9454286}]}]}
{"op":"mcm","clk":"4289911806","pt":1632495306119,"mc":[{"id":"1.188075669","rc":[{"batb":[[0,2.78,2.66],[1,2.76,83.09],[2,2.74,2.29]],"ltp":2.84,"tv":16261.59,"id":9631939},{"batl":[[0,1.56,175.67],[1,1.57,262.08],[2,1.58,551.89]],"ltp":1.54,"tv":3893.65,"id":9454286}]}]}
{"op":"mcm","clk":"4289911849","pt":1632495306913,"mc":[{"id":"1.188075669","rc":[{"batb":[[1,1.52,633.79]],"ltp":1.54,"tv":3893.65,"id":9454286}]}]}
{"op":"mcm","clk":"4289911920","pt":1632495308011,"mc":[{"id":"1.188075669","rc":[{"batl":[[1,2.92,49.35]],"ltp":2.84,"tv":16261.59,"id":9631939},{"batl":[[0,1.56,325.67]],"ltp":1.54,"tv":3893.65,"id":9454286}]}]}
{"op":"mcm","clk":"4289911994","pt":1632495309164,"mc":[{"id":"1.188075669","rc":[{"batb":[[0,1.55,2.35],[1,1.53,234.07],[2,1.52,633.79]],"ltp":1.54,"tv":3893.65,"id":9454286}]}]}
{"op":"mcm","clk":"4289912014","pt":1632495309426,"mc":[{"id":"1.188075669","rc":[{"batl":[[0,2.84,3.52],[1,2.9,25.75],[2,2.92,49.35]],"ltp":2.84,"tv":16261.59,"id":9631939}]}]}
{"op":"mcm","clk":"4289912165","pt":1632495311159,"mc":[{"id":"1.188075669","rc":[{"batb":[[0,2.74,2.29],[1,2.72,2.59],[2,2.66,91.02]],"batl":[[1,2.92,43.3],[2,2.96,2.35]],"ltp":2.84,"tv":16261.59,"id":9631939},{"trd":[[1.55,0.62]],"batb":[[0,1.55,2.04],[1,1.52,83.43],[2,1.51,2.35]],"batl":[[0,1.56,304],[1,1.57,21.5],[2,1.58,18.25]],"ltp":1.55,"tv":3894.27,"id":9454286}],"tv":20155.86}]}
{"op":"mcm","clk":"4289912256","pt":1632495312150,"mc":[{"id":"1.188075669","rc":[{"batb":[[0,1.56,17.25],[1,1.55,2.04],[2,1.52,83.43]],"batl":[[0,1.57,21.5],[1,1.58,18.25],[2,1.68,2]],"ltp":1.55,"tv":3894.27,"id":9454286}]}]}
{"op":"mcm","clk":"4289912287","pt":1632495312569,"mc":[{"id":"1.188075669","rc":[{"batl":[[1,2.96,2.35],[2,3,4.32]],"ltp":2.84,"tv":16261.59,"id":9631939},{"batb":[[2,1.51,2.58]],"ltp":1.55,"tv":3894.27,"id":9454286}]}]}
{"op":"mcm","clk":"4289912398","pt":1632495314136,"mc":[{"id":"1.188075669","rc":[{"batb":[[0,2.78,2.66],[1,2.74,2.29],[2,2.72,2.59]],"batl":[[0,2.96,2.35],[1,3,4.32],[2,3.15,5.7]],"ltp":2.84,"tv":16261.59,"id":9631939},{"trd":[[1.56,46.92]],"batb":[[0,1.56,23.79]],"ltp":1.56,"tv":3941.19,"id":9454286}],"tv":20202.78}]}
{"op":"mcm","clk":"4289912431","pt":1632495314555,"mc":[{"id":"1.188075669","rc":[{"batb":[[0,2.74,2.29],[1,2.72,2.59],[2,2.66,91.02]],"ltp":2.84,"tv":16261.59,"id":9631939}]}]}
{"op":"mcm","clk":"4289912556","pt":1632495316069,"mc":[{"id":"1.188075669","rc":[{"batb":[[0,2.74,5.29],[1,2.72,5.59]],"ltp":2.84,"tv":16261.59,"id":9631939},{"batb":[[0,1.56,27.32]],"batl":[[1,1.58,692.21]],"ltp":1.56,"tv":3941.19,"id":9454286}]}]}
{"op":"mcm","clk":"4289912627","pt":1632495316749,"mc":[{"id":"1.188075669","rc":[{"trd":[[1.54,282.12],[1.55,4.7],[1.56,101.56]],"batb":[[0,1.51,297.16],[1,1.5,190.91],[2,1.48,268.5]],"batl":[[0,1.56,221.81],[1,1.57,177.19],[2,1.58,18.25]],"ltp":1.54,"tv":4000.37,"id":9454286}],"tv":20261.96}]}
{"op":"mcm","clk":"4289912750","pt":1632495318033,"mc":[{"id":"1.188075669","rc":[{"batb":[[0,2.74,16.74]],"batl":[[0,2.94,11.75],[1,2.96,2.35]],"ltp":2.84,"tv":16261.59,"id":9631939},{"batl":[[0,1.56,221.9]],"ltp":1.54,"tv":4000.37,"id":9454286}]}]}
{"op":"mcm","clk":"4289912829","pt":1632495319078,"mc":[{"id":"1.188075669","rc":[{"trd":[[1.54,282.31],[1.56,119.42]],"batl":[[0,1.56,212.88]],"ltp":1.56,"tv":4018.42,"id":9454286}],"tv":20280.01}]}
{"op":"mcm","clk":"4289912897","pt":1632495320174,"mc":[{"id":"1.188075669","rc":[{"batb":[[0,2.74,5.29]],"batl":[[0,2.96,2.35],[1,3.15,5.7],[2,3.3,2.15]],"ltp":2.84,"tv":16261.59,"id":9631939},{"batb":[[0,1.51,2.35],[1,1.5,2.35]],"batl":[[0,1.57,21.5],[1,1.58,18.25],[2,1.68,2]],"ltp":1.56,"tv":4018.42,"id":9454286}]}]}
{"op":"mcm","clk":"4289912960","pt":1632495321158,"mc":[{"id":"1.188075669","rc":[{"batb":[[0,2.78,2.66],[1,2.74,5.29],[2,2.72,5.59]],"ltp":2.84,"tv":16261.59,"id":9631939},{"trd":[[1.57,493.34]],"batl":[[0,1.57,21.27]],"ltp":1.57,"tv":4018.88,"id":9454286}],"tv":20280.47}]}
{"op":"mcm","clk":"4289912976","pt":1632495321476,"mc":[{"id":"1.188075669","rc":[{"batb":[[0,2.74,5.29],[1,2.72,5.59],[2,2.66,91.02]],"ltp":2.84,"tv":16261.59,"id":9631939}]}]}
{"op":"mcm","clk":"4289913076","pt":1632495322783,"mc":[{"id":"1.188075669","rc":[{"batb":[[2,1.48,444.04]],"batl":[[0,1.57,21.58],[2,1.6,193.47]],"ltp":1.57,"tv":4018.88,"id":9454286}]}]}
{"op":"mcm","clk":"4289913131","pt":1632495323673,"mc":[{"id":"1.188075669","rc":[{"batl":[[0,1.54,3.27],[1,1.57,21.58],[2,1.58,18.25]],"ltp":1.57,"tv":4018.88,"id":9454286}]}]}
{"op":"mcm","clk":"4289913236","pt":1632495325094,"mc":[{"id":"1.188075669","rc":[{"batb":[[2,1.48,268.5]],"ltp":1.57,"tv":4018.88,"id":9454286}]}]}
{"op":"mcm","clk":"4289913375","pt":1632495327190,"mc":[{"id":"1.188075669","rc":[{"batb":[[0,2.74,2.29],[1,2.72,2.59]],"ltp":2.84,"tv":16261.59,"id":9631939}]}]}
{"op":"mcm","clk":"4289913441","pt":1632495328181,"mc":[{"id":"1.188075669","rc":[{"trd":[[2.74,14.1]],"batb":[[0,2.72,2.59],[1,2.66,91.02],[2,1.12,2.53]],"batl":[[0,2.84,12.66],[1,2.86,334.36],[2,2.88,534.97]],"ltp":2.74,"tv":16275.69,"id":9631939},{"trd":[[1.54,288.85],[1.57,509.95]],"batb":[[0,1.55,2533.35],[1,1.54,213.04],[2,1.52,67.99]],"batl":[[0,1.57,4.97],[1,1.58,29.63],[2,1.6,505.17]],"ltp":1.57,"tv":4042.04,"id":9454286}],"tv":20317.73}]}
{"op":"mcm","clk":"4289913511","pt":1632495329178,"mc":[{"id":"1.188075669","rc":[{"batb":[[2,2.6,97.43]],"batl":[[0,2.82,44.47],[1,2.84,12.66],[2,2.86,334.36]],"ltp":2.74,"tv":16275.69,"id":9631939},{"batb":[[0,1.56,216.88],[1,1.55,457.9],[2,1.54,209.81]],"ltp":1.57,"tv":4042.04,"id":9454286}]}]}
{"op":"mcm","clk":"4289913576","pt":1632495330066,"mc":[{"id":"1.188075669","rc":[{"batb":[[2,1.54,213.81]],"ltp":1.57,"tv":4042.04,"id":9454286}]}]}
{"op":"mcm","clk":"4289913642","pt":1632495330980,"mc":[{"id":"1.188075669","rc":[{"batl":[[0,2.82,47.47]],"ltp":2.74,"tv":16275.69,"id":9631939}]}]}
{"op":"mcm","clk":"4289913709","pt":1632495331981,"mc":[{"id":"1.188075669","rc":[{"trd":[[1.56,434.7]],"batb":[[0,1.56,59.24]],"ltp":1.56,"tv":4357.32,"id":9454286}],"tv":20633.01}]}
{"op":"mcm","clk":"4289913795","pt":1632495333176,"mc":[{"id":"1.188075669","rc":[{"batl":[[0,2.8,19.88],[1,2.82,47.47],[2,2.84,12.66]],"ltp":2.74,"tv":16275.69,"id":9631939},{"trd":[[1.57,513.37]],"batl":[[0,1.57,3.26]],"ltp":1.57,"tv":4360.74,"id":9454286}],"tv":20636.43}]}
{"op":"mcm","clk":"4289913850","pt":1632495334073,"mc":[{"id":"1.188075669","rc":[{"batl":[[0,1.57,233.26]],"ltp":1.57,"tv":4360.74,"id":9454286}]}]}
{"op":"mcm","clk":"4289913906","pt":1632495334966,"mc":[{"id":"1.188075669","rc":[{"batb":[[2,2.6,250.59]],"batl":[[2,2.84,147.66]],"ltp":2.74,"tv":16275.69,"id":9631939},{"batb":[[2,1.54,493.18]],"ltp":1.57,"tv":4360.74,"id":9454286}]}]}
{"op":"mcm","clk":"4289914069","pt":1632495337111,"mc":[{"id":"1.188075669","rc":[{"trd":[[1.57,517.37]],"batb":[[1,1.55,538.8]],"batl":[[0,1.57,449.26]],"ltp":1.57,"tv":4364.74,"id":9454286}],"tv":20640.43}]}
{"op":"mcm","clk":"4289914273","pt":1632495339877,"mc":[{"id":"1.188075669","rc":[{"batb":[[1,1.55,359.6]],"ltp":1.57,"tv":4364.74,"id":9454286}]}]}
{"op":"mcm","clk":"4289914455","pt":1632495342182,"mc":[{"id":"1.188075669","rc":[{"batl":[[0,2.84,135],[1,2.86,146.89],[2,2.96,2.35]],"ltp":2.74,"tv":16275.69,"id":9631939},{"batb":[[1,1.54,279.37],[2,1.53,299.45]],"batl":[[1,1.58,18.25],[2,1.62,286.65]],"ltp":1.57,"tv":4364.74,"id":9454286}]}]}
{"op":"mcm","clk":"4289914524","pt":1632495343175,"mc":[{"id":"1.188075669","rc":[{"batb":[[1,2.6,250.59],[2,2.58,202.02]],"ltp":2.74,"tv":16275.69,"id":9631939},{"batb":[[0,1.54,279.37],[1,1.53,299.45],[2,1.52,244.98]],"batl":[[0,1.57,1.26]],"ltp":1.57,"tv":4364.74,"id":9454286}]}]}
{"op":"mcm","clk":"4289914616","pt":1632495344220,"mc":[{"id":"1.188075669","rc":[{"trd":[[2.74,14.16]],"ltp":2.74,"tv":16275.74,"id":9631939},{"trd":[[1.57,517.47]],"batl":[[0,1.58,18.46],[1,1.62,286.65],[2,1.63,280.8]],"ltp":1.57,"tv":4364.84,"id":9454286}],"tv":20640.58}]}
{"op":"mcm","clk":"4289914676","pt":1632495345217,"mc":[{"id":"1.188075669","rc":[{"batb":[[0,2.74,2.52],[1,2.72,2.59],[2,2.62,95.49]],"batl":[[0,2.84,139.27]],"ltp":2.74,"tv":16275.74,"id":9631939},{"batb":[[2,1.52,497.74]],"batl":[[1,1.62,467.82],[2,1.63,416.8]],"ltp":1.57,"tv":4364.84,"id":9454286}]}]}
{"op":"mcm","clk":"4289914729","pt":1632495346009,"mc":[{"id":"1.188075669","rc":[{"batb":[[0,2.72,2.59],[1,2.62,95.49],[2,2.6,153.16]],"ltp":2.74,"tv":16275.74,"id":9631939},{"batb":[[2,1.52,6]],"batl":[[1,1.62,286.65],[2,1.63,280.8]],"ltp":1.57,"tv":4364.84,"id":9454286}]}]}
{"op":"mcm","clk":"4289914905","pt":1632495348210,"mc":[{"id":"1.188075669","rc":[{"batl":[[1,1.61,656.59],[2,1.62,286.65]],"ltp":1.57,"tv":4364.84,"id":9454286}]}]}
{"op":"mcm","clk":"4289914968","pt":1632495348996,"mc":[{"id":"1.188075669","rc":[{"batb":[[0,1.55,172.17],[1,1.54,448.4],[2,1.53,299.45]],"batl":[[1,1.59,149.72],[2,1.6,145.51]],"ltp":1.57,"tv":4364.84,"id":9454286}]}]}
{"op":"mcm","clk":"4289915046","pt":1632495350193,"mc":[{"id":"1.188075669","rc":[{"batl":[[0,2.82,19.42],[1,2.84,139.27],[2,2.86,146.89]],"ltp":2.74,"tv":16275.74,"id":9631939},{"batb":[[0,1.55,206.87]],"batl":[[0,1.57,24.71],[1,1.58,18.25],[2,1.59,149.72]],"ltp":1.57,"tv":4364.84,"id":9454286}]}]}
{"op":"mcm","clk":"4289915054","pt":1632495350298,"mc":[{"id":"1.188075669","rc":[{"batl":[[0,1.58,18.46],[1,1.59,149.72],[2,1.6,145.51]],"ltp":1.57,"tv":4364.84,"id":9454286}]}]}
{"op":"mcm","clk":"4289915161","pt":1632495351912,"mc":[{"id":"1.188075669","rc":[{"batb":[[0,2.74,2.52],[1,2.72,2.59],[2,2.62,95.49]],"ltp":2.74,"tv":16275.74,"id":9631939},{"batl":[[0,1.57,166.21],[1,1.58,18.25],[2,1.59,149.72]],"ltp":1.57,"tv":4364.84,"id":9454286}]}]}
{"op":"mcm","clk":"4289915285","pt":1632495353539,"mc":[{"id":"1.188075669","rc":[{"batl":[[0,1.57,186.71]],"ltp":1.57,"tv":4364.84,"id":9454286}]}]}
{"op":"mcm","clk":"4289915428","pt":1632495355139,"mc":[{"id":"1.188075669","rc":[{"batl":[[0,2.84,135],[1,2.86,146.89],[2,2.96,2.35]],"ltp":2.74,"tv":16275.74,"id":9631939},{"batb":[[0,1.55,2.35],[1,1.54,279.37]],"batl":[[0,1.57,109.71],[2,1.62,286.65]],"ltp":1.57,"tv":4364.84,"id":9454286}]}]}
{"op":"mcm","clk":"4289915447","pt":1632495355348,"mc":[{"id":"1.188075669","rc":[{"batb":[[0,2.72,2.59],[1,2.62,95.49],[2,2.6,153.16]],"ltp":2.74,"tv":16275.74,"id":9631939},{"batl":[[0,1.58,18.46],[1,1.62,286.65],[2,1.63,280.8]],"ltp":1.57,"tv":4364.84,"id":9454286}]}]}
{"op":"mcm","clk":"4289915637","pt":1632495358028,"mc":[{"id":"1.188075669","rc":[{"trd":[[2.72,13.96],[2.74,14.28]],"batb":[[0,2.62,95.85],[1,2.6,153.16],[2,2.58,202.02]],"batl":[[0,2.96,2.35],[1,2.98,4.75],[2,4.3,68.9]],"ltp":2.72,"tv":16280.32,"id":9631939},{"trd":[[1.57,517.68]],"batb":[[1,1.52,6],[2,1.51,314.02]],"batl":[[0,1.58,18.25],[1,1.62,467.82],[2,1.63,416.8]],"ltp":1.57,"tv":4365.05,"id":9454286}],"tv":20645.37}]}
{"op":"mcm","clk":"4289915772","pt":1632495360137,"mc":[{"id":"1.188075669","rc":[{"trd":[[2.66,7.72],[2.72,25.28]],"batb":[[0,2.62,95.49]],"batl":[[0,2.78,10.97],[1,2.8,1366.08],[2,2.82,1325.9]],"ltp":2.66,"tv":16292.68,"id":9631939},{"trd":[[1.58,34.6],[1.6,55.13]],"batb":[[0,1.57,2746.44],[1,1.55,2.35],[2,1.52,6]],"batl":[[0,1.6,13.24],[1,1.62,839.4]],"ltp":1.6,"tv":4385.03,"id":9454286}],"tv":20677.71}]}
{"op":"mcm","clk":"4289915841","pt":1632495361133,"mc":[{"id":"1.188075669","rc":[{"batl":[[1,2.8,341.52],[2,2.82,331.48]],"ltp":2.66,"tv":16292.68,"id":9631939},{"batb":[[0,1.57,477.01],[1,1.56,200.92],[2,1.55,2.35]],"ltp":1.6,"tv":4385.03,"id":9454286}]}]}
{"op":"mcm","clk":"4289915927","pt":1632495362039,"mc":[{"id":"1.188075669","rc":[{"batb":[[0,1.58,208.27],[1,1.57,482.01],[2,1.56,217.67]],"ltp":1.6,"tv":4385.03,"id":9454286}]}]}
{"op":"mcm","clk":"4289915987","pt":1632495362622,"mc":[{"id":"1.188075669","rc":[{"trd":[[1.58,53.91]],"batb":[[0,1.58,198.62]],"ltp":1.58,"tv":4404.33,"id":9454286}],"tv":20697.01}]}
{"op":"mcm","clk":"4289916044","pt":1632495363355,"mc":[{"id":"1.188075669","rc":[{"batl":[[0,2.76,3],[1,2.78,10.97],[2,2.8,341.52]],"ltp":2.66,"tv":16292.68,"id":9631939}]}]}
{"op":"mcm","clk":"4289916299","pt":1632495367061,"mc":[{"id":"1.188075669","rc":[{"batb":[[0,2.62,95.32]],"ltp":2.66,"tv":16292.68,"id":9631939},{"batl":[[0,1.6,176.24]],"ltp":1.58,"tv":4404.33,"id":9454286}]}]}
{"op":"mcm","clk":"4289916435","pt":1632495368942,"mc":[{"id":"1.188075669","rc":[{"trd":[[2.66,17.72]],"batl":[[0,2.74,24.26],[1,2.76,3],[2,2.78,10.97]],"ltp":2.66,"tv":16302.68,"id":9631939},{"trd":[[1.6,71.76]],"batl":[[0,1.6,159.61]],"ltp":1.6,"tv":4420.96,"id":9454286}],"tv":20723.64}]}
{"op":"mcm","clk":"4289916561","pt":1632495371076,"mc":[{"id":"1.188075669","rc":[{"batl":[[2,2.8,341.52]],"ltp":2.66,"tv":16302.68,"id":9631939},{"batl":[[0,1.6,254.61]],"ltp":1.6,"tv":4420.96,"id":9454286}]}]}
{"op":"mcm","clk":"4289916623","pt":1632495372170,"mc":[{"id":"1.188075669","rc":[{"trd":[[1.6,119.6]],"batb":[[1,1.57,264.04]],"batl":[[0,1.6,230.69]],"ltp":1.6,"tv":4468.8,"id":9454286}],"tv":20771.48}]}
{"op":"mcm","clk":"4289916643","pt":1632495372480,"mc":[{"id":"1.188075669","rc":[{"batl":[[0,1.6,231]],"ltp":1.6,"tv":4468.8,"id":9454286}]}]}
{"op":"mcm","clk":"4289916734","pt":1632495373684,"mc":[{"id":"1.188075669","rc":[{"batl":[[0,2.72,9.54],[1,2.74,24.26],[2,2.76,3]],"ltp":2.66,"tv":16302.68,"id":9631939},{"batb":[[2,1.56,212.67]],"batl":[[1,1.62,855.94]],"ltp":1.6,"tv":4468.8,"id":9454286}]}]}
{"op":"mcm","clk":"4289916830","pt":1632495375145,"mc":[{"id":"1.188075669","rc":[{"trd":[[1.58,71.27]],"batb":[[0,1.58,189.94]],"batl":[[0,1.6,350.31]],"ltp":1.58,"tv":4486.17,"id":9454286}],"tv":20788.85}]}
{"op":"mcm","clk":"4289916924","pt":1632495376870,"mc":[{"id":"1.188075669","rc":[{"trd":[[2.66,22]],"ltp":2.66,"tv":16306.95,"id":9631939},{"trd":[[1.59,0.62],[1.6,135.11]],"batl":[[0,1.6,338.69]],"ltp":1.6,"tv":4502.3,"id":9454286}],"tv":20809.26}]}
{"op":"mcm","clk":"4289917060","pt":1632495378967,"mc":[{"id":"1.188075669","rc":[{"batl":[[0,2.74,24.26],[1,2.76,3],[2,2.8,341.52]],"ltp":2.66,"tv":16306.95,"id":9631939},{"trd":[[1.58,71.74]],"batb":[[0,1.58,189.7]],"batl":[[1,1.62,839.4]],"ltp":1.58,"tv":4502.77,"id":9454286}],"tv":20809.73}]}
{"op":"mcm","clk":"4289917296","pt":1632495382092,"mc":[{"id":"1.188075669","rc":[{"batl":[[0,2.72,9.54],[1,2.74,24.26],[2,2.76,3]],"ltp":2.66,"tv":16306.95,"id":9631939},{"batl":[[0,1.59,13.16],[1,1.6,338.69],[2,1.62,855.94]],"ltp":1.58,"tv":4502.77,"id":9454286}]}]}
{"op":"mcm","clk":"4289917515","pt":1632495385583,"mc":[{"id":"1.188075669","rc":[{"trd":[[2.66,50.71],[2.68,7.81]],"ltp":2.66,"tv":16343.47,"id":9631939},{"trd":[[1.59,13.78],[1.6,182.84]],"batl":[[0,1.6,290.96],[1,1.62,855.94],[2,1.63,416.8]],"ltp":1.6,"tv":4563.66,"id":9454286}],"tv":20907.14}]}
{"op":"mcm","clk":"4289917963","pt":1632495392496,"mc":[{"id":"1.188075669","rc":[{"batb":[[0,1.59,2.35],[1,1.58,189.7],[2,1.57,264.04]],"ltp":1.6,"tv":4563.66,"id":9454286}]}]}
{"op":"mcm","clk":"4289918225","pt":1632495396598,"mc":[{"id":"1.188075669","rc":[{"batb":[[0,1.58,189.7],[1,1.57,264.04],[2,1.56,212.67]],"ltp":1.6,"tv":4563.66,"id":9454286}]}]}
{"op":"mcm","clk":"4289918277","pt":1632495397520,"mc":[{"id":"1.188075669","rc":[{"batb":[[1,1.57,5],[2,1.56,11.75]],"batl":[[1,1.62,674.77],[2,1.63,280.8]],"ltp":1.6,"tv":4563.66,"id":9454286}]}]}
{"op":"mcm","clk":"4289918795","pt":1632495405536,"mc":[{"id":"1.188075669","rc":[{"trd":[[1.6,184.24]],"batl":[[0,1.6,290.26]],"ltp":1.6,"tv":4565.06,"id":9454286}],"tv":20908.54}]}
{"op":"mcm","clk":"4289918852","pt":1632495406628,"mc":[{"id":"1.188075669","rc":[{"trd":[[1.6,188.94]],"batl":[[0,1.6,287.91]],"ltp":1.6,"tv":4569.76,"id":9454286}],"tv":20913.23}]}
{"op":"mcm","clk":"4289919027","pt":1632495408939,"mc":[{"id":"1.188075669","rc":[{"batb":[[0,2.54,38.96],[1,2.42,164.64],[2,2.4,178.59]],"batl":[[0,2.84,44.23],[1,2.86,114.09],[2,2.88,136.81]],"ltp":2.66,"tv":16343.47,"id":9631939},{"batb":[[0,1.55,2.35],[1,1.54,298.78],[2,1.53,528.25]],"batl":[[1,1.65,60],[2,1.68,2]],"ltp":1.6,"tv":4569.76,"id":9454286}]}]}
{"op":"mcm","clk":"4289919125","pt":1632495410139,"mc":[{"id":"1.188075669","rc":[{"batl":[[0,1.65,60],[1,1.68,2],[2,1.71,226.36]],"ltp":1.6,"tv":4569.76,"id":9454286}]}]}
{"op":"mcm","clk":"4289919191","pt":1632495411131,"mc":[{"id":"1.188075669","rc":[{"batb":[[0,2.42,164.64],[1,2.4,178.59],[2,2.38,121.56]],"batl":[[0,2.86,114.09],[1,2.88,136.81],[2,2.98,4.75]],"ltp":2.66,"tv":16343.47,"id":9631939},{"batb":[[1,1.54,217.14]],"batl":[[0,1.68,2],[1,1.71,226.36],[2,1.72,217.72]],"ltp":1.6,"tv":4569.76,"id":9454286}]}]}
{"op":"mcm","clk":"4289919259","pt":1632495411926,"mc":[{"id":"1.188075669","rc":[{"batb":[[1,2.4,181.45]],"batl":[[2,2.94,5.25]],"ltp":2.66,"tv":16343.47,"id":9631939},{"batl":[[1,1.71,243.86]],"ltp":1.6,"tv":4569.76,"id":9454286}]}]}
{"op":"mcm","clk":"4289919422","pt":1632495414029,"mc":[{"id":"1.188075669","rc":[{"batb":[[0,2.42,168.64],[1,2.4,184.45]],"ltp":2.66,"tv":16343.47,"id":9631939},{"batb":[[0,1.59,222.66],[1,1.58,153.37],[2,1.55,2.35]],"batl":[[0,1.64,186.98],[1,1.65,130.17],[2,1.68,2]],"ltp":1.6,"tv":4569.76,"id":9454286}]}]}
{"op":"mcm","clk":"4289919494","pt":1632495415124,"mc":[{"id":"1.188075669","rc":[{"batb":[[0,2.46,6.88],[1,2.44,4],[2,2.42,168.64]],"ltp":2.66,"tv":16343.47,"id":9631939},{"batl":[[2,1.68,20.14]],"ltp":1.6,"tv":4569.76,"id":9454286}]}]}
{"op":"mcm","clk":"4289919537","pt":1632495415751,"mc":[{"id":"1.188075669","rc":[{"batl":[[0,2.84,50.69],[1,2.86,114.09],[2,2.88,136.81]],"ltp":2.66,"tv":16343.47,"id":9631939},{"batl":[[2,1.67,10]],"ltp":1.6,"tv":4569.76,"id":9454286}]}]}
{"op":"mcm","clk":"4289919758","pt":1632495419148,"mc":[{"id":"1.188075669","rc":[{"batb":[[0,2.46,4]],"batl":[[0,2.86,114.09],[1,2.88,136.81],[2,2.94,5.25]],"ltp":2.66,"tv":16343.47,"id":9631939},{"batb":[[0,1.59,40.33],[1,1.54,217.14],[2,1.53,528.25]],"batl":[[0,1.68,2],[1,1.71,243.86],[2,1.72,217.72]],"ltp":1.6,"tv":4569.76,"id":9454286}]}]}
{"op":"mcm","clk":"4289919764","pt":1632495419248,"mc":[{"id":"1.188075669","rc":[{"batb":[[0,1.54,217.14],[1,1.53,528.25],[2,1.52,85.49]],"ltp":1.6,"tv":4569.76,"id":9454286}]}]}
{"op":"mcm","clk":"4289919917","pt":1632495422155,"mc":[{"id":"1.188075669","rc":[{"batb":[[2,2.42,4]],"ltp":2.66,"tv":16343.47,"id":9631939},{"batb":[[2,1.52,369.8]],"batl":[[1,1.71,17.5],[2,990,0.01]],"ltp":1.6,"tv":4569.76,"id":9454286}]}]}
{"op":"mcm","clk":"4289920109","pt":1632495425158,"mc":[{"id":"1.188075669","rc":[{"batb":[[0,2.78,4.97],[1,2.76,170.28],[2,2.74,85.14]],"batl":[[0,2.94,5.25],[1,3,106.71],[2,3.05,4.9]],"ltp":2.66,"tv":16343.47,"id":9631939},{"batb":[[0,1.54,12.1],[1,1.53,234.42]],"batl":[[0,1.57,239.78],[1,1.58,629.37],[2,1.67,37.13]],"ltp":1.6,"tv":4569.76,"id":9454286}]}]}
{"op":"mcm","clk":"4289920176","pt":1632495426173,"mc":[{"id":"1.188075669","rc":[{"trd":[[2.76,12.96],[2.78,9.94]],"batb":[[0,2.76,246.55],[1,2.74,85.14],[2,2.72,85.14]],"batl":[[1,2.98,157.72],[2,3,185.57]],"ltp":2.76,"tv":16366.37,"id":9631939},{"batl":[[2,1.59,60]],"ltp":1.6,"tv":4569.76,"id":9454286}],"tv":20936.13}]}
{"op":"mcm","clk":"4289920382","pt":1632495429059,"mc":[{"id":"1.188075669","rc":[{"batl":[[0,2.92,23.94],[1,2.94,5.25],[2,2.98,157.72]],"ltp":2.76,"tv":16366.37,"id":9631939},{"batl":[[0,1.56,226],[1,1.57,239.78],[2,1.58,629.37]],"ltp":1.6,"tv":4569.76,"id":9454286}]}]}
{"op":"mcm","clk":"4289920840","pt":1632495436080,"mc":[{"id":"1.188075669","rc":[{"batb":[[0,1.53,234.42],[1,1.52,369.8],[2,1.51,224.4]],"ltp":1.6,"tv":4569.76,"id":9454286}]}]}
{"op":"mcm","clk":"4289920980","pt":1632495438174,"mc":[{"id":"1.188075669","rc":[{"batb":[[0,2.76,82.75],[1,2.7,35.29],[2,2.66,2.34]],"batl":[[2,3,5.14]],"ltp":2.76,"tv":16366.37,"id":9631939},{"batl":[[0,1.55,1.71],[1,1.56,226],[2,1.57,239.78]],"ltp":1.6,"tv":4569.76,"id":9454286}]}]}
{"op":"mcm","clk":"4289921056","pt":1632495439167,"mc":[{"id":"1.188075669","rc":[{"batb":[[0,2.7,35.29],[1,2.66,2.34],[2,2.62,2.54]],"batl":[[0,3.05,46.8],[1,3.1,5.15],[2,4.3,68.9]],"ltp":2.76,"tv":16366.37,"id":9631939},{"batb":[[0,1.49,432.23],[1,1.48,87.26],[2,1.46,158.99]],"batl":[[1,1.59,60],[2,1.6,18.11]],"ltp":1.6,"tv":4569.76,"id":9454286}]}]}
{"op":"mcm","clk":"4289921139","pt":1632495440269,"mc":[{"id":"1.188075669","rc":[{"batb":[[0,2.66,2.34],[1,2.62,2.54],[2,2.6,2.54]],"batl":[[0,3.05,4.9]],"ltp":2.76,"tv":16366.37,"id":9631939},{"batb":[[0,1.49,346.52]],"batl":[[1,1.6,18.11],[2,1.61,20.5]],"ltp":1.6,"tv":4569.76,"id":9454286}]}]}
{"op":"mcm","clk":"4289921277","pt":1632495442106,"mc":[{"id":"1.188075669","rc":[{"batl":[[0,3,4.96],[1,3.05,7.9],[2,3.1,5.15]],"ltp":2.76,"tv":16366.37,"id":9631939},{"batb":[[0,1.5,84.88],[1,1.49,495.44],[2,1.48,291.34]],"ltp":1.6,"tv":4569.76,"id":9454286}]}]}
{"op":"mcm","clk":"4289921286","pt":1632495442281,"mc":[{"id":"1.188075669","rc":[{"batl":[[0,3.05,7.9],[1,3.1,5.15],[2,4.3,68.9]],"ltp":2.76,"tv":16366.37,"id":9631939},{"batb":[[0,1.49,495.44],[1,1.48,291.34],[2,1.46,158.99]],"ltp":1.6,"tv":4569.76,"id":9454286}]}]}
{"op":"mcm","clk":"4289921424","pt":1632495444305,"mc":[{"id":"1.188075669","rc":[{"batb":[[0,1.49,351.52],[1,1.48,93.26]],"ltp":1.6,"tv":4569.76,"id":9454286}]}]}
{"op":"mcm","clk":"4289921634","pt":1632495447209,"mc":[{"id":"1.188075669","rc":[{"trd":[[2.6,12.52],[2.62,64.27],[2.66,55.39]],"batb":[[0,2.6,2.21],[1,2.58,2.68],[2,2.54,102.74]],"batl":[[0,2.72,1406.24],[1,2.74,1364.88],[2,2.76,1382.4]],"ltp":2.6,"tv":16389.39,"id":9631939},{"trd":[[1.55,8.12],[1.6,225.16],[1.61,20.5]],"batb":[[0,1.6,2284.28],[1,1.59,149.46],[2,1.57,92.57]],"batl":[[0,1.62,19.25],[1,1.63,18.5],[2,1.65,244.87]],"ltp":1.61,"tv":4629.9,"id":9454286}],"tv":21019.29}]}
{"op":"mcm","clk":"4289921699","pt":1632495448212,"mc":[{"id":"1.188075669","rc":[{"batb":[[1,2.54,102.74],[2,2.48,40.54]],"batl":[[0,2.72,351.56],[1,2.74,341.22],[2,2.76,358.74]],"ltp":2.6,"tv":16389.39,"id":9631939},{"batb":[[0,1.6,516.04],[2,1.57,132.06]],"batl":[[1,1.65,244.87],[2,1.66,613.56]],"ltp":1.61,"tv":4629.9,"id":9454286}]}]}
{"op":"mcm","clk":"4289921831","pt":1632495450175,"mc":[{"id":"1.188075669","rc":[{"batl":[[0,2.7,2],[1,2.72,351.56],[2,2.74,341.22]],"ltp":2.6,"tv":16389.39,"id":9631939}]}]}
{"op":"mcm","clk":"4289921953","pt":1632495452193,"mc":[{"id":"1.188075669","rc":[{"trd":[[1.6,626]],"batb":[[0,1.6,315.62]],"batl":[[2,1.66,779.19]],"ltp":1.6,"tv":5030.74,"id":9454286}],"tv":21420.13}]}
{"op":"mcm","clk":"4289922043","pt":1632495452986,"mc":[{"id":"1.188075669","rc":[{"batb":[[0,1.6,349.63]],"batl":[[2,1.66,613.56]],"ltp":1.6,"tv":5030.74,"id":9454286}]}]}
{"op":"mcm","clk":"4289922102","pt":1632495454185,"mc":[{"id":"1.188075669","rc":[{"batl":[[0,1.62,149.25]],"ltp":1.6,"tv":5030.74,"id":9454286}]}]}
{"op":"mcm","clk":"4289922201","pt":1632495456113,"mc":[{"id":"1.188075669","rc":[{"batl":[[0,2.68,39.5],[1,2.7,2],[2,2.72,351.56]],"ltp":2.6,"tv":16389.39,"id":9631939}]}]}
{"op":"mcm","clk":"4289922264","pt":1632495457207,"mc":[{"id":"1.188075669","rc":[{"batl":[[0,2.7,2],[1,2.72,351.56],[2,2.74,341.22]],"ltp":2.6,"tv":16389.39,"id":9631939},{"batl":[[0,1.62,239.25],[2,1.66,595.73]],"ltp":1.6,"tv":5030.74,"id":9454286}]}]}
{"op":"mcm","clk":"4289922433","pt":1632495460214,"mc":[{"id":"1.188075669","rc":[{"batl":[[0,2.66,11.37],[1,2.68,10],[2,2.7,2]],"ltp":2.6,"tv":16389.39,"id":9631939},{"batl":[[1,1.64,11.91],[2,1.65,244.87]],"ltp":1.6,"tv":5030.74,"id":9454286}]}]}
{"op":"mcm","clk":"4289922488","pt":1632495461004,"mc":[{"id":"1.188075669","rc":[{"batb":[[0,2.54,102.74],[1,2.48,40.54],[2,2.44,4]],"batl":[[0,2.7,2],[1,2.78,44.97],[2,2.82,166.49]],"ltp":2.6,"tv":16389.39,"id":9631939},{"trd":[[1.6,626.08]],"batb":[[0,1.6,195.54],[1,1.57,39.49],[2,1.56,80.17]],"batl":[[0,1.62,220],[1,1.75,35.43],[2,1.76,200.9]],"ltp":1.6,"tv":5030.82,"id":9454286}],"tv":21420.21}]}
{"op":"mcm","clk":"4289922567","pt":1632495462005,"mc":[{"id":"1.188075669","rc":[{"batb":[[0,2.48,40.54],[1,2.32,168.16],[2,2.3,326.11]],"batl":[[0,2.78,44.97],[1,2.82,166.49],[2,2.84,157.21]],"ltp":2.6,"tv":16389.39,"id":9631939},{"batb":[[0,1.56,80.17],[1,1.55,211.97],[2,1.54,676.51]],"batl":[[0,1.76,200.9],[1,1.77,260.04],[2,1.95,419.78]],"ltp":1.6,"tv":5030.82,"id":9454286}]}]}
{"op":"mcm","clk":"4289922638","pt":1632495463116,"mc":[{"id":"1.188075669","rc":[{"batb":[[0,2.32,168.16],[1,2.3,326.11],[2,1.12,2.53]],"batl":[[0,2.82,166.49],[1,2.84,157.21],[2,2.86,7.25]],"ltp":2.6,"tv":16389.39,"id":9631939},{"batb":[[0,1.55,211.97],[1,1.54,676.51],[2,1.51,111.99]],"batl":[[0,1.62,126],[1,1.76,200.9],[2,1.77,260.04]],"ltp":1.6,"tv":5030.82,"id":9454286}]}]}
{"op":"mcm","clk":"4289922710","pt":1632495464216,"mc":[{"id":"1.188075669","rc":[{"batb":[[2,1.53,287.35]],"batl":[[0,1.76,200.9],[1,1.77,432.52],[2,1.79,198.93]],"ltp":1.6,"tv":5030.82,"id":9454286}]}]}
{"op":"mcm","clk":"4289922768","pt":1632495465210,"mc":[{"id":"1.188075669","rc":[{"batl":[[0,1.68,60.2],[1,1.76,200.9],[2,1.77,432.52]],"ltp":1.6,"tv":5030.82,"id":9454286}]}]}
{"op":"mcm","clk":"4289922781","pt":1632495465521,"mc":[{"id":"1.188075669","rc":[{"batb":[[0,2.32,171.16],[1,2.3,330.11]],"ltp":2.6,"tv":16389.39,"id":9631939},{"batl":[[0,1.76,205.09],[1,1.77,432.52],[2,1.79,198.93]],"ltp":1.6,"tv":5030.82,"id":9454286}]}]}
{"op":"mcm","clk":"4289922857","pt":1632495466723,"mc":[{"id":"1.188075669","rc":[{"batl":[[0,1.71,4],[1,1.76,204.9],[2,1.77,432.52]],"ltp":1.6,"tv":5030.82,"id":9454286}]}]}
{"op":"mcm","clk":"4289923022","pt":1632495469707,"mc":[{"id":"1.188075669","rc":[{"batb":[[0,2.4,4],[1,2.38,4],[2,2.32,171.16]],"ltp":2.6,"tv":16389.39,"id":9631939}]}]}
{"op":"mcm","clk":"4289923063","pt":1632495470640,"mc":[{"id":"1.188075669","rc":[{"batb":[[2,1.51,111.99]],"batl":[[2,1.77,260.04]],"ltp":1.6,"tv":5030.82,"id":9454286}]}]}
{"op":"mcm","clk":"4289923224","pt":1632495473937,"mc":[{"id":"1.188075669","rc":[{"batb":[[0,2.56,20.08]],"batl":[[0,2.64,18.18],[1,2.82,166.49],[2,2.84,157.21]],"ltp":2.6,"tv":16389.39,"id":9631939},{"batb":[[0,1.62,161.76],[1,1.61,142.77],[2,1.55,211.97]],"batl":[[0,1.64,20.68],[1,1.67,206.19],[2,1.69,240.9]],"ltp":1.6,"tv":5030.82,"id":9454286}]}]}
{"op":"mcm","clk":"4289923294","pt":1632495474922,"mc":[{"id":"1.188075669","rc":[{"batb":[[0,2.38,4],[1,2.32,171.16],[2,2.3,330.11]],"batl":[[0,2.82,166.49],[1,2.84,157.21],[2,2.86,7.25]],"ltp":2.6,"tv":16389.39,"id":9631939},{"batl":[[0,1.67,206.19],[1,1.69,240.9],[2,1.76,204.9]],"ltp":1.6,"tv":5030.82,"id":9454286}]}]}
{"op":"mcm","clk":"4289923356","pt":1632495475914,"mc":[{"id":"1.188075669","rc":[{"batb":[[0,1.55,211.97],[1,1.54,676.51],[2,1.51,111.99]],"batl":[[0,1.76,204.9],[1,1.77,260.04],[2,1.95,419.78]],"ltp":1.6,"tv":5030.82,"id":9454286}]}]}
{"op":"mcm","clk":"4289923431","pt":1632495476949,"mc":[{"id":"1.188075669","rc":[{"batl":[[0,1.72,5],[1,1.76,204.9],[2,1.77,260.04]],"ltp":1.6,"tv":5030.82,"id":9454286}]}]}
{"op":"mcm","clk":"4289923460","pt":1632495477420,"mc":[{"id":"1.188075669","rc":[{"batb":[[1,2.32,168.16],[2,2.3,326.11]],"ltp":2.6,"tv":16389.39,"id":9631939}]}]}
{"op":"mcm","clk":"4289923538","pt":1632495478619,"mc":[{"id":"1.188075669","rc":[{"batb":[[1,2.36,3],[2,2.32,168.16]],"ltp":2.6,"tv":16389.39,"id":9631939},{"batb":[[2,1.53,287.32]],"batl":[[1,1.73,5],[2,1.76,204.9]],"ltp":1.6,"tv":5030.82,"id":9454286}]}]}
{"op":"mcm","clk":"4289924197","pt":1632495487741,"mc":[{"id":"1.188075669","rc":[{"trd":[[2.38,0.18]],"batb":[[0,2.4,2.5],[1,2.38,3.91],[2,2.36,3]],"ltp":2.38,"tv":16389.58,"id":9631939}],"tv":21420.4}]}
{"op":"mcm","clk":"4289924312","pt":1632495489150,"mc":[{"id":"1.188075669","rc":[{"batl":[[0,2.86,7.25],[1,2.98,5.75],[2,3,6.02]],"ltp":2.38,"tv":16389.58,"id":9631939},{"batb":[[0,1.54,346.1],[1,1.51,111.99],[2,1.5,104.82]],"ltp":1.6,"tv":5030.82,"id":9454286}]}]}
{"op":"mcm","clk":"4289924325","pt":1632495489359,"mc":[{"id":"1.188075669","rc":[{"batl":[[0,1.73,5],[1,1.76,200.9],[2,1.77,432.54]],"ltp":1.6,"tv":5030.82,"id":9454286}]}]}
{"op":"mcm","clk":"4289924479","pt":1632495491149,"mc":[{"id":"1.188075669","rc":[{"batb":[[0,2.4,5.5],[2,2.32,168.16]],"ltp":2.38,"tv":16389.58,"id":9631939}]}]}
{"op":"mcm","clk":"4289924567","pt":1632495492146,"mc":[{"id":"1.188075669","rc":[{"trd":[[2.32,26.32],[2.4,5]],"batb":[[0,2.32,155],[1,2.3,326.11],[2,1.12,2.53]],"batl":[[0,2.36,3.53],[1,2.44,391.9],[2,2.46,405.63]],"ltp":2.32,"tv":16420.89,"id":9631939},{"batb":[[0,1.71,3140.67],[1,1.69,348.76],[2,1.67,37.13]],"batl":[[0,1.76,200.9],[1,1.77,432.54],[2,1.78,327.57]],"ltp":1.6,"tv":5030.82,"id":9454286}],"tv":21451.71}]}
{"op":"mcm","clk":"4289924637","pt":1632495493184,"mc":[{"id":"1.188075669","rc":[{"trd":[[2.36,3.53]],"batb":[[2,2.26,47.61]],"batl":[[0,2.44,391.9],[1,2.46,405.63],[2,2.48,380.38]],"ltp":2.36,"tv":16424.42,"id":9631939},{"trd":[[1.73,4.82]],"batb":[[0,1.72,154.29],[1,1.71,438.09],[2,1.69,348.76]],"ltp":1.73,"tv":5035.64,"id":9454286}],"tv":21460.06}]}
{"op":"mcm","clk":"4289924863","pt":1632495497153,"mc":[{"id":"1.188075669","rc":[{"batl":[[0,2.42,36.25],[1,2.44,391.9],[2,2.46,405.63]],"ltp":2.36,"tv":16424.42,"id":9631939},{"batb":[[0,1.72,183.32]],"ltp":1.73,"tv":5035.64,"id":9454286}]}]}
{"op":"mcm","clk":"4289925046","pt":1632495500059,"mc":[{"id":"1.188075669","rc":[{"batl":[[0,1.75,806],[1,1.76,200.9],[2,1.77,432.54]],"ltp":1.73,"tv":5035.64,"id":9454286}]}]}
{"op":"mcm","clk":"4289925119","pt":1632495501158,"mc":[{"id":"1.188075669","rc":[{"trd":[[1.72,0.47]],"batb":[[0,1.72,183.08]],"ltp":1.72,"tv":5036.1,"id":9454286}],"tv":21460.53}]}
{"op":"mcm","clk":"4289925218","pt":1632495503084,"mc":[{"id":"1.188075669","rc":[{"trd":[[2.32,85.32]],"batb":[[0,2.32,125.5]],"ltp":2.32,"tv":16483.43,"id":9631939},{"trd":[[1.72,0.52]],"batb":[[0,1.72,183.05]],"ltp":1.72,"tv":5036.16,"id":9454286}],"tv":21519.59}]}
{"op":"mcm","clk":"4289925289","pt":1632495504080,"mc":[{"id":"1.188075669","rc":[{"batb":[[1,1.71,205.11]],"ltp":1.72,"tv":5036.16,"id":9454286}]}]}
{"op":"mcm","clk":"4289925351","pt":1632495505075,"mc":[{"id":"1.188075669","rc":[{"batb":[[0,2.32,136.15]],"ltp":2.32,"tv":16483.43,"id":9631939},{"trd":[[1.72,1.46]],"batb":[[0,1.72,192.65]],"ltp":1.72,"tv":5037.1,"id":9454286}],"tv":21520.53}]}
{"op":"mcm","clk":"4289925364","pt":1632495505391,"mc":[{"id":"1.188075669","rc":[{"batb":[[0,2.32,125.5]],"ltp":2.32,"tv":16483.43,"id":9631939},{"batb":[[0,1.72,182.59]],"ltp":1.72,"tv":5037.1,"id":9454286}]}]}
{"op":"mcm","clk":"4289925551","pt":1632495508205,"mc":[{"id":"1.188075669","rc":[{"batb":[[0,2.32,136.15]],"ltp":2.32,"tv":16483.43,"id":9631939},{"batb":[[0,1.72,192.65]],"ltp":1.72,"tv":5037.1,"id":9454286}]}]}
{"op":"mcm","clk":"4289925661","pt":1632495509883,"mc":[{"id":"1.188075669","rc":[{"trd":[[2.32,120.01]],"batb":[[0,2.32,118.8]],"ltp":2.32,"tv":16518.12,"id":9631939}],"tv":21555.22}]}
{"op":"mcm","clk":"4289925912","pt":1632495513922,"mc":[{"id":"1.188075669","rc":[{"batb":[[0,2.3,134.21],[1,2.26,47.61],[2,2.04,189.38]],"batl":[[0,2.5,48.98],[1,2.64,7.43],[2,2.76,7.02]],"ltp":2.32,"tv":16518.12,"id":9631939},{"batb":[[0,1.72,153.56],[1,1.63,184.74],[2,1.61,110.09]],"batl":[[1,1.8,60.17],[2,2.22,337.02]],"ltp":1.72,"tv":5037.1,"id":9454286}]}]}
{"op":"mcm","clk":"4289925934","pt":1632495514239,"mc":[{"id":"1.188075669","rc":[{"batb":[[0,2.26,47.61],[1,2.04,189.38],[2,1.12,2.53]],"ltp":2.32,"tv":16518.12,"id":9631939},{"batb":[[0,1.63,184.74],[1,1.61,110.09],[2,1.57,100.57]],"batl":[[0,1.8,60.17],[1,2.22,337.02],[2,990,0.01]],"ltp":1.72,"tv":5037.1,"id":9454286}]}]}
{"op":"mcm","clk":"4289926037","pt":1632495516009,"mc":[{"id":"1.188075669","rc":[{"batb":[[0,2.04,189.38],[1,1.12,2.53],[2,1.11,2.86]],"batl":[[0,2.64,7.43],[1,2.76,7.02],[2,2.84,3]],"ltp":2.32,"tv":16518.12,"id":9631939},{"batl":[[0,2.22,337.41],[1,990,0.01],[2,990,0]],"ltp":1.72,"tv":5037.1,"id":9454286}]}]}
{"op":"mcm","clk":"4289926115","pt":1632495517210,"mc":[{"id":"1.188075669","rc":[{"batb":[[1,1.62,176.27],[2,1.61,252.9]],"batl":[[0,1.72,18.26],[1,1.96,118.16],[2,1.98,145.18]],"ltp":1.72,"tv":5037.1,"id":9454286}]}]}
{"op":"mcm","clk":"4289926221","pt":1632495518895,"mc":[{"id":"1.188075669","rc":[{"batb":[[0,2.04,193.38],[1,2.02,4],[2,1.12,2.53]],"ltp":2.32,"tv":16518.12,"id":9631939},{"batl":[[0,1.72,18.13],[2,1.97,4]],"ltp":1.72,"tv":5037.1,"id":9454286}]}]}
{"op":"mcm","clk":"4289926280","pt":1632495519727,"mc":[{"id":"1.188075669","rc":[{"trd":[[2.38,13.29]],"batl":[[0,2.32,26.89],[1,2.64,7.43],[2,2.76,7.02]],"ltp":2.38,"tv":16531.23,"id":9631939},{"trd":[[1.72,19.6]],"batb":[[1,1.61,110.09],[2,1.57,100.57]],"batl":[[0,1.96,118.16],[1,1.97,4],[2,1.98,145.18]],"ltp":1.72,"tv":5055.23,"id":9454286}],"tv":21586.47}]}
{"op":"mcm","clk":"4289926434","pt":1632495522224,"mc":[{"id":"1.188075669","rc":[{"batl":[[0,2.06,14.56],[1,2.18,2308.15],[2,2.2,458.16]],"ltp":2.38,"tv":16531.23,"id":9631939},{"trd":[[1.8,0.34]],"batb":[[0,1.92,8.74],[1,1.87,2045.46],[2,1.86,1985.13]],"batl":[[0,1.96,127.43]],"ltp":1.8,"tv":5055.57,"id":9454286}],"tv":21586.8}]}
{"op":"mcm","clk":"4289926506","pt":1632495523216,"mc":[{"id":"1.188075669","rc":[{"batb":[[0,2.04,189.38],[1,1.95,31.8],[2,1.85,127.63]],"batl":[[1,2.16,29.97]],"ltp":2.38,"tv":16531.23,"id":9631939},{"batb":[[1,1.9,111.52],[2,1.89,183.6]],"batl":[[1,1.98,145.18],[2,2,478.12]],"ltp":1.8,"tv":5055.57,"id":9454286}]}]}
{"op":"mcm","clk":"4289926528","pt":1632495523634,"mc":[{"id":"1.188075669","rc":[{"trd":[[2.06,10.75]],"batl":[[0,2.06,10.28]],"ltp":2.06,"tv":16539.79,"id":9631939}],"tv":21595.36}]}
{"op":"mcm","clk":"4289926589","pt":1632495524554,"mc":[{"id":"1.188075669","rc":[{"batb":[[1,2.02,58.82],[2,1.95,31.8]],"ltp":2.06,"tv":16539.79,"id":9631939},{"batl":[[1,1.98,205.18]],"ltp":1.8,"tv":5055.57,"id":9454286}]}]}
{"op":"mcm","clk":"4289926694","pt":1632495526017,"mc":[{"id":"1.188075669","rc":[{"trd":[[2.06,25.79]],"batb":[[2,1.98,5]],"batl":[[0,2.06,2.76]],"ltp":2.06,"tv":16554.83,"id":9631939}],"tv":21610.4}]}
{"op":"mcm","clk":"4289926767","pt":1632495527104,"mc":[{"id":"1.188075669","rc":[{"trd":[[2.06,30.58]],"batl":[[0,2.16,29.97],[1,2.2,458.16],[2,2.32,1.71]],"ltp":2.06,"tv":16559.62,"id":9631939},{"trd":[[1.94,7.53]],"batl":[[0,1.93,117.75],[1,1.96,127.43],[2,1.98,205.18]],"ltp":1.94,"tv":5056.35,"id":9454286}],"tv":21615.97}]}
{"op":"mcm","clk":"4289926830","pt":1632495528043,"mc":[{"id":"1.188075669","rc":[{"batl":[[0,1.96,127.43],[1,1.98,205.18],[2,2,478.12]],"ltp":1.94,"tv":5056.35,"id":9454286}]}]}
{"op":"mcm","clk":"4289926953","pt":1632495530135,"mc":[{"id":"1.188075669","rc":[{"batl":[[0,2.14,86.09],[1,2.16,29.97],[2,2.2,458.16]],"ltp":2.06,"tv":16559.62,"id":9631939}]}]}
{"op":"mcm","clk":"4289927007","pt":1632495530814,"mc":[{"id":"1.188075669","rc":[{"batl":[[0,2.16,29.97],[1,2.2,458.16],[2,2.26,168.58]],"ltp":2.06,"tv":16559.62,"id":9631939}]}]}
{"op":"mcm","clk":"4289927085","pt":1632495531649,"mc":[{"id":"1.188075669","rc":[{"batl":[[2,2.22,54.32]],"ltp":2.06,"tv":16559.62,"id":9631939}]}]}
{"op":"mcm","clk":"4289927276","pt":1632495533949,"mc":[{"id":"1.188075669","rc":[{"batb":[[2,2,2.5]],"ltp":2.06,"tv":16559.62,"id":9631939},{"batl":[[0,1.96,249.43]],"ltp":1.94,"tv":5056.35,"id":9454286}]}]}
{"op":"mcm","clk":"4289927425","pt":1632495536029,"mc":[{"id":"1.188075669","rc":[{"trd":[[1.92,2.66]],"batb":[[0,1.92,7.41]],"ltp":1.92,"tv":5059.01,"id":9454286}],"tv":21618.64}]}
{"op":"mcm","clk":"4289927510","pt":1632495537182,"mc":[{"id":"1.188075669","rc":[{"batl":[[0,2.14,31.71],[1,2.16,29.97]],"ltp":2.06,"tv":16559.62,"id":9631939},{"batb":[[0,1.9,111.52],[1,1.87,104.27],[2,1.81,34.26]],"batl":[[0,1.96,122],[1,1.98,60],[2,2.18,185.35]],"ltp":1.92,"tv":5059.01,"id":9454286}]}]}
{"op":"mcm","clk":"4289927577","pt":1632495538059,"mc":[{"id":"1.188075669","rc":[{"trd":[[2.04,0.78]],"batb":[[0,2.02,58.82],[1,2,2.5],[2,1.85,307.32]],"batl":[[0,2.22,54.32],[1,2.26,168.58],[2,2.28,185.38]],"ltp":2.04,"tv":16560.4,"id":9631939},{"batb":[[0,1.79,237.43],[1,1.78,383.2],[2,1.76,90.23]],"batl":[[0,1.92,7.29]],"ltp":1.92,"tv":5059.01,"id":9454286}],"tv":21619.42}]}
{"op":"mcm","clk":"4289927587","pt":1632495538268,"mc":[{"id":"1.188075669","rc":[{"batb":[[0,2,2.5],[1,1.85,307.32],[2,1.84,215.81]],"batl":[[0,2.26,168.58],[1,2.28,185.38],[2,2.32,7.61]],"ltp":2.04,"tv":16560.4,"id":9631939},{"batl":[[1,2.18,185.35],[2,2.2,189.32]],"ltp":1.92,"tv":5059.01,"id":9454286}]}]}
{"op":"mcm","clk":"4289927740","pt":1632495540155,"mc":[{"id":"1.188075669","rc":[{"batb":[[1,1.78,535.97],[2,1.76,297.62]],"batl":[[0,2.18,185.52],[1,2.2,323.34],[2,2.22,104.13]],"ltp":1.92,"tv":5059.01,"id":9454286}]}]}
{"op":"mcm","clk":"4289927906","pt":1632495541779,"mc":[{"id":"1.188075669","rc":[{"batl":[[0,2.18,185.35]],"ltp":1.92,"tv":5059.01,"id":9454286}]}]}
{"op":"mcm","clk":"4289927976","pt":1632495542671,"mc":[{"id":"1.188075669","rc":[{"batl":[[0,2.26,168.67]],"ltp":2.04,"tv":16560.4,"id":9631939}]}]}
{"op":"mcm","clk":"4289928023","pt":1632495543452,"mc":[{"id":"1.188075669","rc":[{"batb":[[1,1.85,127.63],[2,1.12,2.53]],"ltp":2.04,"tv":16560.4,"id":9631939},{"batl":[[0,2.5,281.5],[1,990,0.01],[2,2.22,0]],"ltp":1.92,"tv":5059.01,"id":9454286}]}]}
{"op":"mcm","clk":"4289928201","pt":1632495546053,"mc":[{"id":"1.188075669","rc":[{"trd":[[2.04,0.88]],"batl":[[0,2.26,168.58],[1,2.28,198.5]],"ltp":2.04,"tv":16560.49,"id":9631939},{"trd":[[1.96,0.1]],"batl":[[0,1.83,11.04],[1,1.84,1500.26],[2,1.86,2056.44]],"ltp":1.96,"tv":5059.11,"id":9454286}],"tv":21619.61}]}
{"op":"mcm","clk":"4289928301","pt":1632495547149,"mc":[{"id":"1.188075669","rc":[{"trd":[[2.18,13.76]],"batb":[[0,2.18,154.2],[1,2,2.5],[2,1.88,122.4]],"batl":[[1,2.28,185.38]],"ltp":2.18,"tv":16574.25,"id":9631939},{"trd":[[1.84,72.58]],"batl":[[0,1.84,257.6],[1,1.86,690.1],[2,1.87,498.98]],"ltp":1.84,"tv":5075.41,"id":9454286}],"tv":21649.67}]}
{"op":"mcm","clk":"4289928375","pt":1632495548191,"mc":[{"id":"1.188075669","rc":[{"batb":[[1,2.12,53.57],[2,2,2.5]],"ltp":2.18,"tv":16574.25,"id":9631939}]}]}
{"op":"mcm","clk":"4289928449","pt":1632495549181,"mc":[{"id":"1.188075669","rc":[{"batb":[[2,2.02,3]],"batl":[[1,2.28,198.5]],"ltp":2.18,"tv":16574.25,"id":9631939},{"batl":[[0,1.83,11.04],[1,1.84,257.6],[2,1.86,690.1]],"ltp":1.84,"tv":5075.41,"id":9454286}]}]}
{"op":"mcm","clk":"4289928514","pt":1632495550076,"mc":[{"id":"1.188075669","rc":[{"batb":[[1,2.02,78],[2,2,6.5]],"ltp":2.18,"tv":16574.25,"id":9631939}]}]}
{"op":"mcm","clk":"4289928909","pt":1632495555107,"mc":[{"id":"1.188075669","rc":[{"trd":[[2.2,27.37]],"ltp":2.2,"tv":16601.63,"id":9631939},{"trd":[[1.83,32.91]],"batl":[[0,1.83,340.13]],"ltp":1.83,"tv":5108.32,"id":9454286}],"tv":21709.96}]}
{"op":"mcm","clk":"4289928974","pt":1632495556100,"mc":[{"id":"1.188075669","rc":[{"batb":[[1,2.1,54.54],[2,2.02,78]],"batl":[[2,2.32,59.83]],"ltp":2.2,"tv":16601.63,"id":9631939}]}]}
{"op":"mcm","clk":"4289929099","pt":1632495558103,"mc":[{"id":"1.188075669","rc":[{"batl":[[1,1.84,154.82]],"ltp":1.83,"tv":5108.32,"id":9454286}]}]}
{"op":"mcm","clk":"4289929159","pt":1632495559099,"mc":[{"id":"1.188075669","rc":[{"trd":[[1.79,15.34]],"batb":[[0,1.79,229.75]],"ltp":1.79,"tv":5123.67,"id":9454286}],"tv":21725.3}]}
{"op":"mcm","clk":"4289929389","pt":1632495562181,"mc":[{"id":"1.188075669","rc":[{"trd":[[1.83,37.61]],"batl":[[0,1.83,337.78]],"ltp":1.83,"tv":5128.36,"id":9454286}],"tv":21729.99}]}
{"op":"mcm","clk":"4289929442","pt":1632495563121,"mc":[{"id":"1.188075669","rc":[{"trd":[[2.2,37.54]],"ltp":2.2,"tv":16611.8,"id":9631939},{"trd":[[1.83,49.84]],"batl":[[0,1.83,325.55]],"ltp":1.83,"tv":5140.59,"id":9454286}],"tv":21752.4}]}
{"op":"mcm","clk":"4289929579","pt":1632495565205,"mc":[{"id":"1.188075669","rc":[{"batl":[[1,2.28,185.38]],"ltp":2.2,"tv":16611.8,"id":9631939}]}]}
{"op":"mcm","clk":"4289929820","pt":1632495568705,"mc":[{"id":"1.188075669","rc":[{"trd":[[2.24,0.14]],"batl":[[0,2.24,10.47],[1,2.26,168.58],[2,2.28,185.38]],"ltp":2.24,"tv":16611.94,"id":9631939},{"trd":[[1.8,0.51]],"batl":[[2,1.86,705.83]],"ltp":1.8,"tv":5140.76,"id":9454286}],"tv":21752.7}]}
{"op":"mcm","clk":"4289930011","pt":1632495571143,"mc":[{"id":"1.188075669","rc":[{"batb":[[0,2.1,54.54],[1,2,2.5],[2,1.88,122.4]],"batl":[[0,2.32,52.22],[1,2.54,6.75],[2,2.68,7.14]],"ltp":2.24,"tv":16611.94,"id":9631939},{"batb":[[0,1.75,69.28],[1,1.65,94.73],[2,1.64,179.34]],"batl":[[0,1.91,60],[1,2.36,306.69],[2,990,0.01]],"ltp":1.8,"tv":5140.76,"id":9454286}]}]}
{"op":"mcm","clk":"4289930167","pt":1632495572840,"mc":[{"id":"1.188075669","rc":[{"batb":[[0,2,2.5],[1,1.88,122.4],[2,1.12,2.53]],"batl":[[0,2.68,7.14],[1,2.84,3],[2,4.3,68.9]],"ltp":2.24,"tv":16611.94,"id":9631939},{"batb":[[0,1.64,179.34],[1,1.6,103.85],[2,1.58,421.15]],"batl":[[0,2.36,306.69],[1,990,0.01],[2,990,0]],"ltp":1.8,"tv":5140.76,"id":9454286}]}]}
{"op":"mcm","clk":"4289930224","pt":1632495573628,"mc":[{"id":"1.188075669","rc":[{"batb":[[1,1.63,212.44],[2,1.62,139.71]],"batl":[[0,2.18,177.92],[1,2.2,106.88],[2,2.36,306.69]],"ltp":1.8,"tv":5140.76,"id":9454286}]}]}
{"op":"mcm","clk":"4289930321","pt":1632495574918,"mc":[{"id":"1.188075669","rc":[{"batb":[[1,1.6,103.85],[2,1.58,421.15]],"batl":[[0,2.36,306.69],[1,990,0.01],[2,2.36,0]],"ltp":1.8,"tv":5140.76,"id":9454286}]}]}
{"op":"mcm","clk":"4289930391","pt":1632495576023,"mc":[{"id":"1.188075669","rc":[{"batl":[[0,2.54,6.75],[1,2.68,7.14],[2,2.84,3]],"ltp":2.24,"tv":16611.94,"id":9631939},{"batb":[[0,1.65,101.73],[1,1.64,179.34],[2,1.6,103.85]],"ltp":1.8,"tv":5140.76,"id":9454286}]}]}
{"op":"mcm","clk":"4289930419","pt":1632495576345,"mc":[{"id":"1.188075669","rc":[{"batl":[[0,2.68,7.14],[1,2.84,3],[2,4.3,68.9]],"ltp":2.24,"tv":16611.94,"id":9631939},{"batb":[[0,1.64,179.34],[1,1.6,103.85],[2,1.58,421.15]],"ltp":1.8,"tv":5140.76,"id":9454286}]}]}
{"op":"mcm","clk":"4289930554","pt":1632495578209,"mc":[{"id":"1.188075669","rc":[{"batb":[[0,1.83,183.65],[1,1.81,189.01],[2,1.64,179.34]],"batl":[[0,1.9,166.38],[1,1.92,159.4],[2,2.36,306.69]],"ltp":1.8,"tv":5140.76,"id":9454286}]}]}
{"op":"mcm","clk":"4289930713","pt":1632495580133,"mc":[{"id":"1.188075669","rc":[{"batl":[[0,2.54,7.75],[1,2.68,7.14],[2,2.84,3]],"ltp":2.24,"tv":16611.94,"id":9631939},{"batb":[[0,1.65,106.13],[1,1.64,179.34],[2,1.6,103.85]],"batl":[[0,2.36,306.69],[1,990,0.01],[2,2.36,0]],"ltp":1.8,"tv":5140.76,"id":9454286}]}]}
{"op":"mcm","clk":"4289930769","pt":1632495580927,"mc":[{"id":"1.188075669","rc":[{"batl":[[0,2.68,7.14],[1,2.84,3],[2,4.3,68.9]],"ltp":2.24,"tv":16611.94,"id":9631939},{"batb":[[0,1.64,179.34],[1,1.6,103.85],[2,1.58,421.15]],"ltp":1.8,"tv":5140.76,"id":9454286}]}]}
{"op":"mcm","clk":"4289930951","pt":1632495583036,"mc":[{"id":"1.188075669","rc":[{"batb":[[1,1.63,212.44],[2,1.62,139.71]],"batl":[[0,2.18,177.92],[1,2.2,106.88],[2,2.36,306.69]],"ltp":1.8,"tv":5140.76,"id":9454286}]}]}
{"op":"mcm","clk":"4289931279","pt":1632495586645,"mc":[{"id":"1.188075669","rc":[{"batb":[[1,1.6,103.85],[2,1.58,421.15]],"batl":[[0,2.36,306.69],[1,990,0.01],[2,2.36,0]],"ltp":1.8,"tv":5140.76,"id":9454286}]}]}
{"op":"mcm","clk":"4289931383","pt":1632495588152,"mc":[{"id":"1.188075669","rc":[{"batb":[[2,1.55,7]],"batl":[[0,990,0.18],[1,990,0]],"ltp":1.8,"tv":5140.76,"id":9454286}]}]}
{"op":"mcm","clk":"4289931566","pt":1632495590033,"mc":[{"id":"1.188075669","rc":[{"trd":[[1.88,38.9],[2,2.5]],"batb":[[0,1.88,102.95],[1,1.85,187.02],[2,1.83,182.05]],"batl":[[0,1.89,15.87],[1,1.92,144.92],[2,1.94,646.97]],"ltp":1.88,"tv":16653.34,"id":9631939},{"trd":[[2,2.5]],"batb":[[0,2.08,176.08],[1,2.06,387.59],[2,1.95,31.8]],"batl":[[0,2.24,7.69],[1,2.48,1.88],[2,990,0.01]],"ltp":2.0,"tv":5143.26,"id":9454286}],"tv":21796.6}]}
{"op":"mcm","clk":"4289931699","pt":1632495591135,"mc":[{"id":"1.188075669","rc":[{"batb":[[1,2.06,559.51],[2,2,146.07]],"batl":[[1,2.34,82.61],[2,2.48,1.88]],"ltp":2.0,"tv":5143.26,"id":9454286}]}]}
{"op":"mcm","clk":"4289931770","pt":1632495592039,"mc":[{"id":"1.188075669","rc":[{"batb":[[2,2,2]],"batl":[[1,2.34,12.82]],"ltp":2.0,"tv":5143.26,"id":9454286}]}]}
{"op":"mcm","clk":"4289931832","pt":1632495592766,"mc":[{"id":"1.188075669","rc":[{"batb":[[1,2.06,563.51],[2,2.04,5]],"ltp":2.0,"tv":5143.26,"id":9454286}]}]}
{"op":"mcm","clk":"4289931987","pt":1632495594959,"mc":[{"id":"1.188075669","rc":[{"trd":[[1.89,15.87]],"batb":[[2,1.83,247.9]],"batl":[[0,1.92,144.92],[1,1.94,646.97],[2,1.95,478.42]],"ltp":1.89,"tv":16669.21,"id":9631939},{"trd":[[2.12,14.15]],"batb":[[0,2.08,200.76]],"batl":[[0,2.22,31.75],[1,2.24,61.57],[2,2.34,12.82]],"ltp":2.12,"tv":5157.41,"id":9454286}],"tv":21826.62}]}
{"op":"mcm","clk":"4289932062","pt":1632495596052,"mc":[{"id":"1.188075669","rc":[{"batb":[[0,1.88,272.95],[2,1.83,182.05]],"ltp":1.89,"tv":16669.21,"id":9631939}]}]}
{"op":"mcm","clk":"4289932097","pt":1632495596571,"mc":[{"id":"1.188075669","rc":[{"batl":[[2,2.26,192.04]],"ltp":2.12,"tv":5157.41,"id":9454286}]}]}
{"op":"mcm","clk":"4289932280","pt":1632495599069,"mc":[{"id":"1.188075669","rc":[{"batb":[[0,1.88,485.95],[2,1.83,247.9]],"ltp":1.89,"tv":16669.21,"id":9631939}]}]}
{"op":"mcm","clk":"4289932363","pt":1632495600069,"mc":[{"id":"1.188075669","rc":[{"trd":[[1.88,39.1]],"batb":[[0,1.88,485.85]],"ltp":1.88,"tv":16669.4,"id":9631939},{"batl":[[0,2.26,192.04],[1,2.28,194.23],[2,2.34,12.82]],"ltp":2.12,"tv":5157.41,"id":9454286}],"tv":21826.82}]}
{"op":"mcm","clk":"4289932501","pt":1632495601209,"mc":[{"id":"1.188075669","rc":[{"batl":[[0,2.12,105.95],[1,2.26,192.04],[2,2.28,194.23]],"ltp":2.12,"tv":5157.41,"id":9454286}]}]}
{"op":"mcm","clk":"4289932590","pt":1632495601960,"mc":[{"id":"1.188075669","rc":[{"batb":[[0,2.08,24.68]],"ltp":2.12,"tv":5157.41,"id":9454286}]}]}
{"op":"mcm","clk":"4289932730","pt":1632495603172,"mc":[{"id":"1.188075669","rc":[{"trd":[[1.89,33.04]],"ltp":1.89,"tv":16686.57,"id":9631939},{"trd":[[2.12,29.45]],"batl":[[0,2.12,90.65],[1,2.2,12.07],[2,2.22,54.32]],"ltp":2.12,"tv":5172.71,"id":9454286}],"tv":21859.29}]}
{"op":"mcm","clk":"4289932893","pt":1632495604499,"mc":[{"id":"1.188075669","rc":[{"batb":[[2,2,284.63]],"ltp":2.12,"tv":5172.71,"id":9454286}]}]}
{"op":"mcm","clk":"4289933063","pt":1632495606257,"mc":[{"id":"1.188075669","rc":[{"trd":[[1.89,62.04]],"ltp":1.89,"tv":16715.57,"id":9631939},{"trd":[[2.12,55.27]],"batl":[[0,2.12,64.83]],"ltp":2.12,"tv":5198.53,"id":9454286}],"tv":21914.1}]}
{"op":"mcm","clk":"4289933197","pt":1632495607704,"mc":[{"id":"1.188075669","rc":[{"batb":[[2,2.04,3]],"ltp":2.12,"tv":5198.53,"id":9454286}]}]}
{"op":"mcm","clk":"4289933416","pt":1632495610194,"mc":[{"id":"1.188075669","rc":[{"trd":[[1.88,233.38],[1.89,134.86],[1.92,11.15]],"batb":[[0,1.88,388.75]],"batl":[[0,1.92,139.34]],"ltp":1.88,"tv":16993.82,"id":9631939},{"trd":[[2.12,120.1]],"batl":[[0,2.2,12.07],[1,2.22,54.32],[2,2.24,38.68]],"ltp":2.12,"tv":5263.36,"id":9454286}],"tv":22257.19}]}
{"op":"mcm","clk":"4289933427","pt":1632495610393,"mc":[{"id":"1.188075669","rc":[{"batl":[[2,2.26,192.04]],"ltp":2.12,"tv":5263.36,"id":9454286}]}]}
{"op":"mcm","clk":"4289933647","pt":1632495613107,"mc":[{"id":"1.188075669","rc":[{"batl":[[0,2.22,54.32],[1,2.26,192.04],[2,2.28,194.23]],"ltp":2.12,"tv":5263.36,"id":9454286}]}]}
{"op":"mcm","clk":"4289933663","pt":1632495613485,"mc":[{"id":"1.188075669","rc":[{"trd":[[1.88,243.37]],"batb":[[0,1.88,383.75]],"ltp":1.88,"tv":17003.81,"id":9631939},{"batl":[[0,2.2,38.68],[1,2.22,54.32],[2,2.26,192.04]],"ltp":2.12,"tv":5263.36,"id":9454286}],"tv":22267.18}]}
{"op":"mcm","clk":"4289933853","pt":1632495615704,"mc":[{"id":"1.188075669","rc":[{"batl":[[0,1.92,153.61]],"ltp":1.88,"tv":17003.81,"id":9631939},{"batl":[[0,2.16,12.23],[1,2.2,38.68],[2,2.22,54.32]],"ltp":2.12,"tv":5263.36,"id":9454286}]}]}
{"op":"mcm","clk":"4289934210","pt":1632495620113,"mc":[{"id":"1.188075669","rc":[{"batb":[[0,1.83,65.85],[1,1.81,137.58],[2,1.79,189.35]],"batl":[[0,2,159.59],[1,2.02,228.31],[2,2.04,8.88]],"ltp":1.88,"tv":17003.81,"id":9631939},{"batb":[[0,2,284.63],[1,1.99,223.17],[2,1.97,89.17]],"batl":[[0,2.22,54.32],[1,2.26,192.04],[2,2.28,194.23]],"ltp":2.12,"tv":5263.36,"id":9454286}]}]}
{"op":"mcm","clk":"4289934282","pt":1632495621005,"mc":[{"id":"1.188075669","rc":[{"batl":[[0,1.88,20.66],[1,2,159.59],[2,2.02,228.31]],"ltp":1.88,"tv":17003.81,"id":9631939}]}]}
{"op":"mcm","clk":"4289934302","pt":1632495621320,"mc":[{"id":"1.188075669","rc":[{"batb":[[0,1.81,137.58],[1,1.79,189.35],[2,1.78,222.99]],"ltp":1.88,"tv":17003.81,"id":9631939},{"batb":[[0,2,224.63]],"batl":[[0,2.26,192.04],[1,2.28,194.23],[2,2.72,247.76]],"ltp":2.12,"tv":5263.36,"id":9454286}]}]}
{"op":"mcm","clk":"4289934488","pt":1632495623221,"mc":[{"id":"1.188075669","rc":[{"batb":[[0,1.8,139.95],[1,1.79,394.38]],"ltp":1.88,"tv":17003.81,"id":9631939}]}]}
{"op":"mcm","clk":"4289934597","pt":1632495624490,"mc":[{"id":"1.188075669","rc":[{"batb":[[0,1.81,5],[1,1.8,144.95],[2,1.79,189.35]],"ltp":1.88,"tv":17003.81,"id":9631939},{"batl":[[0,2.24,4],[1,2.26,192.04],[2,2.28,194.23]],"ltp":2.12,"tv":5263.36,"id":9454286}]}]}
{"op":"mcm","clk":"4289934836","pt":1632495627209,"mc":[{"id":"1.188075669","rc":[{"batb":[[0,1.88,126.04],[1,1.86,172.74],[2,1.81,5]],"batl":[[0,1.95,180.02],[1,1.97,147.1],[2,2,159.59]],"ltp":1.88,"tv":17003.81,"id":9631939},{"batl":[[1,2.26,196.04]],"ltp":2.12,"tv":5263.36,"id":9454286}]}]}
{"op":"mcm","clk":"4289934880","pt":1632495627639,"mc":[{"id":"1.188075669","rc":[{"trd":[[1.88,251.93]],"batb":[[0,1.88,121.76]],"ltp":1.88,"tv":17012.37,"id":9631939}],"tv":22275.74}]}
{"op":"mcm","clk":"4289935006","pt":1632495628915,"mc":[{"id":"1.188075669","rc":[{"batb":[[0,1.81,5],[1,1.8,144.95],[2,1.79,193.35]],"batl":[[0,2,159.59],[1,2.02,228.31],[2,2.04,8.88]],"ltp":1.88,"tv":17012.37,"id":9631939}]}]}
{"op":"mcm","clk":"4289935298","pt":1632495632143,"mc":[{"id":"1.188075669","rc":[{"batb":[[2,1.79,395.89]],"ltp":1.88,"tv":17012.37,"id":9631939},{"trd":[[2,7.54]],"batb":[[0,2,222.1]],"ltp":2.0,"tv":5268.41,"id":9454286}],"tv":22280.78}]}
{"op":"mcm","clk":"4289935382","pt":1632495633137,"mc":[{"id":"1.188075669","rc":[{"batl":[[0,2.08,9.44],[1,2.1,9.15],[2,990,0.01]],"ltp":1.88,"tv":17012.37,"id":9631939},{"batb":[[0,1.95,102.58],[1,1.93,83.93],[2,1.91,83.39]],"ltp":2.0,"tv":5268.41,"id":9454286}]}]}
{"op":"mcm","clk":"4289935661","pt":1632495636137,"mc":[{"id":"1.188075669","rc":[{"batl":[[0,1.84,16.3],[1,1.86,1312.42],[2,1.87,498.98]],"ltp":1.88,"tv":17012.37,"id":9631939},{"batb":[[0,2.12,28.54],[1,1.95,102.58],[2,1.93,83.93]],"batl":[[0,2.24,14.94]],"ltp":2.0,"tv":5268.41,"id":9454286}]}]}
{"op":"mcm","clk":"4289935732","pt":1632495636828,"mc":[{"id":"1.188075669","rc":[{"batb":[[1,1.8,139.95]],"ltp":1.88,"tv":17012.37,"id":9631939},{"batb":[[0,2.16,149.22],[1,2.12,28.54],[2,2.04,179.93]],"ltp":2.0,"tv":5268.41,"id":9454286}]}]}
{"op":"mcm","clk":"4289935851","pt":1632495638053,"mc":[{"id":"1.188075669","rc":[{"batb":[[2,2.08,55.55]],"ltp":2.0,"tv":5268.41,"id":9454286}]}]}
{"op":"mcm","clk":"4289936032","pt":1632495640030,"mc":[{"id":"1.188075669","rc":[{"batb":[[0,1.81,107],[1,1.8,144.95],[2,1.79,391.89]],"ltp":1.88,"tv":17012.37,"id":9631939},{"batl":[[1,2.26,192.04]],"ltp":2.0,"tv":5268.41,"id":9454286}]}]}
{"op":"mcm","clk":"4289936128","pt":1632495641132,"mc":[{"id":"1.188075669","rc":[{"trd":[[1.84,16.3]],"batb":[[0,1.81,5]],"batl":[[0,1.86,1312.42],[1,1.87,498.98],[2,1.88,668.43]],"ltp":1.84,"tv":17028.67,"id":9631939},{"trd":[[2.18,13.76]],"ltp":2.18,"tv":5282.17,"id":9454286}],"tv":22310.84}]}
{"op":"mcm","clk":"4289936330","pt":1632495643136,"mc":[{"id":"1.188075669","rc":[{"batb":[[0,1.8,139.95],[1,1.79,391.89],[2,1.78,222.99]],"ltp":1.84,"tv":17028.67,"id":9631939},{"batb":[[2,2.08,242.01]],"batl":[[0,2.24,10.94]],"ltp":2.18,"tv":5282.17,"id":9454286}]}]}
{"op":"mcm","clk":"4289936763","pt":1632495647163,"mc":[{"id":"1.188075669","rc":[{"trd":[[2.16,20.25]],"batb":[[0,2.16,139.1]],"batl":[[0,2.24,11.41]],"ltp":2.16,"tv":5302.42,"id":9454286}],"tv":22331.09}]}
{"op":"mcm","clk":"4289936874","pt":1632495648155,"mc":[{"id":"1.188075669","rc":[{"batb":[[1,1.77,68.37],[2,1.76,35.23]],"batl":[[0,1.92,264.96],[1,1.93,311.24],[2,1.96,91.62]],"ltp":1.84,"tv":17028.67,"id":9631939},{"batb":[[1,2.08,242.01],[2,2.06,238.46]],"batl":[[0,2.3,53.09],[1,2.32,189.18],[2,2.34,171.74]],"ltp":2.16,"tv":5302.42,"id":9454286}]}]}
{"op":"mcm","clk":"4289936927","pt":1632495648681,"mc":[{"id":"1.188075669","rc":[{"batb":[[0,1.77,68.37],[1,1.75,380.65],[2,1.74,296.18]],"ltp":1.84,"tv":17028.67,"id":9631939},{"batb":[[0,2.08,242.01],[1,2.06,238.46],[2,2.04,188.8]],"ltp":2.16,"tv":5302.42,"id":9454286}]}]}
{"op":"mcm","clk":"4289936988","pt":1632495649261,"mc":[{"id":"1.188075669","rc":[{"batb":[[0,1.75,380.65],[1,1.74,296.18],[2,1.12,2.53]],"batl":[[0,1.92,204.96]],"ltp":1.84,"tv":17028.67,"id":9631939},{"batb":[[0,2.08,186.46]],"batl":[[0,2.32,189.65],[1,2.34,171.74],[2,2.72,247.76]],"ltp":2.16,"tv":5302.42,"id":9454286}]}]}
{"op":"mcm","clk":"4289937157","pt":1632495651061,"mc":[{"id":"1.188075669","rc":[{"batb":[[0,1.75,538.93],[2,1.73,218.89]],"batl":[[2,1.95,108.26]],"ltp":1.84,"tv":17028.67,"id":9631939}]}]}
{"op":"mcm","clk":"4289937280","pt":1632495652171,"mc":[{"id":"1.188075669","rc":[{"batb":[[0,1.76,151.76],[1,1.75,386.92],[2,1.74,296.18]],"ltp":1.84,"tv":17028.67,"id":9631939},{"batb":[[2,2.04,8.87]],"ltp":2.16,"tv":5302.42,"id":9454286}]}]}
{"op":"mcm","clk":"4289937338","pt":1632495652748,"mc":[{"id":"1.188075669","rc":[{"batb":[[1,1.75,391.92],[2,1.74,300.18]],"ltp":1.84,"tv":17028.67,"id":9631939}]}]}
{"op":"mcm","clk":"4289937523","pt":1632495655080,"mc":[{"id":"1.188075669","rc":[{"trd":[[1.91,0.02]],"batl":[[0,1.91,4.99],[1,1.92,204.96],[2,1.93,311.24]],"ltp":1.91,"tv":17028.69,"id":9631939},{"batb":[[0,2.1,4],[1,2.08,190.46],[2,2.06,248.04]],"ltp":2.16,"tv":5302.42,"id":9454286}],"tv":22331.11}]}
{"op":"mcm","clk":"4289937619","pt":1632495656136,"mc":[{"id":"1.188075669","rc":[{"trd":[[1.76,33.07],[1.84,16.86]],"batb":[[0,1.76,148.9]],"ltp":1.76,"tv":17034.96,"id":9631939},{"trd":[[2.18,14.23]],"batb":[[2,2.06,238.46]],"batl":[[0,2.32,189.18]],"ltp":2.18,"tv":5302.89,"id":9454286}],"tv":22337.85}]}
{"op":"mcm","clk":"4289937714","pt":1632495657567,"mc":[{"id":"1.188075669","rc":[{"batl":[[0,1.9,4],[1,1.91,4.99],[2,1.92,204.96]],"ltp":1.76,"tv":17034.96,"id":9631939},{"batb":[[0,2.12,4],[1,2.1,4],[2,2.08,190.46]],"ltp":2.18,"tv":5302.89,"id":9454286}]}]}
{"op":"mcm","clk":"4289938019","pt":1632495661156,"mc":[{"id":"1.188075669","rc":[{"trd":[[1.76,35.8],[1.89,134.9]],"batb":[[0,1.76,147.53]],"batl":[[0,1.89,3.98],[1,1.9,4],[2,1.91,4.99]],"ltp":1.89,"tv":17037.74,"id":9631939}],"tv":22340.63}]}
{"op":"mcm","clk":"4289938109","pt":1632495662201,"mc":[{"id":"1.188075669","rc":[{"batb":[[0,1.78,2.35],[1,1.76,147.53],[2,1.75,391.92]],"ltp":1.89,"tv":17037.74,"id":9631939}]}]}
{"op":"mcm","clk":"4289938170","pt":1632495662989,"mc":[{"id":"1.188075669","rc":[{"batl":[[0,1.92,204.96],[1,1.93,311.24],[2,1.95,108.26]],"ltp":1.89,"tv":17037.74,"id":9631939},{"batb":[[0,2.08,186.46],[1,2.06,238.46],[2,2.04,8.87]],"ltp":2.18,"tv":5302.89,"id":9454286}]}]}
{"op":"mcm","clk":"4289938259","pt":1632495663998,"mc":[{"id":"1.188075669","rc":[{"batl":[[0,1.88,4],[1,1.89,26.33],[2,1.92,204.96]],"ltp":1.89,"tv":17037.74,"id":9631939},{"batb":[[0,2.14,3],[1,2.08,186.46],[2,2.06,238.46]],"ltp":2.18,"tv":5302.89,"id":9454286}]}]}
{"op":"mcm","clk":"4289938341","pt":1632495665015,"mc":[{"id":"1.188075669","rc":[{"batl":[[0,1.89,26.33],[1,1.92,204.96],[2,1.93,311.24]],"ltp":1.89,"tv":17037.74,"id":9631939},{"batb":[[0,2.08,186.46],[1,2.06,238.46],[2,2.04,8.87]],"ltp":2.18,"tv":5302.89,"id":9454286}]}]}
{"op":"mcm","clk":"4289938458","pt":1632495666183,"mc":[{"id":"1.188075669","rc":[{"batb":[[1,1.77,5],[2,1.76,147.53]],"ltp":1.89,"tv":17037.74,"id":9631939},{"batb":[[1,2.06,248.04]],"ltp":2.18,"tv":5302.89,"id":9454286}]}]}
{"op":"mcm","clk":"4289938541","pt":1632495667189,"mc":[{"id":"1.188075669","rc":[{"batb":[[1,1.76,147.53],[2,1.75,391.92]],"ltp":1.89,"tv":17037.74,"id":9631939},{"batb":[[1,2.06,238.46]],"ltp":2.18,"tv":5302.89,"id":9454286}]}]}
{"op":"mcm","clk":"4289939139","pt":1632495673096,"mc":[{"id":"1.188075669","rc":[{"batb":[[0,2.12,4],[1,2.08,186.46],[2,2.06,248.04]],"ltp":2.18,"tv":5302.89,"id":9454286}]}]}
{"op":"mcm","clk":"4289939164","pt":1632495673413,"mc":[{"id":"1.188075669","rc":[{"batb":[[2,2.06,238.46]],"ltp":2.18,"tv":5302.89,"id":9454286}]}]}
{"op":"mcm","clk":"4289939470","pt":1632495676985,"mc":[{"id":"1.188075669","rc":[{"batb":[[0,2.08,186.46],[1,2.06,238.46],[2,2.04,8.87]],"ltp":2.18,"tv":5302.89,"id":9454286}]}]}
{"op":"mcm","clk":"4289939698","pt":1632495679786,"mc":[{"id":"1.188075669","rc":[{"batb":[[0,1.78,7.35]],"ltp":1.89,"tv":17037.74,"id":9631939}]}]}
{"op":"mcm","clk":"4289939974","pt":1632495683198,"mc":[{"id":"1.188075669","rc":[{"batb":[[0,1.78,5],[1,1.77,5],[2,1.76,147.53]],"ltp":1.89,"tv":17037.74,"id":9631939},{"batl":[[0,2.3,3],[1,2.32,193.18],[2,2.34,171.74]],"ltp":2.18,"tv":5302.89,"id":9454286}]}]}
{"op":"mcm","clk":"4289940051","pt":1632495684090,"mc":[{"id":"1.188075669","rc":[{"batl":[[1,2.32,4],[2,2.72,247.76]],"ltp":2.18,"tv":5302.89,"id":9454286}]}]}
{"op":"mcm","clk":"4289940209","pt":1632495686215,"mc":[{"id":"1.188075669","rc":[{"trd":[[1.89,171.79]],"batb":[[0,1.89,105.65],[1,1.88,2376.18],[2,1.87,169.83]],"batl":[[0,1.92,204.96],[1,1.93,311.24],[2,1.94,261.24]],"ltp":1.89,"tv":17074.63,"id":9631939},{"trd":[[2.12,134.18]],"batb":[[1,2.06,246.1]],"batl":[[0,2.16,442.72],[1,2.18,429.7],[2,2.2,648.62]],"ltp":2.12,"tv":5316.97,"id":9454286}],"tv":22391.6}]}
{"op":"mcm","clk":"4289940351","pt":1632495687221,"mc":[{"id":"1.188075669","rc":[{"batb":[[0,1.9,117.09],[1,1.88,188.59],[2,1.85,65.07]],"batl":[[0,1.91,15.71],[1,1.92,204.96],[2,1.93,311.24]],"ltp":1.89,"tv":17074.63,"id":9631939},{"batb":[[2,2.04,188.97]],"batl":[[1,2.18,484.93]],"ltp":2.12,"tv":5316.97,"id":9454286}]}]}
{"op":"mcm","clk":"4289940521","pt":1632495689212,"mc":[{"id":"1.188075669","rc":[{"batl":[[1,2.18,429.7]],"ltp":2.12,"tv":5316.97,"id":9454286}]}]}
{"op":"mcm","clk":"4289940584","pt":1632495689743,"mc":[{"id":"1.188075669","rc":[{"batb":[[1,1.88,383.52],[2,1.86,172.86]],"ltp":1.89,"tv":17074.63,"id":9631939}]}]}
{"op":"mcm","clk":"4289940725","pt":1632495691013,"mc":[{"id":"1.188075669","rc":[{"trd":[[2.08,199.48]],"batb":[[0,2.08,86.78]],"batl":[[0,2.16,468.75]],"ltp":2.08,"tv":5516.45,"id":9454286}],"tv":22591.09}]}
{"op":"mcm","clk":"4289940933","pt":1632495693122,"mc":[{"id":"1.188075669","rc":[{"batb":[[0,1.9,273.09]],"ltp":1.89,"tv":17074.63,"id":9631939},{"batl":[[0,2.16,524.45]],"ltp":2.08,"tv":5516.45,"id":9454286}]}]}
{"op":"mcm","clk":"4289941091","pt":1632495695059,"mc":[{"id":"1.188075669","rc":[{"trd":[[1.9,18.37]],"batb":[[0,1.9,263.91],[2,1.86,237.55]],"ltp":1.9,"tv":17093.0,"id":9631939}],"tv":22609.45}]}
{"op":"mcm","clk":"4289941179","pt":1632495696066,"mc":[{"id":"1.188075669","rc":[{"batb":[[0,1.9,408.91]],"ltp":1.9,"tv":17093.0,"id":9631939}]}]}
{"op":"mcm","clk":"4289941202","pt":1632495696226,"mc":[{"id":"1.188075669","rc":[{"batb":[[1,2.06,238.46]],"ltp":2.08,"tv":5516.45,"id":9454286}]}]}
{"op":"mcm","clk":"4289941375","pt":1632495698141,"mc":[{"id":"1.188075669","rc":[{"batb":[[1,1.88,194.93]],"ltp":1.9,"tv":17093.0,"id":9631939}]}]}
{"op":"mcm","clk":"4289941463","pt":1632495699150,"mc":[{"id":"1.188075669","rc":[{"trd":[[1.9,23.06]],"batb":[[0,1.9,406.56]],"batl":[[1,1.92,217.88]],"ltp":1.9,"tv":17097.69,"id":9631939},{"batl":[[0,2.16,537.94]],"ltp":2.08,"tv":5516.45,"id":9454286}],"tv":22614.14}]}
{"op":"mcm","clk":"4289941806","pt":1632495703143,"mc":[{"id":"1.188075669","rc":[{"batl":[[0,1.92,217.88],[1,1.93,311.24],[2,1.94,261.24]],"ltp":1.9,"tv":17097.69,"id":9631939},{"batl":[[0,2.16,95.22],[1,2.2,218.92],[2,2.24,174.79]],"ltp":2.08,"tv":5516.45,"id":9454286}]}]}
{"op":"mcm","clk":"4289941895","pt":1632495704153,"mc":[{"id":"1.188075669","rc":[{"trd":[[1.9,63.06]],"batb":[[0,1.86,64.69],[1,1.84,4],[2,1.82,134.13]],"batl":[[0,2.08,199.31],[1,2.1,227.37],[2,2.12,8.71]],"ltp":1.9,"tv":17137.69,"id":9631939},{"batb":[[0,1.93,252.29],[1,1.92,225.31],[2,1.91,83.39]],"batl":[[0,2.16,55.7],[1,2.24,174.79],[2,2.26,221.27]],"ltp":2.08,"tv":5516.45,"id":9454286}],"tv":22654.14}]}
{"op":"mcm","clk":"4289942067","pt":1632495706067,"mc":[{"id":"1.188075669","rc":[{"batb":[[0,1.84,4],[1,1.83,5]],"ltp":1.9,"tv":17137.69,"id":9631939},{"batl":[[0,2.24,174.79],[1,2.26,221.27],[2,2.28,3]],"ltp":2.08,"tv":5516.45,"id":9454286}]}]}
{"op":"mcm","clk":"4289942183","pt":1632495707179,"mc":[{"id":"1.188075669","rc":[{"batl":[[0,1.9,2.48],[1,2.06,8.75],[2,2.08,203.31]],"ltp":1.9,"tv":17137.69,"id":9631939},{"batb":[[0,1.95,89.71],[1,1.94,4],[2,1.93,256.29]],"ltp":2.08,"tv":5516.45,"id":9454286}]}]}
{"op":"mcm","clk":"4289942272","pt":1632495708077,"mc":[{"id":"1.188075669","rc":[{"batl":[[0,1.9,2.58],[1,2.08,203.31],[2,2.1,227.37]],"ltp":1.9,"tv":17137.69,"id":9631939},{"batb":[[0,1.94,4],[1,1.93,256.29],[2,1.92,229.31]],"ltp":2.08,"tv":5516.45,"id":9454286}]}]}
{"op":"mcm","clk":"4289942371","pt":1632495709181,"mc":[{"id":"1.188075669","rc":[{"batl":[[0,2.08,203.42],[1,2.1,227.37],[2,2.12,151.82]],"ltp":1.9,"tv":17137.69,"id":9631939}]}]}
{"op":"mcm","clk":"4289942456","pt":1632495710175,"mc":[{"id":"1.188075669","rc":[{"batl":[[0,2.08,203.31]],"ltp":1.9,"tv":17137.69,"id":9631939}]}]}
{"op":"mcm","clk":"4289942845","pt":1632495714049,"mc":[{"id":"1.188075669","rc":[{"batl":[[0,2.06,8.75],[1,2.08,4],[2,2.12,8.71]],"ltp":1.9,"tv":17137.69,"id":9631939},{"batb":[[0,1.95,86.11],[1,1.94,4],[2,1.93,4]],"ltp":2.08,"tv":5516.45,"id":9454286}]}]}
{"op":"mcm","clk":"4289942891","pt":1632495714579,"mc":[{"id":"1.188075669","rc":[{"batb":[[0,1.82,134.13],[1,1.81,360.04],[2,1.8,236.13]],"batl":[[0,2.08,4],[1,2.12,8.71],[2,990,0.01]],"ltp":1.9,"tv":17137.69,"id":9631939},{"batb":[[0,1.94,4],[1,1.93,4],[2,1.92,4]],"batl":[[2,2.6,264.15]],"ltp":2.08,"tv":5516.45,"id":9454286}]}]}
{"op":"mcm","clk":"4289943007","pt":1632495716154,"mc":[{"id":"1.188075669","rc":[{"batl":[[0,1.85,16.22],[1,1.86,268.87],[2,1.87,1730.36]],"ltp":1.9,"tv":17137.69,"id":9631939},{"batb":[[0,2.14,28.82],[1,1.94,4],[2,1.93,4]],"batl":[[0,2.24,181.46]],"ltp":2.08,"tv":5516.45,"id":9454286}]}]}
{"op":"mcm","clk":"4289943112","pt":1632495717157,"mc":[{"id":"1.188075669","rc":[{"batl":[[2,1.87,345.35]],"ltp":1.9,"tv":17137.69,"id":9631939},{"batb":[[0,2.14,184.71],[1,2.06,56.6],[2,2,190.22]],"batl":[[1,2.26,274.72],[2,2.4,12.67]],"ltp":2.08,"tv":5516.45,"id":9454286}]}]}
{"op":"mcm","clk":"4289943262","pt":1632495718892,"mc":[{"id":"1.188075669","rc":[{"trd":[[1.82,241.83]],"batb":[[0,1.82,34.21]],"ltp":1.82,"tv":17337.61,"id":9631939}],"tv":22854.06}]}
{"op":"mcm","clk":"4289943371","pt":1632495720172,"mc":[{"id":"1.188075669","rc":[{"trd":[[1.82,281.82]],"batb":[[0,1.82,14.22]],"ltp":1.82,"tv":17377.59,"id":9631939}],"tv":22894.05}]}
{"op":"mcm","clk":"4289943542","pt":1632495721858,"mc":[{"id":"1.188075669","rc":[{"trd":[[1.82,291.81]],"batb":[[0,1.82,9.23]],"ltp":1.82,"tv":17387.59,"id":9631939},{"batb":[[0,2.14,207.7]],"ltp":2.08,"tv":5516.45,"id":9454286}],"tv":22904.04}]}
{"op":"mcm","clk":"4289943701","pt":1632495723397,"mc":[{"id":"1.188075669","rc":[{"batb":[[0,1.82,102.23]],"ltp":1.82,"tv":17387.59,"id":9631939},{"batb":[[1,2.06,273.32],[2,2.04,207.72]],"batl":[[2,2.32,197.46]],"ltp":2.08,"tv":5516.45,"id":9454286}]}]}
{"op":"mcm","clk":"4289944037","pt":1632495727095,"mc":[{"id":"1.188075669","rc":[{"trd":[[1.82,292]],"batb":[[0,1.82,161.13]],"ltp":1.82,"tv":17387.77,"id":9631939}],"tv":22904.23}]}
{"op":"mcm","clk":"4289944121","pt":1632495728095,"mc":[{"id":"1.188075669","rc":[{"batl":[[2,1.87,215.92]],"ltp":1.82,"tv":17387.77,"id":9631939}]}]}
{"op":"mcm","clk":"4289944264","pt":1632495729781,"mc":[{"id":"1.188075669","rc":[{"trd":[[1.85,105.94]],"batl":[[0,1.85,13.35]],"ltp":1.85,"tv":17393.52,"id":9631939}],"tv":22909.97}]}
{"op":"mcm","clk":"4289944657","pt":1632495734080,"mc":[{"id":"1.188075669","rc":[{"batb":[[0,1.79,67.5],[1,1.77,148.04],[2,1.76,233.35]],"batl":[[0,1.93,87.5],[1,1.95,208.97],[2,1.96,338.43]],"ltp":1.85,"tv":17393.52,"id":9631939},{"batb":[[0,2.06,263.74],[1,2.04,207.72],[2,2,190.22]],"batl":[[0,2.26,53.45],[1,2.32,197.46],[2,2.34,161.06]],"ltp":2.08,"tv":5516.45,"id":9454286}]}]}
{"op":"mcm","clk":"4289944743","pt":1632495735179,"mc":[{"id":"1.188075669","rc":[{"batb":[[0,1.77,148.04],[1,1.76,233.35],[2,1.75,220.01]],"batl":[[0,1.95,208.97],[1,1.96,338.43],[2,2.06,5]],"ltp":1.85,"tv":17393.52,"id":9631939},{"batb":[[0,2.06,207.14]],"batl":[[0,2.32,197.46],[1,2.34,161.06],[2,2.6,264.15]],"ltp":2.08,"tv":5516.45,"id":9454286}]}]}
{"op":"mcm","clk":"4289944888","pt":1632495737224,"mc":[{"id":"1.188075669","rc":[{"batb":[[0,1.76,520.93],[1,1.75,220.01],[2,1.74,214.61]],"batl":[[0,1.92,5],[1,1.95,208.97],[2,1.96,338.43]],"ltp":1.85,"tv":17393.52,"id":9631939},{"batb":[[0,2.08,4],[1,2.06,218.72],[2,2.04,207.72]],"ltp":2.08,"tv":5516.45,"id":9454286}]}]}
{"op":"mcm","clk":"4289944947","pt":1632495737909,"mc":[{"id":"1.188075669","rc":[{"batl":[[0,1.95,212.97],[1,1.96,338.43],[2,1.99,138.31]],"ltp":1.85,"tv":17393.52,"id":9631939},{"batb":[[0,2.06,210.14],[1,2.04,211.72],[2,2,186.93]],"ltp":2.08,"tv":5516.45,"id":9454286}]}]}
{"op":"mcm","clk":"4289945034","pt":1632495739019,"mc":[{"id":"1.188075669","rc":[{"batb":[[0,1.76,383.84],[2,1.12,2.53]],"batl":[[2,2.06,5]],"ltp":1.85,"tv":17393.52,"id":9631939}]}]}
{"op":"mcm","clk":"4289945069","pt":1632495739380,"mc":[{"id":"1.188075669","rc":[{"batb":[[0,1.85,2.5],[1,1.76,383.84],[2,1.75,220.01]],"ltp":1.85,"tv":17393.52,"id":9631939}]}]}
{"op":"mcm","clk":"4289945206","pt":1632495741117,"mc":[{"id":"1.188075669","rc":[{"batb":[[1,1.76,387.84],[2,1.75,225.01]],"batl":[[0,1.93,94.5],[1,1.95,212.97],[2,1.96,338.43]],"ltp":1.85,"tv":17393.52,"id":9631939}]}]}
{"op":"mcm","clk":"4289945278","pt":1632495741906,"mc":[{"id":"1.188075669","rc":[{"batb":[[0,1.84,19.72],[1,1.83,168.02],[2,1.81,188.57]],"batl":[[0,1.86,18.25],[1,1.9,179.84],[2,1.92,158.91]],"ltp":1.85,"tv":17393.52,"id":9631939},{"batl":[[0,2.2,17.88],[1,2.32,197.46],[2,2.34,161.06]],"ltp":2.08,"tv":5516.45,"id":9454286}]}]}
{"op":"mcm","clk":"4289945311","pt":1632495742327,"mc":[{"id":"1.188075669","rc":[{"batb":[[0,1.83,168.02],[1,1.81,188.57],[2,1.76,387.84]],"batl":[[0,1.9,179.84],[1,1.92,158.91],[2,1.95,212.97]],"ltp":1.85,"tv":17393.52,"id":9631939},{"batl":[[0,2.32,197.46],[1,2.34,161.06],[2,2.6,264.15]],"ltp":2.08,"tv":5516.45,"id":9454286}]}]}
{"op":"mcm","clk":"4289945488","pt":1632495744119,"mc":[{"id":"1.188075669","rc":[{"batb":[[0,2.08,39.56],[1,2.06,218.72],[2,2.04,211.72]],"batl":[[0,2.3,44.75],[1,2.32,197.46],[2,2.34,161.06]],"ltp":2.08,"tv":5516.45,"id":9454286}]}]}
{"op":"mcm","clk":"4289945572","pt":1632495745221,"mc":[{"id":"1.188075669","rc":[{"batb":[[0,1.76,387.84],[1,1.75,225.01],[2,1.12,2.53]],"batl":[[0,1.95,212.97],[1,1.96,338.43],[2,2.06,5]],"ltp":1.85,"tv":17393.52,"id":9631939},{"batb":[[0,2.06,210.14],[1,2.04,211.72],[2,2,186.93]],"batl":[[0,2.32,197.46],[1,2.34,161.06],[2,2.6,264.15]],"ltp":2.08,"tv":5516.45,"id":9454286}]}]}
{"op":"mcm","clk":"4289945753","pt":1632495747214,"mc":[{"id":"1.188075669","rc":[{"batl":[[0,1.9,50.24],[1,1.95,212.97],[2,1.96,338.43]],"ltp":1.85,"tv":17393.52,"id":9631939}]}]}
{"op":"mcm","clk":"4289945801","pt":1632495747794,"mc":[{"id":"1.188075669","rc":[{"batb":[[0,1.76,524.93],[2,1.74,214.61]],"batl":[[0,1.95,212.97],[1,1.96,338.43],[2,1.99,138.31]],"ltp":1.85,"tv":17393.52,"id":9631939}]}]}
{"op":"mcm","clk":"4289945924","pt":1632495749223,"mc":[{"id":"1.188075669","rc":[{"batb":[[0,1.76,154.49],[1,1.75,5],[2,1.12,2.53]],"ltp":1.85,"tv":17393.52,"id":9631939},{"batb":[[1,2.04,207.72]],"batl":[[0,2.6,264.15],[1,990,0.01],[2,2.6,0]],"ltp":2.08,"tv":5516.45,"id":9454286}]}]}
{"op":"mcm","clk":"4289946067","pt":1632495751127,"mc":[{"id":"1.188075669","rc":[{"batb":[[0,1.78,17.16],[1,1.76,154.49],[2,1.75,5]],"batl":[[0,1.83,3.16],[1,1.95,208.97],[2,1.96,338.43]],"ltp":1.85,"tv":17393.52,"id":9631939},{"batb":[[0,2.06,217.22]],"batl":[[0,2.3,3.55],[1,2.6,264.15],[2,990,0.01]],"ltp":2.08,"tv":5516.45,"id":9454286}]}]}
{"op":"mcm","clk":"4289946167","pt":1632495752131,"mc":[{"id":"1.188075669","rc":[{"trd":[[1.83,3.16]],"batb":[[0,1.92,140],[1,1.9,1419.84],[2,1.89,488.48]],"batl":[[0,1.93,90.5],[1,1.96,351.96],[2,1.98,255.28]],"ltp":1.83,"tv":17396.68,"id":9631939},{"trd":[[2.2,2.63]],"batb":[[0,2.04,207.72],[1,2,186.93],[2,1.98,482.96]],"batl":[[0,2.12,15.84],[1,2.16,257.08],[2,2.28,177.49]],"ltp":2.2,"tv":5519.08,"id":9454286}],"tv":22915.76}]}
{"op":"mcm","clk":"4289946247","pt":1632495753029,"mc":[{"id":"1.188075669","rc":[{"batb":[[0,1.93,112.87],[1,1.92,140],[2,1.9,664.9]],"batl":[[0,1.94,15.46]],"ltp":1.83,"tv":17396.68,"id":9631939},{"batl":[[2,2.28,13.16]],"ltp":2.2,"tv":5519.08,"id":9454286}]}]}
{"op":"mcm","clk":"4289946329","pt":1632495753925,"mc":[{"id":"1.188075669","rc":[{"batb":[[1,2,189.93],[2,1.99,4]],"batl":[[2,2.28,17.16]],"ltp":2.2,"tv":5519.08,"id":9454286}]}]}
{"op":"mcm","clk":"4289946393","pt":1632495754552,"mc":[{"id":"1.188075669","rc":[{"batl":[[2,2.2,2]],"ltp":2.2,"tv":5519.08,"id":9454286}]}]}
{"op":"mcm","clk":"4289946659","pt":1632495757150,"mc":[{"id":"1.188075669","rc":[{"trd":[[1.94,22.38]],"batb":[[0,1.93,254.87]],"batl":[[0,1.96,351.96],[1,1.98,255.28],[2,1.99,138.31]],"ltp":1.94,"tv":17412.14,"id":9631939},{"trd":[[2.06,21.51]],"ltp":2.06,"tv":5533.64,"id":9454286}],"tv":22945.78}]}
{"op":"mcm","clk":"4289946794","pt":1632495759096,"mc":[{"id":"1.188075669","rc":[{"batl":[[0,2.06,22.72],[1,2.12,15.84],[2,2.16,257.08]],"ltp":2.06,"tv":5533.64,"id":9454286}]}]}
{"op":"mcm","clk":"4289946960","pt":1632495760936,"mc":[{"id":"1.188075669","rc":[{"batb":[[2,1.9,728.14]],"ltp":1.94,"tv":17412.14,"id":9631939},{"batl":[[1,2.12,72.53]],"ltp":2.06,"tv":5533.64,"id":9454286}]}]}
{"op":"mcm","clk":"4289947121","pt":1632495763139,"mc":[{"id":"1.188075669","rc":[{"trd":[[1.94,22.47]],"ltp":1.94,"tv":17412.23,"id":9631939},{"trd":[[2.06,21.6]],"batl":[[0,2.06,22.63]],"ltp":2.06,"tv":5533.73,"id":9454286}],"tv":22945.97}]}
{"op":"mcm","clk":"4289947181","pt":1632495764139,"mc":[{"id":"1.188075669","rc":[{"batb":[[0,1.93,336.87]],"ltp":1.94,"tv":17412.23,"id":9631939}]}]}
{"op":"mcm","clk":"4289947347","pt":1632495766154,"mc":[{"id":"1.188075669","rc":[{"trd":[[2.06,25.6]],"batb":[[2,1.98,482.96]],"batl":[[0,2.06,20.63]],"ltp":2.06,"tv":5537.73,"id":9454286}],"tv":22949.97}]}
{"op":"mcm","clk":"4289947429","pt":1632495767257,"mc":[{"id":"1.188075669","rc":[{"trd":[[1.94,25.99]],"ltp":1.94,"tv":17415.75,"id":9631939},{"trd":[[2.06,28.92]],"batl":[[0,2.06,17.31]],"ltp":2.06,"tv":5541.05,"id":9454286}],"tv":22956.8}]}
{"op":"mcm","clk":"4289947589","pt":1632495769151,"mc":[{"id":"1.188075669","rc":[{"batb":[[2,1.99,3]],"ltp":2.06,"tv":5541.05,"id":9454286}]}]}
{"op":"mcm","clk":"4289947872","pt":1632495772726,"mc":[{"id":"1.188075669","rc":[{"batl":[[0,2.12,72.53],[1,2.16,257.08],[2,2.2,2]],"ltp":2.06,"tv":5541.05,"id":9454286}]}]}
{"op":"mcm","clk":"4289947976","pt":1632495774165,"mc":[{"id":"1.188075669","rc":[{"batb":[[0,1.93,224],[1,1.9,63.24],[2,1.83,133.2]],"batl":[[0,2.18,150.68],[1,2.2,161.7],[2,2.24,8.23]],"ltp":1.94,"tv":17415.75,"id":9631939},{"batb":[[0,1.85,267.04],[1,1.84,239.79],[2,1.83,125.44]],"batl":[[0,2.12,56.69],[1,2.22,189.63],[2,2.24,176.13]],"ltp":2.06,"tv":5541.05,"id":9454286}]}]}
{"op":"mcm","clk":"4289948060","pt":1632495775157,"mc":[{"id":"1.188075669","rc":[{"batb":[[0,1.9,63.24],[1,1.83,133.2],[2,1.82,210.93]],"ltp":1.94,"tv":17415.75,"id":9631939}]}]}
{"op":"mcm","clk":"4289948136","pt":1632495775953,"mc":[{"id":"1.188075669","rc":[{"batb":[[0,1.83,133.2],[1,1.82,210.93],[2,1.81,209.12]],"ltp":1.94,"tv":17415.75,"id":9631939},{"batl":[[0,2.04,17.48]],"ltp":2.06,"tv":5541.05,"id":9454286}]}]}
{"op":"mcm","clk":"4289948205","pt":1632495777166,"mc":[{"id":"1.188075669","rc":[{"trd":[[1.96,51.25]],"batb":[[1,1.82,344.51]],"batl":[[0,2.08,57.73],[1,2.18,150.68],[2,2.2,161.7]],"ltp":1.96,"tv":17418.09,"id":9631939},{"trd":[[2.04,17.92]],"batl":[[0,2.04,15.22]],"ltp":2.04,"tv":5543.31,"id":9454286}],"tv":22961.41}]}
{"op":"mcm","clk":"4289948275","pt":1632495778058,"mc":[{"id":"1.188075669","rc":[{"batb":[[0,1.99,1.96],[1,1.83,133.2],[2,1.82,344.51]],"batl":[[0,2.18,11.75],[1,2.24,8.23],[2,2.26,7.25]],"ltp":1.96,"tv":17418.09,"id":9631939},{"batb":[[0,1.85,96.57],[1,1.84,5]],"ltp":2.04,"tv":5543.31,"id":9454286}]}]}
{"op":"mcm","clk":"4289948296","pt":1632495778371,"mc":[{"id":"1.188075669","rc":[{"batl":[[0,2.18,4]],"ltp":1.96,"tv":17418.09,"id":9631939},{"batb":[[0,1.85,5]],"ltp":2.04,"tv":5543.31,"id":9454286}]}]}
{"op":"mcm","clk":"4289948565","pt":1632495781175,"mc":[{"id":"1.188075669","rc":[{"trd":[[1.96,67.09],[1.99,3.92]],"batb":[[0,1.83,133.2],[1,1.82,344.51],[2,1.81,209.12]],"batl":[[0,1.85,16.22],[1,1.86,15.67],[2,1.87,101.5]],"ltp":1.96,"tv":17437.85,"id":9631939},{"trd":[[2.04,33.14]],"batb":[[0,2.14,29.82],[1,2.04,15.12],[2,1.85,5]],"batl":[[0,2.22,189.63],[1,2.24,186.92],[2,2.28,419.4]],"ltp":2.04,"tv":5558.53,"id":9454286}],"tv":22996.39}]}
{"op":"mcm","clk":"4289948682","pt":1632495782168,"mc":[{"id":"1.188075669","rc":[{"batb":[[1,2.12,157.32],[2,2.04,140.45]],"ltp":2.04,"tv":5558.53,"id":9454286}]}]}
{"op":"mcm","clk":"4289948762","pt":1632495783169,"mc":[{"id":"1.188075669","rc":[{"batb":[[2,1.99,193.01]],"ltp":2.04,"tv":5558.53,"id":9454286}]}]}
{"op":"mcm","clk":"4289948846","pt":1632495783979,"mc":[{"id":"1.188075669","rc":[{"batb":[[2,2.04,57.69]],"batl":[[2,2.26,53.45]],"ltp":2.04,"tv":5558.53,"id":9454286}]}]}
{"op":"mcm","clk":"4289948872","pt":1632495784262,"mc":[{"id":"1.188075669","rc":[{"batb":[[2,2.1,4]],"ltp":2.04,"tv":5558.53,"id":9454286}]}]}
{"op":"mcm","clk":"4289949401","pt":1632495790178,"mc":[{"id":"1.188075669","rc":[{"trd":[[1.85,106.19]],"batl":[[0,1.85,16.09]],"ltp":1.85,"tv":17438.11,"id":9631939}],"tv":22996.65}]}
{"op":"mcm","clk":"4289949830","pt":1632495795766,"mc":[{"id":"1.188075669","rc":[{"trd":[[1.83,7.85]],"batb":[[0,1.83,130.85]],"ltp":1.83,"tv":17442.8,"id":9631939}],"tv":23001.34}]}
{"op":"mcm","clk":"4289950035","pt":1632495798094,"mc":[{"id":"1.188075669","rc":[{"batb":[[0,1.79,67.5],[1,1.77,148.47],[2,1.76,212.4]],"batl":[[0,1.85,2.92],[1,1.96,80.71],[2,1.97,164.56]],"ltp":1.83,"tv":17442.8,"id":9631939},{"batb":[[0,2.1,4],[1,2.04,67.77],[2,2.02,186.1]],"batl":[[0,2.26,53.51],[1,2.3,195.99],[2,2.32,223.19]],"ltp":2.04,"tv":5558.53,"id":9454286}]}]}
{"op":"mcm","clk":"4289950065","pt":1632495798407,"mc":[{"id":"1.188075669","rc":[{"batb":[[0,2.04,67.77],[1,2.02,186.1],[2,2,245.9]],"ltp":2.04,"tv":5558.53,"id":9454286}]}]}
{"op":"mcm","clk":"4289950173","pt":1632495799509,"mc":[{"id":"1.188075669","rc":[{"trd":[[1.85,110.88]],"batb":[[0,1.77,148.47],[1,1.76,212.4],[2,1.75,283.54]],"batl":[[0,1.96,81.29],[1,1.97,164.56],[2,1.98,226.85]],"ltp":1.85,"tv":17447.49,"id":9631939},{"batb":[[0,2.04,10.08]],"batl":[[0,2.3,196.04],[1,2.32,223.19],[2,2.6,264.15]],"ltp":2.04,"tv":5558.53,"id":9454286}],"tv":23006.03}]}
{"op":"mcm","clk":"4289950330","pt":1632495801206,"mc":[{"id":"1.188075669","rc":[{"batb":[[1,1.76,354.61]],"ltp":1.85,"tv":17447.49,"id":9631939},{"batl":[[0,2.3,195.99]],"ltp":2.04,"tv":5558.53,"id":9454286}]}]}
{"op":"mcm","clk":"4289950464","pt":1632495802496,"mc":[{"id":"1.188075669","rc":[{"batb":[[0,1.77,151.47],[1,1.76,357.61]],"ltp":1.85,"tv":17447.49,"id":9631939},{"batl":[[0,2.3,198.99]],"ltp":2.04,"tv":5558.53,"id":9454286}]}]}
{"op":"mcm","clk":"4289950669","pt":1632495804809,"mc":[{"id":"1.188075669","rc":[{"batl":[[0,1.92,4.58],[1,1.96,80.71],[2,1.97,164.56]],"ltp":1.85,"tv":17447.49,"id":9631939},{"batb":[[0,2.06,4],[1,2.04,12.37],[2,2.02,186.1]],"ltp":2.04,"tv":5558.53,"id":9454286}]}]}
{"op":"mcm","clk":"4289950745","pt":1632495805702,"mc":[{"id":"1.188075669","rc":[{"batl":[[1,1.95,5.09],[2,1.96,80.62]],"ltp":1.85,"tv":17447.49,"id":9631939}]}]}
{"op":"mcm","clk":"4289950952","pt":1632495808013,"mc":[{"id":"1.188075669","rc":[{"batl":[[0,1.91,4.58],[1,1.92,4],[2,1.94,5.09]],"ltp":1.85,"tv":17447.49,"id":9631939},{"batb":[[0,2.26,1.71],[1,2.1,4],[2,2.06,13.08]],"ltp":2.04,"tv":5558.53,"id":9454286}]}]}
{"op":"mcm","clk":"4289951030","pt":1632495808908,"mc":[{"id":"1.188075669","rc":[{"batl":[[2,1.93,94.5]],"ltp":1.85,"tv":17447.49,"id":9631939},{"batb":[[2,2.06,4]],"ltp":2.04,"tv":5558.53,"id":9454286}]}]}
{"op":"mcm","clk":"4289951057","pt":1632495809332,"mc":[{"id":"1.188075669","rc":[{"batl":[[2,1.94,5.09]],"ltp":1.85,"tv":17447.49,"id":9631939}]}]}
{"op":"mcm","clk":"4289951437","pt":1632495813714,"mc":[{"id":"1.188075669","rc":[{"batb":[[0,2.1,4],[1,2.06,4],[2,2.04,12.37]],"ltp":2.04,"tv":5558.53,"id":9454286}]}]}
{"op":"mcm","clk":"4289951562","pt":1632495815124,"mc":[{"id":"1.188075669","rc":[{"batb":[[1,2.08,4],[2,2.06,13.08]],"ltp":2.04,"tv":5558.53,"id":9454286}]}]}
{"op":"mcm","clk":"4289951649","pt":1632495816140,"mc":[{"id":"1.188075669","rc":[{"batb":[[1,1.76,354.61]],"batl":[[0,1.93,88.08],[1,1.96,80.71],[2,1.97,164.56]],"ltp":1.85,"tv":17447.49,"id":9631939},{"batb":[[0,2.04,8.37],[1,2.02,186.1],[2,2,245.9]],"ltp":2.04,"tv":5558.53,"id":9454286}]}]}
{"op":"mcm","clk":"4289951720","pt":1632495816822,"mc":[{"id":"1.188075669","rc":[{"batl":[[0,1.96,81.29],[1,1.97,164.56],[2,1.98,226.85]],"ltp":1.85,"tv":17447.49,"id":9631939},{"trd":[[2.3,5.52]],"batl":[[0,2.3,197.28]],"ltp":2.3,"tv":5561.95,"id":9454286}],"tv":23009.45}]}
{"op":"mcm","clk":"4289951891","pt":1632495818822,"mc":[{"id":"1.188075669","rc":[{"batb":[[1,1.76,358.61]],"ltp":1.85,"tv":17447.49,"id":9631939}]}]}
{"op":"mcm","clk":"4289951987","pt":1632495820132,"mc":[{"id":"1.188075669","rc":[{"batl":[[0,2.3,197.33]],"ltp":2.3,"tv":5561.95,"id":9454286}]}]}
{"op":"mcm","clk":"4289952142","pt":1632495822032,"mc":[{"id":"1.188075669","rc":[{"batb":[[0,2.06,9.58],[1,2.04,8.37],[2,2.02,186.1]],"ltp":2.3,"tv":5561.95,"id":9454286}]}]}
{"op":"mcm","clk":"4289952169","pt":1632495822348,"mc":[{"id":"1.188075669","rc":[{"batb":[[0,2.04,8.37],[1,2.02,186.1],[2,2,245.9]],"ltp":2.3,"tv":5561.95,"id":9454286}]}]}
{"op":"mcm","clk":"4289952713","pt":1632495829148,"mc":[{"id":"1.188075669","rc":[{"batb":[[0,2.06,9.08],[1,2.04,8.37],[2,2.02,186.1]],"ltp":2.3,"tv":5561.95,"id":9454286}]}]}
{"op":"mcm","clk":"4289952769","pt":1632495829983,"mc":[{"id":"1.188075669","rc":[{"batb":[[1,1.76,4],[2,1.12,2.53]],"ltp":1.85,"tv":17447.49,"id":9631939},{"batb":[[0,2.04,8.37],[1,2.02,186.1],[2,2,245.9]],"batl":[[0,2.3,3.06],[1,2.6,264.15],[2,990,0.01]],"ltp":2.3,"tv":5561.95,"id":9454286}]}]}
{"op":"mcm","clk":"4289952823","pt":1632495830558,"mc":[{"id":"1.188075669","rc":[{"batb":[[1,1.12,2.53],[2,1.11,2.86]],"ltp":1.85,"tv":17447.49,"id":9631939}]}]}
{"op":"mcm","clk":"4289952926","pt":1632495831666,"mc":[{"id":"1.188075669","rc":[{"batl":[[1,990,0.18],[2,990,0]],"ltp":2.3,"tv":5561.95,"id":9454286}]}]}
{"op":"mcm","clk":"4289953051","pt":1632495833150,"mc":[{"id":"1.188075669","rc":[{"trd":[[1.85,112.04],[1.94,26.18]],"batb":[[0,1.94,129.87],[1,1.93,2248.16],[2,1.92,654.47]],"batl":[[0,1.96,80.62],[1,1.98,239.9],[2,2.02,574.34]],"ltp":1.94,"tv":17448.83,"id":9631939},{"batl":[[0,2.08,10.19],[1,2.16,389.96],[2,2.26,13.33]],"ltp":2.3,"tv":5561.95,"id":9454286}],"tv":23010.79}]}
{"op":"mcm","clk":"4289953122","pt":1632495834151,"mc":[{"id":"1.188075669","rc":[{"trd":[[1.95,75.11]],"batb":[[0,1.95,94.13],[1,1.94,129.87],[2,1.93,178.47]],"ltp":1.95,"tv":17479.58,"id":9631939},{"batl":[[1,2.12,56.69],[2,2.16,389.96]],"ltp":2.3,"tv":5561.95,"id":9454286}],"tv":23041.54}]}
{"op":"mcm","clk":"4289953524","pt":1632495838153,"mc":[{"id":"1.188075669","rc":[{"trd":[[1.96,139.19]],"batb":[[0,1.95,245.13]],"batl":[[0,1.96,8.52]],"ltp":1.96,"tv":17551.68,"id":9631939},{"trd":[[2.04,119.15]],"batb":[[0,2.02,186.1],[1,2,245.9],[2,1.99,193.01]],"batl":[[1,2.16,389.96],[2,2.24,109.84]],"ltp":2.04,"tv":5647.96,"id":9454286}],"tv":23199.65}]}
{"op":"mcm","clk":"4289953574","pt":1632495839088,"mc":[{"id":"1.188075669","rc":[{"batl":[[2,2.26,13.33]],"ltp":2.04,"tv":5647.96,"id":9454286}]}]}
{"op":"mcm","clk":"4289953634","pt":1632495839976,"mc":[{"id":"1.188075669","rc":[{"batl":[[2,2.18,153.46]],"ltp":2.04,"tv":5647.96,"id":9454286}]}]}
{"op":"mcm","clk":"4289953719","pt":1632495841089,"mc":[{"id":"1.188075669","rc":[{"trd":[[1.96,155.09]],"batl":[[0,1.98,240.47],[1,2.02,574.34],[2,2.04,132.74]],"ltp":1.96,"tv":17567.58,"id":9631939},{"batl":[[1,2.1,57.2],[2,2.16,389.96]],"ltp":2.04,"tv":5647.96,"id":9454286}],"tv":23215.55}]}
{"op":"mcm","clk":"4289953823","pt":1632495842193,"mc":[{"id":"1.188075669","rc":[{"trd":[[1.95,229.12]],"batb":[[0,1.95,168.11]],"ltp":1.95,"tv":17721.59,"id":9631939}],"tv":23369.56}]}
{"op":"mcm","clk":"4289953969","pt":1632495844179,"mc":[{"id":"1.188075669","rc":[{"trd":[[1.95,233.81]],"batb":[[0,1.95,165.76]],"ltp":1.95,"tv":17726.28,"id":9631939}],"tv":23374.25}]}
{"op":"mcm","clk":"4289954044","pt":1632495845186,"mc":[{"id":"1.188075669","rc":[{"trd":[[1.95,404.98]],"batb":[[0,1.95,80.13],[2,1.92,654.47]],"ltp":1.95,"tv":17897.45,"id":9631939}],"tv":23545.42}]}
{"op":"mcm","clk":"4289954497","pt":1632495851093,"mc":[{"id":"1.188075669","rc":[{"trd":[[1.95,565.25]],"batb":[[0,1.94,129.87],[1,1.92,654.47],[2,1.91,546.29]],"batl":[[0,1.95,78.85],[1,1.98,240.47],[2,2.02,574.34]],"ltp":1.95,"tv":18057.72,"id":9631939}],"tv":23705.69}]}
{"op":"mcm","clk":"4289954674","pt":1632495853112,"mc":[{"id":"1.188075669","rc":[{"trd":[[1.95,720.99]],"batl":[[0,1.96,1.55],[1,1.98,239.9]],"ltp":1.95,"tv":18213.46,"id":9631939}],"tv":23861.43}]}
{"op":"mcm","clk":"4289954973","pt":1632495857101,"mc":[{"id":"1.188075669","rc":[{"batb":[[0,1.94,240.87]],"ltp":1.95,"tv":18213.46,"id":9631939}]}]}
{"op":"mcm","clk":"4289955156","pt":1632495859093,"mc":[{"id":"1.188075669","rc":[{"batb":[[0,1.94,111],[1,1.91,62.89],[2,1.84,350.11]],"batl":[[1,2.16,3.97],[2,2.18,9.25]],"ltp":1.95,"tv":18213.46,"id":9631939},{"batb":[[0,1.99,193.01],[1,1.98,4],[2,1.97,4]],"batl":[[0,2.1,57.2],[1,2.18,153.46],[2,2.2,170.78]],"ltp":2.04,"tv":5647.96,"id":9454286}]}]}
{"op":"mcm","clk":"4289955243","pt":1632495860086,"mc":[{"id":"1.188075669","rc":[{"batb":[[0,1.91,62.89],[1,1.84,350.11],[2,1.83,195.81]],"batl":[[0,2.18,4.98],[1,2.2,162.2],[2,2.22,194.01]],"ltp":1.95,"tv":18213.46,"id":9631939},{"batb":[[0,1.83,226.52],[1,1.82,251.98],[2,1.81,214.78]],"ltp":2.04,"tv":5647.96,"id":9454286}]}]}
{"op":"mcm","clk":"4289955253","pt":1632495860298,"mc":[{"id":"1.188075669","rc":[{"batb":[[0,1.84,350.11],[1,1.83,195.81],[2,1.8,14.48]],"ltp":1.95,"tv":18213.46,"id":9631939},{"batl":[[0,2.18,153.46],[1,2.2,170.78],[2,2.26,3.31]],"ltp":2.04,"tv":5647.96,"id":9454286}]}]}
{"op":"mcm","clk":"4289955429","pt":1632495862128,"mc":[{"id":"1.188075669","rc":[{"batb":[[1,1.83,380.04],[2,1.81,188.58]],"ltp":1.95,"tv":18213.46,"id":9631939}]}]}
{"op":"mcm","clk":"4289955508","pt":1632495863016,"mc":[{"id":"1.188075669","rc":[{"batb":[[0,1.84,220.8],[2,1.82,131.34]],"batl":[[0,1.94,2.35],[1,2.16,8.2],[2,2.18,4]],"ltp":1.95,"tv":18213.46,"id":9631939},{"batb":[[0,1.87,48.27],[1,1.86,5],[2,1.85,4]],"ltp":2.04,"tv":5647.96,"id":9454286}]}]}
{"op":"mcm","clk":"4289955561","pt":1632495863503,"mc":[{"id":"1.188075669","rc":[{"batb":[[0,1.84,225.8],[1,1.83,385.04]],"ltp":1.95,"tv":18213.46,"id":9631939}]}]}
{"op":"mcm","clk":"4289955941","pt":1632495868119,"mc":[{"id":"1.188075669","rc":[{"batb":[[0,1.83,184.23],[1,1.82,131.34],[2,1.81,188.58]],"batl":[[0,1.85,508.1],[1,1.86,16.13],[2,1.87,52.5]],"ltp":1.95,"tv":18213.46,"id":9631939},{"batb":[[0,2.16,6.35],[1,2.14,15.32],[2,2.12,459]],"batl":[[0,2.2,6.55],[1,2.26,3.31],[2,2.28,287.54]],"ltp":2.04,"tv":5647.96,"id":9454286}]}]}
{"op":"mcm","clk":"4289956009","pt":1632495868738,"mc":[{"id":"1.188075669","rc":[{"batb":[[2,2.12,618.68]],"batl":[[1,2.24,209.82],[2,2.26,108.23]],"ltp":2.04,"tv":5647.96,"id":9454286}]}]}
{"op":"mcm","clk":"4289956117","pt":1632495870114,"mc":[{"id":"1.188075669","rc":[{"batb":[[2,1.81,255.24]],"ltp":1.95,"tv":18213.46,"id":9631939},{"batl":[[1,2.24,263.7]],"ltp":2.04,"tv":5647.96,"id":9454286}]}]}
{"op":"mcm","clk":"4289956172","pt":1632495870737,"mc":[{"id":"1.188075669","rc":[{"trd":[[1.85,1128.24]],"batl":[[0,1.86,16.13],[1,1.87,52.5],[2,1.9,164.22]],"ltp":1.85,"tv":19229.66,"id":9631939}],"tv":24877.63}]}
{"op":"mcm","clk":"4289956387","pt":1632495872933,"mc":[{"id":"1.188075669","rc":[{"trd":[[1.86,16.13]],"batl":[[0,1.87,52.5],[1,1.9,164.22],[2,1.92,158.91]],"ltp":1.86,"tv":19245.79,"id":9631939},{"trd":[[2.16,46.84]],"batb":[[0,2.14,15.32],[1,2.12,618.68],[2,2.1,110.84]],"ltp":2.16,"tv":5674.55,"id":9454286}],"tv":24920.35}]}
{"op":"mcm","clk":"4289956451","pt":1632495873823,"mc":[{"id":"1.188075669","rc":[{"trd":[[1.83,17.85]],"batb":[[0,1.83,179.23]],"ltp":1.83,"tv":19255.79,"id":9631939}],"tv":24930.35}]}
{"op":"mcm","clk":"4289956727","pt":1632495877125,"mc":[{"id":"1.188075669","rc":[{"batb":[[0,1.84,144],[1,1.83,179.23],[2,1.82,131.34]],"ltp":1.83,"tv":19255.79,"id":9631939}]}]}
{"op":"mcm","clk":"4289957238","pt":1632495882664,"mc":[{"id":"1.188075669","rc":[{"batl":[[0,2.24,263.7],[1,2.26,108.23],[2,2.28,392.46]],"ltp":2.16,"tv":5674.55,"id":9454286}]}]}
{"op":"mcm","clk":"4289957380","pt":1632495884092,"mc":[{"id":"1.188075669","rc":[{"batb":[[1,2.12,159.68],[2,2.08,4]],"batl":[[0,2.24,53.88],[1,2.26,3.31],[2,2.3,202.21]],"ltp":2.16,"tv":5674.55,"id":9454286}]}]}
{"op":"mcm","clk":"4289957490","pt":1632495885137,"mc":[{"id":"1.188075669","rc":[{"batb":[[0,1.81,66.66],[1,1.8,14.48],[2,1.78,17.16]],"batl":[[0,1.97,48.48],[1,1.98,207.77],[2,1.99,208.28]],"ltp":1.83,"tv":19255.79,"id":9631939},{"batb":[[0,2.02,249.56],[1,2,245.71],[2,1.98,196.21]],"ltp":2.16,"tv":5674.55,"id":9454286}]}]}
{"op":"mcm","clk":"4289957589","pt":1632495886034,"mc":[{"id":"1.188075669","rc":[{"batb":[[0,1.78,17.16],[1,1.77,242.95],[2,1.76,398.22]],"ltp":1.83,"tv":19255.79,"id":9631939},{"batb":[[0,2.02,190.74]],"batl":[[0,2.3,202.26],[1,2.32,206.75],[2,2.5,281.5]],"ltp":2.16,"tv":5674.55,"id":9454286}]}]}
{"op":"mcm","clk":"4289957767","pt":1632495887970,"mc":[{"id":"1.188075669","rc":[{"batb":[[1,1.77,415.08]],"batl":[[0,1.94,42.25],[1,1.97,53.48],[2,1.98,207.77]],"ltp":1.83,"tv":19255.79,"id":9631939},{"batb":[[0,2.06,5.08],[1,2.02,199.48],[2,2,249.71]],"ltp":2.16,"tv":5674.55,"id":9454286}]}]}
{"op":"mcm","clk":"4289957879","pt":1632495889173,"mc":[{"id":"1.188075669","rc":[{"batb":[[0,1.8,16.78],[1,1.78,21.16],[2,1.77,242.95]],"batl":[[0,1.97,53.48],[1,1.98,207.77],[2,1.99,208.28]],"ltp":1.83,"tv":19255.79,"id":9631939},{"batb":[[0,2.02,199.48],[1,2,249.71],[2,1.98,196.21]],"batl":[[0,2.26,3.08],[1,2.3,202.21],[2,2.32,206.75]],"ltp":2.16,"tv":5674.55,"id":9454286}]}]}
{"op":"mcm","clk":"4289957900","pt":1632495889439,"mc":[{"id":"1.188075669","rc":[{"batb":[[0,1.78,21.16],[1,1.77,242.95],[2,1.76,398.22]],"ltp":1.83,"tv":19255.79,"id":9631939},{"batl":[[0,2.3,202.26],[1,2.32,206.75],[2,2.5,281.5]],"ltp":2.16,"tv":5674.55,"id":9454286}]}]}
{"op":"mcm","clk":"4289958035","pt":1632495891064,"mc":[{"id":"1.188075669","rc":[{"batl":[[0,2.24,451.88],[1,2.3,202.26],[2,2.32,206.75]],"ltp":2.16,"tv":5674.55,"id":9454286}]}]}
{"op":"mcm","clk":"4289958083","pt":1632495891535,"mc":[{"id":"1.188075669","rc":[{"batb":[[0,1.86,118.59],[1,1.84,178.75],[2,1.78,21.16]],"batl":[[0,1.92,125.2],[1,1.94,196.34],[2,1.97,53.48]],"ltp":1.83,"tv":19255.79,"id":9631939},{"batb":[[0,2.06,4.58],[1,2.02,199.48],[2,2,249.71]],"batl":[[0,2.3,202.26],[1,2.32,206.75],[2,2.5,281.5]],"ltp":2.16,"tv":5674.55,"id":9454286}]}]}
{"op":"mcm","clk":"4289958183","pt":1632495892640,"mc":[{"id":"1.188075669","rc":[{"batb":[[2,1.8,15.08]],"ltp":1.83,"tv":19255.79,"id":9631939},{"batl":[[0,2.26,3.81],[1,2.3,202.21],[2,2.32,206.75]],"ltp":2.16,"tv":5674.55,"id":9454286}]}]}
{"op":"mcm","clk":"4289958278","pt":1632495893764,"mc":[{"id":"1.188075669","rc":[{"batl":[[2,1.96,43.28]],"ltp":1.83,"tv":19255.79,"id":9631939}]}]}
{"op":"mcm","clk":"4289958496","pt":1632495896082,"mc":[{"id":"1.188075669","rc":[{"batb":[[0,1.78,21.16],[1,1.77,242.95],[2,1.76,398.22]],"batl":[[0,1.97,53.48],[1,1.98,207.77],[2,1.99,208.28]],"ltp":1.83,"tv":19255.79,"id":9631939},{"batb":[[0,2.02,199.48],[1,2,249.71],[2,1.98,196.21]],"batl":[[0,2.3,202.26],[1,2.32,206.75],[2,2.5,281.5]],"ltp":2.16,"tv":5674.55,"id":9454286}]}]}
{"op":"mcm","clk":"4289958713","pt":1632495898554,"mc":[{"id":"1.188075669","rc":[{"batb":[[1,1.77,415.08]],"ltp":1.83,"tv":19255.79,"id":9631939}]}]}
{"op":"mcm","clk":"4289958804","pt":1632495899657,"mc":[{"id":"1.188075669","rc":[{"batb":[[1,2,245.71]],"ltp":2.16,"tv":5674.55,"id":9454286}]}]}
{"op":"mcm","clk":"4289958955","pt":1632495901585,"mc":[{"id":"1.188075669","rc":[{"batb":[[1,1.77,412.08]],"ltp":1.83,"tv":19255.79,"id":9631939}]}]}
{"op":"mcm","clk":"4289959118","pt":1632495903167,"mc":[{"id":"1.188075669","rc":[{"batb":[[1,2,250.71]],"ltp":2.16,"tv":5674.55,"id":9454286}]}]}
{"op":"mcm","clk":"4289959307","pt":1632495905214,"mc":[{"id":"1.188075669","rc":[{"trd":[[1.78,3.32],[1.79,50.59]],"batb":[[0,1.78,19.5],[1,1.77,5],[2,1.76,147.45]],"batl":[[0,1.97,48.48]],"ltp":1.78,"tv":19259.19,"id":9631939},{"trd":[[2.26,0.06]],"batb":[[0,2.02,195.48],[1,2,245.71]],"batl":[[0,2.3,3],[1,2.5,281.5],[2,990,0.01]],"ltp":2.26,"tv":5674.61,"id":9454286}],"tv":24933.8}]}
{"op":"mcm","clk":"4289959625","pt":1632495908076,"mc":[{"id":"1.188075669","rc":[{"trd":[[1.95,722.95]],"batb":[[0,1.96,114.46],[1,1.95,191.44],[2,1.94,151.51]],"batl":[[0,1.97,47.5],[1,2.02,13.74],[2,2.04,559.59]],"ltp":1.95,"tv":19261.15,"id":9631939},{"batb":[[0,2.02,4.74]],"batl":[[0,2.04,10.35],[1,2.2,732.25],[2,2.24,13.39]],"ltp":2.26,"tv":5674.61,"id":9454286}],"tv":24935.76}]}
{"op":"mcm","clk":"4289959733","pt":1632495908970,"mc":[{"id":"1.188075669","rc":[{"trd":[[1.96,185.71]],"batb":[[0,1.95,191.44],[1,1.94,107.64],[2,1.93,495.46]],"ltp":1.96,"tv":19291.77,"id":9631939}],"tv":24966.38}]}
{"op":"mcm","clk":"4289959810","pt":1632495909706,"mc":[{"id":"1.188075669","rc":[{"batl":[[2,2.24,17.39]],"ltp":2.26,"tv":5674.61,"id":9454286}]}]}
{"op":"mcm","clk":"4289960005","pt":1632495911908,"mc":[{"id":"1.188075669","rc":[{"batb":[[0,1.95,372.09],[2,1.93,649.44]],"ltp":1.96,"tv":19291.77,"id":9631939}]}]}
{"op":"mcm","clk":"4289960113","pt":1632495913108,"mc":[{"id":"1.188075669","rc":[{"batl":[[1,2.08,57.73],[2,2.2,732.25]],"ltp":2.26,"tv":5674.61,"id":9454286}]}]}
{"op":"mcm","clk":"4289960320","pt":1632495915177,"mc":[{"id":"1.188075669","rc":[{"batb":[[0,1.96,156],[1,1.95,372.09],[2,1.94,107.64]],"ltp":1.96,"tv":19291.77,"id":9631939},{"batl":[[2,2.16,193.33]],"ltp":2.26,"tv":5674.61,"id":9454286}]}]}
{"op":"mcm","clk":"4289960631","pt":1632495918190,"mc":[{"id":"1.188075669","rc":[{"trd":[[1.97,12.79]],"batl":[[0,1.97,45.5]],"ltp":1.97,"tv":19295.77,"id":9631939}],"tv":24970.38}]}
{"op":"mcm","clk":"4289960691","pt":1632495918914,"mc":[{"id":"1.188075669","rc":[{"trd":[[1.96,186.02]],"batb":[[0,1.96,155.84]],"ltp":1.96,"tv":19296.08,"id":9631939}],"tv":24970.69}]}
{"op":"mcm","clk":"4289960757","pt":1632495919606,"mc":[{"id":"1.188075669","rc":[{"trd":[[1.96,190.72]],"batb":[[0,1.96,153.49],[1,1.95,180.65]],"ltp":1.96,"tv":19300.78,"id":9631939}],"tv":24975.39}]}
{"op":"mcm","clk":"4289960929","pt":1632495921489,"mc":[{"id":"1.188075669","rc":[{"trd":[[1.97,18.81]],"batl":[[0,1.97,42.49]],"ltp":1.97,"tv":19306.8,"id":9631939}],"tv":24981.41}]}
{"op":"mcm","clk":"4289961229","pt":1632495924116,"mc":[{"id":"1.188075669","rc":[{"trd":[[1.96,217.06]],"batb":[[0,1.96,140.31]],"ltp":1.96,"tv":19333.14,"id":9631939}],"tv":25007.75}]}
{"op":"mcm","clk":"4289961318","pt":1632495925013,"mc":[{"id":"1.188075669","rc":[{"trd":[[1.96,240.34],[1.97,24.83]],"batb":[[0,1.96,128.66]],"batl":[[0,1.97,39.48],[2,2.04,577.34]],"ltp":1.96,"tv":19362.44,"id":9631939}],"tv":25037.05}]}
{"op":"mcm","clk":"4289962127","pt":1632495933128,"mc":[{"id":"1.188075669","rc":[{"batb":[[0,1.93,62.21],[1,1.86,220.62],[2,1.85,247.39]],"batl":[[0,2.2,4.28],[1,2.22,165.42],[2,2.24,191.88]],"ltp":1.96,"tv":19362.44,"id":9631939},{"batb":[[0,1.84,48.97],[1,1.82,217.19],[2,1.81,332.75]],"batl":[[0,2.08,57.73],[1,2.16,193.33],[2,2.18,224.61]],"ltp":2.26,"tv":5674.61,"id":9454286}]}]}
{"op":"mcm","clk":"4289962157","pt":1632495933448,"mc":[{"id":"1.188075669","rc":[{"batl":[[0,2.22,165.42],[1,2.24,191.88],[2,2.28,4.09]],"ltp":1.96,"tv":19362.44,"id":9631939},{"batb":[[0,1.82,217.19],[1,1.81,332.75],[2,1.79,48.31]],"ltp":2.26,"tv":5674.61,"id":9454286}]}]}
{"op":"mcm","clk":"4289962225","pt":1632495934229,"mc":[{"id":"1.188075669","rc":[{"batb":[[0,1.86,220.62],[1,1.85,247.39],[2,1.83,128.47]],"ltp":1.96,"tv":19362.44,"id":9631939},{"batl":[[0,2.16,193.33],[1,2.18,224.61],[2,2.24,7.73]],"ltp":2.26,"tv":5674.61,"id":9454286}]}]}
{"op":"mcm","clk":"4289962481","pt":1632495937125,"mc":[{"id":"1.188075669","rc":[{"batl":[[0,2.22,168.42]],"ltp":1.96,"tv":19362.44,"id":9631939},{"batb":[[0,1.82,221.19],[1,1.81,336.75]],"ltp":2.26,"tv":5674.61,"id":9454286}]}]}
{"op":"mcm","clk":"4289962686","pt":1632495939062,"mc":[{"id":"1.188075669","rc":[{"batb":[[0,1.97,20.17],[1,1.86,220.62],[2,1.85,247.39]],"batl":[[0,2.02,18.25],[1,2.22,168.42],[2,2.24,191.88]],"ltp":1.96,"tv":19362.44,"id":9631939},{"batl":[[0,2.04,18.38],[1,2.16,193.33],[2,2.18,224.61]],"ltp":2.26,"tv":5674.61,"id":9454286}]}]}
{"op":"mcm","clk":"4289962719","pt":1632495939384,"mc":[{"id":"1.188075669","rc":[{"batb":[[0,1.86,220.62],[1,1.85,247.39],[2,1.83,128.47]],"batl":[[0,2.22,168.42],[1,2.24,191.88],[2,2.28,4.09]],"ltp":1.96,"tv":19362.44,"id":9631939},{"batb":[[0,1.93,172.83],[1,1.91,159.1],[2,1.82,221.19]],"batl":[[0,2.02,236.35],[1,2.04,132.91],[2,2.16,193.33]],"ltp":2.26,"tv":5674.61,"id":9454286}]}]}
{"op":"mcm","clk":"4289962879","pt":1632495941061,"mc":[{"id":"1.188075669","rc":[{"batb":[[0,1.87,85.48],[1,1.86,220.62],[2,1.85,247.39]],"batl":[[0,2.2,4.13],[1,2.22,168.42],[2,2.24,191.88]],"ltp":1.96,"tv":19362.44,"id":9631939},{"batb":[[2,1.84,39.72]],"batl":[[2,2.14,70.87]],"ltp":2.26,"tv":5674.61,"id":9454286}]}]}
{"op":"mcm","clk":"4289963178","pt":1632495944150,"mc":[{"id":"1.188075669","rc":[{"batl":[[0,2.18,73.19],[1,2.2,4.13],[2,2.22,168.42]],"ltp":1.96,"tv":19362.44,"id":9631939},{"batb":[[0,1.93,262.99]],"ltp":2.26,"tv":5674.61,"id":9454286}]}]}
{"op":"mcm","clk":"4289963207","pt":1632495944454,"mc":[{"id":"1.188075669","rc":[{"batb":[[0,1.86,220.62],[1,1.85,247.39],[2,1.83,128.47]],"batl":[[0,2.2,4.13],[1,2.22,168.42],[2,2.24,191.88]],"ltp":1.96,"tv":19362.44,"id":9631939},{"batb":[[0,1.84,39.72],[1,1.82,221.19],[2,1.81,336.75]],"batl":[[0,2.16,193.33],[1,2.18,224.61],[2,2.24,7.73]],"ltp":2.26,"tv":5674.61,"id":9454286}]}]}
{"op":"mcm","clk":"4289963447","pt":1632495947241,"mc":[{"id":"1.188075669","rc":[{"batl":[[0,2.22,168.42],[1,2.24,191.88],[2,2.28,4.09]],"ltp":1.96,"tv":19362.44,"id":9631939},{"batb":[[0,1.82,221.19],[1,1.81,336.75],[2,1.79,201.9]],"batl":[[1,2.18,345.16],[2,2.2,106.78]],"ltp":2.26,"tv":5674.61,"id":9454286}]}]}
{"op":"mcm","clk":"4289963580","pt":1632495948566,"mc":[{"id":"1.188075669","rc":[{"batl":[[0,2.22,3],[1,2.28,4.09],[2,990,0.01]],"ltp":1.96,"tv":19362.44,"id":9631939},{"batb":[[0,1.82,4],[1,1.81,130.16],[2,1.79,48.31]],"batl":[[1,2.18,224.61],[2,2.24,7.73]],"ltp":2.26,"tv":5674.61,"id":9454286}]}]}
{"op":"mcm","clk":"4289963853","pt":1632495951151,"mc":[{"id":"1.188075669","rc":[{"batb":[[1,1.85,366.83],[2,1.83,310.35]],"batl":[[0,1.87,518.72],[1,1.89,48.5],[2,1.91,131.14]],"ltp":1.96,"tv":19362.44,"id":9631939},{"batb":[[0,2.12,14.29],[1,2.1,223.8],[2,2.08,111.9]],"batl":[[0,2.16,201.29],[2,2.24,227.52]],"ltp":2.26,"tv":5674.61,"id":9454286}]}]}
{"op":"mcm","clk":"4289963975","pt":1632495952152,"mc":[{"id":"1.188075669","rc":[{"batb":[[0,1.85,132.21],[1,1.83,310.35],[2,1.81,50.55]],"ltp":1.96,"tv":19362.44,"id":9631939},{"batb":[[1,2.1,387.2]],"batl":[[0,2.16,7.96],[1,2.18,3.75],[2,2.22,211.72]],"ltp":2.26,"tv":5674.61,"id":9454286}]}]}
{"op":"mcm","clk":"4289963994","pt":1632495952359,"mc":[{"id":"1.188075669","rc":[{"batb":[[2,1.82,66.25]],"ltp":1.96,"tv":19362.44,"id":9631939},{"batl":[[2,2.22,266.04]],"ltp":2.26,"tv":5674.61,"id":9454286}]}]}
{"op":"mcm","clk":"4289964271","pt":1632495955093,"mc":[{"id":"1.188075669","rc":[{"trd":[[1.87,404.36]],"batl":[[0,1.87,316.54]],"ltp":1.87,"tv":19766.8,"id":9631939}],"tv":25441.41}]}
{"op":"mcm","clk":"4289964383","pt":1632495956078,"mc":[{"id":"1.188075669","rc":[{"trd":[[1.87,461.34]],"batl":[[0,1.87,259.56]],"ltp":1.87,"tv":19823.78,"id":9631939},{"trd":[[2.14,49.79]],"ltp":2.14,"tv":5724.4,"id":9454286}],"tv":25548.18}]}
{"op":"mcm","clk":"4289964573","pt":1632495958386,"mc":[{"id":"1.188075669","rc":[{"trd":[[1.86,21.13]],"batb":[[0,1.86,205],[1,1.85,132.21],[2,1.83,310.35]],"ltp":1.86,"tv":19828.78,"id":9631939},{"trd":[[2.16,51.15]],"batl":[[0,2.16,3.65]],"ltp":2.16,"tv":5728.71,"id":9454286}],"tv":25557.49}]}
{"op":"mcm","clk":"4289965275","pt":1632495965173,"mc":[{"id":"1.188075669","rc":[{"trd":[[1.87,466.36]],"batl":[[0,1.87,257.04]],"ltp":1.87,"tv":19833.8,"id":9631939},{"trd":[[2.14,49.81]],"ltp":2.14,"tv":5728.73,"id":9454286}],"tv":25562.53}]}
{"op":"mcm","clk":"4289965376","pt":1632495966110,"mc":[{"id":"1.188075669","rc":[{"batl":[[0,1.89,48.5],[1,1.91,131.14],[2,1.93,156.5]],"ltp":1.87,"tv":19833.8,"id":9631939},{"batb":[[1,2.1,163.4],[2,2.06,3]],"batl":[[0,2.18,3.75],[1,2.22,54.32],[2,2.24,3.73]],"ltp":2.14,"tv":5728.73,"id":9454286}]}]}
{"op":"mcm","clk":"4289965496","pt":1632495967215,"mc":[{"id":"1.188075669","rc":[{"batb":[[0,1.81,16.43],[1,1.79,15.31],[2,1.78,206.79]],"batl":[[0,1.99,208.64],[1,2,255.92],[2,2.18,4]],"ltp":1.87,"tv":19833.8,"id":9631939},{"batb":[[0,2,153.8],[1,1.99,223.68],[2,1.97,199.58]],"batl":[[0,2.24,3.73],[1,2.28,185.08],[2,2.3,201.51]],"ltp":2.14,"tv":5728.73,"id":9454286}]}]}
{"op":"mcm","clk":"4289965548","pt":1632495967703,"mc":[{"id":"1.188075669","rc":[{"batb":[[0,1.79,15.45],[1,1.78,206.79],[2,1.77,432.39]],"ltp":1.87,"tv":19833.8,"id":9631939},{"batl":[[0,2.28,185.08],[1,2.3,201.51],[2,2.5,281.5]],"ltp":2.14,"tv":5728.73,"id":9454286}]}]}
{"op":"mcm","clk":"4289965766","pt":1632495969991,"mc":[{"id":"1.188075669","rc":[{"batb":[[1,1.78,392.12]],"batl":[[0,1.96,41.62],[1,1.99,212.64],[2,2,255.92]],"ltp":1.87,"tv":19833.8,"id":9631939},{"batb":[[0,2.04,4.62],[1,2,169.82],[2,1.99,227.68]],"ltp":2.14,"tv":5728.73,"id":9454286}]}]}
{"op":"mcm","clk":"4289965877","pt":1632495971091,"mc":[{"id":"1.188075669","rc":[{"batb":[[0,1.8,4.14],[1,1.79,20.31],[2,1.78,397.12]],"batl":[[0,1.99,212.64],[1,2,255.92],[2,2.06,219.54]],"ltp":1.87,"tv":19833.8,"id":9631939},{"batb":[[0,2,169.82],[1,1.99,227.68],[2,1.97,199.58]],"batl":[[0,2.28,189.08]],"ltp":2.14,"tv":5728.73,"id":9454286}]}]}
{"op":"mcm","clk":"4289965899","pt":1632495971302,"mc":[{"id":"1.188075669","rc":[{"batb":[[0,1.8,4]],"ltp":1.87,"tv":19833.8,"id":9631939}]}]}
{"op":"mcm","clk":"4289966061","pt":1632495972990,"mc":[{"id":"1.188075669","rc":[{"batl":[[0,1.99,4],[1,2.18,4],[2,990,0.01]],"ltp":1.87,"tv":19833.8,"id":9631939},{"batb":[[0,2,16.02],[1,1.99,4]],"ltp":2.14,"tv":5728.73,"id":9454286}]}]}
{"op":"mcm","clk":"4289966254","pt":1632495974621,"mc":[{"id":"1.188075669","rc":[{"batl":[[0,2.26,4],[1,2.28,189.08],[2,2.3,201.51]],"ltp":2.14,"tv":5728.73,"id":9454286}]}]}
{"op":"mcm","clk":"4289966401","pt":1632495976091,"mc":[{"id":"1.188075669","rc":[{"batb":[[0,1.79,15.31],[1,1.78,392.12],[2,1.77,432.39]],"batl":[[0,1.82,16.48],[1,1.83,58.57],[2,1.84,294.06]],"ltp":1.87,"tv":19833.8,"id":9631939},{"batb":[[0,2.2,13.32],[1,2,16.02],[2,1.99,4]],"batl":[[0,2.28,199.04],[1,2.3,201.51],[2,2.32,194.51]],"ltp":2.14,"tv":5728.73,"id":9454286}]}]}
{"op":"mcm","clk":"4289966520","pt":1632495977202,"mc":[{"id":"1.188075669","rc":[{"batb":[[1,1.78,401.77]],"ltp":1.87,"tv":19833.8,"id":9631939},{"batb":[[1,2.18,145.26],[2,2.12,159.43]],"batl":[[2,2.32,246.73]],"ltp":2.14,"tv":5728.73,"id":9454286}]}]}
{"op":"mcm","clk":"4289967062","pt":1632495983105,"mc":[{"id":"1.188075669","rc":[{"batb":[[0,1.79,88.31]],"ltp":1.87,"tv":19833.8,"id":9631939},{"batb":[[2,2.14,212.59]],"ltp":2.14,"tv":5728.73,"id":9454286}]}]}
{"op":"mcm","clk":"4289967176","pt":1632495984212,"mc":[{"id":"1.188075669","rc":[{"trd":[[2.2,6.63]],"batb":[[0,2.2,11.32]],"ltp":2.2,"tv":5732.73,"id":9454286}],"tv":25566.53}]}
{"op":"mcm","clk":"4289967340","pt":1632495986209,"mc":[{"id":"1.188075669","rc":[{"batb":[[0,1.79,165.31]],"ltp":1.87,"tv":19833.8,"id":9631939}]}]}
{"op":"mcm","clk":"4289967469","pt":1632495987723,"mc":[{"id":"1.188075669","rc":[{"batl":[[2,1.84,121.54]],"ltp":1.87,"tv":19833.8,"id":9631939}]}]}
{"op":"mcm","clk":"4289967567","pt":1632495988930,"mc":[{"id":"1.188075669","rc":[{"trd":[[2.2,6.91]],"batb":[[0,2.2,11.18]],"ltp":2.2,"tv":5733.0,"id":9454286}],"tv":25566.81}]}
{"op":"mcm","clk":"4289967868","pt":1632495992143,"mc":[{"id":"1.188075669","rc":[{"trd":[[1.82,292.4]],"batl":[[0,1.82,16.28]],"ltp":1.82,"tv":19834.2,"id":9631939}],"tv":25567.2}]}
{"op":"mcm","clk":"4289967930","pt":1632495992747,"mc":[{"id":"1.188075669","rc":[{"trd":[[1.82,324.94]],"batb":[[0,1.82,193.4],[1,1.79,165.31],[2,1.78,401.77]],"batl":[[0,1.83,58.57],[1,1.84,121.54],[2,1.86,766.25]],"ltp":1.82,"tv":19866.74,"id":9631939}],"tv":25599.75}]}
{"op":"mcm","clk":"4289968568","pt":1632495999667,"mc":[{"id":"1.188075669","rc":[{"batb":[[1,1.8,7.02],[2,1.79,165.31]],"ltp":1.82,"tv":19866.74,"id":9631939},{"trd":[[2.2,7.09]],"batb":[[0,2.2,11.09]],"ltp":2.2,"tv":5733.19,"id":9454286}],"tv":25599.93}]}
{"op":"mcm","clk":"4289968647","pt":1632496000980,"mc":[{"id":"1.188075669","rc":[{"trd":[[1.83,22.55]],"batl":[[0,1.83,56.22]],"ltp":1.83,"tv":19871.43,"id":9631939}],"tv":25604.62}]}
{"op":"mcm","clk":"4289968759","pt":1632496002339,"mc":[{"id":"1.188075669","rc":[{"batb":[[0,1.82,193.49]],"ltp":1.83,"tv":19871.43,"id":9631939}]}]}
{"op":"mcm","clk":"4289968824","pt":1632496003340,"mc":[{"id":"1.188075669","rc":[{"trd":[[1.83,134.91]],"batb":[[0,1.83,131.47],[1,1.82,193.49],[2,1.8,7.02]],"batl":[[0,1.84,121.54],[1,1.86,766.25],[2,1.87,731.56]],"ltp":1.83,"tv":19983.79,"id":9631939}],"tv":25716.98}]}
{"op":"mcm","clk":"4289968942","pt":1632496004864,"mc":[{"id":"1.188075669","rc":[{"batb":[[1,1.82,193.4]],"ltp":1.83,"tv":19983.79,"id":9631939}]}]}
{"op":"mcm","clk":"4289969189","pt":1632496008072,"mc":[{"id":"1.188075669","rc":[{"batb":[[1,1.82,5.79]],"ltp":1.83,"tv":19983.79,"id":9631939}]}]}
{"op":"mcm","clk":"4289969425","pt":1632496011160,"mc":[{"id":"1.188075669","rc":[{"batl":[[0,2.28,185.08]],"ltp":2.2,"tv":5733.19,"id":9454286}]}]}
{"op":"mcm","clk":"4289969638","pt":1632496014064,"mc":[{"id":"1.188075669","rc":[{"batl":[[1,1.86,782.02]],"ltp":1.83,"tv":19983.79,"id":9631939},{"batl":[[0,2.24,10.65],[1,2.28,185.08],[2,2.3,201.51]],"ltp":2.2,"tv":5733.19,"id":9454286}]}]}
{"op":"mcm","clk":"4289969656","pt":1632496014385,"mc":[{"id":"1.188075669","rc":[{"trd":[[1.84,17.04]],"batl":[[0,1.84,121.45],[1,1.86,766.25]],"ltp":1.84,"tv":19983.98,"id":9631939},{"batl":[[0,2.28,185.08],[1,2.3,201.51],[2,2.32,246.73]],"ltp":2.2,"tv":5733.19,"id":9454286}],"tv":25717.17}]}
{"op":"mcm","clk":"4289969884","pt":1632496017182,"mc":[{"id":"1.188075669","rc":[{"batl":[[1,1.86,782.02]],"ltp":1.84,"tv":19983.98,"id":9631939},{"batl":[[0,2.24,10.65],[1,2.28,185.08],[2,2.3,201.51]],"ltp":2.2,"tv":5733.19,"id":9454286}]}]}
{"op":"mcm","clk":"4289969966","pt":1632496018189,"mc":[{"id":"1.188075669","rc":[{"batb":[[2,1.79,507.31]],"ltp":1.84,"tv":19983.98,"id":9631939}]}]}
{"op":"mcm","clk":"4289970540","pt":1632496024014,"mc":[{"id":"1.188075669","rc":[{"trd":[[1.84,18.39]],"batl":[[0,1.84,120.77]],"ltp":1.84,"tv":19985.33,"id":9631939}],"tv":25718.52}]}
{"op":"mcm","clk":"4289970698","pt":1632496025607,"mc":[{"id":"1.188075669","rc":[{"batb":[[0,1.82,5.79],[1,1.79,507.31],[2,1.78,401.77]],"ltp":1.84,"tv":19985.33,"id":9631939}]}]}
{"op":"mcm","clk":"4289971516","pt":1632496035324,"mc":[{"id":"1.188075669","rc":[{"batl":[[0,1.83,42.77],[1,1.84,120.77],[2,1.86,782.02]],"ltp":1.84,"tv":19985.33,"id":9631939}]}]}
{"op":"mcm","clk":"4289971747","pt":1632496038430,"mc":[{"id":"1.188075669","rc":[{"trd":[[1.82,336.51]],"batb":[[0,1.79,507.32],[1,1.78,401.77],[2,1.77,432.39]],"ltp":1.82,"tv":19996.91,"id":9631939}],"tv":25730.1}]}
{"op":"mcm","clk":"4289973628","pt":1632496059061,"mc":[{"id":"1.188075669","rc":[{"batb":[[0,1.81,6.15],[1,1.79,507.31],[2,1.78,401.77]],"ltp":1.82,"tv":19996.91,"id":9631939}]}]}
{"op":"mcm","clk":"4289973831","pt":1632496062085,"mc":[{"id":"1.188075669","rc":[{"batl":[[2,1.86,252.13]],"ltp":1.82,"tv":19996.91,"id":9631939},{"batl":[[0,2.28,185.08],[1,2.3,201.51],[2,2.32,52.22]],"ltp":2.2,"tv":5733.19,"id":9454286}]}]}
{"op":"mcm","clk":"4289973923","pt":1632496063188,"mc":[{"id":"1.188075669","rc":[{"batb":[[1,1.78,9.65],[2,1.76,75.84]],"batl":[[1,1.86,76.85],[2,1.87,232.58]],"ltp":1.82,"tv":19996.91,"id":9631939},{"batb":[[0,2.14,212.59],[1,2.12,369.44],[2,2.1,54.54]],"batl":[[0,2.32,52.22],[1,2.36,188.18],[2,2.38,162.08]],"ltp":2.2,"tv":5733.19,"id":9454286}]}]}
{"op":"mcm","clk":"4289974029","pt":1632496064188,"mc":[{"id":"1.188075669","rc":[{"batb":[[2,1.76,7.02]],"ltp":1.82,"tv":19996.91,"id":9631939},{"batb":[[2,2.02,3]],"batl":[[0,2.36,188.18],[1,2.38,162.08],[2,2.5,281.33]],"ltp":2.2,"tv":5733.19,"id":9454286}]}]}
{"op":"mcm","clk":"4289974138","pt":1632496065564,"mc":[{"id":"1.188075669","rc":[{"batl":[[1,1.86,97.6]],"ltp":1.82,"tv":19996.91,"id":9631939},{"batb":[[0,2.16,3.78],[1,2.14,212.59],[2,2.12,369.44]],"batl":[[0,2.34,3.25],[1,2.36,188.18],[2,2.38,162.08]],"ltp":2.2,"tv":5733.19,"id":9454286}]}]}
{"op":"mcm","clk":"4289974323","pt":1632496067976,"mc":[{"id":"1.188075669","rc":[{"batb":[[2,1.77,157.82]],"batl":[[0,1.83,199.42],[1,1.85,178.22],[2,1.86,97.6]],"ltp":1.82,"tv":19996.91,"id":9631939}]}]}
{"op":"mcm","clk":"4289974418","pt":1632496069073,"mc":[{"id":"1.188075669","rc":[{"trd":[[1.82,336.53]],"batb":[[0,1.81,143.14],[2,1.77,174.19]],"batl":[[1,1.85,200.12]],"ltp":1.82,"tv":19996.92,"id":9631939},{"batl":[[0,2.3,3.15],[1,2.34,3.25],[2,2.36,188.18]],"ltp":2.2,"tv":5733.19,"id":9454286}],"tv":25730.12}]}
{"op":"mcm","clk":"4289974502","pt":1632496070084,"mc":[{"id":"1.188075669","rc":[{"batb":[[2,1.77,16.37]],"batl":[[0,1.83,42.77],[1,1.85,21.9]],"ltp":1.82,"tv":19996.92,"id":9631939}]}]}
{"op":"mcm","clk":"4289974549","pt":1632496070564,"mc":[{"id":"1.188075669","rc":[{"batl":[[1,1.86,97.6],[2,1.87,232.58]],"ltp":1.82,"tv":19996.92,"id":9631939}]}]}
{"op":"mcm","clk":"4289974684","pt":1632496072081,"mc":[{"id":"1.188075669","rc":[{"batb":[[0,1.81,109.14],[2,1.76,7.02]],"ltp":1.82,"tv":19996.92,"id":9631939},{"batl":[[0,2.34,3.25],[1,2.36,188.18],[2,2.38,162.08]],"ltp":2.2,"tv":5733.19,"id":9454286}]}]}
{"op":"mcm","clk":"4289974755","pt":1632496072978,"mc":[{"id":"1.188075669","rc":[{"batb":[[0,1.81,6.14]],"ltp":1.82,"tv":19996.92,"id":9631939}]}]}
{"op":"mcm","clk":"4289974833","pt":1632496073980,"mc":[{"id":"1.188075669","rc":[{"batl":[[2,1.99,4]],"ltp":1.82,"tv":19996.92,"id":9631939},{"batb":[[1,2.12,159.43],[2,2.02,3]],"ltp":2.2,"tv":5733.19,"id":9454286}]}]}
{"op":"mcm","clk":"4289975084","pt":1632496077180,"mc":[{"id":"1.188075669","rc":[{"trd":[[1.78,22.64],[1.81,12.29]],"batb":[[0,1.76,7.02],[1,1.75,17.71],[2,1.74,198.2]],"batl":[[0,1.78,462.99],[1,1.79,556.72],[2,1.8,712.92]],"ltp":1.78,"tv":20028.54,"id":9631939},{"batb":[[0,2.26,5.98],[1,2.16,3.78],[2,2.12,159.43]],"ltp":2.2,"tv":5733.19,"id":9454286}],"tv":25761.73}]}
{"op":"mcm","clk":"4289975157","pt":1632496078220,"mc":[{"id":"1.188075669","rc":[{"batb":[[0,2.3,126.79],[1,2.26,5.98],[2,2.2,140.87]],"ltp":2.2,"tv":5733.19,"id":9454286}]}]}
{"op":"mcm","clk":"4289975306","pt":1632496079700,"mc":[{"id":"1.188075669","rc":[{"trd":[[1.77,5.23]],"ltp":1.77,"tv":20031.04,"id":9631939},{"trd":[[2.3,7.44]],"batb":[[0,2.3,124.86],[2,2.24,3]],"ltp":2.3,"tv":5735.11,"id":9454286}],"tv":25766.15}]}
{"op":"mcm","clk":"4289975510","pt":1632496082097,"mc":[{"id":"1.188075669","rc":[{"batl":[[0,1.78,519.24]],"ltp":1.77,"tv":20031.04,"id":9631939},{"trd":[[2.3,78.46]],"batb":[[0,2.3,89.37]],"ltp":2.3,"tv":5806.12,"id":9454286}],"tv":25837.16}]}
{"op":"mcm","clk":"4289975601","pt":1632496083098,"mc":[{"id":"1.188075669","rc":[{"batb":[[0,1.76,561.02]],"ltp":1.77,"tv":20031.04,"id":9631939}]}]}
{"op":"mcm","clk":"4289976124","pt":1632496089111,"mc":[{"id":"1.188075669","rc":[{"batb":[[1,1.71,181.66],[2,1.7,71.71]],"batl":[[0,1.82,19.75],[1,1.83,260.33],[2,1.84,269.52]],"ltp":1.77,"tv":20031.04,"id":9631939},{"batb":[[1,2.24,3],[2,2.22,4]],"batl":[[0,2.42,53.08],[1,2.46,3.25],[2,2.48,185.03]],"ltp":2.3,"tv":5806.12,"id":9454286}]}]}
{"op":"mcm","clk":"4289976221","pt":1632496090210,"mc":[{"id":"1.188075669","rc":[{"batb":[[0,1.76,7.02],[1,1.71,19.19],[2,1.69,19.21]],"batl":[[0,1.83,260.33],[1,1.84,209.52],[2,1.86,97.6]],"ltp":1.77,"tv":20031.04,"id":9631939},{"batb":[[0,2.2,318.04],[1,2.18,208.23],[2,2.16,3.78]],"batl":[[0,2.42,2.73]],"ltp":2.3,"tv":5806.12,"id":9454286}]}]}
{"op":"mcm","clk":"4289976251","pt":1632496090520,"mc":[{"id":"1.188075669","rc":[{"batb":[[1,1.69,19.21],[2,1.68,188.38]],"ltp":1.77,"tv":20031.04,"id":9631939},{"batl":[[0,2.46,3.42],[1,2.48,185.03],[2,2.5,181.15]],"ltp":2.3,"tv":5806.12,"id":9454286}]}]}
{"op":"mcm","clk":"4289976364","pt":1632496092044,"mc":[{"id":"1.188075669","rc":[{"batl":[[0,1.83,451.64],[2,1.85,178.11]],"ltp":1.77,"tv":20031.04,"id":9631939}]}]}
{"op":"mcm","clk":"4289976556","pt":1632496094143,"mc":[{"id":"1.188075669","rc":[{"batb":[[1,1.71,17.19],[2,1.69,19.21]],"ltp":1.77,"tv":20031.04,"id":9631939},{"batl":[[0,2.42,2.73],[1,2.46,3.25],[2,2.48,185.03]],"ltp":2.3,"tv":5806.12,"id":9454286}]}]}
{"op":"mcm","clk":"4289976596","pt":1632496094565,"mc":[{"id":"1.188075669","rc":[{"batb":[[1,1.69,19.21],[2,1.68,188.38]],"ltp":1.77,"tv":20031.04,"id":9631939},{"batl":[[0,2.46,3.42],[1,2.48,185.03],[2,2.5,181.15]],"ltp":2.3,"tv":5806.12,"id":9454286}]}]}
{"op":"mcm","clk":"4289976753","pt":1632496096116,"mc":[{"id":"1.188075669","rc":[{"batl":[[0,1.83,42.77],[1,1.86,76.85],[2,1.99,4]],"ltp":1.77,"tv":20031.04,"id":9631939},{"batb":[[0,2.2,140.87],[1,2.18,3.86],[2,2.02,3]],"ltp":2.3,"tv":5806.12,"id":9454286}]}]}
{"op":"mcm","clk":"4289976951","pt":1632496098159,"mc":[{"id":"1.188075669","rc":[{"trd":[[1.73,13.37],[1.76,49.85]],"batb":[[0,1.69,19.21],[1,1.68,199.9],[2,1.67,246.08]],"batl":[[0,1.72,1407.34],[1,1.73,539.62],[2,1.74,562.37]],"ltp":1.73,"tv":20045.32,"id":9631939},{"trd":[[2.36,0.17]],"batb":[[0,2.4,235.62],[1,2.34,5.72],[2,2.2,140.87]],"batl":[[0,2.46,3.25]],"ltp":2.36,"tv":5806.29,"id":9454286}],"tv":25851.61}]}
{"op":"mcm","clk":"4289977056","pt":1632496099157,"mc":[{"id":"1.188075669","rc":[{"batl":[[0,1.71,231.61],[1,1.72,573.4],[2,1.73,761.02]],"ltp":1.73,"tv":20045.32,"id":9631939},{"batb":[[0,2.44,108.14],[1,2.4,235.62],[2,2.34,5.72]],"ltp":2.36,"tv":5806.29,"id":9454286}]}]}
{"op":"mcm","clk":"4289977200","pt":1632496101157,"mc":[{"id":"1.188075669","rc":[{"batb":[[0,1.69,24.21],[1,1.68,205.9]],"ltp":1.73,"tv":20045.32,"id":9631939},{"trd":[[2.44,8]],"batb":[[0,2.44,104.15]],"ltp":2.44,"tv":5814.29,"id":9454286}],"tv":25859.61}]}
{"op":"mcm","clk":"4289977266","pt":1632496102051,"mc":[{"id":"1.188075669","rc":[{"batb":[[0,1.69,798.21],[1,1.68,199.9]],"ltp":1.73,"tv":20045.32,"id":9631939}]}]}
{"op":"mcm","clk":"4289977359","pt":1632496103167,"mc":[{"id":"1.188075669","rc":[{"trd":[[2.44,46.96]],"batb":[[0,2.44,84.67]],"ltp":2.44,"tv":5853.25,"id":9454286}],"tv":25898.57}]}
{"op":"mcm","clk":"4289977531","pt":1632496105166,"mc":[{"id":"1.188075669","rc":[{"batl":[[0,1.71,261.01]],"ltp":1.73,"tv":20045.32,"id":9631939}]}]}
{"op":"mcm","clk":"4289977563","pt":1632496105643,"mc":[{"id":"1.188075669","rc":[{"batl":[[0,1.71,29.4],[2,1.73,539.62]],"ltp":1.73,"tv":20045.32,"id":9631939},{"trd":[[2.44,47.15]],"batb":[[0,2.44,84.58]],"ltp":2.44,"tv":5853.44,"id":9454286}],"tv":25898.76}]}
{"op":"mcm","clk":"4289977826","pt":1632496109020,"mc":[{"id":"1.188075669","rc":[{"batl":[[0,1.7,127.08],[1,1.71,29.4],[2,1.72,799.76]],"ltp":1.73,"tv":20045.32,"id":9631939},{"trd":[[2.44,66.06]],"batb":[[0,2.44,75.13]],"ltp":2.44,"tv":5872.35,"id":9454286}],"tv":25917.67}]}
{"op":"mcm","clk":"4289978182","pt":1632496113165,"mc":[{"id":"1.188075669","rc":[{"batl":[[2,1.72,782.32]],"ltp":1.73,"tv":20045.32,"id":9631939}]}]}
{"op":"mcm","clk":"4289978299","pt":1632496114169,"mc":[{"id":"1.188075669","rc":[{"batb":[[0,1.63,19.23],[1,1.62,282.5],[2,1.61,275.76]],"batl":[[0,1.76,175.72],[1,1.77,351.87],[2,1.78,21.75]],"ltp":1.73,"tv":20045.32,"id":9631939},{"batb":[[0,2.32,263.93],[1,2.3,220.03],[2,2.28,3.41]],"batl":[[0,2.58,47.73],[1,2.6,5.76],[2,2.62,166.3]],"ltp":2.44,"tv":5872.35,"id":9454286}]}]}
{"op":"mcm","clk":"4289978340","pt":1632496114589,"mc":[{"id":"1.188075669","rc":[{"batb":[[0,1.62,282.5],[1,1.61,275.76],[2,1.58,215.87]],"ltp":1.73,"tv":20045.32,"id":9631939},{"batl":[[1,2.6,3]],"ltp":2.44,"tv":5872.35,"id":9454286}]}]}
{"op":"mcm","clk":"4289978395","pt":1632496115273,"mc":[{"id":"1.188075669","rc":[{"batl":[[1,1.77,291.87]],"ltp":1.73,"tv":20045.32,"id":9631939},{"batb":[[1,2.3,173.88]],"batl":[[0,2.6,3],[1,2.62,166.3],[2,2.64,181.24]],"ltp":2.44,"tv":5872.35,"id":9454286}]}]}
{"op":"mcm","clk":"4289978477","pt":1632496116375,"mc":[{"id":"1.188075669","rc":[{"batb":[[2,1.59,176.16]],"batl":[[0,1.75,144.74],[1,1.76,175.72],[2,1.77,497.53]],"ltp":1.73,"tv":20045.32,"id":9631939}]}]}
{"op":"mcm","clk":"4289978616","pt":1632496117998,"mc":[{"id":"1.188075669","rc":[{"batb":[[0,1.62,287.5],[1,1.61,280.76]],"ltp":1.73,"tv":20045.32,"id":9631939}]}]}
{"op":"mcm","clk":"4289978915","pt":1632496121203,"mc":[{"id":"1.188075669","rc":[{"batb":[[0,1.63,20.23],[1,1.62,287.5],[2,1.61,280.76]],"batl":[[0,1.74,4],[1,1.75,144.74],[2,1.76,175.72]],"ltp":1.73,"tv":20045.32,"id":9631939},{"batb":[[0,2.34,3],[1,2.32,266.93],[2,2.3,173.88]],"batl":[[0,2.6,5.46]],"ltp":2.44,"tv":5872.35,"id":9454286}]}]}
{"op":"mcm","clk":"4289978951","pt":1632496121575,"mc":[{"id":"1.188075669","rc":[{"batb":[[0,1.62,287.5],[1,1.61,280.76],[2,1.59,176.16]],"ltp":1.73,"tv":20045.32,"id":9631939},{"batl":[[0,2.6,3]],"ltp":2.44,"tv":5872.35,"id":9454286}]}]}
{"op":"mcm","clk":"4289979106","pt":1632496123679,"mc":[{"id":"1.188075669","rc":[{"batb":[[0,1.7,7.02],[1,1.62,287.5],[2,1.61,280.76]],"batl":[[0,1.73,5],[1,1.74,4],[2,1.75,144.74]],"ltp":1.73,"tv":20045.32,"id":9631939},{"batb":[[0,2.36,3],[1,2.34,3],[2,2.32,266.93]],"ltp":2.44,"tv":5872.35,"id":9454286}]}]}
{"op":"mcm","clk":"4289979384","pt":1632496127177,"mc":[{"id":"1.188075669","rc":[{"batb":[[0,1.7,284.02]],"batl":[[0,1.75,144.74],[1,1.76,175.72],[2,1.77,497.53]],"ltp":1.73,"tv":20045.32,"id":9631939},{"batb":[[0,2.32,263.93],[1,2.3,173.88],[2,2.28,3.41]],"ltp":2.44,"tv":5872.35,"id":9454286}]}]}
{"op":"mcm","clk":"4289979502","pt":1632496128596,"mc":[{"id":"1.188075669","rc":[{"batb":[[0,1.7,7.02]],"ltp":1.73,"tv":20045.32,"id":9631939}]}]}
{"op":"mcm","clk":"4289979802","pt":1632496132109,"mc":[{"id":"1.188075669","rc":[{"trd":[[1.7,72.06]],"batb":[[0,1.62,287.5],[1,1.61,275.76],[2,1.59,176.16]],"batl":[[0,1.75,145.6]],"ltp":1.7,"tv":20059.36,"id":9631939}],"tv":25931.71}]}
{"op":"mcm","clk":"4289979869","pt":1632496132909,"mc":[{"id":"1.188075669","rc":[{"batb":[[0,1.62,5],[1,1.61,17.68],[2,1.58,215.87]],"ltp":1.7,"tv":20059.36,"id":9631939},{"batl":[[1,2.64,2.93],[2,3,218.84]],"ltp":2.44,"tv":5872.35,"id":9454286}]}]}
{"op":"mcm","clk":"4289979943","pt":1632496133651,"mc":[{"id":"1.188075669","rc":[{"batl":[[0,1.7,1.33],[1,1.75,144.74],[2,1.76,175.72]],"ltp":1.7,"tv":20059.36,"id":9631939}]}]}
{"op":"mcm","clk":"4289980103","pt":1632496135127,"mc":[{"id":"1.188075669","rc":[{"batb":[[0,1.63,5],[1,1.62,5],[2,1.61,17.68]],"ltp":1.7,"tv":20059.36,"id":9631939}]}]}
{"op":"mcm","clk":"4289980192","pt":1632496136224,"mc":[{"id":"1.188075669","rc":[{"trd":[[1.7,74.71]],"batb":[[0,1.72,12.52],[1,1.7,135.02],[2,1.68,242.44]],"batl":[[0,1.75,144.74],[1,1.76,175.72],[2,1.77,497.53]],"ltp":1.7,"tv":20062.02,"id":9631939},{"batb":[[0,2.32,501.28]],"batl":[[0,2.48,385.58],[1,2.5,638.28],[2,2.52,374.24]],"ltp":2.44,"tv":5872.35,"id":9454286}],"tv":25934.37}]}
{"op":"mcm","clk":"4289980282","pt":1632496137207,"mc":[{"id":"1.188075669","rc":[{"trd":[[1.75,66.98]],"batb":[[1,1.7,302.72]],"batl":[[0,1.75,144.54],[1,1.76,192.77]],"ltp":1.75,"tv":20062.41,"id":9631939},{"batl":[[1,2.5,687.26]],"ltp":2.44,"tv":5872.35,"id":9454286}],"tv":25934.77}]}
{"op":"mcm","clk":"4289980378","pt":1632496138041,"mc":[{"id":"1.188075669","rc":[{"batb":[[0,2.32,523.73]],"ltp":2.44,"tv":5872.35,"id":9454286}]}]}
{"op":"mcm","clk":"4289980456","pt":1632496138625,"mc":[{"id":"1.188075669","rc":[{"trd":[[1.72,567.46]],"batb":[[0,1.7,302.72],[1,1.68,242.44],[2,1.67,110.43]],"ltp":1.72,"tv":20087.45,"id":9631939}],"tv":25959.81}]}
{"op":"mcm","clk":"4289980612","pt":1632496140150,"mc":[{"id":"1.188075669","rc":[{"batb":[[0,1.72,468],[1,1.7,302.72],[2,1.68,242.44]],"ltp":1.72,"tv":20087.45,"id":9631939}]}]}
{"op":"mcm","clk":"4289980684","pt":1632496140936,"mc":[{"id":"1.188075669","rc":[{"batb":[[0,1.7,302.72],[1,1.68,242.44],[2,1.67,37.13]],"ltp":1.72,"tv":20087.45,"id":9631939},{"batl":[[0,2.46,19.85],[1,2.48,385.58],[2,2.5,638.28]],"ltp":2.44,"tv":5872.35,"id":9454286}]}]}
{"op":"mcm","clk":"4289980953","pt":1632496144124,"mc":[{"id":"1.188075669","rc":[{"batb":[[1,1.68,315.2],[2,1.67,58.6]],"ltp":1.72,"tv":20087.45,"id":9631939},{"batl":[[1,2.48,434.89],[2,2.5,641.13]],"ltp":2.44,"tv":5872.35,"id":9454286}]}]}
{"op":"mcm","clk":"4289981100","pt":1632496145759,"mc":[{"id":"1.188075669","rc":[{"batb":[[0,2.32,515.82]],"ltp":2.44,"tv":5872.35,"id":9454286}]}]}
{"op":"mcm","clk":"4289981331","pt":1632496147966,"mc":[{"id":"1.188075669","rc":[{"batl":[[0,1.72,1.37],[1,1.75,144.54],[2,1.76,192.77]],"ltp":1.72,"tv":20087.45,"id":9631939}]}]}
{"op":"mcm","clk":"4289981720","pt":1632496152167,"mc":[{"id":"1.188075669","rc":[{"batl":[[2,1.76,175.72]],"ltp":1.72,"tv":20087.45,"id":9631939},{"batb":[[0,2.36,7.4],[1,2.32,515.82],[2,2.3,173.88]],"batl":[[0,2.42,7.62],[1,2.46,19.85],[2,2.48,49.31]],"ltp":2.44,"tv":5872.35,"id":9454286}]}]}
{"op":"mcm","clk":"4289981810","pt":1632496153171,"mc":[{"id":"1.188075669","rc":[{"batb":[[0,1.64,34.98],[1,1.62,217.02],[2,1.61,17.68]],"batl":[[1,1.79,19.5],[2,1.81,17.71]],"ltp":1.72,"tv":20087.45,"id":9631939},{"batb":[[0,2.26,2.98],[1,2.22,191.3],[2,2.02,3]],"batl":[[0,2.48,49.31],[1,2.58,5.75],[2,2.62,2.75]],"ltp":2.44,"tv":5872.35,"id":9454286}]}]}
{"op":"mcm","clk":"4289981919","pt":1632496154543,"mc":[{"id":"1.188075669","rc":[{"batb":[[0,1.64,16.41]],"ltp":1.72,"tv":20087.45,"id":9631939},{"batb":[[1,2.22,142.12]],"batl":[[0,2.58,3],[1,2.62,2.75],[2,2.64,2.93]],"ltp":2.44,"tv":5872.35,"id":9454286}]}]}
{"op":"mcm","clk":"4289982087","pt":1632496156062,"mc":[{"id":"1.188075669","rc":[{"batl":[[2,1.81,191.74]],"ltp":1.72,"tv":20087.45,"id":9631939},{"batb":[[2,2.2,3.22]],"ltp":2.44,"tv":5872.35,"id":9454286}]}]}
{"op":"mcm","clk":"4289982250","pt":1632496158045,"mc":[{"id":"1.188075669","rc":[{"batb":[[1,1.63,5],[2,1.62,217.02]],"ltp":1.72,"tv":20087.45,"id":9631939}]}]}
{"op":"mcm","clk":"4289982309","pt":1632496158882,"mc":[{"id":"1.188075669","rc":[{"trd":[[1.72,570.2]],"batb":[[0,1.75,158.99],[1,1.74,18.91],[2,1.73,219.1]],"batl":[[0,1.8,17.73],[1,1.81,191.74],[2,1.82,19.75]],"ltp":1.72,"tv":20090.19,"id":9631939},{"batb":[[0,2.24,208.89]],"batl":[[0,2.48,12.1],[1,2.58,3],[2,2.62,2.75]],"ltp":2.44,"tv":5872.35,"id":9454286}],"tv":25962.54}]}
{"op":"mcm","clk":"4289982461","pt":1632496160150,"mc":[{"id":"1.188075669","rc":[{"batb":[[0,1.76,149.82],[1,1.75,158.99],[2,1.74,18.91]],"batl":[[0,1.8,34.4]],"ltp":1.72,"tv":20090.19,"id":9631939},{"batl":[[0,2.38,51.07],[1,2.48,12.1],[2,2.58,3]],"ltp":2.44,"tv":5872.35,"id":9454286}]}]}
{"op":"mcm","clk":"4289982526","pt":1632496160949,"mc":[{"id":"1.188075669","rc":[{"batl":[[0,2.48,12.1],[1,2.58,3],[2,2.62,2.75]],"ltp":2.44,"tv":5872.35,"id":9454286}]}]}
{"op":"mcm","clk":"4289982617","pt":1632496161940,"mc":[{"id":"1.188075669","rc":[{"batl":[[1,1.81,174.03]],"ltp":1.72,"tv":20090.19,"id":9631939},{"batb":[[1,2.22,138.6],[2,2.2,6.22]],"batl":[[0,2.46,3],[1,2.48,12.1],[2,2.56,4]],"ltp":2.44,"tv":5872.35,"id":9454286}]}]}
{"op":"mcm","clk":"4289982716","pt":1632496163085,"mc":[{"id":"1.188075669","rc":[{"batb":[[0,1.76,304.82]],"ltp":1.72,"tv":20090.19,"id":9631939}]}]}
{"op":"mcm","clk":"4289982842","pt":1632496164137,"mc":[{"id":"1.188075669","rc":[{"batl":[[0,2.4,50.7],[1,2.46,3],[2,2.48,12.1]],"ltp":2.44,"tv":5872.35,"id":9454286}]}]}
{"op":"mcm","clk":"4289983003","pt":1632496166069,"mc":[{"id":"1.188075669","rc":[{"batl":[[1,2.44,3.33],[2,2.46,1010.43]],"ltp":2.44,"tv":5872.35,"id":9454286}]}]}
{"op":"mcm","clk":"4289983105","pt":1632496167172,"mc":[{"id":"1.188075669","rc":[{"batb":[[0,1.76,435.82]],"ltp":1.72,"tv":20090.19,"id":9631939},{"batl":[[1,2.44,24.5],[2,2.46,156.01]],"ltp":2.44,"tv":5872.35,"id":9454286}]}]}
{"op":"mcm","clk":"4289983122","pt":1632496167384,"mc":[{"id":"1.188075669","rc":[{"batl":[[1,2.44,3.33]],"ltp":2.44,"tv":5872.35,"id":9454286}]}]}
{"op":"mcm","clk":"4289983337","pt":1632496170056,"mc":[{"id":"1.188075669","rc":[{"trd":[[1.76,84.58]],"batb":[[0,1.76,401.09]],"ltp":1.76,"tv":20124.91,"id":9631939},{"trd":[[2.32,40.63]],"ltp":2.32,"tv":5898.68,"id":9454286}],"tv":26023.59}]}
{"op":"mcm","clk":"4289983387","pt":1632496170584,"mc":[{"id":"1.188075669","rc":[{"batl":[[0,2.38,27.08],[1,2.4,50.7],[2,2.44,3.33]],"ltp":2.32,"tv":5898.68,"id":9454286}]}]}
{"op":"mcm","clk":"4289983686","pt":1632496174176,"mc":[{"id":"1.188075669","rc":[{"batl":[[0,1.8,17.73]],"ltp":1.76,"tv":20124.91,"id":9631939}]}]}
{"op":"mcm","clk":"4289983767","pt":1632496175173,"mc":[{"id":"1.188075669","rc":[{"batb":[[0,1.73,70.22],[1,1.7,17.92],[2,1.68,212.1]],"batl":[[0,1.83,42.77],[1,1.84,19.53],[2,1.85,190.5]],"ltp":1.76,"tv":20124.91,"id":9631939},{"batb":[[0,2.2,3],[1,2.18,152.11],[2,2.16,175.1]],"batl":[[0,2.4,50.7],[1,2.44,3.33],[2,2.46,153.01]],"ltp":2.32,"tv":5898.68,"id":9454286}]}]}
{"op":"mcm","clk":"4289983859","pt":1632496176171,"mc":[{"id":"1.188075669","rc":[{"batb":[[0,1.7,17.92],[1,1.68,212.1],[2,1.67,430.65]],"ltp":1.76,"tv":20124.91,"id":9631939},{"batl":[[0,2.44,3.33],[1,2.46,153.01],[2,2.48,191.11]],"ltp":2.32,"tv":5898.68,"id":9454286}]}]}
{"op":"mcm","clk":"4289983892","pt":1632496176483,"mc":[{"id":"1.188075669","rc":[{"batb":[[0,1.68,212.1],[1,1.67,430.65],[2,1.65,6]],"ltp":1.76,"tv":20124.91,"id":9631939},{"batl":[[0,2.46,153.01],[1,2.48,191.11],[2,2.5,2.71]],"ltp":2.32,"tv":5898.68,"id":9454286}]}]}
{"op":"mcm","clk":"4289984031","pt":1632496178109,"mc":[{"id":"1.188075669","rc":[{"batb":[[1,1.67,401.71],[2,1.66,306.39]],"ltp":1.76,"tv":20124.91,"id":9631939},{"batb":[[1,2.18,156.11]],"ltp":2.32,"tv":5898.68,"id":9454286}]}]}
{"op":"mcm","clk":"4289984181","pt":1632496179678,"mc":[{"id":"1.188075669","rc":[{"batb":[[0,1.68,218.1],[1,1.67,407.71]],"ltp":1.76,"tv":20124.91,"id":9631939}]}]}
{"op":"mcm","clk":"4289984291","pt":1632496180988,"mc":[{"id":"1.188075669","rc":[{"batl":[[0,2.46,153.1]],"ltp":2.32,"tv":5898.68,"id":9454286}]}]}
{"op":"mcm","clk":"4289984704","pt":1632496186098,"mc":[{"id":"1.188075669","rc":[{"batb":[[0,1.68,6],[1,1.67,24.47],[2,1.66,179.09]],"ltp":1.76,"tv":20124.91,"id":9631939},{"batl":[[0,2.5,2.8],[1,2.62,2.75],[2,2.64,2.93]],"ltp":2.32,"tv":5898.68,"id":9454286}]}]}
{"op":"mcm","clk":"4289984780","pt":1632496186995,"mc":[{"id":"1.188075669","rc":[{"batl":[[0,1.82,20.25],[1,1.83,42.77],[2,1.84,19.53]],"ltp":1.76,"tv":20124.91,"id":9631939}]}]}
{"op":"mcm","clk":"4289984875","pt":1632496187999,"mc":[{"id":"1.188075669","rc":[{"batl":[[0,1.83,42.77],[1,1.84,19.53],[2,1.85,190.5]],"ltp":1.76,"tv":20124.91,"id":9631939},{"batb":[[0,2.18,152.11],[1,2.16,175.1],[2,2.14,154.88]],"ltp":2.32,"tv":5898.68,"id":9454286}]}]}
{"op":"mcm","clk":"4289984984","pt":1632496189212,"mc":[{"id":"1.188075669","rc":[{"batb":[[0,1.81,118.55],[1,1.79,195.26],[2,1.78,34.83]],"ltp":1.76,"tv":20124.91,"id":9631939},{"batl":[[0,2.24,7.09],[1,2.28,419.4],[2,2.3,407.08]],"ltp":2.32,"tv":5898.68,"id":9454286}]}]}
{"op":"mcm","clk":"4289985090","pt":1632496190218,"mc":[{"id":"1.188075669","rc":[{"batb":[[0,1.81,253.77]],"batl":[[1,1.84,35.83]],"ltp":1.76,"tv":20124.91,"id":9631939},{"batl":[[2,2.3,459.7]],"ltp":2.32,"tv":5898.68,"id":9454286}]}]}
{"op":"mcm","clk":"4289985412","pt":1632496194123,"mc":[{"id":"1.188075669","rc":[{"trd":[[1.83,161.33]],"batb":[[0,1.81,350.77]],"batl":[[0,1.83,16.36]],"ltp":1.83,"tv":20151.33,"id":9631939},{"trd":[[2.2,29.09]],"batl":[[2,2.3,407.08]],"ltp":2.2,"tv":5920.68,"id":9454286}],"tv":26072.01}]}
{"op":"mcm","clk":"4289985495","pt":1632496195027,"mc":[{"id":"1.188075669","rc":[{"trd":[[1.81,24.58]],"batb":[[0,1.81,344.62]],"ltp":1.81,"tv":20163.62,"id":9631939}],"tv":26084.3}]}
{"op":"mcm","clk":"4289985605","pt":1632496196139,"mc":[{"id":"1.188075669","rc":[{"batb":[[0,1.81,232.22],[1,1.78,34.83],[2,1.76,396.74]],"batl":[[2,1.85,209.8]],"ltp":1.81,"tv":20163.62,"id":9631939}]}]}
{"op":"mcm","clk":"4289985637","pt":1632496196349,"mc":[{"id":"1.188075669","rc":[{"batl":[[2,1.85,190.5]],"ltp":1.81,"tv":20163.62,"id":9631939}]}]}
{"op":"mcm","clk":"4289985743","pt":1632496197451,"mc":[{"id":"1.188075669","rc":[{"batb":[[0,1.81,323.22],[1,1.78,102.76]],"ltp":1.81,"tv":20163.62,"id":9631939},{"batl":[[1,2.28,472.43]],"ltp":2.2,"tv":5920.68,"id":9454286}]}]}
{"op":"mcm","clk":"4289985838","pt":1632496198507,"mc":[{"id":"1.188075669","rc":[{"batb":[[1,1.8,212.21],[2,1.78,301.92]],"ltp":1.81,"tv":20163.62,"id":9631939}]}]}
{"op":"mcm","clk":"4289985921","pt":1632496199566,"mc":[{"id":"1.188075669","rc":[{"batl":[[2,1.85,209.2]],"ltp":1.81,"tv":20163.62,"id":9631939}]}]}
{"op":"mcm","clk":"4289986381","pt":1632496204128,"mc":[{"id":"1.188075669","rc":[{"batb":[[0,1.78,67.93],[1,1.76,13.98],[2,1.75,215.47]],"batl":[[1,1.85,18.7],[2,1.86,96.1]],"ltp":1.81,"tv":20163.62,"id":9631939},{"batb":[[0,2.16,3.53],[1,2.12,159.2],[2,2.1,230.29]],"batl":[[0,2.28,53.12],[1,2.32,2.86],[2,2.34,181.08]],"ltp":2.2,"tv":5920.68,"id":9454286}]}]}
{"op":"mcm","clk":"4289986400","pt":1632496204339,"mc":[{"id":"1.188075669","rc":[{"batl":[[1,1.86,96.1],[2,1.89,184.23]],"ltp":1.81,"tv":20163.62,"id":9631939}]}]}
{"op":"mcm","clk":"4289986515","pt":1632496205443,"mc":[{"id":"1.188075669","rc":[{"batb":[[0,1.75,215.47],[1,1.74,438.03],[2,1.69,5]],"ltp":1.81,"tv":20163.62,"id":9631939},{"batl":[[0,2.34,181.17],[1,2.36,193.77],[2,2.42,3]],"ltp":2.2,"tv":5920.68,"id":9454286}]}]}
{"op":"mcm","clk":"4289986669","pt":1632496207155,"mc":[{"id":"1.188075669","rc":[{"batb":[[1,1.74,570.2],[2,1.72,223.37]],"ltp":1.81,"tv":20163.62,"id":9631939}]}]}
{"op":"mcm","clk":"4289986840","pt":1632496209047,"mc":[{"id":"1.188075669","rc":[{"batb":[[0,1.75,4],[1,1.74,175.9],[2,1.69,5]],"ltp":1.81,"tv":20163.62,"id":9631939},{"batl":[[0,2.34,3.09],[1,2.36,3.07]],"ltp":2.2,"tv":5920.68,"id":9454286}]}]}
{"op":"mcm","clk":"4289987040","pt":1632496211176,"mc":[{"id":"1.188075669","rc":[{"trd":[[1.83,194.06],[1.85,1169.64]],"batb":[[0,1.85,2202.84],[1,1.83,2090.16],[2,1.82,2028.68]],"batl":[[0,1.86,96.1],[1,1.89,184.23],[2,1.9,216.7]],"ltp":1.85,"tv":20237.76,"id":9631939},{"batb":[[1,2.12,156.2]],"batl":[[0,2.24,235.9],[1,2.34,3],[2,2.36,15.78]],"ltp":2.2,"tv":5920.68,"id":9454286}],"tv":26158.44}]}
{"op":"mcm","clk":"4289987157","pt":1632496212168,"mc":[{"id":"1.188075669","rc":[{"trd":[[1.86,213.24]],"batb":[[0,1.86,28.49],[1,1.85,343.06],[2,1.83,704.25]],"batl":[[0,1.88,15.96],[1,1.89,198.36]],"ltp":1.86,"tv":20429.87,"id":9631939},{"batl":[[0,2.2,12.69],[1,2.24,235.9],[2,2.34,3]],"ltp":2.2,"tv":5920.68,"id":9454286}],"tv":26350.55}]}
{"op":"mcm","clk":"4289987271","pt":1632496213172,"mc":[{"id":"1.188075669","rc":[{"batb":[[0,2.12,156.2],[1,2.1,230.29],[2,2.08,168.96]],"batl":[[1,2.24,289.78],[2,2.32,15.45]],"ltp":2.2,"tv":5920.68,"id":9454286}]}]}
{"op":"mcm","clk":"4289987339","pt":1632496213850,"mc":[{"id":"1.188075669","rc":[{"batl":[[2,2.32,19.45]],"ltp":2.2,"tv":5920.68,"id":9454286}]}]}
{"op":"mcm","clk":"4289987580","pt":1632496216175,"mc":[{"id":"1.188075669","rc":[{"batl":[[0,2.14,27.82],[1,2.2,12.69],[2,2.24,289.78]],"ltp":2.2,"tv":5920.68,"id":9454286}]}]}
{"op":"mcm","clk":"4289987657","pt":1632496216859,"mc":[{"id":"1.188075669","rc":[{"trd":[[1.86,218.54]],"batb":[[0,1.86,25.84]],"ltp":1.86,"tv":20435.17,"id":9631939},{"batl":[[0,2.2,12.69],[1,2.24,235.9],[2,2.32,19.45]],"ltp":2.2,"tv":5920.68,"id":9454286}],"tv":26355.85}]}
{"op":"mcm","clk":"4289987813","pt":1632496218545,"mc":[{"id":"1.188075669","rc":[{"batl":[[2,2.26,138.25]],"ltp":2.2,"tv":5920.68,"id":9454286}]}]}
{"op":"mcm","clk":"4289987948","pt":1632496220070,"mc":[{"id":"1.188075669","rc":[{"trd":[[1.87,483.93]],"batb":[[0,1.87,186.21],[1,1.86,25.84],[2,1.85,343.06]],"ltp":1.87,"tv":20452.74,"id":9631939},{"batl":[[1,2.22,54.32],[2,2.24,235.9]],"ltp":2.2,"tv":5920.68,"id":9454286}],"tv":26373.42}]}
{"op":"mcm","clk":"4289988232","pt":1632496223072,"mc":[{"id":"1.188075669","rc":[{"batb":[[0,1.87,289.21]],"ltp":1.87,"tv":20452.74,"id":9631939}]}]}
{"op":"mcm","clk":"4289988252","pt":1632496223283,"mc":[{"id":"1.188075669","rc":[{"batb":[[2,1.85,165.29]],"ltp":1.87,"tv":20452.74,"id":9631939}]}]}
{"op":"mcm","clk":"4289988709","pt":1632496228375,"mc":[{"id":"1.188075669","rc":[{"batl":[[1,1.89,14.13]],"ltp":1.87,"tv":20452.74,"id":9631939},{"batb":[[0,2.1,230.29],[1,2.08,168.96],[2,2.02,4.24]],"ltp":2.2,"tv":5920.68,"id":9454286}]}]}
