{"op":"mcm","clk":"4223822905","pt":1631450287785,"mc":[{"id":"1.187528277","rc":[{"trd":[[1.43,95860.33]],"batl":[[0,1.43,9617.93]],"ltp":1.43,"tv":377076.24,"id":2249229}],"tv":455026.36}]}
{"op":"mcm","clk":"4223823209","pt":1631450289377,"mc":[{"id":"1.187528277","rc":[{"trd":[[3.3,16457.67]],"batb":[[0,3.3,3404.95]],"ltp":3.3,"tv":77960.76,"id":19924831}],"tv":455037.0}]}
{"op":"mcm","clk":"4223827010","pt":1631450311144,"mc":[{"id":"1.187528277","rc":[{"trd":[[1.42,165283.8]],"batb":[[0,1.42,27625.98]],"ltp":1.42,"tv":378076.24,"id":2249229}],"tv":456037.0}]}
{"op":"mcm","clk":"4223827134","pt":1631450311843,"mc":[{"id":"1.187528277","rc":[{"batb":[[0,1.42,27607.83]],"ltp":1.42,"tv":378076.24,"id":2249229}]}]}
{"op":"mcm","clk":"4223828252","pt":1631450317343,"mc":[{"id":"1.187528277","rc":[{"trd":[[1.42,165303.8]],"batb":[[0,1.42,27597.83]],"ltp":1.42,"tv":378096.24,"id":2249229}],"tv":456057.0}]}
{"op":"mcm","clk":"4223828833","pt":1631450320633,"mc":[{"id":"1.187528277","rc":[{"batb":[[0,3.3,5148.86]],"batl":[[0,3.35,3259.8]],"ltp":3.3,"tv":77960.76,"id":19924831}]}]}
{"op":"mcm","clk":"4223829169","pt":1631450322474,"mc":[{"id":"1.187528277","rc":[{"batb":[[0,1.42,27615.98]],"ltp":1.42,"tv":378096.24,"id":2249229}]}]}
{"op":"mcm","clk":"4223829310","pt":1631450323159,"mc":[{"id":"1.187528277","rc":[{"batb":[[0,1.42,27597.83]],"ltp":1.42,"tv":378096.24,"id":2249229}]}]}
{"op":"mcm","clk":"4223829905","pt":1631450326259,"mc":[{"id":"1.187528277","rc":[{"trd":[[1.42,165503.8]],"batb":[[0,1.42,27497.83]],"ltp":1.42,"tv":378296.24,"id":2249229}],"tv":456257.0}]}
{"op":"mcm","clk":"4223831489","pt":1631450334590,"mc":[{"id":"1.187528277","rc":[{"trd":[[1.42,166035.59]],"batb":[[0,1.42,27250.09]],"ltp":1.42,"tv":378828.03,"id":2249229}],"tv":456788.79}]}
{"op":"mcm","clk":"4223831519","pt":1631450334758,"mc":[{"id":"1.187528277","rc":[{"batb":[[0,1.42,27231.94]],"ltp":1.42,"tv":378828.03,"id":2249229}]}]}
{"op":"mcm","clk":"4223832989","pt":1631450342502,"mc":[{"id":"1.187528277","rc":[{"trd":[[1.42,166056.86]],"batb":[[0,1.42,27239.45]],"ltp":1.42,"tv":378849.3,"id":2249229}],"tv":456810.06}]}
{"op":"mcm","clk":"4223833106","pt":1631450343112,"mc":[{"id":"1.187528277","rc":[{"batb":[[0,1.42,27221.3]],"ltp":1.42,"tv":378849.3,"id":2249229}]}]}
{"op":"mcm","clk":"4223836114","pt":1631450358316,"mc":[{"id":"1.187528277","rc":[{"batl":[[0,1.43,10239.72]],"ltp":1.42,"tv":378849.3,"id":2249229}]}]}
{"op":"mcm","clk":"4223839063","pt":1631450373930,"mc":[{"id":"1.187528277","rc":[{"trd":[[1.42,166076.86]],"batb":[[0,1.42,27211.3]],"ltp":1.42,"tv":378869.3,"id":2249229}],"tv":456830.06}]}
{"op":"mcm","clk":"4223841355","pt":1631450385561,"mc":[{"id":"1.187528277","rc":[{"batl":[[1,1.44,18744.56]],"ltp":1.42,"tv":378869.3,"id":2249229}]}]}
{"op":"mcm","clk":"4223857612","pt":1631450464473,"mc":[{"id":"1.187528277","rc":[{"trd":[[1.42,166087.08]],"batb":[[0,1.42,27206.19]],"ltp":1.42,"tv":378879.52,"id":2249229}],"tv":456840.28}]}
{"op":"mcm","clk":"4223859801","pt":1631450475690,"mc":[{"id":"1.187528277","rc":[{"trd":[[1.42,166287.08]],"batb":[[0,1.42,27106.19]],"ltp":1.42,"tv":379079.52,"id":2249229}],"tv":457040.28}]}
{"op":"mcm","clk":"4223864570","pt":1631450500701,"mc":[{"id":"1.187528277","rc":[{"trd":[[3.35,24303.35]],"batl":[[0,3.35,3252.94]],"ltp":3.35,"tv":77974.48,"id":19924831}],"tv":457054.0}]}
{"op":"mcm","clk":"4223873818","pt":1631450539590,"mc":[{"id":"1.187528277","rc":[{"trd":[[3.35,24391.32]],"batl":[[0,3.35,3208.96]],"ltp":3.35,"tv":78062.44,"id":19924831},{"batl":[[0,1.43,10367.83]],"ltp":1.42,"tv":379079.52,"id":2249229}],"tv":457141.97}]}
{"op":"mcm","clk":"4223894845","pt":1631450637447,"mc":[{"id":"1.187528277","rc":[{"batb":[[1,3.25,2981.81]],"ltp":3.35,"tv":78062.44,"id":19924831},{"batl":[[1,1.44,18726.63]],"ltp":1.42,"tv":379079.52,"id":2249229}]}]}
{"op":"mcm","clk":"4223926847","pt":1631450795700,"mc":[{"id":"1.187528277","rc":[{"trd":[[1.42,167254.53]],"batb":[[0,1.42,26622.46]],"ltp":1.42,"tv":380046.98,"id":2249229}],"tv":458109.42}]}
{"op":"mcm","clk":"4223928429","pt":1631450803898,"mc":[{"id":"1.187528277","rc":[{"batl":[[1,1.44,63807.77]],"ltp":1.42,"tv":380046.98,"id":2249229}]}]}
{"op":"mcm","clk":"4223928691","pt":1631450805314,"mc":[{"id":"1.187528277","rc":[{"batl":[[0,3.35,2453.96]],"ltp":3.35,"tv":78062.44,"id":19924831}]}]}
{"op":"mcm","clk":"4223938008","pt":1631450855681,"mc":[{"id":"1.187528277","rc":[{"batl":[[1,1.44,57842.91]],"ltp":1.42,"tv":380046.98,"id":2249229}]}]}
{"op":"mcm","clk":"4223938024","pt":1631450855789,"mc":[{"id":"1.187528277","rc":[{"batl":[[0,1.43,16332.69]],"ltp":1.42,"tv":380046.98,"id":2249229}]}]}
{"op":"mcm","clk":"4223951633","pt":1631450875947,"mc":[{"id":"1.187528277","rc":[{"trd":[[1.42,167334.53]],"batb":[[0,1.42,26582.46]],"ltp":1.42,"tv":380126.97,"id":2249229}],"tv":458189.42}]}
{"op":"mcm","clk":"4223955940","pt":1631450899993,"mc":[{"id":"1.187528277","rc":[{"trd":[[1.42,167338.53]],"batb":[[0,1.42,26580.46]],"ltp":1.42,"tv":380130.97,"id":2249229}],"tv":458193.42}]}
{"op":"mcm","clk":"4223961803","pt":1631450935029,"mc":[{"id":"1.187528277","rc":[{"batl":[[0,1.43,15609.67]],"ltp":1.42,"tv":380130.97,"id":2249229}]}]}
{"op":"mcm","clk":"4223968275","pt":1631450972305,"mc":[{"id":"1.187528277","rc":[{"trd":[[1.43,96105.19]],"batl":[[0,1.43,15487.25]],"ltp":1.43,"tv":380375.83,"id":2249229}],"tv":458438.28}]}
{"op":"mcm","clk":"4223976141","pt":1631451020113,"mc":[{"id":"1.187528277","rc":[{"batb":[[0,1.42,26900.61]],"ltp":1.43,"tv":380375.83,"id":2249229}]}]}
{"op":"mcm","clk":"4223977080","pt":1631451025917,"mc":[{"id":"1.187528277","rc":[{"trd":[[3.35,24468.2]],"batl":[[0,3.35,2415.52]],"ltp":3.35,"tv":78139.33,"id":19924831}],"tv":458515.17}]}
{"op":"mcm","clk":"4223977230","pt":1631451026816,"mc":[{"id":"1.187528277","rc":[{"batl":[[0,3.35,1250.02]],"ltp":3.35,"tv":78139.33,"id":19924831}]}]}
{"op":"mcm","clk":"4223977575","pt":1631451029148,"mc":[{"id":"1.187528277","rc":[{"batl":[[0,3.35,1136.13]],"ltp":3.35,"tv":78139.33,"id":19924831}]}]}
{"op":"mcm","clk":"4223978064","pt":1631451031930,"mc":[{"id":"1.187528277","rc":[{"trd":[[3.35,24766.44]],"batl":[[0,3.35,987.01]],"ltp":3.35,"tv":78437.56,"id":19924831}],"tv":458813.4}]}
{"op":"mcm","clk":"4223981483","pt":1631451051371,"mc":[{"id":"1.187528277","rc":[{"trd":[[1.42,167352.53]],"batb":[[0,1.42,26893.61]],"ltp":1.42,"tv":380389.83,"id":2249229}],"tv":458827.4}]}
{"op":"mcm","clk":"4223988677","pt":1631451094139,"mc":[{"id":"1.187528277","rc":[{"trd":[[3.3,16464.5]],"batb":[[0,3.3,5145.44]],"ltp":3.3,"tv":78444.4,"id":19924831}],"tv":458834.24}]}
{"op":"mcm","clk":"4223992971","pt":1631451121205,"mc":[{"id":"1.187528277","rc":[{"batl":[[0,1.43,15871.57]],"ltp":1.42,"tv":380389.83,"id":2249229}]}]}
{"op":"mcm","clk":"4223993109","pt":1631451121963,"mc":[{"id":"1.187528277","rc":[{"trd":[[3.35,24813.24]],"batl":[[0,3.35,963.61]],"ltp":3.35,"tv":78491.2,"id":19924831}],"tv":458881.04}]}
{"op":"mcm","clk":"4224002639","pt":1631451184800,"mc":[{"id":"1.187528277","rc":[{"trd":[[1.42,167367.15]],"batb":[[0,1.42,26886.3]],"ltp":1.42,"tv":380404.45,"id":2249229}],"tv":458895.66}]}
{"op":"mcm","clk":"4224005321","pt":1631451203440,"mc":[{"id":"1.187528277","rc":[{"trd":[[1.42,167968.17]],"batb":[[0,1.42,26585.79]],"ltp":1.42,"tv":381005.47,"id":2249229}],"tv":459496.68}]}
{"op":"mcm","clk":"4224013335","pt":1631451257224,"mc":[{"id":"1.187528277","rc":[{"batl":[[0,1.43,19473.02]],"ltp":1.42,"tv":381005.47,"id":2249229}]}]}
{"op":"mcm","clk":"4224017626","pt":1631451284080,"mc":[{"id":"1.187528277","rc":[{"batl":[[0,1.43,19723.02]],"ltp":1.42,"tv":381005.47,"id":2249229}]}]}
{"op":"mcm","clk":"4224039593","pt":1631451415331,"mc":[{"id":"1.187528277","rc":[{"trd":[[1.42,167973.49]],"batb":[[0,1.42,29814.3]],"ltp":1.42,"tv":381010.79,"id":2249229}],"tv":459502.0}]}
{"op":"mcm","clk":"4224045989","pt":1631451454306,"mc":[{"id":"1.187528277","rc":[{"batl":[[2,1.45,14041.89]],"ltp":1.42,"tv":381010.79,"id":2249229}]}]}
{"op":"mcm","clk":"4224049053","pt":1631451472139,"mc":[{"id":"1.187528277","rc":[{"batb":[[0,1.42,26583.13]],"ltp":1.42,"tv":381010.79,"id":2249229}]}]}
{"op":"mcm","clk":"4224049483","pt":1631451474959,"mc":[{"id":"1.187528277","rc":[{"trd":[[1.43,96117.2]],"batb":[[0,1.42,29814.3]],"batl":[[0,1.43,19717.01]],"ltp":1.43,"tv":381022.8,"id":2249229}],"tv":459514.0}]}
{"op":"mcm","clk":"4224050595","pt":1631451481270,"mc":[{"id":"1.187528277","rc":[{"batb":[[1,3.25,4725.72]],"ltp":3.35,"tv":78491.2,"id":19924831}]}]}
{"op":"mcm","clk":"4224053669","pt":1631451498778,"mc":[{"id":"1.187528277","rc":[{"trd":[[3.3,16474.7]],"batb":[[0,3.3,5140.34]],"ltp":3.3,"tv":78501.4,"id":19924831}],"tv":459524.2}]}
{"op":"mcm","clk":"4224054095","pt":1631451501415,"mc":[{"id":"1.187528277","rc":[{"trd":[[3.3,16645.51]],"batb":[[0,3.3,5054.94]],"ltp":3.3,"tv":78672.2,"id":19924831}],"tv":459695.0}]}
{"op":"mcm","clk":"4224054235","pt":1631451502312,"mc":[{"id":"1.187528277","rc":[{"batb":[[0,1.42,26583.13]],"ltp":1.43,"tv":381022.8,"id":2249229}]}]}
{"op":"mcm","clk":"4224055289","pt":1631451509019,"mc":[{"id":"1.187528277","rc":[{"batb":[[0,3.3,5481.96]],"ltp":3.3,"tv":78672.2,"id":19924831}]}]}
{"op":"mcm","clk":"4224073352","pt":1631451612431,"mc":[{"id":"1.187528277","rc":[{"trd":[[3.3,17153.09]],"batb":[[0,3.3,5228.17]],"ltp":3.3,"tv":79179.78,"id":19924831}],"tv":460202.58}]}
{"op":"mcm","clk":"4224075409","pt":1631451622880,"mc":[{"id":"1.187528277","rc":[{"trd":[[3.35,26003.23]],"batl":[[0,3.35,368.61]],"ltp":3.35,"tv":80369.78,"id":19924831}],"tv":461392.58}]}
{"op":"mcm","clk":"4224081999","pt":1631451656124,"mc":[{"id":"1.187528277","rc":[{"batl":[[1,3.4,1601.17]],"ltp":3.35,"tv":80369.78,"id":19924831}]}]}
{"op":"mcm","clk":"4224082135","pt":1631451656823,"mc":[{"id":"1.187528277","rc":[{"batl":[[0,3.35,667.53]],"ltp":3.35,"tv":80369.78,"id":19924831}]}]}
{"op":"mcm","clk":"4224086270","pt":1631451677871,"mc":[{"id":"1.187528277","rc":[{"batl":[[0,3.35,2274.06]],"ltp":3.35,"tv":80369.78,"id":19924831}]}]}
{"op":"mcm","clk":"4224090274","pt":1631451697398,"mc":[{"id":"1.187528277","rc":[{"batb":[[0,1.42,28316.84]],"ltp":1.43,"tv":381022.8,"id":2249229}]}]}
{"op":"mcm","clk":"4224094078","pt":1631451716243,"mc":[{"id":"1.187528277","rc":[{"trd":[[3.3,17703.09]],"batb":[[0,3.3,4953.17]],"ltp":3.3,"tv":80919.78,"id":19924831}],"tv":461942.58}]}
{"op":"mcm","clk":"4224094395","pt":1631451717955,"mc":[{"id":"1.187528277","rc":[{"batb":[[0,1.42,31548.01]],"batl":[[0,1.43,18813.24]],"ltp":1.43,"tv":381022.8,"id":2249229}]}]}
{"op":"mcm","clk":"4224101944","pt":1631451755518,"mc":[{"id":"1.187528277","rc":[{"batb":[[0,1.42,28316.84]],"batl":[[0,1.43,18451.74]],"ltp":1.43,"tv":381022.8,"id":2249229}]}]}
{"op":"mcm","clk":"4224101963","pt":1631451755722,"mc":[{"id":"1.187528277","rc":[{"batb":[[0,1.42,31548.01]],"ltp":1.43,"tv":381022.8,"id":2249229}]}]}
{"op":"mcm","clk":"4224102895","pt":1631451760932,"mc":[{"id":"1.187528277","rc":[{"trd":[[3.3,17703.71]],"batb":[[0,3.3,4952.86]],"ltp":3.3,"tv":80920.41,"id":19924831}],"tv":461943.21}]}
{"op":"mcm","clk":"4224114413","pt":1631451818547,"mc":[{"id":"1.187528277","rc":[{"batb":[[1,3.25,4736.82]],"ltp":3.3,"tv":80920.41,"id":19924831},{"batl":[[1,1.44,57861.69]],"ltp":1.43,"tv":381022.8,"id":2249229}]}]}
{"op":"mcm","clk":"4224134946","pt":1631451902702,"mc":[{"id":"1.187528277","rc":[{"trd":[[1.43,96756.64]],"batl":[[0,1.43,18132.02]],"ltp":1.43,"tv":381662.24,"id":2249229}],"tv":462582.65}]}
{"op":"mcm","clk":"4224135170","pt":1631451903683,"mc":[{"id":"1.187528277","rc":[{"batb":[[0,1.42,28316.84]],"ltp":1.43,"tv":381662.24,"id":2249229}]}]}
{"op":"mcm","clk":"4224135483","pt":1631451905096,"mc":[{"id":"1.187528277","rc":[{"trd":[[1.43,97288.43]],"batb":[[0,1.42,31548.01]],"batl":[[0,1.43,17866.13]],"ltp":1.43,"tv":382194.03,"id":2249229}],"tv":463114.44}]}
{"op":"mcm","clk":"4224135845","pt":1631451906573,"mc":[{"id":"1.187528277","rc":[{"batb":[[0,1.42,28316.84]],"ltp":1.43,"tv":382194.03,"id":2249229}]}]}
{"op":"mcm","clk":"4224144158","pt":1631451944066,"mc":[{"id":"1.187528277","rc":[{"trd":[[3.35,26021.32]],"batl":[[0,3.35,2265.02]],"ltp":3.35,"tv":80938.49,"id":19924831}],"tv":463132.52}]}
{"op":"mcm","clk":"4224149018","pt":1631451969335,"mc":[{"id":"1.187528277","rc":[{"trd":[[1.42,168292.56]],"batb":[[0,1.42,28157.31]],"ltp":1.42,"tv":382513.1,"id":2249229}],"tv":463451.59}]}
{"op":"mcm","clk":"4224157852","pt":1631452012379,"mc":[{"id":"1.187528277","rc":[{"trd":[[1.42,168470.17]],"batb":[[0,1.42,28068.5]],"ltp":1.42,"tv":382690.72,"id":2249229}],"tv":463629.21}]}
{"op":"mcm","clk":"4224169888","pt":1631452067590,"mc":[{"id":"1.187528277","rc":[{"batb":[[1,3.25,4728.28]],"ltp":3.35,"tv":80938.49,"id":19924831},{"batl":[[1,1.44,57854.01]],"ltp":1.42,"tv":382690.72,"id":2249229}]}]}
{"op":"mcm","clk":"4224170981","pt":1631452072503,"mc":[{"id":"1.187528277","rc":[{"batb":[[0,3.3,5352.86]],"ltp":3.35,"tv":80938.49,"id":19924831}]}]}
{"op":"mcm","clk":"4224171052","pt":1631452072784,"mc":[{"id":"1.187528277","rc":[{"batb":[[0,1.42,31297.62]],"ltp":1.42,"tv":382690.72,"id":2249229}]}]}
{"op":"mcm","clk":"4224174413","pt":1631452088125,"mc":[{"id":"1.187528277","rc":[{"trd":[[1.42,168473.7]],"batb":[[0,1.42,31295.86]],"ltp":1.42,"tv":382694.24,"id":2249229}],"tv":463632.73}]}
{"op":"mcm","clk":"4224174749","pt":1631452089833,"mc":[{"id":"1.187528277","rc":[{"batb":[[0,1.42,28066.74]],"ltp":1.42,"tv":382694.24,"id":2249229}]}]}
{"op":"mcm","clk":"4224176461","pt":1631452097954,"mc":[{"id":"1.187528277","rc":[{"batb":[[1,3.25,4717.18]],"ltp":3.35,"tv":80938.49,"id":19924831},{"batl":[[1,1.44,57844.61]],"ltp":1.42,"tv":382694.24,"id":2249229}]}]}
{"op":"mcm","clk":"4224180858","pt":1631452118088,"mc":[{"id":"1.187528277","rc":[{"trd":[[3.35,26039.4]],"batl":[[0,3.35,2255.97]],"ltp":3.35,"tv":80956.58,"id":19924831},{"batb":[[0,1.42,31295.86]],"ltp":1.42,"tv":382694.24,"id":2249229}],"tv":463650.82}]}
{"op":"mcm","clk":"4224182662","pt":1631452126084,"mc":[{"id":"1.187528277","rc":[{"trd":[[1.42,168580.05]],"batb":[[0,1.42,31242.68]],"ltp":1.42,"tv":382800.59,"id":2249229}],"tv":463757.17}]}
{"op":"mcm","clk":"4224182860","pt":1631452127003,"mc":[{"id":"1.187528277","rc":[{"batb":[[0,1.42,28013.56]],"ltp":1.42,"tv":382800.59,"id":2249229}]}]}
{"op":"mcm","clk":"4224184231","pt":1631452133185,"mc":[{"id":"1.187528277","rc":[{"trd":[[3.3,17720.46]],"batb":[[0,3.3,5344.48]],"ltp":3.3,"tv":80973.32,"id":19924831}],"tv":463773.92}]}
{"op":"mcm","clk":"4224185316","pt":1631452137883,"mc":[{"id":"1.187528277","rc":[{"batb":[[1,3.25,4726.57]],"ltp":3.3,"tv":80973.32,"id":19924831},{"batl":[[1,1.44,57854.01]],"ltp":1.42,"tv":382800.59,"id":2249229}]}]}
{"op":"mcm","clk":"4224185564","pt":1631452139114,"mc":[{"id":"1.187528277","rc":[{"batb":[[1,3.25,4737.74]],"ltp":3.3,"tv":80973.32,"id":19924831}]}]}
{"op":"mcm","clk":"4224187207","pt":1631452146511,"mc":[{"id":"1.187528277","rc":[{"trd":[[1.42,168899.13]],"batb":[[0,1.42,27854.03]],"ltp":1.42,"tv":383119.67,"id":2249229}],"tv":464093.0}]}
{"op":"mcm","clk":"4224187254","pt":1631452146736,"mc":[{"id":"1.187528277","rc":[{"batb":[[0,1.42,31083.15]],"ltp":1.42,"tv":383119.67,"id":2249229}]}]}
{"op":"mcm","clk":"4224189293","pt":1631452155717,"mc":[{"id":"1.187528277","rc":[{"batl":[[1,1.44,57854.09]],"ltp":1.42,"tv":383119.67,"id":2249229}]}]}
{"op":"mcm","clk":"4224189604","pt":1631452157140,"mc":[{"id":"1.187528277","rc":[{"batb":[[2,1.4,45378.69]],"ltp":1.42,"tv":383119.67,"id":2249229}]}]}
{"op":"mcm","clk":"4224190440","pt":1631452160624,"mc":[{"id":"1.187528277","rc":[{"batb":[[1,1.41,40762.09]],"ltp":1.42,"tv":383119.67,"id":2249229}]}]}
{"op":"mcm","clk":"4224190557","pt":1631452161222,"mc":[{"id":"1.187528277","rc":[{"batl":[[0,1.43,17866.21]],"ltp":1.42,"tv":383119.67,"id":2249229}]}]}
{"op":"mcm","clk":"4224190959","pt":1631452162934,"mc":[{"id":"1.187528277","rc":[{"batb":[[0,1.42,31083.23]],"ltp":1.42,"tv":383119.67,"id":2249229}]}]}
{"op":"mcm","clk":"4224195538","pt":1631452183003,"mc":[{"id":"1.187528277","rc":[{"trd":[[3.3,17856.59]],"batb":[[0,3.3,5276.42]],"ltp":3.3,"tv":81109.46,"id":19924831}],"tv":464229.13}]}
{"op":"mcm","clk":"4224195792","pt":1631452184087,"mc":[{"id":"1.187528277","rc":[{"batb":[[0,1.42,27854.11]],"ltp":1.42,"tv":383119.67,"id":2249229}]}]}
{"op":"mcm","clk":"4224200247","pt":1631452204029,"mc":[{"id":"1.187528277","rc":[{"batb":[[0,1.42,28110.33]],"ltp":1.42,"tv":383119.67,"id":2249229}]}]}
{"op":"mcm","clk":"4224231790","pt":1631452343253,"mc":[{"id":"1.187528277","rc":[{"trd":[[1.42,168904.44]],"batb":[[0,1.42,28107.67]],"ltp":1.42,"tv":383124.98,"id":2249229}],"tv":464234.45}]}
{"op":"mcm","clk":"4224247137","pt":1631452411601,"mc":[{"id":"1.187528277","rc":[{"trd":[[1.43,133020.43]],"batl":[[0,1.44,57854.31],[1,1.45,14041.89],[2,1.46,2434.83]],"ltp":1.43,"tv":418856.98,"id":2249229}],"tv":499966.44}]}
{"op":"mcm","clk":"4224247271","pt":1631452412106,"mc":[{"id":"1.187528277","rc":[{"batb":[[0,3.3,5246.12]],"ltp":3.3,"tv":81109.46,"id":19924831},{"batb":[[0,1.42,31336.79]],"batl":[[0,1.44,57923.75]],"ltp":1.43,"tv":418856.98,"id":2249229}]}]}
{"op":"mcm","clk":"4224247632","pt":1631452413609,"mc":[{"id":"1.187528277","rc":[{"batl":[[0,3.35,3177.97]],"ltp":3.3,"tv":81109.46,"id":19924831}]}]}
{"op":"mcm","clk":"4224248339","pt":1631452416988,"mc":[{"id":"1.187528277","rc":[{"batb":[[0,1.42,28107.67]],"ltp":1.43,"tv":418856.98,"id":2249229}]}]}
{"op":"mcm","clk":"4224250735","pt":1631452427574,"mc":[{"id":"1.187528277","rc":[{"trd":[[1.42,169104.44]],"batb":[[0,1.42,28007.67]],"ltp":1.42,"tv":419056.98,"id":2249229}],"tv":500166.44}]}
{"op":"mcm","clk":"4224257054","pt":1631452454538,"mc":[{"id":"1.187528277","rc":[{"batb":[[0,3.3,5276.42]],"batl":[[0,3.35,2255.97],[1,3.4,1936.03]],"ltp":3.3,"tv":81109.46,"id":19924831},{"batl":[[0,1.43,2800.22],[1,1.44,57854.09],[2,1.45,14041.89]],"ltp":1.42,"tv":419056.98,"id":2249229}]}]}
{"op":"mcm","clk":"4224263909","pt":1631452483393,"mc":[{"id":"1.187528277","rc":[{"trd":[[1.42,169108.44]],"batb":[[0,1.42,28005.67]],"ltp":1.42,"tv":419060.98,"id":2249229}],"tv":500170.44}]}
{"op":"mcm","clk":"4224265270","pt":1631452489212,"mc":[{"id":"1.187528277","rc":[{"trd":[[1.43,135051.02]],"batl":[[0,1.43,1784.92]],"ltp":1.43,"tv":421091.57,"id":2249229}],"tv":502201.03}]}
{"op":"mcm","clk":"4224267709","pt":1631452500308,"mc":[{"id":"1.187528277","rc":[{"batb":[[0,1.42,29154.12]],"ltp":1.43,"tv":421091.57,"id":2249229}]}]}
{"op":"mcm","clk":"4224271766","pt":1631452516939,"mc":[{"id":"1.187528277","rc":[{"trd":[[3.3,17864.59]],"batb":[[0,3.3,5272.42]],"ltp":3.3,"tv":81117.45,"id":19924831}],"tv":502209.03}]}
{"op":"mcm","clk":"4224272487","pt":1631452519949,"mc":[{"id":"1.187528277","rc":[{"trd":[[1.43,135229.76]],"batl":[[0,1.43,1695.55]],"ltp":1.43,"tv":421270.31,"id":2249229}],"tv":502387.77}]}
{"op":"mcm","clk":"4224276558","pt":1631452537808,"mc":[{"id":"1.187528277","rc":[{"batb":[[0,1.42,32769.19]],"ltp":1.43,"tv":421270.31,"id":2249229}]}]}
{"op":"mcm","clk":"4224290280","pt":1631452593556,"mc":[{"id":"1.187528277","rc":[{"batb":[[0,1.42,32833.38],[1,1.41,41187.53]],"ltp":1.43,"tv":421270.31,"id":2249229}]}]}
{"op":"mcm","clk":"4224290497","pt":1631452594492,"mc":[{"id":"1.187528277","rc":[{"batb":[[1,3.25,5025.3]],"ltp":3.3,"tv":81117.45,"id":19924831},{"batl":[[0,1.43,1741.42]],"ltp":1.43,"tv":421270.31,"id":2249229}]}]}
{"op":"mcm","clk":"4224290781","pt":1631452595669,"mc":[{"id":"1.187528277","rc":[{"batl":[[0,3.35,2375.44],[1,3.4,1960.5]],"ltp":3.3,"tv":81117.45,"id":19924831}]}]}
{"op":"mcm","clk":"4224294162","pt":1631452609500,"mc":[{"id":"1.187528277","rc":[{"trd":[[1.42,169138.44]],"batb":[[0,1.42,32818.38]],"ltp":1.42,"tv":421300.31,"id":2249229}],"tv":502417.77}]}
{"op":"mcm","clk":"4224304006","pt":1631452649174,"mc":[{"id":"1.187528277","rc":[{"trd":[[1.42,169158.44]],"batb":[[0,1.42,32808.38]],"ltp":1.42,"tv":421320.31,"id":2249229}],"tv":502437.77}]}
{"op":"mcm","clk":"4224307390","pt":1631452663802,"mc":[{"id":"1.187528277","rc":[{"trd":[[1.42,169168.44]],"batb":[[0,1.42,32803.38]],"ltp":1.42,"tv":421330.31,"id":2249229}],"tv":502447.77}]}
{"op":"mcm","clk":"4224314666","pt":1631452696631,"mc":[{"id":"1.187528277","rc":[{"batb":[[0,3.3,4845.4]],"ltp":3.3,"tv":81117.45,"id":19924831}]}]}
{"op":"mcm","clk":"4224315024","pt":1631452698343,"mc":[{"id":"1.187528277","rc":[{"batb":[[1,1.41,40162.68]],"ltp":1.42,"tv":421330.31,"id":2249229}]}]}
{"op":"mcm","clk":"4224319785","pt":1631452719668,"mc":[{"id":"1.187528277","rc":[{"batb":[[0,3.3,4922.9]],"ltp":3.3,"tv":81117.45,"id":19924831}]}]}
{"op":"mcm","clk":"4224320548","pt":1631452723002,"mc":[{"id":"1.187528277","rc":[{"trd":[[1.42,169368.44]],"batb":[[0,1.42,32703.38]],"ltp":1.42,"tv":421530.31,"id":2249229}],"tv":502647.77}]}
{"op":"mcm","clk":"4224323196","pt":1631452734516,"mc":[{"id":"1.187528277","rc":[{"trd":[[1.42,169568.44]],"batb":[[0,1.42,32603.38]],"ltp":1.42,"tv":421730.31,"id":2249229}],"tv":502847.77}]}
{"op":"mcm","clk":"4224335999","pt":1631452794390,"mc":[{"id":"1.187528277","rc":[{"trd":[[1.43,135279.74]],"batb":[[1,1.41,39737.24]],"batl":[[0,1.43,1716.43],[1,1.44,57428.65]],"ltp":1.43,"tv":421780.29,"id":2249229}],"tv":502897.75}]}
{"op":"mcm","clk":"4224336148","pt":1631452794987,"mc":[{"id":"1.187528277","rc":[{"batl":[[1,3.4,1904.7]],"ltp":3.3,"tv":81117.45,"id":19924831}]}]}
{"op":"mcm","clk":"4224336473","pt":1631452796600,"mc":[{"id":"1.187528277","rc":[{"batb":[[1,3.25,4737.74]],"batl":[[1,3.4,1887.33]],"ltp":3.3,"tv":81117.45,"id":19924831},{"trd":[[1.43,135398.59]],"batl":[[0,1.43,1657.01]],"ltp":1.43,"tv":421899.13,"id":2249229}],"tv":503016.59}]}
{"op":"mcm","clk":"4224336863","pt":1631452798598,"mc":[{"id":"1.187528277","rc":[{"batl":[[1,3.4,1862.86]],"ltp":3.3,"tv":81117.45,"id":19924831}]}]}
{"op":"mcm","clk":"4224336975","pt":1631452799202,"mc":[{"id":"1.187528277","rc":[{"batl":[[1,3.4,1854.89]],"ltp":3.3,"tv":81117.45,"id":19924831}]}]}
{"op":"mcm","clk":"4224337118","pt":1631452799900,"mc":[{"id":"1.187528277","rc":[{"batl":[[1,3.4,1770.26]],"ltp":3.3,"tv":81117.45,"id":19924831}]}]}
{"op":"mcm","clk":"4224337667","pt":1631452802408,"mc":[{"id":"1.187528277","rc":[{"batl":[[1,3.4,1707.71]],"ltp":3.3,"tv":81117.45,"id":19924831}]}]}
{"op":"mcm","clk":"4224337789","pt":1631452803002,"mc":[{"id":"1.187528277","rc":[{"batl":[[1,3.4,1669.9]],"ltp":3.3,"tv":81117.45,"id":19924831}]}]}
{"op":"mcm","clk":"4224338250","pt":1631452805302,"mc":[{"id":"1.187528277","rc":[{"trd":[[3.3,17869.91]],"batb":[[0,3.3,4920.24]],"ltp":3.3,"tv":81122.77,"id":19924831}],"tv":503021.91}]}
{"op":"mcm","clk":"4224338347","pt":1631452805794,"mc":[{"id":"1.187528277","rc":[{"batl":[[1,3.4,1665.88]],"ltp":3.3,"tv":81122.77,"id":19924831}]}]}
{"op":"mcm","clk":"4224338562","pt":1631452806808,"mc":[{"id":"1.187528277","rc":[{"batl":[[1,3.4,1661.38]],"ltp":3.3,"tv":81122.77,"id":19924831}]}]}
{"op":"mcm","clk":"4224338960","pt":1631452808632,"mc":[{"id":"1.187528277","rc":[{"batl":[[1,3.4,1654.65]],"ltp":3.3,"tv":81122.77,"id":19924831}]}]}
{"op":"mcm","clk":"4224339082","pt":1631452809224,"mc":[{"id":"1.187528277","rc":[{"batl":[[1,3.4,1650.35]],"ltp":3.3,"tv":81122.77,"id":19924831}]}]}
{"op":"mcm","clk":"4224339317","pt":1631452810307,"mc":[{"id":"1.187528277","rc":[{"batb":[[0,1.42,32519.45]],"ltp":1.43,"tv":421899.13,"id":2249229}]}]}
{"op":"mcm","clk":"4224339573","pt":1631452811638,"mc":[{"id":"1.187528277","rc":[{"batb":[[0,1.42,32509.5]],"ltp":1.43,"tv":421899.13,"id":2249229}]}]}
{"op":"mcm","clk":"4224339720","pt":1631452812334,"mc":[{"id":"1.187528277","rc":[{"batb":[[0,1.42,32373.07]],"ltp":1.43,"tv":421899.13,"id":2249229}]}]}
{"op":"mcm","clk":"4224339876","pt":1631452813029,"mc":[{"id":"1.187528277","rc":[{"batb":[[0,1.42,32175.96]],"ltp":1.43,"tv":421899.13,"id":2249229}]}]}
{"op":"mcm","clk":"4224340155","pt":1631452814404,"mc":[{"id":"1.187528277","rc":[{"batb":[[1,3.25,4742.74]],"ltp":3.3,"tv":81122.77,"id":19924831},{"batb":[[0,1.42,32171.78]],"ltp":1.43,"tv":421899.13,"id":2249229}]}]}
{"op":"mcm","clk":"4224340259","pt":1631452814914,"mc":[{"id":"1.187528277","rc":[{"batb":[[0,1.42,32142.23]],"ltp":1.43,"tv":421899.13,"id":2249229}]}]}
{"op":"mcm","clk":"4224340583","pt":1631452816564,"mc":[{"id":"1.187528277","rc":[{"batb":[[0,3.3,4855.57]],"ltp":3.3,"tv":81122.77,"id":19924831},{"batl":[[0,1.43,1623.81]],"ltp":1.43,"tv":421899.13,"id":2249229}]}]}
{"op":"mcm","clk":"4224340693","pt":1631452817154,"mc":[{"id":"1.187528277","rc":[{"batl":[[0,3.35,2255.97]],"ltp":3.3,"tv":81122.77,"id":19924831}]}]}
{"op":"mcm","clk":"4224350897","pt":1631452871509,"mc":[{"id":"1.187528277","rc":[{"trd":[[3.35,26119.41]],"batl":[[0,3.35,2215.97]],"ltp":3.35,"tv":81202.78,"id":19924831}],"tv":503101.92}]}
{"op":"mcm","clk":"4224356641","pt":1631452903456,"mc":[{"id":"1.187528277","rc":[{"trd":[[1.42,169572.43]],"batb":[[0,1.42,32140.23]],"ltp":1.42,"tv":421903.13,"id":2249229}],"tv":503105.92}]}
{"op":"mcm","clk":"4224356920","pt":1631452905056,"mc":[{"id":"1.187528277","rc":[{"batb":[[0,1.42,32225.64]],"ltp":1.42,"tv":421903.13,"id":2249229}]}]}
{"op":"mcm","clk":"4224357795","pt":1631452909332,"mc":[{"id":"1.187528277","rc":[{"trd":[[1.43,136642.17]],"batl":[[0,1.43,1002.02]],"ltp":1.43,"tv":423146.72,"id":2249229}],"tv":504349.5}]}
{"op":"mcm","clk":"4224358020","pt":1631452910466,"mc":[{"id":"1.187528277","rc":[{"batl":[[1,1.44,57528.65]],"ltp":1.43,"tv":423146.72,"id":2249229}]}]}
{"op":"mcm","clk":"4224361484","pt":1631452930303,"mc":[{"id":"1.187528277","rc":[{"batl":[[0,3.35,3236.86]],"ltp":3.35,"tv":81202.78,"id":19924831}]}]}
{"op":"mcm","clk":"4224368139","pt":1631452964560,"mc":[{"id":"1.187528277","rc":[{"trd":[[1.42,169678.8]],"batb":[[0,1.42,32172.46]],"ltp":1.42,"tv":423253.08,"id":2249229}],"tv":504455.86}]}
{"op":"mcm","clk":"4224373801","pt":1631452994578,"mc":[{"id":"1.187528277","rc":[{"trd":[[1.42,169710.7]],"batb":[[0,1.42,32156.5]],"ltp":1.42,"tv":423284.98,"id":2249229}],"tv":504487.77}]}
{"op":"mcm","clk":"4224382684","pt":1631453040644,"mc":[{"id":"1.187528277","rc":[{"batl":[[0,1.43,1102.02]],"ltp":1.42,"tv":423284.98,"id":2249229}]}]}
{"op":"mcm","clk":"4224386810","pt":1631453061545,"mc":[{"id":"1.187528277","rc":[{"batl":[[0,1.43,3102.02]],"ltp":1.42,"tv":423284.98,"id":2249229}]}]}
{"op":"mcm","clk":"4224388942","pt":1631453072363,"mc":[{"id":"1.187528277","rc":[{"batl":[[1,1.44,57848.27]],"ltp":1.42,"tv":423284.98,"id":2249229}]}]}
{"op":"mcm","clk":"4224394698","pt":1631453101622,"mc":[{"id":"1.187528277","rc":[{"batb":[[0,1.42,32229.55]],"ltp":1.42,"tv":423284.98,"id":2249229}]}]}
{"op":"mcm","clk":"4224399994","pt":1631453126582,"mc":[{"id":"1.187528277","rc":[{"batb":[[0,1.42,32156.5]],"ltp":1.42,"tv":423284.98,"id":2249229}]}]}
{"op":"mcm","clk":"4224400605","pt":1631453129444,"mc":[{"id":"1.187528277","rc":[{"trd":[[1.43,136784.87]],"batl":[[0,1.43,3030.67]],"ltp":1.43,"tv":423427.68,"id":2249229}],"tv":504630.47}]}
{"op":"mcm","clk":"4224404210","pt":1631453146497,"mc":[{"id":"1.187528277","rc":[{"batl":[[0,3.35,3238.57]],"ltp":3.35,"tv":81202.78,"id":19924831}]}]}
{"op":"mcm","clk":"4224414281","pt":1631453194260,"mc":[{"id":"1.187528277","rc":[{"trd":[[3.35,26192.78]],"batl":[[0,3.35,3201.88]],"ltp":3.35,"tv":81276.15,"id":19924831}],"tv":504703.84}]}
{"op":"mcm","clk":"4224436157","pt":1631453307129,"mc":[{"id":"1.187528277","rc":[{"batb":[[0,3.3,4866.74],[1,3.25,4731.57]],"ltp":3.35,"tv":81276.15,"id":19924831}]}]}
{"op":"mcm","clk":"4224438538","pt":1631453320940,"mc":[{"id":"1.187528277","rc":[{"batb":[[0,3.3,4873.12]],"ltp":3.35,"tv":81276.15,"id":19924831}]}]}
{"op":"mcm","clk":"4224439790","pt":1631453327845,"mc":[{"id":"1.187528277","rc":[{"batl":[[0,1.43,3033.67]],"ltp":1.43,"tv":423427.68,"id":2249229}]}]}
{"op":"mcm","clk":"4224440554","pt":1631453332084,"mc":[{"id":"1.187528277","rc":[{"batb":[[0,1.42,32159.5]],"ltp":1.43,"tv":423427.68,"id":2249229}]}]}
{"op":"mcm","clk":"4224455824","pt":1631453415593,"mc":[{"id":"1.187528277","rc":[{"batb":[[0,3.3,4878.12],[1,3.25,4726.57]],"ltp":3.35,"tv":81276.15,"id":19924831}]}]}
{"op":"mcm","clk":"4224459537","pt":1631453435304,"mc":[{"id":"1.187528277","rc":[{"trd":[[3.3,18069.91]],"batb":[[0,3.3,4778.12]],"batl":[[1,3.4,1550.35]],"ltp":3.3,"tv":81476.15,"id":19924831}],"tv":504903.84}]}
{"op":"mcm","clk":"4224460111","pt":1631453438087,"mc":[{"id":"1.187528277","rc":[{"batl":[[0,1.43,9033.67]],"ltp":1.43,"tv":423427.68,"id":2249229}]}]}
{"op":"mcm","clk":"4224461870","pt":1631453447407,"mc":[{"id":"1.187528277","rc":[{"batb":[[0,3.3,4773.12]],"ltp":3.3,"tv":81476.15,"id":19924831}]}]}
{"op":"mcm","clk":"4224462546","pt":1631453450822,"mc":[{"id":"1.187528277","rc":[{"trd":[[1.42,169739.57]],"batb":[[0,1.42,32145.07]],"ltp":1.42,"tv":423456.55,"id":2249229}],"tv":504932.71}]}
{"op":"mcm","clk":"4224464508","pt":1631453460539,"mc":[{"id":"1.187528277","rc":[{"trd":[[1.43,137091.67]],"batl":[[0,1.43,8880.27]],"ltp":1.43,"tv":423763.35,"id":2249229}],"tv":505239.51}]}
{"op":"mcm","clk":"4224464630","pt":1631453461137,"mc":[{"id":"1.187528277","rc":[{"batb":[[1,3.25,4731.57]],"ltp":3.3,"tv":81476.15,"id":19924831}]}]}
{"op":"mcm","clk":"4224481283","pt":1631453542821,"mc":[{"id":"1.187528277","rc":[{"batl":[[1,1.44,57948.27]],"ltp":1.43,"tv":423763.35,"id":2249229}]}]}
{"op":"mcm","clk":"4224490691","pt":1631453589289,"mc":[{"id":"1.187528277","rc":[{"batb":[[0,3.3,4873.12]],"ltp":3.3,"tv":81476.15,"id":19924831}]}]}
{"op":"mcm","clk":"4224563583","pt":1631453964677,"mc":[{"id":"1.187528277","rc":[{"batl":[[0,1.43,8965.68]],"ltp":1.43,"tv":423763.35,"id":2249229}]}]}
{"op":"mcm","clk":"4224565403","pt":1631453974274,"mc":[{"id":"1.187528277","rc":[{"batb":[[0,1.42,32230.47]],"ltp":1.43,"tv":423763.35,"id":2249229}]}]}
{"op":"mcm","clk":"4224579651","pt":1631454049081,"mc":[{"id":"1.187528277","rc":[{"batl":[[0,1.43,10965.68]],"ltp":1.43,"tv":423763.35,"id":2249229}]}]}
{"op":"mcm","clk":"4224583277","pt":1631454068677,"mc":[{"id":"1.187528277","rc":[{"trd":[[1.43,137329.49]],"batl":[[0,1.43,10846.77]],"ltp":1.43,"tv":424001.16,"id":2249229}],"tv":505477.32}]}
{"op":"mcm","clk":"4224592239","pt":1631454116763,"mc":[{"id":"1.187528277","rc":[{"trd":[[1.42,169759.57]],"batb":[[0,1.42,32220.47]],"ltp":1.42,"tv":424021.17,"id":2249229}],"tv":505497.32}]}
{"op":"mcm","clk":"4224595864","pt":1631454136654,"mc":[{"id":"1.187528277","rc":[{"batb":[[1,3.25,4719.67]],"ltp":3.3,"tv":81476.15,"id":19924831},{"trd":[[1.43,137381.2]],"batb":[[0,1.42,35447.42]],"batl":[[0,1.43,10820.91]],"ltp":1.43,"tv":424072.88,"id":2249229}],"tv":505549.04}]}
{"op":"mcm","clk":"4224596019","pt":1631454137346,"mc":[{"id":"1.187528277","rc":[{"batb":[[2,3.2,2633.01]],"ltp":3.3,"tv":81476.15,"id":19924831},{"trd":[[1.43,137415.67]],"batl":[[0,1.43,10803.67]],"ltp":1.43,"tv":424107.35,"id":2249229}],"tv":505583.51}]}
{"op":"mcm","clk":"4224596209","pt":1631454138364,"mc":[{"id":"1.187528277","rc":[{"trd":[[1.43,137450.15]],"batl":[[0,1.43,10786.43]],"ltp":1.43,"tv":424141.83,"id":2249229}],"tv":505617.98}]}
{"op":"mcm","clk":"4224596414","pt":1631454139463,"mc":[{"id":"1.187528277","rc":[{"trd":[[1.43,137501.86]],"batl":[[0,1.43,10760.57]],"ltp":1.43,"tv":424193.54,"id":2249229}],"tv":505669.7}]}
{"op":"mcm","clk":"4224596600","pt":1631454140567,"mc":[{"id":"1.187528277","rc":[{"trd":[[1.43,137553.57]],"batl":[[0,1.43,10734.71]],"ltp":1.43,"tv":424245.25,"id":2249229}],"tv":505721.41}]}
{"op":"mcm","clk":"4224596758","pt":1631454141428,"mc":[{"id":"1.187528277","rc":[{"trd":[[1.43,137588.05]],"batl":[[0,1.43,10717.47]],"ltp":1.43,"tv":424279.72,"id":2249229}],"tv":505755.88}]}
{"op":"mcm","clk":"4224596919","pt":1631454142354,"mc":[{"id":"1.187528277","rc":[{"trd":[[1.43,137622.52]],"batl":[[0,1.43,10700.23]],"ltp":1.43,"tv":424314.2,"id":2249229}],"tv":505790.36}]}
{"op":"mcm","clk":"4224597116","pt":1631454143456,"mc":[{"id":"1.187528277","rc":[{"trd":[[1.43,137674.23]],"batl":[[0,1.43,10674.37]],"ltp":1.43,"tv":424365.91,"id":2249229}],"tv":505842.07}]}
{"op":"mcm","clk":"4224597293","pt":1631454144485,"mc":[{"id":"1.187528277","rc":[{"trd":[[1.43,137725.94]],"batl":[[0,1.43,10648.51]],"ltp":1.43,"tv":424417.62,"id":2249229}],"tv":505893.78}]}
{"op":"mcm","clk":"4224597428","pt":1631454145352,"mc":[{"id":"1.187528277","rc":[{"trd":[[1.43,137760.42]],"batl":[[0,1.43,10631.27]],"ltp":1.43,"tv":424452.1,"id":2249229}],"tv":505928.26}]}
{"op":"mcm","clk":"4224597652","pt":1631454146557,"mc":[{"id":"1.187528277","rc":[{"trd":[[1.43,137812.13]],"batl":[[0,1.43,10605.41]],"ltp":1.43,"tv":424503.81,"id":2249229}],"tv":505979.97}]}
{"op":"mcm","clk":"4224597814","pt":1631454147457,"mc":[{"id":"1.187528277","rc":[{"trd":[[1.43,137846.6]],"batl":[[0,1.43,10588.17]],"ltp":1.43,"tv":424538.28,"id":2249229}],"tv":506014.44}]}
{"op":"mcm","clk":"4224597999","pt":1631454148669,"mc":[{"id":"1.187528277","rc":[{"trd":[[1.43,137898.32]],"batl":[[0,1.43,10562.31]],"ltp":1.43,"tv":424590.0,"id":2249229}],"tv":506066.15}]}
{"op":"mcm","clk":"4224598180","pt":1631454149689,"mc":[{"id":"1.187528277","rc":[{"trd":[[1.43,137950.03]],"batl":[[0,1.43,10536.45]],"ltp":1.43,"tv":424641.71,"id":2249229}],"tv":506117.87}]}
{"op":"mcm","clk":"4224598256","pt":1631454150057,"mc":[{"id":"1.187528277","rc":[{"trd":[[1.43,137967.27]],"batl":[[0,1.43,10527.83]],"ltp":1.43,"tv":424658.95,"id":2249229}],"tv":506135.1}]}
{"op":"mcm","clk":"4224605153","pt":1631454185325,"mc":[{"id":"1.187528277","rc":[{"trd":[[1.42,170159.57]],"batb":[[0,1.42,35247.42]],"ltp":1.42,"tv":425058.95,"id":2249229}],"tv":506535.1}]}
{"op":"mcm","clk":"4224606329","pt":1631454191209,"mc":[{"id":"1.187528277","rc":[{"trd":[[3.3,18089.91]],"batb":[[0,3.3,4863.12]],"ltp":3.3,"tv":81496.15,"id":19924831}],"tv":506555.1}]}
{"op":"mcm","clk":"4224609789","pt":1631454210037,"mc":[{"id":"1.187528277","rc":[{"batb":[[0,1.42,32020.47]],"ltp":1.42,"tv":425058.95,"id":2249229}]}]}
{"op":"mcm","clk":"4224610542","pt":1631454213951,"mc":[{"id":"1.187528277","rc":[{"trd":[[1.43,137977.27]],"batl":[[0,1.43,10522.83]],"ltp":1.43,"tv":425068.95,"id":2249229}],"tv":506565.1}]}
{"op":"mcm","clk":"4224619456","pt":1631454258676,"mc":[{"id":"1.187528277","rc":[{"trd":[[1.42,170501.19]],"batb":[[0,1.42,31849.66]],"ltp":1.42,"tv":425410.56,"id":2249229}],"tv":506906.72}]}
{"op":"mcm","clk":"4224629519","pt":1631454311429,"mc":[{"id":"1.187528277","rc":[{"trd":[[1.42,172501.2]],"batb":[[0,1.42,30849.65]],"ltp":1.42,"tv":427410.58,"id":2249229}],"tv":508906.74}]}
{"op":"mcm","clk":"4224661480","pt":1631454481878,"mc":[{"id":"1.187528277","rc":[{"batb":[[0,3.3,5013.12]],"ltp":3.3,"tv":81496.15,"id":19924831}]}]}
{"op":"mcm","clk":"4224663536","pt":1631454493674,"mc":[{"id":"1.187528277","rc":[{"trd":[[3.35,26240.64]],"batl":[[0,3.35,3177.95]],"ltp":3.35,"tv":81544.01,"id":19924831}],"tv":508954.6}]}
{"op":"mcm","clk":"4224688963","pt":1631454638038,"mc":[{"id":"1.187528277","rc":[{"trd":[[3.3,18095.91]],"batb":[[0,3.3,5010.12]],"ltp":3.3,"tv":81550.01,"id":19924831}],"tv":508960.6}]}
{"op":"mcm","clk":"4224709615","pt":1631454753785,"mc":[{"id":"1.187528277","rc":[{"trd":[[3.3,18202.27]],"batb":[[0,3.3,4956.94]],"ltp":3.3,"tv":81656.37,"id":19924831}],"tv":509066.96}]}
{"op":"mcm","clk":"4224740019","pt":1631454927685,"mc":[{"id":"1.187528277","rc":[{"trd":[[3.3,18202.78]],"batb":[[0,3.3,4956.69]],"ltp":3.3,"tv":81656.88,"id":19924831}],"tv":509067.46}]}
{"op":"mcm","clk":"4224740505","pt":1631454930283,"mc":[{"id":"1.187528277","rc":[{"batl":[[0,3.35,3467.16]],"ltp":3.3,"tv":81656.88,"id":19924831}]}]}
{"op":"mcm","clk":"4224765324","pt":1631455081769,"mc":[{"id":"1.187528277","rc":[{"trd":[[1.43,137981.27]],"batl":[[0,1.43,10520.83]],"ltp":1.43,"tv":427414.58,"id":2249229}],"tv":509071.46}]}
{"op":"mcm","clk":"4224779490","pt":1631455174707,"mc":[{"id":"1.187528277","rc":[{"trd":[[1.43,139141.27]],"batl":[[0,1.43,9940.82]],"ltp":1.43,"tv":428574.58,"id":2249229}],"tv":510231.46}]}
{"op":"mcm","clk":"4224781342","pt":1631455186333,"mc":[{"id":"1.187528277","rc":[{"batl":[[0,1.43,9949.71]],"ltp":1.43,"tv":428574.58,"id":2249229}]}]}
{"op":"mcm","clk":"4224782736","pt":1631455195028,"mc":[{"id":"1.187528277","rc":[{"trd":[[3.3,18212.78]],"batb":[[0,3.3,4951.69]],"ltp":3.3,"tv":81666.88,"id":19924831}],"tv":510241.47}]}
{"op":"mcm","clk":"4224790936","pt":1631455242973,"mc":[{"id":"1.187528277","rc":[{"batl":[[0,1.43,9976.3]],"ltp":1.43,"tv":428574.58,"id":2249229}]}]}
{"op":"mcm","clk":"4224792737","pt":1631455253904,"mc":[{"id":"1.187528277","rc":[{"trd":[[1.42,172527.79]],"batb":[[0,1.42,30836.35]],"ltp":1.42,"tv":428601.17,"id":2249229}],"tv":510268.06}]}
{"op":"mcm","clk":"4224793917","pt":1631455260621,"mc":[{"id":"1.187528277","rc":[{"batl":[[0,3.35,3168.24]],"ltp":3.3,"tv":81666.88,"id":19924831}]}]}
{"op":"mcm","clk":"4224796564","pt":1631455275258,"mc":[{"id":"1.187528277","rc":[{"batb":[[0,3.3,5378.71]],"ltp":3.3,"tv":81666.88,"id":19924831}]}]}
{"op":"mcm","clk":"4224797175","pt":1631455278552,"mc":[{"id":"1.187528277","rc":[{"batb":[[0,3.3,4951.69]],"ltp":3.3,"tv":81666.88,"id":19924831}]}]}
{"op":"mcm","clk":"4224825199","pt":1631455423382,"mc":[{"id":"1.187528277","rc":[{"trd":[[3.3,18222.78]],"batb":[[0,3.3,4946.68]],"ltp":3.3,"tv":81676.89,"id":19924831}],"tv":510278.06}]}
{"op":"mcm","clk":"4224827501","pt":1631455435480,"mc":[{"id":"1.187528277","rc":[{"batb":[[0,3.3,5373.7]],"ltp":3.3,"tv":81676.89,"id":19924831}]}]}
{"op":"mcm","clk":"4224829490","pt":1631455446003,"mc":[{"id":"1.187528277","rc":[{"trd":[[1.42,172571.79]],"batb":[[0,1.42,30814.35]],"ltp":1.42,"tv":428645.17,"id":2249229}],"tv":510322.06}]}
{"op":"mcm","clk":"4224831410","pt":1631455456018,"mc":[{"id":"1.187528277","rc":[{"trd":[[1.42,172574.55]],"batb":[[0,1.42,30812.97]],"ltp":1.42,"tv":428647.93,"id":2249229}],"tv":510324.82}]}
{"op":"mcm","clk":"4224833185","pt":1631455465445,"mc":[{"id":"1.187528277","rc":[{"batb":[[0,3.3,5379.86]],"ltp":3.3,"tv":81676.89,"id":19924831}]}]}
{"op":"mcm","clk":"4224833514","pt":1631455467139,"mc":[{"id":"1.187528277","rc":[{"batb":[[0,3.3,5373.7]],"ltp":3.3,"tv":81676.89,"id":19924831}]}]}
{"op":"mcm","clk":"4224835140","pt":1631455475737,"mc":[{"id":"1.187528277","rc":[{"batl":[[0,1.43,10314.04]],"ltp":1.42,"tv":428647.93,"id":2249229}]}]}
{"op":"mcm","clk":"4224837842","pt":1631455490361,"mc":[{"id":"1.187528277","rc":[{"trd":[[3.3,18252.69]],"batb":[[0,3.3,5358.75]],"ltp":3.3,"tv":81706.79,"id":19924831}],"tv":510354.73}]}
{"op":"mcm","clk":"4224842809","pt":1631455516111,"mc":[{"id":"1.187528277","rc":[{"trd":[[1.42,172684.1]],"batb":[[0,1.42,30758.19]],"ltp":1.42,"tv":428757.48,"id":2249229}],"tv":510464.28}]}
{"op":"mcm","clk":"4224845728","pt":1631455531130,"mc":[{"id":"1.187528277","rc":[{"trd":[[3.35,26440.65]],"batl":[[0,3.35,3068.24]],"ltp":3.35,"tv":81906.79,"id":19924831}],"tv":510664.28}]}
{"op":"mcm","clk":"4224847208","pt":1631455539249,"mc":[{"id":"1.187528277","rc":[{"trd":[[1.43,139157.27]],"batl":[[0,1.43,10306.04]],"ltp":1.43,"tv":428773.48,"id":2249229}],"tv":510680.28}]}
{"op":"mcm","clk":"4224850747","pt":1631455558274,"mc":[{"id":"1.187528277","rc":[{"batl":[[0,1.43,9968.3]],"ltp":1.43,"tv":428773.48,"id":2249229}]}]}
{"op":"mcm","clk":"4224852752","pt":1631455568778,"mc":[{"id":"1.187528277","rc":[{"batl":[[0,1.43,10206.04]],"ltp":1.43,"tv":428773.48,"id":2249229}]}]}
{"op":"mcm","clk":"4224854230","pt":1631455576561,"mc":[{"id":"1.187528277","rc":[{"trd":[[1.42,172701.48]],"batb":[[0,1.42,30749.5]],"ltp":1.42,"tv":428790.86,"id":2249229}],"tv":510697.66}]}
{"op":"mcm","clk":"4224854741","pt":1631455579088,"mc":[{"id":"1.187528277","rc":[{"trd":[[1.43,139203.77]],"batl":[[0,1.43,10182.79]],"ltp":1.43,"tv":428837.36,"id":2249229}],"tv":510744.16}]}
{"op":"mcm","clk":"4224856293","pt":1631455586687,"mc":[{"id":"1.187528277","rc":[{"trd":[[3.3,18492.69]],"batb":[[0,3.3,5238.75]],"ltp":3.3,"tv":82146.79,"id":19924831}],"tv":510984.16}]}
{"op":"mcm","clk":"4224858703","pt":1631455598705,"mc":[{"id":"1.187528277","rc":[{"batl":[[2,3.45,714.7]],"ltp":3.3,"tv":82146.79,"id":19924831}]}]}
{"op":"mcm","clk":"4224861324","pt":1631455610718,"mc":[{"id":"1.187528277","rc":[{"batl":[[0,1.43,9945.05]],"ltp":1.43,"tv":428837.36,"id":2249229}]}]}
{"op":"mcm","clk":"4224863257","pt":1631455619020,"mc":[{"id":"1.187528277","rc":[{"trd":[[1.42,172704.24]],"batb":[[0,1.42,30748.12]],"ltp":1.42,"tv":428840.12,"id":2249229}],"tv":510986.92}]}
{"op":"mcm","clk":"4224864736","pt":1631455626323,"mc":[{"id":"1.187528277","rc":[{"trd":[[3.35,26658.81]],"batl":[[0,3.35,2959.16]],"ltp":3.35,"tv":82364.95,"id":19924831}],"tv":511205.08}]}
{"op":"mcm","clk":"4224874420","pt":1631455673916,"mc":[{"id":"1.187528277","rc":[{"batl":[[1,3.4,1665.53]],"ltp":3.35,"tv":82364.95,"id":19924831}]}]}
{"op":"mcm","clk":"4224876937","pt":1631455686194,"mc":[{"id":"1.187528277","rc":[{"trd":[[1.42,173079.68]],"batb":[[0,1.42,30560.41]],"ltp":1.42,"tv":429215.56,"id":2249229}],"tv":511580.52}]}
{"op":"mcm","clk":"4224881815","pt":1631455709132,"mc":[{"id":"1.187528277","rc":[{"trd":[[1.43,139207.77]],"batl":[[0,1.43,9943.05]],"ltp":1.43,"tv":429219.56,"id":2249229}],"tv":511584.52}]}
{"op":"mcm","clk":"4224883753","pt":1631455719043,"mc":[{"id":"1.187528277","rc":[{"batl":[[0,1.43,12239.94]],"ltp":1.43,"tv":429219.56,"id":2249229}]}]}
{"op":"mcm","clk":"4224885848","pt":1631455729390,"mc":[{"id":"1.187528277","rc":[{"batl":[[0,1.43,12325.35]],"ltp":1.43,"tv":429219.56,"id":2249229}]}]}
{"op":"mcm","clk":"4224891714","pt":1631455758008,"mc":[{"id":"1.187528277","rc":[{"trd":[[1.42,173455.62]],"batb":[[0,1.42,30372.44]],"ltp":1.42,"tv":429595.5,"id":2249229}],"tv":511960.46}]}
{"op":"mcm","clk":"4224902078","pt":1631455812393,"mc":[{"id":"1.187528277","rc":[{"batb":[[0,1.42,30472.44]],"ltp":1.42,"tv":429595.5,"id":2249229}]}]}
{"op":"mcm","clk":"4224905551","pt":1631455829814,"mc":[{"id":"1.187528277","rc":[{"trd":[[3.3,18992.69]],"batb":[[0,3.3,4988.75]],"ltp":3.3,"tv":82864.96,"id":19924831}],"tv":512460.46}]}
{"op":"mcm","clk":"4224922053","pt":1631455913507,"mc":[{"id":"1.187528277","rc":[{"trd":[[1.42,173555.62]],"batb":[[0,1.42,30422.43]],"ltp":1.42,"tv":429695.5,"id":2249229}],"tv":512560.46}]}
{"op":"mcm","clk":"4224927188","pt":1631455938835,"mc":[{"id":"1.187528277","rc":[{"trd":[[1.42,181555.62]],"batb":[[0,1.42,26422.43]],"ltp":1.42,"tv":437695.5,"id":2249229}],"tv":520560.46}]}
{"op":"mcm","clk":"4224935278","pt":1631455979401,"mc":[{"id":"1.187528277","rc":[{"trd":[[1.42,181773.26]],"batb":[[0,1.42,26313.62]],"ltp":1.42,"tv":437913.14,"id":2249229}],"tv":520778.1}]}
{"op":"mcm","clk":"4224935732","pt":1631455981686,"mc":[{"id":"1.187528277","rc":[{"batb":[[0,3.3,5179.6]],"ltp":3.3,"tv":82864.96,"id":19924831}]}]}
{"op":"mcm","clk":"4224938268","pt":1631455993980,"mc":[{"id":"1.187528277","rc":[{"trd":[[3.3,19037.1]],"batb":[[0,3.3,5157.4]],"ltp":3.3,"tv":82909.36,"id":19924831}],"tv":520822.51}]}
{"op":"mcm","clk":"4224945508","pt":1631456032380,"mc":[{"id":"1.187528277","rc":[{"trd":[[1.43,139301.47]],"batl":[[0,1.43,12278.5]],"ltp":1.43,"tv":438006.84,"id":2249229}],"tv":520916.21}]}
{"op":"mcm","clk":"4224945838","pt":1631456034074,"mc":[{"id":"1.187528277","rc":[{"batl":[[0,1.43,13426.95]],"ltp":1.43,"tv":438006.84,"id":2249229}]}]}
{"op":"mcm","clk":"4224954988","pt":1631456082098,"mc":[{"id":"1.187528277","rc":[{"trd":[[3.3,19047.1]],"batb":[[0,3.3,5152.4]],"ltp":3.3,"tv":82919.37,"id":19924831}],"tv":520926.21}]}
{"op":"mcm","clk":"4224969986","pt":1631456152703,"mc":[{"id":"1.187528277","rc":[{"trd":[[3.3,34199.5]],"batb":[[0,3.3,41.68]],"batl":[[0,3.35,3012.89]],"ltp":3.3,"tv":98071.76,"id":19924831},{"trd":[[1.43,150488.26]],"batl":[[0,1.43,2240.15]],"ltp":1.43,"tv":449193.63,"id":2249229}],"tv":547265.4}]}
{"op":"mcm","clk":"4224970106","pt":1631456153091,"mc":[{"id":"1.187528277","rc":[{"batb":[[0,3.3,1002.98]],"batl":[[0,3.35,4369.89],[2,3.45,1120.7]],"ltp":3.3,"tv":98071.76,"id":19924831},{"trd":[[1.43,150628.1]],"batb":[[0,1.42,27722.62],[1,1.41,40758.24]],"batl":[[0,1.43,2170.23]],"ltp":1.43,"tv":449333.47,"id":2249229}],"tv":547405.24}]}
{"op":"mcm","clk":"4224970794","pt":1631456156104,"mc":[{"id":"1.187528277","rc":[{"trd":[[1.43,152598.98]],"batl":[[0,1.43,1184.8]],"ltp":1.43,"tv":451304.35,"id":2249229}],"tv":549376.11}]}
{"op":"mcm","clk":"4224972862","pt":1631456165222,"mc":[{"id":"1.187528277","rc":[{"batb":[[0,3.3,1430]],"ltp":3.3,"tv":98071.76,"id":19924831}]}]}
{"op":"mcm","clk":"4224975885","pt":1631456179935,"mc":[{"id":"1.187528277","rc":[{"batb":[[1,3.25,5146.69]],"ltp":3.3,"tv":98071.76,"id":19924831}]}]}
{"op":"mcm","clk":"4224977135","pt":1631456185821,"mc":[{"id":"1.187528277","rc":[{"trd":[[1.43,153575.23]],"batl":[[0,1.43,696.67]],"ltp":1.43,"tv":452280.6,"id":2249229}],"tv":550352.36}]}
{"op":"mcm","clk":"4224979501","pt":1631456196650,"mc":[{"id":"1.187528277","rc":[{"trd":[[1.43,154551.48]],"batl":[[0,1.43,208.55]],"ltp":1.43,"tv":453256.85,"id":2249229}],"tv":551328.61}]}
{"op":"mcm","clk":"4224980245","pt":1631456200070,"mc":[{"id":"1.187528277","rc":[{"trd":[[1.43,154840.68]],"batl":[[0,1.43,63.94]],"ltp":1.43,"tv":453546.05,"id":2249229}],"tv":551617.82}]}
{"op":"mcm","clk":"4224981499","pt":1631456205665,"mc":[{"id":"1.187528277","rc":[{"batb":[[0,3.3,1656.91]],"ltp":3.3,"tv":98071.76,"id":19924831}]}]}
{"op":"mcm","clk":"4224983239","pt":1631456213682,"mc":[{"id":"1.187528277","rc":[{"trd":[[1.43,154968.57]],"batb":[[0,1.43,24.01],[1,1.42,27722.62],[2,1.41,40758.24]],"batl":[[0,1.44,57948.27],[1,1.45,14041.89],[2,1.46,2434.83]],"ltp":1.43,"tv":453673.94,"id":2249229}],"tv":551745.71}]}
{"op":"mcm","clk":"4224983348","pt":1631456214176,"mc":[{"id":"1.187528277","rc":[{"batb":[[0,3.3,1626.61]],"batl":[[0,3.35,4399.74]],"ltp":3.3,"tv":98071.76,"id":19924831},{"batb":[[1,1.42,27652.2]],"batl":[[0,1.44,58017.71]],"ltp":1.43,"tv":453673.94,"id":2249229}]}]}
{"op":"mcm","clk":"4224987515","pt":1631456233207,"mc":[{"id":"1.187528277","rc":[{"batl":[[0,3.35,4402.37]],"ltp":3.3,"tv":98071.76,"id":19924831}]}]}
{"op":"mcm","clk":"4224990005","pt":1631456244330,"mc":[{"id":"1.187528277","rc":[{"batb":[[0,3.3,1649.67]],"ltp":3.3,"tv":98071.76,"id":19924831},{"batb":[[0,1.43,77.22]],"ltp":1.43,"tv":453673.94,"id":2249229}]}]}
{"op":"mcm","clk":"4225004281","pt":1631456267738,"mc":[{"id":"1.187528277","rc":[{"batb":[[0,3.3,1693.07]],"ltp":3.3,"tv":98071.76,"id":19924831}]}]}
{"op":"mcm","clk":"4225006306","pt":1631456277146,"mc":[{"id":"1.187528277","rc":[{"trd":[[1.44,6235.77]],"batl":[[0,1.44,58008.68]],"ltp":1.44,"tv":453691.98,"id":2249229}],"tv":551763.75}]}
{"op":"mcm","clk":"4225008961","pt":1631456289666,"mc":[{"id":"1.187528277","rc":[{"batb":[[0,3.3,1723.37]],"batl":[[0,3.35,4372.52]],"ltp":3.3,"tv":98071.76,"id":19924831},{"trd":[[1.43,155123.01]],"batb":[[0,1.42,27722.62],[1,1.41,40758.24],[2,1.4,45378.69]],"batl":[[0,1.43,243.8],[1,1.44,57939.24],[2,1.45,14041.89]],"ltp":1.43,"tv":453846.42,"id":2249229}],"tv":551918.19}]}
{"op":"mcm","clk":"4225014858","pt":1631456318323,"mc":[{"id":"1.187528277","rc":[{"batb":[[0,3.3,1693.07]],"batl":[[0,3.35,4402.37]],"ltp":3.3,"tv":98071.76,"id":19924831},{"trd":[[1.43,155610.61]],"batb":[[0,1.43,101.2],[1,1.42,27652.2],[2,1.41,40758.24]],"batl":[[0,1.44,58008.68],[1,1.45,14041.89],[2,1.46,2434.83]],"ltp":1.43,"tv":454334.02,"id":2249229}],"tv":552405.79}]}
{"op":"mcm","clk":"4225017791","pt":1631456333958,"mc":[{"id":"1.187528277","rc":[{"batl":[[0,1.44,58018.68]],"ltp":1.43,"tv":454334.02,"id":2249229}]}]}
{"op":"mcm","clk":"4225018482","pt":1631456337553,"mc":[{"id":"1.187528277","rc":[{"batb":[[0,1.43,111.2]],"ltp":1.43,"tv":454334.02,"id":2249229}]}]}
{"op":"mcm","clk":"4225021894","pt":1631456354440,"mc":[{"id":"1.187528277","rc":[{"trd":[[1.43,155833.01]],"batb":[[0,1.42,27652.2],[1,1.41,40758.24],[2,1.4,45378.69]],"batl":[[0,1.43,123.06],[1,1.44,58018.68],[2,1.45,14041.89]],"ltp":1.43,"tv":454556.42,"id":2249229}],"tv":552628.19}]}
{"op":"mcm","clk":"4225022015","pt":1631456355079,"mc":[{"id":"1.187528277","rc":[{"batb":[[0,3.3,1723.37]],"batl":[[0,3.35,4372.52]],"ltp":3.3,"tv":98071.76,"id":19924831},{"batb":[[0,1.42,27722.62]],"batl":[[1,1.44,57949.24]],"ltp":1.43,"tv":454556.42,"id":2249229}]}]}
{"op":"mcm","clk":"4225024514","pt":1631456368073,"mc":[{"id":"1.187528277","rc":[{"batl":[[0,1.43,143.06]],"ltp":1.43,"tv":454556.42,"id":2249229}]}]}
{"op":"mcm","clk":"4225025221","pt":1631456371606,"mc":[{"id":"1.187528277","rc":[{"batb":[[0,1.42,27742.62]],"ltp":1.43,"tv":454556.42,"id":2249229}]}]}
{"op":"mcm","clk":"4225026858","pt":1631456379466,"mc":[{"id":"1.187528277","rc":[{"trd":[[1.43,157673]],"batl":[[0,1.43,223.06]],"ltp":1.43,"tv":456396.42,"id":2249229}],"tv":554468.19}]}
{"op":"mcm","clk":"4225028141","pt":1631456385906,"mc":[{"id":"1.187528277","rc":[{"trd":[[3.3,34207.48]],"batb":[[0,3.3,1719.38]],"ltp":3.3,"tv":98079.74,"id":19924831}],"tv":554476.17}]}
{"op":"mcm","clk":"4225028853","pt":1631456389379,"mc":[{"id":"1.187528277","rc":[{"batl":[[0,1.43,512.41]],"ltp":1.43,"tv":456396.42,"id":2249229}]}]}
{"op":"mcm","clk":"4225029650","pt":1631456393225,"mc":[{"id":"1.187528277","rc":[{"batb":[[0,3.3,1724.38],[1,3.25,5141.69]],"ltp":3.3,"tv":98079.74,"id":19924831}]}]}
{"op":"mcm","clk":"4225030121","pt":1631456395403,"mc":[{"id":"1.187528277","rc":[{"batl":[[0,1.43,233.06]],"ltp":1.43,"tv":456396.42,"id":2249229}]}]}
{"op":"mcm","clk":"4225030778","pt":1631456398717,"mc":[{"id":"1.187528277","rc":[{"batb":[[0,1.42,27752.62]],"ltp":1.43,"tv":456396.42,"id":2249229}]}]}
{"op":"mcm","clk":"4225031529","pt":1631456402405,"mc":[{"id":"1.187528277","rc":[{"batb":[[0,1.42,28134.62],[1,1.41,40376.24]],"ltp":1.43,"tv":456396.42,"id":2249229}]}]}
{"op":"mcm","clk":"4225032106","pt":1631456405112,"mc":[{"id":"1.187528277","rc":[{"trd":[[1.43,157697]],"batl":[[0,1.43,221.06]],"ltp":1.43,"tv":456420.42,"id":2249229}],"tv":554500.17}]}
{"op":"mcm","clk":"4225033904","pt":1631456413829,"mc":[{"id":"1.187528277","rc":[{"batb":[[0,3.3,2119.38]],"ltp":3.3,"tv":98079.74,"id":19924831}]}]}
{"op":"mcm","clk":"4225035280","pt":1631456420704,"mc":[{"id":"1.187528277","rc":[{"batl":[[0,1.43,1221.06]],"ltp":1.43,"tv":456420.42,"id":2249229}]}]}
{"op":"mcm","clk":"4225036173","pt":1631456425323,"mc":[{"id":"1.187528277","rc":[{"trd":[[1.42,182351.96]],"batb":[[0,1.42,27845.27]],"ltp":1.42,"tv":456999.12,"id":2249229}],"tv":555078.87}]}
{"op":"mcm","clk":"4225037200","pt":1631456430572,"mc":[{"id":"1.187528277","rc":[{"batb":[[1,3.25,5146.69]],"ltp":3.3,"tv":98079.74,"id":19924831}]}]}
{"op":"mcm","clk":"4225038589","pt":1631456437650,"mc":[{"id":"1.187528277","rc":[{"batl":[[1,1.44,57969.24]],"ltp":1.42,"tv":456999.12,"id":2249229}]}]}
{"op":"mcm","clk":"4225039397","pt":1631456442149,"mc":[{"id":"1.187528277","rc":[{"trd":[[1.43,157737]],"batl":[[0,1.43,1201.06]],"ltp":1.43,"tv":457039.12,"id":2249229}],"tv":555118.87}]}
{"op":"mcm","clk":"4225040725","pt":1631456449078,"mc":[{"id":"1.187528277","rc":[{"batl":[[0,1.43,1221.06]],"ltp":1.43,"tv":457039.12,"id":2249229}]}]}
{"op":"mcm","clk":"4225041447","pt":1631456452889,"mc":[{"id":"1.187528277","rc":[{"batb":[[0,1.42,27865.27]],"ltp":1.43,"tv":457039.12,"id":2249229}]}]}
{"op":"mcm","clk":"4225046406","pt":1631456478638,"mc":[{"id":"1.187528277","rc":[{"batl":[[0,1.43,2221.06]],"ltp":1.43,"tv":457039.12,"id":2249229}]}]}
{"op":"mcm","clk":"4225050839","pt":1631456500062,"mc":[{"id":"1.187528277","rc":[{"batl":[[0,1.43,2241.06]],"ltp":1.43,"tv":457039.12,"id":2249229}]}]}
{"op":"mcm","clk":"4225051822","pt":1631456505073,"mc":[{"id":"1.187528277","rc":[{"batb":[[0,1.42,27885.27]],"ltp":1.43,"tv":457039.12,"id":2249229}]}]}
{"op":"mcm","clk":"4225056728","pt":1631456529414,"mc":[{"id":"1.187528277","rc":[{"trd":[[1.43,162219.12]],"batb":[[0,1.43,1783.34],[1,1.42,27885.27],[2,1.41,40376.24]],"batl":[[0,1.44,57969.24],[1,1.45,14041.89],[2,1.46,2434.83]],"ltp":1.43,"tv":461521.24,"id":2249229}],"tv":559600.99}]}
{"op":"mcm","clk":"4225056843","pt":1631456530094,"mc":[{"id":"1.187528277","rc":[{"batb":[[0,3.3,2089.08]],"batl":[[0,3.35,4402.37]],"ltp":3.3,"tv":98079.74,"id":19924831},{"trd":[[1.43,162609.85]],"batb":[[0,1.43,1587.98],[1,1.42,27814.85]],"batl":[[0,1.44,58038.68]],"ltp":1.43,"tv":461911.97,"id":2249229}],"tv":559991.71}]}
{"op":"mcm","clk":"4225057313","pt":1631456532382,"mc":[{"id":"1.187528277","rc":[{"batb":[[1,1.42,27804.71]],"ltp":1.43,"tv":461911.97,"id":2249229}]}]}
{"op":"mcm","clk":"4225062117","pt":1631456556655,"mc":[{"id":"1.187528277","rc":[{"batb":[[0,1.43,1598.06]],"ltp":1.43,"tv":461911.97,"id":2249229}]}]}
{"op":"mcm","clk":"4225063449","pt":1631456562973,"mc":[{"id":"1.187528277","rc":[{"batb":[[0,1.43,1683.46],[1,1.42,27719.31]],"ltp":1.43,"tv":461911.97,"id":2249229}]}]}
{"op":"mcm","clk":"4225066129","pt":1631456576849,"mc":[{"id":"1.187528277","rc":[{"trd":[[1.43,165609.85]],"batb":[[0,1.43,183.46]],"ltp":1.43,"tv":464911.97,"id":2249229}],"tv":562991.71}]}
{"op":"mcm","clk":"4225070136","pt":1631456596382,"mc":[{"id":"1.187528277","rc":[{"batl":[[0,1.44,58058.68]],"ltp":1.43,"tv":464911.97,"id":2249229}]}]}
{"op":"mcm","clk":"4225071166","pt":1631456601600,"mc":[{"id":"1.187528277","rc":[{"batb":[[0,1.43,203.46]],"ltp":1.43,"tv":464911.97,"id":2249229}]}]}
{"op":"mcm","clk":"4225077690","pt":1631456633936,"mc":[{"id":"1.187528277","rc":[{"batb":[[1,1.42,31164.65]],"ltp":1.43,"tv":464911.97,"id":2249229}]}]}
{"op":"mcm","clk":"4225080260","pt":1631456646178,"mc":[{"id":"1.187528277","rc":[{"batb":[[0,3.3,2119.38]],"batl":[[0,3.35,4372.52]],"ltp":3.3,"tv":98079.74,"id":19924831},{"trd":[[1.43,166016.77]],"batb":[[0,1.42,31235.07],[1,1.41,40376.24],[2,1.4,46878.69]],"batl":[[0,1.43,117.56],[1,1.44,57989.24],[2,1.45,14041.89]],"ltp":1.43,"tv":465318.88,"id":2249229}],"tv":563398.63}]}
{"op":"mcm","clk":"4225083474","pt":1631456661579,"mc":[{"id":"1.187528277","rc":[{"batl":[[0,1.43,295.53]],"ltp":1.43,"tv":465318.88,"id":2249229}]}]}
{"op":"mcm","clk":"4225090208","pt":1631456693040,"mc":[{"id":"1.187528277","rc":[{"batb":[[0,3.3,2144.9]],"ltp":3.3,"tv":98079.74,"id":19924831},{"batl":[[0,1.43,315.53]],"ltp":1.43,"tv":465318.88,"id":2249229}]}]}
{"op":"mcm","clk":"4225091920","pt":1631456701528,"mc":[{"id":"1.187528277","rc":[{"batb":[[1,1.41,40396.24]],"ltp":1.43,"tv":465318.88,"id":2249229}]}]}
{"op":"mcm","clk":"4225093925","pt":1631456710760,"mc":[{"id":"1.187528277","rc":[{"batl":[[0,1.43,1379.14]],"ltp":1.43,"tv":465318.88,"id":2249229}]}]}
{"op":"mcm","clk":"4225099823","pt":1631456737712,"mc":[{"id":"1.187528277","rc":[{"trd":[[3.3,34279.78]],"batb":[[0,3.3,2108.75]],"ltp":3.3,"tv":98152.04,"id":19924831}],"tv":563470.93}]}
{"op":"mcm","clk":"4225100378","pt":1631456740473,"mc":[{"id":"1.187528277","rc":[{"trd":[[3.3,34897.08]],"batb":[[0,3.3,1800.1]],"ltp":3.3,"tv":98769.34,"id":19924831}],"tv":564088.23}]}
{"op":"mcm","clk":"4225106013","pt":1631456767617,"mc":[{"id":"1.187528277","rc":[{"trd":[[3.35,26765.17]],"batl":[[0,3.35,4319.34]],"ltp":3.35,"tv":98875.7,"id":19924831}],"tv":564194.59}]}
{"op":"mcm","clk":"4225106392","pt":1631456769475,"mc":[{"id":"1.187528277","rc":[{"trd":[[1.43,166198.77]],"batl":[[0,1.43,1288.14]],"ltp":1.43,"tv":465500.88,"id":2249229}],"tv":564376.59}]}
{"op":"mcm","clk":"4225107858","pt":1631456776133,"mc":[{"id":"1.187528277","rc":[{"trd":[[3.3,34947.08]],"batb":[[0,3.3,1775.1]],"ltp":3.3,"tv":98925.7,"id":19924831}],"tv":564426.59}]}
{"op":"mcm","clk":"4225116346","pt":1631456818464,"mc":[{"id":"1.187528277","rc":[{"trd":[[1.43,166228.77]],"batl":[[0,1.43,1273.13]],"ltp":1.43,"tv":465530.88,"id":2249229}],"tv":564456.59}]}
{"op":"mcm","clk":"4225121363","pt":1631456844694,"mc":[{"id":"1.187528277","rc":[{"trd":[[3.3,34951.08]],"batb":[[0,3.3,1773.1]],"ltp":3.3,"tv":98929.7,"id":19924831}],"tv":564460.59}]}
{"op":"mcm","clk":"4225133111","pt":1631456910166,"mc":[{"id":"1.187528277","rc":[{"batb":[[0,3.3,1773.64]],"ltp":3.3,"tv":98929.7,"id":19924831}]}]}
{"op":"mcm","clk":"4225134036","pt":1631456915364,"mc":[{"id":"1.187528277","rc":[{"batb":[[0,3.3,1747.58]],"ltp":3.3,"tv":98929.7,"id":19924831}]}]}
{"op":"mcm","clk":"4225136814","pt":1631456930970,"mc":[{"id":"1.187528277","rc":[{"batb":[[0,3.3,1773.42]],"ltp":3.3,"tv":98929.7,"id":19924831}]}]}
{"op":"mcm","clk":"4225154757","pt":1631457024211,"mc":[{"id":"1.187528277","rc":[{"trd":[[3.3,34999.08]],"batb":[[0,3.3,1749.42]],"ltp":3.3,"tv":98977.7,"id":19924831}],"tv":564508.59}]}
{"op":"mcm","clk":"4225154902","pt":1631457024881,"mc":[{"id":"1.187528277","rc":[{"batb":[[0,3.3,1176.53],[1,3.25,4158.69],[2,3.2,1759.01]],"ltp":3.3,"tv":98977.7,"id":19924831},{"batl":[[1,1.44,56109.24],[2,1.45,12422.89]],"ltp":1.43,"tv":465530.88,"id":2249229}]}]}
{"op":"mcm","clk":"4225167557","pt":1631457090679,"mc":[{"id":"1.187528277","rc":[{"trd":[[1.43,166511.91]],"batl":[[0,1.43,1131.56]],"ltp":1.43,"tv":465814.02,"id":2249229}],"tv":564791.73}]}
{"op":"mcm","clk":"4225172481","pt":1631457115543,"mc":[{"id":"1.187528277","rc":[{"batb":[[1,3.25,3731.67]],"ltp":3.3,"tv":98977.7,"id":19924831}]}]}
{"op":"mcm","clk":"4225173655","pt":1631457121517,"mc":[{"id":"1.187528277","rc":[{"trd":[[1.43,166519.14]],"batl":[[0,1.43,1127.94]],"ltp":1.43,"tv":465821.26,"id":2249229}],"tv":564798.96}]}
{"op":"mcm","clk":"4225180279","pt":1631457153690,"mc":[{"id":"1.187528277","rc":[{"trd":[[1.42,182369.04]],"batb":[[0,1.42,31226.53]],"ltp":1.42,"tv":465838.34,"id":2249229}],"tv":564816.04}]}
{"op":"mcm","clk":"4225182093","pt":1631457162270,"mc":[{"id":"1.187528277","rc":[{"batb":[[0,3.3,2920.44]],"ltp":3.3,"tv":98977.7,"id":19924831}]}]}
{"op":"mcm","clk":"4225182403","pt":1631457163991,"mc":[{"id":"1.187528277","rc":[{"trd":[[1.43,167097.57]],"batl":[[0,1.43,838.73]],"ltp":1.43,"tv":466416.76,"id":2249229}],"tv":565394.46}]}
{"op":"mcm","clk":"4225182853","pt":1631457165707,"mc":[{"id":"1.187528277","rc":[{"trd":[[1.42,182536.52]],"batb":[[0,1.42,31142.79]],"ltp":1.42,"tv":466584.24,"id":2249229}],"tv":565561.94}]}
{"op":"mcm","clk":"4225184112","pt":1631457171602,"mc":[{"id":"1.187528277","rc":[{"trd":[[1.43,168255.86]],"batl":[[0,1.43,259.56]],"ltp":1.43,"tv":467742.53,"id":2249229}],"tv":566720.24}]}
{"op":"mcm","clk":"4225191113","pt":1631457203737,"mc":[{"id":"1.187528277","rc":[{"trd":[[3.3,35029.07]],"batb":[[0,3.3,2905.44]],"ltp":3.3,"tv":99007.7,"id":19924831}],"tv":566750.24}]}
{"op":"mcm","clk":"4225192008","pt":1631457207732,"mc":[{"id":"1.187528277","rc":[{"trd":[[1.43,168260.28]],"batl":[[0,1.43,257.35]],"ltp":1.43,"tv":467746.95,"id":2249229}],"tv":566754.65}]}
{"op":"mcm","clk":"4225192313","pt":1631457209279,"mc":[{"id":"1.187528277","rc":[{"trd":[[1.43,168329.49]],"batl":[[0,1.43,222.75]],"ltp":1.43,"tv":467816.16,"id":2249229}],"tv":566823.87}]}
{"op":"mcm","clk":"4225194018","pt":1631457216862,"mc":[{"id":"1.187528277","rc":[{"batb":[[0,3.3,7905.44]],"ltp":3.3,"tv":99007.7,"id":19924831}]}]}
{"op":"mcm","clk":"4225194293","pt":1631457218073,"mc":[{"id":"1.187528277","rc":[{"batl":[[1,3.4,1692],[2,3.45,1079.71]],"ltp":3.3,"tv":99007.7,"id":19924831},{"batl":[[1,1.44,56031.52],[2,1.45,12560.4]],"ltp":1.43,"tv":467816.16,"id":2249229}]}]}
{"op":"mcm","clk":"4225198911","pt":1631457240898,"mc":[{"id":"1.187528277","rc":[{"batl":[[0,1.43,486.6]],"ltp":1.43,"tv":467816.16,"id":2249229}]}]}
{"op":"mcm","clk":"4225202923","pt":1631457260877,"mc":[{"id":"1.187528277","rc":[{"trd":[[1.42,184936.52]],"batb":[[0,1.42,29942.79]],"ltp":1.42,"tv":470216.16,"id":2249229}],"tv":569223.87}]}
{"op":"mcm","clk":"4225208153","pt":1631457282829,"mc":[{"id":"1.187528277","rc":[{"batl":[[0,1.43,544.7]],"ltp":1.42,"tv":470216.16,"id":2249229}]}]}
{"op":"mcm","clk":"4225217572","pt":1631457324262,"mc":[{"id":"1.187528277","rc":[{"trd":[[1.42,185021.92]],"batb":[[0,1.42,29900.09]],"ltp":1.42,"tv":470301.57,"id":2249229}],"tv":569309.27}]}
{"op":"mcm","clk":"4225218945","pt":1631457330493,"mc":[{"id":"1.187528277","rc":[{"trd":[[3.3,35130.89]],"batb":[[0,3.3,7854.54]],"ltp":3.3,"tv":99109.52,"id":19924831}],"tv":569411.09}]}
{"op":"mcm","clk":"4225220329","pt":1631457336790,"mc":[{"id":"1.187528277","rc":[{"trd":[[1.43,168564.47]],"batl":[[0,1.43,427.21]],"ltp":1.43,"tv":470536.54,"id":2249229}],"tv":569646.06}]}
{"op":"mcm","clk":"4225223349","pt":1631457350819,"mc":[{"id":"1.187528277","rc":[{"trd":[[1.42,185026.94]],"batb":[[0,1.42,29897.58]],"ltp":1.42,"tv":470541.56,"id":2249229}],"tv":569651.08}]}
{"op":"mcm","clk":"4225232519","pt":1631457393769,"mc":[{"id":"1.187528277","rc":[{"trd":[[1.43,169021.28]],"batl":[[0,1.43,198.8]],"ltp":1.43,"tv":470998.38,"id":2249229}],"tv":570107.9}]}
{"op":"mcm","clk":"4225235182","pt":1631457406868,"mc":[{"id":"1.187528277","rc":[{"batl":[[0,1.43,798.8]],"ltp":1.43,"tv":470998.38,"id":2249229}]}]}
{"op":"mcm","clk":"4225242358","pt":1631457442911,"mc":[{"id":"1.187528277","rc":[{"trd":[[1.42,185807.68]],"batb":[[0,1.42,29507.21]],"ltp":1.42,"tv":471779.11,"id":2249229}],"tv":570888.63}]}
{"op":"mcm","clk":"4225243015","pt":1631457446291,"mc":[{"id":"1.187528277","rc":[{"trd":[[1.42,185829.37]],"batb":[[0,1.42,29496.37]],"ltp":1.42,"tv":471800.8,"id":2249229}],"tv":570910.32}]}
{"op":"mcm","clk":"4225246423","pt":1631457464247,"mc":[{"id":"1.187528277","rc":[{"trd":[[3.3,35165.05]],"batb":[[0,3.3,7837.45]],"ltp":3.3,"tv":99143.68,"id":19924831}],"tv":570944.49}]}
{"op":"mcm","clk":"4225247227","pt":1631457468518,"mc":[{"id":"1.187528277","rc":[{"batb":[[1,3.25,3723.12]],"batl":[[1,3.4,1699.69]],"ltp":3.3,"tv":99143.68,"id":19924831},{"trd":[[1.43,169100.11]],"batb":[[1,1.41,40436.38]],"batl":[[0,1.43,759.39],[2,1.45,12509.15]],"ltp":1.43,"tv":471879.63,"id":2249229}],"tv":571023.31}]}
{"op":"mcm","clk":"4225247265","pt":1631457468725,"mc":[{"id":"1.187528277","rc":[{"trd":[[3.3,35265.8]],"batb":[[0,3.3,7787.08]],"ltp":3.3,"tv":99244.43,"id":19924831}],"tv":571124.06}]}
{"op":"mcm","clk":"4225247958","pt":1631457472432,"mc":[{"id":"1.187528277","rc":[{"trd":[[1.43,169332.6]],"batl":[[0,1.43,643.14]],"ltp":1.43,"tv":472112.12,"id":2249229}],"tv":571356.55}]}
{"op":"mcm","clk":"4225261272","pt":1631457543304,"mc":[{"id":"1.187528277","rc":[{"batb":[[1,1.41,44051.44]],"ltp":1.43,"tv":472112.12,"id":2249229}]}]}
{"op":"mcm","clk":"4225261363","pt":1631457543785,"mc":[{"id":"1.187528277","rc":[{"batb":[[0,1.42,29232.52]],"ltp":1.43,"tv":472112.12,"id":2249229}]}]}
{"op":"mcm","clk":"4225273050","pt":1631457602698,"mc":[{"id":"1.187528277","rc":[{"trd":[[1.42,185929.37]],"batb":[[0,1.42,29182.51]],"ltp":1.42,"tv":472212.12,"id":2249229}],"tv":571456.56}]}
{"op":"mcm","clk":"4225280848","pt":1631457640801,"mc":[{"id":"1.187528277","rc":[{"trd":[[3.35,26782.75]],"batl":[[0,3.35,4310.55]],"ltp":3.35,"tv":99262.02,"id":19924831}],"tv":571474.14}]}
{"op":"mcm","clk":"4225284472","pt":1631457658918,"mc":[{"id":"1.187528277","rc":[{"trd":[[3.35,26789.51]],"batl":[[0,3.35,4307.17]],"ltp":3.35,"tv":99268.77,"id":19924831}],"tv":571480.9}]}
{"op":"mcm","clk":"4225303363","pt":1631457755246,"mc":[{"id":"1.187528277","rc":[{"trd":[[1.42,186029.37]],"batb":[[0,1.42,29132.51]],"ltp":1.42,"tv":472312.13,"id":2249229}],"tv":571580.91}]}
{"op":"mcm","clk":"4225311882","pt":1631457796068,"mc":[{"id":"1.187528277","rc":[{"trd":[[3.35,26824.69]],"batl":[[0,3.35,4289.58]],"ltp":3.35,"tv":99303.95,"id":19924831}],"tv":571616.09}]}
{"op":"mcm","clk":"4225315224","pt":1631457811496,"mc":[{"id":"1.187528277","rc":[{"batb":[[1,3.25,3740.74]],"ltp":3.35,"tv":99303.95,"id":19924831}]}]}
{"op":"mcm","clk":"4225323697","pt":1631457851240,"mc":[{"id":"1.187528277","rc":[{"batl":[[0,1.43,1123.14]],"ltp":1.42,"tv":472312.13,"id":2249229}]}]}
{"op":"mcm","clk":"4225326737","pt":1631457866771,"mc":[{"id":"1.187528277","rc":[{"trd":[[3.35,26830.46]],"batl":[[0,3.35,4286.69]],"ltp":3.35,"tv":99309.72,"id":19924831}],"tv":571621.86}]}
{"op":"mcm","clk":"4225327376","pt":1631457870152,"mc":[{"id":"1.187528277","rc":[{"trd":[[1.42,186629.37]],"batb":[[0,1.42,28832.51]],"ltp":1.42,"tv":472912.13,"id":2249229}],"tv":572221.86}]}
{"op":"mcm","clk":"4225330070","pt":1631457882863,"mc":[{"id":"1.187528277","rc":[{"trd":[[3.35,26846.29]],"batl":[[0,3.35,4278.78]],"ltp":3.35,"tv":99325.56,"id":19924831}],"tv":572237.69}]}
{"op":"mcm","clk":"4225349354","pt":1631457986503,"mc":[{"id":"1.187528277","rc":[{"trd":[[3.3,35273.3]],"batb":[[0,3.3,7783.33]],"ltp":3.3,"tv":99333.06,"id":19924831},{"trd":[[1.43,169367.15]],"batl":[[0,1.43,1105.86]],"ltp":1.43,"tv":472946.68,"id":2249229}],"tv":572279.74}]}
{"op":"mcm","clk":"4225349482","pt":1631457987201,"mc":[{"id":"1.187528277","rc":[{"trd":[[3.3,35280.8]],"batb":[[0,3.3,7779.58]],"ltp":3.3,"tv":99340.55,"id":19924831},{"trd":[[1.43,169384.47]],"batl":[[0,1.43,1097.2]],"ltp":1.43,"tv":472964.0,"id":2249229}],"tv":572304.56}]}
{"op":"mcm","clk":"4225349780","pt":1631457988687,"mc":[{"id":"1.187528277","rc":[{"batb":[[1,3.25,3707.43]],"batl":[[1,3.4,1665.53]],"ltp":3.3,"tv":99340.55,"id":19924831},{"batb":[[1,1.41,43927.61]],"batl":[[2,1.45,12422.89]],"ltp":1.43,"tv":472964.0,"id":2249229}]}]}
{"op":"mcm","clk":"4225349854","pt":1631457989110,"mc":[{"id":"1.187528277","rc":[{"batb":[[2,3.2,1791.46]],"batl":[[0,3.35,4312.94]],"ltp":3.3,"tv":99340.55,"id":19924831},{"batb":[[0,1.42,28917.06]],"ltp":1.43,"tv":472964.0,"id":2249229}]}]}
{"op":"mcm","clk":"4225350429","pt":1631457992111,"mc":[{"id":"1.187528277","rc":[{"trd":[[1.43,169419.08]],"batl":[[0,1.43,1079.9]],"ltp":1.43,"tv":472998.61,"id":2249229}],"tv":572339.17}]}
{"op":"mcm","clk":"4225355320","pt":1631458019255,"mc":[{"id":"1.187528277","rc":[{"batb":[[2,3.2,1810.25]],"batl":[[0,3.35,4278.78],[1,3.4,1709.09]],"ltp":3.3,"tv":99340.55,"id":19924831},{"batl":[[2,1.45,12501.47]],"ltp":1.43,"tv":472998.61,"id":2249229}]}]}
{"op":"mcm","clk":"4225365326","pt":1631458076614,"mc":[{"id":"1.187528277","rc":[{"batb":[[0,1.42,28909.37]],"ltp":1.43,"tv":472998.61,"id":2249229}]}]}
{"op":"mcm","clk":"4225365419","pt":1631458077200,"mc":[{"id":"1.187528277","rc":[{"batl":[[2,1.45,12506.59]],"ltp":1.43,"tv":472998.61,"id":2249229}]}]}
{"op":"mcm","clk":"4225366781","pt":1631458084423,"mc":[{"id":"1.187528277","rc":[{"batb":[[0,1.42,28900.83]],"ltp":1.43,"tv":472998.61,"id":2249229}]}]}
{"op":"mcm","clk":"4225368810","pt":1631458095835,"mc":[{"id":"1.187528277","rc":[{"batb":[[0,1.42,28894.86]],"ltp":1.43,"tv":472998.61,"id":2249229}]}]}
{"op":"mcm","clk":"4225370923","pt":1631458108655,"mc":[{"id":"1.187528277","rc":[{"batl":[[0,1.43,1190.29]],"ltp":1.43,"tv":472998.61,"id":2249229}]}]}
{"op":"mcm","clk":"4225371627","pt":1631458112968,"mc":[{"id":"1.187528277","rc":[{"batb":[[0,1.42,28905.1]],"ltp":1.43,"tv":472998.61,"id":2249229}]}]}
{"op":"mcm","clk":"4225375401","pt":1631458134675,"mc":[{"id":"1.187528277","rc":[{"trd":[[1.42,186629.45]],"batb":[[0,1.42,28905.07]],"ltp":1.42,"tv":472998.68,"id":2249229}],"tv":572339.24}]}
{"op":"mcm","clk":"4225376721","pt":1631458141994,"mc":[{"id":"1.187528277","rc":[{"trd":[[3.3,35326.92]],"batb":[[0,3.3,7756.53]],"ltp":3.3,"tv":99386.67,"id":19924831}],"tv":572385.36}]}
{"op":"mcm","clk":"4225377335","pt":1631458145505,"mc":[{"id":"1.187528277","rc":[{"trd":[[1.43,169525.51]],"batl":[[0,1.43,1137.07]],"ltp":1.43,"tv":473105.12,"id":2249229}],"tv":572491.79}]}
{"op":"mcm","clk":"4225394838","pt":1631458244332,"mc":[{"id":"1.187528277","rc":[{"trd":[[3.3,35354.57]],"batb":[[0,3.3,7742.7]],"ltp":3.3,"tv":99414.33,"id":19924831}],"tv":572519.45}]}
{"op":"mcm","clk":"4225396285","pt":1631458252537,"mc":[{"id":"1.187528277","rc":[{"trd":[[1.43,169589.33]],"batl":[[0,1.43,1105.16]],"ltp":1.43,"tv":473168.93,"id":2249229}],"tv":572583.26}]}
{"op":"mcm","clk":"4225399786","pt":1631458272259,"mc":[{"id":"1.187528277","rc":[{"batl":[[2,1.45,12537.33]],"ltp":1.43,"tv":473168.93,"id":2249229}]}]}
{"op":"mcm","clk":"4225424642","pt":1631458417039,"mc":[{"id":"1.187528277","rc":[{"trd":[[3.35,26862.65]],"batl":[[0,3.35,4270.6]],"ltp":3.35,"tv":99430.68,"id":19924831}],"tv":572599.62}]}
{"op":"mcm","clk":"4225444909","pt":1631458534101,"mc":[{"id":"1.187528277","rc":[{"batb":[[0,1.42,28911.05]],"ltp":1.43,"tv":473168.93,"id":2249229}]}]}
{"op":"mcm","clk":"4225453364","pt":1631458582254,"mc":[{"id":"1.187528277","rc":[{"trd":[[3.35,34862.64]],"batb":[[0,3.3,8766.24],[1,3.25,4698.43],[2,3.2,2822.25]],"batl":[[0,3.35,2.63]],"ltp":3.35,"tv":107430.67,"id":19924831},{"batl":[[0,1.43,2881.7],[1,1.44,57803.52],[2,1.45,14413.33]],"ltp":1.43,"tv":473168.93,"id":2249229}],"tv":580599.61}]}
{"op":"mcm","clk":"4225457505","pt":1631458606600,"mc":[{"id":"1.187528277","rc":[{"trd":[[3.35,34878.83]],"batl":[[0,3.35,45.57]],"ltp":3.35,"tv":107446.86,"id":19924831},{"batl":[[0,1.43,3001.27]],"ltp":1.43,"tv":473168.93,"id":2249229}],"tv":580615.8}]}
{"op":"mcm","clk":"4225463801","pt":1631458641228,"mc":[{"id":"1.187528277","rc":[{"trd":[[3.35,34923.5]],"batl":[[0,3.35,23.24]],"ltp":3.35,"tv":107491.53,"id":19924831}],"tv":580660.47}]}
{"op":"mcm","clk":"4225465775","pt":1631458652350,"mc":[{"id":"1.187528277","rc":[{"batl":[[0,1.43,3033.18]],"ltp":1.43,"tv":473168.93,"id":2249229}]}]}
{"op":"mcm","clk":"4225468885","pt":1631458670449,"mc":[{"id":"1.187528277","rc":[{"trd":[[3.35,34969.98]],"batb":[[0,3.35,7.6],[1,3.3,8735.94],[2,3.25,4698.43]],"batl":[[0,3.4,1738.5],[1,3.45,1079.71],[2,3.5,687]],"ltp":3.35,"tv":107538.01,"id":19924831},{"batb":[[0,1.42,28840.63]],"batl":[[0,1.43,3103.11]],"ltp":1.43,"tv":473168.93,"id":2249229}],"tv":580706.95}]}
{"op":"mcm","clk":"4225470090","pt":1631458677990,"mc":[{"id":"1.187528277","rc":[{"batl":[[0,1.43,3071.2]],"ltp":1.43,"tv":473168.93,"id":2249229}]}]}
{"op":"mcm","clk":"4225472557","pt":1631458693606,"mc":[{"id":"1.187528277","rc":[{"trd":[[1.42,186661.35]],"batb":[[0,1.42,28824.68],[2,1.4,46883.03]],"ltp":1.42,"tv":473200.84,"id":2249229}],"tv":580738.85}]}
{"op":"mcm","clk":"4225473220","pt":1631458697417,"mc":[{"id":"1.187528277","rc":[{"trd":[[3.35,34984.44]],"batb":[[0,3.3,8736.31],[1,3.25,4698.43],[2,3.2,2822.25]],"ltp":3.35,"tv":107552.47,"id":19924831}],"tv":580753.31}]}
{"op":"mcm","clk":"4225473313","pt":1631458697892,"mc":[{"id":"1.187528277","rc":[{"batb":[[0,3.3,8766.61]],"ltp":3.35,"tv":107552.47,"id":19924831},{"batl":[[0,1.43,3001.27]],"ltp":1.42,"tv":473200.84,"id":2249229}]}]}
{"op":"mcm","clk":"4225475109","pt":1631458708816,"mc":[{"id":"1.187528277","rc":[{"trd":[[3.3,35447.83],[3.35,34985.18]],"batb":[[0,3.3,8719.61]],"ltp":3.3,"tv":107646.47,"id":19924831}],"tv":580847.31}]}
{"op":"mcm","clk":"4225475671","pt":1631458712645,"mc":[{"id":"1.187528277","rc":[{"batb":[[0,1.42,28829.01],[2,1.4,46878.69]],"ltp":1.42,"tv":473200.84,"id":2249229}]}]}
{"op":"mcm","clk":"4225477279","pt":1631458722450,"mc":[{"id":"1.187528277","rc":[{"batl":[[0,3.35,46.97],[1,3.4,1738.5],[2,3.45,1079.71]],"ltp":3.3,"tv":107646.47,"id":19924831}]}]}
{"op":"mcm","clk":"4225477359","pt":1631458722952,"mc":[{"id":"1.187528277","rc":[{"batl":[[1,3.4,1709.09]],"ltp":3.3,"tv":107646.47,"id":19924831},{"batb":[[0,1.42,28899.43]],"ltp":1.42,"tv":473200.84,"id":2249229}]}]}
{"op":"mcm","clk":"4225478514","pt":1631458730064,"mc":[{"id":"1.187528277","rc":[{"trd":[[3.3,36047.83]],"batb":[[0,3.3,8419.61]],"ltp":3.3,"tv":108246.47,"id":19924831}],"tv":581447.31}]}
{"op":"mcm","clk":"4225480288","pt":1631458740740,"mc":[{"id":"1.187528277","rc":[{"batl":[[0,3.35,247.67]],"ltp":3.3,"tv":108246.47,"id":19924831}]}]}
{"op":"mcm","clk":"4225482921","pt":1631458755382,"mc":[{"id":"1.187528277","rc":[{"trd":[[1.42,186677.35]],"batb":[[0,1.42,28891.44]],"ltp":1.42,"tv":473216.83,"id":2249229}],"tv":581463.31}]}
{"op":"mcm","clk":"4225492920","pt":1631458811874,"mc":[{"id":"1.187528277","rc":[{"trd":[[1.43,169815.63]],"batl":[[0,1.43,2888.12]],"ltp":1.43,"tv":473443.13,"id":2249229}],"tv":581689.6}]}
{"op":"mcm","clk":"4225493691","pt":1631458815990,"mc":[{"id":"1.187528277","rc":[{"batl":[[0,1.43,2941.3]],"ltp":1.43,"tv":473443.13,"id":2249229}]}]}
{"op":"mcm","clk":"4225493941","pt":1631458817281,"mc":[{"id":"1.187528277","rc":[{"trd":[[3.35,35019.72]],"batl":[[0,3.35,230.4]],"ltp":3.35,"tv":108281.01,"id":19924831}],"tv":581724.14}]}
{"op":"mcm","clk":"4225494900","pt":1631458822690,"mc":[{"id":"1.187528277","rc":[{"batl":[[0,1.43,2942.84]],"ltp":1.43,"tv":473443.13,"id":2249229}]}]}
{"op":"mcm","clk":"4225496309","pt":1631458830400,"mc":[{"id":"1.187528277","rc":[{"trd":[[3.3,36526.44]],"batb":[[0,3.3,8180.3]],"ltp":3.3,"tv":108759.62,"id":19924831}],"tv":582202.76}]}
{"op":"mcm","clk":"4225500955","pt":1631458855312,"mc":[{"id":"1.187528277","rc":[{"batl":[[0,1.43,2972.84]],"ltp":1.43,"tv":473443.13,"id":2249229}]}]}
{"op":"mcm","clk":"4225503389","pt":1631458867956,"mc":[{"id":"1.187528277","rc":[{"trd":[[3.3,36529.2]],"batb":[[0,3.3,8178.92]],"ltp":3.3,"tv":108762.38,"id":19924831}],"tv":582205.51}]}
{"op":"mcm","clk":"4225505302","pt":1631458877678,"mc":[{"id":"1.187528277","rc":[{"batl":[[0,3.35,343.03]],"ltp":3.3,"tv":108762.38,"id":19924831}]}]}
{"op":"mcm","clk":"4225524407","pt":1631458974588,"mc":[{"id":"1.187528277","rc":[{"batb":[[1,1.41,44027.61]],"ltp":1.43,"tv":473443.13,"id":2249229}]}]}
{"op":"mcm","clk":"4225525331","pt":1631458979506,"mc":[{"id":"1.187528277","rc":[{"batb":[[0,1.42,28991.44]],"batl":[[0,1.43,5364.45]],"ltp":1.43,"tv":473443.13,"id":2249229}]}]}
{"op":"mcm","clk":"4225527165","pt":1631458988699,"mc":[{"id":"1.187528277","rc":[{"batb":[[2,1.4,46978.69]],"ltp":1.43,"tv":473443.13,"id":2249229}]}]}
{"op":"mcm","clk":"4225527715","pt":1631458991625,"mc":[{"id":"1.187528277","rc":[{"batl":[[0,3.35,1363.93]],"ltp":3.3,"tv":108762.38,"id":19924831}]}]}
{"op":"mcm","clk":"4225531511","pt":1631459011527,"mc":[{"id":"1.187528277","rc":[{"batb":[[1,3.25,4798.43]],"ltp":3.3,"tv":108762.38,"id":19924831}]}]}
{"op":"mcm","clk":"4225538652","pt":1631459047800,"mc":[{"id":"1.187528277","rc":[{"trd":[[3.3,36929.2]],"batb":[[0,3.3,7978.92]],"ltp":3.3,"tv":109162.38,"id":19924831}],"tv":582605.51}]}
{"op":"mcm","clk":"4225545151","pt":1631459081859,"mc":[{"id":"1.187528277","rc":[{"trd":[[1.42,187255.76]],"batb":[[0,1.42,28702.23]],"ltp":1.42,"tv":474021.54,"id":2249229}],"tv":583183.93}]}
{"op":"mcm","clk":"4225548039","pt":1631459096738,"mc":[{"id":"1.187528277","rc":[{"trd":[[1.42,187284.38]],"batb":[[0,1.42,28687.92]],"ltp":1.42,"tv":474050.16,"id":2249229}],"tv":583212.54}]}
{"op":"mcm","clk":"4225548811","pt":1631459100460,"mc":[{"id":"1.187528277","rc":[{"trd":[[1.43,170474.95]],"batl":[[0,1.43,5034.79]],"ltp":1.43,"tv":474709.48,"id":2249229}],"tv":583871.87}]}
{"op":"mcm","clk":"4225549963","pt":1631459106255,"mc":[{"id":"1.187528277","rc":[{"trd":[[1.43,170696.95]],"batl":[[0,1.43,4923.79]],"ltp":1.43,"tv":474931.48,"id":2249229}],"tv":584093.87}]}
{"op":"mcm","clk":"4225556309","pt":1631459137639,"mc":[{"id":"1.187528277","rc":[{"batb":[[2,3.2,2814.56]],"batl":[[1,3.4,1665.53]],"ltp":3.3,"tv":109162.38,"id":19924831},{"batl":[[2,1.45,14329.64]],"ltp":1.43,"tv":474931.48,"id":2249229}]}]}
{"op":"mcm","clk":"4225556401","pt":1631459138018,"mc":[{"id":"1.187528277","rc":[{"batl":[[0,3.35,1391.26]],"ltp":3.3,"tv":109162.38,"id":19924831},{"batb":[[0,1.42,28694.76]],"ltp":1.43,"tv":474931.48,"id":2249229}]}]}
{"op":"mcm","clk":"4225557388","pt":1631459142909,"mc":[{"id":"1.187528277","rc":[{"batl":[[0,1.43,4954.53],[2,1.45,14298.89]],"ltp":1.43,"tv":474931.48,"id":2249229}]}]}
{"op":"mcm","clk":"4225562522","pt":1631459168757,"mc":[{"id":"1.187528277","rc":[{"trd":[[3.3,37005.74]],"batb":[[0,3.3,7940.65]],"ltp":3.3,"tv":109238.92,"id":19924831}],"tv":584170.4}]}
{"op":"mcm","clk":"4225568472","pt":1631459199110,"mc":[{"id":"1.187528277","rc":[{"batb":[[0,1.42,29033.14]],"ltp":1.43,"tv":474931.48,"id":2249229}]}]}
{"op":"mcm","clk":"4225570257","pt":1631459208108,"mc":[{"id":"1.187528277","rc":[{"trd":[[1.42,187290.16]],"batb":[[0,1.42,29030.25]],"ltp":1.42,"tv":474937.26,"id":2249229}],"tv":584176.19}]}
{"op":"mcm","clk":"4225574483","pt":1631459229069,"mc":[{"id":"1.187528277","rc":[{"trd":[[3.35,35748.11]],"batl":[[0,3.35,1027.06]],"ltp":3.35,"tv":109967.31,"id":19924831}],"tv":584904.57}]}
{"op":"mcm","clk":"4225575552","pt":1631459234353,"mc":[{"id":"1.187528277","rc":[{"trd":[[3.35,35752.34]],"batl":[[0,3.35,1024.94]],"ltp":3.35,"tv":109971.54,"id":19924831}],"tv":584908.81}]}
{"op":"mcm","clk":"4225581933","pt":1631459268676,"mc":[{"id":"1.187528277","rc":[{"trd":[[1.42,187300.28]],"batb":[[0,1.42,29025.19]],"ltp":1.42,"tv":474947.39,"id":2249229}],"tv":584918.93}]}
{"op":"mcm","clk":"4225586843","pt":1631459293874,"mc":[{"id":"1.187528277","rc":[{"batb":[[0,1.42,28686.8]],"ltp":1.42,"tv":474947.39,"id":2249229}]}]}
{"op":"mcm","clk":"4225588504","pt":1631459302371,"mc":[{"id":"1.187528277","rc":[{"trd":[[1.43,171373.72]],"batl":[[0,1.43,4616.14]],"ltp":1.43,"tv":475624.16,"id":2249229}],"tv":585595.71}]}
{"op":"mcm","clk":"4225628632","pt":1631459508895,"mc":[{"id":"1.187528277","rc":[{"trd":[[3.35,35800.68]],"batl":[[0,3.35,1000.77]],"ltp":3.35,"tv":110019.88,"id":19924831}],"tv":585644.05}]}
{"op":"mcm","clk":"4225632912","pt":1631459531608,"mc":[{"id":"1.187528277","rc":[{"trd":[[1.42,195840.72]],"batb":[[0,1.42,24416.58]],"ltp":1.42,"tv":484164.6,"id":2249229}],"tv":594184.49}]}
{"op":"mcm","clk":"4225638590","pt":1631459558148,"mc":[{"id":"1.187528277","rc":[{"batl":[[0,3.35,973.44],[1,3.4,1709.94]],"ltp":3.35,"tv":110019.88,"id":19924831}]}]}
{"op":"mcm","clk":"4225642452","pt":1631459576688,"mc":[{"id":"1.187528277","rc":[{"batl":[[0,1.43,10358.38]],"ltp":1.42,"tv":484164.6,"id":2249229}]}]}
{"op":"mcm","clk":"4225648742","pt":1631459606742,"mc":[{"id":"1.187528277","rc":[{"trd":[[1.42,196040.72]],"batb":[[0,1.42,24316.58]],"ltp":1.42,"tv":484364.6,"id":2249229}],"tv":594384.49}]}
{"op":"mcm","clk":"4225655963","pt":1631459641498,"mc":[{"id":"1.187528277","rc":[{"batl":[[0,3.4,1709.94],[1,3.45,1079.71],[2,3.5,687]],"ltp":3.35,"tv":110019.88,"id":19924831}]}]}
{"op":"mcm","clk":"4225656108","pt":1631459642106,"mc":[{"id":"1.187528277","rc":[{"batl":[[0,3.4,1739.35]],"ltp":3.35,"tv":110019.88,"id":19924831},{"batb":[[0,1.42,24246.16]],"ltp":1.42,"tv":484364.6,"id":2249229}]}]}
{"op":"mcm","clk":"4225664602","pt":1631459682371,"mc":[{"id":"1.187528277","rc":[{"trd":[[1.42,196057.8]],"batb":[[0,1.42,24237.63]],"ltp":1.42,"tv":484381.68,"id":2249229}],"tv":594401.57}]}
{"op":"mcm","clk":"4225675198","pt":1631459731354,"mc":[{"id":"1.187528277","rc":[{"batb":[[0,3.35,3.04],[1,3.3,7940.65],[2,3.25,4798.43]],"ltp":3.35,"tv":110019.88,"id":19924831}]}]}
{"op":"mcm","clk":"4225675290","pt":1631459731755,"mc":[{"id":"1.187528277","rc":[{"batb":[[1,3.3,7910.35]],"ltp":3.35,"tv":110019.88,"id":19924831},{"batb":[[0,1.42,20561.63]],"batl":[[0,1.43,10428.31]],"ltp":1.42,"tv":484381.68,"id":2249229}]}]}
{"op":"mcm","clk":"4225677344","pt":1631459740875,"mc":[{"id":"1.187528277","rc":[{"batl":[[0,1.43,14613.13],[2,1.45,10114.08]],"ltp":1.42,"tv":484381.68,"id":2249229}]}]}
{"op":"mcm","clk":"4225683788","pt":1631459770626,"mc":[{"id":"1.187528277","rc":[{"trd":[[1.42,196061.8]],"batb":[[0,1.42,20559.62]],"ltp":1.42,"tv":484385.68,"id":2249229}],"tv":594405.57}]}
{"op":"mcm","clk":"4225688329","pt":1631459791036,"mc":[{"id":"1.187528277","rc":[{"batb":[[0,3.35,2412.84]],"ltp":3.35,"tv":110019.88,"id":19924831}]}]}
{"op":"mcm","clk":"4225689430","pt":1631459796175,"mc":[{"id":"1.187528277","rc":[{"trd":[[3.35,35803.06]],"batb":[[0,3.35,2411.65]],"ltp":3.35,"tv":110022.26,"id":19924831},{"batl":[[0,1.43,16191.13]],"ltp":1.42,"tv":484385.68,"id":2249229}],"tv":594407.95}]}
{"op":"mcm","clk":"4225690028","pt":1631459799069,"mc":[{"id":"1.187528277","rc":[{"batl":[[0,1.43,14613.13]],"ltp":1.42,"tv":484385.68,"id":2249229}]}]}
{"op":"mcm","clk":"4225692667","pt":1631459811606,"mc":[{"id":"1.187528277","rc":[{"batb":[[0,3.35,3479.99]],"ltp":3.35,"tv":110022.26,"id":19924831},{"batl":[[0,1.43,14739]],"ltp":1.42,"tv":484385.68,"id":2249229}]}]}
{"op":"mcm","clk":"4225696322","pt":1631459828056,"mc":[{"id":"1.187528277","rc":[{"batl":[[0,1.43,14744]],"ltp":1.42,"tv":484385.68,"id":2249229}]}]}
{"op":"mcm","clk":"4225697047","pt":1631459831676,"mc":[{"id":"1.187528277","rc":[{"batb":[[1,1.41,44032.61]],"ltp":1.42,"tv":484385.68,"id":2249229}]}]}
{"op":"mcm","clk":"4225704903","pt":1631459869523,"mc":[{"id":"1.187528277","rc":[{"trd":[[3.35,35883.07]],"batb":[[0,3.35,3439.99]],"ltp":3.35,"tv":110102.27,"id":19924831}],"tv":594487.95}]}
{"op":"mcm","clk":"4225712237","pt":1631459908370,"mc":[{"id":"1.187528277","rc":[{"batb":[[0,1.42,20562.62]],"ltp":1.42,"tv":484385.68,"id":2249229}]}]}
{"op":"mcm","clk":"4225712929","pt":1631459911616,"mc":[{"id":"1.187528277","rc":[{"trd":[[1.43,171379.72]],"batb":[[0,1.42,20559.62]],"batl":[[0,1.43,14741]],"ltp":1.43,"tv":484391.68,"id":2249229}],"tv":594493.95}]}
{"op":"mcm","clk":"4225720879","pt":1631459952846,"mc":[{"id":"1.187528277","rc":[{"batl":[[0,1.43,19846.29]],"ltp":1.43,"tv":484391.68,"id":2249229}]}]}
{"op":"mcm","clk":"4225726725","pt":1631459982607,"mc":[{"id":"1.187528277","rc":[{"batl":[[0,1.43,14741]],"ltp":1.43,"tv":484391.68,"id":2249229}]}]}
{"op":"mcm","clk":"4225729762","pt":1631459998152,"mc":[{"id":"1.187528277","rc":[{"trd":[[1.42,196116.91]],"batb":[[0,1.42,20532.07]],"ltp":1.42,"tv":484446.79,"id":2249229}],"tv":594549.06}]}
{"op":"mcm","clk":"4225763927","pt":1631460171504,"mc":[{"id":"1.187528277","rc":[{"trd":[[1.43,171380.54]],"batl":[[0,1.43,14740.59]],"ltp":1.43,"tv":484447.61,"id":2249229}],"tv":594549.88}]}
{"op":"mcm","clk":"4225770558","pt":1631460205354,"mc":[{"id":"1.187528277","rc":[{"trd":[[1.42,200387.13]],"batb":[[0,1.42,18396.96]],"ltp":1.42,"tv":488717.83,"id":2249229}],"tv":598820.1}]}
{"op":"mcm","clk":"4225773103","pt":1631460219051,"mc":[{"id":"1.187528277","rc":[{"trd":[[1.43,171389.73]],"batl":[[0,1.43,14736]],"ltp":1.43,"tv":488727.01,"id":2249229}],"tv":598829.29}]}
{"op":"mcm","clk":"4225773262","pt":1631460220073,"mc":[{"id":"1.187528277","rc":[{"trd":[[3.35,35884.18]],"batb":[[0,3.35,3439.43]],"ltp":3.35,"tv":110103.38,"id":19924831}],"tv":598830.4}]}
{"op":"mcm","clk":"4225774526","pt":1631460227495,"mc":[{"id":"1.187528277","rc":[{"trd":[[3.35,35888.87]],"batb":[[0,3.35,3437.09]],"ltp":3.35,"tv":110108.07,"id":19924831}],"tv":598835.08}]}
{"op":"mcm","clk":"4225782736","pt":1631460273672,"mc":[{"id":"1.187528277","rc":[{"trd":[[3.35,36117.54]],"batb":[[0,3.35,3322.75]],"ltp":3.35,"tv":110336.74,"id":19924831}],"tv":599063.76}]}
{"op":"mcm","clk":"4225783023","pt":1631460275557,"mc":[{"id":"1.187528277","rc":[{"trd":[[3.35,36126.08]],"batb":[[0,3.35,3318.48]],"ltp":3.35,"tv":110345.28,"id":19924831},{"batb":[[0,1.42,21641.63]],"ltp":1.43,"tv":488727.01,"id":2249229}],"tv":599072.3}]}
{"op":"mcm","clk":"4225783059","pt":1631460275777,"mc":[{"id":"1.187528277","rc":[{"batb":[[0,1.42,18396.96]],"ltp":1.43,"tv":488727.01,"id":2249229}]}]}
{"op":"mcm","clk":"4225784974","pt":1631460287985,"mc":[{"id":"1.187528277","rc":[{"batb":[[0,1.42,18496.96],[2,1.4,46878.69]],"ltp":1.43,"tv":488727.01,"id":2249229}]}]}
{"op":"mcm","clk":"4225785842","pt":1631460293702,"mc":[{"id":"1.187528277","rc":[{"trd":[[3.35,36130.48]],"batb":[[0,3.35,3316.28]],"ltp":3.35,"tv":110349.68,"id":19924831}],"tv":599076.7}]}
{"op":"mcm","clk":"4225802276","pt":1631460393618,"mc":[{"id":"1.187528277","rc":[{"trd":[[1.42,200575.11]],"batb":[[0,1.42,18402.97]],"ltp":1.42,"tv":488915.0,"id":2249229}],"tv":599264.68}]}
{"op":"mcm","clk":"4225802750","pt":1631460396608,"mc":[{"id":"1.187528277","rc":[{"trd":[[1.42,206575.12]],"batb":[[0,1.42,15402.96]],"ltp":1.42,"tv":494915.0,"id":2249229}],"tv":605264.69}]}
{"op":"mcm","clk":"4225804844","pt":1631460408646,"mc":[{"id":"1.187528277","rc":[{"trd":[[1.42,206701.77]],"batb":[[0,1.42,15329.39]],"batl":[[2,1.45,10198.63]],"ltp":1.42,"tv":495041.65,"id":2249229}],"tv":605391.33}]}
{"op":"mcm","clk":"4225808328","pt":1631460429608,"mc":[{"id":"1.187528277","rc":[{"batb":[[0,1.42,18572.92]],"ltp":1.42,"tv":495041.65,"id":2249229}]}]}
{"op":"mcm","clk":"4225808392","pt":1631460429880,"mc":[{"id":"1.187528277","rc":[{"batb":[[0,1.42,15329.39]],"ltp":1.42,"tv":495041.65,"id":2249229}]}]}
{"op":"mcm","clk":"4225808797","pt":1631460432394,"mc":[{"id":"1.187528277","rc":[{"trd":[[3.35,36247.61]],"batb":[[0,3.35,3257.72]],"ltp":3.35,"tv":110466.81,"id":19924831}],"tv":605508.46}]}
{"op":"mcm","clk":"4225809012","pt":1631460433676,"mc":[{"id":"1.187528277","rc":[{"batb":[[0,1.42,15419.92]],"ltp":1.42,"tv":495041.65,"id":2249229}]}]}
{"op":"mcm","clk":"4225810128","pt":1631460440404,"mc":[{"id":"1.187528277","rc":[{"trd":[[1.42,206704.52]],"batb":[[0,1.42,15418.54]],"ltp":1.42,"tv":495044.41,"id":2249229}],"tv":605511.22}]}
{"op":"mcm","clk":"4225810807","pt":1631460444698,"mc":[{"id":"1.187528277","rc":[{"trd":[[3.35,36270.85]],"batb":[[0,3.35,3246.1]],"ltp":3.35,"tv":110490.05,"id":19924831}],"tv":605534.46}]}
{"op":"mcm","clk":"4225813485","pt":1631460460435,"mc":[{"id":"1.187528277","rc":[{"trd":[[1.43,171392.47]],"batl":[[0,1.43,14734.63]],"ltp":1.43,"tv":495047.15,"id":2249229}],"tv":605537.2}]}
{"op":"mcm","clk":"4225815288","pt":1631460470824,"mc":[{"id":"1.187528277","rc":[{"batl":[[2,1.45,10200.01]],"ltp":1.43,"tv":495047.15,"id":2249229}]}]}
{"op":"mcm","clk":"4225817583","pt":1631460483665,"mc":[{"id":"1.187528277","rc":[{"batb":[[0,1.42,18662.07]],"ltp":1.43,"tv":495047.15,"id":2249229}]}]}
{"op":"mcm","clk":"4225817626","pt":1631460483912,"mc":[{"id":"1.187528277","rc":[{"batb":[[0,1.42,15418.54]],"ltp":1.43,"tv":495047.15,"id":2249229}]}]}
{"op":"mcm","clk":"4225824541","pt":1631460527079,"mc":[{"id":"1.187528277","rc":[{"trd":[[3.4,28925.88]],"batl":[[0,3.4,1739.01]],"ltp":3.4,"tv":110490.72,"id":19924831}],"tv":605537.88}]}
{"op":"mcm","clk":"4225831563","pt":1631460574160,"mc":[{"id":"1.187528277","rc":[{"trd":[[1.42,206718.99]],"batb":[[0,1.42,15411.31]],"ltp":1.42,"tv":495061.61,"id":2249229}],"tv":605552.34}]}
{"op":"mcm","clk":"4225833597","pt":1631460586893,"mc":[{"id":"1.187528277","rc":[{"trd":[[1.42,206818.99]],"batb":[[0,1.42,15361.31]],"ltp":1.42,"tv":495161.61,"id":2249229}],"tv":605652.34}]}
{"op":"mcm","clk":"4225845519","pt":1631460656708,"mc":[{"id":"1.187528277","rc":[{"trd":[[1.42,206934.6]],"batb":[[0,1.42,15303.5]],"ltp":1.42,"tv":495277.22,"id":2249229}],"tv":605767.95}]}
{"op":"mcm","clk":"4225845868","pt":1631460658677,"mc":[{"id":"1.187528277","rc":[{"batb":[[2,3.25,4834.3]],"batl":[[0,3.4,1730.47]],"ltp":3.4,"tv":110490.72,"id":19924831},{"batb":[[0,1.42,15228.35],[1,1.41,44161.57]],"batl":[[2,1.45,10237.59]],"ltp":1.42,"tv":495277.22,"id":2249229}]}]}
{"op":"mcm","clk":"4225847344","pt":1631460666509,"mc":[{"id":"1.187528277","rc":[{"batl":[[2,3.5,688.71]],"ltp":3.4,"tv":110490.72,"id":19924831}]}]}
{"op":"mcm","clk":"4225848419","pt":1631460672215,"mc":[{"id":"1.187528277","rc":[{"batl":[[0,1.43,14754.63]],"ltp":1.42,"tv":495277.22,"id":2249229}]}]}
{"op":"mcm","clk":"4225849143","pt":1631460676053,"mc":[{"id":"1.187528277","rc":[{"batb":[[0,1.42,15248.35]],"ltp":1.42,"tv":495277.22,"id":2249229}]}]}
{"op":"mcm","clk":"4225856488","pt":1631460714611,"mc":[{"id":"1.187528277","rc":[{"batl":[[0,1.43,14779.63]],"ltp":1.42,"tv":495277.22,"id":2249229}]}]}
{"op":"mcm","clk":"4225857289","pt":1631460719046,"mc":[{"id":"1.187528277","rc":[{"batb":[[0,1.42,15273.35]],"ltp":1.42,"tv":495277.22,"id":2249229}]}]}
{"op":"mcm","clk":"4225859933","pt":1631460733749,"mc":[{"id":"1.187528277","rc":[{"batl":[[0,1.43,17671.68]],"ltp":1.42,"tv":495277.22,"id":2249229}]}]}
{"op":"mcm","clk":"4225867929","pt":1631460779850,"mc":[{"id":"1.187528277","rc":[{"trd":[[1.42,207078.52]],"batb":[[0,1.42,15201.38]],"ltp":1.42,"tv":495421.14,"id":2249229}],"tv":605911.87}]}
{"op":"mcm","clk":"4225873381","pt":1631460812606,"mc":[{"id":"1.187528277","rc":[{"trd":[[1.42,207082.52]],"batb":[[0,1.42,15199.38]],"ltp":1.42,"tv":495425.14,"id":2249229}],"tv":605915.87}]}
{"op":"mcm","clk":"4225878377","pt":1631460840624,"mc":[{"id":"1.187528277","rc":[{"batb":[[2,3.25,4822.34]],"ltp":3.4,"tv":110490.72,"id":19924831},{"batb":[[1,1.41,44032.61]],"batl":[[2,1.45,10200.01]],"ltp":1.42,"tv":495425.14,"id":2249229}]}]}
{"op":"mcm","clk":"4225878485","pt":1631460841328,"mc":[{"id":"1.187528277","rc":[{"batl":[[0,3.4,1735.59]],"ltp":3.4,"tv":110490.72,"id":19924831},{"batb":[[0,1.42,15275.39]],"ltp":1.42,"tv":495425.14,"id":2249229}]}]}
{"op":"mcm","clk":"4225879859","pt":1631460848951,"mc":[{"id":"1.187528277","rc":[{"trd":[[3.35,36330.84]],"batb":[[0,3.35,3216.1]],"ltp":3.35,"tv":110550.72,"id":19924831}],"tv":605975.87}]}
{"op":"mcm","clk":"4225882130","pt":1631460860993,"mc":[{"id":"1.187528277","rc":[{"batl":[[0,1.43,17721.68]],"ltp":1.42,"tv":495425.14,"id":2249229}]}]}
{"op":"mcm","clk":"4225882680","pt":1631460863991,"mc":[{"id":"1.187528277","rc":[{"trd":[[3.35,36358.4]],"batb":[[0,3.35,3202.32]],"ltp":3.35,"tv":110578.28,"id":19924831}],"tv":606003.43}]}
{"op":"mcm","clk":"4225883072","pt":1631460866299,"mc":[{"id":"1.187528277","rc":[{"batb":[[0,1.42,15325.39]],"ltp":1.42,"tv":495425.14,"id":2249229}]}]}
{"op":"mcm","clk":"4225883206","pt":1631460867007,"mc":[{"id":"1.187528277","rc":[{"batl":[[0,1.43,22826.98]],"ltp":1.42,"tv":495425.14,"id":2249229}]}]}
{"op":"mcm","clk":"4225884331","pt":1631460873688,"mc":[{"id":"1.187528277","rc":[{"batl":[[2,3.5,2738.41]],"ltp":3.35,"tv":110578.28,"id":19924831}]}]}
{"op":"mcm","clk":"4225887521","pt":1631460891313,"mc":[{"id":"1.187528277","rc":[{"trd":[[3.35,36366.86]],"batb":[[0,3.35,3198.09]],"ltp":3.35,"tv":110586.74,"id":19924831}],"tv":606011.89}]}
{"op":"mcm","clk":"4225888859","pt":1631460898346,"mc":[{"id":"1.187528277","rc":[{"trd":[[1.43,171392.51]],"batl":[[0,1.43,22826.96]],"ltp":1.43,"tv":495425.18,"id":2249229}],"tv":606011.93}]}
{"op":"mcm","clk":"4225890060","pt":1631460905256,"mc":[{"id":"1.187528277","rc":[{"batb":[[0,3.35,3222.02]],"ltp":3.35,"tv":110586.74,"id":19924831}]}]}
{"op":"mcm","clk":"4225902979","pt":1631460975674,"mc":[{"id":"1.187528277","rc":[{"trd":[[1.42,207086.52]],"batb":[[0,1.42,15323.39]],"ltp":1.42,"tv":495429.18,"id":2249229}],"tv":606015.93}]}
{"op":"mcm","clk":"4225914489","pt":1631461038674,"mc":[{"id":"1.187528277","rc":[{"batb":[[0,1.42,15384.12]],"ltp":1.42,"tv":495429.18,"id":2249229}]}]}
{"op":"mcm","clk":"4225915689","pt":1631461045289,"mc":[{"id":"1.187528277","rc":[{"batb":[[1,3.3,8132.35]],"ltp":3.35,"tv":110586.74,"id":19924831}]}]}
{"op":"mcm","clk":"4225915953","pt":1631461046676,"mc":[{"id":"1.187528277","rc":[{"batb":[[0,3.35,3269.88]],"ltp":3.35,"tv":110586.74,"id":19924831}]}]}
{"op":"mcm","clk":"4225917777","pt":1631461057008,"mc":[{"id":"1.187528277","rc":[{"trd":[[1.43,171420.23]],"batl":[[0,1.43,22813.1]],"ltp":1.43,"tv":495456.9,"id":2249229}],"tv":606043.65}]}
{"op":"mcm","clk":"4225918937","pt":1631461063808,"mc":[{"id":"1.187528277","rc":[{"trd":[[1.42,207772.52]],"batb":[[0,1.42,15041.13]],"ltp":1.42,"tv":496142.91,"id":2249229}],"tv":606729.65}]}
{"op":"mcm","clk":"4225932450","pt":1631461138636,"mc":[{"id":"1.187528277","rc":[{"trd":[[1.42,219537.24]],"batb":[[0,1.42,9158.76]],"batl":[[1,1.44,57937.52]],"ltp":1.42,"tv":507907.62,"id":2249229}],"tv":618494.37}]}
{"op":"mcm","clk":"4225932614","pt":1631461139434,"mc":[{"id":"1.187528277","rc":[{"batb":[[0,1.42,9174.43]],"ltp":1.42,"tv":507907.62,"id":2249229}]}]}
{"op":"mcm","clk":"4225932807","pt":1631461140533,"mc":[{"id":"1.187528277","rc":[{"trd":[[3.35,36370.86]],"batb":[[0,3.35,3267.88]],"ltp":3.35,"tv":110590.74,"id":19924831}],"tv":618498.37}]}
{"op":"mcm","clk":"4225933699","pt":1631461145315,"mc":[{"id":"1.187528277","rc":[{"trd":[[1.42,231301.94]],"batb":[[0,1.42,3292.08]],"ltp":1.42,"tv":519672.32,"id":2249229}],"tv":630263.07}]}
{"op":"mcm","clk":"4225934191","pt":1631461147719,"mc":[{"id":"1.187528277","rc":[{"trd":[[1.42,237886.1]],"batb":[[0,1.41,44032.61],[1,1.4,46878.69],[2,1.39,49984.59]],"batl":[[0,1.42,1619.4],[1,1.43,22813.1],[2,1.44,57937.52]],"ltp":1.42,"tv":526256.48,"id":2249229}],"tv":636847.23}]}
{"op":"mcm","clk":"4225934366","pt":1631461148645,"mc":[{"id":"1.187528277","rc":[{"batb":[[0,3.35,4305.46],[1,3.3,8145.51],[2,3.25,4798.43]],"batl":[[0,3.4,1612.25]],"ltp":3.35,"tv":110590.74,"id":19924831},{"trd":[[1.42,238306.75]],"batb":[[0,1.41,47529.83]],"batl":[[0,1.42,1409.07],[1,1.43,22743.17]],"ltp":1.42,"tv":526677.13,"id":2249229}],"tv":637267.88}]}
{"op":"mcm","clk":"4225934548","pt":1631461149622,"mc":[{"id":"1.187528277","rc":[{"batb":[[0,3.35,4275.61],[2,3.25,4818.92]],"batl":[[1,3.45,1124.12]],"ltp":3.35,"tv":110590.74,"id":19924831},{"trd":[[1.42,241124.9]],"batb":[[0,1.41,47616.09]],"batl":[[0,1.43,22813.1],[1,1.44,58016.1],[2,1.45,10115.46]],"ltp":1.42,"tv":529495.28,"id":2249229}],"tv":640086.03}]}
{"op":"mcm","clk":"4225934597","pt":1631461149968,"mc":[{"id":"1.187528277","rc":[{"batl":[[0,1.43,26428.17]],"ltp":1.42,"tv":529495.28,"id":2249229}]}]}
{"op":"mcm","clk":"4225935642","pt":1631461155647,"mc":[{"id":"1.187528277","rc":[{"batb":[[0,3.35,4305.46]],"batl":[[0,3.4,693.59]],"ltp":3.35,"tv":110590.74,"id":19924831},{"trd":[[1.41,106804.13],[1.42,252370.69]],"batb":[[0,1.42,8.49],[1,1.41,41733.75],[2,1.4,46878.69]],"batl":[[0,1.43,26358.24]],"ltp":1.42,"tv":552505.77,"id":2249229}],"tv":663096.52}]}
{"op":"mcm","clk":"4225935821","pt":1631461156665,"mc":[{"id":"1.187528277","rc":[{"batb":[[0,3.35,4275.61]],"batl":[[0,3.4,1782.22]],"ltp":3.35,"tv":110590.74,"id":19924831},{"batb":[[0,1.41,42060.58],[1,1.4,46878.69],[2,1.39,49984.59]],"batl":[[0,1.43,26428.17]],"ltp":1.42,"tv":552505.77,"id":2249229}]}]}
{"op":"mcm","clk":"4225936575","pt":1631461160649,"mc":[{"id":"1.187528277","rc":[{"batl":[[0,1.42,175.9],[1,1.43,26428.17],[2,1.44,58016.1]],"ltp":1.42,"tv":552505.77,"id":2249229}]}]}
{"op":"mcm","clk":"4225936739","pt":1631461161663,"mc":[{"id":"1.187528277","rc":[{"batb":[[0,3.35,4305.46]],"batl":[[0,3.4,693.59]],"ltp":3.35,"tv":110590.74,"id":19924831},{"trd":[[1.42,252722.33]],"batl":[[0,1.43,26358.32],[1,1.44,58016.1],[2,1.45,10115.46]],"ltp":1.42,"tv":552857.41,"id":2249229}],"tv":663448.16}]}
{"op":"mcm","clk":"4225936826","pt":1631461162047,"mc":[{"id":"1.187528277","rc":[{"batb":[[0,3.35,4275.61]],"batl":[[0,3.4,1779.22]],"ltp":3.35,"tv":110590.74,"id":19924831},{"trd":[[1.42,252722.5],[1.43,171549.72]],"batl":[[0,1.43,26363.42]],"ltp":1.43,"tv":552987.07,"id":2249229}],"tv":663577.81}]}
{"op":"mcm","clk":"4225937000","pt":1631461162968,"mc":[{"id":"1.187528277","rc":[{"batb":[[0,3.35,6019.52]],"ltp":3.35,"tv":110590.74,"id":19924831}]}]}
{"op":"mcm","clk":"4225937622","pt":1631461166283,"mc":[{"id":"1.187528277","rc":[{"trd":[[1.43,171555.29]],"batl":[[0,1.43,26360.64]],"ltp":1.43,"tv":552992.63,"id":2249229}],"tv":663583.38}]}
{"op":"mcm","clk":"4225938850","pt":1631461173080,"mc":[{"id":"1.187528277","rc":[{"batl":[[0,1.43,27806.66]],"ltp":1.43,"tv":552992.63,"id":2249229}]}]}
{"op":"mcm","clk":"4225939817","pt":1631461178777,"mc":[{"id":"1.187528277","rc":[{"batb":[[2,3.25,4840.28]],"ltp":3.35,"tv":110590.74,"id":19924831}]}]}
{"op":"mcm","clk":"4225943020","pt":1631461196715,"mc":[{"id":"1.187528277","rc":[{"batl":[[0,3.4,1861.89]],"ltp":3.35,"tv":110590.74,"id":19924831},{"batl":[[0,1.42,22.03],[1,1.43,27806.66],[2,1.44,58016.1]],"ltp":1.43,"tv":552992.63,"id":2249229}]}]}
{"op":"mcm","clk":"4225943082","pt":1631461197027,"mc":[{"id":"1.187528277","rc":[{"batb":[[0,3.35,6049.37]],"batl":[[0,3.4,776.26]],"ltp":3.35,"tv":110590.74,"id":19924831},{"batl":[[1,1.43,27736.73]],"ltp":1.43,"tv":552992.63,"id":2249229}]}]}
{"op":"mcm","clk":"4225944931","pt":1631461206647,"mc":[{"id":"1.187528277","rc":[{"trd":[[1.42,252766.38]],"batl":[[0,1.43,27736.82],[1,1.44,58016.1],[2,1.45,10115.46]],"ltp":1.42,"tv":553036.51,"id":2249229}],"tv":663627.26}]}
{"op":"mcm","clk":"4225945006","pt":1631461207023,"mc":[{"id":"1.187528277","rc":[{"batb":[[0,3.35,6019.52]],"batl":[[0,3.4,1861.59]],"ltp":3.35,"tv":110590.74,"id":19924831},{"batl":[[0,1.43,27806.75]],"ltp":1.42,"tv":553036.51,"id":2249229}]}]}
{"op":"mcm","clk":"4225945316","pt":1631461208614,"mc":[{"id":"1.187528277","rc":[{"trd":[[3.35,36374.87]],"batb":[[0,3.35,6017.52]],"ltp":3.35,"tv":110594.74,"id":19924831}],"tv":663631.26}]}
{"op":"mcm","clk":"4225952166","pt":1631461246102,"mc":[{"id":"1.187528277","rc":[{"trd":[[1.42,252766.56],[1.43,171560.67]],"batl":[[0,1.43,27803.97]],"ltp":1.43,"tv":553042.08,"id":2249229}],"tv":663636.83}]}
{"op":"mcm","clk":"4225958744","pt":1631461280649,"mc":[{"id":"1.187528277","rc":[{"trd":[[1.41,106921.76]],"batb":[[0,1.41,42001.76]],"batl":[[0,1.42,58.41],[1,1.43,27803.97],[2,1.44,58016.1]],"ltp":1.41,"tv":553159.71,"id":2249229}],"tv":663754.46}]}
{"op":"mcm","clk":"4225958820","pt":1631461281069,"mc":[{"id":"1.187528277","rc":[{"batb":[[0,3.35,6047.37]],"batl":[[0,3.4,776.26]],"ltp":3.35,"tv":110594.74,"id":19924831},{"batl":[[1,1.43,27734.04]],"ltp":1.41,"tv":553159.71,"id":2249229}]}]}
{"op":"mcm","clk":"4225963383","pt":1631461306207,"mc":[{"id":"1.187528277","rc":[{"trd":[[3.35,36444.87]],"batb":[[0,3.35,6012.37]],"ltp":3.35,"tv":110664.75,"id":19924831}],"tv":663824.46}]}
{"op":"mcm","clk":"4225970487","pt":1631461344255,"mc":[{"id":"1.187528277","rc":[{"trd":[[3.4,28995.44]],"batl":[[0,3.4,741.49]],"ltp":3.4,"tv":110734.3,"id":19924831},{"batb":[[0,1.41,41936.76]],"batl":[[1,1.43,27634.04],[2,1.44,57966.1]],"ltp":1.41,"tv":553159.71,"id":2249229}],"tv":663894.02}]}
{"op":"mcm","clk":"4225980029","pt":1631461393924,"mc":[{"id":"1.187528277","rc":[{"batl":[[0,1.42,632.63]],"ltp":1.41,"tv":553159.71,"id":2249229}]}]}
{"op":"mcm","clk":"4225988236","pt":1631461439880,"mc":[{"id":"1.187528277","rc":[{"trd":[[1.41,107240.84]],"batb":[[0,1.41,41777.23]],"ltp":1.41,"tv":553478.79,"id":2249229}],"tv":664213.1}]}
{"op":"mcm","clk":"4225989013","pt":1631461444123,"mc":[{"id":"1.187528277","rc":[{"batl":[[0,1.42,791.03]],"ltp":1.41,"tv":553478.79,"id":2249229}]}]}
{"op":"mcm","clk":"4225990737","pt":1631461453806,"mc":[{"id":"1.187528277","rc":[{"batl":[[1,1.43,27734.04]],"ltp":1.41,"tv":553478.79,"id":2249229}]}]}
{"op":"mcm","clk":"4225997652","pt":1631461494373,"mc":[{"id":"1.187528277","rc":[{"batl":[[1,1.43,27834.04]],"ltp":1.41,"tv":553478.79,"id":2249229}]}]}
{"op":"mcm","clk":"4226006521","pt":1631461545243,"mc":[{"id":"1.187528277","rc":[{"trd":[[3.35,36468.87]],"batb":[[0,3.35,6000.36]],"ltp":3.35,"tv":110758.3,"id":19924831}],"tv":664237.1}]}
{"op":"mcm","clk":"4226013231","pt":1631461582902,"mc":[{"id":"1.187528277","rc":[{"batl":[[0,3.4,841.49]],"ltp":3.35,"tv":110758.3,"id":19924831}]}]}
{"op":"mcm","clk":"4226015670","pt":1631461596716,"mc":[{"id":"1.187528277","rc":[{"batb":[[1,3.3,8134.98]],"ltp":3.35,"tv":110758.3,"id":19924831}]}]}
{"op":"mcm","clk":"4226015796","pt":1631461597313,"mc":[{"id":"1.187528277","rc":[{"batb":[[1,3.3,8132.35],[2,3.25,4852.65]],"ltp":3.35,"tv":110758.3,"id":19924831},{"trd":[[1.41,107411.64]],"batb":[[0,1.41,41691.83]],"ltp":1.41,"tv":553649.59,"id":2249229}],"tv":664407.9}]}
{"op":"mcm","clk":"4226016548","pt":1631461601457,"mc":[{"id":"1.187528277","rc":[{"batl":[[0,1.42,875.84]],"ltp":1.41,"tv":553649.59,"id":2249229}]}]}
{"op":"mcm","clk":"4226026010","pt":1631461653830,"mc":[{"id":"1.187528277","rc":[{"trd":[[1.41,107414.4]],"batb":[[0,1.41,41690.45]],"ltp":1.41,"tv":553652.35,"id":2249229}],"tv":664410.66}]}
{"op":"mcm","clk":"4226038217","pt":1631461674528,"mc":[{"id":"1.187528277","rc":[{"trd":[[1.42,253379.48]],"batl":[[0,1.42,569.38]],"ltp":1.42,"tv":554265.27,"id":2249229}],"tv":665023.58}]}
{"op":"mcm","clk":"4226038372","pt":1631461675438,"mc":[{"id":"1.187528277","rc":[{"trd":[[1.42,253431.23]],"batl":[[0,1.42,543.5]],"ltp":1.42,"tv":554317.02,"id":2249229}],"tv":665075.33}]}
{"op":"mcm","clk":"4226038567","pt":1631461676557,"mc":[{"id":"1.187528277","rc":[{"trd":[[1.42,253482.99]],"batl":[[0,1.42,517.62]],"ltp":1.42,"tv":554368.78,"id":2249229}],"tv":665127.09}]}
{"op":"mcm","clk":"4226038737","pt":1631461677551,"mc":[{"id":"1.187528277","rc":[{"trd":[[1.42,253534.74]],"batl":[[0,1.42,491.75]],"ltp":1.42,"tv":554420.53,"id":2249229}],"tv":665178.84}]}
{"op":"mcm","clk":"4226038904","pt":1631461678545,"mc":[{"id":"1.187528277","rc":[{"trd":[[1.42,253586.5]],"batl":[[0,1.42,465.87]],"ltp":1.42,"tv":554472.29,"id":2249229}],"tv":665230.6}]}
{"op":"mcm","clk":"4226039077","pt":1631461679540,"mc":[{"id":"1.187528277","rc":[{"trd":[[1.42,253638.25]],"batl":[[0,1.42,439.99]],"ltp":1.42,"tv":554524.04,"id":2249229}],"tv":665282.35}]}
{"op":"mcm","clk":"4226039251","pt":1631461680555,"mc":[{"id":"1.187528277","rc":[{"trd":[[1.42,253690.01]],"batl":[[0,1.42,414.11]],"ltp":1.42,"tv":554575.8,"id":2249229}],"tv":665334.11}]}
{"op":"mcm","clk":"4226039435","pt":1631461681567,"mc":[{"id":"1.187528277","rc":[{"trd":[[1.42,253741.76]],"batl":[[0,1.42,388.23]],"ltp":1.42,"tv":554627.56,"id":2249229}],"tv":665385.87}]}
{"op":"mcm","clk":"4226039576","pt":1631461682448,"mc":[{"id":"1.187528277","rc":[{"trd":[[1.42,253793.52]],"batl":[[0,1.42,362.36]],"ltp":1.42,"tv":554679.31,"id":2249229}],"tv":665437.62}]}
{"op":"mcm","clk":"4226039752","pt":1631461683452,"mc":[{"id":"1.187528277","rc":[{"trd":[[1.42,253845.28]],"batl":[[0,1.42,336.48]],"ltp":1.42,"tv":554731.07,"id":2249229}],"tv":665489.38}]}
{"op":"mcm","clk":"4226039981","pt":1631461684691,"mc":[{"id":"1.187528277","rc":[{"trd":[[1.42,253914.28]],"batl":[[0,1.42,301.97]],"ltp":1.42,"tv":554800.07,"id":2249229}],"tv":665558.38}]}
{"op":"mcm","clk":"4226040145","pt":1631461685582,"mc":[{"id":"1.187528277","rc":[{"trd":[[1.42,253948.79]],"batl":[[0,1.42,284.72]],"ltp":1.42,"tv":554834.58,"id":2249229}],"tv":665592.89}]}
{"op":"mcm","clk":"4226040337","pt":1631461686660,"mc":[{"id":"1.187528277","rc":[{"trd":[[1.42,254017.79]],"batl":[[0,1.42,250.22]],"ltp":1.42,"tv":554903.59,"id":2249229}],"tv":665661.9}]}
{"op":"mcm","clk":"4226040517","pt":1631461687666,"mc":[{"id":"1.187528277","rc":[{"trd":[[1.42,254069.54]],"batl":[[0,1.42,224.34]],"ltp":1.42,"tv":554955.34,"id":2249229}],"tv":665713.65}]}
{"op":"mcm","clk":"4226040626","pt":1631461688276,"mc":[{"id":"1.187528277","rc":[{"trd":[[1.42,254104.05]],"batl":[[0,1.42,207.09]],"ltp":1.42,"tv":554989.84,"id":2249229}],"tv":665748.15}]}
{"op":"mcm","clk":"4226041547","pt":1631461693860,"mc":[{"id":"1.187528277","rc":[{"batb":[[0,1.41,42264.67]],"ltp":1.42,"tv":554989.84,"id":2249229}]}]}
{"op":"mcm","clk":"4226042472","pt":1631461699489,"mc":[{"id":"1.187528277","rc":[{"batb":[[0,3.35,5970.51]],"batl":[[0,3.4,1959.9]],"ltp":3.35,"tv":110758.3,"id":19924831},{"trd":[[1.42,254518.23]],"batb":[[0,1.42,12705.91],[1,1.41,42193.75],[2,1.4,46878.69]],"batl":[[0,1.43,27903.97],[1,1.44,57966.1],[2,1.45,10115.46]],"ltp":1.42,"tv":555404.02,"id":2249229}],"tv":666162.33}]}
{"op":"mcm","clk":"4226045071","pt":1631461713634,"mc":[{"id":"1.187528277","rc":[{"trd":[[1.42,254545.79]],"batb":[[0,1.42,12692.13],[1,1.41,38915.76]],"ltp":1.42,"tv":555431.58,"id":2249229}],"tv":666189.89}]}
{"op":"mcm","clk":"4226045215","pt":1631461714335,"mc":[{"id":"1.187528277","rc":[{"batb":[[0,1.42,12770.93]],"ltp":1.42,"tv":555431.58,"id":2249229}]}]}
{"op":"mcm","clk":"4226046241","pt":1631461719427,"mc":[{"id":"1.187528277","rc":[{"batb":[[0,1.42,13345.16],[1,1.41,38341.54]],"ltp":1.42,"tv":555431.58,"id":2249229}]}]}
{"op":"mcm","clk":"4226047261","pt":1631461724922,"mc":[{"id":"1.187528277","rc":[{"batb":[[0,3.35,4226.61]],"ltp":3.35,"tv":110758.3,"id":19924831}]}]}
{"op":"mcm","clk":"4226049421","pt":1631461736529,"mc":[{"id":"1.187528277","rc":[{"trd":[[3.35,36571.37]],"batb":[[0,3.35,4175.36]],"ltp":3.35,"tv":110860.8,"id":19924831}],"tv":666292.38}]}
{"op":"mcm","clk":"4226064095","pt":1631461820007,"mc":[{"id":"1.187528277","rc":[{"trd":[[1.43,171660.67]],"batl":[[0,1.43,27853.97]],"ltp":1.43,"tv":555531.58,"id":2249229}],"tv":666392.38}]}
{"op":"mcm","clk":"4226065757","pt":1631461830411,"mc":[{"id":"1.187528277","rc":[{"trd":[[1.42,254579.95]],"batb":[[0,1.42,13328.08]],"ltp":1.42,"tv":555565.74,"id":2249229}],"tv":666426.54}]}
{"op":"mcm","clk":"4226072592","pt":1631461871405,"mc":[{"id":"1.187528277","rc":[{"trd":[[3.35,36581.08]],"batb":[[0,3.35,4170.5]],"ltp":3.35,"tv":110870.52,"id":19924831}],"tv":666436.26}]}
{"op":"mcm","clk":"4226074805","pt":1631461884424,"mc":[{"id":"1.187528277","rc":[{"trd":[[1.43,171680.95]],"batl":[[0,1.43,27843.83]],"ltp":1.43,"tv":555586.02,"id":2249229}],"tv":666456.54}]}
{"op":"mcm","clk":"4226074922","pt":1631461885217,"mc":[{"id":"1.187528277","rc":[{"trd":[[3.35,36597.83]],"batb":[[0,3.35,4162.13]],"ltp":3.35,"tv":110887.26,"id":19924831}],"tv":666473.29}]}
{"op":"mcm","clk":"4226082364","pt":1631461929594,"mc":[{"id":"1.187528277","rc":[{"trd":[[3.35,38046.28]],"batb":[[0,3.35,3437.9]],"ltp":3.35,"tv":112335.72,"id":19924831}],"tv":667921.74}]}
{"op":"mcm","clk":"4226084836","pt":1631461944422,"mc":[{"id":"1.187528277","rc":[{"batl":[[0,1.43,28043.83]],"ltp":1.43,"tv":555586.02,"id":2249229}]}]}
{"op":"mcm","clk":"4226087609","pt":1631461960785,"mc":[{"id":"1.187528277","rc":[{"batb":[[0,1.42,13500.22]],"ltp":1.43,"tv":555586.02,"id":2249229}]}]}
{"op":"mcm","clk":"4226101717","pt":1631462045209,"mc":[{"id":"1.187528277","rc":[{"batl":[[0,1.43,28470.85],[2,1.45,9688.44]],"ltp":1.43,"tv":555586.02,"id":2249229}]}]}
{"op":"mcm","clk":"4226103504","pt":1631462055892,"mc":[{"id":"1.187528277","rc":[{"trd":[[3.35,38088.67]],"batb":[[0,3.35,3416.71]],"ltp":3.35,"tv":112378.1,"id":19924831}],"tv":667964.13}]}
{"op":"mcm","clk":"4226104564","pt":1631462062350,"mc":[{"id":"1.187528277","rc":[{"trd":[[1.43,171829.84]],"batl":[[0,1.43,28396.41]],"ltp":1.43,"tv":555734.92,"id":2249229}],"tv":668113.02}]}
{"op":"mcm","clk":"4226117799","pt":1631462144298,"mc":[{"id":"1.187528277","rc":[{"trd":[[1.42,254607.51]],"batb":[[0,1.42,13486.44]],"ltp":1.42,"tv":555762.47,"id":2249229}],"tv":668140.58}]}
{"op":"mcm","clk":"4226123431","pt":1631462178564,"mc":[{"id":"1.187528277","rc":[{"batb":[[0,1.42,825.17]],"ltp":1.42,"tv":555762.47,"id":2249229}]}]}
{"op":"mcm","clk":"4226125328","pt":1631462189559,"mc":[{"id":"1.187528277","rc":[{"trd":[[1.42,255109.51]],"batb":[[0,1.42,574.17]],"ltp":1.42,"tv":556264.47,"id":2249229}],"tv":668642.58}]}
{"op":"mcm","clk":"4226127238","pt":1631462201389,"mc":[{"id":"1.187528277","rc":[{"trd":[[1.42,255112.25]],"batb":[[0,1.42,572.8]],"ltp":1.42,"tv":556267.22,"id":2249229}],"tv":668645.33}]}
{"op":"mcm","clk":"4226130571","pt":1631462221324,"mc":[{"id":"1.187528277","rc":[{"trd":[[1.42,255372.25]],"batb":[[0,1.42,442.8]],"ltp":1.42,"tv":556527.22,"id":2249229}],"tv":668905.33}]}
{"op":"mcm","clk":"4226134256","pt":1631462244678,"mc":[{"id":"1.187528277","rc":[{"batb":[[0,1.42,1101.56]],"ltp":1.42,"tv":556527.22,"id":2249229}]}]}
{"op":"mcm","clk":"4226134916","pt":1631462249270,"mc":[{"id":"1.187528277","rc":[{"trd":[[1.42,255444.55]],"batb":[[0,1.42,1065.41]],"ltp":1.42,"tv":556599.52,"id":2249229}],"tv":668977.63}]}
{"op":"mcm","clk":"4226138329","pt":1631462271224,"mc":[{"id":"1.187528277","rc":[{"trd":[[3.4,29027.59]],"batl":[[0,3.4,1943.82]],"ltp":3.4,"tv":112410.25,"id":19924831}],"tv":669009.77}]}
{"op":"mcm","clk":"4226143427","pt":1631462302877,"mc":[{"id":"1.187528277","rc":[{"trd":[[1.42,255445.97]],"batb":[[0,1.42,1064.7]],"ltp":1.42,"tv":556600.94,"id":2249229}],"tv":669011.19}]}
{"op":"mcm","clk":"4226144849","pt":1631462312322,"mc":[{"id":"1.187528277","rc":[{"trd":[[3.35,38100.26]],"batb":[[0,3.35,3410.91]],"ltp":3.35,"tv":112421.84,"id":19924831}],"tv":669022.79}]}
{"op":"mcm","clk":"4226145309","pt":1631462315580,"mc":[{"id":"1.187528277","rc":[{"trd":[[1.42,257259.32]],"batb":[[0,1.42,158.03]],"ltp":1.42,"tv":558414.28,"id":2249229}],"tv":670836.13}]}
{"op":"mcm","clk":"4226153968","pt":1631462369702,"mc":[{"id":"1.187528277","rc":[{"trd":[[3.35,38104.6]],"batb":[[0,3.35,3408.74]],"ltp":3.35,"tv":112426.18,"id":19924831}],"tv":670840.47}]}
{"op":"mcm","clk":"4226155559","pt":1631462379618,"mc":[{"id":"1.187528277","rc":[{"trd":[[1.42,257430.12]],"batb":[[0,1.42,72.63]],"ltp":1.42,"tv":558585.09,"id":2249229}],"tv":671011.27}]}
{"op":"mcm","clk":"4226166616","pt":1631462437629,"mc":[{"id":"1.187528277","rc":[{"trd":[[3.35,38124.6]],"batb":[[0,3.35,3398.74]],"ltp":3.35,"tv":112446.18,"id":19924831}],"tv":671031.27}]}
{"op":"mcm","clk":"4226166714","pt":1631462438138,"mc":[{"id":"1.187528277","rc":[{"batb":[[1,1.41,38350.17]],"ltp":1.42,"tv":558585.09,"id":2249229}]}]}
{"op":"mcm","clk":"4226181566","pt":1631462515964,"mc":[{"id":"1.187528277","rc":[{"batb":[[0,1.42,12985.63]],"ltp":1.42,"tv":558585.09,"id":2249229}]}]}
{"op":"mcm","clk":"4226182270","pt":1631462519694,"mc":[{"id":"1.187528277","rc":[{"trd":[[1.42,257471.92]],"batb":[[0,1.42,12964.73]],"ltp":1.42,"tv":558626.89,"id":2249229}],"tv":671073.07}]}
{"op":"mcm","clk":"4226183477","pt":1631462525801,"mc":[{"id":"1.187528277","rc":[{"trd":[[3.35,38425.48]],"batb":[[0,3.35,3248.3]],"ltp":3.35,"tv":112747.06,"id":19924831}],"tv":671373.95}]}
{"op":"mcm","clk":"4226188117","pt":1631462549727,"mc":[{"id":"1.187528277","rc":[{"batb":[[0,1.42,13066.4]],"ltp":1.42,"tv":558626.89,"id":2249229}]}]}
{"op":"mcm","clk":"4226190197","pt":1631462559953,"mc":[{"id":"1.187528277","rc":[{"trd":[[1.42,257716.3]],"batb":[[0,1.42,12944.21]],"ltp":1.42,"tv":558871.27,"id":2249229}],"tv":671618.33}]}
{"op":"mcm","clk":"4226190363","pt":1631462560741,"mc":[{"id":"1.187528277","rc":[{"batb":[[2,3.25,4847.65]],"ltp":3.35,"tv":112747.06,"id":19924831}]}]}
{"op":"mcm","clk":"4226193584","pt":1631462577171,"mc":[{"id":"1.187528277","rc":[{"batb":[[1,3.3,8137.35]],"ltp":3.35,"tv":112747.06,"id":19924831}]}]}
{"op":"mcm","clk":"4226194818","pt":1631462583598,"mc":[{"id":"1.187528277","rc":[{"trd":[[3.4,29028.18]],"batl":[[0,3.4,1943.53]],"ltp":3.4,"tv":112747.65,"id":19924831}],"tv":671618.92}]}
{"op":"mcm","clk":"4226212585","pt":1631462684966,"mc":[{"id":"1.187528277","rc":[{"trd":[[3.35,38565.48]],"batb":[[0,3.35,3178.3]],"ltp":3.35,"tv":112887.65,"id":19924831}],"tv":671758.92}]}
{"op":"mcm","clk":"4226219812","pt":1631462725095,"mc":[{"id":"1.187528277","rc":[{"trd":[[1.43,171886.78]],"batl":[[0,1.43,28367.94]],"ltp":1.43,"tv":558928.21,"id":2249229}],"tv":671815.86}]}
{"op":"mcm","clk":"4226227067","pt":1631462765074,"mc":[{"id":"1.187528277","rc":[{"batl":[[0,3.4,1947.78]],"ltp":3.35,"tv":112887.65,"id":19924831}]}]}
{"op":"mcm","clk":"4226230516","pt":1631462784106,"mc":[{"id":"1.187528277","rc":[{"trd":[[1.42,257758.56]],"batb":[[0,1.42,12923.08]],"ltp":1.42,"tv":558970.47,"id":2249229}],"tv":671858.12}]}
{"op":"mcm","clk":"4226244427","pt":1631462840074,"mc":[{"id":"1.187528277","rc":[{"trd":[[3.35,38575.73]],"batb":[[0,3.35,3173.18]],"ltp":3.35,"tv":112897.9,"id":19924831}],"tv":671868.37}]}
{"op":"mcm","clk":"4226247219","pt":1631462855420,"mc":[{"id":"1.187528277","rc":[{"trd":[[1.42,257764.58]],"batb":[[0,1.42,12920.07]],"ltp":1.42,"tv":558976.48,"id":2249229}],"tv":671874.39}]}
{"op":"mcm","clk":"4226250770","pt":1631462876261,"mc":[{"id":"1.187528277","rc":[{"trd":[[3.4,29128.18]],"batl":[[0,3.4,1897.77]],"ltp":3.4,"tv":112997.91,"id":19924831}],"tv":671974.39}]}
{"op":"mcm","clk":"4226255402","pt":1631462902575,"mc":[{"id":"1.187528277","rc":[{"trd":[[1.42,257766.28]],"batb":[[0,1.42,12919.22]],"ltp":1.42,"tv":558978.19,"id":2249229}],"tv":671976.1}]}
{"op":"mcm","clk":"4226258619","pt":1631462918207,"mc":[{"id":"1.187528277","rc":[{"trd":[[1.42,259419.54]],"batb":[[0,1.42,12092.59]],"ltp":1.42,"tv":560631.45,"id":2249229}],"tv":673629.36}]}
{"op":"mcm","clk":"4226266916","pt":1631462957065,"mc":[{"id":"1.187528277","rc":[{"trd":[[1.42,259619.54]],"batb":[[0,1.42,11992.59]],"ltp":1.42,"tv":560831.45,"id":2249229}],"tv":673829.36}]}
{"op":"mcm","clk":"4226274334","pt":1631462996367,"mc":[{"id":"1.187528277","rc":[{"trd":[[3.35,38591.73]],"batb":[[0,3.35,3165.18]],"ltp":3.35,"tv":113013.9,"id":19924831}],"tv":673845.35}]}
{"op":"mcm","clk":"4226284262","pt":1631463047263,"mc":[{"id":"1.187528277","rc":[{"batl":[[0,3.4,4897.77]],"ltp":3.35,"tv":113013.9,"id":19924831}]}]}
{"op":"mcm","clk":"4226284649","pt":1631463049440,"mc":[{"id":"1.187528277","rc":[{"trd":[[1.43,171887.96]],"batl":[[0,1.43,28367.35]],"ltp":1.43,"tv":560832.63,"id":2249229}],"tv":673846.53}]}
{"op":"mcm","clk":"4226287066","pt":1631463061476,"mc":[{"id":"1.187528277","rc":[{"batb":[[1,1.41,38454.32]],"ltp":1.43,"tv":560832.63,"id":2249229}]}]}
{"op":"mcm","clk":"4226290426","pt":1631463078614,"mc":[{"id":"1.187528277","rc":[{"batl":[[1,1.44,57957.56]],"ltp":1.43,"tv":560832.63,"id":2249229}]}]}
{"op":"mcm","clk":"4226290929","pt":1631463081194,"mc":[{"id":"1.187528277","rc":[{"trd":[[1.42,259752.74]],"batb":[[0,1.42,11925.99]],"ltp":1.42,"tv":560965.83,"id":2249229}],"tv":673979.73}]}
{"op":"mcm","clk":"4226296210","pt":1631463108831,"mc":[{"id":"1.187528277","rc":[{"batl":[[1,1.44,57949.02]],"ltp":1.42,"tv":560965.83,"id":2249229}]}]}
{"op":"mcm","clk":"4226297373","pt":1631463115296,"mc":[{"id":"1.187528277","rc":[{"batb":[[0,1.42,12353.02]],"ltp":1.42,"tv":560965.83,"id":2249229}]}]}
{"op":"mcm","clk":"4226297595","pt":1631463116381,"mc":[{"id":"1.187528277","rc":[{"batl":[[1,1.44,57521.99]],"ltp":1.42,"tv":560965.83,"id":2249229}]}]}
{"op":"mcm","clk":"4226302418","pt":1631463141695,"mc":[{"id":"1.187528277","rc":[{"trd":[[1.43,172089.2]],"batl":[[0,1.43,28266.73]],"ltp":1.43,"tv":561167.06,"id":2249229}],"tv":674180.97}]}
{"op":"mcm","clk":"4226303775","pt":1631463148534,"mc":[{"id":"1.187528277","rc":[{"batl":[[1,1.44,57530.53]],"ltp":1.43,"tv":561167.06,"id":2249229}]}]}
{"op":"mcm","clk":"4226306302","pt":1631463161465,"mc":[{"id":"1.187528277","rc":[{"trd":[[3.35,38601.98]],"batb":[[0,3.35,3160.05]],"ltp":3.35,"tv":113024.15,"id":19924831}],"tv":674191.22}]}
{"op":"mcm","clk":"4226318370","pt":1631463225869,"mc":[{"id":"1.187528277","rc":[{"trd":[[3.35,38605.98]],"batb":[[0,3.35,3158.05]],"ltp":3.35,"tv":113028.16,"id":19924831}],"tv":674195.22}]}
{"op":"mcm","clk":"4226322668","pt":1631463247593,"mc":[{"id":"1.187528277","rc":[{"trd":[[3.35,38609.43]],"batb":[[0,3.35,3156.32]],"ltp":3.35,"tv":113031.61,"id":19924831}],"tv":674198.68}]}
{"op":"mcm","clk":"4226330397","pt":1631463289176,"mc":[{"id":"1.187528277","rc":[{"trd":[[3.35,38951.05]],"batb":[[0,3.35,2985.51]],"ltp":3.35,"tv":113373.23,"id":19924831}],"tv":674540.3}]}
{"op":"mcm","clk":"4226345178","pt":1631463364352,"mc":[{"id":"1.187528277","rc":[{"trd":[[1.42,259765.52]],"batb":[[0,1.42,12346.63]],"ltp":1.42,"tv":561179.84,"id":2249229}],"tv":674553.08}]}
{"op":"mcm","clk":"4226353610","pt":1631463408019,"mc":[{"id":"1.187528277","rc":[{"trd":[[1.42,259781.28]],"batb":[[0,1.42,12338.75]],"ltp":1.42,"tv":561195.6,"id":2249229}],"tv":674568.84}]}
{"op":"mcm","clk":"4226354301","pt":1631463411957,"mc":[{"id":"1.187528277","rc":[{"trd":[[1.42,260021.32]],"batb":[[0,1.42,12218.73]],"ltp":1.42,"tv":561435.64,"id":2249229}],"tv":674808.88}]}
{"op":"mcm","clk":"4226360111","pt":1631463442480,"mc":[{"id":"1.187528277","rc":[{"trd":[[1.42,260038.72]],"batb":[[0,1.42,12210.03]],"ltp":1.42,"tv":561453.04,"id":2249229}],"tv":674826.28}]}
{"op":"mcm","clk":"4226362948","pt":1631463457919,"mc":[{"id":"1.187528277","rc":[{"batb":[[0,1.42,12108.35]],"ltp":1.42,"tv":561453.04,"id":2249229}]}]}
{"op":"mcm","clk":"4226380258","pt":1631463546911,"mc":[{"id":"1.187528277","rc":[{"trd":[[3.35,38953.08]],"batb":[[0,3.35,2984.5]],"ltp":3.35,"tv":113375.26,"id":19924831}],"tv":674828.3}]}
{"op":"mcm","clk":"4226385782","pt":1631463576327,"mc":[{"id":"1.187528277","rc":[{"trd":[[1.42,260438.72]],"batb":[[0,1.42,11908.35]],"ltp":1.42,"tv":561853.04,"id":2249229}],"tv":675228.3}]}
{"op":"mcm","clk":"4226386109","pt":1631463577948,"mc":[{"id":"1.187528277","rc":[{"trd":[[1.42,261438.72]],"batb":[[0,1.42,11408.35]],"ltp":1.42,"tv":562853.04,"id":2249229}],"tv":676228.3}]}
{"op":"mcm","clk":"4226387718","pt":1631463585874,"mc":[{"id":"1.187528277","rc":[{"trd":[[3.35,39153.08]],"batb":[[0,3.35,2884.5]],"ltp":3.35,"tv":113575.26,"id":19924831}],"tv":676428.3}]}
{"op":"mcm","clk":"4226390522","pt":1631463600861,"mc":[{"id":"1.187528277","rc":[{"trd":[[1.42,261583.32]],"batb":[[0,1.42,11336.05]],"ltp":1.42,"tv":562997.64,"id":2249229}],"tv":676572.91}]}
{"op":"mcm","clk":"4226392307","pt":1631463609904,"mc":[{"id":"1.187528277","rc":[{"batb":[[0,3.35,2935.18]],"ltp":3.35,"tv":113575.26,"id":19924831},{"batb":[[0,1.42,11455.62]],"ltp":1.42,"tv":562997.64,"id":2249229}]}]}
{"op":"mcm","clk":"4226392942","pt":1631463613076,"mc":[{"id":"1.187528277","rc":[{"trd":[[3.35,39353.08]],"batb":[[0,3.35,2835.18]],"ltp":3.35,"tv":113775.26,"id":19924831}],"tv":676772.91}]}
{"op":"mcm","clk":"4226397504","pt":1631463638724,"mc":[{"id":"1.187528277","rc":[{"trd":[[3.4,29164.98]],"batl":[[0,3.4,4879.37]],"ltp":3.4,"tv":113812.06,"id":19924831}],"tv":676809.71}]}
{"op":"mcm","clk":"4226402275","pt":1631463664737,"mc":[{"id":"1.187528277","rc":[{"trd":[[1.43,172139.92]],"batl":[[0,1.43,28241.37]],"ltp":1.43,"tv":563048.36,"id":2249229}],"tv":676860.43}]}
{"op":"mcm","clk":"4226406151","pt":1631463686564,"mc":[{"id":"1.187528277","rc":[{"batl":[[0,3.4,4881.37]],"ltp":3.4,"tv":113812.06,"id":19924831}]}]}
{"op":"mcm","clk":"4226408187","pt":1631463697803,"mc":[{"id":"1.187528277","rc":[{"trd":[[3.35,39354.09]],"batb":[[0,3.35,2834.67]],"ltp":3.35,"tv":113813.07,"id":19924831}],"tv":676861.44}]}
{"op":"mcm","clk":"4226414844","pt":1631463736127,"mc":[{"id":"1.187528277","rc":[{"batb":[[0,1.42,11755.62]],"ltp":1.43,"tv":563048.36,"id":2249229}]}]}
{"op":"mcm","clk":"4226415076","pt":1631463737526,"mc":[{"id":"1.187528277","rc":[{"trd":[[3.35,39420.09]],"batb":[[0,3.35,2801.67]],"ltp":3.35,"tv":113879.07,"id":19924831}],"tv":676927.44}]}
{"op":"mcm","clk":"4226415559","pt":1631463740597,"mc":[{"id":"1.187528277","rc":[{"trd":[[3.35,39424.1]],"batb":[[0,3.35,2799.67]],"ltp":3.35,"tv":113883.07,"id":19924831}],"tv":676931.44}]}
{"op":"mcm","clk":"4226418548","pt":1631463761433,"mc":[{"id":"1.187528277","rc":[{"trd":[[3.35,39465.96]],"batb":[[0,3.35,2778.74]],"ltp":3.35,"tv":113924.94,"id":19924831}],"tv":676973.31}]}
{"op":"mcm","clk":"4226443932","pt":1631463928406,"mc":[{"id":"1.187528277","rc":[{"batb":[[0,3.35,2903.74],[2,3.25,4747.65]],"ltp":3.35,"tv":113924.94,"id":19924831}]}]}
{"op":"mcm","clk":"4226444938","pt":1631463934698,"mc":[{"id":"1.187528277","rc":[{"batb":[[0,3.35,2887.74]],"ltp":3.35,"tv":113924.94,"id":19924831}]}]}
{"op":"mcm","clk":"4226445612","pt":1631463939390,"mc":[{"id":"1.187528277","rc":[{"batb":[[0,3.35,3020.39]],"ltp":3.35,"tv":113924.94,"id":19924831}]}]}
{"op":"mcm","clk":"4226446574","pt":1631463945803,"mc":[{"id":"1.187528277","rc":[{"batb":[[2,1.4,46978.69]],"ltp":1.43,"tv":563048.36,"id":2249229}]}]}
{"op":"mcm","clk":"4226447269","pt":1631463950516,"mc":[{"id":"1.187528277","rc":[{"trd":[[1.42,261603.82]],"batb":[[0,1.42,11745.37]],"ltp":1.42,"tv":563068.86,"id":2249229}],"tv":676993.8}]}
{"op":"mcm","clk":"4226447347","pt":1631463951007,"mc":[{"id":"1.187528277","rc":[{"batb":[[2,1.4,46989.08]],"batl":[[0,1.43,28273.81]],"ltp":1.42,"tv":563068.86,"id":2249229}]}]}
{"op":"mcm","clk":"4226447683","pt":1631463953203,"mc":[{"id":"1.187528277","rc":[{"batb":[[2,1.4,46978.69]],"ltp":1.42,"tv":563068.86,"id":2249229}]}]}
{"op":"mcm","clk":"4226451928","pt":1631463981646,"mc":[{"id":"1.187528277","rc":[{"batb":[[0,1.42,11943.3]],"ltp":1.42,"tv":563068.86,"id":2249229}]}]}
{"op":"mcm","clk":"4226452803","pt":1631463987664,"mc":[{"id":"1.187528277","rc":[{"batl":[[0,3.4,4798.7]],"ltp":3.35,"tv":113924.94,"id":19924831},{"trd":[[1.43,172891.48]],"batl":[[0,1.43,27898.03]],"ltp":1.43,"tv":563820.42,"id":2249229}],"tv":677745.36}]}
{"op":"mcm","clk":"4226460509","pt":1631464039558,"mc":[{"id":"1.187528277","rc":[{"batl":[[1,1.44,57538.22]],"ltp":1.43,"tv":563820.42,"id":2249229}]}]}
{"op":"mcm","clk":"4226463040","pt":1631464057092,"mc":[{"id":"1.187528277","rc":[{"batl":[[0,1.43,27918.03]],"ltp":1.43,"tv":563820.42,"id":2249229}]}]}
{"op":"mcm","clk":"4226466046","pt":1631464077384,"mc":[{"id":"1.187528277","rc":[{"batl":[[1,1.44,57558.22]],"ltp":1.43,"tv":563820.42,"id":2249229}]}]}
{"op":"mcm","clk":"4226468454","pt":1631464093505,"mc":[{"id":"1.187528277","rc":[{"trd":[[1.42,261653.82]],"batb":[[0,1.42,11918.3]],"ltp":1.42,"tv":563870.42,"id":2249229}],"tv":677795.36}]}
{"op":"mcm","clk":"4226470580","pt":1631464108419,"mc":[{"id":"1.187528277","rc":[{"batl":[[2,1.45,9708.44]],"ltp":1.42,"tv":563870.42,"id":2249229}]}]}
{"op":"mcm","clk":"4226474368","pt":1631464135428,"mc":[{"id":"1.187528277","rc":[{"trd":[[1.42,261693.82]],"batb":[[0,1.42,11898.3]],"ltp":1.42,"tv":563910.42,"id":2249229}],"tv":677835.36}]}
{"op":"mcm","clk":"4226474621","pt":1631464137262,"mc":[{"id":"1.187528277","rc":[{"trd":[[1.42,261735.82]],"batb":[[0,1.42,11877.3]],"ltp":1.42,"tv":563952.42,"id":2249229}],"tv":677877.36}]}
{"op":"mcm","clk":"4226474824","pt":1631464138534,"mc":[{"id":"1.187528277","rc":[{"trd":[[1.42,261835.82]],"batb":[[0,1.42,11827.3]],"ltp":1.42,"tv":564052.42,"id":2249229}],"tv":677977.36}]}
{"op":"mcm","clk":"4226475942","pt":1631464146046,"mc":[{"id":"1.187528277","rc":[{"batl":[[2,1.45,9735.99]],"ltp":1.42,"tv":564052.42,"id":2249229}]}]}
{"op":"mcm","clk":"4226477027","pt":1631464153445,"mc":[{"id":"1.187528277","rc":[{"trd":[[3.35,39575.96]],"batb":[[0,3.35,2965.39]],"ltp":3.35,"tv":114034.94,"id":19924831},{"batl":[[1,1.44,57585.77],[2,1.45,9708.44]],"ltp":1.42,"tv":564052.42,"id":2249229}],"tv":678087.36}]}
{"op":"mcm","clk":"4226477842","pt":1631464159077,"mc":[{"id":"1.187528277","rc":[{"batb":[[2,3.25,4757.05]],"ltp":3.35,"tv":114034.94,"id":19924831},{"batl":[[1,1.44,57591.75]],"ltp":1.42,"tv":564052.42,"id":2249229}]}]}
{"op":"mcm","clk":"4226478386","pt":1631464162988,"mc":[{"id":"1.187528277","rc":[{"batb":[[1,1.41,38474.37]],"ltp":1.42,"tv":564052.42,"id":2249229}]}]}
{"op":"mcm","clk":"4226483328","pt":1631464199412,"mc":[{"id":"1.187528277","rc":[{"trd":[[1.42,262302.42]],"batb":[[0,1.42,11594]],"ltp":1.42,"tv":564519.02,"id":2249229}],"tv":678553.96}]}
{"op":"mcm","clk":"4226483670","pt":1631464201624,"mc":[{"id":"1.187528277","rc":[{"trd":[[1.42,262653.4]],"batb":[[0,1.42,11418.51]],"ltp":1.42,"tv":564870.01,"id":2249229}],"tv":678904.95}]}
{"op":"mcm","clk":"4226484528","pt":1631464206965,"mc":[{"id":"1.187528277","rc":[{"trd":[[3.35,39605.96]],"batb":[[0,3.35,2950.39]],"ltp":3.35,"tv":114064.94,"id":19924831}],"tv":678934.95}]}
{"op":"mcm","clk":"4226485216","pt":1631464211135,"mc":[{"id":"1.187528277","rc":[{"batl":[[1,1.44,57564.2]],"ltp":1.42,"tv":564870.01,"id":2249229}]}]}
{"op":"mcm","clk":"4226487855","pt":1631464228351,"mc":[{"id":"1.187528277","rc":[{"trd":[[1.42,263385.4]],"batb":[[0,1.42,11052.51]],"ltp":1.42,"tv":565602.01,"id":2249229}],"tv":679666.95}]}
{"op":"mcm","clk":"4226488159","pt":1631464230369,"mc":[{"id":"1.187528277","rc":[{"trd":[[1.42,263440.51]],"batb":[[0,1.42,11024.96]],"ltp":1.42,"tv":565657.11,"id":2249229}],"tv":679722.05}]}
{"op":"mcm","clk":"4226492202","pt":1631464259130,"mc":[{"id":"1.187528277","rc":[{"batb":[[1,1.41,38499.37]],"ltp":1.42,"tv":565657.11,"id":2249229}]}]}
{"op":"mcm","clk":"4226492976","pt":1631464264509,"mc":[{"id":"1.187528277","rc":[{"trd":[[3.35,39611.96]],"batb":[[0,3.35,2947.39]],"ltp":3.35,"tv":114070.94,"id":19924831}],"tv":679728.06}]}
{"op":"mcm","clk":"4226493821","pt":1631464269962,"mc":[{"id":"1.187528277","rc":[{"trd":[[3.35,39618.2]],"batb":[[0,3.35,2944.27]],"ltp":3.35,"tv":114077.17,"id":19924831}],"tv":679734.29}]}
{"op":"mcm","clk":"4226494175","pt":1631464272433,"mc":[{"id":"1.187528277","rc":[{"batb":[[2,3.25,4748.5]],"batl":[[0,3.4,4825.17],[1,3.45,1079.71]],"ltp":3.35,"tv":114077.17,"id":19924831},{"batl":[[1,1.44,57480.5],[2,1.45,9844.23]],"ltp":1.42,"tv":565657.11,"id":2249229}]}]}
{"op":"mcm","clk":"4226496761","pt":1631464290749,"mc":[{"id":"1.187528277","rc":[{"trd":[[1.42,263490.51]],"batb":[[0,1.42,10999.96]],"ltp":1.42,"tv":565707.11,"id":2249229}],"tv":679784.29}]}
{"op":"mcm","clk":"4226503867","pt":1631464340424,"mc":[{"id":"1.187528277","rc":[{"trd":[[1.42,264672.26]],"batb":[[0,1.42,10409.1]],"ltp":1.42,"tv":566888.86,"id":2249229}],"tv":680966.04}]}
{"op":"mcm","clk":"4226504070","pt":1631464342011,"mc":[{"id":"1.187528277","rc":[{"batb":[[2,3.25,4738.26]],"ltp":3.35,"tv":114077.17,"id":19924831},{"batb":[[1,1.41,38540.36]],"ltp":1.42,"tv":566888.86,"id":2249229}]}]}
{"op":"mcm","clk":"4226506082","pt":1631464356668,"mc":[{"id":"1.187528277","rc":[{"trd":[[3.35,45399.28]],"batb":[[0,3.3,7198.65],[1,3.25,3747.26],[2,3.2,1743.91]],"batl":[[0,3.4,4848.7]],"ltp":3.35,"tv":119858.25,"id":19924831},{"batb":[[2,1.4,48181.69]],"batl":[[0,1.43,26617.47],[1,1.44,55708.5],[2,1.45,7968.23]],"ltp":1.42,"tv":566888.86,"id":2249229}],"tv":686747.12}]}
{"op":"mcm","clk":"4226506217","pt":1631464357446,"mc":[{"id":"1.187528277","rc":[{"batl":[[0,3.35,3],[1,3.4,4848.7],[2,3.45,1079.71]],"ltp":3.35,"tv":119858.25,"id":19924831},{"batb":[[0,1.42,14531.52]],"ltp":1.42,"tv":566888.86,"id":2249229}]}]}
{"op":"mcm","clk":"4226508081","pt":1631464370470,"mc":[{"id":"1.187528277","rc":[{"trd":[[3.3,37065.74]],"batb":[[0,3.3,7168.65]],"ltp":3.3,"tv":119918.25,"id":19924831}],"tv":686807.12}]}
{"op":"mcm","clk":"4226508216","pt":1631464371447,"mc":[{"id":"1.187528277","rc":[{"batb":[[0,1.42,18146.59]],"ltp":1.42,"tv":566888.86,"id":2249229}]}]}
{"op":"mcm","clk":"4226508361","pt":1631464372554,"mc":[{"id":"1.187528277","rc":[{"trd":[[3.3,37070.26]],"batb":[[0,3.3,7166.39]],"ltp":3.3,"tv":119922.77,"id":19924831},{"trd":[[1.42,265072.26]],"batb":[[0,1.42,17946.59]],"ltp":1.42,"tv":567288.86,"id":2249229}],"tv":687211.64}]}
{"op":"mcm","clk":"4226510419","pt":1631464388171,"mc":[{"id":"1.187528277","rc":[{"trd":[[1.42,267072.26]],"batb":[[0,1.42,16946.59]],"ltp":1.42,"tv":569288.86,"id":2249229}],"tv":689211.64}]}
{"op":"mcm","clk":"4226512136","pt":1631464400703,"mc":[{"id":"1.187528277","rc":[{"batl":[[1,3.4,4858.1]],"ltp":3.3,"tv":119922.77,"id":19924831}]}]}
{"op":"mcm","clk":"4226514099","pt":1631464414617,"mc":[{"id":"1.187528277","rc":[{"batl":[[0,1.43,26667.47]],"ltp":1.42,"tv":569288.86,"id":2249229}]}]}
{"op":"mcm","clk":"4226514664","pt":1631464418394,"mc":[{"id":"1.187528277","rc":[{"batb":[[0,1.42,16996.59]],"ltp":1.42,"tv":569288.86,"id":2249229}]}]}
{"op":"mcm","clk":"4226515401","pt":1631464423704,"mc":[{"id":"1.187528277","rc":[{"trd":[[1.42,267122.26]],"batb":[[0,1.42,16971.59]],"ltp":1.42,"tv":569338.86,"id":2249229}],"tv":689261.64}]}
{"op":"mcm","clk":"4226516055","pt":1631464428479,"mc":[{"id":"1.187528277","rc":[{"batb":[[1,1.41,38565.36]],"ltp":1.42,"tv":569338.86,"id":2249229}]}]}
{"op":"mcm","clk":"4226517054","pt":1631464434599,"mc":[{"id":"1.187528277","rc":[{"batl":[[0,3.4,4887.51],[1,3.45,1079.71],[2,3.5,2738.41]],"ltp":3.3,"tv":119922.77,"id":19924831},{"batb":[[0,1.42,21754.03]],"ltp":1.42,"tv":569338.86,"id":2249229}]}]}
{"op":"mcm","clk":"4226517366","pt":1631464436411,"mc":[{"id":"1.187528277","rc":[{"trd":[[1.42,267148.26]],"batb":[[0,1.42,21741.03]],"ltp":1.42,"tv":569364.86,"id":2249229}],"tv":689287.64}]}
{"op":"mcm","clk":"4226519144","pt":1631464447829,"mc":[{"id":"1.187528277","rc":[{"batl":[[0,1.43,26717.47]],"ltp":1.42,"tv":569364.86,"id":2249229}]}]}
{"op":"mcm","clk":"4226520108","pt":1631464454132,"mc":[{"id":"1.187528277","rc":[{"batb":[[0,1.42,21791.03]],"ltp":1.42,"tv":569364.86,"id":2249229}]}]}
{"op":"mcm","clk":"4226521411","pt":1631464462546,"mc":[{"id":"1.187528277","rc":[{"trd":[[3.4,29170.09]],"batl":[[0,3.4,4884.96]],"ltp":3.4,"tv":119927.88,"id":19924831}],"tv":689292.74}]}
{"op":"mcm","clk":"4226523121","pt":1631464474341,"mc":[{"id":"1.187528277","rc":[{"batl":[[2,1.45,7966.85]],"ltp":1.42,"tv":569364.86,"id":2249229}]}]}
{"op":"mcm","clk":"4226524162","pt":1631464481069,"mc":[{"id":"1.187528277","rc":[{"batl":[[0,1.43,21612.17]],"ltp":1.42,"tv":569364.86,"id":2249229}]}]}
{"op":"mcm","clk":"4226530649","pt":1631464523872,"mc":[{"id":"1.187528277","rc":[{"trd":[[1.43,172953.69]],"batl":[[0,1.43,21581.07]],"ltp":1.43,"tv":569427.07,"id":2249229}],"tv":689354.95}]}
{"op":"mcm","clk":"4226533971","pt":1631464545823,"mc":[{"id":"1.187528277","rc":[{"batb":[[0,1.42,25975.85]],"ltp":1.43,"tv":569427.07,"id":2249229}]}]}
{"op":"mcm","clk":"4226535340","pt":1631464554713,"mc":[{"id":"1.187528277","rc":[{"batl":[[0,3.35,83.9],[1,3.4,4884.96],[2,3.45,1079.71]],"ltp":3.4,"tv":119927.88,"id":19924831}]}]}
{"op":"mcm","clk":"4226535412","pt":1631464555136,"mc":[{"id":"1.187528277","rc":[{"batl":[[1,3.4,4855.55]],"ltp":3.4,"tv":119927.88,"id":19924831},{"batb":[[0,1.42,26046.27]],"ltp":1.43,"tv":569427.07,"id":2249229}]}]}
{"op":"mcm","clk":"4226538445","pt":1631464575035,"mc":[{"id":"1.187528277","rc":[{"batl":[[0,3.35,183.9]],"ltp":3.4,"tv":119927.88,"id":19924831}]}]}
{"op":"mcm","clk":"4226539018","pt":1631464578763,"mc":[{"id":"1.187528277","rc":[{"batb":[[1,1.41,38461.21]],"ltp":1.43,"tv":569427.07,"id":2249229}]}]}
{"op":"mcm","clk":"4226542516","pt":1631464599669,"mc":[{"id":"1.187528277","rc":[{"batl":[[0,3.35,1252.24]],"ltp":3.4,"tv":119927.88,"id":19924831}]}]}
{"op":"mcm","clk":"4226542553","pt":1631464599879,"mc":[{"id":"1.187528277","rc":[{"batl":[[0,1.43,21455.2]],"ltp":1.43,"tv":569427.07,"id":2249229}]}]}
{"op":"mcm","clk":"4226543189","pt":1631464603863,"mc":[{"id":"1.187528277","rc":[{"trd":[[3.3,37074.6]],"batb":[[0,3.3,7164.22]],"ltp":3.3,"tv":119932.22,"id":19924831}],"tv":689359.29}]}
{"op":"mcm","clk":"4226543600","pt":1631464606709,"mc":[{"id":"1.187528277","rc":[{"trd":[[3.35,45399.83]],"batl":[[0,3.35,1251.97]],"ltp":3.35,"tv":119932.77,"id":19924831}],"tv":689359.84}]}
{"op":"mcm","clk":"4226544382","pt":1631464611592,"mc":[{"id":"1.187528277","rc":[{"batl":[[2,3.45,4154.27]],"ltp":3.35,"tv":119932.77,"id":19924831}]}]}
{"op":"mcm","clk":"4226551422","pt":1631464657451,"mc":[{"id":"1.187528277","rc":[{"batb":[[0,1.42,26093.87]],"ltp":1.43,"tv":569427.07,"id":2249229}]}]}
{"op":"mcm","clk":"4226552220","pt":1631464663052,"mc":[{"id":"1.187528277","rc":[{"trd":[[1.43,173053.69]],"batl":[[0,1.43,21405.19]],"ltp":1.43,"tv":569527.08,"id":2249229}],"tv":689459.85}]}
{"op":"mcm","clk":"4226553396","pt":1631464670861,"mc":[{"id":"1.187528277","rc":[{"batb":[[0,1.42,26046.27]],"ltp":1.43,"tv":569527.08,"id":2249229}]}]}
{"op":"mcm","clk":"4226556385","pt":1631464690397,"mc":[{"id":"1.187528277","rc":[{"trd":[[3.3,37126.98]],"batb":[[0,3.3,7138.03]],"ltp":3.3,"tv":119985.15,"id":19924831}],"tv":689512.23}]}
{"op":"mcm","clk":"4226556567","pt":1631464691689,"mc":[{"id":"1.187528277","rc":[{"trd":[[1.43,173146.69]],"batl":[[0,1.43,21358.7]],"ltp":1.43,"tv":569620.07,"id":2249229}],"tv":689605.23}]}
{"op":"mcm","clk":"4226576021","pt":1631464819179,"mc":[{"id":"1.187528277","rc":[{"trd":[[1.43,173161.69]],"batl":[[0,1.43,21351.2]],"ltp":1.43,"tv":569635.07,"id":2249229}],"tv":689620.23}]}
{"op":"mcm","clk":"4226580749","pt":1631464851343,"mc":[{"id":"1.187528277","rc":[{"trd":[[1.42,267154.26]],"batb":[[0,1.42,26043.27]],"ltp":1.42,"tv":569641.07,"id":2249229}],"tv":689626.23}]}
{"op":"mcm","clk":"4226586700","pt":1631464892972,"mc":[{"id":"1.187528277","rc":[{"batl":[[0,1.43,22641.78]],"ltp":1.42,"tv":569641.07,"id":2249229}]}]}
{"op":"mcm","clk":"4226587615","pt":1631464899139,"mc":[{"id":"1.187528277","rc":[{"trd":[[1.42,267157.68]],"batb":[[0,1.42,26041.56]],"ltp":1.42,"tv":569644.49,"id":2249229}],"tv":689629.65}]}
{"op":"mcm","clk":"4226587993","pt":1631464901643,"mc":[{"id":"1.187528277","rc":[{"batb":[[0,1.42,26181.99]],"ltp":1.42,"tv":569644.49,"id":2249229}]}]}
{"op":"mcm","clk":"4226588329","pt":1631464903984,"mc":[{"id":"1.187528277","rc":[{"trd":[[1.42,267178.95]],"batb":[[0,1.42,26171.35]],"ltp":1.42,"tv":569665.77,"id":2249229}],"tv":689650.92}]}
{"op":"mcm","clk":"4226588614","pt":1631464905970,"mc":[{"id":"1.187528277","rc":[{"trd":[[1.43,173371.79]],"batl":[[0,1.43,22536.73]],"ltp":1.43,"tv":569875.86,"id":2249229}],"tv":689861.02}]}
{"op":"mcm","clk":"4226588828","pt":1631464907372,"mc":[{"id":"1.187528277","rc":[{"trd":[[1.42,267206.51]],"batb":[[0,1.42,26157.57]],"ltp":1.42,"tv":569903.42,"id":2249229}],"tv":689888.58}]}
{"op":"mcm","clk":"4226593860","pt":1631464943680,"mc":[{"id":"1.187528277","rc":[{"trd":[[1.42,267210.51]],"batb":[[0,1.42,26155.57]],"ltp":1.42,"tv":569907.42,"id":2249229}],"tv":689892.58}]}
{"op":"mcm","clk":"4226595229","pt":1631464953621,"mc":[{"id":"1.187528277","rc":[{"batl":[[0,3.35,1296.38]],"ltp":3.3,"tv":119985.15,"id":19924831}]}]}
{"op":"mcm","clk":"4226595949","pt":1631464958929,"mc":[{"id":"1.187528277","rc":[{"trd":[[1.42,267222.13]],"batb":[[0,1.42,26149.76]],"ltp":1.42,"tv":569919.04,"id":2249229}],"tv":689904.2}]}
{"op":"mcm","clk":"4226596108","pt":1631464960247,"mc":[{"id":"1.187528277","rc":[{"trd":[[3.3,37215.8]],"batb":[[0,3.3,7093.62]],"batl":[[0,3.35,1251.97]],"ltp":3.3,"tv":120073.97,"id":19924831}],"tv":689993.02}]}
{"op":"mcm","clk":"4226597473","pt":1631464970524,"mc":[{"id":"1.187528277","rc":[{"trd":[[1.42,267230.67]],"batb":[[0,1.42,26145.49]],"ltp":1.42,"tv":569927.58,"id":2249229}],"tv":690001.56}]}
{"op":"mcm","clk":"4226598744","pt":1631464979909,"mc":[{"id":"1.187528277","rc":[{"trd":[[3.3,37235.8]],"batb":[[0,3.3,7083.62]],"ltp":3.3,"tv":120093.97,"id":19924831}],"tv":690021.56}]}
{"op":"mcm","clk":"4226612534","pt":1631465074245,"mc":[{"id":"1.187528277","rc":[{"trd":[[1.42,267630.67]],"batb":[[0,1.42,25945.49]],"ltp":1.42,"tv":570327.58,"id":2249229}],"tv":690421.56}]}
{"op":"mcm","clk":"4226625935","pt":1631465162030,"mc":[{"id":"1.187528277","rc":[{"batl":[[0,1.43,24132.13]],"ltp":1.42,"tv":570327.58,"id":2249229}]}]}
{"op":"mcm","clk":"4226634533","pt":1631465219786,"mc":[{"id":"1.187528277","rc":[{"trd":[[1.42,267634.67]],"batb":[[0,1.42,25943.49]],"ltp":1.42,"tv":570331.58,"id":2249229}],"tv":690425.56}]}
{"op":"mcm","clk":"4226635780","pt":1631465228184,"mc":[{"id":"1.187528277","rc":[{"trd":[[1.43,173381.5]],"batl":[[0,1.43,24127.27]],"ltp":1.43,"tv":570341.3,"id":2249229}],"tv":690435.28}]}
{"op":"mcm","clk":"4226636041","pt":1631465229788,"mc":[{"id":"1.187528277","rc":[{"trd":[[1.42,267638.67]],"batb":[[0,1.42,25941.49]],"ltp":1.42,"tv":570345.3,"id":2249229}],"tv":690439.28}]}
{"op":"mcm","clk":"4226641447","pt":1631465265883,"mc":[{"id":"1.187528277","rc":[{"trd":[[1.42,268312.67]],"batb":[[0,1.42,25604.49]],"ltp":1.42,"tv":571019.3,"id":2249229}],"tv":691113.28}]}
{"op":"mcm","clk":"4226642276","pt":1631465271726,"mc":[{"id":"1.187528277","rc":[{"trd":[[1.42,268342.67]],"batb":[[0,1.42,25589.49]],"ltp":1.42,"tv":571049.3,"id":2249229}],"tv":691143.28}]}
{"op":"mcm","clk":"4226647084","pt":1631465304467,"mc":[{"id":"1.187528277","rc":[{"trd":[[3.35,45401.48]],"batl":[[0,3.35,1251.14]],"ltp":3.35,"tv":120095.62,"id":19924831}],"tv":691144.92}]}
{"op":"mcm","clk":"4226649590","pt":1631465321495,"mc":[{"id":"1.187528277","rc":[{"trd":[[3.35,45444.86]],"batl":[[0,3.35,1229.45]],"ltp":3.35,"tv":120139.0,"id":19924831}],"tv":691188.3}]}
{"op":"mcm","clk":"4226651720","pt":1631465335696,"mc":[{"id":"1.187528277","rc":[{"trd":[[1.42,268360.27]],"batb":[[0,1.42,25580.69]],"ltp":1.42,"tv":571066.89,"id":2249229}],"tv":691205.9}]}
{"op":"mcm","clk":"4226656358","pt":1631465369655,"mc":[{"id":"1.187528277","rc":[{"trd":[[1.42,268410.27],[1.43,173453.25]],"batb":[[0,1.42,25555.69]],"batl":[[0,1.43,24091.4]],"ltp":1.42,"tv":571188.64,"id":2249229}],"tv":691327.65}]}
{"op":"mcm","clk":"4226662836","pt":1631465415704,"mc":[{"id":"1.187528277","rc":[{"trd":[[1.42,269236.89]],"batb":[[0,1.42,25142.38]],"ltp":1.42,"tv":572015.27,"id":2249229}],"tv":692154.27}]}
{"op":"mcm","clk":"4226662888","pt":1631465416080,"mc":[{"id":"1.187528277","rc":[{"trd":[[1.42,270890.14]],"batb":[[0,1.42,24315.76]],"ltp":1.42,"tv":573668.52,"id":2249229}],"tv":693807.52}]}
{"op":"mcm","clk":"4226663250","pt":1631465418662,"mc":[{"id":"1.187528277","rc":[{"trd":[[1.42,275023.26]],"batb":[[0,1.42,22249.21]],"ltp":1.42,"tv":577801.64,"id":2249229}],"tv":697940.64}]}
{"op":"mcm","clk":"4226664135","pt":1631465425465,"mc":[{"id":"1.187528277","rc":[{"trd":[[1.42,275298.8]],"batb":[[0,1.42,22111.44]],"ltp":1.42,"tv":578077.18,"id":2249229}],"tv":698216.19}]}
{"op":"mcm","clk":"4226666513","pt":1631465444211,"mc":[{"id":"1.187528277","rc":[{"trd":[[1.42,275309.28]],"batb":[[0,1.42,22106.2]],"ltp":1.42,"tv":578087.66,"id":2249229}],"tv":698226.66}]}
{"op":"mcm","clk":"4226669347","pt":1631465466236,"mc":[{"id":"1.187528277","rc":[{"batb":[[0,1.42,22206.2]],"ltp":1.42,"tv":578087.66,"id":2249229}]}]}
{"op":"mcm","clk":"4226671578","pt":1631465480051,"mc":[{"id":"1.187528277","rc":[{"batb":[[0,3.3,7125.41]],"ltp":3.35,"tv":120139.0,"id":19924831},{"batb":[[0,1.42,22434.99]],"ltp":1.42,"tv":578087.66,"id":2249229}]}]}
{"op":"mcm","clk":"4226672541","pt":1631465486652,"mc":[{"id":"1.187528277","rc":[{"batl":[[1,3.4,4845.3]],"ltp":3.35,"tv":120139.0,"id":19924831}]}]}
{"op":"mcm","clk":"4226672908","pt":1631465489066,"mc":[{"id":"1.187528277","rc":[{"trd":[[3.3,37435.81]],"batb":[[0,3.3,7025.4]],"ltp":3.3,"tv":120339.0,"id":19924831}],"tv":698426.66}]}
{"op":"mcm","clk":"4226680694","pt":1631465548114,"mc":[{"id":"1.187528277","rc":[{"trd":[[1.42,275329.28]],"batb":[[0,1.42,22424.99]],"ltp":1.42,"tv":578107.66,"id":2249229}],"tv":698446.66}]}
{"op":"mcm","clk":"4226685997","pt":1631465590856,"mc":[{"id":"1.187528277","rc":[{"trd":[[3.3,37552.8]],"batb":[[0,3.3,6966.91]],"ltp":3.3,"tv":120455.99,"id":19924831}],"tv":698563.65}]}
{"op":"mcm","clk":"4226688318","pt":1631465608256,"mc":[{"id":"1.187528277","rc":[{"batb":[[0,1.42,22451.99],[2,1.4,48154.69]],"ltp":1.42,"tv":578107.66,"id":2249229}]}]}
{"op":"mcm","clk":"4226691681","pt":1631465634121,"mc":[{"id":"1.187528277","rc":[{"trd":[[3.35,45451.74]],"batl":[[0,3.35,1226.01]],"ltp":3.35,"tv":120462.87,"id":19924831}],"tv":698570.53}]}
{"op":"mcm","clk":"4226691817","pt":1631465635331,"mc":[{"id":"1.187528277","rc":[{"trd":[[1.42,275341.28]],"batb":[[0,1.42,22445.99]],"ltp":1.42,"tv":578119.66,"id":2249229}],"tv":698582.53}]}
{"op":"mcm","clk":"4226701840","pt":1631465718330,"mc":[{"id":"1.187528277","rc":[{"trd":[[3.35,45477.56]],"batl":[[0,3.35,1213.1]],"ltp":3.35,"tv":120488.69,"id":19924831}],"tv":698608.35}]}
{"op":"mcm","clk":"4226703330","pt":1631465729951,"mc":[{"id":"1.187528277","rc":[{"trd":[[1.42,275841.28]],"batb":[[0,1.42,22195.99]],"ltp":1.42,"tv":578619.66,"id":2249229}],"tv":699108.35}]}
{"op":"mcm","clk":"4226706768","pt":1631465758991,"mc":[{"id":"1.187528277","rc":[{"trd":[[1.42,275858.36]],"batb":[[0,1.42,22187.45]],"ltp":1.42,"tv":578636.74,"id":2249229}],"tv":699125.43}]}
{"op":"mcm","clk":"4226709290","pt":1631465779739,"mc":[{"id":"1.187528277","rc":[{"trd":[[1.43,173489.13]],"batl":[[0,1.43,24073.46]],"ltp":1.43,"tv":578672.61,"id":2249229}],"tv":699161.31}]}
{"op":"mcm","clk":"4226712309","pt":1631465805363,"mc":[{"id":"1.187528277","rc":[{"trd":[[3.3,37556.8]],"batb":[[0,3.3,6964.91]],"ltp":3.3,"tv":120492.7,"id":19924831}],"tv":699165.31}]}
{"op":"mcm","clk":"4226712881","pt":1631465809972,"mc":[{"id":"1.187528277","rc":[{"batb":[[0,1.42,22318.26]],"ltp":1.43,"tv":578672.61,"id":2249229}]}]}
{"op":"mcm","clk":"4226713591","pt":1631465815397,"mc":[{"id":"1.187528277","rc":[{"trd":[[1.42,275958.36]],"batb":[[0,1.42,22268.26]],"ltp":1.42,"tv":578772.61,"id":2249229}],"tv":699265.31}]}
{"op":"mcm","clk":"4226714092","pt":1631465819798,"mc":[{"id":"1.187528277","rc":[{"batb":[[0,3.3,6984.91]],"ltp":3.3,"tv":120492.7,"id":19924831}]}]}
{"op":"mcm","clk":"4226715391","pt":1631465830014,"mc":[{"id":"1.187528277","rc":[{"batl":[[0,3.35,144.76]],"ltp":3.3,"tv":120492.7,"id":19924831}]}]}
{"op":"mcm","clk":"4226716861","pt":1631465843025,"mc":[{"id":"1.187528277","rc":[{"trd":[[1.42,275962.36]],"batb":[[0,1.42,22266.26]],"ltp":1.42,"tv":578776.61,"id":2249229}],"tv":699269.31}]}
{"op":"mcm","clk":"4226717182","pt":1631465846386,"mc":[{"id":"1.187528277","rc":[{"trd":[[1.42,276494.15]],"batb":[[0,1.42,22000.37]],"ltp":1.42,"tv":579308.4,"id":2249229}],"tv":699801.11}]}
{"op":"mcm","clk":"4226718436","pt":1631465857732,"mc":[{"id":"1.187528277","rc":[{"trd":[[1.42,276594.15]],"batb":[[0,1.42,21950.37]],"ltp":1.42,"tv":579408.4,"id":2249229}],"tv":699901.11}]}
{"op":"mcm","clk":"4226718611","pt":1631465859304,"mc":[{"id":"1.187528277","rc":[{"trd":[[3.35,45497.56]],"batl":[[0,3.35,134.76]],"ltp":3.35,"tv":120512.7,"id":19924831}],"tv":699921.11}]}
{"op":"mcm","clk":"4226720313","pt":1631465874160,"mc":[{"id":"1.187528277","rc":[{"trd":[[1.42,276794.15]],"batb":[[0,1.42,21850.37]],"ltp":1.42,"tv":579608.4,"id":2249229}],"tv":700121.11}]}
{"op":"mcm","clk":"4226721310","pt":1631465882175,"mc":[{"id":"1.187528277","rc":[{"trd":[[1.43,173498.43]],"batl":[[0,1.43,24068.81]],"ltp":1.43,"tv":579617.7,"id":2249229}],"tv":700130.4}]}
{"op":"mcm","clk":"4226722807","pt":1631465894686,"mc":[{"id":"1.187528277","rc":[{"trd":[[1.42,276830.95]],"batb":[[0,1.42,21831.97]],"ltp":1.42,"tv":579654.5,"id":2249229}],"tv":700167.2}]}
{"op":"mcm","clk":"4226722939","pt":1631465895688,"mc":[{"id":"1.187528277","rc":[{"trd":[[3.3,37582.42]],"batb":[[0,3.3,6972.1]],"ltp":3.3,"tv":120538.32,"id":19924831}],"tv":700192.83}]}
{"op":"mcm","clk":"4226723310","pt":1631465898897,"mc":[{"id":"1.187528277","rc":[{"trd":[[1.43,173518.43]],"batl":[[0,1.43,24058.81]],"ltp":1.43,"tv":579674.5,"id":2249229}],"tv":700212.83}]}
{"op":"mcm","clk":"4226723446","pt":1631465900186,"mc":[{"id":"1.187528277","rc":[{"trd":[[1.42,279230.95]],"batb":[[0,1.42,20631.97]],"ltp":1.42,"tv":582074.5,"id":2249229}],"tv":702612.83}]}
{"op":"mcm","clk":"4226724719","pt":1631465911697,"mc":[{"id":"1.187528277","rc":[{"trd":[[3.35,45502.56]],"batl":[[0,3.35,132.26]],"ltp":3.35,"tv":120543.32,"id":19924831},{"trd":[[1.42,279236.95]],"batb":[[0,1.42,20628.97]],"ltp":1.42,"tv":582080.5,"id":2249229}],"tv":702623.83}]}
{"op":"mcm","clk":"4226727325","pt":1631465933841,"mc":[{"id":"1.187528277","rc":[{"trd":[[3.35,45510.87]],"batl":[[0,3.35,128.11]],"ltp":3.35,"tv":120551.63,"id":19924831}],"tv":702632.14}]}
{"op":"mcm","clk":"4226730928","pt":1631465964276,"mc":[{"id":"1.187528277","rc":[{"batb":[[0,3.3,7083.67]],"ltp":3.35,"tv":120551.63,"id":19924831}]}]}
{"op":"mcm","clk":"4226735183","pt":1631465997467,"mc":[{"id":"1.187528277","rc":[{"trd":[[1.43,173683.67]],"batl":[[0,1.43,23976.19]],"ltp":1.43,"tv":582245.74,"id":2249229}],"tv":702797.38}]}
{"op":"mcm","clk":"4226735333","pt":1631465998686,"mc":[{"id":"1.187528277","rc":[{"batb":[[0,1.42,21148.22]],"ltp":1.43,"tv":582245.74,"id":2249229}]}]}
{"op":"mcm","clk":"4226738112","pt":1631466018168,"mc":[{"id":"1.187528277","rc":[{"batl":[[0,3.35,248.11]],"ltp":3.35,"tv":120551.63,"id":19924831}]}]}
{"op":"mcm","clk":"4226744440","pt":1631466063637,"mc":[{"id":"1.187528277","rc":[{"batl":[[1,3.4,4841.05]],"ltp":3.35,"tv":120551.63,"id":19924831}]}]}
{"op":"mcm","clk":"4226744983","pt":1631466067233,"mc":[{"id":"1.187528277","rc":[{"trd":[[1.42,279322.35]],"batb":[[0,1.42,21105.52]],"ltp":1.42,"tv":582331.14,"id":2249229}],"tv":702882.78}]}
{"op":"mcm","clk":"4226750202","pt":1631466101745,"mc":[{"id":"1.187528277","rc":[{"batl":[[0,3.35,537.31]],"ltp":3.35,"tv":120551.63,"id":19924831}]}]}
{"op":"mcm","clk":"4226755693","pt":1631466138610,"mc":[{"id":"1.187528277","rc":[{"batl":[[2,1.45,7976.85]],"ltp":1.42,"tv":582331.14,"id":2249229}]}]}
{"op":"mcm","clk":"4226755851","pt":1631466139507,"mc":[{"id":"1.187528277","rc":[{"batl":[[1,1.44,61176.09]],"ltp":1.42,"tv":582331.14,"id":2249229}]}]}
{"op":"mcm","clk":"4226756525","pt":1631466143810,"mc":[{"id":"1.187528277","rc":[{"batl":[[1,1.44,55708.5]],"ltp":1.42,"tv":582331.14,"id":2249229}]}]}
{"op":"mcm","clk":"4226761940","pt":1631466180050,"mc":[{"id":"1.187528277","rc":[{"trd":[[1.43,175325.36]],"batl":[[0,1.43,23155.35]],"ltp":1.43,"tv":583972.83,"id":2249229}],"tv":704524.47}]}
{"op":"mcm","clk":"4226763972","pt":1631466192782,"mc":[{"id":"1.187528277","rc":[{"trd":[[1.42,279332.35]],"batb":[[0,1.42,21100.52]],"ltp":1.42,"tv":583982.83,"id":2249229}],"tv":704534.47}]}
{"op":"mcm","clk":"4226764587","pt":1631466196684,"mc":[{"id":"1.187528277","rc":[{"trd":[[1.42,279335.65]],"batb":[[0,1.42,21098.87]],"ltp":1.42,"tv":583986.14,"id":2249229}],"tv":704537.77}]}
{"op":"mcm","clk":"4226767089","pt":1631466214797,"mc":[{"id":"1.187528277","rc":[{"trd":[[3.3,37822.42]],"batb":[[0,3.3,6963.67]],"ltp":3.3,"tv":120791.63,"id":19924831}],"tv":704777.77}]}
{"op":"mcm","clk":"4226768643","pt":1631466225698,"mc":[{"id":"1.187528277","rc":[{"trd":[[3.3,37922.42]],"batb":[[0,3.3,6913.67]],"ltp":3.3,"tv":120891.63,"id":19924831}],"tv":704877.78}]}
{"op":"mcm","clk":"4226770194","pt":1631466236592,"mc":[{"id":"1.187528277","rc":[{"batl":[[1,3.4,4849.59]],"ltp":3.3,"tv":120891.63,"id":19924831}]}]}
{"op":"mcm","clk":"4226773224","pt":1631466256647,"mc":[{"id":"1.187528277","rc":[{"batl":[[0,1.43,23190.98]],"ltp":1.42,"tv":583986.14,"id":2249229}]}]}
{"op":"mcm","clk":"4226773695","pt":1631466259858,"mc":[{"id":"1.187528277","rc":[{"batl":[[0,3.35,509.75]],"ltp":3.3,"tv":120891.63,"id":19924831}]}]}
{"op":"mcm","clk":"4226780442","pt":1631466305071,"mc":[{"id":"1.187528277","rc":[{"batb":[[0,1.42,21122.67]],"ltp":1.42,"tv":583986.14,"id":2249229}]}]}
{"op":"mcm","clk":"4226781601","pt":1631466312622,"mc":[{"id":"1.187528277","rc":[{"batb":[[1,3.25,3869.47]],"ltp":3.3,"tv":120891.63,"id":19924831},{"batb":[[0,1.42,21148.99]],"ltp":1.42,"tv":583986.14,"id":2249229}]}]}
{"op":"mcm","clk":"4226781623","pt":1631466312784,"mc":[{"id":"1.187528277","rc":[{"trd":[[1.42,279775.65]],"batb":[[0,1.42,20928.99]],"ltp":1.42,"tv":584426.14,"id":2249229}],"tv":705317.78}]}
{"op":"mcm","clk":"4226782291","pt":1631466317209,"mc":[{"id":"1.187528277","rc":[{"trd":[[1.42,279815.65]],"batb":[[0,1.42,20908.99]],"ltp":1.42,"tv":584466.14,"id":2249229}],"tv":705357.78}]}
{"op":"mcm","clk":"4226790579","pt":1631466368273,"mc":[{"id":"1.187528277","rc":[{"trd":[[3.3,37927.02]],"batb":[[0,3.3,6911.37]],"ltp":3.3,"tv":120896.23,"id":19924831}],"tv":705362.38}]}
{"op":"mcm","clk":"4226796501","pt":1631466406521,"mc":[{"id":"1.187528277","rc":[{"batb":[[0,3.3,7111.37]],"ltp":3.3,"tv":120896.23,"id":19924831}]}]}
{"op":"mcm","clk":"4226806513","pt":1631466470846,"mc":[{"id":"1.187528277","rc":[{"trd":[[3.35,45536.11]],"batl":[[0,3.35,497.13]],"ltp":3.35,"tv":120921.48,"id":19924831}],"tv":705387.62}]}
{"op":"mcm","clk":"4226808485","pt":1631466483759,"mc":[{"id":"1.187528277","rc":[{"trd":[[1.43,176850.72]],"batl":[[0,1.43,22428.3]],"ltp":1.43,"tv":585991.49,"id":2249229}],"tv":706912.98}]}
{"op":"mcm","clk":"4226810862","pt":1631466498144,"mc":[{"id":"1.187528277","rc":[{"trd":[[1.42,280642.28]],"batb":[[0,1.42,20495.68]],"ltp":1.42,"tv":586818.12,"id":2249229}],"tv":707739.6}]}
{"op":"mcm","clk":"4226811343","pt":1631466500718,"mc":[{"id":"1.187528277","rc":[{"trd":[[1.42,281193.36]],"batb":[[0,1.42,20220.14]],"ltp":1.42,"tv":587369.2,"id":2249229}],"tv":708290.68}]}
{"op":"mcm","clk":"4226813263","pt":1631466512219,"mc":[{"id":"1.187528277","rc":[{"trd":[[3.3,37931.03]],"batb":[[0,3.3,7109.37]],"ltp":3.3,"tv":120925.48,"id":19924831}],"tv":708294.69}]}
{"op":"mcm","clk":"4226814039","pt":1631466516331,"mc":[{"id":"1.187528277","rc":[{"trd":[[1.43,176893.72]],"batl":[[0,1.43,22406.8]],"ltp":1.43,"tv":587412.21,"id":2249229}],"tv":708337.69}]}
{"op":"mcm","clk":"4226820088","pt":1631466552699,"mc":[{"id":"1.187528277","rc":[{"trd":[[3.3,38172.89]],"batb":[[0,3.3,6988.44]],"ltp":3.3,"tv":121167.34,"id":19924831}],"tv":708579.56}]}
{"op":"mcm","clk":"4226821364","pt":1631466560083,"mc":[{"id":"1.187528277","rc":[{"batb":[[0,1.42,21964.05]],"ltp":1.43,"tv":587412.21,"id":2249229}]}]}
{"op":"mcm","clk":"4226822441","pt":1631466566577,"mc":[{"id":"1.187528277","rc":[{"batl":[[2,1.45,7925.61]],"ltp":1.43,"tv":587412.21,"id":2249229}]}]}
{"op":"mcm","clk":"4226822675","pt":1631466567808,"mc":[{"id":"1.187528277","rc":[{"trd":[[1.42,281468.9]],"batb":[[0,1.42,21826.28]],"ltp":1.42,"tv":587687.75,"id":2249229}],"tv":708855.1}]}
{"op":"mcm","clk":"4226823599","pt":1631466573104,"mc":[{"id":"1.187528277","rc":[{"batl":[[0,3.35,702.46]],"ltp":3.3,"tv":121167.34,"id":19924831}]}]}
{"op":"mcm","clk":"4226825415","pt":1631466583796,"mc":[{"id":"1.187528277","rc":[{"batb":[[2,1.4,48454.69]],"ltp":1.42,"tv":587687.75,"id":2249229}]}]}
{"op":"mcm","clk":"4226827814","pt":1631466598434,"mc":[{"id":"1.187528277","rc":[{"trd":[[3.3,38192.89]],"batb":[[0,3.3,6978.44]],"ltp":3.3,"tv":121187.34,"id":19924831}],"tv":708875.1}]}
{"op":"mcm","clk":"4226830694","pt":1631466615351,"mc":[{"id":"1.187528277","rc":[{"trd":[[1.42,281488.9]],"batb":[[0,1.42,21816.28]],"ltp":1.42,"tv":587707.75,"id":2249229}],"tv":708895.1}]}
{"op":"mcm","clk":"4226831426","pt":1631466619157,"mc":[{"id":"1.187528277","rc":[{"batb":[[0,3.3,6991.76]],"ltp":3.3,"tv":121187.34,"id":19924831},{"batb":[[0,1.42,21840.68]],"ltp":1.42,"tv":587707.75,"id":2249229}]}]}
{"op":"mcm","clk":"4226834676","pt":1631466639175,"mc":[{"id":"1.187528277","rc":[{"batl":[[1,1.44,55711.95]],"ltp":1.42,"tv":587707.75,"id":2249229}]}]}
{"op":"mcm","clk":"4226835688","pt":1631466645642,"mc":[{"id":"1.187528277","rc":[{"trd":[[1.42,281500.46]],"batb":[[0,1.42,21834.9]],"ltp":1.42,"tv":587719.31,"id":2249229}],"tv":708906.66}]}
{"op":"mcm","clk":"4226839980","pt":1631466673221,"mc":[{"id":"1.187528277","rc":[{"batl":[[0,1.43,22426.8]],"ltp":1.42,"tv":587719.31,"id":2249229}]}]}
{"op":"mcm","clk":"4226842005","pt":1631466684396,"mc":[{"id":"1.187528277","rc":[{"trd":[[1.43,177678.05]],"batl":[[0,1.43,22034.64]],"ltp":1.43,"tv":588503.64,"id":2249229}],"tv":709690.98}]}
{"op":"mcm","clk":"4226842072","pt":1631466684827,"mc":[{"id":"1.187528277","rc":[{"trd":[[1.43,177755.06]],"batl":[[0,1.43,21996.13]],"ltp":1.43,"tv":588580.65,"id":2249229}],"tv":709768.0}]}
{"op":"mcm","clk":"4226842378","pt":1631466686712,"mc":[{"id":"1.187528277","rc":[{"trd":[[1.43,177775.8]],"batl":[[0,1.43,21985.76]],"ltp":1.43,"tv":588601.39,"id":2249229}],"tv":709788.74}]}
{"op":"mcm","clk":"4226842647","pt":1631466688409,"mc":[{"id":"1.187528277","rc":[{"trd":[[3.35,45626.52]],"batl":[[0,3.35,657.26]],"ltp":3.35,"tv":121277.75,"id":19924831}],"tv":709879.14}]}
{"op":"mcm","clk":"4226844346","pt":1631466698401,"mc":[{"id":"1.187528277","rc":[{"batl":[[0,1.43,21785.76]],"ltp":1.43,"tv":588601.39,"id":2249229}]}]}
{"op":"mcm","clk":"4226844786","pt":1631466701028,"mc":[{"id":"1.187528277","rc":[{"batl":[[1,1.44,55611.95]],"ltp":1.43,"tv":588601.39,"id":2249229}]}]}
{"op":"mcm","clk":"4226845072","pt":1631466702812,"mc":[{"id":"1.187528277","rc":[{"batl":[[1,1.44,55511.95]],"ltp":1.43,"tv":588601.39,"id":2249229}]}]}
{"op":"mcm","clk":"4226847183","pt":1631466715930,"mc":[{"id":"1.187528277","rc":[{"batl":[[0,1.43,21789.76]],"ltp":1.43,"tv":588601.39,"id":2249229}]}]}
{"op":"mcm","clk":"4226848413","pt":1631466723327,"mc":[{"id":"1.187528277","rc":[{"trd":[[1.42,281543.84]],"batb":[[0,1.42,21813.21]],"ltp":1.42,"tv":588644.77,"id":2249229}],"tv":709922.52}]}
{"op":"mcm","clk":"4226859332","pt":1631466788612,"mc":[{"id":"1.187528277","rc":[{"trd":[[3.3,38262.92]],"batb":[[0,3.3,6956.75]],"ltp":3.3,"tv":121347.78,"id":19924831}],"tv":709992.55}]}
{"op":"mcm","clk":"4226864091","pt":1631466816652,"mc":[{"id":"1.187528277","rc":[{"batb":[[1,3.25,3861.78]],"ltp":3.3,"tv":121347.78,"id":19924831}]}]}
{"op":"mcm","clk":"4226864597","pt":1631466819454,"mc":[{"id":"1.187528277","rc":[{"batb":[[1,3.25,3856.66]],"ltp":3.3,"tv":121347.78,"id":19924831}]}]}
{"op":"mcm","clk":"4226866545","pt":1631466830688,"mc":[{"id":"1.187528277","rc":[{"trd":[[1.43,177799.67]],"batl":[[0,1.43,21777.82]],"ltp":1.43,"tv":588668.64,"id":2249229}],"tv":710016.43}]}
{"op":"mcm","clk":"4226866710","pt":1631466831702,"mc":[{"id":"1.187528277","rc":[{"batl":[[0,1.43,21797.82]],"ltp":1.43,"tv":588668.64,"id":2249229}]}]}
{"op":"mcm","clk":"4226867711","pt":1631466837696,"mc":[{"id":"1.187528277","rc":[{"batb":[[0,1.42,21833.21]],"ltp":1.43,"tv":588668.64,"id":2249229}]}]}
{"op":"mcm","clk":"4226867729","pt":1631466837766,"mc":[{"id":"1.187528277","rc":[{"batb":[[1,3.25,3864.34]],"ltp":3.3,"tv":121347.78,"id":19924831}]}]}
{"op":"mcm","clk":"4226875330","pt":1631466881844,"mc":[{"id":"1.187528277","rc":[{"trd":[[1.43,177882.76]],"batl":[[0,1.43,21756.28]],"ltp":1.43,"tv":588751.73,"id":2249229}],"tv":710099.52}]}
{"op":"mcm","clk":"4226880369","pt":1631466911258,"mc":[{"id":"1.187528277","rc":[{"trd":[[3.3,38320.92]],"batb":[[0,3.3,6927.75]],"ltp":3.3,"tv":121405.78,"id":19924831}],"tv":710157.52}]}
{"op":"mcm","clk":"4226885599","pt":1631466941397,"mc":[{"id":"1.187528277","rc":[{"trd":[[1.42,283134.47]],"batb":[[0,1.42,21037.9]],"ltp":1.42,"tv":590342.36,"id":2249229}],"tv":711748.14}]}
{"op":"mcm","clk":"4226886313","pt":1631466945520,"mc":[{"id":"1.187528277","rc":[{"batb":[[0,1.42,21068.17]],"ltp":1.42,"tv":590342.36,"id":2249229}]}]}
{"op":"mcm","clk":"4226886710","pt":1631466947809,"mc":[{"id":"1.187528277","rc":[{"trd":[[1.43,179078.42]],"batl":[[0,1.43,21158.45]],"ltp":1.43,"tv":591538.02,"id":2249229}],"tv":712943.8}]}
{"op":"mcm","clk":"4226893435","pt":1631466985657,"mc":[{"id":"1.187528277","rc":[{"trd":[[1.42,283174.47]],"batb":[[0,1.42,21048.17]],"ltp":1.42,"tv":591578.02,"id":2249229}],"tv":712983.8}]}
{"op":"mcm","clk":"4226893901","pt":1631466988292,"mc":[{"id":"1.187528277","rc":[{"batb":[[1,3.25,3837.01],[2,3.2,1793.44]],"batl":[[1,3.4,4857.27]],"ltp":3.3,"tv":121405.78,"id":19924831},{"batb":[[0,1.42,21123.32],[1,1.41,38333.96]],"ltp":1.42,"tv":591578.02,"id":2249229}]}]}
{"op":"mcm","clk":"4226894371","pt":1631466990658,"mc":[{"id":"1.187528277","rc":[{"trd":[[1.43,179100.41]],"batl":[[0,1.43,21147.46]],"ltp":1.43,"tv":591600.0,"id":2249229}],"tv":713005.79}]}
{"op":"mcm","clk":"4226895914","pt":1631466998973,"mc":[{"id":"1.187528277","rc":[{"trd":[[1.42,283179.21]],"batb":[[0,1.42,21120.95]],"ltp":1.42,"tv":591604.75,"id":2249229}],"tv":713010.53}]}
{"op":"mcm","clk":"4226898663","pt":1631467013674,"mc":[{"id":"1.187528277","rc":[{"batb":[[2,3.2,1785.76]],"ltp":3.3,"tv":121405.78,"id":19924831},{"batl":[[2,1.45,7917.07]],"ltp":1.42,"tv":591604.75,"id":2249229}]}]}
{"op":"mcm","clk":"4226898765","pt":1631467014281,"mc":[{"id":"1.187528277","rc":[{"batb":[[0,1.42,21131.2]],"ltp":1.42,"tv":591604.75,"id":2249229}]}]}
{"op":"mcm","clk":"4226899990","pt":1631467020990,"mc":[{"id":"1.187528277","rc":[{"batb":[[2,3.2,1780.63]],"ltp":3.3,"tv":121405.78,"id":19924831},{"batl":[[2,1.45,7908.53]],"ltp":1.42,"tv":591604.75,"id":2249229}]}]}
{"op":"mcm","clk":"4226900206","pt":1631467022021,"mc":[{"id":"1.187528277","rc":[{"trd":[[1.42,283206.77]],"batb":[[0,1.42,21117.42]],"ltp":1.42,"tv":591632.3,"id":2249229}],"tv":713038.08}]}
{"op":"mcm","clk":"4226902366","pt":1631467033601,"mc":[{"id":"1.187528277","rc":[{"batb":[[2,3.2,1775.51]],"ltp":3.3,"tv":121405.78,"id":19924831},{"batl":[[2,1.45,7899.13]],"ltp":1.42,"tv":591632.3,"id":2249229}]}]}
{"op":"mcm","clk":"4226905081","pt":1631467049620,"mc":[{"id":"1.187528277","rc":[{"batb":[[2,3.2,1784.9]],"ltp":3.3,"tv":121405.78,"id":19924831},{"batl":[[2,1.45,7918.78]],"ltp":1.42,"tv":591632.3,"id":2249229}]}]}
{"op":"mcm","clk":"4226918305","pt":1631467081349,"mc":[{"id":"1.187528277","rc":[{"batb":[[0,1.42,21576.8]],"ltp":1.42,"tv":591632.3,"id":2249229}]}]}
{"op":"mcm","clk":"4226919027","pt":1631467085565,"mc":[{"id":"1.187528277","rc":[{"trd":[[1.42,283326.81]],"batb":[[0,1.42,21516.78]],"ltp":1.42,"tv":591752.34,"id":2249229}],"tv":713158.12}]}
{"op":"mcm","clk":"4226921419","pt":1631467099179,"mc":[{"id":"1.187528277","rc":[{"batl":[[0,3.35,683.74],[1,3.4,4815.43]],"ltp":3.3,"tv":121405.78,"id":19924831},{"batl":[[2,1.45,7841.06]],"ltp":1.42,"tv":591752.34,"id":2249229}]}]}
{"op":"mcm","clk":"4226933917","pt":1631467170459,"mc":[{"id":"1.187528277","rc":[{"batb":[[0,1.42,21559.48]],"ltp":1.42,"tv":591752.34,"id":2249229}]}]}
{"op":"mcm","clk":"4226934207","pt":1631467172265,"mc":[{"id":"1.187528277","rc":[{"trd":[[1.42,283370.81]],"batb":[[0,1.42,21537.48]],"ltp":1.42,"tv":591796.34,"id":2249229}],"tv":713202.12}]}
{"op":"mcm","clk":"4226934906","pt":1631467176285,"mc":[{"id":"1.187528277","rc":[{"trd":[[1.43,179111.89]],"batl":[[0,1.43,21141.72]],"ltp":1.43,"tv":591807.83,"id":2249229}],"tv":713213.61}]}
{"op":"mcm","clk":"4226937682","pt":1631467191474,"mc":[{"id":"1.187528277","rc":[{"trd":[[3.3,38329.46]],"batb":[[0,3.3,6923.47]],"ltp":3.3,"tv":121414.32,"id":19924831}],"tv":713222.15}]}
{"op":"mcm","clk":"4226942145","pt":1631467216822,"mc":[{"id":"1.187528277","rc":[{"trd":[[3.35,45654.6]],"batl":[[0,3.35,669.7]],"ltp":3.35,"tv":121442.4,"id":19924831}],"tv":713250.23}]}
{"op":"mcm","clk":"4226943612","pt":1631467224876,"mc":[{"id":"1.187528277","rc":[{"trd":[[3.3,38447.9]],"batb":[[0,3.3,6864.26]],"ltp":3.3,"tv":121560.83,"id":19924831}],"tv":713368.67}]}
{"op":"mcm","clk":"4226957637","pt":1631467310758,"mc":[{"id":"1.187528277","rc":[{"trd":[[1.42,283442.81]],"batb":[[0,1.42,21501.49]],"ltp":1.42,"tv":591879.82,"id":2249229}],"tv":713440.66}]}
{"op":"mcm","clk":"4226959794","pt":1631467324699,"mc":[{"id":"1.187528277","rc":[{"batl":[[0,1.43,21191.72]],"ltp":1.42,"tv":591879.82,"id":2249229}]}]}
{"op":"mcm","clk":"4226960449","pt":1631467328802,"mc":[{"id":"1.187528277","rc":[{"batb":[[0,1.42,21551.49]],"ltp":1.42,"tv":591879.82,"id":2249229}]}]}
{"op":"mcm","clk":"4226966817","pt":1631467369952,"mc":[{"id":"1.187528277","rc":[{"trd":[[3.3,38451.9]],"batb":[[0,3.3,6862.26]],"ltp":3.3,"tv":121564.84,"id":19924831}],"tv":713444.67}]}
{"op":"mcm","clk":"4226972732","pt":1631467407570,"mc":[{"id":"1.187528277","rc":[{"batb":[[0,3.3,6872.26]],"ltp":3.3,"tv":121564.84,"id":19924831}]}]}
{"op":"mcm","clk":"4226974774","pt":1631467421899,"mc":[{"id":"1.187528277","rc":[{"trd":[[1.43,179712.05]],"batl":[[0,1.43,20891.64]],"ltp":1.43,"tv":592479.99,"id":2249229}],"tv":714044.83}]}
{"op":"mcm","clk":"4226977065","pt":1631467435839,"mc":[{"id":"1.187528277","rc":[{"batl":[[0,1.43,20944.82]],"ltp":1.43,"tv":592479.99,"id":2249229}]}]}
{"op":"mcm","clk":"4226978167","pt":1631467442862,"mc":[{"id":"1.187528277","rc":[{"trd":[[1.42,283451.35]],"batb":[[0,1.42,21547.22]],"ltp":1.42,"tv":592488.53,"id":2249229}],"tv":714053.37}]}
{"op":"mcm","clk":"4226978732","pt":1631467446567,"mc":[{"id":"1.187528277","rc":[{"batb":[[0,1.42,21891.75]],"ltp":1.42,"tv":592488.53,"id":2249229}]}]}
{"op":"mcm","clk":"4226979615","pt":1631467452053,"mc":[{"id":"1.187528277","rc":[{"trd":[[1.43,179777.79]],"batl":[[0,1.43,20911.95]],"ltp":1.43,"tv":592554.27,"id":2249229}],"tv":714119.11}]}
{"op":"mcm","clk":"4226980740","pt":1631467459462,"mc":[{"id":"1.187528277","rc":[{"batl":[[0,1.43,20921.95]],"ltp":1.43,"tv":592554.27,"id":2249229}]}]}
{"op":"mcm","clk":"4226986653","pt":1631467496051,"mc":[{"id":"1.187528277","rc":[{"batb":[[0,1.42,24422.3]],"ltp":1.43,"tv":592554.27,"id":2249229}]}]}
{"op":"mcm","clk":"4226988542","pt":1631467506943,"mc":[{"id":"1.187528277","rc":[{"trd":[[1.42,284071.35]],"batb":[[0,1.42,24112.3]],"ltp":1.42,"tv":593174.27,"id":2249229}],"tv":714739.11}]}
{"op":"mcm","clk":"4226991312","pt":1631467524041,"mc":[{"id":"1.187528277","rc":[{"trd":[[1.42,284315.35]],"batb":[[0,1.42,23990.3]],"ltp":1.42,"tv":593418.27,"id":2249229}],"tv":714983.11}]}
{"op":"mcm","clk":"4226991792","pt":1631467527138,"mc":[{"id":"1.187528277","rc":[{"trd":[[1.42,284332.43]],"batb":[[0,1.42,23981.76]],"ltp":1.42,"tv":593435.35,"id":2249229}],"tv":715000.19}]}
{"op":"mcm","clk":"4226994244","pt":1631467542669,"mc":[{"id":"1.187528277","rc":[{"trd":[[3.3,38486.06]],"batb":[[0,3.3,6855.18]],"ltp":3.3,"tv":121598.99,"id":19924831}],"tv":715034.35}]}
{"op":"mcm","clk":"4226994828","pt":1631467546355,"mc":[{"id":"1.187528277","rc":[{"batl":[[0,3.35,643.22],[1,3.4,4856.42]],"ltp":3.3,"tv":121598.99,"id":19924831},{"batl":[[2,1.45,7919.63]],"ltp":1.42,"tv":593435.35,"id":2249229}]}]}
{"op":"mcm","clk":"4226995283","pt":1631467549388,"mc":[{"id":"1.187528277","rc":[{"trd":[[3.35,45736.59]],"batl":[[0,3.35,602.22]],"ltp":3.35,"tv":121680.99,"id":19924831}],"tv":715116.34}]}
{"op":"mcm","clk":"4227000893","pt":1631467584174,"mc":[{"id":"1.187528277","rc":[{"batb":[[0,3.3,7793.18],[1,3.25,4812.01],[2,3.2,2796.9]],"ltp":3.35,"tv":121680.99,"id":19924831},{"trd":[[1.42,288252.43]],"batb":[[0,1.42,22021.75]],"batl":[[1,1.44,57213.95]],"ltp":1.42,"tv":597355.35,"id":2249229}],"tv":719036.34}]}
{"op":"mcm","clk":"4227003283","pt":1631467598958,"mc":[{"id":"1.187528277","rc":[{"trd":[[1.43,179857.79]],"batl":[[0,1.43,20881.95]],"ltp":1.43,"tv":597435.35,"id":2249229}],"tv":719116.34}]}
{"op":"mcm","clk":"4227004435","pt":1631467605979,"mc":[{"id":"1.187528277","rc":[{"trd":[[1.42,288485.23]],"batb":[[0,1.42,21905.35]],"ltp":1.42,"tv":597668.14,"id":2249229}],"tv":719349.14}]}
{"op":"mcm","clk":"4227006831","pt":1631467620651,"mc":[{"id":"1.187528277","rc":[{"trd":[[3.35,45904.4]],"batl":[[0,3.35,518.32]],"ltp":3.35,"tv":121848.79,"id":19924831}],"tv":719516.94}]}
{"op":"mcm","clk":"4227007314","pt":1631467623584,"mc":[{"id":"1.187528277","rc":[{"batl":[[1,3.4,5145.63]],"ltp":3.35,"tv":121848.79,"id":19924831}]}]}
{"op":"mcm","clk":"4227007812","pt":1631467626669,"mc":[{"id":"1.187528277","rc":[{"trd":[[3.3,38554.38]],"batb":[[0,3.3,7759.02]],"ltp":3.3,"tv":121917.12,"id":19924831}],"tv":719585.27}]}
{"op":"mcm","clk":"4227010314","pt":1631467642720,"mc":[{"id":"1.187528277","rc":[{"batl":[[0,3.35,312.99],[1,3.4,5350.96]],"ltp":3.3,"tv":121917.12,"id":19924831}]}]}
{"op":"mcm","clk":"4227014785","pt":1631467671012,"mc":[{"id":"1.187528277","rc":[{"trd":[[3.35,46413.04]],"batl":[[0,3.35,58.67]],"ltp":3.35,"tv":122425.76,"id":19924831}],"tv":720093.91}]}
{"op":"mcm","clk":"4227016632","pt":1631467682656,"mc":[{"id":"1.187528277","rc":[{"trd":[[1.42,288504.01]],"batb":[[0,1.42,21895.96]],"ltp":1.42,"tv":597686.93,"id":2249229}],"tv":720112.69}]}
{"op":"mcm","clk":"4227019076","pt":1631467698245,"mc":[{"id":"1.187528277","rc":[{"trd":[[1.42,288524.01]],"batb":[[0,1.42,21885.96]],"ltp":1.42,"tv":597706.93,"id":2249229}],"tv":720132.69}]}
{"op":"mcm","clk":"4227021854","pt":1631467718879,"mc":[{"id":"1.187528277","rc":[{"batl":[[1,3.4,5728.86]],"ltp":3.35,"tv":122425.76,"id":19924831}]}]}
{"op":"mcm","clk":"4227022856","pt":1631467726155,"mc":[{"id":"1.187528277","rc":[{"batl":[[0,3.35,85.14],[1,3.4,5687.87]],"ltp":3.35,"tv":122425.76,"id":19924831},{"batl":[[2,1.45,7841.06]],"ltp":1.42,"tv":597706.93,"id":2249229}]}]}
{"op":"mcm","clk":"4227024659","pt":1631467739094,"mc":[{"id":"1.187528277","rc":[{"trd":[[1.42,288529.01]],"batb":[[0,1.42,21883.46]],"ltp":1.42,"tv":597711.93,"id":2249229}],"tv":720137.69}]}
{"op":"mcm","clk":"4227025453","pt":1631467744507,"mc":[{"id":"1.187528277","rc":[{"trd":[[1.43,179861.79]],"batl":[[0,1.43,20879.95]],"ltp":1.43,"tv":597715.93,"id":2249229}],"tv":720141.69}]}
{"op":"mcm","clk":"4227028918","pt":1631467768329,"mc":[{"id":"1.187528277","rc":[{"batb":[[0,3.3,8186.04]],"ltp":3.35,"tv":122425.76,"id":19924831}]}]}
{"op":"mcm","clk":"4227030511","pt":1631467779626,"mc":[{"id":"1.187528277","rc":[{"batb":[[1,3.25,5239.04]],"ltp":3.35,"tv":122425.76,"id":19924831},{"trd":[[1.42,288583.31]],"batb":[[0,1.42,21856.31]],"ltp":1.42,"tv":597770.23,"id":2249229}],"tv":720195.99}]}
{"op":"mcm","clk":"4227032113","pt":1631467790476,"mc":[{"id":"1.187528277","rc":[{"batl":[[0,3.35,91.14]],"ltp":3.35,"tv":122425.76,"id":19924831}]}]}
{"op":"mcm","clk":"4227032406","pt":1631467792245,"mc":[{"id":"1.187528277","rc":[{"batb":[[2,3.2,3223.92]],"ltp":3.35,"tv":122425.76,"id":19924831}]}]}
{"op":"mcm","clk":"4227033152","pt":1631467797167,"mc":[{"id":"1.187528277","rc":[{"trd":[[1.42,288589.31]],"batb":[[0,1.42,21853.31]],"ltp":1.42,"tv":597776.23,"id":2249229}],"tv":720201.99}]}
{"op":"mcm","clk":"4227035069","pt":1631467809496,"mc":[{"id":"1.187528277","rc":[{"trd":[[1.42,289193.31]],"batb":[[0,1.42,21551.31]],"ltp":1.42,"tv":598380.23,"id":2249229}],"tv":720805.99}]}
{"op":"mcm","clk":"4227037987","pt":1631467830196,"mc":[{"id":"1.187528277","rc":[{"trd":[[3.3,38578.96]],"batb":[[0,3.3,8173.75]],"ltp":3.3,"tv":122450.34,"id":19924831}],"tv":720830.57}]}
{"op":"mcm","clk":"4227040515","pt":1631467849616,"mc":[{"id":"1.187528277","rc":[{"trd":[[1.42,289213.19]],"batb":[[0,1.42,21541.37]],"ltp":1.42,"tv":598400.11,"id":2249229}],"tv":720850.45}]}
{"op":"mcm","clk":"4227040854","pt":1631467852130,"mc":[{"id":"1.187528277","rc":[{"trd":[[1.42,289273.19]],"batb":[[0,1.42,21511.37]],"ltp":1.42,"tv":598460.11,"id":2249229}],"tv":720910.45}]}
{"op":"mcm","clk":"4227041047","pt":1631467853570,"mc":[{"id":"1.187528277","rc":[{"trd":[[1.42,289572.59]],"batb":[[0,1.42,21361.67]],"ltp":1.42,"tv":598759.51,"id":2249229}],"tv":721209.85}]}
{"op":"mcm","clk":"4227041610","pt":1631467857536,"mc":[{"id":"1.187528277","rc":[{"trd":[[3.35,46501]],"batl":[[0,3.35,47.16]],"ltp":3.35,"tv":122538.3,"id":19924831}],"tv":721297.82}]}
{"op":"mcm","clk":"4227042398","pt":1631467862957,"mc":[{"id":"1.187528277","rc":[{"batb":[[0,1.42,21861.67]],"ltp":1.42,"tv":598759.51,"id":2249229}]}]}
{"op":"mcm","clk":"4227052984","pt":1631467938915,"mc":[{"id":"1.187528277","rc":[{"trd":[[1.42,289972.59]],"batb":[[0,1.42,21661.67]],"ltp":1.42,"tv":599159.51,"id":2249229}],"tv":721697.82}]}
{"op":"mcm","clk":"4227056346","pt":1631467963951,"mc":[{"id":"1.187528277","rc":[{"batl":[[0,1.43,20979.95]],"ltp":1.42,"tv":599159.51,"id":2249229}]}]}
{"op":"mcm","clk":"4227056908","pt":1631467968167,"mc":[{"id":"1.187528277","rc":[{"batl":[[1,1.44,57313.95]],"ltp":1.42,"tv":599159.51,"id":2249229}]}]}
{"op":"mcm","clk":"4227057589","pt":1631467973684,"mc":[{"id":"1.187528277","rc":[{"batl":[[2,1.45,7941.06]],"ltp":1.42,"tv":599159.51,"id":2249229}]}]}
{"op":"mcm","clk":"4227057817","pt":1631467975674,"mc":[{"id":"1.187528277","rc":[{"batl":[[0,3.35,20.68]],"ltp":3.35,"tv":122538.3,"id":19924831}]}]}
{"op":"mcm","clk":"4227057875","pt":1631467976253,"mc":[{"id":"1.187528277","rc":[{"batl":[[1,3.4,5740.82]],"ltp":3.35,"tv":122538.3,"id":19924831}]}]}
{"op":"mcm","clk":"4227058063","pt":1631467977886,"mc":[{"id":"1.187528277","rc":[{"trd":[[3.3,38914.95]],"batb":[[0,3.3,8005.76]],"ltp":3.3,"tv":122874.29,"id":19924831}],"tv":722033.8}]}
{"op":"mcm","clk":"4227061489","pt":1631468003913,"mc":[{"id":"1.187528277","rc":[{"trd":[[1.42,290009.17]],"batb":[[0,1.42,21643.38]],"ltp":1.42,"tv":599196.09,"id":2249229}],"tv":722070.38}]}
{"op":"mcm","clk":"4227061624","pt":1631468004869,"mc":[{"id":"1.187528277","rc":[{"trd":[[1.42,290385.14]],"batb":[[0,1.42,21455.4]],"ltp":1.42,"tv":599572.06,"id":2249229}],"tv":722446.35}]}
{"op":"mcm","clk":"4227062327","pt":1631468010504,"mc":[{"id":"1.187528277","rc":[{"trd":[[3.3,39114.95]],"batb":[[0,3.3,7905.76]],"ltp":3.3,"tv":123074.29,"id":19924831}],"tv":722646.35}]}
{"op":"mcm","clk":"4227064012","pt":1631468024348,"mc":[{"id":"1.187528277","rc":[{"trd":[[1.42,290388.55]],"batb":[[0,1.42,21453.69]],"ltp":1.42,"tv":599575.47,"id":2249229}],"tv":722649.76}]}
{"op":"mcm","clk":"4227064327","pt":1631468026795,"mc":[{"id":"1.187528277","rc":[{"batb":[[1,3.25,5240.91]],"ltp":3.3,"tv":123074.29,"id":19924831}]}]}
{"op":"mcm","clk":"4227064623","pt":1631468029240,"mc":[{"id":"1.187528277","rc":[{"batb":[[0,3.3,7907.63]],"ltp":3.3,"tv":123074.29,"id":19924831}]}]}
{"op":"mcm","clk":"4227067754","pt":1631468054228,"mc":[{"id":"1.187528277","rc":[{"trd":[[1.42,290398.55]],"batb":[[0,1.42,21448.69]],"ltp":1.42,"tv":599585.47,"id":2249229}],"tv":722659.76}]}
{"op":"mcm","clk":"4227071778","pt":1631468083163,"mc":[{"id":"1.187528277","rc":[{"batl":[[0,3.35,70.68]],"ltp":3.3,"tv":123074.29,"id":19924831}]}]}
{"op":"mcm","clk":"4227073108","pt":1631468092877,"mc":[{"id":"1.187528277","rc":[{"trd":[[1.42,290453.66]],"batb":[[0,1.42,21421.14]],"ltp":1.42,"tv":599640.58,"id":2249229}],"tv":722714.87}]}
{"op":"mcm","clk":"4227075032","pt":1631468107186,"mc":[{"id":"1.187528277","rc":[{"trd":[[1.42,290541.76]],"batb":[[0,1.42,21377.09]],"ltp":1.42,"tv":599728.68,"id":2249229}],"tv":722802.97}]}
{"op":"mcm","clk":"4227077070","pt":1631468122012,"mc":[{"id":"1.187528277","rc":[{"batb":[[0,1.42,21547.9]],"ltp":1.42,"tv":599728.68,"id":2249229}]}]}
{"op":"mcm","clk":"4227078576","pt":1631468133707,"mc":[{"id":"1.187528277","rc":[{"trd":[[1.42,291541.76]],"batb":[[0,1.42,21047.9]],"ltp":1.42,"tv":600728.68,"id":2249229}],"tv":723802.97}]}
{"op":"mcm","clk":"4227080135","pt":1631468146548,"mc":[{"id":"1.187528277","rc":[{"batb":[[0,1.42,21925.64]],"ltp":1.42,"tv":600728.68,"id":2249229}]}]}
{"op":"mcm","clk":"4227083792","pt":1631468175681,"mc":[{"id":"1.187528277","rc":[{"batl":[[1,3.4,5362.92]],"ltp":3.3,"tv":123074.29,"id":19924831}]}]}
{"op":"mcm","clk":"4227083805","pt":1631468175786,"mc":[{"id":"1.187528277","rc":[{"batl":[[0,3.35,448.58]],"ltp":3.3,"tv":123074.29,"id":19924831}]}]}
{"op":"mcm","clk":"4227085229","pt":1631468186282,"mc":[{"id":"1.187528277","rc":[{"batl":[[0,3.35,70.68],[1,3.4,5740.82]],"ltp":3.3,"tv":123074.29,"id":19924831}]}]}
{"op":"mcm","clk":"4227087476","pt":1631468203508,"mc":[{"id":"1.187528277","rc":[{"trd":[[1.42,291702.24]],"batb":[[0,1.42,21845.4]],"ltp":1.42,"tv":600889.16,"id":2249229}],"tv":723963.45}]}
{"op":"mcm","clk":"4227090942","pt":1631468229153,"mc":[{"id":"1.187528277","rc":[{"batl":[[1,1.44,57315.95]],"ltp":1.42,"tv":600889.16,"id":2249229}]}]}
{"op":"mcm","clk":"4227092175","pt":1631468237741,"mc":[{"id":"1.187528277","rc":[{"batb":[[0,1.42,21849.67]],"ltp":1.42,"tv":600889.16,"id":2249229}]}]}
{"op":"mcm","clk":"4227092579","pt":1631468240844,"mc":[{"id":"1.187528277","rc":[{"trd":[[1.42,291742.82]],"batb":[[0,1.42,21829.38]],"ltp":1.42,"tv":600929.74,"id":2249229}],"tv":724004.03}]}
{"op":"mcm","clk":"4227098165","pt":1631468278863,"mc":[{"id":"1.187528277","rc":[{"trd":[[3.35,46509.56]],"batl":[[0,3.35,66.4]],"ltp":3.35,"tv":123082.85,"id":19924831}],"tv":724012.59}]}
{"op":"mcm","clk":"4227099928","pt":1631468290788,"mc":[{"id":"1.187528277","rc":[{"trd":[[3.3,39494.95]],"batb":[[0,3.3,7717.63]],"ltp":3.3,"tv":123462.85,"id":19924831}],"tv":724392.59}]}
{"op":"mcm","clk":"4227100732","pt":1631468296092,"mc":[{"id":"1.187528277","rc":[{"trd":[[3.35,46513.9]],"batl":[[0,3.35,64.24]],"ltp":3.35,"tv":123467.19,"id":19924831}],"tv":724396.93}]}
{"op":"mcm","clk":"4227102417","pt":1631468307521,"mc":[{"id":"1.187528277","rc":[{"batl":[[1,3.4,5783.52]],"ltp":3.35,"tv":123467.19,"id":19924831}]}]}
{"op":"mcm","clk":"4227102872","pt":1631468310614,"mc":[{"id":"1.187528277","rc":[{"batb":[[1,3.25,5283.62],[2,3.2,3182.93]],"batl":[[1,3.4,5757.05]],"ltp":3.35,"tv":123467.19,"id":19924831},{"batb":[[0,1.42,21743.98],[1,1.41,38417.65]],"batl":[[2,1.45,8069.16]],"ltp":1.42,"tv":600929.74,"id":2249229}]}]}
{"op":"mcm","clk":"4227103979","pt":1631468318389,"mc":[{"id":"1.187528277","rc":[{"trd":[[1.43,179981.41]],"batl":[[0,1.43,20920.14]],"ltp":1.43,"tv":601049.36,"id":2249229}],"tv":724516.55}]}
{"op":"mcm","clk":"4227104821","pt":1631468324021,"mc":[{"id":"1.187528277","rc":[{"trd":[[1.42,295349.32]],"batb":[[0,1.42,22558.73]],"batl":[[0,1.43,22755.14],[2,1.45,9941.16]],"ltp":1.42,"tv":604655.86,"id":2249229}],"tv":728123.05}]}
{"op":"mcm","clk":"4227105332","pt":1631468327643,"mc":[{"id":"1.187528277","rc":[{"trd":[[3.3,40494.95]],"batb":[[0,3.3,7217.63]],"ltp":3.3,"tv":124467.19,"id":19924831}],"tv":729123.05}]}
{"op":"mcm","clk":"4227106264","pt":1631468333940,"mc":[{"id":"1.187528277","rc":[{"trd":[[3.3,40601.3]],"batb":[[0,3.3,7164.46]],"ltp":3.3,"tv":124573.55,"id":19924831}],"tv":729229.41}]}
{"op":"mcm","clk":"4227106711","pt":1631468336631,"mc":[{"id":"1.187528277","rc":[{"trd":[[1.42,298955.82]],"batb":[[0,1.42,20755.48]],"ltp":1.42,"tv":608262.36,"id":2249229}],"tv":732835.91}]}
{"op":"mcm","clk":"4227107239","pt":1631468340459,"mc":[{"id":"1.187528277","rc":[{"batb":[[0,1.42,22215.24]],"ltp":1.42,"tv":608262.36,"id":2249229}]}]}
{"op":"mcm","clk":"4227107372","pt":1631468341364,"mc":[{"id":"1.187528277","rc":[{"batb":[[0,3.3,7591.48]],"ltp":3.3,"tv":124573.55,"id":19924831}]}]}
{"op":"mcm","clk":"4227107601","pt":1631468342942,"mc":[{"id":"1.187528277","rc":[{"batl":[[0,1.43,26370.21]],"ltp":1.42,"tv":608262.36,"id":2249229}]}]}
{"op":"mcm","clk":"4227108217","pt":1631468347313,"mc":[{"id":"1.187528277","rc":[{"batb":[[1,3.25,5281.74]],"ltp":3.3,"tv":124573.55,"id":19924831}]}]}
{"op":"mcm","clk":"4227108804","pt":1631468351634,"mc":[{"id":"1.187528277","rc":[{"batb":[[0,1.42,22330.08]],"ltp":1.42,"tv":608262.36,"id":2249229}]}]}
{"op":"mcm","clk":"4227110589","pt":1631468365456,"mc":[{"id":"1.187528277","rc":[{"trd":[[1.42,299000.76]],"batb":[[0,1.42,22307.61]],"ltp":1.42,"tv":608307.3,"id":2249229}],"tv":732880.85}]}
{"op":"mcm","clk":"4227111076","pt":1631468369268,"mc":[{"id":"1.187528277","rc":[{"trd":[[3.35,46601.87]],"batl":[[0,3.35,20.25]],"ltp":3.35,"tv":124661.51,"id":19924831}],"tv":732968.82}]}
{"op":"mcm","clk":"4227111345","pt":1631468371264,"mc":[{"id":"1.187528277","rc":[{"trd":[[1.42,299053.94]],"batb":[[0,1.42,22281.03]],"ltp":1.42,"tv":608360.48,"id":2249229}],"tv":733021.99}]}
{"op":"mcm","clk":"4227112199","pt":1631468377578,"mc":[{"id":"1.187528277","rc":[{"trd":[[1.42,299111.52]],"batb":[[0,1.42,22252.24]],"ltp":1.42,"tv":608418.06,"id":2249229}],"tv":733079.57}]}
{"op":"mcm","clk":"4227112972","pt":1631468383583,"mc":[{"id":"1.187528277","rc":[{"trd":[[1.42,299115.85]],"batb":[[0,1.42,22250.07]],"ltp":1.42,"tv":608422.39,"id":2249229}],"tv":733083.91}]}
{"op":"mcm","clk":"4227113751","pt":1631468389700,"mc":[{"id":"1.187528277","rc":[{"trd":[[3.35,46642.37]],"batb":[[0,3.35,64.75],[1,3.3,7561.18],[2,3.25,5281.74]],"batl":[[0,3.4,5786.46],[1,3.45,4154.27],[2,3.5,2738.41]],"ltp":3.35,"tv":124702.01,"id":19924831},{"batb":[[0,1.42,19561.65]],"batl":[[0,1.43,26440.14]],"ltp":1.42,"tv":608422.39,"id":2249229}],"tv":733124.41}]}
{"op":"mcm","clk":"4227113863","pt":1631468390436,"mc":[{"id":"1.187528277","rc":[{"batb":[[1,3.3,7643.56]],"ltp":3.35,"tv":124702.01,"id":19924831}]}]}
{"op":"mcm","clk":"4227114153","pt":1631468392617,"mc":[{"id":"1.187528277","rc":[{"batb":[[1,3.3,7820.9]],"ltp":3.35,"tv":124702.01,"id":19924831}]}]}
{"op":"mcm","clk":"4227114521","pt":1631468395494,"mc":[{"id":"1.187528277","rc":[{"batb":[[2,3.25,5159.53]],"ltp":3.35,"tv":124702.01,"id":19924831}]}]}
{"op":"mcm","clk":"4227116543","pt":1631468411542,"mc":[{"id":"1.187528277","rc":[{"batb":[[2,3.25,5150.13]],"ltp":3.35,"tv":124702.01,"id":19924831},{"batb":[[1,1.41,38469.75]],"ltp":1.42,"tv":608422.39,"id":2249229}]}]}
{"op":"mcm","clk":"4227116906","pt":1631468414350,"mc":[{"id":"1.187528277","rc":[{"trd":[[1.42,299135.85]],"batb":[[0,1.42,19551.65]],"ltp":1.42,"tv":608442.39,"id":2249229}],"tv":733144.41}]}
{"op":"mcm","clk":"4227117237","pt":1631468416854,"mc":[{"id":"1.187528277","rc":[{"trd":[[3.4,29192.56]],"batl":[[0,3.4,5775.22]],"ltp":3.4,"tv":124724.48,"id":19924831}],"tv":733166.88}]}
{"op":"mcm","clk":"4227121484","pt":1631468449066,"mc":[{"id":"1.187528277","rc":[{"trd":[[3.35,46662.37]],"batb":[[0,3.35,54.75]],"ltp":3.35,"tv":124744.48,"id":19924831}],"tv":733186.88}]}
{"op":"mcm","clk":"4227121641","pt":1631468450087,"mc":[{"id":"1.187528277","rc":[{"trd":[[1.42,299231.85]],"batb":[[0,1.42,19503.65]],"ltp":1.42,"tv":608538.39,"id":2249229}],"tv":733282.88}]}
{"op":"mcm","clk":"4227124964","pt":1631468474521,"mc":[{"id":"1.187528277","rc":[{"batb":[[0,3.35,64.25]],"ltp":3.35,"tv":124744.48,"id":19924831}]}]}
{"op":"mcm","clk":"4227125624","pt":1631468479216,"mc":[{"id":"1.187528277","rc":[{"trd":[[3.35,46771.69]],"batb":[[0,3.35,9.59]],"ltp":3.35,"tv":124853.8,"id":19924831}],"tv":733392.2}]}
{"op":"mcm","clk":"4227127167","pt":1631468489331,"mc":[{"id":"1.187528277","rc":[{"trd":[[1.43,180835.46]],"batl":[[0,1.43,26013.11]],"ltp":1.43,"tv":609392.44,"id":2249229}],"tv":734246.25}]}
{"op":"mcm","clk":"4227128135","pt":1631468496061,"mc":[{"id":"1.187528277","rc":[{"trd":[[1.43,181689.5]],"batl":[[0,1.43,25586.09]],"ltp":1.43,"tv":610246.48,"id":2249229}],"tv":735100.29}]}
{"op":"mcm","clk":"4227129177","pt":1631468503449,"mc":[{"id":"1.187528277","rc":[{"trd":[[3.35,46790.47]],"batb":[[0,3.3,7851.4],[1,3.25,5150.13],[2,3.2,3182.93]],"ltp":3.35,"tv":124872.59,"id":19924831},{"batl":[[0,1.43,25516.16]],"ltp":1.43,"tv":610246.48,"id":2249229}],"tv":735119.07}]}
{"op":"mcm","clk":"4227130133","pt":1631468510550,"mc":[{"id":"1.187528277","rc":[{"trd":[[3.35,46790.87]],"batb":[[0,3.3,7851.2]],"batl":[[0,3.35,9.2],[1,3.4,5775.22],[2,3.45,4154.27]],"ltp":3.35,"tv":124872.98,"id":19924831},{"batb":[[0,1.42,22121.65]],"ltp":1.43,"tv":610246.48,"id":2249229}],"tv":735119.47}]}
{"op":"mcm","clk":"4227130182","pt":1631468510873,"mc":[{"id":"1.187528277","rc":[{"batl":[[1,3.4,5745.81]],"ltp":3.35,"tv":124872.98,"id":19924831},{"batb":[[0,1.42,22192.07]],"ltp":1.43,"tv":610246.48,"id":2249229}]}]}
{"op":"mcm","clk":"4227130670","pt":1631468514345,"mc":[{"id":"1.187528277","rc":[{"trd":[[1.42,300012.64]],"batb":[[0,1.42,21801.68]],"ltp":1.42,"tv":611027.26,"id":2249229}],"tv":735900.25}]}
{"op":"mcm","clk":"4227130733","pt":1631468514764,"mc":[{"id":"1.187528277","rc":[{"trd":[[1.43,182031.12]],"batl":[[0,1.43,25345.35]],"ltp":1.43,"tv":611368.88,"id":2249229}],"tv":736241.87}]}
{"op":"mcm","clk":"4227132821","pt":1631468529967,"mc":[{"id":"1.187528277","rc":[{"batb":[[0,1.42,22835.28]],"ltp":1.43,"tv":611368.88,"id":2249229}]}]}
{"op":"mcm","clk":"4227134835","pt":1631468544386,"mc":[{"id":"1.187528277","rc":[{"trd":[[1.43,182032.65]],"batl":[[0,1.43,25344.59]],"ltp":1.43,"tv":611370.41,"id":2249229}],"tv":736243.4}]}
{"op":"mcm","clk":"4227135572","pt":1631468549689,"mc":[{"id":"1.187528277","rc":[{"trd":[[1.43,182039.15]],"batl":[[0,1.43,25341.34]],"ltp":1.43,"tv":611376.91,"id":2249229}],"tv":736249.9}]}
{"op":"mcm","clk":"4227142640","pt":1631468603259,"mc":[{"id":"1.187528277","rc":[{"batl":[[0,1.43,29611.56]],"ltp":1.43,"tv":611376.91,"id":2249229}]}]}
{"op":"mcm","clk":"4227142778","pt":1631468604256,"mc":[{"id":"1.187528277","rc":[{"batl":[[0,3.35,414.11]],"ltp":3.35,"tv":124872.98,"id":19924831}]}]}
{"op":"mcm","clk":"4227143754","pt":1631468611265,"mc":[{"id":"1.187528277","rc":[{"trd":[[1.42,300078.64]],"batb":[[0,1.42,22802.28]],"ltp":1.42,"tv":611442.91,"id":2249229}],"tv":736315.9}]}
{"op":"mcm","clk":"4227143890","pt":1631468612168,"mc":[{"id":"1.187528277","rc":[{"batl":[[1,3.4,5743.81]],"ltp":3.35,"tv":124872.98,"id":19924831}]}]}
{"op":"mcm","clk":"4227145764","pt":1631468626560,"mc":[{"id":"1.187528277","rc":[{"batl":[[0,3.35,9.2]],"ltp":3.35,"tv":124872.98,"id":19924831}]}]}
{"op":"mcm","clk":"4227150257","pt":1631468659692,"mc":[{"id":"1.187528277","rc":[{"trd":[[1.42,303494.8]],"batb":[[0,1.42,21094.2]],"ltp":1.42,"tv":614859.08,"id":2249229}],"tv":739732.07}]}
{"op":"mcm","clk":"4227150364","pt":1631468660537,"mc":[{"id":"1.187528277","rc":[{"trd":[[1.42,304802.81]],"batb":[[0,1.42,20440.2]],"ltp":1.42,"tv":616167.08,"id":2249229}],"tv":741040.07}]}
{"op":"mcm","clk":"4227151166","pt":1631468666711,"mc":[{"id":"1.187528277","rc":[{"trd":[[3.35,46809.26]],"batb":[[0,3.35,218.78],[1,3.3,7820.9],[2,3.25,5150.13]],"batl":[[0,3.4,5773.22],[1,3.45,4154.27],[2,3.5,2738.41]],"ltp":3.35,"tv":124891.38,"id":19924831},{"batb":[[0,1.42,18120.19]],"batl":[[0,1.43,29681.49]],"ltp":1.42,"tv":616167.08,"id":2249229}],"tv":741058.47}]}
{"op":"mcm","clk":"4227151210","pt":1631468667027,"mc":[{"id":"1.187528277","rc":[{"batb":[[1,3.3,7636.4]],"ltp":3.35,"tv":124891.38,"id":19924831}]}]}
{"op":"mcm","clk":"4227151390","pt":1631468668303,"mc":[{"id":"1.187528277","rc":[{"batb":[[0,3.35,258.72]],"ltp":3.35,"tv":124891.38,"id":19924831}]}]}
{"op":"mcm","clk":"4227151730","pt":1631468670620,"mc":[{"id":"1.187528277","rc":[{"batb":[[1,3.3,7527.15]],"ltp":3.35,"tv":124891.38,"id":19924831},{"batb":[[0,1.42,15589.65]],"ltp":1.42,"tv":616167.08,"id":2249229}]}]}
{"op":"mcm","clk":"4227152507","pt":1631468676631,"mc":[{"id":"1.187528277","rc":[{"trd":[[3.35,47009.27]],"batb":[[0,3.35,158.72]],"ltp":3.35,"tv":125091.39,"id":19924831}],"tv":741258.47}]}
{"op":"mcm","clk":"4227152580","pt":1631468677154,"mc":[{"id":"1.187528277","rc":[{"batb":[[0,3.35,134.02]],"ltp":3.35,"tv":125091.39,"id":19924831}]}]}
{"op":"mcm","clk":"4227153514","pt":1631468684741,"mc":[{"id":"1.187528277","rc":[{"trd":[[1.42,304803.82]],"batb":[[0,1.42,15589.14]],"ltp":1.42,"tv":616168.1,"id":2249229}],"tv":741259.49}]}
{"op":"mcm","clk":"4227154020","pt":1631468688713,"mc":[{"id":"1.187528277","rc":[{"batb":[[0,1.42,15610.29]],"ltp":1.42,"tv":616168.1,"id":2249229}]}]}
{"op":"mcm","clk":"4227154727","pt":1631468694661,"mc":[{"id":"1.187528277","rc":[{"batb":[[0,1.42,17318.38]],"ltp":1.42,"tv":616168.1,"id":2249229}]}]}
{"op":"mcm","clk":"4227154857","pt":1631468695616,"mc":[{"id":"1.187528277","rc":[{"batb":[[0,3.35,110.79],[1,3.3,9850.92]],"ltp":3.35,"tv":125091.39,"id":19924831}]}]}
{"op":"mcm","clk":"4227156759","pt":1631468710748,"mc":[{"id":"1.187528277","rc":[{"trd":[[1.43,182122.24]],"batl":[[0,1.43,29639.94]],"ltp":1.43,"tv":616251.19,"id":2249229}],"tv":741342.58}]}
{"op":"mcm","clk":"4227157048","pt":1631468713127,"mc":[{"id":"1.187528277","rc":[{"trd":[[1.42,304833.82]],"batb":[[0,1.42,17303.37]],"ltp":1.42,"tv":616281.19,"id":2249229}],"tv":741372.58}]}
{"op":"mcm","clk":"4227157672","pt":1631468718565,"mc":[{"id":"1.187528277","rc":[{"batl":[[0,1.43,29643.56]],"ltp":1.42,"tv":616281.19,"id":2249229}]}]}
{"op":"mcm","clk":"4227160988","pt":1631468745679,"mc":[{"id":"1.187528277","rc":[{"batb":[[0,3.35,91.9]],"ltp":3.35,"tv":125091.39,"id":19924831}]}]}
{"op":"mcm","clk":"4227161455","pt":1631468749701,"mc":[{"id":"1.187528277","rc":[{"trd":[[3.4,29234.77]],"batl":[[0,3.4,5752.11]],"ltp":3.4,"tv":125133.6,"id":19924831}],"tv":741414.8}]}
{"op":"mcm","clk":"4227161564","pt":1631468750600,"mc":[{"id":"1.187528277","rc":[{"trd":[[1.43,183122.24]],"batl":[[0,1.43,29143.56]],"ltp":1.43,"tv":617281.19,"id":2249229}],"tv":742414.8}]}
{"op":"mcm","clk":"4227162094","pt":1631468755133,"mc":[{"id":"1.187528277","rc":[{"trd":[[3.35,47030.07]],"batb":[[0,3.35,81.51]],"ltp":3.35,"tv":125154.4,"id":19924831}],"tv":742435.59}]}
{"op":"mcm","clk":"4227164882","pt":1631468776715,"mc":[{"id":"1.187528277","rc":[{"trd":[[3.35,47035.37]],"batb":[[0,3.35,78.85]],"ltp":3.35,"tv":125159.7,"id":19924831}],"tv":742440.9}]}
{"op":"mcm","clk":"4227165834","pt":1631468784141,"mc":[{"id":"1.187528277","rc":[{"batb":[[0,1.42,17877.6]],"ltp":1.43,"tv":617281.19,"id":2249229}]}]}
{"op":"mcm","clk":"4227166770","pt":1631468791637,"mc":[{"id":"1.187528277","rc":[{"trd":[[3.35,47069.53]],"batb":[[0,3.3,9881.22],[1,3.25,5150.13],[2,3.2,3182.93]],"batl":[[0,3.35,139.33],[1,3.4,5752.11],[2,3.45,4154.27]],"ltp":3.35,"tv":125193.86,"id":19924831},{"batl":[[0,1.43,29073.63]],"ltp":1.43,"tv":617281.19,"id":2249229}],"tv":742475.05}]}
{"op":"mcm","clk":"4227166808","pt":1631468792047,"mc":[{"id":"1.187528277","rc":[{"batl":[[1,3.4,5722.7]],"ltp":3.35,"tv":125193.86,"id":19924831},{"batb":[[0,1.42,20566.02]],"ltp":1.43,"tv":617281.19,"id":2249229}]}]}
{"op":"mcm","clk":"4227167754","pt":1631468799650,"mc":[{"id":"1.187528277","rc":[{"trd":[[1.42,304933.83]],"batb":[[0,1.42,20516.01]],"ltp":1.42,"tv":617381.19,"id":2249229}],"tv":742575.06}]}
{"op":"mcm","clk":"4227169770","pt":1631468816271,"mc":[{"id":"1.187528277","rc":[{"trd":[[3.3,40641.2]],"batb":[[0,3.3,9861.27]],"ltp":3.3,"tv":125233.76,"id":19924831}],"tv":742614.96}]}
{"op":"mcm","clk":"4227173907","pt":1631468851715,"mc":[{"id":"1.187528277","rc":[{"trd":[[1.43,194886.95]],"batl":[[0,1.43,23191.28]],"ltp":1.43,"tv":629145.9,"id":2249229}],"tv":754379.66}]}
{"op":"mcm","clk":"4227174120","pt":1631468853543,"mc":[{"id":"1.187528277","rc":[{"trd":[[1.43,194946.95]],"batl":[[0,1.43,23161.28]],"ltp":1.43,"tv":629205.9,"id":2249229}],"tv":754439.66}]}
{"op":"mcm","clk":"4227174954","pt":1631468860551,"mc":[{"id":"1.187528277","rc":[{"trd":[[1.43,194950.95]],"batl":[[0,1.43,23159.28]],"ltp":1.43,"tv":629209.9,"id":2249229}],"tv":754443.66}]}
{"op":"mcm","clk":"4227176439","pt":1631468873058,"mc":[{"id":"1.187528277","rc":[{"batb":[[0,1.42,23731.67]],"ltp":1.43,"tv":629209.9,"id":2249229}]}]}
{"op":"mcm","clk":"4227177188","pt":1631468879127,"mc":[{"id":"1.187528277","rc":[{"trd":[[1.42,306647.04]],"batb":[[0,1.42,22875.07]],"ltp":1.42,"tv":630923.11,"id":2249229}],"tv":756156.87}]}
{"op":"mcm","clk":"4227177831","pt":1631468884786,"mc":[{"id":"1.187528277","rc":[{"batb":[[0,1.42,25767.12]],"ltp":1.42,"tv":630923.11,"id":2249229}]}]}
{"op":"mcm","clk":"4227180524","pt":1631468909185,"mc":[{"id":"1.187528277","rc":[{"trd":[[1.43,195050.95]],"batl":[[0,1.43,23109.28]],"ltp":1.43,"tv":631023.11,"id":2249229}],"tv":756256.87}]}
{"op":"mcm","clk":"4227182131","pt":1631468923477,"mc":[{"id":"1.187528277","rc":[{"batl":[[1,1.44,60316.95]],"ltp":1.43,"tv":631023.11,"id":2249229}]}]}
{"op":"mcm","clk":"4227184354","pt":1631468944521,"mc":[{"id":"1.187528277","rc":[{"trd":[[1.42,306847.04]],"batb":[[0,1.42,25667.12]],"ltp":1.42,"tv":631223.11,"id":2249229}],"tv":756456.87}]}
{"op":"mcm","clk":"4227187149","pt":1631468970130,"mc":[{"id":"1.187528277","rc":[{"trd":[[1.42,306857.04]],"batb":[[0,1.42,25662.12]],"ltp":1.42,"tv":631233.12,"id":2249229}],"tv":756466.88}]}
{"op":"mcm","clk":"4227188309","pt":1631468980561,"mc":[{"id":"1.187528277","rc":[{"trd":[[1.42,308047.04]],"batb":[[0,1.42,25067.12]],"ltp":1.42,"tv":632423.11,"id":2249229}],"tv":757656.87}]}
{"op":"mcm","clk":"4227191290","pt":1631469006564,"mc":[{"id":"1.187528277","rc":[{"trd":[[3.3,40690.9]],"batb":[[0,3.3,9836.42]],"ltp":3.3,"tv":125283.46,"id":19924831}],"tv":757706.57}]}
{"op":"mcm","clk":"4227194530","pt":1631469035518,"mc":[{"id":"1.187528277","rc":[{"trd":[[3.3,40710.9]],"batb":[[0,3.3,9826.42]],"ltp":3.3,"tv":125303.46,"id":19924831}],"tv":757726.57}]}
{"op":"mcm","clk":"4227195001","pt":1631469040250,"mc":[{"id":"1.187528277","rc":[{"trd":[[3.3,41055.97]],"batb":[[0,3.3,9653.89]],"ltp":3.3,"tv":125648.52,"id":19924831}],"tv":758071.64}]}
{"op":"mcm","clk":"4227195935","pt":1631469048638,"mc":[{"id":"1.187528277","rc":[{"trd":[[3.3,41065.97]],"batb":[[0,3.3,9648.89]],"ltp":3.3,"tv":125658.52,"id":19924831}],"tv":758081.64}]}
{"op":"mcm","clk":"4227199706","pt":1631469084273,"mc":[{"id":"1.187528277","rc":[{"trd":[[1.43,195068.03]],"batl":[[0,1.43,23100.74]],"ltp":1.43,"tv":632440.19,"id":2249229}],"tv":758098.72}]}
{"op":"mcm","clk":"4227200490","pt":1631469091904,"mc":[{"id":"1.187528277","rc":[{"batl":[[0,1.43,24296.4]],"ltp":1.43,"tv":632440.19,"id":2249229}]}]}
{"op":"mcm","clk":"4227204088","pt":1631469125664,"mc":[{"id":"1.187528277","rc":[{"batl":[[0,1.43,24518.4]],"ltp":1.43,"tv":632440.19,"id":2249229}]}]}
{"op":"mcm","clk":"4227205273","pt":1631469136868,"mc":[{"id":"1.187528277","rc":[{"trd":[[1.42,308067.04]],"batb":[[0,1.42,25057.12]],"ltp":1.42,"tv":632460.19,"id":2249229}],"tv":758118.72}]}
{"op":"mcm","clk":"4227205482","pt":1631469139267,"mc":[{"id":"1.187528277","rc":[{"trd":[[3.3,41105.97]],"batb":[[0,3.3,9628.89]],"ltp":3.3,"tv":125698.52,"id":19924831}],"tv":758158.72}]}
{"op":"mcm","clk":"4227205755","pt":1631469142061,"mc":[{"id":"1.187528277","rc":[{"batl":[[0,3.35,566.35]],"ltp":3.3,"tv":125698.52,"id":19924831}]}]}
{"op":"mcm","clk":"4227205944","pt":1631469143341,"mc":[{"id":"1.187528277","rc":[{"batb":[[0,1.42,27609.77]],"ltp":1.42,"tv":632460.19,"id":2249229}]}]}
{"op":"mcm","clk":"4227208076","pt":1631469163675,"mc":[{"id":"1.187528277","rc":[{"batb":[[1,3.25,5116.82]],"ltp":3.3,"tv":125698.52,"id":19924831},{"batb":[[1,1.41,38333.96]],"ltp":1.42,"tv":632460.19,"id":2249229}]}]}
{"op":"mcm","clk":"4227208124","pt":1631469164187,"mc":[{"id":"1.187528277","rc":[{"batb":[[2,3.2,3226.49]],"batl":[[1,3.4,5738.08]],"ltp":3.3,"tv":125698.52,"id":19924831},{"batb":[[0,1.42,27696.88]],"batl":[[2,1.45,9889.07]],"ltp":1.42,"tv":632460.19,"id":2249229}]}]}
{"op":"mcm","clk":"4227208442","pt":1631469167269,"mc":[{"id":"1.187528277","rc":[{"trd":[[3.3,41165.97]],"batb":[[0,3.3,9598.89]],"ltp":3.3,"tv":125758.52,"id":19924831}],"tv":758218.72}]}
{"op":"mcm","clk":"4227208743","pt":1631469170287,"mc":[{"id":"1.187528277","rc":[{"trd":[[3.35,47920.39]],"batb":[[0,3.3,9747.33]],"batl":[[0,3.35,140.93]],"ltp":3.35,"tv":126609.38,"id":19924831}],"tv":759069.58}]}
{"op":"mcm","clk":"4227209365","pt":1631469176212,"mc":[{"id":"1.187528277","rc":[{"batb":[[0,1.42,29142.91]],"ltp":1.42,"tv":632460.19,"id":2249229}]}]}
{"op":"mcm","clk":"4227209979","pt":1631469182604,"mc":[{"id":"1.187528277","rc":[{"batl":[[0,1.43,24618.4]],"ltp":1.42,"tv":632460.19,"id":2249229}]}]}
{"op":"mcm","clk":"4227210245","pt":1631469185629,"mc":[{"id":"1.187528277","rc":[{"trd":[[1.42,309775.12]],"batb":[[0,1.42,28288.86]],"batl":[[0,1.43,24718.4]],"ltp":1.42,"tv":634168.28,"id":2249229}],"tv":760777.67}]}
{"op":"mcm","clk":"4227210605","pt":1631469189304,"mc":[{"id":"1.187528277","rc":[{"trd":[[1.43,195161.98]],"batl":[[0,1.43,24671.42]],"ltp":1.43,"tv":634262.23,"id":2249229}],"tv":760871.62}]}
{"op":"mcm","clk":"4227212389","pt":1631469209246,"mc":[{"id":"1.187528277","rc":[{"trd":[[1.43,195164.06]],"batl":[[0,1.43,24670.38]],"ltp":1.43,"tv":634264.31,"id":2249229}],"tv":760873.7}]}
{"op":"mcm","clk":"4227212878","pt":1631469215068,"mc":[{"id":"1.187528277","rc":[{"trd":[[3.3,41179.63]],"batb":[[0,3.3,9740.5]],"ltp":3.3,"tv":126623.05,"id":19924831}],"tv":760887.36}]}
{"op":"mcm","clk":"4227212992","pt":1631469216432,"mc":[{"id":"1.187528277","rc":[{"trd":[[1.43,195164.81]],"batl":[[0,1.43,24670.01]],"ltp":1.43,"tv":634265.06,"id":2249229}],"tv":760888.12}]}
{"op":"mcm","clk":"4227215326","pt":1631469241891,"mc":[{"id":"1.187528277","rc":[{"trd":[[1.43,195168.23]],"batl":[[0,1.43,24668.3]],"ltp":1.43,"tv":634268.48,"id":2249229}],"tv":760891.53}]}
{"op":"mcm","clk":"4227215499","pt":1631469243791,"mc":[{"id":"1.187528277","rc":[{"trd":[[1.42,309818.55]],"batb":[[0,1.42,28267.15]],"ltp":1.42,"tv":634311.9,"id":2249229}],"tv":760934.95}]}
{"op":"mcm","clk":"4227216340","pt":1631469251708,"mc":[{"id":"1.187528277","rc":[{"trd":[[1.42,310627.77]],"batb":[[0,1.42,27862.54]],"ltp":1.42,"tv":635121.12,"id":2249229}],"tv":761744.18}]}
{"op":"mcm","clk":"4227217704","pt":1631469265103,"mc":[{"id":"1.187528277","rc":[{"trd":[[3.3,41464.01]],"batb":[[0,3.3,9598.31]],"ltp":3.3,"tv":126907.43,"id":19924831}],"tv":762028.56}]}
{"op":"mcm","clk":"4227218077","pt":1631469269311,"mc":[{"id":"1.187528277","rc":[{"trd":[[3.35,48138.19]],"batl":[[0,3.35,32.04]],"ltp":3.35,"tv":127125.23,"id":19924831}],"tv":762246.36}]}
{"op":"mcm","clk":"4227218989","pt":1631469278709,"mc":[{"id":"1.187528277","rc":[{"trd":[[1.43,195171.65]],"batl":[[0,1.43,24666.59]],"ltp":1.43,"tv":635124.54,"id":2249229}],"tv":762249.77}]}
{"op":"mcm","clk":"4227220082","pt":1631469290141,"mc":[{"id":"1.187528277","rc":[{"trd":[[3.3,41484.01]],"batb":[[0,3.3,9588.31]],"ltp":3.3,"tv":127145.23,"id":19924831}],"tv":762269.77}]}
{"op":"mcm","clk":"4227221883","pt":1631469307746,"mc":[{"id":"1.187528277","rc":[{"trd":[[1.42,310699.31]],"batb":[[0,1.42,27826.77]],"ltp":1.42,"tv":635196.08,"id":2249229}],"tv":762341.31}]}
{"op":"mcm","clk":"4227223862","pt":1631469327403,"mc":[{"id":"1.187528277","rc":[{"trd":[[3.3,42584.01]],"batb":[[0,3.3,9038.31]],"ltp":3.3,"tv":128245.23,"id":19924831}],"tv":763441.31}]}
{"op":"mcm","clk":"4227224184","pt":1631469330606,"mc":[{"id":"1.187528277","rc":[{"batb":[[0,3.3,8975.38]],"ltp":3.3,"tv":128245.23,"id":19924831}]}]}
{"op":"mcm","clk":"4227224269","pt":1631469331498,"mc":[{"id":"1.187528277","rc":[{"trd":[[3.35,48202.26]],"batb":[[0,3.35,73.93],[1,3.3,8945.08],[2,3.25,5116.82]],"batl":[[0,3.4,5767.49],[1,3.45,4154.27],[2,3.5,2738.41]],"ltp":3.35,"tv":128309.3,"id":19924831},{"batb":[[0,1.42,25138.35]],"batl":[[0,1.43,24736.52]],"ltp":1.42,"tv":635196.08,"id":2249229}],"tv":763505.38}]}
{"op":"mcm","clk":"4227224401","pt":1631469332680,"mc":[{"id":"1.187528277","rc":[{"batb":[[0,3.35,187.41],[1,3.3,8879.11]],"ltp":3.35,"tv":128309.3,"id":19924831}]}]}
{"op":"mcm","clk":"4227224732","pt":1631469335678,"mc":[{"id":"1.187528277","rc":[{"trd":[[3.35,48210.81]],"batb":[[0,3.35,143.42],[1,3.3,8829.5]],"ltp":3.35,"tv":128317.84,"id":19924831}],"tv":763513.93}]}
{"op":"mcm","clk":"4227224760","pt":1631469335985,"mc":[{"id":"1.187528277","rc":[{"batb":[[0,3.35,73.76]],"ltp":3.35,"tv":128317.84,"id":19924831}]}]}
{"op":"mcm","clk":"4227227520","pt":1631469363143,"mc":[{"id":"1.187528277","rc":[{"trd":[[1.42,310702.07]],"batb":[[0,1.42,25136.97]],"ltp":1.42,"tv":635198.84,"id":2249229}],"tv":763516.68}]}
{"op":"mcm","clk":"4227227592","pt":1631469363827,"mc":[{"id":"1.187528277","rc":[{"trd":[[3.35,48214.82]],"batb":[[0,3.35,71.75]],"ltp":3.35,"tv":128321.86,"id":19924831}],"tv":763520.7}]}
{"op":"mcm","clk":"4227229444","pt":1631469381531,"mc":[{"id":"1.187528277","rc":[{"trd":[[3.35,48358.32]],"batb":[[0,3.3,8829.5],[1,3.25,5116.82],[2,3.2,3226.49]],"batl":[[0,3.35,1.7],[1,3.4,5767.49],[2,3.45,4154.27]],"ltp":3.35,"tv":128465.36,"id":19924831},{"batb":[[0,1.42,27754.97]],"ltp":1.42,"tv":635198.84,"id":2249229}],"tv":763664.2}]}
{"op":"mcm","clk":"4227229498","pt":1631469382159,"mc":[{"id":"1.187528277","rc":[{"batb":[[0,3.3,8859.8]],"batl":[[0,3.35,184.36],[1,3.4,5738.08]],"ltp":3.35,"tv":128465.36,"id":19924831},{"batb":[[0,1.42,27825.39]],"batl":[[0,1.43,24666.59]],"ltp":1.42,"tv":635198.84,"id":2249229}]}]}
{"op":"mcm","clk":"4227229850","pt":1631469385659,"mc":[{"id":"1.187528277","rc":[{"trd":[[1.42,310713.23]],"batb":[[0,1.42,27819.81]],"ltp":1.42,"tv":635210.0,"id":2249229}],"tv":763675.36}]}
{"op":"mcm","clk":"4227231629","pt":1631469403073,"mc":[{"id":"1.187528277","rc":[{"batl":[[0,3.35,535.36]],"ltp":3.35,"tv":128465.36,"id":19924831}]}]}
{"op":"mcm","clk":"4227231996","pt":1631469406269,"mc":[{"id":"1.187528277","rc":[{"batl":[[0,3.35,537.36]],"ltp":3.35,"tv":128465.36,"id":19924831}]}]}
{"op":"mcm","clk":"4227233738","pt":1631469423592,"mc":[{"id":"1.187528277","rc":[{"batb":[[0,1.42,30870.2]],"ltp":1.42,"tv":635210.0,"id":2249229}]}]}
{"op":"mcm","clk":"4227234916","pt":1631469434585,"mc":[{"id":"1.187528277","rc":[{"trd":[[3.3,42628.01]],"batb":[[0,3.3,8837.8]],"ltp":3.3,"tv":128509.36,"id":19924831}],"tv":763719.36}]}
{"op":"mcm","clk":"4227236874","pt":1631469454355,"mc":[{"id":"1.187528277","rc":[{"trd":[[1.42,311264.32]],"batb":[[0,1.42,30594.66]],"ltp":1.42,"tv":635761.09,"id":2249229}],"tv":764270.45}]}
{"op":"mcm","clk":"4227239995","pt":1631469484799,"mc":[{"id":"1.187528277","rc":[{"trd":[[1.43,195257.05]],"batl":[[0,1.43,24623.89]],"ltp":1.43,"tv":635846.49,"id":2249229}],"tv":764355.86}]}
{"op":"mcm","clk":"4227241028","pt":1631469494407,"mc":[{"id":"1.187528277","rc":[{"batl":[[0,3.35,563.84],[1,3.4,5696.23]],"ltp":3.3,"tv":128509.36,"id":19924831},{"batl":[[2,1.45,9813.06]],"ltp":1.43,"tv":635846.49,"id":2249229}]}]}
{"op":"mcm","clk":"4227241708","pt":1631469500995,"mc":[{"id":"1.187528277","rc":[{"trd":[[3.3,42740.09]],"batb":[[0,3.3,8781.76]],"ltp":3.3,"tv":128621.44,"id":19924831}],"tv":764467.94}]}
{"op":"mcm","clk":"4227242490","pt":1631469508403,"mc":[{"id":"1.187528277","rc":[{"trd":[[3.35,48423.39]],"batl":[[0,3.35,531.3]],"ltp":3.35,"tv":128686.51,"id":19924831}],"tv":764533.01}]}
{"op":"mcm","clk":"4227242882","pt":1631469512217,"mc":[{"id":"1.187528277","rc":[{"trd":[[1.42,311270.32]],"batb":[[0,1.42,30591.66]],"ltp":1.42,"tv":635852.49,"id":2249229}],"tv":764539.01}]}
{"op":"mcm","clk":"4227244739","pt":1631469529841,"mc":[{"id":"1.187528277","rc":[{"trd":[[3.3,42759.39]],"batb":[[0,3.3,8772.11]],"ltp":3.3,"tv":128705.8,"id":19924831}],"tv":764558.3}]}
{"op":"mcm","clk":"4227246888","pt":1631469550183,"mc":[{"id":"1.187528277","rc":[{"trd":[[1.43,195297.05]],"batl":[[0,1.43,24603.89]],"ltp":1.43,"tv":635892.49,"id":2249229}],"tv":764598.3}]}
{"op":"mcm","clk":"4227249110","pt":1631469571998,"mc":[{"id":"1.187528277","rc":[{"trd":[[1.43,195312.43]],"batl":[[0,1.43,24596.2]],"ltp":1.43,"tv":635907.87,"id":2249229}],"tv":764613.68}]}
{"op":"mcm","clk":"4227249656","pt":1631469577012,"mc":[{"id":"1.187528277","rc":[{"batl":[[2,1.45,10063.06]],"ltp":1.43,"tv":635907.87,"id":2249229}]}]}
{"op":"mcm","clk":"4227250819","pt":1631469588193,"mc":[{"id":"1.187528277","rc":[{"trd":[[1.42,311470.32]],"batb":[[0,1.42,30491.66]],"ltp":1.42,"tv":636107.87,"id":2249229}],"tv":764813.68}]}
{"op":"mcm","clk":"4227251684","pt":1631469598347,"mc":[{"id":"1.187528277","rc":[{"trd":[[3.3,42794.49]],"batb":[[0,3.3,8754.56]],"ltp":3.3,"tv":128740.9,"id":19924831}],"tv":764848.78}]}
{"op":"mcm","clk":"4227253947","pt":1631469617369,"mc":[{"id":"1.187528277","rc":[{"batb":[[1,3.25,5543.85]],"ltp":3.3,"tv":128740.9,"id":19924831}]}]}
{"op":"mcm","clk":"4227254647","pt":1631469624468,"mc":[{"id":"1.187528277","rc":[{"trd":[[3.3,42834.49]],"batb":[[0,3.3,8734.56]],"ltp":3.3,"tv":128780.9,"id":19924831}],"tv":764888.78}]}
{"op":"mcm","clk":"4227255892","pt":1631469636082,"mc":[{"id":"1.187528277","rc":[{"trd":[[3.3,43134.49]],"batb":[[0,3.3,8584.56]],"ltp":3.3,"tv":129080.9,"id":19924831}],"tv":765188.78}]}
{"op":"mcm","clk":"4227256088","pt":1631469637760,"mc":[{"id":"1.187528277","rc":[{"batb":[[0,1.42,30494.04]],"ltp":1.42,"tv":636107.87,"id":2249229}]}]}
{"op":"mcm","clk":"4227256394","pt":1631469640383,"mc":[{"id":"1.187528277","rc":[{"batb":[[0,1.42,30491.66]],"ltp":1.42,"tv":636107.87,"id":2249229}]}]}
{"op":"mcm","clk":"4227256773","pt":1631469644267,"mc":[{"id":"1.187528277","rc":[{"trd":[[3.3,43434.49]],"batb":[[0,3.3,8434.56]],"ltp":3.3,"tv":129380.9,"id":19924831}],"tv":765488.78}]}
{"op":"mcm","clk":"4227261904","pt":1631469696635,"mc":[{"id":"1.187528277","rc":[{"trd":[[3.3,45683.25]],"batb":[[0,3.3,7310.18]],"ltp":3.3,"tv":131629.67,"id":19924831}],"tv":767737.54}]}
{"op":"mcm","clk":"4227265471","pt":1631469729235,"mc":[{"id":"1.187528277","rc":[{"batl":[[0,1.43,24646.2]],"ltp":1.42,"tv":636107.87,"id":2249229}]}]}
{"op":"mcm","clk":"4227265666","pt":1631469731142,"mc":[{"id":"1.187528277","rc":[{"batl":[[0,3.35,601.3]],"ltp":3.3,"tv":131629.67,"id":19924831}]}]}
{"op":"mcm","clk":"4227266098","pt":1631469734525,"mc":[{"id":"1.187528277","rc":[{"batb":[[0,1.42,30541.66]],"ltp":1.42,"tv":636107.87,"id":2249229}]}]}
{"op":"mcm","clk":"4227270234","pt":1631469769848,"mc":[{"id":"1.187528277","rc":[{"trd":[[1.42,311478.04]],"batb":[[0,1.42,30537.8]],"ltp":1.42,"tv":636115.59,"id":2249229}],"tv":767745.26}]}
{"op":"mcm","clk":"4227270555","pt":1631469772664,"mc":[{"id":"1.187528277","rc":[{"batl":[[0,1.43,24696.2]],"ltp":1.42,"tv":636115.59,"id":2249229}]}]}
{"op":"mcm","clk":"4227271112","pt":1631469777450,"mc":[{"id":"1.187528277","rc":[{"batb":[[1,1.41,38383.96]],"ltp":1.42,"tv":636115.59,"id":2249229}]}]}
{"op":"mcm","clk":"4227271215","pt":1631469778395,"mc":[{"id":"1.187528277","rc":[{"batl":[[0,1.43,25930.2]],"ltp":1.42,"tv":636115.59,"id":2249229}]}]}
{"op":"mcm","clk":"4227271627","pt":1631469781879,"mc":[{"id":"1.187528277","rc":[{"trd":[[1.43,195412.43]],"batl":[[0,1.43,25880.2]],"ltp":1.43,"tv":636215.59,"id":2249229}],"tv":767845.26}]}
{"op":"mcm","clk":"4227271925","pt":1631469784685,"mc":[{"id":"1.187528277","rc":[{"trd":[[1.42,311533.16]],"batb":[[0,1.42,30510.24]],"ltp":1.42,"tv":636270.71,"id":2249229}],"tv":767900.39}]}
{"op":"mcm","clk":"4227272484","pt":1631469789293,"mc":[{"id":"1.187528277","rc":[{"batb":[[1,1.41,38408.96]],"ltp":1.42,"tv":636270.71,"id":2249229}]}]}
{"op":"mcm","clk":"4227273563","pt":1631469797679,"mc":[{"id":"1.187528277","rc":[{"trd":[[1.42,311539.16]],"batb":[[0,1.42,30507.24]],"ltp":1.42,"tv":636276.71,"id":2249229}],"tv":767906.38}]}
{"op":"mcm","clk":"4227274192","pt":1631469802504,"mc":[{"id":"1.187528277","rc":[{"batl":[[0,1.43,25905.2]],"ltp":1.42,"tv":636276.71,"id":2249229}]}]}
{"op":"mcm","clk":"4227274668","pt":1631469806722,"mc":[{"id":"1.187528277","rc":[{"batb":[[0,1.42,30532.24]],"ltp":1.42,"tv":636276.71,"id":2249229}]}]}
{"op":"mcm","clk":"4227275698","pt":1631469815316,"mc":[{"id":"1.187528277","rc":[{"trd":[[3.3,45912.93]],"batb":[[0,3.3,7195.34]],"ltp":3.3,"tv":131859.35,"id":19924831}],"tv":768136.07}]}
