{"op":"mcm","clk":"4283926620","pt":1632401904616,"mc":[{"id":"1.188075669","marketDefinition":{"bspMarket":false,"turnInPlayEnabled":true,"persistenceEnabled":true,"marketBaseRate":5.0,"eventId":"30936519","eventTypeId":"2","numberOfWinners":1,"bettingType":"ODDS","marketType":"MATCH_ODDS","marketTime":"2021-09-24T09:00:00.000Z","suspendTime":"2021-09-24T09:00:00.000Z","bspReconciled":false,"complete":true,"inPlay":false,"crossMatching":false,"runnersVoidable":false,"numberOfActiveRunners":2,"betDelay":0,"status":"OPEN","runners":[{"status":"ACTIVE","sortPriority":1,"id":9454286,"name":"Antoine Escoffier"},{"status":"ACTIVE","sortPriority":2,"id":9631939,"name":"Marc-Andrea Huesler"}],"regulators":["MR_INT"],"countryCode":"CH","discountAllowed":false,"timezone":"UTC","openDate":"2021-09-24T09:00:00.000Z","version":4051056201,"name":"Match Odds","eventName":"Escoffier v Huesler"},"rc":[{"batb":[[0,1.01,25]],"ltp":0.0,"tv":0.0,"id":9631939},{"batb":[[0,1.01,25]],"ltp":0.0,"tv":0.0,"id":9454286}]}]}
{"op":"mcm","clk":"4283926765","pt":1632401906314,"mc":[{"id":"1.188075669","marketDefinition":{"bspMarket":false,"turnInPlayEnabled":true,"persistenceEnabled":true,"marketBaseRate":5.0,"eventId":"30936519","eventTypeId":"2","numberOfWinners":1,"bettingType":"ODDS","marketType":"MATCH_ODDS","marketTime":"2021-09-24T09:00:00.000Z","suspendTime":"2021-09-24T09:00:00.000Z","bspReconciled":false,"complete":true,"inPlay":false,"crossMatching":false,"runnersVoidable":false,"numberOfActiveRunners":2,"betDelay":0,"status":"OPEN","runners":[{"status":"ACTIVE","sortPriority":1,"id":9454286,"name":"Antoine Escoffier"},{"status":"ACTIVE","sortPriority":2,"id":9631939,"name":"Marc-Andrea Huesler"}],"regulators":["MR_INT"],"countryCode":"CH","discountAllowed":true,"timezone":"UTC","openDate":"2021-09-24T09:00:00.000Z","version":4051056201,"name":"Match Odds","eventName":"Escoffier v Huesler"}}]}
{"op":"mcm","clk":"4284005657","pt":1632402739135,"mc":[{"id":"1.188075669","rc":[{"batl":[[0,990,2.2]],"ltp":0.0,"tv":0.0,"id":9631939},{"batl":[[0,990,2.2]],"ltp":0.0,"tv":0.0,"id":9454286}]}]}
{"op":"mcm","clk":"4284021443","pt":1632402911056,"mc":[{"id":"1.188075669","rc":[{"batb":[[0,1.01,15]],"ltp":0.0,"tv":0.0,"id":9631939},{"batb":[[0,1.01,15]],"ltp":0.0,"tv":0.0,"id":9454286}]}]}
{"op":"mcm","clk":"4284026484","pt":1632402969821,"mc":[{"id":"1.188075669","rc":[{"batb":[[0,1.01,134.57]],"ltp":0.0,"tv":0.0,"id":9631939},{"batb":[[0,1.01,134.57]],"ltp":0.0,"tv":0.0,"id":9454286}]}]}
{"op":"mcm","clk":"4284308888","pt":1632406291035,"mc":[{"id":"1.188075669","rc":[{"batb":[[0,1.27,85.91],[1,1.01,134.65]],"ltp":0.0,"tv":0.0,"id":9631939},{"batb":[[0,2.3,40.73],[1,1.01,134.65]],"ltp":0.0,"tv":0.0,"id":9454286}]}]}
{"op":"mcm","clk":"4284309736","pt":1632406302536,"mc":[{"id":"1.188075669","rc":[{"batb":[[0,1.35,69.33]],"ltp":0.0,"tv":0.0,"id":9631939},{"batb":[[0,1.86,44.56]],"ltp":0.0,"tv":0.0,"id":9454286}]}]}
{"op":"mcm","clk":"4284310586","pt":1632406313572,"mc":[{"id":"1.188075669","rc":[{"batb":[[0,1.47,56.14]],"ltp":0.0,"tv":0.0,"id":9631939}]}]}
{"op":"mcm","clk":"4284310760","pt":1632406315926,"mc":[{"id":"1.188075669","marketDefinition":{"bspMarket":false,"turnInPlayEnabled":true,"persistenceEnabled":true,"marketBaseRate":5.0,"eventId":"30936519","eventTypeId":"2","numberOfWinners":1,"bettingType":"ODDS","marketType":"MATCH_ODDS","marketTime":"2021-09-24T09:00:00.000Z","suspendTime":"2021-09-24T09:00:00.000Z","bspReconciled":false,"complete":true,"inPlay":false,"crossMatching":true,"runnersVoidable":false,"numberOfActiveRunners":2,"betDelay":0,"status":"OPEN","runners":[{"status":"ACTIVE","sortPriority":1,"id":9454286,"name":"Antoine Escoffier"},{"status":"ACTIVE","sortPriority":2,"id":9631939,"name":"Marc-Andrea Huesler"}],"regulators":["MR_INT"],"countryCode":"CH","discountAllowed":true,"timezone":"UTC","openDate":"2021-09-24T09:00:00.000Z","version":4051056201,"name":"Match Odds","eventName":"Escoffier v Huesler"}}]}
{"op":"mcm","clk":"4284313941","pt":1632406353425,"mc":[{"id":"1.188075669","rc":[{"batb":[[0,1.58,49.87]],"ltp":0.0,"tv":0.0,"id":9631939}]}]}
{"op":"mcm","clk":"4284324741","pt":1632406463113,"mc":[{"id":"1.188075669","rc":[{"batb":[[0,1.33,73.12]],"ltp":0.0,"tv":0.0,"id":9631939}]}]}
{"op":"mcm","clk":"4284337484","pt":1632406605015,"mc":[{"id":"1.188075669","rc":[{"batb":[[0,1.36,69.33]],"ltp":0.0,"tv":0.0,"id":9631939}]}]}
{"op":"mcm","clk":"4284337683","pt":1632406607703,"mc":[{"id":"1.188075669","rc":[{"batb":[[0,1.44,63.39]],"ltp":0.0,"tv":0.0,"id":9631939}]}]}
{"op":"mcm","clk":"4284410037","pt":1632407493031,"mc":[{"id":"1.188075669","rc":[{"batb":[[0,1.01,134.65],[1,1.01,0]],"ltp":0.0,"tv":0.0,"id":9631939}]}]}
{"op":"mcm","clk":"4284410056","pt":1632407493233,"mc":[{"id":"1.188075669","rc":[{"batb":[[0,1.48,65.6],[1,1.01,134.65]],"ltp":0.0,"tv":0.0,"id":9631939}]}]}
{"op":"mcm","clk":"4284454048","pt":1632408001937,"mc":[{"id":"1.188075669","rc":[{"batb":[[0,2.16,40.84]],"batl":[[0,990,2.34]],"ltp":0.0,"tv":0.0,"id":9454286}]}]}
{"op":"mcm","clk":"4284456061","pt":1632408021441,"mc":[{"id":"1.188075669","rc":[{"batl":[[0,990,2.2]],"ltp":0.0,"tv":0.0,"id":9454286}]}]}
{"op":"mcm","clk":"4284468442","pt":1632408153824,"mc":[{"id":"1.188075669","rc":[{"batb":[[0,1.49,10.26],[1,1.48,65.6],[2,1.01,134.65]],"batl":[[0,11,3.42],[1,990,2.2]],"ltp":0.0,"tv":0.0,"id":9631939},{"batl":[[0,14,3.42],[1,990,2.2]],"ltp":0.0,"tv":0.0,"id":9454286}]}]}
{"op":"mcm","clk":"4284488863","pt":1632408399473,"mc":[{"id":"1.188075669","rc":[{"batb":[[0,1.55,63.84],[1,1.49,10.26]],"ltp":0.0,"tv":0.0,"id":9631939}]}]}
{"op":"mcm","clk":"4284490808","pt":1632408427448,"mc":[{"id":"1.188075669","rc":[{"batb":[[1,1.01,134.65],[2,1.01,0]],"ltp":0.0,"tv":0.0,"id":9631939}]}]}
{"op":"mcm","clk":"4284549742","pt":1632409106053,"mc":[{"id":"1.188075669","rc":[{"batb":[[0,1.6,379.45],[1,1.55,63.84],[2,1.01,134.65]],"ltp":0.0,"tv":0.0,"id":9631939}]}]}
{"op":"mcm","clk":"4284549760","pt":1632409106262,"mc":[{"id":"1.188075669","rc":[{"batb":[[1,1.01,134.65],[2,1.01,0]],"ltp":0.0,"tv":0.0,"id":9631939}]}]}
{"op":"mcm","clk":"4284592363","pt":1632409727288,"mc":[{"id":"1.188075669","rc":[{"batb":[[0,1.01,134.65],[1,1.01,0]],"ltp":0.0,"tv":0.0,"id":9454286}]}]}
{"op":"mcm","clk":"4284601519","pt":1632409849630,"mc":[{"id":"1.188075669","rc":[{"batb":[[0,1.02,15.38],[1,1.01,134.65]],"ltp":0.0,"tv":0.0,"id":9454286}]}]}
{"op":"mcm","clk":"4284624597","pt":1632410174287,"mc":[{"id":"1.188075669","rc":[{"batb":[[0,1.99,65.74],[1,1.02,15.38],[2,1.01,134.65]],"ltp":0.0,"tv":0.0,"id":9454286}]}]}
{"op":"mcm","clk":"4284628517","pt":1632410234468,"mc":[{"id":"1.188075669","rc":[{"batb":[[1,1.01,134.65],[2,1.01,0]],"ltp":0.0,"tv":0.0,"id":9454286}]}]}
{"op":"mcm","clk":"4284704232","pt":1632411532037,"mc":[{"id":"1.188075669","rc":[{"batb":[[1,1.01,610.77]],"ltp":0.0,"tv":0.0,"id":9631939},{"batb":[[1,1.01,610.77]],"ltp":0.0,"tv":0.0,"id":9454286}]}]}
{"op":"mcm","clk":"4284752988","pt":1632412192900,"mc":[{"id":"1.188075669","rc":[{"batb":[[1,1.18,20.22],[2,1.01,610.77]],"ltp":0.0,"tv":0.0,"id":9631939},{"batb":[[1,1.3,12.14],[2,1.01,610.77]],"ltp":0.0,"tv":0.0,"id":9454286}]}]}
{"op":"mcm","clk":"4284828837","pt":1632413245810,"mc":[{"id":"1.188075669","rc":[{"batb":[[0,1.55,379.07],[1,1.18,20.21],[2,1.01,610.37]],"batl":[[0,11,3.42]],"ltp":0.0,"tv":0.0,"id":9631939},{"batb":[[1,1.3,12.13],[2,1.01,610.37]],"batl":[[0,14,3.42]],"ltp":0.0,"tv":0.0,"id":9454286}]}]}
{"op":"mcm","clk":"4284843025","pt":1632413434849,"mc":[{"id":"1.188075669","rc":[{"batb":[[0,2,12.81],[1,1.99,65.74],[2,1.3,12.13]],"ltp":0.0,"tv":0.0,"id":9454286}]}]}
{"op":"mcm","clk":"4284846231","pt":1632413474626,"mc":[{"id":"1.188075669","rc":[{"batb":[[0,2.08,67.1],[1,2,12.81]],"ltp":0.0,"tv":0.0,"id":9454286}]}]}
{"op":"mcm","clk":"4284854902","pt":1632413590352,"mc":[{"id":"1.188075669","rc":[{"batb":[[1,1.3,12.13],[2,1.01,610.37]],"ltp":0.0,"tv":0.0,"id":9454286}]}]}
{"op":"mcm","clk":"4285044661","pt":1632416154652,"mc":[{"id":"1.188075669","rc":[{"batb":[[0,1.3,12.13],[1,1.01,610.37],[2,1.01,0]],"ltp":0.0,"tv":0.0,"id":9454286}]}]}
{"op":"mcm","clk":"4285051687","pt":1632416256370,"mc":[{"id":"1.188075669","rc":[{"batb":[[0,1.31,15.37],[1,1.3,12.13],[2,1.01,610.37]],"ltp":0.0,"tv":0.0,"id":9454286}]}]}
{"op":"mcm","clk":"4285060130","pt":1632416374974,"mc":[{"id":"1.188075669","rc":[{"batb":[[0,2.12,96.41],[1,1.31,15.37],[2,1.3,12.13]],"ltp":0.0,"tv":0.0,"id":9454286}]}]}
{"op":"mcm","clk":"4285061375","pt":1632416392993,"mc":[{"id":"1.188075669","rc":[{"batb":[[1,1.3,12.13],[2,1.01,610.37]],"ltp":0.0,"tv":0.0,"id":9454286}]}]}
{"op":"mcm","clk":"4285082015","pt":1632416616901,"mc":[{"id":"1.188075669","rc":[{"trd":[[1.55,6]],"batb":[[0,1.55,376.07]],"ltp":1.55,"tv":5.99,"id":9631939}],"tv":5.99}]}
{"op":"mcm","clk":"4285101604","pt":1632416801457,"mc":[{"id":"1.188075669","rc":[{"batl":[[0,2.4,13.63],[1,11,3.42],[2,990,2.2]],"ltp":1.55,"tv":5.99,"id":9631939},{"batl":[[0,4.7,18.96],[1,14,3.42],[2,990,2.2]],"ltp":0.0,"tv":0.0,"id":9454286}]}]}
{"op":"mcm","clk":"4285104904","pt":1632416831626,"mc":[{"id":"1.188075669","rc":[{"batl":[[1,990,2.2],[2,990,0]],"ltp":1.55,"tv":5.99,"id":9631939},{"batl":[[1,990,2.2],[2,990,0]],"ltp":0.0,"tv":0.0,"id":9454286}]}]}
{"op":"mcm","clk":"4285122048","pt":1632416983248,"mc":[{"id":"1.188075669","rc":[{"batl":[[0,4.6,3.42],[1,4.7,18.96],[2,990,2.2]],"ltp":0.0,"tv":0.0,"id":9454286}]}]}
{"op":"mcm","clk":"4285128123","pt":1632417041850,"mc":[{"id":"1.188075669","rc":[{"batl":[[0,4.1,21.73],[1,4.6,3.42]],"ltp":0.0,"tv":0.0,"id":9454286}]}]}
{"op":"mcm","clk":"4285150306","pt":1632417236191,"mc":[{"id":"1.188075669","rc":[{"batl":[[0,2.62,11.08]],"ltp":1.55,"tv":5.99,"id":9631939},{"batl":[[1,990,2.2],[2,990,0]],"ltp":0.0,"tv":0.0,"id":9454286}]}]}
{"op":"mcm","clk":"4285169528","pt":1632417401028,"mc":[{"id":"1.188075669","rc":[{"batl":[[0,2.6,3.42],[1,2.62,11.08],[2,990,2.2]],"ltp":1.55,"tv":5.99,"id":9631939}]}]}
{"op":"mcm","clk":"4285217631","pt":1632417818211,"mc":[{"id":"1.188075669","rc":[{"batl":[[0,2.56,11.34],[1,2.6,3.42]],"ltp":1.55,"tv":5.99,"id":9631939}]}]}
{"op":"mcm","clk":"4285224295","pt":1632417880813,"mc":[{"id":"1.188075669","rc":[{"batl":[[1,990,2.2],[2,990,0]],"ltp":1.55,"tv":5.99,"id":9631939}]}]}
{"op":"mcm","clk":"4285241382","pt":1632418001654,"mc":[{"id":"1.188075669","rc":[{"batl":[[0,4.5,16.91]],"ltp":0.0,"tv":0.0,"id":9454286}]}]}
{"op":"mcm","clk":"4285246888","pt":1632418044626,"mc":[{"id":"1.188075669","rc":[{"batl":[[0,2.54,3.42],[1,2.56,11.34],[2,990,2.2]],"ltp":1.55,"tv":5.99,"id":9631939},{"batl":[[0,4.4,3.42],[1,4.5,16.91],[2,990,2.2]],"ltp":0.0,"tv":0.0,"id":9454286}]}]}
{"op":"mcm","clk":"4285262604","pt":1632418170851,"mc":[{"id":"1.188075669","rc":[{"batb":[[0,1.55,539.09]],"batl":[[0,2.4,12.09],[1,2.54,3.42]],"ltp":1.55,"tv":5.99,"id":9631939},{"batl":[[0,3.75,20.27],[1,4.4,3.42]],"ltp":0.0,"tv":0.0,"id":9454286}]}]}
{"op":"mcm","clk":"4285270557","pt":1632418236863,"mc":[{"id":"1.188075669","rc":[{"batl":[[1,990,2.2],[2,990,0]],"ltp":1.55,"tv":5.99,"id":9631939},{"batl":[[1,990,2.2],[2,990,0]],"ltp":0.0,"tv":0.0,"id":9454286}]}]}
{"op":"mcm","clk":"4285281157","pt":1632418323384,"mc":[{"id":"1.188075669","marketDefinition":{"bspMarket":false,"turnInPlayEnabled":true,"persistenceEnabled":true,"marketBaseRate":5.0,"eventId":"30936519","eventTypeId":"2","numberOfWinners":1,"bettingType":"ODDS","marketType":"MATCH_ODDS","marketTime":"2021-09-24T15:00:00.000Z","suspendTime":"2021-09-24T15:00:00.000Z","bspReconciled":false,"complete":true,"inPlay":false,"crossMatching":true,"runnersVoidable":false,"numberOfActiveRunners":2,"betDelay":0,"status":"OPEN","runners":[{"status":"ACTIVE","sortPriority":1,"id":9454286,"name":"Antoine Escoffier"},{"status":"ACTIVE","sortPriority":2,"id":9631939,"name":"Marc-Andrea Huesler"}],"regulators":["MR_INT"],"countryCode":"CH","discountAllowed":true,"timezone":"UTC","openDate":"2021-09-24T09:00:00.000Z","version":4051506553,"name":"Match Odds","eventName":"Escoffier v Huesler"}}]}
{"op":"mcm","clk":"4285281610","pt":1632418326592,"mc":[{"id":"1.188075669","marketDefinition":{"bspMarket":false,"turnInPlayEnabled":true,"persistenceEnabled":true,"marketBaseRate":5.0,"eventId":"30936519","eventTypeId":"2","numberOfWinners":1,"bettingType":"ODDS","marketType":"MATCH_ODDS","marketTime":"2021-09-24T15:00:00.000Z","suspendTime":"2021-09-24T15:00:00.000Z","bspReconciled":false,"complete":true,"inPlay":false,"crossMatching":true,"runnersVoidable":false,"numberOfActiveRunners":2,"betDelay":0,"status":"OPEN","runners":[{"status":"ACTIVE","sortPriority":1,"id":9454286,"name":"Antoine Escoffier"},{"status":"ACTIVE","sortPriority":2,"id":9631939,"name":"Marc-Andrea Huesler"}],"regulators":["MR_INT"],"countryCode":"CH","discountAllowed":true,"timezone":"UTC","openDate":"2021-09-24T15:00:00.000Z","version":4051506553,"name":"Match Odds","eventName":"Escoffier v Huesler"},"rc":[{"batl":[[0,990,2.2],[1,990,0]],"ltp":1.55,"tv":5.99,"id":9631939},{"batl":[[0,990,2.2],[1,990,0]],"ltp":0.0,"tv":0.0,"id":9454286}]}]}
{"op":"mcm","clk":"4285283036","pt":1632418337931,"mc":[{"id":"1.188075669","rc":[{"batl":[[0,2.4,12.09],[1,990,2.2]],"ltp":1.55,"tv":5.99,"id":9631939},{"batl":[[0,3.55,23.29],[1,990,2.2]],"ltp":0.0,"tv":0.0,"id":9454286}]}]}
{"op":"mcm","clk":"4285380462","pt":1632419138926,"mc":[{"id":"1.188075669","rc":[{"batb":[[0,1.55,669.53]],"ltp":1.55,"tv":5.99,"id":9631939}]}]}
{"op":"mcm","clk":"4285440622","pt":1632419577108,"mc":[{"id":"1.188075669","rc":[{"batl":[[0,3.45,8.16]],"ltp":1.55,"tv":5.99,"id":9631939}]}]}
{"op":"mcm","clk":"4285440644","pt":1632419577314,"mc":[{"id":"1.188075669","rc":[{"batl":[[0,990,2.2],[1,990,0]],"ltp":1.55,"tv":5.99,"id":9631939}]}]}
{"op":"mcm","clk":"4285455342","pt":1632419708571,"mc":[{"id":"1.188075669","rc":[{"batl":[[0,10,3.42],[1,990,2.2]],"ltp":1.55,"tv":5.99,"id":9631939}]}]}
{"op":"mcm","clk":"4285466596","pt":1632419817374,"mc":[{"id":"1.188075669","rc":[{"batl":[[0,8.8,3.06],[1,10,3.42],[2,990,2.2]],"ltp":1.55,"tv":5.99,"id":9631939}]}]}
{"op":"mcm","clk":"4285472301","pt":1632419873648,"mc":[{"id":"1.188075669","rc":[{"batl":[[1,990,2.2],[2,990,0]],"ltp":1.55,"tv":5.99,"id":9631939}]}]}
{"op":"mcm","clk":"4285487390","pt":1632420022475,"mc":[{"id":"1.188075669","rc":[{"trd":[[1.55,6]],"batb":[[0,1.55,670.14],[1,1.18,20.22],[2,1.01,610.77]],"batl":[[0,8.6,3.42],[1,8.8,3.06],[2,990,2.2]],"ltp":1.55,"tv":6.0,"id":9631939},{"batb":[[1,1.3,12.13],[2,1.01,610.77]],"ltp":0.0,"tv":0.0,"id":9454286}],"tv":6.0}]}
{"op":"mcm","clk":"4285491221","pt":1632420058202,"mc":[{"id":"1.188075669","rc":[{"batl":[[1,990,2.2],[2,990,0]],"ltp":1.55,"tv":6.0,"id":9631939}]}]}
{"op":"mcm","clk":"4285491232","pt":1632420058309,"mc":[{"id":"1.188075669","rc":[{"batl":[[0,7.8,6.84],[1,8.6,3.42],[2,990,2.2]],"ltp":1.55,"tv":6.0,"id":9631939}]}]}
{"op":"mcm","clk":"4285495032","pt":1632420095037,"mc":[{"id":"1.188075669","rc":[{"batb":[[0,1.55,376.68]],"ltp":1.55,"tv":6.0,"id":9631939}]}]}
{"op":"mcm","clk":"4285510554","pt":1632420235174,"mc":[{"id":"1.188075669","rc":[{"batl":[[1,990,2.2],[2,990,0]],"ltp":1.55,"tv":6.0,"id":9631939}]}]}
{"op":"mcm","clk":"4285542926","pt":1632420465518,"mc":[{"id":"1.188075669","rc":[{"batl":[[0,7.6,3.42],[1,7.8,6.84],[2,990,2.2]],"ltp":1.55,"tv":6.0,"id":9631939}]}]}
{"op":"mcm","clk":"4285607701","pt":1632420951215,"mc":[{"id":"1.188075669","rc":[{"batl":[[0,2.3,12.23],[1,7.6,3.42]],"ltp":1.55,"tv":6.0,"id":9631939},{"batb":[[0,2.2,253.18]],"ltp":0.0,"tv":0.0,"id":9454286}]}]}
{"op":"mcm","clk":"4285636595","pt":1632421159281,"mc":[{"id":"1.188075669","rc":[{"batl":[[1,990,2.2],[2,990,0]],"ltp":1.55,"tv":6.0,"id":9631939}]}]}
{"op":"mcm","clk":"4285925171","pt":1632423305868,"mc":[{"id":"1.188075669","rc":[{"batl":[[0,990,2.2],[1,990,0]],"ltp":1.55,"tv":6.0,"id":9631939},{"batb":[[0,1.3,12.13],[1,1.01,610.77],[2,1.01,0]],"ltp":0.0,"tv":0.0,"id":9454286}]}]}
{"op":"mcm","clk":"4285925449","pt":1632423308070,"mc":[{"id":"1.188075669","rc":[{"batb":[[0,2.06,278.76],[1,1.3,12.13],[2,1.01,610.77]],"ltp":0.0,"tv":0.0,"id":9454286}]}]}
{"op":"mcm","clk":"4285939585","pt":1632423416492,"mc":[{"id":"1.188075669","rc":[{"batl":[[0,10,3.42],[1,990,2.2]],"ltp":1.55,"tv":6.0,"id":9631939}]}]}
{"op":"mcm","clk":"4285955923","pt":1632423547117,"mc":[{"id":"1.188075669","rc":[{"batl":[[0,2.72,21.12],[1,10,3.42],[2,990,2.2]],"ltp":1.55,"tv":6.0,"id":9631939}]}]}
{"op":"mcm","clk":"4285965325","pt":1632423622722,"mc":[{"id":"1.188075669","rc":[{"batl":[[1,990,2.2],[2,990,0]],"ltp":1.55,"tv":6.0,"id":9631939}]}]}
{"op":"mcm","clk":"4285985894","pt":1632423788214,"mc":[{"id":"1.188075669","rc":[{"batl":[[0,2.22,27.36]],"ltp":1.55,"tv":6.0,"id":9631939}]}]}
{"op":"mcm","clk":"4286121682","pt":1632424731089,"mc":[{"id":"1.188075669","rc":[{"batl":[[0,1.94,4],[1,2.22,27.36],[2,990,2.2]],"ltp":1.55,"tv":6.0,"id":9631939},{"batb":[[0,2.08,4],[1,2.06,282.76],[2,1.3,12.13]],"ltp":0.0,"tv":0.0,"id":9454286}]}]}
{"op":"mcm","clk":"4286121732","pt":1632424731456,"mc":[{"id":"1.188075669","rc":[{"batl":[[1,990,2.2],[2,990,0]],"ltp":1.55,"tv":6.0,"id":9631939}]}]}
{"op":"mcm","clk":"4286123496","pt":1632424745196,"mc":[{"id":"1.188075669","rc":[{"batb":[[1,2.06,4]],"ltp":0.0,"tv":0.0,"id":9454286}]}]}
{"op":"mcm","clk":"4286123593","pt":1632424745873,"mc":[{"id":"1.188075669","rc":[{"batl":[[0,1.92,37.96],[1,1.94,4],[2,990,2.2]],"ltp":1.55,"tv":6.0,"id":9631939},{"batb":[[0,2.24,256.25],[1,2.08,4]],"ltp":0.0,"tv":0.0,"id":9454286}]}]}
{"op":"mcm","clk":"4286206357","pt":1632425412868,"mc":[{"id":"1.188075669","rc":[{"batl":[[0,990,2.2],[1,990,0]],"ltp":0.0,"tv":0.0,"id":9454286}]}]}
{"op":"mcm","clk":"4286221038","pt":1632425545904,"mc":[{"id":"1.188075669","rc":[{"batl":[[0,4.4,18.71],[1,16,3.42],[2,990,2.2]],"ltp":0.0,"tv":0.0,"id":9454286}]}]}
{"op":"mcm","clk":"4286237564","pt":1632425687588,"mc":[{"id":"1.188075669","rc":[{"batl":[[1,990,2.2],[2,990,0]],"ltp":0.0,"tv":0.0,"id":9454286}]}]}
{"op":"mcm","clk":"4286258739","pt":1632425883093,"mc":[{"id":"1.188075669","rc":[{"batl":[[0,1.8,4],[1,1.92,37.96],[2,1.94,4]],"ltp":1.55,"tv":6.0,"id":9631939},{"batb":[[0,2.1,39.53]],"ltp":0.0,"tv":0.0,"id":9454286}]}]}
{"op":"mcm","clk":"4286258808","pt":1632425883817,"mc":[{"id":"1.188075669","rc":[{"batl":[[0,990,2.2],[1,1.92,0],[2,1.94,0]],"ltp":1.55,"tv":6.0,"id":9631939},{"batb":[[0,1.3,12.13],[1,1.01,610.77],[2,1.3,0]],"ltp":0.0,"tv":0.0,"id":9454286}]}]}
{"op":"mcm","clk":"4286258961","pt":1632425885314,"mc":[{"id":"1.188075669","rc":[{"batb":[[0,2.26,269.09],[1,1.3,12.13],[2,1.01,610.77]],"ltp":0.0,"tv":0.0,"id":9454286}]}]}
{"op":"mcm","clk":"4286267459","pt":1632425964609,"mc":[{"id":"1.188075669","rc":[{"batl":[[0,9.8,3.42],[1,990,2.2]],"ltp":1.55,"tv":6.0,"id":9631939},{"batl":[[0,4.3,3.42],[1,4.4,18.71],[2,990,2.2]],"ltp":0.0,"tv":0.0,"id":9454286}]}]}
{"op":"mcm","clk":"4286283974","pt":1632426124065,"mc":[{"id":"1.188075669","rc":[{"batl":[[0,2.3,33.81],[1,9.8,3.42],[2,990,2.2]],"ltp":1.55,"tv":6.0,"id":9631939},{"batl":[[1,990,2.2],[2,990,0]],"ltp":0.0,"tv":0.0,"id":9454286}]}]}
{"op":"mcm","clk":"4286283995","pt":1632426124266,"mc":[{"id":"1.188075669","rc":[{"batl":[[0,3.6,22.85],[1,4.3,3.42],[2,990,2.2]],"ltp":0.0,"tv":0.0,"id":9454286}]}]}
{"op":"mcm","clk":"4286295489","pt":1632426233537,"mc":[{"id":"1.188075669","rc":[{"batl":[[1,990,2.2],[2,990,0]],"ltp":1.55,"tv":6.0,"id":9631939},{"batl":[[1,990,2.2],[2,990,0]],"ltp":0.0,"tv":0.0,"id":9454286}]}]}
{"op":"mcm","clk":"4286614358","pt":1632430065780,"mc":[{"id":"1.188075669","rc":[{"trd":[[1.55,6]],"batb":[[0,1.55,376.91],[1,1.18,20.24],[2,1.01,611.36]],"ltp":1.55,"tv":6.0,"id":9631939},{"batb":[[1,1.3,12.15],[2,1.01,611.36]],"ltp":0.0,"tv":0.0,"id":9454286}],"tv":6.0}]}
{"op":"mcm","clk":"4286667330","pt":1632431038076,"mc":[{"id":"1.188075669","rc":[{"batb":[[0,1.8,43.95]],"ltp":0.0,"tv":0.0,"id":9454286}]}]}
{"op":"mcm","clk":"4286667416","pt":1632431039172,"mc":[{"id":"1.188075669","rc":[{"batl":[[0,990,2.2],[1,990,0]],"ltp":1.55,"tv":6.0,"id":9631939},{"batb":[[0,1.3,12.15],[1,1.01,611.36],[2,1.01,0]],"ltp":0.0,"tv":0.0,"id":9454286}]}]}
{"op":"mcm","clk":"4286667616","pt":1632431042152,"mc":[{"id":"1.188075669","rc":[{"batb":[[0,2.3,264.39],[1,1.3,12.15],[2,1.01,611.36]],"ltp":0.0,"tv":0.0,"id":9454286}]}]}
{"op":"mcm","clk":"4286671379","pt":1632431126621,"mc":[{"id":"1.188075669","rc":[{"batl":[[0,9.6,3.42],[1,990,2.2]],"ltp":1.55,"tv":6.0,"id":9631939}]}]}
{"op":"mcm","clk":"4286677888","pt":1632431279186,"mc":[{"id":"1.188075669","rc":[{"batl":[[0,2.24,38.23],[1,9.6,3.42],[2,990,2.2]],"ltp":1.55,"tv":6.0,"id":9631939}]}]}
{"op":"mcm","clk":"4286682561","pt":1632431394007,"mc":[{"id":"1.188075669","rc":[{"batl":[[1,990,2.2],[2,990,0]],"ltp":1.55,"tv":6.0,"id":9631939}]}]}
{"op":"mcm","clk":"4286734527","pt":1632432683060,"mc":[{"id":"1.188075669","rc":[{"batl":[[0,990,2.2],[1,990,0]],"ltp":0.0,"tv":0.0,"id":9454286}]}]}
{"op":"mcm","clk":"4286734537","pt":1632432683266,"mc":[{"id":"1.188075669","rc":[{"batl":[[0,4.4,18.73],[1,990,2.2]],"ltp":0.0,"tv":0.0,"id":9454286}]}]}
{"op":"mcm","clk":"4286838433","pt":1632435465747,"mc":[{"id":"1.188075669","rc":[{"batb":[[0,1.55,376.84],[1,1.18,20.25],[2,1.01,611.41]],"ltp":1.55,"tv":6.0,"id":9631939},{"batb":[[1,1.3,12.15],[2,1.01,611.41]],"ltp":0.0,"tv":0.0,"id":9454286}]}]}
{"op":"mcm","clk":"4286874691","pt":1632436608992,"mc":[{"id":"1.188075669","rc":[{"batb":[[1,1.01,134.77],[2,1.01,0]],"ltp":1.55,"tv":6.0,"id":9631939},{"batb":[[1,1.01,134.77],[2,1.01,0]],"ltp":0.0,"tv":0.0,"id":9454286}]}]}
{"op":"mcm","clk":"4286908867","pt":1632437890216,"mc":[{"id":"1.188075669","rc":[{"batb":[[0,1.99,349.21]],"batl":[[0,990,2.2],[1,990,0]],"ltp":0.0,"tv":0.0,"id":9454286}]}]}
{"op":"mcm","clk":"4286908892","pt":1632437890729,"mc":[{"id":"1.188075669","rc":[{"batl":[[0,2.84,31.44]],"ltp":1.55,"tv":6.0,"id":9631939},{"batl":[[0,4.7,17.53],[1,990,2.2]],"ltp":0.0,"tv":0.0,"id":9454286}]}]}
{"op":"mcm","clk":"4286912530","pt":1632438003331,"mc":[{"id":"1.188075669","rc":[{"batb":[[1,1.01,139.77]],"ltp":1.55,"tv":6.0,"id":9631939},{"batb":[[1,1.01,139.77]],"ltp":0.0,"tv":0.0,"id":9454286}]}]}
{"op":"mcm","clk":"4286917258","pt":1632438146917,"mc":[{"id":"1.188075669","rc":[{"batl":[[0,990,2.2],[1,990,0]],"ltp":1.55,"tv":6.0,"id":9631939},{"batb":[[0,2.14,284.26]],"ltp":0.0,"tv":0.0,"id":9454286}]}]}
{"op":"mcm","clk":"4286923606","pt":1632438371461,"mc":[{"id":"1.188075669","rc":[{"batl":[[0,2.16,41.64],[1,990,2.2]],"ltp":1.55,"tv":6.0,"id":9631939}]}]}
{"op":"mcm","clk":"4286924799","pt":1632438429057,"mc":[{"id":"1.188075669","rc":[{"batb":[[1,1.01,616.41]],"ltp":1.55,"tv":6.0,"id":9631939},{"batb":[[1,1.01,616.41]],"ltp":0.0,"tv":0.0,"id":9454286}]}]}
{"op":"mcm","clk":"4286940348","pt":1632439185668,"mc":[{"id":"1.188075669","rc":[{"batb":[[1,1.16,22.78],[2,1.01,616.41]],"ltp":1.55,"tv":6.0,"id":9631939},{"batb":[[1,1.34,10.72],[2,1.01,616.41]],"ltp":0.0,"tv":0.0,"id":9454286}]}]}
{"op":"mcm","clk":"4286947317","pt":1632439570008,"mc":[{"id":"1.188075669","rc":[{"batl":[[0,1.61,25],[1,2.16,41.64],[2,990,2.2]],"ltp":1.55,"tv":6.0,"id":9631939},{"batl":[[0,3.25,25],[1,4.7,17.53],[2,990,2.2]],"ltp":0.0,"tv":0.0,"id":9454286}]}]}
{"op":"mcm","clk":"4286947323","pt":1632439570315,"mc":[{"id":"1.188075669","rc":[{"batl":[[1,990,2.2],[2,990,0]],"ltp":1.55,"tv":6.0,"id":9631939}]}]}
{"op":"mcm","clk":"4286987516","pt":1632441317967,"mc":[{"id":"1.188075669","rc":[{"batb":[[0,1.48,376.84],[1,1.32,600.1],[2,1.16,22.78]],"ltp":1.55,"tv":6.0,"id":9631939}]}]}
{"op":"mcm","clk":"4286987525","pt":1632441318272,"mc":[{"id":"1.188075669","rc":[{"batl":[[1,990,2.2],[2,990,0]],"ltp":0.0,"tv":0.0,"id":9454286}]}]}
{"op":"mcm","clk":"4286987678","pt":1632441330556,"mc":[{"id":"1.188075669","rc":[{"batb":[[0,2.16,11.98],[1,2.14,284.26],[2,1.34,10.72]],"ltp":0.0,"tv":0.0,"id":9454286}]}]}
{"op":"mcm","clk":"4286989411","pt":1632441447217,"mc":[{"id":"1.188075669","rc":[{"batb":[[1,1.16,22.78],[2,1.01,616.41]],"ltp":1.55,"tv":6.0,"id":9631939},{"batb":[[0,2.2,276.47],[1,2.16,11.98]],"ltp":0.0,"tv":0.0,"id":9454286}]}]}
{"op":"mcm","clk":"4286989546","pt":1632441455633,"mc":[{"id":"1.188075669","rc":[{"batb":[[1,1.34,10.72],[2,1.01,616.41]],"ltp":0.0,"tv":0.0,"id":9454286}]}]}
{"op":"mcm","clk":"4287079148","pt":1632445237577,"mc":[{"id":"1.188075669","rc":[{"batb":[[0,1.48,403.91],[2,1.01,616.42]],"ltp":1.55,"tv":6.0,"id":9631939},{"batb":[[2,1.01,616.42]],"ltp":0.0,"tv":0.0,"id":9454286}]}]}
{"op":"mcm","clk":"4287084075","pt":1632445428155,"mc":[{"id":"1.188075669","rc":[{"batb":[[0,1.34,10.72],[1,1.01,616.42],[2,1.01,0]],"ltp":0.0,"tv":0.0,"id":9454286}]}]}
{"op":"mcm","clk":"4287084082","pt":1632445428361,"mc":[{"id":"1.188075669","rc":[{"batb":[[0,2.04,339.64],[1,1.34,10.72],[2,1.01,616.42]],"ltp":0.0,"tv":0.0,"id":9454286}]}]}
{"op":"mcm","clk":"4287085608","pt":1632445490014,"mc":[{"id":"1.188075669","rc":[{"batb":[[0,2.06,13.69],[1,2.04,339.64],[2,1.34,10.72]],"ltp":0.0,"tv":0.0,"id":9454286}]}]}
{"op":"mcm","clk":"4287091928","pt":1632445728487,"mc":[{"id":"1.188075669","rc":[{"batb":[[0,2.28,266.72],[1,2.06,13.69]],"ltp":0.0,"tv":0.0,"id":9454286}]}]}
{"op":"mcm","clk":"4287092362","pt":1632445744286,"mc":[{"id":"1.188075669","rc":[{"batb":[[1,1.34,10.72],[2,1.01,616.42]],"ltp":0.0,"tv":0.0,"id":9454286}]}]}
{"op":"mcm","clk":"4287166323","pt":1632448057132,"mc":[{"id":"1.188075669","rc":[{"batl":[[0,1.6,6],[1,1.61,25],[2,990,2.2]],"ltp":1.55,"tv":6.0,"id":9631939},{"batb":[[0,2.64,4],[1,2.62,4],[2,2.28,266.72]],"ltp":0.0,"tv":0.0,"id":9454286}]}]}
{"op":"mcm","clk":"4287168210","pt":1632448128720,"mc":[{"id":"1.188075669","rc":[{"batb":[[0,2.64,236.8],[1,1.34,10.72],[2,1.01,616.42]],"ltp":0.0,"tv":0.0,"id":9454286}]}]}
{"op":"mcm","clk":"4287173801","pt":1632448336598,"mc":[{"id":"1.188075669","rc":[{"batl":[[2,46,28.9]],"ltp":1.55,"tv":6.0,"id":9631939},{"batl":[[1,46,28.9],[2,990,2.2]],"ltp":0.0,"tv":0.0,"id":9454286}]}]}
{"op":"mcm","clk":"4287196178","pt":1632449039209,"mc":[{"id":"1.188075669","rc":[{"batb":[[0,1.48,403.88],[1,1.16,22.77],[2,1.01,616.38]],"batl":[[2,46,28.9]],"ltp":1.55,"tv":6.0,"id":9631939},{"batb":[[2,1.01,616.38]],"batl":[[1,46,28.9]],"ltp":0.0,"tv":0.0,"id":9454286}]}]}
{"op":"mcm","clk":"4287235478","pt":1632450757815,"mc":[{"id":"1.188075669","rc":[{"batl":[[0,1.61,25],[1,46,28.9],[2,990,2.2]],"ltp":1.55,"tv":6.0,"id":9631939},{"batb":[[0,2.64,232.8]],"ltp":0.0,"tv":0.0,"id":9454286}]}]}
{"op":"mcm","clk":"4287313743","pt":1632452984715,"mc":[{"id":"1.188075669","rc":[{"batb":[[2,1.14,52.06]],"ltp":1.55,"tv":6.0,"id":9631939}]}]}
{"op":"mcm","clk":"4287374086","pt":1632454933033,"mc":[{"id":"1.188075669","rc":[{"trd":[[1.48,103.99]],"batb":[[0,1.48,351.89]],"ltp":1.48,"tv":109.99,"id":9631939}],"tv":109.99}]}
{"op":"mcm","clk":"4287407398","pt":1632456136933,"mc":[{"id":"1.188075669","rc":[{"batb":[[1,1.16,22.77],[2,1.14,52.05]],"batl":[[0,1.6,6],[1,1.61,25],[2,46,28.9]],"ltp":1.48,"tv":109.99,"id":9631939},{"batb":[[0,2.64,3],[1,2.62,4],[2,2.22,278.07]],"ltp":0.0,"tv":0.0,"id":9454286}]}]}
{"op":"mcm","clk":"4287408610","pt":1632456176486,"mc":[{"id":"1.188075669","rc":[{"batb":[[0,2.66,231.9],[1,2.64,3],[2,1.34,10.72]],"ltp":0.0,"tv":0.0,"id":9454286}]}]}
{"op":"mcm","clk":"4287522365","pt":1632459628004,"mc":[{"id":"1.188075669","rc":[{"batl":[[0,1.61,25],[1,46,28.9],[2,990,2.2]],"ltp":1.48,"tv":109.99,"id":9631939},{"batb":[[0,2.66,350.55],[1,1.34,10.72],[2,1.01,616.31]],"ltp":0.0,"tv":0.0,"id":9454286}]}]}
{"op":"mcm","clk":"4287524985","pt":1632459682877,"mc":[{"id":"1.188075669","rc":[{"batb":[[0,1.34,10.72],[1,1.01,616.31],[2,1.01,0]],"ltp":0.0,"tv":0.0,"id":9454286}]}]}
{"op":"mcm","clk":"4287526225","pt":1632459711010,"mc":[{"id":"1.188075669","rc":[{"batb":[[0,1.35,15.4],[1,1.34,10.72],[2,1.01,616.31]],"ltp":0.0,"tv":0.0,"id":9454286}]}]}
{"op":"mcm","clk":"4287528955","pt":1632459774129,"mc":[{"id":"1.188075669","rc":[{"batb":[[0,2.4,390.83],[1,1.35,15.4],[2,1.34,10.72]],"ltp":0.0,"tv":0.0,"id":9454286}]}]}
{"op":"mcm","clk":"4287531371","pt":1632459832751,"mc":[{"id":"1.188075669","rc":[{"batb":[[1,1.34,10.72],[2,1.01,616.31]],"ltp":0.0,"tv":0.0,"id":9454286}]}]}
{"op":"mcm","clk":"4287550534","pt":1632460510027,"mc":[{"id":"1.188075669","rc":[{"batl":[[0,1.6,32.66],[1,1.61,25],[2,46,28.9]],"ltp":1.48,"tv":109.99,"id":9631939},{"batb":[[0,2.46,819.72]],"batl":[[0,3.25,42.66]],"ltp":0.0,"tv":0.0,"id":9454286}]}]}
{"op":"mcm","clk":"4287550569","pt":1632460510901,"mc":[{"id":"1.188075669","rc":[{"batb":[[0,1.49,11.07],[1,1.48,351.89],[2,1.16,22.77]],"ltp":1.48,"tv":109.99,"id":9631939},{"batb":[[0,2.74,11.71]],"ltp":0.0,"tv":0.0,"id":9454286}]}]}
{"op":"mcm","clk":"4287635761","pt":1632462653145,"mc":[{"id":"1.188075669","rc":[{"trd":[[2.74,23.42]],"batb":[[0,1.34,10.72],[1,1.01,616.31],[2,1.01,0]],"batl":[[0,2.74,1.12],[1,3.25,42.66],[2,46,28.9]],"ltp":2.74,"tv":23.42,"id":9454286}],"tv":133.41}]}
{"op":"mcm","clk":"4287635798","pt":1632462654127,"mc":[{"id":"1.188075669","rc":[{"batb":[[0,1.51,19.86],[1,1.49,35.67],[2,1.48,351.89]],"batl":[[0,1.61,25],[1,46,28.9],[2,990,2.2]],"ltp":1.48,"tv":109.99,"id":9631939},{"trd":[[2.74,25.66]],"batb":[[0,2.68,360.1],[1,1.5,14.57],[2,1.34,10.72]],"batl":[[0,3.25,202.88],[1,46,28.9],[2,990,2.2]],"ltp":2.74,"tv":25.66,"id":9454286}],"tv":135.65}]}
{"op":"mcm","clk":"4287635824","pt":1632462655211,"mc":[{"id":"1.188075669","rc":[{"batl":[[0,3.25,25]],"ltp":2.74,"tv":25.66,"id":9454286}]}]}
{"op":"mcm","clk":"4287635827","pt":1632462655307,"mc":[{"id":"1.188075669","rc":[{"batl":[[0,3.2,184.52],[1,3.25,25],[2,46,28.9]],"ltp":2.74,"tv":25.66,"id":9454286}]}]}
{"op":"mcm","clk":"4287643570","pt":1632462894171,"mc":[{"id":"1.188075669","rc":[{"batb":[[1,1.48,351.89],[2,1.16,22.77]],"ltp":1.48,"tv":109.99,"id":9631939}]}]}
{"op":"mcm","clk":"4287658515","pt":1632463258969,"mc":[{"id":"1.188075669","rc":[{"trd":[[1.48,104]],"batb":[[0,1.51,19.86],[1,1.48,351.95],[2,1.16,22.78]],"batl":[[0,1.59,6],[1,1.61,25],[2,46,28.91]],"ltp":1.48,"tv":110.0,"id":9631939},{"trd":[[2.74,25.67]],"batb":[[0,2.7,465.75],[1,2.68,10.38],[2,1.5,14.58]],"batl":[[2,46,28.91]],"ltp":2.74,"tv":25.66,"id":9454286}],"tv":135.66}]}
{"op":"mcm","clk":"4287658711","pt":1632463263182,"mc":[{"id":"1.188075669","rc":[{"batb":[[1,2.68,4]],"ltp":2.74,"tv":25.66,"id":9454286}]}]}
{"op":"mcm","clk":"4287658714","pt":1632463263286,"mc":[{"id":"1.188075669","rc":[{"batb":[[0,2.72,3.65],[1,2.7,465.75],[2,2.68,4]],"ltp":2.74,"tv":25.66,"id":9454286}]}]}
{"op":"mcm","clk":"4287663200","pt":1632463364082,"mc":[{"id":"1.188075669","rc":[{"batb":[[1,2.7,3],[2,1.5,14.58]],"ltp":2.74,"tv":25.66,"id":9454286}]}]}
{"op":"mcm","clk":"4287667001","pt":1632463465150,"mc":[{"id":"1.188075669","rc":[{"batb":[[0,2.7,3],[1,1.5,14.58],[2,1.34,10.72]],"ltp":2.74,"tv":25.66,"id":9454286}]}]}
{"op":"mcm","clk":"4287667011","pt":1632463465355,"mc":[{"id":"1.188075669","rc":[{"batb":[[0,2.7,473.33]],"ltp":2.74,"tv":25.66,"id":9454286}]}]}
{"op":"mcm","clk":"4287673363","pt":1632463748798,"mc":[{"id":"1.188075669","rc":[{"batl":[[0,1.58,6],[1,1.59,6],[2,1.61,25]],"ltp":1.48,"tv":110.0,"id":9631939},{"batb":[[0,2.74,3],[1,2.72,28.81],[2,2.7,473.33]],"ltp":2.74,"tv":25.66,"id":9454286}]}]}
{"op":"mcm","clk":"4287673374","pt":1632463749413,"mc":[{"id":"1.188075669","rc":[{"batb":[[1,2.72,4]],"ltp":2.74,"tv":25.66,"id":9454286}]}]}
{"op":"mcm","clk":"4287673662","pt":1632463765534,"mc":[{"id":"1.188075669","rc":[{"batl":[[1,1.61,25],[2,46,28.91]],"ltp":1.48,"tv":110.0,"id":9631939},{"batb":[[0,2.76,481.56],[1,2.74,3],[2,2.7,5]],"ltp":2.74,"tv":25.66,"id":9454286}]}]}
{"op":"mcm","clk":"4287675412","pt":1632463841335,"mc":[{"id":"1.188075669","rc":[{"batl":[[2,1.8,9.48]],"ltp":1.48,"tv":110.0,"id":9631939}]}]}
{"op":"mcm","clk":"4287675719","pt":1632463854579,"mc":[{"id":"1.188075669","rc":[{"batb":[[2,1.35,7.29]],"ltp":1.48,"tv":110.0,"id":9631939}]}]}
{"op":"mcm","clk":"4287675994","pt":1632463864780,"mc":[{"id":"1.188075669","rc":[{"batb":[[2,2.64,9.26]],"ltp":2.74,"tv":25.66,"id":9454286}]}]}
{"op":"mcm","clk":"4287694771","pt":1632464400258,"mc":[{"id":"1.188075669","rc":[{"batl":[[0,3.25,25],[1,46,28.91],[2,990,2.2]],"ltp":2.74,"tv":25.66,"id":9454286}]}]}
{"op":"mcm","clk":"4287694871","pt":1632464401587,"mc":[{"id":"1.188075669","rc":[{"batl":[[0,3.2,148.33],[1,3.25,25],[2,46,28.91]],"ltp":2.74,"tv":25.66,"id":9454286}]}]}
{"op":"mcm","clk":"4287701293","pt":1632464535118,"mc":[{"id":"1.188075669","rc":[{"batb":[[1,1.48,27.04],[2,1.46,324.91]],"ltp":1.48,"tv":110.0,"id":9631939}]}]}
{"op":"mcm","clk":"4287701518","pt":1632464540573,"mc":[{"id":"1.188075669","rc":[{"batb":[[1,1.46,324.91],[2,1.35,7.29]],"ltp":1.48,"tv":110.0,"id":9631939}]}]}
{"op":"mcm","clk":"4287701709","pt":1632464545054,"mc":[{"id":"1.188075669","rc":[{"batb":[[1,1.46,153.78]],"ltp":1.48,"tv":110.0,"id":9631939}]}]}
{"op":"mcm","clk":"4287701773","pt":1632464546548,"mc":[{"id":"1.188075669","rc":[{"batb":[[1,1.46,181.18]],"ltp":1.48,"tv":110.0,"id":9631939}]}]}
{"op":"mcm","clk":"4287723198","pt":1632465203827,"mc":[{"id":"1.188075669","rc":[{"batb":[[0,2.78,481.36]],"ltp":2.74,"tv":25.66,"id":9454286}]}]}
{"op":"mcm","clk":"4287812940","pt":1632466964417,"mc":[{"id":"1.188075669","rc":[{"batl":[[0,1.56,5],[1,1.58,6],[2,1.61,25]],"ltp":1.48,"tv":110.0,"id":9631939},{"batb":[[0,2.8,3],[1,2.78,484.36],[2,2.74,3]],"ltp":2.74,"tv":25.66,"id":9454286}]}]}
{"op":"mcm","clk":"4287815501","pt":1632467004072,"mc":[{"id":"1.188075669","rc":[{"batl":[[1,1.61,25],[2,1.8,9.48]],"ltp":1.48,"tv":110.0,"id":9631939},{"batb":[[0,2.82,474.51],[1,2.8,3],[2,2.64,9.26]],"ltp":2.74,"tv":25.66,"id":9454286}]}]}
{"op":"mcm","clk":"4287817023","pt":1632467029032,"mc":[{"id":"1.188075669","rc":[{"batb":[[0,1.46,181.18],[1,1.35,7.29],[2,1.16,22.78]],"ltp":1.48,"tv":110.0,"id":9631939},{"trd":[[2.82,4.92]],"batb":[[0,2.82,472.05]],"ltp":2.82,"tv":30.59,"id":9454286}],"tv":140.59}]}
{"op":"mcm","clk":"4287817070","pt":1632467029911,"mc":[{"id":"1.188075669","rc":[{"batb":[[0,1.5,20.09],[1,1.46,181.18],[2,1.35,7.29]],"ltp":1.48,"tv":110.0,"id":9631939},{"batb":[[0,2.8,3],[1,2.64,9.26],[2,1.5,14.58]],"batl":[[0,3.2,148.14]],"ltp":2.82,"tv":30.59,"id":9454286}]}]}
{"op":"mcm","clk":"4287817269","pt":1632467032798,"mc":[{"id":"1.188075669","rc":[{"batb":[[1,1.46,153.78]],"ltp":1.48,"tv":110.0,"id":9631939}]}]}
{"op":"mcm","clk":"4287817647","pt":1632467038739,"mc":[{"id":"1.188075669","rc":[{"batb":[[0,1.5,46.77]],"ltp":1.48,"tv":110.0,"id":9631939}]}]}
{"op":"mcm","clk":"4287841204","pt":1632467496995,"mc":[{"id":"1.188075669","rc":[{"batb":[[0,2.82,472.89],[1,2.8,3],[2,2.64,9.26]],"ltp":2.82,"tv":30.59,"id":9454286}]}]}
{"op":"mcm","clk":"4287848982","pt":1632467639934,"mc":[{"id":"1.188075669","rc":[{"batl":[[0,1.55,5],[1,1.56,5],[2,1.61,25]],"ltp":1.48,"tv":110.0,"id":9631939},{"batb":[[0,2.82,3],[1,2.8,469.53]],"ltp":2.82,"tv":30.59,"id":9454286}]}]}
{"op":"mcm","clk":"4287854173","pt":1632467726471,"mc":[{"id":"1.188075669","rc":[{"batb":[[2,1.42,7]],"batl":[[0,1.54,7],[1,1.55,5]],"ltp":1.48,"tv":110.0,"id":9631939},{"batb":[[0,2.84,3],[1,2.82,3]],"ltp":2.82,"tv":30.59,"id":9454286}]}]}
{"op":"mcm","clk":"4287856563","pt":1632467765143,"mc":[{"id":"1.188075669","rc":[{"trd":[[1.54,8.24]],"batl":[[0,1.54,2.88]],"ltp":1.54,"tv":118.24,"id":9631939}],"tv":148.83}]}
{"op":"mcm","clk":"4287856592","pt":1632467765619,"mc":[{"id":"1.188075669","rc":[{"batl":[[1,1.61,25],[2,1.8,9.48]],"ltp":1.54,"tv":118.24,"id":9631939},{"batb":[[1,2.66,12.05],[2,1.5,14.58]],"ltp":2.82,"tv":30.59,"id":9454286}]}]}
{"op":"mcm","clk":"4287876222","pt":1632467868034,"mc":[{"id":"1.188075669","rc":[{"trd":[[1.5,10.27]],"batb":[[0,1.5,26.68],[1,1.48,20.95],[2,1.46,153.78]],"ltp":1.5,"tv":128.51,"id":9631939},{"batb":[[1,2.7,11.46]],"ltp":2.82,"tv":30.59,"id":9454286}],"tv":159.1}]}
{"op":"mcm","clk":"4287876550","pt":1632467873073,"mc":[{"id":"1.188075669","rc":[{"batb":[[0,1.48,20.95],[1,1.46,153.78],[2,1.42,7]],"ltp":1.5,"tv":128.51,"id":9631939}]}]}
{"op":"mcm","clk":"4287876903","pt":1632467879048,"mc":[{"id":"1.188075669","rc":[{"batb":[[0,1.48,47.99]],"ltp":1.5,"tv":128.51,"id":9631939}]}]}
{"op":"mcm","clk":"4287937625","pt":1632468890969,"mc":[{"id":"1.188075669","rc":[{"batb":[[0,1.48,20.95]],"ltp":1.5,"tv":128.51,"id":9631939}]}]}
{"op":"mcm","clk":"4287937969","pt":1632468896341,"mc":[{"id":"1.188075669","rc":[{"batb":[[0,1.48,47.99]],"ltp":1.5,"tv":128.51,"id":9631939}]}]}
{"op":"mcm","clk":"4287952539","pt":1632469109283,"mc":[{"id":"1.188075669","rc":[{"trd":[[2.84,0.22]],"batb":[[0,2.84,2.89]],"ltp":2.84,"tv":30.81,"id":9454286}],"tv":159.32}]}
{"op":"mcm","clk":"4287954895","pt":1632469140024,"mc":[{"id":"1.188075669","rc":[{"batl":[[0,3.25,25],[1,46,28.91],[2,990,2.2]],"ltp":2.84,"tv":30.81,"id":9454286}]}]}
{"op":"mcm","clk":"4287954913","pt":1632469140232,"mc":[{"id":"1.188075669","rc":[{"batl":[[0,3.2,171.68],[1,3.25,25],[2,46,28.91]],"ltp":2.84,"tv":30.81,"id":9454286}]}]}
{"op":"mcm","clk":"4287964110","pt":1632469266845,"mc":[{"id":"1.188075669","rc":[{"batb":[[1,2.8,12.87],[2,2.7,11.46]],"ltp":2.84,"tv":30.81,"id":9454286}]}]}
{"op":"mcm","clk":"4287979787","pt":1632469532643,"mc":[{"id":"1.188075669","rc":[{"batl":[[0,3.2,18.52]],"ltp":2.84,"tv":30.81,"id":9454286}]}]}
{"op":"mcm","clk":"4287981571","pt":1632469568414,"mc":[{"id":"1.188075669","rc":[{"batl":[[0,3.2,171.68]],"ltp":2.84,"tv":30.81,"id":9454286}]}]}
{"op":"mcm","clk":"4288028882","pt":1632470487029,"mc":[{"id":"1.188075669","rc":[{"trd":[[1.48,104.03],[1.5,10.27],[1.54,8.25],[1.55,6.01]],"batb":[[0,1.48,48.01],[1,1.46,153.87]],"batl":[[1,1.58,2.68],[2,1.61,25]],"ltp":1.5,"tv":128.55,"id":9631939},{"trd":[[2.74,25.68],[2.82,4.93]],"batb":[[2,2.7,11.46]],"batl":[[2,46,28.92]],"ltp":2.84,"tv":30.82,"id":9454286}],"tv":159.38}]}
{"op":"mcm","clk":"4288235895","pt":1632473824451,"mc":[{"id":"1.188075669","marketDefinition":{"bspMarket":false,"turnInPlayEnabled":true,"persistenceEnabled":true,"marketBaseRate":5.0,"eventId":"30936519","eventTypeId":"2","numberOfWinners":1,"bettingType":"ODDS","marketType":"MATCH_ODDS","marketTime":"2021-09-24T14:54:00.000Z","suspendTime":"2021-09-24T14:54:00.000Z","bspReconciled":false,"complete":true,"inPlay":false,"crossMatching":true,"runnersVoidable":false,"numberOfActiveRunners":2,"betDelay":0,"status":"OPEN","runners":[{"status":"ACTIVE","sortPriority":1,"id":9454286,"name":"Antoine Escoffier"},{"status":"ACTIVE","sortPriority":2,"id":9631939,"name":"Marc-Andrea Huesler"}],"regulators":["MR_INT"],"countryCode":"CH","discountAllowed":true,"timezone":"UTC","openDate":"2021-09-24T15:00:00.000Z","version":4052386702,"name":"Match Odds","eventName":"Escoffier v Huesler"}}]}
{"op":"mcm","clk":"4288237182","pt":1632473845570,"mc":[{"id":"1.188075669","marketDefinition":{"bspMarket":false,"turnInPlayEnabled":true,"persistenceEnabled":true,"marketBaseRate":5.0,"eventId":"30936519","eventTypeId":"2","numberOfWinners":1,"bettingType":"ODDS","marketType":"MATCH_ODDS","marketTime":"2021-09-24T14:54:00.000Z","suspendTime":"2021-09-24T14:54:00.000Z","bspReconciled":false,"complete":true,"inPlay":false,"crossMatching":true,"runnersVoidable":false,"numberOfActiveRunners":2,"betDelay":0,"status":"OPEN","runners":[{"status":"ACTIVE","sortPriority":1,"id":9454286,"name":"Antoine Escoffier"},{"status":"ACTIVE","sortPriority":2,"id":9631939,"name":"Marc-Andrea Huesler"}],"regulators":["MR_INT"],"countryCode":"CH","discountAllowed":true,"timezone":"UTC","openDate":"2021-09-24T14:54:00.000Z","version":4052386702,"name":"Match Odds","eventName":"Escoffier v Huesler"}}]}
{"op":"mcm","clk":"4288240976","pt":1632473907580,"mc":[{"id":"1.188075669","rc":[{"batb":[[1,2.8,19.3]],"ltp":2.84,"tv":30.82,"id":9454286}]}]}
{"op":"mcm","clk":"4288250042","pt":1632474059134,"mc":[{"id":"1.188075669","rc":[{"batb":[[2,1.5,14.59]],"ltp":2.84,"tv":30.82,"id":9454286}]}]}
{"op":"mcm","clk":"4288250052","pt":1632474059267,"mc":[{"id":"1.188075669","rc":[{"batb":[[1,2.82,3.6],[2,2.8,19.3]],"ltp":2.84,"tv":30.82,"id":9454286}]}]}
{"op":"mcm","clk":"4288256554","pt":1632474171884,"mc":[{"id":"1.188075669","rc":[{"batb":[[1,1.42,7],[2,1.36,96.54]],"ltp":1.5,"tv":128.55,"id":9631939}]}]}
{"op":"mcm","clk":"4288262753","pt":1632474287007,"mc":[{"id":"1.188075669","rc":[{"batl":[[0,3.25,199.1],[1,46,28.92],[2,990,2.2]],"ltp":2.84,"tv":30.82,"id":9454286}]}]}
{"op":"mcm","clk":"4288269250","pt":1632474404348,"mc":[{"id":"1.188075669","rc":[{"batl":[[0,1.52,12],[1,1.54,2.88],[2,1.58,2.68]],"ltp":1.5,"tv":128.55,"id":9631939}]}]}
{"op":"mcm","clk":"4288272057","pt":1632474459623,"mc":[{"id":"1.188075669","rc":[{"trd":[[1.52,8.72]],"batb":[[0,1.48,41.72]],"batl":[[0,1.52,7.64]],"ltp":1.52,"tv":137.27,"id":9631939}],"tv":168.1}]}
{"op":"mcm","clk":"4288272109","pt":1632474460296,"mc":[{"id":"1.188075669","rc":[{"batb":[[0,1.48,14.68]],"ltp":1.52,"tv":137.27,"id":9631939}]}]}
{"op":"mcm","clk":"4288272464","pt":1632474466409,"mc":[{"id":"1.188075669","rc":[{"batb":[[1,1.44,15.93],[2,1.42,7]],"ltp":1.52,"tv":137.27,"id":9631939}]}]}
{"op":"mcm","clk":"4288306548","pt":1632475018293,"mc":[{"id":"1.188075669","rc":[{"batb":[[0,2.88,18.48],[1,2.84,2.89],[2,2.82,3.6]],"ltp":2.84,"tv":30.82,"id":9454286}]}]}
{"op":"mcm","clk":"4288306864","pt":1632475022420,"mc":[{"id":"1.188075669","rc":[{"batb":[[1,1.44,18.61]],"ltp":1.52,"tv":137.27,"id":9631939}]}]}
{"op":"mcm","clk":"4288327734","pt":1632475337980,"mc":[{"id":"1.188075669","rc":[{"batl":[[0,3.25,43.09]],"ltp":2.84,"tv":30.82,"id":9454286}]}]}
{"op":"mcm","clk":"4288329712","pt":1632475361785,"mc":[{"id":"1.188075669","rc":[{"batl":[[0,3.25,199.7]],"ltp":2.84,"tv":30.82,"id":9454286}]}]}
{"op":"mcm","clk":"4288384243","pt":1632476059462,"mc":[{"id":"1.188075669","rc":[{"batb":[[0,1.47,21.87],[1,1.45,39.28],[2,1.44,18.61]],"ltp":1.52,"tv":137.27,"id":9631939},{"batb":[[2,2.74,10.65]],"ltp":2.84,"tv":30.82,"id":9454286}]}]}
{"op":"mcm","clk":"4288384322","pt":1632476060361,"mc":[{"id":"1.188075669","rc":[{"batb":[[2,1.42,7]],"ltp":1.52,"tv":137.27,"id":9631939}]}]}
{"op":"mcm","clk":"4288384835","pt":1632476066377,"mc":[{"id":"1.188075669","rc":[{"batb":[[0,1.47,43.75]],"ltp":1.52,"tv":137.27,"id":9631939}]}]}
{"op":"mcm","clk":"4288385264","pt":1632476072476,"mc":[{"id":"1.188075669","rc":[{"batb":[[0,1.47,49.09],[1,1.42,7],[2,1.36,96.54]],"ltp":1.52,"tv":137.27,"id":9631939}]}]}
{"op":"mcm","clk":"4288410061","pt":1632476445339,"mc":[{"id":"1.188075669","rc":[{"batl":[[0,3.2,13.37],[1,3.25,25],[2,46,28.92]],"ltp":2.84,"tv":30.82,"id":9454286}]}]}
{"op":"mcm","clk":"4288449883","pt":1632477042216,"mc":[{"id":"1.188075669","rc":[{"batl":[[0,1.49,239.73],[1,1.52,7.64],[2,1.54,2.88]],"ltp":1.52,"tv":137.27,"id":9631939}]}]}
{"op":"mcm","clk":"4288449901","pt":1632477042424,"mc":[{"id":"1.188075669","rc":[{"batb":[[1,1.36,96.54],[2,1.35,7.29]],"batl":[[2,1.58,2.68]],"ltp":1.52,"tv":137.27,"id":9631939},{"batb":[[1,2.74,10.65],[2,1.5,14.59]],"ltp":2.84,"tv":30.82,"id":9454286}]}]}
{"op":"mcm","clk":"4288450981","pt":1632477059145,"mc":[{"id":"1.188075669","rc":[{"trd":[[1.49,31.3]],"batb":[[0,1.47,27.22]],"batl":[[0,1.49,224.08]],"ltp":1.49,"tv":168.57,"id":9631939},{"batl":[[0,3.25,25],[1,46,28.92],[2,990,2.2]],"ltp":2.84,"tv":30.82,"id":9454286}],"tv":199.4}]}
{"op":"mcm","clk":"4288451007","pt":1632477059719,"mc":[{"id":"1.188075669","rc":[{"batb":[[1,1.45,18.44],[2,1.36,96.54]],"ltp":1.49,"tv":168.57,"id":9631939},{"batb":[[0,2.94,4.98],[1,2.88,18.48]],"ltp":2.84,"tv":30.82,"id":9454286}]}]}
{"op":"mcm","clk":"4288451282","pt":1632477064245,"mc":[{"id":"1.188075669","rc":[{"batb":[[0,1.45,18.44],[1,1.36,96.54],[2,1.35,7.29]],"ltp":1.49,"tv":168.57,"id":9631939}]}]}
{"op":"mcm","clk":"4288451636","pt":1632477070265,"mc":[{"id":"1.188075669","rc":[{"batb":[[1,1.44,27.78],[2,1.36,96.54]],"ltp":1.49,"tv":168.57,"id":9631939}]}]}
{"op":"mcm","clk":"4288452101","pt":1632477079558,"mc":[{"id":"1.188075669","rc":[{"batl":[[0,1.5,224.08]],"ltp":1.49,"tv":168.57,"id":9631939}]}]}
{"op":"mcm","clk":"4288452765","pt":1632477090953,"mc":[{"id":"1.188075669","rc":[{"batl":[[0,3.25,25.86]],"ltp":2.84,"tv":30.82,"id":9454286}]}]}
{"op":"mcm","clk":"4288452910","pt":1632477093752,"mc":[{"id":"1.188075669","rc":[{"batb":[[1,1.36,96.54],[2,1.35,7.29]],"ltp":1.49,"tv":168.57,"id":9631939}]}]}
{"op":"mcm","clk":"4288453276","pt":1632477099802,"mc":[{"id":"1.188075669","rc":[{"batb":[[0,1.45,46.04]],"ltp":1.49,"tv":168.57,"id":9631939}]}]}
{"op":"mcm","clk":"4288489270","pt":1632477716169,"mc":[{"id":"1.188075669","rc":[{"batb":[[2,1.35,7.3]],"batl":[[0,1.52,7.64],[1,1.58,2.68],[2,1.61,25]],"ltp":1.49,"tv":168.57,"id":9631939},{"batb":[[2,1.5,14.59]],"batl":[[1,46,28.93]],"ltp":2.84,"tv":30.82,"id":9454286}]}]}
{"op":"mcm","clk":"4288489277","pt":1632477716274,"mc":[{"id":"1.188075669","rc":[{"batl":[[0,1.49,224.08],[1,1.52,7.64],[2,1.58,2.68]],"ltp":1.49,"tv":168.57,"id":9631939}]}]}
{"op":"mcm","clk":"4288499556","pt":1632477838359,"mc":[{"id":"1.188075669","rc":[{"trd":[[1.49,209.52]],"batl":[[0,1.49,134.97]],"ltp":1.49,"tv":346.79,"id":9631939}],"tv":377.62}]}
{"op":"mcm","clk":"4288533499","pt":1632478165448,"mc":[{"id":"1.188075669","rc":[{"batb":[[0,1.46,3.01],[1,1.45,46.04],[2,1.36,96.54]],"ltp":1.49,"tv":346.79,"id":9631939}]}]}
{"op":"mcm","clk":"4288659242","pt":1632479528018,"mc":[{"id":"1.188075669","marketDefinition":{"bspMarket":false,"turnInPlayEnabled":true,"persistenceEnabled":true,"marketBaseRate":5.0,"eventId":"30936519","eventTypeId":"2","numberOfWinners":1,"bettingType":"ODDS","marketType":"MATCH_ODDS","marketTime":"2021-09-24T14:34:00.000Z","suspendTime":"2021-09-24T14:34:00.000Z","bspReconciled":false,"complete":true,"inPlay":false,"crossMatching":true,"runnersVoidable":false,"numberOfActiveRunners":2,"betDelay":0,"status":"OPEN","runners":[{"status":"ACTIVE","sortPriority":1,"id":9454286,"name":"Antoine Escoffier"},{"status":"ACTIVE","sortPriority":2,"id":9631939,"name":"Marc-Andrea Huesler"}],"regulators":["MR_INT"],"countryCode":"CH","discountAllowed":true,"timezone":"UTC","openDate":"2021-09-24T14:54:00.000Z","version":4052505022,"name":"Match Odds","eventName":"Escoffier v Huesler"}}]}
{"op":"mcm","clk":"4288659621","pt":1632479532043,"mc":[{"id":"1.188075669","marketDefinition":{"bspMarket":false,"turnInPlayEnabled":true,"persistenceEnabled":true,"marketBaseRate":5.0,"eventId":"30936519","eventTypeId":"2","numberOfWinners":1,"bettingType":"ODDS","marketType":"MATCH_ODDS","marketTime":"2021-09-24T14:34:00.000Z","suspendTime":"2021-09-24T14:34:00.000Z","bspReconciled":false,"complete":true,"inPlay":false,"crossMatching":true,"runnersVoidable":false,"numberOfActiveRunners":2,"betDelay":0,"status":"OPEN","runners":[{"status":"ACTIVE","sortPriority":1,"id":9454286,"name":"Antoine Escoffier"},{"status":"ACTIVE","sortPriority":2,"id":9631939,"name":"Marc-Andrea Huesler"}],"regulators":["MR_INT"],"countryCode":"CH","discountAllowed":true,"timezone":"UTC","openDate":"2021-09-24T14:34:00.000Z","version":4052505022,"name":"Match Odds","eventName":"Escoffier v Huesler"}}]}
{"op":"mcm","clk":"4288663400","pt":1632479582130,"mc":[{"id":"1.188075669","rc":[{"batb":[[0,2.94,473.03]],"ltp":2.84,"tv":30.82,"id":9454286}]}]}
{"op":"mcm","clk":"4288663677","pt":1632479585532,"mc":[{"id":"1.188075669","rc":[{"batb":[[0,3,3],[1,2.98,3],[2,2.94,473.03]],"ltp":2.84,"tv":30.82,"id":9454286}]}]}
{"op":"mcm","clk":"4288669237","pt":1632479660033,"mc":[{"id":"1.188075669","rc":[{"batb":[[2,2.94,4.98]],"ltp":2.84,"tv":30.82,"id":9454286}]}]}
{"op":"mcm","clk":"4288669321","pt":1632479660920,"mc":[{"id":"1.188075669","rc":[{"batb":[[1,2.94,4.98],[2,2.88,18.48]],"ltp":2.84,"tv":30.82,"id":9454286}]}]}
{"op":"mcm","clk":"4288680588","pt":1632479802687,"mc":[{"id":"1.188075669","rc":[{"trd":[[1.46,1.4]],"batb":[[0,1.46,2.31]],"ltp":1.46,"tv":348.19,"id":9631939}],"tv":379.02}]}
{"op":"mcm","clk":"4288793775","pt":1632481544109,"mc":[{"id":"1.188075669","rc":[{"trd":[[1.49,218.42]],"batl":[[0,1.49,130.51]],"ltp":1.49,"tv":357.09,"id":9631939}],"tv":387.92}]}
{"op":"mcm","clk":"4288860651","pt":1632482488319,"mc":[{"id":"1.188075669","rc":[{"batb":[[0,2.98,3],[1,2.96,3],[2,2.94,4.98]],"ltp":2.84,"tv":30.82,"id":9454286}]}]}
{"op":"mcm","clk":"4288872703","pt":1632482636695,"mc":[{"id":"1.188075669","rc":[{"batb":[[1,2.94,4.98],[2,2.88,18.48]],"ltp":2.84,"tv":30.82,"id":9454286}]}]}
{"op":"mcm","clk":"4288910959","pt":1632483097647,"mc":[{"id":"1.188075669","rc":[{"batb":[[2,1.35,7.3]],"ltp":1.49,"tv":357.09,"id":9631939},{"batb":[[2,1.8,11.94]],"ltp":2.84,"tv":30.82,"id":9454286}]}]}
{"op":"mcm","clk":"4288922730","pt":1632483248947,"mc":[{"id":"1.188075669","rc":[{"batl":[[1,46,29.9]],"ltp":2.84,"tv":30.82,"id":9454286}]}]}
{"op":"mcm","clk":"4289007096","pt":1632484211082,"mc":[{"id":"1.188075669","rc":[{"batb":[[0,2.94,4.98],[1,1.8,11.94],[2,1.5,14.59]],"ltp":2.84,"tv":30.82,"id":9454286}]}]}
{"op":"mcm","clk":"4289007116","pt":1632484211243,"mc":[{"id":"1.188075669","rc":[{"batb":[[0,2.96,462.76],[1,2.94,4.98],[2,1.8,11.94]],"ltp":2.84,"tv":30.82,"id":9454286}]}]}
{"op":"mcm","clk":"4289031826","pt":1632484581567,"mc":[{"id":"1.188075669","rc":[{"batb":[[2,1.8,23.82]],"ltp":2.84,"tv":30.82,"id":9454286}]}]}
{"op":"mcm","clk":"4289062549","pt":1632485059387,"mc":[{"id":"1.188075669","rc":[{"trd":[[1.46,1.4],[1.48,104.06],[1.49,218.56],[1.5,10.28],[1.52,8.72],[1.54,8.25],[1.55,6.01]],"batb":[[1,1.45,46.05],[2,1.35,7.31]],"batl":[[0,1.49,130.59]],"ltp":1.49,"tv":357.28,"id":9631939},{"trd":[[2.74,25.7],[2.82,4.93]],"batb":[[0,2.98,2.84],[1,2.96,462.76],[2,1.8,23.88]],"batl":[[1,46,29.97]],"ltp":2.84,"tv":30.84,"id":9454286}],"tv":388.12}]}
{"op":"mcm","clk":"4289066068","pt":1632485106030,"mc":[{"id":"1.188075669","rc":[{"batb":[[1,1.8,23.88],[2,1.5,14.63]],"ltp":2.84,"tv":30.84,"id":9454286}]}]}
{"op":"mcm","clk":"4289119390","pt":1632485824412,"mc":[{"id":"1.188075669","marketDefinition":{"bspMarket":false,"turnInPlayEnabled":true,"persistenceEnabled":true,"marketBaseRate":5.0,"eventId":"30936519","eventTypeId":"2","numberOfWinners":1,"bettingType":"ODDS","marketType":"MATCH_ODDS","marketTime":"2021-09-24T14:32:00.000Z","suspendTime":"2021-09-24T14:32:00.000Z","bspReconciled":false,"complete":true,"inPlay":false,"crossMatching":true,"runnersVoidable":false,"numberOfActiveRunners":2,"betDelay":0,"status":"OPEN","runners":[{"status":"ACTIVE","sortPriority":1,"id":9454286,"name":"Antoine Escoffier"},{"status":"ACTIVE","sortPriority":2,"id":9631939,"name":"Marc-Andrea Huesler"}],"regulators":["MR_INT"],"countryCode":"CH","discountAllowed":true,"timezone":"UTC","openDate":"2021-09-24T14:34:00.000Z","version":4052638361,"name":"Match Odds","eventName":"Escoffier v Huesler"}}]}
{"op":"mcm","clk":"4289119648","pt":1632485827468,"mc":[{"id":"1.188075669","marketDefinition":{"bspMarket":false,"turnInPlayEnabled":true,"persistenceEnabled":true,"marketBaseRate":5.0,"eventId":"30936519","eventTypeId":"2","numberOfWinners":1,"bettingType":"ODDS","marketType":"MATCH_ODDS","marketTime":"2021-09-24T14:32:00.000Z","suspendTime":"2021-09-24T14:32:00.000Z","bspReconciled":false,"complete":true,"inPlay":false,"crossMatching":true,"runnersVoidable":false,"numberOfActiveRunners":2,"betDelay":0,"status":"OPEN","runners":[{"status":"ACTIVE","sortPriority":1,"id":9454286,"name":"Antoine Escoffier"},{"status":"ACTIVE","sortPriority":2,"id":9631939,"name":"Marc-Andrea Huesler"}],"regulators":["MR_INT"],"countryCode":"CH","discountAllowed":true,"timezone":"UTC","openDate":"2021-09-24T14:32:00.000Z","version":4052638361,"name":"Match Odds","eventName":"Escoffier v Huesler"}}]}
{"op":"mcm","clk":"4289129985","pt":1632485959018,"mc":[{"id":"1.188075669","rc":[{"batb":[[0,1.8,23.88],[1,1.5,14.63],[2,1.34,10.76]],"ltp":2.84,"tv":30.84,"id":9454286}]}]}
{"op":"mcm","clk":"4289130032","pt":1632485959536,"mc":[{"id":"1.188075669","rc":[{"batb":[[0,2.96,462.76],[1,2.94,4.99],[2,1.8,23.88]],"ltp":2.84,"tv":30.84,"id":9454286}]}]}
{"op":"mcm","clk":"4289143100","pt":1632486127387,"mc":[{"id":"1.188075669","marketDefinition":{"bspMarket":false,"turnInPlayEnabled":true,"persistenceEnabled":true,"marketBaseRate":5.0,"eventId":"30936519","eventTypeId":"2","numberOfWinners":1,"bettingType":"ODDS","marketType":"MATCH_ODDS","marketTime":"2021-09-24T14:17:00.000Z","suspendTime":"2021-09-24T14:17:00.000Z","bspReconciled":false,"complete":true,"inPlay":false,"crossMatching":true,"runnersVoidable":false,"numberOfActiveRunners":2,"betDelay":0,"status":"OPEN","runners":[{"status":"ACTIVE","sortPriority":1,"id":9454286,"name":"Antoine Escoffier"},{"status":"ACTIVE","sortPriority":2,"id":9631939,"name":"Marc-Andrea Huesler"}],"regulators":["MR_INT"],"countryCode":"CH","discountAllowed":true,"timezone":"UTC","openDate":"2021-09-24T14:32:00.000Z","version":4052646159,"name":"Match Odds","eventName":"Escoffier v Huesler"}}]}
{"op":"mcm","clk":"4289143301","pt":1632486129401,"mc":[{"id":"1.188075669","marketDefinition":{"bspMarket":false,"turnInPlayEnabled":true,"persistenceEnabled":true,"marketBaseRate":5.0,"eventId":"30936519","eventTypeId":"2","numberOfWinners":1,"bettingType":"ODDS","marketType":"MATCH_ODDS","marketTime":"2021-09-24T14:17:00.000Z","suspendTime":"2021-09-24T14:17:00.000Z","bspReconciled":false,"complete":true,"inPlay":false,"crossMatching":true,"runnersVoidable":false,"numberOfActiveRunners":2,"betDelay":0,"status":"OPEN","runners":[{"status":"ACTIVE","sortPriority":1,"id":9454286,"name":"Antoine Escoffier"},{"status":"ACTIVE","sortPriority":2,"id":9631939,"name":"Marc-Andrea Huesler"}],"regulators":["MR_INT"],"countryCode":"CH","discountAllowed":true,"timezone":"UTC","openDate":"2021-09-24T14:17:00.000Z","version":4052646159,"name":"Match Odds","eventName":"Escoffier v Huesler"}}]}
{"op":"mcm","clk":"4289175587","pt":1632486544634,"mc":[{"id":"1.188075669","rc":[{"batb":[[0,2.94,4.99],[1,1.8,23.88],[2,1.5,14.63]],"ltp":2.84,"tv":30.84,"id":9454286}]}]}
{"op":"mcm","clk":"4289175645","pt":1632486545525,"mc":[{"id":"1.188075669","rc":[{"batb":[[0,2.94,489.21]],"ltp":2.84,"tv":30.84,"id":9454286}]}]}
{"op":"mcm","clk":"4289201710","pt":1632486849006,"mc":[{"id":"1.188075669","rc":[{"batb":[[0,3,3],[1,2.98,3],[2,2.94,489.21]],"ltp":2.84,"tv":30.84,"id":9454286}]}]}
{"op":"mcm","clk":"4289201811","pt":1632486850221,"mc":[{"id":"1.188075669","rc":[{"batl":[[1,46,29]],"ltp":2.84,"tv":30.84,"id":9454286}]}]}
{"op":"mcm","clk":"4289201832","pt":1632486850540,"mc":[{"id":"1.188075669","rc":[{"batl":[[1,46,29.97]],"ltp":2.84,"tv":30.84,"id":9454286}]}]}
{"op":"mcm","clk":"4289206188","pt":1632486902676,"mc":[{"id":"1.188075669","rc":[{"batb":[[1,2.94,4.99],[2,1.8,23.88]],"ltp":2.84,"tv":30.84,"id":9454286}]}]}
{"op":"mcm","clk":"4289299311","pt":1632487955224,"mc":[{"id":"1.188075669","rc":[{"batl":[[0,1.52,7.64],[1,1.58,2.68],[2,1.61,25]],"ltp":1.49,"tv":357.28,"id":9631939}]}]}
{"op":"mcm","clk":"4289299314","pt":1632487955327,"mc":[{"id":"1.188075669","rc":[{"batl":[[0,1.48,130.59],[1,1.52,7.64],[2,1.58,2.68]],"ltp":1.49,"tv":357.28,"id":9631939}]}]}
{"op":"mcm","clk":"4289299572","pt":1632487959809,"mc":[{"id":"1.188075669","rc":[{"trd":[[1.48,113.62]],"batb":[[1,1.45,27.6]],"batl":[[0,1.48,125.81]],"ltp":1.48,"tv":366.84,"id":9631939}],"tv":397.68}]}
{"op":"mcm","clk":"4289299591","pt":1632487960229,"mc":[{"id":"1.188075669","rc":[{"batb":[[0,1.46,12.17]],"ltp":1.48,"tv":366.84,"id":9631939}]}]}
{"op":"mcm","clk":"4289299898","pt":1632487965417,"mc":[{"id":"1.188075669","rc":[{"batb":[[1,1.35,7.31],[2,1.23,41.44]],"ltp":1.48,"tv":366.84,"id":9631939}]}]}
{"op":"mcm","clk":"4289300249","pt":1632487971340,"mc":[{"id":"1.188075669","rc":[{"batb":[[1,1.44,20.43],[2,1.35,7.31]],"ltp":1.48,"tv":366.84,"id":9631939}]}]}
{"op":"mcm","clk":"4289313863","pt":1632488171690,"mc":[{"id":"1.188075669","rc":[{"trd":[[1.46,11.4]],"batb":[[0,1.46,7.17]],"ltp":1.46,"tv":376.84,"id":9631939}],"tv":407.68}]}
{"op":"mcm","clk":"4289322788","pt":1632488306508,"mc":[{"id":"1.188075669","rc":[{"trd":[[1.48,117.15]],"batl":[[0,1.48,122.28]],"ltp":1.48,"tv":380.37,"id":9631939},{"trd":[[3.05,1.71]],"ltp":3.05,"tv":32.55,"id":9454286}],"tv":412.93}]}
{"op":"mcm","clk":"4289326418","pt":1632488359701,"mc":[{"id":"1.188075669","rc":[{"batb":[[0,1.45,12.39]],"ltp":1.48,"tv":380.37,"id":9631939},{"batb":[[1,2.94,7.98]],"ltp":3.05,"tv":32.55,"id":9454286}]}]}
{"op":"mcm","clk":"4289326783","pt":1632488364393,"mc":[{"id":"1.188075669","rc":[{"batb":[[1,1.44,27.78]],"ltp":1.48,"tv":380.37,"id":9631939}]}]}
{"op":"mcm","clk":"4289340883","pt":1632488541649,"mc":[{"id":"1.188075669","rc":[{"batl":[[0,1.52,7.64],[1,1.58,2.68],[2,1.61,25]],"ltp":1.48,"tv":380.37,"id":9631939}]}]}
{"op":"mcm","clk":"4289342188","pt":1632488558603,"mc":[{"id":"1.188075669","rc":[{"batl":[[0,1.48,155.92],[1,1.52,7.64],[2,1.58,2.68]],"ltp":1.48,"tv":380.37,"id":9631939}]}]}
{"op":"mcm","clk":"4289347933","pt":1632488627125,"mc":[{"id":"1.188075669","rc":[{"batl":[[0,1.52,7.64],[1,1.58,2.68],[2,1.61,25]],"ltp":1.48,"tv":380.37,"id":9631939}]}]}
{"op":"mcm","clk":"4289347945","pt":1632488627230,"mc":[{"id":"1.188075669","rc":[{"batl":[[0,1.47,155.92],[1,1.52,7.64],[2,1.58,2.68]],"ltp":1.48,"tv":380.37,"id":9631939}]}]}
{"op":"mcm","clk":"4289348574","pt":1632488634156,"mc":[{"id":"1.188075669","rc":[{"batl":[[0,1.48,155.92]],"ltp":1.48,"tv":380.37,"id":9631939}]}]}
{"op":"mcm","clk":"4289391147","pt":1632489167610,"mc":[{"id":"1.188075669","rc":[{"batb":[[0,3,29.36]],"ltp":3.05,"tv":32.55,"id":9454286}]}]}
{"op":"mcm","clk":"4289412531","pt":1632489420869,"mc":[{"id":"1.188075669","rc":[{"batb":[[2,1.42,30.59]],"ltp":1.48,"tv":380.37,"id":9631939},{"batb":[[0,3,26.36],[1,2.98,6.49],[2,2.94,7.98]],"ltp":3.05,"tv":32.55,"id":9454286}]}]}
{"op":"mcm","clk":"4289445298","pt":1632489659708,"mc":[{"id":"1.188075669","rc":[{"batb":[[0,3,31.79],[2,1.8,23.88]],"ltp":3.05,"tv":32.55,"id":9454286}]}]}
{"op":"mcm","clk":"4289453716","pt":1632489763943,"mc":[{"id":"1.188075669","rc":[{"trd":[[1.45,5.3]],"batb":[[0,1.45,9.74]],"ltp":1.45,"tv":385.66,"id":9631939},{"batb":[[0,3.1,2.65],[1,3,31.79],[2,2.98,6.49]],"ltp":3.05,"tv":32.55,"id":9454286}],"tv":418.22}]}
{"op":"mcm","clk":"4289476474","pt":1632490036210,"mc":[{"id":"1.188075669","rc":[{"trd":[[1.45,10.6]],"batb":[[0,1.45,10.01]],"ltp":1.45,"tv":390.96,"id":9631939}],"tv":423.52}]}
{"op":"mcm","clk":"4289515988","pt":1632490451074,"mc":[{"id":"1.188075669","rc":[{"batl":[[1,46,29]],"ltp":3.05,"tv":32.55,"id":9454286}]}]}
{"op":"mcm","clk":"4289516207","pt":1632490453557,"mc":[{"id":"1.188075669","rc":[{"batl":[[1,46,29.91]],"ltp":3.05,"tv":32.55,"id":9454286}]}]}
{"op":"mcm","clk":"4289516333","pt":1632490454876,"mc":[{"id":"1.188075669","rc":[{"batb":[[2,1.41,31.35]],"ltp":1.45,"tv":390.96,"id":9631939},{"batb":[[0,3.15,10.36],[1,3.1,2.65],[2,3.05,6.27]],"ltp":3.05,"tv":32.55,"id":9454286}]}]}
{"op":"mcm","clk":"4289516762","pt":1632490459984,"mc":[{"id":"1.188075669","rc":[{"batb":[[0,3.1,2.65],[1,3.05,6.27],[2,3,31.79]],"ltp":3.05,"tv":32.55,"id":9454286}]}]}
{"op":"mcm","clk":"4289516837","pt":1632490460786,"mc":[{"id":"1.188075669","rc":[{"batb":[[2,1.42,30.59]],"ltp":1.45,"tv":390.96,"id":9631939},{"batb":[[1,3,31.79],[2,2.98,6.49]],"ltp":3.05,"tv":32.55,"id":9454286}]}]}
{"op":"mcm","clk":"4289531367","pt":1632490627002,"mc":[{"id":"1.188075669","rc":[{"trd":[[3.1,60]],"batb":[[0,3,31.79],[1,2.98,6.49],[2,1.8,23.88]],"ltp":3.1,"tv":92.55,"id":9454286}],"tv":483.52}]}
{"op":"mcm","clk":"4289581432","pt":1632491194099,"mc":[{"id":"1.188075669","rc":[{"batl":[[1,1.49,4.46],[2,1.52,7.64]],"ltp":1.45,"tv":390.96,"id":9631939}]}]}
{"op":"mcm","clk":"4289581833","pt":1632491199170,"mc":[{"id":"1.188075669","rc":[{"batl":[[1,1.52,7.64],[2,1.58,2.68]],"ltp":1.45,"tv":390.96,"id":9631939}]}]}
{"op":"mcm","clk":"4289581841","pt":1632491199321,"mc":[{"id":"1.188075669","rc":[{"batl":[[1,1.49,4.46],[2,1.52,7.64]],"ltp":1.45,"tv":390.96,"id":9631939}]}]}
{"op":"mcm","clk":"4289586562","pt":1632491256271,"mc":[{"id":"1.188075669","rc":[{"batb":[[2,2.88,2.65]],"ltp":3.1,"tv":92.55,"id":9454286}]}]}
{"op":"mcm","clk":"4289588411","pt":1632491278735,"mc":[{"id":"1.188075669","rc":[{"trd":[[1.48,273.07]],"batl":[[0,1.49,4.46],[1,1.52,7.64],[2,1.58,2.68]],"ltp":1.48,"tv":546.88,"id":9631939},{"trd":[[3,20.02],[3.05,77.37]],"batb":[[0,3,21.78]],"ltp":3.0,"tv":188.23,"id":9454286}],"tv":735.12}]}
{"op":"mcm","clk":"4289588483","pt":1632491279414,"mc":[{"id":"1.188075669","rc":[{"batb":[[1,2.96,6.55]],"ltp":3.0,"tv":188.23,"id":9454286}]}]}
{"op":"mcm","clk":"4289605661","pt":1632491497968,"mc":[{"id":"1.188075669","rc":[{"batb":[[0,3.05,4.66],[1,3,21.78],[2,2.96,6.55]],"ltp":3.0,"tv":188.23,"id":9454286}]}]}
{"op":"mcm","clk":"4289605681","pt":1632491498285,"mc":[{"id":"1.188075669","rc":[{"batb":[[0,3,21.78],[1,2.96,6.55],[2,2.88,2.65]],"ltp":3.0,"tv":188.23,"id":9454286}]}]}
{"op":"mcm","clk":"4289607412","pt":1632491524336,"mc":[{"id":"1.188075669","marketDefinition":{"bspMarket":false,"turnInPlayEnabled":true,"persistenceEnabled":true,"marketBaseRate":5.0,"eventId":"30936519","eventTypeId":"2","numberOfWinners":1,"bettingType":"ODDS","marketType":"MATCH_ODDS","marketTime":"2021-09-24T13:54:00.000Z","suspendTime":"2021-09-24T13:54:00.000Z","bspReconciled":false,"complete":true,"inPlay":false,"crossMatching":true,"runnersVoidable":false,"numberOfActiveRunners":2,"betDelay":0,"status":"OPEN","runners":[{"status":"ACTIVE","sortPriority":1,"id":9454286,"name":"Antoine Escoffier"},{"status":"ACTIVE","sortPriority":2,"id":9631939,"name":"Marc-Andrea Huesler"}],"regulators":["MR_INT"],"countryCode":"CH","discountAllowed":true,"timezone":"UTC","openDate":"2021-09-24T14:17:00.000Z","version":4052775457,"name":"Match Odds","eventName":"Escoffier v Huesler"}}]}
{"op":"mcm","clk":"4289607649","pt":1632491527355,"mc":[{"id":"1.188075669","marketDefinition":{"bspMarket":false,"turnInPlayEnabled":true,"persistenceEnabled":true,"marketBaseRate":5.0,"eventId":"30936519","eventTypeId":"2","numberOfWinners":1,"bettingType":"ODDS","marketType":"MATCH_ODDS","marketTime":"2021-09-24T13:54:00.000Z","suspendTime":"2021-09-24T13:54:00.000Z","bspReconciled":false,"complete":true,"inPlay":false,"crossMatching":true,"runnersVoidable":false,"numberOfActiveRunners":2,"betDelay":0,"status":"OPEN","runners":[{"status":"ACTIVE","sortPriority":1,"id":9454286,"name":"Antoine Escoffier"},{"status":"ACTIVE","sortPriority":2,"id":9631939,"name":"Marc-Andrea Huesler"}],"regulators":["MR_INT"],"countryCode":"CH","discountAllowed":true,"timezone":"UTC","openDate":"2021-09-24T13:54:00.000Z","version":4052775457,"name":"Match Odds","eventName":"Escoffier v Huesler"}}]}
{"op":"mcm","clk":"4289614818","pt":1632491636401,"mc":[{"id":"1.188075669","rc":[{"batl":[[0,1.49,6.46]],"ltp":1.48,"tv":546.88,"id":9631939},{"batl":[[0,3.25,27.86]],"ltp":3.0,"tv":188.23,"id":9454286}]}]}
{"op":"mcm","clk":"4289617571","pt":1632491678197,"mc":[{"id":"1.188075669","rc":[{"batb":[[0,1.45,17.38],[1,1.44,325.41]],"ltp":1.48,"tv":546.88,"id":9631939},{"batb":[[0,3,178.71]],"ltp":3.0,"tv":188.23,"id":9454286}]}]}
{"op":"mcm","clk":"4289621931","pt":1632491741384,"mc":[{"id":"1.188075669","rc":[{"trd":[[1.45,30.6]],"batb":[[0,1.45,7.37]],"ltp":1.45,"tv":566.88,"id":9631939}],"tv":755.12}]}
{"op":"mcm","clk":"4289622027","pt":1632491742898,"mc":[{"id":"1.188075669","rc":[{"trd":[[1.45,40.6]],"batb":[[0,1.45,2.37],[2,1.43,14.62]],"ltp":1.45,"tv":576.88,"id":9631939},{"batb":[[0,3.05,4.11],[1,3,178.71],[2,2.96,6.55]],"ltp":3.0,"tv":188.23,"id":9454286}],"tv":765.12}]}
{"op":"mcm","clk":"4289623348","pt":1632491762204,"mc":[{"id":"1.188075669","rc":[{"trd":[[1.45,45.88]],"batb":[[0,1.44,325.41],[1,1.43,14.62],[2,1.42,30.59]],"ltp":1.45,"tv":582.16,"id":9631939},{"trd":[[3.2,0.25]],"batl":[[0,3.25,27.61]],"ltp":3.2,"tv":188.48,"id":9454286}],"tv":770.65}]}
{"op":"mcm","clk":"4289624067","pt":1632491774021,"mc":[{"id":"1.188075669","rc":[{"batl":[[2,1.57,11.52]],"ltp":1.45,"tv":582.16,"id":9631939}]}]}
{"op":"mcm","clk":"4289624085","pt":1632491774231,"mc":[{"id":"1.188075669","rc":[{"batb":[[0,1.44,336.93]],"ltp":1.45,"tv":582.16,"id":9631939}]}]}
{"op":"mcm","clk":"4289624236","pt":1632491776558,"mc":[{"id":"1.188075669","rc":[{"batb":[[0,1.44,348.45]],"ltp":1.45,"tv":582.16,"id":9631939}]}]}
{"op":"mcm","clk":"4289624564","pt":1632491781547,"mc":[{"id":"1.188075669","rc":[{"batl":[[0,1.48,5.85],[1,1.49,6.46],[2,1.52,7.64]],"ltp":1.45,"tv":582.16,"id":9631939}]}]}
{"op":"mcm","clk":"4289624657","pt":1632491782633,"mc":[{"id":"1.188075669","rc":[{"batb":[[2,2.98,6.49]],"ltp":3.2,"tv":188.48,"id":9454286}]}]}
{"op":"mcm","clk":"4289625649","pt":1632491798274,"mc":[{"id":"1.188075669","rc":[{"trd":[[1.45,45.99]],"ltp":1.45,"tv":582.27,"id":9631939},{"trd":[[3.2,0.3]],"batl":[[0,3.25,27.56]],"ltp":3.2,"tv":188.53,"id":9454286}],"tv":770.81}]}
{"op":"mcm","clk":"4289627448","pt":1632491825150,"mc":[{"id":"1.188075669","marketDefinition":{"bspMarket":false,"turnInPlayEnabled":true,"persistenceEnabled":true,"marketBaseRate":5.0,"eventId":"30936519","eventTypeId":"2","numberOfWinners":1,"bettingType":"ODDS","marketType":"MATCH_ODDS","marketTime":"2021-09-24T13:53:00.000Z","suspendTime":"2021-09-24T13:53:00.000Z","bspReconciled":false,"complete":true,"inPlay":false,"crossMatching":true,"runnersVoidable":false,"numberOfActiveRunners":2,"betDelay":0,"status":"OPEN","runners":[{"status":"ACTIVE","sortPriority":1,"id":9454286,"name":"Antoine Escoffier"},{"status":"ACTIVE","sortPriority":2,"id":9631939,"name":"Marc-Andrea Huesler"}],"regulators":["MR_INT"],"countryCode":"CH","discountAllowed":true,"timezone":"UTC","openDate":"2021-09-24T13:54:00.000Z","version":4052780975,"name":"Match Odds","eventName":"Escoffier v Huesler"}}]}
{"op":"mcm","clk":"4289628439","pt":1632491840675,"mc":[{"id":"1.188075669","rc":[{"batl":[[0,3.15,30.31],[1,3.25,27.56],[2,46,29.91]],"ltp":3.2,"tv":188.53,"id":9454286}]}]}
{"op":"mcm","clk":"4289628495","pt":1632491841766,"mc":[{"id":"1.188075669","rc":[{"batb":[[2,2.96,6.55]],"ltp":3.2,"tv":188.53,"id":9454286}]}]}
{"op":"mcm","clk":"4289629551","pt":1632491856325,"mc":[{"id":"1.188075669","marketDefinition":{"bspMarket":false,"turnInPlayEnabled":true,"persistenceEnabled":true,"marketBaseRate":5.0,"eventId":"30936519","eventTypeId":"2","numberOfWinners":1,"bettingType":"ODDS","marketType":"MATCH_ODDS","marketTime":"2021-09-24T13:53:00.000Z","suspendTime":"2021-09-24T13:53:00.000Z","bspReconciled":false,"complete":true,"inPlay":false,"crossMatching":true,"runnersVoidable":false,"numberOfActiveRunners":2,"betDelay":0,"status":"OPEN","runners":[{"status":"ACTIVE","sortPriority":1,"id":9454286,"name":"Antoine Escoffier"},{"status":"ACTIVE","sortPriority":2,"id":9631939,"name":"Marc-Andrea Huesler"}],"regulators":["MR_INT"],"countryCode":"CH","discountAllowed":true,"timezone":"UTC","openDate":"2021-09-24T13:53:00.000Z","version":4052780975,"name":"Match Odds","eventName":"Escoffier v Huesler"}}]}
{"op":"mcm","clk":"4289630037","pt":1632491857807,"mc":[{"id":"1.188075669","rc":[{"trd":[[3.15,6.48]],"batb":[[0,3,173.28],[1,2.96,6.55],[2,2.88,2.65]],"batl":[[0,3.15,27.08]],"ltp":3.15,"tv":195.01,"id":9454286}],"tv":777.29}]}
{"op":"mcm","clk":"4289630101","pt":1632491858602,"mc":[{"id":"1.188075669","rc":[{"batb":[[0,1.45,7.62],[1,1.44,348.45],[2,1.43,29.88]],"ltp":1.45,"tv":582.27,"id":9631939},{"batb":[[0,3.05,6.86],[1,3,173.28],[2,2.96,6.55]],"ltp":3.15,"tv":195.01,"id":9454286}]}]}
{"op":"mcm","clk":"4289638269","pt":1632491970006,"mc":[{"id":"1.188075669","rc":[{"batb":[[0,3.1,1.17],[1,3.05,6.86],[2,3,173.28]],"ltp":3.15,"tv":195.01,"id":9454286}]}]}
{"op":"mcm","clk":"4289639125","pt":1632491983926,"mc":[{"id":"1.188075669","rc":[{"batb":[[0,1.44,348.45],[1,1.43,29.88],[2,1.42,30.59]],"ltp":1.45,"tv":582.27,"id":9631939},{"batb":[[1,3,176.28],[2,2.98,3]],"batl":[[2,3.5,3]],"ltp":3.15,"tv":195.01,"id":9454286}]}]}
{"op":"mcm","clk":"4289639165","pt":1632491984711,"mc":[{"id":"1.188075669","rc":[{"batb":[[1,1.41,31.35],[2,1.4,8]],"ltp":1.45,"tv":582.27,"id":9631939}]}]}
{"op":"mcm","clk":"4289639318","pt":1632491986717,"mc":[{"id":"1.188075669","rc":[{"trd":[[1.48,274.47]],"batl":[[0,1.48,5.15]],"ltp":1.48,"tv":583.68,"id":9631939}],"tv":778.69}]}
{"op":"mcm","clk":"4289639445","pt":1632491988520,"mc":[{"id":"1.188075669","rc":[{"batb":[[0,1.44,349.16]],"ltp":1.48,"tv":583.68,"id":9631939}]}]}
{"op":"mcm","clk":"4289643145","pt":1632492025899,"mc":[{"id":"1.188075669","rc":[{"trd":[[1.45,45.97],[1.46,13.03],[1.47,1.42],[1.48,274.15],[1.49,218.25],[1.5,10.27],[1.52,8.71],[1.54,8.24],[1.55,6]],"batb":[[0,1.44,347.89],[1,1.41,31.3],[2,1.39,6]],"batl":[[0,1.48,5.14],[1,1.49,6.46]],"ltp":1.46,"tv":586.03,"id":9631939},{"trd":[[2.74,25.66],[2.82,4.92],[3,20],[3.05,77.25],[3.15,7.22]],"batb":[[0,3.1,1.17],[1,3,175.98],[2,2.92,6.68]],"batl":[[0,3.15,26.28],[2,46,29.87]],"ltp":3.15,"tv":195.58,"id":9454286}],"tv":781.61}]}
{"op":"mcm","clk":"4289644922","pt":1632492046728,"mc":[{"id":"1.188075669","rc":[{"batb":[[0,1.44,320.11]],"ltp":1.46,"tv":586.03,"id":9631939}]}]}
{"op":"mcm","clk":"4289645501","pt":1632492053026,"mc":[{"id":"1.188075669","rc":[{"batb":[[0,1.46,11.1],[1,1.44,320.11],[2,1.41,31.3]],"ltp":1.46,"tv":586.03,"id":9631939}]}]}
{"op":"mcm","clk":"4289645544","pt":1632492053345,"mc":[{"id":"1.188075669","rc":[{"batl":[[2,4.2,8.22]],"ltp":3.15,"tv":195.58,"id":9454286}]}]}
{"op":"mcm","clk":"4289645992","pt":1632492059051,"mc":[{"id":"1.188075669","rc":[{"batb":[[0,1.46,27.4]],"ltp":1.46,"tv":586.03,"id":9631939}]}]}
{"op":"mcm","clk":"4289646790","pt":1632492067164,"mc":[{"id":"1.188075669","rc":[{"batl":[[0,3.25,27.56],[1,4.2,8.22],[2,46,28.96]],"ltp":3.15,"tv":195.58,"id":9454286}]}]}
{"op":"mcm","clk":"4289646847","pt":1632492067747,"mc":[{"id":"1.188075669","rc":[{"batb":[[2,1.43,29.84]],"ltp":1.46,"tv":586.03,"id":9631939},{"trd":[[3.1,112.56]],"batb":[[0,3,175.98],[1,2.92,6.68],[2,2.88,2.65]],"ltp":3.1,"tv":248.14,"id":9454286}],"tv":834.18}]}
{"op":"mcm","clk":"4289647108","pt":1632492070750,"mc":[{"id":"1.188075669","rc":[{"batb":[[0,1.44,320.11],[1,1.42,30.55],[2,1.41,31.3]],"ltp":1.46,"tv":586.03,"id":9631939},{"batb":[[1,2.96,6.54],[2,2.92,6.68]],"ltp":3.1,"tv":248.14,"id":9454286}]}]}
{"op":"mcm","clk":"4289647609","pt":1632492076362,"mc":[{"id":"1.188075669","rc":[{"batb":[[0,1.44,347.89]],"ltp":1.46,"tv":586.03,"id":9631939}]}]}
{"op":"mcm","clk":"4289648044","pt":1632492082187,"mc":[{"id":"1.188075669","rc":[{"batb":[[2,2.94,30.27]],"ltp":3.1,"tv":248.14,"id":9454286}]}]}
{"op":"mcm","clk":"4289648538","pt":1632492087183,"mc":[{"id":"1.188075669","rc":[{"batb":[[2,2.92,6.68]],"ltp":3.1,"tv":248.14,"id":9454286}]}]}
{"op":"mcm","clk":"4289648600","pt":1632492088100,"mc":[{"id":"1.188075669","rc":[{"batb":[[2,2.94,30.27]],"ltp":3.1,"tv":248.14,"id":9454286}]}]}
{"op":"mcm","clk":"4289648650","pt":1632492088797,"mc":[{"id":"1.188075669","rc":[{"batb":[[0,3,175.81]],"ltp":3.1,"tv":248.14,"id":9454286}]}]}
{"op":"mcm","clk":"4289649286","pt":1632492096717,"mc":[{"id":"1.188075669","rc":[{"batl":[[0,1.47,3.95],[1,1.48,5.14],[2,1.49,6.46]],"ltp":1.46,"tv":586.03,"id":9631939}]}]}
{"op":"mcm","clk":"4289649360","pt":1632492097815,"mc":[{"id":"1.188075669","rc":[{"batb":[[1,1.4,32.08],[2,1.39,6]],"ltp":1.46,"tv":586.03,"id":9631939}]}]}
{"op":"mcm","clk":"4289649526","pt":1632492100039,"mc":[{"id":"1.188075669","rc":[{"batb":[[2,2.92,36.95]],"ltp":3.1,"tv":248.14,"id":9454286}]}]}
{"op":"mcm","clk":"4289651404","pt":1632492122859,"mc":[{"id":"1.188075669","rc":[{"trd":[[1.47,2.59]],"batb":[[1,1.39,38.9],[2,1.38,2.65]],"batl":[[0,1.47,2.78]],"ltp":1.47,"tv":587.21,"id":9631939},{"trd":[[3.1,113.12]],"batl":[[0,3.25,27]],"ltp":3.1,"tv":248.7,"id":9454286}],"tv":835.91}]}
{"op":"mcm","clk":"4289655593","pt":1632492180169,"mc":[{"id":"1.188075669","rc":[{"trd":[[1.44,84.42]],"batb":[[0,1.44,305.68]],"ltp":1.44,"tv":671.63,"id":9631939}],"tv":920.33}]}
{"op":"mcm","clk":"4289655654","pt":1632492181076,"mc":[{"id":"1.188075669","rc":[{"batb":[[0,3,174.96]],"ltp":3.1,"tv":248.7,"id":9454286}]}]}
{"op":"mcm","clk":"4289658574","pt":1632492223072,"mc":[{"id":"1.188075669","rc":[{"batl":[[2,1.49,2]],"ltp":1.44,"tv":671.63,"id":9631939}]}]}
{"op":"mcm","clk":"4289659217","pt":1632492232059,"mc":[{"id":"1.188075669","rc":[{"trd":[[1.44,89.11]],"batb":[[0,1.44,303.33]],"ltp":1.44,"tv":676.32,"id":9631939}],"tv":925.02}]}
{"op":"mcm","clk":"4289664437","pt":1632492303223,"mc":[{"id":"1.188075669","marketDefinition":{"bspMarket":false,"turnInPlayEnabled":true,"persistenceEnabled":true,"marketBaseRate":5.0,"eventId":"30936519","eventTypeId":"2","numberOfWinners":1,"bettingType":"ODDS","marketType":"MATCH_ODDS","marketTime":"2021-09-24T13:53:00.000Z","suspendTime":"2021-09-24T13:53:00.000Z","bspReconciled":false,"complete":true,"inPlay":false,"crossMatching":true,"runnersVoidable":false,"numberOfActiveRunners":2,"betDelay":0,"status":"SUSPENDED","runners":[{"status":"ACTIVE","sortPriority":1,"id":9454286,"name":"Antoine Escoffier"},{"status":"ACTIVE","sortPriority":2,"id":9631939,"name":"Marc-Andrea Huesler"}],"regulators":["MR_INT"],"countryCode":"CH","discountAllowed":true,"timezone":"UTC","openDate":"2021-09-24T13:53:00.000Z","version":4052799718,"name":"Match Odds","eventName":"Escoffier v Huesler"}}]}
{"op":"mcm","clk":"4289664480","pt":1632492303465,"mc":[{"id":"1.188075669","marketDefinition":{"bspMarket":false,"turnInPlayEnabled":true,"persistenceEnabled":true,"marketBaseRate":5.0,"eventId":"30936519","eventTypeId":"2","numberOfWinners":1,"bettingType":"ODDS","marketType":"MATCH_ODDS","marketTime":"2021-09-24T13:53:00.000Z","suspendTime":"2021-09-24T13:53:00.000Z","bspReconciled":false,"complete":true,"inPlay":true,"crossMatching":true,"runnersVoidable":false,"numberOfActiveRunners":2,"betDelay":3,"status":"OPEN","runners":[{"status":"ACTIVE","sortPriority":1,"id":9454286,"name":"Antoine Escoffier"},{"status":"ACTIVE","sortPriority":2,"id":9631939,"name":"Marc-Andrea Huesler"}],"regulators":["MR_INT"],"countryCode":"CH","discountAllowed":true,"timezone":"UTC","openDate":"2021-09-24T13:53:00.000Z","version":4052799894,"name":"Match Odds","eventName":"Escoffier v Huesler"},"rc":[{"batb":[[0,1.35,7.3],[1,1.14,104.34],[2,1.01,617.41]],"batl":[[0,1.52,7.64],[1,1.8,9.49],[2,1.49,0]],"ltp":1.44,"tv":676.32,"id":9631939},{"batb":[[0,3,16.33],[1,2.92,30.27],[2,1.53,3.42]],"ltp":3.1,"tv":248.7,"id":9454286}]}]}
{"op":"mcm","clk":"4289664835","pt":1632492306935,"mc":[{"id":"1.188075669","rc":[{"batb":[[2,1.8,10.52]],"ltp":3.1,"tv":248.7,"id":9454286}]}]}
{"op":"mcm","clk":"4289665117","pt":1632492310131,"mc":[{"id":"1.188075669","rc":[{"trd":[[1.14,5.4],[1.35,14.6]],"batb":[[0,1.14,101.64],[1,1.03,438.16]],"ltp":1.14,"tv":696.33,"id":9631939}],"tv":945.03}]}
{"op":"mcm","clk":"4289665928","pt":1632492321183,"mc":[{"id":"1.188075669","rc":[{"trd":[[1.15,2.19]],"ltp":1.15,"tv":698.52,"id":9631939},{"trd":[[7.6,0.33]],"batl":[[0,3.7,4],[1,3.8,293.99]],"ltp":7.6,"tv":249.03,"id":9454286}],"tv":947.55}]}
{"op":"mcm","clk":"4289666165","pt":1632492324183,"mc":[{"id":"1.188075669","rc":[{"batl":[[0,1.15,14],[1,1.52,7.64],[2,1.8,9.49]],"ltp":1.15,"tv":698.52,"id":9631939},{"batl":[[0,8.2,2],[1,3.8,0]],"ltp":7.6,"tv":249.03,"id":9454286}]}]}
{"op":"mcm","clk":"4289666197","pt":1632492324554,"mc":[{"id":"1.188075669","rc":[{"trd":[[1.15,15.41]],"batb":[[0,1.05,420.63],[1,1.01,617.41],[2,1.01,0]],"batl":[[0,1.5,7]],"ltp":1.15,"tv":711.74,"id":9631939},{"trd":[[7.6,2.33]],"ltp":7.6,"tv":251.03,"id":9454286}],"tv":962.77}]}
{"op":"mcm","clk":"4289666440","pt":1632492327469,"mc":[{"id":"1.188075669","rc":[{"batb":[[2,2.2,43.09]],"ltp":7.6,"tv":251.03,"id":9454286}]}]}
{"op":"mcm","clk":"4289666837","pt":1632492332217,"mc":[{"id":"1.188075669","rc":[{"batb":[[0,1.46,14.92],[1,1.45,294.36],[2,1.05,420.63]],"batl":[[0,1.5,190.45]],"ltp":1.15,"tv":711.74,"id":9631939},{"batb":[[0,3.05,8.88],[1,3,108.05],[2,2.92,30.27]],"ltp":7.6,"tv":251.03,"id":9454286}]}]}
{"op":"mcm","clk":"4289666913","pt":1632492333009,"mc":[{"id":"1.188075669","rc":[{"batb":[[2,1.15,73.04]],"ltp":1.15,"tv":711.74,"id":9631939},{"batb":[[1,3,672.26]],"ltp":7.6,"tv":251.03,"id":9454286}]}]}
{"op":"mcm","clk":"4289666970","pt":1632492333802,"mc":[{"id":"1.188075669","rc":[{"trd":[[1.46,27.95]],"batb":[[0,1.45,294.36],[1,1.4,333.29],[2,1.38,361.21]],"batl":[[0,1.49,373.15],[1,1.5,190.45],[2,1.52,7.64]],"ltp":1.46,"tv":726.66,"id":9631939},{"trd":[[3.2,7.11]],"batb":[[0,3.2,128.33],[1,3.05,8.88],[2,3,108.05]],"ltp":3.2,"tv":257.83,"id":9454286}],"tv":984.49}]}
{"op":"mcm","clk":"4289667091","pt":1632492335207,"mc":[{"id":"1.188075669","rc":[{"batl":[[0,1.48,5],[1,1.49,379.15],[2,1.5,190.45]],"ltp":1.46,"tv":726.66,"id":9631939},{"batb":[[1,3.05,10.88],[2,3,110.05]],"batl":[[0,8,2],[1,8.2,2]],"ltp":3.2,"tv":257.83,"id":9454286}]}]}
{"op":"mcm","clk":"4289667328","pt":1632492338214,"mc":[{"id":"1.188075669","rc":[{"batl":[[0,5.8,177.94],[1,8,2],[2,8.2,2]],"ltp":3.2,"tv":257.83,"id":9454286}]}]}
{"op":"mcm","clk":"4289667371","pt":1632492338688,"mc":[{"id":"1.188075669","rc":[{"batl":[[0,8,2],[1,8.2,2],[2,8.2,0]],"ltp":3.2,"tv":257.83,"id":9454286}]}]}
{"op":"mcm","clk":"4289667578","pt":1632492341525,"mc":[{"id":"1.188075669","rc":[{"batl":[[0,6,175.67],[1,8,2],[2,8.2,2]],"ltp":3.2,"tv":257.83,"id":9454286}]}]}
{"op":"mcm","clk":"4289667727","pt":1632492343210,"mc":[{"id":"1.188075669","rc":[{"batb":[[0,1.38,360.7],[1,1.19,73.04],[2,1.17,73.04]],"batl":[[1,1.49,6],[2,1.5,7]],"ltp":1.46,"tv":726.66,"id":9631939},{"batb":[[0,3.05,2],[1,3,18.33],[2,2.94,166.43]],"batl":[[0,8,2],[1,8.2,2],[2,8.2,0]],"ltp":3.2,"tv":257.83,"id":9454286}]}]}
{"op":"mcm","clk":"4289667750","pt":1632492343526,"mc":[{"id":"1.188075669","rc":[{"batl":[[0,1.5,7],[1,1.52,7.64],[2,1.8,9.49]],"ltp":1.46,"tv":726.66,"id":9631939},{"batb":[[0,3,16.33],[1,2.94,166.43],[2,2.92,30.27]],"ltp":3.2,"tv":257.83,"id":9454286}]}]}
{"op":"mcm","clk":"4289667993","pt":1632492346732,"mc":[{"id":"1.188075669","rc":[{"batb":[[0,1.38,366.7],[1,1.37,7],[2,1.19,73.04]],"ltp":1.46,"tv":726.66,"id":9631939},{"batl":[[0,3.5,3],[1,3.65,2]],"ltp":3.2,"tv":257.83,"id":9454286}]}]}
{"op":"mcm","clk":"4289668229","pt":1632492350046,"mc":[{"id":"1.188075669","rc":[{"trd":[[1.41,27.3]],"batb":[[0,1.42,410.07],[1,1.38,366.7],[2,1.37,7]],"ltp":1.41,"tv":753.96,"id":9631939},{"trd":[[3.4,6.33]],"batb":[[0,3.25,4.76],[1,3.1,175.9],[2,3,16.33]],"batl":[[0,3.65,2],[1,3.65,0]],"ltp":3.4,"tv":264.16,"id":9454286}],"tv":1018.12}]}
{"op":"mcm","clk":"4289668311","pt":1632492351149,"mc":[{"id":"1.188075669","rc":[{"batl":[[0,1.49,757.84],[1,1.5,7],[2,1.52,7.64]],"ltp":1.41,"tv":753.96,"id":9631939},{"batb":[[0,3.3,121.81],[1,3.25,4.76],[2,3.1,320.23]],"batl":[[1,4,7.5]],"ltp":3.4,"tv":264.16,"id":9454286}]}]}
{"op":"mcm","clk":"4289668490","pt":1632492353152,"mc":[{"id":"1.188075669","rc":[{"batl":[[0,1.49,764.84]],"ltp":1.41,"tv":753.96,"id":9631939}]}]}
{"op":"mcm","clk":"4289668729","pt":1632492355726,"mc":[{"id":"1.188075669","rc":[{"batl":[[0,1.49,7]],"ltp":1.41,"tv":753.96,"id":9631939}]}]}
{"op":"mcm","clk":"4289668778","pt":1632492356255,"mc":[{"id":"1.188075669","rc":[{"trd":[[1.42,0.34]],"batb":[[0,1.42,409.9]],"ltp":1.42,"tv":754.3,"id":9631939}],"tv":1018.46}]}
{"op":"mcm","clk":"4289669005","pt":1632492358882,"mc":[{"id":"1.188075669","rc":[{"batb":[[2,1.36,383.23]],"batl":[[0,1.49,785.22]],"ltp":1.42,"tv":754.3,"id":9631939}]}]}
{"op":"mcm","clk":"4289669131","pt":1632492360145,"mc":[{"id":"1.188075669","rc":[{"batb":[[0,1.38,6],[1,1.36,383.23],[2,1.19,73.04]],"batl":[[0,1.49,7]],"ltp":1.42,"tv":754.3,"id":9631939},{"batb":[[0,3.1,144.33],[1,3.05,3],[2,3,19.33]],"batl":[[1,4,0]],"ltp":3.4,"tv":264.16,"id":9454286}]}]}
{"op":"mcm","clk":"4289669356","pt":1632492362842,"mc":[{"id":"1.188075669","rc":[{"batl":[[0,3.6,3],[1,3.65,2]],"ltp":3.4,"tv":264.16,"id":9454286}]}]}
{"op":"mcm","clk":"4289669403","pt":1632492363437,"mc":[{"id":"1.188075669","rc":[{"batb":[[1,1.37,7],[2,1.36,383.23]],"batl":[[0,1.48,6],[1,1.49,7],[2,1.5,7]],"ltp":1.42,"tv":754.3,"id":9631939},{"batb":[[0,3.1,147.33]],"ltp":3.4,"tv":264.16,"id":9454286}]}]}
{"op":"mcm","clk":"4289669613","pt":1632492366166,"mc":[{"id":"1.188075669","rc":[{"trd":[[3.1,114.74]],"batb":[[0,3.1,146.52]],"ltp":3.1,"tv":265.78,"id":9454286}],"tv":1020.09}]}
{"op":"mcm","clk":"4289669628","pt":1632492366332,"mc":[{"id":"1.188075669","rc":[{"batl":[[1,1.52,7.64],[2,1.8,9.49]],"ltp":1.42,"tv":754.3,"id":9631939},{"batb":[[1,3,16.33],[2,2.92,30.27]],"ltp":3.1,"tv":265.78,"id":9454286}]}]}
{"op":"mcm","clk":"4289669856","pt":1632492369542,"mc":[{"id":"1.188075669","rc":[{"batb":[[1,3.05,3],[2,3,16.33]],"ltp":3.1,"tv":265.78,"id":9454286}]}]}
{"op":"mcm","clk":"4289669942","pt":1632492370540,"mc":[{"id":"1.188075669","rc":[{"batl":[[0,1.47,308.79],[1,1.48,198.21],[2,1.52,7.64]],"ltp":1.42,"tv":754.3,"id":9631939}]}]}
{"op":"mcm","clk":"4289670048","pt":1632492372059,"mc":[{"id":"1.188075669","rc":[{"batb":[[0,1.43,211.77],[1,1.42,233.57],[2,1.41,1578.62]],"batl":[[1,1.48,192.21]],"ltp":1.42,"tv":754.3,"id":9631939},{"batb":[[0,3.1,148.79],[1,3,16.33],[2,2.92,188.3]],"batl":[[0,3.2,7.26],[1,3.6,3],[2,3.65,2]],"ltp":3.1,"tv":265.78,"id":9454286}]}]}
{"op":"mcm","clk":"4289670145","pt":1632492373165,"mc":[{"id":"1.188075669","rc":[{"trd":[[1.45,61.99]],"batb":[[1,1.42,550.32]],"batl":[[0,1.44,4.81],[1,1.47,308.79],[2,1.48,192.21]],"ltp":1.45,"tv":770.32,"id":9631939},{"trd":[[3.2,14.37]],"batb":[[2,2.94,159.86]],"batl":[[0,3.55,157.29]],"ltp":3.2,"tv":273.04,"id":9454286}],"tv":1043.37}]}
{"op":"mcm","clk":"4289670207","pt":1632492374063,"mc":[{"id":"1.188075669","rc":[{"batl":[[0,3.6,3],[1,3.65,2],[2,3.8,131.57]],"ltp":3.2,"tv":273.04,"id":9454286}]}]}
{"op":"mcm","clk":"4289670295","pt":1632492375172,"mc":[{"id":"1.188075669","rc":[{"batb":[[1,1.42,556.32],[2,1.41,1586.62]],"ltp":1.45,"tv":770.32,"id":9631939},{"batl":[[1,3.8,131.57],[2,3.85,61.84]],"ltp":3.2,"tv":273.04,"id":9454286}]}]}
{"op":"mcm","clk":"4289670915","pt":1632492382961,"mc":[{"id":"1.188075669","rc":[{"batb":[[0,1.43,319.77]],"ltp":1.45,"tv":770.32,"id":9631939},{"batb":[[0,3.1,143.52]],"batl":[[0,3.6,262.96]],"ltp":3.2,"tv":273.04,"id":9454286}]}]}
{"op":"mcm","clk":"4289671199","pt":1632492386094,"mc":[{"id":"1.188075669","rc":[{"trd":[[1.44,93.92]],"batb":[[0,1.43,476.77]],"batl":[[0,1.47,308.79],[1,1.48,192.21],[2,1.52,7.64]],"ltp":1.44,"tv":775.13,"id":9631939},{"trd":[[3.25,2.13]],"batb":[[0,3.15,6.23],[1,3.1,143.52],[2,3,16.33]],"batl":[[0,3.25,3.83],[1,3.6,3],[2,3.8,131.57]],"ltp":3.25,"tv":275.17,"id":9454286}],"tv":1050.31}]}
{"op":"mcm","clk":"4289671216","pt":1632492386270,"mc":[{"id":"1.188075669","rc":[{"batb":[[2,1.41,1578.62]],"ltp":1.44,"tv":775.13,"id":9631939}]}]}
{"op":"mcm","clk":"4289671379","pt":1632492388106,"mc":[{"id":"1.188075669","rc":[{"batb":[[0,1.43,265],[1,1.42,322.75],[2,1.39,345.1]],"batl":[[0,1.52,7.64],[1,1.8,9.49],[2,1.52,0]],"ltp":1.44,"tv":775.13,"id":9631939},{"batb":[[0,3.1,143.52],[1,3,16.33],[2,2.92,30.27]],"batl":[[0,3.6,3],[1,3.6,0],[2,3.8,0]],"ltp":3.25,"tv":275.17,"id":9454286}]}]}
{"op":"mcm","clk":"4289671454","pt":1632492388998,"mc":[{"id":"1.188075669","rc":[{"batb":[[0,1.39,345.1],[1,1.19,73.04],[2,1.17,73.04]],"ltp":1.44,"tv":775.13,"id":9631939},{"batb":[[0,3,16.33],[1,2.92,30.27],[2,2.86,71.79]],"ltp":3.25,"tv":275.17,"id":9454286}]}]}
{"op":"mcm","clk":"4289671602","pt":1632492390999,"mc":[{"id":"1.188075669","rc":[{"batb":[[0,1.4,251.55],[1,1.39,602.69],[2,1.19,73.04]],"batl":[[1,1.53,210.32],[2,1.54,165.11]],"ltp":1.44,"tv":775.13,"id":9631939}]}]}
{"op":"mcm","clk":"4289671713","pt":1632492392215,"mc":[{"id":"1.188075669","rc":[{"batb":[[1,1.39,608.69],[2,1.38,6]],"batl":[[0,1.51,7],[1,1.52,7.64],[2,1.8,9.49]],"ltp":1.44,"tv":775.13,"id":9631939}]}]}
{"op":"mcm","clk":"4289671885","pt":1632492394192,"mc":[{"id":"1.188075669","rc":[{"batb":[[0,1.4,258.55]],"ltp":1.44,"tv":775.13,"id":9631939},{"batl":[[0,3.5,2],[1,3.6,3]],"ltp":3.25,"tv":275.17,"id":9454286}]}]}
{"op":"mcm","clk":"4289671974","pt":1632492395199,"mc":[{"id":"1.188075669","rc":[{"trd":[[1.41,48.58]],"batb":[[0,1.4,251.55],[2,1.38,698.94]],"batl":[[0,1.44,2707.1],[1,1.45,868.24],[2,1.46,640.08]],"ltp":1.41,"tv":796.41,"id":9631939},{"trd":[[3.3,12.52],[3.4,15.15]],"batb":[[0,3.05,139.44],[1,3,16.33],[2,2.92,30.27]],"batl":[[0,3.3,152.6],[1,3.4,4.69],[2,3.6,3]],"ltp":3.3,"tv":296.51,"id":9454286}],"tv":1092.93}]}
{"op":"mcm","clk":"4289672062","pt":1632492396092,"mc":[{"id":"1.188075669","rc":[{"batl":[[0,1.44,529.61]],"ltp":1.41,"tv":796.41,"id":9631939},{"batb":[[0,3.25,129.06],[1,3.05,289.68],[2,3,16.33]],"batl":[[1,3.6,3],[2,4,7.5]],"ltp":3.3,"tv":296.51,"id":9454286}]}]}
{"op":"mcm","clk":"4289672234","pt":1632492397998,"mc":[{"id":"1.188075669","rc":[{"batb":[[1,3.05,291.68],[2,3,18.33]],"batl":[[1,3.55,3],[2,3.6,3]],"ltp":3.3,"tv":296.51,"id":9454286}]}]}
{"op":"mcm","clk":"4289672319","pt":1632492398988,"mc":[{"id":"1.188075669","rc":[{"batb":[[0,3.25,134.81]],"batl":[[1,3.35,5.5],[2,3.55,3]],"ltp":3.3,"tv":296.51,"id":9454286}]}]}
{"op":"mcm","clk":"4289672401","pt":1632492399994,"mc":[{"id":"1.188075669","rc":[{"trd":[[1.44,473.74]],"batl":[[0,1.44,339.7]],"ltp":1.44,"tv":1176.23,"id":9631939}],"tv":1472.75}]}
{"op":"mcm","clk":"4289672586","pt":1632492402101,"mc":[{"id":"1.188075669","rc":[{"batb":[[0,1.43,133],[1,1.4,251.55],[2,1.39,608.69]],"ltp":1.44,"tv":1176.23,"id":9631939}]}]}
{"op":"mcm","clk":"4289672827","pt":1632492405140,"mc":[{"id":"1.188075669","rc":[{"batb":[[0,1.43,274]],"ltp":1.44,"tv":1176.23,"id":9631939},{"batb":[[0,3.25,129.06]],"batl":[[1,3.55,3],[2,3.6,3]],"ltp":3.3,"tv":296.51,"id":9454286}]}]}
{"op":"mcm","clk":"4289672994","pt":1632492407033,"mc":[{"id":"1.188075669","rc":[{"batb":[[0,1.39,6],[1,1.37,368.3],[2,1.19,73.04]],"batl":[[0,1.49,7],[1,1.51,7],[2,1.52,7.64]],"ltp":1.44,"tv":1176.23,"id":9631939},{"batb":[[0,3.05,152.24],[1,3,18.33],[2,2.92,30.27]],"batl":[[0,3.55,3],[1,3.6,3],[2,3.6,0]],"ltp":3.3,"tv":296.51,"id":9454286}]}]}
{"op":"mcm","clk":"4289673142","pt":1632492408715,"mc":[{"id":"1.188075669","rc":[{"batl":[[0,1.41,3.63],[1,1.49,7],[2,1.51,7]],"ltp":1.44,"tv":1176.23,"id":9631939}]}]}
{"op":"mcm","clk":"4289673255","pt":1632492410131,"mc":[{"id":"1.188075669","rc":[{"batb":[[1,1.38,359.24],[2,1.37,645.13]],"batl":[[1,1.47,195.09],[2,1.48,193.05]],"ltp":1.44,"tv":1176.23,"id":9631939},{"batb":[[1,3,16.33]],"batl":[[1,3.6,0]],"ltp":3.3,"tv":296.51,"id":9454286}]}]}
{"op":"mcm","clk":"4289673321","pt":1632492410834,"mc":[{"id":"1.188075669","rc":[{"batb":[[1,1.38,366.24]],"batl":[[1,1.49,7],[2,1.52,7.64]],"ltp":1.44,"tv":1176.23,"id":9631939}]}]}
{"op":"mcm","clk":"4289673510","pt":1632492413027,"mc":[{"id":"1.188075669","rc":[{"batb":[[0,3.1,3],[1,3.05,152.24],[2,3,16.33]],"ltp":3.3,"tv":296.51,"id":9454286}]}]}
{"op":"mcm","clk":"4289673600","pt":1632492414139,"mc":[{"id":"1.188075669","rc":[{"trd":[[1.4,42.86],[1.41,55.84],[1.42,607.42]],"batb":[[0,1.41,12.06]],"batl":[[0,1.42,488.92],[1,1.43,238.25],[2,1.47,354.07]],"ltp":1.42,"tv":1833.42,"id":9631939},{"batb":[[0,3.35,285.44],[1,3.3,277.04],[2,3.25,277.04]],"ltp":3.3,"tv":296.51,"id":9454286}],"tv":2129.94}]}
{"op":"mcm","clk":"4289673646","pt":1632492414731,"mc":[{"id":"1.188075669","rc":[{"batb":[[0,3.35,403.88]],"batl":[[0,4.1,7.32]],"ltp":3.3,"tv":296.51,"id":9454286}]}]}
{"op":"mcm","clk":"4289673842","pt":1632492416936,"mc":[{"id":"1.188075669","rc":[{"trd":[[1.42,1585.26]],"batl":[[0,1.43,238.25],[1,1.47,354.07],[2,1.49,7]],"ltp":1.42,"tv":2811.26,"id":9631939},{"batb":[[2,3.25,280.04]],"ltp":3.3,"tv":296.51,"id":9454286}],"tv":3107.78}]}
{"op":"mcm","clk":"4289673911","pt":1632492417930,"mc":[{"id":"1.188075669","rc":[{"batb":[[0,1.41,284.06],[1,1.38,271.59],[2,1.37,368.3]],"ltp":1.42,"tv":2811.26,"id":9631939}]}]}
{"op":"mcm","clk":"4289674140","pt":1632492420938,"mc":[{"id":"1.188075669","rc":[{"batb":[[0,1.41,443.06],[1,1.39,260.53],[2,1.38,271.59]],"batl":[[0,1.43,369.29],[1,1.44,213.17],[2,1.47,354.07]],"ltp":1.42,"tv":2811.26,"id":9631939}]}]}
{"op":"mcm","clk":"4289674520","pt":1632492425153,"mc":[{"id":"1.188075669","rc":[{"batb":[[0,1.41,467.01]],"ltp":1.42,"tv":2811.26,"id":9631939},{"batb":[[2,3.25,277.04]],"batl":[[0,4,607.31],[1,4.1,7.32]],"ltp":3.3,"tv":296.51,"id":9454286}]}]}
{"op":"mcm","clk":"4289674575","pt":1632492425843,"mc":[{"id":"1.188075669","rc":[{"trd":[[1.43,256.62]],"batl":[[0,1.43,240.98]],"ltp":1.43,"tv":3067.89,"id":9631939}],"tv":3364.41}]}
{"op":"mcm","clk":"4289674818","pt":1632492428948,"mc":[{"id":"1.188075669","rc":[{"batb":[[1,1.39,324.13]],"batl":[[0,1.43,291.01]],"ltp":1.43,"tv":3067.89,"id":9631939}]}]}
{"op":"mcm","clk":"4289675071","pt":1632492432452,"mc":[{"id":"1.188075669","rc":[{"batb":[[0,1.41,443.06]],"ltp":1.43,"tv":3067.89,"id":9631939}]}]}
{"op":"mcm","clk":"4289675260","pt":1632492435691,"mc":[{"id":"1.188075669","rc":[{"trd":[[1.43,304.53]],"batb":[[0,1.41,431]],"batl":[[0,1.43,267.06]],"ltp":1.43,"tv":3115.79,"id":9631939}],"tv":3412.31}]}
{"op":"mcm","clk":"4289675416","pt":1632492438570,"mc":[{"id":"1.188075669","rc":[{"batb":[[0,1.42,14.06],[1,1.41,431],[2,1.39,324.13]],"batl":[[1,1.44,226.59]],"ltp":1.43,"tv":3115.79,"id":9631939}]}]}
{"op":"mcm","clk":"4289675774","pt":1632492443870,"mc":[{"id":"1.188075669","rc":[{"trd":[[1.41,175.72],[1.42,1613.38]],"batb":[[0,1.41,371.06],[1,1.39,324.13],[2,1.38,271.59]],"ltp":1.41,"tv":3263.79,"id":9631939}],"tv":3560.31}]}
{"op":"mcm","clk":"4289675874","pt":1632492445172,"mc":[{"id":"1.188075669","rc":[{"trd":[[1.41,179.14]],"batb":[[0,1.41,369.35]],"ltp":1.41,"tv":3267.21,"id":9631939}],"tv":3563.73}]}
{"op":"mcm","clk":"4289676040","pt":1632492447890,"mc":[{"id":"1.188075669","rc":[{"batb":[[0,1.41,581.29]],"ltp":1.41,"tv":3267.21,"id":9631939}]}]}
{"op":"mcm","clk":"4289676216","pt":1632492450699,"mc":[{"id":"1.188075669","rc":[{"batb":[[1,1.38,7],[2,1.37,368.3]],"batl":[[0,1.44,13.42],[1,1.47,354.07],[2,1.49,7]],"ltp":1.41,"tv":3267.21,"id":9631939}]}]}
{"op":"mcm","clk":"4289676480","pt":1632492454093,"mc":[{"id":"1.188075669","rc":[{"batl":[[0,1.47,685.99],[1,1.48,189.94]],"ltp":1.41,"tv":3267.21,"id":9631939}]}]}
{"op":"mcm","clk":"4289676698","pt":1632492457219,"mc":[{"id":"1.188075669","rc":[{"batl":[[0,1.47,2852.38]],"ltp":1.41,"tv":3267.21,"id":9631939},{"batl":[[1,4.1,0]],"ltp":3.3,"tv":296.51,"id":9454286}]}]}
{"op":"mcm","clk":"4289676750","pt":1632492457904,"mc":[{"id":"1.188075669","rc":[{"batb":[[0,1.34,371.32],[1,1.33,317.24],[2,1.32,443.37]],"batl":[[0,1.47,331.92]],"ltp":1.41,"tv":3267.21,"id":9631939},{"batb":[[0,3.15,135.9],[1,3,16.33],[2,2.92,30.27]],"ltp":3.3,"tv":296.51,"id":9454286}]}]}
{"op":"mcm","clk":"4289676812","pt":1632492458706,"mc":[{"id":"1.188075669","rc":[{"batl":[[2,1.49,11.46]],"ltp":1.41,"tv":3267.21,"id":9631939}]}]}
{"op":"mcm","clk":"4289676983","pt":1632492461124,"mc":[{"id":"1.188075669","rc":[{"batb":[[0,1.34,378.32],[1,1.33,325.24]],"batl":[[0,1.47,336.92]],"ltp":1.41,"tv":3267.21,"id":9631939},{"batb":[[0,3.15,138.9],[1,3.1,3],[2,3,16.33]],"batl":[[0,3.95,3]],"ltp":3.3,"tv":296.51,"id":9454286}]}]}
{"op":"mcm","clk":"4289676989","pt":1632492461232,"mc":[{"id":"1.188075669","rc":[{"batb":[[0,1.34,7],[1,1.33,8]],"batl":[[0,1.47,5],[1,1.49,11.46],[2,1.52,7.64]],"ltp":1.41,"tv":3267.21,"id":9631939}]}]}
{"op":"mcm","clk":"4289677199","pt":1632492464134,"mc":[{"id":"1.188075669","rc":[{"batb":[[0,1.38,336.07],[1,1.37,273.84],[2,1.34,7]],"batl":[[0,1.42,306.65],[1,1.43,219.3],[2,1.47,5]],"ltp":1.41,"tv":3267.21,"id":9631939}]}]}
{"op":"mcm","clk":"4289677252","pt":1632492464923,"mc":[{"id":"1.188075669","rc":[{"trd":[[1.38,4.38]],"batb":[[0,1.38,333.88]],"ltp":1.38,"tv":3271.59,"id":9631939}],"tv":3568.11}]}
{"op":"mcm","clk":"4289677285","pt":1632492465444,"mc":[{"id":"1.188075669","rc":[{"batb":[[0,1.34,7],[1,1.33,8],[2,1.32,443.37]],"batl":[[0,1.47,5],[1,1.49,11.46],[2,1.52,7.64]],"ltp":1.38,"tv":3271.59,"id":9631939}]}]}
{"op":"mcm","clk":"4289677395","pt":1632492466717,"mc":[{"id":"1.188075669","rc":[{"batl":[[0,1.45,2.19],[1,1.47,5],[2,1.49,11.46]],"ltp":1.38,"tv":3271.59,"id":9631939}]}]}
{"op":"mcm","clk":"4289677495","pt":1632492467924,"mc":[{"id":"1.188075669","rc":[{"batb":[[0,1.39,128],[1,1.34,7],[2,1.33,8]],"ltp":1.38,"tv":3271.59,"id":9631939}]}]}
{"op":"mcm","clk":"4289677512","pt":1632492468234,"mc":[{"id":"1.188075669","rc":[{"batb":[[0,1.34,7],[1,1.33,8],[2,1.32,443.37]],"ltp":1.38,"tv":3271.59,"id":9631939}]}]}
{"op":"mcm","clk":"4289677671","pt":1632492470027,"mc":[{"id":"1.188075669","rc":[{"batl":[[1,1.47,333.06],[2,1.48,189.95]],"ltp":1.38,"tv":3271.59,"id":9631939},{"batb":[[0,3.15,135.9],[1,3,16.33],[2,2.92,30.27]],"ltp":3.3,"tv":296.51,"id":9454286}]}]}
{"op":"mcm","clk":"4289677747","pt":1632492471132,"mc":[{"id":"1.188075669","rc":[{"batb":[[0,1.43,176.88],[1,1.42,230.87],[2,1.4,612.39]],"ltp":1.38,"tv":3271.59,"id":9631939},{"batb":[[0,3.15,142.74],[1,3,141.09]],"batl":[[0,3.25,5.27],[1,3.3,310.06],[2,3.35,71.22]],"ltp":3.3,"tv":296.51,"id":9454286}]}]}
{"op":"mcm","clk":"4289677810","pt":1632492471858,"mc":[{"id":"1.188075669","rc":[{"trd":[[1.43,322.71],[1.44,485.63]],"batb":[[0,1.43,167.79],[2,1.41,331.77]],"ltp":1.43,"tv":3301.66,"id":9631939},{"trd":[[3.25,7.4]],"batb":[[1,3,294.87]],"batl":[[0,3.3,310.06],[1,3.35,71.22],[2,3.4,71.22]],"ltp":3.25,"tv":301.78,"id":9454286}],"tv":3603.45}]}
{"op":"mcm","clk":"4289677897","pt":1632492472956,"mc":[{"id":"1.188075669","rc":[{"batl":[[1,1.47,196.86],[2,1.49,326.9]],"ltp":1.43,"tv":3301.66,"id":9631939}]}]}
{"op":"mcm","clk":"4289678076","pt":1632492475025,"mc":[{"id":"1.188075669","rc":[{"batb":[[0,1.43,281.79]],"batl":[[1,1.46,142],[2,1.47,196.86]],"ltp":1.43,"tv":3301.66,"id":9631939}]}]}
{"op":"mcm","clk":"4289678335","pt":1632492478131,"mc":[{"id":"1.188075669","rc":[{"batb":[[0,1.43,392.79]],"ltp":1.43,"tv":3301.66,"id":9631939}]}]}
{"op":"mcm","clk":"4289678509","pt":1632492480136,"mc":[{"id":"1.188075669","rc":[{"trd":[[1.45,66.11]],"batl":[[0,1.46,142.13],[1,1.47,196.86],[2,1.49,326.9]],"ltp":1.45,"tv":3305.78,"id":9631939}],"tv":3607.57}]}
{"op":"mcm","clk":"4289678637","pt":1632492481777,"mc":[{"id":"1.188075669","rc":[{"batb":[[0,3.15,135.9]],"ltp":3.25,"tv":301.78,"id":9454286}]}]}
{"op":"mcm","clk":"4289678834","pt":1632492484089,"mc":[{"id":"1.188075669","rc":[{"trd":[[1.45,66.24]],"batl":[[0,1.46,142]],"ltp":1.45,"tv":3305.91,"id":9631939},{"trd":[[3.15,7.29],[3.2,14.43]],"batb":[[0,3.15,135.86]],"ltp":3.15,"tv":301.91,"id":9454286}],"tv":3607.83}]}
{"op":"mcm","clk":"4289678884","pt":1632492484682,"mc":[{"id":"1.188075669","rc":[{"batb":[[0,3.2,5.99],[1,3.15,135.86],[2,3,294.87]],"batl":[[0,3.3,315.8]],"ltp":3.15,"tv":301.91,"id":9454286}]}]}
{"op":"mcm","clk":"4289678978","pt":1632492485958,"mc":[{"id":"1.188075669","rc":[{"batb":[[0,1.36,388.71],[1,1.35,3],[2,1.19,73.04]],"batl":[[0,1.49,11.46],[1,1.52,7.64],[2,1.8,9.49]],"ltp":1.45,"tv":3305.91,"id":9631939},{"batb":[[0,3,170.11],[1,2.92,30.27],[2,2,10.52]],"batl":[[0,3.9,2],[1,3.35,0],[2,3.4,0]],"ltp":3.15,"tv":301.91,"id":9454286}]}]}
{"op":"mcm","clk":"4289679242","pt":1632492489179,"mc":[{"id":"1.188075669","rc":[{"batb":[[0,1.38,287.63],[1,1.37,273.33],[2,1.36,397.71]],"batl":[[1,1.5,278.77],[2,1.51,175.84]],"ltp":1.45,"tv":3305.91,"id":9631939},{"batb":[[0,3,173.11],[1,2.98,4],[2,2.92,30.27]],"batl":[[0,3.55,3],[1,3.8,3],[2,3.9,2]],"ltp":3.15,"tv":301.91,"id":9454286}]}]}
{"op":"mcm","clk":"4289679283","pt":1632492489860,"mc":[{"id":"1.188075669","rc":[{"batb":[[0,1.36,397.71],[1,1.35,3],[2,1.19,73.04]],"ltp":1.45,"tv":3305.91,"id":9631939}]}]}
{"op":"mcm","clk":"4289679449","pt":1632492492076,"mc":[{"id":"1.188075669","rc":[{"batb":[[0,1.39,7],[1,1.38,8],[2,1.37,8]],"batl":[[0,1.49,4.46]],"ltp":1.45,"tv":3305.91,"id":9631939},{"batb":[[0,3,170.11],[1,2.92,30.27],[2,2,10.52]],"ltp":3.15,"tv":301.91,"id":9454286}]}]}
{"op":"mcm","clk":"4289679515","pt":1632492492872,"mc":[{"id":"1.188075669","rc":[{"batb":[[0,1.46,187.64],[1,1.45,491.36],[2,1.43,1135.34]],"ltp":1.45,"tv":3305.91,"id":9631939},{"batb":[[0,3.05,8.66],[1,3,170.11],[2,2.92,30.27]],"batl":[[0,3.25,294.22],[1,3.3,285.58],[2,3.35,285.58]],"ltp":3.15,"tv":301.91,"id":9454286}]}]}
{"op":"mcm","clk":"4289679613","pt":1632492493879,"mc":[{"id":"1.188075669","rc":[{"trd":[[1.46,69.33]],"batb":[[0,1.46,166.95],[2,1.44,301.49]],"ltp":1.46,"tv":3347.29,"id":9631939},{"batb":[[2,2.92,98.18]],"ltp":3.15,"tv":301.91,"id":9454286}],"tv":3649.21}]}
{"op":"mcm","clk":"4289679759","pt":1632492495885,"mc":[{"id":"1.188075669","rc":[{"batb":[[0,1.46,243.95]],"ltp":1.46,"tv":3347.29,"id":9631939}]}]}
{"op":"mcm","clk":"4289680427","pt":1632492503797,"mc":[{"id":"1.188075669","rc":[{"batb":[[0,3,170.11],[1,2.92,98.18],[2,2,10.52]],"ltp":3.15,"tv":301.91,"id":9454286}]}]}
{"op":"mcm","clk":"4289680477","pt":1632492504488,"mc":[{"id":"1.188075669","rc":[{"batb":[[1,1.45,210.88]],"ltp":1.46,"tv":3347.29,"id":9631939}]}]}
{"op":"mcm","clk":"4289680646","pt":1632492506492,"mc":[{"id":"1.188075669","rc":[{"batb":[[1,1.45,224.05]],"batl":[[0,1.47,12.61],[1,1.49,4.46],[2,1.5,278.77]],"ltp":1.46,"tv":3347.29,"id":9631939}]}]}
{"op":"mcm","clk":"4289680900","pt":1632492509708,"mc":[{"id":"1.188075669","rc":[{"batb":[[1,1.45,246.41]],"ltp":1.46,"tv":3347.29,"id":9631939},{"batb":[[2,2.84,8.15]],"batl":[[0,3.25,304.22]],"ltp":3.15,"tv":301.91,"id":9454286}]}]}
{"op":"mcm","clk":"4289681178","pt":1632492513019,"mc":[{"id":"1.188075669","rc":[{"batb":[[0,1.46,432.95]],"ltp":1.46,"tv":3347.29,"id":9631939}]}]}
{"op":"mcm","clk":"4289681276","pt":1632492514129,"mc":[{"id":"1.188075669","rc":[{"batb":[[1,1.45,233.24]],"batl":[[0,1.49,4.46],[1,1.5,278.77],[2,1.51,175.84]],"ltp":1.46,"tv":3347.29,"id":9631939},{"batl":[[0,3.25,157.11],[1,3.3,142.79],[2,3.35,142.79]],"ltp":3.15,"tv":301.91,"id":9454286}]}]}
{"op":"mcm","clk":"4289681362","pt":1632492515017,"mc":[{"id":"1.188075669","rc":[{"batb":[[0,1.45,22.36],[1,1.4,349.39],[2,1.19,73.04]],"batl":[[1,1.52,7.64],[2,1.54,15]],"ltp":1.46,"tv":3347.29,"id":9631939},{"batb":[[0,3,16.33]],"batl":[[0,3.25,10],[1,3.5,3],[2,3.35,0]],"ltp":3.15,"tv":301.91,"id":9454286}]}]}
{"op":"mcm","clk":"4289681381","pt":1632492515330,"mc":[{"id":"1.188075669","rc":[{"batb":[[0,1.4,349.39],[1,1.19,73.04],[2,1.17,73.04]],"batl":[[2,1.8,9.49]],"ltp":1.46,"tv":3347.29,"id":9631939},{"batb":[[2,2,10.52]],"batl":[[0,3.5,3],[1,3.5,0]],"ltp":3.15,"tv":301.91,"id":9454286}]}]}
{"op":"mcm","clk":"4289681455","pt":1632492516227,"mc":[{"id":"1.188075669","rc":[{"batb":[[1,2.94,4],[2,2.92,101.18]],"ltp":3.15,"tv":301.91,"id":9454286}]}]}
{"op":"mcm","clk":"4289681578","pt":1632492517757,"mc":[{"id":"1.188075669","rc":[{"batb":[[0,1.42,239.66],[1,1.41,238.9],[2,1.4,349.39]],"batl":[[0,1.49,10.46],[1,1.52,185.4],[2,1.53,167.77]],"ltp":1.46,"tv":3347.29,"id":9631939},{"batb":[[0,3,19.33],[1,2.98,4],[2,2.94,4]],"ltp":3.15,"tv":301.91,"id":9454286}]}]}
{"op":"mcm","clk":"4289681745","pt":1632492519723,"mc":[{"id":"1.188075669","rc":[{"batb":[[0,1.4,349.39],[1,1.39,4],[2,1.19,73.04]],"ltp":1.46,"tv":3347.29,"id":9631939}]}]}
{"op":"mcm","clk":"4289681810","pt":1632492520553,"mc":[{"id":"1.188075669","rc":[{"batb":[[0,1.42,5],[1,1.41,6],[2,1.4,349.39]],"ltp":1.46,"tv":3347.29,"id":9631939},{"batl":[[0,3.4,3],[1,3.5,3]],"ltp":3.15,"tv":301.91,"id":9454286}]}]}
{"op":"mcm","clk":"4289681938","pt":1632492522154,"mc":[{"id":"1.188075669","rc":[{"trd":[[1.42,1617.76]],"batb":[[0,1.42,2.81]],"batl":[[0,1.49,4.46]],"ltp":1.42,"tv":3351.67,"id":9631939},{"batb":[[0,3,16.33],[1,2.92,98.18],[2,2,10.52]],"ltp":3.15,"tv":301.91,"id":9454286}],"tv":3653.59}]}
{"op":"mcm","clk":"4289682038","pt":1632492523154,"mc":[{"id":"1.188075669","rc":[{"batb":[[0,1.48,479.97],[1,1.47,215.41],[2,1.45,1158.25]],"batl":[[1,1.5,10.06],[2,1.52,185.4]],"ltp":1.42,"tv":3351.67,"id":9631939},{"batb":[[0,3,21.36],[2,2.86,334.36]],"batl":[[0,3.2,298.82],[1,3.25,725.1],[2,3.3,290.04]],"ltp":3.15,"tv":301.91,"id":9454286}]}]}
{"op":"mcm","clk":"4289682086","pt":1632492523631,"mc":[{"id":"1.188075669","rc":[{"trd":[[1.48,314.97]],"batb":[[0,1.48,459.56],[2,1.46,278.96]],"ltp":1.48,"tv":3392.49,"id":9631939},{"batb":[[2,2.86,405.81]],"batl":[[1,3.25,290.04]],"ltp":3.15,"tv":301.91,"id":9454286}],"tv":3694.41}]}
{"op":"mcm","clk":"4289682209","pt":1632492525062,"mc":[{"id":"1.188075669","rc":[{"trd":[[1.49,222.25]],"batl":[[0,1.49,2.46]],"ltp":1.49,"tv":3396.49,"id":9631939},{"batl":[[0,3.15,10.22],[1,3.2,298.82],[2,3.25,290.04]],"ltp":3.15,"tv":301.91,"id":9454286}],"tv":3698.41}]}
{"op":"mcm","clk":"4289682384","pt":1632492526929,"mc":[{"id":"1.188075669","rc":[{"batb":[[0,1.48,573.56]],"ltp":1.49,"tv":3396.49,"id":9631939}]}]}
{"op":"mcm","clk":"4289682664","pt":1632492530979,"mc":[{"id":"1.188075669","rc":[{"batb":[[0,1.48,660.16]],"ltp":1.49,"tv":3396.49,"id":9631939}]}]}
{"op":"mcm","clk":"4289682893","pt":1632492534080,"mc":[{"id":"1.188075669","rc":[{"trd":[[1.49,226.45]],"batl":[[0,1.5,10.41],[1,1.52,185.4],[2,1.53,167.77]],"ltp":1.49,"tv":3400.7,"id":9631939}],"tv":3702.62}]}
{"op":"mcm","clk":"4289682917","pt":1632492534355,"mc":[{"id":"1.188075669","rc":[{"batb":[[0,1.48,441.29]],"ltp":1.49,"tv":3400.7,"id":9631939}]}]}
{"op":"mcm","clk":"4289683118","pt":1632492536985,"mc":[{"id":"1.188075669","rc":[{"batb":[[0,1.48,86.6],[1,1.43,316.08],[2,1.19,73.04]],"batl":[[0,1.52,7.99],[1,1.8,9.49],[2,100,0.73]],"ltp":1.49,"tv":3400.7,"id":9631939},{"batb":[[0,3,16.33],[1,2.92,30.27],[2,2.86,71.45]],"batl":[[1,3.35,3],[2,3.25,0]],"ltp":3.15,"tv":301.91,"id":9454286}]}]}
{"op":"mcm","clk":"4289683204","pt":1632492537979,"mc":[{"id":"1.188075669","rc":[{"batb":[[0,1.48,176.6]],"ltp":1.49,"tv":3400.7,"id":9631939}]}]}
{"op":"mcm","clk":"4289683228","pt":1632492538366,"mc":[{"id":"1.188075669","rc":[{"batb":[[0,1.43,316.08],[1,1.19,73.04],[2,1.17,73.04]],"ltp":1.49,"tv":3400.7,"id":9631939},{"batl":[[0,3.35,3],[1,3.35,0]],"ltp":3.15,"tv":301.91,"id":9454286}]}]}
{"op":"mcm","clk":"4289683373","pt":1632492540086,"mc":[{"id":"1.188075669","rc":[{"batb":[[0,1.45,306.65],[1,1.44,218.36],[2,1.43,316.08]],"batl":[[0,1.5,7.35],[1,1.52,7.64],[2,1.54,210.64]],"ltp":1.49,"tv":3400.7,"id":9631939},{"batb":[[0,3,19.33],[1,2.98,3],[2,2.92,30.27]],"ltp":3.15,"tv":301.91,"id":9454286}]}]}
{"op":"mcm","clk":"4289683576","pt":1632492542794,"mc":[{"id":"1.188075669","rc":[{"batb":[[0,1.45,314.65],[1,1.44,225.36]],"ltp":1.49,"tv":3400.7,"id":9631939},{"batl":[[0,3.25,3],[1,3.35,3]],"ltp":3.15,"tv":301.91,"id":9454286}]}]}
{"op":"mcm","clk":"4289683639","pt":1632492543479,"mc":[{"id":"1.188075669","rc":[{"batb":[[0,1.45,8],[1,1.44,7]],"ltp":1.49,"tv":3400.7,"id":9631939}]}]}
{"op":"mcm","clk":"4289683762","pt":1632492545207,"mc":[{"id":"1.188075669","rc":[{"batb":[[0,3.1,20],[1,3,19.33],[2,2.98,3]],"ltp":3.15,"tv":301.91,"id":9454286}]}]}
{"op":"mcm","clk":"4289683839","pt":1632492546209,"mc":[{"id":"1.188075669","rc":[{"trd":[[1.48,356.86],[1.49,227.15],[1.5,62.93]],"batb":[[0,1.5,3219.66],[1,1.45,8],[2,1.44,7]],"batl":[[0,1.52,7.64],[1,1.54,210.64],[2,1.55,159.66]],"ltp":1.5,"tv":3495.95,"id":9631939},{"trd":[[2.96,11.76],[2.98,6],[3,39.33],[3.1,134.74]],"batb":[[0,2.92,30.27],[1,2.86,71.45],[2,2.78,144.1]],"batl":[[0,2.96,126.02],[1,3.05,1261.12],[2,3.1,1217.22]],"ltp":2.96,"tv":359.0,"id":9454286}],"tv":3854.96}]}
{"op":"mcm","clk":"4289683931","pt":1632492547211,"mc":[{"id":"1.188075669","rc":[{"trd":[[1.51,20.13]],"batb":[[0,1.5,435.12],[1,1.49,199.31],[2,1.48,265.13]],"ltp":1.51,"tv":3516.08,"id":9631939},{"trd":[[2.96,22.03]],"batl":[[0,2.96,115.75],[1,3.05,320.54],[2,3.1,304.3]],"ltp":2.96,"tv":369.27,"id":9454286}],"tv":3885.36}]}
{"op":"mcm","clk":"4289684002","pt":1632492548210,"mc":[{"id":"1.188075669","rc":[{"batb":[[1,1.49,201.5]],"ltp":1.51,"tv":3516.08,"id":9631939},{"batl":[[1,3.05,331.01]],"ltp":2.96,"tv":369.27,"id":9454286}]}]}
{"op":"mcm","clk":"4289684043","pt":1632492548689,"mc":[{"id":"1.188075669","rc":[{"trd":[[1.51,22.32]],"ltp":1.51,"tv":3518.27,"id":9631939},{"trd":[[2.96,23.15]],"batl":[[0,2.96,114.63],[1,3.05,320.54]],"ltp":2.96,"tv":370.39,"id":9454286}],"tv":3888.67}]}
{"op":"mcm","clk":"4289684147","pt":1632492549888,"mc":[{"id":"1.188075669","rc":[{"batb":[[0,1.51,152],[1,1.5,435.12],[2,1.49,188.35]],"ltp":1.51,"tv":3518.27,"id":9631939}]}]}
{"op":"mcm","clk":"4289684298","pt":1632492552125,"mc":[{"id":"1.188075669","rc":[{"batl":[[1,3,10.6],[2,3.05,320.54]],"ltp":2.96,"tv":370.39,"id":9454286}]}]}
{"op":"mcm","clk":"4289684328","pt":1632492552505,"mc":[{"id":"1.188075669","rc":[{"batl":[[1,3.05,320.54],[2,3.1,304.3]],"ltp":2.96,"tv":370.39,"id":9454286}]}]}
{"op":"mcm","clk":"4289684632","pt":1632492556020,"mc":[{"id":"1.188075669","rc":[{"batb":[[0,1.51,236.01]],"ltp":1.51,"tv":3518.27,"id":9631939},{"trd":[[2.92,2.28]],"batb":[[0,2.92,29.13]],"batl":[[0,2.96,125.34]],"ltp":2.92,"tv":372.67,"id":9454286}],"tv":3890.95}]}
{"op":"mcm","clk":"4289684680","pt":1632492556504,"mc":[{"id":"1.188075669","rc":[{"batl":[[1,3.05,313.52]],"ltp":2.92,"tv":372.67,"id":9454286}]}]}
{"op":"mcm","clk":"4289684806","pt":1632492558333,"mc":[{"id":"1.188075669","rc":[{"batb":[[1,1.5,172.62]],"ltp":1.51,"tv":3518.27,"id":9631939}]}]}
{"op":"mcm","clk":"4289684885","pt":1632492559326,"mc":[{"id":"1.188075669","rc":[{"batl":[[0,1.52,18.34]],"ltp":1.51,"tv":3518.27,"id":9631939},{"batl":[[1,3,5.8],[2,3.05,313.52]],"ltp":2.92,"tv":372.67,"id":9454286}]}]}
{"op":"mcm","clk":"4289685612","pt":1632492569123,"mc":[{"id":"1.188075669","rc":[{"batl":[[0,1.52,7.64]],"ltp":1.51,"tv":3518.27,"id":9631939},{"batb":[[2,2.6,91.69]],"batl":[[0,2.96,10.71],[1,3.25,3],[2,3.65,173.5]],"ltp":2.92,"tv":372.67,"id":9454286}]}]}
{"op":"mcm","clk":"4289685679","pt":1632492569906,"mc":[{"id":"1.188075669","rc":[{"batb":[[0,1.51,84.01],[1,1.45,293.47],[2,1.25,147.22]],"batl":[[1,1.8,9.49],[2,100,0.73]],"ltp":1.51,"tv":3518.27,"id":9631939},{"batb":[[1,2.6,91.69],[2,2,10.52]],"batl":[[1,3.65,173.5],[2,3.65,0]],"ltp":2.92,"tv":372.67,"id":9454286}]}]}
{"op":"mcm","clk":"4289685707","pt":1632492570327,"mc":[{"id":"1.188075669","rc":[{"batb":[[0,1.45,293.47],[1,1.25,147.22],[2,1.2,394.35]],"ltp":1.51,"tv":3518.27,"id":9631939},{"batl":[[0,3.65,173.5],[1,3.65,0]],"ltp":2.92,"tv":372.67,"id":9454286}]}]}
{"op":"mcm","clk":"4289685912","pt":1632492572810,"mc":[{"id":"1.188075669","rc":[{"batb":[[0,1.46,254.65],[1,1.45,505],[2,1.25,147.22]],"batl":[[1,1.62,146.05],[2,1.63,133.03]],"ltp":1.51,"tv":3518.27,"id":9631939}]}]}
{"op":"mcm","clk":"4289686087","pt":1632492575555,"mc":[{"id":"1.188075669","rc":[{"batb":[[0,1.45,293.47],[1,1.25,147.22],[2,1.2,394.35]],"ltp":1.51,"tv":3518.27,"id":9631939}]}]}
{"op":"mcm","clk":"4289686290","pt":1632492578143,"mc":[{"id":"1.188075669","rc":[{"trd":[[1.52,23.99],[1.53,55.6]],"batb":[[0,1.57,2873.7],[1,1.45,293.47],[2,1.25,147.22]],"batl":[[0,1.62,146.05],[1,1.63,133.03],[2,1.65,2318.18]],"ltp":1.53,"tv":3589.15,"id":9631939},{"trd":[[2.92,31.41]],"batb":[[0,2.66,6.05]],"batl":[[0,2.72,5.25],[1,2.8,1366.08],[2,2.82,1325.9]],"ltp":2.92,"tv":401.8,"id":9454286}],"tv":3990.96}]}
{"op":"mcm","clk":"4289686369","pt":1632492579145,"mc":[{"id":"1.188075669","rc":[{"trd":[[1.58,38.7]],"batb":[[0,1.58,111.71],[1,1.57,386.41],[2,1.45,293.47]],"batl":[[2,1.65,579.54]],"ltp":1.58,"tv":3627.85,"id":9631939},{"batb":[[2,1.97,402.02]],"batl":[[1,2.8,341.52],[2,2.82,331.48]],"ltp":2.92,"tv":401.8,"id":9454286}],"tv":4029.66}]}
{"op":"mcm","clk":"4289686431","pt":1632492579936,"mc":[{"id":"1.188075669","rc":[{"batb":[[0,1.57,386.41],[1,1.56,215.61],[2,1.51,248.17]],"ltp":1.58,"tv":3627.85,"id":9631939},{"batb":[[2,2.3,125.86]],"ltp":2.92,"tv":401.8,"id":9454286}]}]}
{"op":"mcm","clk":"4289686517","pt":1632492580940,"mc":[{"id":"1.188075669","rc":[{"batb":[[2,1.52,280.91]],"ltp":1.58,"tv":3627.85,"id":9631939}]}]}
{"op":"mcm","clk":"4289686611","pt":1632492581960,"mc":[{"id":"1.188075669","rc":[{"batb":[[0,1.59,189],[1,1.57,386.41],[2,1.56,215.61]],"ltp":1.58,"tv":3627.85,"id":9631939},{"batl":[[0,2.72,16.68]],"ltp":2.92,"tv":401.8,"id":9454286}]}]}
{"op":"mcm","clk":"4289686723","pt":1632492583167,"mc":[{"id":"1.188075669","rc":[{"batb":[[1,1.58,78.78],[2,1.57,507.56]],"batl":[[0,1.6,75.52],[1,1.62,146.05],[2,1.63,133.03]],"ltp":1.58,"tv":3627.85,"id":9631939},{"batl":[[1,2.8,366.91]],"ltp":2.92,"tv":401.8,"id":9454286}]}]}
{"op":"mcm","clk":"4289686747","pt":1632492583471,"mc":[{"id":"1.188075669","rc":[{"batb":[[1,1.57,507.56],[2,1.56,373.42]],"batl":[[0,1.62,146.05],[1,1.63,133.03],[2,1.65,579.54]],"ltp":1.58,"tv":3627.85,"id":9631939},{"batl":[[1,2.8,341.52]],"ltp":2.92,"tv":401.8,"id":9454286}]}]}
{"op":"mcm","clk":"4289687033","pt":1632492586960,"mc":[{"id":"1.188075669","rc":[{"batb":[[0,1.59,267.11]],"ltp":1.58,"tv":3627.85,"id":9631939}]}]}
{"op":"mcm","clk":"4289687325","pt":1632492590171,"mc":[{"id":"1.188075669","rc":[{"batb":[[1,1.57,274.47]],"ltp":1.58,"tv":3627.85,"id":9631939}]}]}
{"op":"mcm","clk":"4289687641","pt":1632492594178,"mc":[{"id":"1.188075669","rc":[{"trd":[[2.66,11.84]],"batb":[[0,2.6,91.82],[1,2.3,125.86],[2,1.97,402.02]],"ltp":2.66,"tv":413.64,"id":9454286}],"tv":4041.5}]}
{"op":"mcm","clk":"4289687809","pt":1632492596177,"mc":[{"id":"1.188075669","rc":[{"batb":[[1,1.51,248.17],[2,1.47,8.81]],"batl":[[0,1.8,9.49],[1,100,0.73],[2,1.65,0]],"ltp":1.58,"tv":3627.85,"id":9631939},{"batb":[[0,2.3,125.86],[1,1.97,402.02],[2,1.8,10.52]],"batl":[[0,2.72,11.43],[1,3.45,183.67],[2,2.82,0]],"ltp":2.66,"tv":413.64,"id":9454286}]}]}
{"op":"mcm","clk":"4289687878","pt":1632492596963,"mc":[{"id":"1.188075669","rc":[{"batb":[[0,1.59,78.11]],"ltp":1.58,"tv":3627.85,"id":9631939}]}]}
{"op":"mcm","clk":"4289687947","pt":1632492597760,"mc":[{"id":"1.188075669","rc":[{"batb":[[0,1.51,248.17],[1,1.47,8.81],[2,1.25,147.22]],"ltp":1.58,"tv":3627.85,"id":9631939},{"batl":[[0,3.45,183.67],[1,3.45,0]],"ltp":2.66,"tv":413.64,"id":9454286}]}]}
{"op":"mcm","clk":"4289688044","pt":1632492599078,"mc":[{"id":"1.188075669","rc":[{"batb":[[0,1.52,181.82],[1,1.51,426.82],[2,1.47,8.81]],"batl":[[0,1.75,136.23],[1,1.77,202.44],[2,1.8,9.49]],"ltp":1.58,"tv":3627.85,"id":9631939}]}]}
{"op":"mcm","clk":"4289688088","pt":1632492599675,"mc":[{"id":"1.188075669","rc":[{"batl":[[1,1.77,206.44]],"ltp":1.58,"tv":3627.85,"id":9631939},{"batb":[[0,2.3,129.86],[1,2.28,3],[2,1.97,402.02]],"ltp":2.66,"tv":413.64,"id":9454286}]}]}
{"op":"mcm","clk":"4289688279","pt":1632492602070,"mc":[{"id":"1.188075669","rc":[{"trd":[[1.75,4.38]],"batl":[[0,1.75,134.04]],"ltp":1.75,"tv":3632.24,"id":9631939}],"tv":4045.88}]}
{"op":"mcm","clk":"4289688347","pt":1632492602868,"mc":[{"id":"1.188075669","rc":[{"trd":[[1.75,17.52]],"batl":[[0,1.71,5],[1,1.75,131.47],[2,1.77,206.44]],"ltp":1.75,"tv":3645.38,"id":9631939},{"batb":[[0,2.42,4],[1,2.4,3],[2,2.38,3]],"ltp":2.66,"tv":413.64,"id":9454286}],"tv":4059.03}]}
{"op":"mcm","clk":"4289688554","pt":1632492605268,"mc":[{"id":"1.188075669","rc":[{"trd":[[1.71,4.38]],"batl":[[0,1.71,2.81]],"ltp":1.71,"tv":3649.76,"id":9631939}],"tv":4063.41}]}
{"op":"mcm","clk":"4289688701","pt":1632492607099,"mc":[{"id":"1.188075669","rc":[{"batb":[[0,1.51,248.17],[1,1.47,8.81],[2,1.25,147.22]],"ltp":1.71,"tv":3649.76,"id":9631939}]}]}
{"op":"mcm","clk":"4289688816","pt":1632492608373,"mc":[{"id":"1.188075669","rc":[{"batl":[[0,1.75,127.47],[1,1.77,202.44],[2,1.8,9.49]],"ltp":1.71,"tv":3649.76,"id":9631939},{"batb":[[0,2.3,125.86],[1,2.28,3],[2,1.8,10.52]],"ltp":2.66,"tv":413.64,"id":9454286}]}]}
{"op":"mcm","clk":"4289688974","pt":1632492610198,"mc":[{"id":"1.188075669","rc":[{"batb":[[0,1.72,12.08],[1,1.7,1082.4],[2,1.68,238.64]],"batl":[[2,1.78,537.22]],"ltp":1.71,"tv":3649.76,"id":9631939},{"batb":[[0,2.32,9.67],[1,2.3,125.86],[2,2.28,3]],"batl":[[0,2.48,385.58],[1,2.5,374.24],[2,2.52,374.24]],"ltp":2.66,"tv":413.64,"id":9454286}]}]}
{"op":"mcm","clk":"4289689035","pt":1632492610994,"mc":[{"id":"1.188075669","rc":[{"trd":[[1.7,12.2],[1.72,24.16]],"batb":[[0,1.7,319.32],[1,1.69,163.57]],"ltp":1.7,"tv":3686.12,"id":9631939},{"batb":[[2,2.04,180.69]],"ltp":2.66,"tv":413.64,"id":9454286}],"tv":4099.77}]}
{"op":"mcm","clk":"4289689145","pt":1632492612097,"mc":[{"id":"1.188075669","rc":[{"batb":[[0,1.7,391.03]],"ltp":1.7,"tv":3686.12,"id":9631939},{"batb":[[2,2.26,3]],"batl":[[0,2.44,50],[1,2.48,385.58],[2,2.5,374.24]],"ltp":2.66,"tv":413.64,"id":9454286}]}]}
{"op":"mcm","clk":"4289689869","pt":1632492620911,"mc":[{"id":"1.188075669","rc":[{"batb":[[0,2.3,125.86],[1,2.26,3],[2,2.04,180.69]],"ltp":2.66,"tv":413.64,"id":9454286}]}]}
{"op":"mcm","clk":"4289689922","pt":1632492621739,"mc":[{"id":"1.188075669","rc":[{"batb":[[0,1.7,216.9]],"ltp":1.7,"tv":3686.12,"id":9631939}]}]}
{"op":"mcm","clk":"4289690088","pt":1632492623830,"mc":[{"id":"1.188075669","rc":[{"batb":[[0,2.36,7.58],[1,2.3,125.86],[2,2.26,3]],"batl":[[0,2.42,7.81],[1,2.44,50],[2,2.48,385.58]],"ltp":2.66,"tv":413.64,"id":9454286}]}]}
{"op":"mcm","clk":"4289690543","pt":1632492629134,"mc":[{"id":"1.188075669","rc":[{"batb":[[0,1.71,153],[1,1.7,216.9],[2,1.69,163.57]],"ltp":1.7,"tv":3686.12,"id":9631939},{"batl":[[1,2.48,385.58],[2,2.5,374.24]],"ltp":2.66,"tv":413.64,"id":9454286}]}]}
{"op":"mcm","clk":"4289690765","pt":1632492632360,"mc":[{"id":"1.188075669","rc":[{"batl":[[0,2.42,58.16]],"ltp":2.66,"tv":413.64,"id":9454286}]}]}
{"op":"mcm","clk":"4289690919","pt":1632492633944,"mc":[{"id":"1.188075669","rc":[{"batb":[[1,1.7,71.71],[2,1.61,194.44]],"batl":[[0,1.8,9.49],[1,100,0.73],[2,1.78,0]],"ltp":1.7,"tv":3686.12,"id":9631939},{"batb":[[0,2.04,180.52],[1,1.77,409.56],[2,1.7,15.02]],"batl":[[0,2.42,50.35],[1,2.96,3],[2,3,217.32]],"ltp":2.66,"tv":413.64,"id":9454286}]}]}
{"op":"mcm","clk":"4289691022","pt":1632492635052,"mc":[{"id":"1.188075669","rc":[{"batb":[[0,1.7,71.71],[1,1.61,194.44],[2,1.52,6]],"ltp":1.7,"tv":3686.12,"id":9631939}]}]}
{"op":"mcm","clk":"4289691057","pt":1632492635356,"mc":[{"id":"1.188075669","rc":[{"batb":[[0,1.61,194.44],[1,1.52,6],[2,1.47,8.81]],"ltp":1.7,"tv":3686.12,"id":9631939},{"batl":[[0,2.96,3],[1,3,217.32],[2,3,0]],"ltp":2.66,"tv":413.64,"id":9454286}]}]}
{"op":"mcm","clk":"4289691218","pt":1632492637117,"mc":[{"id":"1.188075669","rc":[{"batb":[[0,1.62,155.81],[1,1.61,334.22],[2,1.52,6]],"batl":[[1,1.85,15],[2,1.94,168.81]],"ltp":1.7,"tv":3686.12,"id":9631939},{"batb":[[0,2.18,12.71],[1,2.04,180.52],[2,1.77,409.56]],"ltp":2.66,"tv":413.64,"id":9454286}]}]}
{"op":"mcm","clk":"4289691237","pt":1632492637438,"mc":[{"id":"1.188075669","rc":[{"batl":[[1,1.94,168.81],[2,1.96,147.16]],"ltp":1.7,"tv":3686.12,"id":9631939},{"batb":[[0,2.04,180.52],[1,1.77,409.56],[2,1.7,15.02]],"ltp":2.66,"tv":413.64,"id":9454286}]}]}
{"op":"mcm","clk":"4289691534","pt":1632492641221,"mc":[{"id":"1.188075669","rc":[{"trd":[[1.62,4.38]],"batb":[[0,1.62,153.62]],"batl":[[0,1.66,2.19],[1,1.8,9.49],[2,1.94,168.81]],"ltp":1.62,"tv":3690.5,"id":9631939}],"tv":4104.15}]}
{"op":"mcm","clk":"4289691581","pt":1632492641853,"mc":[{"id":"1.188075669","rc":[{"batl":[[0,1.66,8.76]],"ltp":1.62,"tv":3690.5,"id":9631939}]}]}
{"op":"mcm","clk":"4289691664","pt":1632492642854,"mc":[{"id":"1.188075669","rc":[{"batl":[[0,1.66,10.96]],"ltp":1.62,"tv":3690.5,"id":9631939}]}]}
{"op":"mcm","clk":"4289691844","pt":1632492645065,"mc":[{"id":"1.188075669","rc":[{"batl":[[0,1.64,2.19],[1,1.66,10.96],[2,1.7,2.19]],"ltp":1.62,"tv":3690.5,"id":9631939}]}]}
{"op":"mcm","clk":"4289692153","pt":1632492649071,"mc":[{"id":"1.188075669","rc":[{"trd":[[1.62,42.36]],"batb":[[0,1.62,134.63],[2,1.59,601.42]],"batl":[[1,1.66,26.93],[2,1.67,362.92]],"ltp":1.62,"tv":3728.48,"id":9631939},{"batb":[[0,2.06,2830.18],[1,2.04,180.52],[2,1.8,10.52]],"batl":[[0,2.6,262.37],[1,2.96,3],[2,3,217.32]],"ltp":2.66,"tv":413.64,"id":9454286}],"tv":4142.13}]}
{"op":"mcm","clk":"4289692233","pt":1632492650070,"mc":[{"id":"1.188075669","rc":[{"batl":[[0,1.64,13.15]],"ltp":1.62,"tv":3728.48,"id":9631939},{"batb":[[0,2.48,103.25],[1,2.16,152.94]],"batl":[[1,2.92,1.71],[2,2.96,3]],"ltp":2.66,"tv":413.64,"id":9454286}]}]}
{"op":"mcm","clk":"4289692335","pt":1632492651172,"mc":[{"id":"1.188075669","rc":[{"trd":[[1.64,21.73]],"batb":[[0,1.63,75.59],[1,1.62,134.63],[2,1.61,334.22]],"batl":[[0,1.64,4.47]],"ltp":1.64,"tv":3750.21,"id":9631939},{"batl":[[0,2.58,47.73],[1,2.6,262.37],[2,2.92,1.71]],"ltp":2.66,"tv":413.64,"id":9454286}],"tv":4163.86}]}
{"op":"mcm","clk":"4289692391","pt":1632492651751,"mc":[{"id":"1.188075669","rc":[{"batb":[[0,1.63,974.59]],"ltp":1.64,"tv":3750.21,"id":9631939},{"batb":[[1,2.42,4],[2,2.16,152.94]],"ltp":2.66,"tv":413.64,"id":9454286}]}]}
{"op":"mcm","clk":"4289692581","pt":1632492653976,"mc":[{"id":"1.188075669","rc":[{"trd":[[1.64,29.73]],"batl":[[0,1.66,15.97],[1,1.67,362.92],[2,1.68,569.2]],"ltp":1.64,"tv":3758.21,"id":9631939}],"tv":4171.86}]}
{"op":"mcm","clk":"4289692946","pt":1632492659065,"mc":[{"id":"1.188075669","rc":[{"batb":[[0,1.64,187.61],[1,1.63,974.59],[2,1.62,134.63]],"ltp":1.64,"tv":3758.21,"id":9631939}]}]}
{"op":"mcm","clk":"4289693002","pt":1632492659752,"mc":[{"id":"1.188075669","rc":[{"batb":[[1,1.63,75.59]],"ltp":1.64,"tv":3758.21,"id":9631939},{"batl":[[2,2.96,3]],"ltp":2.66,"tv":413.64,"id":9454286}]}]}
{"op":"mcm","clk":"4289693040","pt":1632492660386,"mc":[{"id":"1.188075669","rc":[{"batl":[[1,1.67,204.93]],"ltp":1.64,"tv":3758.21,"id":9631939}]}]}
{"op":"mcm","clk":"4289693134","pt":1632492661465,"mc":[{"id":"1.188075669","rc":[{"batb":[[0,1.63,75.59],[1,1.62,134.63],[2,1.61,334.22]],"ltp":1.64,"tv":3758.21,"id":9631939}]}]}
{"op":"mcm","clk":"4289693262","pt":1632492663067,"mc":[{"id":"1.188075669","rc":[{"trd":[[1.66,3.9]],"batb":[[0,1.65,843],[1,1.63,75.59],[2,1.62,134.63]],"batl":[[0,1.66,14.02]],"ltp":1.66,"tv":3762.11,"id":9631939},{"batl":[[0,2.6,262.37],[1,2.96,3],[2,3,217.32]],"ltp":2.66,"tv":413.64,"id":9454286}],"tv":4175.76}]}
{"op":"mcm","clk":"4289693390","pt":1632492664402,"mc":[{"id":"1.188075669","rc":[{"trd":[[1.65,0.78]],"batb":[[0,1.65,842.61]],"ltp":1.65,"tv":3762.89,"id":9631939}],"tv":4176.54}]}
{"op":"mcm","clk":"4289693554","pt":1632492665990,"mc":[{"id":"1.188075669","rc":[{"batl":[[1,2.62,47.14],[2,2.96,3]],"ltp":2.66,"tv":413.64,"id":9454286}]}]}
{"op":"mcm","clk":"4289694129","pt":1632492673197,"mc":[{"id":"1.188075669","rc":[{"batb":[[2,1.53,232.23]],"batl":[[0,1.8,9.49],[1,100,0.73],[2,1.68,0]],"ltp":1.65,"tv":3762.89,"id":9631939},{"batb":[[0,2.16,152.68],[1,1.77,409.56],[2,1.7,15.02]],"batl":[[0,2.62,47.14],[1,2.96,3],[2,3,217.32]],"ltp":2.66,"tv":413.64,"id":9454286}]}]}
{"op":"mcm","clk":"4289694198","pt":1632492673895,"mc":[{"id":"1.188075669","rc":[{"batb":[[0,1.63,75.59],[1,1.53,232.23],[2,1.47,8.81]],"ltp":1.65,"tv":3762.89,"id":9631939}]}]}
{"op":"mcm","clk":"4289694245","pt":1632492674319,"mc":[{"id":"1.188075669","rc":[{"batb":[[0,1.53,232.23],[1,1.47,8.81],[2,1.25,147.22]],"ltp":1.65,"tv":3762.89,"id":9631939},{"batl":[[0,2.96,3],[1,3,217.32],[2,3,0]],"ltp":2.66,"tv":413.64,"id":9454286}]}]}
{"op":"mcm","clk":"4289694431","pt":1632492676189,"mc":[{"id":"1.188075669","rc":[{"batl":[[0,1.74,15],[1,1.8,9.49],[2,100,0.73]],"ltp":1.65,"tv":3762.89,"id":9631939}]}]}
{"op":"mcm","clk":"4289694470","pt":1632492676709,"mc":[{"id":"1.188075669","rc":[{"batl":[[0,1.8,14.49],[1,100,0.73],[2,100,0]],"ltp":1.65,"tv":3762.89,"id":9631939},{"batb":[[0,2.24,3],[1,2.22,4],[2,2.16,152.68]],"ltp":2.66,"tv":413.64,"id":9454286}]}]}
{"op":"mcm","clk":"4289694583","pt":1632492677974,"mc":[{"id":"1.188075669","rc":[{"batl":[[2,1000,0.07]],"ltp":2.66,"tv":413.64,"id":9454286}]}]}
{"op":"mcm","clk":"4289694700","pt":1632492679178,"mc":[{"id":"1.188075669","rc":[{"batb":[[0,1.79,15.34],[1,1.53,232.23],[2,1.47,8.81]],"ltp":1.65,"tv":3762.89,"id":9631939},{"batl":[[2,1000,0]],"ltp":2.66,"tv":413.64,"id":9454286}]}]}
{"op":"mcm","clk":"4289694801","pt":1632492680178,"mc":[{"id":"1.188075669","rc":[{"trd":[[1.7,25.34],[1.79,30.67]],"batb":[[0,1.65,156.14],[1,1.64,130.79],[2,1.53,232.23]],"batl":[[0,1.7,148.02],[1,1.72,222.4],[2,1.8,14.49]],"ltp":1.7,"tv":3806.7,"id":9631939}],"tv":4220.35}]}
{"op":"mcm","clk":"4289694843","pt":1632492680806,"mc":[{"id":"1.188075669","rc":[{"batb":[[0,1.69,2.19],[1,1.68,2.19],[2,1.65,156.14]],"ltp":1.7,"tv":3806.7,"id":9631939}]}]}
{"op":"mcm","clk":"4289694938","pt":1632492681903,"mc":[{"id":"1.188075669","rc":[{"batl":[[2,810,0.07]],"ltp":2.66,"tv":413.64,"id":9454286}]}]}
{"op":"mcm","clk":"4289695196","pt":1632492685137,"mc":[{"id":"1.188075669","rc":[{"batb":[[2,1.53,232.23]],"batl":[[0,1.8,14.49],[1,100,0.73],[2,1.8,0]],"ltp":1.7,"tv":3806.7,"id":9631939}]}]}
{"op":"mcm","clk":"4289695337","pt":1632492687337,"mc":[{"id":"1.188075669","rc":[{"batb":[[2,1.54,219.56]],"batl":[[1,1.85,161.78],[2,1.87,169.87]],"ltp":1.7,"tv":3806.7,"id":9631939}]}]}
{"op":"mcm","clk":"4289695539","pt":1632492690200,"mc":[{"id":"1.188075669","rc":[{"batb":[[0,1.79,6.57],[1,1.69,2.19],[2,1.68,2.19]],"ltp":1.7,"tv":3806.7,"id":9631939},{"batb":[[1,2.16,152.68],[2,1.77,409.56]],"ltp":2.66,"tv":413.64,"id":9454286}]}]}
{"op":"mcm","clk":"4289695648","pt":1632492691718,"mc":[{"id":"1.188075669","rc":[{"batb":[[0,1.79,8.76]],"batl":[[0,1.8,9.49]],"ltp":1.7,"tv":3806.7,"id":9631939},{"batb":[[0,2.16,152.68],[1,1.77,409.56],[2,1.6,87.64]],"batl":[[1,810,0.07],[2,810,0]],"ltp":2.66,"tv":413.64,"id":9454286}]}]}
{"op":"mcm","clk":"4289695770","pt":1632492693199,"mc":[{"id":"1.188075669","rc":[{"trd":[[1.8,9.49]],"batb":[[0,1.79,140.41],[1,1.78,187.73],[2,1.77,740.12]],"batl":[[0,1.85,161.78],[1,1.86,12.75]],"ltp":1.8,"tv":3816.2,"id":9631939},{"trd":[[2.24,7.63]],"batb":[[1,2.12,451.06],[2,2.1,437.8]],"batl":[[0,2.24,6.15],[1,2.6,1.71],[2,2.66,1830.6]],"ltp":2.24,"tv":421.27,"id":9454286}],"tv":4237.48}]}
{"op":"mcm","clk":"4289695862","pt":1632492694205,"mc":[{"id":"1.188075669","rc":[{"trd":[[1.79,50.25],[1.8,17.14]],"batb":[[0,1.79,130.62],[1,1.78,324.72]],"ltp":1.79,"tv":3843.43,"id":9631939},{"trd":[[2.24,13.78]],"batl":[[0,2.32,52.22]],"ltp":2.24,"tv":427.42,"id":9454286}],"tv":4270.86}]}
{"op":"mcm","clk":"4289695981","pt":1632492695729,"mc":[{"id":"1.188075669","rc":[{"batl":[[0,2.6,1.71],[1,2.66,1830.6],[2,2.82,235.47]],"ltp":2.24,"tv":427.42,"id":9454286}]}]}
{"op":"mcm","clk":"4289696103","pt":1632492697038,"mc":[{"id":"1.188075669","rc":[{"batl":[[0,2.56,979.96],[1,2.6,1.71],[2,2.66,1830.6]],"ltp":2.24,"tv":427.42,"id":9454286}]}]}
{"op":"mcm","clk":"4289696181","pt":1632492697937,"mc":[{"id":"1.188075669","rc":[{"batl":[[0,2.6,1.71],[1,2.66,1830.6],[2,2.82,235.47]],"ltp":2.24,"tv":427.42,"id":9454286}]}]}
{"op":"mcm","clk":"4289696262","pt":1632492699166,"mc":[{"id":"1.188075669","rc":[{"batl":[[0,2.32,52.22],[1,2.6,1.71],[2,2.66,1830.6]],"ltp":2.24,"tv":427.42,"id":9454286}]}]}
{"op":"mcm","clk":"4289696572","pt":1632492702741,"mc":[{"id":"1.188075669","rc":[{"trd":[[1.85,100]],"batb":[[1,1.78,392.65]],"batl":[[0,1.85,111.78],[1,1.87,169.87],[2,1.96,390.1]],"ltp":1.85,"tv":3943.43,"id":9631939}],"tv":4370.86}]}
{"op":"mcm","clk":"4289696646","pt":1632492703528,"mc":[{"id":"1.188075669","rc":[{"batl":[[1,2.66,1830.6],[2,2.82,235.47]],"ltp":2.24,"tv":427.42,"id":9454286}]}]}
{"op":"mcm","clk":"4289696741","pt":1632492704836,"mc":[{"id":"1.188075669","rc":[{"batb":[[1,1.78,204.92]],"ltp":1.85,"tv":3943.43,"id":9631939}]}]}
{"op":"mcm","clk":"4289696853","pt":1632492706152,"mc":[{"id":"1.188075669","rc":[{"batb":[[0,1.79,159.65]],"batl":[[0,1.85,134.69]],"ltp":1.85,"tv":3943.43,"id":9631939}]}]}
{"op":"mcm","clk":"4289697107","pt":1632492709172,"mc":[{"id":"1.188075669","rc":[{"batl":[[0,1.83,13.36],[1,1.85,134.69],[2,1.87,169.87]],"ltp":1.85,"tv":3943.43,"id":9631939},{"batl":[[0,2.28,11.88],[1,2.32,52.22],[2,2.66,1830.6]],"ltp":2.24,"tv":427.42,"id":9454286}]}]}
{"op":"mcm","clk":"4289697183","pt":1632492709852,"mc":[{"id":"1.188075669","rc":[{"batb":[[0,1.78,67.93],[1,1.68,167.45],[2,1.47,8.81]],"batl":[[0,100,0.73],[1,1.85,0],[2,1.87,0]],"ltp":1.85,"tv":3943.43,"id":9631939},{"batb":[[0,2.08,13.88],[1,1.89,114.13],[2,1.77,409.56]],"batl":[[0,2.32,52.22],[1,2.82,235.47],[2,2.96,3]],"ltp":2.24,"tv":427.42,"id":9454286}]}]}
{"op":"mcm","clk":"4289697284","pt":1632492711162,"mc":[{"id":"1.188075669","rc":[{"batl":[[0,100,0.86]],"ltp":1.85,"tv":3943.43,"id":9631939}]}]}
{"op":"mcm","clk":"4289697360","pt":1632492712057,"mc":[{"id":"1.188075669","rc":[{"trd":[[1.79,50.51]],"batb":[[0,1.8,163.87]],"batl":[[0,100,0.73]],"ltp":1.79,"tv":3943.69,"id":9631939},{"batb":[[0,1.89,114.13],[1,1.77,409.56],[2,1.6,87.64]],"batl":[[0,2.82,235.47],[1,2.96,3],[2,810,0.07]],"ltp":2.24,"tv":427.42,"id":9454286}],"tv":4371.12}]}
{"op":"mcm","clk":"4289697445","pt":1632492713162,"mc":[{"id":"1.188075669","rc":[{"batb":[[0,1.68,405.49],[1,1.66,249.27]],"batl":[[0,1.92,15],[1,2.1,122.31],[2,2.12,116.98]],"ltp":1.79,"tv":3943.69,"id":9631939}]}]}
{"op":"mcm","clk":"4289697459","pt":1632492713267,"mc":[{"id":"1.188075669","rc":[{"batl":[[0,2.1,122.31],[1,2.12,116.98],[2,100,0.73]],"ltp":1.79,"tv":3943.69,"id":9631939}]}]}
{"op":"mcm","clk":"4289697617","pt":1632492715157,"mc":[{"id":"1.188075669","rc":[{"batl":[[2,2.14,4]],"ltp":1.79,"tv":3943.69,"id":9631939},{"batb":[[0,1.89,119.13],[1,1.88,4],[2,1.77,409.56]],"batl":[[2,1000,0.15]],"ltp":2.24,"tv":427.42,"id":9454286}]}]}
{"op":"mcm","clk":"4289697685","pt":1632492716051,"mc":[{"id":"1.188075669","rc":[{"batb":[[0,2.02,2.19],[1,1.68,405.49],[2,1.66,249.27]],"batl":[[0,2.1,126.31]],"ltp":1.79,"tv":3943.69,"id":9631939},{"batb":[[0,1.9,4],[1,1.89,119.13],[2,1.88,4]],"batl":[[2,810,0.07]],"ltp":2.24,"tv":427.42,"id":9454286}]}]}
{"op":"mcm","clk":"4289697757","pt":1632492717046,"mc":[{"id":"1.188075669","rc":[{"trd":[[2.1,13.14]],"batb":[[0,2.08,2.19],[1,2.02,2.19],[2,1.68,405.49]],"batl":[[0,2.1,119.74]],"ltp":2.1,"tv":3956.84,"id":9631939}],"tv":4384.26}]}
{"op":"mcm","clk":"4289697847","pt":1632492718146,"mc":[{"id":"1.188075669","rc":[{"batb":[[0,2.08,4.38],[2,2,2.19]],"ltp":2.1,"tv":3956.84,"id":9631939}]}]}
{"op":"mcm","clk":"4289697888","pt":1632492718669,"mc":[{"id":"1.188075669","rc":[{"batb":[[1,2.06,2.19],[2,2.02,2.19]],"ltp":2.1,"tv":3956.84,"id":9631939},{"batl":[[2,820,0.15]],"ltp":2.24,"tv":427.42,"id":9454286}]}]}
{"op":"mcm","clk":"4289697956","pt":1632492719656,"mc":[{"id":"1.188075669","rc":[{"batl":[[2,810,0.07]],"ltp":2.24,"tv":427.42,"id":9454286}]}]}
{"op":"mcm","clk":"4289698526","pt":1632492726195,"mc":[{"id":"1.188075669","rc":[{"batl":[[0,2.1,4],[1,2.14,4],[2,100,0.73]],"ltp":2.1,"tv":3956.84,"id":9631939}]}]}
{"op":"mcm","clk":"4289698542","pt":1632492726405,"mc":[{"id":"1.188075669","rc":[{"batb":[[1,1.89,114.13],[2,1.77,409.56]],"ltp":2.24,"tv":427.42,"id":9454286}]}]}
{"op":"mcm","clk":"4289698788","pt":1632492729103,"mc":[{"id":"1.188075669","rc":[{"trd":[[1.7,43.63]],"batb":[[0,1.68,417.47],[1,1.66,249.27],[2,1.65,579.54]],"batl":[[0,1.74,1669.98],[1,1.75,1366.08],[2,1.76,1531.86]],"ltp":1.7,"tv":3975.13,"id":9631939},{"trd":[[2.42,12.85]],"batb":[[0,2.4,9.14],[1,2.24,229.24],[2,1.9,4]],"batl":[[0,2.42,233.77],[1,2.82,235.47],[2,2.96,3]],"ltp":2.42,"tv":440.27,"id":9454286}],"tv":4415.4}]}
{"op":"mcm","clk":"4289698871","pt":1632492730182,"mc":[{"id":"1.188075669","rc":[{"batb":[[0,1.68,490.23]],"batl":[[0,1.74,282.12],[1,1.75,546.44],[2,1.76,736.32]],"ltp":1.7,"tv":3975.13,"id":9631939},{"batb":[[1,2.34,122.48],[2,2.24,229.24]],"batl":[[1,2.5,48.98],[2,2.66,1.71]],"ltp":2.42,"tv":440.27,"id":9454286}]}]}
{"op":"mcm","clk":"4289699033","pt":1632492732128,"mc":[{"id":"1.188075669","rc":[{"trd":[[2.42,22.93]],"batb":[[2,2.3,4]],"batl":[[0,2.42,228.73]],"ltp":2.42,"tv":450.35,"id":9454286}],"tv":4425.48}]}
{"op":"mcm","clk":"4289699109","pt":1632492733122,"mc":[{"id":"1.188075669","rc":[{"batb":[[0,1.71,275],[1,1.68,490.23],[2,1.66,249.27]],"ltp":1.7,"tv":3975.13,"id":9631939}]}]}
{"op":"mcm","clk":"4289699197","pt":1632492734223,"mc":[{"id":"1.188075669","rc":[{"trd":[[1.71,120.38]],"batb":[[0,1.71,217]],"ltp":1.71,"tv":4091.13,"id":9631939},{"batl":[[1,2.66,1.71],[2,2.82,235.47]],"ltp":2.42,"tv":450.35,"id":9454286}],"tv":4541.48}]}
{"op":"mcm","clk":"4289699327","pt":1632492735895,"mc":[{"id":"1.188075669","rc":[{"batb":[[0,1.71,421]],"ltp":1.71,"tv":4091.13,"id":9631939}]}]}
{"op":"mcm","clk":"4289699442","pt":1632492737521,"mc":[{"id":"1.188075669","rc":[{"batl":[[1,2.46,49.65],[2,2.66,1.71]],"ltp":2.42,"tv":450.35,"id":9454286}]}]}
{"op":"mcm","clk":"4289699704","pt":1632492740897,"mc":[{"id":"1.188075669","rc":[{"batl":[[0,1.74,162.48]],"ltp":1.71,"tv":4091.13,"id":9631939},{"batl":[[2,2.82,235.47]],"ltp":2.42,"tv":450.35,"id":9454286}]}]}
{"op":"mcm","clk":"4289700327","pt":1632492749129,"mc":[{"id":"1.188075669","rc":[{"trd":[[1.72,25.73]],"ltp":1.72,"tv":4092.7,"id":9631939},{"trd":[[2.4,1.13]],"batb":[[0,2.4,8.01]],"ltp":2.4,"tv":451.48,"id":9454286}],"tv":4544.18}]}
{"op":"mcm","clk":"4289700998","pt":1632492755957,"mc":[{"id":"1.188075669","rc":[{"batb":[[0,1.68,72.76],[1,1.54,225.65],[2,1.3,175.26]],"batl":[[0,2.08,4],[1,100,0.73],[2,1.76,0]],"ltp":1.72,"tv":4092.7,"id":9631939},{"batb":[[0,1.92,109.41],[1,1.77,409.56],[2,1.7,15.02]],"batl":[[0,2.46,49.65],[1,2.82,235.47],[2,2.96,3]],"ltp":2.4,"tv":451.48,"id":9454286}]}]}
{"op":"mcm","clk":"4289701103","pt":1632492757183,"mc":[{"id":"1.188075669","rc":[{"batb":[[0,1.54,225.65],[1,1.3,175.26],[2,1.25,147.22]],"ltp":1.72,"tv":4092.7,"id":9631939},{"batl":[[0,2.82,235.47],[1,2.96,3],[2,810,0.07]],"ltp":2.4,"tv":451.48,"id":9454286}]}]}
{"op":"mcm","clk":"4289701170","pt":1632492758065,"mc":[{"id":"1.188075669","rc":[{"batl":[[0,1.56,2.19],[1,2.08,4],[2,100,0.73]],"ltp":1.72,"tv":4092.7,"id":9631939}]}]}
{"op":"mcm","clk":"4289701273","pt":1632492759223,"mc":[{"id":"1.188075669","rc":[{"batb":[[1,1.25,147.22],[2,1.2,394.35]],"ltp":1.72,"tv":4092.7,"id":9631939},{"batb":[[0,1.92,113.41],[1,1.91,3],[2,1.77,409.56]],"ltp":2.4,"tv":451.48,"id":9454286}]}]}
{"op":"mcm","clk":"4289701345","pt":1632492760166,"mc":[{"id":"1.188075669","rc":[{"batb":[[0,1.54,228.65],[1,1.53,4],[2,1.25,147.22]],"batl":[[0,1.56,4.38]],"ltp":1.72,"tv":4092.7,"id":9631939},{"batl":[[0,2.82,239.47]],"ltp":2.4,"tv":451.48,"id":9454286}]}]}
{"op":"mcm","clk":"4289701387","pt":1632492760645,"mc":[{"id":"1.188075669","rc":[{"batl":[[0,1.56,10.96]],"ltp":1.72,"tv":4092.7,"id":9631939}]}]}
{"op":"mcm","clk":"4289701495","pt":1632492762061,"mc":[{"id":"1.188075669","rc":[{"trd":[[1.56,10.96],[1.61,4.38],[1.7,48.02]],"batl":[[0,1.58,4.38]],"ltp":1.7,"tv":4112.42,"id":9631939},{"trd":[[2.42,26.01],[2.62,2.69],[2.78,6.15]],"ltp":2.42,"tv":463.4,"id":9454286}],"tv":4575.82}]}
{"op":"mcm","clk":"4289701570","pt":1632492763065,"mc":[{"id":"1.188075669","rc":[{"trd":[[1.57,4.38],[1.58,56.22]],"batb":[[0,1.74,158.64],[1,1.72,220.07],[2,1.54,228.65]],"batl":[[0,1.8,169.11],[1,1.82,184.85],[2,2.08,4]],"ltp":1.58,"tv":4134.32,"id":9631939}],"tv":4597.73}]}
{"op":"mcm","clk":"4289701650","pt":1632492763973,"mc":[{"id":"1.188075669","rc":[{"trd":[[1.74,4.38]],"batb":[[0,1.74,156.45]],"ltp":1.74,"tv":4138.7,"id":9631939}],"tv":4602.11}]}
{"op":"mcm","clk":"4289701803","pt":1632492765671,"mc":[{"id":"1.188075669","rc":[{"trd":[[1.74,8.76]],"batb":[[0,1.74,154.26]],"ltp":1.74,"tv":4143.08,"id":9631939}],"tv":4606.49}]}
{"op":"mcm","clk":"4289701869","pt":1632492766467,"mc":[{"id":"1.188075669","rc":[{"trd":[[1.74,13.14]],"batb":[[0,1.54,228.65],[1,1.53,4],[2,1.3,175.26]],"batl":[[0,2.08,4],[1,100,0.73],[2,2.08,0]],"ltp":1.74,"tv":4147.46,"id":9631939}],"tv":4610.87}]}
{"op":"mcm","clk":"4289701970","pt":1632492767676,"mc":[{"id":"1.188075669","rc":[{"batl":[[0,1.6,4.38],[1,2.08,4],[2,100,0.73]],"ltp":1.74,"tv":4147.46,"id":9631939}]}]}
{"op":"mcm","clk":"4289702176","pt":1632492770136,"mc":[{"id":"1.188075669","rc":[{"batb":[[0,1.55,274.29],[1,1.54,394.37],[2,1.53,4]],"batl":[[1,2.08,151.18],[2,2.1,120.21]],"ltp":1.74,"tv":4147.46,"id":9631939}]}]}
{"op":"mcm","clk":"4289702197","pt":1632492770351,"mc":[{"id":"1.188075669","rc":[{"batb":[[1,1.77,409.56],[2,1.7,15.02]],"ltp":2.42,"tv":463.4,"id":9454286}]}]}
{"op":"mcm","clk":"4289702374","pt":1632492772051,"mc":[{"id":"1.188075669","rc":[{"batb":[[2,1.3,175.26]],"batl":[[0,1.56,6.57],[1,1.57,6.57],[2,1.6,4.38]],"ltp":1.74,"tv":4147.46,"id":9631939},{"batl":[[1,810,0.07],[2,810,0]],"ltp":2.42,"tv":463.4,"id":9454286}]}]}
{"op":"mcm","clk":"4289702481","pt":1632492773058,"mc":[{"id":"1.188075669","rc":[{"batb":[[2,1.25,147.22]],"batl":[[0,1.56,15.34]],"ltp":1.74,"tv":4147.46,"id":9631939}]}]}
{"op":"mcm","clk":"4289702581","pt":1632492773946,"mc":[{"id":"1.188075669","rc":[{"trd":[[1.56,36.63]],"batb":[[0,1.55,279.29]],"batl":[[0,1.56,2.5]],"ltp":1.56,"tv":4173.14,"id":9631939}],"tv":4636.54}]}
{"op":"mcm","clk":"4289702670","pt":1632492774997,"mc":[{"id":"1.188075669","rc":[{"trd":[[1.56,41.62],[1.57,17.52],[1.6,13.14]],"batb":[[0,1.6,1.47],[1,1.55,279.29],[2,1.54,394.37]],"batl":[[0,2.08,151.81],[1,2.1,120.21],[2,100,0.73]],"ltp":1.6,"tv":4204.42,"id":9631939}],"tv":4667.82}]}
{"op":"mcm","clk":"4289702695","pt":1632492775283,"mc":[{"id":"1.188075669","rc":[{"batb":[[1,1.57,4.35],[2,1.55,279.29]],"ltp":1.6,"tv":4204.42,"id":9631939}]}]}
{"op":"mcm","clk":"4289702814","pt":1632492776865,"mc":[{"id":"1.188075669","rc":[{"batb":[[0,1.56,6.57],[1,1.55,279.29],[2,1.54,394.37]],"batl":[[0,2.08,4.63],[1,100,0.73],[2,100,0]],"ltp":1.6,"tv":4204.42,"id":9631939}]}]}
{"op":"mcm","clk":"4289702891","pt":1632492777973,"mc":[{"id":"1.188075669","rc":[{"batb":[[0,1.55,279.29],[1,1.54,394.37],[2,1.25,147.22]],"ltp":1.6,"tv":4204.42,"id":9631939},{"batb":[[1,1.91,2],[2,1.77,409.56]],"ltp":2.42,"tv":463.4,"id":9454286}]}]}
{"op":"mcm","clk":"4289702972","pt":1632492778979,"mc":[{"id":"1.188075669","rc":[{"trd":[[1.55,276.48]],"batb":[[0,1.55,144.05]],"ltp":1.55,"tv":4474.9,"id":9631939},{"batb":[[2,1.7,15.02]],"batl":[[0,2.82,4]],"ltp":2.42,"tv":463.4,"id":9454286}],"tv":4938.3}]}
{"op":"mcm","clk":"4289703080","pt":1632492780188,"mc":[{"id":"1.188075669","rc":[{"trd":[[1.55,315.7]],"batb":[[0,1.55,119.44],[1,1.54,391.37]],"batl":[[0,1.58,10.95],[1,1.6,318.79],[2,1.61,138.77]],"ltp":1.55,"tv":4514.12,"id":9631939},{"batb":[[0,2.64,362.22],[1,2.62,351.56],[2,2.6,351.56]],"batl":[[0,2.78,275.83],[1,2.84,13.67],[2,2.9,329.74]],"ltp":2.42,"tv":463.4,"id":9454286}],"tv":4977.52}]}
{"op":"mcm","clk":"4289703168","pt":1632492781216,"mc":[{"id":"1.188075669","rc":[{"batb":[[0,1.56,80.17],[1,1.55,119.44],[2,1.54,391.37]],"batl":[[0,1.58,17.52]],"ltp":1.55,"tv":4514.12,"id":9631939},{"batb":[[0,2.66,86.72],[1,2.64,362.22],[2,2.62,351.56]],"batl":[[0,2.78,320.8]],"ltp":2.42,"tv":463.4,"id":9454286}]}]}
{"op":"mcm","clk":"4289703260","pt":1632492782221,"mc":[{"id":"1.188075669","rc":[{"batl":[[1,1.59,2.19],[2,1.6,320.98]],"ltp":1.55,"tv":4514.12,"id":9631939}]}]}
{"op":"mcm","clk":"4289703311","pt":1632492782705,"mc":[{"id":"1.188075669","rc":[{"batb":[[1,1.55,179.94]],"batl":[[2,1.6,393.48]],"ltp":1.55,"tv":4514.12,"id":9631939}]}]}
{"op":"mcm","clk":"4289703443","pt":1632492784089,"mc":[{"id":"1.188075669","rc":[{"batb":[[0,1.57,308],[1,1.56,80.17],[2,1.55,179.94]],"batl":[[0,1.58,10.95],[1,1.6,391.29],[2,1.61,138.77]],"ltp":1.55,"tv":4514.12,"id":9631939}]}]}
{"op":"mcm","clk":"4289703535","pt":1632492785199,"mc":[{"id":"1.188075669","rc":[{"batb":[[1,1.55,179.94],[2,1.54,391.37]],"ltp":1.55,"tv":4514.12,"id":9631939}]}]}
{"op":"mcm","clk":"4289703713","pt":1632492787169,"mc":[{"id":"1.188075669","rc":[{"trd":[[1.58,60.22]],"batl":[[0,1.58,8.95]],"ltp":1.58,"tv":4518.12,"id":9631939}],"tv":4981.52}]}
{"op":"mcm","clk":"4289703801","pt":1632492788120,"mc":[{"id":"1.188075669","rc":[{"batb":[[0,1.57,387.47]],"ltp":1.58,"tv":4518.12,"id":9631939}]}]}
{"op":"mcm","clk":"4289704087","pt":1632492791628,"mc":[{"id":"1.188075669","rc":[{"batl":[[1,1.6,258.65]],"ltp":1.58,"tv":4518.12,"id":9631939}]}]}
{"op":"mcm","clk":"4289704273","pt":1632492793580,"mc":[{"id":"1.188075669","rc":[{"trd":[[1.58,61.78]],"batl":[[0,1.58,8.17]],"ltp":1.58,"tv":4519.68,"id":9631939}],"tv":4983.08}]}
{"op":"mcm","clk":"4289704375","pt":1632492795011,"mc":[{"id":"1.188075669","rc":[{"batb":[[0,1.57,543.47]],"ltp":1.58,"tv":4519.68,"id":9631939}]}]}
{"op":"mcm","clk":"4289704508","pt":1632492796720,"mc":[{"id":"1.188075669","rc":[{"trd":[[1.58,73.78]],"batl":[[0,1.58,2.17]],"ltp":1.58,"tv":4531.68,"id":9631939}],"tv":4995.08}]}
{"op":"mcm","clk":"4289704619","pt":1632492798200,"mc":[{"id":"1.188075669","rc":[{"batl":[[0,1.6,258.65],[1,1.61,138.77],[2,1.68,15]],"ltp":1.58,"tv":4531.68,"id":9631939},{"batl":[[1,2.9,329.74],[2,2.92,320.04]],"ltp":2.42,"tv":463.4,"id":9454286}]}]}
{"op":"mcm","clk":"4289704766","pt":1632492800043,"mc":[{"id":"1.188075669","rc":[{"batb":[[0,1.58,2.53],[1,1.57,543.47],[2,1.55,179.94]],"ltp":1.58,"tv":4531.68,"id":9631939},{"batb":[[1,2.6,4],[2,2.58,3]],"batl":[[0,2.78,44.97],[1,3.45,183.67],[2,810,0.07]],"ltp":2.42,"tv":463.4,"id":9454286}]}]}
{"op":"mcm","clk":"4289704851","pt":1632492801002,"mc":[{"id":"1.188075669","rc":[{"batb":[[1,1.57,79.47],[2,1.48,267.15]],"batl":[[0,1.68,15],[1,2.06,4],[2,100,0.73]],"ltp":1.58,"tv":4531.68,"id":9631939},{"batb":[[0,2.3,127.21],[1,1.92,402.07],[2,1.8,10.52]],"ltp":2.42,"tv":463.4,"id":9454286}]}]}
{"op":"mcm","clk":"4289704883","pt":1632492801327,"mc":[{"id":"1.188075669","rc":[{"batb":[[1,1.48,267.15],[2,1.25,147.22]],"batl":[[0,2.06,4],[1,100,0.73],[2,100,0]],"ltp":1.58,"tv":4531.68,"id":9631939},{"batl":[[0,3.45,183.67],[1,810,0.07],[2,810,0]],"ltp":2.42,"tv":463.4,"id":9454286}]}]}
{"op":"mcm","clk":"4289705024","pt":1632492803025,"mc":[{"id":"1.188075669","rc":[{"batb":[[0,1.48,267.15],[1,1.25,147.22],[2,1.2,394.35]],"ltp":1.58,"tv":4531.68,"id":9631939}]}]}
{"op":"mcm","clk":"4289705218","pt":1632492805142,"mc":[{"id":"1.188075669","rc":[{"batb":[[0,1.71,2.19],[1,1.48,267.15],[2,1.25,147.22]],"batl":[[0,1.77,2],[1,2.06,4],[2,100,0.73]],"ltp":1.58,"tv":4531.68,"id":9631939},{"batb":[[0,2.3,131.21],[1,2.28,4],[2,1.92,402.07]],"ltp":2.42,"tv":463.4,"id":9454286}]}]}
{"op":"mcm","clk":"4289705314","pt":1632492806210,"mc":[{"id":"1.188075669","rc":[{"batb":[[0,1.76,2.19],[1,1.74,2.19],[2,1.72,2.19]],"ltp":1.58,"tv":4531.68,"id":9631939},{"batl":[[0,3.1,3]],"ltp":2.42,"tv":463.4,"id":9454286}]}]}
{"op":"mcm","clk":"4289705390","pt":1632492807028,"mc":[{"id":"1.188075669","rc":[{"trd":[[1.75,25.15],[1.76,4.95]],"ltp":1.76,"tv":4544.25,"id":9631939},{"trd":[[2.32,0.43]],"ltp":2.32,"tv":463.83,"id":9454286}],"tv":5008.09}]}
{"op":"mcm","clk":"4289705415","pt":1632492807333,"mc":[{"id":"1.188075669","rc":[{"trd":[[1.71,129.14],[1.72,30.11],[1.74,17.52],[1.76,9.33]],"batb":[[0,1.58,134],[1,1.57,153.67],[2,1.48,272.15]],"batl":[[0,1.62,133.57],[1,1.63,133.35],[2,1.77,2]],"ltp":1.71,"tv":4566.16,"id":9631939}],"tv":5029.99}]}
{"op":"mcm","clk":"4289705547","pt":1632492808755,"mc":[{"id":"1.188075669","rc":[{"trd":[[1.62,51.12]],"batl":[[0,1.62,129.19]],"ltp":1.62,"tv":4574.92,"id":9631939}],"tv":5038.76}]}
{"op":"mcm","clk":"4289705640","pt":1632492809856,"mc":[{"id":"1.188075669","rc":[{"batl":[[2,1.76,2]],"ltp":1.62,"tv":4574.92,"id":9631939},{"batl":[[1,3.3,195.4],[2,810,0.07]],"ltp":2.32,"tv":463.83,"id":9454286}]}]}
{"op":"mcm","clk":"4289705970","pt":1632492813167,"mc":[{"id":"1.188075669","rc":[{"batb":[[0,1.48,272.15],[1,1.47,6],[2,1.25,147.22]],"batl":[[0,1.76,2],[1,1.77,2],[2,2.06,4]],"ltp":1.62,"tv":4574.92,"id":9631939}]}]}
{"op":"mcm","clk":"4289706023","pt":1632492813749,"mc":[{"id":"1.188075669","rc":[{"batl":[[0,1.76,2.63]],"ltp":1.62,"tv":4574.92,"id":9631939}]}]}
{"op":"mcm","clk":"4289706163","pt":1632492815433,"mc":[{"id":"1.188075669","rc":[{"batb":[[0,1.48,560.67],[1,1.47,206.38]],"batl":[[0,1.75,175.72],[1,1.76,2.63],[2,1.77,204.59]],"ltp":1.62,"tv":4574.92,"id":9631939}]}]}
{"op":"mcm","clk":"4289706292","pt":1632492816933,"mc":[{"id":"1.188075669","rc":[{"batl":[[1,1.76,4.98],[2,1.77,202.59]],"ltp":1.62,"tv":4574.92,"id":9631939},{"batb":[[1,1.92,402.07],[2,1.7,15.02]],"ltp":2.32,"tv":463.83,"id":9454286}]}]}
{"op":"mcm","clk":"4289706347","pt":1632492817682,"mc":[{"id":"1.188075669","rc":[{"batl":[[0,1.76,4.98],[1,100,0.73],[2,1.77,0]],"ltp":1.62,"tv":4574.92,"id":9631939}]}]}
{"op":"mcm","clk":"4289706500","pt":1632492819157,"mc":[{"id":"1.188075669","rc":[{"trd":[[1.76,13.71]],"batl":[[0,1.76,2.79]],"ltp":1.76,"tv":4579.3,"id":9631939},{"batl":[[1,810,0.07],[2,810,0]],"ltp":2.32,"tv":463.83,"id":9454286}],"tv":5043.14}]}
{"op":"mcm","clk":"4289706605","pt":1632492820161,"mc":[{"id":"1.188075669","rc":[{"trd":[[1.76,18.1]],"batb":[[0,1.75,2.19],[1,1.74,6.57],[2,1.73,4.38]],"batl":[[0,100,1.32],[1,100,0]],"ltp":1.76,"tv":4583.68,"id":9631939},{"batb":[[2,1.6,87.64]],"batl":[[0,810,0.07],[1,810,0]],"ltp":2.32,"tv":463.83,"id":9454286}],"tv":5047.52}]}
{"op":"mcm","clk":"4289706692","pt":1632492821169,"mc":[{"id":"1.188075669","rc":[{"trd":[[1.51,42.73],[1.52,32.76],[1.73,13.14],[1.74,30.67],[1.75,29.53]],"batb":[[0,1.5,9.49],[1,1.48,555.67],[2,1.47,200.38]],"batl":[[0,1.52,188.89],[1,1.53,301.92],[2,1.54,163.25]],"ltp":1.52,"tv":4643.52,"id":9631939},{"trd":[[2.96,33.56]],"batb":[[0,2.9,329.74],[1,2.88,328.62],[2,2.86,320.04]],"batl":[[0,2.96,212.45],[1,3,4.74],[2,3.2,298.82]],"ltp":2.96,"tv":474.24,"id":9454286}],"tv":5117.77}]}
{"op":"mcm","clk":"4289706786","pt":1632492822162,"mc":[{"id":"1.188075669","rc":[{"trd":[[1.52,37.14]],"batb":[[0,1.5,94.34]],"batl":[[0,1.52,186.7]],"ltp":1.52,"tv":4647.9,"id":9631939},{"batb":[[1,2.88,399.31]],"batl":[[1,2.98,42.64],[2,3,4.74]],"ltp":2.96,"tv":474.24,"id":9454286}],"tv":5122.15}]}
{"op":"mcm","clk":"4289706878","pt":1632492823164,"mc":[{"id":"1.188075669","rc":[{"batl":[[1,3,4.74],[2,3.2,298.82]],"ltp":2.96,"tv":474.24,"id":9454286}]}]}
{"op":"mcm","clk":"4289706962","pt":1632492823961,"mc":[{"id":"1.188075669","rc":[{"trd":[[1.52,410.54]],"batl":[[0,1.53,301.92],[1,1.54,163.25],[2,1.6,554.65]],"ltp":1.52,"tv":5021.3,"id":9631939},{"trd":[[2.96,38.02]],"batl":[[0,2.96,210.22]],"ltp":2.96,"tv":478.7,"id":9454286}],"tv":5500.01}]}
{"op":"mcm","clk":"4289707095","pt":1632492825686,"mc":[{"id":"1.188075669","rc":[{"trd":[[1.51,119.91]],"ltp":1.51,"tv":5098.48,"id":9631939},{"trd":[[2.96,77.39]],"batl":[[0,2.96,170.85],[1,2.98,42.64],[2,3,4.74]],"ltp":2.96,"tv":518.07,"id":9454286}],"tv":5616.56}]}
{"op":"mcm","clk":"4289707213","pt":1632492827167,"mc":[{"id":"1.188075669","rc":[{"trd":[[1.51,129.91]],"batb":[[0,1.51,182],[1,1.5,94.34],[2,1.48,555.67]],"ltp":1.51,"tv":5108.48,"id":9631939}],"tv":5626.56}]}
{"op":"mcm","clk":"4289707550","pt":1632492830997,"mc":[{"id":"1.188075669","rc":[{"trd":[[1.53,713]],"batl":[[0,1.54,163.25],[1,1.6,554.65],[2,1.68,1.71]],"ltp":1.53,"tv":5765.88,"id":9631939},{"trd":[[2.9,28.26]],"batb":[[0,2.9,301.48]],"ltp":2.9,"tv":546.33,"id":9454286}],"tv":6312.22}]}
{"op":"mcm","clk":"4289707600","pt":1632492831689,"mc":[{"id":"1.188075669","rc":[{"batb":[[2,1.48,460.68]],"batl":[[2,1.75,5]],"ltp":1.53,"tv":5765.88,"id":9631939}]}]}
{"op":"mcm","clk":"4289707772","pt":1632492834168,"mc":[{"id":"1.188075669","rc":[{"trd":[[1.51,139.91],[1.53,713.63]],"batb":[[0,1.51,177]],"ltp":1.51,"tv":5776.51,"id":9631939},{"trd":[[2.9,28.59]],"batb":[[0,2.9,301.15]],"ltp":2.9,"tv":546.66,"id":9454286}],"tv":6323.18}]}
{"op":"mcm","clk":"4289707830","pt":1632492834906,"mc":[{"id":"1.188075669","rc":[{"trd":[[1.53,716.67]],"batb":[[0,1.51,290],[2,1.49,265.74]],"batl":[[0,1.54,297.5],[1,1.55,158.33],[2,1.6,554.65]],"ltp":1.53,"tv":5779.55,"id":9631939},{"trd":[[2.9,30.19]],"batb":[[0,2.9,299.55]],"ltp":2.9,"tv":548.26,"id":9454286}],"tv":6327.82}]}
{"op":"mcm","clk":"4289708174","pt":1632492839207,"mc":[{"id":"1.188075669","rc":[{"batb":[[1,1.5,84.85],[2,1.44,298.28]],"batl":[[0,1.75,5],[1,1.76,4.63],[2,100,0.73]],"ltp":1.53,"tv":5779.55,"id":9631939},{"batb":[[0,2.6,91.27],[1,2.36,3],[2,1.92,402.07]],"batl":[[0,2.98,42.64],[1,3.65,173.5],[2,810,0.07]],"ltp":2.9,"tv":548.26,"id":9454286}]}]}
{"op":"mcm","clk":"4289708236","pt":1632492839993,"mc":[{"id":"1.188075669","rc":[{"batb":[[0,1.5,84.85],[1,1.44,298.28],[2,1.25,147.22]],"ltp":1.53,"tv":5779.55,"id":9631939}]}]}
{"op":"mcm","clk":"4289708259","pt":1632492840313,"mc":[{"id":"1.188075669","rc":[{"batb":[[0,1.44,298.28],[1,1.25,147.22],[2,1.2,394.35]],"ltp":1.53,"tv":5779.55,"id":9631939},{"batl":[[0,3.65,173.5],[1,810,0.07],[2,810,0]],"ltp":2.9,"tv":548.26,"id":9454286}]}]}
{"op":"mcm","clk":"4289708415","pt":1632492842217,"mc":[{"id":"1.188075669","rc":[{"batb":[[0,1.45,324.31],[1,1.44,515.9],[2,1.25,147.22]],"batl":[[0,1.62,188.62],[1,1.63,132.39],[2,1.75,5]],"ltp":1.53,"tv":5779.55,"id":9631939},{"batb":[[0,2.8,3],[1,2.78,3],[2,2.6,91.27]],"ltp":2.9,"tv":548.26,"id":9454286}]}]}
{"op":"mcm","clk":"4289708461","pt":1632492842692,"mc":[{"id":"1.188075669","rc":[{"batl":[[1,1.63,138.39]],"ltp":1.53,"tv":5779.55,"id":9631939},{"batb":[[0,2.6,94.27],[1,2.58,3],[2,2.36,3]],"ltp":2.9,"tv":548.26,"id":9454286}]}]}
{"op":"mcm","clk":"4289708529","pt":1632492843619,"mc":[{"id":"1.188075669","rc":[{"batb":[[0,1.44,305.28],[1,1.43,8]],"ltp":1.53,"tv":5779.55,"id":9631939},{"batl":[[0,3.3,3],[1,3.65,173.5],[2,810,0.07]],"ltp":2.9,"tv":548.26,"id":9454286}]}]}
{"op":"mcm","clk":"4289708591","pt":1632492844312,"mc":[{"id":"1.188075669","rc":[{"batl":[[1,810,0.07],[2,810,0]],"ltp":2.9,"tv":548.26,"id":9454286}]}]}
{"op":"mcm","clk":"4289708736","pt":1632492846217,"mc":[{"id":"1.188075669","rc":[{"trd":[[1.45,78.24]],"batl":[[0,1.45,4.95],[1,1.62,188.62],[2,1.63,132.39]],"ltp":1.45,"tv":5791.56,"id":9631939},{"batb":[[0,2.6,91.27],[1,2.36,3],[2,1.92,402.07]],"batl":[[0,3.25,3],[1,3.3,3],[2,810,0.07]],"ltp":2.9,"tv":548.26,"id":9454286}],"tv":6339.82}]}
{"op":"mcm","clk":"4289708820","pt":1632492847223,"mc":[{"id":"1.188075669","rc":[{"trd":[[1.45,83.19],[1.58,82.55]],"batb":[[0,1.57,508.8],[1,1.56,157.07],[2,1.44,305.28]],"batl":[[0,1.62,208.24],[1,1.63,132.39],[2,1.65,579.54]],"ltp":1.58,"tv":5805.27,"id":9631939},{"trd":[[2.72,5.08],[3.2,16.67]],"batl":[[0,2.72,251.1],[1,2.8,341.52],[2,2.82,331.48]],"ltp":2.72,"tv":555.58,"id":9454286}],"tv":6360.86}]}
{"op":"mcm","clk":"4289708900","pt":1632492848015,"mc":[{"id":"1.188075669","rc":[{"trd":[[1.58,102.03]],"batb":[[1,1.56,373.53],[2,1.49,256.69]],"ltp":1.58,"tv":5824.75,"id":9631939},{"trd":[[2.72,16.4]],"batb":[[2,2.26,132.44]],"batl":[[0,2.72,239.78]],"ltp":2.72,"tv":566.9,"id":9454286}],"tv":6391.66}]}
{"op":"mcm","clk":"4289709007","pt":1632492849126,"mc":[{"id":"1.188075669","rc":[{"batb":[[1,2.56,3],[2,2.54,3]],"ltp":2.72,"tv":566.9,"id":9454286}]}]}
{"op":"mcm","clk":"4289709272","pt":1632492851904,"mc":[{"id":"1.188075669","rc":[{"batb":[[0,1.59,118],[1,1.57,508.8],[2,1.56,373.53]],"ltp":1.58,"tv":5824.75,"id":9631939},{"batl":[[0,2.72,285.52]],"ltp":2.72,"tv":566.9,"id":9454286}]}]}
{"op":"mcm","clk":"4289709333","pt":1632492852631,"mc":[{"id":"1.188075669","rc":[{"batb":[[1,1.58,78.78],[2,1.57,508.8]],"ltp":1.58,"tv":5824.75,"id":9631939}]}]}
{"op":"mcm","clk":"4289709519","pt":1632492855218,"mc":[{"id":"1.188075669","rc":[{"batb":[[0,1.59,236]],"ltp":1.58,"tv":5824.75,"id":9631939}]}]}
{"op":"mcm","clk":"4289709573","pt":1632492855841,"mc":[{"id":"1.188075669","rc":[{"trd":[[1.59,0.4]],"batb":[[0,1.59,235.8]],"ltp":1.59,"tv":5825.15,"id":9631939}],"tv":6392.06}]}
{"op":"mcm","clk":"4289709664","pt":1632492857045,"mc":[{"id":"1.188075669","rc":[{"batl":[[0,1.62,188.62]],"ltp":1.59,"tv":5825.15,"id":9631939}]}]}
{"op":"mcm","clk":"4289709694","pt":1632492857356,"mc":[{"id":"1.188075669","rc":[{"batb":[[1,1.57,508.8],[2,1.56,373.53]],"ltp":1.59,"tv":5825.15,"id":9631939}]}]}
{"op":"mcm","clk":"4289709797","pt":1632492858463,"mc":[{"id":"1.188075669","rc":[{"batb":[[1,1.57,237.83]],"ltp":1.59,"tv":5825.15,"id":9631939}]}]}
{"op":"mcm","clk":"4289709963","pt":1632492860833,"mc":[{"id":"1.188075669","rc":[{"batb":[[0,1.59,313.91]],"ltp":1.59,"tv":5825.15,"id":9631939},{"batb":[[2,2.26,132.44]],"ltp":2.72,"tv":566.9,"id":9454286}]}]}
{"op":"mcm","clk":"4289710004","pt":1632492861353,"mc":[{"id":"1.188075669","rc":[{"batb":[[0,1.59,235.8]],"ltp":1.59,"tv":5825.15,"id":9631939}]}]}
{"op":"mcm","clk":"4289710266","pt":1632492864051,"mc":[{"id":"1.188075669","rc":[{"batb":[[2,2.54,3]],"ltp":2.72,"tv":566.9,"id":9454286}]}]}
{"op":"mcm","clk":"4289710410","pt":1632492865157,"mc":[{"id":"1.188075669","rc":[{"batb":[[1,1.57,79.47],[2,1.49,256.69]],"batl":[[0,1.74,16.38],[1,1.75,5],[2,1.76,4.63]],"ltp":1.59,"tv":5825.15,"id":9631939},{"batb":[[0,2.34,3.72],[1,2.26,135.92],[2,1.92,402.07]],"batl":[[0,2.72,45.74],[1,3.2,3],[2,3.3,195.4]],"ltp":2.72,"tv":566.9,"id":9454286}]}]}
{"op":"mcm","clk":"4289710492","pt":1632492866162,"mc":[{"id":"1.188075669","rc":[{"batb":[[0,1.49,256.69],[1,1.46,6],[2,1.25,147.22]],"batl":[[0,1.75,5.63],[1,1.76,4.63],[2,1.79,18.5]],"ltp":1.59,"tv":5825.15,"id":9631939},{"batb":[[0,2.26,135.75],[1,1.92,402.07],[2,1.8,10.52]],"ltp":2.72,"tv":566.9,"id":9454286}]}]}
{"op":"mcm","clk":"4289710502","pt":1632492866265,"mc":[{"id":"1.188075669","rc":[{"batl":[[0,3.2,3],[1,3.3,195.4],[2,810,0.07]],"ltp":2.72,"tv":566.9,"id":9454286}]}]}
{"op":"mcm","clk":"4289710665","pt":1632492868164,"mc":[{"id":"1.188075669","rc":[{"batb":[[0,1.5,270.65],[1,1.49,470.01],[2,1.46,6]],"batl":[[2,1.78,164.92]],"ltp":1.59,"tv":5825.15,"id":9631939},{"batl":[[0,3.05,2.1],[1,3.2,3],[2,3.3,195.4]],"ltp":2.72,"tv":566.9,"id":9454286}]}]}
{"op":"mcm","clk":"4289710733","pt":1632492868953,"mc":[{"id":"1.188075669","rc":[{"batl":[[0,1.74,5.63],[1,1.75,5],[2,1.76,4.63]],"ltp":1.59,"tv":5825.15,"id":9631939},{"batb":[[0,2.34,6.22],[1,2.32,3],[2,2.3,4]],"ltp":2.72,"tv":566.9,"id":9454286}]}]}
{"op":"mcm","clk":"4289710808","pt":1632492869952,"mc":[{"id":"1.188075669","rc":[{"batb":[[0,1.49,281.7],[1,1.46,6],[2,1.25,147.22]],"batl":[[0,1.5,4.38],[1,1.74,5.63],[2,1.75,5]],"ltp":1.59,"tv":5825.15,"id":9631939},{"batb":[[0,2.34,3]],"ltp":2.72,"tv":566.9,"id":9454286}]}]}
{"op":"mcm","clk":"4289710897","pt":1632492871162,"mc":[{"id":"1.188075669","rc":[{"batl":[[1,1.51,2.19],[2,1.52,4.38]],"ltp":1.59,"tv":5825.15,"id":9631939},{"batb":[[0,2.36,3],[1,2.34,3],[2,2.32,3]],"ltp":2.72,"tv":566.9,"id":9454286}]}]}
{"op":"mcm","clk":"4289710993","pt":1632492872169,"mc":[{"id":"1.188075669","rc":[{"trd":[[1.5,67.31],[1.51,144.29],[1.52,414.92],[1.53,718.86],[1.56,43.81],[1.61,8.76]],"batl":[[0,1.74,23.38],[1,1.75,5],[2,1.76,4.63]],"ltp":1.61,"tv":5847.06,"id":9631939},{"trd":[[2.76,1.24],[2.88,1.16],[2.92,33.69],[2.96,79.63],[3,41.52]],"ltp":2.76,"tv":576.01,"id":9454286}],"tv":6423.07}]}
{"op":"mcm","clk":"4289711054","pt":1632492872759,"mc":[{"id":"1.188075669","rc":[{"batl":[[0,1.74,5.63]],"ltp":1.61,"tv":5847.06,"id":9631939}]}]}
{"op":"mcm","clk":"4289711104","pt":1632492873274,"mc":[{"id":"1.188075669","rc":[{"batb":[[0,1.6,198.26],[1,1.59,146.05],[2,1.49,281.7]],"batl":[[0,1.65,185.68],[1,1.67,244.77],[2,1.74,5.63]],"ltp":1.61,"tv":5847.06,"id":9631939}]}]}
{"op":"mcm","clk":"4289711245","pt":1632492874968,"mc":[{"id":"1.188075669","rc":[{"batb":[[0,1.49,281.7],[1,1.46,6],[2,1.25,147.22]],"batl":[[0,1.74,5.63],[1,1.75,5],[2,1.76,4.63]],"ltp":1.61,"tv":5847.06,"id":9631939}]}]}
{"op":"mcm","clk":"4289711320","pt":1632492876074,"mc":[{"id":"1.188075669","rc":[{"batb":[[1,2.34,6.72]],"ltp":2.76,"tv":576.01,"id":9454286}]}]}
{"op":"mcm","clk":"4289711389","pt":1632492876975,"mc":[{"id":"1.188075669","rc":[{"batb":[[1,2.34,3]],"ltp":2.76,"tv":576.01,"id":9454286}]}]}
{"op":"mcm","clk":"4289711477","pt":1632492877972,"mc":[{"id":"1.188075669","rc":[{"batb":[[0,1.5,270.65],[1,1.49,470.01],[2,1.46,6]],"ltp":1.61,"tv":5847.06,"id":9631939}]}]}
{"op":"mcm","clk":"4289711696","pt":1632492880859,"mc":[{"id":"1.188075669","rc":[{"batl":[[1,1.76,4.63],[2,1.79,18.5]],"ltp":1.61,"tv":5847.06,"id":9631939},{"batb":[[1,2.26,135.75],[2,1.92,402.07]],"batl":[[2,810,0.07]],"ltp":2.76,"tv":576.01,"id":9454286}]}]}
{"op":"mcm","clk":"4289711816","pt":1632492882179,"mc":[{"id":"1.188075669","rc":[{"trd":[[1.5,107.85],[1.52,417.11]],"batb":[[0,1.5,250.38]],"batl":[[0,1.53,4.38],[1,1.55,2515.95],[2,1.56,154.71]],"ltp":1.52,"tv":5889.79,"id":9631939},{"trd":[[2.92,34.83]],"batb":[[0,2.88,6.77],[1,2.8,341.52],[2,2.78,331.48]],"batl":[[0,2.92,226.23],[1,2.96,5.57],[2,3.05,2.1]],"ltp":2.92,"tv":577.15,"id":9454286}],"tv":6466.95}]}
{"op":"mcm","clk":"4289711926","pt":1632492883176,"mc":[{"id":"1.188075669","rc":[{"trd":[[1.52,425.87]],"batb":[[0,1.52,83.2],[1,1.5,250.38],[2,1.49,470.01]],"batl":[[1,1.55,451.37]],"ltp":1.52,"tv":5898.55,"id":9631939},{"trd":[[2.92,39.39]],"batb":[[1,2.82,74.15],[2,2.8,341.52]],"batl":[[0,2.92,264.97]],"ltp":2.92,"tv":581.71,"id":9454286}],"tv":6480.27}]}
{"op":"mcm","clk":"4289712112","pt":1632492884959,"mc":[{"id":"1.188075669","rc":[{"batb":[[0,1.5,250.38],[1,1.49,470.01],[2,1.46,291.63]],"ltp":1.52,"tv":5898.55,"id":9631939},{"batl":[[0,2.92,221.67]],"ltp":2.92,"tv":581.71,"id":9454286}]}]}
{"op":"mcm","clk":"4289712228","pt":1632492886172,"mc":[{"id":"1.188075669","rc":[{"batb":[[0,1.52,182],[1,1.5,250.38],[2,1.49,470.01]],"batl":[[0,1.55,451.37],[1,1.56,154.71],[2,1.6,378.15]],"ltp":1.52,"tv":5898.55,"id":9631939}]}]}
{"op":"mcm","clk":"4289712293","pt":1632492887000,"mc":[{"id":"1.188075669","rc":[{"trd":[[1.52,545.23]],"batb":[[0,1.52,122.32]],"ltp":1.52,"tv":6017.91,"id":9631939}],"tv":6599.63}]}
{"op":"mcm","clk":"4289712382","pt":1632492888201,"mc":[{"id":"1.188075669","rc":[{"batb":[[1,1.5,335.23]],"ltp":1.52,"tv":6017.91,"id":9631939},{"batl":[[2,2.98,42.64]],"ltp":2.92,"tv":581.71,"id":9454286}]}]}
{"op":"mcm","clk":"4289712480","pt":1632492889203,"mc":[{"id":"1.188075669","rc":[{"batb":[[0,1.52,240.32]],"batl":[[2,1.6,396.91]],"ltp":1.52,"tv":6017.91,"id":9631939}]}]}
{"op":"mcm","clk":"4289712731","pt":1632492892100,"mc":[{"id":"1.188075669","rc":[{"batl":[[2,1.6,397.54]],"ltp":1.52,"tv":6017.91,"id":9631939}]}]}
{"op":"mcm","clk":"4289712862","pt":1632492893796,"mc":[{"id":"1.188075669","rc":[{"batl":[[0,1.55,273.39]],"ltp":1.52,"tv":6017.91,"id":9631939}]}]}
{"op":"mcm","clk":"4289712988","pt":1632492895279,"mc":[{"id":"1.188075669","rc":[{"batb":[[0,1.52,372]],"ltp":1.52,"tv":6017.91,"id":9631939}]}]}
{"op":"mcm","clk":"4289713206","pt":1632492898117,"mc":[{"id":"1.188075669","rc":[{"trd":[[1.54,8.34]],"ltp":1.54,"tv":6018.01,"id":9631939},{"trd":[[2.88,1.21]],"batb":[[0,2.88,6.72]],"ltp":2.88,"tv":581.76,"id":9454286}],"tv":6599.77}]}
{"op":"mcm","clk":"4289713474","pt":1632492901204,"mc":[{"id":"1.188075669","rc":[{"batl":[[2,1.6,19.39]],"ltp":1.54,"tv":6018.01,"id":9631939},{"batb":[[0,2.82,74.15],[1,2.76,3],[2,2.66,2.28]],"batl":[[0,2.98,42.64],[1,3.05,2.1],[2,3.15,2.1]],"ltp":2.88,"tv":581.76,"id":9454286}]}]}
{"op":"mcm","clk":"4289713555","pt":1632492902013,"mc":[{"id":"1.188075669","rc":[{"batb":[[0,1.5,84.85],[1,1.49,25.01],[2,1.47,24.67]],"batl":[[0,1.63,21.13],[1,1.74,5.63],[2,1.76,4.63]],"ltp":1.54,"tv":6018.01,"id":9631939},{"batb":[[0,2.58,2.37],[1,2.54,96.17],[2,2.26,3.48]],"ltp":2.88,"tv":581.76,"id":9454286}]}]}
{"op":"mcm","clk":"4289713606","pt":1632492902605,"mc":[{"id":"1.188075669","rc":[{"batb":[[0,1.47,24.67],[1,1.46,291.63],[2,1.25,147.22]],"ltp":1.54,"tv":6018.01,"id":9631939},{"batl":[[0,3.15,2.1],[1,3.2,3],[2,3.65,173.5]],"ltp":2.88,"tv":581.76,"id":9454286}]}]}
{"op":"mcm","clk":"4289713866","pt":1632492905208,"mc":[{"id":"1.188075669","rc":[{"batb":[[1,1.46,6],[2,1.45,285.96]],"batl":[[0,1.6,19.63],[1,1.61,5],[2,1.63,25.5]],"ltp":1.54,"tv":6018.01,"id":9631939},{"batb":[[0,2.66,13.03],[1,2.64,4],[2,2.58,5.37]],"ltp":2.88,"tv":581.76,"id":9454286}]}]}
{"op":"mcm","clk":"4289713960","pt":1632492906219,"mc":[{"id":"1.188075669","rc":[{"batb":[[0,1.47,30.67]],"batl":[[0,1.6,4.63]],"ltp":1.54,"tv":6018.01,"id":9631939},{"batb":[[0,2.66,4]],"batl":[[0,3.15,5.1],[2,810,0.07]],"ltp":2.88,"tv":581.76,"id":9454286}]}]}
{"op":"mcm","clk":"4289714029","pt":1632492906900,"mc":[{"id":"1.188075669","rc":[{"batb":[[0,1.52,178.54],[1,1.51,177.97],[2,1.47,30.67]],"batl":[[0,1.56,173.17],[1,1.57,151.71],[2,1.6,4.63]],"ltp":1.54,"tv":6018.01,"id":9631939}]}]}
{"op":"mcm","clk":"4289714207","pt":1632492909224,"mc":[{"id":"1.188075669","rc":[{"batl":[[2,1.6,27.29]],"ltp":1.54,"tv":6018.01,"id":9631939},{"batb":[[0,2.66,6.28]],"batl":[[2,3.45,183.67]],"ltp":2.88,"tv":581.76,"id":9454286}]}]}
{"op":"mcm","clk":"4289714228","pt":1632492909535,"mc":[{"id":"1.188075669","rc":[{"batb":[[2,1.49,25.01]],"ltp":1.54,"tv":6018.01,"id":9631939},{"batl":[[0,3.05,2.3],[1,3.15,5.1],[2,3.2,3]],"ltp":2.88,"tv":581.76,"id":9454286}]}]}
{"op":"mcm","clk":"4289714362","pt":1632492911019,"mc":[{"id":"1.188075669","rc":[{"batb":[[0,1.53,156],[1,1.52,178.54],[2,1.51,177.97]],"ltp":1.54,"tv":6018.01,"id":9631939}]}]}
{"op":"mcm","clk":"4289714545","pt":1632492913220,"mc":[{"id":"1.188075669","rc":[{"batb":[[0,1.49,25.01],[1,1.47,30.67],[2,1.46,6]],"batl":[[0,1.6,27.29],[1,1.61,5],[2,1.63,25.5]],"ltp":1.54,"tv":6018.01,"id":9631939}]}]}
{"op":"mcm","clk":"4289714576","pt":1632492913536,"mc":[{"id":"1.188075669","rc":[{"batb":[[0,1.47,30.67],[1,1.46,6],[2,1.45,285.96]],"batl":[[0,1.6,4.63]],"ltp":1.54,"tv":6018.01,"id":9631939},{"batb":[[0,2.66,4]],"batl":[[0,3.15,5.1],[1,3.2,3],[2,3.45,183.67]],"ltp":2.88,"tv":581.76,"id":9454286}]}]}
{"op":"mcm","clk":"4289714783","pt":1632492916016,"mc":[{"id":"1.188075669","rc":[{"batb":[[1,1.46,294.13],[2,1.45,497.01]],"batl":[[2,1.63,5]],"ltp":1.54,"tv":6018.01,"id":9631939}]}]}
{"op":"mcm","clk":"4289714854","pt":1632492917013,"mc":[{"id":"1.188075669","rc":[{"batl":[[0,1.61,5.63],[1,1.63,5],[2,1.76,5.26]],"ltp":1.54,"tv":6018.01,"id":9631939},{"batb":[[1,2.58,5.37],[2,2.56,99]],"ltp":2.88,"tv":581.76,"id":9454286}]}]}
{"op":"mcm","clk":"4289714867","pt":1632492917227,"mc":[{"id":"1.188075669","rc":[{"batb":[[1,1.46,288.13]],"batl":[[1,1.76,5.26],[2,100,0.73]],"ltp":1.54,"tv":6018.01,"id":9631939},{"batb":[[1,2.58,2.37],[2,2.56,96]],"batl":[[1,3.45,183.67],[2,810,0.07]],"ltp":2.88,"tv":581.76,"id":9454286}]}]}
{"op":"mcm","clk":"4289715042","pt":1632492919120,"mc":[{"id":"1.188075669","rc":[{"trd":[[1.47,43.97]],"batb":[[0,1.47,3.98]],"batl":[[0,1.5,1942.53],[1,1.51,809.22],[2,1.52,614.66]],"ltp":1.47,"tv":6059.39,"id":9631939},{"batb":[[0,3,3.81],[1,2.68,1011.48],[2,2.66,4]],"batl":[[0,3.05,227.1],[1,3.1,6.24],[2,3.15,2.1]],"ltp":2.88,"tv":581.76,"id":9454286}],"tv":6641.15}]}
{"op":"mcm","clk":"4289715121","pt":1632492920022,"mc":[{"id":"1.188075669","rc":[{"batl":[[0,1.5,313.89]],"ltp":1.47,"tv":6059.39,"id":9631939},{"batb":[[1,2.94,164.49],[2,2.82,74.4]],"ltp":2.88,"tv":581.76,"id":9454286}]}]}
{"op":"mcm","clk":"4289715179","pt":1632492920756,"mc":[{"id":"1.188075669","rc":[{"batb":[[1,1.46,376.59]],"ltp":1.47,"tv":6059.39,"id":9631939},{"batb":[[2,2.82,82.64]],"batl":[[2,3.15,43.01]],"ltp":2.88,"tv":581.76,"id":9454286}]}]}
{"op":"mcm","clk":"4289715290","pt":1632492921719,"mc":[{"id":"1.188075669","rc":[{"batb":[[2,1.45,504.01]],"ltp":1.47,"tv":6059.39,"id":9631939}]}]}
{"op":"mcm","clk":"4289715392","pt":1632492922929,"mc":[{"id":"1.188075669","rc":[{"batb":[[0,1.49,325],[1,1.47,3.98],[2,1.46,376.59]],"ltp":1.47,"tv":6059.39,"id":9631939},{"batb":[[2,2.9,3]],"ltp":2.88,"tv":581.76,"id":9454286}]}]}
{"op":"mcm","clk":"4289715486","pt":1632492924126,"mc":[{"id":"1.188075669","rc":[{"trd":[[1.49,314.37]],"batb":[[0,1.49,281.39]],"ltp":1.49,"tv":6146.61,"id":9631939}],"tv":6728.37}]}
{"op":"mcm","clk":"4289715558","pt":1632492925148,"mc":[{"id":"1.188075669","rc":[{"batb":[[1,2.94,164.24]],"ltp":2.88,"tv":581.76,"id":9454286}]}]}
{"op":"mcm","clk":"4289715620","pt":1632492925951,"mc":[{"id":"1.188075669","rc":[{"batb":[[0,1.49,596.39]],"ltp":1.49,"tv":6146.61,"id":9631939}]}]}
{"op":"mcm","clk":"4289716038","pt":1632492931047,"mc":[{"id":"1.188075669","rc":[{"trd":[[1.5,378.33]],"batl":[[0,1.5,38.25]],"ltp":1.5,"tv":6417.09,"id":9631939}],"tv":6998.85}]}
{"op":"mcm","clk":"4289716155","pt":1632492932156,"mc":[{"id":"1.188075669","rc":[{"trd":[[1.5,385.95]],"batb":[[0,1.5,461.4],[1,1.49,596.39],[2,1.47,3.98]],"batl":[[0,1.51,809.22],[1,1.52,614.66],[2,1.53,614.66]],"ltp":1.5,"tv":6424.71,"id":9631939},{"trd":[[3,45.33]],"batb":[[0,2.94,164.24],[1,2.9,3],[2,2.88,3]],"ltp":3.0,"tv":585.57,"id":9454286}],"tv":7010.28}]}
{"op":"mcm","clk":"4289716359","pt":1632492934570,"mc":[{"id":"1.188075669","rc":[{"trd":[[1.5,395.95]],"batb":[[0,1.5,456.4],[2,1.47,160.07]],"batl":[[0,1.51,903.97],[1,1.52,784.94]],"ltp":1.5,"tv":6434.71,"id":9631939},{"batb":[[2,2.82,82.47]],"ltp":3.0,"tv":585.57,"id":9454286}],"tv":7020.28}]}
{"op":"mcm","clk":"4289716604","pt":1632492937647,"mc":[{"id":"1.188075669","rc":[{"batb":[[2,2.88,3]],"ltp":3.0,"tv":585.57,"id":9454286}]}]}
{"op":"mcm","clk":"4289716830","pt":1632492940275,"mc":[{"id":"1.188075669","rc":[{"trd":[[1.51,144.53]],"batl":[[0,1.51,903.85]],"ltp":1.51,"tv":6434.94,"id":9631939}],"tv":7020.52}]}
{"op":"mcm","clk":"4289716933","pt":1632492941362,"mc":[{"id":"1.188075669","rc":[{"batl":[[1,3.15,43.01],[2,3.3,289.78]],"ltp":3.0,"tv":585.57,"id":9454286}]}]}
{"op":"mcm","clk":"4289717020","pt":1632492942283,"mc":[{"id":"1.188075669","rc":[{"trd":[[1.51,1082.57]],"batl":[[0,1.51,434.83]],"ltp":1.51,"tv":7372.98,"id":9631939}],"tv":7958.56}]}
{"op":"mcm","clk":"4289717201","pt":1632492944176,"mc":[{"id":"1.188075669","rc":[{"batb":[[0,2.96,5.84],[1,2.94,164.24],[2,2.9,3]],"batl":[[0,3.05,234.08]],"ltp":3.0,"tv":585.57,"id":9454286}]}]}
{"op":"mcm","clk":"4289717218","pt":1632492944384,"mc":[{"id":"1.188075669","rc":[{"batb":[[0,2.94,164.24],[1,2.9,3],[2,2.88,3]],"batl":[[0,3.05,227.1]],"ltp":3.0,"tv":585.57,"id":9454286}]}]}
{"op":"mcm","clk":"4289717311","pt":1632492945461,"mc":[{"id":"1.188075669","rc":[{"trd":[[1.5,405.95]],"batb":[[0,1.5,451.4]],"ltp":1.5,"tv":7382.98,"id":9631939},{"batl":[[1,3.1,61.7],[2,3.15,43.01]],"ltp":3.0,"tv":585.57,"id":9454286}],"tv":7968.56}]}
{"op":"mcm","clk":"4289717524","pt":1632492947876,"mc":[{"id":"1.188075669","rc":[{"batb":[[0,2.96,5.84],[1,2.94,164.24],[2,2.9,3]],"batl":[[0,3.05,234.08]],"ltp":3.0,"tv":585.57,"id":9454286}]}]}
{"op":"mcm","clk":"4289717771","pt":1632492950975,"mc":[{"id":"1.188075669","rc":[{"batb":[[1,1.49,904]],"ltp":1.5,"tv":7382.98,"id":9631939}]}]}
{"op":"mcm","clk":"4289717792","pt":1632492951291,"mc":[{"id":"1.188075669","rc":[{"batb":[[2,2.88,3]],"ltp":3.0,"tv":585.57,"id":9454286}]}]}
{"op":"mcm","clk":"4289718187","pt":1632492956195,"mc":[{"id":"1.188075669","rc":[{"trd":[[1.51,1952.23]],"batb":[[0,1.51,34.19],[1,1.5,451.4],[2,1.49,904]],"batl":[[0,1.52,784.94],[1,1.53,614.66],[2,1.55,15]],"ltp":1.51,"tv":8252.64,"id":9631939}],"tv":8838.22}]}
{"op":"mcm","clk":"4289718418","pt":1632492959085,"mc":[{"id":"1.188075669","rc":[{"trd":[[1.5,415.59],[1.51,2020.61]],"batb":[[0,1.5,446.58],[1,1.49,904],[2,1.47,313.7]],"batl":[[0,1.52,905.32],[1,1.53,779.57]],"ltp":1.5,"tv":8330.66,"id":9631939}],"tv":8916.24}]}
{"op":"mcm","clk":"4289719190","pt":1632492968709,"mc":[{"id":"1.188075669","rc":[{"trd":[[1.52,2388.6]],"batb":[[2,1.47,200.3]],"batl":[[0,1.53,779.57],[1,1.55,15],[2,1.56,402.92]],"ltp":1.52,"tv":10174.03,"id":9631939},{"trd":[[2.94,11.04],[2.96,85.47]],"batb":[[0,2.94,153.2],[1,2.88,3],[2,2.82,82.47]],"ltp":2.94,"tv":602.45,"id":9454286}],"tv":10776.48}]}
{"op":"mcm","clk":"4289719487","pt":1632492971923,"mc":[{"id":"1.188075669","rc":[{"trd":[[1.5,425.59]],"batb":[[0,1.5,441.58],[2,1.48,277.56]],"batl":[[0,1.53,908.83],[1,1.54,159.81],[2,1.55,15]],"ltp":1.5,"tv":10184.03,"id":9631939},{"batb":[[1,2.82,82.47],[2,2.58,2.37]],"ltp":2.94,"tv":602.45,"id":9454286}],"tv":10786.48}]}
{"op":"mcm","clk":"4289719799","pt":1632492975034,"mc":[{"id":"1.188075669","rc":[{"batl":[[0,1.53,1035.69]],"ltp":1.5,"tv":10184.03,"id":9631939}]}]}
{"op":"mcm","clk":"4289720202","pt":1632492979218,"mc":[{"id":"1.188075669","rc":[{"batb":[[0,1.51,469.02],[1,1.5,441.58],[2,1.49,904]],"batl":[[0,1.53,908.83]],"ltp":1.5,"tv":10184.03,"id":9631939},{"batl":[[0,3.05,227.1]],"ltp":2.94,"tv":602.45,"id":9454286}]}]}
{"op":"mcm","clk":"4289720425","pt":1632492981864,"mc":[{"id":"1.188075669","rc":[{"batl":[[0,1.52,10.65],[1,1.53,908.83],[2,1.54,159.81]],"ltp":1.5,"tv":10184.03,"id":9631939},{"batl":[[0,3,5.76],[1,3.05,227.1],[2,3.1,61.7]],"ltp":2.94,"tv":602.45,"id":9454286}]}]}
{"op":"mcm","clk":"4289721393","pt":1632492992553,"mc":[{"id":"1.188075669","rc":[{"trd":[[1.52,2706.22]],"batb":[[0,1.52,162.05],[1,1.51,469.02],[2,1.5,441.58]],"batl":[[0,1.53,908.83],[1,1.54,159.81],[2,1.55,15]],"ltp":1.52,"tv":10501.65,"id":9631939},{"trd":[[2.94,164.24]],"batb":[[0,2.82,82.47],[1,2.58,2.37],[2,1.92,402.07]],"ltp":2.94,"tv":755.65,"id":9454286}],"tv":11257.31}]}
{"op":"mcm","clk":"4289721698","pt":1632492995775,"mc":[{"id":"1.188075669","rc":[{"trd":[[1.52,2716.22]],"batb":[[0,1.52,157.05]],"ltp":1.52,"tv":10511.65,"id":9631939}],"tv":11267.31}]}
{"op":"mcm","clk":"4289721835","pt":1632492997050,"mc":[{"id":"1.188075669","rc":[{"batb":[[0,1.49,904],[1,1.48,277.56],[2,1.47,200.3]],"batl":[[0,1.52,129.01],[1,1.53,908.83],[2,1.54,159.81]],"ltp":1.52,"tv":10511.65,"id":9631939},{"batb":[[0,2.82,812.95]],"ltp":2.94,"tv":755.65,"id":9454286}]}]}
{"op":"mcm","clk":"4289721854","pt":1632492997258,"mc":[{"id":"1.188075669","rc":[{"batl":[[0,1.53,908.83],[1,1.54,159.81],[2,1.55,15]],"ltp":1.52,"tv":10511.65,"id":9631939}]}]}
{"op":"mcm","clk":"4289722086","pt":1632493000058,"mc":[{"id":"1.188075669","rc":[{"batl":[[0,1.53,1035.69]],"ltp":1.52,"tv":10511.65,"id":9631939}]}]}
{"op":"mcm","clk":"4289722115","pt":1632493000371,"mc":[{"id":"1.188075669","rc":[{"batl":[[0,1.53,908.83]],"ltp":1.52,"tv":10511.65,"id":9631939}]}]}
{"op":"mcm","clk":"4289722320","pt":1632493002769,"mc":[{"id":"1.188075669","rc":[{"batl":[[0,3.05,227.1],[1,3.1,61.7],[2,3.15,43.01]],"ltp":2.94,"tv":755.65,"id":9454286}]}]}
{"op":"mcm","clk":"4289722373","pt":1632493003458,"mc":[{"id":"1.188075669","rc":[{"batl":[[0,1.51,4.22],[1,1.53,908.83],[2,1.54,159.81]],"ltp":1.52,"tv":10511.65,"id":9631939}]}]}
{"op":"mcm","clk":"4289722577","pt":1632493005994,"mc":[{"id":"1.188075669","rc":[{"trd":[[1.51,2024.83]],"batl":[[0,1.53,908.83],[1,1.54,159.81],[2,1.55,15]],"ltp":1.51,"tv":10515.87,"id":9631939},{"trd":[[2.96,87.62]],"batb":[[0,2.88,6.65],[1,2.86,3],[2,2.84,3]],"batl":[[0,2.96,3.32],[1,3.05,227.1],[2,3.1,61.7]],"ltp":2.96,"tv":757.8,"id":9454286}],"tv":11273.68}]}
{"op":"mcm","clk":"4289722761","pt":1632493008074,"mc":[{"id":"1.188075669","rc":[{"batb":[[0,1.46,88.46],[1,1.39,349.23],[2,1.25,147.22]],"batl":[[0,1.55,15],[1,1.61,5],[2,1.76,4.63]],"ltp":1.51,"tv":10515.87,"id":9631939},{"batb":[[0,2.82,82.47],[1,1.92,402.07],[2,1.8,10.52]],"batl":[[0,3.15,40.91],[1,3.45,183.67],[2,3.1,0]],"ltp":2.96,"tv":757.8,"id":9454286}]}]}
{"op":"mcm","clk":"4289722861","pt":1632493009185,"mc":[{"id":"1.188075669","rc":[{"batb":[[1,1.43,31.43],[2,1.39,349.23]],"batl":[[1,1.56,24.92],[2,1.61,5]],"ltp":1.51,"tv":10515.87,"id":9631939},{"batb":[[1,2.78,2.16],[2,1.92,402.07]],"batl":[[1,3.35,2],[2,3.45,183.67]],"ltp":2.96,"tv":757.8,"id":9454286}]}]}
{"op":"mcm","clk":"4289722934","pt":1632493010090,"mc":[{"id":"1.188075669","rc":[{"batb":[[0,1.44,28.67],[1,1.41,31.89]],"batl":[[0,1.55,22.7]],"ltp":1.51,"tv":10515.87,"id":9631939},{"batb":[[0,2.82,74.23],[1,2.8,2.13],[2,2.78,2.16]],"batl":[[0,3.3,2.05],[1,3.45,185.77],[2,3.45,0]],"ltp":2.96,"tv":757.8,"id":9454286}]}]}
{"op":"mcm","clk":"4289723031","pt":1632493011196,"mc":[{"id":"1.188075669","rc":[{"batb":[[0,1.42,185.07],[1,1.41,604.81],[2,1.25,147.22]],"batl":[[2,1.57,195.76]],"ltp":1.51,"tv":10515.87,"id":9631939},{"batb":[[0,2.8,2.13],[1,2.78,2.16],[2,2.76,77.27]],"batl":[[0,3.45,185.77],[1,3.45,0]],"ltp":2.96,"tv":757.8,"id":9454286}]}]}
{"op":"mcm","clk":"4289723084","pt":1632493011786,"mc":[{"id":"1.188075669","rc":[{"batb":[[0,1.41,371],[1,1.25,147.22],[2,1.2,394.35]],"ltp":1.51,"tv":10515.87,"id":9631939}]}]}
{"op":"mcm","clk":"4289723182","pt":1632493012786,"mc":[{"id":"1.188075669","rc":[{"batb":[[0,1.42,7],[1,1.41,378],[2,1.4,7]],"ltp":1.51,"tv":10515.87,"id":9631939},{"batl":[[0,3.35,3],[1,3.45,188.77]],"ltp":2.96,"tv":757.8,"id":9454286}]}]}
{"op":"mcm","clk":"4289723279","pt":1632493013971,"mc":[{"id":"1.188075669","rc":[{"batl":[[1,3.4,3],[2,3.45,188.77]],"ltp":2.96,"tv":757.8,"id":9454286}]}]}
{"op":"mcm","clk":"4289723363","pt":1632493015105,"mc":[{"id":"1.188075669","rc":[{"batb":[[0,1.52,681.3],[1,1.51,176.22],[2,1.42,7]],"ltp":1.51,"tv":10515.87,"id":9631939},{"batb":[[0,2.8,6.13],[1,2.78,5.16]],"batl":[[0,2.84,7.43],[1,2.88,186.88],[2,2.98,320.9]],"ltp":2.96,"tv":757.8,"id":9454286}]}]}
{"op":"mcm","clk":"4289723463","pt":1632493016180,"mc":[{"id":"1.188075669","rc":[{"trd":[[1.53,732],[1.54,22.04]],"batb":[[0,1.53,242.03],[1,1.52,681.3],[2,1.51,260.23]],"ltp":1.53,"tv":10542.71,"id":9631939},{"trd":[[2.84,7.65]],"batb":[[0,2.8,2.13],[1,2.78,2.16]],"batl":[[0,2.88,186.88],[1,2.98,363.54],[2,3,311.46]],"ltp":2.84,"tv":765.23,"id":9454286}],"tv":11307.95}]}
{"op":"mcm","clk":"4289723551","pt":1632493017184,"mc":[{"id":"1.188075669","rc":[{"batb":[[2,1.51,176.22]],"ltp":1.53,"tv":10542.71,"id":9631939},{"batl":[[1,2.98,320.9]],"ltp":2.84,"tv":765.23,"id":9454286}]}]}
{"op":"mcm","clk":"4289723693","pt":1632493018780,"mc":[{"id":"1.188075669","rc":[{"batl":[[1,1.56,41.27]],"ltp":1.53,"tv":10542.71,"id":9631939},{"batl":[[0,2.88,193.28]],"ltp":2.84,"tv":765.23,"id":9454286}]}]}
{"op":"mcm","clk":"4289723771","pt":1632493019683,"mc":[{"id":"1.188075669","rc":[{"trd":[[1.53,780.84]],"batb":[[0,1.53,217.61],[2,1.51,260.23]],"ltp":1.53,"tv":10591.55,"id":9631939},{"batl":[[1,2.98,363.54]],"ltp":2.84,"tv":765.23,"id":9454286}],"tv":11356.79}]}
{"op":"mcm","clk":"4289723897","pt":1632493021211,"mc":[{"id":"1.188075669","rc":[{"batb":[[0,1.53,331.61]],"ltp":1.53,"tv":10591.55,"id":9631939}]}]}
{"op":"mcm","clk":"4289724103","pt":1632493023222,"mc":[{"id":"1.188075669","rc":[{"batb":[[1,1.52,302.3]],"batl":[[1,1.56,24.92],[2,1.57,217.26]],"ltp":1.53,"tv":10591.55,"id":9631939},{"batl":[[0,2.98,42.64],[1,3.05,2.1],[2,3.15,2.1]],"ltp":2.84,"tv":765.23,"id":9454286}]}]}
{"op":"mcm","clk":"4289724173","pt":1632493024020,"mc":[{"id":"1.188075669","rc":[{"batb":[[0,1.51,84.01],[1,1.49,26.01],[2,1.47,27.67]],"batl":[[0,1.58,20.25],[1,1.59,15],[2,1.61,5]],"ltp":1.53,"tv":10591.55,"id":9631939},{"batb":[[0,2.72,2.34],[1,2.66,9.03],[2,2.64,86.04]],"ltp":2.84,"tv":765.23,"id":9454286}]}]}
{"op":"mcm","clk":"4289724289","pt":1632493025190,"mc":[{"id":"1.188075669","rc":[{"batb":[[0,1.47,27.67],[1,1.46,294.91],[2,1.45,7]],"batl":[[1,1.61,5],[2,1.76,4.63]],"ltp":1.53,"tv":10591.55,"id":9631939},{"batb":[[1,2.64,86.04],[2,1.92,402.07]],"batl":[[0,3.15,2.1],[1,3.25,3],[2,3.3,3]],"ltp":2.84,"tv":765.23,"id":9454286}]}]}
{"op":"mcm","clk":"4289724463","pt":1632493027137,"mc":[{"id":"1.188075669","rc":[{"batb":[[0,1.47,172.96],[1,1.46,495.8]],"batl":[[0,1.57,21.59],[1,1.58,26.25],[2,1.61,192.96]],"ltp":1.53,"tv":10591.55,"id":9631939},{"batb":[[0,2.74,5.52],[1,2.72,5.34],[2,2.7,3]],"ltp":2.84,"tv":765.23,"id":9454286}]}]}
{"op":"mcm","clk":"4289724555","pt":1632493028210,"mc":[{"id":"1.188075669","rc":[{"batb":[[0,1.47,34.67],[1,1.46,300.91]],"batl":[[0,1.58,26.34],[1,1.61,192.96],[2,1.62,133.35]],"ltp":1.53,"tv":10591.55,"id":9631939},{"batb":[[0,2.74,3]],"batl":[[0,3.15,5.1]],"ltp":2.84,"tv":765.23,"id":9454286}]}]}
{"op":"mcm","clk":"4289724616","pt":1632493028805,"mc":[{"id":"1.188075669","rc":[{"batb":[[2,1.43,7]],"ltp":1.53,"tv":10591.55,"id":9631939},{"batl":[[1,3.3,3],[2,3.45,2.1]],"ltp":2.84,"tv":765.23,"id":9454286}]}]}
{"op":"mcm","clk":"4289724870","pt":1632493031132,"mc":[{"id":"1.188075669","rc":[{"trd":[[1.53,781.02]],"batb":[[0,1.56,416.32],[1,1.55,158.8],[2,1.47,34.67]],"batl":[[0,1.58,20.25],[1,1.6,19.18],[2,1.61,187.96]],"ltp":1.53,"tv":10591.74,"id":9631939},{"batb":[[0,2.72,2.34],[1,2.66,85.62],[2,1.92,402.07]],"batl":[[0,2.78,9.16],[1,2.84,336.7],[2,2.86,326.8]],"ltp":2.84,"tv":765.23,"id":9454286}],"tv":11356.97}]}
{"op":"mcm","clk":"4289724987","pt":1632493032205,"mc":[{"id":"1.188075669","rc":[{"trd":[[1.56,83.55]],"batb":[[0,1.56,624.88],[2,1.54,81.64]],"ltp":1.56,"tv":10631.48,"id":9631939},{"batb":[[2,2.56,93.72]],"batl":[[1,2.84,380.93]],"ltp":2.84,"tv":765.23,"id":9454286}],"tv":11396.71}]}
{"op":"mcm","clk":"4289725127","pt":1632493033517,"mc":[{"id":"1.188075669","rc":[{"batb":[[2,2.62,3]],"ltp":2.84,"tv":765.23,"id":9454286}]}]}
{"op":"mcm","clk":"4289725311","pt":1632493035634,"mc":[{"id":"1.188075669","rc":[{"trd":[[1.56,134.83]],"batb":[[0,1.56,599.24],[2,1.51,260.49]],"batl":[[0,1.58,20.56]],"ltp":1.56,"tv":10682.76,"id":9631939},{"batl":[[1,2.84,336.7]],"ltp":2.84,"tv":765.23,"id":9454286}],"tv":11447.99}]}
{"op":"mcm","clk":"4289725529","pt":1632493038220,"mc":[{"id":"1.188075669","rc":[{"trd":[[1.56,135.61]],"batb":[[0,1.56,598.85]],"ltp":1.56,"tv":10683.54,"id":9631939}],"tv":11448.77}]}
{"op":"mcm","clk":"4289725603","pt":1632493038846,"mc":[{"id":"1.188075669","rc":[{"batb":[[1,1.55,239.7],[2,1.53,24.33]],"batl":[[1,1.59,18.89],[2,1.6,39.04]],"ltp":1.56,"tv":10683.54,"id":9631939},{"batb":[[1,2.68,2.36],[2,2.66,88.4]],"batl":[[1,2.8,44.72],[2,2.84,336.7]],"ltp":2.84,"tv":765.23,"id":9454286}]}]}
{"op":"mcm","clk":"4289725726","pt":1632493040019,"mc":[{"id":"1.188075669","rc":[{"trd":[[1.57,18.14],[1.58,106.67]],"batl":[[0,1.58,17.93]],"ltp":1.58,"tv":10688.8,"id":9631939}],"tv":11454.04}]}
{"op":"mcm","clk":"4289725944","pt":1632493042329,"mc":[{"id":"1.188075669","rc":[{"batb":[[0,1.56,471.66]],"ltp":1.58,"tv":10688.8,"id":9631939}]}]}
{"op":"mcm","clk":"4289726137","pt":1632493044124,"mc":[{"id":"1.188075669","rc":[{"batl":[[2,1.6,19.86]],"ltp":1.58,"tv":10688.8,"id":9631939},{"batl":[[0,2.8,44.72],[1,2.84,168.35],[2,2.86,163.4]],"ltp":2.84,"tv":765.23,"id":9454286}]}]}
{"op":"mcm","clk":"4289726162","pt":1632493044434,"mc":[{"id":"1.188075669","rc":[{"batb":[[0,1.55,80.9],[1,1.53,24.33],[2,1.51,282.48]],"batl":[[0,1.6,19.86],[1,1.76,4.63],[2,100,0.73]],"ltp":1.58,"tv":10688.8,"id":9631939},{"batb":[[0,2.62,3],[1,2.6,3],[2,2.56,93.72]],"batl":[[1,2.9,2.05],[2,2.98,2.25]],"ltp":2.84,"tv":765.23,"id":9454286}]}]}
{"op":"mcm","clk":"4289726253","pt":1632493045529,"mc":[{"id":"1.188075669","rc":[{"batb":[[0,1.51,282.48],[1,1.48,6],[2,1.47,27.67]],"ltp":1.58,"tv":10688.8,"id":9631939},{"batb":[[1,2.56,93.72],[2,1.92,402.07]],"batl":[[0,2.98,2.25],[1,3.15,5.1],[2,3.3,195.4]],"ltp":2.84,"tv":765.23,"id":9454286}]}]}
{"op":"mcm","clk":"4289726445","pt":1632493047745,"mc":[{"id":"1.188075669","rc":[{"batl":[[0,1.6,25.86]],"ltp":1.58,"tv":10688.8,"id":9631939},{"batb":[[0,2.66,6.78],[1,2.64,3],[2,2.62,3]],"ltp":2.84,"tv":765.23,"id":9454286}]}]}
{"op":"mcm","clk":"4289726532","pt":1632493049052,"mc":[{"id":"1.188075669","rc":[{"batb":[[0,1.51,289.48],[1,1.5,7],[2,1.48,6]],"ltp":1.58,"tv":10688.8,"id":9631939},{"batl":[[0,2.98,5.25]],"ltp":2.84,"tv":765.23,"id":9454286}]}]}
{"op":"mcm","clk":"4289726698","pt":1632493050947,"mc":[{"id":"1.188075669","rc":[{"batl":[[0,1.59,22.89],[1,1.6,25.86],[2,1.76,4.63]],"ltp":1.58,"tv":10688.8,"id":9631939},{"batb":[[0,2.68,5.36],[1,2.66,6.78],[2,2.64,3]],"ltp":2.84,"tv":765.23,"id":9454286}]}]}
{"op":"mcm","clk":"4289726762","pt":1632493051536,"mc":[{"id":"1.188075669","rc":[{"batb":[[0,1.55,247.94],[1,1.54,162.84],[2,1.51,289.48]],"batl":[[0,1.6,224.31],[1,1.61,136.26]],"ltp":1.58,"tv":10688.8,"id":9631939},{"batb":[[0,2.68,3]],"ltp":2.84,"tv":765.23,"id":9454286}]}]}
{"op":"mcm","clk":"4289726838","pt":1632493052366,"mc":[{"id":"1.188075669","rc":[{"batb":[[2,1.53,23.33]],"ltp":1.58,"tv":10688.8,"id":9631939},{"batl":[[0,2.9,2.15],[1,2.98,5.25],[2,3.15,5.1]],"ltp":2.84,"tv":765.23,"id":9454286}]}]}
{"op":"mcm","clk":"4289726924","pt":1632493053538,"mc":[{"id":"1.188075669","rc":[{"batb":[[0,1.51,289.48],[1,1.5,7],[2,1.48,6]],"batl":[[0,1.6,25.86],[1,1.76,4.63],[2,100,0.73]],"ltp":1.58,"tv":10688.8,"id":9631939},{"batl":[[0,2.98,5.25],[1,3.15,5.1],[2,3.3,195.4]],"ltp":2.84,"tv":765.23,"id":9454286}]}]}
{"op":"mcm","clk":"4289727155","pt":1632493056162,"mc":[{"id":"1.188075669","rc":[{"batb":[[0,1.51,586.15],[1,1.5,187.91]],"batl":[[1,1.64,166.43],[2,1.66,246.5]],"ltp":1.58,"tv":10688.8,"id":9631939}]}]}
{"op":"mcm","clk":"4289727352","pt":1632493058154,"mc":[{"id":"1.188075669","rc":[{"batl":[[0,1.59,20.5],[1,1.6,25.86],[2,1.76,4.63]],"ltp":1.58,"tv":10688.8,"id":9631939},{"batb":[[0,2.68,5.61]],"ltp":2.84,"tv":765.23,"id":9454286}]}]}
{"op":"mcm","clk":"4289727373","pt":1632493058464,"mc":[{"id":"1.188075669","rc":[{"batl":[[0,1.6,25.86],[1,1.76,4.63],[2,100,0.73]],"ltp":1.58,"tv":10688.8,"id":9631939},{"batb":[[0,2.68,3]],"ltp":2.84,"tv":765.23,"id":9454286}]}]}
{"op":"mcm","clk":"4289727604","pt":1632493061064,"mc":[{"id":"1.188075669","rc":[{"trd":[[1.51,2065.37]],"batb":[[0,1.51,558.88],[1,1.5,180.91],[2,1.48,652.12]],"batl":[[0,1.54,15.58],[1,1.55,9.1],[2,1.56,3433.09]],"ltp":1.51,"tv":10729.34,"id":9631939},{"batb":[[0,2.8,2],[1,2.68,3],[2,2.66,2.78]],"batl":[[0,2.96,215.57],[1,2.98,2.25],[2,3.15,2.1]],"ltp":2.84,"tv":765.23,"id":9454286}],"tv":11494.58}]}
{"op":"mcm","clk":"4289727709","pt":1632493062164,"mc":[{"id":"1.188075669","rc":[{"batb":[[2,1.49,85.71]],"batl":[[2,1.56,1038.08]],"ltp":1.51,"tv":10729.34,"id":9631939},{"batb":[[0,2.82,72.97],[1,2.8,2],[2,2.7,8.82]],"batl":[[2,3.05,41.9]],"ltp":2.84,"tv":765.23,"id":9454286}]}]}
{"op":"mcm","clk":"4289727920","pt":1632493064154,"mc":[{"id":"1.188075669","rc":[{"batb":[[2,2.7,10.82]],"ltp":2.84,"tv":765.23,"id":9454286}]}]}
{"op":"mcm","clk":"4289727994","pt":1632493064984,"mc":[{"id":"1.188075669","rc":[{"batb":[[0,1.52,239],[1,1.51,558.88],[2,1.5,180.91]],"ltp":1.51,"tv":10729.34,"id":9631939}]}]}
{"op":"mcm","clk":"4289728075","pt":1632493066028,"mc":[{"id":"1.188075669","rc":[{"trd":[[1.52,2721.46]],"batb":[[0,1.52,236.38]],"ltp":1.52,"tv":10734.58,"id":9631939}],"tv":11499.82}]}
{"op":"mcm","clk":"4289728267","pt":1632493068188,"mc":[{"id":"1.188075669","rc":[{"batb":[[2,2.74,2.29]],"ltp":2.84,"tv":765.23,"id":9454286}]}]}
{"op":"mcm","clk":"4289728275","pt":1632493068282,"mc":[{"id":"1.188075669","rc":[{"batb":[[0,1.52,365.38]],"ltp":1.52,"tv":10734.58,"id":9631939}]}]}
{"op":"mcm","clk":"4289728645","pt":1632493072774,"mc":[{"id":"1.188075669","rc":[{"batl":[[2,1.56,831.61]],"ltp":1.52,"tv":10734.58,"id":9631939}]}]}
{"op":"mcm","clk":"4289729041","pt":1632493077178,"mc":[{"id":"1.188075669","rc":[{"batl":[[0,1.55,9.1],[1,1.56,218.63],[2,1.57,170.65]],"ltp":1.52,"tv":10734.58,"id":9631939},{"batl":[[0,2.98,2.25],[1,3.05,41.9],[2,3.1,2.05]],"ltp":2.84,"tv":765.23,"id":9454286}]}]}
{"op":"mcm","clk":"4289729139","pt":1632493078180,"mc":[{"id":"1.188075669","rc":[{"batb":[[0,1.48,26.76],[1,1.47,27.67],[2,1.46,28.38]],"batl":[[0,1.59,24.5],[1,1.6,19.86],[2,1.76,4.63]],"ltp":1.52,"tv":10734.58,"id":9631939},{"batb":[[0,2.7,2],[1,2.68,86.21],[2,2.66,2.78]],"batl":[[0,3.1,2.05],[1,3.15,2.1],[2,3.2,2.03]],"ltp":2.84,"tv":765.23,"id":9454286}]}]}
{"op":"mcm","clk":"4289729165","pt":1632493078494,"mc":[{"id":"1.188075669","rc":[{"batb":[[0,1.46,28.38],[1,1.44,317.43],[2,1.41,31.89]],"ltp":1.52,"tv":10734.58,"id":9631939},{"batl":[[0,3.2,2.03],[1,3.45,2.1],[2,3.65,173.5]],"ltp":2.84,"tv":765.23,"id":9454286}]}]}
{"op":"mcm","clk":"4289729420","pt":1632493081207,"mc":[{"id":"1.188075669","rc":[{"batb":[[1,1.43,318.44]],"ltp":1.52,"tv":10734.58,"id":9631939},{"batb":[[0,2.74,3],[1,2.72,3],[2,2.7,2]],"ltp":2.84,"tv":765.23,"id":9454286}]}]}
{"op":"mcm","clk":"4289729635","pt":1632493083176,"mc":[{"id":"1.188075669","rc":[{"trd":[[1.56,139.99]],"batb":[[0,1.51,18.48],[1,1.5,235.57],[2,1.49,185.43]],"batl":[[0,1.53,18.31],[1,1.54,138.24],[2,1.55,156.92]],"ltp":1.56,"tv":10738.96,"id":9631939},{"batl":[[0,2.96,17.87],[1,3.2,2.03],[2,3.45,2.1]],"ltp":2.84,"tv":765.23,"id":9454286}],"tv":11504.2}]}
{"op":"mcm","clk":"4289729709","pt":1632493084086,"mc":[{"id":"1.188075669","rc":[{"trd":[[1.54,39.56]],"batb":[[0,1.5,235.57],[1,1.49,185.43],[2,1.46,28.38]],"batl":[[0,1.54,129.48],[1,1.55,156.92],[2,1.58,5]],"ltp":1.54,"tv":10756.48,"id":9631939},{"batl":[[0,3.2,2.03],[1,3.45,2.1],[2,3.65,173.5]],"ltp":2.84,"tv":765.23,"id":9454286}],"tv":11521.72}]}
{"op":"mcm","clk":"4289729809","pt":1632493085188,"mc":[{"id":"1.188075669","rc":[{"trd":[[1.54,52.7],[1.55,320.08]],"batl":[[0,1.55,154.73],[1,1.57,22.5]],"ltp":1.55,"tv":10774.01,"id":9631939},{"batb":[[0,2.74,5.29]],"ltp":2.84,"tv":765.23,"id":9454286}],"tv":11539.24}]}
{"op":"mcm","clk":"4289729840","pt":1632493085613,"mc":[{"id":"1.188075669","rc":[{"trd":[[1.55,324.46]],"batb":[[2,1.48,26.01]],"batl":[[0,1.55,152.54]],"ltp":1.55,"tv":10778.39,"id":9631939},{"batl":[[0,3.1,2.05],[1,3.2,2.03],[2,3.45,2.1]],"ltp":2.84,"tv":765.23,"id":9454286}],"tv":11543.63}]}
{"op":"mcm","clk":"4289729977","pt":1632493087209,"mc":[{"id":"1.188075669","rc":[{"batb":[[0,1.54,2.19],[1,1.52,2.19]],"batl":[[0,1.57,22.5],[1,1.58,5],[2,1.59,24.5]],"ltp":1.55,"tv":10778.39,"id":9631939}]}]}
{"op":"mcm","clk":"4289730007","pt":1632493087526,"mc":[{"id":"1.188075669","rc":[{"batb":[[0,1.56,2.19],[1,1.54,2.19],[2,1.52,2.19]],"batl":[[0,1.58,5],[1,1.59,24.5],[2,1.6,19.86]],"ltp":1.55,"tv":10778.39,"id":9631939},{"batb":[[0,2.74,3]],"batl":[[0,3.2,2.03],[1,3.45,2.1],[2,3.65,173.5]],"ltp":2.84,"tv":765.23,"id":9454286}]}]}
{"op":"mcm","clk":"4289730228","pt":1632493090030,"mc":[{"id":"1.188075669","rc":[{"trd":[[1.56,144.38]],"batb":[[0,1.54,2.19],[1,1.52,2.19],[2,1.46,28.38]],"ltp":1.56,"tv":10782.77,"id":9631939}],"tv":11548.01}]}
{"op":"mcm","clk":"4289730492","pt":1632493093132,"mc":[{"id":"1.188075669","rc":[{"batb":[[0,1.57,8.76],[1,1.54,2.19],[2,1.52,2.19]],"ltp":1.56,"tv":10782.77,"id":9631939},{"batb":[[1,2.68,88.87],[2,2.66,2.78]],"ltp":2.84,"tv":765.23,"id":9454286}]}]}
{"op":"mcm","clk":"4289730572","pt":1632493094029,"mc":[{"id":"1.188075669","rc":[{"trd":[[1.57,35.67]],"batb":[[0,1.54,2.19],[1,1.52,2.19],[2,1.46,28.38]],"batl":[[0,1.57,11.74],[1,1.58,5],[2,1.59,24.5]],"ltp":1.57,"tv":10800.29,"id":9631939},{"batb":[[0,2.74,5.52],[1,2.68,85.87]],"ltp":2.84,"tv":765.23,"id":9454286}],"tv":11565.53}]}
{"op":"mcm","clk":"4289730672","pt":1632493095194,"mc":[{"id":"1.188075669","rc":[{"batb":[[0,1.57,2.19],[1,1.54,2.19],[2,1.52,2.19]],"batl":[[0,1.58,5],[1,1.59,24.5],[2,1.6,19.86]],"ltp":1.57,"tv":10800.29,"id":9631939},{"batb":[[0,2.74,3]],"ltp":2.84,"tv":765.23,"id":9454286}]}]}
{"op":"mcm","clk":"4289730739","pt":1632493096205,"mc":[{"id":"1.188075669","rc":[{"trd":[[1.46,111.29],[1.52,2725.84],[1.54,57.09],[1.56,148.76],[1.57,40.05]],"batb":[[0,1.46,7.4],[1,1.45,212.64],[2,1.44,660.87]],"batl":[[0,1.49,1671.12],[1,1.58,5],[2,1.59,24.5]],"ltp":1.46,"tv":10859.78,"id":9631939},{"batb":[[0,3.15,5.67],[1,3,1275],[2,2.98,1237.5]],"batl":[[1,3.25,6.53],[2,3.35,1141.78]],"ltp":2.84,"tv":765.23,"id":9454286}],"tv":11625.02}]}
{"op":"mcm","clk":"4289730838","pt":1632493097209,"mc":[{"id":"1.188075669","rc":[{"batl":[[0,1.49,376.1],[1,1.5,186.5],[2,1.58,5]],"ltp":1.46,"tv":10859.78,"id":9631939},{"batb":[[1,3,320.76],[2,2.98,309.38]],"batl":[[0,3.2,5.03],[2,3.35,285.44]],"ltp":2.84,"tv":765.23,"id":9454286}]}]}
{"op":"mcm","clk":"4289730882","pt":1632493097707,"mc":[{"id":"1.188075669","rc":[{"batb":[[1,3.1,143.4],[2,3,320.76]],"batl":[[0,3.2,2.03]],"ltp":2.84,"tv":765.23,"id":9454286}]}]}
{"op":"mcm","clk":"4289731024","pt":1632493099123,"mc":[{"id":"1.188075669","rc":[{"batl":[[2,1.57,2]],"ltp":1.46,"tv":10859.78,"id":9631939},{"batl":[[2,3.35,324.57]],"ltp":2.84,"tv":765.23,"id":9454286}]}]}
{"op":"mcm","clk":"4289731090","pt":1632493099914,"mc":[{"id":"1.188075669","rc":[{"trd":[[1.46,124.27],[1.47,46.16]],"batb":[[0,1.46,256.91]],"batl":[[2,1.52,15]],"ltp":1.46,"tv":10874.95,"id":9631939},{"trd":[[3.15,8.31]],"batb":[[0,3.15,4.65]],"ltp":3.15,"tv":766.25,"id":9454286}],"tv":11641.21}]}
{"op":"mcm","clk":"4289731203","pt":1632493101128,"mc":[{"id":"1.188075669","rc":[{"trd":[[1.46,151.31]],"batb":[[0,1.46,243.39]],"ltp":1.46,"tv":10901.99,"id":9631939}],"tv":11668.25}]}
{"op":"mcm","clk":"4289731247","pt":1632493101608,"mc":[{"id":"1.188075669","rc":[{"batl":[[2,1.57,2]],"ltp":1.46,"tv":10901.99,"id":9631939}]}]}
{"op":"mcm","clk":"4289731383","pt":1632493103216,"mc":[{"id":"1.188075669","rc":[{"trd":[[3.15,17.61]],"batb":[[0,3.1,143.4],[1,3,320.76],[2,2.98,309.38]],"batl":[[0,3.15,10],[1,3.2,2.03],[2,3.25,6.53]],"ltp":3.15,"tv":775.55,"id":9454286}],"tv":11677.55}]}
{"op":"mcm","clk":"4289731433","pt":1632493103806,"mc":[{"id":"1.188075669","rc":[{"batl":[[2,1.55,22.5]],"ltp":1.46,"tv":10901.99,"id":9631939}]}]}
{"op":"mcm","clk":"4289731496","pt":1632493104637,"mc":[{"id":"1.188075669","rc":[{"batl":[[2,1.51,15]],"ltp":1.46,"tv":10901.99,"id":9631939}]}]}
{"op":"mcm","clk":"4289731651","pt":1632493106113,"mc":[{"id":"1.188075669","rc":[{"batl":[[0,3.15,14.64]],"ltp":3.15,"tv":775.55,"id":9454286}]}]}
{"op":"mcm","clk":"4289731749","pt":1632493107220,"mc":[{"id":"1.188075669","rc":[{"batl":[[0,3.15,10]],"ltp":3.15,"tv":775.55,"id":9454286}]}]}
{"op":"mcm","clk":"4289731826","pt":1632493108222,"mc":[{"id":"1.188075669","rc":[{"batl":[[0,1.49,242.78]],"ltp":1.46,"tv":10901.99,"id":9631939}]}]}
{"op":"mcm","clk":"4289731932","pt":1632493109436,"mc":[{"id":"1.188075669","rc":[{"batb":[[0,1.46,383]],"ltp":1.46,"tv":10901.99,"id":9631939},{"batl":[[2,3.35,324.57]],"ltp":3.15,"tv":775.55,"id":9454286}]}]}
{"op":"mcm","clk":"4289732161","pt":1632493112040,"mc":[{"id":"1.188075669","rc":[{"batb":[[0,1.42,92.58],[1,1.36,32.68],[2,1.35,33.27]],"batl":[[0,1.51,15],[1,1.55,22.5],[2,1.57,2]],"ltp":1.46,"tv":10901.99,"id":9631939},{"batb":[[0,2.96,7.65],[1,2.86,70.86],[2,2.8,2.08]],"batl":[[1,3.35,39.13],[2,3.8,2]],"ltp":3.15,"tv":775.55,"id":9454286}]}]}
{"op":"mcm","clk":"4289732339","pt":1632493114048,"mc":[{"id":"1.188075669","rc":[{"batb":[[0,1.48,469.02],[1,1.34,431.9],[2,1.32,37.64]],"batl":[[0,1.55,22.5],[1,1.57,2],[2,1.58,19.25]],"ltp":1.46,"tv":10901.99,"id":9631939},{"batb":[[0,2.86,70.86],[1,2.8,2.08],[2,2.76,3]],"batl":[[1,4.2,152.71],[2,4.3,2]],"ltp":3.15,"tv":775.55,"id":9454286}]}]}
{"op":"mcm","clk":"4289732442","pt":1632493115159,"mc":[{"id":"1.188075669","rc":[{"batb":[[1,1.36,171.4],[2,1.35,285.82]],"batl":[[1,1.56,247.51],[2,1.57,150.89]],"ltp":1.46,"tv":10901.99,"id":9631939},{"batl":[[1,3.55,2],[2,4.2,152.71]],"ltp":3.15,"tv":775.55,"id":9454286}]}]}
{"op":"mcm","clk":"4289732506","pt":1632493116056,"mc":[{"id":"1.188075669","rc":[{"batb":[[0,1.34,432.29],[1,1.32,37.64],[2,1.31,42.79]],"batl":[[1,1.57,2],[2,1.58,19.25]],"ltp":1.46,"tv":10901.99,"id":9631939}]}]}
{"op":"mcm","clk":"4289732697","pt":1632493118165,"mc":[{"id":"1.188075669","rc":[{"trd":[[1.47,55.7],[1.5,429.97],[1.51,2069.75]],"batb":[[0,1.53,2.19],[1,1.34,431.9],[2,1.32,37.64]],"ltp":1.47,"tv":10920.29,"id":9631939}],"tv":11695.85}]}
{"op":"mcm","clk":"4289732772","pt":1632493119062,"mc":[{"id":"1.188075669","rc":[{"trd":[[1.47,60.08],[1.52,2730.22],[1.53,798.55]],"batb":[[0,1.43,231.6],[1,1.42,226.96],[2,1.34,431.9]],"batl":[[0,1.47,252.77],[1,1.48,186.6],[2,1.55,22.5]],"ltp":1.47,"tv":10946.58,"id":9631939}],"tv":11722.14}]}
{"op":"mcm","clk":"4289732858","pt":1632493120064,"mc":[{"id":"1.188075669","rc":[{"trd":[[1.47,81.99]],"batl":[[0,1.47,241.82]],"ltp":1.47,"tv":10968.48,"id":9631939}],"tv":11744.04}]}
{"op":"mcm","clk":"4289732936","pt":1632493120968,"mc":[{"id":"1.188075669","rc":[{"trd":[[1.47,90.75]],"batb":[[2,1.36,36.68]],"batl":[[0,1.47,237.44]],"ltp":1.47,"tv":10977.25,"id":9631939},{"batl":[[2,3.8,2]],"ltp":3.15,"tv":775.55,"id":9454286}],"tv":11752.8}]}
{"op":"mcm","clk":"4289733028","pt":1632493122078,"mc":[{"id":"1.188075669","rc":[{"batb":[[0,1.52,2.19],[1,1.51,4.38],[2,1.47,2.19]],"batl":[[0,1.55,22.5],[1,1.57,2],[2,1.58,19.25]],"ltp":1.47,"tv":10977.25,"id":9631939},{"batl":[[2,4.2,152.71]],"ltp":3.15,"tv":775.55,"id":9454286}]}]}
{"op":"mcm","clk":"4289733126","pt":1632493123149,"mc":[{"id":"1.188075669","rc":[{"batb":[[0,1.52,6.57],[2,1.48,2.19]],"ltp":1.47,"tv":10977.25,"id":9631939}]}]}
{"op":"mcm","clk":"4289733202","pt":1632493124043,"mc":[{"id":"1.188075669","rc":[{"batb":[[1,1.51,6.57]],"ltp":1.47,"tv":10977.25,"id":9631939}]}]}
{"op":"mcm","clk":"4289733293","pt":1632493125044,"mc":[{"id":"1.188075669","rc":[{"batb":[[0,1.52,8.76],[1,1.51,8.76]],"batl":[[1,1.56,232.4],[2,1.57,150.88]],"ltp":1.47,"tv":10977.25,"id":9631939}]}]}
{"op":"mcm","clk":"4289733368","pt":1632493126051,"mc":[{"id":"1.188075669","rc":[{"batb":[[0,1.52,13.15]],"ltp":1.47,"tv":10977.25,"id":9631939}]}]}
{"op":"mcm","clk":"4289733520","pt":1632493127883,"mc":[{"id":"1.188075669","rc":[{"batb":[[0,1.36,188.22],[1,1.35,285.85],[2,1.34,431.9]],"ltp":1.47,"tv":10977.25,"id":9631939}]}]}
{"op":"mcm","clk":"4289733566","pt":1632493128359,"mc":[{"id":"1.188075669","rc":[{"batb":[[0,1.36,220.15]],"ltp":1.47,"tv":10977.25,"id":9631939},{"batl":[[2,3.8,2]],"ltp":3.15,"tv":775.55,"id":9454286}]}]}
{"op":"mcm","clk":"4289733671","pt":1632493129565,"mc":[{"id":"1.188075669","rc":[{"batb":[[0,1.34,431.9],[1,1.32,37.64],[2,1.31,42.79]],"ltp":1.47,"tv":10977.25,"id":9631939},{"batl":[[2,4.2,152.71]],"ltp":3.15,"tv":775.55,"id":9454286}]}]}
{"op":"mcm","clk":"4289733911","pt":1632493132160,"mc":[{"id":"1.188075669","rc":[{"batb":[[0,1.51,3158.99],[1,1.5,368],[2,1.49,1604.45]],"batl":[[0,1.54,16.15],[1,1.55,22.5],[2,1.56,232.4]],"ltp":1.47,"tv":10977.25,"id":9631939},{"batl":[[0,2.96,7.9],[1,3,93.7],[2,3.15,10]],"ltp":3.15,"tv":775.55,"id":9454286}]}]}
{"op":"mcm","clk":"4289734013","pt":1632493133171,"mc":[{"id":"1.188075669","rc":[{"trd":[[1.51,2110.29]],"batb":[[0,1.51,489.11],[1,1.5,634.9],[2,1.49,641.78]],"ltp":1.51,"tv":11017.79,"id":9631939},{"batl":[[2,3.1,41.4]],"ltp":3.15,"tv":775.55,"id":9454286}],"tv":11793.34}]}
{"op":"mcm","clk":"4289734393","pt":1632493137208,"mc":[{"id":"1.188075669","rc":[{"batl":[[2,3.15,10]],"ltp":3.15,"tv":775.55,"id":9454286}]}]}
{"op":"mcm","clk":"4289734422","pt":1632493137477,"mc":[{"id":"1.188075669","rc":[{"batl":[[0,1.54,16.54]],"ltp":1.51,"tv":11017.79,"id":9631939}]}]}
{"op":"mcm","clk":"4289734510","pt":1632493138478,"mc":[{"id":"1.188075669","rc":[{"trd":[[1.52,2735.7]],"batb":[[0,1.52,172.26],[1,1.51,489.11],[2,1.5,634.9]],"batl":[[0,1.54,16.15]],"ltp":1.52,"tv":11023.26,"id":9631939}],"tv":11798.82}]}
{"op":"mcm","clk":"4289734659","pt":1632493140160,"mc":[{"id":"1.188075669","rc":[{"batl":[[2,3.15,12.1]],"ltp":3.15,"tv":775.55,"id":9454286}]}]}
{"op":"mcm","clk":"4289734695","pt":1632493140583,"mc":[{"id":"1.188075669","rc":[{"batl":[[2,3.05,41.9]],"ltp":3.15,"tv":775.55,"id":9454286}]}]}
{"op":"mcm","clk":"4289735036","pt":1632493143985,"mc":[{"id":"1.188075669","rc":[{"batb":[[1,1.51,280.97]],"ltp":1.52,"tv":11023.26,"id":9631939}]}]}
{"op":"mcm","clk":"4289735355","pt":1632493147213,"mc":[{"id":"1.188075669","rc":[{"trd":[[1.52,2735.9]],"batb":[[0,1.52,172.16]],"ltp":1.52,"tv":11023.46,"id":9631939}],"tv":11799.02}]}
{"op":"mcm","clk":"4289736066","pt":1632493154983,"mc":[{"id":"1.188075669","rc":[{"batb":[[0,1.51,280.97],[1,1.5,180.59],[2,1.49,85.71]],"batl":[[0,1.56,232.4],[1,1.57,148.88],[2,1.58,34.25]],"ltp":1.52,"tv":11023.46,"id":9631939},{"batb":[[0,2.72,11.31],[1,2.7,81.82],[2,2.68,2.36]],"batl":[[0,3.05,41.9],[1,3.15,12.1],[2,3.25,2.02]],"ltp":3.15,"tv":775.55,"id":9454286}]}]}
{"op":"mcm","clk":"4289736117","pt":1632493155506,"mc":[{"id":"1.188075669","rc":[{"batb":[[0,1.49,85.71],[1,1.47,25.84],[2,1.45,25.41]],"batl":[[0,1.58,15],[1,1.59,19.5],[2,1.6,19.86]],"ltp":1.52,"tv":11023.46,"id":9631939},{"batb":[[0,2.72,8.72]],"ltp":3.15,"tv":775.55,"id":9454286}]}]}
{"op":"mcm","clk":"4289736228","pt":1632493156613,"mc":[{"id":"1.188075669","rc":[{"batb":[[0,1.45,25.41],[1,1.42,330.5],[2,1.32,37.64]],"batl":[[0,1.59,19.5],[1,1.6,19.86],[2,1.76,4.63]],"ltp":1.52,"tv":11023.46,"id":9631939},{"batb":[[0,2.7,81.82],[1,2.68,2.36],[2,2.66,2.78]],"batl":[[0,3.15,10],[1,3.25,2.02],[2,3.55,2]],"ltp":3.15,"tv":775.55,"id":9454286}]}]}
{"op":"mcm","clk":"4289736386","pt":1632493158194,"mc":[{"id":"1.188075669","rc":[{"batb":[[1,1.44,241.58],[2,1.43,220.1]],"batl":[[2,1.61,217.34]],"ltp":1.52,"tv":11023.46,"id":9631939}]}]}
{"op":"mcm","clk":"4289736458","pt":1632493158996,"mc":[{"id":"1.188075669","rc":[{"batl":[[0,1.58,5],[1,1.59,19.5],[2,1.6,19.86]],"ltp":1.52,"tv":11023.46,"id":9631939},{"batb":[[0,2.72,3],[1,2.7,85.82],[2,2.68,2.36]],"ltp":3.15,"tv":775.55,"id":9454286}]}]}
{"op":"mcm","clk":"4289736554","pt":1632493160102,"mc":[{"id":"1.188075669","rc":[{"batl":[[0,1.5,2.19],[1,1.58,5],[2,1.59,25.5]],"ltp":1.52,"tv":11023.46,"id":9631939},{"batb":[[2,2.68,5.36]],"ltp":3.15,"tv":775.55,"id":9454286}]}]}
{"op":"mcm","clk":"4289736609","pt":1632493160793,"mc":[{"id":"1.188075669","rc":[{"batl":[[0,1.5,10.96]],"ltp":1.52,"tv":11023.46,"id":9631939}]}]}
{"op":"mcm","clk":"4289736742","pt":1632493162214,"mc":[{"id":"1.188075669","rc":[{"trd":[[1.46,155.7]],"batl":[[0,1.47,4.38],[1,1.48,4.38],[2,1.5,13.15]],"ltp":1.46,"tv":11027.84,"id":9631939},{"trd":[[3.15,19.65]],"batb":[[0,2.72,5.59]],"batl":[[0,3.15,7.96]],"ltp":3.15,"tv":777.59,"id":9454286}],"tv":11805.44}]}
{"op":"mcm","clk":"4289736790","pt":1632493162797,"mc":[{"id":"1.188075669","rc":[{"trd":[[1.47,91.58]],"batl":[[0,1.47,7.94]],"ltp":1.47,"tv":11028.67,"id":9631939},{"trd":[[3.1,135.13]],"batb":[[0,2.72,3]],"ltp":3.1,"tv":777.98,"id":9454286}],"tv":11806.66}]}
{"op":"mcm","clk":"4289736920","pt":1632493164017,"mc":[{"id":"1.188075669","rc":[{"trd":[[1.47,107.46]],"batl":[[0,1.47,2.19],[2,1.49,2.19]],"ltp":1.47,"tv":11044.55,"id":9631939}],"tv":11822.54}]}
{"op":"mcm","clk":"4289737117","pt":1632493165126,"mc":[{"id":"1.188075669","rc":[{"batl":[[2,1.49,6.57]],"ltp":1.47,"tv":11044.55,"id":9631939}]}]}
{"op":"mcm","clk":"4289737299","pt":1632493166126,"mc":[{"id":"1.188075669","rc":[{"trd":[[1.47,111.84]],"batl":[[0,1.47,4.38],[2,1.49,8.76]],"ltp":1.47,"tv":11048.93,"id":9631939}],"tv":11826.92}]}
{"op":"mcm","clk":"4289737518","pt":1632493166815,"mc":[{"id":"1.188075669","rc":[{"batl":[[0,3.15,10.06]],"ltp":3.1,"tv":777.98,"id":9454286}]}]}
{"op":"mcm","clk":"4289737716","pt":1632493167818,"mc":[{"id":"1.188075669","rc":[{"batl":[[0,3.15,7.96]],"ltp":3.1,"tv":777.98,"id":9454286}]}]}
{"op":"mcm","clk":"4289737810","pt":1632493168820,"mc":[{"id":"1.188075669","rc":[{"batl":[[1,1.48,6.57]],"ltp":1.47,"tv":11048.93,"id":9631939}]}]}
{"op":"mcm","clk":"4289738047","pt":1632493170032,"mc":[{"id":"1.188075669","rc":[{"batl":[[1,1.48,10.96]],"ltp":1.47,"tv":11048.93,"id":9631939}]}]}
{"op":"mcm","clk":"4289738148","pt":1632493171206,"mc":[{"id":"1.188075669","rc":[{"trd":[[1.47,112.61]],"batl":[[0,1.47,4],[1,1.48,15.34]],"ltp":1.47,"tv":11049.71,"id":9631939},{"batb":[[1,2.7,81.82]],"ltp":3.1,"tv":777.98,"id":9454286}],"tv":11827.7}]}
{"op":"mcm","clk":"4289738162","pt":1632493171410,"mc":[{"id":"1.188075669","rc":[{"batb":[[2,2.68,2.36]],"ltp":3.1,"tv":777.98,"id":9454286}]}]}
{"op":"mcm","clk":"4289738329","pt":1632493172943,"mc":[{"id":"1.188075669","rc":[{"batl":[[1,1.48,17.53]],"ltp":1.47,"tv":11049.71,"id":9631939},{"batb":[[0,2.72,5.09]],"ltp":3.1,"tv":777.98,"id":9454286}]}]}
{"op":"mcm","clk":"4289738433","pt":1632493174211,"mc":[{"id":"1.188075669","rc":[{"trd":[[1.45,84.27],[1.46,172.87],[1.47,120.03]],"batb":[[0,1.45,24.87],[1,1.44,256.2]],"batl":[[0,1.46,11.57],[1,1.48,2464.4],[2,1.49,214.56]],"ltp":1.45,"tv":11075.37,"id":9631939},{"trd":[[3.1,138.65],[3.15,27.61]],"batb":[[0,3.05,313.52],[1,3,437.29],[2,2.98,304.3]],"batl":[[0,3.25,2.02],[1,3.35,199.54],[2,3.4,281.24]],"ltp":3.15,"tv":789.46,"id":9454286}],"tv":11864.84}]}
{"op":"mcm","clk":"4289738514","pt":1632493175218,"mc":[{"id":"1.188075669","rc":[{"batl":[[1,1.48,433]],"ltp":1.45,"tv":11075.37,"id":9631939},{"batb":[[0,3.15,136.57],[1,3.05,313.52],[2,3,437.29]],"ltp":3.15,"tv":789.46,"id":9454286}]}]}
{"op":"mcm","clk":"4289738586","pt":1632493176219,"mc":[{"id":"1.188075669","rc":[{"trd":[[1.46,182.55]],"batl":[[0,1.46,6.73]],"ltp":1.46,"tv":11085.05,"id":9631939}],"tv":11874.52}]}
{"op":"mcm","clk":"4289738617","pt":1632493176642,"mc":[{"id":"1.188075669","rc":[{"batl":[[1,1.48,411.09],[2,1.49,205.8]],"ltp":1.46,"tv":11085.05,"id":9631939}]}]}
{"op":"mcm","clk":"4289738836","pt":1632493179035,"mc":[{"id":"1.188075669","rc":[{"trd":[[1.45,134.01]],"batb":[[0,1.44,256.2],[1,1.43,220.1],[2,1.42,330.5]],"batl":[[2,1.49,220.8]],"ltp":1.45,"tv":11134.79,"id":9631939}],"tv":11924.26}]}
{"op":"mcm","clk":"4289739000","pt":1632493180942,"mc":[{"id":"1.188075669","rc":[{"batb":[[0,1.45,246],[1,1.44,256.2],[2,1.43,220.1]],"ltp":1.45,"tv":11134.79,"id":9631939}]}]}
{"op":"mcm","clk":"4289739190","pt":1632493183137,"mc":[{"id":"1.188075669","rc":[{"batb":[[2,3,444.79]],"ltp":3.15,"tv":789.46,"id":9454286}]}]}
{"op":"mcm","clk":"4289739418","pt":1632493185841,"mc":[{"id":"1.188075669","rc":[{"batl":[[1,1.48,235.78]],"ltp":1.45,"tv":11134.79,"id":9631939}]}]}
{"op":"mcm","clk":"4289739465","pt":1632493186364,"mc":[{"id":"1.188075669","rc":[{"batb":[[1,1.44,241.58]],"batl":[[0,1.48,235.78],[1,1.49,220.8],[2,1.5,258.25]],"ltp":1.45,"tv":11134.79,"id":9631939}]}]}
{"op":"mcm","clk":"4289739744","pt":1632493189557,"mc":[{"id":"1.188075669","rc":[{"batl":[[0,1.47,39.98],[1,1.48,235.78],[2,1.49,220.8]],"ltp":1.45,"tv":11134.79,"id":9631939}]}]}
{"op":"mcm","clk":"4289739976","pt":1632493192565,"mc":[{"id":"1.188075669","rc":[{"batb":[[0,1.45,387]],"ltp":1.45,"tv":11134.79,"id":9631939},{"batb":[[0,3.15,142.66]],"batl":[[0,3.25,8.02]],"ltp":3.15,"tv":789.46,"id":9454286}]}]}
{"op":"mcm","clk":"4289740307","pt":1632493197153,"mc":[{"id":"1.188075669","rc":[{"batb":[[1,1.42,330.5],[2,1.41,93.7]],"batl":[[0,1.49,15],[1,1.54,21.75],[2,1.57,22.5]],"ltp":1.45,"tv":11134.79,"id":9631939},{"batb":[[0,3.15,136.57],[1,3,7.5],[2,2.9,169.13]],"batl":[[0,3.45,38.33],[1,3.9,2],[2,3.95,2]],"ltp":3.15,"tv":789.46,"id":9454286}]}]}
{"op":"mcm","clk":"4289740372","pt":1632493197951,"mc":[{"id":"1.188075669","rc":[{"batb":[[0,1.41,93.7],[1,1.35,33.87],[2,1.34,40.72]],"ltp":1.45,"tv":11134.79,"id":9631939},{"batb":[[0,3,7.5],[1,2.9,169.13],[2,2.84,2.22]],"ltp":3.15,"tv":789.46,"id":9454286}]}]}
{"op":"mcm","clk":"4289740422","pt":1632493198575,"mc":[{"id":"1.188075669","rc":[{"batb":[[0,1.32,489.62],[1,1.31,42.79],[2,1.3,42.48]],"batl":[[0,1.54,21.75],[1,1.57,22.5],[2,1.58,5]],"ltp":1.45,"tv":11134.79,"id":9631939},{"batb":[[0,2.9,169.13],[1,2.84,2.22],[2,2.74,2.52]],"batl":[[0,4.2,152.71],[1,4.3,2],[2,4.4,2]],"ltp":3.15,"tv":789.46,"id":9454286}]}]}
{"op":"mcm","clk":"4289740527","pt":1632493200052,"mc":[{"id":"1.188075669","rc":[{"batb":[[0,1.35,260],[1,1.34,297.58],[2,1.32,489.62]],"batl":[[1,1.55,252.18],[2,1.56,152.35]],"ltp":1.45,"tv":11134.79,"id":9631939}]}]}
{"op":"mcm","clk":"4289740617","pt":1632493200964,"mc":[{"id":"1.188075669","rc":[{"batb":[[0,1.32,489.62],[1,1.31,42.79],[2,1.3,42.48]],"batl":[[1,1.57,22.5],[2,1.58,5]],"ltp":1.45,"tv":11134.79,"id":9631939},{"batl":[[0,4.2,2]],"ltp":3.15,"tv":789.46,"id":9454286}]}]}
{"op":"mcm","clk":"4289740739","pt":1632493202169,"mc":[{"id":"1.188075669","rc":[{"batb":[[0,1.33,7],[1,1.32,499.62],[2,1.31,51.79]],"ltp":1.45,"tv":11134.79,"id":9631939},{"batl":[[0,4.2,4]],"ltp":3.15,"tv":789.46,"id":9454286}]}]}
{"op":"mcm","clk":"4289740812","pt":1632493202857,"mc":[{"id":"1.188075669","rc":[{"trd":[[1.48,361.24],[1.49,323.14]],"batb":[[0,1.42,270.65],[1,1.41,234.46],[2,1.33,7]],"batl":[[0,1.46,250.3],[1,1.47,191.82],[2,1.54,21.75]],"ltp":1.48,"tv":11147.94,"id":9631939}],"tv":11937.4}]}
{"op":"mcm","clk":"4289740934","pt":1632493204176,"mc":[{"id":"1.188075669","rc":[{"trd":[[1.46,221.98]],"batl":[[0,1.46,230.59]],"ltp":1.46,"tv":11187.36,"id":9631939}],"tv":11976.83}]}
{"op":"mcm","clk":"4289741004","pt":1632493205077,"mc":[{"id":"1.188075669","rc":[{"trd":[[1.46,235.12]],"batb":[[0,1.45,2.19],[1,1.43,2.19],[2,1.42,270.65]],"batl":[[0,1.46,224.02]],"ltp":1.46,"tv":11200.51,"id":9631939},{"batb":[[0,2.92,71.91],[1,2.9,169.13],[2,2.84,2.22]],"batl":[[0,3.95,3],[1,4.1,3],[2,4.2,4]],"ltp":3.15,"tv":789.46,"id":9454286}],"tv":11989.97}]}
