{"op":"mcm","clk":"4296965689","pt":1632571175851,"mc":[{"id":"1.188134680","rc":[{"batb":[[0,1.3,138.61]],"batl":[[0,1.31,1195.71]],"ltp":1.31,"tv":13327.32,"id":8681938}]}]}
{"op":"mcm","clk":"4296965884","pt":1632571177140,"mc":[{"id":"1.188134680","rc":[{"batb":[[0,4.2,137.11]],"ltp":4.3,"tv":3019.07,"id":9631939},{"batb":[[0,1.3,138.51]],"batl":[[0,1.31,1258.47]],"ltp":1.31,"tv":13327.32,"id":8681938}]}]}
{"op":"mcm","clk":"4296966025","pt":1632571178146,"mc":[{"id":"1.188134680","rc":[{"trd":[[1.31,300.36]],"batl":[[0,1.31,1229.59]],"ltp":1.31,"tv":13385.09,"id":8681938}],"tv":16404.16}]}
{"op":"mcm","clk":"4296966183","pt":1632571179225,"mc":[{"id":"1.188134680","rc":[{"trd":[[4.2,24.19]],"batb":[[0,4.2,135.06]],"ltp":4.2,"tv":3023.18,"id":9631939}],"tv":16408.27}]}
{"op":"mcm","clk":"4296966654","pt":1632571182257,"mc":[{"id":"1.188134680","rc":[{"batb":[[2,4,3]],"ltp":4.2,"tv":3023.18,"id":9631939}]}]}
{"op":"mcm","clk":"4296966809","pt":1632571183287,"mc":[{"id":"1.188134680","rc":[{"batb":[[0,4.2,2]],"batl":[[0,4.5,98.51],[1,4.6,123.21],[2,4.8,2]],"ltp":4.2,"tv":3023.18,"id":9631939},{"trd":[[1.31,318.96]],"batb":[[0,1.29,366.38],[1,1.28,451],[2,1.27,46.87]],"batl":[[0,1.31,534.01],[1,1.32,724.94]],"ltp":1.31,"tv":13403.69,"id":8681938}],"tv":16426.88}]}
{"op":"mcm","clk":"4296966974","pt":1632571184330,"mc":[{"id":"1.188134680","rc":[{"batb":[[0,4.1,148.19],[1,4,3],[2,3.9,100.52]],"ltp":4.2,"tv":3023.18,"id":9631939},{"trd":[[1.31,331.39]],"batl":[[0,1.31,22.04],[1,1.32,664.94]],"ltp":1.31,"tv":13416.12,"id":8681938}],"tv":16439.3}]}
{"op":"mcm","clk":"4296967274","pt":1632571186129,"mc":[{"id":"1.188134680","rc":[{"batb":[[0,4.1,148.21],[2,3.95,2]],"ltp":4.2,"tv":3023.18,"id":9631939},{"batl":[[0,1.32,886.75],[1,1.33,601.92],[2,1.35,297.52]],"ltp":1.31,"tv":13416.12,"id":8681938}]}]}
{"op":"mcm","clk":"4296967462","pt":1632571187362,"mc":[{"id":"1.188134680","rc":[{"batl":[[0,1.32,664.94],[1,1.33,1.25]],"ltp":1.31,"tv":13416.12,"id":8681938}]}]}
{"op":"mcm","clk":"4296967949","pt":1632571190349,"mc":[{"id":"1.188134680","rc":[{"batl":[[0,4.3,18.45],[1,4.5,98.51],[2,4.6,123.21]],"ltp":4.2,"tv":3023.18,"id":9631939},{"batb":[[0,1.3,21.38],[1,1.29,366.38],[2,1.28,932.42]],"batl":[[0,1.31,920.94],[1,1.32,685.3],[2,1.33,1.25]],"ltp":1.31,"tv":13416.12,"id":8681938}]}]}
{"op":"mcm","clk":"4296968106","pt":1632571191261,"mc":[{"id":"1.188134680","rc":[{"batb":[[0,4.2,15.45],[1,4.1,148.19],[2,4,3]],"batl":[[0,4.5,98.51],[1,4.6,123.21],[2,4.8,2]],"ltp":4.2,"tv":3023.18,"id":9631939},{"batb":[[0,1.29,366.38],[1,1.28,932.42],[2,1.27,844.37]],"batl":[[0,1.31,961.44],[1,1.32,726.17]],"ltp":1.31,"tv":13416.12,"id":8681938}]}]}
{"op":"mcm","clk":"4296968257","pt":1632571192110,"mc":[{"id":"1.188134680","rc":[{"batl":[[0,1.31,983.48]],"ltp":1.31,"tv":13416.12,"id":8681938}]}]}
{"op":"mcm","clk":"4296968447","pt":1632571193300,"mc":[{"id":"1.188134680","rc":[{"batl":[[0,1.31,1221.48]],"ltp":1.31,"tv":13416.12,"id":8681938}]}]}
{"op":"mcm","clk":"4296968838","pt":1632571195735,"mc":[{"id":"1.188134680","rc":[{"batb":[[0,4.2,2.02]],"ltp":4.2,"tv":3023.18,"id":9631939},{"batb":[[1,1.28,451],[2,1.27,46.87]],"batl":[[0,1.31,300.54],[1,1.32,664.94]],"ltp":1.31,"tv":13416.12,"id":8681938}]}]}
{"op":"mcm","clk":"4296969173","pt":1632571197128,"mc":[{"id":"1.188134680","rc":[{"trd":[[1.31,331.59]],"batl":[[0,1.31,300.44]],"ltp":1.31,"tv":13416.32,"id":8681938}],"tv":16439.5}]}
{"op":"mcm","clk":"4296969312","pt":1632571197931,"mc":[{"id":"1.188134680","rc":[{"batb":[[0,4.1,148.21],[1,4,3],[2,3.9,100.52]],"ltp":4.2,"tv":3023.18,"id":9631939},{"batl":[[0,1.31,22.04]],"ltp":1.31,"tv":13416.32,"id":8681938}]}]}
{"op":"mcm","clk":"4296969464","pt":1632571198754,"mc":[{"id":"1.188134680","rc":[{"batl":[[1,1.32,886.75],[2,1.33,601.92]],"ltp":1.31,"tv":13416.32,"id":8681938}]}]}
{"op":"mcm","clk":"4296970017","pt":1632571201315,"mc":[{"id":"1.188134680","rc":[{"batb":[[0,4.2,2.02],[1,4.1,148.19],[2,4,3]],"ltp":4.2,"tv":3023.18,"id":9631939}]}]}
{"op":"mcm","clk":"4296970104","pt":1632571201633,"mc":[{"id":"1.188134680","rc":[{"batb":[[0,4.1,148.21],[1,4,3],[2,3.9,100.52]],"ltp":4.2,"tv":3023.18,"id":9631939}]}]}
{"op":"mcm","clk":"4296970547","pt":1632571203125,"mc":[{"id":"1.188134680","rc":[{"trd":[[4.2,24.73]],"batb":[[0,4.1,2]],"batl":[[0,4.8,2],[1,5.2,2],[2,5.8,2.54]],"ltp":4.2,"tv":3023.72,"id":9631939},{"trd":[[1.31,333.22]],"batb":[[0,1.27,46.87],[1,1.25,611.64],[2,1.24,11.38]],"batl":[[0,1.31,20.41]],"ltp":1.31,"tv":13417.94,"id":8681938}],"tv":16441.67}]}
{"op":"mcm","clk":"4296971208","pt":1632571205331,"mc":[{"id":"1.188134680","rc":[{"trd":[[4.2,33.22]],"batb":[[1,4,956.26],[2,3.95,928.12]],"batl":[[0,4.4,6.82],[1,4.8,2],[2,5.2,2]],"ltp":4.2,"tv":3032.21,"id":9631939},{"trd":[[1.31,359.65]],"batb":[[0,1.31,137.54],[1,1.3,12762],[2,1.29,478.23]],"batl":[[0,1.32,886.75],[1,1.33,615.34],[2,1.35,446.95]],"ltp":1.31,"tv":13444.38,"id":8681938}],"tv":16476.6}]}
{"op":"mcm","clk":"4296971461","pt":1632571206370,"mc":[{"id":"1.188134680","rc":[{"batb":[[0,4.1,5],[1,4,408.12],[2,3.95,232.02]],"batl":[[1,4.8,11.4]],"ltp":4.2,"tv":3032.21,"id":9631939},{"batb":[[1,1.3,1012.86],[2,1.29,1001.09]],"batl":[[1,1.33,675.34]],"ltp":1.31,"tv":13444.38,"id":8681938}]}]}
{"op":"mcm","clk":"4296971539","pt":1632571206658,"mc":[{"id":"1.188134680","rc":[{"batb":[[0,4.1,12]],"batl":[[1,4.7,10],[2,4.8,11.4]],"ltp":4.2,"tv":3032.21,"id":9631939}]}]}
{"op":"mcm","clk":"4296971806","pt":1632571207659,"mc":[{"id":"1.188134680","rc":[{"batl":[[1,4.7,12]],"ltp":4.2,"tv":3032.21,"id":9631939}]}]}
{"op":"mcm","clk":"4296973031","pt":1632571212384,"mc":[{"id":"1.188134680","rc":[{"batl":[[1,4.6,111.78],[2,4.7,139.35]],"ltp":4.2,"tv":3032.21,"id":9631939}]}]}
{"op":"mcm","clk":"4296973268","pt":1632571213386,"mc":[{"id":"1.188134680","rc":[{"batl":[[0,1.32,1149.75]],"ltp":1.31,"tv":13444.38,"id":8681938}]}]}
{"op":"mcm","clk":"4296973684","pt":1632571215288,"mc":[{"id":"1.188134680","rc":[{"trd":[[4.3,30.08]],"ltp":4.3,"tv":3041.61,"id":9631939},{"trd":[[1.31,390.48]],"batb":[[0,1.31,106.71]],"batl":[[1,1.33,661.92]],"ltp":1.31,"tv":13475.21,"id":8681938}],"tv":16516.82}]}
{"op":"mcm","clk":"4296974097","pt":1632571217081,"mc":[{"id":"1.188134680","rc":[{"trd":[[4.1,115.77]],"batb":[[0,4.1,11.03]],"ltp":4.1,"tv":3043.55,"id":9631939},{"batb":[[1,1.29,1001.09],[2,1.28,1970.24]],"batl":[[0,1.32,1333.75]],"ltp":1.31,"tv":13475.21,"id":8681938}],"tv":16518.76}]}
{"op":"mcm","clk":"4296974383","pt":1632571218293,"mc":[{"id":"1.188134680","rc":[{"batl":[[0,4.3,6.05],[1,4.4,6.82],[2,4.6,111.78]],"ltp":4.1,"tv":3043.55,"id":9631939},{"batl":[[0,1.32,1348.75]],"ltp":1.31,"tv":13475.21,"id":8681938}]}]}
{"op":"mcm","clk":"4296979494","pt":1632571243040,"mc":[{"id":"1.188134680","rc":[{"trd":[[1.32,49.8]],"batl":[[0,1.32,1348.44]],"ltp":1.32,"tv":13475.83,"id":8681938}],"tv":16519.38}]}
{"op":"mcm","clk":"4296979881","pt":1632571245041,"mc":[{"id":"1.188134680","rc":[{"trd":[[1.31,417.9]],"batb":[[0,1.31,93]],"ltp":1.31,"tv":13503.25,"id":8681938}],"tv":16546.8}]}
{"op":"mcm","clk":"4296981907","pt":1632571254876,"mc":[{"id":"1.188134680","rc":[{"trd":[[1.31,420.64]],"batb":[[0,1.31,91.63]],"ltp":1.31,"tv":13505.99,"id":8681938}],"tv":16549.54}]}
{"op":"mcm","clk":"4296982515","pt":1632571257986,"mc":[{"id":"1.188134680","rc":[{"trd":[[1.32,57.31]],"batl":[[0,1.32,1344.68]],"ltp":1.32,"tv":13513.51,"id":8681938}],"tv":16557.06}]}
{"op":"mcm","clk":"4296982680","pt":1632571258787,"mc":[{"id":"1.188134680","rc":[{"trd":[[1.31,448.05]],"batb":[[0,1.31,77.92]],"ltp":1.31,"tv":13540.92,"id":8681938}],"tv":16584.47}]}
{"op":"mcm","clk":"4296983049","pt":1632571260492,"mc":[{"id":"1.188134680","rc":[{"trd":[[1.31,452.75]],"batb":[[0,1.31,75.57]],"ltp":1.31,"tv":13545.62,"id":8681938}],"tv":16589.17}]}
{"op":"mcm","clk":"4296986643","pt":1632571276399,"mc":[{"id":"1.188134680","rc":[{"trd":[[4.3,30.71]],"batl":[[0,4.3,5.74]],"ltp":4.3,"tv":3044.17,"id":9631939}],"tv":16589.8}]}
{"op":"mcm","clk":"4296988814","pt":1632571286542,"mc":[{"id":"1.188134680","rc":[{"batl":[[0,4.4,6.82],[1,4.6,111.78],[2,4.7,139.35]],"ltp":4.3,"tv":3044.17,"id":9631939},{"batl":[[0,1.32,1329.68]],"ltp":1.31,"tv":13545.62,"id":8681938}]}]}
{"op":"mcm","clk":"4296989495","pt":1632571289601,"mc":[{"id":"1.188134680","rc":[{"batl":[[0,4.3,5.74],[1,4.4,6.82],[2,4.6,111.78]],"ltp":4.3,"tv":3044.17,"id":9631939},{"batl":[[0,1.32,1345.69]],"ltp":1.31,"tv":13545.62,"id":8681938}]}]}
{"op":"mcm","clk":"4296989876","pt":1632571291267,"mc":[{"id":"1.188134680","rc":[{"batb":[[0,4,169.06],[1,3.6,98.16],[2,3.55,141.87]],"batl":[[0,4.6,111.78],[1,4.7,129.35],[2,4.8,9.69]],"ltp":4.3,"tv":3044.17,"id":9631939},{"trd":[[1.32,62.01]],"batb":[[0,1.29,522.86],[1,1.28,380.91],[2,1.27,471.95]],"batl":[[0,1.32,444.65],[1,1.33,61.25],[2,1.38,47.63]],"ltp":1.32,"tv":13550.32,"id":8681938}],"tv":16594.49}]}
{"op":"mcm","clk":"4296990100","pt":1632571292307,"mc":[{"id":"1.188134680","rc":[{"batb":[[0,3.6,98.16],[1,3.55,141.87],[2,3.5,131.83]],"batl":[[2,4.8,2]],"ltp":4.3,"tv":3044.17,"id":9631939},{"batb":[[0,1.28,380.91],[1,1.27,420.53],[2,1.26,570.3]],"batl":[[1,1.33,1.25],[2,1.39,277.72]],"ltp":1.32,"tv":13550.32,"id":8681938}]}]}
{"op":"mcm","clk":"4296990164","pt":1632571292569,"mc":[{"id":"1.188134680","rc":[{"batl":[[0,1.33,1.25],[1,1.39,277.72],[2,1.4,283.25]],"ltp":1.32,"tv":13550.32,"id":8681938}]}]}
{"op":"mcm","clk":"4296990561","pt":1632571294205,"mc":[{"id":"1.188134680","rc":[{"batb":[[0,3.7,2],[1,3.6,98.16],[2,3.55,143.87]],"batl":[[0,4.6,113.78]],"ltp":4.3,"tv":3044.17,"id":9631939},{"batb":[[0,1.28,423.82],[1,1.27,1127.61],[2,1.26,1461.2]],"batl":[[1,1.37,635.74],[2,1.38,505.97]],"ltp":1.32,"tv":13550.32,"id":8681938}]}]}
{"op":"mcm","clk":"4296990737","pt":1632571294872,"mc":[{"id":"1.188134680","rc":[{"batl":[[0,4.6,116.78],[2,4.9,2]],"ltp":4.3,"tv":3044.17,"id":9631939},{"batb":[[1,1.27,1080.74]],"ltp":1.32,"tv":13550.32,"id":8681938}]}]}
{"op":"mcm","clk":"4296991035","pt":1632571296119,"mc":[{"id":"1.188134680","rc":[{"batb":[[1,3.6,101.16],[2,3.55,5]],"ltp":4.3,"tv":3044.17,"id":9631939},{"batl":[[1,1.37,31.81],[2,1.39,31.5]],"ltp":1.32,"tv":13550.32,"id":8681938}]}]}
{"op":"mcm","clk":"4296991308","pt":1632571297258,"mc":[{"id":"1.188134680","rc":[{"batb":[[0,3.7,5],[1,3.65,3],[2,3.6,101.16]],"ltp":4.3,"tv":3044.17,"id":9631939}]}]}
{"op":"mcm","clk":"4296991792","pt":1632571299376,"mc":[{"id":"1.188134680","rc":[{"batb":[[0,4.4,5.44],[1,4.2,2],[2,3.7,5]],"batl":[[1,4.7,198.81]],"ltp":4.3,"tv":3044.17,"id":9631939},{"batb":[[0,1.28,437.32]],"batl":[[0,1.3,1350.63],[1,1.31,1393.86],[2,1.32,903.69]],"ltp":1.32,"tv":13550.32,"id":8681938}]}]}
{"op":"mcm","clk":"4296992014","pt":1632571300299,"mc":[{"id":"1.188134680","rc":[{"batb":[[1,4.2,152.31],[2,3.8,85.57]],"batl":[[0,4.6,114.78],[1,4.7,205.19]],"ltp":4.3,"tv":3044.17,"id":9631939},{"batb":[[0,1.28,13.5]],"batl":[[2,1.32,963.69]],"ltp":1.32,"tv":13550.32,"id":8681938}]}]}
{"op":"mcm","clk":"4296992691","pt":1632571303186,"mc":[{"id":"1.188134680","rc":[{"batb":[[0,4.4,7.44],[1,4.3,3],[2,4.2,152.31]],"batl":[[0,4.6,111.78]],"ltp":4.3,"tv":3044.17,"id":9631939},{"batb":[[0,1.28,23.5],[1,1.27,1090.74]],"batl":[[0,1.3,1360.63]],"ltp":1.32,"tv":13550.32,"id":8681938}]}]}
{"op":"mcm","clk":"4296992927","pt":1632571304280,"mc":[{"id":"1.188134680","rc":[{"batb":[[0,4.4,5.44],[1,4.2,133.56],[2,3.8,85.57]],"ltp":4.3,"tv":3044.17,"id":9631939},{"batb":[[0,1.28,13.5]],"batl":[[0,1.29,325.71],[1,1.3,1350.63],[2,1.31,1393.86]],"ltp":1.32,"tv":13550.32,"id":8681938}]}]}
{"op":"mcm","clk":"4296993287","pt":1632571306031,"mc":[{"id":"1.188134680","rc":[{"batb":[[2,4.1,2]],"batl":[[2,4.8,2]],"ltp":4.3,"tv":3044.17,"id":9631939},{"batb":[[1,1.27,1136.61],[2,1.26,1869.08]],"ltp":1.32,"tv":13550.32,"id":8681938}]}]}
{"op":"mcm","clk":"4296993539","pt":1632571307340,"mc":[{"id":"1.188134680","rc":[{"batb":[[1,4.3,18.18],[2,4.2,133.56]],"ltp":4.3,"tv":3044.17,"id":9631939},{"batl":[[0,1.29,641.71],[2,1.31,1453.86]],"ltp":1.32,"tv":13550.32,"id":8681938}]}]}
{"op":"mcm","clk":"4296993949","pt":1632571309328,"mc":[{"id":"1.188134680","rc":[{"trd":[[4.4,119.68]],"batb":[[0,4.3,18.18],[1,4.2,131.56],[2,4.1,2]],"batl":[[0,4.7,2],[1,4.8,2],[2,4.9,106.32]],"ltp":4.4,"tv":3048.87,"id":9631939},{"batb":[[0,1.27,762.95],[1,1.26,1869.08],[2,1.25,1092]],"batl":[[1,1.3,795.68],[2,1.31,709.4]],"ltp":1.32,"tv":13550.32,"id":8681938}],"tv":16599.19}]}
{"op":"mcm","clk":"4296994155","pt":1632571310324,"mc":[{"id":"1.188134680","rc":[{"batb":[[0,4.1,2],[1,3.9,127.24],[2,3.85,121.11]],"batl":[[0,4.9,106.32],[1,5,117.57],[2,5.8,2.54]],"ltp":4.4,"tv":3048.87,"id":9631939},{"batb":[[0,1.26,991.67],[1,1.25,1039.75],[2,1.01,140]],"batl":[[1,1.32,38.11],[2,1.33,1.25]],"ltp":1.32,"tv":13550.32,"id":8681938}]}]}
{"op":"mcm","clk":"4296994277","pt":1632571310920,"mc":[{"id":"1.188134680","rc":[{"batb":[[0,3.9,127.24],[1,3.85,121.11],[2,3.8,85.57]],"batl":[[1,5,115.86]],"ltp":4.4,"tv":3048.87,"id":9631939},{"batl":[[0,1.29,13.71],[1,1.33,1.25],[2,1.34,41.75]],"ltp":1.32,"tv":13550.32,"id":8681938}]}]}
{"op":"mcm","clk":"4296994589","pt":1632571312315,"mc":[{"id":"1.188134680","rc":[{"batb":[[1,1.25,1916.89]],"batl":[[2,1.34,887.65]],"ltp":1.32,"tv":13550.32,"id":8681938}]}]}
{"op":"mcm","clk":"4296994821","pt":1632571313213,"mc":[{"id":"1.188134680","rc":[{"batl":[[0,4.9,109.32]],"ltp":4.4,"tv":3048.87,"id":9631939},{"batb":[[0,1.26,1001.67],[1,1.25,1925.89]],"ltp":1.32,"tv":13550.32,"id":8681938}]}]}
{"op":"mcm","clk":"4296995028","pt":1632571314125,"mc":[{"id":"1.188134680","rc":[{"batb":[[0,4.1,2],[1,3.9,127.24],[2,3.85,121.11]],"ltp":4.4,"tv":3048.87,"id":9631939},{"batl":[[1,1.32,36.36],[2,1.33,1.25]],"ltp":1.32,"tv":13550.32,"id":8681938}]}]}
{"op":"mcm","clk":"4296995206","pt":1632571314938,"mc":[{"id":"1.188134680","rc":[{"batb":[[0,3.9,2],[1,3.8,85.57],[2,3.7,3]],"ltp":4.4,"tv":3048.87,"id":9631939},{"batl":[[1,1.33,1.25],[2,1.34,41.75]],"ltp":1.32,"tv":13550.32,"id":8681938}]}]}
{"op":"mcm","clk":"4296995511","pt":1632571316203,"mc":[{"id":"1.188134680","rc":[{"batl":[[0,1.33,1.25],[1,1.34,41.75],[2,4.4,3.65]],"ltp":1.32,"tv":13550.32,"id":8681938}]}]}
{"op":"mcm","clk":"4296995953","pt":1632571318302,"mc":[{"id":"1.188134680","rc":[{"batb":[[0,4.5,104.44],[1,4.4,176.99],[2,4.3,52.22]],"batl":[[0,4.8,4.43],[1,4.9,109.32],[2,5,153.48]],"ltp":4.4,"tv":3048.87,"id":9631939},{"batb":[[1,1.25,2076.38],[2,1.23,53.1]],"batl":[[0,1.28,357.9],[1,1.29,1379.99],[2,1.3,220.83]],"ltp":1.32,"tv":13550.32,"id":8681938}]}]}
{"op":"mcm","clk":"4296996170","pt":1632571319229,"mc":[{"id":"1.188134680","rc":[{"batb":[[2,4.3,70.4]],"batl":[[0,4.9,129.54],[1,5,153.48],[2,5.1,92.16]],"ltp":4.4,"tv":3048.87,"id":9631939},{"batb":[[0,1.26,1045.93]],"batl":[[0,1.28,334.19],[1,1.29,1480.7]],"ltp":1.32,"tv":13550.32,"id":8681938}]}]}
{"op":"mcm","clk":"4296996794","pt":1632571322213,"mc":[{"id":"1.188134680","rc":[{"batl":[[0,4.8,4.43],[1,4.9,129.54],[2,5,153.48]],"ltp":4.4,"tv":3048.87,"id":9631939},{"batl":[[0,1.27,4.11],[1,1.28,357.9],[2,1.29,1480.7]],"ltp":1.32,"tv":13550.32,"id":8681938}]}]}
{"op":"mcm","clk":"4296996959","pt":1632571323035,"mc":[{"id":"1.188134680","rc":[{"batb":[[2,4.3,52.22]],"ltp":4.4,"tv":3048.87,"id":9631939},{"batl":[[0,1.27,8.22],[1,1.28,487.9]],"ltp":1.32,"tv":13550.32,"id":8681938}]}]}
{"op":"mcm","clk":"4296997260","pt":1632571324242,"mc":[{"id":"1.188134680","rc":[{"batb":[[2,4.3,54.22]],"batl":[[2,5,155.48]],"ltp":4.4,"tv":3048.87,"id":9631939},{"batb":[[1,1.25,2123.63]],"batl":[[0,1.27,12.34]],"ltp":1.32,"tv":13550.32,"id":8681938}]}]}
{"op":"mcm","clk":"4296997366","pt":1632571324737,"mc":[{"id":"1.188134680","rc":[{"batl":[[2,5,256.66]],"ltp":4.4,"tv":3048.87,"id":9631939},{"batb":[[1,1.25,2459.73],[2,1.24,437.5]],"ltp":1.32,"tv":13550.32,"id":8681938}]}]}
{"op":"mcm","clk":"4296997681","pt":1632571326038,"mc":[{"id":"1.188134680","rc":[{"batb":[[1,4.4,194.63]],"ltp":4.4,"tv":3048.87,"id":9631939},{"batl":[[1,1.28,719.9]],"ltp":1.32,"tv":13550.32,"id":8681938}]}]}
{"op":"mcm","clk":"4296998747","pt":1632571331356,"mc":[{"id":"1.188134680","rc":[{"batb":[[0,4.4,17.64],[1,4.3,2],[2,4.2,2]],"batl":[[0,4.9,2],[1,5,103.18],[2,5.1,95.88]],"ltp":4.4,"tv":3048.87,"id":9631939},{"batb":[[0,1.26,50.98],[1,1.25,1689.08]],"batl":[[1,1.28,362],[2,1.29,60]],"ltp":1.32,"tv":13550.32,"id":8681938}]}]}
{"op":"mcm","clk":"4296998938","pt":1632571332273,"mc":[{"id":"1.188134680","rc":[{"batb":[[0,4.3,2],[1,4.2,2],[2,4.1,112.89]],"batl":[[0,5,103.18],[1,5.1,95.88],[2,5.8,2.54]],"ltp":4.4,"tv":3048.87,"id":9631939},{"batb":[[0,1.25,1689.08],[1,1.24,437.5],[2,1.01,140]],"batl":[[1,1.3,46.95],[2,1.31,42.5]],"ltp":1.32,"tv":13550.32,"id":8681938}]}]}
{"op":"mcm","clk":"4296999091","pt":1632571332933,"mc":[{"id":"1.188134680","rc":[{"batb":[[0,4.1,112.89],[1,4,275.58],[2,3.95,2]],"ltp":4.4,"tv":3048.87,"id":9631939},{"trd":[[1.27,27.21]],"batl":[[0,1.27,12.18],[1,1.32,358.5],[2,1.33,321.72]],"ltp":1.27,"tv":13550.63,"id":8681938}],"tv":16599.5}]}
{"op":"mcm","clk":"4296999354","pt":1632571334243,"mc":[{"id":"1.188134680","rc":[{"batb":[[1,1.24,1363.08]],"batl":[[1,1.31,635.49],[2,1.32,985.53]],"ltp":1.27,"tv":13550.63,"id":8681938}]}]}
{"op":"mcm","clk":"4296999550","pt":1632571335153,"mc":[{"id":"1.188134680","rc":[{"batl":[[0,5,106.18],[2,5.3,7.23]],"ltp":4.4,"tv":3048.87,"id":9631939},{"batb":[[0,1.25,1700.08],[1,1.24,1371.08],[2,1.23,125.1]],"ltp":1.27,"tv":13550.63,"id":8681938}]}]}
{"op":"mcm","clk":"4296999757","pt":1632571336131,"mc":[{"id":"1.188134680","rc":[{"batb":[[0,4.3,2],[1,4.1,112.89],[2,4,275.58]],"batl":[[2,5.8,2.54]],"ltp":4.4,"tv":3048.87,"id":9631939},{"batb":[[2,1.01,140]],"batl":[[1,1.3,42.15],[2,1.31,635.49]],"ltp":1.27,"tv":13550.63,"id":8681938}]}]}
{"op":"mcm","clk":"4297000025","pt":1632571337256,"mc":[{"id":"1.188134680","rc":[{"batb":[[0,4.1,2],[1,4,148.98],[2,3.95,2]],"ltp":4.4,"tv":3048.87,"id":9631939},{"batl":[[1,1.32,38.36],[2,1.33,8.25]],"ltp":1.27,"tv":13550.63,"id":8681938}]}]}
{"op":"mcm","clk":"4297000226","pt":1632571338228,"mc":[{"id":"1.188134680","rc":[{"batl":[[0,4.9,2],[1,5,106.18],[2,5.1,95.88]],"ltp":4.4,"tv":3048.87,"id":9631939},{"batb":[[0,1.26,39.98],[1,1.25,1700.08],[2,1.24,1371.08]],"batl":[[1,1.33,8.25],[2,4.4,3.65]],"ltp":1.27,"tv":13550.63,"id":8681938}]}]}
{"op":"mcm","clk":"4297000362","pt":1632571338817,"mc":[{"id":"1.188134680","rc":[{"batl":[[0,5,106.18],[1,5.1,95.88],[2,5.8,2.54]],"ltp":4.4,"tv":3048.87,"id":9631939},{"trd":[[1.27,27.29]],"batb":[[0,1.25,1700.08],[1,1.24,1371.08],[2,1.01,140]],"batl":[[0,1.27,12.14]],"ltp":1.27,"tv":13550.71,"id":8681938}],"tv":16599.58}]}
{"op":"mcm","clk":"4297000655","pt":1632571340164,"mc":[{"id":"1.188134680","rc":[{"batb":[[0,4.8,4.08],[1,4.5,2],[2,4.1,2]],"batl":[[0,5,110.83],[1,5.1,146.43]],"ltp":4.4,"tv":3048.87,"id":9631939},{"batb":[[2,1.22,53.53]],"batl":[[0,1.27,382.22],[1,1.28,1966.08],[2,1.29,885.88]],"ltp":1.27,"tv":13550.71,"id":8681938}]}]}
{"op":"mcm","clk":"4297000932","pt":1632571341358,"mc":[{"id":"1.188134680","rc":[{"batb":[[1,4.5,134.89],[2,4.2,134.1]],"batl":[[1,5.1,152.31],[2,5.3,90.39]],"ltp":4.4,"tv":3048.87,"id":9631939},{"batb":[[1,1.24,2020.51]],"batl":[[1,1.28,2026.08]],"ltp":1.27,"tv":13550.71,"id":8681938}]}]}
{"op":"mcm","clk":"4297001144","pt":1632571342280,"mc":[{"id":"1.188134680","rc":[{"batb":[[2,4.2,144.1]],"batl":[[0,5,123.32]],"ltp":4.4,"tv":3048.87,"id":9631939},{"batb":[[0,1.25,1750.03]],"ltp":1.27,"tv":13550.71,"id":8681938}]}]}
{"op":"mcm","clk":"4297001585","pt":1632571344339,"mc":[{"id":"1.188134680","rc":[{"batl":[[0,5,123.73]],"ltp":4.4,"tv":3048.87,"id":9631939},{"batl":[[0,1.27,492.22]],"ltp":1.27,"tv":13550.71,"id":8681938}]}]}
{"op":"mcm","clk":"4297001800","pt":1632571345362,"mc":[{"id":"1.188134680","rc":[{"batb":[[1,4.5,117.75]],"ltp":4.4,"tv":3048.87,"id":9631939}]}]}
{"op":"mcm","clk":"4297002235","pt":1632571347320,"mc":[{"id":"1.188134680","rc":[{"batb":[[2,4.4,2]],"batl":[[1,5.1,253.25],[2,5.2,102.5]],"ltp":4.4,"tv":3048.87,"id":9631939},{"batb":[[0,1.25,1750.21],[1,1.24,2517.24],[2,1.23,531.39]],"batl":[[0,1.27,619.22],[2,1.29,926.38]],"ltp":1.27,"tv":13550.71,"id":8681938}]}]}
{"op":"mcm","clk":"4297002483","pt":1632571348562,"mc":[{"id":"1.188134680","rc":[{"batb":[[1,4.6,16.66],[2,4.5,117.75]],"ltp":4.4,"tv":3048.87,"id":9631939}]}]}
{"op":"mcm","clk":"4297002894","pt":1632571350551,"mc":[{"id":"1.188134680","rc":[{"batl":[[0,1.27,785.22]],"ltp":1.27,"tv":13550.71,"id":8681938}]}]}
{"op":"mcm","clk":"4297003152","pt":1632571351751,"mc":[{"id":"1.188134680","rc":[{"trd":[[1.27,37.86]],"batl":[[0,1.27,779.93]],"ltp":1.27,"tv":13561.29,"id":8681938}],"tv":16610.16}]}
{"op":"mcm","clk":"4297003439","pt":1632571353167,"mc":[{"id":"1.188134680","rc":[{"batb":[[0,4.6,16.66],[1,4.4,2],[2,4.3,109.72]],"batl":[[0,5,5.41],[1,5.1,100.94]],"ltp":4.4,"tv":3048.87,"id":9631939},{"batb":[[0,1.25,58.44],[1,1.24,2079.74]],"batl":[[0,1.27,409.85],[1,1.28,60],[2,1.29,481.24]],"ltp":1.27,"tv":13561.29,"id":8681938}]}]}
{"op":"mcm","clk":"4297003662","pt":1632571354245,"mc":[{"id":"1.188134680","rc":[{"batb":[[0,4.4,2],[1,4.3,109.72],[2,4.2,271.97]],"batl":[[0,5,3.41]],"ltp":4.4,"tv":3048.87,"id":9631939},{"batb":[[0,1.25,11.19]],"batl":[[0,1.27,6.85],[1,1.29,481.24],[2,1.3,303.7]],"ltp":1.27,"tv":13561.29,"id":8681938}]}]}
{"op":"mcm","clk":"4297004105","pt":1632571356363,"mc":[{"id":"1.188134680","rc":[{"batb":[[1,1.24,2257.11],[2,1.23,1515.77]],"batl":[[2,1.3,986.13]],"ltp":1.27,"tv":13561.29,"id":8681938}]}]}
{"op":"mcm","clk":"4297004266","pt":1632571357069,"mc":[{"id":"1.188134680","rc":[{"batl":[[1,5.2,2],[2,5.8,2.54]],"ltp":4.4,"tv":3048.87,"id":9631939},{"batb":[[1,1.24,713.71],[2,1.01,140]],"ltp":1.27,"tv":13561.29,"id":8681938}]}]}
{"op":"mcm","clk":"4297004690","pt":1632571359066,"mc":[{"id":"1.188134680","rc":[{"batl":[[0,1.29,481.24],[1,1.3,986.13],[2,1.31,314.66]],"ltp":1.27,"tv":13561.29,"id":8681938}]}]}
{"op":"mcm","clk":"4297004955","pt":1632571360371,"mc":[{"id":"1.188134680","rc":[{"batb":[[0,4.5,6.84],[1,4.4,2],[2,4.3,109.72]],"batl":[[0,4.8,52.53],[1,4.9,6.12],[2,5,171.26]],"ltp":4.4,"tv":3048.87,"id":9631939},{"batb":[[0,1.27,359.18],[1,1.26,1205.37],[2,1.25,197.69]],"batl":[[1,1.3,1134.32]],"ltp":1.27,"tv":13561.29,"id":8681938}]}]}
{"op":"mcm","clk":"4297005082","pt":1632571361014,"mc":[{"id":"1.188134680","rc":[{"batl":[[1,4.9,23.17]],"ltp":4.4,"tv":3048.87,"id":9631939},{"batb":[[0,1.27,922.04],[1,1.26,1849.37],[2,1.25,3227.99]],"batl":[[1,1.3,1495.86],[2,1.31,495.42]],"ltp":1.27,"tv":13561.29,"id":8681938}]}]}
{"op":"mcm","clk":"4297005382","pt":1632571362381,"mc":[{"id":"1.188134680","rc":[{"batb":[[2,4.3,127.9]],"batl":[[1,4.9,8.12]],"ltp":4.4,"tv":3048.87,"id":9631939},{"batb":[[0,1.27,925.56],[1,1.26,1801.42]],"batl":[[1,1.3,1555.86]],"ltp":1.27,"tv":13561.29,"id":8681938}]}]}
{"op":"mcm","clk":"4297005498","pt":1632571362962,"mc":[{"id":"1.188134680","rc":[{"batl":[[0,4.7,2],[1,4.8,52.53],[2,4.9,8.12]],"ltp":4.4,"tv":3048.87,"id":9631939},{"batb":[[0,1.27,933.56]],"ltp":1.27,"tv":13561.29,"id":8681938}]}]}
{"op":"mcm","clk":"4297005949","pt":1632571365076,"mc":[{"id":"1.188134680","rc":[{"batl":[[1,4.8,69.58]],"ltp":4.4,"tv":3048.87,"id":9631939},{"batb":[[0,1.27,989.51],[2,1.25,197.69]],"batl":[[0,1.28,371],[1,1.29,481.24],[2,1.3,1555.86]],"ltp":1.27,"tv":13561.29,"id":8681938}]}]}
{"op":"mcm","clk":"4297006182","pt":1632571366184,"mc":[{"id":"1.188134680","rc":[{"batb":[[0,1.27,1023.27]],"ltp":1.27,"tv":13561.29,"id":8681938}]}]}
{"op":"mcm","clk":"4297006373","pt":1632571367061,"mc":[{"id":"1.188134680","rc":[{"batl":[[1,4.8,172.86],[2,4.9,114.13]],"ltp":4.4,"tv":3048.87,"id":9631939},{"batb":[[1,1.26,2135.88],[2,1.25,612.68]],"ltp":1.27,"tv":13561.29,"id":8681938}]}]}
{"op":"mcm","clk":"4297006593","pt":1632571368120,"mc":[{"id":"1.188134680","rc":[{"batb":[[2,4.3,129.9]],"ltp":4.4,"tv":3048.87,"id":9631939},{"batb":[[0,1.27,1019.13],[2,1.25,651.25]],"batl":[[2,1.3,1602.41]],"ltp":1.27,"tv":13561.29,"id":8681938}]}]}
{"op":"mcm","clk":"4297007279","pt":1632571371589,"mc":[{"id":"1.188134680","rc":[{"batl":[[0,1.28,591]],"ltp":1.27,"tv":13561.29,"id":8681938}]}]}
{"op":"mcm","clk":"4297007633","pt":1632571373267,"mc":[{"id":"1.188134680","rc":[{"batb":[[0,4.4,2],[1,4.3,20.18],[2,4.2,134.1]],"batl":[[1,4.8,103.28],[2,4.9,108.01]],"ltp":4.4,"tv":3048.87,"id":9631939},{"batb":[[0,1.27,608.14],[1,1.26,1387.59],[2,1.25,464.75]],"batl":[[1,1.29,40.5],[2,1.3,106.55]],"ltp":1.27,"tv":13561.29,"id":8681938}]}]}
{"op":"mcm","clk":"4297007853","pt":1632571374308,"mc":[{"id":"1.188134680","rc":[{"batb":[[1,4.3,2],[2,4,103.87]],"batl":[[0,4.8,103.28],[1,4.9,108.01],[2,5,5.41]],"ltp":4.4,"tv":3048.87,"id":9631939},{"trd":[[1.27,437.86]],"batb":[[0,1.27,37.28]],"batl":[[2,1.3,46.55]],"ltp":1.27,"tv":13961.29,"id":8681938}],"tv":17010.16}]}
{"op":"mcm","clk":"4297007961","pt":1632571374884,"mc":[{"id":"1.188134680","rc":[{"batb":[[0,4.3,2],[1,4,103.87],[2,3.95,148.1]],"batl":[[2,5,2.41]],"ltp":4.4,"tv":3048.87,"id":9631939},{"batl":[[0,1.3,46.55],[1,1.33,348.38],[2,1.34,413.1]],"ltp":1.27,"tv":13961.29,"id":8681938}]}]}
{"op":"mcm","clk":"4297008222","pt":1632571376342,"mc":[{"id":"1.188134680","rc":[{"batb":[[0,1.28,4.14],[1,1.27,37.28],[2,1.26,1387.59]],"batl":[[1,1.32,725.2],[2,1.33,950.42]],"ltp":1.27,"tv":13961.29,"id":8681938}]}]}
{"op":"mcm","clk":"4297008578","pt":1632571378174,"mc":[{"id":"1.188134680","rc":[{"batb":[[0,4.4,2],[1,4.3,4],[2,4.2,2]],"ltp":4.4,"tv":3048.87,"id":9631939},{"batl":[[0,1.29,44.5],[1,1.3,56.55],[2,1.32,725.2]],"ltp":1.27,"tv":13961.29,"id":8681938}]}]}
{"op":"mcm","clk":"4297008640","pt":1632571378445,"mc":[{"id":"1.188134680","rc":[{"batb":[[0,4.3,4],[1,4.2,2],[2,4,103.87]],"ltp":4.4,"tv":3048.87,"id":9631939},{"batl":[[0,1.3,56.55],[1,1.32,725.2],[2,1.33,950.42]],"ltp":1.27,"tv":13961.29,"id":8681938}]}]}
{"op":"mcm","clk":"4297009192","pt":1632571381383,"mc":[{"id":"1.188134680","rc":[{"batb":[[2,3.95,2]],"ltp":4.4,"tv":3048.87,"id":9631939},{"batl":[[1,1.33,8.25],[2,4.4,3.65]],"ltp":1.27,"tv":13961.29,"id":8681938}]}]}
{"op":"mcm","clk":"4297009365","pt":1632571382241,"mc":[{"id":"1.188134680","rc":[{"batb":[[0,1.27,37.28],[1,1.26,799.54],[2,1.25,1340.16]],"ltp":1.27,"tv":13961.29,"id":8681938}]}]}
{"op":"mcm","clk":"4297009776","pt":1632571384236,"mc":[{"id":"1.188134680","rc":[{"batb":[[0,4.6,510.88],[1,4.5,298.63],[2,4.4,1206.71]],"batl":[[2,5,31.66]],"ltp":4.4,"tv":3048.87,"id":9631939},{"trd":[[1.27,472.47]],"batb":[[0,1.27,19.98],[2,1.25,1456.98]],"batl":[[0,1.28,983.71],[1,1.3,56.55],[2,1.31,22.9]],"ltp":1.27,"tv":13995.89,"id":8681938}],"tv":17044.76}]}
{"op":"mcm","clk":"4297009983","pt":1632571385216,"mc":[{"id":"1.188134680","rc":[{"batb":[[0,4.6,102.18],[1,4.5,94.27],[2,4.4,364.27]],"ltp":4.4,"tv":3048.87,"id":9631939},{"batb":[[2,1.25,2054.33]],"batl":[[0,1.28,419.64],[1,1.29,712.02],[2,1.3,46.55]],"ltp":1.27,"tv":13995.89,"id":8681938}]}]}
{"op":"mcm","clk":"4297010213","pt":1632571386249,"mc":[{"id":"1.188134680","rc":[{"batb":[[1,4.5,111.41],[2,4.4,380.61]],"ltp":4.4,"tv":3048.87,"id":9631939},{"trd":[[1.28,150.85]],"batl":[[0,1.28,419.19],[1,1.29,756.5],[2,1.3,106.55]],"ltp":1.28,"tv":13996.79,"id":8681938}],"tv":17045.66}]}
{"op":"mcm","clk":"4297010832","pt":1632571389171,"mc":[{"id":"1.188134680","rc":[{"batl":[[1,4.9,142.37]],"ltp":4.4,"tv":3048.87,"id":9631939},{"batl":[[1,1.29,865.65]],"ltp":1.28,"tv":13996.79,"id":8681938}]}]}
{"op":"mcm","clk":"4297010944","pt":1632571389791,"mc":[{"id":"1.188134680","rc":[{"batl":[[1,4.9,108.01]],"ltp":4.4,"tv":3048.87,"id":9631939},{"batl":[[1,1.29,756.5],[2,1.3,46.55]],"ltp":1.28,"tv":13996.79,"id":8681938}]}]}
{"op":"mcm","clk":"4297011473","pt":1632571392343,"mc":[{"id":"1.188134680","rc":[{"trd":[[1.28,159.13]],"batl":[[0,1.28,609.05]],"ltp":1.28,"tv":14005.07,"id":8681938}],"tv":17053.95}]}
{"op":"mcm","clk":"4297011633","pt":1632571392947,"mc":[{"id":"1.188134680","rc":[{"batl":[[1,1.29,816.5]],"ltp":1.28,"tv":14005.07,"id":8681938}]}]}
{"op":"mcm","clk":"4297011961","pt":1632571394377,"mc":[{"id":"1.188134680","rc":[{"batl":[[2,5,27.39]],"ltp":4.4,"tv":3048.87,"id":9631939},{"batb":[[2,1.25,2037.25]],"ltp":1.28,"tv":14005.07,"id":8681938}]}]}
{"op":"mcm","clk":"4297012136","pt":1632571395137,"mc":[{"id":"1.188134680","rc":[{"trd":[[1.28,163.83]],"batl":[[0,1.28,606.7]],"ltp":1.28,"tv":14009.77,"id":8681938}],"tv":17058.64}]}
{"op":"mcm","clk":"4297012209","pt":1632571395562,"mc":[{"id":"1.188134680","rc":[{"batl":[[0,1.28,834.7]],"ltp":1.28,"tv":14009.77,"id":8681938}]}]}
{"op":"mcm","clk":"4297012644","pt":1632571397366,"mc":[{"id":"1.188134680","rc":[{"batl":[[0,4.8,107.71]],"ltp":4.4,"tv":3048.87,"id":9631939},{"trd":[[1.28,180.97]],"batl":[[0,1.28,849.24]],"ltp":1.28,"tv":14026.91,"id":8681938}],"tv":17075.79}]}
{"op":"mcm","clk":"4297012904","pt":1632571398666,"mc":[{"id":"1.188134680","rc":[{"trd":[[1.28,187.55]],"batl":[[0,1.28,845.95]],"ltp":1.28,"tv":14033.49,"id":8681938}],"tv":17082.37}]}
{"op":"mcm","clk":"4297013320","pt":1632571400674,"mc":[{"id":"1.188134680","rc":[{"trd":[[1.28,205.13]],"batl":[[0,1.28,837.16]],"ltp":1.28,"tv":14051.07,"id":8681938}],"tv":17099.94}]}
{"op":"mcm","clk":"4297013508","pt":1632571401487,"mc":[{"id":"1.188134680","rc":[{"batb":[[0,1.27,44.98]],"ltp":1.28,"tv":14051.07,"id":8681938}]}]}
{"op":"mcm","clk":"4297013978","pt":1632571403765,"mc":[{"id":"1.188134680","rc":[{"trd":[[4.6,19.6]],"batb":[[0,4.6,92.79]],"batl":[[2,5,26.98]],"ltp":4.6,"tv":3067.65,"id":9631939}],"tv":17118.73}]}
{"op":"mcm","clk":"4297014170","pt":1632571404685,"mc":[{"id":"1.188134680","rc":[{"batl":[[0,1.28,1053.16]],"ltp":1.28,"tv":14051.07,"id":8681938}]}]}
{"op":"mcm","clk":"4297014518","pt":1632571406076,"mc":[{"id":"1.188134680","rc":[{"trd":[[1.28,212.65]],"batl":[[0,1.28,1049.4]],"ltp":1.28,"tv":14058.59,"id":8681938}],"tv":17126.24}]}
{"op":"mcm","clk":"4297014693","pt":1632571406878,"mc":[{"id":"1.188134680","rc":[{"trd":[[1.28,221.1]],"batl":[[0,1.28,1045.17]],"ltp":1.28,"tv":14067.04,"id":8681938}],"tv":17134.7}]}
{"op":"mcm","clk":"4297015225","pt":1632571409372,"mc":[{"id":"1.188134680","rc":[{"batb":[[0,4.5,17.14],[1,4.3,2],[2,4.2,142.49]],"batl":[[0,5.5,75.34],[1,5.6,86.85],[2,5.8,2.54]],"ltp":4.6,"tv":3067.65,"id":9631939},{"trd":[[1.28,1122.36]],"batb":[[1,1.22,423.87],[2,1.21,532.91]],"batl":[[0,1.28,571.43],[1,1.29,60]],"ltp":1.28,"tv":14968.3,"id":8681938}],"tv":18035.96}]}
{"op":"mcm","clk":"4297015410","pt":1632571410281,"mc":[{"id":"1.188134680","rc":[{"batb":[[0,4.3,2],[1,4.2,142.49],[2,4,123.46]],"ltp":4.6,"tv":3067.65,"id":9631939},{"batb":[[1,1.26,41.34],[2,1.22,423.87]],"batl":[[1,1.3,46.55],[2,1.31,42.5]],"ltp":1.28,"tv":14968.3,"id":8681938}]}]}
{"op":"mcm","clk":"4297015573","pt":1632571411005,"mc":[{"id":"1.188134680","rc":[{"batb":[[0,4.2,142.49],[1,4,123.46],[2,3.95,124.23]],"ltp":4.6,"tv":3067.65,"id":9631939},{"batb":[[1,1.22,423.87],[2,1.21,532.91]],"batl":[[0,1.31,42.5],[1,1.33,339.19],[2,1.34,412.1]],"ltp":1.28,"tv":14968.3,"id":8681938}]}]}
{"op":"mcm","clk":"4297015843","pt":1632571412199,"mc":[{"id":"1.188134680","rc":[{"batb":[[2,1.21,1872.67]],"batl":[[0,1.31,976.15],[1,1.32,621.27],[2,1.33,339.19]],"ltp":1.28,"tv":14968.3,"id":8681938}]}]}
{"op":"mcm","clk":"4297016014","pt":1632571412888,"mc":[{"id":"1.188134680","rc":[{"batb":[[1,1.22,912.04],[2,1.21,1605.83]],"batl":[[0,1.31,768.71]],"ltp":1.28,"tv":14968.3,"id":8681938}]}]}
{"op":"mcm","clk":"4297016304","pt":1632571414178,"mc":[{"id":"1.188134680","rc":[{"batb":[[0,4.3,2],[1,4.2,142.49],[2,4.1,2]],"ltp":4.6,"tv":3067.65,"id":9631939},{"batl":[[0,1.3,42.95],[1,1.31,777.71],[2,1.32,621.27]],"ltp":1.28,"tv":14968.3,"id":8681938}]}]}
{"op":"mcm","clk":"4297016422","pt":1632571414772,"mc":[{"id":"1.188134680","rc":[{"batb":[[0,4.2,142.49],[1,4.1,2],[2,4,123.46]],"ltp":4.6,"tv":3067.65,"id":9631939},{"batl":[[0,1.31,777.71],[1,1.32,621.27],[2,1.33,339.19]],"ltp":1.28,"tv":14968.3,"id":8681938}]}]}
{"op":"mcm","clk":"4297016749","pt":1632571416382,"mc":[{"id":"1.188134680","rc":[{"batb":[[2,1.9,5.76]],"batl":[[0,5.6,86.85],[1,5.8,2.54],[2,6,115.31]],"ltp":4.6,"tv":3067.65,"id":9631939},{"trd":[[1.27,562.43]],"batb":[[0,1.22,912.04],[1,1.21,1605.83],[2,1.2,820.73]],"batl":[[0,1.23,955.02],[1,1.31,51.5],[2,1.33,8.25]],"ltp":1.27,"tv":15058.26,"id":8681938}],"tv":18125.92}]}
{"op":"mcm","clk":"4297016802","pt":1632571416695,"mc":[{"id":"1.188134680","rc":[{"batl":[[1,1.31,9]],"ltp":1.27,"tv":15058.26,"id":8681938}]}]}
{"op":"mcm","clk":"4297017133","pt":1632571418290,"mc":[{"id":"1.188134680","rc":[{"batb":[[0,4.3,2],[1,4.2,142.49],[2,4.1,2]],"batl":[[2,6,7]],"ltp":4.6,"tv":3067.65,"id":9631939},{"trd":[[1.23,563.6]],"batl":[[0,1.23,673.22],[1,1.3,40.75],[2,1.31,9]],"ltp":1.23,"tv":15621.87,"id":8681938}],"tv":18689.52}]}
{"op":"mcm","clk":"4297017364","pt":1632571419380,"mc":[{"id":"1.188134680","rc":[{"batb":[[0,5.2,459.74],[1,5.1,178.48],[2,5,448.21]],"batl":[[1,5.7,6.04],[2,5.8,2.54]],"ltp":4.6,"tv":3067.65,"id":9631939},{"batb":[[0,1.22,924.04],[1,1.21,1614.83],[2,1.2,951.58]],"batl":[[0,1.23,697.32],[1,1.24,10462.64],[2,1.25,847.86]],"ltp":1.23,"tv":15621.87,"id":8681938}]}]}
{"op":"mcm","clk":"4297017528","pt":1632571420229,"mc":[{"id":"1.188134680","rc":[{"batb":[[0,5.2,183.9],[1,5.1,264.47],[2,5,180.48]],"batl":[[0,5.6,89.85],[2,5.8,4.25]],"ltp":4.6,"tv":3067.65,"id":9631939},{"batl":[[1,1.24,1444.08]],"ltp":1.23,"tv":15621.87,"id":8681938}]}]}
{"op":"mcm","clk":"4297017739","pt":1632571421315,"mc":[{"id":"1.188134680","rc":[{"batb":[[1,5.1,279.1]],"batl":[[0,5.6,99.35]],"ltp":4.6,"tv":3067.65,"id":9631939},{"batl":[[2,1.25,907.86]],"ltp":1.23,"tv":15621.87,"id":8681938}]}]}
{"op":"mcm","clk":"4297017841","pt":1632571421816,"mc":[{"id":"1.188134680","rc":[{"batb":[[1,5.1,264.47]],"ltp":4.6,"tv":3067.65,"id":9631939},{"batl":[[2,1.25,847.86]],"ltp":1.23,"tv":15621.87,"id":8681938}]}]}
{"op":"mcm","clk":"4297018218","pt":1632571423306,"mc":[{"id":"1.188134680","rc":[{"trd":[[1.22,42.64]],"batb":[[0,1.22,902.72]],"ltp":1.22,"tv":15664.5,"id":8681938}],"tv":18732.16}]}
{"op":"mcm","clk":"4297018437","pt":1632571424284,"mc":[{"id":"1.188134680","rc":[{"trd":[[1.23,813.52]],"batl":[[0,1.23,572.36]],"ltp":1.23,"tv":15914.42,"id":8681938}],"tv":18982.08}]}
{"op":"mcm","clk":"4297018575","pt":1632571424837,"mc":[{"id":"1.188134680","rc":[{"batb":[[0,5.3,13.95],[1,5.2,183.9],[2,5.1,264.47]],"ltp":4.6,"tv":3067.65,"id":9631939}]}]}
{"op":"mcm","clk":"4297018796","pt":1632571425648,"mc":[{"id":"1.188134680","rc":[{"batl":[[0,1.23,841.36]],"ltp":1.23,"tv":15914.42,"id":8681938}]}]}
{"op":"mcm","clk":"4297019151","pt":1632571426918,"mc":[{"id":"1.188134680","rc":[{"batl":[[0,5.6,99.77]],"ltp":4.6,"tv":3067.65,"id":9631939}]}]}
{"op":"mcm","clk":"4297019459","pt":1632571428318,"mc":[{"id":"1.188134680","rc":[{"trd":[[1.22,161.98]],"batb":[[0,1.22,843.05]],"batl":[[0,1.23,901.36]],"ltp":1.22,"tv":16033.76,"id":8681938}],"tv":19101.42}]}
{"op":"mcm","clk":"4297019534","pt":1632571428631,"mc":[{"id":"1.188134680","rc":[{"batl":[[0,1.23,1173.36]],"ltp":1.22,"tv":16033.76,"id":8681938}]}]}
{"op":"mcm","clk":"4297019831","pt":1632571430103,"mc":[{"id":"1.188134680","rc":[{"batl":[[2,5.8,2.54]],"ltp":4.6,"tv":3067.65,"id":9631939}]}]}
{"op":"mcm","clk":"4297020035","pt":1632571431233,"mc":[{"id":"1.188134680","rc":[{"trd":[[1.22,262.98],[1.23,814.09]],"batb":[[0,1.22,792.55],[1,1.21,1605.83]],"batl":[[0,1.23,1173.08],[1,1.24,666.62]],"ltp":1.23,"tv":16135.33,"id":8681938}],"tv":19202.99}]}
{"op":"mcm","clk":"4297020314","pt":1632571432525,"mc":[{"id":"1.188134680","rc":[{"batl":[[0,1.23,625.1]],"ltp":1.23,"tv":16135.33,"id":8681938}]}]}
{"op":"mcm","clk":"4297020661","pt":1632571434126,"mc":[{"id":"1.188134680","rc":[{"batl":[[0,5.6,99.35]],"ltp":4.6,"tv":3067.65,"id":9631939},{"batb":[[1,1.21,1615.83]],"ltp":1.23,"tv":16135.33,"id":8681938}]}]}
{"op":"mcm","clk":"4297020941","pt":1632571435227,"mc":[{"id":"1.188134680","rc":[{"batb":[[1,4.8,2],[2,4.6,108.82]],"batl":[[0,5.8,2.54],[1,6,5],[2,7,74.56]],"ltp":4.6,"tv":3067.65,"id":9631939},{"trd":[[1.22,1848.47]],"batb":[[0,1.18,55.35],[1,1.17,411.67],[2,1.16,504.33]],"batl":[[0,1.22,207.25],[1,1.23,601],[2,1.26,47.25]],"ltp":1.22,"tv":17720.82,"id":8681938}],"tv":20788.48}]}
{"op":"mcm","clk":"4297021194","pt":1632571436325,"mc":[{"id":"1.188134680","rc":[{"batb":[[0,4.8,2],[1,4.6,108.82],[2,4.5,2]],"ltp":4.6,"tv":3067.65,"id":9631939},{"batb":[[0,1.17,411.67],[1,1.16,504.33],[2,1.15,81.23]],"batl":[[1,1.26,47.25],[2,1.28,38.59]],"ltp":1.22,"tv":17720.82,"id":8681938}]}]}
{"op":"mcm","clk":"4297021642","pt":1632571438327,"mc":[{"id":"1.188134680","rc":[{"batb":[[1,1.16,914.38],[2,1.15,1677.25]],"batl":[[2,1.27,535.79]],"ltp":1.22,"tv":17720.82,"id":8681938}]}]}
{"op":"mcm","clk":"4297021709","pt":1632571438639,"mc":[{"id":"1.188134680","rc":[{"batl":[[2,1.27,794.99]],"ltp":1.22,"tv":17720.82,"id":8681938}]}]}
{"op":"mcm","clk":"4297022237","pt":1632571441350,"mc":[{"id":"1.188134680","rc":[{"trd":[[5.5,0.41]],"batl":[[2,7.8,91.68]],"ltp":5.5,"tv":3068.06,"id":9631939},{"trd":[[1.22,1850.32]],"batb":[[0,1.15,81.23],[1,1.14,1106.09],[2,1.12,98.54]],"batl":[[0,1.22,205.4]],"ltp":1.22,"tv":17722.67,"id":8681938}],"tv":20790.74}]}
{"op":"mcm","clk":"4297022602","pt":1632571442746,"mc":[{"id":"1.188134680","rc":[{"batl":[[2,7.8,2]],"ltp":5.5,"tv":3068.06,"id":9631939},{"trd":[[1.22,1853.46]],"batl":[[0,1.22,203.83]],"ltp":1.22,"tv":17725.81,"id":8681938}],"tv":20793.88}]}
{"op":"mcm","clk":"4297023022","pt":1632571444345,"mc":[{"id":"1.188134680","rc":[{"batb":[[0,4.8,5.9],[2,4.5,214.5]],"batl":[[0,5,4.7],[1,5.3,67.91],[2,5.8,2.54]],"ltp":5.5,"tv":3068.06,"id":9631939},{"trd":[[1.22,2261.12]],"batb":[[0,1.24,2173.17],[1,1.23,1760.54],[2,1.22,754.58]],"batl":[[0,1.26,47.25],[1,1.27,794.99],[2,1.28,995.83]],"ltp":1.22,"tv":18133.47,"id":8681938}],"tv":21201.54}]}
{"op":"mcm","clk":"4297023252","pt":1632571445246,"mc":[{"id":"1.188134680","rc":[{"batb":[[0,4.8,3.9],[1,4.7,16.21],[2,4.6,108.82]],"batl":[[2,5.7,8.62]],"ltp":5.5,"tv":3068.06,"id":9631939},{"batb":[[1,1.23,2409.3]],"batl":[[0,1.27,794.99],[1,1.28,995.83],[2,1.29,344.14]],"ltp":1.22,"tv":18133.47,"id":8681938}]}]}
{"op":"mcm","clk":"4297023477","pt":1632571446155,"mc":[{"id":"1.188134680","rc":[{"batl":[[2,5.5,2]],"ltp":5.5,"tv":3068.06,"id":9631939},{"batb":[[0,1.24,2190.3],[2,1.22,767.58]],"ltp":1.22,"tv":18133.47,"id":8681938}]}]}
{"op":"mcm","clk":"4297023730","pt":1632571447263,"mc":[{"id":"1.188134680","rc":[{"batb":[[1,4.6,108.82],[2,4.5,214.5]],"ltp":5.5,"tv":3068.06,"id":9631939}]}]}
{"op":"mcm","clk":"4297024190","pt":1632571449286,"mc":[{"id":"1.188134680","rc":[{"batl":[[2,5.5,3.8]],"ltp":5.5,"tv":3068.06,"id":9631939},{"batb":[[0,1.24,2173.17]],"ltp":1.22,"tv":18133.47,"id":8681938}]}]}
{"op":"mcm","clk":"4297024429","pt":1632571450262,"mc":[{"id":"1.188134680","rc":[{"batb":[[1,4.7,16.21],[2,4.6,108.82]],"ltp":5.5,"tv":3068.06,"id":9631939},{"batb":[[0,1.24,2233.55]],"batl":[[0,1.27,911.99]],"ltp":1.22,"tv":18133.47,"id":8681938}]}]}
{"op":"mcm","clk":"4297024599","pt":1632571451070,"mc":[{"id":"1.188134680","rc":[{"batb":[[0,1.25,16.45],[1,1.24,2233.55],[2,1.23,2409.3]],"batl":[[0,1.27,971.99],[2,1.29,382.64]],"ltp":1.22,"tv":18133.47,"id":8681938}]}]}
{"op":"mcm","clk":"4297025188","pt":1632571453561,"mc":[{"id":"1.188134680","rc":[{"batl":[[0,1.27,1082.99]],"ltp":1.22,"tv":18133.47,"id":8681938}]}]}
{"op":"mcm","clk":"4297025611","pt":1632571455263,"mc":[{"id":"1.188134680","rc":[{"batb":[[2,1.23,2415.25]],"ltp":1.22,"tv":18133.47,"id":8681938}]}]}
{"op":"mcm","clk":"4297025755","pt":1632571455858,"mc":[{"id":"1.188134680","rc":[{"batb":[[1,1.24,1088.15]],"batl":[[0,1.27,1083.62]],"ltp":1.22,"tv":18133.47,"id":8681938}]}]}
{"op":"mcm","clk":"4297026109","pt":1632571457374,"mc":[{"id":"1.188134680","rc":[{"batb":[[0,4.7,16.21],[1,4.5,2],[2,4.4,2]],"batl":[[0,5.5,1.8],[1,5.7,6.91],[2,5.8,2.54]],"ltp":5.5,"tv":3068.06,"id":9631939},{"batb":[[1,1.24,1027.77],[2,1.23,989.05]],"batl":[[1,1.28,773.97],[2,1.29,38.5]],"ltp":1.22,"tv":18133.47,"id":8681938}]}]}
{"op":"mcm","clk":"4297026320","pt":1632571458256,"mc":[{"id":"1.188134680","rc":[{"batb":[[0,4.5,2],[1,4.4,2],[2,4.3,130.46]],"batl":[[1,5.8,2.54],[2,6,100.45]],"ltp":5.5,"tv":3068.06,"id":9631939},{"batb":[[1,1.23,5.95],[2,1.2,487.63]],"batl":[[0,1.28,39.22],[1,1.29,38.5],[2,1.31,9]],"ltp":1.22,"tv":18133.47,"id":8681938}]}]}
{"op":"mcm","clk":"4297026397","pt":1632571458578,"mc":[{"id":"1.188134680","rc":[{"batb":[[0,4.4,2],[1,4.3,130.46],[2,4.2,2]],"ltp":5.5,"tv":3068.06,"id":9631939},{"batl":[[0,1.29,39.13],[1,1.31,9],[2,1.32,380.78]],"ltp":1.22,"tv":18133.47,"id":8681938}]}]}
{"op":"mcm","clk":"4297026703","pt":1632571459966,"mc":[{"id":"1.188134680","rc":[{"batb":[[0,1.23,5.95],[1,1.2,487.63],[2,1.19,499.25]],"ltp":1.22,"tv":18133.47,"id":8681938}]}]}
{"op":"mcm","clk":"4297027257","pt":1632571462344,"mc":[{"id":"1.188134680","rc":[{"batb":[[0,4.4,4],[1,4.3,133.46]],"ltp":5.5,"tv":3068.06,"id":9631939},{"batb":[[0,1.23,981.14],[1,1.22,1035.72],[2,1.2,487.63]],"batl":[[0,1.26,958.03],[1,1.27,765.29],[2,1.29,46.5]],"ltp":1.22,"tv":18133.47,"id":8681938}]}]}
{"op":"mcm","clk":"4297027435","pt":1632571463254,"mc":[{"id":"1.188134680","rc":[{"batb":[[0,4.5,2],[1,4.4,4],[2,4.3,133.46]],"batl":[[0,5.2,17.98],[1,5.5,1.8],[2,5.8,2.54]],"ltp":5.5,"tv":3068.06,"id":9631939},{"batb":[[0,1.23,1000.9],[2,1.21,19.58]],"batl":[[0,1.25,20.06],[1,1.26,958.03],[2,1.27,765.29]],"ltp":1.22,"tv":18133.47,"id":8681938}]}]}
{"op":"mcm","clk":"4297027657","pt":1632571464277,"mc":[{"id":"1.188134680","rc":[{"batb":[[0,4.5,12]],"batl":[[0,5.4,9]],"ltp":5.5,"tv":3068.06,"id":9631939},{"batb":[[0,1.23,1010.89]],"batl":[[0,1.26,958.03],[1,1.27,765.29],[2,1.28,141.5]],"ltp":1.22,"tv":18133.47,"id":8681938}]}]}
{"op":"mcm","clk":"4297027726","pt":1632571464582,"mc":[{"id":"1.188134680","rc":[{"batb":[[0,4.5,2]],"ltp":5.5,"tv":3068.06,"id":9631939},{"batl":[[2,1.28,42.59]],"ltp":1.22,"tv":18133.47,"id":8681938}]}]}
{"op":"mcm","clk":"4297028485","pt":1632571468274,"mc":[{"id":"1.188134680","rc":[{"batb":[[0,4.4,4],[1,4.3,133.46],[2,4.2,2]],"batl":[[0,5.5,1.8],[1,5.8,2.54],[2,6,100.45]],"ltp":5.5,"tv":3068.06,"id":9631939},{"batb":[[0,1.24,17.13],[1,1.21,19.58],[2,1.2,487.63]],"batl":[[0,1.29,47.13],[1,1.31,9],[2,1.32,380.78]],"ltp":1.22,"tv":18133.47,"id":8681938}]}]}
{"op":"mcm","clk":"4297028610","pt":1632571468955,"mc":[{"id":"1.188134680","rc":[{"batb":[[0,1.2,487.63],[1,1.19,499.25],[2,1.18,878.15]],"ltp":1.22,"tv":18133.47,"id":8681938}]}]}
{"op":"mcm","clk":"4297029079","pt":1632571471189,"mc":[{"id":"1.188134680","rc":[{"batb":[[0,4.5,2],[1,4.4,4],[2,4.3,133.46]],"ltp":5.5,"tv":3068.06,"id":9631939},{"batb":[[1,1.19,1425.2],[2,1.18,2189.77]],"batl":[[0,1.28,49.47],[1,1.29,46.5],[2,1.3,937.65]],"ltp":1.22,"tv":18133.47,"id":8681938}]}]}
{"op":"mcm","clk":"4297029152","pt":1632571471481,"mc":[{"id":"1.188134680","rc":[{"batb":[[0,4.4,4],[1,4.3,133.46],[2,4.2,2]],"ltp":5.5,"tv":3068.06,"id":9631939},{"batl":[[0,1.29,47.13],[1,1.3,937.65],[2,1.31,656.05]],"ltp":1.22,"tv":18133.47,"id":8681938}]}]}
{"op":"mcm","clk":"4297029522","pt":1632571473275,"mc":[{"id":"1.188134680","rc":[{"batb":[[1,4.3,130.46],[2,4.1,95.4]],"ltp":5.5,"tv":3068.06,"id":9631939},{"batb":[[0,1.21,19.58],[1,1.2,487.63],[2,1.19,1425.2]],"batl":[[2,1.31,647.05]],"ltp":1.22,"tv":18133.47,"id":8681938}]}]}
{"op":"mcm","clk":"4297029916","pt":1632571475085,"mc":[{"id":"1.188134680","rc":[{"batl":[[1,1.3,937.97]],"ltp":1.22,"tv":18133.47,"id":8681938}]}]}
{"op":"mcm","clk":"4297030078","pt":1632571475889,"mc":[{"id":"1.188134680","rc":[{"batl":[[2,6.4,2]],"ltp":5.5,"tv":3068.06,"id":9631939},{"batb":[[1,1.19,69.71],[2,1.18,878.15]],"ltp":1.22,"tv":18133.47,"id":8681938}]}]}
{"op":"mcm","clk":"4297030384","pt":1632571477292,"mc":[{"id":"1.188134680","rc":[{"batb":[[0,4.4,2]],"batl":[[2,7,2]],"ltp":5.5,"tv":3068.06,"id":9631939},{"batb":[[1,1.18,878.15],[2,1.17,77.97]],"batl":[[0,1.29,39.13]],"ltp":1.22,"tv":18133.47,"id":8681938}]}]}
{"op":"mcm","clk":"4297030619","pt":1632571478366,"mc":[{"id":"1.188134680","rc":[{"batb":[[0,4.5,2],[1,4.4,2],[2,4.3,130.46]],"ltp":5.5,"tv":3068.06,"id":9631939},{"batl":[[0,1.28,45.97],[1,1.29,38.5],[2,1.3,937.97]],"ltp":1.22,"tv":18133.47,"id":8681938}]}]}
{"op":"mcm","clk":"4297030813","pt":1632571479292,"mc":[{"id":"1.188134680","rc":[{"trd":[[4.5,8.76]],"batb":[[0,4.4,2],[1,4.3,130.46],[2,4.2,52.76]],"batl":[[0,4.7,45.32],[1,4.8,6.25],[2,5.5,1.8]],"ltp":4.5,"tv":3073.73,"id":9631939},{"trd":[[1.26,2337.8],[1.28,1128.23]],"batb":[[0,1.27,1672.45],[1,1.26,1595.8],[2,1.25,736.62]],"batl":[[0,1.29,38.5],[1,1.3,956.04],[2,1.31,647.05]],"ltp":1.28,"tv":18140.6,"id":8681938}],"tv":21214.34}]}
{"op":"mcm","clk":"4297031030","pt":1632571480302,"mc":[{"id":"1.188134680","rc":[{"batb":[[0,4.4,19.64]],"batl":[[2,5.1,1.71]],"ltp":4.5,"tv":3073.73,"id":9631939},{"batb":[[1,1.26,2168.63]],"batl":[[1,1.3,1016.04]],"ltp":1.28,"tv":18140.6,"id":8681938}]}]}
{"op":"mcm","clk":"4297031201","pt":1632571481066,"mc":[{"id":"1.188134680","rc":[{"batb":[[0,1.28,14.68],[1,1.27,1672.45],[2,1.26,2184.45]],"ltp":1.28,"tv":18140.6,"id":8681938}]}]}
{"op":"mcm","clk":"4297031373","pt":1632571481776,"mc":[{"id":"1.188134680","rc":[{"batb":[[1,1.27,1687.68]],"ltp":1.28,"tv":18140.6,"id":8681938}]}]}
{"op":"mcm","clk":"4297031716","pt":1632571483377,"mc":[{"id":"1.188134680","rc":[{"batb":[[1,1.27,1785.58]],"ltp":1.28,"tv":18140.6,"id":8681938}]}]}
{"op":"mcm","clk":"4297031795","pt":1632571483868,"mc":[{"id":"1.188134680","rc":[{"batl":[[0,4.7,57.04]],"ltp":4.5,"tv":3073.73,"id":9631939}]}]}
{"op":"mcm","clk":"4297031994","pt":1632571484771,"mc":[{"id":"1.188134680","rc":[{"batl":[[0,1.29,363.5]],"ltp":1.28,"tv":18140.6,"id":8681938}]}]}
{"op":"mcm","clk":"4297032246","pt":1632571485910,"mc":[{"id":"1.188134680","rc":[{"batb":[[1,4.3,132.46],[2,4.2,54.76]],"batl":[[2,5,2]],"ltp":4.5,"tv":3073.73,"id":9631939},{"batl":[[1,1.3,1055.59],[2,1.31,687.55]],"ltp":1.28,"tv":18140.6,"id":8681938}]}]}
{"op":"mcm","clk":"4297032707","pt":1632571488195,"mc":[{"id":"1.188134680","rc":[{"trd":[[1.29,451.72]],"batl":[[0,1.29,360.98]],"ltp":1.29,"tv":18145.64,"id":8681938}],"tv":21219.38}]}
{"op":"mcm","clk":"4297032855","pt":1632571488907,"mc":[{"id":"1.188134680","rc":[{"trd":[[1.28,1129.49]],"batb":[[0,1.28,14.05]],"batl":[[0,1.29,630.98],[1,1.3,1037.52]],"ltp":1.28,"tv":18146.9,"id":8681938}],"tv":21220.64}]}
{"op":"mcm","clk":"4297033291","pt":1632571491030,"mc":[{"id":"1.188134680","rc":[{"trd":[[4.4,120.5]],"batb":[[0,4.4,19.23]],"ltp":4.4,"tv":3074.55,"id":9631939},{"batb":[[1,1.27,666.79]],"ltp":1.28,"tv":18146.9,"id":8681938}],"tv":21221.45}]}
{"op":"mcm","clk":"4297033439","pt":1632571491713,"mc":[{"id":"1.188134680","rc":[{"batb":[[0,4.4,24.66]],"ltp":4.4,"tv":3074.55,"id":9631939},{"batb":[[0,1.28,27.25]],"ltp":1.28,"tv":18146.9,"id":8681938}]}]}
{"op":"mcm","clk":"4297033752","pt":1632571493213,"mc":[{"id":"1.188134680","rc":[{"batb":[[0,4.4,17.64],[1,4.3,2],[2,4.2,2]],"batl":[[0,5.2,77.96],[1,5.3,104.92],[2,5.4,2]],"ltp":4.4,"tv":3074.55,"id":9631939},{"batb":[[0,1.28,14.05],[1,1.27,15.23],[2,1.26,15.81]],"batl":[[0,1.29,595],[1,1.3,99.87],[2,1.31,40.5]],"ltp":1.28,"tv":18146.9,"id":8681938}]}]}
{"op":"mcm","clk":"4297033976","pt":1632571494318,"mc":[{"id":"1.188134680","rc":[{"batb":[[0,4.3,2],[1,4.2,2],[2,4,148.3]],"ltp":4.4,"tv":3074.55,"id":9631939},{"batl":[[0,1.3,39.87],[1,1.31,40.5],[2,1.33,1.25]],"ltp":1.28,"tv":18146.9,"id":8681938}]}]}
{"op":"mcm","clk":"4297034185","pt":1632571495333,"mc":[{"id":"1.188134680","rc":[{"batb":[[0,4.2,2],[1,4,148.3],[2,3.9,132.84]],"batl":[[0,5.4,2],[1,5.5,1.8],[2,5.7,2]],"ltp":4.4,"tv":3074.55,"id":9631939},{"batl":[[0,1.31,40.82],[1,1.33,1.25],[2,1.35,366.2]],"ltp":1.28,"tv":18146.9,"id":8681938}]}]}
{"op":"mcm","clk":"4297034403","pt":1632571496315,"mc":[{"id":"1.188134680","rc":[{"batb":[[0,1.23,58.63],[1,1.22,711.5],[2,1.17,77.97]],"batl":[[0,1.31,41.01],[1,1.32,899.86],[2,1.33,600.78]],"ltp":1.28,"tv":18146.9,"id":8681938}]}]}
{"op":"mcm","clk":"4297034630","pt":1632571497216,"mc":[{"id":"1.188134680","rc":[{"batl":[[0,1.31,41.05]],"ltp":1.28,"tv":18146.9,"id":8681938}]}]}
{"op":"mcm","clk":"4297034865","pt":1632571498302,"mc":[{"id":"1.188134680","rc":[{"trd":[[4.3,38.82],[4.5,8.83]],"batl":[[0,4.5,556.31],[1,4.7,149.85],[2,5.4,2]],"ltp":4.3,"tv":3082.73,"id":9631939},{"trd":[[1.28,1129.73],[1.3,149.07]],"batb":[[0,1.29,786.29],[1,1.28,943.65],[2,1.27,546.52]],"batl":[[0,1.31,40.5],[1,1.32,914.34]],"ltp":1.3,"tv":18160.73,"id":8681938}],"tv":21243.47}]}
{"op":"mcm","clk":"4297035068","pt":1632571499320,"mc":[{"id":"1.188134680","rc":[{"batb":[[0,4.2,20.75],[1,4,265.8],[2,3.95,218.05]],"batl":[[0,4.5,187.32],[2,4.9,7.59]],"ltp":4.3,"tv":3082.73,"id":9631939},{"batb":[[1,1.28,1467.87],[2,1.27,182.18]],"batl":[[1,1.32,974.34]],"ltp":1.3,"tv":18160.73,"id":8681938}]}]}
{"op":"mcm","clk":"4297035197","pt":1632571499901,"mc":[{"id":"1.188134680","rc":[{"batl":[[0,4.5,189.03]],"ltp":4.3,"tv":3082.73,"id":9631939}]}]}
{"op":"mcm","clk":"4297035465","pt":1632571501104,"mc":[{"id":"1.188134680","rc":[{"batl":[[2,4.9,10.59]],"ltp":4.3,"tv":3082.73,"id":9631939},{"batb":[[1,1.28,1482.55]],"ltp":1.3,"tv":18160.73,"id":8681938}]}]}
{"op":"mcm","clk":"4297035677","pt":1632571502140,"mc":[{"id":"1.188134680","rc":[{"batb":[[1,1.28,1467.87]],"ltp":1.3,"tv":18160.73,"id":8681938}]}]}
{"op":"mcm","clk":"4297035914","pt":1632571503227,"mc":[{"id":"1.188134680","rc":[{"batl":[[0,4.5,203.89]],"ltp":4.3,"tv":3082.73,"id":9631939},{"batb":[[0,1.29,827.02]],"batl":[[0,1.31,239.5]],"ltp":1.3,"tv":18160.73,"id":8681938}]}]}
{"op":"mcm","clk":"4297036370","pt":1632571505294,"mc":[{"id":"1.188134680","rc":[{"batl":[[1,4.6,107.32],[2,4.7,264.11]],"ltp":4.3,"tv":3082.73,"id":9631939},{"trd":[[1.3,149.69]],"batb":[[0,1.3,13.4],[1,1.29,827.02],[2,1.28,1815.32]],"ltp":1.3,"tv":18161.35,"id":8681938}],"tv":21244.09}]}
{"op":"mcm","clk":"4297036440","pt":1632571505623,"mc":[{"id":"1.188134680","rc":[{"batb":[[1,4.1,2],[2,4,265.8]],"batl":[[1,4.6,109.32]],"ltp":4.3,"tv":3082.73,"id":9631939},{"batb":[[2,1.28,1860.73]],"batl":[[0,1.31,421.5],[1,1.32,1013.7]],"ltp":1.3,"tv":18161.35,"id":8681938}]}]}
{"op":"mcm","clk":"4297036990","pt":1632571508220,"mc":[{"id":"1.188134680","rc":[{"trd":[[1.3,159.04]],"batb":[[0,1.3,8.72]],"batl":[[1,1.32,999.22]],"ltp":1.3,"tv":18170.71,"id":8681938}],"tv":21253.45}]}
{"op":"mcm","clk":"4297037237","pt":1632571509318,"mc":[{"id":"1.188134680","rc":[{"batb":[[2,4,148.3]],"batl":[[0,4.5,16.57],[2,4.7,114.26]],"ltp":4.3,"tv":3082.73,"id":9631939},{"batb":[[1,1.29,462.68],[2,1.28,1678.55]],"ltp":1.3,"tv":18170.71,"id":8681938}]}]}
{"op":"mcm","clk":"4297037352","pt":1632571509842,"mc":[{"id":"1.188134680","rc":[{"batb":[[2,3.95,159.29]],"batl":[[0,4.6,109.32],[1,4.7,114.26],[2,4.8,2]],"ltp":4.3,"tv":3082.73,"id":9631939},{"batb":[[1,1.29,4.69],[2,1.28,392.86]],"batl":[[0,1.31,619.5],[1,1.32,99.36]],"ltp":1.3,"tv":18170.71,"id":8681938}]}]}
{"op":"mcm","clk":"4297037673","pt":1632571511331,"mc":[{"id":"1.188134680","rc":[{"batb":[[0,4.1,2],[1,3.95,159.29],[2,3.8,124.73]],"ltp":4.3,"tv":3082.73,"id":9631939},{"batl":[[0,1.32,39.36],[1,1.33,600.78],[2,1.36,306.2]],"ltp":1.3,"tv":18170.71,"id":8681938}]}]}
{"op":"mcm","clk":"4297037739","pt":1632571511653,"mc":[{"id":"1.188134680","rc":[{"batb":[[0,1.29,4.69],[1,1.28,392.86],[2,1.27,459.35]],"ltp":1.3,"tv":18170.71,"id":8681938}]}]}
{"op":"mcm","clk":"4297038071","pt":1632571513237,"mc":[{"id":"1.188134680","rc":[{"batl":[[1,1.33,825.6],[2,1.34,578.8]],"ltp":1.3,"tv":18170.71,"id":8681938}]}]}
{"op":"mcm","clk":"4297038249","pt":1632571514112,"mc":[{"id":"1.188134680","rc":[{"batb":[[0,4.2,2],[1,4.1,2],[2,3.95,159.29]],"ltp":4.3,"tv":3082.73,"id":9631939},{"batl":[[0,1.31,33.5],[1,1.32,46.36],[2,1.33,825.6]],"ltp":1.3,"tv":18170.71,"id":8681938}]}]}
{"op":"mcm","clk":"4297038376","pt":1632571514641,"mc":[{"id":"1.188134680","rc":[{"batb":[[0,4.1,4],[1,4,3]],"ltp":4.3,"tv":3082.73,"id":9631939},{"batl":[[0,1.31,5.57]],"ltp":1.3,"tv":18170.71,"id":8681938}]}]}
{"op":"mcm","clk":"4297038881","pt":1632571516944,"mc":[{"id":"1.188134680","rc":[{"trd":[[1.31,457.45]],"batl":[[0,1.31,3.22]],"ltp":1.31,"tv":18175.41,"id":8681938}],"tv":21258.14}]}
{"op":"mcm","clk":"4297039505","pt":1632571519992,"mc":[{"id":"1.188134680","rc":[{"batl":[[0,1.31,5.69]],"ltp":1.31,"tv":18175.41,"id":8681938}]}]}
{"op":"mcm","clk":"4297040109","pt":1632571522958,"mc":[{"id":"1.188134680","rc":[{"batl":[[2,1.33,1.25]],"ltp":1.31,"tv":18175.41,"id":8681938}]}]}
{"op":"mcm","clk":"4297040812","pt":1632571526354,"mc":[{"id":"1.188134680","rc":[{"batb":[[0,4.5,6.76],[1,4.3,2.01],[2,4.2,60.99]],"batl":[[0,4.7,156.42],[1,4.8,2],[2,4.9,4.71]],"ltp":4.3,"tv":3082.73,"id":9631939},{"trd":[[1.29,461.1]],"batb":[[0,1.27,472.89],[1,1.26,1039.46],[2,1.25,1489.52]],"batl":[[0,1.29,989.5],[1,1.3,1432.32],[2,1.31,719.63]],"ltp":1.29,"tv":18184.79,"id":8681938}],"tv":21267.52}]}
{"op":"mcm","clk":"4297040999","pt":1632571527272,"mc":[{"id":"1.188134680","rc":[{"batb":[[1,4.4,139.48],[2,4.3,2.01]],"batl":[[1,4.8,8.25]],"ltp":4.3,"tv":3082.73,"id":9631939},{"batl":[[1,1.3,1460.77]],"ltp":1.29,"tv":18184.79,"id":8681938}]}]}
{"op":"mcm","clk":"4297041644","pt":1632571530273,"mc":[{"id":"1.188134680","rc":[{"batb":[[1,4.4,121.84]],"ltp":4.3,"tv":3082.73,"id":9631939}]}]}
{"op":"mcm","clk":"4297042258","pt":1632571533065,"mc":[{"id":"1.188134680","rc":[{"batl":[[0,1.29,1172.5]],"ltp":1.29,"tv":18184.79,"id":8681938}]}]}
{"op":"mcm","clk":"4297042507","pt":1632571534290,"mc":[{"id":"1.188134680","rc":[{"batb":[[0,4.5,23.9]],"ltp":4.3,"tv":3082.73,"id":9631939},{"trd":[[1.29,465.79]],"batl":[[0,1.29,1230.15],[2,1.31,759.13]],"ltp":1.29,"tv":18189.49,"id":8681938}],"tv":21272.22}]}
{"op":"mcm","clk":"4297042654","pt":1632571534961,"mc":[{"id":"1.188134680","rc":[{"trd":[[1.27,612.43]],"batb":[[0,1.27,447.89]],"ltp":1.27,"tv":18239.49,"id":8681938}],"tv":21322.22}]}
{"op":"mcm","clk":"4297042893","pt":1632571536092,"mc":[{"id":"1.188134680","rc":[{"batl":[[0,1.29,1402.15]],"ltp":1.27,"tv":18239.49,"id":8681938}]}]}
{"op":"mcm","clk":"4297043014","pt":1632571536694,"mc":[{"id":"1.188134680","rc":[{"batl":[[2,4.9,3]],"ltp":4.3,"tv":3082.73,"id":9631939}]}]}
{"op":"mcm","clk":"4297043231","pt":1632571537755,"mc":[{"id":"1.188134680","rc":[{"batl":[[0,1.29,1002.69]],"ltp":1.27,"tv":18239.49,"id":8681938}]}]}
{"op":"mcm","clk":"4297045701","pt":1632571549267,"mc":[{"id":"1.188134680","rc":[{"batb":[[0,4.5,17.14],[1,4.2,2],[2,4.1,143.85]],"batl":[[0,5.4,89.89],[1,5.5,114.07],[2,5.6,2]],"ltp":4.3,"tv":3082.73,"id":9631939},{"batb":[[0,1.22,481.47],[1,1.21,1179.75],[2,1.17,77.97]],"batl":[[0,1.29,415],[1,1.31,45.19],[2,1.32,46.36]],"ltp":1.27,"tv":18239.49,"id":8681938}]}]}
{"op":"mcm","clk":"4297045922","pt":1632571550266,"mc":[{"id":"1.188134680","rc":[{"batb":[[0,4.2,2],[1,4.1,143.85],[2,3.95,89.93]],"ltp":4.3,"tv":3082.73,"id":9631939},{"batl":[[0,1.31,45.19],[1,1.32,46.36],[2,1.33,1.25]],"ltp":1.27,"tv":18239.49,"id":8681938}]}]}
{"op":"mcm","clk":"4297046066","pt":1632571550883,"mc":[{"id":"1.188134680","rc":[{"batb":[[1,4.1,141.85]],"ltp":4.3,"tv":3082.73,"id":9631939},{"batl":[[1,1.32,7]],"ltp":1.27,"tv":18239.49,"id":8681938}]}]}
{"op":"mcm","clk":"4297046438","pt":1632571552360,"mc":[{"id":"1.188134680","rc":[{"batb":[[0,1.22,1454.69],[1,1.21,2274.57]],"batl":[[0,1.31,528.68],[1,1.32,636.67]],"ltp":1.27,"tv":18239.49,"id":8681938}]}]}
{"op":"mcm","clk":"4297046545","pt":1632571552875,"mc":[{"id":"1.188134680","rc":[{"batl":[[0,5.4,2],[1,5.5,1.8]],"ltp":4.3,"tv":3082.73,"id":9631939},{"batb":[[0,1.22,64.84],[1,1.21,752],[2,1.01,140]],"ltp":1.27,"tv":18239.49,"id":8681938}]}]}
{"op":"mcm","clk":"4297046736","pt":1632571553656,"mc":[{"id":"1.188134680","rc":[{"batb":[[1,4.1,139.85]],"ltp":4.3,"tv":3082.73,"id":9631939},{"batl":[[1,1.32,629.67]],"ltp":1.27,"tv":18239.49,"id":8681938}]}]}
{"op":"mcm","clk":"4297047073","pt":1632571555257,"mc":[{"id":"1.188134680","rc":[{"batb":[[0,4.3,3],[1,4.2,2],[2,4.1,139.85]],"batl":[[0,5.3,2],[1,5.4,2],[2,5.5,1.8]],"ltp":4.3,"tv":3082.73,"id":9631939},{"batb":[[0,1.23,11],[1,1.22,64.84],[2,1.21,752]],"ltp":1.27,"tv":18239.49,"id":8681938}]}]}
{"op":"mcm","clk":"4297047303","pt":1632571556300,"mc":[{"id":"1.188134680","rc":[{"batb":[[0,4.2,2],[1,4.1,139.85],[2,3.95,89.93]],"batl":[[0,4.4,74.81],[1,4.6,1.71],[2,4.7,203.46]],"ltp":4.3,"tv":3082.73,"id":9631939},{"batb":[[0,1.28,1988.92],[1,1.27,806.8],[2,1.26,51.83]],"batl":[[0,1.31,541.28],[2,1.33,720.23]],"ltp":1.27,"tv":18239.49,"id":8681938}]}]}
{"op":"mcm","clk":"4297047545","pt":1632571557177,"mc":[{"id":"1.188134680","rc":[{"batb":[[1,1.27,1349.36],[2,1.26,637.68]],"ltp":1.27,"tv":18239.49,"id":8681938}]}]}
{"op":"mcm","clk":"4297047775","pt":1632571558353,"mc":[{"id":"1.188134680","rc":[{"batb":[[0,4.2,20.75]],"ltp":4.3,"tv":3082.73,"id":9631939},{"batl":[[0,1.31,601.28]],"ltp":1.27,"tv":18239.49,"id":8681938}]}]}
{"op":"mcm","clk":"4297047991","pt":1632571559267,"mc":[{"id":"1.188134680","rc":[{"batl":[[0,1.31,598.06]],"ltp":1.27,"tv":18239.49,"id":8681938}]}]}
{"op":"mcm","clk":"4297048193","pt":1632571560318,"mc":[{"id":"1.188134680","rc":[{"batb":[[0,1.29,14.18],[1,1.28,1988.92],[2,1.27,1349.36]],"ltp":1.27,"tv":18239.49,"id":8681938}]}]}
{"op":"mcm","clk":"4297048382","pt":1632571561076,"mc":[{"id":"1.188134680","rc":[{"batb":[[1,1.28,2162.6]],"ltp":1.27,"tv":18239.49,"id":8681938}]}]}
{"op":"mcm","clk":"4297048660","pt":1632571562309,"mc":[{"id":"1.188134680","rc":[{"trd":[[1.29,472.32]],"batb":[[0,1.29,10.92],[2,1.27,1348.6]],"batl":[[0,1.3,341.24],[1,1.31,598.06],[2,1.32,629.67]],"ltp":1.29,"tv":18246.02,"id":8681938}],"tv":21328.75}]}
{"op":"mcm","clk":"4297048916","pt":1632571563275,"mc":[{"id":"1.188134680","rc":[{"trd":[[1.3,259.04]],"batl":[[0,1.3,291.24]],"ltp":1.3,"tv":18346.02,"id":8681938}],"tv":21428.75}]}
{"op":"mcm","clk":"4297049154","pt":1632571564350,"mc":[{"id":"1.188134680","rc":[{"trd":[[1.3,399.04]],"batl":[[0,1.3,221.24]],"ltp":1.3,"tv":18486.02,"id":8681938}],"tv":21568.75}]}
{"op":"mcm","clk":"4297049291","pt":1632571564967,"mc":[{"id":"1.188134680","rc":[{"trd":[[1.3,459.04]],"batl":[[0,1.3,602.24]],"ltp":1.3,"tv":18546.02,"id":8681938}],"tv":21628.75}]}
{"op":"mcm","clk":"4297049565","pt":1632571566268,"mc":[{"id":"1.188134680","rc":[{"trd":[[1.3,519.04]],"batl":[[0,1.3,572.24]],"ltp":1.3,"tv":18606.02,"id":8681938}],"tv":21688.75}]}
{"op":"mcm","clk":"4297049660","pt":1632571566694,"mc":[{"id":"1.188134680","rc":[{"batl":[[1,4.7,203.46],[2,4.8,288.62]],"ltp":4.3,"tv":3082.73,"id":9631939},{"trd":[[1.3,539.04]],"batl":[[0,1.3,562.24]],"ltp":1.3,"tv":18626.02,"id":8681938}],"tv":21708.75}]}
{"op":"mcm","clk":"4297049967","pt":1632571568104,"mc":[{"id":"1.188134680","rc":[{"trd":[[1.3,2315.04]],"batb":[[0,1.3,339.53],[1,1.28,1013.44]],"batl":[[0,1.31,595.59],[1,1.32,629.67],[2,1.33,720.23]],"ltp":1.3,"tv":20402.02,"id":8681938}],"tv":23484.75}]}
{"op":"mcm","clk":"4297050691","pt":1632571571273,"mc":[{"id":"1.188134680","rc":[{"trd":[[1.3,2925.29]],"batb":[[0,1.3,34.41]],"ltp":1.3,"tv":21012.26,"id":8681938}],"tv":24094.99}]}
{"op":"mcm","clk":"4297050966","pt":1632571572364,"mc":[{"id":"1.188134680","rc":[{"trd":[[1.3,2930.32]],"batb":[[0,1.3,34.24]],"batl":[[0,1.31,801.59]],"ltp":1.3,"tv":21017.3,"id":8681938}],"tv":24100.03}]}
{"op":"mcm","clk":"4297051448","pt":1632571574584,"mc":[{"id":"1.188134680","rc":[{"batl":[[0,1.31,808.02]],"ltp":1.3,"tv":21017.3,"id":8681938}]}]}
{"op":"mcm","clk":"4297051700","pt":1632571575684,"mc":[{"id":"1.188134680","rc":[{"trd":[[1.3,2943.29]],"batb":[[0,1.3,27.76]],"batl":[[0,1.31,992.59]],"ltp":1.3,"tv":21030.26,"id":8681938}],"tv":24112.99}]}
{"op":"mcm","clk":"4297052139","pt":1632571577599,"mc":[{"id":"1.188134680","rc":[{"batb":[[0,1.3,25.41]],"ltp":1.3,"tv":21030.26,"id":8681938}]}]}
{"op":"mcm","clk":"4297052509","pt":1632571579221,"mc":[{"id":"1.188134680","rc":[{"batl":[[0,1.31,1205.59]],"ltp":1.3,"tv":21030.26,"id":8681938}]}]}
{"op":"mcm","clk":"4297053622","pt":1632571583991,"mc":[{"id":"1.188134680","rc":[{"trd":[[1.3,2943.46]],"batb":[[0,1.3,25.32]],"ltp":1.3,"tv":21030.44,"id":8681938}],"tv":24113.17}]}
{"op":"mcm","clk":"4297054157","pt":1632571586293,"mc":[{"id":"1.188134680","rc":[{"batb":[[2,1.27,1348.62]],"ltp":1.3,"tv":21030.44,"id":8681938}]}]}
{"op":"mcm","clk":"4297054230","pt":1632571586621,"mc":[{"id":"1.188134680","rc":[{"batb":[[2,1.27,1348.6]],"ltp":1.3,"tv":21030.44,"id":8681938}]}]}
{"op":"mcm","clk":"4297054879","pt":1632571589704,"mc":[{"id":"1.188134680","rc":[{"trd":[[1.31,457.49]],"batl":[[0,1.31,1205.57]],"ltp":1.31,"tv":21030.48,"id":8681938}],"tv":24113.21}]}
{"op":"mcm","clk":"4297055067","pt":1632571590512,"mc":[{"id":"1.188134680","rc":[{"trd":[[1.3,2948.44]],"batb":[[0,1.3,22.83]],"ltp":1.3,"tv":21035.45,"id":8681938}],"tv":24118.19}]}
{"op":"mcm","clk":"4297061939","pt":1632571621458,"mc":[{"id":"1.188134680","rc":[{"trd":[[1.3,2949.04]],"batb":[[0,1.3,22.53]],"ltp":1.3,"tv":21036.05,"id":8681938}],"tv":24118.78}]}
{"op":"mcm","clk":"4297064449","pt":1632571632884,"mc":[{"id":"1.188134680","rc":[{"trd":[[1.3,2949.06]],"batb":[[0,1.3,22.52]],"ltp":1.3,"tv":21036.07,"id":8681938}],"tv":24118.8}]}
{"op":"mcm","clk":"4297064979","pt":1632571635179,"mc":[{"id":"1.188134680","rc":[{"batb":[[0,1.3,52.52]],"ltp":1.3,"tv":21036.07,"id":8681938}]}]}
{"op":"mcm","clk":"4297065209","pt":1632571636164,"mc":[{"id":"1.188134680","rc":[{"batb":[[0,1.3,82.52]],"ltp":1.3,"tv":21036.07,"id":8681938}]}]}
{"op":"mcm","clk":"4297068308","pt":1632571651364,"mc":[{"id":"1.188134680","rc":[{"batb":[[0,4.2,18.75],[1,3.65,94.95],[2,3.6,116.37]],"batl":[[0,4.8,91.14],[1,4.9,90.14],[2,5.2,2]],"ltp":4.3,"tv":3082.73,"id":9631939},{"batb":[[1,1.27,332.92],[2,1.26,971.52]],"batl":[[0,1.31,670],[1,1.33,1.25],[2,1.38,340]],"ltp":1.3,"tv":21036.07,"id":8681938}]}]}
{"op":"mcm","clk":"4297068509","pt":1632571652381,"mc":[{"id":"1.188134680","rc":[{"batb":[[0,3.65,94.95],[1,3.6,116.37],[2,3.55,123.88]],"ltp":4.3,"tv":3082.73,"id":9631939},{"batl":[[0,1.33,1.25],[1,1.38,340],[2,1.39,389.29]],"ltp":1.3,"tv":21036.07,"id":8681938}]}]}
{"op":"mcm","clk":"4297068927","pt":1632571654381,"mc":[{"id":"1.188134680","rc":[{"batb":[[0,3.7,93.85],[1,3.65,94.95],[2,1.9,5.76]],"ltp":4.3,"tv":3082.73,"id":9631939},{"batb":[[2,1.26,1803.95]],"batl":[[1,1.93,2.86],[2,4.4,3.34]],"ltp":1.3,"tv":21036.07,"id":8681938}]}]}
{"op":"mcm","clk":"4297069002","pt":1632571654785,"mc":[{"id":"1.188134680","rc":[{"batb":[[1,1.9,5.76],[2,1.01,140]],"ltp":4.3,"tv":3082.73,"id":9631939},{"batb":[[2,1.26,1218.94]],"ltp":1.3,"tv":21036.07,"id":8681938}]}]}
{"op":"mcm","clk":"4297069151","pt":1632571655499,"mc":[{"id":"1.188134680","rc":[{"batb":[[1,3.65,2],[2,3.6,3]],"ltp":4.3,"tv":3082.73,"id":9631939},{"batl":[[1,1.38,7.31],[2,1.93,2.55]],"ltp":1.3,"tv":21036.07,"id":8681938}]}]}
{"op":"mcm","clk":"4297069528","pt":1632571657383,"mc":[{"id":"1.188134680","rc":[{"batb":[[0,4.5,5.71],[1,3.7,93.85],[2,3.65,2]],"batl":[[0,4.7,53.12],[1,4.8,91.14],[2,4.9,90.14]],"ltp":4.3,"tv":3082.73,"id":9631939},{"trd":[[1.3,3114.1]],"batb":[[0,1.27,332.92],[1,1.26,1218.94],[2,1.25,1040.4]],"batl":[[0,1.29,462.83],[1,1.3,1044.04],[2,1.31,326.09]],"ltp":1.3,"tv":21201.11,"id":8681938}],"tv":24283.84}]}
{"op":"mcm","clk":"4297069698","pt":1632571658283,"mc":[{"id":"1.188134680","rc":[{"batb":[[1,4.3,124.8],[2,3.9,161.41]],"batl":[[0,4.7,59.5],[1,4.8,106.27],[2,4.9,186.06]],"ltp":4.3,"tv":3082.73,"id":9631939}]}]}
{"op":"mcm","clk":"4297069717","pt":1632571658392,"mc":[{"id":"1.188134680","rc":[{"batb":[[1,4.3,142.98]],"ltp":4.3,"tv":3082.73,"id":9631939}]}]}
{"op":"mcm","clk":"4297070046","pt":1632571659899,"mc":[{"id":"1.188134680","rc":[{"batb":[[0,1.27,370.75]],"ltp":1.3,"tv":21201.11,"id":8681938}]}]}
{"op":"mcm","clk":"4297070504","pt":1632571662088,"mc":[{"id":"1.188134680","rc":[{"batb":[[1,4.3,124.8]],"ltp":4.3,"tv":3082.73,"id":9631939},{"batl":[[0,1.28,480.71],[1,1.29,462.83],[2,1.3,1044.04]],"ltp":1.3,"tv":21201.11,"id":8681938}]}]}
{"op":"mcm","clk":"4297070901","pt":1632571664001,"mc":[{"id":"1.188134680","rc":[{"batb":[[2,3.9,287.2]],"ltp":4.3,"tv":3082.73,"id":9631939},{"batb":[[2,1.25,1402.01]],"ltp":1.3,"tv":21201.11,"id":8681938}]}]}
{"op":"mcm","clk":"4297071212","pt":1632571665292,"mc":[{"id":"1.188134680","rc":[{"batb":[[1,4.4,17.64],[2,4.3,124.8]],"ltp":4.3,"tv":3082.73,"id":9631939},{"batl":[[1,1.29,522.83]],"ltp":1.3,"tv":21201.11,"id":8681938}]}]}
{"op":"mcm","clk":"4297072529","pt":1632571671800,"mc":[{"id":"1.188134680","rc":[{"batl":[[0,1.28,775.71]],"ltp":1.3,"tv":21201.11,"id":8681938}]}]}
{"op":"mcm","clk":"4297072846","pt":1632571673336,"mc":[{"id":"1.188134680","rc":[{"batb":[[0,4.4,17.64],[1,3.9,125.79],[2,3.85,115.75]],"batl":[[0,5.1,7.4],[1,5.2,2],[2,5.5,1.8]],"ltp":4.3,"tv":3082.73,"id":9631939},{"batb":[[0,1.24,9],[1,1.01,140],[2,1.25,0]],"batl":[[1,1.29,60],[2,1.32,6.25]],"ltp":1.3,"tv":21201.11,"id":8681938}]}]}
{"op":"mcm","clk":"4297073050","pt":1632571674344,"mc":[{"id":"1.188134680","rc":[{"batb":[[0,3.9,125.79],[1,3.85,115.75],[2,3.8,64.14]],"batl":[[0,5.2,2],[1,5.5,1.8],[2,5.8,2.54]],"ltp":4.3,"tv":3082.73,"id":9631939},{"batl":[[0,1.28,13.71],[1,1.32,6.25],[2,1.33,1.56]],"ltp":1.3,"tv":21201.11,"id":8681938}]}]}
{"op":"mcm","clk":"4297073278","pt":1632571675319,"mc":[{"id":"1.188134680","rc":[{"batb":[[2,2.62,386.89]],"ltp":4.3,"tv":3082.73,"id":9631939},{"batl":[[0,1.32,6.25],[1,1.33,1.56],[2,1.35,298.43]],"ltp":1.3,"tv":21201.11,"id":8681938}]}]}
{"op":"mcm","clk":"4297073472","pt":1632571676222,"mc":[{"id":"1.188134680","rc":[{"batl":[[0,4.2,54.75],[1,4.7,3],[2,5.2,2]],"ltp":4.3,"tv":3082.73,"id":9631939},{"batb":[[0,1.3,799],[1,1.29,735.83],[2,1.28,775.66]],"batl":[[0,1.33,498.37],[1,1.34,584.03]],"ltp":1.3,"tv":21201.11,"id":8681938}]}]}
{"op":"mcm","clk":"4297073711","pt":1632571677374,"mc":[{"id":"1.188134680","rc":[{"batl":[[1,4.3,1.71],[2,4.7,3]],"ltp":4.3,"tv":3082.73,"id":9631939},{"batb":[[1,1.29,1258.2],[2,1.24,9]],"ltp":1.3,"tv":21201.11,"id":8681938}]}]}
{"op":"mcm","clk":"4297073760","pt":1632571677642,"mc":[{"id":"1.188134680","rc":[{"batb":[[0,4,20],[1,3.9,125.79],[2,3.85,115.75]],"batl":[[2,4.5,3]],"ltp":4.3,"tv":3082.73,"id":9631939},{"batb":[[1,1.29,735.83],[2,1.28,10]],"batl":[[0,1.33,558.37]],"ltp":1.3,"tv":21201.11,"id":8681938}]}]}
{"op":"mcm","clk":"4297073916","pt":1632571678457,"mc":[{"id":"1.188134680","rc":[{"batb":[[1,3.95,64.14],[2,3.9,125.79]],"ltp":4.3,"tv":3082.73,"id":9631939},{"batb":[[0,1.3,808],[1,1.29,745.83]],"ltp":1.3,"tv":21201.11,"id":8681938}]}]}
{"op":"mcm","clk":"4297074177","pt":1632571679862,"mc":[{"id":"1.188134680","rc":[{"batb":[[0,1.3,861.71]],"ltp":1.3,"tv":21201.11,"id":8681938}]}]}
{"op":"mcm","clk":"4297074819","pt":1632571683080,"mc":[{"id":"1.188134680","rc":[{"batb":[[2,1.28,484.88]],"batl":[[0,1.32,577],[1,1.33,558.37],[2,1.34,584.03]],"ltp":1.3,"tv":21201.11,"id":8681938}]}]}
{"op":"mcm","clk":"4297075537","pt":1632571686243,"mc":[{"id":"1.188134680","rc":[{"batl":[[0,1.32,1155]],"ltp":1.3,"tv":21201.11,"id":8681938}]}]}
{"op":"mcm","clk":"4297075695","pt":1632571686900,"mc":[{"id":"1.188134680","rc":[{"batb":[[1,3.5,2],[2,3.35,147.76]],"batl":[[0,4.5,3],[1,4.6,101.93],[2,4.7,116.87]],"ltp":4.3,"tv":3082.73,"id":9631939},{"batb":[[0,1.3,9],[1,1.29,10]],"batl":[[1,1.33,61.56],[2,1.4,32.9]],"ltp":1.3,"tv":21201.11,"id":8681938}]}]}
{"op":"mcm","clk":"4297075988","pt":1632571688260,"mc":[{"id":"1.188134680","rc":[{"batb":[[0,3.5,2],[1,3.35,147.76],[2,3.3,121.25]],"batl":[[0,4.6,101.93],[1,4.7,106.08],[2,4.9,2]],"ltp":4.3,"tv":3082.73,"id":9631939},{"batb":[[0,1.28,484.88],[1,1.27,512.09],[2,1.26,53.98]],"batl":[[0,1.33,1.56],[1,1.4,32.9],[2,1.42,27.25]],"ltp":1.3,"tv":21201.11,"id":8681938}]}]}
{"op":"mcm","clk":"4297076483","pt":1632571690272,"mc":[{"id":"1.188134680","rc":[{"batb":[[0,1.28,908.88],[1,1.27,1297.68]],"batl":[[2,1.41,534.56]],"ltp":1.3,"tv":21201.11,"id":8681938}]}]}
{"op":"mcm","clk":"4297076794","pt":1632571691582,"mc":[{"id":"1.188134680","rc":[{"batl":[[0,4.6,103.93]],"ltp":4.3,"tv":3082.73,"id":9631939}]}]}
{"op":"mcm","clk":"4297077231","pt":1632571693465,"mc":[{"id":"1.188134680","rc":[{"batb":[[1,1.27,1307.68]],"ltp":1.3,"tv":21201.11,"id":8681938}]}]}
{"op":"mcm","clk":"4297078702","pt":1632571700170,"mc":[{"id":"1.188134680","rc":[{"batb":[[1,3.35,2],[2,3.3,2.08]],"ltp":4.3,"tv":3082.73,"id":9631939},{"batl":[[2,1.42,27.25]],"ltp":1.3,"tv":21201.11,"id":8681938}]}]}
{"op":"mcm","clk":"4297079145","pt":1632571702289,"mc":[{"id":"1.188134680","rc":[{"batl":[[0,1.33,1.25]],"ltp":1.3,"tv":21201.11,"id":8681938}]}]}
{"op":"mcm","clk":"4297079360","pt":1632571703232,"mc":[{"id":"1.188134680","rc":[{"batb":[[0,4.4,5.82],[1,4.3,2.08],[2,3.5,2]],"batl":[[1,4.7,194.67],[2,4.8,498.05]],"ltp":4.3,"tv":3082.73,"id":9631939},{"batl":[[0,1.3,337.06],[1,1.31,6833.66],[2,1.32,1958.84]],"ltp":1.3,"tv":21201.11,"id":8681938}]}]}
{"op":"mcm","clk":"4297079616","pt":1632571704293,"mc":[{"id":"1.188134680","rc":[{"batb":[[1,4.2,18.75]],"batl":[[1,4.7,201.05],[2,4.8,199.22]],"ltp":4.3,"tv":3082.73,"id":9631939},{"trd":[[1.3,3121.01]],"batl":[[0,1.3,319.81],[1,1.31,1148],[2,1.32,932.2]],"ltp":1.3,"tv":21208.03,"id":8681938}],"tv":24290.76}]}
{"op":"mcm","clk":"4297079717","pt":1632571704782,"mc":[{"id":"1.188134680","rc":[{"batb":[[2,3.7,10]],"batl":[[0,4.6,116.8]],"ltp":4.3,"tv":3082.73,"id":9631939},{"trd":[[1.3,3126.81]],"batb":[[0,1.28,949.13]],"batl":[[0,1.3,316.91],[2,1.32,940]],"ltp":1.3,"tv":21213.83,"id":8681938}],"tv":24296.56}]}
{"op":"mcm","clk":"4297079960","pt":1632571705831,"mc":[{"id":"1.188134680","rc":[{"batb":[[1,1.27,1297.68]],"batl":[[1,1.31,1161.71]],"ltp":1.3,"tv":21213.83,"id":8681938}]}]}
{"op":"mcm","clk":"4297080532","pt":1632571708191,"mc":[{"id":"1.188134680","rc":[{"batb":[[1,3.7,10],[2,3.55,3]],"ltp":4.3,"tv":3082.73,"id":9631939},{"batl":[[2,1.32,880]],"ltp":1.3,"tv":21213.83,"id":8681938}]}]}
{"op":"mcm","clk":"4297080689","pt":1632571708905,"mc":[{"id":"1.188134680","rc":[{"batl":[[0,1.3,432.91]],"ltp":1.3,"tv":21213.83,"id":8681938}]}]}
{"op":"mcm","clk":"4297080998","pt":1632571710194,"mc":[{"id":"1.188134680","rc":[{"batb":[[1,3.7,147.7],[2,3.65,144.66]],"batl":[[2,4.8,282.61]],"ltp":4.3,"tv":3082.73,"id":9631939},{"batb":[[2,1.26,383.16]],"ltp":1.3,"tv":21213.83,"id":8681938}]}]}
{"op":"mcm","clk":"4297081095","pt":1632571710635,"mc":[{"id":"1.188134680","rc":[{"batb":[[1,4.1,2],[2,3.9,2]],"batl":[[2,4.8,284.61]],"ltp":4.3,"tv":3082.73,"id":9631939},{"batb":[[1,1.27,1344.55]],"batl":[[2,1.32,916.36]],"ltp":1.3,"tv":21213.83,"id":8681938}]}]}
{"op":"mcm","clk":"4297081446","pt":1632571712129,"mc":[{"id":"1.188134680","rc":[{"batb":[[1,4.3,18.18],[2,4.1,2]],"ltp":4.3,"tv":3082.73,"id":9631939},{"batl":[[1,1.31,1208]],"ltp":1.3,"tv":21213.83,"id":8681938}]}]}
{"op":"mcm","clk":"4297081549","pt":1632571712600,"mc":[{"id":"1.188134680","rc":[{"batl":[[0,1.3,523.91]],"ltp":1.3,"tv":21213.83,"id":8681938}]}]}
{"op":"mcm","clk":"4297081917","pt":1632571714205,"mc":[{"id":"1.188134680","rc":[{"batb":[[0,4.3,18.18],[1,4.1,2],[2,3.9,2]],"batl":[[1,4.7,106.08],[2,4.8,85.39]],"ltp":4.3,"tv":3082.73,"id":9631939},{"batl":[[1,1.31,717.86],[2,1.32,44.16]],"ltp":1.3,"tv":21213.83,"id":8681938}]}]}
{"op":"mcm","clk":"4297082063","pt":1632571714807,"mc":[{"id":"1.188134680","rc":[{"batl":[[0,4.8,83.39],[1,4.9,108.59],[2,5.5,1.8]],"ltp":4.3,"tv":3082.73,"id":9631939},{"batb":[[0,1.26,383.16],[1,1.25,357.05],[2,1.01,140]],"batl":[[0,1.28,26.57],[1,1.3,207],[2,1.31,60]],"ltp":1.3,"tv":21213.83,"id":8681938}]}]}
{"op":"mcm","clk":"4297082394","pt":1632571716309,"mc":[{"id":"1.188134680","rc":[{"batb":[[0,4.1,2],[1,3.9,2],[2,3.7,137.7]],"ltp":4.3,"tv":3082.73,"id":9631939},{"batl":[[1,1.32,36.36],[2,1.33,1.25]],"ltp":1.3,"tv":21213.83,"id":8681938}]}]}
{"op":"mcm","clk":"4297082454","pt":1632571716589,"mc":[{"id":"1.188134680","rc":[{"batb":[[0,3.9,2],[1,3.7,137.7],[2,3.65,144.66]],"ltp":4.3,"tv":3082.73,"id":9631939},{"batl":[[1,1.33,1.25],[2,1.34,36.75]],"ltp":1.3,"tv":21213.83,"id":8681938}]}]}
{"op":"mcm","clk":"4297082824","pt":1632571718320,"mc":[{"id":"1.188134680","rc":[{"batb":[[1,3.5,3],[2,2.62,386.89]],"batl":[[0,4.8,85.39]],"ltp":4.3,"tv":3082.73,"id":9631939},{"batb":[[0,1.26,1113.46],[1,1.25,1250.76]],"ltp":1.3,"tv":21213.83,"id":8681938}]}]}
{"op":"mcm","clk":"4297082994","pt":1632571719107,"mc":[{"id":"1.188134680","rc":[{"batl":[[1,1.33,1.56]],"ltp":1.3,"tv":21213.83,"id":8681938}]}]}
{"op":"mcm","clk":"4297083374","pt":1632571721018,"mc":[{"id":"1.188134680","rc":[{"batb":[[0,4.5,2],[1,4.4,48.83],[2,3.9,2]],"batl":[[0,4.8,2],[1,4.9,110.31],[2,5,37.44]],"ltp":4.3,"tv":3082.73,"id":9631939},{"batb":[[1,1.25,1400.52],[2,1.23,53.1]],"batl":[[0,1.27,20.81],[1,1.28,409.09],[2,1.29,1708.05]],"ltp":1.3,"tv":21213.83,"id":8681938}]}]}
{"op":"mcm","clk":"4297083675","pt":1632571722332,"mc":[{"id":"1.188134680","rc":[{"batb":[[1,4.4,66.47]],"batl":[[2,5,43.44]],"ltp":4.3,"tv":3082.73,"id":9631939},{"batl":[[0,1.27,34.52]],"ltp":1.3,"tv":21213.83,"id":8681938}]}]}
{"op":"mcm","clk":"4297083740","pt":1632571722625,"mc":[{"id":"1.188134680","rc":[{"batb":[[2,3.95,10]],"batl":[[0,4.8,12.63]],"ltp":4.3,"tv":3082.73,"id":9631939},{"batb":[[0,1.26,1163.17]],"ltp":1.3,"tv":21213.83,"id":8681938}]}]}
{"op":"mcm","clk":"4297084470","pt":1632571725935,"mc":[{"id":"1.188134680","rc":[{"batb":[[1,4.4,48.83]],"ltp":4.3,"tv":3082.73,"id":9631939},{"batl":[[2,1.29,1768.05]],"ltp":1.3,"tv":21213.83,"id":8681938}]}]}
{"op":"mcm","clk":"4297084786","pt":1632571727328,"mc":[{"id":"1.188134680","rc":[{"batb":[[1,4.4,50.83],[2,4.3,2]],"batl":[[2,5,45.44]],"ltp":4.3,"tv":3082.73,"id":9631939},{"batb":[[1,1.25,1448.33],[2,1.24,626.27]],"batl":[[2,1.29,1810.55]],"ltp":1.3,"tv":21213.83,"id":8681938}]}]}
{"op":"mcm","clk":"4297084857","pt":1632571727699,"mc":[{"id":"1.188134680","rc":[{"batb":[[2,1.24,1007.97]],"ltp":1.3,"tv":21213.83,"id":8681938}]}]}
{"op":"mcm","clk":"4297085182","pt":1632571729334,"mc":[{"id":"1.188134680","rc":[{"batb":[[0,4.5,19.14]],"ltp":4.3,"tv":3082.73,"id":9631939},{"batb":[[1,1.25,1436.33]],"ltp":1.3,"tv":21213.83,"id":8681938}]}]}
{"op":"mcm","clk":"4297085663","pt":1632571731533,"mc":[{"id":"1.188134680","rc":[{"batl":[[1,4.9,108.59]],"ltp":4.3,"tv":3082.73,"id":9631939}]}]}
{"op":"mcm","clk":"4297085976","pt":1632571733010,"mc":[{"id":"1.188134680","rc":[{"batb":[[0,4.5,17.14],[1,4.4,2]],"batl":[[0,5,2],[1,5.1,75.95],[2,5.2,109.22]],"ltp":4.3,"tv":3082.73,"id":9631939},{"batb":[[0,1.25,884.21],[1,1.24,1007.97],[2,1.23,435.75]],"batl":[[0,1.27,13.71],[1,1.28,26.57],[2,1.29,102.5]],"ltp":1.3,"tv":21213.83,"id":8681938}]}]}
{"op":"mcm","clk":"4297086219","pt":1632571734244,"mc":[{"id":"1.188134680","rc":[{"batb":[[0,4.4,2],[1,4.3,2],[2,4.1,102.16]],"ltp":4.3,"tv":3082.73,"id":9631939},{"batl":[[1,1.29,42.5],[2,1.3,41.95]],"ltp":1.3,"tv":21213.83,"id":8681938}]}]}
{"op":"mcm","clk":"4297086415","pt":1632571735157,"mc":[{"id":"1.188134680","rc":[{"batb":[[0,4.3,2],[1,4.1,102.16],[2,4,266.91]],"ltp":4.3,"tv":3082.73,"id":9631939},{"batl":[[0,1.3,41.95],[1,1.32,334.34],[2,1.33,456.41]],"ltp":1.3,"tv":21213.83,"id":8681938}]}]}
{"op":"mcm","clk":"4297086683","pt":1632571736343,"mc":[{"id":"1.188134680","rc":[{"batb":[[1,4,150.16],[2,3.5,3]],"batl":[[0,4.9,2],[1,5,5],[2,5.1,75.95]],"ltp":4.3,"tv":3082.73,"id":9631939},{"batb":[[0,1.26,43.98],[1,1.25,893.21],[2,1.24,1948.21]],"batl":[[0,1.33,1.56],[1,1.93,2.86],[2,4.4,3.34]],"ltp":1.3,"tv":21213.83,"id":8681938}]}]}
{"op":"mcm","clk":"4297086727","pt":1632571736546,"mc":[{"id":"1.188134680","rc":[{"batl":[[0,5,5],[1,5.1,75.95],[2,5.2,109.22]],"ltp":4.3,"tv":3082.73,"id":9631939},{"batb":[[0,1.25,893.21],[1,1.24,1948.21],[2,1.23,435.75]],"ltp":1.3,"tv":21213.83,"id":8681938}]}]}
{"op":"mcm","clk":"4297087095","pt":1632571738149,"mc":[{"id":"1.188134680","rc":[{"batl":[[0,1.28,13.71],[1,1.33,1.56],[2,1.93,2.86]],"ltp":1.3,"tv":21213.83,"id":8681938}]}]}
{"op":"mcm","clk":"4297087346","pt":1632571739347,"mc":[{"id":"1.188134680","rc":[{"batb":[[0,4.6,165.65],[1,4.5,116.65],[2,4.4,32.82]],"batl":[[1,5.1,126.75]],"ltp":4.3,"tv":3082.73,"id":9631939},{"batl":[[0,1.26,26.67],[1,1.27,370.08],[2,1.28,1246.27]],"ltp":1.3,"tv":21213.83,"id":8681938}]}]}
{"op":"mcm","clk":"4297087431","pt":1632571739733,"mc":[{"id":"1.188134680","rc":[{"batb":[[2,4.4,42.82]],"batl":[[0,5,18.39],[2,5.2,114.99]],"ltp":4.3,"tv":3082.73,"id":9631939},{"batb":[[0,1.25,946.78]],"ltp":1.3,"tv":21213.83,"id":8681938}]}]}
{"op":"mcm","clk":"4297087715","pt":1632571741038,"mc":[{"id":"1.188134680","rc":[{"batb":[[1,4.5,133.79]],"ltp":4.3,"tv":3082.73,"id":9631939},{"batl":[[1,1.27,383.79],[2,1.28,1306.27]],"ltp":1.3,"tv":21213.83,"id":8681938}]}]}
{"op":"mcm","clk":"4297088024","pt":1632571742253,"mc":[{"id":"1.188134680","rc":[{"batl":[[1,1.27,370.08],[2,1.28,1292.56]],"ltp":1.3,"tv":21213.83,"id":8681938}]}]}
{"op":"mcm","clk":"4297088500","pt":1632571744237,"mc":[{"id":"1.188134680","rc":[{"batb":[[1,4.5,116.65],[2,4.4,10]],"ltp":4.3,"tv":3082.73,"id":9631939},{"trd":[[1.26,2371.22]],"batl":[[0,1.26,9.96]],"ltp":1.26,"tv":21247.25,"id":8681938}],"tv":24329.98}]}
{"op":"mcm","clk":"4297088848","pt":1632571745656,"mc":[{"id":"1.188134680","rc":[{"batb":[[2,4.4,12]],"ltp":4.3,"tv":3082.73,"id":9631939}]}]}
{"op":"mcm","clk":"4297089173","pt":1632571747258,"mc":[{"id":"1.188134680","rc":[{"batb":[[0,4.6,182.31]],"ltp":4.3,"tv":3082.73,"id":9631939},{"trd":[[1.26,2390.64]],"batl":[[0,1.27,370.33],[1,1.28,1292.56],[2,1.29,938.13]],"ltp":1.26,"tv":21266.67,"id":8681938}],"tv":24349.4}]}
{"op":"mcm","clk":"4297089710","pt":1632571749653,"mc":[{"id":"1.188134680","rc":[{"batb":[[1,1.24,1937.21]],"ltp":1.26,"tv":21266.67,"id":8681938}]}]}
{"op":"mcm","clk":"4297089921","pt":1632571750639,"mc":[{"id":"1.188134680","rc":[{"batl":[[0,1.27,489.33]],"ltp":1.26,"tv":21266.67,"id":8681938}]}]}
{"op":"mcm","clk":"4297090657","pt":1632571754061,"mc":[{"id":"1.188134680","rc":[{"batl":[[1,5.1,122.79]],"ltp":4.3,"tv":3082.73,"id":9631939},{"batl":[[0,1.27,489.08]],"ltp":1.26,"tv":21266.67,"id":8681938}]}]}
{"op":"mcm","clk":"4297090775","pt":1632571754656,"mc":[{"id":"1.188134680","rc":[{"batl":[[0,1.27,609.08]],"ltp":1.26,"tv":21266.67,"id":8681938}]}]}
{"op":"mcm","clk":"4297091293","pt":1632571757056,"mc":[{"id":"1.188134680","rc":[{"trd":[[4.7,45.38]],"batl":[[0,5,24.88]],"ltp":4.7,"tv":3083.18,"id":9631939},{"trd":[[1.27,614.09]],"batl":[[0,1.27,631.95]],"ltp":1.27,"tv":21268.33,"id":8681938}],"tv":24351.51}]}
{"op":"mcm","clk":"4297091482","pt":1632571757959,"mc":[{"id":"1.188134680","rc":[{"batl":[[0,5,18.39]],"ltp":4.7,"tv":3083.18,"id":9631939},{"batl":[[0,1.27,728.42]],"ltp":1.27,"tv":21268.33,"id":8681938}]}]}
{"op":"mcm","clk":"4297091950","pt":1632571760444,"mc":[{"id":"1.188134680","rc":[{"batl":[[0,5,24.88]],"ltp":4.7,"tv":3083.18,"id":9631939},{"batl":[[0,1.27,752.95]],"ltp":1.27,"tv":21268.33,"id":8681938}]}]}
{"op":"mcm","clk":"4297093288","pt":1632571767283,"mc":[{"id":"1.188134680","rc":[{"batb":[[0,4.6,16.66]],"batl":[[0,5,18.39],[1,5.1,75.95],[2,5.2,109.22]],"ltp":4.7,"tv":3083.18,"id":9631939},{"batl":[[0,1.27,360],[1,1.28,939.02],[2,1.29,753.09]],"ltp":1.27,"tv":21268.33,"id":8681938}]}]}
{"op":"mcm","clk":"4297093461","pt":1632571768281,"mc":[{"id":"1.188134680","rc":[{"batb":[[1,4.4,2],[2,4.3,2]],"batl":[[0,5.5,8.87],[1,5.8,2.54],[2,5.9,84.85]],"ltp":4.7,"tv":3083.18,"id":9631939},{"batb":[[0,1.2,466.08],[1,1.19,1374.72],[2,1.01,140]],"batl":[[0,1.28,60],[1,1.29,49.5],[2,1.3,44.75]],"ltp":1.27,"tv":21268.33,"id":8681938}]}]}
{"op":"mcm","clk":"4297093683","pt":1632571769319,"mc":[{"id":"1.188134680","rc":[{"batb":[[0,4.4,2],[1,4.3,2],[2,4.2,133.65]],"batl":[[0,5.5,1.8]],"ltp":4.7,"tv":3083.18,"id":9631939},{"batb":[[0,1.27,2.35],[1,1.2,466.08],[2,1.19,1374.72]],"batl":[[0,1.29,49.5],[1,1.3,44.75],[2,1.31,39.5]],"ltp":1.27,"tv":21268.33,"id":8681938}]}]}
{"op":"mcm","clk":"4297093749","pt":1632571769585,"mc":[{"id":"1.188134680","rc":[{"batb":[[0,4.3,2],[1,4.2,131.65],[2,4.1,101.41]],"ltp":4.7,"tv":3083.18,"id":9631939},{"batl":[[0,1.3,44.75],[1,1.32,331.51],[2,1.33,439.6]],"ltp":1.27,"tv":21268.33,"id":8681938}]}]}
{"op":"mcm","clk":"4297094101","pt":1632571771196,"mc":[{"id":"1.188134680","rc":[{"batb":[[1,1.21,517.61],[2,1.2,1612.06]],"batl":[[0,1.3,720.87],[1,1.31,651.63],[2,1.32,331.51]],"ltp":1.27,"tv":21268.33,"id":8681938}]}]}
{"op":"mcm","clk":"4297094308","pt":1632571772181,"mc":[{"id":"1.188134680","rc":[{"batl":[[0,4.7,17.29],[1,5.5,1.8],[2,5.8,4.54]],"ltp":4.7,"tv":3083.18,"id":9631939},{"trd":[[1.27,618.09]],"batb":[[0,1.21,573.65],[1,1.2,1612.06],[2,1.19,1374.72]],"ltp":1.27,"tv":21272.33,"id":8681938}],"tv":24355.51}]}
{"op":"mcm","clk":"4297094524","pt":1632571773206,"mc":[{"id":"1.188134680","rc":[{"batl":[[2,5.8,6.54]],"ltp":4.7,"tv":3083.18,"id":9631939},{"batb":[[0,1.21,56.04],[1,1.19,859.26],[2,1.01,140]],"batl":[[0,1.3,676.12]],"ltp":1.27,"tv":21272.33,"id":8681938}]}]}
{"op":"mcm","clk":"4297094787","pt":1632571774374,"mc":[{"id":"1.188134680","rc":[{"trd":[[4.7,62.67],[5.5,2.21]],"batl":[[0,5.8,6.54],[1,6,108.31],[2,6.4,2]],"ltp":5.5,"tv":3102.27,"id":9631939},{"trd":[[1.21,111.38],[1.22,2269.23],[1.27,682.77]],"batb":[[0,1.19,859.26],[1,1.01,140],[2,1.01,0]],"batl":[[0,1.21,271.87],[1,1.3,676.12],[2,1.31,651.63]],"ltp":1.21,"tv":21456.5,"id":8681938}],"tv":24558.77}]}
{"op":"mcm","clk":"4297094845","pt":1632571774675,"mc":[{"id":"1.188134680","rc":[{"batl":[[0,5.8,4.54]],"ltp":5.5,"tv":3102.27,"id":9631939},{"batl":[[0,1.3,676.12],[1,1.31,651.63],[2,1.32,331.51]],"ltp":1.21,"tv":21456.5,"id":8681938}]}]}
{"op":"mcm","clk":"4297095252","pt":1632571776371,"mc":[{"id":"1.188134680","rc":[{"batb":[[1,4.2,179.94]],"batl":[[0,4.7,52.42],[1,4.8,6.25],[2,5.8,4.54]],"ltp":5.5,"tv":3102.27,"id":9631939},{"batb":[[0,1.28,22.06],[1,1.27,1669.28],[2,1.26,1601.79]],"batl":[[0,1.3,698.25],[2,1.32,1055.95]],"ltp":1.21,"tv":21456.5,"id":8681938}]}]}
{"op":"mcm","clk":"4297095475","pt":1632571777288,"mc":[{"id":"1.188134680","rc":[{"batb":[[0,4.3,20.18]],"batl":[[2,5.1,1.71]],"ltp":5.5,"tv":3102.27,"id":9631939},{"batb":[[2,1.26,2170.99]],"batl":[[0,1.3,758.25]],"ltp":1.21,"tv":21456.5,"id":8681938}]}]}
{"op":"mcm","clk":"4297095737","pt":1632571778347,"mc":[{"id":"1.188134680","rc":[{"batb":[[0,4.3,2],[2,4.1,103.41]],"ltp":5.5,"tv":3102.27,"id":9631939},{"batl":[[0,1.3,698.25]],"ltp":1.21,"tv":21456.5,"id":8681938}]}]}
{"op":"mcm","clk":"4297095991","pt":1632571779593,"mc":[{"id":"1.188134680","rc":[{"trd":[[1.28,1143.21]],"batb":[[0,1.28,15.32]],"ltp":1.28,"tv":21469.98,"id":8681938}],"tv":24572.25}]}
{"op":"mcm","clk":"4297096330","pt":1632571781001,"mc":[{"id":"1.188134680","rc":[{"batb":[[0,4.3,20.18]],"ltp":5.5,"tv":3102.27,"id":9631939},{"trd":[[1.28,1147.21]],"batb":[[0,1.28,13.32]],"ltp":1.28,"tv":21473.98,"id":8681938}],"tv":24576.25}]}
{"op":"mcm","clk":"4297096547","pt":1632571781868,"mc":[{"id":"1.188134680","rc":[{"batl":[[0,4.7,75.12]],"ltp":5.5,"tv":3102.27,"id":9631939},{"batl":[[0,1.29,428],[1,1.3,698.25],[2,1.31,651.63]],"ltp":1.28,"tv":21473.98,"id":8681938}]}]}
{"op":"mcm","clk":"4297096812","pt":1632571783100,"mc":[{"id":"1.188134680","rc":[{"batb":[[1,4.2,181.94],[2,4.1,105.41]],"batl":[[2,5,2]],"ltp":5.5,"tv":3102.27,"id":9631939},{"batl":[[2,1.31,692.13]],"ltp":1.28,"tv":21473.98,"id":8681938}]}]}
{"op":"mcm","clk":"4297096926","pt":1632571783701,"mc":[{"id":"1.188134680","rc":[{"batl":[[1,1.3,758.25]],"ltp":1.28,"tv":21473.98,"id":8681938}]}]}
{"op":"mcm","clk":"4297097445","pt":1632571785992,"mc":[{"id":"1.188134680","rc":[{"batl":[[0,1.29,645],[1,1.3,801.6],[2,1.31,692.76]],"ltp":1.28,"tv":21473.98,"id":8681938}]}]}
{"op":"mcm","clk":"4297097633","pt":1632571786980,"mc":[{"id":"1.188134680","rc":[{"trd":[[1.28,1147.23]],"batb":[[0,1.28,13.31]],"ltp":1.28,"tv":21474.0,"id":8681938}],"tv":24576.27}]}
{"op":"mcm","clk":"4297097830","pt":1632571787901,"mc":[{"id":"1.188134680","rc":[{"batb":[[1,1.27,837.48]],"ltp":1.28,"tv":21474.0,"id":8681938}]}]}
{"op":"mcm","clk":"4297098121","pt":1632571789208,"mc":[{"id":"1.188134680","rc":[{"batb":[[1,4.2,133.65]],"batl":[[0,4.7,22.7],[1,5,2],[2,5.1,109.61]],"ltp":5.5,"tv":3102.27,"id":9631939},{"batb":[[0,1.27,837.48],[1,1.26,1412.05],[2,1.25,46.97]],"batl":[[1,1.3,779.47]],"ltp":1.28,"tv":21474.0,"id":8681938}]}]}
{"op":"mcm","clk":"4297098334","pt":1632571790309,"mc":[{"id":"1.188134680","rc":[{"batb":[[0,4.2,2],[1,4.1,2],[2,4,148.05]],"batl":[[0,5.1,109.61],[1,5.2,92.11],[2,5.4,2]],"ltp":5.5,"tv":3102.27,"id":9631939},{"batb":[[0,1.24,451.11],[1,1.23,424.85],[2,1.22,686.47]],"batl":[[0,1.31,41.13],[1,1.32,41.92],[2,1.35,269.94]],"ltp":1.28,"tv":21474.0,"id":8681938}]}]}
{"op":"mcm","clk":"4297098411","pt":1632571790710,"mc":[{"id":"1.188134680","rc":[{"batb":[[1,4,148.05],[2,3.9,105.16]],"ltp":5.5,"tv":3102.27,"id":9631939},{"batl":[[1,1.35,270.25],[2,1.36,362.08]],"ltp":1.28,"tv":21474.0,"id":8681938}]}]}
{"op":"mcm","clk":"4297098904","pt":1632571793101,"mc":[{"id":"1.188134680","rc":[{"batl":[[0,5.4,2],[1,5.7,3],[2,5.8,2.54]],"ltp":5.5,"tv":3102.27,"id":9631939},{"batb":[[0,1.23,52.63],[1,1.22,686.47],[2,1.21,13]],"batl":[[1,1.32,833.77],[2,1.33,600.61]],"ltp":1.28,"tv":21474.0,"id":8681938}]}]}
{"op":"mcm","clk":"4297099154","pt":1632571794205,"mc":[{"id":"1.188134680","rc":[{"batl":[[0,1.25,800],[1,1.31,41.13],[2,1.32,833.77]],"ltp":1.28,"tv":21474.0,"id":8681938}]}]}
{"op":"mcm","clk":"4297099406","pt":1632571795286,"mc":[{"id":"1.188134680","rc":[{"trd":[[5,190.94]],"batb":[[0,4.3,2],[1,4.2,2],[2,4,148.05]],"batl":[[0,4.5,86.91],[1,5.4,2],[2,5.7,3]],"ltp":5.0,"tv":3284.66,"id":9631939},{"trd":[[1.25,942.5]],"batl":[[0,1.3,42.25]],"ltp":1.25,"tv":22344.43,"id":8681938}],"tv":25629.09}]}
{"op":"mcm","clk":"4297099571","pt":1632571796040,"mc":[{"id":"1.188134680","rc":[{"trd":[[4.3,45.17]],"batb":[[0,4.2,2],[1,4,148.05],[2,3.9,105.16]],"batl":[[0,4.4,54.82],[1,4.5,6.67],[2,4.7,1.71]],"ltp":4.3,"tv":3291.01,"id":9631939},{"trd":[[1.3,3134.58]],"batb":[[0,1.29,3459.55],[1,1.28,1309.37],[2,1.27,828.32]],"batl":[[0,1.31,41.13],[1,1.32,853.91],[2,1.33,600.61]],"ltp":1.3,"tv":22352.2,"id":8681938}],"tv":25643.21}]}
{"op":"mcm","clk":"4297099886","pt":1632571797296,"mc":[{"id":"1.188134680","rc":[{"batb":[[0,4.3,18.18],[1,4.2,2],[2,4,148.05]],"ltp":4.3,"tv":3291.01,"id":9631939},{"batb":[[0,1.29,1484.77],[1,1.28,1469.84],[2,1.27,463.98]],"batl":[[1,1.32,833.77],[2,1.33,953.99]],"ltp":1.3,"tv":22352.2,"id":8681938}]}]}
{"op":"mcm","clk":"4297100063","pt":1632571798328,"mc":[{"id":"1.188134680","rc":[{"batb":[[0,4.2,2],[1,4,148.05],[2,3.9,266.74]],"ltp":4.3,"tv":3291.01,"id":9631939}]}]}
{"op":"mcm","clk":"4297100238","pt":1632571799207,"mc":[{"id":"1.188134680","rc":[{"trd":[[1.29,552.32]],"batb":[[0,1.29,1454.77],[1,1.28,1493.52]],"batl":[[1,1.32,893.77]],"ltp":1.29,"tv":22432.2,"id":8681938}],"tv":25723.21}]}
{"op":"mcm","clk":"4297100486","pt":1632571800310,"mc":[{"id":"1.188134680","rc":[{"batl":[[0,4.4,60.58]],"ltp":4.3,"tv":3291.01,"id":9631939},{"batb":[[0,1.29,1495.5]],"batl":[[0,1.31,55.69]],"ltp":1.29,"tv":22432.2,"id":8681938}]}]}
{"op":"mcm","clk":"4297100588","pt":1632571800840,"mc":[{"id":"1.188134680","rc":[{"batb":[[1,4.1,19.35],[2,4,148.05]],"ltp":4.3,"tv":3291.01,"id":9631939}]}]}
{"op":"mcm","clk":"4297100861","pt":1632571802220,"mc":[{"id":"1.188134680","rc":[{"batb":[[1,4.1,21.39]],"ltp":4.3,"tv":3291.01,"id":9631939},{"batb":[[2,1.27,504.85]],"batl":[[0,1.31,254.69],[1,1.32,954.63]],"ltp":1.29,"tv":22432.2,"id":8681938}]}]}
{"op":"mcm","clk":"4297100937","pt":1632571802623,"mc":[{"id":"1.188134680","rc":[{"batl":[[2,4.7,103.71]],"ltp":4.3,"tv":3291.01,"id":9631939},{"batb":[[2,1.27,895.37]],"ltp":1.29,"tv":22432.2,"id":8681938}]}]}
{"op":"mcm","clk":"4297101304","pt":1632571804198,"mc":[{"id":"1.188134680","rc":[{"batl":[[0,4.7,103.71],[1,4.8,108],[2,4.9,2]],"ltp":4.3,"tv":3291.01,"id":9631939},{"batb":[[0,1.28,524.81],[1,1.27,713.19],[2,1.26,534.09]],"batl":[[0,1.31,240.13],[1,1.32,121.17],[2,1.36,314.69]],"ltp":1.29,"tv":22432.2,"id":8681938}]}]}
{"op":"mcm","clk":"4297101538","pt":1632571805339,"mc":[{"id":"1.188134680","rc":[{"batb":[[1,4.1,2.04],[2,3.9,161.58]],"ltp":4.3,"tv":3291.01,"id":9631939},{"batb":[[0,1.27,713.19],[1,1.26,534.09],[2,1.25,610.45]],"batl":[[0,1.3,2.7],[1,1.31,41.13],[2,1.32,61.17]],"ltp":1.29,"tv":22432.2,"id":8681938}]}]}
{"op":"mcm","clk":"4297101989","pt":1632571807350,"mc":[{"id":"1.188134680","rc":[{"batb":[[0,4.2,3],[1,4.1,2]],"batl":[[0,4.7,102],[2,4.9,9.59]],"ltp":4.3,"tv":3291.01,"id":9631939},{"batb":[[1,1.26,1477.72],[2,1.25,1497.06]],"batl":[[1,1.31,50.13],[2,1.33,702.83]],"ltp":1.29,"tv":22432.2,"id":8681938}]}]}
{"op":"mcm","clk":"4297102142","pt":1632571808082,"mc":[{"id":"1.188134680","rc":[{"batl":[[0,4.8,2],[1,4.9,2],[2,5.3,2]],"ltp":4.3,"tv":3291.01,"id":9631939},{"batb":[[0,1.27,322.67],[1,1.26,53.98],[2,1.25,610.45]],"ltp":1.29,"tv":22432.2,"id":8681938}]}]}
{"op":"mcm","clk":"4297102385","pt":1632571809329,"mc":[{"id":"1.188134680","rc":[{"trd":[[1.27,1328.11]],"batb":[[0,1.26,53.98],[1,1.25,610.45],[2,1.24,12]],"batl":[[0,1.27,77.33],[1,1.3,2.7],[2,1.31,50.13]],"ltp":1.27,"tv":23077.54,"id":8681938}],"tv":26368.55}]}
{"op":"mcm","clk":"4297102583","pt":1632571810241,"mc":[{"id":"1.188134680","rc":[{"batb":[[0,4.3,2.08],[1,3.9,161.58],[2,3.8,119.93]],"batl":[[0,4.9,2],[1,5.3,2],[2,5.4,2]],"ltp":4.3,"tv":3291.01,"id":9631939},{"batb":[[2,1.23,62.63]],"batl":[[0,1.27,477.33],[1,1.3,62.15],[2,1.31,41.13]],"ltp":1.27,"tv":23077.54,"id":8681938}]}]}
{"op":"mcm","clk":"4297102813","pt":1632571811233,"mc":[{"id":"1.188134680","rc":[{"trd":[[4.2,39.92]],"batb":[[0,4.1,2.04],[1,3.9,406.78],[2,3.85,237.98]],"batl":[[0,4.3,6.98],[1,4.4,120.51],[2,4.9,2]],"ltp":4.2,"tv":3297.71,"id":9631939},{"trd":[[1.27,2282.77],[1.3,3159.98],[1.31,464.74]],"batb":[[0,1.3,1462.37],[1,1.29,1472.78],[2,1.28,719.48]],"batl":[[0,1.31,33.88],[1,1.32,63.17],[2,1.33,722.81]],"ltp":1.3,"tv":24064.85,"id":8681938}],"tv":27362.56}]}
{"op":"mcm","clk":"4297103052","pt":1632571812333,"mc":[{"id":"1.188134680","rc":[{"trd":[[4.2,41.63]],"batl":[[2,4.7,10]],"ltp":4.2,"tv":3299.42,"id":9631939},{"trd":[[1.31,470.24]],"batb":[[0,1.3,1956],[2,1.28,814.65]],"batl":[[0,1.31,28.38]],"ltp":1.31,"tv":24070.35,"id":8681938}],"tv":27369.77}]}
{"op":"mcm","clk":"4297103214","pt":1632571813027,"mc":[{"id":"1.188134680","rc":[{"batb":[[1,3.95,16.46],[2,3.9,406.78]],"batl":[[2,4.7,13]],"ltp":4.2,"tv":3299.42,"id":9631939},{"batb":[[0,1.3,1958],[2,1.28,817.38]],"ltp":1.31,"tv":24070.35,"id":8681938}]}]}
{"op":"mcm","clk":"4297103874","pt":1632571816146,"mc":[{"id":"1.188134680","rc":[{"batb":[[0,1.3,2001.31]],"batl":[[2,1.33,782.81]],"ltp":1.31,"tv":24070.35,"id":8681938}]}]}
{"op":"mcm","clk":"4297104311","pt":1632571818246,"mc":[{"id":"1.188134680","rc":[{"batb":[[0,3.8,201.16],[1,3.75,113.59],[2,3.5,3]],"batl":[[0,4.4,119.05],[1,4.5,101.17],[2,4.6,2]],"ltp":4.2,"tv":3299.42,"id":9631939},{"batb":[[0,1.29,373.37],[1,1.28,578.23],[2,1.27,551.02]],"batl":[[0,1.32,63.8],[1,1.33,60],[2,1.34,580.63]],"ltp":1.31,"tv":24070.35,"id":8681938}]}]}
{"op":"mcm","clk":"4297104527","pt":1632571819333,"mc":[{"id":"1.188134680","rc":[{"batb":[[0,4,20],[1,3.8,201.16],[2,3.75,113.59]],"ltp":4.2,"tv":3299.42,"id":9631939},{"batl":[[1,1.34,580.63],[2,1.36,275.45]],"ltp":1.31,"tv":24070.35,"id":8681938}]}]}
{"op":"mcm","clk":"4297104569","pt":1632571819542,"mc":[{"id":"1.188134680","rc":[{"batb":[[0,3.8,201.16],[1,3.75,113.59],[2,3.5,3]],"ltp":4.2,"tv":3299.42,"id":9631939}]}]}
{"op":"mcm","clk":"4297104925","pt":1632571821331,"mc":[{"id":"1.188134680","rc":[{"batb":[[0,4.1,4.54],[1,4,3],[2,3.8,201.16]],"ltp":4.2,"tv":3299.42,"id":9631939},{"batb":[[1,1.28,1294.61],[2,1.27,1355.14]],"batl":[[0,1.31,73.13],[1,1.32,72.17],[2,1.34,822.9]],"ltp":1.31,"tv":24070.35,"id":8681938}]}]}
{"op":"mcm","clk":"4297105139","pt":1632571822354,"mc":[{"id":"1.188134680","rc":[{"batl":[[0,4.5,2],[1,4.6,2],[2,4.9,2]],"ltp":4.2,"tv":3299.42,"id":9631939},{"batb":[[0,1.29,41.81],[1,1.28,44.16],[2,1.27,551.02]],"batl":[[0,1.32,72.8],[1,1.34,822.9],[2,1.35,558.21]],"ltp":1.31,"tv":24070.35,"id":8681938}]}]}
{"op":"mcm","clk":"4297105190","pt":1632571822651,"mc":[{"id":"1.188134680","rc":[{"batl":[[0,4.6,2],[1,5.3,2],[2,5.8,2.54]],"ltp":4.2,"tv":3299.42,"id":9631939},{"batb":[[0,1.28,44.16],[1,1.27,551.02],[2,1.25,12]],"ltp":1.31,"tv":24070.35,"id":8681938}]}]}
{"op":"mcm","clk":"4297105535","pt":1632571824143,"mc":[{"id":"1.188134680","rc":[{"trd":[[1.31,470.62]],"batb":[[0,1.3,91.38],[1,1.28,44.16],[2,1.27,551.02]],"batl":[[0,1.32,72.61]],"ltp":1.31,"tv":24070.73,"id":8681938}],"tv":27370.15}]}
{"op":"mcm","clk":"4297105772","pt":1632571825332,"mc":[{"id":"1.188134680","rc":[{"batb":[[0,4.1,2.54],[1,3.8,452.8],[2,3.75,405.28]],"batl":[[0,4.2,6.06],[1,4.3,132.43],[2,4.6,2]],"ltp":4.2,"tv":3299.42,"id":9631939},{"trd":[[1.31,622.5]],"batb":[[0,1.31,10476.1],[1,1.3,1524.8],[2,1.29,713.94]],"batl":[[0,1.32,63.17],[1,1.33,15.82],[2,1.34,822.9]],"ltp":1.31,"tv":24222.61,"id":8681938}],"tv":27522.03}]}
{"op":"mcm","clk":"4297105971","pt":1632571826251,"mc":[{"id":"1.188134680","rc":[{"batb":[[1,3.9,20.68],[2,3.8,452.8]],"batl":[[2,4.6,9.9]],"ltp":4.2,"tv":3299.42,"id":9631939},{"batb":[[0,1.31,1638.97],[2,1.29,4257.13]],"ltp":1.31,"tv":24222.61,"id":8681938}]}]}
{"op":"mcm","clk":"4297106194","pt":1632571827348,"mc":[{"id":"1.188134680","rc":[{"batl":[[2,4.5,10]],"ltp":4.2,"tv":3299.42,"id":9631939},{"batb":[[1,1.3,1433.42],[2,1.29,4342.64]],"ltp":1.31,"tv":24222.61,"id":8681938}]}]}
{"op":"mcm","clk":"4297106318","pt":1632571827954,"mc":[{"id":"1.188134680","rc":[{"trd":[[4.2,47.63]],"batl":[[0,4.2,3.06],[1,4.3,135.43]],"ltp":4.2,"tv":3305.42,"id":9631939},{"batb":[[0,1.31,1648.97],[1,1.3,1442.42]],"ltp":1.31,"tv":24222.61,"id":8681938}],"tv":27528.03}]}
{"op":"mcm","clk":"4297106827","pt":1632571830339,"mc":[{"id":"1.188134680","rc":[{"batb":[[2,1.29,1312.34]],"batl":[[0,1.32,78.75]],"ltp":1.31,"tv":24222.61,"id":8681938}]}]}
{"op":"mcm","clk":"4297107244","pt":1632571832340,"mc":[{"id":"1.188134680","rc":[{"batl":[[2,4.5,129.62]],"ltp":4.2,"tv":3305.42,"id":9631939}]}]}
{"op":"mcm","clk":"4297107670","pt":1632571834352,"mc":[{"id":"1.188134680","rc":[{"batb":[[2,3.85,85.14]],"ltp":4.2,"tv":3305.42,"id":9631939},{"batb":[[0,1.31,1175.32],[1,1.3,1918.61],[2,1.29,799.45]],"ltp":1.31,"tv":24222.61,"id":8681938}]}]}
{"op":"mcm","clk":"4297108218","pt":1632571837079,"mc":[{"id":"1.188134680","rc":[{"batb":[[0,1.31,366.12]],"ltp":1.31,"tv":24222.61,"id":8681938}]}]}
{"op":"mcm","clk":"4297108463","pt":1632571838377,"mc":[{"id":"1.188134680","rc":[{"batl":[[0,4.3,135.43],[1,4.5,119.62],[2,4.6,131.22]],"ltp":4.2,"tv":3305.42,"id":9631939},{"batl":[[1,1.34,822.9],[2,1.35,618.21]],"ltp":1.31,"tv":24222.61,"id":8681938}]}]}
{"op":"mcm","clk":"4297109096","pt":1632571841290,"mc":[{"id":"1.188134680","rc":[{"batb":[[0,1.31,381.25],[1,1.3,1909.61],[2,1.29,713.94]],"batl":[[0,1.32,63.17],[1,1.33,25.3],[2,1.34,822.9]],"ltp":1.31,"tv":24222.61,"id":8681938}]}]}
{"op":"mcm","clk":"4297109219","pt":1632571841903,"mc":[{"id":"1.188134680","rc":[{"batl":[[0,4.3,151.41]],"ltp":4.2,"tv":3305.42,"id":9631939},{"trd":[[1.31,623.76]],"batb":[[0,1.31,380.62]],"batl":[[0,1.32,62.86]],"ltp":1.31,"tv":24223.87,"id":8681938}],"tv":27529.29}]}
{"op":"mcm","clk":"4297109745","pt":1632571844290,"mc":[{"id":"1.188134680","rc":[{"trd":[[1.32,94.33]],"batb":[[0,1.31,418.88]],"batl":[[0,1.32,46.7],[1,1.33,40.76]],"ltp":1.32,"tv":24256.19,"id":8681938}],"tv":27561.61}]}
{"op":"mcm","clk":"4297110101","pt":1632571845980,"mc":[{"id":"1.188134680","rc":[{"trd":[[1.32,95.63]],"batl":[[0,1.32,46.05]],"ltp":1.32,"tv":24257.49,"id":8681938}],"tv":27562.91}]}
{"op":"mcm","clk":"4297110360","pt":1632571847285,"mc":[{"id":"1.188134680","rc":[{"trd":[[1.31,624.66]],"batb":[[0,1.31,418.43]],"ltp":1.31,"tv":24258.39,"id":8681938}],"tv":27563.81}]}
{"op":"mcm","clk":"4297110739","pt":1632571848897,"mc":[{"id":"1.188134680","rc":[{"trd":[[1.32,112.07]],"batl":[[0,1.32,37.83]],"ltp":1.32,"tv":24274.82,"id":8681938}],"tv":27580.25}]}
{"op":"mcm","clk":"4297110875","pt":1632571849503,"mc":[{"id":"1.188134680","rc":[{"trd":[[1.31,625.28]],"batb":[[0,1.31,418.12]],"ltp":1.31,"tv":24275.45,"id":8681938}],"tv":27580.87}]}
{"op":"mcm","clk":"4297111928","pt":1632571854333,"mc":[{"id":"1.188134680","rc":[{"batl":[[1,1.33,25.3]],"ltp":1.31,"tv":24275.45,"id":8681938}]}]}
{"op":"mcm","clk":"4297112588","pt":1632571857245,"mc":[{"id":"1.188134680","rc":[{"batl":[[0,1.32,53.41]],"ltp":1.31,"tv":24275.45,"id":8681938}]}]}
{"op":"mcm","clk":"4297119467","pt":1632571889984,"mc":[{"id":"1.188134680","rc":[{"trd":[[1.31,675]],"batb":[[0,1.31,393.26]],"ltp":1.31,"tv":24325.16,"id":8681938}],"tv":27630.59}]}
{"op":"mcm","clk":"4297121287","pt":1632571898315,"mc":[{"id":"1.188134680","rc":[{"trd":[[1.31,675.08]],"batb":[[0,1.31,393.22]],"ltp":1.31,"tv":24325.24,"id":8681938}],"tv":27630.67}]}
{"op":"mcm","clk":"4297123809","pt":1632571910017,"mc":[{"id":"1.188134680","rc":[{"batb":[[0,3.9,20.68],[1,3.4,216.04],[2,3.35,153.64]],"batl":[[0,4.5,119.62],[1,4.6,131.22],[2,5.8,2.54]],"ltp":4.2,"tv":3305.42,"id":9631939},{"batb":[[0,1.28,1001.95],[1,1.27,1205.79],[2,1.26,400]],"batl":[[0,1.32,15.58],[1,1.35,60],[2,1.42,254.13]],"ltp":1.31,"tv":24325.24,"id":8681938}]}]}
{"op":"mcm","clk":"4297124103","pt":1632571911262,"mc":[{"id":"1.188134680","rc":[{"batb":[[0,3.4,216.04],[1,3.35,153.64],[2,2.62,386.89]],"batl":[[1,4.6,123.32]],"ltp":4.2,"tv":3305.42,"id":9631939},{"batb":[[0,1.28,888.57]],"batl":[[1,1.42,254.13],[2,1.43,309.35]],"ltp":1.31,"tv":24325.24,"id":8681938}]}]}
{"op":"mcm","clk":"4297124640","pt":1632571913376,"mc":[{"id":"1.188134680","rc":[{"batb":[[0,3.7,2],[1,3.55,2],[2,3.4,216.04]],"batl":[[2,4.9,2]],"ltp":4.2,"tv":3305.42,"id":9631939},{"trd":[[1.32,132.07]],"batb":[[2,1.26,448.48]],"batl":[[0,1.32,5.58],[1,1.37,36.13],[2,1.39,29.5]],"ltp":1.32,"tv":24345.24,"id":8681938}],"tv":27650.67}]}
{"op":"mcm","clk":"4297124951","pt":1632571914842,"mc":[{"id":"1.188134680","rc":[{"trd":[[1.32,143.23]],"batb":[[0,1.32,407.97],[1,1.31,670.9],[2,1.28,888.57]],"batl":[[0,1.35,707.19],[1,1.36,540.52],[2,1.37,36.13]],"ltp":1.32,"tv":24356.4,"id":8681938}],"tv":27661.82}]}
{"op":"mcm","clk":"4297125192","pt":1632571916053,"mc":[{"id":"1.188134680","rc":[{"batb":[[0,3.75,10],[1,3.7,2],[2,3.55,2]],"batl":[[0,4.4,30.9],[1,4.5,119.62],[2,4.6,123.32]],"ltp":4.2,"tv":3305.42,"id":9631939},{"batb":[[2,1.3,90.44]],"ltp":1.32,"tv":24356.4,"id":8681938}]}]}
{"op":"mcm","clk":"4297125346","pt":1632571916763,"mc":[{"id":"1.188134680","rc":[{"batb":[[2,1.28,888.57]],"ltp":1.32,"tv":24356.4,"id":8681938}]}]}
{"op":"mcm","clk":"4297125683","pt":1632571918344,"mc":[{"id":"1.188134680","rc":[{"batb":[[0,3.55,2],[1,3.4,216.04],[2,3.35,153.64]],"batl":[[0,4.5,119.62],[1,4.6,123.32],[2,4.9,2]],"ltp":4.2,"tv":3305.42,"id":9631939},{"batb":[[0,1.28,888.57],[1,1.27,1205.79],[2,1.26,448.48]],"batl":[[0,1.39,30.13],[1,1.42,253.5],[2,1.43,309.35]],"ltp":1.32,"tv":24356.4,"id":8681938}]}]}
{"op":"mcm","clk":"4297126335","pt":1632571921249,"mc":[{"id":"1.188134680","rc":[{"batb":[[0,1.29,346.07],[1,1.28,1648.92],[2,1.27,1205.79]],"batl":[[0,1.37,7.63],[1,1.39,29.5],[2,1.4,645.45]],"ltp":1.32,"tv":24356.4,"id":8681938}]}]}
{"op":"mcm","clk":"4297126569","pt":1632571922299,"mc":[{"id":"1.188134680","rc":[{"batb":[[0,3.55,4],[1,3.5,3],[2,3.4,216.04]],"ltp":4.2,"tv":3305.42,"id":9631939},{"batl":[[1,1.38,9],[2,1.39,36.5]],"ltp":1.32,"tv":24356.4,"id":8681938}]}]}
{"op":"mcm","clk":"4297127399","pt":1632571925961,"mc":[{"id":"1.188134680","rc":[{"batb":[[0,3.6,3],[1,3.55,4],[2,3.5,3]],"ltp":4.2,"tv":3305.42,"id":9631939}]}]}
{"op":"mcm","clk":"4297128134","pt":1632571929355,"mc":[{"id":"1.188134680","rc":[{"batb":[[0,4,43.5],[1,3.7,2],[2,3.6,3]],"batl":[[0,4.4,43],[1,4.5,119.62],[2,4.6,123.32]],"ltp":4.2,"tv":3305.42,"id":9631939},{"batb":[[1,1.28,1671.29]],"batl":[[0,1.3,23.56],[1,1.33,2875.94],[2,1.34,2791.36]],"ltp":1.32,"tv":24356.4,"id":8681938}]}]}
{"op":"mcm","clk":"4297128340","pt":1632571930371,"mc":[{"id":"1.188134680","rc":[{"batb":[[0,4.3,2.28],[1,4,195.61],[2,3.65,96.22]],"batl":[[2,4.6,129.84]],"ltp":4.2,"tv":3305.42,"id":9631939},{"batb":[[2,1.27,1763.23]],"batl":[[0,1.3,45.61],[1,1.31,341.48],[2,1.32,632.22]],"ltp":1.32,"tv":24356.4,"id":8681938}]}]}
{"op":"mcm","clk":"4297128528","pt":1632571931246,"mc":[{"id":"1.188134680","rc":[{"batb":[[1,4.1,19.35],[2,4,195.61]],"ltp":4.2,"tv":3305.42,"id":9631939},{"batl":[[2,1.32,692.22]],"ltp":1.32,"tv":24356.4,"id":8681938}]}]}
{"op":"mcm","clk":"4297128642","pt":1632571931767,"mc":[{"id":"1.188134680","rc":[{"batl":[[1,4.5,134.2]],"ltp":4.2,"tv":3305.42,"id":9631939},{"batb":[[0,1.29,385.83]],"ltp":1.32,"tv":24356.4,"id":8681938}]}]}
{"op":"mcm","clk":"4297129520","pt":1632571936181,"mc":[{"id":"1.188134680","rc":[{"batb":[[2,4,197.61]],"ltp":4.2,"tv":3305.42,"id":9631939},{"batb":[[2,1.27,1807.1]],"ltp":1.32,"tv":24356.4,"id":8681938}]}]}
{"op":"mcm","clk":"4297129619","pt":1632571936677,"mc":[{"id":"1.188134680","rc":[{"batb":[[2,1.27,2209.65]],"ltp":1.32,"tv":24356.4,"id":8681938}]}]}
{"op":"mcm","clk":"4297129873","pt":1632571937662,"mc":[{"id":"1.188134680","rc":[{"trd":[[1.29,557.96]],"batb":[[0,1.29,383.01]],"ltp":1.29,"tv":24362.04,"id":8681938}],"tv":27667.46}]}
{"op":"mcm","clk":"4297130466","pt":1632571940339,"mc":[{"id":"1.188134680","rc":[{"batb":[[0,4.1,19.35],[1,4,2],[2,3.9,2]],"batl":[[0,4.7,84.18],[1,4.8,124.51],[2,4.9,2]],"ltp":4.2,"tv":3305.42,"id":9631939},{"batb":[[0,1.27,1803.87],[1,1.26,860.55],[2,1.25,600]],"batl":[[0,1.32,60],[1,1.33,32.5],[2,1.34,38.75]],"ltp":1.29,"tv":24362.04,"id":8681938}]}]}
{"op":"mcm","clk":"4297130681","pt":1632571941374,"mc":[{"id":"1.188134680","rc":[{"batb":[[0,4,2],[1,3.9,2],[2,3.75,3]],"ltp":4.2,"tv":3305.42,"id":9631939},{"batl":[[0,1.33,32.5],[1,1.34,38.75],[2,1.36,6]],"ltp":1.29,"tv":24362.04,"id":8681938}]}]}
{"op":"mcm","clk":"4297130758","pt":1632571941682,"mc":[{"id":"1.188134680","rc":[{"batb":[[0,3.9,2],[1,3.75,3],[2,3.7,3]],"ltp":4.2,"tv":3305.42,"id":9631939},{"batl":[[0,1.34,38.75],[1,1.36,6],[2,1.38,310.08]],"ltp":1.29,"tv":24362.04,"id":8681938}]}]}
{"op":"mcm","clk":"4297131102","pt":1632571943311,"mc":[{"id":"1.188134680","rc":[{"batb":[[0,1.27,2073.84],[1,1.26,2265.88]],"batl":[[1,1.36,688.21],[2,1.37,523.11]],"ltp":1.29,"tv":24362.04,"id":8681938}]}]}
{"op":"mcm","clk":"4297131289","pt":1632571944212,"mc":[{"id":"1.188134680","rc":[{"batb":[[2,3.65,211.71]],"ltp":4.2,"tv":3305.42,"id":9631939}]}]}
{"op":"mcm","clk":"4297131542","pt":1632571945295,"mc":[{"id":"1.188134680","rc":[{"batb":[[0,3.9,5],[1,3.85,2],[2,3.75,3]],"ltp":4.2,"tv":3305.42,"id":9631939},{"batl":[[0,1.34,46.75]],"ltp":1.29,"tv":24362.04,"id":8681938}]}]}
{"op":"mcm","clk":"4297131997","pt":1632571947185,"mc":[{"id":"1.188134680","rc":[{"batl":[[0,4.6,2],[1,4.7,84.18],[2,4.8,124.51]],"ltp":4.2,"tv":3305.42,"id":9631939},{"batb":[[0,1.28,43.66],[1,1.27,1246.42],[2,1.26,1422.98]],"batl":[[1,1.36,6],[2,1.38,310.08]],"ltp":1.29,"tv":24362.04,"id":8681938}]}]}
{"op":"mcm","clk":"4297132073","pt":1632571947597,"mc":[{"id":"1.188134680","rc":[{"batl":[[0,4.7,84.18],[1,4.8,124.51],[2,4.9,2]],"ltp":4.2,"tv":3305.42,"id":9631939},{"batb":[[0,1.27,1246.42],[1,1.26,1422.98],[2,1.25,600]],"ltp":1.29,"tv":24362.04,"id":8681938}]}]}
{"op":"mcm","clk":"4297132494","pt":1632571949622,"mc":[{"id":"1.188134680","rc":[{"batl":[[0,4.4,18.89],[1,4.7,84.18],[2,4.8,124.51]],"ltp":4.2,"tv":3305.42,"id":9631939},{"batb":[[0,1.3,20.08],[1,1.29,921.95],[2,1.28,771.01]],"batl":[[0,1.31,21.5],[1,1.32,436.61],[2,1.33,606.97]],"ltp":1.29,"tv":24362.04,"id":8681938}]}]}
{"op":"mcm","clk":"4297132876","pt":1632571951295,"mc":[{"id":"1.188134680","rc":[{"batb":[[0,3.95,19.52],[1,3.9,5],[2,3.85,2]],"batl":[[0,4.6,2]],"ltp":4.2,"tv":3305.42,"id":9631939},{"batb":[[0,1.29,921.95],[1,1.28,813.17],[2,1.27,1246.42]],"batl":[[0,1.32,436.61],[1,1.33,644.21],[2,1.34,46.75]],"ltp":1.29,"tv":24362.04,"id":8681938}]}]}
{"op":"mcm","clk":"4297133157","pt":1632571952377,"mc":[{"id":"1.188134680","rc":[{"batb":[[0,4,2]],"ltp":4.2,"tv":3305.42,"id":9631939},{"batl":[[1,1.33,646.47]],"ltp":1.29,"tv":24362.04,"id":8681938}]}]}
{"op":"mcm","clk":"4297133217","pt":1632571952724,"mc":[{"id":"1.188134680","rc":[{"batb":[[0,3.9,5],[1,3.85,2],[2,3.75,3]],"batl":[[0,4.7,84.18],[1,4.8,124.51],[2,4.9,2]],"ltp":4.2,"tv":3305.42,"id":9631939},{"batb":[[0,1.27,1246.42],[1,1.26,1422.98],[2,1.25,600]],"batl":[[0,1.34,46.75],[1,1.36,6],[2,1.38,310.08]],"ltp":1.29,"tv":24362.04,"id":8681938}]}]}
{"op":"mcm","clk":"4297133679","pt":1632571954911,"mc":[{"id":"1.188134680","rc":[{"batl":[[0,1.34,47.38]],"ltp":1.29,"tv":24362.04,"id":8681938}]}]}
{"op":"mcm","clk":"4297133973","pt":1632571956326,"mc":[{"id":"1.188134680","rc":[{"batb":[[1,3.65,211.71],[2,3.6,120.35]],"ltp":4.2,"tv":3305.42,"id":9631939},{"batb":[[0,1.27,2073.84],[1,1.26,2265.88]],"batl":[[1,1.36,682.21],[2,1.37,523.11]],"ltp":1.29,"tv":24362.04,"id":8681938}]}]}
{"op":"mcm","clk":"4297134171","pt":1632571957197,"mc":[{"id":"1.188134680","rc":[{"batl":[[0,4.8,2],[1,4.9,2],[2,5.5,117.37]],"ltp":4.2,"tv":3305.42,"id":9631939},{"batb":[[0,1.27,843.87],[1,1.26,1010.91]],"ltp":1.29,"tv":24362.04,"id":8681938}]}]}
{"op":"mcm","clk":"4297134825","pt":1632571960166,"mc":[{"id":"1.188134680","rc":[{"trd":[[4,86.29]],"batb":[[0,3.9,8.32],[1,3.65,473.69],[2,3.6,374.63]],"batl":[[0,4,54.7],[1,4.1,15.3],[2,4.8,2]],"ltp":4.0,"tv":3322.76,"id":9631939},{"trd":[[1.33,272.09]],"batb":[[0,1.33,377.67],[1,1.32,1368.58],[2,1.31,1757.81]],"batl":[[0,1.34,38.75]],"ltp":1.33,"tv":24402.17,"id":8681938}],"tv":27724.93}]}
{"op":"mcm","clk":"4297135058","pt":1632571961315,"mc":[{"id":"1.188134680","rc":[{"batb":[[1,3.7,22.22],[2,3.65,473.69]],"batl":[[2,4.4,8.13]],"ltp":4.0,"tv":3322.76,"id":9631939},{"batb":[[0,1.33,813.02],[2,1.31,703.12]],"batl":[[2,1.37,583.11]],"ltp":1.33,"tv":24402.17,"id":8681938}]}]}
{"op":"mcm","clk":"4297135851","pt":1632571965116,"mc":[{"id":"1.188134680","rc":[{"batl":[[2,4.6,10]],"ltp":4.0,"tv":3322.76,"id":9631939},{"batb":[[0,1.33,855.55]],"ltp":1.33,"tv":24402.17,"id":8681938}]}]}
{"op":"mcm","clk":"4297136081","pt":1632571966267,"mc":[{"id":"1.188134680","rc":[{"trd":[[1.33,292.09]],"batb":[[0,1.33,845.55]],"ltp":1.33,"tv":24422.17,"id":8681938}],"tv":27744.93}]}
{"op":"mcm","clk":"4297136278","pt":1632571967102,"mc":[{"id":"1.188134680","rc":[{"batl":[[2,4.5,89.13]],"ltp":4.0,"tv":3322.76,"id":9631939}]}]}
{"op":"mcm","clk":"4297136531","pt":1632571968285,"mc":[{"id":"1.188134680","rc":[{"batl":[[2,4.3,8.25]],"ltp":4.0,"tv":3322.76,"id":9631939}]}]}
{"op":"mcm","clk":"4297137177","pt":1632571971348,"mc":[{"id":"1.188134680","rc":[{"batb":[[0,3.9,2],[2,3.65,211.71]],"batl":[[0,4.3,8.25],[1,4.5,89.13],[2,4.6,129.31]],"ltp":4.0,"tv":3322.76,"id":9631939},{"batb":[[1,1.32,644.14],[2,1.3,645.86]],"ltp":1.33,"tv":24422.17,"id":8681938}]}]}
{"op":"mcm","clk":"4297137303","pt":1632571971818,"mc":[{"id":"1.188134680","rc":[{"batb":[[0,3.7,22.22],[1,3.35,2.04],[2,3.2,125.47]],"batl":[[2,4.6,119.31]],"ltp":4.0,"tv":3322.76,"id":9631939},{"batb":[[0,1.3,595.62],[1,1.29,370.97],[2,1.28,439.18]],"batl":[[0,1.37,60.63],[1,1.42,28.75],[2,1.45,301.48]],"ltp":1.33,"tv":24422.17,"id":8681938}]}]}
{"op":"mcm","clk":"4297137614","pt":1632571973320,"mc":[{"id":"1.188134680","rc":[{"batb":[[0,3.35,2.04],[1,3.2,125.47],[2,3.15,136.38]],"batl":[[0,4.5,89.13],[1,4.6,119.31],[2,4.8,2]],"ltp":4.0,"tv":3322.76,"id":9631939},{"batb":[[0,1.3,486.08]],"batl":[[0,1.33,7.05],[1,1.42,29.38]],"ltp":1.33,"tv":24422.17,"id":8681938}]}]}
{"op":"mcm","clk":"4297138033","pt":1632571975323,"mc":[{"id":"1.188134680","rc":[{"batb":[[2,3.15,275.97]],"ltp":4.0,"tv":3322.76,"id":9631939},{"batb":[[0,1.29,864.84],[1,1.28,439.18],[2,1.27,853.87]],"ltp":1.33,"tv":24422.17,"id":8681938}]}]}
{"op":"mcm","clk":"4297138378","pt":1632571977026,"mc":[{"id":"1.188134680","rc":[{"trd":[[4,88.63]],"ltp":4.0,"tv":3325.1,"id":9631939},{"trd":[[1.33,299.14]],"batb":[[0,1.34,700.08],[1,1.33,624.14],[2,1.29,864.84]],"batl":[[0,1.37,324.81],[1,1.38,509.45],[2,1.42,28.75]],"ltp":1.33,"tv":24429.21,"id":8681938}],"tv":27754.32}]}
{"op":"mcm","clk":"4297138651","pt":1632571978191,"mc":[{"id":"1.188134680","rc":[{"batb":[[0,3.4,10.2],[1,3.35,2.04],[2,3.2,125.47]],"batl":[[0,4.4,46.6],[1,4.5,89.13],[2,4.6,119.31]],"ltp":4.0,"tv":3325.1,"id":9631939},{"batb":[[2,1.3,144.07]],"ltp":1.33,"tv":24429.21,"id":8681938}]}]}
{"op":"mcm","clk":"4297138715","pt":1632571978517,"mc":[{"id":"1.188134680","rc":[{"batb":[[2,1.29,864.84]],"ltp":1.33,"tv":24429.21,"id":8681938}]}]}
{"op":"mcm","clk":"4297139085","pt":1632571980327,"mc":[{"id":"1.188134680","rc":[{"batb":[[2,1.3,68.53]],"batl":[[0,1.36,175],[1,1.37,324.81],[2,1.38,509.45]],"ltp":1.33,"tv":24429.21,"id":8681938}]}]}
{"op":"mcm","clk":"4297139256","pt":1632571981030,"mc":[{"id":"1.188134680","rc":[{"batb":[[0,3.35,2.04],[1,3.2,125.47],[2,3.15,275.97]],"batl":[[0,4.5,89.13],[1,4.6,119.31],[2,4.8,2]],"ltp":4.0,"tv":3325.1,"id":9631939},{"batb":[[0,1.3,68.53],[1,1.29,864.84],[2,1.28,439.18]],"batl":[[1,1.42,29.38],[2,1.45,301.48]],"ltp":1.33,"tv":24429.21,"id":8681938}]}]}
{"op":"mcm","clk":"4297139456","pt":1632571981919,"mc":[{"id":"1.188134680","rc":[{"batb":[[0,3.2,125.47],[1,3.15,275.97],[2,2.62,386.89]],"ltp":4.0,"tv":3325.1,"id":9631939},{"batl":[[0,1.45,302.11],[1,1.46,329.12],[2,1.93,2.55]],"ltp":1.33,"tv":24429.21,"id":8681938}]}]}
{"op":"mcm","clk":"4297139877","pt":1632571983901,"mc":[{"id":"1.188134680","rc":[{"batb":[[0,1.3,557.85],[1,1.29,1595.47]],"batl":[[0,1.45,979.07],[1,1.46,723.99]],"ltp":1.33,"tv":24429.21,"id":8681938}]}]}
{"op":"mcm","clk":"4297140171","pt":1632571985221,"mc":[{"id":"1.188134680","rc":[{"batb":[[0,3.35,2.07],[1,3.2,128.47],[2,3.15,278.97]],"ltp":4.0,"tv":3325.1,"id":9631939},{"batl":[[0,1.42,32.88],[1,1.43,7],[2,1.45,985.44]],"ltp":1.33,"tv":24429.21,"id":8681938}]}]}
{"op":"mcm","clk":"4297140208","pt":1632571985433,"mc":[{"id":"1.188134680","rc":[{"batb":[[0,3.2,128.47],[1,3.15,278.97],[2,2.62,386.89]],"ltp":4.0,"tv":3325.1,"id":9631939},{"batl":[[0,1.43,7.63],[1,1.45,985.44],[2,1.46,723.99]],"ltp":1.33,"tv":24429.21,"id":8681938}]}]}
{"op":"mcm","clk":"4297140647","pt":1632571987382,"mc":[{"id":"1.188134680","rc":[{"batl":[[0,1.34,7.05],[1,1.43,7.63],[2,1.45,308.48]],"ltp":1.33,"tv":24429.21,"id":8681938}]}]}
{"op":"mcm","clk":"4297140673","pt":1632571987493,"mc":[{"id":"1.188134680","rc":[{"batb":[[0,3.2,5.02],[1,3.15,142.59]],"ltp":4.0,"tv":3325.1,"id":9631939},{"batl":[[2,1.45,32.5]],"ltp":1.33,"tv":24429.21,"id":8681938}]}]}
{"op":"mcm","clk":"4297141067","pt":1632571989008,"mc":[{"id":"1.188134680","rc":[{"batb":[[0,3.25,3],[1,3.2,5.02],[2,3.15,142.59]],"ltp":4.0,"tv":3325.1,"id":9631939},{"batb":[[0,1.3,489.32]],"ltp":1.33,"tv":24429.21,"id":8681938}]}]}
{"op":"mcm","clk":"4297141371","pt":1632571990316,"mc":[{"id":"1.188134680","rc":[{"batb":[[0,3.9,1043.93],[1,3.85,951.92],[2,3.8,951.92]],"batl":[[0,4.4,61.7],[1,4.5,89.13],[2,4.6,119.31]],"ltp":4.0,"tv":3325.1,"id":9631939},{"batb":[[1,1.29,1614.09],[2,1.28,3427.46]],"batl":[[0,1.31,25.28],[1,1.33,766.6],[2,1.34,579.96]],"ltp":1.33,"tv":24429.21,"id":8681938}]}]}
{"op":"mcm","clk":"4297141571","pt":1632571991231,"mc":[{"id":"1.188134680","rc":[{"batb":[[0,3.9,470.01],[1,3.85,237.98],[2,3.8,237.98]],"batl":[[0,4.4,78.87],[1,4.5,95.8]],"ltp":4.0,"tv":3325.1,"id":9631939},{"batb":[[0,1.3,532.82],[2,1.28,1733.27]],"batl":[[2,1.34,615.21]],"ltp":1.33,"tv":24429.21,"id":8681938}]}]}
{"op":"mcm","clk":"4297141842","pt":1632571992329,"mc":[{"id":"1.188134680","rc":[{"batb":[[0,3.95,20.33],[1,3.9,470.01],[2,3.85,237.98]],"batl":[[2,4.6,127.21]],"ltp":4.0,"tv":3325.1,"id":9631939},{"batl":[[2,1.34,675.21]],"ltp":1.33,"tv":24429.21,"id":8681938}]}]}
{"op":"mcm","clk":"4297142613","pt":1632571995341,"mc":[{"id":"1.188134680","rc":[{"batb":[[0,3.95,45.43]],"ltp":4.0,"tv":3325.1,"id":9631939}]}]}
{"op":"mcm","clk":"4297143045","pt":1632571997250,"mc":[{"id":"1.188134680","rc":[{"batb":[[0,3.95,80.61],[2,3.85,239.98]],"batl":[[2,4.6,129.21]],"ltp":4.0,"tv":3325.1,"id":9631939},{"batb":[[2,1.28,1770.93]],"ltp":1.33,"tv":24429.21,"id":8681938}]}]}
{"op":"mcm","clk":"4297143131","pt":1632571997561,"mc":[{"id":"1.188134680","rc":[{"batl":[[2,4.6,238.59]],"ltp":4.0,"tv":3325.1,"id":9631939}]}]}
{"op":"mcm","clk":"4297144334","pt":1632572002844,"mc":[{"id":"1.188134680","rc":[{"trd":[[1.31,725.64]],"batb":[[0,1.3,533.51]],"batl":[[0,1.33,766.6],[1,1.34,675.21],[2,1.35,37.3]],"ltp":1.31,"tv":24479.77,"id":8681938}],"tv":27804.88}]}
{"op":"mcm","clk":"4297144464","pt":1632572003457,"mc":[{"id":"1.188134680","rc":[{"batb":[[0,3.95,45.43]],"ltp":4.0,"tv":3325.1,"id":9631939}]}]}
{"op":"mcm","clk":"4297145089","pt":1632572006154,"mc":[{"id":"1.188134680","rc":[{"batl":[[0,1.32,435],[1,1.33,766.6],[2,1.34,675.21]],"ltp":1.31,"tv":24479.77,"id":8681938}]}]}
{"op":"mcm","clk":"4297146271","pt":1632572011237,"mc":[{"id":"1.188134680","rc":[{"batb":[[0,1.3,532.82]],"ltp":1.31,"tv":24479.77,"id":8681938}]}]}
{"op":"mcm","clk":"4297146655","pt":1632572013072,"mc":[{"id":"1.188134680","rc":[{"batb":[[1,1.29,1595.47]],"ltp":1.31,"tv":24479.77,"id":8681938}]}]}
{"op":"mcm","clk":"4297147062","pt":1632572014978,"mc":[{"id":"1.188134680","rc":[{"batb":[[0,3.95,20.33],[1,3.85,2],[2,3.75,2.03]],"batl":[[0,4.6,119.28],[1,4.7,108.86],[2,4.8,2]],"ltp":4.0,"tv":3325.1,"id":9631939},{"batb":[[0,1.28,584.69],[1,1.27,1324.51],[2,1.26,1013.07]],"batl":[[1,1.34,60],[2,1.35,37.3]],"ltp":1.31,"tv":24479.77,"id":8681938}]}]}
{"op":"mcm","clk":"4297147364","pt":1632572016239,"mc":[{"id":"1.188134680","rc":[{"batb":[[0,3.85,2],[1,3.75,2.03],[2,3.7,2]],"batl":[[0,4.6,111.38]],"ltp":4.0,"tv":3325.1,"id":9631939},{"batb":[[1,1.27,1209.04]],"batl":[[0,1.35,37.3],[1,1.36,32.82],[2,1.37,39.13]],"ltp":1.31,"tv":24479.77,"id":8681938}]}]}
{"op":"mcm","clk":"4297147410","pt":1632572016463,"mc":[{"id":"1.188134680","rc":[{"batb":[[0,3.7,2],[1,3.5,209.89],[2,3.45,115.6]],"ltp":4.0,"tv":3325.1,"id":9631939},{"batl":[[0,1.37,39.13],[1,1.4,345.05],[2,1.41,303.87]],"ltp":1.31,"tv":24479.77,"id":8681938}]}]}
{"op":"mcm","clk":"4297147793","pt":1632572018151,"mc":[{"id":"1.188134680","rc":[{"batb":[[0,1.28,1215.44],[1,1.27,2009.9]],"batl":[[1,1.38,377.5],[2,1.39,492.17]],"ltp":1.31,"tv":24479.77,"id":8681938}]}]}
{"op":"mcm","clk":"4297148043","pt":1632572019167,"mc":[{"id":"1.188134680","rc":[{"batb":[[0,1.28,584.69],[1,1.27,1209.04]],"batl":[[1,1.4,345.05],[2,1.41,303.87]],"ltp":1.31,"tv":24479.77,"id":8681938}]}]}
{"op":"mcm","clk":"4297148251","pt":1632572020046,"mc":[{"id":"1.188134680","rc":[{"batb":[[0,3.7,5],[1,3.65,3],[2,3.5,209.89]],"ltp":4.0,"tv":3325.1,"id":9631939},{"batl":[[0,1.37,48.13]],"ltp":1.31,"tv":24479.77,"id":8681938}]}]}
{"op":"mcm","clk":"4297148396","pt":1632572020754,"mc":[{"id":"1.188134680","rc":[{"batb":[[0,1.29,70.89],[1,1.28,584.69],[2,1.27,1209.04]],"ltp":1.31,"tv":24479.77,"id":8681938}]}]}
{"op":"mcm","clk":"4297148676","pt":1632572022057,"mc":[{"id":"1.188134680","rc":[{"batl":[[0,4.3,21.55],[1,4.6,111.38],[2,4.7,108.86]],"ltp":4.0,"tv":3325.1,"id":9631939},{"batb":[[0,1.31,509.44],[1,1.3,700.37],[2,1.29,70.89]],"batl":[[0,1.33,18.5],[1,1.34,699.33],[2,1.35,560.21]],"ltp":1.31,"tv":24479.77,"id":8681938}]}]}
{"op":"mcm","clk":"4297148938","pt":1632572023254,"mc":[{"id":"1.188134680","rc":[{"batb":[[0,3.85,2],[1,3.7,5],[2,3.65,3]],"batl":[[0,4.6,111.38],[1,4.7,108.86],[2,4.8,2]],"ltp":4.0,"tv":3325.1,"id":9631939},{"batb":[[0,1.31,489.36]],"batl":[[0,1.34,699.33],[1,1.35,597.31],[2,1.36,9]],"ltp":1.31,"tv":24479.77,"id":8681938}]}]}
{"op":"mcm","clk":"4297149525","pt":1632572025886,"mc":[{"id":"1.188134680","rc":[{"batb":[[0,3.7,5],[1,3.65,3],[2,3.5,209.89]],"ltp":4.0,"tv":3325.1,"id":9631939},{"batb":[[0,1.29,70.89],[1,1.28,584.69],[2,1.27,1209.04]],"batl":[[0,1.36,9],[1,1.37,48.13],[2,1.4,345.05]],"ltp":1.31,"tv":24479.77,"id":8681938}]}]}
{"op":"mcm","clk":"4297150103","pt":1632572028295,"mc":[{"id":"1.188134680","rc":[{"batb":[[2,3.5,107.55]],"ltp":4.0,"tv":3325.1,"id":9631939},{"batl":[[2,1.43,7]],"ltp":1.31,"tv":24479.77,"id":8681938}]}]}
{"op":"mcm","clk":"4297150345","pt":1632572029381,"mc":[{"id":"1.188134680","rc":[{"batb":[[0,3.75,3],[1,3.7,5],[2,3.65,3]],"ltp":4.0,"tv":3325.1,"id":9631939},{"batb":[[1,1.28,1215.44],[2,1.27,2009.9]],"ltp":1.31,"tv":24479.77,"id":8681938}]}]}
{"op":"mcm","clk":"4297150509","pt":1632572030085,"mc":[{"id":"1.188134680","rc":[{"batb":[[0,1.28,1215.44],[1,1.27,2009.9],[2,1.26,933.99]],"ltp":1.31,"tv":24479.77,"id":8681938}]}]}
{"op":"mcm","clk":"4297150782","pt":1632572031312,"mc":[{"id":"1.188134680","rc":[{"batb":[[0,4.4,6.18],[1,3.75,3],[2,3.7,2]],"batl":[[1,4.7,177.78],[2,4.8,500.05]],"ltp":4.0,"tv":3325.1,"id":9631939},{"batl":[[0,1.31,784.48],[1,1.32,1582.49],[2,1.33,1780.37]],"ltp":1.31,"tv":24479.77,"id":8681938}]}]}
{"op":"mcm","clk":"4297151032","pt":1632572032314,"mc":[{"id":"1.188134680","rc":[{"batb":[[1,4.1,143.65],[2,3.8,86.24]],"batl":[[2,4.8,201.22]],"ltp":4.0,"tv":3325.1,"id":9631939},{"batb":[[2,1.26,1503.28]],"batl":[[2,1.33,725.68]],"ltp":1.31,"tv":24479.77,"id":8681938}]}]}
{"op":"mcm","clk":"4297151295","pt":1632572033375,"mc":[{"id":"1.188134680","rc":[{"batb":[[2,4,20]],"ltp":4.0,"tv":3325.1,"id":9631939},{"batb":[[2,1.26,1620.94]],"batl":[[2,1.33,785.68]],"ltp":1.31,"tv":24479.77,"id":8681938}]}]}
{"op":"mcm","clk":"4297151493","pt":1632572034171,"mc":[{"id":"1.188134680","rc":[{"batb":[[2,4,23]],"batl":[[0,4.6,126.7]],"ltp":4.0,"tv":3325.1,"id":9631939},{"batb":[[0,1.28,1264.55]],"ltp":1.31,"tv":24479.77,"id":8681938}]}]}
{"op":"mcm","clk":"4297151966","pt":1632572036286,"mc":[{"id":"1.188134680","rc":[{"batb":[[2,4,3]],"ltp":4.0,"tv":3325.1,"id":9631939},{"batl":[[0,1.3,175],[1,1.31,784.48],[2,1.32,1582.49]],"ltp":1.31,"tv":24479.77,"id":8681938}]}]}
{"op":"mcm","clk":"4297152367","pt":1632572038343,"mc":[{"id":"1.188134680","rc":[{"batb":[[1,4.2,2],[2,4.1,145.65]],"batl":[[1,4.7,281.09],[2,4.8,317.3]],"ltp":4.0,"tv":3325.1,"id":9631939},{"batb":[[1,1.27,2381.79],[2,1.26,2073.85]],"batl":[[1,1.31,828.98],[2,1.32,1617.6]],"ltp":1.31,"tv":24479.77,"id":8681938}]}]}
{"op":"mcm","clk":"4297152512","pt":1632572039009,"mc":[{"id":"1.188134680","rc":[{"batb":[[2,1.26,2152.93]],"batl":[[0,1.3,329]],"ltp":1.31,"tv":24479.77,"id":8681938}]}]}
{"op":"mcm","clk":"4297152684","pt":1632572039812,"mc":[{"id":"1.188134680","rc":[{"batb":[[2,4.1,165]],"ltp":4.0,"tv":3325.1,"id":9631939},{"batl":[[2,1.32,1677.6]],"ltp":1.31,"tv":24479.77,"id":8681938}]}]}
{"op":"mcm","clk":"4297153036","pt":1632572041315,"mc":[{"id":"1.188134680","rc":[{"batb":[[0,4.2,2],[1,4.1,165],[2,4,3]],"batl":[[1,4.7,212.17],[2,4.8,118.08]],"ltp":4.0,"tv":3325.1,"id":9631939},{"batl":[[2,1.32,720.15]],"ltp":1.31,"tv":24479.77,"id":8681938}]}]}
{"op":"mcm","clk":"4297153197","pt":1632572042016,"mc":[{"id":"1.188134680","rc":[{"batb":[[1,4.1,21.35]],"batl":[[0,4.7,103.31],[1,4.8,118.08],[2,4.9,9.59]],"ltp":4.0,"tv":3325.1,"id":9631939},{"batb":[[0,1.28,10.39],[1,1.27,1900.11],[2,1.26,1667.41]],"batl":[[1,1.31,44.5],[2,1.32,95.11]],"ltp":1.31,"tv":24479.77,"id":8681938}]}]}
{"op":"mcm","clk":"4297153497","pt":1632572043313,"mc":[{"id":"1.188134680","rc":[{"batb":[[0,4.1,2],[1,4,3],[2,3.95,3]],"batl":[[2,4.9,2]],"ltp":4.0,"tv":3325.1,"id":9631939},{"batb":[[2,1.26,1549.75]],"batl":[[0,1.32,35.11],[1,1.35,366.96],[2,1.36,353.22]],"ltp":1.31,"tv":24479.77,"id":8681938}]}]}
{"op":"mcm","clk":"4297153937","pt":1632572045327,"mc":[{"id":"1.188134680","rc":[{"batl":[[0,4.6,2],[1,4.7,106.31],[2,4.8,118.08]],"ltp":4.0,"tv":3325.1,"id":9631939},{"trd":[[1.28,1175.41]],"batb":[[0,1.28,40.71],[2,1.26,2389.51]],"batl":[[1,1.34,838.01],[2,1.35,925.23]],"ltp":1.28,"tv":24507.95,"id":8681938}],"tv":27833.06}]}
{"op":"mcm","clk":"4297154168","pt":1632572046233,"mc":[{"id":"1.188134680","rc":[{"batb":[[0,4.2,3],[1,4.1,5],[2,4,3]],"batl":[[0,4.7,106.31],[1,4.8,118.08],[2,4.9,2]],"ltp":4.0,"tv":3325.1,"id":9631939},{"batb":[[0,1.27,1900.11],[1,1.26,2389.51],[2,1.25,600]],"batl":[[0,1.31,7],[1,1.32,35.11],[2,1.34,838.01]],"ltp":1.28,"tv":24507.95,"id":8681938}]}]}
{"op":"mcm","clk":"4297154418","pt":1632572047271,"mc":[{"id":"1.188134680","rc":[{"batl":[[1,1.32,44.11],[2,1.35,366.96]],"ltp":1.28,"tv":24507.95,"id":8681938}]}]}
{"op":"mcm","clk":"4297154607","pt":1632572048033,"mc":[{"id":"1.188134680","rc":[{"batb":[[0,4.1,5],[1,4,3],[2,3.8,86.24]],"ltp":4.0,"tv":3325.1,"id":9631939},{"batl":[[0,1.36,9],[1,1.44,2.98],[2,1.93,2.55]],"ltp":1.28,"tv":24507.95,"id":8681938}]}]}
{"op":"mcm","clk":"4297154925","pt":1632572049383,"mc":[{"id":"1.188134680","rc":[{"trd":[[1.28,1189.5]],"batb":[[0,1.3,99.15],[1,1.27,1900.11],[2,1.26,2397.51]],"ltp":1.28,"tv":24522.04,"id":8681938}],"tv":27847.15}]}
{"op":"mcm","clk":"4297155147","pt":1632572050375,"mc":[{"id":"1.188134680","rc":[{"batb":[[0,4.2,2],[1,4.1,5],[2,4,3]],"batl":[[1,4.8,167.55]],"ltp":4.0,"tv":3325.1,"id":9631939},{"trd":[[1.3,3358.28]],"batb":[[0,1.27,1900.11],[1,1.26,2397.51],[2,1.25,600]],"batl":[[0,1.28,17.7],[1,1.29,364.34],[2,1.3,1836.78]],"ltp":1.3,"tv":24720.34,"id":8681938}],"tv":28045.44}]}
{"op":"mcm","clk":"4297155361","pt":1632572051352,"mc":[{"id":"1.188134680","rc":[{"batb":[[0,4.2,133.9],[2,4,153.92]],"ltp":4.0,"tv":3325.1,"id":9631939}]}]}
{"op":"mcm","clk":"4297155565","pt":1632572052347,"mc":[{"id":"1.188134680","rc":[{"batb":[[0,4.3,18.18],[1,4.2,153.11],[2,4.1,5]],"batl":[[0,4.7,119.94]],"ltp":4.0,"tv":3325.1,"id":9631939},{"batb":[[0,1.27,1951.3]],"batl":[[2,1.3,1935.73]],"ltp":1.3,"tv":24720.34,"id":8681938}]}]}
{"op":"mcm","clk":"4297155749","pt":1632572053146,"mc":[{"id":"1.188134680","rc":[{"batb":[[0,4.2,153.11],[1,4.1,5],[2,4,153.92]],"ltp":4.0,"tv":3325.1,"id":9631939},{"batl":[[2,1.3,1836.78]],"ltp":1.3,"tv":24720.34,"id":8681938}]}]}
{"op":"mcm","clk":"4297156349","pt":1632572055869,"mc":[{"id":"1.188134680","rc":[{"batb":[[0,4.3,18.18],[1,4.2,153.11],[2,4.1,5]],"ltp":4.0,"tv":3325.1,"id":9631939},{"batb":[[1,1.26,2318.44]],"ltp":1.3,"tv":24720.34,"id":8681938}]}]}
{"op":"mcm","clk":"4297156854","pt":1632572058284,"mc":[{"id":"1.188134680","rc":[{"batb":[[0,1.27,1151.3],[2,1.24,122.47]],"ltp":1.3,"tv":24720.34,"id":8681938}]}]}
{"op":"mcm","clk":"4297157495","pt":1632572061164,"mc":[{"id":"1.188134680","rc":[{"trd":[[1.28,1224.82]],"batl":[[0,1.29,364.38],[1,1.3,1836.78],[2,1.31,930.97]],"ltp":1.28,"tv":24755.66,"id":8681938}],"tv":28080.76}]}
{"op":"mcm","clk":"4297157761","pt":1632572062372,"mc":[{"id":"1.188134680","rc":[{"batb":[[1,1.26,2310.44]],"ltp":1.28,"tv":24755.66,"id":8681938}]}]}
{"op":"mcm","clk":"4297158199","pt":1632572064284,"mc":[{"id":"1.188134680","rc":[{"batb":[[2,1.25,400]],"ltp":1.28,"tv":24755.66,"id":8681938}]}]}
{"op":"mcm","clk":"4297158920","pt":1632572067402,"mc":[{"id":"1.188134680","rc":[{"batl":[[0,1.29,504.38]],"ltp":1.28,"tv":24755.66,"id":8681938}]}]}
{"op":"mcm","clk":"4297159259","pt":1632572068919,"mc":[{"id":"1.188134680","rc":[{"batb":[[1,4.2,133.9]],"ltp":4.0,"tv":3325.1,"id":9631939}]}]}
{"op":"mcm","clk":"4297159789","pt":1632572071310,"mc":[{"id":"1.188134680","rc":[{"batl":[[1,4.8,161.36]],"ltp":4.0,"tv":3325.1,"id":9631939},{"trd":[[1.27,2287.47]],"batb":[[0,1.27,1148.95]],"batl":[[0,1.29,647.34]],"ltp":1.27,"tv":24760.36,"id":8681938}],"tv":28085.46}]}
{"op":"mcm","clk":"4297159930","pt":1632572072003,"mc":[{"id":"1.188134680","rc":[{"batb":[[0,4.3,37.39]],"ltp":4.0,"tv":3325.1,"id":9631939}]}]}
{"op":"mcm","clk":"4297160421","pt":1632572074313,"mc":[{"id":"1.188134680","rc":[{"batb":[[0,4.5,3.71],[1,4.3,37.39],[2,4.2,133.9]],"batl":[[0,4.7,126.23]],"ltp":4.0,"tv":3325.1,"id":9631939}]}]}
{"op":"mcm","clk":"4297160836","pt":1632572076253,"mc":[{"id":"1.188134680","rc":[{"batb":[[0,4.3,18.18],[1,4.2,133.9],[2,4.1,2]],"batl":[[0,5.1,7.4],[1,5.6,101.45],[2,5.7,81.75]],"ltp":4.0,"tv":3325.1,"id":9631939},{"batb":[[0,1.26,969.28],[1,1.25,400],[2,1.24,122.47]],"batl":[[0,1.29,283],[1,1.31,99.5],[2,1.32,38.11]],"ltp":1.27,"tv":24760.36,"id":8681938}]}]}
{"op":"mcm","clk":"4297161058","pt":1632572077348,"mc":[{"id":"1.188134680","rc":[{"batb":[[0,4.2,2],[1,4.1,2],[2,4,152.92]],"batl":[[0,5.6,101.45],[1,5.7,81.75],[2,5.8,4.54]],"ltp":4.0,"tv":3325.1,"id":9631939},{"batb":[[0,1.26,400],[2,1.22,150.79]],"batl":[[1,1.31,39.5]],"ltp":1.27,"tv":24760.36,"id":8681938}]}]}
{"op":"mcm","clk":"4297161173","pt":1632572077906,"mc":[{"id":"1.188134680","rc":[{"batb":[[0,4.1,2],[1,4,150.92],[2,3.85,122.85]],"ltp":4.0,"tv":3325.1,"id":9631939},{"batl":[[0,1.32,38.11],[1,1.35,350.14],[2,1.36,404.62]],"ltp":1.27,"tv":24760.36,"id":8681938}]}]}
{"op":"mcm","clk":"4297161508","pt":1632572079339,"mc":[{"id":"1.188134680","rc":[{"batl":[[0,5.4,2],[1,5.6,101.45],[2,5.7,81.75]],"ltp":4.0,"tv":3325.1,"id":9631939},{"batb":[[2,1.23,48.63]],"ltp":1.27,"tv":24760.36,"id":8681938}]}]}
{"op":"mcm","clk":"4297161681","pt":1632572080144,"mc":[{"id":"1.188134680","rc":[{"batb":[[0,1.23,48.63],[1,1.22,57.34],[2,1.21,1177.84]],"ltp":1.27,"tv":24760.36,"id":8681938}]}]}
{"op":"mcm","clk":"4297161918","pt":1632572081225,"mc":[{"id":"1.188134680","rc":[{"batb":[[0,4.2,2],[1,4.1,2],[2,4,150.92]],"batl":[[0,5.6,99.45],[1,5.7,81.75],[2,5.8,4.54]],"ltp":4.0,"tv":3325.1,"id":9631939},{"batb":[[0,1.26,680.91],[1,1.25,881.13]],"batl":[[0,1.29,911.01],[1,1.3,674.46],[2,1.31,40.5]],"ltp":1.27,"tv":24760.36,"id":8681938}]}]}
{"op":"mcm","clk":"4297162149","pt":1632572082216,"mc":[{"id":"1.188134680","rc":[{"batb":[[0,4.2,12]],"batl":[[0,5.5,37.45],[1,5.6,99.45],[2,5.7,81.75]],"ltp":4.0,"tv":3325.1,"id":9631939},{"batb":[[0,1.26,730.62]],"batl":[[2,1.31,127.81]],"ltp":1.27,"tv":24760.36,"id":8681938}]}]}
{"op":"mcm","clk":"4297162352","pt":1632572083336,"mc":[{"id":"1.188134680","rc":[{"batb":[[0,4.2,2]],"batl":[[0,5.4,3],[1,5.5,37.45],[2,5.6,99.45]],"ltp":4.0,"tv":3325.1,"id":9631939},{"batb":[[2,1.23,10]],"ltp":1.27,"tv":24760.36,"id":8681938}]}]}
{"op":"mcm","clk":"4297162403","pt":1632572083613,"mc":[{"id":"1.188134680","rc":[{"batl":[[0,5.4,5],[1,5.6,101.45],[2,5.7,81.75]],"ltp":4.0,"tv":3325.1,"id":9631939},{"batb":[[2,1.23,56.63]],"ltp":1.27,"tv":24760.36,"id":8681938}]}]}
{"op":"mcm","clk":"4297162631","pt":1632572084636,"mc":[{"id":"1.188134680","rc":[{"batl":[[0,1.29,1007.01]],"ltp":1.27,"tv":24760.36,"id":8681938}]}]}
{"op":"mcm","clk":"4297162932","pt":1632572086067,"mc":[{"id":"1.188134680","rc":[{"batb":[[0,4.3,10],[1,4.2,2],[2,4.1,2]],"ltp":4.0,"tv":3325.1,"id":9631939}]}]}
{"op":"mcm","clk":"4297163137","pt":1632572086939,"mc":[{"id":"1.188134680","rc":[{"batb":[[0,4.2,2],[1,4.1,2],[2,4,150.92]],"batl":[[0,5.4,3]],"ltp":4.0,"tv":3325.1,"id":9631939},{"batb":[[0,1.23,10],[1,1.22,103.45],[2,1.21,1187.84]],"batl":[[0,1.29,96],[1,1.31,40.5],[2,1.32,38.11]],"ltp":1.27,"tv":24760.36,"id":8681938}]}]}
{"op":"mcm","clk":"4297163362","pt":1632572087906,"mc":[{"id":"1.188134680","rc":[{"batb":[[0,4.1,2],[1,4,150.92],[2,3.85,122.85]],"ltp":4.0,"tv":3325.1,"id":9631939},{"batl":[[0,1.32,38.11],[1,1.35,350.14],[2,1.36,404.62]],"ltp":1.27,"tv":24760.36,"id":8681938}]}]}
{"op":"mcm","clk":"4297163892","pt":1632572090337,"mc":[{"id":"1.188134680","rc":[{"batl":[[0,5.3,3],[1,5.4,3],[2,5.6,101.45]],"ltp":4.0,"tv":3325.1,"id":9631939},{"batb":[[1,1.22,984.19],[2,1.21,2280.52]],"batl":[[0,1.32,591.88],[1,1.33,605.2],[2,1.35,350.14]],"ltp":1.27,"tv":24760.36,"id":8681938}]}]}
{"op":"mcm","clk":"4297164113","pt":1632572091336,"mc":[{"id":"1.188134680","rc":[{"batb":[[0,4.2,2],[1,4.1,2],[2,4,150.92]],"batl":[[2,5.6,2]],"ltp":4.0,"tv":3325.1,"id":9631939},{"batb":[[2,1.21,1886.36]],"batl":[[0,1.31,43.5],[1,1.32,553.77],[2,1.33,605.2]],"ltp":1.27,"tv":24760.36,"id":8681938}]}]}
{"op":"mcm","clk":"4297164161","pt":1632572091552,"mc":[{"id":"1.188134680","rc":[{"batb":[[0,4.1,2],[1,4,150.92],[2,3.85,122.85]],"ltp":4.0,"tv":3325.1,"id":9631939},{"batb":[[1,1.22,103.45],[2,1.21,793.68]],"batl":[[0,1.32,553.77],[1,1.33,605.2],[2,1.35,350.14]],"ltp":1.27,"tv":24760.36,"id":8681938}]}]}
{"op":"mcm","clk":"4297164758","pt":1632572094346,"mc":[{"id":"1.188134680","rc":[{"batb":[[0,4.1,5],[1,4,750.58],[2,3.95,232.02]],"batl":[[0,4.3,6.42],[1,4.6,6.52],[2,4.7,134.67]],"ltp":4.0,"tv":3325.1,"id":9631939},{"batb":[[0,1.29,795.9],[1,1.28,1515.81],[2,1.27,725.1]],"batl":[[0,1.32,576.2],[2,1.34,195.57]],"ltp":1.27,"tv":24760.36,"id":8681938}]}]}
{"op":"mcm","clk":"4297164998","pt":1632572095362,"mc":[{"id":"1.188134680","rc":[{"batb":[[0,4.1,2],[1,4,389.98]],"ltp":4.0,"tv":3325.1,"id":9631939},{"batb":[[1,1.28,2034.19]],"batl":[[0,1.32,567.2]],"ltp":1.27,"tv":24760.36,"id":8681938}]}]}
{"op":"mcm","clk":"4297165231","pt":1632572096365,"mc":[{"id":"1.188134680","rc":[{"batb":[[1,4,409.98]],"batl":[[2,4.7,142.46]],"ltp":4.0,"tv":3325.1,"id":9631939},{"batb":[[1,1.28,2107.62],[2,1.27,840.57]],"batl":[[2,1.34,255.57]],"ltp":1.27,"tv":24760.36,"id":8681938}]}]}
{"op":"mcm","clk":"4297165487","pt":1632572097562,"mc":[{"id":"1.188134680","rc":[{"batb":[[1,1.28,2034.19]],"ltp":1.27,"tv":24760.36,"id":8681938}]}]}
{"op":"mcm","clk":"4297165808","pt":1632572099043,"mc":[{"id":"1.188134680","rc":[{"batb":[[0,1.29,849.56]],"ltp":1.27,"tv":24760.36,"id":8681938}]}]}
{"op":"mcm","clk":"4297166367","pt":1632572101251,"mc":[{"id":"1.188134680","rc":[{"batb":[[1,4,411.98]],"ltp":4.0,"tv":3325.1,"id":9631939},{"batb":[[0,1.3,68.53],[1,1.29,849.56],[2,1.28,2034.19]],"batl":[[0,1.31,408],[1,1.32,567.2],[2,1.33,644.7]],"ltp":1.27,"tv":24760.36,"id":8681938}]}]}
{"op":"mcm","clk":"4297166589","pt":1632572102073,"mc":[{"id":"1.188134680","rc":[{"trd":[[1.3,3377.06]],"batb":[[0,1.3,59.14]],"ltp":1.3,"tv":24779.14,"id":8681938}],"tv":28104.25}]}
{"op":"mcm","clk":"4297166918","pt":1632572103366,"mc":[{"id":"1.188134680","rc":[{"trd":[[1.31,758.92]],"batl":[[0,1.31,391.36]],"ltp":1.31,"tv":24812.42,"id":8681938}],"tv":28137.53}]}
{"op":"mcm","clk":"4297167161","pt":1632572104359,"mc":[{"id":"1.188134680","rc":[{"batb":[[1,4,172.92],[2,3.9,2]],"batl":[[0,4.7,7.79],[1,4.8,2],[2,5,90.51]],"ltp":4.0,"tv":3325.1,"id":9631939},{"batb":[[2,1.28,1287.13]],"batl":[[0,1.31,623.36],[1,1.32,553.77]],"ltp":1.31,"tv":24812.42,"id":8681938}]}]}
{"op":"mcm","clk":"4297167263","pt":1632572104752,"mc":[{"id":"1.188134680","rc":[{"batb":[[1,4,22]],"ltp":4.0,"tv":3325.1,"id":9631939},{"batb":[[1,1.27,156.34],[2,1.25,500.76]],"batl":[[1,1.32,34.36],[2,1.33,39.5]],"ltp":1.31,"tv":24812.42,"id":8681938}]}]}
{"op":"mcm","clk":"4297167635","pt":1632572106284,"mc":[{"id":"1.188134680","rc":[{"batb":[[0,4,2],[1,3.9,2],[2,3.85,169.19]],"batl":[[0,4.8,2],[1,5,90.51],[2,5.1,100.66]],"ltp":4.0,"tv":3325.1,"id":9631939},{"batb":[[0,1.27,40.87],[1,1.25,500.76],[2,1.24,1140.59]],"batl":[[0,1.33,39.5],[1,1.34,38.25],[2,1.36,9]],"ltp":1.31,"tv":24812.42,"id":8681938}]}]}
{"op":"mcm","clk":"4297167728","pt":1632572106671,"mc":[{"id":"1.188134680","rc":[{"batb":[[1,3.85,169.19],[2,3.75,118.33]],"batl":[[0,5,90.51],[1,5.1,100.66],[2,5.2,2]],"ltp":4.0,"tv":3325.1,"id":9631939},{"batb":[[0,1.25,500.76],[1,1.24,1140.59],[2,1.23,10]],"batl":[[1,1.36,9],[2,1.37,289.56]],"ltp":1.31,"tv":24812.42,"id":8681938}]}]}
{"op":"mcm","clk":"4297167913","pt":1632572107451,"mc":[{"id":"1.188134680","rc":[{"batb":[[0,1.25,1516.36],[1,1.24,2074.38]],"batl":[[1,1.34,644.05],[2,1.35,560.95]],"ltp":1.31,"tv":24812.42,"id":8681938}]}]}
{"op":"mcm","clk":"4297168322","pt":1632572109259,"mc":[{"id":"1.188134680","rc":[{"batl":[[0,4.1,3.52],[1,5,90.51],[2,5.1,100.66]],"ltp":4.0,"tv":3325.1,"id":9631939},{"batb":[[2,1.21,60.69]],"ltp":1.31,"tv":24812.42,"id":8681938}]}]}
{"op":"mcm","clk":"4297168548","pt":1632572110188,"mc":[{"id":"1.188134680","rc":[{"trd":[[4.1,121.3]],"batl":[[0,4.7,3],[1,4.8,2],[2,4.9,3]],"ltp":4.1,"tv":3330.62,"id":9631939},{"trd":[[1.32,147.96]],"batb":[[0,1.27,10],[1,1.26,11],[2,1.25,1527.36]],"ltp":1.32,"tv":24817.15,"id":8681938}],"tv":28147.78}]}
{"op":"mcm","clk":"4297168682","pt":1632572110747,"mc":[{"id":"1.188134680","rc":[{"batb":[[1,1.26,90.07]],"ltp":1.32,"tv":24817.15,"id":8681938}]}]}
{"op":"mcm","clk":"4297168962","pt":1632572111937,"mc":[{"id":"1.188134680","rc":[{"batb":[[2,1.25,63.05]],"ltp":1.32,"tv":24817.15,"id":8681938}]}]}
{"op":"mcm","clk":"4297169472","pt":1632572114267,"mc":[{"id":"1.188134680","rc":[{"batb":[[0,1.27,610]],"ltp":1.32,"tv":24817.15,"id":8681938}]}]}
{"op":"mcm","clk":"4297169693","pt":1632572115178,"mc":[{"id":"1.188134680","rc":[{"trd":[[4,94.85]],"batb":[[0,3.85,169.19],[1,3.8,251.64],[2,3.75,415.85]],"batl":[[0,4.3,8.98],[1,4.7,3],[2,4.8,2]],"ltp":4.0,"tv":3336.84,"id":9631939},{"trd":[[1.33,305.82]],"batb":[[0,1.32,145.78],[1,1.31,1528.24],[2,1.3,1436.88]],"batl":[[0,1.33,32.82],[2,1.35,578.37]],"ltp":1.33,"tv":24823.83,"id":8681938}],"tv":28160.68}]}
{"op":"mcm","clk":"4297169977","pt":1632572116285,"mc":[{"id":"1.188134680","rc":[{"batb":[[0,3.85,190.24],[2,3.75,506.41]],"batl":[[1,4.5,8.01],[2,4.7,3]],"ltp":4.0,"tv":3336.84,"id":9631939},{"batb":[[2,1.3,1915.18]],"ltp":1.33,"tv":24823.83,"id":8681938}]}]}
{"op":"mcm","clk":"4297170354","pt":1632572117872,"mc":[{"id":"1.188134680","rc":[{"batb":[[0,3.85,206.62]],"batl":[[0,4.2,2],[1,4.3,8.98],[2,4.5,8.01]],"ltp":4.0,"tv":3336.84,"id":9631939}]}]}
{"op":"mcm","clk":"4297170977","pt":1632572120573,"mc":[{"id":"1.188134680","rc":[{"batl":[[0,4.2,17]],"ltp":4.0,"tv":3336.84,"id":9631939},{"batl":[[0,1.33,344.82]],"ltp":1.33,"tv":24823.83,"id":8681938}]}]}
{"op":"mcm","clk":"4297171338","pt":1632572121875,"mc":[{"id":"1.188134680","rc":[{"batb":[[0,3.9,2],[1,3.85,208.62],[2,3.8,251.64]],"batl":[[2,4.4,2]],"ltp":4.0,"tv":3336.84,"id":9631939},{"batb":[[2,1.3,1953.86]],"batl":[[1,1.34,676.3],[2,1.35,616.27]],"ltp":1.33,"tv":24823.83,"id":8681938}]}]}
{"op":"mcm","clk":"4297171811","pt":1632572123873,"mc":[{"id":"1.188134680","rc":[{"trd":[[1.32,148.58],[1.33,430.42]],"batb":[[0,1.32,145.47]],"batl":[[0,1.33,602.52]],"ltp":1.33,"tv":24949.06,"id":8681938}],"tv":28285.9}]}
{"op":"mcm","clk":"4297172117","pt":1632572125297,"mc":[{"id":"1.188134680","rc":[{"trd":[[1.32,148.9]],"batb":[[0,1.32,145.31]],"batl":[[2,1.35,598.85]],"ltp":1.32,"tv":24949.38,"id":8681938}],"tv":28286.23}]}
{"op":"mcm","clk":"4297172434","pt":1632572126701,"mc":[{"id":"1.188134680","rc":[{"batb":[[1,1.31,553.54]],"ltp":1.32,"tv":24949.38,"id":8681938}]}]}
{"op":"mcm","clk":"4297172739","pt":1632572128102,"mc":[{"id":"1.188134680","rc":[{"batb":[[1,3.85,23.05],[2,3.75,90.55]],"batl":[[0,4.4,2],[1,4.5,120.76],[2,4.6,118.61]],"ltp":4.0,"tv":3336.84,"id":9631939},{"batb":[[0,1.3,38.68],[1,1.29,470.4],[2,1.28,467.12]],"batl":[[1,1.34,32.25],[2,1.35,531.86]],"ltp":1.32,"tv":24949.38,"id":8681938}]}]}
{"op":"mcm","clk":"4297173011","pt":1632572129300,"mc":[{"id":"1.188134680","rc":[{"batb":[[0,3.85,2],[1,3.75,90.55],[2,3.6,114.67]],"batl":[[0,4.5,112.75],[1,4.6,118.61],[2,5,2]],"ltp":4.0,"tv":3336.84,"id":9631939},{"batb":[[0,1.29,358.99],[1,1.28,467.12],[2,1.27,1152.96]],"batl":[[0,1.35,531.86],[1,1.38,338.39],[2,1.39,345.08]],"ltp":1.32,"tv":24949.38,"id":8681938}]}]}
{"op":"mcm","clk":"4297173233","pt":1632572130291,"mc":[{"id":"1.188134680","rc":[{"batl":[[0,1.35,602.28]],"ltp":1.32,"tv":24949.38,"id":8681938}]}]}
{"op":"mcm","clk":"4297173476","pt":1632572131168,"mc":[{"id":"1.188134680","rc":[{"batl":[[0,4.4,3],[1,4.5,112.75],[2,4.6,118.61]],"ltp":4.0,"tv":3336.84,"id":9631939},{"batb":[[1,1.28,1268.67],[2,1.27,1957.09]],"batl":[[1,1.36,543.36],[2,1.38,338.39]],"ltp":1.32,"tv":24949.38,"id":8681938}]}]}
{"op":"mcm","clk":"4297173750","pt":1632572132303,"mc":[{"id":"1.188134680","rc":[{"batb":[[0,3.9,2],[1,3.85,2],[2,3.75,90.55]],"batl":[[0,4.5,4],[1,4.6,3],[2,5,2]],"ltp":4.0,"tv":3336.84,"id":9631939},{"batb":[[0,1.29,48.81],[1,1.28,11],[2,1.27,1152.96]],"batl":[[0,1.34,40.75],[1,1.35,611.28],[2,1.36,543.36]],"ltp":1.32,"tv":24949.38,"id":8681938}]}]}
{"op":"mcm","clk":"4297173834","pt":1632572132688,"mc":[{"id":"1.188134680","rc":[{"batb":[[0,3.85,2],[1,3.75,90.55],[2,3.6,114.67]],"ltp":4.0,"tv":3336.84,"id":9631939},{"batl":[[0,1.35,611.28],[1,1.36,543.36],[2,1.38,338.39]],"ltp":1.32,"tv":24949.38,"id":8681938}]}]}
{"op":"mcm","clk":"4297174481","pt":1632572135313,"mc":[{"id":"1.188134680","rc":[{"batb":[[0,3.85,4],[1,3.8,3],[2,3.75,90.55]],"batl":[[0,4.1,449.58],[1,4.2,179.09],[2,4.3,174.8]],"ltp":4.0,"tv":3336.84,"id":9631939},{"batb":[[0,1.34,20.21],[1,1.33,1904.38],[2,1.32,641.46]],"batl":[[0,1.35,602.28],[1,1.36,558.73],[2,1.38,464.99]],"ltp":1.32,"tv":24949.38,"id":8681938}]}]}
{"op":"mcm","clk":"4297174698","pt":1632572136288,"mc":[{"id":"1.188134680","rc":[{"batb":[[0,3.85,2],[1,3.75,112.36],[2,3.7,94.11]],"batl":[[0,4.1,220.32],[1,4.2,64.46],[2,4.3,60.17]],"ltp":4.0,"tv":3336.84,"id":9631939},{"batb":[[1,1.33,606.91],[2,1.32,1092.29]],"batl":[[2,1.37,403.69]],"ltp":1.32,"tv":24949.38,"id":8681938}]}]}
{"op":"mcm","clk":"4297175112","pt":1632572138098,"mc":[{"id":"1.188134680","rc":[{"batl":[[0,1.35,531.86]],"ltp":1.32,"tv":24949.38,"id":8681938}]}]}
{"op":"mcm","clk":"4297175593","pt":1632572140320,"mc":[{"id":"1.188134680","rc":[{"batl":[[0,4.1,240.32]],"ltp":4.0,"tv":3336.84,"id":9631939},{"batl":[[0,1.35,803.86]],"ltp":1.32,"tv":24949.38,"id":8681938}]}]}
{"op":"mcm","clk":"4297176080","pt":1632572142301,"mc":[{"id":"1.188134680","rc":[{"batb":[[1,3.75,114.36]],"batl":[[0,4.1,369.46],[1,4.2,163.6]],"ltp":4.0,"tv":3336.84,"id":9631939},{"batb":[[2,1.32,1369.25]],"batl":[[1,1.36,589.55]],"ltp":1.32,"tv":24949.38,"id":8681938}]}]}
{"op":"mcm","clk":"4297176145","pt":1632572142605,"mc":[{"id":"1.188134680","rc":[{"batl":[[0,1.35,996.86]],"ltp":1.32,"tv":24949.38,"id":8681938}]}]}
{"op":"mcm","clk":"4297176553","pt":1632572144291,"mc":[{"id":"1.188134680","rc":[{"batl":[[1,1.36,659.46]],"ltp":1.32,"tv":24949.38,"id":8681938}]}]}
{"op":"mcm","clk":"4297176775","pt":1632572145292,"mc":[{"id":"1.188134680","rc":[{"batb":[[1,3.75,23.81]],"batl":[[0,4.1,129.14],[1,4.2,99.14],[2,4.4,10.13]],"ltp":4.0,"tv":3336.84,"id":9631939},{"batb":[[0,1.32,276.96],[1,1.31,426.3],[2,1.3,164.72]],"batl":[[0,1.35,502.9],[1,1.36,644.09],[2,1.37,60.63]],"ltp":1.32,"tv":24949.38,"id":8681938}]}]}
{"op":"mcm","clk":"4297177029","pt":1632572146313,"mc":[{"id":"1.188134680","rc":[{"batb":[[0,3.75,2],[1,3.7,94.11],[2,3.6,103.73]],"batl":[[2,4.4,2]],"ltp":4.0,"tv":3336.84,"id":9631939},{"batb":[[2,1.3,55.18]],"batl":[[0,1.36,644.09],[1,1.39,297.54],[2,1.4,295.99]],"ltp":1.32,"tv":24949.38,"id":8681938}]}]}
{"op":"mcm","clk":"4297177442","pt":1632572148011,"mc":[{"id":"1.188134680","rc":[{"batb":[[2,1.3,844.91]],"batl":[[0,1.36,644.13],[1,1.37,524.53],[2,1.39,296.91]],"ltp":1.32,"tv":24949.38,"id":8681938}]}]}
{"op":"mcm","clk":"4297177674","pt":1632572148999,"mc":[{"id":"1.188134680","rc":[{"batl":[[0,4.5,4],[1,5.5,117.37],[2,5.8,2.54]],"ltp":4.0,"tv":3336.84,"id":9631939},{"batb":[[0,1.3,10],[1,1.29,548.05],[2,1.27,600]],"batl":[[0,1.36,574.22]],"ltp":1.32,"tv":24949.38,"id":8681938}]}]}
{"op":"mcm","clk":"4297177856","pt":1632572149797,"mc":[{"id":"1.188134680","rc":[{"batb":[[0,3.75,5],[1,3.7,97.11]],"ltp":4.0,"tv":3336.84,"id":9631939},{"batl":[[0,1.36,581.22]],"ltp":1.32,"tv":24949.38,"id":8681938}]}]}
{"op":"mcm","clk":"4297178345","pt":1632572151927,"mc":[{"id":"1.188134680","rc":[{"trd":[[3.9,0.01]],"batl":[[0,3.85,44.84],[1,4,117.5],[2,4.1,66.08]],"ltp":3.9,"tv":3336.85,"id":9631939},{"trd":[[1.34,0.04]],"batb":[[0,1.33,1051.04],[1,1.32,673.56],[2,1.3,60.24]],"batl":[[0,1.36,581.18],[1,1.37,539.9],[2,1.39,425.55]],"ltp":1.34,"tv":24949.42,"id":8681938}],"tv":28286.28}]}
{"op":"mcm","clk":"4297178683","pt":1632572153362,"mc":[{"id":"1.188134680","rc":[{"batb":[[2,3.65,22.64]],"ltp":3.9,"tv":3336.85,"id":9631939},{"batb":[[0,1.33,1489.35],[2,1.31,3138.06]],"batl":[[2,1.38,400.58]],"ltp":1.34,"tv":24949.42,"id":8681938}]}]}
{"op":"mcm","clk":"4297178743","pt":1632572153637,"mc":[{"id":"1.188134680","rc":[{"batb":[[0,3.75,2],[1,3.7,94.11]],"ltp":3.9,"tv":3336.85,"id":9631939},{"batl":[[0,1.36,574.18]],"ltp":1.34,"tv":24949.42,"id":8681938}]}]}
{"op":"mcm","clk":"4297179236","pt":1632572155732,"mc":[{"id":"1.188134680","rc":[{"trd":[[3.85,24.69]],"batl":[[0,3.85,20.15]],"ltp":3.85,"tv":3361.54,"id":9631939},{"trd":[[1.35,70.42]],"ltp":1.35,"tv":25019.84,"id":8681938}],"tv":28381.39}]}
{"op":"mcm","clk":"4297179550","pt":1632572157147,"mc":[{"id":"1.188134680","rc":[{"batb":[[0,1.33,1539.35],[2,1.31,107.76]],"batl":[[0,1.36,873.18]],"ltp":1.35,"tv":25019.84,"id":8681938}]}]}
{"op":"mcm","clk":"4297180334","pt":1632572160374,"mc":[{"id":"1.188134680","rc":[{"batl":[[0,1.36,1126.18]],"ltp":1.35,"tv":25019.84,"id":8681938}]}]}
{"op":"mcm","clk":"4297180480","pt":1632572160933,"mc":[{"id":"1.188134680","rc":[{"batb":[[1,3.65,116.91],[2,3.6,103.73]],"ltp":3.85,"tv":3361.54,"id":9631939},{"batb":[[0,1.33,1538.76]],"ltp":1.35,"tv":25019.84,"id":8681938}]}]}
{"op":"mcm","clk":"4297181873","pt":1632572166543,"mc":[{"id":"1.188134680","rc":[{"batb":[[0,3.75,111.71]],"ltp":3.85,"tv":3361.54,"id":9631939},{"batl":[[1,1.37,840.2]],"ltp":1.35,"tv":25019.84,"id":8681938}]}]}
{"op":"mcm","clk":"4297183499","pt":1632572173671,"mc":[{"id":"1.188134680","rc":[{"trd":[[3.85,31.9]],"batl":[[0,3.85,12.94]],"ltp":3.85,"tv":3368.75,"id":9631939},{"trd":[[1.35,90.98]],"ltp":1.35,"tv":25040.4,"id":8681938}],"tv":28409.16}]}
{"op":"mcm","clk":"4297184389","pt":1632572176950,"mc":[{"id":"1.188134680","rc":[{"batl":[[0,1.36,1453.18]],"ltp":1.35,"tv":25040.4,"id":8681938}]}]}
{"op":"mcm","clk":"4297184827","pt":1632572178760,"mc":[{"id":"1.188134680","rc":[{"trd":[[3.85,39.11]],"batl":[[0,3.85,5.73]],"ltp":3.85,"tv":3375.96,"id":9631939},{"trd":[[1.35,111.54]],"ltp":1.35,"tv":25060.96,"id":8681938}],"tv":28436.93}]}
{"op":"mcm","clk":"4297185707","pt":1632572182204,"mc":[{"id":"1.188134680","rc":[{"batb":[[1,3.7,93.51],[2,3.65,22.64]],"ltp":3.85,"tv":3375.96,"id":9631939},{"batb":[[0,1.33,1101.04],[1,1.32,1113.82]],"ltp":1.35,"tv":25060.96,"id":8681938}]}]}
{"op":"mcm","clk":"4297186731","pt":1632572186362,"mc":[{"id":"1.188134680","rc":[{"batb":[[0,1.34,41.43],[1,1.33,1101.04],[2,1.32,1113.82]],"ltp":1.35,"tv":25060.96,"id":8681938}]}]}
{"op":"mcm","clk":"4297187456","pt":1632572189196,"mc":[{"id":"1.188134680","rc":[{"batl":[[0,4,117.5],[1,4.1,66.08],[2,4.2,61.64]],"ltp":3.85,"tv":3375.96,"id":9631939},{"batl":[[1,1.37,824.83]],"ltp":1.35,"tv":25060.96,"id":8681938}]}]}
{"op":"mcm","clk":"4297188227","pt":1632572192299,"mc":[{"id":"1.188134680","rc":[{"batl":[[0,3.85,5.73],[1,4,137.5],[2,4.1,66.08]],"ltp":3.85,"tv":3375.96,"id":9631939},{"batl":[[1,1.37,841.22]],"ltp":1.35,"tv":25060.96,"id":8681938}]}]}
{"op":"mcm","clk":"4297190370","pt":1632572201306,"mc":[{"id":"1.188134680","rc":[{"batb":[[1,1.33,1141.55]],"ltp":1.35,"tv":25060.96,"id":8681938}]}]}
{"op":"mcm","clk":"4297190421","pt":1632572201523,"mc":[{"id":"1.188134680","rc":[{"batl":[[0,1.36,1410.31]],"ltp":1.35,"tv":25060.96,"id":8681938}]}]}
{"op":"mcm","clk":"4297191951","pt":1632572207713,"mc":[{"id":"1.188134680","rc":[{"batb":[[1,1.33,1186.51]],"ltp":1.35,"tv":25060.96,"id":8681938}]}]}
{"op":"mcm","clk":"4297199835","pt":1632572239871,"mc":[{"id":"1.188134680","rc":[{"batb":[[0,3.65,22.64],[1,3.2,131.9],[2,3.15,145.38]],"batl":[[0,4.3,122.66],[1,4.4,138.6],[2,4.5,4]],"ltp":3.85,"tv":3375.96,"id":9631939},{"batb":[[1,1.31,107.76],[2,1.3,871.73]],"batl":[[0,1.36,879],[1,1.38,60.63],[2,1.44,2.35]],"ltp":1.35,"tv":25060.96,"id":8681938}]}]}
{"op":"mcm","clk":"4297200158","pt":1632572241253,"mc":[{"id":"1.188134680","rc":[{"batb":[[0,3.2,131.9],[1,3.15,145.38],[2,3.1,145.33]],"batl":[[0,4.3,114.41]],"ltp":3.85,"tv":3375.96,"id":9631939},{"batb":[[0,1.3,871.73],[1,1.29,456.14],[2,1.27,600]],"batl":[[0,1.44,2.98],[1,1.46,301.81],[2,1.47,318.84]],"ltp":1.35,"tv":25060.96,"id":8681938}]}]}
{"op":"mcm","clk":"4297200378","pt":1632572242162,"mc":[{"id":"1.188134680","rc":[{"batb":[[0,3.35,2],[1,3.25,2.13],[2,3.2,131.9]],"batl":[[0,4.3,116.41]],"ltp":3.85,"tv":3375.96,"id":9631939},{"batb":[[0,1.31,43.79],[1,1.3,871.73],[2,1.29,456.14]],"batl":[[0,1.42,30.88],[1,1.44,32.18],[2,1.46,301.81]],"ltp":1.35,"tv":25060.96,"id":8681938}]}]}
{"op":"mcm","clk":"4297200464","pt":1632572242547,"mc":[{"id":"1.188134680","rc":[{"batb":[[0,3.25,2.13],[1,3.2,131.9],[2,3.15,145.38]],"batl":[[0,4.3,114.41]],"ltp":3.85,"tv":3375.96,"id":9631939},{"batb":[[0,1.31,360.06],[1,1.3,1570.18]],"batl":[[0,1.43,283.69],[1,1.44,451.1]],"ltp":1.35,"tv":25060.96,"id":8681938}]}]}
{"op":"mcm","clk":"4297200828","pt":1632572244281,"mc":[{"id":"1.188134680","rc":[{"batl":[[0,4.3,117.41]],"ltp":3.85,"tv":3375.96,"id":9631939},{"batb":[[0,1.31,370.06]],"ltp":1.35,"tv":25060.96,"id":8681938}]}]}
{"op":"mcm","clk":"4297200902","pt":1632572244553,"mc":[{"id":"1.188134680","rc":[{"batb":[[1,3.2,133.9],[2,3.15,148.38]],"ltp":3.85,"tv":3375.96,"id":9631939},{"batb":[[2,1.29,458.14]],"batl":[[1,1.44,457.1]],"ltp":1.35,"tv":25060.96,"id":8681938}]}]}
{"op":"mcm","clk":"4297201240","pt":1632572246063,"mc":[{"id":"1.188134680","rc":[{"batb":[[0,3.3,3],[1,3.25,5.13],[2,3.2,133.9]],"batl":[[0,4.3,119.41]],"ltp":3.85,"tv":3375.96,"id":9631939},{"batb":[[0,1.31,409.85]],"batl":[[0,1.43,288.69]],"ltp":1.35,"tv":25060.96,"id":8681938}]}]}
{"op":"mcm","clk":"4297201568","pt":1632572247585,"mc":[{"id":"1.188134680","rc":[{"batb":[[0,3.35,3],[1,3.3,3],[2,3.25,5.13]],"batl":[[0,4.2,3],[1,4.3,119.41],[2,4.4,138.6]],"ltp":3.85,"tv":3375.96,"id":9631939},{"batb":[[0,1.32,7],[1,1.31,409.85],[2,1.3,1570.18]],"batl":[[0,1.42,8.63],[1,1.43,288.06],[2,1.44,457.1]],"ltp":1.35,"tv":25060.96,"id":8681938}]}]}
{"op":"mcm","clk":"4297201919","pt":1632572249261,"mc":[{"id":"1.188134680","rc":[{"batb":[[0,3.4,3],[1,3.35,5.07],[2,3.3,3]],"ltp":3.85,"tv":3375.96,"id":9631939},{"batl":[[0,1.41,7.63],[1,1.42,35.25],[2,1.43,288.06]],"ltp":1.35,"tv":25060.96,"id":8681938}]}]}
{"op":"mcm","clk":"4297201992","pt":1632572249683,"mc":[{"id":"1.188134680","rc":[{"batb":[[1,3.35,3]],"ltp":3.85,"tv":3375.96,"id":9631939},{"batb":[[0,1.32,49.05]],"batl":[[1,1.42,8]],"ltp":1.35,"tv":25060.96,"id":8681938}]}]}
{"op":"mcm","clk":"4297202283","pt":1632572250873,"mc":[{"id":"1.188134680","rc":[{"batl":[[0,4.1,3],[1,4.2,3],[2,4.3,119.41]],"ltp":3.85,"tv":3375.96,"id":9631939},{"batb":[[0,1.33,9],[1,1.32,49.05],[2,1.31,409.85]],"ltp":1.35,"tv":25060.96,"id":8681938}]}]}
{"op":"mcm","clk":"4297202555","pt":1632572252076,"mc":[{"id":"1.188134680","rc":[{"batb":[[0,3.45,3],[1,3.4,3],[2,3.35,3]],"ltp":3.85,"tv":3375.96,"id":9631939},{"batl":[[0,1.4,6.63],[1,1.41,7],[2,1.42,8]],"ltp":1.35,"tv":25060.96,"id":8681938}]}]}
{"op":"mcm","clk":"4297203029","pt":1632572254166,"mc":[{"id":"1.188134680","rc":[{"batl":[[0,4,3]],"ltp":3.85,"tv":3375.96,"id":9631939},{"batb":[[0,1.32,42.05],[1,1.31,409.85],[2,1.3,1570.18]],"batl":[[0,1.41,7.63],[1,1.42,8],[2,1.43,288.06]],"ltp":1.35,"tv":25060.96,"id":8681938}]}]}
{"op":"mcm","clk":"4297203149","pt":1632572254674,"mc":[{"id":"1.188134680","rc":[{"batl":[[0,4.2,3],[1,4.3,119.41],[2,4.4,138.6]],"ltp":3.85,"tv":3375.96,"id":9631939}]}]}
{"op":"mcm","clk":"4297203418","pt":1632572255844,"mc":[{"id":"1.188134680","rc":[{"batb":[[0,1.31,409.85],[1,1.3,1570.18],[2,1.29,458.14]],"ltp":1.35,"tv":25060.96,"id":8681938}]}]}
{"op":"mcm","clk":"4297203586","pt":1632572256669,"mc":[{"id":"1.188134680","rc":[{"batl":[[1,4.3,116.41]],"ltp":3.85,"tv":3375.96,"id":9631939},{"batb":[[0,1.34,20.56],[1,1.31,409.85],[2,1.3,1560.18]],"ltp":1.35,"tv":25060.96,"id":8681938}]}]}
{"op":"mcm","clk":"4297204351","pt":1632572260288,"mc":[{"id":"1.188134680","rc":[{"batb":[[2,3.25,2.13]],"ltp":3.85,"tv":3375.96,"id":9631939},{"batl":[[1,1.43,283.06],[2,1.44,451.1]],"ltp":1.35,"tv":25060.96,"id":8681938}]}]}
{"op":"mcm","clk":"4297204785","pt":1632572262272,"mc":[{"id":"1.188134680","rc":[{"batl":[[1,4.5,2],[2,5.5,117.37]],"ltp":3.85,"tv":3375.96,"id":9631939},{"batb":[[1,1.31,10],[2,1.3,475.09]],"ltp":1.35,"tv":25060.96,"id":8681938}]}]}
{"op":"mcm","clk":"4297205132","pt":1632572263906,"mc":[{"id":"1.188134680","rc":[{"batb":[[0,3.25,2.13],[1,3.2,131.9],[2,3.15,145.38]],"batl":[[2,5.8,2.54]],"ltp":3.85,"tv":3375.96,"id":9631939},{"batb":[[0,1.31,10],[1,1.3,475.09],[2,1.29,39.81]],"batl":[[0,1.43,283.69],[1,1.44,451.1],[2,1.46,301.81]],"ltp":1.35,"tv":25060.96,"id":8681938}]}]}
{"op":"mcm","clk":"4297205427","pt":1632572265267,"mc":[{"id":"1.188134680","rc":[{"batl":[[0,3.55,8.45],[1,3.65,3.5],[2,3.9,285.38]],"ltp":3.85,"tv":3375.96,"id":9631939},{"trd":[[1.37,1.26],[1.42,31.04]],"batb":[[0,1.4,446.01],[1,1.39,497.27],[2,1.38,720.4]],"batl":[[0,1.43,283.06],[2,1.45,670.6]],"ltp":1.42,"tv":25093.26,"id":8681938}],"tv":28469.23}]}
{"op":"mcm","clk":"4297205650","pt":1632572266280,"mc":[{"id":"1.188134680","rc":[{"batb":[[1,3.2,159.17]],"batl":[[2,3.75,9.04]],"ltp":3.85,"tv":3375.96,"id":9631939},{"batb":[[0,1.4,786.92]],"batl":[[2,1.45,730.6]],"ltp":1.42,"tv":25093.26,"id":8681938}]}]}
{"op":"mcm","clk":"4297206008","pt":1632572267947,"mc":[{"id":"1.188134680","rc":[{"batl":[[0,3.45,9.39],[1,3.5,2],[2,3.55,8.45]],"ltp":3.85,"tv":3375.96,"id":9631939},{"batb":[[0,1.4,792.92],[1,1.39,505.27],[2,1.38,728.4]],"ltp":1.42,"tv":25093.26,"id":8681938}]}]}
{"op":"mcm","clk":"4297206529","pt":1632572270357,"mc":[{"id":"1.188134680","rc":[{"batl":[[1,3.5,18.25]],"ltp":3.85,"tv":3375.96,"id":9631939},{"batb":[[0,1.4,833.55]],"ltp":1.42,"tv":25093.26,"id":8681938}]}]}
{"op":"mcm","clk":"4297206638","pt":1632572270867,"mc":[{"id":"1.188134680","rc":[{"batl":[[0,1.43,465.06]],"ltp":1.42,"tv":25093.26,"id":8681938}]}]}
{"op":"mcm","clk":"4297207208","pt":1632572273337,"mc":[{"id":"1.188134680","rc":[{"trd":[[1.43,13.36]],"batl":[[0,1.43,458.38]],"ltp":1.43,"tv":25106.62,"id":8681938}],"tv":28482.59}]}
{"op":"mcm","clk":"4297207384","pt":1632572274147,"mc":[{"id":"1.188134680","rc":[{"batl":[[0,1.43,182]],"ltp":1.43,"tv":25106.62,"id":8681938}]}]}
{"op":"mcm","clk":"4297207526","pt":1632572274846,"mc":[{"id":"1.188134680","rc":[{"batl":[[0,1.43,316],[2,1.45,719.48]],"ltp":1.43,"tv":25106.62,"id":8681938}]}]}
{"op":"mcm","clk":"4297207935","pt":1632572276935,"mc":[{"id":"1.188134680","rc":[{"trd":[[1.4,0.08]],"batb":[[0,1.4,833.51]],"batl":[[1,1.44,726.68],[2,1.45,1122.7]],"ltp":1.4,"tv":25106.7,"id":8681938}],"tv":28482.67}]}
{"op":"mcm","clk":"4297208212","pt":1632572278333,"mc":[{"id":"1.188134680","rc":[{"batl":[[2,3.65,3.5]],"ltp":3.85,"tv":3375.96,"id":9631939},{"batb":[[2,1.38,35.46]],"batl":[[2,1.45,463.22]],"ltp":1.4,"tv":25106.7,"id":8681938}]}]}
{"op":"mcm","clk":"4297208390","pt":1632572279246,"mc":[{"id":"1.188134680","rc":[{"trd":[[3.45,0.95]],"batb":[[0,3.2,27.27],[1,2.8,136.81],[2,2.78,145.05]],"batl":[[0,3.45,8.44],[1,3.9,2],[2,3.95,104.71]],"ltp":3.45,"tv":3376.92,"id":9631939},{"trd":[[1.4,2.43]],"batb":[[0,1.37,98.63],[1,1.36,392.32],[2,1.35,32.47]],"batl":[[1,1.44,2.35],[2,1.45,60]],"ltp":1.4,"tv":25109.05,"id":8681938}],"tv":28485.97}]}
{"op":"mcm","clk":"4297208581","pt":1632572280271,"mc":[{"id":"1.188134680","rc":[{"batb":[[0,2.8,136.81],[1,2.78,145.05],[2,2.68,83.79]],"ltp":3.45,"tv":3376.92,"id":9631939},{"batb":[[0,1.36,392.32],[1,1.35,32.47],[2,1.34,352.64]],"batl":[[0,1.44,2.35],[1,1.56,282.03],[2,1.57,263.13]],"ltp":1.4,"tv":25109.05,"id":8681938}]}]}
{"op":"mcm","clk":"4297208938","pt":1632572281965,"mc":[{"id":"1.188134680","rc":[{"batb":[[1,2.78,147.71],[2,2.74,2.29]],"ltp":3.45,"tv":3376.92,"id":9631939},{"batb":[[1,1.35,786.06],[2,1.34,952.16]],"batl":[[1,1.56,305.45],[2,1.57,285.63]],"ltp":1.4,"tv":25109.05,"id":8681938}]}]}
{"op":"mcm","clk":"4297209159","pt":1632572282948,"mc":[{"id":"1.188134680","rc":[{"batb":[[0,2.78,2.66],[1,2.74,2.29],[2,2.68,83.79]],"ltp":3.45,"tv":3376.92,"id":9631939},{"batl":[[1,1.56,23.42],[2,1.57,22.5]],"ltp":1.4,"tv":25109.05,"id":8681938}]}]}
{"op":"mcm","clk":"4297209841","pt":1632572286079,"mc":[{"id":"1.188134680","rc":[{"trd":[[3.45,9.39]],"batb":[[0,3.25,198.53],[1,2.78,2.66],[2,2.74,2.29]],"batl":[[0,3.75,4.77],[1,3.85,63.32],[2,3.9,2]],"ltp":3.45,"tv":3385.36,"id":9631939},{"trd":[[1.4,23.23]],"batl":[[0,1.38,14.06],[1,1.39,1394.42],[2,1.4,1138.91]],"ltp":1.4,"tv":25129.85,"id":8681938}],"tv":28515.21}]}
{"op":"mcm","clk":"4297210130","pt":1632572287370,"mc":[{"id":"1.188134680","rc":[{"batb":[[0,3.45,109.41],[1,3.25,198.53],[2,2.94,165.55]],"batl":[[2,3.9,9.69]],"ltp":3.45,"tv":3385.36,"id":9631939}]}]}
{"op":"mcm","clk":"4297210482","pt":1632572289042,"mc":[{"id":"1.188134680","rc":[{"batb":[[0,3.45,133.89],[1,3.3,3],[2,3.25,201.53]],"ltp":3.45,"tv":3385.36,"id":9631939}]}]}
{"op":"mcm","clk":"4297210943","pt":1632572291144,"mc":[{"id":"1.188134680","rc":[{"batb":[[0,3.5,17.59],[1,3.45,133.89],[2,3.3,3]],"ltp":3.45,"tv":3385.36,"id":9631939}]}]}
{"op":"mcm","clk":"4297211301","pt":1632572292994,"mc":[{"id":"1.188134680","rc":[{"batl":[[0,1.38,172.06]],"ltp":1.4,"tv":25129.85,"id":8681938}]}]}
{"op":"mcm","clk":"4297211621","pt":1632572294382,"mc":[{"id":"1.188134680","rc":[{"batl":[[2,1.4,1198.91]],"ltp":1.4,"tv":25129.85,"id":8681938}]}]}
{"op":"mcm","clk":"4297212032","pt":1632572296157,"mc":[{"id":"1.188134680","rc":[{"batb":[[1,3.45,109.41]],"ltp":3.45,"tv":3385.36,"id":9631939},{"batb":[[2,1.34,954.9]],"batl":[[0,1.38,274.06]],"ltp":1.4,"tv":25129.85,"id":8681938}]}]}
{"op":"mcm","clk":"4297212257","pt":1632572297273,"mc":[{"id":"1.188134680","rc":[{"trd":[[1.38,0.08]],"batl":[[0,1.38,274.02]],"ltp":1.38,"tv":25129.93,"id":8681938}],"tv":28515.29}]}
{"op":"mcm","clk":"4297212730","pt":1632572299367,"mc":[{"id":"1.188134680","rc":[{"batb":[[0,3.5,24]],"batl":[[0,3.9,2],[1,3.95,104.71],[2,4,102.76]],"ltp":3.45,"tv":3385.36,"id":9631939},{"batl":[[0,1.38,260],[1,1.39,706.48],[2,1.4,531.19]],"ltp":1.38,"tv":25129.93,"id":8681938}]}]}
{"op":"mcm","clk":"4297212865","pt":1632572300067,"mc":[{"id":"1.188134680","rc":[{"batb":[[1,3.1,2.04],[2,3,141.43]],"batl":[[0,4.1,8.51],[1,4.2,125.21],[2,4.3,106.77]],"ltp":3.45,"tv":3385.36,"id":9631939},{"batb":[[0,1.34,2.74],[1,1.33,2.74],[2,1.32,480.77]],"batl":[[0,1.36,2.35],[1,1.38,260],[2,1.4,60]],"ltp":1.38,"tv":25129.93,"id":8681938}]}]}
{"op":"mcm","clk":"4297213139","pt":1632572301307,"mc":[{"id":"1.188134680","rc":[{"batb":[[0,3.1,2.04],[1,3,141.43],[2,2.98,167.46]],"batl":[[0,4.2,125.21],[1,4.3,106.77],[2,4.5,2]],"ltp":3.45,"tv":3385.36,"id":9631939},{"batb":[[2,1.32,483.51]],"batl":[[1,1.47,25.81],[2,1.5,314.31]],"ltp":1.38,"tv":25129.93,"id":8681938}]}]}
{"op":"mcm","clk":"4297213370","pt":1632572302382,"mc":[{"id":"1.188134680","rc":[{"batb":[[2,1.32,1037.52]],"batl":[[2,1.49,388.49]],"ltp":1.38,"tv":25129.93,"id":8681938}]}]}
{"op":"mcm","clk":"4297213584","pt":1632572303381,"mc":[{"id":"1.188134680","rc":[{"batl":[[0,4.1,4],[1,4.2,125.21],[2,4.3,106.77]],"ltp":3.45,"tv":3385.36,"id":9631939},{"batb":[[1,1.33,41.27]],"ltp":1.38,"tv":25129.93,"id":8681938}]}]}
{"op":"mcm","clk":"4297213619","pt":1632572303584,"mc":[{"id":"1.188134680","rc":[{"batl":[[0,4.1,2]],"ltp":3.45,"tv":3385.36,"id":9631939},{"trd":[[1.36,0.78]],"batb":[[1,1.33,2.74]],"batl":[[0,1.36,1.96]],"ltp":1.36,"tv":25130.71,"id":8681938}],"tv":28516.07}]}
{"op":"mcm","clk":"4297213808","pt":1632572304495,"mc":[{"id":"1.188134680","rc":[{"batl":[[1,4.2,127.21]],"ltp":3.45,"tv":3385.36,"id":9631939}]}]}
{"op":"mcm","clk":"4297214271","pt":1632572306775,"mc":[{"id":"1.188134680","rc":[{"batl":[[0,4.1,4]],"ltp":3.45,"tv":3385.36,"id":9631939},{"batb":[[1,1.33,40.27]],"ltp":1.36,"tv":25130.71,"id":8681938}]}]}
{"op":"mcm","clk":"4297214700","pt":1632572308973,"mc":[{"id":"1.188134680","rc":[{"batl":[[0,4.1,2]],"ltp":3.45,"tv":3385.36,"id":9631939},{"batb":[[1,1.33,2.74]],"ltp":1.36,"tv":25130.71,"id":8681938}]}]}
{"op":"mcm","clk":"4297214913","pt":1632572309992,"mc":[{"id":"1.188134680","rc":[{"batb":[[0,3.15,3],[1,3.1,4.04],[2,3,141.43]],"batl":[[0,4,2],[1,4.1,2],[2,4.2,127.21]],"ltp":3.45,"tv":3385.36,"id":9631939},{"batb":[[0,1.35,7],[1,1.34,10.74],[2,1.33,2.74]],"batl":[[1,1.46,2.31],[2,1.47,25.5]],"ltp":1.36,"tv":25130.71,"id":8681938}]}]}
{"op":"mcm","clk":"4297215086","pt":1632572310795,"mc":[{"id":"1.188134680","rc":[{"batb":[[1,3.1,2]],"ltp":3.45,"tv":3385.36,"id":9631939},{"batb":[[0,1.35,7.39]],"batl":[[0,1.46,2.31],[1,1.49,388.49],[2,1.5,666.32]],"ltp":1.36,"tv":25130.71,"id":8681938}]}]}
{"op":"mcm","clk":"4297215411","pt":1632572312275,"mc":[{"id":"1.188134680","rc":[{"batl":[[1,4.1,4]],"ltp":3.45,"tv":3385.36,"id":9631939},{"batb":[[2,1.33,42.27]],"ltp":1.36,"tv":25130.71,"id":8681938}]}]}
{"op":"mcm","clk":"4297215616","pt":1632572313190,"mc":[{"id":"1.188134680","rc":[{"batb":[[0,3.2,2],[1,3.15,3],[2,3.1,2]],"batl":[[0,3.85,3],[1,3.95,3],[2,4,2]],"ltp":3.45,"tv":3385.36,"id":9631939},{"batb":[[2,1.33,5.48]],"batl":[[0,1.45,7.31],[1,1.46,2],[2,1.49,388.49]],"ltp":1.36,"tv":25130.71,"id":8681938}]}]}
{"op":"mcm","clk":"4297216296","pt":1632572316395,"mc":[{"id":"1.188134680","rc":[{"batb":[[0,3.25,3],[1,3.2,2],[2,3.15,3]],"batl":[[0,3.8,2],[1,3.85,3],[2,3.95,3]],"ltp":3.45,"tv":3385.36,"id":9631939},{"batl":[[0,1.44,8.31],[1,1.45,7],[2,1.46,2]],"ltp":1.36,"tv":25130.71,"id":8681938}]}]}
{"op":"mcm","clk":"4297216611","pt":1632572317900,"mc":[{"id":"1.188134680","rc":[{"batb":[[0,3,141.43],[1,2.98,167.46],[2,2.96,2.13]],"batl":[[0,4.2,125.21],[1,4.3,106.77],[2,4.5,2]],"ltp":3.45,"tv":3385.36,"id":9631939},{"batb":[[0,1.34,3.13],[1,1.33,5.48],[2,1.32,1037.52]],"batl":[[0,1.49,388.8],[1,1.5,666.32],[2,1.51,325.09]],"ltp":1.36,"tv":25130.71,"id":8681938}]}]}
{"op":"mcm","clk":"4297216937","pt":1632572319339,"mc":[{"id":"1.188134680","rc":[{"batl":[[0,4.1,2],[1,4.2,125.21],[2,4.3,106.77]],"ltp":3.45,"tv":3385.36,"id":9631939},{"batb":[[1,1.33,42.01]],"ltp":1.36,"tv":25130.71,"id":8681938}]}]}
{"op":"mcm","clk":"4297217091","pt":1632572320041,"mc":[{"id":"1.188134680","rc":[{"batl":[[0,4.2,125.21],[1,4.3,106.77],[2,4.5,2]],"ltp":3.45,"tv":3385.36,"id":9631939},{"batb":[[1,1.33,5.48],[2,1.32,483.51]],"batl":[[0,1.5,314.62],[1,1.51,325.09],[2,1.56,23.42]],"ltp":1.36,"tv":25130.71,"id":8681938}]}]}
{"op":"mcm","clk":"4297217343","pt":1632572321185,"mc":[{"id":"1.188134680","rc":[{"batb":[[0,3.1,2.04],[1,3,141.43],[2,2.98,167.46]],"batl":[[0,4.2,128.21]],"ltp":3.45,"tv":3385.36,"id":9631939},{"batl":[[0,1.47,25.81],[1,1.5,314.31],[2,1.51,325.09]],"ltp":1.36,"tv":25130.71,"id":8681938}]}]}
{"op":"mcm","clk":"4297217427","pt":1632572321516,"mc":[{"id":"1.188134680","rc":[{"batb":[[0,3,141.43],[1,2.98,167.46],[2,2.96,2.13]],"ltp":3.45,"tv":3385.36,"id":9631939},{"batl":[[0,1.5,314.62],[1,1.51,325.09],[2,1.56,23.42]],"ltp":1.36,"tv":25130.71,"id":8681938}]}]}
{"op":"mcm","clk":"4297217790","pt":1632572323218,"mc":[{"id":"1.188134680","rc":[{"batl":[[0,3.65,18.9],[1,4.1,5],[2,4.2,128.21]],"ltp":3.45,"tv":3385.36,"id":9631939},{"batb":[[0,1.38,18.96],[1,1.37,646.29],[2,1.36,555.37]],"batl":[[0,1.4,18.64],[1,1.41,678.38],[2,1.42,442.1]],"ltp":1.36,"tv":25130.71,"id":8681938}]}]}
{"op":"mcm","clk":"4297217827","pt":1632572323434,"mc":[{"id":"1.188134680","rc":[{"batl":[[0,4.1,5],[1,4.2,128.21],[2,4.3,106.77]],"ltp":3.45,"tv":3385.36,"id":9631939},{"batb":[[0,1.37,646.29],[1,1.36,555.37],[2,1.34,2.74]],"batl":[[0,1.41,678.38],[1,1.42,442.1],[2,1.5,317.62]],"ltp":1.36,"tv":25130.71,"id":8681938}]}]}
{"op":"mcm","clk":"4297218192","pt":1632572324945,"mc":[{"id":"1.188134680","rc":[{"batb":[[0,3.1,2.04],[1,3,141.43],[2,2.98,167.46]],"ltp":3.45,"tv":3385.36,"id":9631939},{"batl":[[2,1.46,105.87]],"ltp":1.36,"tv":25130.71,"id":8681938}]}]}
{"op":"mcm","clk":"4297218605","pt":1632572326665,"mc":[{"id":"1.188134680","rc":[{"batl":[[0,1.4,141],[1,1.41,678.38],[2,1.42,442.1]],"ltp":1.36,"tv":25130.71,"id":8681938}]}]}
{"op":"mcm","clk":"4297219041","pt":1632572328339,"mc":[{"id":"1.188134680","rc":[{"batl":[[0,4.1,3]],"ltp":3.45,"tv":3385.36,"id":9631939},{"batb":[[0,1.37,48.3],[1,1.34,3.13],[2,1.33,5.48]],"batl":[[1,1.47,25.81],[2,1.5,317.31]],"ltp":1.36,"tv":25130.71,"id":8681938}]}]}
{"op":"mcm","clk":"4297219133","pt":1632572328716,"mc":[{"id":"1.188134680","rc":[{"batb":[[0,3,141.43],[1,2.98,167.46],[2,2.96,2.13]],"ltp":3.45,"tv":3385.36,"id":9631939},{"batb":[[0,1.34,3.13],[1,1.33,5.48],[2,1.32,483.51]],"batl":[[0,1.5,317.62],[1,1.51,325.09],[2,1.56,23.42]],"ltp":1.36,"tv":25130.71,"id":8681938}]}]}
{"op":"mcm","clk":"4297219531","pt":1632572330940,"mc":[{"id":"1.188134680","rc":[{"batb":[[2,1.32,1037.52]],"batl":[[0,1.49,388.8],[1,1.5,669.32],[2,1.51,325.09]],"ltp":1.36,"tv":25130.71,"id":8681938}]}]}
{"op":"mcm","clk":"4297220521","pt":1632572335324,"mc":[{"id":"1.188134680","rc":[{"batb":[[0,3.15,2],[1,3.1,3],[2,3.05,3]],"batl":[[0,4,3],[1,4.1,2],[2,4.2,125.21]],"ltp":3.45,"tv":3385.36,"id":9631939},{"batb":[[0,1.35,9.39],[1,1.34,9.74],[2,1.33,5.48]],"batl":[[0,1.46,3.31],[1,1.48,3],[2,1.49,388.49]],"ltp":1.36,"tv":25130.71,"id":8681938}]}]}
{"op":"mcm","clk":"4297220603","pt":1632572335552,"mc":[{"id":"1.188134680","rc":[{"batb":[[0,3.1,3],[1,3.05,3],[2,3,144.43]],"batl":[[1,4.2,125.21],[2,4.3,106.77]],"ltp":3.45,"tv":3385.36,"id":9631939},{"batl":[[0,1.47,3.31]],"ltp":1.36,"tv":25130.71,"id":8681938}]}]}
{"op":"mcm","clk":"4297220888","pt":1632572336959,"mc":[{"id":"1.188134680","rc":[{"batb":[[1,1.34,7],[2,1.32,1032.03]],"ltp":1.36,"tv":25130.71,"id":8681938}]}]}
{"op":"mcm","clk":"4297221131","pt":1632572338032,"mc":[{"id":"1.188134680","rc":[{"batl":[[0,3.85,3],[1,3.95,3],[2,4,3]],"ltp":3.45,"tv":3385.36,"id":9631939},{"batb":[[0,1.36,2.39],[1,1.35,9],[2,1.34,7]],"ltp":1.36,"tv":25130.71,"id":8681938}]}]}
{"op":"mcm","clk":"4297221575","pt":1632572340237,"mc":[{"id":"1.188134680","rc":[{"batb":[[0,3.1,5.04]],"ltp":3.45,"tv":3385.36,"id":9631939},{"batb":[[2,1.34,48.43]],"batl":[[0,1.47,33.81]],"ltp":1.36,"tv":25130.71,"id":8681938}]}]}
{"op":"mcm","clk":"4297221789","pt":1632572341261,"mc":[{"id":"1.188134680","rc":[{"batb":[[0,3.1,3]],"batl":[[0,3.8,3],[1,3.85,3],[2,3.95,3]],"ltp":3.45,"tv":3385.36,"id":9631939},{"batb":[[0,1.37,4],[1,1.36,2.39],[2,1.35,9]],"batl":[[0,1.47,3.31]],"ltp":1.36,"tv":25130.71,"id":8681938}]}]}
{"op":"mcm","clk":"4297222020","pt":1632572342239,"mc":[{"id":"1.188134680","rc":[{"batb":[[0,3,141.43],[1,2.98,167.46],[2,2.96,2.13]],"batl":[[0,4.1,2],[1,4.2,125.21],[2,4.3,106.77]],"ltp":3.45,"tv":3385.36,"id":9631939},{"batb":[[0,1.34,41.82],[1,1.32,1032.03],[2,1.31,1068.03]],"batl":[[0,1.49,388.8],[1,1.5,669.32],[2,1.51,325.09]],"ltp":1.36,"tv":25130.71,"id":8681938}]}]}
{"op":"mcm","clk":"4297222097","pt":1632572342558,"mc":[{"id":"1.188134680","rc":[{"batl":[[0,4.2,125.21],[1,4.3,106.77],[2,4.5,2]],"ltp":3.45,"tv":3385.36,"id":9631939}]}]}
{"op":"mcm","clk":"4297222590","pt":1632572344768,"mc":[{"id":"1.188134680","rc":[{"batb":[[0,2.96,2.13],[1,2.94,165.55],[2,2.78,2.66]],"ltp":3.45,"tv":3385.36,"id":9631939},{"batl":[[0,1.5,3.31],[1,1.51,23.01],[2,1.56,23.42]],"ltp":1.36,"tv":25130.71,"id":8681938}]}]}
{"op":"mcm","clk":"4297222936","pt":1632572346288,"mc":[{"id":"1.188134680","rc":[{"batb":[[0,1.32,1032.43],[1,1.31,1068.03],[2,1.3,474.36]],"ltp":1.36,"tv":25130.71,"id":8681938}]}]}
{"op":"mcm","clk":"4297223174","pt":1632572347365,"mc":[{"id":"1.188134680","rc":[{"trd":[[3.8,0.14]],"batb":[[0,4,4.94],[1,3.8,629.11],[2,3.75,976.98]],"batl":[[0,4.2,133.61]],"ltp":3.8,"tv":3385.5,"id":9631939},{"trd":[[1.36,1.17]],"batb":[[0,1.32,1032.03],[1,1.31,1226.54],[2,1.3,2313.3]],"batl":[[0,1.37,21.9],[1,1.47,27.81],[2,1.5,3]],"ltp":1.36,"tv":25131.1,"id":8681938}],"tv":28516.6}]}
{"op":"mcm","clk":"4297223380","pt":1632572348357,"mc":[{"id":"1.188134680","rc":[{"batb":[[1,3.8,251.64],[2,3.75,244.24]],"batl":[[0,4.1,12.64],[1,4.2,133.61],[2,4.3,106.77]],"ltp":3.8,"tv":3385.5,"id":9631939},{"batb":[[2,1.3,1694.07]],"batl":[[0,1.35,575.58],[1,1.36,542.21],[2,1.37,21.9]],"ltp":1.36,"tv":25131.1,"id":8681938}]}]}
{"op":"mcm","clk":"4297223606","pt":1632572349366,"mc":[{"id":"1.188134680","rc":[{"batb":[[0,1.32,1077.19],[2,1.3,1803.61]],"ltp":1.36,"tv":25131.1,"id":8681938}]}]}
{"op":"mcm","clk":"4297223655","pt":1632572349580,"mc":[{"id":"1.188134680","rc":[{"batl":[[0,4.1,15.64]],"ltp":3.8,"tv":3385.5,"id":9631939}]}]}
{"op":"mcm","clk":"4297224329","pt":1632572352177,"mc":[{"id":"1.188134680","rc":[{"batl":[[2,4.3,156.73]],"ltp":3.8,"tv":3385.5,"id":9631939},{"batl":[[0,1.34,57.43],[1,1.35,575.58],[2,1.36,542.21]],"ltp":1.36,"tv":25131.1,"id":8681938}]}]}
{"op":"mcm","clk":"4297224558","pt":1632572353162,"mc":[{"id":"1.188134680","rc":[{"batl":[[2,4.3,106.77]],"ltp":3.8,"tv":3385.5,"id":9631939},{"batl":[[0,1.35,575.58],[1,1.36,542.21],[2,1.37,21.9]],"ltp":1.36,"tv":25131.1,"id":8681938}]}]}
{"op":"mcm","clk":"4297225008","pt":1632572355163,"mc":[{"id":"1.188134680","rc":[{"trd":[[1.32,168.9]],"batb":[[0,1.32,1067.19],[2,1.3,1845.39]],"batl":[[0,1.34,251],[1,1.35,575.58],[2,1.36,542.21]],"ltp":1.32,"tv":25151.1,"id":8681938}],"tv":28536.6}]}
{"op":"mcm","clk":"4297225241","pt":1632572356158,"mc":[{"id":"1.188134680","rc":[{"batb":[[2,3.75,266.05]],"ltp":3.8,"tv":3385.5,"id":9631939},{"trd":[[1.34,0.12]],"batl":[[0,1.34,250.96]],"ltp":1.34,"tv":25151.18,"id":8681938}],"tv":28536.68}]}
{"op":"mcm","clk":"4297225474","pt":1632572357285,"mc":[{"id":"1.188134680","rc":[{"batb":[[0,1.33,2.74],[1,1.32,1069.94],[2,1.31,1226.54]],"ltp":1.34,"tv":25151.18,"id":8681938}]}]}
{"op":"mcm","clk":"4297225612","pt":1632572357886,"mc":[{"id":"1.188134680","rc":[{"batb":[[2,1.31,1229.28]],"ltp":1.34,"tv":25151.18,"id":8681938}]}]}
{"op":"mcm","clk":"4297226585","pt":1632572362074,"mc":[{"id":"1.188134680","rc":[{"trd":[[1.34,4.82]],"batl":[[0,1.34,444.65]],"ltp":1.34,"tv":25155.88,"id":8681938}],"tv":28541.38}]}
{"op":"mcm","clk":"4297227092","pt":1632572364381,"mc":[{"id":"1.188134680","rc":[{"batb":[[0,3.75,21.81],[1,3.7,92.67],[2,3.55,2]],"batl":[[1,4.2,125.21]],"ltp":3.8,"tv":3385.5,"id":9631939},{"batb":[[2,1.31,1070.77]],"ltp":1.34,"tv":25155.88,"id":8681938}]}]}
{"op":"mcm","clk":"4297227256","pt":1632572365075,"mc":[{"id":"1.188134680","rc":[{"batb":[[1,3.55,2],[2,3.4,2]],"batl":[[0,4.4,10.13],[1,4.5,97.57],[2,4.6,134.85]],"ltp":3.8,"tv":3385.5,"id":9631939},{"batb":[[1,1.32,2.74],[2,1.31,2.74]],"batl":[[0,1.34,683.65],[1,1.37,60],[2,1.39,36.5]],"ltp":1.34,"tv":25155.88,"id":8681938}]}]}
{"op":"mcm","clk":"4297227550","pt":1632572366302,"mc":[{"id":"1.188134680","rc":[{"batb":[[0,3.55,2],[1,3.4,2],[2,3.3,114.45]],"batl":[[0,4.4,2]],"ltp":3.8,"tv":3385.5,"id":9631939},{"batl":[[0,1.39,36.5],[1,1.41,31.5],[2,1.44,231.86]],"ltp":1.34,"tv":25155.88,"id":8681938}]}]}
{"op":"mcm","clk":"4297227630","pt":1632572366677,"mc":[{"id":"1.188134680","rc":[{"batb":[[0,3.4,2],[1,3.3,114.45],[2,3.25,270.6]],"ltp":3.8,"tv":3385.5,"id":9631939},{"batl":[[0,1.41,31.5],[1,1.44,231.86],[2,1.45,359.3]],"ltp":1.34,"tv":25155.88,"id":8681938}]}]}
{"op":"mcm","clk":"4297227997","pt":1632572368294,"mc":[{"id":"1.188134680","rc":[{"batb":[[1,3.25,126.57],[2,3.1,2.04]],"batl":[[0,4.3,2],[1,4.4,2],[2,4.5,97.57]],"ltp":3.8,"tv":3385.5,"id":9631939},{"batb":[[2,1.31,41.53]],"batl":[[1,1.47,27.81],[2,1.49,7]],"ltp":1.34,"tv":25155.88,"id":8681938}]}]}
{"op":"mcm","clk":"4297228070","pt":1632572368604,"mc":[{"id":"1.188134680","rc":[{"batb":[[2,2.98,3]],"batl":[[0,4.4,2],[1,4.5,97.57],[2,4.6,134.85]],"ltp":3.8,"tv":3385.5,"id":9631939},{"batb":[[2,1.31,2.74]],"batl":[[1,1.49,7.31],[2,1.93,2.55]],"ltp":1.34,"tv":25155.88,"id":8681938}]}]}
{"op":"mcm","clk":"4297228431","pt":1632572370287,"mc":[{"id":"1.188134680","rc":[{"batb":[[0,3.4,5],[1,3.35,3],[2,3.25,126.57]],"ltp":3.8,"tv":3385.5,"id":9631939},{"batb":[[0,1.3,990.54],[1,1.29,1088.05],[2,1.28,469.13]],"batl":[[0,1.41,33.5]],"ltp":1.34,"tv":25155.88,"id":8681938}]}]}
{"op":"mcm","clk":"4297228671","pt":1632572371274,"mc":[{"id":"1.188134680","rc":[{"batb":[[0,4.3,4.63],[1,4.1,48.55],[2,3.9,245.2]],"ltp":3.8,"tv":3385.5,"id":9631939},{"batb":[[1,1.29,1101.52],[2,1.28,1414.55]],"batl":[[0,1.33,7775.35],[1,1.34,603.04],[2,1.41,33.5]],"ltp":1.34,"tv":25155.88,"id":8681938}]}]}
{"op":"mcm","clk":"4297228880","pt":1632572372256,"mc":[{"id":"1.188134680","rc":[{"trd":[[4.3,49.17]],"batb":[[0,4.3,2.63],[2,3.9,409.48]],"batl":[[0,4.4,4],[2,4.6,142.75]],"ltp":4.3,"tv":3389.5,"id":9631939},{"batb":[[1,1.29,1613.48],[2,1.28,1527.93]],"batl":[[0,1.33,1349.28],[2,1.35,60]],"ltp":1.34,"tv":25155.88,"id":8681938}],"tv":28545.38}]}
{"op":"mcm","clk":"4297229112","pt":1632572373216,"mc":[{"id":"1.188134680","rc":[{"batl":[[0,4.4,14]],"ltp":4.3,"tv":3389.5,"id":9631939},{"batb":[[0,1.3,1033.03]],"ltp":1.34,"tv":25155.88,"id":8681938}]}]}
{"op":"mcm","clk":"4297229816","pt":1632572376342,"mc":[{"id":"1.188134680","rc":[{"trd":[[4.3,54.27]],"batb":[[0,4.1,48.63],[1,3.9,409.48],[2,3.85,237.98]],"ltp":4.3,"tv":3394.6,"id":9631939},{"batl":[[2,1.36,48.02]],"ltp":1.34,"tv":25155.88,"id":8681938}],"tv":28550.48}]}
{"op":"mcm","clk":"4297230164","pt":1632572377878,"mc":[{"id":"1.188134680","rc":[{"batb":[[2,3.85,239.98]],"batl":[[2,4.6,144.75]],"ltp":4.3,"tv":3394.6,"id":9631939},{"batb":[[1,1.29,1656.51],[2,1.28,1579.34]],"batl":[[2,1.35,34.1]],"ltp":1.34,"tv":25155.88,"id":8681938}]}]}
{"op":"mcm","clk":"4297230361","pt":1632572378842,"mc":[{"id":"1.188134680","rc":[{"batl":[[2,4.6,252.93]],"ltp":4.3,"tv":3394.6,"id":9631939},{"batb":[[2,1.28,1989.84]],"batl":[[0,1.32,235],[1,1.33,1349.28],[2,1.34,603.04]],"ltp":1.34,"tv":25155.88,"id":8681938}]}]}
{"op":"mcm","clk":"4297230581","pt":1632572379816,"mc":[{"id":"1.188134680","rc":[{"trd":[[4.3,54.28]],"batb":[[0,4.1,48.62],[1,3.95,20.33],[2,3.9,409.48]],"ltp":4.3,"tv":3394.61,"id":9631939},{"trd":[[1.31,758.96]],"batb":[[1,1.29,1613.48]],"batl":[[2,1.34,663.04]],"ltp":1.31,"tv":25155.92,"id":8681938}],"tv":28550.53}]}
{"op":"mcm","clk":"4297230948","pt":1632572381331,"mc":[{"id":"1.188134680","rc":[{"batl":[[1,1.33,795.31]],"ltp":1.31,"tv":25155.92,"id":8681938}]}]}
{"op":"mcm","clk":"4297231172","pt":1632572382241,"mc":[{"id":"1.188134680","rc":[{"batb":[[0,3.95,20.33],[1,3.85,2],[2,3.7,103.47]],"batl":[[0,4.4,2],[1,4.5,2],[2,4.6,118.08]],"ltp":4.3,"tv":3394.61,"id":9631939},{"batb":[[0,1.3,5.09],[1,1.29,955.16],[2,1.28,575.3]],"batl":[[1,1.34,60],[2,1.35,34.1]],"ltp":1.31,"tv":25155.92,"id":8681938}]}]}
{"op":"mcm","clk":"4297231425","pt":1632572383325,"mc":[{"id":"1.188134680","rc":[{"batb":[[0,3.85,2],[1,3.7,103.47],[2,3.65,124.09]],"batl":[[0,4.5,2],[1,4.6,110.18],[2,4.7,111.81]],"ltp":4.3,"tv":3394.61,"id":9631939},{"batb":[[0,1.31,2.74],[1,1.3,5.09],[2,1.29,955.16]],"batl":[[0,1.35,34.1],[1,1.37,362.86],[2,1.38,349.9]],"ltp":1.31,"tv":25155.92,"id":8681938}]}]}
{"op":"mcm","clk":"4297231613","pt":1632572384129,"mc":[{"id":"1.188134680","rc":[{"batb":[[0,3.7,103.47],[1,3.65,124.09],[2,3.6,2]],"ltp":4.3,"tv":3394.61,"id":9631939},{"batb":[[2,1.29,957.9]],"batl":[[0,1.37,362.86],[1,1.38,349.9],[2,1.39,7]],"ltp":1.31,"tv":25155.92,"id":8681938}]}]}
{"op":"mcm","clk":"4297232003","pt":1632572385894,"mc":[{"id":"1.188134680","rc":[{"batl":[[2,1.41,31.5]],"ltp":1.31,"tv":25155.92,"id":8681938}]}]}
{"op":"mcm","clk":"4297232345","pt":1632572387353,"mc":[{"id":"1.188134680","rc":[{"batb":[[0,3.7,105.47],[1,3.65,127.09]],"ltp":4.3,"tv":3394.61,"id":9631939},{"batb":[[1,1.3,875.87],[2,1.29,1292.84]],"batl":[[0,1.33,414.24],[1,1.34,585.99],[2,1.37,365.86]],"ltp":1.31,"tv":25155.92,"id":8681938}]}]}
{"op":"mcm","clk":"4297232767","pt":1632572389256,"mc":[{"id":"1.188134680","rc":[{"batb":[[0,3.75,32.42],[1,3.7,105.47],[2,3.65,127.09]],"batl":[[0,4.4,2],[1,4.5,2],[2,4.6,110.18]],"ltp":4.3,"tv":3394.61,"id":9631939},{"batb":[[1,1.3,915.45]],"batl":[[2,1.36,81.63]],"ltp":1.31,"tv":25155.92,"id":8681938}]}]}
{"op":"mcm","clk":"4297232997","pt":1632572390328,"mc":[{"id":"1.188134680","rc":[{"batb":[[0,3.85,2],[1,3.75,32.42],[2,3.7,105.47]],"ltp":4.3,"tv":3394.61,"id":9631939},{"batb":[[0,1.31,5.48]],"batl":[[2,1.35,39.7]],"ltp":1.31,"tv":25155.92,"id":8681938}]}]}
{"op":"mcm","clk":"4297233058","pt":1632572390652,"mc":[{"id":"1.188134680","rc":[{"batb":[[1,3.7,105.47],[2,3.65,127.09]],"ltp":4.3,"tv":3394.61,"id":9631939},{"batb":[[1,1.3,918.19]],"ltp":1.31,"tv":25155.92,"id":8681938}]}]}
{"op":"mcm","clk":"4297233451","pt":1632572392331,"mc":[{"id":"1.188134680","rc":[{"batl":[[0,4.4,12]],"ltp":4.3,"tv":3394.61,"id":9631939}]}]}
{"op":"mcm","clk":"4297233592","pt":1632572393044,"mc":[{"id":"1.188134680","rc":[{"batl":[[0,4.4,2]],"ltp":4.3,"tv":3394.61,"id":9631939},{"batb":[[1,1.3,920.93]],"batl":[[0,1.32,304],[1,1.33,414.24],[2,1.34,585.99]],"ltp":1.31,"tv":25155.92,"id":8681938}]}]}
{"op":"mcm","clk":"4297233854","pt":1632572394211,"mc":[{"id":"1.188134680","rc":[{"batb":[[0,3.9,10],[1,3.85,2],[2,3.7,105.47]],"batl":[[0,4.5,2],[1,4.6,110.18],[2,4.7,111.81]],"ltp":4.3,"tv":3394.61,"id":9631939},{"batb":[[1,1.3,10.57],[2,1.29,957.9]],"batl":[[1,1.35,39.7],[2,1.36,81.63]],"ltp":1.31,"tv":25155.92,"id":8681938}]}]}
{"op":"mcm","clk":"4297234240","pt":1632572396055,"mc":[{"id":"1.188134680","rc":[{"batl":[[0,1.32,622]],"ltp":1.31,"tv":25155.92,"id":8681938}]}]}
{"op":"mcm","clk":"4297234463","pt":1632572397045,"mc":[{"id":"1.188134680","rc":[{"batl":[[2,1.36,719.13]],"ltp":1.31,"tv":25155.92,"id":8681938}]}]}
{"op":"mcm","clk":"4297234948","pt":1632572399356,"mc":[{"id":"1.188134680","rc":[{"batl":[[0,4.4,10],[1,4.5,2],[2,4.6,110.18]],"ltp":4.3,"tv":3394.61,"id":9631939}]}]}
{"op":"mcm","clk":"4297235066","pt":1632572399945,"mc":[{"id":"1.188134680","rc":[{"batb":[[0,3.85,2],[1,3.7,105.47],[2,3.65,124.09]],"batl":[[0,4.5,2],[1,4.6,110.18],[2,4.7,111.81]],"ltp":4.3,"tv":3394.61,"id":9631939},{"batl":[[2,1.36,637.5]],"ltp":1.31,"tv":25155.92,"id":8681938}]}]}
{"op":"mcm","clk":"4297235365","pt":1632572401159,"mc":[{"id":"1.188134680","rc":[{"batb":[[0,3.7,105.47],[1,3.65,124.09],[2,3.55,100.62]],"batl":[[0,4.4,2],[1,4.5,2],[2,4.6,110.18]],"ltp":4.3,"tv":3394.61,"id":9631939},{"batb":[[1,1.3,55.05]],"batl":[[0,1.36,637.5],[1,1.37,888.98],[2,1.38,347.9]],"ltp":1.31,"tv":25155.92,"id":8681938}]}]}
{"op":"mcm","clk":"4297235515","pt":1632572401760,"mc":[{"id":"1.188134680","rc":[{"batl":[[0,4.5,2],[1,4.6,110.18],[2,4.7,111.81]],"ltp":4.3,"tv":3394.61,"id":9631939},{"batb":[[1,1.3,10.57]],"ltp":1.31,"tv":25155.92,"id":8681938}]}]}
{"op":"mcm","clk":"4297236086","pt":1632572404252,"mc":[{"id":"1.188134680","rc":[{"batb":[[0,3.85,2],[1,3.75,3],[2,3.7,105.47]],"ltp":4.3,"tv":3394.61,"id":9631939},{"batl":[[0,1.35,31.7],[1,1.36,642.5],[2,1.37,888.98]],"ltp":1.31,"tv":25155.92,"id":8681938}]}]}
{"op":"mcm","clk":"4297236298","pt":1632572405165,"mc":[{"id":"1.188134680","rc":[{"batb":[[0,3.75,3],[1,3.7,105.47],[2,3.65,124.09]],"ltp":4.3,"tv":3394.61,"id":9631939},{"batl":[[0,1.36,642.5],[1,1.37,888.98],[2,1.38,347.9]],"ltp":1.31,"tv":25155.92,"id":8681938}]}]}
{"op":"mcm","clk":"4297236576","pt":1632572406253,"mc":[{"id":"1.188134680","rc":[{"batl":[[0,4.1,20.56],[1,4.5,2],[2,4.6,110.18]],"ltp":4.3,"tv":3394.61,"id":9631939}]}]}
{"op":"mcm","clk":"4297237041","pt":1632572408155,"mc":[{"id":"1.188134680","rc":[{"batl":[[2,4.6,2]],"ltp":4.3,"tv":3394.61,"id":9631939},{"batb":[[2,1.29,554.51]],"ltp":1.31,"tv":25155.92,"id":8681938}]}]}
{"op":"mcm","clk":"4297237318","pt":1632572409356,"mc":[{"id":"1.188134680","rc":[{"batl":[[0,4.4,2]],"ltp":4.3,"tv":3394.61,"id":9631939}]}]}
{"op":"mcm","clk":"4297237554","pt":1632572410379,"mc":[{"id":"1.188134680","rc":[{"batb":[[0,3.9,6.24],[1,3.75,3],[2,3.7,105.47]],"batl":[[0,4.1,2271.58],[1,4.2,338.9],[2,4.3,1259.14]],"ltp":4.3,"tv":3394.61,"id":9631939},{"batb":[[0,1.33,425.62],[1,1.32,676.85],[2,1.31,5.48]],"batl":[[0,1.36,824.44]],"ltp":1.31,"tv":25155.92,"id":8681938}]}]}
{"op":"mcm","clk":"4297237785","pt":1632572411371,"mc":[{"id":"1.188134680","rc":[{"batb":[[1,3.7,103.47],[2,3.65,124.09]],"batl":[[0,4.1,122.38],[1,4.2,109.64],[2,4.3,251.83]],"ltp":4.3,"tv":3394.61,"id":9631939},{"batb":[[0,1.34,417.43],[1,1.33,425.62],[2,1.32,676.85]],"batl":[[0,1.36,819.44],[1,1.37,2623.2],[2,1.38,1205.56]],"ltp":1.31,"tv":25155.92,"id":8681938}]}]}
{"op":"mcm","clk":"4297238041","pt":1632572412350,"mc":[{"id":"1.188134680","rc":[{"batb":[[2,3.65,146.73]],"batl":[[0,4.1,229.11]],"ltp":4.3,"tv":3394.61,"id":9631939},{"batb":[[2,1.32,704.25]],"batl":[[1,1.37,1250.94],[2,1.38,579.44]],"ltp":1.31,"tv":25155.92,"id":8681938}]}]}
{"op":"mcm","clk":"4297238507","pt":1632572414256,"mc":[{"id":"1.188134680","rc":[{"batb":[[1,1.33,432.62],[2,1.32,711.25]],"ltp":1.31,"tv":25155.92,"id":8681938}]}]}
{"op":"mcm","clk":"4297238781","pt":1632572415377,"mc":[{"id":"1.188134680","rc":[{"trd":[[1.34,124.84]],"batb":[[0,1.34,357.42]],"ltp":1.34,"tv":25275.94,"id":8681938}],"tv":28670.55}]}
{"op":"mcm","clk":"4297239270","pt":1632572417381,"mc":[{"id":"1.188134680","rc":[{"batl":[[2,4.3,253.83]],"ltp":4.3,"tv":3394.61,"id":9631939}]}]}
{"op":"mcm","clk":"4297239354","pt":1632572417763,"mc":[{"id":"1.188134680","rc":[{"batl":[[2,4.3,262.08]],"ltp":4.3,"tv":3394.61,"id":9631939},{"batl":[[0,1.35,297],[1,1.36,819.44],[2,1.37,1250.94]],"ltp":1.34,"tv":25275.94,"id":8681938}]}]}
{"op":"mcm","clk":"4297240338","pt":1632572422202,"mc":[{"id":"1.188134680","rc":[{"batl":[[0,1.35,465]],"ltp":1.34,"tv":25275.94,"id":8681938}]}]}
{"op":"mcm","clk":"4297241119","pt":1632572425441,"mc":[{"id":"1.188134680","rc":[{"batb":[[2,1.32,704.25]],"ltp":1.34,"tv":25275.94,"id":8681938}]}]}
{"op":"mcm","clk":"4297241967","pt":1632572429212,"mc":[{"id":"1.188134680","rc":[{"batl":[[1,4.2,130.2]],"ltp":4.3,"tv":3394.61,"id":9631939}]}]}
{"op":"mcm","clk":"4297242707","pt":1632572432248,"mc":[{"id":"1.188134680","rc":[{"trd":[[3.9,12.49]],"batb":[[0,3.7,103.47],[1,3.65,146.73],[2,3.55,102.68]],"ltp":3.9,"tv":3407.09,"id":9631939}],"tv":28683.03}]}
{"op":"mcm","clk":"4297242750","pt":1632572432414,"mc":[{"id":"1.188134680","rc":[{"batl":[[2,1.37,1310.94]],"ltp":1.34,"tv":25275.94,"id":8681938}]}]}
{"op":"mcm","clk":"4297243638","pt":1632572436218,"mc":[{"id":"1.188134680","rc":[{"batb":[[0,3.65,22.64],[1,3.55,2.06],[2,3.4,2]],"batl":[[0,4.1,88.4],[1,4.2,20.56],[2,4.3,35.02]],"ltp":3.9,"tv":3407.09,"id":9631939},{"batb":[[0,1.31,536.85],[1,1.3,2.35],[2,1.29,361.5]],"batl":[[1,1.37,60],[2,1.39,30.5]],"ltp":1.34,"tv":25275.94,"id":8681938}]}]}
{"op":"mcm","clk":"4297243887","pt":1632572437244,"mc":[{"id":"1.188134680","rc":[{"batb":[[0,3.55,2.06],[1,3.4,2],[2,3.15,248.89]],"batl":[[0,4.2,20.56],[1,4.3,2],[2,4.4,85.06]],"ltp":3.9,"tv":3407.09,"id":9631939},{"batl":[[0,1.39,30.5],[1,1.41,31.5],[2,1.46,318.29]],"ltp":1.34,"tv":25275.94,"id":8681938}]}]}
{"op":"mcm","clk":"4297243950","pt":1632572437526,"mc":[{"id":"1.188134680","rc":[{"batb":[[0,3.4,2],[1,3.15,248.89],[2,3.1,127.35]],"ltp":3.9,"tv":3407.09,"id":9631939},{"batl":[[0,1.41,31.5],[1,1.46,318.29],[2,1.47,293.61]],"ltp":1.34,"tv":25275.94,"id":8681938}]}]}
{"op":"mcm","clk":"4297244335","pt":1632572439348,"mc":[{"id":"1.188134680","rc":[{"batb":[[0,3.5,3],[1,3.45,3],[2,3.4,2]],"ltp":3.9,"tv":3407.09,"id":9631939},{"batb":[[0,1.31,602.24],[1,1.3,805.61],[2,1.29,1097.2]],"batl":[[1,1.43,407.77],[2,1.44,418.52]],"ltp":1.34,"tv":25275.94,"id":8681938}]}]}
{"op":"mcm","clk":"4297244427","pt":1632572439737,"mc":[{"id":"1.188134680","rc":[{"batb":[[0,1.31,503.48],[1,1.3,814.61]],"ltp":1.34,"tv":25275.94,"id":8681938}]}]}
{"op":"mcm","clk":"4297244768","pt":1632572441146,"mc":[{"id":"1.188134680","rc":[{"batb":[[2,3.4,5]],"ltp":3.9,"tv":3407.09,"id":9631939},{"batl":[[0,1.4,6],[1,1.41,38.5],[2,1.43,407.77]],"ltp":1.34,"tv":25275.94,"id":8681938}]}]}
{"op":"mcm","clk":"4297244999","pt":1632572442180,"mc":[{"id":"1.188134680","rc":[{"batb":[[0,1.32,42.05],[1,1.31,503.48],[2,1.3,814.61]],"ltp":1.34,"tv":25275.94,"id":8681938}]}]}
{"op":"mcm","clk":"4297245437","pt":1632572444378,"mc":[{"id":"1.188134680","rc":[{"batb":[[0,3.55,2.08],[1,3.5,3],[2,3.45,3]],"ltp":3.9,"tv":3407.09,"id":9631939},{"batl":[[0,1.39,31.5],[1,1.4,6],[2,1.41,7]],"ltp":1.34,"tv":25275.94,"id":8681938}]}]}
{"op":"mcm","clk":"4297245666","pt":1632572445360,"mc":[{"id":"1.188134680","rc":[{"batb":[[0,3.5,3],[1,3.45,3],[2,3.4,5]],"ltp":3.9,"tv":3407.09,"id":9631939},{"batb":[[1,1.31,44.79]],"batl":[[0,1.4,6],[1,1.41,7],[2,1.93,2.86]],"ltp":1.34,"tv":25275.94,"id":8681938}]}]}
{"op":"mcm","clk":"4297245710","pt":1632572445579,"mc":[{"id":"1.188134680","rc":[{"batb":[[0,1.31,44.79],[1,1.3,814.61],[2,1.29,1097.2]],"ltp":1.34,"tv":25275.94,"id":8681938}]}]}
{"op":"mcm","clk":"4297246088","pt":1632572447379,"mc":[{"id":"1.188134680","rc":[{"batb":[[0,3.9,245.2],[1,3.85,237.98],[2,3.8,237.98]],"ltp":3.9,"tv":3407.09,"id":9631939},{"batb":[[0,1.31,35.79]],"batl":[[0,1.33,497.28],[1,1.34,585.73],[2,1.4,6]],"ltp":1.34,"tv":25275.94,"id":8681938}]}]}
{"op":"mcm","clk":"4297246296","pt":1632572448281,"mc":[{"id":"1.188134680","rc":[{"batb":[[1,3.85,259.03]],"ltp":3.9,"tv":3407.09,"id":9631939},{"batl":[[2,1.35,60]],"ltp":1.34,"tv":25275.94,"id":8681938}]}]}
{"op":"mcm","clk":"4297246441","pt":1632572448992,"mc":[{"id":"1.188134680","rc":[{"batb":[[1,3.85,237.98]],"ltp":3.9,"tv":3407.09,"id":9631939},{"batl":[[2,1.39,30]],"ltp":1.34,"tv":25275.94,"id":8681938}]}]}
{"op":"mcm","clk":"4297247198","pt":1632572452372,"mc":[{"id":"1.188134680","rc":[{"batb":[[0,3.9,262.21]],"ltp":3.9,"tv":3407.09,"id":9631939},{"trd":[[1.32,253]],"batl":[[0,1.32,237.95],[1,1.33,497.28],[2,1.34,585.73]],"ltp":1.32,"tv":25360.04,"id":8681938}],"tv":28767.14}]}
{"op":"mcm","clk":"4297247539","pt":1632572453891,"mc":[{"id":"1.188134680","rc":[{"batl":[[2,4.4,87.06]],"ltp":3.9,"tv":3407.09,"id":9631939},{"batb":[[1,1.3,851.19]],"ltp":1.32,"tv":25360.04,"id":8681938}]}]}
{"op":"mcm","clk":"4297247719","pt":1632572454655,"mc":[{"id":"1.188134680","rc":[{"batl":[[0,1.32,473.95]],"ltp":1.32,"tv":25360.04,"id":8681938}]}]}
{"op":"mcm","clk":"4297248542","pt":1632572458609,"mc":[{"id":"1.188134680","rc":[{"batb":[[1,1.3,848.84]],"ltp":1.32,"tv":25360.04,"id":8681938}]}]}
{"op":"mcm","clk":"4297248901","pt":1632572460291,"mc":[{"id":"1.188134680","rc":[{"trd":[[1.32,273]],"batl":[[0,1.32,463.95]],"ltp":1.32,"tv":25380.04,"id":8681938}],"tv":28787.14}]}
{"op":"mcm","clk":"4297250310","pt":1632572466404,"mc":[{"id":"1.188134680","rc":[{"trd":[[1.32,277.7]],"batl":[[0,1.32,461.6]],"ltp":1.32,"tv":25384.74,"id":8681938}],"tv":28791.83}]}
{"op":"mcm","clk":"4297251156","pt":1632572470200,"mc":[{"id":"1.188134680","rc":[{"trd":[[1.31,768.34]],"batb":[[0,1.31,31.1]],"ltp":1.31,"tv":25394.12,"id":8681938}],"tv":28801.21}]}
{"op":"mcm","clk":"4297252213","pt":1632572475212,"mc":[{"id":"1.188134680","rc":[{"batb":[[0,3.65,96.56],[1,3.6,2],[2,3.55,135.66]],"batl":[[1,4.5,2],[2,5.1,78.72]],"ltp":3.9,"tv":3407.09,"id":9631939},{"batb":[[0,1.29,39.81],[1,1.27,600],[2,1.25,621.37]],"batl":[[1,1.38,34.25],[2,1.39,390.89]],"ltp":1.31,"tv":25394.12,"id":8681938}]}]}
{"op":"mcm","clk":"4297252309","pt":1632572475597,"mc":[{"id":"1.188134680","rc":[{"batl":[[0,1.38,34.25],[1,1.39,390.89],[2,1.4,338.55]],"ltp":1.31,"tv":25394.12,"id":8681938}]}]}
{"op":"mcm","clk":"4297252842","pt":1632572478300,"mc":[{"id":"1.188134680","rc":[{"batb":[[0,1.3,37.48],[1,1.29,39.81],[2,1.27,600]],"batl":[[0,1.36,726.15],[1,1.37,523.32],[2,1.38,34.25]],"ltp":1.31,"tv":25394.12,"id":8681938}]}]}
{"op":"mcm","clk":"4297252951","pt":1632572478812,"mc":[{"id":"1.188134680","rc":[{"batl":[[1,4.4,2],[2,4.5,2]],"ltp":3.9,"tv":3407.09,"id":9631939},{"batl":[[2,1.38,40.25]],"ltp":1.31,"tv":25394.12,"id":8681938}]}]}
{"op":"mcm","clk":"4297253499","pt":1632572481387,"mc":[{"id":"1.188134680","rc":[{"batb":[[2,1.25,621.37]],"ltp":1.31,"tv":25394.12,"id":8681938}]}]}
{"op":"mcm","clk":"4297253925","pt":1632572483289,"mc":[{"id":"1.188134680","rc":[{"batb":[[0,3.65,751.52],[1,3.6,256.28],[2,3.55,771.36]],"batl":[[0,3.8,3.52],[1,4,7.79],[2,4.2,72.96]],"ltp":3.9,"tv":3407.09,"id":9631939},{"trd":[[1.36,60.03]],"batb":[[0,1.33,333.43],[1,1.32,2135.08],[2,1.31,703.12]],"batl":[[0,1.36,887.44],[2,1.38,34.25]],"ltp":1.36,"tv":25452.98,"id":8681938}],"tv":28860.07}]}
{"op":"mcm","clk":"4297254151","pt":1632572484316,"mc":[{"id":"1.188134680","rc":[{"batb":[[0,3.65,381.18],[2,3.55,389.94]],"batl":[[0,4,7.79],[1,4.2,72.96],[2,4.3,33.02]],"ltp":3.9,"tv":3407.09,"id":9631939},{"batb":[[0,1.33,763.62],[2,1.31,3522.47]],"batl":[[1,1.37,545.22],[2,1.38,94.25]],"ltp":1.36,"tv":25452.98,"id":8681938}]}]}
{"op":"mcm","clk":"4297254370","pt":1632572485182,"mc":[{"id":"1.188134680","rc":[{"batb":[[0,3.7,17.6],[1,3.65,381.18],[2,3.6,256.28]],"batl":[[1,4.1,17.53],[2,4.2,72.96]],"ltp":3.9,"tv":3407.09,"id":9631939},{"batb":[[0,1.33,777.33],[2,1.31,3606.15]],"ltp":1.36,"tv":25452.98,"id":8681938}]}]}
{"op":"mcm","clk":"4297254605","pt":1632572486199,"mc":[{"id":"1.188134680","rc":[{"batb":[[0,1.33,763.62],[1,1.32,2145.08],[2,1.31,3532.47]],"ltp":1.36,"tv":25452.98,"id":8681938}]}]}
{"op":"mcm","clk":"4297255278","pt":1632572489108,"mc":[{"id":"1.188134680","rc":[{"batb":[[0,1.34,13.71],[1,1.33,801.19],[2,1.32,2145.08]],"ltp":1.36,"tv":25452.98,"id":8681938}]}]}
{"op":"mcm","clk":"4297255495","pt":1632572489927,"mc":[{"id":"1.188134680","rc":[{"batl":[[0,1.35,311],[1,1.36,887.44],[2,1.37,545.22]],"ltp":1.36,"tv":25452.98,"id":8681938}]}]}
{"op":"mcm","clk":"4297256124","pt":1632572492334,"mc":[{"id":"1.188134680","rc":[{"batb":[[0,3.65,119.2],[1,3.6,2],[2,3.55,2.06]],"batl":[[0,4.2,20.56],[1,4.3,33.02],[2,4.4,3.71]],"ltp":3.9,"tv":3407.09,"id":9631939},{"batb":[[1,1.33,430.19],[2,1.32,10]],"batl":[[1,1.38,94.25],[2,1.39,31.5]],"ltp":1.36,"tv":25452.98,"id":8681938}]}]}
{"op":"mcm","clk":"4297256372","pt":1632572493319,"mc":[{"id":"1.188134680","rc":[{"batb":[[0,3.6,2],[1,3.55,2.06],[2,3.5,112]],"batl":[[1,4.4,3.71],[2,4.5,2]],"ltp":3.9,"tv":3407.09,"id":9631939},{"batb":[[0,1.3,37.48],[1,1.29,39.81],[2,1.28,573.99]],"batl":[[0,1.35,610],[1,1.38,34.25]],"ltp":1.36,"tv":25452.98,"id":8681938}]}]}
{"op":"mcm","clk":"4297256512","pt":1632572493961,"mc":[{"id":"1.188134680","rc":[{"batb":[[0,3.7,2],[1,3.5,112],[2,3.4,2]],"ltp":3.9,"tv":3407.09,"id":9631939},{"batl":[[0,1.37,31.5],[1,1.4,39.34],[2,1.41,29.5]],"ltp":1.36,"tv":25452.98,"id":8681938}]}]}
{"op":"mcm","clk":"4297256850","pt":1632572495226,"mc":[{"id":"1.188134680","rc":[{"batl":[[0,3.75,21.97],[1,4.2,20.56],[2,4.4,2]],"ltp":3.9,"tv":3407.09,"id":9631939},{"batb":[[2,1.28,1526.3]],"batl":[[1,1.38,728.75],[2,1.39,489.25]],"ltp":1.36,"tv":25452.98,"id":8681938}]}]}
{"op":"mcm","clk":"4297257049","pt":1632572496030,"mc":[{"id":"1.188134680","rc":[{"batb":[[2,2.62,386.89]],"ltp":3.9,"tv":3407.09,"id":9631939},{"batb":[[0,1.34,40.31],[1,1.3,37.48],[2,1.29,39.81]],"ltp":1.36,"tv":25452.98,"id":8681938}]}]}
{"op":"mcm","clk":"4297257609","pt":1632572498331,"mc":[{"id":"1.188134680","rc":[{"batb":[[1,3.6,54.5],[2,3.5,112]],"batl":[[0,3.75,1281.89],[1,3.85,2383.52],[2,3.9,305.2]],"ltp":3.9,"tv":3407.09,"id":9631939},{"batb":[[0,1.34,154.93],[1,1.31,44.21],[2,1.3,37.48]],"ltp":1.36,"tv":25452.98,"id":8681938}]}]}
{"op":"mcm","clk":"4297257828","pt":1632572499308,"mc":[{"id":"1.188134680","rc":[{"batb":[[2,3.5,780.44]],"batl":[[0,3.75,279.21],[1,3.85,122.08],[2,3.9,61.04]],"ltp":3.9,"tv":3407.09,"id":9631939},{"batb":[[0,1.35,399],[1,1.34,982.66],[2,1.33,627.04]],"ltp":1.36,"tv":25452.98,"id":8681938}]}]}
{"op":"mcm","clk":"4297258030","pt":1632572500231,"mc":[{"id":"1.188134680","rc":[{"batb":[[2,3.5,267.28]],"batl":[[0,3.75,257.24]],"ltp":3.9,"tv":3407.09,"id":9631939}]}]}
{"op":"mcm","clk":"4297258287","pt":1632572501314,"mc":[{"id":"1.188134680","rc":[{"batb":[[1,1.34,1037.96]],"ltp":1.36,"tv":25452.98,"id":8681938}]}]}
{"op":"mcm","clk":"4297258765","pt":1632572503310,"mc":[{"id":"1.188134680","rc":[{"trd":[[3.7,23.97],[3.75,0.41]],"batb":[[0,3.6,54.5],[1,3.5,267.28],[2,3.45,70.14]],"batl":[[0,3.75,256.83]],"ltp":3.75,"tv":3431.46,"id":9631939},{"trd":[[1.36,61.16],[1.37,55.19]],"batl":[[0,1.38,728.75],[1,1.39,489.25],[2,1.4,114.77]],"ltp":1.36,"tv":25508.04,"id":8681938}],"tv":28939.51}]}
{"op":"mcm","clk":"4297258978","pt":1632572504224,"mc":[{"id":"1.188134680","rc":[{"trd":[[3.75,103.94]],"batl":[[0,3.75,153.3]],"ltp":3.75,"tv":3534.99,"id":9631939},{"trd":[[1.36,346.63]],"batb":[[0,1.37,37.04],[1,1.35,399],[2,1.34,1037.96]],"ltp":1.36,"tv":25793.51,"id":8681938}],"tv":29328.51}]}
{"op":"mcm","clk":"4297259457","pt":1632572506230,"mc":[{"id":"1.188134680","rc":[{"batb":[[0,3.6,56.5],[1,3.55,2],[2,3.5,267.28]],"ltp":3.75,"tv":3534.99,"id":9631939},{"trd":[[1.37,55.27]],"batb":[[0,1.37,37]],"batl":[[0,1.38,759],[1,1.39,517.75]],"ltp":1.37,"tv":25793.59,"id":8681938}],"tv":29328.59}]}
{"op":"mcm","clk":"4297259731","pt":1632572507332,"mc":[{"id":"1.188134680","rc":[{"batb":[[0,3.55,2],[1,3.5,133],[2,3.45,3]],"batl":[[0,4,102.63],[1,4.1,131.64],[2,4.2,20.56]],"ltp":3.75,"tv":3534.99,"id":9631939},{"batb":[[2,1.33,363.41]],"batl":[[0,1.38,154],[2,1.4,93.34]],"ltp":1.37,"tv":25793.59,"id":8681938}]}]}
{"op":"mcm","clk":"4297259939","pt":1632572508258,"mc":[{"id":"1.188134680","rc":[{"batb":[[1,3.5,2.04]],"ltp":3.75,"tv":3534.99,"id":9631939},{"batb":[[0,1.33,363.41],[1,1.32,324.33],[2,1.31,510.61]],"batl":[[2,1.4,33.34]],"ltp":1.37,"tv":25793.59,"id":8681938}]}]}
{"op":"mcm","clk":"4297260021","pt":1632572508621,"mc":[{"id":"1.188134680","rc":[{"batl":[[0,1.39,517.75],[1,1.4,33.34],[2,1.43,272.27]],"ltp":1.37,"tv":25793.59,"id":8681938}]}]}
{"op":"mcm","clk":"4297260385","pt":1632572510337,"mc":[{"id":"1.188134680","rc":[{"batb":[[0,3.6,3],[1,3.55,5],[2,3.5,2.04]],"batl":[[1,4.1,165.71]],"ltp":3.75,"tv":3534.99,"id":9631939},{"batb":[[0,1.35,39.16],[1,1.33,363.41],[2,1.32,324.33]],"batl":[[0,1.38,6],[1,1.39,586.24],[2,1.4,508.86]],"ltp":1.37,"tv":25793.59,"id":8681938}]}]}
{"op":"mcm","clk":"4297260524","pt":1632572510945,"mc":[{"id":"1.188134680","rc":[{"batb":[[0,3.55,2],[1,3.5,5.04],[2,3.45,3]],"batl":[[1,4.1,131.64]],"ltp":3.75,"tv":3534.99,"id":9631939},{"batb":[[1,1.33,373.41],[2,1.32,334.33]],"batl":[[0,1.39,586.24],[1,1.4,508.86],[2,1.43,272.27]],"ltp":1.37,"tv":25793.59,"id":8681938}]}]}
{"op":"mcm","clk":"4297260825","pt":1632572512080,"mc":[{"id":"1.188134680","rc":[{"batl":[[0,1.39,36.5],[1,1.4,33.34]],"ltp":1.37,"tv":25793.59,"id":8681938}]}]}
{"op":"mcm","clk":"4297261315","pt":1632572514346,"mc":[{"id":"1.188134680","rc":[{"batb":[[0,3.6,2],[1,3.55,2],[2,3.5,5.04]],"ltp":3.75,"tv":3534.99,"id":9631939},{"batb":[[0,1.33,373.41],[1,1.32,334.33],[2,1.31,510.61]],"batl":[[0,1.38,35.75],[1,1.39,36.5],[2,1.4,33.34]],"ltp":1.37,"tv":25793.59,"id":8681938}]}]}
{"op":"mcm","clk":"4297261524","pt":1632572515314,"mc":[{"id":"1.188134680","rc":[{"batb":[[0,3.55,2],[1,3.5,5.04],[2,3.4,113.55]],"ltp":3.75,"tv":3534.99,"id":9631939},{"batb":[[0,1.34,451.61],[1,1.33,995.39],[2,1.32,334.33]],"batl":[[0,1.37,559.22],[1,1.38,507.71],[2,1.39,36.5]],"ltp":1.37,"tv":25793.59,"id":8681938}]}]}
{"op":"mcm","clk":"4297261699","pt":1632572516217,"mc":[{"id":"1.188134680","rc":[{"batb":[[0,3.6,10],[1,3.55,2],[2,3.5,5.04]],"batl":[[0,3.95,15.31],[1,4,102.63],[2,4.1,131.64]],"ltp":3.75,"tv":3534.99,"id":9631939},{"batb":[[0,1.34,491.92]],"batl":[[1,1.38,546]],"ltp":1.37,"tv":25793.59,"id":8681938}]}]}
{"op":"mcm","clk":"4297261934","pt":1632572517332,"mc":[{"id":"1.188134680","rc":[{"trd":[[1.37,56.67]],"batb":[[0,1.34,534.89]],"batl":[[0,1.37,558.52]],"ltp":1.37,"tv":25795.0,"id":8681938}],"tv":29329.99}]}
{"op":"mcm","clk":"4297262057","pt":1632572517858,"mc":[{"id":"1.188134680","rc":[{"batb":[[0,3.6,12]],"ltp":3.75,"tv":3534.99,"id":9631939},{"batl":[[1,1.38,576.75]],"ltp":1.37,"tv":25795.0,"id":8681938}]}]}
{"op":"mcm","clk":"4297262366","pt":1632572519369,"mc":[{"id":"1.188134680","rc":[{"batb":[[0,3.6,2]],"batl":[[0,4,102.63],[1,4.1,131.64],[2,4.2,20.56]],"ltp":3.75,"tv":3534.99,"id":9631939},{"trd":[[1.37,587.63]],"batb":[[0,1.34,491.92]],"batl":[[0,1.37,293.04],[1,1.38,538.46]],"ltp":1.37,"tv":26325.95,"id":8681938}],"tv":29860.95}]}
{"op":"mcm","clk":"4297262442","pt":1632572519732,"mc":[{"id":"1.188134680","rc":[{"batb":[[0,3.55,2],[1,3.5,5.04],[2,3.4,113.55]],"ltp":3.75,"tv":3534.99,"id":9631939},{"batb":[[0,1.34,40.31],[1,1.33,373.41]],"batl":[[0,1.36,225],[1,1.39,36.5],[2,1.4,33.34]],"ltp":1.37,"tv":26325.95,"id":8681938}]}]}
{"op":"mcm","clk":"4297262620","pt":1632572520636,"mc":[{"id":"1.188134680","rc":[{"batl":[[0,1.39,36.5],[1,1.4,33.34],[2,1.43,272.27]],"ltp":1.37,"tv":26325.95,"id":8681938}]}]}
{"op":"mcm","clk":"4297262971","pt":1632572522315,"mc":[{"id":"1.188134680","rc":[{"batl":[[0,1.39,593.86],[1,1.4,508.86]],"ltp":1.37,"tv":26325.95,"id":8681938}]}]}
{"op":"mcm","clk":"4297263187","pt":1632572523335,"mc":[{"id":"1.188134680","rc":[{"batb":[[2,1.32,698.92]],"batl":[[0,1.39,36.5]],"ltp":1.37,"tv":26325.95,"id":8681938}]}]}
{"op":"mcm","clk":"4297263796","pt":1632572526035,"mc":[{"id":"1.188134680","rc":[{"batl":[[0,4.2,20.56],[1,4.3,2],[2,4.4,2]],"ltp":3.75,"tv":3534.99,"id":9631939},{"batb":[[1,1.33,10],[2,1.31,510.61]],"batl":[[0,1.39,449.26]],"ltp":1.37,"tv":26325.95,"id":8681938}]}]}
{"op":"mcm","clk":"4297263964","pt":1632572526847,"mc":[{"id":"1.188134680","rc":[{"batb":[[1,3.5,2.04]],"ltp":3.75,"tv":3534.99,"id":9631939},{"batl":[[0,1.39,441.26]],"ltp":1.37,"tv":26325.95,"id":8681938}]}]}
{"op":"mcm","clk":"4297264485","pt":1632572529262,"mc":[{"id":"1.188134680","rc":[{"batb":[[0,3.55,5]],"batl":[[0,3.6,5.31],[1,3.7,336.49],[2,3.75,63.52]],"ltp":3.75,"tv":3534.99,"id":9631939},{"batb":[[0,1.36,627.35],[1,1.35,607.85],[2,1.34,40.31]],"batl":[[2,1.41,207.95]],"ltp":1.37,"tv":26325.95,"id":8681938}]}]}
{"op":"mcm","clk":"4297264723","pt":1632572530265,"mc":[{"id":"1.188134680","rc":[{"batb":[[0,3.55,2],[2,3.45,24.48]],"ltp":3.75,"tv":3534.99,"id":9631939},{"batb":[[0,1.36,1009.1],[1,1.35,678],[2,1.34,3180.5]],"batl":[[2,1.41,289.23]],"ltp":1.37,"tv":26325.95,"id":8681938}]}]}
{"op":"mcm","clk":"4297264959","pt":1632572531025,"mc":[{"id":"1.188134680","rc":[{"batb":[[0,1.37,41.01],[1,1.36,1009.1],[2,1.35,615.85]],"ltp":1.37,"tv":26325.95,"id":8681938}]}]}
{"op":"mcm","clk":"4297265241","pt":1632572532257,"mc":[{"id":"1.188134680","rc":[{"batb":[[2,3.4,113.55]],"ltp":3.75,"tv":3534.99,"id":9631939},{"batb":[[0,1.37,3.97]],"ltp":1.37,"tv":26325.95,"id":8681938}]}]}
{"op":"mcm","clk":"4297265596","pt":1632572533761,"mc":[{"id":"1.188134680","rc":[{"trd":[[3.6,5.31]],"batl":[[0,3.7,336.49],[1,3.75,63.52],[2,3.8,63.52]],"ltp":3.6,"tv":3540.3,"id":9631939},{"trd":[[1.38,13.94]],"batb":[[1,1.36,1071.25]],"ltp":1.38,"tv":26339.81,"id":8681938}],"tv":29880.12}]}
{"op":"mcm","clk":"4297265946","pt":1632572535365,"mc":[{"id":"1.188134680","rc":[{"batb":[[2,3.4,138.55]],"ltp":3.6,"tv":3540.3,"id":9631939},{"batb":[[0,1.38,36.07],[1,1.37,3.97],[2,1.36,1071.25]],"ltp":1.38,"tv":26339.81,"id":8681938}]}]}
{"op":"mcm","clk":"4297266046","pt":1632572535752,"mc":[{"id":"1.188134680","rc":[{"batl":[[1,3.75,158.96],[2,3.8,201.73]],"ltp":3.6,"tv":3540.3,"id":9631939},{"batb":[[2,1.36,1342.29]],"batl":[[0,1.39,607.26]],"ltp":1.38,"tv":26339.81,"id":8681938}]}]}
{"op":"mcm","clk":"4297266634","pt":1632572538331,"mc":[{"id":"1.188134680","rc":[{"trd":[[3.7,135.19]],"batl":[[0,3.7,225.27]],"ltp":3.7,"tv":3651.52,"id":9631939},{"trd":[[1.37,895.96],[1.38,86.08]],"batb":[[0,1.38,400],[1,1.36,1342.29],[2,1.35,958.38]],"ltp":1.37,"tv":26720.28,"id":8681938}],"tv":30371.81}]}
{"op":"mcm","clk":"4297266800","pt":1632572539029,"mc":[{"id":"1.188134680","rc":[{"trd":[[1.38,86.16]],"batb":[[0,1.38,599.96]],"batl":[[0,1.39,766.26]],"ltp":1.38,"tv":26720.36,"id":8681938}],"tv":30371.89}]}
{"op":"mcm","clk":"4297267233","pt":1632572541177,"mc":[{"id":"1.188134680","rc":[{"batb":[[0,1.38,799.96]],"ltp":1.38,"tv":26720.36,"id":8681938}]}]}
{"op":"mcm","clk":"4297267480","pt":1632572542371,"mc":[{"id":"1.188134680","rc":[{"batl":[[0,3.75,95.44],[1,3.8,138.21],[2,3.9,5.75]],"ltp":3.7,"tv":3651.52,"id":9631939},{"batb":[[1,1.36,1209.33]],"batl":[[2,1.41,60]],"ltp":1.38,"tv":26720.36,"id":8681938}]}]}
{"op":"mcm","clk":"4297267593","pt":1632572542895,"mc":[{"id":"1.188134680","rc":[{"batb":[[2,3.4,25]],"batl":[[2,3.9,2]],"ltp":3.7,"tv":3651.52,"id":9631939},{"batb":[[1,1.36,271.05],[2,1.35,382.6]],"batl":[[0,1.39,531.5],[1,1.4,464.74]],"ltp":1.38,"tv":26720.36,"id":8681938}]}]}
{"op":"mcm","clk":"4297267841","pt":1632572544062,"mc":[{"id":"1.188134680","rc":[{"batb":[[0,3.5,2.04],[1,3.4,25],[2,3.35,120.32]],"ltp":3.7,"tv":3651.52,"id":9631939},{"batl":[[0,1.4,500.33],[1,1.41,60],[2,1.43,289.21]],"ltp":1.38,"tv":26720.36,"id":8681938}]}]}
{"op":"mcm","clk":"4297268138","pt":1632572545356,"mc":[{"id":"1.188134680","rc":[{"batb":[[1,3.35,120.32],[2,3.3,147.18]],"ltp":3.7,"tv":3651.52,"id":9631939},{"trd":[[1.38,673.34]],"batb":[[0,1.36,271.05],[1,1.35,382.6],[2,1.33,432.22]],"batl":[[1,1.43,289.21],[2,1.44,283.76]],"ltp":1.38,"tv":27307.54,"id":8681938}],"tv":30959.07}]}
{"op":"mcm","clk":"4297268348","pt":1632572546292,"mc":[{"id":"1.188134680","rc":[{"batl":[[2,3.9,4]],"ltp":3.7,"tv":3651.52,"id":9631939},{"batb":[[2,1.34,498.54]],"batl":[[0,1.39,7],[1,1.4,500.33],[2,1.43,289.21]],"ltp":1.38,"tv":27307.54,"id":8681938}]}]}
{"op":"mcm","clk":"4297268551","pt":1632572547254,"mc":[{"id":"1.188134680","rc":[{"batb":[[0,3.55,2.06],[1,3.5,5.04],[2,3.45,3]],"ltp":3.7,"tv":3651.52,"id":9631939},{"batl":[[0,1.39,38.5],[1,1.4,507.33]],"ltp":1.38,"tv":27307.54,"id":8681938}]}]}
{"op":"mcm","clk":"4297268702","pt":1632572547956,"mc":[{"id":"1.188134680","rc":[{"batb":[[0,3.5,5.04],[1,3.45,3],[2,3.35,120.32]],"ltp":3.7,"tv":3651.52,"id":9631939},{"trd":[[1.39,0.08]],"batl":[[0,1.39,6.96]],"ltp":1.39,"tv":27307.62,"id":8681938}],"tv":30959.15}]}
{"op":"mcm","clk":"4297268955","pt":1632572549294,"mc":[{"id":"1.188134680","rc":[{"batl":[[0,3.65,20.3],[1,3.75,95.44],[2,3.8,138.21]],"ltp":3.7,"tv":3651.52,"id":9631939},{"batb":[[0,1.37,18.77],[1,1.36,271.05],[2,1.35,1242.4]],"batl":[[0,1.39,638.39],[1,1.4,549.01]],"ltp":1.39,"tv":27307.62,"id":8681938}]}]}
{"op":"mcm","clk":"4297269110","pt":1632572549996,"mc":[{"id":"1.188134680","rc":[{"trd":[[3.65,24.9]],"batl":[[0,3.75,95.44],[1,3.8,138.21],[2,3.9,4]],"ltp":3.65,"tv":3676.42,"id":9631939},{"batb":[[0,1.37,200]],"batl":[[0,1.39,616.89]],"ltp":1.39,"tv":27307.62,"id":8681938}],"tv":30984.04}]}
{"op":"mcm","clk":"4297269321","pt":1632572550977,"mc":[{"id":"1.188134680","rc":[{"batb":[[0,3.55,2],[1,3.5,22.13],[2,3.45,3]],"ltp":3.65,"tv":3676.42,"id":9631939},{"batl":[[0,1.39,645.39]],"ltp":1.39,"tv":27307.62,"id":8681938}]}]}
{"op":"mcm","clk":"4297269607","pt":1632572552193,"mc":[{"id":"1.188134680","rc":[{"batb":[[1,3.5,5.04]],"ltp":3.65,"tv":3676.42,"id":9631939},{"batb":[[0,1.37,237.04],[2,1.35,382.6]],"batl":[[0,1.39,35.46],[1,1.4,507.33]],"ltp":1.39,"tv":27307.62,"id":8681938}]}]}
{"op":"mcm","clk":"4297269711","pt":1632572552666,"mc":[{"id":"1.188134680","rc":[{"batb":[[0,3.5,5.04],[1,3.45,3],[2,3.35,120.32]],"ltp":3.65,"tv":3676.42,"id":9631939},{"batl":[[0,1.38,339],[1,1.39,6.96],[2,1.4,507.33]],"ltp":1.39,"tv":27307.62,"id":8681938}]}]}
{"op":"mcm","clk":"4297269946","pt":1632572553714,"mc":[{"id":"1.188134680","rc":[{"batl":[[0,1.39,6.96],[1,1.4,507.33],[2,1.43,289.21]],"ltp":1.39,"tv":27307.62,"id":8681938}]}]}
{"op":"mcm","clk":"4297270232","pt":1632572555064,"mc":[{"id":"1.188134680","rc":[{"batl":[[2,1.41,460.23]],"ltp":1.39,"tv":27307.62,"id":8681938}]}]}
{"op":"mcm","clk":"4297271076","pt":1632572559158,"mc":[{"id":"1.188134680","rc":[{"batb":[[1,3.35,120.32],[2,2.62,386.89]],"ltp":3.65,"tv":3676.42,"id":9631939},{"batl":[[1,1.4,68.93],[2,1.93,2.86]],"ltp":1.39,"tv":27307.62,"id":8681938}]}]}
{"op":"mcm","clk":"4297271500","pt":1632572561158,"mc":[{"id":"1.188134680","rc":[{"batl":[[2,3.9,2]],"ltp":3.65,"tv":3676.42,"id":9631939},{"batb":[[0,1.36,271.05],[1,1.35,374.6],[2,1.34,498.54]],"batl":[[0,1.4,33.34],[1,1.93,2.86],[2,4.4,3.34]],"ltp":1.39,"tv":27307.62,"id":8681938}]}]}
{"op":"mcm","clk":"4297271741","pt":1632572562297,"mc":[{"id":"1.188134680","rc":[{"batb":[[0,3.7,4.28],[1,3.6,130.56],[2,3.55,65.28]],"batl":[[0,3.85,7.67],[1,3.9,2],[2,4.2,1.71]],"ltp":3.65,"tv":3676.42,"id":9631939},{"batb":[[0,1.35,32.07],[1,1.34,631.68],[2,1.33,1052.5]],"batl":[[0,1.37,508.7],[1,1.38,506.27],[2,1.4,202.79]],"ltp":1.39,"tv":27307.62,"id":8681938}]}]}
