{"op":"mcm","clk":"4290949432","pt":1632505031897,"mc":[{"id":"1.188134680","marketDefinition":{"bspMarket":false,"turnInPlayEnabled":true,"persistenceEnabled":true,"marketBaseRate":5.0,"eventId":"30941304","eventTypeId":"2","numberOfWinners":1,"bettingType":"ODDS","marketType":"MATCH_ODDS","marketTime":"2021-09-25T12:00:00.000Z","suspendTime":"2021-09-25T12:00:00.000Z","bspReconciled":false,"complete":true,"inPlay":false,"crossMatching":false,"runnersVoidable":false,"numberOfActiveRunners":2,"betDelay":0,"status":"OPEN","runners":[{"status":"ACTIVE","sortPriority":1,"id":9631939,"name":"Marc-Andrea Huesler"},{"status":"ACTIVE","sortPriority":2,"id":8681938,"name":"Tim Van Rijthoven"}],"regulators":["MR_INT"],"countryCode":"CH","discountAllowed":false,"timezone":"UTC","openDate":"2021-09-25T12:00:00.000Z","version":4053336659,"name":"Match Odds","eventName":"Huesler v Van Rijthoven"},"rc":[{"batb":[[0,1.01,25]],"ltp":0.0,"tv":0.0,"id":9631939},{"batb":[[0,1.01,25]],"ltp":0.0,"tv":0.0,"id":8681938}]}]}
{"op":"mcm","clk":"4290949673","pt":1632505033397,"mc":[{"id":"1.188134680","marketDefinition":{"bspMarket":false,"turnInPlayEnabled":true,"persistenceEnabled":true,"marketBaseRate":5.0,"eventId":"30941304","eventTypeId":"2","numberOfWinners":1,"bettingType":"ODDS","marketType":"MATCH_ODDS","marketTime":"2021-09-25T12:00:00.000Z","suspendTime":"2021-09-25T12:00:00.000Z","bspReconciled":false,"complete":true,"inPlay":false,"crossMatching":false,"runnersVoidable":false,"numberOfActiveRunners":2,"betDelay":0,"status":"OPEN","runners":[{"status":"ACTIVE","sortPriority":1,"id":9631939,"name":"Marc-Andrea Huesler"},{"status":"ACTIVE","sortPriority":2,"id":8681938,"name":"Tim Van Rijthoven"}],"regulators":["MR_INT"],"countryCode":"CH","discountAllowed":false,"timezone":"UTC","openDate":"2021-09-25T12:00:00.000Z","version":4053336659,"name":"Match Odds","eventName":"Huesler v Van Rijthoven"}}]}
{"op":"mcm","clk":"4290949833","pt":1632505034404,"mc":[{"id":"1.188134680","marketDefinition":{"bspMarket":false,"turnInPlayEnabled":true,"persistenceEnabled":true,"marketBaseRate":5.0,"eventId":"30941304","eventTypeId":"2","numberOfWinners":1,"bettingType":"ODDS","marketType":"MATCH_ODDS","marketTime":"2021-09-25T12:00:00.000Z","suspendTime":"2021-09-25T12:00:00.000Z","bspReconciled":false,"complete":true,"inPlay":false,"crossMatching":false,"runnersVoidable":false,"numberOfActiveRunners":2,"betDelay":0,"status":"OPEN","runners":[{"status":"ACTIVE","sortPriority":1,"id":9631939,"name":"Marc-Andrea Huesler"},{"status":"ACTIVE","sortPriority":2,"id":8681938,"name":"Tim Van Rijthoven"}],"regulators":["MR_INT"],"countryCode":"CH","discountAllowed":true,"timezone":"UTC","openDate":"2021-09-25T12:00:00.000Z","version":4053336659,"name":"Match Odds","eventName":"Huesler v Van Rijthoven"}}]}
{"op":"mcm","clk":"4291021694","pt":1632505510308,"mc":[{"id":"1.188134680","rc":[{"batb":[[0,1.01,15]],"ltp":0.0,"tv":0.0,"id":9631939},{"batb":[[0,1.01,15]],"ltp":0.0,"tv":0.0,"id":8681938}]}]}
{"op":"mcm","clk":"4291319000","pt":1632507432219,"mc":[{"id":"1.188134680","rc":[{"batb":[[0,1.01,135.03]],"ltp":0.0,"tv":0.0,"id":9631939},{"batb":[[0,1.01,135.03]],"ltp":0.0,"tv":0.0,"id":8681938}]}]}
{"op":"mcm","clk":"4291639303","pt":1632509235275,"mc":[{"id":"1.188134680","rc":[{"batb":[[0,1.01,613.52]],"ltp":0.0,"tv":0.0,"id":9631939},{"batb":[[0,1.01,613.52]],"ltp":0.0,"tv":0.0,"id":8681938}]}]}
{"op":"mcm","clk":"4291639789","pt":1632509238336,"mc":[{"id":"1.188134680","rc":[{"batb":[[0,1.02,109.75],[1,1.01,613.52]],"ltp":0.0,"tv":0.0,"id":9631939}]}]}
{"op":"mcm","clk":"4291639797","pt":1632509238441,"mc":[{"id":"1.188134680","rc":[{"batb":[[0,1.02,109.75],[1,1.01,613.52]],"ltp":0.0,"tv":0.0,"id":8681938}]}]}
{"op":"mcm","clk":"4291766450","pt":1632510209432,"mc":[{"id":"1.188134680","rc":[{"batb":[[0,1.01,135.03],[1,1.01,0]],"ltp":0.0,"tv":0.0,"id":9631939},{"batb":[[0,1.01,135.03],[1,1.01,0]],"ltp":0.0,"tv":0.0,"id":8681938}]}]}
{"op":"mcm","clk":"4291868596","pt":1632510851620,"mc":[{"id":"1.188134680","rc":[{"batl":[[0,990,2.2]],"ltp":0.0,"tv":0.0,"id":9631939},{"batl":[[0,990,2.2]],"ltp":0.0,"tv":0.0,"id":8681938}]}]}
{"op":"mcm","clk":"4292159070","pt":1632512870259,"mc":[{"id":"1.188134680","rc":[{"batb":[[0,1.75,34.12],[1,1.01,135.03]],"ltp":0.0,"tv":0.0,"id":9631939},{"batb":[[0,1.68,38.2],[1,1.01,135.03]],"ltp":0.0,"tv":0.0,"id":8681938}]}]}
{"op":"mcm","clk":"4292162320","pt":1632512903588,"mc":[{"id":"1.188134680","marketDefinition":{"bspMarket":false,"turnInPlayEnabled":true,"persistenceEnabled":true,"marketBaseRate":5.0,"eventId":"30941304","eventTypeId":"2","numberOfWinners":1,"bettingType":"ODDS","marketType":"MATCH_ODDS","marketTime":"2021-09-25T12:00:00.000Z","suspendTime":"2021-09-25T12:00:00.000Z","bspReconciled":false,"complete":true,"inPlay":false,"crossMatching":true,"runnersVoidable":false,"numberOfActiveRunners":2,"betDelay":0,"status":"OPEN","runners":[{"status":"ACTIVE","sortPriority":1,"id":9631939,"name":"Marc-Andrea Huesler"},{"status":"ACTIVE","sortPriority":2,"id":8681938,"name":"Tim Van Rijthoven"}],"regulators":["MR_INT"],"countryCode":"CH","discountAllowed":true,"timezone":"UTC","openDate":"2021-09-25T12:00:00.000Z","version":4053336659,"name":"Match Odds","eventName":"Huesler v Van Rijthoven"}}]}
{"op":"mcm","clk":"4292281441","pt":1632514058349,"mc":[{"id":"1.188134680","rc":[{"batb":[[0,1.76,10.28],[1,1.75,34.12],[2,1.01,134.98]],"ltp":0.0,"tv":0.0,"id":9631939},{"batb":[[1,1.01,134.98]],"ltp":0.0,"tv":0.0,"id":8681938}]}]}
{"op":"mcm","clk":"4292281482","pt":1632514058765,"mc":[{"id":"1.188134680","rc":[{"batl":[[0,12.5,3.43],[1,990,2.2]],"ltp":0.0,"tv":0.0,"id":9631939},{"batl":[[0,12,3.43],[1,990,2.2]],"ltp":0.0,"tv":0.0,"id":8681938}]}]}
{"op":"mcm","clk":"4292282809","pt":1632514070458,"mc":[{"id":"1.188134680","rc":[{"batb":[[0,1.77,33.73],[1,1.76,10.28]],"ltp":0.0,"tv":0.0,"id":9631939}]}]}
{"op":"mcm","clk":"4292294880","pt":1632514186977,"mc":[{"id":"1.188134680","rc":[{"batb":[[1,1.01,134.98],[2,1.01,0]],"ltp":0.0,"tv":0.0,"id":9631939}]}]}
{"op":"mcm","clk":"4292352333","pt":1632514697955,"mc":[{"id":"1.188134680","rc":[{"batb":[[1,1.01,613.36]],"ltp":0.0,"tv":0.0,"id":9631939},{"batb":[[1,1.01,613.36]],"ltp":0.0,"tv":0.0,"id":8681938}]}]}
{"op":"mcm","clk":"4292405672","pt":1632515227496,"mc":[{"id":"1.188134680","rc":[{"batb":[[1,1.23,15.9],[2,1.01,613.36]],"ltp":0.0,"tv":0.0,"id":9631939},{"batb":[[1,1.2,18.29],[2,1.01,613.36]],"ltp":0.0,"tv":0.0,"id":8681938}]}]}
{"op":"mcm","clk":"4292710571","pt":1632519905692,"mc":[{"id":"1.188134680","rc":[{"batb":[[0,1.68,57.82]],"ltp":0.0,"tv":0.0,"id":8681938}]}]}
{"op":"mcm","clk":"4292718770","pt":1632520075967,"mc":[{"id":"1.188134680","rc":[{"batb":[[0,1.23,15.9],[1,1.01,613.36],[2,1.01,0]],"ltp":0.0,"tv":0.0,"id":9631939}]}]}
{"op":"mcm","clk":"4292723822","pt":1632520180044,"mc":[{"id":"1.188134680","rc":[{"batb":[[0,1.71,51.87],[1,1.24,15.43],[2,1.23,15.9]],"ltp":0.0,"tv":0.0,"id":9631939}]}]}
{"op":"mcm","clk":"4292730756","pt":1632520306747,"mc":[{"id":"1.188134680","rc":[{"batb":[[1,1.23,15.9],[2,1.01,613.36]],"ltp":0.0,"tv":0.0,"id":9631939}]}]}
{"op":"mcm","clk":"4292737255","pt":1632520432741,"mc":[{"id":"1.188134680","rc":[{"batb":[[0,1.72,11.14],[1,1.71,51.87],[2,1.23,15.9]],"ltp":0.0,"tv":0.0,"id":9631939}]}]}
{"op":"mcm","clk":"4292739949","pt":1632520480318,"mc":[{"id":"1.188134680","rc":[{"batb":[[0,1.79,66.04],[1,1.72,11.14]],"ltp":0.0,"tv":0.0,"id":9631939}]}]}
{"op":"mcm","clk":"4292744495","pt":1632520559645,"mc":[{"id":"1.188134680","rc":[{"batb":[[1,1.23,15.9],[2,1.01,613.36]],"ltp":0.0,"tv":0.0,"id":9631939}]}]}
{"op":"mcm","clk":"4292803384","pt":1632521504015,"mc":[{"id":"1.188134680","rc":[{"batb":[[1,1.23,15.9],[2,1.01,613.28]],"batl":[[0,2.2,25],[1,12.5,3.43],[2,990,2.2]],"ltp":0.0,"tv":0.0,"id":9631939},{"batb":[[1,1.2,18.28],[2,1.01,613.28]],"batl":[[0,2.2,25],[1,12,3.43],[2,990,2.2]],"ltp":0.0,"tv":0.0,"id":8681938}]}]}
{"op":"mcm","clk":"4292806157","pt":1632521557377,"mc":[{"id":"1.188134680","rc":[{"batl":[[1,990,2.2],[2,990,0]],"ltp":0.0,"tv":0.0,"id":9631939},{"batl":[[1,990,2.2],[2,990,0]],"ltp":0.0,"tv":0.0,"id":8681938}]}]}
{"op":"mcm","clk":"4292844128","pt":1632522037202,"mc":[{"id":"1.188134680","rc":[{"batb":[[0,1.69,10.29],[1,1.68,57.82],[2,1.2,18.28]],"ltp":0.0,"tv":0.0,"id":8681938}]}]}
{"op":"mcm","clk":"4292865724","pt":1632522305969,"mc":[{"id":"1.188134680","rc":[{"batb":[[0,1.74,70.68],[1,1.69,10.29]],"ltp":0.0,"tv":0.0,"id":8681938}]}]}
{"op":"mcm","clk":"4292872085","pt":1632522430270,"mc":[{"id":"1.188134680","rc":[{"batb":[[1,1.2,18.28],[2,1.01,613.28]],"ltp":0.0,"tv":0.0,"id":8681938}]}]}
{"op":"mcm","clk":"4292953960","pt":1632524113313,"mc":[{"id":"1.188134680","rc":[{"batb":[[0,1.23,15.9],[1,1.01,613.28],[2,1.01,0]],"ltp":0.0,"tv":0.0,"id":9631939},{"batb":[[0,1.2,18.28],[1,1.01,613.28],[2,1.01,0]],"ltp":0.0,"tv":0.0,"id":8681938}]}]}
{"op":"mcm","clk":"4292954283","pt":1632524117623,"mc":[{"id":"1.188134680","rc":[{"batb":[[0,1.55,99.37],[1,1.23,15.9],[2,1.01,613.28]],"ltp":0.0,"tv":0.0,"id":9631939},{"batb":[[0,1.58,98.39],[1,1.2,18.28],[2,1.01,613.28]],"ltp":0.0,"tv":0.0,"id":8681938}]}]}
{"op":"mcm","clk":"4292954362","pt":1632524118602,"mc":[{"id":"1.188134680","rc":[{"batb":[[0,1.56,12.86],[1,1.55,99.37],[2,1.23,15.9]],"ltp":0.0,"tv":0.0,"id":9631939},{"batb":[[0,1.59,12],[1,1.58,98.39],[2,1.2,18.28]],"ltp":0.0,"tv":0.0,"id":8681938}]}]}
{"op":"mcm","clk":"4292978712","pt":1632524417764,"mc":[{"id":"1.188134680","rc":[{"batb":[[0,1.6,96.17],[1,1.56,12.86]],"ltp":0.0,"tv":0.0,"id":9631939},{"batb":[[0,1.68,92.42],[1,1.59,12]],"ltp":0.0,"tv":0.0,"id":8681938}]}]}
{"op":"mcm","clk":"4292981264","pt":1632524455215,"mc":[{"id":"1.188134680","rc":[{"batb":[[1,1.2,18.28],[2,1.01,613.28]],"ltp":0.0,"tv":0.0,"id":8681938}]}]}
{"op":"mcm","clk":"4292981275","pt":1632524455421,"mc":[{"id":"1.188134680","rc":[{"batb":[[1,1.23,15.9],[2,1.01,613.28]],"ltp":0.0,"tv":0.0,"id":9631939}]}]}
{"op":"mcm","clk":"4292983229","pt":1632524485859,"mc":[{"id":"1.188134680","rc":[{"batb":[[0,1.23,15.9],[1,1.01,613.28],[2,1.01,0]],"ltp":0.0,"tv":0.0,"id":9631939},{"batb":[[0,1.2,18.28],[1,1.01,613.28],[2,1.01,0]],"ltp":0.0,"tv":0.0,"id":8681938}]}]}
{"op":"mcm","clk":"4292983530","pt":1632524490409,"mc":[{"id":"1.188134680","rc":[{"batb":[[0,1.63,94.43],[1,1.23,15.9],[2,1.01,613.28]],"ltp":0.0,"tv":0.0,"id":9631939},{"batb":[[0,1.6,97.15],[1,1.2,18.28],[2,1.01,613.28]],"ltp":0.0,"tv":0.0,"id":8681938}]}]}
{"op":"mcm","clk":"4292984654","pt":1632524510200,"mc":[{"id":"1.188134680","rc":[{"batb":[[0,1.64,11.14],[1,1.63,94.43],[2,1.23,15.9]],"ltp":0.0,"tv":0.0,"id":9631939},{"batb":[[0,1.61,12],[1,1.6,97.15],[2,1.2,18.28]],"ltp":0.0,"tv":0.0,"id":8681938}]}]}
{"op":"mcm","clk":"4292990945","pt":1632524619090,"mc":[{"id":"1.188134680","rc":[{"batb":[[0,1.71,89.96],[1,1.64,11.14]],"ltp":0.0,"tv":0.0,"id":9631939},{"batb":[[0,1.7,91.37],[1,1.61,12]],"ltp":0.0,"tv":0.0,"id":8681938}]}]}
{"op":"mcm","clk":"4292992567","pt":1632524647045,"mc":[{"id":"1.188134680","rc":[{"batb":[[1,1.23,15.9],[2,1.01,613.28]],"ltp":0.0,"tv":0.0,"id":9631939},{"batb":[[1,1.2,18.28],[2,1.01,613.28]],"ltp":0.0,"tv":0.0,"id":8681938}]}]}
{"op":"mcm","clk":"4292994841","pt":1632524686021,"mc":[{"id":"1.188134680","rc":[{"batb":[[0,1.23,15.9],[1,1.01,613.28],[2,1.01,0]],"ltp":0.0,"tv":0.0,"id":9631939},{"batb":[[0,1.2,18.28],[1,1.01,613.28],[2,1.01,0]],"ltp":0.0,"tv":0.0,"id":8681938}]}]}
{"op":"mcm","clk":"4292995107","pt":1632524690608,"mc":[{"id":"1.188134680","rc":[{"batb":[[0,1.54,100.02],[1,1.23,15.9],[2,1.01,613.28]],"ltp":0.0,"tv":0.0,"id":9631939},{"batb":[[0,1.6,97.15],[1,1.2,18.28],[2,1.01,613.28]],"ltp":0.0,"tv":0.0,"id":8681938}]}]}
{"op":"mcm","clk":"4293002157","pt":1632524803066,"mc":[{"id":"1.188134680","rc":[{"batb":[[2,1.01,618.28]],"ltp":0.0,"tv":0.0,"id":9631939},{"batb":[[2,1.01,618.28]],"ltp":0.0,"tv":0.0,"id":8681938}]}]}
{"op":"mcm","clk":"4293007577","pt":1632524856259,"mc":[{"id":"1.188134680","rc":[{"batb":[[0,1.55,12.86],[1,1.54,100.02],[2,1.23,15.9]],"ltp":0.0,"tv":0.0,"id":9631939},{"batb":[[0,1.61,12],[1,1.6,97.15],[2,1.2,18.28]],"ltp":0.0,"tv":0.0,"id":8681938}]}]}
{"op":"mcm","clk":"4293016729","pt":1632524990876,"mc":[{"id":"1.188134680","rc":[{"batb":[[0,1.71,89.91],[1,1.55,12.86]],"ltp":0.0,"tv":0.0,"id":9631939},{"batb":[[0,1.67,92.98],[1,1.61,12]],"ltp":0.0,"tv":0.0,"id":8681938}]}]}
{"op":"mcm","clk":"4293018480","pt":1632525014315,"mc":[{"id":"1.188134680","rc":[{"batb":[[1,1.23,15.9],[2,1.01,618.28]],"ltp":0.0,"tv":0.0,"id":9631939},{"batb":[[1,1.2,18.28],[2,1.01,618.28]],"ltp":0.0,"tv":0.0,"id":8681938}]}]}
{"op":"mcm","clk":"4293022127","pt":1632525067179,"mc":[{"id":"1.188134680","rc":[{"batb":[[0,1.68,11.14],[1,1.67,92.98],[2,1.2,18.28]],"ltp":0.0,"tv":0.0,"id":8681938}]}]}
{"op":"mcm","clk":"4293032267","pt":1632525215520,"mc":[{"id":"1.188134680","rc":[{"batb":[[0,1.23,15.9],[1,1.01,618.28],[2,1.01,0]],"ltp":0.0,"tv":0.0,"id":9631939},{"batb":[[1,1.2,18.28],[2,1.01,618.28]],"ltp":0.0,"tv":0.0,"id":8681938}]}]}
{"op":"mcm","clk":"4293032617","pt":1632525220241,"mc":[{"id":"1.188134680","rc":[{"batb":[[0,1.55,99.37],[1,1.23,15.9],[2,1.01,618.28]],"ltp":0.0,"tv":0.0,"id":9631939},{"batb":[[0,1.69,91.91],[1,1.68,11.14],[2,1.2,18.28]],"ltp":0.0,"tv":0.0,"id":8681938}]}]}
{"op":"mcm","clk":"4293036006","pt":1632525269342,"mc":[{"id":"1.188134680","rc":[{"batb":[[1,1.2,18.28],[2,1.01,618.28]],"ltp":0.0,"tv":0.0,"id":8681938}]}]}
{"op":"mcm","clk":"4293036022","pt":1632525269548,"mc":[{"id":"1.188134680","rc":[{"batb":[[0,1.56,12.86],[1,1.55,99.37],[2,1.23,15.9]],"ltp":0.0,"tv":0.0,"id":9631939}]}]}
{"op":"mcm","clk":"4293039830","pt":1632525323996,"mc":[{"id":"1.188134680","rc":[{"batb":[[0,1.7,10.29],[1,1.69,91.91],[2,1.2,18.28]],"ltp":0.0,"tv":0.0,"id":8681938}]}]}
{"op":"mcm","clk":"4293048878","pt":1632525478680,"mc":[{"id":"1.188134680","rc":[{"batb":[[0,1.64,168.93],[1,1.56,12.86]],"ltp":0.0,"tv":0.0,"id":9631939},{"batb":[[0,1.76,158.79],[1,1.7,10.29]],"ltp":0.0,"tv":0.0,"id":8681938}]}]}
{"op":"mcm","clk":"4293049349","pt":1632525486279,"mc":[{"id":"1.188134680","rc":[{"batb":[[1,1.2,18.28],[2,1.01,618.28]],"ltp":0.0,"tv":0.0,"id":8681938}]}]}
{"op":"mcm","clk":"4293049369","pt":1632525486618,"mc":[{"id":"1.188134680","rc":[{"batb":[[1,1.23,15.9],[2,1.01,618.28]],"ltp":0.0,"tv":0.0,"id":9631939}]}]}
{"op":"mcm","clk":"4293052343","pt":1632525538850,"mc":[{"id":"1.188134680","rc":[{"batb":[[0,1.65,11.14],[1,1.64,168.93],[2,1.23,15.9]],"ltp":0.0,"tv":0.0,"id":9631939}]}]}
{"op":"mcm","clk":"4293071728","pt":1632525820329,"mc":[{"id":"1.188134680","rc":[{"batb":[[0,1.77,156.3],[1,1.65,11.14]],"ltp":0.0,"tv":0.0,"id":9631939}]}]}
{"op":"mcm","clk":"4293082599","pt":1632525999415,"mc":[{"id":"1.188134680","rc":[{"batb":[[0,1.65,11.14],[1,1.23,15.9],[2,1.01,618.28]],"ltp":0.0,"tv":0.0,"id":9631939},{"batb":[[0,1.2,18.28],[1,1.01,618.28],[2,1.01,0]],"ltp":0.0,"tv":0.0,"id":8681938}]}]}
{"op":"mcm","clk":"4293082952","pt":1632526004529,"mc":[{"id":"1.188134680","rc":[{"batb":[[0,1.78,155.49],[1,1.65,11.14],[2,1.23,15.9]],"ltp":0.0,"tv":0.0,"id":9631939},{"batb":[[0,1.66,168.47],[1,1.2,18.28],[2,1.01,618.28]],"ltp":0.0,"tv":0.0,"id":8681938}]}]}
{"op":"mcm","clk":"4293084450","pt":1632526030268,"mc":[{"id":"1.188134680","rc":[{"batb":[[1,1.23,15.9],[2,1.01,618.28]],"ltp":0.0,"tv":0.0,"id":9631939}]}]}
{"op":"mcm","clk":"4293084458","pt":1632526030471,"mc":[{"id":"1.188134680","rc":[{"batb":[[0,1.67,11.14],[1,1.66,168.47],[2,1.2,18.28]],"ltp":0.0,"tv":0.0,"id":8681938}]}]}
{"op":"mcm","clk":"4293104356","pt":1632526304669,"mc":[{"id":"1.188134680","rc":[{"batb":[[0,1.68,166.36],[1,1.67,11.14]],"ltp":0.0,"tv":0.0,"id":8681938}]}]}
{"op":"mcm","clk":"4293106559","pt":1632526344741,"mc":[{"id":"1.188134680","rc":[{"batb":[[1,1.2,18.28],[2,1.01,618.28]],"ltp":0.0,"tv":0.0,"id":8681938}]}]}
{"op":"mcm","clk":"4293112498","pt":1632526464758,"mc":[{"id":"1.188134680","rc":[{"batb":[[0,1.69,10.29],[1,1.68,166.36],[2,1.2,18.28]],"ltp":0.0,"tv":0.0,"id":8681938}]}]}
{"op":"mcm","clk":"4293120015","pt":1632526604725,"mc":[{"id":"1.188134680","rc":[{"batb":[[0,1.7,164.38],[1,1.69,10.29]],"ltp":0.0,"tv":0.0,"id":8681938}]}]}
{"op":"mcm","clk":"4293129843","pt":1632526716108,"mc":[{"id":"1.188134680","rc":[{"batb":[[1,1.2,18.28],[2,1.01,618.28]],"ltp":0.0,"tv":0.0,"id":8681938}]}]}
{"op":"mcm","clk":"4293138319","pt":1632526841218,"mc":[{"id":"1.188134680","rc":[{"batb":[[0,1.71,10.29],[1,1.7,164.38],[2,1.2,18.28]],"ltp":0.0,"tv":0.0,"id":8681938}]}]}
{"op":"mcm","clk":"4293142392","pt":1632526904782,"mc":[{"id":"1.188134680","rc":[{"batb":[[0,1.75,159.62],[1,1.71,10.29]],"ltp":0.0,"tv":0.0,"id":8681938}]}]}
{"op":"mcm","clk":"4293143907","pt":1632526931963,"mc":[{"id":"1.188134680","rc":[{"batb":[[0,1.23,15.9],[1,1.01,618.28],[2,1.01,0]],"ltp":0.0,"tv":0.0,"id":9631939},{"batb":[[0,1.71,10.29],[1,1.2,18.28],[2,1.01,618.28]],"ltp":0.0,"tv":0.0,"id":8681938}]}]}
{"op":"mcm","clk":"4293144254","pt":1632526937021,"mc":[{"id":"1.188134680","rc":[{"batb":[[0,1.56,177.7],[1,1.23,15.9],[2,1.01,618.28]],"ltp":0.0,"tv":0.0,"id":9631939},{"batb":[[0,1.76,158.79],[1,1.71,10.29],[2,1.2,18.28]],"ltp":0.0,"tv":0.0,"id":8681938}]}]}
{"op":"mcm","clk":"4293146316","pt":1632526967713,"mc":[{"id":"1.188134680","rc":[{"batb":[[0,1.57,12.86],[1,1.56,177.7],[2,1.23,15.9]],"ltp":0.0,"tv":0.0,"id":9631939},{"batb":[[1,1.2,18.28],[2,1.01,618.28]],"ltp":0.0,"tv":0.0,"id":8681938}]}]}
{"op":"mcm","clk":"4293156069","pt":1632527128583,"mc":[{"id":"1.188134680","rc":[{"batb":[[1,1.23,15.9],[2,1.01,618.28]],"ltp":0.0,"tv":0.0,"id":9631939},{"batb":[[0,1.2,18.28],[1,1.01,618.28],[2,1.01,0]],"ltp":0.0,"tv":0.0,"id":8681938}]}]}
{"op":"mcm","clk":"4293156403","pt":1632527133657,"mc":[{"id":"1.188134680","rc":[{"batb":[[0,1.67,165.86],[1,1.57,12.86],[2,1.23,15.9]],"ltp":0.0,"tv":0.0,"id":9631939},{"batb":[[0,1.67,167.45],[1,1.2,18.28],[2,1.01,618.28]],"ltp":0.0,"tv":0.0,"id":8681938}]}]}
{"op":"mcm","clk":"4293160915","pt":1632527216174,"mc":[{"id":"1.188134680","rc":[{"batb":[[1,1.23,15.9],[2,1.01,618.28]],"ltp":0.0,"tv":0.0,"id":9631939},{"batb":[[0,1.68,11.14],[1,1.67,167.45],[2,1.2,18.28]],"ltp":0.0,"tv":0.0,"id":8681938}]}]}
{"op":"mcm","clk":"4293179678","pt":1632527289914,"mc":[{"id":"1.188134680","rc":[{"batb":[[0,1.23,15.9],[1,1.01,618.28],[2,1.01,0]],"ltp":0.0,"tv":0.0,"id":9631939},{"batb":[[1,1.2,18.28],[2,1.01,618.28]],"ltp":0.0,"tv":0.0,"id":8681938}]}]}
{"op":"mcm","clk":"4293180648","pt":1632527306641,"mc":[{"id":"1.188134680","rc":[{"batb":[[0,1.62,237.56],[1,1.23,15.9],[2,1.01,618.28]],"ltp":0.0,"tv":0.0,"id":9631939},{"batb":[[0,1.74,223.11],[1,1.68,11.14],[2,1.2,18.28]],"ltp":0.0,"tv":0.0,"id":8681938}]}]}
{"op":"mcm","clk":"4293182591","pt":1632527341699,"mc":[{"id":"1.188134680","rc":[{"batb":[[0,1.63,12],[1,1.62,237.56],[2,1.23,15.9]],"ltp":0.0,"tv":0.0,"id":9631939},{"batb":[[1,1.2,18.28],[2,1.01,618.28]],"ltp":0.0,"tv":0.0,"id":8681938}]}]}
{"op":"mcm","clk":"4293183528","pt":1632527360617,"mc":[{"id":"1.188134680","rc":[{"batb":[[0,1.65,233.18],[1,1.63,12]],"ltp":0.0,"tv":0.0,"id":9631939}]}]}
{"op":"mcm","clk":"4293188790","pt":1632527466009,"mc":[{"id":"1.188134680","rc":[{"batb":[[1,1.23,15.9],[2,1.01,618.28]],"ltp":0.0,"tv":0.0,"id":9631939}]}]}
{"op":"mcm","clk":"4293192273","pt":1632527538990,"mc":[{"id":"1.188134680","rc":[{"batb":[[0,1.23,15.9],[1,1.01,618.28],[2,1.01,0]],"ltp":0.0,"tv":0.0,"id":9631939},{"batb":[[0,1.2,18.28],[1,1.01,618.28],[2,1.01,0]],"ltp":0.0,"tv":0.0,"id":8681938}]}]}
{"op":"mcm","clk":"4293192504","pt":1632527544174,"mc":[{"id":"1.188134680","rc":[{"batb":[[0,1.56,246.81],[1,1.23,15.9],[2,1.01,618.28]],"ltp":0.0,"tv":0.0,"id":9631939},{"batb":[[0,1.65,235.43],[1,1.2,18.28],[2,1.01,618.28]],"ltp":0.0,"tv":0.0,"id":8681938}]}]}
{"op":"mcm","clk":"4293194398","pt":1632527589639,"mc":[{"id":"1.188134680","rc":[{"batb":[[0,1.57,12.86],[1,1.56,246.81],[2,1.23,15.9]],"ltp":0.0,"tv":0.0,"id":9631939},{"batb":[[0,1.66,11.14],[1,1.65,235.43],[2,1.2,18.28]],"ltp":0.0,"tv":0.0,"id":8681938}]}]}
{"op":"mcm","clk":"4293207177","pt":1632527854748,"mc":[{"id":"1.188134680","rc":[{"batb":[[0,1.62,237.56],[1,1.57,12.86]],"ltp":0.0,"tv":0.0,"id":9631939},{"batb":[[0,1.74,223.11],[1,1.66,11.14]],"ltp":0.0,"tv":0.0,"id":8681938}]}]}
{"op":"mcm","clk":"4293209378","pt":1632527894774,"mc":[{"id":"1.188134680","rc":[{"batb":[[0,1.57,12.86],[1,1.23,15.9],[2,1.01,618.28]],"ltp":0.0,"tv":0.0,"id":9631939},{"batb":[[0,1.66,11.14],[1,1.2,18.28],[2,1.01,618.28]],"ltp":0.0,"tv":0.0,"id":8681938}]}]}
{"op":"mcm","clk":"4293209696","pt":1632527899964,"mc":[{"id":"1.188134680","rc":[{"batb":[[0,1.59,242.1],[1,1.57,12.86],[2,1.23,15.9]],"ltp":0.0,"tv":0.0,"id":9631939},{"batb":[[0,1.69,229.79],[1,1.66,11.14],[2,1.2,18.28]],"ltp":0.0,"tv":0.0,"id":8681938}]}]}
{"op":"mcm","clk":"4293214672","pt":1632527990424,"mc":[{"id":"1.188134680","rc":[{"batb":[[0,1.57,12.86],[1,1.23,15.9],[2,1.01,618.28]],"ltp":0.0,"tv":0.0,"id":9631939},{"batb":[[0,1.66,11.14],[1,1.2,18.28],[2,1.01,618.28]],"ltp":0.0,"tv":0.0,"id":8681938}]}]}
{"op":"mcm","clk":"4293214969","pt":1632527995838,"mc":[{"id":"1.188134680","rc":[{"batb":[[0,1.67,230.36],[1,1.57,12.86],[2,1.23,15.9]],"ltp":0.0,"tv":0.0,"id":9631939},{"batb":[[0,1.68,231.17],[1,1.66,11.14],[2,1.2,18.28]],"ltp":0.0,"tv":0.0,"id":8681938}]}]}
{"op":"mcm","clk":"4293220069","pt":1632528081299,"mc":[{"id":"1.188134680","rc":[{"batb":[[1,1.2,18.28],[2,1.01,618.28]],"ltp":0.0,"tv":0.0,"id":8681938}]}]}
{"op":"mcm","clk":"4293220078","pt":1632528081606,"mc":[{"id":"1.188134680","rc":[{"batb":[[1,1.23,15.9],[2,1.01,618.28]],"ltp":0.0,"tv":0.0,"id":9631939}]}]}
{"op":"mcm","clk":"4293226407","pt":1632528207882,"mc":[{"id":"1.188134680","rc":[{"batb":[[0,1.68,11.14],[1,1.67,230.36],[2,1.23,15.9]],"ltp":0.0,"tv":0.0,"id":9631939},{"batb":[[0,1.69,10.29],[1,1.68,231.17],[2,1.2,18.28]],"ltp":0.0,"tv":0.0,"id":8681938}]}]}
{"op":"mcm","clk":"4293230920","pt":1632528296070,"mc":[{"id":"1.188134680","rc":[{"batb":[[0,1.73,222.15],[1,1.68,11.14]],"ltp":0.0,"tv":0.0,"id":9631939},{"batb":[[0,1.81,214.27],[1,1.69,10.29]],"ltp":0.0,"tv":0.0,"id":8681938}]}]}
{"op":"mcm","clk":"4293232766","pt":1632528329308,"mc":[{"id":"1.188134680","rc":[{"batb":[[1,1.2,18.28],[2,1.01,618.28]],"ltp":0.0,"tv":0.0,"id":8681938}]}]}
{"op":"mcm","clk":"4293232787","pt":1632528329614,"mc":[{"id":"1.188134680","rc":[{"batb":[[1,1.23,15.9],[2,1.01,618.28]],"ltp":0.0,"tv":0.0,"id":9631939}]}]}
{"op":"mcm","clk":"4293243852","pt":1632528531408,"mc":[{"id":"1.188134680","rc":[{"batb":[[1,1.25,29.25],[2,1.23,15.9]],"ltp":0.0,"tv":0.0,"id":9631939},{"batb":[[1,1.25,29.25],[2,1.2,18.28]],"ltp":0.0,"tv":0.0,"id":8681938}]}]}
{"op":"mcm","clk":"4293335061","pt":1632530009002,"mc":[{"id":"1.188134680","rc":[{"batb":[[0,1.25,29.25],[1,1.23,15.9],[2,1.01,618.28]],"ltp":0.0,"tv":0.0,"id":9631939},{"batb":[[0,1.25,29.25],[1,1.2,18.28],[2,1.01,618.28]],"ltp":0.0,"tv":0.0,"id":8681938}]}]}
{"op":"mcm","clk":"4293335525","pt":1632530017314,"mc":[{"id":"1.188134680","rc":[{"batb":[[0,1.71,224.91],[1,1.26,15.43],[2,1.25,29.25]],"ltp":0.0,"tv":0.0,"id":9631939},{"batb":[[0,1.61,241.35],[1,1.26,15.43],[2,1.25,29.25]],"ltp":0.0,"tv":0.0,"id":8681938}]}]}
{"op":"mcm","clk":"4293338662","pt":1632530070326,"mc":[{"id":"1.188134680","rc":[{"batb":[[1,1.25,29.25],[2,1.2,18.28]],"ltp":0.0,"tv":0.0,"id":8681938}]}]}
{"op":"mcm","clk":"4293338676","pt":1632530070535,"mc":[{"id":"1.188134680","rc":[{"batb":[[1,1.25,29.25],[2,1.23,15.9]],"ltp":0.0,"tv":0.0,"id":9631939}]}]}
{"op":"mcm","clk":"4293341950","pt":1632530122915,"mc":[{"id":"1.188134680","rc":[{"batb":[[0,1.62,12],[1,1.61,241.35],[2,1.25,29.25]],"ltp":0.0,"tv":0.0,"id":8681938}]}]}
{"op":"mcm","clk":"4293347979","pt":1632530223632,"mc":[{"id":"1.188134680","rc":[{"batb":[[0,1.25,29.25],[1,1.23,15.9],[2,1.01,618.28]],"ltp":0.0,"tv":0.0,"id":9631939},{"batb":[[1,1.25,29.25],[2,1.2,18.28]],"ltp":0.0,"tv":0.0,"id":8681938}]}]}
{"op":"mcm","clk":"4293348249","pt":1632530228291,"mc":[{"id":"1.188134680","rc":[{"batb":[[0,1.26,15.43],[1,1.25,29.25],[2,1.23,15.9]],"ltp":0.0,"tv":0.0,"id":9631939}]}]}
{"op":"mcm","clk":"4293348304","pt":1632530229326,"mc":[{"id":"1.188134680","rc":[{"batb":[[0,1.71,224.91],[1,1.26,15.43],[2,1.25,29.25]],"ltp":0.0,"tv":0.0,"id":9631939},{"batb":[[0,1.74,223.11],[1,1.62,12],[2,1.25,29.25]],"ltp":0.0,"tv":0.0,"id":8681938}]}]}
{"op":"mcm","clk":"4293351379","pt":1632530281277,"mc":[{"id":"1.188134680","rc":[{"batb":[[1,1.25,29.25],[2,1.23,15.9]],"ltp":0.0,"tv":0.0,"id":9631939}]}]}
{"op":"mcm","clk":"4293351399","pt":1632530281485,"mc":[{"id":"1.188134680","rc":[{"batb":[[1,1.25,29.25],[2,1.2,18.28]],"ltp":0.0,"tv":0.0,"id":8681938}]}]}
{"op":"mcm","clk":"4293365405","pt":1632530523068,"mc":[{"id":"1.188134680","rc":[{"batb":[[0,1.48,84.03]],"ltp":0.0,"tv":0.0,"id":9631939},{"batb":[[0,1.57,78.43]],"ltp":0.0,"tv":0.0,"id":8681938}]}]}
{"op":"mcm","clk":"4293365765","pt":1632530528638,"mc":[{"id":"1.188134680","rc":[{"batb":[[0,1.55,356]],"ltp":0.0,"tv":0.0,"id":9631939},{"batb":[[0,1.58,328.58]],"ltp":0.0,"tv":0.0,"id":8681938}]}]}
{"op":"mcm","clk":"4293366693","pt":1632530543286,"mc":[{"id":"1.188134680","rc":[{"batb":[[0,1.56,12.86],[1,1.55,356],[2,1.25,29.25]],"ltp":0.0,"tv":0.0,"id":9631939},{"batb":[[0,1.59,12],[1,1.58,328.58],[2,1.25,29.25]],"ltp":0.0,"tv":0.0,"id":8681938}]}]}
{"op":"mcm","clk":"4293383990","pt":1632530828745,"mc":[{"id":"1.188134680","rc":[{"batb":[[0,1.6,323.09],[1,1.56,12.86]],"ltp":0.0,"tv":0.0,"id":9631939},{"batb":[[0,1.6,324.28],[1,1.59,12]],"ltp":0.0,"tv":0.0,"id":8681938}]}]}
{"op":"mcm","clk":"4293384548","pt":1632530837978,"mc":[{"id":"1.188134680","rc":[{"batb":[[1,1.25,29.25],[2,1.23,15.9]],"ltp":0.0,"tv":0.0,"id":9631939},{"batb":[[1,1.25,29.25],[2,1.2,18.28]],"ltp":0.0,"tv":0.0,"id":8681938}]}]}
{"op":"mcm","clk":"4293387394","pt":1632530886887,"mc":[{"id":"1.188134680","rc":[{"batb":[[0,1.61,77.16]],"ltp":0.0,"tv":0.0,"id":9631939},{"batb":[[0,1.64,75.04]],"ltp":0.0,"tv":0.0,"id":8681938}]}]}
{"op":"mcm","clk":"4293387561","pt":1632530890082,"mc":[{"id":"1.188134680","rc":[{"batb":[[0,1.62,12],[1,1.61,77.16],[2,1.25,29.25]],"ltp":0.0,"tv":0.0,"id":9631939},{"batb":[[0,1.65,11.14],[1,1.64,75.04],[2,1.25,29.25]],"ltp":0.0,"tv":0.0,"id":8681938}]}]}
{"op":"mcm","clk":"4293387687","pt":1632530892359,"mc":[{"id":"1.188134680","rc":[{"batb":[[1,1.25,29.25],[2,1.23,15.9]],"ltp":0.0,"tv":0.0,"id":9631939},{"batb":[[1,1.25,29.25],[2,1.2,18.28]],"ltp":0.0,"tv":0.0,"id":8681938}]}]}
{"op":"mcm","clk":"4293387693","pt":1632530892562,"mc":[{"id":"1.188134680","rc":[{"batb":[[0,1.66,311.4],[1,1.62,12],[2,1.25,29.25]],"ltp":0.0,"tv":0.0,"id":9631939},{"batb":[[0,1.66,312.55],[1,1.65,11.14],[2,1.25,29.25]],"ltp":0.0,"tv":0.0,"id":8681938}]}]}
{"op":"mcm","clk":"4293390315","pt":1632530941132,"mc":[{"id":"1.188134680","rc":[{"batb":[[1,1.25,29.25],[2,1.2,18.28]],"ltp":0.0,"tv":0.0,"id":8681938}]}]}
{"op":"mcm","clk":"4293390336","pt":1632530941433,"mc":[{"id":"1.188134680","rc":[{"batb":[[1,1.25,29.25],[2,1.23,15.9]],"ltp":0.0,"tv":0.0,"id":9631939}]}]}
{"op":"mcm","clk":"4293392976","pt":1632530992269,"mc":[{"id":"1.188134680","rc":[{"batb":[[0,1.67,11.14],[1,1.66,311.4],[2,1.25,29.25]],"ltp":0.0,"tv":0.0,"id":9631939}]}]}
{"op":"mcm","clk":"4293392983","pt":1632530992476,"mc":[{"id":"1.188134680","rc":[{"batb":[[0,1.67,11.14],[1,1.66,312.55],[2,1.25,29.25]],"ltp":0.0,"tv":0.0,"id":8681938}]}]}
{"op":"mcm","clk":"4293401706","pt":1632531177953,"mc":[{"id":"1.188134680","rc":[{"batb":[[0,1.69,73.46],[1,1.67,11.14]],"ltp":0.0,"tv":0.0,"id":9631939},{"batb":[[0,1.73,71.09],[1,1.67,11.14]],"ltp":0.0,"tv":0.0,"id":8681938}]}]}
{"op":"mcm","clk":"4293402087","pt":1632531183867,"mc":[{"id":"1.188134680","rc":[{"batb":[[0,1.68,307.65]],"ltp":0.0,"tv":0.0,"id":9631939},{"batb":[[0,1.7,305.11]],"ltp":0.0,"tv":0.0,"id":8681938}]}]}
{"op":"mcm","clk":"4293403022","pt":1632531201378,"mc":[{"id":"1.188134680","rc":[{"batb":[[1,1.25,29.25],[2,1.2,18.28]],"ltp":0.0,"tv":0.0,"id":8681938}]}]}
{"op":"mcm","clk":"4293403033","pt":1632531201584,"mc":[{"id":"1.188134680","rc":[{"batb":[[1,1.25,29.25],[2,1.23,15.9]],"ltp":0.0,"tv":0.0,"id":9631939}]}]}
{"op":"mcm","clk":"4293405370","pt":1632531253262,"mc":[{"id":"1.188134680","rc":[{"batb":[[0,1.69,10.29],[1,1.68,307.65],[2,1.25,29.25]],"ltp":0.0,"tv":0.0,"id":9631939},{"batb":[[0,1.71,10.29],[1,1.7,305.11],[2,1.25,29.25]],"ltp":0.0,"tv":0.0,"id":8681938}]}]}
{"op":"mcm","clk":"4293415816","pt":1632531483856,"mc":[{"id":"1.188134680","rc":[{"batb":[[0,1.71,302.06],[1,1.69,10.29]],"ltp":0.0,"tv":0.0,"id":9631939},{"batb":[[0,1.72,301.39],[1,1.71,10.29]],"ltp":0.0,"tv":0.0,"id":8681938}]}]}
{"op":"mcm","clk":"4293416703","pt":1632531500273,"mc":[{"id":"1.188134680","rc":[{"batb":[[0,1.69,10.29],[1,1.25,29.25],[2,1.23,15.9]],"ltp":0.0,"tv":0.0,"id":9631939},{"batb":[[0,1.71,10.29],[1,1.25,29.25],[2,1.2,18.28]],"ltp":0.0,"tv":0.0,"id":8681938}]}]}
{"op":"mcm","clk":"4293416724","pt":1632531500488,"mc":[{"id":"1.188134680","rc":[{"batb":[[0,1.72,72.17],[1,1.69,10.29],[2,1.25,29.25]],"ltp":0.0,"tv":0.0,"id":9631939},{"batb":[[0,1.73,71.09],[1,1.71,10.29],[2,1.25,29.25]],"ltp":0.0,"tv":0.0,"id":8681938}]}]}
{"op":"mcm","clk":"4293417049","pt":1632531506197,"mc":[{"id":"1.188134680","rc":[{"batb":[[0,1.74,296.92]],"ltp":0.0,"tv":0.0,"id":9631939},{"batb":[[0,1.74,298.01]],"ltp":0.0,"tv":0.0,"id":8681938}]}]}
{"op":"mcm","clk":"4293417153","pt":1632531508355,"mc":[{"id":"1.188134680","rc":[{"batb":[[1,1.25,29.25],[2,1.23,15.9]],"ltp":0.0,"tv":0.0,"id":9631939},{"batb":[[1,1.25,29.25],[2,1.2,18.28]],"ltp":0.0,"tv":0.0,"id":8681938}]}]}
{"op":"mcm","clk":"4293426454","pt":1632531681293,"mc":[{"id":"1.188134680","rc":[{"batb":[[0,1.25,29.25],[1,1.23,15.9],[2,1.01,618.28]],"ltp":0.0,"tv":0.0,"id":9631939},{"batb":[[0,1.25,29.25],[1,1.2,18.28],[2,1.01,618.28]],"ltp":0.0,"tv":0.0,"id":8681938}]}]}
{"op":"mcm","clk":"4293426471","pt":1632531681501,"mc":[{"id":"1.188134680","rc":[{"batb":[[0,1.75,70.92],[1,1.25,29.25],[2,1.23,15.9]],"ltp":0.0,"tv":0.0,"id":9631939},{"batb":[[0,1.75,70.27],[1,1.25,29.25],[2,1.2,18.28]],"ltp":0.0,"tv":0.0,"id":8681938}]}]}
{"op":"mcm","clk":"4293426794","pt":1632531687216,"mc":[{"id":"1.188134680","rc":[{"batb":[[0,1.76,277.74]],"ltp":0.0,"tv":0.0,"id":9631939},{"batb":[[0,1.76,277.61]],"ltp":0.0,"tv":0.0,"id":8681938}]}]}
{"op":"mcm","clk":"4293431970","pt":1632531783316,"mc":[{"id":"1.188134680","rc":[{"batb":[[0,1.76,18.18]],"ltp":0.0,"tv":0.0,"id":9631939},{"batb":[[0,1.76,15.15]],"ltp":0.0,"tv":0.0,"id":8681938}]}]}
{"op":"mcm","clk":"4293432363","pt":1632531789008,"mc":[{"id":"1.188134680","rc":[{"batb":[[0,1.77,255.67]],"ltp":0.0,"tv":0.0,"id":9631939},{"batb":[[0,1.77,256.13]],"ltp":0.0,"tv":0.0,"id":8681938}]}]}
{"op":"mcm","clk":"4293438338","pt":1632531908444,"mc":[{"id":"1.188134680","rc":[{"batb":[[0,1.25,29.25],[1,1.23,15.9],[2,1.01,618.28]],"ltp":0.0,"tv":0.0,"id":9631939},{"batb":[[0,1.25,29.25],[1,1.2,18.28],[2,1.01,618.28]],"ltp":0.0,"tv":0.0,"id":8681938}]}]}
{"op":"mcm","clk":"4293438701","pt":1632531914238,"mc":[{"id":"1.188134680","rc":[{"batb":[[0,1.54,378.97],[1,1.25,29.25],[2,1.23,15.9]],"ltp":0.0,"tv":0.0,"id":9631939},{"batb":[[0,1.57,376.13],[1,1.25,29.25],[2,1.2,18.28]],"ltp":0.0,"tv":0.0,"id":8681938}]}]}
{"op":"mcm","clk":"4293443577","pt":1632532002663,"mc":[{"id":"1.188134680","rc":[{"batb":[[0,1.59,78.14]],"ltp":0.0,"tv":0.0,"id":9631939},{"batb":[[0,1.64,75.04]],"ltp":0.0,"tv":0.0,"id":8681938}]}]}
{"op":"mcm","clk":"4293443881","pt":1632532008352,"mc":[{"id":"1.188134680","rc":[{"batb":[[0,1.25,29.25],[1,1.23,15.9],[2,1.01,618.28]],"ltp":0.0,"tv":0.0,"id":9631939},{"batb":[[0,1.25,29.25],[1,1.2,18.28],[2,1.01,618.28]],"ltp":0.0,"tv":0.0,"id":8681938}]}]}
{"op":"mcm","clk":"4293443888","pt":1632532008456,"mc":[{"id":"1.188134680","rc":[{"batb":[[0,1.64,315.25],[1,1.25,29.25],[2,1.23,15.9]],"ltp":0.0,"tv":0.0,"id":9631939},{"batb":[[0,1.67,310.65],[1,1.25,29.25],[2,1.2,18.28]],"ltp":0.0,"tv":0.0,"id":8681938}]}]}
{"op":"mcm","clk":"4293449619","pt":1632532125309,"mc":[{"id":"1.188134680","rc":[{"batb":[[0,1.25,29.25],[1,1.23,15.9],[2,1.01,618.28]],"ltp":0.0,"tv":0.0,"id":9631939},{"batb":[[0,1.25,29.25],[1,1.2,18.28],[2,1.01,618.28]],"ltp":0.0,"tv":0.0,"id":8681938}]}]}
{"op":"mcm","clk":"4293449644","pt":1632532125720,"mc":[{"id":"1.188134680","rc":[{"batb":[[0,1.71,72.59],[1,1.25,29.25],[2,1.23,15.9]],"ltp":0.0,"tv":0.0,"id":9631939},{"batb":[[0,1.71,71.94],[1,1.25,29.25],[2,1.2,18.28]],"ltp":0.0,"tv":0.0,"id":8681938}]}]}
{"op":"mcm","clk":"4293449925","pt":1632532131248,"mc":[{"id":"1.188134680","rc":[{"batb":[[0,1.73,298.65]],"ltp":0.0,"tv":0.0,"id":9631939},{"batb":[[0,1.73,299.75]],"ltp":0.0,"tv":0.0,"id":8681938}]}]}
{"op":"mcm","clk":"4293456986","pt":1632532271294,"mc":[{"id":"1.188134680","rc":[{"batb":[[0,1.74,71.33]],"ltp":0.0,"tv":0.0,"id":9631939},{"batb":[[0,1.74,70.68]],"ltp":0.0,"tv":0.0,"id":8681938}]}]}
{"op":"mcm","clk":"4293457275","pt":1632532276886,"mc":[{"id":"1.188134680","rc":[{"batb":[[0,1.75,295.2]],"ltp":0.0,"tv":0.0,"id":9631939},{"batb":[[0,1.75,296.29]],"ltp":0.0,"tv":0.0,"id":8681938}]}]}
{"op":"mcm","clk":"4293490455","pt":1632532700334,"mc":[{"id":"1.188134680","rc":[{"batb":[[0,1.5,82.9]],"ltp":0.0,"tv":0.0,"id":9631939},{"batb":[[0,1.44,85.62]],"ltp":0.0,"tv":0.0,"id":8681938}]}]}
{"op":"mcm","clk":"4293490488","pt":1632532700906,"mc":[{"id":"1.188134680","rc":[{"batb":[[0,1.47,84.61]],"ltp":0.0,"tv":0.0,"id":9631939},{"batb":[[0,1.54,79.98]],"ltp":0.0,"tv":0.0,"id":8681938}]}]}
{"op":"mcm","clk":"4293490706","pt":1632532705841,"mc":[{"id":"1.188134680","rc":[{"batb":[[0,1.7,303.99]],"ltp":0.0,"tv":0.0,"id":9631939},{"batb":[[0,1.63,318.37]],"ltp":0.0,"tv":0.0,"id":8681938}]}]}
{"op":"mcm","clk":"4293494450","pt":1632532789255,"mc":[{"id":"1.188134680","rc":[{"batb":[[0,1.71,10.29],[1,1.7,303.99],[2,1.25,29.25]],"ltp":0.0,"tv":0.0,"id":9631939},{"batb":[[0,1.64,11.14],[1,1.63,318.37],[2,1.25,29.25]],"ltp":0.0,"tv":0.0,"id":8681938}]}]}
{"op":"mcm","clk":"4293504644","pt":1632532995773,"mc":[{"id":"1.188134680","rc":[{"batb":[[0,1.73,71.75],[1,1.71,10.29]],"ltp":0.0,"tv":0.0,"id":9631939},{"batb":[[0,1.68,73.24],[1,1.64,11.14]],"ltp":0.0,"tv":0.0,"id":8681938}]}]}
{"op":"mcm","clk":"4293504942","pt":1632533001363,"mc":[{"id":"1.188134680","rc":[{"batb":[[0,1.71,10.29],[1,1.25,29.25],[2,1.23,15.9]],"ltp":0.0,"tv":0.0,"id":9631939},{"batb":[[0,1.64,11.14],[1,1.25,29.25],[2,1.2,18.28]],"ltp":0.0,"tv":0.0,"id":8681938}]}]}
{"op":"mcm","clk":"4293504949","pt":1632533001465,"mc":[{"id":"1.188134680","rc":[{"batb":[[0,1.74,296.92],[1,1.71,10.29],[2,1.25,29.25]],"ltp":0.0,"tv":0.0,"id":9631939},{"batb":[[0,1.7,305.11],[1,1.64,11.14],[2,1.25,29.25]],"ltp":0.0,"tv":0.0,"id":8681938}]}]}
{"op":"mcm","clk":"4293506462","pt":1632533031201,"mc":[{"id":"1.188134680","rc":[{"batb":[[1,1.25,29.25],[2,1.2,18.28]],"ltp":0.0,"tv":0.0,"id":8681938}]}]}
{"op":"mcm","clk":"4293506484","pt":1632533031509,"mc":[{"id":"1.188134680","rc":[{"batb":[[1,1.25,29.25],[2,1.23,15.9]],"ltp":0.0,"tv":0.0,"id":9631939}]}]}
{"op":"mcm","clk":"4293512480","pt":1632533153140,"mc":[{"id":"1.188134680","rc":[{"batb":[[0,1.71,10.29],[1,1.7,305.11],[2,1.25,29.25]],"ltp":0.0,"tv":0.0,"id":8681938}]}]}
{"op":"mcm","clk":"4293512981","pt":1632533163953,"mc":[{"id":"1.188134680","rc":[{"batb":[[0,1.58,78.64]],"ltp":0.0,"tv":0.0,"id":9631939},{"batb":[[0,1.72,71.51],[1,1.71,10.29]],"ltp":0.0,"tv":0.0,"id":8681938}]}]}
{"op":"mcm","clk":"4293513249","pt":1632533169342,"mc":[{"id":"1.188134680","rc":[{"batb":[[0,1.73,298.65]],"ltp":0.0,"tv":0.0,"id":9631939},{"batb":[[0,1.72,301.52]],"ltp":0.0,"tv":0.0,"id":8681938}]}]}
{"op":"mcm","clk":"4293518819","pt":1632533276200,"mc":[{"id":"1.188134680","rc":[{"batb":[[1,1.25,29.25],[2,1.2,18.28]],"ltp":0.0,"tv":0.0,"id":8681938}]}]}
{"op":"mcm","clk":"4293526668","pt":1632533446307,"mc":[{"id":"1.188134680","rc":[{"batb":[[0,1.25,29.25],[1,1.23,15.9],[2,1.01,618.28]],"ltp":0.0,"tv":0.0,"id":9631939},{"batb":[[0,1.25,29.25],[1,1.2,18.28],[2,1.01,618.28]],"ltp":0.0,"tv":0.0,"id":8681938}]}]}
{"op":"mcm","clk":"4293526684","pt":1632533446617,"mc":[{"id":"1.188134680","rc":[{"batb":[[0,1.74,71.33],[1,1.25,29.25],[2,1.23,15.9]],"ltp":0.0,"tv":0.0,"id":9631939},{"batb":[[0,1.73,71.09],[1,1.25,29.25],[2,1.2,18.28]],"ltp":0.0,"tv":0.0,"id":8681938}]}]}
{"op":"mcm","clk":"4293526960","pt":1632533452131,"mc":[{"id":"1.188134680","rc":[{"batb":[[0,1.75,295.2]],"ltp":0.0,"tv":0.0,"id":9631939},{"batb":[[0,1.74,298.01]],"ltp":0.0,"tv":0.0,"id":8681938}]}]}
{"op":"mcm","clk":"4293535917","pt":1632533635088,"mc":[{"id":"1.188134680","rc":[{"batb":[[0,1.25,29.25],[1,1.23,15.9],[2,1.01,618.28]],"ltp":0.0,"tv":0.0,"id":9631939},{"batb":[[0,1.25,29.25],[1,1.2,18.28],[2,1.01,618.28]],"ltp":0.0,"tv":0.0,"id":8681938}]}]}
{"op":"mcm","clk":"4293535940","pt":1632533635452,"mc":[{"id":"1.188134680","rc":[{"batb":[[0,1.75,70.92],[1,1.25,29.25],[2,1.23,15.9]],"ltp":0.0,"tv":0.0,"id":9631939},{"batb":[[0,1.75,70.27],[1,1.25,29.25],[2,1.2,18.28]],"ltp":0.0,"tv":0.0,"id":8681938}]}]}
{"op":"mcm","clk":"4293536233","pt":1632533641090,"mc":[{"id":"1.188134680","rc":[{"batb":[[0,1.76,277.74]],"ltp":0.0,"tv":0.0,"id":9631939},{"batb":[[0,1.76,277.61]],"ltp":0.0,"tv":0.0,"id":8681938}]}]}
{"op":"mcm","clk":"4293546198","pt":1632533829839,"mc":[{"id":"1.188134680","rc":[{"batb":[[0,1.76,18.18]],"ltp":0.0,"tv":0.0,"id":9631939},{"batb":[[0,1.76,15.15]],"ltp":0.0,"tv":0.0,"id":8681938}]}]}
{"op":"mcm","clk":"4293546496","pt":1632533835353,"mc":[{"id":"1.188134680","rc":[{"batb":[[0,1.25,29.25],[1,1.23,15.9],[2,1.01,618.28]],"ltp":0.0,"tv":0.0,"id":9631939},{"batb":[[0,1.25,29.25],[1,1.2,18.28],[2,1.01,618.28]],"ltp":0.0,"tv":0.0,"id":8681938}]}]}
{"op":"mcm","clk":"4293546502","pt":1632533835459,"mc":[{"id":"1.188134680","rc":[{"batb":[[0,1.77,255.67],[1,1.25,29.25],[2,1.23,15.9]],"ltp":0.0,"tv":0.0,"id":9631939},{"batb":[[0,1.77,256.13],[1,1.25,29.25],[2,1.2,18.28]],"ltp":0.0,"tv":0.0,"id":8681938}]}]}
{"op":"mcm","clk":"4293563564","pt":1632534146233,"mc":[{"id":"1.188134680","rc":[{"batb":[[0,1.78,274.58]],"ltp":0.0,"tv":0.0,"id":9631939},{"batb":[[0,1.78,274.46]],"ltp":0.0,"tv":0.0,"id":8681938}]}]}
{"op":"mcm","clk":"4293566662","pt":1632534207340,"mc":[{"id":"1.188134680","rc":[{"batb":[[0,1.25,29.25],[1,1.23,15.9],[2,1.01,618.28]],"ltp":0.0,"tv":0.0,"id":9631939},{"batb":[[0,1.25,29.25],[1,1.2,18.28],[2,1.01,618.28]],"ltp":0.0,"tv":0.0,"id":8681938}]}]}
{"op":"mcm","clk":"4293566688","pt":1632534207654,"mc":[{"id":"1.188134680","rc":[{"batb":[[0,1.45,85.79],[1,1.25,29.25],[2,1.23,15.9]],"ltp":0.0,"tv":0.0,"id":9631939},{"batb":[[0,1.6,76.94],[1,1.25,29.25],[2,1.2,18.28]],"ltp":0.0,"tv":0.0,"id":8681938}]}]}
{"op":"mcm","clk":"4293566972","pt":1632534213378,"mc":[{"id":"1.188134680","rc":[{"batb":[[0,1.54,335.99],[1,1.46,14.57],[2,1.25,29.25]],"ltp":0.0,"tv":0.0,"id":9631939},{"batb":[[0,1.69,306.93],[1,1.61,12],[2,1.25,29.25]],"ltp":0.0,"tv":0.0,"id":8681938}]}]}
{"op":"mcm","clk":"4293571321","pt":1632534310077,"mc":[{"id":"1.188134680","rc":[{"batb":[[0,1.46,14.57],[1,1.25,29.25],[2,1.23,15.9]],"ltp":0.0,"tv":0.0,"id":9631939},{"batb":[[0,1.61,12],[1,1.25,29.25],[2,1.2,18.28]],"ltp":0.0,"tv":0.0,"id":8681938}]}]}
{"op":"mcm","clk":"4293571342","pt":1632534310440,"mc":[{"id":"1.188134680","rc":[{"batb":[[0,1.55,80.19],[1,1.46,14.57],[2,1.25,29.25]],"ltp":0.0,"tv":0.0,"id":9631939},{"batb":[[0,1.7,72.36],[1,1.61,12],[2,1.25,29.25]],"ltp":0.0,"tv":0.0,"id":8681938}]}]}
{"op":"mcm","clk":"4293571629","pt":1632534316241,"mc":[{"id":"1.188134680","rc":[{"batb":[[0,1.66,311.4],[1,1.25,29.25],[2,1.23,15.9]],"ltp":0.0,"tv":0.0,"id":9631939},{"batb":[[0,1.73,299.75],[1,1.25,29.25],[2,1.2,18.28]],"ltp":0.0,"tv":0.0,"id":8681938}]}]}
{"op":"mcm","clk":"4293576506","pt":1632534424910,"mc":[{"id":"1.188134680","rc":[{"batb":[[0,1.67,11.14],[1,1.66,311.4],[2,1.25,29.25]],"ltp":0.0,"tv":0.0,"id":9631939}]}]}
{"op":"mcm","clk":"4293581199","pt":1632534538210,"mc":[{"id":"1.188134680","rc":[{"batb":[[0,1.7,73.03],[1,1.67,11.14]],"ltp":0.0,"tv":0.0,"id":9631939},{"batb":[[0,1.74,70.68]],"ltp":0.0,"tv":0.0,"id":8681938}]}]}
{"op":"mcm","clk":"4293581445","pt":1632534543704,"mc":[{"id":"1.188134680","rc":[{"batb":[[0,1.71,302.19]],"ltp":0.0,"tv":0.0,"id":9631939},{"batb":[[0,1.52,341.72]],"ltp":0.0,"tv":0.0,"id":8681938}]}]}
{"op":"mcm","clk":"4293581539","pt":1632534546232,"mc":[{"id":"1.188134680","rc":[{"batb":[[1,1.25,29.25],[2,1.23,15.9]],"ltp":0.0,"tv":0.0,"id":9631939},{"batb":[[0,1.53,12.86],[1,1.52,341.72],[2,1.25,29.25]],"ltp":0.0,"tv":0.0,"id":8681938}]}]}
{"op":"mcm","clk":"4293591242","pt":1632534817185,"mc":[{"id":"1.188134680","rc":[{"batb":[[0,1.47,84.61]],"ltp":0.0,"tv":0.0,"id":9631939},{"batb":[[0,1.62,75.98],[1,1.53,12.86]],"ltp":0.0,"tv":0.0,"id":8681938}]}]}
{"op":"mcm","clk":"4293591444","pt":1632534823003,"mc":[{"id":"1.188134680","rc":[{"batb":[[0,1.54,335.99]],"ltp":0.0,"tv":0.0,"id":9631939},{"batb":[[0,1.7,305.11]],"ltp":0.0,"tv":0.0,"id":8681938}]}]}
{"op":"mcm","clk":"4293593624","pt":1632534883866,"mc":[{"id":"1.188134680","rc":[{"batb":[[0,1.55,12.86],[1,1.54,335.99],[2,1.25,29.25]],"ltp":0.0,"tv":0.0,"id":9631939},{"batb":[[1,1.25,29.25],[2,1.2,18.28]],"ltp":0.0,"tv":0.0,"id":8681938}]}]}
{"op":"mcm","clk":"4293598259","pt":1632535007160,"mc":[{"id":"1.188134680","rc":[{"batb":[[0,1.71,10.29],[1,1.7,305.11],[2,1.25,29.25]],"ltp":0.0,"tv":0.0,"id":8681938}]}]}
{"op":"mcm","clk":"4293602573","pt":1632535122921,"mc":[{"id":"1.188134680","rc":[{"batb":[[0,1.7,303.86],[1,1.55,12.86]],"ltp":0.0,"tv":0.0,"id":9631939},{"batb":[[0,1.73,299.63],[1,1.71,10.29]],"ltp":0.0,"tv":0.0,"id":8681938}]}]}
{"op":"mcm","clk":"4293602881","pt":1632535132123,"mc":[{"id":"1.188134680","rc":[{"batb":[[1,1.25,29.25],[2,1.2,18.28]],"ltp":0.0,"tv":0.0,"id":8681938}]}]}
{"op":"mcm","clk":"4293602893","pt":1632535132426,"mc":[{"id":"1.188134680","rc":[{"batb":[[1,1.25,29.25],[2,1.23,15.9]],"ltp":0.0,"tv":0.0,"id":9631939}]}]}
{"op":"mcm","clk":"4293602969","pt":1632535134383,"mc":[{"id":"1.188134680","rc":[{"batb":[[0,1.44,86.4]],"ltp":0.0,"tv":0.0,"id":9631939},{"batb":[[0,1.51,81.59]],"ltp":0.0,"tv":0.0,"id":8681938}]}]}
{"op":"mcm","clk":"4293603182","pt":1632535140135,"mc":[{"id":"1.188134680","rc":[{"batb":[[0,1.62,319.19]],"ltp":0.0,"tv":0.0,"id":9631939},{"batb":[[0,1.53,339.46]],"ltp":0.0,"tv":0.0,"id":8681938}]}]}
{"op":"mcm","clk":"4293608764","pt":1632535257379,"mc":[{"id":"1.188134680","rc":[{"batb":[[0,1.63,12],[1,1.62,319.19],[2,1.25,29.25]],"ltp":0.0,"tv":0.0,"id":9631939},{"batb":[[0,1.54,12.86],[1,1.53,339.46],[2,1.25,29.25]],"ltp":0.0,"tv":0.0,"id":8681938}]}]}
{"op":"mcm","clk":"4293610721","pt":1632535294102,"mc":[{"id":"1.188134680","rc":[{"batb":[[0,1.65,75.27],[1,1.63,12]],"ltp":0.0,"tv":0.0,"id":9631939},{"batb":[[0,1.7,72.36],[1,1.54,12.86]],"ltp":0.0,"tv":0.0,"id":8681938}]}]}
{"op":"mcm","clk":"4293611075","pt":1632535300328,"mc":[{"id":"1.188134680","rc":[{"batb":[[0,1.67,309.51]],"ltp":0.0,"tv":0.0,"id":9631939},{"batb":[[0,1.54,12.86],[1,1.25,29.25],[2,1.2,18.28]],"ltp":0.0,"tv":0.0,"id":8681938}]}]}
{"op":"mcm","clk":"4293611085","pt":1632535300425,"mc":[{"id":"1.188134680","rc":[{"batb":[[0,1.56,332.84],[1,1.54,12.86],[2,1.25,29.25]],"ltp":0.0,"tv":0.0,"id":8681938}]}]}
{"op":"mcm","clk":"4293615039","pt":1632535385004,"mc":[{"id":"1.188134680","rc":[{"batb":[[1,1.25,29.25],[2,1.23,15.9]],"ltp":0.0,"tv":0.0,"id":9631939},{"batb":[[1,1.25,29.25],[2,1.2,18.28]],"ltp":0.0,"tv":0.0,"id":8681938}]}]}
{"op":"mcm","clk":"4293620125","pt":1632535505868,"mc":[{"id":"1.188134680","rc":[{"batb":[[0,1.68,11.14],[1,1.67,309.51],[2,1.25,29.25]],"ltp":0.0,"tv":0.0,"id":9631939},{"batb":[[0,1.57,12.86],[1,1.56,332.84],[2,1.25,29.25]],"ltp":0.0,"tv":0.0,"id":8681938}]}]}
{"op":"mcm","clk":"4293623610","pt":1632535600229,"mc":[{"id":"1.188134680","rc":[{"batb":[[0,1.7,303.86],[1,1.68,11.14]],"ltp":0.0,"tv":0.0,"id":9631939},{"batb":[[0,1.65,314.33],[1,1.57,12.86]],"ltp":0.0,"tv":0.0,"id":8681938}]}]}
{"op":"mcm","clk":"4293624471","pt":1632535626170,"mc":[{"id":"1.188134680","rc":[{"batb":[[1,1.25,29.25],[2,1.23,15.9]],"ltp":0.0,"tv":0.0,"id":9631939},{"batb":[[1,1.25,29.25],[2,1.2,18.28]],"ltp":0.0,"tv":0.0,"id":8681938}]}]}
{"op":"mcm","clk":"4293628185","pt":1632535737308,"mc":[{"id":"1.188134680","rc":[{"batb":[[0,1.71,10.29],[1,1.7,303.86],[2,1.25,29.25]],"ltp":0.0,"tv":0.0,"id":9631939},{"batb":[[0,1.66,11.14],[1,1.65,314.33],[2,1.25,29.25]],"ltp":0.0,"tv":0.0,"id":8681938}]}]}
{"op":"mcm","clk":"4293633896","pt":1632535900297,"mc":[{"id":"1.188134680","rc":[{"batb":[[0,1.72,300.29],[1,1.71,10.29]],"ltp":0.0,"tv":0.0,"id":9631939},{"batb":[[0,1.72,301.39],[1,1.66,11.14]],"ltp":0.0,"tv":0.0,"id":8681938}]}]}
{"op":"mcm","clk":"4293635407","pt":1632535939254,"mc":[{"id":"1.188134680","rc":[{"batb":[[0,1.71,10.29],[1,1.25,29.25],[2,1.23,15.9]],"ltp":0.0,"tv":0.0,"id":9631939},{"batb":[[0,1.66,11.14],[1,1.25,29.25],[2,1.2,18.28]],"ltp":0.0,"tv":0.0,"id":8681938}]}]}
{"op":"mcm","clk":"4293635427","pt":1632535939666,"mc":[{"id":"1.188134680","rc":[{"batb":[[0,1.72,72.17],[1,1.71,10.29],[2,1.25,29.25]],"ltp":0.0,"tv":0.0,"id":9631939},{"batb":[[0,1.7,72.36],[1,1.66,11.14],[2,1.25,29.25]],"ltp":0.0,"tv":0.0,"id":8681938}]}]}
{"op":"mcm","clk":"4293635685","pt":1632535945331,"mc":[{"id":"1.188134680","rc":[{"batb":[[0,1.71,10.29],[1,1.25,29.25],[2,1.23,15.9]],"ltp":0.0,"tv":0.0,"id":9631939},{"batb":[[0,1.66,11.14],[1,1.25,29.25],[2,1.2,18.28]],"ltp":0.0,"tv":0.0,"id":8681938}]}]}
{"op":"mcm","clk":"4293635695","pt":1632535945537,"mc":[{"id":"1.188134680","rc":[{"batb":[[0,1.72,300.41],[1,1.71,10.29],[2,1.25,29.25]],"ltp":0.0,"tv":0.0,"id":9631939},{"batb":[[0,1.69,306.93],[1,1.66,11.14],[2,1.25,29.25]],"ltp":0.0,"tv":0.0,"id":8681938}]}]}
{"op":"mcm","clk":"4293637275","pt":1632535989325,"mc":[{"id":"1.188134680","rc":[{"batb":[[1,1.25,29.25],[2,1.23,15.9]],"ltp":0.0,"tv":0.0,"id":9631939},{"batb":[[1,1.25,29.25],[2,1.2,18.28]],"ltp":0.0,"tv":0.0,"id":8681938}]}]}
{"op":"mcm","clk":"4293639465","pt":1632536054126,"mc":[{"id":"1.188134680","rc":[{"batb":[[0,1.73,71.75]],"ltp":0.0,"tv":0.0,"id":9631939},{"batb":[[0,1.7,72.36]],"ltp":0.0,"tv":0.0,"id":8681938}]}]}
{"op":"mcm","clk":"4293639634","pt":1632536060175,"mc":[{"id":"1.188134680","rc":[{"batb":[[0,1.74,296.92]],"ltp":0.0,"tv":0.0,"id":9631939},{"batb":[[0,1.71,303.3]],"ltp":0.0,"tv":0.0,"id":8681938}]}]}
{"op":"mcm","clk":"4293660589","pt":1632536645948,"mc":[{"id":"1.188134680","rc":[{"batb":[[0,1.84,5],[1,1.83,5],[2,1.74,296.92]],"batl":[[0,2.16,4],[1,2.18,37.92],[2,2.2,25]],"ltp":0.0,"tv":0.0,"id":9631939},{"batb":[[0,1.84,4],[1,1.83,5],[2,1.71,303.3]],"batl":[[0,2.18,4],[1,2.2,25],[2,990,2.2]],"ltp":0.0,"tv":0.0,"id":8681938}]}]}
{"op":"mcm","clk":"4293661176","pt":1632536660328,"mc":[{"id":"1.188134680","rc":[{"batb":[[0,1.85,248.87],[1,1.84,4],[2,1.83,5]],"ltp":0.0,"tv":0.0,"id":8681938}]}]}
{"op":"mcm","clk":"4293661201","pt":1632536660847,"mc":[{"id":"1.188134680","rc":[{"batb":[[0,1.84,245.41],[1,1.25,29.25],[2,1.23,15.9]],"batl":[[0,2.14,38.62],[1,2.16,4]],"ltp":0.0,"tv":0.0,"id":9631939},{"batb":[[2,1.25,29.25]],"ltp":0.0,"tv":0.0,"id":8681938}]}]}
{"op":"mcm","clk":"4293671809","pt":1632536947292,"mc":[{"id":"1.188134680","rc":[{"batb":[[0,1.84,5]],"ltp":0.0,"tv":0.0,"id":9631939},{"batb":[[0,1.86,45.78]],"ltp":0.0,"tv":0.0,"id":8681938}]}]}
{"op":"mcm","clk":"4293672063","pt":1632536953198,"mc":[{"id":"1.188134680","rc":[{"batb":[[0,1.84,245.41]],"ltp":0.0,"tv":0.0,"id":9631939},{"batb":[[0,1.84,4],[1,1.25,29.25],[2,1.2,18.28]],"ltp":0.0,"tv":0.0,"id":8681938}]}]}
{"op":"mcm","clk":"4293672075","pt":1632536953404,"mc":[{"id":"1.188134680","rc":[{"batb":[[0,1.85,248.98],[1,1.84,4],[2,1.25,29.25]],"ltp":0.0,"tv":0.0,"id":8681938}]}]}
{"op":"mcm","clk":"4293684084","pt":1632537241923,"mc":[{"id":"1.188134680","rc":[{"batb":[[0,1.84,5]],"ltp":0.0,"tv":0.0,"id":9631939},{"batb":[[0,1.85,46.03]],"ltp":0.0,"tv":0.0,"id":8681938}]}]}
{"op":"mcm","clk":"4293684365","pt":1632537247597,"mc":[{"id":"1.188134680","rc":[{"batb":[[0,1.84,245.41]],"ltp":0.0,"tv":0.0,"id":9631939},{"batb":[[0,1.86,247.62]],"ltp":0.0,"tv":0.0,"id":8681938}]}]}
{"op":"mcm","clk":"4293690341","pt":1632537373104,"mc":[{"id":"1.188134680","rc":[{"batb":[[0,1.84,5]],"ltp":0.0,"tv":0.0,"id":9631939},{"batb":[[0,1.85,46.03]],"ltp":0.0,"tv":0.0,"id":8681938}]}]}
{"op":"mcm","clk":"4293690679","pt":1632537379198,"mc":[{"id":"1.188134680","rc":[{"batb":[[0,1.84,245.41]],"ltp":0.0,"tv":0.0,"id":9631939},{"batb":[[0,1.86,247.62]],"ltp":0.0,"tv":0.0,"id":8681938}]}]}
{"op":"mcm","clk":"4293698638","pt":1632537544751,"mc":[{"id":"1.188134680","rc":[{"batb":[[0,1.84,5]],"ltp":0.0,"tv":0.0,"id":9631939},{"batb":[[0,1.87,45.53]],"ltp":0.0,"tv":0.0,"id":8681938}]}]}
{"op":"mcm","clk":"4293698904","pt":1632537550643,"mc":[{"id":"1.188134680","rc":[{"batb":[[0,1.84,245.41]],"ltp":0.0,"tv":0.0,"id":9631939},{"batb":[[0,1.93,214.99]],"ltp":0.0,"tv":0.0,"id":8681938}]}]}
{"op":"mcm","clk":"4293707433","pt":1632537798064,"mc":[{"id":"1.188134680","rc":[{"batb":[[0,1.84,5]],"ltp":0.0,"tv":0.0,"id":9631939},{"batb":[[0,1.86,45.78]],"ltp":0.0,"tv":0.0,"id":8681938}]}]}
{"op":"mcm","clk":"4293707657","pt":1632537804155,"mc":[{"id":"1.188134680","rc":[{"batb":[[0,1.84,245.41]],"ltp":0.0,"tv":0.0,"id":9631939},{"batb":[[0,1.87,246.29]],"ltp":0.0,"tv":0.0,"id":8681938}]}]}
{"op":"mcm","clk":"4293711687","pt":1632537913275,"mc":[{"id":"1.188134680","rc":[{"batb":[[0,1.84,5]],"ltp":0.0,"tv":0.0,"id":9631939},{"batb":[[0,1.86,45.78]],"ltp":0.0,"tv":0.0,"id":8681938}]}]}
{"op":"mcm","clk":"4293711938","pt":1632537918755,"mc":[{"id":"1.188134680","rc":[{"batb":[[0,1.84,245.41]],"ltp":0.0,"tv":0.0,"id":9631939},{"batb":[[0,1.84,4],[1,1.25,29.25],[2,1.2,18.28]],"ltp":0.0,"tv":0.0,"id":8681938}]}]}
{"op":"mcm","clk":"4293735557","pt":1632538169131,"mc":[{"id":"1.188134680","rc":[{"batb":[[0,1.84,5]],"ltp":0.0,"tv":0.0,"id":9631939},{"batb":[[0,1.85,46.03],[1,1.84,4],[2,1.25,29.25]],"ltp":0.0,"tv":0.0,"id":8681938}]}]}
{"op":"mcm","clk":"4293735802","pt":1632538174742,"mc":[{"id":"1.188134680","rc":[{"batb":[[0,1.84,245.41]],"ltp":0.0,"tv":0.0,"id":9631939},{"batb":[[0,1.86,247.62]],"ltp":0.0,"tv":0.0,"id":8681938}]}]}
{"op":"mcm","clk":"4293740591","pt":1632538305052,"mc":[{"id":"1.188134680","rc":[{"batb":[[0,1.84,5]],"ltp":0.0,"tv":0.0,"id":9631939},{"batb":[[0,1.84,4],[1,1.25,29.25],[2,1.2,18.28]],"ltp":0.0,"tv":0.0,"id":8681938}]}]}
{"op":"mcm","clk":"4293740615","pt":1632538305517,"mc":[{"id":"1.188134680","rc":[{"batb":[[0,1.86,45.78],[1,1.84,4],[2,1.25,29.25]],"ltp":0.0,"tv":0.0,"id":8681938}]}]}
{"op":"mcm","clk":"4293740856","pt":1632538311250,"mc":[{"id":"1.188134680","rc":[{"batb":[[0,1.84,245.41]],"ltp":0.0,"tv":0.0,"id":9631939},{"batb":[[0,1.87,246.29]],"ltp":0.0,"tv":0.0,"id":8681938}]}]}
{"op":"mcm","clk":"4293744783","pt":1632538416557,"mc":[{"id":"1.188134680","rc":[{"batb":[[0,1.84,5]],"ltp":0.0,"tv":0.0,"id":9631939},{"batb":[[0,1.9,21.9]],"ltp":0.0,"tv":0.0,"id":8681938}]}]}
{"op":"mcm","clk":"4293745028","pt":1632538422383,"mc":[{"id":"1.188134680","rc":[{"batb":[[0,1.84,245.41]],"ltp":0.0,"tv":0.0,"id":9631939},{"batb":[[0,1.84,4],[1,1.25,29.25],[2,1.2,18.28]],"ltp":0.0,"tv":0.0,"id":8681938}]}]}
{"op":"mcm","clk":"4293745032","pt":1632538422480,"mc":[{"id":"1.188134680","rc":[{"batb":[[0,1.92,216.12],[1,1.84,4],[2,1.25,29.25]],"ltp":0.0,"tv":0.0,"id":8681938}]}]}
{"op":"mcm","clk":"4293750714","pt":1632538582216,"mc":[{"id":"1.188134680","rc":[{"batb":[[0,1.84,5]],"ltp":0.0,"tv":0.0,"id":9631939},{"batb":[[0,1.86,45.78]],"ltp":0.0,"tv":0.0,"id":8681938}]}]}
{"op":"mcm","clk":"4293750878","pt":1632538587954,"mc":[{"id":"1.188134680","rc":[{"batb":[[0,1.84,245.41]],"ltp":0.0,"tv":0.0,"id":9631939},{"batb":[[0,1.87,246.29]],"ltp":0.0,"tv":0.0,"id":8681938}]}]}
{"op":"mcm","clk":"4293755651","pt":1632538739884,"mc":[{"id":"1.188134680","rc":[{"batb":[[0,1.84,5]],"ltp":0.0,"tv":0.0,"id":9631939},{"batb":[[0,1.89,22.02]],"ltp":0.0,"tv":0.0,"id":8681938}]}]}
{"op":"mcm","clk":"4293755882","pt":1632538745791,"mc":[{"id":"1.188134680","rc":[{"batb":[[0,1.84,245.41]],"ltp":0.0,"tv":0.0,"id":9631939},{"batb":[[0,1.93,214.99]],"ltp":0.0,"tv":0.0,"id":8681938}]}]}
{"op":"mcm","clk":"4293758540","pt":1632538826027,"mc":[{"id":"1.188134680","rc":[{"batb":[[0,1.85,16.17],[1,1.84,245.41],[2,1.25,29.25]],"ltp":0.0,"tv":0.0,"id":9631939},{"batb":[[0,1.97,14.72],[1,1.93,214.99],[2,1.84,4]],"ltp":0.0,"tv":0.0,"id":8681938}]}]}
{"op":"mcm","clk":"4293760043","pt":1632538864170,"mc":[{"id":"1.188134680","rc":[{"batb":[[0,1.84,245.41],[1,1.25,29.25],[2,1.23,15.9]],"ltp":0.0,"tv":0.0,"id":9631939},{"batb":[[0,1.93,214.99],[1,1.84,4],[2,1.25,29.25]],"ltp":0.0,"tv":0.0,"id":8681938}]}]}
{"op":"mcm","clk":"4293762358","pt":1632538915824,"mc":[{"id":"1.188134680","rc":[{"batb":[[0,1.84,5]],"ltp":0.0,"tv":0.0,"id":9631939},{"batb":[[0,1.94,21.44]],"ltp":0.0,"tv":0.0,"id":8681938}]}]}
{"op":"mcm","clk":"4293762639","pt":1632538921739,"mc":[{"id":"1.188134680","rc":[{"batb":[[0,1.84,245.41]],"ltp":0.0,"tv":0.0,"id":9631939},{"batb":[[0,1.95,212.77]],"ltp":0.0,"tv":0.0,"id":8681938}]}]}
{"op":"mcm","clk":"4293768635","pt":1632539062381,"mc":[{"id":"1.188134680","rc":[{"batb":[[0,1.84,5]],"ltp":0.0,"tv":0.0,"id":9631939},{"batb":[[0,1.84,4],[1,1.25,29.25],[2,1.2,18.28]],"ltp":0.0,"tv":0.0,"id":8681938}]}]}
{"op":"mcm","clk":"4293768640","pt":1632539062490,"mc":[{"id":"1.188134680","rc":[{"batb":[[0,1.86,45.78],[1,1.84,4],[2,1.25,29.25]],"ltp":0.0,"tv":0.0,"id":8681938}]}]}
{"op":"mcm","clk":"4293768931","pt":1632539067952,"mc":[{"id":"1.188134680","rc":[{"batb":[[0,1.84,245.41]],"ltp":0.0,"tv":0.0,"id":9631939},{"batb":[[0,1.87,246.29]],"ltp":0.0,"tv":0.0,"id":8681938}]}]}
{"op":"mcm","clk":"4293776570","pt":1632539216347,"mc":[{"id":"1.188134680","rc":[{"batb":[[0,1.84,5]],"ltp":0.0,"tv":0.0,"id":9631939},{"batb":[[0,1.84,4],[1,1.25,29.25],[2,1.2,18.28]],"ltp":0.0,"tv":0.0,"id":8681938}]}]}
{"op":"mcm","clk":"4293776579","pt":1632539216451,"mc":[{"id":"1.188134680","rc":[{"batb":[[0,1.88,22.14],[1,1.84,4],[2,1.25,29.25]],"ltp":0.0,"tv":0.0,"id":8681938}]}]}
{"op":"mcm","clk":"4293776988","pt":1632539222574,"mc":[{"id":"1.188134680","rc":[{"batb":[[0,1.84,245.41]],"ltp":0.0,"tv":0.0,"id":9631939},{"batb":[[0,1.89,219.59]],"ltp":0.0,"tv":0.0,"id":8681938}]}]}
{"op":"mcm","clk":"4293783822","pt":1632539354347,"mc":[{"id":"1.188134680","rc":[{"batb":[[0,1.25,29.25],[1,1.23,15.9],[2,1.01,618.28]],"batl":[[1,2.2,25],[2,990,2.2]],"ltp":0.0,"tv":0.0,"id":9631939},{"batb":[[0,1.9,21.9],[1,1.25,29.25],[2,1.2,18.28]],"batl":[[0,2.2,25],[1,990,2.2],[2,990,0]],"ltp":0.0,"tv":0.0,"id":8681938}]}]}
{"op":"mcm","clk":"4293783852","pt":1632539354762,"mc":[{"id":"1.188134680","rc":[{"batb":[[0,1.48,150.89],[1,1.25,29.25],[2,1.23,15.9]],"ltp":0.0,"tv":0.0,"id":9631939}]}]}
{"op":"mcm","clk":"4293784137","pt":1632539360357,"mc":[{"id":"1.188134680","rc":[{"batb":[[0,1.5,440.68],[1,1.49,13.71],[2,1.25,29.25]],"ltp":0.0,"tv":0.0,"id":9631939},{"batb":[[0,1.68,378.25]],"ltp":0.0,"tv":0.0,"id":8681938}]}]}
{"op":"mcm","clk":"4293786831","pt":1632539410733,"mc":[{"id":"1.188134680","rc":[{"batb":[[0,1.5,148.85]],"ltp":0.0,"tv":0.0,"id":9631939},{"batb":[[0,1.58,159.62]],"ltp":0.0,"tv":0.0,"id":8681938}]}]}
{"op":"mcm","clk":"4293787877","pt":1632539430038,"mc":[{"id":"1.188134680","rc":[{"batb":[[0,1.56,442.39]],"ltp":0.0,"tv":0.0,"id":9631939},{"batb":[[0,1.61,394.9]],"ltp":0.0,"tv":0.0,"id":8681938}]}]}
{"op":"mcm","clk":"4293790662","pt":1632539481836,"mc":[{"id":"1.188134680","rc":[{"batb":[[1,1.25,29.25],[2,1.23,15.9]],"ltp":0.0,"tv":0.0,"id":9631939},{"batb":[[0,1.62,12],[1,1.61,394.9],[2,1.25,29.25]],"ltp":0.0,"tv":0.0,"id":8681938}]}]}
{"op":"mcm","clk":"4293797266","pt":1632539604694,"mc":[{"id":"1.188134680","rc":[{"batb":[[0,1.57,12],[1,1.56,442.39],[2,1.25,29.25]],"ltp":0.0,"tv":0.0,"id":9631939}]}]}
{"op":"mcm","clk":"4293799691","pt":1632539654469,"mc":[{"id":"1.188134680","rc":[{"batb":[[0,1.7,373.75],[1,1.62,12]],"ltp":0.0,"tv":0.0,"id":8681938}]}]}
{"op":"mcm","clk":"4293802114","pt":1632539710846,"mc":[{"id":"1.188134680","rc":[{"batb":[[0,1.59,415.42],[1,1.57,12]],"ltp":0.0,"tv":0.0,"id":9631939}]}]}
{"op":"mcm","clk":"4293802565","pt":1632539719683,"mc":[{"id":"1.188134680","rc":[{"batb":[[1,1.25,29.25],[2,1.23,15.9]],"ltp":0.0,"tv":0.0,"id":9631939},{"batb":[[1,1.25,29.25],[2,1.2,18.28]],"ltp":0.0,"tv":0.0,"id":8681938}]}]}
{"op":"mcm","clk":"4293805614","pt":1632539797201,"mc":[{"id":"1.188134680","rc":[{"batb":[[0,1.6,159.54]],"ltp":0.0,"tv":0.0,"id":9631939},{"batb":[[0,1.71,147.34]],"ltp":0.0,"tv":0.0,"id":8681938}]}]}
{"op":"mcm","clk":"4293805863","pt":1632539802880,"mc":[{"id":"1.188134680","rc":[{"batb":[[0,1.66,415.41]],"ltp":0.0,"tv":0.0,"id":9631939},{"batb":[[0,1.72,369.35]],"ltp":0.0,"tv":0.0,"id":8681938}]}]}
{"op":"mcm","clk":"4293811818","pt":1632539976873,"mc":[{"id":"1.188134680","rc":[{"batb":[[0,1.67,10.29],[1,1.66,415.41],[2,1.25,29.25]],"ltp":0.0,"tv":0.0,"id":9631939},{"batb":[[0,1.73,10.29],[1,1.72,369.35],[2,1.25,29.25]],"ltp":0.0,"tv":0.0,"id":8681938}]}]}
{"op":"mcm","clk":"4293815779","pt":1632540097226,"mc":[{"id":"1.188134680","rc":[{"batb":[[0,1.68,392.9],[1,1.67,10.29]],"ltp":0.0,"tv":0.0,"id":9631939}]}]}
{"op":"mcm","clk":"4293815826","pt":1632540099074,"mc":[{"id":"1.188134680","rc":[{"batb":[[1,1.25,29.25],[2,1.23,15.9]],"ltp":0.0,"tv":0.0,"id":9631939}]}]}
{"op":"mcm","clk":"4293818074","pt":1632540161784,"mc":[{"id":"1.188134680","rc":[{"batb":[[0,1.69,150.94]],"ltp":0.0,"tv":0.0,"id":9631939},{"batb":[[0,1.74,144.77],[1,1.73,10.29]],"ltp":0.0,"tv":0.0,"id":8681938}]}]}
{"op":"mcm","clk":"4293818285","pt":1632540167713,"mc":[{"id":"1.188134680","rc":[{"batb":[[0,1.71,377.4]],"ltp":0.0,"tv":0.0,"id":9631939},{"batb":[[0,1.75,362.95]],"ltp":0.0,"tv":0.0,"id":8681938}]}]}
{"op":"mcm","clk":"4293821790","pt":1632540265651,"mc":[{"id":"1.188134680","rc":[{"batb":[[1,1.25,29.25],[2,1.2,18.28]],"ltp":0.0,"tv":0.0,"id":8681938}]}]}
{"op":"mcm","clk":"4293830840","pt":1632540456361,"mc":[{"id":"1.188134680","rc":[{"batb":[[0,1.72,122.89]],"ltp":0.0,"tv":0.0,"id":9631939},{"batb":[[0,1.76,126.28]],"ltp":0.0,"tv":0.0,"id":8681938}]}]}
{"op":"mcm","clk":"4293831202","pt":1632540462359,"mc":[{"id":"1.188134680","rc":[{"batb":[[0,1.56,442.39]],"ltp":0.0,"tv":0.0,"id":9631939},{"batb":[[0,1.25,29.25],[1,1.2,18.28],[2,1.01,618.28]],"ltp":0.0,"tv":0.0,"id":8681938}]}]}
{"op":"mcm","clk":"4293831210","pt":1632540462460,"mc":[{"id":"1.188134680","rc":[{"batb":[[0,1.59,399.94],[1,1.25,29.25],[2,1.2,18.28]],"ltp":0.0,"tv":0.0,"id":8681938}]}]}
{"op":"mcm","clk":"4293832144","pt":1632540483007,"mc":[{"id":"1.188134680","rc":[{"batb":[[0,1.57,12],[1,1.56,442.39],[2,1.25,29.25]],"ltp":0.0,"tv":0.0,"id":9631939},{"batb":[[0,1.6,12.86],[1,1.59,399.94],[2,1.25,29.25]],"ltp":0.0,"tv":0.0,"id":8681938}]}]}
{"op":"mcm","clk":"4293835453","pt":1632540559314,"mc":[{"id":"1.188134680","rc":[{"batb":[[0,1.62,157.54],[1,1.57,12]],"ltp":0.0,"tv":0.0,"id":9631939},{"batb":[[0,1.64,153.71],[1,1.6,12.86]],"ltp":0.0,"tv":0.0,"id":8681938}]}]}
{"op":"mcm","clk":"4293835713","pt":1632540565042,"mc":[{"id":"1.188134680","rc":[{"batb":[[0,1.63,423.15]],"ltp":0.0,"tv":0.0,"id":9631939},{"batb":[[0,1.73,367.19]],"ltp":0.0,"tv":0.0,"id":8681938}]}]}
{"op":"mcm","clk":"4293838589","pt":1632540635927,"mc":[{"id":"1.188134680","rc":[{"batb":[[1,1.25,29.25],[2,1.23,15.9]],"ltp":0.0,"tv":0.0,"id":9631939},{"batb":[[1,1.25,29.25],[2,1.2,18.28]],"ltp":0.0,"tv":0.0,"id":8681938}]}]}
{"op":"mcm","clk":"4293838809","pt":1632540641219,"mc":[{"id":"1.188134680","rc":[{"batb":[[0,1.65,154.64]],"ltp":0.0,"tv":0.0,"id":9631939},{"batb":[[0,1.74,144.77]],"ltp":0.0,"tv":0.0,"id":8681938}]}]}
{"op":"mcm","clk":"4293839056","pt":1632540647347,"mc":[{"id":"1.188134680","rc":[{"batb":[[0,1.25,29.25],[1,1.23,15.9],[2,1.01,618.28]],"ltp":0.0,"tv":0.0,"id":9631939},{"batb":[[0,1.25,29.25],[1,1.2,18.28],[2,1.01,618.28]],"ltp":0.0,"tv":0.0,"id":8681938}]}]}
{"op":"mcm","clk":"4293839058","pt":1632540647450,"mc":[{"id":"1.188134680","rc":[{"batb":[[0,1.66,415.41],[1,1.25,29.25],[2,1.23,15.9]],"ltp":0.0,"tv":0.0,"id":9631939},{"batb":[[0,1.75,362.95],[1,1.25,29.25],[2,1.2,18.28]],"ltp":0.0,"tv":0.0,"id":8681938}]}]}
{"op":"mcm","clk":"4293843809","pt":1632540777325,"mc":[{"id":"1.188134680","rc":[{"batb":[[0,1.67,152.77]],"ltp":0.0,"tv":0.0,"id":9631939},{"batb":[[0,1.48,170.55]],"ltp":0.0,"tv":0.0,"id":8681938}]}]}
{"op":"mcm","clk":"4293844051","pt":1632540783347,"mc":[{"id":"1.188134680","rc":[{"batb":[[0,1.25,29.25],[1,1.23,15.9],[2,1.01,618.28]],"ltp":0.0,"tv":0.0,"id":9631939},{"batb":[[0,1.25,29.25],[1,1.2,18.28],[2,1.01,618.28]],"ltp":0.0,"tv":0.0,"id":8681938}]}]}
{"op":"mcm","clk":"4293844059","pt":1632540783550,"mc":[{"id":"1.188134680","rc":[{"batb":[[0,1.56,442.39],[1,1.25,29.25],[2,1.23,15.9]],"ltp":0.0,"tv":0.0,"id":9631939},{"batb":[[0,1.62,428.41],[1,1.25,29.25],[2,1.2,18.28]],"ltp":0.0,"tv":0.0,"id":8681938}]}]}
{"op":"mcm","clk":"4293845669","pt":1632540799891,"mc":[{"id":"1.188134680","rc":[{"batb":[[0,1.57,12],[1,1.56,442.39],[2,1.25,29.25]],"ltp":0.0,"tv":0.0,"id":9631939},{"batb":[[0,1.63,12],[1,1.62,428.41],[2,1.25,29.25]],"ltp":0.0,"tv":0.0,"id":8681938}]}]}
{"op":"mcm","clk":"4293857174","pt":1632541056286,"mc":[{"id":"1.188134680","rc":[{"batb":[[0,1.66,382.86],[1,1.63,12]],"ltp":0.0,"tv":0.0,"id":8681938}]}]}
{"op":"mcm","clk":"4293858166","pt":1632541077925,"mc":[{"id":"1.188134680","rc":[{"batb":[[0,1.64,402.6],[1,1.57,12]],"ltp":0.0,"tv":0.0,"id":9631939}]}]}
{"op":"mcm","clk":"4293858301","pt":1632541081128,"mc":[{"id":"1.188134680","rc":[{"batb":[[0,1.57,12],[1,1.25,29.25],[2,1.23,15.9]],"ltp":0.0,"tv":0.0,"id":9631939},{"batb":[[0,1.63,12],[1,1.25,29.25],[2,1.2,18.28]],"ltp":0.0,"tv":0.0,"id":8681938}]}]}
{"op":"mcm","clk":"4293858322","pt":1632541081439,"mc":[{"id":"1.188134680","rc":[{"batb":[[0,1.65,154.64],[1,1.57,12],[2,1.25,29.25]],"ltp":0.0,"tv":0.0,"id":9631939},{"batb":[[0,1.69,149.1],[1,1.63,12],[2,1.25,29.25]],"ltp":0.0,"tv":0.0,"id":8681938}]}]}
{"op":"mcm","clk":"4293858600","pt":1632541087212,"mc":[{"id":"1.188134680","rc":[{"batb":[[0,1.57,12],[1,1.25,29.25],[2,1.23,15.9]],"ltp":0.0,"tv":0.0,"id":9631939},{"batb":[[0,1.63,12],[1,1.25,29.25],[2,1.2,18.28]],"ltp":0.0,"tv":0.0,"id":8681938}]}]}
{"op":"mcm","clk":"4293858606","pt":1632541087418,"mc":[{"id":"1.188134680","rc":[{"batb":[[0,1.66,415.41],[1,1.57,12],[2,1.25,29.25]],"ltp":0.0,"tv":0.0,"id":9631939},{"batb":[[0,1.71,371.54],[1,1.63,12],[2,1.25,29.25]],"ltp":0.0,"tv":0.0,"id":8681938}]}]}
{"op":"mcm","clk":"4293859551","pt":1632541113237,"mc":[{"id":"1.188134680","rc":[{"batb":[[1,1.25,29.25],[2,1.2,18.28]],"ltp":0.0,"tv":0.0,"id":8681938}]}]}
{"op":"mcm","clk":"4293859559","pt":1632541113443,"mc":[{"id":"1.188134680","rc":[{"batb":[[1,1.25,29.25],[2,1.23,15.9]],"ltp":0.0,"tv":0.0,"id":9631939}]}]}
{"op":"mcm","clk":"4293865469","pt":1632541246954,"mc":[{"id":"1.188134680","rc":[{"batb":[[0,1.67,152.77]],"ltp":0.0,"tv":0.0,"id":9631939},{"batb":[[0,1.72,146.47]],"ltp":0.0,"tv":0.0,"id":8681938}]}]}
{"op":"mcm","clk":"4293865791","pt":1632541252767,"mc":[{"id":"1.188134680","rc":[{"batb":[[0,1.68,410.41]],"ltp":0.0,"tv":0.0,"id":9631939},{"batb":[[0,1.73,367.19]],"ltp":0.0,"tv":0.0,"id":8681938}]}]}
{"op":"mcm","clk":"4293865852","pt":1632541254169,"mc":[{"id":"1.188134680","rc":[{"batb":[[0,1.74,10.29],[1,1.73,367.19],[2,1.25,29.25]],"ltp":0.0,"tv":0.0,"id":8681938}]}]}
{"op":"mcm","clk":"4293870581","pt":1632541356383,"mc":[{"id":"1.188134680","rc":[{"batb":[[0,1.75,362.95],[1,1.74,10.29]],"ltp":0.0,"tv":0.0,"id":8681938}]}]}
{"op":"mcm","clk":"4293872352","pt":1632541395341,"mc":[{"id":"1.188134680","rc":[{"batb":[[1,1.25,29.25],[2,1.2,18.28]],"ltp":0.0,"tv":0.0,"id":8681938}]}]}
{"op":"mcm","clk":"4293885143","pt":1632541646838,"mc":[{"id":"1.188134680","rc":[{"batb":[[0,1.48,172.65]],"ltp":0.0,"tv":0.0,"id":9631939},{"batb":[[0,1.76,167.83]],"ltp":0.0,"tv":0.0,"id":8681938}]}]}
{"op":"mcm","clk":"4293885501","pt":1632541652867,"mc":[{"id":"1.188134680","rc":[{"batb":[[0,1.57,439.53]],"ltp":0.0,"tv":0.0,"id":9631939},{"batb":[[0,1.25,29.25],[1,1.2,18.28],[2,1.01,618.28]],"ltp":0.0,"tv":0.0,"id":8681938}]}]}
{"op":"mcm","clk":"4293886291","pt":1632541668068,"mc":[{"id":"1.188134680","rc":[{"batb":[[0,1.58,12],[1,1.57,439.53],[2,1.25,29.25]],"ltp":0.0,"tv":0.0,"id":9631939},{"batb":[[0,1.62,418.98],[1,1.26,15.43],[2,1.25,29.25]],"ltp":0.0,"tv":0.0,"id":8681938}]}]}
{"op":"mcm","clk":"4293892251","pt":1632541793107,"mc":[{"id":"1.188134680","rc":[{"batb":[[0,1.59,160.55],[1,1.58,12]],"ltp":0.0,"tv":0.0,"id":9631939},{"batb":[[0,1.49,198.66]],"ltp":0.0,"tv":0.0,"id":8681938}]}]}
{"op":"mcm","clk":"4293892536","pt":1632541798715,"mc":[{"id":"1.188134680","rc":[{"batb":[[0,1.62,425.8]],"ltp":0.0,"tv":0.0,"id":9631939},{"batb":[[0,1.6,424.28]],"ltp":0.0,"tv":0.0,"id":8681938}]}]}
{"op":"mcm","clk":"4293897923","pt":1632541931143,"mc":[{"id":"1.188134680","rc":[{"batb":[[1,1.25,29.25],[2,1.23,15.9]],"ltp":0.0,"tv":0.0,"id":9631939},{"batb":[[1,1.25,29.25],[2,1.2,18.28]],"ltp":0.0,"tv":0.0,"id":8681938}]}]}
{"op":"mcm","clk":"4293900514","pt":1632541999640,"mc":[{"id":"1.188134680","rc":[{"batb":[[0,1.65,154.64]],"ltp":0.0,"tv":0.0,"id":9631939},{"batb":[[0,1.52,194.69]],"ltp":0.0,"tv":0.0,"id":8681938}]}]}
{"op":"mcm","clk":"4293900788","pt":1632542005756,"mc":[{"id":"1.188134680","rc":[{"batb":[[0,1.66,415.41]],"ltp":0.0,"tv":0.0,"id":9631939},{"batb":[[0,1.55,438.15]],"ltp":0.0,"tv":0.0,"id":8681938}]}]}
{"op":"mcm","clk":"4293903052","pt":1632542069626,"mc":[{"id":"1.188134680","rc":[{"batb":[[0,1.67,10.29],[1,1.66,415.41],[2,1.25,29.25]],"ltp":0.0,"tv":0.0,"id":9631939},{"batb":[[0,1.56,13.71],[1,1.55,438.15],[2,1.25,29.25]],"ltp":0.0,"tv":0.0,"id":8681938}]}]}
{"op":"mcm","clk":"4293910333","pt":1632542268267,"mc":[{"id":"1.188134680","rc":[{"batb":[[0,1.64,413.81],[1,1.56,13.71]],"ltp":0.0,"tv":0.0,"id":8681938}]}]}
{"op":"mcm","clk":"4293910883","pt":1632542279118,"mc":[{"id":"1.188134680","rc":[{"batb":[[0,1.68,151.85],[1,1.67,10.29]],"ltp":0.0,"tv":0.0,"id":9631939},{"batb":[[0,1.73,170.78]],"ltp":0.0,"tv":0.0,"id":8681938}]}]}
{"op":"mcm","clk":"4293911140","pt":1632542285294,"mc":[{"id":"1.188134680","rc":[{"batb":[[0,1.67,10.29],[1,1.25,29.25],[2,1.23,15.9]],"ltp":0.0,"tv":0.0,"id":9631939},{"batb":[[0,1.56,13.71],[1,1.25,29.25],[2,1.2,18.28]],"ltp":0.0,"tv":0.0,"id":8681938}]}]}
{"op":"mcm","clk":"4293911147","pt":1632542285502,"mc":[{"id":"1.188134680","rc":[{"batb":[[0,1.61,440.29],[1,1.56,13.71],[2,1.25,29.25]],"ltp":0.0,"tv":0.0,"id":8681938}]}]}
{"op":"mcm","clk":"4293912751","pt":1632542330364,"mc":[{"id":"1.188134680","rc":[{"batb":[[1,1.25,29.25],[2,1.2,18.28]],"ltp":0.0,"tv":0.0,"id":8681938}]}]}
{"op":"mcm","clk":"4293919177","pt":1632542401289,"mc":[{"id":"1.188134680","rc":[{"batb":[[0,1.25,29.25],[1,1.2,18.28],[2,1.01,618.28]],"ltp":0.0,"tv":0.0,"id":8681938}]}]}
{"op":"mcm","clk":"4293919205","pt":1632542401600,"mc":[{"id":"1.188134680","rc":[{"batb":[[0,1.68,151.85],[1,1.67,10.29],[2,1.25,29.25]],"ltp":0.0,"tv":0.0,"id":9631939},{"batb":[[0,1.62,182.52],[1,1.25,29.25],[2,1.2,18.28]],"ltp":0.0,"tv":0.0,"id":8681938}]}]}
{"op":"mcm","clk":"4293919762","pt":1632542407605,"mc":[{"id":"1.188134680","rc":[{"batb":[[0,1.69,407.95]],"ltp":0.0,"tv":0.0,"id":9631939},{"batb":[[0,1.65,411.27]],"ltp":0.0,"tv":0.0,"id":8681938}]}]}
{"op":"mcm","clk":"4293923639","pt":1632542466183,"mc":[{"id":"1.188134680","rc":[{"batb":[[1,1.25,29.25],[2,1.23,15.9]],"ltp":0.0,"tv":0.0,"id":9631939},{"batb":[[0,1.66,12],[1,1.65,411.27],[2,1.25,29.25]],"ltp":0.0,"tv":0.0,"id":8681938}]}]}
{"op":"mcm","clk":"4293930368","pt":1632542568200,"mc":[{"id":"1.188134680","rc":[{"batb":[[0,1.67,406.16],[1,1.66,12]],"ltp":0.0,"tv":0.0,"id":8681938}]}]}
{"op":"mcm","clk":"4293932257","pt":1632542601710,"mc":[{"id":"1.188134680","rc":[{"batb":[[1,1.25,29.25],[2,1.2,18.28]],"ltp":0.0,"tv":0.0,"id":8681938}]}]}
{"op":"mcm","clk":"4293940304","pt":1632542737002,"mc":[{"id":"1.188134680","rc":[{"batb":[[0,1.68,11.14],[1,1.67,406.16],[2,1.25,29.25]],"ltp":0.0,"tv":0.0,"id":8681938}]}]}
{"op":"mcm","clk":"4293943768","pt":1632542800086,"mc":[{"id":"1.188134680","rc":[{"batb":[[0,1.25,29.25],[1,1.23,15.9],[2,1.01,618.28]],"ltp":0.0,"tv":0.0,"id":9631939},{"batb":[[1,1.25,29.25],[2,1.2,18.28]],"ltp":0.0,"tv":0.0,"id":8681938}]}]}
{"op":"mcm","clk":"4293943790","pt":1632542800398,"mc":[{"id":"1.188134680","rc":[{"batb":[[0,1.49,171.48],[1,1.25,29.25],[2,1.23,15.9]],"ltp":0.0,"tv":0.0,"id":9631939},{"batb":[[0,1.72,171.78],[1,1.68,11.14],[2,1.25,29.25]],"ltp":0.0,"tv":0.0,"id":8681938}]}]}
{"op":"mcm","clk":"4293944151","pt":1632542806637,"mc":[{"id":"1.188134680","rc":[{"batb":[[0,1.5,460.32]],"ltp":0.0,"tv":0.0,"id":9631939},{"batb":[[0,1.74,389.75]],"ltp":0.0,"tv":0.0,"id":8681938}]}]}
{"op":"mcm","clk":"4293947338","pt":1632542881024,"mc":[{"id":"1.188134680","rc":[{"batb":[[0,1.51,12.86],[1,1.5,460.32],[2,1.25,29.25]],"ltp":0.0,"tv":0.0,"id":9631939},{"batb":[[1,1.25,29.25],[2,1.2,18.28]],"ltp":0.0,"tv":0.0,"id":8681938}]}]}
{"op":"mcm","clk":"4293951903","pt":1632543001860,"mc":[{"id":"1.188134680","rc":[{"batb":[[0,1.53,431.93],[1,1.51,12.86]],"ltp":0.0,"tv":0.0,"id":9631939}]}]}
{"op":"mcm","clk":"4293953416","pt":1632543039393,"mc":[{"id":"1.188134680","rc":[{"batb":[[1,1.25,29.25],[2,1.23,15.9]],"ltp":0.0,"tv":0.0,"id":9631939}]}]}
{"op":"mcm","clk":"4293963612","pt":1632543259020,"mc":[{"id":"1.188134680","rc":[{"batb":[[0,1.54,12.86],[1,1.53,431.93],[2,1.25,29.25]],"ltp":0.0,"tv":0.0,"id":9631939}]}]}
{"op":"mcm","clk":"4293965487","pt":1632543301762,"mc":[{"id":"1.188134680","rc":[{"batb":[[0,1.58,418.08],[1,1.54,12.86]],"ltp":0.0,"tv":0.0,"id":9631939}]}]}
{"op":"mcm","clk":"4293970154","pt":1632543401721,"mc":[{"id":"1.188134680","rc":[{"batb":[[1,1.25,29.25],[2,1.23,15.9]],"ltp":0.0,"tv":0.0,"id":9631939}]}]}
{"op":"mcm","clk":"4293991781","pt":1632543532524,"mc":[{"id":"1.188134680","rc":[{"batb":[[0,1.59,12],[1,1.58,418.08],[2,1.25,29.25]],"ltp":0.0,"tv":0.0,"id":9631939}]}]}
{"op":"mcm","clk":"4293996032","pt":1632543601633,"mc":[{"id":"1.188134680","rc":[{"batb":[[0,1.61,410.2],[1,1.59,12]],"ltp":0.0,"tv":0.0,"id":9631939}]}]}
{"op":"mcm","clk":"4294000748","pt":1632543681593,"mc":[{"id":"1.188134680","rc":[{"batb":[[1,1.25,29.25],[2,1.23,15.9]],"ltp":0.0,"tv":0.0,"id":9631939}]}]}
{"op":"mcm","clk":"4294002652","pt":1632543715325,"mc":[{"id":"1.188134680","rc":[{"batl":[[0,2.18,37.92]],"ltp":0.0,"tv":0.0,"id":9631939}]}]}
{"op":"mcm","clk":"4294015084","pt":1632543943439,"mc":[{"id":"1.188134680","rc":[{"batb":[[0,1.62,11.14],[1,1.61,410.2],[2,1.25,29.25]],"ltp":0.0,"tv":0.0,"id":9631939}]}]}
{"op":"mcm","clk":"4294025408","pt":1632544201830,"mc":[{"id":"1.188134680","rc":[{"batb":[[0,1.65,400.13],[1,1.62,11.14]],"ltp":0.0,"tv":0.0,"id":9631939}]}]}
{"op":"mcm","clk":"4294027393","pt":1632544243841,"mc":[{"id":"1.188134680","rc":[{"batb":[[1,1.25,29.25],[2,1.23,15.9]],"ltp":0.0,"tv":0.0,"id":9631939}]}]}
{"op":"mcm","clk":"4294033732","pt":1632544386740,"mc":[{"id":"1.188134680","rc":[{"batb":[[0,1.66,10.29],[1,1.65,400.13],[2,1.25,29.25]],"ltp":0.0,"tv":0.0,"id":9631939}]}]}
{"op":"mcm","clk":"4294039134","pt":1632544501798,"mc":[{"id":"1.188134680","rc":[{"batb":[[0,1.67,395.28],[1,1.66,10.29]],"ltp":0.0,"tv":0.0,"id":9631939}]}]}
{"op":"mcm","clk":"4294041085","pt":1632544540979,"mc":[{"id":"1.188134680","rc":[{"batb":[[1,1.25,29.25],[2,1.23,15.9]],"ltp":0.0,"tv":0.0,"id":9631939}]}]}
{"op":"mcm","clk":"4294073110","pt":1632545257882,"mc":[{"id":"1.188134680","rc":[{"batb":[[0,1.58,396.45]],"batl":[[0,2.2,43.31]],"ltp":0.0,"tv":0.0,"id":8681938}]}]}
{"op":"mcm","clk":"4294079010","pt":1632545396523,"mc":[{"id":"1.188134680","rc":[{"batb":[[0,1.59,12.86],[1,1.58,396.45],[2,1.25,29.25]],"ltp":0.0,"tv":0.0,"id":8681938}]}]}
{"op":"mcm","clk":"4294081805","pt":1632545464610,"mc":[{"id":"1.188134680","rc":[{"batb":[[0,1.62,386.6],[1,1.59,12.86]],"ltp":0.0,"tv":0.0,"id":8681938}]}]}
{"op":"mcm","clk":"4294084733","pt":1632545531455,"mc":[{"id":"1.188134680","rc":[{"batb":[[1,1.25,29.25],[2,1.2,18.28]],"ltp":0.0,"tv":0.0,"id":8681938}]}]}
{"op":"mcm","clk":"4294085629","pt":1632545551733,"mc":[{"id":"1.188134680","rc":[{"batb":[[0,1.84,239.1]],"ltp":0.0,"tv":0.0,"id":9631939}]}]}
{"op":"mcm","clk":"4294090892","pt":1632545669546,"mc":[{"id":"1.188134680","rc":[{"batb":[[0,1.63,12],[1,1.62,386.6],[2,1.25,29.25]],"ltp":0.0,"tv":0.0,"id":8681938}]}]}
{"op":"mcm","clk":"4294100403","pt":1632545868295,"mc":[{"id":"1.188134680","rc":[{"batb":[[0,1.65,305.56],[1,1.63,12]],"ltp":0.0,"tv":0.0,"id":8681938}]}]}
{"op":"mcm","clk":"4294110626","pt":1632546056841,"mc":[{"id":"1.188134680","rc":[{"batb":[[1,1.25,29.25],[2,1.2,18.28]],"ltp":0.0,"tv":0.0,"id":8681938}]}]}
{"op":"mcm","clk":"4294117626","pt":1632546208728,"mc":[{"id":"1.188134680","rc":[{"batb":[[0,1.66,12],[1,1.65,305.56],[2,1.25,29.25]],"ltp":0.0,"tv":0.0,"id":8681938}]}]}
{"op":"mcm","clk":"4294126578","pt":1632546387357,"mc":[{"id":"1.188134680","rc":[{"batb":[[1,1.25,29.25],[2,1.2,18.28]],"batl":[[0,1.99,6.12],[1,2.2,25],[2,990,2.2]],"ltp":0.0,"tv":0.0,"id":8681938}]}]}
{"op":"mcm","clk":"4294126591","pt":1632546387566,"mc":[{"id":"1.188134680","rc":[{"batb":[[0,1.74,289.66],[1,1.66,12],[2,1.25,29.25]],"ltp":0.0,"tv":0.0,"id":8681938}]}]}
{"op":"mcm","clk":"4294128629","pt":1632546422343,"mc":[{"id":"1.188134680","rc":[{"batb":[[1,1.25,29.25],[2,1.2,18.28]],"ltp":0.0,"tv":0.0,"id":8681938}]}]}
{"op":"mcm","clk":"4294131998","pt":1632546484211,"mc":[{"id":"1.188134680","rc":[{"trd":[[1.99,12.24]],"batl":[[0,2.2,43.31],[1,990,2.2],[2,990,0]],"ltp":1.99,"tv":12.23,"id":8681938}],"tv":12.23}]}
{"op":"mcm","clk":"4294132050","pt":1632546484939,"mc":[{"id":"1.188134680","rc":[{"batl":[[0,2.18,38.27]],"ltp":0.0,"tv":0.0,"id":9631939},{"batb":[[0,1.75,286.84]],"batl":[[0,2.18,19.66],[1,2.2,25],[2,990,2.2]],"ltp":1.99,"tv":12.23,"id":8681938}]}]}
{"op":"mcm","clk":"4294133269","pt":1632546505954,"mc":[{"id":"1.188134680","rc":[{"batb":[[0,1.85,42.86],[1,1.75,286.84],[2,1.25,29.25]],"ltp":1.99,"tv":12.23,"id":8681938}]}]}
{"op":"mcm","clk":"4294147826","pt":1632546768306,"mc":[{"id":"1.188134680","rc":[{"batb":[[0,1.86,244.55],[1,1.85,42.86]],"ltp":1.99,"tv":12.23,"id":8681938}]}]}
{"op":"mcm","clk":"4294147859","pt":1632546768872,"mc":[{"id":"1.188134680","rc":[{"batb":[[1,1.25,29.25],[2,1.2,18.28]],"ltp":1.99,"tv":12.23,"id":8681938}]}]}
{"op":"mcm","clk":"4294163479","pt":1632547097113,"mc":[{"id":"1.188134680","rc":[{"batb":[[0,1.85,22.42]],"ltp":0.0,"tv":0.0,"id":9631939},{"batb":[[0,1.65,108.55]],"ltp":1.99,"tv":12.23,"id":8681938}]}]}
{"op":"mcm","clk":"4294163811","pt":1632547103031,"mc":[{"id":"1.188134680","rc":[{"batb":[[0,1.85,236.99]],"ltp":0.0,"tv":0.0,"id":9631939},{"batb":[[0,1.69,314.55]],"ltp":1.99,"tv":12.23,"id":8681938}]}]}
{"op":"mcm","clk":"4294163839","pt":1632547103603,"mc":[{"id":"1.188134680","rc":[{"batb":[[0,1.85,42.86],[1,1.69,314.55],[2,1.25,29.25]],"ltp":1.99,"tv":12.23,"id":8681938}]}]}
{"op":"mcm","clk":"4294175009","pt":1632547337332,"mc":[{"id":"1.188134680","rc":[{"batb":[[1,1.25,29.25],[2,1.2,18.28]],"ltp":1.99,"tv":12.23,"id":8681938}]}]}
{"op":"mcm","clk":"4294175052","pt":1632547338259,"mc":[{"id":"1.188134680","rc":[{"batb":[[0,1.87,220.99]],"ltp":1.99,"tv":12.23,"id":8681938}]}]}
{"op":"mcm","clk":"4294281135","pt":1632548890103,"mc":[{"id":"1.188134680","rc":[{"batb":[[0,1.86,3],[1,1.85,241.99],[2,1.25,29.25]],"batl":[[0,2.14,4],[1,2.18,38.27],[2,2.2,25]],"ltp":0.0,"tv":0.0,"id":9631939},{"batb":[[0,1.88,4],[1,1.87,225.99],[2,1.25,29.25]],"batl":[[0,2.16,4],[1,2.18,19.66],[2,2.2,25]],"ltp":1.99,"tv":12.23,"id":8681938}]}]}
{"op":"mcm","clk":"4294284313","pt":1632548948153,"mc":[{"id":"1.188134680","rc":[{"batb":[[0,1.87,228.02],[1,1.86,3]],"batl":[[0,2.12,18.68],[1,2.14,4]],"ltp":0.0,"tv":0.0,"id":9631939},{"batb":[[0,1.89,224.87],[1,1.88,4]],"batl":[[1,2.2,25],[2,990,2.2]],"ltp":1.99,"tv":12.23,"id":8681938}]}]}
{"op":"mcm","clk":"4294289241","pt":1632549035194,"mc":[{"id":"1.188134680","rc":[{"batb":[[0,1.88,4],[1,1.25,29.25],[2,1.2,18.28]],"ltp":1.99,"tv":12.23,"id":8681938}]}]}
{"op":"mcm","clk":"4294296675","pt":1632549188797,"mc":[{"id":"1.188134680","rc":[{"batb":[[0,1.89,224.87],[1,1.88,4],[2,1.25,29.25]],"ltp":1.99,"tv":12.23,"id":8681938}]}]}
{"op":"mcm","clk":"4294312039","pt":1632549542181,"mc":[{"id":"1.188134680","rc":[{"batb":[[0,1.86,3],[1,1.25,29.25],[2,1.23,15.9]],"ltp":0.0,"tv":0.0,"id":9631939}]}]}
{"op":"mcm","clk":"4294312057","pt":1632549542593,"mc":[{"id":"1.188134680","rc":[{"batb":[[0,1.87,228.02],[1,1.86,3],[2,1.25,29.25]],"ltp":0.0,"tv":0.0,"id":9631939}]}]}
{"op":"mcm","clk":"4294320038","pt":1632549685222,"mc":[{"id":"1.188134680","rc":[{"batb":[[0,1.89,3],[1,1.88,10.95],[2,1.87,228.02]],"ltp":0.0,"tv":0.0,"id":9631939},{"batb":[[0,1.9,5],[1,1.89,228.87],[2,1.88,4]],"batl":[[0,2.12,3],[1,2.16,4],[2,2.2,25]],"ltp":1.99,"tv":12.23,"id":8681938}]}]}
{"op":"mcm","clk":"4294322469","pt":1632549724304,"mc":[{"id":"1.188134680","rc":[{"batb":[[0,1.91,199.09],[1,1.89,3],[2,1.88,6.95]],"ltp":0.0,"tv":0.0,"id":9631939},{"batb":[[0,1.91,21.55],[1,1.9,5],[2,1.25,29.25]],"batl":[[1,2.2,25],[2,990,2.2]],"ltp":1.99,"tv":12.23,"id":8681938}]}]}
{"op":"mcm","clk":"4294329871","pt":1632549854704,"mc":[{"id":"1.188134680","rc":[{"batb":[[2,1.36,21.76]],"ltp":1.99,"tv":12.23,"id":8681938}]}]}
{"op":"mcm","clk":"4294331688","pt":1632549884523,"mc":[{"id":"1.188134680","rc":[{"batb":[[2,1.36,21.76]],"ltp":0.0,"tv":0.0,"id":9631939}]}]}
{"op":"mcm","clk":"4294353852","pt":1632550189632,"mc":[{"id":"1.188134680","rc":[{"batl":[[2,46,29]],"ltp":1.99,"tv":12.23,"id":8681938}]}]}
{"op":"mcm","clk":"4294513005","pt":1632552347762,"mc":[{"id":"1.188134680","rc":[{"batb":[[0,1.89,3],[1,1.36,21.76],[2,1.25,29.25]],"ltp":0.0,"tv":0.0,"id":9631939}]}]}
{"op":"mcm","clk":"4294513501","pt":1632552353956,"mc":[{"id":"1.188134680","rc":[{"batb":[[0,1.91,199.09],[1,1.89,3],[2,1.36,21.76]],"ltp":0.0,"tv":0.0,"id":9631939}]}]}
{"op":"mcm","clk":"4294570471","pt":1632553214363,"mc":[{"id":"1.188134680","rc":[{"batb":[[0,1.9,5],[1,1.36,21.76],[2,1.25,29.25]],"ltp":1.99,"tv":12.23,"id":8681938}]}]}
{"op":"mcm","clk":"4294570556","pt":1632553215363,"mc":[{"id":"1.188134680","rc":[{"batb":[[0,1.96,6.37],[1,1.91,199.09]],"batl":[[0,2.2,25],[1,46,29],[2,990,2.2]],"ltp":0.0,"tv":0.0,"id":9631939},{"batb":[[0,1.69,418.65]],"batl":[[0,2.2,43.79],[1,46,29],[2,990,2.2]],"ltp":1.99,"tv":12.23,"id":8681938}]}]}
{"op":"mcm","clk":"4294570568","pt":1632553215573,"mc":[{"id":"1.188134680","rc":[{"batb":[[1,1.36,21.76],[2,1.25,29.25]],"batl":[[0,2.2,44.19]],"ltp":0.0,"tv":0.0,"id":9631939}]}]}
{"op":"mcm","clk":"4294584187","pt":1632553369041,"mc":[{"id":"1.188134680","rc":[{"batb":[[0,2,26.36],[1,1.96,6.37],[2,1.36,21.76]],"ltp":0.0,"tv":0.0,"id":9631939}]}]}
{"op":"mcm","clk":"4294614664","pt":1632553690251,"mc":[{"id":"1.188134680","rc":[{"batb":[[1,1.36,21.76],[2,1.25,29.25]],"ltp":0.0,"tv":0.0,"id":9631939}]}]}
{"op":"mcm","clk":"4294855401","pt":1632555970309,"mc":[{"id":"1.188134680","rc":[{"batb":[[1,1.9,4],[2,1.89,4]],"batl":[[0,2.18,3],[1,2.2,44.19],[2,46,29]],"ltp":0.0,"tv":0.0,"id":9631939},{"batb":[[0,1.84,4],[1,1.83,5],[2,1.36,21.76]],"ltp":1.99,"tv":12.23,"id":8681938}]}]}
{"op":"mcm","clk":"4294855423","pt":1632555970515,"mc":[{"id":"1.188134680","rc":[{"batb":[[1,1.36,21.76],[2,1.25,29.25]],"batl":[[0,2.2,44.19],[1,46,29],[2,990,2.2]],"ltp":0.0,"tv":0.0,"id":9631939},{"batb":[[0,1.84,23.51],[1,1.36,21.76],[2,1.25,29.25]],"ltp":1.99,"tv":12.23,"id":8681938}]}]}
{"op":"mcm","clk":"4294855934","pt":1632555975242,"mc":[{"id":"1.188134680","rc":[{"batb":[[0,1.85,229.97]],"ltp":1.99,"tv":12.23,"id":8681938}]}]}
{"op":"mcm","clk":"4294890436","pt":1632556235176,"mc":[{"id":"1.188134680","rc":[{"batb":[[1,1.83,38.53],[2,1.36,21.76]],"ltp":0.0,"tv":0.0,"id":9631939},{"batb":[[1,1.83,38.53],[2,1.36,21.76]],"ltp":1.99,"tv":12.23,"id":8681938}]}]}
{"op":"mcm","clk":"4294890713","pt":1632556235867,"mc":[{"id":"1.188134680","rc":[{"batl":[[0,2.18,143.95],[1,2.2,25],[2,46,29]],"ltp":1.99,"tv":12.23,"id":8681938}]}]}
{"op":"mcm","clk":"4294900662","pt":1632556296419,"mc":[{"id":"1.188134680","rc":[{"batl":[[2,2.62,2.65]],"ltp":1.99,"tv":12.23,"id":8681938}]}]}
{"op":"mcm","clk":"4294903115","pt":1632556316365,"mc":[{"id":"1.188134680","rc":[{"batb":[[2,1.38,6.64]],"ltp":1.99,"tv":12.23,"id":8681938}]}]}
{"op":"mcm","clk":"4294965916","pt":1632556890238,"mc":[{"id":"1.188134680","rc":[{"batb":[[0,2.02,4.79],[1,2,26.36],[2,1.83,38.53]],"ltp":0.0,"tv":0.0,"id":9631939},{"batb":[[0,1.86,16.29],[1,1.85,229.97],[2,1.83,38.53]],"ltp":1.99,"tv":12.23,"id":8681938}]}]}
{"op":"mcm","clk":"4294965941","pt":1632556890448,"mc":[{"id":"1.188134680","rc":[{"batl":[[0,2.16,4],[1,2.2,44.19],[2,46,29]],"ltp":0.0,"tv":0.0,"id":9631939},{"batb":[[0,1.87,4],[1,1.86,21.29],[2,1.85,229.97]],"ltp":1.99,"tv":12.23,"id":8681938}]}]}
{"op":"mcm","clk":"4294968508","pt":1632556909349,"mc":[{"id":"1.188134680","rc":[{"batl":[[1,2.2,25]],"ltp":0.0,"tv":0.0,"id":9631939},{"batb":[[0,1.89,304.35],[1,1.87,4],[2,1.86,16.29]],"ltp":1.99,"tv":12.23,"id":8681938}]}]}
{"op":"mcm","clk":"4295040576","pt":1632557520248,"mc":[{"id":"1.188134680","rc":[{"batb":[[0,1.87,4],[1,1.86,16.29],[2,1.83,38.53]],"ltp":1.99,"tv":12.23,"id":8681938}]}]}
{"op":"mcm","clk":"4295040611","pt":1632557520558,"mc":[{"id":"1.188134680","rc":[{"batb":[[0,1.9,302.47],[1,1.87,4],[2,1.86,16.29]],"ltp":1.99,"tv":12.23,"id":8681938}]}]}
{"op":"mcm","clk":"4295114713","pt":1632558190751,"mc":[{"id":"1.188134680","rc":[{"batb":[[2,1.83,38.53]],"ltp":1.99,"tv":12.23,"id":8681938}]}]}
{"op":"mcm","clk":"4295184145","pt":1632558722079,"mc":[{"id":"1.188134680","rc":[{"batb":[[0,1.88,305.98]],"ltp":1.99,"tv":12.23,"id":8681938}]}]}
{"op":"mcm","clk":"4295423447","pt":1632560399044,"mc":[{"id":"1.188134680","rc":[{"batl":[[0,2.18,147.52]],"ltp":1.99,"tv":12.23,"id":8681938}]}]}
{"op":"mcm","clk":"4295424638","pt":1632560407245,"mc":[{"id":"1.188134680","rc":[{"batl":[[0,2.14,82.81],[1,2.16,2.52],[2,2.2,25]],"ltp":1.99,"tv":12.23,"id":8681938}]}]}
{"op":"mcm","clk":"4295424679","pt":1632560407518,"mc":[{"id":"1.188134680","rc":[{"batl":[[2,2.42,2.06]],"ltp":0.0,"tv":0.0,"id":9631939}]}]}
{"op":"mcm","clk":"4295440970","pt":1632560535080,"mc":[{"id":"1.188134680","rc":[{"batb":[[0,1.9,398.35]],"ltp":1.99,"tv":12.23,"id":8681938}]}]}
{"op":"mcm","clk":"4295443053","pt":1632560549710,"mc":[{"id":"1.188134680","rc":[{"trd":[[2.12,7.96]],"ltp":2.12,"tv":7.96,"id":9631939},{"trd":[[1.9,8.89]],"batb":[[0,1.9,389.46]],"ltp":1.9,"tv":21.12,"id":8681938}],"tv":29.09}]}
{"op":"mcm","clk":"4295443247","pt":1632560550971,"mc":[{"id":"1.188134680","rc":[{"batb":[[0,1.87,4],[1,1.83,38.53],[2,1.38,6.64]],"ltp":1.9,"tv":21.12,"id":8681938}]}]}
{"op":"mcm","clk":"4295461786","pt":1632560684679,"mc":[{"id":"1.188134680","rc":[{"batb":[[2,1.42,97.54]],"ltp":1.9,"tv":21.12,"id":8681938}]}]}
{"op":"mcm","clk":"4295609021","pt":1632561702028,"mc":[{"id":"1.188134680","rc":[{"batb":[[2,1.44,17.99]],"ltp":1.9,"tv":21.12,"id":8681938}]}]}
{"op":"mcm","clk":"4295729415","pt":1632562652317,"mc":[{"id":"1.188134680","rc":[{"batl":[[0,2.2,25],[1,2.42,2.06],[2,46,29]],"ltp":2.12,"tv":7.96,"id":9631939},{"batb":[[0,1.84,23.51]],"ltp":1.9,"tv":21.12,"id":8681938}]}]}
{"op":"mcm","clk":"4295729430","pt":1632562652422,"mc":[{"id":"1.188134680","rc":[{"batl":[[0,2.2,44.19]],"ltp":2.12,"tv":7.96,"id":9631939}]}]}
{"op":"mcm","clk":"4295841292","pt":1632563527127,"mc":[{"id":"1.188134680","marketDefinition":{"bspMarket":false,"turnInPlayEnabled":true,"persistenceEnabled":true,"marketBaseRate":5.0,"eventId":"30941304","eventTypeId":"2","numberOfWinners":1,"bettingType":"ODDS","marketType":"MATCH_ODDS","marketTime":"2021-09-25T11:50:00.000Z","suspendTime":"2021-09-25T11:50:00.000Z","bspReconciled":false,"complete":true,"inPlay":false,"crossMatching":true,"runnersVoidable":false,"numberOfActiveRunners":2,"betDelay":0,"status":"OPEN","runners":[{"status":"ACTIVE","sortPriority":1,"id":9631939,"name":"Marc-Andrea Huesler"},{"status":"ACTIVE","sortPriority":2,"id":8681938,"name":"Tim Van Rijthoven"}],"regulators":["MR_INT"],"countryCode":"CH","discountAllowed":true,"timezone":"UTC","openDate":"2021-09-25T12:00:00.000Z","version":4054607703,"name":"Match Odds","eventName":"Huesler v Van Rijthoven"}}]}
{"op":"mcm","clk":"4295841704","pt":1632563530339,"mc":[{"id":"1.188134680","marketDefinition":{"bspMarket":false,"turnInPlayEnabled":true,"persistenceEnabled":true,"marketBaseRate":5.0,"eventId":"30941304","eventTypeId":"2","numberOfWinners":1,"bettingType":"ODDS","marketType":"MATCH_ODDS","marketTime":"2021-09-25T11:50:00.000Z","suspendTime":"2021-09-25T11:50:00.000Z","bspReconciled":false,"complete":true,"inPlay":false,"crossMatching":true,"runnersVoidable":false,"numberOfActiveRunners":2,"betDelay":0,"status":"OPEN","runners":[{"status":"ACTIVE","sortPriority":1,"id":9631939,"name":"Marc-Andrea Huesler"},{"status":"ACTIVE","sortPriority":2,"id":8681938,"name":"Tim Van Rijthoven"}],"regulators":["MR_INT"],"countryCode":"CH","discountAllowed":true,"timezone":"UTC","openDate":"2021-09-25T11:50:00.000Z","version":4054607703,"name":"Match Odds","eventName":"Huesler v Van Rijthoven"},"rc":[{"batl":[[0,2.16,2.52],[1,2.2,25],[2,2.62,2.65]],"ltp":1.9,"tv":21.12,"id":8681938}]}]}
{"op":"mcm","clk":"4295853429","pt":1632563628308,"mc":[{"id":"1.188134680","rc":[{"batb":[[2,1.83,51.37]],"ltp":2.12,"tv":7.96,"id":9631939},{"batb":[[1,1.83,51.37]],"ltp":1.9,"tv":21.12,"id":8681938}]}]}
{"op":"mcm","clk":"4295853448","pt":1632563628522,"mc":[{"id":"1.188134680","rc":[{"batl":[[0,2.12,21.46],[1,2.16,2.52],[2,2.2,25]],"ltp":1.9,"tv":21.12,"id":8681938}]}]}
{"op":"mcm","clk":"4295896803","pt":1632564007214,"mc":[{"id":"1.188134680","rc":[{"batl":[[1,2.2,25],[2,2.62,2.65]],"ltp":1.9,"tv":21.12,"id":8681938}]}]}
{"op":"mcm","clk":"4295896967","pt":1632564008334,"mc":[{"id":"1.188134680","rc":[{"batl":[[1,46,29],[2,990,2.2]],"ltp":2.12,"tv":7.96,"id":9631939},{"batl":[[0,2.08,2.71],[1,2.12,21.46],[2,2.2,25]],"ltp":1.9,"tv":21.12,"id":8681938}]}]}
{"op":"mcm","clk":"4295897014","pt":1632564008603,"mc":[{"id":"1.188134680","rc":[{"batl":[[1,2.42,2.06],[2,46,29]],"ltp":2.12,"tv":7.96,"id":9631939}]}]}
{"op":"mcm","clk":"4295901947","pt":1632564046186,"mc":[{"id":"1.188134680","rc":[{"batb":[[1,2,31.25]],"ltp":2.12,"tv":7.96,"id":9631939}]}]}
{"op":"mcm","clk":"4295907749","pt":1632564089639,"mc":[{"id":"1.188134680","rc":[{"batb":[[0,2,31.25],[1,1.83,51.37],[2,1.51,15.52]],"ltp":2.12,"tv":7.96,"id":9631939}]}]}
{"op":"mcm","clk":"4295908086","pt":1632564092093,"mc":[{"id":"1.188134680","rc":[{"batb":[[0,2,46.37]],"ltp":2.12,"tv":7.96,"id":9631939}]}]}
{"op":"mcm","clk":"4295925681","pt":1632564228642,"mc":[{"id":"1.188134680","rc":[{"batl":[[0,2.06,22.08],[1,2.08,2.71]],"ltp":1.9,"tv":21.12,"id":8681938}]}]}
{"op":"mcm","clk":"4295998572","pt":1632564676185,"mc":[{"id":"1.188134680","rc":[{"batb":[[0,2.02,4.79],[1,2,46.37],[2,1.83,51.37]],"ltp":2.12,"tv":7.96,"id":9631939}]}]}
{"op":"mcm","clk":"4296192686","pt":1632566100327,"mc":[{"id":"1.188134680","rc":[{"trd":[[1.84,10]],"batb":[[0,1.84,18.51]],"ltp":1.84,"tv":31.12,"id":8681938}],"tv":39.09}]}
{"op":"mcm","clk":"4296192757","pt":1632566100915,"mc":[{"id":"1.188134680","rc":[{"batb":[[0,1.83,51.37],[1,1.44,17.99],[2,1.38,6.64]],"ltp":1.84,"tv":31.12,"id":8681938}]}]}
{"op":"mcm","clk":"4296192900","pt":1632566102029,"mc":[{"id":"1.188134680","rc":[{"batl":[[0,2.2,43.88]],"ltp":2.12,"tv":7.96,"id":9631939},{"batl":[[0,2.06,22.19]],"ltp":1.84,"tv":31.12,"id":8681938}]}]}
{"op":"mcm","clk":"4296304114","pt":1632567000652,"mc":[{"id":"1.188134680","rc":[{"batb":[[0,2.02,17.4]],"ltp":2.12,"tv":7.96,"id":9631939},{"batb":[[0,1.84,15.31],[1,1.83,51.37],[2,1.44,17.99]],"ltp":1.84,"tv":31.12,"id":8681938}]}]}
{"op":"mcm","clk":"4296319201","pt":1632567125732,"mc":[{"id":"1.188134680","marketDefinition":{"bspMarket":false,"turnInPlayEnabled":true,"persistenceEnabled":true,"marketBaseRate":5.0,"eventId":"30941304","eventTypeId":"2","numberOfWinners":1,"bettingType":"ODDS","marketType":"MATCH_ODDS","marketTime":"2021-09-25T11:07:00.000Z","suspendTime":"2021-09-25T11:07:00.000Z","bspReconciled":false,"complete":true,"inPlay":false,"crossMatching":true,"runnersVoidable":false,"numberOfActiveRunners":2,"betDelay":0,"status":"OPEN","runners":[{"status":"ACTIVE","sortPriority":1,"id":9631939,"name":"Marc-Andrea Huesler"},{"status":"ACTIVE","sortPriority":2,"id":8681938,"name":"Tim Van Rijthoven"}],"regulators":["MR_INT"],"countryCode":"CH","discountAllowed":true,"timezone":"UTC","openDate":"2021-09-25T11:50:00.000Z","version":4054701976,"name":"Match Odds","eventName":"Huesler v Van Rijthoven"}}]}
{"op":"mcm","clk":"4296319420","pt":1632567127743,"mc":[{"id":"1.188134680","marketDefinition":{"bspMarket":false,"turnInPlayEnabled":true,"persistenceEnabled":true,"marketBaseRate":5.0,"eventId":"30941304","eventTypeId":"2","numberOfWinners":1,"bettingType":"ODDS","marketType":"MATCH_ODDS","marketTime":"2021-09-25T11:07:00.000Z","suspendTime":"2021-09-25T11:07:00.000Z","bspReconciled":false,"complete":true,"inPlay":false,"crossMatching":true,"runnersVoidable":false,"numberOfActiveRunners":2,"betDelay":0,"status":"OPEN","runners":[{"status":"ACTIVE","sortPriority":1,"id":9631939,"name":"Marc-Andrea Huesler"},{"status":"ACTIVE","sortPriority":2,"id":8681938,"name":"Tim Van Rijthoven"}],"regulators":["MR_INT"],"countryCode":"CH","discountAllowed":true,"timezone":"UTC","openDate":"2021-09-25T11:07:00.000Z","version":4054701976,"name":"Match Odds","eventName":"Huesler v Van Rijthoven"}}]}
{"op":"mcm","clk":"4296356310","pt":1632567472275,"mc":[{"id":"1.188134680","rc":[{"trd":[[1.84,15.31]],"batb":[[0,1.84,12.65]],"ltp":1.84,"tv":36.43,"id":8681938}],"tv":44.4}]}
{"op":"mcm","clk":"4296356377","pt":1632567472919,"mc":[{"id":"1.188134680","rc":[{"batb":[[0,2.04,2.65],[1,2.02,17.4],[2,2,46.37]],"ltp":2.12,"tv":7.96,"id":9631939}]}]}
{"op":"mcm","clk":"4296371161","pt":1632567608337,"mc":[{"id":"1.188134680","rc":[{"batl":[[1,2.2,25],[2,2.62,2.65]],"ltp":1.84,"tv":36.43,"id":8681938}]}]}
{"op":"mcm","clk":"4296371232","pt":1632567608959,"mc":[{"id":"1.188134680","rc":[{"batl":[[1,46,29],[2,990,2.2]],"ltp":2.12,"tv":7.96,"id":9631939}]}]}
{"op":"mcm","clk":"4296375847","pt":1632567631463,"mc":[{"id":"1.188134680","rc":[{"batl":[[0,2.2,25],[1,2.62,2.65],[2,46,29]],"ltp":1.84,"tv":36.43,"id":8681938}]}]}
{"op":"mcm","clk":"4296376143","pt":1632567633283,"mc":[{"id":"1.188134680","rc":[{"batl":[[0,2.2,25]],"ltp":2.12,"tv":7.96,"id":9631939}]}]}
{"op":"mcm","clk":"4296379086","pt":1632567651496,"mc":[{"id":"1.188134680","rc":[{"batl":[[0,2.2,43.88]],"ltp":2.12,"tv":7.96,"id":9631939},{"batl":[[0,2.18,87.18],[1,2.2,25],[2,2.62,2.65]],"ltp":1.84,"tv":36.43,"id":8681938}]}]}
{"op":"mcm","clk":"4296385912","pt":1632567691721,"mc":[{"id":"1.188134680","rc":[{"batb":[[1,2.02,12.61]],"ltp":2.12,"tv":7.96,"id":9631939}]}]}
{"op":"mcm","clk":"4296391244","pt":1632567721655,"mc":[{"id":"1.188134680","rc":[{"batl":[[1,5.8,2.54],[2,46,29]],"ltp":2.12,"tv":7.96,"id":9631939}]}]}
{"op":"mcm","clk":"4296391869","pt":1632567725704,"mc":[{"id":"1.188134680","marketDefinition":{"bspMarket":false,"turnInPlayEnabled":true,"persistenceEnabled":true,"marketBaseRate":5.0,"eventId":"30941304","eventTypeId":"2","numberOfWinners":1,"bettingType":"ODDS","marketType":"MATCH_ODDS","marketTime":"2021-09-25T11:15:00.000Z","suspendTime":"2021-09-25T11:15:00.000Z","bspReconciled":false,"complete":true,"inPlay":false,"crossMatching":true,"runnersVoidable":false,"numberOfActiveRunners":2,"betDelay":0,"status":"OPEN","runners":[{"status":"ACTIVE","sortPriority":1,"id":9631939,"name":"Marc-Andrea Huesler"},{"status":"ACTIVE","sortPriority":2,"id":8681938,"name":"Tim Van Rijthoven"}],"regulators":["MR_INT"],"countryCode":"CH","discountAllowed":true,"timezone":"UTC","openDate":"2021-09-25T11:07:00.000Z","version":4054725749,"name":"Match Odds","eventName":"Huesler v Van Rijthoven"}}]}
{"op":"mcm","clk":"4296392211","pt":1632567727981,"mc":[{"id":"1.188134680","marketDefinition":{"bspMarket":false,"turnInPlayEnabled":true,"persistenceEnabled":true,"marketBaseRate":5.0,"eventId":"30941304","eventTypeId":"2","numberOfWinners":1,"bettingType":"ODDS","marketType":"MATCH_ODDS","marketTime":"2021-09-25T11:15:00.000Z","suspendTime":"2021-09-25T11:15:00.000Z","bspReconciled":false,"complete":true,"inPlay":false,"crossMatching":true,"runnersVoidable":false,"numberOfActiveRunners":2,"betDelay":0,"status":"OPEN","runners":[{"status":"ACTIVE","sortPriority":1,"id":9631939,"name":"Marc-Andrea Huesler"},{"status":"ACTIVE","sortPriority":2,"id":8681938,"name":"Tim Van Rijthoven"}],"regulators":["MR_INT"],"countryCode":"CH","discountAllowed":true,"timezone":"UTC","openDate":"2021-09-25T11:15:00.000Z","version":4054725749,"name":"Match Odds","eventName":"Huesler v Van Rijthoven"},"rc":[{"batl":[[0,2.2,25],[1,2.62,2.65],[2,4.4,3.34]],"ltp":1.84,"tv":36.43,"id":8681938}]}]}
{"op":"mcm","clk":"4296401846","pt":1632567792194,"mc":[{"id":"1.188134680","rc":[{"batb":[[1,2.02,18.93]],"ltp":2.12,"tv":7.96,"id":9631939},{"batb":[[0,1.86,14.63],[1,1.84,12.65],[2,1.83,51.37]],"ltp":1.84,"tv":36.43,"id":8681938}]}]}
{"op":"mcm","clk":"4296401920","pt":1632567792783,"mc":[{"id":"1.188134680","rc":[{"batb":[[1,1.85,15.13],[2,1.84,12.65]],"batl":[[0,2.18,87.18],[1,2.2,25],[2,2.62,2.65]],"ltp":1.84,"tv":36.43,"id":8681938}]}]}
{"op":"mcm","clk":"4296411344","pt":1632567854402,"mc":[{"id":"1.188134680","rc":[{"trd":[[1.86,1.41]],"batb":[[0,1.86,13.93]],"ltp":1.86,"tv":37.84,"id":8681938}],"tv":45.8}]}
{"op":"mcm","clk":"4296415540","pt":1632567880216,"mc":[{"id":"1.188134680","rc":[{"batb":[[0,1.86,19.93]],"ltp":1.86,"tv":37.84,"id":8681938}]}]}
{"op":"mcm","clk":"4296415631","pt":1632567880814,"mc":[{"id":"1.188134680","rc":[{"batb":[[1,2.02,6.33],[2,2,59.23]],"ltp":2.12,"tv":7.96,"id":9631939},{"batb":[[2,1.83,51.37]],"ltp":1.86,"tv":37.84,"id":8681938}]}]}
{"op":"mcm","clk":"4296439721","pt":1632568025848,"mc":[{"id":"1.188134680","marketDefinition":{"bspMarket":false,"turnInPlayEnabled":true,"persistenceEnabled":true,"marketBaseRate":5.0,"eventId":"30941304","eventTypeId":"2","numberOfWinners":1,"bettingType":"ODDS","marketType":"MATCH_ODDS","marketTime":"2021-09-25T11:06:00.000Z","suspendTime":"2021-09-25T11:06:00.000Z","bspReconciled":false,"complete":true,"inPlay":false,"crossMatching":true,"runnersVoidable":false,"numberOfActiveRunners":2,"betDelay":0,"status":"OPEN","runners":[{"status":"ACTIVE","sortPriority":1,"id":9631939,"name":"Marc-Andrea Huesler"},{"status":"ACTIVE","sortPriority":2,"id":8681938,"name":"Tim Van Rijthoven"}],"regulators":["MR_INT"],"countryCode":"CH","discountAllowed":true,"timezone":"UTC","openDate":"2021-09-25T11:15:00.000Z","version":4054735558,"name":"Match Odds","eventName":"Huesler v Van Rijthoven"}}]}
{"op":"mcm","clk":"4296440350","pt":1632568029128,"mc":[{"id":"1.188134680","marketDefinition":{"bspMarket":false,"turnInPlayEnabled":true,"persistenceEnabled":true,"marketBaseRate":5.0,"eventId":"30941304","eventTypeId":"2","numberOfWinners":1,"bettingType":"ODDS","marketType":"MATCH_ODDS","marketTime":"2021-09-25T11:06:00.000Z","suspendTime":"2021-09-25T11:06:00.000Z","bspReconciled":false,"complete":true,"inPlay":false,"crossMatching":true,"runnersVoidable":false,"numberOfActiveRunners":2,"betDelay":0,"status":"OPEN","runners":[{"status":"ACTIVE","sortPriority":1,"id":9631939,"name":"Marc-Andrea Huesler"},{"status":"ACTIVE","sortPriority":2,"id":8681938,"name":"Tim Van Rijthoven"}],"regulators":["MR_INT"],"countryCode":"CH","discountAllowed":true,"timezone":"UTC","openDate":"2021-09-25T11:06:00.000Z","version":4054735558,"name":"Match Odds","eventName":"Huesler v Van Rijthoven"},"rc":[{"batl":[[0,2.2,25],[1,2.62,2.65],[2,4.4,3.34]],"ltp":1.86,"tv":37.84,"id":8681938}]}]}
{"op":"mcm","clk":"4296446640","pt":1632568067339,"mc":[{"id":"1.188134680","rc":[{"batl":[[0,2.18,2],[1,2.2,43.88],[2,5.8,2.54]],"ltp":2.12,"tv":7.96,"id":9631939},{"batl":[[0,1.97,2],[1,2.2,25],[2,2.62,2.65]],"ltp":1.86,"tv":37.84,"id":8681938}]}]}
{"op":"mcm","clk":"4296446739","pt":1632568067930,"mc":[{"id":"1.188134680","rc":[{"batb":[[0,1.86,34.88]],"ltp":1.86,"tv":37.84,"id":8681938}]}]}
{"op":"mcm","clk":"4296450172","pt":1632568090357,"mc":[{"id":"1.188134680","rc":[{"batb":[[0,2.04,182.24],[1,2.02,18.93]],"batl":[[1,2.2,25],[2,2.44,7.31]],"ltp":2.12,"tv":7.96,"id":9631939},{"batb":[[0,1.87,117.95],[1,1.86,19.93],[2,1.85,15.13]],"batl":[[1,2.14,7.31],[2,2.2,25]],"ltp":1.86,"tv":37.84,"id":8681938}]}]}
{"op":"mcm","clk":"4296450221","pt":1632568090778,"mc":[{"id":"1.188134680","rc":[{"batb":[[2,2,39.22]],"ltp":2.12,"tv":7.96,"id":9631939}]}]}
{"op":"mcm","clk":"4296450474","pt":1632568092696,"mc":[{"id":"1.188134680","rc":[{"batl":[[0,2.18,16.92]],"ltp":2.12,"tv":7.96,"id":9631939},{"batb":[[0,1.88,10.18],[1,1.87,117.95],[2,1.86,6]],"ltp":1.86,"tv":37.84,"id":8681938}]}]}
{"op":"mcm","clk":"4296451101","pt":1632568096579,"mc":[{"id":"1.188134680","rc":[{"batb":[[0,2.04,201.86]],"ltp":2.12,"tv":7.96,"id":9631939}]}]}
{"op":"mcm","clk":"4296499068","pt":1632568398863,"mc":[{"id":"1.188134680","rc":[{"trd":[[1.88,1.56]],"batb":[[0,1.88,9.4]],"ltp":1.88,"tv":39.4,"id":8681938}],"tv":47.37}]}
{"op":"mcm","clk":"4296529705","pt":1632568593512,"mc":[{"id":"1.188134680","rc":[{"batb":[[1,2.02,21.15]],"ltp":2.12,"tv":7.96,"id":9631939}]}]}
{"op":"mcm","clk":"4296544431","pt":1632568698359,"mc":[{"id":"1.188134680","rc":[{"batb":[[1,2.02,8.54]],"ltp":2.12,"tv":7.96,"id":9631939},{"batb":[[0,1.89,402.41],[1,1.88,9.4],[2,1.87,117.95]],"ltp":1.88,"tv":39.4,"id":8681938}]}]}
{"op":"mcm","clk":"4296547617","pt":1632568720150,"mc":[{"id":"1.188134680","rc":[{"batl":[[0,2.12,4],[1,2.18,2],[2,2.2,25]],"ltp":2.12,"tv":7.96,"id":9631939},{"batb":[[0,1.89,5],[1,1.88,13.4]],"ltp":1.88,"tv":39.4,"id":8681938}]}]}
{"op":"mcm","clk":"4296548938","pt":1632568729143,"mc":[{"id":"1.188134680","rc":[{"batb":[[0,1.9,1428.82],[1,1.89,5],[2,1.88,13.4]],"ltp":1.88,"tv":39.4,"id":8681938}]}]}
{"op":"mcm","clk":"4296551486","pt":1632568747079,"mc":[{"id":"1.188134680","rc":[{"batb":[[1,2,39.22],[2,1.9,166.67]],"ltp":2.12,"tv":7.96,"id":9631939},{"batb":[[2,1.87,117.95]],"ltp":1.88,"tv":39.4,"id":8681938}]}]}
{"op":"mcm","clk":"4296552557","pt":1632568754702,"mc":[{"id":"1.188134680","rc":[{"batb":[[0,1.9,1028.54]],"ltp":1.88,"tv":39.4,"id":8681938}]}]}
{"op":"mcm","clk":"4296552673","pt":1632568755612,"mc":[{"id":"1.188134680","rc":[{"batb":[[2,1.98,5]],"batl":[[0,2.18,2],[1,2.2,25],[2,2.44,7.31]],"ltp":2.12,"tv":7.96,"id":9631939},{"batb":[[1,1.87,132.73],[2,1.86,20.95]],"ltp":1.88,"tv":39.4,"id":8681938}]}]}
{"op":"mcm","clk":"4296555631","pt":1632568775927,"mc":[{"id":"1.188134680","rc":[{"trd":[[1.9,13.59]],"batb":[[0,1.9,1026.19]],"ltp":1.9,"tv":44.1,"id":8681938}],"tv":52.06}]}
{"op":"mcm","clk":"4296556629","pt":1632568783360,"mc":[{"id":"1.188134680","rc":[{"batb":[[1,2.02,12.61],[2,2,39.22]],"ltp":2.12,"tv":7.96,"id":9631939},{"batb":[[0,1.87,117.95],[1,1.86,6],[2,1.85,15.13]],"ltp":1.9,"tv":44.1,"id":8681938}]}]}
{"op":"mcm","clk":"4296557233","pt":1632568787352,"mc":[{"id":"1.188134680","rc":[{"batb":[[2,1.83,51.37]],"batl":[[0,1.9,2.35],[1,1.97,2],[2,2.14,7.31]],"ltp":1.9,"tv":44.1,"id":8681938}]}]}
{"op":"mcm","clk":"4296564681","pt":1632568835813,"mc":[{"id":"1.188134680","rc":[{"trd":[[1.87,0.39]],"batb":[[0,1.87,117.75]],"ltp":1.87,"tv":44.49,"id":8681938}],"tv":52.45}]}
{"op":"mcm","clk":"4296570769","pt":1632568878573,"mc":[{"id":"1.188134680","rc":[{"batl":[[1,2.2,25.2]],"ltp":2.12,"tv":7.96,"id":9631939}]}]}
{"op":"mcm","clk":"4296583792","pt":1632568975978,"mc":[{"id":"1.188134680","rc":[{"batl":[[0,2.14,39.98],[1,2.18,2],[2,2.2,25.2]],"ltp":2.12,"tv":7.96,"id":9631939}]}]}
{"op":"mcm","clk":"4296583869","pt":1632568976565,"mc":[{"id":"1.188134680","rc":[{"batb":[[1,2,39.22],[2,1.99,4]],"ltp":2.12,"tv":7.96,"id":9631939}]}]}
{"op":"mcm","clk":"4296585745","pt":1632568990303,"mc":[{"id":"1.188134680","marketDefinition":{"bspMarket":false,"turnInPlayEnabled":true,"persistenceEnabled":true,"marketBaseRate":5.0,"eventId":"30941304","eventTypeId":"2","numberOfWinners":1,"bettingType":"ODDS","marketType":"MATCH_ODDS","marketTime":"2021-09-25T11:06:00.000Z","suspendTime":"2021-09-25T11:06:00.000Z","bspReconciled":false,"complete":true,"inPlay":true,"crossMatching":true,"runnersVoidable":false,"numberOfActiveRunners":2,"betDelay":3,"status":"OPEN","runners":[{"status":"ACTIVE","sortPriority":1,"id":9631939,"name":"Marc-Andrea Huesler"},{"status":"ACTIVE","sortPriority":2,"id":8681938,"name":"Tim Van Rijthoven"}],"regulators":["MR_INT"],"countryCode":"CH","discountAllowed":true,"timezone":"UTC","openDate":"2021-09-25T11:06:00.000Z","version":4054761384,"name":"Match Odds","eventName":"Huesler v Van Rijthoven"},"rc":[{"batb":[[0,2,26.36],[1,1.25,29.25],[2,1.01,618.28]],"batl":[[0,5.8,2.73],[1,2.18,0],[2,2.2,0]],"ltp":2.12,"tv":7.96,"id":9631939},{"batb":[[0,1.25,29.25],[1,1.01,618.28],[2,1.83,0]],"batl":[[1,4.4,3.54],[2,2.14,0]],"ltp":1.87,"tv":44.49,"id":8681938}]}]}
{"op":"mcm","clk":"4296586794","pt":1632568998698,"mc":[{"id":"1.188134680","rc":[{"batb":[[2,1.03,439.76]],"ltp":2.12,"tv":7.96,"id":9631939},{"batb":[[1,1.03,439.76],[2,1.01,618.28]],"ltp":1.87,"tv":44.49,"id":8681938}]}]}
{"op":"mcm","clk":"4296587925","pt":1632569007191,"mc":[{"id":"1.188134680","rc":[{"trd":[[1.9,18.15]],"batl":[[0,4.4,3.61],[1,4.4,0]],"ltp":1.9,"tv":49.05,"id":8681938}],"tv":57.01}]}
{"op":"mcm","clk":"4296588045","pt":1632569008080,"mc":[{"id":"1.188134680","rc":[{"batb":[[1,1.92,108.56],[2,1.75,144.75]],"batl":[[0,2.82,206.81],[1,5.8,2.54]],"ltp":2.12,"tv":7.96,"id":9631939},{"trd":[[1.9,18.28]],"batb":[[0,1.98,195.48],[1,1.91,109.85],[2,1.25,29.25]],"batl":[[0,4.4,3.54]],"ltp":1.9,"tv":49.19,"id":8681938}],"tv":57.15}]}
{"op":"mcm","clk":"4296588464","pt":1632569011289,"mc":[{"id":"1.188134680","rc":[{"trd":[[2,15]],"batb":[[0,2,16.36]],"batl":[[0,2.02,37.77],[1,2.1,2],[2,2.82,206.81]],"ltp":2.0,"tv":22.96,"id":9631939},{"trd":[[2,5]],"batb":[[0,1.99,5],[1,1.98,195.48],[2,1.91,109.85]],"batl":[[0,2.06,57.74],[1,4.4,3.54]],"ltp":2.0,"tv":54.19,"id":8681938}],"tv":77.15}]}
{"op":"mcm","clk":"4296588500","pt":1632569011514,"mc":[{"id":"1.188134680","rc":[{"batl":[[0,2.1,2],[1,5.8,2.73],[2,2.82,0]],"ltp":2.0,"tv":22.96,"id":9631939},{"batl":[[0,4.4,3.54],[1,4.4,0]],"ltp":2.0,"tv":54.19,"id":8681938}]}]}
{"op":"mcm","clk":"4296588881","pt":1632569014116,"mc":[{"id":"1.188134680","rc":[{"trd":[[2,47.72]],"batb":[[0,1.92,108.56],[1,1.75,144.75],[2,1.25,29.25]],"ltp":2.0,"tv":55.68,"id":9631939}],"tv":109.87}]}
{"op":"mcm","clk":"4296588988","pt":1632569014805,"mc":[{"id":"1.188134680","rc":[{"batl":[[0,2.08,98.71],[1,2.1,2],[2,5.8,2.73]],"ltp":2.0,"tv":55.68,"id":9631939}]}]}
{"op":"mcm","clk":"4296589304","pt":1632569017096,"mc":[{"id":"1.188134680","rc":[{"batb":[[0,1.75,144.75],[1,1.25,29.25],[2,1.11,239.87]],"batl":[[0,5.8,2.73],[1,2.1,0],[2,5.8,0]],"ltp":2.0,"tv":55.68,"id":9631939},{"batb":[[0,1.91,109.85],[1,1.25,29.25],[2,1.11,239.87]],"ltp":2.0,"tv":54.19,"id":8681938}]}]}
{"op":"mcm","clk":"4296589427","pt":1632569017932,"mc":[{"id":"1.188134680","rc":[{"batb":[[2,1.2,343.02]],"ltp":2.0,"tv":55.68,"id":9631939}]}]}
{"op":"mcm","clk":"4296589731","pt":1632569020220,"mc":[{"id":"1.188134680","rc":[{"batb":[[0,1.75,149.75],[1,1.74,4],[2,1.25,29.25]],"ltp":2.0,"tv":55.68,"id":9631939},{"batb":[[2,1.2,395.79]],"batl":[[0,2.34,3.2],[1,4.4,3.34]],"ltp":2.0,"tv":54.19,"id":8681938}]}]}
{"op":"mcm","clk":"4296590231","pt":1632569023709,"mc":[{"id":"1.188134680","rc":[{"batb":[[1,1.4,131.93],[2,1.3,175.9]],"ltp":2.0,"tv":54.19,"id":8681938}]}]}
{"op":"mcm","clk":"4296590942","pt":1632569029112,"mc":[{"id":"1.188134680","rc":[{"batl":[[0,1.98,15.15],[1,2.34,3.2],[2,4.4,3.34]],"ltp":2.0,"tv":54.19,"id":8681938}]}]}
{"op":"mcm","clk":"4296591075","pt":1632569030218,"mc":[{"id":"1.188134680","rc":[{"batb":[[0,1.99,193.11],[1,1.85,1327.22],[2,1.84,122.85]],"batl":[[0,2.22,13.71],[1,5.8,2.54]],"ltp":2.0,"tv":55.68,"id":9631939},{"batb":[[1,1.84,122.51],[2,1.4,131.93]],"ltp":2.0,"tv":54.19,"id":8681938}]}]}
{"op":"mcm","clk":"4296591167","pt":1632569030847,"mc":[{"id":"1.188134680","rc":[{"batb":[[1,1.84,122.85],[2,1.75,5]],"ltp":2.0,"tv":55.68,"id":9631939}]}]}
{"op":"mcm","clk":"4296591382","pt":1632569032229,"mc":[{"id":"1.188134680","rc":[{"batb":[[2,1.76,4]],"batl":[[0,2.08,4],[1,2.22,13.71],[2,5.8,2.54]],"ltp":2.0,"tv":55.68,"id":9631939},{"batb":[[0,1.92,5],[1,1.91,113.85],[2,1.84,122.51]],"ltp":2.0,"tv":54.19,"id":8681938}]}]}
{"op":"mcm","clk":"4296591872","pt":1632569035936,"mc":[{"id":"1.188134680","rc":[{"batb":[[0,1.93,4],[1,1.92,5],[2,1.91,113.85]],"ltp":2.0,"tv":54.19,"id":8681938}]}]}
{"op":"mcm","clk":"4296592213","pt":1632569038652,"mc":[{"id":"1.188134680","rc":[{"batb":[[0,1.94,4],[1,1.93,4],[2,1.92,5]],"ltp":2.0,"tv":54.19,"id":8681938}]}]}
{"op":"mcm","clk":"4296592734","pt":1632569042351,"mc":[{"id":"1.188134680","rc":[{"trd":[[2.02,14.85]],"batb":[[1,1.95,304.85],[2,1.93,304.97]],"batl":[[0,2.04,263.12],[1,2.08,4],[2,2.22,13.71]],"ltp":2.02,"tv":70.53,"id":9631939},{"trd":[[1.98,15.15]],"batl":[[0,2.34,3.2],[1,4.4,3.34],[2,4.4,0]],"ltp":1.98,"tv":69.34,"id":8681938}],"tv":139.87}]}
{"op":"mcm","clk":"4296593012","pt":1632569044353,"mc":[{"id":"1.188134680","rc":[{"batb":[[2,1.91,109.85]],"ltp":1.98,"tv":69.34,"id":8681938}]}]}
{"op":"mcm","clk":"4296593146","pt":1632569045358,"mc":[{"id":"1.188134680","rc":[{"batl":[[0,2.04,466.29],[1,2.06,255.71],[2,5.8,2.73]],"ltp":2.02,"tv":70.53,"id":9631939},{"batb":[[0,1.91,109.85],[1,1.84,122.51],[2,1.4,131.93]],"batl":[[0,2.32,251.11],[1,2.34,3],[2,4.4,3.34]],"ltp":1.98,"tv":69.34,"id":8681938}]}]}
{"op":"mcm","clk":"4296593157","pt":1632569045461,"mc":[{"id":"1.188134680","rc":[{"batb":[[0,1.84,122.85],[1,1.76,4],[2,1.5,94.99]],"batl":[[0,5.8,2.73],[1,2.06,0],[2,5.8,0]],"ltp":2.02,"tv":70.53,"id":9631939},{"batb":[[0,1.84,122.51],[1,1.4,131.93],[2,1.3,175.9]],"batl":[[0,2.34,3.2],[1,4.4,3.34],[2,4.4,0]],"ltp":1.98,"tv":69.34,"id":8681938}]}]}
{"op":"mcm","clk":"4296593704","pt":1632569049261,"mc":[{"id":"1.188134680","rc":[{"batb":[[0,1.84,127.85],[1,1.83,5],[2,1.81,353.27]],"batl":[[0,2.1,309.06],[1,2.12,235.36],[2,2.2,4.2]],"ltp":2.02,"tv":70.53,"id":9631939},{"batb":[[0,1.84,127.51],[1,1.83,5],[2,1.4,131.93]],"batl":[[0,2.2,4.2],[1,2.34,3],[2,4.4,3.34]],"ltp":1.98,"tv":69.34,"id":8681938}]}]}
{"op":"mcm","clk":"4296593817","pt":1632569050063,"mc":[{"id":"1.188134680","rc":[{"batb":[[0,1.92,325.28],[1,1.9,320.27],[2,1.84,127.85]],"batl":[[0,1.99,232.54],[1,2.02,408.29]],"ltp":2.02,"tv":70.53,"id":9631939}]}]}
{"op":"mcm","clk":"4296594292","pt":1632569053257,"mc":[{"id":"1.188134680","rc":[{"batb":[[2,1.5,94.99]],"ltp":1.98,"tv":69.34,"id":8681938}]}]}
{"op":"mcm","clk":"4296594344","pt":1632569053675,"mc":[{"id":"1.188134680","rc":[{"trd":[[1.92,5.91]],"batb":[[0,1.92,319.37]],"ltp":1.92,"tv":76.44,"id":9631939},{"trd":[[2.1,5.4]],"ltp":2.1,"tv":74.74,"id":8681938}],"tv":151.18}]}
{"op":"mcm","clk":"4296594505","pt":1632569054853,"mc":[{"id":"1.188134680","rc":[{"batb":[[0,1.84,127.85],[1,1.83,5],[2,1.76,4]],"batl":[[0,2.2,4.2],[1,5.8,2.54],[2,2.2,0]],"ltp":1.92,"tv":76.44,"id":9631939}]}]}
{"op":"mcm","clk":"4296594874","pt":1632569057769,"mc":[{"id":"1.188134680","rc":[{"batb":[[2,1.81,349.8]],"batl":[[0,2.1,312.05],[1,2.12,235.37],[2,2.2,4.2]],"ltp":1.92,"tv":76.44,"id":9631939}]}]}
{"op":"mcm","clk":"4296595876","pt":1632569065192,"mc":[{"id":"1.188134680","rc":[{"batb":[[2,1.76,4]],"batl":[[0,2.2,4.2],[1,5.8,2.54],[2,2.2,0]],"ltp":1.92,"tv":76.44,"id":9631939}]}]}
{"op":"mcm","clk":"4296595913","pt":1632569065466,"mc":[{"id":"1.188134680","rc":[{"batb":[[1,1.5,94.99],[2,1.4,131.93]],"ltp":1.92,"tv":76.44,"id":9631939},{"batb":[[1,1.5,94.99],[2,1.4,131.93]],"batl":[[1,4.4,3.34],[2,4.4,0]],"ltp":2.1,"tv":74.74,"id":8681938}]}]}
{"op":"mcm","clk":"4296596304","pt":1632569068222,"mc":[{"id":"1.188134680","rc":[{"batb":[[0,2,1195.31],[1,1.99,1160.15],[2,1.98,1160.15]],"ltp":1.92,"tv":76.44,"id":9631939},{"trd":[[1.91,31.42]],"batb":[[0,1.91,312.9],[1,1.89,325.65],[2,1.87,511.36]],"batl":[[0,1.98,243.01],[1,2,278.98],[2,2.2,4.2]],"ltp":1.91,"tv":106.16,"id":8681938}],"tv":182.6}]}
{"op":"mcm","clk":"4296596449","pt":1632569069233,"mc":[{"id":"1.188134680","rc":[{"batb":[[0,2.06,172.57],[1,2,478.12],[2,1.99,464.06]],"batl":[[1,2.3,13.04],[2,5.8,2.54]],"ltp":1.92,"tv":76.44,"id":9631939}]}]}
{"op":"mcm","clk":"4296596709","pt":1632569071113,"mc":[{"id":"1.188134680","rc":[{"batl":[[0,2.14,4],[1,2.18,3],[2,2.2,4.2]],"ltp":1.92,"tv":76.44,"id":9631939},{"batb":[[2,1.88,5]],"ltp":1.91,"tv":106.16,"id":8681938}]}]}
{"op":"mcm","clk":"4296596865","pt":1632569072016,"mc":[{"id":"1.188134680","rc":[{"batl":[[0,1.97,112.23],[1,1.98,243.01],[2,2,278.98]],"ltp":1.91,"tv":106.16,"id":8681938}]}]}
{"op":"mcm","clk":"4296597055","pt":1632569073306,"mc":[{"id":"1.188134680","rc":[{"trd":[[1.91,141.22]],"batb":[[0,1.91,258]],"ltp":1.91,"tv":215.96,"id":8681938}],"tv":292.4}]}
{"op":"mcm","clk":"4296597260","pt":1632569075045,"mc":[{"id":"1.188134680","rc":[{"batl":[[2,2.2,210.62]],"ltp":1.92,"tv":76.44,"id":9631939}]}]}
{"op":"mcm","clk":"4296597399","pt":1632569076214,"mc":[{"id":"1.188134680","rc":[{"batb":[[0,1.91,289.59]],"batl":[[1,1.98,280.68]],"ltp":1.91,"tv":215.96,"id":8681938}]}]}
{"op":"mcm","clk":"4296598126","pt":1632569082928,"mc":[{"id":"1.188134680","rc":[{"batl":[[0,2.1,177.42],[1,2.14,4],[2,2.2,206.62]],"ltp":1.92,"tv":76.44,"id":9631939},{"trd":[[1.91,146.86]],"batb":[[0,1.91,286.77],[1,1.9,196.09],[2,1.89,325.65]],"ltp":1.91,"tv":221.59,"id":8681938}],"tv":298.04}]}
{"op":"mcm","clk":"4296598310","pt":1632569084516,"mc":[{"id":"1.188134680","rc":[{"batb":[[1,2.04,204],[2,2,478.12]],"ltp":1.92,"tv":76.44,"id":9631939},{"batl":[[0,1.95,213.42],[1,1.97,112.23],[2,1.98,280.68]],"ltp":1.91,"tv":221.59,"id":8681938}]}]}
{"op":"mcm","clk":"4296599445","pt":1632569093257,"mc":[{"id":"1.188134680","rc":[{"batb":[[0,1.98,3],[1,1.97,5],[2,1.94,325.11]],"batl":[[0,2.2,206.62],[1,2.22,190.7],[2,5.8,2.54]],"ltp":1.92,"tv":76.44,"id":9631939},{"batb":[[0,1.84,178.24],[1,1.83,230.35],[2,1.8,131.48]],"batl":[[0,2.06,175.38],[1,2.08,202.97],[2,2.2,4.2]],"ltp":1.91,"tv":221.59,"id":8681938}]}]}
{"op":"mcm","clk":"4296599790","pt":1632569096158,"mc":[{"id":"1.188134680","rc":[{"batb":[[0,1.87,253.8],[1,1.85,348.52],[2,1.84,178.24]],"batl":[[2,2.1,280.32]],"ltp":1.91,"tv":221.59,"id":8681938}]}]}
{"op":"mcm","clk":"4296599862","pt":1632569096580,"mc":[{"id":"1.188134680","rc":[{"batl":[[0,2.2,209.62]],"ltp":1.92,"tv":76.44,"id":9631939},{"batb":[[2,1.84,183.24]],"batl":[[0,2.04,4],[1,2.06,175.38],[2,2.08,202.97]],"ltp":1.91,"tv":221.59,"id":8681938}]}]}
{"op":"mcm","clk":"4296600287","pt":1632569100172,"mc":[{"id":"1.188134680","rc":[{"batb":[[1,1.94,325.11],[2,1.93,218.87]],"batl":[[0,2.2,3.2],[1,5.8,2.54],[2,5.8,0]],"ltp":1.92,"tv":76.44,"id":9631939},{"batb":[[0,1.84,5],[1,1.83,5],[2,1.8,131.48]],"ltp":1.91,"tv":221.59,"id":8681938}]}]}
{"op":"mcm","clk":"4296600758","pt":1632569103188,"mc":[{"id":"1.188134680","rc":[{"batb":[[0,1.94,325.11],[1,1.93,218.87],[2,1.91,293.72]],"batl":[[0,1.98,276.61],[1,2,278.96],[2,2.18,13.76]],"ltp":1.92,"tv":76.44,"id":9631939},{"batb":[[0,2,478.12],[1,1.99,464.06],[2,1.98,464.06]],"batl":[[0,2.08,202.97],[1,2.2,4.2],[2,4.4,3.34]],"ltp":1.91,"tv":221.59,"id":8681938}]}]}
{"op":"mcm","clk":"4296600907","pt":1632569104192,"mc":[{"id":"1.188134680","rc":[{"trd":[[1.98,15.15]],"batl":[[0,1.98,261.46]],"ltp":1.98,"tv":91.59,"id":9631939},{"trd":[[2.02,14.85]],"ltp":2.02,"tv":236.44,"id":8681938}],"tv":328.04}]}
{"op":"mcm","clk":"4296601202","pt":1632569106310,"mc":[{"id":"1.188134680","rc":[{"batl":[[0,1.98,263.81],[2,2.16,3]],"ltp":1.98,"tv":91.59,"id":9631939},{"batb":[[1,1.99,469.06],[2,1.98,469.06]],"ltp":2.02,"tv":236.44,"id":8681938}]}]}
{"op":"mcm","clk":"4296601495","pt":1632569108225,"mc":[{"id":"1.188134680","rc":[{"trd":[[1.98,51.98]],"batl":[[0,1.98,226.98]],"ltp":1.98,"tv":128.42,"id":9631939},{"trd":[[2.02,50.95]],"ltp":2.02,"tv":272.54,"id":8681938}],"tv":400.97}]}
{"op":"mcm","clk":"4296601617","pt":1632569109188,"mc":[{"id":"1.188134680","rc":[{"batb":[[0,1.95,786],[1,1.94,325.11],[2,1.93,218.87]],"ltp":1.98,"tv":128.42,"id":9631939}]}]}
{"op":"mcm","clk":"4296601728","pt":1632569110025,"mc":[{"id":"1.188134680","rc":[{"batl":[[2,2.1,170.59]],"ltp":1.98,"tv":128.42,"id":9631939},{"batl":[[2,2.3,135.51]],"ltp":2.02,"tv":272.54,"id":8681938}]}]}
{"op":"mcm","clk":"4296601908","pt":1632569111402,"mc":[{"id":"1.188134680","rc":[{"batl":[[0,1.98,254.23]],"ltp":1.98,"tv":128.42,"id":9631939}]}]}
{"op":"mcm","clk":"4296602616","pt":1632569116339,"mc":[{"id":"1.188134680","rc":[{"batl":[[0,1.98,251.88]],"ltp":1.98,"tv":128.42,"id":9631939},{"batb":[[0,2,239.06],[1,1.99,237.03],[2,1.98,237.03]],"ltp":2.02,"tv":272.54,"id":8681938}]}]}
{"op":"mcm","clk":"4296602687","pt":1632569116813,"mc":[{"id":"1.188134680","rc":[{"batb":[[1,1.77,174.06],[2,1.76,259.25]],"batl":[[0,2.1,170.59],[1,2.12,234.2],[2,2.16,3]],"ltp":1.98,"tv":128.42,"id":9631939},{"batb":[[0,1.91,185.93],[1,1.9,201.02],[2,1.87,117.19]],"batl":[[0,2.3,135.71],[1,2.32,218.93],[2,4.4,3.34]],"ltp":2.02,"tv":272.54,"id":8681938}]}]}
{"op":"mcm","clk":"4296602803","pt":1632569117720,"mc":[{"id":"1.188134680","rc":[{"batb":[[0,1.77,174.06],[1,1.76,259.25],[2,1.75,145.43]],"ltp":1.98,"tv":128.42,"id":9631939}]}]}
{"op":"mcm","clk":"4296603063","pt":1632569119726,"mc":[{"id":"1.188134680","rc":[{"batl":[[0,2.08,243.43],[1,2.1,412.44],[2,2.12,234.2]],"ltp":1.98,"tv":128.42,"id":9631939}]}]}
{"op":"mcm","clk":"4296603230","pt":1632569120900,"mc":[{"id":"1.188134680","rc":[{"batb":[[0,1.77,178.06],[1,1.76,263.25]],"ltp":1.98,"tv":128.42,"id":9631939},{"batl":[[0,2.3,138.71]],"ltp":2.02,"tv":272.54,"id":8681938}]}]}
{"op":"mcm","clk":"4296604086","pt":1632569127304,"mc":[{"id":"1.188134680","rc":[{"batl":[[0,1.95,2.35],[1,2.08,243.43],[2,2.1,412.44]],"ltp":1.98,"tv":128.42,"id":9631939}]}]}
{"op":"mcm","clk":"4296604824","pt":1632569133346,"mc":[{"id":"1.188134680","rc":[{"batb":[[0,1.77,4],[1,1.76,4]],"ltp":1.98,"tv":128.42,"id":9631939},{"batl":[[0,2.3,3.2],[1,4.4,3.34],[2,4.4,0]],"ltp":2.02,"tv":272.54,"id":8681938}]}]}
{"op":"mcm","clk":"4296604846","pt":1632569133556,"mc":[{"id":"1.188134680","rc":[{"batb":[[1,1.75,145.43],[2,1.4,131.93]],"batl":[[1,2.1,170.59],[2,2.12,234.2]],"ltp":1.98,"tv":128.42,"id":9631939}]}]}
{"op":"mcm","clk":"4296605151","pt":1632569136256,"mc":[{"id":"1.188134680","rc":[{"trd":[[1.95,4.7]],"batb":[[0,1.99,1922.1],[1,1.98,1863.23],[2,1.97,1865.58]],"batl":[[0,2.1,170.59],[1,2.12,234.2],[2,2.16,3]],"ltp":1.95,"tv":133.12,"id":9631939},{"trd":[[1.91,178.28]],"batb":[[0,1.91,170.22],[2,1.88,2034.58]],"ltp":1.91,"tv":303.97,"id":8681938}],"tv":437.09}]}
{"op":"mcm","clk":"4296605290","pt":1632569137378,"mc":[{"id":"1.188134680","rc":[{"batb":[[0,2.02,180.77],[1,1.99,480.52],[2,1.98,466.4]],"ltp":1.95,"tv":133.12,"id":9631939},{"batb":[[0,1.92,356.28],[1,1.91,170.22],[2,1.9,521.34]],"batl":[[0,2,340.66],[1,2.02,270.87],[2,2.3,3.2]],"ltp":1.91,"tv":303.97,"id":8681938}]}]}
{"op":"mcm","clk":"4296605592","pt":1632569139958,"mc":[{"id":"1.188134680","rc":[{"batb":[[2,1.9,525.34]],"batl":[[0,2,448.13],[2,2.28,2.2]],"ltp":1.91,"tv":303.97,"id":8681938}]}]}
{"op":"mcm","clk":"4296605771","pt":1632569141236,"mc":[{"id":"1.188134680","rc":[{"trd":[[1.92,63.96]],"batb":[[0,1.92,324.3]],"ltp":1.92,"tv":367.93,"id":8681938}],"tv":501.05}]}
{"op":"mcm","clk":"4296605830","pt":1632569141761,"mc":[{"id":"1.188134680","rc":[{"batl":[[0,2,107.47]],"ltp":1.92,"tv":367.93,"id":8681938}]}]}
{"op":"mcm","clk":"4296606177","pt":1632569144639,"mc":[{"id":"1.188134680","rc":[{"batl":[[0,1.99,221.09],[1,2,107.47],[2,2.02,408.37]],"ltp":1.92,"tv":367.93,"id":8681938}]}]}
{"op":"mcm","clk":"4296606811","pt":1632569150160,"mc":[{"id":"1.188134680","rc":[{"batb":[[0,1.91,109.83],[1,1.77,4],[2,1.5,94.99]],"batl":[[0,5.8,2.73],[1,2.12,0],[2,2.16,0]],"ltp":1.95,"tv":133.12,"id":9631939},{"batb":[[0,1.85,4],[1,1.82,128.18],[2,1.5,94.99]],"batl":[[0,2.28,2.2],[1,2.3,3],[2,4.4,3.34]],"ltp":1.92,"tv":367.93,"id":8681938}]}]}
{"op":"mcm","clk":"4296607192","pt":1632569153182,"mc":[{"id":"1.188134680","rc":[{"batl":[[0,2.02,3],[1,4.4,3.54],[2,4.4,0]],"ltp":1.92,"tv":367.93,"id":8681938}]}]}
{"op":"mcm","clk":"4296607220","pt":1632569153393,"mc":[{"id":"1.188134680","rc":[{"batb":[[0,1.91,113.83],[1,1.9,4],[2,1.77,4]],"batl":[[0,2.18,4],[1,5.8,2.73]],"ltp":1.95,"tv":133.12,"id":9631939},{"batb":[[1,1.84,4],[2,1.82,128.18]],"batl":[[1,2.04,4],[2,2.1,3]],"ltp":1.92,"tv":367.93,"id":8681938}]}]}
{"op":"mcm","clk":"4296607473","pt":1632569155375,"mc":[{"id":"1.188134680","rc":[{"batb":[[0,2.1,1047],[1,2.08,111.9],[2,2.06,335.71]],"ltp":1.95,"tv":133.12,"id":9631939},{"trd":[[1.88,34]],"batb":[[0,1.88,214.19],[1,1.86,342.56],[2,1.85,4]],"batl":[[0,1.94,232.24],[1,1.96,296.47],[2,2.02,3]],"ltp":1.88,"tv":400.37,"id":8681938}],"tv":533.49}]}
{"op":"mcm","clk":"4296607618","pt":1632569156377,"mc":[{"id":"1.188134680","rc":[{"batb":[[0,2.1,764.09],[2,2.06,111.9]],"batl":[[1,2.4,12.7],[2,5.8,2.54]],"ltp":1.95,"tv":133.12,"id":9631939},{"batb":[[0,1.85,4],[1,1.84,4],[2,1.82,128.18]],"ltp":1.88,"tv":400.37,"id":8681938}]}]}
{"op":"mcm","clk":"4296607862","pt":1632569158379,"mc":[{"id":"1.188134680","rc":[{"batb":[[0,1.87,390.66],[1,1.85,352.72],[2,1.84,4]],"ltp":1.88,"tv":400.37,"id":8681938}]}]}
{"op":"mcm","clk":"4296607891","pt":1632569158590,"mc":[{"id":"1.188134680","rc":[{"batl":[[2,2,3]],"ltp":1.88,"tv":400.37,"id":8681938}]}]}
{"op":"mcm","clk":"4296608121","pt":1632569160286,"mc":[{"id":"1.188134680","rc":[{"trd":[[2.1,137.14]],"batb":[[0,2.1,695.52]],"ltp":2.1,"tv":270.26,"id":9631939},{"trd":[[1.87,35.77]],"batb":[[0,1.87,372.97]],"ltp":1.87,"tv":435.75,"id":8681938}],"tv":706.01}]}
{"op":"mcm","clk":"4296608405","pt":1632569162305,"mc":[{"id":"1.188134680","rc":[{"batl":[[1,2.22,13.78],[2,2.32,167.75]],"ltp":2.1,"tv":270.26,"id":9631939},{"batl":[[2,1.97,225.91]],"ltp":1.87,"tv":435.75,"id":8681938}]}]}
{"op":"mcm","clk":"4296608442","pt":1632569162467,"mc":[{"id":"1.188134680","rc":[{"batl":[[0,1.9,124],[1,1.94,232.24],[2,1.96,296.47]],"ltp":1.87,"tv":435.75,"id":8681938}]}]}
{"op":"mcm","clk":"4296608891","pt":1632569165777,"mc":[{"id":"1.188134680","rc":[{"batb":[[2,1.82,144.74]],"batl":[[0,1.9,240]],"ltp":1.87,"tv":435.75,"id":8681938}]}]}
{"op":"mcm","clk":"4296609723","pt":1632569172186,"mc":[{"id":"1.188134680","rc":[{"trd":[[2.1,141.84]],"batb":[[0,2.1,693.17]],"ltp":2.1,"tv":274.96,"id":9631939}],"tv":710.71}]}
{"op":"mcm","clk":"4296612086","pt":1632569190255,"mc":[{"id":"1.188134680","rc":[{"batl":[[0,1.89,2.64],[1,1.9,240],[2,1.94,232.24]],"ltp":1.87,"tv":435.75,"id":8681938}]}]}
{"op":"mcm","clk":"4296612513","pt":1632569193345,"mc":[{"id":"1.188134680","rc":[{"batb":[[0,1.85,4],[1,1.82,144.74],[2,1.81,259.66]],"batl":[[1,1.9,374],[2,1.97,225.91]],"ltp":1.87,"tv":435.75,"id":8681938}]}]}
{"op":"mcm","clk":"4296614933","pt":1632569211323,"mc":[{"id":"1.188134680","rc":[{"batb":[[0,2.02,388.87],[1,2,265.07],[2,1.5,94.99]],"batl":[[0,2.22,13.78],[1,2.32,167.75],[2,2.34,167.85]],"ltp":2.1,"tv":274.96,"id":9631939},{"batb":[[0,1.82,16.56],[1,1.77,328.12],[2,1.76,217.8]],"ltp":1.87,"tv":435.75,"id":8681938}]}]}
{"op":"mcm","clk":"4296615082","pt":1632569212334,"mc":[{"id":"1.188134680","rc":[{"batb":[[0,2.02,374.17]],"batl":[[0,2.32,167.94],[1,2.34,167.85],[2,5.8,2.54]],"ltp":2.1,"tv":274.96,"id":9631939},{"batb":[[0,1.77,328.12],[1,1.76,217.8],[2,1.75,716.39]],"batl":[[1,1.97,225.91],[2,1.98,246.4]],"ltp":1.87,"tv":435.75,"id":8681938}]}]}
{"op":"mcm","clk":"4296615325","pt":1632569214096,"mc":[{"id":"1.188134680","rc":[{"trd":[[1.89,5.27]],"batb":[[0,1.89,14.68],[1,1.77,328.12],[2,1.76,217.8]],"batl":[[0,1.97,225.91],[1,1.98,246.4],[2,1.99,225.66]],"ltp":1.89,"tv":441.02,"id":8681938}],"tv":715.98}]}
{"op":"mcm","clk":"4296615502","pt":1632569215489,"mc":[{"id":"1.188134680","rc":[{"batl":[[0,2.3,2.2],[1,2.32,167.75],[2,2.34,167.85]],"ltp":2.1,"tv":274.96,"id":9631939},{"batb":[[1,1.77,331.12],[2,1.76,220.8]],"ltp":1.89,"tv":441.02,"id":8681938}]}]}
{"op":"mcm","clk":"4296615743","pt":1632569217292,"mc":[{"id":"1.188134680","rc":[{"batl":[[0,1.97,228.91]],"ltp":1.89,"tv":441.02,"id":8681938}]}]}
{"op":"mcm","clk":"4296615788","pt":1632569217612,"mc":[{"id":"1.188134680","rc":[{"batb":[[0,2.02,181.02],[1,2,3]],"ltp":2.1,"tv":274.96,"id":9631939},{"batl":[[0,1.97,3],[1,2,3],[2,4.4,3.54]],"ltp":1.89,"tv":441.02,"id":8681938}]}]}
{"op":"mcm","clk":"4296616107","pt":1632569220322,"mc":[{"id":"1.188134680","rc":[{"trd":[[2.2,0.2],[2.3,95.3]],"batl":[[0,2.32,167.75],[1,2.34,167.85],[2,2.46,12.14]],"ltp":2.3,"tv":370.45,"id":9631939},{"trd":[[1.77,152.74],[1.83,0.23],[1.89,34.63]],"batb":[[0,1.77,195.43],[1,1.76,220.8],[2,1.75,716.39]],"batl":[[0,1.78,1320.22],[1,1.79,2857.73],[2,1.8,660.12]],"ltp":1.77,"tv":623.35,"id":8681938}],"tv":993.8}]}
{"op":"mcm","clk":"4296616264","pt":1632569221333,"mc":[{"id":"1.188134680","rc":[{"batb":[[0,2.14,13.15],[1,2.02,181.02],[2,2,3]],"batl":[[0,2.34,167.85],[1,2.42,12.58]],"ltp":2.3,"tv":370.45,"id":9631939},{"batb":[[0,1.77,192.43],[1,1.75,418.66],[2,1.71,155.4]],"batl":[[0,1.78,264.04],[1,1.79,571.54],[2,1.8,132.02]],"ltp":1.77,"tv":623.35,"id":8681938}]}]}
{"op":"mcm","clk":"4296616414","pt":1632569222203,"mc":[{"id":"1.188134680","rc":[{"batb":[[0,2.26,133.84],[1,2.16,152.36],[2,2.14,13.15]],"ltp":2.3,"tv":370.45,"id":9631939}]}]}
{"op":"mcm","clk":"4296616681","pt":1632569224010,"mc":[{"id":"1.188134680","rc":[{"batb":[[2,2.14,17.15]],"ltp":2.3,"tv":370.45,"id":9631939},{"batb":[[0,1.77,251.79]],"ltp":1.77,"tv":623.35,"id":8681938}]}]}
{"op":"mcm","clk":"4296616885","pt":1632569225336,"mc":[{"id":"1.188134680","rc":[{"batb":[[1,2.16,359.98]],"batl":[[2,2.46,78.81]],"ltp":2.3,"tv":370.45,"id":9631939},{"trd":[[1.77,186.9]],"batb":[[0,1.77,234.71]],"batl":[[0,1.78,663.04]],"ltp":1.77,"tv":657.51,"id":8681938}],"tv":1027.96}]}
{"op":"mcm","clk":"4296616950","pt":1632569225809,"mc":[{"id":"1.188134680","rc":[{"batl":[[2,2.46,12.14]],"ltp":2.3,"tv":370.45,"id":9631939}]}]}
{"op":"mcm","clk":"4296617118","pt":1632569227028,"mc":[{"id":"1.188134680","rc":[{"batb":[[1,2.16,152.36],[2,2.14,4]],"ltp":2.3,"tv":370.45,"id":9631939}]}]}
{"op":"mcm","clk":"4296617237","pt":1632569228032,"mc":[{"id":"1.188134680","rc":[{"batb":[[1,2.16,347.63],[2,2.14,224.61]],"ltp":2.3,"tv":370.45,"id":9631939},{"trd":[[1.78,0.38]],"batl":[[0,1.78,662.85]],"ltp":1.78,"tv":657.89,"id":8681938}],"tv":1028.35}]}
{"op":"mcm","clk":"4296617494","pt":1632569230215,"mc":[{"id":"1.188134680","rc":[{"batb":[[1,2.18,12.71],[2,2.16,347.63]],"ltp":2.3,"tv":370.45,"id":9631939}]}]}
{"op":"mcm","clk":"4296617529","pt":1632569230529,"mc":[{"id":"1.188134680","rc":[{"batl":[[2,2.56,11.72]],"ltp":2.3,"tv":370.45,"id":9631939}]}]}
{"op":"mcm","clk":"4296617874","pt":1632569233265,"mc":[{"id":"1.188134680","rc":[{"trd":[[1.78,12.1]],"batl":[[0,1.78,656.99]],"ltp":1.78,"tv":669.61,"id":8681938}],"tv":1040.07}]}
{"op":"mcm","clk":"4296617975","pt":1632569233842,"mc":[{"id":"1.188134680","rc":[{"trd":[[2.3,106.04]],"ltp":2.3,"tv":381.19,"id":9631939},{"trd":[[1.77,200.86],[1.78,19.35]],"batb":[[0,1.77,220.75],[2,1.72,10.14]],"batl":[[0,1.78,653.37]],"ltp":1.78,"tv":690.81,"id":8681938}],"tv":1072.01}]}
{"op":"mcm","clk":"4296618663","pt":1632569239075,"mc":[{"id":"1.188134680","rc":[{"batb":[[0,2.18,12.71],[1,2.16,347.63],[2,2.14,220.61]],"batl":[[0,2.42,12.58],[1,2.58,133.98],[2,2.6,183.28]],"ltp":2.3,"tv":381.19,"id":9631939},{"batb":[[0,1.63,252.71],[1,1.62,324.49],[2,1.58,205.12]],"batl":[[0,1.87,219.13],[1,1.88,276.07],[2,1.97,3]],"ltp":1.78,"tv":690.81,"id":8681938}]}]}
{"op":"mcm","clk":"4296618799","pt":1632569240363,"mc":[{"id":"1.188134680","rc":[{"batb":[[0,2.16,347.63],[1,2.14,220.61],[2,2.12,4]],"batl":[[0,2.58,133.98],[1,2.6,183.28],[2,5.8,2.54]],"ltp":2.3,"tv":381.19,"id":9631939}]}]}
{"op":"mcm","clk":"4296618949","pt":1632569241371,"mc":[{"id":"1.188134680","rc":[{"batl":[[0,5.8,2.54],[1,2.6,0],[2,5.8,0]],"ltp":2.3,"tv":381.19,"id":9631939},{"batb":[[0,1.58,205.12],[1,1.4,131.93],[2,1.3,175.9]],"ltp":1.78,"tv":690.81,"id":8681938}]}]}
{"op":"mcm","clk":"4296619073","pt":1632569242273,"mc":[{"id":"1.188134680","rc":[{"batb":[[0,1.71,17.8],[1,1.58,205.12],[2,1.4,131.93]],"batl":[[0,1.85,15],[1,1.87,219.13],[2,1.88,276.07]],"ltp":1.78,"tv":690.81,"id":8681938}]}]}
{"op":"mcm","clk":"4296619107","pt":1632569242544,"mc":[{"id":"1.188134680","rc":[{"batb":[[0,1.58,205.12],[1,1.4,131.93],[2,1.3,175.9]],"batl":[[0,1.87,219.13],[1,1.88,276.07],[2,1.9,353.78]],"ltp":1.78,"tv":690.81,"id":8681938}]}]}
{"op":"mcm","clk":"4296619400","pt":1632569244353,"mc":[{"id":"1.188134680","rc":[{"batb":[[0,2.16,226.78],[2,1.6,87.96]],"batl":[[0,2.24,14.11],[1,2.44,12.3],[2,5.8,2.54]],"ltp":2.3,"tv":381.19,"id":9631939},{"batb":[[0,1.82,774.72],[1,1.81,387.36],[2,1.8,387.36]],"batl":[[0,1.86,11.6]],"ltp":1.78,"tv":690.81,"id":8681938}]}]}
{"op":"mcm","clk":"4296619551","pt":1632569245359,"mc":[{"id":"1.188134680","rc":[{"batb":[[2,2.06,172.74]],"batl":[[0,2.44,12.3],[1,5.8,2.54],[2,5.8,0]],"ltp":2.3,"tv":381.19,"id":9631939},{"trd":[[1.83,33.01]],"batb":[[0,1.83,327.03],[1,1.82,258.24],[2,1.81,503.63]],"batl":[[0,1.88,276.07],[1,1.9,353.78],[2,1.92,1539.72]],"ltp":1.83,"tv":723.59,"id":8681938}],"tv":1104.79}]}
{"op":"mcm","clk":"4296619671","pt":1632569246264,"mc":[{"id":"1.188134680","rc":[{"batb":[[2,2.08,13.88]],"batl":[[0,2.32,13.05],[1,2.44,12.3],[2,5.8,2.54]],"ltp":2.3,"tv":381.19,"id":9631939},{"batl":[[2,1.92,560.56]],"ltp":1.83,"tv":723.59,"id":8681938}]}]}
{"op":"mcm","clk":"4296619737","pt":1632569246778,"mc":[{"id":"1.188134680","rc":[{"batl":[[2,2.56,4]],"ltp":2.3,"tv":381.19,"id":9631939}]}]}
{"op":"mcm","clk":"4296619900","pt":1632569248046,"mc":[{"id":"1.188134680","rc":[{"batl":[[0,2.24,14.11],[1,2.32,13.05],[2,2.44,12.3]],"ltp":2.3,"tv":381.19,"id":9631939},{"batl":[[0,1.86,11.6],[1,1.88,276.07],[2,1.9,353.78]],"ltp":1.83,"tv":723.59,"id":8681938}]}]}
{"op":"mcm","clk":"4296620055","pt":1632569249250,"mc":[{"id":"1.188134680","rc":[{"batl":[[1,2.32,77.06]],"ltp":2.3,"tv":381.19,"id":9631939},{"trd":[[1.83,53.89]],"batb":[[0,1.83,316.59]],"batl":[[0,1.86,158.6]],"ltp":1.83,"tv":744.47,"id":8681938}],"tv":1125.67}]}
{"op":"mcm","clk":"4296620137","pt":1632569249880,"mc":[{"id":"1.188134680","rc":[{"batl":[[0,2.22,180.85],[1,2.24,14.11],[2,2.32,13.05]],"ltp":2.3,"tv":381.19,"id":9631939},{"batb":[[2,1.81,725.44]],"ltp":1.83,"tv":744.47,"id":8681938}]}]}
{"op":"mcm","clk":"4296620362","pt":1632569251569,"mc":[{"id":"1.188134680","rc":[{"batl":[[1,2.24,183.82]],"ltp":2.3,"tv":381.19,"id":9631939},{"batl":[[0,1.86,243.6]],"ltp":1.83,"tv":744.47,"id":8681938}]}]}
{"op":"mcm","clk":"4296620496","pt":1632569252689,"mc":[{"id":"1.188134680","rc":[{"batl":[[2,2.36,166.41]],"ltp":2.3,"tv":381.19,"id":9631939}]}]}
{"op":"mcm","clk":"4296620883","pt":1632569255904,"mc":[{"id":"1.188134680","rc":[{"batl":[[2,2.3,13.15]],"ltp":2.3,"tv":381.19,"id":9631939}]}]}
{"op":"mcm","clk":"4296621150","pt":1632569257881,"mc":[{"id":"1.188134680","rc":[{"batb":[[0,2.08,13.88],[1,2.06,172.74],[2,2.02,202.62]],"batl":[[0,2.3,13.15],[1,2.36,166.41],[2,2.38,187.08]],"ltp":2.3,"tv":381.19,"id":9631939},{"batb":[[0,1.77,17.09],[1,1.74,182.03],[2,1.73,297.22]],"batl":[[0,1.86,232],[1,1.93,15],[2,1.97,3]],"ltp":1.83,"tv":744.47,"id":8681938}]}]}
{"op":"mcm","clk":"4296621340","pt":1632569259296,"mc":[{"id":"1.188134680","rc":[{"batb":[[0,2.06,172.74],[1,2.02,202.62],[2,2,207.42]],"batl":[[0,2.36,166.41],[1,2.38,187.08],[2,2.56,4]],"ltp":2.3,"tv":381.19,"id":9631939},{"batb":[[0,1.74,182.03],[1,1.73,297.22],[2,1.66,175.36]],"batl":[[0,1.97,3],[1,1.98,173.88],[2,1.99,257.74]],"ltp":1.83,"tv":744.47,"id":8681938}]}]}
{"op":"mcm","clk":"4296621573","pt":1632569261378,"mc":[{"id":"1.188134680","rc":[{"batb":[[2,1.71,255.86]],"batl":[[0,1.96,293.48],[1,1.97,3],[2,1.98,461.54]],"ltp":1.83,"tv":744.47,"id":8681938}]}]}
{"op":"mcm","clk":"4296621752","pt":1632569262599,"mc":[{"id":"1.188134680","rc":[{"batb":[[0,2.06,176.74],[1,2.04,4],[2,2.02,202.62]],"batl":[[0,2.56,4],[1,5.8,2.54],[2,2.56,0]],"ltp":2.3,"tv":381.19,"id":9631939},{"batb":[[0,1.66,175.36],[1,1.64,5],[2,1.4,131.93]],"batl":[[0,1.95,4],[1,1.96,293.48],[2,1.97,3]],"ltp":1.83,"tv":744.47,"id":8681938}]}]}
{"op":"mcm","clk":"4296622088","pt":1632569265304,"mc":[{"id":"1.188134680","rc":[{"batb":[[0,2.06,252.43]],"batl":[[0,2.2,104.66],[1,2.32,12.93],[2,2.56,4]],"ltp":2.3,"tv":381.19,"id":9631939},{"batb":[[0,1.89,4585.38],[1,1.87,2045.46],[2,1.86,1985.3]],"ltp":1.83,"tv":744.47,"id":8681938}]}]}
{"op":"mcm","clk":"4296622234","pt":1632569266317,"mc":[{"id":"1.188134680","rc":[{"trd":[[2.08,0.39]],"batb":[[0,2.06,248.43],[1,2.02,202.62],[2,2,207.42]],"batl":[[0,2.12,11.06],[1,2.2,104.27],[2,2.32,12.93]],"ltp":2.08,"tv":381.58,"id":9631939},{"trd":[[1.92,64.38]],"batb":[[0,1.89,670.38],[1,1.87,848.34],[2,1.86,496.32]],"batl":[[0,1.9,15.37],[1,1.94,9.88],[2,1.96,293.48]],"ltp":1.92,"tv":744.89,"id":8681938}],"tv":1126.48}]}
{"op":"mcm","clk":"4296622408","pt":1632569267383,"mc":[{"id":"1.188134680","rc":[{"batb":[[1,2.02,387.2],[2,2,222.42]],"batl":[[2,2.22,13.58]],"ltp":2.08,"tv":381.58,"id":9631939}]}]}
{"op":"mcm","clk":"4296622592","pt":1632569268493,"mc":[{"id":"1.188134680","rc":[{"batl":[[1,2.18,3],[2,2.2,104.27]],"ltp":2.08,"tv":381.58,"id":9631939}]}]}
{"op":"mcm","clk":"4296622790","pt":1632569270314,"mc":[{"id":"1.188134680","rc":[{"trd":[[1.89,56.39]],"batb":[[0,1.89,659.5]],"ltp":1.89,"tv":766.65,"id":8681938}],"tv":1148.24}]}
{"op":"mcm","clk":"4296622848","pt":1632569270794,"mc":[{"id":"1.188134680","rc":[{"trd":[[1.89,678.03]],"batb":[[0,1.89,348.68]],"ltp":1.89,"tv":1388.29,"id":8681938}],"tv":1769.88}]}
{"op":"mcm","clk":"4296623073","pt":1632569272486,"mc":[{"id":"1.188134680","rc":[{"batl":[[0,1.9,247.37]],"ltp":1.89,"tv":1388.29,"id":8681938}]}]}
{"op":"mcm","clk":"4296623245","pt":1632569273807,"mc":[{"id":"1.188134680","rc":[{"batl":[[2,2.2,117.96]],"ltp":2.08,"tv":381.58,"id":9631939}]}]}
{"op":"mcm","clk":"4296623497","pt":1632569275690,"mc":[{"id":"1.188134680","rc":[{"batl":[[0,1.9,407.37]],"ltp":1.89,"tv":1388.29,"id":8681938}]}]}
{"op":"mcm","clk":"4296623696","pt":1632569277428,"mc":[{"id":"1.188134680","rc":[{"batb":[[0,1.89,306.46]],"ltp":1.89,"tv":1388.29,"id":8681938}]}]}
{"op":"mcm","clk":"4296623921","pt":1632569279327,"mc":[{"id":"1.188134680","rc":[{"batb":[[0,2.06,172.74],[1,2.02,184.57],[2,2,15]],"batl":[[0,2.18,3],[1,2.2,13.69],[2,2.24,204.16]],"ltp":2.08,"tv":381.58,"id":9631939},{"batb":[[1,1.87,592.66],[2,1.86,248.16]],"batl":[[0,1.9,392],[1,1.96,293.48],[2,1.98,287.66]],"ltp":1.89,"tv":1388.29,"id":8681938}]}]}
{"op":"mcm","clk":"4296623973","pt":1632569279705,"mc":[{"id":"1.188134680","rc":[{"batb":[[0,2.02,184.57],[1,2,15],[2,1.99,5]],"ltp":2.08,"tv":381.58,"id":9631939},{"batb":[[0,1.83,16.46],[1,1.81,236.22],[2,1.8,236.87]],"batl":[[1,2,15],[2,2.04,166.76]],"ltp":1.89,"tv":1388.29,"id":8681938}]}]}
{"op":"mcm","clk":"4296624198","pt":1632569281292,"mc":[{"id":"1.188134680","rc":[{"batb":[[1,1.99,5],[2,1.97,169.81]],"batl":[[0,2.24,204.16],[1,2.26,204.78],[2,2.72,246.41]],"ltp":2.08,"tv":381.58,"id":9631939},{"batb":[[0,1.81,236.22],[1,1.8,236.87],[2,1.74,148.89]],"batl":[[0,2.04,166.76],[1,2.06,181.25],[2,4.4,3.54]],"ltp":1.89,"tv":1388.29,"id":8681938}]}]}
{"op":"mcm","clk":"4296624550","pt":1632569283800,"mc":[{"id":"1.188134680","rc":[{"batb":[[0,2.02,187.57],[1,2,3],[2,1.99,5]],"ltp":2.08,"tv":381.58,"id":9631939},{"batl":[[0,1.99,4],[1,2.04,166.76],[2,2.06,181.25]],"ltp":1.89,"tv":1388.29,"id":8681938}]}]}
{"op":"mcm","clk":"4296624684","pt":1632569284908,"mc":[{"id":"1.188134680","rc":[{"batb":[[0,1.87,300.24],[1,1.85,348.79],[2,1.81,236.22]],"batl":[[0,1.94,329.64],[1,1.96,296.57],[2,1.99,4]],"ltp":1.89,"tv":1388.29,"id":8681938}]}]}
{"op":"mcm","clk":"4296625333","pt":1632569290302,"mc":[{"id":"1.188134680","rc":[{"trd":[[1.94,39.44]],"batl":[[0,1.94,309.92]],"ltp":1.94,"tv":1427.73,"id":8681938}],"tv":1809.32}]}
{"op":"mcm","clk":"4296625356","pt":1632569290511,"mc":[{"id":"1.188134680","rc":[{"batb":[[0,1.81,236.22],[1,1.8,236.87],[2,1.74,148.89]],"batl":[[0,1.99,4],[1,2.04,166.76],[2,2.06,181.25]],"ltp":1.94,"tv":1427.73,"id":8681938}]}]}
{"op":"mcm","clk":"4296625835","pt":1632569294301,"mc":[{"id":"1.188134680","rc":[{"batb":[[2,1.79,363.74]],"batl":[[1,2.02,427.24],[2,2.04,429.97]],"ltp":1.94,"tv":1427.73,"id":8681938}]}]}
{"op":"mcm","clk":"4296626661","pt":1632569302230,"mc":[{"id":"1.188134680","rc":[{"batl":[[0,2.72,246.41],[1,5.8,2.54],[2,2.72,0]],"ltp":2.08,"tv":381.58,"id":9631939},{"batb":[[0,1.74,148.89],[1,1.67,5],[2,1.4,131.93]],"ltp":1.94,"tv":1427.73,"id":8681938}]}]}
{"op":"mcm","clk":"4296626778","pt":1632569303122,"mc":[{"id":"1.188134680","rc":[{"batb":[[0,2.02,3],[1,1.97,169.81],[2,1.96,225.75]],"ltp":2.08,"tv":381.58,"id":9631939}]}]}
{"op":"mcm","clk":"4296626888","pt":1632569304121,"mc":[{"id":"1.188134680","rc":[{"batb":[[0,1.97,169.81],[1,1.96,225.75],[2,1.67,418.02]],"batl":[[0,5.8,2.54],[1,5.8,0]],"ltp":2.08,"tv":381.58,"id":9631939},{"batl":[[0,2.02,427.24],[1,2.04,429.97],[2,2.06,181.25]],"ltp":1.94,"tv":1427.73,"id":8681938}]}]}
{"op":"mcm","clk":"4296627030","pt":1632569305349,"mc":[{"id":"1.188134680","rc":[{"batb":[[2,1.93,495.46]],"batl":[[0,2.04,11.5],[1,2.12,122.65],[2,2.24,13.39]],"ltp":2.08,"tv":381.58,"id":9631939},{"batb":[[0,1.94,234.81],[1,1.93,4757.76],[2,1.92,808.05]],"batl":[[0,2.02,531.94]],"ltp":1.94,"tv":1427.73,"id":8681938}]}]}
{"op":"mcm","clk":"4296627158","pt":1632569306336,"mc":[{"id":"1.188134680","rc":[{"trd":[[2.02,15.04],[2.04,11.31]],"batb":[[0,2,186.18],[1,1.98,195.23],[2,1.97,169.81]],"batl":[[0,2.12,122.65],[1,2.16,13.92]],"ltp":2.04,"tv":393.08,"id":9631939},{"trd":[[1.96,11.77],[1.98,15.34]],"batb":[[1,1.93,377.6]],"batl":[[0,1.95,3.42],[1,2.02,531.94],[2,2.04,429.97]],"ltp":1.96,"tv":1439.69,"id":8681938}],"tv":1832.78}]}
{"op":"mcm","clk":"4296627625","pt":1632569310230,"mc":[{"id":"1.188134680","rc":[{"batl":[[1,2.24,13.39],[2,2.34,3]],"ltp":2.04,"tv":393.08,"id":9631939},{"trd":[[1.95,6.84]],"batb":[[0,1.94,235.72]],"batl":[[0,2.02,531.94],[1,2.04,429.97],[2,2.06,195.81]],"ltp":1.95,"tv":1446.53,"id":8681938}],"tv":1839.62}]}
{"op":"mcm","clk":"4296627666","pt":1632569310544,"mc":[{"id":"1.188134680","rc":[{"batb":[[0,1.95,5.24],[1,1.94,234.81],[2,1.93,377.6]],"ltp":1.95,"tv":1446.53,"id":8681938}]}]}
{"op":"mcm","clk":"4296627861","pt":1632569312126,"mc":[{"id":"1.188134680","rc":[{"batl":[[0,2.02,72.4],[1,2.1,201.52],[2,2.12,356.82]],"ltp":2.04,"tv":393.08,"id":9631939}]}]}
{"op":"mcm","clk":"4296628372","pt":1632569316152,"mc":[{"id":"1.188134680","rc":[{"batl":[[0,2.02,623.64]],"ltp":1.95,"tv":1446.53,"id":8681938}]}]}
{"op":"mcm","clk":"4296628514","pt":1632569317360,"mc":[{"id":"1.188134680","rc":[{"batl":[[0,2.1,201.52],[1,2.12,356.82],[2,2.14,14.04]],"ltp":2.04,"tv":393.08,"id":9631939},{"batb":[[2,1.92,808.05]],"ltp":1.95,"tv":1446.53,"id":8681938}]}]}
{"op":"mcm","clk":"4296628542","pt":1632569317572,"mc":[{"id":"1.188134680","rc":[{"batl":[[0,2.06,168],[1,2.1,201.52],[2,2.12,356.82]],"ltp":2.04,"tv":393.08,"id":9631939},{"batb":[[1,1.94,413.19]],"ltp":1.95,"tv":1446.53,"id":8681938}]}]}
{"op":"mcm","clk":"4296628736","pt":1632569319255,"mc":[{"id":"1.188134680","rc":[{"batb":[[0,2,500.18]],"batl":[[0,2.06,175.67]],"ltp":2.04,"tv":393.08,"id":9631939},{"batl":[[0,1.98,7.97],[1,2.02,623.64],[2,2.04,429.97]],"ltp":1.95,"tv":1446.53,"id":8681938}]}]}
{"op":"mcm","clk":"4296628769","pt":1632569319469,"mc":[{"id":"1.188134680","rc":[{"batb":[[0,2,186.18]],"ltp":2.04,"tv":393.08,"id":9631939}]}]}
{"op":"mcm","clk":"4296628888","pt":1632569320468,"mc":[{"id":"1.188134680","rc":[{"trd":[[2,176.9],[2.02,22.85]],"batb":[[0,2,121.59]],"ltp":2.0,"tv":530.07,"id":9631939},{"trd":[[1.98,23.31]],"batl":[[0,2.02,623.64],[1,2.04,429.97],[2,2.06,195.81]],"ltp":1.98,"tv":1454.5,"id":8681938}],"tv":1984.58}]}
{"op":"mcm","clk":"4296629203","pt":1632569322857,"mc":[{"id":"1.188134680","rc":[{"batb":[[0,2,121.78]],"ltp":2.0,"tv":530.07,"id":9631939}]}]}
{"op":"mcm","clk":"4296629389","pt":1632569324186,"mc":[{"id":"1.188134680","rc":[{"batb":[[2,1.94,235.27]],"batl":[[0,2.1,201.52],[1,2.12,234.17],[2,2.14,14.04]],"ltp":2.0,"tv":530.07,"id":9631939},{"batb":[[1,1.94,234.81],[2,1.92,310.01]],"batl":[[0,2.02,427.24],[1,2.04,263.21],[2,2.06,14.56]],"ltp":1.98,"tv":1454.5,"id":8681938}]}]}
{"op":"mcm","clk":"4296629554","pt":1632569325381,"mc":[{"id":"1.188134680","rc":[{"trd":[[2,318.18],[2.02,23.22]],"batb":[[0,1.98,195.23],[1,1.94,219.8],[2,1.93,215.47]],"batl":[[2,2.34,3]],"ltp":2.0,"tv":671.73,"id":9631939},{"batb":[[1,1.91,236.1],[2,1.9,190.99]],"batl":[[0,2.04,263.21],[1,2.08,211.64],[2,2.1,216.73]],"ltp":1.98,"tv":1454.5,"id":8681938}],"tv":2126.23}]}
{"op":"mcm","clk":"4296629851","pt":1632569327381,"mc":[{"id":"1.188134680","rc":[{"batl":[[0,2.04,303.16],[1,2.06,255.87],[2,2.08,211.64]],"ltp":1.98,"tv":1454.5,"id":8681938}]}]}
{"op":"mcm","clk":"4296629952","pt":1632569328278,"mc":[{"id":"1.188134680","rc":[{"batb":[[0,1.98,199.23],[1,1.97,3],[2,1.94,219.8]],"batl":[[0,2.34,3],[1,2.5,280.07],[2,5.8,2.54]],"ltp":2.0,"tv":671.73,"id":9631939},{"batb":[[1,1.87,373.11],[2,1.85,348.83]],"batl":[[0,2,5],[1,2.04,306.16],[2,2.06,255.87]],"ltp":1.98,"tv":1454.5,"id":8681938}]}]}
{"op":"mcm","clk":"4296630070","pt":1632569329284,"mc":[{"id":"1.188134680","rc":[{"batb":[[0,1.97,3],[1,1.94,219.8],[2,1.93,215.47]],"ltp":2.0,"tv":671.73,"id":9631939},{"batb":[[1,1.84,126.66],[2,1.75,5]],"batl":[[0,2.04,306.16],[1,2.06,255.87],[2,2.08,211.64]],"ltp":1.98,"tv":1454.5,"id":8681938}]}]}
{"op":"mcm","clk":"4296630192","pt":1632569330283,"mc":[{"id":"1.188134680","rc":[{"batb":[[0,1.94,219.8],[1,1.93,215.47],[2,1.67,418.02]],"ltp":2.0,"tv":671.73,"id":9631939},{"batl":[[0,2.04,303.16]],"ltp":1.98,"tv":1454.5,"id":8681938}]}]}
{"op":"mcm","clk":"4296630316","pt":1632569331383,"mc":[{"id":"1.188134680","rc":[{"batl":[[0,2,5.92],[1,2.02,395.01],[2,2.04,70.31]],"ltp":2.0,"tv":671.73,"id":9631939},{"batb":[[0,2,5.92],[1,1.99,236.18],[2,1.98,118.1]],"batl":[[1,2.06,337.92]],"ltp":1.98,"tv":1454.5,"id":8681938}]}]}
{"op":"mcm","clk":"4296630437","pt":1632569332280,"mc":[{"id":"1.188134680","rc":[{"batb":[[0,1.97,199.2],[1,1.94,219.8],[2,1.93,215.47]],"batl":[[0,2.02,395.01],[1,2.04,70.31],[2,2.08,14.43]],"ltp":2.0,"tv":671.73,"id":9631939},{"trd":[[1.99,42.4]],"batb":[[0,1.99,221.1],[1,1.98,118.1],[2,1.97,224.63]],"batl":[[1,2.06,325.95]],"ltp":1.99,"tv":1484.66,"id":8681938}],"tv":2156.39}]}
{"op":"mcm","clk":"4296630717","pt":1632569334470,"mc":[{"id":"1.188134680","rc":[{"batl":[[0,2,5.92],[1,2.02,395.01],[2,2.04,70.31]],"ltp":2.0,"tv":671.73,"id":9631939},{"batb":[[0,2,5.92],[1,1.99,221.1],[2,1.98,118.1]],"batl":[[1,2.06,337.92]],"ltp":1.99,"tv":1484.66,"id":8681938}]}]}
{"op":"mcm","clk":"4296630917","pt":1632569336187,"mc":[{"id":"1.188134680","rc":[{"batl":[[0,2.02,3.3],[1,2.04,303.16],[2,2.06,337.92]],"ltp":1.99,"tv":1484.66,"id":8681938}]}]}
{"op":"mcm","clk":"4296631649","pt":1632569341605,"mc":[{"id":"1.188134680","rc":[{"batb":[[0,1.98,492],[1,1.97,199.2],[2,1.94,219.8]],"ltp":2.0,"tv":671.73,"id":9631939}]}]}
{"op":"mcm","clk":"4296631931","pt":1632569343478,"mc":[{"id":"1.188134680","rc":[{"trd":[[2,324.1]],"batl":[[0,2.02,395.01],[1,2.04,70.31],[2,2.08,213.52]],"ltp":2.0,"tv":677.65,"id":9631939},{"trd":[[1.98,23.67],[1.99,484.6],[2,22.77]],"batb":[[0,1.98,117.92],[1,1.97,224.63],[2,1.96,334.31]],"ltp":1.98,"tv":1944.99,"id":8681938}],"tv":2622.64}]}
{"op":"mcm","clk":"4296632135","pt":1632569345004,"mc":[{"id":"1.188134680","rc":[{"batl":[[0,2.02,598.51]],"ltp":2.0,"tv":677.65,"id":9631939},{"batb":[[0,1.99,206.57],[1,1.98,117.92],[2,1.97,224.63]],"ltp":1.98,"tv":1944.99,"id":8681938}]}]}
{"op":"mcm","clk":"4296632427","pt":1632569347416,"mc":[{"id":"1.188134680","rc":[{"batb":[[2,1.96,294.39]],"ltp":2.0,"tv":677.65,"id":9631939},{"batl":[[1,2.04,586.01]],"ltp":1.98,"tv":1944.99,"id":8681938}]}]}
{"op":"mcm","clk":"4296632771","pt":1632569350642,"mc":[{"id":"1.188134680","rc":[{"trd":[[1.99,493.46]],"batb":[[0,1.99,202.13]],"ltp":1.99,"tv":1953.85,"id":8681938}],"tv":2631.5}]}
{"op":"mcm","clk":"4296633136","pt":1632569353583,"mc":[{"id":"1.188134680","rc":[{"batl":[[2,2.06,325.95]],"ltp":1.99,"tv":1953.85,"id":8681938}]}]}
{"op":"mcm","clk":"4296633510","pt":1632569356289,"mc":[{"id":"1.188134680","rc":[{"batl":[[1,2.04,261.64]],"ltp":2.0,"tv":677.65,"id":9631939},{"batb":[[0,1.98,315.06],[1,1.97,224.63],[2,1.96,334.31]],"ltp":1.99,"tv":1953.85,"id":8681938}]}]}
{"op":"mcm","clk":"4296633544","pt":1632569356603,"mc":[{"id":"1.188134680","rc":[{"batl":[[0,2.02,606.65]],"ltp":2.0,"tv":677.65,"id":9631939},{"batl":[[0,2.02,11.43]],"ltp":1.99,"tv":1953.85,"id":8681938}]}]}
{"op":"mcm","clk":"4296633869","pt":1632569359194,"mc":[{"id":"1.188134680","rc":[{"batb":[[2,1.9,15.81]],"batl":[[0,2.08,213.52],[1,2.1,225],[2,2.34,3]],"ltp":2.0,"tv":677.65,"id":9631939},{"batb":[[0,1.97,106.53],[1,1.93,217.81],[2,1.92,195.02]],"batl":[[0,2.02,3.3],[1,2.12,14.17],[2,2.2,202.6]],"ltp":1.99,"tv":1953.85,"id":8681938}]}]}
{"op":"mcm","clk":"4296634004","pt":1632569360310,"mc":[{"id":"1.188134680","rc":[{"batb":[[0,1.84,123.53],[1,1.83,180.64],[2,1.82,196.76]],"batl":[[0,2.08,199.09]],"ltp":2.0,"tv":677.65,"id":9631939},{"batb":[[0,1.93,202.26],[1,1.92,195.02],[2,1.91,115.41]],"batl":[[1,2.2,202.6],[2,2.22,186.11]],"ltp":1.99,"tv":1953.85,"id":8681938}]}]}
{"op":"mcm","clk":"4296634056","pt":1632569360704,"mc":[{"id":"1.188134680","rc":[{"batl":[[0,1.99,6.04],[1,2.02,3.3],[2,2.2,202.6]],"ltp":1.99,"tv":1953.85,"id":8681938}]}]}
{"op":"mcm","clk":"4296634261","pt":1632569362236,"mc":[{"id":"1.188134680","rc":[{"batb":[[2,1.91,442.8]],"batl":[[2,2.18,240.37]],"ltp":1.99,"tv":1953.85,"id":8681938}]}]}
{"op":"mcm","clk":"4296634645","pt":1632569365427,"mc":[{"id":"1.188134680","rc":[{"batb":[[0,1.94,5],[1,1.93,206.26],[2,1.92,195.02]],"ltp":1.99,"tv":1953.85,"id":8681938}]}]}
{"op":"mcm","clk":"4296635584","pt":1632569373213,"mc":[{"id":"1.188134680","rc":[{"batb":[[1,1.67,418.02],[2,1.5,94.99]],"ltp":2.0,"tv":677.65,"id":9631939},{"batl":[[2,4.4,3.54]],"ltp":1.99,"tv":1953.85,"id":8681938}]}]}
{"op":"mcm","clk":"4296635621","pt":1632569373421,"mc":[{"id":"1.188134680","rc":[{"batb":[[0,1.93,202.26],[1,1.92,195.02],[2,1.91,442.8]],"ltp":1.99,"tv":1953.85,"id":8681938}]}]}
{"op":"mcm","clk":"4296635862","pt":1632569375120,"mc":[{"id":"1.188134680","rc":[{"trd":[[1.99,496.2]],"batl":[[0,1.99,4.67],[1,4.4,3.54],[2,4.4,0]],"ltp":1.99,"tv":1956.59,"id":8681938}],"tv":2634.24}]}
{"op":"mcm","clk":"4296636022","pt":1632569376355,"mc":[{"id":"1.188134680","rc":[{"batl":[[0,2.1,225],[1,2.12,13.37],[2,2.16,130.09]],"ltp":2.0,"tv":677.65,"id":9631939},{"trd":[[1.93,31.08]],"batb":[[0,1.92,195.02],[1,1.91,442.8],[2,1.89,325.69]],"batl":[[0,1.94,7.4],[1,1.98,470.7],[2,1.99,4.67]],"ltp":1.93,"tv":1987.67,"id":8681938}],"tv":2665.32}]}
{"op":"mcm","clk":"4296636141","pt":1632569377267,"mc":[{"id":"1.188134680","rc":[{"batb":[[0,2.02,183.64],[1,1.96,15.3],[2,1.91,108.99]],"batl":[[2,2.16,144.01]],"ltp":2.0,"tv":677.65,"id":9631939}]}]}
{"op":"mcm","clk":"4296636255","pt":1632569378157,"mc":[{"id":"1.188134680","rc":[{"batl":[[1,1.95,3.42],[2,1.98,470.7]],"ltp":1.93,"tv":1987.67,"id":8681938}]}]}
{"op":"mcm","clk":"4296636391","pt":1632569379059,"mc":[{"id":"1.188134680","rc":[{"batb":[[1,1.97,3],[2,1.96,19.3]],"ltp":2.0,"tv":677.65,"id":9631939}]}]}
{"op":"mcm","clk":"4296636699","pt":1632569381343,"mc":[{"id":"1.188134680","rc":[{"batb":[[1,1.96,19.3],[2,1.91,108.99]],"ltp":2.0,"tv":677.65,"id":9631939}]}]}
{"op":"mcm","clk":"4296636806","pt":1632569382137,"mc":[{"id":"1.188134680","rc":[{"batl":[[0,1.94,170.4]],"ltp":1.93,"tv":1987.67,"id":8681938}]}]}
{"op":"mcm","clk":"4296636908","pt":1632569382932,"mc":[{"id":"1.188134680","rc":[{"batb":[[2,1.94,209.51]],"ltp":2.0,"tv":677.65,"id":9631939}]}]}
{"op":"mcm","clk":"4296637393","pt":1632569386325,"mc":[{"id":"1.188134680","rc":[{"batb":[[0,1.96,19.3],[1,1.94,209.51],[2,1.93,248.2]],"batl":[[0,2.16,13.92],[1,2.18,156.96],[2,2.2,176.42]],"ltp":2.0,"tv":677.65,"id":9631939},{"batb":[[0,1.87,139.36],[1,1.85,218.59],[2,1.84,246.7]],"batl":[[0,1.94,163],[2,1.99,4.67]],"ltp":1.93,"tv":1987.67,"id":8681938}]}]}
{"op":"mcm","clk":"4296637544","pt":1632569387355,"mc":[{"id":"1.188134680","rc":[{"batb":[[0,1.96,4]],"batl":[[0,2.18,156.96],[1,2.2,176.42],[2,2.34,3]],"ltp":2.0,"tv":677.65,"id":9631939},{"batb":[[0,1.87,123.28]],"batl":[[0,1.95,3.42],[1,1.99,4.67],[2,2.06,195.66]],"ltp":1.93,"tv":1987.67,"id":8681938}]}]}
{"op":"mcm","clk":"4296637580","pt":1632569387675,"mc":[{"id":"1.188134680","rc":[{"batl":[[0,1.93,4.11]],"ltp":1.93,"tv":1987.67,"id":8681938}]}]}
{"op":"mcm","clk":"4296637793","pt":1632569389329,"mc":[{"id":"1.188134680","rc":[{"batb":[[1,1.91,108.99],[2,1.67,418.02]],"ltp":2.0,"tv":677.65,"id":9631939},{"batb":[[0,1.88,221.73],[1,1.87,123.28],[2,1.86,342.54]],"batl":[[0,1.99,4.67],[1,2.02,3],[2,2.1,433.85]],"ltp":1.93,"tv":1987.67,"id":8681938}]}]}
{"op":"mcm","clk":"4296637886","pt":1632569390172,"mc":[{"id":"1.188134680","rc":[{"batb":[[2,1.86,346.54]],"batl":[[2,4.4,3.54]],"ltp":1.93,"tv":1987.67,"id":8681938}]}]}
{"op":"mcm","clk":"4296637940","pt":1632569390543,"mc":[{"id":"1.188134680","rc":[{"batl":[[0,2.18,159.96]],"ltp":2.0,"tv":677.65,"id":9631939}]}]}
{"op":"mcm","clk":"4296638204","pt":1632569392351,"mc":[{"id":"1.188134680","rc":[{"batb":[[0,2.06,171.47],[1,1.98,195.82],[2,1.96,4]],"batl":[[1,2.2,190.59]],"ltp":2.0,"tv":677.65,"id":9631939},{"trd":[[1.88,65.92]],"batb":[[0,1.87,123.28],[1,1.86,4],[2,1.85,218.59]],"batl":[[0,1.89,12.38],[1,1.9,247.36],[2,1.91,123.68]],"ltp":1.88,"tv":2019.59,"id":8681938}],"tv":2697.24}]}
{"op":"mcm","clk":"4296638353","pt":1632569393266,"mc":[{"id":"1.188134680","rc":[{"batb":[[1,2,19],[2,1.99,3]],"batl":[[2,2.22,13.58]],"ltp":2.0,"tv":677.65,"id":9631939}]}]}
{"op":"mcm","clk":"4296638455","pt":1632569393866,"mc":[{"id":"1.188134680","rc":[{"batl":[[2,1.91,127.79]],"ltp":1.88,"tv":2019.59,"id":8681938}]}]}
{"op":"mcm","clk":"4296638605","pt":1632569394768,"mc":[{"id":"1.188134680","rc":[{"batb":[[0,1.87,505.37],[2,1.85,567.29]],"batl":[[2,1.91,123.68]],"ltp":1.88,"tv":2019.59,"id":8681938}]}]}
{"op":"mcm","clk":"4296638827","pt":1632569396357,"mc":[{"id":"1.188134680","rc":[{"trd":[[1.87,50.97]],"batb":[[0,1.87,497.76]],"batl":[[0,1.88,4.11],[1,1.89,152.49],[2,1.9,247.36]],"ltp":1.87,"tv":2034.79,"id":8681938}],"tv":2712.44}]}
{"op":"mcm","clk":"4296638946","pt":1632569397148,"mc":[{"id":"1.188134680","rc":[{"batl":[[0,1.88,8.22]],"ltp":1.87,"tv":2034.79,"id":8681938}]}]}
{"op":"mcm","clk":"4296639210","pt":1632569399167,"mc":[{"id":"1.188134680","rc":[{"batb":[[1,2.04,204.36],[2,2.02,191.26]],"ltp":2.0,"tv":677.65,"id":9631939},{"trd":[[1.87,430.35]],"batb":[[0,1.87,308.08]],"ltp":1.87,"tv":2414.16,"id":8681938}],"tv":3091.81}]}
{"op":"mcm","clk":"4296639362","pt":1632569400278,"mc":[{"id":"1.188134680","rc":[{"trd":[[1.87,438.57]],"batb":[[0,1.87,303.97]],"batl":[[1,1.89,281.49]],"ltp":1.87,"tv":2422.39,"id":8681938}],"tv":3100.04}]}
{"op":"mcm","clk":"4296639776","pt":1632569402286,"mc":[{"id":"1.188134680","rc":[{"batb":[[0,1.87,337.08]],"ltp":1.87,"tv":2422.39,"id":8681938}]}]}
{"op":"mcm","clk":"4296640187","pt":1632569404292,"mc":[{"id":"1.188134680","rc":[{"trd":[[1.87,446.79]],"batb":[[0,1.87,332.97]],"ltp":1.87,"tv":2430.61,"id":8681938}],"tv":3108.26}]}
{"op":"mcm","clk":"4296640250","pt":1632569404547,"mc":[{"id":"1.188134680","rc":[{"batb":[[1,1.85,567.29],[2,1.84,376.83]],"ltp":1.87,"tv":2430.61,"id":8681938}]}]}
{"op":"mcm","clk":"4296640428","pt":1632569405495,"mc":[{"id":"1.188134680","rc":[{"batl":[[1,1.89,446.49]],"ltp":1.87,"tv":2430.61,"id":8681938}]}]}
{"op":"mcm","clk":"4296640744","pt":1632569407299,"mc":[{"id":"1.188134680","rc":[{"batl":[[1,2.2,176.42]],"ltp":2.0,"tv":677.65,"id":9631939},{"batl":[[0,1.89,430],[1,1.9,123.68],[2,1.91,61.84]],"ltp":1.87,"tv":2430.61,"id":8681938}]}]}
{"op":"mcm","clk":"4296640897","pt":1632569408299,"mc":[{"id":"1.188134680","rc":[{"batb":[[0,2.04,204.36],[1,2.02,191.26],[2,2,4]],"batl":[[0,2.18,3],[1,2.24,162.49],[2,2.26,187.04]],"ltp":2.0,"tv":677.65,"id":9631939},{"batb":[[0,1.85,256.76],[1,1.84,130.12],[2,1.81,190.76]],"batl":[[1,1.97,224.58],[2,1.98,261.38]],"ltp":1.87,"tv":2430.61,"id":8681938}]}]}
{"op":"mcm","clk":"4296640944","pt":1632569408570,"mc":[{"id":"1.188134680","rc":[{"batl":[[0,2.24,162.49],[1,2.26,187.04],[2,2.82,235.94]],"ltp":2.0,"tv":677.65,"id":9631939}]}]}
{"op":"mcm","clk":"4296641199","pt":1632569410076,"mc":[{"id":"1.188134680","rc":[{"batb":[[0,1.84,130.12],[1,1.81,190.76],[2,1.8,262.24]],"batl":[[0,1.97,224.58],[1,1.98,261.38],[2,2,4]],"ltp":1.87,"tv":2430.61,"id":8681938}]}]}
{"op":"mcm","clk":"4296641383","pt":1632569411110,"mc":[{"id":"1.188134680","rc":[{"batb":[[0,1.81,190.76],[1,1.8,394.56],[2,1.4,131.93]],"ltp":1.87,"tv":2430.61,"id":8681938}]}]}
{"op":"mcm","clk":"4296641702","pt":1632569413021,"mc":[{"id":"1.188134680","rc":[{"batb":[[0,2.04,208.36],[1,2.02,196.26]],"ltp":2.0,"tv":677.65,"id":9631939},{"batb":[[0,1.88,376.1],[1,1.86,342.76],[2,1.81,190.76]],"batl":[[0,1.95,241.25],[1,1.97,521.61],[2,1.98,261.38]],"ltp":1.87,"tv":2430.61,"id":8681938}]}]}
{"op":"mcm","clk":"4296641885","pt":1632569414206,"mc":[{"id":"1.188134680","rc":[{"batl":[[0,2.24,165.49]],"ltp":2.0,"tv":677.65,"id":9631939},{"batb":[[2,1.81,194.76]],"ltp":1.87,"tv":2430.61,"id":8681938}]}]}
{"op":"mcm","clk":"4296642189","pt":1632569415800,"mc":[{"id":"1.188134680","rc":[{"batl":[[0,2.22,4],[1,2.24,165.49],[2,2.26,187.04]],"ltp":2.0,"tv":677.65,"id":9631939},{"batb":[[2,1.82,4.79]],"ltp":1.87,"tv":2430.61,"id":8681938}]}]}
{"op":"mcm","clk":"4296642370","pt":1632569417104,"mc":[{"id":"1.188134680","rc":[{"batb":[[0,1.82,4.79],[1,1.81,194.76],[2,1.8,398.56]],"batl":[[0,1.97,229.58],[1,1.98,261.38],[2,2,4]],"ltp":1.87,"tv":2430.61,"id":8681938}]}]}
{"op":"mcm","clk":"4296643017","pt":1632569420314,"mc":[{"id":"1.188134680","rc":[{"batb":[[2,1.99,192.44]],"ltp":2.0,"tv":677.65,"id":9631939},{"batb":[[0,1.85,256.76],[1,1.83,361.03],[2,1.82,9.79]],"ltp":1.87,"tv":2430.61,"id":8681938}]}]}
{"op":"mcm","clk":"4296643134","pt":1632569421129,"mc":[{"id":"1.188134680","rc":[{"batb":[[0,2.04,4],[1,2.02,5]],"ltp":2.0,"tv":677.65,"id":9631939},{"batl":[[0,1.97,5],[1,2,4],[2,4.4,3.54]],"ltp":1.87,"tv":2430.61,"id":8681938}]}]}
{"op":"mcm","clk":"4296643562","pt":1632569422795,"mc":[{"id":"1.188134680","rc":[{"batb":[[0,2.02,5],[1,1.99,192.44],[2,1.67,418.02]],"ltp":2.0,"tv":677.65,"id":9631939},{"batb":[[2,1.82,5]],"batl":[[0,2,4],[1,4.4,3.54],[2,4.4,0]],"ltp":1.87,"tv":2430.61,"id":8681938}]}]}
{"op":"mcm","clk":"4296643838","pt":1632569424196,"mc":[{"id":"1.188134680","rc":[{"batl":[[1,2.24,173.34]],"ltp":2.0,"tv":677.65,"id":9631939},{"trd":[[1.85,32.6]],"batb":[[0,1.85,240.46]],"batl":[[0,1.86,19.17],[1,1.87,251.34],[2,1.88,125.66]],"ltp":1.85,"tv":2463.21,"id":8681938}],"tv":3140.86}]}
{"op":"mcm","clk":"4296644036","pt":1632569425299,"mc":[{"id":"1.188134680","rc":[{"batb":[[0,2.12,159.12],[1,2.06,14.15],[2,2.04,177.64]],"ltp":2.0,"tv":677.65,"id":9631939}]}]}
{"op":"mcm","clk":"4296644284","pt":1632569427207,"mc":[{"id":"1.188134680","rc":[{"batb":[[1,2.08,374.96],[2,2.06,14.15]],"ltp":2.0,"tv":677.65,"id":9631939}]}]}
{"op":"mcm","clk":"4296644310","pt":1632569427417,"mc":[{"id":"1.188134680","rc":[{"batl":[[1,2.24,170.34]],"ltp":2.0,"tv":677.65,"id":9631939}]}]}
{"op":"mcm","clk":"4296644742","pt":1632569429325,"mc":[{"id":"1.188134680","rc":[{"trd":[[1.85,45.96]],"batb":[[0,1.85,233.78]],"ltp":1.85,"tv":2476.57,"id":8681938}],"tv":3154.22}]}
{"op":"mcm","clk":"4296644841","pt":1632569429916,"mc":[{"id":"1.188134680","rc":[{"batl":[[0,1.86,214.17]],"ltp":1.85,"tv":2476.57,"id":8681938}]}]}
{"op":"mcm","clk":"4296645139","pt":1632569431115,"mc":[{"id":"1.188134680","rc":[{"batb":[[1,2.1,200.6],[2,2.08,608.66]],"batl":[[2,2.26,341.6]],"ltp":2.0,"tv":677.65,"id":9631939}]}]}
{"op":"mcm","clk":"4296645197","pt":1632569431493,"mc":[{"id":"1.188134680","rc":[{"batb":[[2,2.08,233.7]],"ltp":2.0,"tv":677.65,"id":9631939},{"trd":[[1.85,54.18]],"batb":[[0,1.85,229.67]],"ltp":1.85,"tv":2484.79,"id":8681938}],"tv":3162.44}]}
{"op":"mcm","clk":"4296645778","pt":1632569435028,"mc":[{"id":"1.188134680","rc":[{"trd":[[2.16,70.83]],"ltp":2.16,"tv":748.47,"id":9631939},{"trd":[[1.85,62.4],[1.86,83.66]],"batb":[[0,1.85,225.56]],"batl":[[0,1.86,131.92]],"ltp":1.86,"tv":2575.26,"id":8681938}],"tv":3323.74}]}
{"op":"mcm","clk":"4296645850","pt":1632569435527,"mc":[{"id":"1.188134680","rc":[{"batl":[[0,1.86,229.92]],"ltp":1.86,"tv":2575.26,"id":8681938}]}]}
{"op":"mcm","clk":"4296646434","pt":1632569439120,"mc":[{"id":"1.188134680","rc":[{"batb":[[0,2.1,200.6],[1,2.08,233.7],[2,2.06,14.15]],"batl":[[0,2.26,154.56],[1,2.28,208.34],[2,2.82,235.94]],"ltp":2.16,"tv":748.47,"id":9631939},{"batb":[[0,1.83,303.97],[1,1.82,5],[2,1.79,270.77]],"batl":[[1,1.91,192.8],[2,1.92,212.15]],"ltp":1.86,"tv":2575.26,"id":8681938}]}]}
{"op":"mcm","clk":"4296646616","pt":1632569440244,"mc":[{"id":"1.188134680","rc":[{"batb":[[2,2.04,177.64]],"batl":[[1,2.28,195.09]],"ltp":2.16,"tv":748.47,"id":9631939},{"batb":[[0,1.83,317.04],[2,1.79,253.9]],"batl":[[0,1.91,192.8],[1,1.92,212.15],[2,1.98,3]],"ltp":1.86,"tv":2575.26,"id":8681938}]}]}
{"op":"mcm","clk":"4296646801","pt":1632569441383,"mc":[{"id":"1.188134680","rc":[{"batb":[[0,2.04,177.64],[1,2.02,5],[2,1.67,418.02]],"ltp":2.16,"tv":748.47,"id":9631939},{"batl":[[0,1.98,3],[1,4.4,3.54],[2,1.98,0]],"ltp":1.86,"tv":2575.26,"id":8681938}]}]}
{"op":"mcm","clk":"4296646976","pt":1632569442340,"mc":[{"id":"1.188134680","rc":[{"batl":[[0,2.26,157.56]],"ltp":2.16,"tv":748.47,"id":9631939},{"batb":[[2,1.81,374.4]],"ltp":1.86,"tv":2575.26,"id":8681938}]}]}
{"op":"mcm","clk":"4296647309","pt":1632569444324,"mc":[{"id":"1.188134680","rc":[{"batb":[[2,1.5,94.99]],"batl":[[0,2.22,3],[1,2.24,11.12],[2,2.26,157.56]],"ltp":2.16,"tv":748.47,"id":9631939},{"trd":[[1.83,86.85]],"batb":[[0,1.83,304.56],[1,1.81,374.4],[2,1.79,253.9]],"batl":[[0,1.85,254.06],[1,1.86,142.14],[2,1.87,127.02]],"ltp":1.83,"tv":2608.22,"id":8681938}],"tv":3356.7}]}
{"op":"mcm","clk":"4296647454","pt":1632569445236,"mc":[{"id":"1.188134680","rc":[{"batb":[[0,2.16,152.45],[1,2.08,181.88],[2,2.04,177.64]],"batl":[[0,2.26,157.56],[1,2.28,195.09],[2,2.32,13.05]],"ltp":2.16,"tv":748.47,"id":9631939},{"batb":[[0,1.83,300.56]],"batl":[[1,1.86,127.02]],"ltp":1.83,"tv":2608.22,"id":8681938}]}]}
{"op":"mcm","clk":"4296647947","pt":1632569448315,"mc":[{"id":"1.188134680","rc":[{"batb":[[2,2.04,1072.7]],"batl":[[0,2.24,11.12],[1,2.26,157.56],[2,2.28,195.09]],"ltp":2.16,"tv":748.47,"id":9631939},{"batl":[[1,1.86,142.14]],"ltp":1.83,"tv":2608.22,"id":8681938}]}]}
{"op":"mcm","clk":"4296648065","pt":1632569449120,"mc":[{"id":"1.188134680","rc":[{"batb":[[2,2.04,177.64]],"ltp":2.16,"tv":748.47,"id":9631939},{"trd":[[1.83,95.31]],"batb":[[0,1.83,296.33]],"ltp":1.83,"tv":2616.68,"id":8681938}],"tv":3365.16}]}
{"op":"mcm","clk":"4296648215","pt":1632569450145,"mc":[{"id":"1.188134680","rc":[{"batl":[[0,1.84,290],[1,1.85,254.06],[2,1.86,142.14]],"ltp":1.83,"tv":2616.68,"id":8681938}]}]}
{"op":"mcm","clk":"4296648352","pt":1632569451155,"mc":[{"id":"1.188134680","rc":[{"batb":[[1,2.08,341.71],[2,2.06,206.38]],"ltp":2.16,"tv":748.47,"id":9631939}]}]}
{"op":"mcm","clk":"4296649303","pt":1632569457330,"mc":[{"id":"1.188134680","rc":[{"trd":[[1.84,29.41]],"batl":[[0,1.84,282.95]],"ltp":1.84,"tv":2630.78,"id":8681938}],"tv":3379.25}]}
{"op":"mcm","clk":"4296649856","pt":1632569460945,"mc":[{"id":"1.188134680","rc":[{"batb":[[0,1.83,297.54]],"ltp":1.84,"tv":2630.78,"id":8681938}]}]}
{"op":"mcm","clk":"4296650443","pt":1632569464434,"mc":[{"id":"1.188134680","rc":[{"batb":[[0,1.83,284.47]],"ltp":1.84,"tv":2630.78,"id":8681938}]}]}
{"op":"mcm","clk":"4296650975","pt":1632569468038,"mc":[{"id":"1.188134680","rc":[{"batb":[[0,1.83,283.26],[1,1.82,13.15],[2,1.81,374.4]],"ltp":1.84,"tv":2630.78,"id":8681938}]}]}
{"op":"mcm","clk":"4296651489","pt":1632569471247,"mc":[{"id":"1.188134680","rc":[{"trd":[[1.84,31.82]],"batl":[[0,1.84,281.74]],"ltp":1.84,"tv":2633.2,"id":8681938}],"tv":3381.67}]}
{"op":"mcm","clk":"4296653045","pt":1632569481253,"mc":[{"id":"1.188134680","rc":[{"trd":[[2.22,14]],"ltp":2.22,"tv":762.47,"id":9631939},{"trd":[[1.83,112.29]],"batb":[[0,1.83,266.28]],"ltp":1.83,"tv":2650.18,"id":8681938}],"tv":3412.65}]}
{"op":"mcm","clk":"4296653281","pt":1632569482732,"mc":[{"id":"1.188134680","rc":[{"trd":[[1.84,43.54]],"batl":[[0,1.84,275.88]],"ltp":1.84,"tv":2661.89,"id":8681938}],"tv":3424.37}]}
{"op":"mcm","clk":"4296656507","pt":1632569503093,"mc":[{"id":"1.188134680","rc":[{"trd":[[2.18,0.45]],"ltp":2.18,"tv":762.92,"id":9631939},{"trd":[[1.84,44.07]],"batl":[[0,1.84,275.35]],"ltp":1.84,"tv":2662.42,"id":8681938}],"tv":3425.35}]}
{"op":"mcm","clk":"4296659613","pt":1632569522218,"mc":[{"id":"1.188134680","rc":[{"batb":[[1,1.81,374.4],[2,1.79,253.9]],"ltp":1.84,"tv":2662.42,"id":8681938}]}]}
{"op":"mcm","clk":"4296660204","pt":1632569525129,"mc":[{"id":"1.188134680","rc":[{"batb":[[0,1.83,279.35]],"ltp":1.84,"tv":2662.42,"id":8681938}]}]}
{"op":"mcm","clk":"4296661185","pt":1632569530614,"mc":[{"id":"1.188134680","rc":[{"batb":[[1,2.08,181.88],[2,2.04,177.64]],"batl":[[1,2.26,3],[2,2.32,13.05]],"ltp":2.18,"tv":762.92,"id":9631939},{"batb":[[0,1.83,266.28],[2,1.78,137.82]],"ltp":1.84,"tv":2662.42,"id":8681938}]}]}
{"op":"mcm","clk":"4296661455","pt":1632569532013,"mc":[{"id":"1.188134680","rc":[{"trd":[[1.84,44.47]],"batl":[[0,1.84,275.15]],"ltp":1.84,"tv":2662.82,"id":8681938}],"tv":3425.75}]}
{"op":"mcm","clk":"4296662045","pt":1632569536130,"mc":[{"id":"1.188134680","rc":[{"trd":[[1.83,670.85]],"batb":[[0,1.78,137.82],[1,1.76,371.66],[2,1.75,133.52]],"batl":[[0,1.83,154.09],[1,1.84,275.15],[2,1.85,254.06]],"ltp":1.83,"tv":3221.38,"id":8681938}],"tv":3984.31}]}
{"op":"mcm","clk":"4296662453","pt":1632569538311,"mc":[{"id":"1.188134680","rc":[{"trd":[[1.83,674.28]],"batl":[[0,1.83,152.38]],"ltp":1.83,"tv":3224.81,"id":8681938}],"tv":3987.73}]}
{"op":"mcm","clk":"4296662622","pt":1632569539307,"mc":[{"id":"1.188134680","rc":[{"batb":[[0,1.82,322.66],[1,1.81,4],[2,1.8,386.47]],"ltp":1.83,"tv":3224.81,"id":8681938}]}]}
{"op":"mcm","clk":"4296662767","pt":1632569540144,"mc":[{"id":"1.188134680","rc":[{"batl":[[1,2.32,13.05],[2,2.44,12.3]],"ltp":2.18,"tv":762.92,"id":9631939},{"batb":[[0,1.8,300.2],[1,1.78,137.82],[2,1.76,388.86]],"ltp":1.83,"tv":3224.81,"id":8681938}]}]}
{"op":"mcm","clk":"4296662961","pt":1632569541217,"mc":[{"id":"1.188134680","rc":[{"batb":[[1,2.08,168]],"batl":[[1,2.44,12.3],[2,2.82,235.94]],"ltp":2.18,"tv":762.92,"id":9631939},{"batb":[[0,1.8,300.27],[2,1.76,371.66]],"batl":[[0,1.84,275.15],[1,1.85,254.06],[2,1.86,142.14]],"ltp":1.83,"tv":3224.81,"id":8681938}]}]}
{"op":"mcm","clk":"4296663239","pt":1632569542848,"mc":[{"id":"1.188134680","rc":[{"batb":[[1,1.78,533.64]],"batl":[[2,1.86,423.42]],"ltp":1.83,"tv":3224.81,"id":8681938}]}]}
{"op":"mcm","clk":"4296664085","pt":1632569548616,"mc":[{"id":"1.188134680","rc":[{"trd":[[1.8,4.56],[1.83,674.42]],"batb":[[0,1.8,297.92]],"ltp":1.8,"tv":3229.5,"id":8681938}],"tv":3992.43}]}
{"op":"mcm","clk":"4296664331","pt":1632569550231,"mc":[{"id":"1.188134680","rc":[{"batl":[[0,2.82,235.94],[1,5.8,2.54],[2,2.82,0]],"ltp":2.18,"tv":762.92,"id":9631939},{"batb":[[0,1.78,137.82],[1,1.68,169.19],[2,1.4,131.93]],"batl":[[1,1.98,3],[2,4.4,3.54]],"ltp":1.8,"tv":3229.5,"id":8681938}]}]}
{"op":"mcm","clk":"4296664383","pt":1632569550551,"mc":[{"id":"1.188134680","rc":[{"batb":[[0,2.02,5],[1,1.74,412.43],[2,1.6,87.96]],"ltp":2.18,"tv":762.92,"id":9631939},{"batb":[[0,1.4,131.93],[1,1.3,175.9],[2,1.25,29.25]],"batl":[[0,1.98,3],[1,4.4,3.54],[2,4.4,0]],"ltp":1.8,"tv":3229.5,"id":8681938}]}]}
{"op":"mcm","clk":"4296664836","pt":1632569553255,"mc":[{"id":"1.188134680","rc":[{"batb":[[0,1.74,412.43],[1,1.6,87.96],[2,1.5,94.99]],"batl":[[0,2.16,16.74],[1,2.24,120.91],[2,2.82,235.94]],"ltp":2.18,"tv":762.92,"id":9631939},{"batl":[[0,1.92,93.51],[1,1.93,231.96],[2,1.95,301.38]],"ltp":1.8,"tv":3229.5,"id":8681938}]}]}
{"op":"mcm","clk":"4296664998","pt":1632569554360,"mc":[{"id":"1.188134680","rc":[{"batb":[[0,2.02,14.7],[1,2,4],[2,1.74,412.43]],"batl":[[1,2.24,134.38]],"ltp":2.18,"tv":762.92,"id":9631939},{"batb":[[0,1.87,245.24],[1,1.85,348.79],[2,1.81,16.66]],"ltp":1.8,"tv":3229.5,"id":8681938}]}]}
{"op":"mcm","clk":"4296665131","pt":1632569555163,"mc":[{"id":"1.188134680","rc":[{"batl":[[2,2.4,1.71]],"ltp":2.18,"tv":762.92,"id":9631939}]}]}
{"op":"mcm","clk":"4296665314","pt":1632569556339,"mc":[{"id":"1.188134680","rc":[{"batb":[[2,1.99,4]],"batl":[[2,2.38,3]],"ltp":2.18,"tv":762.92,"id":9631939}]}]}
{"op":"mcm","clk":"4296665649","pt":1632569558236,"mc":[{"id":"1.188134680","rc":[{"trd":[[1.87,463.87]],"batb":[[0,1.87,236.7]],"ltp":1.87,"tv":3246.58,"id":8681938}],"tv":4009.51}]}
{"op":"mcm","clk":"4296666633","pt":1632569563875,"mc":[{"id":"1.188134680","rc":[{"batl":[[0,2.24,13.47],[1,2.38,3],[2,2.4,1.71]],"ltp":2.18,"tv":762.92,"id":9631939},{"batb":[[0,1.81,16.66],[1,1.73,5],[2,1.72,4]],"batl":[[0,1.97,15],[1,2,4],[2,2.14,1.71]],"ltp":1.87,"tv":3246.58,"id":8681938}]}]}
{"op":"mcm","clk":"4296666847","pt":1632569565288,"mc":[{"id":"1.188134680","rc":[{"batb":[[0,2,4],[1,1.99,4],[2,1.74,412.43]],"batl":[[0,2.38,3],[1,2.8,3],[2,2.82,235.94]],"ltp":2.18,"tv":762.92,"id":9631939},{"batb":[[0,1.73,5],[1,1.72,4],[2,1.55,7]],"batl":[[0,2,4],[1,4.4,3.54],[2,2.14,0]],"ltp":1.87,"tv":3246.58,"id":8681938}]}]}
{"op":"mcm","clk":"4296667168","pt":1632569567045,"mc":[{"id":"1.188134680","rc":[{"batb":[[0,2.02,4],[1,2,4],[2,1.99,4]],"ltp":2.18,"tv":762.92,"id":9631939},{"batb":[[0,1.78,362.75],[1,1.76,411.23],[2,1.73,5]],"batl":[[0,1.97,245.17],[1,1.99,283.43],[2,2,4]],"ltp":1.87,"tv":3246.58,"id":8681938}]}]}
{"op":"mcm","clk":"4296667465","pt":1632569568773,"mc":[{"id":"1.188134680","rc":[{"batb":[[1,1.74,412.43],[2,1.5,94.99]],"batl":[[0,2.3,4],[1,2.82,235.94],[2,5.8,2.54]],"ltp":2.18,"tv":762.92,"id":9631939},{"batl":[[1,1.99,286.43]],"ltp":1.87,"tv":3246.58,"id":8681938}]}]}
{"op":"mcm","clk":"4296667696","pt":1632569570148,"mc":[{"id":"1.188134680","rc":[{"batb":[[0,1.78,367.75],[1,1.77,5],[2,1.76,411.23]],"ltp":1.87,"tv":3246.58,"id":8681938}]}]}
{"op":"mcm","clk":"4296667961","pt":1632569571944,"mc":[{"id":"1.188134680","rc":[{"batb":[[1,2,4],[2,1.74,412.43]],"ltp":2.18,"tv":762.92,"id":9631939}]}]}
{"op":"mcm","clk":"4296668425","pt":1632569574756,"mc":[{"id":"1.188134680","rc":[{"batl":[[0,1.97,4],[1,1.99,3]],"ltp":1.87,"tv":3246.58,"id":8681938}]}]}
{"op":"mcm","clk":"4296668713","pt":1632569576875,"mc":[{"id":"1.188134680","rc":[{"batl":[[0,2.3,4.09]],"ltp":2.18,"tv":762.92,"id":9631939},{"batb":[[0,1.78,362.75]],"ltp":1.87,"tv":3246.58,"id":8681938}]}]}
{"op":"mcm","clk":"4296668946","pt":1632569578351,"mc":[{"id":"1.188134680","rc":[{"trd":[[2.18,0.54]],"batl":[[0,2.3,4],[1,2.34,408.66],[2,2.36,396.64]],"ltp":2.18,"tv":763.02,"id":9631939},{"trd":[[1.84,44.58]],"batb":[[0,1.78,370.8]],"batl":[[0,1.8,16.67],[1,1.83,161.48],[2,1.84,516.86]],"ltp":1.84,"tv":3246.69,"id":8681938}],"tv":4009.72}]}
{"op":"mcm","clk":"4296669084","pt":1632569579260,"mc":[{"id":"1.188134680","rc":[{"batb":[[0,2.12,13.39],[1,2.02,4],[2,2,4]],"ltp":2.18,"tv":763.02,"id":9631939}]}]}
{"op":"mcm","clk":"4296669286","pt":1632569580273,"mc":[{"id":"1.188134680","rc":[{"batl":[[0,1.8,18.86]],"ltp":1.84,"tv":3246.69,"id":8681938}]}]}
{"op":"mcm","clk":"4296669484","pt":1632569581179,"mc":[{"id":"1.188134680","rc":[{"batb":[[1,2.1,3],[2,2.08,4]],"ltp":2.18,"tv":763.02,"id":9631939}]}]}
{"op":"mcm","clk":"4296669844","pt":1632569583268,"mc":[{"id":"1.188134680","rc":[{"batl":[[0,1.8,16.67]],"ltp":1.84,"tv":3246.69,"id":8681938}]}]}
{"op":"mcm","clk":"4296669890","pt":1632569583495,"mc":[{"id":"1.188134680","rc":[{"batl":[[0,1.8,184.67]],"ltp":1.84,"tv":3246.69,"id":8681938}]}]}
{"op":"mcm","clk":"4296670146","pt":1632569584987,"mc":[{"id":"1.188134680","rc":[{"batb":[[0,2.12,23.26]],"ltp":2.18,"tv":763.02,"id":9631939}]}]}
{"op":"mcm","clk":"4296670455","pt":1632569586631,"mc":[{"id":"1.188134680","rc":[{"batl":[[0,1.8,354.67]],"ltp":1.84,"tv":3246.69,"id":8681938}]}]}
{"op":"mcm","clk":"4296670985","pt":1632569589702,"mc":[{"id":"1.188134680","rc":[{"trd":[[1.8,32.74]],"batl":[[0,1.8,340.58],[2,1.84,254.56]],"ltp":1.8,"tv":3274.88,"id":8681938}],"tv":4037.9}]}
{"op":"mcm","clk":"4296671437","pt":1632569592312,"mc":[{"id":"1.188134680","rc":[{"batb":[[2,1.74,412.43]],"batl":[[1,2.38,12.76],[2,2.82,235.94]],"ltp":2.18,"tv":763.02,"id":9631939},{"batb":[[0,1.78,362.75]],"batl":[[0,1.8,338],[1,1.84,254.56],[2,1.86,348.92]],"ltp":1.8,"tv":3274.88,"id":8681938}]}]}
{"op":"mcm","clk":"4296671625","pt":1632569593259,"mc":[{"id":"1.188134680","rc":[{"batb":[[0,1.74,412.43],[1,1.6,87.96],[2,1.5,94.99]],"batl":[[0,2.82,235.94],[1,5.8,2.54],[2,810,0.07]],"ltp":2.18,"tv":763.02,"id":9631939},{"batb":[[0,1.4,131.93],[1,1.3,175.9],[2,1.25,29.25]],"batl":[[1,1.96,4],[2,4.4,3.54]],"ltp":1.8,"tv":3274.88,"id":8681938}]}]}
{"op":"mcm","clk":"4296671677","pt":1632569593524,"mc":[{"id":"1.188134680","rc":[{"batl":[[0,1.96,4],[1,4.4,3.54],[2,4.4,0]],"ltp":1.8,"tv":3274.88,"id":8681938}]}]}
{"op":"mcm","clk":"4296672038","pt":1632569595409,"mc":[{"id":"1.188134680","rc":[{"batb":[[0,1.66,346.83],[1,1.65,258.91],[2,1.4,131.93]],"batl":[[0,1.91,350.27],[1,1.93,310.92],[2,1.96,4]],"ltp":1.8,"tv":3274.88,"id":8681938}]}]}
{"op":"mcm","clk":"4296672391","pt":1632569597259,"mc":[{"id":"1.188134680","rc":[{"batb":[[0,2.04,5],[1,2.02,3],[2,1.74,412.43]],"batl":[[0,2.4,3],[1,2.82,239.94],[2,5.8,2.54]],"ltp":2.18,"tv":763.02,"id":9631939},{"batb":[[2,1.54,7]],"ltp":1.8,"tv":3274.88,"id":8681938}]}]}
{"op":"mcm","clk":"4296672664","pt":1632569598856,"mc":[{"id":"1.188134680","rc":[{"batl":[[1,2.52,3],[2,2.82,239.94]],"ltp":2.18,"tv":763.02,"id":9631939},{"batb":[[0,1.66,5],[1,1.65,6]],"ltp":1.8,"tv":3274.88,"id":8681938}]}]}
{"op":"mcm","clk":"4296672947","pt":1632569600347,"mc":[{"id":"1.188134680","rc":[{"batb":[[0,1.71,5],[1,1.7,4],[2,1.66,5]],"ltp":1.8,"tv":3274.88,"id":8681938}]}]}
{"op":"mcm","clk":"4296673089","pt":1632569601152,"mc":[{"id":"1.188134680","rc":[{"batb":[[0,2.02,3],[1,1.74,412.43],[2,1.6,87.96]],"ltp":2.18,"tv":763.02,"id":9631939},{"batl":[[2,4.4,3.54]],"ltp":1.8,"tv":3274.88,"id":8681938}]}]}
{"op":"mcm","clk":"4296673308","pt":1632569602262,"mc":[{"id":"1.188134680","rc":[{"batb":[[0,2.12,76.95],[1,2.02,3],[2,1.74,412.43]],"batl":[[0,2.2,17.38],[1,2.28,116.96],[2,2.36,12.71]],"ltp":2.18,"tv":763.02,"id":9631939},{"batb":[[0,1.84,632.88],[1,1.82,893.29],[2,1.81,509.96]],"batl":[[0,1.89,8.54],[1,1.91,350.27],[2,1.93,310.92]],"ltp":1.8,"tv":3274.88,"id":8681938}]}]}
{"op":"mcm","clk":"4296673439","pt":1632569602953,"mc":[{"id":"1.188134680","rc":[{"batl":[[0,1.87,16.04],[1,1.89,8.54],[2,1.91,350.27]],"ltp":1.8,"tv":3274.88,"id":8681938}]}]}
{"op":"mcm","clk":"4296673580","pt":1632569603749,"mc":[{"id":"1.188134680","rc":[{"batb":[[1,2.08,13.88],[2,2.02,3]],"batl":[[2,2.3,13.15]],"ltp":2.18,"tv":763.02,"id":9631939}]}]}
{"op":"mcm","clk":"4296674360","pt":1632569608078,"mc":[{"id":"1.188134680","rc":[{"batb":[[2,2.06,171.89]],"ltp":2.18,"tv":763.02,"id":9631939}]}]}
{"op":"mcm","clk":"4296674725","pt":1632569610361,"mc":[{"id":"1.188134680","rc":[{"trd":[[1.84,490.68]],"batb":[[0,1.84,409.83]],"ltp":1.84,"tv":3720.98,"id":8681938}],"tv":4484.0}]}
{"op":"mcm","clk":"4296674995","pt":1632569611956,"mc":[{"id":"1.188134680","rc":[{"trd":[[1.84,516.4]],"batb":[[0,1.84,396.97]],"ltp":1.84,"tv":3746.69,"id":8681938}],"tv":4509.71}]}
{"op":"mcm","clk":"4296675215","pt":1632569613073,"mc":[{"id":"1.188134680","rc":[{"batl":[[0,1.87,113.04]],"ltp":1.84,"tv":3746.69,"id":8681938}]}]}
{"op":"mcm","clk":"4296675322","pt":1632569613544,"mc":[{"id":"1.188134680","rc":[{"batb":[[0,1.84,330.01]],"ltp":1.84,"tv":3746.69,"id":8681938}]}]}
{"op":"mcm","clk":"4296675840","pt":1632569616572,"mc":[{"id":"1.188134680","rc":[{"batl":[[0,1.87,177.04]],"ltp":1.84,"tv":3746.69,"id":8681938}]}]}
{"op":"mcm","clk":"4296676262","pt":1632569618975,"mc":[{"id":"1.188134680","rc":[{"batb":[[0,2.08,13.88],[1,2.06,171.89],[2,2.02,3]],"batl":[[0,2.3,13.15],[1,2.38,3],[2,2.82,235.94]],"ltp":2.18,"tv":763.02,"id":9631939},{"batb":[[0,1.78,16.98],[1,1.72,5],[2,1.69,164.2]],"batl":[[0,1.87,161],[1,1.93,15],[2,4.4,3.54]],"ltp":1.84,"tv":3746.69,"id":8681938}]}]}
{"op":"mcm","clk":"4296676497","pt":1632569620262,"mc":[{"id":"1.188134680","rc":[{"batb":[[0,2.06,171.89],[1,2.02,3],[2,1.74,412.53]],"batl":[[0,2.38,3],[1,2.82,235.94],[2,5.8,2.54]],"ltp":2.18,"tv":763.02,"id":9631939},{"batb":[[0,1.72,5],[1,1.69,164.2],[2,1.4,131.93]],"batl":[[0,4.4,3.54],[1,1.93,0],[2,4.4,0]],"ltp":1.84,"tv":3746.69,"id":8681938}]}]}
{"op":"mcm","clk":"4296676557","pt":1632569620591,"mc":[{"id":"1.188134680","rc":[{"batl":[[0,4.4,3.73]],"ltp":1.84,"tv":3746.69,"id":8681938}]}]}
{"op":"mcm","clk":"4296676835","pt":1632569621968,"mc":[{"id":"1.188134680","rc":[{"batb":[[0,1.74,419.46],[1,1.72,449.89],[2,1.69,164.2]],"batl":[[0,1.95,233.85],[1,1.97,292.18],[2,4.4,3.54]],"ltp":1.84,"tv":3746.69,"id":8681938}]}]}
{"op":"mcm","clk":"4296677176","pt":1632569623959,"mc":[{"id":"1.188134680","rc":[{"batb":[[2,1.71,4]],"batl":[[0,1.84,7.24],[1,1.95,233.65],[2,1.97,292.18]],"ltp":1.84,"tv":3746.69,"id":8681938}]}]}
{"op":"mcm","clk":"4296677400","pt":1632569625183,"mc":[{"id":"1.188134680","rc":[{"batl":[[0,2.34,4],[1,2.36,4],[2,2.38,3]],"ltp":2.18,"tv":763.02,"id":9631939},{"batb":[[0,1.75,4],[1,1.74,424.46],[2,1.72,449.89]],"ltp":1.84,"tv":3746.69,"id":8681938}]}]}
{"op":"mcm","clk":"4296677683","pt":1632569626772,"mc":[{"id":"1.188134680","rc":[{"trd":[[1.75,4.38]],"batb":[[0,1.75,1.81]],"ltp":1.75,"tv":3751.08,"id":8681938}],"tv":4514.1}]}
{"op":"mcm","clk":"4296677965","pt":1632569628359,"mc":[{"id":"1.188134680","rc":[{"batl":[[0,2.32,4],[1,2.34,4],[2,2.36,4]],"ltp":2.18,"tv":763.02,"id":9631939},{"batb":[[0,1.76,4],[1,1.75,1.81],[2,1.74,424.46]],"ltp":1.75,"tv":3751.08,"id":8681938}]}]}
{"op":"mcm","clk":"4296678607","pt":1632569631982,"mc":[{"id":"1.188134680","rc":[{"batl":[[0,2.34,4],[1,2.36,4],[2,2.38,3]],"ltp":2.18,"tv":763.02,"id":9631939},{"batb":[[0,1.74,424.46],[1,1.72,449.89],[2,1.71,4]],"ltp":1.75,"tv":3751.08,"id":8681938}]}]}
{"op":"mcm","clk":"4296678879","pt":1632569633380,"mc":[{"id":"1.188134680","rc":[{"batb":[[0,1.74,5],[1,1.72,5]],"ltp":1.75,"tv":3751.08,"id":8681938}]}]}
{"op":"mcm","clk":"4296679199","pt":1632569635296,"mc":[{"id":"1.188134680","rc":[{"batb":[[1,1.74,412.53],[2,1.6,87.96]],"ltp":2.18,"tv":763.02,"id":9631939},{"batb":[[1,1.73,5],[2,1.69,164.2]],"ltp":1.75,"tv":3751.08,"id":8681938}]}]}
{"op":"mcm","clk":"4296679370","pt":1632569636291,"mc":[{"id":"1.188134680","rc":[{"batl":[[0,2.16,515.96],[1,2.18,1074.23],[2,2.2,429.7]],"ltp":2.18,"tv":763.02,"id":9631939},{"trd":[[1.84,516.79]],"batb":[[0,1.92,9.65],[1,1.88,5829.93],[2,1.86,342.9]],"batl":[[0,1.95,233.65],[1,1.96,89.32]],"ltp":1.84,"tv":3751.47,"id":8681938}],"tv":4514.49}]}
{"op":"mcm","clk":"4296679539","pt":1632569637292,"mc":[{"id":"1.188134680","rc":[{"batb":[[1,2.02,180.85],[2,2,15.1]],"batl":[[1,2.18,429.7],[2,2.2,443.39]],"ltp":2.18,"tv":763.02,"id":9631939},{"batb":[[1,1.88,816.89]],"batl":[[0,1.93,15.54],[1,1.95,233.65],[2,1.96,89.32]],"ltp":1.84,"tv":3751.47,"id":8681938}]}]}
{"op":"mcm","clk":"4296679724","pt":1632569638291,"mc":[{"id":"1.188134680","rc":[{"batl":[[1,2.18,432.7]],"ltp":2.18,"tv":763.02,"id":9631939}]}]}
{"op":"mcm","clk":"4296680252","pt":1632569641316,"mc":[{"id":"1.188134680","rc":[{"batl":[[0,1.93,277.54]],"ltp":1.84,"tv":3751.47,"id":8681938}]}]}
{"op":"mcm","clk":"4296680702","pt":1632569643868,"mc":[{"id":"1.188134680","rc":[{"trd":[[1.93,35.02]],"batl":[[0,1.93,553.57]],"ltp":1.93,"tv":3755.41,"id":8681938}],"tv":4518.43}]}
{"op":"mcm","clk":"4296681015","pt":1632569645774,"mc":[{"id":"1.188134680","rc":[{"trd":[[1.92,78.48]],"batb":[[0,1.92,2.6]],"ltp":1.92,"tv":3769.5,"id":8681938}],"tv":4532.52}]}
{"op":"mcm","clk":"4296681447","pt":1632569648113,"mc":[{"id":"1.188134680","rc":[{"batb":[[1,1.88,384.71]],"ltp":1.92,"tv":3769.5,"id":8681938}]}]}
{"op":"mcm","clk":"4296681642","pt":1632569649024,"mc":[{"id":"1.188134680","rc":[{"batb":[[0,2.02,180.85],[1,2,15.1],[2,1.98,4]],"batl":[[0,2.2,13.69],[1,2.34,4],[2,2.82,235.94]],"ltp":2.18,"tv":763.02,"id":9631939},{"batb":[[0,1.84,4],[1,1.83,20.46],[2,1.77,140.69]],"batl":[[0,2,15],[1,4.4,3.54],[2,1.96,0]],"ltp":1.92,"tv":3769.5,"id":8681938}]}]}
{"op":"mcm","clk":"4296681891","pt":1632569650305,"mc":[{"id":"1.188134680","rc":[{"batb":[[1,1.98,4.1],[2,1.97,4]],"batl":[[0,2.34,4],[1,2.82,235.94],[2,5.8,2.54]],"ltp":2.18,"tv":763.02,"id":9631939},{"batb":[[1,1.83,4]],"batl":[[0,4.4,3.54],[1,4.4,0]],"ltp":1.92,"tv":3769.5,"id":8681938}]}]}
{"op":"mcm","clk":"4296681929","pt":1632569650521,"mc":[{"id":"1.188134680","rc":[{"batb":[[2,1.74,412.43]],"ltp":2.18,"tv":763.02,"id":9631939},{"batb":[[1,1.77,140.69],[2,1.4,131.93]],"ltp":1.92,"tv":3769.5,"id":8681938}]}]}
{"op":"mcm","clk":"4296682247","pt":1632569652215,"mc":[{"id":"1.188134680","rc":[{"batb":[[0,2.02,184.85],[1,2,4.1],[2,1.98,4]],"batl":[[0,2.2,4],[1,2.34,4],[2,2.82,235.94]],"ltp":2.18,"tv":763.02,"id":9631939},{"batl":[[0,1.99,5],[1,4.4,3.54]],"ltp":1.92,"tv":3769.5,"id":8681938}]}]}
{"op":"mcm","clk":"4296682594","pt":1632569654127,"mc":[{"id":"1.188134680","rc":[{"batl":[[1,2.22,4],[2,2.34,4]],"ltp":2.18,"tv":763.02,"id":9631939},{"batb":[[1,1.83,5],[2,1.77,140.69]],"batl":[[0,1.92,2.35],[1,1.99,5],[2,4.4,3.54]],"ltp":1.92,"tv":3769.5,"id":8681938}]}]}
{"op":"mcm","clk":"4296682761","pt":1632569655111,"mc":[{"id":"1.188134680","rc":[{"batb":[[0,1.87,347.41],[1,1.85,348.88],[2,1.84,4]],"batl":[[1,1.94,284.86],[2,1.96,296.69]],"ltp":1.92,"tv":3769.5,"id":8681938}]}]}
{"op":"mcm","clk":"4296683285","pt":1632569658137,"mc":[{"id":"1.188134680","rc":[{"trd":[[1.92,83.12]],"batl":[[0,1.94,284.89],[1,1.96,296.69],[2,1.98,5]],"ltp":1.92,"tv":3774.15,"id":8681938}],"tv":4537.17}]}
{"op":"mcm","clk":"4296683469","pt":1632569659255,"mc":[{"id":"1.188134680","rc":[{"trd":[[1.87,468.25],[1.92,83.17]],"batb":[[0,1.87,345.22]],"batl":[[0,1.94,284.86]],"ltp":1.92,"tv":3778.58,"id":8681938}],"tv":4541.61}]}
{"op":"mcm","clk":"4296683700","pt":1632569660756,"mc":[{"id":"1.188134680","rc":[{"trd":[[1.94,44.14]],"batl":[[0,1.94,282.51]],"ltp":1.94,"tv":3783.28,"id":8681938}],"tv":4546.3}]}
{"op":"mcm","clk":"4296683916","pt":1632569662041,"mc":[{"id":"1.188134680","rc":[{"batb":[[0,1.84,4],[1,1.83,5],[2,1.77,140.69]],"batl":[[0,1.98,5],[1,1.99,5],[2,4.4,3.54]],"ltp":1.94,"tv":3783.28,"id":8681938}]}]}
{"op":"mcm","clk":"4296684463","pt":1632569665254,"mc":[{"id":"1.188134680","rc":[{"batb":[[1,1.74,412.53],[2,1.5,94.99]],"batl":[[1,2.82,235.94],[2,5.8,2.54]],"ltp":2.18,"tv":763.02,"id":9631939},{"batb":[[1,1.82,398.7],[2,1.8,381.58]],"batl":[[0,1.98,276.84],[2,2,279.24]],"ltp":1.94,"tv":3783.28,"id":8681938}]}]}
{"op":"mcm","clk":"4296685066","pt":1632569668645,"mc":[{"id":"1.188134680","rc":[{"batb":[[1,2,4.1],[2,1.74,412.43]],"ltp":2.18,"tv":763.02,"id":9631939},{"batb":[[1,1.83,5],[2,1.82,398.7]],"batl":[[1,2,279.24],[2,4.4,3.54]],"ltp":1.94,"tv":3783.28,"id":8681938}]}]}
{"op":"mcm","clk":"4296685362","pt":1632569670355,"mc":[{"id":"1.188134680","rc":[{"batb":[[0,1.92,1.57],[1,1.84,4],[2,1.83,5]],"ltp":1.94,"tv":3783.28,"id":8681938}]}]}
{"op":"mcm","clk":"4296685786","pt":1632569672864,"mc":[{"id":"1.188134680","rc":[{"trd":[[1.92,86.31]],"batb":[[0,1.84,4],[1,1.83,5],[2,1.82,398.7]],"batl":[[0,1.98,277.46]],"ltp":1.92,"tv":3786.43,"id":8681938}],"tv":4549.45}]}
{"op":"mcm","clk":"4296686708","pt":1632569678582,"mc":[{"id":"1.188134680","rc":[{"batb":[[2,1.77,140.69]],"ltp":1.92,"tv":3786.43,"id":8681938}]}]}
{"op":"mcm","clk":"4296686887","pt":1632569679641,"mc":[{"id":"1.188134680","rc":[{"batl":[[0,1.98,276.84]],"ltp":1.92,"tv":3786.43,"id":8681938}]}]}
{"op":"mcm","clk":"4296687153","pt":1632569681346,"mc":[{"id":"1.188134680","rc":[{"batb":[[0,2.02,180.85],[1,2,6.19],[2,1.99,1922.1]],"batl":[[0,2.06,11.61],[1,2.12,110.07],[2,2.2,4]],"ltp":2.18,"tv":763.02,"id":9631939},{"batb":[[0,1.91,4914.9],[1,1.88,2034.58],[2,1.87,1974.74]],"batl":[[0,1.98,271.84],[1,2,285.33],[2,2.02,115.17]],"ltp":1.92,"tv":3786.43,"id":8681938}]}]}
{"op":"mcm","clk":"4296687312","pt":1632569682353,"mc":[{"id":"1.188134680","rc":[{"batb":[[2,1.99,480.52]],"batl":[[2,2.2,304.84]],"ltp":2.18,"tv":763.02,"id":9631939},{"batb":[[0,1.91,689.89],[1,1.89,325.79],[2,1.88,625.74]],"batl":[[0,1.96,15.31],[1,1.98,271.84],[2,2,285.33]],"ltp":1.92,"tv":3786.43,"id":8681938}]}]}
{"op":"mcm","clk":"4296687448","pt":1632569683253,"mc":[{"id":"1.188134680","rc":[{"trd":[[2.06,2.21]],"batl":[[0,2.06,9.4],[2,2.18,13.8]],"ltp":2.06,"tv":765.23,"id":9631939},{"trd":[[1.94,46.49]],"ltp":1.94,"tv":3788.77,"id":8681938}],"tv":4554.0}]}
{"op":"mcm","clk":"4296687616","pt":1632569684279,"mc":[{"id":"1.188134680","rc":[{"batl":[[2,2.18,17.8]],"ltp":2.06,"tv":765.23,"id":9631939}]}]}
{"op":"mcm","clk":"4296687727","pt":1632569685065,"mc":[{"id":"1.188134680","rc":[{"batb":[[1,1.9,5],[2,1.89,330.79]],"ltp":1.94,"tv":3788.77,"id":8681938}]}]}
{"op":"mcm","clk":"4296687925","pt":1632569686349,"mc":[{"id":"1.188134680","rc":[{"batl":[[2,2.16,92.34]],"ltp":2.06,"tv":765.23,"id":9631939},{"batl":[[1,1.97,256],[2,1.98,271.84]],"ltp":1.94,"tv":3788.77,"id":8681938}]}]}
{"op":"mcm","clk":"4296688065","pt":1632569687144,"mc":[{"id":"1.188134680","rc":[{"batl":[[2,2.18,4]],"ltp":2.06,"tv":765.23,"id":9631939}]}]}
{"op":"mcm","clk":"4296688551","pt":1632569690069,"mc":[{"id":"1.188134680","rc":[{"batl":[[2,2.16,13.92]],"ltp":2.06,"tv":765.23,"id":9631939}]}]}
{"op":"mcm","clk":"4296688894","pt":1632569692264,"mc":[{"id":"1.188134680","rc":[{"trd":[[2.04,14.82]],"ltp":2.04,"tv":768.74,"id":9631939},{"trd":[[1.96,15.42]],"batl":[[0,1.96,11.66]],"ltp":1.96,"tv":3792.42,"id":8681938}],"tv":4561.16}]}
{"op":"mcm","clk":"4296689077","pt":1632569693372,"mc":[{"id":"1.188134680","rc":[{"batb":[[1,1.99,480.62],[2,1.98,466.4]],"batl":[[0,2.12,110.07],[1,2.16,13.92],[2,2.18,4]],"ltp":2.04,"tv":768.74,"id":9631939},{"batb":[[0,1.91,299.82]],"batl":[[1,1.98,271.84],[2,2,279.24]],"ltp":1.96,"tv":3792.42,"id":8681938}]}]}
{"op":"mcm","clk":"4296689495","pt":1632569695871,"mc":[{"id":"1.188134680","rc":[{"trd":[[2.06,7.49]],"batb":[[1,2,7.33],[2,1.99,480.52]],"batl":[[0,2.06,4.12],[1,2.12,110.07],[2,2.16,13.92]],"ltp":2.06,"tv":774.02,"id":9631939},{"trd":[[1.94,52.09]],"batl":[[2,2,286.47]],"ltp":1.94,"tv":3798.03,"id":8681938}],"tv":4572.05}]}
{"op":"mcm","clk":"4296689729","pt":1632569697189,"mc":[{"id":"1.188134680","rc":[{"trd":[[1.96,38.74]],"batb":[[2,1.89,325.79]],"batl":[[0,1.98,271.84],[1,2,286.47],[2,2.02,115.17]],"ltp":1.96,"tv":3821.34,"id":8681938}],"tv":4595.37}]}
{"op":"mcm","clk":"4296690325","pt":1632569700369,"mc":[{"id":"1.188134680","rc":[{"batb":[[2,1.89,330.79]],"batl":[[0,1.96,133],[1,1.98,271.84],[2,2,286.47]],"ltp":1.96,"tv":3821.34,"id":8681938}]}]}
{"op":"mcm","clk":"4296691118","pt":1632569704686,"mc":[{"id":"1.188134680","rc":[{"trd":[[1.96,302.2]],"batl":[[0,1.96,1.27]],"ltp":1.96,"tv":4084.8,"id":8681938}],"tv":4858.83}]}
{"op":"mcm","clk":"4296691349","pt":1632569706133,"mc":[{"id":"1.188134680","rc":[{"batb":[[1,1.99,480.62],[2,1.98,466.4]],"batl":[[0,2.12,110.07],[1,2.16,13.92],[2,2.18,4]],"ltp":2.06,"tv":774.02,"id":9631939},{"trd":[[1.96,304.74]],"batl":[[0,1.98,271.84],[1,2,279.24],[2,2.02,115.17]],"ltp":1.96,"tv":4087.34,"id":8681938}],"tv":4861.36}]}
{"op":"mcm","clk":"4296691881","pt":1632569708990,"mc":[{"id":"1.188134680","rc":[{"batl":[[0,2.08,11.53],[1,2.12,110.07],[2,2.16,13.92]],"ltp":2.06,"tv":774.02,"id":9631939},{"batl":[[0,1.98,283.49]],"ltp":1.96,"tv":4087.34,"id":8681938}]}]}
{"op":"mcm","clk":"4296692855","pt":1632569714318,"mc":[{"id":"1.188134680","rc":[{"batb":[[1,1.96,15.4],[2,1.89,112.62]],"batl":[[0,2.16,13.92],[1,2.18,4],[2,5.8,2.54]],"ltp":2.06,"tv":774.02,"id":9631939},{"batb":[[0,1.88,117.1],[1,1.87,16.08],[2,1.83,126.57]],"batl":[[0,2.04,14.7],[1,4.4,3.54],[2,2.02,0]],"ltp":1.96,"tv":4087.34,"id":8681938}]}]}
{"op":"mcm","clk":"4296693017","pt":1632569715293,"mc":[{"id":"1.188134680","rc":[{"batb":[[0,1.89,112.72],[1,1.5,94.99],[2,1.4,131.93]],"batl":[[0,2.18,4],[1,5.8,2.54],[2,810,0.07]],"ltp":2.06,"tv":774.02,"id":9631939},{"batb":[[0,1.83,126.57],[1,1.4,131.93],[2,1.3,175.9]],"batl":[[0,4.4,3.54],[1,4.4,0]],"ltp":1.96,"tv":4087.34,"id":8681938}]}]}
{"op":"mcm","clk":"4296693350","pt":1632569717205,"mc":[{"id":"1.188134680","rc":[{"batb":[[0,1.86,323.55],[1,1.84,354.99],[2,1.83,126.57]],"batl":[[0,2.12,237.47],[1,2.14,229.09],[2,4.4,3.54]],"ltp":1.96,"tv":4087.34,"id":8681938}]}]}
{"op":"mcm","clk":"4296693554","pt":1632569718317,"mc":[{"id":"1.188134680","rc":[{"batl":[[0,4.4,3.54],[1,2.14,0],[2,4.4,0]],"ltp":1.96,"tv":4087.34,"id":8681938}]}]}
{"op":"mcm","clk":"4296693623","pt":1632569718694,"mc":[{"id":"1.188134680","rc":[{"batb":[[0,1.89,115.72],[1,1.88,4],[2,1.5,94.99]],"ltp":2.06,"tv":774.02,"id":9631939},{"batb":[[1,1.84,359.99],[2,1.83,131.57]],"batl":[[0,2.14,3],[1,4.4,3.54]],"ltp":1.96,"tv":4087.34,"id":8681938}]}]}
{"op":"mcm","clk":"4296694072","pt":1632569721298,"mc":[{"id":"1.188134680","rc":[{"batl":[[0,2.16,7.4],[1,2.18,4],[2,2.2,72.43]],"ltp":2.06,"tv":774.02,"id":9631939},{"batl":[[0,1.9,15.79],[1,1.92,19.71],[2,1.93,3262.88]],"ltp":1.96,"tv":4087.34,"id":8681938}]}]}
{"op":"mcm","clk":"4296694266","pt":1632569722316,"mc":[{"id":"1.188134680","rc":[{"batb":[[0,2.08,166.9],[1,2.02,14.7],[2,1.96,200.83]],"ltp":2.06,"tv":774.02,"id":9631939},{"batl":[[2,1.93,556.82]],"ltp":1.96,"tv":4087.34,"id":8681938}]}]}
{"op":"mcm","clk":"4296694657","pt":1632569724304,"mc":[{"id":"1.188134680","rc":[{"batb":[[2,2,3.1]],"ltp":2.06,"tv":774.02,"id":9631939}]}]}
{"op":"mcm","clk":"4296694779","pt":1632569724998,"mc":[{"id":"1.188134680","rc":[{"trd":[[1.9,49.54]],"batl":[[0,1.92,19.87],[1,1.93,556.82],[2,1.94,604.22]],"ltp":1.9,"tv":4118.6,"id":8681938}],"tv":4892.62}]}
{"op":"mcm","clk":"4296695071","pt":1632569726598,"mc":[{"id":"1.188134680","rc":[{"batl":[[0,1.89,4.11],[1,1.92,19.87],[2,1.93,556.82]],"ltp":1.9,"tv":4118.6,"id":8681938}]}]}
{"op":"mcm","clk":"4296695617","pt":1632569729716,"mc":[{"id":"1.188134680","rc":[{"batl":[[1,1.91,4.27],[2,1.92,19.71]],"ltp":1.9,"tv":4118.6,"id":8681938}]}]}
{"op":"mcm","clk":"4296695806","pt":1632569730917,"mc":[{"id":"1.188134680","rc":[{"batb":[[2,1.83,126.57]],"batl":[[1,1.9,4.27],[2,1.91,4.11]],"ltp":1.9,"tv":4118.6,"id":8681938}]}]}
{"op":"mcm","clk":"4296695924","pt":1632569731509,"mc":[{"id":"1.188134680","rc":[{"batl":[[0,1.89,102.11]],"ltp":1.9,"tv":4118.6,"id":8681938}]}]}
{"op":"mcm","clk":"4296696275","pt":1632569733326,"mc":[{"id":"1.188134680","rc":[{"batl":[[0,2.18,4],[1,2.24,13.47],[2,5.8,2.54]],"ltp":2.06,"tv":774.02,"id":9631939},{"batl":[[1,1.9,4.11]],"ltp":1.9,"tv":4118.6,"id":8681938}]}]}
{"op":"mcm","clk":"4296696448","pt":1632569734325,"mc":[{"id":"1.188134680","rc":[{"batb":[[0,2.02,14.7],[1,2,3.1],[2,1.99,4]],"batl":[[0,2.24,13.47],[1,5.8,2.54],[2,810,0.07]],"ltp":2.06,"tv":774.02,"id":9631939},{"batb":[[0,1.81,16.66],[1,1.79,135.11],[2,1.4,131.93]],"batl":[[0,1.86,45.34],[1,1.89,102.11],[2,1.9,4.11]],"ltp":1.9,"tv":4118.6,"id":8681938}]}]}
{"op":"mcm","clk":"4296696655","pt":1632569735306,"mc":[{"id":"1.188134680","rc":[{"batb":[[0,2,3.1],[1,1.99,4],[2,1.96,200.72]],"batl":[[0,5.8,2.54],[1,810,0.07],[2,810,0]],"ltp":2.06,"tv":774.02,"id":9631939},{"batb":[[0,1.79,135.11],[1,1.4,131.93],[2,1.3,175.9]],"batl":[[1,1.89,4.11]],"ltp":1.9,"tv":4118.6,"id":8681938}]}]}
{"op":"mcm","clk":"4296697023","pt":1632569737032,"mc":[{"id":"1.188134680","rc":[{"batb":[[1,1.96,200.72],[2,1.5,94.99]],"batl":[[0,2.2,3],[1,2.24,3],[2,5.8,2.54]],"ltp":2.06,"tv":774.02,"id":9631939},{"batb":[[0,1.83,247.35],[1,1.81,378.38],[2,1.8,139.6]],"ltp":1.9,"tv":4118.6,"id":8681938}]}]}
{"op":"mcm","clk":"4296697344","pt":1632569738504,"mc":[{"id":"1.188134680","rc":[{"batl":[[2,2.28,3]],"ltp":2.06,"tv":774.02,"id":9631939}]}]}
{"op":"mcm","clk":"4296697659","pt":1632569740301,"mc":[{"id":"1.188134680","rc":[{"batb":[[0,2.1,1138.39],[1,2.08,1104.91],[2,2.06,1104.91]],"batl":[[0,2.24,10.56],[1,2.26,1057.8],[2,2.28,484.02]],"ltp":2.06,"tv":774.02,"id":9631939},{"batl":[[0,1.85,16.22],[1,1.86,64.8],[2,1.89,4383.91]],"ltp":1.9,"tv":4118.6,"id":8681938}]}]}
{"op":"mcm","clk":"4296697844","pt":1632569741309,"mc":[{"id":"1.188134680","rc":[{"batb":[[0,2.14,156.33],[1,2.1,455.36],[2,2.08,441.96]],"batl":[[1,2.26,423.12]],"ltp":2.06,"tv":774.02,"id":9631939},{"batl":[[2,1.89,771.53]],"ltp":1.9,"tv":4118.6,"id":8681938}]}]}
{"op":"mcm","clk":"4296698007","pt":1632569742207,"mc":[{"id":"1.188134680","rc":[{"batl":[[0,1.84,4.11],[1,1.85,20.33],[2,1.86,64.8]],"ltp":1.9,"tv":4118.6,"id":8681938}]}]}
{"op":"mcm","clk":"4296698264","pt":1632569743794,"mc":[{"id":"1.188134680","rc":[{"batl":[[2,1.86,19.46]],"ltp":1.9,"tv":4118.6,"id":8681938}]}]}
{"op":"mcm","clk":"4296698500","pt":1632569745343,"mc":[{"id":"1.188134680","rc":[{"trd":[[1.83,685.54]],"batb":[[0,1.83,241.79]],"batl":[[2,1.86,29.46]],"ltp":1.83,"tv":4129.72,"id":8681938}],"tv":4903.74}]}
{"op":"mcm","clk":"4296698663","pt":1632569746326,"mc":[{"id":"1.188134680","rc":[{"batl":[[0,1.84,261.11]],"ltp":1.83,"tv":4129.72,"id":8681938}]}]}
{"op":"mcm","clk":"4296698990","pt":1632569748340,"mc":[{"id":"1.188134680","rc":[{"batl":[[2,1.86,19.46]],"ltp":1.83,"tv":4129.72,"id":8681938}]}]}
{"op":"mcm","clk":"4296699012","pt":1632569748547,"mc":[{"id":"1.188134680","rc":[{"batb":[[2,2.08,455.84]],"ltp":2.06,"tv":774.02,"id":9631939},{"batb":[[2,1.8,134.6]],"batl":[[0,1.84,393.11]],"ltp":1.83,"tv":4129.72,"id":8681938}]}]}
{"op":"mcm","clk":"4296699633","pt":1632569752030,"mc":[{"id":"1.188134680","rc":[{"batl":[[2,2.28,481.02]],"ltp":2.06,"tv":774.02,"id":9631939}]}]}
{"op":"mcm","clk":"4296700350","pt":1632569756256,"mc":[{"id":"1.188134680","rc":[{"batb":[[0,2.08,13.88],[1,2.04,182.08],[2,1.6,88.06]],"batl":[[0,2.3,13.15],[1,5.8,2.54],[2,810,0.07]],"ltp":2.06,"tv":774.02,"id":9631939},{"batb":[[0,1.77,141.62],[1,1.4,131.93],[2,1.3,175.9]],"batl":[[0,1.84,4.11],[1,1.85,4.11],[2,1.89,4.11]],"ltp":1.83,"tv":4129.72,"id":8681938}]}]}
{"op":"mcm","clk":"4296700557","pt":1632569757261,"mc":[{"id":"1.188134680","rc":[{"batb":[[0,2.04,182.08],[1,1.6,88.06],[2,1.5,94.99]],"batl":[[0,5.8,2.54],[1,810,0.07],[2,810,0]],"ltp":2.06,"tv":774.02,"id":9631939}]}]}
{"op":"mcm","clk":"4296700635","pt":1632569757634,"mc":[{"id":"1.188134680","rc":[{"batl":[[0,1.83,4.11],[1,1.84,4.11],[2,1.85,4.11]],"ltp":1.83,"tv":4129.72,"id":8681938}]}]}
{"op":"mcm","clk":"4296700958","pt":1632569759332,"mc":[{"id":"1.188134680","rc":[{"batl":[[0,2.3,3],[1,5.8,2.54],[2,810,0.07]],"ltp":2.06,"tv":774.02,"id":9631939},{"batb":[[0,1.8,375.93],[1,1.79,5],[2,1.78,400.86]],"ltp":1.83,"tv":4129.72,"id":8681938}]}]}
{"op":"mcm","clk":"4296701283","pt":1632569761273,"mc":[{"id":"1.188134680","rc":[{"batl":[[1,3.5,2],[2,5.8,2.54]],"ltp":2.06,"tv":774.02,"id":9631939},{"batl":[[0,1.96,312.1],[1,1.98,287.71],[2,2,4]],"ltp":1.83,"tv":4129.72,"id":8681938}]}]}
{"op":"mcm","clk":"4296701467","pt":1632569762232,"mc":[{"id":"1.188134680","rc":[{"batb":[[1,2.02,4],[2,1.6,88.06]],"batl":[[0,2.24,4],[1,2.28,3],[2,2.3,3]],"ltp":2.06,"tv":774.02,"id":9631939},{"batl":[[0,1.86,4.11],[1,1.87,4.11],[2,1.96,312.1]],"ltp":1.83,"tv":4129.72,"id":8681938}]}]}
{"op":"mcm","clk":"4296701559","pt":1632569762715,"mc":[{"id":"1.188134680","rc":[{"batb":[[0,1.81,4],[1,1.8,378.93],[2,1.79,5]],"ltp":1.83,"tv":4129.72,"id":8681938}]}]}
{"op":"mcm","clk":"4296701842","pt":1632569764497,"mc":[{"id":"1.188134680","rc":[{"batl":[[0,1.96,312.1],[1,1.98,287.71],[2,2,4]],"ltp":1.83,"tv":4129.72,"id":8681938}]}]}
{"op":"mcm","clk":"4296702278","pt":1632569767234,"mc":[{"id":"1.188134680","rc":[{"batl":[[0,1.94,4.11],[1,1.95,4.11],[2,1.96,312.1]],"ltp":1.83,"tv":4129.72,"id":8681938}]}]}
{"op":"mcm","clk":"4296702525","pt":1632569768576,"mc":[{"id":"1.188134680","rc":[{"batl":[[0,1.93,4.11],[1,1.94,4.11],[2,1.95,4.11]],"ltp":1.83,"tv":4129.72,"id":8681938}]}]}
{"op":"mcm","clk":"4296704516","pt":1632569779599,"mc":[{"id":"1.188134680","rc":[{"batb":[[1,1.6,88.06],[2,1.5,94.99]],"batl":[[1,5.8,2.54],[2,810,0.07]],"ltp":2.06,"tv":774.02,"id":9631939},{"batb":[[1,1.77,141.62],[2,1.4,131.93]],"ltp":1.83,"tv":4129.72,"id":8681938}]}]}
{"op":"mcm","clk":"4296704776","pt":1632569781221,"mc":[{"id":"1.188134680","rc":[{"batl":[[0,1.96,312.1],[1,1.98,287.71],[2,2,4]],"ltp":1.83,"tv":4129.72,"id":8681938}]}]}
{"op":"mcm","clk":"4296704957","pt":1632569782299,"mc":[{"id":"1.188134680","rc":[{"batb":[[0,2.08,8.14],[1,2.04,259.82],[2,1.5,95.09]],"batl":[[0,2.2,141.71],[1,2.24,4],[2,2.3,13.04]],"ltp":2.06,"tv":774.02,"id":9631939},{"batb":[[0,1.89,5158.33],[1,1.87,848.34],[2,1.86,496.32]],"batl":[[2,2,1195.31]],"ltp":1.83,"tv":4129.72,"id":8681938}]}]}
{"op":"mcm","clk":"4296705124","pt":1632569783313,"mc":[{"id":"1.188134680","rc":[{"batb":[[2,1.99,15.17]],"batl":[[1,2.22,13.58],[2,2.24,4]],"ltp":2.06,"tv":774.02,"id":9631939},{"batb":[[0,1.89,681.95],[1,1.87,966.63]],"batl":[[0,1.91,15.71],[1,1.96,312.1],[2,1.98,287.71]],"ltp":1.83,"tv":4129.72,"id":8681938}]}]}
{"op":"mcm","clk":"4296705426","pt":1632569785207,"mc":[{"id":"1.188134680","rc":[{"batl":[[0,2.18,4],[1,2.2,141.71],[2,2.22,13.58]],"ltp":2.06,"tv":774.02,"id":9631939}]}]}
{"op":"mcm","clk":"4296705784","pt":1632569787325,"mc":[{"id":"1.188134680","rc":[{"batl":[[2,2.24,4]],"ltp":2.06,"tv":774.02,"id":9631939},{"batl":[[0,1.91,209.71]],"ltp":1.83,"tv":4129.72,"id":8681938}]}]}
{"op":"mcm","clk":"4296706241","pt":1632569790103,"mc":[{"id":"1.188134680","rc":[{"batl":[[0,1.91,829.07]],"ltp":1.83,"tv":4129.72,"id":8681938}]}]}
{"op":"mcm","clk":"4296706353","pt":1632569790731,"mc":[{"id":"1.188134680","rc":[{"batl":[[0,2.18,362.7]],"ltp":2.06,"tv":774.02,"id":9631939}]}]}
{"op":"mcm","clk":"4296706950","pt":1632569794133,"mc":[{"id":"1.188134680","rc":[{"batb":[[0,1.89,296.05]],"ltp":1.83,"tv":4129.72,"id":8681938}]}]}
{"op":"mcm","clk":"4296707083","pt":1632569794933,"mc":[{"id":"1.188134680","rc":[{"batb":[[0,1.99,15.17],[1,1.98,4],[2,1.97,3]],"batl":[[0,2.18,13.8],[1,2.24,4],[2,5.8,2.54]],"ltp":2.06,"tv":774.02,"id":9631939},{"trd":[[1.89,682.73]],"batb":[[0,1.84,16.36],[1,1.83,127.42],[2,1.81,4]],"batl":[[0,1.91,374],[1,2.02,14.85],[2,4.4,3.54]],"ltp":1.89,"tv":4134.42,"id":8681938}],"tv":4908.44}]}
{"op":"mcm","clk":"4296707300","pt":1632569796321,"mc":[{"id":"1.188134680","rc":[{"batb":[[0,1.98,4.1],[1,1.97,3],[2,1.9,111.18]],"batl":[[0,2.24,4],[1,5.8,2.54],[2,810,0.07]],"ltp":2.06,"tv":774.02,"id":9631939},{"batb":[[0,1.83,127.42],[1,1.81,4],[2,1.4,131.93]],"batl":[[0,4.4,3.54],[1,2.02,0],[2,4.4,0]],"ltp":1.89,"tv":4134.42,"id":8681938}]}]}
{"op":"mcm","clk":"4296707597","pt":1632569798098,"mc":[{"id":"1.188134680","rc":[{"batb":[[1,1.9,111.18],[2,1.5,94.99]],"ltp":2.06,"tv":774.02,"id":9631939},{"batb":[[0,1.84,407.4],[1,1.83,131.42],[2,1.82,367.92]],"batl":[[0,1.89,439.36],[1,2.1,433.44],[2,2.12,235.49]],"ltp":1.89,"tv":4134.42,"id":8681938}]}]}
{"op":"mcm","clk":"4296707774","pt":1632569799006,"mc":[{"id":"1.188134680","rc":[{"batl":[[1,2.02,4],[2,2.1,433.44]],"ltp":1.89,"tv":4134.42,"id":8681938}]}]}
{"op":"mcm","clk":"4296707963","pt":1632569800131,"mc":[{"id":"1.188134680","rc":[{"batl":[[0,2.22,4],[1,2.24,4],[2,5.8,2.54]],"ltp":2.06,"tv":774.02,"id":9631939},{"batb":[[2,1.82,371.92]],"batl":[[0,2.02,4],[1,2.04,4]],"ltp":1.89,"tv":4134.42,"id":8681938}]}]}
{"op":"mcm","clk":"4296708515","pt":1632569803327,"mc":[{"id":"1.188134680","rc":[{"batb":[[1,1.97,3],[2,1.9,111.18]],"ltp":2.06,"tv":774.02,"id":9631939}]}]}
{"op":"mcm","clk":"4296709050","pt":1632569806627,"mc":[{"id":"1.188134680","rc":[{"batb":[[0,1.84,5],[2,1.82,4]],"batl":[[2,4.4,3.54]],"ltp":1.89,"tv":4134.42,"id":8681938}]}]}
{"op":"mcm","clk":"4296709493","pt":1632569809344,"mc":[{"id":"1.188134680","rc":[{"trd":[[1.98,64.06],[2,324.2]],"batb":[[0,1.97,3],[1,1.9,111.18],[2,1.89,100.78]],"batl":[[0,1.98,4.12],[1,2.02,105.53],[2,2.16,13.89]],"ltp":1.98,"tv":786.2,"id":9631939},{"trd":[[2,22.87],[2.02,54.95]],"batb":[[0,2,6765.44],[1,1.99,1856.24],[2,1.98,1856.24]],"batl":[[0,2.04,4],[1,2.08,11.02]],"ltp":2.02,"tv":4138.52,"id":8681938}],"tv":4924.72}]}
{"op":"mcm","clk":"4296709687","pt":1632569810353,"mc":[{"id":"1.188134680","rc":[{"batb":[[0,1.92,303.34],[1,1.9,431.51]],"batl":[[1,1.99,254.12],[2,2.02,513.77]],"ltp":1.98,"tv":786.2,"id":9631939},{"batb":[[0,2,863.28],[1,1.99,464.06],[2,1.98,464.06]],"batl":[[0,2.04,14.71],[2,2.46,1.91]],"ltp":2.02,"tv":4138.52,"id":8681938}]}]}
{"op":"mcm","clk":"4296709839","pt":1632569811247,"mc":[{"id":"1.188134680","rc":[{"batb":[[0,2,1054.03]],"batl":[[2,2.16,13.92]],"ltp":2.02,"tv":4138.52,"id":8681938}]}]}
{"op":"mcm","clk":"4296710069","pt":1632569812640,"mc":[{"id":"1.188134680","rc":[{"batl":[[2,2,3]],"ltp":1.98,"tv":786.2,"id":9631939},{"batb":[[0,2,1059.03],[1,1.99,467.06]],"ltp":2.02,"tv":4138.52,"id":8681938}]}]}
{"op":"mcm","clk":"4296710342","pt":1632569814334,"mc":[{"id":"1.188134680","rc":[{"trd":[[1.98,68.18]],"batl":[[0,1.99,254.12],[1,2,3],[2,2.02,513.77]],"ltp":1.98,"tv":790.32,"id":9631939},{"trd":[[2.02,58.99]],"batl":[[0,2.04,15.45]],"ltp":2.02,"tv":4142.56,"id":8681938}],"tv":4932.88}]}
{"op":"mcm","clk":"4296710465","pt":1632569815034,"mc":[{"id":"1.188134680","rc":[{"batl":[[0,2.04,14.71]],"ltp":2.02,"tv":4142.56,"id":8681938}]}]}
{"op":"mcm","clk":"4296710708","pt":1632569816539,"mc":[{"id":"1.188134680","rc":[{"batb":[[0,1.96,149],[1,1.92,303.34],[2,1.9,431.51]],"ltp":1.98,"tv":790.32,"id":9631939}]}]}
{"op":"mcm","clk":"4296711113","pt":1632569819046,"mc":[{"id":"1.188134680","rc":[{"batl":[[0,2.02,441.71],[1,2.04,14.71],[2,2.08,11.02]],"ltp":2.02,"tv":4142.56,"id":8681938}]}]}
{"op":"mcm","clk":"4296711263","pt":1632569820041,"mc":[{"id":"1.188134680","rc":[{"batb":[[0,1.98,2.66],[1,1.96,149],[2,1.92,303.34]],"ltp":1.98,"tv":790.32,"id":9631939},{"batl":[[2,2.16,13.92]],"ltp":2.02,"tv":4142.56,"id":8681938}]}]}
{"op":"mcm","clk":"4296711503","pt":1632569821338,"mc":[{"id":"1.188134680","rc":[{"batb":[[0,2,673.87]],"ltp":2.02,"tv":4142.56,"id":8681938}]}]}
{"op":"mcm","clk":"4296711647","pt":1632569822151,"mc":[{"id":"1.188134680","rc":[{"batb":[[0,1.98,858.92]],"ltp":1.98,"tv":790.32,"id":9631939},{"trd":[[2.02,311.47]],"batl":[[0,2.02,315.47]],"ltp":2.02,"tv":4395.04,"id":8681938}],"tv":5185.36}]}
{"op":"mcm","clk":"4296711714","pt":1632569822564,"mc":[{"id":"1.188134680","rc":[{"batl":[[1,2,7.19]],"ltp":1.98,"tv":790.32,"id":9631939},{"batb":[[0,2,678.06]],"batl":[[1,2.04,22.44]],"ltp":2.02,"tv":4395.04,"id":8681938}]}]}
{"op":"mcm","clk":"4296712017","pt":1632569824358,"mc":[{"id":"1.188134680","rc":[{"trd":[[1.99,508.24],[2,327.34]],"batb":[[0,1.99,31.3],[1,1.98,858.92],[2,1.96,243]],"batl":[[0,2,5.62],[1,2.02,376.3],[2,2.04,14.7]],"ltp":2.0,"tv":1301.7,"id":9631939},{"trd":[[2,23.3]],"batb":[[0,2,677.84],[1,1.99,464.06]],"batl":[[0,2.02,313.12]],"ltp":2.0,"tv":4395.47,"id":8681938}],"tv":5697.17}]}
{"op":"mcm","clk":"4296712186","pt":1632569825138,"mc":[{"id":"1.188134680","rc":[{"batl":[[0,2,1.43]],"ltp":2.0,"tv":1301.7,"id":9631939},{"trd":[[2,33.3]],"batb":[[0,2,668.65]],"batl":[[1,2.04,14.71]],"ltp":2.0,"tv":4405.47,"id":8681938}],"tv":5707.17}]}
{"op":"mcm","clk":"4296712514","pt":1632569827363,"mc":[{"id":"1.188134680","rc":[{"batl":[[0,2,253.37],[1,2.04,14.7],[2,5.8,2.54]],"ltp":2.0,"tv":1301.7,"id":9631939},{"batb":[[0,2,5],[1,1.97,15.23],[2,1.9,111.95]],"batl":[[1,2.16,13.92],[2,4.4,3.34]],"ltp":2.0,"tv":4405.47,"id":8681938}]}]}
{"op":"mcm","clk":"4296712676","pt":1632569828348,"mc":[{"id":"1.188134680","rc":[{"trd":[[1.99,560.83],[2,332.34]],"batb":[[0,1.99,5.01],[2,1.69,161.83]],"batl":[[0,5.8,2.72],[1,810,0.07],[2,5.8,0]],"ltp":1.99,"tv":1359.29,"id":9631939},{"trd":[[2,38.3]],"batb":[[0,1.9,111.95],[1,1.5,95],[2,1.4,131.93]],"batl":[[1,4.4,3.34],[2,4.4,0]],"ltp":2.0,"tv":4410.47,"id":8681938}],"tv":5769.77}]}
{"op":"mcm","clk":"4296712965","pt":1632569830281,"mc":[{"id":"1.188134680","rc":[{"batb":[[2,1.72,335.3]],"batl":[[0,2.12,328.41],[1,2.14,229.25],[2,5.8,2.72]],"ltp":1.99,"tv":1359.29,"id":9631939}]}]}
{"op":"mcm","clk":"4296713159","pt":1632569831442,"mc":[{"id":"1.188134680","rc":[{"batb":[[0,1.98,2.66],[1,1.72,335.3],[2,1.7,460.81]],"ltp":1.99,"tv":1359.29,"id":9631939}]}]}
{"op":"mcm","clk":"4296713373","pt":1632569832683,"mc":[{"id":"1.188134680","rc":[{"batl":[[0,4.4,3.34],[1,4.4,0]],"ltp":2.0,"tv":4410.47,"id":8681938}]}]}
{"op":"mcm","clk":"4296713584","pt":1632569833878,"mc":[{"id":"1.188134680","rc":[{"batb":[[1,1.69,161.83],[2,1.5,94.99]],"batl":[[0,5.8,2.72],[1,810,0.07],[2,5.8,0]],"ltp":1.99,"tv":1359.29,"id":9631939}]}]}
{"op":"mcm","clk":"4296714185","pt":1632569837300,"mc":[{"id":"1.188134680","rc":[{"batb":[[0,2.04,398.06],[1,2,64.99],[2,1.98,103.18]],"batl":[[0,2.16,115.62],[1,2.32,1.71],[2,3,3]],"ltp":1.99,"tv":1359.29,"id":9631939},{"batb":[[0,1.9,362.19],[1,1.88,331.26],[2,1.85,516.88]],"batl":[[0,1.91,15.71],[1,1.92,11.06],[2,1.97,333.59]],"ltp":2.0,"tv":4410.47,"id":8681938}]}]}
{"op":"mcm","clk":"4296714354","pt":1632569838261,"mc":[{"id":"1.188134680","rc":[{"batb":[[1,2,252.86],[2,1.98,2.66]],"batl":[[0,2.14,14.04],[1,2.16,115.62],[2,2.32,14.64]],"ltp":1.99,"tv":1359.29,"id":9631939},{"batb":[[2,1.87,16.08]],"ltp":2.0,"tv":4410.47,"id":8681938}]}]}
{"op":"mcm","clk":"4296714577","pt":1632569839792,"mc":[{"id":"1.188134680","rc":[{"trd":[[1.91,209.7]],"batb":[[0,1.9,367.19],[1,1.89,4],[2,1.88,331.26]],"batl":[[0,1.92,11.06],[1,1.97,333.59],[2,1.98,482.96]],"ltp":1.91,"tv":4441.89,"id":8681938}],"tv":5801.19}]}
{"op":"mcm","clk":"4296715461","pt":1632569845320,"mc":[{"id":"1.188134680","rc":[{"batb":[[2,1.97,15.54]],"batl":[[0,2.14,194.34]],"ltp":1.99,"tv":1359.29,"id":9631939}]}]}
{"op":"mcm","clk":"4296715606","pt":1632569846176,"mc":[{"id":"1.188134680","rc":[{"trd":[[1.9,783.91]],"batb":[[0,1.89,4],[1,1.87,64.32],[2,1.85,516.88]],"batl":[[0,1.9,72.17],[1,1.92,11.06]],"ltp":1.9,"tv":5176.26,"id":8681938}],"tv":6535.56}]}
{"op":"mcm","clk":"4296715859","pt":1632569847704,"mc":[{"id":"1.188134680","rc":[{"batl":[[2,2.32,12.93]],"ltp":1.99,"tv":1359.29,"id":9631939},{"batl":[[0,1.92,11.06],[1,1.98,482.96],[2,1.99,468.76]],"ltp":1.9,"tv":5176.26,"id":8681938}]}]}
{"op":"mcm","clk":"4296716099","pt":1632569849276,"mc":[{"id":"1.188134680","rc":[{"trd":[[2.08,10.6],[2.12,8.85]],"batb":[[0,2,252.86],[1,1.97,15.54],[2,1.87,116.85]],"batl":[[0,2.08,74.97],[1,2.12,3.11],[2,2.14,194.34]],"ltp":2.08,"tv":1370.39,"id":9631939},{"trd":[[1.89,691.73],[1.92,97.37]],"batb":[[0,1.9,71.96],[1,1.89,276.33],[2,1.87,401.34]],"batl":[[0,1.96,323.21],[1,1.98,770.76]],"ltp":1.92,"tv":5196.32,"id":8681938}],"tv":6566.72}]}
{"op":"mcm","clk":"4296716132","pt":1632569849491,"mc":[{"id":"1.188134680","rc":[{"batb":[[0,1.89,276.33],[1,1.87,401.34],[2,1.85,516.88]],"ltp":1.92,"tv":5196.32,"id":8681938}]}]}
{"op":"mcm","clk":"4296716638","pt":1632569852376,"mc":[{"id":"1.188134680","rc":[{"batb":[[0,2,187.87]],"batl":[[1,2.14,194.34],[2,3,3]],"ltp":2.08,"tv":1370.39,"id":9631939},{"batb":[[1,1.88,5],[2,1.87,405.34]],"batl":[[1,1.98,287.8],[2,2.04,14.7]],"ltp":1.92,"tv":5196.32,"id":8681938}]}]}
