{"op":"mcm","clk":"4297272033","pt":1632572563380,"mc":[{"id":"1.188134680","rc":[{"batb":[[1,3.65,95.97],[2,3.6,130.56]],"batl":[[2,4,117.5]],"ltp":3.65,"tv":3676.42,"id":9631939},{"batl":[[2,1.39,180.99]],"ltp":1.39,"tv":27307.62,"id":8681938}]}]}
{"op":"mcm","clk":"4297272185","pt":1632572564121,"mc":[{"id":"1.188134680","rc":[{"batl":[[1,1.38,541.07]],"ltp":1.39,"tv":27307.62,"id":8681938}]}]}
{"op":"mcm","clk":"4297272811","pt":1632572567206,"mc":[{"id":"1.188134680","rc":[{"batb":[[0,1.35,232.07]],"batl":[[0,1.37,511.05],[2,1.39,240.99]],"ltp":1.39,"tv":27307.62,"id":8681938}]}]}
{"op":"mcm","clk":"4297272947","pt":1632572567902,"mc":[{"id":"1.188134680","rc":[{"batb":[[0,1.35,271.23]],"batl":[[2,1.39,60]],"ltp":1.39,"tv":27307.62,"id":8681938}]}]}
{"op":"mcm","clk":"4297273205","pt":1632572569107,"mc":[{"id":"1.188134680","rc":[{"batl":[[0,1.36,300],[1,1.37,511.05],[2,1.38,541.07]],"ltp":1.39,"tv":27307.62,"id":8681938}]}]}
{"op":"mcm","clk":"4297273271","pt":1632572569423,"mc":[{"id":"1.188134680","rc":[{"batl":[[2,3.95,2]],"ltp":3.65,"tv":3676.42,"id":9631939},{"batb":[[1,1.34,666.4],[2,1.33,1092.03]],"ltp":1.39,"tv":27307.62,"id":8681938}]}]}
{"op":"mcm","clk":"4297273647","pt":1632572571095,"mc":[{"id":"1.188134680","rc":[{"trd":[[3.75,109.7]],"ltp":3.75,"tv":3682.18,"id":9631939},{"trd":[[1.36,362.52]],"batl":[[0,1.36,284.11]],"ltp":1.36,"tv":27323.51,"id":8681938}],"tv":31005.7}]}
{"op":"mcm","clk":"4297273792","pt":1632572571791,"mc":[{"id":"1.188134680","rc":[{"trd":[[1.36,395.88]],"batl":[[0,1.36,564.43]],"ltp":1.36,"tv":27356.87,"id":8681938}],"tv":31039.06}]}
{"op":"mcm","clk":"4297274524","pt":1632572575197,"mc":[{"id":"1.188134680","rc":[{"trd":[[1.36,429.24]],"batl":[[0,1.36,547.75]],"ltp":1.36,"tv":27390.23,"id":8681938}],"tv":31072.42}]}
{"op":"mcm","clk":"4297275054","pt":1632572578026,"mc":[{"id":"1.188134680","rc":[{"trd":[[1.36,429.32]],"batl":[[0,1.36,547.71]],"ltp":1.36,"tv":27390.31,"id":8681938}],"tv":31072.5}]}
{"op":"mcm","clk":"4297275325","pt":1632572579244,"mc":[{"id":"1.188134680","rc":[{"batb":[[0,3.55,25.52],[1,3.5,110.64],[2,3.45,136.88]],"batl":[[0,3.95,2],[1,4.1,36.07],[2,4.2,113.21]],"ltp":3.75,"tv":3682.18,"id":9631939},{"batb":[[0,1.35,200],[1,1.34,34.72],[2,1.33,39.53]],"batl":[[1,1.37,2.35],[2,1.38,350.26]],"ltp":1.36,"tv":27390.31,"id":8681938}]}]}
{"op":"mcm","clk":"4297275577","pt":1632572580326,"mc":[{"id":"1.188134680","rc":[{"batb":[[0,3.55,2]],"batl":[[1,4.1,2]],"ltp":3.75,"tv":3682.18,"id":9631939},{"batl":[[0,1.37,2.35],[1,1.38,350.26],[2,1.39,30.5]],"ltp":1.36,"tv":27390.31,"id":8681938}]}]}
{"op":"mcm","clk":"4297275788","pt":1632572581254,"mc":[{"id":"1.188134680","rc":[{"batb":[[2,3.45,139.88]],"ltp":3.75,"tv":3682.18,"id":9631939}]}]}
{"op":"mcm","clk":"4297276012","pt":1632572582200,"mc":[{"id":"1.188134680","rc":[{"batl":[[2,1.39,557.96]],"ltp":1.36,"tv":27390.31,"id":8681938}]}]}
{"op":"mcm","clk":"4297276162","pt":1632572582906,"mc":[{"id":"1.188134680","rc":[{"batb":[[0,3.6,2],[1,3.55,5],[2,3.5,110.64]],"ltp":3.75,"tv":3682.18,"id":9631939},{"batb":[[0,1.36,2.35],[1,1.35,200],[2,1.34,34.72]],"ltp":1.36,"tv":27390.31,"id":8681938}]}]}
{"op":"mcm","clk":"4297276275","pt":1632572583445,"mc":[{"id":"1.188134680","rc":[{"batb":[[2,3.5,108.6]],"batl":[[2,5.5,117.37]],"ltp":3.75,"tv":3682.18,"id":9631939}]}]}
{"op":"mcm","clk":"4297276878","pt":1632572586349,"mc":[{"id":"1.188134680","rc":[{"trd":[[3.7,136.06]],"batb":[[0,3.55,2],[1,3.5,132.65],[2,3.45,136.88]],"batl":[[0,3.7,5.33],[1,3.85,189.93],[2,3.9,186.87]],"ltp":3.7,"tv":3683.05,"id":9631939},{"trd":[[1.37,898.31]],"batb":[[0,1.36,1739.54],[1,1.35,232.47]],"batl":[[0,1.38,350.26],[1,1.39,572.53],[2,1.4,67.62]],"ltp":1.37,"tv":27392.66,"id":8681938}],"tv":31075.72}]}
{"op":"mcm","clk":"4297277116","pt":1632572587324,"mc":[{"id":"1.188134680","rc":[{"batb":[[1,3.5,804.09],[2,3.45,472.6]],"batl":[[2,3.9,74.79]],"ltp":3.7,"tv":3683.05,"id":9631939},{"batb":[[0,1.36,593.31],[1,1.35,1247.04],[2,1.34,633.41]],"ltp":1.37,"tv":27392.66,"id":8681938}]}]}
{"op":"mcm","clk":"4297277290","pt":1632572588240,"mc":[{"id":"1.188134680","rc":[{"batb":[[1,3.5,266.93],[2,3.45,228.5]],"ltp":3.7,"tv":3683.05,"id":9631939}]}]}
{"op":"mcm","clk":"4297277618","pt":1632572589816,"mc":[{"id":"1.188134680","rc":[{"batb":[[0,3.55,12]],"ltp":3.7,"tv":3683.05,"id":9631939},{"batl":[[1,1.39,536.68]],"ltp":1.37,"tv":27392.66,"id":8681938}]}]}
{"op":"mcm","clk":"4297277955","pt":1632572591335,"mc":[{"id":"1.188134680","rc":[{"trd":[[3.7,137.04]],"batl":[[0,3.7,4.35]],"ltp":3.7,"tv":3684.03,"id":9631939},{"trd":[[1.37,900.96]],"ltp":1.37,"tv":27395.31,"id":8681938}],"tv":31079.35}]}
{"op":"mcm","clk":"4297278176","pt":1632572592325,"mc":[{"id":"1.188134680","rc":[{"trd":[[3.7,137.15]],"batl":[[0,3.7,4.24]],"ltp":3.7,"tv":3684.14,"id":9631939},{"trd":[[1.37,901.27]],"ltp":1.37,"tv":27395.62,"id":8681938}],"tv":31079.77}]}
{"op":"mcm","clk":"4297278380","pt":1632572593347,"mc":[{"id":"1.188134680","rc":[{"trd":[[1.38,1473.34]],"batb":[[0,1.37,200],[1,1.36,593.31],[2,1.35,1247.04]],"batl":[[0,1.38,156.37]],"ltp":1.38,"tv":28195.62,"id":8681938}],"tv":31879.76}]}
{"op":"mcm","clk":"4297278576","pt":1632572594277,"mc":[{"id":"1.188134680","rc":[{"trd":[[1.38,1786.08]],"batb":[[0,1.38,443.63],[1,1.37,200],[2,1.36,593.31]],"batl":[[0,1.39,536.68],[1,1.4,67.62],[2,1.41,388.28]],"ltp":1.38,"tv":28508.36,"id":8681938}],"tv":32192.5}]}
{"op":"mcm","clk":"4297278598","pt":1632572594384,"mc":[{"id":"1.188134680","rc":[{"batb":[[0,1.38,643.63]],"ltp":1.38,"tv":28508.36,"id":8681938}]}]}
{"op":"mcm","clk":"4297279134","pt":1632572596790,"mc":[{"id":"1.188134680","rc":[{"batl":[[0,3.85,189.93],[1,3.9,64.79],[2,3.95,63.04]],"ltp":3.7,"tv":3684.14,"id":9631939},{"trd":[[1.38,2251.34]],"batb":[[0,1.38,411]],"batl":[[0,1.39,675.63],[1,1.4,538.12]],"ltp":1.38,"tv":28973.62,"id":8681938}],"tv":32657.76}]}
{"op":"mcm","clk":"4297279451","pt":1632572598281,"mc":[{"id":"1.188134680","rc":[{"trd":[[1.38,2533.14]],"batb":[[0,1.38,270.1],[1,1.37,237.04]],"ltp":1.38,"tv":29255.42,"id":8681938}],"tv":32939.57}]}
{"op":"mcm","clk":"4297279710","pt":1632572599382,"mc":[{"id":"1.188134680","rc":[{"batb":[[0,3.6,4.44],[1,3.55,12],[2,3.5,266.93]],"batl":[[0,3.7,4.24],[1,3.85,189.93],[2,3.9,64.79]],"ltp":3.7,"tv":3684.14,"id":9631939}]}]}
{"op":"mcm","clk":"4297279835","pt":1632572599987,"mc":[{"id":"1.188134680","rc":[{"batl":[[1,3.85,204.72]],"ltp":3.7,"tv":3684.14,"id":9631939},{"trd":[[1.38,3073.34]],"batb":[[0,1.37,237.04],[1,1.36,593.31],[2,1.35,1447.26]],"batl":[[0,1.38,859.27],[1,1.39,675.63],[2,1.4,538.12]],"ltp":1.38,"tv":29795.62,"id":8681938}],"tv":33479.77}]}
{"op":"mcm","clk":"4297280092","pt":1632572601383,"mc":[{"id":"1.188134680","rc":[{"batb":[[0,3.55,12],[1,3.5,266.93],[2,3.45,228.5]],"batl":[[0,3.85,204.72],[1,3.9,64.79],[2,3.95,63.04]],"ltp":3.7,"tv":3684.14,"id":9631939}]}]}
{"op":"mcm","clk":"4297280136","pt":1632572601600,"mc":[{"id":"1.188134680","rc":[{"trd":[[1.38,3873.34]],"batl":[[0,1.38,459.27]],"ltp":1.38,"tv":30595.62,"id":8681938}],"tv":34279.77}]}
{"op":"mcm","clk":"4297280359","pt":1632572602578,"mc":[{"id":"1.188134680","rc":[{"trd":[[1.38,4673.34]],"batl":[[0,1.38,59.27]],"ltp":1.38,"tv":31395.62,"id":8681938}],"tv":35079.77}]}
{"op":"mcm","clk":"4297280699","pt":1632572604093,"mc":[{"id":"1.188134680","rc":[{"batb":[[0,1.37,200]],"ltp":1.38,"tv":31395.62,"id":8681938}]}]}
{"op":"mcm","clk":"4297281328","pt":1632572607121,"mc":[{"id":"1.188134680","rc":[{"trd":[[1.38,5073.34]],"batb":[[1,1.36,631.38]],"batl":[[0,1.38,276]],"ltp":1.38,"tv":31795.62,"id":8681938}],"tv":35479.77}]}
{"op":"mcm","clk":"4297281549","pt":1632572608156,"mc":[{"id":"1.188134680","rc":[{"batb":[[0,3.6,4.44],[1,3.55,12],[2,3.5,266.93]],"batl":[[0,3.7,4.24],[1,3.85,204.72],[2,3.9,64.79]],"ltp":3.7,"tv":3684.14,"id":9631939},{"batb":[[0,1.37,237.04]],"ltp":1.38,"tv":31795.62,"id":8681938}]}]}
{"op":"mcm","clk":"4297281900","pt":1632572609788,"mc":[{"id":"1.188134680","rc":[{"batl":[[0,1.38,655]],"ltp":1.38,"tv":31795.62,"id":8681938}]}]}
{"op":"mcm","clk":"4297282850","pt":1632572614014,"mc":[{"id":"1.188134680","rc":[{"trd":[[1.38,5445]],"batb":[[0,1.37,200]],"batl":[[0,1.38,469.17]],"ltp":1.38,"tv":32167.28,"id":8681938}],"tv":35851.43}]}
{"op":"mcm","clk":"4297283504","pt":1632572617180,"mc":[{"id":"1.188134680","rc":[{"batb":[[0,1.37,400]],"ltp":1.38,"tv":32167.28,"id":8681938}]}]}
{"op":"mcm","clk":"4297283578","pt":1632572617601,"mc":[{"id":"1.188134680","rc":[{"batb":[[0,1.37,600]],"batl":[[0,1.38,827]],"ltp":1.38,"tv":32167.28,"id":8681938}]}]}
{"op":"mcm","clk":"4297283861","pt":1632572618889,"mc":[{"id":"1.188134680","rc":[{"trd":[[1.37,1183.07]],"batb":[[0,1.37,459.1]],"ltp":1.37,"tv":32449.08,"id":8681938}],"tv":36133.23}]}
{"op":"mcm","clk":"4297285030","pt":1632572624215,"mc":[{"id":"1.188134680","rc":[{"trd":[[1.37,1183.26]],"batb":[[0,1.37,459.01]],"ltp":1.37,"tv":32449.27,"id":8681938}],"tv":36133.42}]}
{"op":"mcm","clk":"4297285720","pt":1632572627490,"mc":[{"id":"1.188134680","rc":[{"batl":[[0,1.38,1326]],"ltp":1.37,"tv":32449.27,"id":8681938}]}]}
{"op":"mcm","clk":"4297286103","pt":1632572629417,"mc":[{"id":"1.188134680","rc":[{"trd":[[1.37,1211.44]],"batb":[[0,1.37,444.92]],"ltp":1.37,"tv":32477.45,"id":8681938}],"tv":36161.6}]}
{"op":"mcm","clk":"4297286839","pt":1632572632919,"mc":[{"id":"1.188134680","rc":[{"trd":[[1.38,5869.77]],"batl":[[0,1.38,1113.62]],"ltp":1.38,"tv":32902.21,"id":8681938}],"tv":36586.36}]}
{"op":"mcm","clk":"4297287764","pt":1632572637276,"mc":[{"id":"1.188134680","rc":[{"trd":[[1.37,1211.62]],"batb":[[0,1.37,444.83]],"ltp":1.37,"tv":32902.39,"id":8681938}],"tv":36586.54}]}
{"op":"mcm","clk":"4297288019","pt":1632572638513,"mc":[{"id":"1.188134680","rc":[{"batb":[[2,1.35,1247.26]],"ltp":1.37,"tv":32902.39,"id":8681938}]}]}
{"op":"mcm","clk":"4297290568","pt":1632572650425,"mc":[{"id":"1.188134680","rc":[{"trd":[[1.37,1216.76]],"batb":[[0,1.37,442.26]],"ltp":1.37,"tv":32907.54,"id":8681938}],"tv":36591.68}]}
{"op":"mcm","clk":"4297291246","pt":1632572653747,"mc":[{"id":"1.188134680","rc":[{"trd":[[1.38,5883.86]],"batl":[[0,1.38,1106.57]],"ltp":1.38,"tv":32921.63,"id":8681938}],"tv":36605.78}]}
{"op":"mcm","clk":"4297291580","pt":1632572655422,"mc":[{"id":"1.188134680","rc":[{"trd":[[1.37,1251.98]],"batb":[[0,1.37,424.65]],"ltp":1.37,"tv":32956.85,"id":8681938}],"tv":36641.0}]}
{"op":"mcm","clk":"4297293479","pt":1632572664275,"mc":[{"id":"1.188134680","rc":[{"batb":[[1,1.36,593.31]],"ltp":1.37,"tv":32956.85,"id":8681938}]}]}
{"op":"mcm","clk":"4297293643","pt":1632572665058,"mc":[{"id":"1.188134680","rc":[{"trd":[[1.38,5884.26]],"batl":[[0,1.38,1106.37]],"ltp":1.38,"tv":32957.25,"id":8681938}],"tv":36641.4}]}
{"op":"mcm","clk":"4297295386","pt":1632572674351,"mc":[{"id":"1.188134680","rc":[{"batb":[[2,3.5,132.65]],"batl":[[1,3.85,82.64],[2,3.9,3.75]],"ltp":3.7,"tv":3684.14,"id":9631939},{"batb":[[1,1.35,1247.26],[2,1.34,633.41]],"ltp":1.38,"tv":32957.25,"id":8681938}]}]}
{"op":"mcm","clk":"4297295475","pt":1632572674745,"mc":[{"id":"1.188134680","rc":[{"batb":[[0,3.45,24.48],[1,3.05,277.94],[2,3,172.93]],"batl":[[0,3.95,2],[1,4,34.64],[2,4.1,91.45]],"ltp":3.7,"tv":3684.14,"id":9631939},{"batb":[[1,1.34,34.72],[2,1.33,104.44]],"batl":[[1,1.41,60],[2,1.48,283.93]],"ltp":1.38,"tv":32957.25,"id":8681938}]}]}
{"op":"mcm","clk":"4297295817","pt":1632572676353,"mc":[{"id":"1.188134680","rc":[{"batb":[[0,3.05,277.94],[1,3,172.93],[2,2.44,11.53]],"batl":[[1,4.1,91.45],[2,4.2,134.22]],"ltp":3.7,"tv":3684.14,"id":9631939},{"batb":[[2,1.32,768.4]],"batl":[[0,1.48,283.93],[1,1.49,288.95],[2,1.93,2.55]],"ltp":1.38,"tv":32957.25,"id":8681938}]}]}
{"op":"mcm","clk":"4297295983","pt":1632572677153,"mc":[{"id":"1.188134680","rc":[{"batb":[[0,3.35,3],[1,3.15,2.03],[2,3.05,277.94]],"ltp":3.7,"tv":3684.14,"id":9631939},{"batl":[[0,1.46,27.06],[1,1.48,283.62],[2,1.49,288.95]],"ltp":1.38,"tv":32957.25,"id":8681938}]}]}
{"op":"mcm","clk":"4297296187","pt":1632572678247,"mc":[{"id":"1.188134680","rc":[{"batb":[[0,3.15,2.03],[1,3.05,277.94],[2,3,172.93]],"batl":[[0,3.9,2.09],[1,3.95,2],[2,4.1,91.45]],"ltp":3.7,"tv":3684.14,"id":9631939},{"batb":[[1,1.35,35.27],[2,1.34,34.72]],"ltp":1.38,"tv":32957.25,"id":8681938}]}]}
{"op":"mcm","clk":"4297296325","pt":1632572679047,"mc":[{"id":"1.188134680","rc":[{"batl":[[0,3.95,2.09],[1,4.1,91.45],[2,4.2,134.22]],"ltp":3.7,"tv":3684.14,"id":9631939},{"batb":[[0,1.34,34.72],[1,1.32,768.4],[2,1.31,339.31]],"ltp":1.38,"tv":32957.25,"id":8681938}]}]}
{"op":"mcm","clk":"4297296568","pt":1632572680360,"mc":[{"id":"1.188134680","rc":[{"batb":[[0,3.25,2],[1,3.15,5.03],[2,3.1,3]],"ltp":3.7,"tv":3684.14,"id":9631939},{"batb":[[0,1.38,20],[1,1.34,34.72],[2,1.32,768.4]],"batl":[[0,1.44,24.39],[1,1.45,7],[2,1.46,31.75]],"ltp":1.38,"tv":32957.25,"id":8681938}]}]}
{"op":"mcm","clk":"4297296742","pt":1632572681254,"mc":[{"id":"1.188134680","rc":[{"batb":[[0,3.15,5.03],[1,3.1,3],[2,3.05,279.94]],"ltp":3.7,"tv":3684.14,"id":9631939},{"batb":[[0,1.39,20],[1,1.38,20],[2,1.37,448.63]],"batl":[[0,1.4,402.81],[1,1.41,458.4],[2,1.45,7.31]],"ltp":1.38,"tv":32957.25,"id":8681938}]}]}
{"op":"mcm","clk":"4297296976","pt":1632572682278,"mc":[{"id":"1.188134680","rc":[{"batb":[[0,3.2,10.15],[1,3.15,5.03],[2,3.1,3]],"batl":[[0,3.9,5.09],[1,3.95,4],[2,4.1,91.45]],"ltp":3.7,"tv":3684.14,"id":9631939},{"batl":[[2,1.45,108.6]],"ltp":1.38,"tv":32957.25,"id":8681938}]}]}
{"op":"mcm","clk":"4297297352","pt":1632572684168,"mc":[{"id":"1.188134680","rc":[{"batb":[[0,3.25,2.01]],"ltp":3.7,"tv":3684.14,"id":9631939},{"batl":[[2,1.44,29.14]],"ltp":1.38,"tv":32957.25,"id":8681938}]}]}
{"op":"mcm","clk":"4297297582","pt":1632572685358,"mc":[{"id":"1.188134680","rc":[{"batl":[[0,3.9,13.54]],"ltp":3.7,"tv":3684.14,"id":9631939},{"batb":[[2,1.34,41.72]],"batl":[[0,1.4,209],[1,1.44,29.14],[2,1.45,7]],"ltp":1.38,"tv":32957.25,"id":8681938}]}]}
{"op":"mcm","clk":"4297297695","pt":1632572685967,"mc":[{"id":"1.188134680","rc":[{"batb":[[0,3.15,5.03],[1,3.1,3],[2,3.05,279.94]],"batl":[[0,3.9,3.09]],"ltp":3.7,"tv":3684.14,"id":9631939},{"batl":[[0,1.45,7.31],[1,1.46,31.75],[2,1.48,289.62]],"ltp":1.38,"tv":32957.25,"id":8681938}]}]}
{"op":"mcm","clk":"4297298020","pt":1632572687363,"mc":[{"id":"1.188134680","rc":[{"batb":[[0,3.3,10.15],[1,3.15,5.03],[2,3.1,3]],"ltp":3.7,"tv":3684.14,"id":9631939}]}]}
{"op":"mcm","clk":"4297298210","pt":1632572688248,"mc":[{"id":"1.188134680","rc":[{"batb":[[0,3.15,5.03],[1,3.1,3],[2,3.05,279.94]],"batl":[[0,3.9,5.09]],"ltp":3.7,"tv":3684.14,"id":9631939},{"batb":[[2,1.35,33.67]],"batl":[[2,1.47,649.94]],"ltp":1.38,"tv":32957.25,"id":8681938}]}]}
{"op":"mcm","clk":"4297298423","pt":1632572689358,"mc":[{"id":"1.188134680","rc":[{"trd":[[3.6,5.4]],"batb":[[0,3.25,2],[1,3.15,5.03],[2,3.1,3]],"batl":[[0,3.9,3]],"ltp":3.6,"tv":3684.24,"id":9631939},{"trd":[[1.38,5884.51]],"batb":[[0,1.34,41.72],[1,1.33,560.72],[2,1.32,1410.58]],"batl":[[0,1.44,30.64],[1,1.45,7],[2,1.46,31.75]],"ltp":1.38,"tv":32957.5,"id":8681938}],"tv":36641.74}]}
{"op":"mcm","clk":"4297298486","pt":1632572689653,"mc":[{"id":"1.188134680","rc":[{"batb":[[0,3.15,5.03],[1,3.1,3],[2,3.05,279.94]],"ltp":3.6,"tv":3684.24,"id":9631939},{"batl":[[0,1.45,7.31],[1,1.46,31.75],[2,1.47,649.94]],"ltp":1.38,"tv":32957.5,"id":8681938}]}]}
{"op":"mcm","clk":"4297299007","pt":1632572692347,"mc":[{"id":"1.188134680","rc":[{"batb":[[1,3.05,277.94],[2,3,172.93]],"ltp":3.6,"tv":3684.24,"id":9631939},{"batl":[[1,1.46,26.75]],"ltp":1.38,"tv":32957.5,"id":8681938}]}]}
{"op":"mcm","clk":"4297299511","pt":1632572695159,"mc":[{"id":"1.188134680","rc":[{"batb":[[0,3.2,2],[1,3.15,5.03],[2,3.05,277.94]],"ltp":3.6,"tv":3684.24,"id":9631939}]}]}
{"op":"mcm","clk":"4297299678","pt":1632572696058,"mc":[{"id":"1.188134680","rc":[{"batb":[[0,3.25,3],[1,3.2,2],[2,3.15,5.03]],"batl":[[1,3.95,2]],"ltp":3.6,"tv":3684.24,"id":9631939},{"batb":[[1,1.33,553.72]],"batl":[[0,1.44,6.31],[1,1.45,7],[2,1.46,26.75]],"ltp":1.38,"tv":32957.5,"id":8681938}]}]}
{"op":"mcm","clk":"4297300363","pt":1632572699372,"mc":[{"id":"1.188134680","rc":[{"trd":[[1.43,13.98],[1.44,12],[1.45,26.58]],"batb":[[1,1.33,559.72]],"batl":[[0,1.44,1109.39],[1,1.45,6.26]],"ltp":1.45,"tv":32971.59,"id":8681938}],"tv":36655.84}]}
{"op":"mcm","clk":"4297300497","pt":1632572700077,"mc":[{"id":"1.188134680","rc":[{"batb":[[0,3.25,5]],"ltp":3.6,"tv":3684.24,"id":9631939},{"batl":[[0,1.44,1136.22]],"ltp":1.45,"tv":32971.59,"id":8681938}]}]}
{"op":"mcm","clk":"4297301452","pt":1632572704306,"mc":[{"id":"1.188134680","rc":[{"batb":[[0,3.75,53.3],[1,3.25,5],[2,3.2,2]],"batl":[[0,3.95,2],[1,4,4.54]],"ltp":3.6,"tv":3684.24,"id":9631939},{"batb":[[0,1.34,34.72],[1,1.33,443.68]],"batl":[[0,1.35,16.82],[1,1.36,1054.01],[2,1.37,2265.75]],"ltp":1.45,"tv":32971.59,"id":8681938}]}]}
{"op":"mcm","clk":"4297301665","pt":1632572705279,"mc":[{"id":"1.188134680","rc":[{"batb":[[0,3.75,144.7],[1,3.6,23.07],[2,3.35,120.23]],"ltp":3.6,"tv":3684.24,"id":9631939},{"batl":[[2,1.37,1218.76]],"ltp":1.45,"tv":32971.59,"id":8681938}]}]}
{"op":"mcm","clk":"4297302070","pt":1632572707215,"mc":[{"id":"1.188134680","rc":[{"batl":[[1,1.36,1126.96]],"ltp":1.45,"tv":32971.59,"id":8681938}]}]}
{"op":"mcm","clk":"4297302269","pt":1632572708191,"mc":[{"id":"1.188134680","rc":[{"batb":[[0,1.34,110.73]],"batl":[[0,1.35,80.24]],"ltp":1.45,"tv":32971.59,"id":8681938}]}]}
{"op":"mcm","clk":"4297302480","pt":1632572709299,"mc":[{"id":"1.188134680","rc":[{"trd":[[3.95,2],[4,99.39]],"batb":[[1,3.35,120.23],[2,3.3,28]],"batl":[[0,4.1,91.45],[1,4.2,434.6],[2,4.3,260.98]],"ltp":4.0,"tv":3690.78,"id":9631939},{"trd":[[1.33,1337.37],[1.34,346.3]],"batb":[[0,1.32,1410.58],[1,1.31,339.31],[2,1.3,479.49]],"batl":[[0,1.33,627.14],[1,1.35,80.24],[2,1.36,1057.16]],"ltp":1.33,"tv":34100.0,"id":8681938}],"tv":37790.79}]}
{"op":"mcm","clk":"4297302685","pt":1632572710271,"mc":[{"id":"1.188134680","rc":[{"batl":[[1,1.35,422.24]],"ltp":1.33,"tv":34100.0,"id":8681938}]}]}
{"op":"mcm","clk":"4297302858","pt":1632572711084,"mc":[{"id":"1.188134680","rc":[{"batb":[[1,3.55,2],[2,3.4,2]],"batl":[[0,4.1,93.45],[1,4.2,436.6],[2,4.3,382.79]],"ltp":4.0,"tv":3690.78,"id":9631939},{"trd":[[1.33,1404.43]],"batb":[[0,1.32,1448.97],[2,1.3,804.86]],"batl":[[0,1.33,593.61]],"ltp":1.33,"tv":34167.06,"id":8681938}],"tv":37857.85}]}
{"op":"mcm","clk":"4297303092","pt":1632572712191,"mc":[{"id":"1.188134680","rc":[{"batb":[[1,3.65,22.64],[2,3.55,2]],"batl":[[0,4.1,109.78]],"ltp":4.0,"tv":3690.78,"id":9631939},{"trd":[[1.33,1484.53]],"batb":[[0,1.32,1656.55],[1,1.31,1125.46]],"batl":[[0,1.33,553.56],[1,1.35,728.79]],"ltp":1.33,"tv":34247.16,"id":8681938}],"tv":37937.95}]}
{"op":"mcm","clk":"4297303280","pt":1632572713079,"mc":[{"id":"1.188134680","rc":[{"batl":[[2,4.3,384.79]],"ltp":4.0,"tv":3690.78,"id":9631939},{"trd":[[1.33,2888.16],[1.35,641.08]],"batb":[[0,1.33,9],[1,1.32,1732.24],[2,1.31,1167.25]],"batl":[[0,1.35,653.02],[1,1.36,1069.8],[2,1.37,698]],"ltp":1.35,"tv":36180.33,"id":8681938}],"tv":39871.12}]}
{"op":"mcm","clk":"4297303917","pt":1632572716193,"mc":[{"id":"1.188134680","rc":[{"batl":[[1,1.36,559.1]],"ltp":1.35,"tv":36180.33,"id":8681938}]}]}
{"op":"mcm","clk":"4297304473","pt":1632572719085,"mc":[{"id":"1.188134680","rc":[{"batl":[[0,1.35,855.55]],"ltp":1.35,"tv":36180.33,"id":8681938}]}]}
{"op":"mcm","clk":"4297304859","pt":1632572721196,"mc":[{"id":"1.188134680","rc":[{"batb":[[0,3.75,169.7]],"ltp":4.0,"tv":3690.78,"id":9631939}]}]}
{"op":"mcm","clk":"4297305052","pt":1632572722008,"mc":[{"id":"1.188134680","rc":[{"batl":[[0,4,5.68],[1,4.1,109.78],[2,4.2,436.6]],"ltp":4.0,"tv":3690.78,"id":9631939},{"batl":[[0,1.35,869.01]],"ltp":1.35,"tv":36180.33,"id":8681938}]}]}
{"op":"mcm","clk":"4297305272","pt":1632572723190,"mc":[{"id":"1.188134680","rc":[{"batb":[[0,3.65,22.64],[1,3.35,118.96],[2,3.3,126.37]],"batl":[[0,4.3,154.83],[1,4.4,135.93],[2,5.8,2.54]],"ltp":4.0,"tv":3690.78,"id":9631939},{"batb":[[0,1.32,114.07],[1,1.31,467.7],[2,1.3,850.55]],"batl":[[0,1.35,549],[1,1.36,12.64],[2,1.38,60]],"ltp":1.35,"tv":36180.33,"id":8681938}]}]}
{"op":"mcm","clk":"4297305492","pt":1632572724318,"mc":[{"id":"1.188134680","rc":[{"batb":[[0,3.35,118.96],[1,3.3,126.37],[2,3.25,120.79]],"batl":[[0,4.3,121.81]],"ltp":4.0,"tv":3690.78,"id":9631939},{"batb":[[0,1.35,14.09],[1,1.32,114.07],[2,1.31,359.94]],"batl":[[0,1.36,12.64],[1,1.41,27.5],[2,1.43,288.58]],"ltp":1.35,"tv":36180.33,"id":8681938}]}]}
{"op":"mcm","clk":"4297305551","pt":1632572724634,"mc":[{"id":"1.188134680","rc":[{"batb":[[1,1.32,38.39]],"ltp":1.35,"tv":36180.33,"id":8681938}]}]}
{"op":"mcm","clk":"4297305859","pt":1632572726228,"mc":[{"id":"1.188134680","rc":[{"batl":[[0,4.3,124.81]],"ltp":4.0,"tv":3690.78,"id":9631939},{"batl":[[1,1.41,642.42],[2,1.42,445.57]],"ltp":1.35,"tv":36180.33,"id":8681938}]}]}
{"op":"mcm","clk":"4297306078","pt":1632572727248,"mc":[{"id":"1.188134680","rc":[{"trd":[[1.36,454.6]],"batb":[[0,1.37,257.85],[1,1.35,14.09],[2,1.32,38.39]],"batl":[[0,1.41,642.42],[1,1.42,445.57],[2,1.43,288.58]],"ltp":1.36,"tv":36205.62,"id":8681938}],"tv":39896.4}]}
{"op":"mcm","clk":"4297306771","pt":1632572730539,"mc":[{"id":"1.188134680","rc":[{"batb":[[0,3.4,3],[1,3.35,121.96],[2,3.3,126.37]],"ltp":4.0,"tv":3690.78,"id":9631939},{"batl":[[0,1.41,649.42]],"ltp":1.36,"tv":36205.62,"id":8681938}]}]}
{"op":"mcm","clk":"4297307794","pt":1632572735358,"mc":[{"id":"1.188134680","rc":[{"batb":[[2,3.3,3]],"ltp":4.0,"tv":3690.78,"id":9631939},{"batb":[[0,1.35,14.09],[1,1.32,38.39],[2,1.31,359.94]],"batl":[[0,1.41,34.5],[1,1.43,5],[2,1.48,2.35]],"ltp":1.36,"tv":36205.62,"id":8681938}]}]}
{"op":"mcm","clk":"4297308543","pt":1632572738351,"mc":[{"id":"1.188134680","rc":[{"batb":[[0,4,58.75],[1,3.95,88.87],[2,3.9,267.16]],"batl":[[1,4.4,187.37]],"ltp":4.0,"tv":3690.78,"id":9631939},{"trd":[[1.35,669.26]],"batb":[[0,1.32,38.39],[1,1.31,374.17],[2,1.3,1503.79]],"batl":[[0,1.33,25.16],[1,1.34,1013.34],[2,1.35,581.26]],"ltp":1.35,"tv":36233.8,"id":8681938}],"tv":39924.58}]}
{"op":"mcm","clk":"4297308770","pt":1632572739341,"mc":[{"id":"1.188134680","rc":[{"batb":[[2,3.9,433.73]],"batl":[[1,4.4,294.19],[2,4.5,53.4]],"ltp":4.0,"tv":3690.78,"id":9631939}]}]}
{"op":"mcm","clk":"4297308954","pt":1632572740248,"mc":[{"id":"1.188134680","rc":[{"batl":[[0,4.3,141.08],[2,4.5,85.47]],"ltp":4.0,"tv":3690.78,"id":9631939}]}]}
{"op":"mcm","clk":"4297309121","pt":1632572741150,"mc":[{"id":"1.188134680","rc":[{"batl":[[2,4.5,53.4]],"ltp":4.0,"tv":3690.78,"id":9631939}]}]}
{"op":"mcm","clk":"4297309349","pt":1632572742239,"mc":[{"id":"1.188134680","rc":[{"batl":[[2,1.35,594.97]],"ltp":1.35,"tv":36233.8,"id":8681938}]}]}
{"op":"mcm","clk":"4297309595","pt":1632572743365,"mc":[{"id":"1.188134680","rc":[{"trd":[[1.32,292.2]],"batb":[[0,1.32,258.63],[1,1.31,448.91]],"batl":[[0,1.33,86.63],[1,1.34,1084.16],[2,1.35,581.26]],"ltp":1.32,"tv":36248.3,"id":8681938}],"tv":39939.08}]}
{"op":"mcm","clk":"4297309801","pt":1632572744341,"mc":[{"id":"1.188134680","rc":[{"batl":[[2,4.5,85.47]],"ltp":4.0,"tv":3690.78,"id":9631939}]}]}
{"op":"mcm","clk":"4297309954","pt":1632572745029,"mc":[{"id":"1.188134680","rc":[{"trd":[[4,99.58]],"batb":[[0,4,58.66]],"batl":[[0,4.2,2],[1,4.3,143.08],[2,4.4,294.19]],"ltp":4.0,"tv":3690.96,"id":9631939},{"batb":[[1,1.31,486.7]],"batl":[[0,1.33,376.63]],"ltp":1.32,"tv":36248.3,"id":8681938}],"tv":39939.26}]}
{"op":"mcm","clk":"4297310381","pt":1632572747239,"mc":[{"id":"1.188134680","rc":[{"batb":[[0,1.32,331.8]],"batl":[[0,1.33,448.21]],"ltp":1.32,"tv":36248.3,"id":8681938}]}]}
{"op":"mcm","clk":"4297310586","pt":1632572748170,"mc":[{"id":"1.188134680","rc":[{"trd":[[1.33,2892.86]],"batb":[[0,1.32,258.63],[1,1.31,411.96]],"batl":[[0,1.33,600.28],[1,1.34,1013.34]],"ltp":1.33,"tv":36253.0,"id":8681938}],"tv":39943.96}]}
{"op":"mcm","clk":"4297311326","pt":1632572751747,"mc":[{"id":"1.188134680","rc":[{"trd":[[1.33,3415.8]],"batl":[[0,1.33,338.81]],"ltp":1.33,"tv":36775.94,"id":8681938}],"tv":40466.9}]}
{"op":"mcm","clk":"4297312028","pt":1632572755663,"mc":[{"id":"1.188134680","rc":[{"batl":[[0,1.33,658]],"ltp":1.33,"tv":36775.94,"id":8681938}]}]}
{"op":"mcm","clk":"4297312452","pt":1632572758073,"mc":[{"id":"1.188134680","rc":[{"batb":[[0,3.9,166.57],[1,3.8,21.42],[2,3.75,2]],"batl":[[1,4.3,5],[2,4.5,149.38]],"ltp":4.0,"tv":3690.96,"id":9631939},{"batb":[[1,1.31,37.79],[2,1.3,479.49]],"batl":[[1,1.36,93.32],[2,1.37,75.08]],"ltp":1.33,"tv":36775.94,"id":8681938}]}]}
{"op":"mcm","clk":"4297312666","pt":1632572759307,"mc":[{"id":"1.188134680","rc":[{"batb":[[0,3.75,2],[1,3.65,137.5],[2,3.6,258.61]],"batl":[[2,4.5,117.31]],"ltp":4.0,"tv":3690.96,"id":9631939},{"batb":[[2,1.29,325.17]],"batl":[[0,1.36,33.32],[1,1.37,27.41],[2,1.38,322.04]],"ltp":1.33,"tv":36775.94,"id":8681938}]}]}
{"op":"mcm","clk":"4297312749","pt":1632572759678,"mc":[{"id":"1.188134680","rc":[{"batb":[[0,3.65,137.5],[1,3.6,258.61],[2,3.4,3]],"ltp":4.0,"tv":3690.96,"id":9631939},{"batl":[[0,1.37,27.41],[1,1.38,322.04],[2,1.39,324.49]],"ltp":1.33,"tv":36775.94,"id":8681938}]}]}
{"op":"mcm","clk":"4297313057","pt":1632572761352,"mc":[{"id":"1.188134680","rc":[{"batb":[[0,1.32,258.67]],"batl":[[2,1.39,313.67]],"ltp":1.33,"tv":36775.94,"id":8681938}]}]}
{"op":"mcm","clk":"4297313426","pt":1632572763158,"mc":[{"id":"1.188134680","rc":[{"batb":[[0,3.75,2],[1,3.7,3],[2,3.65,140.5]],"ltp":4.0,"tv":3690.96,"id":9631939},{"batl":[[0,1.37,33.41]],"ltp":1.33,"tv":36775.94,"id":8681938}]}]}
{"op":"mcm","clk":"4297313694","pt":1632572764349,"mc":[{"id":"1.188134680","rc":[{"batl":[[0,4.2,20.03]],"ltp":4.0,"tv":3690.96,"id":9631939},{"trd":[[1.33,3454.8]],"batb":[[0,1.33,328.13],[1,1.32,277.02],[2,1.31,814.53]],"batl":[[0,1.34,430.92],[1,1.35,564.49],[2,1.37,33.41]],"ltp":1.33,"tv":36814.93,"id":8681938}],"tv":40505.9}]}
{"op":"mcm","clk":"4297313740","pt":1632572764567,"mc":[{"id":"1.188134680","rc":[{"batl":[[0,4.2,2]],"ltp":4.0,"tv":3690.96,"id":9631939},{"batb":[[1,1.32,108.52]],"ltp":1.33,"tv":36814.93,"id":8681938}]}]}
{"op":"mcm","clk":"4297314154","pt":1632572766368,"mc":[{"id":"1.188134680","rc":[{"batb":[[0,3.8,10],[1,3.75,4.03],[2,3.7,3]],"batl":[[0,4.2,12]],"ltp":4.0,"tv":3690.96,"id":9631939},{"batl":[[2,1.36,92.04]],"ltp":1.33,"tv":36814.93,"id":8681938}]}]}
{"op":"mcm","clk":"4297314587","pt":1632572768266,"mc":[{"id":"1.188134680","rc":[{"batb":[[0,3.75,2],[1,3.7,3],[2,3.65,140.5]],"batl":[[0,4.3,5],[1,4.5,117.31],[2,4.6,100.71]],"ltp":4.0,"tv":3690.96,"id":9631939},{"batb":[[0,1.31,37.79],[1,1.29,325.17],[2,1.28,963.28]],"batl":[[0,1.37,33.41],[1,1.38,322.04],[2,1.39,313.67]],"ltp":1.33,"tv":36814.93,"id":8681938}]}]}
{"op":"mcm","clk":"4297315234","pt":1632572771359,"mc":[{"id":"1.188134680","rc":[{"batb":[[0,3.75,4]],"ltp":4.0,"tv":3690.96,"id":9631939},{"batb":[[1,1.29,1331.29],[2,1.28,1736.66]],"batl":[[0,1.36,38.07],[1,1.37,588.46],[2,1.38,829.26]],"ltp":1.33,"tv":36814.93,"id":8681938}]}]}
{"op":"mcm","clk":"4297315328","pt":1632572771878,"mc":[{"id":"1.188134680","rc":[{"batb":[[0,3.75,2]],"ltp":4.0,"tv":3690.96,"id":9631939},{"batb":[[0,1.31,46.79],[1,1.3,8],[2,1.29,1331.29]],"batl":[[0,1.37,588.46],[1,1.38,829.26],[2,1.39,313.67]],"ltp":1.33,"tv":36814.93,"id":8681938}]}]}
{"op":"mcm","clk":"4297315543","pt":1632572772970,"mc":[{"id":"1.188134680","rc":[{"batl":[[1,5.8,2.54],[2,990,0.01]],"ltp":4.0,"tv":3690.96,"id":9631939},{"batb":[[2,1.28,513.48]],"ltp":1.33,"tv":36814.93,"id":8681938}]}]}
{"op":"mcm","clk":"4297315833","pt":1632572774373,"mc":[{"id":"1.188134680","rc":[{"batb":[[0,3.65,137.5],[1,3.6,258.61],[2,3.4,3]],"ltp":4.0,"tv":3690.96,"id":9631939},{"batb":[[0,1.34,2.82],[1,1.31,46.79],[2,1.3,8]],"batl":[[0,1.37,582.46]],"ltp":1.33,"tv":36814.93,"id":8681938}]}]}
{"op":"mcm","clk":"4297315972","pt":1632572775069,"mc":[{"id":"1.188134680","rc":[{"batb":[[0,3.75,2],[1,3.65,137.5],[2,3.6,258.61]],"batl":[[0,4.2,2],[1,4.3,5],[2,5.8,2.54]],"ltp":4.0,"tv":3690.96,"id":9631939},{"batb":[[1,1.32,37.64],[2,1.31,46.79]],"batl":[[0,1.36,37.32],[1,1.37,555.05],[2,1.38,829.26]],"ltp":1.33,"tv":36814.93,"id":8681938}]}]}
{"op":"mcm","clk":"4297316227","pt":1632572776369,"mc":[{"id":"1.188134680","rc":[{"batb":[[0,3.65,137.5],[1,3.6,258.61],[2,3.55,269.36]],"batl":[[0,3.85,9.15],[1,4.1,67.9],[2,4.3,11.98]],"ltp":4.0,"tv":3690.96,"id":9631939},{"batb":[[0,1.34,1346.89],[1,1.33,1340.38],[2,1.32,697.84]],"batl":[[0,1.37,555.05],[1,1.38,1060.5],[2,1.39,313.67]],"ltp":1.33,"tv":36814.93,"id":8681938}]}]}
{"op":"mcm","clk":"4297316431","pt":1632572777383,"mc":[{"id":"1.188134680","rc":[{"batb":[[2,3.55,292.88]],"batl":[[2,4.2,35.54]],"ltp":4.0,"tv":3690.96,"id":9631939},{"batb":[[0,1.34,1763.39],[2,1.32,3842.2]],"batl":[[1,1.38,1082.24],[2,1.39,373.67]],"ltp":1.33,"tv":36814.93,"id":8681938}]}]}
{"op":"mcm","clk":"4297316622","pt":1632572778302,"mc":[{"id":"1.188134680","rc":[{"batl":[[1,4.1,69.9],[2,4.2,60.54]],"ltp":4.0,"tv":3690.96,"id":9631939},{"batb":[[0,1.34,1777.49]],"ltp":1.33,"tv":36814.93,"id":8681938}]}]}
{"op":"mcm","clk":"4297316998","pt":1632572780190,"mc":[{"id":"1.188134680","rc":[{"batb":[[0,1.35,253.01],[1,1.34,1777.49],[2,1.33,1340.38]],"batl":[[0,1.36,65.35],[1,1.37,617.01],[2,1.38,1082.24]],"ltp":1.33,"tv":36814.93,"id":8681938}]}]}
{"op":"mcm","clk":"4297317089","pt":1632572780678,"mc":[{"id":"1.188134680","rc":[{"trd":[[1.35,705.64]],"batb":[[0,1.35,234.82],[1,1.34,1850.81]],"ltp":1.35,"tv":36851.31,"id":8681938}],"tv":40542.28}]}
{"op":"mcm","clk":"4297317618","pt":1632572783377,"mc":[{"id":"1.188134680","rc":[{"batl":[[1,4.1,71.9],[2,4.2,157.67]],"ltp":4.0,"tv":3690.96,"id":9631939},{"batb":[[2,1.33,1374.91]],"batl":[[0,1.36,354.35]],"ltp":1.35,"tv":36851.31,"id":8681938}]}]}
{"op":"mcm","clk":"4297317946","pt":1632572785001,"mc":[{"id":"1.188134680","rc":[{"batb":[[1,1.34,1777.49]],"batl":[[1,1.37,555.05]],"ltp":1.35,"tv":36851.31,"id":8681938}]}]}
{"op":"mcm","clk":"4297318290","pt":1632572786697,"mc":[{"id":"1.188134680","rc":[{"batl":[[0,1.36,558.35]],"ltp":1.35,"tv":36851.31,"id":8681938}]}]}
{"op":"mcm","clk":"4297318462","pt":1632572787492,"mc":[{"id":"1.188134680","rc":[{"batb":[[1,1.34,887.74]],"ltp":1.35,"tv":36851.31,"id":8681938}]}]}
{"op":"mcm","clk":"4297318793","pt":1632572789382,"mc":[{"id":"1.188134680","rc":[{"trd":[[1.35,706.03],[1.36,460.24]],"batb":[[0,1.35,234.63]],"batl":[[0,1.36,555.53]],"ltp":1.36,"tv":36857.34,"id":8681938}],"tv":40548.31}]}
{"op":"mcm","clk":"4297318910","pt":1632572789985,"mc":[{"id":"1.188134680","rc":[{"batl":[[2,4.2,155.67]],"ltp":4.0,"tv":3690.96,"id":9631939},{"batl":[[0,1.36,811.53]],"ltp":1.36,"tv":36857.34,"id":8681938}]}]}
{"op":"mcm","clk":"4297319303","pt":1632572791924,"mc":[{"id":"1.188134680","rc":[{"batb":[[1,1.34,884.92]],"ltp":1.36,"tv":36857.34,"id":8681938}]}]}
{"op":"mcm","clk":"4297320096","pt":1632572796278,"mc":[{"id":"1.188134680","rc":[{"batb":[[0,3.55,23.52],[1,3.5,2.04],[2,3.4,5.01]],"batl":[[0,4.1,2],[1,4.2,130.67],[2,4.3,141.64]],"ltp":4.0,"tv":3690.96,"id":9631939},{"batb":[[1,1.33,34.53],[2,1.32,158.2]],"batl":[[1,1.39,60],[2,1.4,42.99]],"ltp":1.36,"tv":36857.34,"id":8681938}]}]}
{"op":"mcm","clk":"4297320287","pt":1632572797298,"mc":[{"id":"1.188134680","rc":[{"batb":[[0,3.5,2.04],[1,3.4,5.01],[2,3.35,2.07]],"batl":[[1,4.2,97.13]],"ltp":4.0,"tv":3690.96,"id":9631939},{"batb":[[2,1.32,52.14]],"batl":[[0,1.36,62.53],[1,1.4,42.99],[2,1.41,27.5]],"ltp":1.36,"tv":36857.34,"id":8681938}]}]}
{"op":"mcm","clk":"4297320407","pt":1632572797899,"mc":[{"id":"1.188134680","rc":[{"batb":[[0,3.4,3],[1,3.35,2.07],[2,3.15,292.11]],"batl":[[0,4.2,97.13],[1,4.3,141.64],[2,5.8,2.54]],"ltp":4.0,"tv":3690.96,"id":9631939},{"batb":[[0,1.32,52.14],[1,1.31,769.47],[2,1.3,369.5]],"batl":[[0,1.4,11.8],[1,1.42,31.25],[2,1.47,310.19]],"ltp":1.36,"tv":36857.34,"id":8681938}]}]}
{"op":"mcm","clk":"4297320664","pt":1632572799083,"mc":[{"id":"1.188134680","rc":[{"batb":[[1,1.31,1714.87],[2,1.3,1078.1]],"batl":[[2,1.44,547.84]],"ltp":1.36,"tv":36857.34,"id":8681938}]}]}
{"op":"mcm","clk":"4297321079","pt":1632572801092,"mc":[{"id":"1.188134680","rc":[{"batb":[[0,3.5,2],[1,3.4,3],[2,3.35,5.07]],"batl":[[0,4.1,2],[1,4.2,99.13],[2,4.3,141.64]],"ltp":4.0,"tv":3690.96,"id":9631939},{"batb":[[0,1.33,34.53],[1,1.32,52.14],[2,1.31,1723.87]],"batl":[[0,1.4,43.64]],"ltp":1.36,"tv":36857.34,"id":8681938}]}]}
{"op":"mcm","clk":"4297321185","pt":1632572801608,"mc":[{"id":"1.188134680","rc":[{"batb":[[0,3.4,3.09],[1,3.35,5.07],[2,3.15,292.11]],"batl":[[0,4.2,99.13],[1,4.3,141.64],[2,5.8,2.54]],"ltp":4.0,"tv":3690.96,"id":9631939},{"batb":[[0,1.32,52.14],[1,1.31,1723.87],[2,1.3,1078.1]],"batl":[[0,1.4,11.8]],"ltp":1.36,"tv":36857.34,"id":8681938}]}]}
{"op":"mcm","clk":"4297322723","pt":1632572809326,"mc":[{"id":"1.188134680","rc":[{"batb":[[2,3.15,139.26]],"ltp":4.0,"tv":3690.96,"id":9631939},{"batl":[[2,1.48,2.35]],"ltp":1.36,"tv":36857.34,"id":8681938}]}]}
{"op":"mcm","clk":"4297323355","pt":1632572812370,"mc":[{"id":"1.188134680","rc":[{"batb":[[0,3.9,245.2],[1,3.85,237.98],[2,3.8,237.98]],"batl":[[2,4.4,1.71]],"ltp":4.0,"tv":3690.96,"id":9631939},{"batb":[[1,1.31,1260.24]],"batl":[[0,1.35,860.41],[1,1.36,539.38],[2,1.38,47.32]],"ltp":1.36,"tv":36857.34,"id":8681938}]}]}
{"op":"mcm","clk":"4297323569","pt":1632572813271,"mc":[{"id":"1.188134680","rc":[{"batl":[[2,4.4,34.24]],"ltp":4.0,"tv":3690.96,"id":9631939},{"trd":[[1.35,710.73]],"batb":[[2,1.3,1551.84]],"batl":[[0,1.35,858.06],[1,1.36,599.38],[2,1.42,31.25]],"ltp":1.35,"tv":36862.04,"id":8681938}],"tv":40553.01}]}
{"op":"mcm","clk":"4297323758","pt":1632572814142,"mc":[{"id":"1.188134680","rc":[{"batl":[[0,4.2,115.47],[2,4.4,1.71]],"ltp":4.0,"tv":3690.96,"id":9631939},{"batl":[[1,1.36,539.38],[2,1.39,59]],"ltp":1.35,"tv":36862.04,"id":8681938}]}]}
{"op":"mcm","clk":"4297324196","pt":1632572816082,"mc":[{"id":"1.188134680","rc":[{"batb":[[0,1.33,232.76],[1,1.32,52.14],[2,1.31,1260.24]],"batl":[[0,1.34,81.24],[1,1.35,858.06],[2,1.36,539.38]],"ltp":1.35,"tv":36862.04,"id":8681938}]}]}
{"op":"mcm","clk":"4297324673","pt":1632572818266,"mc":[{"id":"1.188134680","rc":[{"batb":[[1,3.85,239.98]],"batl":[[0,4.1,2],[1,4.2,115.47],[2,4.3,141.64]],"ltp":4.0,"tv":3690.96,"id":9631939},{"batb":[[0,1.33,266.29]],"batl":[[0,1.34,94.95],[1,1.35,894.76],[2,1.36,577.95]],"ltp":1.35,"tv":36862.04,"id":8681938}]}]}
{"op":"mcm","clk":"4297324854","pt":1632572819141,"mc":[{"id":"1.188134680","rc":[{"batl":[[0,1.34,362.95]],"ltp":1.35,"tv":36862.04,"id":8681938}]}]}
{"op":"mcm","clk":"4297325204","pt":1632572820976,"mc":[{"id":"1.188134680","rc":[{"batb":[[1,1.32,109.85]],"ltp":1.35,"tv":36862.04,"id":8681938}]}]}
{"op":"mcm","clk":"4297325579","pt":1632572822696,"mc":[{"id":"1.188134680","rc":[{"batl":[[0,1.34,582.95]],"ltp":1.35,"tv":36862.04,"id":8681938}]}]}
{"op":"mcm","clk":"4297326185","pt":1632572825270,"mc":[{"id":"1.188134680","rc":[{"trd":[[1.34,346.49]],"batl":[[0,1.34,582.85]],"ltp":1.34,"tv":36862.23,"id":8681938}],"tv":40553.2}]}
{"op":"mcm","clk":"4297326341","pt":1632572825969,"mc":[{"id":"1.188134680","rc":[{"trd":[[3.9,53.61]],"batb":[[0,3.9,224.64]],"ltp":3.9,"tv":3732.08,"id":9631939},{"batl":[[0,1.34,844.85]],"ltp":1.34,"tv":36862.23,"id":8681938}],"tv":40594.32}]}
{"op":"mcm","clk":"4297327521","pt":1632572832100,"mc":[{"id":"1.188134680","rc":[{"trd":[[1.34,346.8]],"batl":[[0,1.34,844.7]],"ltp":1.34,"tv":36862.54,"id":8681938}],"tv":40594.63}]}
{"op":"mcm","clk":"4297328097","pt":1632572835076,"mc":[{"id":"1.188134680","rc":[{"batb":[[0,3.85,2],[1,3.75,2],[2,3.6,99.12]],"batl":[[1,4.2,4],[2,4.3,2]],"ltp":3.9,"tv":3732.08,"id":9631939},{"batb":[[2,1.31,37.79]],"batl":[[1,1.35,36.7],[2,1.36,38.57]],"ltp":1.34,"tv":36862.54,"id":8681938}]}]}
{"op":"mcm","clk":"4297328216","pt":1632572835673,"mc":[{"id":"1.188134680","rc":[{"batl":[[0,1.34,94.7]],"ltp":1.34,"tv":36862.54,"id":8681938}]}]}
{"op":"mcm","clk":"4297328434","pt":1632572836774,"mc":[{"id":"1.188134680","rc":[{"batl":[[0,1.34,67.28]],"ltp":1.34,"tv":36862.54,"id":8681938}]}]}
{"op":"mcm","clk":"4297328693","pt":1632572838066,"mc":[{"id":"1.188134680","rc":[{"batl":[[0,4.1,5]],"ltp":3.9,"tv":3732.08,"id":9631939}]}]}
{"op":"mcm","clk":"4297329593","pt":1632572842502,"mc":[{"id":"1.188134680","rc":[{"batl":[[0,4.1,2]],"ltp":3.9,"tv":3732.08,"id":9631939}]}]}
{"op":"mcm","clk":"4297330044","pt":1632572844577,"mc":[{"id":"1.188134680","rc":[{"trd":[[1.34,346.99]],"batl":[[0,1.34,67.19]],"ltp":1.34,"tv":36862.73,"id":8681938}],"tv":40594.82}]}
{"op":"mcm","clk":"4297330227","pt":1632572845484,"mc":[{"id":"1.188134680","rc":[{"batl":[[0,1.34,237.19]],"ltp":1.34,"tv":36862.73,"id":8681938}]}]}
{"op":"mcm","clk":"4297330718","pt":1632572847982,"mc":[{"id":"1.188134680","rc":[{"trd":[[1.33,3584.8]],"batb":[[0,1.33,201.29]],"ltp":1.33,"tv":36992.74,"id":8681938}],"tv":40724.82}]}
{"op":"mcm","clk":"4297331063","pt":1632572849796,"mc":[{"id":"1.188134680","rc":[{"trd":[[1.33,3600.3]],"batb":[[0,1.33,193.54]],"ltp":1.33,"tv":37008.24,"id":8681938}],"tv":40740.32}]}
{"op":"mcm","clk":"4297333167","pt":1632572860310,"mc":[{"id":"1.188134680","rc":[{"batb":[[2,3.45,110.6]],"ltp":3.9,"tv":3732.08,"id":9631939},{"batb":[[0,1.33,33.53],[1,1.32,52.14]],"ltp":1.33,"tv":37008.24,"id":8681938}]}]}
{"op":"mcm","clk":"4297333230","pt":1632572860686,"mc":[{"id":"1.188134680","rc":[{"batl":[[0,4.2,4],[1,4.4,107.76],[2,4.5,134.79]],"ltp":3.9,"tv":3732.08,"id":9631939},{"batb":[[0,1.32,52.14],[1,1.3,1332.97],[2,1.29,1057.93]],"batl":[[0,1.34,67.19]],"ltp":1.33,"tv":37008.24,"id":8681938}]}]}
{"op":"mcm","clk":"4297333773","pt":1632572863367,"mc":[{"id":"1.188134680","rc":[{"trd":[[4.1,125.3]],"batb":[[0,4.1,45.1],[1,3.9,245.2],[2,3.85,239.98]],"batl":[[0,4.2,2],[2,4.5,178.5]],"ltp":4.1,"tv":3736.08,"id":9631939},{"trd":[[1.32,396.48]],"batb":[[0,1.31,16.05]],"batl":[[0,1.32,6862.98],[1,1.33,467.17],[2,1.34,652.73]],"ltp":1.32,"tv":37112.52,"id":8681938}],"tv":40848.6}]}
{"op":"mcm","clk":"4297333950","pt":1632572864279,"mc":[{"id":"1.188134680","rc":[{"batb":[[2,3.85,325.71]],"ltp":4.1,"tv":3736.08,"id":9631939},{"batl":[[0,1.32,548.82],[2,1.34,585.54]],"ltp":1.32,"tv":37112.52,"id":8681938}]}]}
{"op":"mcm","clk":"4297334154","pt":1632572865357,"mc":[{"id":"1.188134680","rc":[{"batb":[[1,3.9,255.2],[2,3.85,346.76]],"batl":[[2,4.5,210.57]],"ltp":4.1,"tv":3736.08,"id":9631939},{"batl":[[2,1.34,625.65]],"ltp":1.32,"tv":37112.52,"id":8681938}]}]}
{"op":"mcm","clk":"4297334515","pt":1632572867284,"mc":[{"id":"1.188134680","rc":[{"batb":[[0,1.31,195.92]],"batl":[[0,1.32,615.29]],"ltp":1.32,"tv":37112.52,"id":8681938}]}]}
{"op":"mcm","clk":"4297334663","pt":1632572868083,"mc":[{"id":"1.188134680","rc":[{"batb":[[1,1.3,1391.07]],"batl":[[1,1.33,530.94]],"ltp":1.32,"tv":37112.52,"id":8681938}]}]}
{"op":"mcm","clk":"4297335466","pt":1632572871892,"mc":[{"id":"1.188134680","rc":[{"trd":[[1.32,411.1]],"batl":[[0,1.32,607.98]],"ltp":1.32,"tv":37127.14,"id":8681938}],"tv":40863.23}]}
{"op":"mcm","clk":"4297335700","pt":1632572873194,"mc":[{"id":"1.188134680","rc":[{"batb":[[1,1.3,1332.97]],"batl":[[1,1.33,467.17]],"ltp":1.32,"tv":37127.14,"id":8681938}]}]}
{"op":"mcm","clk":"4297336042","pt":1632572875018,"mc":[{"id":"1.188134680","rc":[{"batl":[[0,1.32,66.47]],"ltp":1.32,"tv":37127.14,"id":8681938}]}]}
{"op":"mcm","clk":"4297337606","pt":1632572882937,"mc":[{"id":"1.188134680","rc":[{"trd":[[4.1,127.01]],"batb":[[0,4.1,44.24]],"ltp":4.1,"tv":3737.8,"id":9631939}],"tv":40864.94}]}
{"op":"mcm","clk":"4297338844","pt":1632572889302,"mc":[{"id":"1.188134680","rc":[{"batb":[[1,3.9,10],[2,3.85,108.78]],"ltp":4.1,"tv":3737.8,"id":9631939},{"batl":[[1,1.33,444.61]],"ltp":1.32,"tv":37127.14,"id":8681938}]}]}
{"op":"mcm","clk":"4297339011","pt":1632572890098,"mc":[{"id":"1.188134680","rc":[{"batb":[[0,3.85,21.05],[1,3.5,2.09],[2,3.4,118.07]],"batl":[[0,4.5,32.07],[1,5.8,2.54],[2,8.8,2]],"ltp":4.1,"tv":3737.8,"id":9631939},{"batb":[[0,1.28,113.38],[1,1.17,27.27],[2,1.16,1022.39]],"batl":[[0,1.35,60],[1,1.39,9.26],[2,1.4,29.74]],"ltp":1.32,"tv":37127.14,"id":8681938}]}]}
{"op":"mcm","clk":"4297339464","pt":1632572892030,"mc":[{"id":"1.188134680","rc":[{"batb":[[0,3.4,118.17],[1,3.35,2.07],[2,3.3,2.01]],"batl":[[0,5.8,2.54],[1,8.8,2],[2,15.5,2]],"ltp":4.1,"tv":3737.8,"id":9631939},{"batb":[[0,1.17,27.27],[1,1.16,1022.39],[2,1.13,97.73]],"batl":[[0,1.39,9.26],[1,1.42,31.25],[2,1.43,29.5]],"ltp":1.32,"tv":37127.14,"id":8681938}]}]}
{"op":"mcm","clk":"4297339732","pt":1632572893323,"mc":[{"id":"1.188134680","rc":[{"batb":[[0,3.5,2.09],[1,3.45,2],[2,3.4,118.07]],"ltp":4.1,"tv":3737.8,"id":9631939},{"batb":[[0,1.17,882.04],[1,1.16,2830.75]],"batl":[[1,1.41,889.96],[2,1.42,568.55]],"ltp":1.32,"tv":37127.14,"id":8681938}]}]}
{"op":"mcm","clk":"4297340081","pt":1632572895306,"mc":[{"id":"1.188134680","rc":[{"batb":[[0,3.5,4.13]],"ltp":4.1,"tv":3737.8,"id":9631939},{"batl":[[1,1.4,31.74],[2,1.41,889.96]],"ltp":1.32,"tv":37127.14,"id":8681938}]}]}
{"op":"mcm","clk":"4297340191","pt":1632572895928,"mc":[{"id":"1.188134680","rc":[{"batb":[[0,3.5,2.09]],"ltp":4.1,"tv":3737.8,"id":9631939},{"batl":[[1,1.41,889.96],[2,1.42,568.55]],"ltp":1.32,"tv":37127.14,"id":8681938}]}]}
{"op":"mcm","clk":"4297340412","pt":1632572896986,"mc":[{"id":"1.188134680","rc":[{"batb":[[0,1.17,870.9]],"batl":[[1,1.42,31.25],[2,1.43,29.5]],"ltp":1.32,"tv":37127.14,"id":8681938}]}]}
{"op":"mcm","clk":"4297340885","pt":1632572899206,"mc":[{"id":"1.188134680","rc":[{"batb":[[0,3.5,4.13]],"ltp":4.1,"tv":3737.8,"id":9631939},{"batb":[[0,1.17,854.77]],"batl":[[1,1.4,31.49],[2,1.42,31.25]],"ltp":1.32,"tv":37127.14,"id":8681938}]}]}
{"op":"mcm","clk":"4297341135","pt":1632572900290,"mc":[{"id":"1.188134680","rc":[{"trd":[[5.8,5.08]],"batb":[[0,6,159.38],[1,5.9,154.69],[2,5.8,154.7]],"batl":[[0,6.8,6.37],[1,7.6,127.53],[2,7.8,122.12]],"ltp":5.8,"tv":3742.87,"id":9631939},{"batb":[[2,1.14,57.28]],"batl":[[0,1.19,1311.6],[1,1.2,1317.18],[2,1.21,506.25]],"ltp":1.32,"tv":37127.14,"id":8681938}],"tv":40870.02}]}
{"op":"mcm","clk":"4297341356","pt":1632572901214,"mc":[{"id":"1.188134680","rc":[{"batb":[[0,6.2,110.09],[1,6,159.38],[2,5.9,154.69]],"batl":[[1,7.2,24.09],[2,7.4,4.05]],"ltp":5.8,"tv":3742.87,"id":9631939},{"batb":[[0,1.17,897.87],[1,1.16,2980.75]],"ltp":1.32,"tv":37127.14,"id":8681938}]}]}
{"op":"mcm","clk":"4297342071","pt":1632572904337,"mc":[{"id":"1.188134680","rc":[{"batb":[[0,1.18,115.87],[1,1.17,972.77],[2,1.16,2980.75]],"batl":[[0,1.19,1384.11]],"ltp":1.32,"tv":37127.14,"id":8681938}]}]}
{"op":"mcm","clk":"4297342244","pt":1632572905134,"mc":[{"id":"1.188134680","rc":[{"batb":[[0,6.2,121.74]],"ltp":5.8,"tv":3742.87,"id":9631939},{"batb":[[2,1.16,3048.35]],"batl":[[0,1.19,1434.3],[1,1.2,1387.93],[2,1.21,566.25]],"ltp":1.32,"tv":37127.14,"id":8681938}]}]}
{"op":"mcm","clk":"4297342428","pt":1632572906040,"mc":[{"id":"1.188134680","rc":[{"batl":[[0,1.19,3550.3]],"ltp":1.32,"tv":37127.14,"id":8681938}]}]}
{"op":"mcm","clk":"4297342672","pt":1632572907334,"mc":[{"id":"1.188134680","rc":[{"trd":[[1.17,1701.42],[1.18,231.75],[1.19,13.84]],"batb":[[0,1.17,118],[1,1.16,3048.35],[2,1.14,57.28]],"batl":[[0,1.19,3543.38],[1,1.2,940.71]],"ltp":1.19,"tv":39074.15,"id":8681938}],"tv":42817.02}]}
{"op":"mcm","clk":"4297342869","pt":1632572908302,"mc":[{"id":"1.188134680","rc":[{"batb":[[2,5.9,166.93]],"ltp":5.8,"tv":3742.87,"id":9631939}]}]}
{"op":"mcm","clk":"4297343069","pt":1632572909203,"mc":[{"id":"1.188134680","rc":[{"batb":[[0,1.17,74.9],[1,1.16,2980.75],[2,1.15,12.67]],"batl":[[1,1.2,869.96]],"ltp":1.19,"tv":39074.15,"id":8681938}]}]}
{"op":"mcm","clk":"4297343281","pt":1632572910218,"mc":[{"id":"1.188134680","rc":[{"batb":[[1,1.16,3273.24],[2,1.15,702.12]],"batl":[[0,1.19,4099.18]],"ltp":1.19,"tv":39074.15,"id":8681938}]}]}
{"op":"mcm","clk":"4297343456","pt":1632572911133,"mc":[{"id":"1.188134680","rc":[{"trd":[[1.19,28.4]],"batl":[[0,1.19,4091.9]],"ltp":1.19,"tv":39088.71,"id":8681938}],"tv":42831.58}]}
{"op":"mcm","clk":"4297344701","pt":1632572917531,"mc":[{"id":"1.188134680","rc":[{"batl":[[0,7.2,24.09],[1,7.4,4.05],[2,7.6,125.82]],"ltp":5.8,"tv":3742.87,"id":9631939},{"batl":[[0,1.19,4075.6]],"ltp":1.19,"tv":39088.71,"id":8681938}]}]}
{"op":"mcm","clk":"4297345151","pt":1632572919720,"mc":[{"id":"1.188134680","rc":[{"trd":[[1.19,36.23]],"batl":[[0,1.19,4071.68]],"ltp":1.19,"tv":39096.54,"id":8681938}],"tv":42839.42}]}
{"op":"mcm","clk":"4297345386","pt":1632572920917,"mc":[{"id":"1.188134680","rc":[{"batl":[[0,7,9.17],[1,7.2,24.09],[2,7.4,4.05]],"ltp":5.8,"tv":3742.87,"id":9631939}]}]}
{"op":"mcm","clk":"4297346436","pt":1632572926241,"mc":[{"id":"1.188134680","rc":[{"trd":[[6.2,25.5]],"batb":[[0,6.2,108.99]],"ltp":6.2,"tv":3768.37,"id":9631939}],"tv":42864.92}]}
{"op":"mcm","clk":"4297346566","pt":1632572926943,"mc":[{"id":"1.188134680","rc":[{"batb":[[0,1.18,20.56],[1,1.17,74.9],[2,1.16,3273.24]],"batl":[[0,1.19,4087.98]],"ltp":1.19,"tv":39096.54,"id":8681938}]}]}
{"op":"mcm","clk":"4297346821","pt":1632572928349,"mc":[{"id":"1.188134680","rc":[{"batb":[[1,5.9,12.24],[2,5.8,3]],"batl":[[2,8.8,2]],"ltp":6.2,"tv":3768.37,"id":9631939},{"batl":[[2,1.21,60]],"ltp":1.19,"tv":39096.54,"id":8681938}]}]}
{"op":"mcm","clk":"4297346976","pt":1632572929152,"mc":[{"id":"1.188134680","rc":[{"batb":[[0,5.9,12.24],[1,5.8,3],[2,4,2]],"batl":[[0,7.2,24.09],[1,8.8,2],[2,10.5,2]],"ltp":6.2,"tv":3768.37,"id":9631939},{"batb":[[0,1.17,74.9],[1,1.16,150],[2,1.15,12.67]],"batl":[[0,1.19,2188.51],[1,1.21,60],[2,1.22,10.63]],"ltp":1.19,"tv":39096.54,"id":8681938}]}]}
{"op":"mcm","clk":"4297347200","pt":1632572930349,"mc":[{"id":"1.188134680","rc":[{"batb":[[0,4,2],[1,3.85,85.14],[2,3.6,2.09]],"batl":[[0,8.8,2],[1,10.5,2],[2,11.5,71.53]],"ltp":6.2,"tv":3768.37,"id":9631939},{"batb":[[0,1.15,12.67],[1,1.13,97.73],[2,1.11,1571.38]],"batl":[[0,1.22,10.63],[1,1.33,35.5],[2,1.36,37.57]],"ltp":1.19,"tv":39096.54,"id":8681938}]}]}
{"op":"mcm","clk":"4297347271","pt":1632572930615,"mc":[{"id":"1.188134680","rc":[{"batb":[[0,3.85,85.14],[1,3.6,2.09],[2,3.35,2.07]],"ltp":6.2,"tv":3768.37,"id":9631939},{"batl":[[1,1.36,37.57],[2,1.38,35.75]],"ltp":1.19,"tv":39096.54,"id":8681938}]}]}
{"op":"mcm","clk":"4297347618","pt":1632572932346,"mc":[{"id":"1.188134680","rc":[{"batb":[[2,1.12,1650.99]],"batl":[[1,1.33,890.67],[2,1.34,711.17]],"ltp":1.19,"tv":39096.54,"id":8681938}]}]}
{"op":"mcm","clk":"4297347682","pt":1632572932635,"mc":[{"id":"1.188134680","rc":[{"batb":[[2,1.11,1571.38]],"batl":[[0,1.36,37.57],[1,1.38,35.75],[2,1.42,31.25]],"ltp":1.19,"tv":39096.54,"id":8681938}]}]}
{"op":"mcm","clk":"4297348013","pt":1632572934244,"mc":[{"id":"1.188134680","rc":[{"batl":[[2,15.5,2]],"ltp":6.2,"tv":3768.37,"id":9631939}]}]}
{"op":"mcm","clk":"4297348208","pt":1632572935228,"mc":[{"id":"1.188134680","rc":[{"batl":[[0,6.4,212.7],[1,8.8,2],[2,10.5,2]],"ltp":6.2,"tv":3768.37,"id":9631939}]}]}
{"op":"mcm","clk":"4297348308","pt":1632572935834,"mc":[{"id":"1.188134680","rc":[{"batb":[[0,3.85,88.14],[1,3.8,3],[2,3.6,2.09]],"batl":[[0,8.8,2],[1,10.5,2],[2,15.5,2]],"ltp":6.2,"tv":3768.37,"id":9631939},{"batb":[[0,1.19,958.46],[1,1.18,1602.16],[2,1.15,12.67]],"batl":[[0,1.21,895.59],[1,1.22,1206.68],[2,1.36,43.57]],"ltp":1.19,"tv":39096.54,"id":8681938}]}]}
{"op":"mcm","clk":"4297348609","pt":1632572937339,"mc":[{"id":"1.188134680","rc":[{"batb":[[0,1.15,12.67],[1,1.13,97.73],[2,1.11,1571.38]],"batl":[[0,1.36,43.57],[1,1.38,35.75],[2,1.41,12.91]],"ltp":1.19,"tv":39096.54,"id":8681938}]}]}
{"op":"mcm","clk":"4297348804","pt":1632572938371,"mc":[{"id":"1.188134680","rc":[{"batl":[[1,9.8,76.79],[2,10.5,2]],"ltp":6.2,"tv":3768.37,"id":9631939},{"batb":[[0,1.15,30.94]],"batl":[[0,1.34,8],[1,1.36,43.57],[2,1.38,35.75]],"ltp":1.19,"tv":39096.54,"id":8681938}]}]}
{"op":"mcm","clk":"4297349164","pt":1632572940142,"mc":[{"id":"1.188134680","rc":[{"batb":[[2,1.12,1650.99]],"batl":[[0,1.33,890.67],[1,1.34,719.17],[2,1.36,43.57]],"ltp":1.19,"tv":39096.54,"id":8681938}]}]}
{"op":"mcm","clk":"4297349345","pt":1632572940964,"mc":[{"id":"1.188134680","rc":[{"batb":[[0,4,2],[1,3.9,3],[2,3.85,88.14]],"ltp":6.2,"tv":3768.37,"id":9631939},{"batl":[[0,1.33,929.17]],"ltp":1.19,"tv":39096.54,"id":8681938}]}]}
{"op":"mcm","clk":"4297350769","pt":1632572947970,"mc":[{"id":"1.188134680","rc":[{"batb":[[2,3.85,85.14]],"ltp":6.2,"tv":3768.37,"id":9631939},{"batb":[[0,1.15,12.67]],"batl":[[2,1.36,37.57]],"ltp":1.19,"tv":39096.54,"id":8681938}]}]}
{"op":"mcm","clk":"4297351247","pt":1632572950366,"mc":[{"id":"1.188134680","rc":[{"batb":[[2,1.11,1571.38]],"ltp":1.19,"tv":39096.54,"id":8681938}]}]}
{"op":"mcm","clk":"4297351862","pt":1632572953369,"mc":[{"id":"1.188134680","rc":[{"batb":[[0,4,6.28],[1,3.9,612.99],[2,3.85,323.12]],"batl":[[0,4.8,103.72],[1,8.8,2]],"ltp":6.2,"tv":3768.37,"id":9631939},{"batb":[[0,1.32,12.06],[1,1.3,16409.37],[2,1.29,1637.07]],"batl":[[1,1.34,711.17],[2,1.35,278.09]],"ltp":1.19,"tv":39096.54,"id":8681938}]}]}
{"op":"mcm","clk":"4297352042","pt":1632572954280,"mc":[{"id":"1.188134680","rc":[{"batb":[[1,3.9,245.2]],"batl":[[0,4.7,1.71],[1,4.8,103.72],[2,8.8,2]],"ltp":6.2,"tv":3768.37,"id":9631939},{"batb":[[1,1.3,2391.48]],"batl":[[0,1.33,951.73]],"ltp":1.19,"tv":39096.54,"id":8681938}]}]}
{"op":"mcm","clk":"4297352279","pt":1632572955362,"mc":[{"id":"1.188134680","rc":[{"batb":[[2,3.85,344.17]],"batl":[[0,4.6,31.62],[1,4.7,1.71],[2,4.8,103.72]],"ltp":6.2,"tv":3768.37,"id":9631939},{"batl":[[2,1.35,338.09]],"ltp":1.19,"tv":39096.54,"id":8681938}]}]}
{"op":"mcm","clk":"4297352479","pt":1632572956347,"mc":[{"id":"1.188134680","rc":[{"batl":[[0,4.3,2],[1,4.6,31.62],[2,4.7,1.71]],"ltp":6.2,"tv":3768.37,"id":9631939}]}]}
{"op":"mcm","clk":"4297352498","pt":1632572956455,"mc":[{"id":"1.188134680","rc":[{"batb":[[0,4,4.28]],"ltp":6.2,"tv":3768.37,"id":9631939},{"batl":[[0,1.33,913.23]],"ltp":1.19,"tv":39096.54,"id":8681938}]}]}
{"op":"mcm","clk":"4297352885","pt":1632572958260,"mc":[{"id":"1.188134680","rc":[{"trd":[[1.32,524.12]],"batb":[[0,1.32,31.88],[1,1.31,82.24],[2,1.3,2391.48]],"batl":[[0,1.33,989.14],[1,1.34,786.18]],"ltp":1.32,"tv":39209.56,"id":8681938}],"tv":42977.94}]}
{"op":"mcm","clk":"4297353074","pt":1632572959172,"mc":[{"id":"1.188134680","rc":[{"batl":[[1,4.7,1.71],[2,4.8,103.72]],"ltp":6.2,"tv":3768.37,"id":9631939},{"batl":[[0,1.33,1261.14]],"ltp":1.32,"tv":39209.56,"id":8681938}]}]}
{"op":"mcm","clk":"4297353318","pt":1632572960267,"mc":[{"id":"1.188134680","rc":[{"trd":[[1.32,527.26]],"batb":[[0,1.32,30.31]],"ltp":1.32,"tv":39212.7,"id":8681938}],"tv":42981.08}]}
{"op":"mcm","clk":"4297353465","pt":1632572960970,"mc":[{"id":"1.188134680","rc":[{"batl":[[0,4.3,12]],"ltp":6.2,"tv":3768.37,"id":9631939}]}]}
{"op":"mcm","clk":"4297353778","pt":1632572962382,"mc":[{"id":"1.188134680","rc":[{"batl":[[1,4.5,32.07],[2,4.7,1.71]],"ltp":6.2,"tv":3768.37,"id":9631939},{"batb":[[0,1.31,82.24],[1,1.3,2391.48],[2,1.29,1637.07]],"batl":[[0,1.32,14.14],[1,1.33,1261.14],[2,1.34,711.17]],"ltp":1.32,"tv":39212.7,"id":8681938}]}]}
{"op":"mcm","clk":"4297354032","pt":1632572963358,"mc":[{"id":"1.188134680","rc":[{"trd":[[1.31,787.62]],"batb":[[0,1.31,72.6]],"batl":[[1,1.33,1471.14]],"ltp":1.31,"tv":39231.98,"id":8681938}],"tv":43000.36}]}
{"op":"mcm","clk":"4297354169","pt":1632572964009,"mc":[{"id":"1.188134680","rc":[{"batl":[[2,4.8,103.72]],"ltp":6.2,"tv":3768.37,"id":9631939}]}]}
{"op":"mcm","clk":"4297354394","pt":1632572965236,"mc":[{"id":"1.188134680","rc":[{"batb":[[1,1.3,1141.48]],"batl":[[0,1.32,16.49]],"ltp":1.31,"tv":39231.98,"id":8681938}]}]}
{"op":"mcm","clk":"4297354849","pt":1632572967272,"mc":[{"id":"1.188134680","rc":[{"batl":[[0,1.32,22.92]],"ltp":1.31,"tv":39231.98,"id":8681938}]}]}
{"op":"mcm","clk":"4297355019","pt":1632572968297,"mc":[{"id":"1.188134680","rc":[{"batb":[[0,3.9,245.2],[1,3.85,344.17],[2,3.8,237.98]],"ltp":6.2,"tv":3768.37,"id":9631939}]}]}
{"op":"mcm","clk":"4297355585","pt":1632572971306,"mc":[{"id":"1.188134680","rc":[{"batl":[[0,4.2,4.65],[1,4.3,12],[2,4.5,32.07]],"ltp":6.2,"tv":3768.37,"id":9631939},{"batl":[[1,1.33,1489.91]],"ltp":1.31,"tv":39231.98,"id":8681938}]}]}
{"op":"mcm","clk":"4297355631","pt":1632572971519,"mc":[{"id":"1.188134680","rc":[{"batb":[[0,3.95,12.84],[1,3.9,245.2],[2,3.85,344.17]],"ltp":6.2,"tv":3768.37,"id":9631939}]}]}
{"op":"mcm","clk":"4297356048","pt":1632572973809,"mc":[{"id":"1.188134680","rc":[{"trd":[[1.32,541.35]],"batl":[[0,1.32,15.87]],"ltp":1.32,"tv":39246.07,"id":8681938}],"tv":43014.45}]}
{"op":"mcm","clk":"4297356289","pt":1632572975010,"mc":[{"id":"1.188134680","rc":[{"batl":[[1,1.33,1744.91]],"ltp":1.32,"tv":39246.07,"id":8681938}]}]}
{"op":"mcm","clk":"4297356478","pt":1632572975894,"mc":[{"id":"1.188134680","rc":[{"trd":[[1.31,793.58]],"batb":[[0,1.31,69.62]],"ltp":1.31,"tv":39252.03,"id":8681938}],"tv":43020.41}]}
{"op":"mcm","clk":"4297356820","pt":1632572977725,"mc":[{"id":"1.188134680","rc":[{"trd":[[4.1,129.36]],"ltp":4.1,"tv":3770.72,"id":9631939},{"trd":[[1.32,548.65]],"batl":[[0,1.32,8.58]],"ltp":1.32,"tv":39259.33,"id":8681938}],"tv":43030.05}]}
{"op":"mcm","clk":"4297357709","pt":1632572982216,"mc":[{"id":"1.188134680","rc":[{"batb":[[0,3.85,106.19],[1,2.76,78.13],[2,2.52,391.63]],"batl":[[0,4.5,32.07],[1,5,2],[2,5.2,2]],"ltp":4.1,"tv":3770.72,"id":9631939},{"trd":[[1.32,565.81]],"batb":[[0,1.31,70.06],[1,1.3,482.11],[2,1.28,113.38]],"batl":[[0,1.33,812.91],[1,1.35,60],[2,1.37,9.24]],"ltp":1.32,"tv":39276.49,"id":8681938}],"tv":43047.21}]}
{"op":"mcm","clk":"4297357921","pt":1632572983300,"mc":[{"id":"1.188134680","rc":[{"batb":[[0,2.76,78.13],[1,2.52,391.63],[2,2.44,11.53]],"batl":[[0,5,2],[1,5.2,2],[2,5.4,2]],"ltp":4.1,"tv":3770.72,"id":9631939},{"batb":[[0,1.26,11.92],[1,1.25,44.73],[2,1.24,688.37]],"batl":[[0,1.37,9.24],[1,1.65,19.7],[2,1.75,13.58]],"ltp":1.32,"tv":39276.49,"id":8681938}]}]}
{"op":"mcm","clk":"4297358022","pt":1632572983888,"mc":[{"id":"1.188134680","rc":[{"batl":[[0,5.2,2],[1,5.4,2],[2,5.6,2]],"ltp":4.1,"tv":3770.72,"id":9631939},{"batb":[[0,1.32,3.9],[1,1.26,11.48]],"ltp":1.32,"tv":39276.49,"id":8681938}]}]}
{"op":"mcm","clk":"4297358250","pt":1632572985129,"mc":[{"id":"1.188134680","rc":[{"batl":[[1,1.53,350.24],[2,1.54,393.14]],"ltp":1.32,"tv":39276.49,"id":8681938}]}]}
{"op":"mcm","clk":"4297358581","pt":1632572986795,"mc":[{"id":"1.188134680","rc":[{"batl":[[0,5,2],[1,5.2,2],[2,5.4,2]],"ltp":4.1,"tv":3770.72,"id":9631939},{"batb":[[2,1.25,42.13]],"ltp":1.32,"tv":39276.49,"id":8681938}]}]}
{"op":"mcm","clk":"4297358716","pt":1632572987605,"mc":[{"id":"1.188134680","rc":[{"batl":[[0,5.2,2],[1,5.4,2],[2,5.6,2]],"ltp":4.1,"tv":3770.72,"id":9631939},{"batb":[[2,1.24,688.37]],"ltp":1.32,"tv":39276.49,"id":8681938}]}]}
{"op":"mcm","clk":"4297358921","pt":1632572988834,"mc":[{"id":"1.188134680","rc":[{"batb":[[1,2.52,389.14]],"ltp":4.1,"tv":3770.72,"id":9631939},{"batb":[[1,1.24,688.37],[2,1.23,1537.21]],"batl":[[1,4.4,3.34],[2,8.8,7.31]],"ltp":1.32,"tv":39276.49,"id":8681938}]}]}
{"op":"mcm","clk":"4297359194","pt":1632572990308,"mc":[{"id":"1.188134680","rc":[{"batb":[[1,2.44,11.53],[2,2.32,3.39]],"ltp":4.1,"tv":3770.72,"id":9631939},{"trd":[[1.32,565.88]],"batb":[[0,1.32,3.86]],"ltp":1.32,"tv":39276.57,"id":8681938}],"tv":43047.29}]}
{"op":"mcm","clk":"4297359408","pt":1632572991338,"mc":[{"id":"1.188134680","rc":[{"batb":[[0,4.8,796.88],[1,4.7,773.44],[2,4.6,773.44]],"batl":[[1,5.3,6.82],[2,5.4,2]],"ltp":4.1,"tv":3770.72,"id":9631939},{"trd":[[1.32,566.68]],"batb":[[0,1.24,688.37],[1,1.23,1537.21],[2,1.22,1207.02]],"batl":[[0,1.25,9.28],[1,1.26,4706.71],[2,1.37,9.24]],"ltp":1.32,"tv":39277.37,"id":8681938}],"tv":43048.09}]}
{"op":"mcm","clk":"4297359607","pt":1632572992328,"mc":[{"id":"1.188134680","rc":[{"batb":[[0,4.8,199.22],[1,4.7,196.68],[2,4.6,303.45]],"batl":[[0,5.2,3.71]],"ltp":4.1,"tv":3770.72,"id":9631939},{"batl":[[1,1.26,1315.39],[2,1.27,980.55]],"ltp":1.32,"tv":39277.37,"id":8681938}]}]}
{"op":"mcm","clk":"4297359810","pt":1632572993207,"mc":[{"id":"1.188134680","rc":[{"batl":[[2,5.4,30.6]],"ltp":4.1,"tv":3770.72,"id":9631939},{"batb":[[2,1.22,1334.94]],"ltp":1.32,"tv":39277.37,"id":8681938}]}]}
{"op":"mcm","clk":"4297359944","pt":1632572993909,"mc":[{"id":"1.188134680","rc":[{"batl":[[0,5.1,2],[1,5.2,13.71],[2,5.3,6.82]],"ltp":4.1,"tv":3770.72,"id":9631939},{"batb":[[0,1.24,731.49]],"ltp":1.32,"tv":39277.37,"id":8681938}]}]}
{"op":"mcm","clk":"4297360385","pt":1632572996345,"mc":[{"id":"1.188134680","rc":[{"batb":[[0,1.24,804.3],[1,1.23,1603.76]],"batl":[[0,1.25,154.55],[1,1.26,1372.19]],"ltp":1.32,"tv":39277.37,"id":8681938}]}]}
{"op":"mcm","clk":"4297360505","pt":1632572996914,"mc":[{"id":"1.188134680","rc":[{"batl":[[0,1.25,108.65]],"ltp":1.32,"tv":39277.37,"id":8681938}]}]}
{"op":"mcm","clk":"4297361151","pt":1632573000123,"mc":[{"id":"1.188134680","rc":[{"batb":[[2,4.6,320.11]],"ltp":4.1,"tv":3770.72,"id":9631939}]}]}
{"op":"mcm","clk":"4297361548","pt":1632573001650,"mc":[{"id":"1.188134680","rc":[{"batb":[[1,1.23,1537.21]],"batl":[[1,1.26,1315.39]],"ltp":1.32,"tv":39277.37,"id":8681938}]}]}
{"op":"mcm","clk":"4297362033","pt":1632573003363,"mc":[{"id":"1.188134680","rc":[{"batl":[[1,5.2,12]],"ltp":4.1,"tv":3770.72,"id":9631939},{"batl":[[1,1.26,943.7]],"ltp":1.32,"tv":39277.37,"id":8681938}]}]}
{"op":"mcm","clk":"4297362573","pt":1632573005829,"mc":[{"id":"1.188134680","rc":[{"trd":[[1.25,942.58]],"batl":[[0,1.25,108.61]],"ltp":1.25,"tv":39277.45,"id":8681938}],"tv":43048.17}]}
{"op":"mcm","clk":"4297363410","pt":1632573009957,"mc":[{"id":"1.188134680","rc":[{"trd":[[1.25,947.28]],"batl":[[0,1.25,106.26]],"ltp":1.25,"tv":39282.14,"id":8681938}],"tv":43052.87}]}
{"op":"mcm","clk":"4297363727","pt":1632573011471,"mc":[{"id":"1.188134680","rc":[{"trd":[[1.25,961.37]],"batl":[[0,1.25,99.21]],"ltp":1.25,"tv":39296.23,"id":8681938}],"tv":43066.96}]}
{"op":"mcm","clk":"4297364335","pt":1632573014357,"mc":[{"id":"1.188134680","rc":[{"batb":[[0,4.7,3.32],[1,4.6,126.75],[2,4.1,60.98]],"batl":[[2,5.4,30.6]],"ltp":4.1,"tv":3770.72,"id":9631939},{"trd":[[1.25,982.14]],"batl":[[0,1.25,88.82],[1,1.26,919.89]],"ltp":1.25,"tv":39317.01,"id":8681938}],"tv":43087.74}]}
{"op":"mcm","clk":"4297364517","pt":1632573015249,"mc":[{"id":"1.188134680","rc":[{"batb":[[0,4.6,16.66],[1,4,2],[2,3.9,165.89]],"batl":[[0,5.4,28.6],[1,7.2,94.03],[2,13.5,2]],"ltp":4.1,"tv":3770.72,"id":9631939},{"batb":[[0,1.22,127.92],[1,1.2,9.26],[2,1.11,37.38]],"batl":[[0,1.28,72.44],[1,1.33,40.5],[2,1.36,31.32]],"ltp":1.25,"tv":39317.01,"id":8681938}]}]}
{"op":"mcm","clk":"4297364754","pt":1632573016374,"mc":[{"id":"1.188134680","rc":[{"batb":[[0,4,2],[1,3.9,165.89],[2,3.75,4]],"batl":[[0,13.5,2],[1,15.5,2],[2,55,2]],"ltp":4.1,"tv":3770.72,"id":9631939},{"batb":[[0,1.2,9.26],[1,1.11,37.38],[2,1.1,1624.56]],"batl":[[0,1.28,12.44]],"ltp":1.25,"tv":39317.01,"id":8681938}]}]}
{"op":"mcm","clk":"4297365125","pt":1632573018169,"mc":[{"id":"1.188134680","rc":[{"batl":[[0,13.5,2.16]],"ltp":4.1,"tv":3770.72,"id":9631939},{"batl":[[0,1.33,920.37],[1,1.34,711.33]],"ltp":1.25,"tv":39317.01,"id":8681938}]}]}
{"op":"mcm","clk":"4297365753","pt":1632573021364,"mc":[{"id":"1.188134680","rc":[{"batb":[[0,4,4],[1,3.95,2],[2,3.9,411.09]],"batl":[[0,4.8,6.25],[1,13.5,2.16],[2,15.5,2]],"ltp":4.1,"tv":3770.72,"id":9631939},{"batb":[[0,1.3,1920.95],[1,1.29,1637.27],[2,1.28,926.95]],"batl":[[0,1.33,929.37],[1,1.34,945.01],[2,1.36,79.34]],"ltp":1.25,"tv":39317.01,"id":8681938}]}]}
{"op":"mcm","clk":"4297365984","pt":1632573022377,"mc":[{"id":"1.188134680","rc":[{"batb":[[0,4,2],[1,3.9,411.09],[2,3.85,237.98]],"batl":[[0,4.8,7.96]],"ltp":4.1,"tv":3770.72,"id":9631939},{"batb":[[0,1.3,2406.02]],"batl":[[0,1.33,942.93]],"ltp":1.25,"tv":39317.01,"id":8681938}]}]}
{"op":"mcm","clk":"4297366175","pt":1632573023156,"mc":[{"id":"1.188134680","rc":[{"batb":[[2,3.85,259.03]],"batl":[[0,4.6,31.62],[1,4.8,7.96],[2,6,108.47]],"ltp":4.1,"tv":3770.72,"id":9631939},{"batb":[[1,1.29,1651.45],[2,1.28,1040.33]],"batl":[[2,1.35,60]],"ltp":1.25,"tv":39317.01,"id":8681938}]}]}
{"op":"mcm","clk":"4297366400","pt":1632573024265,"mc":[{"id":"1.188134680","rc":[{"batb":[[0,3.9,411.09],[1,3.85,259.03],[2,3.8,237.98]],"batl":[[0,4.3,2],[1,4.6,31.62],[2,4.8,7.96]],"ltp":4.1,"tv":3770.72,"id":9631939},{"batb":[[1,1.29,1637.27]],"batl":[[0,1.33,902.43]],"ltp":1.25,"tv":39317.01,"id":8681938}]}]}
{"op":"mcm","clk":"4297366580","pt":1632573025183,"mc":[{"id":"1.188134680","rc":[{"batb":[[0,1.31,87.12],[1,1.3,2406.02],[2,1.29,1637.27]],"batl":[[0,1.32,92.94],[1,1.33,902.43],[2,1.34,945.01]],"ltp":1.25,"tv":39317.01,"id":8681938}]}]}
{"op":"mcm","clk":"4297366805","pt":1632573026272,"mc":[{"id":"1.188134680","rc":[{"batl":[[1,4.8,7.96],[2,6,108.47]],"ltp":4.1,"tv":3770.72,"id":9631939},{"batb":[[1,1.3,2534.14]],"batl":[[1,1.33,963.23]],"ltp":1.25,"tv":39317.01,"id":8681938}]}]}
{"op":"mcm","clk":"4297366998","pt":1632573027193,"mc":[{"id":"1.188134680","rc":[{"batb":[[0,4,4.64],[1,3.9,411.09],[2,3.85,259.03]],"batl":[[0,4.2,8.11],[1,4.3,2],[2,4.8,7.96]],"ltp":4.1,"tv":3770.72,"id":9631939}]}]}
{"op":"mcm","clk":"4297367114","pt":1632573027662,"mc":[{"id":"1.188134680","rc":[{"batb":[[1,3.95,12.84],[2,3.9,411.09]],"ltp":4.1,"tv":3770.72,"id":9631939},{"batl":[[1,1.33,1103.23]],"ltp":1.25,"tv":39317.01,"id":8681938}]}]}
{"op":"mcm","clk":"4297367440","pt":1632573029196,"mc":[{"id":"1.188134680","rc":[{"batl":[[1,4.3,37.43],[2,4.5,32.07]],"ltp":4.1,"tv":3770.72,"id":9631939},{"trd":[[1.31,793.66]],"batb":[[0,1.31,87.08]],"ltp":1.31,"tv":39317.09,"id":8681938}],"tv":43087.81}]}
{"op":"mcm","clk":"4297367840","pt":1632573030990,"mc":[{"id":"1.188134680","rc":[{"batb":[[1,1.3,2459.63]],"batl":[[1,1.33,1322.23]],"ltp":1.31,"tv":39317.09,"id":8681938}]}]}
{"op":"mcm","clk":"4297368272","pt":1632573032785,"mc":[{"id":"1.188134680","rc":[{"batb":[[1,1.3,1209.63]],"ltp":1.31,"tv":39317.09,"id":8681938}]}]}
{"op":"mcm","clk":"4297368516","pt":1632573033880,"mc":[{"id":"1.188134680","rc":[{"batl":[[1,1.33,1525.23]],"ltp":1.31,"tv":39317.09,"id":8681938}]}]}
{"op":"mcm","clk":"4297368753","pt":1632573035165,"mc":[{"id":"1.188134680","rc":[{"batb":[[0,3.85,21.05],[1,3.5,2.09],[2,3.3,122.48]],"batl":[[0,6,108.31],[1,11,2],[2,13.5,2]],"ltp":4.1,"tv":3770.72,"id":9631939},{"batb":[[1,1.28,113.38],[2,1.26,10.43]],"batl":[[1,1.33,622.8],[2,1.35,60]],"ltp":1.31,"tv":39317.09,"id":8681938}]}]}
{"op":"mcm","clk":"4297368981","pt":1632573036361,"mc":[{"id":"1.188134680","rc":[{"batb":[[0,3.5,2.09],[1,3.3,122.48],[2,2.52,389.14]],"ltp":4.1,"tv":3770.72,"id":9631939},{"batb":[[0,1.26,10.43],[1,1.13,1198.17],[2,1.1,120.44]],"batl":[[0,1.36,12.75],[1,1.4,31.29],[2,1.43,24.5]],"ltp":1.31,"tv":39317.09,"id":8681938}]}]}
{"op":"mcm","clk":"4297369057","pt":1632573036691,"mc":[{"id":"1.188134680","rc":[{"batb":[[0,3.3,122.58],[1,2.44,11.53],[2,1.18,50.93]],"batl":[[0,11,2],[1,13.5,2],[2,15.5,2]],"ltp":4.1,"tv":3770.72,"id":9631939},{"batl":[[1,1.43,24.5],[2,4.4,3.34]],"ltp":1.31,"tv":39317.09,"id":8681938}]}]}
{"op":"mcm","clk":"4297369352","pt":1632573038268,"mc":[{"id":"1.188134680","rc":[{"batb":[[0,3.5,3.09],[1,3.45,3],[2,3.3,122.48]],"ltp":4.1,"tv":3770.72,"id":9631939},{"batl":[[0,1.41,440.69],[1,1.42,547.88],[2,1.43,24.5]],"ltp":1.31,"tv":39317.09,"id":8681938}]}]}
{"op":"mcm","clk":"4297369473","pt":1632573038902,"mc":[{"id":"1.188134680","rc":[{"batb":[[0,3.3,122.58],[1,2.44,11.53],[2,1.18,50.93]],"ltp":4.1,"tv":3770.72,"id":9631939}]}]}
{"op":"mcm","clk":"4297369767","pt":1632573040375,"mc":[{"id":"1.188134680","rc":[{"trd":[[3.4,6],[3.6,5.59],[3.9,53.62]],"batb":[[0,3.3,126.81]],"batl":[[0,3.55,1323.94],[1,3.6,1858.52],[2,3.75,86.51]],"ltp":3.4,"tv":3776.91,"id":9631939},{"trd":[[1.34,347.03],[1.41,14.47]],"batb":[[0,1.38,2272.17],[1,1.37,1507.85],[2,1.36,851.46]],"batl":[[0,1.41,426.22]],"ltp":1.41,"tv":39331.6,"id":8681938}],"tv":43108.52}]}
{"op":"mcm","clk":"4297369931","pt":1632573041277,"mc":[{"id":"1.188134680","rc":[{"batl":[[0,3.55,264.78],[1,3.75,86.51],[2,3.9,7.69]],"ltp":3.4,"tv":3776.91,"id":9631939},{"batb":[[0,1.38,909.85],[1,1.37,826.69],[2,1.36,170.3]],"batl":[[2,1.43,1688.84]],"ltp":1.41,"tv":39331.6,"id":8681938}]}]}
{"op":"mcm","clk":"4297370131","pt":1632573042301,"mc":[{"id":"1.188134680","rc":[{"batb":[[0,3.3,152.89],[2,2.38,115.83]],"batl":[[2,3.85,35.54]],"ltp":3.4,"tv":3776.91,"id":9631939},{"batb":[[0,1.38,1274.86]],"batl":[[2,1.43,374.16]],"ltp":1.41,"tv":39331.6,"id":8681938}]}]}
{"op":"mcm","clk":"4297370228","pt":1632573042796,"mc":[{"id":"1.188134680","rc":[{"batb":[[0,3.3,170.87]],"ltp":3.4,"tv":3776.91,"id":9631939}]}]}
{"op":"mcm","clk":"4297370363","pt":1632573043499,"mc":[{"id":"1.188134680","rc":[{"batb":[[0,1.39,6],[1,1.38,1281.86],[2,1.37,826.69]],"ltp":1.41,"tv":39331.6,"id":8681938}]}]}
{"op":"mcm","clk":"4297370735","pt":1632573045287,"mc":[{"id":"1.188134680","rc":[{"batl":[[1,3.75,153.46]],"ltp":3.4,"tv":3776.91,"id":9631939},{"batb":[[0,1.39,83.83],[1,1.38,1340.53]],"batl":[[0,1.4,88.54],[1,1.41,483.02],[2,1.42,547.88]],"ltp":1.41,"tv":39331.6,"id":8681938}]}]}
{"op":"mcm","clk":"4297370905","pt":1632573046080,"mc":[{"id":"1.188134680","rc":[{"batl":[[1,3.75,86.51],[2,3.9,7.69]],"ltp":3.4,"tv":3776.91,"id":9631939},{"batb":[[0,1.39,135.98]],"ltp":1.41,"tv":39331.6,"id":8681938}]}]}
{"op":"mcm","clk":"4297371117","pt":1632573047111,"mc":[{"id":"1.188134680","rc":[{"batl":[[1,1.41,628.02]],"ltp":1.41,"tv":39331.6,"id":8681938}]}]}
{"op":"mcm","clk":"4297371538","pt":1632573049303,"mc":[{"id":"1.188134680","rc":[{"batl":[[2,3.8,35.85]],"ltp":3.4,"tv":3776.91,"id":9631939},{"trd":[[1.39,0.16]],"batb":[[0,1.39,214.44]],"batl":[[1,1.41,701.54]],"ltp":1.39,"tv":39331.68,"id":8681938}],"tv":43108.6}]}
{"op":"mcm","clk":"4297371697","pt":1632573050009,"mc":[{"id":"1.188134680","rc":[{"batb":[[0,1.39,135.94],[1,1.38,1281.86]],"batl":[[1,1.41,966.54]],"ltp":1.39,"tv":39331.68,"id":8681938}]}]}
{"op":"mcm","clk":"4297371792","pt":1632573050598,"mc":[{"id":"1.188134680","rc":[{"batb":[[0,3.3,166.54]],"ltp":3.4,"tv":3776.91,"id":9631939}]}]}
{"op":"mcm","clk":"4297372380","pt":1632573053657,"mc":[{"id":"1.188134680","rc":[{"trd":[[3.5,5.71]],"batb":[[0,3.35,5.15],[1,3.3,166.54],[2,2.44,11.53]],"ltp":3.5,"tv":3782.62,"id":9631939},{"trd":[[1.4,61.66]],"batl":[[0,1.4,62.18],[1,1.41,1182.54]],"ltp":1.4,"tv":39370.12,"id":8681938}],"tv":43152.74}]}
{"op":"mcm","clk":"4297373215","pt":1632573057861,"mc":[{"id":"1.188134680","rc":[{"batb":[[1,1.38,1274.86]],"ltp":1.4,"tv":39370.12,"id":8681938}]}]}
{"op":"mcm","clk":"4297373943","pt":1632573061156,"mc":[{"id":"1.188134680","rc":[{"trd":[[1.39,0.54]],"batb":[[0,1.39,135.75]],"ltp":1.39,"tv":39370.5,"id":8681938}],"tv":43153.13}]}
{"op":"mcm","clk":"4297374554","pt":1632573063759,"mc":[{"id":"1.188134680","rc":[{"batb":[[0,3.3,166.54],[1,2.44,11.53],[2,2.38,115.83]],"ltp":3.5,"tv":3782.62,"id":9631939}]}]}
{"op":"mcm","clk":"4297375324","pt":1632573066969,"mc":[{"id":"1.188134680","rc":[{"batl":[[0,3.55,269.47]],"ltp":3.5,"tv":3782.62,"id":9631939},{"batl":[[1,1.41,1197.09]],"ltp":1.39,"tv":39370.5,"id":8681938}]}]}
{"op":"mcm","clk":"4297376068","pt":1632573070366,"mc":[{"id":"1.188134680","rc":[{"batb":[[0,3.3,146.56]],"batl":[[0,3.8,35.85],[1,4.3,2],[2,4.5,3]],"ltp":3.5,"tv":3782.62,"id":9631939},{"batb":[[0,1.39,83.6],[1,1.38,365.01],[2,1.36,100]],"batl":[[1,1.41,756.32],[2,1.44,69.49]],"ltp":1.39,"tv":39370.5,"id":8681938}]}]}
{"op":"mcm","clk":"4297376267","pt":1632573071308,"mc":[{"id":"1.188134680","rc":[{"batb":[[0,2.44,11.53],[1,2.38,115.5],[2,2.3,392.84]],"batl":[[0,4.3,2],[1,4.5,3],[2,4.6,2]],"ltp":3.5,"tv":3782.62,"id":9631939},{"batb":[[0,1.39,77.83],[1,1.34,11.51],[2,1.31,43.79]],"batl":[[2,1.44,9.49]],"ltp":1.39,"tv":39370.5,"id":8681938}]}]}
{"op":"mcm","clk":"4297376459","pt":1632573072067,"mc":[{"id":"1.188134680","rc":[{"batb":[[0,2.44,12.38]],"batl":[[0,4.5,3],[1,4.6,2],[2,4.9,128.82]],"ltp":3.5,"tv":3782.62,"id":9631939},{"batb":[[0,1.34,11.51],[1,1.3,488.87],[2,1.28,42.41]],"batl":[[0,1.44,9.49],[1,1.78,15.25],[2,1.9,13.05]],"ltp":1.39,"tv":39370.5,"id":8681938}]}]}
{"op":"mcm","clk":"4297376700","pt":1632573073252,"mc":[{"id":"1.188134680","rc":[{"batb":[[1,1.3,1259.17],[2,1.29,897.54]],"batl":[[1,1.68,319.56],[2,1.7,552.35]],"ltp":1.39,"tv":39370.5,"id":8681938}]}]}
{"op":"mcm","clk":"4297377112","pt":1632573075348,"mc":[{"id":"1.188134680","rc":[{"batl":[[0,4.3,2],[1,4.5,3],[2,4.6,2]],"ltp":3.5,"tv":3782.62,"id":9631939},{"batb":[[1,1.31,43.79],[2,1.3,488.87]],"batl":[[0,1.78,15.25],[1,1.9,13.05],[2,4.4,3.34]],"ltp":1.39,"tv":39370.5,"id":8681938}]}]}
{"op":"mcm","clk":"4297377248","pt":1632573076056,"mc":[{"id":"1.188134680","rc":[{"batl":[[0,4.5,3],[1,4.6,2],[2,11,2]],"ltp":3.5,"tv":3782.62,"id":9631939},{"batb":[[1,1.3,488.87],[2,1.28,42.41]],"ltp":1.39,"tv":39370.5,"id":8681938}]}]}
{"op":"mcm","clk":"4297377529","pt":1632573077210,"mc":[{"id":"1.188134680","rc":[{"batb":[[0,2.44,11.53]],"ltp":3.5,"tv":3782.62,"id":9631939}]}]}
{"op":"mcm","clk":"4297377765","pt":1632573078285,"mc":[{"id":"1.188134680","rc":[{"batb":[[0,2.44,15.53],[1,2.42,4],[2,2.38,115.5]],"batl":[[0,3.35,19.7],[1,4.5,3],[2,4.6,2]],"ltp":3.5,"tv":3782.62,"id":9631939},{"batb":[[0,1.43,20.43],[1,1.42,745.53],[2,1.41,575.57]],"batl":[[0,1.46,574.23],[1,1.47,471.71],[2,1.49,21.5]],"ltp":1.39,"tv":39370.5,"id":8681938}]}]}
{"op":"mcm","clk":"4297377899","pt":1632573078926,"mc":[{"id":"1.188134680","rc":[{"batl":[[0,4.3,2]],"ltp":3.5,"tv":3782.62,"id":9631939},{"batb":[[0,1.42,745.53],[1,1.41,575.57],[2,1.34,11.51]],"batl":[[2,1.78,15.25]],"ltp":1.39,"tv":39370.5,"id":8681938}]}]}
{"op":"mcm","clk":"4297378134","pt":1632573080185,"mc":[{"id":"1.188134680","rc":[{"batl":[[2,4.6,140.79]],"ltp":3.5,"tv":3782.62,"id":9631939},{"batb":[[0,1.34,11.51],[1,1.31,40.79],[2,1.3,488.87]],"batl":[[0,1.78,15.25],[1,1.89,9.67],[2,1.9,13.05]],"ltp":1.39,"tv":39370.5,"id":8681938}]}]}
{"op":"mcm","clk":"4297378298","pt":1632573081060,"mc":[{"id":"1.188134680","rc":[{"batl":[[0,4.5,3],[1,4.6,140.79],[2,11,2]],"ltp":3.5,"tv":3782.62,"id":9631939},{"batb":[[1,1.31,13.26]],"batl":[[0,1.7,4],[1,1.78,15.25],[2,1.89,9.67]],"ltp":1.39,"tv":39370.5,"id":8681938}]}]}
{"op":"mcm","clk":"4297378494","pt":1632573082082,"mc":[{"id":"1.188134680","rc":[{"batl":[[0,3.5,8.3],[1,4.5,3],[2,4.6,140.79]],"ltp":3.5,"tv":3782.62,"id":9631939}]}]}
{"op":"mcm","clk":"4297378686","pt":1632573083073,"mc":[{"id":"1.188134680","rc":[{"batb":[[2,1.3,1259.17]],"batl":[[0,1.68,319.56],[1,1.7,556.35],[2,1.78,15.25]],"ltp":1.39,"tv":39370.5,"id":8681938}]}]}
{"op":"mcm","clk":"4297378876","pt":1632573084111,"mc":[{"id":"1.188134680","rc":[{"batb":[[0,1.31,13.26],[1,1.3,1259.17],[2,1.29,897.54]],"batl":[[0,1.7,4],[1,1.78,15.25],[2,1.89,9.67]],"ltp":1.39,"tv":39370.5,"id":8681938}]}]}
{"op":"mcm","clk":"4297379121","pt":1632573085284,"mc":[{"id":"1.188134680","rc":[{"batl":[[2,4.6,2]],"ltp":3.5,"tv":3782.62,"id":9631939},{"batl":[[0,1.42,3.76],[1,1.7,4],[2,1.78,15.25]],"ltp":1.39,"tv":39370.5,"id":8681938}]}]}
{"op":"mcm","clk":"4297379316","pt":1632573086378,"mc":[{"id":"1.188134680","rc":[{"batb":[[0,2.46,4],[1,2.44,15.53],[2,2.42,4]],"ltp":3.5,"tv":3782.62,"id":9631939},{"batb":[[0,1.3,1259.17],[1,1.29,897.54],[2,1.28,42.41]],"batl":[[1,1.68,6],[2,1.7,4]],"ltp":1.39,"tv":39370.5,"id":8681938}]}]}
{"op":"mcm","clk":"4297379516","pt":1632573087282,"mc":[{"id":"1.188134680","rc":[{"trd":[[3.5,14.01]],"batb":[[0,3.9,245.2],[1,3.85,237.98],[2,3.8,237.98]],"batl":[[0,4.5,3],[1,4.6,2],[2,11,2]],"ltp":3.5,"tv":3790.93,"id":9631939},{"trd":[[1.4,82.41]],"batb":[[0,1.3,1273.92],[2,1.28,1020.55]],"batl":[[0,1.32,26.21],[1,1.33,1245.46],[2,1.34,922.08]],"ltp":1.4,"tv":39391.25,"id":8681938}],"tv":43182.18}]}
{"op":"mcm","clk":"4297379735","pt":1632573088375,"mc":[{"id":"1.188134680","rc":[{"batb":[[0,3.9,409.23]],"batl":[[0,4.5,4.71],[2,4.8,6.25]],"ltp":3.5,"tv":3790.93,"id":9631939},{"batb":[[0,1.31,3],[1,1.3,1276.92],[2,1.29,897.54]],"ltp":1.4,"tv":39391.25,"id":8681938}]}]}
{"op":"mcm","clk":"4297379908","pt":1632573089191,"mc":[{"id":"1.188134680","rc":[{"batb":[[1,1.3,1333.06]],"ltp":1.4,"tv":39391.25,"id":8681938}]}]}
{"op":"mcm","clk":"4297380115","pt":1632573090220,"mc":[{"id":"1.188134680","rc":[{"batl":[[0,4.3,3],[1,4.5,36.78],[2,4.6,2]],"ltp":3.5,"tv":3790.93,"id":9631939}]}]}
{"op":"mcm","clk":"4297380279","pt":1632573091093,"mc":[{"id":"1.188134680","rc":[{"batb":[[0,1.31,5.33],[1,1.3,1391.05]],"batl":[[0,1.32,101.52]],"ltp":1.4,"tv":39391.25,"id":8681938}]}]}
{"op":"mcm","clk":"4297380449","pt":1632573092153,"mc":[{"id":"1.188134680","rc":[{"batb":[[0,3.9,425.8]],"ltp":3.5,"tv":3790.93,"id":9631939},{"batb":[[2,1.29,975.53]],"batl":[[1,1.33,1322.41]],"ltp":1.4,"tv":39391.25,"id":8681938}]}]}
{"op":"mcm","clk":"4297380703","pt":1632573093300,"mc":[{"id":"1.188134680","rc":[{"batl":[[0,4.3,18]],"ltp":3.5,"tv":3790.93,"id":9631939}]}]}
{"op":"mcm","clk":"4297380747","pt":1632573093578,"mc":[{"id":"1.188134680","rc":[{"batl":[[0,4.3,3]],"ltp":3.5,"tv":3790.93,"id":9631939}]}]}
{"op":"mcm","clk":"4297381053","pt":1632573095206,"mc":[{"id":"1.188134680","rc":[{"trd":[[1.32,566.76]],"batl":[[0,1.32,101.48]],"ltp":1.32,"tv":39391.33,"id":8681938}],"tv":43182.26}]}
{"op":"mcm","clk":"4297381290","pt":1632573096323,"mc":[{"id":"1.188134680","rc":[{"batb":[[1,3.85,259.03]],"ltp":3.5,"tv":3790.93,"id":9631939},{"trd":[[1.31,804.32]],"batb":[[0,1.3,1391.05],[1,1.29,975.53],[2,1.28,1133.93]],"batl":[[0,1.31,4.06],[1,1.32,101.48],[2,1.33,1322.41]],"ltp":1.31,"tv":39401.99,"id":8681938}],"tv":43192.92}]}
{"op":"mcm","clk":"4297381590","pt":1632573097720,"mc":[{"id":"1.188134680","rc":[{"batl":[[1,4.5,35.07]],"ltp":3.5,"tv":3790.93,"id":9631939},{"trd":[[1.31,808.23]],"batb":[[1,1.29,897.54]],"batl":[[0,1.31,2.11]],"ltp":1.31,"tv":39405.9,"id":8681938}],"tv":43196.83}]}
{"op":"mcm","clk":"4297381852","pt":1632573099075,"mc":[{"id":"1.188134680","rc":[{"batl":[[2,1.33,809.5]],"ltp":1.31,"tv":39405.9,"id":8681938}]}]}
{"op":"mcm","clk":"4297382058","pt":1632573100200,"mc":[{"id":"1.188134680","rc":[{"batl":[[0,4.3,17.74]],"ltp":3.5,"tv":3790.93,"id":9631939}]}]}
{"op":"mcm","clk":"4297382256","pt":1632573101325,"mc":[{"id":"1.188134680","rc":[{"batl":[[0,4.3,3]],"ltp":3.5,"tv":3790.93,"id":9631939}]}]}
{"op":"mcm","clk":"4297382318","pt":1632573101591,"mc":[{"id":"1.188134680","rc":[{"batl":[[1,4.5,32.07]],"ltp":3.5,"tv":3790.93,"id":9631939}]}]}
{"op":"mcm","clk":"4297382485","pt":1632573102516,"mc":[{"id":"1.188134680","rc":[{"trd":[[1.31,812.23]],"batl":[[0,1.32,101.58],[1,1.33,809.5],[2,1.34,922.08]],"ltp":1.31,"tv":39409.9,"id":8681938}],"tv":43200.83}]}
{"op":"mcm","clk":"4297382813","pt":1632573104107,"mc":[{"id":"1.188134680","rc":[{"batl":[[0,4.3,17.74]],"ltp":3.5,"tv":3790.93,"id":9631939},{"batl":[[0,1.32,101.48]],"ltp":1.31,"tv":39409.9,"id":8681938}]}]}
{"op":"mcm","clk":"4297383029","pt":1632573105128,"mc":[{"id":"1.188134680","rc":[{"batb":[[0,1.3,1376.3]],"batl":[[0,1.32,75.31]],"ltp":1.31,"tv":39409.9,"id":8681938}]}]}
{"op":"mcm","clk":"4297383624","pt":1632573108119,"mc":[{"id":"1.188134680","rc":[{"batb":[[0,1.3,1391.09]],"batl":[[0,1.32,101.48]],"ltp":1.31,"tv":39409.9,"id":8681938}]}]}
{"op":"mcm","clk":"4297383854","pt":1632573109318,"mc":[{"id":"1.188134680","rc":[{"trd":[[4.1,136.68]],"ltp":4.1,"tv":3798.24,"id":9631939},{"trd":[[1.32,589.48]],"batl":[[0,1.31,5.12],[1,1.32,78.76],[2,1.33,809.5]],"ltp":1.32,"tv":39432.61,"id":8681938}],"tv":43230.85}]}
{"op":"mcm","clk":"4297384831","pt":1632573114227,"mc":[{"id":"1.188134680","rc":[{"trd":[[4.2,47.79]],"ltp":4.2,"tv":3798.39,"id":9631939},{"trd":[[1.31,812.73]],"batl":[[0,1.31,4.62]],"ltp":1.31,"tv":39433.11,"id":8681938}],"tv":43231.51}]}
{"op":"mcm","clk":"4297385268","pt":1632573116304,"mc":[{"id":"1.188134680","rc":[{"trd":[[1.31,818.36]],"batl":[[0,1.31,1.81]],"ltp":1.31,"tv":39438.74,"id":8681938}],"tv":43237.14}]}
{"op":"mcm","clk":"4297385489","pt":1632573117425,"mc":[{"id":"1.188134680","rc":[{"trd":[[1.31,821.98]],"batb":[[0,1.31,3.19],[1,1.3,1391.09],[2,1.29,897.54]],"batl":[[0,1.32,78.76],[1,1.33,809.5],[2,1.34,922.08]],"ltp":1.31,"tv":39442.36,"id":8681938}],"tv":43240.76}]}
{"op":"mcm","clk":"4297386070","pt":1632573120244,"mc":[{"id":"1.188134680","rc":[{"trd":[[4.1,137.46]],"ltp":4.1,"tv":3799.18,"id":9631939},{"trd":[[1.32,591.9]],"batl":[[0,1.32,76.34]],"ltp":1.32,"tv":39444.78,"id":8681938}],"tv":43243.96}]}
{"op":"mcm","clk":"4297386859","pt":1632573123863,"mc":[{"id":"1.188134680","rc":[{"batb":[[1,1.3,620.79],[2,1.28,1133.93]],"batl":[[1,1.33,22.56],[2,1.34,209.53]],"ltp":1.32,"tv":39444.78,"id":8681938}]}]}
{"op":"mcm","clk":"4297388487","pt":1632573131361,"mc":[{"id":"1.188134680","rc":[{"batb":[[0,3.9,303.2],[1,3.85,140.04],[2,3.8,118.99]],"ltp":4.1,"tv":3799.18,"id":9631939},{"batb":[[2,1.28,760.4]],"batl":[[1,1.34,209.53],[2,1.35,60]],"ltp":1.32,"tv":39444.78,"id":8681938}]}]}
{"op":"mcm","clk":"4297388654","pt":1632573132201,"mc":[{"id":"1.188134680","rc":[{"batb":[[0,3.85,21.05],[1,2.58,93.68],[2,2.52,389.14]],"batl":[[0,4.5,32.07],[1,5.2,2],[2,5.8,2]],"ltp":4.1,"tv":3799.18,"id":9631939},{"batb":[[0,1.3,57.98],[1,1.28,113.38],[2,1.27,13.42]],"batl":[[0,1.32,50.17],[1,1.35,60],[2,1.39,10.71]],"ltp":1.32,"tv":39444.78,"id":8681938}]}]}
{"op":"mcm","clk":"4297388943","pt":1632573133308,"mc":[{"id":"1.188134680","rc":[{"batb":[[0,2.58,93.68],[1,2.52,389.14],[2,2.44,11.53]],"batl":[[0,5.2,2],[1,5.8,2],[2,6,108.31]],"ltp":4.1,"tv":3799.18,"id":9631939},{"batb":[[0,1.27,13.42],[1,1.24,53.02],[2,1.23,17.88]],"batl":[[0,1.39,10.71],[1,1.6,640.52],[2,1.61,331.58]],"ltp":1.32,"tv":39444.78,"id":8681938}]}]}
{"op":"mcm","clk":"4297389043","pt":1632573133753,"mc":[{"id":"1.188134680","rc":[{"batl":[[0,5.8,2],[1,6,108.31],[2,990,0.01]],"ltp":4.1,"tv":3799.18,"id":9631939},{"batb":[[1,1.23,17.88],[2,1.22,2014.17]],"ltp":1.32,"tv":39444.78,"id":8681938}]}]}
{"op":"mcm","clk":"4297389707","pt":1632573136950,"mc":[{"id":"1.188134680","rc":[{"batb":[[0,1.23,17.88],[1,1.22,2014.17],[2,1.21,1397.85]],"batl":[[1,1.74,15.75],[2,4.4,3.34]],"ltp":1.32,"tv":39444.78,"id":8681938}]}]}
{"op":"mcm","clk":"4297390224","pt":1632573139371,"mc":[{"id":"1.188134680","rc":[{"batb":[[0,5,470],[1,4.9,235],[2,4.8,235]],"batl":[[0,5.7,4.04],[1,5.8,2],[2,6.2,71.89]],"ltp":4.1,"tv":3799.18,"id":9631939},{"batb":[[0,1.22,2014.17],[1,1.21,1397.85],[2,1.01,140]],"batl":[[0,1.23,33.95],[1,1.24,6273.48],[2,1.25,24]],"ltp":1.32,"tv":39444.78,"id":8681938}]}]}
{"op":"mcm","clk":"4297390424","pt":1632573140361,"mc":[{"id":"1.188134680","rc":[{"trd":[[5.3,2]],"batb":[[0,5,97.25],[1,4.9,47],[2,4.8,146.09]],"batl":[[0,5.4,2],[1,5.7,4.04],[2,5.8,2]],"ltp":5.3,"tv":3801.18,"id":9631939},{"trd":[[1.23,846.71]],"batb":[[0,1.22,2024.17],[2,1.17,55.82]],"batl":[[0,1.23,13.33],[1,1.25,1283.01],[2,1.26,1727.07]],"ltp":1.23,"tv":39477.4,"id":8681938}],"tv":43278.58}]}
{"op":"mcm","clk":"4297390641","pt":1632573141355,"mc":[{"id":"1.188134680","rc":[{"batl":[[1,5.7,124.17],[2,5.8,43.22]],"ltp":5.3,"tv":3801.18,"id":9631939},{"batb":[[1,1.21,1528.78]],"ltp":1.23,"tv":39477.4,"id":8681938}]}]}
{"op":"mcm","clk":"4297390868","pt":1632573142352,"mc":[{"id":"1.188134680","rc":[{"batl":[[1,5.5,3],[2,5.7,114.17]],"ltp":5.3,"tv":3801.18,"id":9631939},{"batb":[[0,1.22,2095.12]],"ltp":1.23,"tv":39477.4,"id":8681938}]}]}
{"op":"mcm","clk":"4297391319","pt":1632573144363,"mc":[{"id":"1.188134680","rc":[{"trd":[[1.23,882.46]],"batb":[[0,1.22,2190.9],[1,1.21,1606.59]],"batl":[[0,1.23,63.56],[1,1.24,143.85],[2,1.25,1283.01]],"ltp":1.23,"tv":39513.16,"id":8681938}],"tv":43314.34}]}
{"op":"mcm","clk":"4297391400","pt":1632573144761,"mc":[{"id":"1.188134680","rc":[{"batl":[[0,5.4,12]],"ltp":5.3,"tv":3801.18,"id":9631939},{"batl":[[1,1.24,63.87]],"ltp":1.23,"tv":39513.16,"id":8681938}]}]}
{"op":"mcm","clk":"4297392158","pt":1632573148171,"mc":[{"id":"1.188134680","rc":[{"batb":[[2,4.8,161.87]],"ltp":5.3,"tv":3801.18,"id":9631939},{"trd":[[1.23,882.55]],"batl":[[0,1.23,63.51]],"ltp":1.23,"tv":39513.24,"id":8681938}],"tv":43314.42}]}
{"op":"mcm","clk":"4297392387","pt":1632573149376,"mc":[{"id":"1.188134680","rc":[{"batb":[[1,1.21,1528.78]],"batl":[[1,1.24,81.61]],"ltp":1.23,"tv":39513.24,"id":8681938}]}]}
{"op":"mcm","clk":"4297392572","pt":1632573150349,"mc":[{"id":"1.188134680","rc":[{"batl":[[2,5.7,110.13]],"ltp":5.3,"tv":3801.18,"id":9631939},{"batb":[[0,1.22,2095.12],[2,1.18,10.79]],"batl":[[0,1.24,81.61],[1,1.25,1283.01],[2,1.26,1727.07]],"ltp":1.23,"tv":39513.24,"id":8681938}]}]}
{"op":"mcm","clk":"4297392734","pt":1632573151177,"mc":[{"id":"1.188134680","rc":[{"batl":[[0,5.4,12.41]],"ltp":5.3,"tv":3801.18,"id":9631939}]}]}
{"op":"mcm","clk":"4297392918","pt":1632573152081,"mc":[{"id":"1.188134680","rc":[{"trd":[[5.3,2.41]],"batl":[[0,5.4,12]],"ltp":5.3,"tv":3801.58,"id":9631939},{"trd":[[1.22,2503.33],[1.23,884.31]],"batb":[[0,1.23,97.54],[1,1.22,1978.07],[2,1.21,1528.78]],"ltp":1.22,"tv":39749.1,"id":8681938}],"tv":43550.69}]}
{"op":"mcm","clk":"4297393428","pt":1632573154374,"mc":[{"id":"1.188134680","rc":[{"trd":[[1.23,895.58]],"batb":[[0,1.23,103.9]],"ltp":1.23,"tv":39760.37,"id":8681938}],"tv":43561.96}]}
{"op":"mcm","clk":"4297393448","pt":1632573154486,"mc":[{"id":"1.188134680","rc":[{"batl":[[1,5.7,110.13],[2,5.8,43.22]],"ltp":5.3,"tv":3801.58,"id":9631939}]}]}
{"op":"mcm","clk":"4297394022","pt":1632573157298,"mc":[{"id":"1.188134680","rc":[{"batl":[[1,5.5,5.13],[2,5.7,110.13]],"ltp":5.3,"tv":3801.58,"id":9631939},{"batb":[[0,1.23,104.14]],"batl":[[0,1.24,109.1]],"ltp":1.23,"tv":39760.37,"id":8681938}]}]}
{"op":"mcm","clk":"4297394122","pt":1632573157688,"mc":[{"id":"1.188134680","rc":[{"batl":[[0,5.3,2.35],[1,5.4,12],[2,5.5,5.13]],"ltp":5.3,"tv":3801.58,"id":9631939}]}]}
{"op":"mcm","clk":"4297394497","pt":1632573159264,"mc":[{"id":"1.188134680","rc":[{"trd":[[1.24,1.95]],"batb":[[0,1.23,103.9]],"batl":[[0,1.24,108.12]],"ltp":1.24,"tv":39762.33,"id":8681938}],"tv":43563.92}]}
{"op":"mcm","clk":"4297394723","pt":1632573160307,"mc":[{"id":"1.188134680","rc":[{"trd":[[5.1,0.09]],"ltp":5.1,"tv":3801.68,"id":9631939},{"trd":[[1.24,2.96]],"batl":[[0,1.24,107.42]],"ltp":1.24,"tv":39763.33,"id":8681938}],"tv":43565.02}]}
{"op":"mcm","clk":"4297395312","pt":1632573163097,"mc":[{"id":"1.188134680","rc":[{"trd":[[1.24,3.71]],"batl":[[0,1.24,107.05]],"ltp":1.24,"tv":39764.09,"id":8681938}],"tv":43565.77}]}
{"op":"mcm","clk":"4297395822","pt":1632573165277,"mc":[{"id":"1.188134680","rc":[{"batb":[[0,4.8,15.78],[1,4.1,2],[2,3.9,162.76]],"batl":[[1,5.7,27.67],[2,7.8,89.68]],"ltp":5.1,"tv":3801.68,"id":9631939},{"trd":[[1.24,8.09]],"batb":[[0,1.23,91.9],[1,1.21,130.93],[2,1.18,10.79]],"batl":[[0,1.24,15.54],[1,1.27,60],[2,1.3,13.04]],"ltp":1.24,"tv":39768.46,"id":8681938}],"tv":43570.15}]}
{"op":"mcm","clk":"4297396042","pt":1632573166298,"mc":[{"id":"1.188134680","rc":[{"batb":[[0,4.1,2],[1,3.9,162.76],[2,3.85,2]],"batl":[[0,36,2],[1,990,0.01],[2,7.8,0]],"ltp":5.1,"tv":3801.68,"id":9631939},{"batb":[[1,1.18,10.79],[2,1.06,2625.56]],"batl":[[1,1.3,13.04],[2,1.32,37.61]],"ltp":1.24,"tv":39768.46,"id":8681938}]}]}
{"op":"mcm","clk":"4297396106","pt":1632573166588,"mc":[{"id":"1.188134680","rc":[{"batb":[[0,3.9,162.76],[1,3.85,2],[2,2.44,11.53]],"ltp":5.1,"tv":3801.68,"id":9631939},{"trd":[[1.24,8.72]],"batl":[[0,1.24,15.23],[2,1.35,37.9]],"ltp":1.24,"tv":39769.09,"id":8681938}],"tv":43570.77}]}
{"op":"mcm","clk":"4297396482","pt":1632573168269,"mc":[{"id":"1.188134680","rc":[{"batb":[[2,1.07,3018.57]],"batl":[[2,1.33,834.37]],"ltp":1.24,"tv":39769.09,"id":8681938}]}]}
{"op":"mcm","clk":"4297396668","pt":1632573169195,"mc":[{"id":"1.188134680","rc":[{"trd":[[1.23,900.28]],"batb":[[0,1.23,89.55],[1,1.07,3018.57],[2,1.06,2625.56]],"ltp":1.23,"tv":39773.79,"id":8681938}],"tv":43575.47}]}
{"op":"mcm","clk":"4297396851","pt":1632573169998,"mc":[{"id":"1.188134680","rc":[{"batb":[[1,1.06,2625.56],[2,1.03,401.83]],"batl":[[2,1.35,37.9]],"ltp":1.23,"tv":39773.79,"id":8681938}]}]}
{"op":"mcm","clk":"4297397359","pt":1632573172299,"mc":[{"id":"1.188134680","rc":[{"batl":[[0,7,22.06],[1,36,2],[2,990,0.01]],"ltp":5.1,"tv":3801.68,"id":9631939},{"trd":[[1.23,1079.38]],"batb":[[0,1.19,1046.94],[1,1.18,1605.03],[2,1.16,19.78]],"batl":[[0,1.21,972.18],[1,1.22,1208.81],[2,1.24,15.23]],"ltp":1.23,"tv":39952.89,"id":8681938}],"tv":43754.57}]}
{"op":"mcm","clk":"4297397551","pt":1632573173207,"mc":[{"id":"1.188134680","rc":[{"batb":[[0,4.1,2],[1,3.9,162.76],[2,3.85,2]],"batl":[[0,36,2],[1,990,0.01],[2,990,0]],"ltp":5.1,"tv":3801.68,"id":9631939},{"batb":[[2,1.06,2625.56]],"batl":[[0,1.21,813.54]],"ltp":1.23,"tv":39952.89,"id":8681938}]}]}
{"op":"mcm","clk":"4297397745","pt":1632573174095,"mc":[{"id":"1.188134680","rc":[{"batl":[[0,7.2,10],[1,8.6,83.54],[2,36,2]],"ltp":5.1,"tv":3801.68,"id":9631939},{"batb":[[2,1.07,13.65]],"batl":[[2,1.23,76.15]],"ltp":1.23,"tv":39952.89,"id":8681938}]}]}
{"op":"mcm","clk":"4297397973","pt":1632573175195,"mc":[{"id":"1.188134680","rc":[{"batl":[[2,18,2]],"ltp":5.1,"tv":3801.68,"id":9631939},{"trd":[[1.21,112.16]],"batb":[[2,1.16,194.6]],"batl":[[0,1.21,813.15]],"ltp":1.21,"tv":39953.67,"id":8681938}],"tv":43755.35}]}
{"op":"mcm","clk":"4297398087","pt":1632573175718,"mc":[{"id":"1.188134680","rc":[{"trd":[[5.7,0.06]],"ltp":5.7,"tv":3801.73,"id":9631939},{"trd":[[1.21,112.43]],"batb":[[2,1.07,13.65]],"batl":[[0,1.21,812.88]],"ltp":1.21,"tv":39953.94,"id":8681938}],"tv":43755.68}]}
{"op":"mcm","clk":"4297398398","pt":1632573177310,"mc":[{"id":"1.188134680","rc":[{"batb":[[0,5,41.74],[1,4.1,2],[2,3.9,162.76]],"ltp":5.7,"tv":3801.73,"id":9631939}]}]}
{"op":"mcm","clk":"4297398427","pt":1632573177401,"mc":[{"id":"1.188134680","rc":[{"batb":[[0,4.1,2],[1,3.9,162.76],[2,3.85,2]],"batl":[[0,8.6,83.54],[1,18,2],[2,36,2]],"ltp":5.7,"tv":3801.73,"id":9631939},{"batb":[[0,1.07,13.65],[1,1.06,2665.56],[2,1.05,49]],"batl":[[0,1.24,15.23],[1,1.3,13.04],[2,1.32,41.36]],"ltp":1.21,"tv":39953.94,"id":8681938}]}]}
{"op":"mcm","clk":"4297398789","pt":1632573179223,"mc":[{"id":"1.188134680","rc":[{"batl":[[0,18,2],[1,36,2],[2,990,0.01]],"ltp":5.7,"tv":3801.73,"id":9631939},{"trd":[[1.24,15.57]],"batl":[[0,1.24,11.8]],"ltp":1.24,"tv":39960.8,"id":8681938}],"tv":43762.54}]}
{"op":"mcm","clk":"4297399023","pt":1632573180322,"mc":[{"id":"1.188134680","rc":[{"batb":[[0,1.07,3032.22]],"ltp":1.24,"tv":39960.8,"id":8681938}]}]}
{"op":"mcm","clk":"4297399644","pt":1632573183228,"mc":[{"id":"1.188134680","rc":[{"batb":[[0,1.07,13.65]],"ltp":1.24,"tv":39960.8,"id":8681938}]}]}
{"op":"mcm","clk":"4297399728","pt":1632573183633,"mc":[{"id":"1.188134680","rc":[{"trd":[[1.24,20.27]],"batl":[[0,1.24,9.46],[1,1.32,41.36],[2,1.33,833.97]],"ltp":1.24,"tv":39965.49,"id":8681938}],"tv":43767.23}]}
{"op":"mcm","clk":"4297400083","pt":1632573185223,"mc":[{"id":"1.188134680","rc":[{"batb":[[0,3.9,162.76],[1,3.85,2],[2,2.44,11.53]],"ltp":5.7,"tv":3801.73,"id":9631939},{"batl":[[0,1.33,833.97],[1,1.34,745.11],[2,1.35,37.9]],"ltp":1.24,"tv":39965.49,"id":8681938}]}]}
{"op":"mcm","clk":"4297400321","pt":1632573186328,"mc":[{"id":"1.188134680","rc":[{"batb":[[0,3.9,243.51]],"batl":[[0,4.2,6.98],[1,4.3,109.3],[2,4.4,54.66]],"ltp":5.7,"tv":3801.73,"id":9631939},{"batb":[[0,1.3,16469.76],[1,1.29,896.66],[2,1.28,226.29]],"batl":[[0,1.33,845.4]],"ltp":1.24,"tv":39965.49,"id":8681938}]}]}
{"op":"mcm","clk":"4297400518","pt":1632573187329,"mc":[{"id":"1.188134680","rc":[{"batb":[[0,3.9,384.71],[1,3.85,62.26],[2,3.8,60.26]],"batl":[[1,4.3,111.01]],"ltp":5.7,"tv":3801.73,"id":9631939},{"batb":[[0,1.3,2461.34],[1,1.29,1506.09]],"batl":[[1,1.34,767.5],[2,1.35,97.9]],"ltp":1.24,"tv":39965.49,"id":8681938}]}]}
{"op":"mcm","clk":"4297400691","pt":1632573188129,"mc":[{"id":"1.188134680","rc":[{"batb":[[1,1.29,896.66]],"ltp":1.24,"tv":39965.49,"id":8681938}]}]}
{"op":"mcm","clk":"4297400811","pt":1632573188719,"mc":[{"id":"1.188134680","rc":[{"batb":[[0,3.95,12.47],[1,3.9,384.71],[2,3.85,62.26]],"ltp":5.7,"tv":3801.73,"id":9631939}]}]}
{"op":"mcm","clk":"4297401097","pt":1632573190322,"mc":[{"id":"1.188134680","rc":[{"batb":[[0,1.31,88.2],[1,1.3,2461.34],[2,1.29,896.66]],"batl":[[0,1.32,65.84],[1,1.33,845.4],[2,1.34,767.5]],"ltp":1.24,"tv":39965.49,"id":8681938}]}]}
{"op":"mcm","clk":"4297401289","pt":1632573191234,"mc":[{"id":"1.188134680","rc":[{"batb":[[1,1.3,2608.69]],"batl":[[1,1.33,906.23]],"ltp":1.24,"tv":39965.49,"id":8681938}]}]}
{"op":"mcm","clk":"4297401503","pt":1632573192143,"mc":[{"id":"1.188134680","rc":[{"batl":[[0,1.32,74.72],[1,1.33,1079.23]],"ltp":1.24,"tv":39965.49,"id":8681938}]}]}
{"op":"mcm","clk":"4297402170","pt":1632573195373,"mc":[{"id":"1.188134680","rc":[{"trd":[[1.31,822.06],[1.32,600.92]],"batb":[[0,1.31,88.15]],"batl":[[0,1.32,70.21],[1,1.33,1350.23]],"ltp":1.32,"tv":39974.59,"id":8681938}],"tv":43776.33}]}
{"op":"mcm","clk":"4297402339","pt":1632573196185,"mc":[{"id":"1.188134680","rc":[{"trd":[[1.31,826.75]],"batb":[[0,1.31,85.81],[1,1.3,2684.05]],"batl":[[0,1.32,144.83]],"ltp":1.31,"tv":39979.29,"id":8681938}],"tv":43781.03}]}
{"op":"mcm","clk":"4297402589","pt":1632573197162,"mc":[{"id":"1.188134680","rc":[{"batl":[[1,4.3,109.3]],"ltp":5.7,"tv":3801.73,"id":9631939},{"trd":[[1.31,840.85]],"batb":[[0,1.31,78.76],[1,1.3,2608.69]],"batl":[[0,1.32,70.21],[1,1.33,1289.4]],"ltp":1.31,"tv":39993.38,"id":8681938}],"tv":43795.12}]}
{"op":"mcm","clk":"4297402773","pt":1632573197969,"mc":[{"id":"1.188134680","rc":[{"batb":[[1,1.3,1358.69]],"batl":[[1,1.33,1514.4]],"ltp":1.31,"tv":39993.38,"id":8681938}]}]}
{"op":"mcm","clk":"4297402963","pt":1632573198852,"mc":[{"id":"1.188134680","rc":[{"trd":[[1.31,851.18]],"batb":[[0,1.31,73.59]],"ltp":1.31,"tv":40003.71,"id":8681938}],"tv":43805.45}]}
{"op":"mcm","clk":"4297403955","pt":1632573203280,"mc":[{"id":"1.188134680","rc":[{"trd":[[1.31,851.63]],"batb":[[0,1.31,73.37]],"ltp":1.31,"tv":40004.16,"id":8681938}],"tv":43805.9}]}
{"op":"mcm","clk":"4297404632","pt":1632573206364,"mc":[{"id":"1.188134680","rc":[{"batb":[[1,3.9,264.19],[2,3.85,2]],"batl":[[1,4.5,32.07],[2,4.9,10]],"ltp":5.7,"tv":3801.73,"id":9631939},{"trd":[[1.31,865.72],[1.32,605.62]],"batb":[[0,1.31,66.32]],"batl":[[0,1.32,67.86],[2,1.34,745.11]],"ltp":1.32,"tv":40022.95,"id":8681938}],"tv":43824.69}]}
{"op":"mcm","clk":"4297404782","pt":1632573207082,"mc":[{"id":"1.188134680","rc":[{"batb":[[0,3.9,20.68],[1,3.35,2.07],[2,3.3,2.01]],"batl":[[0,4.5,32.07],[1,6,108.31],[2,18,2]],"ltp":5.7,"tv":3801.73,"id":9631939},{"batb":[[1,1.3,79.1],[2,1.28,113.38]],"batl":[[1,1.33,669],[2,1.35,60]],"ltp":1.32,"tv":40022.95,"id":8681938}]}]}
{"op":"mcm","clk":"4297405059","pt":1632573208276,"mc":[{"id":"1.188134680","rc":[{"batb":[[0,3.35,2.07],[1,3.3,2.01],[2,3.25,129.62]],"batl":[[0,6,108.31],[1,18,2],[2,990,0.01]],"ltp":5.7,"tv":3801.73,"id":9631939},{"batb":[[0,1.26,11.74],[1,1.09,1818.94],[2,1.06,40]],"batl":[[0,1.32,8.88],[1,1.37,12.57],[2,1.42,30.75]],"ltp":1.32,"tv":40022.95,"id":8681938}]}]}
{"op":"mcm","clk":"4297405129","pt":1632573208594,"mc":[{"id":"1.188134680","rc":[{"batb":[[0,3.25,129.62],[1,3.15,2.03],[2,3.1,2.14]],"batl":[[0,18,2],[1,990,0.01],[2,990,0]],"ltp":5.7,"tv":3801.73,"id":9631939},{"batl":[[2,1.46,27.25]],"ltp":1.32,"tv":40022.95,"id":8681938}]}]}
{"op":"mcm","clk":"4297405470","pt":1632573210201,"mc":[{"id":"1.188134680","rc":[{"batb":[[1,1.1,2936.25],[2,1.09,1818.94]],"batl":[[2,1.44,541.42]],"ltp":1.32,"tv":40022.95,"id":8681938}]}]}
{"op":"mcm","clk":"4297406563","pt":1632573215303,"mc":[{"id":"1.188134680","rc":[{"batb":[[0,3.35,2.07],[1,3.25,129.62],[2,3.15,2.03]],"ltp":5.7,"tv":3801.73,"id":9631939},{"batl":[[2,1.42,25.25]],"ltp":1.32,"tv":40022.95,"id":8681938}]}]}
{"op":"mcm","clk":"4297406639","pt":1632573215687,"mc":[{"id":"1.188134680","rc":[{"batb":[[0,3.25,129.62],[1,3.15,2.03],[2,3.1,2.14]],"ltp":5.7,"tv":3801.73,"id":9631939},{"batl":[[2,1.44,541.42]],"ltp":1.32,"tv":40022.95,"id":8681938}]}]}
{"op":"mcm","clk":"4297407423","pt":1632573219186,"mc":[{"id":"1.188134680","rc":[{"batb":[[1,1.09,1818.94],[2,1.06,40]],"batl":[[1,1.44,541.42],[2,1.45,499.75]],"ltp":1.32,"tv":40022.95,"id":8681938}]}]}
{"op":"mcm","clk":"4297407487","pt":1632573219527,"mc":[{"id":"1.188134680","rc":[{"batl":[[0,1.44,541.42],[1,1.45,499.75],[2,1.46,27.25]],"ltp":1.32,"tv":40022.95,"id":8681938}]}]}
{"op":"mcm","clk":"4297407845","pt":1632573221304,"mc":[{"id":"1.188134680","rc":[{"trd":[[3.25,13.7]],"batb":[[0,3.25,122.77],[1,3.15,6.75]],"batl":[[0,3.35,701.49],[1,3.55,92.9],[2,3.65,8.22]],"ltp":3.25,"tv":3815.44,"id":9631939},{"batb":[[0,1.42,1654.93],[1,1.41,1666.68],[2,1.4,16583.34]],"ltp":1.32,"tv":40022.95,"id":8681938}],"tv":43838.39}]}
{"op":"mcm","clk":"4297408058","pt":1632573222338,"mc":[{"id":"1.188134680","rc":[{"batb":[[1,3.15,752.79],[2,3.1,375.16]],"batl":[[0,3.35,140.3],[1,3.5,1.71],[2,3.55,92.9]],"ltp":3.25,"tv":3815.44,"id":9631939},{"batb":[[0,1.42,330.99],[1,1.41,333.34],[2,1.4,2664.92]],"batl":[[2,1.46,47.8]],"ltp":1.32,"tv":40022.95,"id":8681938}]}]}
{"op":"mcm","clk":"4297408236","pt":1632573223200,"mc":[{"id":"1.188134680","rc":[{"batb":[[1,3.15,183.85],[2,3.1,76.74]],"ltp":3.25,"tv":3815.44,"id":9631939},{"trd":[[1.42,32.6]],"batb":[[0,1.42,330.21]],"ltp":1.42,"tv":40024.51,"id":8681938}],"tv":43839.95}]}
{"op":"mcm","clk":"4297408490","pt":1632573224328,"mc":[{"id":"1.188134680","rc":[{"trd":[[1.42,85.26]],"batb":[[0,1.42,303.88]],"ltp":1.42,"tv":40077.17,"id":8681938}],"tv":43892.61}]}
{"op":"mcm","clk":"4297408946","pt":1632573226293,"mc":[{"id":"1.188134680","rc":[{"batl":[[2,3.55,167.68]],"ltp":3.25,"tv":3815.44,"id":9631939},{"trd":[[1.43,30.38]],"batb":[[0,1.43,7.02],[1,1.42,374.56],[2,1.41,408.53]],"batl":[[0,1.44,712.08],[1,1.45,577.16]],"ltp":1.43,"tv":40093.57,"id":8681938}],"tv":43909.01}]}
{"op":"mcm","clk":"4297409025","pt":1632573226615,"mc":[{"id":"1.188134680","rc":[{"batl":[[2,3.55,92.9]],"ltp":3.25,"tv":3815.44,"id":9631939}]}]}
{"op":"mcm","clk":"4297409468","pt":1632573228811,"mc":[{"id":"1.188134680","rc":[{"batl":[[0,1.44,904.08]],"ltp":1.43,"tv":40093.57,"id":8681938}]}]}
{"op":"mcm","clk":"4297409913","pt":1632573230926,"mc":[{"id":"1.188134680","rc":[{"trd":[[3.25,23.15]],"batb":[[0,3.25,118.04]],"ltp":3.25,"tv":3824.88,"id":9631939},{"trd":[[1.43,31.79]],"batb":[[0,1.43,6.32]],"ltp":1.43,"tv":40094.98,"id":8681938}],"tv":43919.87}]}
{"op":"mcm","clk":"4297410199","pt":1632573232157,"mc":[{"id":"1.188134680","rc":[{"batb":[[1,3.15,179.13]],"batl":[[1,3.55,92.9],[2,3.65,8.22]],"ltp":3.25,"tv":3824.88,"id":9631939},{"batl":[[0,1.44,1089.08],[1,1.45,499.75]],"ltp":1.43,"tv":40094.98,"id":8681938}]}]}
{"op":"mcm","clk":"4297410538","pt":1632573233827,"mc":[{"id":"1.188134680","rc":[{"trd":[[3.25,27.85]],"batb":[[0,3.25,115.69]],"ltp":3.25,"tv":3829.58,"id":9631939},{"batb":[[2,1.41,333.34]],"ltp":1.43,"tv":40094.98,"id":8681938}],"tv":43924.56}]}
{"op":"mcm","clk":"4297410721","pt":1632573234747,"mc":[{"id":"1.188134680","rc":[{"batb":[[1,3.2,5.76],[2,3.15,179.13]],"batl":[[0,3.3,5.51],[1,3.35,140.3],[2,3.55,92.9]],"ltp":3.25,"tv":3829.58,"id":9631939}]}]}
{"op":"mcm","clk":"4297410992","pt":1632573236036,"mc":[{"id":"1.188134680","rc":[{"trd":[[1.43,36.49],[1.44,16.7]],"batb":[[0,1.43,3.97]],"batl":[[0,1.44,1086.73]],"ltp":1.44,"tv":40104.37,"id":8681938}],"tv":43933.96}]}
{"op":"mcm","clk":"4297411826","pt":1632573240349,"mc":[{"id":"1.188134680","rc":[{"trd":[[1.43,41.18]],"batb":[[0,1.43,1.62]],"ltp":1.43,"tv":40109.07,"id":8681938}],"tv":43938.66}]}
{"op":"mcm","clk":"4297411864","pt":1632573240556,"mc":[{"id":"1.188134680","rc":[{"trd":[[3.3,0.52]],"batl":[[0,3.3,4.99]],"ltp":3.3,"tv":3830.1,"id":9631939},{"trd":[[1.43,45.62]],"batb":[[0,1.42,374.56],[1,1.41,333.34],[2,1.4,1414.92]],"ltp":1.43,"tv":40113.51,"id":8681938}],"tv":43943.61}]}
{"op":"mcm","clk":"4297412403","pt":1632573243050,"mc":[{"id":"1.188134680","rc":[{"trd":[[3.3,1.54]],"batl":[[0,3.3,3.97]],"ltp":3.3,"tv":3831.12,"id":9631939},{"trd":[[1.43,47.97]],"ltp":1.43,"tv":40115.86,"id":8681938}],"tv":43946.98}]}
{"op":"mcm","clk":"4297412771","pt":1632573244864,"mc":[{"id":"1.188134680","rc":[{"trd":[[3.3,1.64]],"batl":[[0,3.3,3.87]],"ltp":3.3,"tv":3831.22,"id":9631939},{"trd":[[1.43,48.21]],"ltp":1.43,"tv":40116.09,"id":8681938}],"tv":43947.32}]}
{"op":"mcm","clk":"4297413214","pt":1632573247062,"mc":[{"id":"1.188134680","rc":[{"trd":[[3.3,1.81]],"batl":[[0,3.3,3.7]],"ltp":3.3,"tv":3831.39,"id":9631939},{"trd":[[1.43,48.6],[1.44,21.4]],"batl":[[0,1.44,1084.38]],"ltp":1.44,"tv":40121.18,"id":8681938}],"tv":43952.58}]}
{"op":"mcm","clk":"4297413401","pt":1632573248052,"mc":[{"id":"1.188134680","rc":[{"trd":[[3.3,2.83]],"batb":[[0,3.15,27.9],[1,3.05,3],[2,3,3]],"batl":[[0,4.6,138.79],[1,4.8,2],[2,990,0.01]],"ltp":3.3,"tv":3832.41,"id":9631939},{"trd":[[1.43,50.95]],"batb":[[0,1.42,70.68],[1,1.38,97.33],[2,1.37,10.5]],"batl":[[0,1.44,547.66],[1,1.47,60],[2,1.48,11.49]],"ltp":1.43,"tv":40123.53,"id":8681938}],"tv":43955.94}]}
{"op":"mcm","clk":"4297413614","pt":1632573249284,"mc":[{"id":"1.188134680","rc":[{"batb":[[0,2.44,11.53],[1,2.22,392.26],[2,2.14,156.42]],"ltp":3.3,"tv":3832.41,"id":9631939},{"batb":[[0,1.37,10.5],[1,1.29,493.48],[2,1.27,10]],"batl":[[0,1.48,11.58],[1,2.06,4.25],[2,2.26,3.52]],"ltp":1.43,"tv":40123.53,"id":8681938}]}]}
{"op":"mcm","clk":"4297414024","pt":1632573251247,"mc":[{"id":"1.188134680","rc":[{"batb":[[1,1.3,1259.43],[2,1.29,897.44]],"batl":[[1,1.84,467.96],[2,1.86,410.15]],"ltp":1.43,"tv":40123.53,"id":8681938}]}]}
{"op":"mcm","clk":"4297414674","pt":1632573254346,"mc":[{"id":"1.188134680","rc":[{"batl":[[0,1.48,11.49]],"ltp":1.43,"tv":40123.53,"id":8681938}]}]}
{"op":"mcm","clk":"4297415742","pt":1632573259365,"mc":[{"id":"1.188134680","rc":[{"batl":[[0,1.84,467.96],[1,1.86,410.15],[2,2.06,4.25]],"ltp":1.43,"tv":40123.53,"id":8681938}]}]}
{"op":"mcm","clk":"4297415834","pt":1632573259852,"mc":[{"id":"1.188134680","rc":[{"batb":[[2,1.95,12.31]],"ltp":3.3,"tv":3832.41,"id":9631939},{"batb":[[1,1.3,492.12],[2,1.27,10]],"ltp":1.43,"tv":40123.53,"id":8681938}]}]}
{"op":"mcm","clk":"4297416280","pt":1632573262265,"mc":[{"id":"1.188134680","rc":[{"trd":[[2.44,11.53]],"batb":[[0,2.08,185.68],[1,1.95,12.31],[2,1.8,14.48]],"batl":[[0,2.28,13.23],[1,2.52,11.9],[2,4.8,2]],"ltp":2.44,"tv":3843.94,"id":9631939},{"trd":[[1.7,16.54]],"batb":[[0,1.77,10471.4],[1,1.75,1366.08],[2,1.74,1325.9]],"batl":[[0,1.83,10.87],[1,1.84,467.96],[2,1.85,35.3]],"ltp":1.7,"tv":40140.07,"id":8681938}],"tv":43984.01}]}
{"op":"mcm","clk":"4297416444","pt":1632573263285,"mc":[{"id":"1.188134680","rc":[{"batb":[[0,2.12,159.97],[1,2.08,185.68],[2,1.95,12.31]],"batl":[[1,2.32,1.71],[2,2.52,11.9]],"ltp":2.44,"tv":3843.94,"id":9631939},{"trd":[[1.8,77.8]],"batb":[[0,1.8,114.88],[1,1.77,1326.92],[2,1.75,1039.57]],"ltp":1.8,"tv":40173.77,"id":8681938}],"tv":44017.71}]}
{"op":"mcm","clk":"4297416652","pt":1632573264358,"mc":[{"id":"1.188134680","rc":[{"batl":[[2,2.44,2]],"ltp":2.44,"tv":3843.94,"id":9631939}]}]}
{"op":"mcm","clk":"4297416854","pt":1632573265369,"mc":[{"id":"1.188134680","rc":[{"batb":[[0,2.14,52.63],[1,2.12,159.97],[2,2.1,37.88]],"batl":[[2,2.52,11.9]],"ltp":2.44,"tv":3843.94,"id":9631939},{"batb":[[1,1.79,4],[2,1.78,4]],"ltp":1.8,"tv":40173.77,"id":8681938}]}]}
{"op":"mcm","clk":"4297417045","pt":1632573266287,"mc":[{"id":"1.188134680","rc":[{"batb":[[0,1.81,68.14],[1,1.8,114.88],[2,1.79,4]],"batl":[[0,1.82,58.84],[1,1.83,10.87],[2,1.84,467.96]],"ltp":1.8,"tv":40173.77,"id":8681938}]}]}
{"op":"mcm","clk":"4297417231","pt":1632573267302,"mc":[{"id":"1.188134680","rc":[{"batb":[[1,1.8,179.88]],"batl":[[1,1.83,91.58]],"ltp":1.8,"tv":40173.77,"id":8681938}]}]}
{"op":"mcm","clk":"4297417386","pt":1632573268078,"mc":[{"id":"1.188134680","rc":[{"batb":[[1,2.12,166.15]],"batl":[[0,2.26,24.84],[1,2.28,13.23],[2,2.32,1.71]],"ltp":2.44,"tv":3843.94,"id":9631939}]}]}
{"op":"mcm","clk":"4297417614","pt":1632573269298,"mc":[{"id":"1.188134680","rc":[{"batl":[[0,2.26,169.17]],"ltp":2.44,"tv":3843.94,"id":9631939},{"batl":[[1,1.83,163.58]],"ltp":1.8,"tv":40173.77,"id":8681938}]}]}
{"op":"mcm","clk":"4297417706","pt":1632573269837,"mc":[{"id":"1.188134680","rc":[{"trd":[[1.82,277.67]],"batl":[[0,1.83,163.78],[1,1.84,467.96],[2,1.85,35.3]],"ltp":1.82,"tv":40291.05,"id":8681938}],"tv":44134.99}]}
{"op":"mcm","clk":"4297418040","pt":1632573271321,"mc":[{"id":"1.188134680","rc":[{"batb":[[1,2.12,159.97]],"ltp":2.44,"tv":3843.94,"id":9631939}]}]}
{"op":"mcm","clk":"4297418222","pt":1632573271986,"mc":[{"id":"1.188134680","rc":[{"trd":[[1.81,100.69]],"batb":[[0,1.81,65.6]],"ltp":1.81,"tv":40296.13,"id":8681938}],"tv":44140.07}]}
{"op":"mcm","clk":"4297418586","pt":1632573273339,"mc":[{"id":"1.188134680","rc":[{"batl":[[2,2.38,53.61]],"ltp":2.44,"tv":3843.94,"id":9631939},{"trd":[[1.81,101.47]],"batb":[[0,1.81,65.21]],"batl":[[0,1.83,305.78]],"ltp":1.81,"tv":40296.91,"id":8681938}],"tv":44140.85}]}
{"op":"mcm","clk":"4297418851","pt":1632573274316,"mc":[{"id":"1.188134680","rc":[{"trd":[[1.8,513.99],[1.81,241.29]],"batb":[[0,1.81,93.61],[1,1.79,4],[2,1.78,12.79]],"batl":[[0,1.82,77.02],[1,1.83,224.87],[2,1.84,467.96]],"ltp":1.81,"tv":40872.92,"id":8681938}],"tv":44716.86}]}
{"op":"mcm","clk":"4297419229","pt":1632573275827,"mc":[{"id":"1.188134680","rc":[{"batl":[[2,2.38,2.54]],"ltp":2.44,"tv":3843.94,"id":9631939},{"trd":[[1.81,241.61]],"batb":[[0,1.81,93.45]],"ltp":1.81,"tv":40873.24,"id":8681938}],"tv":44717.18}]}
{"op":"mcm","clk":"4297419609","pt":1632573277218,"mc":[{"id":"1.188134680","rc":[{"trd":[[1.81,249.72]],"batb":[[0,1.81,89.4],[1,1.79,56.5],[2,1.78,4]],"ltp":1.81,"tv":40881.35,"id":8681938}],"tv":44725.29}]}
{"op":"mcm","clk":"4297419870","pt":1632573278288,"mc":[{"id":"1.188134680","rc":[{"batb":[[1,1.95,12.31],[2,1.92,169.55]],"batl":[[0,2.38,2.54],[1,2.44,2.58],[2,2.48,128.38]],"ltp":2.44,"tv":3843.94,"id":9631939},{"trd":[[1.81,307.14]],"batb":[[0,1.76,11.25],[1,1.73,240.36],[2,1.7,19.02]],"batl":[[0,1.83,214],[1,1.87,10.95],[2,2.06,4.25]],"ltp":1.81,"tv":40938.77,"id":8681938}],"tv":44782.71}]}
{"op":"mcm","clk":"4297420124","pt":1632573279300,"mc":[{"id":"1.188134680","rc":[{"batb":[[0,1.95,12.31],[1,1.92,169.55],[2,1.91,244.27]],"ltp":2.44,"tv":3843.94,"id":9631939},{"batb":[[0,1.76,20.26],[1,1.73,170.14]],"batl":[[0,1.81,1.23]],"ltp":1.81,"tv":40938.77,"id":8681938}]}]}
{"op":"mcm","clk":"4297420370","pt":1632573280191,"mc":[{"id":"1.188134680","rc":[{"batb":[[0,1.76,11.25]],"ltp":1.81,"tv":40938.77,"id":8681938}]}]}
{"op":"mcm","clk":"4297420653","pt":1632573281277,"mc":[{"id":"1.188134680","rc":[{"batb":[[0,2,4],[1,1.99,3],[2,1.95,12.31]],"ltp":2.44,"tv":3843.94,"id":9631939},{"batb":[[2,1.72,154.05]],"batl":[[0,1.81,1.5]],"ltp":1.81,"tv":40938.77,"id":8681938}]}]}
{"op":"mcm","clk":"4297420931","pt":1632573282311,"mc":[{"id":"1.188134680","rc":[{"batl":[[0,2.44,2.58],[1,2.48,128.38],[2,2.5,163.65]],"ltp":2.44,"tv":3843.94,"id":9631939},{"batb":[[0,1.72,154.05],[1,1.7,366.18],[2,1.68,567.7]],"batl":[[0,1.81,1.99]],"ltp":1.81,"tv":40938.77,"id":8681938}]}]}
{"op":"mcm","clk":"4297421169","pt":1632573283205,"mc":[{"id":"1.188134680","rc":[{"trd":[[1.99,561.83],[2,340.34],[2.14,11.41],[2.22,22.85]],"batb":[[0,1.99,2.5],[1,1.95,12.31],[2,1.92,115.24]],"ltp":1.99,"tv":3864.37,"id":9631939},{"trd":[[1.81,309.44],[1.87,523.72]],"batl":[[0,2.06,4.25],[1,2.08,120],[2,4.4,3.34]],"ltp":1.87,"tv":40952.02,"id":8681938}],"tv":44816.39}]}
{"op":"mcm","clk":"4297421667","pt":1632573285332,"mc":[{"id":"1.188134680","rc":[{"batb":[[0,2.36,11.5],[1,2.32,92.27],[2,2.3,550.87]],"batl":[[0,2.4,3],[1,2.44,2.58],[2,2.48,128.38]],"ltp":1.99,"tv":3864.37,"id":9631939},{"trd":[[1.72,53.18]],"batb":[[0,1.72,136.3],[1,1.7,374.1]],"batl":[[0,1.75,688.44],[1,1.76,37.11],[2,1.77,481.95]],"ltp":1.72,"tv":40987.52,"id":8681938}],"tv":44851.89}]}
{"op":"mcm","clk":"4297421892","pt":1632573286324,"mc":[{"id":"1.188134680","rc":[{"batl":[[2,2.48,130.09]],"ltp":1.99,"tv":3864.37,"id":9631939},{"batb":[[0,1.72,167.85]],"ltp":1.72,"tv":40987.52,"id":8681938}]}]}
{"op":"mcm","clk":"4297422168","pt":1632573287310,"mc":[{"id":"1.188134680","rc":[{"trd":[[2.36,12.74]],"batb":[[0,2.36,1.78]],"ltp":2.36,"tv":3876.43,"id":9631939},{"trd":[[1.74,75.77]],"ltp":1.74,"tv":40997.52,"id":8681938}],"tv":44873.95}]}
{"op":"mcm","clk":"4297422584","pt":1632573289028,"mc":[{"id":"1.188134680","rc":[{"trd":[[1.72,56.1]],"batb":[[0,1.73,74.06],[1,1.72,166.39],[2,1.7,374.1]],"batl":[[0,1.74,212.39],[1,1.75,747.91],[2,1.76,37.11]],"ltp":1.72,"tv":41000.44,"id":8681938}],"tv":44876.87}]}
{"op":"mcm","clk":"4297422853","pt":1632573290211,"mc":[{"id":"1.188134680","rc":[{"batb":[[1,1.72,247.3]],"ltp":1.72,"tv":41000.44,"id":8681938}]}]}
{"op":"mcm","clk":"4297423083","pt":1632573291333,"mc":[{"id":"1.188134680","rc":[{"batb":[[2,1.71,9.65]],"ltp":1.72,"tv":41000.44,"id":8681938}]}]}
{"op":"mcm","clk":"4297423500","pt":1632573293322,"mc":[{"id":"1.188134680","rc":[{"trd":[[1.73,392.17]],"batb":[[0,1.73,74.01]],"ltp":1.73,"tv":41000.54,"id":8681938}],"tv":44876.98}]}
{"op":"mcm","clk":"4297423681","pt":1632573294333,"mc":[{"id":"1.188134680","rc":[{"trd":[[2.36,16.3]],"batb":[[0,2.32,92.27],[1,2.3,550.87],[2,2.28,450.41]],"ltp":2.36,"tv":3879.99,"id":9631939},{"trd":[[1.73,399.02]],"batb":[[0,1.73,70.58]],"batl":[[0,1.74,272.04]],"ltp":1.73,"tv":41007.4,"id":8681938}],"tv":44887.4}]}
{"op":"mcm","clk":"4297423745","pt":1632573294606,"mc":[{"id":"1.188134680","rc":[{"batb":[[1,1.72,166.39]],"batl":[[0,1.74,212.39],[1,1.75,688.44]],"ltp":1.73,"tv":41007.4,"id":8681938}]}]}
{"op":"mcm","clk":"4297424072","pt":1632573296231,"mc":[{"id":"1.188134680","rc":[{"batl":[[0,2.4,18],[2,2.48,128.38]],"ltp":2.36,"tv":3879.99,"id":9631939}]}]}
{"op":"mcm","clk":"4297424230","pt":1632573296929,"mc":[{"id":"1.188134680","rc":[{"batl":[[0,2.4,3]],"ltp":2.36,"tv":3879.99,"id":9631939},{"trd":[[1.73,403.72]],"batb":[[0,1.73,68.24],[2,1.7,366.18]],"batl":[[1,1.75,321.69]],"ltp":1.73,"tv":41012.1,"id":8681938}],"tv":44892.1}]}
{"op":"mcm","clk":"4297424491","pt":1632573298220,"mc":[{"id":"1.188134680","rc":[{"trd":[[2.34,6.61]],"ltp":2.34,"tv":3885.82,"id":9631939},{"trd":[[1.74,83.61]],"batl":[[0,1.74,204.56]],"ltp":1.74,"tv":41019.93,"id":8681938}],"tv":44905.76}]}
{"op":"mcm","clk":"4297424690","pt":1632573299220,"mc":[{"id":"1.188134680","rc":[{"trd":[[1.74,83.92]],"batl":[[0,1.74,204.41]],"ltp":1.74,"tv":41020.24,"id":8681938}],"tv":44906.07}]}
{"op":"mcm","clk":"4297425251","pt":1632573301658,"mc":[{"id":"1.188134680","rc":[{"batl":[[2,1.77,481.95]],"ltp":1.74,"tv":41020.24,"id":8681938}]}]}
{"op":"mcm","clk":"4297425555","pt":1632573303044,"mc":[{"id":"1.188134680","rc":[{"batb":[[0,2.32,102.83]],"ltp":2.34,"tv":3885.82,"id":9631939},{"trd":[[1.73,403.98]],"batb":[[0,1.73,68.11],[1,1.72,176.46]],"ltp":1.73,"tv":41020.5,"id":8681938}],"tv":44906.33}]}
{"op":"mcm","clk":"4297426066","pt":1632573305135,"mc":[{"id":"1.188134680","rc":[{"batb":[[0,2.32,92.27]],"ltp":2.34,"tv":3885.82,"id":9631939},{"batb":[[1,1.72,166.39]],"ltp":1.73,"tv":41020.5,"id":8681938}]}]}
{"op":"mcm","clk":"4297426289","pt":1632573306137,"mc":[{"id":"1.188134680","rc":[{"batl":[[1,2.42,15],[2,2.44,2.58]],"ltp":2.34,"tv":3885.82,"id":9631939}]}]}
{"op":"mcm","clk":"4297426347","pt":1632573306443,"mc":[{"id":"1.188134680","rc":[{"batl":[[1,2.44,2.58],[2,2.48,128.38]],"ltp":2.34,"tv":3885.82,"id":9631939}]}]}
{"op":"mcm","clk":"4297426794","pt":1632573308346,"mc":[{"id":"1.188134680","rc":[{"batb":[[0,2.3,135.11],[1,2.28,46.87],[2,1.99,103.07]],"batl":[[0,2.52,48.66],[1,990,0.01],[2,2.48,0]],"ltp":2.34,"tv":3885.82,"id":9631939},{"batb":[[0,1.72,134.84],[1,1.69,12.22],[2,1.32,1.3]],"batl":[[0,1.73,2.35],[1,1.78,60],[2,1.8,10.2]],"ltp":1.73,"tv":41020.5,"id":8681938}]}]}
{"op":"mcm","clk":"4297427037","pt":1632573309258,"mc":[{"id":"1.188134680","rc":[{"batb":[[0,1.99,102.56],[1,1.95,12.31],[2,1.18,50.93]],"batl":[[0,990,0.01],[1,990,0]],"ltp":2.34,"tv":3885.82,"id":9631939},{"batb":[[0,1.69,12.22],[1,1.32,1.3],[2,1.29,492.42]],"batl":[[0,1.73,228.99],[1,1.8,10.2],[2,1.88,2.35]],"ltp":1.73,"tv":41020.5,"id":8681938}]}]}
{"op":"mcm","clk":"4297427452","pt":1632573311063,"mc":[{"id":"1.188134680","rc":[{"batb":[[2,1.3,754.49]],"ltp":1.73,"tv":41020.5,"id":8681938}]}]}
{"op":"mcm","clk":"4297427712","pt":1632573312134,"mc":[{"id":"1.188134680","rc":[{"batb":[[0,1.32,1.3],[1,1.3,754.49],[2,1.29,1389.65]],"ltp":1.73,"tv":41020.5,"id":8681938}]}]}
{"op":"mcm","clk":"4297427892","pt":1632573312946,"mc":[{"id":"1.188134680","rc":[{"batl":[[0,1.73,226.65]],"ltp":1.73,"tv":41020.5,"id":8681938}]}]}
{"op":"mcm","clk":"4297428471","pt":1632573315369,"mc":[{"id":"1.188134680","rc":[{"trd":[[2.36,22.18]],"batb":[[0,4,5.83],[1,3.9,245.2],[2,3.85,237.98]],"batl":[[0,4.2,6.49],[1,4.4,2],[2,5,66.58]],"ltp":2.36,"tv":3891.7,"id":9631939},{"trd":[[1.44,22.57],[1.73,412]],"batb":[[0,1.3,765.2],[1,1.29,1397.65],[2,1.28,747.06]],"batl":[[0,1.33,1191.59],[1,1.34,734.68],[2,1.36,48.02]],"ltp":1.44,"tv":41029.7,"id":8681938}],"tv":44921.41}]}
{"op":"mcm","clk":"4297428715","pt":1632573316357,"mc":[{"id":"1.188134680","rc":[{"batb":[[0,4,165.12]],"batl":[[2,4.5,32.07]],"ltp":2.36,"tv":3891.7,"id":9631939},{"batb":[[2,1.28,860.44]],"batl":[[2,1.36,108.02]],"ltp":1.44,"tv":41029.7,"id":8681938}]}]}
{"op":"mcm","clk":"4297429123","pt":1632573318069,"mc":[{"id":"1.188134680","rc":[{"batl":[[1,4.3,3],[2,4.4,2]],"ltp":2.36,"tv":3891.7,"id":9631939},{"batb":[[0,1.31,8.71],[1,1.3,823.14],[2,1.29,1397.65]],"ltp":1.44,"tv":41029.7,"id":8681938}]}]}
{"op":"mcm","clk":"4297429378","pt":1632573319248,"mc":[{"id":"1.188134680","rc":[{"trd":[[1.32,607.04]],"batb":[[0,1.31,86.31]],"batl":[[0,1.32,266.76],[1,1.33,1253.76],[2,1.34,734.68]],"ltp":1.32,"tv":41031.13,"id":8681938}],"tv":44922.83}]}
{"op":"mcm","clk":"4297429637","pt":1632573320361,"mc":[{"id":"1.188134680","rc":[{"batb":[[1,1.3,893.16]],"ltp":1.32,"tv":41031.13,"id":8681938}]}]}
{"op":"mcm","clk":"4297430290","pt":1632573323308,"mc":[{"id":"1.188134680","rc":[{"batb":[[2,3.85,259.03]],"ltp":2.36,"tv":3891.7,"id":9631939},{"batl":[[1,1.33,1181.7]],"ltp":1.32,"tv":41031.13,"id":8681938}]}]}
{"op":"mcm","clk":"4297430508","pt":1632573324378,"mc":[{"id":"1.188134680","rc":[{"trd":[[1.32,607.3]],"batl":[[0,1.32,266.63]],"ltp":1.32,"tv":41031.39,"id":8681938}],"tv":44923.09}]}
{"op":"mcm","clk":"4297430647","pt":1632573325084,"mc":[{"id":"1.188134680","rc":[{"batb":[[1,1.3,823.14]],"ltp":1.32,"tv":41031.39,"id":8681938}]}]}
{"op":"mcm","clk":"4297430836","pt":1632573325892,"mc":[{"id":"1.188134680","rc":[{"batb":[[1,1.3,897.04]],"ltp":1.32,"tv":41031.39,"id":8681938}]}]}
{"op":"mcm","clk":"4297431041","pt":1632573326820,"mc":[{"id":"1.188134680","rc":[{"batl":[[1,1.33,857.29]],"ltp":1.32,"tv":41031.39,"id":8681938}]}]}
{"op":"mcm","clk":"4297431409","pt":1632573328307,"mc":[{"id":"1.188134680","rc":[{"trd":[[1.32,641.87]],"batb":[[1,1.3,887.04],[2,1.29,1389.65]],"batl":[[0,1.32,249.35]],"ltp":1.32,"tv":41065.95,"id":8681938}],"tv":44957.66}]}
{"op":"mcm","clk":"4297431774","pt":1632573329997,"mc":[{"id":"1.188134680","rc":[{"trd":[[4.1,139.09]],"batl":[[2,4.5,32.07]],"ltp":4.1,"tv":3893.34,"id":9631939},{"trd":[[1.31,881.14],[1.32,651.63]],"batb":[[0,1.31,78.6]],"batl":[[0,1.32,241.94]],"ltp":1.32,"tv":41091.14,"id":8681938}],"tv":44984.48}]}
{"op":"mcm","clk":"4297432458","pt":1632573332923,"mc":[{"id":"1.188134680","rc":[{"trd":[[1.32,723.77]],"batl":[[0,1.32,205.87]],"ltp":1.32,"tv":41163.28,"id":8681938}],"tv":45056.62}]}
{"op":"mcm","clk":"4297432793","pt":1632573334230,"mc":[{"id":"1.188134680","rc":[{"trd":[[4.1,139.36]],"ltp":4.1,"tv":3893.61,"id":9631939},{"trd":[[1.31,926.91],[1.32,724.62]],"batb":[[0,1.31,55.71]],"batl":[[0,1.32,205.02]],"ltp":1.31,"tv":41209.89,"id":8681938}],"tv":45103.5}]}
{"op":"mcm","clk":"4297432946","pt":1632573335026,"mc":[{"id":"1.188134680","rc":[{"trd":[[1.31,936.3],[1.32,731.67]],"batb":[[0,1.31,51.02]],"batl":[[0,1.32,201.5]],"ltp":1.32,"tv":41226.33,"id":8681938}],"tv":45119.94}]}
{"op":"mcm","clk":"4297433258","pt":1632573336320,"mc":[{"id":"1.188134680","rc":[{"trd":[[4.1,139.41]],"ltp":4.1,"tv":3893.65,"id":9631939},{"trd":[[1.32,732.19]],"batl":[[0,1.32,201.17]],"ltp":1.32,"tv":41226.85,"id":8681938}],"tv":45120.51}]}
{"op":"mcm","clk":"4297433303","pt":1632573336536,"mc":[{"id":"1.188134680","rc":[{"trd":[[1.32,732.94]],"batl":[[0,1.32,200.79]],"ltp":1.32,"tv":41227.61,"id":8681938}],"tv":45121.27}]}
{"op":"mcm","clk":"4297433512","pt":1632573337423,"mc":[{"id":"1.188134680","rc":[{"trd":[[1.32,737.64]],"batl":[[0,1.32,198.44]],"ltp":1.32,"tv":41232.3,"id":8681938}],"tv":45125.96}]}
{"op":"mcm","clk":"4297434090","pt":1632573339933,"mc":[{"id":"1.188134680","rc":[{"trd":[[1.32,737.67]],"batl":[[0,1.32,198.42]],"ltp":1.32,"tv":41232.33,"id":8681938}],"tv":45125.99}]}
{"op":"mcm","clk":"4297434269","pt":1632573340825,"mc":[{"id":"1.188134680","rc":[{"trd":[[4.2,48.85]],"batl":[[0,4.2,5.96]],"ltp":4.2,"tv":3894.71,"id":9631939}],"tv":45127.05}]}
{"op":"mcm","clk":"4297435255","pt":1632573345008,"mc":[{"id":"1.188134680","rc":[{"trd":[[1.32,739.23]],"batl":[[0,1.32,197.64]],"ltp":1.32,"tv":41233.9,"id":8681938}],"tv":45128.61}]}
{"op":"mcm","clk":"4297435477","pt":1632573346039,"mc":[{"id":"1.188134680","rc":[{"trd":[[1.31,950.39]],"batb":[[0,1.31,43.97]],"ltp":1.31,"tv":41247.99,"id":8681938}],"tv":45142.7}]}
{"op":"mcm","clk":"4297436658","pt":1632573350933,"mc":[{"id":"1.188134680","rc":[{"batl":[[0,4.3,3],[1,4.5,32.07],[2,4.8,6.25]],"ltp":4.2,"tv":3894.71,"id":9631939},{"batl":[[1,1.33,844.14]],"ltp":1.31,"tv":41247.99,"id":8681938}]}]}
{"op":"mcm","clk":"4297436916","pt":1632573352036,"mc":[{"id":"1.188134680","rc":[{"batb":[[1,1.3,58.65],[2,1.29,492.42]],"batl":[[1,1.33,114.67],[2,1.34,22.39]],"ltp":1.31,"tv":41247.99,"id":8681938}]}]}
{"op":"mcm","clk":"4297437400","pt":1632573354157,"mc":[{"id":"1.188134680","rc":[{"batl":[[0,4.2,5.96],[1,4.3,18],[2,4.5,32.07]],"ltp":4.2,"tv":3894.71,"id":9631939},{"batl":[[1,1.33,129.49]],"ltp":1.31,"tv":41247.99,"id":8681938}]}]}
{"op":"mcm","clk":"4297437723","pt":1632573355567,"mc":[{"id":"1.188134680","rc":[{"trd":[[1.32,742.99]],"batl":[[0,1.32,195.77]],"ltp":1.32,"tv":41251.74,"id":8681938}],"tv":45146.46}]}
{"op":"mcm","clk":"4297437964","pt":1632573356597,"mc":[{"id":"1.188134680","rc":[{"trd":[[4.1,139.44]],"ltp":4.1,"tv":3894.75,"id":9631939},{"trd":[[1.32,743.11]],"batl":[[0,1.32,195.65]],"ltp":1.32,"tv":41251.86,"id":8681938}],"tv":45146.62}]}
{"op":"mcm","clk":"4297438559","pt":1632573359299,"mc":[{"id":"1.188134680","rc":[{"batb":[[1,3.85,21.05],[2,3.75,3]],"ltp":4.1,"tv":3894.75,"id":9631939},{"batl":[[2,1.35,69.48]],"ltp":1.32,"tv":41251.86,"id":8681938}]}]}
{"op":"mcm","clk":"4297438774","pt":1632573360150,"mc":[{"id":"1.188134680","rc":[{"batb":[[0,3.85,21.05],[1,3.15,146.3],[2,2.96,2.13]],"batl":[[0,4.5,32.07],[1,990,0.01],[2,4.5,0]],"ltp":4.1,"tv":3894.75,"id":9631939},{"batb":[[0,1.28,113.38],[1,1.21,13.44],[2,1.2,2.35]],"batl":[[0,1.35,69.48],[1,1.46,27.25],[2,1.48,782.28]],"ltp":1.32,"tv":41251.86,"id":8681938}]}]}
{"op":"mcm","clk":"4297439032","pt":1632573361299,"mc":[{"id":"1.188134680","rc":[{"batb":[[0,3.15,146.3],[1,2.96,2.13],[2,1.18,50.93]],"batl":[[0,990,0.01],[1,990,0]],"ltp":4.1,"tv":3894.75,"id":9631939},{"batb":[[0,1.21,13.44],[1,1.2,2.35],[2,1.07,1740.52]],"batl":[[0,1.35,9.48]],"ltp":1.32,"tv":41251.86,"id":8681938}]}]}
{"op":"mcm","clk":"4297439469","pt":1632573363081,"mc":[{"id":"1.188134680","rc":[{"batb":[[0,3.15,2.23],[1,3.1,147.29],[2,2.96,2.13]],"ltp":4.1,"tv":3894.75,"id":9631939}]}]}
{"op":"mcm","clk":"4297439934","pt":1632573365072,"mc":[{"id":"1.188134680","rc":[{"batb":[[0,1.21,13.64]],"ltp":1.32,"tv":41251.86,"id":8681938}]}]}
{"op":"mcm","clk":"4297440716","pt":1632573368499,"mc":[{"id":"1.188134680","rc":[{"batb":[[0,1.21,13.44]],"ltp":1.32,"tv":41251.86,"id":8681938}]}]}
{"op":"mcm","clk":"4297441651","pt":1632573372574,"mc":[{"id":"1.188134680","rc":[{"batl":[[0,1.32,12.18],[1,1.35,9.48],[2,1.46,27.25]],"ltp":1.32,"tv":41251.86,"id":8681938}]}]}
{"op":"mcm","clk":"4297442720","pt":1632573377089,"mc":[{"id":"1.188134680","rc":[{"batb":[[2,1.05,2976.19]],"batl":[[0,1.46,27.25],[1,1.48,782.28],[2,1.49,444.13]],"ltp":1.32,"tv":41251.86,"id":8681938}]}]}
{"op":"mcm","clk":"4297442791","pt":1632573377399,"mc":[{"id":"1.188134680","rc":[{"batb":[[0,3.1,147.29],[1,2.96,2.13],[2,1.18,50.93]],"ltp":4.1,"tv":3894.75,"id":9631939},{"batl":[[0,1.48,782.28],[1,1.49,444.13],[2,1.51,28.72]],"ltp":1.32,"tv":41251.86,"id":8681938}]}]}
{"op":"mcm","clk":"4297443428","pt":1632573380276,"mc":[{"id":"1.188134680","rc":[{"trd":[[3.1,294.58]],"batb":[[0,2.96,11.67],[1,2.88,110.47]],"batl":[[0,3.4,8.82],[1,3.45,1.71],[2,4.3,523.89]],"ltp":3.1,"tv":4189.33,"id":9631939},{"trd":[[1.48,29.5]],"batb":[[0,1.46,965.76],[1,1.45,2427.71],[2,1.44,892.42]],"batl":[[0,1.48,767.53],[2,1.51,22.72]],"ltp":1.48,"tv":41281.36,"id":8681938}],"tv":45470.69}]}
{"op":"mcm","clk":"4297443647","pt":1632573381297,"mc":[{"id":"1.188134680","rc":[{"batb":[[0,3,30],[1,2.96,11.67],[2,2.88,110.47]],"batl":[[2,3.5,37.94]],"ltp":3.1,"tv":4189.33,"id":9631939},{"batb":[[0,1.46,321.92],[1,1.45,809.24],[2,1.44,570.5]],"batl":[[2,1.5,60.71]],"ltp":1.48,"tv":41281.36,"id":8681938}]}]}
{"op":"mcm","clk":"4297443750","pt":1632573381783,"mc":[{"id":"1.188134680","rc":[{"batl":[[2,4.3,523.89]],"ltp":3.1,"tv":4189.33,"id":9631939}]}]}
{"op":"mcm","clk":"4297444019","pt":1632573383169,"mc":[{"id":"1.188134680","rc":[{"batb":[[2,2.9,3]],"batl":[[0,3.35,30.36],[1,3.4,8.82],[2,3.45,1.71]],"ltp":3.1,"tv":4189.33,"id":9631939},{"trd":[[1.46,58.4]],"batb":[[0,1.46,303.36],[1,1.45,816.24],[2,1.44,578.5]],"ltp":1.46,"tv":41318.48,"id":8681938}],"tv":45507.81}]}
{"op":"mcm","clk":"4297444234","pt":1632573384296,"mc":[{"id":"1.188134680","rc":[{"batb":[[0,1.46,359.57]],"batl":[[0,1.47,133.74],[1,1.48,848.85],[2,1.49,511.65]],"ltp":1.46,"tv":41318.48,"id":8681938}]}]}
{"op":"mcm","clk":"4297444393","pt":1632573385109,"mc":[{"id":"1.188134680","rc":[{"batl":[[0,3.4,8.82],[1,3.45,40.04],[2,4.3,523.89]],"ltp":3.1,"tv":4189.33,"id":9631939},{"batb":[[1,1.45,887.21]],"ltp":1.46,"tv":41318.48,"id":8681938}]}]}
{"op":"mcm","clk":"4297444641","pt":1632573386285,"mc":[{"id":"1.188134680","rc":[{"batb":[[0,3,52.59]],"ltp":3.1,"tv":4189.33,"id":9631939}]}]}
{"op":"mcm","clk":"4297444719","pt":1632573386708,"mc":[{"id":"1.188134680","rc":[{"batl":[[0,1.47,412.74]],"ltp":1.46,"tv":41318.48,"id":8681938}]}]}
{"op":"mcm","clk":"4297445044","pt":1632573388282,"mc":[{"id":"1.188134680","rc":[{"trd":[[1.46,59.68]],"batb":[[0,1.46,358.93]],"ltp":1.46,"tv":41319.77,"id":8681938}],"tv":45509.1}]}
{"op":"mcm","clk":"4297445240","pt":1632573389210,"mc":[{"id":"1.188134680","rc":[{"batb":[[2,1.44,519.18]],"batl":[[1,1.48,541.1],[2,1.49,67.52]],"ltp":1.46,"tv":41319.77,"id":8681938}]}]}
{"op":"mcm","clk":"4297445271","pt":1632573389408,"mc":[{"id":"1.188134680","rc":[{"batl":[[2,1.5,60]],"ltp":1.46,"tv":41319.77,"id":8681938}]}]}
{"op":"mcm","clk":"4297445661","pt":1632573391382,"mc":[{"id":"1.188134680","rc":[{"batb":[[1,2.96,2.13]],"batl":[[0,3.35,30.36],[1,3.4,8.82],[2,3.45,38.33]],"ltp":3.1,"tv":4189.33,"id":9631939}]}]}
{"op":"mcm","clk":"4297445790","pt":1632573392007,"mc":[{"id":"1.188134680","rc":[{"batb":[[0,1.46,439.05],[1,1.45,816.24]],"batl":[[0,1.47,859.4],[1,1.48,459.78]],"ltp":1.46,"tv":41319.77,"id":8681938}]}]}
{"op":"mcm","clk":"4297445949","pt":1632573392711,"mc":[{"id":"1.188134680","rc":[{"batl":[[0,1.47,1003.4]],"ltp":1.46,"tv":41319.77,"id":8681938}]}]}
{"op":"mcm","clk":"4297446128","pt":1632573393622,"mc":[{"id":"1.188134680","rc":[{"batb":[[0,3,58.19]],"ltp":3.1,"tv":4189.33,"id":9631939},{"trd":[[1.47,34.61]],"batl":[[0,1.47,991.09],[2,1.5,71.2]],"ltp":1.47,"tv":41344.38,"id":8681938}],"tv":45533.71}]}
{"op":"mcm","clk":"4297446868","pt":1632573397214,"mc":[{"id":"1.188134680","rc":[{"trd":[[1.46,67.2]],"batb":[[0,1.46,435.29],[2,1.44,511.18]],"ltp":1.46,"tv":41351.89,"id":8681938}],"tv":45541.23}]}
{"op":"mcm","clk":"4297447148","pt":1632573398818,"mc":[{"id":"1.188134680","rc":[{"trd":[[1.46,70.58]],"batb":[[0,1.46,433.6]],"ltp":1.46,"tv":41355.27,"id":8681938}],"tv":45544.61}]}
{"op":"mcm","clk":"4297447345","pt":1632573399826,"mc":[{"id":"1.188134680","rc":[{"trd":[[1.46,72.06]],"batb":[[0,1.46,432.86]],"ltp":1.46,"tv":41356.75,"id":8681938}],"tv":45546.08}]}
{"op":"mcm","clk":"4297447460","pt":1632573400419,"mc":[{"id":"1.188134680","rc":[{"batb":[[2,1.44,516.18]],"ltp":1.46,"tv":41356.75,"id":8681938}]}]}
{"op":"mcm","clk":"4297448143","pt":1632573403841,"mc":[{"id":"1.188134680","rc":[{"batb":[[0,3,52.59]],"ltp":3.1,"tv":4189.33,"id":9631939},{"batl":[[2,1.5,60]],"ltp":1.46,"tv":41356.75,"id":8681938}]}]}
{"op":"mcm","clk":"4297448794","pt":1632573406835,"mc":[{"id":"1.188134680","rc":[{"trd":[[1.46,76.76]],"batb":[[0,1.46,442.86]],"batl":[[1,1.48,471.61]],"ltp":1.46,"tv":41361.45,"id":8681938}],"tv":45550.78}]}
{"op":"mcm","clk":"4297449009","pt":1632573407833,"mc":[{"id":"1.188134680","rc":[{"trd":[[1.46,81.85]],"batb":[[0,1.46,440.31]],"ltp":1.46,"tv":41366.54,"id":8681938}],"tv":45555.87}]}
{"op":"mcm","clk":"4297449549","pt":1632573410248,"mc":[{"id":"1.188134680","rc":[{"batb":[[0,3,30],[1,1.99,103.15],[2,1.67,17.47]],"batl":[[0,3.45,38.33],[1,990,0.01],[2,3.45,0]],"ltp":3.1,"tv":4189.33,"id":9631939},{"batb":[[0,1.46,136.33],[1,1.4,12.99],[2,1.3,491.75]],"batl":[[0,1.47,608.19],[1,1.5,60],[2,1.72,13.3]],"ltp":1.46,"tv":41366.54,"id":8681938}]}]}
{"op":"mcm","clk":"4297449806","pt":1632573411343,"mc":[{"id":"1.188134680","rc":[{"batb":[[0,1.99,103.15],[1,1.67,17.47],[2,1.55,23.79]],"batl":[[0,990,0.01],[1,990,0]],"ltp":3.1,"tv":4189.33,"id":9631939},{"batb":[[0,1.4,12.99],[1,1.3,491.75],[2,1.2,2.35]],"batl":[[0,1.72,13.3],[1,1.73,218.62],[2,1.88,2.35]],"ltp":1.46,"tv":41366.54,"id":8681938}]}]}
{"op":"mcm","clk":"4297450221","pt":1632573413379,"mc":[{"id":"1.188134680","rc":[{"batb":[[0,1.93,106.7],[1,1.55,23.79],[2,1.18,50.93]],"ltp":3.1,"tv":4189.33,"id":9631939},{"batb":[[0,1.3,1273.78],[1,1.29,897.42]],"ltp":1.46,"tv":41366.54,"id":8681938}]}]}
{"op":"mcm","clk":"4297450409","pt":1632573414156,"mc":[{"id":"1.188134680","rc":[{"batb":[[0,1.41,93.7],[1,1.3,1273.78],[2,1.29,897.42]],"ltp":1.46,"tv":41366.54,"id":8681938}]}]}
{"op":"mcm","clk":"4297450482","pt":1632573414442,"mc":[{"id":"1.188134680","rc":[{"batb":[[0,1.3,1273.78],[1,1.29,897.42],[2,1.2,2.35]],"ltp":1.46,"tv":41366.54,"id":8681938}]}]}
{"op":"mcm","clk":"4297450887","pt":1632573416347,"mc":[{"id":"1.188134680","rc":[{"batb":[[0,3.9,4.36],[1,3.85,83.27],[2,1.93,106.7]],"batl":[[0,4.7,99.11],[1,990,0.01]],"ltp":3.1,"tv":4189.33,"id":9631939},{"trd":[[1.32,761.89]],"batb":[[0,1.3,1291.84],[2,1.25,52.25]],"batl":[[0,1.32,13.65],[1,1.33,760.95],[2,1.34,773.08]],"ltp":1.32,"tv":41385.33,"id":8681938}],"tv":45574.66}]}
{"op":"mcm","clk":"4297451107","pt":1632573417341,"mc":[{"id":"1.188134680","rc":[{"batb":[[1,3.85,252.96],[2,3.8,21.42]],"batl":[[0,4.4,3],[1,4.5,32.07],[2,4.6,1.71]],"ltp":3.1,"tv":4189.33,"id":9631939},{"batb":[[0,1.3,1299.84],[1,1.29,906.42],[2,1.28,1101.56]],"ltp":1.32,"tv":41385.33,"id":8681938}]}]}
{"op":"mcm","clk":"4297451314","pt":1632573418146,"mc":[{"id":"1.188134680","rc":[{"batl":[[0,4.3,3],[1,4.4,3],[2,4.5,32.07]],"ltp":3.1,"tv":4189.33,"id":9631939},{"batb":[[0,1.31,9],[1,1.3,1359.96],[2,1.29,906.42]],"ltp":1.32,"tv":41385.33,"id":8681938}]}]}
{"op":"mcm","clk":"4297451730","pt":1632573420152,"mc":[{"id":"1.188134680","rc":[{"trd":[[1.31,968.39]],"batb":[[0,1.3,1433.49],[1,1.29,906.42],[2,1.28,480.56]],"batl":[[0,1.31,127.26],[1,1.32,93.99],[2,1.33,760.95]],"ltp":1.31,"tv":41403.33,"id":8681938}],"tv":45592.66}]}
{"op":"mcm","clk":"4297451969","pt":1632573421254,"mc":[{"id":"1.188134680","rc":[{"batb":[[0,3.9,73.37],[2,3.75,3]],"ltp":3.1,"tv":4189.33,"id":9631939},{"batb":[[1,1.29,962.4]],"batl":[[2,1.33,834.51]],"ltp":1.31,"tv":41403.33,"id":8681938}]}]}
{"op":"mcm","clk":"4297452259","pt":1632573422342,"mc":[{"id":"1.188134680","rc":[{"batb":[[0,3.9,19.51]],"batl":[[0,4.3,35.56]],"ltp":3.1,"tv":4189.33,"id":9631939}]}]}
{"op":"mcm","clk":"4297452343","pt":1632573422646,"mc":[{"id":"1.188134680","rc":[{"batl":[[0,4.3,18]],"ltp":3.1,"tv":4189.33,"id":9631939}]}]}
{"op":"mcm","clk":"4297452712","pt":1632573424153,"mc":[{"id":"1.188134680","rc":[{"batb":[[1,3.85,274.01]],"ltp":3.1,"tv":4189.33,"id":9631939},{"trd":[[1.31,1222.55]],"batl":[[0,1.32,94.18],[1,1.33,834.51],[2,1.34,773.08]],"ltp":1.31,"tv":41657.48,"id":8681938}],"tv":45846.81}]}
{"op":"mcm","clk":"4297453069","pt":1632573425769,"mc":[{"id":"1.188134680","rc":[{"batb":[[1,1.29,906.42]],"batl":[[1,1.33,771.08]],"ltp":1.31,"tv":41657.48,"id":8681938}]}]}
{"op":"mcm","clk":"4297453412","pt":1632573427244,"mc":[{"id":"1.188134680","rc":[{"trd":[[1.31,1222.93],[1.32,776.07]],"batb":[[0,1.31,2.35],[1,1.3,1433.49],[2,1.29,906.42]],"batl":[[0,1.32,86.9]],"ltp":1.32,"tv":41672.04,"id":8681938}],"tv":45861.37}]}
{"op":"mcm","clk":"4297453682","pt":1632573428379,"mc":[{"id":"1.188134680","rc":[{"batb":[[1,1.3,1480.49],[2,1.29,897.42]],"batl":[[0,1.32,80.34],[1,1.33,697.52]],"ltp":1.32,"tv":41672.04,"id":8681938}]}]}
{"op":"mcm","clk":"4297453856","pt":1632573429169,"mc":[{"id":"1.188134680","rc":[{"batb":[[2,3.7,3]],"batl":[[0,4.3,18.21],[1,4.5,32.07],[2,4.7,99.11]],"ltp":3.1,"tv":4189.33,"id":9631939},{"trd":[[1.32,780.77]],"batb":[[1,1.3,1420.37]],"batl":[[0,1.32,77.99]],"ltp":1.32,"tv":41676.74,"id":8681938}],"tv":45866.07}]}
{"op":"mcm","clk":"4297454226","pt":1632573430688,"mc":[{"id":"1.188134680","rc":[{"batb":[[0,1.31,15.8]],"batl":[[1,1.33,722.88]],"ltp":1.32,"tv":41676.74,"id":8681938}]}]}
{"op":"mcm","clk":"4297454469","pt":1632573431875,"mc":[{"id":"1.188134680","rc":[{"batl":[[0,4.3,18.19]],"ltp":3.1,"tv":4189.33,"id":9631939},{"batb":[[0,1.31,76.37]],"ltp":1.32,"tv":41676.74,"id":8681938}]}]}
{"op":"mcm","clk":"4297455118","pt":1632573435012,"mc":[{"id":"1.188134680","rc":[{"trd":[[4.1,139.72]],"ltp":4.1,"tv":4189.6,"id":9631939},{"trd":[[1.32,781.62]],"batl":[[0,1.32,77.14]],"ltp":1.32,"tv":41677.59,"id":8681938}],"tv":45867.19}]}
{"op":"mcm","clk":"4297455319","pt":1632573435880,"mc":[{"id":"1.188134680","rc":[{"batb":[[0,1.31,75.92]],"ltp":1.32,"tv":41677.59,"id":8681938}]}]}
{"op":"mcm","clk":"4297455555","pt":1632573437003,"mc":[{"id":"1.188134680","rc":[{"batb":[[0,1.31,14.1]],"batl":[[1,1.33,697.52]],"ltp":1.32,"tv":41677.59,"id":8681938}]}]}
{"op":"mcm","clk":"4297455849","pt":1632573438326,"mc":[{"id":"1.188134680","rc":[{"batb":[[0,3.85,190.74],[1,3.7,3],[2,2.22,138.41]],"batl":[[0,4.3,3.19],[2,990,0.01]],"ltp":4.1,"tv":4189.6,"id":9631939},{"trd":[[1.32,786.31]],"batb":[[0,1.31,2.35],[1,1.3,558.74],[2,1.28,113.38]],"batl":[[0,1.32,74.79],[1,1.35,60],[2,1.4,11.16]],"ltp":1.32,"tv":41682.28,"id":8681938}],"tv":45871.89}]}
{"op":"mcm","clk":"4297456057","pt":1632573439310,"mc":[{"id":"1.188134680","rc":[{"trd":[[4.2,49.03]],"batb":[[0,3.85,21.05],[1,2.22,138.41],[2,1.82,14.64]],"batl":[[0,4.5,32.07],[1,990,0.01],[2,990,0]],"ltp":4.2,"tv":4189.79,"id":9631939},{"trd":[[1.31,1228.23]],"batb":[[0,1.28,113.38],[1,1.21,11.72],[2,1.2,796.45]],"batl":[[0,1.35,60.12],[1,1.4,11.16],[2,1.88,2.35]],"ltp":1.31,"tv":41687.58,"id":8681938}],"tv":45877.37}]}
{"op":"mcm","clk":"4297456172","pt":1632573439919,"mc":[{"id":"1.188134680","rc":[{"trd":[[4.2,49.07]],"batb":[[0,2.22,138.41],[1,1.82,14.64],[2,1.67,17.47]],"batl":[[0,990,0.4],[1,990,0]],"ltp":4.2,"tv":4189.82,"id":9631939},{"trd":[[1.31,1228.35]],"batb":[[0,1.32,30]],"batl":[[0,1.4,11.16],[1,1.88,2.35],[2,2.08,120]],"ltp":1.31,"tv":41687.7,"id":8681938}],"tv":45877.53}]}
{"op":"mcm","clk":"4297456458","pt":1632573441111,"mc":[{"id":"1.188134680","rc":[{"batb":[[0,1.32,30.09]],"batl":[[1,1.75,338.77],[2,1.77,480.96]],"ltp":1.31,"tv":41687.7,"id":8681938}]}]}
{"op":"mcm","clk":"4297456832","pt":1632573442907,"mc":[{"id":"1.188134680","rc":[{"batl":[[0,990,0.01]],"ltp":4.2,"tv":4189.82,"id":9631939},{"batb":[[0,1.32,30.19]],"ltp":1.31,"tv":41687.7,"id":8681938}]}]}
{"op":"mcm","clk":"4297457070","pt":1632573444106,"mc":[{"id":"1.188134680","rc":[{"batb":[[1,1.67,17.47],[2,1.18,50.93]],"ltp":4.2,"tv":4189.82,"id":9631939},{"batb":[[1,1.2,796.45],[2,1.19,1413.31]],"batl":[[1,1.88,2.35],[2,2.08,120]],"ltp":1.31,"tv":41687.7,"id":8681938}]}]}
{"op":"mcm","clk":"4297457782","pt":1632573447296,"mc":[{"id":"1.188134680","rc":[{"batb":[[0,5.5,177.56],[1,5.4,168.76],[2,5.3,249]],"batl":[[0,6.8,140.62],[1,7,136.48],[2,7.2,136.48]],"ltp":4.2,"tv":4189.82,"id":9631939},{"trd":[[1.32,846.68]],"batb":[[0,1.2,796.45],[1,1.19,1413.31],[2,1.18,1341.73]],"batl":[[0,1.21,905.5],[1,1.22,1693.46],[2,1.24,52.67]],"ltp":1.32,"tv":41748.07,"id":8681938}],"tv":45937.9}]}
{"op":"mcm","clk":"4297457997","pt":1632573448317,"mc":[{"id":"1.188134680","rc":[{"batl":[[0,6.6,25.35],[1,6.8,142.33],[2,7,136.48]],"ltp":4.2,"tv":4189.82,"id":9631939}]}]}
{"op":"mcm","clk":"4297458373","pt":1632573450022,"mc":[{"id":"1.188134680","rc":[{"batb":[[0,5.5,189.41]],"ltp":4.2,"tv":4189.82,"id":9631939},{"batb":[[2,1.18,1483.15]],"batl":[[2,1.24,112.67]],"ltp":1.32,"tv":41748.07,"id":8681938}]}]}
{"op":"mcm","clk":"4297458595","pt":1632573451105,"mc":[{"id":"1.188134680","rc":[{"batb":[[0,1.2,864.34]],"batl":[[0,1.21,976.34],[1,1.22,1759.96]],"ltp":1.32,"tv":41748.07,"id":8681938}]}]}
{"op":"mcm","clk":"4297458769","pt":1632573451920,"mc":[{"id":"1.188134680","rc":[{"trd":[[1.2,124.38]],"batb":[[0,1.2,802.15],[1,1.19,1474.3]],"batl":[[2,1.24,52.67]],"ltp":1.2,"tv":41872.45,"id":8681938}],"tv":46062.28}]}
{"op":"mcm","clk":"4297459053","pt":1632573453326,"mc":[{"id":"1.188134680","rc":[{"batl":[[0,6.4,21.93],[1,6.6,25.35],[2,6.8,142.33]],"ltp":4.2,"tv":4189.82,"id":9631939}]}]}
{"op":"mcm","clk":"4297459417","pt":1632573455126,"mc":[{"id":"1.188134680","rc":[{"batb":[[1,5.4,182.39]],"ltp":4.2,"tv":4189.82,"id":9631939},{"batl":[[2,1.23,60]],"ltp":1.2,"tv":41872.45,"id":8681938}]}]}
{"op":"mcm","clk":"4297459518","pt":1632573455641,"mc":[{"id":"1.188134680","rc":[{"trd":[[1.21,114.23]],"batl":[[0,1.21,975.44]],"ltp":1.21,"tv":41874.25,"id":8681938}],"tv":46064.08}]}
{"op":"mcm","clk":"4297459813","pt":1632573457044,"mc":[{"id":"1.188134680","rc":[{"trd":[[5.7,0.08]],"ltp":5.7,"tv":4189.84,"id":9631939},{"trd":[[1.21,115.22]],"batb":[[1,1.19,1413.31]],"batl":[[0,1.21,974.9],[1,1.22,1693.46],[2,1.23,71.42]],"ltp":1.21,"tv":41875.24,"id":8681938}],"tv":46065.09}]}
{"op":"mcm","clk":"4297460103","pt":1632573458253,"mc":[{"id":"1.188134680","rc":[{"batl":[[2,6.8,140.62]],"ltp":5.7,"tv":4189.84,"id":9631939},{"trd":[[1.2,152.56]],"batb":[[0,1.2,788.06]],"ltp":1.2,"tv":41903.42,"id":8681938}],"tv":46093.27}]}
{"op":"mcm","clk":"4297460177","pt":1632573458523,"mc":[{"id":"1.188134680","rc":[{"batl":[[0,1.21,566.47]],"ltp":1.2,"tv":41903.42,"id":8681938}]}]}
{"op":"mcm","clk":"4297460551","pt":1632573460330,"mc":[{"id":"1.188134680","rc":[{"batl":[[1,6.8,140.62],[2,7,136.48]],"ltp":5.7,"tv":4189.84,"id":9631939}]}]}
{"op":"mcm","clk":"4297460611","pt":1632573460652,"mc":[{"id":"1.188134680","rc":[{"batl":[[0,6.8,140.62],[1,7,136.48],[2,7.2,136.48]],"ltp":5.7,"tv":4189.84,"id":9631939}]}]}
{"op":"mcm","clk":"4297461023","pt":1632573462244,"mc":[{"id":"1.188134680","rc":[{"trd":[[1.21,119.92]],"batl":[[0,1.21,564.12]],"ltp":1.21,"tv":41908.12,"id":8681938}],"tv":46097.96}]}
{"op":"mcm","clk":"4297461241","pt":1632573463353,"mc":[{"id":"1.188134680","rc":[{"trd":[[1.2,674.12],[1.21,120.29]],"batb":[[0,1.2,527.28]],"batl":[[0,1.21,563.94]],"ltp":1.21,"tv":42430.05,"id":8681938}],"tv":46619.89}]}
{"op":"mcm","clk":"4297461385","pt":1632573464055,"mc":[{"id":"1.188134680","rc":[{"batl":[[0,6.4,25.81],[1,6.8,140.62],[2,7,136.48]],"ltp":5.7,"tv":4189.84,"id":9631939}]}]}
{"op":"mcm","clk":"4297461560","pt":1632573464825,"mc":[{"id":"1.188134680","rc":[{"trd":[[5.7,0.47]],"ltp":5.7,"tv":4190.23,"id":9631939},{"trd":[[1.21,122.13]],"batl":[[0,1.21,562.1]],"ltp":1.21,"tv":42431.89,"id":8681938}],"tv":46622.13}]}
{"op":"mcm","clk":"4297462044","pt":1632573467129,"mc":[{"id":"1.188134680","rc":[{"batl":[[0,6.2,21.93],[1,6.4,25.81],[2,6.8,140.62]],"ltp":5.7,"tv":4190.23,"id":9631939}]}]}
{"op":"mcm","clk":"4297462189","pt":1632573467840,"mc":[{"id":"1.188134680","rc":[{"trd":[[1.21,140.17]],"batl":[[0,1.21,553.08]],"ltp":1.21,"tv":42449.93,"id":8681938}],"tv":46640.16}]}
{"op":"mcm","clk":"4297463107","pt":1632573472372,"mc":[{"id":"1.188134680","rc":[{"batb":[[0,5.5,15.55],[1,5.4,13.63],[2,5.3,80.24]],"batl":[[2,7.6,92.56]],"ltp":5.7,"tv":4190.23,"id":9631939},{"trd":[[1.21,380.56]],"batb":[[2,1.18,1396.04]],"batl":[[0,1.21,70.84]],"ltp":1.21,"tv":42690.32,"id":8681938}],"tv":46880.56}]}
{"op":"mcm","clk":"4297463318","pt":1632573473264,"mc":[{"id":"1.188134680","rc":[{"batb":[[0,5.4,13.63],[1,4,2],[2,3.85,169.02]],"batl":[[0,6.4,25.81],[1,8.6,83.54],[2,990,0.01]],"ltp":5.7,"tv":4190.23,"id":9631939},{"batb":[[0,1.18,141.42],[1,1.15,9.19],[2,1.01,140]],"batl":[[0,1.23,71.42],[1,1.33,36.5],[2,1.37,37.5]],"ltp":1.21,"tv":42690.32,"id":8681938}]}]}
{"op":"mcm","clk":"4297463552","pt":1632573474245,"mc":[{"id":"1.188134680","rc":[{"batb":[[0,4,2],[1,3.85,169.02],[2,3.7,2]],"batl":[[0,990,0.01],[1,8.6,0],[2,990,0]],"ltp":5.7,"tv":4190.23,"id":9631939},{"trd":[[1.18,382.4]],"batb":[[0,1.21,2.35]],"batl":[[0,1.23,11.42]],"ltp":1.18,"tv":42840.98,"id":8681938}],"tv":47031.22}]}
{"op":"mcm","clk":"4297464091","pt":1632573476373,"mc":[{"id":"1.188134680","rc":[{"batb":[[0,3.95,161.91],[1,3.7,2],[2,1.18,50.93]],"ltp":5.7,"tv":4190.23,"id":9631939},{"batb":[[1,1.01,140],[2,1.01,0]],"batl":[[1,1.35,35.3]],"ltp":1.18,"tv":42840.98,"id":8681938}]}]}
{"op":"mcm","clk":"4297464260","pt":1632573477170,"mc":[{"id":"1.188134680","rc":[{"batl":[[0,5.7,5.12],[1,990,0.01]],"ltp":5.7,"tv":4190.23,"id":9631939},{"batl":[[1,1.37,37.5],[2,1.88,2.35]],"ltp":1.18,"tv":42840.98,"id":8681938}]}]}
{"op":"mcm","clk":"4297464498","pt":1632573478371,"mc":[{"id":"1.188134680","rc":[{"trd":[[5.7,5.59]],"batl":[[0,990,0.01],[1,990,0]],"ltp":5.7,"tv":4195.35,"id":9631939},{"trd":[[1.21,409.38]],"batb":[[0,1.02,102.8]],"batl":[[0,1.18,1211.66],[1,1.23,11.42],[2,1.37,37.5]],"ltp":1.21,"tv":42869.8,"id":8681938}],"tv":47065.15}]}
{"op":"mcm","clk":"4297464716","pt":1632573479348,"mc":[{"id":"1.188134680","rc":[{"batb":[[0,4.1,2],[1,3.95,161.91],[2,3.9,2]],"ltp":5.7,"tv":4195.35,"id":9631939},{"batb":[[0,1.15,849],[1,1.14,1976.77],[2,1.02,102.8]],"batl":[[0,1.17,1726.28],[1,1.18,1025.52],[2,1.23,11.42]],"ltp":1.21,"tv":42869.8,"id":8681938}]}]}
{"op":"mcm","clk":"4297464946","pt":1632573480360,"mc":[{"id":"1.188134680","rc":[{"batb":[[0,4,2],[2,3.7,2]],"ltp":5.7,"tv":4195.35,"id":9631939}]}]}
{"op":"mcm","clk":"4297465042","pt":1632573480747,"mc":[{"id":"1.188134680","rc":[{"batb":[[0,5.6,44.64],[1,4,2],[2,3.95,161.91]],"batl":[[0,11.5,71.53],[1,990,0.01]],"ltp":5.7,"tv":4195.35,"id":9631939}]}]}
{"op":"mcm","clk":"4297465712","pt":1632573483882,"mc":[{"id":"1.188134680","rc":[{"batl":[[0,9,24.31],[1,11.5,71.53],[2,990,0.01]],"ltp":5.7,"tv":4195.35,"id":9631939},{"batl":[[0,1.17,1783.38]],"ltp":1.21,"tv":42869.8,"id":8681938}]}]}
{"op":"mcm","clk":"4297465960","pt":1632573485043,"mc":[{"id":"1.188134680","rc":[{"batb":[[0,1.15,1145.21]],"ltp":1.21,"tv":42869.8,"id":8681938}]}]}
{"op":"mcm","clk":"4297466216","pt":1632573485959,"mc":[{"id":"1.188134680","rc":[{"batb":[[0,1.15,123.29],[1,1.02,102.8],[2,1.01,152.79]],"batl":[[0,1.23,11.42],[1,1.33,38.5],[2,1.35,31.3]],"ltp":1.21,"tv":42869.8,"id":8681938}]}]}
{"op":"mcm","clk":"4297466462","pt":1632573486988,"mc":[{"id":"1.188134680","rc":[{"trd":[[1.15,18.78]],"batb":[[0,1.02,102.8],[1,1.01,152.79],[2,1.01,0]],"ltp":1.15,"tv":42888.58,"id":8681938}],"tv":47083.94}]}
{"op":"mcm","clk":"4297466743","pt":1632573488295,"mc":[{"id":"1.188134680","rc":[{"batb":[[1,1.01,358.39]],"ltp":1.15,"tv":42888.58,"id":8681938}]}]}
{"op":"mcm","clk":"4297466948","pt":1632573489081,"mc":[{"id":"1.188134680","rc":[{"batb":[[0,1.17,60],[1,1.02,102.8],[2,1.01,358.39]],"batl":[[0,1.2,57.1],[1,1.23,11.42],[2,1.33,673.37]],"ltp":1.15,"tv":42888.58,"id":8681938}]}]}
{"op":"mcm","clk":"4297467193","pt":1632573490157,"mc":[{"id":"1.188134680","rc":[{"trd":[[1.17,1725.13]],"batb":[[0,1.17,48.15],[1,1.15,50.29],[2,1.02,102.8]],"ltp":1.17,"tv":42912.28,"id":8681938}],"tv":47107.64}]}
{"op":"mcm","clk":"4297468452","pt":1632573495677,"mc":[{"id":"1.188134680","rc":[{"trd":[[1.2,674.5]],"batl":[[0,1.2,56.91]],"ltp":1.2,"tv":42912.66,"id":8681938}],"tv":47108.02}]}
{"op":"mcm","clk":"4297469697","pt":1632573500937,"mc":[{"id":"1.188134680","rc":[{"batb":[[0,4,2],[1,3.95,161.91],[2,3.7,2]],"batl":[[0,11.5,71.53],[1,990,0.01],[2,990,0]],"ltp":5.7,"tv":4195.35,"id":9631939},{"batb":[[1,1.02,102.8],[2,1.01,358.39]],"batl":[[0,1.23,11.42],[1,1.3,5.67]],"ltp":1.2,"tv":42912.66,"id":8681938}]}]}
{"op":"mcm","clk":"4297469903","pt":1632573501811,"mc":[{"id":"1.188134680","rc":[{"batl":[[0,11.5,71.88]],"ltp":5.7,"tv":4195.35,"id":9631939}]}]}
{"op":"mcm","clk":"4297470131","pt":1632573502724,"mc":[{"id":"1.188134680","rc":[{"batl":[[0,990,0.36],[1,990,0]],"ltp":5.7,"tv":4195.35,"id":9631939}]}]}
{"op":"mcm","clk":"4297471236","pt":1632573507433,"mc":[{"id":"1.188134680","rc":[{"trd":[[6,0.35]],"batl":[[0,990,0.01]],"ltp":6.0,"tv":4195.7,"id":9631939},{"trd":[[1.17,1735.71],[1.2,676.25]],"batb":[[0,1.17,42.86]],"ltp":1.17,"tv":42925.0,"id":8681938}],"tv":47120.7}]}
{"op":"mcm","clk":"4297471604","pt":1632573509108,"mc":[{"id":"1.188134680","rc":[{"trd":[[5.3,2.72]],"ltp":5.3,"tv":4196.02,"id":9631939},{"trd":[[1.23,1080.73]],"batl":[[0,1.23,10.07]],"ltp":1.23,"tv":42926.34,"id":8681938}],"tv":47122.36}]}
{"op":"mcm","clk":"4297472279","pt":1632573512214,"mc":[{"id":"1.188134680","rc":[{"batl":[[0,1.3,5.67],[1,1.33,673.37],[2,1.34,712.06]],"ltp":1.23,"tv":42926.34,"id":8681938}]}]}
{"op":"mcm","clk":"4297472950","pt":1632573515315,"mc":[{"id":"1.188134680","rc":[{"trd":[[4.3,55.99]],"batb":[[0,4.1,4.08],[1,4,2],[2,3.95,161.91]],"batl":[[0,4.4,322.17],[1,4.5,53.4],[2,4.6,53.4]],"ltp":4.3,"tv":4197.73,"id":9631939},{"trd":[[1.3,3382.73]],"batb":[[0,1.31,12.29],[1,1.3,924.52],[2,1.29,897.03]],"batl":[[0,1.33,673.37],[1,1.34,712.06],[2,1.35,31.3]],"ltp":1.3,"tv":42932.01,"id":8681938}],"tv":47129.74}]}
{"op":"mcm","clk":"4297473139","pt":1632573516333,"mc":[{"id":"1.188134680","rc":[{"batb":[[2,1.29,1390.47]],"batl":[[1,1.34,734.45]],"ltp":1.3,"tv":42932.01,"id":8681938}]}]}
{"op":"mcm","clk":"4297473194","pt":1632573516636,"mc":[{"id":"1.188134680","rc":[{"batb":[[1,4,22]],"ltp":4.3,"tv":4197.73,"id":9631939},{"batb":[[1,1.3,929.52],[2,1.29,1395.47]],"batl":[[1,1.34,794.45]],"ltp":1.3,"tv":42932.01,"id":8681938}]}]}
{"op":"mcm","clk":"4297473517","pt":1632573518097,"mc":[{"id":"1.188134680","rc":[{"batl":[[0,4.3,15.51],[1,4.4,322.17],[2,4.5,53.4]],"ltp":4.3,"tv":4197.73,"id":9631939}]}]}
{"op":"mcm","clk":"4297473771","pt":1632573519298,"mc":[{"id":"1.188134680","rc":[{"batb":[[1,4,20]],"ltp":4.3,"tv":4197.73,"id":9631939},{"batb":[[0,1.32,6.8],[1,1.31,80.53],[2,1.3,929.52]],"batl":[[0,1.33,856.02]],"ltp":1.3,"tv":42932.01,"id":8681938}]}]}
{"op":"mcm","clk":"4297473919","pt":1632573520035,"mc":[{"id":"1.188134680","rc":[{"batb":[[2,1.3,999.8]],"batl":[[1,1.34,868.87]],"ltp":1.3,"tv":42932.01,"id":8681938}]}]}
{"op":"mcm","clk":"4297474109","pt":1632573521018,"mc":[{"id":"1.188134680","rc":[{"trd":[[1.32,847.58]],"batb":[[0,1.32,6.34]],"ltp":1.32,"tv":42932.92,"id":8681938}],"tv":47130.65}]}
{"op":"mcm","clk":"4297474342","pt":1632573522107,"mc":[{"id":"1.188134680","rc":[{"trd":[[4.1,139.94]],"batb":[[0,4.1,3.97]],"ltp":4.1,"tv":4197.95,"id":9631939},{"trd":[[1.32,851.34]],"batb":[[0,1.32,4.47]],"batl":[[0,1.33,991.02]],"ltp":1.32,"tv":42936.67,"id":8681938}],"tv":47134.62}]}
{"op":"mcm","clk":"4297474599","pt":1632573523232,"mc":[{"id":"1.188134680","rc":[{"batb":[[2,1.3,934.94]],"ltp":1.32,"tv":42936.67,"id":8681938}]}]}
{"op":"mcm","clk":"4297474742","pt":1632573523958,"mc":[{"id":"1.188134680","rc":[{"trd":[[1.32,855.67]],"batb":[[0,1.32,2.3]],"ltp":1.32,"tv":42941.0,"id":8681938}],"tv":47138.96}]}
{"op":"mcm","clk":"4297475013","pt":1632573525133,"mc":[{"id":"1.188134680","rc":[{"batb":[[2,1.3,864.66]],"batl":[[1,1.34,794.45]],"ltp":1.32,"tv":42941.0,"id":8681938}]}]}
{"op":"mcm","clk":"4297475205","pt":1632573526052,"mc":[{"id":"1.188134680","rc":[{"batl":[[1,4.4,320.46]],"ltp":4.1,"tv":4197.95,"id":9631939},{"batl":[[0,1.33,1229.46]],"ltp":1.32,"tv":42941.0,"id":8681938}]}]}
{"op":"mcm","clk":"4297475708","pt":1632573528247,"mc":[{"id":"1.188134680","rc":[{"batb":[[1,1.31,87.16]],"ltp":1.32,"tv":42941.0,"id":8681938}]}]}
{"op":"mcm","clk":"4297475874","pt":1632573529059,"mc":[{"id":"1.188134680","rc":[{"trd":[[1.32,855.71]],"batb":[[0,1.32,2.28]],"ltp":1.32,"tv":42941.04,"id":8681938}],"tv":47138.99}]}
{"op":"mcm","clk":"4297476570","pt":1632573532352,"mc":[{"id":"1.188134680","rc":[{"batb":[[0,4,20],[1,3.95,161.91],[2,3.8,123.68]],"ltp":4.1,"tv":4197.95,"id":9631939},{"trd":[[1.32,860.27],[1.33,3617.37]],"batb":[[0,1.31,74.87],[1,1.3,864.66],[2,1.29,1390.47]],"batl":[[0,1.33,1220.92]],"ltp":1.33,"tv":42962.67,"id":8681938}],"tv":47160.63}]}
{"op":"mcm","clk":"4297476971","pt":1632573534045,"mc":[{"id":"1.188134680","rc":[{"trd":[[1.31,1228.74]],"batb":[[0,1.31,74.68]],"ltp":1.31,"tv":42963.07,"id":8681938}],"tv":47161.02}]}
{"op":"mcm","clk":"4297477162","pt":1632573534949,"mc":[{"id":"1.188134680","rc":[{"batb":[[0,4.1,3.97],[1,4,20],[2,3.95,161.91]],"ltp":4.1,"tv":4197.95,"id":9631939},{"trd":[[1.31,1230.3]],"batb":[[0,1.31,86.53]],"batl":[[0,1.32,2.35],[1,1.33,1220.92],[2,1.34,794.45]],"ltp":1.31,"tv":42964.63,"id":8681938}],"tv":47162.58}]}
{"op":"mcm","clk":"4297477605","pt":1632573536850,"mc":[{"id":"1.188134680","rc":[{"trd":[[1.33,3624.42]],"batl":[[0,1.33,1217.4],[1,1.34,794.45],[2,1.35,31.3]],"ltp":1.33,"tv":42971.67,"id":8681938}],"tv":47169.62}]}
{"op":"mcm","clk":"4297478062","pt":1632573538949,"mc":[{"id":"1.188134680","rc":[{"trd":[[1.33,3625.73]],"batl":[[0,1.33,1216.74]],"ltp":1.33,"tv":42972.99,"id":8681938}],"tv":47170.94}]}
{"op":"mcm","clk":"4297478220","pt":1632573539663,"mc":[{"id":"1.188134680","rc":[{"trd":[[1.33,3626.28]],"batl":[[0,1.33,1216.47]],"ltp":1.33,"tv":42973.53,"id":8681938}],"tv":47171.49}]}
{"op":"mcm","clk":"4297478823","pt":1632573542073,"mc":[{"id":"1.188134680","rc":[{"trd":[[4.1,140.14]],"batb":[[0,4.1,3.87]],"ltp":4.1,"tv":4198.15,"id":9631939},{"trd":[[1.31,1230.49]],"batb":[[0,1.31,86.43]],"ltp":1.31,"tv":42973.72,"id":8681938}],"tv":47171.87}]}
{"op":"mcm","clk":"4297479351","pt":1632573544360,"mc":[{"id":"1.188134680","rc":[{"batb":[[0,4,20],[1,3.95,161.91],[2,3.75,2]],"batl":[[0,4.6,31.62],[1,5.3,2],[2,6,108.31]],"ltp":4.1,"tv":4198.15,"id":9631939},{"batb":[[0,1.31,60.54],[1,1.3,5],[2,1.29,493.44]],"batl":[[0,1.33,531.15],[1,1.34,60],[2,1.45,24.9]],"ltp":1.31,"tv":42973.72,"id":8681938}]}]}
{"op":"mcm","clk":"4297479578","pt":1632573545253,"mc":[{"id":"1.188134680","rc":[{"batb":[[0,3.2,2.02],[1,3.15,145.43],[2,3,2]],"batl":[[0,6,108.31],[1,990,0.01],[2,6,0]],"ltp":4.1,"tv":4198.15,"id":9631939},{"batb":[[0,1.26,11.45],[1,1.05,3020.66],[2,1.01,140]],"batl":[[0,1.45,24.9],[1,1.46,29.75],[2,1.49,23.99]],"ltp":1.31,"tv":42973.72,"id":8681938}]}]}
{"op":"mcm","clk":"4297479703","pt":1632573545791,"mc":[{"id":"1.188134680","rc":[{"batb":[[0,3.15,143.4],[1,3,2],[2,2.96,2.13]],"batl":[[0,990,0.01],[1,990,0]],"ltp":4.1,"tv":4198.15,"id":9631939},{"batl":[[0,1.49,23.99],[1,1.5,26.59],[2,1.51,22.5]],"ltp":1.31,"tv":42973.72,"id":8681938}]}]}
{"op":"mcm","clk":"4297479991","pt":1632573546906,"mc":[{"id":"1.188134680","rc":[{"batb":[[1,1.07,1309.09],[2,1.06,1725.61]],"batl":[[0,1.47,390.47],[1,1.48,459],[2,1.49,23.99]],"ltp":1.31,"tv":42973.72,"id":8681938}]}]}
{"op":"mcm","clk":"4297480548","pt":1632573549059,"mc":[{"id":"1.188134680","rc":[{"batb":[[1,1.05,3020.66],[2,1.01,140]],"batl":[[0,1.47,397.47]],"ltp":1.31,"tv":42973.72,"id":8681938}]}]}
{"op":"mcm","clk":"4297481059","pt":1632573551283,"mc":[{"id":"1.188134680","rc":[{"batl":[[0,990,0.1]],"ltp":4.1,"tv":4198.15,"id":9631939},{"batl":[[0,1.47,390.47]],"ltp":1.31,"tv":42973.72,"id":8681938}]}]}
{"op":"mcm","clk":"4297481312","pt":1632573552285,"mc":[{"id":"1.188134680","rc":[{"batb":[[1,3.05,313.52],[2,3,306.3]],"batl":[[0,3.35,92.47],[1,3.4,290.06],[2,3.45,272.98]],"ltp":4.1,"tv":4198.15,"id":9631939},{"trd":[[1.47,64.19]],"batb":[[0,1.44,339.95],[1,1.43,1785.91],[2,1.39,46.98]],"batl":[[0,1.47,375.68]],"ltp":1.47,"tv":43003.3,"id":8681938}],"tv":47201.45}]}
{"op":"mcm","clk":"4297481554","pt":1632573553365,"mc":[{"id":"1.188134680","rc":[{"batb":[[1,3.1,28.57],[2,3.05,313.52]],"batl":[[0,3.35,94.18]],"ltp":4.1,"tv":4198.15,"id":9631939},{"trd":[[1.44,27.27]],"batb":[[0,1.44,337.6],[2,1.42,319.69]],"batl":[[1,1.48,519]],"ltp":1.44,"tv":43008.0,"id":8681938}],"tv":47206.15}]}
{"op":"mcm","clk":"4297481973","pt":1632573555285,"mc":[{"id":"1.188134680","rc":[{"batl":[[0,3.25,3],[1,3.3,3],[2,3.35,94.18]],"ltp":4.1,"tv":4198.15,"id":9631939},{"batb":[[0,1.46,12.32],[1,1.44,344.6],[2,1.43,1790.91]],"batl":[[1,1.48,530.81]],"ltp":1.44,"tv":43008.0,"id":8681938}]}]}
{"op":"mcm","clk":"4297482240","pt":1632573556375,"mc":[{"id":"1.188134680","rc":[{"trd":[[1.46,106.49]],"batb":[[0,1.45,68.96]],"batl":[[0,1.46,43.71],[1,1.47,439.68],[2,1.48,530.81]],"ltp":1.46,"tv":43032.63,"id":8681938}],"tv":47230.79}]}
{"op":"mcm","clk":"4297482448","pt":1632573557284,"mc":[{"id":"1.188134680","rc":[{"batb":[[1,1.44,471.53]],"batl":[[1,1.47,504.8]],"ltp":1.46,"tv":43032.63,"id":8681938}]}]}
{"op":"mcm","clk":"4297482681","pt":1632573558289,"mc":[{"id":"1.188134680","rc":[{"batl":[[0,3.25,26.16]],"ltp":4.1,"tv":4198.15,"id":9631939}]}]}
{"op":"mcm","clk":"4297482913","pt":1632573559276,"mc":[{"id":"1.188134680","rc":[{"batl":[[1,1.47,677.8]],"ltp":1.46,"tv":43032.63,"id":8681938}]}]}
{"op":"mcm","clk":"4297483114","pt":1632573560278,"mc":[{"id":"1.188134680","rc":[{"batb":[[1,1.44,133.93]],"ltp":1.46,"tv":43032.63,"id":8681938}]}]}
{"op":"mcm","clk":"4297483341","pt":1632573561306,"mc":[{"id":"1.188134680","rc":[{"trd":[[3.15,0.19]],"batb":[[0,3.15,143.3]],"ltp":3.15,"tv":4198.34,"id":9631939}],"tv":47230.97}]}
{"op":"mcm","clk":"4297483503","pt":1632573562012,"mc":[{"id":"1.188134680","rc":[{"batl":[[1,1.47,809.8],[2,1.48,519]],"ltp":1.46,"tv":43032.63,"id":8681938}]}]}
{"op":"mcm","clk":"4297483795","pt":1632573563286,"mc":[{"id":"1.188134680","rc":[{"trd":[[3.15,0.81]],"batb":[[0,3.15,142.99]],"batl":[[2,3.35,92.47]],"ltp":3.15,"tv":4198.96,"id":9631939},{"trd":[[1.45,26.77]],"batb":[[0,1.45,68.87],[2,1.43,2106.88]],"batl":[[1,1.47,850.44]],"ltp":1.45,"tv":43032.82,"id":8681938}],"tv":47231.79}]}
{"op":"mcm","clk":"4297484017","pt":1632573564281,"mc":[{"id":"1.188134680","rc":[{"trd":[[3.15,0.85]],"batb":[[0,3.15,142.97]],"ltp":3.15,"tv":4199.0,"id":9631939},{"batb":[[0,1.45,80.3],[1,1.44,64.25],[2,1.43,856.88]],"batl":[[0,1.46,100.31],[1,1.47,785.32]],"ltp":1.45,"tv":43032.82,"id":8681938}],"tv":47231.83}]}
{"op":"mcm","clk":"4297484165","pt":1632573565000,"mc":[{"id":"1.188134680","rc":[{"trd":[[1.45,33.62]],"batb":[[0,1.45,89.65]],"batl":[[1,1.47,797.55]],"ltp":1.45,"tv":43039.68,"id":8681938}],"tv":47238.68}]}
{"op":"mcm","clk":"4297484454","pt":1632573566281,"mc":[{"id":"1.188134680","rc":[{"trd":[[1.45,41.13],[1.46,111.18]],"batb":[[0,1.45,73.12]],"batl":[[0,1.46,97.96],[1,1.47,785.32]],"ltp":1.45,"tv":43051.89,"id":8681938}],"tv":47250.89}]}
{"op":"mcm","clk":"4297484583","pt":1632573566881,"mc":[{"id":"1.188134680","rc":[{"batl":[[1,3.35,92.47],[2,3.4,290.06]],"ltp":3.15,"tv":4199.0,"id":9631939},{"trd":[[1.45,45.83]],"batb":[[0,1.45,70.77],[2,1.43,851.88]],"ltp":1.45,"tv":43056.58,"id":8681938}],"tv":47255.59}]}
{"op":"mcm","clk":"4297484807","pt":1632573567987,"mc":[{"id":"1.188134680","rc":[{"batb":[[0,1.45,66.2]],"ltp":1.45,"tv":43056.58,"id":8681938}]}]}
{"op":"mcm","clk":"4297485049","pt":1632573569172,"mc":[{"id":"1.188134680","rc":[{"batb":[[0,1.45,78.98]],"batl":[[1,1.47,797.55]],"ltp":1.45,"tv":43056.58,"id":8681938}]}]}
{"op":"mcm","clk":"4297485130","pt":1632573569605,"mc":[{"id":"1.188134680","rc":[{"trd":[[1.45,50.53]],"batb":[[0,1.45,76.64]],"ltp":1.45,"tv":43061.28,"id":8681938}],"tv":47260.28}]}
{"op":"mcm","clk":"4297485390","pt":1632573570794,"mc":[{"id":"1.188134680","rc":[{"trd":[[3.15,162.11]],"batb":[[0,3.15,62.34]],"ltp":3.15,"tv":4360.26,"id":9631939},{"trd":[[1.45,50.84],[1.46,125.27]],"batb":[[0,1.45,76.48]],"batl":[[0,1.46,90.91]],"ltp":1.45,"tv":43075.68,"id":8681938}],"tv":47435.95}]}
{"op":"mcm","clk":"4297485684","pt":1632573572105,"mc":[{"id":"1.188134680","rc":[{"trd":[[1.45,51.08]],"batb":[[0,1.45,76.36]],"ltp":1.45,"tv":43075.92,"id":8681938}],"tv":47436.18}]}
{"op":"mcm","clk":"4297486969","pt":1632573578016,"mc":[{"id":"1.188134680","rc":[{"trd":[[1.45,56.08],[1.46,129.97]],"batb":[[0,1.45,73.86]],"batl":[[0,1.46,88.57]],"ltp":1.45,"tv":43085.62,"id":8681938}],"tv":47445.89}]}
{"op":"mcm","clk":"4297487259","pt":1632573579490,"mc":[{"id":"1.188134680","rc":[{"trd":[[1.45,56.32]],"batb":[[0,1.45,73.74]],"ltp":1.45,"tv":43085.86,"id":8681938}],"tv":47446.12}]}
{"op":"mcm","clk":"4297487798","pt":1632573582055,"mc":[{"id":"1.188134680","rc":[{"batb":[[0,3.1,28.57],[1,2.12,396.48],[2,1.98,103.24]],"batl":[[0,3.5,37.94],[1,4.2,151.01],[2,990,0.01]],"ltp":3.15,"tv":4360.26,"id":9631939},{"batb":[[0,1.45,60.96],[1,1.41,12.17],[2,1.4,94.86]],"batl":[[1,1.47,369],[2,1.48,60]],"ltp":1.45,"tv":43085.86,"id":8681938}]}]}
{"op":"mcm","clk":"4297488079","pt":1632573583310,"mc":[{"id":"1.188134680","rc":[{"batb":[[0,1.98,103.24],[1,1.69,20.21],[2,1.18,50.93]],"batl":[[0,990,0.01],[1,4.2,0],[2,990,0]],"ltp":3.15,"tv":4360.26,"id":9631939},{"batb":[[0,1.41,12.17],[1,1.29,494.03],[2,1.01,140]],"batl":[[0,1.87,12.39],[1,1.88,2.35],[2,2.08,120]],"ltp":1.45,"tv":43085.86,"id":8681938}]}]}
{"op":"mcm","clk":"4297488533","pt":1632573585316,"mc":[{"id":"1.188134680","rc":[{"batb":[[0,1.94,105.27],[2,1.57,19.57]],"ltp":3.15,"tv":4360.26,"id":9631939},{"batb":[[1,1.3,1351.69],[2,1.29,897.5]],"batl":[[0,1.87,12.93],[2,2.02,249.62]],"ltp":1.45,"tv":43085.86,"id":8681938}]}]}
{"op":"mcm","clk":"4297488738","pt":1632573586205,"mc":[{"id":"1.188134680","rc":[{"batl":[[0,1.87,13.22]],"ltp":1.45,"tv":43085.86,"id":8681938}]}]}
{"op":"mcm","clk":"4297489412","pt":1632573589381,"mc":[{"id":"1.188134680","rc":[{"batl":[[0,1.45,1.8],[1,1.87,12.39],[2,1.88,2.35]],"ltp":1.45,"tv":43085.86,"id":8681938}]}]}
{"op":"mcm","clk":"4297489616","pt":1632573590321,"mc":[{"id":"1.188134680","rc":[{"trd":[[1.41,15.03]],"batb":[[0,1.41,11.89]],"ltp":1.41,"tv":43086.43,"id":8681938}],"tv":47446.69}]}
{"op":"mcm","clk":"4297489835","pt":1632573591096,"mc":[{"id":"1.188134680","rc":[{"batl":[[0,1.87,13.13],[1,1.88,2.35],[2,2.02,249.62]],"ltp":1.41,"tv":43086.43,"id":8681938}]}]}
{"op":"mcm","clk":"4297489957","pt":1632573591715,"mc":[{"id":"1.188134680","rc":[{"batl":[[0,1.87,12.93]],"ltp":1.41,"tv":43086.43,"id":8681938}]}]}
{"op":"mcm","clk":"4297490221","pt":1632573592988,"mc":[{"id":"1.188134680","rc":[{"batb":[[1,1.3,485.58],[2,1.01,140]],"batl":[[0,1.88,2.89],[1,2.08,120],[2,2.1,2.55]],"ltp":1.41,"tv":43086.43,"id":8681938}]}]}
{"op":"mcm","clk":"4297490691","pt":1632573595128,"mc":[{"id":"1.188134680","rc":[{"batl":[[0,1.88,2.44]],"ltp":1.41,"tv":43086.43,"id":8681938}]}]}
{"op":"mcm","clk":"4297490956","pt":1632573596187,"mc":[{"id":"1.188134680","rc":[{"trd":[[3.2,0.04]],"batl":[[0,2.9,19.55],[1,990,0.01]],"ltp":3.2,"tv":4360.3,"id":9631939},{"trd":[[1.45,56.41]],"batb":[[0,1.53,19.33],[1,1.51,684.71],[2,1.5,440.05]],"batl":[[0,1.56,597.22],[1,1.57,363.49],[2,1.63,19.5]],"ltp":1.45,"tv":43086.52,"id":8681938}],"tv":47446.82}]}
{"op":"mcm","clk":"4297491161","pt":1632573597206,"mc":[{"id":"1.188134680","rc":[{"batb":[[0,2.04,402.03],[1,1.94,105.27],[2,1.69,20.21]],"batl":[[0,3.9,161.43]],"ltp":3.2,"tv":4360.3,"id":9631939},{"batb":[[0,1.51,684.71],[1,1.5,440.05],[2,1.41,11.89]],"batl":[[2,1.88,2.35]],"ltp":1.45,"tv":43086.52,"id":8681938}]}]}
{"op":"mcm","clk":"4297491285","pt":1632573597833,"mc":[{"id":"1.188134680","rc":[{"batb":[[0,2.44,95.7],[1,2.04,402.03],[2,1.94,105.27]],"ltp":3.2,"tv":4360.3,"id":9631939},{"batl":[[2,1.7,14.45]],"ltp":1.45,"tv":43086.52,"id":8681938}]}]}
{"op":"mcm","clk":"4297491591","pt":1632573599307,"mc":[{"id":"1.188134680","rc":[{"batb":[[0,2.04,402.03],[1,1.94,105.27],[2,1.7,11.96]],"batl":[[0,3,32.83],[1,3.9,161.43],[2,990,0.01]],"ltp":3.2,"tv":4360.3,"id":9631939},{"batb":[[0,1.41,11.89],[1,1.3,485.58],[2,1.01,140]],"batl":[[0,1.88,2.35],[1,2.08,120],[2,2.1,2.55]],"ltp":1.45,"tv":43086.52,"id":8681938}]}]}
{"op":"mcm","clk":"4297491763","pt":1632573600232,"mc":[{"id":"1.188134680","rc":[{"batl":[[0,3.9,161.43],[1,990,0.01],[2,990,0]],"ltp":3.2,"tv":4360.3,"id":9631939}]}]}
{"op":"mcm","clk":"4297492122","pt":1632573601729,"mc":[{"id":"1.188134680","rc":[{"batb":[[1,1.3,1351.69],[2,1.29,897.5]],"batl":[[1,2.02,249.62],[2,2.04,309.26]],"ltp":1.45,"tv":43086.52,"id":8681938}]}]}
{"op":"mcm","clk":"4297492889","pt":1632573605125,"mc":[{"id":"1.188134680","rc":[{"batl":[[0,1.88,2.44]],"ltp":1.45,"tv":43086.52,"id":8681938}]}]}
{"op":"mcm","clk":"4297493571","pt":1632573608021,"mc":[{"id":"1.188134680","rc":[{"batb":[[0,1.3,1351.69],[1,1.29,897.5],[2,1.01,140]],"batl":[[1,2.08,120],[2,2.1,2.55]],"ltp":1.45,"tv":43086.52,"id":8681938}]}]}
{"op":"mcm","clk":"4297493893","pt":1632573609451,"mc":[{"id":"1.188134680","rc":[{"batb":[[0,1.94,105.27],[1,1.7,11.96],[2,1.57,19.57]],"batl":[[0,990,0.01],[1,990,0]],"ltp":3.2,"tv":4360.3,"id":9631939},{"batl":[[0,1.88,2.35]],"ltp":1.45,"tv":43086.52,"id":8681938}]}]}
{"op":"mcm","clk":"4297494357","pt":1632573611366,"mc":[{"id":"1.188134680","rc":[{"batb":[[0,4,4.29],[1,3.9,410.84],[2,3.85,237.98]],"batl":[[0,4.4,5.71],[1,4.7,102.24],[2,990,0.01]],"ltp":3.2,"tv":4360.3,"id":9631939},{"batb":[[2,1.28,747.06]],"batl":[[0,1.31,14.72],[1,1.33,1012.15],[2,1.34,734.87]],"ltp":1.45,"tv":43086.52,"id":8681938}]}]}
{"op":"mcm","clk":"4297494639","pt":1632573612374,"mc":[{"id":"1.188134680","rc":[{"batl":[[1,4.6,1.71],[2,4.7,102.24]],"ltp":3.2,"tv":4360.3,"id":9631939},{"batb":[[0,1.3,1407.85],[2,1.28,860.44]],"ltp":1.45,"tv":43086.52,"id":8681938}]}]}
{"op":"mcm","clk":"4297494696","pt":1632573612694,"mc":[{"id":"1.188134680","rc":[{"batl":[[0,4.3,2],[1,4.4,5.71],[2,4.6,33.33]],"ltp":3.2,"tv":4360.3,"id":9631939},{"trd":[[1.31,1236.49]],"batb":[[0,1.3,1409.85]],"batl":[[0,1.31,11.72]],"ltp":1.31,"tv":43092.52,"id":8681938}],"tv":47452.82}]}
{"op":"mcm","clk":"4297494944","pt":1632573613774,"mc":[{"id":"1.188134680","rc":[{"batl":[[0,4.3,16.75]],"ltp":3.2,"tv":4360.3,"id":9631939}]}]}
{"op":"mcm","clk":"4297495257","pt":1632573615330,"mc":[{"id":"1.188134680","rc":[{"batb":[[0,1.3,1484.58]],"batl":[[0,1.31,88.23]],"ltp":1.31,"tv":43092.52,"id":8681938}]}]}
{"op":"mcm","clk":"4297495535","pt":1632573616194,"mc":[{"id":"1.188134680","rc":[{"batb":[[1,1.29,964.28]],"batl":[[1,1.32,75.17],[2,1.33,1012.15]],"ltp":1.31,"tv":43092.52,"id":8681938}]}]}
{"op":"mcm","clk":"4297496230","pt":1632573619166,"mc":[{"id":"1.188134680","rc":[{"batb":[[0,4,24.29]],"ltp":3.2,"tv":4360.3,"id":9631939}]}]}
{"op":"mcm","clk":"4297496425","pt":1632573619974,"mc":[{"id":"1.188134680","rc":[{"trd":[[4.2,49.09]],"ltp":4.2,"tv":4360.32,"id":9631939},{"trd":[[1.31,1265.87]],"batl":[[0,1.31,73.51]],"ltp":1.31,"tv":43121.9,"id":8681938}],"tv":47482.22}]}
{"op":"mcm","clk":"4297496753","pt":1632573621369,"mc":[{"id":"1.188134680","rc":[{"trd":[[1.31,1275.26]],"batl":[[0,1.31,68.81],[2,1.33,948.71]],"ltp":1.31,"tv":43131.29,"id":8681938}],"tv":47491.62}]}
{"op":"mcm","clk":"4297496778","pt":1632573621485,"mc":[{"id":"1.188134680","rc":[{"trd":[[1.31,1281.06]],"batb":[[1,1.29,897.5]],"batl":[[0,1.31,65.91]],"ltp":1.31,"tv":43137.09,"id":8681938}],"tv":47497.41}]}
{"op":"mcm","clk":"4297497177","pt":1632573623207,"mc":[{"id":"1.188134680","rc":[{"batl":[[1,4.6,31.62],[2,4.7,102.24]],"ltp":4.2,"tv":4360.32,"id":9631939},{"trd":[[1.31,1285.76]],"batl":[[0,1.31,63.56],[1,1.33,669.27],[2,1.34,794.87]],"ltp":1.31,"tv":43141.79,"id":8681938}],"tv":47502.11}]}
{"op":"mcm","clk":"4297497282","pt":1632573623605,"mc":[{"id":"1.188134680","rc":[{"batb":[[0,1.3,1549.65]],"ltp":1.31,"tv":43141.79,"id":8681938}]}]}
{"op":"mcm","clk":"4297497855","pt":1632573626026,"mc":[{"id":"1.188134680","rc":[{"trd":[[4.2,49.4]],"batl":[[0,4.3,21.18]],"ltp":4.2,"tv":4360.63,"id":9631939},{"trd":[[1.31,1286.76]],"batl":[[0,1.31,62.56],[1,1.32,19.86],[2,1.33,669.27]],"ltp":1.31,"tv":43142.79,"id":8681938}],"tv":47503.43}]}
{"op":"mcm","clk":"4297498045","pt":1632573626774,"mc":[{"id":"1.188134680","rc":[{"trd":[[1.31,1301.67]],"batl":[[0,1.31,55.1]],"ltp":1.31,"tv":43157.7,"id":8681938}],"tv":47518.33}]}
{"op":"mcm","clk":"4297498686","pt":1632573629592,"mc":[{"id":"1.188134680","rc":[{"batl":[[0,4.3,16.75]],"ltp":4.2,"tv":4360.63,"id":9631939},{"batl":[[1,1.33,669.27],[2,1.34,794.87]],"ltp":1.31,"tv":43157.7,"id":8681938}]}]}
{"op":"mcm","clk":"4297500180","pt":1632573635829,"mc":[{"id":"1.188134680","rc":[{"batl":[[0,4.3,21.18]],"ltp":4.2,"tv":4360.63,"id":9631939},{"batl":[[1,1.32,19.86],[2,1.33,669.27]],"ltp":1.31,"tv":43157.7,"id":8681938}]}]}
{"op":"mcm","clk":"4297500593","pt":1632573637604,"mc":[{"id":"1.188134680","rc":[{"trd":[[1.31,1301.98]],"batl":[[0,1.31,54.95]],"ltp":1.31,"tv":43158.01,"id":8681938}],"tv":47518.64}]}
{"op":"mcm","clk":"4297500932","pt":1632573639113,"mc":[{"id":"1.188134680","rc":[{"trd":[[4.2,49.56]],"ltp":4.2,"tv":4360.79,"id":9631939},{"trd":[[1.31,1302.47]],"batl":[[0,1.31,54.45]],"ltp":1.31,"tv":43158.5,"id":8681938}],"tv":47519.3}]}
{"op":"mcm","clk":"4297501220","pt":1632573640532,"mc":[{"id":"1.188134680","rc":[{"trd":[[4.2,49.62]],"ltp":4.2,"tv":4360.84,"id":9631939},{"trd":[[1.31,1302.65]],"batl":[[0,1.31,54.27]],"ltp":1.31,"tv":43158.68,"id":8681938}],"tv":47519.53}]}
{"op":"mcm","clk":"4297501631","pt":1632573642359,"mc":[{"id":"1.188134680","rc":[{"trd":[[1.31,1316.66]],"batl":[[0,1.31,47.27]],"ltp":1.31,"tv":43172.69,"id":8681938}],"tv":47533.53}]}
{"op":"mcm","clk":"4297501853","pt":1632573643332,"mc":[{"id":"1.188134680","rc":[{"batb":[[0,1.3,1552]],"ltp":1.31,"tv":43172.69,"id":8681938}]}]}
{"op":"mcm","clk":"4297501863","pt":1632573643432,"mc":[{"id":"1.188134680","rc":[{"trd":[[4.2,49.71]],"ltp":4.2,"tv":4360.94,"id":9631939},{"trd":[[1.31,1316.96]],"batl":[[0,1.31,46.97]],"ltp":1.31,"tv":43172.99,"id":8681938}],"tv":47533.93}]}
{"op":"mcm","clk":"4297502446","pt":1632573645934,"mc":[{"id":"1.188134680","rc":[{"trd":[[1.31,1323.17]],"batl":[[0,1.31,43.86]],"ltp":1.31,"tv":43179.21,"id":8681938}],"tv":47540.15}]}
{"op":"mcm","clk":"4297502723","pt":1632573647135,"mc":[{"id":"1.188134680","rc":[{"trd":[[1.3,3383.94]],"batb":[[0,1.3,1551.39]],"ltp":1.3,"tv":43180.41,"id":8681938}],"tv":47541.35}]}
{"op":"mcm","clk":"4297502882","pt":1632573647870,"mc":[{"id":"1.188134680","rc":[{"batb":[[0,1.3,620.21],[1,1.28,860.44],[2,1.27,725.1]],"batl":[[2,1.33,39.5]],"ltp":1.3,"tv":43180.41,"id":8681938}]}]}
{"op":"mcm","clk":"4297504491","pt":1632573655656,"mc":[{"id":"1.188134680","rc":[{"trd":[[1.31,1329.39]],"batl":[[0,1.31,40.75]],"ltp":1.31,"tv":43186.63,"id":8681938}],"tv":47547.57}]}
{"op":"mcm","clk":"4297505076","pt":1632573658840,"mc":[{"id":"1.188134680","rc":[{"trd":[[1.31,1345.39]],"batl":[[0,1.31,32.75]],"ltp":1.31,"tv":43202.62,"id":8681938}],"tv":47563.56}]}
{"op":"mcm","clk":"4297505206","pt":1632573659532,"mc":[{"id":"1.188134680","rc":[{"trd":[[1.31,1359.48]],"batl":[[0,1.31,25.7]],"ltp":1.31,"tv":43216.71,"id":8681938}],"tv":47577.66}]}
{"op":"mcm","clk":"4297505582","pt":1632573661379,"mc":[{"id":"1.188134680","rc":[{"batb":[[0,4,20],[1,2.52,389.14],[2,2.24,136.13]],"batl":[[0,4.6,31.62],[1,6,108.31],[2,990,0.01]],"ltp":4.2,"tv":4360.94,"id":9631939},{"batb":[[0,1.3,77.08],[1,1.28,113.38],[2,1.21,9.46]],"batl":[[1,1.34,60],[2,1.35,11.96]],"ltp":1.31,"tv":43216.71,"id":8681938}]}]}
{"op":"mcm","clk":"4297505772","pt":1632573662261,"mc":[{"id":"1.188134680","rc":[{"batb":[[0,2.52,389.14],[1,2.24,136.13],[2,2.14,3]],"batl":[[0,6,108.31],[1,990,0.01],[2,990,0]],"ltp":4.2,"tv":4360.94,"id":9631939},{"batb":[[0,1.3,2.35],[1,1.21,9.46],[2,1.2,786.24]],"batl":[[0,1.35,11.96],[1,1.76,458.35],[2,1.78,471.49]],"ltp":1.31,"tv":43216.71,"id":8681938}]}]}
{"op":"mcm","clk":"4297505896","pt":1632573662772,"mc":[{"id":"1.188134680","rc":[{"batb":[[0,2.24,136.13],[1,2.14,3],[2,1.85,16.17]],"batl":[[0,990,0.01],[1,990,0]],"ltp":4.2,"tv":4360.94,"id":9631939}]}]}
{"op":"mcm","clk":"4297506624","pt":1632573666165,"mc":[{"id":"1.188134680","rc":[{"batb":[[2,1.69,19.21]],"batl":[[0,990,0.03]],"ltp":4.2,"tv":4360.94,"id":9631939},{"batb":[[0,1.2,786.24],[1,1.19,1674.19],[2,1.18,1048.79]],"batl":[[1,1.85,1.45],[2,1.87,4]],"ltp":1.31,"tv":43216.71,"id":8681938}]}]}
{"op":"mcm","clk":"4297507243","pt":1632573669165,"mc":[{"id":"1.188134680","rc":[{"trd":[[4.2,49.73]],"batb":[[0,5.9,79.66],[1,5.8,39.84],[2,5.7,39.84]],"batl":[[0,6,2],[1,990,0.01]],"ltp":4.2,"tv":4360.95,"id":9631939},{"trd":[[1.19,75.87],[1.2,2248.73],[1.31,1359.54]],"batb":[[0,1.2,14],[1,1.19,1667.37],[2,1.18,1066.98]],"batl":[[0,1.21,24.79],[1,1.22,1896.76],[2,1.23,1125.21]],"ltp":1.19,"tv":44828.89,"id":8681938}],"tv":49189.85}]}
{"op":"mcm","clk":"4297507475","pt":1632573670282,"mc":[{"id":"1.188134680","rc":[{"batl":[[1,6.4,1.71],[2,6.6,25.35]],"ltp":4.2,"tv":4360.95,"id":9631939},{"batl":[[2,1.23,1185.21]],"ltp":1.19,"tv":44828.89,"id":8681938}]}]}
{"op":"mcm","clk":"4297507676","pt":1632573671269,"mc":[{"id":"1.188134680","rc":[{"batl":[[2,6.8,69.12]],"ltp":4.2,"tv":4360.95,"id":9631939},{"batl":[[2,1.23,1125.21]],"ltp":1.19,"tv":44828.89,"id":8681938}]}]}
{"op":"mcm","clk":"4297507845","pt":1632573672078,"mc":[{"id":"1.188134680","rc":[{"batl":[[1,6.2,3],[2,6.4,1.71]],"ltp":4.2,"tv":4360.95,"id":9631939},{"batb":[[1,1.19,1741.59]],"ltp":1.19,"tv":44828.89,"id":8681938}]}]}
{"op":"mcm","clk":"4297508149","pt":1632573673364,"mc":[{"id":"1.188134680","rc":[{"batb":[[0,1.2,145.12]],"batl":[[0,1.21,100.58],[1,1.22,1964.7]],"ltp":1.19,"tv":44828.89,"id":8681938}]}]}
{"op":"mcm","clk":"4297508276","pt":1632573674052,"mc":[{"id":"1.188134680","rc":[{"trd":[[1.2,2322.61]],"batb":[[0,1.2,108.19],[1,1.19,1806.07]],"ltp":1.2,"tv":44902.77,"id":8681938}],"tv":49263.73}]}
{"op":"mcm","clk":"4297508510","pt":1632573675241,"mc":[{"id":"1.188134680","rc":[{"batb":[[2,1.18,1208.4]],"ltp":1.2,"tv":44902.77,"id":8681938}]}]}
{"op":"mcm","clk":"4297509104","pt":1632573678270,"mc":[{"id":"1.188134680","rc":[{"trd":[[5.9,8.17]],"batb":[[0,5.9,71.49]],"ltp":5.9,"tv":4369.12,"id":9631939},{"trd":[[1.21,650.43]],"batl":[[0,1.22,2024.7],[1,1.23,1125.21],[2,1.24,52.67]],"ltp":1.21,"tv":45143.82,"id":8681938}],"tv":49512.95}]}
{"op":"mcm","clk":"4297509253","pt":1632573678966,"mc":[{"id":"1.188134680","rc":[{"trd":[[5.9,8.49]],"batb":[[0,5.9,71.33]],"ltp":5.9,"tv":4369.44,"id":9631939},{"batb":[[2,1.18,1190.21]],"batl":[[0,1.21,63.08],[1,1.22,1956.76],[2,1.23,1125.21]],"ltp":1.21,"tv":45143.82,"id":8681938}],"tv":49513.26}]}
{"op":"mcm","clk":"4297509476","pt":1632573680195,"mc":[{"id":"1.188134680","rc":[{"batl":[[2,6.6,25.35]],"ltp":5.9,"tv":4369.44,"id":9631939},{"trd":[[1.2,2456.44]],"batb":[[0,1.2,41.27]],"ltp":1.2,"tv":45277.65,"id":8681938}],"tv":49647.09}]}
{"op":"mcm","clk":"4297509693","pt":1632573681302,"mc":[{"id":"1.188134680","rc":[{"trd":[[1.2,2461.14]],"batb":[[0,1.2,38.92]],"ltp":1.2,"tv":45282.34,"id":8681938}],"tv":49651.79}]}
{"op":"mcm","clk":"4297509902","pt":1632573682193,"mc":[{"id":"1.188134680","rc":[{"trd":[[6,5.79]],"batl":[[0,6.2,3],[1,6.6,25.35],[2,6.8,69.12]],"ltp":6.0,"tv":4374.88,"id":9631939},{"trd":[[1.2,2502.69],[1.21,656.78]],"batb":[[0,1.2,14.55]],"batl":[[0,1.21,59.9],[1,1.22,2016.56]],"ltp":1.21,"tv":45330.26,"id":8681938}],"tv":49705.14}]}
{"op":"mcm","clk":"4297510048","pt":1632573682884,"mc":[{"id":"1.188134680","rc":[{"trd":[[5.9,8.52]],"batb":[[0,5.9,71.31]],"ltp":5.9,"tv":4374.92,"id":9631939},{"trd":[[1.21,671.95]],"batl":[[0,1.21,52.31]],"ltp":1.21,"tv":45345.43,"id":8681938}],"tv":49720.35}]}
{"op":"mcm","clk":"4297510360","pt":1632573684192,"mc":[{"id":"1.188134680","rc":[{"trd":[[1.21,672.03]],"batl":[[0,1.21,52.28]],"ltp":1.21,"tv":45345.5,"id":8681938}],"tv":49720.42}]}
{"op":"mcm","clk":"4297510502","pt":1632573684969,"mc":[{"id":"1.188134680","rc":[{"batl":[[0,6,3],[1,6.2,15.43],[2,6.6,25.35]],"ltp":5.9,"tv":4374.92,"id":9631939},{"trd":[[1.2,2507.39]],"batb":[[0,1.2,12.2]],"ltp":1.2,"tv":45350.2,"id":8681938}],"tv":49725.12}]}
{"op":"mcm","clk":"4297510735","pt":1632573686216,"mc":[{"id":"1.188134680","rc":[{"trd":[[5.9,21.55]],"batb":[[0,5.9,64.8]],"batl":[[0,6.2,15.43],[1,6.6,25.35],[2,6.8,69.12]],"ltp":5.9,"tv":4387.94,"id":9631939},{"trd":[[1.21,676.72]],"batl":[[0,1.21,49.93]],"ltp":1.21,"tv":45354.89,"id":8681938}],"tv":49742.84}]}
{"op":"mcm","clk":"4297510791","pt":1632573686535,"mc":[{"id":"1.188134680","rc":[{"trd":[[5.9,21.73]],"batb":[[0,5.9,64.71]],"ltp":5.9,"tv":4388.12,"id":9631939}],"tv":49743.02}]}
{"op":"mcm","clk":"4297511061","pt":1632573687884,"mc":[{"id":"1.188134680","rc":[{"trd":[[5.9,22.07]],"batb":[[0,5.9,64.54]],"ltp":5.9,"tv":4388.46,"id":9631939},{"trd":[[1.21,681.42]],"batl":[[0,1.21,47.58]],"ltp":1.21,"tv":45359.59,"id":8681938}],"tv":49748.06}]}
{"op":"mcm","clk":"4297511255","pt":1632573688603,"mc":[{"id":"1.188134680","rc":[{"batb":[[0,1.2,24.2]],"ltp":1.21,"tv":45359.59,"id":8681938}]}]}
{"op":"mcm","clk":"4297511756","pt":1632573691182,"mc":[{"id":"1.188134680","rc":[{"batb":[[0,5.5,13.33],[1,4.1,2],[2,3.85,166.31]],"batl":[[0,6.2,3],[2,8.6,83.54]],"ltp":5.9,"tv":4388.46,"id":9631939},{"batb":[[1,1.19,77.48],[2,1.18,141.42]],"batl":[[1,1.22,60],[2,1.26,11.52]],"ltp":1.21,"tv":45359.59,"id":8681938}]}]}
{"op":"mcm","clk":"4297511934","pt":1632573692093,"mc":[{"id":"1.188134680","rc":[{"batl":[[0,6.6,25.35],[1,8.6,83.54],[2,990,0.01]],"ltp":5.9,"tv":4388.46,"id":9631939},{"trd":[[1.21,682.98]],"batb":[[0,1.21,3.37],[1,1.18,141.42],[2,1.17,11.2]],"batl":[[0,1.22,60],[1,1.26,11.52],[2,1.32,40.86]],"ltp":1.21,"tv":45361.15,"id":8681938}],"tv":49749.62}]}
{"op":"mcm","clk":"4297512121","pt":1632573693088,"mc":[{"id":"1.188134680","rc":[{"batb":[[0,4.1,2],[1,3.85,166.31],[2,3.75,2]],"batl":[[0,990,0.01],[1,8.6,0],[2,990,0]],"ltp":5.9,"tv":4388.46,"id":9631939},{"batb":[[1,1.17,11.2],[2,1.01,140]],"batl":[[0,1.26,11.52],[1,1.32,40.86],[2,1.36,32.82]],"ltp":1.21,"tv":45361.15,"id":8681938}]}]}
{"op":"mcm","clk":"4297512320","pt":1632573694077,"mc":[{"id":"1.188134680","rc":[{"batb":[[0,4.2,148.89],[1,4.1,2],[2,3.85,166.31]],"ltp":5.9,"tv":4388.46,"id":9631939},{"batl":[[2,1.33,645.4]],"ltp":1.21,"tv":45361.15,"id":8681938}]}]}
{"op":"mcm","clk":"4297512529","pt":1632573695306,"mc":[{"id":"1.188134680","rc":[{"batb":[[2,3.75,2]],"ltp":5.9,"tv":4388.46,"id":9631939},{"batb":[[0,1.21,5.72]],"batl":[[0,1.32,40.86],[1,1.33,645.4],[2,1.34,746.51]],"ltp":1.21,"tv":45361.15,"id":8681938}]}]}
{"op":"mcm","clk":"4297512580","pt":1632573695604,"mc":[{"id":"1.188134680","rc":[{"trd":[[1.21,684.54]],"batb":[[0,1.21,3.37]],"ltp":1.21,"tv":45362.71,"id":8681938}],"tv":49751.18}]}
{"op":"mcm","clk":"4297512868","pt":1632573696898,"mc":[{"id":"1.188134680","rc":[{"batb":[[0,1.21,5.72]],"ltp":1.21,"tv":45362.71,"id":8681938}]}]}
{"op":"mcm","clk":"4297513126","pt":1632573698029,"mc":[{"id":"1.188134680","rc":[{"trd":[[4.1,149.48],[4.2,347.51]],"batb":[[0,3.9,5.89],[1,3.75,2],[2,2.14,3]],"batl":[[0,4.5,104.44],[1,4.6,52.22],[2,4.7,147.83]],"ltp":4.1,"tv":4695.59,"id":9631939},{"trd":[[1.32,876.86]],"batb":[[0,1.3,914.39],[1,1.29,1625.94],[2,1.25,52.25]],"batl":[[0,1.33,645.4],[1,1.34,746.51],[2,1.36,399.4]],"ltp":1.32,"tv":45379.3,"id":8681938}],"tv":50074.9}]}
{"op":"mcm","clk":"4297513416","pt":1632573699346,"mc":[{"id":"1.188134680","rc":[{"batb":[[0,3.95,20.33],[1,3.9,5.89],[2,3.75,2]],"batl":[[0,4.5,106.15],[1,4.6,83.84]],"ltp":4.1,"tv":4695.59,"id":9631939},{"batb":[[2,1.28,523.37]],"batl":[[1,1.34,828.9],[2,1.35,348.14]],"ltp":1.32,"tv":45379.3,"id":8681938}]}]}
{"op":"mcm","clk":"4297513789","pt":1632573701206,"mc":[{"id":"1.188134680","rc":[{"batb":[[0,3.95,33.16]],"batl":[[0,4.3,2],[1,4.4,2],[2,4.5,106.15]],"ltp":4.1,"tv":4695.59,"id":9631939}]}]}
{"op":"mcm","clk":"4297514005","pt":1632573702098,"mc":[{"id":"1.188134680","rc":[{"batb":[[0,1.31,107.95],[1,1.3,914.39],[2,1.29,1625.94]],"batl":[[0,1.32,75.95],[1,1.33,708.99],[2,1.34,828.9]],"ltp":1.32,"tv":45379.3,"id":8681938}]}]}
{"op":"mcm","clk":"4297514214","pt":1632573703017,"mc":[{"id":"1.188134680","rc":[{"batb":[[1,1.3,1042.45]],"ltp":1.32,"tv":45379.3,"id":8681938}]}]}
{"op":"mcm","clk":"4297514473","pt":1632573704326,"mc":[{"id":"1.188134680","rc":[{"batl":[[0,4.3,22.12]],"ltp":4.1,"tv":4695.59,"id":9631939},{"trd":[[1.31,1360.44]],"batb":[[0,1.31,107.5]],"batl":[[1,1.33,781.99]],"ltp":1.31,"tv":45380.21,"id":8681938}],"tv":50075.8}]}
{"op":"mcm","clk":"4297514564","pt":1632573704730,"mc":[{"id":"1.188134680","rc":[{"batl":[[0,4.3,12]],"ltp":4.1,"tv":4695.59,"id":9631939}]}]}
{"op":"mcm","clk":"4297514801","pt":1632573705896,"mc":[{"id":"1.188134680","rc":[{"batl":[[2,4.5,138.22]],"ltp":4.1,"tv":4695.59,"id":9631939}]}]}
{"op":"mcm","clk":"4297515309","pt":1632573708217,"mc":[{"id":"1.188134680","rc":[{"batb":[[1,3.75,2],[2,3.3,129.95]],"ltp":4.1,"tv":4695.59,"id":9631939},{"trd":[[1.31,1362.79],[1.32,877.05]],"batb":[[0,1.31,106.33],[1,1.3,968.02]],"batl":[[0,1.32,75.85],[1,1.33,930.4]],"ltp":1.31,"tv":45382.75,"id":8681938}],"tv":50078.34}]}
{"op":"mcm","clk":"4297515513","pt":1632573709132,"mc":[{"id":"1.188134680","rc":[{"batl":[[2,4.5,136.51]],"ltp":4.1,"tv":4695.59,"id":9631939}]}]}
{"op":"mcm","clk":"4297515650","pt":1632573709725,"mc":[{"id":"1.188134680","rc":[{"trd":[[1.31,1364.78],[1.32,881.75]],"batb":[[0,1.31,105.33]],"batl":[[0,1.32,73.51]],"ltp":1.32,"tv":45389.43,"id":8681938}],"tv":50085.02}]}
{"op":"mcm","clk":"4297515911","pt":1632573710919,"mc":[{"id":"1.188134680","rc":[{"batl":[[0,4.2,6.17],[1,4.3,12],[2,4.4,2]],"ltp":4.1,"tv":4695.59,"id":9631939},{"batl":[[1,1.33,1115.15]],"ltp":1.32,"tv":45389.43,"id":8681938}]}]}
{"op":"mcm","clk":"4297516191","pt":1632573712133,"mc":[{"id":"1.188134680","rc":[{"batl":[[2,4.5,136.51]],"ltp":4.1,"tv":4695.59,"id":9631939},{"trd":[[1.32,965.49]],"batl":[[0,1.32,31.64]],"ltp":1.32,"tv":45473.17,"id":8681938}],"tv":50168.76}]}
{"op":"mcm","clk":"4297516464","pt":1632573713328,"mc":[{"id":"1.188134680","rc":[{"batl":[[0,4.3,12],[1,4.5,32.07],[2,6,108.31]],"ltp":4.1,"tv":4695.59,"id":9631939},{"batb":[[1,1.3,53.63],[2,1.28,636.75]],"batl":[[1,1.33,456],[2,1.34,94.25]],"ltp":1.32,"tv":45473.17,"id":8681938}]}]}
{"op":"mcm","clk":"4297516539","pt":1632573713734,"mc":[{"id":"1.188134680","rc":[{"batb":[[0,3.95,20.33],[1,3.3,129.95],[2,3.25,2]],"batl":[[0,4.5,32.07],[1,6,108.31],[2,990,0.01]],"ltp":4.1,"tv":4695.59,"id":9631939},{"trd":[[1.31,1371.91]],"batb":[[0,1.31,101.77],[1,1.28,113.38],[2,1.26,10.57]],"batl":[[2,1.34,60]],"ltp":1.31,"tv":45480.3,"id":8681938}],"tv":50175.9}]}
{"op":"mcm","clk":"4297516845","pt":1632573715351,"mc":[{"id":"1.188134680","rc":[{"batb":[[0,3.3,129.95],[1,3.25,2],[2,3.05,2.09]],"batl":[[0,990,0.01],[1,6,0],[2,990,0]],"ltp":4.1,"tv":4695.59,"id":9631939},{"batb":[[0,1.26,10.57],[1,1.21,6.89],[2,1.05,3381.53]],"batl":[[0,1.44,30.58],[1,1.48,26.99],[2,1.85,1.45]],"ltp":1.31,"tv":45480.3,"id":8681938}]}]}
{"op":"mcm","clk":"4297517021","pt":1632573716341,"mc":[{"id":"1.188134680","rc":[{"trd":[[1.32,967.05]],"batb":[[0,1.32,1.57],[1,1.26,10.57],[2,1.21,6.89]],"batl":[[1,1.47,456.99],[2,1.48,485.21]],"ltp":1.32,"tv":45481.87,"id":8681938}],"tv":50177.46}]}
{"op":"mcm","clk":"4297517211","pt":1632573717248,"mc":[{"id":"1.188134680","rc":[{"batb":[[0,3.2,137.14],[1,3.05,2.09],[2,2.14,3]],"ltp":4.1,"tv":4695.59,"id":9631939},{"trd":[[1.32,968.63]],"batb":[[0,1.26,10.57],[1,1.21,6.89],[2,1.05,3262.9]],"batl":[[0,1.31,1.57]],"ltp":1.32,"tv":45483.45,"id":8681938}],"tv":50179.04}]}
{"op":"mcm","clk":"4297517828","pt":1632573720342,"mc":[{"id":"1.188134680","rc":[{"trd":[[3.2,5.46]],"batb":[[0,3.2,131.72],[1,3.05,315.61],[2,3,304.3]],"batl":[[0,3.3,1.71],[1,3.4,290.06],[2,3.45,272.98]],"ltp":3.2,"tv":4701.01,"id":9631939},{"trd":[[1.31,1375.05],[1.46,141.85]],"batb":[[0,1.43,2056.44],[1,1.42,556.45],[2,1.39,46.98]],"batl":[[0,1.47,456.99],[1,1.48,485.21],[2,1.5,5.26]],"ltp":1.46,"tv":45498.47,"id":8681938}],"tv":50199.48}]}
{"op":"mcm","clk":"4297518015","pt":1632573721353,"mc":[{"id":"1.188134680","rc":[{"batb":[[1,3.05,344.87]],"ltp":3.2,"tv":4701.01,"id":9631939},{"batb":[[2,1.41,330.85]],"batl":[[0,1.46,21],[1,1.47,456.99],[2,1.48,545.21]],"ltp":1.46,"tv":45498.47,"id":8681938}]}]}
{"op":"mcm","clk":"4297518110","pt":1632573721759,"mc":[{"id":"1.188134680","rc":[{"batb":[[1,3.05,315.61]],"ltp":3.2,"tv":4701.01,"id":9631939}]}]}
{"op":"mcm","clk":"4297518388","pt":1632573723060,"mc":[{"id":"1.188134680","rc":[{"batl":[[0,3.3,4.71],[1,3.35,3],[2,3.4,290.06]],"ltp":3.2,"tv":4701.01,"id":9631939},{"batb":[[0,1.44,43.48],[1,1.43,2060.44],[2,1.42,556.45]],"ltp":1.46,"tv":45498.47,"id":8681938}]}]}
{"op":"mcm","clk":"4297518674","pt":1632573724354,"mc":[{"id":"1.188134680","rc":[{"batb":[[0,1.44,110.46],[1,1.43,2187.99]],"batl":[[0,1.45,57.98],[1,1.46,21],[2,1.47,514.22]],"ltp":1.46,"tv":45498.47,"id":8681938}]}]}
{"op":"mcm","clk":"4297518836","pt":1632573725143,"mc":[{"id":"1.188134680","rc":[{"batb":[[1,3.05,344.87]],"ltp":3.2,"tv":4701.01,"id":9631939},{"batb":[[1,1.43,2117.7]],"ltp":1.46,"tv":45498.47,"id":8681938}]}]}
{"op":"mcm","clk":"4297519019","pt":1632573726268,"mc":[{"id":"1.188134680","rc":[{"trd":[[3.2,32.05]],"batb":[[0,3.2,118.42]],"batl":[[0,3.3,30.9]],"ltp":3.2,"tv":4727.6,"id":9631939}],"tv":50226.07}]}
{"op":"mcm","clk":"4297519252","pt":1632573727563,"mc":[{"id":"1.188134680","rc":[{"trd":[[1.44,27.74]],"batb":[[0,1.44,110.23]],"ltp":1.44,"tv":45498.93,"id":8681938}],"tv":50226.54}]}
{"op":"mcm","clk":"4297520031","pt":1632573731181,"mc":[{"id":"1.188134680","rc":[{"batl":[[0,3.3,29.19]],"ltp":3.2,"tv":4727.6,"id":9631939},{"trd":[[1.44,30.64]],"batb":[[0,1.44,108.78]],"ltp":1.44,"tv":45501.83,"id":8681938}],"tv":50229.44}]}
{"op":"mcm","clk":"4297520261","pt":1632573732367,"mc":[{"id":"1.188134680","rc":[{"trd":[[1.45,61.11]],"batb":[[0,1.45,6.2],[1,1.44,105.48],[2,1.43,810.44]],"batl":[[0,1.46,86.07],[1,1.47,456.99],[2,1.48,545.21]],"ltp":1.45,"tv":45506.53,"id":8681938}],"tv":50234.13}]}
{"op":"mcm","clk":"4297520417","pt":1632573733060,"mc":[{"id":"1.188134680","rc":[{"batb":[[2,3,309.82]],"ltp":3.2,"tv":4727.6,"id":9631939},{"trd":[[1.45,65.81],[1.46,165.51]],"batb":[[0,1.45,3.85]],"batl":[[0,1.46,74.24]],"ltp":1.45,"tv":45534.89,"id":8681938}],"tv":50262.49}]}
{"op":"mcm","clk":"4297520833","pt":1632573735291,"mc":[{"id":"1.188134680","rc":[{"batl":[[1,3.4,290.06],[2,3.45,311.31]],"ltp":3.2,"tv":4727.6,"id":9631939},{"trd":[[1.45,71.64]],"batb":[[0,1.45,7.98],[2,1.43,806.44]],"ltp":1.45,"tv":45540.72,"id":8681938}],"tv":50268.32}]}
{"op":"mcm","clk":"4297521025","pt":1632573736264,"mc":[{"id":"1.188134680","rc":[{"trd":[[1.45,76.2]],"batb":[[0,1.45,5.7]],"ltp":1.45,"tv":45545.28,"id":8681938}],"tv":50272.88}]}
{"op":"mcm","clk":"4297521201","pt":1632573737275,"mc":[{"id":"1.188134680","rc":[{"batb":[[0,1.45,6.48]],"ltp":1.45,"tv":45545.28,"id":8681938}]}]}
{"op":"mcm","clk":"4297521385","pt":1632573738288,"mc":[{"id":"1.188134680","rc":[{"trd":[[1.45,77.76]],"batb":[[0,1.45,6.09]],"ltp":1.45,"tv":45546.84,"id":8681938}],"tv":50274.44}]}
{"op":"mcm","clk":"4297521490","pt":1632573738800,"mc":[{"id":"1.188134680","rc":[{"trd":[[3.2,35.65]],"batb":[[0,3.2,116.62]],"ltp":3.2,"tv":4731.2,"id":9631939}],"tv":50278.04}]}
{"op":"mcm","clk":"4297521702","pt":1632573740007,"mc":[{"id":"1.188134680","rc":[{"batb":[[0,1.45,2.96]],"ltp":1.45,"tv":45546.84,"id":8681938}]}]}
{"op":"mcm","clk":"4297522181","pt":1632573742307,"mc":[{"id":"1.188134680","rc":[{"trd":[[1.46,191.22]],"batl":[[0,1.46,61.39]],"ltp":1.46,"tv":45572.55,"id":8681938}],"tv":50303.76}]}
{"op":"mcm","clk":"4297522387","pt":1632573743376,"mc":[{"id":"1.188134680","rc":[{"batb":[[2,3,304.3]],"ltp":3.2,"tv":4731.2,"id":9631939},{"trd":[[1.45,78.03]],"batb":[[0,1.44,105.96],[1,1.43,806.44],[2,1.42,556.45]],"ltp":1.45,"tv":45572.82,"id":8681938}],"tv":50304.02}]}
{"op":"mcm","clk":"4297522900","pt":1632573745912,"mc":[{"id":"1.188134680","rc":[{"trd":[[1.46,215.56]],"batl":[[0,1.46,49.22],[2,1.48,556.88]],"ltp":1.46,"tv":45597.16,"id":8681938}],"tv":50328.36}]}
{"op":"mcm","clk":"4297523372","pt":1632573748306,"mc":[{"id":"1.188134680","rc":[{"batb":[[1,3.05,29.26],[2,2.12,396.48]],"batl":[[0,3.45,38.33],[1,4.2,151.01],[2,4.3,2]],"ltp":3.2,"tv":4731.2,"id":9631939},{"batb":[[0,1.41,425.03],[1,1.4,12.26],[2,1.31,39.79]],"batl":[[0,1.48,60],[1,1.49,10.27],[2,1.8,2.35]],"ltp":1.46,"tv":45597.16,"id":8681938}]}]}
{"op":"mcm","clk":"4297523599","pt":1632573749378,"mc":[{"id":"1.188134680","rc":[{"batb":[[0,2.12,396.48],[1,1.98,201.65],[2,1.7,16.22]],"batl":[[0,4.2,151.01],[1,4.3,2],[2,4.9,2]],"ltp":3.2,"tv":4731.2,"id":9631939},{"trd":[[1.45,78.81]],"batb":[[0,1.4,12.26],[1,1.31,39.79],[2,1.29,504.68]],"batl":[[0,1.45,6.38]],"ltp":1.45,"tv":45597.94,"id":8681938}],"tv":50329.14}]}
{"op":"mcm","clk":"4297523732","pt":1632573750002,"mc":[{"id":"1.188134680","rc":[{"batb":[[0,1.98,201.65],[1,1.7,16.22],[2,1.58,20.56]],"batl":[[0,4.9,2],[1,990,0.01],[2,4.9,0]],"ltp":3.2,"tv":4731.2,"id":9631939},{"batb":[[1,1.29,504.68],[2,1.26,50.48]],"ltp":1.45,"tv":45597.94,"id":8681938}]}]}
{"op":"mcm","clk":"4297524001","pt":1632573751283,"mc":[{"id":"1.188134680","rc":[{"batl":[[1,1.8,2.35],[2,1.85,1.45]],"ltp":1.45,"tv":45597.94,"id":8681938}]}]}
{"op":"mcm","clk":"4297524428","pt":1632573753292,"mc":[{"id":"1.188134680","rc":[{"trd":[[3.2,38.18]],"batl":[[0,3.1,344.99],[1,4.9,2],[2,990,0.01]],"ltp":3.2,"tv":4733.73,"id":9631939},{"trd":[[1.45,85.97]],"batl":[[0,1.8,2.35],[1,1.85,1.45],[2,1.88,2.35]],"ltp":1.45,"tv":45605.1,"id":8681938}],"tv":50338.83}]}
{"op":"mcm","clk":"4297524551","pt":1632573753929,"mc":[{"id":"1.188134680","rc":[{"batl":[[0,4.3,2]],"ltp":3.2,"tv":4733.73,"id":9631939},{"batb":[[0,1.51,657.48],[1,1.5,439.34],[2,1.47,210.07]],"batl":[[0,1.56,620.32],[1,1.57,362.89],[2,1.8,2.35]],"ltp":1.45,"tv":45605.1,"id":8681938}]}]}
{"op":"mcm","clk":"4297525032","pt":1632573756209,"mc":[{"id":"1.188134680","rc":[{"batb":[[0,2.44,95.7],[1,2.04,402.03],[2,1.98,201.65]],"batl":[[0,3.3,10],[1,3.9,161.43],[2,4.3,2]],"ltp":3.2,"tv":4733.73,"id":9631939}]}]}
{"op":"mcm","clk":"4297525134","pt":1632573756697,"mc":[{"id":"1.188134680","rc":[{"batl":[[0,3.9,161.43],[1,4.3,2],[2,4.9,2]],"ltp":3.2,"tv":4733.73,"id":9631939},{"batl":[[2,1.7,11.75]],"ltp":1.45,"tv":45605.1,"id":8681938}]}]}
{"op":"mcm","clk":"4297525360","pt":1632573757808,"mc":[{"id":"1.188134680","rc":[{"batb":[[0,2.04,402.03],[1,1.98,201.65],[2,1.7,16.22]],"ltp":3.2,"tv":4733.73,"id":9631939},{"batb":[[0,1.4,12.26],[1,1.31,37.79],[2,1.29,504.68]],"batl":[[0,1.8,2.35],[1,1.85,1.45],[2,1.88,2.35]],"ltp":1.45,"tv":45605.1,"id":8681938}]}]}
{"op":"mcm","clk":"4297525696","pt":1632573759299,"mc":[{"id":"1.188134680","rc":[{"batb":[[0,1.52,61.3],[1,1.4,12.26],[2,1.31,37.79]],"ltp":1.45,"tv":45605.1,"id":8681938}]}]}
{"op":"mcm","clk":"4297525862","pt":1632573760122,"mc":[{"id":"1.188134680","rc":[{"trd":[[3.15,162.32]],"ltp":3.15,"tv":4733.94,"id":9631939},{"trd":[[1.46,216.01]],"batb":[[0,1.4,12.26],[1,1.31,37.79],[2,1.29,504.68]],"ltp":1.46,"tv":45605.55,"id":8681938}],"tv":50339.49}]}
{"op":"mcm","clk":"4297525997","pt":1632573760707,"mc":[{"id":"1.188134680","rc":[{"batb":[[2,1.3,958.09]],"ltp":1.46,"tv":45605.55,"id":8681938}]}]}
{"op":"mcm","clk":"4297526603","pt":1632573763651,"mc":[{"id":"1.188134680","rc":[{"batl":[[0,1.85,1.45],[1,1.88,2.35],[2,2.02,269.69]],"ltp":1.46,"tv":45605.55,"id":8681938}]}]}
{"op":"mcm","clk":"4297528537","pt":1632573773368,"mc":[{"id":"1.188134680","rc":[{"batb":[[2,1.29,504.68]],"ltp":1.46,"tv":45605.55,"id":8681938}]}]}
{"op":"mcm","clk":"4297528701","pt":1632573774087,"mc":[{"id":"1.188134680","rc":[{"batb":[[0,3.25,2.35],[1,2.04,402.03],[2,1.98,201.65]],"batl":[[1,4.9,2],[2,990,0.01]],"ltp":3.15,"tv":4733.94,"id":9631939},{"batb":[[1,1.29,504.68],[2,1.26,50.48]],"ltp":1.46,"tv":45605.55,"id":8681938}]}]}
{"op":"mcm","clk":"4297529200","pt":1632573776346,"mc":[{"id":"1.188134680","rc":[{"trd":[[2.16,112.58],[3.25,32.54]],"batb":[[0,2,3.82],[1,1.98,201.65],[2,1.93,1981.86]],"batl":[[0,2.04,8.33],[1,2.16,200.21],[2,2.22,13.51]],"ltp":2.16,"tv":4739.88,"id":9631939},{"trd":[[1.85,108.12],[1.88,345.78]],"batb":[[0,1.95,340.72],[1,1.93,357.28],[2,1.92,1245.11]],"batl":[[0,2,3.82],[1,2.02,269.69],[2,2.04,309.33]],"ltp":1.88,"tv":45611.7,"id":8681938}],"tv":50351.58}]}
{"op":"mcm","clk":"4297529373","pt":1632573777148,"mc":[{"id":"1.188134680","rc":[{"trd":[[2.04,95.74]],"batb":[[2,1.95,33.49]],"batl":[[0,2.04,7.78]],"ltp":2.04,"tv":4742.14,"id":9631939},{"trd":[[1.96,362.29]],"batb":[[1,1.94,104.76],[2,1.93,357.28]],"batl":[[0,1.97,15.23],[1,2,3.82],[2,2.02,269.69]],"ltp":1.96,"tv":45614.04,"id":8681938}],"tv":50356.19}]}
{"op":"mcm","clk":"4297529778","pt":1632573779343,"mc":[{"id":"1.188134680","rc":[{"batl":[[1,2.08,4],[2,2.12,67.17]],"ltp":2.04,"tv":4742.14,"id":9631939},{"batb":[[2,1.93,411.78]],"ltp":1.96,"tv":45614.04,"id":8681938}]}]}
{"op":"mcm","clk":"4297529882","pt":1632573779860,"mc":[{"id":"1.188134680","rc":[{"trd":[[2.04,111.31]],"batl":[[0,2.08,4],[1,2.12,2],[2,2.16,255.91]],"ltp":2.04,"tv":4757.7,"id":9631939},{"trd":[[1.97,8]],"batb":[[0,1.96,5],[1,1.95,340.72],[2,1.94,104.76]],"batl":[[0,1.97,11.23]],"ltp":1.97,"tv":45622.04,"id":8681938}],"tv":50379.75}]}
{"op":"mcm","clk":"4297530354","pt":1632573782055,"mc":[{"id":"1.188134680","rc":[{"batl":[[2,2.16,200.21]],"ltp":2.04,"tv":4757.7,"id":9631939}]}]}
{"op":"mcm","clk":"4297530610","pt":1632573783286,"mc":[{"id":"1.188134680","rc":[{"batb":[[2,1.97,60.92]],"batl":[[0,2.04,3],[1,2.08,4],[2,2.12,2]],"ltp":2.04,"tv":4757.7,"id":9631939}]}]}
{"op":"mcm","clk":"4297531222","pt":1632573786239,"mc":[{"id":"1.188134680","rc":[{"batl":[[1,2.06,65.17],[2,2.08,4]],"ltp":2.04,"tv":4757.7,"id":9631939},{"trd":[[1.96,365.19],[1.97,30.46]],"batb":[[0,1.97,39.27],[1,1.96,3.55],[2,1.95,340.72]],"batl":[[0,2,3.82],[1,2.02,269.69],[2,2.04,368.16]],"ltp":1.97,"tv":45647.4,"id":8681938}],"tv":50405.11}]}
{"op":"mcm","clk":"4297531431","pt":1632573787281,"mc":[{"id":"1.188134680","rc":[{"batb":[[0,1.98,201.65],[1,1.97,60.92],[2,1.95,33.49]],"batl":[[1,2.08,4],[2,2.12,2.09]],"ltp":2.04,"tv":4757.7,"id":9631939},{"trd":[[1.97,40.38]],"batb":[[0,1.96,3.55],[1,1.95,340.72],[2,1.94,104.76]],"batl":[[0,2.02,269.69],[1,2.04,368.16],[2,2.2,220.91]],"ltp":1.97,"tv":45657.33,"id":8681938}],"tv":50415.03}]}
{"op":"mcm","clk":"4297531678","pt":1632573788306,"mc":[{"id":"1.188134680","rc":[{"trd":[[2.04,117.31],[2.06,40.62]],"batl":[[0,2.08,4],[1,2.12,2.09],[2,2.14,56.19]],"ltp":2.06,"tv":4764.22,"id":9631939},{"trd":[[1.96,371.75]],"batb":[[0,1.95,340.72],[1,1.94,104.76],[2,1.93,3402.67]],"batl":[[0,1.96,2.56],[1,2.02,269.69],[2,2.04,368.16]],"ltp":1.96,"tv":45663.88,"id":8681938}],"tv":50428.11}]}
{"op":"mcm","clk":"4297532114","pt":1632573790221,"mc":[{"id":"1.188134680","rc":[{"trd":[[2.04,119.77]],"batl":[[0,2.06,7.62],[1,2.08,4],[2,2.12,2.09]],"ltp":2.04,"tv":4766.68,"id":9631939},{"trd":[[1.96,374.3]],"batl":[[0,1.98,7.9]],"ltp":1.96,"tv":45666.43,"id":8681938}],"tv":50433.12}]}
{"op":"mcm","clk":"4297532380","pt":1632573791324,"mc":[{"id":"1.188134680","rc":[{"batl":[[0,2.08,4],[1,2.14,56.28],[2,2.16,200.21]],"ltp":2.04,"tv":4766.68,"id":9631939},{"trd":[[1.95,50.12]],"batb":[[0,1.95,333.43]],"batl":[[0,1.96,292.47]],"ltp":1.95,"tv":45691.01,"id":8681938}],"tv":50457.7}]}
{"op":"mcm","clk":"4297532504","pt":1632573791831,"mc":[{"id":"1.188134680","rc":[{"batb":[[0,2.04,2.35],[1,1.98,201.65],[2,1.97,60.92]],"ltp":2.04,"tv":4766.68,"id":9631939},{"trd":[[1.96,445.62]],"batl":[[0,1.96,256.81],[2,2.04,309.33]],"ltp":1.96,"tv":45762.33,"id":8681938}],"tv":50529.02}]}
{"op":"mcm","clk":"4297532834","pt":1632573793191,"mc":[{"id":"1.188134680","rc":[{"batl":[[0,2.06,62.71],[1,2.08,4],[2,2.14,56.28]],"ltp":2.04,"tv":4766.68,"id":9631939},{"batl":[[0,1.96,260.33]],"ltp":1.96,"tv":45762.33,"id":8681938}]}]}
{"op":"mcm","clk":"4297533009","pt":1632573794009,"mc":[{"id":"1.188134680","rc":[{"trd":[[2.04,123.91]],"batb":[[0,1.98,201.93],[1,1.97,60.92],[2,1.95,33.49]],"batl":[[0,2.06,10.62]],"ltp":2.04,"tv":4770.83,"id":9631939},{"trd":[[1.96,453.62]],"batl":[[0,1.96,271.02],[1,1.98,7.9],[2,2.02,269.69]],"ltp":1.96,"tv":45770.33,"id":8681938}],"tv":50541.16}]}
{"op":"mcm","clk":"4297533280","pt":1632573795198,"mc":[{"id":"1.188134680","rc":[{"batb":[[0,2.04,2.63],[1,1.98,201.65],[2,1.97,60.92]],"ltp":2.04,"tv":4770.83,"id":9631939},{"trd":[[1.95,54.82],[1.96,765.38]],"batb":[[0,1.95,331.08]],"batl":[[0,1.96,122.98],[1,1.97,2.35],[2,1.98,7.9]],"ltp":1.95,"tv":46086.79,"id":8681938}],"tv":50857.62}]}
{"op":"mcm","clk":"4297533484","pt":1632573796208,"mc":[{"id":"1.188134680","rc":[{"batl":[[0,1.96,119.46]],"ltp":1.95,"tv":46086.79,"id":8681938}]}]}
{"op":"mcm","clk":"4297533683","pt":1632573797158,"mc":[{"id":"1.188134680","rc":[{"trd":[[2.04,156.09]],"batb":[[0,1.98,201.65],[1,1.97,60.92],[2,1.95,33.49]],"ltp":2.04,"tv":4803.01,"id":9631939},{"trd":[[1.96,793.41]],"batl":[[0,1.96,91.43]],"ltp":1.96,"tv":46114.82,"id":8681938}],"tv":50917.84}]}
{"op":"mcm","clk":"4297533906","pt":1632573798232,"mc":[{"id":"1.188134680","rc":[{"trd":[[1.95,65.1]],"batb":[[0,1.95,325.94]],"batl":[[0,1.96,81.87]],"ltp":1.95,"tv":46125.1,"id":8681938}],"tv":50928.12}]}
{"op":"mcm","clk":"4297534025","pt":1632573798797,"mc":[{"id":"1.188134680","rc":[{"trd":[[1.95,74.96]],"batb":[[0,1.95,321.01]],"ltp":1.95,"tv":46134.96,"id":8681938}],"tv":50937.98}]}
{"op":"mcm","clk":"4297534327","pt":1632573800055,"mc":[{"id":"1.188134680","rc":[{"batb":[[0,2.04,2.35],[1,1.98,201.65],[2,1.97,60.92]],"ltp":2.04,"tv":4803.01,"id":9631939},{"batl":[[0,1.96,69.54],[1,1.98,7.9],[2,2.02,269.69]],"ltp":1.95,"tv":46134.96,"id":8681938}]}]}
{"op":"mcm","clk":"4297534581","pt":1632573801216,"mc":[{"id":"1.188134680","rc":[{"trd":[[1.96,815.89]],"batl":[[0,1.98,7.9],[1,2.02,269.69],[2,2.04,368.16]],"ltp":1.96,"tv":46157.45,"id":8681938}],"tv":50960.46}]}
{"op":"mcm","clk":"4297534664","pt":1632573801633,"mc":[{"id":"1.188134680","rc":[{"trd":[[1.95,92.78]],"batb":[[0,1.95,312.1]],"ltp":1.95,"tv":46175.27,"id":8681938}],"tv":50978.28}]}
{"op":"mcm","clk":"4297535222","pt":1632573804333,"mc":[{"id":"1.188134680","rc":[{"trd":[[2.06,70.03]],"batb":[[0,1.98,201.65],[1,1.97,60.92],[2,1.95,33.49]],"batl":[[0,2.08,4],[1,2.14,56.28],[2,2.16,200.21]],"ltp":2.06,"tv":4832.42,"id":9631939},{"trd":[[1.95,101.41]],"batb":[[0,1.97,3],[1,1.95,303.47],[2,1.94,104.76]],"ltp":1.95,"tv":46183.9,"id":8681938}],"tv":51016.32}]}
{"op":"mcm","clk":"4297535312","pt":1632573804762,"mc":[{"id":"1.188134680","rc":[{"trd":[[2.06,70.12]],"ltp":2.06,"tv":4832.51,"id":9631939},{"trd":[[1.95,101.51]],"batb":[[0,1.95,303.37],[1,1.94,104.76],[2,1.93,3398.67]],"ltp":1.95,"tv":46184.0,"id":8681938}],"tv":51016.51}]}
{"op":"mcm","clk":"4297535464","pt":1632573805410,"mc":[{"id":"1.188134680","rc":[{"trd":[[1.95,110.53]],"batb":[[0,1.95,298.86]],"batl":[[0,1.96,2.35],[1,1.98,7.9],[2,2.02,269.69]],"ltp":1.95,"tv":46193.02,"id":8681938}],"tv":51025.53}]}
{"op":"mcm","clk":"4297535835","pt":1632573807216,"mc":[{"id":"1.188134680","rc":[{"trd":[[1.95,143]],"batb":[[0,1.95,282.63]],"batl":[[2,2.02,296.14]],"ltp":1.95,"tv":46225.48,"id":8681938}],"tv":51058.0}]}
{"op":"mcm","clk":"4297536044","pt":1632573808136,"mc":[{"id":"1.188134680","rc":[{"trd":[[1.96,820.61]],"batb":[[0,1.96,2.64],[1,1.95,282.63],[2,1.94,104.76]],"batl":[[0,1.98,7.9],[1,2.02,296.14],[2,2.04,368.16]],"ltp":1.96,"tv":46230.2,"id":8681938}],"tv":51062.72}]}
{"op":"mcm","clk":"4297536169","pt":1632573808757,"mc":[{"id":"1.188134680","rc":[{"trd":[[1.95,146.17],[1.96,825.89]],"batb":[[0,1.95,281.04],[1,1.94,104.76],[2,1.93,3398.67]],"ltp":1.95,"tv":46238.66,"id":8681938}],"tv":51071.18}]}
{"op":"mcm","clk":"4297536695","pt":1632573811333,"mc":[{"id":"1.188134680","rc":[{"batl":[[0,2.04,4],[1,2.08,4],[2,2.14,56.28]],"ltp":2.06,"tv":4832.51,"id":9631939}]}]}
{"op":"mcm","clk":"4297536869","pt":1632573812159,"mc":[{"id":"1.188134680","rc":[{"trd":[[1.96,849.37]],"ltp":1.96,"tv":46262.14,"id":8681938}],"tv":51094.66}]}
{"op":"mcm","clk":"4297537137","pt":1632573813262,"mc":[{"id":"1.188134680","rc":[{"trd":[[2.04,160.09]],"batl":[[0,2.08,4],[1,2.14,56.28],[2,2.16,200.21]],"ltp":2.04,"tv":4836.51,"id":9631939},{"trd":[[1.95,149.69],[1.96,853.53]],"batb":[[0,1.95,279.28]],"ltp":1.95,"tv":46269.82,"id":8681938}],"tv":51106.34}]}
{"op":"mcm","clk":"4297537276","pt":1632573813871,"mc":[{"id":"1.188134680","rc":[{"trd":[[1.95,154.39]],"batb":[[0,1.95,276.93]],"batl":[[0,2.02,296.14],[1,2.04,368.16],[2,2.2,220.91]],"ltp":1.95,"tv":46274.51,"id":8681938}],"tv":51111.03}]}
{"op":"mcm","clk":"4297537576","pt":1632573815244,"mc":[{"id":"1.188134680","rc":[{"trd":[[1.95,165.29]],"batb":[[0,1.95,271.48]],"ltp":1.95,"tv":46285.41,"id":8681938}],"tv":51121.93}]}
{"op":"mcm","clk":"4297537800","pt":1632573816332,"mc":[{"id":"1.188134680","rc":[{"trd":[[1.95,169.99]],"batb":[[0,1.95,299.15]],"ltp":1.95,"tv":46290.11,"id":8681938}],"tv":51126.63}]}
{"op":"mcm","clk":"4297538021","pt":1632573817378,"mc":[{"id":"1.188134680","rc":[{"batl":[[0,2.06,20],[1,2.08,11.4],[2,2.14,56.28]],"ltp":2.04,"tv":4836.51,"id":9631939},{"trd":[[1.95,174.74]],"batb":[[0,1.95,296.77]],"batl":[[0,1.96,7.33],[1,2.02,296.14],[2,2.04,368.16]],"ltp":1.95,"tv":46294.87,"id":8681938}],"tv":51131.39}]}
{"op":"mcm","clk":"4297538117","pt":1632573817853,"mc":[{"id":"1.188134680","rc":[{"batb":[[0,1.98,201.15]],"ltp":2.04,"tv":4836.51,"id":9631939},{"trd":[[1.95,175.87]],"batb":[[0,1.95,296.21]],"ltp":1.95,"tv":46295.99,"id":8681938}],"tv":51132.51}]}
{"op":"mcm","clk":"4297538525","pt":1632573819942,"mc":[{"id":"1.188134680","rc":[{"trd":[[1.95,186.49],[1.96,867.79]],"batb":[[0,1.95,290.9]],"batl":[[0,2.02,296.34],[1,2.04,368.16],[2,2.2,220.91]],"ltp":1.96,"tv":46320.88,"id":8681938}],"tv":51157.4}]}
{"op":"mcm","clk":"4297538807","pt":1632573821358,"mc":[{"id":"1.188134680","rc":[{"trd":[[1.95,191.75]],"batb":[[0,1.95,314.45]],"ltp":1.95,"tv":46326.13,"id":8681938}],"tv":51162.65}]}
{"op":"mcm","clk":"4297538972","pt":1632573822157,"mc":[{"id":"1.188134680","rc":[{"trd":[[1.95,553.17]],"batb":[[0,1.95,133.74]],"ltp":1.95,"tv":46687.55,"id":8681938}],"tv":51524.07}]}
{"op":"mcm","clk":"4297539096","pt":1632573822757,"mc":[{"id":"1.188134680","rc":[{"trd":[[1.95,557.87],[1.96,868.19]],"batb":[[0,1.96,3.8],[1,1.95,35.02],[2,1.94,104.76]],"batl":[[0,2.02,323.61]],"ltp":1.96,"tv":46692.65,"id":8681938}],"tv":51529.17}]}
{"op":"mcm","clk":"4297539388","pt":1632573824269,"mc":[{"id":"1.188134680","rc":[{"trd":[[1.98,686.53],[2.02,25.57]],"batb":[[0,1.98,170.67]],"ltp":2.02,"tv":4899.82,"id":9631939},{"trd":[[1.99,498.58]],"batb":[[0,1.99,3.01],[1,1.98,10.83],[2,1.97,16.33]],"ltp":1.99,"tv":46695.03,"id":8681938}],"tv":51594.86}]}
{"op":"mcm","clk":"4297539604","pt":1632573825276,"mc":[{"id":"1.188134680","rc":[{"batl":[[0,2.02,441.62]],"ltp":1.99,"tv":46695.03,"id":8681938}]}]}
{"op":"mcm","clk":"4297539729","pt":1632573825852,"mc":[{"id":"1.188134680","rc":[{"batl":[[0,2.04,5],[1,2.06,20],[2,2.08,11.4]],"ltp":2.02,"tv":4899.82,"id":9631939},{"trd":[[1.98,25.09],[1.99,504.6]],"batb":[[0,1.98,10.11],[1,1.97,20.33],[2,1.96,3.8]],"ltp":1.98,"tv":46702.47,"id":8681938}],"tv":51602.3}]}
{"op":"mcm","clk":"4297539983","pt":1632573827157,"mc":[{"id":"1.188134680","rc":[{"trd":[[1.98,1001.67]],"batb":[[0,1.98,13.1]],"ltp":1.98,"tv":5214.96,"id":9631939}],"tv":51917.44}]}
{"op":"mcm","clk":"4297540318","pt":1632573828962,"mc":[{"id":"1.188134680","rc":[{"trd":[[1.98,41.43]],"batb":[[0,1.98,1.95]],"ltp":1.98,"tv":46718.81,"id":8681938}],"tv":51933.78}]}
{"op":"mcm","clk":"4297540607","pt":1632573830372,"mc":[{"id":"1.188134680","rc":[{"batl":[[2,2.08,4]],"ltp":1.98,"tv":5214.96,"id":9631939},{"trd":[[1.98,43.7]],"batb":[[0,1.97,21.14],[1,1.96,3.8],[2,1.95,35.02]],"ltp":1.98,"tv":46721.08,"id":8681938}],"tv":51936.05}]}
{"op":"mcm","clk":"4297540697","pt":1632573830792,"mc":[{"id":"1.188134680","rc":[{"trd":[[1.98,43.99]],"batb":[[0,1.97,21]],"ltp":1.98,"tv":46721.37,"id":8681938}],"tv":51936.34}]}
{"op":"mcm","clk":"4297541216","pt":1632573833182,"mc":[{"id":"1.188134680","rc":[{"batl":[[1,2.06,26.97]],"ltp":1.98,"tv":5214.96,"id":9631939},{"trd":[[1.98,45.33]],"batb":[[0,1.97,20.33]],"batl":[[0,1.98,7.9],[1,2.02,441.62],[2,2.04,368.16]],"ltp":1.98,"tv":46722.71,"id":8681938}],"tv":51937.68}]}
{"op":"mcm","clk":"4297541264","pt":1632573833384,"mc":[{"id":"1.188134680","rc":[{"batl":[[1,2.06,20]],"ltp":1.98,"tv":5214.96,"id":9631939},{"batl":[[0,2.02,441.62],[1,2.04,368.16],[2,2.2,220.91]],"ltp":1.98,"tv":46722.71,"id":8681938}]}]}
{"op":"mcm","clk":"4297541909","pt":1632573836292,"mc":[{"id":"1.188134680","rc":[{"batb":[[0,1.97,163.56],[1,1.95,33.49],[2,1.93,495.46]],"batl":[[1,2.06,26.97]],"ltp":1.98,"tv":5214.96,"id":9631939},{"trd":[[1.97,42.34]],"batb":[[0,1.97,19.35],[1,1.96,103.49],[2,1.95,30.02]],"batl":[[0,1.98,8.57],[1,2.02,441.62],[2,2.04,368.16]],"ltp":1.97,"tv":46724.66,"id":8681938}],"tv":51939.63}]}
{"op":"mcm","clk":"4297542147","pt":1632573837371,"mc":[{"id":"1.188134680","rc":[{"batl":[[2,2.14,56.28]],"ltp":1.98,"tv":5214.96,"id":9631939},{"batl":[[0,1.98,10.92]],"ltp":1.97,"tv":46724.66,"id":8681938}]}]}
{"op":"mcm","clk":"4297542305","pt":1632573838176,"mc":[{"id":"1.188134680","rc":[{"batl":[[0,1.98,11.04]],"ltp":1.97,"tv":46724.66,"id":8681938}]}]}
{"op":"mcm","clk":"4297542563","pt":1632573839367,"mc":[{"id":"1.188134680","rc":[{"trd":[[2.04,164.79]],"batl":[[0,2.04,2.65]],"ltp":2.04,"tv":5219.66,"id":9631939},{"batb":[[1,1.96,107.49]],"ltp":1.97,"tv":46724.66,"id":8681938}],"tv":51944.33}]}
{"op":"mcm","clk":"4297542760","pt":1632573840340,"mc":[{"id":"1.188134680","rc":[{"trd":[[1.98,1018.78],[2.02,36.64]],"ltp":1.98,"tv":5247.84,"id":9631939},{"trd":[[1.98,56.62],[2.02,337.32]],"batl":[[0,2.02,424.85],[1,2.04,368.16],[2,2.2,220.91]],"ltp":2.02,"tv":46752.72,"id":8681938}],"tv":52000.57}]}
{"op":"mcm","clk":"4297542889","pt":1632573841037,"mc":[{"id":"1.188134680","rc":[{"trd":[[1.97,47.03]],"batb":[[0,1.97,17]],"ltp":1.97,"tv":46757.42,"id":8681938}],"tv":52005.27}]}
{"op":"mcm","clk":"4297543315","pt":1632573842833,"mc":[{"id":"1.188134680","rc":[{"trd":[[1.97,68.59]],"batb":[[0,1.97,6.22]],"ltp":1.97,"tv":46778.98,"id":8681938}],"tv":52026.83}]}
{"op":"mcm","clk":"4297543434","pt":1632573843398,"mc":[{"id":"1.188134680","rc":[{"batl":[[1,2.06,20]],"ltp":1.98,"tv":5247.84,"id":9631939}]}]}
{"op":"mcm","clk":"4297544038","pt":1632573846327,"mc":[{"id":"1.188134680","rc":[{"batb":[[0,2,3.83],[1,1.97,163.56],[2,1.95,33.49]],"batl":[[0,2.04,10.97]],"ltp":1.98,"tv":5247.84,"id":9631939},{"trd":[[1.97,73.29]],"batb":[[0,1.97,3.87]],"batl":[[0,2,3.83],[1,2.02,424.85],[2,2.04,368.16]],"ltp":1.97,"tv":46783.68,"id":8681938}],"tv":52031.53}]}
{"op":"mcm","clk":"4297544116","pt":1632573846708,"mc":[{"id":"1.188134680","rc":[{"batl":[[0,2.02,28.18],[1,2.04,10.97],[2,2.06,20]],"ltp":1.98,"tv":5247.84,"id":9631939}]}]}
{"op":"mcm","clk":"4297544779","pt":1632573849973,"mc":[{"id":"1.188134680","rc":[{"trd":[[2.02,58.14]],"batl":[[0,2.02,6.68]],"ltp":2.02,"tv":5269.34,"id":9631939},{"trd":[[1.98,78.55]],"ltp":1.98,"tv":46805.62,"id":8681938}],"tv":52074.96}]}
{"op":"mcm","clk":"4297544915","pt":1632573850557,"mc":[{"id":"1.188134680","rc":[{"batb":[[0,1.97,163.56],[1,1.95,33.49],[2,1.93,495.46]],"batl":[[1,2.04,2.65]],"ltp":2.02,"tv":5269.34,"id":9631939},{"batl":[[0,2.02,424.85],[1,2.04,368.16],[2,2.2,220.91]],"ltp":1.98,"tv":46805.62,"id":8681938}]}]}
{"op":"mcm","clk":"4297545552","pt":1632573853151,"mc":[{"id":"1.188134680","rc":[{"trd":[[2,340.43]],"batl":[[0,2,28.09],[1,2.02,6.68],[2,2.04,2.65]],"ltp":2.0,"tv":5269.44,"id":9631939},{"trd":[[2,42.39]],"batb":[[1,1.96,103.49]],"ltp":2.0,"tv":46805.71,"id":8681938}],"tv":52075.15}]}
{"op":"mcm","clk":"4297545623","pt":1632573853436,"mc":[{"id":"1.188134680","rc":[{"trd":[[2,351.92]],"batl":[[0,2,20.43],[2,2.04,10.97]],"ltp":2.0,"tv":5280.93,"id":9631939},{"trd":[[2,46.22]],"ltp":2.0,"tv":46809.54,"id":8681938}],"tv":52090.47}]}
{"op":"mcm","clk":"4297546107","pt":1632573855860,"mc":[{"id":"1.188134680","rc":[{"batb":[[1,1.96,108.49]],"ltp":2.0,"tv":46809.54,"id":8681938}]}]}
{"op":"mcm","clk":"4297546591","pt":1632573858151,"mc":[{"id":"1.188134680","rc":[{"trd":[[2,368.17]],"batb":[[0,1.97,102.64]],"batl":[[0,2,4.18]],"ltp":2.0,"tv":5297.17,"id":9631939},{"trd":[[2,62.47]],"ltp":2.0,"tv":46825.78,"id":8681938}],"tv":52122.96}]}
{"op":"mcm","clk":"4297546771","pt":1632573859054,"mc":[{"id":"1.188134680","rc":[{"trd":[[1.98,1046.96],[2,370.52]],"batl":[[0,2,1.84]],"ltp":2.0,"tv":5327.7,"id":9631939},{"trd":[[2,64.82],[2.02,364.94]],"batl":[[0,2.02,397.23]],"ltp":2.0,"tv":46855.75,"id":8681938}],"tv":52183.46}]}
{"op":"mcm","clk":"4297546938","pt":1632573859997,"mc":[{"id":"1.188134680","rc":[{"batb":[[0,1.98,60.33],[1,1.97,102.64],[2,1.95,33.49]],"batl":[[0,1.99,96.87],[1,2,69.06],[2,2.02,6.68]],"ltp":2.0,"tv":5327.7,"id":9631939}]}]}
{"op":"mcm","clk":"4297547146","pt":1632573861151,"mc":[{"id":"1.188134680","rc":[{"trd":[[1.99,569.38]],"batb":[[1,1.97,176.63]],"batl":[[0,1.99,93.1]],"ltp":1.99,"tv":5335.24,"id":9631939}],"tv":52191.0}]}
{"op":"mcm","clk":"4297547364","pt":1632573862155,"mc":[{"id":"1.188134680","rc":[{"trd":[[1.99,578.44]],"batl":[[0,1.99,84.03]],"ltp":1.99,"tv":5344.31,"id":9631939},{"trd":[[2,73.84]],"ltp":2.0,"tv":46864.77,"id":8681938}],"tv":52209.09}]}
{"op":"mcm","clk":"4297547826","pt":1632573864362,"mc":[{"id":"1.188134680","rc":[{"batb":[[2,1.95,95.04]],"ltp":1.99,"tv":5344.31,"id":9631939}]}]}
{"op":"mcm","clk":"4297548253","pt":1632573866575,"mc":[{"id":"1.188134680","rc":[{"batl":[[2,2.02,14.75]],"ltp":1.99,"tv":5344.31,"id":9631939},{"batl":[[0,2.02,405.3]],"ltp":2.0,"tv":46864.77,"id":8681938}]}]}
{"op":"mcm","clk":"4297548589","pt":1632573868156,"mc":[{"id":"1.188134680","rc":[{"trd":[[1.99,675.88]],"batl":[[0,1.99,35.31],[1,2,67.22],[2,2.02,8.07]],"ltp":1.99,"tv":5441.74,"id":9631939},{"batb":[[1,1.96,103.49]],"ltp":2.0,"tv":46864.77,"id":8681938}],"tv":52306.52}]}
{"op":"mcm","clk":"4297548778","pt":1632573869172,"mc":[{"id":"1.188134680","rc":[{"trd":[[1.99,678.79]],"batl":[[0,1.99,32.41]],"ltp":1.99,"tv":5444.65,"id":9631939},{"trd":[[2,76.73]],"batb":[[0,1.99,1.74],[1,1.98,2.62],[2,1.97,7.39]],"ltp":2.0,"tv":46867.66,"id":8681938}],"tv":52312.32}]}
{"op":"mcm","clk":"4297548817","pt":1632573869396,"mc":[{"id":"1.188134680","rc":[{"batl":[[0,1.99,10.86]],"ltp":1.99,"tv":5444.65,"id":9631939},{"batb":[[1,1.97,7.39],[2,1.96,103.49]],"ltp":2.0,"tv":46867.66,"id":8681938}]}]}
{"op":"mcm","clk":"4297549214","pt":1632573871249,"mc":[{"id":"1.188134680","rc":[{"batb":[[2,1.96,106.49]],"ltp":2.0,"tv":46867.66,"id":8681938}]}]}
{"op":"mcm","clk":"4297549266","pt":1632573871571,"mc":[{"id":"1.188134680","rc":[{"trd":[[1.98,1047.74]],"batb":[[0,1.98,59.94]],"ltp":1.98,"tv":5445.43,"id":9631939}],"tv":52313.1}]}
{"op":"mcm","clk":"4297549578","pt":1632573873102,"mc":[{"id":"1.188134680","rc":[{"trd":[[1.99,700.5]],"batb":[[0,1.99,11.99],[1,1.98,59.94],[2,1.97,176.63]],"batl":[[0,2,67.22],[1,2.02,8.07],[2,2.04,2.65]],"ltp":1.99,"tv":5467.15,"id":9631939}],"tv":52334.82}]}
{"op":"mcm","clk":"4297550292","pt":1632573876378,"mc":[{"id":"1.188134680","rc":[{"batb":[[0,1.99,12.03]],"ltp":1.99,"tv":5467.15,"id":9631939}]}]}
{"op":"mcm","clk":"4297550339","pt":1632573876592,"mc":[{"id":"1.188134680","rc":[{"batl":[[0,2.02,8.07],[1,2.04,2.65],[2,2.14,56.28]],"ltp":1.99,"tv":5467.15,"id":9631939},{"batb":[[0,1.97,3.87],[1,1.96,106.49],[2,1.94,368.45]],"ltp":2.0,"tv":46867.66,"id":8681938}]}]}
{"op":"mcm","clk":"4297550672","pt":1632573878160,"mc":[{"id":"1.188134680","rc":[{"batb":[[0,1.99,19.07]],"ltp":1.99,"tv":5467.15,"id":9631939}]}]}
{"op":"mcm","clk":"4297551031","pt":1632573879799,"mc":[{"id":"1.188134680","rc":[{"batl":[[0,2,14.22],[1,2.02,405.3],[2,2.04,368.16]],"ltp":2.0,"tv":46867.66,"id":8681938}]}]}
