{"op":"mcm","clk":"4296716812","pt":1632569853290,"mc":[{"id":"1.188134680","rc":[{"batb":[[0,1.87,117.16],[1,1.5,94.99],[2,1.4,131.93]],"batl":[[1,3,3],[2,5.8,2.54]],"ltp":2.08,"tv":1370.39,"id":9631939},{"batb":[[0,1.84,123.78],[1,1.4,131.93],[2,1.3,175.9]],"batl":[[0,4.4,3.34],[1,1.98,0],[2,2.04,0]],"ltp":1.92,"tv":5196.32,"id":8681938}]}]}
{"op":"mcm","clk":"4296717121","pt":1632569855291,"mc":[{"id":"1.188134680","rc":[{"batl":[[0,1.95,157],[1,4.4,3.34]],"ltp":1.92,"tv":5196.32,"id":8681938}]}]}
{"op":"mcm","clk":"4296717273","pt":1632569856200,"mc":[{"id":"1.188134680","rc":[{"batb":[[0,1.97,4.31],[1,1.96,5],[2,1.91,114.9]],"ltp":2.08,"tv":1370.39,"id":9631939},{"batb":[[0,1.83,125.9]],"batl":[[0,4.4,3.34],[1,4.4,0]],"ltp":1.92,"tv":5196.32,"id":8681938}]}]}
{"op":"mcm","clk":"4296717369","pt":1632569856782,"mc":[{"id":"1.188134680","rc":[{"trd":[[2.08,47.1]],"batb":[[2,1.95,4]],"batl":[[0,2.08,38.47]],"ltp":2.08,"tv":1406.89,"id":9631939},{"trd":[[1.92,136.92]],"batl":[[0,2.16,4],[1,4.4,3.34]],"ltp":1.92,"tv":5235.86,"id":8681938}],"tv":6642.76}]}
{"op":"mcm","clk":"4296717753","pt":1632569858995,"mc":[{"id":"1.188134680","rc":[{"batb":[[0,1.91,339.45],[1,1.89,325.8],[2,1.83,125.9]],"batl":[[0,1.98,233.73],[1,2,279.25],[2,2.1,3]],"ltp":1.92,"tv":5235.86,"id":8681938}]}]}
{"op":"mcm","clk":"4296718014","pt":1632569860525,"mc":[{"id":"1.188134680","rc":[{"batb":[[0,2,285.42],[1,1.97,4.31],[2,1.96,5]],"ltp":2.08,"tv":1406.89,"id":9631939}]}]}
{"op":"mcm","clk":"4296718940","pt":1632569865798,"mc":[{"id":"1.188134680","rc":[{"batb":[[0,1.83,125.9],[1,1.4,131.93],[2,1.3,175.9]],"batl":[[0,2.1,3],[1,2.16,4],[2,4.4,3.34]],"ltp":1.92,"tv":5235.86,"id":8681938}]}]}
{"op":"mcm","clk":"4296719237","pt":1632569867603,"mc":[{"id":"1.188134680","rc":[{"batb":[[2,1.95,4]],"ltp":2.08,"tv":1406.89,"id":9631939}]}]}
{"op":"mcm","clk":"4296719459","pt":1632569869028,"mc":[{"id":"1.188134680","rc":[{"batb":[[2,1.91,119.9]],"ltp":2.08,"tv":1406.89,"id":9631939},{"batb":[[0,1.84,332.84],[1,1.83,125.9],[2,1.82,368]],"batl":[[0,2.1,329.23],[1,2.12,235.34],[2,2.16,4]],"ltp":1.92,"tv":5235.86,"id":8681938}]}]}
{"op":"mcm","clk":"4296719765","pt":1632569870830,"mc":[{"id":"1.188134680","rc":[{"batb":[[1,1.97,4.37],[2,1.91,114.9]],"ltp":2.08,"tv":1406.89,"id":9631939},{"batl":[[2,4.4,3.34]],"ltp":1.92,"tv":5235.86,"id":8681938}]}]}
{"op":"mcm","clk":"4296720038","pt":1632569872220,"mc":[{"id":"1.188134680","rc":[{"trd":[[2.08,85.57]],"batl":[[0,3,3],[1,5.8,2.54],[2,5.8,0]],"ltp":2.08,"tv":1445.36,"id":9631939},{"trd":[[1.92,178.59]],"batl":[[0,1.92,3.67],[1,2.1,3]],"ltp":1.92,"tv":5277.54,"id":8681938}],"tv":6722.9}]}
{"op":"mcm","clk":"4296720157","pt":1632569872810,"mc":[{"id":"1.188134680","rc":[{"batb":[[0,1.97,4.37],[1,1.91,114.9],[2,1.5,95.18]],"ltp":2.08,"tv":1445.36,"id":9631939},{"batb":[[1,1.82,368],[2,1.4,131.93]],"ltp":1.92,"tv":5277.54,"id":8681938}]}]}
{"op":"mcm","clk":"4296720393","pt":1632569874202,"mc":[{"id":"1.188134680","rc":[{"batb":[[0,2.16,6.44],[1,1.97,4.37],[2,1.91,114.9]],"batl":[[0,2.2,6.43],[1,2.24,1778.91],[2,2.26,1657.36]],"ltp":2.08,"tv":1445.36,"id":9631939},{"trd":[[1.84,549.39]],"batb":[[0,1.84,316.54]],"batl":[[0,1.91,3537.9],[1,1.92,2136.76],[2,1.93,1933.6]],"ltp":1.84,"tv":5310.14,"id":8681938}],"tv":6755.5}]}
{"op":"mcm","clk":"4296720575","pt":1632569875202,"mc":[{"id":"1.188134680","rc":[{"batl":[[1,2.24,498.23],[2,2.26,414.34]],"ltp":2.08,"tv":1445.36,"id":9631939},{"batl":[[0,1.91,628.85],[1,1.92,642.62],[2,1.93,794.45]],"ltp":1.84,"tv":5310.14,"id":8681938}]}]}
{"op":"mcm","clk":"4296720782","pt":1632569876319,"mc":[{"id":"1.188134680","rc":[{"batb":[[1,2.1,166.65],[2,2.04,184.15]],"batl":[[0,2.2,10.43],[1,2.24,511.7]],"ltp":2.08,"tv":1445.36,"id":9631939},{"batb":[[1,1.82,494.66],[2,1.81,66.66]],"ltp":1.84,"tv":5310.14,"id":8681938}]}]}
{"op":"mcm","clk":"4296721541","pt":1632569880815,"mc":[{"id":"1.188134680","rc":[{"batb":[[1,2.1,166.48],[2,2.04,183.9]],"ltp":2.08,"tv":1445.36,"id":9631939}]}]}
{"op":"mcm","clk":"4296721955","pt":1632569883010,"mc":[{"id":"1.188134680","rc":[{"batb":[[2,2.04,198.32]],"ltp":2.08,"tv":1445.36,"id":9631939}]}]}
{"op":"mcm","clk":"4296722461","pt":1632569886332,"mc":[{"id":"1.188134680","rc":[{"batl":[[0,1.91,348.06]],"ltp":1.84,"tv":5310.14,"id":8681938}]}]}
{"op":"mcm","clk":"4296722583","pt":1632569887123,"mc":[{"id":"1.188134680","rc":[{"trd":[[2.16,76.93]],"batb":[[0,2.1,166.82],[1,2.04,198.32],[2,1.97,4.37]],"ltp":2.16,"tv":1451.46,"id":9631939},{"trd":[[1.87,475.3]],"ltp":1.87,"tv":5317.18,"id":8681938}],"tv":6768.65}]}
{"op":"mcm","clk":"4296722932","pt":1632569889214,"mc":[{"id":"1.188134680","rc":[{"trd":[[2.16,77.1]],"batb":[[0,2.1,166.65]],"ltp":2.16,"tv":1451.63,"id":9631939},{"trd":[[1.87,475.49]],"ltp":1.87,"tv":5317.38,"id":8681938}],"tv":6769.01}]}
{"op":"mcm","clk":"4296723811","pt":1632569894311,"mc":[{"id":"1.188134680","rc":[{"trd":[[2.16,77.44]],"batb":[[0,2.1,166.48]],"batl":[[0,2.16,5.98],[1,2.2,10.43],[2,2.24,511.7]],"ltp":2.16,"tv":1451.97,"id":9631939},{"batb":[[0,1.85,4.23],[1,1.84,316.54],[2,1.82,494.66]],"ltp":1.87,"tv":5317.38,"id":8681938}],"tv":6769.35}]}
{"op":"mcm","clk":"4296723935","pt":1632569895035,"mc":[{"id":"1.188134680","rc":[{"batb":[[2,1.83,518.44]],"ltp":1.87,"tv":5317.38,"id":8681938}]}]}
{"op":"mcm","clk":"4296724320","pt":1632569897330,"mc":[{"id":"1.188134680","rc":[{"batl":[[1,2.2,4]],"ltp":2.16,"tv":1451.97,"id":9631939}]}]}
{"op":"mcm","clk":"4296724813","pt":1632569900341,"mc":[{"id":"1.188134680","rc":[{"batl":[[1,2.2,16.75]],"ltp":2.16,"tv":1451.97,"id":9631939},{"batl":[[0,1.89,13.92],[1,1.91,348.06],[2,1.92,642.62]],"ltp":1.87,"tv":5317.38,"id":8681938}]}]}
{"op":"mcm","clk":"4296724845","pt":1632569900551,"mc":[{"id":"1.188134680","rc":[{"batl":[[1,2.2,4]],"ltp":2.16,"tv":1451.97,"id":9631939},{"batl":[[0,1.91,348.06],[1,1.92,642.62],[2,1.93,794.45]],"ltp":1.87,"tv":5317.38,"id":8681938}]}]}
{"op":"mcm","clk":"4296725898","pt":1632569906847,"mc":[{"id":"1.188134680","rc":[{"batl":[[1,2.2,16.75]],"ltp":2.16,"tv":1451.97,"id":9631939},{"batl":[[0,1.89,13.92],[1,1.91,348.06],[2,1.92,642.62]],"ltp":1.87,"tv":5317.38,"id":8681938}]}]}
{"op":"mcm","clk":"4296726116","pt":1632569908255,"mc":[{"id":"1.188134680","rc":[{"batb":[[0,1.84,316.54],[1,1.83,518.44],[2,1.82,494.66]],"ltp":1.87,"tv":5317.38,"id":8681938}]}]}
{"op":"mcm","clk":"4296726231","pt":1632569909053,"mc":[{"id":"1.188134680","rc":[{"batl":[[1,2.18,7.91],[2,2.2,16.75]],"ltp":2.16,"tv":1451.97,"id":9631939}]}]}
{"op":"mcm","clk":"4296726627","pt":1632569911461,"mc":[{"id":"1.188134680","rc":[{"batb":[[0,1.87,4.23],[1,1.84,316.54],[2,1.83,518.44]],"ltp":1.87,"tv":5317.38,"id":8681938}]}]}
{"op":"mcm","clk":"4296727167","pt":1632569914709,"mc":[{"id":"1.188134680","rc":[{"batl":[[0,1.89,186.92]],"ltp":1.87,"tv":5317.38,"id":8681938}]}]}
{"op":"mcm","clk":"4296727317","pt":1632569915605,"mc":[{"id":"1.188134680","rc":[{"trd":[[2.12,17.64]],"ltp":2.12,"tv":1460.76,"id":9631939},{"trd":[[1.89,701.59]],"batl":[[0,1.89,177.06]],"ltp":1.89,"tv":5327.24,"id":8681938}],"tv":6788.0}]}
{"op":"mcm","clk":"4296729081","pt":1632569925833,"mc":[{"id":"1.188134680","rc":[{"batl":[[2,2.2,4]],"ltp":2.12,"tv":1460.76,"id":9631939},{"batl":[[0,1.89,173]],"ltp":1.89,"tv":5327.24,"id":8681938}]}]}
{"op":"mcm","clk":"4296729593","pt":1632569928750,"mc":[{"id":"1.188134680","rc":[{"batl":[[0,2.16,14.61]],"ltp":2.12,"tv":1460.76,"id":9631939},{"batl":[[2,1.92,660.84]],"ltp":1.89,"tv":5327.24,"id":8681938}]}]}
{"op":"mcm","clk":"4296729784","pt":1632569929639,"mc":[{"id":"1.188134680","rc":[{"trd":[[2.16,92.05]],"batl":[[0,2.18,7.91],[1,2.2,4],[2,2.24,511.7]],"ltp":2.16,"tv":1475.37,"id":9631939},{"trd":[[1.86,121.71],[1.87,483.95]],"batb":[[0,1.84,316.54],[1,1.83,518.44],[2,1.82,494.66]],"batl":[[0,1.86,194.86],[1,1.89,173],[2,1.91,348.06]],"ltp":1.86,"tv":5373.75,"id":8681938}],"tv":6849.12}]}
{"op":"mcm","clk":"4296730430","pt":1632569932930,"mc":[{"id":"1.188134680","rc":[{"batl":[[1,1.89,343]],"ltp":1.86,"tv":5373.75,"id":8681938}]}]}
{"op":"mcm","clk":"4296732253","pt":1632569942745,"mc":[{"id":"1.188134680","rc":[{"batl":[[1,2.2,16.75]],"ltp":2.16,"tv":1475.37,"id":9631939},{"batl":[[1,1.89,356.93]],"ltp":1.86,"tv":5373.75,"id":8681938}]}]}
{"op":"mcm","clk":"4296735174","pt":1632569959671,"mc":[{"id":"1.188134680","rc":[{"batb":[[0,1.85,14.94],[1,1.84,316.54],[2,1.83,518.44]],"ltp":1.86,"tv":5373.75,"id":8681938}]}]}
{"op":"mcm","clk":"4296736147","pt":1632569965238,"mc":[{"id":"1.188134680","rc":[{"batb":[[0,2.04,198.32],[1,1.97,4.37],[2,1.5,94.99]],"batl":[[1,2.24,13.47],[2,5.8,2.54]],"ltp":2.16,"tv":1475.37,"id":9631939},{"batb":[[1,1.83,518.44],[2,1.81,66.66]],"batl":[[1,1.89,343],[2,1.92,3.67]],"ltp":1.86,"tv":5373.75,"id":8681938}]}]}
{"op":"mcm","clk":"4296736322","pt":1632569966247,"mc":[{"id":"1.188134680","rc":[{"batb":[[0,2.04,183.9]],"batl":[[1,5.8,2.54],[2,5.8,0]],"ltp":2.16,"tv":1475.37,"id":9631939},{"batb":[[2,1.71,156.67]],"ltp":1.86,"tv":5373.75,"id":8681938}]}]}
{"op":"mcm","clk":"4296736440","pt":1632569966879,"mc":[{"id":"1.188134680","rc":[{"batb":[[1,1.71,156.67],[2,1.4,131.93]],"batl":[[1,1.92,3.67],[2,2.1,3]],"ltp":1.86,"tv":5373.75,"id":8681938}]}]}
{"op":"mcm","clk":"4296736764","pt":1632569968841,"mc":[{"id":"1.188134680","rc":[{"batl":[[1,2.1,3],[2,4.4,3.34]],"ltp":1.86,"tv":5373.75,"id":8681938}]}]}
{"op":"mcm","clk":"4296736937","pt":1632569969845,"mc":[{"id":"1.188134680","rc":[{"batb":[[1,1.82,287.54],[2,1.8,381.52]],"batl":[[1,1.88,262.6],[2,1.9,326.57]],"ltp":1.86,"tv":5373.75,"id":8681938}]}]}
{"op":"mcm","clk":"4296737344","pt":1632569972481,"mc":[{"id":"1.188134680","rc":[{"trd":[[1.86,135.81]],"batl":[[0,1.86,187.81]],"ltp":1.86,"tv":5387.84,"id":8681938}],"tv":6863.22}]}
{"op":"mcm","clk":"4296737690","pt":1632569974641,"mc":[{"id":"1.188134680","rc":[{"batb":[[1,1.71,156.67],[2,1.4,131.93]],"batl":[[1,2.1,3],[2,4.4,3.34]],"ltp":1.86,"tv":5387.84,"id":8681938}]}]}
{"op":"mcm","clk":"4296737930","pt":1632569976078,"mc":[{"id":"1.188134680","rc":[{"batl":[[0,5.8,2.54],[1,5.8,0]],"ltp":2.16,"tv":1475.37,"id":9631939}]}]}
{"op":"mcm","clk":"4296738164","pt":1632569977551,"mc":[{"id":"1.188134680","rc":[{"batb":[[1,1.73,363.94],[2,1.71,610.72]],"batl":[[1,1.96,278.98],[2,1.98,287.77]],"ltp":1.86,"tv":5387.84,"id":8681938}]}]}
{"op":"mcm","clk":"4296738427","pt":1632569979141,"mc":[{"id":"1.188134680","rc":[{"batl":[[0,2.28,7.91],[1,5.8,2.54]],"ltp":2.16,"tv":1475.37,"id":9631939}]}]}
{"op":"mcm","clk":"4296738576","pt":1632569980189,"mc":[{"id":"1.188134680","rc":[{"batb":[[2,1.5,95.18]],"ltp":2.16,"tv":1475.37,"id":9631939}]}]}
{"op":"mcm","clk":"4296738650","pt":1632569980668,"mc":[{"id":"1.188134680","rc":[{"batl":[[1,2.1,3],[2,4.4,3.34]],"ltp":1.86,"tv":5387.84,"id":8681938}]}]}
{"op":"mcm","clk":"4296738870","pt":1632569981986,"mc":[{"id":"1.188134680","rc":[{"batl":[[0,2.1,3],[1,4.4,3.34],[2,4.4,0]],"ltp":1.86,"tv":5387.84,"id":8681938}]}]}
{"op":"mcm","clk":"4296739101","pt":1632569983362,"mc":[{"id":"1.188134680","rc":[{"trd":[[2.28,7.91]],"batb":[[0,2.32,10.25],[1,2.04,183.9],[2,1.97,4.37]],"batl":[[0,5.8,2.54],[1,5.8,0]],"ltp":2.28,"tv":1483.28,"id":9631939},{"trd":[[1.78,29.48],[1.85,92.28]],"batb":[[0,1.73,363.94],[1,1.72,10.55]],"batl":[[0,1.74,7.11],[1,1.78,114.55],[2,1.8,2125]],"ltp":1.78,"tv":5427.85,"id":8681938}],"tv":6911.13}]}
{"op":"mcm","clk":"4296739289","pt":1632569984369,"mc":[{"id":"1.188134680","rc":[{"batb":[[1,2.3,132.41],[2,2.18,151.68]],"batl":[[0,2.62,11.45],[1,2.66,1.71],[2,5.8,2.54]],"ltp":2.28,"tv":1483.28,"id":9631939},{"batl":[[2,1.79,347.7]],"ltp":1.78,"tv":5427.85,"id":8681938}]}]}
{"op":"mcm","clk":"4296739448","pt":1632569985262,"mc":[{"id":"1.188134680","rc":[{"batb":[[2,2.18,164.39]],"batl":[[0,2.44,12.5],[1,2.62,11.45],[2,2.66,1.71]],"ltp":2.28,"tv":1483.28,"id":9631939}]}]}
{"op":"mcm","clk":"4296739722","pt":1632569986696,"mc":[{"id":"1.188134680","rc":[{"batb":[[2,2.18,151.68]],"batl":[[0,2.62,11.45],[1,2.66,1.71],[2,3,217.75]],"ltp":2.28,"tv":1483.28,"id":9631939}]}]}
{"op":"mcm","clk":"4296740039","pt":1632569988319,"mc":[{"id":"1.188134680","rc":[{"batl":[[0,2.48,75.71],[1,2.62,11.45],[2,2.66,1.71]],"ltp":2.28,"tv":1483.28,"id":9631939},{"trd":[[1.73,6.86]],"batb":[[0,1.73,360.51]],"ltp":1.73,"tv":5434.71,"id":8681938}],"tv":6917.99}]}
{"op":"mcm","clk":"4296740079","pt":1632569988591,"mc":[{"id":"1.188134680","rc":[{"batl":[[0,2.62,11.45],[1,2.66,1.71],[2,3,217.75]],"ltp":2.28,"tv":1483.28,"id":9631939}]}]}
{"op":"mcm","clk":"4296740335","pt":1632569990154,"mc":[{"id":"1.188134680","rc":[{"batl":[[0,2.44,12.5],[1,2.62,11.45],[2,2.66,1.71]],"ltp":2.28,"tv":1483.28,"id":9631939}]}]}
{"op":"mcm","clk":"4296740926","pt":1632569993381,"mc":[{"id":"1.188134680","rc":[{"trd":[[2.34,0.78]],"batb":[[2,2.22,12.29]],"batl":[[0,2.44,132.59]],"ltp":2.34,"tv":1484.06,"id":9631939},{"trd":[[1.74,13.17]],"batl":[[0,1.78,114.55],[1,1.79,347.7],[2,1.8,531.24]],"ltp":1.74,"tv":5447.88,"id":8681938}],"tv":6931.94}]}
{"op":"mcm","clk":"4296741222","pt":1632569994928,"mc":[{"id":"1.188134680","rc":[{"batl":[[2,2.76,2.06]],"ltp":2.34,"tv":1484.06,"id":9631939},{"trd":[[1.73,382.48]],"batb":[[0,1.73,172.7]],"batl":[[1,1.8,531.24],[2,1.81,515.62]],"ltp":1.73,"tv":5823.5,"id":8681938}],"tv":7307.56}]}
{"op":"mcm","clk":"4296741633","pt":1632569997203,"mc":[{"id":"1.188134680","rc":[{"batb":[[0,1.74,1.3],[1,1.73,172.7],[2,1.72,10.55]],"ltp":1.73,"tv":5823.5,"id":8681938}]}]}
{"op":"mcm","clk":"4296741803","pt":1632569998189,"mc":[{"id":"1.188134680","rc":[{"batl":[[0,2.44,12.5],[2,2.74,2.48]],"ltp":2.34,"tv":1484.06,"id":9631939},{"trd":[[1.73,389.88],[1.74,15.77]],"batb":[[0,1.73,254.56],[1,1.72,10.55],[2,1.71,610.72]],"batl":[[0,1.78,369.25],[1,1.8,919.45]],"ltp":1.73,"tv":5833.5,"id":8681938}],"tv":7317.57}]}
{"op":"mcm","clk":"4296742141","pt":1632570000110,"mc":[{"id":"1.188134680","rc":[{"batb":[[0,2.22,12.29],[1,2.18,151.43],[2,1.77,410.93]],"batl":[[1,3,217.75],[2,5.8,2.54]],"ltp":2.34,"tv":1484.06,"id":9631939},{"batb":[[0,1.69,72.23],[1,1.56,218.56],[2,1.3,175.9]],"batl":[[0,1.76,126],[1,1.82,15],[2,1.84,13.28]],"ltp":1.73,"tv":5833.5,"id":8681938}]}]}
{"op":"mcm","clk":"4296742363","pt":1632570001289,"mc":[{"id":"1.188134680","rc":[{"batb":[[0,2.18,151.43],[1,2.14,3.82]],"batl":[[0,3,217.75],[1,5.8,2.54],[2,5.8,0]],"ltp":2.34,"tv":1484.06,"id":9631939},{"batb":[[0,1.56,218.56],[1,1.3,175.9],[2,1.25,29.25]],"batl":[[0,1.87,15.5],[1,1.88,13.04],[2,2.1,3]],"ltp":1.73,"tv":5833.5,"id":8681938}]}]}
{"op":"mcm","clk":"4296742422","pt":1632570001606,"mc":[{"id":"1.188134680","rc":[{"batb":[[1,2.14,6.82]],"ltp":2.34,"tv":1484.06,"id":9631939}]}]}
{"op":"mcm","clk":"4296742762","pt":1632570003330,"mc":[{"id":"1.188134680","rc":[{"batl":[[0,2.74,2.48],[1,3,217.75],[2,5.8,2.54]],"ltp":2.34,"tv":1484.06,"id":9631939},{"batb":[[0,1.58,493.51],[1,1.57,312.5],[2,1.56,218.56]],"batl":[[0,1.86,335.78],[1,1.87,15.5],[2,1.88,350.7]],"ltp":1.73,"tv":5833.5,"id":8681938}]}]}
{"op":"mcm","clk":"4296743097","pt":1632570005121,"mc":[{"id":"1.188134680","rc":[{"batl":[[1,2.8,3],[2,3,217.75]],"ltp":2.34,"tv":1484.06,"id":9631939},{"batb":[[2,1.56,224.56]],"ltp":1.73,"tv":5833.5,"id":8681938}]}]}
{"op":"mcm","clk":"4296743333","pt":1632570006292,"mc":[{"id":"1.188134680","rc":[{"batb":[[2,1.7,15.63]],"batl":[[0,2.74,5.48],[2,5.8,2.54]],"ltp":2.34,"tv":1484.06,"id":9631939},{"batb":[[0,1.58,498.51],[1,1.57,317.5]],"batl":[[0,2.1,3],[1,4.4,3.34],[2,1.88,0]],"ltp":1.73,"tv":5833.5,"id":8681938}]}]}
{"op":"mcm","clk":"4296743696","pt":1632570008307,"mc":[{"id":"1.188134680","rc":[{"batb":[[0,2.18,154.79]],"batl":[[0,2.72,7.1],[1,2.74,5.48],[2,2.8,3]],"ltp":2.34,"tv":1484.06,"id":9631939},{"batl":[[0,1.62,39.18],[1,1.64,152.94],[2,1.65,2318.18]],"ltp":1.73,"tv":5833.5,"id":8681938}]}]}
{"op":"mcm","clk":"4296743879","pt":1632570009320,"mc":[{"id":"1.188134680","rc":[{"batb":[[0,2.64,90.55],[1,2.44,112.28],[2,2.18,151.43]],"ltp":2.34,"tv":1484.06,"id":9631939},{"batl":[[1,1.63,379.07],[2,1.64,417.45]],"ltp":1.73,"tv":5833.5,"id":8681938}]}]}
{"op":"mcm","clk":"4296744046","pt":1632570010289,"mc":[{"id":"1.188134680","rc":[{"batb":[[1,2.46,10.27],[2,2.44,112.28]],"batl":[[0,2.72,10.1],[2,2.78,11.24]],"ltp":2.34,"tv":1484.06,"id":9631939},{"batb":[[0,1.59,5],[1,1.58,498.51],[2,1.57,317.5]],"ltp":1.73,"tv":5833.5,"id":8681938}]}]}
{"op":"mcm","clk":"4296744335","pt":1632570011995,"mc":[{"id":"1.188134680","rc":[{"batb":[[1,2.44,112.28],[2,2.2,4]],"batl":[[0,2.7,4],[1,2.72,10.1],[2,2.74,5.48]],"ltp":2.34,"tv":1484.06,"id":9631939}]}]}
{"op":"mcm","clk":"4296744557","pt":1632570013313,"mc":[{"id":"1.188134680","rc":[{"batl":[[0,1.6,20.81],[1,1.62,275.18],[2,1.63,379.07]],"ltp":1.73,"tv":5833.5,"id":8681938}]}]}
{"op":"mcm","clk":"4296744647","pt":1632570013785,"mc":[{"id":"1.188134680","rc":[{"batl":[[0,1.62,275.18],[1,1.63,379.07],[2,1.64,417.45]],"ltp":1.73,"tv":5833.5,"id":8681938}]}]}
{"op":"mcm","clk":"4296745059","pt":1632570016220,"mc":[{"id":"1.188134680","rc":[{"batb":[[2,2.38,3.46]],"ltp":2.34,"tv":1484.06,"id":9631939},{"batl":[[0,1.62,436.18]],"ltp":1.73,"tv":5833.5,"id":8681938}]}]}
{"op":"mcm","clk":"4296745412","pt":1632570018332,"mc":[{"id":"1.188134680","rc":[{"trd":[[2.64,0.1]],"batb":[[0,2.64,90.45]],"batl":[[2,2.74,2.48]],"ltp":2.64,"tv":1484.16,"id":9631939},{"trd":[[1.61,0.17]],"batb":[[1,1.58,493.51],[2,1.57,312.5]],"ltp":1.61,"tv":5833.67,"id":8681938}],"tv":7317.84}]}
{"op":"mcm","clk":"4296746305","pt":1632570023311,"mc":[{"id":"1.188134680","rc":[{"batl":[[1,2.72,7.1]],"ltp":2.64,"tv":1484.16,"id":9631939}]}]}
{"op":"mcm","clk":"4296746379","pt":1632570023728,"mc":[{"id":"1.188134680","rc":[{"trd":[[1.59,3.32]],"batb":[[0,1.59,3.34]],"ltp":1.59,"tv":5836.99,"id":8681938}],"tv":7321.16}]}
{"op":"mcm","clk":"4296746532","pt":1632570024414,"mc":[{"id":"1.188134680","rc":[{"trd":[[2.64,116.96]],"batb":[[0,2.64,32.02]],"ltp":2.64,"tv":1601.02,"id":9631939}],"tv":7438.02}]}
{"op":"mcm","clk":"4296746739","pt":1632570025630,"mc":[{"id":"1.188134680","rc":[{"trd":[[2.64,117.35]],"batb":[[0,2.64,31.64]],"ltp":2.64,"tv":1601.41,"id":9631939},{"trd":[[1.61,0.8]],"ltp":1.61,"tv":5837.62,"id":8681938}],"tv":7439.03}]}
{"op":"mcm","clk":"4296747045","pt":1632570027548,"mc":[{"id":"1.188134680","rc":[{"trd":[[2.64,137.71]],"batb":[[0,2.64,21.46]],"ltp":2.64,"tv":1621.77,"id":9631939}],"tv":7459.39}]}
{"op":"mcm","clk":"4296747672","pt":1632570031223,"mc":[{"id":"1.188134680","rc":[{"batb":[[0,2.44,112.28],[1,2.38,3.46],[2,2.3,2.78]],"batl":[[0,2.78,11.24],[1,3.4,2.04],[2,3.45,184.03]],"ltp":2.64,"tv":1621.77,"id":9631939},{"batb":[[0,1.56,80.17],[1,1.42,29.44],[2,1.4,340.15]],"batl":[[0,1.62,397],[1,1.67,15],[2,1.72,14.91]],"ltp":1.61,"tv":5837.62,"id":8681938}]}]}
{"op":"mcm","clk":"4296747870","pt":1632570032369,"mc":[{"id":"1.188134680","rc":[{"batl":[[0,3.4,2.04],[1,3.45,184.03],[2,3.8,2]],"ltp":2.64,"tv":1621.77,"id":9631939},{"batb":[[0,1.42,29.44],[1,1.4,340.15],[2,1.36,29.93]],"batl":[[0,1.72,14.91],[1,1.76,18.27],[2,1.83,4.47]],"ltp":1.61,"tv":5837.62,"id":8681938}]}]}
{"op":"mcm","clk":"4296747927","pt":1632570032642,"mc":[{"id":"1.188134680","rc":[{"batl":[[0,3.45,184.03],[1,3.8,2],[2,5.8,2.54]],"ltp":2.64,"tv":1621.77,"id":9631939},{"batb":[[0,1.4,340.15],[1,1.36,29.93],[2,1.3,175.9]],"ltp":1.61,"tv":5837.62,"id":8681938}]}]}
{"op":"mcm","clk":"4296748234","pt":1632570034344,"mc":[{"id":"1.188134680","rc":[{"batb":[[0,2.5,10],[1,2.38,117.43]],"ltp":2.64,"tv":1621.77,"id":9631939},{"batb":[[0,1.42,750.31],[1,1.41,490.54],[2,1.4,336.09]],"batl":[[0,1.72,425.17],[1,1.74,433.66],[2,1.76,18.27]],"ltp":1.61,"tv":5837.62,"id":8681938}]}]}
{"op":"mcm","clk":"4296748282","pt":1632570034657,"mc":[{"id":"1.188134680","rc":[{"batb":[[0,2.38,117.43],[1,2.3,2.78],[2,2.2,4]],"ltp":2.64,"tv":1621.77,"id":9631939}]}]}
{"op":"mcm","clk":"4296748540","pt":1632570036141,"mc":[{"id":"1.188134680","rc":[{"batl":[[0,3.4,5.04],[1,3.45,187.03],[2,3.8,2]],"ltp":2.64,"tv":1621.77,"id":9631939},{"batb":[[0,1.42,785.75],[1,1.41,497.54],[2,1.4,342.09]],"ltp":1.61,"tv":5837.62,"id":8681938}]}]}
{"op":"mcm","clk":"4296749056","pt":1632570039264,"mc":[{"id":"1.188134680","rc":[{"batb":[[0,2.38,113.97]],"ltp":2.64,"tv":1621.77,"id":9631939},{"batl":[[0,1.83,4.47],[1,4.4,3.34],[2,1.76,0]],"ltp":1.61,"tv":5837.62,"id":8681938}]}]}
{"op":"mcm","clk":"4296749436","pt":1632570041338,"mc":[{"id":"1.188134680","rc":[{"batl":[[1,3.45,3]],"ltp":2.64,"tv":1621.77,"id":9631939},{"batl":[[0,1.82,1.1],[1,1.83,4],[2,4.4,3.34]],"ltp":1.61,"tv":5837.62,"id":8681938}]}]}
{"op":"mcm","clk":"4296749625","pt":1632570042346,"mc":[{"id":"1.188134680","rc":[{"batb":[[0,3,46.55],[1,2.38,113.97],[2,2.3,2.78]],"batl":[[0,3.4,76.3],[2,3.6,1.71]],"ltp":2.64,"tv":1621.77,"id":9631939},{"batb":[[0,1.45,12.55],[1,1.42,785.75],[2,1.41,497.54]],"batl":[[0,1.46,375.92],[1,1.47,1064.39],[2,1.48,631.38]],"ltp":1.61,"tv":5837.62,"id":8681938}]}]}
{"op":"mcm","clk":"4296749778","pt":1632570043148,"mc":[{"id":"1.188134680","rc":[{"batb":[[0,3.15,134.35],[1,3,46.55],[2,2.9,68.49]],"batl":[[1,3.45,11.7]],"ltp":2.64,"tv":1621.77,"id":9631939}]}]}
{"op":"mcm","clk":"4296749895","pt":1632570043827,"mc":[{"id":"1.188134680","rc":[{"batb":[[2,2.96,7.65]],"batl":[[0,3.35,3],[1,3.4,85.98],[2,3.45,11.7]],"ltp":2.64,"tv":1621.77,"id":9631939},{"batb":[[1,1.43,7],[2,1.42,878.33]],"ltp":1.61,"tv":5837.62,"id":8681938}]}]}
{"op":"mcm","clk":"4296750109","pt":1632570045152,"mc":[{"id":"1.188134680","rc":[{"batb":[[2,2.98,3]],"ltp":2.64,"tv":1621.77,"id":9631939},{"trd":[[1.46,4.38]],"batl":[[0,1.46,373.73]],"ltp":1.46,"tv":5842.01,"id":8681938}],"tv":7463.78}]}
{"op":"mcm","clk":"4296750838","pt":1632570049165,"mc":[{"id":"1.188134680","rc":[{"batl":[[1,3.4,82.98],[2,3.45,8.7]],"ltp":2.64,"tv":1621.77,"id":9631939},{"batb":[[2,1.42,871.33]],"batl":[[0,1.46,811.73]],"ltp":1.46,"tv":5842.01,"id":8681938}]}]}
{"op":"mcm","clk":"4296750982","pt":1632570050070,"mc":[{"id":"1.188134680","rc":[{"batb":[[1,3,54.05]],"ltp":2.64,"tv":1621.77,"id":9631939}]}]}
{"op":"mcm","clk":"4296751364","pt":1632570052352,"mc":[{"id":"1.188134680","rc":[{"trd":[[1.46,20.02]],"batl":[[0,1.46,803.91]],"ltp":1.46,"tv":5857.64,"id":8681938}],"tv":7479.41}]}
{"op":"mcm","clk":"4296751531","pt":1632570053153,"mc":[{"id":"1.188134680","rc":[{"trd":[[1.45,4.4]],"batb":[[0,1.45,10.35]],"ltp":1.45,"tv":5862.04,"id":8681938}],"tv":7483.81}]}
{"op":"mcm","clk":"4296751711","pt":1632570054148,"mc":[{"id":"1.188134680","rc":[{"trd":[[1.45,17.58]],"batb":[[0,1.45,3.76]],"ltp":1.45,"tv":5875.22,"id":8681938}],"tv":7496.99}]}
{"op":"mcm","clk":"4296751804","pt":1632570054676,"mc":[{"id":"1.188134680","rc":[{"trd":[[1.46,21.28]],"batl":[[0,1.46,803.28]],"ltp":1.46,"tv":5876.48,"id":8681938}],"tv":7498.25}]}
{"op":"mcm","clk":"4296752070","pt":1632570056297,"mc":[{"id":"1.188134680","rc":[{"trd":[[1.45,25.1]],"batb":[[0,1.43,7],[1,1.42,871.33],[2,1.41,5716.87]],"batl":[[0,1.45,2.28],[1,1.46,803.28],[2,1.47,1064.39]],"ltp":1.45,"tv":5884.0,"id":8681938}],"tv":7505.77}]}
{"op":"mcm","clk":"4296752196","pt":1632570057095,"mc":[{"id":"1.188134680","rc":[{"batb":[[2,1.41,490.54]],"batl":[[1,1.46,365.28]],"ltp":1.45,"tv":5884.0,"id":8681938}]}]}
{"op":"mcm","clk":"4296752620","pt":1632570059803,"mc":[{"id":"1.188134680","rc":[{"batl":[[0,1.45,6239.28]],"ltp":1.45,"tv":5884.0,"id":8681938}]}]}
{"op":"mcm","clk":"4296752872","pt":1632570061206,"mc":[{"id":"1.188134680","rc":[{"batb":[[0,3,7.5],[1,2.9,68.49],[2,2.84,2.47]],"batl":[[0,3.4,9.68],[1,4.2,151.01],[2,4.3,2]],"ltp":2.64,"tv":1621.77,"id":9631939},{"batb":[[0,1.42,92.58],[1,1.31,35.79],[2,1.28,514.15]],"batl":[[1,1.5,15],[2,1.54,21.75]],"ltp":1.45,"tv":5884.0,"id":8681938}]}]}
{"op":"mcm","clk":"4296753073","pt":1632570062336,"mc":[{"id":"1.188134680","rc":[{"batb":[[0,2.9,68.49],[1,2.84,2.47],[2,2.74,2.52]],"batl":[[0,4.2,151.01],[1,4.3,2],[2,4.8,2]],"ltp":2.64,"tv":1621.77,"id":9631939},{"batb":[[0,1.31,35.79],[1,1.28,514.15],[2,1.27,53.87]],"batl":[[0,1.45,2.28],[1,1.54,21.75],[2,1.57,23.5]],"ltp":1.45,"tv":5884.0,"id":8681938}]}]}
{"op":"mcm","clk":"4296753536","pt":1632570064371,"mc":[{"id":"1.188134680","rc":[{"batb":[[1,2.74,2.52],[2,2.72,2.59]],"ltp":2.64,"tv":1621.77,"id":9631939},{"batb":[[0,1.31,447.08],[1,1.3,727.53],[2,1.28,514.15]],"batl":[[1,1.53,487.01],[2,1.54,333.24]],"ltp":1.45,"tv":5884.0,"id":8681938}]}]}
{"op":"mcm","clk":"4296753647","pt":1632570065007,"mc":[{"id":"1.188134680","rc":[{"batl":[[1,4.8,2],[2,5.8,2.54]],"ltp":2.64,"tv":1621.77,"id":9631939},{"batb":[[0,1.28,514.15],[1,1.27,53.87],[2,1.2,395.79]],"batl":[[0,1.53,487.01],[1,1.54,333.24],[2,1.57,23.5]],"ltp":1.45,"tv":5884.0,"id":8681938}]}]}
{"op":"mcm","clk":"4296753823","pt":1632570066004,"mc":[{"id":"1.188134680","rc":[{"batl":[[0,4.2,3]],"ltp":2.64,"tv":1621.77,"id":9631939},{"batb":[[0,1.31,2],[1,1.3,2],[2,1.28,514.15]],"ltp":1.45,"tv":5884.0,"id":8681938}]}]}
{"op":"mcm","clk":"4296754053","pt":1632570067281,"mc":[{"id":"1.188134680","rc":[{"batl":[[0,3.15,895.24],[1,3.2,9.38],[2,4.2,3]],"ltp":2.64,"tv":1621.77,"id":9631939},{"batb":[[0,1.48,131.64],[1,1.47,319.72],[2,1.46,479.59]],"batl":[[2,1.56,195.55]],"ltp":1.45,"tv":5884.0,"id":8681938}]}]}
{"op":"mcm","clk":"4296754218","pt":1632570068294,"mc":[{"id":"1.188134680","rc":[{"batb":[[0,2.9,878.83],[1,2.88,243.11],[2,2.86,243.11]],"batl":[[0,3.15,298.42],[1,3.2,19.49]],"ltp":2.64,"tv":1621.77,"id":9631939},{"trd":[[1.49,4.56]],"batb":[[0,1.49,335.45],[1,1.48,526.31],[2,1.47,594.43]],"batl":[[2,1.55,19.35]],"ltp":1.49,"tv":5888.56,"id":8681938}],"tv":7510.33}]}
{"op":"mcm","clk":"4296754292","pt":1632570068818,"mc":[{"id":"1.188134680","rc":[{"batb":[[0,2.9,230.55],[1,2.88,81.04],[2,2.86,81.04]],"batl":[[2,3.25,1.71]],"ltp":2.64,"tv":1621.77,"id":9631939}]}]}
{"op":"mcm","clk":"4296754527","pt":1632570070290,"mc":[{"id":"1.188134680","rc":[{"batl":[[0,3.05,10.76],[1,3.15,298.42],[2,3.2,19.49]],"ltp":2.64,"tv":1621.77,"id":9631939},{"batb":[[0,1.49,340.45],[1,1.48,533.31]],"batl":[[0,1.52,13.32],[1,1.53,487.01],[2,1.54,333.24]],"ltp":1.49,"tv":5888.56,"id":8681938}]}]}
{"op":"mcm","clk":"4296754597","pt":1632570070714,"mc":[{"id":"1.188134680","rc":[{"batl":[[0,3.05,13.76]],"ltp":2.64,"tv":1621.77,"id":9631939}]}]}
{"op":"mcm","clk":"4296754845","pt":1632570072200,"mc":[{"id":"1.188134680","rc":[{"batb":[[2,1.47,5153.57]],"ltp":1.49,"tv":5888.56,"id":8681938}]}]}
{"op":"mcm","clk":"4296754884","pt":1632570072408,"mc":[{"id":"1.188134680","rc":[{"batl":[[2,3.2,9.38]],"ltp":2.64,"tv":1621.77,"id":9631939}]}]}
{"op":"mcm","clk":"4296755062","pt":1632570073510,"mc":[{"id":"1.188134680","rc":[{"batl":[[0,1.52,427.32]],"ltp":1.49,"tv":5888.56,"id":8681938}]}]}
{"op":"mcm","clk":"4296755363","pt":1632570075309,"mc":[{"id":"1.188134680","rc":[{"trd":[[1.49,65.22]],"batb":[[0,1.49,310.12]],"ltp":1.49,"tv":5949.23,"id":8681938}],"tv":7571.0}]}
{"op":"mcm","clk":"4296755412","pt":1632570075579,"mc":[{"id":"1.188134680","rc":[{"batl":[[1,3.15,308.64]],"ltp":2.64,"tv":1621.77,"id":9631939},{"batb":[[2,1.47,5241.08]],"ltp":1.49,"tv":5949.23,"id":8681938}]}]}
{"op":"mcm","clk":"4296755565","pt":1632570076484,"mc":[{"id":"1.188134680","rc":[{"batl":[[0,1.52,2585.32]],"ltp":1.49,"tv":5949.23,"id":8681938}]}]}
{"op":"mcm","clk":"4296756654","pt":1632570083225,"mc":[{"id":"1.188134680","rc":[{"batb":[[2,1.47,681.94]],"ltp":1.49,"tv":5949.23,"id":8681938}]}]}
{"op":"mcm","clk":"4296756706","pt":1632570083497,"mc":[{"id":"1.188134680","rc":[{"batb":[[1,1.48,526.31]],"ltp":1.49,"tv":5949.23,"id":8681938}]}]}
{"op":"mcm","clk":"4296757046","pt":1632570085693,"mc":[{"id":"1.188134680","rc":[{"trd":[[1.52,1315.36]],"batl":[[0,1.52,1927.64]],"ltp":1.52,"tv":7264.58,"id":8681938}],"tv":8886.35}]}
{"op":"mcm","clk":"4296757410","pt":1632570087922,"mc":[{"id":"1.188134680","rc":[{"batb":[[0,2.8,8.33],[1,2.6,2.89],[2,2.58,92.92]],"batl":[[0,3.15,10.22],[1,3.9,161.43],[2,4.3,2]],"ltp":2.64,"tv":1621.77,"id":9631939},{"batb":[[0,1.47,87.51],[1,1.31,38.79],[2,1.29,500.29]],"batl":[[1,1.56,15],[2,1.62,18.88]],"ltp":1.52,"tv":7264.58,"id":8681938}]}]}
{"op":"mcm","clk":"4296757632","pt":1632570089301,"mc":[{"id":"1.188134680","rc":[{"batb":[[0,2.58,92.92],[1,2.5,2.68],[2,2.12,396.48]],"batl":[[0,3.9,161.43],[1,4.3,2],[2,4.8,2]],"ltp":2.64,"tv":1621.77,"id":9631939},{"trd":[[1.47,10]],"batb":[[0,1.52,12.86]],"batl":[[0,1.66,19.88],[1,1.72,5],[2,1.82,1.1]],"ltp":1.47,"tv":7274.58,"id":8681938}],"tv":8896.35}]}
{"op":"mcm","clk":"4296757964","pt":1632570091097,"mc":[{"id":"1.188134680","rc":[{"batl":[[0,1.63,408.64],[1,1.64,264.46],[2,1.66,19.25]],"ltp":1.47,"tv":7274.58,"id":8681938}]}]}
{"op":"mcm","clk":"4296758201","pt":1632570092313,"mc":[{"id":"1.188134680","rc":[{"batb":[[2,1.8,11.11]],"batl":[[0,4.3,2],[1,4.8,2],[2,5,2]],"ltp":2.64,"tv":1621.77,"id":9631939}]}]}
{"op":"mcm","clk":"4296758361","pt":1632570093320,"mc":[{"id":"1.188134680","rc":[{"batb":[[0,2.6,6.92],[1,2.58,92.92],[2,2.5,2.68]],"batl":[[0,2.78,507.19],[1,2.8,84.54],[2,2.82,253.6]],"ltp":2.64,"tv":1621.77,"id":9631939},{"trd":[[1.57,1.26]],"batb":[[0,1.6,9.74],[1,1.59,591.2],[2,1.58,442.77]],"batl":[[0,1.63,408.01],[2,1.66,202]],"ltp":1.57,"tv":7275.84,"id":8681938}],"tv":8897.61}]}
{"op":"mcm","clk":"4296758530","pt":1632570094325,"mc":[{"id":"1.188134680","rc":[{"batb":[[0,2.6,187.68],[1,2.58,183.3],[2,2.56,90.38]],"batl":[[0,2.78,169.06],[2,2.82,84.54]],"ltp":2.64,"tv":1621.77,"id":9631939},{"batl":[[1,1.64,282.75],[2,1.65,15]],"ltp":1.57,"tv":7275.84,"id":8681938}]}]}
{"op":"mcm","clk":"4296758856","pt":1632570096331,"mc":[{"id":"1.188134680","rc":[{"batb":[[0,2.6,180.76]],"batl":[[0,2.76,3],[1,2.78,169.06],[2,2.8,84.54]],"ltp":2.64,"tv":1621.77,"id":9631939},{"batb":[[0,1.59,591.2],[1,1.58,442.77],[2,1.57,526.51]],"ltp":1.57,"tv":7275.84,"id":8681938}]}]}
{"op":"mcm","clk":"4296758968","pt":1632570097016,"mc":[{"id":"1.188134680","rc":[{"batl":[[0,1.63,575.01]],"ltp":1.57,"tv":7275.84,"id":8681938}]}]}
{"op":"mcm","clk":"4296759140","pt":1632570098138,"mc":[{"id":"1.188134680","rc":[{"batl":[[0,1.63,408.01]],"ltp":1.57,"tv":7275.84,"id":8681938}]}]}
{"op":"mcm","clk":"4296759317","pt":1632570099093,"mc":[{"id":"1.188134680","rc":[{"batb":[[0,2.6,187.68]],"batl":[[0,2.76,40.98]],"ltp":2.64,"tv":1621.77,"id":9631939},{"batb":[[0,1.62,2.19],[1,1.6,41.85],[2,1.59,591.2]],"ltp":1.57,"tv":7275.84,"id":8681938}]}]}
{"op":"mcm","clk":"4296759413","pt":1632570099728,"mc":[{"id":"1.188134680","rc":[{"batl":[[0,2.76,3]],"ltp":2.64,"tv":1621.77,"id":9631939}]}]}
{"op":"mcm","clk":"4296759673","pt":1632570101211,"mc":[{"id":"1.188134680","rc":[{"trd":[[1.62,4.38]],"batb":[[0,1.6,41.85],[1,1.59,591.2],[2,1.58,442.77]],"batl":[[0,1.62,1548.81],[1,1.63,408.01],[2,1.64,282.75]],"ltp":1.62,"tv":7280.23,"id":8681938}],"tv":8902.0}]}
{"op":"mcm","clk":"4296759841","pt":1632570102210,"mc":[{"id":"1.188134680","rc":[{"batl":[[0,1.62,1588.35]],"ltp":1.62,"tv":7280.23,"id":8681938}]}]}
{"op":"mcm","clk":"4296759953","pt":1632570102965,"mc":[{"id":"1.188134680","rc":[{"trd":[[1.6,51.43]],"batb":[[0,1.6,16.13]],"ltp":1.6,"tv":7331.66,"id":8681938}],"tv":8953.43}]}
{"op":"mcm","clk":"4296760309","pt":1632570105034,"mc":[{"id":"1.188134680","rc":[{"trd":[[1.6,51.51]],"batb":[[0,1.59,591.2],[1,1.58,442.77],[2,1.57,526.51]],"ltp":1.6,"tv":7331.74,"id":8681938}],"tv":8953.51}]}
{"op":"mcm","clk":"4296760503","pt":1632570106159,"mc":[{"id":"1.188134680","rc":[{"batl":[[0,2.72,29.34],[1,2.76,3],[2,2.78,169.06]],"ltp":2.64,"tv":1621.77,"id":9631939}]}]}
{"op":"mcm","clk":"4296760555","pt":1632570106422,"mc":[{"id":"1.188134680","rc":[{"batl":[[0,2.76,3],[1,2.78,169.06],[2,2.8,84.54]],"ltp":2.64,"tv":1621.77,"id":9631939}]}]}
{"op":"mcm","clk":"4296761061","pt":1632570109245,"mc":[{"id":"1.188134680","rc":[{"batb":[[0,2.54,9.74],[1,2.3,2.88],[2,2.24,140.15]],"batl":[[0,2.82,11.11],[1,3.45,184.03],[2,4.6,2]],"ltp":2.64,"tv":1621.77,"id":9631939},{"batb":[[0,1.6,30.51],[1,1.55,80.9],[2,1.46,10.24]],"batl":[[1,1.65,15],[2,1.76,15.65]],"ltp":1.6,"tv":7331.74,"id":8681938}]}]}
{"op":"mcm","clk":"4296761249","pt":1632570110353,"mc":[{"id":"1.188134680","rc":[{"batb":[[0,2.3,2.88],[1,2.24,140.15],[2,2.22,3.34]],"batl":[[0,3.45,184.03],[1,4.6,2],[2,4.8,2]],"ltp":2.64,"tv":1621.77,"id":9631939},{"batb":[[0,1.46,10.24],[1,1.3,478.81],[2,1.28,46.66]],"batl":[[0,1.62,39.54],[1,1.76,15.65],[2,1.77,16.5]],"ltp":1.6,"tv":7331.74,"id":8681938}]}]}
{"op":"mcm","clk":"4296761420","pt":1632570111164,"mc":[{"id":"1.188134680","rc":[{"batl":[[0,1.76,15.65],[1,1.77,16.5],[2,1.8,15.12]],"ltp":1.6,"tv":7331.74,"id":8681938}]}]}
{"op":"mcm","clk":"4296761590","pt":1632570112141,"mc":[{"id":"1.188134680","rc":[{"batb":[[0,2.24,140.15],[1,2.22,3.34],[2,1.92,403.42]],"ltp":2.64,"tv":1621.77,"id":9631939},{"batb":[[1,1.32,515.46],[2,1.31,700.14]],"batl":[[0,1.79,247.7],[1,1.8,15.12],[2,1.81,397.83]],"ltp":1.6,"tv":7331.74,"id":8681938}]}]}
{"op":"mcm","clk":"4296761784","pt":1632570113230,"mc":[{"id":"1.188134680","rc":[{"batl":[[0,1.79,247.79]],"ltp":1.6,"tv":7331.74,"id":8681938}]}]}
{"op":"mcm","clk":"4296762154","pt":1632570115323,"mc":[{"id":"1.188134680","rc":[{"batb":[[0,2.26,4],[1,2.24,143.15],[2,2.22,7.34]],"ltp":2.64,"tv":1621.77,"id":9631939},{"batl":[[0,1.79,251.7],[1,1.8,20.12]],"ltp":1.6,"tv":7331.74,"id":8681938}]}]}
{"op":"mcm","clk":"4296762619","pt":1632570118153,"mc":[{"id":"1.188134680","rc":[{"batb":[[0,2.3,3.08],[1,2.26,4],[2,2.24,143.15]],"ltp":2.64,"tv":1621.77,"id":9631939},{"batl":[[0,1.76,17.4],[1,1.77,5],[2,1.79,251.07]],"ltp":1.6,"tv":7331.74,"id":8681938}]}]}
{"op":"mcm","clk":"4296762815","pt":1632570119268,"mc":[{"id":"1.188134680","rc":[{"batb":[[0,2.26,4],[1,2.24,143.15],[2,2.22,7.34]],"ltp":2.64,"tv":1621.77,"id":9631939},{"batb":[[1,1.3,478.81],[2,1.28,46.66]],"batl":[[0,1.77,5.63],[1,1.79,251.07],[2,1.8,20.12]],"ltp":1.6,"tv":7331.74,"id":8681938}]}]}
{"op":"mcm","clk":"4296763002","pt":1632570120129,"mc":[{"id":"1.188134680","rc":[{"batl":[[0,1.59,10.71],[1,1.77,5.63],[2,1.79,251.07]],"ltp":1.6,"tv":7331.74,"id":8681938}]}]}
{"op":"mcm","clk":"4296763107","pt":1632570120765,"mc":[{"id":"1.188134680","rc":[{"batl":[[0,4.6,2],[1,4.8,2],[2,5,2]],"ltp":2.64,"tv":1621.77,"id":9631939}]}]}
{"op":"mcm","clk":"4296763410","pt":1632570122329,"mc":[{"id":"1.188134680","rc":[{"batb":[[0,2.24,140.15],[1,2.22,434.08],[2,2.2,418.08]],"batl":[[0,2.36,7.1],[1,2.4,398.44],[2,2.42,386.72]],"ltp":2.64,"tv":1621.77,"id":9631939},{"trd":[[1.59,24.74],[1.73,391.14]],"batb":[[0,1.74,249.22],[1,1.73,7646.94],[2,1.72,445]],"batl":[[0,1.78,18.02],[1,1.79,247.07],[2,1.8,15.12]],"ltp":1.73,"tv":7354.42,"id":8681938}],"tv":8976.19}]}
{"op":"mcm","clk":"4296763602","pt":1632570123337,"mc":[{"id":"1.188134680","rc":[{"batb":[[0,2.26,11.9],[1,2.24,140.15],[2,2.22,434.08]],"ltp":2.64,"tv":1621.77,"id":9631939},{"batb":[[1,1.73,607.8],[2,1.72,598.04]],"batl":[[0,1.78,34.87],[2,1.8,30.12]],"ltp":1.73,"tv":7354.42,"id":8681938}]}]}
{"op":"mcm","clk":"4296763901","pt":1632570125137,"mc":[{"id":"1.188134680","rc":[{"batl":[[0,2.36,11.1],[1,2.38,4],[2,2.4,398.44]],"ltp":2.64,"tv":1621.77,"id":9631939},{"batb":[[0,1.74,253.22],[1,1.73,612.8]],"ltp":1.73,"tv":7354.42,"id":8681938}]}]}
{"op":"mcm","clk":"4296764000","pt":1632570125561,"mc":[{"id":"1.188134680","rc":[{"batl":[[0,1.78,236.87]],"ltp":1.73,"tv":7354.42,"id":8681938}]}]}
{"op":"mcm","clk":"4296764309","pt":1632570127276,"mc":[{"id":"1.188134680","rc":[{"batl":[[0,2.34,89.42],[1,2.36,11.1],[2,2.38,4]],"ltp":2.64,"tv":1621.77,"id":9631939},{"batb":[[0,1.75,51.2],[1,1.74,253.22],[2,1.73,612.8]],"ltp":1.73,"tv":7354.42,"id":8681938}]}]}
{"op":"mcm","clk":"4296764513","pt":1632570128342,"mc":[{"id":"1.188134680","rc":[{"batl":[[0,2.34,29.81]],"ltp":2.64,"tv":1621.77,"id":9631939},{"trd":[[1.75,4.57]],"batb":[[0,1.75,51.11]],"ltp":1.75,"tv":7354.61,"id":8681938}],"tv":8976.38}]}
{"op":"mcm","clk":"4296764651","pt":1632570129184,"mc":[{"id":"1.188134680","rc":[{"batb":[[0,1.74,253.22],[1,1.73,612.8],[2,1.72,598.04]],"ltp":1.75,"tv":7354.61,"id":8681938}]}]}
{"op":"mcm","clk":"4296765000","pt":1632570131273,"mc":[{"id":"1.188134680","rc":[{"trd":[[1.74,15.85]],"batb":[[0,1.74,253.18]],"ltp":1.74,"tv":7354.69,"id":8681938}],"tv":8976.46}]}
{"op":"mcm","clk":"4296765085","pt":1632570131778,"mc":[{"id":"1.188134680","rc":[{"trd":[[1.78,46.38]],"batl":[[0,1.78,228.42]],"ltp":1.78,"tv":7371.59,"id":8681938}],"tv":8993.36}]}
{"op":"mcm","clk":"4296765346","pt":1632570133170,"mc":[{"id":"1.188134680","rc":[{"batb":[[0,1.75,37.02],[1,1.74,253.18],[2,1.73,612.8]],"ltp":1.78,"tv":7371.59,"id":8681938}]}]}
{"op":"mcm","clk":"4296765471","pt":1632570133963,"mc":[{"id":"1.188134680","rc":[{"batb":[[2,1.73,5]],"ltp":1.78,"tv":7371.59,"id":8681938}]}]}
{"op":"mcm","clk":"4296765865","pt":1632570136370,"mc":[{"id":"1.188134680","rc":[{"batb":[[1,2.14,3.32],[2,2.1,162]],"batl":[[0,2.48,12.32],[1,2.66,158.77],[2,2.68,159.18]],"ltp":2.64,"tv":1621.77,"id":9631939},{"trd":[[1.78,53.9]],"batb":[[0,1.74,249.18],[1,1.72,445],[2,1.6,236.68]],"batl":[[0,1.78,198.24],[2,1.8,15]],"ltp":1.78,"tv":7379.11,"id":8681938}],"tv":9000.88}]}
{"op":"mcm","clk":"4296766021","pt":1632570137277,"mc":[{"id":"1.188134680","rc":[{"batb":[[0,2.1,162],[1,2.08,149.04],[2,2.06,174.33]],"batl":[[0,2.66,158.77],[1,2.68,159.18],[2,2.86,2.25]],"ltp":2.64,"tv":1621.77,"id":9631939},{"batb":[[0,1.6,236.68],[1,1.59,329.23],[2,1.54,250.79]],"batl":[[0,1.84,3.11],[1,1.88,14.79],[2,1.92,236.78]],"ltp":1.78,"tv":7379.11,"id":8681938}]}]}
{"op":"mcm","clk":"4296766187","pt":1632570138282,"mc":[{"id":"1.188134680","rc":[{"batb":[[0,1.78,7.05],[1,1.6,236.68],[2,1.59,329.23]],"ltp":1.78,"tv":7379.11,"id":8681938}]}]}
{"op":"mcm","clk":"4296766329","pt":1632570139261,"mc":[{"id":"1.188134680","rc":[{"trd":[[2.3,108.61]],"batb":[[0,2.12,3.79],[1,2.1,162],[2,2.08,149.04]],"ltp":2.3,"tv":1624.34,"id":9631939},{"trd":[[1.78,61.5]],"batb":[[0,1.78,1.58]],"ltp":1.78,"tv":7386.71,"id":8681938}],"tv":9011.06}]}
{"op":"mcm","clk":"4296766512","pt":1632570140373,"mc":[{"id":"1.188134680","rc":[{"batl":[[2,1.89,349.45]],"ltp":1.78,"tv":7386.71,"id":8681938}]}]}
{"op":"mcm","clk":"4296766525","pt":1632570140479,"mc":[{"id":"1.188134680","rc":[{"batb":[[0,2.18,3],[1,2.16,4],[2,2.12,3.79]],"ltp":2.3,"tv":1624.34,"id":9631939},{"batl":[[0,1.84,7.11]],"ltp":1.78,"tv":7386.71,"id":8681938}]}]}
{"op":"mcm","clk":"4296767086","pt":1632570143891,"mc":[{"id":"1.188134680","rc":[{"batl":[[0,2.86,2.25],[1,3,217.75],[2,3.15,2.3]],"ltp":2.3,"tv":1624.34,"id":9631939},{"batb":[[1,1.54,250.79],[2,1.47,28.67]],"ltp":1.78,"tv":7386.71,"id":8681938}]}]}
{"op":"mcm","clk":"4296767271","pt":1632570144991,"mc":[{"id":"1.188134680","rc":[{"batl":[[1,3.15,2.3],[2,4.6,2]],"ltp":2.3,"tv":1624.34,"id":9631939}]}]}
{"op":"mcm","clk":"4296767509","pt":1632570146373,"mc":[{"id":"1.188134680","rc":[{"batb":[[0,2.12,3.79],[1,2.1,162],[2,2.08,149.04]],"batl":[[0,2.2,17.03],[1,2.34,12.82],[2,2.86,2.25]],"ltp":2.3,"tv":1624.34,"id":9631939},{"trd":[[1.82,0.94]],"batb":[[0,1.82,5638.57],[1,1.79,534.22],[2,1.78,1297.84]],"batl":[[0,1.84,2.64],[2,1.89,358.46]],"ltp":1.82,"tv":7387.65,"id":8681938}],"tv":9012.0}]}
{"op":"mcm","clk":"4296767664","pt":1632570147279,"mc":[{"id":"1.188134680","rc":[{"batl":[[2,2.44,1.71]],"ltp":2.3,"tv":1624.34,"id":9631939},{"batb":[[0,1.82,816.15],[1,1.81,130.21],[2,1.8,381.87]],"batl":[[1,1.88,30.75]],"ltp":1.82,"tv":7387.65,"id":8681938}]}]}
{"op":"mcm","clk":"4296767854","pt":1632570148292,"mc":[{"id":"1.188134680","rc":[{"batb":[[1,2.1,175.63]],"batl":[[1,2.32,13.05],[2,2.34,12.82]],"ltp":2.3,"tv":1624.34,"id":9631939}]}]}
{"op":"mcm","clk":"4296768058","pt":1632570149398,"mc":[{"id":"1.188134680","rc":[{"batb":[[0,1.83,4],[1,1.82,821.15],[2,1.81,130.21]],"ltp":1.82,"tv":7387.65,"id":8681938}]}]}
{"op":"mcm","clk":"4296768395","pt":1632570151305,"mc":[{"id":"1.188134680","rc":[{"trd":[[1.83,689.92]],"batb":[[0,1.83,1.81]],"ltp":1.83,"tv":7392.04,"id":8681938}],"tv":9016.38}]}
{"op":"mcm","clk":"4296768567","pt":1632570152214,"mc":[{"id":"1.188134680","rc":[{"trd":[[2.18,2.77]],"batl":[[0,2.18,22.96],[1,2.2,17.03],[2,2.32,13.05]],"ltp":2.18,"tv":1626.57,"id":9631939},{"trd":[[1.84,552.03]],"batl":[[0,1.88,30.75],[1,1.89,358.46],[2,1.9,15]],"ltp":1.84,"tv":7394.68,"id":8681938}],"tv":9021.25}]}
{"op":"mcm","clk":"4296768762","pt":1632570153379,"mc":[{"id":"1.188134680","rc":[{"trd":[[2.18,2.8]],"batl":[[0,2.18,22.93]],"ltp":2.18,"tv":1626.6,"id":9631939},{"trd":[[1.84,552.07]],"ltp":1.84,"tv":7394.72,"id":8681938}],"tv":9021.32}]}
{"op":"mcm","clk":"4296768805","pt":1632570153691,"mc":[{"id":"1.188134680","rc":[{"batb":[[1,2.1,179.27]],"batl":[[0,2.2,17.03],[1,2.32,13.05],[2,2.34,12.82]],"ltp":2.18,"tv":1626.6,"id":9631939},{"batl":[[2,1.9,30.95]],"ltp":1.84,"tv":7394.72,"id":8681938}]}]}
{"op":"mcm","clk":"4296769101","pt":1632570155312,"mc":[{"id":"1.188134680","rc":[{"batb":[[0,1.84,9.05],[1,1.83,1.81],[2,1.82,821.15]],"ltp":1.84,"tv":7394.72,"id":8681938}]}]}
{"op":"mcm","clk":"4296769187","pt":1632570155690,"mc":[{"id":"1.188134680","rc":[{"batb":[[0,1.83,1.81],[1,1.82,821.15],[2,1.81,130.21]],"ltp":1.84,"tv":7394.72,"id":8681938}]}]}
{"op":"mcm","clk":"4296769449","pt":1632570157099,"mc":[{"id":"1.188134680","rc":[{"batb":[[2,2.08,153.6]],"ltp":2.18,"tv":1626.6,"id":9631939}]}]}
{"op":"mcm","clk":"4296769646","pt":1632570158211,"mc":[{"id":"1.188134680","rc":[{"batl":[[0,2.18,24.96],[1,2.2,17.03],[2,2.32,13.05]],"ltp":2.18,"tv":1626.6,"id":9631939},{"batb":[[1,1.82,373.61]],"ltp":1.84,"tv":7394.72,"id":8681938}]}]}
{"op":"mcm","clk":"4296769869","pt":1632570159376,"mc":[{"id":"1.188134680","rc":[{"trd":[[2.18,4.78]],"batl":[[0,2.18,22.98]],"ltp":2.18,"tv":1628.58,"id":9631939},{"trd":[[1.84,554.42]],"ltp":1.84,"tv":7397.07,"id":8681938}],"tv":9025.65}]}
{"op":"mcm","clk":"4296770343","pt":1632570162295,"mc":[{"id":"1.188134680","rc":[{"batb":[[0,1.84,9.05],[1,1.83,1.81],[2,1.82,368.61]],"ltp":1.84,"tv":7397.07,"id":8681938}]}]}
{"op":"mcm","clk":"4296770688","pt":1632570164205,"mc":[{"id":"1.188134680","rc":[{"batb":[[2,2.08,4.56]],"batl":[[0,2.32,13.05],[1,2.38,170.12],[2,2.4,169.39]],"ltp":2.18,"tv":1628.58,"id":9631939},{"batb":[[0,1.83,1.81],[1,1.82,368.61],[2,1.81,130.21]],"batl":[[0,1.88,87.79],[1,1.89,349.45]],"ltp":1.84,"tv":7397.07,"id":8681938}]}]}
{"op":"mcm","clk":"4296770873","pt":1632570165320,"mc":[{"id":"1.188134680","rc":[{"batb":[[0,2.04,176.8],[1,2.02,198.1],[2,2,232.71]],"batl":[[0,2.38,170.12],[1,2.4,169.39],[2,2.48,3.24]],"ltp":2.18,"tv":1628.58,"id":9631939},{"batb":[[0,1.78,1.58],[1,1.73,17.76],[2,1.72,223.99]],"batl":[[0,1.93,13.07],[1,1.97,194.09],[2,1.98,213.47]],"ltp":1.84,"tv":7397.07,"id":8681938}]}]}
{"op":"mcm","clk":"4296770925","pt":1632570165602,"mc":[{"id":"1.188134680","rc":[{"batl":[[0,2.38,166.87]],"ltp":2.18,"tv":1628.58,"id":9631939},{"batb":[[1,1.72,223.99],[2,1.71,295.08]],"ltp":1.84,"tv":7397.07,"id":8681938}]}]}
{"op":"mcm","clk":"4296771345","pt":1632570168288,"mc":[{"id":"1.188134680","rc":[{"batb":[[0,2.06,4.08],[1,2.04,176.8],[2,2.02,198.1]],"batl":[[0,2.48,3.24],[1,2.68,3],[2,2.82,235.94]],"ltp":2.18,"tv":1628.58,"id":9631939},{"batb":[[1,1.69,162.17],[2,1.68,17.86]],"batl":[[0,1.9,4],[1,1.93,13.07],[2,1.94,292.08]],"ltp":1.84,"tv":7397.07,"id":8681938}]}]}
{"op":"mcm","clk":"4296771509","pt":1632570169296,"mc":[{"id":"1.188134680","rc":[{"batb":[[0,2.08,4],[1,2.06,8.08],[2,2.04,181.8]],"ltp":2.18,"tv":1628.58,"id":9631939},{"batl":[[1,1.91,5],[2,1.93,17.07]],"ltp":1.84,"tv":7397.07,"id":8681938}]}]}
{"op":"mcm","clk":"4296771688","pt":1632570170300,"mc":[{"id":"1.188134680","rc":[{"trd":[[2.08,98.16]],"batb":[[0,2.06,8.08],[1,2.04,181.8],[2,2.02,198.1]],"batl":[[0,2.14,2811.44],[1,2.16,135.09],[2,2.24,13.39]],"ltp":2.08,"tv":1641.17,"id":9631939},{"trd":[[1.9,791.91],[1.91,214.7]],"batb":[[0,1.9,1232.84],[1,1.89,618.42],[2,1.88,2589.61]],"batl":[[0,1.93,17.07],[1,1.94,292.08],[2,1.96,296.93]],"ltp":1.91,"tv":7410.07,"id":8681938}],"tv":9051.24}]}
{"op":"mcm","clk":"4296771865","pt":1632570171312,"mc":[{"id":"1.188134680","rc":[{"trd":[[2.08,99.64]],"batb":[[0,2.1,3.26],[1,2.06,4.08],[2,2.04,176.8]],"batl":[[0,2.16,135.09],[1,2.24,13.39],[2,2.36,1.71]],"ltp":2.08,"tv":1642.65,"id":9631939},{"batb":[[0,1.9,247.36],[1,1.89,123.68],[2,1.88,517.91]],"batl":[[0,1.93,13.07],[2,1.96,312.24]],"ltp":1.91,"tv":7410.07,"id":8681938}],"tv":9052.72}]}
{"op":"mcm","clk":"4296771982","pt":1632570171912,"mc":[{"id":"1.188134680","rc":[{"batb":[[0,2.06,4.08],[1,2.04,176.8],[2,2.02,198.1]],"ltp":2.08,"tv":1642.65,"id":9631939}]}]}
{"op":"mcm","clk":"4296772193","pt":1632570173013,"mc":[{"id":"1.188134680","rc":[{"batb":[[1,2.04,191.22]],"batl":[[1,2.22,13.58],[2,2.24,13.39]],"ltp":2.08,"tv":1642.65,"id":9631939},{"trd":[[1.9,796.29]],"batb":[[0,1.9,245.17]],"ltp":1.9,"tv":7414.45,"id":8681938}],"tv":9057.1}]}
{"op":"mcm","clk":"4296772273","pt":1632570173423,"mc":[{"id":"1.188134680","rc":[{"batl":[[0,1.93,13.38]],"ltp":1.9,"tv":7414.45,"id":8681938}]}]}
{"op":"mcm","clk":"4296772568","pt":1632570175216,"mc":[{"id":"1.188134680","rc":[{"batl":[[1,2.18,98.45],[2,2.22,13.58]],"ltp":2.08,"tv":1642.65,"id":9631939}]}]}
{"op":"mcm","clk":"4296772661","pt":1632570175909,"mc":[{"id":"1.188134680","rc":[{"batl":[[0,2.14,35.06],[1,2.16,275.4]],"ltp":2.08,"tv":1642.65,"id":9631939},{"batb":[[0,1.9,271.2]],"ltp":1.9,"tv":7414.45,"id":8681938}]}]}
{"op":"mcm","clk":"4296772756","pt":1632570176526,"mc":[{"id":"1.188134680","rc":[{"batl":[[0,1.93,109.38]],"ltp":1.9,"tv":7414.45,"id":8681938}]}]}
{"op":"mcm","clk":"4296773066","pt":1632570178315,"mc":[{"id":"1.188134680","rc":[{"batl":[[2,2.22,204.81]],"ltp":2.08,"tv":1642.65,"id":9631939},{"trd":[[1.9,796.37]],"batb":[[0,1.9,271.16]],"ltp":1.9,"tv":7414.53,"id":8681938}],"tv":9057.18}]}
{"op":"mcm","clk":"4296773278","pt":1632570179514,"mc":[{"id":"1.188134680","rc":[{"trd":[[1.9,804.19]],"batb":[[0,1.9,267.25]],"batl":[[0,1.93,209.38]],"ltp":1.9,"tv":7422.35,"id":8681938}],"tv":9065.0}]}
{"op":"mcm","clk":"4296773470","pt":1632570180711,"mc":[{"id":"1.188134680","rc":[{"trd":[[1.91,215.32],[1.93,39.16]],"batl":[[0,1.93,207]],"ltp":1.93,"tv":7427.1,"id":8681938}],"tv":9069.76}]}
{"op":"mcm","clk":"4296773749","pt":1632570182254,"mc":[{"id":"1.188134680","rc":[{"batl":[[1,2.16,135.09]],"ltp":2.08,"tv":1642.65,"id":9631939},{"batl":[[0,1.92,8.45],[1,1.93,207],[2,1.94,292.08]],"ltp":1.93,"tv":7427.1,"id":8681938}]}]}
{"op":"mcm","clk":"4296774053","pt":1632570183924,"mc":[{"id":"1.188134680","rc":[{"batb":[[0,2.06,4.27]],"batl":[[0,2.16,135.09],[1,2.22,204.81],[2,2.24,174.52]],"ltp":2.08,"tv":1642.65,"id":9631939}]}]}
{"op":"mcm","clk":"4296774319","pt":1632570185525,"mc":[{"id":"1.188134680","rc":[{"batl":[[1,1.93,331]],"ltp":1.93,"tv":7427.1,"id":8681938}]}]}
{"op":"mcm","clk":"4296774610","pt":1632570187236,"mc":[{"id":"1.188134680","rc":[{"batb":[[0,2.06,11.6]],"batl":[[0,2.12,14.24],[1,2.14,3],[2,2.16,275.4]],"ltp":2.08,"tv":1642.65,"id":9631939},{"trd":[[1.9,804.53]],"batb":[[0,1.9,267.08]],"ltp":1.9,"tv":7427.44,"id":8681938}],"tv":9070.1}]}
{"op":"mcm","clk":"4296775100","pt":1632570190136,"mc":[{"id":"1.188134680","rc":[{"batl":[[1,2.14,38.06]],"ltp":2.08,"tv":1642.65,"id":9631939}]}]}
{"op":"mcm","clk":"4296775144","pt":1632570190417,"mc":[{"id":"1.188134680","rc":[{"batl":[[1,2.14,3]],"ltp":2.08,"tv":1642.65,"id":9631939}]}]}
{"op":"mcm","clk":"4296775685","pt":1632570193725,"mc":[{"id":"1.188134680","rc":[{"batl":[[0,2.12,49.3],[2,2.16,135.09]],"ltp":2.08,"tv":1642.65,"id":9631939}]}]}
{"op":"mcm","clk":"4296776549","pt":1632570198986,"mc":[{"id":"1.188134680","rc":[{"batl":[[0,2.12,14.24]],"ltp":2.08,"tv":1642.65,"id":9631939},{"batb":[[0,1.9,241.05]],"ltp":1.9,"tv":7427.44,"id":8681938}]}]}
{"op":"mcm","clk":"4296776783","pt":1632570200366,"mc":[{"id":"1.188134680","rc":[{"batl":[[1,2.16,135.09],[2,2.22,204.81]],"ltp":2.08,"tv":1642.65,"id":9631939},{"trd":[[1.9,810.17]],"batb":[[0,1.9,238.23]],"ltp":1.9,"tv":7433.08,"id":8681938}],"tv":9075.73}]}
{"op":"mcm","clk":"4296777057","pt":1632570201968,"mc":[{"id":"1.188134680","rc":[{"trd":[[1.9,810.51]],"batb":[[0,1.9,238.06]],"ltp":1.9,"tv":7433.42,"id":8681938}],"tv":9076.07}]}
{"op":"mcm","clk":"4296777213","pt":1632570202868,"mc":[{"id":"1.188134680","rc":[{"trd":[[1.9,811.13]],"batb":[[0,1.9,237.75]],"ltp":1.9,"tv":7434.04,"id":8681938}],"tv":9076.69}]}
{"op":"mcm","clk":"4296777921","pt":1632570207285,"mc":[{"id":"1.188134680","rc":[{"batb":[[0,2.04,191.22],[1,1.99,4],[2,1.98,4.37]],"batl":[[0,2.22,201.56],[1,2.24,161.13],[2,2.26,3.29]],"ltp":2.08,"tv":1642.65,"id":9631939},{"batb":[[0,1.86,119.72],[1,1.83,16.56],[2,1.82,264.37]],"batl":[[1,1.93,320],[2,1.97,15]],"ltp":1.9,"tv":7434.04,"id":8681938}]}]}
{"op":"mcm","clk":"4296778096","pt":1632570208260,"mc":[{"id":"1.188134680","rc":[{"batb":[[0,1.95,12.28],[1,1.9,338.2],[2,1.89,258.3]],"batl":[[0,2.22,187.98]],"ltp":2.08,"tv":1642.65,"id":9631939},{"batb":[[0,1.82,198.12],[1,1.81,381.65],[2,1.8,13.33]],"batl":[[1,2,2],[2,2.06,3.92]],"ltp":1.9,"tv":7434.04,"id":8681938}]}]}
{"op":"mcm","clk":"4296778435","pt":1632570210283,"mc":[{"id":"1.188134680","rc":[{"batl":[[0,2.2,477.9],[1,2.22,187.98],[2,2.24,161.13]],"ltp":2.08,"tv":1642.65,"id":9631939},{"batb":[[0,1.82,520.66],[2,1.8,395.15]],"ltp":1.9,"tv":7434.04,"id":8681938}]}]}
{"op":"mcm","clk":"4296778605","pt":1632570211194,"mc":[{"id":"1.188134680","rc":[{"batl":[[0,2.22,187.98],[1,2.24,161.13],[2,2.26,3.29]],"ltp":2.08,"tv":1642.65,"id":9631939},{"batb":[[0,1.83,17.03],[1,1.82,520.66],[2,1.81,381.65]],"ltp":1.9,"tv":7434.04,"id":8681938}]}]}
{"op":"mcm","clk":"4296778748","pt":1632570211988,"mc":[{"id":"1.188134680","rc":[{"batb":[[1,1.9,125.61],[2,1.77,410.58]],"ltp":2.08,"tv":1642.65,"id":9631939},{"batb":[[0,1.82,520.66],[1,1.81,381.65],[2,1.8,395.15]],"batl":[[0,1.91,10],[1,1.92,8.45],[2,2,2]],"ltp":1.9,"tv":7434.04,"id":8681938}]}]}
{"op":"mcm","clk":"4296779150","pt":1632570214298,"mc":[{"id":"1.188134680","rc":[{"batl":[[0,2.12,40],[1,2.22,187.98],[2,2.24,161.13]],"ltp":2.08,"tv":1642.65,"id":9631939}]}]}
{"op":"mcm","clk":"4296779328","pt":1632570215258,"mc":[{"id":"1.188134680","rc":[{"trd":[[2.12,57.64]],"batl":[[0,2.2,6.82],[2,2.24,244.61]],"ltp":2.12,"tv":1682.65,"id":9631939},{"trd":[[1.89,746.46]],"batl":[[0,1.88,580.45],[1,1.89,20.89],[2,1.9,326.85]],"ltp":1.89,"tv":7478.91,"id":8681938}],"tv":9161.56}]}
{"op":"mcm","clk":"4296779532","pt":1632570216327,"mc":[{"id":"1.188134680","rc":[{"batb":[[0,2.12,161.24],[1,2.08,13.88],[2,1.98,196.52]],"batl":[[0,2.2,34.8]],"ltp":2.12,"tv":1682.65,"id":9631939},{"batb":[[0,1.83,35.82],[1,1.82,520.66],[2,1.81,381.65]],"ltp":1.89,"tv":7478.91,"id":8681938}]}]}
{"op":"mcm","clk":"4296779703","pt":1632570217180,"mc":[{"id":"1.188134680","rc":[{"batb":[[2,2.04,3]],"ltp":2.12,"tv":1682.65,"id":9631939}]}]}
{"op":"mcm","clk":"4296780040","pt":1632570219080,"mc":[{"id":"1.188134680","rc":[{"trd":[[1.83,694.31]],"batb":[[0,1.82,520.66],[1,1.81,381.65],[2,1.8,395.15]],"ltp":1.83,"tv":7483.29,"id":8681938}],"tv":9165.95}]}
{"op":"mcm","clk":"4296780174","pt":1632570219885,"mc":[{"id":"1.188134680","rc":[{"batb":[[1,2.04,3],[2,2.02,3]],"ltp":2.12,"tv":1682.65,"id":9631939}]}]}
{"op":"mcm","clk":"4296780551","pt":1632570222207,"mc":[{"id":"1.188134680","rc":[{"batb":[[1,2.06,3.41],[2,2.04,7.12]],"batl":[[1,2.22,191.23]],"ltp":2.12,"tv":1682.65,"id":9631939},{"batb":[[0,1.84,33.63],[1,1.82,535.8],[2,1.81,381.65]],"ltp":1.83,"tv":7483.29,"id":8681938}]}]}
{"op":"mcm","clk":"4296780705","pt":1632570223118,"mc":[{"id":"1.188134680","rc":[{"batb":[[1,2.1,13.63],[2,2.06,3.41]],"ltp":2.12,"tv":1682.65,"id":9631939},{"batb":[[0,1.82,535.8],[1,1.81,381.65],[2,1.8,395.15]],"ltp":1.83,"tv":7483.29,"id":8681938}]}]}
{"op":"mcm","clk":"4296780901","pt":1632570224185,"mc":[{"id":"1.188134680","rc":[{"batb":[[2,2.08,3.81]],"batl":[[2,2.24,248.34]],"ltp":2.12,"tv":1682.65,"id":9631939},{"batb":[[1,1.81,396.94]],"ltp":1.83,"tv":7483.29,"id":8681938}]}]}
{"op":"mcm","clk":"4296781313","pt":1632570226513,"mc":[{"id":"1.188134680","rc":[{"batl":[[0,1.88,245.57]],"ltp":1.83,"tv":7483.29,"id":8681938}]}]}
{"op":"mcm","clk":"4296781782","pt":1632570229337,"mc":[{"id":"1.188134680","rc":[{"batb":[[0,2.1,13.63],[1,2.04,4.12],[2,1.98,196.52]],"batl":[[0,2.26,3.29],[1,2.48,3.24],[2,2.82,235.94]],"ltp":2.12,"tv":1682.65,"id":9631939},{"batb":[[0,1.8,13.33],[1,1.78,1.58],[2,1.77,139.93]],"batl":[[0,1.91,15],[1,1.93,13.5],[2,1.95,12.5]],"ltp":1.83,"tv":7483.29,"id":8681938}]}]}
{"op":"mcm","clk":"4296781919","pt":1632570230349,"mc":[{"id":"1.188134680","rc":[{"batb":[[0,2.04,4.12],[1,1.98,196.52],[2,1.95,11.91]],"ltp":2.12,"tv":1682.65,"id":9631939},{"batl":[[0,1.96,11.62],[1,2,2],[2,2.06,3.92]],"ltp":1.83,"tv":7483.29,"id":8681938}]}]}
{"op":"mcm","clk":"4296782235","pt":1632570232214,"mc":[{"id":"1.188134680","rc":[{"batb":[[1,1.78,418.4]],"ltp":1.83,"tv":7483.29,"id":8681938}]}]}
{"op":"mcm","clk":"4296782438","pt":1632570233458,"mc":[{"id":"1.188134680","rc":[{"batl":[[0,2.12,17],[1,2.26,3.29],[2,2.48,3.24]],"ltp":2.12,"tv":1682.65,"id":9631939}]}]}
{"op":"mcm","clk":"4296782723","pt":1632570235151,"mc":[{"id":"1.188134680","rc":[{"trd":[[2.12,74.64]],"batb":[[0,2.24,6.91],[1,2.18,379.46],[2,2.04,4.12]],"batl":[[0,2.26,3.29],[1,2.32,68.28]],"ltp":2.12,"tv":1699.65,"id":9631939},{"trd":[[1.89,765.53]],"batl":[[0,1.83,273.23],[1,1.84,128.42],[2,1.85,508.34]],"ltp":1.89,"tv":7502.36,"id":8681938}],"tv":9202.02}]}
{"op":"mcm","clk":"4296782932","pt":1632570236378,"mc":[{"id":"1.188134680","rc":[{"batb":[[2,2.16,162.92]],"batl":[[2,2.34,200.86]],"ltp":2.12,"tv":1699.65,"id":9631939}]}]}
{"op":"mcm","clk":"4296783306","pt":1632570238571,"mc":[{"id":"1.188134680","rc":[{"batl":[[0,1.81,214],[1,1.83,273.23],[2,1.84,128.42]],"ltp":1.89,"tv":7502.36,"id":8681938}]}]}
{"op":"mcm","clk":"4296783532","pt":1632570239813,"mc":[{"id":"1.188134680","rc":[{"batb":[[2,2.16,149.99]],"ltp":2.12,"tv":1699.65,"id":9631939}]}]}
{"op":"mcm","clk":"4296783864","pt":1632570241743,"mc":[{"id":"1.188134680","rc":[{"batl":[[2,2.34,367.24]],"ltp":2.12,"tv":1699.65,"id":9631939}]}]}
{"op":"mcm","clk":"4296784102","pt":1632570243070,"mc":[{"id":"1.188134680","rc":[{"batb":[[1,2.18,392.17]],"batl":[[0,2.26,30.47],[1,2.3,3.15],[2,2.32,68.28]],"ltp":2.12,"tv":1699.65,"id":9631939},{"batb":[[0,1.8,43.05],[1,1.78,434.56],[2,1.77,156.3]],"batl":[[1,1.82,4.11],[2,1.83,273.23]],"ltp":1.89,"tv":7502.36,"id":8681938}]}]}
{"op":"mcm","clk":"4296784307","pt":1632570244089,"mc":[{"id":"1.188134680","rc":[{"trd":[[1.81,0.16]],"batl":[[0,1.81,213.92]],"ltp":1.81,"tv":7502.52,"id":8681938}],"tv":9202.17}]}
{"op":"mcm","clk":"4296784506","pt":1632570245157,"mc":[{"id":"1.188134680","rc":[{"trd":[[1.8,40.96]],"batb":[[0,1.8,38.94]],"ltp":1.8,"tv":7510.74,"id":8681938}],"tv":9210.4}]}
{"op":"mcm","clk":"4296784934","pt":1632570247352,"mc":[{"id":"1.188134680","rc":[{"batb":[[0,2.18,192.4],[1,2.16,149.99],[2,2.14,19.64]],"batl":[[2,2.34,266.81]],"ltp":2.12,"tv":1699.65,"id":9631939},{"batl":[[1,1.83,128.42],[2,1.84,64.21]],"ltp":1.8,"tv":7510.74,"id":8681938}]}]}
{"op":"mcm","clk":"4296785076","pt":1632570248046,"mc":[{"id":"1.188134680","rc":[{"batb":[[0,2.18,12.71],[1,2.14,19.64],[2,2.1,186.6]],"batl":[[0,2.3,3.15],[1,2.34,166.38],[2,2.36,167.11]],"ltp":2.12,"tv":1699.65,"id":9631939},{"trd":[[1.81,9.55]],"batb":[[0,1.78,1.58],[1,1.77,16.37],[2,1.76,347.24]],"batl":[[0,1.81,209.22],[1,1.85,15],[2,1.87,20]],"ltp":1.81,"tv":7520.14,"id":8681938}],"tv":9219.79}]}
{"op":"mcm","clk":"4296785298","pt":1632570249280,"mc":[{"id":"1.188134680","rc":[{"batb":[[0,2.1,169.16],[1,2.08,247.62],[2,2.06,173.24]],"ltp":2.12,"tv":1699.65,"id":9631939},{"batl":[[0,1.9,15.05],[1,1.91,167.15],[2,1.92,271.17]],"ltp":1.81,"tv":7520.14,"id":8681938}]}]}
{"op":"mcm","clk":"4296785660","pt":1632570251355,"mc":[{"id":"1.188134680","rc":[{"batl":[[0,2.3,6.15]],"ltp":2.12,"tv":1699.65,"id":9631939},{"batb":[[0,1.78,20.24],[1,1.77,20.37],[2,1.76,351.24]],"batl":[[1,1.91,397.52]],"ltp":1.81,"tv":7520.14,"id":8681938}]}]}
{"op":"mcm","clk":"4296785803","pt":1632570252157,"mc":[{"id":"1.188134680","rc":[{"batb":[[0,2.14,19.71],[1,2.1,186.1],[2,2.08,247.62]],"ltp":2.12,"tv":1699.65,"id":9631939},{"batb":[[0,1.78,5.58]],"batl":[[0,1.87,23],[1,1.9,20.8],[2,1.91,397.52]],"ltp":1.81,"tv":7520.14,"id":8681938}]}]}
{"op":"mcm","clk":"4296786027","pt":1632570253283,"mc":[{"id":"1.188134680","rc":[{"batb":[[0,2.1,169.16],[1,2.08,247.62],[2,2.06,173.24]],"batl":[[1,2.48,3.24],[2,2.82,235.94]],"ltp":2.12,"tv":1699.65,"id":9631939},{"batl":[[0,1.9,15.05],[1,1.91,397.52],[2,1.92,271.17]],"ltp":1.81,"tv":7520.14,"id":8681938}]}]}
{"op":"mcm","clk":"4296786057","pt":1632570253436,"mc":[{"id":"1.188134680","rc":[{"batb":[[2,1.76,4]],"ltp":1.81,"tv":7520.14,"id":8681938}]}]}
{"op":"mcm","clk":"4296786570","pt":1632570256357,"mc":[{"id":"1.188134680","rc":[{"batl":[[0,2.16,217.6],[1,2.18,108.8],[2,2.2,185.85]],"ltp":2.12,"tv":1699.65,"id":9631939},{"batb":[[0,1.86,7.5],[1,1.85,276.05],[2,1.83,361.58]],"batl":[[0,1.89,7.66],[1,1.9,15.05],[2,1.91,397.52]],"ltp":1.81,"tv":7520.14,"id":8681938}]}]}
{"op":"mcm","clk":"4296786739","pt":1632570257369,"mc":[{"id":"1.188134680","rc":[{"trd":[[2.12,76.99]],"batb":[[2,2.06,187.39]],"ltp":2.12,"tv":1701.99,"id":9631939},{"trd":[[1.89,768.16]],"batb":[[1,1.85,398.14]],"batl":[[0,1.89,20.9]],"ltp":1.89,"tv":7522.77,"id":8681938}],"tv":9224.77}]}
{"op":"mcm","clk":"4296787264","pt":1632570260352,"mc":[{"id":"1.188134680","rc":[{"batb":[[0,2.12,3],[1,2.1,173.16],[2,2.08,247.62]],"ltp":2.12,"tv":1701.99,"id":9631939},{"batl":[[0,1.89,24.9]],"ltp":1.89,"tv":7522.77,"id":8681938}]}]}
{"op":"mcm","clk":"4296787435","pt":1632570261331,"mc":[{"id":"1.188134680","rc":[{"batb":[[0,2.1,169.16],[1,2.08,247.62],[2,2.06,187.39]],"batl":[[0,2.16,248.35]],"ltp":2.12,"tv":1701.99,"id":9631939},{"batb":[[0,1.87,29.41],[1,1.86,7.5],[2,1.85,398.14]],"batl":[[0,1.89,128.9]],"ltp":1.89,"tv":7522.77,"id":8681938}]}]}
{"op":"mcm","clk":"4296787779","pt":1632570263360,"mc":[{"id":"1.188134680","rc":[{"trd":[[2.16,97.41]],"batl":[[0,2.16,245.67]],"ltp":2.16,"tv":1707.36,"id":9631939}],"tv":9230.13}]}
{"op":"mcm","clk":"4296787822","pt":1632570263626,"mc":[{"id":"1.188134680","rc":[{"batl":[[0,1.89,235.9]],"ltp":1.89,"tv":7522.77,"id":8681938}]}]}
{"op":"mcm","clk":"4296788064","pt":1632570264939,"mc":[{"id":"1.188134680","rc":[{"trd":[[1.87,492.17]],"batb":[[0,1.87,25.3]],"ltp":1.87,"tv":7530.99,"id":8681938}],"tv":9238.36}]}
{"op":"mcm","clk":"4296788219","pt":1632570265945,"mc":[{"id":"1.188134680","rc":[{"trd":[[1.87,512.25]],"batb":[[0,1.86,7.5],[1,1.85,398.14],[2,1.83,361.58]],"ltp":1.87,"tv":7551.07,"id":8681938}],"tv":9258.44}]}
{"op":"mcm","clk":"4296788361","pt":1632570266857,"mc":[{"id":"1.188134680","rc":[{"batb":[[0,1.85,398.14],[1,1.83,361.58],[2,1.82,15.64]],"batl":[[0,1.89,230.87]],"ltp":1.87,"tv":7551.07,"id":8681938}]}]}
{"op":"mcm","clk":"4296788529","pt":1632570267868,"mc":[{"id":"1.188134680","rc":[{"trd":[[2.16,104.69]],"batl":[[0,2.16,238.39]],"ltp":2.16,"tv":1714.64,"id":9631939},{"trd":[[1.86,144.26]],"batl":[[0,1.89,350.87]],"ltp":1.86,"tv":7559.53,"id":8681938}],"tv":9274.17}]}
{"op":"mcm","clk":"4296788923","pt":1632570270184,"mc":[{"id":"1.188134680","rc":[{"batl":[[0,2.16,246.23]],"ltp":2.16,"tv":1714.64,"id":9631939},{"batb":[[0,1.86,34.34],[1,1.85,398.14],[2,1.83,361.58]],"ltp":1.86,"tv":7559.53,"id":8681938}]}]}
{"op":"mcm","clk":"4296789670","pt":1632570274298,"mc":[{"id":"1.188134680","rc":[{"batl":[[0,1.89,335]],"ltp":1.86,"tv":7559.53,"id":8681938}]}]}
{"op":"mcm","clk":"4296789812","pt":1632570274994,"mc":[{"id":"1.188134680","rc":[{"batb":[[0,2.06,14.15],[1,2,15.05],[2,1.95,12.28]],"batl":[[0,2.26,165.17],[1,2.28,213.35],[2,2.3,6.15]],"ltp":2.16,"tv":1714.64,"id":9631939},{"batb":[[0,1.81,8.34],[1,1.8,150.25],[2,1.79,314.46]],"batl":[[1,1.94,15],[2,1.97,11.83]],"ltp":1.86,"tv":7559.53,"id":8681938}]}]}
{"op":"mcm","clk":"4296790056","pt":1632570276280,"mc":[{"id":"1.188134680","rc":[{"batb":[[0,2,15.05],[1,1.95,12.28],[2,1.94,186.22]],"ltp":2.16,"tv":1714.64,"id":9631939},{"batb":[[2,1.79,246.96]],"batl":[[0,2,15.67],[1,2.06,203.3],[2,2.08,223.98]],"ltp":1.86,"tv":7559.53,"id":8681938}]}]}
{"op":"mcm","clk":"4296790434","pt":1632570278292,"mc":[{"id":"1.188134680","rc":[{"batb":[[2,1.91,108.9]],"batl":[[0,2.22,3.25],[1,2.26,165.17],[2,2.28,213.35]],"ltp":2.16,"tv":1714.64,"id":9631939},{"batb":[[0,1.82,15.14],[1,1.81,12.34],[2,1.8,521.16]],"batl":[[1,2.06,3.92],[2,2.12,4.21]],"ltp":1.86,"tv":7559.53,"id":8681938}]}]}
{"op":"mcm","clk":"4296790589","pt":1632570279100,"mc":[{"id":"1.188134680","rc":[{"batl":[[0,2.26,165.17],[1,2.28,213.35],[2,2.3,6.15]],"ltp":2.16,"tv":1714.64,"id":9631939},{"batb":[[0,1.81,12.34],[1,1.8,521.16],[2,1.79,246.96]],"batl":[[0,1.97,13.5],[1,2,15.67],[2,2.06,3.92]],"ltp":1.86,"tv":7559.53,"id":8681938}]}]}
{"op":"mcm","clk":"4296790650","pt":1632570279467,"mc":[{"id":"1.188134680","rc":[{"batb":[[1,1.99,4],[2,1.95,12.28]],"ltp":2.16,"tv":1714.64,"id":9631939},{"batl":[[0,2,15.67],[1,2.06,3.92],[2,2.12,4.21]],"ltp":1.86,"tv":7559.53,"id":8681938}]}]}
{"op":"mcm","clk":"4296790999","pt":1632570281372,"mc":[{"id":"1.188134680","rc":[{"batb":[[0,2.16,2],[1,2.12,366.61],[2,2,15.05]],"batl":[[1,2.28,227.25]],"ltp":2.16,"tv":1714.64,"id":9631939},{"batb":[[0,1.81,8.34],[1,1.8,488.65]],"batl":[[0,1.83,26.49],[1,1.84,255.44],[2,1.85,129.72]],"ltp":1.86,"tv":7559.53,"id":8681938}]}]}
{"op":"mcm","clk":"4296791175","pt":1632570282278,"mc":[{"id":"1.188134680","rc":[{"batb":[[1,2.12,538.11],[2,2.02,247.08]],"batl":[[0,2.24,30.8],[1,2.26,165.17],[2,2.28,227.25]],"ltp":2.16,"tv":1714.64,"id":9631939},{"batb":[[0,1.82,28.81],[1,1.81,8.34],[2,1.8,488.65]],"ltp":1.86,"tv":7559.53,"id":8681938}]}]}
{"op":"mcm","clk":"4296791420","pt":1632570283607,"mc":[{"id":"1.188134680","rc":[{"batb":[[2,2.06,4]],"ltp":2.16,"tv":1714.64,"id":9631939}]}]}
{"op":"mcm","clk":"4296791771","pt":1632570285782,"mc":[{"id":"1.188134680","rc":[{"batb":[[1,2.12,524.72]],"ltp":2.16,"tv":1714.64,"id":9631939},{"trd":[[1.82,5.04]],"batb":[[0,1.82,10.25]],"ltp":1.82,"tv":7563.63,"id":8681938}],"tv":9278.27}]}
{"op":"mcm","clk":"4296792140","pt":1632570288005,"mc":[{"id":"1.188134680","rc":[{"batb":[[1,2.12,528.76],[2,2.1,147.36]],"batl":[[0,2.24,3.73]],"ltp":2.16,"tv":1714.64,"id":9631939},{"batb":[[1,1.81,23.63]],"ltp":1.82,"tv":7563.63,"id":8681938}]}]}
{"op":"mcm","clk":"4296792341","pt":1632570289301,"mc":[{"id":"1.188134680","rc":[{"batb":[[1,2.14,13.15]],"batl":[[0,2.26,3.25],[1,2.3,6.15],[2,2.34,150.36]],"ltp":2.16,"tv":1714.64,"id":9631939},{"trd":[[1.83,694.39]],"batb":[[0,1.81,8.34],[1,1.8,22.08],[2,1.78,285.54]],"batl":[[0,1.86,13.75],[1,1.88,27.29],[2,1.9,192.8]],"ltp":1.83,"tv":7563.71,"id":8681938}],"tv":9278.35}]}
{"op":"mcm","clk":"4296792507","pt":1632570290304,"mc":[{"id":"1.188134680","rc":[{"batb":[[0,2.1,147.36],[1,2.08,231.19],[2,2.06,4]],"ltp":2.16,"tv":1714.64,"id":9631939},{"batl":[[0,1.88,12.29],[1,1.9,192.8],[2,1.91,274.78]],"ltp":1.83,"tv":7563.71,"id":8681938}]}]}
{"op":"mcm","clk":"4296792632","pt":1632570291092,"mc":[{"id":"1.188134680","rc":[{"batl":[[0,2.22,30.8],[1,2.26,3.25],[2,2.3,6.15]],"ltp":2.16,"tv":1714.64,"id":9631939},{"batb":[[1,1.8,17.08]],"ltp":1.83,"tv":7563.71,"id":8681938}]}]}
{"op":"mcm","clk":"4296792820","pt":1632570292310,"mc":[{"id":"1.188134680","rc":[{"batb":[[0,2.12,4.04],[1,2.1,147.36],[2,2.08,231.19]],"batl":[[0,2.24,3.48]],"ltp":2.16,"tv":1714.64,"id":9631939},{"batb":[[0,1.81,23.63]],"ltp":1.83,"tv":7563.71,"id":8681938}]}]}
{"op":"mcm","clk":"4296793001","pt":1632570293380,"mc":[{"id":"1.188134680","rc":[{"batb":[[0,2.16,3.53],[1,2.12,4.04],[2,2.1,147.36]],"batl":[[0,2.26,3.25],[1,2.3,6.15],[2,2.48,3.24]],"ltp":2.16,"tv":1714.64,"id":9631939},{"batb":[[0,1.81,8.34],[2,1.78,5.58]],"batl":[[0,1.86,13.75],[1,1.88,12.29],[2,1.9,192.8]],"ltp":1.83,"tv":7563.71,"id":8681938}]}]}
{"op":"mcm","clk":"4296793019","pt":1632570293491,"mc":[{"id":"1.188134680","rc":[{"batb":[[0,2.12,4.04],[1,2.1,147.36],[2,2.08,231.19]],"ltp":2.16,"tv":1714.64,"id":9631939},{"batl":[[0,1.88,12.29],[1,1.9,192.8],[2,1.91,274.78]],"ltp":1.83,"tv":7563.71,"id":8681938}]}]}
{"op":"mcm","clk":"4296793480","pt":1632570296356,"mc":[{"id":"1.188134680","rc":[{"batb":[[1,2.02,184.24],[2,2,11.05]],"batl":[[0,2.16,13.62],[1,2.2,111.97],[2,2.26,3.25]],"ltp":2.16,"tv":1714.64,"id":9631939},{"trd":[[1.88,90.5]],"batb":[[0,1.88,250],[1,1.87,125],[2,1.86,498.37]],"batl":[[0,1.92,12.76],[1,1.93,290.2],[2,1.95,301.7]],"ltp":1.88,"tv":7588.29,"id":8681938}],"tv":9302.93}]}
{"op":"mcm","clk":"4296793638","pt":1632570297365,"mc":[{"id":"1.188134680","rc":[{"batb":[[1,2.04,14.42],[2,2.02,184.24]],"batl":[[2,2.24,13.47]],"ltp":2.16,"tv":1714.64,"id":9631939},{"batb":[[0,1.88,364.99],[2,1.86,484.69]],"batl":[[0,1.89,15.87],[1,1.92,12.76],[2,1.93,290.2]],"ltp":1.88,"tv":7588.29,"id":8681938}]}]}
{"op":"mcm","clk":"4296793785","pt":1632570298349,"mc":[{"id":"1.188134680","rc":[{"batl":[[2,2.24,29.72]],"ltp":2.16,"tv":1714.64,"id":9631939}]}]}
{"op":"mcm","clk":"4296793905","pt":1632570299152,"mc":[{"id":"1.188134680","rc":[{"batl":[[2,2.24,13.47]],"ltp":2.16,"tv":1714.64,"id":9631939}]}]}
{"op":"mcm","clk":"4296793986","pt":1632570299673,"mc":[{"id":"1.188134680","rc":[{"trd":[[2.12,84.91]],"batb":[[0,2.04,14.5],[1,2.02,184.24],[2,2,11.05]],"ltp":2.12,"tv":1722.56,"id":9631939}],"tv":9310.85}]}
{"op":"mcm","clk":"4296794286","pt":1632570301339,"mc":[{"id":"1.188134680","rc":[{"batl":[[2,2.26,3.25]],"ltp":2.12,"tv":1722.56,"id":9631939}]}]}
{"op":"mcm","clk":"4296794344","pt":1632570301688,"mc":[{"id":"1.188134680","rc":[{"batl":[[0,2.14,26.99],[1,2.16,13.62],[2,2.2,111.97]],"ltp":2.12,"tv":1722.56,"id":9631939},{"batb":[[0,1.88,406.69]],"ltp":1.88,"tv":7588.29,"id":8681938}]}]}
{"op":"mcm","clk":"4296795040","pt":1632570305066,"mc":[{"id":"1.188134680","rc":[{"trd":[[1.88,90.58]],"batb":[[0,1.88,406.65]],"ltp":1.88,"tv":7588.37,"id":8681938}],"tv":9310.93}]}
{"op":"mcm","clk":"4296795807","pt":1632570309177,"mc":[{"id":"1.188134680","rc":[{"trd":[[2.14,0.38]],"batl":[[0,2.14,26.8]],"ltp":2.14,"tv":1722.94,"id":9631939},{"trd":[[1.89,799.9]],"batl":[[0,1.92,12.76],[1,1.93,290.2],[2,1.95,301.7]],"ltp":1.89,"tv":7620.11,"id":8681938}],"tv":9343.05}]}
{"op":"mcm","clk":"4296796928","pt":1632570315371,"mc":[{"id":"1.188134680","rc":[{"batl":[[2,2.22,13.58]],"ltp":2.14,"tv":1722.94,"id":9631939}]}]}
{"op":"mcm","clk":"4296797072","pt":1632570316074,"mc":[{"id":"1.188134680","rc":[{"trd":[[2.12,84.99]],"batb":[[0,2.04,14.42],[1,1.97,12.21],[2,1.95,11.91]],"batl":[[0,2.22,13.58],[1,2.24,182.22],[2,2.26,203.17]],"ltp":2.12,"tv":1723.02,"id":9631939},{"trd":[[1.9,811.22]],"batb":[[0,1.83,65.85],[1,1.82,135.71],[2,1.81,194.85]],"batl":[[0,1.96,15],[1,2,2],[2,2.04,4.13]],"ltp":1.9,"tv":7620.2,"id":8681938}],"tv":9343.22}]}
{"op":"mcm","clk":"4296797284","pt":1632570317303,"mc":[{"id":"1.188134680","rc":[{"batb":[[0,1.98,5.37],[1,1.97,11.84]],"batl":[[0,2.24,182.22],[1,2.26,203.17],[2,2.3,6.15]],"ltp":2.12,"tv":1723.02,"id":9631939},{"batb":[[0,1.82,135.71],[1,1.81,194.85],[2,1.8,302.08]],"batl":[[0,2,2],[1,2.04,4.13],[2,2.06,3.92]],"ltp":1.9,"tv":7620.2,"id":8681938}]}]}
{"op":"mcm","clk":"4296797606","pt":1632570319297,"mc":[{"id":"1.188134680","rc":[{"batb":[[0,1.99,13.51],[1,1.98,5.37],[2,1.97,11.84]],"ltp":2.12,"tv":1723.02,"id":9631939},{"batl":[[1,2.02,4.25],[2,2.04,4.13]],"ltp":1.9,"tv":7620.2,"id":8681938}]}]}
{"op":"mcm","clk":"4296797782","pt":1632570320304,"mc":[{"id":"1.188134680","rc":[{"batb":[[0,1.98,5.37],[1,1.97,11.84],[2,1.95,11.91]],"batl":[[0,2.1,20.35],[1,2.2,47.15],[2,2.24,182.22]],"ltp":2.12,"tv":1723.02,"id":9631939},{"trd":[[1.89,815.32]],"batb":[[0,1.91,18.39],[1,1.89,252.19],[2,1.87,337.26]],"batl":[[0,1.94,20.25],[1,1.96,339.96],[2,1.98,288.05]],"ltp":1.89,"tv":7635.61,"id":8681938}],"tv":9358.64}]}
{"op":"mcm","clk":"4296797936","pt":1632570321211,"mc":[{"id":"1.188134680","rc":[{"batb":[[0,1.99,26.85],[1,1.98,5.37],[2,1.97,11.84]],"batl":[[0,2.24,184.22],[1,2.26,203.17],[2,2.3,6.15]],"ltp":2.12,"tv":1723.02,"id":9631939},{"batb":[[0,1.89,252.19],[1,1.87,337.26],[2,1.82,132.42]],"batl":[[0,1.96,339.96],[1,1.98,288.05],[2,1.99,10]],"ltp":1.89,"tv":7635.61,"id":8681938}]}]}
{"op":"mcm","clk":"4296798258","pt":1632570323089,"mc":[{"id":"1.188134680","rc":[{"batb":[[0,1.99,13.51]],"ltp":2.12,"tv":1723.02,"id":9631939}]}]}
{"op":"mcm","clk":"4296798500","pt":1632570324310,"mc":[{"id":"1.188134680","rc":[{"batb":[[0,1.98,5.37],[1,1.97,11.84],[2,1.95,11.91]],"batl":[[0,2.22,67],[1,2.24,184.22],[2,2.26,203.17]],"ltp":2.12,"tv":1723.02,"id":9631939},{"batb":[[0,1.83,8.25],[1,1.82,132.42],[2,1.81,198.85]],"batl":[[0,2,2],[1,2.04,4.13],[2,2.06,3.92]],"ltp":1.89,"tv":7635.61,"id":8681938}]}]}
{"op":"mcm","clk":"4296798554","pt":1632570324636,"mc":[{"id":"1.188134680","rc":[{"batl":[[0,2.24,184.22],[1,2.26,203.17],[2,2.3,6.15]],"ltp":2.12,"tv":1723.02,"id":9631939}]}]}
{"op":"mcm","clk":"4296798842","pt":1632570326198,"mc":[{"id":"1.188134680","rc":[{"batb":[[0,2,26.85],[1,1.98,5.37],[2,1.97,11.84]],"ltp":2.12,"tv":1723.02,"id":9631939}]}]}
{"op":"mcm","clk":"4296799027","pt":1632570327310,"mc":[{"id":"1.188134680","rc":[{"batb":[[0,1.99,11.51]],"ltp":2.12,"tv":1723.02,"id":9631939},{"batb":[[2,1.81,551.72]],"batl":[[1,2.02,4.25],[2,2.04,4.13]],"ltp":1.89,"tv":7635.61,"id":8681938}]}]}
{"op":"mcm","clk":"4296799078","pt":1632570327583,"mc":[{"id":"1.188134680","rc":[{"batb":[[0,1.98,5.37],[1,1.97,11.84],[2,1.95,11.91]],"ltp":2.12,"tv":1723.02,"id":9631939},{"batl":[[1,2.04,4.13],[2,2.06,3.92]],"ltp":1.89,"tv":7635.61,"id":8681938}]}]}
{"op":"mcm","clk":"4296799554","pt":1632570330292,"mc":[{"id":"1.188134680","rc":[{"batb":[[1,1.97,15.84]],"batl":[[0,2.24,5.48],[1,2.26,3.25]],"ltp":2.12,"tv":1723.02,"id":9631939},{"batb":[[2,1.81,373.16]],"ltp":1.89,"tv":7635.61,"id":8681938}]}]}
{"op":"mcm","clk":"4296799671","pt":1632570330992,"mc":[{"id":"1.188134680","rc":[{"batb":[[0,1.99,11.51],[1,1.98,5.37],[2,1.97,15.84]],"ltp":2.12,"tv":1723.02,"id":9631939},{"batb":[[2,1.81,20.29]],"batl":[[1,2.02,4.25],[2,2.04,4.13]],"ltp":1.89,"tv":7635.61,"id":8681938}]}]}
{"op":"mcm","clk":"4296799869","pt":1632570332152,"mc":[{"id":"1.188134680","rc":[{"batb":[[0,1.82,132.42],[1,1.81,20.29],[2,1.8,17.08]],"ltp":1.89,"tv":7635.61,"id":8681938}]}]}
{"op":"mcm","clk":"4296800072","pt":1632570333200,"mc":[{"id":"1.188134680","rc":[{"trd":[[1.97,0.37],[1.98,68.55]],"batb":[[0,1.97,11.47],[1,1.95,11.91],[2,1.9,247.65]],"batl":[[0,2.02,123.35],[1,2.14,14.02],[2,2.24,5.48]],"ltp":1.97,"tv":1723.75,"id":9631939},{"trd":[[2,42.3],[2.04,8.98]],"batb":[[0,1.99,1922.1],[1,1.98,6568.5],[2,1.97,1865.58]],"batl":[[0,2.06,3.92],[1,2.08,8.38],[2,2.12,215.25]],"ltp":2.04,"tv":7648.59,"id":8681938}],"tv":9372.35}]}
{"op":"mcm","clk":"4296800259","pt":1632570334311,"mc":[{"id":"1.188134680","rc":[{"batb":[[2,1.93,324.95]],"batl":[[0,2,220.09],[1,2.02,394.17],[2,2.08,2.44]],"ltp":1.97,"tv":1723.75,"id":9631939},{"batb":[[0,2.02,185.08],[1,1.99,480.52],[2,1.98,839.65]],"batl":[[0,2.04,14.71],[1,2.06,3.92],[2,2.08,8.38]],"ltp":2.04,"tv":7648.59,"id":8681938}]}]}
{"op":"mcm","clk":"4296800417","pt":1632570335316,"mc":[{"id":"1.188134680","rc":[{"trd":[[2.02,315.86]],"batb":[[0,2.02,182.89]],"ltp":2.02,"tv":7652.98,"id":8681938}],"tv":9376.74}]}
{"op":"mcm","clk":"4296800698","pt":1632570336706,"mc":[{"id":"1.188134680","rc":[{"batl":[[0,2,222.09]],"ltp":1.97,"tv":1723.75,"id":9631939},{"batb":[[1,2,3],[2,1.99,484.52]],"ltp":2.02,"tv":7652.98,"id":8681938}]}]}
{"op":"mcm","clk":"4296801006","pt":1632570338313,"mc":[{"id":"1.188134680","rc":[{"batb":[[0,2.02,190.36]],"ltp":2.02,"tv":7652.98,"id":8681938}]}]}
{"op":"mcm","clk":"4296801195","pt":1632570339306,"mc":[{"id":"1.188134680","rc":[{"trd":[[1.97,23.31]],"batb":[[0,1.95,11.91],[1,1.93,324.95],[2,1.91,315.19]],"batl":[[0,1.99,29.4],[1,2,222.09],[2,2.02,394.17]],"ltp":1.97,"tv":1746.69,"id":9631939}],"tv":9399.68}]}
{"op":"mcm","clk":"4296801269","pt":1632570339729,"mc":[{"id":"1.188134680","rc":[{"batb":[[0,2.02,182.89]],"ltp":2.02,"tv":7652.98,"id":8681938}]}]}
{"op":"mcm","clk":"4296801699","pt":1632570342121,"mc":[{"id":"1.188134680","rc":[{"batl":[[1,2,425.13]],"ltp":1.97,"tv":1746.69,"id":9631939}]}]}
{"op":"mcm","clk":"4296801900","pt":1632570343311,"mc":[{"id":"1.188134680","rc":[{"trd":[[2.04,23.78]],"batl":[[0,2.04,7.31]],"ltp":2.04,"tv":7667.78,"id":8681938}],"tv":9414.48}]}
{"op":"mcm","clk":"4296801912","pt":1632570343412,"mc":[{"id":"1.188134680","rc":[{"batl":[[2,2.12,215.25]],"ltp":2.04,"tv":7667.78,"id":8681938}]}]}
{"op":"mcm","clk":"4296802205","pt":1632570345227,"mc":[{"id":"1.188134680","rc":[{"batl":[[1,2,222.09]],"ltp":1.97,"tv":1746.69,"id":9631939}]}]}
{"op":"mcm","clk":"4296802440","pt":1632570346517,"mc":[{"id":"1.188134680","rc":[{"batl":[[0,1.98,7.96],[1,1.99,29.4],[2,2,222.09]],"ltp":1.97,"tv":1746.69,"id":9631939},{"trd":[[2.02,320.55]],"batb":[[0,2.02,180.54]],"batl":[[1,2.06,11.6]],"ltp":2.02,"tv":7672.48,"id":8681938}],"tv":9419.17}]}
{"op":"mcm","clk":"4296802770","pt":1632570348324,"mc":[{"id":"1.188134680","rc":[{"trd":[[1.98,73.24]],"batl":[[0,1.98,5.61]],"ltp":1.98,"tv":1751.39,"id":9631939},{"batb":[[2,1.99,480.52]],"ltp":2.02,"tv":7672.48,"id":8681938}],"tv":9423.87}]}
{"op":"mcm","clk":"4296802787","pt":1632570348429,"mc":[{"id":"1.188134680","rc":[{"batl":[[1,1.99,125.33]],"ltp":1.98,"tv":1751.39,"id":9631939}]}]}
{"op":"mcm","clk":"4296803277","pt":1632570351334,"mc":[{"id":"1.188134680","rc":[{"batb":[[0,1.88,114.57],[1,1.87,16.08],[2,1.72,201.35]],"batl":[[0,2,2],[1,2.04,14.7],[2,2.16,176.18]],"ltp":1.98,"tv":1751.39,"id":9631939},{"batb":[[2,1.97,60.92]],"batl":[[0,2.16,13.92],[1,2.4,134.52],[2,2.42,193.82]],"ltp":2.02,"tv":7672.48,"id":8681938}]}]}
{"op":"mcm","clk":"4296803467","pt":1632570352236,"mc":[{"id":"1.188134680","rc":[{"batb":[[0,1.72,201.35],[1,1.71,305.26],[2,1.7,17.72]],"batl":[[0,2.16,176.18],[1,2.18,196.66],[2,2.22,3.75]],"ltp":1.98,"tv":1751.39,"id":9631939},{"batb":[[0,1.91,110.51],[1,1.87,184.66],[2,1.86,274.34]],"batl":[[0,2.4,134.52],[1,2.42,193.82],[2,2.44,2.58]],"ltp":2.02,"tv":7672.48,"id":8681938}]}]}
{"op":"mcm","clk":"4296803844","pt":1632570354334,"mc":[{"id":"1.188134680","rc":[{"batb":[[0,1.98,285.42],[1,1.72,201.35],[2,1.71,569.48]],"batl":[[0,2.14,364.09],[1,2.16,399.74],[2,2.18,196.66]],"ltp":1.98,"tv":1751.39,"id":9631939}]}]}
{"op":"mcm","clk":"4296804032","pt":1632570355306,"mc":[{"id":"1.188134680","rc":[{"batb":[[2,1.71,305.26]],"batl":[[0,2.02,499.36],[1,2.16,172.96]],"ltp":1.98,"tv":1751.39,"id":9631939},{"batb":[[1,1.87,169.39]],"ltp":2.02,"tv":7672.48,"id":8681938}]}]}
{"op":"mcm","clk":"4296804161","pt":1632570356035,"mc":[{"id":"1.188134680","rc":[{"trd":[[1.95,4.78],[1.98,624.95]],"batb":[[0,1.88,342.71],[1,1.86,342.47],[2,1.72,205.35]],"batl":[[0,1.95,25.49],[1,1.97,291.52],[2,2.16,172.96]],"ltp":1.95,"tv":2303.17,"id":9631939},{"trd":[[2.04,42.36]],"batl":[[0,2.4,137.52]],"ltp":2.04,"tv":7691.06,"id":8681938}],"tv":9994.23}]}
{"op":"mcm","clk":"4296804398","pt":1632570357342,"mc":[{"id":"1.188134680","rc":[{"batb":[[0,1.72,205.35],[1,1.71,309.26],[2,1.7,17.72]],"batl":[[0,2.12,111.9],[1,2.16,172.96],[2,2.18,196.66]],"ltp":1.95,"tv":2303.17,"id":9631939},{"batb":[[0,1.92,107.92],[1,1.91,110.51],[2,1.87,169.39]],"batl":[[0,2.38,82.84],[1,2.4,137.52],[2,2.42,193.82]],"ltp":2.04,"tv":7691.06,"id":8681938}]}]}
{"op":"mcm","clk":"4296804433","pt":1632570357535,"mc":[{"id":"1.188134680","rc":[{"batl":[[2,2.18,200.41]],"ltp":1.95,"tv":2303.17,"id":9631939}]}]}
{"op":"mcm","clk":"4296804697","pt":1632570359037,"mc":[{"id":"1.188134680","rc":[{"batb":[[0,1.72,205.66]],"batl":[[1,2.16,176.93]],"ltp":1.95,"tv":2303.17,"id":9631939},{"batb":[[2,1.87,184.66]],"ltp":2.04,"tv":7691.06,"id":8681938}]}]}
{"op":"mcm","clk":"4296804917","pt":1632570360244,"mc":[{"id":"1.188134680","rc":[{"trd":[[1.98,625.57]],"batb":[[0,1.89,318.26],[1,1.87,336.5],[2,1.72,205.35]],"batl":[[0,1.96,280.25],[1,1.98,286.99],[2,2.12,111.9]],"ltp":1.98,"tv":2303.79,"id":9631939}],"tv":9994.85}]}
{"op":"mcm","clk":"4296805026","pt":1632570360740,"mc":[{"id":"1.188134680","rc":[{"batl":[[2,2.16,176.93]],"ltp":1.98,"tv":2303.79,"id":9631939},{"batl":[[0,2.38,4]],"ltp":2.04,"tv":7691.06,"id":8681938}]}]}
{"op":"mcm","clk":"4296805343","pt":1632570362250,"mc":[{"id":"1.188134680","rc":[{"batb":[[0,1.73,1.88],[1,1.72,205.35],[2,1.71,309.26]],"batl":[[0,2.16,176.93],[1,2.18,200.41],[2,2.22,3.75]],"ltp":1.98,"tv":2303.79,"id":9631939},{"batb":[[0,1.91,110.51],[1,1.87,184.66],[2,1.86,288.52]],"ltp":2.04,"tv":7691.06,"id":8681938}]}]}
{"op":"mcm","clk":"4296805565","pt":1632570363342,"mc":[{"id":"1.188134680","rc":[{"batb":[[0,1.73,6.88]],"ltp":1.98,"tv":2303.79,"id":9631939}]}]}
{"op":"mcm","clk":"4296805757","pt":1632570364237,"mc":[{"id":"1.188134680","rc":[{"batb":[[1,1.72,4],[2,1.71,4]],"ltp":1.98,"tv":2303.79,"id":9631939},{"batl":[[1,2.4,3],[2,2.62,2.46]],"ltp":2.04,"tv":7691.06,"id":8681938}]}]}
{"op":"mcm","clk":"4296805900","pt":1632570364934,"mc":[{"id":"1.188134680","rc":[{"batl":[[0,2.16,172.96],[1,2.18,196.66]],"ltp":1.98,"tv":2303.79,"id":9631939},{"batb":[[1,1.87,169.39]],"batl":[[0,1.92,2.19],[1,2.38,4],[2,2.4,3]],"ltp":2.04,"tv":7691.06,"id":8681938}]}]}
{"op":"mcm","clk":"4296806386","pt":1632570367344,"mc":[{"id":"1.188134680","rc":[{"batb":[[0,2.04,366.63],[1,1.73,6.88],[2,1.66,173.58]],"batl":[[0,2.16,275.25]],"ltp":1.98,"tv":2303.79,"id":9631939},{"trd":[[1.91,246.9]],"batb":[[0,1.91,94.72],[1,1.88,222.87],[2,1.87,169.39]],"batl":[[0,1.92,13.35],[1,1.94,241.68],[2,1.96,784.95]],"ltp":1.91,"tv":7722.64,"id":8681938}],"tv":10026.43}]}
{"op":"mcm","clk":"4296806570","pt":1632570368340,"mc":[{"id":"1.188134680","rc":[{"batb":[[1,2,191.76],[2,1.85,120.4]],"ltp":1.98,"tv":2303.79,"id":9631939},{"batl":[[0,1.92,11.16]],"ltp":1.91,"tv":7722.64,"id":8681938}]}]}
{"op":"mcm","clk":"4296806658","pt":1632570368823,"mc":[{"id":"1.188134680","rc":[{"batb":[[2,1.96,15.3]],"batl":[[0,2.14,38.01],[1,2.16,289.17],[2,2.18,196.66]],"ltp":1.98,"tv":2303.79,"id":9631939}]}]}
{"op":"mcm","clk":"4296806919","pt":1632570370347,"mc":[{"id":"1.188134680","rc":[{"batb":[[2,1.97,3]],"ltp":1.98,"tv":2303.79,"id":9631939}]}]}
{"op":"mcm","clk":"4296807638","pt":1632570374233,"mc":[{"id":"1.188134680","rc":[{"batb":[[2,1.97,15.17]],"ltp":1.98,"tv":2303.79,"id":9631939}]}]}
{"op":"mcm","clk":"4296807805","pt":1632570375245,"mc":[{"id":"1.188134680","rc":[{"batb":[[2,1.98,15.15]],"ltp":1.98,"tv":2303.79,"id":9631939}]}]}
{"op":"mcm","clk":"4296808314","pt":1632570377958,"mc":[{"id":"1.188134680","rc":[{"trd":[[2.06,40.1],[2.08,109.94]],"ltp":2.06,"tv":2346.7,"id":9631939},{"trd":[[1.92,189.75],[1.94,86.72]],"batl":[[0,1.94,207.05],[1,1.96,784.95],[2,1.97,473.54]],"ltp":1.94,"tv":7768.43,"id":8681938}],"tv":10115.14}]}
{"op":"mcm","clk":"4296808548","pt":1632570379155,"mc":[{"id":"1.188134680","rc":[{"batb":[[0,1.98,15.15],[1,1.97,15.17],[2,1.96,4]],"batl":[[0,2.16,13.92],[1,2.2,3.63],[2,2.22,3.75]],"ltp":2.06,"tv":2346.7,"id":9631939},{"batb":[[0,1.86,64.69],[1,1.84,137.82],[2,1.82,16.14]],"batl":[[0,2.04,4.13],[1,2.08,4.19],[2,2.1,155.57]],"ltp":1.94,"tv":7768.43,"id":8681938}]}]}
{"op":"mcm","clk":"4296808735","pt":1632570380261,"mc":[{"id":"1.188134680","rc":[{"batb":[[0,1.97,3],[1,1.96,4],[2,1.93,14.93]],"batl":[[0,2.2,3.63],[1,2.22,3.75],[2,2.24,3.48]],"ltp":2.06,"tv":2346.7,"id":9631939},{"batb":[[0,1.84,137.82],[1,1.82,16.14],[2,1.81,16.29]],"batl":[[0,2.08,4.19],[1,2.1,155.57],[2,2.12,170.94]],"ltp":1.94,"tv":7768.43,"id":8681938}]}]}
{"op":"mcm","clk":"4296809105","pt":1632570382347,"mc":[{"id":"1.188134680","rc":[{"batb":[[1,1.93,14.93],[2,1.92,187.13]],"ltp":2.06,"tv":2346.7,"id":9631939},{"batl":[[0,2.02,14.85],[1,2.08,4.19],[2,2.1,155.57]],"ltp":1.94,"tv":7768.43,"id":8681938}]}]}
{"op":"mcm","clk":"4296809271","pt":1632570383261,"mc":[{"id":"1.188134680","rc":[{"batb":[[0,1.97,15.51]],"ltp":2.06,"tv":2346.7,"id":9631939},{"batl":[[0,2.04,4.13],[1,2.06,4],[2,2.08,4.19]],"ltp":1.94,"tv":7768.43,"id":8681938}]}]}
{"op":"mcm","clk":"4296809454","pt":1632570384266,"mc":[{"id":"1.188134680","rc":[{"batb":[[0,1.97,3]],"batl":[[0,2.16,468.09],[1,2.2,3.63],[2,2.22,3.75]],"ltp":2.06,"tv":2346.7,"id":9631939},{"batl":[[0,2.06,4],[1,2.08,4.19],[2,2.1,155.57]],"ltp":1.94,"tv":7768.43,"id":8681938}]}]}
{"op":"mcm","clk":"4296809627","pt":1632570385230,"mc":[{"id":"1.188134680","rc":[{"batl":[[0,2.08,18.19]],"ltp":2.06,"tv":2346.7,"id":9631939},{"batb":[[0,1.93,20.93],[1,1.9,338.84],[2,1.88,331.5]],"batl":[[0,1.96,18.37],[1,1.97,249.18],[2,1.99,283.68]],"ltp":1.94,"tv":7768.43,"id":8681938}]}]}
{"op":"mcm","clk":"4296809794","pt":1632570386234,"mc":[{"id":"1.188134680","rc":[{"batb":[[0,1.97,29.2],[1,1.96,5],[2,1.93,14.93]],"batl":[[0,2.18,18.15]],"ltp":2.06,"tv":2346.7,"id":9631939},{"batb":[[0,1.94,2.35]],"batl":[[0,1.97,249.18],[1,1.99,283.68],[2,2.04,20.65]],"ltp":1.94,"tv":7768.43,"id":8681938}]}]}
{"op":"mcm","clk":"4296810031","pt":1632570387559,"mc":[{"id":"1.188134680","rc":[{"batb":[[0,1.97,42.71]],"ltp":2.06,"tv":2346.7,"id":9631939},{"batl":[[2,2.04,25.28]],"ltp":1.94,"tv":7768.43,"id":8681938}]}]}
{"op":"mcm","clk":"4296810360","pt":1632570389281,"mc":[{"id":"1.188134680","rc":[{"batb":[[1,1.91,76.22],[2,1.9,338.84]],"ltp":1.94,"tv":7768.43,"id":8681938}]}]}
{"op":"mcm","clk":"4296810525","pt":1632570390146,"mc":[{"id":"1.188134680","rc":[{"batb":[[0,1.97,16.51]],"batl":[[0,2.2,3.63],[1,2.22,3.75],[2,2.24,3.48]],"ltp":2.06,"tv":2346.7,"id":9631939},{"trd":[[1.94,91.11]],"batb":[[0,1.9,338.99],[1,1.88,331.5],[2,1.84,137.82]],"batl":[[2,2.04,4.63]],"ltp":1.94,"tv":7772.81,"id":8681938}],"tv":10119.52}]}
{"op":"mcm","clk":"4296810662","pt":1632570390956,"mc":[{"id":"1.188134680","rc":[{"batb":[[0,1.97,3]],"ltp":2.06,"tv":2346.7,"id":9631939},{"batb":[[0,1.84,137.97],[1,1.82,16.14],[2,1.81,16.29]],"batl":[[0,2.06,17.71],[1,2.08,4.19],[2,2.1,155.57]],"ltp":1.94,"tv":7772.81,"id":8681938}]}]}
{"op":"mcm","clk":"4296811078","pt":1632570393365,"mc":[{"id":"1.188134680","rc":[{"batb":[[1,1.82,406.64]],"batl":[[2,2.1,499.16]],"ltp":1.94,"tv":7772.81,"id":8681938}]}]}
{"op":"mcm","clk":"4296811246","pt":1632570394359,"mc":[{"id":"1.188134680","rc":[{"batl":[[0,2.06,4]],"ltp":1.94,"tv":7772.81,"id":8681938}]}]}
{"op":"mcm","clk":"4296811423","pt":1632570395383,"mc":[{"id":"1.188134680","rc":[{"trd":[[1.94,91.42]],"batb":[[0,1.84,137.82]],"batl":[[0,1.9,1.8],[1,2.06,4],[2,2.08,4.19]],"ltp":1.94,"tv":7773.12,"id":8681938}],"tv":10119.83}]}
{"op":"mcm","clk":"4296811555","pt":1632570396277,"mc":[{"id":"1.188134680","rc":[{"batl":[[2,2.08,17.9]],"ltp":1.94,"tv":7773.12,"id":8681938}]}]}
{"op":"mcm","clk":"4296811836","pt":1632570397875,"mc":[{"id":"1.188134680","rc":[{"batb":[[1,1.93,14.93],[2,1.92,187.13]],"ltp":2.06,"tv":2346.7,"id":9631939}]}]}
{"op":"mcm","clk":"4296812350","pt":1632570401054,"mc":[{"id":"1.188134680","rc":[{"batb":[[1,1.96,5],[2,1.93,14.93]],"ltp":2.06,"tv":2346.7,"id":9631939}]}]}
{"op":"mcm","clk":"4296812517","pt":1632570402169,"mc":[{"id":"1.188134680","rc":[{"batb":[[0,1.97,15.17]],"ltp":2.06,"tv":2346.7,"id":9631939},{"batl":[[1,2.04,4.13],[2,2.06,4]],"ltp":1.94,"tv":7773.12,"id":8681938}]}]}
{"op":"mcm","clk":"4296812613","pt":1632570402783,"mc":[{"id":"1.188134680","rc":[{"batb":[[0,1.97,3]],"batl":[[1,2.24,3.48],[2,2.26,158.94]],"ltp":2.06,"tv":2346.7,"id":9631939},{"batb":[[1,1.82,390.5]],"batl":[[1,2.06,4],[2,2.08,13.71]],"ltp":1.94,"tv":7773.12,"id":8681938}]}]}
{"op":"mcm","clk":"4296812882","pt":1632570404383,"mc":[{"id":"1.188134680","rc":[{"batl":[[0,2.06,4],[1,2.08,13.71],[2,4.4,3.34]],"ltp":1.94,"tv":7773.12,"id":8681938}]}]}
{"op":"mcm","clk":"4296813024","pt":1632570405282,"mc":[{"id":"1.188134680","rc":[{"batb":[[0,2,298.57],[1,1.97,3],[2,1.96,5]],"batl":[[1,2.24,19.54]],"ltp":2.06,"tv":2346.7,"id":9631939},{"trd":[[1.84,587.2]],"batb":[[0,1.84,121.43]],"batl":[[0,1.85,2.19],[1,1.86,9.3],[2,1.89,4060.16]],"ltp":1.84,"tv":7805.9,"id":8681938}],"tv":10152.61}]}
{"op":"mcm","clk":"4296813210","pt":1632570406358,"mc":[{"id":"1.188134680","rc":[{"batb":[[0,2.06,171.81],[1,2.04,14.42],[2,2,190.49]],"batl":[[2,2.26,172.3]],"ltp":2.06,"tv":2346.7,"id":9631939},{"batl":[[2,1.89,702.46]],"ltp":1.84,"tv":7805.9,"id":8681938}]}]}
{"op":"mcm","clk":"4296813377","pt":1632570407374,"mc":[{"id":"1.188134680","rc":[{"batl":[[0,2.18,18.15],[1,2.2,3.63],[2,2.24,19.54]],"ltp":2.06,"tv":2346.7,"id":9631939},{"trd":[[1.85,96.67]],"batb":[[0,1.85,28.46],[1,1.84,121.43],[2,1.82,390.5]],"batl":[[0,1.86,9.3],[1,1.89,702.46],[2,1.9,13.71]],"ltp":1.85,"tv":7810.29,"id":8681938}],"tv":10157.0}]}
{"op":"mcm","clk":"4296813514","pt":1632570408197,"mc":[{"id":"1.188134680","rc":[{"batb":[[2,2.02,4]],"ltp":2.06,"tv":2346.7,"id":9631939},{"trd":[[1.86,152.72]],"batb":[[1,1.84,125.43],[2,1.83,5]],"batl":[[0,1.86,5.07]],"ltp":1.86,"tv":7818.74,"id":8681938}],"tv":10165.45}]}
{"op":"mcm","clk":"4296813688","pt":1632570409197,"mc":[{"id":"1.188134680","rc":[{"batl":[[2,1.91,822.31]],"ltp":1.86,"tv":7818.74,"id":8681938}]}]}
{"op":"mcm","clk":"4296813874","pt":1632570410274,"mc":[{"id":"1.188134680","rc":[{"batl":[[1,1.88,13.71],[2,1.89,702.46]],"ltp":1.86,"tv":7818.74,"id":8681938}]}]}
{"op":"mcm","clk":"4296814040","pt":1632570411379,"mc":[{"id":"1.188134680","rc":[{"batb":[[1,2.02,4],[2,2,195.49]],"ltp":2.06,"tv":2346.7,"id":9631939}]}]}
{"op":"mcm","clk":"4296814161","pt":1632570412202,"mc":[{"id":"1.188134680","rc":[{"batb":[[1,2.04,182.46],[2,2.02,201.69]],"ltp":2.06,"tv":2346.7,"id":9631939}]}]}
{"op":"mcm","clk":"4296814552","pt":1632570414376,"mc":[{"id":"1.188134680","rc":[{"batb":[[0,2.08,171.22],[1,2.06,14.15],[2,2.04,182.46]],"ltp":2.06,"tv":2346.7,"id":9631939}]}]}
{"op":"mcm","clk":"4296814757","pt":1632570415688,"mc":[{"id":"1.188134680","rc":[{"trd":[[2.16,108.54]],"ltp":2.16,"tv":2350.55,"id":9631939},{"trd":[[1.86,157.19]],"batl":[[0,1.88,14.31],[1,1.89,702.46],[2,1.91,822.31]],"ltp":1.86,"tv":7823.21,"id":8681938}],"tv":10173.77}]}
{"op":"mcm","clk":"4296814971","pt":1632570416970,"mc":[{"id":"1.188134680","rc":[{"trd":[[2.16,109.05]],"batl":[[0,2.16,1.83],[1,2.18,18.15],[2,2.2,3.63]],"ltp":2.16,"tv":2351.07,"id":9631939},{"trd":[[1.86,157.79]],"batl":[[0,1.88,27.41],[1,1.89,413]],"ltp":1.86,"tv":7823.81,"id":8681938}],"tv":10174.89}]}
{"op":"mcm","clk":"4296815711","pt":1632570421281,"mc":[{"id":"1.188134680","rc":[{"batl":[[2,2.2,15.47]],"ltp":2.16,"tv":2351.07,"id":9631939},{"batl":[[1,1.89,427.97]],"ltp":1.86,"tv":7823.81,"id":8681938}]}]}
{"op":"mcm","clk":"4296815846","pt":1632570422015,"mc":[{"id":"1.188134680","rc":[{"batb":[[2,1.82,390.5]],"ltp":1.86,"tv":7823.81,"id":8681938}]}]}
{"op":"mcm","clk":"4296816432","pt":1632570425203,"mc":[{"id":"1.188134680","rc":[{"batb":[[2,1.83,4]],"ltp":1.86,"tv":7823.81,"id":8681938}]}]}
{"op":"mcm","clk":"4296816534","pt":1632570425798,"mc":[{"id":"1.188134680","rc":[{"batl":[[2,2.2,3.63]],"ltp":2.16,"tv":2351.07,"id":9631939},{"batl":[[1,1.89,413]],"ltp":1.86,"tv":7823.81,"id":8681938}]}]}
{"op":"mcm","clk":"4296817484","pt":1632570431800,"mc":[{"id":"1.188134680","rc":[{"batl":[[2,2.2,15.47]],"ltp":2.16,"tv":2351.07,"id":9631939},{"batl":[[0,1.88,124.41],[1,1.89,427.97]],"ltp":1.86,"tv":7823.81,"id":8681938}]}]}
{"op":"mcm","clk":"4296818603","pt":1632570438711,"mc":[{"id":"1.188134680","rc":[{"trd":[[2.16,110.89]],"batl":[[0,2.18,18.15],[1,2.2,15.47],[2,2.24,3.48]],"ltp":2.16,"tv":2352.9,"id":9631939},{"trd":[[1.86,159.92]],"batb":[[2,1.82,390.5]],"batl":[[0,1.88,124.63]],"ltp":1.86,"tv":7825.94,"id":8681938}],"tv":10178.85}]}
{"op":"mcm","clk":"4296819129","pt":1632570441977,"mc":[{"id":"1.188134680","rc":[{"batb":[[2,1.83,4]],"ltp":1.86,"tv":7825.94,"id":8681938}]}]}
{"op":"mcm","clk":"4296819247","pt":1632570442435,"mc":[{"id":"1.188134680","rc":[{"trd":[[1.88,94.84]],"batl":[[0,1.88,122.29]],"ltp":1.88,"tv":7830.2,"id":8681938}],"tv":10183.1}]}
{"op":"mcm","clk":"4296819569","pt":1632570444028,"mc":[{"id":"1.188134680","rc":[{"trd":[[1.88,339.41],[1.89,1638.07]],"batl":[[0,1.89,16.59],[1,1.91,822.31],[2,1.92,485.94]],"ltp":1.89,"tv":8897.52,"id":8681938}],"tv":11250.42}]}
{"op":"mcm","clk":"4296819668","pt":1632570444659,"mc":[{"id":"1.188134680","rc":[{"batl":[[0,1.89,14.97],[1,1.91,500.66]],"ltp":1.89,"tv":8897.52,"id":8681938}]}]}
{"op":"mcm","clk":"4296820243","pt":1632570447340,"mc":[{"id":"1.188134680","rc":[{"trd":[[1.85,106.67]],"batb":[[0,1.85,23.46]],"ltp":1.85,"tv":8907.52,"id":8681938}],"tv":11260.42}]}
{"op":"mcm","clk":"4296820415","pt":1632570448144,"mc":[{"id":"1.188134680","rc":[{"trd":[[1.89,1668.02],[1.91,249.06]],"batb":[[0,1.86,27.71],[1,1.85,23.46],[2,1.84,125.43]],"batl":[[0,1.9,298.98],[1,1.91,499.58],[2,1.92,802.29]],"ltp":1.91,"tv":8939.62,"id":8681938}],"tv":11292.53}]}
{"op":"mcm","clk":"4296820616","pt":1632570449170,"mc":[{"id":"1.188134680","rc":[{"trd":[[2.12,90.75]],"ltp":2.12,"tv":2358.66,"id":9631939},{"trd":[[1.89,1674.48]],"batl":[[0,1.89,100.54],[1,1.9,298.98],[2,1.91,499.58]],"ltp":1.89,"tv":8946.08,"id":8681938}],"tv":11304.75}]}
{"op":"mcm","clk":"4296821902","pt":1632570455658,"mc":[{"id":"1.188134680","rc":[{"trd":[[2.12,95.58]],"ltp":2.12,"tv":2363.49,"id":9631939},{"trd":[[1.89,1679.9]],"batl":[[0,1.89,95.12]],"ltp":1.89,"tv":8951.5,"id":8681938}],"tv":11315.0}]}
{"op":"mcm","clk":"4296822306","pt":1632570457740,"mc":[{"id":"1.188134680","rc":[{"batl":[[1,2.2,3.63]],"ltp":2.12,"tv":2363.49,"id":9631939}]}]}
{"op":"mcm","clk":"4296822824","pt":1632570460662,"mc":[{"id":"1.188134680","rc":[{"batl":[[0,2.16,12.18],[1,2.18,18.15],[2,2.2,3.63]],"ltp":2.12,"tv":2363.49,"id":9631939}]}]}
{"op":"mcm","clk":"4296842421","pt":1632570494290,"mc":[{"id":"1.188134680","rc":[{"batb":[[0,2.06,14.15],[1,2.04,182.46],[2,2.02,201.69]],"batl":[[0,2.26,13.36],[1,2.4,164.93],[2,2.42,207.79]],"ltp":2.12,"tv":2363.49,"id":9631939},{"batb":[[1,1.81,3491.96],[2,1.8,67.08]],"batl":[[1,1.94,15],[2,1.97,183.83]],"ltp":1.89,"tv":8951.5,"id":8681938}]}]}
{"op":"mcm","clk":"4296842593","pt":1632570495290,"mc":[{"id":"1.188134680","rc":[{"trd":[[2.12,105.37]],"batb":[[0,2.04,182.46],[1,2.02,201.69],[2,2,189.82]],"batl":[[0,2.12,77.14]],"ltp":2.12,"tv":2373.28,"id":9631939},{"trd":[[1.89,1690.88]],"batb":[[2,1.78,1.58]],"batl":[[0,1.97,183.83],[1,1.98,231.62],[2,2.06,4]],"ltp":1.89,"tv":8962.48,"id":8681938}],"tv":11335.77}]}
{"op":"mcm","clk":"4296842935","pt":1632570497196,"mc":[{"id":"1.188134680","rc":[{"batb":[[0,2.04,186.33]],"batl":[[1,2.36,2.82],[2,2.4,164.93]],"ltp":2.12,"tv":2373.28,"id":9631939},{"batl":[[0,1.95,14.7],[1,1.96,282.77],[2,1.97,183.83]],"ltp":1.89,"tv":8962.48,"id":8681938}]}]}
{"op":"mcm","clk":"4296843146","pt":1632570498484,"mc":[{"id":"1.188134680","rc":[{"batl":[[0,1.95,18.7],[2,1.97,188.83]],"ltp":1.89,"tv":8962.48,"id":8681938}]}]}
{"op":"mcm","clk":"4296843796","pt":1632570502001,"mc":[{"id":"1.188134680","rc":[{"batb":[[0,2.1,2.35],[1,2.04,186.33],[2,2.02,201.69]],"batl":[[0,2.12,1.96]],"ltp":2.12,"tv":2373.28,"id":9631939},{"batb":[[1,1.78,1.58],[2,1.74,16.52]],"ltp":1.89,"tv":8962.48,"id":8681938}]}]}
{"op":"mcm","clk":"4296843967","pt":1632570503131,"mc":[{"id":"1.188134680","rc":[{"batb":[[0,1.78,1.58],[1,1.74,16.52],[2,1.71,831.33]],"ltp":1.89,"tv":8962.48,"id":8681938}]}]}
{"op":"mcm","clk":"4296844109","pt":1632570503987,"mc":[{"id":"1.188134680","rc":[{"batb":[[1,2.06,4.58],[2,2.04,3.87]],"ltp":2.12,"tv":2373.28,"id":9631939},{"batl":[[0,1.93,14.5],[1,1.95,18.7],[2,1.97,5]],"ltp":1.89,"tv":8962.48,"id":8681938}]}]}
{"op":"mcm","clk":"4296844275","pt":1632570505098,"mc":[{"id":"1.188134680","rc":[{"trd":[[2.04,40.44],[2.1,146.53]],"batb":[[0,2.02,4],[1,2,189.82],[2,1.9,5.76]],"batl":[[0,2.04,53.05],[1,2.12,1.96],[2,2.36,2.82]],"ltp":2.04,"tv":2403.59,"id":9631939},{"trd":[[1.95,25.54]],"batl":[[0,1.97,5],[1,2.06,4],[2,4.4,3.34]],"ltp":1.95,"tv":8981.18,"id":8681938}],"tv":11384.78}]}
{"op":"mcm","clk":"4296844456","pt":1632570506314,"mc":[{"id":"1.188134680","rc":[{"trd":[[2.04,93.48],[2.12,107.33],[2.36,0.67]],"batl":[[0,2.36,2.15],[1,2.4,164.93],[2,2.42,207.79]],"ltp":2.36,"tv":2459.26,"id":9631939},{"trd":[[1.73,392.06],[1.74,48.89],[1.78,64.66],[1.89,1693.07],[1.96,359.95]],"batb":[[0,1.74,8.44],[1,1.71,831.33],[2,1.7,230.2]],"batl":[[0,1.78,2163.3],[1,1.79,2028.28],[2,1.8,2232.69]],"ltp":1.73,"tv":9075.7,"id":8681938}],"tv":11534.97}]}
{"op":"mcm","clk":"4296844616","pt":1632570507327,"mc":[{"id":"1.188134680","rc":[{"batl":[[0,2.4,164.93],[1,2.42,207.79],[2,2.46,88.65]],"ltp":2.36,"tv":2459.26,"id":9631939},{"batl":[[0,1.77,318.24],[1,1.78,553.22],[2,1.79,914.83]],"ltp":1.73,"tv":9075.7,"id":8681938}]}]}
{"op":"mcm","clk":"4296844763","pt":1632570508226,"mc":[{"id":"1.188134680","rc":[{"batb":[[0,2.28,132.66],[1,2.14,155.49],[2,2.02,4]],"ltp":2.36,"tv":2459.26,"id":9631939}]}]}
{"op":"mcm","clk":"4296844792","pt":1632570508392,"mc":[{"id":"1.188134680","rc":[{"batb":[[2,2.02,24]],"ltp":2.36,"tv":2459.26,"id":9631939}]}]}
{"op":"mcm","clk":"4296845108","pt":1632570510302,"mc":[{"id":"1.188134680","rc":[{"batb":[[2,2.04,2]],"batl":[[0,2.38,24.06],[1,2.4,164.93],[2,2.42,207.79]],"ltp":2.36,"tv":2459.26,"id":9631939},{"batb":[[1,1.72,36.99],[2,1.71,831.33]],"ltp":1.73,"tv":9075.7,"id":8681938}]}]}
{"op":"mcm","clk":"4296845244","pt":1632570511244,"mc":[{"id":"1.188134680","rc":[{"trd":[[1.72,5.84],[1.74,65.77],[1.76,58.56]],"batb":[[0,1.72,34.07],[1,1.71,831.33],[2,1.7,230.2]],"batl":[[0,1.76,174.72],[1,1.77,318.24],[2,1.78,553.22]],"ltp":1.72,"tv":9156.99,"id":8681938}],"tv":11616.26}]}
{"op":"mcm","clk":"4296845644","pt":1632570513720,"mc":[{"id":"1.188134680","rc":[{"batb":[[1,2.24,12.09],[2,2.16,19.31]],"ltp":2.36,"tv":2459.26,"id":9631939}]}]}
{"op":"mcm","clk":"4296845962","pt":1632570515936,"mc":[{"id":"1.188134680","rc":[{"trd":[[1.76,74.2]],"batl":[[0,1.76,166.9]],"ltp":1.76,"tv":9172.62,"id":8681938}],"tv":11631.89}]}
{"op":"mcm","clk":"4296846218","pt":1632570517726,"mc":[{"id":"1.188134680","rc":[{"trd":[[1.72,17.68]],"batb":[[0,1.72,28.15]],"ltp":1.72,"tv":9184.46,"id":8681938}],"tv":11643.73}]}
{"op":"mcm","clk":"4296846768","pt":1632570521209,"mc":[{"id":"1.188134680","rc":[{"batb":[[0,2.24,12.09],[1,2.16,19.31],[2,2.14,315.12]],"batl":[[0,2.48,12.32],[1,2.7,128.13],[2,2.72,182.93]],"ltp":2.36,"tv":2459.26,"id":9631939},{"batb":[[0,1.67,73.3],[1,1.59,245.9],[2,1.58,280.25]],"batl":[[1,1.8,15],[2,1.86,20]],"ltp":1.72,"tv":9184.46,"id":8681938}]}]}
{"op":"mcm","clk":"4296846871","pt":1632570521840,"mc":[{"id":"1.188134680","rc":[{"batb":[[1,2.14,315.12],[2,2.12,221.61]],"ltp":2.36,"tv":2459.26,"id":9631939},{"batl":[[0,1.8,15],[1,1.87,179.01],[2,1.88,232.49]],"ltp":1.72,"tv":9184.46,"id":8681938}]}]}
{"op":"mcm","clk":"4296847003","pt":1632570522627,"mc":[{"id":"1.188134680","rc":[{"batb":[[0,2.14,315.12],[1,2.12,221.61],[2,2.1,19.78]],"batl":[[0,2.7,128.13],[1,2.72,182.93],[2,2.76,2.27]],"ltp":2.36,"tv":2459.26,"id":9631939},{"batb":[[0,1.59,245.9],[1,1.58,280.25],[2,1.57,22.57]],"batl":[[0,1.87,179.01],[1,1.88,232.49],[2,1.9,19.6]],"ltp":1.72,"tv":9184.46,"id":8681938}]}]}
{"op":"mcm","clk":"4296847317","pt":1632570524323,"mc":[{"id":"1.188134680","rc":[{"batl":[[0,2.94,2.08],[1,2.98,2.25],[2,3,217.75]],"ltp":2.36,"tv":2459.26,"id":9631939},{"batb":[[0,1.55,222.88],[1,1.52,22.99],[2,1.51,23.99]],"batl":[[0,1.85,241.84],[1,1.87,522.22],[2,1.88,232.49]],"ltp":1.72,"tv":9184.46,"id":8681938}]}]}
{"op":"mcm","clk":"4296847504","pt":1632570525334,"mc":[{"id":"1.188134680","rc":[{"batb":[[0,2.16,20.06],[1,2.14,315.12],[2,2.12,221.61]],"batl":[[2,5.8,2.54]],"ltp":2.36,"tv":2459.26,"id":9631939},{"batl":[[1,1.86,19.5],[2,1.87,522.22]],"ltp":1.72,"tv":9184.46,"id":8681938}]}]}
{"op":"mcm","clk":"4296847588","pt":1632570525859,"mc":[{"id":"1.188134680","rc":[{"batl":[[0,2.7,3],[1,2.94,2.08],[2,2.98,2.25]],"ltp":2.36,"tv":2459.26,"id":9631939},{"batb":[[0,1.6,5],[1,1.59,5],[2,1.58,6]],"ltp":1.72,"tv":9184.46,"id":8681938}]}]}
{"op":"mcm","clk":"4296847831","pt":1632570527040,"mc":[{"id":"1.188134680","rc":[{"batl":[[0,2.24,16.9],[1,2.48,12.1],[2,2.7,3]],"ltp":2.36,"tv":2459.26,"id":9631939},{"batb":[[0,1.81,19.29],[1,1.8,261.12],[2,1.79,489.29]],"batl":[[1,1.86,33.96]],"ltp":1.72,"tv":9184.46,"id":8681938}]}]}
{"op":"mcm","clk":"4296848132","pt":1632570528357,"mc":[{"id":"1.188134680","rc":[{"batb":[[2,2.12,235]],"batl":[[1,2.36,12.86],[2,2.48,12.1]],"ltp":2.36,"tv":2459.26,"id":9631939},{"trd":[[1.81,42.89]],"batb":[[0,1.81,2.62],[2,1.79,624.74]],"ltp":1.81,"tv":9217.8,"id":8681938}],"tv":11677.07}]}
{"op":"mcm","clk":"4296848478","pt":1632570530225,"mc":[{"id":"1.188134680","rc":[{"batb":[[1,1.8,266.12],[2,1.79,628.74]],"ltp":1.81,"tv":9217.8,"id":8681938}]}]}
{"op":"mcm","clk":"4296848653","pt":1632570531331,"mc":[{"id":"1.188134680","rc":[{"batb":[[0,1.81,153.35]],"batl":[[0,1.84,181],[1,1.85,241.84],[2,1.86,33.96]],"ltp":1.81,"tv":9217.8,"id":8681938}]}]}
{"op":"mcm","clk":"4296848799","pt":1632570532235,"mc":[{"id":"1.188134680","rc":[{"batl":[[1,2.48,12.1],[2,2.5,1.71]],"ltp":2.36,"tv":2459.26,"id":9631939},{"batb":[[0,1.82,16.71],[1,1.81,48.74],[2,1.8,266.12]],"ltp":1.81,"tv":9217.8,"id":8681938}]}]}
{"op":"mcm","clk":"4296848959","pt":1632570533240,"mc":[{"id":"1.188134680","rc":[{"trd":[[1.82,9.43]],"batb":[[0,1.82,14.52]],"ltp":1.82,"tv":9222.19,"id":8681938}],"tv":11681.46}]}
{"op":"mcm","clk":"4296849111","pt":1632570534247,"mc":[{"id":"1.188134680","rc":[{"batl":[[1,2.48,164.26],[2,2.5,152.8]],"ltp":2.36,"tv":2459.26,"id":9631939}]}]}
{"op":"mcm","clk":"4296849299","pt":1632570535355,"mc":[{"id":"1.188134680","rc":[{"batl":[[1,2.34,12.95],[2,2.48,164.26]],"ltp":2.36,"tv":2459.26,"id":9631939}]}]}
{"op":"mcm","clk":"4296849423","pt":1632570536253,"mc":[{"id":"1.188134680","rc":[{"trd":[[1.82,14.12]],"batb":[[0,1.82,12.17]],"ltp":1.82,"tv":9226.88,"id":8681938}],"tv":11686.15}]}
{"op":"mcm","clk":"4296849578","pt":1632570537254,"mc":[{"id":"1.188134680","rc":[{"batb":[[0,2.16,16.53],[1,2.12,13.39],[2,2.08,21.62]],"batl":[[0,2.34,12.95],[1,2.48,152.16],[2,2.5,155.29]],"ltp":2.36,"tv":2459.26,"id":9631939},{"batb":[[1,1.81,16.92],[2,1.8,5]],"batl":[[1,1.86,5.75],[2,1.89,15]],"ltp":1.82,"tv":9226.88,"id":8681938}]}]}
{"op":"mcm","clk":"4296849753","pt":1632570538268,"mc":[{"id":"1.188134680","rc":[{"batb":[[0,2.04,178.06],[1,2.02,165.63],[2,2,179.72]],"batl":[[0,2.48,152.16],[1,2.5,153.57],[2,2.6,2.46]],"ltp":2.36,"tv":2459.26,"id":9631939},{"batb":[[0,1.68,19.86],[1,1.67,266.47],[2,1.66,225.62]],"batl":[[0,1.95,12.9],[1,1.97,209.86],[2,1.98,183.26]],"ltp":1.82,"tv":9226.88,"id":8681938}]}]}
{"op":"mcm","clk":"4296849812","pt":1632570538657,"mc":[{"id":"1.188134680","rc":[{"batl":[[0,2.48,149.42]],"ltp":2.36,"tv":2459.26,"id":9631939},{"batb":[[0,1.67,266.47],[1,1.66,225.62],[2,1.64,182.8]],"ltp":1.82,"tv":9226.88,"id":8681938}]}]}
{"op":"mcm","clk":"4296850029","pt":1632570540236,"mc":[{"id":"1.188134680","rc":[{"batb":[[0,2.04,200.55]],"ltp":2.36,"tv":2459.26,"id":9631939},{"batb":[[2,1.65,276.27]],"batl":[[0,1.93,294.67],[1,1.95,315.09],[2,1.97,209.86]],"ltp":1.82,"tv":9226.88,"id":8681938}]}]}
{"op":"mcm","clk":"4296850235","pt":1632570541368,"mc":[{"id":"1.188134680","rc":[{"batb":[[0,2.08,17.81],[1,2.04,182.43],[2,2.02,165.63]],"batl":[[0,2.6,2.46],[1,2.62,2.75],[2,2.66,4]],"ltp":2.36,"tv":2459.26,"id":9631939},{"batb":[[0,1.64,182.8],[1,1.63,18.23],[2,1.62,20.04]],"batl":[[0,1.92,6.31],[1,1.93,294.67],[2,1.95,321.59]],"ltp":1.82,"tv":9226.88,"id":8681938}]}]}
{"op":"mcm","clk":"4296850376","pt":1632570542164,"mc":[{"id":"1.188134680","rc":[{"batb":[[0,2.04,182.43],[1,2.02,165.63],[2,2,179.72]],"ltp":2.36,"tv":2459.26,"id":9631939},{"batb":[[0,1.67,5],[1,1.66,6],[2,1.64,182.8]],"batl":[[0,1.93,294.67],[1,1.95,321.59],[2,1.97,209.86]],"ltp":1.82,"tv":9226.88,"id":8681938}]}]}
{"op":"mcm","clk":"4296850455","pt":1632570542548,"mc":[{"id":"1.188134680","rc":[{"batl":[[0,1.82,73.13],[1,1.93,294.67],[2,1.95,321.59]],"ltp":1.82,"tv":9226.88,"id":8681938}]}]}
{"op":"mcm","clk":"4296850755","pt":1632570544360,"mc":[{"id":"1.188134680","rc":[{"batl":[[0,2.12,13.43],[1,2.14,3.25],[2,2.16,91.74]],"ltp":2.36,"tv":2459.26,"id":9631939},{"trd":[[1.82,160.39]],"batb":[[0,1.89,10.41],[1,1.86,356.97],[2,1.84,875.67]],"batl":[[0,1.93,294.67],[1,1.94,7.25]],"ltp":1.82,"tv":9373.15,"id":8681938}],"tv":11832.42}]}
{"op":"mcm","clk":"4296850981","pt":1632570545375,"mc":[{"id":"1.188134680","rc":[{"trd":[[2.12,112.2]],"batl":[[0,2.12,8.56]],"ltp":2.12,"tv":2464.13,"id":9631939},{"trd":[[1.89,1719.35]],"batb":[[0,1.86,475.85],[1,1.84,875.67],[2,1.83,504.42]],"ltp":1.89,"tv":9399.43,"id":8681938}],"tv":11863.57}]}
{"op":"mcm","clk":"4296851224","pt":1632570546975,"mc":[{"id":"1.188134680","rc":[{"batb":[[1,1.85,5],[2,1.84,895.99]],"ltp":1.89,"tv":9399.43,"id":8681938}]}]}
{"op":"mcm","clk":"4296851422","pt":1632570548356,"mc":[{"id":"1.188134680","rc":[{"batl":[[0,1.92,193],[1,1.93,294.67],[2,1.94,7.25]],"ltp":1.89,"tv":9399.43,"id":8681938}]}]}
{"op":"mcm","clk":"4296851554","pt":1632570549374,"mc":[{"id":"1.188134680","rc":[{"trd":[[2.12,114.16]],"batb":[[1,2.02,180.33]],"batl":[[0,2.12,6.6]],"ltp":2.12,"tv":2466.09,"id":9631939},{"trd":[[1.89,1721.54]],"batb":[[0,1.88,15.58],[1,1.86,475.85],[2,1.85,5]],"ltp":1.89,"tv":9401.62,"id":8681938}],"tv":11867.72}]}
{"op":"mcm","clk":"4296851647","pt":1632570549963,"mc":[{"id":"1.188134680","rc":[{"batb":[[0,1.88,31.15],[1,1.87,31.04],[2,1.86,475.85]],"ltp":1.89,"tv":9401.62,"id":8681938}]}]}
{"op":"mcm","clk":"4296851796","pt":1632570550965,"mc":[{"id":"1.188134680","rc":[{"batb":[[1,2.02,184.07]],"ltp":2.12,"tv":2466.09,"id":9631939}]}]}
{"op":"mcm","clk":"4296852314","pt":1632570554280,"mc":[{"id":"1.188134680","rc":[{"trd":[[2.12,115.9]],"batl":[[0,2.12,4.86]],"ltp":2.12,"tv":2467.83,"id":9631939},{"trd":[[1.89,1723.49]],"ltp":1.89,"tv":9403.57,"id":8681938}],"tv":11871.41}]}
{"op":"mcm","clk":"4296852466","pt":1632570555362,"mc":[{"id":"1.188134680","rc":[{"trd":[[2.12,117.44]],"batl":[[0,2.14,3.25],[1,2.18,4],[2,2.22,17.33]],"ltp":2.12,"tv":2469.37,"id":9631939},{"trd":[[1.89,1725.22]],"batl":[[2,1.95,321.59]],"ltp":1.89,"tv":9405.3,"id":8681938}],"tv":11874.68}]}
{"op":"mcm","clk":"4296852563","pt":1632570556099,"mc":[{"id":"1.188134680","rc":[{"batb":[[0,2.04,4.37],[1,2.02,18.44],[2,2,3]],"batl":[[0,2.22,13.58],[1,2.28,3.34],[2,2.32,193.52]],"ltp":2.12,"tv":2469.37,"id":9631939},{"batb":[[1,1.84,16.32],[2,1.82,66.25]],"batl":[[1,1.95,6.5],[2,1.96,13.62]],"ltp":1.89,"tv":9405.3,"id":8681938}]}]}
{"op":"mcm","clk":"4296852802","pt":1632570557297,"mc":[{"id":"1.188134680","rc":[{"batb":[[0,2.02,3.74],[1,2,3],[2,1.99,174.84]],"batl":[[0,2.28,3.34],[1,2.32,193.52],[2,2.34,209.27]],"ltp":2.12,"tv":2469.37,"id":9631939},{"batb":[[2,1.79,15.31]],"batl":[[0,1.98,10.75],[1,2,4],[2,2.02,165.57]],"ltp":1.89,"tv":9405.3,"id":8681938}]}]}
{"op":"mcm","clk":"4296852945","pt":1632570558184,"mc":[{"id":"1.188134680","rc":[{"batb":[[2,1.99,169.84]],"ltp":2.12,"tv":2469.37,"id":9631939},{"batb":[[0,1.79,15.31],[1,1.75,183.59],[2,1.74,275.78]],"ltp":1.89,"tv":9405.3,"id":8681938}]}]}
{"op":"mcm","clk":"4296853130","pt":1632570559263,"mc":[{"id":"1.188134680","rc":[{"batl":[[0,2.22,4.25],[1,2.28,3.34],[2,2.32,193.52]],"ltp":2.12,"tv":2469.37,"id":9631939},{"batb":[[0,1.82,14.64],[1,1.79,15.31],[2,1.75,450.13]],"batl":[[1,1.99,316.93],[2,2,4]],"ltp":1.89,"tv":9405.3,"id":8681938}]}]}
{"op":"mcm","clk":"4296853282","pt":1632570560278,"mc":[{"id":"1.188134680","rc":[{"batl":[[0,2.08,2.35]],"ltp":2.12,"tv":2469.37,"id":9631939},{"batb":[[0,1.79,15.31],[1,1.75,450.13],[2,1.74,275.78]],"ltp":1.89,"tv":9405.3,"id":8681938}]}]}
{"op":"mcm","clk":"4296853331","pt":1632570560585,"mc":[{"id":"1.188134680","rc":[{"trd":[[2.08,112.29]],"batl":[[0,2.28,3.34],[1,2.32,193.52],[2,2.34,209.27]],"ltp":2.08,"tv":2471.72,"id":9631939},{"trd":[[1.92,192.29]],"batl":[[0,1.92,1.76],[1,1.98,10.75],[2,1.99,316.93]],"ltp":1.92,"tv":9407.84,"id":8681938}],"tv":11879.57}]}
{"op":"mcm","clk":"4296853621","pt":1632570562359,"mc":[{"id":"1.188134680","rc":[{"batb":[[2,1.98,197.26]],"ltp":2.08,"tv":2471.72,"id":9631939}]}]}
{"op":"mcm","clk":"4296853724","pt":1632570562984,"mc":[{"id":"1.188134680","rc":[{"batl":[[2,2,4]],"ltp":1.92,"tv":9407.84,"id":8681938}]}]}
{"op":"mcm","clk":"4296854145","pt":1632570565283,"mc":[{"id":"1.188134680","rc":[{"trd":[[2.28,9.11]],"batb":[[0,2.22,1076.86],[1,2.2,418.08],[2,2.18,1045.19]],"batl":[[0,2.28,2.14],[1,2.32,199.9]],"ltp":2.28,"tv":2472.92,"id":9631939},{"trd":[[1.78,66.2],[1.79,30.62]],"batb":[[0,1.75,450.13],[1,1.74,275.78],[2,1.73,584.83]],"batl":[[0,1.8,16.76],[1,1.86,158.7],[2,1.92,1.76]],"ltp":1.78,"tv":9440.0,"id":8681938}],"tv":11912.93}]}
{"op":"mcm","clk":"4296854316","pt":1632570566382,"mc":[{"id":"1.188134680","rc":[{"batb":[[0,2.22,570.25],[2,2.18,430.79]],"batl":[[1,2.32,193.52]],"ltp":2.28,"tv":2472.92,"id":9631939},{"batl":[[0,1.81,400.17],[1,1.83,366.86],[2,1.85,15]],"ltp":1.78,"tv":9440.0,"id":8681938}]}]}
{"op":"mcm","clk":"4296854798","pt":1632570569291,"mc":[{"id":"1.188134680","rc":[{"batb":[[2,2.18,418.08]],"ltp":2.28,"tv":2472.92,"id":9631939},{"batl":[[1,1.83,369.05]],"ltp":1.78,"tv":9440.0,"id":8681938}]}]}
{"op":"mcm","clk":"4296854993","pt":1632570570380,"mc":[{"id":"1.188134680","rc":[{"trd":[[2.28,11.25]],"batl":[[0,2.32,193.52],[1,2.34,209.27],[2,2.36,83.6]],"ltp":2.28,"tv":2475.06,"id":9631939},{"trd":[[1.78,68.94]],"batb":[[0,1.76,29.64],[1,1.75,450.13],[2,1.74,275.78]],"batl":[[0,1.8,1.88],[1,1.81,400.17],[2,1.83,369.05]],"ltp":1.78,"tv":9442.74,"id":8681938}],"tv":11917.81}]}
{"op":"mcm","clk":"4296855149","pt":1632570571286,"mc":[{"id":"1.188134680","rc":[{"trd":[[2.22,20.98],[2.24,1.51]],"batb":[[0,2.22,566.76]],"ltp":2.22,"tv":2483.55,"id":9631939},{"trd":[[1.8,42.84]],"batl":[[0,1.81,400.17],[1,1.83,366.86],[2,1.86,158.7]],"ltp":1.8,"tv":9444.62,"id":8681938}],"tv":11928.18}]}
{"op":"mcm","clk":"4296855266","pt":1632570571877,"mc":[{"id":"1.188134680","rc":[{"batb":[[1,2.2,430.58]],"batl":[[0,2.32,199.9]],"ltp":2.22,"tv":2483.55,"id":9631939},{"batb":[[0,1.76,47.67]],"batl":[[0,1.8,16.76],[1,1.81,400.17],[2,1.83,366.86]],"ltp":1.8,"tv":9444.62,"id":8681938}]}]}
{"op":"mcm","clk":"4296855550","pt":1632570573671,"mc":[{"id":"1.188134680","rc":[{"batl":[[2,1.83,381.86]],"ltp":1.8,"tv":9444.62,"id":8681938}]}]}
{"op":"mcm","clk":"4296855948","pt":1632570576309,"mc":[{"id":"1.188134680","rc":[{"batl":[[0,1.8,120.76]],"ltp":1.8,"tv":9444.62,"id":8681938}]}]}
{"op":"mcm","clk":"4296856228","pt":1632570578380,"mc":[{"id":"1.188134680","rc":[{"batl":[[0,2.32,223.75]],"ltp":2.22,"tv":2483.55,"id":9631939}]}]}
{"op":"mcm","clk":"4296856302","pt":1632570578894,"mc":[{"id":"1.188134680","rc":[{"batl":[[0,1.8,200.76]],"ltp":1.8,"tv":9444.62,"id":8681938}]}]}
{"op":"mcm","clk":"4296856491","pt":1632570580073,"mc":[{"id":"1.188134680","rc":[{"batb":[[0,1.76,29.64]],"ltp":1.8,"tv":9444.62,"id":8681938}]}]}
{"op":"mcm","clk":"4296856832","pt":1632570582295,"mc":[{"id":"1.188134680","rc":[{"batb":[[0,2.22,139.51],[1,2.2,12.5],[2,2.14,2.45]],"batl":[[0,2.42,12.58],[1,2.66,4],[2,2.7,128.21]],"ltp":2.22,"tv":2483.55,"id":9631939},{"trd":[[1.76,84.2],[1.8,44.1]],"batb":[[0,1.75,266.54],[1,1.73,584.83],[2,1.7,71.71]],"batl":[[0,1.8,184]],"ltp":1.76,"tv":9455.88,"id":8681938}],"tv":11939.44}]}
{"op":"mcm","clk":"4296856931","pt":1632570582887,"mc":[{"id":"1.188134680","rc":[{"batb":[[0,2.2,12.5],[1,2.1,5.75],[2,2.08,169.86]],"ltp":2.22,"tv":2483.55,"id":9631939},{"batb":[[0,1.7,71.71],[1,1.59,23.23],[2,1.58,282.4]],"batl":[[0,1.83,15],[1,1.91,21.33],[2,1.94,197.32]],"ltp":1.76,"tv":9455.88,"id":8681938}]}]}
{"op":"mcm","clk":"4296857059","pt":1632570583716,"mc":[{"id":"1.188134680","rc":[{"batb":[[0,2.1,5.75],[1,2.08,169.86],[2,2.06,178.75]],"batl":[[0,2.66,4],[1,2.7,128.21],[2,2.72,166.85]],"ltp":2.22,"tv":2483.55,"id":9631939},{"batb":[[0,1.59,23.23],[1,1.58,282.4],[2,1.57,316.01]],"batl":[[0,1.94,197.32],[1,1.95,205.88],[2,1.98,10.75]],"ltp":1.76,"tv":9455.88,"id":8681938}]}]}
{"op":"mcm","clk":"4296857307","pt":1632570585309,"mc":[{"id":"1.188134680","rc":[{"batl":[[0,2.36,4],[1,2.66,4],[2,2.7,128.21]],"ltp":2.22,"tv":2483.55,"id":9631939},{"batl":[[0,1.91,255.75],[1,1.93,312.04],[2,1.94,197.32]],"ltp":1.76,"tv":9455.88,"id":8681938}]}]}
{"op":"mcm","clk":"4296857462","pt":1632570586210,"mc":[{"id":"1.188134680","rc":[{"batl":[[0,2.66,4],[1,2.7,128.21],[2,2.72,166.85]],"ltp":2.22,"tv":2483.55,"id":9631939},{"batl":[[0,1.94,197.32],[1,1.95,205.88],[2,1.98,10.75]],"ltp":1.76,"tv":9455.88,"id":8681938}]}]}
{"op":"mcm","clk":"4296857644","pt":1632570587290,"mc":[{"id":"1.188134680","rc":[{"batb":[[0,1.81,26.36],[1,1.6,5],[2,1.59,29.23]],"ltp":1.76,"tv":9455.88,"id":8681938}]}]}
{"op":"mcm","clk":"4296857818","pt":1632570588291,"mc":[{"id":"1.188134680","rc":[{"batl":[[0,2.4,20.44],[1,2.66,4],[2,2.7,128.21]],"ltp":2.22,"tv":2483.55,"id":9631939},{"trd":[[1.81,81.43]],"batb":[[0,1.81,7.09],[1,1.71,18.19],[2,1.6,5]],"ltp":1.81,"tv":9494.42,"id":8681938}],"tv":11977.98}]}
{"op":"mcm","clk":"4296857973","pt":1632570589305,"mc":[{"id":"1.188134680","rc":[{"batb":[[1,2.08,173.67]],"batl":[[0,2.66,4],[1,2.7,128.21],[2,2.72,166.85]],"ltp":2.22,"tv":2483.55,"id":9631939},{"trd":[[1.81,95.62]],"batb":[[0,1.7,462.73],[1,1.68,481.81]],"batl":[[0,1.76,305.62],[1,1.78,400.8],[2,1.94,197.32]],"ltp":1.81,"tv":9508.6,"id":8681938}],"tv":11992.16}]}
{"op":"mcm","clk":"4296858067","pt":1632570589881,"mc":[{"id":"1.188134680","rc":[{"batb":[[1,2.08,169.86]],"ltp":2.22,"tv":2483.55,"id":9631939}]}]}
{"op":"mcm","clk":"4296858296","pt":1632570591326,"mc":[{"id":"1.188134680","rc":[{"batb":[[0,2.12,29.2],[1,2.1,5.3],[2,2.08,169.86]],"batl":[[0,2.64,20],[1,2.66,4],[2,2.7,128.21]],"ltp":2.22,"tv":2483.55,"id":9631939},{"batl":[[2,1.91,20]],"ltp":1.81,"tv":9508.6,"id":8681938}]}]}
{"op":"mcm","clk":"4296858460","pt":1632570592328,"mc":[{"id":"1.188134680","rc":[{"batb":[[0,2.1,5.75],[1,2.08,169.86],[2,2.06,178.75]],"batl":[[0,2.66,4],[1,2.7,128.21],[2,2.72,166.85]],"ltp":2.22,"tv":2483.55,"id":9631939},{"trd":[[1.76,88.58]],"batb":[[0,1.61,22.47],[1,1.6,5],[2,1.59,6]],"batl":[[0,1.91,20],[1,1.94,197.32],[2,1.95,205.88]],"ltp":1.76,"tv":9512.99,"id":8681938}],"tv":11996.54}]}
{"op":"mcm","clk":"4296858616","pt":1632570593235,"mc":[{"id":"1.188134680","rc":[{"batb":[[0,1.6,5],[1,1.59,6],[2,1.58,282.4]],"batl":[[0,1.94,197.32],[1,1.95,205.88],[2,1.98,10.75]],"ltp":1.76,"tv":9512.99,"id":8681938}]}]}
{"op":"mcm","clk":"4296858661","pt":1632570593501,"mc":[{"id":"1.188134680","rc":[{"batb":[[0,1.6,27.84]],"ltp":1.76,"tv":9512.99,"id":8681938}]}]}
{"op":"mcm","clk":"4296858938","pt":1632570595315,"mc":[{"id":"1.188134680","rc":[{"batl":[[0,1.91,252.03],[1,1.93,312.04],[2,1.94,197.32]],"ltp":1.76,"tv":9512.99,"id":8681938}]}]}
{"op":"mcm","clk":"4296859086","pt":1632570596183,"mc":[{"id":"1.188134680","rc":[{"batb":[[1,2.08,173.67]],"ltp":2.22,"tv":2483.55,"id":9631939},{"batl":[[0,1.91,272.14]],"ltp":1.76,"tv":9512.99,"id":8681938}]}]}
{"op":"mcm","clk":"4296859535","pt":1632570599089,"mc":[{"id":"1.188134680","rc":[{"batb":[[1,2.08,169.86]],"ltp":2.22,"tv":2483.55,"id":9631939},{"batb":[[1,1.59,23.23]],"ltp":1.76,"tv":9512.99,"id":8681938}]}]}
{"op":"mcm","clk":"4296859667","pt":1632570599981,"mc":[{"id":"1.188134680","rc":[{"batb":[[0,2.08,170.31],[1,2.06,178.75],[2,2.04,259.07]],"ltp":2.22,"tv":2483.55,"id":9631939}]}]}
{"op":"mcm","clk":"4296860036","pt":1632570602324,"mc":[{"id":"1.188134680","rc":[{"batb":[[0,2.08,173.87]],"ltp":2.22,"tv":2483.55,"id":9631939},{"batb":[[1,1.59,28.23]],"ltp":1.76,"tv":9512.99,"id":8681938}]}]}
{"op":"mcm","clk":"4296860201","pt":1632570603204,"mc":[{"id":"1.188134680","rc":[{"batb":[[0,2.14,5.65],[1,2.08,169.86],[2,2.06,178.75]],"ltp":2.22,"tv":2483.55,"id":9631939}]}]}
{"op":"mcm","clk":"4296860470","pt":1632570604809,"mc":[{"id":"1.188134680","rc":[{"trd":[[2.14,1.85],[2.16,111.34]],"batb":[[0,2.14,3.73],[2,2.04,4.37]],"ltp":2.14,"tv":2485.47,"id":9631939},{"trd":[[1.87,512.77],[1.88,341.08]],"batl":[[0,1.95,6.1],[1,2,4],[2,4.4,3.34]],"ltp":1.88,"tv":9515.18,"id":8681938}],"tv":12000.66}]}
{"op":"mcm","clk":"4296860852","pt":1632570607205,"mc":[{"id":"1.188134680","rc":[{"batb":[[0,2.62,1459.92],[1,2.6,1416.98],[2,2.58,1416.98]],"batl":[[0,2.7,128.21],[1,2.72,166.85],[2,2.78,13.41]],"ltp":2.14,"tv":2485.47,"id":9631939},{"trd":[[1.6,72.87]],"batb":[[0,1.6,12.16],[1,1.59,23.23]],"batl":[[0,1.61,18.63],[1,1.95,6.1],[2,2,4]],"ltp":1.6,"tv":9536.54,"id":8681938}],"tv":12022.02}]}
{"op":"mcm","clk":"4296861024","pt":1632570608311,"mc":[{"id":"1.188134680","rc":[{"batb":[[0,2.62,364.98],[1,2.6,366.83],[2,2.58,354.24]],"batl":[[0,2.72,166.85],[1,2.78,13.41],[2,2.8,2.52]],"ltp":2.14,"tv":2485.47,"id":9631939},{"trd":[[1.6,97.2]],"batb":[[0,1.59,23.23],[1,1.58,282.4],[2,1.57,316.01]],"batl":[[0,1.6,254.69],[1,1.61,298.39],[2,1.62,12.5]],"ltp":1.6,"tv":9560.86,"id":8681938}],"tv":12046.34}]}
{"op":"mcm","clk":"4296861205","pt":1632570609306,"mc":[{"id":"1.188134680","rc":[{"batb":[[0,2.66,87.85],[1,2.62,364.98],[2,2.6,366.83]],"ltp":2.14,"tv":2485.47,"id":9631939}]}]}
{"op":"mcm","clk":"4296861737","pt":1632570612333,"mc":[{"id":"1.188134680","rc":[{"trd":[[1.59,62.52]],"batb":[[0,1.59,4.34]],"batl":[[0,1.6,630.69]],"ltp":1.59,"tv":9598.64,"id":8681938}],"tv":12084.12}]}
{"op":"mcm","clk":"4296862090","pt":1632570614301,"mc":[{"id":"1.188134680","rc":[{"batb":[[0,1.58,282.4],[1,1.57,316.01],[2,1.56,362.74]],"ltp":1.59,"tv":9598.64,"id":8681938}]}]}
{"op":"mcm","clk":"4296862168","pt":1632570614823,"mc":[{"id":"1.188134680","rc":[{"batl":[[0,1.6,650.69]],"ltp":1.59,"tv":9598.64,"id":8681938}]}]}
{"op":"mcm","clk":"4296862370","pt":1632570615910,"mc":[{"id":"1.188134680","rc":[{"trd":[[1.6,97.36]],"batl":[[0,1.6,650.61]],"ltp":1.6,"tv":9598.8,"id":8681938}],"tv":12084.28}]}
{"op":"mcm","clk":"4296862527","pt":1632570616905,"mc":[{"id":"1.188134680","rc":[{"trd":[[1.6,111.45]],"batl":[[0,1.6,437.62]],"ltp":1.6,"tv":9612.9,"id":8681938}],"tv":12098.37}]}
{"op":"mcm","clk":"4296862783","pt":1632570618303,"mc":[{"id":"1.188134680","rc":[{"batb":[[2,2.6,376.2]],"batl":[[1,2.8,2.52],[2,2.84,102.25]],"ltp":2.14,"tv":2485.47,"id":9631939},{"trd":[[1.59,63.79]],"batl":[[0,1.59,5.41],[1,1.6,670.62],[2,1.61,298.39]],"ltp":1.59,"tv":9614.16,"id":8681938}],"tv":12099.63}]}
{"op":"mcm","clk":"4296863019","pt":1632570619825,"mc":[{"id":"1.188134680","rc":[{"batl":[[2,1.61,552.98]],"ltp":1.59,"tv":9614.16,"id":8681938}]}]}
{"op":"mcm","clk":"4296863156","pt":1632570620628,"mc":[{"id":"1.188134680","rc":[{"batl":[[0,2.72,176.37]],"ltp":2.14,"tv":2485.47,"id":9631939},{"trd":[[1.59,68.48]],"batl":[[0,1.59,3.06]],"ltp":1.59,"tv":9618.85,"id":8681938}],"tv":12104.33}]}
{"op":"mcm","clk":"4296863418","pt":1632570622315,"mc":[{"id":"1.188134680","rc":[{"batl":[[1,1.6,650.62]],"ltp":1.59,"tv":9618.85,"id":8681938}]}]}
{"op":"mcm","clk":"4296863590","pt":1632570623329,"mc":[{"id":"1.188134680","rc":[{"trd":[[2.68,0.28]],"ltp":2.68,"tv":2485.75,"id":9631939},{"trd":[[1.59,68.95]],"batl":[[0,1.59,2.59]],"ltp":1.59,"tv":9619.32,"id":8681938}],"tv":12105.08}]}
{"op":"mcm","clk":"4296863861","pt":1632570624918,"mc":[{"id":"1.188134680","rc":[{"trd":[[2.72,9.52]],"batl":[[0,2.8,2.52],[1,2.84,102.25],[2,2.88,332.04]],"ltp":2.72,"tv":2495.27,"id":9631939},{"trd":[[1.58,16.39]],"batb":[[0,1.57,316.01],[1,1.56,362.74],[2,1.55,548.44]],"batl":[[0,1.58,3.61],[1,1.59,2.59],[2,1.6,650.62]],"ltp":1.58,"tv":9635.71,"id":8681938}],"tv":12130.99}]}
{"op":"mcm","clk":"4296864361","pt":1632570628148,"mc":[{"id":"1.188134680","rc":[{"batl":[[0,2.78,12.6],[1,2.8,2.52],[2,2.84,102.25]],"ltp":2.72,"tv":2495.27,"id":9631939},{"batb":[[0,1.57,347.82]],"ltp":1.58,"tv":9635.71,"id":8681938}]}]}
{"op":"mcm","clk":"4296864518","pt":1632570629146,"mc":[{"id":"1.188134680","rc":[{"trd":[[1.58,16.55]],"batb":[[0,1.57,316.01]],"batl":[[0,1.58,3.53]],"ltp":1.58,"tv":9635.87,"id":8681938}],"tv":12131.15}]}
{"op":"mcm","clk":"4296864697","pt":1632570630230,"mc":[{"id":"1.188134680","rc":[{"batb":[[0,2.6,19.96],[1,2.28,131.48],[2,2.22,17.86]],"batl":[[0,2.9,10.88],[1,3.45,184.03],[2,5,2]],"ltp":2.72,"tv":2495.27,"id":9631939},{"batb":[[0,1.53,82.41],[1,1.27,536.39],[2,1.25,52.37]],"ltp":1.58,"tv":9635.87,"id":8681938}]}]}
{"op":"mcm","clk":"4296864854","pt":1632570631350,"mc":[{"id":"1.188134680","rc":[{"batb":[[0,2.6,10.59]],"batl":[[0,3.45,184.03],[1,5,2],[2,5.8,2.54]],"ltp":2.72,"tv":2495.27,"id":9631939},{"batb":[[0,1.27,536.39],[1,1.25,52.37],[2,1.16,70.78]],"batl":[[0,1.58,49.6],[2,1.6,41.62]],"ltp":1.58,"tv":9635.87,"id":8681938}]}]}
{"op":"mcm","clk":"4296865158","pt":1632570633130,"mc":[{"id":"1.188134680","rc":[{"batb":[[2,2.26,133.08]],"ltp":2.72,"tv":2495.27,"id":9631939},{"batb":[[0,1.29,966.58],[1,1.28,1332.36],[2,1.27,536.39]],"ltp":1.58,"tv":9635.87,"id":8681938}]}]}
{"op":"mcm","clk":"4296865242","pt":1632570633640,"mc":[{"id":"1.188134680","rc":[{"batb":[[1,2.26,133.08],[2,2.22,17.86]],"ltp":2.72,"tv":2495.27,"id":9631939},{"batb":[[2,1.25,52.37]],"ltp":1.58,"tv":9635.87,"id":8681938}]}]}
{"op":"mcm","clk":"4296865543","pt":1632570635534,"mc":[{"id":"1.188134680","rc":[{"batb":[[0,2.26,133.08],[1,2.22,17.86],[2,2.16,4]],"ltp":2.72,"tv":2495.27,"id":9631939}]}]}
{"op":"mcm","clk":"4296865925","pt":1632570637628,"mc":[{"id":"1.188134680","rc":[{"batb":[[1,2.22,14.34]],"ltp":2.72,"tv":2495.27,"id":9631939}]}]}
{"op":"mcm","clk":"4296866101","pt":1632570638631,"mc":[{"id":"1.188134680","rc":[{"trd":[[1.58,16.66]],"batl":[[0,1.58,49.54]],"ltp":1.58,"tv":9635.99,"id":8681938}],"tv":12131.27}]}
{"op":"mcm","clk":"4296866432","pt":1632570640340,"mc":[{"id":"1.188134680","rc":[{"batl":[[0,4.2,84.72],[1,4.7,813.84],[2,4.8,493.69]],"ltp":2.72,"tv":2495.27,"id":9631939},{"trd":[[1.33,24.58]],"batl":[[0,1.33,706.69],[1,1.34,697.84],[2,1.35,697.84]],"ltp":1.33,"tv":9660.57,"id":8681938}],"tv":12155.85}]}
{"op":"mcm","clk":"4296866607","pt":1632570641249,"mc":[{"id":"1.188134680","rc":[{"batl":[[0,4.2,93.57],[1,4.7,203.46],[2,4.8,197.48]],"ltp":2.72,"tv":2495.27,"id":9631939},{"batl":[[0,1.32,432.23],[1,1.33,1314.19],[2,1.34,697.84]],"ltp":1.33,"tv":9660.57,"id":8681938}]}]}
{"op":"mcm","clk":"4296866817","pt":1632570642310,"mc":[{"id":"1.188134680","rc":[{"batb":[[0,4.1,146.1],[1,3.55,102.64],[2,3.45,370.29]],"ltp":2.72,"tv":2495.27,"id":9631939},{"batb":[[0,1.3,109.54],[1,1.29,966.58],[2,1.28,1332.36]],"ltp":1.33,"tv":9660.57,"id":8681938}]}]}
{"op":"mcm","clk":"4296867016","pt":1632570643275,"mc":[{"id":"1.188134680","rc":[{"batl":[[1,4.4,8.13],[2,4.5,2]],"ltp":2.72,"tv":2495.27,"id":9631939},{"trd":[[1.32,15.3]],"batb":[[0,1.29,1024.5],[1,1.28,1335.36],[2,1.25,644.99]],"batl":[[0,1.32,424.58]],"ltp":1.32,"tv":9675.87,"id":8681938}],"tv":12171.15}]}
{"op":"mcm","clk":"4296867183","pt":1632570644274,"mc":[{"id":"1.188134680","rc":[{"batb":[[2,3.45,128.78]],"ltp":2.72,"tv":2495.27,"id":9631939}]}]}
{"op":"mcm","clk":"4296867321","pt":1632570645185,"mc":[{"id":"1.188134680","rc":[{"batb":[[2,3.4,73.53]],"batl":[[1,4.3,57.16],[2,4.4,8.13]],"ltp":2.72,"tv":2495.27,"id":9631939},{"batl":[[2,1.34,733.09]],"ltp":1.32,"tv":9675.87,"id":8681938}]}]}
{"op":"mcm","clk":"4296867427","pt":1632570645785,"mc":[{"id":"1.188134680","rc":[{"batb":[[1,3.75,5.45],[2,3.55,102.64]],"batl":[[1,4.4,8.13],[2,4.5,2]],"ltp":2.72,"tv":2495.27,"id":9631939},{"batb":[[0,1.29,1135.91]],"batl":[[0,1.32,979.58],[2,1.34,697.84]],"ltp":1.32,"tv":9675.87,"id":8681938}]}]}
{"op":"mcm","clk":"4296867629","pt":1632570647017,"mc":[{"id":"1.188134680","rc":[{"batb":[[1,3.55,102.64],[2,3.4,73.53]],"ltp":2.72,"tv":2495.27,"id":9631939}]}]}
{"op":"mcm","clk":"4296867804","pt":1632570647913,"mc":[{"id":"1.188134680","rc":[{"batb":[[1,3.55,233.39],[2,3.5,117.45]],"ltp":2.72,"tv":2495.27,"id":9631939},{"batb":[[2,1.27,436.64]],"ltp":1.32,"tv":9675.87,"id":8681938}]}]}
{"op":"mcm","clk":"4296868052","pt":1632570649186,"mc":[{"id":"1.188134680","rc":[{"trd":[[1.32,15.46]],"batb":[[1,1.28,6539.3]],"batl":[[0,1.32,979.5]],"ltp":1.32,"tv":9676.03,"id":8681938}],"tv":12171.31}]}
{"op":"mcm","clk":"4296868233","pt":1632570650200,"mc":[{"id":"1.188134680","rc":[{"trd":[[4.1,64.93]],"batb":[[0,4.1,113.64],[1,3.85,5.26],[2,3.55,233.39]],"ltp":4.1,"tv":2560.2,"id":9631939}],"tv":12236.23}]}
{"op":"mcm","clk":"4296868436","pt":1632570651204,"mc":[{"id":"1.188134680","rc":[{"batl":[[0,4.2,91.86]],"ltp":4.1,"tv":2560.2,"id":9631939},{"trd":[[1.32,17.72]],"batb":[[1,1.28,6585.71]],"batl":[[0,1.32,978.37]],"ltp":1.32,"tv":9678.29,"id":8681938}],"tv":12238.49}]}
{"op":"mcm","clk":"4296868484","pt":1632570651440,"mc":[{"id":"1.188134680","rc":[{"batb":[[1,1.28,6539.3]],"ltp":1.32,"tv":9678.29,"id":8681938}]}]}
{"op":"mcm","clk":"4296868751","pt":1632570652900,"mc":[{"id":"1.188134680","rc":[{"trd":[[1.32,17.96]],"batl":[[0,1.32,3022.25]],"ltp":1.32,"tv":9678.53,"id":8681938}],"tv":12238.73}]}
{"op":"mcm","clk":"4296868986","pt":1632570654287,"mc":[{"id":"1.188134680","rc":[{"trd":[[4.1,73.19]],"batb":[[0,4.1,109.51]],"ltp":4.1,"tv":2568.46,"id":9631939},{"batb":[[0,1.29,1086.31]],"ltp":1.32,"tv":9678.53,"id":8681938}],"tv":12246.99}]}
{"op":"mcm","clk":"4296869117","pt":1632570654985,"mc":[{"id":"1.188134680","rc":[{"trd":[[4.1,83.35],[4.2,3.8]],"batb":[[0,4.1,104.43]],"batl":[[0,4.2,89.96]],"ltp":4.1,"tv":2582.42,"id":9631939},{"batb":[[1,1.28,6536.3]],"ltp":1.32,"tv":9678.53,"id":8681938}],"tv":12260.96}]}
{"op":"mcm","clk":"4296869262","pt":1632570655885,"mc":[{"id":"1.188134680","rc":[{"trd":[[4.2,18.17]],"batl":[[0,4.2,75.59]],"ltp":4.2,"tv":2596.79,"id":9631939},{"trd":[[1.31,46.07],[1.32,25]],"batl":[[0,1.32,3018.73]],"ltp":1.32,"tv":9731.64,"id":8681938}],"tv":12328.44}]}
{"op":"mcm","clk":"4296869635","pt":1632570658236,"mc":[{"id":"1.188134680","rc":[{"batb":[[1,1.28,6586.46]],"ltp":1.32,"tv":9731.64,"id":8681938}]}]}
{"op":"mcm","clk":"4296869807","pt":1632570659247,"mc":[{"id":"1.188134680","rc":[{"trd":[[4.1,100.49]],"batb":[[0,4.1,95.86]],"ltp":4.1,"tv":2613.94,"id":9631939},{"trd":[[1.32,25.12]],"batb":[[1,1.28,6536.3]],"batl":[[0,1.32,4340.67]],"ltp":1.32,"tv":9731.76,"id":8681938}],"tv":12345.7}]}
{"op":"mcm","clk":"4296870073","pt":1632570661027,"mc":[{"id":"1.188134680","rc":[{"trd":[[1.32,25.3]],"batl":[[0,1.32,4340.58]],"ltp":1.32,"tv":9731.94,"id":8681938}],"tv":12345.88}]}
{"op":"mcm","clk":"4296870206","pt":1632570661705,"mc":[{"id":"1.188134680","rc":[{"trd":[[1.32,28.04]],"batb":[[1,1.28,6586.71]],"batl":[[0,1.32,4339.21]],"ltp":1.32,"tv":9734.68,"id":8681938}],"tv":12348.62}]}
{"op":"mcm","clk":"4296870419","pt":1632570662893,"mc":[{"id":"1.188134680","rc":[{"batb":[[1,1.28,6536.3]],"ltp":1.32,"tv":9734.68,"id":8681938}]}]}
{"op":"mcm","clk":"4296870716","pt":1632570664706,"mc":[{"id":"1.188134680","rc":[{"trd":[[1.32,39.78]],"batl":[[0,1.32,4333.34]],"ltp":1.32,"tv":9746.42,"id":8681938}],"tv":12360.36}]}
{"op":"mcm","clk":"4296870976","pt":1632570666082,"mc":[{"id":"1.188134680","rc":[{"batb":[[1,1.28,6578.71]],"ltp":1.32,"tv":9746.42,"id":8681938}]}]}
{"op":"mcm","clk":"4296871069","pt":1632570666608,"mc":[{"id":"1.188134680","rc":[{"trd":[[4.1,113.83]],"batb":[[0,4.1,89.19]],"ltp":4.1,"tv":2627.28,"id":9631939},{"batb":[[1,1.28,6536.3]],"batl":[[2,1.34,710.48]],"ltp":1.32,"tv":9746.42,"id":8681938}],"tv":12373.7}]}
{"op":"mcm","clk":"4296871459","pt":1632570668995,"mc":[{"id":"1.188134680","rc":[{"trd":[[4.2,18.2]],"batl":[[0,4.2,75.56]],"ltp":4.2,"tv":2627.31,"id":9631939},{"trd":[[1.31,46.17]],"ltp":1.31,"tv":9746.52,"id":8681938}],"tv":12373.83}]}
{"op":"mcm","clk":"4296871841","pt":1632570671326,"mc":[{"id":"1.188134680","rc":[{"batb":[[1,1.28,1332.36]],"ltp":1.31,"tv":9746.52,"id":8681938}]}]}
{"op":"mcm","clk":"4296871979","pt":1632570672020,"mc":[{"id":"1.188134680","rc":[{"batb":[[0,3.85,5.26],[1,3.55,233.39],[2,3.5,117.45]],"batl":[[0,4.4,8.13],[1,4.5,2],[2,4.7,91.33]],"ltp":4.2,"tv":2627.31,"id":9631939},{"batb":[[0,1.29,114.41],[1,1.27,436.64],[2,1.26,393.68]],"batl":[[0,1.32,3921],[1,1.35,15],[2,1.39,358.88]],"ltp":1.31,"tv":9746.52,"id":8681938}]}]}
{"op":"mcm","clk":"4296872208","pt":1632570673309,"mc":[{"id":"1.188134680","rc":[{"batb":[[0,3.55,233.39],[1,3.5,117.45],[2,3.35,2.07]],"batl":[[0,4.5,2],[1,4.6,2]],"ltp":4.2,"tv":2627.31,"id":9631939},{"batb":[[0,1.29,3],[1,1.28,40.66],[2,1.27,436.64]],"batl":[[0,1.39,358.88],[1,1.4,313.47],[2,1.42,29.75]],"ltp":1.31,"tv":9746.52,"id":8681938}]}]}
{"op":"mcm","clk":"4296872343","pt":1632570674108,"mc":[{"id":"1.188134680","rc":[{"batb":[[0,1.3,731.97],[1,1.29,3],[2,1.28,40.66]],"ltp":1.31,"tv":9746.52,"id":8681938}]}]}
{"op":"mcm","clk":"4296872532","pt":1632570675233,"mc":[{"id":"1.188134680","rc":[{"batb":[[0,3.55,130.74],[1,3.5,224.07]],"ltp":4.2,"tv":2627.31,"id":9631939},{"batb":[[2,1.28,50.66]],"ltp":1.31,"tv":9746.52,"id":8681938}]}]}
{"op":"mcm","clk":"4296872615","pt":1632570675717,"mc":[{"id":"1.188134680","rc":[{"batb":[[0,1.29,3],[1,1.28,50.66],[2,1.27,436.64]],"ltp":1.31,"tv":9746.52,"id":8681938}]}]}
{"op":"mcm","clk":"4296872856","pt":1632570677208,"mc":[{"id":"1.188134680","rc":[{"batb":[[0,1.3,966.47],[1,1.29,742.59],[2,1.28,50.66]],"batl":[[0,1.33,325.93],[1,1.34,587.05],[2,1.39,358.88]],"ltp":1.31,"tv":9746.52,"id":8681938}]}]}
{"op":"mcm","clk":"4296872991","pt":1632570678016,"mc":[{"id":"1.188134680","rc":[{"batl":[[0,4.2,38.33],[1,4.5,2],[2,4.6,2]],"ltp":4.2,"tv":2627.31,"id":9631939},{"batb":[[0,1.32,36.89],[1,1.3,966.47],[2,1.29,742.59]],"batl":[[1,1.34,627.3]],"ltp":1.31,"tv":9746.52,"id":8681938}]}]}
{"op":"mcm","clk":"4296873112","pt":1632570678618,"mc":[{"id":"1.188134680","rc":[{"batb":[[0,3.6,49.52],[1,3.55,130.74],[2,3.5,224.07]],"batl":[[0,4.4,10]],"ltp":4.2,"tv":2627.31,"id":9631939},{"batb":[[0,1.32,2.35],[1,1.3,1023.95]],"batl":[[1,1.34,587.05],[2,1.38,119.76]],"ltp":1.31,"tv":9746.52,"id":8681938}]}]}
{"op":"mcm","clk":"4296873258","pt":1632570679517,"mc":[{"id":"1.188134680","rc":[{"batb":[[0,1.32,4.7]],"ltp":1.31,"tv":9746.52,"id":8681938}]}]}
{"op":"mcm","clk":"4296873531","pt":1632570681223,"mc":[{"id":"1.188134680","rc":[{"batb":[[0,3.55,130.74],[1,3.5,224.07],[2,3.35,2.07]],"batl":[[0,4.5,2],[1,4.6,2],[2,4.7,91.33]],"ltp":4.2,"tv":2627.31,"id":9631939},{"batb":[[1,1.29,3],[2,1.28,50.66]],"batl":[[0,1.39,358.88],[1,1.4,313.47],[2,1.42,29.75]],"ltp":1.31,"tv":9746.52,"id":8681938}]}]}
{"op":"mcm","clk":"4296873613","pt":1632570681742,"mc":[{"id":"1.188134680","rc":[{"trd":[[1.32,49.17]],"batb":[[0,1.29,3],[1,1.28,50.66],[2,1.27,436.64]],"batl":[[0,1.31,7.01],[1,1.39,358.88],[2,1.4,313.47]],"ltp":1.32,"tv":9755.91,"id":8681938}],"tv":12383.22}]}
{"op":"mcm","clk":"4296874015","pt":1632570684052,"mc":[{"id":"1.188134680","rc":[{"batb":[[0,3.5,106.62],[1,3.15,2.03],[2,2.42,389.42]],"ltp":4.2,"tv":2627.31,"id":9631939},{"batb":[[2,1.27,1307.13]],"batl":[[1,1.46,23.75],[2,1.56,42.68]],"ltp":1.32,"tv":9755.91,"id":8681938}]}]}
{"op":"mcm","clk":"4296874164","pt":1632570684942,"mc":[{"id":"1.188134680","rc":[{"trd":[[4.2,20.07]],"batl":[[0,4,68.95],[1,4.5,2],[2,4.6,2]],"ltp":4.2,"tv":2629.18,"id":9631939},{"trd":[[1.31,54.17]],"batl":[[0,1.46,23.75],[1,1.81,6.5],[2,1.87,5]],"ltp":1.31,"tv":9763.91,"id":8681938}],"tv":12393.1}]}
{"op":"mcm","clk":"4296874376","pt":1632570686322,"mc":[{"id":"1.188134680","rc":[{"trd":[[4,68.95]],"batb":[[0,4,2],[1,3.5,106.62],[2,3.15,2.03]],"batl":[[0,4.4,53.94]],"ltp":4.0,"tv":2698.13,"id":9631939},{"trd":[[1.33,231.96]],"batb":[[1,1.28,74.93]],"batl":[[0,1.3,21.47],[1,1.31,2919.84],[2,1.32,8017.04]],"ltp":1.33,"tv":9971.29,"id":8681938}],"tv":12669.43}]}
{"op":"mcm","clk":"4296874522","pt":1632570687278,"mc":[{"id":"1.188134680","rc":[{"batl":[[1,4.5,8.38]],"ltp":4.0,"tv":2698.13,"id":9631939},{"batb":[[0,1.28,64.93],[1,1.27,1307.13],[2,1.26,1814.43]],"batl":[[0,1.3,617.51],[1,1.31,1382.69],[2,1.32,708.48]],"ltp":1.33,"tv":9971.29,"id":8681938}]}]}
{"op":"mcm","clk":"4296874700","pt":1632570688239,"mc":[{"id":"1.188134680","rc":[{"batb":[[0,4.3,129.45],[1,4,2],[2,3.8,85.48]],"ltp":4.0,"tv":2698.13,"id":9631939},{"batb":[[1,1.27,1422.6]],"batl":[[0,1.3,668.73],[1,1.31,1412.69]],"ltp":1.33,"tv":9971.29,"id":8681938}]}]}
{"op":"mcm","clk":"4296874873","pt":1632570689343,"mc":[{"id":"1.188134680","rc":[{"batl":[[0,4.4,55.94]],"ltp":4.0,"tv":2698.13,"id":9631939},{"batb":[[1,1.27,1307.13]],"ltp":1.33,"tv":9971.29,"id":8681938}]}]}
{"op":"mcm","clk":"4296875024","pt":1632570690247,"mc":[{"id":"1.188134680","rc":[{"batb":[[1,4.1,2],[2,4,4]],"batl":[[0,4.4,53.94]],"ltp":4.0,"tv":2698.13,"id":9631939},{"batb":[[1,1.27,1362.26]],"batl":[[0,1.3,613.77]],"ltp":1.33,"tv":9971.29,"id":8681938}]}]}
{"op":"mcm","clk":"4296875168","pt":1632570691282,"mc":[{"id":"1.188134680","rc":[{"batl":[[1,4.5,46.03]],"ltp":4.0,"tv":2698.13,"id":9631939},{"batl":[[0,1.3,1048.55],[2,1.32,796.41]],"ltp":1.33,"tv":9971.29,"id":8681938}]}]}
{"op":"mcm","clk":"4296875331","pt":1632570692226,"mc":[{"id":"1.188134680","rc":[{"batb":[[1,4.1,6.83]],"batl":[[1,4.5,8.38]],"ltp":4.0,"tv":2698.13,"id":9631939},{"trd":[[1.3,4.28]],"batb":[[2,1.26,1932.09]],"batl":[[0,1.3,1046.41],[2,1.32,723.48]],"ltp":1.3,"tv":9975.58,"id":8681938}],"tv":12673.71}]}
{"op":"mcm","clk":"4296875499","pt":1632570693254,"mc":[{"id":"1.188134680","rc":[{"batb":[[1,4.1,4.83]],"ltp":4.0,"tv":2698.13,"id":9631939},{"batb":[[1,1.27,1419.18]],"ltp":1.3,"tv":9975.58,"id":8681938}]}]}
{"op":"mcm","clk":"4296875587","pt":1632570693729,"mc":[{"id":"1.188134680","rc":[{"batb":[[1,1.27,1467.05],[2,1.26,2290.06]],"batl":[[0,1.3,1546.41]],"ltp":1.3,"tv":9975.58,"id":8681938}]}]}
{"op":"mcm","clk":"4296875832","pt":1632570695225,"mc":[{"id":"1.188134680","rc":[{"trd":[[4.3,0.19]],"batb":[[0,4.3,129.35]],"ltp":4.3,"tv":2698.32,"id":9631939}],"tv":12673.9}]}
{"op":"mcm","clk":"4296876134","pt":1632570696927,"mc":[{"id":"1.188134680","rc":[{"batl":[[1,4.5,6.67]],"ltp":4.3,"tv":2698.32,"id":9631939},{"trd":[[1.3,8.98]],"batl":[[0,1.3,1544.06]],"ltp":1.3,"tv":9980.28,"id":8681938}],"tv":12678.6}]}
{"op":"mcm","clk":"4296876280","pt":1632570697847,"mc":[{"id":"1.188134680","rc":[{"trd":[[1.3,34.7]],"batl":[[0,1.3,1531.2]],"ltp":1.3,"tv":10005.99,"id":8681938}],"tv":12704.32}]}
{"op":"mcm","clk":"4296877040","pt":1632570702339,"mc":[{"id":"1.188134680","rc":[{"batb":[[0,4.1,4.83],[1,3.8,85.48],[2,3.75,125.26]],"batl":[[0,4.8,89.39],[1,4.9,94.32],[2,5,2]],"ltp":4.3,"tv":2698.32,"id":9631939},{"batb":[[0,1.27,47.87],[1,1.26,1005.88],[2,1.25,456.8]],"batl":[[0,1.32,15],[1,1.37,360.46],[2,1.38,285.21]],"ltp":1.3,"tv":10005.99,"id":8681938}]}]}
{"op":"mcm","clk":"4296877222","pt":1632570703361,"mc":[{"id":"1.188134680","rc":[{"batb":[[0,3.8,85.48],[1,3.75,125.26],[2,3.7,119.26]],"ltp":4.3,"tv":2698.32,"id":9631939},{"batb":[[1,1.26,888.22]],"batl":[[0,1.37,360.46],[1,1.38,285.21],[2,1.46,23.75]],"ltp":1.3,"tv":10005.99,"id":8681938}]}]}
{"op":"mcm","clk":"4296877564","pt":1632570705372,"mc":[{"id":"1.188134680","rc":[{"batl":[[0,4.8,91.39]],"ltp":4.3,"tv":2698.32,"id":9631939},{"batb":[[0,1.27,58.87],[1,1.26,898.22],[2,1.25,1335]],"batl":[[0,1.35,728.34],[1,1.36,536.36],[2,1.37,360.46]],"ltp":1.3,"tv":10005.99,"id":8681938}]}]}
{"op":"mcm","clk":"4296877695","pt":1632570706169,"mc":[{"id":"1.188134680","rc":[{"batb":[[0,3.85,2],[1,3.8,85.48],[2,3.7,2]],"ltp":4.3,"tv":2698.32,"id":9631939},{"batl":[[0,1.35,37.3],[1,1.37,31.5],[2,1.81,6.5]],"ltp":1.3,"tv":10005.99,"id":8681938}]}]}
{"op":"mcm","clk":"4296877749","pt":1632570706445,"mc":[{"id":"1.188134680","rc":[{"batb":[[0,3.8,85.48],[1,3.7,2],[2,2.42,389.42]],"ltp":4.3,"tv":2698.32,"id":9631939},{"batl":[[0,1.37,31.5],[1,1.81,6.5],[2,1.87,5]],"ltp":1.3,"tv":10005.99,"id":8681938}]}]}
{"op":"mcm","clk":"4296878173","pt":1632570709256,"mc":[{"id":"1.188134680","rc":[{"batb":[[0,4.3,190.13],[1,4.2,2],[2,3.8,85.48]],"batl":[[0,4.7,51.64],[1,4.8,89.39],[2,4.9,94.32]],"ltp":4.3,"tv":2698.32,"id":9631939},{"trd":[[1.28,28.9]],"batb":[[0,1.27,47.87]],"batl":[[0,1.28,340.51],[1,1.29,1078.74],[2,1.3,182.18]],"ltp":1.28,"tv":10034.89,"id":8681938}],"tv":12733.22}]}
{"op":"mcm","clk":"4296878355","pt":1632570710263,"mc":[{"id":"1.188134680","rc":[{"batb":[[0,4.5,114.48],[1,4.3,194.67],[2,4.2,2]],"batl":[[1,4.8,95.64]],"ltp":4.3,"tv":2698.32,"id":9631939},{"batl":[[2,1.3,197.18]],"ltp":1.28,"tv":10034.89,"id":8681938}]}]}
{"op":"mcm","clk":"4296878480","pt":1632570711065,"mc":[{"id":"1.188134680","rc":[{"trd":[[1.28,32.04]],"batl":[[0,1.28,338.94]],"ltp":1.28,"tv":10038.03,"id":8681938}],"tv":12736.36}]}
{"op":"mcm","clk":"4296879046","pt":1632570714876,"mc":[{"id":"1.188134680","rc":[{"batb":[[0,4.5,118.19]],"batl":[[0,4.7,57.96]],"ltp":4.3,"tv":2698.32,"id":9631939}]}]}
{"op":"mcm","clk":"4296879282","pt":1632570716262,"mc":[{"id":"1.188134680","rc":[{"batl":[[2,4.9,183.91]],"ltp":4.3,"tv":2698.32,"id":9631939},{"trd":[[1.27,2.04],[1.28,37.9]],"batb":[[0,1.27,46.85],[1,1.26,944.2],[2,1.25,1772.93]],"batl":[[0,1.28,1653.01]],"ltp":1.27,"tv":10045.93,"id":8681938}],"tv":12744.26}]}
{"op":"mcm","clk":"4296879492","pt":1632570717689,"mc":[{"id":"1.188134680","rc":[{"trd":[[1.27,22.04]],"batb":[[0,1.27,36.85]],"ltp":1.27,"tv":10065.93,"id":8681938}],"tv":12764.26}]}
{"op":"mcm","clk":"4296879662","pt":1632570718903,"mc":[{"id":"1.188134680","rc":[{"batb":[[0,4.5,114.48]],"batl":[[0,4.7,51.64]],"ltp":4.3,"tv":2698.32,"id":9631939}]}]}
{"op":"mcm","clk":"4296879845","pt":1632570720270,"mc":[{"id":"1.188134680","rc":[{"batb":[[1,4.3,4.54],[2,4.1,141.62]],"batl":[[0,4.9,89.59],[1,5,126.4],[2,5.1,7.4]],"ltp":4.3,"tv":2698.32,"id":9631939},{"batb":[[0,1.26,586.22],[1,1.25,1368.5],[2,1.24,1159.24]],"batl":[[1,1.29,714.4],[2,1.3,15]],"ltp":1.27,"tv":10065.93,"id":8681938}]}]}
{"op":"mcm","clk":"4296879989","pt":1632570721284,"mc":[{"id":"1.188134680","rc":[{"batb":[[0,4.1,141.62],[1,4,115.73],[2,3.95,128.34]],"batl":[[0,4.9,87.59],[2,5.5,117.37]],"ltp":4.3,"tv":2698.32,"id":9631939},{"batb":[[0,1.25,1030.12],[1,1.24,409.74],[2,1.23,672.52]],"batl":[[0,1.33,383.59],[1,1.34,369.28],[2,1.35,9]],"ltp":1.27,"tv":10065.93,"id":8681938}]}]}
{"op":"mcm","clk":"4296880091","pt":1632570722005,"mc":[{"id":"1.188134680","rc":[{"batl":[[0,1.32,50.44],[1,1.33,383.59],[2,1.34,369.28]],"ltp":1.27,"tv":10065.93,"id":8681938}]}]}
{"op":"mcm","clk":"4296880262","pt":1632570723188,"mc":[{"id":"1.188134680","rc":[{"batb":[[1,4,2],[2,3.85,2]],"ltp":4.3,"tv":2698.32,"id":9631939},{"batl":[[1,1.35,9],[2,1.81,6.5]],"ltp":1.27,"tv":10065.93,"id":8681938}]}]}
{"op":"mcm","clk":"4296880427","pt":1632570724295,"mc":[{"id":"1.188134680","rc":[{"batl":[[0,4.3,1.71],[1,4.9,90.59],[2,5,126.4]],"ltp":4.3,"tv":2698.32,"id":9631939},{"batb":[[0,1.28,2.93],[1,1.26,8],[2,1.25,1041.12]],"ltp":1.27,"tv":10065.93,"id":8681938}]}]}
{"op":"mcm","clk":"4296880488","pt":1632570724694,"mc":[{"id":"1.188134680","rc":[{"batl":[[1,4.9,87.59]],"ltp":4.3,"tv":2698.32,"id":9631939},{"batb":[[1,1.25,1041.12],[2,1.24,1342.88]],"batl":[[1,1.33,9],[2,1.35,9]],"ltp":1.27,"tv":10065.93,"id":8681938}]}]}
{"op":"mcm","clk":"4296880721","pt":1632570726303,"mc":[{"id":"1.188134680","rc":[{"trd":[[4.3,1.9],[4.6,0.82]],"batb":[[0,4.6,102.18],[1,4.5,241.81],[2,4.4,103.18]],"batl":[[0,5,164.95],[1,5.8,2.54],[2,7.4,2]],"ltp":4.6,"tv":2700.85,"id":9631939},{"trd":[[1.28,40.83],[1.3,40.37]],"batb":[[0,1.25,1195.33],[1,1.24,1342.88],[2,1.23,672.52]],"batl":[[0,1.27,415.85],[1,1.28,745.47],[2,1.29,19.5]],"ltp":1.28,"tv":10074.53,"id":8681938}],"tv":12775.39}]}
{"op":"mcm","clk":"4296880887","pt":1632570727372,"mc":[{"id":"1.188134680","rc":[{"batb":[[0,4.7,103.15],[1,4.6,102.18],[2,4.5,241.81]],"batl":[[0,5,170.95],[1,5.2,1.71],[2,5.3,88.68]],"ltp":4.6,"tv":2700.85,"id":9631939},{"batb":[[2,1.23,797.62]],"ltp":1.28,"tv":10074.53,"id":8681938}]}]}
{"op":"mcm","clk":"4296881112","pt":1632570729099,"mc":[{"id":"1.188134680","rc":[{"batl":[[0,5,181.46],[2,5.3,95.91]],"ltp":4.6,"tv":2700.85,"id":9631939},{"batb":[[0,1.25,1237.36]],"ltp":1.28,"tv":10074.53,"id":8681938}]}]}
{"op":"mcm","clk":"4296881501","pt":1632570732179,"mc":[{"id":"1.188134680","rc":[{"batl":[[0,1.26,2226],[1,1.27,415.85],[2,1.28,745.47]],"ltp":1.28,"tv":10074.53,"id":8681938}]}]}
{"op":"mcm","clk":"4296881647","pt":1632570733304,"mc":[{"id":"1.188134680","rc":[{"batl":[[1,5.1,87.43],[2,5.2,107.26]],"ltp":4.6,"tv":2700.85,"id":9631939},{"batb":[[0,1.25,1999.47],[1,1.24,1700.78],[2,1.23,1264.64]],"ltp":1.28,"tv":10074.53,"id":8681938}]}]}
{"op":"mcm","clk":"4296881772","pt":1632570734219,"mc":[{"id":"1.188134680","rc":[{"batb":[[2,4.5,246.09]],"batl":[[2,5.2,109.26]],"ltp":4.6,"tv":2700.85,"id":9631939},{"trd":[[1.26,10.28]],"batb":[[1,1.24,1749.05]],"batl":[[0,1.26,2220.86],[2,1.28,760.47]],"ltp":1.26,"tv":10084.82,"id":8681938}],"tv":12785.68}]}
{"op":"mcm","clk":"4296882196","pt":1632570737112,"mc":[{"id":"1.188134680","rc":[{"batl":[[2,5.2,107.55]],"ltp":4.6,"tv":2700.85,"id":9631939},{"trd":[[1.26,51.71]],"batb":[[1,1.24,1740.05]],"batl":[[0,1.26,2200.15]],"ltp":1.26,"tv":10126.24,"id":8681938}],"tv":12827.1}]}
{"op":"mcm","clk":"4296882491","pt":1632570739300,"mc":[{"id":"1.188134680","rc":[{"batb":[[1,4.5,4.28],[2,4.4,126.43]],"batl":[[0,5,12.51],[2,5.2,105.55]],"ltp":4.6,"tv":2700.85,"id":9631939},{"trd":[[1.25,6.26]],"batb":[[0,1.25,864.38],[1,1.24,1131.08]],"batl":[[1,1.27,400.26]],"ltp":1.25,"tv":10132.5,"id":8681938}],"tv":12833.35}]}
{"op":"mcm","clk":"4296882629","pt":1632570740305,"mc":[{"id":"1.188134680","rc":[{"batb":[[0,4.4,2.01],[1,4,2],[2,2.62,386.89]],"ltp":4.6,"tv":2700.85,"id":9631939},{"batb":[[0,1.25,865.16],[2,1.23,467.03]],"batl":[[0,1.27,400.26],[1,1.28,745.47],[2,1.29,19.5]],"ltp":1.25,"tv":10132.5,"id":8681938}]}]}
{"op":"mcm","clk":"4296882736","pt":1632570740988,"mc":[{"id":"1.188134680","rc":[{"batl":[[0,5,2]],"ltp":4.6,"tv":2700.85,"id":9631939},{"batb":[[0,1.25,812.13]],"ltp":1.25,"tv":10132.5,"id":8681938}]}]}
{"op":"mcm","clk":"4296882931","pt":1632570742325,"mc":[{"id":"1.188134680","rc":[{"batl":[[0,5,19.06],[1,5.1,94.41]],"ltp":4.6,"tv":2700.85,"id":9631939},{"trd":[[1.26,53.27]],"batb":[[0,1.25,879.6],[2,1.23,1446.17]],"batl":[[0,1.26,13.4],[1,1.27,1033.7],[2,1.28,872.41]],"ltp":1.26,"tv":10134.06,"id":8681938}],"tv":12834.92}]}
{"op":"mcm","clk":"4296883086","pt":1632570743222,"mc":[{"id":"1.188134680","rc":[{"trd":[[4.8,1.71]],"batl":[[0,5,21.06]],"ltp":4.8,"tv":2702.57,"id":9631939},{"trd":[[1.26,59.8]],"batb":[[1,1.24,1140.08]],"batl":[[0,1.26,6.87]],"ltp":1.26,"tv":10140.59,"id":8681938}],"tv":12843.16}]}
{"op":"mcm","clk":"4296883180","pt":1632570743922,"mc":[{"id":"1.188134680","rc":[{"batb":[[0,4.7,4.05],[1,4.5,2],[2,4.4,4.01]],"batl":[[0,5,19.06]],"ltp":4.8,"tv":2702.57,"id":9631939},{"trd":[[1.26,60.52]],"batl":[[0,1.26,6.51],[1,1.27,1176.89]],"ltp":1.26,"tv":10141.31,"id":8681938}],"tv":12843.88}]}
{"op":"mcm","clk":"4296883908","pt":1632570746366,"mc":[{"id":"1.188134680","rc":[{"batb":[[1,4.5,44.07]],"ltp":4.8,"tv":2702.57,"id":9631939}]}]}
{"op":"mcm","clk":"4296884187","pt":1632570747164,"mc":[{"id":"1.188134680","rc":[{"batb":[[1,4.5,2]],"ltp":4.8,"tv":2702.57,"id":9631939},{"batl":[[0,1.26,1588.51]],"ltp":1.26,"tv":10141.31,"id":8681938}]}]}
{"op":"mcm","clk":"4296884749","pt":1632570749372,"mc":[{"id":"1.188134680","rc":[{"batb":[[2,1.23,7781.39]],"ltp":1.26,"tv":10141.31,"id":8681938}]}]}
{"op":"mcm","clk":"4296884959","pt":1632570750269,"mc":[{"id":"1.188134680","rc":[{"batb":[[0,4.7,46.12]],"ltp":4.8,"tv":2702.57,"id":9631939}]}]}
{"op":"mcm","clk":"4296885120","pt":1632570750727,"mc":[{"id":"1.188134680","rc":[{"batb":[[0,4.7,4.05]],"ltp":4.8,"tv":2702.57,"id":9631939}]}]}
{"op":"mcm","clk":"4296885460","pt":1632570752144,"mc":[{"id":"1.188134680","rc":[{"batl":[[1,5.1,87.43]],"ltp":4.8,"tv":2702.57,"id":9631939},{"trd":[[1.26,80.52]],"batl":[[0,1.26,1578.51]],"ltp":1.26,"tv":10161.31,"id":8681938}],"tv":12863.88}]}
{"op":"mcm","clk":"4296885708","pt":1632570753029,"mc":[{"id":"1.188134680","rc":[{"batb":[[2,4.4,2]],"ltp":4.8,"tv":2702.57,"id":9631939}]}]}
{"op":"mcm","clk":"4296885897","pt":1632570753741,"mc":[{"id":"1.188134680","rc":[{"trd":[[1.26,82.08]],"batl":[[0,1.26,4063.73]],"ltp":1.26,"tv":10162.87,"id":8681938}],"tv":12865.44}]}
{"op":"mcm","clk":"4296886175","pt":1632570755251,"mc":[{"id":"1.188134680","rc":[{"batb":[[2,4.2,112.19]],"ltp":4.8,"tv":2702.57,"id":9631939}]}]}
{"op":"mcm","clk":"4296886598","pt":1632570757066,"mc":[{"id":"1.188134680","rc":[{"batb":[[0,4.7,15.46]],"ltp":4.8,"tv":2702.57,"id":9631939}]}]}
{"op":"mcm","clk":"4296886908","pt":1632570758242,"mc":[{"id":"1.188134680","rc":[{"batl":[[0,5,25.57]],"ltp":4.8,"tv":2702.57,"id":9631939},{"trd":[[1.26,82.26]],"batl":[[0,1.26,4063.64],[1,1.27,1201]],"ltp":1.26,"tv":10163.05,"id":8681938}],"tv":12865.63}]}
{"op":"mcm","clk":"4296887025","pt":1632570758681,"mc":[{"id":"1.188134680","rc":[{"batb":[[2,4.4,3]],"batl":[[0,5,19.06]],"ltp":4.8,"tv":2702.57,"id":9631939},{"trd":[[1.25,10.26]],"batb":[[0,1.25,877.6]],"batl":[[1,1.27,1176.89]],"ltp":1.25,"tv":10167.05,"id":8681938}],"tv":12869.63}]}
{"op":"mcm","clk":"4296887246","pt":1632570759657,"mc":[{"id":"1.188134680","rc":[{"trd":[[4.8,2.98]],"ltp":4.8,"tv":2703.84,"id":9631939},{"trd":[[1.26,87.1]],"batl":[[0,1.26,4058.8]],"ltp":1.26,"tv":10171.89,"id":8681938}],"tv":12875.74}]}
{"op":"mcm","clk":"4296887412","pt":1632570760447,"mc":[{"id":"1.188134680","rc":[{"trd":[[4.8,3.08]],"ltp":4.8,"tv":2703.93,"id":9631939},{"trd":[[1.26,87.46]],"batl":[[0,1.26,4058.44]],"ltp":1.26,"tv":10172.25,"id":8681938}],"tv":12876.19}]}
{"op":"mcm","clk":"4296888077","pt":1632570763054,"mc":[{"id":"1.188134680","rc":[{"trd":[[1.26,96.77]],"batl":[[0,1.26,4053.79]],"ltp":1.26,"tv":10181.56,"id":8681938}],"tv":12885.49}]}
{"op":"mcm","clk":"4296888495","pt":1632570764752,"mc":[{"id":"1.188134680","rc":[{"batl":[[0,5,25.57]],"ltp":4.8,"tv":2703.93,"id":9631939},{"batl":[[1,1.27,1201]],"ltp":1.26,"tv":10181.56,"id":8681938}]}]}
{"op":"mcm","clk":"4296888849","pt":1632570766040,"mc":[{"id":"1.188134680","rc":[{"trd":[[4.8,8.52]],"ltp":4.8,"tv":2709.37,"id":9631939},{"trd":[[1.26,117.49]],"batl":[[0,1.26,4033.07]],"ltp":1.26,"tv":10202.28,"id":8681938}],"tv":12911.65}]}
{"op":"mcm","clk":"4296889404","pt":1632570768449,"mc":[{"id":"1.188134680","rc":[{"trd":[[1.26,150.45]],"batl":[[0,1.26,4016.59]],"ltp":1.26,"tv":10235.24,"id":8681938}],"tv":12944.61}]}
{"op":"mcm","clk":"4296890895","pt":1632570774373,"mc":[{"id":"1.188134680","rc":[{"batb":[[2,4.2,112.19]],"ltp":4.8,"tv":2709.37,"id":9631939},{"trd":[[1.26,150.51]],"batl":[[0,1.26,4016.56]],"ltp":1.26,"tv":10235.3,"id":8681938}],"tv":12944.68}]}
{"op":"mcm","clk":"4296891106","pt":1632570775061,"mc":[{"id":"1.188134680","rc":[{"trd":[[4.8,8.61]],"ltp":4.8,"tv":2709.47,"id":9631939},{"trd":[[1.26,150.87]],"batl":[[0,1.26,4016.2]],"ltp":1.26,"tv":10235.66,"id":8681938}],"tv":12945.13}]}
{"op":"mcm","clk":"4296891294","pt":1632570775836,"mc":[{"id":"1.188134680","rc":[{"trd":[[1.26,151.65]],"batl":[[0,1.26,4015.81]],"ltp":1.26,"tv":10236.44,"id":8681938}],"tv":12945.91}]}
{"op":"mcm","clk":"4296891787","pt":1632570777585,"mc":[{"id":"1.188134680","rc":[{"batb":[[2,4.4,3]],"ltp":4.8,"tv":2709.47,"id":9631939}]}]}
{"op":"mcm","clk":"4296892756","pt":1632570781263,"mc":[{"id":"1.188134680","rc":[{"trd":[[1.26,155.56]],"batl":[[0,1.26,4013.86]],"ltp":1.26,"tv":10240.35,"id":8681938}],"tv":12949.82}]}
{"op":"mcm","clk":"4296892983","pt":1632570782152,"mc":[{"id":"1.188134680","rc":[{"trd":[[1.26,160.25]],"batl":[[0,1.26,4011.51]],"ltp":1.26,"tv":10245.04,"id":8681938}],"tv":12954.52}]}
{"op":"mcm","clk":"4296893046","pt":1632570782392,"mc":[{"id":"1.188134680","rc":[{"trd":[[1.26,188.43]],"batl":[[0,1.26,3997.42]],"ltp":1.26,"tv":10273.22,"id":8681938}],"tv":12982.7}]}
{"op":"mcm","clk":"4296894058","pt":1632570785972,"mc":[{"id":"1.188134680","rc":[{"trd":[[1.26,194.69]],"batl":[[0,1.26,3994.29]],"ltp":1.26,"tv":10279.48,"id":8681938}],"tv":12988.95}]}
{"op":"mcm","clk":"4296894900","pt":1632570788576,"mc":[{"id":"1.188134680","rc":[{"trd":[[4.8,79.44]],"ltp":4.8,"tv":2780.29,"id":9631939},{"trd":[[1.26,464.51]],"batl":[[0,1.26,3724.47]],"ltp":1.26,"tv":10549.3,"id":8681938}],"tv":13329.6}]}
{"op":"mcm","clk":"4296896437","pt":1632570793479,"mc":[{"id":"1.188134680","rc":[{"batb":[[1,4.4,3],[2,4.2,112.19]],"ltp":4.8,"tv":2780.29,"id":9631939}]}]}
{"op":"mcm","clk":"4296897815","pt":1632570798181,"mc":[{"id":"1.188134680","rc":[{"batb":[[2,1.23,1446.17]],"ltp":1.26,"tv":10549.3,"id":8681938}]}]}
{"op":"mcm","clk":"4296897948","pt":1632570798837,"mc":[{"id":"1.188134680","rc":[{"trd":[[4.8,81.27]],"ltp":4.8,"tv":2782.12,"id":9631939},{"trd":[[1.26,491.64]],"batl":[[0,1.26,3707.42]],"ltp":1.26,"tv":10576.43,"id":8681938}],"tv":13358.56}]}
{"op":"mcm","clk":"4296898735","pt":1632570802315,"mc":[{"id":"1.188134680","rc":[{"trd":[[1.26,494.78]],"batl":[[0,1.26,3705.85]],"ltp":1.26,"tv":10579.57,"id":8681938}],"tv":13361.7}]}
{"op":"mcm","clk":"4296899163","pt":1632570803723,"mc":[{"id":"1.188134680","rc":[{"trd":[[1.26,494.8]],"batl":[[0,1.26,3705.84]],"ltp":1.26,"tv":10579.59,"id":8681938}],"tv":13361.72}]}
{"op":"mcm","clk":"4296901089","pt":1632570810813,"mc":[{"id":"1.188134680","rc":[{"trd":[[4.8,99.09]],"ltp":4.8,"tv":2799.94,"id":9631939},{"trd":[[1.26,562.68]],"batl":[[0,1.26,3637.96]],"ltp":1.26,"tv":10647.47,"id":8681938}],"tv":13447.42}]}
{"op":"mcm","clk":"4296901840","pt":1632570813713,"mc":[{"id":"1.188134680","rc":[{"trd":[[4.8,99.18]],"ltp":4.8,"tv":2800.04,"id":9631939},{"trd":[[1.26,563.04]],"batl":[[0,1.26,3637.6]],"ltp":1.26,"tv":10647.83,"id":8681938}],"tv":13447.87}]}
{"op":"mcm","clk":"4296902473","pt":1632570816598,"mc":[{"id":"1.188134680","rc":[{"trd":[[1.26,563.36]],"batl":[[0,1.26,3637.44]],"ltp":1.26,"tv":10648.15,"id":8681938}],"tv":13448.19}]}
{"op":"mcm","clk":"4296904303","pt":1632570824856,"mc":[{"id":"1.188134680","rc":[{"trd":[[1.26,583.36]],"batl":[[0,1.26,3627.44]],"ltp":1.26,"tv":10668.15,"id":8681938}],"tv":13468.19}]}
{"op":"mcm","clk":"4296904842","pt":1632570827345,"mc":[{"id":"1.188134680","rc":[{"batb":[[0,4.7,4.05]],"ltp":4.8,"tv":2800.04,"id":9631939}]}]}
{"op":"mcm","clk":"4296905517","pt":1632570830562,"mc":[{"id":"1.188134680","rc":[{"trd":[[4.8,99.2]],"ltp":4.8,"tv":2800.05,"id":9631939},{"trd":[[1.26,583.43]],"batl":[[0,1.26,3627.37]],"ltp":1.26,"tv":10668.22,"id":8681938}],"tv":13468.28}]}
{"op":"mcm","clk":"4296906167","pt":1632570833440,"mc":[{"id":"1.188134680","rc":[{"trd":[[1.26,588.57]],"batl":[[0,1.26,3624.8]],"ltp":1.26,"tv":10673.36,"id":8681938}],"tv":13473.42}]}
{"op":"mcm","clk":"4296906394","pt":1632570834446,"mc":[{"id":"1.188134680","rc":[{"trd":[[1.25,10.44]],"batb":[[0,1.25,877.51]],"ltp":1.25,"tv":10673.55,"id":8681938}],"tv":13473.61}]}
{"op":"mcm","clk":"4296907203","pt":1632570838463,"mc":[{"id":"1.188134680","rc":[{"batl":[[1,1.27,1072.81]],"ltp":1.25,"tv":10673.55,"id":8681938}]}]}
{"op":"mcm","clk":"4296908480","pt":1632570844372,"mc":[{"id":"1.188134680","rc":[{"trd":[[4.8,99.51]],"ltp":4.8,"tv":2800.37,"id":9631939},{"trd":[[1.26,589.76]],"batl":[[0,1.26,3623.61]],"ltp":1.26,"tv":10674.74,"id":8681938}],"tv":13475.11}]}
{"op":"mcm","clk":"4296909362","pt":1632570848372,"mc":[{"id":"1.188134680","rc":[{"trd":[[4.8,99.61]],"ltp":4.8,"tv":2800.46,"id":9631939},{"trd":[[1.26,590.12]],"batl":[[0,1.26,3623.25]],"ltp":1.26,"tv":10675.1,"id":8681938}],"tv":13475.56}]}
{"op":"mcm","clk":"4296910858","pt":1632570855689,"mc":[{"id":"1.188134680","rc":[{"batb":[[0,1.25,115.4]],"ltp":1.26,"tv":10675.1,"id":8681938}]}]}
{"op":"mcm","clk":"4296911415","pt":1632570858795,"mc":[{"id":"1.188134680","rc":[{"trd":[[1.26,2102.27]],"batl":[[0,1.26,2867.18]],"ltp":1.26,"tv":12187.24,"id":8681938}],"tv":14987.71}]}
{"op":"mcm","clk":"4296911569","pt":1632570859492,"mc":[{"id":"1.188134680","rc":[{"batl":[[0,1.27,1072.81],[1,1.28,872.41],[2,1.31,330.17]],"ltp":1.26,"tv":12187.24,"id":8681938}]}]}
{"op":"mcm","clk":"4296912820","pt":1632570865680,"mc":[{"id":"1.188134680","rc":[{"batb":[[1,4.2,112.19],[2,4.1,116.14]],"batl":[[0,5.5,7.07],[1,5.7,92.85],[2,5.8,113.04]],"ltp":4.8,"tv":2800.46,"id":9631939},{"batb":[[0,1.21,429.5],[1,1.2,549.91],[2,1.01,140]],"batl":[[0,1.27,15],[1,1.31,330.17],[2,1.32,388.6]],"ltp":1.26,"tv":12187.24,"id":8681938}]}]}
{"op":"mcm","clk":"4296913131","pt":1632570867307,"mc":[{"id":"1.188134680","rc":[{"batb":[[0,4.2,112.19],[1,4.1,116.14],[2,1.9,5.76]],"batl":[[0,5.7,92.85],[1,5.8,113.04],[2,990,0.01]],"ltp":4.8,"tv":2800.46,"id":9631939},{"batl":[[0,1.31,330.17],[1,1.32,388.6],[2,4.4,3.34]],"ltp":1.26,"tv":12187.24,"id":8681938}]}]}
{"op":"mcm","clk":"4296913471","pt":1632570869113,"mc":[{"id":"1.188134680","rc":[{"batl":[[0,5.5,2],[1,5.8,2.54]],"ltp":4.8,"tv":2800.46,"id":9631939},{"batb":[[0,1.22,13],[1,1.21,10]],"batl":[[0,1.29,987.86],[1,1.3,675.32],[2,1.31,330.17]],"ltp":1.26,"tv":12187.24,"id":8681938}]}]}
{"op":"mcm","clk":"4296913842","pt":1632570870715,"mc":[{"id":"1.188134680","rc":[{"batb":[[0,4.2,114.19],[1,4.1,119.14]],"batl":[[0,4.8,2.34],[1,5.5,2],[2,5.7,3]],"ltp":4.8,"tv":2800.46,"id":9631939},{"batb":[[2,1.2,14]],"batl":[[2,1.31,339.17]],"ltp":1.26,"tv":12187.24,"id":8681938}]}]}
{"op":"mcm","clk":"4296914165","pt":1632570872319,"mc":[{"id":"1.188134680","rc":[{"batb":[[0,4.4,5.36],[1,4.3,222.38],[2,4.2,330.03]],"batl":[[0,4.7,49.47],[1,4.8,8.59],[2,5,191.24]],"ltp":4.8,"tv":2800.46,"id":9631939},{"batb":[[0,1.28,13.05],[1,1.26,1718.77],[2,1.25,882.18]],"batl":[[2,1.31,475.98]],"ltp":1.26,"tv":12187.24,"id":8681938}]}]}
{"op":"mcm","clk":"4296914369","pt":1632570873299,"mc":[{"id":"1.188134680","rc":[{"batb":[[0,4.4,9.77],[1,4.3,243.05]],"ltp":4.8,"tv":2800.46,"id":9631939},{"batl":[[1,1.3,690.32]],"ltp":1.26,"tv":12187.24,"id":8681938}]}]}
{"op":"mcm","clk":"4296914647","pt":1632570874615,"mc":[{"id":"1.188134680","rc":[{"batb":[[1,4.3,222.38]],"ltp":4.8,"tv":2800.46,"id":9631939}]}]}
{"op":"mcm","clk":"4296915320","pt":1632570878322,"mc":[{"id":"1.188134680","rc":[{"batb":[[0,4.4,30.44],[1,4.3,349.63]],"ltp":4.8,"tv":2800.46,"id":9631939}]}]}
{"op":"mcm","clk":"4296915646","pt":1632570880216,"mc":[{"id":"1.188134680","rc":[{"batb":[[0,4.4,4.41],[1,4.3,129.25],[2,4.2,4]],"batl":[[0,4.8,2.34],[1,5,2],[2,5.1,97.84]],"ltp":4.8,"tv":2800.46,"id":9631939},{"batb":[[0,1.25,53.01],[1,1.24,503.65],[2,1.23,482.17]],"batl":[[0,1.29,223],[1,1.3,609.74],[2,1.31,48.5]],"ltp":1.26,"tv":12187.24,"id":8681938}]}]}
{"op":"mcm","clk":"4296915843","pt":1632570881298,"mc":[{"id":"1.188134680","rc":[{"batb":[[0,4.3,129.25],[1,4.2,4],[2,4.1,3]],"batl":[[0,5.1,90.44],[1,5.2,115.11],[2,5.4,2]],"ltp":4.8,"tv":2800.46,"id":9631939},{"batb":[[0,1.24,381.18],[1,1.23,482.17],[2,1.22,13]],"batl":[[0,1.3,594.78],[1,1.31,48.5],[2,1.33,387.8]],"ltp":1.26,"tv":12187.24,"id":8681938}]}]}
{"op":"mcm","clk":"4296915964","pt":1632570881983,"mc":[{"id":"1.188134680","rc":[{"batb":[[0,4.3,127.25]],"ltp":4.8,"tv":2800.46,"id":9631939},{"batl":[[0,1.31,48.54],[1,1.33,387.8],[2,1.34,438.36]],"ltp":1.26,"tv":12187.24,"id":8681938}]}]}
{"op":"mcm","clk":"4296916200","pt":1632570883315,"mc":[{"id":"1.188134680","rc":[{"trd":[[4.5,0.01]],"batb":[[2,4,129.23]],"batl":[[0,5.1,90.53],[1,5.2,113.4]],"ltp":4.5,"tv":2800.47,"id":9631939},{"trd":[[1.28,40.87]],"batb":[[0,1.25,9],[1,1.24,390.18],[2,1.23,1057.28]],"batl":[[0,1.31,704.77]],"ltp":1.28,"tv":12187.28,"id":8681938}],"tv":14987.76}]}
{"op":"mcm","clk":"4296916401","pt":1632570884322,"mc":[{"id":"1.188134680","rc":[{"batl":[[0,4.4,2.42],[1,5.1,93.44],[2,5.2,113.4]],"ltp":4.5,"tv":2800.47,"id":9631939},{"batb":[[0,1.24,390.18],[1,1.23,493.17],[2,1.22,13]],"batl":[[0,1.31,987.93]],"ltp":1.28,"tv":12187.28,"id":8681938}]}]}
{"op":"mcm","clk":"4296916507","pt":1632570884913,"mc":[{"id":"1.188134680","rc":[{"trd":[[4.4,2.42]],"batb":[[0,4.3,129.25]],"batl":[[0,5.1,93.44],[1,5.2,113.4],[2,5.4,2]],"ltp":4.4,"tv":2802.89,"id":9631939},{"trd":[[1.29,8.26]],"batb":[[0,1.25,947.91],[1,1.24,1325.16],[2,1.23,493.17]],"batl":[[0,1.28,762.51],[1,1.29,707.99],[2,1.3,42.25]],"ltp":1.29,"tv":12195.54,"id":8681938}],"tv":14998.44}]}
{"op":"mcm","clk":"4296916636","pt":1632570885712,"mc":[{"id":"1.188134680","rc":[{"batb":[[0,4.4,18.51],[1,4.3,129.25],[2,4.2,4]],"batl":[[0,5,16],[1,5.1,93.44],[2,5.2,113.4]],"ltp":4.4,"tv":2802.89,"id":9631939},{"batb":[[0,1.25,1011.88]],"batl":[[2,1.3,120.83]],"ltp":1.29,"tv":12195.54,"id":8681938}]}]}
{"op":"mcm","clk":"4296916917","pt":1632570887310,"mc":[{"id":"1.188134680","rc":[{"batl":[[0,5,2]],"ltp":4.4,"tv":2802.89,"id":9631939}]}]}
{"op":"mcm","clk":"4296916949","pt":1632570887526,"mc":[{"id":"1.188134680","rc":[{"batl":[[0,5,4]],"ltp":4.4,"tv":2802.89,"id":9631939},{"batb":[[0,1.25,1063.89]],"ltp":1.29,"tv":12195.54,"id":8681938}]}]}
{"op":"mcm","clk":"4296917332","pt":1632570889615,"mc":[{"id":"1.188134680","rc":[{"batl":[[0,1.28,850.51]],"ltp":1.29,"tv":12195.54,"id":8681938}]}]}
{"op":"mcm","clk":"4296917547","pt":1632570890824,"mc":[{"id":"1.188134680","rc":[{"batb":[[0,4.3,129.25],[1,4.2,4],[2,4,129.23]],"batl":[[0,5,2]],"ltp":4.4,"tv":2802.89,"id":9631939},{"batb":[[0,1.24,390.18],[1,1.23,493.17],[2,1.22,13]],"batl":[[0,1.28,88],[1,1.3,42.25],[2,1.31,48.5]],"ltp":1.29,"tv":12195.54,"id":8681938}]}]}
{"op":"mcm","clk":"4296917728","pt":1632570891818,"mc":[{"id":"1.188134680","rc":[{"batb":[[0,4.3,127.25]],"ltp":4.4,"tv":2802.89,"id":9631939},{"batl":[[0,1.31,48.5],[1,1.33,387.8],[2,1.34,438.36]],"ltp":1.29,"tv":12195.54,"id":8681938}]}]}
{"op":"mcm","clk":"4296918227","pt":1632570894335,"mc":[{"id":"1.188134680","rc":[{"batb":[[1,1.23,1073.08],[2,1.22,1041.11]],"batl":[[0,1.3,548.16],[1,1.31,704.78],[2,1.33,387.8]],"ltp":1.29,"tv":12195.54,"id":8681938}]}]}
{"op":"mcm","clk":"4296918375","pt":1632570895131,"mc":[{"id":"1.188134680","rc":[{"batb":[[0,4.3,129.25]],"ltp":4.4,"tv":2802.89,"id":9631939},{"batl":[[0,1.3,587.11]],"ltp":1.29,"tv":12195.54,"id":8681938}]}]}
{"op":"mcm","clk":"4296918543","pt":1632570896112,"mc":[{"id":"1.188134680","rc":[{"batl":[[1,5.4,2],[2,5.8,2.54]],"ltp":4.4,"tv":2802.89,"id":9631939},{"batb":[[0,1.24,9],[1,1.23,55.63],[2,1.21,745.65]],"ltp":1.29,"tv":12195.54,"id":8681938}]}]}
{"op":"mcm","clk":"4296918883","pt":1632570898164,"mc":[{"id":"1.188134680","rc":[{"batb":[[1,4.2,2]],"batl":[[0,5,4]],"ltp":4.4,"tv":2802.89,"id":9631939},{"batb":[[0,1.25,58.41],[1,1.24,9],[2,1.23,55.63]],"batl":[[1,1.31,695.78]],"ltp":1.29,"tv":12195.54,"id":8681938}]}]}
{"op":"mcm","clk":"4296919030","pt":1632570899125,"mc":[{"id":"1.188134680","rc":[{"batb":[[2,4,174.49]],"batl":[[0,4.4,256.88],[1,4.5,104.44],[2,4.6,58.74]],"ltp":4.4,"tv":2802.89,"id":9631939},{"trd":[[1.3,72.71]],"batb":[[0,1.27,984.82],[1,1.26,900.63],[2,1.25,9]],"batl":[[0,1.3,570.94],[2,1.32,24.08]],"ltp":1.3,"tv":12227.88,"id":8681938}],"tv":15030.78}]}
{"op":"mcm","clk":"4296919219","pt":1632570900229,"mc":[{"id":"1.188134680","rc":[{"batb":[[1,4.2,143.91]],"ltp":4.4,"tv":2802.89,"id":9631939},{"batb":[[1,1.26,1484.2],[2,1.25,2889.76]],"batl":[[1,1.31,710.78]],"ltp":1.3,"tv":12227.88,"id":8681938}]}]}
{"op":"mcm","clk":"4296919398","pt":1632570901217,"mc":[{"id":"1.188134680","rc":[{"batb":[[0,1.28,48.95],[1,1.27,984.82],[2,1.26,1494.2]],"ltp":1.3,"tv":12227.88,"id":8681938}]}]}
{"op":"mcm","clk":"4296919546","pt":1632570902141,"mc":[{"id":"1.188134680","rc":[{"batb":[[0,1.28,9],[1,1.27,995.82]],"ltp":1.3,"tv":12227.88,"id":8681938}]}]}
{"op":"mcm","clk":"4296919709","pt":1632570902933,"mc":[{"id":"1.188134680","rc":[{"batb":[[0,4.3,127.25]],"ltp":4.4,"tv":2802.89,"id":9631939},{"batl":[[0,1.3,531.99]],"ltp":1.3,"tv":12227.88,"id":8681938}]}]}
{"op":"mcm","clk":"4296919950","pt":1632570904373,"mc":[{"id":"1.188134680","rc":[{"trd":[[4.4,110.94]],"batl":[[0,4.4,148.36]],"ltp":4.4,"tv":2911.41,"id":9631939},{"trd":[[1.29,378.4]],"batb":[[1,1.27,1059.77]],"ltp":1.29,"tv":12598.02,"id":8681938}],"tv":15509.44}]}
{"op":"mcm","clk":"4296920096","pt":1632570905302,"mc":[{"id":"1.188134680","rc":[{"trd":[[4.4,111.05]],"batl":[[0,4.4,148.25]],"ltp":4.4,"tv":2911.52,"id":9631939},{"trd":[[1.29,378.76]],"batl":[[0,1.3,764.99]],"ltp":1.29,"tv":12598.38,"id":8681938}],"tv":15509.91}]}
{"op":"mcm","clk":"4296920282","pt":1632570906161,"mc":[{"id":"1.188134680","rc":[{"batb":[[2,4.1,2]],"ltp":4.4,"tv":2911.52,"id":9631939},{"batb":[[1,1.27,1485.21],[2,1.26,1989.17]],"batl":[[2,1.32,59.44]],"ltp":1.29,"tv":12598.38,"id":8681938}]}]}
{"op":"mcm","clk":"4296920656","pt":1632570908309,"mc":[{"id":"1.188134680","rc":[{"trd":[[1.3,82.28]],"batl":[[0,1.3,920.2]],"ltp":1.3,"tv":12607.96,"id":8681938}],"tv":15519.49}]}
{"op":"mcm","clk":"4296920824","pt":1632570909164,"mc":[{"id":"1.188134680","rc":[{"batl":[[2,1.32,35.36]],"ltp":1.3,"tv":12607.96,"id":8681938}]}]}
{"op":"mcm","clk":"4296921121","pt":1632570910868,"mc":[{"id":"1.188134680","rc":[{"batl":[[0,1.3,1177.2]],"ltp":1.3,"tv":12607.96,"id":8681938}]}]}
{"op":"mcm","clk":"4296921392","pt":1632570912364,"mc":[{"id":"1.188134680","rc":[{"batl":[[0,4.4,152.02]],"ltp":4.4,"tv":2911.52,"id":9631939},{"trd":[[1.3,110.46]],"batl":[[0,1.3,1163.11],[1,1.31,716.44]],"ltp":1.3,"tv":12636.14,"id":8681938}],"tv":15547.67}]}
{"op":"mcm","clk":"4296921561","pt":1632570913367,"mc":[{"id":"1.188134680","rc":[{"batl":[[0,4.7,114.03],[1,4.8,106.9],[2,4.9,5]],"ltp":4.4,"tv":2911.52,"id":9631939},{"batb":[[1,1.27,1421.26]],"batl":[[1,1.31,695.78]],"ltp":1.3,"tv":12636.14,"id":8681938}]}]}
{"op":"mcm","clk":"4296921719","pt":1632570914304,"mc":[{"id":"1.188134680","rc":[{"batb":[[0,4.2,143.91],[1,4.1,2],[2,3.9,116.17]],"ltp":4.4,"tv":2911.52,"id":9631939},{"batb":[[0,1.27,436.44],[1,1.26,494.97],[2,1.23,714.79]],"batl":[[0,1.3,650],[1,1.31,473.81]],"ltp":1.3,"tv":12636.14,"id":8681938}]}]}
{"op":"mcm","clk":"4296921914","pt":1632570915292,"mc":[{"id":"1.188134680","rc":[{"batb":[[0,4.2,139.23]],"ltp":4.4,"tv":2911.52,"id":9631939},{"batl":[[0,1.31,473.81],[1,1.32,35.36],[2,1.35,332.54]],"ltp":1.3,"tv":12636.14,"id":8681938}]}]}
{"op":"mcm","clk":"4296922028","pt":1632570915875,"mc":[{"id":"1.188134680","rc":[{"batb":[[0,1.27,436.73]],"ltp":1.3,"tv":12636.14,"id":8681938}]}]}
{"op":"mcm","clk":"4296922238","pt":1632570917049,"mc":[{"id":"1.188134680","rc":[{"batl":[[0,4.6,3],[1,4.7,114.03],[2,4.8,106.9]],"ltp":4.4,"tv":2911.52,"id":9631939},{"batb":[[2,1.25,858.77]],"batl":[[1,1.32,667.92]],"ltp":1.3,"tv":12636.14,"id":8681938}]}]}
{"op":"mcm","clk":"4296922424","pt":1632570918197,"mc":[{"id":"1.188134680","rc":[{"batb":[[0,4.2,142.23],[1,4.1,5]],"batl":[[0,4.7,116.03],[1,4.8,106.9],[2,4.9,5]],"ltp":4.4,"tv":2911.52,"id":9631939},{"batb":[[1,1.26,503.97]],"batl":[[0,1.31,483.81]],"ltp":1.3,"tv":12636.14,"id":8681938}]}]}
{"op":"mcm","clk":"4296922680","pt":1632570919664,"mc":[{"id":"1.188134680","rc":[{"batb":[[0,4.2,140.23],[2,1.9,5.78]],"ltp":4.4,"tv":2911.52,"id":9631939},{"batl":[[0,1.31,10],[1,1.32,35.36],[2,4.4,3.34]],"ltp":1.3,"tv":12636.14,"id":8681938}]}]}
{"op":"mcm","clk":"4296923114","pt":1632570922285,"mc":[{"id":"1.188134680","rc":[{"batb":[[0,4.5,522.22],[1,4.4,261.12],[2,4.3,261.12]],"batl":[[1,4.8,159.7]],"ltp":4.4,"tv":2911.52,"id":9631939},{"trd":[[1.3,111.04]],"batb":[[0,1.27,436.44]],"batl":[[0,1.28,20.51],[1,1.29,5713.33],[2,1.31,3311.66]],"ltp":1.3,"tv":12636.72,"id":8681938}],"tv":15548.25}]}
{"op":"mcm","clk":"4296923299","pt":1632570923275,"mc":[{"id":"1.188134680","rc":[{"batb":[[0,4.7,106.28],[1,4.5,104.44],[2,4.4,176.4]],"batl":[[0,4.8,157.7],[1,4.9,11.12],[2,5.1,460.78]],"ltp":4.4,"tv":2911.52,"id":9631939},{"batb":[[0,1.26,494.97],[1,1.25,858.77],[2,1.24,932.39]],"batl":[[0,1.28,871.56],[1,1.29,729.52],[2,1.31,855.17]],"ltp":1.3,"tv":12636.72,"id":8681938}]}]}
{"op":"mcm","clk":"4296923480","pt":1632570924291,"mc":[{"id":"1.188134680","rc":[{"batb":[[1,4.5,108.72]],"batl":[[2,5.1,92.16]],"ltp":4.4,"tv":2911.52,"id":9631939},{"batl":[[1,1.29,744.52]],"ltp":1.3,"tv":12636.72,"id":8681938}]}]}
{"op":"mcm","clk":"4296923503","pt":1632570924414,"mc":[{"id":"1.188134680","rc":[{"batl":[[2,1.3,50]],"ltp":1.3,"tv":12636.72,"id":8681938}]}]}
{"op":"mcm","clk":"4296923785","pt":1632570925868,"mc":[{"id":"1.188134680","rc":[{"trd":[[4.7,21.51]],"batb":[[0,4.7,95.52]],"ltp":4.7,"tv":2933.04,"id":9631939}],"tv":15569.76}]}
{"op":"mcm","clk":"4296924033","pt":1632570927364,"mc":[{"id":"1.188134680","rc":[{"batl":[[0,4.8,195.28]],"ltp":4.7,"tv":2933.04,"id":9631939},{"batl":[[1,1.29,795.33]],"ltp":1.3,"tv":12636.72,"id":8681938}]}]}
{"op":"mcm","clk":"4296924085","pt":1632570927687,"mc":[{"id":"1.188134680","rc":[{"batl":[[0,4.8,157.7]],"ltp":4.7,"tv":2933.04,"id":9631939},{"batl":[[1,1.29,744.52]],"ltp":1.3,"tv":12636.72,"id":8681938}]}]}
{"op":"mcm","clk":"4296924353","pt":1632570929263,"mc":[{"id":"1.188134680","rc":[{"batb":[[2,1.24,984.41]],"batl":[[2,1.3,87.85]],"ltp":1.3,"tv":12636.72,"id":8681938}]}]}
{"op":"mcm","clk":"4296924548","pt":1632570930383,"mc":[{"id":"1.188134680","rc":[{"trd":[[4.8,127.82]],"batl":[[0,4.8,143.59]],"ltp":4.8,"tv":2961.25,"id":9631939},{"batl":[[0,1.28,1037.56]],"ltp":1.3,"tv":12636.72,"id":8681938}],"tv":15597.98}]}
{"op":"mcm","clk":"4296924986","pt":1632570932884,"mc":[{"id":"1.188134680","rc":[{"trd":[[4.7,25.51]],"batb":[[0,4.7,93.52]],"ltp":4.7,"tv":2965.25,"id":9631939},{"batl":[[0,1.28,1192.56]],"ltp":1.3,"tv":12636.72,"id":8681938}],"tv":15601.98}]}
{"op":"mcm","clk":"4296925205","pt":1632570934111,"mc":[{"id":"1.188134680","rc":[{"batb":[[1,4.5,121.58]],"ltp":4.7,"tv":2965.25,"id":9631939},{"trd":[[1.28,46.09]],"batl":[[0,1.28,1189.95]],"ltp":1.28,"tv":12641.94,"id":8681938}],"tv":15607.2}]}
{"op":"mcm","clk":"4296925392","pt":1632570935188,"mc":[{"id":"1.188134680","rc":[{"trd":[[4.7,25.9]],"batb":[[0,4.7,93.33]],"ltp":4.7,"tv":2965.64,"id":9631939}],"tv":15607.59}]}
{"op":"mcm","clk":"4296926396","pt":1632570941326,"mc":[{"id":"1.188134680","rc":[{"trd":[[4.7,40.93]],"batb":[[0,4.7,85.81],[1,4.5,69.36],[2,4.4,150.29]],"batl":[[0,4.8,52.8],[1,4.9,5],[2,5.1,46.08]],"ltp":4.7,"tv":2980.67,"id":9631939}],"tv":15622.62}]}
{"op":"mcm","clk":"4296926539","pt":1632570942133,"mc":[{"id":"1.188134680","rc":[{"batb":[[0,4.5,17.14],[1,4.4,121.92],[2,4.3,2]],"batl":[[0,5.3,85.01],[1,5.4,125.97],[2,5.8,2.54]],"ltp":4.7,"tv":2980.67,"id":9631939},{"batb":[[0,1.23,482.02],[1,1.22,390.75],[2,1.2,793.43]],"batl":[[0,1.28,321],[1,1.29,15],[2,1.3,37.85]],"ltp":1.28,"tv":12641.94,"id":8681938}]}]}
{"op":"mcm","clk":"4296926757","pt":1632570943200,"mc":[{"id":"1.188134680","rc":[{"batb":[[0,4.4,121.92],[1,4.3,2],[2,4.2,5]],"ltp":4.7,"tv":2980.67,"id":9631939},{"batl":[[0,1.3,37.85],[1,1.31,51.5],[2,1.32,35.36]],"ltp":1.28,"tv":12641.94,"id":8681938}]}]}
{"op":"mcm","clk":"4296926880","pt":1632570943834,"mc":[{"id":"1.188134680","rc":[{"batl":[[0,5.4,2],[1,5.8,2.54],[2,6,108.31]],"ltp":4.7,"tv":2980.67,"id":9631939},{"batb":[[0,1.23,55.63],[1,1.2,793.43],[2,1.01,140]],"ltp":1.28,"tv":12641.94,"id":8681938}]}]}
{"op":"mcm","clk":"4296927204","pt":1632570945320,"mc":[{"id":"1.188134680","rc":[{"batl":[[0,5.2,2],[1,5.3,2],[2,5.4,2]],"ltp":4.7,"tv":2980.67,"id":9631939},{"batb":[[0,1.25,8],[1,1.24,57.77],[2,1.23,66.63]],"batl":[[0,1.3,915.47],[1,1.31,701.78]],"ltp":1.28,"tv":12641.94,"id":8681938}]}]}
{"op":"mcm","clk":"4296927264","pt":1632570945597,"mc":[{"id":"1.188134680","rc":[{"batb":[[2,4.2,2]],"batl":[[0,5.3,2],[1,5.4,2],[2,5.8,2.54]],"ltp":4.7,"tv":2980.67,"id":9631939},{"batb":[[1,1.24,12]],"batl":[[0,1.3,915.62],[1,1.31,691.78]],"ltp":1.28,"tv":12641.94,"id":8681938}]}]}
{"op":"mcm","clk":"4296927554","pt":1632570947136,"mc":[{"id":"1.188134680","rc":[{"trd":[[4.8,127.86]],"batl":[[0,4.6,6.52],[1,4.7,101.71],[2,4.8,192.71]],"ltp":4.8,"tv":2980.71,"id":9631939},{"trd":[[1.26,2102.42]],"batb":[[0,1.27,626.51],[1,1.26,840.99],[2,1.25,60.25]],"batl":[[0,1.3,915.47]],"ltp":1.26,"tv":12642.09,"id":8681938}],"tv":15622.81}]}
{"op":"mcm","clk":"4296927776","pt":1632570948307,"mc":[{"id":"1.188134680","rc":[{"batb":[[2,4.2,265.73]],"ltp":4.8,"tv":2980.71,"id":9631939},{"batb":[[0,1.28,48.95],[1,1.27,626.51],[2,1.26,840.99]],"batl":[[1,1.31,706.78]],"ltp":1.26,"tv":12642.09,"id":8681938}]}]}
{"op":"mcm","clk":"4296927922","pt":1632570949101,"mc":[{"id":"1.188134680","rc":[{"batb":[[2,1.26,852.99]],"ltp":1.26,"tv":12642.09,"id":8681938}]}]}
{"op":"mcm","clk":"4296928077","pt":1632570950166,"mc":[{"id":"1.188134680","rc":[{"batb":[[1,4.3,3.95]],"ltp":4.8,"tv":2980.71,"id":9631939},{"batb":[[0,1.29,15.14],[1,1.28,48.95],[2,1.27,626.51]],"batl":[[0,1.3,877.62]],"ltp":1.26,"tv":12642.09,"id":8681938}]}]}
{"op":"mcm","clk":"4296928255","pt":1632570951039,"mc":[{"id":"1.188134680","rc":[{"trd":[[1.29,409.04]],"batb":[[0,1.28,48.95],[1,1.27,766.38],[2,1.26,852.99]],"batl":[[0,1.29,232.86],[1,1.3,877.62],[2,1.31,706.78]],"ltp":1.29,"tv":12672.37,"id":8681938}],"tv":15653.09}]}
{"op":"mcm","clk":"4296928774","pt":1632570953924,"mc":[{"id":"1.188134680","rc":[{"batb":[[1,4.3,5.95]],"batl":[[2,4.8,277.4]],"ltp":4.8,"tv":2980.71,"id":9631939},{"batb":[[1,1.27,817.25],[2,1.26,1325.63]],"batl":[[0,1.29,492.86],[1,1.3,917.07]],"ltp":1.29,"tv":12672.37,"id":8681938}]}]}
{"op":"mcm","clk":"4296929477","pt":1632570957753,"mc":[{"id":"1.188134680","rc":[{"batl":[[1,4.7,100]],"ltp":4.8,"tv":2980.71,"id":9631939}]}]}
{"op":"mcm","clk":"4296929765","pt":1632570959345,"mc":[{"id":"1.188134680","rc":[{"batb":[[1,4.3,2],[2,4.2,153.83]],"batl":[[0,4.8,84.69],[1,4.9,99.23],[2,5,7.5]],"ltp":4.8,"tv":2980.71,"id":9631939},{"trd":[[1.29,412.22]],"batb":[[1,1.27,677.38]],"batl":[[0,1.29,491.27]],"ltp":1.29,"tv":12675.54,"id":8681938}],"tv":15656.26}]}
{"op":"mcm","clk":"4296929841","pt":1632570959718,"mc":[{"id":"1.188134680","rc":[{"batb":[[0,4.3,2],[1,4.2,153.83],[2,4.1,2]],"batl":[[0,4.8,82.69]],"ltp":4.8,"tv":2980.71,"id":9631939},{"batb":[[1,1.26,484.64],[2,1.25,597.17]],"batl":[[1,1.3,39.45]],"ltp":1.29,"tv":12675.54,"id":8681938}]}]}
{"op":"mcm","clk":"4296930113","pt":1632570961263,"mc":[{"id":"1.188134680","rc":[{"batb":[[0,4.2,135.08],[1,4.1,2],[2,4,101.89]],"batl":[[2,5.4,2]],"ltp":4.8,"tv":2980.71,"id":9631939},{"batb":[[2,1.25,477.17]],"batl":[[0,1.31,691.78],[1,1.32,35.36],[2,1.33,272.84]],"ltp":1.29,"tv":12675.54,"id":8681938}]}]}
{"op":"mcm","clk":"4296930541","pt":1632570963360,"mc":[{"id":"1.188134680","rc":[{"batb":[[2,1.25,1036.68]],"batl":[[0,1.31,831.3],[1,1.32,661.22]],"ltp":1.29,"tv":12675.54,"id":8681938}]}]}
{"op":"mcm","clk":"4296930730","pt":1632570964321,"mc":[{"id":"1.188134680","rc":[{"batb":[[0,4.2,138.08],[1,4.1,3]],"batl":[[0,4.9,5],[1,5.8,2.54],[2,6,108.31]],"ltp":4.8,"tv":2980.71,"id":9631939},{"batb":[[1,1.26,64.48],[2,1.23,665.33]],"batl":[[0,1.31,841.3],[1,1.32,625.86]],"ltp":1.29,"tv":12675.54,"id":8681938}]}]}
{"op":"mcm","clk":"4296931075","pt":1632570966341,"mc":[{"id":"1.188134680","rc":[{"batb":[[0,4.2,142.96]],"batl":[[0,4.4,6.98],[1,4.5,6.67],[2,4.7,813.84]],"ltp":4.8,"tv":2980.71,"id":9631939},{"batb":[[0,1.29,9354.6],[1,1.28,547.68],[2,1.26,64.48]],"batl":[[2,1.33,3148.78]],"ltp":1.29,"tv":12675.54,"id":8681938}]}]}
{"op":"mcm","clk":"4296931270","pt":1632570967333,"mc":[{"id":"1.188134680","rc":[{"batb":[[0,4.3,2],[1,4.2,139.96]],"batl":[[2,4.7,203.46]],"ltp":4.8,"tv":2980.71,"id":9631939},{"batb":[[0,1.29,742.43],[1,1.28,1176.9],[2,1.27,1419.34]],"batl":[[0,1.31,831.3],[2,1.33,991.82]],"ltp":1.29,"tv":12675.54,"id":8681938}]}]}
{"op":"mcm","clk":"4296931438","pt":1632570968236,"mc":[{"id":"1.188134680","rc":[{"batb":[[0,4.2,139.96],[1,4.1,19.35]],"ltp":4.8,"tv":2980.71,"id":9631939},{"batb":[[1,1.28,1227.28]],"batl":[[2,1.33,1006.82]],"ltp":1.29,"tv":12675.54,"id":8681938}]}]}
{"op":"mcm","clk":"4296931588","pt":1632570969143,"mc":[{"id":"1.188134680","rc":[{"batb":[[1,1.28,1178.33]],"ltp":1.29,"tv":12675.54,"id":8681938}]}]}
{"op":"mcm","clk":"4296931644","pt":1632570969459,"mc":[{"id":"1.188134680","rc":[{"batb":[[2,4,104.89]],"ltp":4.8,"tv":2980.71,"id":9631939}]}]}
{"op":"mcm","clk":"4296931955","pt":1632570971249,"mc":[{"id":"1.188134680","rc":[{"batl":[[1,4.5,60.73]],"ltp":4.8,"tv":2980.71,"id":9631939},{"trd":[[1.29,431.76]],"batb":[[0,1.29,732.66]],"batl":[[1,1.32,660.14]],"ltp":1.29,"tv":12695.08,"id":8681938}],"tv":15675.8}]}
{"op":"mcm","clk":"4296932177","pt":1632570972367,"mc":[{"id":"1.188134680","rc":[{"batl":[[1,4.5,6.67]],"ltp":4.8,"tv":2980.71,"id":9631939},{"batb":[[2,1.27,1418.49]],"batl":[[0,1.3,51.22],[1,1.31,831.3],[2,1.32,625.86]],"ltp":1.29,"tv":12695.08,"id":8681938}]}]}
{"op":"mcm","clk":"4296932214","pt":1632570972585,"mc":[{"id":"1.188134680","rc":[{"batl":[[1,1.31,947.3]],"ltp":1.29,"tv":12695.08,"id":8681938}]}]}
{"op":"mcm","clk":"4296932392","pt":1632570973596,"mc":[{"id":"1.188134680","rc":[{"batl":[[2,4.7,317.53]],"ltp":4.8,"tv":2980.71,"id":9631939},{"batb":[[2,1.27,1713.61]],"ltp":1.29,"tv":12695.08,"id":8681938}]}]}
{"op":"mcm","clk":"4296932753","pt":1632570975762,"mc":[{"id":"1.188134680","rc":[{"batl":[[1,1.31,1148.3]],"ltp":1.29,"tv":12695.08,"id":8681938}]}]}
{"op":"mcm","clk":"4296933129","pt":1632570978366,"mc":[{"id":"1.188134680","rc":[{"trd":[[1.3,129.83]],"batb":[[0,1.28,1178.33],[1,1.27,1713.61],[2,1.26,586.79]],"batl":[[0,1.3,41.83]],"ltp":1.3,"tv":12713.87,"id":8681938}],"tv":15694.59}]}
{"op":"mcm","clk":"4296933237","pt":1632570979176,"mc":[{"id":"1.188134680","rc":[{"batl":[[1,1.31,1375.3]],"ltp":1.3,"tv":12713.87,"id":8681938}]}]}
{"op":"mcm","clk":"4296934015","pt":1632570983651,"mc":[{"id":"1.188134680","rc":[{"trd":[[4.4,112.53]],"batl":[[0,4.4,5.5]],"ltp":4.4,"tv":2982.19,"id":9631939},{"trd":[[1.29,436.81]],"ltp":1.29,"tv":12718.92,"id":8681938}],"tv":15701.12}]}
{"op":"mcm","clk":"4296935766","pt":1632570993693,"mc":[{"id":"1.188134680","rc":[{"batb":[[0,4.2,135.08]],"batl":[[0,4.5,6.67],[1,4.7,317.53],[2,4.8,344.72]],"ltp":4.4,"tv":2982.19,"id":9631939}]}]}
{"op":"mcm","clk":"4296936213","pt":1632570996566,"mc":[{"id":"1.188134680","rc":[{"batl":[[0,4.4,5.5],[1,4.5,6.67],[2,4.7,317.53]],"ltp":4.4,"tv":2982.19,"id":9631939},{"batl":[[1,1.31,1390.8]],"ltp":1.29,"tv":12718.92,"id":8681938}]}]}
{"op":"mcm","clk":"4296936906","pt":1632571000996,"mc":[{"id":"1.188134680","rc":[{"batl":[[0,1.31,1390.8],[1,1.32,625.86],[2,1.33,1001.93]],"ltp":1.29,"tv":12718.92,"id":8681938}]}]}
{"op":"mcm","clk":"4296937208","pt":1632571002909,"mc":[{"id":"1.188134680","rc":[{"batl":[[0,1.31,1712.8]],"ltp":1.29,"tv":12718.92,"id":8681938}]}]}
{"op":"mcm","clk":"4296937405","pt":1632571004182,"mc":[{"id":"1.188134680","rc":[{"batb":[[0,1.28,549.11],[1,1.27,859.16]],"batl":[[0,1.3,41.83],[1,1.31,923]],"ltp":1.29,"tv":12718.92,"id":8681938}]}]}
{"op":"mcm","clk":"4296937478","pt":1632571004704,"mc":[{"id":"1.188134680","rc":[{"trd":[[4.4,114.99]],"batl":[[0,4.4,4.27]],"ltp":4.4,"tv":2984.65,"id":9631939}],"tv":15703.57}]}
{"op":"mcm","clk":"4296937784","pt":1632571006814,"mc":[{"id":"1.188134680","rc":[{"batb":[[2,1.26,1495.77]],"ltp":1.29,"tv":12718.92,"id":8681938}]}]}
{"op":"mcm","clk":"4296937992","pt":1632571008308,"mc":[{"id":"1.188134680","rc":[{"batb":[[0,4.2,133.08],[2,3.8,87.95]],"batl":[[0,4.7,114.07],[1,4.8,122.24],[2,4.9,5]],"ltp":4.4,"tv":2984.65,"id":9631939},{"batb":[[0,1.27,859.16],[1,1.26,1495.77],[2,1.25,1504.14]],"batl":[[1,1.31,866],[2,1.33,15]],"ltp":1.29,"tv":12718.92,"id":8681938}]}]}
{"op":"mcm","clk":"4296938178","pt":1632571009312,"mc":[{"id":"1.188134680","rc":[{"batb":[[0,3.8,87.95],[1,3.65,104.67],[2,3.6,129]],"batl":[[1,4.8,114.55]],"ltp":4.4,"tv":2984.65,"id":9631939},{"batb":[[0,1.27,295.12],[1,1.26,1378.11]],"batl":[[1,1.36,716.42],[2,1.37,523.88]],"ltp":1.29,"tv":12718.92,"id":8681938}]}]}
{"op":"mcm","clk":"4296938479","pt":1632571011211,"mc":[{"id":"1.188134680","rc":[{"batb":[[0,3.85,2.02],[1,3.8,87.93],[2,3.7,2]],"batl":[[0,4.6,2],[1,4.7,114.07],[2,4.8,116.55]],"ltp":4.4,"tv":2984.65,"id":9631939},{"batb":[[0,1.28,40.66],[1,1.27,337.99],[2,1.26,1378.11]],"batl":[[1,1.35,36.5],[2,1.36,716.42]],"ltp":1.29,"tv":12718.92,"id":8681938}]}]}
{"op":"mcm","clk":"4296938537","pt":1632571011488,"mc":[{"id":"1.188134680","rc":[{"batl":[[0,4.7,114.07],[1,4.8,116.55],[2,4.9,3]],"ltp":4.4,"tv":2984.65,"id":9631939},{"batb":[[0,1.27,337.99],[1,1.26,1325.63],[2,1.25,1504.14]],"ltp":1.29,"tv":12718.92,"id":8681938}]}]}
{"op":"mcm","clk":"4296939202","pt":1632571015019,"mc":[{"id":"1.188134680","rc":[{"batb":[[1,1.26,416.65],[2,1.25,615.53]],"batl":[[2,1.37,34.5]],"ltp":1.29,"tv":12718.92,"id":8681938}]}]}
{"op":"mcm","clk":"4296939530","pt":1632571016820,"mc":[{"id":"1.188134680","rc":[{"batb":[[0,3.8,87.95],[1,3.7,2],[2,1.9,5.76]],"ltp":4.4,"tv":2984.65,"id":9631939},{"batl":[[0,1.37,34.5],[1,4.4,3.34],[2,8.8,7.31]],"ltp":1.29,"tv":12718.92,"id":8681938}]}]}
{"op":"mcm","clk":"4296939765","pt":1632571018308,"mc":[{"id":"1.188134680","rc":[{"batb":[[0,4.4,2.26],[1,4.2,189.01],[2,3.8,87.95]],"batl":[[0,4.7,78.17]],"ltp":4.4,"tv":2984.65,"id":9631939},{"batb":[[0,1.27,42.87],[1,1.26,1325.63],[2,1.25,1504.14]],"batl":[[0,1.29,1094.9],[1,1.3,862.37],[2,1.31,182.18]],"ltp":1.29,"tv":12718.92,"id":8681938}]}]}
{"op":"mcm","clk":"4296939935","pt":1632571019320,"mc":[{"id":"1.188134680","rc":[{"batb":[[0,4.5,117.61],[1,4.4,2.26],[2,4.2,207.76]],"batl":[[0,4.7,81.55],[2,4.9,4.71]],"ltp":4.4,"tv":2984.65,"id":9631939},{"batl":[[1,1.3,928.26]],"ltp":1.29,"tv":12718.92,"id":8681938}]}]}
{"op":"mcm","clk":"4296940118","pt":1632571020321,"mc":[{"id":"1.188134680","rc":[{"batl":[[0,1.28,42.48],[1,1.29,1094.9],[2,1.3,928.26]],"ltp":1.29,"tv":12718.92,"id":8681938}]}]}
{"op":"mcm","clk":"4296940207","pt":1632571020911,"mc":[{"id":"1.188134680","rc":[{"batb":[[0,4.5,124.27]],"batl":[[0,4.7,85.16]],"ltp":4.4,"tv":2984.65,"id":9631939}]}]}
{"op":"mcm","clk":"4296940334","pt":1632571021619,"mc":[{"id":"1.188134680","rc":[{"batl":[[0,1.28,375.48]],"ltp":1.29,"tv":12718.92,"id":8681938}]}]}
{"op":"mcm","clk":"4296940650","pt":1632571023461,"mc":[{"id":"1.188134680","rc":[{"batb":[[2,4.2,189.01]],"ltp":4.4,"tv":2984.65,"id":9631939}]}]}
{"op":"mcm","clk":"4296940998","pt":1632571025121,"mc":[{"id":"1.188134680","rc":[{"batb":[[2,4.2,191.01]],"batl":[[2,4.9,6.71]],"ltp":4.4,"tv":2984.65,"id":9631939},{"batb":[[1,1.26,1368.11],[2,1.25,1877.39]],"batl":[[0,1.28,616.48]],"ltp":1.29,"tv":12718.92,"id":8681938}]}]}
{"op":"mcm","clk":"4296941231","pt":1632571026655,"mc":[{"id":"1.188134680","rc":[{"batb":[[2,4.3,18.18]],"ltp":4.4,"tv":2984.65,"id":9631939},{"batl":[[0,1.28,630.19]],"ltp":1.29,"tv":12718.92,"id":8681938}]}]}
{"op":"mcm","clk":"4296941541","pt":1632571028318,"mc":[{"id":"1.188134680","rc":[{"batb":[[0,4.5,117.61],[1,4.3,18.18],[2,4.2,2]],"batl":[[0,4.9,3.71],[1,5,96.96],[2,5.1,107.23]],"ltp":4.4,"tv":2984.65,"id":9631939},{"batb":[[0,1.26,42.48],[1,1.25,1749.73],[2,1.24,1191.22]],"batl":[[1,1.3,15],[2,1.31,41.5]],"ltp":1.29,"tv":12718.92,"id":8681938}]}]}
{"op":"mcm","clk":"4296941679","pt":1632571029223,"mc":[{"id":"1.188134680","rc":[{"batb":[[0,4.2,2],[1,4,285.63],[2,3.95,128.16]],"batl":[[0,5,96.96],[1,5.1,107.23],[2,5.8,2.54]],"ltp":4.4,"tv":2984.65,"id":9631939},{"batb":[[0,1.25,1134.2],[1,1.24,1137.63],[2,1.01,140]],"batl":[[1,1.31,41.5],[2,1.33,37.5]],"ltp":1.29,"tv":12718.92,"id":8681938}]}]}
{"op":"mcm","clk":"4296941880","pt":1632571030340,"mc":[{"id":"1.188134680","rc":[{"batb":[[1,4,154.04],[2,3.9,3]],"ltp":4.4,"tv":2984.65,"id":9631939},{"batl":[[0,1.28,56.19]],"ltp":1.29,"tv":12718.92,"id":8681938}]}]}
{"op":"mcm","clk":"4296942056","pt":1632571031324,"mc":[{"id":"1.188134680","rc":[{"batl":[[1,5.1,114.63]],"ltp":4.4,"tv":2984.65,"id":9631939},{"batb":[[1,1.24,2067.62]],"batl":[[2,1.33,911.93]],"ltp":1.29,"tv":12718.92,"id":8681938}]}]}
{"op":"mcm","clk":"4296942203","pt":1632571032332,"mc":[{"id":"1.188134680","rc":[{"batl":[[0,4.9,2],[1,5,99.96],[2,5.1,107.23]],"ltp":4.4,"tv":2984.65,"id":9631939},{"batb":[[0,1.26,47.48],[1,1.25,1144.2],[2,1.24,2078.62]],"batl":[[0,1.27,13.71],[1,1.28,56.19],[2,1.31,41.5]],"ltp":1.29,"tv":12718.92,"id":8681938}]}]}
{"op":"mcm","clk":"4296942358","pt":1632571033336,"mc":[{"id":"1.188134680","rc":[{"batb":[[0,4.8,4.02],[1,4.6,102.18],[2,4.5,53.18]],"batl":[[0,5,104.82],[1,5.1,107.23],[2,5.8,2.54]],"ltp":4.4,"tv":2984.65,"id":9631939},{"batb":[[0,1.26,160.73]],"batl":[[1,1.28,1671.27],[2,1.29,704.22]],"ltp":1.29,"tv":12718.92,"id":8681938}]}]}
{"op":"mcm","clk":"4296942508","pt":1632571034240,"mc":[{"id":"1.188134680","rc":[{"batb":[[1,4.6,211.42]],"batl":[[0,5,110.82],[2,5.3,443.4]],"ltp":4.4,"tv":2984.65,"id":9631939}]}]}
{"op":"mcm","clk":"4296942666","pt":1632571035224,"mc":[{"id":"1.188134680","rc":[{"batl":[[0,5,124.54],[2,5.3,95.91]],"ltp":4.4,"tv":2984.65,"id":9631939},{"batb":[[1,1.25,1199.07]],"batl":[[2,1.29,719.22]],"ltp":1.29,"tv":12718.92,"id":8681938}]}]}
{"op":"mcm","clk":"4296942929","pt":1632571036816,"mc":[{"id":"1.188134680","rc":[{"trd":[[1.26,2129.83]],"batb":[[0,1.26,147.02]],"batl":[[0,1.27,236],[1,1.28,1615.08]],"ltp":1.26,"tv":12746.33,"id":8681938}],"tv":15730.99}]}
{"op":"mcm","clk":"4296943138","pt":1632571038179,"mc":[{"id":"1.188134680","rc":[{"batl":[[0,4.9,40.04],[1,5,124.54],[2,5.1,107.23]],"ltp":4.4,"tv":2984.65,"id":9631939},{"batl":[[2,1.29,807.88]],"ltp":1.26,"tv":12746.33,"id":8681938}]}]}
{"op":"mcm","clk":"4296943344","pt":1632571039361,"mc":[{"id":"1.188134680","rc":[{"batl":[[0,5,124.54],[1,5.1,107.23],[2,5.3,95.91]],"ltp":4.4,"tv":2984.65,"id":9631939},{"batl":[[2,1.29,719.22]],"ltp":1.26,"tv":12746.33,"id":8681938}]}]}
{"op":"mcm","clk":"4296943569","pt":1632571040846,"mc":[{"id":"1.188134680","rc":[{"batl":[[2,5.2,89.62]],"ltp":4.4,"tv":2984.65,"id":9631939},{"trd":[[1.26,2157.25]],"batb":[[0,1.26,133.31],[2,1.24,2588.53]],"batl":[[0,1.27,440],[2,1.29,759.72]],"ltp":1.26,"tv":12773.75,"id":8681938}],"tv":15758.41}]}
{"op":"mcm","clk":"4296943722","pt":1632571041953,"mc":[{"id":"1.188134680","rc":[{"batb":[[2,4.5,70.32]],"ltp":4.4,"tv":2984.65,"id":9631939},{"trd":[[1.26,2184.67]],"batb":[[0,1.26,119.6]],"ltp":1.26,"tv":12801.17,"id":8681938}],"tv":15785.82}]}
{"op":"mcm","clk":"4296944249","pt":1632571045079,"mc":[{"id":"1.188134680","rc":[{"trd":[[1.27,26.9]],"batb":[[2,1.24,2577.53]],"batl":[[0,1.27,437.57]],"ltp":1.27,"tv":12806.02,"id":8681938}],"tv":15790.68}]}
{"op":"mcm","clk":"4296944764","pt":1632571048368,"mc":[{"id":"1.188134680","rc":[{"batb":[[0,4.6,109.24],[1,4.5,17.14],[2,4.4,2]],"batl":[[0,5,5],[1,5.2,89.62],[2,5.3,98.02]],"ltp":4.4,"tv":2984.65,"id":9631939},{"batb":[[0,1.25,52.25],[1,1.24,2087.43],[2,1.23,1266.63]],"batl":[[1,1.29,55.5],[2,1.31,379.76]],"ltp":1.27,"tv":12806.02,"id":8681938}]}]}
{"op":"mcm","clk":"4296944928","pt":1632571049288,"mc":[{"id":"1.188134680","rc":[{"batb":[[0,4.4,2],[1,4.3,131.31],[2,4.2,125.64]],"batl":[[0,5.2,89.62],[1,5.3,90.79],[2,5.8,2.54]],"ltp":4.4,"tv":2984.65,"id":9631939},{"batb":[[0,1.24,1440.28],[1,1.23,1141.53],[2,1.01,140]],"batl":[[1,1.29,40.5]],"ltp":1.27,"tv":12806.02,"id":8681938}]}]}
{"op":"mcm","clk":"4296944991","pt":1632571049607,"mc":[{"id":"1.188134680","rc":[{"batl":[[0,1.26,13.71]],"ltp":1.27,"tv":12806.02,"id":8681938}]}]}
{"op":"mcm","clk":"4296945270","pt":1632571051357,"mc":[{"id":"1.188134680","rc":[{"batb":[[1,1.23,2125.39]],"batl":[[2,1.3,593.77]],"ltp":1.27,"tv":12806.02,"id":8681938}]}]}
{"op":"mcm","clk":"4296945398","pt":1632571052150,"mc":[{"id":"1.188134680","rc":[{"batb":[[1,4.2,257.2],[2,4.1,118.06]],"batl":[[0,5.2,92.62]],"ltp":4.4,"tv":2984.65,"id":9631939},{"batb":[[0,1.24,1449.28],[1,1.23,1149.51]],"batl":[[0,1.26,34.42],[2,1.31,379.76]],"ltp":1.27,"tv":12806.02,"id":8681938}]}]}
{"op":"mcm","clk":"4296945551","pt":1632571052998,"mc":[{"id":"1.188134680","rc":[{"trd":[[1.26,2227.62]],"batb":[[0,1.25,1149.17],[1,1.24,1449.28],[2,1.23,1149.51]],"batl":[[0,1.26,12.94],[1,1.28,584.13],[2,1.29,751.6]],"ltp":1.26,"tv":12848.98,"id":8681938}],"tv":15833.63}]}
{"op":"mcm","clk":"4296945904","pt":1632571055303,"mc":[{"id":"1.188134680","rc":[{"batb":[[0,4.5,2],[1,4.4,2],[2,4.2,257.2]],"batl":[[0,5,2],[1,5.2,92.62],[2,5.3,90.79]],"ltp":4.4,"tv":2984.65,"id":9631939},{"trd":[[1.26,2253.51]],"batb":[[0,1.25,1193.34]],"batl":[[0,1.28,630.47],[1,1.29,751.6],[2,1.31,379.76]],"ltp":1.26,"tv":12874.86,"id":8681938}],"tv":15859.52}]}
{"op":"mcm","clk":"4296946394","pt":1632571058176,"mc":[{"id":"1.188134680","rc":[{"batb":[[0,4.4,2],[1,4.2,257.2],[2,4.1,118.06]],"batl":[[0,5.2,92.62],[1,5.3,90.79],[2,5.8,2.54]],"ltp":4.4,"tv":2984.65,"id":9631939},{"batb":[[0,1.25,11.76]],"batl":[[0,1.29,40.5],[1,1.31,379.76],[2,1.32,313.63]],"ltp":1.26,"tv":12874.86,"id":8681938}]}]}
{"op":"mcm","clk":"4296946696","pt":1632571060188,"mc":[{"id":"1.188134680","rc":[{"batb":[[1,4.2,136.56],[2,4,2.02]],"ltp":4.4,"tv":2984.65,"id":9631939},{"batl":[[1,1.31,41.5],[2,1.33,37.5]],"ltp":1.26,"tv":12874.86,"id":8681938}]}]}
{"op":"mcm","clk":"4296946868","pt":1632571061372,"mc":[{"id":"1.188134680","rc":[{"batb":[[0,4.5,2],[1,4.4,4],[2,4.3,2]],"batl":[[0,5,2],[1,5.2,92.62],[2,5.3,90.79]],"ltp":4.4,"tv":2984.65,"id":9631939},{"batb":[[0,1.25,59.33],[2,1.23,2133.37]],"batl":[[0,1.28,47.34],[1,1.29,50.5],[2,1.34,7]],"ltp":1.26,"tv":12874.86,"id":8681938}]}]}
{"op":"mcm","clk":"4296946924","pt":1632571061708,"mc":[{"id":"1.188134680","rc":[{"batb":[[0,4.4,4],[1,4.3,2],[2,4.2,134.56]],"batl":[[0,5.2,92.62],[1,5.3,90.79],[2,5.8,2.54]],"ltp":4.4,"tv":2984.65,"id":9631939},{"batb":[[0,1.24,1449.28],[1,1.23,2133.37],[2,1.01,140]],"batl":[[0,1.29,50.5],[1,1.34,7],[2,4.4,3.34]],"ltp":1.26,"tv":12874.86,"id":8681938}]}]}
{"op":"mcm","clk":"4296947166","pt":1632571063187,"mc":[{"id":"1.188134680","rc":[{"batb":[[0,4.8,97.92],[1,4.7,223.69],[2,4.6,48.96]],"batl":[[0,5.1,45.81],[1,5.2,92.62],[2,5.3,90.79]],"ltp":4.4,"tv":2984.65,"id":9631939},{"batb":[[0,1.24,1463.26],[1,1.23,2124.37],[2,1.22,53.53]],"batl":[[0,1.25,6.92],[1,1.26,7867.5],[2,1.27,892.59]],"ltp":1.26,"tv":12874.86,"id":8681938}]}]}
{"op":"mcm","clk":"4296947360","pt":1632571064318,"mc":[{"id":"1.188134680","rc":[{"trd":[[5,1.73]],"batb":[[0,4.8,198.7],[2,4.6,65.62]],"batl":[[0,5.1,63.36]],"ltp":5.0,"tv":2986.38,"id":9631939},{"trd":[[1.25,17.36]],"batb":[[2,1.22,885.17]],"batl":[[0,1.26,624.4],[1,1.27,907.59],[2,1.28,963.89]],"ltp":1.25,"tv":12881.78,"id":8681938}],"tv":15868.17}]}
{"op":"mcm","clk":"4296947475","pt":1632571064899,"mc":[{"id":"1.188134680","rc":[{"batb":[[0,1.24,1523.64]],"ltp":1.25,"tv":12881.78,"id":8681938}]}]}
{"op":"mcm","clk":"4296947709","pt":1632571066225,"mc":[{"id":"1.188134680","rc":[{"trd":[[1.26,2262.08]],"batl":[[0,1.26,620.11]],"ltp":1.26,"tv":12890.36,"id":8681938}],"tv":15876.74}]}
{"op":"mcm","clk":"4296948041","pt":1632571068306,"mc":[{"id":"1.188134680","rc":[{"batb":[[2,4.6,48.96]],"ltp":5.0,"tv":2986.38,"id":9631939},{"batl":[[0,1.25,13.71],[1,1.26,620.11],[2,1.27,907.59]],"ltp":1.26,"tv":12890.36,"id":8681938}]}]}
{"op":"mcm","clk":"4296948082","pt":1632571068621,"mc":[{"id":"1.188134680","rc":[{"batl":[[1,1.26,752.11]],"ltp":1.26,"tv":12890.36,"id":8681938}]}]}
{"op":"mcm","clk":"4296948330","pt":1632571070218,"mc":[{"id":"1.188134680","rc":[{"batl":[[2,5.3,166.44]],"ltp":5.0,"tv":2986.38,"id":9631939},{"batb":[[1,1.23,2601.82],[2,1.22,1317.61]],"ltp":1.26,"tv":12890.36,"id":8681938}]}]}
{"op":"mcm","clk":"4296948500","pt":1632571071371,"mc":[{"id":"1.188134680","rc":[{"batb":[[1,4.7,239.9]],"ltp":5.0,"tv":2986.38,"id":9631939}]}]}
{"op":"mcm","clk":"4296948550","pt":1632571071641,"mc":[{"id":"1.188134680","rc":[{"trd":[[1.25,44.77],[1.26,2336.52]],"batl":[[0,1.26,714.89],[1,1.27,907.59],[2,1.28,1001.98]],"ltp":1.26,"tv":12992.21,"id":8681938}],"tv":15978.6}]}
{"op":"mcm","clk":"4296948683","pt":1632571072534,"mc":[{"id":"1.188134680","rc":[{"batl":[[0,1.26,872.89]],"ltp":1.26,"tv":12992.21,"id":8681938}]}]}
{"op":"mcm","clk":"4296948929","pt":1632571073929,"mc":[{"id":"1.188134680","rc":[{"batb":[[0,1.24,1509.66]],"ltp":1.26,"tv":12992.21,"id":8681938}]}]}
{"op":"mcm","clk":"4296949086","pt":1632571074949,"mc":[{"id":"1.188134680","rc":[{"batl":[[0,1.26,290]],"ltp":1.26,"tv":12992.21,"id":8681938}]}]}
{"op":"mcm","clk":"4296949175","pt":1632571075536,"mc":[{"id":"1.188134680","rc":[{"batl":[[0,1.26,446]],"ltp":1.26,"tv":12992.21,"id":8681938}]}]}
{"op":"mcm","clk":"4296949412","pt":1632571077064,"mc":[{"id":"1.188134680","rc":[{"batb":[[0,1.25,10],[1,1.24,1556.3],[2,1.23,2601.82]],"batl":[[0,1.26,478.64]],"ltp":1.26,"tv":12992.21,"id":8681938}]}]}
{"op":"mcm","clk":"4296949632","pt":1632571078451,"mc":[{"id":"1.188134680","rc":[{"batl":[[0,5,4.95],[1,5.1,63.36],[2,5.2,92.62]],"ltp":5.0,"tv":2986.38,"id":9631939},{"batb":[[1,1.24,1530.62]],"ltp":1.26,"tv":12992.21,"id":8681938}]}]}
{"op":"mcm","clk":"4296950090","pt":1632571081691,"mc":[{"id":"1.188134680","rc":[{"batl":[[0,5,6.95]],"ltp":5.0,"tv":2986.38,"id":9631939},{"batb":[[0,1.25,80.16]],"batl":[[0,1.26,724.64]],"ltp":1.26,"tv":12992.21,"id":8681938}]}]}
{"op":"mcm","clk":"4296951141","pt":1632571088086,"mc":[{"id":"1.188134680","rc":[{"batb":[[0,4.7,18.23],[1,4.5,12],[2,4.4,4]],"batl":[[0,5,4.95],[1,5.1,11.67],[2,5.2,2]],"ltp":5.0,"tv":2986.38,"id":9631939},{"batb":[[0,1.25,35.47],[1,1.24,498.81],[2,1.23,1461.31]],"batl":[[0,1.26,692],[1,1.27,812.61],[2,1.28,99.15]],"ltp":1.26,"tv":12992.21,"id":8681938}]}]}
{"op":"mcm","clk":"4296951329","pt":1632571089265,"mc":[{"id":"1.188134680","rc":[{"batb":[[0,4.7,2.02],[1,4.5,2]],"ltp":5.0,"tv":2986.38,"id":9631939},{"batl":[[0,1.27,797.61],[1,1.28,38.09],[2,1.29,10]],"ltp":1.26,"tv":12992.21,"id":8681938}]}]}
{"op":"mcm","clk":"4296951484","pt":1632571090276,"mc":[{"id":"1.188134680","rc":[{"trd":[[5,8.55]],"batl":[[0,5,1.54]],"ltp":5.0,"tv":2993.2,"id":9631939},{"trd":[[1.25,72.07]],"batb":[[0,1.25,21.82],[1,1.24,632.92]],"batl":[[0,1.27,948.71]],"ltp":1.25,"tv":13019.51,"id":8681938}],"tv":16012.72}]}
{"op":"mcm","clk":"4296951536","pt":1632571090594,"mc":[{"id":"1.188134680","rc":[{"batb":[[0,4.5,2],[1,4.4,4],[2,1.9,5.78]],"ltp":5.0,"tv":2993.2,"id":9631939},{"batl":[[0,1.26,608.37],[1,1.27,926.21],[2,1.28,38.09]],"ltp":1.25,"tv":13019.51,"id":8681938}]}]}
{"op":"mcm","clk":"4296951815","pt":1632571092298,"mc":[{"id":"1.188134680","rc":[{"batb":[[0,4.7,14.42],[1,4.5,2],[2,4.4,4]],"ltp":5.0,"tv":2993.2,"id":9631939},{"batl":[[1,1.27,987.27]],"ltp":1.25,"tv":13019.51,"id":8681938}]}]}
{"op":"mcm","clk":"4296952011","pt":1632571093370,"mc":[{"id":"1.188134680","rc":[{"batb":[[0,4.8,15.78]],"ltp":5.0,"tv":2993.2,"id":9631939},{"batl":[[1,1.27,1002.27]],"ltp":1.25,"tv":13019.51,"id":8681938}]}]}
{"op":"mcm","clk":"4296952294","pt":1632571095288,"mc":[{"id":"1.188134680","rc":[{"batl":[[1,5.1,45.75]],"ltp":5.0,"tv":2993.2,"id":9631939},{"batl":[[1,1.27,1067.63]],"ltp":1.25,"tv":13019.51,"id":8681938}]}]}
{"op":"mcm","clk":"4296952365","pt":1632571095769,"mc":[{"id":"1.188134680","rc":[{"batb":[[1,4.6,14.42],[2,4.5,2]],"batl":[[1,5.1,11.67]],"ltp":5.0,"tv":2993.2,"id":9631939},{"batl":[[1,1.27,1002.27]],"ltp":1.25,"tv":13019.51,"id":8681938}]}]}
{"op":"mcm","clk":"4296952585","pt":1632571097378,"mc":[{"id":"1.188134680","rc":[{"batb":[[2,4.5,4.56]],"ltp":5.0,"tv":2993.2,"id":9631939},{"batl":[[0,1.26,900.37]],"ltp":1.25,"tv":13019.51,"id":8681938}]}]}
{"op":"mcm","clk":"4296952627","pt":1632571097591,"mc":[{"id":"1.188134680","rc":[{"batb":[[2,4.5,2]],"ltp":5.0,"tv":2993.2,"id":9631939}]}]}
{"op":"mcm","clk":"4296953109","pt":1632571100556,"mc":[{"id":"1.188134680","rc":[{"batl":[[0,1.26,1262.37]],"ltp":1.25,"tv":13019.51,"id":8681938}]}]}
{"op":"mcm","clk":"4296953279","pt":1632571101783,"mc":[{"id":"1.188134680","rc":[{"trd":[[1.26,2336.54]],"batl":[[0,1.26,1262.36]],"ltp":1.26,"tv":13019.53,"id":8681938}],"tv":16012.74}]}
{"op":"mcm","clk":"4296953605","pt":1632571103711,"mc":[{"id":"1.188134680","rc":[{"batl":[[1,5.1,15.68]],"ltp":5.0,"tv":2993.2,"id":9631939},{"batl":[[0,1.26,1626.69]],"ltp":1.26,"tv":13019.53,"id":8681938}]}]}
{"op":"mcm","clk":"4296953938","pt":1632571105795,"mc":[{"id":"1.188134680","rc":[{"batl":[[0,5.1,4.01],[1,5.2,2],[2,5.3,75.66]],"ltp":5.0,"tv":2993.2,"id":9631939}]}]}
{"op":"mcm","clk":"4296954379","pt":1632571108983,"mc":[{"id":"1.188134680","rc":[{"batb":[[0,4.6,14.42],[1,4.5,2],[2,4.4,4]],"batl":[[0,4.9,1.54],[1,5.1,4.01],[2,5.2,2]],"ltp":5.0,"tv":2993.2,"id":9631939}]}]}
{"op":"mcm","clk":"4296954895","pt":1632571112331,"mc":[{"id":"1.188134680","rc":[{"batb":[[0,4.7,16.21]],"batl":[[0,5.2,2],[1,5.4,2],[2,5.7,90.72]],"ltp":5.0,"tv":2993.2,"id":9631939},{"batb":[[1,1.24,438.43],[2,1.23,1041.49]],"batl":[[0,1.26,1601.36],[1,1.27,790.11]],"ltp":1.26,"tv":13019.53,"id":8681938}]}]}
{"op":"mcm","clk":"4296955070","pt":1632571113319,"mc":[{"id":"1.188134680","rc":[{"batb":[[0,4.5,2],[1,4.4,4],[2,4.2,94.75]],"batl":[[0,5.7,83.81],[1,5.8,101.95],[2,6.4,2]],"ltp":5.0,"tv":2993.2,"id":9631939},{"batb":[[1,1.21,426.08],[2,1.2,515.58]],"batl":[[0,1.26,993],[1,1.28,38.09],[2,1.29,51.5]],"ltp":1.26,"tv":13019.53,"id":8681938}]}]}
{"op":"mcm","clk":"4296955149","pt":1632571113808,"mc":[{"id":"1.188134680","rc":[{"batb":[[0,4.4,4],[1,4.2,94.75],[2,4.1,131.13]],"ltp":5.0,"tv":2993.2,"id":9631939},{"batl":[[0,1.29,51.5],[1,1.31,323.45],[2,1.32,432.3]],"ltp":1.26,"tv":13019.53,"id":8681938}]}]}
{"op":"mcm","clk":"4296955518","pt":1632571116000,"mc":[{"id":"1.188134680","rc":[{"batl":[[0,4.8,1.54],[1,5.7,83.81],[2,5.8,101.95]],"ltp":5.0,"tv":2993.2,"id":9631939},{"batb":[[2,1.2,1133.22]],"batl":[[0,1.28,598.3],[1,1.29,762.14],[2,1.31,323.45]],"ltp":1.26,"tv":13019.53,"id":8681938}]}]}
{"op":"mcm","clk":"4296955658","pt":1632571117021,"mc":[{"id":"1.188134680","rc":[{"batb":[[0,4.5,5],[1,4.4,4],[2,4.3,3]],"ltp":5.0,"tv":2993.2,"id":9631939},{"batl":[[0,1.28,651.14]],"ltp":1.26,"tv":13019.53,"id":8681938}]}]}
{"op":"mcm","clk":"4296956367","pt":1632571121180,"mc":[{"id":"1.188134680","rc":[{"batl":[[1,5.8,2.54],[2,6.4,2]],"ltp":5.0,"tv":2993.2,"id":9631939},{"batb":[[1,1.19,66.09],[2,1.01,140]],"batl":[[1,1.29,720.64]],"ltp":1.26,"tv":13019.53,"id":8681938}]}]}
{"op":"mcm","clk":"4296956402","pt":1632571121393,"mc":[{"id":"1.188134680","rc":[{"batb":[[0,1.26,14.09],[1,1.25,21.82],[2,1.19,66.09]],"ltp":1.26,"tv":13019.53,"id":8681938}]}]}
{"op":"mcm","clk":"4296956618","pt":1632571122798,"mc":[{"id":"1.188134680","rc":[{"batb":[[0,4.5,2],[1,4.4,2],[2,4.2,94.75]],"ltp":5.0,"tv":2993.2,"id":9631939},{"batb":[[1,1.19,66.09],[2,1.01,140]],"batl":[[0,1.28,643.14],[1,1.29,710.64]],"ltp":1.26,"tv":13019.53,"id":8681938}]}]}
{"op":"mcm","clk":"4296956860","pt":1632571124348,"mc":[{"id":"1.188134680","rc":[{"batb":[[0,4.5,8.39],[2,4.3,222.38]],"batl":[[0,4.7,3.57],[1,4.8,1.54],[2,4.9,6.12]],"ltp":5.0,"tv":2993.2,"id":9631939},{"batb":[[1,1.25,8869.91],[2,1.24,2236.24]],"batl":[[2,1.3,156.77]],"ltp":1.26,"tv":13019.53,"id":8681938}]}]}
{"op":"mcm","clk":"4296957015","pt":1632571125302,"mc":[{"id":"1.188134680","rc":[{"batb":[[0,4.5,25.53]],"ltp":5.0,"tv":2993.2,"id":9631939},{"batb":[[1,1.25,2054.23]],"batl":[[1,1.29,725.64]],"ltp":1.26,"tv":13019.53,"id":8681938}]}]}
{"op":"mcm","clk":"4296957291","pt":1632571127130,"mc":[{"id":"1.188134680","rc":[{"trd":[[4.7,44.93]],"batl":[[0,4.7,1.57]],"ltp":4.7,"tv":2997.2,"id":9631939},{"batb":[[0,1.27,21.48]],"ltp":1.26,"tv":13019.53,"id":8681938}],"tv":16016.74}]}
{"op":"mcm","clk":"4296957431","pt":1632571128138,"mc":[{"id":"1.188134680","rc":[{"batb":[[0,4.5,23.53]],"ltp":4.7,"tv":2997.2,"id":9631939},{"batl":[[0,1.28,598.3]],"ltp":1.26,"tv":13019.53,"id":8681938}]}]}
{"op":"mcm","clk":"4296957864","pt":1632571131151,"mc":[{"id":"1.188134680","rc":[{"batb":[[2,4.3,349.6]],"ltp":4.7,"tv":2997.2,"id":9631939},{"batb":[[2,1.24,2289.26]],"batl":[[0,1.28,828.3],[1,1.29,770.14],[2,1.3,198.12]],"ltp":1.26,"tv":13019.53,"id":8681938}]}]}
{"op":"mcm","clk":"4296957962","pt":1632571131727,"mc":[{"id":"1.188134680","rc":[{"batb":[[1,1.26,52.72],[2,1.25,2054.23]],"ltp":1.26,"tv":13019.53,"id":8681938}]}]}
{"op":"mcm","clk":"4296958303","pt":1632571133916,"mc":[{"id":"1.188134680","rc":[{"batl":[[1,4.9,6.12],[2,5.1,1.71]],"ltp":4.7,"tv":2997.2,"id":9631939},{"batl":[[0,1.28,1063.3]],"ltp":1.26,"tv":13019.53,"id":8681938}]}]}
{"op":"mcm","clk":"4296958651","pt":1632571136120,"mc":[{"id":"1.188134680","rc":[{"batl":[[2,5.2,2]],"ltp":4.7,"tv":2997.2,"id":9631939},{"trd":[[1.28,116.55]],"batb":[[2,1.25,1133.19]],"batl":[[0,1.28,1028.07]],"ltp":1.28,"tv":13089.99,"id":8681938}],"tv":16087.19}]}
{"op":"mcm","clk":"4296958828","pt":1632571137284,"mc":[{"id":"1.188134680","rc":[{"trd":[[4.5,3.09]],"batb":[[0,4.5,17.14]],"batl":[[0,4.9,6.12],[1,5.2,2],[2,5.3,84]],"ltp":4.5,"tv":3000.28,"id":9631939},{"batl":[[0,1.28,1269.07]],"ltp":1.28,"tv":13089.99,"id":8681938}],"tv":16090.27}]}
{"op":"mcm","clk":"4296958941","pt":1632571137880,"mc":[{"id":"1.188134680","rc":[{"trd":[[1.28,121.77]],"batl":[[0,1.28,1266.46]],"ltp":1.28,"tv":13095.21,"id":8681938}],"tv":16095.49}]}
{"op":"mcm","clk":"4296959347","pt":1632571140238,"mc":[{"id":"1.188134680","rc":[{"batb":[[0,4.5,24.08]],"batl":[[0,4.8,7.65],[1,4.9,6.12],[2,5.2,2]],"ltp":4.5,"tv":3000.28,"id":9631939}]}]}
{"op":"mcm","clk":"4296959543","pt":1632571141305,"mc":[{"id":"1.188134680","rc":[{"batb":[[0,4.5,17.14],[2,4.3,127.22]],"batl":[[0,5.2,2],[1,5.3,84],[2,5.4,111.85]],"ltp":4.5,"tv":3000.28,"id":9631939},{"trd":[[1.28,149.95]],"batl":[[0,1.28,1252.37],[2,1.3,41.35]],"ltp":1.28,"tv":13123.39,"id":8681938}],"tv":16123.67}]}
{"op":"mcm","clk":"4296959782","pt":1632571142294,"mc":[{"id":"1.188134680","rc":[{"batb":[[0,4.4,2],[1,4.3,127.22],[2,4.1,102.23]],"batl":[[2,5.4,104.7]],"ltp":4.5,"tv":3000.28,"id":9631939},{"batb":[[2,1.24,53.4]],"batl":[[0,1.28,706],[1,1.29,44.5]],"ltp":1.28,"tv":13123.39,"id":8681938}]}]}
{"op":"mcm","clk":"4296959926","pt":1632571142907,"mc":[{"id":"1.188134680","rc":[{"batb":[[0,4.3,127.22],[1,4.1,102.23],[2,4,145.69]],"ltp":4.5,"tv":3000.28,"id":9631939},{"batl":[[0,1.3,41.35],[1,1.32,352.41],[2,1.33,327.08]],"ltp":1.28,"tv":13123.39,"id":8681938}]}]}
{"op":"mcm","clk":"4296960181","pt":1632571144089,"mc":[{"id":"1.188134680","rc":[{"batl":[[0,5.3,84],[1,5.4,104.7],[2,5.6,2]],"ltp":4.5,"tv":3000.28,"id":9631939},{"batb":[[0,1.28,2.82],[1,1.23,327.81],[2,1.22,556.46]],"ltp":1.28,"tv":13123.39,"id":8681938}]}]}
{"op":"mcm","clk":"4296960354","pt":1632571145119,"mc":[{"id":"1.188134680","rc":[{"batl":[[0,5.6,2],[1,5.8,2.54],[2,6,5]],"ltp":4.5,"tv":3000.28,"id":9631939},{"batb":[[1,1.22,49.72],[2,1.2,763.49]],"batl":[[0,1.3,894.88],[1,1.31,649.69],[2,1.32,352.41]],"ltp":1.28,"tv":13123.39,"id":8681938}]}]}
{"op":"mcm","clk":"4296960523","pt":1632571146192,"mc":[{"id":"1.188134680","rc":[{"batb":[[0,4.4,2],[1,4.3,130.22],[2,4.2,3]],"ltp":4.5,"tv":3000.28,"id":9631939},{"batl":[[0,1.29,44.5],[1,1.3,902.88],[2,1.31,649.69]],"ltp":1.28,"tv":13123.39,"id":8681938}]}]}
{"op":"mcm","clk":"4296960680","pt":1632571147205,"mc":[{"id":"1.188134680","rc":[{"batb":[[0,4.3,130.22],[1,4.2,3],[2,4.1,102.23]],"batl":[[0,5.2,4],[1,5.6,2],[2,5.8,2.54]],"ltp":4.5,"tv":3000.28,"id":9631939},{"batb":[[1,1.25,21.82],[2,1.24,62.4]],"batl":[[0,1.3,902.88],[1,1.31,649.69],[2,1.32,352.41]],"ltp":1.28,"tv":13123.39,"id":8681938}]}]}
{"op":"mcm","clk":"4296960852","pt":1632571148084,"mc":[{"id":"1.188134680","rc":[{"batb":[[0,4.3,127.22],[1,4.1,150.85],[2,4,145.69]],"batl":[[0,4.6,57.61],[1,4.7,25.54],[2,4.8,25.54]],"ltp":4.5,"tv":3000.28,"id":9631939},{"batb":[[0,1.28,533.64],[1,1.27,14456.68],[2,1.26,2358.12]],"batl":[[0,1.3,894.88],[2,1.32,714.63]],"ltp":1.28,"tv":13123.39,"id":8681938}]}]}
{"op":"mcm","clk":"4296961070","pt":1632571149213,"mc":[{"id":"1.188134680","rc":[{"batb":[[0,4.3,157.35],[1,4.2,135.11],[2,4.1,150.85]],"ltp":4.5,"tv":3000.28,"id":9631939},{"batb":[[0,1.28,530.82],[1,1.27,1744.24],[2,1.26,2948.12]],"batl":[[0,1.3,909.88],[2,1.32,892.66]],"ltp":1.28,"tv":13123.39,"id":8681938}]}]}
{"op":"mcm","clk":"4296961211","pt":1632571150014,"mc":[{"id":"1.188134680","rc":[{"batb":[[0,1.29,47.26],[1,1.28,530.82],[2,1.27,1744.24]],"ltp":1.28,"tv":13123.39,"id":8681938}]}]}
{"op":"mcm","clk":"4296961489","pt":1632571151291,"mc":[{"id":"1.188134680","rc":[{"batb":[[0,4.3,161.44]],"ltp":4.5,"tv":3000.28,"id":9631939},{"batb":[[0,1.29,61.75]],"ltp":1.28,"tv":13123.39,"id":8681938}]}]}
{"op":"mcm","clk":"4296961542","pt":1632571151608,"mc":[{"id":"1.188134680","rc":[{"batl":[[1,1.31,652.24]],"ltp":1.28,"tv":13123.39,"id":8681938}]}]}
{"op":"mcm","clk":"4296961944","pt":1632571154082,"mc":[{"id":"1.188134680","rc":[{"trd":[[1.29,441.9]],"batb":[[0,1.29,59.2]],"batl":[[0,1.3,1117.88]],"ltp":1.29,"tv":13128.49,"id":8681938}],"tv":16128.77}]}
{"op":"mcm","clk":"4296962143","pt":1632571155197,"mc":[{"id":"1.188134680","rc":[{"batb":[[1,4.2,137.11],[2,4.1,152.85]],"batl":[[2,4.8,118.47]],"ltp":4.5,"tv":3000.28,"id":9631939},{"batb":[[2,1.27,1785.11]],"batl":[[1,1.31,692.74],[2,1.32,931.52]],"ltp":1.29,"tv":13128.49,"id":8681938}]}]}
{"op":"mcm","clk":"4296962345","pt":1632571155897,"mc":[{"id":"1.188134680","rc":[{"trd":[[4.3,20.69]],"batb":[[0,4.3,152.05]],"ltp":4.3,"tv":3019.07,"id":9631939}],"tv":16147.56}]}
{"op":"mcm","clk":"4296962593","pt":1632571157289,"mc":[{"id":"1.188134680","rc":[{"batl":[[0,1.3,1414.88]],"ltp":1.29,"tv":13128.49,"id":8681938}]}]}
{"op":"mcm","clk":"4296962670","pt":1632571157823,"mc":[{"id":"1.188134680","rc":[{"trd":[[1.29,441.98]],"batb":[[0,1.29,59.16]],"ltp":1.29,"tv":13128.57,"id":8681938}],"tv":16147.64}]}
{"op":"mcm","clk":"4296962792","pt":1632571158726,"mc":[{"id":"1.188134680","rc":[{"trd":[[1.3,135.47]],"batl":[[0,1.3,1412.06]],"ltp":1.3,"tv":13134.2,"id":8681938}],"tv":16153.28}]}
{"op":"mcm","clk":"4296963022","pt":1632571160232,"mc":[{"id":"1.188134680","rc":[{"batb":[[0,4.3,134.01],[2,4.1,2]],"batl":[[0,4.8,92.93],[1,4.9,125.22],[2,5.1,7.4]],"ltp":4.3,"tv":3019.07,"id":9631939},{"batb":[[0,1.29,44.67],[1,1.27,40.87],[2,1.26,937.85]],"batl":[[0,1.3,520],[2,1.32,38.86]],"ltp":1.3,"tv":13134.2,"id":8681938}]}]}
{"op":"mcm","clk":"4296963203","pt":1632571161308,"mc":[{"id":"1.188134680","rc":[{"batb":[[0,4.2,137.11],[1,4.1,2],[2,3.95,112.9]],"batl":[[0,4.8,90.93],[2,5.2,2]],"ltp":4.3,"tv":3019.07,"id":9631939},{"batb":[[1,1.26,347.85],[2,1.25,369.65]],"batl":[[0,1.31,692.74],[1,1.32,38.86],[2,1.33,1.25]],"ltp":1.3,"tv":13134.2,"id":8681938}]}]}
{"op":"mcm","clk":"4296963283","pt":1632571161730,"mc":[{"id":"1.188134680","rc":[{"trd":[[1.29,446.68]],"batb":[[0,1.29,42.33]],"ltp":1.29,"tv":13138.9,"id":8681938}],"tv":16157.97}]}
{"op":"mcm","clk":"4296963534","pt":1632571163316,"mc":[{"id":"1.188134680","rc":[{"batl":[[0,4.9,2],[1,5.2,2],[2,5.6,2]],"ltp":4.3,"tv":3019.07,"id":9631939},{"batb":[[1,1.26,48.48],[2,1.24,11.38]],"batl":[[0,1.31,812.64],[1,1.32,664.94]],"ltp":1.29,"tv":13138.9,"id":8681938}]}]}
{"op":"mcm","clk":"4296963657","pt":1632571164018,"mc":[{"id":"1.188134680","rc":[{"batb":[[0,1.3,7.25],[1,1.29,42.33],[2,1.26,48.48]],"ltp":1.29,"tv":13138.9,"id":8681938}]}]}
{"op":"mcm","clk":"4296964069","pt":1632571166244,"mc":[{"id":"1.188134680","rc":[{"batl":[[0,4.3,5.97],[1,4.4,275.54],[2,4.5,60.07]],"ltp":4.3,"tv":3019.07,"id":9631939},{"batb":[[0,1.3,145.76],[2,1.28,648.9]],"batl":[[1,1.32,679.61]],"ltp":1.29,"tv":13138.9,"id":8681938}]}]}
{"op":"mcm","clk":"4296964272","pt":1632571167330,"mc":[{"id":"1.188134680","rc":[{"batb":[[1,4.1,167.54],[2,3.95,231.88]],"ltp":4.3,"tv":3019.07,"id":9631939},{"batl":[[1,1.32,739.61]],"ltp":1.29,"tv":13138.9,"id":8681938}]}]}
{"op":"mcm","clk":"4296964443","pt":1632571168344,"mc":[{"id":"1.188134680","rc":[{"trd":[[1.31,142.6]],"batb":[[0,1.3,145.86]],"batl":[[0,1.31,768.43]],"ltp":1.31,"tv":13227.32,"id":8681938}],"tv":16246.4}]}
{"op":"mcm","clk":"4296964613","pt":1632571169311,"mc":[{"id":"1.188134680","rc":[{"batb":[[0,4.2,135.11],[2,4,3.02]],"ltp":4.3,"tv":3019.07,"id":9631939},{"batl":[[0,1.31,727.93]],"ltp":1.31,"tv":13227.32,"id":8681938}]}]}
{"op":"mcm","clk":"4296965023","pt":1632571171931,"mc":[{"id":"1.188134680","rc":[{"trd":[[1.31,242.6]],"batl":[[0,1.31,677.93]],"ltp":1.31,"tv":13327.32,"id":8681938}],"tv":16346.4}]}
{"op":"mcm","clk":"4296965250","pt":1632571173222,"mc":[{"id":"1.188134680","rc":[{"batl":[[2,4.5,158.58]],"ltp":4.3,"tv":3019.07,"id":9631939},{"batb":[[1,1.29,408.7],[2,1.28,1099.9]],"batl":[[0,1.31,914.93]],"ltp":1.31,"tv":13327.32,"id":8681938}]}]}
{"op":"mcm","clk":"4296965400","pt":1632571174125,"mc":[{"id":"1.188134680","rc":[{"batb":[[1,1.29,366.38]],"ltp":1.31,"tv":13327.32,"id":8681938}]}]}
{"op":"mcm","clk":"4296965602","pt":1632571175213,"mc":[{"id":"1.188134680","rc":[{"batb":[[2,1.28,1155.71]],"batl":[[0,1.31,954.71]],"ltp":1.31,"tv":13327.32,"id":8681938}]}]}
