{"info": {"id": "1.187528277", "eventId": "30891863", "eventName": "Match Odds", "marketType": "MATCH_ODDS", "openDate": 1631477833160, "name": "Djokovic v Medvedev", "numberOfActiveRunner": 2, "countryCode": "", "sport": "TENNIS", "venue": "", "volume": {"total": 11825068.38, "preMatch": 1852569.96, "inPlay": 9972498.42}, "winner": {"id": 19924831, "name": "Daniil Medvedev", "status": "WINNER", "position": 2}, "delay": 3}, "runners": [{"id": 2249229, "name": "Novak Djokovic", "status": "LOSER", "position": 1, "inPlayOdds": 1.44, "inPlayTime": 1631477833160, "avgPrematch": 1.42, "closedOdds": 19.0, "maxPrematch": 1.44, "minPrematch": 1.38, "maxInPlay": 120.0, "minInPlay": 1.41, "inPlayIndex": 4532, "lengthOdds": 12014, "lengthOddsPrematch": 4532, "lengthOddsInPlay": 7482, "tradedVolume": 4302965.3, "preMatchVolume": 1578301.23, "inPlayVolume": 2724664.07}, {"id": 19924831, "name": "Daniil Medvedev", "status": "WINNER", "position": 2, "inPlayOdds": 3.3, "inPlayTime": 1631477833160, "avgPrematch": 3.34, "closedOdds": 1.01, "maxPrematch": 3.55, "minPrematch": 3.25, "maxInPlay": 3.45, "minInPlay": 1.01, "inPlayIndex": 3013, "lengthOdds": 10613, "lengthOddsPrematch": 3013, "lengthOddsInPlay": 7600, "tradedVolume": 7522103.08, "preMatchVolume": 274268.73, "inPlayVolume": 7247834.35}], "marketUpdates": [{"timestamp": 1631330837213000000, "openDate": "2021-09-12T15:00:00.000Z", "status": "OPEN", "betDelay": 0, "inPlay": false, "complete": true}, {"timestamp": 1631334824468000000, "openDate": "2021-09-12T20:00:00.000Z", "status": "OPEN", "betDelay": 0, "inPlay": false, "complete": true}, {"timestamp": 1631339930202000000, "openDate": "2021-09-12T20:00:00.000Z", "status": "SUSPENDED", "betDelay": 0, "inPlay": false, "complete": true}, {"timestamp": 1631339939435000000, "openDate": "2021-09-12T20:00:00.000Z", "status": "OPEN", "betDelay": 0, "inPlay": false, "complete": true}, {"timestamp": 1631476915685000000, "openDate": "2021-09-12T20:15:00.000Z", "status": "OPEN", "betDelay": 0, "inPlay": false, "complete": true}, {"timestamp": 1631477521419000000, "openDate": "2021-09-12T20:08:00.000Z", "status": "OPEN", "betDelay": 0, "inPlay": false, "complete": true}, {"timestamp": 1631477832479000000, "openDate": "2021-09-12T20:08:00.000Z", "status": "SUSPENDED", "betDelay": 0, "inPlay": false, "complete": true}, {"timestamp": 1631477833160000000, "openDate": "2021-09-12T20:08:00.000Z", "status": "OPEN", "betDelay": 3, "inPlay": true, "complete": true}, {"timestamp": 1631486006482000000, "openDate": "2021-09-12T20:08:00.000Z", "status": "SUSPENDED", "betDelay": 3, "inPlay": true, "complete": true}, {"timestamp": 1631486183103000000, "openDate": "2021-09-12T20:08:00.000Z", "status": "CLOSED", "betDelay": 3, "inPlay": true, "complete": true}], "odds": [{"runnerId": 2249229, "odds": [{"timestamp": 1631331869016, "ltp": 1.44, "tv": 88.67, "trd": [[1.44, 88.67]], "batb": NaN, "batl": [[0, 1.44, 111.33]]}, {"timestamp": 1631331959995, "ltp": 1.44, "tv": 199.5, "trd": [[1.44, 199.5]], "batb": NaN, "batl": [[0, 1.45, 1678.1], [1, 1.55, 3922.04], [2, 1.57, 189.6]]}, {"timestamp": 1631332002527, "ltp": 1.44, "tv": 200.5, "trd": [[1.44, 200.5]], "batb": [[0, 1.44, 255.71], [1, 1.41, 86.26], [2, 1.37, 5.32]], "batl": [[0, 1.45, 1677.6]]}, {"timestamp": 1631332017940, "ltp": 1.44, "tv": 200.5, "trd": NaN, "batb": [[1, 1.43, 256.21], [2, 1.41, 86.26]], "batl": NaN}, {"timestamp": 1631332022571, "ltp": 1.44, "tv": 711.92, "trd": [[1.44, 711.92]], "batb": [[0, 1.43, 256.21], [1, 1.41, 86.26], [2, 1.37, 5.32]], "batl": [[0, 1.44, 171.31], [1, 1.45, 1677.6], [2, 1.55, 3922.04]]}, {"timestamp": 1631332031567, "ltp": 1.44, "tv": 711.92, "trd": NaN, "batb": [[1, 1.42, 256.21], [2, 1.41, 86.26]], "batl": NaN}, {"timestamp": 1631332069472, "ltp": 1.44, "tv": 711.92, "trd": NaN, "batb": NaN, "batl": [[0, 1.45, 1677.6], [1, 1.55, 3922.04], [2, 1.57, 189.6]]}, {"timestamp": 1631332092682, "ltp": 1.44, "tv": 711.92, "trd": NaN, "batb": [[0, 1.44, 219.88], [1, 1.43, 256.21], [2, 1.42, 256.21]], "batl": NaN}, {"timestamp": 1631332104735, "ltp": 1.44, "tv": 711.92, "trd": NaN, "batb": [[1, 1.43, 454.1]], "batl": NaN}, {"timestamp": 1631332113662, "ltp": 1.44, "tv": 1144.28, "trd": [[1.44, 1144.28]], "batb": [[0, 1.44, 3.69]], "batl": NaN}, {"timestamp": 1631332116774, "ltp": 1.44, "tv": 1144.28, "trd": NaN, "batb": [[2, 1.42, 476.09]], "batl": NaN}, {"timestamp": 1631332131800, "ltp": 1.44, "tv": 1151.67, "trd": [[1.44, 1151.68]], "batb": [[0, 1.43, 454.1], [1, 1.42, 476.09], [2, 1.41, 86.26]], "batl": [[0, 1.44, 423.32], [1, 1.45, 1677.6], [2, 1.55, 3922.04]]}, {"timestamp": 1631332143935, "ltp": 1.44, "tv": 1151.67, "trd": NaN, "batb": NaN, "batl": [[2, 1.48, 249.38]]}, {"timestamp": 1631332160668, "ltp": 1.44, "tv": 1151.67, "trd": NaN, "batb": NaN, "batl": [[2, 1.47, 215.48]]}, {"timestamp": 1631332224515, "ltp": 1.43, "tv": 1164.13, "trd": [[1.43, 12.46]], "batb": [[0, 1.43, 441.64]], "batl": NaN}, {"timestamp": 1631332430841, "ltp": 1.43, "tv": 1164.13, "trd": NaN, "batb": [[0, 1.43, 641.64]], "batl": NaN}, {"timestamp": 1631332459366, "ltp": 1.43, "tv": 1164.13, "trd": NaN, "batb": [[0, 1.43, 441.64], [1, 1.42, 676.09]], "batl": NaN}, {"timestamp": 1631332977777, "ltp": 1.43, "tv": 1164.13, "trd": NaN, "batb": NaN, "batl": [[1, 1.45, 1704.19]]}, {"timestamp": 1631333024174, "ltp": 1.43, "tv": 2033.2, "trd": [[1.43, 881.53]], "batb": [[0, 1.43, 7.11]], "batl": NaN}, {"timestamp": 1631333104663, "ltp": 1.43, "tv": 2033.2, "trd": NaN, "batb": NaN, "batl": [[0, 1.45, 1704.19], [1, 1.47, 215.48], [2, 1.48, 1525.71]]}, {"timestamp": 1631333108487, "ltp": 1.43, "tv": 2033.2, "trd": NaN, "batb": [[0, 1.43, 268.32]], "batl": NaN}, {"timestamp": 1631333124369, "ltp": 1.43, "tv": 2033.2, "trd": NaN, "batb": NaN, "batl": [[0, 1.44, 393.32], [1, 1.45, 1704.19], [2, 1.47, 215.48]]}, {"timestamp": 1631333230677, "ltp": 1.43, "tv": 2417.84, "trd": [[1.43, 1266.17]], "batb": [[0, 1.43, 76]], "batl": NaN}, {"timestamp": 1631333243212, "ltp": 1.43, "tv": 2561.0, "trd": [[1.43, 1409.33]], "batb": [[0, 1.43, 4.42]], "batl": NaN}, {"timestamp": 1631333290695, "ltp": 1.42, "tv": 3921.79, "trd": [[1.42, 1351.94], [1.43, 1418.18]], "batb": [[0, 1.41, 86.38], [1, 1.4, 85.4], [2, 1.37, 5.32]], "batl": NaN}, {"timestamp": 1631333369024, "ltp": 1.42, "tv": 3921.79, "trd": NaN, "batb": NaN, "batl": [[0, 1.44, 820.34]]}, {"timestamp": 1631333376143, "ltp": 1.42, "tv": 3921.79, "trd": NaN, "batb": NaN, "batl": [[0, 1.44, 427.02], [1, 1.45, 1302.91]]}, {"timestamp": 1631333398249, "ltp": 1.42, "tv": 3921.79, "trd": NaN, "batb": NaN, "batl": [[0, 1.43, 100], [1, 1.44, 427.02], [2, 1.45, 1302.91]]}, {"timestamp": 1631333403783, "ltp": 1.42, "tv": 3921.79, "trd": NaN, "batb": NaN, "batl": [[1, 1.44, 527.02]]}, {"timestamp": 1631333481331, "ltp": 1.42, "tv": 3921.79, "trd": NaN, "batb": [[0, 1.4, 85.52], [1, 1.39, 86.26]], "batl": NaN}, {"timestamp": 1631333503488, "ltp": 1.42, "tv": 3921.79, "trd": NaN, "batb": [[1, 1.37, 5.32], [2, 1.36, 56.67]], "batl": NaN}, {"timestamp": 1631333507980, "ltp": 1.42, "tv": 3921.79, "trd": NaN, "batb": [[0, 1.37, 927.11], [1, 1.36, 56.67], [2, 1.33, 472.29]], "batl": NaN}, {"timestamp": 1631333554927, "ltp": 1.42, "tv": 3921.79, "trd": NaN, "batb": [[0, 1.38, 3.13], [1, 1.37, 926.99], [2, 1.36, 56.67]], "batl": NaN}, {"timestamp": 1631333567672, "ltp": 1.42, "tv": 3921.79, "trd": NaN, "batb": [[0, 1.38, 74.02], [1, 1.37, 5.32]], "batl": NaN}, {"timestamp": 1631333601892, "ltp": 1.38, "tv": 3974.97, "trd": [[1.38, 52.94], [1.42, 1352.18]], "batb": [[0, 1.38, 47.43]], "batl": NaN}, {"timestamp": 1631333614479, "ltp": 1.38, "tv": 3974.97, "trd": NaN, "batb": [[0, 1.38, 945.25]], "batl": NaN}, {"timestamp": 1631333614899, "ltp": 1.38, "tv": 3980.29, "trd": [[1.38, 58.25]], "batb": [[0, 1.38, 942.59]], "batl": NaN}, {"timestamp": 1631333621705, "ltp": 1.38, "tv": 3980.29, "trd": NaN, "batb": [[0, 1.38, 44.77]], "batl": NaN}, {"timestamp": 1631333621787, "ltp": 1.38, "tv": 3980.29, "trd": NaN, "batb": [[0, 1.38, 1391.5]], "batl": NaN}, {"timestamp": 1631333625617, "ltp": 1.38, "tv": 3980.29, "trd": NaN, "batb": [[0, 1.39, 845.5], [1, 1.38, 1391.5], [2, 1.37, 5.32]], "batl": NaN}, {"timestamp": 1631333674426, "ltp": 1.38, "tv": 3980.29, "trd": NaN, "batb": [[1, 1.38, 44.77]], "batl": [[0, 1.42, 3.06], [1, 1.43, 100], [2, 1.44, 527.02]]}, {"timestamp": 1631333678156, "ltp": 1.38, "tv": 3980.29, "trd": NaN, "batb": [[0, 1.38, 1391.5], [1, 1.37, 5.32], [2, 1.36, 56.67]], "batl": [[2, 1.44, 100]]}, {"timestamp": 1631333680071, "ltp": 1.38, "tv": 3980.29, "trd": NaN, "batb": [[2, 1.33, 472.29]], "batl": NaN}, {"timestamp": 1631333684351, "ltp": 1.38, "tv": 3980.29, "trd": NaN, "batb": [[0, 1.39, 35.33], [1, 1.38, 1391.5], [2, 1.37, 5.32]], "batl": NaN}, {"timestamp": 1631333691499, "ltp": 1.38, "tv": 3980.29, "trd": NaN, "batb": [[1, 1.38, 1427.75]], "batl": NaN}, {"timestamp": 1631333695683, "ltp": 1.38, "tv": 3980.29, "trd": NaN, "batb": [[0, 1.39, 44.59], [1, 1.38, 81.02]], "batl": NaN}, {"timestamp": 1631333701906, "ltp": 1.38, "tv": 3980.29, "trd": NaN, "batb": [[1, 1.38, 99.15]], "batl": NaN}, {"timestamp": 1631334331469, "ltp": 1.42, "tv": 3986.41, "trd": [[1.42, 1358.3]], "batb": [[0, 1.39, 45.15]], "batl": [[0, 1.43, 100], [1, 1.44, 100], [2, 1.45, 26.59]]}, {"timestamp": 1631334337976, "ltp": 1.42, "tv": 3986.41, "trd": NaN, "batb": NaN, "batl": [[2, 1.45, 664.75]]}, {"timestamp": 1631334341493, "ltp": 1.42, "tv": 3986.41, "trd": NaN, "batb": NaN, "batl": [[2, 1.45, 26.59]]}, {"timestamp": 1631334380157, "ltp": 1.42, "tv": 3986.41, "trd": NaN, "batb": [[0, 1.4, 6.57], [1, 1.39, 44.59], [2, 1.38, 99.15]], "batl": NaN}, {"timestamp": 1631334565145, "ltp": 1.4, "tv": 3999.54, "trd": [[1.4, 12.02], [1.42, 1359.41]], "batb": [[0, 1.39, 44.59], [1, 1.38, 99.15], [2, 1.37, 5.32]], "batl": [[0, 1.4, 6.73], [1, 1.43, 100], [2, 1.44, 100]]}, {"timestamp": 1631334566636, "ltp": 1.4, "tv": 3999.54, "trd": NaN, "batb": NaN, "batl": [[1, 1.42, 8.76], [2, 1.43, 100]]}, {"timestamp": 1631334568133, "ltp": 1.4, "tv": 3999.54, "trd": NaN, "batb": NaN, "batl": [[1, 1.43, 100], [2, 1.44, 100]]}, {"timestamp": 1631334585681, "ltp": 1.39, "tv": 4013.0, "trd": [[1.39, 13.45]], "batb": [[0, 1.39, 37.86]], "batl": [[0, 1.43, 100], [1, 1.44, 100], [2, 1.45, 26.59]]}, {"timestamp": 1631334614021, "ltp": 1.39, "tv": 4013.0, "trd": NaN, "batb": NaN, "batl": [[0, 1.42, 6.06], [1, 1.43, 100], [2, 1.44, 100]]}, {"timestamp": 1631334655109, "ltp": 1.39, "tv": 4013.0, "trd": NaN, "batb": NaN, "batl": [[0, 1.42, 14.77]]}, {"timestamp": 1631334656811, "ltp": 1.39, "tv": 4013.0, "trd": NaN, "batb": NaN, "batl": [[0, 1.42, 6.06]]}, {"timestamp": 1631334742571, "ltp": 1.39, "tv": 4013.0, "trd": NaN, "batb": NaN, "batl": [[0, 1.42, 14.77]]}, {"timestamp": 1631334744215, "ltp": 1.39, "tv": 4013.0, "trd": NaN, "batb": NaN, "batl": [[0, 1.42, 6.06]]}, {"timestamp": 1631334747991, "ltp": 1.39, "tv": 4013.0, "trd": NaN, "batb": [[0, 1.39, 96.79]], "batl": [[1, 1.43, 158.07]]}, {"timestamp": 1631334765439, "ltp": 1.39, "tv": 4249.85, "trd": [[1.39, 250.31]], "batb": [[0, 1.38, 1749.7], [1, 1.37, 5.32], [2, 1.36, 56.67]], "batl": NaN}, {"timestamp": 1631334766624, "ltp": 1.39, "tv": 4249.85, "trd": NaN, "batb": NaN, "batl": [[0, 1.42, 15.13]]}, {"timestamp": 1631334767343, "ltp": 1.39, "tv": 4249.85, "trd": NaN, "batb": [[0, 1.38, 1800.95]], "batl": [[0, 1.41, 50.39], [1, 1.42, 15.13], [2, 1.43, 100]]}, {"timestamp": 1631334770054, "ltp": 1.39, "tv": 4249.85, "trd": NaN, "batb": [[2, 1.33, 472.29]], "batl": NaN}, {"timestamp": 1631334817665, "ltp": 1.39, "tv": 4249.85, "trd": NaN, "batb": NaN, "batl": [[1, 1.42, 6.06]]}, {"timestamp": 1631334817974, "ltp": 1.4, "tv": 4259.05, "trd": [[1.4, 21.22]], "batb": NaN, "batl": NaN}, {"timestamp": 1631334819466, "ltp": 1.4, "tv": 4259.05, "trd": NaN, "batb": [[0, 1.39, 16.16], [1, 1.38, 1800.95], [2, 1.37, 5.32]], "batl": NaN}, {"timestamp": 1631334833383, "ltp": 1.4, "tv": 4259.05, "trd": NaN, "batb": [[1, 1.38, 150.4]], "batl": NaN}, {"timestamp": 1631334912933, "ltp": 1.4, "tv": 4259.05, "trd": NaN, "batb": [[0, 1.4, 170.81], [1, 1.39, 16.16], [2, 1.38, 150.4]], "batl": NaN}, {"timestamp": 1631334914222, "ltp": 1.4, "tv": 4259.05, "trd": NaN, "batb": [[1, 1.38, 150.4], [2, 1.37, 5.32]], "batl": NaN}, {"timestamp": 1631334957704, "ltp": 1.41, "tv": 4403.55, "trd": [[1.41, 144.5]], "batb": NaN, "batl": [[0, 1.42, 6.06], [1, 1.43, 100], [2, 1.44, 100]]}, {"timestamp": 1631334958582, "ltp": 1.41, "tv": 4403.72, "trd": [[1.41, 144.67]], "batb": [[0, 1.41, 10.47], [1, 1.4, 170.81], [2, 1.38, 150.4]], "batl": [[0, 1.42, 14.86]]}, {"timestamp": 1631334959710, "ltp": 1.41, "tv": 4403.72, "trd": NaN, "batb": NaN, "batl": [[0, 1.42, 6.06]]}, {"timestamp": 1631334967425, "ltp": 1.41, "tv": 4403.72, "trd": NaN, "batb": [[2, 1.39, 68.32]], "batl": [[1, 1.43, 167.47]]}, {"timestamp": 1631335025144, "ltp": 1.41, "tv": 4403.72, "trd": NaN, "batb": [[0, 1.41, 138.58]], "batl": NaN}, {"timestamp": 1631335716368, "ltp": 1.42, "tv": 4409.78, "trd": [[1.42, 1365.47]], "batb": NaN, "batl": [[0, 1.43, 167.47], [1, 1.44, 100], [2, 1.45, 1174.81]]}, {"timestamp": 1631335816652, "ltp": 1.42, "tv": 4409.78, "trd": NaN, "batb": [[2, 1.38, 99.15]], "batl": [[0, 1.43, 100]]}, {"timestamp": 1631335817427, "ltp": 1.42, "tv": 4409.78, "trd": NaN, "batb": [[1, 1.4, 231.45]], "batl": [[1, 1.44, 170.03]]}, {"timestamp": 1631336008958, "ltp": 1.42, "tv": 4409.78, "trd": NaN, "batb": [[0, 1.42, 2], [1, 1.41, 138.58], [2, 1.4, 231.45]], "batl": NaN}, {"timestamp": 1631336339266, "ltp": 1.42, "tv": 4409.78, "trd": NaN, "batb": NaN, "batl": [[0, 1.43, 300.27]]}, {"timestamp": 1631336414280, "ltp": 1.42, "tv": 4409.78, "trd": NaN, "batb": [[2, 1.4, 264.7]], "batl": NaN}, {"timestamp": 1631336452270, "ltp": 1.43, "tv": 4417.01, "trd": [[1.43, 1425.42]], "batb": NaN, "batl": [[0, 1.43, 296.65]]}, {"timestamp": 1631336454968, "ltp": 1.43, "tv": 4417.01, "trd": NaN, "batb": [[0, 1.42, 5.62]], "batl": NaN}, {"timestamp": 1631337120672, "ltp": 1.42, "tv": 4428.24, "trd": [[1.42, 1376.71]], "batb": [[0, 1.41, 138.58], [1, 1.4, 264.7], [2, 1.39, 200.27]], "batl": [[0, 1.42, 154.89], [1, 1.43, 296.65], [2, 1.44, 170.03]]}, {"timestamp": 1631337144596, "ltp": 1.42, "tv": 4583.14, "trd": [[1.42, 1531.6]], "batb": NaN, "batl": [[0, 1.43, 296.65], [1, 1.44, 170.03], [2, 1.45, 1174.81]]}, {"timestamp": 1631337435059, "ltp": 1.42, "tv": 4583.14, "trd": NaN, "batb": NaN, "batl": [[0, 1.42, 343.54], [1, 1.43, 296.65], [2, 1.44, 170.03]]}, {"timestamp": 1631337586007, "ltp": 1.42, "tv": 4583.14, "trd": NaN, "batb": NaN, "batl": [[0, 1.42, 350.43]]}, {"timestamp": 1631337587244, "ltp": 1.42, "tv": 4583.14, "trd": NaN, "batb": NaN, "batl": [[0, 1.42, 357.32]]}, {"timestamp": 1631337595757, "ltp": 1.42, "tv": 4583.14, "trd": NaN, "batb": NaN, "batl": [[0, 1.42, 343.54]]}, {"timestamp": 1631337615278, "ltp": 1.42, "tv": 4583.14, "trd": NaN, "batb": NaN, "batl": [[0, 1.42, 350.43]]}, {"timestamp": 1631337617754, "ltp": 1.42, "tv": 4583.14, "trd": NaN, "batb": NaN, "batl": [[0, 1.42, 343.54]]}, {"timestamp": 1631337619557, "ltp": 1.41, "tv": 4596.92, "trd": [[1.41, 158.45]], "batb": [[0, 1.41, 131.69]], "batl": NaN}, {"timestamp": 1631337624767, "ltp": 1.41, "tv": 4596.92, "trd": NaN, "batb": NaN, "batl": [[0, 1.42, 350.43]]}, {"timestamp": 1631337628475, "ltp": 1.41, "tv": 4610.7, "trd": [[1.41, 172.23]], "batb": [[0, 1.41, 124.79]], "batl": NaN}, {"timestamp": 1631337629567, "ltp": 1.41, "tv": 4610.7, "trd": NaN, "batb": NaN, "batl": [[0, 1.42, 361]]}, {"timestamp": 1631337645655, "ltp": 1.41, "tv": 4610.7, "trd": NaN, "batb": NaN, "batl": [[0, 1.42, 354.11]]}, {"timestamp": 1631337943119, "ltp": 1.41, "tv": 4610.7, "trd": NaN, "batb": NaN, "batl": [[0, 1.42, 247.22]]}, {"timestamp": 1631338197033, "ltp": 1.41, "tv": 4663.87, "trd": [[1.41, 225.4]], "batb": [[0, 1.41, 98.21]], "batl": NaN}, {"timestamp": 1631338252855, "ltp": 1.42, "tv": 4703.87, "trd": [[1.42, 1571.6]], "batb": NaN, "batl": [[0, 1.42, 227.22]]}, {"timestamp": 1631338412458, "ltp": 1.42, "tv": 4703.87, "trd": NaN, "batb": NaN, "batl": [[0, 1.42, 247.22]]}, {"timestamp": 1631338616235, "ltp": 1.42, "tv": 4703.87, "trd": NaN, "batb": NaN, "batl": [[0, 1.42, 131.08]]}, {"timestamp": 1631338710854, "ltp": 1.42, "tv": 4703.87, "trd": NaN, "batb": NaN, "batl": [[0, 1.42, 214.96]]}, {"timestamp": 1631338717377, "ltp": 1.42, "tv": 4703.87, "trd": NaN, "batb": NaN, "batl": [[0, 1.42, 415.23], [1, 1.43, 96.38]]}, {"timestamp": 1631338729574, "ltp": 1.42, "tv": 4703.87, "trd": NaN, "batb": NaN, "batl": [[0, 1.42, 214.96], [1, 1.43, 296.65]]}, {"timestamp": 1631338749629, "ltp": 1.41, "tv": 4899.57, "trd": [[1.41, 421.1]], "batb": [[0, 1.4, 265.06], [1, 1.39, 200.27], [2, 1.38, 81.02]], "batl": NaN}, {"timestamp": 1631338803704, "ltp": 1.41, "tv": 4899.57, "trd": NaN, "batb": NaN, "batl": [[0, 1.42, 415.23], [1, 1.43, 96.38]]}, {"timestamp": 1631338826701, "ltp": 1.41, "tv": 4899.57, "trd": NaN, "batb": NaN, "batl": [[2, 1.44, 159.78]]}, {"timestamp": 1631338826866, "ltp": 1.41, "tv": 4899.57, "trd": NaN, "batb": [[0, 1.4, 282.14]], "batl": NaN}, {"timestamp": 1631338828708, "ltp": 1.41, "tv": 4899.57, "trd": NaN, "batb": [[0, 1.4, 273.6]], "batl": [[2, 1.44, 167.47]]}, {"timestamp": 1631338921214, "ltp": 1.41, "tv": 4899.57, "trd": NaN, "batb": [[0, 1.41, 80.1], [1, 1.4, 273.24], [2, 1.39, 200.27]], "batl": NaN}, {"timestamp": 1631339034705, "ltp": 1.41, "tv": 4899.57, "trd": NaN, "batb": [[1, 1.4, 339.35]], "batl": NaN}, {"timestamp": 1631339035277, "ltp": 1.41, "tv": 4899.57, "trd": NaN, "batb": [[0, 1.41, 98.68]], "batl": [[0, 1.42, 469.76]]}, {"timestamp": 1631339036350, "ltp": 1.41, "tv": 4899.57, "trd": NaN, "batb": NaN, "batl": [[1, 1.43, 137.71]]}, {"timestamp": 1631339079675, "ltp": 1.42, "tv": 5200.84, "trd": [[1.42, 1872.87]], "batb": NaN, "batl": [[0, 1.42, 168.49]]}, {"timestamp": 1631339092709, "ltp": 1.42, "tv": 5200.84, "trd": NaN, "batb": NaN, "batl": [[0, 1.42, 54.53]]}, {"timestamp": 1631339101197, "ltp": 1.42, "tv": 5200.84, "trd": NaN, "batb": [[0, 1.41, 184.99]], "batl": NaN}, {"timestamp": 1631339106625, "ltp": 1.42, "tv": 5309.9, "trd": [[1.42, 1981.93]], "batb": [[0, 1.42, 78.8], [1, 1.41, 98.68], [2, 1.4, 339.35]], "batl": [[0, 1.43, 186.21], [1, 1.44, 167.47], [2, 1.45, 1174.81]]}, {"timestamp": 1631339116633, "ltp": 1.42, "tv": 5309.9, "trd": NaN, "batb": [[1, 1.41, 109.75], [2, 1.4, 273.24]], "batl": [[0, 1.43, 439.27]]}, {"timestamp": 1631339117714, "ltp": 1.42, "tv": 5309.9, "trd": NaN, "batb": [[0, 1.42, 43.61]], "batl": [[1, 1.44, 211.06]]}, {"timestamp": 1631339195711, "ltp": 1.42, "tv": 5309.9, "trd": NaN, "batb": [[1, 1.41, 115.42]], "batl": [[0, 1.43, 472.19], [1, 1.44, 220.25]]}, {"timestamp": 1631339261710, "ltp": 1.42, "tv": 5309.9, "trd": NaN, "batb": NaN, "batl": [[1, 1.44, 227.67]]}, {"timestamp": 1631339274621, "ltp": 1.42, "tv": 5309.9, "trd": NaN, "batb": NaN, "batl": [[0, 1.43, 219.14]]}, {"timestamp": 1631339327654, "ltp": 1.42, "tv": 5309.9, "trd": NaN, "batb": [[0, 1.42, 106.63]], "batl": [[0, 1.43, 186.21]]}, {"timestamp": 1631339613926, "ltp": 1.43, "tv": 5355.0, "trd": [[1.43, 1470.52]], "batb": NaN, "batl": [[0, 1.43, 163.66]]}, {"timestamp": 1631339685320, "ltp": 1.42, "tv": 5568.25, "trd": [[1.42, 2195.18]], "batb": [[0, 1.41, 123.94], [1, 1.4, 273.24], [2, 1.39, 200.27]], "batl": [[0, 1.42, 651.1], [1, 1.43, 163.66], [2, 1.44, 227.67]]}, {"timestamp": 1631339687436, "ltp": 1.42, "tv": 5568.25, "trd": NaN, "batb": NaN, "batl": [[0, 1.43, 163.66], [1, 1.44, 227.67], [2, 1.45, 1174.81]]}, {"timestamp": 1631339700554, "ltp": 1.42, "tv": 5568.25, "trd": NaN, "batb": [[1, 1.4, 339.35]], "batl": NaN}, {"timestamp": 1631339701665, "ltp": 1.42, "tv": 5568.25, "trd": NaN, "batb": [[0, 1.41, 128.08]], "batl": NaN}, {"timestamp": 1631339839834, "ltp": 1.42, "tv": 5568.25, "trd": NaN, "batb": NaN, "batl": [[0, 1.43, 270.02]]}, {"timestamp": 1631339849720, "ltp": 1.42, "tv": 5568.25, "trd": NaN, "batb": NaN, "batl": [[0, 1.43, 285.81]]}, {"timestamp": 1631339930202, "ltp": 1.42, "tv": 5568.25, "trd": NaN, "batb": [[0, 1.41, 39.82]], "batl": [[0, 1.43, 237.31]]}, {"timestamp": 1631339939435, "ltp": 1.42, "tv": 5568.25, "trd": NaN, "batb": [[0, 1.41, 129.59]], "batl": [[0, 1.43, 325.83]]}, {"timestamp": 1631339956458, "ltp": 1.42, "tv": 5568.25, "trd": NaN, "batb": [[0, 1.41, 125.45]], "batl": NaN}, {"timestamp": 1631339957437, "ltp": 1.42, "tv": 5568.25, "trd": NaN, "batb": NaN, "batl": [[0, 1.43, 340.2]]}, {"timestamp": 1631340014805, "ltp": 1.42, "tv": 5568.25, "trd": NaN, "batb": [[0, 1.41, 119.78]], "batl": NaN}, {"timestamp": 1631340116117, "ltp": 1.42, "tv": 5568.25, "trd": NaN, "batb": NaN, "batl": [[1, 1.44, 355.78]]}, {"timestamp": 1631340134507, "ltp": 1.42, "tv": 5568.25, "trd": NaN, "batb": NaN, "batl": [[1, 1.44, 361.68]]}, {"timestamp": 1631340216875, "ltp": 1.42, "tv": 5568.25, "trd": NaN, "batb": [[2, 1.38, 81.02]], "batl": NaN}, {"timestamp": 1631340236003, "ltp": 1.41, "tv": 5571.7, "trd": [[1.41, 424.56]], "batb": [[0, 1.41, 118.05]], "batl": NaN}, {"timestamp": 1631340997496, "ltp": 1.41, "tv": 5571.7, "trd": NaN, "batb": NaN, "batl": [[1, 1.44, 711.68]]}, {"timestamp": 1631341090589, "ltp": 1.43, "tv": 5763.23, "trd": [[1.43, 1662.04]], "batb": NaN, "batl": [[0, 1.43, 148.68]]}, {"timestamp": 1631341091267, "ltp": 1.43, "tv": 5763.23, "trd": NaN, "batb": [[1, 1.4, 306.09]], "batl": NaN}, {"timestamp": 1631341097652, "ltp": 1.43, "tv": 5763.23, "trd": NaN, "batb": [[0, 1.41, 122.53]], "batl": [[0, 1.43, 134.3]]}, {"timestamp": 1631341109660, "ltp": 1.43, "tv": 5763.23, "trd": NaN, "batb": [[0, 1.42, 19.67], [1, 1.41, 122.53], [2, 1.4, 306.09]], "batl": [[0, 1.43, 103.41]]}, {"timestamp": 1631341109765, "ltp": 1.43, "tv": 5763.23, "trd": NaN, "batb": [[0, 1.42, 63.46]], "batl": NaN}, {"timestamp": 1631341128493, "ltp": 1.43, "tv": 5763.23, "trd": NaN, "batb": [[1, 1.41, 183.17], [2, 1.4, 236.91]], "batl": [[1, 1.44, 644.21], [2, 1.45, 1253.38]]}, {"timestamp": 1631341134640, "ltp": 1.43, "tv": 5970.03, "trd": [[1.43, 1868.84]], "batb": [[0, 1.42, 2523.87]], "batl": [[0, 1.44, 644.22], [1, 1.45, 1253.38], [2, 1.46, 328.81]]}, {"timestamp": 1631341136711, "ltp": 1.43, "tv": 5970.03, "trd": NaN, "batb": [[0, 1.43, 125.87], [1, 1.42, 2523.87], [2, 1.41, 183.17]], "batl": [[0, 1.44, 644.21]]}, {"timestamp": 1631341151625, "ltp": 1.43, "tv": 5970.03, "trd": NaN, "batb": [[0, 1.43, 82.39], [2, 1.41, 172.1]], "batl": NaN}, {"timestamp": 1631341152447, "ltp": 1.43, "tv": 5970.03, "trd": NaN, "batb": [[2, 1.41, 150.41]], "batl": NaN}, {"timestamp": 1631341154688, "ltp": 1.43, "tv": 5970.03, "trd": NaN, "batb": [[1, 1.42, 2589.97]], "batl": [[0, 1.44, 668.9]]}, {"timestamp": 1631341155511, "ltp": 1.43, "tv": 5970.03, "trd": NaN, "batb": NaN, "batl": [[1, 1.45, 1319.48]]}, {"timestamp": 1631341180629, "ltp": 1.43, "tv": 5990.03, "trd": [[1.43, 1888.84]], "batb": [[0, 1.43, 72.39], [1, 1.42, 129.56]], "batl": NaN}, {"timestamp": 1631341181419, "ltp": 1.43, "tv": 5990.03, "trd": NaN, "batb": [[0, 1.43, 82.39], [1, 1.42, 2589.97]], "batl": NaN}, {"timestamp": 1631341204592, "ltp": 1.43, "tv": 5994.03, "trd": [[1.43, 1892.84]], "batb": [[0, 1.42, 2589.97], [1, 1.41, 150.41], [2, 1.4, 170.81]], "batl": [[0, 1.43, 12], [1, 1.44, 668.9], [2, 1.45, 1319.48]]}, {"timestamp": 1631341204961, "ltp": 1.43, "tv": 5994.03, "trd": NaN, "batb": [[0, 1.43, 82.39], [1, 1.42, 2589.97], [2, 1.41, 150.41]], "batl": [[0, 1.44, 668.9], [1, 1.45, 1319.48], [2, 1.46, 328.81]]}, {"timestamp": 1631341220623, "ltp": 1.43, "tv": 5994.03, "trd": NaN, "batb": [[0, 1.42, 129.56], [1, 1.41, 150.41], [2, 1.4, 170.81]], "batl": [[0, 1.43, 12], [1, 1.44, 668.9], [2, 1.45, 1319.48]]}, {"timestamp": 1631341220942, "ltp": 1.43, "tv": 5994.03, "trd": NaN, "batb": [[0, 1.43, 82.39], [1, 1.42, 2589.97], [2, 1.41, 150.41]], "batl": [[0, 1.44, 668.9], [1, 1.45, 1319.48], [2, 1.46, 328.81]]}, {"timestamp": 1631341301605, "ltp": 1.43, "tv": 5994.03, "trd": NaN, "batb": NaN, "batl": [[0, 1.44, 880.39]]}, {"timestamp": 1631341302589, "ltp": 1.43, "tv": 5994.03, "trd": NaN, "batb": NaN, "batl": [[0, 1.44, 892.3]]}, {"timestamp": 1631341351715, "ltp": 1.43, "tv": 5994.03, "trd": NaN, "batb": [[0, 1.42, 2589.97], [1, 1.41, 150.41], [2, 1.4, 170.81]], "batl": [[0, 1.43, 12], [1, 1.44, 892.3], [2, 1.45, 1319.48]]}, {"timestamp": 1631341352034, "ltp": 1.43, "tv": 5994.03, "trd": NaN, "batb": [[0, 1.43, 82.39], [1, 1.42, 2589.97], [2, 1.41, 150.41]], "batl": [[0, 1.44, 892.3], [1, 1.45, 1319.48], [2, 1.46, 328.81]]}, {"timestamp": 1631341382637, "ltp": 1.43, "tv": 5994.03, "trd": NaN, "batb": [[0, 1.42, 2589.97], [1, 1.41, 150.41], [2, 1.4, 170.81]], "batl": [[0, 1.43, 12], [1, 1.44, 892.3], [2, 1.45, 1319.48]]}, {"timestamp": 1631341383157, "ltp": 1.43, "tv": 5994.03, "trd": NaN, "batb": [[0, 1.43, 82.39], [1, 1.42, 2589.97], [2, 1.41, 150.41]], "batl": [[0, 1.44, 892.3], [1, 1.45, 1319.48], [2, 1.46, 328.81]]}, {"timestamp": 1631341427529, "ltp": 1.43, "tv": 5994.03, "trd": NaN, "batb": [[0, 1.42, 129.56], [1, 1.41, 150.41], [2, 1.4, 170.81]], "batl": NaN}, {"timestamp": 1631341428165, "ltp": 1.43, "tv": 5994.03, "trd": NaN, "batb": [[0, 1.43, 82.39], [1, 1.42, 2589.97], [2, 1.41, 150.41]], "batl": NaN}, {"timestamp": 1631341429566, "ltp": 1.43, "tv": 5994.03, "trd": NaN, "batb": [[1, 1.42, 2553.36], [2, 1.41, 204.32]], "batl": NaN}, {"timestamp": 1631341483629, "ltp": 1.43, "tv": 5994.03, "trd": NaN, "batb": [[0, 1.42, 2589.97], [1, 1.41, 150.41], [2, 1.4, 170.81]], "batl": [[0, 1.43, 12], [1, 1.44, 892.3], [2, 1.45, 1319.48]]}, {"timestamp": 1631341484345, "ltp": 1.43, "tv": 5994.03, "trd": NaN, "batb": [[0, 1.43, 82.39], [1, 1.42, 2589.97], [2, 1.41, 150.41]], "batl": [[0, 1.44, 892.3], [1, 1.45, 1319.48], [2, 1.46, 328.81]]}, {"timestamp": 1631341520683, "ltp": 1.43, "tv": 5994.03, "trd": NaN, "batb": [[0, 1.42, 2589.97], [1, 1.41, 150.41], [2, 1.4, 170.81]], "batl": [[0, 1.43, 12], [1, 1.44, 892.3], [2, 1.45, 1319.48]]}, {"timestamp": 1631341521099, "ltp": 1.43, "tv": 5994.03, "trd": NaN, "batb": [[0, 1.43, 82.39], [1, 1.42, 2589.97], [2, 1.41, 150.41]], "batl": [[0, 1.44, 892.3], [1, 1.45, 1319.48], [2, 1.46, 328.81]]}, {"timestamp": 1631341532511, "ltp": 1.43, "tv": 5994.03, "trd": NaN, "batb": NaN, "batl": [[0, 1.44, 897.21]]}, {"timestamp": 1631341533703, "ltp": 1.43, "tv": 5994.03, "trd": NaN, "batb": [[0, 1.42, 2589.97], [1, 1.41, 150.41], [2, 1.4, 170.81]], "batl": [[0, 1.43, 12], [1, 1.44, 897.21], [2, 1.45, 1319.48]]}, {"timestamp": 1631341534114, "ltp": 1.43, "tv": 5994.03, "trd": NaN, "batb": [[0, 1.43, 82.39], [1, 1.42, 2589.97], [2, 1.41, 150.41]], "batl": [[0, 1.44, 897.21], [1, 1.45, 1319.48], [2, 1.46, 328.81]]}, {"timestamp": 1631341549519, "ltp": 1.43, "tv": 5994.03, "trd": NaN, "batb": [[0, 1.42, 129.56], [1, 1.41, 150.41], [2, 1.4, 170.81]], "batl": NaN}, {"timestamp": 1631341550244, "ltp": 1.43, "tv": 5994.03, "trd": NaN, "batb": [[0, 1.43, 82.39], [1, 1.42, 2589.97], [2, 1.41, 150.41]], "batl": NaN}, {"timestamp": 1631341591721, "ltp": 1.43, "tv": 5994.03, "trd": NaN, "batb": [[1, 1.42, 129.56]], "batl": NaN}, {"timestamp": 1631341592549, "ltp": 1.43, "tv": 5994.03, "trd": NaN, "batb": [[1, 1.42, 2589.97]], "batl": NaN}, {"timestamp": 1631341622670, "ltp": 1.43, "tv": 5994.03, "trd": NaN, "batb": [[1, 1.42, 129.56]], "batl": NaN}, {"timestamp": 1631341623388, "ltp": 1.43, "tv": 5994.03, "trd": NaN, "batb": [[1, 1.42, 2589.97]], "batl": NaN}, {"timestamp": 1631341746685, "ltp": 1.43, "tv": 5998.03, "trd": [[1.43, 1896.84]], "batb": [[0, 1.43, 80.39], [1, 1.42, 129.56]], "batl": NaN}, {"timestamp": 1631341747476, "ltp": 1.43, "tv": 5998.03, "trd": NaN, "batb": [[0, 1.43, 82.39], [1, 1.42, 2589.97]], "batl": NaN}, {"timestamp": 1631341831110, "ltp": 1.43, "tv": 6162.81, "trd": [[1.43, 2061.62]], "batb": [[0, 1.42, 2589.97], [1, 1.41, 150.41], [2, 1.4, 170.81]], "batl": [[0, 1.43, 405.27], [1, 1.44, 897.21], [2, 1.45, 1319.48]]}, {"timestamp": 1631341839225, "ltp": 1.43, "tv": 6162.81, "trd": NaN, "batb": NaN, "batl": [[0, 1.43, 892.93]]}, {"timestamp": 1631341847856, "ltp": 1.43, "tv": 6162.81, "trd": NaN, "batb": NaN, "batl": [[0, 1.43, 1380.59]]}, {"timestamp": 1631341853361, "ltp": 1.43, "tv": 6162.81, "trd": NaN, "batb": [[1, 1.41, 204.32]], "batl": [[2, 1.45, 1253.38]]}, {"timestamp": 1631341854181, "ltp": 1.43, "tv": 6162.81, "trd": NaN, "batb": NaN, "batl": [[0, 1.43, 1389.55], [1, 1.44, 892.3]]}, {"timestamp": 1631341855277, "ltp": 1.43, "tv": 6162.81, "trd": NaN, "batb": NaN, "batl": [[1, 1.44, 867.61]]}, {"timestamp": 1631341856466, "ltp": 1.43, "tv": 6162.81, "trd": NaN, "batb": NaN, "batl": [[0, 1.43, 1877.21]]}, {"timestamp": 1631341867410, "ltp": 1.43, "tv": 6162.81, "trd": NaN, "batb": NaN, "batl": [[0, 1.43, 2364.87]]}, {"timestamp": 1631341870805, "ltp": 1.43, "tv": 6162.81, "trd": NaN, "batb": NaN, "batl": [[0, 1.43, 1877.21]]}, {"timestamp": 1631341906583, "ltp": 1.43, "tv": 6162.81, "trd": NaN, "batb": [[1, 1.41, 212.41]], "batl": NaN}, {"timestamp": 1631341909649, "ltp": 1.43, "tv": 6162.81, "trd": NaN, "batb": [[0, 1.42, 129.56]], "batl": NaN}, {"timestamp": 1631341909959, "ltp": 1.43, "tv": 6162.81, "trd": NaN, "batb": [[0, 1.42, 3412.38]], "batl": NaN}, {"timestamp": 1631341915582, "ltp": 1.42, "tv": 9962.81, "trd": [[1.42, 5995.18]], "batb": [[0, 1.42, 1512.38]], "batl": NaN}, {"timestamp": 1631341916561, "ltp": 1.42, "tv": 9962.81, "trd": NaN, "batb": [[0, 1.42, 904.15]], "batl": NaN}, {"timestamp": 1631341918572, "ltp": 1.42, "tv": 9962.81, "trd": NaN, "batb": [[0, 1.42, 38.36]], "batl": [[0, 1.43, 1949.09]]}, {"timestamp": 1631341922580, "ltp": 1.42, "tv": 9995.63, "trd": [[1.42, 6028]], "batb": [[0, 1.42, 5.53]], "batl": NaN}, {"timestamp": 1631341967581, "ltp": 1.42, "tv": 9995.63, "trd": NaN, "batb": [[1, 1.41, 182.27]], "batl": NaN}, {"timestamp": 1631341968507, "ltp": 1.42, "tv": 9995.63, "trd": NaN, "batb": NaN, "batl": [[0, 1.43, 2049.53]]}, {"timestamp": 1631342208714, "ltp": 1.42, "tv": 9995.63, "trd": NaN, "batb": [[1, 1.41, 162.62]], "batl": [[2, 1.45, 1174.81]]}, {"timestamp": 1631342209024, "ltp": 1.42, "tv": 9995.63, "trd": NaN, "batb": NaN, "batl": [[1, 1.44, 927.39]]}, {"timestamp": 1631342210628, "ltp": 1.42, "tv": 9995.63, "trd": NaN, "batb": [[1, 1.41, 121.63]], "batl": NaN}, {"timestamp": 1631342210840, "ltp": 1.42, "tv": 9995.63, "trd": NaN, "batb": [[2, 1.4, 245.96]], "batl": [[1, 1.44, 935.94]]}, {"timestamp": 1631342218666, "ltp": 1.42, "tv": 9995.63, "trd": NaN, "batb": [[2, 1.4, 240.84]], "batl": NaN}, {"timestamp": 1631342218875, "ltp": 1.42, "tv": 9995.63, "trd": NaN, "batb": NaN, "batl": [[1, 1.44, 944.48]]}, {"timestamp": 1631342247497, "ltp": 1.42, "tv": 9995.63, "trd": NaN, "batb": [[1, 1.41, 108.02]], "batl": NaN}, {"timestamp": 1631342308154, "ltp": 1.42, "tv": 9995.63, "trd": NaN, "batb": [[2, 1.4, 385.44]], "batl": NaN}, {"timestamp": 1631342513659, "ltp": 1.42, "tv": 9995.63, "trd": NaN, "batb": NaN, "batl": [[1, 1.44, 867.61]]}, {"timestamp": 1631342514068, "ltp": 1.42, "tv": 9995.63, "trd": NaN, "batb": [[2, 1.4, 373.49]], "batl": [[0, 1.43, 2099.06]]}, {"timestamp": 1631342627361, "ltp": 1.42, "tv": 9995.63, "trd": NaN, "batb": [[1, 1.41, 795.52]], "batl": NaN}, {"timestamp": 1631342644467, "ltp": 1.42, "tv": 9995.63, "trd": NaN, "batb": [[1, 1.41, 840.11]], "batl": NaN}, {"timestamp": 1631343095665, "ltp": 1.42, "tv": 9995.63, "trd": NaN, "batb": [[0, 1.42, 2473.37]], "batl": [[0, 1.43, 2027.18]]}, {"timestamp": 1631343130667, "ltp": 1.42, "tv": 9995.63, "trd": NaN, "batb": NaN, "batl": [[0, 1.43, 2013.54]]}, {"timestamp": 1631343175573, "ltp": 1.42, "tv": 9995.63, "trd": NaN, "batb": [[1, 1.41, 984.71]], "batl": NaN}, {"timestamp": 1631343617638, "ltp": 1.42, "tv": 9995.63, "trd": NaN, "batb": [[0, 1.42, 2492.86]], "batl": NaN}, {"timestamp": 1631343725479, "ltp": 1.42, "tv": 9995.63, "trd": NaN, "batb": [[1, 1.41, 1107.25]], "batl": NaN}, {"timestamp": 1631343726485, "ltp": 1.42, "tv": 9995.63, "trd": NaN, "batb": [[0, 1.42, 2667.24]], "batl": [[0, 1.43, 2156.53], [1, 1.44, 1036.46]]}, {"timestamp": 1631343728418, "ltp": 1.42, "tv": 9995.63, "trd": NaN, "batb": [[0, 1.42, 2794]], "batl": NaN}, {"timestamp": 1631343802600, "ltp": 1.42, "tv": 9995.63, "trd": NaN, "batb": [[1, 1.41, 1170.18]], "batl": [[1, 1.44, 1106.22]]}, {"timestamp": 1631343869224, "ltp": 1.43, "tv": 10016.91, "trd": [[1.43, 2082.9]], "batb": NaN, "batl": [[0, 1.43, 2145.89]]}, {"timestamp": 1631343880934, "ltp": 1.43, "tv": 10038.66, "trd": [[1.43, 2104.65]], "batb": NaN, "batl": [[0, 1.43, 2135.02]]}, {"timestamp": 1631343883618, "ltp": 1.43, "tv": 10038.66, "trd": NaN, "batb": [[1, 1.41, 1179.62]], "batl": NaN}, {"timestamp": 1631343884401, "ltp": 1.43, "tv": 10038.66, "trd": NaN, "batb": NaN, "batl": [[1, 1.44, 1118.28]]}, {"timestamp": 1631343952680, "ltp": 1.42, "tv": 10049.3, "trd": [[1.42, 6038.64]], "batb": [[0, 1.42, 2788.68]], "batl": NaN}, {"timestamp": 1631343953775, "ltp": 1.42, "tv": 10049.3, "trd": NaN, "batb": [[0, 1.42, 2788.46]], "batl": NaN}, {"timestamp": 1631344034294, "ltp": 1.42, "tv": 10081.02, "trd": [[1.42, 6070.36]], "batb": [[0, 1.42, 320.62]], "batl": [[0, 1.43, 2162.39]]}, {"timestamp": 1631344040281, "ltp": 1.42, "tv": 10081.02, "trd": NaN, "batb": [[0, 1.42, 194.34]], "batl": NaN}, {"timestamp": 1631344041165, "ltp": 1.42, "tv": 10081.02, "trd": NaN, "batb": NaN, "batl": [[1, 1.44, 1124.33]]}, {"timestamp": 1631344042096, "ltp": 1.42, "tv": 10187.37, "trd": [[1.42, 6176.72]], "batb": [[0, 1.42, 141.16]], "batl": NaN}, {"timestamp": 1631344108344, "ltp": 1.42, "tv": 10187.37, "trd": NaN, "batb": NaN, "batl": [[1, 1.44, 1112.42]]}, {"timestamp": 1631344119643, "ltp": 1.42, "tv": 10469.7, "trd": [[1.42, 6459.04]], "batb": [[0, 1.41, 1179.62], [1, 1.4, 373.49], [2, 1.39, 144.6]], "batl": [[0, 1.42, 196.84], [1, 1.43, 2162.39], [2, 1.44, 1112.42]]}, {"timestamp": 1631344120652, "ltp": 1.42, "tv": 10483.24, "trd": [[1.42, 6472.58]], "batb": [[0, 1.41, 1137.57]], "batl": [[0, 1.42, 190.07]]}, {"timestamp": 1631344121344, "ltp": 1.42, "tv": 10483.24, "trd": NaN, "batb": NaN, "batl": [[1, 1.43, 2179.13]]}, {"timestamp": 1631344126064, "ltp": 1.42, "tv": 10576.5, "trd": [[1.42, 6565.84]], "batb": NaN, "batl": [[0, 1.42, 143.44]]}, {"timestamp": 1631344131382, "ltp": 1.42, "tv": 10863.38, "trd": [[1.42, 6852.72]], "batb": NaN, "batl": [[0, 1.43, 2179.13], [1, 1.44, 1112.42], [2, 1.45, 1174.81]]}, {"timestamp": 1631344195400, "ltp": 1.42, "tv": 10863.38, "trd": NaN, "batb": [[1, 1.4, 557.83]], "batl": NaN}, {"timestamp": 1631344196611, "ltp": 1.42, "tv": 10863.38, "trd": NaN, "batb": [[0, 1.41, 1120.67]], "batl": [[0, 1.43, 2189.69]]}, {"timestamp": 1631344300234, "ltp": 1.42, "tv": 10863.38, "trd": NaN, "batb": [[1, 1.4, 585.48]], "batl": NaN}, {"timestamp": 1631344384746, "ltp": 1.42, "tv": 10863.38, "trd": NaN, "batb": [[1, 1.4, 589.63]], "batl": NaN}, {"timestamp": 1631344456679, "ltp": 1.42, "tv": 10863.38, "trd": NaN, "batb": NaN, "batl": [[0, 1.43, 2140.15]]}, {"timestamp": 1631344457050, "ltp": 1.42, "tv": 10863.38, "trd": NaN, "batb": [[1, 1.4, 599.88]], "batl": [[1, 1.44, 1189.29]]}, {"timestamp": 1631344678951, "ltp": 1.42, "tv": 10863.38, "trd": NaN, "batb": [[0, 1.42, 26.59], [1, 1.41, 1120.67], [2, 1.4, 599.88]], "batl": NaN}, {"timestamp": 1631344715370, "ltp": 1.42, "tv": 10863.38, "trd": NaN, "batb": [[2, 1.4, 415.53]], "batl": NaN}, {"timestamp": 1631344716577, "ltp": 1.42, "tv": 10863.38, "trd": NaN, "batb": [[2, 1.4, 383.73]], "batl": NaN}, {"timestamp": 1631344717264, "ltp": 1.42, "tv": 10863.38, "trd": NaN, "batb": [[0, 1.42, 30.58]], "batl": NaN}, {"timestamp": 1631344764608, "ltp": 1.42, "tv": 10863.38, "trd": NaN, "batb": [[0, 1.42, 31.55]], "batl": NaN}, {"timestamp": 1631344813550, "ltp": 1.43, "tv": 10914.43, "trd": [[1.43, 2155.7]], "batb": NaN, "batl": [[0, 1.43, 2114.63]]}, {"timestamp": 1631344815742, "ltp": 1.43, "tv": 10914.43, "trd": NaN, "batb": [[0, 1.42, 79.55]], "batl": NaN}, {"timestamp": 1631344892584, "ltp": 1.43, "tv": 10914.43, "trd": NaN, "batb": [[0, 1.42, 87.49]], "batl": NaN}, {"timestamp": 1631345087328, "ltp": 1.43, "tv": 10914.43, "trd": NaN, "batb": [[2, 1.4, 390.57]], "batl": [[1, 1.44, 1179.89]]}, {"timestamp": 1631345108965, "ltp": 1.43, "tv": 10914.43, "trd": NaN, "batb": [[0, 1.42, 140.67]], "batl": NaN}, {"timestamp": 1631345143315, "ltp": 1.43, "tv": 10914.43, "trd": NaN, "batb": [[0, 1.42, 87.49]], "batl": NaN}, {"timestamp": 1631345243449, "ltp": 1.43, "tv": 10914.43, "trd": NaN, "batb": [[0, 1.42, 214.25]], "batl": [[0, 1.43, 2087.26]]}, {"timestamp": 1631345245473, "ltp": 1.42, "tv": 11143.9, "trd": [[1.42, 7082.19]], "batb": [[0, 1.42, 99.52]], "batl": NaN}, {"timestamp": 1631345250456, "ltp": 1.42, "tv": 11147.31, "trd": [[1.42, 7085.6]], "batb": [[0, 1.42, 97.81]], "batl": NaN}, {"timestamp": 1631345297499, "ltp": 1.43, "tv": 11326.87, "trd": [[1.43, 2335.25]], "batb": NaN, "batl": [[0, 1.43, 1997.48]]}, {"timestamp": 1631345311459, "ltp": 1.43, "tv": 11326.87, "trd": NaN, "batb": [[0, 1.42, 233.37]], "batl": NaN}, {"timestamp": 1631345311791, "ltp": 1.43, "tv": 11326.87, "trd": NaN, "batb": NaN, "batl": [[0, 1.43, 2003.37]]}, {"timestamp": 1631345322142, "ltp": 1.43, "tv": 11326.87, "trd": NaN, "batb": [[0, 1.42, 351.37]], "batl": NaN}, {"timestamp": 1631345375428, "ltp": 1.43, "tv": 11326.87, "trd": NaN, "batb": [[0, 1.42, 356.21]], "batl": NaN}, {"timestamp": 1631345449191, "ltp": 1.43, "tv": 11326.87, "trd": NaN, "batb": NaN, "batl": [[0, 1.43, 2032.27]]}, {"timestamp": 1631345459502, "ltp": 1.43, "tv": 11326.87, "trd": NaN, "batb": [[0, 1.42, 351.37]], "batl": NaN}, {"timestamp": 1631345460438, "ltp": 1.43, "tv": 11326.87, "trd": NaN, "batb": [[0, 1.42, 269.24]], "batl": NaN}, {"timestamp": 1631345510414, "ltp": 1.43, "tv": 11326.87, "trd": NaN, "batb": [[0, 1.42, 256.2]], "batl": [[0, 1.43, 2026.38]]}, {"timestamp": 1631345511512, "ltp": 1.43, "tv": 11326.87, "trd": NaN, "batb": NaN, "batl": [[0, 1.43, 2015.82]]}, {"timestamp": 1631345649540, "ltp": 1.43, "tv": 11326.87, "trd": NaN, "batb": NaN, "batl": [[0, 1.43, 1999.08]]}, {"timestamp": 1631345650538, "ltp": 1.43, "tv": 11326.87, "trd": NaN, "batb": NaN, "batl": [[0, 1.43, 1981.15]]}, {"timestamp": 1631345782904, "ltp": 1.43, "tv": 11326.87, "trd": NaN, "batb": [[0, 1.42, 284.46]], "batl": NaN}, {"timestamp": 1631345850018, "ltp": 1.43, "tv": 11326.87, "trd": NaN, "batb": [[0, 1.42, 288.7]], "batl": NaN}, {"timestamp": 1631345975843, "ltp": 1.43, "tv": 11326.87, "trd": NaN, "batb": [[1, 1.41, 1248.78]], "batl": [[1, 1.44, 1308]]}, {"timestamp": 1631346004268, "ltp": 1.43, "tv": 11326.87, "trd": NaN, "batb": [[1, 1.41, 1268.26]], "batl": NaN}, {"timestamp": 1631346044345, "ltp": 1.43, "tv": 11326.87, "trd": NaN, "batb": [[1, 1.41, 1271.19]], "batl": [[1, 1.44, 1301.94]]}, {"timestamp": 1631346128568, "ltp": 1.43, "tv": 11326.87, "trd": NaN, "batb": NaN, "batl": [[1, 1.44, 1311.94]]}, {"timestamp": 1631346353370, "ltp": 1.42, "tv": 11346.87, "trd": [[1.42, 7105.6]], "batb": [[0, 1.42, 278.7]], "batl": NaN}, {"timestamp": 1631346370300, "ltp": 1.43, "tv": 11350.87, "trd": [[1.43, 2339.25]], "batb": NaN, "batl": [[0, 1.43, 1979.16]]}, {"timestamp": 1631346461529, "ltp": 1.42, "tv": 11370.87, "trd": [[1.42, 7125.6]], "batb": [[0, 1.42, 268.7]], "batl": NaN}, {"timestamp": 1631346464342, "ltp": 1.42, "tv": 11370.87, "trd": NaN, "batb": [[0, 1.42, 285.53]], "batl": NaN}, {"timestamp": 1631346539371, "ltp": 1.42, "tv": 11370.87, "trd": NaN, "batb": NaN, "batl": [[1, 1.44, 1323.05]]}, {"timestamp": 1631346609988, "ltp": 1.42, "tv": 11370.87, "trd": NaN, "batb": [[2, 1.4, 402.52]], "batl": NaN}, {"timestamp": 1631346747442, "ltp": 1.43, "tv": 11424.04, "trd": [[1.43, 2392.43]], "batb": NaN, "batl": [[0, 1.43, 1952.57]]}, {"timestamp": 1631346830397, "ltp": 1.43, "tv": 11424.04, "trd": NaN, "batb": NaN, "batl": [[0, 1.43, 1918.24], [1, 1.44, 1310.98]]}, {"timestamp": 1631346908620, "ltp": 1.43, "tv": 11424.04, "trd": NaN, "batb": NaN, "batl": [[0, 1.43, 1897.88]]}, {"timestamp": 1631346939643, "ltp": 1.43, "tv": 11424.04, "trd": NaN, "batb": NaN, "batl": [[1, 1.44, 1302.44]]}, {"timestamp": 1631346943679, "ltp": 1.43, "tv": 11424.04, "trd": NaN, "batb": [[0, 1.42, 289.21]], "batl": NaN}, {"timestamp": 1631346970703, "ltp": 1.43, "tv": 11424.04, "trd": NaN, "batb": [[0, 1.42, 211.4]], "batl": NaN}, {"timestamp": 1631346985434, "ltp": 1.43, "tv": 11424.04, "trd": NaN, "batb": [[0, 1.42, 207.72]], "batl": NaN}, {"timestamp": 1631346986217, "ltp": 1.43, "tv": 11424.04, "trd": NaN, "batb": [[0, 1.42, 186.65]], "batl": NaN}, {"timestamp": 1631346987513, "ltp": 1.43, "tv": 11424.04, "trd": NaN, "batb": [[0, 1.42, 158.39]], "batl": [[0, 1.43, 1907.47]]}, {"timestamp": 1631347028428, "ltp": 1.43, "tv": 11424.04, "trd": NaN, "batb": [[0, 1.42, 141.76]], "batl": NaN}, {"timestamp": 1631347028799, "ltp": 1.43, "tv": 11478.18, "trd": [[1.43, 2446.56]], "batb": NaN, "batl": [[0, 1.43, 1880.41]]}, {"timestamp": 1631347045626, "ltp": 1.42, "tv": 11481.59, "trd": [[1.42, 7129.02]], "batb": [[0, 1.42, 140.05]], "batl": NaN}, {"timestamp": 1631347053847, "ltp": 1.42, "tv": 11481.59, "trd": NaN, "batb": [[0, 1.42, 266.81]], "batl": NaN}, {"timestamp": 1631347067580, "ltp": 1.42, "tv": 11481.59, "trd": NaN, "batb": [[0, 1.42, 284.78]], "batl": NaN}, {"timestamp": 1631347113433, "ltp": 1.42, "tv": 11481.59, "trd": NaN, "batb": [[0, 1.42, 287.48]], "batl": NaN}, {"timestamp": 1631347251490, "ltp": 1.42, "tv": 11481.59, "trd": NaN, "batb": [[1, 1.41, 1292.62]], "batl": NaN}, {"timestamp": 1631347360466, "ltp": 1.42, "tv": 11481.59, "trd": NaN, "batb": [[1, 1.41, 1360.95], [2, 1.4, 315.41]], "batl": [[1, 1.44, 1285.36]]}, {"timestamp": 1631347384539, "ltp": 1.42, "tv": 11481.59, "trd": NaN, "batb": [[1, 1.41, 1373.77]], "batl": [[1, 1.44, 1266.89]]}, {"timestamp": 1631347549559, "ltp": 1.42, "tv": 11481.59, "trd": NaN, "batb": NaN, "batl": [[0, 1.43, 1844.21]]}, {"timestamp": 1631347550172, "ltp": 1.42, "tv": 11481.59, "trd": NaN, "batb": NaN, "batl": [[1, 1.44, 1253.33]]}, {"timestamp": 1631347626619, "ltp": 1.42, "tv": 11481.59, "trd": NaN, "batb": NaN, "batl": [[1, 1.44, 1256.85]]}, {"timestamp": 1631347880431, "ltp": 1.42, "tv": 11481.59, "trd": NaN, "batb": [[1, 1.41, 1383.17]], "batl": [[1, 1.44, 1203.9], [2, 1.45, 1251.67]]}, {"timestamp": 1631347902537, "ltp": 1.42, "tv": 11481.59, "trd": NaN, "batb": [[1, 1.41, 1398.74]], "batl": [[0, 1.43, 1800.44]]}, {"timestamp": 1631347903151, "ltp": 1.42, "tv": 11481.59, "trd": NaN, "batb": NaN, "batl": [[1, 1.44, 1200.38]]}, {"timestamp": 1631347904529, "ltp": 1.42, "tv": 11481.59, "trd": NaN, "batb": NaN, "batl": [[1, 1.44, 1181.94]]}, {"timestamp": 1631347950423, "ltp": 1.42, "tv": 11481.59, "trd": NaN, "batb": NaN, "batl": [[2, 1.45, 1258.5]]}, {"timestamp": 1631347988341, "ltp": 1.42, "tv": 11481.59, "trd": NaN, "batb": [[1, 1.41, 1403.17]], "batl": NaN}, {"timestamp": 1631347989247, "ltp": 1.42, "tv": 11481.59, "trd": NaN, "batb": NaN, "batl": [[1, 1.44, 1185.9]]}, {"timestamp": 1631348007794, "ltp": 1.42, "tv": 11481.59, "trd": NaN, "batb": [[0, 1.42, 472.62]], "batl": NaN}, {"timestamp": 1631348069640, "ltp": 1.42, "tv": 11481.59, "trd": NaN, "batb": NaN, "batl": [[2, 1.45, 1174.81]]}, {"timestamp": 1631348070009, "ltp": 1.42, "tv": 11481.59, "trd": NaN, "batb": [[1, 1.41, 1392.92]], "batl": [[1, 1.44, 1236.29]]}, {"timestamp": 1631348080340, "ltp": 1.42, "tv": 11481.59, "trd": NaN, "batb": [[0, 1.42, 500.79]], "batl": [[1, 1.44, 1244.44]]}, {"timestamp": 1631348100359, "ltp": 1.42, "tv": 11481.59, "trd": NaN, "batb": [[1, 1.41, 1411.71]], "batl": [[1, 1.44, 1194.05], [2, 1.45, 1243.98]]}, {"timestamp": 1631348162548, "ltp": 1.42, "tv": 11481.59, "trd": NaN, "batb": [[1, 1.41, 1419.71]], "batl": NaN}, {"timestamp": 1631348163503, "ltp": 1.42, "tv": 11481.59, "trd": NaN, "batb": [[0, 1.42, 505.02]], "batl": NaN}, {"timestamp": 1631348180021, "ltp": 1.42, "tv": 11481.59, "trd": NaN, "batb": [[1, 1.41, 1683.56]], "batl": [[0, 1.43, 1771.54]]}, {"timestamp": 1631348254664, "ltp": 1.42, "tv": 11481.59, "trd": NaN, "batb": [[1, 1.41, 1726.81]], "batl": NaN}, {"timestamp": 1631348324449, "ltp": 1.42, "tv": 11481.59, "trd": NaN, "batb": [[1, 1.41, 1733.3]], "batl": NaN}, {"timestamp": 1631348393706, "ltp": 1.42, "tv": 11481.59, "trd": NaN, "batb": NaN, "batl": [[2, 1.45, 1250.82]]}, {"timestamp": 1631348403803, "ltp": 1.42, "tv": 11481.59, "trd": NaN, "batb": [[0, 1.42, 465.77]], "batl": NaN}, {"timestamp": 1631348573971, "ltp": 1.42, "tv": 11481.59, "trd": NaN, "batb": NaN, "batl": [[2, 1.45, 1242.28]]}, {"timestamp": 1631348590772, "ltp": 1.42, "tv": 11481.59, "trd": NaN, "batb": NaN, "batl": [[2, 1.45, 1337.07]]}, {"timestamp": 1631348639546, "ltp": 1.42, "tv": 11481.59, "trd": NaN, "batb": NaN, "batl": [[0, 1.43, 1756.8]]}, {"timestamp": 1631348754344, "ltp": 1.42, "tv": 11481.59, "trd": NaN, "batb": [[0, 1.42, 552.88], [1, 1.41, 1647.04]], "batl": [[2, 1.45, 1269.6]]}, {"timestamp": 1631348783713, "ltp": 1.42, "tv": 11481.59, "trd": NaN, "batb": [[0, 1.42, 560.69]], "batl": NaN}, {"timestamp": 1631348827552, "ltp": 1.42, "tv": 12602.96, "trd": [[1.42, 8250.39]], "batb": [[0, 1.41, 1647.04], [1, 1.4, 315.41], [2, 1.39, 144.6]], "batl": [[0, 1.42, 1439.32], [1, 1.43, 1756.8], [2, 1.44, 1194.05]]}, {"timestamp": 1631348828664, "ltp": 1.42, "tv": 13294.22, "trd": [[1.42, 8941.65]], "batb": [[0, 1.41, 4975.64]], "batl": [[0, 1.42, 1093.69]]}, {"timestamp": 1631348829557, "ltp": 1.42, "tv": 13294.22, "trd": NaN, "batb": [[0, 1.41, 5060.19]], "batl": NaN}, {"timestamp": 1631348842056, "ltp": 1.42, "tv": 13294.22, "trd": NaN, "batb": NaN, "batl": [[2, 1.44, 1025.21]]}, {"timestamp": 1631348843573, "ltp": 1.42, "tv": 13294.22, "trd": NaN, "batb": NaN, "batl": [[2, 1.44, 1007.86]]}, {"timestamp": 1631348844571, "ltp": 1.42, "tv": 13294.22, "trd": NaN, "batb": NaN, "batl": [[2, 1.44, 984.62]]}, {"timestamp": 1631348845258, "ltp": 1.42, "tv": 13294.22, "trd": NaN, "batb": NaN, "batl": [[2, 1.44, 977.19]]}, {"timestamp": 1631348846673, "ltp": 1.42, "tv": 13294.22, "trd": NaN, "batb": NaN, "batl": [[2, 1.44, 927.71]]}, {"timestamp": 1631348848551, "ltp": 1.42, "tv": 13294.22, "trd": NaN, "batb": [[0, 1.41, 5409.68], [1, 1.4, 505.75]], "batl": NaN}, {"timestamp": 1631348849381, "ltp": 1.42, "tv": 13294.22, "trd": NaN, "batb": NaN, "batl": [[1, 1.43, 1800.02]]}, {"timestamp": 1631348862686, "ltp": 1.42, "tv": 14807.82, "trd": [[1.42, 10455.25]], "batb": NaN, "batl": [[0, 1.42, 336.89]]}, {"timestamp": 1631348862793, "ltp": 1.42, "tv": 15124.09, "trd": [[1.42, 10771.52]], "batb": NaN, "batl": [[0, 1.42, 178.76]]}, {"timestamp": 1631348880505, "ltp": 1.42, "tv": 15340.47, "trd": [[1.42, 10987.9]], "batb": NaN, "batl": [[0, 1.42, 70.57]]}, {"timestamp": 1631348908375, "ltp": 1.42, "tv": 15340.47, "trd": NaN, "batb": [[1, 1.4, 588.47]], "batl": NaN}, {"timestamp": 1631349001591, "ltp": 1.42, "tv": 15340.47, "trd": NaN, "batb": [[1, 1.4, 600.87]], "batl": NaN}, {"timestamp": 1631349022053, "ltp": 1.42, "tv": 15403.2, "trd": [[1.42, 11050.63]], "batb": NaN, "batl": [[0, 1.42, 7.84]]}, {"timestamp": 1631349135656, "ltp": 1.42, "tv": 15403.2, "trd": NaN, "batb": [[0, 1.41, 5395.01]], "batl": NaN}, {"timestamp": 1631349136544, "ltp": 1.42, "tv": 15403.2, "trd": NaN, "batb": NaN, "batl": [[1, 1.43, 1814]]}, {"timestamp": 1631349170316, "ltp": 1.42, "tv": 15418.88, "trd": [[1.42, 11066.3]], "batb": [[0, 1.42, 172.1], [1, 1.41, 5395.01], [2, 1.4, 600.87]], "batl": [[0, 1.43, 1814], [1, 1.44, 927.71], [2, 1.45, 1354.16]]}, {"timestamp": 1631349180635, "ltp": 1.42, "tv": 15418.88, "trd": NaN, "batb": [[1, 1.41, 2066.41], [2, 1.4, 398.12]], "batl": NaN}, {"timestamp": 1631349180743, "ltp": 1.42, "tv": 15418.88, "trd": NaN, "batb": [[2, 1.4, 315.41]], "batl": NaN}, {"timestamp": 1631349182701, "ltp": 1.42, "tv": 15418.88, "trd": NaN, "batb": [[0, 1.42, 197.92], [1, 1.41, 1731.59]], "batl": NaN}, {"timestamp": 1631349183350, "ltp": 1.42, "tv": 15418.88, "trd": NaN, "batb": NaN, "batl": [[1, 1.44, 1173.22]]}, {"timestamp": 1631349205892, "ltp": 1.42, "tv": 15418.88, "trd": NaN, "batb": [[0, 1.42, 152.57]], "batl": NaN}, {"timestamp": 1631349217639, "ltp": 1.43, "tv": 15509.29, "trd": [[1.43, 2536.97]], "batb": NaN, "batl": [[0, 1.43, 1768.8]]}, {"timestamp": 1631349236575, "ltp": 1.43, "tv": 15509.29, "trd": NaN, "batb": NaN, "batl": [[1, 1.44, 1210.05]]}, {"timestamp": 1631349237202, "ltp": 1.43, "tv": 15509.29, "trd": NaN, "batb": [[0, 1.42, 25.81]], "batl": NaN}, {"timestamp": 1631349318531, "ltp": 1.43, "tv": 15509.29, "trd": NaN, "batb": [[0, 1.42, 3.87]], "batl": [[1, 1.44, 1215.57]]}, {"timestamp": 1631349545745, "ltp": 1.42, "tv": 15517.03, "trd": [[1.42, 11074.05]], "batb": [[0, 1.41, 1731.59], [1, 1.4, 315.41], [2, 1.39, 144.6]], "batl": [[0, 1.42, 189.38], [1, 1.43, 1768.8], [2, 1.44, 1215.57]]}, {"timestamp": 1631349556573, "ltp": 1.41, "tv": 15895.78, "trd": [[1.41, 803.31]], "batb": [[0, 1.41, 1669.87]], "batl": [[0, 1.43, 1894.67], [1, 1.44, 1215.57], [2, 1.45, 1354.16]]}, {"timestamp": 1631349571330, "ltp": 1.41, "tv": 15895.78, "trd": NaN, "batb": [[1, 1.4, 507.34]], "batl": NaN}, {"timestamp": 1631349572371, "ltp": 1.41, "tv": 15895.78, "trd": NaN, "batb": [[0, 1.41, 1663.38]], "batl": NaN}, {"timestamp": 1631349573059, "ltp": 1.41, "tv": 15895.78, "trd": NaN, "batb": NaN, "batl": [[0, 1.43, 1905.42]]}, {"timestamp": 1631349585681, "ltp": 1.41, "tv": 15895.78, "trd": NaN, "batb": NaN, "batl": [[0, 1.43, 1779.55]]}, {"timestamp": 1631349635841, "ltp": 1.41, "tv": 15895.78, "trd": NaN, "batb": NaN, "batl": [[0, 1.43, 1905.42]]}, {"timestamp": 1631349639210, "ltp": 1.41, "tv": 15895.78, "trd": NaN, "batb": [[1, 1.4, 534.54]], "batl": NaN}, {"timestamp": 1631349642151, "ltp": 1.41, "tv": 15895.78, "trd": NaN, "batb": NaN, "batl": [[0, 1.43, 1894.67]]}, {"timestamp": 1631349642832, "ltp": 1.41, "tv": 15895.78, "trd": NaN, "batb": NaN, "batl": [[0, 1.43, 1880.68]]}, {"timestamp": 1631349675395, "ltp": 1.41, "tv": 15895.78, "trd": NaN, "batb": NaN, "batl": [[1, 1.44, 1275.36], [2, 1.45, 1269.6]]}, {"timestamp": 1631349705423, "ltp": 1.41, "tv": 15895.78, "trd": NaN, "batb": [[0, 1.41, 1578.83]], "batl": [[1, 1.44, 1215.57]]}, {"timestamp": 1631349731591, "ltp": 1.41, "tv": 15895.78, "trd": NaN, "batb": [[1, 1.4, 538.62]], "batl": NaN}, {"timestamp": 1631349732701, "ltp": 1.41, "tv": 15895.78, "trd": NaN, "batb": [[0, 1.41, 1540.23]], "batl": NaN}, {"timestamp": 1631349804843, "ltp": 1.41, "tv": 15895.78, "trd": NaN, "batb": [[0, 1.41, 1625.63]], "batl": [[1, 1.44, 1275.36]]}, {"timestamp": 1631349811415, "ltp": 1.41, "tv": 15895.78, "trd": NaN, "batb": [[0, 1.41, 1629.32], [1, 1.4, 549.85]], "batl": NaN}, {"timestamp": 1631349812141, "ltp": 1.41, "tv": 15895.78, "trd": NaN, "batb": NaN, "batl": [[1, 1.44, 1279.98]]}, {"timestamp": 1631349836641, "ltp": 1.41, "tv": 15895.78, "trd": NaN, "batb": [[0, 1.42, 17], [1, 1.41, 1629.32], [2, 1.4, 549.85]], "batl": NaN}, {"timestamp": 1631349836851, "ltp": 1.42, "tv": 15929.78, "trd": [[1.42, 11108.05]], "batb": [[0, 1.41, 1629.32], [1, 1.4, 549.85], [2, 1.39, 144.6]], "batl": NaN}, {"timestamp": 1631349866530, "ltp": 1.42, "tv": 15929.78, "trd": NaN, "batb": [[1, 1.4, 552.79]], "batl": NaN}, {"timestamp": 1631349882156, "ltp": 1.43, "tv": 16089.32, "trd": [[1.43, 2696.51]], "batb": NaN, "batl": [[0, 1.43, 1800.92]]}, {"timestamp": 1631349987734, "ltp": 1.43, "tv": 16089.32, "trd": NaN, "batb": [[0, 1.41, 1666.07]], "batl": NaN}, {"timestamp": 1631350030514, "ltp": 1.43, "tv": 16089.32, "trd": NaN, "batb": [[0, 1.41, 1672.13]], "batl": NaN}, {"timestamp": 1631350055395, "ltp": 1.43, "tv": 16089.32, "trd": NaN, "batb": [[0, 1.42, 121.27], [1, 1.41, 1586.73], [2, 1.4, 552.79]], "batl": [[1, 1.44, 1220.2]]}, {"timestamp": 1631350057119, "ltp": 1.43, "tv": 16089.32, "trd": NaN, "batb": [[1, 1.41, 1549.98]], "batl": NaN}, {"timestamp": 1631350079566, "ltp": 1.43, "tv": 16089.32, "trd": NaN, "batb": [[2, 1.4, 538.62]], "batl": NaN}, {"timestamp": 1631350080564, "ltp": 1.43, "tv": 16089.32, "trd": NaN, "batb": [[2, 1.4, 346.7]], "batl": NaN}, {"timestamp": 1631350081669, "ltp": 1.43, "tv": 16089.32, "trd": NaN, "batb": [[2, 1.4, 315.41]], "batl": NaN}, {"timestamp": 1631350082665, "ltp": 1.43, "tv": 16089.32, "trd": NaN, "batb": [[0, 1.42, 139.47]], "batl": NaN}, {"timestamp": 1631350085452, "ltp": 1.43, "tv": 16089.32, "trd": NaN, "batb": [[0, 1.42, 84.81]], "batl": [[2, 1.45, 1355.86]]}, {"timestamp": 1631350109655, "ltp": 1.42, "tv": 16258.94, "trd": [[1.42, 11277.67]], "batb": [[0, 1.41, 1549.98], [1, 1.4, 315.41], [2, 1.39, 144.6]], "batl": [[0, 1.42, 25.13], [1, 1.43, 1800.92], [2, 1.44, 1220.2]]}, {"timestamp": 1631350110076, "ltp": 1.42, "tv": 16258.94, "trd": NaN, "batb": [[0, 1.41, 4023.93]], "batl": [[1, 1.43, 1675.05]]}, {"timestamp": 1631350111687, "ltp": 1.42, "tv": 16258.94, "trd": NaN, "batb": [[0, 1.41, 1586.73]], "batl": NaN}, {"timestamp": 1631350113483, "ltp": 1.42, "tv": 16258.94, "trd": NaN, "batb": [[0, 1.41, 1670.43]], "batl": NaN}, {"timestamp": 1631350118679, "ltp": 1.42, "tv": 16258.94, "trd": NaN, "batb": NaN, "batl": [[0, 1.43, 1675.05], [1, 1.44, 1220.2], [2, 1.45, 1318.29]]}, {"timestamp": 1631350118886, "ltp": 1.42, "tv": 16258.94, "trd": NaN, "batb": NaN, "batl": [[0, 1.42, 25.13], [1, 1.43, 1780.49], [2, 1.44, 1220.2]]}, {"timestamp": 1631350140743, "ltp": 1.41, "tv": 16346.89, "trd": [[1.41, 891.26]], "batb": [[0, 1.41, 1626.45]], "batl": NaN}, {"timestamp": 1631350144351, "ltp": 1.41, "tv": 16346.89, "trd": NaN, "batb": NaN, "batl": [[2, 1.44, 937.85]]}, {"timestamp": 1631350145352, "ltp": 1.41, "tv": 16346.89, "trd": NaN, "batb": NaN, "batl": [[2, 1.44, 927.71]]}, {"timestamp": 1631350146428, "ltp": 1.41, "tv": 16346.89, "trd": NaN, "batb": [[1, 1.4, 517.57]], "batl": [[1, 1.43, 1790.57]]}, {"timestamp": 1631350157680, "ltp": 1.41, "tv": 16390.58, "trd": [[1.41, 934.95]], "batb": [[0, 1.41, 1604.61]], "batl": NaN}, {"timestamp": 1631350203674, "ltp": 1.42, "tv": 16410.58, "trd": [[1.42, 11297.67]], "batb": NaN, "batl": [[0, 1.42, 15.13]]}, {"timestamp": 1631350205672, "ltp": 1.42, "tv": 16410.58, "trd": NaN, "batb": [[1, 1.4, 551.3]], "batl": NaN}, {"timestamp": 1631350227393, "ltp": 1.42, "tv": 16440.85, "trd": [[1.42, 11327.93]], "batb": [[0, 1.42, 38.05], [1, 1.41, 1604.61], [2, 1.4, 551.3]], "batl": [[0, 1.43, 1790.57], [1, 1.44, 927.71], [2, 1.45, 1399.42]]}, {"timestamp": 1631350228071, "ltp": 1.42, "tv": 16440.85, "trd": NaN, "batb": [[1, 1.41, 1567.86]], "batl": NaN}, {"timestamp": 1631350253341, "ltp": 1.42, "tv": 16440.85, "trd": NaN, "batb": [[2, 1.4, 315.41]], "batl": NaN}, {"timestamp": 1631350254343, "ltp": 1.42, "tv": 16440.85, "trd": NaN, "batb": [[0, 1.42, 43.75], [1, 1.41, 1572.27]], "batl": NaN}, {"timestamp": 1631350255327, "ltp": 1.42, "tv": 16440.85, "trd": NaN, "batb": [[1, 1.41, 1550.83]], "batl": [[1, 1.44, 1170.42]]}, {"timestamp": 1631350257419, "ltp": 1.42, "tv": 16440.85, "trd": NaN, "batb": [[0, 1.42, 78.77]], "batl": NaN}, {"timestamp": 1631350258460, "ltp": 1.42, "tv": 16440.85, "trd": NaN, "batb": [[0, 1.42, 43.75]], "batl": NaN}, {"timestamp": 1631350311452, "ltp": 1.42, "tv": 16440.85, "trd": NaN, "batb": [[1, 1.41, 1556.19]], "batl": [[1, 1.44, 1206.83]]}, {"timestamp": 1631350379233, "ltp": 1.42, "tv": 16440.85, "trd": NaN, "batb": NaN, "batl": [[1, 1.44, 1212.29]]}, {"timestamp": 1631350639304, "ltp": 1.42, "tv": 16440.85, "trd": NaN, "batb": [[0, 1.42, 56.06]], "batl": NaN}, {"timestamp": 1631350665329, "ltp": 1.42, "tv": 16440.85, "trd": NaN, "batb": [[1, 1.41, 1582.78]], "batl": NaN}, {"timestamp": 1631350681149, "ltp": 1.42, "tv": 16440.85, "trd": NaN, "batb": [[0, 1.42, 58.76], [1, 1.41, 1588.88]], "batl": NaN}, {"timestamp": 1631350931023, "ltp": 1.42, "tv": 16460.85, "trd": [[1.42, 11347.94]], "batb": [[0, 1.42, 48.76]], "batl": NaN}, {"timestamp": 1631351205306, "ltp": 1.42, "tv": 16460.85, "trd": NaN, "batb": [[0, 1.42, 233.9]], "batl": NaN}, {"timestamp": 1631351246582, "ltp": 1.42, "tv": 16460.85, "trd": NaN, "batb": [[0, 1.42, 260.58]], "batl": NaN}, {"timestamp": 1631351303507, "ltp": 1.42, "tv": 16460.85, "trd": NaN, "batb": [[0, 1.42, 264.58], [1, 1.41, 1594.31]], "batl": NaN}, {"timestamp": 1631351365677, "ltp": 1.42, "tv": 16460.85, "trd": NaN, "batb": [[0, 1.42, 79.44]], "batl": NaN}, {"timestamp": 1631351427015, "ltp": 1.42, "tv": 16460.85, "trd": NaN, "batb": [[0, 1.42, 75.44]], "batl": NaN}, {"timestamp": 1631351428602, "ltp": 1.42, "tv": 16460.85, "trd": NaN, "batb": [[0, 1.42, 52.27]], "batl": [[1, 1.44, 1220.2]]}, {"timestamp": 1631351431711, "ltp": 1.42, "tv": 16460.85, "trd": NaN, "batb": [[0, 1.42, 584.19]], "batl": NaN}, {"timestamp": 1631351465682, "ltp": 1.42, "tv": 16460.85, "trd": NaN, "batb": [[0, 1.42, 595.94]], "batl": NaN}, {"timestamp": 1631351494696, "ltp": 1.42, "tv": 16460.85, "trd": NaN, "batb": [[0, 1.42, 673.42]], "batl": NaN}, {"timestamp": 1631351495237, "ltp": 1.42, "tv": 16460.85, "trd": NaN, "batb": NaN, "batl": [[0, 1.43, 1685.13]]}, {"timestamp": 1631351550848, "ltp": 1.42, "tv": 16660.86, "trd": [[1.42, 11547.94]], "batb": [[0, 1.42, 573.41]], "batl": NaN}, {"timestamp": 1631351582672, "ltp": 1.42, "tv": 16660.86, "trd": NaN, "batb": [[0, 1.42, 581.95], [1, 1.41, 1603.6]], "batl": [[0, 1.43, 1689.56]]}, {"timestamp": 1631351676062, "ltp": 1.43, "tv": 16682.13, "trd": [[1.43, 2717.78]], "batb": NaN, "batl": [[0, 1.43, 1678.93]]}, {"timestamp": 1631351857458, "ltp": 1.43, "tv": 16682.13, "trd": NaN, "batb": [[0, 1.42, 708.71]], "batl": NaN}, {"timestamp": 1631351897720, "ltp": 1.43, "tv": 16682.13, "trd": NaN, "batb": [[0, 1.42, 730.42]], "batl": NaN}, {"timestamp": 1631351971715, "ltp": 1.43, "tv": 16682.13, "trd": NaN, "batb": [[1, 1.41, 1607.32]], "batl": NaN}, {"timestamp": 1631351972397, "ltp": 1.43, "tv": 16682.13, "trd": NaN, "batb": [[0, 1.42, 733.67]], "batl": NaN}, {"timestamp": 1631352042194, "ltp": 1.43, "tv": 16682.13, "trd": NaN, "batb": [[0, 1.42, 752.67]], "batl": NaN}, {"timestamp": 1631352067214, "ltp": 1.43, "tv": 16682.13, "trd": NaN, "batb": [[0, 1.42, 756.01]], "batl": NaN}, {"timestamp": 1631352319397, "ltp": 1.43, "tv": 16682.13, "trd": NaN, "batb": NaN, "batl": [[0, 1.43, 1674.5]]}, {"timestamp": 1631352320568, "ltp": 1.43, "tv": 16682.13, "trd": NaN, "batb": NaN, "batl": [[0, 1.43, 1621.2]]}, {"timestamp": 1631352321202, "ltp": 1.43, "tv": 16682.13, "trd": NaN, "batb": NaN, "batl": [[0, 1.43, 1549.14]]}, {"timestamp": 1631352322370, "ltp": 1.43, "tv": 16682.13, "trd": NaN, "batb": NaN, "batl": [[1, 1.44, 1206.83]]}, {"timestamp": 1631352323588, "ltp": 1.43, "tv": 16682.13, "trd": NaN, "batb": NaN, "batl": [[1, 1.44, 1187.64]]}, {"timestamp": 1631352388931, "ltp": 1.43, "tv": 16682.13, "trd": NaN, "batb": NaN, "batl": [[1, 1.44, 1202.33]]}, {"timestamp": 1631352395125, "ltp": 1.43, "tv": 17142.12, "trd": [[1.43, 3177.77]], "batb": NaN, "batl": [[0, 1.43, 1319.15]]}, {"timestamp": 1631352451006, "ltp": 1.43, "tv": 17142.12, "trd": NaN, "batb": NaN, "batl": [[1, 1.44, 1220.2]]}, {"timestamp": 1631352501642, "ltp": 1.42, "tv": 17166.3, "trd": [[1.42, 11572.12]], "batb": [[0, 1.42, 743.93]], "batl": NaN}, {"timestamp": 1631352947817, "ltp": 1.43, "tv": 17203.09, "trd": [[1.43, 3214.57]], "batb": NaN, "batl": [[0, 1.43, 1300.75]]}, {"timestamp": 1631353360981, "ltp": 1.42, "tv": 17303.1, "trd": [[1.42, 11672.12]], "batb": [[0, 1.42, 693.92]], "batl": NaN}, {"timestamp": 1631353604676, "ltp": 1.42, "tv": 17303.1, "trd": NaN, "batb": [[1, 1.41, 1659.41]], "batl": [[2, 1.45, 1355.01]]}, {"timestamp": 1631353605265, "ltp": 1.42, "tv": 17303.1, "trd": NaN, "batb": [[1, 1.41, 1707.24]], "batl": NaN}, {"timestamp": 1631353606562, "ltp": 1.42, "tv": 17303.1, "trd": NaN, "batb": [[1, 1.41, 1623.54]], "batl": NaN}, {"timestamp": 1631353614071, "ltp": 1.42, "tv": 17303.1, "trd": NaN, "batb": NaN, "batl": [[2, 1.45, 1391.73]]}, {"timestamp": 1631353625631, "ltp": 1.42, "tv": 17303.1, "trd": NaN, "batb": [[1, 1.41, 1609.88]], "batl": NaN}, {"timestamp": 1631353812718, "ltp": 1.42, "tv": 17303.1, "trd": NaN, "batb": NaN, "batl": [[1, 1.44, 1296.21], [2, 1.45, 1269.6]]}, {"timestamp": 1631353908687, "ltp": 1.43, "tv": 17396.46, "trd": [[1.43, 3307.93]], "batb": NaN, "batl": [[0, 1.43, 1254.07]]}, {"timestamp": 1631354023124, "ltp": 1.42, "tv": 17400.46, "trd": [[1.42, 11676.12]], "batb": [[0, 1.42, 691.92]], "batl": NaN}, {"timestamp": 1631354276632, "ltp": 1.43, "tv": 17547.65, "trd": [[1.43, 3455.12]], "batb": NaN, "batl": [[0, 1.43, 1180.48]]}, {"timestamp": 1631354379028, "ltp": 1.43, "tv": 17547.65, "trd": NaN, "batb": [[0, 1.42, 565.16]], "batl": NaN}, {"timestamp": 1631354392677, "ltp": 1.43, "tv": 17554.5, "trd": [[1.43, 3461.96]], "batb": NaN, "batl": [[0, 1.43, 1177.05]]}, {"timestamp": 1631354398602, "ltp": 1.43, "tv": 17554.5, "trd": NaN, "batb": [[1, 1.41, 1596.87]], "batl": NaN}, {"timestamp": 1631354399609, "ltp": 1.43, "tv": 17554.5, "trd": NaN, "batb": [[0, 1.42, 558.57]], "batl": NaN}, {"timestamp": 1631354400584, "ltp": 1.43, "tv": 17554.5, "trd": NaN, "batb": [[0, 1.42, 536.86]], "batl": [[0, 1.43, 1221.2]]}, {"timestamp": 1631354458563, "ltp": 1.43, "tv": 17625.48, "trd": [[1.43, 3532.95]], "batb": NaN, "batl": [[0, 1.43, 1185.7]]}, {"timestamp": 1631354459255, "ltp": 1.43, "tv": 17625.48, "trd": NaN, "batb": [[0, 1.42, 560.99]], "batl": NaN}, {"timestamp": 1631354551889, "ltp": 1.43, "tv": 17664.77, "trd": [[1.43, 3572.24]], "batb": NaN, "batl": [[0, 1.43, 1166.06]]}, {"timestamp": 1631354646586, "ltp": 1.43, "tv": 17709.18, "trd": [[1.43, 3616.65]], "batb": NaN, "batl": [[0, 1.43, 1143.85]]}, {"timestamp": 1631354655721, "ltp": 1.42, "tv": 18174.01, "trd": [[1.42, 12140.96]], "batb": [[0, 1.42, 328.57]], "batl": NaN}, {"timestamp": 1631354655930, "ltp": 1.42, "tv": 18174.01, "trd": NaN, "batb": NaN, "batl": [[0, 1.43, 1269.72]]}, {"timestamp": 1631354664529, "ltp": 1.42, "tv": 18174.01, "trd": NaN, "batb": [[0, 1.42, 320.03]], "batl": NaN}, {"timestamp": 1631354665500, "ltp": 1.42, "tv": 18174.01, "trd": NaN, "batb": [[0, 1.42, 291.84]], "batl": NaN}, {"timestamp": 1631354738145, "ltp": 1.43, "tv": 18188.53, "trd": [[1.43, 3631.17]], "batb": NaN, "batl": [[0, 1.43, 1262.46]]}, {"timestamp": 1631354744065, "ltp": 1.43, "tv": 18273.94, "trd": [[1.43, 3716.57]], "batb": NaN, "batl": [[0, 1.43, 1219.76]]}, {"timestamp": 1631354901650, "ltp": 1.43, "tv": 18361.05, "trd": [[1.43, 3803.69]], "batb": NaN, "batl": [[0, 1.43, 1176.21]]}, {"timestamp": 1631354906533, "ltp": 1.43, "tv": 18448.16, "trd": [[1.43, 3890.8]], "batb": NaN, "batl": [[0, 1.43, 1132.65]]}, {"timestamp": 1631354918885, "ltp": 1.43, "tv": 18448.16, "trd": NaN, "batb": [[0, 1.42, 384.41]], "batl": NaN}, {"timestamp": 1631354924897, "ltp": 1.43, "tv": 18533.57, "trd": [[1.43, 3976.2]], "batb": NaN, "batl": [[0, 1.43, 1089.95]]}, {"timestamp": 1631354939503, "ltp": 1.43, "tv": 18620.68, "trd": [[1.43, 4063.31]], "batb": NaN, "batl": [[0, 1.43, 1046.39]]}, {"timestamp": 1631354952867, "ltp": 1.43, "tv": 18707.79, "trd": [[1.43, 4150.43]], "batb": NaN, "batl": [[0, 1.43, 1002.83]]}, {"timestamp": 1631354956574, "ltp": 1.43, "tv": 18707.79, "trd": NaN, "batb": [[0, 1.42, 392.79]], "batl": NaN}, {"timestamp": 1631354974836, "ltp": 1.43, "tv": 18794.9, "trd": [[1.43, 4237.54]], "batb": NaN, "batl": [[0, 1.43, 959.28]]}, {"timestamp": 1631354995561, "ltp": 1.43, "tv": 18794.9, "trd": NaN, "batb": [[0, 1.42, 347.04]], "batl": NaN}, {"timestamp": 1631355092700, "ltp": 1.43, "tv": 18880.31, "trd": [[1.43, 4322.94]], "batb": NaN, "batl": [[0, 1.43, 916.58]]}, {"timestamp": 1631355098746, "ltp": 1.42, "tv": 19051.12, "trd": [[1.42, 12311.77]], "batb": [[0, 1.42, 261.63]], "batl": NaN}, {"timestamp": 1631355103534, "ltp": 1.42, "tv": 19051.12, "trd": NaN, "batb": [[1, 1.41, 1637.01]], "batl": [[1, 1.44, 1220.2], [2, 1.45, 1354.16]]}, {"timestamp": 1631355108353, "ltp": 1.42, "tv": 19051.12, "trd": NaN, "batb": [[1, 1.41, 1647.49]], "batl": NaN}, {"timestamp": 1631355109254, "ltp": 1.42, "tv": 19051.12, "trd": NaN, "batb": [[0, 1.42, 253.26]], "batl": NaN}, {"timestamp": 1631355168333, "ltp": 1.42, "tv": 19051.12, "trd": NaN, "batb": [[0, 1.42, 380.02]], "batl": NaN}, {"timestamp": 1631355199593, "ltp": 1.42, "tv": 19051.12, "trd": NaN, "batb": [[0, 1.42, 387.73]], "batl": [[1, 1.44, 1202.33]]}, {"timestamp": 1631355200611, "ltp": 1.42, "tv": 19051.12, "trd": NaN, "batb": NaN, "batl": [[1, 1.44, 1187.64]]}, {"timestamp": 1631355205903, "ltp": 1.43, "tv": 19138.23, "trd": [[1.43, 4410.06]], "batb": NaN, "batl": [[0, 1.43, 873.02]]}, {"timestamp": 1631355243575, "ltp": 1.43, "tv": 19414.94, "trd": [[1.43, 4686.77]], "batb": NaN, "batl": [[0, 1.43, 734.66]]}, {"timestamp": 1631355249555, "ltp": 1.43, "tv": 19484.97, "trd": [[1.43, 4756.8]], "batb": NaN, "batl": [[0, 1.43, 699.65]]}, {"timestamp": 1631355282610, "ltp": 1.43, "tv": 19484.97, "trd": NaN, "batb": [[0, 1.42, 487.73]], "batl": NaN}, {"timestamp": 1631355282827, "ltp": 1.43, "tv": 19484.97, "trd": NaN, "batb": NaN, "batl": [[0, 1.43, 573.78]]}, {"timestamp": 1631355297233, "ltp": 1.43, "tv": 19484.97, "trd": NaN, "batb": [[0, 1.42, 503.89]], "batl": NaN}, {"timestamp": 1631355298431, "ltp": 1.43, "tv": 19484.97, "trd": NaN, "batb": NaN, "batl": [[1, 1.44, 1170.42]]}, {"timestamp": 1631355345934, "ltp": 1.42, "tv": 19664.98, "trd": [[1.42, 12491.78]], "batb": [[0, 1.42, 413.88]], "batl": NaN}, {"timestamp": 1631355663165, "ltp": 1.43, "tv": 19670.11, "trd": [[1.43, 4761.92]], "batb": NaN, "batl": [[0, 1.43, 571.22]]}, {"timestamp": 1631355859991, "ltp": 1.43, "tv": 19755.51, "trd": [[1.43, 4847.33]], "batb": NaN, "batl": [[0, 1.43, 528.52]]}, {"timestamp": 1631355868899, "ltp": 1.43, "tv": 19755.51, "trd": NaN, "batb": [[0, 1.42, 1209.2]], "batl": [[0, 1.43, 532.99]]}, {"timestamp": 1631355906485, "ltp": 1.43, "tv": 19755.51, "trd": NaN, "batb": [[0, 1.42, 1317.42]], "batl": NaN}, {"timestamp": 1631355939669, "ltp": 1.43, "tv": 19755.51, "trd": NaN, "batb": [[0, 1.42, 1333.65]], "batl": NaN}, {"timestamp": 1631355954225, "ltp": 1.43, "tv": 19755.51, "trd": NaN, "batb": [[0, 1.42, 1409.66], [1, 1.41, 1521.09]], "batl": NaN}, {"timestamp": 1631355973261, "ltp": 1.43, "tv": 19755.51, "trd": NaN, "batb": [[0, 1.42, 1423.5]], "batl": NaN}, {"timestamp": 1631355974380, "ltp": 1.43, "tv": 19755.51, "trd": NaN, "batb": [[1, 1.41, 1393.44]], "batl": NaN}, {"timestamp": 1631356007696, "ltp": 1.43, "tv": 19755.51, "trd": NaN, "batb": [[0, 1.42, 1444.59]], "batl": NaN}, {"timestamp": 1631356041538, "ltp": 1.43, "tv": 19755.51, "trd": NaN, "batb": [[0, 1.42, 1450.6]], "batl": NaN}, {"timestamp": 1631356121673, "ltp": 1.43, "tv": 20395.51, "trd": [[1.43, 5487.33]], "batb": [[0, 1.42, 1415.13]], "batl": [[0, 1.43, 212.99]]}, {"timestamp": 1631356137390, "ltp": 1.43, "tv": 20395.51, "trd": NaN, "batb": NaN, "batl": [[0, 1.43, 208.51]]}, {"timestamp": 1631356138397, "ltp": 1.43, "tv": 20395.51, "trd": NaN, "batb": NaN, "batl": [[0, 1.43, 196.32]]}, {"timestamp": 1631356169171, "ltp": 1.43, "tv": 20395.51, "trd": NaN, "batb": NaN, "batl": [[1, 1.44, 1157.39]]}, {"timestamp": 1631356215852, "ltp": 1.43, "tv": 20482.62, "trd": [[1.43, 5574.44]], "batb": NaN, "batl": [[0, 1.43, 152.76]]}, {"timestamp": 1631356320424, "ltp": 1.43, "tv": 20633.51, "trd": [[1.43, 5725.33]], "batb": NaN, "batl": [[0, 1.43, 1.87]]}, {"timestamp": 1631356326354, "ltp": 1.43, "tv": 20633.51, "trd": NaN, "batb": [[0, 1.43, 125.87], [1, 1.42, 1415.13], [2, 1.41, 1393.44]], "batl": [[0, 1.44, 1157.39], [1, 1.45, 1354.16], [2, 1.46, 744.63]]}, {"timestamp": 1631356327650, "ltp": 1.43, "tv": 20633.51, "trd": NaN, "batb": NaN, "batl": [[0, 1.44, 1101.59], [1, 1.45, 1605.44]]}, {"timestamp": 1631356339008, "ltp": 1.43, "tv": 20633.51, "trd": NaN, "batb": [[1, 1.42, 1403.78]], "batl": NaN}, {"timestamp": 1631356348519, "ltp": 1.44, "tv": 21657.33, "trd": [[1.44, 2175.49]], "batb": NaN, "batl": [[0, 1.44, 77.78]]}, {"timestamp": 1631356361439, "ltp": 1.44, "tv": 21657.33, "trd": NaN, "batb": [[2, 1.41, 1387.38]], "batl": NaN}, {"timestamp": 1631356362597, "ltp": 1.44, "tv": 21657.33, "trd": NaN, "batb": [[2, 1.41, 1367.39]], "batl": NaN}, {"timestamp": 1631356363664, "ltp": 1.44, "tv": 21657.33, "trd": NaN, "batb": [[2, 1.41, 1312.32]], "batl": NaN}, {"timestamp": 1631356364645, "ltp": 1.44, "tv": 21657.33, "trd": NaN, "batb": [[2, 1.41, 1299.89]], "batl": NaN}, {"timestamp": 1631356365660, "ltp": 1.44, "tv": 21657.33, "trd": NaN, "batb": [[2, 1.41, 1280.96]], "batl": NaN}, {"timestamp": 1631356366679, "ltp": 1.44, "tv": 21657.33, "trd": NaN, "batb": [[2, 1.41, 1138.94]], "batl": NaN}, {"timestamp": 1631356367589, "ltp": 1.44, "tv": 21657.33, "trd": NaN, "batb": [[2, 1.41, 1122.59]], "batl": NaN}, {"timestamp": 1631356368076, "ltp": 1.44, "tv": 21657.33, "trd": NaN, "batb": [[2, 1.41, 1117.24]], "batl": NaN}, {"timestamp": 1631356369302, "ltp": 1.44, "tv": 21657.33, "trd": NaN, "batb": [[2, 1.41, 1113.55]], "batl": NaN}, {"timestamp": 1631356370272, "ltp": 1.44, "tv": 21657.33, "trd": NaN, "batb": [[2, 1.41, 1103.48]], "batl": NaN}, {"timestamp": 1631356371280, "ltp": 1.44, "tv": 21657.33, "trd": NaN, "batb": [[0, 1.43, 144.75]], "batl": [[0, 1.44, 11.67]]}, {"timestamp": 1631356374494, "ltp": 1.44, "tv": 21657.33, "trd": NaN, "batb": [[0, 1.43, 344.75]], "batl": NaN}, {"timestamp": 1631356381570, "ltp": 1.44, "tv": 21657.33, "trd": NaN, "batb": [[1, 1.42, 1303.78]], "batl": NaN}, {"timestamp": 1631356405093, "ltp": 1.44, "tv": 21657.33, "trd": NaN, "batb": [[0, 1.43, 1198.79]], "batl": NaN}, {"timestamp": 1631356407566, "ltp": 1.44, "tv": 21657.33, "trd": NaN, "batb": [[1, 1.42, 2157.82]], "batl": NaN}, {"timestamp": 1631356410680, "ltp": 1.44, "tv": 21657.33, "trd": NaN, "batb": [[2, 1.41, 1957.52]], "batl": NaN}, {"timestamp": 1631356414671, "ltp": 1.44, "tv": 21657.33, "trd": NaN, "batb": [[1, 1.42, 2139.98]], "batl": NaN}, {"timestamp": 1631356415471, "ltp": 1.44, "tv": 21657.33, "trd": NaN, "batb": [[0, 1.43, 1355.26]], "batl": [[1, 1.45, 1609.69]]}, {"timestamp": 1631356429535, "ltp": 1.44, "tv": 21657.33, "trd": NaN, "batb": [[0, 1.43, 501.22], [1, 1.42, 1285.94], [2, 1.41, 1103.48]], "batl": NaN}, {"timestamp": 1631356431923, "ltp": 1.44, "tv": 21657.33, "trd": NaN, "batb": [[0, 1.43, 2209.31]], "batl": NaN}, {"timestamp": 1631356435427, "ltp": 1.44, "tv": 21657.33, "trd": NaN, "batb": [[1, 1.42, 2994.03]], "batl": NaN}, {"timestamp": 1631356441735, "ltp": 1.44, "tv": 21657.33, "trd": NaN, "batb": [[2, 1.41, 2811.57]], "batl": NaN}, {"timestamp": 1631356452375, "ltp": 1.44, "tv": 21657.33, "trd": NaN, "batb": [[1, 1.42, 3065.8]], "batl": NaN}, {"timestamp": 1631356487907, "ltp": 1.44, "tv": 21680.66, "trd": [[1.44, 2198.83]], "batb": [[0, 1.44, 978.28], [1, 1.43, 2209.31], [2, 1.42, 3065.8]], "batl": [[0, 1.45, 1609.69], [1, 1.46, 744.63], [2, 1.5, 25]]}, {"timestamp": 1631356523617, "ltp": 1.44, "tv": 21680.66, "trd": NaN, "batb": [[2, 1.42, 3042.7]], "batl": NaN}, {"timestamp": 1631356524656, "ltp": 1.44, "tv": 21680.66, "trd": NaN, "batb": [[2, 1.42, 2954.77]], "batl": NaN}, {"timestamp": 1631356525587, "ltp": 1.44, "tv": 21680.66, "trd": NaN, "batb": [[2, 1.42, 2830.32]], "batl": NaN}, {"timestamp": 1631356526655, "ltp": 1.44, "tv": 21680.66, "trd": NaN, "batb": [[2, 1.42, 2773.31]], "batl": NaN}, {"timestamp": 1631356527618, "ltp": 1.44, "tv": 21680.66, "trd": NaN, "batb": [[1, 1.43, 2217.25]], "batl": [[1, 1.46, 923.42]]}, {"timestamp": 1631356541529, "ltp": 1.44, "tv": 21680.66, "trd": NaN, "batb": [[2, 1.42, 1978]], "batl": NaN}, {"timestamp": 1631356563095, "ltp": 1.44, "tv": 21680.66, "trd": NaN, "batb": NaN, "batl": [[1, 1.46, 950.24]]}, {"timestamp": 1631356598664, "ltp": 1.44, "tv": 21680.66, "trd": NaN, "batb": NaN, "batl": [[1, 1.46, 954.26]]}, {"timestamp": 1631356606986, "ltp": 1.44, "tv": 21709.39, "trd": [[1.44, 2227.55]], "batb": [[0, 1.44, 963.92]], "batl": NaN}, {"timestamp": 1631356630717, "ltp": 1.44, "tv": 21709.39, "trd": NaN, "batb": [[1, 1.43, 2223.25]], "batl": [[0, 1.45, 1605.44]]}, {"timestamp": 1631356730332, "ltp": 1.44, "tv": 21709.39, "trd": NaN, "batb": [[0, 1.43, 2223.25], [1, 1.42, 1978], [2, 1.41, 2811.57]], "batl": NaN}, {"timestamp": 1631356733107, "ltp": 1.44, "tv": 21709.39, "trd": NaN, "batb": [[0, 1.44, 52.65], [1, 1.43, 2223.25], [2, 1.42, 1978]], "batl": NaN}, {"timestamp": 1631356791023, "ltp": 1.43, "tv": 21814.72, "trd": [[1.43, 5725.39], [1.44, 2332.83]], "batb": [[0, 1.43, 2223.22], [1, 1.42, 1978], [2, 1.41, 2811.57]], "batl": NaN}, {"timestamp": 1631356820552, "ltp": 1.43, "tv": 21814.72, "trd": NaN, "batb": NaN, "batl": [[0, 1.44, 500], [1, 1.45, 1605.44], [2, 1.46, 954.26]]}, {"timestamp": 1631356821349, "ltp": 1.43, "tv": 21814.72, "trd": NaN, "batb": [[1, 1.42, 2270.49]], "batl": NaN}, {"timestamp": 1631356822477, "ltp": 1.43, "tv": 21814.72, "trd": NaN, "batb": [[0, 1.43, 2209.28]], "batl": NaN}, {"timestamp": 1631356823363, "ltp": 1.43, "tv": 21814.72, "trd": NaN, "batb": NaN, "batl": [[1, 1.45, 1620.65]]}, {"timestamp": 1631356867308, "ltp": 1.43, "tv": 21814.72, "trd": NaN, "batb": NaN, "batl": [[2, 1.46, 950.24]]}, {"timestamp": 1631356868430, "ltp": 1.43, "tv": 21814.72, "trd": NaN, "batb": NaN, "batl": [[2, 1.46, 744.63]]}, {"timestamp": 1631356869514, "ltp": 1.43, "tv": 21814.72, "trd": NaN, "batb": NaN, "batl": [[0, 1.44, 575], [1, 1.45, 1626.78]]}, {"timestamp": 1631356915528, "ltp": 1.43, "tv": 21814.72, "trd": NaN, "batb": NaN, "batl": [[0, 1.44, 586.25], [1, 1.45, 1639.45]]}, {"timestamp": 1631356957405, "ltp": 1.43, "tv": 21814.72, "trd": NaN, "batb": NaN, "batl": [[1, 1.45, 1644.78]]}, {"timestamp": 1631357024664, "ltp": 1.43, "tv": 21814.72, "trd": NaN, "batb": NaN, "batl": [[1, 1.45, 1636.24]]}, {"timestamp": 1631357024932, "ltp": 1.43, "tv": 21814.72, "trd": NaN, "batb": [[1, 1.42, 2279.88]], "batl": NaN}, {"timestamp": 1631357186717, "ltp": 1.44, "tv": 21921.84, "trd": [[1.44, 2439.95]], "batb": NaN, "batl": [[0, 1.44, 532.69]]}, {"timestamp": 1631357295685, "ltp": 1.44, "tv": 22381.84, "trd": [[1.44, 2899.95]], "batb": NaN, "batl": [[0, 1.44, 302.69]]}, {"timestamp": 1631357335657, "ltp": 1.44, "tv": 22381.84, "trd": NaN, "batb": NaN, "batl": [[0, 1.44, 261.85]]}, {"timestamp": 1631357369498, "ltp": 1.44, "tv": 22381.84, "trd": NaN, "batb": [[0, 1.43, 2380.09]], "batl": NaN}, {"timestamp": 1631357401138, "ltp": 1.44, "tv": 22381.84, "trd": NaN, "batb": NaN, "batl": [[0, 1.44, 1115.89]]}, {"timestamp": 1631357406122, "ltp": 1.44, "tv": 22381.84, "trd": NaN, "batb": NaN, "batl": [[0, 1.44, 1237.87]]}, {"timestamp": 1631357436501, "ltp": 1.44, "tv": 22381.84, "trd": NaN, "batb": [[0, 1.43, 2365.37]], "batl": [[0, 1.44, 1256.16]]}, {"timestamp": 1631357471276, "ltp": 1.44, "tv": 22381.84, "trd": NaN, "batb": NaN, "batl": [[0, 1.44, 1258.91]]}, {"timestamp": 1631357513184, "ltp": 1.43, "tv": 27247.22, "trd": [[1.43, 10590.76]], "batb": [[0, 1.42, 2368.29], [1, 1.41, 2811.57], [2, 1.4, 2023.5]], "batl": NaN}, {"timestamp": 1631357533707, "ltp": 1.43, "tv": 27247.22, "trd": NaN, "batb": [[1, 1.41, 3104.06]], "batl": NaN}, {"timestamp": 1631357587343, "ltp": 1.43, "tv": 27247.22, "trd": NaN, "batb": [[0, 1.42, 2338.43]], "batl": NaN}, {"timestamp": 1631357594637, "ltp": 1.44, "tv": 27289.92, "trd": [[1.44, 2942.65]], "batb": NaN, "batl": [[0, 1.44, 1237.56]]}, {"timestamp": 1631357650404, "ltp": 1.44, "tv": 27289.92, "trd": NaN, "batb": NaN, "batl": [[0, 1.44, 1244.57]]}, {"timestamp": 1631357680981, "ltp": 1.44, "tv": 27462.43, "trd": [[1.44, 3115.17]], "batb": NaN, "batl": [[0, 1.44, 1158.31]]}, {"timestamp": 1631357718446, "ltp": 1.44, "tv": 27633.24, "trd": [[1.44, 3285.97]], "batb": NaN, "batl": [[0, 1.44, 1072.91]]}, {"timestamp": 1631357725583, "ltp": 1.44, "tv": 27633.24, "trd": NaN, "batb": NaN, "batl": [[0, 1.44, 1065.9]]}, {"timestamp": 1631357726260, "ltp": 1.44, "tv": 27633.24, "trd": NaN, "batb": NaN, "batl": [[0, 1.44, 1063.15]]}, {"timestamp": 1631357727174, "ltp": 1.44, "tv": 27633.24, "trd": NaN, "batb": NaN, "batl": [[0, 1.44, 1049.68]]}, {"timestamp": 1631357819326, "ltp": 1.44, "tv": 27720.35, "trd": [[1.44, 3373.09]], "batb": NaN, "batl": [[0, 1.44, 1006.12]]}, {"timestamp": 1631357834473, "ltp": 1.44, "tv": 27720.35, "trd": NaN, "batb": NaN, "batl": [[0, 1.44, 1016.23]]}, {"timestamp": 1631357931398, "ltp": 1.44, "tv": 27720.35, "trd": NaN, "batb": NaN, "batl": [[0, 1.44, 1141.23]]}, {"timestamp": 1631357944440, "ltp": 1.44, "tv": 27720.35, "trd": NaN, "batb": NaN, "batl": [[0, 1.44, 1193.1]]}, {"timestamp": 1631357984543, "ltp": 1.44, "tv": 27720.35, "trd": NaN, "batb": NaN, "batl": [[0, 1.44, 1205.85]]}, {"timestamp": 1631357996746, "ltp": 1.44, "tv": 27720.35, "trd": NaN, "batb": [[1, 1.41, 2840.21]], "batl": NaN}, {"timestamp": 1631358027039, "ltp": 1.44, "tv": 27720.35, "trd": NaN, "batb": NaN, "batl": [[0, 1.44, 1672.62]]}, {"timestamp": 1631358034786, "ltp": 1.44, "tv": 27720.35, "trd": NaN, "batb": [[0, 1.42, 2279.88]], "batl": NaN}, {"timestamp": 1631358059432, "ltp": 1.44, "tv": 27720.35, "trd": NaN, "batb": NaN, "batl": [[0, 1.44, 1714.95]]}, {"timestamp": 1631358067429, "ltp": 1.44, "tv": 27720.35, "trd": NaN, "batb": NaN, "batl": [[0, 1.44, 1715.03]]}, {"timestamp": 1631358136166, "ltp": 1.44, "tv": 27805.76, "trd": [[1.44, 3458.5]], "batb": NaN, "batl": [[0, 1.44, 1672.32]]}, {"timestamp": 1631358138247, "ltp": 1.44, "tv": 27805.76, "trd": NaN, "batb": NaN, "batl": [[0, 1.44, 1685.16]]}, {"timestamp": 1631358227217, "ltp": 1.42, "tv": 27811.08, "trd": [[1.42, 12497.09]], "batb": [[0, 1.42, 2277.22]], "batl": NaN}, {"timestamp": 1631358272098, "ltp": 1.42, "tv": 27811.08, "trd": NaN, "batb": [[0, 1.42, 2311.7]], "batl": NaN}, {"timestamp": 1631358317690, "ltp": 1.42, "tv": 27811.08, "trd": NaN, "batb": NaN, "batl": [[0, 1.44, 1687.81]]}, {"timestamp": 1631358333137, "ltp": 1.42, "tv": 27811.08, "trd": NaN, "batb": [[0, 1.42, 2314.9]], "batl": NaN}, {"timestamp": 1631358621450, "ltp": 1.42, "tv": 27811.08, "trd": NaN, "batb": [[0, 1.42, 2229.49], [1, 1.41, 2969.17]], "batl": [[1, 1.45, 1646.49]]}, {"timestamp": 1631358654060, "ltp": 1.42, "tv": 27811.08, "trd": NaN, "batb": [[0, 1.42, 2314.04], [1, 1.41, 2840.21]], "batl": [[1, 1.45, 1560.23], [2, 1.46, 866.76]]}, {"timestamp": 1631358655120, "ltp": 1.42, "tv": 27811.08, "trd": NaN, "batb": [[0, 1.42, 2279.56]], "batl": NaN}, {"timestamp": 1631358655922, "ltp": 1.42, "tv": 27811.08, "trd": NaN, "batb": [[0, 1.42, 2314.04]], "batl": NaN}, {"timestamp": 1631358809220, "ltp": 1.42, "tv": 27811.08, "trd": NaN, "batb": [[0, 1.43, 40], [1, 1.42, 2314.04], [2, 1.41, 2840.21]], "batl": NaN}, {"timestamp": 1631358827675, "ltp": 1.42, "tv": 27811.08, "trd": NaN, "batb": [[1, 1.42, 2258.29], [2, 1.41, 2547.72]], "batl": NaN}, {"timestamp": 1631358828599, "ltp": 1.42, "tv": 27811.08, "trd": NaN, "batb": [[0, 1.43, 46]], "batl": [[0, 1.44, 1674.98]]}, {"timestamp": 1631358829187, "ltp": 1.42, "tv": 27811.08, "trd": NaN, "batb": NaN, "batl": [[0, 1.44, 1632.66]]}, {"timestamp": 1631358830467, "ltp": 1.42, "tv": 27811.08, "trd": NaN, "batb": NaN, "batl": [[1, 1.45, 1542.23]]}, {"timestamp": 1631358880645, "ltp": 1.43, "tv": 27863.14, "trd": [[1.43, 10642.82]], "batb": [[0, 1.43, 19.97]], "batl": NaN}, {"timestamp": 1631358905485, "ltp": 1.43, "tv": 27863.14, "trd": NaN, "batb": [[1, 1.42, 2251.46]], "batl": [[1, 1.45, 1627.63], [2, 1.46, 744.63]]}, {"timestamp": 1631358926693, "ltp": 1.43, "tv": 27863.14, "trd": NaN, "batb": [[1, 1.42, 2258.29]], "batl": NaN}, {"timestamp": 1631358927500, "ltp": 1.43, "tv": 27863.14, "trd": NaN, "batb": [[1, 1.42, 2173.74], [2, 1.41, 2684.36]], "batl": NaN}, {"timestamp": 1631358928633, "ltp": 1.43, "tv": 27863.14, "trd": NaN, "batb": [[2, 1.41, 2631.41]], "batl": [[1, 1.45, 1672.04]]}, {"timestamp": 1631358929623, "ltp": 1.43, "tv": 27863.14, "trd": NaN, "batb": NaN, "batl": [[1, 1.45, 1542.23]]}, {"timestamp": 1631358930056, "ltp": 1.43, "tv": 27863.14, "trd": NaN, "batb": NaN, "batl": [[0, 1.44, 1710.38]]}, {"timestamp": 1631358932227, "ltp": 1.43, "tv": 27863.14, "trd": NaN, "batb": [[2, 1.41, 2682.65]], "batl": [[0, 1.44, 1632.66]]}, {"timestamp": 1631358942245, "ltp": 1.43, "tv": 27903.08, "trd": [[1.43, 10682.76]], "batb": [[0, 1.42, 2173.74], [1, 1.41, 2682.65], [2, 1.4, 2023.5]], "batl": [[0, 1.43, 2480.03], [1, 1.44, 1632.66], [2, 1.45, 1542.23]]}, {"timestamp": 1631358968262, "ltp": 1.43, "tv": 27903.08, "trd": NaN, "batb": NaN, "batl": [[2, 1.45, 1629.34]]}, {"timestamp": 1631358987687, "ltp": 1.43, "tv": 27903.08, "trd": NaN, "batb": NaN, "batl": [[2, 1.45, 1362.85]]}, {"timestamp": 1631358988384, "ltp": 1.43, "tv": 27903.08, "trd": NaN, "batb": NaN, "batl": [[2, 1.45, 1356.72]]}, {"timestamp": 1631358990562, "ltp": 1.43, "tv": 27903.08, "trd": NaN, "batb": [[1, 1.41, 2953.87]], "batl": NaN}, {"timestamp": 1631359006960, "ltp": 1.43, "tv": 27903.08, "trd": NaN, "batb": NaN, "batl": [[1, 1.44, 796.05]]}, {"timestamp": 1631359039085, "ltp": 1.43, "tv": 27903.08, "trd": NaN, "batb": NaN, "batl": [[1, 1.44, 783.31]]}, {"timestamp": 1631359040289, "ltp": 1.43, "tv": 27903.08, "trd": NaN, "batb": NaN, "batl": [[1, 1.44, 766.58]]}, {"timestamp": 1631359093697, "ltp": 1.42, "tv": 27930.97, "trd": [[1.42, 12524.98]], "batb": [[0, 1.42, 2159.8]], "batl": NaN}, {"timestamp": 1631359126771, "ltp": 1.42, "tv": 27930.97, "trd": NaN, "batb": [[0, 1.42, 3659.8]], "batl": NaN}, {"timestamp": 1631359131422, "ltp": 1.42, "tv": 27930.97, "trd": NaN, "batb": NaN, "batl": [[1, 1.44, 937.38]]}, {"timestamp": 1631359142613, "ltp": 1.42, "tv": 27930.97, "trd": NaN, "batb": NaN, "batl": [[1, 1.44, 957.78]]}, {"timestamp": 1631359223288, "ltp": 1.42, "tv": 27930.97, "trd": NaN, "batb": NaN, "batl": [[1, 1.44, 960.84]]}, {"timestamp": 1631359319106, "ltp": 1.42, "tv": 27930.97, "trd": NaN, "batb": NaN, "batl": [[0, 1.43, 2580.03]]}, {"timestamp": 1631359325121, "ltp": 1.43, "tv": 27948.05, "trd": [[1.43, 10699.84]], "batb": NaN, "batl": [[0, 1.43, 2571.49]]}, {"timestamp": 1631359332847, "ltp": 1.43, "tv": 27948.05, "trd": NaN, "batb": NaN, "batl": [[1, 1.44, 1060.84]]}, {"timestamp": 1631359336472, "ltp": 1.43, "tv": 27948.05, "trd": NaN, "batb": NaN, "batl": [[1, 1.44, 1076.3]]}, {"timestamp": 1631359566374, "ltp": 1.43, "tv": 27991.61, "trd": [[1.43, 10743.4]], "batb": NaN, "batl": [[0, 1.43, 2549.71]]}, {"timestamp": 1631359738328, "ltp": 1.43, "tv": 28338.35, "trd": [[1.43, 11090.14]], "batb": NaN, "batl": [[0, 1.43, 2376.34]]}, {"timestamp": 1631359812927, "ltp": 1.43, "tv": 28510.87, "trd": [[1.43, 11262.66]], "batb": NaN, "batl": [[0, 1.43, 2290.08]]}, {"timestamp": 1631359833980, "ltp": 1.43, "tv": 28610.87, "trd": [[1.43, 11362.66]], "batb": NaN, "batl": [[0, 1.43, 2240.08]]}, {"timestamp": 1631359930113, "ltp": 1.43, "tv": 28610.87, "trd": NaN, "batb": [[0, 1.42, 2159.8]], "batl": NaN}, {"timestamp": 1631360240734, "ltp": 1.43, "tv": 28664.05, "trd": [[1.43, 11415.84]], "batb": NaN, "batl": [[0, 1.43, 2213.49]]}, {"timestamp": 1631360651482, "ltp": 1.42, "tv": 28746.03, "trd": [[1.42, 12606.97]], "batb": [[0, 1.42, 2118.81]], "batl": NaN}, {"timestamp": 1631360651860, "ltp": 1.42, "tv": 28746.03, "trd": NaN, "batb": [[0, 1.42, 2135.08]], "batl": NaN}, {"timestamp": 1631360975681, "ltp": 1.42, "tv": 28746.03, "trd": NaN, "batb": [[2, 1.4, 2132.14]], "batl": NaN}, {"timestamp": 1631361011220, "ltp": 1.43, "tv": 28760.55, "trd": [[1.43, 11430.36]], "batb": NaN, "batl": [[0, 1.43, 2206.23]]}, {"timestamp": 1631361167454, "ltp": 1.43, "tv": 28788.55, "trd": [[1.43, 11458.36]], "batb": NaN, "batl": [[0, 1.43, 2192.23]]}, {"timestamp": 1631361304206, "ltp": 1.43, "tv": 28788.55, "trd": NaN, "batb": [[0, 1.42, 2127.3]], "batl": NaN}, {"timestamp": 1631361320129, "ltp": 1.43, "tv": 28788.55, "trd": NaN, "batb": [[1, 1.41, 2992.16]], "batl": NaN}, {"timestamp": 1631361369570, "ltp": 1.43, "tv": 28788.55, "trd": NaN, "batb": [[2, 1.4, 5747.21]], "batl": NaN}, {"timestamp": 1631361373843, "ltp": 1.43, "tv": 28803.07, "trd": [[1.43, 11472.88]], "batb": NaN, "batl": [[0, 1.43, 2184.97]]}, {"timestamp": 1631361496057, "ltp": 1.43, "tv": 28861.17, "trd": [[1.43, 11530.98]], "batb": NaN, "batl": [[0, 1.43, 2155.92]]}, {"timestamp": 1631361774275, "ltp": 1.43, "tv": 28861.17, "trd": NaN, "batb": [[1, 1.41, 3523.96]], "batl": NaN}, {"timestamp": 1631361781055, "ltp": 1.43, "tv": 28861.17, "trd": NaN, "batb": [[2, 1.4, 6810.81]], "batl": NaN}, {"timestamp": 1631361856330, "ltp": 1.43, "tv": 28879.17, "trd": [[1.43, 11548.98]], "batb": NaN, "batl": [[0, 1.43, 2146.92]]}, {"timestamp": 1631361857844, "ltp": 1.43, "tv": 28908.21, "trd": [[1.43, 11578.02]], "batb": NaN, "batl": [[0, 1.43, 2132.4]]}, {"timestamp": 1631362026741, "ltp": 1.43, "tv": 28908.21, "trd": NaN, "batb": NaN, "batl": [[1, 1.44, 1086.28]]}, {"timestamp": 1631362099293, "ltp": 1.43, "tv": 28966.31, "trd": [[1.43, 11636.12]], "batb": NaN, "batl": [[0, 1.43, 2103.35]]}, {"timestamp": 1631362105507, "ltp": 1.42, "tv": 28987.58, "trd": [[1.42, 12628.23]], "batb": [[0, 1.42, 2116.68]], "batl": NaN}, {"timestamp": 1631362105995, "ltp": 1.42, "tv": 28987.58, "trd": NaN, "batb": [[0, 1.42, 2108.18], [1, 1.41, 3550.04]], "batl": NaN}, {"timestamp": 1631362157169, "ltp": 1.42, "tv": 28987.58, "trd": NaN, "batb": NaN, "batl": [[1, 1.44, 1091.19]]}, {"timestamp": 1631362220924, "ltp": 1.43, "tv": 29002.1, "trd": [[1.43, 11650.64]], "batb": NaN, "batl": [[0, 1.43, 2096.09]]}, {"timestamp": 1631362269725, "ltp": 1.43, "tv": 29009.5, "trd": [[1.43, 11658.04]], "batb": NaN, "batl": [[0, 1.43, 2092.39]]}, {"timestamp": 1631362329424, "ltp": 1.43, "tv": 29265.71, "trd": [[1.43, 11914.25]], "batb": NaN, "batl": [[0, 1.43, 1964.28], [1, 1.44, 1219.3]]}, {"timestamp": 1631362336457, "ltp": 1.43, "tv": 29265.71, "trd": NaN, "batb": NaN, "batl": [[1, 1.44, 1239.25]]}, {"timestamp": 1631362442825, "ltp": 1.43, "tv": 29265.71, "trd": NaN, "batb": NaN, "batl": [[1, 1.44, 1242.24]]}, {"timestamp": 1631362471121, "ltp": 1.43, "tv": 29280.23, "trd": [[1.43, 11928.77]], "batb": NaN, "batl": [[0, 1.43, 1957.02]]}, {"timestamp": 1631362707102, "ltp": 1.42, "tv": 29320.23, "trd": [[1.42, 12668.23]], "batb": [[0, 1.42, 2088.18]], "batl": NaN}, {"timestamp": 1631363194336, "ltp": 1.43, "tv": 29334.75, "trd": [[1.43, 11943.29]], "batb": NaN, "batl": [[0, 1.43, 1949.76]]}, {"timestamp": 1631363236530, "ltp": 1.43, "tv": 29363.85, "trd": [[1.43, 11972.4]], "batb": [[0, 1.42, 2096.56], [1, 1.41, 3523.96]], "batl": [[0, 1.43, 1935.21]]}, {"timestamp": 1631363236931, "ltp": 1.43, "tv": 29363.85, "trd": NaN, "batb": [[0, 1.42, 2088.18], [1, 1.41, 3549.92]], "batl": NaN}, {"timestamp": 1631363288615, "ltp": 1.43, "tv": 29363.85, "trd": NaN, "batb": [[1, 1.41, 3414.98]], "batl": [[2, 1.45, 1269.6]]}, {"timestamp": 1631363288894, "ltp": 1.43, "tv": 29519.29, "trd": [[1.43, 12127.83]], "batb": NaN, "batl": [[0, 1.43, 1857.49]]}, {"timestamp": 1631363292521, "ltp": 1.43, "tv": 29519.29, "trd": NaN, "batb": [[0, 1.42, 2165.04]], "batl": NaN}, {"timestamp": 1631363299515, "ltp": 1.43, "tv": 29519.29, "trd": NaN, "batb": NaN, "batl": [[2, 1.45, 1353.3]]}, {"timestamp": 1631363531334, "ltp": 1.42, "tv": 30319.29, "trd": [[1.42, 13468.23]], "batb": [[0, 1.42, 1811.95]], "batl": NaN}, {"timestamp": 1631363580008, "ltp": 1.42, "tv": 30691.55, "trd": [[1.42, 13840.48]], "batb": [[0, 1.42, 1625.83]], "batl": NaN}, {"timestamp": 1631363598696, "ltp": 1.42, "tv": 30691.55, "trd": NaN, "batb": [[0, 1.42, 1598.48]], "batl": NaN}, {"timestamp": 1631363909935, "ltp": 1.43, "tv": 30754.75, "trd": [[1.43, 12191.03]], "batb": NaN, "batl": [[0, 1.43, 1825.89]]}, {"timestamp": 1631364037150, "ltp": 1.43, "tv": 30769.27, "trd": [[1.43, 12205.55]], "batb": NaN, "batl": [[0, 1.43, 1818.63]]}, {"timestamp": 1631364157612, "ltp": 1.43, "tv": 30769.27, "trd": NaN, "batb": [[1, 1.41, 2883.18], [2, 1.4, 5747.21]], "batl": NaN}, {"timestamp": 1631364159920, "ltp": 1.43, "tv": 30769.27, "trd": NaN, "batb": NaN, "batl": [[0, 1.43, 1834.6]]}, {"timestamp": 1631364190868, "ltp": 1.43, "tv": 30813.68, "trd": [[1.43, 12249.97]], "batb": NaN, "batl": [[0, 1.43, 1812.39]]}, {"timestamp": 1631364261798, "ltp": 1.43, "tv": 30899.08, "trd": [[1.43, 12335.37]], "batb": NaN, "batl": [[0, 1.43, 1769.69]]}, {"timestamp": 1631364270712, "ltp": 1.43, "tv": 32668.77, "trd": [[1.43, 14105.06]], "batb": [[0, 1.43, 125.87], [1, 1.42, 1598.48], [2, 1.41, 2883.18]], "batl": [[0, 1.44, 1117.24], [1, 1.45, 1353.3], [2, 1.46, 744.63]]}, {"timestamp": 1631364297177, "ltp": 1.43, "tv": 32668.77, "trd": NaN, "batb": [[0, 1.43, 458.87]], "batl": NaN}, {"timestamp": 1631364303573, "ltp": 1.44, "tv": 33020.79, "trd": [[1.44, 3810.51]], "batb": NaN, "batl": [[0, 1.44, 941.22]]}, {"timestamp": 1631364305243, "ltp": 1.44, "tv": 33020.79, "trd": NaN, "batb": NaN, "batl": [[0, 1.44, 5941.22]]}, {"timestamp": 1631364332538, "ltp": 1.44, "tv": 33020.79, "trd": NaN, "batb": [[2, 1.41, 2611.96]], "batl": NaN}, {"timestamp": 1631364337641, "ltp": 1.44, "tv": 33020.79, "trd": NaN, "batb": [[0, 1.43, 637.87]], "batl": [[0, 1.44, 6005.74]]}, {"timestamp": 1631364370692, "ltp": 1.44, "tv": 33020.79, "trd": NaN, "batb": [[2, 1.41, 2586]], "batl": NaN}, {"timestamp": 1631364371018, "ltp": 1.44, "tv": 33020.79, "trd": NaN, "batb": [[0, 1.43, 657.74]], "batl": NaN}, {"timestamp": 1631364410662, "ltp": 1.44, "tv": 33020.79, "trd": NaN, "batb": [[1, 1.42, 1604.78]], "batl": NaN}, {"timestamp": 1631364435819, "ltp": 1.44, "tv": 33097.65, "trd": [[1.44, 3887.38]], "batb": NaN, "batl": [[0, 1.44, 5967.31]]}, {"timestamp": 1631364484521, "ltp": 1.44, "tv": 33097.65, "trd": NaN, "batb": [[1, 1.42, 1611.79]], "batl": NaN}, {"timestamp": 1631364491846, "ltp": 1.44, "tv": 33140.36, "trd": [[1.44, 3930.08]], "batb": NaN, "batl": [[0, 1.44, 5945.96]]}, {"timestamp": 1631364515472, "ltp": 1.44, "tv": 33225.76, "trd": [[1.44, 4015.49]], "batb": NaN, "batl": [[0, 1.44, 5903.26]]}, {"timestamp": 1631364521174, "ltp": 1.44, "tv": 33240.18, "trd": [[1.44, 4029.9]], "batb": NaN, "batl": [[0, 1.44, 5896.05]]}, {"timestamp": 1631364589110, "ltp": 1.44, "tv": 33325.58, "trd": [[1.44, 4115.31]], "batb": NaN, "batl": [[0, 1.44, 5853.35]]}, {"timestamp": 1631364671582, "ltp": 1.44, "tv": 33369.99, "trd": [[1.44, 4159.72]], "batb": NaN, "batl": [[0, 1.44, 5831.14]]}, {"timestamp": 1631364720888, "ltp": 1.44, "tv": 33369.99, "trd": NaN, "batb": [[0, 1.43, 833.18]], "batl": NaN}, {"timestamp": 1631364743466, "ltp": 1.44, "tv": 33412.69, "trd": [[1.44, 4202.42]], "batb": NaN, "batl": [[0, 1.44, 5809.79]]}, {"timestamp": 1631364762592, "ltp": 1.44, "tv": 33513.57, "trd": [[1.44, 4303.3]], "batb": NaN, "batl": [[0, 1.44, 5759.35]]}, {"timestamp": 1631364828395, "ltp": 1.44, "tv": 33513.57, "trd": NaN, "batb": NaN, "batl": [[0, 1.44, 5874.11], [1, 1.45, 1612.07]]}, {"timestamp": 1631364883777, "ltp": 1.44, "tv": 33527.94, "trd": [[1.44, 4317.66]], "batb": NaN, "batl": [[0, 1.44, 5866.93]]}, {"timestamp": 1631364899530, "ltp": 1.44, "tv": 33527.94, "trd": NaN, "batb": [[1, 1.42, 1617.72]], "batl": [[1, 1.45, 1650.88]]}, {"timestamp": 1631364982468, "ltp": 1.44, "tv": 33527.94, "trd": NaN, "batb": NaN, "batl": [[1, 1.45, 1656.7]]}, {"timestamp": 1631365018581, "ltp": 1.44, "tv": 33541.94, "trd": [[1.44, 4331.67]], "batb": NaN, "batl": [[0, 1.44, 5859.93]]}, {"timestamp": 1631365075878, "ltp": 1.44, "tv": 33917.94, "trd": [[1.44, 4707.67]], "batb": NaN, "batl": [[0, 1.44, 5671.93]]}, {"timestamp": 1631365080188, "ltp": 1.44, "tv": 33917.94, "trd": NaN, "batb": [[0, 1.43, 859.77], [2, 1.41, 2559.41]], "batl": NaN}, {"timestamp": 1631365135719, "ltp": 1.44, "tv": 33917.94, "trd": NaN, "batb": NaN, "batl": [[1, 1.45, 1693]]}, {"timestamp": 1631365193774, "ltp": 1.44, "tv": 33917.94, "trd": NaN, "batb": [[0, 1.43, 1004.37]], "batl": NaN}, {"timestamp": 1631365216368, "ltp": 1.44, "tv": 33917.94, "trd": NaN, "batb": NaN, "batl": [[1, 1.45, 1698.45]]}, {"timestamp": 1631365283595, "ltp": 1.44, "tv": 33917.94, "trd": NaN, "batb": [[1, 1.42, 1623.43]], "batl": NaN}, {"timestamp": 1631365353976, "ltp": 1.44, "tv": 33917.94, "trd": NaN, "batb": [[0, 1.43, 2504.37]], "batl": NaN}, {"timestamp": 1631365542603, "ltp": 1.43, "tv": 35917.96, "trd": [[1.43, 16105.08]], "batb": [[0, 1.43, 1504.35]], "batl": NaN}, {"timestamp": 1631365543005, "ltp": 1.43, "tv": 35917.96, "trd": NaN, "batb": [[1, 1.42, 1644.41]], "batl": NaN}, {"timestamp": 1631365581672, "ltp": 1.43, "tv": 35917.96, "trd": NaN, "batb": [[0, 1.43, 1678.71], [1, 1.42, 1682.93]], "batl": NaN}, {"timestamp": 1631365582506, "ltp": 1.43, "tv": 35917.96, "trd": NaN, "batb": NaN, "batl": [[0, 1.44, 5847.91]]}, {"timestamp": 1631365612903, "ltp": 1.43, "tv": 35917.96, "trd": NaN, "batb": [[0, 1.43, 2011.71]], "batl": NaN}, {"timestamp": 1631365657042, "ltp": 1.43, "tv": 35917.96, "trd": NaN, "batb": [[0, 1.43, 2084.01]], "batl": NaN}, {"timestamp": 1631365662252, "ltp": 1.44, "tv": 36017.95, "trd": [[1.44, 4807.66]], "batb": NaN, "batl": [[0, 1.44, 5797.92]]}, {"timestamp": 1631365675156, "ltp": 1.44, "tv": 36017.95, "trd": NaN, "batb": [[1, 1.42, 1671.22]], "batl": NaN}, {"timestamp": 1631365725612, "ltp": 1.44, "tv": 36017.95, "trd": NaN, "batb": [[1, 1.42, 1650.23]], "batl": NaN}, {"timestamp": 1631365746666, "ltp": 1.44, "tv": 36017.95, "trd": NaN, "batb": [[0, 1.43, 2120.16]], "batl": NaN}, {"timestamp": 1631365765709, "ltp": 1.44, "tv": 36017.95, "trd": NaN, "batb": [[1, 1.42, 1655.84]], "batl": NaN}, {"timestamp": 1631365852324, "ltp": 1.44, "tv": 36017.95, "trd": NaN, "batb": [[1, 1.42, 1659.08]], "batl": NaN}, {"timestamp": 1631365857747, "ltp": 1.44, "tv": 36148.94, "trd": [[1.44, 4938.65]], "batb": NaN, "batl": [[0, 1.44, 5732.42]]}, {"timestamp": 1631365873171, "ltp": 1.44, "tv": 36159.07, "trd": [[1.44, 4948.78]], "batb": NaN, "batl": [[0, 1.44, 5727.36]]}, {"timestamp": 1631366000713, "ltp": 1.44, "tv": 36159.07, "trd": NaN, "batb": [[1, 1.42, 1668.48]], "batl": NaN}, {"timestamp": 1631366295719, "ltp": 1.44, "tv": 36159.07, "trd": NaN, "batb": NaN, "batl": [[1, 1.45, 1692.47]]}, {"timestamp": 1631366484575, "ltp": 1.44, "tv": 36159.07, "trd": NaN, "batb": NaN, "batl": [[1, 1.45, 1687.02]]}, {"timestamp": 1631366531471, "ltp": 1.44, "tv": 36233.07, "trd": [[1.44, 5022.77]], "batb": NaN, "batl": [[0, 1.44, 5690.36]]}, {"timestamp": 1631366558248, "ltp": 1.43, "tv": 36493.55, "trd": [[1.43, 16365.56]], "batb": [[0, 1.43, 1989.92]], "batl": [[0, 1.44, 5815.36]]}, {"timestamp": 1631366574545, "ltp": 1.43, "tv": 36754.03, "trd": [[1.43, 16626.05]], "batb": [[0, 1.43, 1859.68], [1, 1.42, 1621.57]], "batl": NaN}, {"timestamp": 1631366584674, "ltp": 1.43, "tv": 36754.03, "trd": NaN, "batb": [[1, 1.42, 1535.31], [2, 1.41, 2692.65]], "batl": [[1, 1.45, 1693]]}, {"timestamp": 1631366614642, "ltp": 1.43, "tv": 36754.03, "trd": NaN, "batb": [[2, 1.41, 2559.41]], "batl": [[1, 1.45, 1609.3]]}, {"timestamp": 1631366621045, "ltp": 1.43, "tv": 36754.03, "trd": NaN, "batb": [[1, 1.42, 1532.07]], "batl": NaN}, {"timestamp": 1631366622298, "ltp": 1.43, "tv": 36754.03, "trd": NaN, "batb": [[1, 1.42, 1526.46]], "batl": [[0, 1.44, 5821.67]]}, {"timestamp": 1631366623697, "ltp": 1.43, "tv": 36754.03, "trd": NaN, "batb": NaN, "batl": [[1, 1.45, 1589.15]]}, {"timestamp": 1631366654962, "ltp": 1.43, "tv": 36754.03, "trd": NaN, "batb": NaN, "batl": [[0, 1.44, 5696.67]]}, {"timestamp": 1631366670593, "ltp": 1.43, "tv": 36754.03, "trd": NaN, "batb": NaN, "batl": [[0, 1.44, 696.67]]}, {"timestamp": 1631366674305, "ltp": 1.43, "tv": 39894.04, "trd": [[1.43, 19766.05]], "batb": [[0, 1.43, 289.67]], "batl": NaN}, {"timestamp": 1631366695450, "ltp": 1.43, "tv": 39894.04, "trd": NaN, "batb": [[0, 1.43, 3489.67]], "batl": NaN}, {"timestamp": 1631366705800, "ltp": 1.44, "tv": 39894.4, "trd": [[1.44, 5023.13]], "batb": NaN, "batl": [[0, 1.44, 696.49]]}, {"timestamp": 1631366742707, "ltp": 1.44, "tv": 39894.4, "trd": NaN, "batb": [[0, 1.43, 289.67]], "batl": [[0, 1.44, 821.49]]}, {"timestamp": 1631366743459, "ltp": 1.44, "tv": 39894.4, "trd": NaN, "batb": [[1, 1.42, 1529.37]], "batl": NaN}, {"timestamp": 1631366744362, "ltp": 1.44, "tv": 39894.4, "trd": NaN, "batb": [[0, 1.43, 371.11]], "batl": [[0, 1.44, 815.18]]}, {"timestamp": 1631366745564, "ltp": 1.44, "tv": 39894.4, "trd": NaN, "batb": NaN, "batl": [[0, 1.44, 524.44]]}, {"timestamp": 1631366746691, "ltp": 1.44, "tv": 39894.4, "trd": NaN, "batb": [[0, 1.43, 496.98]], "batl": [[0, 1.44, 487.64], [1, 1.45, 1671.59]]}, {"timestamp": 1631366776212, "ltp": 1.44, "tv": 39894.4, "trd": NaN, "batb": [[2, 1.41, 2692.65]], "batl": [[1, 1.45, 1755.28]]}, {"timestamp": 1631366795353, "ltp": 1.44, "tv": 39894.4, "trd": NaN, "batb": [[2, 1.41, 2644.82]], "batl": [[1, 1.45, 1797.99]]}, {"timestamp": 1631366838588, "ltp": 1.44, "tv": 39894.4, "trd": NaN, "batb": [[1, 1.42, 1551.53]], "batl": [[0, 1.44, 459.92]]}, {"timestamp": 1631366882753, "ltp": 1.44, "tv": 39894.4, "trd": NaN, "batb": [[0, 1.43, 460.83]], "batl": NaN}, {"timestamp": 1631366931411, "ltp": 1.44, "tv": 39894.4, "trd": NaN, "batb": [[1, 1.42, 1526.46]], "batl": NaN}, {"timestamp": 1631366932220, "ltp": 1.44, "tv": 39894.4, "trd": NaN, "batb": [[1, 1.42, 1508.74]], "batl": NaN}, {"timestamp": 1631366933623, "ltp": 1.44, "tv": 39894.4, "trd": NaN, "batb": [[0, 1.43, 448.51]], "batl": NaN}, {"timestamp": 1631367035627, "ltp": 1.44, "tv": 39894.4, "trd": NaN, "batb": [[1, 1.42, 1499.66]], "batl": [[0, 1.44, 474.85]]}, {"timestamp": 1631367036535, "ltp": 1.44, "tv": 39894.4, "trd": NaN, "batb": NaN, "batl": [[1, 1.45, 1786.31]]}, {"timestamp": 1631367106490, "ltp": 1.44, "tv": 39894.4, "trd": NaN, "batb": NaN, "batl": [[0, 1.44, 480.49]]}, {"timestamp": 1631367197487, "ltp": 1.44, "tv": 39894.4, "trd": NaN, "batb": [[1, 1.42, 1542.43]], "batl": NaN}, {"timestamp": 1631367286354, "ltp": 1.44, "tv": 39894.4, "trd": NaN, "batb": [[1, 1.42, 1555.55]], "batl": NaN}, {"timestamp": 1631367390660, "ltp": 1.44, "tv": 39894.4, "trd": NaN, "batb": [[1, 1.42, 1558.52]], "batl": NaN}, {"timestamp": 1631367692551, "ltp": 1.43, "tv": 40273.6, "trd": [[1.43, 20145.25]], "batb": [[0, 1.43, 258.92]], "batl": NaN}, {"timestamp": 1631367806648, "ltp": 1.43, "tv": 40273.6, "trd": NaN, "batb": [[0, 1.43, 228.63]], "batl": [[0, 1.44, 499.89]]}, {"timestamp": 1631367906124, "ltp": 1.43, "tv": 40273.6, "trd": NaN, "batb": NaN, "batl": [[0, 1.44, 506.1]]}, {"timestamp": 1631368106509, "ltp": 1.43, "tv": 40531.59, "trd": [[1.43, 20403.25]], "batb": [[0, 1.43, 99.63]], "batl": NaN}, {"timestamp": 1631368170426, "ltp": 1.43, "tv": 40729.59, "trd": [[1.43, 20601.25]], "batb": [[0, 1.43, 40.9], [1, 1.42, 1607.15]], "batl": NaN}, {"timestamp": 1631368188361, "ltp": 1.43, "tv": 40809.59, "trd": [[1.43, 20681.25]], "batb": [[0, 1.42, 1608.05], [1, 1.41, 2644.82], [2, 1.4, 5936.81]], "batl": NaN}, {"timestamp": 1631368191529, "ltp": 1.43, "tv": 40809.59, "trd": NaN, "batb": [[0, 1.43, 7.04], [1, 1.42, 1610.74], [2, 1.41, 2644.82]], "batl": NaN}, {"timestamp": 1631368193260, "ltp": 1.44, "tv": 40861.71, "trd": [[1.44, 5075.25]], "batb": NaN, "batl": [[0, 1.44, 480.04]]}, {"timestamp": 1631368225417, "ltp": 1.43, "tv": 40875.71, "trd": [[1.43, 20695.25]], "batb": [[0, 1.42, 1610.78], [1, 1.41, 2644.82], [2, 1.4, 5936.81]], "batl": NaN}, {"timestamp": 1631368292314, "ltp": 1.43, "tv": 40875.71, "trd": NaN, "batb": [[0, 1.42, 1610.74]], "batl": NaN}, {"timestamp": 1631368296309, "ltp": 1.43, "tv": 40875.71, "trd": NaN, "batb": [[0, 1.42, 1607.15], [1, 1.41, 3128.76]], "batl": NaN}, {"timestamp": 1631368297335, "ltp": 1.43, "tv": 40875.71, "trd": NaN, "batb": [[0, 1.42, 1591.06]], "batl": NaN}, {"timestamp": 1631368298208, "ltp": 1.43, "tv": 40875.71, "trd": NaN, "batb": NaN, "batl": [[0, 1.44, 494.09]]}, {"timestamp": 1631368385611, "ltp": 1.43, "tv": 40875.71, "trd": NaN, "batb": NaN, "batl": [[0, 1.44, 499.25]]}, {"timestamp": 1631368440584, "ltp": 1.44, "tv": 40918.41, "trd": [[1.44, 5117.95]], "batb": NaN, "batl": [[0, 1.44, 477.9]]}, {"timestamp": 1631368471637, "ltp": 1.44, "tv": 40918.41, "trd": NaN, "batb": [[0, 1.42, 1542.43]], "batl": NaN}, {"timestamp": 1631368472170, "ltp": 1.44, "tv": 40918.41, "trd": NaN, "batb": [[0, 1.42, 1591.06]], "batl": [[0, 1.44, 492.82]]}, {"timestamp": 1631368531444, "ltp": 1.44, "tv": 40918.41, "trd": NaN, "batb": [[0, 1.42, 1542.43]], "batl": NaN}, {"timestamp": 1631368553802, "ltp": 1.44, "tv": 40918.41, "trd": NaN, "batb": [[0, 1.42, 1523.77]], "batl": NaN}, {"timestamp": 1631368601751, "ltp": 1.44, "tv": 40971.1, "trd": [[1.44, 5170.64]], "batb": NaN, "batl": [[0, 1.44, 466.48]]}, {"timestamp": 1631368651259, "ltp": 1.42, "tv": 40973.85, "trd": [[1.42, 13843.24]], "batb": [[0, 1.42, 1522.39]], "batl": NaN}, {"timestamp": 1631368653516, "ltp": 1.42, "tv": 40973.85, "trd": NaN, "batb": NaN, "batl": [[0, 1.44, 470.87]]}, {"timestamp": 1631368865044, "ltp": 1.42, "tv": 40973.85, "trd": NaN, "batb": [[0, 1.42, 1542.41]], "batl": NaN}, {"timestamp": 1631368902309, "ltp": 1.42, "tv": 40973.85, "trd": NaN, "batb": [[0, 1.42, 1522.39]], "batl": NaN}, {"timestamp": 1631368902761, "ltp": 1.42, "tv": 40973.85, "trd": NaN, "batb": [[0, 1.42, 1558.12]], "batl": NaN}, {"timestamp": 1631368922909, "ltp": 1.42, "tv": 40973.85, "trd": NaN, "batb": [[0, 1.43, 43.98], [1, 1.42, 1558.12], [2, 1.41, 3128.76]], "batl": NaN}, {"timestamp": 1631368935183, "ltp": 1.42, "tv": 40973.85, "trd": NaN, "batb": [[1, 1.42, 1522.39]], "batl": NaN}, {"timestamp": 1631368948011, "ltp": 1.42, "tv": 40973.85, "trd": NaN, "batb": [[2, 1.41, 2644.82]], "batl": NaN}, {"timestamp": 1631368949618, "ltp": 1.42, "tv": 40973.85, "trd": NaN, "batb": [[0, 1.43, 50.57]], "batl": NaN}, {"timestamp": 1631369040410, "ltp": 1.42, "tv": 40973.85, "trd": NaN, "batb": [[1, 1.42, 1543.38]], "batl": NaN}, {"timestamp": 1631369233612, "ltp": 1.42, "tv": 40973.85, "trd": NaN, "batb": NaN, "batl": [[0, 1.44, 1870.87]]}, {"timestamp": 1631369241376, "ltp": 1.42, "tv": 40973.85, "trd": NaN, "batb": NaN, "batl": [[0, 1.44, 2081.54]]}, {"timestamp": 1631369248420, "ltp": 1.42, "tv": 40973.85, "trd": NaN, "batb": [[0, 1.43, 1450.57]], "batl": NaN}, {"timestamp": 1631369260348, "ltp": 1.42, "tv": 40973.85, "trd": NaN, "batb": [[0, 1.43, 1452.74]], "batl": NaN}, {"timestamp": 1631369326535, "ltp": 1.42, "tv": 40973.85, "trd": NaN, "batb": [[0, 1.43, 1515.68]], "batl": [[0, 1.44, 2111.41], [1, 1.45, 1820.47]]}, {"timestamp": 1631369364384, "ltp": 1.44, "tv": 41059.25, "trd": [[1.44, 5256.04]], "batb": NaN, "batl": [[0, 1.44, 2068.71]]}, {"timestamp": 1631369406389, "ltp": 1.44, "tv": 41059.25, "trd": NaN, "batb": [[1, 1.42, 1575.27]], "batl": NaN}, {"timestamp": 1631369407580, "ltp": 1.44, "tv": 41059.25, "trd": NaN, "batb": NaN, "batl": [[1, 1.45, 1835.07]]}, {"timestamp": 1631369481721, "ltp": 1.44, "tv": 41059.25, "trd": NaN, "batb": [[1, 1.42, 1586.25]], "batl": [[1, 1.45, 1838.4]]}, {"timestamp": 1631369591915, "ltp": 1.44, "tv": 41087.99, "trd": [[1.44, 5284.78]], "batb": NaN, "batl": [[0, 1.44, 2054.34]]}, {"timestamp": 1631370196766, "ltp": 1.44, "tv": 41131.55, "trd": [[1.44, 5328.34]], "batb": NaN, "batl": [[0, 1.44, 2032.56]]}, {"timestamp": 1631370446147, "ltp": 1.44, "tv": 41131.55, "trd": NaN, "batb": [[1, 1.42, 1594.97]], "batl": NaN}, {"timestamp": 1631370527051, "ltp": 1.44, "tv": 41131.55, "trd": NaN, "batb": [[1, 1.42, 1598.27]], "batl": NaN}, {"timestamp": 1631370659407, "ltp": 1.43, "tv": 41135.55, "trd": [[1.43, 20699.25]], "batb": [[0, 1.43, 1513.68]], "batl": NaN}, {"timestamp": 1631370805988, "ltp": 1.44, "tv": 41282.44, "trd": [[1.44, 5475.23]], "batb": NaN, "batl": [[0, 1.44, 1959.12]]}, {"timestamp": 1631370917595, "ltp": 1.44, "tv": 41282.44, "trd": NaN, "batb": [[0, 1.43, 1529.05]], "batl": NaN}, {"timestamp": 1631370918520, "ltp": 1.44, "tv": 41282.44, "trd": NaN, "batb": NaN, "batl": [[0, 1.44, 1971.11]]}, {"timestamp": 1631371018545, "ltp": 1.44, "tv": 41282.44, "trd": NaN, "batb": [[0, 1.43, 1729.05]], "batl": NaN}, {"timestamp": 1631371149496, "ltp": 1.44, "tv": 41282.44, "trd": NaN, "batb": [[1, 1.42, 1603.9]], "batl": [[0, 1.44, 1981.68]]}, {"timestamp": 1631371222915, "ltp": 1.44, "tv": 41282.44, "trd": NaN, "batb": NaN, "batl": [[0, 1.44, 1984.79]]}, {"timestamp": 1631371475013, "ltp": 1.44, "tv": 41282.44, "trd": NaN, "batb": [[0, 1.43, 329.05]], "batl": [[0, 1.44, 584.79]]}, {"timestamp": 1631371516702, "ltp": 1.44, "tv": 41282.44, "trd": NaN, "batb": [[0, 1.43, 293.5]], "batl": NaN}, {"timestamp": 1631371517331, "ltp": 1.44, "tv": 41282.44, "trd": NaN, "batb": NaN, "batl": [[0, 1.44, 581.68]]}, {"timestamp": 1631371518409, "ltp": 1.44, "tv": 41282.44, "trd": NaN, "batb": NaN, "batl": [[0, 1.44, 571.11]]}, {"timestamp": 1631371519087, "ltp": 1.44, "tv": 41282.44, "trd": NaN, "batb": NaN, "batl": [[0, 1.44, 559.12]]}, {"timestamp": 1631371520382, "ltp": 1.44, "tv": 41282.44, "trd": NaN, "batb": NaN, "batl": [[0, 1.44, 375.25]]}, {"timestamp": 1631371624509, "ltp": 1.44, "tv": 41282.44, "trd": NaN, "batb": [[1, 1.42, 1598.27]], "batl": NaN}, {"timestamp": 1631371625597, "ltp": 1.44, "tv": 41282.44, "trd": NaN, "batb": [[1, 1.42, 1586.25]], "batl": NaN}, {"timestamp": 1631371626214, "ltp": 1.44, "tv": 41282.44, "trd": NaN, "batb": [[1, 1.42, 1575.27]], "batl": NaN}, {"timestamp": 1631371627541, "ltp": 1.44, "tv": 41282.44, "trd": NaN, "batb": NaN, "batl": [[0, 1.44, 343.82], [1, 1.45, 1835.07]]}, {"timestamp": 1631371628587, "ltp": 1.44, "tv": 41282.44, "trd": NaN, "batb": NaN, "batl": [[1, 1.45, 1805.75]]}, {"timestamp": 1631371700716, "ltp": 1.44, "tv": 41282.44, "trd": NaN, "batb": NaN, "batl": [[1, 1.45, 1791.55]]}, {"timestamp": 1631371789759, "ltp": 1.43, "tv": 41425.79, "trd": [[1.43, 20842.6]], "batb": [[0, 1.43, 179.85]], "batl": NaN}, {"timestamp": 1631371895591, "ltp": 1.43, "tv": 41425.79, "trd": NaN, "batb": [[0, 1.43, 206.83]], "batl": NaN}, {"timestamp": 1631371978477, "ltp": 1.43, "tv": 41425.79, "trd": NaN, "batb": [[1, 1.42, 1560.66]], "batl": NaN}, {"timestamp": 1631371979387, "ltp": 1.43, "tv": 41425.79, "trd": NaN, "batb": [[0, 1.43, 210.88]], "batl": [[0, 1.44, 332.23]]}, {"timestamp": 1631372343922, "ltp": 1.43, "tv": 41825.79, "trd": [[1.43, 21242.6]], "batb": [[0, 1.43, 10.88]], "batl": NaN}, {"timestamp": 1631372368455, "ltp": 1.43, "tv": 41825.79, "trd": NaN, "batb": [[0, 1.43, 30.77]], "batl": NaN}, {"timestamp": 1631372369465, "ltp": 1.43, "tv": 41825.79, "trd": NaN, "batb": [[0, 1.43, 10.88]], "batl": NaN}, {"timestamp": 1631372558474, "ltp": 1.43, "tv": 41825.79, "trd": NaN, "batb": [[0, 1.43, 13.53]], "batl": NaN}, {"timestamp": 1631372609519, "ltp": 1.43, "tv": 41825.79, "trd": NaN, "batb": NaN, "batl": [[0, 1.44, 864.03]]}, {"timestamp": 1631372646593, "ltp": 1.42, "tv": 45432.15, "trd": [[1.42, 17422.52], [1.43, 21269.67]], "batb": [[0, 1.41, 2666.56], [1, 1.4, 5936.81], [2, 1.39, 6190.77]], "batl": [[0, 1.42, 13078.94], [1, 1.44, 864.03], [2, 1.45, 1791.55]]}, {"timestamp": 1631372664708, "ltp": 1.42, "tv": 45432.15, "trd": NaN, "batb": NaN, "batl": [[1, 1.44, 846.12]]}, {"timestamp": 1631372665412, "ltp": 1.42, "tv": 45432.15, "trd": NaN, "batb": NaN, "batl": [[1, 1.44, 831.2]]}, {"timestamp": 1631372666012, "ltp": 1.42, "tv": 45432.15, "trd": NaN, "batb": NaN, "batl": [[2, 1.45, 1785.73]]}, {"timestamp": 1631372667263, "ltp": 1.42, "tv": 45432.15, "trd": NaN, "batb": NaN, "batl": [[1, 1.44, 826.04], [2, 1.45, 1780.49]]}, {"timestamp": 1631372668368, "ltp": 1.42, "tv": 45432.15, "trd": NaN, "batb": NaN, "batl": [[1, 1.44, 820.39], [2, 1.45, 1764.33]]}, {"timestamp": 1631372669568, "ltp": 1.42, "tv": 45432.15, "trd": NaN, "batb": NaN, "batl": [[1, 1.44, 792.69]]}, {"timestamp": 1631372670263, "ltp": 1.42, "tv": 45432.15, "trd": NaN, "batb": NaN, "batl": [[1, 1.44, 788.3]]}, {"timestamp": 1631372671036, "ltp": 1.42, "tv": 45432.15, "trd": NaN, "batb": NaN, "batl": [[1, 1.44, 768.35]]}, {"timestamp": 1631372672674, "ltp": 1.42, "tv": 45432.15, "trd": NaN, "batb": NaN, "batl": [[2, 1.45, 1434.81]]}, {"timestamp": 1631372673480, "ltp": 1.42, "tv": 45432.15, "trd": NaN, "batb": NaN, "batl": [[2, 1.45, 1396]]}, {"timestamp": 1631372674161, "ltp": 1.42, "tv": 45432.15, "trd": NaN, "batb": NaN, "batl": [[1, 1.44, 762.14]]}, {"timestamp": 1631372675668, "ltp": 1.42, "tv": 45432.15, "trd": NaN, "batb": NaN, "batl": [[1, 1.44, 742.74]]}, {"timestamp": 1631372677683, "ltp": 1.42, "tv": 45432.15, "trd": NaN, "batb": [[0, 1.41, 3171.89], [1, 1.4, 6388.84]], "batl": [[1, 1.43, 18.88], [2, 1.44, 742.74]]}, {"timestamp": 1631372688696, "ltp": 1.42, "tv": 45432.15, "trd": NaN, "batb": [[0, 1.41, 3760.89]], "batl": NaN}, {"timestamp": 1631372719247, "ltp": 1.42, "tv": 45432.15, "trd": NaN, "batb": NaN, "batl": [[2, 1.44, 913.54]]}, {"timestamp": 1631372779584, "ltp": 1.42, "tv": 45432.15, "trd": NaN, "batb": [[0, 1.41, 3819.7]], "batl": [[1, 1.43, 21.71]]}, {"timestamp": 1631372853501, "ltp": 1.42, "tv": 45432.15, "trd": NaN, "batb": [[0, 1.41, 3828.52]], "batl": [[1, 1.43, 30.92]]}, {"timestamp": 1631373073916, "ltp": 1.42, "tv": 45432.15, "trd": NaN, "batb": [[0, 1.41, 3683.91]], "batl": NaN}, {"timestamp": 1631373158125, "ltp": 1.42, "tv": 45432.15, "trd": NaN, "batb": [[0, 1.41, 3675.1]], "batl": NaN}, {"timestamp": 1631373253970, "ltp": 1.42, "tv": 45432.15, "trd": NaN, "batb": [[0, 1.41, 4823.54]], "batl": NaN}, {"timestamp": 1631373263699, "ltp": 1.42, "tv": 45432.15, "trd": NaN, "batb": [[0, 1.41, 4982.94]], "batl": NaN}, {"timestamp": 1631373338691, "ltp": 1.42, "tv": 45432.15, "trd": NaN, "batb": [[0, 1.41, 5006.85]], "batl": NaN}, {"timestamp": 1631373425628, "ltp": 1.42, "tv": 45432.15, "trd": NaN, "batb": [[0, 1.41, 5010.44]], "batl": NaN}, {"timestamp": 1631373453471, "ltp": 1.42, "tv": 45432.15, "trd": NaN, "batb": [[1, 1.4, 5665.82]], "batl": NaN}, {"timestamp": 1631373548677, "ltp": 1.42, "tv": 45432.15, "trd": NaN, "batb": NaN, "batl": [[1, 1.43, 730.92]]}, {"timestamp": 1631373587545, "ltp": 1.42, "tv": 45432.15, "trd": NaN, "batb": NaN, "batl": [[1, 1.43, 837.3]]}, {"timestamp": 1631373660675, "ltp": 1.42, "tv": 45517.55, "trd": [[1.42, 17507.92]], "batb": NaN, "batl": [[0, 1.42, 13036.24]]}, {"timestamp": 1631373671665, "ltp": 1.42, "tv": 45517.55, "trd": NaN, "batb": NaN, "batl": [[1, 1.43, 853.26]]}, {"timestamp": 1631373872666, "ltp": 1.41, "tv": 45717.55, "trd": [[1.41, 1134.95]], "batb": [[0, 1.41, 4910.44]], "batl": NaN}, {"timestamp": 1631373898051, "ltp": 1.41, "tv": 45717.55, "trd": NaN, "batb": NaN, "batl": [[2, 1.44, 381.74]]}, {"timestamp": 1631373978258, "ltp": 1.41, "tv": 45717.55, "trd": NaN, "batb": [[0, 1.41, 4906.85]], "batl": NaN}, {"timestamp": 1631373979004, "ltp": 1.41, "tv": 45993.1, "trd": [[1.41, 1410.5]], "batb": [[0, 1.41, 4769.08]], "batl": NaN}, {"timestamp": 1631373981547, "ltp": 1.42, "tv": 46155.36, "trd": [[1.42, 17670.19]], "batb": NaN, "batl": [[0, 1.42, 12955.11]]}, {"timestamp": 1631374059481, "ltp": 1.42, "tv": 46155.36, "trd": NaN, "batb": [[0, 1.41, 4745.17]], "batl": NaN}, {"timestamp": 1631374190351, "ltp": 1.42, "tv": 46155.36, "trd": NaN, "batb": [[0, 1.41, 4733.41]], "batl": NaN}, {"timestamp": 1631374419055, "ltp": 1.42, "tv": 46172.44, "trd": [[1.42, 17687.27]], "batb": NaN, "batl": [[0, 1.42, 12946.57]]}, {"timestamp": 1631374445678, "ltp": 1.42, "tv": 46172.44, "trd": NaN, "batb": [[0, 1.41, 4734.15]], "batl": NaN}, {"timestamp": 1631374746168, "ltp": 1.42, "tv": 46172.44, "trd": NaN, "batb": [[0, 1.41, 4734.67]], "batl": NaN}, {"timestamp": 1631374765382, "ltp": 1.42, "tv": 46522.6, "trd": [[1.42, 18037.43]], "batb": NaN, "batl": [[0, 1.42, 12771.49]]}, {"timestamp": 1631375169259, "ltp": 1.42, "tv": 46531.14, "trd": [[1.42, 18045.97]], "batb": NaN, "batl": [[0, 1.42, 12767.22]]}, {"timestamp": 1631375223007, "ltp": 1.42, "tv": 46548.22, "trd": [[1.42, 18063.05]], "batb": NaN, "batl": [[0, 1.42, 12758.68]]}, {"timestamp": 1631375245512, "ltp": 1.41, "tv": 46780.22, "trd": [[1.41, 1642.49]], "batb": [[0, 1.41, 4618.67]], "batl": NaN}, {"timestamp": 1631375254515, "ltp": 1.41, "tv": 46780.22, "trd": NaN, "batb": [[0, 1.41, 4599.7]], "batl": NaN}, {"timestamp": 1631375496572, "ltp": 1.41, "tv": 47634.26, "trd": [[1.41, 2496.54]], "batb": [[0, 1.41, 4172.68]], "batl": NaN}, {"timestamp": 1631375497482, "ltp": 1.41, "tv": 48488.31, "trd": [[1.41, 3350.58]], "batb": [[0, 1.41, 3745.65]], "batl": NaN}, {"timestamp": 1631375505689, "ltp": 1.41, "tv": 48488.31, "trd": NaN, "batb": [[0, 1.41, 3616.99]], "batl": NaN}, {"timestamp": 1631375598540, "ltp": 1.41, "tv": 48488.31, "trd": NaN, "batb": [[0, 1.41, 3595.4]], "batl": NaN}, {"timestamp": 1631375616831, "ltp": 1.42, "tv": 48502.95, "trd": [[1.42, 18077.69]], "batb": NaN, "batl": [[0, 1.42, 12751.36]]}, {"timestamp": 1631375831096, "ltp": 1.42, "tv": 48502.95, "trd": NaN, "batb": NaN, "batl": [[0, 1.42, 12633.71]]}, {"timestamp": 1631375899423, "ltp": 1.41, "tv": 48528.95, "trd": [[1.41, 3376.58]], "batb": [[0, 1.41, 3582.41]], "batl": NaN}, {"timestamp": 1631376233054, "ltp": 1.42, "tv": 48532.36, "trd": [[1.42, 18081.11]], "batb": NaN, "batl": [[0, 1.42, 12632]]}, {"timestamp": 1631376266722, "ltp": 1.42, "tv": 48532.36, "trd": NaN, "batb": [[0, 1.41, 3795.92]], "batl": NaN}, {"timestamp": 1631376276751, "ltp": 1.42, "tv": 48532.36, "trd": NaN, "batb": NaN, "batl": [[2, 1.44, 509.85]]}, {"timestamp": 1631376361512, "ltp": 1.42, "tv": 48532.36, "trd": NaN, "batb": [[0, 1.41, 3822.76]], "batl": NaN}, {"timestamp": 1631376469388, "ltp": 1.42, "tv": 48532.36, "trd": NaN, "batb": NaN, "batl": [[0, 1.42, 12758.76]]}, {"timestamp": 1631376488640, "ltp": 1.42, "tv": 48532.36, "trd": NaN, "batb": [[0, 1.41, 3826.78]], "batl": NaN}, {"timestamp": 1631376489326, "ltp": 1.42, "tv": 48532.36, "trd": NaN, "batb": NaN, "batl": [[1, 1.43, 981.73]]}, {"timestamp": 1631376580085, "ltp": 1.42, "tv": 48567.22, "trd": [[1.42, 18115.97]], "batb": NaN, "batl": [[0, 1.42, 12741.33]]}, {"timestamp": 1631376696709, "ltp": 1.41, "tv": 48690.36, "trd": [[1.41, 3499.71]], "batb": [[0, 1.41, 3765.21]], "batl": NaN}, {"timestamp": 1631381839366, "ltp": 1.41, "tv": 48690.36, "trd": NaN, "batb": [[0, 1.41, 3800.23]], "batl": NaN}, {"timestamp": 1631381878103, "ltp": 1.41, "tv": 48700.35, "trd": [[1.41, 3509.71]], "batb": [[0, 1.41, 3795.23]], "batl": NaN}, {"timestamp": 1631381886992, "ltp": 1.41, "tv": 48700.35, "trd": NaN, "batb": NaN, "batl": [[2, 1.44, 384.85]]}, {"timestamp": 1631381892131, "ltp": 1.41, "tv": 48700.35, "trd": NaN, "batb": NaN, "batl": [[0, 1.42, 12746.33]]}, {"timestamp": 1631381949701, "ltp": 1.41, "tv": 48700.35, "trd": NaN, "batb": [[0, 1.41, 3751.68]], "batl": NaN}, {"timestamp": 1631381949804, "ltp": 1.41, "tv": 48700.35, "trd": NaN, "batb": NaN, "batl": [[2, 1.44, 470.25]]}, {"timestamp": 1631382214642, "ltp": 1.41, "tv": 48704.35, "trd": [[1.41, 3513.71]], "batb": [[0, 1.41, 3749.68]], "batl": NaN}, {"timestamp": 1631382324724, "ltp": 1.41, "tv": 49320.0, "trd": [[1.41, 4129.36]], "batb": [[0, 1.41, 3441.86]], "batl": NaN}, {"timestamp": 1631382379707, "ltp": 1.41, "tv": 49320.0, "trd": NaN, "batb": [[0, 1.41, 3410.99]], "batl": NaN}, {"timestamp": 1631382380715, "ltp": 1.41, "tv": 49320.0, "trd": NaN, "batb": [[0, 1.41, 3384.72]], "batl": NaN}, {"timestamp": 1631382394775, "ltp": 1.41, "tv": 49320.0, "trd": NaN, "batb": [[0, 1.41, 3884.72]], "batl": NaN}, {"timestamp": 1631382512041, "ltp": 1.41, "tv": 49320.0, "trd": NaN, "batb": [[0, 1.41, 3951.15]], "batl": NaN}, {"timestamp": 1631382513725, "ltp": 1.42, "tv": 49393.38, "trd": [[1.42, 18189.35]], "batb": NaN, "batl": [[0, 1.42, 12709.64]]}, {"timestamp": 1631382580820, "ltp": 1.42, "tv": 49393.38, "trd": NaN, "batb": [[0, 1.41, 4201.15]], "batl": NaN}, {"timestamp": 1631382653223, "ltp": 1.42, "tv": 49393.38, "trd": NaN, "batb": [[0, 1.41, 4248.62]], "batl": NaN}, {"timestamp": 1631382660323, "ltp": 1.42, "tv": 49393.38, "trd": NaN, "batb": [[0, 1.41, 4256.3]], "batl": NaN}, {"timestamp": 1631382785374, "ltp": 1.42, "tv": 49393.38, "trd": NaN, "batb": [[0, 1.41, 4264.57]], "batl": NaN}, {"timestamp": 1631382974277, "ltp": 1.42, "tv": 49393.38, "trd": NaN, "batb": NaN, "batl": [[1, 1.43, 1081.73]]}, {"timestamp": 1631382978069, "ltp": 1.42, "tv": 49393.38, "trd": NaN, "batb": NaN, "batl": [[2, 1.44, 570.25]]}, {"timestamp": 1631382987004, "ltp": 1.42, "tv": 49393.38, "trd": NaN, "batb": NaN, "batl": [[0, 1.42, 12809.64]]}, {"timestamp": 1631383005108, "ltp": 1.41, "tv": 49427.82, "trd": [[1.41, 4163.8]], "batb": [[0, 1.41, 4247.35]], "batl": NaN}, {"timestamp": 1631383145594, "ltp": 1.41, "tv": 49433.33, "trd": [[1.41, 4169.31]], "batb": [[0, 1.41, 4244.59]], "batl": NaN}, {"timestamp": 1631383294955, "ltp": 1.41, "tv": 50372.63, "trd": [[1.41, 5108.61]], "batb": [[0, 1.41, 3774.95]], "batl": NaN}, {"timestamp": 1631383328728, "ltp": 1.42, "tv": 50447.83, "trd": [[1.42, 18264.55]], "batb": NaN, "batl": [[0, 1.42, 12772.04]]}, {"timestamp": 1631383390476, "ltp": 1.42, "tv": 50447.83, "trd": NaN, "batb": [[0, 1.41, 3766.68]], "batl": NaN}, {"timestamp": 1631383391491, "ltp": 1.42, "tv": 50447.83, "trd": NaN, "batb": [[0, 1.41, 3702.74]], "batl": NaN}, {"timestamp": 1631383523342, "ltp": 1.41, "tv": 54156.12, "trd": [[1.41, 8816.89]], "batb": [[0, 1.41, 1848.59]], "batl": NaN}, {"timestamp": 1631383548472, "ltp": 1.41, "tv": 54156.12, "trd": NaN, "batb": [[0, 1.41, 1968.15]], "batl": NaN}, {"timestamp": 1631383619544, "ltp": 1.41, "tv": 54156.12, "trd": NaN, "batb": [[0, 1.41, 1925.45]], "batl": NaN}, {"timestamp": 1631383620670, "ltp": 1.41, "tv": 54156.12, "trd": NaN, "batb": [[1, 1.4, 5802.47]], "batl": NaN}, {"timestamp": 1631383661546, "ltp": 1.41, "tv": 54156.12, "trd": NaN, "batb": [[0, 1.41, 2164.3]], "batl": [[1, 1.43, 1139.98]]}, {"timestamp": 1631383668939, "ltp": 1.41, "tv": 54156.12, "trd": NaN, "batb": [[0, 1.41, 4018.43]], "batl": NaN}, {"timestamp": 1631383775721, "ltp": 1.41, "tv": 54156.12, "trd": NaN, "batb": [[0, 1.41, 4332.38]], "batl": NaN}, {"timestamp": 1631383776413, "ltp": 1.41, "tv": 54156.12, "trd": NaN, "batb": NaN, "batl": [[1, 1.43, 1177.44]]}, {"timestamp": 1631383824119, "ltp": 1.42, "tv": 54256.12, "trd": [[1.42, 18364.55]], "batb": NaN, "batl": [[0, 1.42, 12722.04]]}, {"timestamp": 1631383897594, "ltp": 1.42, "tv": 54256.12, "trd": NaN, "batb": NaN, "batl": [[1, 1.43, 1183.06]]}, {"timestamp": 1631383912813, "ltp": 1.42, "tv": 54266.12, "trd": [[1.42, 18374.55]], "batb": NaN, "batl": [[0, 1.42, 12717.04]]}, {"timestamp": 1631384126611, "ltp": 1.42, "tv": 54466.12, "trd": [[1.42, 18574.55]], "batb": NaN, "batl": [[0, 1.42, 12617.04]]}, {"timestamp": 1631384564968, "ltp": 1.41, "tv": 54666.12, "trd": [[1.41, 9016.89]], "batb": [[0, 1.41, 4232.38]], "batl": NaN}, {"timestamp": 1631384792728, "ltp": 1.41, "tv": 54667.74, "trd": [[1.41, 9018.51]], "batb": [[0, 1.41, 4231.58]], "batl": NaN}, {"timestamp": 1631384981461, "ltp": 1.41, "tv": 54667.74, "trd": NaN, "batb": NaN, "batl": [[0, 1.42, 12490.28]]}, {"timestamp": 1631385051434, "ltp": 1.42, "tv": 54696.9, "trd": [[1.42, 18603.71]], "batb": NaN, "batl": [[0, 1.42, 12475.7]]}, {"timestamp": 1631385185980, "ltp": 1.42, "tv": 54696.9, "trd": NaN, "batb": [[0, 1.41, 4232.34]], "batl": NaN}, {"timestamp": 1631385273825, "ltp": 1.41, "tv": 58463.23, "trd": [[1.41, 12784.85]], "batb": [[0, 1.41, 2349.17]], "batl": NaN}, {"timestamp": 1631385373426, "ltp": 1.41, "tv": 58463.23, "trd": NaN, "batb": [[0, 1.41, 2207.27]], "batl": NaN}, {"timestamp": 1631385374598, "ltp": 1.41, "tv": 58463.23, "trd": NaN, "batb": NaN, "batl": [[0, 1.42, 12521.76]]}, {"timestamp": 1631385497504, "ltp": 1.41, "tv": 58463.23, "trd": NaN, "batb": [[0, 1.41, 2185.98]], "batl": [[1, 1.43, 1191.99]]}, {"timestamp": 1631385696071, "ltp": 1.42, "tv": 58463.25, "trd": [[1.42, 18603.73]], "batb": NaN, "batl": [[0, 1.42, 12521.75]]}, {"timestamp": 1631385750194, "ltp": 1.42, "tv": 58463.25, "trd": NaN, "batb": [[0, 1.41, 2305.54]], "batl": NaN}, {"timestamp": 1631385760683, "ltp": 1.42, "tv": 58463.25, "trd": NaN, "batb": [[0, 1.41, 2320.29]], "batl": NaN}, {"timestamp": 1631385781941, "ltp": 1.42, "tv": 58463.25, "trd": NaN, "batb": [[0, 1.41, 2452.66]], "batl": NaN}, {"timestamp": 1631385795960, "ltp": 1.41, "tv": 58466.01, "trd": [[1.41, 12787.6]], "batb": [[0, 1.41, 2451.29]], "batl": NaN}, {"timestamp": 1631385861079, "ltp": 1.41, "tv": 60918.01, "trd": [[1.41, 15239.61]], "batb": [[0, 1.41, 1225.28]], "batl": NaN}, {"timestamp": 1631385884588, "ltp": 1.41, "tv": 60918.01, "trd": NaN, "batb": [[0, 1.41, 1243.57]], "batl": [[0, 1.42, 12610.49]]}, {"timestamp": 1631385896893, "ltp": 1.42, "tv": 61797.52, "trd": [[1.42, 19483.23]], "batb": NaN, "batl": [[0, 1.42, 12170.74]]}, {"timestamp": 1631385921832, "ltp": 1.42, "tv": 61885.47, "trd": [[1.42, 19571.19]], "batb": NaN, "batl": [[0, 1.42, 12126.76]]}, {"timestamp": 1631385928737, "ltp": 1.42, "tv": 61973.43, "trd": [[1.42, 19659.14]], "batb": NaN, "batl": [[0, 1.42, 12082.78]]}, {"timestamp": 1631385949679, "ltp": 1.41, "tv": 64460.55, "trd": [[1.41, 17726.73]], "batb": [[0, 1.4, 5802.47], [1, 1.39, 6190.77], [2, 1.38, 6976.68]], "batl": [[0, 1.41, 1256.44], [1, 1.42, 12082.78], [2, 1.43, 1191.99]]}, {"timestamp": 1631386034572, "ltp": 1.41, "tv": 64460.55, "trd": NaN, "batb": NaN, "batl": [[2, 1.43, 1130.9]]}, {"timestamp": 1631386035301, "ltp": 1.41, "tv": 64460.55, "trd": NaN, "batb": NaN, "batl": [[2, 1.43, 1002.43]]}, {"timestamp": 1631386036300, "ltp": 1.41, "tv": 64460.55, "trd": NaN, "batb": NaN, "batl": [[2, 1.43, 949.01]]}, {"timestamp": 1631386037198, "ltp": 1.41, "tv": 64460.55, "trd": NaN, "batb": NaN, "batl": [[2, 1.43, 921.2]]}, {"timestamp": 1631386038308, "ltp": 1.41, "tv": 64460.55, "trd": NaN, "batb": NaN, "batl": [[2, 1.43, 805.62]]}, {"timestamp": 1631386038791, "ltp": 1.41, "tv": 64460.55, "trd": NaN, "batb": NaN, "batl": [[2, 1.43, 800]]}, {"timestamp": 1631386041504, "ltp": 1.41, "tv": 64460.55, "trd": NaN, "batb": [[0, 1.4, 6334.84], [1, 1.39, 6642.8]], "batl": [[1, 1.42, 12169.46]]}, {"timestamp": 1631386057812, "ltp": 1.41, "tv": 64460.55, "trd": NaN, "batb": NaN, "batl": [[0, 1.41, 3809.09]]}, {"timestamp": 1631386064240, "ltp": 1.41, "tv": 64460.55, "trd": NaN, "batb": NaN, "batl": [[0, 1.41, 6361.74]]}, {"timestamp": 1631386140541, "ltp": 1.41, "tv": 64462.71, "trd": [[1.41, 17728.89]], "batb": NaN, "batl": [[0, 1.41, 6360.66]]}, {"timestamp": 1631386162383, "ltp": 1.41, "tv": 64462.71, "trd": NaN, "batb": NaN, "batl": [[0, 1.41, 6386.77]]}, {"timestamp": 1631386304925, "ltp": 1.41, "tv": 64462.71, "trd": NaN, "batb": [[0, 1.4, 6145.24]], "batl": NaN}, {"timestamp": 1631386326695, "ltp": 1.41, "tv": 64462.71, "trd": NaN, "batb": [[0, 1.4, 3253.19]], "batl": NaN}, {"timestamp": 1631386326906, "ltp": 1.41, "tv": 64462.71, "trd": NaN, "batb": [[2, 1.38, 9868.74]], "batl": [[0, 1.41, 6514.42]]}, {"timestamp": 1631386430543, "ltp": 1.41, "tv": 64462.71, "trd": NaN, "batb": [[0, 1.4, 3058.53]], "batl": NaN}, {"timestamp": 1631386493477, "ltp": 1.4, "tv": 64471.25, "trd": [[1.4, 29.76]], "batb": [[0, 1.4, 3054.26]], "batl": NaN}, {"timestamp": 1631386529718, "ltp": 1.4, "tv": 64553.29, "trd": [[1.4, 111.8]], "batb": [[0, 1.4, 3013.24]], "batl": NaN}, {"timestamp": 1631386565672, "ltp": 1.41, "tv": 64577.01, "trd": [[1.41, 17752.61]], "batb": [[0, 1.4, 2897.51]], "batl": [[0, 1.41, 6502.56]]}, {"timestamp": 1631386691424, "ltp": 1.41, "tv": 64577.01, "trd": NaN, "batb": [[0, 1.4, 2805.16]], "batl": NaN}, {"timestamp": 1631386818713, "ltp": 1.41, "tv": 64577.01, "trd": NaN, "batb": [[0, 1.4, 2777.45]], "batl": NaN}, {"timestamp": 1631386869555, "ltp": 1.41, "tv": 64577.01, "trd": NaN, "batb": [[0, 1.4, 2799.9]], "batl": NaN}, {"timestamp": 1631386870767, "ltp": 1.41, "tv": 64577.01, "trd": NaN, "batb": [[0, 1.4, 4056.22]], "batl": NaN}, {"timestamp": 1631386945423, "ltp": 1.41, "tv": 64577.01, "trd": NaN, "batb": [[0, 1.4, 4241.06]], "batl": NaN}, {"timestamp": 1631387059416, "ltp": 1.41, "tv": 64577.01, "trd": NaN, "batb": [[0, 1.4, 4296.51]], "batl": NaN}, {"timestamp": 1631387162581, "ltp": 1.41, "tv": 64637.01, "trd": [[1.41, 17812.61]], "batb": NaN, "batl": [[0, 1.41, 6472.56]]}, {"timestamp": 1631387186544, "ltp": 1.41, "tv": 64637.01, "trd": NaN, "batb": [[0, 1.4, 4313.15]], "batl": NaN}, {"timestamp": 1631387306661, "ltp": 1.41, "tv": 64637.01, "trd": NaN, "batb": [[0, 1.4, 4318.13]], "batl": NaN}, {"timestamp": 1631387445771, "ltp": 1.4, "tv": 64655.41, "trd": [[1.4, 130.19]], "batb": [[0, 1.4, 4308.94]], "batl": NaN}, {"timestamp": 1631387675587, "ltp": 1.4, "tv": 64655.41, "trd": NaN, "batb": [[0, 1.4, 4303.95]], "batl": NaN}, {"timestamp": 1631387806715, "ltp": 1.4, "tv": 64655.41, "trd": NaN, "batb": [[0, 1.4, 4291.01]], "batl": NaN}, {"timestamp": 1631387923395, "ltp": 1.4, "tv": 64655.41, "trd": NaN, "batb": [[0, 1.4, 4298.45]], "batl": NaN}, {"timestamp": 1631387983365, "ltp": 1.4, "tv": 64663.4, "trd": [[1.4, 138.19]], "batb": [[0, 1.4, 4294.45]], "batl": NaN}, {"timestamp": 1631388170499, "ltp": 1.4, "tv": 64663.4, "trd": NaN, "batb": NaN, "batl": [[0, 1.41, 6344.91], [1, 1.42, 326.48]]}, {"timestamp": 1631388594898, "ltp": 1.41, "tv": 64713.4, "trd": [[1.41, 17862.61]], "batb": NaN, "batl": [[0, 1.41, 6319.91]]}, {"timestamp": 1631388614529, "ltp": 1.4, "tv": 65012.14, "trd": [[1.4, 436.93]], "batb": [[0, 1.4, 4145.08]], "batl": NaN}, {"timestamp": 1631388655735, "ltp": 1.41, "tv": 65031.09, "trd": [[1.41, 17881.55]], "batb": NaN, "batl": [[0, 1.41, 6310.44]]}, {"timestamp": 1631388665651, "ltp": 1.41, "tv": 65031.09, "trd": NaN, "batb": [[0, 1.4, 4137.65]], "batl": NaN}, {"timestamp": 1631388666131, "ltp": 1.41, "tv": 65031.09, "trd": NaN, "batb": [[0, 1.4, 4133.95]], "batl": NaN}, {"timestamp": 1631388786236, "ltp": 1.41, "tv": 65031.09, "trd": NaN, "batb": [[0, 1.4, 4134.46]], "batl": NaN}, {"timestamp": 1631388790239, "ltp": 1.41, "tv": 65031.09, "trd": NaN, "batb": [[0, 1.4, 4122.03]], "batl": NaN}, {"timestamp": 1631388845345, "ltp": 1.4, "tv": 65037.09, "trd": [[1.4, 442.93]], "batb": [[0, 1.4, 4119.03]], "batl": NaN}, {"timestamp": 1631389013078, "ltp": 1.41, "tv": 65120.41, "trd": [[1.41, 17964.87]], "batb": NaN, "batl": [[0, 1.41, 6268.78]]}, {"timestamp": 1631389253854, "ltp": 1.41, "tv": 65120.41, "trd": NaN, "batb": [[0, 1.4, 4428.88]], "batl": NaN}, {"timestamp": 1631389262400, "ltp": 1.41, "tv": 65120.41, "trd": NaN, "batb": [[0, 1.4, 4465.28]], "batl": NaN}, {"timestamp": 1631389386720, "ltp": 1.41, "tv": 65120.41, "trd": NaN, "batb": [[0, 1.4, 4477.62]], "batl": NaN}, {"timestamp": 1631389508353, "ltp": 1.41, "tv": 65120.41, "trd": NaN, "batb": [[0, 1.4, 4481.32]], "batl": NaN}, {"timestamp": 1631389575844, "ltp": 1.41, "tv": 65120.41, "trd": NaN, "batb": [[0, 1.4, 4493.32]], "batl": NaN}, {"timestamp": 1631389577046, "ltp": 1.41, "tv": 65120.41, "trd": NaN, "batb": [[1, 1.39, 6654.8]], "batl": NaN}, {"timestamp": 1631389768578, "ltp": 1.41, "tv": 65120.41, "trd": NaN, "batb": [[0, 1.4, 4542.41]], "batl": NaN}, {"timestamp": 1631389768946, "ltp": 1.41, "tv": 65120.41, "trd": NaN, "batb": [[0, 1.4, 4493.32]], "batl": NaN}, {"timestamp": 1631390170222, "ltp": 1.41, "tv": 65164.41, "trd": [[1.41, 18008.87]], "batb": NaN, "batl": [[0, 1.41, 6246.78]]}, {"timestamp": 1631390543343, "ltp": 1.41, "tv": 65224.41, "trd": [[1.41, 18068.87]], "batb": NaN, "batl": [[0, 1.41, 6216.78]]}, {"timestamp": 1631390692607, "ltp": 1.4, "tv": 65264.41, "trd": [[1.4, 482.93]], "batb": [[0, 1.4, 4473.32]], "batl": NaN}, {"timestamp": 1631390718495, "ltp": 1.4, "tv": 65264.41, "trd": NaN, "batb": [[0, 1.4, 4497.71]], "batl": NaN}, {"timestamp": 1631390718807, "ltp": 1.4, "tv": 65264.41, "trd": NaN, "batb": [[0, 1.4, 4473.32]], "batl": NaN}, {"timestamp": 1631390822508, "ltp": 1.4, "tv": 65264.41, "trd": NaN, "batb": [[0, 1.4, 5315.37]], "batl": NaN}, {"timestamp": 1631390822932, "ltp": 1.4, "tv": 65264.41, "trd": NaN, "batb": [[0, 1.4, 4473.32]], "batl": NaN}, {"timestamp": 1631390888631, "ltp": 1.4, "tv": 65287.27, "trd": [[1.4, 505.8]], "batb": [[0, 1.4, 4461.89]], "batl": NaN}, {"timestamp": 1631391019547, "ltp": 1.41, "tv": 65306.05, "trd": [[1.41, 18087.66]], "batb": NaN, "batl": [[0, 1.41, 6207.39]]}, {"timestamp": 1631391101526, "ltp": 1.41, "tv": 65306.05, "trd": NaN, "batb": [[1, 1.39, 6782.91]], "batl": [[1, 1.42, 454.59]]}, {"timestamp": 1631391103910, "ltp": 1.41, "tv": 65343.63, "trd": [[1.41, 18125.24]], "batb": NaN, "batl": [[0, 1.41, 6188.6]]}, {"timestamp": 1631391182006, "ltp": 1.4, "tv": 69343.64, "trd": [[1.4, 4505.8]], "batb": [[0, 1.4, 2461.89]], "batl": NaN}, {"timestamp": 1631391197409, "ltp": 1.4, "tv": 69343.64, "trd": NaN, "batb": [[2, 1.38, 11868.74]], "batl": NaN}, {"timestamp": 1631391265473, "ltp": 1.4, "tv": 69343.64, "trd": NaN, "batb": [[0, 1.4, 2445.85]], "batl": NaN}, {"timestamp": 1631391266584, "ltp": 1.4, "tv": 69343.64, "trd": NaN, "batb": [[0, 1.4, 2366.42]], "batl": NaN}, {"timestamp": 1631391267492, "ltp": 1.4, "tv": 69343.64, "trd": NaN, "batb": [[0, 1.4, 2260.31]], "batl": [[1, 1.42, 508.13]]}, {"timestamp": 1631391282199, "ltp": 1.41, "tv": 69415.31, "trd": [[1.41, 18196.91]], "batb": NaN, "batl": [[0, 1.41, 6152.76]]}, {"timestamp": 1631391389570, "ltp": 1.41, "tv": 69415.31, "trd": NaN, "batb": [[0, 1.4, 2162.6]], "batl": NaN}, {"timestamp": 1631391390404, "ltp": 1.41, "tv": 69415.31, "trd": NaN, "batb": NaN, "batl": [[1, 1.42, 514.99]]}, {"timestamp": 1631391402298, "ltp": 1.41, "tv": 69415.31, "trd": NaN, "batb": [[0, 1.4, 2110.51]], "batl": [[2, 1.43, 883.7]]}, {"timestamp": 1631391513385, "ltp": 1.41, "tv": 69415.31, "trd": NaN, "batb": [[0, 1.4, 2088.81]], "batl": NaN}, {"timestamp": 1631391515695, "ltp": 1.4, "tv": 70382.79, "trd": [[1.4, 5473.27]], "batb": [[0, 1.4, 1605.06]], "batl": NaN}, {"timestamp": 1631391517585, "ltp": 1.4, "tv": 70382.79, "trd": NaN, "batb": NaN, "batl": [[2, 1.43, 800]]}, {"timestamp": 1631391518487, "ltp": 1.4, "tv": 70382.79, "trd": NaN, "batb": [[1, 1.39, 6904.18]], "batl": [[1, 1.42, 591.86]]}, {"timestamp": 1631391520687, "ltp": 1.4, "tv": 71350.25, "trd": [[1.4, 6440.73]], "batb": [[0, 1.4, 1121.33]], "batl": NaN}, {"timestamp": 1631391521684, "ltp": 1.4, "tv": 71350.25, "trd": NaN, "batb": [[1, 1.39, 6927.38]], "batl": NaN}, {"timestamp": 1631391529731, "ltp": 1.4, "tv": 72317.7, "trd": [[1.4, 7408.19]], "batb": [[0, 1.4, 637.6]], "batl": NaN}, {"timestamp": 1631391623599, "ltp": 1.4, "tv": 72317.7, "trd": NaN, "batb": [[0, 1.4, 803.09]], "batl": [[1, 1.42, 758.49]]}, {"timestamp": 1631391625074, "ltp": 1.4, "tv": 72317.7, "trd": NaN, "batb": NaN, "batl": [[0, 1.41, 6280.41]]}, {"timestamp": 1631391742048, "ltp": 1.4, "tv": 72317.7, "trd": NaN, "batb": NaN, "batl": [[1, 1.42, 762]]}, {"timestamp": 1631391783701, "ltp": 1.4, "tv": 72317.7, "trd": NaN, "batb": [[1, 1.39, 7306.58]], "batl": NaN}, {"timestamp": 1631392008604, "ltp": 1.4, "tv": 72317.7, "trd": NaN, "batb": [[0, 1.4, 1408.88]], "batl": NaN}, {"timestamp": 1631392008929, "ltp": 1.4, "tv": 72317.7, "trd": NaN, "batb": [[0, 1.4, 803.09]], "batl": NaN}, {"timestamp": 1631392295151, "ltp": 1.4, "tv": 72317.7, "trd": NaN, "batb": [[1, 1.39, 7371.58]], "batl": NaN}, {"timestamp": 1631392295986, "ltp": 1.4, "tv": 72317.7, "trd": NaN, "batb": [[0, 1.4, 2511.17]], "batl": NaN}, {"timestamp": 1631392364669, "ltp": 1.4, "tv": 72317.7, "trd": NaN, "batb": [[0, 1.4, 3362.35]], "batl": [[0, 1.41, 6152.76]]}, {"timestamp": 1631392364775, "ltp": 1.4, "tv": 72317.7, "trd": NaN, "batb": [[0, 1.4, 2756.56]], "batl": NaN}, {"timestamp": 1631392385785, "ltp": 1.4, "tv": 72317.7, "trd": NaN, "batb": [[0, 1.4, 2757.07]], "batl": NaN}, {"timestamp": 1631392404660, "ltp": 1.4, "tv": 72327.7, "trd": [[1.4, 7418.19]], "batb": [[0, 1.4, 2752.07]], "batl": NaN}, {"timestamp": 1631392425596, "ltp": 1.4, "tv": 72327.7, "trd": NaN, "batb": [[0, 1.4, 2825.01]], "batl": NaN}, {"timestamp": 1631392467812, "ltp": 1.4, "tv": 72327.7, "trd": NaN, "batb": [[0, 1.4, 3160.01]], "batl": NaN}, {"timestamp": 1631392469727, "ltp": 1.4, "tv": 72327.7, "trd": NaN, "batb": [[1, 1.39, 7715.17]], "batl": NaN}, {"timestamp": 1631392471809, "ltp": 1.4, "tv": 72327.7, "trd": NaN, "batb": [[2, 1.38, 12221.37]], "batl": NaN}, {"timestamp": 1631392484459, "ltp": 1.4, "tv": 72327.7, "trd": NaN, "batb": [[0, 1.4, 3232.15]], "batl": NaN}, {"timestamp": 1631392543524, "ltp": 1.4, "tv": 72327.7, "trd": NaN, "batb": [[0, 1.4, 3253.79]], "batl": NaN}, {"timestamp": 1631392603285, "ltp": 1.4, "tv": 72327.7, "trd": NaN, "batb": [[0, 1.4, 3260.28]], "batl": NaN}, {"timestamp": 1631392640147, "ltp": 1.4, "tv": 72327.7, "trd": NaN, "batb": NaN, "batl": [[0, 1.41, 8705.41]]}, {"timestamp": 1631392867639, "ltp": 1.4, "tv": 72341.85, "trd": [[1.4, 7432.33]], "batb": [[0, 1.4, 3253.21]], "batl": NaN}, {"timestamp": 1631392933680, "ltp": 1.41, "tv": 72344.6, "trd": [[1.41, 18199.67]], "batb": NaN, "batl": [[0, 1.41, 8704.03]]}, {"timestamp": 1631392948724, "ltp": 1.4, "tv": 72441.35, "trd": [[1.4, 7529.07]], "batb": [[0, 1.4, 3204.84]], "batl": NaN}, {"timestamp": 1631393252495, "ltp": 1.4, "tv": 72441.35, "trd": NaN, "batb": [[0, 1.4, 3810.63]], "batl": NaN}, {"timestamp": 1631393252803, "ltp": 1.4, "tv": 72441.35, "trd": NaN, "batb": [[0, 1.4, 3204.84]], "batl": NaN}, {"timestamp": 1631393314513, "ltp": 1.41, "tv": 72448.18, "trd": [[1.41, 18206.51]], "batb": NaN, "batl": [[0, 1.41, 8700.61]]}, {"timestamp": 1631393452219, "ltp": 1.41, "tv": 72448.18, "trd": NaN, "batb": [[0, 1.4, 3219.88]], "batl": NaN}, {"timestamp": 1631393507506, "ltp": 1.41, "tv": 72448.18, "trd": NaN, "batb": [[0, 1.4, 3884.92]], "batl": NaN}, {"timestamp": 1631393507764, "ltp": 1.41, "tv": 72448.18, "trd": NaN, "batb": [[0, 1.4, 3219.88]], "batl": NaN}, {"timestamp": 1631393562476, "ltp": 1.41, "tv": 72448.18, "trd": NaN, "batb": [[0, 1.4, 3198.35]], "batl": NaN}, {"timestamp": 1631393563610, "ltp": 1.41, "tv": 72448.18, "trd": NaN, "batb": [[0, 1.4, 3122.1]], "batl": NaN}, {"timestamp": 1631393564385, "ltp": 1.41, "tv": 72448.18, "trd": NaN, "batb": NaN, "batl": [[0, 1.41, 8854.57]]}, {"timestamp": 1631393584315, "ltp": 1.4, "tv": 72481.24, "trd": [[1.4, 7562.14]], "batb": [[0, 1.4, 3105.57]], "batl": NaN}, {"timestamp": 1631393757046, "ltp": 1.41, "tv": 72525.66, "trd": [[1.41, 18250.92]], "batb": NaN, "batl": [[0, 1.41, 8832.36]]}, {"timestamp": 1631393760489, "ltp": 1.41, "tv": 72525.66, "trd": NaN, "batb": NaN, "batl": [[0, 1.41, 11385.01]]}, {"timestamp": 1631393988726, "ltp": 1.41, "tv": 72694.86, "trd": [[1.41, 18420.12]], "batb": NaN, "batl": [[0, 1.41, 11300.41]]}, {"timestamp": 1631394017789, "ltp": 1.41, "tv": 72694.89, "trd": [[1.41, 18420.16]], "batb": NaN, "batl": [[0, 1.41, 11300.39]]}, {"timestamp": 1631394123463, "ltp": 1.41, "tv": 72703.43, "trd": [[1.41, 18428.7]], "batb": NaN, "batl": [[0, 1.41, 11296.12]]}, {"timestamp": 1631394199978, "ltp": 1.4, "tv": 73503.43, "trd": [[1.4, 8362.14]], "batb": [[0, 1.4, 2705.57]], "batl": NaN}, {"timestamp": 1631394228271, "ltp": 1.4, "tv": 73823.43, "trd": [[1.4, 8682.14]], "batb": [[0, 1.4, 2545.57]], "batl": NaN}, {"timestamp": 1631394260424, "ltp": 1.41, "tv": 73837.1, "trd": [[1.41, 18442.36]], "batb": NaN, "batl": [[0, 1.41, 11289.29]]}, {"timestamp": 1631394377188, "ltp": 1.41, "tv": 73837.1, "trd": NaN, "batb": [[0, 1.4, 2528.05]], "batl": NaN}, {"timestamp": 1631394401836, "ltp": 1.41, "tv": 73922.5, "trd": [[1.41, 18527.76]], "batb": NaN, "batl": [[0, 1.41, 11246.59]]}, {"timestamp": 1631394487662, "ltp": 1.41, "tv": 73922.84, "trd": [[1.41, 18528.1]], "batb": NaN, "batl": [[0, 1.41, 11246.42]]}, {"timestamp": 1631394582747, "ltp": 1.41, "tv": 73922.84, "trd": NaN, "batb": [[1, 1.39, 7868.23]], "batl": NaN}, {"timestamp": 1631394675995, "ltp": 1.41, "tv": 73965.54, "trd": [[1.41, 18570.8]], "batb": NaN, "batl": [[0, 1.41, 11225.07]]}, {"timestamp": 1631394707378, "ltp": 1.41, "tv": 73996.28, "trd": [[1.41, 18601.55]], "batb": NaN, "batl": [[0, 1.41, 11209.7]]}, {"timestamp": 1631394850206, "ltp": 1.41, "tv": 73996.28, "trd": NaN, "batb": [[1, 1.39, 8295.25]], "batl": NaN}, {"timestamp": 1631394971583, "ltp": 1.41, "tv": 74081.69, "trd": [[1.41, 18686.95]], "batb": NaN, "batl": [[0, 1.41, 11167]]}, {"timestamp": 1631394987430, "ltp": 1.41, "tv": 74091.77, "trd": [[1.41, 18697.03]], "batb": NaN, "batl": [[0, 1.41, 11161.96]]}, {"timestamp": 1631395033589, "ltp": 1.41, "tv": 74091.77, "trd": NaN, "batb": [[0, 1.4, 3133.84]], "batl": NaN}, {"timestamp": 1631395033900, "ltp": 1.41, "tv": 74433.38, "trd": [[1.41, 19038.65]], "batb": [[0, 1.4, 2528.05]], "batl": [[0, 1.41, 10991.15]]}, {"timestamp": 1631395117413, "ltp": 1.41, "tv": 74433.38, "trd": NaN, "batb": [[0, 1.4, 2540.68]], "batl": NaN}, {"timestamp": 1631395168739, "ltp": 1.41, "tv": 74433.38, "trd": NaN, "batb": [[0, 1.4, 3263.69]], "batl": NaN}, {"timestamp": 1631395174996, "ltp": 1.4, "tv": 74476.73, "trd": [[1.4, 8725.48]], "batb": [[0, 1.4, 3242.02]], "batl": NaN}, {"timestamp": 1631395198715, "ltp": 1.4, "tv": 74476.73, "trd": NaN, "batb": [[0, 1.4, 3269.95]], "batl": [[0, 1.41, 11001.52]]}, {"timestamp": 1631395237552, "ltp": 1.4, "tv": 74476.73, "trd": NaN, "batb": [[0, 1.4, 3398.52]], "batl": NaN}, {"timestamp": 1631395238434, "ltp": 1.4, "tv": 74876.74, "trd": [[1.4, 9125.49]], "batb": [[0, 1.4, 3198.51]], "batl": NaN}, {"timestamp": 1631395322699, "ltp": 1.4, "tv": 74876.74, "trd": NaN, "batb": [[0, 1.4, 3861.74]], "batl": [[0, 1.41, 11086.39]]}, {"timestamp": 1631395323582, "ltp": 1.4, "tv": 74876.74, "trd": NaN, "batb": [[0, 1.4, 3255.95]], "batl": NaN}, {"timestamp": 1631395402021, "ltp": 1.4, "tv": 74876.74, "trd": NaN, "batb": [[0, 1.4, 3405.95]], "batl": NaN}, {"timestamp": 1631395403732, "ltp": 1.4, "tv": 74876.74, "trd": NaN, "batb": [[0, 1.4, 3255.95]], "batl": NaN}, {"timestamp": 1631395412407, "ltp": 1.4, "tv": 74876.74, "trd": NaN, "batb": [[0, 1.4, 3505.95]], "batl": NaN}, {"timestamp": 1631395429378, "ltp": 1.41, "tv": 74962.14, "trd": [[1.41, 19124.05]], "batb": NaN, "batl": [[0, 1.41, 11043.69]]}, {"timestamp": 1631395471813, "ltp": 1.4, "tv": 74983.41, "trd": [[1.4, 9146.76]], "batb": [[0, 1.4, 3495.32]], "batl": NaN}, {"timestamp": 1631395508068, "ltp": 1.4, "tv": 74983.41, "trd": NaN, "batb": [[0, 1.4, 4228.32]], "batl": NaN}, {"timestamp": 1631395575777, "ltp": 1.4, "tv": 74983.41, "trd": NaN, "batb": [[0, 1.4, 4300.62]], "batl": NaN}, {"timestamp": 1631395591941, "ltp": 1.4, "tv": 74983.41, "trd": NaN, "batb": [[0, 1.4, 4228.32]], "batl": NaN}, {"timestamp": 1631395596019, "ltp": 1.4, "tv": 74983.41, "trd": NaN, "batb": [[0, 1.4, 10633.65]], "batl": NaN}, {"timestamp": 1631395615394, "ltp": 1.4, "tv": 74983.41, "trd": NaN, "batb": NaN, "batl": [[0, 1.41, 833.1], [1, 1.42, 10972.6]]}, {"timestamp": 1631395692147, "ltp": 1.4, "tv": 74983.41, "trd": NaN, "batb": NaN, "batl": [[0, 1.41, 748.22]]}, {"timestamp": 1631395693427, "ltp": 1.4, "tv": 74983.41, "trd": NaN, "batb": NaN, "batl": [[0, 1.41, 708.86]]}, {"timestamp": 1631395806516, "ltp": 1.4, "tv": 74983.41, "trd": NaN, "batb": NaN, "batl": [[0, 1.41, 690.23]]}, {"timestamp": 1631395878921, "ltp": 1.41, "tv": 75237.86, "trd": [[1.41, 19378.49]], "batb": NaN, "batl": [[0, 1.41, 5.22]]}, {"timestamp": 1631395889935, "ltp": 1.41, "tv": 75248.3, "trd": [[1.41, 19388.93]], "batb": [[0, 1.41, 680.43], [1, 1.4, 10633.65], [2, 1.39, 8295.25]], "batl": [[0, 1.42, 11057.12], [1, 1.43, 800], [2, 1.44, 484.85]]}, {"timestamp": 1631395921613, "ltp": 1.41, "tv": 75248.3, "trd": NaN, "batb": [[2, 1.39, 7843.22]], "batl": NaN}, {"timestamp": 1631395928398, "ltp": 1.41, "tv": 75248.3, "trd": NaN, "batb": [[1, 1.4, 10681.71]], "batl": [[1, 1.43, 1249.78]]}, {"timestamp": 1631396055606, "ltp": 1.41, "tv": 75251.06, "trd": [[1.41, 19391.69]], "batb": [[0, 1.41, 679.05]], "batl": NaN}, {"timestamp": 1631396116781, "ltp": 1.41, "tv": 75251.06, "trd": NaN, "batb": [[0, 1.41, 688.65]], "batl": NaN}, {"timestamp": 1631396151764, "ltp": 1.41, "tv": 75251.06, "trd": NaN, "batb": [[0, 1.41, 1421.65]], "batl": NaN}, {"timestamp": 1631396158468, "ltp": 1.41, "tv": 75251.06, "trd": NaN, "batb": NaN, "batl": [[0, 1.42, 10972.6]]}, {"timestamp": 1631396175611, "ltp": 1.41, "tv": 75251.06, "trd": NaN, "batb": NaN, "batl": [[1, 1.43, 1158.85]]}, {"timestamp": 1631396181420, "ltp": 1.41, "tv": 75251.06, "trd": NaN, "batb": [[1, 1.4, 10431.71]], "batl": NaN}, {"timestamp": 1631396274530, "ltp": 1.41, "tv": 75251.06, "trd": NaN, "batb": [[2, 1.39, 7721.94]], "batl": [[0, 1.42, 10895.73]]}, {"timestamp": 1631396275048, "ltp": 1.41, "tv": 75251.06, "trd": NaN, "batb": [[1, 1.4, 10516.26]], "batl": [[1, 1.43, 1244.26]]}, {"timestamp": 1631396423768, "ltp": 1.42, "tv": 75269.85, "trd": [[1.42, 19677.94]], "batb": NaN, "batl": [[0, 1.42, 10886.33]]}, {"timestamp": 1631396482843, "ltp": 1.42, "tv": 75355.25, "trd": [[1.42, 19763.34]], "batb": NaN, "batl": [[0, 1.42, 10843.63]]}, {"timestamp": 1631396559845, "ltp": 1.42, "tv": 75355.25, "trd": NaN, "batb": NaN, "batl": [[2, 1.44, 618.85]]}, {"timestamp": 1631396687638, "ltp": 1.42, "tv": 75421.87, "trd": [[1.42, 19829.96]], "batb": NaN, "batl": [[0, 1.42, 10810.32]]}, {"timestamp": 1631396702661, "ltp": 1.42, "tv": 75421.87, "trd": NaN, "batb": [[0, 1.41, 5759.73]], "batl": NaN}, {"timestamp": 1631396793093, "ltp": 1.42, "tv": 75421.87, "trd": NaN, "batb": [[2, 1.39, 7342.75]], "batl": NaN}, {"timestamp": 1631396801425, "ltp": 1.42, "tv": 75421.87, "trd": NaN, "batb": [[0, 1.41, 7205.76]], "batl": NaN}, {"timestamp": 1631397053975, "ltp": 1.42, "tv": 75462.86, "trd": [[1.42, 19870.95]], "batb": NaN, "batl": [[0, 1.42, 10789.83]]}, {"timestamp": 1631397057578, "ltp": 1.41, "tv": 75862.86, "trd": [[1.41, 19791.69]], "batb": [[0, 1.41, 7005.76]], "batl": NaN}, {"timestamp": 1631397127686, "ltp": 1.42, "tv": 76286.47, "trd": [[1.42, 20294.56]], "batb": NaN, "batl": [[0, 1.42, 10578.02]]}, {"timestamp": 1631397155626, "ltp": 1.42, "tv": 76286.47, "trd": NaN, "batb": NaN, "batl": [[0, 1.42, 10790.73]]}, {"timestamp": 1631397281115, "ltp": 1.42, "tv": 76286.47, "trd": NaN, "batb": NaN, "batl": [[1, 1.43, 1221.47]]}, {"timestamp": 1631397286134, "ltp": 1.41, "tv": 76303.57, "trd": [[1.41, 19808.79]], "batb": [[0, 1.41, 6997.21]], "batl": NaN}, {"timestamp": 1631397326851, "ltp": 1.41, "tv": 76303.57, "trd": NaN, "batb": [[1, 1.4, 14854.34]], "batl": NaN}, {"timestamp": 1631397410245, "ltp": 1.41, "tv": 76303.57, "trd": NaN, "batb": [[2, 1.39, 10234.08]], "batl": NaN}, {"timestamp": 1631398320344, "ltp": 1.42, "tv": 76363.57, "trd": [[1.42, 20354.56]], "batb": NaN, "batl": [[0, 1.42, 10760.73]]}, {"timestamp": 1631398339081, "ltp": 1.42, "tv": 76406.95, "trd": [[1.42, 20397.94]], "batb": NaN, "batl": [[0, 1.42, 10739.04]]}, {"timestamp": 1631398353018, "ltp": 1.42, "tv": 76406.95, "trd": NaN, "batb": [[0, 1.41, 7720.22]], "batl": NaN}, {"timestamp": 1631398383762, "ltp": 1.41, "tv": 76506.95, "trd": [[1.41, 19908.79]], "batb": [[0, 1.41, 7670.22]], "batl": NaN}, {"timestamp": 1631398386589, "ltp": 1.41, "tv": 76506.95, "trd": NaN, "batb": NaN, "batl": [[0, 1.42, 10747.81]]}, {"timestamp": 1631398447257, "ltp": 1.41, "tv": 76506.95, "trd": NaN, "batb": [[1, 1.4, 14769.79], [2, 1.39, 10362.18]], "batl": NaN}, {"timestamp": 1631398485436, "ltp": 1.42, "tv": 76549.66, "trd": [[1.42, 20440.64]], "batb": NaN, "batl": [[0, 1.42, 10726.46]]}, {"timestamp": 1631398499135, "ltp": 1.42, "tv": 76549.66, "trd": NaN, "batb": NaN, "batl": [[2, 1.44, 484.85]]}, {"timestamp": 1631398505165, "ltp": 1.41, "tv": 76589.66, "trd": [[1.41, 19948.79]], "batb": [[0, 1.41, 7650.22]], "batl": NaN}, {"timestamp": 1631398506669, "ltp": 1.41, "tv": 76589.66, "trd": NaN, "batb": [[0, 1.41, 7977.05]], "batl": NaN}, {"timestamp": 1631398526311, "ltp": 1.41, "tv": 76596.1, "trd": [[1.41, 19955.23]], "batb": [[0, 1.41, 7973.83]], "batl": NaN}, {"timestamp": 1631398526987, "ltp": 1.41, "tv": 76619.28, "trd": [[1.41, 19978.41]], "batb": [[0, 1.41, 7962.24]], "batl": NaN}, {"timestamp": 1631398535389, "ltp": 1.41, "tv": 77031.72, "trd": [[1.41, 20390.85]], "batb": [[0, 1.41, 7756.02]], "batl": NaN}, {"timestamp": 1631398547594, "ltp": 1.41, "tv": 77031.72, "trd": NaN, "batb": [[0, 1.41, 7856.02]], "batl": NaN}, {"timestamp": 1631398551020, "ltp": 1.42, "tv": 77335.39, "trd": [[1.42, 20744.31]], "batb": NaN, "batl": [[0, 1.42, 10574.62]]}, {"timestamp": 1631398579618, "ltp": 1.42, "tv": 77335.39, "trd": NaN, "batb": [[0, 1.41, 8381.02]], "batl": NaN}, {"timestamp": 1631398646015, "ltp": 1.41, "tv": 78787.26, "trd": [[1.41, 21842.72]], "batb": [[0, 1.41, 7655.09]], "batl": NaN}, {"timestamp": 1631398662624, "ltp": 1.41, "tv": 79110.2, "trd": [[1.41, 22165.66]], "batb": [[0, 1.41, 7493.62]], "batl": NaN}, {"timestamp": 1631398682175, "ltp": 1.41, "tv": 79110.2, "trd": NaN, "batb": [[0, 1.41, 9983.7]], "batl": NaN}, {"timestamp": 1631398691582, "ltp": 1.41, "tv": 79110.2, "trd": NaN, "batb": [[1, 1.4, 14902.17]], "batl": [[1, 1.43, 1353.84]]}, {"timestamp": 1631398721637, "ltp": 1.41, "tv": 79110.2, "trd": NaN, "batb": [[0, 1.41, 10019.64]], "batl": NaN}, {"timestamp": 1631398722312, "ltp": 1.41, "tv": 79110.2, "trd": NaN, "batb": NaN, "batl": [[0, 1.42, 10662.62], [1, 1.43, 1363.89]]}, {"timestamp": 1631398729826, "ltp": 1.41, "tv": 79110.2, "trd": NaN, "batb": NaN, "batl": [[0, 1.42, 13215.27]]}, {"timestamp": 1631398747656, "ltp": 1.41, "tv": 79110.2, "trd": NaN, "batb": [[0, 1.41, 11727.73]], "batl": NaN}, {"timestamp": 1631398890884, "ltp": 1.42, "tv": 79178.2, "trd": [[1.42, 20812.32]], "batb": NaN, "batl": [[0, 1.42, 13181.27]]}, {"timestamp": 1631398937011, "ltp": 1.42, "tv": 79178.2, "trd": NaN, "batb": [[0, 1.41, 11855.38]], "batl": NaN}, {"timestamp": 1631398968175, "ltp": 1.42, "tv": 79178.2, "trd": NaN, "batb": [[0, 1.41, 11996.88]], "batl": NaN}, {"timestamp": 1631399048083, "ltp": 1.42, "tv": 79178.2, "trd": NaN, "batb": [[0, 1.41, 12007.5], [2, 1.39, 10338.99]], "batl": NaN}, {"timestamp": 1631399062614, "ltp": 1.42, "tv": 79178.2, "trd": NaN, "batb": [[0, 1.41, 12012.5]], "batl": NaN}, {"timestamp": 1631399071928, "ltp": 1.42, "tv": 79178.2, "trd": NaN, "batb": [[0, 1.41, 12017.5]], "batl": NaN}, {"timestamp": 1631399077030, "ltp": 1.42, "tv": 79178.2, "trd": NaN, "batb": NaN, "batl": [[0, 1.42, 15681.27]]}, {"timestamp": 1631399090998, "ltp": 1.41, "tv": 79478.2, "trd": [[1.41, 22465.66]], "batb": [[0, 1.41, 11867.5]], "batl": NaN}, {"timestamp": 1631399110612, "ltp": 1.41, "tv": 79478.2, "trd": NaN, "batb": NaN, "batl": [[1, 1.43, 1328.99]]}, {"timestamp": 1631399128532, "ltp": 1.41, "tv": 79478.2, "trd": NaN, "batb": NaN, "batl": [[1, 1.43, 1466.37]]}, {"timestamp": 1631399149079, "ltp": 1.41, "tv": 79692.08, "trd": [[1.41, 22679.54]], "batb": [[0, 1.41, 11760.56]], "batl": NaN}, {"timestamp": 1631399201673, "ltp": 1.41, "tv": 79692.08, "trd": NaN, "batb": [[0, 1.41, 11770.47]], "batl": [[0, 1.42, 15661.7]]}, {"timestamp": 1631399202557, "ltp": 1.41, "tv": 79692.08, "trd": NaN, "batb": NaN, "batl": [[1, 1.43, 1481.74]]}, {"timestamp": 1631399491975, "ltp": 1.41, "tv": 79859.56, "trd": [[1.41, 22847.02]], "batb": [[0, 1.41, 11686.73]], "batl": NaN}, {"timestamp": 1631399618298, "ltp": 1.41, "tv": 80062.0, "trd": [[1.41, 23049.46]], "batb": [[0, 1.41, 11585.5]], "batl": NaN}, {"timestamp": 1631399712705, "ltp": 1.42, "tv": 80072.64, "trd": [[1.42, 20822.95]], "batb": NaN, "batl": [[0, 1.42, 15656.38]]}, {"timestamp": 1631399722910, "ltp": 1.42, "tv": 80072.64, "trd": NaN, "batb": [[0, 1.41, 11588.21]], "batl": NaN}, {"timestamp": 1631399756537, "ltp": 1.42, "tv": 80072.64, "trd": NaN, "batb": NaN, "batl": [[0, 1.42, 15686.38]]}, {"timestamp": 1631399758026, "ltp": 1.42, "tv": 80072.64, "trd": NaN, "batb": NaN, "batl": [[1, 1.43, 1511.74]]}, {"timestamp": 1631399759361, "ltp": 1.42, "tv": 80072.64, "trd": NaN, "batb": NaN, "batl": [[2, 1.44, 514.85]]}, {"timestamp": 1631399762145, "ltp": 1.41, "tv": 80100.64, "trd": [[1.41, 23077.46]], "batb": [[0, 1.41, 11574.21]], "batl": NaN}, {"timestamp": 1631399766159, "ltp": 1.41, "tv": 80100.64, "trd": NaN, "batb": [[0, 1.41, 11604.21]], "batl": NaN}, {"timestamp": 1631399767658, "ltp": 1.41, "tv": 80100.64, "trd": NaN, "batb": [[1, 1.4, 14932.17]], "batl": NaN}, {"timestamp": 1631399769669, "ltp": 1.41, "tv": 81400.64, "trd": [[1.41, 24377.46]], "batb": [[0, 1.41, 10954.2], [2, 1.39, 10368.99]], "batl": NaN}, {"timestamp": 1631399786672, "ltp": 1.41, "tv": 81406.12, "trd": [[1.41, 24382.95]], "batb": [[0, 1.41, 10951.46]], "batl": NaN}, {"timestamp": 1631399807244, "ltp": 1.41, "tv": 81718.12, "trd": [[1.41, 24694.94]], "batb": [[0, 1.41, 10795.47]], "batl": NaN}, {"timestamp": 1631399825051, "ltp": 1.41, "tv": 81718.12, "trd": NaN, "batb": NaN, "batl": [[0, 1.42, 15689.07], [1, 1.43, 1518.55]]}, {"timestamp": 1631399865003, "ltp": 1.42, "tv": 81897.13, "trd": [[1.42, 21001.97]], "batb": NaN, "batl": [[0, 1.42, 15599.56]]}, {"timestamp": 1631399904587, "ltp": 1.42, "tv": 81897.13, "trd": NaN, "batb": [[0, 1.41, 10840.9]], "batl": [[0, 1.42, 15644.71]]}, {"timestamp": 1631399933705, "ltp": 1.41, "tv": 81908.7, "trd": [[1.41, 24706.51]], "batb": [[0, 1.41, 10835.12]], "batl": NaN}, {"timestamp": 1631399978468, "ltp": 1.41, "tv": 81908.7, "trd": NaN, "batb": [[0, 1.41, 11317.12]], "batl": NaN}, {"timestamp": 1631399981411, "ltp": 1.41, "tv": 82018.7, "trd": [[1.41, 24816.51]], "batb": [[0, 1.41, 11262.12]], "batl": NaN}, {"timestamp": 1631399992013, "ltp": 1.41, "tv": 82058.7, "trd": [[1.41, 24856.51]], "batb": [[0, 1.41, 11242.12]], "batl": NaN}, {"timestamp": 1631399994399, "ltp": 1.41, "tv": 82068.7, "trd": [[1.41, 24866.51]], "batb": [[0, 1.41, 11250.83]], "batl": [[0, 1.42, 15631.32]]}, {"timestamp": 1631399996716, "ltp": 1.41, "tv": 82072.7, "trd": [[1.41, 24870.51]], "batb": [[0, 1.41, 11248.83]], "batl": NaN}, {"timestamp": 1631400060398, "ltp": 1.41, "tv": 83072.7, "trd": [[1.41, 25870.51]], "batb": [[0, 1.41, 10748.83]], "batl": NaN}, {"timestamp": 1631400100662, "ltp": 1.41, "tv": 83072.7, "trd": NaN, "batb": [[0, 1.41, 10769.35]], "batl": [[0, 1.42, 15611.29]]}, {"timestamp": 1631400106409, "ltp": 1.41, "tv": 83112.7, "trd": [[1.41, 25910.51]], "batb": [[0, 1.41, 10749.35]], "batl": NaN}, {"timestamp": 1631400122751, "ltp": 1.41, "tv": 83112.7, "trd": NaN, "batb": NaN, "batl": [[2, 1.44, 2306.48]]}, {"timestamp": 1631400138339, "ltp": 1.41, "tv": 83112.7, "trd": NaN, "batb": [[0, 1.41, 15873.61]], "batl": NaN}, {"timestamp": 1631400139475, "ltp": 1.41, "tv": 83152.7, "trd": [[1.41, 25950.51]], "batb": [[0, 1.41, 16576.63]], "batl": NaN}, {"timestamp": 1631400157396, "ltp": 1.41, "tv": 83152.7, "trd": NaN, "batb": [[0, 1.41, 17661.15]], "batl": NaN}, {"timestamp": 1631400157907, "ltp": 1.41, "tv": 83152.7, "trd": NaN, "batb": [[0, 1.41, 17672.51]], "batl": NaN}, {"timestamp": 1631400182532, "ltp": 1.41, "tv": 83152.7, "trd": NaN, "batb": NaN, "batl": [[1, 1.43, 1511.74]]}, {"timestamp": 1631400200827, "ltp": 1.42, "tv": 83160.96, "trd": [[1.42, 21010.23]], "batb": NaN, "batl": [[0, 1.42, 15607.16]]}, {"timestamp": 1631400223236, "ltp": 1.42, "tv": 83168.68, "trd": [[1.42, 21017.94]], "batb": NaN, "batl": [[0, 1.42, 15603.3]]}, {"timestamp": 1631400240940, "ltp": 1.41, "tv": 83668.68, "trd": [[1.41, 26450.52]], "batb": [[0, 1.41, 17422.5]], "batl": NaN}, {"timestamp": 1631400260525, "ltp": 1.41, "tv": 83668.68, "trd": NaN, "batb": NaN, "batl": [[0, 1.42, 15609.36], [1, 1.43, 1522.34]]}, {"timestamp": 1631400290693, "ltp": 1.42, "tv": 84018.38, "trd": [[1.42, 21367.64]], "batb": NaN, "batl": [[0, 1.42, 15259.66]]}, {"timestamp": 1631400318059, "ltp": 1.41, "tv": 84092.38, "trd": [[1.41, 26524.51]], "batb": [[0, 1.41, 17385.51]], "batl": NaN}, {"timestamp": 1631400320643, "ltp": 1.41, "tv": 84092.38, "trd": NaN, "batb": [[1, 1.4, 15062.84], [2, 1.39, 10240.88]], "batl": [[1, 1.43, 1436.94], [2, 1.44, 2424.33]]}, {"timestamp": 1631400329153, "ltp": 1.41, "tv": 86092.38, "trd": [[1.41, 28524.51]], "batb": [[0, 1.41, 16385.51]], "batl": NaN}, {"timestamp": 1631400341259, "ltp": 1.41, "tv": 86092.38, "trd": NaN, "batb": [[0, 1.41, 16651.6]], "batl": [[0, 1.42, 15253.61]]}, {"timestamp": 1631400342454, "ltp": 1.41, "tv": 86092.38, "trd": NaN, "batb": NaN, "batl": [[0, 1.42, 15239.19]]}, {"timestamp": 1631400343691, "ltp": 1.41, "tv": 86092.38, "trd": NaN, "batb": NaN, "batl": [[0, 1.42, 15161.98]]}, {"timestamp": 1631400344569, "ltp": 1.41, "tv": 86092.38, "trd": NaN, "batb": NaN, "batl": [[0, 1.42, 15007.56], [1, 1.43, 1551.79]]}, {"timestamp": 1631400357478, "ltp": 1.41, "tv": 86092.38, "trd": NaN, "batb": NaN, "batl": [[2, 1.44, 3741.67]]}, {"timestamp": 1631400382107, "ltp": 1.41, "tv": 86466.38, "trd": [[1.41, 28898.51]], "batb": [[0, 1.41, 16464.6]], "batl": NaN}, {"timestamp": 1631400415184, "ltp": 1.41, "tv": 90966.37, "trd": [[1.41, 33398.51]], "batb": [[0, 1.41, 14214.6]], "batl": NaN}, {"timestamp": 1631400433722, "ltp": 1.41, "tv": 90966.37, "trd": NaN, "batb": NaN, "batl": [[2, 1.44, 6288.12]]}, {"timestamp": 1631400450005, "ltp": 1.41, "tv": 90966.37, "trd": NaN, "batb": [[0, 1.41, 9090.34], [2, 1.39, 15365.14]], "batl": NaN}, {"timestamp": 1631400459128, "ltp": 1.41, "tv": 90966.37, "trd": NaN, "batb": NaN, "batl": [[0, 1.42, 20131.83]]}, {"timestamp": 1631400474238, "ltp": 1.41, "tv": 90966.37, "trd": NaN, "batb": [[0, 1.41, 8005.82]], "batl": NaN}, {"timestamp": 1631400564619, "ltp": 1.42, "tv": 92093.74, "trd": [[1.42, 22495.01]], "batb": NaN, "batl": [[0, 1.42, 19568.13]]}, {"timestamp": 1631400856564, "ltp": 1.42, "tv": 92093.74, "trd": NaN, "batb": NaN, "batl": [[0, 1.42, 19573.08]]}, {"timestamp": 1631400903219, "ltp": 1.42, "tv": 92093.74, "trd": NaN, "batb": [[0, 1.41, 24072.62]], "batl": NaN}, {"timestamp": 1631401024676, "ltp": 1.42, "tv": 92093.74, "trd": NaN, "batb": NaN, "batl": [[0, 1.42, 19575.82]]}, {"timestamp": 1631401053943, "ltp": 1.42, "tv": 92093.74, "trd": NaN, "batb": NaN, "batl": [[0, 1.42, 14451.56]]}, {"timestamp": 1631401106655, "ltp": 1.42, "tv": 92093.74, "trd": NaN, "batb": NaN, "batl": [[2, 1.44, 6170.26]]}, {"timestamp": 1631401107125, "ltp": 1.42, "tv": 92093.74, "trd": NaN, "batb": [[1, 1.4, 14294.56]], "batl": [[1, 1.43, 1618.41]]}, {"timestamp": 1631401130185, "ltp": 1.41, "tv": 92113.74, "trd": [[1.41, 33418.51]], "batb": [[0, 1.41, 24062.63]], "batl": NaN}, {"timestamp": 1631401391912, "ltp": 1.41, "tv": 92959.71, "trd": [[1.41, 34264.48]], "batb": [[0, 1.41, 23639.64]], "batl": NaN}, {"timestamp": 1631401412108, "ltp": 1.41, "tv": 92979.71, "trd": [[1.41, 34284.48]], "batb": [[0, 1.41, 23629.64]], "batl": NaN}, {"timestamp": 1631401419221, "ltp": 1.41, "tv": 92979.71, "trd": NaN, "batb": NaN, "batl": [[0, 1.42, 2595.99], [1, 1.43, 13473.98]]}, {"timestamp": 1631401426768, "ltp": 1.41, "tv": 92979.71, "trd": NaN, "batb": NaN, "batl": [[0, 1.42, 95.99]]}, {"timestamp": 1631401428769, "ltp": 1.41, "tv": 92979.71, "trd": NaN, "batb": NaN, "batl": [[1, 1.43, 15973.98]]}, {"timestamp": 1631401436986, "ltp": 1.41, "tv": 92979.71, "trd": NaN, "batb": NaN, "batl": [[2, 1.44, 11294.52]]}, {"timestamp": 1631401443693, "ltp": 1.41, "tv": 92979.71, "trd": NaN, "batb": [[2, 1.39, 10240.88]], "batl": NaN}, {"timestamp": 1631401443899, "ltp": 1.41, "tv": 92989.71, "trd": [[1.41, 34294.48]], "batb": [[0, 1.41, 28748.9]], "batl": NaN}, {"timestamp": 1631401479331, "ltp": 1.42, "tv": 93329.66, "trd": [[1.42, 22834.95]], "batb": [[0, 1.42, 790.47], [1, 1.41, 28748.9], [2, 1.4, 14165.99]], "batl": [[0, 1.43, 16057.91], [1, 1.44, 11294.52], [2, 1.45, 1403.6]]}, {"timestamp": 1631401479944, "ltp": 1.42, "tv": 93329.66, "trd": NaN, "batb": [[1, 1.41, 28779.11]], "batl": NaN}, {"timestamp": 1631401487961, "ltp": 1.42, "tv": 93329.66, "trd": NaN, "batb": [[0, 1.42, 1390.47]], "batl": NaN}, {"timestamp": 1631401494362, "ltp": 1.42, "tv": 93329.66, "trd": NaN, "batb": [[2, 1.4, 13847.66]], "batl": NaN}, {"timestamp": 1631401495441, "ltp": 1.42, "tv": 93329.66, "trd": NaN, "batb": [[2, 1.4, 13771.66]], "batl": NaN}, {"timestamp": 1631401496471, "ltp": 1.42, "tv": 93329.66, "trd": NaN, "batb": [[2, 1.4, 13714.22]], "batl": NaN}, {"timestamp": 1631401501588, "ltp": 1.42, "tv": 93329.66, "trd": NaN, "batb": [[1, 1.41, 28695.34]], "batl": [[1, 1.44, 11746.56]]}, {"timestamp": 1631401761047, "ltp": 1.42, "tv": 93529.66, "trd": [[1.42, 23034.96]], "batb": [[0, 1.42, 1290.46]], "batl": NaN}, {"timestamp": 1631401887774, "ltp": 1.42, "tv": 93529.66, "trd": NaN, "batb": [[0, 1.42, 1330.99]], "batl": NaN}, {"timestamp": 1631401901083, "ltp": 1.42, "tv": 93729.67, "trd": [[1.42, 23234.96]], "batb": [[0, 1.42, 1230.98]], "batl": NaN}, {"timestamp": 1631401976084, "ltp": 1.42, "tv": 93825.43, "trd": [[1.42, 23330.73]], "batb": [[0, 1.42, 1183.1]], "batl": NaN}, {"timestamp": 1631401995337, "ltp": 1.42, "tv": 95825.46, "trd": [[1.42, 25330.75]], "batb": [[0, 1.42, 183.07]], "batl": NaN}, {"timestamp": 1631402019872, "ltp": 1.42, "tv": 95825.46, "trd": NaN, "batb": NaN, "batl": [[0, 1.43, 16078.58]]}, {"timestamp": 1631402035018, "ltp": 1.42, "tv": 95825.46, "trd": NaN, "batb": [[0, 1.42, 188.07], [1, 1.41, 28690.34]], "batl": NaN}, {"timestamp": 1631402118327, "ltp": 1.42, "tv": 96085.46, "trd": [[1.42, 25590.75]], "batb": [[0, 1.42, 58.07]], "batl": NaN}, {"timestamp": 1631402145450, "ltp": 1.42, "tv": 96201.61, "trd": [[1.42, 25706.91]], "batb": [[0, 1.41, 28690.34], [1, 1.4, 13714.22], [2, 1.39, 10240.88]], "batl": [[0, 1.42, 13.5], [1, 1.43, 16078.58], [2, 1.44, 11746.56]]}, {"timestamp": 1631402190187, "ltp": 1.42, "tv": 96201.61, "trd": NaN, "batb": NaN, "batl": [[2, 1.44, 11294.52]]}, {"timestamp": 1631402193503, "ltp": 1.42, "tv": 96201.61, "trd": NaN, "batb": [[0, 1.41, 28793.75], [1, 1.4, 14166.25]], "batl": NaN}, {"timestamp": 1631402242366, "ltp": 1.41, "tv": 96321.61, "trd": [[1.41, 34414.48]], "batb": [[0, 1.41, 28733.75]], "batl": NaN}, {"timestamp": 1631402506126, "ltp": 1.41, "tv": 96421.62, "trd": [[1.41, 34514.49]], "batb": [[0, 1.41, 28683.74]], "batl": NaN}, {"timestamp": 1631402521444, "ltp": 1.41, "tv": 96421.62, "trd": NaN, "batb": [[0, 1.41, 28701.49]], "batl": NaN}, {"timestamp": 1631402596186, "ltp": 1.41, "tv": 97429.61, "trd": [[1.41, 35522.48]], "batb": [[0, 1.41, 28197.49]], "batl": [[0, 1.42, 149.16]]}, {"timestamp": 1631402679428, "ltp": 1.41, "tv": 97429.61, "trd": NaN, "batb": NaN, "batl": [[0, 1.42, 170.96]]}, {"timestamp": 1631403076339, "ltp": 1.41, "tv": 97478.41, "trd": [[1.41, 35571.28]], "batb": [[0, 1.41, 28173.09]], "batl": NaN}, {"timestamp": 1631403076758, "ltp": 1.41, "tv": 97478.41, "trd": NaN, "batb": NaN, "batl": [[0, 1.42, 195.19]]}, {"timestamp": 1631403131145, "ltp": 1.42, "tv": 97578.41, "trd": [[1.42, 25806.91]], "batb": NaN, "batl": [[0, 1.42, 145.19]]}, {"timestamp": 1631403138116, "ltp": 1.42, "tv": 97578.41, "trd": NaN, "batb": NaN, "batl": [[0, 1.42, 2645.19], [1, 1.43, 13578.58]]}, {"timestamp": 1631403153455, "ltp": 1.42, "tv": 97578.41, "trd": NaN, "batb": [[2, 1.39, 10087.82]], "batl": NaN}, {"timestamp": 1631403170088, "ltp": 1.42, "tv": 97813.12, "trd": [[1.42, 26041.61]], "batb": NaN, "batl": [[0, 1.42, 2527.84]]}, {"timestamp": 1631403198984, "ltp": 1.42, "tv": 97813.12, "trd": NaN, "batb": NaN, "batl": [[0, 1.42, 3250.85]]}, {"timestamp": 1631403276686, "ltp": 1.42, "tv": 97813.12, "trd": NaN, "batb": NaN, "batl": [[1, 1.43, 13511.96]]}, {"timestamp": 1631403277256, "ltp": 1.42, "tv": 97813.12, "trd": NaN, "batb": [[1, 1.4, 14211.51]], "batl": [[2, 1.44, 11414.94]]}, {"timestamp": 1631403350783, "ltp": 1.42, "tv": 97813.12, "trd": NaN, "batb": NaN, "batl": [[1, 1.43, 14419.75]]}, {"timestamp": 1631403358391, "ltp": 1.42, "tv": 97813.12, "trd": NaN, "batb": [[0, 1.41, 28182.42]], "batl": [[0, 1.42, 3259.94]]}, {"timestamp": 1631403426637, "ltp": 1.42, "tv": 97813.12, "trd": NaN, "batb": NaN, "batl": [[0, 1.42, 16023.3], [1, 1.43, 1656.39]]}, {"timestamp": 1631403472790, "ltp": 1.42, "tv": 97813.12, "trd": NaN, "batb": [[0, 1.41, 28174.73]], "batl": NaN}, {"timestamp": 1631403485457, "ltp": 1.42, "tv": 97813.12, "trd": NaN, "batb": NaN, "batl": [[0, 1.42, 16746.31]]}, {"timestamp": 1631403503629, "ltp": 1.42, "tv": 97813.12, "trd": NaN, "batb": NaN, "batl": [[2, 1.44, 11378.22]]}, {"timestamp": 1631403514254, "ltp": 1.42, "tv": 97813.12, "trd": NaN, "batb": [[0, 1.41, 28251.59], [1, 1.4, 14080.84]], "batl": NaN}, {"timestamp": 1631403637762, "ltp": 1.42, "tv": 98632.6, "trd": [[1.42, 26861.09]], "batb": NaN, "batl": [[0, 1.42, 16336.57]]}, {"timestamp": 1631403651193, "ltp": 1.41, "tv": 98791.66, "trd": [[1.41, 35730.35]], "batb": [[0, 1.41, 28172.06]], "batl": [[0, 1.42, 16415.54]]}, {"timestamp": 1631403652278, "ltp": 1.41, "tv": 98791.66, "trd": NaN, "batb": [[0, 1.41, 28283.84]], "batl": NaN}, {"timestamp": 1631403707462, "ltp": 1.41, "tv": 98791.66, "trd": NaN, "batb": NaN, "batl": [[1, 1.43, 6780.65], [2, 1.44, 6253.96]]}, {"timestamp": 1631403746481, "ltp": 1.41, "tv": 98791.66, "trd": NaN, "batb": [[0, 1.41, 23159.58]], "batl": [[1, 1.43, 1656.39]]}, {"timestamp": 1631403802697, "ltp": 1.41, "tv": 98791.66, "trd": NaN, "batb": [[0, 1.41, 23147.29]], "batl": NaN}, {"timestamp": 1631404280263, "ltp": 1.41, "tv": 98791.66, "trd": NaN, "batb": NaN, "batl": [[1, 1.43, 1635.72]]}, {"timestamp": 1631404359468, "ltp": 1.41, "tv": 98829.82, "trd": [[1.41, 35768.51]], "batb": [[0, 1.41, 23128.21]], "batl": NaN}, {"timestamp": 1631404359977, "ltp": 1.41, "tv": 98829.82, "trd": NaN, "batb": NaN, "batl": [[0, 1.42, 16434.48]]}, {"timestamp": 1631404720587, "ltp": 1.41, "tv": 98849.82, "trd": [[1.41, 35788.51]], "batb": [[0, 1.41, 23118.21]], "batl": [[0, 1.42, 16444.41]]}, {"timestamp": 1631405098167, "ltp": 1.42, "tv": 99131.82, "trd": [[1.42, 27143.09]], "batb": NaN, "batl": [[0, 1.42, 16303.41]]}, {"timestamp": 1631405594055, "ltp": 1.42, "tv": 99250.68, "trd": [[1.42, 27261.96]], "batb": NaN, "batl": [[0, 1.42, 16243.98]]}, {"timestamp": 1631405704352, "ltp": 1.41, "tv": 99270.68, "trd": [[1.41, 35808.51]], "batb": [[0, 1.41, 23108.21]], "batl": [[0, 1.42, 16253.91]]}, {"timestamp": 1631405998114, "ltp": 1.42, "tv": 100325.58, "trd": [[1.42, 28316.86]], "batb": [[0, 1.41, 22583.21], [1, 1.4, 13347.84]], "batl": [[0, 1.42, 15726.46]]}, {"timestamp": 1631406087487, "ltp": 1.42, "tv": 101282.8, "trd": [[1.42, 29274.08]], "batb": NaN, "batl": [[0, 1.42, 15247.86]]}, {"timestamp": 1631406357765, "ltp": 1.42, "tv": 101282.8, "trd": NaN, "batb": NaN, "batl": [[0, 1.42, 15257.86]]}, {"timestamp": 1631406364405, "ltp": 1.41, "tv": 101302.8, "trd": [[1.41, 35828.51]], "batb": [[0, 1.41, 22573.21]], "batl": [[0, 1.42, 15257.79]]}, {"timestamp": 1631407111512, "ltp": 1.41, "tv": 101323.07, "trd": [[1.41, 35848.77]], "batb": [[0, 1.41, 22563.08]], "batl": NaN}, {"timestamp": 1631407111929, "ltp": 1.41, "tv": 101323.07, "trd": NaN, "batb": NaN, "batl": [[0, 1.42, 15267.85]]}, {"timestamp": 1631407722582, "ltp": 1.41, "tv": 101323.07, "trd": NaN, "batb": [[0, 1.41, 22486.22]], "batl": [[2, 1.44, 6170.26]]}, {"timestamp": 1631407830555, "ltp": 1.41, "tv": 101323.07, "trd": NaN, "batb": [[1, 1.4, 13472.53]], "batl": [[2, 1.44, 6300.93]]}, {"timestamp": 1631407948720, "ltp": 1.41, "tv": 101682.09, "trd": [[1.41, 36207.79]], "batb": [[0, 1.41, 22306.71]], "batl": NaN}, {"timestamp": 1631407949230, "ltp": 1.41, "tv": 101682.09, "trd": NaN, "batb": NaN, "batl": [[0, 1.42, 15294.73]]}, {"timestamp": 1631408128223, "ltp": 1.41, "tv": 101788.45, "trd": [[1.41, 36314.15]], "batb": [[0, 1.41, 22253.53]], "batl": NaN}, {"timestamp": 1631408186154, "ltp": 1.41, "tv": 101788.45, "trd": NaN, "batb": NaN, "batl": [[0, 1.42, 15394.73]]}, {"timestamp": 1631408274632, "ltp": 1.41, "tv": 101894.8, "trd": [[1.41, 36420.5]], "batb": [[0, 1.41, 22200.35]], "batl": NaN}, {"timestamp": 1631408320696, "ltp": 1.41, "tv": 103246.03, "trd": [[1.41, 37771.73]], "batb": [[0, 1.41, 21524.74]], "batl": NaN}, {"timestamp": 1631408339047, "ltp": 1.41, "tv": 103246.03, "trd": NaN, "batb": NaN, "batl": [[0, 1.42, 15447.91]]}, {"timestamp": 1631408398304, "ltp": 1.41, "tv": 103300.04, "trd": [[1.41, 37825.74]], "batb": [[0, 1.41, 21497.74]], "batl": NaN}, {"timestamp": 1631408433668, "ltp": 1.41, "tv": 103305.35, "trd": [[1.41, 37831.06]], "batb": [[0, 1.41, 21495.08]], "batl": NaN}, {"timestamp": 1631409054151, "ltp": 1.41, "tv": 103312.58, "trd": [[1.41, 37838.29]], "batb": [[0, 1.41, 21491.46]], "batl": NaN}, {"timestamp": 1631409102681, "ltp": 1.41, "tv": 103324.11, "trd": [[1.41, 37849.81]], "batb": [[0, 1.41, 21485.7]], "batl": NaN}, {"timestamp": 1631409208533, "ltp": 1.41, "tv": 103430.46, "trd": [[1.41, 37956.16]], "batb": [[0, 1.41, 21432.52]], "batl": [[0, 1.42, 15394.73]]}, {"timestamp": 1631409341988, "ltp": 1.41, "tv": 103433.22, "trd": [[1.41, 37958.92]], "batb": [[0, 1.41, 21431.15]], "batl": NaN}, {"timestamp": 1631409623418, "ltp": 1.41, "tv": 103438.54, "trd": [[1.41, 37964.24]], "batb": [[0, 1.41, 21428.49]], "batl": NaN}, {"timestamp": 1631409981068, "ltp": 1.41, "tv": 103438.54, "trd": NaN, "batb": [[1, 1.4, 13434.1]], "batl": NaN}, {"timestamp": 1631410272678, "ltp": 1.41, "tv": 108756.41, "trd": [[1.41, 43282.11]], "batb": [[0, 1.41, 18769.62]], "batl": NaN}, {"timestamp": 1631410323598, "ltp": 1.41, "tv": 108756.41, "trd": NaN, "batb": [[0, 1.41, 18783.82]], "batl": NaN}, {"timestamp": 1631410396022, "ltp": 1.41, "tv": 108795.7, "trd": [[1.41, 43321.4]], "batb": [[0, 1.41, 18764.18]], "batl": NaN}, {"timestamp": 1631410568926, "ltp": 1.41, "tv": 108795.7, "trd": NaN, "batb": [[1, 1.4, 13433.59]], "batl": NaN}, {"timestamp": 1631410571058, "ltp": 1.41, "tv": 108800.74, "trd": [[1.41, 43326.44]], "batb": [[0, 1.41, 18761.66]], "batl": NaN}, {"timestamp": 1631411234274, "ltp": 1.41, "tv": 108800.74, "trd": NaN, "batb": NaN, "batl": [[0, 1.42, 15444.73]]}, {"timestamp": 1631411242685, "ltp": 1.41, "tv": 108800.74, "trd": NaN, "batb": [[0, 1.41, 18811.66]], "batl": NaN}, {"timestamp": 1631411248798, "ltp": 1.41, "tv": 108850.74, "trd": [[1.41, 43376.44]], "batb": [[0, 1.41, 18786.66]], "batl": NaN}, {"timestamp": 1631411257942, "ltp": 1.41, "tv": 108850.74, "trd": NaN, "batb": [[0, 1.41, 18811.66]], "batl": NaN}, {"timestamp": 1631411288986, "ltp": 1.41, "tv": 108850.74, "trd": NaN, "batb": NaN, "batl": [[0, 1.42, 15494.73]]}, {"timestamp": 1631411297799, "ltp": 1.41, "tv": 108850.74, "trd": NaN, "batb": [[0, 1.41, 18861.66]], "batl": NaN}, {"timestamp": 1631411303881, "ltp": 1.41, "tv": 108900.74, "trd": [[1.41, 43426.44]], "batb": [[0, 1.41, 18836.67]], "batl": NaN}, {"timestamp": 1631411310982, "ltp": 1.41, "tv": 108900.74, "trd": NaN, "batb": [[1, 1.4, 13458.59]], "batl": NaN}, {"timestamp": 1631411348124, "ltp": 1.41, "tv": 108900.74, "trd": NaN, "batb": NaN, "batl": [[2, 1.44, 6310.93]]}, {"timestamp": 1631411354658, "ltp": 1.41, "tv": 108900.74, "trd": NaN, "batb": [[1, 1.4, 13468.59]], "batl": NaN}, {"timestamp": 1631411360490, "ltp": 1.41, "tv": 108900.74, "trd": NaN, "batb": NaN, "batl": [[1, 1.43, 1645.72]]}, {"timestamp": 1631411366665, "ltp": 1.41, "tv": 108900.74, "trd": NaN, "batb": [[1, 1.4, 13478.59]], "batl": NaN}, {"timestamp": 1631411393845, "ltp": 1.41, "tv": 108910.73, "trd": [[1.41, 43436.43]], "batb": [[0, 1.41, 18831.67]], "batl": NaN}, {"timestamp": 1631411400433, "ltp": 1.41, "tv": 108910.73, "trd": NaN, "batb": [[2, 1.39, 10092.82]], "batl": NaN}, {"timestamp": 1631411407056, "ltp": 1.41, "tv": 108910.73, "trd": NaN, "batb": NaN, "batl": [[1, 1.43, 1650.72]]}, {"timestamp": 1631411411153, "ltp": 1.42, "tv": 108920.73, "trd": [[1.42, 29284.08]], "batb": NaN, "batl": [[0, 1.42, 15489.73]]}, {"timestamp": 1631411419856, "ltp": 1.42, "tv": 108920.73, "trd": NaN, "batb": NaN, "batl": [[0, 1.42, 15499.73]]}, {"timestamp": 1631411425045, "ltp": 1.42, "tv": 108920.73, "trd": NaN, "batb": [[0, 1.41, 18841.67]], "batl": NaN}, {"timestamp": 1631411447489, "ltp": 1.41, "tv": 108940.73, "trd": [[1.41, 43456.43]], "batb": [[0, 1.41, 18831.67]], "batl": NaN}, {"timestamp": 1631411452715, "ltp": 1.41, "tv": 108940.73, "trd": NaN, "batb": [[1, 1.4, 13488.59]], "batl": NaN}, {"timestamp": 1631411541891, "ltp": 1.42, "tv": 109252.82, "trd": [[1.42, 29596.16]], "batb": NaN, "batl": [[0, 1.42, 15343.69]]}, {"timestamp": 1631412675377, "ltp": 1.41, "tv": 109474.82, "trd": [[1.41, 43678.43]], "batb": [[0, 1.41, 18720.67]], "batl": NaN}, {"timestamp": 1631412914423, "ltp": 1.41, "tv": 109474.82, "trd": NaN, "batb": [[0, 1.41, 18770.67]], "batl": NaN}, {"timestamp": 1631412920749, "ltp": 1.41, "tv": 109480.13, "trd": [[1.41, 43683.75]], "batb": [[0, 1.41, 18768.01]], "batl": NaN}, {"timestamp": 1631412942572, "ltp": 1.41, "tv": 109485.45, "trd": [[1.41, 43689.06]], "batb": [[0, 1.41, 18765.36]], "batl": NaN}, {"timestamp": 1631412947273, "ltp": 1.42, "tv": 109485.7, "trd": [[1.42, 29596.42]], "batb": NaN, "batl": [[0, 1.42, 15343.56]]}, {"timestamp": 1631413232065, "ltp": 1.41, "tv": 109513.26, "trd": [[1.41, 43716.62]], "batb": [[0, 1.41, 18751.58]], "batl": NaN}, {"timestamp": 1631413396869, "ltp": 1.42, "tv": 109521.8, "trd": [[1.42, 29604.96]], "batb": NaN, "batl": [[0, 1.42, 15339.29]]}, {"timestamp": 1631414206556, "ltp": 1.41, "tv": 109549.35, "trd": [[1.41, 43744.17]], "batb": [[0, 1.41, 18737.8]], "batl": NaN}, {"timestamp": 1631414245615, "ltp": 1.41, "tv": 109549.35, "trd": NaN, "batb": NaN, "batl": [[1, 1.43, 1729.3], [2, 1.44, 6180.26]]}, {"timestamp": 1631414253840, "ltp": 1.41, "tv": 110790.05, "trd": [[1.41, 44984.86]], "batb": [[0, 1.41, 18117.46]], "batl": NaN}, {"timestamp": 1631414307701, "ltp": 1.41, "tv": 110790.05, "trd": NaN, "batb": [[0, 1.41, 18156.29]], "batl": NaN}, {"timestamp": 1631414628153, "ltp": 1.41, "tv": 110836.19, "trd": [[1.41, 45031]], "batb": [[0, 1.41, 18133.22]], "batl": NaN}, {"timestamp": 1631414656718, "ltp": 1.41, "tv": 110836.19, "trd": NaN, "batb": [[0, 1.41, 18144.53]], "batl": NaN}, {"timestamp": 1631414946482, "ltp": 1.41, "tv": 111475.39, "trd": [[1.41, 45670.21]], "batb": [[0, 1.41, 17824.94]], "batl": NaN}, {"timestamp": 1631414947359, "ltp": 1.41, "tv": 111475.39, "trd": NaN, "batb": [[0, 1.41, 17821.28], [1, 1.4, 13510.36]], "batl": NaN}, {"timestamp": 1631414991632, "ltp": 1.41, "tv": 111475.39, "trd": NaN, "batb": [[0, 1.41, 17869.03]], "batl": [[0, 1.42, 15366.2]]}, {"timestamp": 1631415297164, "ltp": 1.41, "tv": 111581.75, "trd": [[1.41, 45776.57]], "batb": [[0, 1.41, 17815.85]], "batl": NaN}, {"timestamp": 1631415426296, "ltp": 1.41, "tv": 111595.53, "trd": [[1.41, 45790.35]], "batb": [[0, 1.41, 17808.96]], "batl": NaN}, {"timestamp": 1631415693930, "ltp": 1.41, "tv": 117594.81, "trd": [[1.41, 51789.63]], "batb": [[0, 1.41, 14809.31]], "batl": NaN}, {"timestamp": 1631415781599, "ltp": 1.41, "tv": 117594.81, "trd": NaN, "batb": [[0, 1.41, 14915.56]], "batl": [[0, 1.42, 15473.88]]}, {"timestamp": 1631415869407, "ltp": 1.41, "tv": 117594.81, "trd": NaN, "batb": [[0, 1.41, 14822.43]], "batl": [[0, 1.42, 15564.79]]}, {"timestamp": 1631415925327, "ltp": 1.41, "tv": 117596.61, "trd": [[1.41, 51791.43]], "batb": [[0, 1.41, 14821.53]], "batl": NaN}, {"timestamp": 1631415935223, "ltp": 1.41, "tv": 117613.66, "trd": [[1.41, 51808.48]], "batb": [[0, 1.41, 14813.01]], "batl": NaN}, {"timestamp": 1631416123946, "ltp": 1.41, "tv": 117613.66, "trd": NaN, "batb": [[0, 1.41, 17035.01]], "batl": NaN}, {"timestamp": 1631416147376, "ltp": 1.42, "tv": 117666.06, "trd": [[1.42, 29657.36]], "batb": NaN, "batl": [[0, 1.42, 15538.59]]}, {"timestamp": 1631416260538, "ltp": 1.41, "tv": 129622.68, "trd": [[1.41, 63765.09]], "batb": [[0, 1.41, 11056.7]], "batl": NaN}, {"timestamp": 1631416448489, "ltp": 1.41, "tv": 133074.72, "trd": [[1.41, 67217.14]], "batb": [[0, 1.41, 9330.68]], "batl": NaN}, {"timestamp": 1631416498241, "ltp": 1.41, "tv": 138659.55, "trd": [[1.41, 72801.97]], "batb": [[0, 1.4, 13510.36], [1, 1.39, 10092.82], [2, 1.38, 15893.65]], "batl": [[0, 1.41, 309.98], [1, 1.42, 15538.59], [2, 1.43, 1729.3]]}, {"timestamp": 1631416500142, "ltp": 1.41, "tv": 138659.55, "trd": NaN, "batb": NaN, "batl": [[0, 1.42, 15538.59], [1, 1.43, 1729.3], [2, 1.44, 6180.26]]}, {"timestamp": 1631416533484, "ltp": 1.41, "tv": 138659.55, "trd": NaN, "batb": NaN, "batl": [[0, 1.42, 15710.54]]}, {"timestamp": 1631416573879, "ltp": 1.41, "tv": 138659.55, "trd": NaN, "batb": [[0, 1.41, 222], [1, 1.4, 13510.36], [2, 1.39, 10092.82]], "batl": NaN}, {"timestamp": 1631416613803, "ltp": 1.41, "tv": 138659.55, "trd": NaN, "batb": [[0, 1.41, 341.57]], "batl": NaN}, {"timestamp": 1631416617631, "ltp": 1.41, "tv": 138659.55, "trd": NaN, "batb": [[0, 1.41, 392.8]], "batl": NaN}, {"timestamp": 1631416648468, "ltp": 1.41, "tv": 138659.55, "trd": NaN, "batb": NaN, "batl": [[0, 1.42, 15837.3]]}, {"timestamp": 1631416684173, "ltp": 1.41, "tv": 138659.55, "trd": NaN, "batb": [[0, 1.41, 400.48]], "batl": NaN}, {"timestamp": 1631416786187, "ltp": 1.41, "tv": 138659.55, "trd": NaN, "batb": [[0, 1.41, 800.48]], "batl": NaN}, {"timestamp": 1631416810603, "ltp": 1.41, "tv": 138659.55, "trd": NaN, "batb": [[0, 1.41, 861.64]], "batl": NaN}, {"timestamp": 1631416885487, "ltp": 1.41, "tv": 138670.19, "trd": [[1.41, 72812.61]], "batb": [[0, 1.41, 856.32]], "batl": NaN}, {"timestamp": 1631416886580, "ltp": 1.41, "tv": 138670.19, "trd": NaN, "batb": [[0, 1.41, 865.49]], "batl": NaN}, {"timestamp": 1631416986556, "ltp": 1.41, "tv": 138787.19, "trd": [[1.41, 72929.6]], "batb": [[0, 1.41, 806.99]], "batl": NaN}, {"timestamp": 1631417099318, "ltp": 1.42, "tv": 138797.83, "trd": [[1.42, 29668]], "batb": NaN, "batl": [[0, 1.42, 15831.98]]}, {"timestamp": 1631417557014, "ltp": 1.42, "tv": 138797.83, "trd": NaN, "batb": NaN, "batl": [[1, 1.43, 1857.4]]}, {"timestamp": 1631417634514, "ltp": 1.42, "tv": 138797.83, "trd": NaN, "batb": NaN, "batl": [[0, 1.42, 15818.12]]}, {"timestamp": 1631417639918, "ltp": 1.42, "tv": 138797.83, "trd": NaN, "batb": [[0, 1.41, 2413.53]], "batl": NaN}, {"timestamp": 1631417706402, "ltp": 1.42, "tv": 138797.83, "trd": NaN, "batb": [[0, 1.41, 2477.54]], "batl": NaN}, {"timestamp": 1631417812534, "ltp": 1.41, "tv": 138852.93, "trd": [[1.41, 72984.71]], "batb": [[0, 1.41, 2449.99]], "batl": NaN}, {"timestamp": 1631417894932, "ltp": 1.41, "tv": 138857.27, "trd": [[1.41, 72989.05]], "batb": [[0, 1.41, 2447.82]], "batl": NaN}, {"timestamp": 1631417945865, "ltp": 1.42, "tv": 138889.21, "trd": [[1.42, 29699.94]], "batb": NaN, "batl": [[0, 1.42, 15802.15]]}, {"timestamp": 1631418109445, "ltp": 1.41, "tv": 138893.21, "trd": [[1.41, 72993.05]], "batb": [[0, 1.41, 2445.82]], "batl": NaN}, {"timestamp": 1631418318211, "ltp": 1.41, "tv": 140938.47, "trd": [[1.41, 75038.31]], "batb": [[0, 1.41, 1423.21]], "batl": NaN}, {"timestamp": 1631418350469, "ltp": 1.41, "tv": 140938.47, "trd": NaN, "batb": [[0, 1.41, 1487.31]], "batl": [[0, 1.42, 15861.51]]}, {"timestamp": 1631418384959, "ltp": 1.41, "tv": 143913.08, "trd": [[1.41, 78012.92]], "batb": [[0, 1.4, 13638.93], [1, 1.39, 10092.82], [2, 1.38, 15893.65]], "batl": [[0, 1.41, 512.7], [1, 1.42, 15861.51], [2, 1.43, 1857.4]]}, {"timestamp": 1631418433628, "ltp": 1.41, "tv": 143913.08, "trd": NaN, "batb": NaN, "batl": [[2, 1.43, 1842.03]]}, {"timestamp": 1631418434201, "ltp": 1.41, "tv": 143913.08, "trd": NaN, "batb": NaN, "batl": [[2, 1.43, 1530.83]]}, {"timestamp": 1631418435633, "ltp": 1.41, "tv": 143913.08, "trd": NaN, "batb": NaN, "batl": [[2, 1.43, 1405.37]]}, {"timestamp": 1631418436512, "ltp": 1.41, "tv": 143913.08, "trd": NaN, "batb": [[0, 1.4, 13864.07], [1, 1.39, 10544.85]], "batl": NaN}, {"timestamp": 1631418482784, "ltp": 1.41, "tv": 143965.86, "trd": [[1.41, 78065.7]], "batb": NaN, "batl": [[0, 1.41, 486.31]]}, {"timestamp": 1631418621951, "ltp": 1.41, "tv": 144035.36, "trd": [[1.41, 78135.2]], "batb": NaN, "batl": [[0, 1.41, 451.56]]}, {"timestamp": 1631418628663, "ltp": 1.41, "tv": 144179.96, "trd": [[1.41, 78279.8]], "batb": NaN, "batl": [[0, 1.41, 379.26]]}, {"timestamp": 1631418758624, "ltp": 1.41, "tv": 144353.49, "trd": [[1.41, 78453.32]], "batb": NaN, "batl": [[0, 1.41, 292.5]]}, {"timestamp": 1631418952021, "ltp": 1.41, "tv": 144938.49, "trd": [[1.41, 79038.33]], "batb": [[0, 1.41, 792.02], [1, 1.4, 13864.07], [2, 1.39, 10544.85]], "batl": [[0, 1.42, 15861.51], [1, 1.43, 1405.37], [2, 1.44, 6180.26]]}, {"timestamp": 1631418973665, "ltp": 1.41, "tv": 144938.49, "trd": NaN, "batb": [[2, 1.39, 10092.82]], "batl": NaN}, {"timestamp": 1631418974950, "ltp": 1.41, "tv": 144938.49, "trd": NaN, "batb": [[1, 1.4, 13638.93]], "batl": NaN}, {"timestamp": 1631418976547, "ltp": 1.41, "tv": 144938.49, "trd": NaN, "batb": [[0, 1.41, 855.55]], "batl": [[1, 1.43, 1857.4]]}, {"timestamp": 1631419241915, "ltp": 1.41, "tv": 146649.59, "trd": [[1.41, 80749.43]], "batb": [[0, 1.4, 13638.93], [1, 1.39, 10092.82], [2, 1.38, 15893.65]], "batl": NaN}, {"timestamp": 1631419254341, "ltp": 1.42, "tv": 158414.54, "trd": [[1.42, 41464.89]], "batb": NaN, "batl": [[0, 1.42, 9978.91]]}, {"timestamp": 1631419267669, "ltp": 1.42, "tv": 158414.54, "trd": NaN, "batb": [[0, 1.4, 16191.58]], "batl": NaN}, {"timestamp": 1631419288682, "ltp": 1.42, "tv": 158414.54, "trd": NaN, "batb": [[1, 1.39, 10544.85]], "batl": NaN}, {"timestamp": 1631419289706, "ltp": 1.42, "tv": 158414.54, "trd": NaN, "batb": [[0, 1.4, 16388.75]], "batl": [[0, 1.42, 9987.99]]}, {"timestamp": 1631419365689, "ltp": 1.42, "tv": 158414.54, "trd": NaN, "batb": [[0, 1.4, 16309.9]], "batl": NaN}, {"timestamp": 1631419424985, "ltp": 1.42, "tv": 158414.54, "trd": NaN, "batb": [[0, 1.4, 16948.07]], "batl": NaN}, {"timestamp": 1631419426065, "ltp": 1.42, "tv": 158414.54, "trd": NaN, "batb": [[0, 1.4, 17586.23]], "batl": NaN}, {"timestamp": 1631419429563, "ltp": 1.42, "tv": 158414.54, "trd": NaN, "batb": [[0, 1.4, 18224.39]], "batl": NaN}, {"timestamp": 1631420033757, "ltp": 1.42, "tv": 160190.58, "trd": [[1.42, 43240.93]], "batb": NaN, "batl": [[0, 1.42, 9099.95]]}, {"timestamp": 1631420076415, "ltp": 1.42, "tv": 160190.58, "trd": NaN, "batb": [[0, 1.4, 18862.55]], "batl": NaN}, {"timestamp": 1631420081424, "ltp": 1.42, "tv": 160190.58, "trd": NaN, "batb": [[0, 1.4, 19500.72]], "batl": NaN}, {"timestamp": 1631420125291, "ltp": 1.42, "tv": 160190.58, "trd": NaN, "batb": [[0, 1.4, 19492.17]], "batl": [[1, 1.43, 1862.53]]}, {"timestamp": 1631420173344, "ltp": 1.42, "tv": 160190.58, "trd": NaN, "batb": NaN, "batl": [[0, 1.42, 10699.95]]}, {"timestamp": 1631420197882, "ltp": 1.42, "tv": 160190.58, "trd": NaN, "batb": NaN, "batl": [[0, 1.42, 9099.95], [1, 1.43, 3462.53]]}, {"timestamp": 1631420497742, "ltp": 1.42, "tv": 160190.58, "trd": NaN, "batb": NaN, "batl": [[0, 1.41, 1200], [1, 1.42, 9099.95], [2, 1.43, 3462.53]]}, {"timestamp": 1631420515446, "ltp": 1.42, "tv": 160190.58, "trd": NaN, "batb": NaN, "batl": [[2, 1.43, 3010.49]]}, {"timestamp": 1631420515958, "ltp": 1.42, "tv": 160190.58, "trd": NaN, "batb": NaN, "batl": [[0, 1.41, 1286.62]]}, {"timestamp": 1631420742650, "ltp": 1.42, "tv": 160190.58, "trd": NaN, "batb": NaN, "batl": [[0, 1.41, 1315.41]]}, {"timestamp": 1631420755280, "ltp": 1.42, "tv": 160190.58, "trd": NaN, "batb": [[0, 1.4, 19414.46], [1, 1.39, 10665.27]], "batl": NaN}, {"timestamp": 1631420879675, "ltp": 1.42, "tv": 160190.58, "trd": NaN, "batb": [[1, 1.39, 10638.68]], "batl": NaN}, {"timestamp": 1631420880355, "ltp": 1.42, "tv": 160190.58, "trd": NaN, "batb": [[0, 1.4, 19296.13]], "batl": NaN}, {"timestamp": 1631420881655, "ltp": 1.42, "tv": 160190.58, "trd": NaN, "batb": [[0, 1.4, 19246.37]], "batl": [[0, 1.41, 1418.15]]}, {"timestamp": 1631420882171, "ltp": 1.42, "tv": 160190.58, "trd": NaN, "batb": NaN, "batl": [[1, 1.42, 9090.86]]}, {"timestamp": 1631420883461, "ltp": 1.42, "tv": 160190.58, "trd": NaN, "batb": NaN, "batl": [[1, 1.42, 9073.36]]}, {"timestamp": 1631421114381, "ltp": 1.42, "tv": 160190.58, "trd": NaN, "batb": [[2, 1.38, 15848.89]], "batl": NaN}, {"timestamp": 1631421286656, "ltp": 1.4, "tv": 160228.58, "trd": [[1.4, 9184.77]], "batb": [[0, 1.4, 19227.37]], "batl": NaN}, {"timestamp": 1631421382186, "ltp": 1.41, "tv": 160478.58, "trd": [[1.41, 80999.43]], "batb": NaN, "batl": [[0, 1.41, 1293.15]]}, {"timestamp": 1631421467890, "ltp": 1.41, "tv": 160478.58, "trd": NaN, "batb": NaN, "batl": [[0, 1.41, 1297.77]]}, {"timestamp": 1631421495837, "ltp": 1.41, "tv": 160478.58, "trd": NaN, "batb": NaN, "batl": [[2, 1.43, 3065.15]]}, {"timestamp": 1631421552720, "ltp": 1.41, "tv": 160478.58, "trd": NaN, "batb": [[0, 1.4, 19201.77]], "batl": NaN}, {"timestamp": 1631421594577, "ltp": 1.41, "tv": 160484.22, "trd": [[1.41, 81005.06]], "batb": NaN, "batl": [[0, 1.41, 1294.95]]}, {"timestamp": 1631421782555, "ltp": 1.41, "tv": 160484.22, "trd": NaN, "batb": NaN, "batl": [[0, 1.41, 1319.95]]}, {"timestamp": 1631421845121, "ltp": 1.41, "tv": 160484.22, "trd": NaN, "batb": NaN, "batl": [[0, 1.41, 1323.96]]}, {"timestamp": 1631422160980, "ltp": 1.41, "tv": 160484.22, "trd": NaN, "batb": NaN, "batl": [[0, 1.41, 2923.96], [2, 1.43, 1465.15]]}, {"timestamp": 1631422209357, "ltp": 1.41, "tv": 160484.22, "trd": NaN, "batb": NaN, "batl": [[0, 1.41, 1323.96], [1, 1.42, 10673.36]]}, {"timestamp": 1631422597516, "ltp": 1.41, "tv": 160484.22, "trd": NaN, "batb": NaN, "batl": [[0, 1.41, 2923.96], [1, 1.42, 9073.36]]}, {"timestamp": 1631422675268, "ltp": 1.41, "tv": 160484.22, "trd": NaN, "batb": NaN, "batl": [[0, 1.41, 2940.31]]}, {"timestamp": 1631422884424, "ltp": 1.41, "tv": 160484.22, "trd": NaN, "batb": NaN, "batl": [[1, 1.42, 9151.93], [2, 1.43, 1326.8]]}, {"timestamp": 1631422913673, "ltp": 1.41, "tv": 160484.22, "trd": NaN, "batb": NaN, "batl": [[1, 1.42, 9073.36]]}, {"timestamp": 1631422914708, "ltp": 1.41, "tv": 160484.22, "trd": NaN, "batb": NaN, "batl": [[2, 1.43, 1458.32]]}, {"timestamp": 1631423235208, "ltp": 1.41, "tv": 160484.22, "trd": NaN, "batb": [[0, 1.4, 18563.61]], "batl": NaN}, {"timestamp": 1631423476854, "ltp": 1.4, "tv": 160613.58, "trd": [[1.4, 9314.12]], "batb": [[0, 1.4, 18498.93]], "batl": NaN}, {"timestamp": 1631423905624, "ltp": 1.4, "tv": 160613.58, "trd": NaN, "batb": [[1, 1.39, 10655.35]], "batl": NaN}, {"timestamp": 1631424162396, "ltp": 1.4, "tv": 160613.58, "trd": NaN, "batb": NaN, "batl": [[2, 1.43, 1471.04]]}, {"timestamp": 1631424231739, "ltp": 1.4, "tv": 161677.15, "trd": [[1.4, 10377.69]], "batb": [[0, 1.4, 17967.16]], "batl": NaN}, {"timestamp": 1631424264474, "ltp": 1.41, "tv": 161703.74, "trd": [[1.41, 81031.65]], "batb": NaN, "batl": [[0, 1.41, 2927.02]]}, {"timestamp": 1631424495662, "ltp": 1.4, "tv": 161715.74, "trd": [[1.4, 10389.7]], "batb": [[0, 1.4, 17961.16]], "batl": NaN}, {"timestamp": 1631424798996, "ltp": 1.4, "tv": 161715.74, "trd": NaN, "batb": [[0, 1.4, 18156.41]], "batl": NaN}, {"timestamp": 1631424843950, "ltp": 1.4, "tv": 161715.74, "trd": NaN, "batb": [[0, 1.4, 13051.11], [1, 1.39, 15760.65]], "batl": NaN}, {"timestamp": 1631424870178, "ltp": 1.4, "tv": 161715.74, "trd": NaN, "batb": NaN, "batl": [[1, 1.42, 11626]]}, {"timestamp": 1631424932352, "ltp": 1.4, "tv": 161715.74, "trd": NaN, "batb": [[1, 1.39, 10655.35], [2, 1.38, 20954.18]], "batl": NaN}, {"timestamp": 1631424959522, "ltp": 1.4, "tv": 161715.74, "trd": NaN, "batb": NaN, "batl": [[1, 1.42, 14178.65]]}, {"timestamp": 1631424977444, "ltp": 1.4, "tv": 161715.74, "trd": NaN, "batb": [[0, 1.4, 12972.5]], "batl": NaN}, {"timestamp": 1631424978520, "ltp": 1.4, "tv": 161715.74, "trd": NaN, "batb": NaN, "batl": [[0, 1.41, 3003.71]]}, {"timestamp": 1631425653992, "ltp": 1.4, "tv": 161715.74, "trd": NaN, "batb": NaN, "batl": [[2, 1.43, 1599.15]]}, {"timestamp": 1631425797712, "ltp": 1.4, "tv": 161715.74, "trd": NaN, "batb": [[0, 1.4, 12948.17]], "batl": [[0, 1.41, 3027.45]]}, {"timestamp": 1631426023544, "ltp": 1.41, "tv": 161719.74, "trd": [[1.41, 81035.65]], "batb": NaN, "batl": [[0, 1.41, 3025.45]]}, {"timestamp": 1631426289116, "ltp": 1.4, "tv": 161949.43, "trd": [[1.4, 10619.39]], "batb": [[0, 1.4, 12833.33]], "batl": NaN}, {"timestamp": 1631426442698, "ltp": 1.4, "tv": 161949.43, "trd": NaN, "batb": [[1, 1.39, 10534.93]], "batl": NaN}, {"timestamp": 1631426443313, "ltp": 1.4, "tv": 161949.43, "trd": NaN, "batb": [[0, 1.4, 12917.02]], "batl": [[2, 1.43, 1552.17]]}, {"timestamp": 1631426445518, "ltp": 1.4, "tv": 161949.43, "trd": NaN, "batb": [[0, 1.4, 12970.83]], "batl": [[2, 1.43, 1467.62]]}, {"timestamp": 1631426789020, "ltp": 1.4, "tv": 161954.11, "trd": [[1.4, 10624.07]], "batb": [[0, 1.4, 12968.49]], "batl": NaN}, {"timestamp": 1631426883687, "ltp": 1.41, "tv": 168004.99, "trd": [[1.41, 87086.53]], "batb": [[0, 1.41, 26974.57], [1, 1.4, 12968.49], [2, 1.39, 10534.93]], "batl": [[0, 1.42, 14178.65], [1, 1.43, 1467.62], [2, 1.44, 7064.68]]}, {"timestamp": 1631426899190, "ltp": 1.41, "tv": 168004.99, "trd": NaN, "batb": [[1, 1.4, 12773.24]], "batl": NaN}, {"timestamp": 1631426925655, "ltp": 1.41, "tv": 168004.99, "trd": NaN, "batb": [[2, 1.39, 10109.49]], "batl": NaN}, {"timestamp": 1631426926632, "ltp": 1.41, "tv": 168004.99, "trd": NaN, "batb": [[1, 1.4, 12924.95]], "batl": [[1, 1.43, 1893.06]]}, {"timestamp": 1631427274760, "ltp": 1.41, "tv": 168111.35, "trd": [[1.41, 87192.89]], "batb": [[0, 1.41, 26921.39]], "batl": NaN}, {"timestamp": 1631427277661, "ltp": 1.41, "tv": 168111.35, "trd": NaN, "batb": NaN, "batl": [[2, 1.44, 7112.51]]}, {"timestamp": 1631427435400, "ltp": 1.41, "tv": 168111.35, "trd": NaN, "batb": [[0, 1.4, 12924.95], [1, 1.39, 10109.49], [2, 1.38, 20954.18]], "batl": NaN}, {"timestamp": 1631427448339, "ltp": 1.41, "tv": 168111.35, "trd": NaN, "batb": [[0, 1.4, 12935.04], [1, 1.39, 10534.93]], "batl": NaN}, {"timestamp": 1631427456062, "ltp": 1.41, "tv": 168111.35, "trd": NaN, "batb": NaN, "batl": [[0, 1.41, 3079.2], [1, 1.42, 14178.65], [2, 1.43, 1893.06]]}, {"timestamp": 1631427500721, "ltp": 1.41, "tv": 168111.35, "trd": NaN, "batb": NaN, "batl": [[2, 1.43, 1467.62]]}, {"timestamp": 1631427501340, "ltp": 1.41, "tv": 168111.35, "trd": NaN, "batb": NaN, "batl": [[0, 1.41, 3236.1]]}, {"timestamp": 1631427532594, "ltp": 1.4, "tv": 168191.36, "trd": [[1.4, 10704.07]], "batb": [[0, 1.4, 12895.04]], "batl": NaN}, {"timestamp": 1631427586688, "ltp": 1.4, "tv": 168233.51, "trd": [[1.4, 10746.23]], "batb": [[0, 1.4, 12873.96]], "batl": NaN}, {"timestamp": 1631427687069, "ltp": 1.4, "tv": 168409.12, "trd": [[1.4, 10921.84]], "batb": [[0, 1.4, 12786.16]], "batl": NaN}, {"timestamp": 1631427990655, "ltp": 1.4, "tv": 170080.18, "trd": [[1.4, 12592.9]], "batb": [[0, 1.4, 11950.63]], "batl": NaN}, {"timestamp": 1631427991064, "ltp": 1.4, "tv": 170080.18, "trd": NaN, "batb": NaN, "batl": [[0, 1.41, 3316.7]]}, {"timestamp": 1631428010713, "ltp": 1.4, "tv": 170080.18, "trd": NaN, "batb": [[0, 1.4, 12082.55]], "batl": NaN}, {"timestamp": 1631428050141, "ltp": 1.41, "tv": 170122.88, "trd": [[1.41, 87235.59]], "batb": NaN, "batl": [[0, 1.41, 3295.35]]}, {"timestamp": 1631428090614, "ltp": 1.41, "tv": 170122.88, "trd": NaN, "batb": NaN, "batl": [[1, 1.42, 14238.44]]}, {"timestamp": 1631428137135, "ltp": 1.41, "tv": 170122.88, "trd": NaN, "batb": [[0, 1.4, 12052.55], [1, 1.39, 10504.93]], "batl": [[1, 1.42, 14178.65], [2, 1.43, 1437.62]]}, {"timestamp": 1631428221994, "ltp": 1.41, "tv": 170128.4, "trd": [[1.41, 87241.11]], "batb": NaN, "batl": [[0, 1.41, 3292.59]]}, {"timestamp": 1631428484485, "ltp": 1.4, "tv": 170133.72, "trd": [[1.4, 12598.21]], "batb": [[0, 1.4, 12049.89]], "batl": [[0, 1.41, 3295.23]]}, {"timestamp": 1631428742007, "ltp": 1.4, "tv": 170133.72, "trd": NaN, "batb": [[0, 1.4, 12055.15]], "batl": NaN}, {"timestamp": 1631428898116, "ltp": 1.4, "tv": 170133.72, "trd": NaN, "batb": [[0, 1.4, 12003.91]], "batl": [[2, 1.43, 1522.17]]}, {"timestamp": 1631428923343, "ltp": 1.4, "tv": 170133.72, "trd": NaN, "batb": [[0, 1.4, 12015.88]], "batl": NaN}, {"timestamp": 1631428937694, "ltp": 1.4, "tv": 170505.4, "trd": [[1.4, 12969.9]], "batb": [[0, 1.4, 11644.2]], "batl": NaN}, {"timestamp": 1631428938002, "ltp": 1.4, "tv": 170505.4, "trd": NaN, "batb": NaN, "batl": [[0, 1.41, 3544.62]]}, {"timestamp": 1631428967694, "ltp": 1.4, "tv": 170505.4, "trd": NaN, "batb": [[0, 1.4, 11557.94]], "batl": NaN}, {"timestamp": 1631428967903, "ltp": 1.4, "tv": 170505.4, "trd": NaN, "batb": [[1, 1.39, 10628.77]], "batl": [[2, 1.43, 1559.75]]}, {"timestamp": 1631428974828, "ltp": 1.41, "tv": 170558.18, "trd": [[1.41, 87293.89]], "batb": NaN, "batl": [[0, 1.41, 3518.23]]}, {"timestamp": 1631428998734, "ltp": 1.41, "tv": 170558.18, "trd": NaN, "batb": [[0, 1.4, 11426.02]], "batl": NaN}, {"timestamp": 1631429005714, "ltp": 1.41, "tv": 170558.18, "trd": NaN, "batb": [[0, 1.4, 11403.95]], "batl": NaN}, {"timestamp": 1631429006358, "ltp": 1.41, "tv": 170558.18, "trd": NaN, "batb": [[0, 1.4, 11252.24]], "batl": NaN}, {"timestamp": 1631429007651, "ltp": 1.41, "tv": 170558.18, "trd": NaN, "batb": [[0, 1.4, 11131.34]], "batl": [[0, 1.41, 3786.77]]}, {"timestamp": 1631429065416, "ltp": 1.41, "tv": 170558.18, "trd": NaN, "batb": NaN, "batl": [[0, 1.41, 3914.42], [1, 1.42, 14051.89], [2, 1.43, 1475.82]]}, {"timestamp": 1631429119506, "ltp": 1.4, "tv": 170862.44, "trd": [[1.4, 13274.16]], "batb": [[0, 1.4, 10979.21]], "batl": NaN}, {"timestamp": 1631429296659, "ltp": 1.4, "tv": 170874.76, "trd": [[1.4, 13286.47]], "batb": [[0, 1.4, 10973.06]], "batl": NaN}, {"timestamp": 1631429310681, "ltp": 1.41, "tv": 170887.08, "trd": [[1.41, 87306.21]], "batb": NaN, "batl": [[0, 1.41, 3908.26]]}, {"timestamp": 1631429340550, "ltp": 1.4, "tv": 170960.98, "trd": [[1.4, 13360.38]], "batb": [[0, 1.4, 10936.1]], "batl": NaN}, {"timestamp": 1631429449340, "ltp": 1.41, "tv": 170969.52, "trd": [[1.41, 87314.75]], "batb": NaN, "batl": [[0, 1.41, 3903.99]]}, {"timestamp": 1631429450166, "ltp": 1.4, "tv": 171003.69, "trd": [[1.4, 13394.54]], "batb": [[0, 1.4, 10919.02]], "batl": NaN}, {"timestamp": 1631429622396, "ltp": 1.4, "tv": 171003.69, "trd": NaN, "batb": [[0, 1.4, 10946.02]], "batl": NaN}, {"timestamp": 1631429708574, "ltp": 1.41, "tv": 171168.52, "trd": [[1.41, 87479.58]], "batb": NaN, "batl": [[0, 1.41, 3821.57]]}, {"timestamp": 1631429817655, "ltp": 1.4, "tv": 171173.84, "trd": [[1.4, 13399.86]], "batb": [[0, 1.4, 10943.36]], "batl": NaN}, {"timestamp": 1631429977387, "ltp": 1.41, "tv": 171231.12, "trd": [[1.41, 87536.86]], "batb": NaN, "batl": [[0, 1.41, 3792.93]]}, {"timestamp": 1631430023620, "ltp": 1.41, "tv": 171231.12, "trd": NaN, "batb": [[0, 1.4, 10945.36]], "batl": NaN}, {"timestamp": 1631430026719, "ltp": 1.41, "tv": 171231.12, "trd": NaN, "batb": NaN, "batl": [[2, 1.43, 1439.95]]}, {"timestamp": 1631430056243, "ltp": 1.41, "tv": 171231.12, "trd": NaN, "batb": [[0, 1.4, 11023.94], [1, 1.39, 10504.93]], "batl": NaN}, {"timestamp": 1631430178652, "ltp": 1.41, "tv": 171231.12, "trd": NaN, "batb": [[0, 1.4, 11523.94]], "batl": NaN}, {"timestamp": 1631430564057, "ltp": 1.41, "tv": 171231.12, "trd": NaN, "batb": [[1, 1.39, 17893.41]], "batl": NaN}, {"timestamp": 1631430578848, "ltp": 1.41, "tv": 171231.12, "trd": NaN, "batb": [[2, 1.38, 29810.38]], "batl": NaN}, {"timestamp": 1631430594627, "ltp": 1.41, "tv": 171231.12, "trd": NaN, "batb": [[0, 1.4, 11379.59]], "batl": NaN}, {"timestamp": 1631430636477, "ltp": 1.4, "tv": 171240.68, "trd": [[1.4, 13409.43]], "batb": [[0, 1.4, 11374.81]], "batl": NaN}, {"timestamp": 1631430718069, "ltp": 1.4, "tv": 171240.68, "trd": NaN, "batb": [[0, 1.4, 11383.35]], "batl": NaN}, {"timestamp": 1631430733395, "ltp": 1.4, "tv": 171878.83, "trd": [[1.4, 14047.57]], "batb": [[0, 1.4, 11064.29]], "batl": NaN}, {"timestamp": 1631430745709, "ltp": 1.41, "tv": 171937.33, "trd": [[1.41, 87595.36]], "batb": NaN, "batl": [[0, 1.41, 3763.68]]}, {"timestamp": 1631430748400, "ltp": 1.41, "tv": 171937.33, "trd": NaN, "batb": [[0, 1.4, 11054.9]], "batl": NaN}, {"timestamp": 1631430806338, "ltp": 1.4, "tv": 171953.33, "trd": [[1.4, 14063.57]], "batb": [[0, 1.4, 11046.89]], "batl": NaN}, {"timestamp": 1631430823701, "ltp": 1.4, "tv": 172059.69, "trd": [[1.4, 14169.93]], "batb": [[0, 1.4, 10993.71]], "batl": NaN}, {"timestamp": 1631430887954, "ltp": 1.4, "tv": 172059.69, "trd": NaN, "batb": NaN, "batl": [[0, 1.41, 3773.68]]}, {"timestamp": 1631430898181, "ltp": 1.4, "tv": 172059.69, "trd": NaN, "batb": [[0, 1.4, 11003.71]], "batl": NaN}, {"timestamp": 1631430913163, "ltp": 1.4, "tv": 172059.69, "trd": NaN, "batb": NaN, "batl": [[0, 1.41, 3793.68]]}, {"timestamp": 1631430925021, "ltp": 1.4, "tv": 172059.69, "trd": NaN, "batb": [[0, 1.4, 11023.71]], "batl": NaN}, {"timestamp": 1631431131841, "ltp": 1.4, "tv": 172063.69, "trd": [[1.4, 14173.93]], "batb": [[0, 1.4, 11021.71]], "batl": NaN}, {"timestamp": 1631431218285, "ltp": 1.4, "tv": 172463.69, "trd": [[1.4, 14573.93]], "batb": [[0, 1.4, 10821.71]], "batl": NaN}, {"timestamp": 1631431521025, "ltp": 1.4, "tv": 172463.69, "trd": NaN, "batb": NaN, "batl": [[0, 1.41, 5404.41]]}, {"timestamp": 1631431778145, "ltp": 1.4, "tv": 172463.69, "trd": NaN, "batb": [[0, 1.4, 10744], [1, 1.39, 18030.91]], "batl": [[2, 1.43, 1483.51]]}, {"timestamp": 1631431779282, "ltp": 1.4, "tv": 172623.69, "trd": [[1.4, 14733.93]], "batb": [[0, 1.4, 10664]], "batl": NaN}, {"timestamp": 1631432101972, "ltp": 1.4, "tv": 172623.69, "trd": NaN, "batb": NaN, "batl": [[0, 1.41, 5878.4]]}, {"timestamp": 1631432278212, "ltp": 1.4, "tv": 172623.69, "trd": NaN, "batb": [[1, 1.39, 10642.43]], "batl": NaN}, {"timestamp": 1631432497860, "ltp": 1.4, "tv": 172641.28, "trd": [[1.4, 14751.52]], "batb": [[0, 1.4, 10655.2]], "batl": NaN}, {"timestamp": 1631432518411, "ltp": 1.4, "tv": 172641.28, "trd": NaN, "batb": [[0, 1.4, 10731.21], [1, 1.39, 10504.93]], "batl": [[2, 1.43, 1439.1]]}, {"timestamp": 1631432535028, "ltp": 1.4, "tv": 172843.01, "trd": [[1.4, 14953.26]], "batb": [[0, 1.4, 10630.35]], "batl": NaN}, {"timestamp": 1631432777573, "ltp": 1.4, "tv": 172849.01, "trd": [[1.4, 14959.26]], "batb": [[0, 1.4, 10627.35]], "batl": NaN}, {"timestamp": 1631432882645, "ltp": 1.41, "tv": 173005.03, "trd": [[1.41, 87751.38]], "batb": NaN, "batl": [[0, 1.41, 5800.39]]}, {"timestamp": 1631432971162, "ltp": 1.4, "tv": 173010.03, "trd": [[1.4, 14964.26]], "batb": [[0, 1.4, 10624.85]], "batl": NaN}, {"timestamp": 1631433038287, "ltp": 1.4, "tv": 173010.03, "trd": NaN, "batb": [[0, 1.4, 10548.84], [1, 1.39, 10591.19]], "batl": [[1, 1.42, 14128.76], [2, 1.43, 1353.69]]}, {"timestamp": 1631433206620, "ltp": 1.41, "tv": 173088.61, "trd": [[1.41, 87829.96]], "batb": NaN, "batl": [[0, 1.41, 5761.1]]}, {"timestamp": 1631433294640, "ltp": 1.41, "tv": 173088.61, "trd": NaN, "batb": NaN, "batl": [[1, 1.42, 43528.76]]}, {"timestamp": 1631433294847, "ltp": 1.41, "tv": 173088.61, "trd": NaN, "batb": [[0, 1.4, 10420.27]], "batl": NaN}, {"timestamp": 1631433307679, "ltp": 1.41, "tv": 173088.61, "trd": NaN, "batb": NaN, "batl": [[0, 1.41, 35161.1], [1, 1.42, 14128.76]]}, {"timestamp": 1631433346656, "ltp": 1.4, "tv": 173180.95, "trd": [[1.4, 15056.6]], "batb": [[0, 1.4, 10327.93]], "batl": NaN}, {"timestamp": 1631433351632, "ltp": 1.4, "tv": 173180.95, "trd": NaN, "batb": NaN, "batl": [[0, 1.41, 5761.1]]}, {"timestamp": 1631433351839, "ltp": 1.4, "tv": 173180.95, "trd": NaN, "batb": NaN, "batl": [[1, 1.42, 43528.76]]}, {"timestamp": 1631433356686, "ltp": 1.4, "tv": 173400.82, "trd": [[1.4, 15276.47]], "batb": [[0, 1.4, 10108.05]], "batl": NaN}, {"timestamp": 1631433368823, "ltp": 1.4, "tv": 173400.82, "trd": NaN, "batb": [[1, 1.39, 14776]], "batl": NaN}, {"timestamp": 1631433385968, "ltp": 1.4, "tv": 173400.82, "trd": NaN, "batb": [[0, 1.4, 14292.87]], "batl": NaN}, {"timestamp": 1631433475777, "ltp": 1.4, "tv": 173400.82, "trd": NaN, "batb": [[1, 1.39, 16477.52]], "batl": NaN}, {"timestamp": 1631433478304, "ltp": 1.4, "tv": 173400.82, "trd": NaN, "batb": [[1, 1.39, 18179.03]], "batl": NaN}, {"timestamp": 1631433539112, "ltp": 1.4, "tv": 173400.82, "trd": NaN, "batb": [[1, 1.39, 19004.6]], "batl": NaN}, {"timestamp": 1631433625280, "ltp": 1.4, "tv": 173410.82, "trd": [[1.4, 15286.47]], "batb": [[0, 1.4, 14287.87]], "batl": NaN}, {"timestamp": 1631433748219, "ltp": 1.4, "tv": 173420.82, "trd": [[1.4, 15296.46]], "batb": [[0, 1.4, 14282.88]], "batl": NaN}, {"timestamp": 1631433755134, "ltp": 1.41, "tv": 173507.93, "trd": [[1.41, 87917.07]], "batb": NaN, "batl": [[0, 1.41, 5717.54]]}, {"timestamp": 1631433939332, "ltp": 1.4, "tv": 173511.93, "trd": [[1.4, 15300.46]], "batb": [[0, 1.4, 14280.88]], "batl": NaN}, {"timestamp": 1631433958972, "ltp": 1.4, "tv": 173511.93, "trd": NaN, "batb": NaN, "batl": [[0, 1.41, 5744.13]]}, {"timestamp": 1631433978224, "ltp": 1.41, "tv": 173546.09, "trd": [[1.41, 87951.24]], "batb": NaN, "batl": [[0, 1.41, 5727.05]]}, {"timestamp": 1631434100951, "ltp": 1.4, "tv": 173582.24, "trd": [[1.4, 15336.61]], "batb": [[0, 1.4, 14262.81]], "batl": NaN}, {"timestamp": 1631434228693, "ltp": 1.4, "tv": 173582.24, "trd": NaN, "batb": [[1, 1.39, 19037.05]], "batl": NaN}, {"timestamp": 1631434254955, "ltp": 1.4, "tv": 173609.89, "trd": [[1.4, 15364.26]], "batb": [[0, 1.4, 14248.98]], "batl": NaN}, {"timestamp": 1631434331351, "ltp": 1.4, "tv": 173609.89, "trd": NaN, "batb": NaN, "batl": [[2, 1.43, 1378.69]]}, {"timestamp": 1631434387426, "ltp": 1.4, "tv": 173609.89, "trd": NaN, "batb": NaN, "batl": [[1, 1.42, 44677.2]]}, {"timestamp": 1631434496638, "ltp": 1.4, "tv": 173609.89, "trd": NaN, "batb": NaN, "batl": [[0, 1.41, 5735.59]]}, {"timestamp": 1631434503952, "ltp": 1.41, "tv": 173695.29, "trd": [[1.41, 88036.64]], "batb": NaN, "batl": [[0, 1.41, 5692.89]]}, {"timestamp": 1631434558951, "ltp": 1.41, "tv": 173695.29, "trd": NaN, "batb": [[1, 1.39, 19003.74]], "batl": NaN}, {"timestamp": 1631434588716, "ltp": 1.41, "tv": 173695.29, "trd": NaN, "batb": [[1, 1.39, 19036.2]], "batl": [[1, 1.42, 44600.34], [2, 1.43, 1513.63]]}, {"timestamp": 1631434708966, "ltp": 1.4, "tv": 173697.43, "trd": [[1.4, 15366.39]], "batb": [[0, 1.4, 14247.91]], "batl": NaN}, {"timestamp": 1631434717970, "ltp": 1.41, "tv": 173699.55, "trd": [[1.41, 88038.76]], "batb": NaN, "batl": [[0, 1.41, 5691.83]]}, {"timestamp": 1631434768746, "ltp": 1.41, "tv": 173805.12, "trd": [[1.41, 88144.33]], "batb": NaN, "batl": [[0, 1.41, 5639.05]]}, {"timestamp": 1631434975341, "ltp": 1.41, "tv": 173858.3, "trd": [[1.41, 88197.51]], "batb": NaN, "batl": [[0, 1.41, 5612.46]]}, {"timestamp": 1631435019684, "ltp": 1.41, "tv": 173858.3, "trd": NaN, "batb": NaN, "batl": [[2, 1.43, 1465.81]]}, {"timestamp": 1631435084691, "ltp": 1.41, "tv": 178432.49, "trd": [[1.41, 92771.71]], "batb": NaN, "batl": [[0, 1.41, 1038.26]]}, {"timestamp": 1631435085625, "ltp": 1.41, "tv": 178432.49, "trd": NaN, "batb": [[0, 1.4, 14711.48]], "batl": NaN}, {"timestamp": 1631435086515, "ltp": 1.41, "tv": 180508.62, "trd": [[1.41, 94847.83]], "batb": NaN, "batl": [[0, 1.42, 44600.54], [1, 1.43, 1465.81], [2, 1.44, 6947.57]]}, {"timestamp": 1631435087610, "ltp": 1.41, "tv": 180508.62, "trd": NaN, "batb": [[0, 1.4, 18793.11]], "batl": NaN}, {"timestamp": 1631435088498, "ltp": 1.42, "tv": 231185.4, "trd": [[1.41, 94848.03], [1.42, 93917.52]], "batb": [[0, 1.41, 454.48], [1, 1.4, 14711.48], [2, 1.39, 19036.2]], "batl": [[0, 1.42, 19261.7]]}, {"timestamp": 1631435089335, "ltp": 1.42, "tv": 231326.14, "trd": [[1.42, 94058.26]], "batb": NaN, "batl": [[0, 1.42, 19191.33]]}, {"timestamp": 1631435090326, "ltp": 1.42, "tv": 231599.08, "trd": [[1.42, 94331.2]], "batb": NaN, "batl": [[0, 1.42, 19054.86]]}, {"timestamp": 1631435094388, "ltp": 1.42, "tv": 231599.08, "trd": NaN, "batb": [[0, 1.41, 1479.33]], "batl": NaN}, {"timestamp": 1631435108051, "ltp": 1.42, "tv": 231599.08, "trd": NaN, "batb": [[0, 1.41, 1598.9]], "batl": NaN}, {"timestamp": 1631435149423, "ltp": 1.42, "tv": 231599.08, "trd": NaN, "batb": [[2, 1.39, 18610.76]], "batl": NaN}, {"timestamp": 1631435150716, "ltp": 1.42, "tv": 231599.08, "trd": NaN, "batb": [[0, 1.41, 1838.74], [1, 1.4, 15128.43]], "batl": [[0, 1.42, 19232.37]]}, {"timestamp": 1631435151461, "ltp": 1.42, "tv": 231599.08, "trd": NaN, "batb": NaN, "batl": [[1, 1.43, 1891.25]]}, {"timestamp": 1631435206473, "ltp": 1.42, "tv": 231599.08, "trd": NaN, "batb": [[0, 1.41, 1874.71]], "batl": NaN}, {"timestamp": 1631435222598, "ltp": 1.42, "tv": 231599.08, "trd": NaN, "batb": [[0, 1.41, 2356.71]], "batl": NaN}, {"timestamp": 1631435245627, "ltp": 1.42, "tv": 231753.08, "trd": [[1.42, 94485.2]], "batb": NaN, "batl": [[0, 1.42, 19155.37]]}, {"timestamp": 1631435255366, "ltp": 1.42, "tv": 231753.08, "trd": NaN, "batb": [[0, 1.41, 2434.4]], "batl": NaN}, {"timestamp": 1631435264286, "ltp": 1.42, "tv": 231855.19, "trd": [[1.42, 94587.3]], "batb": NaN, "batl": [[0, 1.42, 19104.32]]}, {"timestamp": 1631435307334, "ltp": 1.42, "tv": 231855.19, "trd": NaN, "batb": [[0, 1.41, 2437.85]], "batl": NaN}, {"timestamp": 1631435344614, "ltp": 1.41, "tv": 232009.41, "trd": [[1.41, 95002.25]], "batb": [[0, 1.41, 2360.74]], "batl": [[0, 1.42, 19182.7