{"info": {"id": "1.188134680", "eventId": "30941304", "eventName": "Match Odds", "marketType": "MATCH_ODDS", "openDate": 1632568990303, "name": "Huesler v Van Rijthoven", "numberOfActiveRunner": 2, "countryCode": "", "sport": "TENNIS", "venue": "", "volume": {"total": 75334.06, "preMatch": 52.45, "inPlay": 75281.61}, "winner": {"id": 9631939, "name": "Marc-Andrea Huesler", "status": "WINNER", "position": 1}, "delay": 3}, "runners": [{"id": 9631939, "name": "Marc-Andrea Huesler", "status": "WINNER", "position": 1, "inPlayOdds": 2.12, "inPlayTime": 1632568990303, "avgPrematch": 2.12, "closedOdds": 1.01, "maxPrematch": 2.12, "minPrematch": 2.12, "maxInPlay": 6.2, "minInPlay": 1.01, "inPlayIndex": 34, "lengthOdds": 3016, "lengthOddsPrematch": 34, "lengthOddsInPlay": 2982, "tradedVolume": 26157.55, "preMatchVolume": 7.96, "inPlayVolume": 26149.59}, {"id": 8681938, "name": "Tim Van Rijthoven", "status": "LOSER", "position": 2, "inPlayOdds": 1.87, "inPlayTime": 1632568990303, "avgPrematch": 1.93, "closedOdds": 36.0, "maxPrematch": 1.99, "minPrematch": 1.84, "maxInPlay": 50.0, "minInPlay": 1.15, "inPlayIndex": 78, "lengthOdds": 3306, "lengthOddsPrematch": 78, "lengthOddsInPlay": 3228, "tradedVolume": 49176.51, "preMatchVolume": 44.49, "inPlayVolume": 49132.02}], "marketUpdates": [{"timestamp": 1632505031897000000, "openDate": "2021-09-25T12:00:00.000Z", "status": "OPEN", "betDelay": 0, "inPlay": false, "complete": true}, {"timestamp": 1632563530339000000, "openDate": "2021-09-25T11:50:00.000Z", "status": "OPEN", "betDelay": 0, "inPlay": false, "complete": true}, {"timestamp": 1632567127743000000, "openDate": "2021-09-25T11:07:00.000Z", "status": "OPEN", "betDelay": 0, "inPlay": false, "complete": true}, {"timestamp": 1632567727981000000, "openDate": "2021-09-25T11:15:00.000Z", "status": "OPEN", "betDelay": 0, "inPlay": false, "complete": true}, {"timestamp": 1632568029128000000, "openDate": "2021-09-25T11:06:00.000Z", "status": "OPEN", "betDelay": 0, "inPlay": false, "complete": true}, {"timestamp": 1632568990303000000, "openDate": "2021-09-25T11:06:00.000Z", "status": "OPEN", "betDelay": 3, "inPlay": true, "complete": true}, {"timestamp": 1632575688229000000, "openDate": "2021-09-25T11:06:00.000Z", "status": "SUSPENDED", "betDelay": 3, "inPlay": true, "complete": true}, {"timestamp": 1632575740198000000, "openDate": "2021-09-25T11:06:00.000Z", "status": "CLOSED", "betDelay": 3, "inPlay": true, "complete": true}], "odds": [{"runnerId": 9631939, "odds": [{"timestamp": 1632560549710, "ltp": 2.12, "tv": 7.96, "trd": [[2.12, 7.96]], "batb": NaN, "batl": NaN}, {"timestamp": 1632562652317, "ltp": 2.12, "tv": 7.96, "trd": NaN, "batb": NaN, "batl": [[0, 2.2, 25], [1, 2.42, 2.06], [2, 46, 29]]}, {"timestamp": 1632562652422, "ltp": 2.12, "tv": 7.96, "trd": NaN, "batb": NaN, "batl": [[0, 2.2, 44.19]]}, {"timestamp": 1632563628308, "ltp": 2.12, "tv": 7.96, "trd": NaN, "batb": [[2, 1.83, 51.37]], "batl": NaN}, {"timestamp": 1632564008334, "ltp": 2.12, "tv": 7.96, "trd": NaN, "batb": NaN, "batl": [[1, 46, 29], [2, 990, 2.2]]}, {"timestamp": 1632564008603, "ltp": 2.12, "tv": 7.96, "trd": NaN, "batb": NaN, "batl": [[1, 2.42, 2.06], [2, 46, 29]]}, {"timestamp": 1632564046186, "ltp": 2.12, "tv": 7.96, "trd": NaN, "batb": [[1, 2, 31.25]], "batl": NaN}, {"timestamp": 1632564089639, "ltp": 2.12, "tv": 7.96, "trd": NaN, "batb": [[0, 2, 31.25], [1, 1.83, 51.37], [2, 1.51, 15.52]], "batl": NaN}, {"timestamp": 1632564092093, "ltp": 2.12, "tv": 7.96, "trd": NaN, "batb": [[0, 2, 46.37]], "batl": NaN}, {"timestamp": 1632564676185, "ltp": 2.12, "tv": 7.96, "trd": NaN, "batb": [[0, 2.02, 4.79], [1, 2, 46.37], [2, 1.83, 51.37]], "batl": NaN}, {"timestamp": 1632566102029, "ltp": 2.12, "tv": 7.96, "trd": NaN, "batb": NaN, "batl": [[0, 2.2, 43.88]]}, {"timestamp": 1632567000652, "ltp": 2.12, "tv": 7.96, "trd": NaN, "batb": [[0, 2.02, 17.4]], "batl": NaN}, {"timestamp": 1632567472919, "ltp": 2.12, "tv": 7.96, "trd": NaN, "batb": [[0, 2.04, 2.65], [1, 2.02, 17.4], [2, 2, 46.37]], "batl": NaN}, {"timestamp": 1632567608959, "ltp": 2.12, "tv": 7.96, "trd": NaN, "batb": NaN, "batl": [[1, 46, 29], [2, 990, 2.2]]}, {"timestamp": 1632567633283, "ltp": 2.12, "tv": 7.96, "trd": NaN, "batb": NaN, "batl": [[0, 2.2, 25]]}, {"timestamp": 1632567651496, "ltp": 2.12, "tv": 7.96, "trd": NaN, "batb": NaN, "batl": [[0, 2.2, 43.88]]}, {"timestamp": 1632567691721, "ltp": 2.12, "tv": 7.96, "trd": NaN, "batb": [[1, 2.02, 12.61]], "batl": NaN}, {"timestamp": 1632567721655, "ltp": 2.12, "tv": 7.96, "trd": NaN, "batb": NaN, "batl": [[1, 5.8, 2.54], [2, 46, 29]]}, {"timestamp": 1632567792194, "ltp": 2.12, "tv": 7.96, "trd": NaN, "batb": [[1, 2.02, 18.93]], "batl": NaN}, {"timestamp": 1632567880814, "ltp": 2.12, "tv": 7.96, "trd": NaN, "batb": [[1, 2.02, 6.33], [2, 2, 59.23]], "batl": NaN}, {"timestamp": 1632568067339, "ltp": 2.12, "tv": 7.96, "trd": NaN, "batb": NaN, "batl": [[0, 2.18, 2], [1, 2.2, 43.88], [2, 5.8, 2.54]]}, {"timestamp": 1632568090357, "ltp": 2.12, "tv": 7.96, "trd": NaN, "batb": [[0, 2.04, 182.24], [1, 2.02, 18.93]], "batl": [[1, 2.2, 25], [2, 2.44, 7.31]]}, {"timestamp": 1632568090778, "ltp": 2.12, "tv": 7.96, "trd": NaN, "batb": [[2, 2, 39.22]], "batl": NaN}, {"timestamp": 1632568092696, "ltp": 2.12, "tv": 7.96, "trd": NaN, "batb": NaN, "batl": [[0, 2.18, 16.92]]}, {"timestamp": 1632568096579, "ltp": 2.12, "tv": 7.96, "trd": NaN, "batb": [[0, 2.04, 201.86]], "batl": NaN}, {"timestamp": 1632568593512, "ltp": 2.12, "tv": 7.96, "trd": NaN, "batb": [[1, 2.02, 21.15]], "batl": NaN}, {"timestamp": 1632568698359, "ltp": 2.12, "tv": 7.96, "trd": NaN, "batb": [[1, 2.02, 8.54]], "batl": NaN}, {"timestamp": 1632568720150, "ltp": 2.12, "tv": 7.96, "trd": NaN, "batb": NaN, "batl": [[0, 2.12, 4], [1, 2.18, 2], [2, 2.2, 25]]}, {"timestamp": 1632568747079, "ltp": 2.12, "tv": 7.96, "trd": NaN, "batb": [[1, 2, 39.22], [2, 1.9, 166.67]], "batl": NaN}, {"timestamp": 1632568755612, "ltp": 2.12, "tv": 7.96, "trd": NaN, "batb": [[2, 1.98, 5]], "batl": [[0, 2.18, 2], [1, 2.2, 25], [2, 2.44, 7.31]]}, {"timestamp": 1632568783360, "ltp": 2.12, "tv": 7.96, "trd": NaN, "batb": [[1, 2.02, 12.61], [2, 2, 39.22]], "batl": NaN}, {"timestamp": 1632568878573, "ltp": 2.12, "tv": 7.96, "trd": NaN, "batb": NaN, "batl": [[1, 2.2, 25.2]]}, {"timestamp": 1632568975978, "ltp": 2.12, "tv": 7.96, "trd": NaN, "batb": NaN, "batl": [[0, 2.14, 39.98], [1, 2.18, 2], [2, 2.2, 25.2]]}, {"timestamp": 1632568976565, "ltp": 2.12, "tv": 7.96, "trd": NaN, "batb": [[1, 2, 39.22], [2, 1.99, 4]], "batl": NaN}, {"timestamp": 1632568990303, "ltp": 2.12, "tv": 7.96, "trd": NaN, "batb": [[0, 2, 26.36], [1, 1.25, 29.25], [2, 1.01, 618.28]], "batl": [[0, 5.8, 2.73], [1, 2.18, 0], [2, 2.2, 0]]}, {"timestamp": 1632568998698, "ltp": 2.12, "tv": 7.96, "trd": NaN, "batb": [[2, 1.03, 439.76]], "batl": NaN}, {"timestamp": 1632569008080, "ltp": 2.12, "tv": 7.96, "trd": NaN, "batb": [[1, 1.92, 108.56], [2, 1.75, 144.75]], "batl": [[0, 2.82, 206.81], [1, 5.8, 2.54]]}, {"timestamp": 1632569011289, "ltp": 2.0, "tv": 22.96, "trd": [[2, 15]], "batb": [[0, 2, 16.36]], "batl": [[0, 2.02, 37.77], [1, 2.1, 2], [2, 2.82, 206.81]]}, {"timestamp": 1632569011514, "ltp": 2.0, "tv": 22.96, "trd": NaN, "batb": NaN, "batl": [[0, 2.1, 2], [1, 5.8, 2.73], [2, 2.82, 0]]}, {"timestamp": 1632569014116, "ltp": 2.0, "tv": 55.68, "trd": [[2, 47.72]], "batb": [[0, 1.92, 108.56], [1, 1.75, 144.75], [2, 1.25, 29.25]], "batl": NaN}, {"timestamp": 1632569014805, "ltp": 2.0, "tv": 55.68, "trd": NaN, "batb": NaN, "batl": [[0, 2.08, 98.71], [1, 2.1, 2], [2, 5.8, 2.73]]}, {"timestamp": 1632569017096, "ltp": 2.0, "tv": 55.68, "trd": NaN, "batb": [[0, 1.75, 144.75], [1, 1.25, 29.25], [2, 1.11, 239.87]], "batl": [[0, 5.8, 2.73], [1, 2.1, 0], [2, 5.8, 0]]}, {"timestamp": 1632569017932, "ltp": 2.0, "tv": 55.68, "trd": NaN, "batb": [[2, 1.2, 343.02]], "batl": NaN}, {"timestamp": 1632569020220, "ltp": 2.0, "tv": 55.68, "trd": NaN, "batb": [[0, 1.75, 149.75], [1, 1.74, 4], [2, 1.25, 29.25]], "batl": NaN}, {"timestamp": 1632569030218, "ltp": 2.0, "tv": 55.68, "trd": NaN, "batb": [[0, 1.99, 193.11], [1, 1.85, 1327.22], [2, 1.84, 122.85]], "batl": [[0, 2.22, 13.71], [1, 5.8, 2.54]]}, {"timestamp": 1632569030847, "ltp": 2.0, "tv": 55.68, "trd": NaN, "batb": [[1, 1.84, 122.85], [2, 1.75, 5]], "batl": NaN}, {"timestamp": 1632569032229, "ltp": 2.0, "tv": 55.68, "trd": NaN, "batb": [[2, 1.76, 4]], "batl": [[0, 2.08, 4], [1, 2.22, 13.71], [2, 5.8, 2.54]]}, {"timestamp": 1632569042351, "ltp": 2.02, "tv": 70.53, "trd": [[2.02, 14.85]], "batb": [[1, 1.95, 304.85], [2, 1.93, 304.97]], "batl": [[0, 2.04, 263.12], [1, 2.08, 4], [2, 2.22, 13.71]]}, {"timestamp": 1632569045358, "ltp": 2.02, "tv": 70.53, "trd": NaN, "batb": NaN, "batl": [[0, 2.04, 466.29], [1, 2.06, 255.71], [2, 5.8, 2.73]]}, {"timestamp": 1632569045461, "ltp": 2.02, "tv": 70.53, "trd": NaN, "batb": [[0, 1.84, 122.85], [1, 1.76, 4], [2, 1.5, 94.99]], "batl": [[0, 5.8, 2.73], [1, 2.06, 0], [2, 5.8, 0]]}, {"timestamp": 1632569049261, "ltp": 2.02, "tv": 70.53, "trd": NaN, "batb": [[0, 1.84, 127.85], [1, 1.83, 5], [2, 1.81, 353.27]], "batl": [[0, 2.1, 309.06], [1, 2.12, 235.36], [2, 2.2, 4.2]]}, {"timestamp": 1632569050063, "ltp": 2.02, "tv": 70.53, "trd": NaN, "batb": [[0, 1.92, 325.28], [1, 1.9, 320.27], [2, 1.84, 127.85]], "batl": [[0, 1.99, 232.54], [1, 2.02, 408.29]]}, {"timestamp": 1632569053675, "ltp": 1.92, "tv": 76.44, "trd": [[1.92, 5.91]], "batb": [[0, 1.92, 319.37]], "batl": NaN}, {"timestamp": 1632569054853, "ltp": 1.92, "tv": 76.44, "trd": NaN, "batb": [[0, 1.84, 127.85], [1, 1.83, 5], [2, 1.76, 4]], "batl": [[0, 2.2, 4.2], [1, 5.8, 2.54], [2, 2.2, 0]]}, {"timestamp": 1632569057769, "ltp": 1.92, "tv": 76.44, "trd": NaN, "batb": [[2, 1.81, 349.8]], "batl": [[0, 2.1, 312.05], [1, 2.12, 235.37], [2, 2.2, 4.2]]}, {"timestamp": 1632569065192, "ltp": 1.92, "tv": 76.44, "trd": NaN, "batb": [[2, 1.76, 4]], "batl": [[0, 2.2, 4.2], [1, 5.8, 2.54], [2, 2.2, 0]]}, {"timestamp": 1632569065466, "ltp": 1.92, "tv": 76.44, "trd": NaN, "batb": [[1, 1.5, 94.99], [2, 1.4, 131.93]], "batl": NaN}, {"timestamp": 1632569068222, "ltp": 1.92, "tv": 76.44, "trd": NaN, "batb": [[0, 2, 1195.31], [1, 1.99, 1160.15], [2, 1.98, 1160.15]], "batl": NaN}, {"timestamp": 1632569069233, "ltp": 1.92, "tv": 76.44, "trd": NaN, "batb": [[0, 2.06, 172.57], [1, 2, 478.12], [2, 1.99, 464.06]], "batl": [[1, 2.3, 13.04], [2, 5.8, 2.54]]}, {"timestamp": 1632569071113, "ltp": 1.92, "tv": 76.44, "trd": NaN, "batb": NaN, "batl": [[0, 2.14, 4], [1, 2.18, 3], [2, 2.2, 4.2]]}, {"timestamp": 1632569075045, "ltp": 1.92, "tv": 76.44, "trd": NaN, "batb": NaN, "batl": [[2, 2.2, 210.62]]}, {"timestamp": 1632569082928, "ltp": 1.92, "tv": 76.44, "trd": NaN, "batb": NaN, "batl": [[0, 2.1, 177.42], [1, 2.14, 4], [2, 2.2, 206.62]]}, {"timestamp": 1632569084516, "ltp": 1.92, "tv": 76.44, "trd": NaN, "batb": [[1, 2.04, 204], [2, 2, 478.12]], "batl": NaN}, {"timestamp": 1632569093257, "ltp": 1.92, "tv": 76.44, "trd": NaN, "batb": [[0, 1.98, 3], [1, 1.97, 5], [2, 1.94, 325.11]], "batl": [[0, 2.2, 206.62], [1, 2.22, 190.7], [2, 5.8, 2.54]]}, {"timestamp": 1632569096580, "ltp": 1.92, "tv": 76.44, "trd": NaN, "batb": NaN, "batl": [[0, 2.2, 209.62]]}, {"timestamp": 1632569100172, "ltp": 1.92, "tv": 76.44, "trd": NaN, "batb": [[1, 1.94, 325.11], [2, 1.93, 218.87]], "batl": [[0, 2.2, 3.2], [1, 5.8, 2.54], [2, 5.8, 0]]}, {"timestamp": 1632569103188, "ltp": 1.92, "tv": 76.44, "trd": NaN, "batb": [[0, 1.94, 325.11], [1, 1.93, 218.87], [2, 1.91, 293.72]], "batl": [[0, 1.98, 276.61], [1, 2, 278.96], [2, 2.18, 13.76]]}, {"timestamp": 1632569104192, "ltp": 1.98, "tv": 91.59, "trd": [[1.98, 15.15]], "batb": NaN, "batl": [[0, 1.98, 261.46]]}, {"timestamp": 1632569106310, "ltp": 1.98, "tv": 91.59, "trd": NaN, "batb": NaN, "batl": [[0, 1.98, 263.81], [2, 2.16, 3]]}, {"timestamp": 1632569108225, "ltp": 1.98, "tv": 128.42, "trd": [[1.98, 51.98]], "batb": NaN, "batl": [[0, 1.98, 226.98]]}, {"timestamp": 1632569109188, "ltp": 1.98, "tv": 128.42, "trd": NaN, "batb": [[0, 1.95, 786], [1, 1.94, 325.11], [2, 1.93, 218.87]], "batl": NaN}, {"timestamp": 1632569110025, "ltp": 1.98, "tv": 128.42, "trd": NaN, "batb": NaN, "batl": [[2, 2.1, 170.59]]}, {"timestamp": 1632569111402, "ltp": 1.98, "tv": 128.42, "trd": NaN, "batb": NaN, "batl": [[0, 1.98, 254.23]]}, {"timestamp": 1632569116339, "ltp": 1.98, "tv": 128.42, "trd": NaN, "batb": NaN, "batl": [[0, 1.98, 251.88]]}, {"timestamp": 1632569116813, "ltp": 1.98, "tv": 128.42, "trd": NaN, "batb": [[1, 1.77, 174.06], [2, 1.76, 259.25]], "batl": [[0, 2.1, 170.59], [1, 2.12, 234.2], [2, 2.16, 3]]}, {"timestamp": 1632569117720, "ltp": 1.98, "tv": 128.42, "trd": NaN, "batb": [[0, 1.77, 174.06], [1, 1.76, 259.25], [2, 1.75, 145.43]], "batl": NaN}, {"timestamp": 1632569119726, "ltp": 1.98, "tv": 128.42, "trd": NaN, "batb": NaN, "batl": [[0, 2.08, 243.43], [1, 2.1, 412.44], [2, 2.12, 234.2]]}, {"timestamp": 1632569120900, "ltp": 1.98, "tv": 128.42, "trd": NaN, "batb": [[0, 1.77, 178.06], [1, 1.76, 263.25]], "batl": NaN}, {"timestamp": 1632569127304, "ltp": 1.98, "tv": 128.42, "trd": NaN, "batb": NaN, "batl": [[0, 1.95, 2.35], [1, 2.08, 243.43], [2, 2.1, 412.44]]}, {"timestamp": 1632569133346, "ltp": 1.98, "tv": 128.42, "trd": NaN, "batb": [[0, 1.77, 4], [1, 1.76, 4]], "batl": NaN}, {"timestamp": 1632569133556, "ltp": 1.98, "tv": 128.42, "trd": NaN, "batb": [[1, 1.75, 145.43], [2, 1.4, 131.93]], "batl": [[1, 2.1, 170.59], [2, 2.12, 234.2]]}, {"timestamp": 1632569136256, "ltp": 1.95, "tv": 133.12, "trd": [[1.95, 4.7]], "batb": [[0, 1.99, 1922.1], [1, 1.98, 1863.23], [2, 1.97, 1865.58]], "batl": [[0, 2.1, 170.59], [1, 2.12, 234.2], [2, 2.16, 3]]}, {"timestamp": 1632569137378, "ltp": 1.95, "tv": 133.12, "trd": NaN, "batb": [[0, 2.02, 180.77], [1, 1.99, 480.52], [2, 1.98, 466.4]], "batl": NaN}, {"timestamp": 1632569150160, "ltp": 1.95, "tv": 133.12, "trd": NaN, "batb": [[0, 1.91, 109.83], [1, 1.77, 4], [2, 1.5, 94.99]], "batl": [[0, 5.8, 2.73], [1, 2.12, 0], [2, 2.16, 0]]}, {"timestamp": 1632569153393, "ltp": 1.95, "tv": 133.12, "trd": NaN, "batb": [[0, 1.91, 113.83], [1, 1.9, 4], [2, 1.77, 4]], "batl": [[0, 2.18, 4], [1, 5.8, 2.73]]}, {"timestamp": 1632569155375, "ltp": 1.95, "tv": 133.12, "trd": NaN, "batb": [[0, 2.1, 1047], [1, 2.08, 111.9], [2, 2.06, 335.71]], "batl": NaN}, {"timestamp": 1632569156377, "ltp": 1.95, "tv": 133.12, "trd": NaN, "batb": [[0, 2.1, 764.09], [2, 2.06, 111.9]], "batl": [[1, 2.4, 12.7], [2, 5.8, 2.54]]}, {"timestamp": 1632569160286, "ltp": 2.1, "tv": 270.26, "trd": [[2.1, 137.14]], "batb": [[0, 2.1, 695.52]], "batl": NaN}, {"timestamp": 1632569162305, "ltp": 2.1, "tv": 270.26, "trd": NaN, "batb": NaN, "batl": [[1, 2.22, 13.78], [2, 2.32, 167.75]]}, {"timestamp": 1632569172186, "ltp": 2.1, "tv": 274.96, "trd": [[2.1, 141.84]], "batb": [[0, 2.1, 693.17]], "batl": NaN}, {"timestamp": 1632569211323, "ltp": 2.1, "tv": 274.96, "trd": NaN, "batb": [[0, 2.02, 388.87], [1, 2, 265.07], [2, 1.5, 94.99]], "batl": [[0, 2.22, 13.78], [1, 2.32, 167.75], [2, 2.34, 167.85]]}, {"timestamp": 1632569212334, "ltp": 2.1, "tv": 274.96, "trd": NaN, "batb": [[0, 2.02, 374.17]], "batl": [[0, 2.32, 167.94], [1, 2.34, 167.85], [2, 5.8, 2.54]]}, {"timestamp": 1632569215489, "ltp": 2.1, "tv": 274.96, "trd": NaN, "batb": NaN, "batl": [[0, 2.3, 2.2], [1, 2.32, 167.75], [2, 2.34, 167.85]]}, {"timestamp": 1632569217612, "ltp": 2.1, "tv": 274.96, "trd": NaN, "batb": [[0, 2.02, 181.02], [1, 2, 3]], "batl": NaN}, {"timestamp": 1632569220322, "ltp": 2.3, "tv": 370.45, "trd": [[2.2, 0.2], [2.3, 95.3]], "batb": NaN, "batl": [[0, 2.32, 167.75], [1, 2.34, 167.85], [2, 2.46, 12.14]]}, {"timestamp": 1632569221333, "ltp": 2.3, "tv": 370.45, "trd": NaN, "batb": [[0, 2.14, 13.15], [1, 2.02, 181.02], [2, 2, 3]], "batl": [[0, 2.34, 167.85], [1, 2.42, 12.58]]}, {"timestamp": 1632569222203, "ltp": 2.3, "tv": 370.45, "trd": NaN, "batb": [[0, 2.26, 133.84], [1, 2.16, 152.36], [2, 2.14, 13.15]], "batl": NaN}, {"timestamp": 1632569224010, "ltp": 2.3, "tv": 370.45, "trd": NaN, "batb": [[2, 2.14, 17.15]], "batl": NaN}, {"timestamp": 1632569225336, "ltp": 2.3, "tv": 370.45, "trd": NaN, "batb": [[1, 2.16, 359.98]], "batl": [[2, 2.46, 78.81]]}, {"timestamp": 1632569225809, "ltp": 2.3, "tv": 370.45, "trd": NaN, "batb": NaN, "batl": [[2, 2.46, 12.14]]}, {"timestamp": 1632569227028, "ltp": 2.3, "tv": 370.45, "trd": NaN, "batb": [[1, 2.16, 152.36], [2, 2.14, 4]], "batl": NaN}, {"timestamp": 1632569228032, "ltp": 2.3, "tv": 370.45, "trd": NaN, "batb": [[1, 2.16, 347.63], [2, 2.14, 224.61]], "batl": NaN}, {"timestamp": 1632569230215, "ltp": 2.3, "tv": 370.45, "trd": NaN, "batb": [[1, 2.18, 12.71], [2, 2.16, 347.63]], "batl": NaN}, {"timestamp": 1632569230529, "ltp": 2.3, "tv": 370.45, "trd": NaN, "batb": NaN, "batl": [[2, 2.56, 11.72]]}, {"timestamp": 1632569233842, "ltp": 2.3, "tv": 381.19, "trd": [[2.3, 106.04]], "batb": NaN, "batl": NaN}, {"timestamp": 1632569239075, "ltp": 2.3, "tv": 381.19, "trd": NaN, "batb": [[0, 2.18, 12.71], [1, 2.16, 347.63], [2, 2.14, 220.61]], "batl": [[0, 2.42, 12.58], [1, 2.58, 133.98], [2, 2.6, 183.28]]}, {"timestamp": 1632569240363, "ltp": 2.3, "tv": 381.19, "trd": NaN, "batb": [[0, 2.16, 347.63], [1, 2.14, 220.61], [2, 2.12, 4]], "batl": [[0, 2.58, 133.98], [1, 2.6, 183.28], [2, 5.8, 2.54]]}, {"timestamp": 1632569241371, "ltp": 2.3, "tv": 381.19, "trd": NaN, "batb": NaN, "batl": [[0, 5.8, 2.54], [1, 2.6, 0], [2, 5.8, 0]]}, {"timestamp": 1632569244353, "ltp": 2.3, "tv": 381.19, "trd": NaN, "batb": [[0, 2.16, 226.78], [2, 1.6, 87.96]], "batl": [[0, 2.24, 14.11], [1, 2.44, 12.3], [2, 5.8, 2.54]]}, {"timestamp": 1632569245359, "ltp": 2.3, "tv": 381.19, "trd": NaN, "batb": [[2, 2.06, 172.74]], "batl": [[0, 2.44, 12.3], [1, 5.8, 2.54], [2, 5.8, 0]]}, {"timestamp": 1632569246264, "ltp": 2.3, "tv": 381.19, "trd": NaN, "batb": [[2, 2.08, 13.88]], "batl": [[0, 2.32, 13.05], [1, 2.44, 12.3], [2, 5.8, 2.54]]}, {"timestamp": 1632569246778, "ltp": 2.3, "tv": 381.19, "trd": NaN, "batb": NaN, "batl": [[2, 2.56, 4]]}, {"timestamp": 1632569248046, "ltp": 2.3, "tv": 381.19, "trd": NaN, "batb": NaN, "batl": [[0, 2.24, 14.11], [1, 2.32, 13.05], [2, 2.44, 12.3]]}, {"timestamp": 1632569249250, "ltp": 2.3, "tv": 381.19, "trd": NaN, "batb": NaN, "batl": [[1, 2.32, 77.06]]}, {"timestamp": 1632569249880, "ltp": 2.3, "tv": 381.19, "trd": NaN, "batb": NaN, "batl": [[0, 2.22, 180.85], [1, 2.24, 14.11], [2, 2.32, 13.05]]}, {"timestamp": 1632569251569, "ltp": 2.3, "tv": 381.19, "trd": NaN, "batb": NaN, "batl": [[1, 2.24, 183.82]]}, {"timestamp": 1632569252689, "ltp": 2.3, "tv": 381.19, "trd": NaN, "batb": NaN, "batl": [[2, 2.36, 166.41]]}, {"timestamp": 1632569255904, "ltp": 2.3, "tv": 381.19, "trd": NaN, "batb": NaN, "batl": [[2, 2.3, 13.15]]}, {"timestamp": 1632569257881, "ltp": 2.3, "tv": 381.19, "trd": NaN, "batb": [[0, 2.08, 13.88], [1, 2.06, 172.74], [2, 2.02, 202.62]], "batl": [[0, 2.3, 13.15], [1, 2.36, 166.41], [2, 2.38, 187.08]]}, {"timestamp": 1632569259296, "ltp": 2.3, "tv": 381.19, "trd": NaN, "batb": [[0, 2.06, 172.74], [1, 2.02, 202.62], [2, 2, 207.42]], "batl": [[0, 2.36, 166.41], [1, 2.38, 187.08], [2, 2.56, 4]]}, {"timestamp": 1632569262599, "ltp": 2.3, "tv": 381.19, "trd": NaN, "batb": [[0, 2.06, 176.74], [1, 2.04, 4], [2, 2.02, 202.62]], "batl": [[0, 2.56, 4], [1, 5.8, 2.54], [2, 2.56, 0]]}, {"timestamp": 1632569265304, "ltp": 2.3, "tv": 381.19, "trd": NaN, "batb": [[0, 2.06, 252.43]], "batl": [[0, 2.2, 104.66], [1, 2.32, 12.93], [2, 2.56, 4]]}, {"timestamp": 1632569266317, "ltp": 2.08, "tv": 381.58, "trd": [[2.08, 0.39]], "batb": [[0, 2.06, 248.43], [1, 2.02, 202.62], [2, 2, 207.42]], "batl": [[0, 2.12, 11.06], [1, 2.2, 104.27], [2, 2.32, 12.93]]}, {"timestamp": 1632569267383, "ltp": 2.08, "tv": 381.58, "trd": NaN, "batb": [[1, 2.02, 387.2], [2, 2, 222.42]], "batl": [[2, 2.22, 13.58]]}, {"timestamp": 1632569268493, "ltp": 2.08, "tv": 381.58, "trd": NaN, "batb": NaN, "batl": [[1, 2.18, 3], [2, 2.2, 104.27]]}, {"timestamp": 1632569273807, "ltp": 2.08, "tv": 381.58, "trd": NaN, "batb": NaN, "batl": [[2, 2.2, 117.96]]}, {"timestamp": 1632569279327, "ltp": 2.08, "tv": 381.58, "trd": NaN, "batb": [[0, 2.06, 172.74], [1, 2.02, 184.57], [2, 2, 15]], "batl": [[0, 2.18, 3], [1, 2.2, 13.69], [2, 2.24, 204.16]]}, {"timestamp": 1632569279705, "ltp": 2.08, "tv": 381.58, "trd": NaN, "batb": [[0, 2.02, 184.57], [1, 2, 15], [2, 1.99, 5]], "batl": NaN}, {"timestamp": 1632569281292, "ltp": 2.08, "tv": 381.58, "trd": NaN, "batb": [[1, 1.99, 5], [2, 1.97, 169.81]], "batl": [[0, 2.24, 204.16], [1, 2.26, 204.78], [2, 2.72, 246.41]]}, {"timestamp": 1632569283800, "ltp": 2.08, "tv": 381.58, "trd": NaN, "batb": [[0, 2.02, 187.57], [1, 2, 3], [2, 1.99, 5]], "batl": NaN}, {"timestamp": 1632569302230, "ltp": 2.08, "tv": 381.58, "trd": NaN, "batb": NaN, "batl": [[0, 2.72, 246.41], [1, 5.8, 2.54], [2, 2.72, 0]]}, {"timestamp": 1632569303122, "ltp": 2.08, "tv": 381.58, "trd": NaN, "batb": [[0, 2.02, 3], [1, 1.97, 169.81], [2, 1.96, 225.75]], "batl": NaN}, {"timestamp": 1632569304121, "ltp": 2.08, "tv": 381.58, "trd": NaN, "batb": [[0, 1.97, 169.81], [1, 1.96, 225.75], [2, 1.67, 418.02]], "batl": [[0, 5.8, 2.54], [1, 5.8, 0]]}, {"timestamp": 1632569305349, "ltp": 2.08, "tv": 381.58, "trd": NaN, "batb": [[2, 1.93, 495.46]], "batl": [[0, 2.04, 11.5], [1, 2.12, 122.65], [2, 2.24, 13.39]]}, {"timestamp": 1632569306336, "ltp": 2.04, "tv": 393.08, "trd": [[2.02, 15.04], [2.04, 11.31]], "batb": [[0, 2, 186.18], [1, 1.98, 195.23], [2, 1.97, 169.81]], "batl": [[0, 2.12, 122.65], [1, 2.16, 13.92]]}, {"timestamp": 1632569310230, "ltp": 2.04, "tv": 393.08, "trd": NaN, "batb": NaN, "batl": [[1, 2.24, 13.39], [2, 2.34, 3]]}, {"timestamp": 1632569312126, "ltp": 2.04, "tv": 393.08, "trd": NaN, "batb": NaN, "batl": [[0, 2.02, 72.4], [1, 2.1, 201.52], [2, 2.12, 356.82]]}, {"timestamp": 1632569317360, "ltp": 2.04, "tv": 393.08, "trd": NaN, "batb": NaN, "batl": [[0, 2.1, 201.52], [1, 2.12, 356.82], [2, 2.14, 14.04]]}, {"timestamp": 1632569317572, "ltp": 2.04, "tv": 393.08, "trd": NaN, "batb": NaN, "batl": [[0, 2.06, 168], [1, 2.1, 201.52], [2, 2.12, 356.82]]}, {"timestamp": 1632569319255, "ltp": 2.04, "tv": 393.08, "trd": NaN, "batb": [[0, 2, 500.18]], "batl": [[0, 2.06, 175.67]]}, {"timestamp": 1632569319469, "ltp": 2.04, "tv": 393.08, "trd": NaN, "batb": [[0, 2, 186.18]], "batl": NaN}, {"timestamp": 1632569320468, "ltp": 2.0, "tv": 530.07, "trd": [[2, 176.9], [2.02, 22.85]], "batb": [[0, 2, 121.59]], "batl": NaN}, {"timestamp": 1632569322857, "ltp": 2.0, "tv": 530.07, "trd": NaN, "batb": [[0, 2, 121.78]], "batl": NaN}, {"timestamp": 1632569324186, "ltp": 2.0, "tv": 530.07, "trd": NaN, "batb": [[2, 1.94, 235.27]], "batl": [[0, 2.1, 201.52], [1, 2.12, 234.17], [2, 2.14, 14.04]]}, {"timestamp": 1632569325381, "ltp": 2.0, "tv": 671.73, "trd": [[2, 318.18], [2.02, 23.22]], "batb": [[0, 1.98, 195.23], [1, 1.94, 219.8], [2, 1.93, 215.47]], "batl": [[2, 2.34, 3]]}, {"timestamp": 1632569328278, "ltp": 2.0, "tv": 671.73, "trd": NaN, "batb": [[0, 1.98, 199.23], [1, 1.97, 3], [2, 1.94, 219.8]], "batl": [[0, 2.34, 3], [1, 2.5, 280.07], [2, 5.8, 2.54]]}, {"timestamp": 1632569329284, "ltp": 2.0, "tv": 671.73, "trd": NaN, "batb": [[0, 1.97, 3], [1, 1.94, 219.8], [2, 1.93, 215.47]], "batl": NaN}, {"timestamp": 1632569330283, "ltp": 2.0, "tv": 671.73, "trd": NaN, "batb": [[0, 1.94, 219.8], [1, 1.93, 215.47], [2, 1.67, 418.02]], "batl": NaN}, {"timestamp": 1632569331383, "ltp": 2.0, "tv": 671.73, "trd": NaN, "batb": NaN, "batl": [[0, 2, 5.92], [1, 2.02, 395.01], [2, 2.04, 70.31]]}, {"timestamp": 1632569332280, "ltp": 2.0, "tv": 671.73, "trd": NaN, "batb": [[0, 1.97, 199.2], [1, 1.94, 219.8], [2, 1.93, 215.47]], "batl": [[0, 2.02, 395.01], [1, 2.04, 70.31], [2, 2.08, 14.43]]}, {"timestamp": 1632569334470, "ltp": 2.0, "tv": 671.73, "trd": NaN, "batb": NaN, "batl": [[0, 2, 5.92], [1, 2.02, 395.01], [2, 2.04, 70.31]]}, {"timestamp": 1632569341605, "ltp": 2.0, "tv": 671.73, "trd": NaN, "batb": [[0, 1.98, 492], [1, 1.97, 199.2], [2, 1.94, 219.8]], "batl": NaN}, {"timestamp": 1632569343478, "ltp": 2.0, "tv": 677.65, "trd": [[2, 324.1]], "batb": NaN, "batl": [[0, 2.02, 395.01], [1, 2.04, 70.31], [2, 2.08, 213.52]]}, {"timestamp": 1632569345004, "ltp": 2.0, "tv": 677.65, "trd": NaN, "batb": NaN, "batl": [[0, 2.02, 598.51]]}, {"timestamp": 1632569347416, "ltp": 2.0, "tv": 677.65, "trd": NaN, "batb": [[2, 1.96, 294.39]], "batl": NaN}, {"timestamp": 1632569356289, "ltp": 2.0, "tv": 677.65, "trd": NaN, "batb": NaN, "batl": [[1, 2.04, 261.64]]}, {"timestamp": 1632569356603, "ltp": 2.0, "tv": 677.65, "trd": NaN, "batb": NaN, "batl": [[0, 2.02, 606.65]]}, {"timestamp": 1632569359194, "ltp": 2.0, "tv": 677.65, "trd": NaN, "batb": [[2, 1.9, 15.81]], "batl": [[0, 2.08, 213.52], [1, 2.1, 225], [2, 2.34, 3]]}, {"timestamp": 1632569360310, "ltp": 2.0, "tv": 677.65, "trd": NaN, "batb": [[0, 1.84, 123.53], [1, 1.83, 180.64], [2, 1.82, 196.76]], "batl": [[0, 2.08, 199.09]]}, {"timestamp": 1632569373213, "ltp": 2.0, "tv": 677.65, "trd": NaN, "batb": [[1, 1.67, 418.02], [2, 1.5, 94.99]], "batl": NaN}, {"timestamp": 1632569376355, "ltp": 2.0, "tv": 677.65, "trd": NaN, "batb": NaN, "batl": [[0, 2.1, 225], [1, 2.12, 13.37], [2, 2.16, 130.09]]}, {"timestamp": 1632569377267, "ltp": 2.0, "tv": 677.65, "trd": NaN, "batb": [[0, 2.02, 183.64], [1, 1.96, 15.3], [2, 1.91, 108.99]], "batl": [[2, 2.16, 144.01]]}, {"timestamp": 1632569379059, "ltp": 2.0, "tv": 677.65, "trd": NaN, "batb": [[1, 1.97, 3], [2, 1.96, 19.3]], "batl": NaN}, {"timestamp": 1632569381343, "ltp": 2.0, "tv": 677.65, "trd": NaN, "batb": [[1, 1.96, 19.3], [2, 1.91, 108.99]], "batl": NaN}, {"timestamp": 1632569382932, "ltp": 2.0, "tv": 677.65, "trd": NaN, "batb": [[2, 1.94, 209.51]], "batl": NaN}, {"timestamp": 1632569386325, "ltp": 2.0, "tv": 677.65, "trd": NaN, "batb": [[0, 1.96, 19.3], [1, 1.94, 209.51], [2, 1.93, 248.2]], "batl": [[0, 2.16, 13.92], [1, 2.18, 156.96], [2, 2.2, 176.42]]}, {"timestamp": 1632569387355, "ltp": 2.0, "tv": 677.65, "trd": NaN, "batb": [[0, 1.96, 4]], "batl": [[0, 2.18, 156.96], [1, 2.2, 176.42], [2, 2.34, 3]]}, {"timestamp": 1632569389329, "ltp": 2.0, "tv": 677.65, "trd": NaN, "batb": [[1, 1.91, 108.99], [2, 1.67, 418.02]], "batl": NaN}, {"timestamp": 1632569390543, "ltp": 2.0, "tv": 677.65, "trd": NaN, "batb": NaN, "batl": [[0, 2.18, 159.96]]}, {"timestamp": 1632569392351, "ltp": 2.0, "tv": 677.65, "trd": NaN, "batb": [[0, 2.06, 171.47], [1, 1.98, 195.82], [2, 1.96, 4]], "batl": [[1, 2.2, 190.59]]}, {"timestamp": 1632569393266, "ltp": 2.0, "tv": 677.65, "trd": NaN, "batb": [[1, 2, 19], [2, 1.99, 3]], "batl": [[2, 2.22, 13.58]]}, {"timestamp": 1632569399167, "ltp": 2.0, "tv": 677.65, "trd": NaN, "batb": [[1, 2.04, 204.36], [2, 2.02, 191.26]], "batl": NaN}, {"timestamp": 1632569407299, "ltp": 2.0, "tv": 677.65, "trd": NaN, "batb": NaN, "batl": [[1, 2.2, 176.42]]}, {"timestamp": 1632569408299, "ltp": 2.0, "tv": 677.65, "trd": NaN, "batb": [[0, 2.04, 204.36], [1, 2.02, 191.26], [2, 2, 4]], "batl": [[0, 2.18, 3], [1, 2.24, 162.49], [2, 2.26, 187.04]]}, {"timestamp": 1632569408570, "ltp": 2.0, "tv": 677.65, "trd": NaN, "batb": NaN, "batl": [[0, 2.24, 162.49], [1, 2.26, 187.04], [2, 2.82, 235.94]]}, {"timestamp": 1632569413021, "ltp": 2.0, "tv": 677.65, "trd": NaN, "batb": [[0, 2.04, 208.36], [1, 2.02, 196.26]], "batl": NaN}, {"timestamp": 1632569414206, "ltp": 2.0, "tv": 677.65, "trd": NaN, "batb": NaN, "batl": [[0, 2.24, 165.49]]}, {"timestamp": 1632569415800, "ltp": 2.0, "tv": 677.65, "trd": NaN, "batb": NaN, "batl": [[0, 2.22, 4], [1, 2.24, 165.49], [2, 2.26, 187.04]]}, {"timestamp": 1632569420314, "ltp": 2.0, "tv": 677.65, "trd": NaN, "batb": [[2, 1.99, 192.44]], "batl": NaN}, {"timestamp": 1632569421129, "ltp": 2.0, "tv": 677.65, "trd": NaN, "batb": [[0, 2.04, 4], [1, 2.02, 5]], "batl": NaN}, {"timestamp": 1632569422795, "ltp": 2.0, "tv": 677.65, "trd": NaN, "batb": [[0, 2.02, 5], [1, 1.99, 192.44], [2, 1.67, 418.02]], "batl": NaN}, {"timestamp": 1632569424196, "ltp": 2.0, "tv": 677.65, "trd": NaN, "batb": NaN, "batl": [[1, 2.24, 173.34]]}, {"timestamp": 1632569425299, "ltp": 2.0, "tv": 677.65, "trd": NaN, "batb": [[0, 2.12, 159.12], [1, 2.06, 14.15], [2, 2.04, 177.64]], "batl": NaN}, {"timestamp": 1632569427207, "ltp": 2.0, "tv": 677.65, "trd": NaN, "batb": [[1, 2.08, 374.96], [2, 2.06, 14.15]], "batl": NaN}, {"timestamp": 1632569427417, "ltp": 2.0, "tv": 677.65, "trd": NaN, "batb": NaN, "batl": [[1, 2.24, 170.34]]}, {"timestamp": 1632569431115, "ltp": 2.0, "tv": 677.65, "trd": NaN, "batb": [[1, 2.1, 200.6], [2, 2.08, 608.66]], "batl": [[2, 2.26, 341.6]]}, {"timestamp": 1632569431493, "ltp": 2.0, "tv": 677.65, "trd": NaN, "batb": [[2, 2.08, 233.7]], "batl": NaN}, {"timestamp": 1632569435028, "ltp": 2.16, "tv": 748.47, "trd": [[2.16, 70.83]], "batb": NaN, "batl": NaN}, {"timestamp": 1632569439120, "ltp": 2.16, "tv": 748.47, "trd": NaN, "batb": [[0, 2.1, 200.6], [1, 2.08, 233.7], [2, 2.06, 14.15]], "batl": [[0, 2.26, 154.56], [1, 2.28, 208.34], [2, 2.82, 235.94]]}, {"timestamp": 1632569440244, "ltp": 2.16, "tv": 748.47, "trd": NaN, "batb": [[2, 2.04, 177.64]], "batl": [[1, 2.28, 195.09]]}, {"timestamp": 1632569441383, "ltp": 2.16, "tv": 748.47, "trd": NaN, "batb": [[0, 2.04, 177.64], [1, 2.02, 5], [2, 1.67, 418.02]], "batl": NaN}, {"timestamp": 1632569442340, "ltp": 2.16, "tv": 748.47, "trd": NaN, "batb": NaN, "batl": [[0, 2.26, 157.56]]}, {"timestamp": 1632569444324, "ltp": 2.16, "tv": 748.47, "trd": NaN, "batb": [[2, 1.5, 94.99]], "batl": [[0, 2.22, 3], [1, 2.24, 11.12], [2, 2.26, 157.56]]}, {"timestamp": 1632569445236, "ltp": 2.16, "tv": 748.47, "trd": NaN, "batb": [[0, 2.16, 152.45], [1, 2.08, 181.88], [2, 2.04, 177.64]], "batl": [[0, 2.26, 157.56], [1, 2.28, 195.09], [2, 2.32, 13.05]]}, {"timestamp": 1632569448315, "ltp": 2.16, "tv": 748.47, "trd": NaN, "batb": [[2, 2.04, 1072.7]], "batl": [[0, 2.24, 11.12], [1, 2.26, 157.56], [2, 2.28, 195.09]]}, {"timestamp": 1632569449120, "ltp": 2.16, "tv": 748.47, "trd": NaN, "batb": [[2, 2.04, 177.64]], "batl": NaN}, {"timestamp": 1632569451155, "ltp": 2.16, "tv": 748.47, "trd": NaN, "batb": [[1, 2.08, 341.71], [2, 2.06, 206.38]], "batl": NaN}, {"timestamp": 1632569481253, "ltp": 2.22, "tv": 762.47, "trd": [[2.22, 14]], "batb": NaN, "batl": NaN}, {"timestamp": 1632569503093, "ltp": 2.18, "tv": 762.92, "trd": [[2.18, 0.45]], "batb": NaN, "batl": NaN}, {"timestamp": 1632569530614, "ltp": 2.18, "tv": 762.92, "trd": NaN, "batb": [[1, 2.08, 181.88], [2, 2.04, 177.64]], "batl": [[1, 2.26, 3], [2, 2.32, 13.05]]}, {"timestamp": 1632569540144, "ltp": 2.18, "tv": 762.92, "trd": NaN, "batb": NaN, "batl": [[1, 2.32, 13.05], [2, 2.44, 12.3]]}, {"timestamp": 1632569541217, "ltp": 2.18, "tv": 762.92, "trd": NaN, "batb": [[1, 2.08, 168]], "batl": [[1, 2.44, 12.3], [2, 2.82, 235.94]]}, {"timestamp": 1632569550231, "ltp": 2.18, "tv": 762.92, "trd": NaN, "batb": NaN, "batl": [[0, 2.82, 235.94], [1, 5.8, 2.54], [2, 2.82, 0]]}, {"timestamp": 1632569550551, "ltp": 2.18, "tv": 762.92, "trd": NaN, "batb": [[0, 2.02, 5], [1, 1.74, 412.43], [2, 1.6, 87.96]], "batl": NaN}, {"timestamp": 1632569553255, "ltp": 2.18, "tv": 762.92, "trd": NaN, "batb": [[0, 1.74, 412.43], [1, 1.6, 87.96], [2, 1.5, 94.99]], "batl": [[0, 2.16, 16.74], [1, 2.24, 120.91], [2, 2.82, 235.94]]}, {"timestamp": 1632569554360, "ltp": 2.18, "tv": 762.92, "trd": NaN, "batb": [[0, 2.02, 14.7], [1, 2, 4], [2, 1.74, 412.43]], "batl": [[1, 2.24, 134.38]]}, {"timestamp": 1632569555163, "ltp": 2.18, "tv": 762.92, "trd": NaN, "batb": NaN, "batl": [[2, 2.4, 1.71]]}, {"timestamp": 1632569556339, "ltp": 2.18, "tv": 762.92, "trd": NaN, "batb": [[2, 1.99, 4]], "batl": [[2, 2.38, 3]]}, {"timestamp": 1632569563875, "ltp": 2.18, "tv": 762.92, "trd": NaN, "batb": NaN, "batl": [[0, 2.24, 13.47], [1, 2.38, 3], [2, 2.4, 1.71]]}, {"timestamp": 1632569565288, "ltp": 2.18, "tv": 762.92, "trd": NaN, "batb": [[0, 2, 4], [1, 1.99, 4], [2, 1.74, 412.43]], "batl": [[0, 2.38, 3], [1, 2.8, 3], [2, 2.82, 235.94]]}, {"timestamp": 1632569567045, "ltp": 2.18, "tv": 762.92, "trd": NaN, "batb": [[0, 2.02, 4], [1, 2, 4], [2, 1.99, 4]], "batl": NaN}, {"timestamp": 1632569568773, "ltp": 2.18, "tv": 762.92, "trd": NaN, "batb": [[1, 1.74, 412.43], [2, 1.5, 94.99]], "batl": [[0, 2.3, 4], [1, 2.82, 235.94], [2, 5.8, 2.54]]}, {"timestamp": 1632569571944, "ltp": 2.18, "tv": 762.92, "trd": NaN, "batb": [[1, 2, 4], [2, 1.74, 412.43]], "batl": NaN}, {"timestamp": 1632569576875, "ltp": 2.18, "tv": 762.92, "trd": NaN, "batb": NaN, "batl": [[0, 2.3, 4.09]]}, {"timestamp": 1632569578351, "ltp": 2.18, "tv": 763.02, "trd": [[2.18, 0.54]], "batb": NaN, "batl": [[0, 2.3, 4], [1, 2.34, 408.66], [2, 2.36, 396.64]]}, {"timestamp": 1632569579260, "ltp": 2.18, "tv": 763.02, "trd": NaN, "batb": [[0, 2.12, 13.39], [1, 2.02, 4], [2, 2, 4]], "batl": NaN}, {"timestamp": 1632569581179, "ltp": 2.18, "tv": 763.02, "trd": NaN, "batb": [[1, 2.1, 3], [2, 2.08, 4]], "batl": NaN}, {"timestamp": 1632569584987, "ltp": 2.18, "tv": 763.02, "trd": NaN, "batb": [[0, 2.12, 23.26]], "batl": NaN}, {"timestamp": 1632569592312, "ltp": 2.18, "tv": 763.02, "trd": NaN, "batb": [[2, 1.74, 412.43]], "batl": [[1, 2.38, 12.76], [2, 2.82, 235.94]]}, {"timestamp": 1632569593259, "ltp": 2.18, "tv": 763.02, "trd": NaN, "batb": [[0, 1.74, 412.43], [1, 1.6, 87.96], [2, 1.5, 94.99]], "batl": [[0, 2.82, 235.94], [1, 5.8, 2.54], [2, 810, 0.07]]}, {"timestamp": 1632569597259, "ltp": 2.18, "tv": 763.02, "trd": NaN, "batb": [[0, 2.04, 5], [1, 2.02, 3], [2, 1.74, 412.43]], "batl": [[0, 2.4, 3], [1, 2.82, 239.94], [2, 5.8, 2.54]]}, {"timestamp": 1632569598856, "ltp": 2.18, "tv": 763.02, "trd": NaN, "batb": NaN, "batl": [[1, 2.52, 3], [2, 2.82, 239.94]]}, {"timestamp": 1632569601152, "ltp": 2.18, "tv": 763.02, "trd": NaN, "batb": [[0, 2.02, 3], [1, 1.74, 412.43], [2, 1.6, 87.96]], "batl": NaN}, {"timestamp": 1632569602262, "ltp": 2.18, "tv": 763.02, "trd": NaN, "batb": [[0, 2.12, 76.95], [1, 2.02, 3], [2, 1.74, 412.43]], "batl": [[0, 2.2, 17.38], [1, 2.28, 116.96], [2, 2.36, 12.71]]}, {"timestamp": 1632569603749, "ltp": 2.18, "tv": 763.02, "trd": NaN, "batb": [[1, 2.08, 13.88], [2, 2.02, 3]], "batl": [[2, 2.3, 13.15]]}, {"timestamp": 1632569608078, "ltp": 2.18, "tv": 763.02, "trd": NaN, "batb": [[2, 2.06, 171.89]], "batl": NaN}, {"timestamp": 1632569618975, "ltp": 2.18, "tv": 763.02, "trd": NaN, "batb": [[0, 2.08, 13.88], [1, 2.06, 171.89], [2, 2.02, 3]], "batl": [[0, 2.3, 13.15], [1, 2.38, 3], [2, 2.82, 235.94]]}, {"timestamp": 1632569620262, "ltp": 2.18, "tv": 763.02, "trd": NaN, "batb": [[0, 2.06, 171.89], [1, 2.02, 3], [2, 1.74, 412.53]], "batl": [[0, 2.38, 3], [1, 2.82, 235.94], [2, 5.8, 2.54]]}, {"timestamp": 1632569625183, "ltp": 2.18, "tv": 763.02, "trd": NaN, "batb": NaN, "batl": [[0, 2.34, 4], [1, 2.36, 4], [2, 2.38, 3]]}, {"timestamp": 1632569628359, "ltp": 2.18, "tv": 763.02, "trd": NaN, "batb": NaN, "batl": [[0, 2.32, 4], [1, 2.34, 4], [2, 2.36, 4]]}, {"timestamp": 1632569631982, "ltp": 2.18, "tv": 763.02, "trd": NaN, "batb": NaN, "batl": [[0, 2.34, 4], [1, 2.36, 4], [2, 2.38, 3]]}, {"timestamp": 1632569635296, "ltp": 2.18, "tv": 763.02, "trd": NaN, "batb": [[1, 1.74, 412.53], [2, 1.6, 87.96]], "batl": NaN}, {"timestamp": 1632569636291, "ltp": 2.18, "tv": 763.02, "trd": NaN, "batb": NaN, "batl": [[0, 2.16, 515.96], [1, 2.18, 1074.23], [2, 2.2, 429.7]]}, {"timestamp": 1632569637292, "ltp": 2.18, "tv": 763.02, "trd": NaN, "batb": [[1, 2.02, 180.85], [2, 2, 15.1]], "batl": [[1, 2.18, 429.7], [2, 2.2, 443.39]]}, {"timestamp": 1632569638291, "ltp": 2.18, "tv": 763.02, "trd": NaN, "batb": NaN, "batl": [[1, 2.18, 432.7]]}, {"timestamp": 1632569649024, "ltp": 2.18, "tv": 763.02, "trd": NaN, "batb": [[0, 2.02, 180.85], [1, 2, 15.1], [2, 1.98, 4]], "batl": [[0, 2.2, 13.69], [1, 2.34, 4], [2, 2.82, 235.94]]}, {"timestamp": 1632569650305, "ltp": 2.18, "tv": 763.02, "trd": NaN, "batb": [[1, 1.98, 4.1], [2, 1.97, 4]], "batl": [[0, 2.34, 4], [1, 2.82, 235.94], [2, 5.8, 2.54]]}, {"timestamp": 1632569650521, "ltp": 2.18, "tv": 763.02, "trd": NaN, "batb": [[2, 1.74, 412.43]], "batl": NaN}, {"timestamp": 1632569652215, "ltp": 2.18, "tv": 763.02, "trd": NaN, "batb": [[0, 2.02, 184.85], [1, 2, 4.1], [2, 1.98, 4]], "batl": [[0, 2.2, 4], [1, 2.34, 4], [2, 2.82, 235.94]]}, {"timestamp": 1632569654127, "ltp": 2.18, "tv": 763.02, "trd": NaN, "batb": NaN, "batl": [[1, 2.22, 4], [2, 2.34, 4]]}, {"timestamp": 1632569665254, "ltp": 2.18, "tv": 763.02, "trd": NaN, "batb": [[1, 1.74, 412.53], [2, 1.5, 94.99]], "batl": [[1, 2.82, 235.94], [2, 5.8, 2.54]]}, {"timestamp": 1632569668645, "ltp": 2.18, "tv": 763.02, "trd": NaN, "batb": [[1, 2, 4.1], [2, 1.74, 412.43]], "batl": NaN}, {"timestamp": 1632569681346, "ltp": 2.18, "tv": 763.02, "trd": NaN, "batb": [[0, 2.02, 180.85], [1, 2, 6.19], [2, 1.99, 1922.1]], "batl": [[0, 2.06, 11.61], [1, 2.12, 110.07], [2, 2.2, 4]]}, {"timestamp": 1632569682353, "ltp": 2.18, "tv": 763.02, "trd": NaN, "batb": [[2, 1.99, 480.52]], "batl": [[2, 2.2, 304.84]]}, {"timestamp": 1632569683253, "ltp": 2.06, "tv": 765.23, "trd": [[2.06, 2.21]], "batb": NaN, "batl": [[0, 2.06, 9.4], [2, 2.18, 13.8]]}, {"timestamp": 1632569684279, "ltp": 2.06, "tv": 765.23, "trd": NaN, "batb": NaN, "batl": [[2, 2.18, 17.8]]}, {"timestamp": 1632569686349, "ltp": 2.06, "tv": 765.23, "trd": NaN, "batb": NaN, "batl": [[2, 2.16, 92.34]]}, {"timestamp": 1632569687144, "ltp": 2.06, "tv": 765.23, "trd": NaN, "batb": NaN, "batl": [[2, 2.18, 4]]}, {"timestamp": 1632569690069, "ltp": 2.06, "tv": 765.23, "trd": NaN, "batb": NaN, "batl": [[2, 2.16, 13.92]]}, {"timestamp": 1632569692264, "ltp": 2.04, "tv": 768.74, "trd": [[2.04, 14.82]], "batb": NaN, "batl": NaN}, {"timestamp": 1632569693372, "ltp": 2.04, "tv": 768.74, "trd": NaN, "batb": [[1, 1.99, 480.62], [2, 1.98, 466.4]], "batl": [[0, 2.12, 110.07], [1, 2.16, 13.92], [2, 2.18, 4]]}, {"timestamp": 1632569695871, "ltp": 2.06, "tv": 774.02, "trd": [[2.06, 7.49]], "batb": [[1, 2, 7.33], [2, 1.99, 480.52]], "batl": [[0, 2.06, 4.12], [1, 2.12, 110.07], [2, 2.16, 13.92]]}, {"timestamp": 1632569706133, "ltp": 2.06, "tv": 774.02, "trd": NaN, "batb": [[1, 1.99, 480.62], [2, 1.98, 466.4]], "batl": [[0, 2.12, 110.07], [1, 2.16, 13.92], [2, 2.18, 4]]}, {"timestamp": 1632569708990, "ltp": 2.06, "tv": 774.02, "trd": NaN, "batb": NaN, "batl": [[0, 2.08, 11.53], [1, 2.12, 110.07], [2, 2.16, 13.92]]}, {"timestamp": 1632569714318, "ltp": 2.06, "tv": 774.02, "trd": NaN, "batb": [[1, 1.96, 15.4], [2, 1.89, 112.62]], "batl": [[0, 2.16, 13.92], [1, 2.18, 4], [2, 5.8, 2.54]]}, {"timestamp": 1632569715293, "ltp": 2.06, "tv": 774.02, "trd": NaN, "batb": [[0, 1.89, 112.72], [1, 1.5, 94.99], [2, 1.4, 131.93]], "batl": [[0, 2.18, 4], [1, 5.8, 2.54], [2, 810, 0.07]]}, {"timestamp": 1632569718694, "ltp": 2.06, "tv": 774.02, "trd": NaN, "batb": [[0, 1.89, 115.72], [1, 1.88, 4], [2, 1.5, 94.99]], "batl": NaN}, {"timestamp": 1632569721298, "ltp": 2.06, "tv": 774.02, "trd": NaN, "batb": NaN, "batl": [[0, 2.16, 7.4], [1, 2.18, 4], [2, 2.2, 72.43]]}, {"timestamp": 1632569722316, "ltp": 2.06, "tv": 774.02, "trd": NaN, "batb": [[0, 2.08, 166.9], [1, 2.02, 14.7], [2, 1.96, 200.83]], "batl": NaN}, {"timestamp": 1632569724304, "ltp": 2.06, "tv": 774.02, "trd": NaN, "batb": [[2, 2, 3.1]], "batl": NaN}, {"timestamp": 1632569733326, "ltp": 2.06, "tv": 774.02, "trd": NaN, "batb": NaN, "batl": [[0, 2.18, 4], [1, 2.24, 13.47], [2, 5.8, 2.54]]}, {"timestamp": 1632569734325, "ltp": 2.06, "tv": 774.02, "trd": NaN, "batb": [[0, 2.02, 14.7], [1, 2, 3.1], [2, 1.99, 4]], "batl": [[0, 2.24, 13.47], [1, 5.8, 2.54], [2, 810, 0.07]]}, {"timestamp": 1632569735306, "ltp": 2.06, "tv": 774.02, "trd": NaN, "batb": [[0, 2, 3.1], [1, 1.99, 4], [2, 1.96, 200.72]], "batl": [[0, 5.8, 2.54], [1, 810, 0.07], [2, 810, 0]]}, {"timestamp": 1632569737032, "ltp": 2.06, "tv": 774.02, "trd": NaN, "batb": [[1, 1.96, 200.72], [2, 1.5, 94.99]], "batl": [[0, 2.2, 3], [1, 2.24, 3], [2, 5.8, 2.54]]}, {"timestamp": 1632569738504, "ltp": 2.06, "tv": 774.02, "trd": NaN, "batb": NaN, "batl": [[2, 2.28, 3]]}, {"timestamp": 1632569740301, "ltp": 2.06, "tv": 774.02, "trd": NaN, "batb": [[0, 2.1, 1138.39], [1, 2.08, 1104.91], [2, 2.06, 1104.91]], "batl": [[0, 2.24, 10.56], [1, 2.26, 1057.8], [2, 2.28, 484.02]]}, {"timestamp": 1632569741309, "ltp": 2.06, "tv": 774.02, "trd": NaN, "batb": [[0, 2.14, 156.33], [1, 2.1, 455.36], [2, 2.08, 441.96]], "batl": [[1, 2.26, 423.12]]}, {"timestamp": 1632569748547, "ltp": 2.06, "tv": 774.02, "trd": NaN, "batb": [[2, 2.08, 455.84]], "batl": NaN}, {"timestamp": 1632569752030, "ltp": 2.06, "tv": 774.02, "trd": NaN, "batb": NaN, "batl": [[2, 2.28, 481.02]]}, {"timestamp": 1632569756256, "ltp": 2.06, "tv": 774.02, "trd": NaN, "batb": [[0, 2.08, 13.88], [1, 2.04, 182.08], [2, 1.6, 88.06]], "batl": [[0, 2.3, 13.15], [1, 5.8, 2.54], [2, 810, 0.07]]}, {"timestamp": 1632569757261, "ltp": 2.06, "tv": 774.02, "trd": NaN, "batb": [[0, 2.04, 182.08], [1, 1.6, 88.06], [2, 1.5, 94.99]], "batl": [[0, 5.8, 2.54], [1, 810, 0.07], [2, 810, 0]]}, {"timestamp": 1632569759332, "ltp": 2.06, "tv": 774.02, "trd": NaN, "batb": NaN, "batl": [[0, 2.3, 3], [1, 5.8, 2.54], [2, 810, 0.07]]}, {"timestamp": 1632569761273, "ltp": 2.06, "tv": 774.02, "trd": NaN, "batb": NaN, "batl": [[1, 3.5, 2], [2, 5.8, 2.54]]}, {"timestamp": 1632569762232, "ltp": 2.06, "tv": 774.02, "trd": NaN, "batb": [[1, 2.02, 4], [2, 1.6, 88.06]], "batl": [[0, 2.24, 4], [1, 2.28, 3], [2, 2.3, 3]]}, {"timestamp": 1632569779599, "ltp": 2.06, "tv": 774.02, "trd": NaN, "batb": [[1, 1.6, 88.06], [2, 1.5, 94.99]], "batl": [[1, 5.8, 2.54], [2, 810, 0.07]]}, {"timestamp": 1632569782299, "ltp": 2.06, "tv": 774.02, "trd": NaN, "batb": [[0, 2.08, 8.14], [1, 2.04, 259.82], [2, 1.5, 95.09]], "batl": [[0, 2.2, 141.71], [1, 2.24, 4], [2, 2.3, 13.04]]}, {"timestamp": 1632569783313, "ltp": 2.06, "tv": 774.02, "trd": NaN, "batb": [[2, 1.99, 15.17]], "batl": [[1, 2.22, 13.58], [2, 2.24, 4]]}, {"timestamp": 1632569785207, "ltp": 2.06, "tv": 774.02, "trd": NaN, "batb": NaN, "batl": [[0, 2.18, 4], [1, 2.2, 141.71], [2, 2.22, 13.58]]}, {"timestamp": 1632569787325, "ltp": 2.06, "tv": 774.02, "trd": NaN, "batb": NaN, "batl": [[2, 2.24, 4]]}, {"timestamp": 1632569790731, "ltp": 2.06, "tv": 774.02, "trd": NaN, "batb": NaN, "batl": [[0, 2.18, 362.7]]}, {"timestamp": 1632569794933, "ltp": 2.06, "tv": 774.02, "trd": NaN, "batb": [[0, 1.99, 15.17], [1, 1.98, 4], [2, 1.97, 3]], "batl": [[0, 2.18, 13.8], [1, 2.24, 4], [2, 5.8, 2.54]]}, {"timestamp": 1632569796321, "ltp": 2.06, "tv": 774.02, "trd": NaN, "batb": [[0, 1.98, 4.1], [1, 1.97, 3], [2, 1.9, 111.18]], "batl": [[0, 2.24, 4], [1, 5.8, 2.54], [2, 810, 0.07]]}, {"timestamp": 1632569798098, "ltp": 2.06, "tv": 774.02, "trd": NaN, "batb": [[1, 1.9, 111.18], [2, 1.5, 94.99]], "batl": NaN}, {"timestamp": 1632569800131, "ltp": 2.06, "tv": 774.02, "trd": NaN, "batb": NaN, "batl": [[0, 2.22, 4], [1, 2.24, 4], [2, 5.8, 2.54]]}, {"timestamp": 1632569803327, "ltp": 2.06, "tv": 774.02, "trd": NaN, "batb": [[1, 1.97, 3], [2, 1.9, 111.18]], "batl": NaN}, {"timestamp": 1632569809344, "ltp": 1.98, "tv": 786.2, "trd": [[1.98, 64.06], [2, 324.2]], "batb": [[0, 1.97, 3], [1, 1.9, 111.18], [2, 1.89, 100.78]], "batl": [[0, 1.98, 4.12], [1, 2.02, 105.53], [2, 2.16, 13.89]]}, {"timestamp": 1632569810353, "ltp": 1.98, "tv": 786.2, "trd": NaN, "batb": [[0, 1.92, 303.34], [1, 1.9, 431.51]], "batl": [[1, 1.99, 254.12], [2, 2.02, 513.77]]}, {"timestamp": 1632569812640, "ltp": 1.98, "tv": 786.2, "trd": NaN, "batb": NaN, "batl": [[2, 2, 3]]}, {"timestamp": 1632569814334, "ltp": 1.98, "tv": 790.32, "trd": [[1.98, 68.18]], "batb": NaN, "batl": [[0, 1.99, 254.12], [1, 2, 3], [2, 2.02, 513.77]]}, {"timestamp": 1632569816539, "ltp": 1.98, "tv": 790.32, "trd": NaN, "batb": [[0, 1.96, 149], [1, 1.92, 303.34], [2, 1.9, 431.51]], "batl": NaN}, {"timestamp": 1632569820041, "ltp": 1.98, "tv": 790.32, "trd": NaN, "batb": [[0, 1.98, 2.66], [1, 1.96, 149], [2, 1.92, 303.34]], "batl": NaN}, {"timestamp": 1632569822151, "ltp": 1.98, "tv": 790.32, "trd": NaN, "batb": [[0, 1.98, 858.92]], "batl": NaN}, {"timestamp": 1632569822564, "ltp": 1.98, "tv": 790.32, "trd": NaN, "batb": NaN, "batl": [[1, 2, 7.19]]}, {"timestamp": 1632569824358, "ltp": 2.0, "tv": 1301.7, "trd": [[1.99, 508.24], [2, 327.34]], "batb": [[0, 1.99, 31.3], [1, 1.98, 858.92], [2, 1.96, 243]], "batl": [[0, 2, 5.62], [1, 2.02, 376.3], [2, 2.04, 14.7]]}, {"timestamp": 1632569825138, "ltp": 2.0, "tv": 1301.7, "trd": NaN, "batb": NaN, "batl": [[0, 2, 1.43]]}, {"timestamp": 1632569827363, "ltp": 2.0, "tv": 1301.7, "trd": NaN, "batb": NaN, "batl": [[0, 2, 253.37], [1, 2.04, 14.7], [2, 5.8, 2.54]]}, {"timestamp": 1632569828348, "ltp": 1.99, "tv": 1359.29, "trd": [[1.99, 560.83], [2, 332.34]], "batb": [[0, 1.99, 5.01], [2, 1.69, 161.83]], "batl": [[0, 5.8, 2.72], [1, 810, 0.07], [2, 5.8, 0]]}, {"timestamp": 1632569830281, "ltp": 1.99, "tv": 1359.29, "trd": NaN, "batb": [[2, 1.72, 335.3]], "batl": [[0, 2.12, 328.41], [1, 2.14, 229.25], [2, 5.8, 2.72]]}, {"timestamp": 1632569831442, "ltp": 1.99, "tv": 1359.29, "trd": NaN, "batb": [[0, 1.98, 2.66], [1, 1.72, 335.3], [2, 1.7, 460.81]], "batl": NaN}, {"timestamp": 1632569833878, "ltp": 1.99, "tv": 1359.29, "trd": NaN, "batb": [[1, 1.69, 161.83], [2, 1.5, 94.99]], "batl": [[0, 5.8, 2.72], [1, 810, 0.07], [2, 5.8, 0]]}, {"timestamp": 1632569837300, "ltp": 1.99, "tv": 1359.29, "trd": NaN, "batb": [[0, 2.04, 398.06], [1, 2, 64.99], [2, 1.98, 103.18]], "batl": [[0, 2.16, 115.62], [1, 2.32, 1.71], [2, 3, 3]]}, {"timestamp": 1632569838261, "ltp": 1.99, "tv": 1359.29, "trd": NaN, "batb": [[1, 2, 252.86], [2, 1.98, 2.66]], "batl": [[0, 2.14, 14.04], [1, 2.16, 115.62], [2, 2.32, 14.64]]}, {"timestamp": 1632569845320, "ltp": 1.99, "tv": 1359.29, "trd": NaN, "batb": [[2, 1.97, 15.54]], "batl": [[0, 2.14, 194.34]]}, {"timestamp": 1632569847704, "ltp": 1.99, "tv": 1359.29, "trd": NaN, "batb": NaN, "batl": [[2, 2.32, 12.93]]}, {"timestamp": 1632569849276, "ltp": 2.08, "tv": 1370.39, "trd": [[2.08, 10.6], [2.12, 8.85]], "batb": [[0, 2, 252.86], [1, 1.97, 15.54], [2, 1.87, 116.85]], "batl": [[0, 2.08, 74.97], [1, 2.12, 3.11], [2, 2.14, 194.34]]}, {"timestamp": 1632569852376, "ltp": 2.08, "tv": 1370.39, "trd": NaN, "batb": [[0, 2, 187.87]], "batl": [[1, 2.14, 194.34], [2, 3, 3]]}, {"timestamp": 1632569853290, "ltp": 2.08, "tv": 1370.39, "trd": NaN, "batb": [[0, 1.87, 117.16], [1, 1.5, 94.99], [2, 1.4, 131.93]], "batl": [[1, 3, 3], [2, 5.8, 2.54]]}, {"timestamp": 1632569856200, "ltp": 2.08, "tv": 1370.39, "trd": NaN, "batb": [[0, 1.97, 4.31], [1, 1.96, 5], [2, 1.91, 114.9]], "batl": NaN}, {"timestamp": 1632569856782, "ltp": 2.08, "tv": 1406.89, "trd": [[2.08, 47.1]], "batb": [[2, 1.95, 4]], "batl": [[0, 2.08, 38.47]]}, {"timestamp": 1632569860525, "ltp": 2.08, "tv": 1406.89, "trd": NaN, "batb": [[0, 2, 285.42], [1, 1.97, 4.31], [2, 1.96, 5]], "batl": NaN}, {"timestamp": 1632569867603, "ltp": 2.08, "tv": 1406.89, "trd": NaN, "batb": [[2, 1.95, 4]], "batl": NaN}, {"timestamp": 1632569869028, "ltp": 2.08, "tv": 1406.89, "trd": NaN, "batb": [[2, 1.91, 119.9]], "batl": NaN}, {"timestamp": 1632569870830, "ltp": 2.08, "tv": 1406.89, "trd": NaN, "batb": [[1, 1.97, 4.37], [2, 1.91, 114.9]], "batl": NaN}, {"timestamp": 1632569872220, "ltp": 2.08, "tv": 1445.36, "trd": [[2.08, 85.57]], "batb": NaN, "batl": [[0, 3, 3], [1, 5.8, 2.54], [2, 5.8, 0]]}, {"timestamp": 1632569872810, "ltp": 2.08, "tv": 1445.36, "trd": NaN, "batb": [[0, 1.97, 4.37], [1, 1.91, 114.9], [2, 1.5, 95.18]], "batl": NaN}, {"timestamp": 1632569874202, "ltp": 2.08, "tv": 1445.36, "trd": NaN, "batb": [[0, 2.16, 6.44], [1, 1.97, 4.37], [2, 1.91, 114.9]], "batl": [[0, 2.2, 6.43], [1, 2.24, 1778.91], [2, 2.26, 1657.36]]}, {"timestamp": 1632569875202, "ltp": 2.08, "tv": 1445.36, "trd": NaN, "batb": NaN, "batl": [[1, 2.24, 498.23], [2, 2.26, 414.34]]}, {"timestamp": 1632569876319, "ltp": 2.08, "tv": 1445.36, "trd": NaN, "batb": [[1, 2.1, 166.65], [2, 2.04, 184.15]], "batl": [[0, 2.2, 10.43], [1, 2.24, 511.7]]}, {"timestamp": 1632569880815, "ltp": 2.08, "tv": 1445.36, "trd": NaN, "batb": [[1, 2.1, 166.48], [2, 2.04, 183.9]], "batl": NaN}, {"timestamp": 1632569883010, "ltp": 2.08, "tv": 1445.36, "trd": NaN, "batb": [[2, 2.04, 198.32]], "batl": NaN}, {"timestamp": 1632569887123, "ltp": 2.16, "tv": 1451.46, "trd": [[2.16, 76.93]], "batb": [[0, 2.1, 166.82], [1, 2.04, 198.32], [2, 1.97, 4.37]], "batl": NaN}, {"timestamp": 1632569889214, "ltp": 2.16, "tv": 1451.63, "trd": [[2.16, 77.1]], "batb": [[0, 2.1, 166.65]], "batl": NaN}, {"timestamp": 1632569894311, "ltp": 2.16, "tv": 1451.97, "trd": [[2.16, 77.44]], "batb": [[0, 2.1, 166.48]], "batl": [[0, 2.16, 5.98], [1, 2.2, 10.43], [2, 2.24, 511.7]]}, {"timestamp": 1632569897330, "ltp": 2.16, "tv": 1451.97, "trd": NaN, "batb": NaN, "batl": [[1, 2.2, 4]]}, {"timestamp": 1632569900341, "ltp": 2.16, "tv": 1451.97, "trd": NaN, "batb": NaN, "batl": [[1, 2.2, 16.75]]}, {"timestamp": 1632569900551, "ltp": 2.16, "tv": 1451.97, "trd": NaN, "batb": NaN, "batl": [[1, 2.2, 4]]}, {"timestamp": 1632569906847, "ltp": 2.16, "tv": 1451.97, "trd": NaN, "batb": NaN, "batl": [[1, 2.2, 16.75]]}, {"timestamp": 1632569909053, "ltp": 2.16, "tv": 1451.97, "trd": NaN, "batb": NaN, "batl": [[1, 2.18, 7.91], [2, 2.2, 16.75]]}, {"timestamp": 1632569915605, "ltp": 2.12, "tv": 1460.76, "trd": [[2.12, 17.64]], "batb": NaN, "batl": NaN}, {"timestamp": 1632569925833, "ltp": 2.12, "tv": 1460.76, "trd": NaN, "batb": NaN, "batl": [[2, 2.2, 4]]}, {"timestamp": 1632569928750, "ltp": 2.12, "tv": 1460.76, "trd": NaN, "batb": NaN, "batl": [[0, 2.16, 14.61]]}, {"timestamp": 1632569929639, "ltp": 2.16, "tv": 1475.37, "trd": [[2.16, 92.05]], "batb": NaN, "batl": [[0, 2.18, 7.91], [1, 2.2, 4], [2, 2.24, 511.7]]}, {"timestamp": 1632569942745, "ltp": 2.16, "tv": 1475.37, "trd": NaN, "batb": NaN, "batl": [[1, 2.2, 16.75]]}, {"timestamp": 1632569965238, "ltp": 2.16, "tv": 1475.37, "trd": NaN, "batb": [[0, 2.04, 198.32], [1, 1.97, 4.37], [2, 1.5, 94.99]], "batl": [[1, 2.24, 13.47], [2, 5.8, 2.54]]}, {"timestamp": 1632569966247, "ltp": 2.16, "tv": 1475.37, "trd": NaN, "batb": [[0, 2.04, 183.9]], "batl": [[1, 5.8, 2.54], [2, 5.8, 0]]}, {"timestamp": 1632569976078, "ltp": 2.16, "tv": 1475.37, "trd": NaN, "batb": NaN, "batl": [[0, 5.8, 2.54], [1, 5.8, 0]]}, {"timestamp": 1632569979141, "ltp": 2.16, "tv": 1475.37, "trd": NaN, "batb": NaN, "batl": [[0, 2.28, 7.91], [1, 5.8, 2.54]]}, {"timestamp": 1632569980189, "ltp": 2.16, "tv": 1475.37, "trd": NaN, "batb": [[2, 1.5, 95.18]], "batl": NaN}, {"timestamp": 1632569983362, "ltp": 2.28, "tv": 1483.28, "trd": [[2.28, 7.91]], "batb": [[0, 2.32, 10.25], [1, 2.04, 183.9], [2, 1.97, 4.37]], "batl": [[0, 5.8, 2.54], [1, 5.8, 0]]}, {"timestamp": 1632569984369, "ltp": 2.28, "tv": 1483.28, "trd": NaN, "batb": [[1, 2.3, 132.41], [2, 2.18, 151.68]], "batl": [[0, 2.62, 11.45], [1, 2.66, 1.71], [2, 5.8, 2.54]]}, {"timestamp": 1632569985262, "ltp": 2.28, "tv": 1483.28, "trd": NaN, "batb": [[2, 2.18, 164.39]], "batl": [[0, 2.44, 12.5], [1, 2.62, 11.45], [2, 2.66, 1.71]]}, {"timestamp": 1632569986696, "ltp": 2.28, "tv": 1483.28, "trd": NaN, "batb": [[2, 2.18, 151.68]], "batl": [[0, 2.62, 11.45], [1, 2.66, 1.71], [2, 3, 217.75]]}, {"timestamp": 1632569988319, "ltp": 2.28, "tv": 1483.28, "trd": NaN, "batb": NaN, "batl": [[0, 2.48, 75.71], [1, 2.62, 11.45], [2, 2.66, 1.71]]}, {"timestamp": 1632569988591, "ltp": 2.28, "tv": 1483.28, "trd": NaN, "batb": NaN, "batl": [[0, 2.62, 11.45], [1, 2.66, 1.71], [2, 3, 217.75]]}, {"timestamp": 1632569990154, "ltp": 2.28, "tv": 1483.28, "trd": NaN, "batb": NaN, "batl": [[0, 2.44, 12.5], [1, 2.62, 11.45], [2, 2.66, 1.71]]}, {"timestamp": 1632569993381, "ltp": 2.34, "tv": 1484.06, "trd": [[2.34, 0.78]], "batb": [[2, 2.22, 12.29]], "batl": [[0, 2.44, 132.59]]}, {"timestamp": 1632569994928, "ltp": 2.34, "tv": 1484.06, "trd": NaN, "batb": NaN, "batl": [[2, 2.76, 2.06]]}, {"timestamp": 1632569998189, "ltp": 2.34, "tv": 1484.06, "trd": NaN, "batb": NaN, "batl": [[0, 2.44, 12.5], [2, 2.74, 2.48]]}, {"timestamp": 1632570000110, "ltp": 2.34, "tv": 1484.06, "trd": NaN, "batb": [[0, 2.22, 12.29], [1, 2.18, 151.43], [2, 1.77, 410.93]], "batl": [[1, 3, 217.75], [2, 5.8, 2.54]]}, {"timestamp": 1632570001289, "ltp": 2.34, "tv": 1484.06, "trd": NaN, "batb": [[0, 2.18, 151.43], [1, 2.14, 3.82]], "batl": [[0, 3, 217.75], [1, 5.8, 2.54], [2, 5.8, 0]]}, {"timestamp": 1632570001606, "ltp": 2.34, "tv": 1484.06, "trd": NaN, "batb": [[1, 2.14, 6.82]], "batl": NaN}, {"timestamp": 1632570003330, "ltp": 2.34, "tv": 1484.06, "trd": NaN, "batb": NaN, "batl": [[0, 2.74, 2.48], [1, 3, 217.75], [2, 5.8, 2.54]]}, {"timestamp": 1632570005121, "ltp": 2.34, "tv": 1484.06, "trd": NaN, "batb": NaN, "batl": [[1, 2.8, 3], [2, 3, 217.75]]}, {"timestamp": 1632570006292, "ltp": 2.34, "tv": 1484.06, "trd": NaN, "batb": [[2, 1.7, 15.63]], "batl": [[0, 2.74, 5.48], [2, 5.8, 2.54]]}, {"timestamp": 1632570008307, "ltp": 2.34, "tv": 1484.06, "trd": NaN, "batb": [[0, 2.18, 154.79]], "batl": [[0, 2.72, 7.1], [1, 2.74, 5.48], [2, 2.8, 3]]}, {"timestamp": 1632570009320, "ltp": 2.34, "tv": 1484.06, "trd": NaN, "batb": [[0, 2.64, 90.55], [1, 2.44, 112.28], [2, 2.18, 151.43]], "batl": NaN}, {"timestamp": 1632570010289, "ltp": 2.34, "tv": 1484.06, "trd": NaN, "batb": [[1, 2.46, 10.27], [2, 2.44, 112.28]], "batl": [[0, 2.72, 10.1], [2, 2.78, 11.24]]}, {"timestamp": 1632570011995, "ltp": 2.34, "tv": 1484.06, "trd": NaN, "batb": [[1, 2.44, 112.28], [2, 2.2, 4]], "batl": [[0, 2.7, 4], [1, 2.72, 10.1], [2, 2.74, 5.48]]}, {"timestamp": 1632570016220, "ltp": 2.34, "tv": 1484.06, "trd": NaN, "batb": [[2, 2.38, 3.46]], "batl": NaN}, {"timestamp": 1632570018332, "ltp": 2.64, "tv": 1484.16, "trd": [[2.64, 0.1]], "batb": [[0, 2.64, 90.45]], "batl": [[2, 2.74, 2.48]]}, {"timestamp": 1632570023311, "ltp": 2.64, "tv": 1484.16, "trd": NaN, "batb": NaN, "batl": [[1, 2.72, 7.1]]}, {"timestamp": 1632570024414, "ltp": 2.64, "tv": 1601.02, "trd": [[2.64, 116.96]], "batb": [[0, 2.64, 32.02]], "batl": NaN}, {"timestamp": 1632570025630, "ltp": 2.64, "tv": 1601.41, "trd": [[2.64, 117.35]], "batb": [[0, 2.64, 31.64]], "batl": NaN}, {"timestamp": 1632570027548, "ltp": 2.64, "tv": 1621.77, "trd": [[2.64, 137.71]], "batb": [[0, 2.64, 21.46]], "batl": NaN}, {"timestamp": 1632570031223, "ltp": 2.64, "tv": 1621.77, "trd": NaN, "batb": [[0, 2.44, 112.28], [1, 2.38, 3.46], [2, 2.3, 2.78]], "batl": [[0, 2.78, 11.24], [1, 3.4, 2.04], [2, 3.45, 184.03]]}, {"timestamp": 1632570032369, "ltp": 2.64, "tv": 1621.77, "trd": NaN, "batb": NaN, "batl": [[0, 3.4, 2.04], [1, 3.45, 184.03], [2, 3.8, 2]]}, {"timestamp": 1632570032642, "ltp": 2.64, "tv": 1621.77, "trd": NaN, "batb": NaN, "batl": [[0, 3.45, 184.03], [1, 3.8, 2], [2, 5.8, 2.54]]}, {"timestamp": 1632570034344, "ltp": 2.64, "tv": 1621.77, "trd": NaN, "batb": [[0, 2.5, 10], [1, 2.38, 117.43]], "batl": NaN}, {"timestamp": 1632570034657, "ltp": 2.64, "tv": 1621.77, "trd": NaN, "batb": [[0, 2.38, 117.43], [1, 2.3, 2.78], [2, 2.2, 4]], "batl": NaN}, {"timestamp": 1632570036141, "ltp": 2.64, "tv": 1621.77, "trd": NaN, "batb": NaN, "batl": [[0, 3.4, 5.04], [1, 3.45, 187.03], [2, 3.8, 2]]}, {"timestamp": 1632570039264, "ltp": 2.64, "tv": 1621.77, "trd": NaN, "batb": [[0, 2.38, 113.97]], "batl": NaN}, {"timestamp": 1632570041338, "ltp": 2.64, "tv": 1621.77, "trd": NaN, "batb": NaN, "batl": [[1, 3.45, 3]]}, {"timestamp": 1632570042346, "ltp": 2.64, "tv": 1621.77, "trd": NaN, "batb": [[0, 3, 46.55], [1, 2.38, 113.97], [2, 2.3, 2.78]], "batl": [[0, 3.4, 76.3], [2, 3.6, 1.71]]}, {"timestamp": 1632570043148, "ltp": 2.64, "tv": 1621.77, "trd": NaN, "batb": [[0, 3.15, 134.35], [1, 3, 46.55], [2, 2.9, 68.49]], "batl": [[1, 3.45, 11.7]]}, {"timestamp": 1632570043827, "ltp": 2.64, "tv": 1621.77, "trd": NaN, "batb": [[2, 2.96, 7.65]], "batl": [[0, 3.35, 3], [1, 3.4, 85.98], [2, 3.45, 11.7]]}, {"timestamp": 1632570045152, "ltp": 2.64, "tv": 1621.77, "trd": NaN, "batb": [[2, 2.98, 3]], "batl": NaN}, {"timestamp": 1632570049165, "ltp": 2.64, "tv": 1621.77, "trd": NaN, "batb": NaN, "batl": [[1, 3.4, 82.98], [2, 3.45, 8.7]]}, {"timestamp": 1632570050070, "ltp": 2.64, "tv": 1621.77, "trd": NaN, "batb": [[1, 3, 54.05]], "batl": NaN}, {"timestamp": 1632570061206, "ltp": 2.64, "tv": 1621.77, "trd": NaN, "batb": [[0, 3, 7.5], [1, 2.9, 68.49], [2, 2.84, 2.47]], "batl": [[0, 3.4, 9.68], [1, 4.2, 151.01], [2, 4.3, 2]]}, {"timestamp": 1632570062336, "ltp": 2.64, "tv": 1621.77, "trd": NaN, "batb": [[0, 2.9, 68.49], [1, 2.84, 2.47], [2, 2.74, 2.52]], "batl": [[0, 4.2, 151.01], [1, 4.3, 2], [2, 4.8, 2]]}, {"timestamp": 1632570064371, "ltp": 2.64, "tv": 1621.77, "trd": NaN, "batb": [[1, 2.74, 2.52], [2, 2.72, 2.59]], "batl": NaN}, {"timestamp": 1632570065007, "ltp": 2.64, "tv": 1621.77, "trd": NaN, "batb": NaN, "batl": [[1, 4.8, 2], [2, 5.8, 2.54]]}, {"timestamp": 1632570066004, "ltp": 2.64, "tv": 1621.77, "trd": NaN, "batb": NaN, "batl": [[0, 4.2, 3]]}, {"timestamp": 1632570067281, "ltp": 2.64, "tv": 1621.77, "trd": NaN, "batb": NaN, "batl": [[0, 3.15, 895.24], [1, 3.2, 9.38], [2, 4.2, 3]]}, {"timestamp": 1632570068294, "ltp": 2.64, "tv": 1621.77, "trd": NaN, "batb": [[0, 2.9, 878.83], [1, 2.88, 243.11], [2, 2.86, 243.11]], "batl": [[0, 3.15, 298.42], [1, 3.2, 19.49]]}, {"timestamp": 1632570068818, "ltp": 2.64, "tv": 1621.77, "trd": NaN, "batb": [[0, 2.9, 230.55], [1, 2.88, 81.04], [2, 2.86, 81.04]], "batl": [[2, 3.25, 1.71]]}, {"timestamp": 1632570070290, "ltp": 2.64, "tv": 1621.77, "trd": NaN, "batb": NaN, "batl": [[0, 3.05, 10.76], [1, 3.15, 298.42], [2, 3.2, 19.49]]}, {"timestamp": 1632570070714, "ltp": 2.64, "tv": 1621.77, "trd": NaN, "batb": NaN, "batl": [[0, 3.05, 13.76]]}, {"timestamp": 1632570072408, "ltp": 2.64, "tv": 1621.77, "trd": NaN, "batb": NaN, "batl": [[2, 3.2, 9.38]]}, {"timestamp": 1632570075579, "ltp": 2.64, "tv": 1621.77, "trd": NaN, "batb": NaN, "batl": [[1, 3.15, 308.64]]}, {"timestamp": 1632570087922, "ltp": 2.64, "tv": 1621.77, "trd": NaN, "batb": [[0, 2.8, 8.33], [1, 2.6, 2.89], [2, 2.58, 92.92]], "batl": [[0, 3.15, 10.22], [1, 3.9, 161.43], [2, 4.3, 2]]}, {"timestamp": 1632570089301, "ltp": 2.64, "tv": 1621.77, "trd": NaN, "batb": [[0, 2.58, 92.92], [1, 2.5, 2.68], [2, 2.12, 396.48]], "batl": [[0, 3.9, 161.43], [1, 4.3, 2], [2, 4.8, 2]]}, {"timestamp": 1632570092313, "ltp": 2.64, "tv": 1621.77, "trd": NaN, "batb": [[2, 1.8, 11.11]], "batl": [[0, 4.3, 2], [1, 4.8, 2], [2, 5, 2]]}, {"timestamp": 1632570093320, "ltp": 2.64, "tv": 1621.77, "trd": NaN, "batb": [[0, 2.6, 6.92], [1, 2.58, 92.92], [2, 2.5, 2.68]], "batl": [[0, 2.78, 507.19], [1, 2.8, 84.54], [2, 2.82, 253.6]]}, {"timestamp": 1632570094325, "ltp": 2.64, "tv": 1621.77, "trd": NaN, "batb": [[0, 2.6, 187.68], [1, 2.58, 183.3], [2, 2.56, 90.38]], "batl": [[0, 2.78, 169.06], [2, 2.82, 84.54]]}, {"timestamp": 1632570096331, "ltp": 2.64, "tv": 1621.77, "trd": NaN, "batb": [[0, 2.6, 180.76]], "batl": [[0, 2.76, 3], [1, 2.78, 169.06], [2, 2.8, 84.54]]}, {"timestamp": 1632570099093, "ltp": 2.64, "tv": 1621.77, "trd": NaN, "batb": [[0, 2.6, 187.68]], "batl": [[0, 2.76, 40.98]]}, {"timestamp": 1632570099728, "ltp": 2.64, "tv": 1621.77, "trd": NaN, "batb": NaN, "batl": [[0, 2.76, 3]]}, {"timestamp": 1632570106159, "ltp": 2.64, "tv": 1621.77, "trd": NaN, "batb": NaN, "batl": [[0, 2.72, 29.34], [1, 2.76, 3], [2, 2.78, 169.06]]}, {"timestamp": 1632570106422, "ltp": 2.64, "tv": 1621.77, "trd": NaN, "batb": NaN, "batl": [[0, 2.76, 3], [1, 2.78, 169.06], [2, 2.8, 84.54]]}, {"timestamp": 1632570109245, "ltp": 2.64, "tv": 1621.77, "trd": NaN, "batb": [[0, 2.54, 9.74], [1, 2.3, 2.88], [2, 2.24, 140.15]], "batl": [[0, 2.82, 11.11], [1, 3.45, 184.03], [2, 4.6, 2]]}, {"timestamp": 1632570110353, "ltp": 2.64, "tv": 1621.77, "trd": NaN, "batb": [[0, 2.3, 2.88], [1, 2.24, 140.15], [2, 2.22, 3.34]], "batl": [[0, 3.45, 184.03], [1, 4.6, 2], [2, 4.8, 2]]}, {"timestamp": 1632570112141, "ltp": 2.64, "tv": 1621.77, "trd": NaN, "batb": [[0, 2.24, 140.15], [1, 2.22, 3.34], [2, 1.92, 403.42]], "batl": NaN}, {"timestamp": 1632570115323, "ltp": 2.64, "tv": 1621.77, "trd": NaN, "batb": [[0, 2.26, 4], [1, 2.24, 143.15], [2, 2.22, 7.34]], "batl": NaN}, {"timestamp": 1632570118153, "ltp": 2.64, "tv": 1621.77, "trd": NaN, "batb": [[0, 2.3, 3.08], [1, 2.26, 4], [2, 2.24, 143.15]], "batl": NaN}, {"timestamp": 1632570119268, "ltp": 2.64, "tv": 1621.77, "trd": NaN, "batb": [[0, 2.26, 4], [1, 2.24, 143.15], [2, 2.22, 7.34]], "batl": NaN}, {"timestamp": 1632570120765, "ltp": 2.64, "tv": 1621.77, "trd": NaN, "batb": NaN, "batl": [[0, 4.6, 2], [1, 4.8, 2], [2, 5, 2]]}, {"timestamp": 1632570122329, "ltp": 2.64, "tv": 1621.77, "trd": NaN, "batb": [[0, 2.24, 140.15], [1, 2.22, 434.08], [2, 2.2, 418.08]], "batl": [[0, 2.36, 7.1], [1, 2.4, 398.44], [2, 2.42, 386.72]]}, {"timestamp": 1632570123337, "ltp": 2.64, "tv": 1621.77, "trd": NaN, "batb": [[0, 2.26, 11.9], [1, 2.24, 140.15], [2, 2.22, 434.08]], "batl": NaN}, {"timestamp": 1632570125137, "ltp": 2.64, "tv": 1621.77, "trd": NaN, "batb": NaN, "batl": [[0, 2.36, 11.1], [1, 2.38, 4], [2, 2.4, 398.44]]}, {"timestamp": 1632570127276, "ltp": 2.64, "tv": 1621.77, "trd": NaN, "batb": NaN, "batl": [[0, 2.34, 89.42], [1, 2.36, 11.1], [2, 2.38, 4]]}, {"timestamp": 1632570128342, "ltp": 2.64, "tv": 1621.77, "trd": NaN, "batb": NaN, "batl": [[0, 2.34, 29.81]]}, {"timestamp": 1632570136370, "ltp": 2.64, "tv": 1621.77, "trd": NaN, "batb": [[1, 2.14, 3.32], [2, 2.1, 162]], "batl": [[0, 2.48, 12.32], [1, 2.66, 158.77], [2, 2.68, 159.18]]}, {"timestamp": 1632570137277, "ltp": 2.64, "tv": 1621.77, "trd": NaN, "batb": [[0, 2.1, 162], [1, 2.08, 149.04], [2, 2.06, 174.33]], "batl": [[0, 2.66, 158.77], [1, 2.68, 159.18], [2, 2.86, 2.25]]}, {"timestamp": 1632570139261, "ltp": 2.3, "tv": 1624.34, "trd": [[2.3, 108.61]], "batb": [[0, 2.12, 3.79], [1, 2.1, 162], [2, 2.08, 149.04]], "batl": NaN}, {"timestamp": 1632570140479, "ltp": 2.3, "tv": 1624.34, "trd": NaN, "batb": [[0, 2.18, 3], [1, 2.16, 4], [2, 2.12, 3.79]], "batl": NaN}, {"timestamp": 1632570143891, "ltp": 2.3, "tv": 1624.34, "trd": NaN, "batb": NaN, "batl": [[0, 2.86, 2.25], [1, 3, 217.75], [2, 3.15, 2.3]]}, {"timestamp": 1632570144991, "ltp": 2.3, "tv": 1624.34, "trd": NaN, "batb": NaN, "batl": [[1, 3.15, 2.3], [2, 4.6, 2]]}, {"timestamp": 1632570146373, "ltp": 2.3, "tv": 1624.34, "trd": NaN, "batb": [[0, 2.12, 3.79], [1, 2.1, 162], [2, 2.08, 149.04]], "batl": [[0, 2.2, 17.03], [1, 2.34, 12.82], [2, 2.86, 2.25]]}, {"timestamp": 1632570147279, "ltp": 2.3, "tv": 1624.34, "trd": NaN, "batb": NaN, "batl": [[2, 2.44, 1.71]]}, {"timestamp": 1632570148292, "ltp": 2.3, "tv": 1624.34, "trd": NaN, "batb": [[1, 2.1, 175.63]], "batl": [[1, 2.32, 13.05], [2, 2.34, 12.82]]}, {"timestamp": 1632570152214, "ltp": 2.18, "tv": 1626.57, "trd": [[2.18, 2.77]], "batb": NaN, "batl": [[0, 2.18, 22.96], [1, 2.2, 17.03], [2, 2.32, 13.05]]}, {"timestamp": 1632570153379, "ltp": 2.18, "tv": 1626.6, "trd": [[2.18, 2.8]], "batb": NaN, "batl": [[0, 2.18, 22.93]]}, {"timestamp": 1632570153691, "ltp": 2.18, "tv": 1626.6, "trd": NaN, "batb": [[1, 2.1, 179.27]], "batl": [[0, 2.2, 17.03], [1, 2.32, 13.05], [2, 2.34, 12.82]]}, {"timestamp": 1632570157099, "ltp": 2.18, "tv": 1626.6, "trd": NaN, "batb": [[2, 2.08, 153.6]], "batl": NaN}, {"timestamp": 1632570158211, "ltp": 2.18, "tv": 1626.6, "trd": NaN, "batb": NaN, "batl": [[0, 2.18, 24.96], [1, 2.2, 17.03], [2, 2.32, 13.05]]}, {"timestamp": 1632570159376, "ltp": 2.18, "tv": 1628.58, "trd": [[2.18, 4.78]], "batb": NaN, "batl": [[0, 2.18, 22.98]]}, {"timestamp": 1632570164205, "ltp": 2.18, "tv": 1628.58, "trd": NaN, "batb": [[2, 2.08, 4.56]], "batl": [[0, 2.32, 13.05], [1, 2.38, 170.12], [2, 2.4, 169.39]]}, {"timestamp": 1632570165320, "ltp": 2.18, "tv": 1628.58, "trd": NaN, "batb": [[0, 2.04, 176.8], [1, 2.02, 198.1], [2, 2, 232.71]], "batl": [[0, 2.38, 170.12], [1, 2.4, 169.39], [2, 2.48, 3.24]]}, {"timestamp": 1632570165602, "ltp": 2.18, "tv": 1628.58, "trd": NaN, "batb": NaN, "batl": [[0, 2.38, 166.87]]}, {"timestamp": 1632570168288, "ltp": 2.18, "tv": 1628.58, "trd": NaN, "batb": [[0, 2.06, 4.08], [1, 2.04, 176.8], [2, 2.02, 198.1]], "batl": [[0, 2.48, 3.24], [1, 2.68, 3], [2, 2.82, 235.94]]}, {"timestamp": 1632570169296, "ltp": 2.18, "tv": 1628.58, "trd": NaN, "batb": [[0, 2.08, 4], [1, 2.06, 8.08], [2, 2.04, 181.8]], "batl": NaN}, {"timestamp": 1632570170300, "ltp": 2.08, "tv": 1641.17, "trd": [[2.08, 98.16]], "batb": [[0, 2.06, 8.08], [1, 2.04, 181.8], [2, 2.02, 198.1]], "batl": [[0, 2.14, 2811.44], [1, 2.16, 135.09], [2, 2.24, 13.39]]}, {"timestamp": 1632570171312, "ltp": 2.08, "tv": 1642.65, "trd": [[2.08, 99.64]], "batb": [[0, 2.1, 3.26], [1, 2.06, 4.08], [2, 2.04, 176.8]], "batl": [[0, 2.16, 135.09], [1, 2.24, 13.39], [2, 2.36, 1.71]]}, {"timestamp": 1632570171912, "ltp": 2.08, "tv": 1642.65, "trd": NaN, "batb": [[0, 2.06, 4.08], [1, 2.04, 176.8], [2, 2.02, 198.1]], "batl": NaN}, {"timestamp": 1632570173013, "ltp": 2.08, "tv": 1642.65, "trd": NaN, "batb": [[1, 2.04, 191.22]], "batl": [[1, 2.22, 13.58], [2, 2.24, 13.39]]}, {"timestamp": 1632570175216, "ltp": 2.08, "tv": 1642.65, "trd": NaN, "batb": NaN, "batl": [[1, 2.18, 98.45], [2, 2.22, 13.58]]}, {"timestamp": 1632570175909, "ltp": 2.08, "tv": 1642.65, "trd": NaN, "batb": NaN, "batl": [[0, 2.14, 35.06], [1, 2.16, 275.4]]}, {"timestamp": 1632570178315, "ltp": 2.08, "tv": 1642.65, "trd": NaN, "batb": NaN, "batl": [[2, 2.22, 204.81]]}, {"timestamp": 1632570182254, "ltp": 2.08, "tv": 1642.65, "trd": NaN, "batb": NaN, "batl": [[1, 2.16, 135.09]]}, {"timestamp": 1632570183924, "ltp": 2.08, "tv": 1642.65, "trd": NaN, "batb": [[0, 2.06, 4.27]], "batl": [[0, 2.16, 135.09], [1, 2.22, 204.81], [2, 2.24, 174.52]]}, {"timestamp": 1632570187236, "ltp": 2.08, "tv": 1642.65, "trd": NaN, "batb": [[0, 2.06, 11.6]], "batl": [[0, 2.12, 14.24], [1, 2.14, 3], [2, 2.16, 275.4]]}, {"timestamp": 1632570190136, "ltp": 2.08, "tv": 1642.65, "trd": NaN, "batb": NaN, "batl": [[1, 2.14, 38.06]]}, {"timestamp": 1632570190417, "ltp": 2.08, "tv": 1642.65, "trd": NaN, "batb": NaN, "batl": [[1, 2.14, 3]]}, {"timestamp": 1632570193725, "ltp": 2.08, "tv": 1642.65, "trd": NaN, "batb": NaN, "batl": [[0, 2.12, 49.3], [2, 2.16, 135.09]]}, {"timestamp": 1632570198986, "ltp": 2.08, "tv": 1642.65, "trd": NaN, "batb": NaN, "batl": [[0, 2.12, 14.24]]}, {"timestamp": 1632570200366, "ltp": 2.08, "tv": 1642.65, "trd": NaN, "batb": NaN, "batl": [[1, 2.16, 135.09], [2, 2.22, 204.81]]}, {"timestamp": 1632570207285, "ltp": 2.08, "tv": 1642.65, "trd": NaN, "batb": [[0, 2.04, 191.22], [1, 1.99, 4], [2, 1.98, 4.37]], "batl": [[0, 2.22, 201.56], [1, 2.24, 161.13], [2, 2.26, 3.29]]}, {"timestamp": 1632570208260, "ltp": 2.08, "tv": 1642.65, "trd": NaN, "batb": [[0, 1.95, 12.28], [1, 1.9, 338.2], [2, 1.89, 258.3]], "batl": [[0, 2.22, 187.98]]}, {"timestamp": 1632570210283, "ltp": 2.08, "tv": 1642.65, "trd": NaN, "batb": NaN, "batl": [[0, 2.2, 477.9], [1, 2.22, 187.98], [2, 2.24, 161.13]]}, {"timestamp": 1632570211194, "ltp": 2.08, "tv": 1642.65, "trd": NaN, "batb": NaN, "batl": [[0, 2.22, 187.98], [1, 2.24, 161.13], [2, 2.26, 3.29]]}, {"timestamp": 1632570211988, "ltp": 2.08, "tv": 1642.65, "trd": NaN, "batb": [[1, 1.9, 125.61], [2, 1.77, 410.58]], "batl": NaN}, {"timestamp": 1632570214298, "ltp": 2.08, "tv": 1642.65, "trd": NaN, "batb": NaN, "batl": [[0, 2.12, 40], [1, 2.22, 187.98], [2, 2.24, 161.13]]}, {"timestamp": 1632570215258, "ltp": 2.12, "tv": 1682.65, "trd": [[2.12, 57.64]], "batb": NaN, "batl": [[0, 2.2, 6.82], [2, 2.24, 244.61]]}, {"timestamp": 1632570216327, "ltp": 2.12, "tv": 1682.65, "trd": NaN, "batb": [[0, 2.12, 161.24], [1, 2.08, 13.88], [2, 1.98, 196.52]], "batl": [[0, 2.2, 34.8]]}, {"timestamp": 1632570217180, "ltp": 2.12, "tv": 1682.65, "trd": NaN, "batb": [[2, 2.04, 3]], "batl": NaN}, {"timestamp": 1632570219885, "ltp": 2.12, "tv": 1682.65, "trd": NaN, "batb": [[1, 2.04, 3], [2, 2.02, 3]], "batl": NaN}, {"timestamp": 1632570222207, "ltp": 2.12, "tv": 1682.65, "trd": NaN, "batb": [[1, 2.06, 3.41], [2, 2.04, 7.12]], "batl": [[1, 2.22, 191.23]]}, {"timestamp": 1632570223118, "ltp": 2.12, "tv": 1682.65, "trd": NaN, "batb": [[1, 2.1, 13.63], [2, 2.06, 3.41]], "batl": NaN}, {"timestamp": 1632570224185, "ltp": 2.12, "tv": 1682.65, "trd": NaN, "batb": [[2, 2.08, 3.81]], "batl": [[2, 2.24, 248.34]]}, {"timestamp": 1632570229337, "ltp": 2.12, "tv": 1682.65, "trd": NaN, "batb": [[0, 2.1, 13.63], [1, 2.04, 4.12], [2, 1.98, 196.52]], "batl": [[0, 2.26, 3.29], [1, 2.48, 3.24], [2, 2.82, 235.94]]}, {"timestamp": 1632570230349, "ltp": 2.12, "tv": 1682.65, "trd": NaN, "batb": [[0, 2.04, 4.12], [1, 1.98, 196.52], [2, 1.95, 11.91]], "batl": NaN}, {"timestamp": 1632570233458, "ltp": 2.12, "tv": 1682.65, "trd": NaN, "batb": NaN, "batl": [[0, 2.12, 17], [1, 2.26, 3.29], [2, 2.48, 3.24]]}, {"timestamp": 1632570235151, "ltp": 2.12, "tv": 1699.65, "trd": [[2.12, 74.64]], "batb": [[0, 2.24, 6.91], [1, 2.18, 379.46], [2, 2.04, 4.12]], "batl": [[0, 2.26, 3.29], [1, 2.32, 68.28]]}, {"timestamp": 1632570236378, "ltp": 2.12, "tv": 1699.65, "trd": NaN, "batb": [[2, 2.16, 162.92]], "batl": [[2, 2.34, 200.86]]}, {"timestamp": 1632570239813, "ltp": 2.12, "tv": 1699.65, "trd": NaN, "batb": [[2, 2.16, 149.99]], "batl": NaN}, {"timestamp": 1632570241743, "ltp": 2.12, "tv": 1699.65, "trd": NaN, "batb": NaN, "batl": [[2, 2.34, 367.24]]}, {"timestamp": 1632570243070, "ltp": 2.12, "tv": 1699.65, "trd": NaN, "batb": [[1, 2.18, 392.17]], "batl": [[0, 2.26, 30.47], [1, 2.3, 3.15], [2, 2.32, 68.28]]}, {"timestamp": 1632570247352, "ltp": 2.12, "tv": 1699.65, "trd": NaN, "batb": [[0, 2.18, 192.4], [1, 2.16, 149.99], [2, 2.14, 19.64]], "batl": [[2, 2.34, 266.81]]}, {"timestamp": 1632570248046, "ltp": 2.12, "tv": 1699.65, "trd": NaN, "batb": [[0, 2.18, 12.71], [1, 2.14, 19.64], [2, 2.1, 186.6]], "batl": [[0, 2.3, 3.15], [1, 2.34, 166.38], [2, 2.36, 167.11]]}, {"timestamp": 1632570249280, "ltp": 2.12, "tv": 1699.65, "trd": NaN, "batb": [[0, 2.1, 169.16], [1, 2.08, 247.62], [2, 2.06, 173.24]], "batl": NaN}, {"timestamp": 1632570251355, "ltp": 2.12, "tv": 1699.65, "trd": NaN, "batb": NaN, "batl": [[0, 2.3, 6.15]]}, {"timestamp": 1632570252157, "ltp": 2.12, "tv": 1699.65, "trd": NaN, "batb": [[0, 2.14, 19.71], [1, 2.1, 186.1], [2, 2.08, 247.62]], "batl": NaN}, {"timestamp": 1632570253283, "ltp": 2.12, "tv": 1699.65, "trd": NaN, "batb": [[0, 2.1, 169.16], [1, 2.08, 247.62], [2, 2.06, 173.24]], "batl": [[1, 2.48, 3.24], [2, 2.82, 235.94]]}, {"timestamp": 1632570256357, "ltp": 2.12, "tv": 1699.65, "trd": NaN, "batb": NaN, "batl": [[0, 2.16, 217.6], [1, 2.18, 108.8], [2, 2.2, 185.85]]}, {"timestamp": 1632570257369, "ltp": 2.12, "tv": 1701.99, "trd": [[2.12, 76.99]], "batb": [[2, 2.06, 187.39]], "batl": NaN}, {"timestamp": 1632570260352, "ltp": 2.12, "tv": 1701.99, "trd": NaN, "batb": [[0, 2.12, 3], [1, 2.1, 173.16], [2, 2.08, 247.62]], "batl": NaN}, {"timestamp": 1632570261331, "ltp": 2.12, "tv": 1701.99, "trd": NaN, "batb": [[0, 2.1, 169.16], [1, 2.08, 247.62], [2, 2.06, 187.39]], "batl": [[0, 2.16, 248.35]]}, {"timestamp": 1632570263360, "ltp": 2.16, "tv": 1707.36, "trd": [[2.16, 97.41]], "batb": NaN, "batl": [[0, 2.16, 245.67]]}, {"timestamp": 1632570267868, "ltp": 2.16, "tv": 1714.64, "trd": [[2.16, 104.69]], "batb": NaN, "batl": [[0, 2.16, 238.39]]}, {"timestamp": 1632570270184, "ltp": 2.16, "tv": 1714.64, "trd": NaN, "batb": NaN, "batl": [[0, 2.16, 246.23]]}, {"timestamp": 1632570274994, "ltp": 2.16, "tv": 1714.64, "trd": NaN, "batb": [[0, 2.06, 14.15], [1, 2, 15.05], [2, 1.95, 12.28]], "batl": [[0, 2.26, 165.17], [1, 2.28, 213.35], [2, 2.3, 6.15]]}, {"timestamp": 1632570276280, "ltp": 2.16, "tv": 1714.64, "trd": NaN, "batb": [[0, 2, 15.05], [1, 1.95, 12.28], [2, 1.94, 186.22]], "batl": NaN}, {"timestamp": 1632570278292, "ltp": 2.16, "tv": 1714.64, "trd": NaN, "batb": [[2, 1.91, 108.9]], "batl": [[0, 2.22, 3.25], [1, 2.26, 165.17], [2, 2.28, 213.35]]}, {"timestamp": 1632570279100, "ltp": 2.16, "tv": 1714.64, "trd": NaN, "batb": NaN, "batl": [[0, 2.26, 165.17], [1, 2.28, 213.35], [2, 2.3, 6.15]]}, {"timestamp": 1632570279467, "ltp": 2.16, "tv": 1714.64, "trd": NaN, "batb": [[1, 1.99, 4], [2, 1.95, 12.28]], "batl": NaN}, {"timestamp": 1632570281372, "ltp": 2.16, "tv": 1714.64, "trd": NaN, "batb": [[0, 2.16, 2], [1, 2.12, 366.61], [2, 2, 15.05]], "batl": [[1, 2.28, 227.25]]}, {"timestamp": 1632570282278, "ltp": 2.16, "tv": 1714.64, "trd": NaN, "batb": [[1, 2.12, 538.11], [2, 2.02, 247.08]], "batl": [[0, 2.24, 30.8], [1, 2.26, 165.17], [2, 2.28, 227.25]]}, {"timestamp": 1632570283607, "ltp": 2.16, "tv": 1714.64, "trd": NaN, "batb": [[2, 2.06, 4]], "batl": NaN}, {"timestamp": 1632570285782, "ltp": 2.16, "tv": 1714.64, "trd": NaN, "batb": [[1, 2.12, 524.72]], "batl": NaN}, {"timestamp": 1632570288005, "ltp": 2.16, "tv": 1714.64, "trd": NaN, "batb": [[1, 2.12, 528.76], [2, 2.1, 147.36]], "batl": [[0, 2.24, 3.73]]}, {"timestamp": 1632570289301, "ltp": 2.16, "tv": 1714.64, "trd": NaN, "batb": [[1, 2.14, 13.15]], "batl": [[0, 2.26, 3.25], [1, 2.3, 6.15], [2, 2.34, 150.36]]}, {"timestamp": 1632570290304, "ltp": 2.16, "tv": 1714.64, "trd": NaN, "batb": [[0, 2.1, 147.36], [1, 2.08, 231.19], [2, 2.06, 4]], "batl": NaN}, {"timestamp": 1632570291092, "ltp": 2.16, "tv": 1714.64, "trd": NaN, "batb": NaN, "batl": [[0, 2.22, 30.8], [1, 2.26, 3.25], [2, 2.3, 6.15]]}, {"timestamp": 1632570292310, "ltp": 2.16, "tv": 1714.64, "trd": NaN, "batb": [[0, 2.12, 4.04], [1, 2.1, 147.36], [2, 2.08, 231.19]], "batl": [[0, 2.24, 3.48]]}, {"timestamp": 1632570293380, "ltp": 2.16, "tv": 1714.64, "trd": NaN, "batb": [[0, 2.16, 3.53], [1, 2.12, 4.04], [2, 2.1, 147.36]], "batl": [[0, 2.26, 3.25], [1, 2.3, 6.15], [2, 2.48, 3.24]]}, {"timestamp": 1632570293491, "ltp": 2.16, "tv": 1714.64, "trd": NaN, "batb": [[0, 2.12, 4.04], [1, 2.1, 147.36], [2, 2.08, 231.19]], "batl": NaN}, {"timestamp": 1632570296356, "ltp": 2.16, "tv": 1714.64, "trd": NaN, "batb": [[1, 2.02, 184.24], [2, 2, 11.05]], "batl": [[0, 2.16, 13.62], [1, 2.2, 111.97], [2, 2.26, 3.25]]}, {"timestamp": 1632570297365, "ltp": 2.16, "tv": 1714.64, "trd": NaN, "batb": [[1, 2.04, 14.42], [2, 2.02, 184.24]], "batl": [[2, 2.24, 13.47]]}, {"timestamp": 1632570298349, "ltp": 2.16, "tv": 1714.64, "trd": NaN, "batb": NaN, "batl": [[2, 2.24, 29.72]]}, {"timestamp": 1632570299152, "ltp": 2.16, "tv": 1714.64, "trd": NaN, "batb": NaN, "batl": [[2, 2.24, 13.47]]}, {"timestamp": 1632570299673, "ltp": 2.12, "tv": 1722.56, "trd": [[2.12, 84.91]], "batb": [[0, 2.04, 14.5], [1, 2.02, 184.24], [2, 2, 11.05]], "batl": NaN}, {"timestamp": 1632570301339, "ltp": 2.12, "tv": 1722.56, "trd": NaN, "batb": NaN, "batl": [[2, 2.26, 3.25]]}, {"timestamp": 1632570301688, "ltp": 2.12, "tv": 1722.56, "trd": NaN, "batb": NaN, "batl": [[0, 2.14, 26.99], [1, 2.16, 13.62], [2, 2.2, 111.97]]}, {"timestamp": 1632570309177, "ltp": 2.14, "tv": 1722.94, "trd": [[2.14, 0.38]], "batb": NaN, "batl": [[0, 2.14, 26.8]]}, {"timestamp": 1632570315371, "ltp": 2.14, "tv": 1722.94, "trd": NaN, "batb": NaN, "batl": [[2, 2.22, 13.58]]}, {"timestamp": 1632570316074, "ltp": 2.12, "tv": 1723.02, "trd": [[2.12, 84.99]], "batb": [[0, 2.04, 14.42], [1, 1.97, 12.21], [2, 1.95, 11.91]], "batl": [[0, 2.22, 13.58], [1, 2.24, 182.22], [2, 2.26, 203.17]]}, {"timestamp": 1632570317303, "ltp": 2.12, "tv": 1723.02, "trd": NaN, "batb": [[0, 1.98, 5.37], [1, 1.97, 11.84]], "batl": [[0, 2.24, 182.22], [1, 2.26, 203.17], [2, 2.3, 6.15]]}, {"timestamp": 1632570319297, "ltp": 2.12, "tv": 1723.02, "trd": NaN, "batb": [[0, 1.99, 13.51], [1, 1.98, 5.37], [2, 1.97, 11.84]], "batl": NaN}, {"timestamp": 1632570320304, "ltp": 2.12, "tv": 1723.02, "trd": NaN, "batb": [[0, 1.98, 5.37], [1, 1.97, 11.84], [2, 1.95, 11.91]], "batl": [[0, 2.1, 20.35], [1, 2.2, 47.15], [2, 2.24, 182.22]]}, {"timestamp": 1632570321211, "ltp": 2.12, "tv": 1723.02, "trd": NaN, "batb": [[0, 1.99, 26.85], [1, 1.98, 5.37], [2, 1.97, 11.84]], "batl": [[0, 2.24, 184.22], [1, 2.26, 203.17], [2, 2.3, 6.15]]}, {"timestamp": 1632570323089, "ltp": 2.12, "tv": 1723.02, "trd": NaN, "batb": [[0, 1.99, 13.51]], "batl": NaN}, {"timestamp": 1632570324310, "ltp": 2.12, "tv": 1723.02, "trd": NaN, "batb": [[0, 1.98, 5.37], [1, 1.97, 11.84], [2, 1.95, 11.91]], "batl": [[0, 2.22, 67], [1, 2.24, 184.22], [2, 2.26, 203.17]]}, {"timestamp": 1632570324636, "ltp": 2.12, "tv": 1723.02, "trd": NaN, "batb": NaN, "batl": [[0, 2.24, 184.22], [1, 2.26, 203.17], [2, 2.3, 6.15]]}, {"timestamp": 1632570326198, "ltp": 2.12, "tv": 1723.02, "trd": NaN, "batb": [[0, 2, 26.85], [1, 1.98, 5.37], [2, 1.97, 11.84]], "batl": NaN}, {"timestamp": 1632570327310, "ltp": 2.12, "tv": 1723.02, "trd": NaN, "batb": [[0, 1.99, 11.51]], "batl": NaN}, {"timestamp": 1632570327583, "ltp": 2.12, "tv": 1723.02, "trd": NaN, "batb": [[0, 1.98, 5.37], [1, 1.97, 11.84], [2, 1.95, 11.91]], "batl": NaN}, {"timestamp": 1632570330292, "ltp": 2.12, "tv": 1723.02, "trd": NaN, "batb": [[1, 1.97, 15.84]], "batl": [[0, 2.24, 5.48], [1, 2.26, 3.25]]}, {"timestamp": 1632570330992, "ltp": 2.12, "tv": 1723.02, "trd": NaN, "batb": [[0, 1.99, 11.51], [1, 1.98, 5.37], [2, 1.97, 15.84]], "batl": NaN}, {"timestamp": 1632570333200, "ltp": 1.97, "tv": 1723.75, "trd": [[1.97, 0.37], [1.98, 68.55]], "batb": [[0, 1.97, 11.47], [1, 1.95, 11.91], [2, 1.9, 247.65]], "batl": [[0, 2.02, 123.35], [1, 2.14, 14.02], [2, 2.24, 5.48]]}, {"timestamp": 1632570334311, "ltp": 1.97, "tv": 1723.75, "trd": NaN, "batb": [[2, 1.93, 324.95]], "batl": [[0, 2, 220.09], [1, 2.02, 394.17], [2, 2.08, 2.44]]}, {"timestamp": 1632570336706, "ltp": 1.97, "tv": 1723.75, "trd": NaN, "batb": NaN, "batl": [[0, 2, 222.09]]}, {"timestamp": 1632570339306, "ltp": 1.97, "tv": 1746.69, "trd": [[1.97, 23.31]], "batb": [[0, 1.95, 11.91], [1, 1.93, 324.95], [2, 1.91, 315.19]], "batl": [[0, 1.99, 29.4], [1, 2, 222.09], [2, 2.02, 394.17]]}, {"timestamp": 1632570342121, "ltp": 1.97, "tv": 1746.69, "trd": NaN, "batb": NaN, "batl": [[1, 2, 425.13]]}, {"timestamp": 1632570345227, "ltp": 1.97, "tv": 1746.69, "trd": NaN, "batb": NaN, "batl": [[1, 2, 222.09]]}, {"timestamp": 1632570346517, "ltp": 1.97, "tv": 1746.69, "trd": NaN, "batb": NaN, "batl": [[0, 1.98, 7.96], [1, 1.99, 29.4], [2, 2, 222.09]]}, {"timestamp": 1632570348324, "ltp": 1.98, "tv": 1751.39, "trd": [[1.98, 73.24]], "batb": NaN, "batl": [[0, 1.98, 5.61]]}, {"timestamp": 1632570348429, "ltp": 1.98, "tv": 1751.39, "trd": NaN, "batb": NaN, "batl": [[1, 1.99, 125.33]]}, {"timestamp": 1632570351334, "ltp": 1.98, "tv": 1751.39, "trd": NaN, "batb": [[0, 1.88, 114.57], [1, 1.87, 16.08], [2, 1.72, 201.35]], "batl": [[0, 2, 2], [1, 2.04, 14.7], [2, 2.16, 176.18]]}, {"timestamp": 1632570352236, "ltp": 1.98, "tv": 1751.39, "trd": NaN, "batb": [[0, 1.72, 201.35], [1, 1.71, 305.26], [2, 1.7, 17.72]], "batl": [[0, 2.16, 176.18], [1, 2.18, 196.66], [2, 2.22, 3.75]]}, {"timestamp": 1632570354334, "ltp": 1.98, "tv": 1751.39, "trd": NaN, "batb": [[0, 1.98, 285.42], [1, 1.72, 201.35], [2, 1.71, 569.48]], "batl": [[0, 2.14, 364.09], [1, 2.16, 399.74], [2, 2.18, 196.66]]}, {"timestamp": 1632570355306, "ltp": 1.98, "tv": 1751.39, "trd": NaN, "batb": [[2, 1.71, 305.26]], "batl": [[0, 2.02, 499.36], [1, 2.16, 172.96]]}, {"timestamp": 1632570356035, "ltp": 1.95, "tv": 2303.17, "trd": [[1.95, 4.78], [1.98, 624.95]], "batb": [[0, 1.88, 342.71], [1, 1.86, 342.47], [2, 1.72, 205.35]], "batl": [[0, 1.95, 25.49], [1, 1.97, 291.52], [2, 2.16, 172.96]]}, {"timestamp": 1632570357342, "ltp": 1.95, "tv": 2303.17, "trd": NaN, "batb": [[0, 1.72, 205.35], [1, 1.71, 309.26], [2, 1.7, 17.72]], "batl": [[0, 2.12, 111.9], [1, 2.16, 172.96], [2, 2.18, 196.66]]}, {"timestamp": 1632570357535, "ltp": 1.95, "tv": 2303.17, "trd": NaN, "batb": NaN, "batl": [[2, 2.18, 200.41]]}, {"timestamp": 1632570359037, "ltp": 1.95, "tv": 2303.17, "trd": NaN, "batb": [[0, 1.72, 205.66]], "batl": [[1, 2.16, 176.93]]}, {"timestamp": 1632570360244, "ltp": 1.98, "tv": 2303.79, "trd": [[1.98, 625.57]], "batb": [[0, 1.89, 318.26], [1, 1.87, 336.5], [2, 1.72, 205.35]], "batl": [[0, 1.96, 280.25], [1, 1.98, 286.99], [2, 2.12, 111.9]]}, {"timestamp": 1632570360740, "ltp": 1.98, "tv": 2303.79, "trd": NaN, "batb": NaN, "batl": [[2, 2.16, 176.93]]}, {"timestamp": 1632570362250, "ltp": 1.98, "tv": 2303.79, "trd": NaN, "batb": [[0, 1.73, 1.88], [1, 1.72, 205.35], [2, 1.71, 309.26]], "batl": [[0, 2.16, 176.93], [1, 2.18, 200.41], [2, 2.22, 3.75]]}, {"timestamp": 1632570363342, "ltp": 1.98, "tv": 2303.79, "trd": NaN, "batb": [[0, 1.73, 6.88]], "batl": NaN}, {"timestamp": 1632570364237, "ltp": 1.98, "tv": 2303.79, "trd": NaN, "batb": [[1, 1.72, 4], [2, 1.71, 4]], "batl": NaN}, {"timestamp": 1632570364934, "ltp": 1.98, "tv": 2303.79, "trd": NaN, "batb": NaN, "batl": [[0, 2.16, 172.96], [1, 2.18, 196.66]]}, {"timestamp": 1632570367344, "ltp": 1.98, "tv": 2303.79, "trd": NaN, "batb": [[0, 2.04, 366.63], [1, 1.73, 6.88], [2, 1.66, 173.58]], "batl": [[0, 2.16, 275.25]]}, {"timestamp": 1632570368340, "ltp": 1.98, "tv": 2303.79, "trd": NaN, "batb": [[1, 2, 191.76], [2, 1.85, 120.4]], "batl": NaN}, {"timestamp": 1632570368823, "ltp": 1.98, "tv": 2303.79, "trd": NaN, "batb": [[2, 1.96, 15.3]], "batl": [[0, 2.14, 38.01], [1, 2.16, 289.17], [2, 2.18, 196.66]]}, {"timestamp": 1632570370347, "ltp": 1.98, "tv": 2303.79, "trd": NaN, "batb": [[2, 1.97, 3]], "batl": NaN}, {"timestamp": 1632570374233, "ltp": 1.98, "tv": 2303.79, "trd": NaN, "batb": [[2, 1.97, 15.17]], "batl": NaN}, {"timestamp": 1632570375245, "ltp": 1.98, "tv": 2303.79, "trd": NaN, "batb": [[2, 1.98, 15.15]], "batl": NaN}, {"timestamp": 1632570377958, "ltp": 2.06, "tv": 2346.7, "trd": [[2.06, 40.1], [2.08, 109.94]], "batb": NaN, "batl": NaN}, {"timestamp": 1632570379155, "ltp": 2.06, "tv": 2346.7, "trd": NaN, "batb": [[0, 1.98, 15.15], [1, 1.97, 15.17], [2, 1.96, 4]], "batl": [[0, 2.16, 13.92], [1, 2.2, 3.63], [2, 2.22, 3.75]]}, {"timestamp": 1632570380261, "ltp": 2.06, "tv": 2346.7, "trd": NaN, "batb": [[0, 1.97, 3], [1, 1.96, 4], [2, 1.93, 14.93]], "batl": [[0, 2.2, 3.63], [1, 2.22, 3.75], [2, 2.24, 3.48]]}, {"timestamp": 1632570382347, "ltp": 2.06, "tv": 2346.7, "trd": NaN, "batb": [[1, 1.93, 14.93], [2, 1.92, 187.13]], "batl": NaN}, {"timestamp": 1632570383261, "ltp": 2.06, "tv": 2346.7, "trd": NaN, "batb": [[0, 1.97, 15.51]], "batl": NaN}, {"timestamp": 1632570384266, "ltp": 2.06, "tv": 2346.7, "trd": NaN, "batb": [[0, 1.97, 3]], "batl": [[0, 2.16, 468.09], [1, 2.2, 3.63], [2, 2.22, 3.75]]}, {"timestamp": 1632570385230, "ltp": 2.06, "tv": 2346.7, "trd": NaN, "batb": NaN, "batl": [[0, 2.08, 18.19]]}, {"timestamp": 1632570386234, "ltp": 2.06, "tv": 2346.7, "trd": NaN, "batb": [[0, 1.97, 29.2], [1, 1.96, 5], [2, 1.93, 14.93]], "batl": [[0, 2.18, 18.15]]}, {"timestamp": 1632570387559, "ltp": 2.06, "tv": 2346.7, "trd": NaN, "batb": [[0, 1.97, 42.71]], "batl": NaN}, {"timestamp": 1632570390146, "ltp": 2.06, "tv": 2346.7, "trd": NaN, "batb": [[0, 1.97, 16.51]], "batl": [[0, 2.2, 3.63], [1, 2.22, 3.75], [2, 2.24, 3.48]]}, {"timestamp": 1632570390956, "ltp": 2.06, "tv": 2346.7, "trd": NaN, "batb": [[0, 1.97, 3]], "batl": NaN}, {"timestamp": 1632570397875, "ltp": 2.06, "tv": 2346.7, "trd": NaN, "batb": [[1, 1.93, 14.93], [2, 1.92, 187.13]], "batl": NaN}, {"timestamp": 1632570401054, "ltp": 2.06, "tv": 2346.7, "trd": NaN, "batb": [[1, 1.96, 5], [2, 1.93, 14.93]], "batl": NaN}, {"timestamp": 1632570402169, "ltp": 2.06, "tv": 2346.7, "trd": NaN, "batb": [[0, 1.97, 15.17]], "batl": NaN}, {"timestamp": 1632570402783, "ltp": 2.06, "tv": 2346.7, "trd": NaN, "batb": [[0, 1.97, 3]], "batl": [[1, 2.24, 3.48], [2, 2.26, 158.94]]}, {"timestamp": 1632570405282, "ltp": 2.06, "tv": 2346.7, "trd": NaN, "batb": [[0, 2, 298.57], [1, 1.97, 3], [2, 1.96, 5]], "batl": [[1, 2.24, 19.54]]}, {"timestamp": 1632570406358, "ltp": 2.06, "tv": 2346.7, "trd": NaN, "batb": [[0, 2.06, 171.81], [1, 2.04, 14.42], [2, 2, 190.49]], "batl": [[2, 2.26, 172.3]]}, {"timestamp": 1632570407374, "ltp": 2.06, "tv": 2346.7, "trd": NaN, "batb": NaN, "batl": [[0, 2.18, 18.15], [1, 2.2, 3.63], [2, 2.24, 19.54]]}, {"timestamp": 1632570408197, "ltp": 2.06, "tv": 2346.7, "trd": NaN, "batb": [[2, 2.02, 4]], "batl": NaN}, {"timestamp": 1632570411379, "ltp": 2.06, "tv": 2346.7, "trd": NaN, "batb": [[1, 2.02, 4], [2, 2, 195.49]], "batl": NaN}, {"timestamp": 1632570412202, "ltp": 2.06, "tv": 2346.7, "trd": NaN, "batb": [[1, 2.04, 182.46], [2, 2.02, 201.69]], "batl": NaN}, {"timestamp": 1632570414376, "ltp": 2.06, "tv": 2346.7, "trd": NaN, "batb": [[0, 2.08, 171.22], [1, 2.06, 14.15], [2, 2.04, 182.46]], "batl": NaN}, {"timestamp": 1632570415688, "ltp": 2.16, "tv": 2350.55, "trd": [[2.16, 108.54]], "batb": NaN, "batl": NaN}, {"timestamp": 1632570416970, "ltp": 2.16, "tv": 2351.07, "trd": [[2.16, 109.05]], "batb": NaN, "batl": [[0, 2.16, 1.83], [1, 2.18, 18.15], [2, 2.2, 3.63]]}, {"timestamp": 1632570421281, "ltp": 2.16, "tv": 2351.07, "trd": NaN, "batb": NaN, "batl": [[2, 2.2, 15.47]]}, {"timestamp": 1632570425798, "ltp": 2.16, "tv": 2351.07, "trd": NaN, "batb": NaN, "batl": [[2, 2.2, 3.63]]}, {"timestamp": 1632570431800, "ltp": 2.16, "tv": 2351.07, "trd": NaN, "batb": NaN, "batl": [[2, 2.2, 15.47]]}, {"timestamp": 1632570438711, "ltp": 2.16, "tv": 2352.9, "trd": [[2.16, 110.89]], "batb": NaN, "batl": [[0, 2.18, 18.15], [1, 2.2, 15.47], [2, 2.24, 3.48]]}, {"timestamp": 1632570449170, "ltp": 2.12, "tv": 2358.66, "trd": [[2.12, 90.75]], "batb": NaN, "batl": NaN}, {"timestamp": 1632570455658, "ltp": 2.12, "tv": 2363.49, "trd": [[2.12, 95.58]], "batb": NaN, "batl": NaN}, {"timestamp": 1632570457740, "ltp": 2.12, "tv": 2363.49, "trd": NaN, "batb": NaN, "batl": [[1, 2.2, 3.63]]}, {"timestamp": 1632570460662, "ltp": 2.12, "tv": 2363.49, "trd": NaN, "batb": NaN, "batl": [[0, 2.16, 12.18], [1, 2.18, 18.15], [2, 2.2, 3.63]]}, {"timestamp": 1632570494290, "ltp": 2.12, "tv": 2363.49, "trd": NaN, "batb": [[0, 2.06, 14.15], [1, 2.04, 182.46], [2, 2.02, 201.69]], "batl": [[0, 2.26, 13.36], [1, 2.4, 164.93], [2, 2.42, 207.79]]}, {"timestamp": 1632570495290, "ltp": 2.12, "tv": 2373.28, "trd": [[2.12, 105.37]], "batb": [[0, 2.04, 182.46], [1, 2.02, 201.69], [2, 2, 189.82]], "batl": [[0, 2.12, 77.14]]}, {"timestamp": 1632570497196, "ltp": 2.12, "tv": 2373.28, "trd": NaN, "batb": [[0, 2.04, 186.33]], "batl": [[1, 2.36, 2.82], [2, 2.4, 164.93]]}, {"timestamp": 1632570502001, "ltp": 2.12, "tv": 2373.28, "trd": NaN, "batb": [[0, 2.1, 2.35], [1, 2.04, 186.33], [2, 2.02, 201.69]], "batl": [[0, 2.12, 1.96]]}, {"timestamp": 1632570503987, "ltp": 2.12, "tv": 2373.28, "trd": NaN, "batb": [[1, 2.06, 4.58], [2, 2.04, 3.87]], "batl": NaN}, {"timestamp": 1632570505098, "ltp": 2.04, "tv": 2403.59, "trd": [[2.04, 40.44], [2.1, 146.53]], "batb": [[0, 2.02, 4], [1, 2, 189.82], [2, 1.9, 5.76]], "batl": [[0, 2.04, 53.05], [1, 2.12, 1.96], [2, 2.36, 2.82]]}, {"timestamp": 1632570506314, "ltp": 2.36, "tv": 2459.26, "trd": [[2.04, 93.48], [2.12, 107.33], [2.36, 0.67]], "batb": NaN, "batl": [[0, 2.36, 2.15], [1, 2.4, 164.93], [2, 2.42, 207.79]]}, {"timestamp": 1632570507327, "ltp": 2.36, "tv": 2459.26, "trd": NaN, "batb": NaN, "batl": [[0, 2.4, 164.93], [1, 2.42, 207.79], [2, 2.46, 88.65]]}, {"timestamp": 1632570508226, "ltp": 2.36, "tv": 2459.26, "trd": NaN, "batb": [[0, 2.28, 132.66], [1, 2.14, 155.49], [2, 2.02, 4]], "batl": NaN}, {"timestamp": 1632570508392, "ltp": 2.36, "tv": 2459.26, "trd": NaN, "batb": [[2, 2.02, 24]], "batl": NaN}, {"timestamp": 1632570510302, "ltp": 2.36, "tv": 2459.26, "trd": NaN, "batb": [[2, 2.04, 2]], "batl": [[0, 2.38, 24.06], [1, 2.4, 164.93], [2, 2.42, 207.79]]}, {"timestamp": 1632570513720, "ltp": 2.36, "tv": 2459.26, "trd": NaN, "batb": [[1, 2.24, 12.09], [2, 2.16, 19.31]], "batl": NaN}, {"timestamp": 1632570521209, "ltp": 2.36, "tv": 2459.26, "trd": NaN, "batb": [[0, 2.24, 12.09], [1, 2.16, 19.31], [2, 2.14, 315.12]], "batl": [[0, 2.48, 12.32], [1, 2.7, 128.13], [2, 2.72, 182.93]]}, {"timestamp": 1632570521840, "ltp": 2.36, "tv": 2459.26, "trd": NaN, "batb": [[1, 2.14, 315.12], [2, 2.12, 221.61]], "batl": NaN}, {"timestamp": 1632570522627, "ltp": 2.36, "tv": 2459.26, "trd": NaN, "batb": [[0, 2.14, 315.12], [1, 2.12, 221.61], [2, 2.1, 19.78]], "batl": [[0, 2.7, 128.13], [1, 2.72, 182.93], [2, 2.76, 2.27]]}, {"timestamp": 1632570524323, "ltp": 2.36, "tv": 2459.26, "trd": NaN, "batb": NaN, "batl": [[0, 2.94, 2.08], [1, 2.98, 2.25], [2, 3, 217.75]]}, {"timestamp": 1632570525334, "ltp": 2.36, "tv": 2459.26, "trd": NaN, "batb": [[0, 2.16, 20.06], [1, 2.14, 315.12], [2, 2.12, 221.61]], "batl": [[2, 5.8, 2.54]]}, {"timestamp": 1632570525859, "ltp": 2.36, "tv": 2459.26, "trd": NaN, "batb": NaN, "batl": [[0, 2.7, 3], [1, 2.94, 2.08], [2, 2.98, 2.25]]}, {"timestamp": 1632570527040, "ltp": 2.36, "tv": 2459.26, "trd": NaN, "batb": NaN, "batl": [[0, 2.24, 16.9], [1, 2.48, 12.1], [2, 2.7, 3]]}, {"timestamp": 1632570528357, "ltp": 2.36, "tv": 2459.26, "trd": NaN, "batb": [[2, 2.12, 235]], "batl": [[1, 2.36, 12.86], [2, 2.48, 12.1]]}, {"timestamp": 1632570532235, "ltp": 2.36, "tv": 2459.26, "trd": NaN, "batb": NaN, "batl": [[1, 2.48, 12.1], [2, 2.5, 1.71]]}, {"timestamp": 1632570534247, "ltp": 2.36, "tv": 2459.26, "trd": NaN, "batb": NaN, "batl": [[1, 2.48, 164.26], [2, 2.5, 152.8]]}, {"timestamp": 1632570535355, "ltp": 2.36, "tv": 2459.26, "trd": NaN, "batb": NaN, "batl": [[1, 2.34, 12.95], [2, 2.48, 164.26]]}, {"timestamp": 1632570537254, "ltp": 2.36, "tv": 2459.26, "trd": NaN, "batb": [[0, 2.16, 16.53], [1, 2.12, 13.39], [2, 2.08, 21.62]], "batl": [[0, 2.34, 12.95], [1, 2.48, 152.16], [2, 2.5, 155.29]]}, {"timestamp": 1632570538268, "ltp": 2.36, "tv": 2459.26, "trd": NaN, "batb": [[0, 2.04, 178.06], [1, 2.02, 165.63], [2, 2, 179.72]], "batl": [[0, 2.48, 152.16], [1, 2.5, 153.57], [2, 2.6, 2.46]]}, {"timestamp": 1632570538657, "ltp": 2.36, "tv": 2459.26, "trd": NaN, "batb": NaN, "batl": [[0, 2.48, 149.42]]}, {"timestamp": 1632570540236, "ltp": 2.36, "tv": 2459.26, "trd": NaN, "batb": [[0, 2.04, 200.55]], "batl": NaN}, {"timestamp": 1632570541368, "ltp": 2.36, "tv": 2459.26, "trd": NaN, "batb": [[0, 2.08, 17.81], [1, 2.04, 182.43], [2, 2.02, 165.63]], "batl": [[0, 2.6, 2.46], [1, 2.62, 2.75], [2, 2.66, 4]]}, {"timestamp": 1632570542164, "ltp": 2.36, "tv": 2459.26, "trd": NaN, "batb": [[0, 2.04, 182.43], [1, 2.02, 165.63], [2, 2, 179.72]], "batl": NaN}, {"timestamp": 1632570544360, "ltp": 2.36, "tv": 2459.26, "trd": NaN, "batb": NaN, "batl": [[0, 2.12, 13.43], [1, 2.14, 3.25], [2, 2.16, 91.74]]}, {"timestamp": 1632570545375, "ltp": 2.12, "tv": 2464.13, "trd": [[2.12, 112.2]], "batb": NaN, "batl": [[0, 2.12, 8.56]]}, {"timestamp": 1632570549374, "ltp": 2.12, "tv": 2466.09, "trd": [[2.12, 114.16]], "batb": [[1, 2.02, 180.33]], "batl": [[0, 2.12, 6.6]]}, {"timestamp": 1632570550965, "ltp": 2.12, "tv": 2466.09, "trd": NaN, "batb": [[1, 2.02, 184.07]], "batl": NaN}, {"timestamp": 1632570554280, "ltp": 2.12, "tv": 2467.83, "trd": [[2.12, 115.9]], "batb": NaN, "batl": [[0, 2.12, 4.86]]}, {"timestamp": 1632570555362, "ltp": 2.12, "tv": 2469.37, "trd": [[2.12, 117.44]], "batb": NaN, "batl": [[0, 2.14, 3.25], [1, 2.18, 4], [2, 2.22, 17.33]]}, {"timestamp": 1632570556099, "ltp": 2.12, "tv": 2469.37, "trd": NaN, "batb": [[0, 2.04, 4.37], [1, 2.02, 18.44], [2, 2, 3]], "batl": [[0, 2.22, 13.58], [1, 2.28, 3.34], [2, 2.32, 193.52]]}, {"timestamp": 1632570557297, "ltp": 2.12, "tv": 2469.37, "trd": NaN, "batb": [[0, 2.02, 3.74], [1, 2, 3], [2, 1.99, 174.84]], "batl": [[0, 2.28, 3.34], [1, 2.32, 193.52], [2, 2.34, 209.27]]}, {"timestamp": 1632570558184, "ltp": 2.12, "tv": 2469.37, "trd": NaN, "batb": [[2, 1.99, 169.84]], "batl": NaN}, {"timestamp": 1632570559263, "ltp": 2.12, "tv": 2469.37, "trd": NaN, "batb": NaN, "batl": [[0, 2.22, 4.25], [1, 2.28, 3.34], [2, 2.32, 193.52]]}, {"timestamp": 1632570560278, "ltp": 2.12, "tv": 2469.37, "trd": NaN, "batb": NaN, "batl": [[0, 2.08, 2.35]]}, {"timestamp": 1632570560585, "ltp": 2.08, "tv": 2471.72, "trd": [[2.08, 112.29]], "batb": NaN, "batl": [[0, 2.28, 3.34], [1, 2.32, 193.52], [2, 2.34, 209.27]]}, {"timestamp": 1632570562359, "ltp": 2.08, "tv": 2471.72, "trd": NaN, "batb": [[2, 1.98, 197.26]], "batl": NaN}, {"timestamp": 1632570565283, "ltp": 2.28, "tv": 2472.92, "trd": [[2.28, 9.11]], "batb": [[0, 2.22, 1076.86], [1, 2.2, 418.08], [2, 2.18, 1045.19]], "batl": [[0, 2.28, 2.14], [1, 2.32, 199.9]]}, {"timestamp": 1632570566382, "ltp": 2.28, "tv": 2472.92, "trd": NaN, "batb": [[0, 2.22, 570.25], [2, 2.18, 430.79]], "batl": [[1, 2.32, 193.52]]}, {"timestamp": 1632570569291, "ltp": 2.28, "tv": 2472.92, "trd": NaN, "batb": [[2, 2.18, 418.08]], "batl": NaN}, {"timestamp": 1632570570380, "ltp": 2.28, "tv": 2475.06, "trd": [[2.28, 11.25]], "batb": NaN, "batl": [[0, 2.32, 193.52], [1, 2.34, 209.27], [2, 2.36, 83.6]]}, {"timestamp": 1632570571286, "ltp": 2.22, "tv": 2483.55, "trd": [[2.22, 20.98], [2.24, 1.51]], "batb": [[0, 2.22, 566.76]], "batl": NaN}, {"timestamp": 1632570571877, "ltp": 2.22, "tv": 2483.55, "trd": NaN, "batb": [[1, 2.2, 430.58]], "batl": [[0, 2.32, 199.9]]}, {"timestamp": 1632570578380, "ltp": 2.22, "tv": 2483.55, "trd": NaN, "batb": NaN, "batl": [[0, 2.32, 223.75]]}, {"timestamp": 1632570582295, "ltp": 2.22, "tv": 2483.55, "trd": NaN, "batb": [[0, 2.22, 139.51], [1, 2.2, 12.5], [2, 2.14, 2.45]], "batl": [[0, 2.42, 12.58], [1, 2.66, 4], [2, 2.7, 128.21]]}, {"timestamp": 1632570582887, "ltp": 2.22, "tv": 2483.55, "trd": NaN, "batb": [[0, 2.2, 12.5], [1, 2.1, 5.75], [2, 2.08, 169.86]], "batl": NaN}, {"timestamp": 1632570583716, "ltp": 2.22, "tv": 2483.55, "trd": NaN, "batb": [[0, 2.1, 5.75], [1, 2.08, 169.86], [2, 2.06, 178.75]], "batl": [[0, 2.66, 4], [1, 2.7, 128.21], [2, 2.72, 166.85]]}, {"timestamp": 1632570585309, "ltp": 2.22, "tv": 2483.55, "trd": NaN, "batb": NaN, "batl": [[0, 2.36, 4], [1, 2.66, 4], [2, 2.7, 128.21]]}, {"timestamp": 1632570586210, "ltp": 2.22, "tv": 2483.55, "trd": NaN, "batb": NaN, "batl": [[0, 2.66, 4], [1, 2.7, 128.21], [2, 2.72, 166.85]]}, {"timestamp": 1632570588291, "ltp": 2.22, "tv": 2483.55, "trd": NaN, "batb": NaN, "batl": [[0, 2.4, 20.44], [1, 2.66, 4], [2, 2.7, 128.21]]}, {"timestamp": 1632570589305, "ltp": 2.22, "tv": 2483.55, "trd": NaN, "batb": [[1, 2.08, 173.67]], "batl": [[0, 2.66, 4], [1, 2.7, 128.21], [2, 2.72, 166.85]]}, {"timestamp": 1632570589881, "ltp": 2.22, "tv": 2483.55, "trd": NaN, "batb": [[1, 2.08, 169.86]], "batl": NaN}, {"timestamp": 1632570591326, "ltp": 2.22, "tv": 2483.55, "trd": NaN, "batb": [[0, 2.12, 29.2], [1, 2.1, 5.3], [2, 2.08, 169.86]], "batl": [[0, 2.64, 20], [1, 2.66, 4], [2, 2.7, 128.21]]}, {"timestamp": 1632570592328, "ltp": 2.22, "tv": 2483.55, "trd": NaN, "batb": [[0, 2.1, 5.75], [1, 2.08, 169.86], [2, 2.06, 178.75]], "batl": [[0, 2.66, 4], [1, 2.7, 128.21], [2, 2.72, 166.85]]}, {"timestamp": 1632570596183, "ltp": 2.22, "tv": 2483.55, "trd": NaN, "batb": [[1, 2.08, 173.67]], "batl": NaN}, {"timestamp": 1632570599089, "ltp": 2.22, "tv": 2483.55, "trd": NaN, "batb": [[1, 2.08, 169.86]], "batl": NaN}, {"timestamp": 1632570599981, "ltp": 2.22, "tv": 2483.55, "trd": NaN, "batb": [[0, 2.08, 170.31], [1, 2.06, 178.75], [2, 2.04, 259.07]], "batl": NaN}, {"timestamp": 1632570602324, "ltp": 2.22, "tv": 2483.55, "trd": NaN, "batb": [[0, 2.08, 173.87]], "batl": NaN}, {"timestamp": 1632570603204, "ltp": 2.22, "tv": 2483.55, "trd": NaN, "batb": [[0, 2.14, 5.65], [1, 2.08, 169.86], [2, 2.06, 178.75]], "batl": NaN}, {"timestamp": 1632570604809, "ltp": 2.14, "tv": 2485.47, "trd": [[2.14, 1.85], [2.16, 111.34]], "batb": [[0, 2.14, 3.73], [2, 2.04, 4.37]], "batl": NaN}, {"timestamp": 1632570607205, "ltp": 2.14, "tv": 2485.47, "trd": NaN, "batb": [[0, 2.62, 1459.92], [1, 2.6, 1416.98], [2, 2.58, 1416.98]], "batl": [[0, 2.7, 128.21], [1, 2.72, 166.85], [2, 2.78, 13.41]]}, {"timestamp": 1632570608311, "ltp": 2.14, "tv": 2485.47, "trd": NaN, "batb": [[0, 2.62, 364.98], [1, 2.6, 366.83], [2, 2.58, 354.24]], "batl": [[0, 2.72, 166.85], [1, 2.78, 13.41], [2, 2.8, 2.52]]}, {"timestamp": 1632570609306, "ltp": 2.14, "tv": 2485.47, "trd": NaN, "batb": [[0, 2.66, 87.85], [1, 2.62, 364.98], [2, 2.6, 366.83]], "batl": NaN}, {"timestamp": 1632570618303, "ltp": 2.14, "tv": 2485.47, "trd": NaN, "batb": [[2, 2.6, 376.2]], "batl": [[1, 2.8, 2.52], [2, 2.84, 102.25]]}, {"timestamp": 1632570620628, "ltp": 2.14, "tv": 2485.47, "trd": NaN, "batb": NaN, "batl": [[0, 2.72, 176.37]]}, {"timestamp": 1632570623329, "ltp": 2.68, "tv": 2485.75, "trd": [[2.68, 0.28]], "batb": NaN, "batl": NaN}, {"timestamp": 1632570624918, "ltp": 2.72, "tv": 2495.27, "trd": [[2.72, 9.52]], "batb": NaN, "batl": [[0, 2.8, 2.52], [1, 2.84, 102.25], [2, 2.88, 332.04]]}, {"timestamp": 1632570628148, "ltp": 2.72, "tv": 2495.27, "trd": NaN, "batb": NaN, "batl": [[0, 2.78, 12.6], [1, 2.8, 2.52], [2, 2.84, 102.25]]}, {"timestamp": 1632570630230, "ltp": 2.72, "tv": 2495.27, "trd": NaN, "batb": [[0, 2.6, 19.96], [1, 2.28, 131.48], [2, 2.22, 17.86]], "batl": [[0, 2.9, 10.88], [1, 3.45, 184.03], [2, 5, 2]]}, {"timestamp": 1632570631350, "ltp": 2.72, "tv": 2495.27, "trd": NaN, "batb": [[0, 2.6, 10.59]], "batl": [[0, 3.45, 184.03], [1, 5, 2], [2, 5.8, 2.54]]}, {"timestamp": 1632570633130, "ltp": 2.72, "tv": 2495.27, "trd": NaN, "batb": [[2, 2.26, 133.08]], "batl": NaN}, {"timestamp": 1632570633640, "ltp": 2.72, "tv": 2495.27, "trd": NaN, "batb": [[1, 2.26, 133.08], [2, 2.22, 17.86]], "batl": NaN}, {"timestamp": 1632570635534, "ltp": 2.72, "tv": 2495.27, "trd": NaN, "batb": [[0, 2.26, 133.08], [1, 2.22, 17.86], [2, 2.16, 4]], "batl": NaN}, {"timestamp": 1632570637628, "ltp": 2.72, "tv": 2495.27, "trd": NaN, "batb": [[1, 2.22, 14.34]], "batl": NaN}, {"timestamp": 1632570640340, "ltp": 2.72, "tv": 2495.27, "trd": NaN, "batb": NaN, "batl": [[0, 4.2, 84.72], [1, 4.7, 813.84], [2, 4.8, 493.69]]}, {"timestamp": 1632570641249, "ltp": 2.72, "tv": 2495.27, "trd": NaN, "batb": NaN, "batl": [[0, 4.2, 93.57], [1, 4.7, 203.46], [2, 4.8, 197.48]]}, {"timestamp": 1632570642310, "ltp": 2.72, "tv": 2495.27, "trd": NaN, "batb": [[0, 4.1, 146.1], [1, 3.55, 102.64], [2, 3.45, 370.29]], "batl": NaN}, {"timestamp": 1632570643275, "ltp": 2.72, "tv": 2495.27, "trd": NaN, "batb": NaN, "batl": [[1, 4.4, 8.13], [2, 4.5, 2]]}, {"timestamp": 1632570644274, "ltp": 2.72, "tv": 2495.27, "trd": NaN, "batb": [[2, 3.45, 128.78]], "batl": NaN}, {"timestamp": 1632570645185, "ltp": 2.72, "tv": 2495.27, "trd": NaN, "batb": [[2, 3.4, 73.53]], "batl": [[1, 4.3, 57.16], [2, 4.4, 8.13]]}, {"timestamp": 1632570645785, "ltp": 2.72, "tv": 2495.27, "trd": NaN, "batb": [[1, 3.75, 5.45], [2, 3.55, 102.64]], "batl": [[1, 4.4, 8.13], [2, 4.5, 2]]}, {"timestamp": 1632570647017, "ltp": 2.72, "tv": 2495.27, "trd": NaN, "batb": [[1, 3.55, 102.64], [2, 3.4, 73.53]], "batl": NaN}, {"timestamp": 1632570647913, "ltp": 2.72, "tv": 2495.27, "trd": NaN, "batb": [[1, 3.55, 233.39], [2, 3.5, 117.45]], "batl": NaN}, {"timestamp": 1632570650200, "ltp": 4.1, "tv": 2560.2, "trd": [[4.1, 64.93]], "batb": [[0, 4.1, 113.64], [1, 3.85, 5.26], [2, 3.55, 233.39]], "batl": NaN}, {"timestamp": 1632570651204, "ltp": 4.1, "tv": 2560.2, "trd": NaN, "batb": NaN, "batl": [[0, 4.2, 91.86]]}, {"timestamp": 1632570654287, "ltp": 4.1, "tv": 2568.46, "trd": [[4.1, 73.19]], "batb": [[0, 4.1, 109.51]], "batl": NaN}, {"timestamp": 1632570654985, "ltp": 4.1, "tv": 2582.42, "trd": [[4.1, 83.35], [4.2, 3.8]], "batb": [[0, 4.1, 104.43]], "batl": [[0, 4.2, 89.96]]}, {"timestamp": 1632570655885, "ltp": 4.2, "tv": 2596.79, "trd": [[4.2, 18.17]], "batb": NaN, "batl": [[0, 4.2, 75.59]]}, {"timestamp": 1632570659247, "ltp": 4.1, "tv": 2613.94, "trd": [[4.1, 100.49]], "batb": [[0, 4.1, 95.86]], "batl": NaN}, {"timestamp": 1632570666608, "ltp": 4.1, "tv": 2627.28, "trd": [[4.1, 113.83]], "batb": [[0, 4.1, 89.19]], "batl": NaN}, {"timestamp": 1632570668995, "ltp": 4.2, "tv": 2627.31, "trd": [[4.2, 18.2]], "batb": NaN, "batl": [[0, 4.2, 75.56]]}, {"timestamp": 1632570672020, "ltp": 4.2, "tv": 2627.31, "trd": NaN, "batb": [[0, 3.85, 5.26], [1, 3.55, 233.39], [2, 3.5, 117.45]], "batl": [[0, 4.4, 8.13], [1, 4.5, 2], [2, 4.7, 91.33]]}, {"timestamp": 1632570673309, "ltp": 4.2, "tv": 2627.31, "trd": NaN, "batb": [[0, 3.55, 233.39], [1, 3.5, 117.45], [2, 3.35, 2.07]], "batl": [[0, 4.5, 2], [1, 4.6, 2]]}, {"timestamp": 1632570675233, "ltp": 4.2, "tv": 2627.31, "trd": NaN, "batb": [[0, 3.55, 130.74], [1, 3.5, 224.07]], "batl": NaN}, {"timestamp": 1632570678016, "ltp": 4.2, "tv": 2627.31, "trd": NaN, "batb": NaN, "batl": [[0, 4.2, 38.33], [1, 4.5, 2], [2, 4.6, 2]]}, {"timestamp": 1632570678618, "ltp": 4.2, "tv": 2627.31, "trd": NaN, "batb": [[0, 3.6, 49.52], [1, 3.55, 130.74], [2, 3.5, 224.07]], "batl": [[0, 4.4, 10]]}, {"timestamp": 1632570681223, "ltp": 4.2, "tv": 2627.31, "trd": NaN, "batb": [[0, 3.55, 130.74], [1, 3.5, 224.07], [2, 3.35, 2.07]], "batl": [[0, 4.5, 2], [1, 4.6, 2], [2, 4.7, 91.33]]}, {"timestamp": 1632570684052, "ltp": 4.2, "tv": 2627.31, "trd": NaN, "batb": [[0, 3.5, 106.62], [1, 3.15, 2.03], [2, 2.42, 389.42]], "batl": NaN}, {"timestamp": 1632570684942, "ltp": 4.2, "tv": 2629.18, "trd": [[4.2, 20.07]], "batb": NaN, "batl": [[0, 4, 68.95], [1, 4.5, 2], [2, 4.6, 2]]}, {"timestamp": 1632570686322, "ltp": 4.0, "tv": 2698.13, "trd": [[4, 68.95]], "batb": [[0, 4, 2], [1, 3.5, 106.62], [2, 3.15, 2.03]], "batl": [[0, 4.4, 53.94]]}, {"timestamp": 1632570687278, "ltp": 4.0, "tv": 2698.13, "trd": NaN, "batb": NaN, "batl": [[1, 4.5, 8.38]]}, {"timestamp": 1632570688239, "ltp": 4.0, "tv": 2698.13, "trd": NaN, "batb": [[0, 4.3, 129.45], [1, 4, 2], [2, 3.8, 85.48]], "batl": NaN}, {"timestamp": 1632570689343, "ltp": 4.0, "tv": 2698.13, "trd": NaN, "batb": NaN, "batl": [[0, 4.4, 55.94]]}, {"timestamp": 1632570690247, "ltp": 4.0, "tv": 2698.13, "trd": NaN, "batb": [[1, 4.1, 2], [2, 4, 4]], "batl": [[0, 4.4, 53.94]]}, {"timestamp": 1632570691282, "ltp": 4.0, "tv": 2698.13, "trd": NaN, "batb": NaN, "batl": [[1, 4.5, 46.03]]}, {"timestamp": 1632570692226, "ltp": 4.0, "tv": 2698.13, "trd": NaN, "batb": [[1, 4.1, 6.83]], "batl": [[1, 4.5, 8.38]]}, {"timestamp": 1632570693254, "ltp": 4.0, "tv": 2698.13, "trd": NaN, "batb": [[1, 4.1, 4.83]], "batl": NaN}, {"timestamp": 1632570695225, "ltp": 4.3, "tv": 2698.32, "trd": [[4.3, 0.19]], "batb": [[0, 4.3, 129.35]], "batl": NaN}, {"timestamp": 1632570696927, "ltp": 4.3, "tv": 2698.32, "trd": NaN, "batb": NaN, "batl": [[1, 4.5, 6.67]]}, {"timestamp": 1632570702339, "ltp": 4.3, "tv": 2698.32, "trd": NaN, "batb": [[0, 4.1, 4.83], [1, 3.8, 85.48], [2, 3.75, 125.26]], "batl": [[0, 4.8, 89.39], [1, 4.9, 94.32], [2, 5, 2]]}, {"timestamp": 1632570703361, "ltp": 4.3, "tv": 2698.32, "trd": NaN, "batb": [[0, 3.8, 85.48], [1, 3.75, 125.26], [2, 3.7, 119.26]], "batl": NaN}, {"timestamp": 1632570705372, "ltp": 4.3, "tv": 2698.32, "trd": NaN, "batb": NaN, "batl": [[0, 4.8, 91.39]]}, {"timestamp": 1632570706169, "ltp": 4.3, "tv": 2698.32, "trd": NaN, "batb": [[0, 3.85, 2], [1, 3.8, 85.48], [2, 3.7, 2]], "batl": NaN}, {"timestamp": 1632570706445, "ltp": 4.3, "tv": 2698.32, "trd": NaN, "batb": [[0, 3.8, 85.48], [1, 3.7, 2], [2, 2.42, 389.42]], "batl": NaN}, {"timestamp": 1632570709256, "ltp": 4.3, "tv": 2698.32, "trd": NaN, "batb": [[0, 4.3, 190.13], [1, 4.2, 2], [2, 3.8, 85.48]], "batl": [[0, 4.7, 51.64], [1, 4.8, 89.39], [2, 4.9, 94.32]]}, {"timestamp": 1632570710263, "ltp": 4.3, "tv": 2698.32, "trd": NaN, "batb": [[0, 4.5, 114.48], [1, 4.3, 194.67], [2, 4.2, 2]], "batl": [[1, 4.8, 95.64]]}, {"timestamp": 1632570714876, "ltp": 4.3, "tv": 2698.32, "trd": NaN, "batb": [[0, 4.5, 118.19]], "batl": [[0, 4.7, 57.96]]}, {"timestamp": 1632570716262, "ltp": 4.3, "tv": 2698.32, "trd": NaN, "batb": NaN, "batl": [[2, 4.9, 183.91]]}, {"timestamp": 1632570718903, "ltp": 4.3, "tv": 2698.32, "trd": NaN, "batb": [[0, 4.5, 114.48]], "batl": [[0, 4.7, 51.64]]}, {"timestamp": 1632570720270, "ltp": 4.3, "tv": 2698.32, "trd": NaN, "batb": [[1, 4.3, 4.54], [2, 4.1, 141.62]], "batl": [[0, 4.9, 89.59], [1, 5, 126.4], [2, 5.1, 7.4]]}, {"timestamp": 1632570721284, "ltp": 4.3, "tv": 2698.32, "trd": NaN, "batb": [[0, 4.1, 141.62], [1, 4, 115.73], [2, 3.95, 128.34]], "batl": [[0, 4.9, 87.59], [2, 5.5, 117.37]]}, {"timestamp": 1632570723188, "ltp": 4.3, "tv": 2698.32, "trd": NaN, "batb": [[1, 4, 2], [2, 3.85, 2]], "batl": NaN}, {"timestamp": 1632570724295, "ltp": 4.3, "tv": 2698.32, "trd": NaN, "batb": NaN, "batl": [[0, 4.3, 1.71], [1, 4.9, 90.59], [2, 5, 126.4]]}, {"timestamp": 1632570724694, "ltp": 4.3, "tv": 2698.32, "trd": NaN, "batb": NaN, "batl": [[1, 4.9, 87.59]]}, {"timestamp": 1632570726303, "ltp": 4.6, "tv": 2700.85, "trd": [[4.3, 1.9], [4.6, 0.82]], "batb": [[0, 4.6, 102.18], [1, 4.5, 241.81], [2, 4.4, 103.18]], "batl": [[0, 5, 164.95], [1, 5.8, 2.54], [2, 7.4, 2]]}, {"timestamp": 1632570727372, "ltp": 4.6, "tv": 2700.85, "trd": NaN, "batb": [[0, 4.7, 103.15], [1, 4.6, 102.18], [2, 4.5, 241.81]], "batl": [[0, 5, 170.95], [1, 5.2, 1.71], [2, 5.3, 88.68]]}, {"timestamp": 1632570729099, "ltp": 4.6, "tv": 2700.85, "trd": NaN, "batb": NaN, "batl": [[0, 5, 181.46], [2, 5.3, 95.91]]}, {"timestamp": 1632570733304, "ltp": 4.6, "tv": 2700.85, "trd": NaN, "batb": NaN, "batl": [[1, 5.1, 87.43], [2, 5.2, 107.26]]}, {"timestamp": 1632570734219, "ltp": 4.6, "tv": 2700.85, "trd": NaN, "batb": [[2, 4.5, 246.09]], "batl": [[2, 5.2, 109.26]]}, {"timestamp": 1632570737112, "ltp": 4.6, "tv": 2700.85, "trd": NaN, "batb": NaN, "batl": [[2, 5.2, 107.55]]}, {"timestamp": 1632570739300, "ltp": 4.6, "tv": 2700.85, "trd": NaN, "batb": [[1, 4.5, 4.28], [2, 4.4, 126.43]], "batl": [[0, 5, 12.51], [2, 5.2, 105.55]]}, {"timestamp": 1632570740305, "ltp": 4.6, "tv": 2700.85, "trd": NaN, "batb": [[0, 4.4, 2.01], [1, 4, 2], [2, 2.62, 386.89]], "batl": NaN}, {"timestamp": 1632570740988, "ltp": 4.6, "tv": 2700.85, "trd": NaN, "batb": NaN, "batl": [[0, 5, 2]]}, {"timestamp": 1632570742325, "ltp": 4.6, "tv": 2700.85, "trd": NaN, "batb": NaN, "batl": [[0, 5, 19.06], [1, 5.1, 94.41]]}, {"timestamp": 1632570743222, "ltp": 4.8, "tv": 2702.57, "trd": [[4.8, 1.71]], "batb": NaN, "batl": [[0, 5, 21.06]]}, {"timestamp": 1632570743922, "ltp": 4.8, "tv": 2702.57, "trd": NaN, "batb": [[0, 4.7, 4.05], [1, 4.5, 2], [2, 4.4, 4.01]], "batl": [[0, 5, 19.06]]}, {"timestamp": 1632570746366, "ltp": 4.8, "tv": 2702.57, "trd": NaN, "batb": [[1, 4.5, 44.07]], "batl": NaN}, {"timestamp": 1632570747164, "ltp": 4.8, "tv": 2702.57, "trd": NaN, "batb": [[1, 4.5, 2]], "batl": NaN}, {"timestamp": 1632570750269, "ltp": 4.8, "tv": 2702.57, "trd": NaN, "batb": [[0, 4.7, 46.12]], "batl": NaN}, {"timestamp": 1632570750727, "ltp": 4.8, "tv": 2702.57, "trd": NaN, "batb": [[0, 4.7, 4.05]], "batl": NaN}, {"timestamp": 1632570752144, "ltp": 4.8, "tv": 2702.57, "trd": NaN, "batb": NaN, "batl": [[1, 5.1, 87.43]]}, {"timestamp": 1632570753029, "ltp": 4.8, "tv": 2702.57, "trd": NaN, "batb": [[2, 4.4, 2]], "batl": NaN}, {"timestamp": 1632570755251, "ltp": 4.8, "tv": 2702.57, "trd": NaN, "batb": [[2, 4.2, 112.19]], "batl": NaN}, {"timestamp": 1632570757066, "ltp": 4.8, "tv": 2702.57, "trd": NaN, "batb": [[0, 4.7, 15.46]], "batl": NaN}, {"timestamp": 1632570758242, "ltp": 4.8, "tv": 2702.57, "trd": NaN, "batb": NaN, "batl": [[0, 5, 25.57]]}, {"timestamp": 1632570758681, "ltp": 4.8, "tv": 2702.57, "trd": NaN, "batb": [[2, 4.4, 3]], "batl": [[0, 5, 19.06]]}, {"timestamp": 1632570759657, "ltp": 4.8, "tv": 2703.84, "trd": [[4.8, 2.98]], "batb": NaN, "batl": NaN}, {"timestamp": 1632570760447, "ltp": 4.8, "tv": 2703.93, "trd": [[4.8, 3.08]], "batb": NaN, "batl": NaN}, {"timestamp": 1632570764752, "ltp": 4.8, "tv": 2703.93, "trd": NaN, "batb": NaN, "batl": [[0, 5, 25.57]]}, {"timestamp": 1632570766040, "ltp": 4.8, "tv": 2709.37, "trd": [[4.8, 8.52]], "batb": NaN, "batl": NaN}, {"timestamp": 1632570774373, "ltp": 4.8, "tv": 2709.37, "trd": NaN, "batb": [[2, 4.2, 112.19]], "batl": NaN}, {"timestamp": 1632570775061, "ltp": 4.8, "tv": 2709.47, "trd": [[4.8, 8.61]], "batb": NaN, "batl": NaN}, {"timestamp": 1632570777585, "ltp": 4.8, "tv": 2709.47, "trd": NaN, "batb": [[2, 4.4, 3]], "batl": NaN}, {"timestamp": 1632570788576, "ltp": 4.8, "tv": 2780.29, "trd": [[4.8, 79.44]], "batb": NaN, "batl": NaN}, {"timestamp": 1632570793479, "ltp": 4.8, "tv": 2780.29, "trd": NaN, "batb": [[1, 4.4, 3], [2, 4.2, 112.19]], "batl": NaN}, {"timestamp": 1632570798837, "ltp": 4.8, "tv": 2782.12, "trd": [[4.8, 81.27]], "batb": NaN, "batl": NaN}, {"timestamp": 1632570810813, "ltp": 4.8, "tv": 2799.94, "trd": [[4.8, 99.09]], "batb": NaN, "batl": NaN}, {"timestamp": 1632570813713, "ltp": 4.8, "tv": 2800.04, "trd": [[4.8, 99.18]], "batb": NaN, "batl": NaN}, {"timestamp": 1632570827345, "ltp": 4.8, "tv": 2800.04, "trd": NaN, "batb": [[0, 4.7, 4.05]], "batl": NaN}, {"timestamp": 1632570830562, "ltp": 4.8, "tv": 2800.05, "trd": [[4.8, 99.2]], "batb": NaN, "batl": NaN}, {"timestamp": 1632570844372, "ltp": 4.8, "tv": 2800.37, "trd": [[4.8, 99.51]], "batb": NaN, "batl": NaN}, {"timestamp": 1632570848372, "ltp": 4.8, "tv": 2800.46, "trd": [[4.8, 99.61]], "batb": NaN, "batl": NaN}, {"timestamp": 1632570865680, "ltp": 4.8, "tv": 2800.46, "trd": NaN, "batb": [[1, 4.2, 112.19], [2, 4.1, 116.14]], "batl": [[0, 5.5, 7.07], [1, 5.7, 92.85], [2, 5.8, 113.04]]}, {"timestamp": 1632570867307, "ltp": 4.8, "tv": 2800.46, "trd": NaN, "batb": [[0, 4.2, 112.19], [1, 4.1, 116.14], [2, 1.9, 5.76]], "batl": [[0, 5.7, 92.85], [1, 5.8, 113.04], [2, 990, 0.01]]}, {"timestamp": 1632570869113, "ltp": 4.8, "tv": 2800.46, "trd": NaN, "batb": NaN, "batl": [[0, 5.5, 2], [1, 5.8, 2.54]]}, {"timestamp": 1632570870715, "ltp": 4.8, "tv": 2800.46, "trd": NaN, "batb": [[0, 4.2, 114.19], [1, 4.1, 119.14]], "batl": [[0, 4.8, 2.34], [1, 5.5, 2], [2, 5.7, 3]]}, {"timestamp": 1632570872319, "ltp": 4.8, "tv": 2800.46, "trd": NaN, "batb": [[0, 4.4, 5.36], [1, 4.3, 222.38], [2, 4.2, 330.03]], "batl": [[0, 4.7, 49.47], [1, 4.8, 8.59], [2, 5, 191.24]]}, {"timestamp": 1632570873299, "ltp": 4.8, "tv": 2800.46, "trd": NaN, "batb": [[0, 4.4, 9.77], [1, 4.3, 243.05]], "batl": NaN}, {"timestamp": 1632570874615, "ltp": 4.8, "tv": 2800.46, "trd": NaN, "batb": [[1, 4.3, 222.38]], "batl": NaN}, {"timestamp": 1632570878322, "ltp": 4.8, "tv": 2800.46, "trd": NaN, "batb": [[0, 4.4, 30.44], [1, 4.3, 349.63]], "batl": NaN}, {"timestamp": 1632570880216, "ltp": 4.8, "tv": 2800.46, "trd": NaN, "batb": [[0, 4.4, 4.41], [1, 4.3, 129.25], [2, 4.2, 4]], "batl": [[0, 4.8, 2.34], [1, 5, 2], [2, 5.1, 97.84]]}, {"timestamp": 1632570881298, "ltp": 4.8, "tv": 2800.46, "trd": NaN, "batb": [[0, 4.3, 129.25], [1, 4.2, 4], [2, 4.1, 3]], "batl": [[0, 5.1, 90.44], [1, 5.2, 115.11], [2, 5.4, 2]]}, {"timestamp": 1632570881983, "ltp": 4.8, "tv": 2800.46, "trd": NaN, "batb": [[0, 4.3, 127.25]], "batl": NaN}, {"timestamp": 1632570883315, "ltp": 4.5, "tv": 2800.47, "trd": [[4.5, 0.01]], "batb": [[2, 4, 129.23]], "batl": [[0, 5.1, 90.53], [1, 5.2, 113.4]]}, {"timestamp": 1632570884322, "ltp": 4.5, "tv": 2800.47, "trd": NaN, "batb": NaN, "batl": [[0, 4.4, 2.42], [1, 5.1, 93.44], [2, 5.2, 113.4]]}, {"timestamp": 1632570884913, "ltp": 4.4, "tv": 2802.89, "trd": [[4.4, 2.42]], "batb": [[0, 4.3, 129.25]], "batl": [[0, 5.1, 93.44], [1, 5.2, 113.4], [2, 5.4, 2]]}, {"timestamp": 1632570885712, "ltp": 4.4, "tv": 2802.89, "trd": NaN, "batb": [[0, 4.4, 18.51], [1, 4.3, 129.25], [2, 4.2, 4]], "batl": [[0, 5, 16], [1, 5.1, 93.44], [2, 5.2, 113.4]]}, {"timestamp": 1632570887310, "ltp": 4.4, "tv": 2802.89, "trd": NaN, "batb": NaN, "batl": [[0, 5, 2]]}, {"timestamp": 1632570887526, "ltp": 4.4, "tv": 2802.89, "trd": NaN, "batb": NaN, "batl": [[0, 5, 4]]}, {"timestamp": 1632570890824, "ltp": 4.4, "tv": 2802.89, "trd": NaN, "batb": [[0, 4.3, 129.25], [1, 4.2, 4], [2, 4, 129.23]], "batl": [[0, 5, 2]]}, {"timestamp": 1632570891818, "ltp": 4.4, "tv": 2802.89, "trd": NaN, "batb": [[0, 4.3, 127.25]], "batl": NaN}, {"timestamp": 1632570895131, "ltp": 4.4, "tv": 2802.89, "trd": NaN, "batb": [[0, 4.3, 129.25]], "batl": NaN}, {"timestamp": 1632570896112, "ltp": 4.4, "tv": 2802.89, "trd": NaN, "batb": NaN, "batl": [[1, 5.4, 2], [2, 5.8, 2.54]]}, {"timestamp": 1632570898164, "ltp": 4.4, "tv": 2802.89, "trd": NaN, "batb": [[1, 4.2, 2]], "batl": [[0, 5, 4]]}, {"timestamp": 1632570899125, "ltp": 4.4, "tv": 2802.89, "trd": NaN, "batb": [[2, 4, 174.49]], "batl": [[0, 4.4, 256.88], [1, 4.5, 104.44], [2, 4.6, 58.74]]}, {"timestamp": 1632570900229, "ltp": 4.4, "tv": 2802.89, "trd": NaN, "batb": [[1, 4.2, 143.91]], "batl": NaN}, {"timestamp": 1632570902933, "ltp": 4.4, "tv": 2802.89, "trd": NaN, "batb": [[0, 4.3, 127.25]], "batl": NaN}, {"timestamp": 1632570904373, "ltp": 4.4, "tv": 2911.41, "trd": [[4.4, 110.94]], "batb": NaN, "batl": [[0, 4.4, 148.36]]}, {"timestamp": 1632570905302, "ltp": 4.4, "tv": 2911.52, "trd": [[4.4, 111.05]], "batb": NaN, "batl": [[0, 4.4, 148.25]]}, {"timestamp": 1632570906161, "ltp": 4.4, "tv": 2911.52, "trd": NaN, "batb": [[2, 4.1, 2]], "batl": NaN}, {"timestamp": 1632570912364, "ltp": 4.4, "tv": 2911.52, "trd": NaN, "batb": NaN, "batl": [[0, 4.4, 152.02]]}, {"timestamp": 1632570913367, "ltp": 4.4, "tv": 2911.52, "trd": NaN, "batb": NaN, "batl": [[0, 4.7, 114.03], [1, 4.8, 106.9], [2, 4.9, 5]]}, {"timestamp": 1632570914304, "ltp": 4.4, "tv": 2911.52, "trd": NaN, "batb": [[0, 4.2, 143.91], [1, 4.1, 2], [2, 3.9, 116.17]], "batl": NaN}, {"timestamp": 1632570915292, "ltp": 4.4, "tv": 2911.52, "trd": NaN, "batb": [[0, 4.2, 139.23]], "batl": NaN}, {"timestamp": 1632570917049, "ltp": 4.4, "tv": 2911.52, "trd": NaN, "batb": NaN, "batl": [[0, 4.6, 3], [1, 4.7, 114.03], [2, 4.8, 106.9]]}, {"timestamp": 1632570918197, "ltp": 4.4, "tv": 2911.52, "trd": NaN, "batb": [[0, 4.2, 142.23], [1, 4.1, 5]], "batl": [[0, 4.7, 116.03], [1, 4.8, 106.9], [2, 4.9, 5]]}, {"timestamp": 1632570919664, "ltp": 4.4, "tv": 2911.52, "trd": NaN, "batb": [[0, 4.2, 140.23], [2, 1.9, 5.78]], "batl": NaN}, {"timestamp": 1632570922285, "ltp": 4.4, "tv": 2911.52, "trd": NaN, "batb": [[0, 4.5, 522.22], [1, 4.4, 261.12], [2, 4.3, 261.12]], "batl": [[1, 4.8, 159.7]]}, {"timestamp": 1632570923275, "ltp": 4.4, "tv": 2911.52, "trd": NaN, "batb": [[0, 4.7, 106.28], [1, 4.5, 104.44], [2, 4.4, 176.4]], "batl": [[0, 4.8, 157.7], [1, 4.9, 11.12], [2, 5.1, 460.78]]}, {"timestamp": 1632570924291, "ltp": 4.4, "tv": 2911.52, "trd": NaN, "batb": [[1, 4.5, 108.72]], "batl": [[2, 5.1, 92.16]]}, {"timestamp": 1632570925868, "ltp": 4.7, "tv": 2933.04, "trd": [[4.7, 21.51]], "batb": [[0, 4.7, 95.52]], "batl": NaN}, {"timestamp": 1632570927364, "ltp": 4.7, "tv": 2933.04, "trd": NaN, "batb": NaN, "batl": [[0, 4.8, 195.28]]}, {"timestamp": 1632570927687, "ltp": 4.7, "tv": 2933.04, "trd": NaN, "batb": NaN, "batl": [[0, 4.8, 157.7]]}, {"timestamp": 1632570930383, "ltp": 4.8, "tv": 2961.25, "trd": [[4.8, 127.82]], "batb": NaN, "batl": [[0, 4.8, 143.59]]}, {"timestamp": 1632570932884, "ltp": 4.7, "tv": 2965.25, "trd": [[4.7, 25.51]], "batb": [[0, 4.7, 93.52]], "batl": NaN}, {"timestamp": 1632570934111, "ltp": 4.7, "tv": 2965.25, "trd": NaN, "batb": [[1, 4.5, 121.58]], "batl": NaN}, {"timestamp": 1632570935188, "ltp": 4.7, "tv": 2965.64, "trd": [[4.7, 25.9]], "batb": [[0, 4.7, 93.33]], "batl": NaN}, {"timestamp": 1632570941326, "ltp": 4.7, "tv": 2980.67, "trd": [[4.7, 40.93]], "batb": [[0, 4.7, 85.81], [1, 4.5, 69.36], [2, 4.4, 150.29]], "batl": [[0, 4.8, 52.8], [1, 4.9, 5], [2, 5.1, 46.08]]}, {"timestamp": 1632570942133, "ltp": 4.7, "tv": 2980.67, "trd": NaN, "batb": [[0, 4.5, 17.14], [1, 4.4, 121.92], [2, 4.3, 2]], "batl": [[0, 5.3, 85.01], [1, 5.4, 125.97], [2, 5.8, 2.54]]}, {"timestamp": 1632570943200, "ltp": 4.7, "tv": 2980.67, "trd": NaN, "batb": [[0, 4.4, 121.92], [1, 4.3, 2], [2, 4.2, 5]], "batl": NaN}, {"timestamp": 1632570943834, "ltp": 4.7, "tv": 2980.67, "trd": NaN, "batb": NaN, "batl": [[0, 5.4, 2], [1, 5.8, 2.54], [2, 6, 108.31]]}, {"timestamp": 1632570945320, "ltp": 4.7, "tv": 2980.67, "trd": NaN, "batb": NaN, "batl": [[0, 5.2, 2], [1, 5.3, 2], [2, 5.4, 2]]}, {"timestamp": 1632570945597, "ltp": 4.7, "tv": 2980.67, "trd": NaN, "batb": [[2, 4.2, 2]], "batl": [[0, 5.3, 2], [1, 5.4, 2], [2, 5.8, 2.54]]}, {"timestamp": 1632570947136, "ltp": 4.8, "tv": 2980.71, "trd": [[4.8, 127.86]], "batb": NaN, "batl": [[0, 4.6, 6.52], [1, 4.7, 101.71], [2, 4.8, 192.71]]}, {"timestamp": 1632570948307, "ltp": 4.8, "tv": 2980.71, "trd": NaN, "batb": [[2, 4.2, 265.73]], "batl": NaN}, {"timestamp": 1632570950166, "ltp": 4.8, "tv": 2980.71, "trd": NaN, "batb": [[1, 4.3, 3.95]], "batl": NaN}, {"timestamp": 1632570953924, "ltp": 4.8, "tv": 2980.71, "trd": NaN, "batb": [[1, 4.3, 5.95]], "batl": [[2, 4.8, 277.4]]}, {"timestamp": 1632570957753, "ltp": 4.8, "tv": 2980.71, "trd": NaN, "batb": NaN, "batl": [[1, 4.7, 100]]}, {"timestamp": 1632570959345, "ltp": 4.8, "tv": 2980.71, "trd": NaN, "batb": [[1, 4.3, 2], [2, 4.2, 153.83]], "batl": [[0, 4.8, 84.69], [1, 4.9, 99.23], [2, 5, 7.5]]}, {"timestamp": 1632570959718, "ltp": 4.8, "tv": 2980.71, "trd": NaN, "batb": [[0, 4.3, 2], [1, 4.2, 153.83], [2, 4.1, 2]], "batl": [[0, 4.8, 82.69]]}, {"timestamp": 1632570961263, "ltp": 4.8, "tv": 2980.71, "trd": NaN, "batb": [[0, 4.2, 135.08], [1, 4.1, 2], [2, 4, 101.89]], "batl": [[2, 5.4, 2]]}, {"timestamp": 1632570964321, "ltp": 4.8, "tv": 2980.71, "trd": NaN, "batb": [[0, 4.2, 138.08], [1, 4.1, 3]], "batl": [[0, 4.9, 5], [1, 5.8, 2.54], [2, 6, 108.31]]}, {"timestamp": 1632570966341, "ltp": 4.8, "tv": 2980.71, "trd": NaN, "batb": [[0, 4.2, 142.96]], "batl": [[0, 4.4, 6.98], [1, 4.5, 6.67], [2, 4.7, 813.84]]}, {"timestamp": 1632570967333, "ltp": 4.8, "tv": 2980.71, "trd": NaN, "batb": [[0, 4.3, 2], [1, 4.2, 139.96]], "batl": [[2, 4.7, 203.46]]}, {"timestamp": 1632570968236, "ltp": 4.8, "tv": 2980.71, "trd": NaN, "batb": [[0, 4.2, 139.96], [1, 4.1, 19.35]], "batl": NaN}, {"timestamp": 1632570969459, "ltp": 4.8, "tv": 2980.71, "trd": NaN, "batb": [[2, 4, 104.89]], "batl": NaN}, {"timestamp": 1632570971249, "ltp": 4.8, "tv": 2980.71, "trd": NaN, "batb": NaN, "batl": [[1, 4.5, 60.73]]}, {"timestamp": 1632570972367, "ltp": 4.8, "tv": 2980.71, "trd": NaN, "batb": NaN, "batl": [[1, 4.5, 6.67]]}, {"timestamp": 1632570973596, "ltp": 4.8, "tv": 2980.71, "trd": NaN, "batb": NaN, "batl": [[2, 4.7, 317.53]]}, {"timestamp": 1632570983651, "ltp": 4.4, "tv": 2982.19, "trd": [[4.4, 112.53]], "batb": NaN, "batl": [[0, 4.4, 5.5]]}, {"timestamp": 1632570993693, "ltp": 4.4, "tv": 2982.19, "trd": NaN, "batb": [[0, 4.2, 135.08]], "batl": [[0, 4.5, 6.67], [1, 4.7, 317.53], [2, 4.8, 344.72]]}, {"timestamp": 1632570996566, "ltp": 4.4, "tv": 2982.19, "trd": NaN, "batb": NaN, "batl": [[0, 4.4, 5.5], [1, 4.5, 6.67], [2, 4.7, 317.53]]}, {"timestamp": 1632571004704, "ltp": 4.4, "tv": 2984.65, "trd": [[4.4, 114.99]], "batb": NaN, "batl": [[0, 4.4, 4.27]]}, {"timestamp": 1632571008308, "ltp": 4.4, "tv": 2984.65, "trd": NaN, "batb": [[0, 4.2, 133.08], [2, 3.8, 87.95]], "batl": [[0, 4.7, 114.07], [1, 4.8, 122.24], [2, 4.9, 5]]}, {"timestamp": 1632571009312, "ltp": 4.4, "tv": 2984.65, "trd": NaN, "batb": [[0, 3.8, 87.95], [1, 3.65, 104.67], [2, 3.6, 129]], "batl": [[1, 4.8, 114.55]]}, {"timestamp": 1632571011211, "ltp": 4.4, "tv": 2984.65, "trd": NaN, "batb": [[0, 3.85, 2.02], [1, 3.8, 87.93], [2, 3.7, 2]], "batl": [[0, 4.6, 2], [1, 4.7, 114.07], [2, 4.8, 116.55]]}, {"timestamp": 1632571011488, "ltp": 4.4, "tv": 2984.65, "trd": NaN, "batb": NaN, "batl": [[0, 4.7, 114.07], [1, 4.8, 116.55], [2, 4.9, 3]]}, {"timestamp": 1632571016820, "ltp": 4.4, "tv": 2984.65, "trd": NaN, "batb": [[0, 3.8, 87.95], [1, 3.7, 2], [2, 1.9, 5.76]], "batl": NaN}, {"timestamp": 1632571018308, "ltp": 4.4, "tv": 2984.65, "trd": NaN, "batb": [[0, 4.4, 2.26], [1, 4.2, 189.01], [2, 3.8, 87.95]], "batl": [[0, 4.7, 78.17]]}, {"timestamp": 1632571019320, "ltp": 4.4, "tv": 2984.65, "trd": NaN, "batb": [[0, 4.5, 117.61], [1, 4.4, 2.26], [2, 4.2, 207.76]], "batl": [[0, 4.7, 81.55], [2, 4.9, 4.71]]}, {"timestamp": 1632571020911, "ltp": 4.4, "tv": 2984.65, "trd": NaN, "batb": [[0, 4.5, 124.27]], "batl": [[0, 4.7, 85.16]]}, {"timestamp": 1632571023461, "ltp": 4.4, "tv": 2984.65, "trd": NaN, "batb": [[2, 4.2, 189.01]], "batl": NaN}, {"timestamp": 1632571025121, "ltp": 4.4, "tv": 2984.65, "trd": NaN, "batb": [[2, 4.2, 191.01]], "batl": [[2, 4.9, 6.71]]}, {"timestamp": 1632571026655, "ltp": 4.4, "tv": 2984.65, "trd": NaN, "batb": [[2, 4.3, 18.18]], "batl": NaN}, {"timestamp": 1632571028318, "ltp": 4.4, "tv": 2984.65, "trd": NaN, "batb": [[0, 4.5, 117.61], [1, 4.3, 18.18], [2, 4.2, 2]], "batl": [[0, 4.9, 3.71], [1, 5, 96.96], [2, 5.1, 107.23]]}, {"timestamp": 1632571029223, "ltp": 4.4, "tv": 2984.65, "trd": NaN, "batb": [[0, 4.2, 2], [1, 4, 285.63], [2, 3.95, 128.16]], "batl": [[0, 5, 96.96], [1, 5.1, 107.23], [2, 5.8, 2.54]]}, {"timestamp": 1632571030340, "ltp": 4.4, "tv": 2984.65, "trd": NaN, "batb": [[1, 4, 154.04], [2, 3.9, 3]], "batl": NaN}, {"timestamp": 1632571031324, "ltp": 4.4, "tv": 2984.65, "trd": NaN, "batb": NaN, "batl": [[1, 5.1, 114.63]]}, {"timestamp": 1632571032332, "ltp": 4.4, "tv": 2984.65, "trd": NaN, "batb": NaN, "batl": [[0, 4.9, 2], [1, 5, 99.96], [2, 5.1, 107.23]]}, {"timestamp": 1632571033336, "ltp": 4.4, "tv": 2984.65, "trd": NaN, "batb": [[0, 4.8, 4.02], [1, 4.6, 102.18], [2, 4.5, 53.18]], "batl": [[0, 5, 104.82], [1, 5.1, 107.23], [2, 5.8, 2.54]]}, {"timestamp": 1632571034240, "ltp": 4.4, "tv": 2984.65, "trd": NaN, "batb": [[1, 4.6, 211.42]], "batl": [[0, 5, 110.82], [2, 5.3, 443.4]]}, {"timestamp": 1632571035224, "ltp": 4.4, "tv": 2984.65, "trd": NaN, "batb": NaN, "batl": [[0, 5, 124.54], [2, 5.3, 95.91]]}, {"timestamp": 1632571038179, "ltp": 4.4, "tv": 2984.65, "trd": NaN, "batb": NaN, "batl": [[0, 4.9, 40.04], [1, 5, 124.54], [2, 5.1, 107.23]]}, {"timestamp": 1632571039361, "ltp": 4.4, "tv": 2984.65, "trd": NaN, "batb": NaN, "batl": [[0, 5, 124.54], [1, 5.1, 107.23], [2, 5.3, 95.91]]}, {"timestamp": 1632571040846, "ltp": 4.4, "tv": 2984.65, "trd": NaN, "batb": NaN, "batl": [[2, 5.2, 89.62]]}, {"timestamp": 1632571041953, "ltp": 4.4, "tv": 2984.65, "trd": NaN, "batb": [[2, 4.5, 70.32]], "batl": NaN}, {"timestamp": 1632571048368, "ltp": 4.4, "tv": 2984.65, "trd": NaN, "batb": [[0, 4.6, 109.24], [1, 4.5, 17.14], [2, 4.4, 2]], "batl": [[0, 5, 5], [1, 5.2, 89.62], [2, 5.3, 98.02]]}, {"timestamp": 1632571049288, "ltp": 4.4, "tv": 2984.65, "trd": NaN, "batb": [[0, 4.4, 2], [1, 4.3, 131.31], [2, 4.2, 125.64]], "batl": [[0, 5.2, 89.62], [1, 5.3, 90.79], [2, 5.8, 2.54]]}, {"timestamp": 1632571052150, "ltp": 4.4, "tv": 2984.65, "trd": NaN, "batb": [[1, 4.2, 257.2], [2, 4.1, 118.06]], "batl": [[0, 5.2, 92.62]]}, {"timestamp": 1632571055303, "ltp": 4.4, "tv": 2984.65, "trd": NaN, "batb": [[0, 4.5, 2], [1, 4.4, 2], [2, 4.2, 257.2]], "batl": [[0, 5, 2], [1, 5.2, 92.62], [2, 5.3, 90.79]]}, {"timestamp": 1632571058176, "ltp": 4.4, "tv": 2984.65, "trd": NaN, "batb": [[0, 4.4, 2], [1, 4.2, 257.2], [2, 4.1, 118.06]], "batl": [[0, 5.2, 92.62], [1, 5.3, 90.79], [2, 5.8, 2.54]]}, {"timestamp": 1632571060188, "ltp": 4.4, "tv": 2984.65, "trd": NaN, "batb": [[1, 4.2, 136.56], [2, 4, 2.02]], "batl": NaN}, {"timestamp": 1632571061372, "ltp": 4.4, "tv": 2984.65, "trd": NaN, "batb": [[0, 4.5, 2], [1, 4.4, 4], [2, 4.3, 2]], "batl": [[0, 5, 2], [1, 5.2, 92.62], [2, 5.3, 90.79]]}, {"timestamp": 1632571061708, "ltp": 4.4, "tv": 2984.65, "trd": NaN, "batb": [[0, 4.4, 4], [1, 4.3, 2], [2, 4.2, 134.56]], "batl": [[0, 5.2, 92.62], [1, 5.3, 90.79], [2, 5.8, 2.54]]}, {"timestamp": 1632571063187, "ltp": 4.4, "tv": 2984.65, "trd": NaN, "batb": [[0, 4.8, 97.92], [1, 4.7, 223.69], [2, 4.6, 48.96]], "batl": [[0, 5.1, 45.81], [1, 5.2, 92.62], [2, 5.3, 90.79]]}, {"timestamp": 1632571064318, "ltp": 5.0, "tv": 2986.38, "trd": [[5, 1.73]], "batb": [[0, 4.8, 198.7], [2, 4.6, 65.62]], "batl": [[0, 5.1, 63.36]]}, {"timestamp": 1632571068306, "ltp": 5.0, "tv": 2986.38, "trd": NaN, "batb": [[2, 4.6, 48.96]], "batl": NaN}, {"timestamp": 1632571070218, "ltp": 5.0, "tv": 2986.38, "trd": NaN, "batb": NaN, "batl": [[2, 5.3, 166.44]]}, {"timestamp": 1632571071371, "ltp": 5.0, "tv": 2986.38, "trd": NaN, "batb": [[1, 4.7, 239.9]], "batl": NaN}, {"timestamp": 1632571078451, "ltp": 5.0, "tv": 2986.38, "trd": NaN, "batb": NaN, "batl": [[0, 5, 4.95], [1, 5.1, 63.36], [2, 5.2, 92.62]]}, {"timestamp": 1632571081691, "ltp": 5.0, "tv": 2986.38, "trd": NaN, "batb": NaN, "batl": [[0, 5, 6.95]]}, {"timestamp": 1632571088086, "ltp": 5.0, "tv": 2986.38, "trd": NaN, "batb": [[0, 4.7, 18.23], [1, 4.5, 12], [2, 4.4, 4]], "batl": [[0, 5, 4.95], [1, 5.1, 11.67], [2, 5.2, 2]]}, {"timestamp": 1632571089265, "ltp": 5.0, "tv": 2986.38, "trd": NaN, "batb": [[0, 4.7, 2.02], [1, 4.5, 2]], "batl": NaN}, {"timestamp": 1632571090276, "ltp": 5.0, "tv": 2993.2, "trd": [[5, 8.55]], "batb": NaN, "batl": [[0, 5, 1.54]]}, {"timestamp": 1632571090594, "ltp": 5.0, "tv": 2993.2, "trd": NaN, "batb": [[0, 4.5, 2], [1, 4.4, 4], [2, 1.9, 5.78]], "batl": NaN}, {"timestamp": 1632571092298, "ltp": 5.0, "tv": 2993.2, "trd": NaN, "batb": [[0, 4.7, 14.42], [1, 4.5, 2], [2, 4.4, 4]], "batl": NaN}, {"timestamp": 1632571093370, "ltp": 5.0, "tv": 2993.2, "trd": NaN, "batb": [[0, 4.8, 15.78]], "batl": NaN}, {"timestamp": 1632571095288, "ltp": 5.0, "tv": 2993.2, "trd": NaN, "batb": NaN, "batl": [[1, 5.1, 45.75]]}, {"timestamp": 1632571095769, "ltp": 5.0, "tv": 2993.2, "trd": NaN, "batb": [[1, 4.6, 14.42], [2, 4.5, 2]], "batl": [[1, 5.1, 11.67]]}, {"timestamp": 1632571097378, "ltp": 5.0, "tv": 2993.2, "trd": NaN, "batb": [[2, 4.5, 4.56]], "batl": NaN}, {"timestamp": 1632571097591, "ltp": 5.0, "tv": 2993.2, "trd": NaN, "batb": [[2, 4.5, 2]], "batl": NaN}, {"timestamp": 1632571103711, "ltp": 5.0, "tv": 2993.2, "trd": NaN, "batb": NaN, "batl": [[1, 5.1, 15.68]]}, {"timestamp": 1632571105795, "ltp": 5.0, "tv": 2993.2, "trd": NaN, "batb": NaN, "batl": [[0, 5.1, 4.01], [1, 5.2, 2], [2, 5.3, 75.66]]}, {"timestamp": 1632571108983, "ltp": 5.0, "tv": 2993.2, "trd": NaN, "batb": [[0, 4.6, 14.42], [1, 4.5, 2], [2, 4.4, 4]], "batl": [[0, 4.9, 1.54], [1, 5.1, 4.01], [2, 5.2, 2]]}, {"timestamp": 1632571112331, "ltp": 5.0, "tv": 2993.2, "trd": NaN, "batb": [[0, 4.7, 16.21]], "batl": [[0, 5.2, 2], [1, 5.4, 2], [2, 5.7, 90.72]]}, {"timestamp": 1632571113319, "ltp": 5.0, "tv": 2993.2, "trd": NaN, "batb": [[0, 4.5, 2], [1, 4.4, 4], [2, 4.2, 94.75]], "batl": [[0, 5.7, 83.81], [1, 5.8, 101.95], [2, 6.4, 2]]}, {"timestamp": 1632571113808, "ltp": 5.0, "tv": 2993.2, "trd": NaN, "batb": [[0, 4.4, 4], [1, 4.2, 94.75], [2, 4.1, 131.13]], "batl": NaN}, {"timestamp": 1632571116000, "ltp": 5.0, "tv": 2993.2, "trd": NaN, "batb": NaN, "batl": [[0, 4.8, 1.54], [1, 5.7, 83.81], [2, 5.8, 101.95]]}, {"timestamp": 1632571117021, "ltp": 5.0, "tv": 2993.2, "trd": NaN, "batb": [[0, 4.5, 5], [1, 4.4, 4], [2, 4.3, 3]], "batl": NaN}, {"timestamp": 1632571121180, "ltp": 5.0, "tv": 2993.2, "trd": NaN, "batb": NaN, "batl": [[1, 5.8, 2.54], [2, 6.4, 2]]}, {"timestamp": 1632571122798, "ltp": 5.0, "tv": 2993.2, "trd": NaN, "batb": [[0, 4.5, 2], [1, 4.4, 2], [2, 4.2, 94.75]], "batl": NaN}, {"timestamp": 1632571124348, "ltp": 5.0, "tv": 2993.2, "trd": NaN, "batb": [[0, 4.5, 8.39], [2, 4.3, 222.38]], "batl": [[0, 4.7, 3.57], [1, 4.8, 1.54], [2, 4.9, 6.12]]}, {"timestamp": 1632571125302, "ltp": 5.0, "tv": 2993.2, "trd": NaN, "batb": [[0, 4.5, 25.53]], "batl": NaN}, {"timestamp": 1632571127130, "ltp": 4.7, "tv": 2997.2, "trd": [[4.7, 44.93]], "batb": NaN, "batl": [[0, 4.7, 1.57]]}, {"timestamp": 1632571128138, "ltp": 4.7, "tv": 2997.2, "trd": NaN, "batb": [[0, 4.5, 23.53]], "batl": NaN}, {"timestamp": 1632571131151, "ltp": 4.7, "tv": 2997.2, "trd": NaN, "batb": [[2, 4.3, 349.6]], "batl": NaN}, {"timestamp": 1632571133916, "ltp": 4.7, "tv": 2997.2, "trd": NaN, "batb": NaN, "batl": [[1, 4.9, 6.12], [2, 5.1, 1.71]]}, {"timestamp": 1632571136120, "ltp": 4.7, "tv": 2997.2, "trd": NaN, "batb": NaN, "batl": [[2, 5.2, 2]]}, {"timestamp": 1632571137284, "ltp": 4.5, "tv": 3000.28, "trd": [[4.5, 3.09]], "batb": [[0, 4.5, 17.14]], "batl": [[0, 4.9, 6.12], [1, 5.2, 2], [2, 5.3, 84]]}, {"timestamp": 1632571140238, "ltp": 4.5, "tv": 3000.28, "trd": NaN, "batb": [[0, 4.5, 24.08]], "batl": [[0, 4.8, 7.65], [1, 4.9, 6.12], [2, 5.2, 2]]}, {"timestamp": 1632571141305, "ltp": 4.5, "tv": 3000.28, "trd": NaN, "batb": [[0, 4.5, 17.14], [2, 4.3, 127.22]], "batl": [[0, 5.2, 2], [1, 5.3, 84], [2, 5.4, 111.85]]}, {"timestamp": 1632571142294, "ltp": 4.5, "tv": 3000.28, "trd": NaN, "batb": [[0, 4.4, 2], [1, 4.3, 127.22], [2, 4.1, 102.23]], "batl": [[2, 5.4, 104.7]]}, {"timestamp": 1632571142907, "ltp": 4.5, "tv": 3000.28, "trd": NaN, "batb": [[0, 4.3, 127.22], [1, 4.1, 102.23], [2, 4, 145.69]], "batl": NaN}, {"timestamp": 1632571144089, "ltp": 4.5, "tv": 3000.28, "trd": NaN, "batb": NaN, "batl": [[0, 5.3, 84], [1, 5.4, 104.7], [2, 5.6, 2]]}, {"timestamp": 1632571145119, "ltp": 4.5, "tv": 3000.28, "trd": NaN, "batb": NaN, "batl": [[0, 5.6, 2], [1, 5.8, 2.54], [2, 6, 5]]}, {"timestamp": 1632571146192, "ltp": 4.5, "tv": 3000.28, "trd": NaN, "batb": [[0, 4.4, 2], [1, 4.3, 130.22], [2, 4.2, 3]], "batl": NaN}, {"timestamp": 1632571147205, "ltp": 4.5, "tv": 3000.28, "trd": NaN, "batb": [[0, 4.3, 130.22], [1, 4.2, 3], [2, 4.1, 102.23]], "batl": [[0, 5.2, 4], [1, 5.6, 2], [2, 5.8, 2.54]]}, {"timestamp": 1632571148084, "ltp": 4.5, "tv": 3000.28, "trd": NaN, "batb": [[0, 4.3, 127.22], [1, 4.1, 150.85], [2, 4, 145.69]], "batl": [[0, 4.6, 57.61], [1, 4.7, 25.54], [2, 4.8, 25.54]]}, {"timestamp": 1632571149213, "ltp": 4.5, "tv": 3000.28, "trd": NaN, "batb": [[0, 4.3, 157.35], [1, 4.2, 135.11], [2, 4.1, 150.85]], "batl": NaN}, {"timestamp": 1632571151291, "ltp": 4.5, "tv": 3000.28, "trd": NaN, "batb": [[0, 4.3, 161.44]], "batl": NaN}, {"timestamp": 1632571155197, "ltp": 4.5, "tv": 3000.28, "trd": NaN, "batb": [[1, 4.2, 137.11], [2, 4.1, 152.85]], "batl": [[2, 4.8, 118.47]]}, {"timestamp": 1632571155897, "ltp": 4.3, "tv": 3019.07, "trd": [[4.3, 20.69]], "batb": [[0, 4.3, 152.05]], "batl": NaN}, {"timestamp": 1632571160232, "ltp": 4.3, "tv": 3019.07, "trd": NaN, "batb": [[0, 4.3, 134.01], [2, 4.1, 2]], "batl": [[0, 4.8, 92.93], [1, 4.9, 125.22], [2, 5.1, 7.4]]}, {"timestamp": 1632571161308, "ltp": 4.3, "tv": 3019.07, "trd": NaN, "batb": [[0, 4.2, 137.11], [1, 4.1, 2], [2, 3.95, 112.9]], "batl": [[0, 4.8, 90.93], [2, 5.2, 2]]}, {"timestamp": 1632571163316, "ltp": 4.3, "tv": 3019.07, "trd": NaN, "batb": NaN, "batl": [[0, 4.9, 2], [1, 5.2, 2], [2, 5.6, 2]]}, {"timestamp": 1632571166244, "ltp": 4.3, "tv": 3019.07, "trd": NaN, "batb": NaN, "batl": [[0, 4.3, 5.97], [1, 4.4, 275.54], [2, 4.5, 60.07]]}, {"timestamp": 1632571167330, "ltp": 4.3, "tv": 3019.07, "trd": NaN, "batb": [[1, 4.1, 167.54], [2, 3.95, 231.88]], "batl": NaN}, {"timestamp": 1632571169311, "ltp": 4.3, "tv": 3019.07, "trd": NaN, "batb": [[0, 4.2, 135.11], [2, 4, 3.02]], "batl": NaN}, {"timestamp": 1632571173222, "ltp": 4.3, "tv": 3019.07, "trd": NaN, "batb": NaN, "batl": [[2, 4.5, 158.58]]}, {"timestamp": 1632571177140, "ltp": 4.3, "tv": 3019.07, "trd": NaN, "batb": [[0, 4.2, 137.11]], "batl": NaN}, {"timestamp": 1632571179225, "ltp": 4.2, "tv": 3023.18, "trd": [[4.2, 24.19]], "batb": [[0, 4.2, 135.06]], "batl": NaN}, {"timestamp": 1632571182257, "ltp": 4.2, "tv": 3023.18, "trd": NaN, "batb": [[2, 4, 3]], "batl": NaN}, {"timestamp": 1632571183287, "ltp": 4.2, "tv": 3023.18, "trd": NaN, "batb": [[0, 4.2, 2]], "batl": [[0, 4.5, 98.51], [1, 4.6, 123.21], [2, 4.8, 2]]}, {"timestamp": 1632571184330, "ltp": 4.2, "tv": 3023.18, "trd": NaN, "batb": [[0, 4.1, 148.19], [1, 4, 3], [2, 3.9, 100.52]], "batl": NaN}, {"timestamp": 1632571186129, "ltp": 4.2, "tv": 3023.18, "trd": NaN, "batb": [[0, 4.1, 148.21], [2, 3.95, 2]], "batl": NaN}, {"timestamp": 1632571190349, "ltp": 4.2, "tv": 3023.18, "trd": NaN, "batb": NaN, "batl": [[0, 4.3, 18.45], [1, 4.5, 98.51], [2, 4.6, 123.21]]}, {"timestamp": 1632571191261, "ltp": 4.2, "tv": 3023.18, "trd": NaN, "batb": [[0, 4.2, 15.45], [1, 4.1, 148.19], [2, 4, 3]], "batl": [[0, 4.5, 98.51], [1, 4.6, 123.21], [2, 4.8, 2]]}, {"timestamp": 1632571195735, "ltp": 4.2, "tv": 3023.18, "trd": NaN, "batb": [[0, 4.2, 2.02]], "batl": NaN}, {"timestamp": 1632571197931, "ltp": 4.2, "tv": 3023.18, "trd": NaN, "batb": [[0, 4.1, 148.21], [1, 4, 3], [2, 3.9, 100.52]], "batl": NaN}, {"timestamp": 1632571201315, "ltp": 4.2, "tv": 3023.18, "trd": NaN, "batb": [[0, 4.2, 2.02], [1, 4.1, 148.19], [2, 4, 3]], "batl": NaN}, {"timestamp": 1632571201633, "ltp": 4.2, "tv": 3023.18, "trd": NaN, "batb": [[0, 4.1, 148.21], [1, 4, 3], [2, 3.9, 100.52]], "batl": NaN}, {"timestamp": 1632571203125, "ltp": 4.2, "tv": 3023.72, "trd": [[4.2, 24.73]], "batb": [[0, 4.1, 2]], "batl": [[0, 4.8, 2], [1, 5.2, 2], [2, 5.8, 2.54]]}, {"timestamp": 1632571205331, "ltp": 4.2, "tv": 3032.21, "trd": [[4.2, 33.22]], "batb": [[1, 4, 956.26], [2, 3.95, 928.12]], "batl": [[0, 4.4, 6.82], [1, 4.8, 2], [2, 5.2, 2]]}, {"timestamp": 1632571206370, "ltp": 4.2, "tv": 3032.21, "trd": NaN, "batb": [[0, 4.1, 5], [1, 4, 408.12], [2, 3.95, 232.02]], "batl": [[1, 4.8, 11.4]]}, {"timestamp": 1632571206658, "ltp": 4.2, "tv": 3032.21, "trd": NaN, "batb": [[0, 4.1, 12]], "batl": [[1, 4.7, 10], [2, 4.8, 11.4]]}, {"timestamp": 1632571207659, "ltp": 4.2, "tv": 3032.21, "trd": NaN, "batb": NaN, "batl": [[1, 4.7, 12]]}, {"timestamp": 1632571212384, "ltp": 4.2, "tv": 3032.21, "trd": NaN, "batb": NaN, "batl": [[1, 4.6, 111.78], [2, 4.7, 139.35]]}, {"timestamp": 1632571215288, "ltp": 4.3, "tv": 3041.61, "trd": [[4.3, 30.08]], "batb": NaN, "batl": NaN}, {"timestamp": 1632571217081, "ltp": 4.1, "tv": 3043.55, "trd": [[4.1, 115.77]], "batb": [[0, 4.1, 11.03]], "batl": NaN}, {"timestamp": 1632571218293, "ltp": 4.1, "tv": 3043.55, "trd": NaN, "batb": NaN, "batl": [[0, 4.3, 6.05], [1, 4.4, 6.82], [2, 4.6, 111.78]]}, {"timestamp": 1632571276399, "ltp": 4.3, "tv": 3044.17, "trd": [[4.3, 30.71]], "batb": NaN, "batl": [[0, 4.3, 5.74]]}, {"timestamp": 1632571286542, "ltp": 4.3, "tv": 3044.17, "trd": NaN, "batb": NaN, "batl": [[0, 4.4, 6.82], [1, 4.6, 111.78], [2, 4.7, 139.35]]}, {"timestamp": 1632571289601, "ltp": 4.3, "tv": 3044.17, "trd": NaN, "batb": NaN, "batl": [[0, 4.3, 5.74], [1, 4.4, 6.82], [2, 4.6, 111.78]]}, {"timestamp": 1632571291267, "ltp": 4.3, "tv": 3044.17, "trd": NaN, "batb": [[0, 4, 169.06], [1, 3.6, 98.16], [2, 3.55, 141.87]], "batl": [[0, 4.6, 111.78], [1, 4.7, 129.35], [2, 4.8, 9.69]]}, {"timestamp": 1632571292307, "ltp": 4.3, "tv": 3044.17, "trd": NaN, "batb": [[0, 3.6, 98.16], [1, 3.55, 141.87], [2, 3.5, 131.83]], "batl": [[2, 4.8, 2]]}, {"timestamp": 1632571294205, "ltp": 4.3, "tv": 3044.17, "trd": NaN, "batb": [[0, 3.7, 2], [1, 3.6, 98.16], [2, 3.55, 143.87]], "batl": [[0, 4.6, 113.78]]}, {"timestamp": 1632571294872, "ltp": 4.3, "tv": 3044.17, "trd": NaN, "batb": NaN, "batl": [[0, 4.6, 116.78], [2, 4.9, 2]]}, {"timestamp": 1632571296119, "ltp": 4.3, "tv": 3044.17, "trd": NaN, "batb": [[1, 3.6, 101.16], [2, 3.55, 5]], "batl": NaN}, {"timestamp": 1632571297258, "ltp": 4.3, "tv": 3044.17, "trd": NaN, "batb": [[0, 3.7, 5], [1, 3.65, 3], [2, 3.6, 101.16]], "batl": NaN}, {"timestamp": 1632571299376, "ltp": 4.3, "tv": 3044.17, "trd": NaN, "batb": [[0, 4.4, 5.44], [1, 4.2, 2], [2, 3.7, 5]], "batl": [[1, 4.7, 198.81]]}, {"timestamp": 1632571300299, "ltp": 4.3, "tv": 3044.17, "trd": NaN, "batb": [[1, 4.2, 152.31], [2, 3.8, 85.57]], "batl": [[0, 4.6, 114.78], [1, 4.7, 205.19]]}, {"timestamp": 1632571303186, "ltp": 4.3, "tv": 3044.17, "trd": NaN, "batb": [[0, 4.4, 7.44], [1, 4.3, 3], [2, 4.2, 152.31]], "batl": [[0, 4.6, 111.78]]}, {"timestamp": 1632571304280, "ltp": 4.3, "tv": 3044.17, "trd": NaN, "batb": [[0, 4.4, 5.44], [1, 4.2, 133.56], [2, 3.8, 85.57]], "batl": NaN}, {"timestamp": 1632571306031, "ltp": 4.3, "tv": 3044.17, "trd": NaN, "batb": [[2, 4.1, 2]], "batl": [[2, 4.8, 2]]}, {"timestamp": 1632571307340, "ltp": 4.3, "tv": 3044.17, "trd": NaN, "batb": [[1, 4.3, 18.18], [2, 4.2, 133.56]], "batl": NaN}, {"timestamp": 1632571309328, "ltp": 4.4, "tv": 3048.87, "trd": [[4.4, 119.68]], "batb": [[0, 4.3, 18.18], [1, 4.2, 131.56], [2, 4.1, 2]], "batl": [[0, 4.7, 2], [1, 4.8, 2], [2, 4.9, 106.32]]}, {"timestamp": 1632571310324, "ltp": 4.4, "tv": 3048.87, "trd": NaN, "batb": [[0, 4.1, 2], [1, 3.9, 127.24], [2, 3.85, 121.11]], "batl": [[0, 4.9, 106.32], [1, 5, 117.57], [2, 5.8, 2.54]]}, {"timestamp": 1632571310920, "ltp": 4.4, "tv": 3048.87, "trd": NaN, "batb": [[0, 3.9, 127.24], [1, 3.85, 121.11], [2, 3.8, 85.57]], "batl": [[1, 5, 115.86]]}, {"timestamp": 1632571313213, "ltp": 4.4, "tv": 3048.87, "trd": NaN, "batb": NaN, "batl": [[0, 4.9, 109.32]]}, {"timestamp": 1632571314125, "ltp": 4.4, "tv": 3048.87, "trd": NaN, "batb": [[0, 4.1, 2], [1, 3.9, 127.24], [2, 3.85, 121.11]], "batl": NaN}, {"timestamp": 1632571314938, "ltp": 4.4, "tv": 3048.87, "trd": NaN, "batb": [[0, 3.9, 2], [1, 3.8, 85.57], [2, 3.7, 3]], "batl": NaN}, {"timestamp": 1632571318302, "ltp": 4.4, "tv": 3048.87, "trd": NaN, "batb": [[0, 4.5, 104.44], [1, 4.4, 176.99], [2, 4.3, 52.22]], "batl": [[0, 4.8, 4.43], [1, 4.9, 109.32], [2, 5, 153.48]]}, {"timestamp": 1632571319229, "ltp": 4.4, "tv": 3048.87, "trd": NaN, "batb": [[2, 4.3, 70.4]], "batl": [[0, 4.9, 129.54], [1, 5, 153.48], [2, 5.1, 92.16]]}, {"timestamp": 1632571322213, "ltp": 4.4, "tv": 3048.87, "trd": NaN, "batb": NaN, "batl": [[0, 4.8, 4.43], [1, 4.9, 129.54], [2, 5, 153.48]]}, {"timestamp": 1632571323035, "ltp": 4.4, "tv": 3048.87, "trd": NaN, "batb": [[2, 4.3, 52.22]], "batl": NaN}, {"timestamp": 1632571324242, "ltp": 4.4, "tv": 3048.87, "trd": NaN, "batb": [[2, 4.3, 54.22]], "batl": [[2, 5, 155.48]]}, {"timestamp": 1632571324737, "ltp": 4.4, "tv": 3048.87, "trd": NaN, "batb": NaN, "batl": [[2, 5, 256.66]]}, {"timestamp": 1632571326038, "ltp": 4.4, "tv": 3048.87, "trd": NaN, "batb": [[1, 4.4, 194.63]], "batl": NaN}, {"timestamp": 1632571331356, "ltp": 4.4, "tv": 3048.87, "trd": NaN, "batb": [[0, 4.4, 17.64], [1, 4.3, 2], [2, 4.2, 2]], "batl": [[0, 4.9, 2], [1, 5, 103.18], [2, 5.1, 95.88]]}, {"timestamp": 1632571332273, "ltp": 4.4, "tv": 3048.87, "trd": NaN, "batb": [[0, 4.3, 2], [1, 4.2, 2], [2, 4.1, 112.89]], "batl": [[0, 5, 103.18], [1, 5.1, 95.88], [2, 5.8, 2.54]]}, {"timestamp": 1632571332933, "ltp": 4.4, "tv": 3048.87, "trd": NaN, "batb": [[0, 4.1, 112.89], [1, 4, 275.58], [2, 3.95, 2]], "batl": NaN}, {"timestamp": 1632571335153, "ltp": 4.4, "tv": 3048.87, "trd": NaN, "batb": NaN, "batl": [[0, 5, 106.18], [2, 5.3, 7.23]]}, {"timestamp": 1632571336131, "ltp": 4.4, "tv": 3048.87, "trd": NaN, "batb": [[0, 4.3, 2], [1, 4.1, 112.89], [2, 4, 275.58]], "batl": [[2, 5.8, 2.54]]}, {"timestamp": 1632571337256, "ltp": 4.4, "tv": 3048.87, "trd": NaN, "batb": [[0, 4.1, 2], [1, 4, 148.98], [2, 3.95, 2]], "batl": NaN}, {"timestamp": 1632571338228, "ltp": 4.4, "tv": 3048.87, "trd": NaN, "batb": NaN, "batl": [[0, 4.9, 2], [1, 5, 106.18], [2, 5.1, 95.88]]}, {"timestamp": 1632571338817, "ltp": 4.4, "tv": 3048.87, "trd": NaN, "batb": NaN, "batl": [[0, 5, 106.18], [1, 5.1, 95.88], [2, 5.8, 2.54]]}, {"timestamp": 1632571340164, "ltp": 4.4, "tv": 3048.87, "trd": NaN, "batb": [[0, 4.8, 4.08], [1, 4.5, 2], [2, 4.1, 2]], "batl": [[0, 5, 110.83], [1, 5.1, 146.43]]}, {"timestamp": 1632571341358, "ltp": 4.4, "tv": 3048.87, "trd": NaN, "batb": [[1, 4.5, 134.89], [2, 4.2, 134.1]], "batl": [[1, 5.1, 152.31], [2, 5.3, 90.39]]}, {"timestamp": 1632571342280, "ltp": 4.4, "tv": 3048.87, "trd": NaN, "batb": [[2, 4.2, 144.1]], "batl": [[0, 5, 123.32]]}, {"timestamp": 1632571344339, "ltp": 4.4, "tv": 3048.87, "trd": NaN, "batb": NaN, "batl": [[0, 5, 123.73]]}, {"timestamp": 1632571345362, "ltp": 4.4, "tv": 3048.87, "trd": NaN, "batb": [[1, 4.5, 117.75]], "batl": NaN}, {"timestamp": 1632571347320, "ltp": 4.4, "tv": 3048.87, "trd": NaN, "batb": [[2, 4.4, 2]], "batl": [[1, 5.1, 253.25], [2, 5.2, 102.5]]}, {"timestamp": 1632571348562, "ltp": 4.4, "tv": 3048.87, "trd": NaN, "batb": [[1, 4.6, 16.66], [2, 4.5, 117.75]], "batl": NaN}, {"timestamp": 1632571353167, "ltp": 4.4, "tv": 3048.87, "trd": NaN, "batb": [[0, 4.6, 16.66], [1, 4.4, 2], [2, 4.3, 109.72]], "batl": [[0, 5, 5.41], [1, 5.1, 100.94]]}, {"timestamp": 1632571354245, "ltp": 4.4, "tv": 3048.87, "trd": NaN, "batb": [[0, 4.4, 2], [1, 4.3, 109.72], [2, 4.2, 271.97]], "batl": [[0, 5, 3.41]]}, {"timestamp": 1632571357069, "ltp": 4.4, "tv": 3048.87, "trd": NaN, "batb": NaN, "batl": [[1, 5.2, 2], [2, 5.8, 2.54]]}, {"timestamp": 1632571360371, "ltp": 4.4, "tv": 3048.87, "trd": NaN, "batb": [[0, 4.5, 6.84], [1, 4.4, 2], [2, 4.3, 109.72]], "batl": [[0, 4.8, 52.53], [1, 4.9, 6.12], [2, 5, 171.26]]}, {"timestamp": 1632571361014, "ltp": 4.4, "tv": 3048.87, "trd": NaN, "batb": NaN, "batl": [[1, 4.9, 23.17]]}, {"timestamp": 1632571362381, "ltp": 4.4, "tv": 3048.87, "trd": NaN, "batb": [[2, 4.3, 127.9]], "batl": [[1, 4.9, 8.12]]}, {"timestamp": 1632571362962, "ltp": 4.4, "tv": 3048.87, "trd": NaN, "batb": NaN, "batl": [[0, 4.7, 2], [1, 4.8, 52.53], [2, 4.9, 8.12]]}, {"timestamp": 1632571365076, "ltp": 4.4, "tv": 3048.87, "trd": NaN, "batb": NaN, "batl": [[1, 4.8, 69.58]]}, {"timestamp": 1632571367061, "ltp": 4.4, "tv": 3048.87, "trd": NaN, "batb": NaN, "batl": [[1, 4.8, 172.86], [2, 4.9, 114.13]]}, {"timestamp": 1632571368120, "ltp": 4.4, "tv": 3048.87, "trd": NaN, "batb": [[2, 4.3, 129.9]], "batl": NaN}, {"timestamp": 1632571373267, "ltp": 4.4, "tv": 3048.87, "trd": NaN, "batb": [[0, 4.4, 2], [1, 4.3, 20.18], [2, 4.2, 134.1]], "batl": [[1, 4.8, 103.28], [2, 4.9, 108.01]]}, {"timestamp": 1632571374308, "ltp": 4.4, "tv": 3048.87, "trd": NaN, "batb": [[1, 4.3, 2], [2, 4, 103.87]], "batl": [[0, 4.8, 103.28], [1, 4.9, 108.01], [2, 5, 5.41]]}, {"timestamp": 1632571374884, "ltp": 4.4, "tv": 3048.87, "trd": NaN, "batb": [[0, 4.3, 2], [1, 4, 103.87], [2, 3.95, 148.1]], "batl": [[2, 5, 2.41]]}, {"timestamp": 1632571378174, "ltp": 4.4, "tv": 3048.87, "trd": NaN, "batb": [[0, 4.4, 2], [1, 4.3, 4], [2, 4.2, 2]], "batl": NaN}, {"timestamp": 1632571378445, "ltp": 4.4, "tv": 3048.87, "trd": NaN, "batb": [[0, 4.3, 4], [1, 4.2, 2], [2, 4, 103.87]], "batl": NaN}, {"timestamp": 1632571381383, "ltp": 4.4, "tv": 3048.87, "trd": NaN, "batb": [[2, 3.95, 2]], "batl": NaN}, {"timestamp": 1632571384236, "ltp": 4.4, "tv": 3048.87, "trd": NaN, "batb": [[0, 4.6, 510.88], [1, 4.5, 298.63], [2, 4.4, 1206.71]], "batl": [[2, 5, 31.66]]}, {"timestamp": 1632571385216, "ltp": 4.4, "tv": 3048.87, "trd": NaN, "batb": [[0, 4.6, 102.18], [1, 4.5, 94.27], [2, 4.4, 364.27]], "batl": NaN}, {"timestamp": 1632571386249, "ltp": 4.4, "tv": 3048.87, "trd": NaN, "batb": [[1, 4.5, 111.41], [2, 4.4, 380.61]], "batl": NaN}, {"timestamp": 1632571389171, "ltp": 4.4, "tv": 3048.87, "trd": NaN, "batb": NaN, "batl": [[1, 4.9, 142.37]]}, {"timestamp": 1632571389791, "ltp": 4.4, "tv": 3048.87, "trd": NaN, "batb": NaN, "batl": [[1, 4.9, 108.01]]}, {"timestamp": 1632571394377, "ltp": 4.4, "tv": 3048.87, "trd": NaN, "batb": NaN, "batl": [[2, 5, 27.39]]}, {"timestamp": 1632571397366, "ltp": 4.4, "tv": 3048.87, "trd": NaN, "batb": NaN, "batl": [[0, 4.8, 107.71]]}, {"timestamp": 1632571403765, "ltp": 4.6, "tv": 3067.65, "trd": [[4.6, 19.6]], "batb": [[0, 4.6, 92.79]], "batl": [[2, 5, 26.98]]}, {"timestamp": 1632571409372, "ltp": 4.6, "tv": 3067.65, "trd": NaN, "batb": [[0, 4.5, 17.14], [1, 4.3, 2], [2, 4.2, 142.49]], "batl": [[0, 5.5, 75.34], [1, 5.6, 86.85], [2, 5.8, 2.54]]}, {"timestamp": 1632571410281, "ltp": 4.6, "tv": 3067.65, "trd": NaN, "batb": [[0, 4.3, 2], [1, 4.2, 142.49], [2, 4, 123.46]], "batl": NaN}, {"timestamp": 1632571411005, "ltp": 4.6, "tv": 3067.65, "trd": NaN, "batb": [[0, 4.2, 142.49], [1, 4, 123.46], [2, 3.95, 124.23]], "batl": NaN}, {"timestamp": 1632571414178, "ltp": 4.6, "tv": 3067.65, "trd": NaN, "batb": [[0, 4.3, 2], [1, 4.2, 142.49], [2, 4.1, 2]], "batl": NaN}, {"timestamp": 1632571414772, "ltp": 4.6, "tv": 3067.65, "trd": NaN, "batb": [[0, 4.2, 142.49], [1, 4.1, 2], [2, 4, 123.46]], "batl": NaN}, {"timestamp": 1632571416382, "ltp": 4.6, "tv": 3067.65, "trd": NaN, "batb": [[2, 1.9, 5.76]], "batl": [[0, 5.6, 86.85], [1, 5.8, 2.54], [2, 6, 115.31]]}, {"timestamp": 1632571418290, "ltp": 4.6, "tv": 3067.65, "trd": NaN, "batb": [[0, 4.3, 2], [1, 4.2, 142.49], [2, 4.1, 2]], "batl": [[2, 6, 7]]}, {"timestamp": 1632571419380, "ltp": 4.6, "tv": 3067.65, "trd": NaN, "batb": [[0, 5.2, 459.74], [1, 5.1, 178.48], [2, 5, 448.21]], "batl": [[1, 5.7, 6.04], [2, 5.8, 2.54]]}, {"timestamp": 1632571420229, "ltp": 4.6, "tv": 3067.65, "trd": NaN, "batb": [[0, 5.2, 183.9], [1, 5.1, 264.47], [2, 5, 180.48]], "batl": [[0, 5.6, 89.85], [2, 5.8, 4.25]]}, {"timestamp": 1632571421315, "ltp": 4.6, "tv": 3067.65, "trd": NaN, "batb": [[1, 5.1, 279.1]], "batl": [[0, 5.6, 99.35]]}, {"timestamp": 1632571421816, "ltp": 4.6, "tv": 3067.65, "trd": NaN, "batb": [[1, 5.1, 264.47]], "batl": NaN}, {"timestamp": 1632571424837, "ltp": 4.6, "tv": 3067.65, "trd": NaN, "batb": [[0, 5.3, 13.95], [1, 5.2, 183.9], [2, 5.1, 264.47]], "batl": NaN}, {"timestamp": 1632571426918, "ltp": 4.6, "tv": 3067.65, "trd": NaN, "batb": NaN, "batl": [[0, 5.6, 99.77]]}, {"timestamp": 1632571430103, "ltp": 4.6, "tv": 3067.65, "trd": NaN, "batb": NaN, "batl": [[2, 5.8, 2.54]]}, {"timestamp": 1632571434126, "ltp": 4.6, "tv": 3067.65, "trd": NaN, "batb": NaN, "batl": [[0, 5.6, 99.35]]}, {"timestamp": 1632571435227, "ltp": 4.6, "tv": 3067.65, "trd": NaN, "batb": [[1, 4.8, 2], [2, 4.6, 108.82]], "batl": [[0, 5.8, 2.54], [1, 6, 5], [2, 7, 74.56]]}, {"timestamp": 1632571436325, "ltp": 4.6, "tv": 3067.65, "trd": NaN, "batb": [[0, 4.8, 2], [1, 4.6, 108.82], [2, 4.5, 2]], "batl": NaN}, {"timestamp": 1632571441350, "ltp": 5.5, "tv": 3068.06, "trd": [[5.5, 0.41]], "batb": NaN, "batl": [[2, 7.8, 91.68]]}, {"timestamp": 1632571442746, "ltp": 5.5, "tv": 3068.06, "trd": NaN, "batb": NaN, "batl": [[2, 7.8, 2]]}, {"timestamp": 1632571444345, "ltp": 5.5, "tv": 3068.06, "trd": NaN, "batb": [[0, 4.8, 5.9], [2, 4.5, 214.5]], "batl": [[0, 5, 4.7], [1, 5.3, 67.91], [2, 5.8, 2.54]]}, {"timestamp": 1632571445246, "ltp": 5.5, "tv": 3068.06, "trd": NaN, "batb": [[0, 4.8, 3.9], [1, 4.7, 16.21], [2, 4.6, 108.82]], "batl": [[2, 5.7, 8.62]]}, {"timestamp": 1632571446155, "ltp": 5.5, "tv": 3068.06, "trd": NaN, "batb": NaN, "batl": [[2, 5.5, 2]]}, {"timestamp": 1632571447263, "ltp": 5.5, "tv": 3068.06, "trd": NaN, "batb": [[1, 4.6, 108.82], [2, 4.5, 214.5]], "batl": NaN}, {"timestamp": 1632571449286, "ltp": 5.5, "tv": 3068.06, "trd": NaN, "batb": NaN, "batl": [[2, 5.5, 3.8]]}, {"timestamp": 1632571450262, "ltp": 5.5, "tv": 3068.06, "trd": NaN, "batb": [[1, 4.7, 16.21], [2, 4.6, 108.82]], "batl": NaN}, {"timestamp": 1632571457374, "ltp": 5.5, "tv": 3068.06, "trd": NaN, "batb": [[0, 4.7, 16.21], [1, 4.5, 2], [2, 4.4, 2]], "batl": [[0, 5.5, 1.8], [1, 5.7, 6.91], [2, 5.8, 2.54]]}, {"timestamp": 1632571458256, "ltp": 5.5, "tv": 3068.06, "trd": NaN, "batb": [[0, 4.5, 2], [1, 4.4, 2], [2, 4.3, 130.46]], "batl": [[1, 5.8, 2.54], [2, 6, 100.45]]}, {"timestamp": 1632571458578, "ltp": 5.5, "tv": 3068.06, "trd": NaN, "batb": [[0, 4.4, 2], [1, 4.3, 130.46], [2, 4.2, 2]], "batl": NaN}, {"timestamp": 1632571462344, "ltp": 5.5, "tv": 3068.06, "trd": NaN, "batb": [[0, 4.4, 4], [1, 4.3, 133.46]], "batl": NaN}, {"timestamp": 1632571463254, "ltp": 5.5, "tv": 3068.06, "trd": NaN, "batb": [[0, 4.5, 2], [1, 4.4, 4], [2, 4.3, 133.46]], "batl": [[0, 5.2, 17.98], [1, 5.5, 1.8], [2, 5.8, 2.54]]}, {"timestamp": 1632571464277, "ltp": 5.5, "tv": 3068.06, "trd": NaN, "batb": [[0, 4.5, 12]], "batl": [[0, 5.4, 9]]}, {"timestamp": 1632571464582, "ltp": 5.5, "tv": 3068.06, "trd": NaN, "batb": [[0, 4.5, 2]], "batl": NaN}, {"timestamp": 1632571468274, "ltp": 5.5, "tv": 3068.06, "trd": NaN, "batb": [[0, 4.4, 4], [1, 4.3, 133.46], [2, 4.2, 2]], "batl": [[0, 5.5, 1.8], [1, 5.8, 2.54], [2, 6, 100.45]]}, {"timestamp": 1632571471189, "ltp": 5.5, "tv": 3068.06, "trd": NaN, "batb": [[0, 4.5, 2], [1, 4.4, 4], [2, 4.3, 133.46]], "batl": NaN}, {"timestamp": 1632571471481, "ltp": 5.5, "tv": 3068.06, "trd": NaN, "batb": [[0, 4.4, 4], [1, 4.3, 133.46], [2, 4.2, 2]], "batl": NaN}, {"timestamp": 1632571473275, "ltp": 5.5, "tv": 3068.06, "trd": NaN, "batb": [[1, 4.3, 130.46], [2, 4.1, 95.4]], "batl": NaN}, {"timestamp": 1632571475889, "ltp": 5.5, "tv": 3068.06, "trd": NaN, "batb": NaN, "batl": [[2, 6.4, 2]]}, {"timestamp": 1632571477292, "ltp": 5.5, "tv": 3068.06, "trd": NaN, "batb": [[0, 4.4, 2]], "batl": [[2, 7, 2]]}, {"timestamp": 1632571478366, "ltp": 5.5, "tv": 3068.06, "trd": NaN, "batb": [[0, 4.5, 2], [1, 4.4, 2], [2, 4.3, 130.46]], "batl": NaN}, {"timestamp": 1632571479292, "ltp": 4.5, "tv": 3073.73, "trd": [[4.5, 8.76]], "batb": [[0, 4.4, 2], [1, 4.3, 130.46], [2, 4.2, 52.76]], "batl": [[0, 4.7, 45.32], [1, 4.8, 6.25], [2, 5.5, 1.8]]}, {"timestamp": 1632571480302, "ltp": 4.5, "tv": 3073.73, "trd": NaN, "batb": [[0, 4.4, 19.64]], "batl": [[2, 5.1, 1.71]]}, {"timestamp": 1632571483868, "ltp": 4.5, "tv": 3073.73, "trd": NaN, "batb": NaN, "batl": [[0, 4.7, 57.04]]}, {"timestamp": 1632571485910, "ltp": 4.5, "tv": 3073.73, "trd": NaN, "batb": [[1, 4.3, 132.46], [2, 4.2, 54.76]], "batl": [[2, 5, 2]]}, {"timestamp": 1632571491030, "ltp": 4.4, "tv": 3074.55, "trd": [[4.4, 120.5]], "batb": [[0, 4.4, 19.23]], "batl": NaN}, {"timestamp": 1632571491713, "ltp": 4.4, "tv": 3074.55, "trd": NaN, "batb": [[0, 4.4, 24.66]], "batl": NaN}, {"timestamp": 1632571493213, "ltp": 4.4, "tv": 3074.55, "trd": NaN, "batb": [[0, 4.4, 17.64], [1, 4.3, 2], [2, 4.2, 2]], "batl": [[0, 5.2, 77.96], [1, 5.3, 104.92], [2, 5.4, 2]]}, {"timestamp": 1632571494318, "ltp": 4.4, "tv": 3074.55, "trd": NaN, "batb": [[0, 4.3, 2], [1, 4.2, 2], [2, 4, 148.3]], "batl": NaN}, {"timestamp": 1632571495333, "ltp": 4.4, "tv": 3074.55, "trd": NaN, "batb": [[0, 4.2, 2], [1, 4, 148.3], [2, 3.9, 132.84]], "batl": [[0, 5.4, 2], [1, 5.5, 1.8], [2, 5.7, 2]]}, {"timestamp": 1632571498302, "ltp": 4.3, "tv": 3082.73, "trd": [[4.3, 38.82], [4.5, 8.83]], "batb": NaN, "batl": [[0, 4.5, 556.31], [1, 4.7, 149.85], [2, 5.4, 2]]}, {"timestamp": 1632571499320, "ltp": 4.3, "tv": 3082.73, "trd": NaN, "batb": [[0, 4.2, 20.75], [1, 4, 265.8], [2, 3.95, 218.05]], "batl": [[0, 4.5, 187.32], [2, 4.9, 7.59]]}, {"timestamp": 1632571499901, "ltp": 4.3, "tv": 3082.73, "trd": NaN, "batb": NaN, "batl": [[0, 4.5, 189.03]]}, {"timestamp": 1632571501104, "ltp": 4.3, "tv": 3082.73, "trd": NaN, "batb": NaN, "batl": [[2, 4.9, 10.59]]}, {"timestamp": 1632571503227, "ltp": 4.3, "tv": 3082.73, "trd": NaN, "batb": NaN, "batl": [[0, 4.5, 203.89]]}, {"timestamp": 1632571505294, "ltp": 4.3, "tv": 3082.73, "trd": NaN, "batb": NaN, "batl": [[1, 4.6, 107.32], [2, 4.7, 264.11]]}, {"timestamp": 1632571505623, "ltp": 4.3, "tv": 3082.73, "trd": NaN, "batb": [[1, 4.1, 2], [2, 4, 265.8]], "batl": [[1, 4.6, 109.32]]}, {"timestamp": 1632571509318, "ltp": 4.3, "tv": 3082.73, "trd": NaN, "batb": [[2, 4, 148.3]], "batl": [[0, 4.5, 16.57], [2, 4.7, 114.26]]}, {"timestamp": 1632571509842, "ltp": 4.3, "tv": 3082.73, "trd": NaN, "batb": [[2, 3.95, 159.29]], "batl": [[0, 4.6, 109.32], [1, 4.7, 114.26], [2, 4.8, 2]]}, {"timestamp": 1632571511331, "ltp": 4.3, "tv": 3082.73, "trd": NaN, "batb": [[0, 4.1, 2], [1, 3.95, 159.29], [2, 3.8, 124.73]], "batl": NaN}, {"timestamp": 1632571514112, "ltp": 4.3, "tv": 3082.73, "trd": NaN, "batb": [[0, 4.2, 2], [1, 4.1, 2], [2, 3.95, 159.29]], "batl": NaN}, {"timestamp": 1632571514641, "ltp": 4.3, "tv": 3082.73, "trd": NaN, "batb": [[0, 4.1, 4], [1, 4, 3]], "batl": NaN}, {"timestamp": 1632571526354, "ltp": 4.3, "tv": 3082.73, "trd": NaN, "batb": [[0, 4.5, 6.76], [1, 4.3, 2.01], [2, 4.2, 60.99]], "batl": [[0, 4.7, 156.42], [1, 4.8, 2], [2, 4.9, 4.71]]}, {"timestamp": 1632571527272, "ltp": 4.3, "tv": 3082.73, "trd": NaN, "batb": [[1, 4.4, 139.48], [2, 4.3, 2.01]], "batl": [[1, 4.8, 8.25]]}, {"timestamp": 1632571530273, "ltp": 4.3, "tv": 3082.73, "trd": NaN, "batb": [[1, 4.4, 121.84]], "batl": NaN}, {"timestamp": 1632571534290, "ltp": 4.3, "tv": 3082.73, "trd": NaN, "batb": [[0, 4.5, 23.9]], "batl": NaN}, {"timestamp": 1632571536694, "ltp": 4.3, "tv": 3082.73, "trd": NaN, "batb": NaN, "batl": [[2, 4.9, 3]]}, {"timestamp": 1632571549267, "ltp": 4.3, "tv": 3082.73, "trd": NaN, "batb": [[0, 4.5, 17.14], [1, 4.2, 2], [2, 4.1, 143.85]], "batl": [[0, 5.4, 89.89], [1, 5.5, 114.07], [2, 5.6, 2]]}, {"timestamp": 1632571550266, "ltp": 4.3, "tv": 3082.73, "trd": NaN, "batb": [[0, 4.2, 2], [1, 4.1, 143.85], [2, 3.95, 89.93]], "batl": NaN}, {"timestamp": 1632571550883, "ltp": 4.3, "tv": 3082.73, "trd": NaN, "batb": [[1, 4.1, 141.85]], "batl": NaN}, {"timestamp": 1632571552875, "ltp": 4.3, "tv": 3082.73, "trd": NaN, "batb": NaN, "batl": [[0, 5.4, 2], [1, 5.5, 1.8]]}, {"timestamp": 1632571553656, "ltp": 4.3, "tv": 3082.73, "trd": NaN, "batb": [[1, 4.1, 139.85]], "batl": NaN}, {"timestamp": 1632571555257, "ltp": 4.3, "tv": 3082.73, "trd": NaN, "batb": [[0, 4.3, 3], [1, 4.2, 2], [2, 4.1, 139.85]], "batl": [[0, 5.3, 2], [1, 5.4, 2], [2, 5.5, 1.8]]}, {"timestamp": 1632571556300, "ltp": 4.3, "tv": 3082.73, "trd": NaN, "batb": [[0, 4.2, 2], [1, 4.1, 139.85], [2, 3.95, 89.93]], "batl": [[0, 4.4, 74.81], [1, 4.6, 1.71], [2, 4.7, 203.46]]}, {"timestamp": 1632571558353, "ltp": 4.3, "tv": 3082.73, "trd": NaN, "batb": [[0, 4.2, 20.75]], "batl": NaN}, {"timestamp": 1632571566694, "ltp": 4.3, "tv": 3082.73, "trd": NaN, "batb": NaN, "batl": [[1, 4.7, 203.46], [2, 4.8, 288.62]]}, {"timestamp": 1632571651364, "ltp": 4.3, "tv": 3082.73, "trd": NaN, "batb": [[0, 4.2, 18.75], [1, 3.65, 94.95], [2, 3.6, 116.37]], "batl": [[0, 4.8, 91.14], [1, 4.9, 90.14], [2, 5.2, 2]]}, {"timestamp": 1632571652381, "ltp": 4.3, "tv": 3082.73, "trd": NaN, "batb": [[0, 3.65, 94.95], [1, 3.6, 116.37], [2, 3.55, 123.88]], "batl": NaN}, {"timestamp": 1632571654381, "ltp": 4.3, "tv": 3082.73, "trd": NaN, "batb": [[0, 3.7, 93.85], [1, 3.65, 94.95], [2, 1.9, 5.76]], "batl": NaN}, {"timestamp": 1632571654785, "ltp": 4.3, "tv": 3082.73, "trd": NaN, "batb": [[1, 1.9, 5.76], [2, 1.01, 140]], "batl": NaN}, {"timestamp": 1632571655499, "ltp": 4.3, "tv": 3082.73, "trd": NaN, "batb": [[1, 3.65, 2], [2, 3.6, 3]], "batl": NaN}, {"timestamp": 1632571657383, "ltp": 4.3, "tv": 3082.73, "trd": NaN, "batb": [[0, 4.5, 5.71], [1, 3.7, 93.85], [2, 3.65, 2]], "batl": [[0, 4.7, 53.12], [1, 4.8, 91.14], [2, 4.9, 90.14]]}, {"timestamp": 1632571658283, "ltp": 4.3, "tv": 3082.73, "trd": NaN, "batb": [[1, 4.3, 124.8], [2, 3.9, 161.41]], "batl": [[0, 4.7, 59.5], [1, 4.8, 106.27], [2, 4.9, 186.06]]}, {"timestamp": 1632571658392, "ltp": 4.3, "tv": 3082.73, "trd": NaN, "batb": [[1, 4.3, 142.98]], "batl": NaN}, {"timestamp": 1632571662088, "ltp": 4.3, "tv": 3082.73, "trd": NaN, "batb": [[1, 4.3, 124.8]], "batl": NaN}, {"timestamp": 1632571664001, "ltp": 4.3, "tv": 3082.73, "trd": NaN, "batb": [[2, 3.9, 287.2]], "batl": NaN}, {"timestamp": 1632571665292, "ltp": 4.3, "tv": 3082.73, "trd": NaN, "batb": [[1, 4.4, 17.64], [2, 4.3, 124.8]], "batl": NaN}, {"timestamp": 1632571673336, "ltp": 4.3, "tv": 3082.73, "trd": NaN, "batb": [[0, 4.4, 17.64], [1, 3.9, 125.79], [2, 3.85, 115.75]], "batl": [[0, 5.1, 7.4], [1, 5.2, 2], [2, 5.5, 1.8]]}, {"timestamp": 1632571674344, "ltp": 4.3, "tv": 3082.73, "trd": NaN, "batb": [[0, 3.9, 125.79], [1, 3.85, 115.75], [2, 3.8, 64.14]], "batl": [[0, 5.2, 2], [1, 5.5, 1.8], [2, 5.8, 2.54]]}, {"timestamp": 1632571675319, "ltp": 4.3, "tv": 3082.73, "trd": NaN, "batb": [[2, 2.62, 386.89]], "batl": NaN}, {"timestamp": 1632571676222, "ltp": 4.3, "tv": 3082.73, "trd": NaN, "batb": NaN, "batl": [[0, 4.2, 54.75], [1, 4.7, 3], [2, 5.2, 2]]}, {"timestamp": 1632571677374, "ltp": 4.3, "tv": 3082.73, "trd": NaN, "batb": NaN, "batl": [[1, 4.3, 1.71], [2, 4.7, 3]]}, {"timestamp": 1632571677642, "ltp": 4.3, "tv": 3082.73, "trd": NaN, "batb": [[0, 4, 20], [1, 3.9, 125.79], [2, 3.85, 115.75]], "batl": [[2, 4.5, 3]]}, {"timestamp": 1632571678457, "ltp": 4.3, "tv": 3082.73, "trd": NaN, "batb": [[1, 3.95, 64.14], [2, 3.9, 125.79]], "batl": NaN}, {"timestamp": 1632571686900, "ltp": 4.3, "tv": 3082.73, "trd": NaN, "batb": [[1, 3.5, 2], [2, 3.35, 147.76]], "batl": [[0, 4.5, 3], [1, 4.6, 101.93], [2, 4.7, 116.87]]}, {"timestamp": 1632571688260, "ltp": 4.3, "tv": 3082.73, "trd": NaN, "batb": [[0, 3.5, 2], [1, 3.35, 147.76], [2, 3.3, 121.25]], "batl": [[0, 4.6, 101.93], [1, 4.7, 106.08], [2, 4.9, 2]]}, {"timestamp": 1632571691582, "ltp": 4.3, "tv": 3082.73, "trd": NaN, "batb": NaN, "batl": [[0, 4.6, 103.93]]}, {"timestamp": 1632571700170, "ltp": 4.3, "tv": 3082.73, "trd": NaN, "batb": [[1, 3.35, 2], [2, 3.3, 2.08]], "batl": NaN}, {"timestamp": 1632571703232, "ltp": 4.3, "tv": 3082.73, "trd": NaN, "batb": [[0, 4.4, 5.82], [1, 4.3, 2.08], [2, 3.5, 2]], "batl": [[1, 4.7, 194.67], [2, 4.8, 498.05]]}, {"timestamp": 1632571704293, "ltp": 4.3, "tv": 3082.73, "trd": NaN, "batb": [[1, 4.2, 18.75]], "batl": [[1, 4.7, 201.05], [2, 4.8, 199.22]]}, {"timestamp": 1632571704782, "ltp": 4.3, "tv": 3082.73, "trd": NaN, "batb": [[2, 3.7, 10]], "batl": [[0, 4.6, 116.8]]}, {"timestamp": 1632571708191, "ltp": 4.3, "tv": 3082.73, "trd": NaN, "batb": [[1, 3.7, 10], [2, 3.55, 3]], "batl": NaN}, {"timestamp": 1632571710194, "ltp": 4.3, "tv": 3082.73, "trd": NaN, "batb": [[1, 3.7, 147.7], [2, 3.65, 144.66]], "batl": [[2, 4.8, 282.61]]}, {"timestamp": 1632571710635, "ltp": 4.3, "tv": 3082.73, "trd": NaN, "batb": [[1, 4.1, 2], [2, 3.9, 2]], "batl": [[2, 4.8, 284.61]]}, {"timestamp": 1632571712129, "ltp": 4.3, "tv": 3082.73, "trd": NaN, "batb": [[1, 4.3, 18.18], [2, 4.1, 2]], "batl": NaN}, {"timestamp": 1632571714205, "ltp": 4.3, "tv": 3082.73, "trd": NaN, "batb": [[0, 4.3, 18.18], [1, 4.1, 2], [2, 3.9, 2]], "batl": [[1, 4.7, 106.08], [2, 4.8, 85.39]]}, {"timestamp": 1632571714807, "ltp": 4.3, "tv": 3082.73, "trd": NaN, "batb": NaN, "batl": [[0, 4.8, 83.39], [1, 4.9, 108.59], [2, 5.5, 1.8]]}, {"timestamp": 1632571716309, "ltp": 4.3, "tv": 3082.73, "trd": NaN, "batb": [[0, 4.1, 2], [1, 3.9, 2], [2, 3.7, 137.7]], "batl": NaN}, {"timestamp": 1632571716589, "ltp": 4.3, "tv": 3082.73, "trd": NaN, "batb": [[0, 3.9, 2], [1, 3.7, 137.7], [2, 3.65, 144.66]], "batl": NaN}, {"timestamp": 1632571718320, "ltp": 4.3, "tv": 3082.73, "trd": NaN, "batb": [[1, 3.5, 3], [2, 2.62, 386.89]], "batl": [[0, 4.8, 85.39]]}, {"timestamp": 1632571721018, "ltp": 4.3, "tv": 3082.73, "trd": NaN, "batb": [[0, 4.5, 2], [1, 4.4, 48.83], [2, 3.9, 2]], "batl": [[0, 4.8, 2], [1, 4.9, 110.31], [2, 5, 37.44]]}, {"timestamp": 1632571722332, "ltp": 4.3, "tv": 3082.73, "trd": NaN, "batb": [[1, 4.4, 66.47]], "batl": [[2, 5, 43.44]]}, {"timestamp": 1632571722625, "ltp": 4.3, "tv": 3082.73, "trd": NaN, "batb": [[2, 3.95, 10]], "batl": [[0, 4.8, 12.63]]}, {"timestamp": 1632571725935, "ltp": 4.3, "tv": 3082.73, "trd": NaN, "batb": [[1, 4.4, 48.83]], "batl": NaN}, {"timestamp": 1632571727328, "ltp": 4.3, "tv": 3082.73, "trd": NaN, "batb": [[1, 4.4, 50.83], [2, 4.3, 2]], "batl": [[2, 5, 45.44]]}, {"timestamp": 1632571729334, "ltp": 4.3, "tv": 3082.73, "trd": NaN, "batb": [[0, 4.5, 19.14]], "batl": NaN}, {"timestamp": 1632571731533, "ltp": 4.3, "tv": 3082.73, "trd": NaN, "batb": NaN, "batl": [[1, 4.9, 108.59]]}, {"timestamp": 1632571733010, "ltp": 4.3, "tv": 3082.73, "trd": NaN, "batb": [[0, 4.5, 17.14], [1, 4.4, 2]], "batl": [[0, 5, 2], [1, 5.1, 75.95], [2, 5.2, 109.22]]}, {"timestamp": 1632571734244, "ltp": 4.3, "tv": 3082.73, "trd": NaN, "batb": [[0, 4.4, 2], [1, 4.3, 2], [2, 4.1, 102.16]], "batl": NaN}, {"timestamp": 1632571735157, "ltp": 4.3, "tv": 3082.73, "trd": NaN, "batb": [[0, 4.3, 2], [1, 4.1, 102.16], [2, 4, 266.91]], "batl": NaN}, {"timestamp": 1632571736343, "ltp": 4.3, "tv": 3082.73, "trd": NaN, "batb": [[1, 4, 150.16], [2, 3.5, 3]], "batl": [[0, 4.9, 2], [1, 5, 5], [2, 5.1, 75.95]]}, {"timestamp": 1632571736546, "ltp": 4.3, "tv": 3082.73, "trd": NaN, "batb": NaN, "batl": [[0, 5, 5], [1, 5.1, 75.95], [2, 5.2, 109.22]]}, {"timestamp": 1632571739347, "ltp": 4.3, "tv": 3082.73, "trd": NaN, "batb": [[0, 4.6, 165.65], [1, 4.5, 116.65], [2, 4.4, 32.82]], "batl": [[1, 5.1, 126.75]]}, {"timestamp": 1632571739733, "ltp": 4.3, "tv": 3082.73, "trd": NaN, "batb": [[2, 4.4, 42.82]], "batl": [[0, 5, 18.39], [2, 5.2, 114.99]]}, {"timestamp": 1632571741038, "ltp": 4.3, "tv": 3082.73, "trd": NaN, "batb": [[1, 4.5, 133.79]], "batl": NaN}, {"timestamp": 1632571744237, "ltp": 4.3, "tv": 3082.73, "trd": NaN, "batb": [[1, 4.5, 116.65], [2, 4.4, 10]], "batl": NaN}, {"timestamp": 1632571745656, "ltp": 4.3, "tv": 3082.73, "trd": NaN, "batb": [[2, 4.4, 12]], "batl": NaN}, {"timestamp": 1632571747258, "ltp": 4.3, "tv": 3082.73, "trd": NaN, "batb": [[0, 4.6, 182.31]], "batl": NaN}, {"timestamp": 1632571754061, "ltp": 4.3, "tv": 3082.73, "trd": NaN, "batb": NaN, "batl": [[1, 5.1, 122.79]]}, {"timestamp": 1632571757056, "ltp": 4.7, "tv": 3083.18, "trd": [[4.7, 45.38]], "batb": NaN, "batl": [[0, 5, 24.88]]}, {"timestamp": 1632571757959, "ltp": 4.7, "tv": 3083.18, "trd": NaN, "batb": NaN, "batl": [[0, 5, 18.39]]}, {"timestamp": 1632571760444, "ltp": 4.7, "tv": 3083.18, "trd": NaN, "batb": NaN, "batl": [[0, 5, 24.88]]}, {"timestamp": 1632571767283, "ltp": 4.7, "tv": 3083.18, "trd": NaN, "batb": [[0, 4.6, 16.66]], "batl": [[0, 5, 18.39], [1, 5.1, 75.95], [2, 5.2, 109.22]]}, {"timestamp": 1632571768281, "ltp": 4.7, "tv": 3083.18, "trd": NaN, "batb": [[1, 4.4, 2], [2, 4.3, 2]], "batl": [[0, 5.5, 8.87], [1, 5.8, 2.54], [2, 5.9, 84.85]]}, {"timestamp": 1632571769319, "ltp": 4.7, "tv": 3083.18, "trd": NaN, "batb": [[0, 4.4, 2], [1, 4.3, 2], [2, 4.2, 133.65]], "batl": [[0, 5.5, 1.8]]}, {"timestamp": 1632571769585, "ltp": 4.7, "tv": 3083.18, "trd": NaN, "batb": [[0, 4.3, 2], [1, 4.2, 131.65], [2, 4.1, 101.41]], "batl": NaN}, {"timestamp": 1632571772181, "ltp": 4.7, "tv": 3083.18, "trd": NaN, "batb": NaN, "batl": [[0, 4.7, 17.29], [1, 5.5, 1.8], [2, 5.8, 4.54]]}, {"timestamp": 1632571773206, "ltp": 4.7, "tv": 3083.18, "trd": NaN, "batb": NaN, "batl": [[2, 5.8, 6.54]]}, {"timestamp": 1632571774374, "ltp": 5.5, "tv": 3102.27, "trd": [[4.7, 62.67], [5.5, 2.21]], "batb": NaN, "batl": [[0, 5.8, 6.54], [1, 6, 108.31], [2, 6.4, 2]]}, {"timestamp": 1632571774675, "ltp": 5.5, "tv": 3102.27, "trd": NaN, "batb": NaN, "batl": [[0, 5.8, 4.54]]}, {"timestamp": 1632571776371, "ltp": 5.5, "tv": 3102.27, "trd": NaN, "batb": [[1, 4.2, 179.94]], "batl": [[0, 4.7, 52.42], [1, 4.8, 6.25], [2, 5.8, 4.54]]}, {"timestamp": 1632571777288, "ltp": 5.5, "tv": 3102.27, "trd": NaN, "batb": [[0, 4.3, 20.18]], "batl": [[2, 5.1, 1.71]]}, {"timestamp": 1632571778347, "ltp": 5.5, "tv": 3102.27, "trd": NaN, "batb": [[0, 4.3, 2], [2, 4.1, 103.41]], "batl": NaN}, {"timestamp": 1632571781001, "ltp": 5.5, "tv": 3102.27, "trd": NaN, "batb": [[0, 4.3, 20.18]], "batl": NaN}, {"timestamp": 1632571781868, "ltp": 5.5, "tv": 3102.27, "trd": NaN, "batb": NaN, "batl": [[0, 4.7, 75.12]]}, {"timestamp": 1632571783100, "ltp": 5.5, "tv": 3102.27, "trd": NaN, "batb": [[1, 4.2, 181.94], [2, 4.1, 105.41]], "batl": [[2, 5, 2]]}, {"timestamp": 1632571789208, "ltp": 5.5, "tv": 3102.27, "trd": NaN, "batb": [[1, 4.2, 133.65]], "batl": [[0, 4.7, 22.7], [1, 5, 2], [2, 5.1, 109.61]]}, {"timestamp": 1632571790309, "ltp": 5.5, "tv": 3102.27, "trd": NaN, "batb": [[0, 4.2, 2], [1, 4.1, 2], [2, 4, 148.05]], "batl": [[0, 5.1, 109.61], [1, 5.2, 92.11], [2, 5.4, 2]]}, {"timestamp": 1632571790710, "ltp": 5.5, "tv": 3102.27, "trd": NaN, "batb": [[1, 4, 148.05], [2, 3.9, 105.16]], "batl": NaN}, {"timestamp": 1632571793101, "ltp": 5.5, "tv": 3102.27, "trd": NaN, "batb": NaN, "batl": [[0, 5.4, 2], [1, 5.7, 3], [2, 5.8, 2.54]]}, {"timestamp": 1632571795286, "ltp": 5.0, "tv": 3284.66, "trd": [[5, 190.94]], "batb": [[0, 4.3, 2], [1, 4.2, 2], [2, 4, 148.05]], "batl": [[0, 4.5, 86.91], [1, 5.4, 2], [2, 5.7, 3]]}, {"timestamp": 1632571796040, "ltp": 4.3, "tv": 3291.01, "trd": [[4.3, 45.17]], "batb": [[0, 4.2, 2], [1, 4, 148.05], [2, 3.9, 105.16]], "batl": [[0, 4.4, 54.82], [1, 4.5, 6.67], [2, 4.7, 1.71]]}, {"timestamp": 1632571797296, "ltp": 4.3, "tv": 3291.01, "trd": NaN, "batb": [[0, 4.3, 18.18], [1, 4.2, 2], [2, 4, 148.05]], "batl": NaN}, {"timestamp": 1632571798328, "ltp": 4.3, "tv": 3291.01, "trd": NaN, "batb": [[0, 4.2, 2], [1, 4, 148.05], [2, 3.9, 266.74]], "batl": NaN}, {"timestamp": 1632571800310, "ltp": 4.3, "tv": 3291.01, "trd": NaN, "batb": NaN, "batl": [[0, 4.4, 60.58]]}, {"timestamp": 1632571800840, "ltp": 4.3, "tv": 3291.01, "trd": NaN, "batb": [[1, 4.1, 19.35], [2, 4, 148.05]], "batl": NaN}, {"timestamp": 1632571802220, "ltp": 4.3, "tv": 3291.01, "trd": NaN, "batb": [[1, 4.1, 21.39]], "batl": NaN}, {"timestamp": 1632571802623, "ltp": 4.3, "tv": 3291.01, "trd": NaN, "batb": NaN, "batl": [[2, 4.7, 103.71]]}, {"timestamp": 1632571804198, "ltp": 4.3, "tv": 3291.01, "trd": NaN, "batb": NaN, "batl": [[0, 4.7, 103.71], [1, 4.8, 108], [2, 4.9, 2]]}, {"timestamp": 1632571805339, "ltp": 4.3, "tv": 3291.01, "trd": NaN, "batb": [[1, 4.1, 2.04], [2, 3.9, 161.58]], "batl": NaN}, {"timestamp": 1632571807350, "ltp": 4.3, "tv": 3291.01, "trd": NaN, "batb": [[0, 4.2, 3], [1, 4.1, 2]], "batl": [[0, 4.7, 102], [2, 4.9, 9.59]]}, {"timestamp": 1632571808082, "ltp": 4.3, "tv": 3291.01, "trd": NaN, "batb": NaN, "batl": [[0, 4.8, 2], [1, 4.9, 2], [2, 5.3, 2]]}, {"timestamp": 1632571810241, "ltp": 4.3, "tv": 3291.01, "trd": NaN, "batb": [[0, 4.3, 2.08], [1, 3.9, 161.58], [2, 3.8, 119.93]], "batl": [[0, 4.9, 2], [1, 5.3, 2], [2, 5.4, 2]]}, {"timestamp": 1632571811233, "ltp": 4.2, "tv": 3297.71, "trd": [[4.2, 39.92]], "batb": [[0, 4.1, 2.04], [1, 3.9, 406.78], [2, 3.85, 237.98]], "batl": [[0, 4.3, 6.98], [1, 4.4, 120.51], [2, 4.9, 2]]}, {"timestamp": 1632571812333, "ltp": 4.2, "tv": 3299.42, "trd": [[4.2, 41.63]], "batb": NaN, "batl": [[2, 4.7, 10]]}, {"timestamp": 1632571813027, "ltp": 4.2, "tv": 3299.42, "trd": NaN, "batb": [[1, 3.95, 16.46], [2, 3.9, 406.78]], "batl": [[2, 4.7, 13]]}, {"timestamp": 1632571818246, "ltp": 4.2, "tv": 3299.42, "trd": NaN, "batb": [[0, 3.8, 201.16], [1, 3.75, 113.59], [2, 3.5, 3]], "batl": [[0, 4.4, 119.05], [1, 4.5, 101.17], [2, 4.6, 2]]}, {"timestamp": 1632571819333, "ltp": 4.2, "tv": 3299.42, "trd": NaN, "batb": [[0, 4, 20], [1, 3.8, 201.16], [2, 3.75, 113.59]], "batl": NaN}, {"timestamp": 1632571819542, "ltp": 4.2, "tv": 3299.42, "trd": NaN, "batb": [[0, 3.8, 201.16], [1, 3.75, 113.59], [2, 3.5, 3]], "batl": NaN}, {"timestamp": 1632571821331, "ltp": 4.2, "tv": 3299.42, "trd": NaN, "batb": [[0, 4.1, 4.54], [1, 4, 3], [2, 3.8, 201.16]], "batl": NaN}, {"timestamp": 1632571822354, "ltp": 4.2, "tv": 3299.42, "trd": NaN, "batb": NaN, "batl": [[0, 4.5, 2], [1, 4.6, 2], [2, 4.9, 2]]}, {"timestamp": 1632571822651, "ltp": 4.2, "tv": 3299.42, "trd": NaN, "batb": NaN, "batl": [[0, 4.6, 2], [1, 5.3, 2], [2, 5.8, 2.54]]}, {"timestamp": 1632571825332, "ltp": 4.2, "tv": 3299.42, "trd": NaN, "batb": [[0, 4.1, 2.54], [1, 3.8, 452.8], [2, 3.75, 405.28]], "batl": [[0, 4.2, 6.06], [1, 4.3, 132.43], [2, 4.6, 2]]}, {"timestamp": 1632571826251, "ltp": 4.2, "tv": 3299.42, "trd": NaN, "batb": [[1, 3.9, 20.68], [2, 3.8, 452.8]], "batl": [[2, 4.6, 9.9]]}, {"timestamp": 1632571827348, "ltp": 4.2, "tv": 3299.42, "trd": NaN, "batb": NaN, "batl": [[2, 4.5, 10]]}, {"timestamp": 1632571827954, "ltp": 4.2, "tv": 3305.42, "trd": [[4.2, 47.63]], "batb": NaN, "batl": [[0, 4.2, 3.06], [1, 4.3, 135.43]]}, {"timestamp": 1632571832340, "ltp": 4.2, "tv": 3305.42, "trd": NaN, "batb": NaN, "batl": [[2, 4.5, 129.62]]}, {"timestamp": 1632571834352, "ltp": 4.2, "tv": 3305.42, "trd": NaN, "batb": [[2, 3.85, 85.14]], "batl": NaN}, {"timestamp": 1632571838377, "ltp": 4.2, "tv": 3305.42, "trd": NaN, "batb": NaN, "batl": [[0, 4.3, 135.43], [1, 4.5, 119.62], [2, 4.6, 131.22]]}, {"timestamp": 1632571841903, "ltp": 4.2, "tv": 3305.42, "trd": NaN, "batb": NaN, "batl": [[0, 4.3, 151.41]]}, {"timestamp": 1632571910017, "ltp": 4.2, "tv": 3305.42, "trd": NaN, "batb": [[0, 3.9, 20.68], [1, 3.4, 216.04], [2, 3.35, 153.64]], "batl": [[0, 4.5, 119.62], [1, 4.6, 131.22], [2, 5.8, 2.54]]}, {"timestamp": 1632571911262, "ltp": 4.2, "tv": 3305.42, "trd": NaN, "batb": [[0, 3.4, 216.04], [1, 3.35, 153.64], [2, 2.62, 386.89]], "batl": [[1, 4.6, 123.32]]}, {"timestamp": 1632571913376, "ltp": 4.2, "tv": 3305.42, "trd": NaN, "batb": [[0, 3.7, 2], [1, 3.55, 2], [2, 3.4, 216.04]], "batl": [[2, 4.9, 2]]}, {"timestamp": 1632571916053, "ltp": 4.2, "tv": 3305.42, "trd": NaN, "batb": [[0, 3.75, 10], [1, 3.7, 2], [2, 3.55, 2]], "batl": [[0, 4.4, 30.9], [1, 4.5, 119.62], [2, 4.6, 123.32]]}, {"timestamp": 1632571918344, "ltp": 4.2, "tv": 3305.42, "trd": NaN, "batb": [[0, 3.55, 2], [1, 3.4, 216.04], [2, 3.35, 153.64]], "batl": [[0, 4.5, 119.62], [1, 4.6, 123.32], [2, 4.9, 2]]}, {"timestamp": 1632571922299, "ltp": 4.2, "tv": 3305.42, "trd": NaN, "batb": [[0, 3.55, 4], [1, 3.5, 3], [2, 3.4, 216.04]], "batl": NaN}, {"timestamp": 1632571925961, "ltp": 4.2, "tv": 3305.42, "trd": NaN, "batb": [[0, 3.6, 3], [1, 3.55, 4], [2, 3.5, 3]], "batl": NaN}, {"timestamp": 1632571929355, "ltp": 4.2, "tv": 3305.42, "trd": NaN, "batb": [[0, 4, 43.5], [1, 3.7, 2], [2, 3.6, 3]], "batl": [[0, 4.4, 43], [1, 4.5, 119.62], [2, 4.6, 123.32]]}, {"timestamp": 1632571930371, "ltp": 4.2, "tv": 3305.42, "trd": NaN, "batb": [[0, 4.3, 2.28], [1, 4, 195.61], [2, 3.65, 96.22]], "batl": [[2, 4.6, 129.84]]}, {"timestamp": 1632571931246, "ltp": 4.2, "tv": 3305.42, "trd": NaN, "batb": [[1, 4.1, 19.35], [2, 4, 195.61]], "batl": NaN}, {"timestamp": 1632571931767, "ltp": 4.2, "tv": 3305.42, "trd": NaN, "batb": NaN, "batl": [[1, 4.5, 134.2]]}, {"timestamp": 1632571936181, "ltp": 4.2, "tv": 3305.42, "trd": NaN, "batb": [[2, 4, 197.61]], "batl": NaN}, {"timestamp": 1632571940339, "ltp": 4.2, "tv": 3305.42, "trd": NaN, "batb": [[0, 4.1, 19.35], [1, 4, 2], [2, 3.9, 2]], "batl": [[0, 4.7, 84.18], [1, 4.8, 124.51], [2, 4.9, 2]]}, {"timestamp": 1632571941374, "ltp": 4.2, "tv": 3305.42, "trd": NaN, "batb": [[0, 4, 2], [1, 3.9, 2], [2, 3.75, 3]], "batl": NaN}, {"timestamp": 1632571941682, "ltp": 4.2, "tv": 3305.42, "trd": NaN, "batb": [[0, 3.9, 2], [1, 3.75, 3], [2, 3.7, 3]], "batl": NaN}, {"timestamp": 1632571944212, "ltp": 4.2, "tv": 3305.42, "trd": NaN, "batb": [[2, 3.65, 211.71]], "batl": NaN}, {"timestamp": 1632571945295, "ltp": 4.2, "tv": 3305.42, "trd": NaN, "batb": [[0, 3.9, 5], [1, 3.85, 2], [2, 3.75, 3]], "batl": NaN}, {"timestamp": 1632571947185, "ltp": 4.2, "tv": 3305.42, "trd": NaN, "batb": NaN, "batl": [[0, 4.6, 2], [1, 4.7, 84.18], [2, 4.8, 124.51]]}, {"timestamp": 1632571947597, "ltp": 4.2, "tv": 3305.42, "trd": NaN, "batb": NaN, "batl": [[0, 4.7, 84.18], [1, 4.8, 124.51], [2, 4.9, 2]]}, {"timestamp": 1632571949622, "ltp": 4.2, "tv": 3305.42, "trd": NaN, "batb": NaN, "batl": [[0, 4.4, 18.89], [1, 4.7, 84.18], [2, 4.8, 124.51]]}, {"timestamp": 1632571951295, "ltp": 4.2, "tv": 3305.42, "trd": NaN, "batb": [[0, 3.95, 19.52], [1, 3.9, 5], [2, 3.85, 2]], "batl": [[0, 4.6, 2]]}, {"timestamp": 1632571952377, "ltp": 4.2, "tv": 3305.42, "trd": NaN, "batb": [[0, 4, 2]], "batl": NaN}, {"timestamp": 1632571952724, "ltp": 4.2, "tv": 3305.42, "trd": NaN, "batb": [[0, 3.9, 5], [1, 3.85, 2], [2, 3.75, 3]], "batl": [[0, 4.7, 84.18], [1, 4.8, 124.51], [2, 4.9, 2]]}, {"timestamp": 1632571956326, "ltp": 4.2, "tv": 3305.42, "trd": NaN, "batb": [[1, 3.65, 211.71], [2, 3.6, 120.35]], "batl": NaN}, {"timestamp": 1632571957197, "ltp": 4.2, "tv": 3305.42, "trd": NaN, "batb": NaN, "batl": [[0, 4.8, 2], [1, 4.9, 2], [2, 5.5, 117.37]]}, {"timestamp": 1632571960166, "ltp": 4.0, "tv": 3322.76, "trd": [[4, 86.29]], "batb": [[0, 3.9, 8.32], [1, 3.65, 473.69], [2, 3.6, 374.63]], "batl": [[0, 4, 54.7], [1, 4.1, 15.3], [2, 4.8, 2]]}, {"timestamp": 1632571961315, "ltp": 4.0, "tv": 3322.76, "trd": NaN, "batb": [[1, 3.7, 22.22], [2, 3.65, 473.69]], "batl": [[2, 4.4, 8.13]]}, {"timestamp": 1632571965116, "ltp": 4.0, "tv": 3322.76, "trd": NaN, "batb": NaN, "batl": [[2, 4.6, 10]]}, {"timestamp": 1632571967102, "ltp": 4.0, "tv": 3322.76, "trd": NaN, "batb": NaN, "batl": [[2, 4.5, 89.13]]}, {"timestamp": 1632571968285, "ltp": 4.0, "tv": 3322.76, "trd": NaN, "batb": NaN, "batl": [[2, 4.3, 8.25]]}, {"timestamp": 1632571971348, "ltp": 4.0, "tv": 3322.76, "trd": NaN, "batb": [[0, 3.9, 2], [2, 3.65, 211.71]], "batl": [[0, 4.3, 8.25], [1, 4.5, 89.13], [2, 4.6, 129.31]]}, {"timestamp": 1632571971818, "ltp": 4.0, "tv": 3322.76, "trd": NaN, "batb": [[0, 3.7, 22.22], [1, 3.35, 2.04], [2, 3.2, 125.47]], "batl": [[2, 4.6, 119.31]]}, {"timestamp": 1632571973320, "ltp": 4.0, "tv": 3322.76, "trd": NaN, "batb": [[0, 3.35, 2.04], [1, 3.2, 125.47], [2, 3.15, 136.38]], "batl": [[0, 4.5, 89.13], [1, 4.6, 119.31], [2, 4.8, 2]]}, {"timestamp": 1632571975323, "ltp": 4.0, "tv": 3322.76, "trd": NaN, "batb": [[2, 3.15, 275.97]], "batl": NaN}, {"timestamp": 1632571977026, "ltp": 4.0, "tv": 3325.1, "trd": [[4, 88.63]], "batb": NaN, "batl": NaN}, {"timestamp": 1632571978191, "ltp": 4.0, "tv": 3325.1, "trd": NaN, "batb": [[0, 3.4, 10.2], [1, 3.35, 2.04], [2, 3.2, 125.47]], "batl": [[0, 4.4, 46.6], [1, 4.5, 89.13], [2, 4.6, 119.31]]}, {"timestamp": 1632571981030, "ltp": 4.0, "tv": 3325.1, "trd": NaN, "batb": [[0, 3.35, 2.04], [1, 3.2, 125.47], [2, 3.15, 275.97]], "batl": [[0, 4.5, 89.13], [1, 4.6, 119.31], [2, 4.8, 2]]}, {"timestamp": 1632571981919, "ltp": 4.0, "tv": 3325.1, "trd": NaN, "batb": [[0, 3.2, 125.47], [1, 3.15, 275.97], [2, 2.62, 386.89]], "batl": NaN}, {"timestamp": 1632571985221, "ltp": 4.0, "tv": 3325.1, "trd": NaN, "batb": [[0, 3.35, 2.07], [1, 3.2, 128.47], [2, 3.15, 278.97]], "batl": NaN}, {"timestamp": 1632571985433, "ltp": 4.0, "tv": 3325.1, "trd": NaN, "batb": [[0, 3.2, 128.47], [1, 3.15, 278.97], [2, 2.62, 386.89]], "batl": NaN}, {"timestamp": 1632571987493, "ltp": 4.0, "tv": 3325.1, "trd": NaN, "batb": [[0, 3.2, 5.02], [1, 3.15, 142.59]], "batl": NaN}, {"timestamp": 1632571989008, "ltp": 4.0, "tv": 3325.1, "trd": NaN, "batb": [[0, 3.25, 3], [1, 3.2, 5.02], [2, 3.15, 142.59]], "batl": NaN}, {"timestamp": 1632571990316, "ltp": 4.0, "tv": 3325.1, "trd": NaN, "batb": [[0, 3.9, 1043.93], [1, 3.85, 951.92], [2, 3.8, 951.92]], "batl": [[0, 4.4, 61.7], [1, 4.5, 89.13], [2, 4.6, 119.31]]}, {"timestamp": 1632571991231, "ltp": 4.0, "tv": 3325.1, "trd": NaN, "batb": [[0, 3.9, 470.01], [1, 3.85, 237.98], [2, 3.8, 237.98]], "batl": [[0, 4.4, 78.87], [1, 4.5, 95.8]]}, {"timestamp": 1632571992329, "ltp": 4.0, "tv": 3325.1, "trd": NaN, "batb": [[0, 3.95, 20.33], [1, 3.9, 470.01], [2, 3.85, 237.98]], "batl": [[2, 4.6, 127.21]]}, {"timestamp": 1632571995341, "ltp": 4.0, "tv": 3325.1, "trd": NaN, "batb": [[0, 3.95, 45.43]], "batl": NaN}, {"timestamp": 1632571997250, "ltp": 4.0, "tv": 3325.1, "trd": NaN, "batb": [[0, 3.95, 80.61], [2, 3.85, 239.98]], "batl": [[2, 4.6, 129.21]]}, {"timestamp": 1632571997561, "ltp": 4.0, "tv": 3325.1, "trd": NaN, "batb": NaN, "batl": [[2, 4.6, 238.59]]}, {"timestamp": 1632572003457, "ltp": 4.0, "tv": 3325.1, "trd": NaN, "batb": [[0, 3.95, 45.43]], "batl": NaN}, {"timestamp": 1632572014978, "ltp": 4.0, "tv": 3325.1, "trd": NaN, "batb": [[0, 3.95, 20.33], [1, 3.85, 2], [2, 3.75, 2.03]], "batl": [[0, 4.6, 119.28], [1, 4.7, 108.86], [2, 4.8, 2]]}, {"timestamp": 1632572016239, "ltp": 4.0, "tv": 3325.1, "trd": NaN, "batb": [[0, 3.85, 2], [1, 3.75, 2.03], [2, 3.7, 2]], "batl": [[0, 4.6, 111.38]]}, {"timestamp": 1632572016463, "ltp": 4.0, "tv": 3325.1, "trd": NaN, "batb": [[0, 3.7, 2], [1, 3.5, 209.89], [2, 3.45, 115.6]], "batl": NaN}, {"timestamp": 1632572020046, "ltp": 4.0, "tv": 3325.1, "trd": NaN, "batb": [[0, 3.7, 5], [1, 3.65, 3], [2, 3.5, 209.89]], "batl": NaN}, {"timestamp": 1632572022057, "ltp": 4.0, "tv": 3325.1, "trd": NaN, "batb": NaN, "batl": [[0, 4.3, 21.55], [1, 4.6, 111.38], [2, 4.7, 108.86]]}, {"timestamp": 1632572023254, "ltp": 4.0, "tv": 3325.1, "trd": NaN, "batb": [[0, 3.85, 2], [1, 3.7, 5], [2, 3.65, 3]], "batl": [[0, 4.6, 111.38], [1, 4.7, 108.86], [2, 4.8, 2]]}, {"timestamp": 1632572025886, "ltp": 4.0, "tv": 3325.1, "trd": NaN, "batb": [[0, 3.7, 5], [1, 3.65, 3], [2, 3.5, 209.89]], "batl": NaN}, {"timestamp": 1632572028295, "ltp": 4.0, "tv": 3325.1, "trd": NaN, "batb": [[2, 3.5, 107.55]], "batl": NaN}, {"timestamp": 1632572029381, "ltp": 4.0, "tv": 3325.1, "trd": NaN, "batb": [[0, 3.75, 3], [1, 3.7, 5], [2, 3.65, 3]], "batl": NaN}, {"timestamp": 1632572031312, "ltp": 4.0, "tv": 3325.1, "trd": NaN, "batb": [[0, 4.4, 6.18], [1, 3.75, 3], [2, 3.7, 2]], "batl": [[1, 4.7, 177.78], [2, 4.8, 500.05]]}, {"timestamp": 1632572032314, "ltp": 4.0, "tv": 3325.1, "trd": NaN, "batb": [[1, 4.1, 143.65], [2, 3.8, 86.24]], "batl": [[2, 4.8, 201.22]]}, {"timestamp": 1632572033375, "ltp": 4.0, "tv": 3325.1, "trd": NaN, "batb": [[2, 4, 20]], "batl": NaN}, {"timestamp": 1632572034171, "ltp": 4.0, "tv": 3325.1, "trd": NaN, "batb": [[2, 4, 23]], "batl": [[0, 4.6, 126.7]]}, {"timestamp": 1632572036286, "ltp": 4.0, "tv": 3325.1, "trd": NaN, "batb": [[2, 4, 3]], "batl": NaN}, {"timestamp": 1632572038343, "ltp": 4.0, "tv": 3325.1, "trd": NaN, "batb": [[1, 4.2, 2], [2, 4.1, 145.65]], "batl": [[1, 4.7, 281.09], [2, 4.8, 317.3]]}, {"timestamp": 1632572039812, "ltp": 4.0, "tv": 3325.1, "trd": NaN, "batb": [[2, 4.1, 165]], "batl": NaN}, {"timestamp": 1632572041315, "ltp": 4.0, "tv": 3325.1, "trd": NaN, "batb": [[0, 4.2, 2], [1, 4.1, 165], [2, 4, 3]], "batl": [[1, 4.7, 212.17], [2, 4.8, 118.08]]}, {"timestamp": 1632572042016, "ltp": 4.0, "tv": 3325.1, "trd": NaN, "batb": [[1, 4.1, 21.35]], "batl": [[0, 4.7, 103.31], [1, 4.8, 118.08], [2, 4.9, 9.59]]}, {"timestamp": 1632572043313, "ltp": 4.0, "tv": 3325.1, "trd": NaN, "batb": [[0, 4.1, 2], [1, 4, 3], [2, 3.95, 3]], "batl": [[2, 4.9, 2]]}, {"timestamp": 1632572045327, "ltp": 4.0, "tv": 3325.1, "trd": NaN, "batb": NaN, "batl": [[0, 4.6, 2], [1, 4.7, 106.31], [2, 4.8, 118.08]]}, {"timestamp": 1632572046233, "ltp": 4.0, "tv": 3325.1, "trd": NaN, "batb": [[0, 4.2, 3], [1, 4.1, 5], [2, 4, 3]], "batl": [[0, 4.7, 106.31], [1, 4.8, 118.08], [2, 4.9, 2]]}, {"timestamp": 1632572048033, "ltp": 4.0, "tv": 3325.1, "trd": NaN, "batb": [[0, 4.1, 5], [1, 4, 3], [2, 3.8, 86.24]], "batl": NaN}, {"timestamp": 1632572050375, "ltp": 4.0, "tv": 3325.1, "trd": NaN, "batb": [[0, 4.2, 2], [1, 4.1, 5], [2, 4, 3]], "batl": [[1, 4.8, 167.55]]}, {"timestamp": 1632572051352, "ltp": 4.0, "tv": 3325.1, "trd": NaN, "batb": [[0, 4.2, 133.9], [2, 4, 153.92]], "batl": NaN}, {"timestamp": 1632572052347, "ltp": 4.0, "tv": 3325.1, "trd": NaN, "batb": [[0, 4.3, 18.18], [1, 4.2, 153.11], [2, 4.1, 5]], "batl": [[0, 4.7, 119.94]]}, {"timestamp": 1632572053146, "ltp": 4.0, "tv": 3325.1, "trd": NaN, "batb": [[0, 4.2, 153.11], [1, 4.1, 5], [2, 4, 153.92]], "batl": NaN}, {"timestamp": 1632572055869, "ltp": 4.0, "tv": 3325.1, "trd": NaN, "batb": [[0, 4.3, 18.18], [1, 4.2, 153.11], [2, 4.1, 5]], "batl": NaN}, {"timestamp": 1632572068919, "ltp": 4.0, "tv": 3325.1, "trd": NaN, "batb": [[1, 4.2, 133.9]], "batl": NaN}, {"timestamp": 1632572071310, "ltp": 4.0, "tv": 3325.1, "trd": NaN, "batb": NaN, "batl": [[1, 4.8, 161.36]]}, {"timestamp": 1632572072003, "ltp": 4.0, "tv": 3325.1, "trd": NaN, "batb": [[0, 4.3, 37.39]], "batl": NaN}, {"timestamp": 1632572074313, "ltp": 4.0, "tv": 3325.1, "trd": NaN, "batb": [[0, 4.5, 3.71], [1, 4.3, 37.39], [2, 4.2, 133.9]], "batl": [[0, 4.7, 126.23]]}, {"timestamp": 1632572076253, "ltp": 4.0, "tv": 3325.1, "trd": NaN, "batb": [[0, 4.3, 18.18], [1, 4.2, 133.9], [2, 4.1, 2]], "batl": [[0, 5.1, 7.4], [1, 5.6, 101.45], [2, 5.7, 81.75]]}, {"timestamp": 1632572077348, "ltp": 4.0, "tv": 3325.1, "trd": NaN, "batb": [[0, 4.2, 2], [1, 4.1, 2], [2, 4, 152.92]], "batl": [[0, 5.6, 101.45], [1, 5.7, 81.75], [2, 5.8, 4.54]]}, {"timestamp": 1632572077906, "ltp": 4.0, "tv": 3325.1, "trd": NaN, "batb": [[0, 4.1, 2], [1, 4, 150.92], [2, 3.85, 122.85]], "batl": NaN}, {"timestamp": 1632572079339, "ltp": 4.0, "tv": 3325.1, "trd": NaN, "batb": NaN, "batl": [[0, 5.4, 2], [1, 5.6, 101.45], [2, 5.7, 81.75]]}, {"timestamp": 1632572081225, "ltp": 4.0, "tv": 3325.1, "trd": NaN, "batb": [[0, 4.2, 2], [1, 4.1, 2], [2, 4, 150.92]], "batl": [[0, 5.6, 99.45], [1, 5.7, 81.75], [2, 5.8, 4.54]]}, {"timestamp": 1632572082216, "ltp": 4.0, "tv": 3325.1, "trd": NaN, "batb": [[0, 4.2, 12]], "batl": [[0, 5.5, 37.45], [1, 5.6, 99.45], [2, 5.7, 81.75]]}, {"timestamp": 1632572083336, "ltp": 4.0, "tv": 3325.1, "trd": NaN, "batb": [[0, 4.2, 2]], "batl": [[0, 5.4, 3], [1, 5.5, 37.45], [2, 5.6, 99.45]]}, {"timestamp": 1632572083613, "ltp": 4.0, "tv": 3325.1, "trd": NaN, "batb": NaN, "batl": [[0, 5.4, 5], [1, 5.6, 101.45], [2, 5.7, 81.75]]}, {"timestamp": 1632572086067, "ltp": 4.0, "tv": 3325.1, "trd": NaN, "batb": [[0, 4.3, 10], [1, 4.2, 2], [2, 4.1, 2]], "batl": NaN}, {"timestamp": 1632572086939, "ltp": 4.0, "tv": 3325.1, "trd": NaN, "batb": [[0, 4.2, 2], [1, 4.1, 2], [2, 4, 150.92]], "batl": [[0, 5.4, 3]]}, {"timestamp": 1632572087906, "ltp": 4.0, "tv": 3325.1, "trd": NaN, "batb": [[0, 4.1, 2], [1, 4, 150.92], [2, 3.85, 122.85]], "batl": NaN}, {"timestamp": 1632572090337, "ltp": 4.0, "tv": 3325.1, "trd": NaN, "batb": NaN, "batl": [[0, 5.3, 3], [1, 5.4, 3], [2, 5.6, 101.45]]}, {"timestamp": 1632572091336, "ltp": 4.0, "tv": 3325.1, "trd": NaN, "batb": [[0, 4.2, 2], [1, 4.1, 2], [2, 4, 150.92]], "batl": [[2, 5.6, 2]]}, {"timestamp": 1632572091552, "ltp": 4.0, "tv": 3325.1, "trd": NaN, "batb": [[0, 4.1, 2], [1, 4, 150.92], [2, 3.85, 122.85]], "batl": NaN}, {"timestamp": 1632572094346, "ltp": 4.0, "tv": 3325.1, "trd": NaN, "batb": [[0, 4.1, 5], [1, 4, 750.58], [2, 3.95, 232.02]], "batl": [[0, 4.3, 6.42], [1, 4.6, 6.52], [2, 4.7, 134.67]]}, {"timestamp": 1632572095362, "ltp": 4.0, "tv": 3325.1, "trd": NaN, "batb": [[0, 4.1, 2], [1, 4, 389.98]], "batl": NaN}, {"timestamp": 1632572096365, "ltp": 4.0, "tv": 3325.1, "trd": NaN, "batb": [[1, 4, 409.98]], "batl": [[2, 4.7, 142.46]]}, {"timestamp": 1632572101251, "ltp": 4.0, "tv": 3325.1, "trd": NaN, "batb": [[1, 4, 411.98]], "batl": NaN}, {"timestamp": 1632572104359, "ltp": 4.0, "tv": 3325.1, "trd": NaN, "batb": [[1, 4, 172.92], [2, 3.9, 2]], "batl": [[0, 4.7, 7.79], [1, 4.8, 2], [2, 5, 90.51]]}, {"timestamp": 1632572104752, "ltp": 4.0, "tv": 3325.1, "trd": NaN, "batb": [[1, 4, 22]], "batl": NaN}, {"timestamp": 1632572106284, "ltp": 4.0, "tv": 3325.1, "trd": NaN, "batb": [[0, 4, 2], [1, 3.9, 2], [2, 3.85, 169.19]], "batl": [[0, 4.8, 2], [1, 5, 90.51], [2, 5.1, 100.66]]}, {"timestamp": 1632572106671, "ltp": 4.0, "tv": 3325.1, "trd": NaN, "batb": [[1, 3.85, 169.19], [2, 3.75, 118.33]], "batl": [[0, 5, 90.51], [1, 5.1, 100.66], [2, 5.2, 2]]}, {"timestamp": 1632572109259, "ltp": 4.0, "tv": 3325.1, "trd": NaN, "batb": NaN, "batl": [[0, 4.1, 3.52], [1, 5, 90.51], [2, 5.1, 100.66]]}, {"timestamp": 1632572110188, "ltp": 4.1, "tv": 3330.62, "trd": [[4.1, 121.3]], "batb": NaN, "batl": [[0, 4.7, 3], [1, 4.8, 2], [2, 4.9, 3]]}, {"timestamp": 1632572115178, "ltp": 4.0, "tv": 3336.84, "trd": [[4, 94.85]], "batb": [[0, 3.85, 169.19], [1, 3.8, 251.64], [2, 3.75, 415.85]], "batl": [[0, 4.3, 8.98], [1, 4.7, 3], [2, 4.8, 2]]}, {"timestamp": 1632572116285, "ltp": 4.0, "tv": 3336.84, "trd": NaN, "batb": [[0, 3.85, 190.24], [2, 3.75, 506.41]], "batl": [[1, 4.5, 8.01], [2, 4.7, 3]]}, {"timestamp": 1632572117872, "ltp": 4.0, "tv": 3336.84, "trd": NaN, "batb": [[0, 3.85, 206.62]], "batl": [[0, 4.2, 2], [1, 4.3, 8.98], [2, 4.5, 8.01]]}, {"timestamp": 1632572120573, "ltp": 4.0, "tv": 3336.84, "trd": NaN, "batb": NaN, "batl": [[0, 4.2, 17]]}, {"timestamp": 1632572121875, "ltp": 4.0, "tv": 3336.84, "trd": NaN, "batb": [[0, 3.9, 2], [1, 3.85, 208.62], [2, 3.8, 251.64]], "batl": [[2, 4.4, 2]]}, {"timestamp": 1632572128102, "ltp": 4.0, "tv": 3336.84, "trd": NaN, "batb": [[1, 3.85, 23.05], [2, 3.75, 90.55]], "batl": [[0, 4.4, 2], [1, 4.5, 120.76], [2, 4.6, 118.61]]}, {"timestamp": 1632572129300, "ltp": 4.0, "tv": 3336.84, "trd": NaN, "batb": [[0, 3.85, 2], [1, 3.75, 90.55], [2, 3.6, 114.67]], "batl": [[0, 4.5, 112.75], [1, 4.6, 118.61], [2, 5, 2]]}, {"timestamp": 1632572131168, "ltp": 4.0, "tv": 3336.84, "trd": NaN, "batb": NaN, "batl": [[0, 4.4, 3], [1, 4.5, 112.75], [2, 4.6, 118.61]]}, {"timestamp": 1632572132303, "ltp": 4.0, "tv": 3336.84, "trd": NaN, "batb": [[0, 3.9, 2], [1, 3.85, 2], [2, 3.75, 90.55]], "batl": [[0, 4.5, 4], [1, 4.6, 3], [2, 5, 2]]}, {"timestamp": 1632572132688, "ltp": 4.0, "tv": 3336.84, "trd": NaN, "batb": [[0, 3.85, 2], [1, 3.75, 90.55], [2, 3.6, 114.67]], "batl": NaN}, {"timestamp": 1632572135313, "ltp": 4.0, "tv": 3336.84, "trd": NaN, "batb": [[0, 3.85, 4], [1, 3.8, 3], [2, 3.75, 90.55]], "batl": [[0, 4.1, 449.58], [1, 4.2, 179.09], [2, 4.3, 174.8]]}, {"timestamp": 1632572136288, "ltp": 4.0, "tv": 3336.84, "trd": NaN, "batb": [[0, 3.85, 2], [1, 3.75, 112.36], [2, 3.7, 94.11]], "batl": [[0, 4.1, 220.32], [1, 4.2, 64.46], [2, 4.3, 60.17]]}, {"timestamp": 1632572140320, "ltp": 4.0, "tv": 3336.84, "trd": NaN, "batb": NaN, "batl": [[0, 4.1, 240.32]]}, {"timestamp": 1632572142301, "ltp": 4.0, "tv": 3336.84, "trd": NaN, "batb": [[1, 3.75, 114.36]], "batl": [[0, 4.1, 369.46], [1, 4.2, 163.6]]}, {"timestamp": 1632572145292, "ltp": 4.0, "tv": 3336.84, "trd": NaN, "batb": [[1, 3.75, 23.81]], "batl": [[0, 4.1, 129.14], [1, 4.2, 99.14], [2, 4.4, 10.13]]}, {"timestamp": 1632572146313, "ltp": 4.0, "tv": 3336.84, "trd": NaN, "batb": [[0, 3.75, 2], [1, 3.7, 94.11], [2, 3.6, 103.73]], "batl": [[2, 4.4, 2]]}, {"timestamp": 1632572148999, "ltp": 4.0, "tv": 3336.84, "trd": NaN, "batb": NaN, "batl": [[0, 4.5, 4], [1, 5.5, 117.37], [2, 5.8, 2.54]]}, {"timestamp": 1632572149797, "ltp": 4.0, "tv": 3336.84, "trd": NaN, "batb": [[0, 3.75, 5], [1, 3.7, 97.11]], "batl": NaN}, {"timestamp": 1632572151927, "ltp": 3.9, "tv": 3336.85, "trd": [[3.9, 0.01]], "batb": NaN, "batl": [[0, 3.85, 44.84], [1, 4, 117.5], [2, 4.1, 66.08]]}, {"timestamp": 1632572153362, "ltp": 3.9, "tv": 3336.85, "trd": NaN, "batb": [[2, 3.65, 22.64]], "batl": NaN}, {"timestamp": 1632572153637, "ltp": 3.9, "tv": 3336.85, "trd": NaN, "batb": [[0, 3.75, 2], [1, 3.7, 94.11]], "batl": NaN}, {"timestamp": 1632572155732, "ltp": 3.85, "tv": 3361.54, "trd": [[3.85, 24.69]], "batb": NaN, "batl": [[0, 3.85, 20.15]]}, {"timestamp": 1632572160933, "ltp": 3.85, "tv": 3361.54, "trd": NaN, "batb": [[1, 3.65, 116.91], [2, 3.6, 103.73]], "batl": NaN}, {"timestamp": 1632572166543, "ltp": 3.85, "tv": 3361.54, "trd": NaN, "batb": [[0, 3.75, 111.71]], "batl": NaN}, {"timestamp": 1632572173671, "ltp": 3.85, "tv": 3368.75, "trd": [[3.85, 31.9]], "batb": NaN, "batl": [[0, 3.85, 12.94]]}, {"timestamp": 1632572178760, "ltp": 3.85, "tv": 3375.96, "trd": [[3.85, 39.11]], "batb": NaN, "batl": [[0, 3.85, 5.73]]}, {"timestamp": 1632572182204, "ltp": 3.85, "tv": 3375.96, "trd": NaN, "batb": [[1, 3.7, 93.51], [2, 3.65, 22.64]], "batl": NaN}, {"timestamp": 1632572189196, "ltp": 3.85, "tv": 3375.96, "trd": NaN, "batb": NaN, "batl": [[0, 4, 117.5], [1, 4.1, 66.08], [2, 4.2, 61.64]]}, {"timestamp": 1632572192299, "ltp": 3.85, "tv": 3375.96, "trd": NaN, "batb": NaN, "batl": [[0, 3.85, 5.73], [1, 4, 137.5], [2, 4.1, 66.08]]}, {"timestamp": 1632572239871, "ltp": 3.85, "tv": 3375.96, "trd": NaN, "batb": [[0, 3.65, 22.64], [1, 3.2, 131.9], [2, 3.15, 145.38]], "batl": [[0, 4.3, 122.66], [1, 4.4, 138.6], [2, 4.5, 4]]}, {"timestamp": 1632572241253, "ltp": 3.85, "tv": 3375.96, "trd": NaN, "batb": [[0, 3.2, 131.9], [1, 3.15, 145.38], [2, 3.1, 145.33]], "batl": [[0, 4.3, 114.41]]}, {"timestamp": 1632572242162, "ltp": 3.85, "tv": 3375.96, "trd": NaN, "batb": [[0, 3.35, 2], [1, 3.25, 2.13], [2, 3.2, 131.9]], "batl": [[0, 4.3, 116.41]]}, {"timestamp": 1632572242547, "ltp": 3.85, "tv": 3375.96, "trd": NaN, "batb": [[0, 3.25, 2.13], [1, 3.2, 131.9], [2, 3.15, 145.38]], "batl": [[0, 4.3, 114.41]]}, {"timestamp": 1632572244281, "ltp": 3.85, "tv": 3375.96, "trd": NaN, "batb": NaN, "batl": [[0, 4.3, 117.41]]}, {"timestamp": 1632572244553, "ltp": 3.85, "tv": 3375.96, "trd": NaN, "batb": [[1, 3.2, 133.9], [2, 3.15, 148.38]], "batl": NaN}, {"timestamp": 1632572246063, "ltp": 3.85, "tv": 3375.96, "trd": NaN, "batb": [[0, 3.3, 3], [1, 3.25, 5.13], [2, 3.2, 133.9]], "batl": [[0, 4.3, 119.41]]}, {"timestamp": 1632572247585, "ltp": 3.85, "tv": 3375.96, "trd": NaN, "batb": [[0, 3.35, 3], [1, 3.3, 3], [2, 3.25, 5.13]], "batl": [[0, 4.2, 3], [1, 4.3, 119.41], [2, 4.4, 138.6]]}, {"timestamp": 1632572249261, "ltp": 3.85, "tv": 3375.96, "trd": NaN, "batb": [[0, 3.4, 3], [1, 3.35, 5.07], [2, 3.3, 3]], "batl": NaN}, {"timestamp": 1632572249683, "ltp": 3.85, "tv": 3375.96, "trd": NaN, "batb": [[1, 3.35, 3]], "batl": NaN}, {"timestamp": 1632572250873, "ltp": 3.85, "tv": 3375.96, "trd": NaN, "batb": NaN, "batl": [[0, 4.1, 3], [1, 4.2, 3], [2, 4.3, 119.41]]}, {"timestamp": 1632572252076, "ltp": 3.85, "tv": 3375.96, "trd": NaN, "batb": [[0, 3.45, 3], [1, 3.4, 3], [2, 3.35, 3]], "batl": NaN}, {"timestamp": 1632572254166, "ltp": 3.85, "tv": 3375.96, "trd": NaN, "batb": NaN, "batl": [[0, 4, 3]]}, {"timestamp": 1632572254674, "ltp": 3.85, "tv": 3375.96, "trd": NaN, "batb": NaN, "batl": [[0, 4.2, 3], [1, 4.3, 119.41], [2, 4.4, 138.6]]}, {"timestamp": 1632572256669, "ltp": 3.85, "tv": 3375.96, "trd": NaN, "batb": NaN, "batl": [[1, 4.3, 116.41]]}, {"timestamp": 1632572260288, "ltp": 3.85, "tv": 3375.96, "trd": NaN, "batb": [[2, 3.25, 2.13]], "batl": NaN}, {"timestamp": 1632572262272, "ltp": 3.85, "tv": 3375.96, "trd": NaN, "batb": NaN, "batl": [[1, 4.5, 2], [2, 5.5, 117.37]]}, {"timestamp": 1632572263906, "ltp": 3.85, "tv": 3375.96, "trd": NaN, "batb": [[0, 3.25, 2.13], [1, 3.2, 131.9], [2, 3.15, 145.38]], "batl": [[2, 5.8, 2.54]]}, {"timestamp": 1632572265267, "ltp": 3.85, "tv": 3375.96, "trd": NaN, "batb": NaN, "batl": [[0, 3.55, 8.45], [1, 3.65, 3.5], [2, 3.9, 285.38]]}, {"timestamp": 1632572266280, "ltp": 3.85, "tv": 3375.96, "trd": NaN, "batb": [[1, 3.2, 159.17]], "batl": [[2, 3.75, 9.04]]}, {"timestamp": 1632572267947, "ltp": 3.85, "tv": 3375.96, "trd": NaN, "batb": NaN, "batl": [[0, 3.45, 9.39], [1, 3.5, 2], [2, 3.55, 8.45]]}, {"timestamp": 1632572270357, "ltp": 3.85, "tv": 3375.96, "trd": NaN, "batb": NaN, "batl": [[1, 3.5, 18.25]]}, {"timestamp": 1632572278333, "ltp": 3.85, "tv": 3375.96, "trd": NaN, "batb": NaN, "batl": [[2, 3.65, 3.5]]}, {"timestamp": 1632572279246, "ltp": 3.45, "tv": 3376.92, "trd": [[3.45, 0.95]], "batb": [[0, 3.2, 27.27], [1, 2.8, 136.81], [2, 2.78, 145.05]], "batl": [[0, 3.45, 8.44], [1, 3.9, 2], [2, 3.95, 104.71]]}, {"timestamp": 1632572280271, "ltp": 3.45, "tv": 3376.92, "trd": NaN, "batb": [[0, 2.8, 136.81], [1, 2.78, 145.05], [2, 2.68, 83.79]], "batl": NaN}, {"timestamp": 1632572281965, "ltp": 3.45, "tv": 3376.92, "trd": NaN, "batb": [[1, 2.78, 147.71], [2, 2.74, 2.29]], "batl": NaN}, {"timestamp": 1632572282948, "ltp": 3.45, "tv": 3376.92, "trd": NaN, "batb": [[0, 2.78, 2.66], [1, 2.74, 2.29], [2, 2.68, 83.79]], "batl": NaN}, {"timestamp": 1632572286079, "ltp": 3.45, "tv": 3385.36, "trd": [[3.45, 9.39]], "batb": [[0, 3.25, 198.53], [1, 2.78, 2.66], [2, 2.74, 2.29]], "batl": [[0, 3.75, 4.77], [1, 3.85, 63.32], [2, 3.9, 2]]}, {"timestamp": 1632572287370, "ltp": 3.45, "tv": 3385.36, "trd": NaN, "batb": [[0, 3.45, 109.41], [1, 3.25, 198.53], [2, 2.94, 165.55]], "batl": [[2, 3.9, 9.69]]}, {"timestamp": 1632572289042, "ltp": 3.45, "tv": 3385.36, "trd": NaN, "batb": [[0, 3.45, 133.89], [1, 3.3, 3], [2, 3.25, 201.53]], "batl": NaN}, {"timestamp": 1632572291144, "ltp": 3.45, "tv": 3385.36, "trd": NaN, "batb": [[0, 3.5, 17.59], [1, 3.45, 133.89], [2, 3.3, 3]], "batl": NaN}, {"timestamp": 1632572296157, "ltp": 3.45, "tv": 3385.36, "trd": NaN, "batb": [[1, 3.45, 109.41]], "batl": NaN}, {"timestamp": 1632572299367, "ltp": 3.45, "tv": 3385.36, "trd": NaN, "batb": [[0, 3.5, 24]], "batl": [[0, 3.9, 2], [1, 3.95, 104.71], [2, 4, 102.76]]}, {"timestamp": 1632572300067, "ltp": 3.45, "tv": 3385.36, "trd": NaN, "batb": [[1, 3.1, 2.04], [2, 3, 141.43]], "batl": [[0, 4.1, 8.51], [1, 4.2, 125.21], [2, 4.3, 106.77]]}, {"timestamp": 1632572301307, "ltp": 3.45, "tv": 3385.36, "trd": NaN, "batb": [[0, 3.1, 2.04], [1, 3, 141.43], [2, 2.98, 167.46]], "batl": [[0, 4.2, 125.21], [1, 4.3, 106.77], [2, 4.5, 2]]}, {"timestamp": 1632572303381, "ltp": 3.45, "tv": 3385.36, "trd": NaN, "batb": NaN, "batl": [[0, 4.1, 4], [1, 4.2, 125.21], [2, 4.3, 106.77]]}, {"timestamp": 1632572303584, "ltp": 3.45, "tv": 3385.36, "trd": NaN, "batb": NaN, "batl": [[0, 4.1, 2]]}, {"timestamp": 1632572304495, "ltp": 3.45, "tv": 3385.36, "trd": NaN, "batb": NaN, "batl": [[1, 4.2, 127.21]]}, {"timestamp": 1632572306775, "ltp": 3.45, "tv": 3385.36, "trd": NaN, "batb": NaN, "batl": [[0, 4.1, 4]]}, {"timestamp": 1632572308973, "ltp": 3.45, "tv": 3385.36, "trd": NaN, "batb": NaN, "batl": [[0, 4.1, 2]]}, {"timestamp": 1632572309992, "ltp": 3.45, "tv": 3385.36, "trd": NaN, "batb": [[0, 3.15, 3], [1, 3.1, 4.04], [2, 3, 141.43]], "batl": [[0, 4, 2], [1, 4.1, 2], [2, 4.2, 127.21]]}, {"timestamp": 1632572310795, "ltp": 3.45, "tv": 3385.36, "trd": NaN, "batb": [[1, 3.1, 2]], "batl": NaN}, {"timestamp": 1632572312275, "ltp": 3.45, "tv": 3385.36, "trd": NaN, "batb": NaN, "batl": [[1, 4.1, 4]]}, {"timestamp": 1632572313190, "ltp": 3.45, "tv": 3385.36, "trd": NaN, "batb": [[0, 3.2, 2], [1, 3.15, 3], [2, 3.1, 2]], "batl": [[0, 3.85, 3], [1, 3.95, 3], [2, 4, 2]]}, {"timestamp": 1632572316395, "ltp": 3.45, "tv": 3385.36, "trd": NaN, "batb": [[0, 3.25, 3], [1, 3.2, 2], [2, 3.15, 3]], "batl": [[0, 3.8, 2], [1, 3.85, 3], [2, 3.95, 3]]}, {"timestamp": 1632572317900, "ltp": 3.45, "tv": 3385.36, "trd": NaN, "batb": [[0, 3, 141.43], [1, 2.98, 167.46], [2, 2.96, 2.13]], "batl": [[0, 4.2, 125.21], [1, 4.3, 106.77], [2, 4.5, 2]]}, {"timestamp": 1632572319339, "ltp": 3.45, "tv": 3385.36, "trd": NaN, "batb": NaN, "batl": [[0, 4.1, 2], [1, 4.2, 125.21], [2, 4.3, 106.77]]}, {"timestamp": 1632572320041, "ltp": 3.45, "tv": 3385.36, "trd": NaN, "batb": NaN, "batl": [[0, 4.2, 125.21], [1, 4.3, 106.77], [2, 4.5, 2]]}, {"timestamp": 1632572321185, "ltp": 3.45, "tv": 3385.36, "trd": NaN, "batb": [[0, 3.1, 2.04], [1, 3, 141.43], [2, 2.98, 167.46]], "batl": [[0, 4.2, 128.21]]}, {"timestamp": 1632572321516, "ltp": 3.45, "tv": 3385.36, "trd": NaN, "batb": [[0, 3, 141.43], [1, 2.98, 167.46], [2, 2.96, 2.13]], "batl": NaN}, {"timestamp": 1632572323218, "ltp": 3.45, "tv": 3385.36, "trd": NaN, "batb": NaN, "batl": [[0, 3.65, 18.9], [1, 4.1, 5], [2, 4.2, 128.21]]}, {"timestamp": 1632572323434, "ltp": 3.45, "tv": 3385.36, "trd": NaN, "batb": NaN, "batl": [[0, 4.1, 5], [1, 4.2, 128.21], [2, 4.3, 106.77]]}, {"timestamp": 1632572324945, "ltp": 3.45, "tv": 3385.36, "trd": NaN, "batb": [[0, 3.1, 2.04], [1, 3, 141.43], [2, 2.98, 167.46]], "batl": NaN}, {"timestamp": 1632572328339, "ltp": 3.45, "tv": 3385.36, "trd": NaN, "batb": NaN, "batl": [[0, 4.1, 3]]}, {"timestamp": 1632572328716, "ltp": 3.45, "tv": 3385.36, "trd": NaN, "batb": [[0, 3, 141.43], [1, 2.98, 167.46], [2, 2.96, 2.13]], "batl": NaN}, {"timestamp": 1632572335324, "ltp": 3.45, "tv": 3385.36, "trd": NaN, "batb": [[0, 3.15, 2], [1, 3.1, 3], [2, 3.05, 3]], "batl": [[0, 4, 3], [1, 4.1, 2], [2, 4.2, 125.21]]}, {"timestamp": 1632572335552, "ltp": 3.45, "tv": 3385.36, "trd": NaN, "batb": [[0, 3.1, 3], [1, 3.05, 3], [2, 3, 144.43]], "batl": [[1, 4.2, 125.21], [2, 4.3, 106.77]]}, {"timestamp": 1632572338032, "ltp": 3.45, "tv": 3385.36, "trd": NaN, "batb": NaN, "batl": [[0, 3.85, 3], [1, 3.95, 3], [2, 4, 3]]}, {"timestamp": 1632572340237, "ltp": 3.45, "tv": 3385.36, "trd": NaN, "batb": [[0, 3.1, 5.04]], "batl": NaN}, {"timestamp": 1632572341261, "ltp": 3.45, "tv": 3385.36, "trd": NaN, "batb": [[0, 3.1, 3]], "batl": [[0, 3.8, 3], [1, 3.85, 3], [2, 3.95, 3]]}, {"timestamp": 1632572342239, "ltp": 3.45, "tv": 3385.36, "trd": NaN, "batb": [[0, 3, 141.43], [1, 2.98, 167.46], [2, 2.96, 2.13]], "batl": [[0, 4.1, 2], [1, 4.2, 125.21], [2, 4.3, 106.77]]}, {"timestamp": 1632572342558, "ltp": 3.45, "tv": 3385.36, "trd": NaN, "batb": NaN, "batl": [[0, 4.2, 125.21], [1, 4.3, 106.77], [2, 4.5, 2]]}, {"timestamp": 1632572344768, "ltp": 3.45, "tv": 3385.36, "trd": NaN, "batb": [[0, 2.96, 2.13], [1, 2.94, 165.55], [2, 2.78, 2.66]], "batl": NaN}, {"timestamp": 1632572347365, "ltp": 3.8, "tv": 3385.5, "trd": [[3.8, 0.14]], "batb": [[0, 4, 4.94], [1, 3.8, 629.11], [2, 3.75, 976.98]], "batl": [[0, 4.2, 133.61]]}, {"timestamp": 1632572348357, "ltp": 3.8, "tv": 3385.5, "trd": NaN, "batb": [[1, 3.8, 251.64], [2, 3.75, 244.24]], "batl": [[0, 4.1, 12.64], [1, 4.2, 133.61], [2, 4.3, 106.77]]}, {"timestamp": 1632572349580, "ltp": 3.8, "tv": 3385.5, "trd": NaN, "batb": NaN, "batl": [[0, 4.1, 15.64]]}, {"timestamp": 1632572352177, "ltp": 3.8, "tv": 3385.5, "trd": NaN, "batb": NaN, "batl": [[2, 4.3, 156.73]]}, {"timestamp": 1632572353162, "ltp": 3.8, "tv": 3385.5, "trd": NaN, "batb": NaN, "batl": [[2, 4.3, 106.77]]}, {"timestamp": 1632572356158, "ltp": 3.8, "tv": 3385.5, "trd": NaN, "batb": [[2, 3.75, 266.05]], "batl": NaN}, {"timestamp": 1632572364381, "ltp": 3.8, "tv": 3385.5, "trd": NaN, "batb": [[0, 3.75, 21.81], [1, 3.7, 92.67], [2, 3.55, 2]], "batl": [[1, 4.2, 125.21]]}, {"timestamp": 1632572365075, "ltp": 3.8, "tv": 3385.5, "trd": NaN, "batb": [[1, 3.55, 2], [2, 3.4, 2]], "batl": [[0, 4.4, 10.13], [1, 4.5, 97.57], [2, 4.6, 134.85]]}, {"timestamp": 1632572366302, "ltp": 3.8, "tv": 3385.5, "trd": NaN, "batb": [[0, 3.55, 2], [1, 3.4, 2], [2, 3.3, 114.45]], "batl": [[0, 4.4, 2]]}, {"timestamp": 1632572366677, "ltp": 3.8, "tv": 3385.5, "trd": NaN, "batb": [[0, 3.4, 2], [1, 3.3, 114.45], [2, 3.25, 270.6]], "batl": NaN}, {"timestamp": 1632572368294, "ltp": 3.8, "tv": 3385.5, "trd": NaN, "batb": [[1, 3.25, 126.57], [2, 3.1, 2.04]], "batl": [[0, 4.3, 2], [1, 4.4, 2], [2, 4.5, 97.57]]}, {"timestamp": 1632572368604, "ltp": 3.8, "tv": 3385.5, "trd": NaN, "batb": [[2, 2.98, 3]], "batl": [[0, 4.4, 2], [1, 4.5, 97.57], [2, 4.6, 134.85]]}, {"timestamp": 1632572370287, "ltp": 3.8, "tv": 3385.5, "trd": NaN, "batb": [[0, 3.4, 5], [1, 3.35, 3], [2, 3.25, 126.57]], "batl": NaN}, {"timestamp": 1632572371274, "ltp": 3.8, "tv": 3385.5, "trd": NaN, "batb": [[0, 4.3, 4.63], [1, 4.1, 48.55], [2, 3.9, 245.2]], "batl": NaN}, {"timestamp": 1632572372256, "ltp": 4.3, "tv": 3389.5, "trd": [[4.3, 49.17]], "batb": [[0, 4.3, 2.63], [2, 3.9, 409.48]], "batl": [[0, 4.4, 4], [2, 4.6, 142.75]]}, {"timestamp": 1632572373216, "ltp": 4.3, "tv": 3389.5, "trd": NaN, "batb": NaN, "batl": [[0, 4.4, 14]]}, {"timestamp": 1632572376342, "ltp": 4.3, "tv": 3394.6, "trd": [[4.3, 54.27]], "batb": [[0, 4.1, 48.63], [1, 3.9, 409.48], [2, 3.85, 237.98]], "batl": NaN}, {"timestamp": 1632572377878, "ltp": 4.3, "tv": 3394.6, "trd": NaN, "batb": [[2, 3.85, 239.98]], "batl": [[2, 4.6, 144.75]]}, {"timestamp": 1632572378842, "ltp": 4.3, "tv": 3394.6, "trd": NaN, "batb": NaN, "batl": [[2, 4.6, 252.93]]}, {"timestamp": 1632572379816, "ltp": 4.3, "tv": 3394.61, "trd": [[4.3, 54.28]], "batb": [[0, 4.1, 48.62], [1, 3.95, 20.33], [2, 3.9, 409.48]], "batl": NaN}, {"timestamp": 1632572382241, "ltp": 4.3, "tv": 3394.61, "trd": NaN, "batb": [[0, 3.95, 20.33], [1, 3.85, 2], [2, 3.7, 103.47]], "batl": [[0, 4.4, 2], [1, 4.5, 2], [2, 4.6, 118.08]]}, {"timestamp": 1632572383325, "ltp": 4.3, "tv": 3394.61, "trd": NaN, "batb": [[0, 3.85, 2], [1, 3.7, 103.47], [2, 3.65, 124.09]], "batl": [[0, 4.5, 2], [1, 4.6, 110.18], [2, 4.7, 111.81]]}, {"timestamp": 1632572384129, "ltp": 4.3, "tv": 3394.61, "trd": NaN, "batb": [[0, 3.7, 103.47], [1, 3.65, 124.09], [2, 3.6, 2]], "batl": NaN}, {"timestamp": 1632572387353, "ltp": 4.3, "tv": 3394.61, "trd": NaN, "batb": [[0, 3.7, 105.47], [1, 3.65, 127.09]], "batl": NaN}, {"timestamp": 1632572389256, "ltp": 4.3, "tv": 3394.61, "trd": NaN, "batb": [[0, 3.75, 32.42], [1, 3.7, 105.47], [2, 3.65, 127.09]], "batl": [[0, 4.4, 2], [1, 4.5, 2], [2, 4.6, 110.18]]}, {"timestamp": 1632572390328, "ltp": 4.3, "tv": 3394.61, "trd": NaN, "batb": [[0, 3.85, 2], [1, 3.75, 32.42], [2, 3.7, 105.47]], "batl": NaN}, {"timestamp": 1632572390652, "ltp": 4.3, "tv": 3394.61, "trd": NaN, "batb": [[1, 3.7, 105.47], [2, 3.65, 127.09]], "batl": NaN}, {"timestamp": 1632572392331, "ltp": 4.3, "tv": 3394.61, "trd": NaN, "batb": NaN, "batl": [[0, 4.4, 12]]}, {"timestamp": 1632572393044, "ltp": 4.3, "tv": 3394.61, "trd": NaN, "batb": NaN, "batl": [[0, 4.4, 2]]}, {"timestamp": 1632572394211, "ltp": 4.3, "tv": 3394.61, "trd": NaN, "batb": [[0, 3.9, 10], [1, 3.85, 2], [2, 3.7, 105.47]], "batl": [[0, 4.5, 2], [1, 4.6, 110.18], [2, 4.7, 111.81]]}, {"timestamp": 1632572399356, "ltp": 4.3, "tv": 3394.61, "trd": NaN, "batb": NaN, "batl": [[0, 4.4, 10], [1, 4.5, 2], [2, 4.6, 110.18]]}, {"timestamp": 1632572399945, "ltp": 4.3, "tv": 3394.61, "trd": NaN, "batb": [[0, 3.85, 2], [1, 3.7, 105.47], [2, 3.65, 124.09]], "batl": [[0, 4.5, 2], [1, 4.6, 110.18], [2, 4.7, 111.81]]}, {"timestamp": 1632572401159, "ltp": 4.3, "tv": 3394.61, "trd": NaN, "batb": [[0, 3.7, 105.47], [1, 3.65, 124.09], [2, 3.55, 100.62]], "batl": [[0, 4.4, 2], [1, 4.5, 2], [2, 4.6, 110.18]]}, {"timestamp": 1632572401760, "ltp": 4.3, "tv": 3394.61, "trd": NaN, "batb": NaN, "batl": [[0, 4.5, 2], [1, 4.6, 110.18], [2, 4.7, 111.81]]}, {"timestamp": 1632572404252, "ltp": 4.3, "tv": 3394.61, "trd": NaN, "batb": [[0, 3.85, 2], [1, 3.7