{"op":"mcm","clk":"4225661074","pt":1631459665770,"mc":[{"id":"1.187557247","marketDefinition":{"bspMarket":false,"turnInPlayEnabled":true,"persistenceEnabled":true,"marketBaseRate":5.0,"eventId":"30896009","eventTypeId":"2","numberOfWinners":1,"bettingType":"ODDS","marketType":"MATCH_ODDS","marketTime":"2021-09-13T10:30:00.000Z","suspendTime":"2021-09-13T10:30:00.000Z","bspReconciled":false,"complete":true,"inPlay":false,"crossMatching":false,"runnersVoidable":false,"numberOfActiveRunners":2,"betDelay":0,"status":"OPEN","runners":[{"status":"ACTIVE","sortPriority":1,"id":9304761,"name":"Cristiana Ferrando"},{"status":"ACTIVE","sortPriority":2,"id":10350473,"name":"Yuliya Hatouka"}],"regulators":["MR_INT"],"discountAllowed":false,"timezone":"UTC","openDate":"2021-09-13T10:30:00.000Z","version":4028820990,"name":"Match Odds","eventName":"Ferrando v Yul Hatouka"}}]}
{"op":"mcm","clk":"4225661323","pt":1631459666780,"mc":[{"id":"1.187557247","marketDefinition":{"bspMarket":false,"turnInPlayEnabled":true,"persistenceEnabled":true,"marketBaseRate":5.0,"eventId":"30896009","eventTypeId":"2","numberOfWinners":1,"bettingType":"ODDS","marketType":"MATCH_ODDS","marketTime":"2021-09-13T10:30:00.000Z","suspendTime":"2021-09-13T10:30:00.000Z","bspReconciled":false,"complete":true,"inPlay":false,"crossMatching":false,"runnersVoidable":false,"numberOfActiveRunners":2,"betDelay":0,"status":"OPEN","runners":[{"status":"ACTIVE","sortPriority":1,"id":9304761,"name":"Cristiana Ferrando"},{"status":"ACTIVE","sortPriority":2,"id":10350473,"name":"Yuliya Hatouka"}],"regulators":["MR_INT"],"discountAllowed":false,"timezone":"UTC","openDate":"2021-09-13T10:30:00.000Z","version":4028820990,"name":"Match Odds","eventName":"Ferrando v Yul Hatouka"}}]}
{"op":"mcm","clk":"4225661543","pt":1631459667784,"mc":[{"id":"1.187557247","marketDefinition":{"bspMarket":false,"turnInPlayEnabled":true,"persistenceEnabled":true,"marketBaseRate":5.0,"eventId":"30896009","eventTypeId":"2","numberOfWinners":1,"bettingType":"ODDS","marketType":"MATCH_ODDS","marketTime":"2021-09-13T10:30:00.000Z","suspendTime":"2021-09-13T10:30:00.000Z","bspReconciled":false,"complete":true,"inPlay":false,"crossMatching":false,"runnersVoidable":false,"numberOfActiveRunners":2,"betDelay":0,"status":"OPEN","runners":[{"status":"ACTIVE","sortPriority":1,"id":9304761,"name":"Cristiana Ferrando"},{"status":"ACTIVE","sortPriority":2,"id":10350473,"name":"Yuliya Hatouka"}],"regulators":["MR_INT"],"discountAllowed":true,"timezone":"UTC","openDate":"2021-09-13T10:30:00.000Z","version":4028820990,"name":"Match Odds","eventName":"Ferrando v Yul Hatouka"}}]}
{"op":"mcm","clk":"4225673109","pt":1631459722105,"mc":[{"id":"1.187557247","rc":[{"batb":[[0,1.01,25]],"ltp":0.0,"tv":0.0,"id":10350473},{"batb":[[0,1.01,25]],"ltp":0.0,"tv":0.0,"id":9304761}]}]}
{"op":"mcm","clk":"4225845672","pt":1631460657641,"mc":[{"id":"1.187557247","rc":[{"batb":[[0,1.01,118.94]],"ltp":0.0,"tv":0.0,"id":10350473},{"batb":[[0,1.01,118.94]],"ltp":0.0,"tv":0.0,"id":9304761}]}]}
{"op":"mcm","clk":"4226071512","pt":1631461865128,"mc":[{"id":"1.187557247","rc":[{"batb":[[0,1.44,51.24],[1,1.01,118.94]],"ltp":0.0,"tv":0.0,"id":10350473},{"batb":[[0,2.74,12.95],[1,1.01,118.94]],"ltp":0.0,"tv":0.0,"id":9304761}]}]}
{"op":"mcm","clk":"4226074203","pt":1631461880982,"mc":[{"id":"1.187557247","marketDefinition":{"bspMarket":false,"turnInPlayEnabled":true,"persistenceEnabled":true,"marketBaseRate":5.0,"eventId":"30896009","eventTypeId":"2","numberOfWinners":1,"bettingType":"ODDS","marketType":"MATCH_ODDS","marketTime":"2021-09-13T10:30:00.000Z","suspendTime":"2021-09-13T10:30:00.000Z","bspReconciled":false,"complete":true,"inPlay":false,"crossMatching":true,"runnersVoidable":false,"numberOfActiveRunners":2,"betDelay":0,"status":"OPEN","runners":[{"status":"ACTIVE","sortPriority":1,"id":9304761,"name":"Cristiana Ferrando"},{"status":"ACTIVE","sortPriority":2,"id":10350473,"name":"Yuliya Hatouka"}],"regulators":["MR_INT"],"discountAllowed":true,"timezone":"UTC","openDate":"2021-09-13T10:30:00.000Z","version":4028820990,"name":"Match Odds","eventName":"Ferrando v Yul Hatouka"}}]}
{"op":"mcm","clk":"4226301364","pt":1631463136479,"mc":[{"id":"1.187557247","rc":[{"batl":[[0,990,2.2]],"ltp":0.0,"tv":0.0,"id":10350473},{"batl":[[0,990,2.2]],"ltp":0.0,"tv":0.0,"id":9304761}]}]}
{"op":"mcm","clk":"4226631945","pt":1631465201605,"mc":[{"id":"1.187557247","rc":[{"batb":[[0,2.78,44.61],[1,2.74,12.95],[2,1.01,118.94]],"ltp":0.0,"tv":0.0,"id":9304761}]}]}
{"op":"mcm","clk":"4226784079","pt":1631466328642,"mc":[{"id":"1.187557247","rc":[{"batl":[[0,9.2,3.42],[1,990,2.2]],"ltp":0.0,"tv":0.0,"id":10350473}]}]}
{"op":"mcm","clk":"4226784127","pt":1631466328917,"mc":[{"id":"1.187557247","rc":[{"batl":[[0,18,3.42],[1,990,2.2]],"ltp":0.0,"tv":0.0,"id":9304761}]}]}
{"op":"mcm","clk":"4226789674","pt":1631466363087,"mc":[{"id":"1.187557247","rc":[{"batb":[[0,2.74,12.95],[1,1.01,118.94],[2,1.01,0]],"ltp":0.0,"tv":0.0,"id":9304761}]}]}
{"op":"mcm","clk":"4226790002","pt":1631466364680,"mc":[{"id":"1.187557247","rc":[{"batb":[[0,2.76,44.94],[1,2.74,12.95],[2,1.01,118.94]],"ltp":0.0,"tv":0.0,"id":9304761}]}]}
{"op":"mcm","clk":"4227106664","pt":1631468336357,"mc":[{"id":"1.187557247","rc":[{"batb":[[0,1.4,198.8]],"ltp":0.0,"tv":0.0,"id":10350473},{"batb":[[0,2.88,11.99],[1,2.76,44.94]],"ltp":0.0,"tv":0.0,"id":9304761}]}]}
{"op":"mcm","clk":"4227123539","pt":1631468464549,"mc":[{"id":"1.187557247","rc":[{"batb":[[1,1.01,118.94],[2,1.01,0]],"ltp":0.0,"tv":0.0,"id":9304761}]}]}
{"op":"mcm","clk":"4227342621","pt":1631470361236,"mc":[{"id":"1.187557247","rc":[{"batl":[[0,1.98,31],[1,9.2,3.42],[2,990,2.2]],"ltp":0.0,"tv":0.0,"id":10350473},{"batl":[[0,5.1,13.75],[1,18,3.42],[2,990,2.2]],"ltp":0.0,"tv":0.0,"id":9304761}]}]}
{"op":"mcm","clk":"4227360494","pt":1631470507323,"mc":[{"id":"1.187557247","rc":[{"batl":[[1,990,2.2],[2,990,0]],"ltp":0.0,"tv":0.0,"id":10350473},{"batl":[[1,990,2.2],[2,990,0]],"ltp":0.0,"tv":0.0,"id":9304761}]}]}
{"op":"mcm","clk":"4227379525","pt":1631470661567,"mc":[{"id":"1.187557247","rc":[{"batl":[[0,6.8,77.94]],"ltp":0.0,"tv":0.0,"id":9304761}]}]}
{"op":"mcm","clk":"4227379987","pt":1631470665808,"mc":[{"id":"1.187557247","rc":[{"batl":[[0,6.6,3.42],[1,6.8,77.94],[2,990,2.2]],"ltp":0.0,"tv":0.0,"id":9304761}]}]}
{"op":"mcm","clk":"4227415711","pt":1631470961339,"mc":[{"id":"1.187557247","rc":[{"batl":[[0,5.3,99.91],[1,6.6,3.42]],"ltp":0.0,"tv":0.0,"id":9304761}]}]}
{"op":"mcm","clk":"4227417366","pt":1631470975258,"mc":[{"id":"1.187557247","rc":[{"batl":[[1,990,2.2],[2,990,0]],"ltp":0.0,"tv":0.0,"id":9304761}]}]}
{"op":"mcm","clk":"4227448502","pt":1631471238525,"mc":[{"id":"1.187557247","rc":[{"batl":[[0,990,2.2],[1,990,0]],"ltp":0.0,"tv":0.0,"id":10350473},{"batl":[[0,990,2.2],[1,990,0]],"ltp":0.0,"tv":0.0,"id":9304761}]}]}
{"op":"mcm","clk":"4227451254","pt":1631471261365,"mc":[{"id":"1.187557247","rc":[{"batl":[[0,1.89,82.8],[1,990,2.2]],"ltp":0.0,"tv":0.0,"id":10350473},{"batl":[[0,5.1,67.39],[1,990,2.2]],"ltp":0.0,"tv":0.0,"id":9304761}]}]}
{"op":"mcm","clk":"4227454448","pt":1631471289001,"mc":[{"id":"1.187557247","rc":[{"batb":[[0,1.41,6.2],[1,1.4,198.8],[2,1.01,118.94]],"ltp":0.0,"tv":0.0,"id":10350473}]}]}
{"op":"mcm","clk":"4227487841","pt":1631471561370,"mc":[{"id":"1.187557247","rc":[{"batb":[[1,1.4,56.36]],"ltp":0.0,"tv":0.0,"id":10350473}]}]}
{"op":"mcm","clk":"4227487914","pt":1631471561838,"mc":[{"id":"1.187557247","rc":[{"batl":[[0,990,2.2],[1,990,0]],"ltp":0.0,"tv":0.0,"id":10350473}]}]}
{"op":"mcm","clk":"4227493496","pt":1631471602699,"mc":[{"id":"1.187557247","rc":[{"batl":[[0,9,3.42],[1,990,2.2]],"ltp":0.0,"tv":0.0,"id":10350473},{"batl":[[0,5,3.42],[1,5.1,67.39],[2,990,2.2]],"ltp":0.0,"tv":0.0,"id":9304761}]}]}
{"op":"mcm","clk":"4227526003","pt":1631471861627,"mc":[{"id":"1.187557247","rc":[{"batl":[[0,1.94,80.69],[1,9,3.42],[2,990,2.2]],"ltp":0.0,"tv":0.0,"id":10350473},{"batl":[[0,4.7,35.47],[1,5,3.42]],"ltp":0.0,"tv":0.0,"id":9304761}]}]}
{"op":"mcm","clk":"4227530775","pt":1631471904555,"mc":[{"id":"1.187557247","rc":[{"batl":[[1,990,2.2],[2,990,0]],"ltp":0.0,"tv":0.0,"id":9304761}]}]}
{"op":"mcm","clk":"4227530807","pt":1631471904860,"mc":[{"id":"1.187557247","rc":[{"batl":[[1,990,2.2],[2,990,0]],"ltp":0.0,"tv":0.0,"id":10350473}]}]}
{"op":"mcm","clk":"4227651702","pt":1631472846843,"mc":[{"id":"1.187557247","rc":[{"batb":[[2,1.01,591.8]],"ltp":0.0,"tv":0.0,"id":10350473},{"batb":[[1,1.01,591.8]],"ltp":0.0,"tv":0.0,"id":9304761}]}]}
{"op":"mcm","clk":"4227709576","pt":1631473420500,"mc":[{"id":"1.187557247","rc":[{"batl":[[0,990,2.2],[1,990,0]],"ltp":0.0,"tv":0.0,"id":10350473}]}]}
{"op":"mcm","clk":"4227711161","pt":1631473434849,"mc":[{"id":"1.187557247","rc":[{"batl":[[0,9,3.42],[1,990,2.2]],"ltp":0.0,"tv":0.0,"id":10350473}]}]}
{"op":"mcm","clk":"4227717603","pt":1631473492099,"mc":[{"id":"1.187557247","rc":[{"batb":[[0,1.4,376.85],[1,1.28,6.2]],"ltp":0.0,"tv":0.0,"id":10350473}]}]}
{"op":"mcm","clk":"4227735736","pt":1631473661439,"mc":[{"id":"1.187557247","rc":[{"batl":[[0,1.84,85.03],[1,9,3.42],[2,990,2.2]],"ltp":0.0,"tv":0.0,"id":10350473}]}]}
{"op":"mcm","clk":"4227744368","pt":1631473740674,"mc":[{"id":"1.187557247","rc":[{"batl":[[1,990,2.2],[2,990,0]],"ltp":0.0,"tv":0.0,"id":10350473}]}]}
{"op":"mcm","clk":"4227776583","pt":1631474051296,"mc":[{"id":"1.187557247","rc":[{"batb":[[0,1.41,109.14],[1,1.4,376.85],[2,1.28,6.2]],"ltp":0.0,"tv":0.0,"id":10350473},{"batb":[[0,2.96,68.54],[1,2.88,11.99],[2,1.01,591.8]],"batl":[[0,6.6,167.13]],"ltp":0.0,"tv":0.0,"id":9304761}]}]}
{"op":"mcm","clk":"4227781294","pt":1631474095439,"mc":[{"id":"1.187557247","rc":[{"batb":[[1,1.4,56.36]],"ltp":0.0,"tv":0.0,"id":10350473}]}]}
{"op":"mcm","clk":"4227797416","pt":1631474261549,"mc":[{"id":"1.187557247","rc":[{"batl":[[0,990,2.2],[1,990,0]],"ltp":0.0,"tv":0.0,"id":10350473}]}]}
{"op":"mcm","clk":"4227799991","pt":1631474290304,"mc":[{"id":"1.187557247","rc":[{"batl":[[0,9,3.42],[1,990,2.2]],"ltp":0.0,"tv":0.0,"id":10350473},{"batl":[[0,6.4,3.42],[1,6.6,167.13],[2,990,2.2]],"ltp":0.0,"tv":0.0,"id":9304761}]}]}
{"op":"mcm","clk":"4227825108","pt":1631474561679,"mc":[{"id":"1.187557247","rc":[{"batl":[[0,5,224.37],[1,6.4,3.42]],"ltp":0.0,"tv":0.0,"id":9304761}]}]}
{"op":"mcm","clk":"4227825523","pt":1631474565788,"mc":[{"id":"1.187557247","rc":[{"batl":[[1,990,2.2],[2,990,0]],"ltp":0.0,"tv":0.0,"id":9304761}]}]}
{"op":"mcm","clk":"4227830986","pt":1631474626625,"mc":[{"id":"1.187557247","rc":[{"batl":[[0,4.9,3.42],[1,5,224.37],[2,990,2.2]],"ltp":0.0,"tv":0.0,"id":9304761}]}]}
{"op":"mcm","clk":"4227852521","pt":1631474861600,"mc":[{"id":"1.187557247","rc":[{"batl":[[0,4.6,243.8],[1,4.9,3.42]],"ltp":0.0,"tv":0.0,"id":9304761}]}]}
{"op":"mcm","clk":"4227853307","pt":1631474870402,"mc":[{"id":"1.187557247","rc":[{"batl":[[1,990,2.2],[2,990,0]],"ltp":0.0,"tv":0.0,"id":9304761}]}]}
{"op":"mcm","clk":"4227868716","pt":1631475043290,"mc":[{"id":"1.187557247","rc":[{"batb":[[0,1.42,419.41],[1,1.41,109.14],[2,1.4,56.36]],"ltp":0.0,"tv":0.0,"id":10350473}]}]}
{"op":"mcm","clk":"4227868852","pt":1631475044618,"mc":[{"id":"1.187557247","rc":[{"batb":[[0,1.45,103.52],[1,1.42,419.41]],"ltp":0.0,"tv":0.0,"id":10350473},{"trd":[[2.96,8.88]],"batb":[[0,2.9,30.87],[2,1.56,6.46]],"batl":[[0,990,2.2],[1,990,0]],"ltp":2.96,"tv":8.88,"id":9304761}],"tv":8.88}]}
{"op":"mcm","clk":"4227868936","pt":1631475045507,"mc":[{"id":"1.187557247","rc":[{"batb":[[0,2.88,11.99],[1,2.78,75.1]],"batl":[[0,4.7,143.88],[1,990,2.2]],"ltp":2.96,"tv":8.88,"id":9304761}]}]}
{"op":"mcm","clk":"4227880808","pt":1631475174594,"mc":[{"id":"1.187557247","rc":[{"batb":[[0,1.5,45.09],[1,1.45,103.52],[2,1.28,6.2]],"ltp":0.0,"tv":0.0,"id":10350473},{"batb":[[0,2.78,75.1],[1,2.62,13.91]],"ltp":2.96,"tv":8.88,"id":9304761}]}]}
{"op":"mcm","clk":"4227881775","pt":1631475185552,"mc":[{"id":"1.187557247","rc":[{"batl":[[0,2.02,11.91],[1,9,3.42],[2,990,2.2]],"ltp":0.0,"tv":0.0,"id":10350473}]}]}
{"op":"mcm","clk":"4227883610","pt":1631475204877,"mc":[{"id":"1.187557247","rc":[{"batl":[[1,990,2.2],[2,990,0]],"ltp":0.0,"tv":0.0,"id":10350473}]}]}
{"op":"mcm","clk":"4227924843","pt":1631475630606,"mc":[{"id":"1.187557247","rc":[{"batb":[[2,1.12,30.13]],"ltp":0.0,"tv":0.0,"id":10350473}]}]}
{"op":"mcm","clk":"4228043435","pt":1631477171256,"mc":[{"id":"1.187557247","rc":[{"batb":[[1,1.45,103.48]],"ltp":0.0,"tv":0.0,"id":10350473},{"trd":[[2.96,8.88]],"batb":[[0,2.78,75.08]],"ltp":2.96,"tv":8.87,"id":9304761}],"tv":8.87}]}
{"op":"mcm","clk":"4228094548","pt":1631477761194,"mc":[{"id":"1.187557247","rc":[{"batl":[[0,990,2.2],[1,990,0]],"ltp":0.0,"tv":0.0,"id":10350473}]}]}
{"op":"mcm","clk":"4228094613","pt":1631477761877,"mc":[{"id":"1.187557247","rc":[{"batl":[[0,2.04,48.16],[1,990,2.2]],"ltp":0.0,"tv":0.0,"id":10350473}]}]}
{"op":"mcm","clk":"4228372328","pt":1631482296201,"mc":[{"id":"1.187557247","rc":[{"batl":[[0,1.96,50.11]],"ltp":0.0,"tv":0.0,"id":10350473}]}]}
{"op":"mcm","clk":"4228375674","pt":1631482394289,"mc":[{"id":"1.187557247","rc":[{"batl":[[0,5.8,131.08]],"ltp":2.96,"tv":8.87,"id":9304761}]}]}
{"op":"mcm","clk":"4228386280","pt":1631482694491,"mc":[{"id":"1.187557247","rc":[{"batl":[[0,4.8,261.44]],"ltp":2.96,"tv":8.87,"id":9304761}]}]}
{"op":"mcm","clk":"4228428220","pt":1631483459432,"mc":[{"id":"1.187557247","rc":[{"batb":[[0,1.51,853.75],[1,1.5,45.09],[2,1.45,103.48]],"batl":[[0,2.02,48.64]],"ltp":0.0,"tv":0.0,"id":10350473}]}]}
{"op":"mcm","clk":"4228428370","pt":1631483462470,"mc":[{"id":"1.187557247","rc":[{"batb":[[1,1.5,853.75]],"ltp":0.0,"tv":0.0,"id":10350473}]}]}
{"op":"mcm","clk":"4228428514","pt":1631483464955,"mc":[{"id":"1.187557247","rc":[{"batb":[[2,1.49,853.75]],"ltp":0.0,"tv":0.0,"id":10350473}]}]}
{"op":"mcm","clk":"4228430171","pt":1631483496396,"mc":[{"id":"1.187557247","rc":[{"batb":[[2,1.49,879.05]],"ltp":0.0,"tv":0.0,"id":10350473}]}]}
{"op":"mcm","clk":"4228434761","pt":1631483594518,"mc":[{"id":"1.187557247","rc":[{"batl":[[0,6.2,135.39]],"ltp":2.96,"tv":8.87,"id":9304761}]}]}
{"op":"mcm","clk":"4228435101","pt":1631483601546,"mc":[{"id":"1.187557247","rc":[{"batl":[[0,6,3.42],[1,6.2,135.39],[2,990,2.2]],"ltp":2.96,"tv":8.87,"id":9304761}]}]}
{"op":"mcm","clk":"4228445222","pt":1631483811980,"mc":[{"id":"1.187557247","rc":[{"batl":[[0,5.9,136.32],[1,6,3.42]],"ltp":2.96,"tv":8.87,"id":9304761}]}]}
{"op":"mcm","clk":"4228447146","pt":1631483850652,"mc":[{"id":"1.187557247","rc":[{"batl":[[1,990,2.2],[2,990,0]],"ltp":2.96,"tv":8.87,"id":9304761}]}]}
{"op":"mcm","clk":"4228450111","pt":1631483912042,"mc":[{"id":"1.187557247","rc":[{"batl":[[0,5.8,3.42],[1,5.9,136.32],[2,990,2.2]],"ltp":2.96,"tv":8.87,"id":9304761}]}]}
{"op":"mcm","clk":"4228464054","pt":1631484194418,"mc":[{"id":"1.187557247","rc":[{"batb":[[0,1.51,853.9],[1,1.5,853.9],[2,1.49,879.2]],"ltp":0.0,"tv":0.0,"id":10350473},{"trd":[[2.96,8.88]],"batb":[[0,2.78,75.09],[2,1.56,6.46]],"batl":[[0,5.7,153.6],[1,5.8,3.42]],"ltp":2.96,"tv":8.88,"id":9304761}],"tv":8.88}]}
{"op":"mcm","clk":"4228464774","pt":1631484209153,"mc":[{"id":"1.187557247","rc":[{"batl":[[1,990,2.2],[2,990,0]],"ltp":2.96,"tv":8.88,"id":9304761}]}]}
{"op":"mcm","clk":"4228506330","pt":1631484954250,"mc":[{"id":"1.187557247","rc":[{"batb":[[0,2.78,78.69]],"ltp":2.96,"tv":8.88,"id":9304761}]}]}
{"op":"mcm","clk":"4228605683","pt":1631487494599,"mc":[{"id":"1.187557247","rc":[{"batl":[[0,5,254.62]],"ltp":2.96,"tv":8.88,"id":9304761}]}]}
{"op":"mcm","clk":"4228652476","pt":1631488665721,"mc":[{"id":"1.187557247","rc":[{"batb":[[0,1.51,853.75],[1,1.5,853.75],[2,1.49,879.05]],"ltp":0.0,"tv":0.0,"id":10350473},{"trd":[[2.96,8.88]],"batb":[[0,2.78,78.68]],"ltp":2.96,"tv":8.87,"id":9304761}],"tv":8.87}]}
{"op":"mcm","clk":"4228696734","pt":1631489618759,"mc":[{"id":"1.187557247","rc":[{"batb":[[2,2.6,3]],"batl":[[0,990,2.2],[1,990,0]],"ltp":2.96,"tv":8.87,"id":9304761}]}]}
{"op":"mcm","clk":"4228696736","pt":1631489618862,"mc":[{"id":"1.187557247","rc":[{"batl":[[0,5,252.45],[1,990,2.2]],"ltp":2.96,"tv":8.87,"id":9304761}]}]}
{"op":"mcm","clk":"4228731283","pt":1631490551749,"mc":[{"id":"1.187557247","rc":[{"batl":[[0,1.74,74.58]],"ltp":0.0,"tv":0.0,"id":10350473}]}]}
{"op":"mcm","clk":"4228815537","pt":1631492804165,"mc":[{"id":"1.187557247","rc":[{"batb":[[2,1.56,6.45]],"ltp":2.96,"tv":8.87,"id":9304761}]}]}
{"op":"mcm","clk":"4228895782","pt":1631494967706,"mc":[{"id":"1.187557247","rc":[{"batb":[[0,1.51,853.32],[1,1.5,853.32],[2,1.49,878.6]],"batl":[[0,1.73,42.23]],"ltp":0.0,"tv":0.0,"id":10350473},{"trd":[[2.96,8.87]],"batb":[[0,2.78,78.64]],"batl":[[0,990,2.2],[1,990,0]],"ltp":2.96,"tv":8.87,"id":9304761}],"tv":8.87}]}
{"op":"mcm","clk":"4228895787","pt":1631494967809,"mc":[{"id":"1.187557247","rc":[{"batl":[[0,4.5,150.15],[1,990,2.2]],"ltp":2.96,"tv":8.87,"id":9304761}]}]}
{"op":"mcm","clk":"4228897651","pt":1631495019680,"mc":[{"id":"1.187557247","rc":[{"batl":[[0,5.6,160.45]],"ltp":2.96,"tv":8.87,"id":9304761}]}]}
{"op":"mcm","clk":"4228907811","pt":1631495319241,"mc":[{"id":"1.187557247","rc":[{"batl":[[0,5.5,227.6]],"ltp":2.96,"tv":8.87,"id":9304761}]}]}
{"op":"mcm","clk":"4228950799","pt":1631496791368,"mc":[{"id":"1.187557247","rc":[{"batl":[[0,4.7,218.56]],"ltp":2.96,"tv":8.87,"id":9304761}]}]}
{"op":"mcm","clk":"4228979765","pt":1631497927484,"mc":[{"id":"1.187557247","rc":[{"batl":[[0,990,2.2],[1,990,0]],"ltp":0.0,"tv":0.0,"id":10350473}]}]}
{"op":"mcm","clk":"4228980921","pt":1631497968145,"mc":[{"id":"1.187557247","rc":[{"batl":[[0,1.99,65.3],[1,9.6,3.41],[2,990,2.2]],"ltp":0.0,"tv":0.0,"id":10350473},{"batl":[[0,4.6,3.41],[1,4.7,218.56],[2,990,2.2]],"ltp":2.96,"tv":8.87,"id":9304761}]}]}
{"op":"mcm","clk":"4228981502","pt":1631497989074,"mc":[{"id":"1.187557247","rc":[{"batl":[[0,4.5,228.22],[1,4.6,3.41]],"ltp":2.96,"tv":8.87,"id":9304761}]}]}
{"op":"mcm","clk":"4228984893","pt":1631498102707,"mc":[{"id":"1.187557247","rc":[{"batl":[[1,990,2.2],[2,990,0]],"ltp":0.0,"tv":0.0,"id":10350473},{"batl":[[1,990,2.2],[2,990,0]],"ltp":2.96,"tv":8.87,"id":9304761}]}]}
{"op":"mcm","clk":"4229130041","pt":1631502772709,"mc":[{"id":"1.187557247","rc":[{"batb":[[0,1.51,853.1],[1,1.5,853.1],[2,1.49,878.37]],"batl":[[0,990,2.2],[1,990,0]],"ltp":0.0,"tv":0.0,"id":10350473},{"trd":[[2.96,8.87]],"batb":[[0,2.78,78.62],[2,1.56,6.45]],"batl":[[0,990,2.2],[1,990,0]],"ltp":2.96,"tv":8.87,"id":9304761}],"tv":8.87}]}
{"op":"mcm","clk":"4229130101","pt":1631502773686,"mc":[{"id":"1.187557247","rc":[{"batl":[[0,2.02,36.2],[1,990,2.2]],"ltp":0.0,"tv":0.0,"id":10350473},{"batl":[[0,3.75,211.9],[1,990,2.2]],"ltp":2.96,"tv":8.87,"id":9304761}]}]}
{"op":"mcm","clk":"4229130170","pt":1631502774713,"mc":[{"id":"1.187557247","rc":[{"batl":[[0,990,2.2],[1,990,0]],"ltp":2.96,"tv":8.87,"id":9304761}]}]}
{"op":"mcm","clk":"4229130221","pt":1631502775587,"mc":[{"id":"1.187557247","rc":[{"batl":[[0,3.5,159.99],[1,990,2.2]],"ltp":2.96,"tv":8.87,"id":9304761}]}]}
{"op":"mcm","clk":"4229140017","pt":1631503073683,"mc":[{"id":"1.187557247","rc":[{"batl":[[0,990,2.2],[1,990,0]],"ltp":2.96,"tv":8.87,"id":9304761}]}]}
{"op":"mcm","clk":"4229140022","pt":1631503073785,"mc":[{"id":"1.187557247","rc":[{"batl":[[0,4.4,869.67],[1,990,2.2]],"ltp":2.96,"tv":8.87,"id":9304761}]}]}
{"op":"mcm","clk":"4229144040","pt":1631503185457,"mc":[{"id":"1.187557247","rc":[{"batl":[[0,4.1,248.23]],"ltp":2.96,"tv":8.87,"id":9304761}]}]}
{"op":"mcm","clk":"4229149923","pt":1631503372684,"mc":[{"id":"1.187557247","rc":[{"batl":[[0,990,2.2],[1,990,0]],"ltp":0.0,"tv":0.0,"id":10350473}]}]}
{"op":"mcm","clk":"4229149984","pt":1631503374017,"mc":[{"id":"1.187557247","rc":[{"batl":[[0,1.78,41.03],[1,990,2.2]],"ltp":0.0,"tv":0.0,"id":10350473},{"batl":[[0,5.7,246.67]],"ltp":2.96,"tv":8.87,"id":9304761}]}]}
{"op":"mcm","clk":"4229159683","pt":1631503673919,"mc":[{"id":"1.187557247","rc":[{"batl":[[0,5.3,830.46]],"ltp":2.96,"tv":8.87,"id":9304761}]}]}
{"op":"mcm","clk":"4229171705","pt":1631504131676,"mc":[{"id":"1.187557247","rc":[{"batl":[[0,4.9,897.94]],"ltp":2.96,"tv":8.87,"id":9304761}]}]}
{"op":"mcm","clk":"4229235394","pt":1631506300375,"mc":[{"id":"1.187557247","rc":[{"batl":[[0,4.1,195.28]],"ltp":2.96,"tv":8.87,"id":9304761}]}]}
{"op":"mcm","clk":"4229237781","pt":1631506386509,"mc":[{"id":"1.187557247","rc":[{"batl":[[0,5.2,228.54]],"ltp":2.96,"tv":8.87,"id":9304761}]}]}
{"op":"mcm","clk":"4229261812","pt":1631507401218,"mc":[{"id":"1.187557247","rc":[{"batb":[[1,2.62,20.87]],"ltp":2.96,"tv":8.87,"id":9304761}]}]}
{"op":"mcm","clk":"4229275852","pt":1631508879524,"mc":[{"id":"1.187557247","rc":[{"batb":[[1,1.5,858.1],[2,1.49,884.37]],"ltp":0.0,"tv":0.0,"id":10350473},{"batb":[[1,2.62,23.87],[2,2.6,3]],"ltp":2.96,"tv":8.87,"id":9304761}]}]}
{"op":"mcm","clk":"4229276474","pt":1631508941624,"mc":[{"id":"1.187557247","rc":[{"batb":[[2,1.49,878.37]],"batl":[[0,1.71,10.18],[1,1.78,41.03],[2,990,2.2]],"ltp":0.0,"tv":0.0,"id":10350473},{"batb":[[2,1.71,24.93]],"batl":[[0,3.45,2.95],[1,5.2,228.54],[2,990,2.2]],"ltp":2.96,"tv":8.87,"id":9304761}]}]}
{"op":"mcm","clk":"4229276936","pt":1631508987388,"mc":[{"id":"1.187557247","rc":[{"batl":[[0,3.35,292.52],[1,3.45,2.95]],"ltp":2.96,"tv":8.87,"id":9304761}]}]}
{"op":"mcm","clk":"4229277786","pt":1631509074119,"mc":[{"id":"1.187557247","rc":[{"batl":[[0,1.66,78.1],[1,1.71,10.18]],"ltp":0.0,"tv":0.0,"id":10350473}]}]}
{"op":"mcm","clk":"4229289154","pt":1631509900545,"mc":[{"id":"1.187557247","rc":[{"batb":[[0,1.51,853.17],[1,1.5,853.17],[2,1.49,878.45]],"batl":[[0,1.71,10.18],[1,990,2.2],[2,990,0]],"ltp":0.0,"tv":0.0,"id":10350473},{"batb":[[0,2.78,78.63],[1,2.62,20.87],[2,1.71,24.95]],"batl":[[0,3.45,2.95],[1,990,2.2],[2,990,0]],"ltp":2.96,"tv":8.87,"id":9304761}]}]}
{"op":"mcm","clk":"4229289162","pt":1631509900852,"mc":[{"id":"1.187557247","rc":[{"batl":[[0,3.3,150.44],[1,3.45,2.95],[2,990,2.2]],"ltp":2.96,"tv":8.87,"id":9304761}]}]}
{"op":"mcm","clk":"4229291868","pt":1631510087613,"mc":[{"id":"1.187557247","rc":[{"batl":[[0,3.35,255.27]],"ltp":2.96,"tv":8.87,"id":9304761}]}]}
{"op":"mcm","clk":"4229293339","pt":1631510186708,"mc":[{"id":"1.187557247","rc":[{"batl":[[0,3.45,2.95],[1,990,2.2],[2,990,0]],"ltp":2.96,"tv":8.87,"id":9304761}]}]}
{"op":"mcm","clk":"4229293340","pt":1631510186808,"mc":[{"id":"1.187557247","rc":[{"batl":[[0,3.35,68.78],[1,3.45,2.95],[2,990,2.2]],"ltp":2.96,"tv":8.87,"id":9304761}]}]}
{"op":"mcm","clk":"4229300966","pt":1631510286700,"mc":[{"id":"1.187557247","rc":[{"batl":[[0,3.4,183.63]],"ltp":2.96,"tv":8.87,"id":9304761}]}]}
{"op":"mcm","clk":"4229303041","pt":1631510424669,"mc":[{"id":"1.187557247","rc":[{"batl":[[1,29,48.39],[2,990,2.2]],"ltp":0.0,"tv":0.0,"id":10350473},{"batl":[[2,29,48.39]],"ltp":2.96,"tv":8.87,"id":9304761}]}]}
{"op":"mcm","clk":"4229304077","pt":1631510487050,"mc":[{"id":"1.187557247","rc":[{"batl":[[0,3.4,288.79]],"ltp":2.96,"tv":8.87,"id":9304761}]}]}
{"op":"mcm","clk":"4229309476","pt":1631510862985,"mc":[{"id":"1.187557247","rc":[{"batl":[[0,3.4,168.72]],"ltp":2.96,"tv":8.87,"id":9304761}]}]}
{"op":"mcm","clk":"4229310244","pt":1631510942705,"mc":[{"id":"1.187557247","rc":[{"batl":[[0,1.56,4.06],[1,1.71,10.18],[2,29,48.39]],"ltp":0.0,"tv":0.0,"id":10350473}]}]}
{"op":"mcm","clk":"4229310307","pt":1631510949736,"mc":[{"id":"1.187557247","rc":[{"batl":[[0,1.71,10.18],[1,29,48.39],[2,990,2.2]],"ltp":0.0,"tv":0.0,"id":10350473}]}]}
{"op":"mcm","clk":"4229310314","pt":1631510950096,"mc":[{"id":"1.187557247","rc":[{"batl":[[0,1.56,4.06],[1,1.71,10.18],[2,29,48.39]],"ltp":0.0,"tv":0.0,"id":10350473}]}]}
{"op":"mcm","clk":"4229311766","pt":1631511087140,"mc":[{"id":"1.187557247","rc":[{"batl":[[0,3.35,288.1]],"ltp":2.96,"tv":8.87,"id":9304761}]}]}
{"op":"mcm","clk":"4229314662","pt":1631511361007,"mc":[{"id":"1.187557247","rc":[{"trd":[[1.56,9.74]],"batl":[[0,1.7,85.32]],"ltp":1.56,"tv":9.74,"id":10350473}],"tv":18.61}]}
{"op":"mcm","clk":"4229314838","pt":1631511380402,"mc":[{"id":"1.187557247","rc":[{"batl":[[0,3.45,2.95],[1,29,48.39],[2,990,2.2]],"ltp":2.96,"tv":8.87,"id":9304761}]}]}
{"op":"mcm","clk":"4229314906","pt":1631511386906,"mc":[{"id":"1.187557247","rc":[{"batl":[[0,3.35,288.1],[1,3.45,2.95],[2,29,48.39]],"ltp":2.96,"tv":8.87,"id":9304761}]}]}
{"op":"mcm","clk":"4229334443","pt":1631512917618,"mc":[{"id":"1.187557247","rc":[{"batl":[[2,1.89,2.66]],"ltp":1.56,"tv":9.74,"id":10350473}]}]}
{"op":"mcm","clk":"4229341563","pt":1631513256874,"mc":[{"id":"1.187557247","rc":[{"batb":[[0,1.51,857.44]],"ltp":1.56,"tv":9.74,"id":10350473}]}]}
{"op":"mcm","clk":"4229403594","pt":1631516142545,"mc":[{"id":"1.187557247","rc":[{"batl":[[1,3.45,5.9]],"ltp":2.96,"tv":8.87,"id":9304761}]}]}
{"op":"mcm","clk":"4229403610","pt":1631516143057,"mc":[{"id":"1.187557247","rc":[{"batl":[[1,3.45,2.95]],"ltp":2.96,"tv":8.87,"id":9304761}]}]}
{"op":"mcm","clk":"4229465586","pt":1631517706432,"mc":[{"id":"1.187557247","rc":[{"trd":[[1.56,9.75]],"batb":[[0,1.51,857.58],[1,1.5,853.32],[2,1.49,878.6]],"batl":[[0,1.68,79],[1,1.71,10.2],[2,1.89,2.66]],"ltp":1.56,"tv":9.74,"id":10350473},{"trd":[[2.96,8.87]],"batb":[[0,2.8,371.39],[1,2.78,78.64],[2,2.72,4]],"batl":[[0,3.3,352.44],[1,3.45,2.96],[2,29,48.45]],"ltp":2.96,"tv":8.87,"id":9304761}],"tv":18.62}]}
{"op":"mcm","clk":"4229465639","pt":1631517707617,"mc":[{"id":"1.187557247","rc":[{"batl":[[0,1.55,6]],"ltp":1.56,"tv":9.74,"id":10350473},{"batb":[[0,2.82,4],[1,2.8,374.39],[2,2.78,78.64]],"batl":[[0,3.4,168.81]],"ltp":2.96,"tv":8.87,"id":9304761}]}]}
{"op":"mcm","clk":"4229468094","pt":1631517757684,"mc":[{"id":"1.187557247","rc":[{"batb":[[0,2.84,51.15],[1,2.82,4],[2,2.78,3.6]],"ltp":2.96,"tv":8.87,"id":9304761}]}]}
{"op":"mcm","clk":"4229468109","pt":1631517757995,"mc":[{"id":"1.187557247","rc":[{"batl":[[0,1.64,33.87]],"ltp":1.56,"tv":9.74,"id":10350473},{"batb":[[1,2.78,3.6],[2,1.71,24.98]],"ltp":2.96,"tv":8.87,"id":9304761}]}]}
{"op":"mcm","clk":"4229468196","pt":1631517760360,"mc":[{"id":"1.187557247","rc":[{"batb":[[2,2.62,20.87]],"ltp":2.96,"tv":8.87,"id":9304761}]}]}
{"op":"mcm","clk":"4229468610","pt":1631517770488,"mc":[{"id":"1.187557247","rc":[{"batb":[[2,2.74,19.43]],"ltp":2.96,"tv":8.87,"id":9304761}]}]}
{"op":"mcm","clk":"4229472394","pt":1631517857461,"mc":[{"id":"1.187557247","rc":[{"batb":[[0,2.8,509.72]],"ltp":2.96,"tv":8.87,"id":9304761}]}]}
{"op":"mcm","clk":"4229472526","pt":1631517861742,"mc":[{"id":"1.187557247","rc":[{"batb":[[2,1.71,24.98]],"ltp":2.96,"tv":8.87,"id":9304761}]}]}
{"op":"mcm","clk":"4229474299","pt":1631517906464,"mc":[{"id":"1.187557247","rc":[{"batl":[[0,3.4,290.29]],"ltp":2.96,"tv":8.87,"id":9304761}]}]}
{"op":"mcm","clk":"4229477068","pt":1631517976754,"mc":[{"id":"1.187557247","rc":[{"trd":[[1.56,11.46]],"ltp":1.56,"tv":11.45,"id":10350473},{"trd":[[2.8,0.95]],"batb":[[0,2.8,508.77]],"ltp":2.8,"tv":9.82,"id":9304761}],"tv":21.28}]}
{"op":"mcm","clk":"4229479651","pt":1631518058207,"mc":[{"id":"1.187557247","rc":[{"batl":[[0,1.67,770.96]],"ltp":1.56,"tv":11.45,"id":10350473}]}]}
{"op":"mcm","clk":"4229482748","pt":1631518159648,"mc":[{"id":"1.187557247","rc":[{"batb":[[0,2.8,509.13]],"ltp":2.8,"tv":9.82,"id":9304761}]}]}
{"op":"mcm","clk":"4229484889","pt":1631518213624,"mc":[{"id":"1.187557247","rc":[{"batb":[[1,1.71,24.98],[2,1.56,6.47]],"ltp":2.8,"tv":9.82,"id":9304761}]}]}
{"op":"mcm","clk":"4229485122","pt":1631518220252,"mc":[{"id":"1.187557247","rc":[{"batb":[[0,2.8,512.71]],"ltp":2.8,"tv":9.82,"id":9304761}]}]}
{"op":"mcm","clk":"4229493050","pt":1631518471310,"mc":[{"id":"1.187557247","rc":[{"batl":[[0,3.35,294.59]],"ltp":2.8,"tv":9.82,"id":9304761}]}]}
{"op":"mcm","clk":"4229500761","pt":1631518698525,"mc":[{"id":"1.187557247","rc":[{"batl":[[0,1.55,6]],"ltp":1.56,"tv":11.45,"id":10350473},{"batb":[[0,2.82,3.36],[1,2.8,515.35],[2,1.71,24.98]],"ltp":2.8,"tv":9.82,"id":9304761}]}]}
{"op":"mcm","clk":"4229503255","pt":1631518757716,"mc":[{"id":"1.187557247","rc":[{"batb":[[0,2.82,445.36],[1,2.8,73.45]],"ltp":2.8,"tv":9.82,"id":9304761}]}]}
{"op":"mcm","clk":"4229503260","pt":1631518757923,"mc":[{"id":"1.187557247","rc":[{"batb":[[1,2.8,70.45]],"ltp":2.8,"tv":9.82,"id":9304761}]}]}
{"op":"mcm","clk":"4229503517","pt":1631518763439,"mc":[{"id":"1.187557247","rc":[{"batb":[[1,2.8,66.87]],"ltp":2.8,"tv":9.82,"id":9304761}]}]}
{"op":"mcm","clk":"4229503817","pt":1631518770042,"mc":[{"id":"1.187557247","rc":[{"batb":[[0,2.82,448.92]],"ltp":2.8,"tv":9.82,"id":9304761}]}]}
{"op":"mcm","clk":"4229507954","pt":1631518859240,"mc":[{"id":"1.187557247","rc":[{"batb":[[0,2.84,51.5],[1,2.82,448.56]],"batl":[[0,3.35,177.63]],"ltp":2.8,"tv":9.82,"id":9304761}]}]}
{"op":"mcm","clk":"4229508048","pt":1631518861962,"mc":[{"id":"1.187557247","rc":[{"batb":[[1,2.82,445]],"ltp":2.8,"tv":9.82,"id":9304761}]}]}
{"op":"mcm","clk":"4229509999","pt":1631518908609,"mc":[{"id":"1.187557247","rc":[{"batb":[[0,2.84,55.02]],"ltp":2.8,"tv":9.82,"id":9304761}]}]}
{"op":"mcm","clk":"4229510005","pt":1631518908813,"mc":[{"id":"1.187557247","rc":[{"batb":[[1,2.82,3]],"ltp":2.8,"tv":9.82,"id":9304761}]}]}
{"op":"mcm","clk":"4229510156","pt":1631518912205,"mc":[{"id":"1.187557247","rc":[{"batb":[[2,2.74,19.43]],"ltp":2.8,"tv":9.82,"id":9304761}]}]}
{"op":"mcm","clk":"4229515749","pt":1631519071631,"mc":[{"id":"1.187557247","rc":[{"batl":[[0,3.4,289.35]],"ltp":2.8,"tv":9.82,"id":9304761}]}]}
{"op":"mcm","clk":"4229538055","pt":1631519743158,"mc":[{"id":"1.187557247","rc":[{"batl":[[1,3.6,2.79]],"ltp":2.8,"tv":9.82,"id":9304761}]}]}
{"op":"mcm","clk":"4229549154","pt":1631519968754,"mc":[{"id":"1.187557247","rc":[{"batl":[[0,1.71,10.2],[1,1.89,2.66],[2,2.2,44.04]],"ltp":1.56,"tv":11.45,"id":10350473},{"batb":[[1,2.74,19.43],[2,1.71,24.98]],"batl":[[0,3.6,2.79],[1,29,48.45],[2,990,2.2]],"ltp":2.8,"tv":9.82,"id":9304761}]}]}
{"op":"mcm","clk":"4229549162","pt":1631519968958,"mc":[{"id":"1.187557247","rc":[{"batl":[[0,1.7,732.19],[1,1.71,10.2],[2,1.89,2.66]],"ltp":1.56,"tv":11.45,"id":10350473},{"batl":[[0,3.3,180.31],[1,3.6,2.79],[2,29,48.45]],"ltp":2.8,"tv":9.82,"id":9304761}]}]}
{"op":"mcm","clk":"4229549273","pt":1631519971573,"mc":[{"id":"1.187557247","rc":[{"batl":[[0,3.55,348.42]],"ltp":2.8,"tv":9.82,"id":9304761}]}]}
{"op":"mcm","clk":"4229553257","pt":1631520058563,"mc":[{"id":"1.187557247","rc":[{"batl":[[0,1.55,4.18],[1,1.7,732.19],[2,1.71,10.2]],"ltp":1.56,"tv":11.45,"id":10350473}]}]}
{"op":"mcm","clk":"4229553271","pt":1631520058819,"mc":[{"id":"1.187557247","rc":[{"batl":[[1,1.71,10.2],[2,1.89,2.66]],"ltp":1.56,"tv":11.45,"id":10350473}]}]}
{"op":"mcm","clk":"4229572466","pt":1631520387963,"mc":[{"id":"1.187557247","rc":[{"batb":[[1,2.74,18]],"ltp":2.8,"tv":9.82,"id":9304761}]}]}
{"op":"mcm","clk":"4229575797","pt":1631520440622,"mc":[{"id":"1.187557247","rc":[{"batl":[[1,1.62,3.44],[2,1.71,10.2]],"ltp":1.56,"tv":11.45,"id":10350473}]}]}
{"op":"mcm","clk":"4229621991","pt":1631521242451,"mc":[{"id":"1.187557247","rc":[{"trd":[[1.51,13.65]],"batb":[[0,1.51,850.76]],"ltp":1.51,"tv":25.1,"id":10350473}],"tv":34.93}]}
{"op":"mcm","clk":"4229627762","pt":1631521342790,"mc":[{"id":"1.187557247","rc":[{"batb":[[2,1.92,21.29]],"ltp":2.8,"tv":9.82,"id":9304761}]}]}
{"op":"mcm","clk":"4229651184","pt":1631521802800,"mc":[{"id":"1.187557247","rc":[{"batb":[[1,2.74,24]],"ltp":2.8,"tv":9.82,"id":9304761}]}]}
{"op":"mcm","clk":"4229662930","pt":1631522078644,"mc":[{"id":"1.187557247","rc":[{"batl":[[0,1.55,12.99]],"ltp":1.51,"tv":25.1,"id":10350473}]}]}
{"op":"mcm","clk":"4229666395","pt":1631522153764,"mc":[{"id":"1.187557247","rc":[{"batl":[[0,3.6,2.79],[1,29,48.45],[2,990,2.2]],"ltp":2.8,"tv":9.82,"id":9304761}]}]}
{"op":"mcm","clk":"4229666397","pt":1631522153866,"mc":[{"id":"1.187557247","rc":[{"batl":[[0,3.5,405.18],[1,3.6,2.79],[2,29,48.45]],"ltp":2.8,"tv":9.82,"id":9304761}]}]}
{"op":"mcm","clk":"4229666725","pt":1631522160967,"mc":[{"id":"1.187557247","rc":[{"batl":[[0,3.45,285.13]],"ltp":2.8,"tv":9.82,"id":9304761}]}]}
{"op":"mcm","clk":"4229675643","pt":1631522376708,"mc":[{"id":"1.187557247","rc":[{"batl":[[0,3.25,222.18]],"ltp":2.8,"tv":9.82,"id":9304761}]}]}
{"op":"mcm","clk":"4229682875","pt":1631522556104,"mc":[{"id":"1.187557247","rc":[{"batl":[[1,3.45,53.23],[2,3.6,2.79]],"ltp":2.8,"tv":9.82,"id":9304761}]}]}
{"op":"mcm","clk":"4229684197","pt":1631522583629,"mc":[{"id":"1.187557247","rc":[{"trd":[[1.51,103.66]],"batb":[[0,1.51,805.75]],"ltp":1.51,"tv":115.11,"id":10350473}],"tv":124.93}]}
{"op":"mcm","clk":"4229703617","pt":1631522961762,"mc":[{"id":"1.187557247","rc":[{"batb":[[0,2.84,54.67]],"ltp":2.8,"tv":9.82,"id":9304761}]}]}
{"op":"mcm","clk":"4229703627","pt":1631522961864,"mc":[{"id":"1.187557247","rc":[{"batb":[[0,2.84,55.02]],"ltp":2.8,"tv":9.82,"id":9304761}]}]}
{"op":"mcm","clk":"4229720418","pt":1631523288543,"mc":[{"id":"1.187557247","rc":[{"trd":[[1.51,105.33]],"batb":[[0,1.51,804.92]],"ltp":1.51,"tv":116.78,"id":10350473}],"tv":126.61}]}
{"op":"mcm","clk":"4229722772","pt":1631523343612,"mc":[{"id":"1.187557247","rc":[{"batl":[[2,1.89,2.66]],"ltp":1.51,"tv":116.78,"id":10350473},{"batl":[[2,29,48.45]],"ltp":2.8,"tv":9.82,"id":9304761}]}]}
{"op":"mcm","clk":"4229722787","pt":1631523343921,"mc":[{"id":"1.187557247","rc":[{"batl":[[2,1.71,10.2]],"ltp":1.51,"tv":116.78,"id":10350473},{"batl":[[2,3.6,2.79]],"ltp":2.8,"tv":9.82,"id":9304761}]}]}
{"op":"mcm","clk":"4229745407","pt":1631523828168,"mc":[{"id":"1.187557247","rc":[{"trd":[[1.51,105.34],[1.56,11.45]],"batb":[[0,1.51,805.05],[1,1.5,853.46],[2,1.49,878.75]],"batl":[[0,1.54,1.28],[1,1.55,12.99],[2,1.62,3.44]],"ltp":1.51,"tv":116.79,"id":10350473},{"trd":[[2.96,8.88]],"batb":[[0,2.84,55.03],[2,1.92,21.27]],"batl":[[1,3.45,53.28],[2,3.6,2.79]],"ltp":2.8,"tv":9.82,"id":9304761}],"tv":126.62}]}
{"op":"mcm","clk":"4229779739","pt":1631524393864,"mc":[{"id":"1.187557247","rc":[{"batb":[[2,1.11,718.61]],"batl":[[2,29,48.42]],"ltp":2.8,"tv":9.82,"id":9304761}]}]}
{"op":"mcm","clk":"4229835741","pt":1631525400458,"mc":[{"id":"1.187557247","rc":[{"batb":[[1,2.78,14.38],[2,2.74,24]],"ltp":2.8,"tv":9.82,"id":9304761}]}]}
{"op":"mcm","clk":"4229859291","pt":1631525765152,"mc":[{"id":"1.187557247","rc":[{"trd":[[1.53,0.67],[1.54,2.56],[1.55,2.1]],"batl":[[0,1.55,11.94],[1,1.62,3.44],[2,1.66,4.28]],"ltp":1.55,"tv":122.12,"id":10350473},{"trd":[[2.9,0.36]],"batb":[[0,2.84,54.68]],"ltp":2.9,"tv":10.18,"id":9304761}],"tv":132.3}]}
{"op":"mcm","clk":"4229864424","pt":1631525842662,"mc":[{"id":"1.187557247","rc":[{"batl":[[0,3.45,53.28],[1,29,48.42],[2,990,2.2]],"ltp":2.9,"tv":10.18,"id":9304761}]}]}
{"op":"mcm","clk":"4229864440","pt":1631525842868,"mc":[{"id":"1.187557247","rc":[{"batl":[[0,3.4,289.26],[1,3.45,53.28],[2,29,48.42]],"ltp":2.9,"tv":10.18,"id":9304761}]}]}
{"op":"mcm","clk":"4229867526","pt":1631525873115,"mc":[{"id":"1.187557247","rc":[{"trd":[[1.51,110.67]],"batb":[[0,1.51,802.39]],"ltp":1.51,"tv":127.45,"id":10350473}],"tv":137.63}]}
{"op":"mcm","clk":"4229867616","pt":1631525874204,"mc":[{"id":"1.187557247","rc":[{"batb":[[0,2.86,2.66],[1,2.84,54.68],[2,2.78,14.38]],"ltp":2.9,"tv":10.18,"id":9304761}]}]}
{"op":"mcm","clk":"4229896189","pt":1631526272172,"mc":[{"id":"1.187557247","rc":[{"trd":[[1.51,117.12]],"batb":[[0,1.51,799.16]],"ltp":1.51,"tv":133.9,"id":10350473}],"tv":144.08}]}
{"op":"mcm","clk":"4229896302","pt":1631526273569,"mc":[{"id":"1.187557247","rc":[{"trd":[[1.51,117.52]],"batb":[[0,1.51,798.97]],"ltp":1.51,"tv":134.3,"id":10350473}],"tv":144.48}]}
{"op":"mcm","clk":"4229924850","pt":1631526580101,"mc":[{"id":"1.187557247","rc":[{"batl":[[0,3.35,177.59]],"ltp":2.9,"tv":10.18,"id":9304761}]}]}
{"op":"mcm","clk":"4229935908","pt":1631526743037,"mc":[{"id":"1.187557247","rc":[{"batl":[[0,3.4,289.26]],"ltp":2.9,"tv":10.18,"id":9304761}]}]}
{"op":"mcm","clk":"4229972075","pt":1631527302643,"mc":[{"id":"1.187557247","rc":[{"batl":[[2,1.89,2.66]],"ltp":1.51,"tv":134.3,"id":10350473},{"batl":[[0,3.35,187.21]],"ltp":2.9,"tv":10.18,"id":9304761}]}]}
{"op":"mcm","clk":"4229974788","pt":1631527342975,"mc":[{"id":"1.187557247","rc":[{"batl":[[0,3.35,303.67]],"ltp":2.9,"tv":10.18,"id":9304761}]}]}
{"op":"mcm","clk":"4230011994","pt":1631527868339,"mc":[{"id":"1.187557247","rc":[{"batl":[[0,2.96,10.66]],"ltp":2.9,"tv":10.18,"id":9304761}]}]}
{"op":"mcm","clk":"4230013632","pt":1631527891134,"mc":[{"id":"1.187557247","rc":[{"trd":[[1.51,138.83]],"batb":[[0,1.51,788.31]],"ltp":1.51,"tv":155.61,"id":10350473}],"tv":165.8}]}
{"op":"mcm","clk":"4230041714","pt":1631528134321,"mc":[{"id":"1.187557247","rc":[{"batb":[[2,1.49,888.56]],"ltp":1.51,"tv":155.61,"id":10350473}]}]}
{"op":"mcm","clk":"4230045113","pt":1631528182144,"mc":[{"id":"1.187557247","rc":[{"batl":[[2,1.66,4.28]],"ltp":1.51,"tv":155.61,"id":10350473}]}]}
{"op":"mcm","clk":"4230087558","pt":1631528801642,"mc":[{"id":"1.187557247","rc":[{"batb":[[0,1.51,789.1]],"ltp":1.51,"tv":155.61,"id":10350473}]}]}
{"op":"mcm","clk":"4230100519","pt":1631528975499,"mc":[{"id":"1.187557247","rc":[{"trd":[[1.52,0.2]],"batb":[[0,1.51,789]],"ltp":1.52,"tv":155.81,"id":10350473}],"tv":166.0}]}
{"op":"mcm","clk":"4230101409","pt":1631528987498,"mc":[{"id":"1.187557247","rc":[{"trd":[[1.51,148.26],[1.52,1.58]],"batb":[[0,1.51,783.6]],"ltp":1.51,"tv":166.62,"id":10350473}],"tv":176.8}]}
{"op":"mcm","clk":"4230101994","pt":1631528995797,"mc":[{"id":"1.187557247","rc":[{"batl":[[0,1.54,2],[1,1.55,11.94],[2,1.62,3.44]],"ltp":1.51,"tv":166.62,"id":10350473},{"batl":[[0,2.96,12.66]],"ltp":2.9,"tv":10.18,"id":9304761}]}]}
{"op":"mcm","clk":"4230146202","pt":1631529543898,"mc":[{"id":"1.187557247","rc":[{"trd":[[1.54,4.56]],"batl":[[0,1.54,1]],"ltp":1.54,"tv":168.62,"id":10350473}],"tv":178.8}]}
{"op":"mcm","clk":"4230147515","pt":1631529559619,"mc":[{"id":"1.187557247","marketDefinition":{"bspMarket":false,"turnInPlayEnabled":true,"persistenceEnabled":true,"marketBaseRate":5.0,"eventId":"30896009","eventTypeId":"2","numberOfWinners":1,"bettingType":"ODDS","marketType":"MATCH_ODDS","marketTime":"2021-09-13T10:50:00.000Z","suspendTime":"2021-09-13T10:50:00.000Z","bspReconciled":false,"complete":true,"inPlay":false,"crossMatching":true,"runnersVoidable":false,"numberOfActiveRunners":2,"betDelay":0,"status":"OPEN","runners":[{"status":"ACTIVE","sortPriority":1,"id":9304761,"name":"Cristiana Ferrando"},{"status":"ACTIVE","sortPriority":2,"id":10350473,"name":"Yuliya Hatouka"}],"regulators":["MR_INT"],"discountAllowed":true,"timezone":"UTC","openDate":"2021-09-13T10:30:00.000Z","version":4030549666,"name":"Match Odds","eventName":"Ferrando v Yul Hatouka"}}]}
{"op":"mcm","clk":"4230147838","pt":1631529562633,"mc":[{"id":"1.187557247","marketDefinition":{"bspMarket":false,"turnInPlayEnabled":true,"persistenceEnabled":true,"marketBaseRate":5.0,"eventId":"30896009","eventTypeId":"2","numberOfWinners":1,"bettingType":"ODDS","marketType":"MATCH_ODDS","marketTime":"2021-09-13T10:50:00.000Z","suspendTime":"2021-09-13T10:50:00.000Z","bspReconciled":false,"complete":true,"inPlay":false,"crossMatching":true,"runnersVoidable":false,"numberOfActiveRunners":2,"betDelay":0,"status":"OPEN","runners":[{"status":"ACTIVE","sortPriority":1,"id":9304761,"name":"Cristiana Ferrando"},{"status":"ACTIVE","sortPriority":2,"id":10350473,"name":"Yuliya Hatouka"}],"regulators":["MR_INT"],"discountAllowed":true,"timezone":"UTC","openDate":"2021-09-13T10:50:00.000Z","version":4030549666,"name":"Match Odds","eventName":"Ferrando v Yul Hatouka"}}]}
{"op":"mcm","clk":"4230149724","pt":1631529587725,"mc":[{"id":"1.187557247","rc":[{"batb":[[0,1.52,1.93],[1,1.51,783.6],[2,1.5,853.46]],"ltp":1.54,"tv":168.62,"id":10350473}]}]}
{"op":"mcm","clk":"4230159916","pt":1631529717792,"mc":[{"id":"1.187557247","rc":[{"trd":[[1.52,2.68]],"batb":[[0,1.51,784.42],[1,1.5,853.46],[2,1.49,888.56]],"ltp":1.52,"tv":169.72,"id":10350473},{"trd":[[2.94,0.57]],"ltp":2.94,"tv":10.75,"id":9304761}],"tv":180.47}]}
{"op":"mcm","clk":"4230168541","pt":1631529823204,"mc":[{"id":"1.187557247","rc":[{"batl":[[2,1.66,4.28]],"ltp":1.52,"tv":169.72,"id":10350473}]}]}
{"op":"mcm","clk":"4230168890","pt":1631529827890,"mc":[{"id":"1.187557247","rc":[{"batl":[[0,1.53,3.44],[1,1.54,1],[2,1.55,11.94]],"ltp":1.52,"tv":169.72,"id":10350473}]}]}
{"op":"mcm","clk":"4230169530","pt":1631529835696,"mc":[{"id":"1.187557247","rc":[{"trd":[[1.52,3.51]],"batb":[[0,1.51,783.6]],"ltp":1.52,"tv":170.54,"id":10350473},{"trd":[[2.94,1]],"batb":[[0,2.86,2.81]],"ltp":2.94,"tv":11.17,"id":9304761}],"tv":181.72}]}
{"op":"mcm","clk":"4230169547","pt":1631529835906,"mc":[{"id":"1.187557247","rc":[{"trd":[[2.94,1.28]],"batb":[[0,2.86,2.66]],"ltp":2.94,"tv":11.45,"id":9304761}],"tv":182.0}]}
{"op":"mcm","clk":"4230179417","pt":1631529955039,"mc":[{"id":"1.187557247","rc":[{"batl":[[0,1.52,2],[1,1.53,3.44],[2,1.54,1]],"ltp":1.52,"tv":170.54,"id":10350473}]}]}
{"op":"mcm","clk":"4230183213","pt":1631529990718,"mc":[{"id":"1.187557247","rc":[{"trd":[[2.96,9.83]],"batl":[[0,2.96,12.18]],"ltp":2.96,"tv":12.41,"id":9304761}],"tv":182.96}]}
{"op":"mcm","clk":"4230186669","pt":1631530030671,"mc":[{"id":"1.187557247","rc":[{"batl":[[0,1.53,3.44],[1,1.54,1],[2,1.55,11.94]],"ltp":1.52,"tv":170.54,"id":10350473}]}]}
{"op":"mcm","clk":"4230186723","pt":1631530031239,"mc":[{"id":"1.187557247","rc":[{"trd":[[1.51,152.25]],"batb":[[0,1.51,781.6]],"ltp":1.51,"tv":174.54,"id":10350473}],"tv":186.96}]}
{"op":"mcm","clk":"4230190429","pt":1631530074723,"mc":[{"id":"1.187557247","rc":[{"batb":[[0,2.86,3.23]],"ltp":2.96,"tv":12.41,"id":9304761}]}]}
{"op":"mcm","clk":"4230190441","pt":1631530074827,"mc":[{"id":"1.187557247","rc":[{"trd":[[2.94,2.42]],"batb":[[0,2.86,2.66]],"ltp":2.94,"tv":13.55,"id":9304761}],"tv":188.1}]}
{"op":"mcm","clk":"4230203644","pt":1631530232117,"mc":[{"id":"1.187557247","rc":[{"batb":[[2,1.49,1056.55]],"ltp":1.51,"tv":174.54,"id":10350473},{"batb":[[2,2.82,47.15]],"ltp":2.94,"tv":13.55,"id":9304761}]}]}
{"op":"mcm","clk":"4230206587","pt":1631530268383,"mc":[{"id":"1.187557247","rc":[{"batl":[[0,1.54,1],[1,1.55,11.94],[2,1.66,4.28]],"ltp":1.51,"tv":174.54,"id":10350473}]}]}
{"op":"mcm","clk":"4230207052","pt":1631530273498,"mc":[{"id":"1.187557247","rc":[{"batl":[[0,1.52,3.44],[1,1.54,1],[2,1.55,11.94]],"ltp":1.51,"tv":174.54,"id":10350473}]}]}
{"op":"mcm","clk":"4230209182","pt":1631530299722,"mc":[{"id":"1.187557247","rc":[{"trd":[[1.52,10.4]],"batb":[[0,1.51,782.01]],"batl":[[0,1.54,1],[1,1.55,11.94],[2,1.66,4.28]],"ltp":1.52,"tv":181.43,"id":10350473}],"tv":194.98}]}
{"op":"mcm","clk":"4230215759","pt":1631530381121,"mc":[{"id":"1.187557247","rc":[{"trd":[[1.51,156.09],[1.52,11.21]],"batb":[[0,1.51,779.68]],"ltp":1.51,"tv":186.08,"id":10350473}],"tv":199.64}]}
{"op":"mcm","clk":"4230216557","pt":1631530392635,"mc":[{"id":"1.187557247","rc":[{"trd":[[1.54,7.89]],"batl":[[0,1.55,11.94],[1,1.66,4.28],[2,1.89,2.66]],"ltp":1.54,"tv":189.41,"id":10350473},{"trd":[[2.86,0.71]],"batb":[[0,2.86,1.95]],"ltp":2.86,"tv":14.26,"id":9304761}],"tv":203.68}]}
{"op":"mcm","clk":"4230219343","pt":1631530431468,"mc":[{"id":"1.187557247","rc":[{"batl":[[0,1.53,2.56],[1,1.55,11.94],[2,1.66,4.28]],"ltp":1.54,"tv":189.41,"id":10350473}]}]}
{"op":"mcm","clk":"4230219684","pt":1631530435576,"mc":[{"id":"1.187557247","rc":[{"batl":[[0,1.52,2.56]],"ltp":1.54,"tv":189.41,"id":10350473}]}]}
{"op":"mcm","clk":"4230219921","pt":1631530438585,"mc":[{"id":"1.187557247","rc":[{"trd":[[1.51,161.21]],"batb":[[0,1.51,777.12]],"batl":[[0,1.55,11.94],[1,1.66,4.28],[2,1.89,2.66]],"ltp":1.51,"tv":194.53,"id":10350473}],"tv":208.8}]}
{"op":"mcm","clk":"4230220823","pt":1631530450610,"mc":[{"id":"1.187557247","rc":[{"trd":[[1.54,11.51]],"batb":[[0,1.54,21.38],[1,1.51,777.12],[2,1.5,853.46]],"ltp":1.54,"tv":198.15,"id":10350473},{"trd":[[2.86,2.66]],"batb":[[0,2.84,54.68],[1,2.82,47.15],[2,2.74,38.71]],"ltp":2.86,"tv":16.21,"id":9304761}],"tv":214.37}]}
{"op":"mcm","clk":"4230221115","pt":1631530454389,"mc":[{"id":"1.187557247","rc":[{"batb":[[2,2.74,14.71]],"ltp":2.86,"tv":16.21,"id":9304761}]}]}
{"op":"mcm","clk":"4230221384","pt":1631530457474,"mc":[{"id":"1.187557247","marketDefinition":{"bspMarket":false,"turnInPlayEnabled":true,"persistenceEnabled":true,"marketBaseRate":5.0,"eventId":"30896009","eventTypeId":"2","numberOfWinners":1,"bettingType":"ODDS","marketType":"MATCH_ODDS","marketTime":"2021-09-13T11:00:00.000Z","suspendTime":"2021-09-13T11:00:00.000Z","bspReconciled":false,"complete":true,"inPlay":false,"crossMatching":true,"runnersVoidable":false,"numberOfActiveRunners":2,"betDelay":0,"status":"OPEN","runners":[{"status":"ACTIVE","sortPriority":1,"id":9304761,"name":"Cristiana Ferrando"},{"status":"ACTIVE","sortPriority":2,"id":10350473,"name":"Yuliya Hatouka"}],"regulators":["MR_INT"],"discountAllowed":true,"timezone":"UTC","openDate":"2021-09-13T10:50:00.000Z","version":4030564337,"name":"Match Odds","eventName":"Ferrando v Yul Hatouka"}}]}
{"op":"mcm","clk":"4230221622","pt":1631530460524,"mc":[{"id":"1.187557247","marketDefinition":{"bspMarket":false,"turnInPlayEnabled":true,"persistenceEnabled":true,"marketBaseRate":5.0,"eventId":"30896009","eventTypeId":"2","numberOfWinners":1,"bettingType":"ODDS","marketType":"MATCH_ODDS","marketTime":"2021-09-13T11:00:00.000Z","suspendTime":"2021-09-13T11:00:00.000Z","bspReconciled":false,"complete":true,"inPlay":false,"crossMatching":true,"runnersVoidable":false,"numberOfActiveRunners":2,"betDelay":0,"status":"OPEN","runners":[{"status":"ACTIVE","sortPriority":1,"id":9304761,"name":"Cristiana Ferrando"},{"status":"ACTIVE","sortPriority":2,"id":10350473,"name":"Yuliya Hatouka"}],"regulators":["MR_INT"],"discountAllowed":true,"timezone":"UTC","openDate":"2021-09-13T11:00:00.000Z","version":4030564337,"name":"Match Odds","eventName":"Ferrando v Yul Hatouka"}}]}
{"op":"mcm","clk":"4230221789","pt":1631530462396,"mc":[{"id":"1.187557247","rc":[{"batb":[[0,1.51,777.12],[1,1.5,853.46],[2,1.49,1056.55]],"ltp":1.54,"tv":198.15,"id":10350473}]}]}
{"op":"mcm","clk":"4230221891","pt":1631530463590,"mc":[{"id":"1.187557247","rc":[{"batb":[[2,2.78,14.38]],"ltp":2.86,"tv":16.21,"id":9304761}]}]}
{"op":"mcm","clk":"4230222758","pt":1631530476640,"mc":[{"id":"1.187557247","rc":[{"trd":[[1.55,34.04]],"batl":[[0,1.65,64.71]],"ltp":1.55,"tv":230.09,"id":10350473},{"trd":[[2.84,4.4]],"batb":[[0,2.84,70.99]],"ltp":2.84,"tv":20.62,"id":9304761}],"tv":250.71}]}
{"op":"mcm","clk":"4230223105","pt":1631530481710,"mc":[{"id":"1.187557247","rc":[{"batb":[[2,1.49,1021.45]],"ltp":1.55,"tv":230.09,"id":10350473},{"batb":[[0,2.84,3.52]],"ltp":2.84,"tv":20.62,"id":9304761}]}]}
{"op":"mcm","clk":"4230223183","pt":1631530482635,"mc":[{"id":"1.187557247","rc":[{"batb":[[2,2.76,14.55]],"ltp":2.84,"tv":20.62,"id":9304761}]}]}
{"op":"mcm","clk":"4230223430","pt":1631530486459,"mc":[{"id":"1.187557247","rc":[{"batb":[[0,2.82,417.7],[1,2.76,14.55],[2,2.74,38.71]],"ltp":2.84,"tv":20.62,"id":9304761}]}]}
{"op":"mcm","clk":"4230223849","pt":1631530492829,"mc":[{"id":"1.187557247","rc":[{"batb":[[0,2.82,421.26]],"ltp":2.84,"tv":20.62,"id":9304761}]}]}
{"op":"mcm","clk":"4230235077","pt":1631530647533,"mc":[{"id":"1.187557247","rc":[{"batb":[[0,2.88,22.21],[1,2.82,421.26],[2,2.76,14.55]],"ltp":2.84,"tv":20.62,"id":9304761}]}]}
{"op":"mcm","clk":"4230235162","pt":1631530648724,"mc":[{"id":"1.187557247","rc":[{"batb":[[2,2.8,14.23]],"ltp":2.84,"tv":20.62,"id":9304761}]}]}
{"op":"mcm","clk":"4230235489","pt":1631530652640,"mc":[{"id":"1.187557247","marketDefinition":{"bspMarket":false,"turnInPlayEnabled":true,"persistenceEnabled":true,"marketBaseRate":5.0,"eventId":"30896009","eventTypeId":"2","numberOfWinners":1,"bettingType":"ODDS","marketType":"MATCH_ODDS","marketTime":"2021-09-13T11:00:00.000Z","suspendTime":"2021-09-13T11:00:00.000Z","bspReconciled":false,"complete":true,"inPlay":false,"crossMatching":true,"runnersVoidable":false,"numberOfActiveRunners":2,"betDelay":0,"status":"OPEN","runners":[{"status":"ACTIVE","sortPriority":1,"id":9304761,"name":"Cristiana Ferrando"},{"status":"ACTIVE","sortPriority":2,"id":10350473,"name":"Yuliya Hatouka"}],"regulators":["MR_INT"],"discountAllowed":true,"timezone":"UTC","openDate":"2021-09-13T11:00:00.000Z","version":4030564337,"name":"Match Odds","eventName":"Ferrando v Yul Hatouka"},"rc":[{"batb":[[2,1.49,853.46]],"ltp":1.55,"tv":230.09,"id":10350473},{"batb":[[1,2.82,374.11]],"ltp":2.84,"tv":20.62,"id":9304761}]}]}
{"op":"mcm","clk":"4230235530","pt":1631530653169,"mc":[{"id":"1.187557247","marketDefinition":{"bspMarket":false,"turnInPlayEnabled":true,"persistenceEnabled":true,"marketBaseRate":5.0,"eventId":"30896009","eventTypeId":"2","numberOfWinners":1,"bettingType":"ODDS","marketType":"MATCH_ODDS","marketTime":"2021-09-13T11:00:00.000Z","suspendTime":"2021-09-13T11:00:00.000Z","bspReconciled":false,"complete":true,"inPlay":true,"crossMatching":true,"runnersVoidable":false,"numberOfActiveRunners":2,"betDelay":3,"status":"OPEN","runners":[{"status":"ACTIVE","sortPriority":1,"id":9304761,"name":"Cristiana Ferrando"},{"status":"ACTIVE","sortPriority":2,"id":10350473,"name":"Yuliya Hatouka"}],"regulators":["MR_INT"],"discountAllowed":true,"timezone":"UTC","openDate":"2021-09-13T11:00:00.000Z","version":4030567191,"name":"Match Odds","eventName":"Ferrando v Yul Hatouka"},"rc":[{"batl":[[0,1.66,4.28],[1,1.66,0],[2,1.89,0]],"ltp":1.55,"tv":230.09,"id":10350473},{"batb":[[0,1.2,2],[1,1.01,123.88],[2,2.8,0]],"batl":[[0,3.45,53.28],[1,3.45,0],[2,29,0]],"ltp":2.84,"tv":20.62,"id":9304761}]}]}
{"op":"mcm","clk":"4230236391","pt":1631530664257,"mc":[{"id":"1.187557247","rc":[{"trd":[[1.49,1706.48],[1.5,1706.49],[1.51,1715.06]],"batb":[[0,1.48,853.46],[1,1.47,854.46],[2,1.46,853.46]],"ltp":1.49,"tv":5196.91,"id":10350473}],"tv":5217.53}]}
{"op":"mcm","clk":"4230236519","pt":1631530665665,"mc":[{"id":"1.187557247","rc":[{"batb":[[0,3,97.4],[1,2.84,46.23],[2,2.4,554.22]],"ltp":2.84,"tv":20.62,"id":9304761}]}]}
{"op":"mcm","clk":"4230236688","pt":1631530667754,"mc":[{"id":"1.187557247","rc":[{"trd":[[1.48,744.35]],"batb":[[0,1.48,481.19]],"batl":[[0,1.65,6],[1,1.66,4.28]],"ltp":1.48,"tv":5941.26,"id":10350473},{"batb":[[1,2.98,3],[2,2.96,3]],"ltp":2.84,"tv":20.62,"id":9304761}],"tv":5961.88}]}
{"op":"mcm","clk":"4230236733","pt":1631530668272,"mc":[{"id":"1.187557247","rc":[{"batl":[[0,1.5,7],[1,1.65,6],[2,1.66,4.28]],"ltp":1.48,"tv":5941.26,"id":10350473}]}]}
{"op":"mcm","clk":"4230236972","pt":1631530671460,"mc":[{"id":"1.187557247","rc":[{"trd":[[1.48,1075.05]],"batb":[[0,1.48,315.8]],"batl":[[0,1.49,186.62],[1,1.5,7],[2,1.65,6]],"ltp":1.48,"tv":6271.96,"id":10350473},{"batl":[[0,3.45,98.96]],"ltp":2.84,"tv":20.62,"id":9304761}],"tv":6292.59}]}
{"op":"mcm","clk":"4230237221","pt":1631530674685,"mc":[{"id":"1.187557247","rc":[{"batl":[[0,1.65,6],[1,1.66,4.28],[2,1.65,0]],"ltp":1.48,"tv":6271.96,"id":10350473},{"batb":[[0,2.84,46.23],[1,2.52,3],[2,2.5,4]],"batl":[[0,3.45,53.28]],"ltp":2.84,"tv":20.62,"id":9304761}]}]}
{"op":"mcm","clk":"4230237325","pt":1631530676356,"mc":[{"id":"1.187557247","rc":[{"trd":[[1.48,1079.53]],"batb":[[0,1.48,313.56]],"ltp":1.48,"tv":6276.44,"id":10350473}],"tv":6297.06}]}
{"op":"mcm","clk":"4230237386","pt":1631530677180,"mc":[{"id":"1.187557247","rc":[{"batl":[[0,1.55,236.96],[1,1.56,155.37],[2,1.65,6]],"ltp":1.48,"tv":6276.44,"id":10350473}]}]}
{"op":"mcm","clk":"4230237453","pt":1631530678068,"mc":[{"id":"1.187557247","rc":[{"batl":[[0,1.65,6],[1,1.66,4.28],[2,1.65,0]],"ltp":1.48,"tv":6276.44,"id":10350473}]}]}
{"op":"mcm","clk":"4230237694","pt":1631530681673,"mc":[{"id":"1.187557247","rc":[{"batl":[[0,1.49,260.11],[1,1.5,180.35],[2,1.65,6]],"ltp":1.48,"tv":6276.44,"id":10350473},{"batb":[[2,1.2,2]],"ltp":2.84,"tv":20.62,"id":9304761}]}]}
{"op":"mcm","clk":"4230237939","pt":1631530684694,"mc":[{"id":"1.187557247","rc":[{"batl":[[0,1.65,6],[1,1.66,4.28],[2,1.65,0]],"ltp":1.48,"tv":6276.44,"id":10350473}]}]}
{"op":"mcm","clk":"4230238169","pt":1631530687703,"mc":[{"id":"1.187557247","rc":[{"batl":[[0,1.55,236.96],[1,1.56,155.37],[2,1.65,6]],"ltp":1.48,"tv":6276.44,"id":10350473}]}]}
{"op":"mcm","clk":"4230238365","pt":1631530690776,"mc":[{"id":"1.187557247","rc":[{"batb":[[1,1.2,2],[2,1.01,123.88]],"ltp":2.84,"tv":20.62,"id":9304761}]}]}
{"op":"mcm","clk":"4230238624","pt":1631530693681,"mc":[{"id":"1.187557247","rc":[{"batb":[[0,1.5,311.58],[1,1.49,1472.66],[2,1.48,1559.38]],"batl":[[0,1.55,242.96],[2,1.57,669.98]],"ltp":1.48,"tv":6276.44,"id":10350473},{"batl":[[1,3.6,5.56]],"ltp":2.84,"tv":20.62,"id":9304761}]}]}
{"op":"mcm","clk":"4230238717","pt":1631530694665,"mc":[{"id":"1.187557247","rc":[{"trd":[[1.5,1733.71]],"batb":[[0,1.5,297.97],[2,1.48,1729.97]],"batl":[[0,1.55,236.96]],"ltp":1.5,"tv":6303.66,"id":10350473},{"batb":[[1,2.62,56.36],[2,1.2,2]],"batl":[[0,3.4,226.02],[1,3.45,53.28],[2,3.6,5.56]],"ltp":2.84,"tv":20.62,"id":9304761}],"tv":6324.28}]}
{"op":"mcm","clk":"4230238794","pt":1631530695695,"mc":[{"id":"1.187557247","rc":[{"batb":[[1,2.8,3],[2,2.78,3]],"ltp":2.84,"tv":20.62,"id":9304761}]}]}
{"op":"mcm","clk":"4230239060","pt":1631530698395,"mc":[{"id":"1.187557247","rc":[{"batl":[[0,3.45,53.28],[1,3.6,5.56],[2,3.6,0]],"ltp":2.84,"tv":20.62,"id":9304761}]}]}
{"op":"mcm","clk":"4230239304","pt":1631530701567,"mc":[{"id":"1.187557247","rc":[{"batb":[[0,2.88,458.17],[1,2.84,46.23],[2,2.8,3]],"batl":[[0,3.4,191.78],[1,3.45,53.28],[2,3.6,5.56]],"ltp":2.84,"tv":20.62,"id":9304761}]}]}
{"op":"mcm","clk":"4230239671","pt":1631530706694,"mc":[{"id":"1.187557247","rc":[{"batb":[[1,1.49,189.1],[2,1.48,313.56]],"batl":[[2,1.65,6]],"ltp":1.5,"tv":6303.66,"id":10350473},{"batb":[[0,2.8,3],[1,2.78,3],[2,2.62,56.36]],"batl":[[0,3.45,53.28],[1,3.45,0],[2,3.6,0]],"ltp":2.84,"tv":20.62,"id":9304761}]}]}
{"op":"mcm","clk":"4230239684","pt":1631530706958,"mc":[{"id":"1.187557247","rc":[{"batb":[[0,1.48,313.56],[1,1.47,854.46],[2,1.46,853.46]],"batl":[[0,1.65,6],[1,1.66,4.28],[2,1.65,0]],"ltp":1.5,"tv":6303.66,"id":10350473},{"batb":[[0,2.62,56.36],[1,1.2,2],[2,1.01,123.88]],"ltp":2.84,"tv":20.62,"id":9304761}]}]}
{"op":"mcm","clk":"4230239886","pt":1631530709736,"mc":[{"id":"1.187557247","rc":[{"batl":[[0,1.62,203.57],[1,1.63,132.71],[2,1.65,6]],"ltp":1.5,"tv":6303.66,"id":10350473}]}]}
{"op":"mcm","clk":"4230239917","pt":1631530710147,"mc":[{"id":"1.187557247","rc":[{"batl":[[0,1.62,208.57]],"ltp":1.5,"tv":6303.66,"id":10350473},{"batb":[[0,2.62,60.36],[1,2.6,3],[2,1.2,2]],"ltp":2.84,"tv":20.62,"id":9304761}]}]}
{"op":"mcm","clk":"4230239984","pt":1631530710931,"mc":[{"id":"1.187557247","rc":[{"batl":[[0,1.62,5],[1,1.65,6],[2,1.66,4.28]],"ltp":1.5,"tv":6303.66,"id":10350473}]}]}
{"op":"mcm","clk":"4230240227","pt":1631530714452,"mc":[{"id":"1.187557247","rc":[{"batb":[[0,1.49,237.52],[1,1.48,507.48],[2,1.47,854.46]],"batl":[[0,1.53,163.65],[1,1.54,163.58],[2,1.62,5]],"ltp":1.5,"tv":6303.66,"id":10350473}]}]}
{"op":"mcm","clk":"4230240607","pt":1631530719660,"mc":[{"id":"1.187557247","rc":[{"batb":[[0,1.48,313.56],[1,1.47,854.46],[2,1.46,853.46]],"batl":[[0,1.62,5],[1,1.65,6],[2,1.66,4.28]],"ltp":1.5,"tv":6303.66,"id":10350473}]}]}
{"op":"mcm","clk":"4230240836","pt":1631530722662,"mc":[{"id":"1.187557247","rc":[{"batl":[[0,1.62,208.57],[1,1.63,132.71],[2,1.65,6]],"ltp":1.5,"tv":6303.66,"id":10350473}]}]}
{"op":"mcm","clk":"4230240861","pt":1631530723078,"mc":[{"id":"1.187557247","rc":[{"batl":[[2,1.66,4.28]],"ltp":1.5,"tv":6303.66,"id":10350473},{"batb":[[1,1.2,2],[2,1.01,123.88]],"ltp":2.84,"tv":20.62,"id":9304761}]}]}
{"op":"mcm","clk":"4230241109","pt":1631530726249,"mc":[{"id":"1.187557247","rc":[{"batb":[[1,2.6,3],[2,1.2,2]],"ltp":2.84,"tv":20.62,"id":9304761}]}]}
{"op":"mcm","clk":"4230241260","pt":1631530728062,"mc":[{"id":"1.187557247","rc":[{"batl":[[0,1.62,5],[1,1.66,4.28],[2,1.66,0]],"ltp":1.5,"tv":6303.66,"id":10350473}]}]}
{"op":"mcm","clk":"4230241460","pt":1631530730650,"mc":[{"id":"1.187557247","rc":[{"trd":[[1.47,28.17],[1.48,1706.49]],"batb":[[0,1.47,840.37],[1,1.46,853.46],[2,1.45,853.46]],"batl":[[0,1.48,1811.86],[1,1.62,5],[2,1.66,4.28]],"ltp":1.47,"tv":6958.79,"id":10350473},{"batb":[[0,3.05,1254.1],[1,3,1217.22],[2,2.98,1217.22]],"batl":[[0,3.4,1125],[1,3.45,1145.2],[2,3.5,1091.92]],"ltp":2.84,"tv":20.62,"id":9304761}],"tv":6979.41}]}
{"op":"mcm","clk":"4230241544","pt":1631530731688,"mc":[{"id":"1.187557247","rc":[{"batl":[[0,1.48,295.02],[1,1.49,184.97],[2,1.62,5]],"ltp":1.47,"tv":6958.79,"id":10350473},{"batb":[[0,3.05,627.06],[1,3,608.6],[2,2.98,608.6]],"batl":[[0,3.4,309.37],[1,3.45,353.56],[2,3.5,300.28]],"ltp":2.84,"tv":20.62,"id":9304761}]}]}
{"op":"mcm","clk":"4230241591","pt":1631530732156,"mc":[{"id":"1.187557247","rc":[{"batb":[[0,3.1,92.54],[1,3.05,627.06],[2,3,608.6]],"ltp":2.84,"tv":20.62,"id":9304761}]}]}
{"op":"mcm","clk":"4230241862","pt":1631530735685,"mc":[{"id":"1.187557247","rc":[{"batl":[[0,1.48,404.16]],"ltp":1.47,"tv":6958.79,"id":10350473},{"batl":[[0,3.3,25.6],[1,3.4,309.37],[2,3.45,353.56]],"ltp":2.84,"tv":20.62,"id":9304761}]}]}
{"op":"mcm","clk":"4230241873","pt":1631530735891,"mc":[{"id":"1.187557247","rc":[{"batl":[[0,1.48,295.02]],"ltp":1.47,"tv":6958.79,"id":10350473},{"batl":[[0,3.4,309.37],[1,3.45,353.56],[2,3.5,300.28]],"ltp":2.84,"tv":20.62,"id":9304761}]}]}
{"op":"mcm","clk":"4230241966","pt":1631530737294,"mc":[{"id":"1.187557247","rc":[{"batb":[[0,1.47,1069.37]],"ltp":1.47,"tv":6958.79,"id":10350473}]}]}
{"op":"mcm","clk":"4230242314","pt":1631530741713,"mc":[{"id":"1.187557247","rc":[{"batl":[[2,1.53,48.5]],"ltp":1.47,"tv":6958.79,"id":10350473},{"batl":[[1,3.45,357.46]],"ltp":2.84,"tv":20.62,"id":9304761}]}]}
{"op":"mcm","clk":"4230242383","pt":1631530742597,"mc":[{"id":"1.187557247","rc":[{"batl":[[0,1.53,48.5],[1,1.56,38.17],[2,1.62,5]],"ltp":1.47,"tv":6958.79,"id":10350473},{"batb":[[0,2.88,4.21],[1,2.84,45.72],[2,2.78,4.66]],"batl":[[0,3.45,57.18],[1,3.65,3.1],[2,3.5,0]],"ltp":2.84,"tv":20.62,"id":9304761}]}]}
{"op":"mcm","clk":"4230242439","pt":1631530743115,"mc":[{"id":"1.187557247","rc":[{"batb":[[0,1.47,840.37]],"batl":[[0,1.56,38.17],[1,1.62,5],[2,1.66,4.28]],"ltp":1.47,"tv":6958.79,"id":10350473},{"batb":[[0,2.84,45.72],[1,2.78,4.66],[2,2.62,4]],"ltp":2.84,"tv":20.62,"id":9304761}]}]}
{"op":"mcm","clk":"4230242574","pt":1631530745387,"mc":[{"id":"1.187557247","rc":[{"batl":[[0,1.54,139.32],[1,1.55,159.78],[2,1.56,38.17]],"ltp":1.47,"tv":6958.79,"id":10350473}]}]}
{"op":"mcm","clk":"4230242650","pt":1631530746319,"mc":[{"id":"1.187557247","rc":[{"batl":[[1,1.55,165.78]],"ltp":1.47,"tv":6958.79,"id":10350473},{"batb":[[0,2.84,48.72],[1,2.82,3],[2,2.78,4.66]],"ltp":2.84,"tv":20.62,"id":9304761}]}]}
{"op":"mcm","clk":"4230242859","pt":1631530749482,"mc":[{"id":"1.187557247","rc":[{"batl":[[0,1.53,51.5],[1,1.54,139.32],[2,1.55,165.78]],"ltp":1.47,"tv":6958.79,"id":10350473},{"batb":[[0,2.88,4.46],[1,2.84,48.72],[2,2.82,3]],"ltp":2.84,"tv":20.62,"id":9304761}]}]}
{"op":"mcm","clk":"4230242877","pt":1631530749789,"mc":[{"id":"1.187557247","rc":[{"batl":[[0,1.54,139.32],[1,1.55,165.78],[2,1.56,38.17]],"ltp":1.47,"tv":6958.79,"id":10350473},{"batb":[[0,2.84,48.72],[1,2.82,3],[2,2.78,4.66]],"ltp":2.84,"tv":20.62,"id":9304761}]}]}
{"op":"mcm","clk":"4230243461","pt":1631530758340,"mc":[{"id":"1.187557247","rc":[{"batb":[[1,2.78,4.66],[2,1.2,2]],"ltp":2.84,"tv":20.62,"id":9304761}]}]}
{"op":"mcm","clk":"4230243633","pt":1631530760110,"mc":[{"id":"1.187557247","rc":[{"batb":[[0,2.84,45.72]],"ltp":2.84,"tv":20.62,"id":9304761}]}]}
{"op":"mcm","clk":"4230243739","pt":1631530761620,"mc":[{"id":"1.187557247","rc":[{"batb":[[0,1.5,272.39],[1,1.49,188.72],[2,1.47,840.37]],"batl":[[2,1.56,712.45]],"ltp":1.47,"tv":6958.79,"id":10350473},{"batb":[[1,2.82,3],[2,2.78,4.66]],"batl":[[0,3.05,627.06],[1,3.1,608.6],[2,3.15,608.6]],"ltp":2.84,"tv":20.62,"id":9304761}]}]}
{"op":"mcm","clk":"4230243831","pt":1631530762406,"mc":[{"id":"1.187557247","rc":[{"trd":[[1.5,1761.11]],"batb":[[0,1.5,258.69],[2,1.48,172.26]],"batl":[[1,1.55,159.78]],"ltp":1.5,"tv":6986.19,"id":10350473},{"batb":[[1,2.78,4.66],[2,2.6,58.29]],"ltp":2.84,"tv":20.62,"id":9304761}],"tv":7006.81}]}
{"op":"mcm","clk":"4230243873","pt":1631530763029,"mc":[{"id":"1.187557247","rc":[{"batb":[[1,2.8,3],[2,2.78,4.66]],"ltp":2.84,"tv":20.62,"id":9304761}]}]}
{"op":"mcm","clk":"4230244565","pt":1631530773142,"mc":[{"id":"1.187557247","rc":[{"batb":[[0,1.5,246.54]],"ltp":1.5,"tv":6986.19,"id":10350473}]}]}
{"op":"mcm","clk":"4230244953","pt":1631530779747,"mc":[{"id":"1.187557247","rc":[{"batl":[[0,3.05,313.53],[1,3.1,304.3],[2,3.15,304.3]],"ltp":2.84,"tv":20.62,"id":9304761}]}]}
{"op":"mcm","clk":"4230245000","pt":1631530780266,"mc":[{"id":"1.187557247","rc":[{"batb":[[0,1.47,840.37],[1,1.46,853.46],[2,1.45,853.46]],"batl":[[0,1.63,39.5],[1,1.66,4.28],[2,1.56,0]],"ltp":1.5,"tv":6986.19,"id":10350473},{"batb":[[0,2.6,58.29],[1,2.58,5.06],[2,1.2,2]],"batl":[[0,3.4,3.29],[1,3.45,57.18],[2,3.65,3.1]],"ltp":2.84,"tv":20.62,"id":9304761}]}]}
{"op":"mcm","clk":"4230245120","pt":1631530781925,"mc":[{"id":"1.187557247","rc":[{"batb":[[0,1.54,70.59],[1,1.47,840.37],[2,1.46,853.46]],"ltp":1.5,"tv":6986.19,"id":10350473}]}]}
{"op":"mcm","clk":"4230245233","pt":1631530783638,"mc":[{"id":"1.187557247","rc":[{"batl":[[0,1.63,190.49],[1,1.64,130.12],[2,1.66,4.28]],"ltp":1.5,"tv":6986.19,"id":10350473},{"batb":[[0,2.6,61.29],[1,2.58,8.06]],"ltp":2.84,"tv":20.62,"id":9304761}]}]}
{"op":"mcm","clk":"4230245372","pt":1631530785565,"mc":[{"id":"1.187557247","rc":[{"batb":[[0,1.47,840.37],[1,1.46,853.46],[2,1.45,853.46]],"ltp":1.5,"tv":6986.19,"id":10350473}]}]}
{"op":"mcm","clk":"4230245459","pt":1631530786652,"mc":[{"id":"1.187557247","rc":[{"batb":[[0,2.68,3],[1,2.66,3],[2,2.6,61.29]],"ltp":2.84,"tv":20.62,"id":9304761}]}]}
{"op":"mcm","clk":"4230245495","pt":1631530787174,"mc":[{"id":"1.187557247","rc":[{"batl":[[0,1.6,6],[1,1.63,190.49],[2,1.64,130.12]],"ltp":1.5,"tv":6986.19,"id":10350473}]}]}
{"op":"mcm","clk":"4230245568","pt":1631530788165,"mc":[{"id":"1.187557247","rc":[{"batl":[[1,1.63,44.5],[2,1.66,4.28]],"ltp":1.5,"tv":6986.19,"id":10350473}]}]}
{"op":"mcm","clk":"4230245806","pt":1631530791638,"mc":[{"id":"1.187557247","rc":[{"trd":[[1.45,28.59],[1.46,1706.49],[1.47,1708.48]],"batb":[[0,1.45,839.17],[1,1.44,853.46],[2,1.42,1160.71]],"batl":[[0,1.46,295.97],[1,1.47,1496.41],[2,1.48,1262.74]],"ltp":1.45,"tv":10401.58,"id":10350473}],"tv":10422.2}]}
{"op":"mcm","clk":"4230245857","pt":1631530792368,"mc":[{"id":"1.187557247","rc":[{"batb":[[0,3.15,85.92],[1,2.92,7.81],[2,2.86,45.39]],"batl":[[0,3.4,12.97]],"ltp":2.84,"tv":20.62,"id":9304761}]}]}
{"op":"mcm","clk":"4230245935","pt":1631530793558,"mc":[{"id":"1.187557247","rc":[{"batl":[[1,1.47,1503.41]],"ltp":1.45,"tv":10401.58,"id":10350473},{"batb":[[0,3.15,88.92],[1,3.1,3]],"batl":[[0,3.4,3.29]],"ltp":2.84,"tv":20.62,"id":9304761}]}]}
{"op":"mcm","clk":"4230246131","pt":1631530796363,"mc":[{"id":"1.187557247","rc":[{"batb":[[2,2.98,7.57]],"batl":[[1,3.45,66.76]],"ltp":2.84,"tv":20.62,"id":9304761}]}]}
{"op":"mcm","clk":"4230246181","pt":1631530796992,"mc":[{"id":"1.187557247","rc":[{"batb":[[2,2.86,45.39]],"batl":[[1,3.45,57.18]],"ltp":2.84,"tv":20.62,"id":9304761}]}]}
{"op":"mcm","clk":"4230246284","pt":1631530798443,"mc":[{"id":"1.187557247","rc":[{"trd":[[1.46,2130.01]],"batl":[[0,1.46,84.21]],"ltp":1.46,"tv":10825.1,"id":10350473},{"batb":[[2,2.88,3.96]],"ltp":2.84,"tv":20.62,"id":9304761}],"tv":10845.72}]}
{"op":"mcm","clk":"4230246371","pt":1631530799589,"mc":[{"id":"1.187557247","rc":[{"batb":[[0,1.45,1118.17]],"ltp":1.46,"tv":10825.1,"id":10350473}]}]}
{"op":"mcm","clk":"4230246635","pt":1631530802375,"mc":[{"id":"1.187557247","rc":[{"batb":[[2,1.42,1273.2]],"batl":[[0,1.46,172.77]],"ltp":1.46,"tv":10825.1,"id":10350473}]}]}
{"op":"mcm","clk":"4230246726","pt":1631530803478,"mc":[{"id":"1.187557247","rc":[{"trd":[[1.45,28.56],[1.46,2128.34],[1.47,1706.81],[1.48,1704.81],[1.49,1704.81],[1.5,1759.44],[1.51,1713.33],[1.52,11.2],[1.54,11.5],[1.55,34.03],[1.56,11.45]],"batb":[[0,1.45,1116.52],[1,1.44,851.79],[2,1.42,1271.53]],"batl":[[1,1.47,202.39],[2,1.53,54.5]],"ltp":1.46,"tv":10814.94,"id":10350473},{"trd":[[2.84,4.4],[2.86,2.66],[2.94,2.41],[2.96,9.81]],"batb":[[0,3.15,88.86]],"batl":[[1,3.45,57.06]],"ltp":2.84,"tv":20.58,"id":9304761}],"tv":10835.52}]}
{"op":"mcm","clk":"4230246824","pt":1631530804478,"mc":[{"id":"1.187557247","rc":[{"batb":[[0,1.45,837.52],[2,1.42,851.79]],"batl":[[0,1.47,7],[1,1.53,54.5],[2,1.57,44.5]],"ltp":1.46,"tv":10814.94,"id":10350473},{"batb":[[0,3.15,3]],"batl":[[0,3.45,53.16],[1,3.95,2.7],[2,4.6,2.31]],"ltp":2.84,"tv":20.58,"id":9304761}]}]}
{"op":"mcm","clk":"4230246912","pt":1631530805472,"mc":[{"id":"1.187557247","rc":[{"trd":[[1.45,48.08]],"batb":[[0,1.45,827.76]],"batl":[[0,1.57,44.5],[1,1.63,39.5],[2,1.66,4.27]],"ltp":1.45,"tv":10834.46,"id":10350473},{"batb":[[0,2.86,45.35],[1,2.74,5.29],[2,2.58,5.06]],"ltp":2.84,"tv":20.58,"id":9304761}],"tv":10855.05}]}
{"op":"mcm","clk":"4230247105","pt":1631530807355,"mc":[{"id":"1.187557247","rc":[{"batl":[[0,1.55,217.57],[1,1.56,154.86],[2,1.57,44.5]],"ltp":1.45,"tv":10834.46,"id":10350473}]}]}
{"op":"mcm","clk":"4230247459","pt":1631530811713,"mc":[{"id":"1.187557247","rc":[{"batb":[[0,1.51,145.54],[1,1.5,213.82],[2,1.49,1283.56]],"batl":[[2,1.57,1262.64]],"ltp":1.45,"tv":10834.46,"id":10350473},{"batl":[[1,3.65,5.48],[2,3.95,2.7]],"ltp":2.84,"tv":20.58,"id":9304761}]}]}
{"op":"mcm","clk":"4230247576","pt":1631530812758,"mc":[{"id":"1.187557247","rc":[{"trd":[[1.51,1740.73]],"batb":[[0,1.51,131.84]],"ltp":1.51,"tv":10861.86,"id":10350473},{"batb":[[2,2.6,57.82]],"ltp":2.84,"tv":20.58,"id":9304761}],"tv":10882.45}]}
{"op":"mcm","clk":"4230247637","pt":1631530813696,"mc":[{"id":"1.187557247","rc":[{"batb":[[1,2.82,3],[2,2.8,3]],"ltp":2.84,"tv":20.58,"id":9304761}]}]}
{"op":"mcm","clk":"4230247707","pt":1631530814688,"mc":[{"id":"1.187557247","rc":[{"batl":[[0,3.2,3],[1,3.45,53.16],[2,3.65,5.48]],"ltp":2.84,"tv":20.58,"id":9304761}]}]}
{"op":"mcm","clk":"4230247852","pt":1631530816377,"mc":[{"id":"1.187557247","rc":[{"trd":[[1.51,2053.03]],"batb":[[0,1.51,46.69]],"batl":[[0,1.55,159.59],[1,1.57,1262.64],[2,1.58,650.28]],"ltp":1.51,"tv":11174.16,"id":10350473}],"tv":11194.75}]}
{"op":"mcm","clk":"4230247953","pt":1631530817585,"mc":[{"id":"1.187557247","rc":[{"trd":[[1.54,13.5]],"ltp":1.54,"tv":11176.16,"id":10350473},{"trd":[[2.86,3.73]],"batb":[[0,2.86,44.28]],"ltp":2.86,"tv":21.66,"id":9304761}],"tv":11197.82}]}
{"op":"mcm","clk":"4230248047","pt":1631530818476,"mc":[{"id":"1.187557247","rc":[{"batl":[[1,3.35,3.7],[2,3.45,53.16]],"ltp":2.86,"tv":21.66,"id":9304761}]}]}
{"op":"mcm","clk":"4230248116","pt":1631530819209,"mc":[{"id":"1.187557247","rc":[{"batb":[[1,1.5,279.37],[2,1.49,1472.07]],"batl":[[0,1.54,137.28],[1,1.55,159.59],[2,1.57,1262.64]],"ltp":1.54,"tv":11176.16,"id":10350473}]}]}
{"op":"mcm","clk":"4230248214","pt":1631530820408,"mc":[{"id":"1.187557247","rc":[{"trd":[[1.54,362.54]],"batb":[[1,1.5,213.84],[2,1.49,1283.56]],"batl":[[0,1.55,159.59],[1,1.57,1262.64],[2,1.58,650.28]],"ltp":1.54,"tv":11525.2,"id":10350473},{"trd":[[2.86,43.84]],"batb":[[0,2.86,4.17]],"batl":[[2,3.45,56.66]],"ltp":2.86,"tv":61.76,"id":9304761}],"tv":11586.97}]}
{"op":"mcm","clk":"4230248402","pt":1631530822706,"mc":[{"id":"1.187557247","rc":[{"batl":[[0,3.2,48.71]],"ltp":2.86,"tv":61.76,"id":9304761}]}]}
{"op":"mcm","clk":"4230248462","pt":1631530823382,"mc":[{"id":"1.187557247","rc":[{"batb":[[0,1.51,189.16],[1,1.5,182.3]],"batl":[[0,1.55,220.64],[1,1.56,154.87],[2,1.57,1262.64]],"ltp":1.54,"tv":11525.2,"id":10350473}]}]}
{"op":"mcm","clk":"4230248638","pt":1631530825522,"mc":[{"id":"1.187557247","rc":[{"batb":[[0,1.51,46.69],[1,1.45,827.76],[2,1.44,851.79]],"batl":[[0,1.62,35.25],[1,1.66,4.27],[2,1.57,0]],"ltp":1.54,"tv":11525.2,"id":10350473},{"batb":[[0,2.6,63.31],[1,1.8,11.85],[2,1.2,2]],"batl":[[0,3.35,3.7],[1,3.45,56.66],[2,3.65,3.1]],"ltp":2.86,"tv":61.76,"id":9304761}]}]}
{"op":"mcm","clk":"4230248670","pt":1631530826094,"mc":[{"id":"1.187557247","rc":[{"batb":[[0,1.45,827.76],[1,1.44,851.79],[2,1.43,54.43]],"ltp":1.54,"tv":11525.2,"id":10350473}]}]}
{"op":"mcm","clk":"4230248870","pt":1631530828690,"mc":[{"id":"1.187557247","rc":[{"batl":[[0,1.6,5],[1,1.62,40.25],[2,1.64,200.55]],"ltp":1.54,"tv":11525.2,"id":10350473},{"batb":[[0,2.68,3],[1,2.66,4],[2,2.6,9.49]],"ltp":2.86,"tv":61.76,"id":9304761}]}]}
{"op":"mcm","clk":"4230249094","pt":1631530831489,"mc":[{"id":"1.187557247","rc":[{"batl":[[2,1.66,4.27]],"ltp":1.54,"tv":11525.2,"id":10350473}]}]}
{"op":"mcm","clk":"4230249349","pt":1631530834721,"mc":[{"id":"1.187557247","rc":[{"trd":[[1.45,76.66]],"batb":[[0,1.45,813.47]],"batl":[[0,1.46,199.31],[1,1.47,1496.23],[2,1.48,1262.74]],"ltp":1.45,"tv":11553.78,"id":10350473}],"tv":11615.55}]}
{"op":"mcm","clk":"4230249420","pt":1631530835707,"mc":[{"id":"1.187557247","rc":[{"batb":[[0,3.15,86.53],[1,2.84,45.61],[2,2.68,3]],"ltp":2.86,"tv":61.76,"id":9304761}]}]}
{"op":"mcm","clk":"4230249563","pt":1631530837524,"mc":[{"id":"1.187557247","rc":[{"batb":[[0,3.15,89.53],[1,3.1,3],[2,2.84,45.61]],"ltp":2.86,"tv":61.76,"id":9304761}]}]}
{"op":"mcm","clk":"4230249709","pt":1631530839497,"mc":[{"id":"1.187557247","rc":[{"trd":[[1.45,264.09]],"batb":[[0,1.45,719.75]],"ltp":1.45,"tv":11741.21,"id":10350473}],"tv":11802.97}]}
{"op":"mcm","clk":"4230249766","pt":1631530840236,"mc":[{"id":"1.187557247","rc":[{"batb":[[0,1.45,1082.75]],"ltp":1.45,"tv":11741.21,"id":10350473}]}]}
{"op":"mcm","clk":"4230249856","pt":1631530841323,"mc":[{"id":"1.187557247","rc":[{"batb":[[2,2.88,5.21]],"ltp":2.86,"tv":61.76,"id":9304761}]}]}
{"op":"mcm","clk":"4230249961","pt":1631530842625,"mc":[{"id":"1.187557247","rc":[{"trd":[[1.46,2481.28]],"batb":[[2,1.42,851.79]],"batl":[[0,1.53,47.5],[1,1.57,43.5],[2,1.59,6]],"ltp":1.46,"tv":12094.15,"id":10350473},{"batl":[[0,3.45,53.16],[1,3.95,2.7],[2,4.6,2.31]],"ltp":2.86,"tv":61.76,"id":9304761}],"tv":12155.91}]}
{"op":"mcm","clk":"4230250035","pt":1631530843304,"mc":[{"id":"1.187557247","rc":[{"batb":[[0,1.45,719.75]],"batl":[[0,1.57,43.5],[1,1.59,6],[2,1.66,4.27]],"ltp":1.46,"tv":12094.15,"id":10350473},{"batb":[[0,3.15,3],[2,2.84,45.61]],"ltp":2.86,"tv":61.76,"id":9304761}]}]}
{"op":"mcm","clk":"4230250212","pt":1631530845731,"mc":[{"id":"1.187557247","rc":[{"batl":[[0,1.47,7],[1,1.57,43.5],[2,1.59,6]],"ltp":1.46,"tv":12094.15,"id":10350473},{"batb":[[0,2.84,45.61],[1,2.74,5.29],[2,2.7,3]],"ltp":2.86,"tv":61.76,"id":9304761}]}]}
{"op":"mcm","clk":"4230250274","pt":1631530846524,"mc":[{"id":"1.187557247","rc":[{"batl":[[0,1.53,48.5],[1,1.55,150.41],[2,1.56,154.68]],"ltp":1.46,"tv":12094.15,"id":10350473},{"batb":[[0,2.88,4.21],[1,2.84,45.61],[2,2.74,5.29]],"ltp":2.86,"tv":61.76,"id":9304761}]}]}
{"op":"mcm","clk":"4230250349","pt":1631530847411,"mc":[{"id":"1.187557247","rc":[{"batl":[[0,1.55,150.41],[1,1.56,154.68],[2,1.57,43.5]],"ltp":1.46,"tv":12094.15,"id":10350473},{"batb":[[0,2.84,45.61],[1,2.74,5.29],[2,2.7,3]],"ltp":2.86,"tv":61.76,"id":9304761}]}]}
{"op":"mcm","clk":"4230250458","pt":1631530848707,"mc":[{"id":"1.187557247","rc":[{"batl":[[0,1.55,155.41]],"ltp":1.46,"tv":12094.15,"id":10350473},{"batb":[[0,2.84,48.61],[1,2.82,3],[2,2.74,5.29]],"ltp":2.86,"tv":61.76,"id":9304761}]}]}
{"op":"mcm","clk":"4230250587","pt":1631530850323,"mc":[{"id":"1.187557247","rc":[{"batl":[[0,1.54,5],[1,1.55,155.41],[2,1.56,154.68]],"ltp":1.46,"tv":12094.15,"id":10350473}]}]}
{"op":"mcm","clk":"4230250807","pt":1631530853534,"mc":[{"id":"1.187557247","rc":[{"batl":[[0,1.53,50.5],[1,1.54,5],[2,1.55,155.41]],"ltp":1.46,"tv":12094.15,"id":10350473},{"batb":[[0,2.88,4.46],[1,2.84,48.61],[2,2.82,3]],"ltp":2.86,"tv":61.76,"id":9304761}]}]}
{"op":"mcm","clk":"4230250828","pt":1631530853843,"mc":[{"id":"1.187557247","rc":[{"batl":[[0,1.54,5],[1,1.55,155.41],[2,1.56,154.68]],"ltp":1.46,"tv":12094.15,"id":10350473},{"batb":[[0,2.84,48.61],[1,2.82,3],[2,2.74,5.29]],"ltp":2.86,"tv":61.76,"id":9304761}]}]}
{"op":"mcm","clk":"4230251185","pt":1631530858928,"mc":[{"id":"1.187557247","rc":[{"batl":[[0,1.55,155.41],[1,1.56,154.68],[2,1.57,43.5]],"ltp":1.46,"tv":12094.15,"id":10350473},{"batb":[[0,2.84,45.61]],"ltp":2.86,"tv":61.76,"id":9304761}]}]}
{"op":"mcm","clk":"4230251332","pt":1631530860754,"mc":[{"id":"1.187557247","rc":[{"batl":[[0,1.53,45.5],[1,1.55,155.41],[2,1.56,154.68]],"ltp":1.46,"tv":12094.15,"id":10350473},{"batb":[[0,2.88,4.96],[1,2.84,45.61],[2,2.82,3]],"ltp":2.86,"tv":61.76,"id":9304761}]}]}
{"op":"mcm","clk":"4230251420","pt":1631530861655,"mc":[{"id":"1.187557247","rc":[{"batb":[[0,1.51,4025.5],[1,1.5,182.11],[2,1.49,1283.56]],"batl":[[0,1.55,155.41],[1,1.56,154.68],[2,1.57,713.48]],"ltp":1.46,"tv":12094.15,"id":10350473},{"batb":[[0,2.84,45.61],[1,2.82,3],[2,2.74,5.29]],"batl":[[1,3.65,5.48],[2,3.95,2.7]],"ltp":2.86,"tv":61.76,"id":9304761}]}]}
{"op":"mcm","clk":"4230251518","pt":1631530862542,"mc":[{"id":"1.187557247","rc":[{"trd":[[1.51,2080.43]],"batb":[[0,1.51,236.26],[2,1.49,1455.77]],"ltp":1.51,"tv":12121.55,"id":10350473}],"tv":12183.31}]}
{"op":"mcm","clk":"4230251656","pt":1631530863743,"mc":[{"id":"1.187557247","rc":[{"batb":[[2,2.8,3]],"batl":[[0,3.2,3],[1,3.45,53.16],[2,3.65,5.48]],"ltp":2.86,"tv":61.76,"id":9304761}]}]}
{"op":"mcm","clk":"4230251801","pt":1631530865568,"mc":[{"id":"1.187557247","rc":[{"trd":[[1.51,2166.57]],"batb":[[0,1.51,193.19]],"ltp":1.51,"tv":12207.69,"id":10350473}],"tv":12269.45}]}
{"op":"mcm","clk":"4230252082","pt":1631530868569,"mc":[{"id":"1.187557247","rc":[{"batl":[[1,3.35,4.1],[2,3.45,53.16]],"ltp":2.86,"tv":61.76,"id":9304761}]}]}
{"op":"mcm","clk":"4230252148","pt":1631530869251,"mc":[{"id":"1.187557247","rc":[{"trd":[[1.55,316.39]],"batl":[[0,1.55,5]],"ltp":1.55,"tv":12490.05,"id":10350473}],"tv":12551.81}]}
{"op":"mcm","clk":"4230252362","pt":1631530872091,"mc":[{"id":"1.187557247","rc":[{"batb":[[0,1.51,282.44]],"batl":[[1,1.56,237.65],[2,1.57,863.67]],"ltp":1.55,"tv":12490.05,"id":10350473}]}]}
{"op":"mcm","clk":"4230253197","pt":1631530882476,"mc":[{"id":"1.187557247","rc":[{"batb":[[0,1.45,719.75],[1,1.44,851.79],[2,1.43,65.43]],"batl":[[0,1.64,35.68],[1,1.66,4.27],[2,1.57,0]],"ltp":1.55,"tv":12490.05,"id":10350473},{"batb":[[0,2.6,58.16],[1,2.56,5.33],[2,1.8,11.85]],"batl":[[0,3.35,4.1],[1,3.45,53.16],[2,3.65,3.1]],"ltp":2.86,"tv":61.76,"id":9304761}]}]}
{"op":"mcm","clk":"4230253439","pt":1631530885672,"mc":[{"id":"1.187557247","rc":[{"batb":[[2,1.43,321.84]],"batl":[[0,1.6,45.86],[1,1.63,6],[2,1.64,35.68]],"ltp":1.55,"tv":12490.05,"id":10350473},{"batb":[[0,2.66,5.28],[1,2.6,58.16],[2,2.56,5.33]],"ltp":2.86,"tv":61.76,"id":9304761}]}]}
{"op":"mcm","clk":"4230253463","pt":1631530886082,"mc":[{"id":"1.187557247","rc":[{"batl":[[0,1.63,6],[1,1.64,35.68],[2,1.65,195.52]],"ltp":1.55,"tv":12490.05,"id":10350473},{"batb":[[0,2.6,58.16],[1,2.56,5.33],[2,1.8,11.85]],"ltp":2.86,"tv":61.76,"id":9304761}]}]}
{"op":"mcm","clk":"4230253950","pt":1631530893097,"mc":[{"id":"1.187557247","rc":[{"batb":[[2,1.43,65.43]],"ltp":1.55,"tv":12490.05,"id":10350473}]}]}
{"op":"mcm","clk":"4230254137","pt":1631530895685,"mc":[{"id":"1.187557247","rc":[{"batb":[[0,1.61,3057.18],[1,1.6,183.3],[2,1.59,145.1]],"batl":[[0,1.64,35.68],[1,1.65,195.52],[2,1.66,4.27]],"ltp":1.55,"tv":12490.05,"id":10350473},{"batb":[[2,2.46,1554.88]],"batl":[[0,2.72,1406.24],[1,2.74,1364.88],[2,2.76,1364.88]],"ltp":2.86,"tv":61.76,"id":9304761}]}]}
{"op":"mcm","clk":"4230254213","pt":1631530896677,"mc":[{"id":"1.187557247","rc":[{"trd":[[1.61,26.32]],"batb":[[0,1.61,11.1]],"ltp":1.61,"tv":12516.37,"id":10350473},{"batb":[[2,2.46,777.44]],"batl":[[0,2.72,703.12],[1,2.74,682.44],[2,2.76,682.44]],"ltp":2.86,"tv":61.76,"id":9304761}],"tv":12578.13}]}
{"op":"mcm","clk":"4230254356","pt":1631530898607,"mc":[{"id":"1.187557247","rc":[{"batb":[[1,2.56,8.33],[2,2.54,3]],"ltp":2.86,"tv":61.76,"id":9304761}]}]}
{"op":"mcm","clk":"4230254502","pt":1631530900680,"mc":[{"id":"1.187557247","rc":[{"trd":[[1.61,48.52]],"batb":[[0,1.6,183.3],[1,1.59,145.1],[2,1.57,141]],"ltp":1.61,"tv":12538.57,"id":10350473}],"tv":12600.33}]}
{"op":"mcm","clk":"4230254745","pt":1631530903906,"mc":[{"id":"1.187557247","rc":[{"trd":[[1.63,28.24]],"ltp":1.63,"tv":12566.81,"id":10350473},{"trd":[[2.6,17.7]],"batb":[[0,2.6,40.45]],"ltp":2.6,"tv":79.47,"id":9304761}],"tv":12646.28}]}
{"op":"mcm","clk":"4230255327","pt":1631530910206,"mc":[{"id":"1.187557247","rc":[{"batb":[[0,1.6,261.3]],"ltp":1.63,"tv":12566.81,"id":10350473},{"batb":[[2,2.48,6.01]],"ltp":2.6,"tv":79.47,"id":9304761}]}]}
{"op":"mcm","clk":"4230255434","pt":1631530911719,"mc":[{"id":"1.187557247","rc":[{"batl":[[0,2.94,4.25],[1,3.15,4.5],[2,3.35,4.1]],"ltp":2.6,"tv":79.47,"id":9304761}]}]}
{"op":"mcm","clk":"4230255484","pt":1631530912339,"mc":[{"id":"1.187557247","rc":[{"trd":[[1.6,100]],"batb":[[0,1.6,28],[1,1.52,44.74],[2,1.48,173.64]],"batl":[[0,1.66,4.27],[1,1.7,34.35],[2,1.66,0]],"ltp":1.6,"tv":12666.81,"id":10350473},{"batb":[[0,2.42,6.94],[1,2.4,71.8],[2,1.8,11.85]],"ltp":2.6,"tv":79.47,"id":9304761}],"tv":12746.28}]}
{"op":"mcm","clk":"4230255573","pt":1631530913711,"mc":[{"id":"1.187557247","rc":[{"batb":[[0,1.48,173.64],[1,1.47,57.67],[2,1.45,719.75]],"ltp":1.6,"tv":12666.81,"id":10350473},{"batl":[[0,3.15,4.5],[1,3.35,4.1],[2,3.45,53.16]],"ltp":2.6,"tv":79.47,"id":9304761}]}]}
{"op":"mcm","clk":"4230255692","pt":1631530915640,"mc":[{"id":"1.187557247","rc":[{"batb":[[0,1.51,246.28],[1,1.5,181.89],[2,1.49,172.8]],"batl":[[1,1.67,33.5],[2,1.7,34.35]],"ltp":1.6,"tv":12666.81,"id":10350473},{"batb":[[0,2.48,6.51],[1,2.42,6.94],[2,2.4,71.8]],"ltp":2.6,"tv":79.47,"id":9304761}]}]}
{"op":"mcm","clk":"4230255785","pt":1631530916527,"mc":[{"id":"1.187557247","rc":[{"batb":[[0,1.52,55.99],[1,1.51,3]],"batl":[[1,1.7,34.35],[2,1.7,0]],"ltp":1.6,"tv":12666.81,"id":10350473},{"batb":[[0,2.42,6.94],[1,2.4,71.8],[2,1.8,11.85]],"batl":[[0,2.94,7.75],[1,3.1,3],[2,3.15,4.5]],"ltp":2.6,"tv":79.47,"id":9304761}]}]}
{"op":"mcm","clk":"4230255866","pt":1631530917305,"mc":[{"id":"1.187557247","rc":[{"batb":[[0,1.52,4]],"ltp":1.6,"tv":12666.81,"id":10350473},{"batl":[[0,2.94,3]],"ltp":2.6,"tv":79.47,"id":9304761}]}]}
{"op":"mcm","clk":"4230255973","pt":1631530918445,"mc":[{"id":"1.187557247","rc":[{"batb":[[2,1.5,4]],"ltp":1.6,"tv":12666.81,"id":10350473},{"batl":[[1,2.98,2],[2,3.1,3]],"ltp":2.6,"tv":79.47,"id":9304761}]}]}
{"op":"mcm","clk":"4230256059","pt":1631530919731,"mc":[{"id":"1.187557247","rc":[{"batb":[[0,1.58,211.72],[1,1.57,152.25],[2,1.52,4]],"batl":[[0,1.63,194.67],[1,1.64,128.7],[2,1.66,4.27]],"ltp":1.6,"tv":12666.81,"id":10350473},{"batl":[[2,3.05,3]],"ltp":2.6,"tv":79.47,"id":9304761}]}]}
{"op":"mcm","clk":"4230256090","pt":1631530920040,"mc":[{"id":"1.187557247","rc":[{"batb":[[2,1.52,51.49]],"ltp":1.6,"tv":12666.81,"id":10350473},{"batl":[[0,2.94,7.25]],"ltp":2.6,"tv":79.47,"id":9304761}]}]}
{"op":"mcm","clk":"4230256308","pt":1631530922716,"mc":[{"id":"1.187557247","rc":[{"batb":[[0,1.52,51.49],[1,1.51,3],[2,1.5,4]],"batl":[[0,1.66,4.27],[1,1.7,34.35],[2,1.66,0]],"ltp":1.6,"tv":12666.81,"id":10350473}]}]}
{"op":"mcm","clk":"4230256368","pt":1631530923440,"mc":[{"id":"1.187557247","rc":[{"batb":[[0,1.52,4]],"ltp":1.6,"tv":12666.81,"id":10350473},{"batl":[[0,2.94,3]],"ltp":2.6,"tv":79.47,"id":9304761}]}]}
{"op":"mcm","clk":"4230256549","pt":1631530925649,"mc":[{"id":"1.187557247","rc":[{"batb":[[1,1.51,249.28],[2,1.5,185.89]],"batl":[[2,1.74,142.66]],"ltp":1.6,"tv":12666.81,"id":10350473}]}]}
{"op":"mcm","clk":"4230256635","pt":1631530926643,"mc":[{"id":"1.187557247","rc":[{"batl":[[1,1.67,41.5],[2,1.7,34.35]],"ltp":1.6,"tv":12666.81,"id":10350473},{"batb":[[0,2.48,5.26],[1,2.42,6.94],[2,2.4,71.8]],"ltp":2.6,"tv":79.47,"id":9304761}]}]}
{"op":"mcm","clk":"4230256657","pt":1631530926956,"mc":[{"id":"1.187557247","rc":[{"batl":[[1,1.7,34.35],[2,1.74,142.66]],"ltp":1.6,"tv":12666.81,"id":10350473},{"batb":[[0,2.42,6.94],[1,2.4,71.8],[2,1.8,11.85]],"ltp":2.6,"tv":79.47,"id":9304761}]}]}
{"op":"mcm","clk":"4230256771","pt":1631530928761,"mc":[{"id":"1.187557247","rc":[{"batb":[[1,1.5,4],[2,1.49,172.8]],"ltp":1.6,"tv":12666.81,"id":10350473},{"batl":[[0,2.98,2],[1,3.05,3],[2,3.15,4.5]],"ltp":2.6,"tv":79.47,"id":9304761}]}]}
{"op":"mcm","clk":"4230256824","pt":1631530929544,"mc":[{"id":"1.187557247","rc":[{"batb":[[0,1.52,54.99]],"ltp":1.6,"tv":12666.81,"id":10350473},{"batl":[[0,2.94,4.25],[1,2.98,2],[2,3.05,3]],"ltp":2.6,"tv":79.47,"id":9304761}]}]}
{"op":"mcm","clk":"4230256891","pt":1631530930534,"mc":[{"id":"1.187557247","rc":[{"batb":[[0,1.52,4],[1,1.49,172.8],[2,1.47,57.67]],"ltp":1.6,"tv":12666.81,"id":10350473},{"batl":[[0,2.98,2],[1,3.15,4.5],[2,3.45,53.16]],"ltp":2.6,"tv":79.47,"id":9304761}]}]}
{"op":"mcm","clk":"4230256962","pt":1631530931519,"mc":[{"id":"1.187557247","rc":[{"trd":[[1.66,8.54]],"batb":[[0,1.69,137.82],[1,1.67,241.62],[2,1.66,1152.12]],"batl":[[0,1.7,34.35],[1,1.74,142.66],[2,1.76,204.38]],"ltp":1.66,"tv":12675.35,"id":10350473},{"batb":[[2,2.3,457.34]],"batl":[[1,3.1,6.45],[2,3.15,4.5]],"ltp":2.6,"tv":79.47,"id":9304761}],"tv":12754.82}]}
{"op":"mcm","clk":"4230257037","pt":1631530932565,"mc":[{"id":"1.187557247","rc":[{"trd":[[1.69,25.32]],"batb":[[0,1.69,125.16],[2,1.66,1269.11]],"ltp":1.69,"tv":12700.67,"id":10350473}],"tv":12780.14}]}
{"op":"mcm","clk":"4230257074","pt":1631530933026,"mc":[{"id":"1.187557247","rc":[{"batl":[[0,2.92,3],[1,2.98,2],[2,3.1,6.45]],"ltp":2.6,"tv":79.47,"id":9304761}]}]}
{"op":"mcm","clk":"4230257158","pt":1631530934368,"mc":[{"id":"1.187557247","rc":[{"trd":[[1.69,27.1]],"batb":[[0,1.69,123.38]],"ltp":1.69,"tv":12702.45,"id":10350473},{"trd":[[2.46,1.22]],"batl":[[0,2.6,3],[1,2.68,3],[2,2.92,3]],"ltp":2.46,"tv":80.69,"id":9304761}],"tv":12783.14}]}
{"op":"mcm","clk":"4230257360","pt":1631530936752,"mc":[{"id":"1.187557247","rc":[{"trd":[[1.69,113.18]],"batb":[[0,1.66,1269.11],[1,1.65,1118.22],[2,1.64,1118.22]],"ltp":1.69,"tv":12788.53,"id":10350473}],"tv":12869.22}]}
{"op":"mcm","clk":"4230257416","pt":1631530937431,"mc":[{"id":"1.187557247","rc":[{"trd":[[1.66,41.94]],"batb":[[0,1.66,1235.71]],"ltp":1.66,"tv":12821.93,"id":10350473},{"trd":[[2.52,22]],"ltp":2.52,"tv":102.69,"id":9304761}],"tv":12924.62}]}
{"op":"mcm","clk":"4230257586","pt":1631530939665,"mc":[{"id":"1.187557247","rc":[{"batb":[[0,1.68,224.67],[1,1.66,1483.18],[2,1.65,1118.22]],"batl":[[1,1.74,174.56]],"ltp":1.66,"tv":12821.93,"id":10350473}]}]}
{"op":"mcm","clk":"4230257653","pt":1631530940756,"mc":[{"id":"1.187557247","rc":[{"trd":[[1.7,56.48]],"batl":[[0,1.7,6.11]],"ltp":1.7,"tv":12878.41,"id":10350473}],"tv":12981.1}]}
{"op":"mcm","clk":"4230257827","pt":1631530943260,"mc":[{"id":"1.187557247","rc":[{"trd":[[1.7,59.96]],"batl":[[0,1.7,4.37]],"ltp":1.7,"tv":12881.89,"id":10350473}],"tv":12984.59}]}
{"op":"mcm","clk":"4230258053","pt":1631530946476,"mc":[{"id":"1.187557247","rc":[{"batl":[[1,1.71,15],[2,1.74,174.56]],"ltp":1.7,"tv":12881.89,"id":10350473},{"batb":[[1,2.4,82.51]],"batl":[[1,3.1,6.45],[2,3.15,4.5]],"ltp":2.52,"tv":102.69,"id":9304761}]}]}
{"op":"mcm","clk":"4230258334","pt":1631530949661,"mc":[{"id":"1.187557247","rc":[{"batl":[[1,2.7,11.5],[2,3.1,6.45]],"ltp":2.52,"tv":102.69,"id":9304761}]}]}
{"op":"mcm","clk":"4230258579","pt":1631530952381,"mc":[{"id":"1.187557247","rc":[{"batl":[[0,1.7,6.37]],"ltp":1.7,"tv":12881.89,"id":10350473}]}]}
{"op":"mcm","clk":"4230259513","pt":1631530963264,"mc":[{"id":"1.187557247","rc":[{"trd":[[1.68,10.42]],"batb":[[0,1.68,219.46]],"ltp":1.68,"tv":12892.31,"id":10350473}],"tv":12995.0}]}
{"op":"mcm","clk":"4230259858","pt":1631530967586,"mc":[{"id":"1.187557247","rc":[{"trd":[[1.68,10.46],[1.7,60.12]],"batb":[[0,1.68,219.42]],"batl":[[0,1.7,6.29]],"ltp":1.7,"tv":12892.51,"id":10350473},{"trd":[[2.48,0.03]],"ltp":2.48,"tv":102.72,"id":9304761}],"tv":12995.23}]}
{"op":"mcm","clk":"4230259966","pt":1631530968900,"mc":[{"id":"1.187557247","rc":[{"batb":[[0,1.66,1235.71],[1,1.65,1118.22],[2,1.64,1118.22]],"batl":[[2,1.74,0]],"ltp":1.7,"tv":12892.51,"id":10350473}]}]}
{"op":"mcm","clk":"4230260183","pt":1631530972065,"mc":[{"id":"1.187557247","rc":[{"batl":[[2,1.84,140.43]],"ltp":1.7,"tv":12892.51,"id":10350473}]}]}
{"op":"mcm","clk":"4230261380","pt":1631530985710,"mc":[{"id":"1.187557247","rc":[{"trd":[[1.66,74.58]],"batb":[[0,1.66,1203.07]],"ltp":1.66,"tv":12925.15,"id":10350473},{"trd":[[2.52,43.5]],"ltp":2.52,"tv":124.22,"id":9304761}],"tv":13049.37}]}
{"op":"mcm","clk":"4230261507","pt":1631530987321,"mc":[{"id":"1.187557247","rc":[{"batb":[[0,1.61,265.18],[1,1.6,142.28],[2,1.59,138.81]],"batl":[[0,1.7,2]],"ltp":1.66,"tv":12925.15,"id":10350473},{"batb":[[0,2.4,10.71],[1,2.22,88.95],[2,1.8,11.85]],"batl":[[0,2.7,11.5],[1,3.15,4.5],[2,3.45,53.16]],"ltp":2.52,"tv":124.22,"id":9304761}]}]}
{"op":"mcm","clk":"4230261596","pt":1631530988425,"mc":[{"id":"1.187557247","rc":[{"batl":[[1,1.84,140.43],[2,1.86,171.62]],"ltp":1.66,"tv":12925.15,"id":10350473},{"batb":[[0,2.22,88.95],[1,1.8,11.85],[2,1.7,16.93]],"batl":[[0,3.15,4.5],[1,3.45,53.16],[2,3.45,0]],"ltp":2.52,"tv":124.22,"id":9304761}]}]}
{"op":"mcm","clk":"4230261770","pt":1631530990615,"mc":[{"id":"1.187557247","rc":[{"batb":[[1,1.6,179.17]],"batl":[[1,1.82,31.75],[2,1.84,140.43]],"ltp":1.66,"tv":12925.15,"id":10350473},{"batb":[[1,2.2,7.17],[2,1.8,11.85]],"batl":[[0,2.68,5.14],[1,2.8,4.87],[2,3.45,53.16]],"ltp":2.52,"tv":124.22,"id":9304761}]}]}
{"op":"mcm","clk":"4230261836","pt":1631530991603,"mc":[{"id":"1.187557247","rc":[{"batb":[[0,2.22,92.95],[1,2.2,11.17]],"ltp":2.52,"tv":124.22,"id":9304761}]}]}
{"op":"mcm","clk":"4230262026","pt":1631530993729,"mc":[{"id":"1.187557247","rc":[{"batb":[[0,2.28,3],[1,2.26,4],[2,2.22,92.95]],"ltp":2.52,"tv":124.22,"id":9304761}]}]}
{"op":"mcm","clk":"4230262430","pt":1631530998721,"mc":[{"id":"1.187557247","rc":[{"batb":[[0,1.6,36.89],[1,1.59,138.81],[2,1.56,49.08]],"ltp":1.66,"tv":12925.15,"id":10350473}]}]}
{"op":"mcm","clk":"4230262459","pt":1631530999033,"mc":[{"id":"1.187557247","rc":[{"batb":[[0,1.59,138.81],[1,1.56,49.08],[2,1.45,719.75]],"ltp":1.66,"tv":12925.15,"id":10350473},{"batl":[[0,2.8,4.87],[1,3.45,53.16],[2,3.45,0]],"ltp":2.52,"tv":124.22,"id":9304761}]}]}
{"op":"mcm","clk":"4230262603","pt":1631531000701,"mc":[{"id":"1.187557247","rc":[{"trd":[[1.7,62.12]],"batl":[[0,1.82,31.75],[1,1.84,140.43],[2,1.86,171.62]],"ltp":1.7,"tv":12927.15,"id":10350473},{"trd":[[2.42,1.4]],"batb":[[0,2.22,88.95],[1,2.2,11.17],[2,1.8,11.85]],"batl":[[0,2.34,2583.22],[1,2.5,6.26],[2,2.8,4.87]],"ltp":2.42,"tv":125.62,"id":9304761}],"tv":13052.77}]}
{"op":"mcm","clk":"4230262696","pt":1631531001746,"mc":[{"id":"1.187557247","rc":[{"batb":[[0,1.78,158.44],[1,1.76,202.44],[2,1.75,2170.45]],"ltp":1.7,"tv":12927.15,"id":10350473},{"batl":[[0,2.4,3.69],[1,2.8,4.87],[2,2.86,6.99]],"ltp":2.42,"tv":125.62,"id":9304761}]}]}
{"op":"mcm","clk":"4230262799","pt":1631531002741,"mc":[{"id":"1.187557247","rc":[{"trd":[[1.78,24.4]],"batb":[[0,1.78,146.24],[2,1.75,1730.38]],"batl":[[1,1.84,300.08],[2,1.85,79.82]],"ltp":1.78,"tv":12951.55,"id":10350473},{"batb":[[2,2.06,111.21]],"ltp":2.42,"tv":125.62,"id":9304761}],"tv":13077.17}]}
{"op":"mcm","clk":"4230262887","pt":1631531003732,"mc":[{"id":"1.187557247","rc":[{"batl":[[0,1.81,15],[1,1.82,31.75],[2,1.84,300.08]],"ltp":1.78,"tv":12951.55,"id":10350473},{"batb":[[0,2.22,101.24],[2,2.18,3]],"batl":[[1,2.52,12.16],[2,2.68,3]],"ltp":2.42,"tv":125.62,"id":9304761}]}]}
{"op":"mcm","clk":"4230263129","pt":1631531006751,"mc":[{"id":"1.187557247","rc":[{"trd":[[1.78,72.48]],"batb":[[0,1.78,122.2]],"ltp":1.78,"tv":12999.63,"id":10350473},{"batl":[[1,2.68,3],[2,2.76,147.23]],"ltp":2.42,"tv":125.62,"id":9304761}],"tv":13125.25}]}
{"op":"mcm","clk":"4230263220","pt":1631531007740,"mc":[{"id":"1.187557247","rc":[{"batl":[[2,2.8,4.87]],"ltp":2.42,"tv":125.62,"id":9304761}]}]}
{"op":"mcm","clk":"4230263327","pt":1631531009143,"mc":[{"id":"1.187557247","rc":[{"batl":[[1,2.48,12.32],[2,2.5,5.99]],"ltp":2.42,"tv":125.62,"id":9304761}]}]}
{"op":"mcm","clk":"4230263449","pt":1631531010734,"mc":[{"id":"1.187557247","rc":[{"trd":[[1.78,216.04]],"batb":[[0,1.75,1730.38],[1,1.74,134.28],[2,1.73,134.28]],"batl":[[2,1.84,320.41]],"ltp":1.78,"tv":13143.19,"id":10350473}],"tv":13268.81}]}
{"op":"mcm","clk":"4230263584","pt":1631531012561,"mc":[{"id":"1.187557247","rc":[{"batb":[[0,1.67,113.39],[1,1.61,43.09],[2,1.6,5]],"batl":[[1,1.98,24.75],[2,1.84,0]],"ltp":1.78,"tv":13143.19,"id":10350473},{"batb":[[0,2.22,12.29],[1,2.06,111.21],[2,2.02,8.24]],"batl":[[0,2.48,12.32],[1,2.64,4.68],[2,2.68,3]],"ltp":2.42,"tv":125.62,"id":9304761}]}]}
{"op":"mcm","clk":"4230263681","pt":1631531013753,"mc":[{"id":"1.187557247","rc":[{"batb":[[0,1.81,7.5],[1,1.67,113.39],[2,1.61,43.09]],"batl":[[0,1.98,24.75],[1,1.98,0]],"ltp":1.78,"tv":13143.19,"id":10350473},{"batb":[[0,2.06,111.21],[1,2.02,8.24],[2,1.86,404.12]],"batl":[[0,2.64,4.68],[1,2.68,3],[2,2.8,4.87]],"ltp":2.42,"tv":125.62,"id":9304761}]}]}
{"op":"mcm","clk":"4230263845","pt":1631531015742,"mc":[{"id":"1.187557247","rc":[{"batb":[[1,1.69,165.02],[2,1.67,392.17]],"batl":[[0,1.92,25.56],[1,1.96,138.24],[2,1.98,166.86]],"ltp":1.78,"tv":13143.19,"id":10350473},{"batb":[[0,2.08,7.81],[1,2.06,111.21],[2,2.02,8.24]],"batl":[[0,2.5,5.45],[1,2.64,4.68],[2,2.68,3]],"ltp":2.42,"tv":125.62,"id":9304761}]}]}
{"op":"mcm","clk":"4230263936","pt":1631531016734,"mc":[{"id":"1.187557247","rc":[{"batl":[[0,1.95,5],[1,1.98,24.75],[2,1.98,0]],"ltp":1.78,"tv":13143.19,"id":10350473},{"batb":[[0,2.06,116.21],[1,2.04,4]],"batl":[[0,2.5,9.45]],"ltp":2.42,"tv":125.62,"id":9304761}]}]}
{"op":"mcm","clk":"4230264040","pt":1631531018246,"mc":[{"id":"1.187557247","rc":[{"batl":[[0,2.5,5.45]],"ltp":2.42,"tv":125.62,"id":9304761}]}]}
{"op":"mcm","clk":"4230264130","pt":1631531019751,"mc":[{"id":"1.187557247","rc":[{"trd":[[1.69,138.34],[1.81,15]],"batb":[[0,1.69,152.44],[1,1.67,392.17],[2,1.66,2304.22]],"batl":[[0,1.74,1761.52],[1,1.75,221],[2,1.76,2173.3]],"ltp":1.69,"tv":13183.35,"id":10350473},{"batb":[[0,2.08,621.74],[1,2.06,116.21],[2,2.04,4]],"ltp":2.42,"tv":125.62,"id":9304761}],"tv":13308.97}]}
{"op":"mcm","clk":"4230264211","pt":1631531020745,"mc":[{"id":"1.187557247","rc":[{"batb":[[2,1.66,633.67]],"batl":[[0,1.74,14.02],[1,1.76,1086.64],[2,1.77,1054.68]],"ltp":1.69,"tv":13183.35,"id":10350473},{"batb":[[0,2.36,74.81],[1,2.18,93.89],[2,2.08,4]],"ltp":2.42,"tv":125.62,"id":9304761}]}]}
{"op":"mcm","clk":"4230264270","pt":1631531021531,"mc":[{"id":"1.187557247","rc":[{"batb":[[0,2.36,85.83],[1,2.24,4],[2,2.22,4]],"batl":[[2,2.68,14.57]],"ltp":2.42,"tv":125.62,"id":9304761}]}]}
{"op":"mcm","clk":"4230264397","pt":1631531023262,"mc":[{"id":"1.187557247","rc":[{"batl":[[0,1.74,139.56],[1,1.76,1291.63]],"ltp":1.69,"tv":13183.35,"id":10350473}]}]}
{"op":"mcm","clk":"4230264544","pt":1631531025040,"mc":[{"id":"1.187557247","rc":[{"batl":[[0,1.74,154.56]],"ltp":1.69,"tv":13183.35,"id":10350473}]}]}
{"op":"mcm","clk":"4230264635","pt":1631531026145,"mc":[{"id":"1.187557247","rc":[{"batl":[[1,2.58,5.75],[2,2.64,4.68]],"ltp":2.42,"tv":125.62,"id":9304761}]}]}
{"op":"mcm","clk":"4230264844","pt":1631531028341,"mc":[{"id":"1.187557247","rc":[{"batb":[[2,2.22,10.84]],"ltp":2.42,"tv":125.62,"id":9304761}]}]}
{"op":"mcm","clk":"4230265037","pt":1631531030647,"mc":[{"id":"1.187557247","rc":[{"trd":[[1.74,9.76]],"batl":[[0,1.74,149.68]],"ltp":1.74,"tv":13193.11,"id":10350473}],"tv":13318.73}]}
{"op":"mcm","clk":"4230265110","pt":1631531031378,"mc":[{"id":"1.187557247","rc":[{"trd":[[1.74,425.53],[1.76,1585.46]],"batl":[[0,1.76,293.91],[1,1.77,1054.68],[2,1.78,1054.68]],"ltp":1.76,"tv":15194.34,"id":10350473},{"trd":[[2.36,85.83]],"batb":[[0,2.24,4],[1,2.22,10.84],[2,2.18,93.89]],"ltp":2.36,"tv":211.45,"id":9304761}],"tv":15405.79}]}
{"op":"mcm","clk":"4230265207","pt":1631531032686,"mc":[{"id":"1.187557247","rc":[{"trd":[[1.69,147.94]],"batb":[[0,1.64,38.82],[1,1.61,43.09],[2,1.6,138.55]],"batl":[[0,1.87,31.5],[1,1.91,29.5],[2,1.93,4]],"ltp":1.69,"tv":15203.94,"id":10350473},{"batb":[[0,2.18,93.89],[1,2.14,7.82],[2,2.08,4]],"batl":[[0,2.58,5.75],[1,2.64,4.68],[2,2.68,3]],"ltp":2.36,"tv":211.45,"id":9304761}],"tv":15415.39}]}
{"op":"mcm","clk":"4230265255","pt":1631531033366,"mc":[{"id":"1.187557247","rc":[{"batb":[[0,1.61,43.09],[1,1.6,138.55],[2,1.59,44.11]],"ltp":1.69,"tv":15203.94,"id":10350473},{"batl":[[0,2.64,4.68],[1,2.68,3],[2,2.7,4.75]],"ltp":2.36,"tv":211.45,"id":9304761}]}]}
{"op":"mcm","clk":"4230265458","pt":1631531035652,"mc":[{"id":"1.187557247","rc":[{"batb":[[0,1.61,174.13]],"ltp":1.69,"tv":15203.94,"id":10350473},{"batb":[[1,2.16,95.9],[2,2.14,7.82]],"ltp":2.36,"tv":211.45,"id":9304761}]}]}
{"op":"mcm","clk":"4230265528","pt":1631531036488,"mc":[{"id":"1.187557247","rc":[{"batb":[[0,1.63,6],[1,1.62,5],[2,1.61,179.13]],"batl":[[0,1.85,4],[1,1.87,31.5],[2,1.91,29.5]],"ltp":1.69,"tv":15203.94,"id":10350473},{"batb":[[0,2.18,3],[1,2.16,98.9]],"batl":[[0,2.58,3],[1,2.64,8.68],[2,2.68,3]],"ltp":2.36,"tv":211.45,"id":9304761}]}]}
{"op":"mcm","clk":"4230265644","pt":1631531037748,"mc":[{"id":"1.187557247","rc":[{"batl":[[0,1.84,123.51],[1,1.85,4],[2,1.87,31.5]],"ltp":1.69,"tv":15203.94,"id":10350473}]}]}
{"op":"mcm","clk":"4230265714","pt":1631531038692,"mc":[{"id":"1.187557247","rc":[{"batl":[[0,1.85,4],[1,1.87,31.5],[2,1.93,4]],"ltp":1.69,"tv":15203.94,"id":10350473}]}]}
{"op":"mcm","clk":"4230265798","pt":1631531039680,"mc":[{"id":"1.187557247","rc":[{"trd":[[1.72,44.32]],"batb":[[0,1.72,99.75],[1,1.7,227.33],[2,1.69,20.21]],"batl":[[0,1.77,132.42],[1,1.79,193.74],[2,1.81,31.5]],"ltp":1.72,"tv":15248.26,"id":10350473},{"batb":[[0,2.22,6.34],[1,2.18,3],[2,2.16,98.9]],"batl":[[0,2.46,20.25],[1,2.58,8.44],[2,2.64,8.68]],"ltp":2.36,"tv":211.45,"id":9304761}],"tv":15459.71}]}
{"op":"mcm","clk":"4230265886","pt":1631531040683,"mc":[{"id":"1.187557247","rc":[{"batb":[[0,1.63,6],[1,1.62,5],[2,1.61,179.13]],"batl":[[2,1.84,4]],"ltp":1.72,"tv":15248.26,"id":10350473},{"batb":[[0,2.18,3],[1,2.16,98.9],[2,2.14,7.82]],"batl":[[0,2.58,3],[1,2.64,8.68],[2,2.68,3]],"ltp":2.36,"tv":211.45,"id":9304761}]}]}
{"op":"mcm","clk":"4230266153","pt":1631531043683,"mc":[{"id":"1.187557247","rc":[{"batb":[[0,1.64,36.07],[1,1.63,6],[2,1.62,137.88]],"batl":[[2,1.81,30.5]],"ltp":1.72,"tv":15248.26,"id":10350473},{"batb":[[0,2.22,7.84],[1,2.18,3],[2,2.16,98.9]],"batl":[[0,2.58,7.94]],"ltp":2.36,"tv":211.45,"id":9304761}]}]}
{"op":"mcm","clk":"4230266191","pt":1631531044095,"mc":[{"id":"1.187557247","rc":[{"batb":[[0,1.71,222.36],[1,1.69,232.57],[2,1.63,6]],"ltp":1.72,"tv":15248.26,"id":10350473},{"batl":[[0,2.58,3]],"ltp":2.36,"tv":211.45,"id":9304761}]}]}
{"op":"mcm","clk":"4230266330","pt":1631531045506,"mc":[{"id":"1.187557247","rc":[{"batb":[[0,1.63,6],[1,1.62,137.88],[2,1.61,179.13]],"batl":[[0,1.84,4],[1,1.85,136.88],[2,1.87,31.5]],"ltp":1.72,"tv":15248.26,"id":10350473},{"batb":[[0,2.18,3],[1,2.16,98.9],[2,2.14,7.82]],"ltp":2.36,"tv":211.45,"id":9304761}]}]}
{"op":"mcm","clk":"4230266472","pt":1631531047268,"mc":[{"id":"1.187557247","rc":[{"batl":[[1,1.85,132.88]],"ltp":1.72,"tv":15248.26,"id":10350473},{"batb":[[1,2.16,95.9]],"batl":[[0,2.64,8.68],[1,2.7,4.75],[2,2.8,4.87]],"ltp":2.36,"tv":211.45,"id":9304761}]}]}
{"op":"mcm","clk":"4230266574","pt":1631531048682,"mc":[{"id":"1.187557247","rc":[{"batb":[[1,1.62,132.88],[2,1.61,426.01]],"batl":[[0,1.81,26.71],[1,1.84,4],[2,1.85,132.88]],"ltp":1.72,"tv":15248.26,"id":10350473},{"batb":[[0,2.22,7.43],[1,2.18,3],[2,2.16,95.9]],"ltp":2.36,"tv":211.45,"id":9304761}]}]}
{"op":"mcm","clk":"4230266606","pt":1631531048996,"mc":[{"id":"1.187557247","rc":[{"batl":[[0,1.84,4],[1,1.85,132.88],[2,1.87,194.14]],"ltp":1.72,"tv":15248.26,"id":10350473},{"batb":[[0,2.18,3],[1,2.16,95.9],[2,2.14,7.82]],"ltp":2.36,"tv":211.45,"id":9304761}]}]}
{"op":"mcm","clk":"4230266750","pt":1631531050764,"mc":[{"id":"1.187557247","rc":[{"batb":[[0,1.64,39.07],[1,1.63,6],[2,1.62,132.88]],"ltp":1.72,"tv":15248.26,"id":10350473},{"batb":[[1,2.16,98.9]],"batl":[[0,2.58,5.75],[1,2.6,3],[2,2.64,8.68]],"ltp":2.36,"tv":211.45,"id":9304761}]}]}
{"op":"mcm","clk":"4230266791","pt":1631531051389,"mc":[{"id":"1.187557247","rc":[{"batb":[[0,1.63,6],[1,1.62,136.88],[2,1.61,426.01]],"ltp":1.72,"tv":15248.26,"id":10350473},{"batl":[[0,2.6,3],[1,2.64,8.68],[2,2.7,4.75]],"ltp":2.36,"tv":211.45,"id":9304761}]}]}
{"op":"mcm","clk":"4230267035","pt":1631531054622,"mc":[{"id":"1.187557247","rc":[{"batl":[[2,1.87,31.5]],"ltp":1.72,"tv":15248.26,"id":10350473},{"batl":[[0,2.58,3],[1,2.6,3],[2,2.64,8.68]],"ltp":2.36,"tv":211.45,"id":9304761}]}]}
{"op":"mcm","clk":"4230267122","pt":1631531055717,"mc":[{"id":"1.187557247","rc":[{"batb":[[1,1.62,4]],"batl":[[1,1.87,31.5],[2,1.87,0]],"ltp":1.72,"tv":15248.26,"id":10350473}]}]}
{"op":"mcm","clk":"4230267174","pt":1631531056297,"mc":[{"id":"1.187557247","rc":[{"batb":[[0,1.61,426.01],[1,1.6,142.27],[2,1.59,44.11]],"ltp":1.72,"tv":15248.26,"id":10350473},{"batl":[[0,2.64,4.68],[1,2.7,4.75],[2,2.8,4.87]],"ltp":2.36,"tv":211.45,"id":9304761}]}]}
{"op":"mcm","clk":"4230267291","pt":1631531057700,"mc":[{"id":"1.187557247","rc":[{"trd":[[1.61,74.5]],"batb":[[0,1.61,413.02]],"batl":[[0,1.67,1403.54],[1,1.68,1111.54],[2,1.69,1345.04]],"ltp":1.61,"tv":15274.24,"id":10350473},{"batl":[[2,2.72,386.72]],"ltp":2.36,"tv":211.45,"id":9304761}],"tv":15485.69}]}
{"op":"mcm","clk":"4230267375","pt":1631531058588,"mc":[{"id":"1.187557247","rc":[{"batl":[[0,1.65,60],[1,1.67,1403.54],[2,1.68,1111.54]],"ltp":1.61,"tv":15274.24,"id":10350473},{"batb":[[0,2.52,63.35],[1,2.32,78.74],[2,2.18,3]],"ltp":2.36,"tv":211.45,"id":9304761}]}]}
{"op":"mcm","clk":"4230267456","pt":1631531059524,"mc":[{"id":"1.187557247","rc":[{"batb":[[2,2.2,3]],"ltp":2.36,"tv":211.45,"id":9304761}]}]}
{"op":"mcm","clk":"4230267545","pt":1631531060417,"mc":[{"id":"1.187557247","rc":[{"batl":[[1,1.66,6],[2,1.67,1403.54]],"ltp":1.61,"tv":15274.24,"id":10350473},{"batb":[[1,2.5,3],[2,2.48,4]],"ltp":2.36,"tv":211.45,"id":9304761}]}]}
{"op":"mcm","clk":"4230267661","pt":1631531061624,"mc":[{"id":"1.187557247","rc":[{"batb":[[0,2.54,38.96],[1,2.52,66.35],[2,2.5,3]],"ltp":2.36,"tv":211.45,"id":9304761}]}]}
{"op":"mcm","clk":"4230267750","pt":1631531062617,"mc":[{"id":"1.187557247","rc":[{"batl":[[0,1.66,6],[1,1.67,1403.54],[2,1.68,1111.54]],"ltp":1.61,"tv":15274.24,"id":10350473}]}]}
{"op":"mcm","clk":"4230267964","pt":1631531065544,"mc":[{"id":"1.187557247","rc":[{"trd":[[1.61,156.5]],"batb":[[0,1.61,372.02]],"batl":[[0,1.64,60],[1,1.66,6],[2,1.67,1403.54]],"ltp":1.61,"tv":15356.24,"id":10350473}],"tv":15567.69}]}
{"op":"mcm","clk":"4230268204","pt":1631531068838,"mc":[{"id":"1.187557247","rc":[{"batl":[[2,1.67,1384.66]],"ltp":1.61,"tv":15356.24,"id":10350473}]}]}
{"op":"mcm","clk":"4230268371","pt":1631531070633,"mc":[{"id":"1.187557247","rc":[{"trd":[[1.64,20.82]],"batl":[[0,1.64,49.59]],"ltp":1.64,"tv":15377.06,"id":10350473}],"tv":15588.52}]}
{"op":"mcm","clk":"4230268521","pt":1631531072450,"mc":[{"id":"1.187557247","rc":[{"batb":[[0,1.61,440.02]],"ltp":1.64,"tv":15377.06,"id":10350473},{"batb":[[2,2.36,5.93]],"ltp":2.36,"tv":211.45,"id":9304761}]}]}
{"op":"mcm","clk":"4230268664","pt":1631531074215,"mc":[{"id":"1.187557247","rc":[{"batb":[[0,1.61,319.88],[2,1.58,42.56]],"batl":[[0,1.64,60],[1,1.67,239.46],[2,1.69,233.5]],"ltp":1.64,"tv":15377.06,"id":10350473},{"batb":[[1,2.36,5.93],[2,2.32,78.58]],"batl":[[0,2.74,4.98],[1,2.76,5.27],[2,2.8,4.87]],"ltp":2.36,"tv":211.45,"id":9304761}]}]}
{"op":"mcm","clk":"4230268769","pt":1631531075645,"mc":[{"id":"1.187557247","rc":[{"trd":[[1.64,140.82],[1.65,59.97]],"batb":[[0,1.66,585.91],[1,1.58,42.56],[2,1.57,45.57]],"batl":[[0,1.74,95.4],[1,1.78,30.75],[2,1.87,31.5]],"ltp":1.65,"tv":15557.03,"id":10350473},{"trd":[[2.54,38.96]],"batb":[[0,2.5,4],[1,2.32,78.58],[2,2.28,6.91]],"ltp":2.54,"tv":250.41,"id":9304761}],"tv":15807.45}]}
{"op":"mcm","clk":"4230268795","pt":1631531075949,"mc":[{"id":"1.187557247","rc":[{"batb":[[0,2.32,78.58],[1,2.28,6.91],[2,2.14,7.82]],"ltp":2.54,"tv":250.41,"id":9304761}]}]}
{"op":"mcm","clk":"4230268927","pt":1631531077720,"mc":[{"id":"1.187557247","rc":[{"batl":[[1,1.76,147.59],[2,1.78,228.01]],"ltp":1.65,"tv":15557.03,"id":10350473}]}]}
{"op":"mcm","clk":"4230268991","pt":1631531078549,"mc":[{"id":"1.187557247","rc":[{"trd":[[1.66,194.34]],"batb":[[0,1.66,526.03]],"ltp":1.66,"tv":15676.79,"id":10350473},{"batb":[[0,2.34,3],[1,2.32,81.58],[2,2.28,6.91]],"ltp":2.54,"tv":250.41,"id":9304761}],"tv":15927.21}]}
{"op":"mcm","clk":"4230269210","pt":1631531081735,"mc":[{"id":"1.187557247","rc":[{"batl":[[0,1.73,30.5],[1,1.74,95.4],[2,1.76,147.59]],"ltp":1.66,"tv":15676.79,"id":10350473},{"batb":[[0,2.36,6.93],[1,2.34,3],[2,2.32,81.58]],"ltp":2.54,"tv":250.41,"id":9304761}]}]}
{"op":"mcm","clk":"4230269304","pt":1631531082725,"mc":[{"id":"1.187557247","rc":[{"batb":[[0,1.7,2420.26],[1,1.55,196.98],[2,1.45,719.75]],"batl":[[0,1.76,147.59],[1,1.78,228.01],[2,1.87,31.5]],"ltp":1.66,"tv":15676.79,"id":10350473},{"batb":[[0,2.32,81.58],[1,2.28,6.91],[2,2.14,7.82]],"batl":[[0,2.82,4.75],[1,3.45,236.05],[2,2.8,0]],"ltp":2.54,"tv":250.41,"id":9304761}]}]}
{"op":"mcm","clk":"4230269383","pt":1631531083764,"mc":[{"id":"1.187557247","rc":[{"batb":[[0,1.7,230.03],[1,1.68,237.44],[2,1.55,196.98]],"batl":[[2,1.79,587.64]],"ltp":1.66,"tv":15676.79,"id":10350473},{"batl":[[0,2.46,777.44],[1,2.48,754.56],[2,2.5,754.56]],"ltp":2.54,"tv":250.41,"id":9304761}]}]}
{"op":"mcm","clk":"4230269452","pt":1631531084649,"mc":[{"id":"1.187557247","rc":[{"trd":[[1.7,87.12]],"batb":[[0,1.7,326.06],[1,1.68,255.63],[2,1.61,132.38]],"ltp":1.7,"tv":15701.79,"id":10350473},{"batb":[[2,2.24,48.38]],"batl":[[1,2.48,766.88]],"ltp":2.54,"tv":250.41,"id":9304761}],"tv":15952.21}]}
{"op":"mcm","clk":"4230269698","pt":1631531087259,"mc":[{"id":"1.187557247","rc":[{"batl":[[0,1.75,46.16],[1,1.76,147.59],[2,1.78,228.01]],"ltp":1.7,"tv":15701.79,"id":10350473},{"batb":[[0,2.34,32.36],[1,2.32,81.58],[2,2.28,6.91]],"ltp":2.54,"tv":250.41,"id":9304761}]}]}
{"op":"mcm","clk":"4230269820","pt":1631531088553,"mc":[{"id":"1.187557247","rc":[{"batb":[[1,1.68,237.44]],"ltp":1.7,"tv":15701.79,"id":10350473},{"batl":[[1,2.48,754.56]],"ltp":2.54,"tv":250.41,"id":9304761}]}]}
{"op":"mcm","clk":"4230269942","pt":1631531089946,"mc":[{"id":"1.187557247","rc":[{"batb":[[2,1.61,178.47]],"ltp":1.7,"tv":15701.79,"id":10350473}]}]}
{"op":"mcm","clk":"4230270092","pt":1631531091658,"mc":[{"id":"1.187557247","rc":[{"batb":[[1,1.69,18.05],[2,1.68,237.44]],"ltp":1.7,"tv":15701.79,"id":10350473},{"batl":[[0,2.44,12.5],[1,2.46,777.44],[2,2.48,754.56]],"ltp":2.54,"tv":250.41,"id":9304761}]}]}
{"op":"mcm","clk":"4230270237","pt":1631531093625,"mc":[{"id":"1.187557247","rc":[{"trd":[[1.75,135.59],[1.76,1688.96]],"batb":[[0,1.7,108.53],[2,1.63,39.23]],"batl":[[0,1.76,95.84],[1,1.78,228.01],[2,1.79,587.64]],"ltp":1.76,"tv":15940.88,"id":10350473},{"trd":[[2.34,32.36]],"batb":[[0,2.32,81.58],[1,2.28,6.91],[2,2.24,48.38]],"ltp":2.34,"tv":282.77,"id":9304761}],"tv":16223.66}]}
{"op":"mcm","clk":"4230270325","pt":1631531094815,"mc":[{"id":"1.187557247","rc":[{"trd":[[1.7,91.77]],"batb":[[0,1.7,106.21]],"ltp":1.7,"tv":15945.53,"id":10350473}],"tv":16228.3}]}
{"op":"mcm","clk":"4230270476","pt":1631531096612,"mc":[{"id":"1.187557247","rc":[{"batb":[[0,1.71,136.56],[1,1.7,106.21],[2,1.69,250.07]],"batl":[[0,1.76,126.66]],"ltp":1.7,"tv":15945.53,"id":10350473}]}]}
{"op":"mcm","clk":"4230270554","pt":1631531097644,"mc":[{"id":"1.187557247","rc":[{"batl":[[0,1.75,37.21],[1,1.76,126.66],[2,1.78,228.01]],"ltp":1.7,"tv":15945.53,"id":10350473},{"batb":[[0,2.34,25.67],[1,2.32,81.58],[2,2.28,6.91]],"ltp":2.34,"tv":282.77,"id":9304761}]}]}
{"op":"mcm","clk":"4230270806","pt":1631531100557,"mc":[{"id":"1.187557247","rc":[{"batb":[[0,1.69,18.05],[1,1.63,39.23],[2,1.62,159.28]],"batl":[[0,1.8,60],[1,1.89,113.29],[2,1.9,28.35]],"ltp":1.7,"tv":15945.53,"id":10350473},{"batb":[[0,2.32,3],[1,2.24,48.38],[2,2.1,112.29]],"batl":[[1,2.6,4.96],[2,2.64,4.93]],"ltp":2.34,"tv":282.77,"id":9304761}]}]}
{"op":"mcm","clk":"4230270926","pt":1631531101741,"mc":[{"id":"1.187557247","rc":[{"batb":[[0,1.65,36.73]],"batl":[[0,1.89,113.29],[1,1.9,28.35],[2,1.98,24.75]],"ltp":1.7,"tv":15945.53,"id":10350473},{"batb":[[0,2.1,112.29],[1,2.02,8.24],[2,2,23.08]],"batl":[[0,2.54,4.88]],"ltp":2.34,"tv":282.77,"id":9304761}]}]}
{"op":"mcm","clk":"4230270947","pt":1631531101954,"mc":[{"id":"1.187557247","rc":[{"batb":[[0,1.62,159.28],[1,1.61,178.47],[2,1.59,47.11]],"ltp":1.7,"tv":15945.53,"id":10350473},{"batl":[[0,2.64,4.93],[1,2.7,4.75],[2,2.72,3]],"ltp":2.34,"tv":282.77,"id":9304761}]}]}
{"op":"mcm","clk":"4230271115","pt":1631531103731,"mc":[{"id":"1.187557247","rc":[{"batb":[[1,1.61,336.54],[2,1.6,141.8]],"batl":[[2,1.92,164.75]],"ltp":1.7,"tv":15945.53,"id":10350473}]}]}
{"op":"mcm","clk":"4230271224","pt":1631531104735,"mc":[{"id":"1.187557247","rc":[{"batb":[[1,1.61,178.47],[2,1.59,47.11]],"batl":[[0,1.89,117.29],[2,1.98,24.75]],"ltp":1.7,"tv":15945.53,"id":10350473},{"batb":[[0,2.12,3],[1,2.1,116.29],[2,2.02,8.24]],"ltp":2.34,"tv":282.77,"id":9304761}]}]}
{"op":"mcm","clk":"4230271416","pt":1631531106713,"mc":[{"id":"1.187557247","rc":[{"batl":[[0,2.48,4],[1,2.64,4.93],[2,2.7,4.75]],"ltp":2.34,"tv":282.77,"id":9304761}]}]}
{"op":"mcm","clk":"4230271479","pt":1631531107546,"mc":[{"id":"1.187557247","rc":[{"batb":[[0,1.73,210.05],[1,1.71,223.22],[2,1.62,159.28]],"batl":[[0,1.79,135.81],[1,1.81,186.95],[2,1.89,117.29]],"ltp":1.7,"tv":15945.53,"id":10350473},{"batl":[[0,2.64,4.93],[1,2.7,4.75],[2,2.72,3]],"ltp":2.34,"tv":282.77,"id":9304761}]}]}
{"op":"mcm","clk":"4230271594","pt":1631531108744,"mc":[{"id":"1.187557247","rc":[{"batb":[[2,1.64,80.72]],"ltp":1.7,"tv":15945.53,"id":10350473},{"batb":[[0,2.14,15],[1,2.12,3],[2,2.1,116.29]],"batl":[[0,2.6,5.56],[1,2.64,4.93],[2,2.7,4.75]],"ltp":2.34,"tv":282.77,"id":9304761}]}]}
{"op":"mcm","clk":"4230271771","pt":1631531110564,"mc":[{"id":"1.187557247","rc":[{"batb":[[2,1.63,42.23]],"ltp":1.7,"tv":15945.53,"id":10350473},{"batb":[[0,2.12,3],[1,2.1,116.29],[2,2.02,8.24]],"ltp":2.34,"tv":282.77,"id":9304761}]}]}
{"op":"mcm","clk":"4230271814","pt":1631531111035,"mc":[{"id":"1.187557247","rc":[{"batb":[[0,1.62,159.28],[1,1.61,178.47],[2,1.59,47.11]],"batl":[[0,1.89,117.29],[1,1.9,28.35],[2,1.98,24.75]],"ltp":1.7,"tv":15945.53,"id":10350473},{"batl":[[0,2.64,4.93],[1,2.7,4.75],[2,2.72,3]],"ltp":2.34,"tv":282.77,"id":9304761}]}]}
{"op":"mcm","clk":"4230272143","pt":1631531114530,"mc":[{"id":"1.187557247","rc":[{"batb":[[1,1.61,336.54],[2,1.6,141.8]],"batl":[[0,1.88,5],[1,1.89,117.29],[2,1.9,28.35]],"ltp":1.7,"tv":15945.53,"id":10350473}]}]}
{"op":"mcm","clk":"4230272350","pt":1631531116360,"mc":[{"id":"1.187557247","rc":[{"batb":[[1,1.61,178.47],[2,1.59,47.11]],"batl":[[0,1.89,117.29],[1,1.9,28.35],[2,1.92,164.75]],"ltp":1.7,"tv":15945.53,"id":10350473},{"batb":[[1,2.1,112.29]],"ltp":2.34,"tv":282.77,"id":9304761}]}]}
{"op":"mcm","clk":"4230272477","pt":1631531117665,"mc":[{"id":"1.187557247","rc":[{"batb":[[0,1.61,178.47],[1,1.59,47.11],[2,1.57,44.57]],"batl":[[0,1.89,4]],"ltp":1.7,"tv":15945.53,"id":10350473}]}]}
{"op":"mcm","clk":"4230272569","pt":1631531118656,"mc":[{"id":"1.187557247","rc":[{"batl":[[0,1.92,164.75],[1,1.94,150.85],[2,1.98,24.75]],"ltp":1.7,"tv":15945.53,"id":10350473},{"batb":[[0,2.1,105.35],[1,2.02,8.24],[2,2,23.08]],"ltp":2.34,"tv":282.77,"id":9304761}]}]}
{"op":"mcm","clk":"4230272645","pt":1631531119539,"mc":[{"id":"1.187557247","rc":[{"batb":[[0,1.85,158.79],[1,1.83,1223.36],[2,1.82,1014.34]],"batl":[[2,1.95,980.78]],"ltp":1.7,"tv":15945.53,"id":10350473},{"batb":[[0,2.1,109.35]],"batl":[[2,2.72,10.35]],"ltp":2.34,"tv":282.77,"id":9304761}]}]}
{"op":"mcm","clk":"4230272722","pt":1631531120474,"mc":[{"id":"1.187557247","rc":[{"trd":[[1.85,23.52]],"batb":[[0,1.85,147.03],[1,1.84,82.93],[2,1.83,1223.36]],"batl":[[1,1.94,210.85]],"ltp":1.85,"tv":15969.05,"id":10350473},{"batb":[[1,2.06,56.6],[2,2.02,8.24]],"batl":[[0,2.26,13.36],[1,2.64,4.93],[2,2.7,4.75]],"ltp":2.34,"tv":282.77,"id":9304761}],"tv":16251.82}]}
{"op":"mcm","clk":"4230272819","pt":1631531121572,"mc":[{"id":"1.187557247","rc":[{"batb":[[0,2.12,15],[1,2.1,109.35],[2,2.08,3]],"batl":[[1,2.62,3],[2,2.64,4.93]],"ltp":2.34,"tv":282.77,"id":9304761}]}]}
{"op":"mcm","clk":"4230272842","pt":1631531121836,"mc":[{"id":"1.187557247","rc":[{"batl":[[0,1.91,35.85],[1,1.92,164.75],[2,1.94,210.85]],"ltp":1.85,"tv":15969.05,"id":10350473}]}]}
{"op":"mcm","clk":"4230273095","pt":1631531124656,"mc":[{"id":"1.187557247","rc":[{"trd":[[1.85,58.28]],"batb":[[0,1.85,112.27]],"batl":[[1,1.94,60],[2,1.95,980.78]],"ltp":1.85,"tv":16003.81,"id":10350473},{"trd":[[2.18,29.51]],"batl":[[0,2.24,24.65],[1,2.26,13.36],[2,2.62,3]],"ltp":2.18,"tv":312.27,"id":9304761}],"tv":16316.09}]}
{"op":"mcm","clk":"4230273159","pt":1631531125331,"mc":[{"id":"1.187557247","rc":[{"batl":[[0,1.94,60],[1,1.95,980.78],[2,1.96,523.56]],"ltp":1.85,"tv":16003.81,"id":10350473}]}]}
{"op":"mcm","clk":"4230273238","pt":1631531126367,"mc":[{"id":"1.187557247","rc":[{"batl":[[0,2.36,6.07],[1,2.48,6.24]],"ltp":2.18,"tv":312.27,"id":9304761}]}]}
{"op":"mcm","clk":"4230273350","pt":1631531127668,"mc":[{"id":"1.187557247","rc":[{"batb":[[0,1.85,132.18]],"batl":[[0,1.91,113.49],[1,1.93,153.37],[2,1.94,60]],"ltp":1.85,"tv":16003.81,"id":10350473},{"batl":[[1,2.38,6.25],[2,2.48,6.24]],"ltp":2.18,"tv":312.27,"id":9304761}]}]}
{"op":"mcm","clk":"4230273454","pt":1631531128764,"mc":[{"id":"1.187557247","rc":[{"trd":[[1.9,77.12],[1.91,188.5]],"batl":[[0,1.94,60],[1,1.95,980.78],[2,1.96,523.56]],"ltp":1.91,"tv":16269.43,"id":10350473},{"trd":[[2.12,15]],"batb":[[0,2.1,109.35],[1,2.08,3],[2,2.06,56.6]],"ltp":2.12,"tv":327.27,"id":9304761}],"tv":16596.71}]}
{"op":"mcm","clk":"4230273539","pt":1631531129755,"mc":[{"id":"1.187557247","rc":[{"batl":[[0,2.24,36.92],[1,2.36,6.07],[2,2.38,6.25]],"ltp":2.12,"tv":327.27,"id":9304761}]}]}
{"op":"mcm","clk":"4230273701","pt":1631531131687,"mc":[{"id":"1.187557247","rc":[{"batb":[[0,1.85,185.94]],"batl":[[0,1.92,138.62],[1,1.94,210.86],[2,1.95,980.78]],"ltp":1.91,"tv":16269.43,"id":10350473}]}]}
{"op":"mcm","clk":"4230273801","pt":1631531132755,"mc":[{"id":"1.187557247","rc":[{"batb":[[2,1.83,178.28]],"batl":[[1,1.93,4],[2,1.94,210.86]],"ltp":1.91,"tv":16269.43,"id":10350473},{"batb":[[0,2.1,137.23]],"ltp":2.12,"tv":327.27,"id":9304761}]}]}
{"op":"mcm","clk":"4230273894","pt":1631531133750,"mc":[{"id":"1.187557247","rc":[{"batb":[[0,1.9,10.41],[1,1.82,16.56],[2,1.71,106.94]],"batl":[[0,1.94,60],[1,2.14,7.75],[2,2.26,7.25]],"ltp":1.91,"tv":16269.43,"id":10350473},{"batb":[[0,2.06,56.6],[1,1.97,400.31],[2,1.89,72.72]],"batl":[[0,2.24,13.47],[1,2.48,6.24],[2,2.5,6.31]],"ltp":2.12,"tv":327.27,"id":9304761}]}]}
{"op":"mcm","clk":"4230273958","pt":1631531134380,"mc":[{"id":"1.187557247","rc":[{"batb":[[1,1.71,106.94],[2,1.68,35.86]],"batl":[[0,2.14,7.75],[1,2.26,7.25],[2,2.28,6.59]],"ltp":1.91,"tv":16269.43,"id":10350473},{"batb":[[0,1.97,400.31],[1,1.89,72.72],[2,1.88,27.21]],"batl":[[0,2.48,6.24],[1,2.5,6.31],[2,2.62,3]],"ltp":2.12,"tv":327.27,"id":9304761}]}]}
{"op":"mcm","clk":"4230274134","pt":1631531136565,"mc":[{"id":"1.187557247","rc":[{"batb":[[1,1.74,36.02],[2,1.71,332.4]],"batl":[[0,2.14,131.41],[1,2.16,110.48],[2,2.26,7.25]],"ltp":1.91,"tv":16269.43,"id":10350473},{"batl":[[0,2.36,6.32],[1,2.48,6.24],[2,2.5,6.31]],"ltp":2.12,"tv":327.27,"id":9304761}]}]}
{"op":"mcm","clk":"4230274201","pt":1631531137268,"mc":[{"id":"1.187557247","rc":[{"batb":[[1,1.71,332.4],[2,1.69,232.4]],"ltp":1.91,"tv":16269.43,"id":10350473},{"batl":[[0,2.48,6.24],[1,2.5,6.31],[2,2.62,3]],"ltp":2.12,"tv":327.27,"id":9304761}]}]}
{"op":"mcm","clk":"4230274767","pt":1631531144155,"mc":[{"id":"1.187557247","rc":[{"batb":[[1,1.71,106.94],[2,1.68,35.86]],"batl":[[0,2.26,7.25],[1,2.16,0],[2,2.26,0]],"ltp":1.91,"tv":16269.43,"id":10350473},{"batb":[[2,1.8,34.58]],"ltp":2.12,"tv":327.27,"id":9304761}]}]}
{"op":"mcm","clk":"4230274872","pt":1631531145461,"mc":[{"id":"1.187557247","rc":[{"batb":[[2,1.67,42.47]],"ltp":1.91,"tv":16269.43,"id":10350473},{"batb":[[0,1.89,72.72],[1,1.8,34.58],[2,1.5,106.65]],"batl":[[0,2.62,3],[1,3.45,53.16],[2,2.62,0]],"ltp":2.12,"tv":327.27,"id":9304761}]}]}
{"op":"mcm","clk":"4230274965","pt":1631531146677,"mc":[{"id":"1.187557247","rc":[{"batb":[[2,1.4,148.12]],"ltp":2.12,"tv":327.27,"id":9304761}]}]}
{"op":"mcm","clk":"4230275062","pt":1631531147676,"mc":[{"id":"1.187557247","rc":[{"batb":[[0,2.04,120.75],[1,1.93,72.22],[2,1.9,10.41]],"ltp":1.91,"tv":16269.43,"id":10350473},{"batb":[[1,1.88,117.45],[2,1.86,169.6]],"batl":[[0,1.94,109.42],[1,1.96,1122.62],[2,1.97,947.06]],"ltp":2.12,"tv":327.27,"id":9304761}]}]}
{"op":"mcm","clk":"4230275150","pt":1631531148564,"mc":[{"id":"1.187557247","rc":[{"trd":[[2.06,10.87]],"batb":[[1,1.96,15.3],[2,1.93,72.22]],"batl":[[0,2.14,60.19],[1,2.26,7.25]],"ltp":2.06,"tv":16280.3,"id":10350473},{"trd":[[1.94,11.54]],"batb":[[0,1.89,140.31],[1,1.88,121.45]],"batl":[[0,1.96,975.78],[1,1.97,947.06],[2,1.98,947.06]],"ltp":1.94,"tv":338.81,"id":9304761}],"tv":16619.12}]}
{"op":"mcm","clk":"4230275214","pt":1631531149393,"mc":[{"id":"1.187557247","rc":[{"batl":[[0,2.14,4]],"ltp":2.06,"tv":16280.3,"id":10350473},{"batb":[[0,1.89,168.87]],"ltp":1.94,"tv":338.81,"id":9304761}]}]}
{"op":"mcm","clk":"4230275373","pt":1631531150766,"mc":[{"id":"1.187557247","rc":[{"batb":[[0,1.94,6.3],[1,1.89,168.87],[2,1.88,121.45]],"ltp":1.94,"tv":338.81,"id":9304761}]}]}
{"op":"mcm","clk":"4230275456","pt":1631531151761,"mc":[{"id":"1.187557247","rc":[{"batb":[[1,1.93,72.22],[2,1.91,56.05]],"batl":[[0,2.08,18.23],[1,2.14,4],[2,2.26,7.25]],"ltp":2.06,"tv":16280.3,"id":10350473},{"trd":[[1.95,16.68]],"batb":[[0,1.89,168.87],[1,1.88,121.45],[2,1.86,169.6]],"batl":[[0,1.95,167.65],[1,1.96,975.78],[2,1.97,1091.62]],"ltp":1.95,"tv":355.49,"id":9304761}],"tv":16635.8}]}
{"op":"mcm","clk":"4230275538","pt":1631531152694,"mc":[{"id":"1.187557247","rc":[{"batl":[[0,2.12,36.25],[2,2.16,55.7]],"ltp":2.06,"tv":16280.3,"id":10350473},{"trd":[[1.95,66.72]],"batb":[[0,1.89,105.28]],"batl":[[0,1.95,142.63]],"ltp":1.95,"tv":405.53,"id":9304761}],"tv":16685.84}]}
{"op":"mcm","clk":"4230275636","pt":1631531153581,"mc":[{"id":"1.187557247","rc":[{"batb":[[1,1.97,27.17],[2,1.93,72.22]],"batl":[[2,2.2,7.63]],"ltp":2.06,"tv":16280.3,"id":10350473},{"trd":[[1.95,100.07]],"batl":[[0,1.95,125.95]],"ltp":1.95,"tv":438.89,"id":9304761}],"tv":16719.19}]}
{"op":"mcm","clk":"4230275726","pt":1631531154574,"mc":[{"id":"1.187557247","rc":[{"batb":[[1,1.99,15.07],[2,1.97,27.17]],"ltp":2.06,"tv":16280.3,"id":10350473},{"trd":[[1.95,133.6]],"batl":[[0,1.95,109.19]],"ltp":1.95,"tv":472.41,"id":9304761}],"tv":16752.72}]}
{"op":"mcm","clk":"4230275821","pt":1631531155681,"mc":[{"id":"1.187557247","rc":[{"trd":[[1.95,337.44]],"batb":[[1,1.88,138.38],[2,1.87,64.32]],"batl":[[0,1.95,7.28]],"ltp":1.95,"tv":676.25,"id":9304761}],"tv":16956.56}]}
{"op":"mcm","clk":"4230275929","pt":1631531156670,"mc":[{"id":"1.187557247","rc":[{"trd":[[2.04,34.07]],"batb":[[0,2.04,103.72]],"ltp":2.04,"tv":16314.37,"id":10350473},{"trd":[[1.95,352]],"batb":[[0,1.95,31.37],[1,1.89,105.28],[2,1.88,4]],"batl":[[0,1.96,975.78],[1,1.97,947.06],[2,1.98,947.06]],"ltp":1.95,"tv":690.82,"id":9304761}],"tv":17005.19}]}
{"op":"mcm","clk":"4230276010","pt":1631531157704,"mc":[{"id":"1.187557247","rc":[{"batl":[[1,2.14,60.19]],"ltp":2.04,"tv":16314.37,"id":10350473},{"trd":[[1.95,380.06]],"batb":[[0,1.95,26.27]],"ltp":1.95,"tv":718.88,"id":9304761}],"tv":17033.25}]}
{"op":"mcm","clk":"4230276134","pt":1631531158699,"mc":[{"id":"1.187557247","rc":[{"trd":[[1.95,430.59]],"batb":[[0,1.95,39.73]],"ltp":1.95,"tv":769.4,"id":9304761}],"tv":17083.78}]}
{"op":"mcm","clk":"4230276217","pt":1631531159587,"mc":[{"id":"1.187557247","rc":[{"batl":[[0,2.1,2],[1,2.12,36.25],[2,2.14,60.19]],"ltp":2.04,"tv":16314.37,"id":10350473},{"trd":[[1.95,434.59]],"batb":[[0,1.95,47.15],[1,1.89,252.7]],"batl":[[0,1.96,1100.95],[2,1.98,1089.41]],"ltp":1.95,"tv":773.4,"id":9304761}],"tv":17087.78}]}
{"op":"mcm","clk":"4230276320","pt":1631531160575,"mc":[{"id":"1.187557247","rc":[{"trd":[[1.96,16.68]],"batb":[[0,1.89,252.7],[1,1.87,231.01],[2,1.84,603.64]],"batl":[[0,1.96,1092.61]],"ltp":1.96,"tv":790.08,"id":9304761}],"tv":17104.46}]}
{"op":"mcm","clk":"4230276419","pt":1631531161680,"mc":[{"id":"1.187557247","rc":[{"trd":[[1.96,50.04]],"batl":[[0,1.96,1075.93]],"ltp":1.96,"tv":823.44,"id":9304761}],"tv":17137.82}]}
{"op":"mcm","clk":"4230276499","pt":1631531162611,"mc":[{"id":"1.187557247","rc":[{"trd":[[1.96,83.4]],"batb":[[0,1.89,275.14]],"batl":[[0,1.96,1059.25]],"ltp":1.96,"tv":856.8,"id":9304761}],"tv":17171.17}]}
{"op":"mcm","clk":"4230276590","pt":1631531163709,"mc":[{"id":"1.187557247","rc":[{"trd":[[1.96,100.07]],"batb":[[0,1.9,5],[1,1.89,275.14],[2,1.87,231.01]],"batl":[[0,1.96,1050.91]],"ltp":1.96,"tv":873.48,"id":9304761}],"tv":17187.85}]}
{"op":"mcm","clk":"4230276668","pt":1631531164594,"mc":[{"id":"1.187557247","rc":[{"trd":[[1.96,150.11]],"batl":[[0,1.96,1025.89]],"ltp":1.96,"tv":923.51,"id":9304761}],"tv":17237.89}]}
{"op":"mcm","clk":"4230276698","pt":1631531164906,"mc":[{"id":"1.187557247","rc":[{"trd":[[1.96,244.03]],"batl":[[0,1.96,978.93]],"ltp":1.96,"tv":1017.43,"id":9304761}],"tv":17331.81}]}
{"op":"mcm","clk":"4230276852","pt":1631531166677,"mc":[{"id":"1.187557247","rc":[{"batl":[[1,2.14,60.19],[2,2.2,7.63]],"ltp":2.04,"tv":16314.37,"id":10350473},{"trd":[[1.96,431.53]],"batb":[[1,1.89,246.58]],"batl":[[0,1.96,93.92],[1,1.98,142.35],[2,2,15]],"ltp":1.96,"tv":1204.93,"id":9304761}],"tv":17519.31}]}
{"op":"mcm","clk":"4230276897","pt":1631531167306,"mc":[{"id":"1.187557247","rc":[{"batb":[[0,1.99,15.07],[1,1.93,72.22],[2,1.91,4]],"batl":[[1,2.14,56.19]],"ltp":2.04,"tv":16314.37,"id":10350473},{"batb":[[0,1.96,31.25],[1,1.87,64.32],[2,1.84,31.97]],"batl":[[0,2,15],[1,2.1,4],[2,2.14,7.75]],"ltp":1.96,"tv":1204.93,"id":9304761}]}]}
{"op":"mcm","clk":"4230277021","pt":1631531168612,"mc":[{"id":"1.187557247","rc":[{"batb":[[0,1.93,72.22],[1,1.91,4],[2,1.9,10.41]],"batl":[[1,2.3,6.85],[2,2.2,0]],"ltp":2.04,"tv":16314.37,"id":10350473},{"batb":[[0,1.8,84.85],[1,1.78,31.16],[2,1.74,409.86]],"batl":[[0,2.1,4],[1,2.14,7.75],[2,2.92,224.31]],"ltp":1.96,"tv":1204.93,"id":9304761}]}]}
{"op":"mcm","clk":"4230277231","pt":1631531170701,"mc":[{"id":"1.187557247","rc":[{"batb":[[0,1.93,96.58]],"ltp":2.04,"tv":16314.37,"id":10350473},{"batb":[[0,1.8,265.58],[1,1.78,227.07]],"batl":[[0,2.08,7.94],[1,2.1,182.56],[2,2.12,116.42]],"ltp":1.96,"tv":1204.93,"id":9304761}]}]}
{"op":"mcm","clk":"4230277327","pt":1631531171696,"mc":[{"id":"1.187557247","rc":[{"batb":[[0,1.93,72.22],[2,1.88,25.96]],"ltp":2.04,"tv":16314.37,"id":10350473},{"batb":[[0,1.8,84.85],[1,1.78,31.16],[2,1.77,38.37]],"batl":[[0,2.1,4],[1,2.14,7.75],[2,2.92,224.31]],"ltp":1.96,"tv":1204.93,"id":9304761}]}]}
{"op":"mcm","clk":"4230277407","pt":1631531172490,"mc":[{"id":"1.187557247","rc":[{"batb":[[0,1.93,74.22],[1,1.92,2],[2,1.91,4]],"ltp":2.04,"tv":16314.37,"id":10350473},{"batb":[[2,1.74,409.86]],"batl":[[0,2.08,2],[1,2.1,4],[2,2.14,7.75]],"ltp":1.96,"tv":1204.93,"id":9304761}]}]}
{"op":"mcm","clk":"4230277515","pt":1631531173689,"mc":[{"id":"1.187557247","rc":[{"batb":[[0,2.02,42.74],[1,1.93,74.22],[2,1.92,2]],"batl":[[0,2.06,42.25],[1,2.1,2],[2,2.3,6.85]],"ltp":2.04,"tv":16314.37,"id":10350473},{"batl":[[0,1.98,37.75],[1,2.08,2],[2,2.1,4]],"ltp":1.96,"tv":1204.93,"id":9304761}]}]}
{"op":"mcm","clk":"4230277550","pt":1631531174206,"mc":[{"id":"1.187557247","rc":[{"batb":[[0,1.93,74.22],[1,1.92,2],[2,1.91,4]],"batl":[[0,2.1,2],[1,2.3,6.85],[2,2.3,0]],"ltp":2.04,"tv":16314.37,"id":10350473},{"batb":[[0,1.8,85.6]],"batl":[[0,2.08,2],[1,2.1,4],[2,2.14,7.75]],"ltp":1.96,"tv":1204.93,"id":9304761}]}]}
{"op":"mcm","clk":"4230277687","pt":1631531175720,"mc":[{"id":"1.187557247","rc":[{"batb":[[0,1.94,47.08],[1,1.93,74.22],[2,1.92,2]],"batl":[[0,2.1,12]],"ltp":2.04,"tv":16314.37,"id":10350473},{"batb":[[0,1.92,126.03],[1,1.9,158.47],[2,1.81,99.7]],"batl":[[0,1.99,147.1],[1,2.02,202.11],[2,2.06,10]],"ltp":1.96,"tv":1204.93,"id":9304761}]}]}
{"op":"mcm","clk":"4230277755","pt":1631531176397,"mc":[{"id":"1.187557247","rc":[{"batb":[[0,1.93,74.22],[1,1.92,2],[2,1.91,4]],"batl":[[0,2.1,2]],"ltp":2.04,"tv":16314.37,"id":10350473},{"batb":[[0,1.8,85.6],[1,1.78,31.16],[2,1.74,409.86]],"batl":[[0,2.08,2],[1,2.1,4],[2,2.14,7.75]],"ltp":1.96,"tv":1204.93,"id":9304761}]}]}
{"op":"mcm","clk":"4230277837","pt":1631531177397,"mc":[{"id":"1.187557247","rc":[{"batb":[[0,1.93,98.58]],"ltp":2.04,"tv":16314.37,"id":10350473},{"batl":[[0,2.08,10.44]],"ltp":1.96,"tv":1204.93,"id":9304761}]}]}
{"op":"mcm","clk":"4230277880","pt":1631531177809,"mc":[{"id":"1.187557247","rc":[{"batb":[[0,1.93,74.22]],"ltp":2.04,"tv":16314.37,"id":10350473},{"batl":[[0,2.08,2]],"ltp":1.96,"tv":1204.93,"id":9304761}]}]}
{"op":"mcm","clk":"4230278013","pt":1631531179323,"mc":[{"id":"1.187557247","rc":[{"batb":[[0,1.81,18.83],[1,1.8,284.45],[2,1.78,227.1]],"batl":[[1,2.1,182.56],[2,2.12,116.42]],"ltp":1.96,"tv":1204.93,"id":9304761}]}]}
{"op":"mcm","clk":"4230278196","pt":1631531181199,"mc":[{"id":"1.187557247","rc":[{"trd":[[1.98,1.49]],"batb":[[0,1.81,18.08]],"batl":[[0,1.94,7.06],[1,2.08,2],[2,2.1,182.56]],"ltp":1.98,"tv":1206.42,"id":9304761}],"tv":17520.8}]}
{"op":"mcm","clk":"4230278473","pt":1631531184518,"mc":[{"id":"1.187557247","rc":[{"batb":[[0,1.93,100.15],[1,1.88,25.96],[2,1.5,106.73]],"ltp":2.04,"tv":16314.37,"id":10350473},{"trd":[[1.94,24.94]],"batl":[[0,2.08,10.05],[1,2.1,178.56],[2,2.12,116.42]],"ltp":1.94,"tv":1219.82,"id":9304761}],"tv":17534.2}]}
{"op":"mcm","clk":"4230278579","pt":1631531185714,"mc":[{"id":"1.187557247","rc":[{"batb":[[0,1.93,74.22]],"batl":[[1,2.3,0]],"ltp":2.04,"tv":16314.37,"id":10350473},{"batb":[[1,1.8,84.85],[2,1.78,31.16]],"batl":[[0,2.08,2.36],[1,2.14,7.75],[2,3.45,53.16]],"ltp":1.94,"tv":1219.82,"id":9304761}]}]}
{"op":"mcm","clk":"4230278765","pt":1631531187700,"mc":[{"id":"1.187557247","rc":[{"trd":[[1.93,22.6]],"batb":[[0,1.93,60.92],[2,1.87,2045.46]],"batl":[[0,1.99,5.5],[1,2.1,2]],"ltp":1.93,"tv":16336.97,"id":10350473},{"trd":[[1.94,25.66]],"batb":[[0,2,4290.73],[1,1.99,1856.24],[2,1.98,1856.24]],"batl":[[0,2.14,7.75],[1,3.45,53.16],[2,3.45,0]],"ltp":1.94,"tv":1220.54,"id":9304761}],"tv":17557.52}]}
{"op":"mcm","clk":"4230278861","pt":1631531188729,"mc":[{"id":"1.187557247","rc":[{"batb":[[1,1.92,110.28],[2,1.9,158.35]],"batl":[[0,1.99,166.52],[1,2.02,201.8],[2,2.1,2]],"ltp":1.93,"tv":16336.97,"id":10350473},{"batb":[[0,2,1101.5],[1,1.99,928.12],[2,1.98,928.12]],"batl":[[1,2.56,7.81],[2,3.45,53.16]],"ltp":1.94,"tv":1220.54,"id":9304761}]}]}
{"op":"mcm","clk":"4230278962","pt":1631531189720,"mc":[{"id":"1.187557247","rc":[{"batl":[[2,2.04,58.83]],"ltp":1.93,"tv":16336.97,"id":10350473},{"batl":[[0,2.14,21.79]],"ltp":1.94,"tv":1220.54,"id":9304761}]}]}
{"op":"mcm","clk":"4230279031","pt":1631531190610,"mc":[{"id":"1.187557247","rc":[{"batl":[[0,2.14,52.65],[2,2.92,224.31]],"ltp":1.94,"tv":1220.54,"id":9304761}]}]}
{"op":"mcm","clk":"4230279226","pt":1631531192697,"mc":[{"id":"1.187557247","rc":[{"batl":[[0,1.99,194.15]],"ltp":1.93,"tv":16336.97,"id":10350473}]}]}
{"op":"mcm","clk":"4230279314","pt":1631531193736,"mc":[{"id":"1.187557247","rc":[{"batl":[[2,2.08,3]],"ltp":1.93,"tv":16336.97,"id":10350473}]}]}
{"op":"mcm","clk":"4230279364","pt":1631531194413,"mc":[{"id":"1.187557247","rc":[{"batl":[[1,2.2,6.33],[2,2.3,6.45]],"ltp":1.94,"tv":1220.54,"id":9304761}]}]}
{"op":"mcm","clk":"4230279563","pt":1631531196540,"mc":[{"id":"1.187557247","rc":[{"batl":[[1,2.02,261.2]],"ltp":1.93,"tv":16336.97,"id":10350473},{"batb":[[1,1.99,988.42]],"batl":[[2,2.22,7.25]],"ltp":1.94,"tv":1220.54,"id":9304761}]}]}
{"op":"mcm","clk":"4230279643","pt":1631531197327,"mc":[{"id":"1.187557247","rc":[{"trd":[[1.93,48.6],[1.99,282.36]],"batb":[[0,1.93,47.92]],"batl":[[0,1.99,52.97]],"ltp":1.99,"tv":16645.33,"id":10350473}],"tv":17865.88}]}
{"op":"mcm","clk":"4230279717","pt":1631531198106,"mc":[{"id":"1.187557247","rc":[{"batb":[[1,1.88,41.95],[2,1.87,1022.72]],"batl":[[0,2.02,193.23],[1,2.08,3],[2,2.1,9.75]],"ltp":1.99,"tv":16645.33,"id":10350473}]}]}
{"op":"mcm","clk":"4230279848","pt":1631531199512,"mc":[{"id":"1.187557247","rc":[{"batb":[[0,2,1111.79]],"ltp":1.94,"tv":1220.54,"id":9304761}]}]}
{"op":"mcm","clk":"4230280033","pt":1631531201643,"mc":[{"id":"1.187557247","rc":[{"batb":[[0,1.93,157.54],[1,1.91,155.73],[2,1.88,41.95]],"batl":[[0,1.99,27.63],[1,2,155],[2,2.02,193.23]],"ltp":1.99,"tv":16645.33,"id":10350473}]}]}
{"op":"mcm","clk":"4230280413","pt":1631531205548,"mc":[{"id":"1.187557247","rc":[{"batb":[[0,1.88,15.99],[1,1.84,28.97],[2,1.82,31.64]],"batl":[[0,2.02,59.4],[1,2.08,3],[2,2.1,9.75]],"ltp":1.99,"tv":16645.33,"id":10350473},{"batb":[[0,1.99,60.3],[1,1.91,29.39],[2,1.9,71.21]],"batl":[[0,2.14,14.04]],"ltp":1.94,"tv":1220.54,"id":9304761}]}]}
{"op":"mcm","clk":"4230280504","pt":1631531206653,"mc":[{"id":"1.187557247","rc":[{"batb":[[0,1.81,88.87],[1,1.78,32.16],[2,1.45,719.75]],"batl":[[0,2.08,3],[1,2.1,2],[2,2.18,7.25]],"ltp":1.99,"tv":16645.33,"id":10350473},{"batb":[[0,1.91,29.39],[1,1.9,71.21],[2,1.85,30.97]],"batl":[[0,3.45,53.16],[1,2.2,0],[2,2.22,0]],"ltp":1.94,"tv":1220.54,"id":9304761}]}]}
{"op":"mcm","clk":"4230280564","pt":1631531207228,"mc":[{"id":"1.187557247","rc":[{"batl":[[0,2.1,2],[1,2.18,7.25],[2,2.18,0]],"ltp":1.99,"tv":16645.33,"id":10350473},{"batb":[[0,1.9,71.21],[1,1.85,30.97],[2,1.74,409.86]],"batl":[[0,2.72,244.88],[1,3.45,53.16]],"ltp":1.94,"tv":1220.54,"id":9304761}]}]}
{"op":"mcm","clk":"4230280704","pt":1631531208722,"mc":[{"id":"1.187557247","rc":[{"batb":[[0,1.8,89.29]],"batl":[[0,2,5],[1,2.1,2],[2,2.18,7.25]],"ltp":1.99,"tv":16645.33,"id":10350473},{"batb":[[0,2,4],[1,1.99,5],[2,1.9,70.88]],"batl":[[0,2.3,6.25],[1,2.72,244.88],[2,3.45,53.16]],"ltp":1.94,"tv":1220.54,"id":9304761}]}]}
{"op":"mcm","clk":"4230280791","pt":1631531209616,"mc":[{"id":"1.187557247","rc":[{"batb":[[0,1.82,3],[1,1.81,3],[2,1.8,89.29]],"batl":[[0,2.06,4]],"ltp":1.99,"tv":16645.33,"id":10350473},{"batb":[[0,1.93,3],[1,1.92,4]],"batl":[[0,2.22,4],[1,2.3,6.25],[2,2.72,244.88]],"ltp":1.94,"tv":1220.54,"id":9304761}]}]}
{"op":"mcm","clk":"4230280924","pt":1631531210726,"mc":[{"id":"1.187557247","rc":[{"batb":[[2,1.8,92.29]],"batl":[[0,2.02,499.49]],"ltp":1.99,"tv":16645.33,"id":10350473},{"batb":[[0,1.9,70.88],[1,1.85,30.97],[2,1.74,409.86]],"batl":[[0,2.24,3]],"ltp":1.94,"tv":1220.54,"id":9304761}]}]}
{"op":"mcm","clk":"4230280985","pt":1631531211247,"mc":[{"id":"1.187557247","rc":[{"batb":[[0,1.9,160.32],[1,1.88,163.67],[2,1.82,3]],"batl":[[0,1.97,126.18],[1,1.99,139.88],[2,2.1,2]],"ltp":1.99,"tv":16645.33,"id":10350473}]}]}
{"op":"mcm","clk":"4230281127","pt":1631531212670,"mc":[{"id":"1.187557247","rc":[{"batb":[[2,1.85,37.79]],"batl":[[2,2.08,10]],"ltp":1.99,"tv":16645.33,"id":10350473},{"batb":[[0,1.91,98.11],[1,1.9,70.88],[2,1.85,30.97]],"batl":[[0,2.18,33.43],[1,2.2,7.13],[2,2.24,3]],"ltp":1.94,"tv":1220.54,"id":9304761}]}]}
{"op":"mcm","clk":"4230281227","pt":1631531213656,"mc":[{"id":"1.187557247","rc":[{"batl":[[2,2.1,10.15]],"ltp":1.99,"tv":16645.33,"id":10350473},{"batb":[[0,1.91,123.5]],"batl":[[0,2.2,7.13],[1,2.24,3],[2,2.26,4]],"ltp":1.94,"tv":1220.54,"id":9304761}]}]}
{"op":"mcm","clk":"4230281264","pt":1631531213970,"mc":[{"id":"1.187557247","rc":[{"batb":[[0,1.91,25.39]],"ltp":1.94,"tv":1220.54,"id":9304761}]}]}
{"op":"mcm","clk":"4230281501","pt":1631531216168,"mc":[{"id":"1.187557247","rc":[{"batl":[[0,1.96,26.46],[1,1.97,126.18],[2,1.99,139.88]],"ltp":1.99,"tv":16645.33,"id":10350473}]}]}
{"op":"mcm","clk":"4230281610","pt":1631531217061,"mc":[{"id":"1.187557247","rc":[{"batb":[[0,1.92,98.11],[1,1.91,25.39],[2,1.9,70.88]],"ltp":1.94,"tv":1220.54,"id":9304761}]}]}
{"op":"mcm","clk":"4230281754","pt":1631531218678,"mc":[{"id":"1.187557247","rc":[{"batb":[[0,1.82,3],[1,1.81,3],[2,1.8,92.29]],"batl":[[0,2.1,2],[1,2.18,7.25],[2,1.99,0]],"ltp":1.99,"tv":16645.33,"id":10350473},{"batb":[[0,1.9,70.88],[1,1.85,30.97],[2,1.74,409.86]],"batl":[[0,2.24,3],[1,2.26,4],[2,2.3,6.25]],"ltp":1.94,"tv":1220.54,"id":9304761}]}]}
{"op":"mcm","clk":"4230281870","pt":1631531219982,"mc":[{"id":"1.187557247","rc":[{"trd":[[1.9,24]],"batb":[[0,1.9,58.88]],"ltp":1.9,"tv":1244.54,"id":9304761}],"tv":17889.88}]}
{"op":"mcm","clk":"4230282058","pt":1631531221767,"mc":[{"id":"1.187557247","rc":[{"batb":[[0,1.84,26.47],[1,1.83,37.79],[2,1.82,3]],"batl":[[0,1.96,26.46],[1,2.1,8.85],[2,2.12,143.84]],"ltp":1.99,"tv":16645.33,"id":10350473},{"batb":[[0,1.91,124.5],[1,1.9,58.88],[2,1.85,30.97]],"batl":[[0,2.2,6.68],[1,2.24,3],[2,2.26,4]],"ltp":1.9,"tv":1244.54,"id":9304761}]}]}
{"op":"mcm","clk":"4230282139","pt":1631531222655,"mc":[{"id":"1.187557247","rc":[{"batb":[[0,1.82,3],[1,1.81,174.7],[2,1.8,89.29]],"batl":[[0,2.1,2],[1,2.12,143.84],[2,2.14,113.4]],"ltp":1.99,"tv":16645.33,"id":10350473},{"batb":[[0,1.9,58.88],[1,1.85,30.97],[2,1.74,409.86]],"batl":[[0,2.22,33.43]],"ltp":1.9,"tv":1244.54,"id":9304761}]}]}
{"op":"mcm","clk":"4230282178","pt":1631531222861,"mc":[{"id":"1.187557247","rc":[{"batl":[[0,2.24,3],[1,2.26,4],[2,2.3,6.25]],"ltp":1.9,"tv":1244.54,"id":9304761}]}]}
{"op":"mcm","clk":"4230282438","pt":1631531225386,"mc":[{"id":"1.187557247","rc":[{"batb":[[1,1.81,176.7]],"ltp":1.99,"tv":16645.33,"id":10350473},{"batl":[[1,2.3,6.25],[2,2.72,244.88]],"ltp":1.9,"tv":1244.54,"id":9304761}]}]}
{"op":"mcm","clk":"4230282539","pt":1631531226278,"mc":[{"id":"1.187557247","rc":[{"batb":[[1,1.81,2]],"batl":[[1,2.18,7.25],[2,2.14,0]],"ltp":1.99,"tv":16645.33,"id":10350473}]}]}
{"op":"mcm","clk":"4230282639","pt":1631531227471,"mc":[{"id":"1.187557247","rc":[{"batb":[[2,1.5,106.73]],"batl":[[2,3.45,53.16]],"ltp":1.9,"tv":1244.54,"id":9304761}]}]}
{"op":"mcm","clk":"4230282721","pt":1631531228570,"mc":[{"id":"1.187557247","rc":[{"batb":[[0,1.84,28.22],[1,1.82,3],[2,1.81,2]],"batl":[[0,2.1,9.55]],"ltp":1.99,"tv":16645.33,"id":10350473},{"batb":[[0,1.91,28.39],[1,1.9,58.88],[2,1.85,30.97]],"batl":[[0,2.2,7.48],[1,2.24,3],[2,2.3,6.25]],"ltp":1.9,"tv":1244.54,"id":9304761}]}]}
{"op":"mcm","clk":"4230282811","pt":1631531229668,"mc":[{"id":"1.187557247","rc":[{"batb":[[0,1.82,3],[1,1.81,2],[2,1.8,89.29]],"batl":[[0,2.1,2]],"ltp":1.99,"tv":16645.33,"id":10350473},{"batb":[[0,1.9,58.88],[1,1.89,184.59],[2,1.87,166.7]],"batl":[[0,1.96,110.94],[1,1.98,1108.27],[2,1.99,937.5]],"ltp":1.9,"tv":1244.54,"id":9304761}]}]}
{"op":"mcm","clk":"4230282890","pt":1631531230560,"mc":[{"id":"1.187557247","rc":[{"trd":[[2.04,44.94]],"batb":[[0,2.02,123.6],[1,1.97,15.23],[2,1.9,76.07]],"batl":[[1,2.14,56.19],[2,2.18,7.25]],"ltp":2.04,"tv":16656.2,"id":10350473},{"trd":[[1.96,442.84]],"batb":[[0,1.9,89],[1,1.88,63.96],[2,1.85,599.55]],"batl":[[0,1.98,965.92],[1,1.99,937.5],[2,2,937.5]],"ltp":1.96,"tv":1255.85,"id":9304761}],"tv":17912.06}]}
{"op":"mcm","clk":"4230283165","pt":1631531233578,"mc":[{"id":"1.187557247","rc":[{"batb":[[1,1.9,76.07],[2,1.85,5]],"ltp":2.04,"tv":16656.2,"id":10350473},{"batb":[[0,1.9,199.21],[1,1.88,227.81]],"batl":[[0,1.97,175.35],[1,1.98,965.92],[2,1.99,1077.69]],"ltp":1.96,"tv":1255.85,"id":9304761}]}]}
{"op":"mcm","clk":"4230283461","pt":1631531236700,"mc":[{"id":"1.187557247","rc":[{"batb":[[1,1.99,15.07],[2,1.91,26.39]],"ltp":2.04,"tv":16656.2,"id":10350473}]}]}
{"op":"mcm","clk":"4230283660","pt":1631531238994,"mc":[{"id":"1.187557247","rc":[{"trd":[[2.02,20]],"batb":[[0,2.02,113.6]],"ltp":2.02,"tv":16676.2,"id":10350473}],"tv":17932.06}]}
{"op":"mcm","clk":"4230283863","pt":1631531241407,"mc":[{"id":"1.187557247","rc":[{"batb":[[0,1.99,15.07],[1,1.9,76.07],[2,1.85,33.57]],"batl":[[2,2.38,6.25]],"ltp":2.02,"tv":16676.2,"id":10350473},{"batb":[[0,1.88,63.96],[1,1.8,84.68],[2,1.73,37.13]],"batl":[[0,2.02,14.85],[1,2.18,10.25],[2,2.2,4]],"ltp":1.96,"tv":1255.85,"id":9304761}]}]}
{"op":"mcm","clk":"4230283959","pt":1631531242507,"mc":[{"id":"1.187557247","rc":[{"batb":[[0,1.9,76.07],[1,1.85,33.57],[2,1.84,4]],"batl":[[1,2.38,6.25],[2,2.38,0]],"ltp":2.02,"tv":16676.2,"id":10350473},{"batb":[[0,1.8,84.68],[1,1.73,37.13],[2,1.62,421.17]],"batl":[[0,2.18,10.25],[1,2.2,4],[2,2.24,3]],"ltp":1.96,"tv":1255.85,"id":9304761}]}]}
{"op":"mcm","clk":"4230284097","pt":1631531244595,"mc":[{"id":"1.187557247","rc":[{"batb":[[0,1.91,31.39],[1,1.89,76.32],[2,1.85,33.57]],"batl":[[1,2.26,6.75],[2,2.38,6.25]],"ltp":2.02,"tv":16676.2,"id":10350473},{"batb":[[0,1.8,117.61],[1,1.79,187.56],[2,1.77,199.68]],"batl":[[0,2.1,7.75],[1,2.12,181.17],[2,2.14,113.28]],"ltp":1.96,"tv":1255.85,"id":9304761}]}]}
{"op":"mcm","clk":"4230284187","pt":1631531245693,"mc":[{"id":"1.187557247","rc":[{"batb":[[0,1.9,2],[1,1.89,78.32]],"batl":[[1,2.24,6.98]],"ltp":2.02,"tv":16676.2,"id":10350473},{"batb":[[0,1.81,33.29],[1,1.8,84.43],[2,1.79,187.56]],"batl":[[0,2.12,183.17],[1,2.14,113.28],[2,2.18,10.25]],"ltp":1.96,"tv":1255.85,"id":9304761}]}]}
{"op":"mcm","clk":"4230284331","pt":1631531247505,"mc":[{"id":"1.187557247","rc":[{"batb":[[2,1.88,2]],"ltp":2.02,"tv":16676.2,"id":10350473}]}]}
{"op":"mcm","clk":"4230284417","pt":1631531248496,"mc":[{"id":"1.187557247","rc":[{"batb":[[0,1.91,2],[1,1.9,2],[2,1.89,78.32]],"batl":[[1,2.38,6.25],[2,2.38,0]],"ltp":2.02,"tv":16676.2,"id":10350473},{"batb":[[0,1.8,84.43],[1,1.79,187.56],[2,1.77,199.68]],"ltp":1.96,"tv":1255.85,"id":9304761}]}]}
{"op":"mcm","clk":"4230284469","pt":1631531249213,"mc":[{"id":"1.187557247","rc":[{"batb":[[0,1.81,18.08],[1,1.8,84.43],[2,1.79,187.56]],"ltp":1.96,"tv":1255.85,"id":9304761}]}]}
{"op":"mcm","clk":"4230284551","pt":1631531250406,"mc":[{"id":"1.187557247","rc":[{"batb":[[0,1.82,18.08],[1,1.81,18.08],[2,1.8,84.43]],"ltp":1.96,"tv":1255.85,"id":9304761}]}]}
{"op":"mcm","clk":"4230284659","pt":1631531251707,"mc":[{"id":"1.187557247","rc":[{"batb":[[0,1.91,26.39]],"batl":[[1,2.24,6.98],[2,2.26,6.25]],"ltp":2.02,"tv":16676.2,"id":10350473},{"batb":[[1,1.81,49.37],[2,1.8,111.21]],"batl":[[0,2.1,6.75],[1,2.12,183.17],[2,2.14,113.28]],"ltp":1.96,"tv":1255.85,"id":9304761}]}]}
{"op":"mcm","clk":"4230284687","pt":1631531252020,"mc":[{"id":"1.187557247","rc":[{"batb":[[0,1.91,2]],"batl":[[1,2.38,6.25],[2,2.26,0]],"ltp":2.02,"tv":16676.2,"id":10350473},{"batb":[[0,1.81,18.08],[1,1.8,84.43],[2,1.79,187.56]],"batl":[[0,2.12,183.17],[1,2.14,113.28],[2,2.18,10.25]],"ltp":1.96,"tv":1255.85,"id":9304761}]}]}
{"op":"mcm","clk":"4230284875","pt":1631531254407,"mc":[{"id":"1.187557247","rc":[{"batb":[[0,2.04,2439.6],[1,1.81,18.08],[2,1.8,84.43]],"ltp":1.96,"tv":1255.85,"id":9304761}]}]}
{"op":"mcm","clk":"4230284975","pt":1631531255598,"mc":[{"id":"1.187557247","rc":[{"batl":[[1,2.24,6.98],[2,2.26,6.25]],"ltp":2.02,"tv":16676.2,"id":10350473},{"batb":[[1,1.81,45.37],[2,1.8,111.71]],"ltp":1.96,"tv":1255.85,"id":9304761}]}]}
{"op":"mcm","clk":"4230285132","pt":1631531257624,"mc":[{"id":"1.187557247","rc":[{"batb":[[1,1.89,76.32],[2,1.88,2]],"ltp":2.02,"tv":16676.2,"id":10350473},{"batl":[[2,2.18,6.25]],"ltp":1.96,"tv":1255.85,"id":9304761}]}]}
{"op":"mcm","clk":"4230285281","pt":1631531259331,"mc":[{"id":"1.187557247","rc":[{"batb":[[2,1.85,28.57]],"ltp":2.02,"tv":16676.2,"id":10350473}]}]}
{"op":"mcm","clk":"4230285376","pt":1631531260532,"mc":[{"id":"1.187557247","rc":[{"batl":[[0,2.12,2],[1,2.18,6.25],[2,2.6,261.12]],"ltp":1.96,"tv":1255.85,"id":9304761}]}]}
{"op":"mcm","clk":"4230285397","pt":1631531260790,"mc":[{"id":"1.187557247","rc":[{"batb":[[1,1.9,5],[2,1.89,76.32]],"ltp":2.02,"tv":16676.2,"id":10350473}]}]}
{"op":"mcm","clk":"4230285562","pt":1631531262607,"mc":[{"id":"1.187557247","rc":[{"batb":[[0,1.89,76.32],[1,1.85,28.57],[2,1.45,719.75]],"ltp":2.02,"tv":16676.2,"id":10350473},{"batl":[[0,2.18,6.25],[1,2.6,261.12],[2,3.45,53.16]],"ltp":1.96,"tv":1255.85,"id":9304761}]}]}
{"op":"mcm","clk":"4230285655","pt":1631531263695,"mc":[{"id":"1.187557247","rc":[{"trd":[[1.89,22.86]],"batb":[[0,1.9,144.77],[1,1.89,64.89],[2,1.88,163.66]],"batl":[[0,1.97,141.14],[1,1.98,965.92],[2,1.99,1079.71]],"ltp":1.89,"tv":16699.06,"id":10350473},{"batb":[[0,2,2]],"ltp":1.96,"tv":1255.85,"id":9304761}],"tv":17954.92}]}
{"op":"mcm","clk":"4230285730","pt":1631531264728,"mc":[{"id":"1.187557247","rc":[{"batb":[[0,2.04,114.89],[1,2,2],[2,1.91,69.45]],"batl":[[0,2.16,13.92],[1,2.18,6.25],[2,2.6,268.81]],"ltp":1.96,"tv":1255.85,"id":9304761}]}]}
{"op":"mcm","clk":"4230285796","pt":1631531265741,"mc":[{"id":"1.187557247","rc":[{"batb":[[0,2.04,144.1],[1,2.02,3],[2,2,2]],"ltp":1.96,"tv":1255.85,"id":9304761}]}]}
{"op":"mcm","clk":"4230285807","pt":1631531265818,"mc":[{"id":"1.187557247","rc":[{"batl":[[0,2.16,39.77]],"ltp":1.96,"tv":1255.85,"id":9304761}]}]}
{"op":"mcm","clk":"4230285890","pt":1631531267012,"mc":[{"id":"1.187557247","rc":[{"trd":[[2.04,117.4]],"batb":[[0,2.04,85.4]],"ltp":2.04,"tv":1373.25,"id":9304761}],"tv":18072.32}]}
{"op":"mcm","clk":"4230286010","pt":1631531268415,"mc":[{"id":"1.187557247","rc":[{"batl":[[0,1.96,26.46],[1,1.97,141.14],[2,1.98,965.92]],"ltp":1.89,"tv":16699.06,"id":10350473},{"batb":[[1,2.02,61.82]],"ltp":2.04,"tv":1373.25,"id":9304761}]}]}
{"op":"mcm","clk":"4230286175","pt":1631531270739,"mc":[{"id":"1.187557247","rc":[{"batl":[[2,2.2,41.78]],"ltp":2.04,"tv":1373.25,"id":9304761}]}]}
{"op":"mcm","clk":"4230286242","pt":1631531271623,"mc":[{"id":"1.187557247","rc":[{"batl":[[1,1.97,201.14]],"ltp":1.89,"tv":16699.06,"id":10350473}]}]}
{"op":"mcm","clk":"4230286691","pt":1631531277628,"mc":[{"id":"1.187557247","rc":[{"batb":[[0,1.84,16.36],[1,1.78,33.16],[2,1.77,94.14]],"batl":[[0,1.97,60],[1,2.1,2],[2,2.12,7.96]],"ltp":1.89,"tv":16699.06,"id":10350473},{"batb":[[0,2.02,58.82],[1,1.91,69.45],[2,1.9,23.46]],"batl":[[0,2.16,13.92],[1,2.2,41.78],[2,2.42,6.25]],"ltp":2.04,"tv":1373.25,"id":9304761}]}]}
{"op":"mcm","clk":"4230286771","pt":1631531278559,"mc":[{"id":"1.187557247","rc":[{"batb":[[0,1.77,94.14],[1,1.71,33.19],[2,1.45,719.75]],"batl":[[0,2.1,2],[1,2.22,6.75],[2,2.24,6.98]],"ltp":1.89,"tv":16699.06,"id":10350473},{"batb":[[0,1.91,69.45],[1,1.82,30.64],[2,1.81,27.29]],"batl":[[0,2.42,6.25],[1,2.6,261.12],[2,3.45,53.16]],"ltp":2.04,"tv":1373.25,"id":9304761}]}]}
{"op":"mcm","clk":"4230286935","pt":1631531280736,"mc":[{"id":"1.187557247","rc":[{"batb":[[0,1.77,299.47],[1,1.75,206.49],[2,1.71,33.19]],"batl":[[0,2.1,103.82],[1,2.12,116.45],[2,2.22,6.75]],"ltp":1.89,"tv":16699.06,"id":10350473},{"batl":[[0,2.3,7.05],[1,2.42,6.25],[2,2.6,261.12]],"ltp":2.04,"tv":1373.25,"id":9304761}]}]}
{"op":"mcm","clk":"4230287012","pt":1631531281641,"mc":[{"id":"1.187557247","rc":[{"batb":[[0,1.77,303.47],[1,1.76,6],[2,1.75,206.49]],"batl":[[1,2.12,124.91]],"ltp":1.89,"tv":16699.06,"id":10350473},{"batb":[[1,1.9,24.46],[2,1.82,30.64]],"batl":[[0,2.3,4]],"ltp":2.04,"tv":1373.25,"id":9304761}]}]}
{"op":"mcm","clk":"4230287267","pt":1631531284758,"mc":[{"id":"1.187557247","rc":[{"batb":[[0,1.78,34.16],[1,1.77,98.14],[2,1.76,6]],"batl":[[0,2.1,2],[1,2.22,6.75],[2,2.24,6.98]],"ltp":1.89,"tv":16699.06,"id":10350473},{"batb":[[1,1.82,30.64],[2,1.81,27.29]],"batl":[[1,2.34,4],[2,2.42,6.25]],"ltp":2.04,"tv":1373.25,"id":9304761}]}]}
{"op":"mcm","clk":"4230287314","pt":1631531285335,"mc":[{"id":"1.187557247","rc":[{"batb":[[0,1.78,5]],"ltp":1.89,"tv":16699.06,"id":10350473}]}]}
{"op":"mcm","clk":"4230287400","pt":1631531286332,"mc":[{"id":"1.187557247","rc":[{"batl":[[2,2.24,0]],"ltp":1.89,"tv":16699.06,"id":10350473},{"batb":[[2,1.67,415.42]],"ltp":2.04,"tv":1373.25,"id":9304761}]}]}
{"op":"mcm","clk":"4230287515","pt":1631531287672,"mc":[{"id":"1.187557247","rc":[{"batb":[[0,2,956.26],[1,1.99,928.12],[2,1.98,928.12]],"ltp":1.89,"tv":16699.06,"id":10350473},{"batb":[[1,1.9,185.02],[2,1.88,163.88]],"batl":[[0,1.98,173.61],[1,2,138.1],[2,2.3,4]],"ltp":2.04,"tv":1373.25,"id":9304761}]}]}
{"op":"mcm","clk":"4230287620","pt":1631531288764,"mc":[{"id":"1.187557247","rc":[{"trd":[[2.02,30.93]],"batb":[[0,2.02,125.02],[1,2,956.26],[2,1.99,928.12]],"batl":[[1,2.12,56.69],[2,2.22,6.75]],"ltp":2.02,"tv":16709.99,"id":10350473},{"trd":[[1.98,12.64]],"batb":[[1,1.9,63.24],[2,1.87,1022.72]],"batl":[[0,1.98,162.46],[2,2.06,58.27]],"ltp":1.98,"tv":1384.4,"id":9304761}],"tv":18094.4}]}
{"op":"mcm","clk":"4230287679","pt":1631531289443,"mc":[{"id":"1.187557247","rc":[{"batl":[[0,2.1,12]],"ltp":2.02,"tv":16709.99,"id":10350473},{"batb":[[0,1.91,98.5]],"batl":[[2,2.22,20]],"ltp":1.98,"tv":1384.4,"id":9304761}]}]}
{"op":"mcm","clk":"4230287857","pt":1631531291666,"mc":[{"id":"1.187557247","rc":[{"batb":[[0,1.91,210.41],[2,1.89,161.12]],"ltp":1.98,"tv":1384.4,"id":9304761}]}]}
{"op":"mcm","clk":"4230287920","pt":1631531292560,"mc":[{"id":"1.187557247","rc":[{"batl":[[2,2.04,58.83]],"ltp":1.98,"tv":1384.4,"id":9304761}]}]}
{"op":"mcm","clk":"4230288236","pt":1631531296559,"mc":[{"id":"1.187557247","rc":[{"trd":[[2.02,39.68]],"batb":[[0,1.96,15.3],[1,1.87,29.27],[2,1.86,80.33]],"batl":[[0,2.1,2],[2,2.28,6.59]],"ltp":2.02,"tv":16718.74,"id":10350473},{"batb":[[0,1.9,63.24],[1,1.79,33.31],[2,1.78,87.36]],"batl":[[0,2.04,58.83],[1,2.16,6.47],[2,2.18,6.75]],"ltp":1.98,"tv":1384.4,"id":9304761}],"tv":18103.15}]}
{"op":"mcm","clk":"4230288306","pt":1631531297486,"mc":[{"id":"1.187557247","rc":[{"batb":[[0,1.86,80.33],[1,1.8,30.88],[2,1.78,5]],"batl":[[1,2.42,6.25],[2,2.28,0]],"ltp":2.02,"tv":16718.74,"id":10350473},{"batb":[[0,1.78,87.36],[1,1.71,35.19],[2,1.67,415.42]],"batl":[[0,2.26,7.25],[1,2.28,4],[2,2.6,261.12]],"ltp":1.98,"tv":1384.4,"id":9304761}]}]}
{"op":"mcm","clk":"4230288483","pt":1631531299678,"mc":[{"id":"1.187557247","rc":[{"batb":[[0,1.78,234.72],[1,1.76,203.45],[2,1.71,35.19]],"batl":[[0,2.16,115.5],[1,2.18,107.36],[2,2.26,7.25]],"ltp":1.98,"tv":1384.4,"id":9304761}]}]}
{"op":"mcm","clk":"4230288569","pt":1631531300678,"mc":[{"id":"1.187557247","rc":[{"batb":[[0,1.86,82.33],[1,1.85,2],[2,1.8,30.88]],"batl":[[1,2.26,7.75],[2,2.28,6.84]],"ltp":2.02,"tv":16718.74,"id":10350473},{"batb":[[0,1.8,31.28],[1,1.79,35.31],[2,1.78,234.72]],"batl":[[1,2.18,109.36]],"ltp":1.98,"tv":1384.4,"id":9304761}]}]}
{"op":"mcm","clk":"4230288619","pt":1631531301366,"mc":[{"id":"1.187557247","rc":[{"batl":[[0,2.18,2],[1,2.26,7.25],[2,2.28,4]],"ltp":1.98,"tv":1384.4,"id":9304761}]}]}
{"op":"mcm","clk":"4230288826","pt":1631531303691,"mc":[{"id":"1.187557247","rc":[{"trd":[[2.1,2]],"batb":[[0,1.87,28.27],[1,1.86,82.33],[2,1.85,2]],"batl":[[0,2.26,7.75],[1,2.28,6.84],[2,2.42,6.25]],"ltp":2.1,"tv":16720.74,"id":10350473},{"trd":[[1.9,26.21]],"batl":[[0,2.16,7.97],[1,2.18,2],[2,2.26,7.25]],"ltp":1.9,"tv":1386.61,"id":9304761}],"tv":18107.36}]}
{"op":"mcm","clk":"4230288914","pt":1631531304580,"mc":[{"id":"1.187557247","rc":[{"batb":[[0,1.87,644.38]],"batl":[[0,2.34,449.53],[1,2.36,436.3],[2,2.38,436.3]],"ltp":2.1,"tv":16720.74,"id":10350473},{"batb":[[0,1.78,234.72],[1,1.76,203.45],[2,1.71,35.19]],"batl":[[0,1.84,154.16],[1,1.86,1200.88],[2,1.87,997.98]],"ltp":1.9,"tv":1386.61,"id":9304761}]}]}
{"op":"mcm","clk":"4230289005","pt":1631531305673,"mc":[{"id":"1.187557247","rc":[{"batb":[[0,2.18,99.75],[1,2,128.53],[2,1.86,2]],"batl":[[0,2.3,52.62],[1,2.34,449.53],[2,2.36,436.3]],"ltp":2.1,"tv":16720.74,"id":10350473},{"batb":[[1,1.77,68.37],[2,1.76,203.45]],"ltp":1.9,"tv":1386.61,"id":9304761}]}]}
{"op":"mcm","clk":"4230289088","pt":1631531306563,"mc":[{"id":"1.187557247","rc":[{"trd":[[2.18,20.52]],"batb":[[0,2.18,89.49],[2,1.96,118.37]],"ltp":2.18,"tv":16741.26,"id":10350473},{"trd":[[1.84,2.88]],"batl":[[0,1.84,152.72]],"ltp":1.84,"tv":1389.49,"id":9304761}],"tv":18130.76}]}
{"op":"mcm","clk":"4230289151","pt":1631531307390,"mc":[{"id":"1.187557247","rc":[{"batl":[[0,2.28,4],[1,2.3,52.62],[2,2.34,449.53]],"ltp":2.18,"tv":16741.26,"id":10350473},{"batb":[[0,1.78,267.29]],"ltp":1.84,"tv":1389.49,"id":9304761}]}]}
{"op":"mcm","clk":"4230289246","pt":1631531308688,"mc":[{"id":"1.187557247","rc":[{"batb":[[1,2.1,13.63],[2,2,128.53]],"ltp":2.18,"tv":16741.26,"id":10350473}]}]}
{"op":"mcm","clk":"4230289282","pt":1631531309167,"mc":[{"id":"1.187557247","rc":[{"batb":[[1,2,128.53],[2,1.96,118.37]],"ltp":2.18,"tv":16741.26,"id":10350473}]}]}
{"op":"mcm","clk":"4230289385","pt":1631531310570,"mc":[{"id":"1.187557247","rc":[{"batb":[[1,2.04,8.87],[2,2,128.53]],"batl":[[0,2.2,5],[1,2.28,35.25],[2,2.3,52.62]],"ltp":2.18,"tv":16741.26,"id":10350473}]}]}
{"op":"mcm","clk":"4230289553","pt":1631531312498,"mc":[{"id":"1.187557247","rc":[{"batb":[[1,2.12,13.39],[2,2.04,8.87]],"ltp":2.18,"tv":16741.26,"id":10350473}]}]}
{"op":"mcm","clk":"4230289636","pt":1631531313602,"mc":[{"id":"1.187557247","rc":[{"batb":[[0,2.12,13.39],[1,2.02,8.74],[2,2,128.53]],"batl":[[1,2.3,52.62],[2,2.44,5.58]],"ltp":2.18,"tv":16741.26,"id":10350473},{"batb":[[0,1.77,68.37],[1,1.7,35.02],[2,1.68,105.52]],"batl":[[0,1.89,60],[1,1.98,26.25],[2,2.02,7.75]],"ltp":1.84,"tv":1389.49,"id":9304761}]}]}
{"op":"mcm","clk":"4230289703","pt":1631531314483,"mc":[{"id":"1.187557247","rc":[{"batb":[[0,2.02,8.74],[1,2,128.53],[2,1.99,23.51]],"batl":[[1,2.44,5.58],[2,2.58,5.25]],"ltp":2.18,"tv":16741.26,"id":10350473},{"batb":[[0,1.7,35.02],[1,1.68,105.52],[2,1.67,415.42]],"batl":[[0,1.98,26.25],[1,2.02,7.75],[2,2.14,4]],"ltp":1.84,"tv":1389.49,"id":9304761}]}]}
{"op":"mcm","clk":"4230289777","pt":1631531315412,"mc":[{"id":"1.187557247","rc":[{"batb":[[1,2,153.72]],"ltp":2.18,"tv":16741.26,"id":10350473},{"batl":[[1,1.99,24.5],[2,2.02,7.75]],"ltp":1.84,"tv":1389.49,"id":9304761}]}]}
{"op":"mcm","clk":"4230289883","pt":1631531316608,"mc":[{"id":"1.187557247","rc":[{"batb":[[1,1.69,105.27],[2,1.68,169.46]],"batl":[[0,1.98,136.39],[2,2,138.1]],"ltp":1.84,"tv":1389.49,"id":9304761}]}]}
{"op":"mcm","clk":"4230289976","pt":1631531317701,"mc":[{"id":"1.187557247","rc":[{"batb":[[2,1.67,415.42]],"batl":[[0,1.98,30.25],[2,2.02,7.75]],"ltp":1.84,"tv":1389.49,"id":9304761}]}]}
{"op":"mcm","clk":"4230290205","pt":1631531320709,"mc":[{"id":"1.187557247","rc":[{"batb":[[0,2.04,43.7],[1,2.02,8.74],[2,2,153.72]],"ltp":2.18,"tv":16741.26,"id":10350473},{"batb":[[0,1.8,196.85],[1,1.78,195.96],[2,1.71,108.51]],"batl":[[0,1.87,173.99],[1,1.89,164.16],[2,1.93,26.5]],"ltp":1.84,"tv":1389.49,"id":9304761}]}]}
{"op":"mcm","clk":"4230290286","pt":1631531321597,"mc":[{"id":"1.187557247","rc":[{"batb":[[2,1.71,18.08]],"ltp":1.84,"tv":1389.49,"id":9304761}]}]}
{"op":"mcm","clk":"4230290376","pt":1631531322697,"mc":[{"id":"1.187557247","rc":[{"batb":[[0,2.02,8.74],[1,2,153.72],[2,1.99,23.51]],"ltp":2.18,"tv":16741.26,"id":10350473}]}]}
{"op":"mcm","clk":"4230290415","pt":1631531323108,"mc":[{"id":"1.187557247","rc":[{"batb":[[0,1.71,18.08],[1,1.7,35.02],[2,1.69,105.27]],"batl":[[0,1.98,30.25],[1,1.99,24.5],[2,2.02,7.75]],"ltp":1.84,"tv":1389.49,"id":9304761}]}]}
{"op":"mcm","clk":"4230290740","pt":1631531326710,"mc":[{"id":"1.187557247","rc":[{"batb":[[0,1.81,18.08],[1,1.71,18.08],[2,1.7,35.02]],"batl":[[0,1.98,140.39],[2,2,138.1]],"ltp":1.84,"tv":1389.49,"id":9304761}]}]}
{"op":"mcm","clk":"4230290824","pt":1631531327692,"mc":[{"id":"1.187557247","rc":[{"batb":[[0,1.71,18.08],[1,1.7,35.02],[2,1.69,105.27]],"ltp":1.84,"tv":1389.49,"id":9304761}]}]}
{"op":"mcm","clk":"4230291277","pt":1631531333525,"mc":[{"id":"1.187557247","rc":[{"batl":[[0,1.93,25.5],[1,1.98,140.39],[2,1.99,24.5]],"ltp":1.84,"tv":1389.49,"id":9304761}]}]}
{"op":"mcm","clk":"4230291363","pt":1631531334714,"mc":[{"id":"1.187557247","rc":[{"batl":[[0,1.98,140.39],[1,1.99,24.5],[2,2,138.1]],"ltp":1.84,"tv":1389.49,"id":9304761}]}]}
{"op":"mcm","clk":"4230291442","pt":1631531335648,"mc":[{"id":"1.187557247","rc":[{"batl":[[0,2.58,5.25],[1,2.6,5.36],[2,2.62,4.96]],"ltp":2.18,"tv":16741.26,"id":10350473},{"batb":[[1,1.69,105.27],[2,1.68,169.46]],"ltp":1.84,"tv":1389.49,"id":9304761}]}]}
{"op":"mcm","clk":"4230291473","pt":1631531336019,"mc":[{"id":"1.187557247","rc":[{"batb":[[2,1.67,415.42]],"ltp":1.84,"tv":1389.49,"id":9304761}]}]}
{"op":"mcm","clk":"4230291691","pt":1631531338719,"mc":[{"id":"1.187557247","rc":[{"trd":[[2.02,59.35]],"batb":[[0,2,153.72],[1,1.99,1945.61],[2,1.98,1865.58]],"batl":[[0,2.16,2],[1,2.58,5.25],[2,2.6,5.36]],"ltp":2.02,"tv":16760.93,"id":10350473},{"trd":[[1.98,14.87]],"batb":[[0,1.88,2034.58],[1,1.87,1976.78],[2,1.86,1974.74]],"batl":[[0,1.98,134.16]],"ltp":1.98,"tv":1391.72,"id":9304761}],"tv":18152.66}]}
{"op":"mcm","clk":"4230291782","pt":1631531339751,"mc":[{"id":"1.187557247","rc":[{"batb":[[0,2.02,4],[1,2,157.72],[2,1.99,984.57]],"batl":[[1,2.42,4],[2,2.58,5.25]],"ltp":2.02,"tv":16760.93,"id":10350473},{"batb":[[0,1.93,68.2],[1,1.91,170.65],[2,1.89,161.12]],"ltp":1.98,"tv":1391.72,"id":9304761}]}]}
{"op":"mcm","clk":"4230291861","pt":1631531340533,"mc":[{"id":"1.187557247","rc":[{"batb":[[0,2,153.72],[1,1.99,984.57],[2,1.98,513.04]],"batl":[[0,2.14,56.19],[1,2.16,2],[2,2.3,26.25]],"ltp":2.02,"tv":16760.93,"id":10350473}]}]}
{"op":"mcm","clk":"4230291954","pt":1631531341739,"mc":[{"id":"1.187557247","rc":[{"batl":[[2,2.42,4]],"ltp":2.02,"tv":16760.93,"id":10350473},{"batb":[[1,1.92,4],[2,1.91,174.65]],"ltp":1.98,"tv":1391.72,"id":9304761}]}]}
{"op":"mcm","clk":"4230292041","pt":1631531342531,"mc":[{"id":"1.187557247","rc":[{"batl":[[0,2.12,3],[1,2.14,56.19],[2,2.16,2]],"ltp":2.02,"tv":16760.93,"id":10350473}]}]}
{"op":"mcm","clk":"4230292147","pt":1631531343634,"mc":[{"id":"1.187557247","rc":[{"batl":[[0,2.04,8.11],[1,2.12,3],[2,2.14,56.19]],"ltp":2.02,"tv":16760.93,"id":10350473}]}]}
{"op":"mcm","clk":"4230292225","pt":1631531344519,"mc":[{"id":"1.187557247","rc":[{"batl":[[0,2.12,3],[1,2.16,2],[2,2.42,4]],"ltp":2.02,"tv":16760.93,"id":10350473}]}]}
{"op":"mcm","clk":"4230292258","pt":1631531344938,"mc":[{"id":"1.187557247","rc":[{"batl":[[2,2.28,7.09]],"ltp":2.02,"tv":16760.93,"id":10350473}]}]}
{"op":"mcm","clk":"4230292395","pt":1631531346449,"mc":[{"id":"1.187557247","rc":[{"trd":[[2.02,64.35]],"ltp":2.02,"tv":16765.93,"id":10350473},{"trd":[[1.98,19.97]],"batl":[[0,1.98,129.06]],"ltp":1.98,"tv":1396.82,"id":9304761}],"tv":18162.76}]}
{"op":"mcm","clk":"4230292522","pt":1631531347750,"mc":[{"id":"1.187557247","rc":[{"batl":[[0,2.1,39.49],[1,2.12,59.69],[2,2.16,2]],"ltp":2.02,"tv":16765.93,"id":10350473}]}]}
{"op":"mcm","clk":"4230292827","pt":1631531351538,"mc":[{"id":"1.187557247","rc":[{"trd":[[1.93,0.31]],"batb":[[0,1.93,68.05]],"ltp":1.93,"tv":1397.13,"id":9304761}],"tv":18163.06}]}
{"op":"mcm","clk":"4230293237","pt":1631531356748,"mc":[{"id":"1.187557247","rc":[{"batb":[[1,1.99,23.51],[2,1.97,15.23]],"batl":[[0,2.12,59.69],[1,2.16,2],[2,2.28,7.09]],"ltp":2.02,"tv":16765.93,"id":10350473}]}]}
{"op":"mcm","clk":"4230293323","pt":1631531357470,"mc":[{"id":"1.187557247","rc":[{"batb":[[0,1.97,15.23],[1,1.85,116.26],[2,1.81,34.29]],"batl":[[0,2.12,56.69],[1,2.44,5.58],[2,2.58,5.25]],"ltp":2.02,"tv":16765.93,"id":10350473},{"batb":[[0,1.9,63.24],[1,1.79,85.86],[2,1.7,37.12]],"batl":[[0,2.04,58.83],[1,2.18,6.75],[2,2.24,6.48]],"ltp":1.93,"tv":1397.13,"id":9304761}]}]}
{"op":"mcm","clk":"4230293418","pt":1631531358466,"mc":[{"id":"1.187557247","rc":[{"batb":[[0,1.85,116.26],[1,1.81,34.29],[2,1.8,30.88]],"batl":[[0,2.44,5.58],[1,2.58,5.25],[2,2.6,5.36]],"ltp":2.02,"tv":16765.93,"id":10350473},{"batb":[[0,1.79,85.86],[1,1.7,37.12],[2,1.67,415.42]],"batl":[[0,2.18,6.75],[1,2.24,6.48],[2,2.26,7.25]],"ltp":1.93,"tv":1397.13,"id":9304761}]}]}
{"op":"mcm","clk":"4230293445","pt":1631531358776,"mc":[{"id":"1.187557247","rc":[{"batb":[[0,1.85,82.09],[1,1.79,29.31],[2,1.5,106.73]],"ltp":2.02,"tv":16765.93,"id":10350473},{"batl":[[0,2.28,7.09],[1,2.5,278.33],[2,3.45,53.16]],"ltp":1.93,"tv":1397.13,"id":9304761}]}]}
{"op":"mcm","clk":"4230293634","pt":1631531360657,"mc":[{"id":"1.187557247","rc":[{"batl":[[0,2.28,7.09],[1,2.44,5.58],[2,2.58,5.25]],"ltp":2.02,"tv":16765.93,"id":10350473},{"batb":[[0,1.79,115.17],[1,1.78,207.84],[2,1.76,203.59]],"batl":[[0,2.18,171.1],[1,2.2,104.7],[2,2.28,7.09]],"ltp":1.93,"tv":1397.13,"id":9304761}]}]}
{"op":"mcm","clk":"4230293733","pt":1631531361652,"mc":[{"id":"1.187557247","rc":[{"batb":[[0,1.85,86.09],[1,1.84,4],[2,1.79,29.31]],"batl":[[0,2.28,4]],"ltp":2.02,"tv":16765.93,"id":10350473},{"batb":[[0,1.79,85.86]],"batl":[[0,2.18,174.1]],"ltp":1.93,"tv":1397.13,"id":9304761}]}]}
{"op":"mcm","clk":"4230293782","pt":1631531362274,"mc":[{"id":"1.187557247","rc":[{"batl":[[0,2.18,3],[1,2.28,7.09],[2,2.5,278.33]],"ltp":1.93,"tv":1397.13,"id":9304761}]}]}
{"op":"mcm","clk":"4230294014","pt":1631531364575,"mc":[{"id":"1.187557247","rc":[{"batl":[[0,2.28,11.09],[1,2.3,4],[2,2.34,1634.62]],"ltp":2.02,"tv":16765.93,"id":10350473},{"batb":[[0,1.79,120.17]],"batl":[[0,1.85,1740.3],[1,1.86,2056.44],[2,1.87,1995.96]],"ltp":1.93,"tv":1397.13,"id":9304761}]}]}
{"op":"mcm","clk":"4230294113","pt":1631531365669,"mc":[{"id":"1.187557247","rc":[{"trd":[[2.16,20.62]],"batb":[[0,2.16,91.19],[1,2,129.79],[2,1.85,86.09]],"batl":[[0,2.28,4],[2,2.34,449.53]],"ltp":2.16,"tv":16786.55,"id":10350473},{"batb":[[0,1.79,85.86]],"batl":[[0,1.85,199.47],[1,1.86,1028.22],[2,1.87,1167.69]],"ltp":1.93,"tv":1397.13,"id":9304761}],"tv":18183.68}]}
{"op":"mcm","clk":"4230294197","pt":1631531366662,"mc":[{"id":"1.187557247","rc":[{"batb":[[1,2.1,13.63],[2,2,129.79]],"batl":[[0,2.26,20],[1,2.28,4],[2,2.3,56.62]],"ltp":2.16,"tv":16786.55,"id":10350473},{"batb":[[0,1.79,115.92],[2,1.77,68.37]],"ltp":1.93,"tv":1397.13,"id":9304761}]}]}
{"op":"mcm","clk":"4230294305","pt":1631531367761,"mc":[{"id":"1.187557247","rc":[{"batb":[[2,2.08,4]],"ltp":2.16,"tv":16786.55,"id":10350473}]}]}
{"op":"mcm","clk":"4230294470","pt":1631531369595,"mc":[{"id":"1.187557247","rc":[{"batl":[[0,2.2,7.47],[1,2.26,20],[2,2.28,4]],"ltp":2.16,"tv":16786.55,"id":10350473}]}]}
{"op":"mcm","clk":"4230294529","pt":1631531370321,"mc":[{"id":"1.187557247","rc":[{"batb":[[1,2.08,4],[2,2.06,4]],"batl":[[0,2.26,20],[1,2.28,4],[2,2.3,56.62]],"ltp":2.16,"tv":16786.55,"id":10350473}]}]}
{"op":"mcm","clk":"4230294636","pt":1631531371731,"mc":[{"id":"1.187557247","rc":[{"batb":[[0,1.8,18.08],[1,1.79,115.92],[2,1.78,207.84]],"ltp":1.93,"tv":1397.13,"id":9304761}]}]}
{"op":"mcm","clk":"4230294779","pt":1631531373743,"mc":[{"id":"1.187557247","rc":[{"batb":[[1,2.12,13.39],[2,2.08,4]],"ltp":2.16,"tv":16786.55,"id":10350473}]}]}
{"op":"mcm","clk":"4230294995","pt":1631531376712,"mc":[{"id":"1.187557247","rc":[{"batl":[[2,2.3,52.62]],"ltp":2.16,"tv":16786.55,"id":10350473},{"batb":[[2,1.77,68.37]],"batl":[[0,1.85,182.92]],"ltp":1.93,"tv":1397.13,"id":9304761}]}]}
{"op":"mcm","clk":"4230295174","pt":1631531379370,"mc":[{"id":"1.187557247","rc":[{"batb":[[0,2.12,13.39],[1,2.02,8.24],[2,2,157.46]],"batl":[[0,2.3,52.62],[1,2.42,6.25],[2,2.44,5.58]],"ltp":2.16,"tv":16786.55,"id":10350473},{"batb":[[1,1.77,68.37],[2,1.71,37.19]],"batl":[[0,1.88,60],[1,1.95,28.5],[2,1.98,25.75]],"ltp":1.93,"tv":1397.13,"id":9304761}]}]}
{"op":"mcm","clk":"4230295265","pt":1631531380515,"mc":[{"id":"1.187557247","rc":[{"batb":[[0,2,157.46],[1,1.97,27.17],[2,1.86,4]],"batl":[[0,2.42,6.25],[1,2.44,5.58],[2,2.54,5.75]],"ltp":2.16,"tv":16786.55,"id":10350473},{"batb":[[0,1.71,37.19],[1,1.7,37.12],[2,1.69,104.01]],"batl":[[0,2,25.48],[1,2.04,7.88],[2,2.16,4]],"ltp":1.93,"tv":1397.13,"id":9304761}]}]}
{"op":"mcm","clk":"4230295291","pt":1631531380831,"mc":[{"id":"1.187557247","rc":[{"batl":[[0,2.54,5.75],[1,2.58,5.25],[2,2.6,5.36]],"ltp":2.16,"tv":16786.55,"id":10350473},{"batb":[[0,1.69,104.01],[1,1.67,415.42],[2,1.65,42.73]],"ltp":1.93,"tv":1397.13,"id":9304761}]}]}
{"op":"mcm","clk":"4230295419","pt":1631531382750,"mc":[{"id":"1.187557247","rc":[{"batb":[[0,2,27.67],[1,1.99,130.12],[2,1.97,27.17]],"ltp":2.16,"tv":16786.55,"id":10350473},{"batb":[[0,1.69,103.76]],"batl":[[0,1.99,114.07],[1,2,25.48],[2,2.02,202.09]],"ltp":1.93,"tv":1397.13,"id":9304761}]}]}
{"op":"mcm","clk":"4230295483","pt":1631531383429,"mc":[{"id":"1.187557247","rc":[{"batb":[[0,1.69,226.72],[1,1.67,659.26]],"ltp":1.93,"tv":1397.13,"id":9304761}]}]}
{"op":"mcm","clk":"4230295551","pt":1631531384318,"mc":[{"id":"1.187557247","rc":[{"batb":[[2,1.86,4]],"batl":[[0,2.46,3],[1,2.54,5.75],[2,2.6,0]],"ltp":2.16,"tv":16786.55,"id":10350473},{"batb":[[0,1.85,41.84],[1,1.69,230.72],[2,1.68,5]],"batl":[[0,2.16,4],[1,2.5,278.33],[2,3.45,53.16]],"ltp":1.93,"tv":1397.13,"id":9304761}]}]}
{"op":"mcm","clk":"4230295649","pt":1631531385667,"mc":[{"id":"1.187557247","rc":[{"batb":[[1,1.71,18.08],[2,1.7,18.08]],"batl":[[1,3.45,53.16],[2,3.45,0]],"ltp":1.93,"tv":1397.13,"id":9304761}]}]}
{"op":"mcm","clk":"4230295733","pt":1631531386759,"mc":[{"id":"1.187557247","rc":[{"trd":[[1.85,83.68]],"batb":[[0,1.71,18.08],[1,1.7,18.08],[2,1.69,230.72]],"batl":[[0,1.75,2185.72],[1,1.76,2121.44],[2,1.77,2121.44]],"ltp":1.85,"tv":1480.81,"id":9304761}],"tv":18267.36}]}
{"op":"mcm","clk":"4230295814","pt":1631531387743,"mc":[{"id":"1.187557247","rc":[{"trd":[[2.34,19.42]],"batb":[[0,2.34,72.97],[1,2.22,94.06],[2,2,27.67]],"ltp":2.34,"tv":16805.97,"id":10350473},{"batl":[[0,1.74,162.35],[1,1.75,1092.86],[2,1.76,1267.18]],"ltp":1.85,"tv":1480.81,"id":9304761}],"tv":18286.79}]}
{"op":"mcm","clk":"4230295908","pt":1631531388732,"mc":[{"id":"1.187557247","rc":[{"batb":[[2,2.1,107.86]],"ltp":2.34,"tv":16805.97,"id":10350473},{"batb":[[0,1.7,18.08],[1,1.69,230.72],[2,1.68,5]],"ltp":1.85,"tv":1480.81,"id":9304761}]}]}
{"op":"mcm","clk":"4230295981","pt":1631531389519,"mc":[{"id":"1.187557247","rc":[{"batb":[[1,2.24,3],[2,2.22,98.06]],"ltp":2.34,"tv":16805.97,"id":10350473}]}]}
{"op":"mcm","clk":"4230296064","pt":1631531390555,"mc":[{"id":"1.187557247","rc":[{"trd":[[2.34,118.2]],"batb":[[0,2.34,23.58]],"ltp":2.34,"tv":16904.75,"id":10350473}],"tv":18385.57}]}
{"op":"mcm","clk":"4230296168","pt":1631531391754,"mc":[{"id":"1.187557247","rc":[{"batl":[[0,2.36,9.37],[1,2.46,18],[2,2.54,5.75]],"ltp":2.34,"tv":16904.75,"id":10350473}]}]}
{"op":"mcm","clk":"4230296210","pt":1631531392220,"mc":[{"id":"1.187557247","rc":[{"batb":[[1,2.3,11.53],[2,2.24,3]],"batl":[[0,2.46,3],[1,2.54,54.09],[2,2.54,0]],"ltp":2.34,"tv":16904.75,"id":10350473}]}]}
{"op":"mcm","clk":"4230296260","pt":1631531392843,"mc":[{"id":"1.187557247","rc":[{"batb":[[1,2.24,3],[2,2.22,98.06]],"ltp":2.34,"tv":16904.75,"id":10350473}]}]}
{"op":"mcm","clk":"4230296493","pt":1631531395653,"mc":[{"id":"1.187557247","rc":[{"batb":[[1,2.3,84.02],[2,2.24,3]],"ltp":2.34,"tv":16904.75,"id":10350473},{"batb":[[0,1.7,120.25],[2,1.67,243.84]],"batl":[[1,1.75,1152.86]],"ltp":1.85,"tv":1480.81,"id":9304761}]}]}
{"op":"mcm","clk":"4230296570","pt":1631531396328,"mc":[{"id":"1.187557247","rc":[{"batb":[[0,2.32,11.36]],"ltp":2.34,"tv":16904.75,"id":10350473},{"batb":[[1,1.69,126.96]],"ltp":1.85,"tv":1480.81,"id":9304761}]}]}
{"op":"mcm","clk":"4230296741","pt":1631531398664,"mc":[{"id":"1.187557247","rc":[{"batl":[[0,2.46,18]],"ltp":2.34,"tv":16904.75,"id":10350473}]}]}
{"op":"mcm","clk":"4230296807","pt":1631531399440,"mc":[{"id":"1.187557247","rc":[{"batb":[[1,2.3,191.88]],"batl":[[0,2.46,3]],"ltp":2.34,"tv":16904.75,"id":10350473},{"trd":[[1.74,10.42]],"batl":[[0,1.74,157.14]],"ltp":1.74,"tv":1491.23,"id":9304761}],"tv":18395.98}]}
{"op":"mcm","clk":"4230296909","pt":1631531400642,"mc":[{"id":"1.187557247","rc":[{"trd":[[1.7,1.74]],"batb":[[0,1.7,101.31]],"ltp":1.7,"tv":1492.96,"id":9304761}],"tv":18397.72}]}
{"op":"mcm","clk":"4230297344","pt":1631531405660,"mc":[{"id":"1.187557247","rc":[{"batl":[[0,2.46,26.72]],"ltp":2.34,"tv":16904.75,"id":10350473}]}]}
{"op":"mcm","clk":"4230297380","pt":1631531406076,"mc":[{"id":"1.187557247","rc":[{"batl":[[0,2.46,3]],"ltp":2.34,"tv":16904.75,"id":10350473}]}]}
{"op":"mcm","clk":"4230297471","pt":1631531407164,"mc":[{"id":"1.187557247","rc":[{"trd":[[1.7,142.92]],"batb":[[0,1.7,30.72]],"ltp":1.7,"tv":1634.14,"id":9304761}],"tv":18538.9}]}
{"op":"mcm","clk":"4230297772","pt":1631531410452,"mc":[{"id":"1.187557247","rc":[{"trd":[[1.74,210.42]],"batl":[[0,1.75,1152.86],[1,1.76,1060.72],[2,1.77,1060.72]],"ltp":1.74,"tv":1834.14,"id":9304761}],"tv":18738.9}]}
{"op":"mcm","clk":"4230297952","pt":1631531412690,"mc":[{"id":"1.187557247","rc":[{"batb":[[0,2.32,94.2],[1,2.3,107.86]],"batl":[[0,2.46,18]],"ltp":2.34,"tv":16904.75,"id":10350473},{"batb":[[0,1.69,230.47],[1,1.67,243.84],[2,1.65,754.65]],"ltp":1.74,"tv":1834.14,"id":9304761}]}]}
{"op":"mcm","clk":"4230298014","pt":1631531413373,"mc":[{"id":"1.187557247","rc":[{"batl":[[0,2.46,3]],"ltp":2.34,"tv":16904.75,"id":10350473},{"batb":[[0,1.69,297]],"batl":[[0,1.75,1354.76],[2,1.77,1262.98]],"ltp":1.74,"tv":1834.14,"id":9304761}]}]}
{"op":"mcm","clk":"4230298222","pt":1631531415662,"mc":[{"id":"1.187557247","rc":[{"batb":[[0,1.69,327.22]],"ltp":1.74,"tv":1834.14,"id":9304761}]}]}
{"op":"mcm","clk":"4230298321","pt":1631531416660,"mc":[{"id":"1.187557247","rc":[{"batb":[[2,2.22,98.22]],"ltp":2.34,"tv":16904.75,"id":10350473}]}]}
{"op":"mcm","clk":"4230298444","pt":1631531418161,"mc":[{"id":"1.187557247","rc":[{"batl":[[0,1.7,28.24],[1,1.75,1354.76],[2,1.76,1060.72]],"ltp":1.74,"tv":1834.14,"id":9304761}]}]}
{"op":"mcm","clk":"4230298557","pt":1631531419501,"mc":[{"id":"1.187557247","rc":[{"batl":[[0,2.44,15],[1,2.46,3],[2,2.54,54.09]],"ltp":2.34,"tv":16904.75,"id":10350473}]}]}
{"op":"mcm","clk":"4230298721","pt":1631531421377,"mc":[{"id":"1.187557247","rc":[{"trd":[[1.69,4.02]],"batb":[[0,1.69,325.21]],"ltp":1.69,"tv":1838.16,"id":9304761}],"tv":18742.92}]}
{"op":"mcm","clk":"4230298995","pt":1631531424599,"mc":[{"id":"1.187557247","rc":[{"trd":[[1.69,568.72],[1.7,177.16]],"batb":[[0,1.69,42.86]],"batl":[[0,1.7,257.12]],"ltp":1.69,"tv":2437.11,"id":9304761}],"tv":19341.86}]}
{"op":"mcm","clk":"4230299051","pt":1631531425404,"mc":[{"id":"1.187557247","rc":[{"batb":[[0,1.65,754.65],[1,1.64,1125],[2,1.63,1125]],"batl":[[1,1.75,1152.86]],"ltp":1.69,"tv":2437.11,"id":9304761}]}]}
{"op":"mcm","clk":"4230299335","pt":1631531428693,"mc":[{"id":"1.187557247","rc":[{"batb":[[0,2.34,81.09],[1,2.32,11.36],[2,2.3,107.86]],"ltp":2.34,"tv":16904.75,"id":10350473},{"trd":[[1.7,210.6]],"batb":[[0,1.69,39.75],[1,1.68,323.08],[2,1.66,249.72]],"batl":[[0,1.7,240.4],[1,1.74,192.76],[2,1.75,1152.86]],"ltp":1.7,"tv":2470.55,"id":9304761}],"tv":19375.3}]}
{"op":"mcm","clk":"4230300022","pt":1631531436714,"mc":[{"id":"1.187557247","rc":[{"trd":[[2.42,4]],"ltp":2.42,"tv":16908.75,"id":10350473},{"trd":[[1.7,216.29]],"batl":[[0,1.7,234.71]],"ltp":1.7,"tv":2476.24,"id":9304761}],"tv":19384.99}]}
{"op":"mcm","clk":"4230300350","pt":1631531440601,"mc":[{"id":"1.187557247","rc":[{"batl":[[0,2.46,3],[1,2.54,54.09],[2,2.54,0]],"ltp":2.42,"tv":16908.75,"id":10350473},{"trd":[[1.69,639.3]],"batb":[[0,1.69,4.46],[1,1.68,318.08]],"ltp":1.69,"tv":2546.82,"id":9304761}],"tv":19455.57}]}
{"op":"mcm","clk":"4230300706","pt":1631531444495,"mc":[{"id":"1.187557247","rc":[{"batl":[[0,2.46,18]],"ltp":2.42,"tv":16908.75,"id":10350473}]}]}
{"op":"mcm","clk":"4230301697","pt":1631531456218,"mc":[{"id":"1.187557247","rc":[{"trd":[[1.68,626.38],[1.69,648.22]],"batb":[[0,1.68,4.9],[1,1.66,249.72],[2,1.65,754.65]],"ltp":1.68,"tv":3182.11,"id":9304761}],"tv":20090.87}]}
{"op":"mcm","clk":"4230301740","pt":1631531456840,"mc":[{"id":"1.187557247","rc":[{"batb":[[1,1.66,125.94]],"batl":[[1,1.75,1152.86],[2,1.76,1060.72]],"ltp":1.68,"tv":3182.11,"id":9304761}]}]}
{"op":"mcm","clk":"4230301944","pt":1631531459721,"mc":[{"id":"1.187557247","rc":[{"batb":[[0,1.69,6],[1,1.68,9.9],[2,1.67,212.86]],"batl":[[1,1.73,206.01],[2,1.75,1363.8]],"ltp":1.68,"tv":3182.11,"id":9304761}]}]}
{"op":"mcm","clk":"4230301993","pt":1631531460440,"mc":[{"id":"1.187557247","rc":[{"batb":[[0,1.69,30.5]],"ltp":1.68,"tv":3182.11,"id":9304761}]}]}
{"op":"mcm","clk":"4230302055","pt":1631531461225,"mc":[{"id":"1.187557247","rc":[{"trd":[[1.69,660.22]],"batb":[[0,1.68,9.9],[1,1.67,212.86],[2,1.66,125.94]],"batl":[[0,1.7,235.54]],"ltp":1.69,"tv":3194.11,"id":9304761}],"tv":20102.87}]}
{"op":"mcm","clk":"4230302301","pt":1631531464438,"mc":[{"id":"1.187557247","rc":[{"batb":[[0,1.68,45.37]],"ltp":1.69,"tv":3194.11,"id":9304761}]}]}
{"op":"mcm","clk":"4230302557","pt":1631531467966,"mc":[{"id":"1.187557247","rc":[{"batl":[[0,1.69,36.12],[1,1.7,234.71],[2,1.73,206.01]],"ltp":1.69,"tv":3194.11,"id":9304761}]}]}
{"op":"mcm","clk":"4230302746","pt":1631531470154,"mc":[{"id":"1.187557247","rc":[{"batb":[[2,1.66,2190.88]],"ltp":1.69,"tv":3194.11,"id":9304761}]}]}
{"op":"mcm","clk":"4230303145","pt":1631531474873,"mc":[{"id":"1.187557247","rc":[{"trd":[[1.69,672.23]],"batl":[[0,1.69,30.12]],"ltp":1.69,"tv":3206.12,"id":9304761}],"tv":20114.87}]}
{"op":"mcm","clk":"4230303361","pt":1631531477574,"mc":[{"id":"1.187557247","rc":[{"batl":[[2,2.6,5.76]],"ltp":2.42,"tv":16908.75,"id":10350473}]}]}
{"op":"mcm","clk":"4230303498","pt":1631531479154,"mc":[{"id":"1.187557247","rc":[{"trd":[[2.44,0.99]],"ltp":2.44,"tv":16909.74,"id":10350473},{"trd":[[1.69,673.66]],"batl":[[0,1.69,28.69]],"ltp":1.69,"tv":3207.55,"id":9304761}],"tv":20117.29}]}
{"op":"mcm","clk":"4230303870","pt":1631531483376,"mc":[{"id":"1.187557247","rc":[{"batb":[[2,2.28,7.66]],"batl":[[0,2.46,3]],"ltp":2.44,"tv":16909.74,"id":10350473},{"batb":[[0,1.68,9.9]],"ltp":1.69,"tv":3207.55,"id":9304761}]}]}
{"op":"mcm","clk":"4230304012","pt":1631531485084,"mc":[{"id":"1.187557247","rc":[{"trd":[[1.69,688.66]],"batl":[[0,1.69,21.19]],"ltp":1.69,"tv":3222.55,"id":9304761}],"tv":20132.29}]}
{"op":"mcm","clk":"4230304430","pt":1631531490500,"mc":[{"id":"1.187557247","rc":[{"batl":[[0,2.46,18]],"ltp":2.44,"tv":16909.74,"id":10350473},{"trd":[[1.69,702.32]],"batb":[[0,1.68,45.37]],"batl":[[0,1.69,14.36]],"ltp":1.69,"tv":3236.21,"id":9304761}],"tv":20145.95}]}
{"op":"mcm","clk":"4230304453","pt":1631531490768,"mc":[{"id":"1.187557247","rc":[{"batl":[[0,2.46,3]],"ltp":2.44,"tv":16909.74,"id":10350473}]}]}
{"op":"mcm","clk":"4230304675","pt":1631531493680,"mc":[{"id":"1.187557247","rc":[{"trd":[[1.69,712.94]],"batl":[[0,1.69,9.05]],"ltp":1.69,"tv":3246.83,"id":9304761}],"tv":20156.57}]}
{"op":"mcm","clk":"4230304977","pt":1631531497473,"mc":[{"id":"1.187557247","rc":[{"batl":[[0,2.46,18]],"ltp":2.44,"tv":16909.74,"id":10350473}]}]}
{"op":"mcm","clk":"4230305154","pt":1631531499589,"mc":[{"id":"1.187557247","rc":[{"batb":[[0,2.32,11.36],[1,2.28,7.66],[2,2.24,96.3]],"batl":[[0,2.46,3],[1,2.54,48.34]],"ltp":2.44,"tv":16909.74,"id":10350473},{"trd":[[1.69,728.56]],"batb":[[0,1.68,5],[1,1.66,2064.94],[2,1.65,74.42]],"batl":[[0,1.69,1.24],[2,1.75,60]],"ltp":1.69,"tv":3262.45,"id":9304761}],"tv":20172.19}]}
{"op":"mcm","clk":"4230305241","pt":1631531500520,"mc":[{"id":"1.187557247","rc":[{"batb":[[0,2.28,7.66],[1,2.24,96.3],[2,2.22,3]],"batl":[[0,2.6,5.76],[1,2.68,5.14],[2,2.6,0]],"ltp":2.44,"tv":16909.74,"id":10350473},{"batb":[[0,1.66,2064.94],[1,1.63,42.23],[2,1.61,123.68]],"batl":[[1,1.77,31.5],[2,1.94,4]],"ltp":1.69,"tv":3262.45,"id":9304761}]}]}
{"op":"mcm","clk":"4230305297","pt":1631531501096,"mc":[{"id":"1.187557247","rc":[{"batl":[[0,2.68,5.14],[1,2.68,0]],"ltp":2.44,"tv":16909.74,"id":10350473},{"batb":[[0,1.61,123.68],[1,1.6,40.44],[2,1.3,197.5]],"ltp":1.69,"tv":3262.45,"id":9304761}]}]}
{"op":"mcm","clk":"4230305444","pt":1631531502712,"mc":[{"id":"1.187557247","rc":[{"batb":[[1,2.26,90.38],[2,2.24,96.3]],"ltp":2.44,"tv":16909.74,"id":10350473},{"batb":[[0,1.61,255.63],[1,1.6,310.69]],"batl":[[2,1.79,136.93]],"ltp":1.69,"tv":3262.45,"id":9304761}]}]}
{"op":"mcm","clk":"4230305520","pt":1631531503700,"mc":[{"id":"1.187557247","rc":[{"batb":[[0,2.28,10.66],[1,2.26,94.38],[2,2.24,4]],"ltp":2.44,"tv":16909.74,"id":10350473},{"batb":[[0,1.61,131.95]],"ltp":1.69,"tv":3262.45,"id":9304761}]}]}
{"op":"mcm","clk":"4230305621","pt":1631531504702,"mc":[{"id":"1.187557247","rc":[{"batl":[[0,2.6,3],[1,2.64,3],[2,2.68,5.14]],"ltp":2.44,"tv":16909.74,"id":10350473},{"batb":[[0,1.63,6],[1,1.62,5],[2,1.61,137.95]],"ltp":1.69,"tv":3262.45,"id":9304761}]}]}
{"op":"mcm","clk":"4230305867","pt":1631531507608,"mc":[{"id":"1.187557247","rc":[{"batb":[[0,1.63,518],[1,1.62,517]],"ltp":1.69,"tv":3262.45,"id":9304761}]}]}
{"op":"mcm","clk":"4230305894","pt":1631531507919,"mc":[{"id":"1.187557247","rc":[{"batl":[[0,2.6,8.31]],"ltp":2.44,"tv":16909.74,"id":10350473},{"batb":[[0,1.63,554.23],[1,1.62,535.08]],"ltp":1.69,"tv":3262.45,"id":9304761}]}]}
{"op":"mcm","clk":"4230306027","pt":1631531509425,"mc":[{"id":"1.187557247","rc":[{"batb":[[2,1.7,16.94]],"ltp":2.44,"tv":16909.74,"id":10350473},{"trd":[[1.69,731.04],[1.77,19.62]],"batb":[[1,1.62,517]],"batl":[[0,1.77,21.69],[1,1.79,136.93],[2,1.81,188.53]],"ltp":1.77,"tv":3284.56,"id":9304761}],"tv":20194.3}]}
{"op":"mcm","clk":"4230306328","pt":1631531512698,"mc":[{"id":"1.187557247","rc":[{"batb":[[0,1.73,8.04],[1,1.63,554.23],[2,1.62,517]],"batl":[[0,1.79,136.93],[1,1.81,188.53],[2,1.94,4]],"ltp":1.77,"tv":3284.56,"id":9304761}]}]}
{"op":"mcm","clk":"4230306369","pt":1631531513216,"mc":[{"id":"1.187557247","rc":[{"batb":[[0,1.64,18.08]],"ltp":1.77,"tv":3284.56,"id":9304761}]}]}
{"op":"mcm","clk":"4230306507","pt":1631531514724,"mc":[{"id":"1.187557247","rc":[{"batb":[[0,2.28,7.66],[1,2.26,90.38]],"ltp":2.44,"tv":16909.74,"id":10350473}]}]}
{"op":"mcm","clk":"4230306592","pt":1631531515716,"mc":[{"id":"1.187557247","rc":[{"trd":[[2.26,4.78],[2.28,15.32]],"batb":[[0,2.26,87.99],[1,2.22,473.81],[2,2.2,459.89]],"batl":[[0,2.4,796.88],[1,2.42,777.5],[2,2.44,773.44]],"ltp":2.26,"tv":16929.84,"id":10350473},{"batb":[[0,1.73,213.8],[1,1.71,241.99],[2,1.64,18.08]],"batl":[[0,1.79,140.93]],"ltp":1.77,"tv":3284.56,"id":9304761}],"tv":20214.4}]}
{"op":"mcm","clk":"4230306690","pt":1631531516498,"mc":[{"id":"1.187557247","rc":[{"batb":[[2,2.2,472.39]],"batl":[[0,2.4,847.58]],"ltp":2.26,"tv":16929.84,"id":10350473},{"batb":[[0,1.73,309.45],[1,1.71,313.19],[2,1.67,109.04]],"batl":[[0,1.79,136.93],[2,1.84,60]],"ltp":1.77,"tv":3284.56,"id":9304761}]}]}
{"op":"mcm","clk":"4230306905","pt":1631531518633,"mc":[{"id":"1.187557247","rc":[{"batl":[[0,2.36,3],[1,2.38,4],[2,2.4,847.58]],"ltp":2.26,"tv":16929.84,"id":10350473},{"batb":[[0,1.74,5],[1,1.73,315.45],[2,1.72,5]],"ltp":1.77,"tv":3284.56,"id":9304761}]}]}
{"op":"mcm","clk":"4230307124","pt":1631531520612,"mc":[{"id":"1.187557247","rc":[{"trd":[[2.26,18.28]],"batb":[[0,2.26,81.24]],"batl":[[2,2.4,796.88]],"ltp":2.26,"tv":16943.34,"id":10350473}],"tv":20227.9}]}
{"op":"mcm","clk":"4230307238","pt":1631531521819,"mc":[{"id":"1.187557247","rc":[{"batb":[[0,2.32,5.64],[1,2.26,81.24],[2,2.22,473.81]],"batl":[[0,2.34,3],[1,2.36,3],[2,2.38,4]],"ltp":2.26,"tv":16943.34,"id":10350473},{"trd":[[1.75,8]],"batl":[[0,1.75,27.34],[1,1.79,136.93],[2,1.81,188.53]],"ltp":1.75,"tv":3292.56,"id":9304761}],"tv":20235.9}]}
{"op":"mcm","clk":"4230307493","pt":1631531523703,"mc":[{"id":"1.187557247","rc":[{"batl":[[0,2.34,44.55],[2,2.38,55.07]],"ltp":2.26,"tv":16943.34,"id":10350473},{"trd":[[1.75,62.68]],"batb":[[0,1.75,63.06],[1,1.74,5],[2,1.73,385.67]],"batl":[[0,1.79,136.93],[1,1.81,188.53],[2,1.84,60]],"ltp":1.75,"tv":3347.24,"id":9304761}],"tv":20290.58}]}
{"op":"mcm","clk":"4230307587","pt":1631531524743,"mc":[{"id":"1.187557247","rc":[{"batl":[[0,2.34,18]],"ltp":2.26,"tv":16943.34,"id":10350473},{"batb":[[0,1.74,5],[1,1.73,385.67],[2,1.72,5]],"ltp":1.75,"tv":3347.24,"id":9304761}]}]}
{"op":"mcm","clk":"4230307822","pt":1631531526730,"mc":[{"id":"1.187557247","rc":[{"trd":[[2.34,136.2]],"batb":[[0,2.26,81.24],[1,2.24,7.77],[2,2.2,12.5]],"batl":[[0,2.36,3],[1,2.38,55.07],[2,2.48,5.49]],"ltp":2.34,"tv":16961.34,"id":10350473},{"trd":[[1.73,435.7],[1.74,244.63]],"batb":[[0,1.73,167.82],[1,1.72,5],[2,1.71,229.8]],"batl":[[1,1.8,29.62],[2,1.81,188.53]],"ltp":1.73,"tv":3817.15,"id":9304761}],"tv":20778.49}]}
{"op":"mcm","clk":"4230307918","pt":1631531527722,"mc":[{"id":"1.187557247","rc":[{"batb":[[0,2.24,7.77],[1,2.22,6.34]],"ltp":2.34,"tv":16961.34,"id":10350473},{"batb":[[0,1.73,76.22],[2,1.71,5]],"batl":[[0,1.8,29.62],[1,1.81,33.5],[2,1.84,60]],"ltp":1.73,"tv":3817.15,"id":9304761}]}]}
{"op":"mcm","clk":"4230308007","pt":1631531528610,"mc":[{"id":"1.187557247","rc":[{"batb":[[2,2.16,102.09]],"batl":[[0,2.48,5.49],[1,2.52,5.26],[2,2.54,5.38]],"ltp":2.34,"tv":16961.34,"id":10350473},{"batb":[[0,1.69,312],[1,1.68,351.36],[2,1.67,109.04]],"batl":[[2,1.94,4]],"ltp":1.73,"tv":3817.15,"id":9304761}]}]}
{"op":"mcm","clk":"4230308204","pt":1631531530736,"mc":[{"id":"1.187557247","rc":[{"batb":[[0,1.75,2.32],[1,1.69,312],[2,1.68,351.36]],"ltp":1.73,"tv":3817.15,"id":9304761}]}]}
{"op":"mcm","clk":"4230308280","pt":1631531531415,"mc":[{"id":"1.187557247","rc":[{"batb":[[2,2.16,101.84]],"ltp":2.34,"tv":16961.34,"id":10350473},{"batl":[[2,1.85,194.51]],"ltp":1.73,"tv":3817.15,"id":9304761}]}]}
{"op":"mcm","clk":"4230308326","pt":1631531531832,"mc":[{"id":"1.187557247","rc":[{"batl":[[0,2.46,4],[1,2.48,5.49],[2,2.52,5.26]],"ltp":2.34,"tv":16961.34,"id":10350473}]}]}
{"op":"mcm","clk":"4230308483","pt":1631531533753,"mc":[{"id":"1.187557247","rc":[{"batl":[[0,1.78,29.75],[1,1.8,29.62],[2,1.81,33.5]],"ltp":1.73,"tv":3817.15,"id":9304761}]}]}
{"op":"mcm","clk":"4230308515","pt":1631531534117,"mc":[{"id":"1.187557247","rc":[{"batl":[[0,1.8,29.62],[1,1.81,33.5],[2,1.85,194.51]],"ltp":1.73,"tv":3817.15,"id":9304761}]}]}
{"op":"mcm","clk":"4230308718","pt":1631531536732,"mc":[{"id":"1.187557247","rc":[{"trd":[[2.22,5.08],[2.24,15.54]],"batb":[[0,2.22,3.8],[1,2.16,101.84],[2,1.6,98.81]],"ltp":2.22,"tv":16981.96,"id":10350473},{"trd":[[1.8,59.24]],"batb":[[0,1.8,2116.16],[1,1.79,1312.84],[2,1.78,656.42]],"batl":[[0,1.81,33.5],[1,1.85,194.51],[2,1.87,169.63]],"ltp":1.8,"tv":3876.39,"id":9304761}],"tv":20858.35}]}
{"op":"mcm","clk":"4230308801","pt":1631531537725,"mc":[{"id":"1.187557247","rc":[{"trd":[[2.26,25.19]],"batb":[[2,2.14,549.07]],"batl":[[0,2.36,9.32],[1,2.46,4],[2,2.48,5.49]],"ltp":2.26,"tv":16988.87,"id":10350473},{"trd":[[1.8,73.92]],"batb":[[0,1.8,2104.48],[1,1.79,262.56],[2,1.78,326.63]],"ltp":1.8,"tv":3891.07,"id":9304761}],"tv":20879.94}]}
{"op":"mcm","clk":"4230308870","pt":1631531538553,"mc":[{"id":"1.187557247","rc":[{"trd":[[2.22,39.99]],"batb":[[0,2.16,101.84],[1,2.14,137.26],[2,2.12,68.64]],"batl":[[0,2.22,45.89],[1,2.28,53.03],[2,2.36,9.32]],"ltp":2.22,"tv":17023.78,"id":10350473},{"trd":[[1.81,33.5]],"batb":[[1,1.79,348.08]],"batl":[[0,1.85,194.51],[1,1.87,169.63],[2,2.26,8.85]],"ltp":1.81,"tv":3924.57,"id":9304761}],"tv":20948.35}]}
{"op":"mcm","clk":"4230309066","pt":1631531540535,"mc":[{"id":"1.187557247","rc":[{"batl":[[1,2.24,3]],"ltp":2.22,"tv":17023.78,"id":10350473},{"batb":[[0,1.81,5],[1,1.8,2108.48],[2,1.79,348.08]],"ltp":1.81,"tv":3924.57,"id":9304761}]}]}
{"op":"mcm","clk":"4230309178","pt":1631531541736,"mc":[{"id":"1.187557247","rc":[{"batb":[[1,2.1,112.22],[2,1.6,98.81]],"batl":[[0,2.18,5.48],[1,2.22,45.89]],"ltp":2.22,"tv":17023.78,"id":10350473},{"batb":[[0,1.79,153.02],[1,1.78,195.35],[2,1.76,203.39]],"batl":[[2,1.91,86.52]],"ltp":1.81,"tv":3924.57,"id":9304761}]}]}
{"op":"mcm","clk":"4230309232","pt":1631531542364,"mc":[{"id":"1.187557247","rc":[{"batb":[[0,2.1,112.22],[1,1.6,98.81],[2,1.5,106.73]],"batl":[[0,2.22,45.89],[1,2.46,4],[2,2.54,5.38]],"ltp":2.22,"tv":17023.78,"id":10350473},{"batb":[[0,1.75,2.32],[1,1.73,96.99],[2,1.65,46.93]],"batl":[[0,3.45,53.16],[1,1.87,0],[2,1.91,0]],"ltp":1.81,"tv":3924.57,"id":9304761}]}]}
{"op":"mcm","clk":"4230309345","pt":1631531543767,"mc":[{"id":"1.187557247","rc":[{"batl":[[1,2.24,53.88],[2,2.42,6.25]],"ltp":2.22,"tv":17023.78,"id":10350473},{"batb":[[2,1.71,84.19]],"ltp":1.81,"tv":3924.57,"id":9304761}]}]}
{"op":"mcm","clk":"4230309417","pt":1631531544657,"mc":[{"id":"1.187557247","rc":[{"batb":[[0,2.16,4],[1,2.14,4],[2,2.1,112.22]],"batl":[[1,2.46,4],[2,2.54,5.38]],"ltp":2.22,"tv":17023.78,"id":10350473},{"batb":[[2,1.65,46.93]],"batl":[[0,1.85,4],[1,3.45,53.16]],"ltp":1.81,"tv":3924.57,"id":9304761}]}]}
{"op":"mcm","clk":"4230309498","pt":1631531545543,"mc":[{"id":"1.187557247","rc":[{"batb":[[2,2.1,116.22]],"ltp":2.22,"tv":17023.78,"id":10350473},{"batb":[[2,1.72,204.46]],"batl":[[1,1.87,4],[2,1.9,135.9]],"ltp":1.81,"tv":3924.57,"id":9304761}]}]}
{"op":"mcm","clk":"4230309642","pt":1631531547359,"mc":[{"id":"1.187557247","rc":[{"batl":[[1,2.42,6.75],[2,2.46,4]],"ltp":2.22,"tv":17023.78,"id":10350473}]}]}
{"op":"mcm","clk":"4230309702","pt":1631531548038,"mc":[{"id":"1.187557247","rc":[{"batl":[[0,2.42,6.75],[1,2.46,4],[2,2.54,5.38]],"ltp":2.22,"tv":17023.78,"id":10350473}]}]}
{"op":"mcm","clk":"4230309948","pt":1631531550676,"mc":[{"id":"1.187557247","rc":[{"batb":[[2,1.71,83.19]],"batl":[[2,1.91,4]],"ltp":1.81,"tv":3924.57,"id":9304761}]}]}
{"op":"mcm","clk":"4230309976","pt":1631531550938,"mc":[{"id":"1.187557247","rc":[{"batl":[[0,2.46,4],[1,2.54,5.38],[2,2.54,0]],"ltp":2.22,"tv":17023.78,"id":10350473},{"batb":[[2,1.65,46.93]],"ltp":1.81,"tv":3924.57,"id":9304761}]}]}
{"op":"mcm","clk":"4230310238","pt":1631531553751,"mc":[{"id":"1.187557247","rc":[{"trd":[[1.84,22.4]],"batb":[[0,1.77,173.75],[1,1.75,209.74],[2,1.73,96.99]],"batl":[[0,1.83,137.45],[1,1.85,179.68],[2,1.87,4]],"ltp":1.84,"tv":3944.09,"id":9304761}],"tv":20967.87}]}
{"op":"mcm","clk":"4230310316","pt":1631531554688,"mc":[{"id":"1.187557247","rc":[{"batl":[[0,2.42,6.75],[1,2.46,4],[2,2.54,5.38]],"ltp":2.22,"tv":17023.78,"id":10350473}]}]}
{"op":"mcm","clk":"4230310499","pt":1631531556670,"mc":[{"id":"1.187557247","rc":[{"batl":[[1,1.84,4],[2,1.85,179.68]],"ltp":1.84,"tv":3944.09,"id":9304761}]}]}
{"op":"mcm","clk":"4230310511","pt":1631531556778,"mc":[{"id":"1.187557247","rc":[{"batb":[[1,2.1,116.22],[2,2.08,4]],"ltp":2.22,"tv":17023.78,"id":10350473}]}]}
{"op":"mcm","clk":"4230310641","pt":1631531558188,"mc":[{"id":"1.187557247","rc":[{"batb":[[1,2.1,112.22],[2,1.6,98.81]],"batl":[[0,2.46,4],[1,2.54,5.38],[2,2.54,0]],"ltp":2.22,"tv":17023.78,"id":10350473},{"batb":[[0,1.75,2.32],[1,1.73,96.99],[2,1.65,46.93]],"batl":[[0,1.84,4],[1,3.45,53.16],[2,1.85,0]],"ltp":1.84,"tv":3944.09,"id":9304761}]}]}
{"op":"mcm","clk":"4230310757","pt":1631531559495,"mc":[{"id":"1.187557247","rc":[{"trd":[[1.73,572.24],[1.75,67.32]],"batb":[[0,1.73,28.72],[1,1.65,46.93],[2,1.3,197.5]],"ltp":1.73,"tv":4085.27,"id":9304761}],"tv":21109.05}]}
{"op":"mcm","clk":"4230310929","pt":1631531561471,"mc":[{"id":"1.187557247","rc":[{"batl":[[0,2.42,6.75],[1,2.46,4],[2,2.54,5.38]],"ltp":2.22,"tv":17023.78,"id":10350473},{"batb":[[1,1.72,204.46],[2,1.71,86.19]],"batl":[[1,1.9,135.9],[2,1.92,156]],"ltp":1.73,"tv":4085.27,"id":9304761}]}]}
{"op":"mcm","clk":"4230310957","pt":1631531561887,"mc":[{"id":"1.187557247","rc":[{"batl":[[1,3.45,53.16],[2,1.92,0]],"ltp":1.73,"tv":4085.27,"id":9304761}]}]}
{"op":"mcm","clk":"4230311044","pt":1631531562774,"mc":[{"id":"1.187557247","rc":[{"batb":[[0,1.72,204.46],[1,1.71,86.19],[2,1.7,229.72]],"ltp":1.73,"tv":4085.27,"id":9304761}]}]}
{"op":"mcm","clk":"4230311194","pt":1631531564589,"mc":[{"id":"1.187557247","rc":[{"batl":[[0,1.78,1841.92],[1,1.79,2136.88],[2,1.8,2074.02]],"ltp":1.73,"tv":4085.27,"id":9304761}]}]}
{"op":"mcm","clk":"4230311293","pt":1631531565685,"mc":[{"id":"1.187557247","rc":[{"trd":[[2.28,25.37]],"batb":[[0,2.28,87.7],[1,2.18,101.25],[2,2.1,112.22]],"ltp":2.28,"tv":17033.83,"id":10350473},{"trd":[[1.78,12.87]],"batb":[[0,1.72,302.78]],"batl":[[0,1.78,161.56],[1,1.79,1068.44],[2,1.8,1229.2]],"ltp":1.78,"tv":4098.14,"id":9304761}],"tv":21131.97}]}
{"op":"mcm","clk":"4230311357","pt":1631531566367,"mc":[{"id":"1.187557247","rc":[{"batb":[[1,2.2,12.5],[2,2.18,101.25]],"batl":[[0,2.4,50.7],[1,2.42,6.75],[2,2.46,4]],"ltp":2.28,"tv":17033.83,"id":10350473},{"batb":[[0,1.72,373.49]],"ltp":1.78,"tv":4098.14,"id":9304761}]}]}
{"op":"mcm","clk":"4230311420","pt":1631531567096,"mc":[{"id":"1.187557247","rc":[{"batb":[[2,2.18,121.25]],"ltp":2.28,"tv":17033.83,"id":10350473},{"batb":[[0,1.73,46.2],[1,1.72,373.49],[2,1.71,86.19]],"ltp":1.78,"tv":4098.14,"id":9304761}]}]}
{"op":"mcm","clk":"4230311513","pt":1631531568085,"mc":[{"id":"1.187557247","rc":[{"batl":[[0,2.38,4],[1,2.4,50.7],[2,2.42,6.75]],"ltp":2.28,"tv":17033.83,"id":10350473},{"batb":[[0,1.73,5],[1,1.72,377.49]],"ltp":1.78,"tv":4098.14,"id":9304761}]}]}
{"op":"mcm","clk":"4230311744","pt":1631531570593,"mc":[{"id":"1.187557247","rc":[{"trd":[[2.28,113.37]],"batb":[[0,2.28,43.7]],"batl":[[0,2.36,4],[1,2.38,4],[2,2.4,50.7]],"ltp":2.28,"tv":17121.83,"id":10350473},{"batb":[[0,1.74,4],[1,1.73,5],[2,1.72,377.49]],"ltp":1.78,"tv":4098.14,"id":9304761}],"tv":21219.97}]}
{"op":"mcm","clk":"4230311825","pt":1631531571484,"mc":[{"id":"1.187557247","rc":[{"batb":[[0,1.74,24]],"ltp":1.78,"tv":4098.14,"id":9304761}]}]}
{"op":"mcm","clk":"4230312031","pt":1631531573718,"mc":[{"id":"1.187557247","rc":[{"batl":[[0,2.34,4],[1,2.36,40.63],[2,2.38,4]],"ltp":2.28,"tv":17121.83,"id":10350473},{"batb":[[0,1.75,4],[1,1.74,24],[2,1.73,5]],"ltp":1.78,"tv":4098.14,"id":9304761}]}]}
{"op":"mcm","clk":"4230312280","pt":1631531576686,"mc":[{"id":"1.187557247","rc":[{"batl":[[0,1.78,156.91]],"ltp":1.78,"tv":4098.14,"id":9304761}]}]}
{"op":"mcm","clk":"4230312361","pt":1631531577684,"mc":[{"id":"1.187557247","rc":[{"batb":[[0,2.2,12.5],[1,2.18,101.25],[2,2.14,4]],"batl":[[0,2.4,50.7],[1,2.5,5.57],[2,2.54,5.38]],"ltp":2.28,"tv":17121.83,"id":10350473},{"batb":[[0,1.72,275.17],[1,1.7,229.72],[2,1.67,83.47]],"batl":[[1,1.8,192.18],[2,1.83,60]],"ltp":1.78,"tv":4098.14,"id":9304761}]}]}
{"op":"mcm","clk":"4230312435","pt":1631531578515,"mc":[{"id":"1.187557247","rc":[{"batb":[[0,2.18,101.25],[1,2.14,4],[2,2.12,4]],"batl":[[0,2.62,6.25],[1,2.64,5.93],[2,2.54,0]],"ltp":2.28,"tv":17121.83,"id":10350473},{"batb":[[0,1.65,6],[1,1.64,115.23],[2,1.62,79.54]],"batl":[[0,3.45,53.16],[1,1.8,0],[2,1.83,0]],"ltp":1.78,"tv":4098.14,"id":9304761}]}]}
{"op":"mcm","clk":"4230312497","pt":1631531579294,"mc":[{"id":"1.187557247","rc":[{"batb":[[2,1.6,98.81]],"ltp":2.28,"tv":17121.83,"id":10350473},{"batb":[[0,1.76,2.32],[1,1.65,6],[2,1.64,115.23]],"ltp":1.78,"tv":4098.14,"id":9304761}]}]}
{"op":"mcm","clk":"4230312623","pt":1631531580691,"mc":[{"id":"1.187557247","rc":[{"batb":[[1,2.16,102.51],[2,2.14,4]],"ltp":2.28,"tv":17121.83,"id":10350473},{"batb":[[1,1.65,287.9],[2,1.64,247.01]],"batl":[[0,1.85,130.52],[1,1.87,169.59],[2,3.45,53.16]],"ltp":1.78,"tv":4098.14,"id":9304761}]}]}
{"op":"mcm","clk":"4230312722","pt":1631531581599,"mc":[{"id":"1.187557247","rc":[{"batb":[[0,2.16,102.51],[1,2.14,4],[2,1.6,98.81]],"batl":[[0,2.54,3],[1,2.62,6.25],[2,2.64,5.93]],"ltp":2.28,"tv":17121.83,"id":10350473},{"batb":[[2,1.64,136.78]],"batl":[[0,1.84,5],[1,1.85,135.52],[2,1.87,169.59]],"ltp":1.78,"tv":4098.14,"id":9304761}]}]}
{"op":"mcm","clk":"4230312744","pt":1631531581805,"mc":[{"id":"1.187557247","rc":[{"batb":[[1,1.65,119.97],[2,1.64,5]],"ltp":1.78,"tv":4098.14,"id":9304761}]}]}
{"op":"mcm","clk":"4230313051","pt":1631531584723,"mc":[{"id":"1.187557247","rc":[{"trd":[[2.16,41.24]],"batb":[[0,2.16,92.2],[1,2.12,496.17],[2,2.1,481.57]],"batl":[[0,2.36,20.57],[1,2.5,4],[2,2.54,3]],"ltp":2.16,"tv":17142.45,"id":10350473},{"batb":[[0,1.79,1891.2],[1,1.78,2.32],[2,1.77,1080.52]],"batl":[[0,1.85,130.52],[1,1.87,169.59],[2,3.45,53.16]],"ltp":1.78,"tv":4098.14,"id":9304761}],"tv":21240.59}]}
{"op":"mcm","clk":"4230313146","pt":1631531585711,"mc":[{"id":"1.187557247","rc":[{"batb":[[2,2.1,594.12]],"batl":[[0,2.26,53.45],[1,2.36,20.57],[2,2.5,4]],"ltp":2.16,"tv":17142.45,"id":10350473},{"batb":[[0,1.8,85.02],[1,1.79,247.97],[2,1.78,2.32]],"batl":[[2,2.28,8.77]],"ltp":1.78,"tv":4098.14,"id":9304761}]}]}
{"op":"mcm","clk":"4230313315","pt":1631531587488,"mc":[{"id":"1.187557247","rc":[{"batl":[[0,2.26,56.45]],"ltp":2.16,"tv":17142.45,"id":10350473},{"trd":[[1.85,103.2]],"batb":[[0,1.8,89.02],[1,1.79,185.47]],"batl":[[0,1.85,120.76]],"ltp":1.85,"tv":4117.66,"id":9304761}],"tv":21260.12}]}
{"op":"mcm","clk":"4230313433","pt":1631531588732,"mc":[{"id":"1.187557247","rc":[{"batl":[[0,2.24,3],[1,2.26,56.45],[2,2.36,20.57]],"ltp":2.16,"tv":17142.45,"id":10350473},{"batb":[[0,1.81,4],[1,1.8,89.02],[2,1.79,185.47]],"ltp":1.85,"tv":4117.66,"id":9304761}]}]}
{"op":"mcm","clk":"4230313505","pt":1631531589616,"mc":[{"id":"1.187557247","rc":[{"batl":[[0,2.2,20.25],[1,2.24,3],[2,2.26,56.45]],"ltp":2.16,"tv":17142.45,"id":10350473}]}]}
{"op":"mcm","clk":"4230313593","pt":1631531590718,"mc":[{"id":"1.187557247","rc":[{"batl":[[1,2.24,29.3]],"ltp":2.16,"tv":17142.45,"id":10350473},{"batb":[[0,1.81,100.8]],"ltp":1.85,"tv":4117.66,"id":9304761}]}]}
{"op":"mcm","clk":"4230313755","pt":1631531592531,"mc":[{"id":"1.187557247","rc":[{"batl":[[1,2.22,3],[2,2.24,29.3]],"ltp":2.16,"tv":17142.45,"id":10350473},{"batb":[[0,1.82,4],[1,1.81,100.8],[2,1.8,89.02]],"ltp":1.85,"tv":4117.66,"id":9304761}]}]}
{"op":"mcm","clk":"4230314024","pt":1631531595547,"mc":[{"id":"1.187557247","rc":[{"batb":[[0,2.1,112.55],[1,2.04,4],[2,2.02,3]],"batl":[[1,2.42,6.75],[2,2.5,4]],"ltp":2.16,"tv":17142.45,"id":10350473},{"batb":[[0,1.81,66.66],[1,1.78,2.32],[2,1.76,2.32]],"batl":[[0,2.5,278.33],[1,3.45,53.16],[2,2.28,0]],"ltp":1.85,"tv":4117.66,"id":9304761}]}]}
{"op":"mcm","clk":"4230314114","pt":1631531596542,"mc":[{"id":"1.187557247","rc":[{"batl":[[1,2.52,3],[2,2.54,5.75]],"ltp":2.16,"tv":17142.45,"id":10350473},{"batb":[[0,1.78,2.32],[1,1.76,2.32],[2,1.73,96.15]],"ltp":1.85,"tv":4117.66,"id":9304761}]}]}
{"op":"mcm","clk":"4230314311","pt":1631531598728,"mc":[{"id":"1.187557247","rc":[{"batb":[[1,2.06,14.15],[2,2.04,4]],"ltp":2.16,"tv":17142.45,"id":10350473},{"batb":[[2,1.73,281.2]],"batl":[[0,1.9,5],[1,1.91,165.83],[2,1.93,214.36]],"ltp":1.85,"tv":4117.66,"id":9304761}]}]}
{"op":"mcm","clk":"4230314339","pt":1631531599041,"mc":[{"id":"1.187557247","rc":[{"batb":[[1,2.04,4],[2,1.6,98.81]],"batl":[[1,2.42,6.75],[2,2.52,3]],"ltp":2.16,"tv":17142.45,"id":10350473},{"batl":[[2,1.93,154.36]],"ltp":1.85,"tv":4117.66,"id":9304761}]}]}
{"op":"mcm","clk":"4230314663","pt":1631531602517,"mc":[{"id":"1.187557247","rc":[{"batl":[[1,2.52,3],[2,2.54,5.75]],"ltp":2.16,"tv":17142.45,"id":10350473},{"batb":[[2,1.73,96.15]],"ltp":1.85,"tv":4117.66,"id":9304761}]}]}
{"op":"mcm","clk":"4230314760","pt":1631531603658,"mc":[{"id":"1.187557247","rc":[{"batb":[[0,1.84,2590.3],[1,1.78,2.32],[2,1.76,2.32]],"ltp":1.85,"tv":4117.66,"id":9304761}]}]}
{"op":"mcm","clk":"4230314784","pt":1631531603861,"mc":[{"id":"1.187557247","rc":[{"batb":[[0,1.78,2.32],[1,1.76,2.32],[2,1.73,96.15]],"ltp":1.85,"tv":4117.66,"id":9304761}]}]}
{"op":"mcm","clk":"4230314946","pt":1631531605743,"mc":[{"id":"1.187557247","rc":[{"trd":[[2.1,23.06]],"batb":[[0,2.1,102.02],[1,1.95,69.71]],"batl":[[1,2.34,20.25],[2,2.52,3]],"ltp":2.1,"tv":17163.51,"id":10350473},{"batb":[[0,1.85,77.66],[1,1.84,173.1],[2,1.82,1232.21]],"batl":[[0,1.91,161.83],[1,1.93,154.36],[2,1.94,542.2]],"ltp":1.85,"tv":4117.66,"id":9304761}],"tv":21281.18}]}
{"op":"mcm","clk":"4230315039","pt":1631531606728,"mc":[{"id":"1.187557247","rc":[{"batb":[[2,1.5,106.73]],"batl":[[0,2.16,55.7],[1,2.18,36.36],[2,2.34,20.25]],"ltp":2.1,"tv":17163.51,"id":10350473},{"batb":[[0,1.87,64.32],[1,1.85,77.66],[2,1.84,173.1]],"ltp":1.85,"tv":4117.66,"id":9304761}]}]}
{"op":"mcm","clk":"4230315045","pt":1631531606830,"mc":[{"id":"1.187557247","rc":[{"batl":[[1,2.34,20.25],[2,2.52,3]],"ltp":2.1,"tv":17163.51,"id":10350473}]}]}
{"op":"mcm","clk":"4230315175","pt":1631531608233,"mc":[{"id":"1.187557247","rc":[{"batb":[[1,1.97,3],[2,1.96,4]],"batl":[[1,2.18,4],[2,2.34,20.25]],"ltp":2.1,"tv":17163.51,"id":10350473},{"batb":[[1,1.85,81.66],[2,1.84,177.1]],"ltp":1.85,"tv":4117.66,"id":9304761}]}]}
{"op":"mcm","clk":"4230315297","pt":1631531609630,"mc":[{"id":"1.187557247","rc":[{"batl":[[0,2.14,4],[1,2.16,59.7],[2,2.18,4]],"ltp":2.1,"tv":17163.51,"id":10350473},{"batb":[[0,1.88,5],[1,1.87,68.32],[2,1.86,4]],"ltp":1.85,"tv":4117.66,"id":9304761}]}]}
{"op":"mcm","clk":"4230315357","pt":1631531610252,"mc":[{"id":"1.187557247","rc":[{"batl":[[1,2.16,96.06]],"ltp":2.1,"tv":17163.51,"id":10350473},{"batb":[[1,1.87,32.43]],"ltp":1.85,"tv":4117.66,"id":9304761}]}]}
{"op":"mcm","clk":"4230315500","pt":1631531612063,"mc":[{"id":"1.187557247","rc":[{"batl":[[1,2.16,40.36]],"ltp":2.1,"tv":17163.51,"id":10350473}]}]}
{"op":"mcm","clk":"4230315608","pt":1631531613463,"mc":[{"id":"1.187557247","rc":[{"batb":[[0,1.89,63.59],[1,1.88,5],[2,1.87,32.43]],"ltp":1.85,"tv":4117.66,"id":9304761}]}]}
{"op":"mcm","clk":"4230315737","pt":1631531615177,"mc":[{"id":"1.187557247","rc":[{"batl":[[0,2.14,60.19]],"ltp":2.1,"tv":17163.51,"id":10350473}]}]}
{"op":"mcm","clk":"4230316311","pt":1631531621663,"mc":[{"id":"1.187557247","rc":[{"batb":[[2,1.95,69.71]],"batl":[[1,2.16,36.36],[2,2.34,20.25]],"ltp":2.1,"tv":17163.51,"id":10350473},{"trd":[[1.89,4.78]],"batb":[[0,1.89,61.2],[2,1.87,28.43]],"ltp":1.89,"tv":4122.45,"id":9304761}],"tv":21285.96}]}
{"op":"mcm","clk":"4230316467","pt":1631531623576,"mc":[{"id":"1.187557247","rc":[{"trd":[[1.89,14.82]],"batb":[[0,1.89,56.18]],"ltp":1.89,"tv":4132.49,"id":9304761}],"tv":21296.0}]}
{"op":"mcm","clk":"4230316557","pt":1631531624665,"mc":[{"id":"1.187557247","rc":[{"batb":[[0,1.97,3],[1,1.95,69.71],[2,1.5,106.73]],"batl":[[1,2.6,5.11],[2,2.34,0]],"ltp":2.1,"tv":17163.51,"id":10350473},{"batb":[[0,1.89,58.57],[2,1.78,2.32]],"batl":[[0,2.5,278.33],[1,3.45,53.16],[2,1.94,0]],"ltp":1.89,"tv":4132.49,"id":9304761}]}]}
{"op":"mcm","clk":"4230316627","pt":1631531625487,"mc":[{"id":"1.187557247","rc":[{"batb":[[1,1.96,5],[2,1.95,69.71]],"batl":[[0,2.6,5.11],[1,2.6,0]],"ltp":2.1,"tv":17163.51,"id":10350473},{"batb":[[0,1.78,2.32],[1,1.76,93.37],[2,1.63,83.23]],"ltp":1.89,"tv":4132.49,"id":9304761}]}]}
{"op":"mcm","clk":"4230316800","pt":1631531627568,"mc":[{"id":"1.187557247","rc":[{"batl":[[0,2.1,81.3],[1,2.6,5.11]],"ltp":2.1,"tv":17163.51,"id":10350473},{"batl":[[0,2.02,59.4],[1,2.5,278.33],[2,3.45,53.16]],"ltp":1.89,"tv":4132.49,"id":9304761}]}]}
{"op":"mcm","clk":"4230316864","pt":1631531628288,"mc":[{"id":"1.187557247","rc":[{"trd":[[2.1,111.06]],"batl":[[0,2.1,37.3]],"ltp":2.1,"tv":17251.51,"id":10350473},{"batl":[[0,2.5,278.33],[1,3.45,53.16],[2,3.45,0]],"ltp":1.89,"tv":4132.49,"id":9304761}],"tv":21384.0}]}
{"op":"mcm","clk":"4230317012","pt":1631531630093,"mc":[{"id":"1.187557247","rc":[{"batb":[[0,1.87,115.3],[1,1.85,171.91],[2,1.78,2.32]],"batl":[[0,1.93,117.7],[1,1.95,148.6],[2,2.5,278.33]],"ltp":1.89,"tv":4132.49,"id":9304761}]}]}
{"op":"mcm","clk":"4230317115","pt":1631531631495,"mc":[{"id":"1.187557247","rc":[{"batb":[[0,1.98,15],[1,1.97,3],[2,1.96,5]],"batl":[[1,2.4,6.39],[2,2.6,5.11]],"ltp":2.1,"tv":17251.51,"id":10350473},{"batb":[[0,1.79,11.6],[1,1.78,2.32],[2,1.76,93.37]],"batl":[[2,2,28.7]],"ltp":1.89,"tv":4132.49,"id":9304761}]}]}
{"op":"mcm","clk":"4230317162","pt":1631531631968,"mc":[{"id":"1.187557247","rc":[{"batb":[[0,1.97,3],[1,1.96,5],[2,1.95,69.71]],"ltp":2.1,"tv":17251.51,"id":10350473},{"batb":[[0,1.78,2.32],[1,1.76,93.37],[2,1.72,81.84]],"batl":[[0,2.06,3],[1,2.5,278.33],[2,3.45,53.16]],"ltp":1.89,"tv":4132.49,"id":9304761}]}]}
{"op":"mcm","clk":"4230317479","pt":1631531636191,"mc":[{"id":"1.187557247","rc":[{"batb":[[1,1.95,69.71],[2,1.5,106.73]],"ltp":2.1,"tv":17251.51,"id":10350473},{"batb":[[2,1.75,179.44]],"batl":[[0,2.04,146.17],[1,2.06,128.97],[2,2.5,278.33]],"ltp":1.89,"tv":4132.49,"id":9304761}]}]}
{"op":"mcm","clk":"4230317610","pt":1631531637798,"mc":[{"id":"1.187557247","rc":[{"trd":[[2.1,120.11]],"batl":[[0,2.1,28.25]],"ltp":2.1,"tv":17260.56,"id":10350473},{"trd":[[1.9,36.21]],"ltp":1.9,"tv":4142.49,"id":9304761}],"tv":21403.05}]}
{"op":"mcm","clk":"4230317722","pt":1631531639397,"mc":[{"id":"1.187557247","rc":[{"batb":[[1,1.96,4],[2,1.95,69.71]],"ltp":2.1,"tv":17260.56,"id":10350473}]}]}
{"op":"mcm","clk":"4230317833","pt":1631531641106,"mc":[{"id":"1.187557247","rc":[{"batb":[[2,1.72,81.84]],"batl":[[0,2.06,3],[1,2.5,278.33],[2,3.45,53.16]],"ltp":1.9,"tv":4142.49,"id":9304761}]}]}
{"op":"mcm","clk":"4230318020","pt":1631531643496,"mc":[{"id":"1.187557247","rc":[{"batb":[[0,1.95,69.71],[1,1.5,106.73],[2,1.45,719.75]],"ltp":2.1,"tv":17260.56,"id":10350473},{"batl":[[0,2.5,278.33],[1,3.45,53.16],[2,3.45,0]],"ltp":1.9,"tv":4142.49,"id":9304761}]}]}
{"op":"mcm","clk":"4230318131","pt":1631531644688,"mc":[{"id":"1.187557247","rc":[{"trd":[[1.95,22.1]],"batb":[[0,1.96,163.26],[1,1.95,58.66],[2,1.94,147.86]],"batl":[[0,2.04,148.3],[1,2.06,125.85],[2,2.1,28.25]],"ltp":1.95,"tv":17282.66,"id":10350473},{"batb":[[0,1.95,24.1],[1,1.93,990.94],[2,1.92,961.8]],"ltp":1.9,"tv":4142.49,"id":9304761}],"tv":21425.15}]}
{"op":"mcm","clk":"4230318225","pt":1631531645723,"mc":[{"id":"1.187557247","rc":[{"batl":[[0,2.02,59.4],[1,2.04,148.3],[2,2.06,125.85]],"ltp":1.95,"tv":17282.66,"id":10350473},{"batb":[[0,1.99,60.3],[1,1.98,125.77],[2,1.95,24.1]],"batl":[[0,2.16,55.7],[1,2.46,8.13],[2,2.5,278.33]],"ltp":1.9,"tv":4142.49,"id":9304761}]}]}
{"op":"mcm","clk":"4230318304","pt":1631531646711,"mc":[{"id":"1.187557247","rc":[{"batl":[[1,2.32,97.21],[2,2.46,8.13]],"ltp":1.9,"tv":4142.49,"id":9304761}]}]}
{"op":"mcm","clk":"4230318344","pt":1631531647222,"mc":[{"id":"1.187557247","rc":[{"batl":[[0,2.02,64.4],[1,2.04,152.3]],"ltp":1.95,"tv":17282.66,"id":10350473},{"batb":[[2,1.97,4]],"batl":[[1,2.46,8.13],[2,2.5,278.33]],"ltp":1.9,"tv":4142.49,"id":9304761}]}]}
{"op":"mcm","clk":"4230318456","pt":1631531648620,"mc":[{"id":"1.187557247","rc":[{"batl":[[0,2,4],[1,2.02,64.4],[2,2.04,152.3]],"ltp":1.95,"tv":17282.66,"id":10350473},{"batb":[[0,2,4],[1,1.99,64.3],[2,1.98,129.77]],"ltp":1.9,"tv":4142.49,"id":9304761}]}]}
{"op":"mcm","clk":"4230318518","pt":1631531649299,"mc":[{"id":"1.187557247","rc":[{"batl":[[0,2,24],[1,2.02,5]],"ltp":1.95,"tv":17282.66,"id":10350473},{"batb":[[0,2,29.45],[1,1.99,4]],"ltp":1.9,"tv":4142.49,"id":9304761}]}]}
{"op":"mcm","clk":"4230318644","pt":1631531650703,"mc":[{"id":"1.187557247","rc":[{"batl":[[0,2.14,37.48],[1,2.16,155.78],[2,2.46,8.13]],"ltp":1.9,"tv":4142.49,"id":9304761}]}]}
{"op":"mcm","clk":"4230318685","pt":1631531651318,"mc":[{"id":"1.187557247","rc":[{"batl":[[1,2.16,55.7]],"ltp":1.9,"tv":4142.49,"id":9304761}]}]}
{"op":"mcm","clk":"4230318766","pt":1631531652402,"mc":[{"id":"1.187557247","rc":[{"batl":[[0,1.99,60],[1,2,24],[2,2.02,5]],"ltp":1.95,"tv":17282.66,"id":10350473},{"batb":[[0,2,89.45]],"ltp":1.9,"tv":4142.49,"id":9304761}]}]}
{"op":"mcm","clk":"4230319374","pt":1631531660538,"mc":[{"id":"1.187557247","rc":[{"batb":[[0,1.82,86.86],[1,1.5,106.73],[2,1.45,719.75]],"batl":[[1,2.34,5.75],[2,2.02,0]],"ltp":1.95,"tv":17282.66,"id":10350473},{"batb":[[0,2,60],[1,1.85,76.74],[2,1.78,2.32]],"batl":[[0,2.16,55.7],[1,2.5,278.33],[2,3.45,53.16]],"ltp":1.9,"tv":4142.49,"id":9304761}]}]}
{"op":"mcm","clk":"4230319443","pt":1631531661426,"mc":[{"id":"1.187557247","rc":[{"batb":[[1,1.45,719.75],[2,1.44,851.79]],"batl":[[0,1.96,27.56]],"ltp":1.95,"tv":17282.66,"id":10350473},{"batb":[[0,1.85,76.74],[1,1.78,2.32],[2,1.76,2.32]],"batl":[[0,2.5,278.33],[1,3.45,53.16],[2,3.45,0]],"ltp":1.9,"tv":4142.49,"id":9304761}]}]}
{"op":"mcm","clk":"4230319477","pt":1631531661941,"mc":[{"id":"1.187557247","rc":[{"trd":[[1.96,12]],"batl":[[0,1.96,21.56]],"ltp":1.96,"tv":17294.66,"id":10350473}],"tv":21437.15}]}
{"op":"mcm","clk":"4230319626","pt":1631531663735,"mc":[{"id":"1.187557247","rc":[{"batb":[[0,1.86,16.17],[1,1.83,196.14],[2,1.82,86.86]],"batl":[[1,2.18,163.69],[2,2.2,104.59]],"ltp":1.96,"tv":17294.66,"id":10350473},{"batb":[[0,1.86,76.57]],"ltp":1.9,"tv":4142.49,"id":9304761}]}]}
{"op":"mcm","clk":"4230319700","pt":1631531664614,"mc":[{"id":"1.187557247","rc":[{"batb":[[0,1.83,196.14],[1,1.82,90.86],[2,1.81,188.81]],"batl":[[1,2.16,4.24],[2,2.18,163.69]],"ltp":1.96,"tv":17294.66,"id":10350473},{"batb":[[1,1.82,78.14],[2,1.78,2.32]],"ltp":1.9,"tv":4142.49,"id":9304761}]}]}
{"op":"mcm","clk":"4230319734","pt":1631531665031,"mc":[{"id":"1.187557247","rc":[{"trd":[[1.96,16.65]],"batl":[[0,1.96,19.24]],"ltp":1.96,"tv":17299.31,"id":10350473}],"tv":21441.8}]}
{"op":"mcm","clk":"4230320448","pt":1631531673738,"mc":[{"id":"1.187557247","rc":[{"trd":[[1.83,65.08]],"batb":[[0,1.83,163.6]],"batl":[[0,1.9,1690.14]],"ltp":1.83,"tv":17364.38,"id":10350473}],"tv":21506.87}]}
{"op":"mcm","clk":"4230320570","pt":1631531675241,"mc":[{"id":"1.187557247","rc":[{"batl":[[2,2.18,0]],"ltp":1.83,"tv":17364.38,"id":10350473},{"batb":[[1,1.78,2.32],[2,1.76,2.32]],"ltp":1.9,"tv":4142.49,"id":9304761}]}]}
{"op":"mcm","clk":"4230320680","pt":1631531676637,"mc":[{"id":"1.187557247","rc":[{"batb":[[0,1.83,178.16]],"batl":[[2,2.18,15.26]],"ltp":1.83,"tv":17364.38,"id":10350473},{"batl":[[0,3.45,53.16],[1,3.45,0]],"ltp":1.9,"tv":4142.49,"id":9304761}]}]}
{"op":"mcm","clk":"4230320749","pt":1631531677622,"mc":[{"id":"1.187557247","rc":[{"trd":[[1.83,88.34]],"batb":[[0,1.83,166.53],[1,1.82,86.86],[2,1.81,183.81]],"batl":[[2,2.18,0]],"ltp":1.83,"tv":17387.64,"id":10350473},{"batb":[[0,2.1,1821.42],[1,2.08,1767.86],[2,2.06,1767.86]],"batl":[[0,2.26,1692.48],[1,2.28,1642.7],[2,2.3,1642.7]],"ltp":1.9,"tv":4142.49,"id":9304761}],"tv":21530.13}]}
{"op":"mcm","clk":"4230320861","pt":1631531678742,"mc":[{"id":"1.187557247","rc":[{"batl":[[0,1.9,161.08],[1,1.92,154.81],[2,1.95,76.3]],"ltp":1.83,"tv":17387.64,"id":10350473},{"batb":[[0,2.14,100],[1,2.1,910.7],[2,2.08,883.94]],"batl":[[0,2.26,465.43],[1,2.28,451.74],[2,2.3,451.74]],"ltp":1.9,"tv":4142.49,"id":9304761}]}]}
{"op":"mcm","clk":"4230320954","pt":1631531679724,"mc":[{"id":"1.187557247","rc":[{"batl":[[0,1.89,64],[1,1.9,161.08],[2,1.92,154.81]],"ltp":1.83,"tv":17387.64,"id":10350473},{"batb":[[1,2.12,56.57],[2,2.1,914.7]],"ltp":1.9,"tv":4142.49,"id":9304761}]}]}
{"op":"mcm","clk":"4230321190","pt":1631531682634,"mc":[{"id":"1.187557247","rc":[{"trd":[[1.83,258.7]],"batb":[[0,1.83,81.35]],"batl":[[0,1.86,10.68],[1,1.87,4],[2,1.89,64]],"ltp":1.83,"tv":17558.0,"id":10350473},{"batb":[[0,2.16,4],[1,2.14,218.91],[2,2.12,56.57]],"batl":[[0,2.24,62.69],[1,2.26,465.43],[2,2.28,451.74]],"ltp":1.9,"tv":4142.49,"id":9304761}],"tv":21700.49}]}
{"op":"mcm","clk":"4230321236","pt":1631531683253,"mc":[{"id":"1.187557247","rc":[{"batl":[[0,1.87,4],[1,1.89,64],[2,1.95,76.3]],"ltp":1.83,"tv":17558.0,"id":10350473},{"batb":[[2,2.12,3]],"batl":[[0,2.26,465.43],[1,2.28,451.74],[2,2.3,451.74]],"ltp":1.9,"tv":4142.49,"id":9304761}]}]}
{"op":"mcm","clk":"4230321339","pt":1631531684755,"mc":[{"id":"1.187557247","rc":[{"batl":[[1,1.89,4]],"ltp":1.83,"tv":17558.0,"id":10350473}]}]}
{"op":"mcm","clk":"4230321433","pt":1631531685741,"mc":[{"id":"1.187557247","rc":[{"batb":[[0,1.83,124.66]],"batl":[[1,1.89,137.77],[2,1.91,157.49]],"ltp":1.83,"tv":17558.0,"id":10350473}]}]}
{"op":"mcm","clk":"4230321493","pt":1631531686463,"mc":[{"id":"1.187557247","rc":[{"batl":[[1,1.88,50],[2,1.89,137.77]],"ltp":1.83,"tv":17558.0,"id":10350473},{"batb":[[1,2.14,156.63]],"ltp":1.9,"tv":4142.49,"id":9304761}]}]}
{"op":"mcm","clk":"4230321592","pt":1631531687552,"mc":[{"id":"1.187557247","rc":[{"batl":[[0,1.87,64]],"ltp":1.83,"tv":17558.0,"id":10350473}]}]}
{"op":"mcm","clk":"4230321695","pt":1631531688757,"mc":[{"id":"1.187557247","rc":[{"batb":[[0,1.71,106.36],[1,1.45,719.75],[2,1.44,851.79]],"batl":[[0,1.87,60],[2,2.02,9.25]],"ltp":1.83,"tv":17558.0,"id":10350473},{"batb":[[0,2.14,52.63],[1,2,119.66],[2,1.99,68.51]],"batl":[[0,2.32,52.22],[1,2.82,234.47],[2,3.45,53.16]],"ltp":1.9,"tv":4142.49,"id":9304761}]}]}
{"op":"mcm","clk":"4230321754","pt":1631531689577,"mc":[{"id":"1.187557247","rc":[{"batl":[[0,1.88,91.01],[1,2.02,9.25],[2,2.1,7.35]],"ltp":1.83,"tv":17558.0,"id":10350473},{"batb":[[0,2,119.66],[1,1.99,68.51],[2,1.91,69.39]],"batl":[[0,2.82,234.47],[1,3.45,53.16],[2,3.45,0]],"ltp":1.9,"tv":4142.49,"id":9304761}]}]}
{"op":"mcm","clk":"4230321843","pt":1631531690665,"mc":[{"id":"1.187557247","rc":[{"batl":[[0,1.86,4],[1,1.88,50],[2,2.02,9.25]],"ltp":1.83,"tv":17558.0,"id":10350473}]}]}
{"op":"mcm","clk":"4230321916","pt":1631531691550,"mc":[{"id":"1.187557247","rc":[{"batb":[[0,1.73,124.18],[1,1.71,328.09],[2,1.45,719.75]],"batl":[[0,1.83,3.9],[2,2,148.3]],"ltp":1.83,"tv":17558.0,"id":10350473}]}]}
{"op":"mcm","clk":"4230322011","pt":1631531692635,"mc":[{"id":"1.187557247","rc":[{"batb":[[1,1.71,334.09],[2,1.7,4]],"ltp":1.83,"tv":17558.0,"id":10350473},{"batl":[[0,2.42,4],[1,2.82,234.47],[2,3.45,53.16]],"ltp":1.9,"tv":4142.49,"id":9304761}]}]}
{"op":"mcm","clk":"4230322073","pt":1631531693570,"mc":[{"id":"1.187557247","rc":[{"batl":[[0,1.83,48.81]],"ltp":1.83,"tv":17558.0,"id":10350473}]}]}
{"op":"mcm","clk":"4230322264","pt":1631531695964,"mc":[{"id":"1.187557247","rc":[{"batl":[[0,1.88,50],[1,2,148.3],[2,2.02,142.57]],"ltp":1.83,"tv":17558.0,"id":10350473}]}]}
