{"op":"mcm","clk":"4229779437","pt":1631469492057,"mc":[{"id":"1.187560677","marketDefinition":{"bspMarket":false,"turnInPlayEnabled":true,"persistenceEnabled":true,"marketBaseRate":5.0,"eventId":"30896281","eventTypeId":"2","numberOfWinners":1,"bettingType":"ODDS","marketType":"MATCH_ODDS","marketTime":"2021-09-13T15:00:00.000Z","suspendTime":"2021-09-13T15:00:00.000Z","bspReconciled":false,"complete":true,"inPlay":false,"crossMatching":false,"runnersVoidable":false,"numberOfActiveRunners":2,"betDelay":0,"status":"OPEN","runners":[{"status":"ACTIVE","sortPriority":1,"id":11439844,"name":"Aleksandar Kovacevic"},{"status":"ACTIVE","sortPriority":2,"id":7588306,"name":"Strong Kirchheimer"}],"regulators":["MR_INT"],"countryCode":"US","discountAllowed":false,"timezone":"UTC","openDate":"2021-09-13T15:00:00.000Z","version":4029419820,"name":"Match Odds","eventName":"Al Kovacevic v Str Kirchheimer"},"rc":[{"batb":[[0,1.01,25]],"ltp":0.0,"tv":0.0,"id":7588306},{"batb":[[0,1.01,25]],"ltp":0.0,"tv":0.0,"id":11439844}]}]}
{"op":"mcm","clk":"4229779665","pt":1631469493726,"mc":[{"id":"1.187560677","marketDefinition":{"bspMarket":false,"turnInPlayEnabled":true,"persistenceEnabled":true,"marketBaseRate":5.0,"eventId":"30896281","eventTypeId":"2","numberOfWinners":1,"bettingType":"ODDS","marketType":"MATCH_ODDS","marketTime":"2021-09-13T15:00:00.000Z","suspendTime":"2021-09-13T15:00:00.000Z","bspReconciled":false,"complete":true,"inPlay":false,"crossMatching":false,"runnersVoidable":false,"numberOfActiveRunners":2,"betDelay":0,"status":"OPEN","runners":[{"status":"ACTIVE","sortPriority":1,"id":11439844,"name":"Aleksandar Kovacevic"},{"status":"ACTIVE","sortPriority":2,"id":7588306,"name":"Strong Kirchheimer"}],"regulators":["MR_INT"],"countryCode":"US","discountAllowed":true,"timezone":"UTC","openDate":"2021-09-13T15:00:00.000Z","version":4029419820,"name":"Match Odds","eventName":"Al Kovacevic v Str Kirchheimer"}}]}
{"op":"mcm","clk":"4229794572","pt":1631469612323,"mc":[{"id":"1.187560677","rc":[{"batb":[[0,1.01,7]],"ltp":0.0,"tv":0.0,"id":7588306},{"batb":[[0,1.01,7]],"ltp":0.0,"tv":0.0,"id":11439844}]}]}
{"op":"mcm","clk":"4229895916","pt":1631470338308,"mc":[{"id":"1.187560677","rc":[{"batl":[[0,990,2.2]],"ltp":0.0,"tv":0.0,"id":7588306},{"batl":[[0,990,2.2]],"ltp":0.0,"tv":0.0,"id":11439844}]}]}
{"op":"mcm","clk":"4229927051","pt":1631470554398,"mc":[{"id":"1.187560677","rc":[{"batb":[[0,1.01,100.94]],"ltp":0.0,"tv":0.0,"id":7588306},{"batb":[[0,1.01,100.94]],"ltp":0.0,"tv":0.0,"id":11439844}]}]}
{"op":"mcm","clk":"4230217902","pt":1631472841679,"mc":[{"id":"1.187560677","rc":[{"batb":[[0,1.02,108.45],[1,1.01,573.8]],"ltp":0.0,"tv":0.0,"id":7588306},{"batb":[[0,1.03,14.46],[1,1.02,108.45],[2,1.01,573.8]],"ltp":0.0,"tv":0.0,"id":11439844}]}]}
{"op":"mcm","clk":"4230219804","pt":1631472859493,"mc":[{"id":"1.187560677","marketDefinition":{"bspMarket":false,"turnInPlayEnabled":true,"persistenceEnabled":true,"marketBaseRate":5.0,"eventId":"30896281","eventTypeId":"2","numberOfWinners":1,"bettingType":"ODDS","marketType":"MATCH_ODDS","marketTime":"2021-09-13T15:00:00.000Z","suspendTime":"2021-09-13T15:00:00.000Z","bspReconciled":false,"complete":true,"inPlay":false,"crossMatching":true,"runnersVoidable":false,"numberOfActiveRunners":2,"betDelay":0,"status":"OPEN","runners":[{"status":"ACTIVE","sortPriority":1,"id":11439844,"name":"Aleksandar Kovacevic"},{"status":"ACTIVE","sortPriority":2,"id":7588306,"name":"Strong Kirchheimer"}],"regulators":["MR_INT"],"countryCode":"US","discountAllowed":true,"timezone":"UTC","openDate":"2021-09-13T15:00:00.000Z","version":4029419820,"name":"Match Odds","eventName":"Al Kovacevic v Str Kirchheimer"}}]}
{"op":"mcm","clk":"4230594759","pt":1631477169273,"mc":[{"id":"1.187560677","rc":[{"batb":[[1,1.01,578.76]],"ltp":0.0,"tv":0.0,"id":7588306},{"batb":[[2,1.01,578.76]],"ltp":0.0,"tv":0.0,"id":11439844}]}]}
{"op":"mcm","clk":"4230964600","pt":1631484955077,"mc":[{"id":"1.187560677","rc":[{"batb":[[0,1.02,118.23],[1,1.01,578.68]],"ltp":0.0,"tv":0.0,"id":7588306},{"batb":[[0,1.03,14.46],[1,1.02,108.43],[2,1.01,578.68]],"ltp":0.0,"tv":0.0,"id":11439844}]}]}
{"op":"mcm","clk":"4231005697","pt":1631485919206,"mc":[{"id":"1.187560677","rc":[{"batb":[[0,1.3,768.51],[1,1.02,118.23],[2,1.01,578.68]],"ltp":0.0,"tv":0.0,"id":7588306},{"batb":[[0,1.15,768.51],[1,1.03,14.46],[2,1.02,108.43]],"ltp":0.0,"tv":0.0,"id":11439844}]}]}
{"op":"mcm","clk":"4231005888","pt":1631485924404,"mc":[{"id":"1.187560677","rc":[{"batb":[[0,1.31,29.03],[1,1.3,768.51],[2,1.02,118.23]],"ltp":0.0,"tv":0.0,"id":7588306},{"batb":[[0,1.16,38.43],[1,1.15,768.51],[2,1.03,14.46]],"ltp":0.0,"tv":0.0,"id":11439844}]}]}
{"op":"mcm","clk":"4231005913","pt":1631485925181,"mc":[{"id":"1.187560677","rc":[{"batb":[[2,1.02,108.43]],"ltp":0.0,"tv":0.0,"id":7588306}]}]}
{"op":"mcm","clk":"4231006152","pt":1631485931829,"mc":[{"id":"1.187560677","rc":[{"batb":[[0,1.31,36.67]],"ltp":0.0,"tv":0.0,"id":7588306}]}]}
{"op":"mcm","clk":"4231037604","pt":1631486682390,"mc":[{"id":"1.187560677","rc":[{"batb":[[0,1.31,42.35]],"ltp":0.0,"tv":0.0,"id":7588306},{"batb":[[0,1.16,44.63]],"ltp":0.0,"tv":0.0,"id":11439844}]}]}
{"op":"mcm","clk":"4231330411","pt":1631492265843,"mc":[{"id":"1.187560677","rc":[{"batb":[[0,1.31,42.35],[1,1.3,768.38],[2,1.02,108.42]],"ltp":0.0,"tv":0.0,"id":7588306},{"batb":[[0,1.16,44.63],[1,1.15,768.38],[2,1.03,14.46]],"ltp":0.0,"tv":0.0,"id":11439844}]}]}
{"op":"mcm","clk":"4231351367","pt":1631492610425,"mc":[{"id":"1.187560677","rc":[{"batb":[[0,1.32,15.37],[1,1.31,42.35],[2,1.3,768.38]],"batl":[[0,15.5,3.42],[1,990,2.2]],"ltp":0.0,"tv":0.0,"id":7588306},{"batb":[[0,1.17,15.37],[1,1.16,44.63],[2,1.15,768.38]],"batl":[[0,9.8,3.42],[1,990,2.2]],"ltp":0.0,"tv":0.0,"id":11439844}]}]}
{"op":"mcm","clk":"4231594845","pt":1631497665872,"mc":[{"id":"1.187560677","rc":[{"batb":[[0,1.32,15.36],[1,1.31,42.33],[2,1.3,767.98]],"batl":[[0,15.5,3.41]],"ltp":0.0,"tv":0.0,"id":7588306},{"batb":[[0,1.17,15.36],[1,1.16,44.61],[2,1.15,767.98]],"batl":[[0,9.8,3.41]],"ltp":0.0,"tv":0.0,"id":11439844}]}]}
{"op":"mcm","clk":"4231756698","pt":1631503065833,"mc":[{"id":"1.187560677","rc":[{"batb":[[0,1.32,15.36],[1,1.31,42.33],[2,1.3,767.79]],"ltp":0.0,"tv":0.0,"id":7588306},{"batb":[[0,1.17,15.36],[1,1.16,44.6],[2,1.15,767.79]],"ltp":0.0,"tv":0.0,"id":11439844}]}]}
{"op":"mcm","clk":"4231989738","pt":1631510109111,"mc":[{"id":"1.187560677","rc":[{"batb":[[0,1.32,15.36],[1,1.31,42.33],[2,1.3,767.85]],"ltp":0.0,"tv":0.0,"id":7588306},{"batb":[[0,1.17,15.36],[1,1.16,44.61],[2,1.15,767.85]],"batl":[[0,3.2,42.66],[1,9.8,3.41],[2,990,2.2]],"ltp":0.0,"tv":0.0,"id":11439844}]}]}
{"op":"mcm","clk":"4231989995","pt":1631510114205,"mc":[{"id":"1.187560677","rc":[{"batb":[[1,1.31,34.69]],"ltp":0.0,"tv":0.0,"id":7588306}]}]}
{"op":"mcm","clk":"4231990178","pt":1631510118307,"mc":[{"id":"1.187560677","rc":[{"batl":[[0,4.5,42.66],[1,15.5,3.41],[2,990,2.2]],"ltp":0.0,"tv":0.0,"id":7588306}]}]}
{"op":"mcm","clk":"4231990311","pt":1631510121000,"mc":[{"id":"1.187560677","rc":[{"batb":[[0,1.45,6.9],[1,1.32,15.36],[2,1.31,34.69]],"ltp":0.0,"tv":0.0,"id":7588306}]}]}
{"op":"mcm","clk":"4231990949","pt":1631510134441,"mc":[{"id":"1.187560677","rc":[{"batb":[[1,1.31,34.69],[2,1.3,767.85]],"batl":[[1,990,2.2],[2,990,0]],"ltp":0.0,"tv":0.0,"id":7588306},{"batl":[[1,990,2.2],[2,990,0]],"ltp":0.0,"tv":0.0,"id":11439844}]}]}
{"op":"mcm","clk":"4231994198","pt":1631510201221,"mc":[{"id":"1.187560677","rc":[{"batb":[[0,1.46,15.36],[1,1.45,6.9],[2,1.31,34.69]],"ltp":0.0,"tv":0.0,"id":7588306},{"batl":[[0,3.15,3.41],[1,3.2,42.66],[2,990,2.2]],"ltp":0.0,"tv":0.0,"id":11439844}]}]}
{"op":"mcm","clk":"4231994483","pt":1631510207146,"mc":[{"id":"1.187560677","rc":[{"batb":[[1,1.31,34.69],[2,1.3,767.85]],"ltp":0.0,"tv":0.0,"id":7588306}]}]}
{"op":"mcm","clk":"4231994827","pt":1631510214026,"mc":[{"id":"1.187560677","rc":[{"batb":[[0,1.46,22.22]],"ltp":0.0,"tv":0.0,"id":7588306}]}]}
{"op":"mcm","clk":"4232050883","pt":1631511754539,"mc":[{"id":"1.187560677","rc":[{"batb":[[0,1.29,6.21],[1,1.17,15.36],[2,1.16,38.39]],"ltp":0.0,"tv":0.0,"id":11439844}]}]}
{"op":"mcm","clk":"4232052526","pt":1631511802283,"mc":[{"id":"1.187560677","rc":[{"batb":[[1,1.16,38.39],[2,1.15,767.85]],"ltp":0.0,"tv":0.0,"id":11439844}]}]}
{"op":"mcm","clk":"4232080604","pt":1631512538655,"mc":[{"id":"1.187560677","rc":[{"batl":[[1,46,29.03],[2,990,2.2]],"ltp":0.0,"tv":0.0,"id":7588306},{"batl":[[2,46,29.03]],"ltp":0.0,"tv":0.0,"id":11439844}]}]}
{"op":"mcm","clk":"4232411449","pt":1631519265818,"mc":[{"id":"1.187560677","rc":[{"batb":[[0,1.46,22.22],[1,1.31,34.71],[2,1.3,767.98]],"batl":[[0,4.5,42.67],[1,46,29.07]],"ltp":0.0,"tv":0.0,"id":7588306},{"batb":[[0,1.29,6.22],[1,1.16,38.4],[2,1.15,767.98]],"batl":[[1,3.2,42.67],[2,46,29.07]],"ltp":0.0,"tv":0.0,"id":11439844}]}]}
{"op":"mcm","clk":"4232730215","pt":1631524665825,"mc":[{"id":"1.187560677","rc":[{"batb":[[0,1.46,22.22],[2,1.3,768.11]],"batl":[[0,4.5,42.67],[1,46,29.05]],"ltp":0.0,"tv":0.0,"id":7588306},{"batb":[[0,1.29,6.22],[1,1.16,38.41],[2,1.15,768.11]],"batl":[[1,3.2,42.67],[2,46,29.05]],"ltp":0.0,"tv":0.0,"id":11439844}]}]}
{"op":"mcm","clk":"4232771608","pt":1631525506992,"mc":[{"id":"1.187560677","rc":[{"batl":[[0,3.5,25],[1,4.5,42.67],[2,46,29.05]],"ltp":0.0,"tv":0.0,"id":7588306},{"batl":[[0,1.57,25],[1,3.15,3.41],[2,3.2,42.67]],"ltp":0.0,"tv":0.0,"id":11439844}]}]}
{"op":"mcm","clk":"4232774167","pt":1631525551974,"mc":[{"id":"1.187560677","rc":[{"batl":[[1,3.2,42.67],[2,46,29.05]],"ltp":0.0,"tv":0.0,"id":11439844}]}]}
{"op":"mcm","clk":"4232775173","pt":1631525558557,"mc":[{"id":"1.187560677","rc":[{"batb":[[0,1.46,15.36]],"ltp":0.0,"tv":0.0,"id":7588306}]}]}
{"op":"mcm","clk":"4232776165","pt":1631525565223,"mc":[{"id":"1.187560677","rc":[{"batb":[[1,1.45,6.9],[2,1.31,34.71]],"ltp":0.0,"tv":0.0,"id":7588306}]}]}
{"op":"mcm","clk":"4232786872","pt":1631525740318,"mc":[{"id":"1.187560677","rc":[{"batb":[[0,2.74,18],[1,1.46,15.36],[2,1.45,6.9]],"ltp":0.0,"tv":0.0,"id":7588306},{"batb":[[0,1.4,78.31],[1,1.29,6.22],[2,1.16,38.41]],"ltp":0.0,"tv":0.0,"id":11439844}]}]}
{"op":"mcm","clk":"4232791524","pt":1631525830827,"mc":[{"id":"1.187560677","rc":[{"batb":[[1,1.45,6.9],[2,1.31,34.71]],"ltp":0.0,"tv":0.0,"id":7588306}]}]}
{"op":"mcm","clk":"4232806622","pt":1631526088691,"mc":[{"id":"1.187560677","rc":[{"batl":[[0,1.57,25.53]],"ltp":0.0,"tv":0.0,"id":11439844}]}]}
{"op":"mcm","clk":"4232807121","pt":1631526091685,"mc":[{"id":"1.187560677","rc":[{"batl":[[0,1.57,25]],"ltp":0.0,"tv":0.0,"id":11439844}]}]}
{"op":"mcm","clk":"4232807153","pt":1631526091895,"mc":[{"id":"1.187560677","rc":[{"batl":[[0,1.57,25.53]],"ltp":0.0,"tv":0.0,"id":11439844}]}]}
{"op":"mcm","clk":"4232819624","pt":1631526255641,"mc":[{"id":"1.187560677","rc":[{"batb":[[2,1.31,29.02]],"ltp":0.0,"tv":0.0,"id":7588306},{"batb":[[1,1.16,38.41],[2,1.15,768.11]],"ltp":0.0,"tv":0.0,"id":11439844}]}]}
{"op":"mcm","clk":"4232869861","pt":1631527104436,"mc":[{"id":"1.187560677","rc":[{"batb":[[1,1.16,149.59]],"ltp":0.0,"tv":0.0,"id":11439844}]}]}
{"op":"mcm","clk":"4232876841","pt":1631527220878,"mc":[{"id":"1.187560677","rc":[{"batb":[[1,1.31,29.02],[2,1.3,768.11]],"ltp":0.0,"tv":0.0,"id":7588306}]}]}
{"op":"mcm","clk":"4232877238","pt":1631527228414,"mc":[{"id":"1.187560677","rc":[{"batb":[[0,2.74,21.66]],"ltp":0.0,"tv":0.0,"id":7588306}]}]}
{"op":"mcm","clk":"4233144266","pt":1631531145675,"mc":[{"id":"1.187560677","rc":[{"batb":[[1,1.31,28.96],[2,1.3,766.61]],"batl":[[1,4.5,42.59],[2,46,29.02]],"ltp":0.0,"tv":0.0,"id":7588306},{"trd":[[1.4,34.98]],"batb":[[0,1.4,60.82],[1,1.16,149.42],[2,1.15,766.61]],"batl":[[1,3.2,42.59],[2,46,29.02]],"ltp":1.4,"tv":34.98,"id":11439844}],"tv":34.98}]}
{"op":"mcm","clk":"4233144317","pt":1631531146204,"mc":[{"id":"1.187560677","rc":[{"batb":[[0,1.4,78.31]],"ltp":1.4,"tv":34.98,"id":11439844}]}]}
{"op":"mcm","clk":"4233184239","pt":1631531645626,"mc":[{"id":"1.187560677","rc":[{"trd":[[3.5,25]],"batl":[[0,4.3,9.32]],"ltp":3.5,"tv":25.0,"id":7588306},{"trd":[[1.4,254.1]],"batb":[[0,1.17,34.19]],"batl":[[0,1.4,1004.66],[1,1.57,25.53],[2,3.2,42.59]],"ltp":1.4,"tv":254.1,"id":11439844}],"tv":279.1}]}
{"op":"mcm","clk":"4233184259","pt":1631531645928,"mc":[{"id":"1.187560677","rc":[{"batb":[[1,2,19.61],[2,1.31,28.96]],"batl":[[0,4.5,42.59],[1,46,29.02],[2,990,2.2]],"ltp":3.5,"tv":25.0,"id":7588306},{"batb":[[0,1.16,149.42],[1,1.15,766.61],[2,1.12,90.4]],"ltp":1.4,"tv":254.1,"id":11439844}]}]}
{"op":"mcm","clk":"4233184534","pt":1631531649612,"mc":[{"id":"1.187560677","rc":[{"batb":[[0,1.32,97.89],[1,1.16,149.42],[2,1.15,766.61]],"ltp":1.4,"tv":254.1,"id":11439844}]}]}
{"op":"mcm","clk":"4233190071","pt":1631531718625,"mc":[{"id":"1.187560677","rc":[{"batl":[[0,1.57,25.53],[1,3.2,42.59],[2,46,29.02]],"ltp":1.4,"tv":254.1,"id":11439844}]}]}
{"op":"mcm","clk":"4233190080","pt":1631531718728,"mc":[{"id":"1.187560677","rc":[{"batl":[[0,1.39,1004.66],[1,1.57,25.53],[2,3.2,42.59]],"ltp":1.4,"tv":254.1,"id":11439844}]}]}
{"op":"mcm","clk":"4233196190","pt":1631531792668,"mc":[{"id":"1.187560677","rc":[{"trd":[[3.55,2]],"ltp":3.55,"tv":27.0,"id":7588306},{"trd":[[1.39,5.11]],"batl":[[0,1.39,999.56]],"ltp":1.39,"tv":259.2,"id":11439844}],"tv":286.2}]}
{"op":"mcm","clk":"4233198911","pt":1631531824924,"mc":[{"id":"1.187560677","rc":[{"trd":[[1.39,47.7]],"batl":[[0,1.39,978.26]],"ltp":1.39,"tv":301.79,"id":11439844}],"tv":328.79}]}
{"op":"mcm","clk":"4233199010","pt":1631531826431,"mc":[{"id":"1.187560677","rc":[{"trd":[[1.39,65.46]],"batl":[[0,1.39,969.38]],"ltp":1.39,"tv":319.56,"id":11439844}],"tv":346.56}]}
{"op":"mcm","clk":"4233202982","pt":1631531877394,"mc":[{"id":"1.187560677","rc":[{"trd":[[1.39,108.05]],"batl":[[0,1.39,948.09]],"ltp":1.39,"tv":362.15,"id":11439844}],"tv":389.15}]}
{"op":"mcm","clk":"4233207044","pt":1631531936647,"mc":[{"id":"1.187560677","rc":[{"trd":[[1.39,129.65]],"batl":[[0,1.39,937.29]],"ltp":1.39,"tv":383.74,"id":11439844}],"tv":410.74}]}
{"op":"mcm","clk":"4233219824","pt":1631532109015,"mc":[{"id":"1.187560677","rc":[{"trd":[[1.39,340.45]],"batl":[[0,1.39,831.89]],"ltp":1.39,"tv":594.54,"id":11439844}],"tv":621.54}]}
{"op":"mcm","clk":"4233224749","pt":1631532176669,"mc":[{"id":"1.187560677","rc":[{"batb":[[0,1.36,85.18],[1,1.32,97.89],[2,1.16,149.42]],"ltp":1.39,"tv":594.54,"id":11439844}]}]}
{"op":"mcm","clk":"4233227086","pt":1631532212503,"mc":[{"id":"1.187560677","rc":[{"trd":[[1.39,510.8]],"batl":[[0,1.39,746.71]],"ltp":1.39,"tv":764.9,"id":11439844}],"tv":791.9}]}
{"op":"mcm","clk":"4233227858","pt":1631532224216,"mc":[{"id":"1.187560677","rc":[{"batb":[[0,1.38,42.59],[1,1.36,85.18],[2,1.32,97.89]],"ltp":1.39,"tv":764.9,"id":11439844}]}]}
{"op":"mcm","clk":"4233229260","pt":1631532244675,"mc":[{"id":"1.187560677","rc":[{"trd":[[3.65,16.08]],"ltp":3.65,"tv":43.08,"id":7588306},{"trd":[[1.38,42.64],[1.39,766.34]],"batb":[[0,1.36,85.18],[1,1.32,97.89],[2,1.16,149.42]],"batl":[[0,1.39,618.94]],"ltp":1.38,"tv":1063.08,"id":11439844}],"tv":1106.16}]}
{"op":"mcm","clk":"4233229302","pt":1631532245616,"mc":[{"id":"1.187560677","rc":[{"batl":[[0,4.5,78.27]],"ltp":3.65,"tv":43.08,"id":7588306},{"batl":[[0,1.38,3.5],[1,1.39,618.94],[2,1.57,25.53]],"ltp":1.38,"tv":1063.08,"id":11439844}]}]}
{"op":"mcm","clk":"4233229311","pt":1631532245770,"mc":[{"id":"1.187560677","rc":[{"batb":[[0,2.96,35.43],[1,2.74,21.66],[2,2,19.61]],"ltp":3.65,"tv":43.08,"id":7588306}]}]}
{"op":"mcm","clk":"4233229780","pt":1631532252846,"mc":[{"id":"1.187560677","rc":[{"trd":[[1.36,7]],"batb":[[0,1.36,81.68]],"batl":[[0,1.39,618.94],[1,1.57,25.53],[2,3.2,42.59]],"ltp":1.36,"tv":1070.08,"id":11439844}],"tv":1113.16}]}
{"op":"mcm","clk":"4233230072","pt":1631532257293,"mc":[{"id":"1.187560677","rc":[{"batl":[[0,4.5,42.59]],"ltp":3.65,"tv":43.08,"id":7588306},{"batb":[[0,1.38,42.59],[1,1.36,81.68],[2,1.32,97.89]],"ltp":1.36,"tv":1070.08,"id":11439844}]}]}
{"op":"mcm","clk":"4233232846","pt":1631532304231,"mc":[{"id":"1.187560677","rc":[{"batb":[[0,1.38,85.18]],"ltp":1.36,"tv":1070.08,"id":11439844}]}]}
{"op":"mcm","clk":"4233233717","pt":1631532318542,"mc":[{"id":"1.187560677","rc":[{"trd":[[1.39,919.66]],"batl":[[0,1.39,542.28]],"ltp":1.39,"tv":1223.4,"id":11439844}],"tv":1266.48}]}
{"op":"mcm","clk":"4233234840","pt":1631532335905,"mc":[{"id":"1.187560677","rc":[{"batb":[[0,1.32,97.89],[1,1.16,149.42],[2,1.15,766.61]],"ltp":1.39,"tv":1223.4,"id":11439844}]}]}
{"op":"mcm","clk":"4233235534","pt":1631532347498,"mc":[{"id":"1.187560677","rc":[{"batb":[[0,1.37,85.18],[1,1.32,97.89],[2,1.16,149.42]],"ltp":1.39,"tv":1223.4,"id":11439844}]}]}
{"op":"mcm","clk":"4233237674","pt":1631532378482,"mc":[{"id":"1.187560677","rc":[{"batb":[[0,1.38,5.02],[1,1.37,85.18],[2,1.32,97.89]],"ltp":1.39,"tv":1223.4,"id":11439844}]}]}
{"op":"mcm","clk":"4233243522","pt":1631532466568,"mc":[{"id":"1.187560677","rc":[{"trd":[[1.39,930.46]],"batl":[[0,1.39,536.88]],"ltp":1.39,"tv":1234.2,"id":11439844}],"tv":1277.28}]}
{"op":"mcm","clk":"4233248633","pt":1631532534482,"mc":[{"id":"1.187560677","rc":[{"trd":[[1.39,1145.96]],"batl":[[0,1.39,429.13]],"ltp":1.39,"tv":1449.7,"id":11439844}],"tv":1492.78}]}
{"op":"mcm","clk":"4233249477","pt":1631532545679,"mc":[{"id":"1.187560677","rc":[{"batl":[[0,4.5,95.78]],"ltp":3.65,"tv":43.08,"id":7588306}]}]}
{"op":"mcm","clk":"4233249818","pt":1631532550395,"mc":[{"id":"1.187560677","rc":[{"batb":[[0,3.2,14.23],[1,2.96,35.43],[2,2.74,3.66]],"ltp":3.65,"tv":43.08,"id":7588306},{"batb":[[2,1.3,104.41]],"ltp":1.39,"tv":1449.7,"id":11439844}]}]}
{"op":"mcm","clk":"4233249850","pt":1631532550809,"mc":[{"id":"1.187560677","rc":[{"batl":[[0,4.5,42.59]],"ltp":3.65,"tv":43.08,"id":7588306}]}]}
{"op":"mcm","clk":"4233250012","pt":1631532553122,"mc":[{"id":"1.187560677","rc":[{"trd":[[1.39,1153.62]],"batl":[[0,1.39,425.3]],"ltp":1.39,"tv":1457.36,"id":11439844}],"tv":1500.44}]}
{"op":"mcm","clk":"4233250640","pt":1631532560643,"mc":[{"id":"1.187560677","rc":[{"batb":[[1,2.74,3.66],[2,2,19.61]],"ltp":3.65,"tv":43.08,"id":7588306},{"batb":[[0,1.38,90.2],[1,1.3,104.41],[2,1.16,149.42]],"ltp":1.39,"tv":1457.36,"id":11439844}]}]}
{"op":"mcm","clk":"4233250645","pt":1631532560738,"mc":[{"id":"1.187560677","rc":[{"batb":[[0,3.3,65.09],[1,3.2,14.23],[2,2.74,3.66]],"ltp":3.65,"tv":43.08,"id":7588306}]}]}
{"op":"mcm","clk":"4233251322","pt":1631532569543,"mc":[{"id":"1.187560677","rc":[{"batb":[[0,1.38,5.02]],"ltp":1.39,"tv":1457.36,"id":11439844}]}]}
{"op":"mcm","clk":"4233252312","pt":1631532584818,"mc":[{"id":"1.187560677","rc":[{"trd":[[1.39,1238.8]],"batl":[[0,1.39,382.71]],"ltp":1.39,"tv":1542.54,"id":11439844}],"tv":1585.62}]}
{"op":"mcm","clk":"4233253358","pt":1631532600644,"mc":[{"id":"1.187560677","rc":[{"trd":[[1.39,1248.84]],"batl":[[0,1.39,377.69]],"ltp":1.39,"tv":1552.57,"id":11439844}],"tv":1595.66}]}
{"op":"mcm","clk":"4233254577","pt":1631532615457,"mc":[{"id":"1.187560677","rc":[{"batb":[[1,1.36,42.59],[2,1.3,104.41]],"ltp":1.39,"tv":1552.57,"id":11439844}]}]}
{"op":"mcm","clk":"4233257513","pt":1631532652482,"mc":[{"id":"1.187560677","rc":[{"batb":[[1,2.74,21.66],[2,2,19.61]],"ltp":3.65,"tv":43.08,"id":7588306},{"batb":[[2,1.16,149.42]],"ltp":1.39,"tv":1552.57,"id":11439844}]}]}
{"op":"mcm","clk":"4233259961","pt":1631532682989,"mc":[{"id":"1.187560677","rc":[{"batb":[[1,2.88,16.66],[2,2.74,3.66]],"ltp":3.65,"tv":43.08,"id":7588306}]}]}
{"op":"mcm","clk":"4233260750","pt":1631532692148,"mc":[{"id":"1.187560677","rc":[{"trd":[[1.39,1253.26]],"batl":[[0,1.39,375.48]],"ltp":1.39,"tv":1556.99,"id":11439844}],"tv":1600.07}]}
{"op":"mcm","clk":"4233270301","pt":1631532805184,"mc":[{"id":"1.187560677","rc":[{"trd":[[3.55,2.85]],"ltp":3.55,"tv":43.93,"id":7588306},{"trd":[[1.39,1255.43]],"batl":[[0,1.39,373.31]],"ltp":1.39,"tv":1559.17,"id":11439844}],"tv":1603.1}]}
{"op":"mcm","clk":"4233283424","pt":1631532952534,"mc":[{"id":"1.187560677","rc":[{"trd":[[1.38,52.67]],"batb":[[0,1.36,42.59],[1,1.16,149.42],[2,1.15,766.61]],"batl":[[0,1.38,5.77],[1,1.39,373.31],[2,1.57,25.53]],"ltp":1.38,"tv":1569.2,"id":11439844}],"tv":1613.14}]}
{"op":"mcm","clk":"4233284017","pt":1631532958944,"mc":[{"id":"1.187560677","rc":[{"trd":[[1.38,88.88]],"batl":[[0,1.39,373.31],[1,1.57,25.53],[2,3.2,42.59]],"ltp":1.38,"tv":1605.41,"id":11439844}],"tv":1649.35}]}
{"op":"mcm","clk":"4233289762","pt":1631533017634,"mc":[{"id":"1.187560677","rc":[{"batb":[[0,1.17,23.63]],"ltp":1.38,"tv":1605.41,"id":11439844}]}]}
{"op":"mcm","clk":"4233289830","pt":1631533018319,"mc":[{"id":"1.187560677","rc":[{"batb":[[0,3.05,34.37]],"ltp":3.55,"tv":43.93,"id":7588306},{"batb":[[0,1.29,11.53]],"ltp":1.38,"tv":1605.41,"id":11439844}]}]}
{"op":"mcm","clk":"4233292716","pt":1631533050135,"mc":[{"id":"1.187560677","rc":[{"batb":[[0,1.35,37.57],[1,1.29,11.53],[2,1.16,149.42]],"ltp":1.38,"tv":1605.41,"id":11439844}]}]}
{"op":"mcm","clk":"4233295002","pt":1631533078680,"mc":[{"id":"1.187560677","rc":[{"trd":[[1.39,1292.34]],"batl":[[0,1.39,354.85]],"ltp":1.39,"tv":1642.32,"id":11439844}],"tv":1686.25}]}
{"op":"mcm","clk":"4233296244","pt":1631533094666,"mc":[{"id":"1.187560677","rc":[{"batb":[[0,1.36,3.01],[1,1.35,37.57],[2,1.29,11.53]],"ltp":1.39,"tv":1642.32,"id":11439844}]}]}
{"op":"mcm","clk":"4233296936","pt":1631533096678,"mc":[{"id":"1.187560677","rc":[{"batb":[[0,2.88,16.66],[1,2.74,3.66],[2,2,19.61]],"ltp":3.55,"tv":43.93,"id":7588306},{"batl":[[1,1.56,13.44],[2,1.57,25]],"ltp":1.39,"tv":1642.32,"id":11439844}]}]}
{"op":"mcm","clk":"4233296970","pt":1631533096991,"mc":[{"id":"1.187560677","rc":[{"batl":[[1,5.1,1.76],[2,46,29.02]],"ltp":3.55,"tv":43.93,"id":7588306}]}]}
{"op":"mcm","clk":"4233318138","pt":1631533404660,"mc":[{"id":"1.187560677","rc":[{"batb":[[0,2.92,35.91],[1,2.88,16.66],[2,2.74,3.66]],"ltp":3.55,"tv":43.93,"id":7588306}]}]}
{"op":"mcm","clk":"4233336613","pt":1631533634578,"mc":[{"id":"1.187560677","rc":[{"batl":[[0,1.39,1500.33]],"ltp":1.39,"tv":1642.32,"id":11439844}]}]}
{"op":"mcm","clk":"4233348233","pt":1631533782642,"mc":[{"id":"1.187560677","rc":[{"batb":[[0,3,34.95]],"ltp":3.55,"tv":43.93,"id":7588306},{"batb":[[0,1.36,40.58],[1,1.29,11.53],[2,1.16,149.42]],"ltp":1.39,"tv":1642.32,"id":11439844}]}]}
{"op":"mcm","clk":"4233352942","pt":1631533844423,"mc":[{"id":"1.187560677","rc":[{"batb":[[0,3,31.99]],"ltp":3.55,"tv":43.93,"id":7588306}]}]}
{"op":"mcm","clk":"4233364970","pt":1631534005664,"mc":[{"id":"1.187560677","rc":[{"trd":[[3.55,186.84]],"ltp":3.55,"tv":227.92,"id":7588306},{"trd":[[1.39,1762.25]],"batl":[[0,1.39,1030.42]],"ltp":1.39,"tv":2112.23,"id":11439844}],"tv":2340.15}]}
{"op":"mcm","clk":"4233367343","pt":1631534038699,"mc":[{"id":"1.187560677","rc":[{"batl":[[0,3.75,36.8],[1,4.5,42.59],[2,5.1,1.76]],"ltp":3.55,"tv":227.92,"id":7588306}]}]}
{"op":"mcm","clk":"4233367401","pt":1631534039488,"mc":[{"id":"1.187560677","rc":[{"batb":[[0,1.37,20.95],[1,1.36,40.58]],"ltp":1.39,"tv":2112.23,"id":11439844}]}]}
{"op":"mcm","clk":"4233374465","pt":1631534144472,"mc":[{"id":"1.187560677","rc":[{"batb":[[0,2.88,16.66],[1,2.74,3.66],[2,2,19.61]],"ltp":3.55,"tv":227.92,"id":7588306}]}]}
{"op":"mcm","clk":"4233374484","pt":1631534144888,"mc":[{"id":"1.187560677","rc":[{"batb":[[0,2.94,32.65],[1,2.88,16.66],[2,2.74,3.66]],"ltp":3.55,"tv":227.92,"id":7588306}]}]}
{"op":"mcm","clk":"4233379316","pt":1631534219558,"mc":[{"id":"1.187560677","rc":[{"trd":[[3.55,196.09]],"ltp":3.55,"tv":237.17,"id":7588306},{"trd":[[1.39,1785.87]],"batl":[[0,1.39,1006.8]],"ltp":1.39,"tv":2135.85,"id":11439844}],"tv":2373.02}]}
{"op":"mcm","clk":"4233384990","pt":1631534307675,"mc":[{"id":"1.187560677","rc":[{"trd":[[3.55,232.89]],"ltp":3.55,"tv":273.97,"id":7588306},{"trd":[[1.39,1879.85]],"batl":[[0,1.39,912.82]],"ltp":1.39,"tv":2229.83,"id":11439844}],"tv":2503.8}]}
{"op":"mcm","clk":"4233392224","pt":1631534407751,"mc":[{"id":"1.187560677","rc":[{"trd":[[1.39,1889.69]],"batl":[[0,1.39,907.9]],"ltp":1.39,"tv":2239.67,"id":11439844}],"tv":2513.64}]}
{"op":"mcm","clk":"4233417420","pt":1631534677575,"mc":[{"id":"1.187560677","rc":[{"trd":[[1.37,9]],"batb":[[0,1.37,16.45]],"ltp":1.37,"tv":2248.67,"id":11439844}],"tv":2522.64}]}
{"op":"mcm","clk":"4233443318","pt":1631534929135,"mc":[{"id":"1.187560677","rc":[{"trd":[[1.39,1943.21]],"batl":[[0,1.39,881.13]],"ltp":1.39,"tv":2302.19,"id":11439844}],"tv":2576.17}]}
{"op":"mcm","clk":"4233458590","pt":1631535098316,"mc":[{"id":"1.187560677","rc":[{"trd":[[1.39,2170.95]],"batl":[[0,1.39,767.23]],"ltp":1.39,"tv":2529.92,"id":11439844}],"tv":2803.9}]}
{"op":"mcm","clk":"4233461124","pt":1631535124460,"mc":[{"id":"1.187560677","rc":[{"trd":[[1.39,2284.81]],"batl":[[0,1.39,710.28]],"ltp":1.39,"tv":2643.78,"id":11439844}],"tv":2917.76}]}
{"op":"mcm","clk":"4233464985","pt":1631535164780,"mc":[{"id":"1.187560677","rc":[{"trd":[[1.37,26.49]],"batb":[[0,1.37,7.7]],"ltp":1.37,"tv":2661.28,"id":11439844}],"tv":2935.25}]}
{"op":"mcm","clk":"4233465097","pt":1631535165867,"mc":[{"id":"1.187560677","rc":[{"batl":[[0,1.38,10.3],[1,1.39,710.28],[2,1.56,13.44]],"ltp":1.37,"tv":2661.28,"id":11439844}]}]}
{"op":"mcm","clk":"4233468592","pt":1631535202075,"mc":[{"id":"1.187560677","rc":[{"trd":[[1.38,109.47],[1.39,2378.08]],"batl":[[0,1.39,663.63],[1,1.56,13.44],[2,1.57,25]],"ltp":1.39,"tv":2775.14,"id":11439844}],"tv":3049.11}]}
{"op":"mcm","clk":"4233468692","pt":1631535203276,"mc":[{"id":"1.187560677","rc":[{"batb":[[0,1.37,18.47]],"ltp":1.39,"tv":2775.14,"id":11439844}]}]}
{"op":"mcm","clk":"4233469184","pt":1631535208800,"mc":[{"id":"1.187560677","rc":[{"batb":[[0,1.37,41.75]],"ltp":1.39,"tv":2775.14,"id":11439844}]}]}
{"op":"mcm","clk":"4233471129","pt":1631535228312,"mc":[{"id":"1.187560677","rc":[{"trd":[[1.39,2658.78]],"batl":[[0,1.39,523.23]],"ltp":1.39,"tv":3055.84,"id":11439844}],"tv":3329.81}]}
{"op":"mcm","clk":"4233471816","pt":1631535235260,"mc":[{"id":"1.187560677","rc":[{"batb":[[0,1.37,18.47]],"ltp":1.39,"tv":3055.84,"id":11439844}]}]}
{"op":"mcm","clk":"4233479443","pt":1631535309398,"mc":[{"id":"1.187560677","rc":[{"trd":[[1.39,2771.07]],"batl":[[0,1.39,467.06]],"ltp":1.39,"tv":3168.13,"id":11439844}],"tv":3442.1}]}
{"op":"mcm","clk":"4233495905","pt":1631535464690,"mc":[{"id":"1.187560677","rc":[{"trd":[[3.55,306.49]],"ltp":3.55,"tv":347.57,"id":7588306},{"trd":[[1.39,2959.11]],"batl":[[0,1.39,279.02]],"ltp":1.39,"tv":3356.17,"id":11439844}],"tv":3703.74}]}
{"op":"mcm","clk":"4233508994","pt":1631535489727,"mc":[{"id":"1.187560677","rc":[{"batl":[[0,3.65,36.8],[1,3.75,36.8],[2,4.5,42.59]],"ltp":3.55,"tv":347.57,"id":7588306}]}]}
{"op":"mcm","clk":"4233514773","pt":1631535539356,"mc":[{"id":"1.187560677","rc":[{"batb":[[0,3.05,31.46]],"ltp":3.55,"tv":347.57,"id":7588306}]}]}
{"op":"mcm","clk":"4233523618","pt":1631535621256,"mc":[{"id":"1.187560677","rc":[{"batb":[[0,1.38,37.57],[1,1.37,18.47],[2,1.36,3.01]],"ltp":1.39,"tv":3356.17,"id":11439844}]}]}
{"op":"mcm","clk":"4233552712","pt":1631535934480,"mc":[{"id":"1.187560677","rc":[{"trd":[[1.39,3007.12]],"batl":[[0,1.39,255.02]],"ltp":1.39,"tv":3404.17,"id":11439844}],"tv":3751.75}]}
{"op":"mcm","clk":"4233602069","pt":1631536510985,"mc":[{"id":"1.187560677","rc":[{"trd":[[1.39,3082.26]],"batb":[[0,1.37,18.47],[1,1.36,3.01],[2,1.16,149.42]],"batl":[[0,1.39,217.44]],"ltp":1.39,"tv":3479.32,"id":11439844}],"tv":3826.89}]}
{"op":"mcm","clk":"4233608441","pt":1631536578343,"mc":[{"id":"1.187560677","rc":[{"trd":[[1.39,3145.11]],"batl":[[0,1.39,186.01]],"ltp":1.39,"tv":3542.17,"id":11439844}],"tv":3889.74}]}
{"op":"mcm","clk":"4233613890","pt":1631536636585,"mc":[{"id":"1.187560677","rc":[{"batb":[[0,2.88,16.66],[1,2.74,3.66],[2,2,19.61]],"ltp":3.55,"tv":347.57,"id":7588306},{"trd":[[1.39,3477.13]],"batl":[[0,1.39,19.94]],"ltp":1.39,"tv":3874.19,"id":11439844}],"tv":4221.76}]}
{"op":"mcm","clk":"4233614361","pt":1631536642676,"mc":[{"id":"1.187560677","rc":[{"batb":[[0,3.05,10.46],[1,2.88,16.66],[2,2.74,3.66]],"ltp":3.55,"tv":347.57,"id":7588306}]}]}
{"op":"mcm","clk":"4233614366","pt":1631536642778,"mc":[{"id":"1.187560677","rc":[{"batl":[[1,1.49,21.55],[2,1.56,13.44]],"ltp":1.39,"tv":3874.19,"id":11439844}]}]}
{"op":"mcm","clk":"4233619086","pt":1631536697681,"mc":[{"id":"1.187560677","rc":[{"batl":[[2,1.57,25.53]],"ltp":1.39,"tv":3874.19,"id":11439844}]}]}
{"op":"mcm","clk":"4233619126","pt":1631536698159,"mc":[{"id":"1.187560677","rc":[{"batl":[[2,1.57,38.21]],"ltp":1.39,"tv":3874.19,"id":11439844}]}]}
{"op":"mcm","clk":"4233624670","pt":1631536759646,"mc":[{"id":"1.187560677","rc":[{"batb":[[2,1.16,411.79]],"ltp":1.39,"tv":3874.19,"id":11439844}]}]}
{"op":"mcm","clk":"4233626654","pt":1631536780632,"mc":[{"id":"1.187560677","rc":[{"batl":[[1,1.4,3.44],[2,1.49,21.55]],"ltp":1.39,"tv":3874.19,"id":11439844}]}]}
{"op":"mcm","clk":"4233628797","pt":1631536807460,"mc":[{"id":"1.187560677","rc":[{"trd":[[1.39,3486.7]],"batl":[[0,1.39,15.15]],"ltp":1.39,"tv":3883.76,"id":11439844}],"tv":4231.33}]}
{"op":"mcm","clk":"4233629124","pt":1631536811297,"mc":[{"id":"1.187560677","rc":[{"batb":[[0,3,10.46]],"ltp":3.55,"tv":347.57,"id":7588306},{"batl":[[2,1.5,21.55]],"ltp":1.39,"tv":3883.76,"id":11439844}]}]}
{"op":"mcm","clk":"4233631545","pt":1631536841191,"mc":[{"id":"1.187560677","rc":[{"batb":[[0,1.38,30.78],[1,1.37,18.47],[2,1.36,3.01]],"ltp":1.39,"tv":3883.76,"id":11439844}]}]}
{"op":"mcm","clk":"4233632102","pt":1631536849218,"mc":[{"id":"1.187560677","rc":[{"batb":[[0,1.37,18.47],[1,1.36,3.01],[2,1.16,411.79]],"ltp":1.39,"tv":3883.76,"id":11439844}]}]}
{"op":"mcm","clk":"4233632874","pt":1631536859038,"mc":[{"id":"1.187560677","rc":[{"trd":[[1.39,3517.01],[1.4,260.98]],"batb":[[0,1.4,12.67],[1,1.37,18.47],[2,1.36,3.01]],"batl":[[0,1.5,21.55],[1,1.57,38.21],[2,1.8,43.73]],"ltp":1.4,"tv":3920.94,"id":11439844}],"tv":4268.51}]}
{"op":"mcm","clk":"4233632998","pt":1631536860603,"mc":[{"id":"1.187560677","rc":[{"batb":[[0,1.37,10.77],[1,1.36,3.01],[2,1.16,411.79]],"ltp":1.4,"tv":3920.94,"id":11439844}]}]}
{"op":"mcm","clk":"4233633096","pt":1631536861542,"mc":[{"id":"1.187560677","rc":[{"batl":[[0,3.6,8.86],[1,3.65,36.8],[2,3.75,36.8]],"ltp":3.55,"tv":347.57,"id":7588306}]}]}
{"op":"mcm","clk":"4233633178","pt":1631536862537,"mc":[{"id":"1.187560677","rc":[{"batb":[[0,1.4,78.31],[1,1.37,10.77],[2,1.36,3.01]],"ltp":1.4,"tv":3920.94,"id":11439844}]}]}
{"op":"mcm","clk":"4233633235","pt":1631536863219,"mc":[{"id":"1.187560677","rc":[{"batb":[[1,1.39,7.88]],"ltp":1.4,"tv":3920.94,"id":11439844}]}]}
{"op":"mcm","clk":"4233635206","pt":1631536878651,"mc":[{"id":"1.187560677","rc":[{"batb":[[0,2.88,16.66],[1,2.74,3.66],[2,2,19.61]],"ltp":3.55,"tv":347.57,"id":7588306},{"batl":[[0,1.57,38.21],[1,1.8,43.73],[2,1.89,2.66]],"ltp":1.4,"tv":3920.94,"id":11439844}]}]}
{"op":"mcm","clk":"4233635216","pt":1631536878755,"mc":[{"id":"1.187560677","rc":[{"batb":[[0,2.9,10.46],[1,2.88,16.66],[2,2.74,3.66]],"ltp":3.55,"tv":347.57,"id":7588306},{"batl":[[0,1.53,22.08],[1,1.57,37.69],[2,1.8,43.73]],"ltp":1.4,"tv":3920.94,"id":11439844}]}]}
{"op":"mcm","clk":"4233636550","pt":1631536895236,"mc":[{"id":"1.187560677","rc":[{"batb":[[0,1.41,22.62],[1,1.4,78.31],[2,1.39,7.88]],"ltp":1.4,"tv":3920.94,"id":11439844}]}]}
{"op":"mcm","clk":"4233636661","pt":1631536896594,"mc":[{"id":"1.187560677","rc":[{"batb":[[2,1.36,3.01]],"ltp":1.4,"tv":3920.94,"id":11439844}]}]}
{"op":"mcm","clk":"4233636672","pt":1631536896800,"mc":[{"id":"1.187560677","rc":[{"batb":[[0,1.41,30.38]],"ltp":1.4,"tv":3920.94,"id":11439844}]}]}
{"op":"mcm","clk":"4233641568","pt":1631536954569,"mc":[{"id":"1.187560677","rc":[{"batl":[[0,3.45,8.86]],"ltp":3.55,"tv":347.57,"id":7588306}]}]}
{"op":"mcm","clk":"4233667232","pt":1631537285600,"mc":[{"id":"1.187560677","rc":[{"batb":[[1,1.4,80.87]],"ltp":1.4,"tv":3920.94,"id":11439844}]}]}
{"op":"mcm","clk":"4233668391","pt":1631537302473,"mc":[{"id":"1.187560677","rc":[{"trd":[[3.45,8.42]],"batl":[[0,3.65,37.24],[1,3.75,36.8],[2,4.5,42.59]],"ltp":3.45,"tv":355.99,"id":7588306},{"trd":[[1.4,443.48],[1.41,60.77]],"batb":[[0,1.36,3.01],[1,1.16,411.79],[2,1.15,766.61]],"ltp":1.4,"tv":4164.21,"id":11439844}],"tv":4520.2}]}
{"op":"mcm","clk":"4233668559","pt":1631537304556,"mc":[{"id":"1.187560677","rc":[{"batb":[[1,1.32,97.89],[2,1.16,411.79]],"ltp":1.4,"tv":4164.21,"id":11439844}]}]}
{"op":"mcm","clk":"4233669704","pt":1631537321547,"mc":[{"id":"1.187560677","rc":[{"batl":[[0,3.65,36.8]],"ltp":3.45,"tv":355.99,"id":7588306}]}]}
{"op":"mcm","clk":"4233669860","pt":1631537323988,"mc":[{"id":"1.187560677","rc":[{"trd":[[1.4,447.48]],"batl":[[0,1.4,3.11],[1,1.53,22.08],[2,1.57,37.69]],"ltp":1.4,"tv":4168.22,"id":11439844}],"tv":4524.21}]}
{"op":"mcm","clk":"4233674765","pt":1631537391446,"mc":[{"id":"1.187560677","rc":[{"trd":[[1.4,452.59]],"batl":[[0,1.52,1.08],[1,1.53,21.55]],"ltp":1.4,"tv":4173.33,"id":11439844}],"tv":4529.32}]}
{"op":"mcm","clk":"4233682086","pt":1631537493757,"mc":[{"id":"1.187560677","rc":[{"batb":[[2,1.18,108.94]],"ltp":1.4,"tv":4173.33,"id":11439844}]}]}
{"op":"mcm","clk":"4233686977","pt":1631537567555,"mc":[{"id":"1.187560677","rc":[{"batb":[[0,1.38,86.03],[1,1.36,3.01],[2,1.32,97.89]],"ltp":1.4,"tv":4173.33,"id":11439844}]}]}
{"op":"mcm","clk":"4233693382","pt":1631537674779,"mc":[{"id":"1.187560677","rc":[{"batb":[[0,1.36,3.01],[1,1.32,97.89],[2,1.18,108.94]],"ltp":1.4,"tv":4173.33,"id":11439844}]}]}
{"op":"mcm","clk":"4233701749","pt":1631537809537,"mc":[{"id":"1.187560677","rc":[{"batl":[[0,1.53,22.08],[1,1.57,37.69],[2,1.8,43.73]],"ltp":1.4,"tv":4173.33,"id":11439844}]}]}
{"op":"mcm","clk":"4233702468","pt":1631537821116,"mc":[{"id":"1.187560677","rc":[{"batb":[[0,1.4,137.14],[1,1.36,3.01],[2,1.32,97.89]],"ltp":1.4,"tv":4173.33,"id":11439844}]}]}
{"op":"mcm","clk":"4233702533","pt":1631537821899,"mc":[{"id":"1.187560677","rc":[{"batb":[[0,1.41,9.64],[1,1.4,137.14],[2,1.36,3.01]],"ltp":1.4,"tv":4173.33,"id":11439844}]}]}
{"op":"mcm","clk":"4233707950","pt":1631537911671,"mc":[{"id":"1.187560677","rc":[{"batl":[[2,1.89,2.66]],"ltp":1.4,"tv":4173.33,"id":11439844}]}]}
{"op":"mcm","clk":"4233713465","pt":1631538001227,"mc":[{"id":"1.187560677","rc":[{"batb":[[1,2.88,22.21]],"ltp":3.45,"tv":355.99,"id":7588306}]}]}
{"op":"mcm","clk":"4233713596","pt":1631538002709,"mc":[{"id":"1.187560677","rc":[{"batb":[[0,1.4,137.14],[1,1.36,3.01],[2,1.32,130.52]],"ltp":1.4,"tv":4173.33,"id":11439844}]}]}
{"op":"mcm","clk":"4233714697","pt":1631538018850,"mc":[{"id":"1.187560677","rc":[{"trd":[[3.45,8.43],[3.55,306.31],[3.65,16.08]],"batb":[[0,2.9,10.47]],"batl":[[0,3.65,36.77],[1,3.75,36.77],[2,4.5,42.58]],"ltp":3.45,"tv":355.81,"id":7588306},{"trd":[[1.36,7],[1.37,26.48],[1.38,109.46],[1.39,3517.42],[1.4,452.54],[1.41,60.79]],"batb":[[0,1.4,137.11]],"batl":[[0,1.53,22.11],[1,1.57,37.68],[2,1.89,2.66]],"ltp":1.4,"tv":4173.69,"id":11439844}],"tv":4529.51}]}
{"op":"mcm","clk":"4233724613","pt":1631538144265,"mc":[{"id":"1.187560677","rc":[{"batb":[[0,1.42,94.53],[1,1.4,137.11],[2,1.36,3.01]],"ltp":1.4,"tv":4173.69,"id":11439844}]}]}
{"op":"mcm","clk":"4233732730","pt":1631538237304,"mc":[{"id":"1.187560677","rc":[{"batb":[[0,2.92,18.02],[1,2.9,10.47],[2,2.88,22.21]],"ltp":3.45,"tv":355.81,"id":7588306},{"trd":[[1.42,189.06]],"batb":[[0,1.4,137.11],[1,1.36,3.01],[2,1.32,130.52]],"batl":[[0,1.42,1050.76],[1,1.53,22.11],[2,1.57,37.68]],"ltp":1.42,"tv":4362.76,"id":11439844}],"tv":4718.58}]}
{"op":"mcm","clk":"4233739837","pt":1631538313365,"mc":[{"id":"1.187560677","rc":[{"batl":[[0,1.41,21.58],[1,1.42,1050.76],[2,1.57,38.2]],"ltp":1.42,"tv":4362.76,"id":11439844}]}]}
{"op":"mcm","clk":"4233740659","pt":1631538322989,"mc":[{"id":"1.187560677","rc":[{"batb":[[0,3.4,8.55],[1,2.88,22.21],[2,2.74,3.66]],"ltp":3.45,"tv":355.81,"id":7588306}]}]}
{"op":"mcm","clk":"4233833637","pt":1631539210484,"mc":[{"id":"1.187560677","rc":[{"batl":[[0,3.65,44.06]],"ltp":3.45,"tv":355.81,"id":7588306}]}]}
{"op":"mcm","clk":"4233833676","pt":1631539210756,"mc":[{"id":"1.187560677","rc":[{"batl":[[0,3.65,36.77]],"ltp":3.45,"tv":355.81,"id":7588306}]}]}
{"op":"mcm","clk":"4233834654","pt":1631539219771,"mc":[{"id":"1.187560677","rc":[{"batl":[[2,5.1,1.76]],"ltp":3.45,"tv":355.81,"id":7588306}]}]}
{"op":"mcm","clk":"4233859915","pt":1631539458616,"mc":[{"id":"1.187560677","rc":[{"batb":[[0,2.9,22.9]],"ltp":3.45,"tv":355.81,"id":7588306},{"batl":[[0,1.42,1050.76],[1,1.57,38.2],[2,1.89,2.66]],"ltp":1.42,"tv":4362.76,"id":11439844}]}]}
{"op":"mcm","clk":"4233863013","pt":1631539486485,"mc":[{"id":"1.187560677","rc":[{"batb":[[0,3.4,8.55],[1,2.9,22.9],[2,2.88,22.21]],"ltp":3.45,"tv":355.81,"id":7588306},{"batl":[[0,1.41,22.65],[1,1.42,1050.76],[2,1.57,38.2]],"ltp":1.42,"tv":4362.76,"id":11439844}]}]}
{"op":"mcm","clk":"4233863045","pt":1631539486792,"mc":[{"id":"1.187560677","rc":[{"batb":[[1,2.88,22.21],[2,2.74,3.66]],"ltp":3.45,"tv":355.81,"id":7588306}]}]}
{"op":"mcm","clk":"4233920501","pt":1631540052708,"mc":[{"id":"1.187560677","rc":[{"trd":[[1.4,726.77]],"batb":[[0,1.36,3.01],[1,1.32,130.52],[2,1.2,218.49]],"batl":[[0,1.4,913.65],[1,1.41,22.65]],"ltp":1.4,"tv":4636.99,"id":11439844}],"tv":4992.81}]}
{"op":"mcm","clk":"4233925120","pt":1631540099139,"mc":[{"id":"1.187560677","rc":[{"batl":[[0,1.39,22.65],[1,1.4,913.65]],"ltp":1.4,"tv":4636.99,"id":11439844}]}]}
{"op":"mcm","clk":"4233925588","pt":1631540103669,"mc":[{"id":"1.187560677","rc":[{"batb":[[0,3.55,8.55]],"ltp":3.45,"tv":355.81,"id":7588306}]}]}
{"op":"mcm","clk":"4233930282","pt":1631540149160,"mc":[{"id":"1.187560677","rc":[{"batb":[[0,1.37,150.74],[1,1.36,3.01],[2,1.32,130.52]],"ltp":1.4,"tv":4636.99,"id":11439844}]}]}
{"op":"mcm","clk":"4233944530","pt":1631540298714,"mc":[{"id":"1.187560677","rc":[{"batl":[[2,46,29]],"ltp":3.45,"tv":355.81,"id":7588306},{"batl":[[2,1.57,25.53]],"ltp":1.4,"tv":4636.99,"id":11439844}]}]}
{"op":"mcm","clk":"4233944608","pt":1631540299607,"mc":[{"id":"1.187560677","rc":[{"batl":[[2,5.1,1.76]],"ltp":3.45,"tv":355.81,"id":7588306},{"batl":[[2,1.57,38.2]],"ltp":1.4,"tv":4636.99,"id":11439844}]}]}
{"op":"mcm","clk":"4234019888","pt":1631541194343,"mc":[{"id":"1.187560677","rc":[{"batb":[[0,2.98,27.87]],"ltp":3.45,"tv":355.81,"id":7588306},{"batl":[[0,1.4,913.65],[1,1.57,38.2],[2,1.8,43.7]],"ltp":1.4,"tv":4636.99,"id":11439844}]}]}
{"op":"mcm","clk":"4234022046","pt":1631541226455,"mc":[{"id":"1.187560677","rc":[{"batb":[[0,3.55,8.19],[1,2.98,27.87],[2,2.88,22.21]],"ltp":3.45,"tv":355.81,"id":7588306},{"batl":[[0,1.39,22.97],[1,1.4,913.65],[2,1.57,38.2]],"ltp":1.4,"tv":4636.99,"id":11439844}]}]}
{"op":"mcm","clk":"4234022071","pt":1631541226768,"mc":[{"id":"1.187560677","rc":[{"batb":[[1,2.88,22.21],[2,2.74,3.66]],"ltp":3.45,"tv":355.81,"id":7588306}]}]}
{"op":"mcm","clk":"4234030805","pt":1631541356539,"mc":[{"id":"1.187560677","rc":[{"trd":[[1.37,29.89]],"batb":[[0,1.37,149.04]],"ltp":1.37,"tv":4640.39,"id":11439844}],"tv":4996.21}]}
{"op":"mcm","clk":"4234049127","pt":1631541601158,"mc":[{"id":"1.187560677","rc":[{"batb":[[1,3.45,5.21],[2,2.88,22.21]],"ltp":3.45,"tv":355.81,"id":7588306},{"batb":[[2,1.34,37.57]],"ltp":1.37,"tv":4640.39,"id":11439844}]}]}
{"op":"mcm","clk":"4234079867","pt":1631541946183,"mc":[{"id":"1.187560677","rc":[{"trd":[[1.37,35.21]],"batb":[[0,1.37,146.38]],"batl":[[0,1.39,25.97]],"ltp":1.37,"tv":4645.71,"id":11439844}],"tv":5001.53}]}
{"op":"mcm","clk":"4234079968","pt":1631541947183,"mc":[{"id":"1.187560677","rc":[{"trd":[[3.65,21.4]],"batl":[[0,3.65,34.11]],"ltp":3.65,"tv":361.14,"id":7588306}],"tv":5006.86}]}
{"op":"mcm","clk":"4234126823","pt":1631542421034,"mc":[{"id":"1.187560677","rc":[{"batl":[[2,1.43,2.03]],"ltp":1.37,"tv":4645.71,"id":11439844}]}]}
{"op":"mcm","clk":"4234212933","pt":1631543326545,"mc":[{"id":"1.187560677","rc":[{"trd":[[3.65,55.51],[3.75,36.77]],"batl":[[0,5.1,1.76],[1,46,29],[2,990,2.2]],"ltp":3.75,"tv":432.02,"id":7588306},{"trd":[[1.36,114.37],[1.37,418.96]],"batb":[[0,1.34,37.57],[1,1.32,130.52],[2,1.21,121.67]],"batl":[[0,1.35,4981.37],[1,1.39,25.97],[2,1.4,913.65]],"ltp":1.36,"tv":5136.84,"id":11439844}],"tv":5568.87}]}
{"op":"mcm","clk":"4234212982","pt":1631543327170,"mc":[{"id":"1.187560677","rc":[{"trd":[[3.95,12.73]],"batb":[[0,3.75,4.64],[1,3.55,8.19],[2,3.45,5.21]],"ltp":3.95,"tv":444.75,"id":7588306},{"trd":[[1.34,37.53]],"batb":[[0,1.32,130.52],[1,1.29,44.05]],"ltp":1.34,"tv":5174.37,"id":11439844}],"tv":5619.13}]}
{"op":"mcm","clk":"4234214775","pt":1631543347352,"mc":[{"id":"1.187560677","rc":[{"batl":[[0,1.34,32.61],[1,1.35,4981.37],[2,1.39,3]],"ltp":1.34,"tv":5174.37,"id":11439844}]}]}
{"op":"mcm","clk":"4234214913","pt":1631543348657,"mc":[{"id":"1.187560677","rc":[{"batb":[[0,3.9,7.46],[1,3.8,4.56],[2,3.75,4.64]],"ltp":3.95,"tv":444.75,"id":7588306}]}]}
{"op":"mcm","clk":"4234220834","pt":1631543415079,"mc":[{"id":"1.187560677","rc":[{"trd":[[1.34,44.71]],"batl":[[0,1.34,29.02]],"ltp":1.34,"tv":5181.56,"id":11439844}],"tv":5626.32}]}
{"op":"mcm","clk":"4234232653","pt":1631543505985,"mc":[{"id":"1.187560677","rc":[{"trd":[[1.32,11.93]],"batb":[[0,1.32,124.55]],"ltp":1.32,"tv":5193.49,"id":11439844}],"tv":5638.25}]}
{"op":"mcm","clk":"4234232874","pt":1631543507291,"mc":[{"id":"1.187560677","rc":[{"trd":[[3.9,54.52]],"batb":[[0,3.75,4.64],[1,3.45,5.21],[2,2.88,22.21]],"ltp":3.9,"tv":499.27,"id":7588306},{"trd":[[1.34,73.74]],"batl":[[0,1.35,4991.07],[1,1.39,3],[2,1.4,913.65]],"ltp":1.34,"tv":5222.51,"id":11439844}],"tv":5721.79}]}
{"op":"mcm","clk":"4234233138","pt":1631543509535,"mc":[{"id":"1.187560677","rc":[{"batb":[[0,1.32,130.52]],"ltp":1.34,"tv":5222.51,"id":11439844}]}]}
{"op":"mcm","clk":"4234233169","pt":1631543509744,"mc":[{"id":"1.187560677","rc":[{"batl":[[0,1.35,4981.37]],"ltp":1.34,"tv":5222.51,"id":11439844}]}]}
{"op":"mcm","clk":"4234235311","pt":1631543525550,"mc":[{"id":"1.187560677","rc":[{"batb":[[1,1.31,8.71],[2,1.29,44.05]],"ltp":1.34,"tv":5222.51,"id":11439844}]}]}
{"op":"mcm","clk":"4234235486","pt":1631543526649,"mc":[{"id":"1.187560677","rc":[{"batb":[[0,3.75,5.76]],"ltp":3.9,"tv":499.27,"id":7588306},{"trd":[[1.35,350.16]],"batl":[[0,1.35,4806.33]],"ltp":1.35,"tv":5572.67,"id":11439844}],"tv":6071.95}]}
{"op":"mcm","clk":"4234237774","pt":1631543545281,"mc":[{"id":"1.187560677","rc":[{"batb":[[0,3.9,7.46],[1,3.8,4.56],[2,3.75,5.76]],"ltp":3.9,"tv":499.27,"id":7588306}]}]}
{"op":"mcm","clk":"4234239944","pt":1631543563726,"mc":[{"id":"1.187560677","rc":[{"trd":[[1.32,21.93]],"batb":[[0,1.32,125.52]],"ltp":1.32,"tv":5582.67,"id":11439844}],"tv":6081.95}]}
{"op":"mcm","clk":"4234240110","pt":1631543565240,"mc":[{"id":"1.187560677","rc":[{"batb":[[0,1.32,130.52]],"ltp":1.32,"tv":5582.67,"id":11439844}]}]}
{"op":"mcm","clk":"4234244148","pt":1631543596455,"mc":[{"id":"1.187560677","rc":[{"trd":[[3.9,68.97]],"batb":[[0,3.75,6],[1,3.45,5.21],[2,2.88,22.21]],"ltp":3.9,"tv":513.72,"id":7588306}],"tv":6096.4}]}
{"op":"mcm","clk":"4234246322","pt":1631543612097,"mc":[{"id":"1.187560677","rc":[{"batl":[[0,4.1,6.87],[1,5.1,1.76],[2,46,29]],"ltp":3.9,"tv":513.72,"id":7588306}]}]}
{"op":"mcm","clk":"4234246800","pt":1631543615688,"mc":[{"id":"1.187560677","rc":[{"trd":[[1.35,358.06]],"batl":[[0,1.35,4802.38]],"ltp":1.35,"tv":5590.57,"id":11439844}],"tv":6104.3}]}
{"op":"mcm","clk":"4234247182","pt":1631543618395,"mc":[{"id":"1.187560677","rc":[{"trd":[[3.95,15.89]],"ltp":3.95,"tv":516.88,"id":7588306},{"trd":[[1.34,83.06]],"ltp":1.34,"tv":5599.89,"id":11439844}],"tv":6116.77}]}
{"op":"mcm","clk":"4234249504","pt":1631543637503,"mc":[{"id":"1.187560677","rc":[{"trd":[[3.85,17.44],[3.9,69.44]],"batb":[[0,3.75,5.76]],"ltp":3.85,"tv":534.79,"id":7588306},{"trd":[[1.35,420.83]],"batl":[[0,1.35,4746.14]],"ltp":1.35,"tv":5662.66,"id":11439844}],"tv":6197.46}]}
{"op":"mcm","clk":"4234249775","pt":1631543639737,"mc":[{"id":"1.187560677","rc":[{"trd":[[3.85,27.73]],"ltp":3.85,"tv":545.08,"id":7588306},{"trd":[[1.35,450.18]],"batl":[[0,1.35,4716.78]],"ltp":1.35,"tv":5692.01,"id":11439844}],"tv":6237.1}]}
{"op":"mcm","clk":"4234250695","pt":1631543646920,"mc":[{"id":"1.187560677","rc":[{"batb":[[0,1.32,280.41]],"ltp":1.35,"tv":5692.01,"id":11439844}]}]}
{"op":"mcm","clk":"4234251038","pt":1631543650011,"mc":[{"id":"1.187560677","rc":[{"trd":[[1.35,472.98]],"batl":[[0,1.35,4705.39]],"ltp":1.35,"tv":5714.81,"id":11439844}],"tv":6259.9}]}
{"op":"mcm","clk":"4234252001","pt":1631543658433,"mc":[{"id":"1.187560677","rc":[{"batb":[[0,3.9,5.63],[1,3.8,4.56],[2,3.75,5.76]],"ltp":3.85,"tv":545.08,"id":7588306}]}]}
{"op":"mcm","clk":"4234252486","pt":1631543661673,"mc":[{"id":"1.187560677","rc":[{"trd":[[1.35,544.87]],"batl":[[0,1.35,4669.45]],"ltp":1.35,"tv":5786.7,"id":11439844}],"tv":6331.79}]}
{"op":"mcm","clk":"4234254228","pt":1631543676586,"mc":[{"id":"1.187560677","rc":[{"trd":[[1.35,564.45]],"batl":[[0,1.35,4659.66]],"ltp":1.35,"tv":5806.28,"id":11439844}],"tv":6351.37}]}
{"op":"mcm","clk":"4234255520","pt":1631543687080,"mc":[{"id":"1.187560677","rc":[{"trd":[[1.35,669.7]],"batl":[[0,1.35,4607.04]],"ltp":1.35,"tv":5911.53,"id":11439844}],"tv":6456.62}]}
{"op":"mcm","clk":"4234256992","pt":1631543699509,"mc":[{"id":"1.187560677","rc":[{"batb":[[0,3.9,5.86]],"ltp":3.85,"tv":545.08,"id":7588306}]}]}
{"op":"mcm","clk":"4234260458","pt":1631543726938,"mc":[{"id":"1.187560677","rc":[{"batl":[[0,1.34,3.41],[1,1.35,4607.04],[2,1.39,3]],"ltp":1.35,"tv":5911.53,"id":11439844}]}]}
{"op":"mcm","clk":"4234271269","pt":1631543810659,"mc":[{"id":"1.187560677","rc":[{"trd":[[1.34,89.87],[1.35,682.71]],"batl":[[0,1.35,4600.53],[1,1.39,3],[2,1.4,913.65]],"ltp":1.35,"tv":5931.36,"id":11439844}],"tv":6476.45}]}
{"op":"mcm","clk":"4234281844","pt":1631543899692,"mc":[{"id":"1.187560677","rc":[{"trd":[[3.9,81.15]],"batb":[[0,3.75,1.12],[1,3.7,4.74],[2,3.45,5.21]],"batl":[[0,3.9,17.14],[1,4.1,6.87],[2,5.1,1.76]],"ltp":3.9,"tv":556.8,"id":7588306},{"batb":[[2,1.21,121.67]],"ltp":1.35,"tv":5931.36,"id":11439844}],"tv":6488.16}]}
{"op":"mcm","clk":"4234281966","pt":1631543900581,"mc":[{"id":"1.187560677","rc":[{"batl":[[2,46,29]],"ltp":3.9,"tv":556.8,"id":7588306}]}]}
{"op":"mcm","clk":"4234282605","pt":1631543905703,"mc":[{"id":"1.187560677","rc":[{"trd":[[3.9,115.38]],"batb":[[0,3.75,5.76]],"batl":[[0,4.1,6.9],[1,46,29],[2,990,2.2]],"ltp":3.9,"tv":591.03,"id":7588306},{"batb":[[2,1.29,44.05]],"ltp":1.35,"tv":5931.36,"id":11439844}],"tv":6522.39}]}
{"op":"mcm","clk":"4234282665","pt":1631543906284,"mc":[{"id":"1.187560677","rc":[{"trd":[[3.9,115.41]],"batl":[[0,4.1,6.87]],"ltp":3.9,"tv":591.06,"id":7588306},{"trd":[[1.34,89.95]],"batl":[[0,1.34,42.51],[1,1.35,4600.53],[2,1.39,3]],"ltp":1.34,"tv":5931.43,"id":11439844}],"tv":6522.5}]}
{"op":"mcm","clk":"4234282823","pt":1631543907715,"mc":[{"id":"1.187560677","rc":[{"batl":[[0,4.1,12.67]],"ltp":3.9,"tv":591.06,"id":7588306},{"trd":[[1.34,152.42]],"batl":[[0,1.34,11.29]],"ltp":1.34,"tv":5993.91,"id":11439844}],"tv":6584.97}]}
{"op":"mcm","clk":"4234283858","pt":1631543916478,"mc":[{"id":"1.187560677","rc":[{"batl":[[0,1.35,4610.67],[1,1.39,3],[2,1.4,913.65]],"ltp":1.34,"tv":5993.91,"id":11439844}]}]}
{"op":"mcm","clk":"4234284047","pt":1631543918109,"mc":[{"id":"1.187560677","rc":[{"batl":[[1,5.8,1.5],[2,46,29]],"ltp":3.9,"tv":591.06,"id":7588306}]}]}
{"op":"mcm","clk":"4234284329","pt":1631543920527,"mc":[{"id":"1.187560677","rc":[{"trd":[[1.35,744.15]],"batl":[[0,1.35,4569.8]],"ltp":1.35,"tv":6055.34,"id":11439844}],"tv":6646.41}]}
{"op":"mcm","clk":"4234285399","pt":1631543929696,"mc":[{"id":"1.187560677","rc":[{"trd":[[1.35,943.43]],"batl":[[0,1.35,4470.17]],"ltp":1.35,"tv":6254.62,"id":11439844}],"tv":6845.69}]}
{"op":"mcm","clk":"4234285557","pt":1631543931211,"mc":[{"id":"1.187560677","rc":[{"trd":[[1.35,944.82]],"batl":[[0,1.35,4469.48]],"ltp":1.35,"tv":6256.02,"id":11439844}],"tv":6847.08}]}
{"op":"mcm","clk":"4234289106","pt":1631543961660,"mc":[{"id":"1.187560677","rc":[{"trd":[[1.35,1381.85]],"batl":[[0,1.35,4251.01]],"ltp":1.35,"tv":6693.04,"id":11439844}],"tv":7284.11}]}
{"op":"mcm","clk":"4234290141","pt":1631543970789,"mc":[{"id":"1.187560677","rc":[{"batl":[[0,3.9,19.56],[1,4.1,12.67],[2,5.8,1.5]],"ltp":3.9,"tv":591.06,"id":7588306}]}]}
{"op":"mcm","clk":"4234290230","pt":1631543971788,"mc":[{"id":"1.187560677","rc":[{"batb":[[0,3.75,1.12]],"ltp":3.9,"tv":591.06,"id":7588306},{"batb":[[2,1.21,121.67]],"ltp":1.35,"tv":6693.04,"id":11439844}]}]}
{"op":"mcm","clk":"4234293035","pt":1631543997688,"mc":[{"id":"1.187560677","rc":[{"trd":[[1.35,1484.34]],"batb":[[2,1.3,42.58]],"batl":[[0,1.35,4199.77]],"ltp":1.35,"tv":6795.53,"id":11439844}],"tv":7386.6}]}
{"op":"mcm","clk":"4234293064","pt":1631543997897,"mc":[{"id":"1.187560677","rc":[{"batb":[[0,1.33,24.01],[1,1.32,290.75],[2,1.31,8.71]],"ltp":1.35,"tv":6795.53,"id":11439844}]}]}
{"op":"mcm","clk":"4234297969","pt":1631544047701,"mc":[{"id":"1.187560677","rc":[{"trd":[[3.85,37.3]],"ltp":3.85,"tv":600.62,"id":7588306},{"trd":[[1.35,1511.6]],"batl":[[0,1.35,4172.51]],"ltp":1.35,"tv":6822.79,"id":11439844}],"tv":7423.42}]}
{"op":"mcm","clk":"4234298201","pt":1631544049884,"mc":[{"id":"1.187560677","rc":[{"trd":[[1.35,1531.25]],"batl":[[0,1.35,4162.68]],"ltp":1.35,"tv":6842.45,"id":11439844}],"tv":7443.07}]}
{"op":"mcm","clk":"4234298405","pt":1631544051673,"mc":[{"id":"1.187560677","rc":[{"trd":[[1.35,1593.76]],"batl":[[0,1.35,4131.43]],"ltp":1.35,"tv":6904.95,"id":11439844}],"tv":7505.58}]}
{"op":"mcm","clk":"4234299652","pt":1631544063722,"mc":[{"id":"1.187560677","rc":[{"trd":[[1.35,2093.64]],"batl":[[0,1.35,3881.54]],"ltp":1.35,"tv":7404.83,"id":11439844}],"tv":8005.46}]}
{"op":"mcm","clk":"4234306586","pt":1631544129850,"mc":[{"id":"1.187560677","rc":[{"trd":[[1.35,2119.64]],"batl":[[0,1.35,3868.54]],"ltp":1.35,"tv":7430.83,"id":11439844}],"tv":8031.46}]}
{"op":"mcm","clk":"4234310950","pt":1631544174233,"mc":[{"id":"1.187560677","rc":[{"trd":[[3.85,52.73]],"ltp":3.85,"tv":616.06,"id":7588306},{"trd":[[1.35,2163.66]],"batl":[[0,1.35,3824.52]],"ltp":1.35,"tv":7474.86,"id":11439844}],"tv":8090.92}]}
{"op":"mcm","clk":"4234312800","pt":1631544193011,"mc":[{"id":"1.187560677","rc":[{"trd":[[1.35,2269.32]],"batl":[[0,1.35,3771.66]],"ltp":1.35,"tv":7580.52,"id":11439844}],"tv":8196.58}]}
{"op":"mcm","clk":"4234313104","pt":1631544195994,"mc":[{"id":"1.187560677","rc":[{"batl":[[0,3.9,19.16]],"ltp":3.85,"tv":616.06,"id":7588306}]}]}
{"op":"mcm","clk":"4234314089","pt":1631544205221,"mc":[{"id":"1.187560677","rc":[{"trd":[[3.85,71.9]],"batl":[[0,4.1,12.67],[1,5.8,1.5],[2,46,29]],"ltp":3.85,"tv":635.22,"id":7588306},{"trd":[[1.35,2323.97]],"batl":[[0,1.35,3717.01]],"ltp":1.35,"tv":7635.17,"id":11439844}],"tv":8270.39}]}
{"op":"mcm","clk":"4234314161","pt":1631544205971,"mc":[{"id":"1.187560677","rc":[{"batb":[[0,3.75,5.76]],"ltp":3.85,"tv":635.22,"id":7588306}]}]}
{"op":"mcm","clk":"4234314604","pt":1631544210326,"mc":[{"id":"1.187560677","rc":[{"batb":[[0,1.32,280.41],[1,1.31,8.71],[2,1.29,44.05]],"ltp":1.35,"tv":7635.17,"id":11439844}]}]}
{"op":"mcm","clk":"4234315096","pt":1631544214555,"mc":[{"id":"1.187560677","rc":[{"batb":[[0,1.33,152.79],[1,1.32,280.41],[2,1.31,8.71]],"ltp":1.35,"tv":7635.17,"id":11439844}]}]}
{"op":"mcm","clk":"4234315143","pt":1631544215028,"mc":[{"id":"1.187560677","rc":[{"batb":[[0,3.75,1.12]],"ltp":3.85,"tv":635.22,"id":7588306}]}]}
{"op":"mcm","clk":"4234316402","pt":1631544226679,"mc":[{"id":"1.187560677","rc":[{"batl":[[0,4,12.98],[1,4.1,12.67],[2,5.8,1.5]],"ltp":3.85,"tv":635.22,"id":7588306}]}]}
{"op":"mcm","clk":"4234316434","pt":1631544226941,"mc":[{"id":"1.187560677","rc":[{"batl":[[1,5.8,1.5],[2,46,29]],"ltp":3.85,"tv":635.22,"id":7588306}]}]}
{"op":"mcm","clk":"4234316665","pt":1631544229286,"mc":[{"id":"1.187560677","rc":[{"batb":[[0,1.33,9.24],[2,1.31,17.97]],"ltp":1.35,"tv":7635.17,"id":11439844}]}]}
{"op":"mcm","clk":"4234316886","pt":1631544231680,"mc":[{"id":"1.187560677","rc":[{"batl":[[0,5.8,1.5],[1,46,29],[2,990,2.2]],"ltp":3.85,"tv":635.22,"id":7588306}]}]}
{"op":"mcm","clk":"4234316915","pt":1631544231956,"mc":[{"id":"1.187560677","rc":[{"batb":[[0,3.75,5.76]],"batl":[[0,5.1,13.88],[1,5.8,1.5],[2,46,29]],"ltp":3.85,"tv":635.22,"id":7588306}]}]}
{"op":"mcm","clk":"4234317190","pt":1631544235071,"mc":[{"id":"1.187560677","rc":[{"trd":[[1.35,2692.08]],"batl":[[0,1.35,3532.86]],"ltp":1.35,"tv":8003.27,"id":11439844}],"tv":8638.5}]}
{"op":"mcm","clk":"4234317525","pt":1631544238265,"mc":[{"id":"1.187560677","rc":[{"batl":[[0,4.1,12.4]],"ltp":3.85,"tv":635.22,"id":7588306}]}]}
{"op":"mcm","clk":"4234317616","pt":1631544239300,"mc":[{"id":"1.187560677","rc":[{"trd":[[1.35,2700.6]],"batl":[[0,1.35,3528.6]],"ltp":1.35,"tv":8011.79,"id":11439844}],"tv":8647.02}]}
{"op":"mcm","clk":"4234320448","pt":1631544266652,"mc":[{"id":"1.187560677","rc":[{"trd":[[1.35,2705.9]],"batl":[[0,1.35,3525.94]],"ltp":1.35,"tv":8017.1,"id":11439844}],"tv":8652.32}]}
{"op":"mcm","clk":"4234324374","pt":1631544306822,"mc":[{"id":"1.187560677","rc":[{"trd":[[1.35,2725.4]],"batl":[[0,1.35,3516.2]],"ltp":1.35,"tv":8036.59,"id":11439844}],"tv":8671.82}]}
{"op":"mcm","clk":"4234327609","pt":1631544337062,"mc":[{"id":"1.187560677","rc":[{"trd":[[1.33,4.48]],"batb":[[0,1.33,7]],"ltp":1.33,"tv":8041.07,"id":11439844}],"tv":8676.3}]}
{"op":"mcm","clk":"4234336080","pt":1631544412360,"mc":[{"id":"1.187560677","rc":[{"batb":[[0,1.32,280.41],[1,1.31,17.97],[2,1.29,44.05]],"batl":[[0,1.34,913.65],[1,1.35,3516.2],[2,1.39,3]],"ltp":1.33,"tv":8041.07,"id":11439844}]}]}
{"op":"mcm","clk":"4234336181","pt":1631544413086,"mc":[{"id":"1.187560677","rc":[{"batb":[[0,3.8,4.56],[1,3.75,5.76],[2,3.7,4.74]],"ltp":3.85,"tv":635.22,"id":7588306}]}]}
{"op":"mcm","clk":"4234339728","pt":1631544447604,"mc":[{"id":"1.187560677","rc":[{"trd":[[1.34,336.38]],"batb":[[1,1.31,8.71]],"batl":[[0,1.34,821.67]],"ltp":1.34,"tv":8225.03,"id":11439844}],"tv":8860.26}]}
{"op":"mcm","clk":"4234341912","pt":1631544468620,"mc":[{"id":"1.187560677","rc":[{"batb":[[0,1.32,291.86]],"ltp":1.34,"tv":8225.03,"id":11439844}]}]}
{"op":"mcm","clk":"4234346504","pt":1631544517971,"mc":[{"id":"1.187560677","rc":[{"trd":[[1.32,27.05]],"batb":[[0,1.32,289.3]],"ltp":1.32,"tv":8230.15,"id":11439844}],"tv":8865.37}]}
{"op":"mcm","clk":"4234346618","pt":1631544519166,"mc":[{"id":"1.187560677","rc":[{"batb":[[0,1.32,291.86]],"ltp":1.32,"tv":8230.15,"id":11439844}]}]}
{"op":"mcm","clk":"4234347878","pt":1631544534829,"mc":[{"id":"1.187560677","rc":[{"trd":[[1.34,368.12]],"batl":[[0,1.34,805.8]],"ltp":1.34,"tv":8261.89,"id":11439844}],"tv":8897.11}]}
{"op":"mcm","clk":"4234349664","pt":1631544556243,"mc":[{"id":"1.187560677","rc":[{"batb":[[0,3.75,5.76],[1,3.7,4.74],[2,3.45,5.21]],"ltp":3.85,"tv":635.22,"id":7588306},{"batb":[[0,1.33,212.91],[1,1.32,300.85],[2,1.31,8.71]],"ltp":1.34,"tv":8261.89,"id":11439844}]}]}
{"op":"mcm","clk":"4234350439","pt":1631544565075,"mc":[{"id":"1.187560677","rc":[{"trd":[[1.34,793.95]],"batl":[[0,1.34,592.89]],"ltp":1.34,"tv":8687.72,"id":11439844}],"tv":9322.94}]}
{"op":"mcm","clk":"4234350657","pt":1631544567367,"mc":[{"id":"1.187560677","rc":[{"batl":[[0,4,12.4]],"ltp":3.85,"tv":635.22,"id":7588306}]}]}
{"op":"mcm","clk":"4234350794","pt":1631544568882,"mc":[{"id":"1.187560677","rc":[{"trd":[[3.9,126.07]],"ltp":3.9,"tv":645.88,"id":7588306},{"trd":[[1.34,824.94]],"batl":[[0,1.34,561.89]],"ltp":1.34,"tv":8718.71,"id":11439844}],"tv":9364.6}]}
{"op":"mcm","clk":"4234351487","pt":1631544576686,"mc":[{"id":"1.187560677","rc":[{"trd":[[1.34,1250.77]],"batb":[[0,1.32,291.86],[1,1.31,17.06],[2,1.29,44.05]],"batl":[[0,1.34,348.98]],"ltp":1.34,"tv":9144.54,"id":11439844}],"tv":9790.43}]}
{"op":"mcm","clk":"4234351543","pt":1631544577256,"mc":[{"id":"1.187560677","rc":[{"batb":[[0,3.8,4.56],[1,3.75,5.76],[2,3.7,4.74]],"ltp":3.9,"tv":645.88,"id":7588306},{"batb":[[1,1.31,8.71]],"ltp":1.34,"tv":9144.54,"id":11439844}]}]}
{"op":"mcm","clk":"4234351633","pt":1631544578393,"mc":[{"id":"1.187560677","rc":[{"batl":[[0,4.1,12.4]],"ltp":3.9,"tv":645.88,"id":7588306},{"batb":[[2,1.2,121.67]],"ltp":1.34,"tv":9144.54,"id":11439844}]}]}
{"op":"mcm","clk":"4234351716","pt":1631544579291,"mc":[{"id":"1.187560677","rc":[{"batb":[[2,1.29,44.05]],"ltp":1.34,"tv":9144.54,"id":11439844}]}]}
{"op":"mcm","clk":"4234353689","pt":1631544602695,"mc":[{"id":"1.187560677","rc":[{"batb":[[0,3.8,4.62]],"ltp":3.9,"tv":645.88,"id":7588306}]}]}
{"op":"mcm","clk":"4234353806","pt":1631544603687,"mc":[{"id":"1.187560677","rc":[{"trd":[[1.34,1740.47]],"batb":[[1,1.31,22.08]],"batl":[[0,1.34,104.28]],"ltp":1.34,"tv":9634.24,"id":11439844}],"tv":10280.13}]}
{"op":"mcm","clk":"4234354719","pt":1631544613970,"mc":[{"id":"1.187560677","rc":[{"batl":[[0,4.1,10.95]],"ltp":3.9,"tv":645.88,"id":7588306}]}]}
{"op":"mcm","clk":"4234356464","pt":1631544635528,"mc":[{"id":"1.187560677","rc":[{"trd":[[4,0.06]],"batb":[[0,3.8,4.56]],"ltp":4.0,"tv":645.94,"id":7588306},{"trd":[[1.34,1949.2]],"batb":[[0,1.34,108.46],[1,1.32,291.86],[2,1.31,22.08]],"batl":[[0,1.35,3516.2],[1,1.39,3],[2,1.42,11.45]],"ltp":1.34,"tv":9842.97,"id":11439844}],"tv":10488.92}]}
{"op":"mcm","clk":"4234356522","pt":1631544636418,"mc":[{"id":"1.187560677","rc":[{"batb":[[0,3.75,1.12],[1,3.7,4.74],[2,3.45,5.21]],"ltp":4.0,"tv":645.94,"id":7588306}]}]}
{"op":"mcm","clk":"4234357194","pt":1631544644637,"mc":[{"id":"1.187560677","rc":[{"batl":[[0,3.9,10.12],[1,4.1,10.95],[2,5.8,1.5]],"ltp":4.0,"tv":645.94,"id":7588306}]}]}
{"op":"mcm","clk":"4234357260","pt":1631544645317,"mc":[{"id":"1.187560677","rc":[{"batl":[[0,3.9,19.93],[1,5.8,1.5],[2,46,29]],"ltp":4.0,"tv":645.94,"id":7588306}]}]}
{"op":"mcm","clk":"4234358473","pt":1631544660061,"mc":[{"id":"1.187560677","rc":[{"batl":[[0,3.9,9.82]],"ltp":4.0,"tv":645.94,"id":7588306}]}]}
{"op":"mcm","clk":"4234358563","pt":1631544661157,"mc":[{"id":"1.187560677","rc":[{"batl":[[0,3.95,9.82]],"ltp":4.0,"tv":645.94,"id":7588306}]}]}
{"op":"mcm","clk":"4234359226","pt":1631544668874,"mc":[{"id":"1.187560677","rc":[{"trd":[[3.85,82.38]],"ltp":3.85,"tv":656.42,"id":7588306},{"trd":[[1.35,2755.28]],"batl":[[0,1.35,3486.32]],"ltp":1.35,"tv":9872.85,"id":11439844}],"tv":10529.28}]}
{"op":"mcm","clk":"4234363652","pt":1631544722569,"mc":[{"id":"1.187560677","rc":[{"trd":[[3.85,83.76]],"ltp":3.85,"tv":657.81,"id":7588306},{"trd":[[1.35,2759.22]],"batl":[[0,1.35,3482.38]],"ltp":1.35,"tv":9876.79,"id":11439844}],"tv":10534.6}]}
{"op":"mcm","clk":"4234366254","pt":1631544754014,"mc":[{"id":"1.187560677","rc":[{"trd":[[1.35,2765.65]],"batl":[[0,1.35,3479.16]],"ltp":1.35,"tv":9883.22,"id":11439844}],"tv":10541.03}]}
{"op":"mcm","clk":"4234366915","pt":1631544762300,"mc":[{"id":"1.187560677","rc":[{"batb":[[1,1.32,161.34]],"ltp":1.35,"tv":9883.22,"id":11439844}]}]}
{"op":"mcm","clk":"4234368801","pt":1631544787757,"mc":[{"id":"1.187560677","rc":[{"trd":[[1.35,2771.97]],"batl":[[0,1.35,3476]],"ltp":1.35,"tv":9889.54,"id":11439844}],"tv":10547.35}]}
{"op":"mcm","clk":"4234372679","pt":1631544836999,"mc":[{"id":"1.187560677","rc":[{"trd":[[1.35,2828.48]],"batl":[[0,1.35,3447.74]],"ltp":1.35,"tv":9946.05,"id":11439844}],"tv":10603.86}]}
{"op":"mcm","clk":"4234377089","pt":1631544890470,"mc":[{"id":"1.187560677","rc":[{"trd":[[1.35,2919.59]],"batl":[[0,1.35,3402.17]],"ltp":1.35,"tv":10037.16,"id":11439844}],"tv":10694.97}]}
{"op":"mcm","clk":"4234379635","pt":1631544920698,"mc":[{"id":"1.187560677","rc":[{"trd":[[1.35,3101.78]],"batl":[[0,1.35,3311.02]],"ltp":1.35,"tv":10219.35,"id":11439844}],"tv":10877.16}]}
{"op":"mcm","clk":"4234382498","pt":1631544960544,"mc":[{"id":"1.187560677","rc":[{"trd":[[1.35,3228.77]],"batl":[[0,1.35,3247.54]],"ltp":1.35,"tv":10346.34,"id":11439844}],"tv":11004.15}]}
{"op":"mcm","clk":"4234382886","pt":1631544966150,"mc":[{"id":"1.187560677","rc":[{"trd":[[1.35,3340.32]],"batl":[[0,1.35,3191.77]],"ltp":1.35,"tv":10457.89,"id":11439844}],"tv":11115.7}]}
{"op":"mcm","clk":"4234384489","pt":1631544988722,"mc":[{"id":"1.187560677","rc":[{"trd":[[1.35,3522.66]],"batl":[[0,1.35,3100.54]],"ltp":1.35,"tv":10640.24,"id":11439844}],"tv":11298.05}]}
{"op":"mcm","clk":"4234384694","pt":1631544991595,"mc":[{"id":"1.187560677","rc":[{"trd":[[1.35,3542.41]],"batl":[[0,1.35,3090.67]],"ltp":1.35,"tv":10659.98,"id":11439844}],"tv":11317.79}]}
{"op":"mcm","clk":"4234385179","pt":1631544998909,"mc":[{"id":"1.187560677","rc":[{"batl":[[0,3.95,9.51]],"ltp":3.85,"tv":657.81,"id":7588306}]}]}
{"op":"mcm","clk":"4234385756","pt":1631545008011,"mc":[{"id":"1.187560677","rc":[{"trd":[[1.34,1949.4]],"batb":[[0,1.34,108.35]],"ltp":1.34,"tv":10660.18,"id":11439844}],"tv":11317.99}]}
{"op":"mcm","clk":"4234385839","pt":1631545009232,"mc":[{"id":"1.187560677","marketDefinition":{"bspMarket":false,"turnInPlayEnabled":true,"persistenceEnabled":true,"marketBaseRate":5.0,"eventId":"30896281","eventTypeId":"2","numberOfWinners":1,"bettingType":"ODDS","marketType":"MATCH_ODDS","marketTime":"2021-09-13T14:56:00.000Z","suspendTime":"2021-09-13T14:56:00.000Z","bspReconciled":false,"complete":true,"inPlay":false,"crossMatching":true,"runnersVoidable":false,"numberOfActiveRunners":2,"betDelay":0,"status":"OPEN","runners":[{"status":"ACTIVE","sortPriority":1,"id":11439844,"name":"Aleksandar Kovacevic"},{"status":"ACTIVE","sortPriority":2,"id":7588306,"name":"Strong Kirchheimer"}],"regulators":["MR_INT"],"countryCode":"US","discountAllowed":true,"timezone":"UTC","openDate":"2021-09-13T15:00:00.000Z","version":4030797474,"name":"Match Odds","eventName":"Al Kovacevic v Str Kirchheimer"},"rc":[{"batb":[[0,1.34,115.77]],"batl":[[1,1.42,11.45],[2,1.43,2.03]],"ltp":1.34,"tv":10660.18,"id":11439844}]}]}
{"op":"mcm","clk":"4234386172","pt":1631545013767,"mc":[{"id":"1.187560677","rc":[{"batl":[[0,3.95,10.68]],"ltp":3.85,"tv":657.81,"id":7588306}]}]}
{"op":"mcm","clk":"4234386780","pt":1631545022032,"mc":[{"id":"1.187560677","marketDefinition":{"bspMarket":false,"turnInPlayEnabled":true,"persistenceEnabled":true,"marketBaseRate":5.0,"eventId":"30896281","eventTypeId":"2","numberOfWinners":1,"bettingType":"ODDS","marketType":"MATCH_ODDS","marketTime":"2021-09-13T14:56:00.000Z","suspendTime":"2021-09-13T14:56:00.000Z","bspReconciled":false,"complete":true,"inPlay":false,"crossMatching":true,"runnersVoidable":false,"numberOfActiveRunners":2,"betDelay":0,"status":"OPEN","runners":[{"status":"ACTIVE","sortPriority":1,"id":11439844,"name":"Aleksandar Kovacevic"},{"status":"ACTIVE","sortPriority":2,"id":7588306,"name":"Strong Kirchheimer"}],"regulators":["MR_INT"],"countryCode":"US","discountAllowed":true,"timezone":"UTC","openDate":"2021-09-13T14:56:00.000Z","version":4030797474,"name":"Match Odds","eventName":"Al Kovacevic v Str Kirchheimer"}}]}
{"op":"mcm","clk":"4234387050","pt":1631545025459,"mc":[{"id":"1.187560677","rc":[{"trd":[[3.85,89.57]],"ltp":3.85,"tv":663.61,"id":7588306},{"trd":[[1.35,3558.97]],"batl":[[0,1.35,3074.11]],"ltp":1.35,"tv":10676.74,"id":11439844}],"tv":11340.36}]}
{"op":"mcm","clk":"4234387759","pt":1631545034781,"mc":[{"id":"1.187560677","rc":[{"batl":[[0,3.95,12.68]],"ltp":3.85,"tv":663.61,"id":7588306},{"batl":[[0,1.35,3076.11]],"ltp":1.35,"tv":10676.74,"id":11439844}]}]}
{"op":"mcm","clk":"4234388975","pt":1631545052619,"mc":[{"id":"1.187560677","marketDefinition":{"bspMarket":false,"turnInPlayEnabled":true,"persistenceEnabled":true,"marketBaseRate":5.0,"eventId":"30896281","eventTypeId":"2","numberOfWinners":1,"bettingType":"ODDS","marketType":"MATCH_ODDS","marketTime":"2021-09-13T14:56:00.000Z","suspendTime":"2021-09-13T14:56:00.000Z","bspReconciled":false,"complete":true,"inPlay":true,"crossMatching":true,"runnersVoidable":false,"numberOfActiveRunners":2,"betDelay":3,"status":"OPEN","runners":[{"status":"ACTIVE","sortPriority":1,"id":11439844,"name":"Aleksandar Kovacevic"},{"status":"ACTIVE","sortPriority":2,"id":7588306,"name":"Strong Kirchheimer"}],"regulators":["MR_INT"],"countryCode":"US","discountAllowed":true,"timezone":"UTC","openDate":"2021-09-13T14:56:00.000Z","version":4030798893,"name":"Match Odds","eventName":"Al Kovacevic v Str Kirchheimer"},"rc":[{"batb":[[0,1.6,766.48],[1,1.3,5],[2,1.25,28.91]],"ltp":3.85,"tv":663.61,"id":7588306},{"batb":[[0,1.34,7.42],[1,1.12,60.22],[2,1.06,766.48]],"batl":[[0,1.35,3074.11],[1,1.52,0.53],[2,1.43,0]],"ltp":1.35,"tv":10676.74,"id":11439844}]}]}
{"op":"mcm","clk":"4234389184","pt":1631545055884,"mc":[{"id":"1.187560677","rc":[{"trd":[[1.35,3578.67]],"batb":[[0,1.12,60.22],[1,1.06,766.48],[2,1.01,578.33]],"batl":[[0,1.35,3064.26]],"ltp":1.35,"tv":10696.44,"id":11439844}],"tv":11360.06}]}
{"op":"mcm","clk":"4234389300","pt":1631545058012,"mc":[{"id":"1.187560677","rc":[{"trd":[[1.35,3698.08]],"batl":[[0,1.35,3004.56]],"ltp":1.35,"tv":10815.85,"id":11439844}],"tv":11479.47}]}
{"op":"mcm","clk":"4234389381","pt":1631545058899,"mc":[{"id":"1.187560677","rc":[{"batb":[[0,1.12,69.09]],"ltp":1.35,"tv":10815.85,"id":11439844}]}]}
{"op":"mcm","clk":"4234389453","pt":1631545060109,"mc":[{"id":"1.187560677","rc":[{"batb":[[0,1.13,196.53],[1,1.12,60.22],[2,1.06,766.48]],"ltp":1.35,"tv":10815.85,"id":11439844}]}]}
{"op":"mcm","clk":"4234389488","pt":1631545060727,"mc":[{"id":"1.187560677","rc":[{"batb":[[2,1.07,364.99]],"ltp":1.35,"tv":10815.85,"id":11439844}]}]}
{"op":"mcm","clk":"4234389646","pt":1631545063021,"mc":[{"id":"1.187560677","rc":[{"batb":[[0,1.13,205.33]],"ltp":1.35,"tv":10815.85,"id":11439844}]}]}
{"op":"mcm","clk":"4234389703","pt":1631545063909,"mc":[{"id":"1.187560677","rc":[{"trd":[[1.35,3854.6]],"batl":[[0,1.35,2926.31]],"ltp":1.35,"tv":10972.38,"id":11439844}],"tv":11636.0}]}
{"op":"mcm","clk":"4234389937","pt":1631545067242,"mc":[{"id":"1.187560677","rc":[{"batb":[[0,1.13,196.53]],"ltp":1.35,"tv":10972.38,"id":11439844}]}]}
{"op":"mcm","clk":"4234390143","pt":1631545070321,"mc":[{"id":"1.187560677","rc":[{"batb":[[0,1.18,8.42],[1,1.15,170.33],[2,1.13,196.53]],"ltp":1.35,"tv":10972.38,"id":11439844}]}]}
{"op":"mcm","clk":"4234390627","pt":1631545078328,"mc":[{"id":"1.187560677","rc":[{"trd":[[1.15,33.14],[1.18,16.84]],"batb":[[0,1.15,153.76],[1,1.13,196.53],[2,1.12,60.22]],"ltp":1.15,"tv":11022.36,"id":11439844}],"tv":11685.98}]}
{"op":"mcm","clk":"4234390765","pt":1631545080316,"mc":[{"id":"1.187560677","rc":[{"batb":[[0,1.19,134.47],[1,1.15,153.76],[2,1.13,196.53]],"ltp":1.15,"tv":11022.36,"id":11439844}]}]}
{"op":"mcm","clk":"4234390840","pt":1631545081417,"mc":[{"id":"1.187560677","rc":[{"batb":[[0,1.15,153.76],[1,1.13,196.53],[2,1.12,60.22]],"ltp":1.15,"tv":11022.36,"id":11439844}]}]}
{"op":"mcm","clk":"4234391157","pt":1631545086467,"mc":[{"id":"1.187560677","rc":[{"batl":[[0,1.33,14.32],[1,1.35,2926.31],[2,1.52,0.53]],"ltp":1.15,"tv":11022.36,"id":11439844}]}]}
{"op":"mcm","clk":"4234391346","pt":1631545089557,"mc":[{"id":"1.187560677","rc":[{"trd":[[1.33,33.13],[1.35,3996.36]],"batl":[[0,1.35,2855.39],[1,1.52,0.53],[2,1.52,0]],"ltp":1.35,"tv":11192.76,"id":11439844}],"tv":11856.38}]}
{"op":"mcm","clk":"4234391421","pt":1631545090666,"mc":[{"id":"1.187560677","rc":[{"batb":[[0,1.16,609.73],[1,1.15,153.76],[2,1.13,196.53]],"ltp":1.35,"tv":11192.76,"id":11439844}]}]}
{"op":"mcm","clk":"4234391864","pt":1631545096628,"mc":[{"id":"1.187560677","rc":[{"batb":[[1,1.13,196.53],[2,1.12,60.22]],"ltp":1.35,"tv":11192.76,"id":11439844}]}]}
{"op":"mcm","clk":"4234391948","pt":1631545097659,"mc":[{"id":"1.187560677","rc":[{"batb":[[0,1.17,300.58],[1,1.16,609.73],[2,1.13,196.53]],"ltp":1.35,"tv":11192.76,"id":11439844}]}]}
{"op":"mcm","clk":"4234392442","pt":1631545104478,"mc":[{"id":"1.187560677","rc":[{"batb":[[1,1.12,60.22],[2,1.07,364.99]],"ltp":1.35,"tv":11192.76,"id":11439844}]}]}
{"op":"mcm","clk":"4234392480","pt":1631545104994,"mc":[{"id":"1.187560677","rc":[{"batb":[[0,1.17,450.87]],"ltp":1.35,"tv":11192.76,"id":11439844}]}]}
{"op":"mcm","clk":"4234392658","pt":1631545107587,"mc":[{"id":"1.187560677","rc":[{"batb":[[0,1.17,1055.3]],"ltp":1.35,"tv":11192.76,"id":11439844}]}]}
{"op":"mcm","clk":"4234392868","pt":1631545110573,"mc":[{"id":"1.187560677","rc":[{"batb":[[0,1.19,134.47],[1,1.17,1055.3],[2,1.12,60.22]],"ltp":1.35,"tv":11192.76,"id":11439844}]}]}
{"op":"mcm","clk":"4234393210","pt":1631545114682,"mc":[{"id":"1.187560677","rc":[{"batb":[[0,1.18,141.94],[1,1.17,604.43]],"ltp":1.35,"tv":11192.76,"id":11439844}]}]}
{"op":"mcm","clk":"4234393286","pt":1631545115714,"mc":[{"id":"1.187560677","rc":[{"batb":[[0,1.18,283.89]],"ltp":1.35,"tv":11192.76,"id":11439844}]}]}
{"op":"mcm","clk":"4234393359","pt":1631545116622,"mc":[{"id":"1.187560677","rc":[{"batb":[[0,1.18,286.89]],"ltp":1.35,"tv":11192.76,"id":11439844}]}]}
{"op":"mcm","clk":"4234394331","pt":1631545129715,"mc":[{"id":"1.187560677","rc":[{"trd":[[1.35,4759.44]],"batl":[[0,1.35,2473.9]],"ltp":1.35,"tv":11955.85,"id":11439844}],"tv":12619.47}]}
{"op":"mcm","clk":"4234394352","pt":1631545129926,"mc":[{"id":"1.187560677","rc":[{"batb":[[1,1.12,60.22],[2,1.07,364.99]],"ltp":1.35,"tv":11955.85,"id":11439844}]}]}
{"op":"mcm","clk":"4234394643","pt":1631545134238,"mc":[{"id":"1.187560677","rc":[{"trd":[[1.35,4806.96]],"batl":[[0,1.35,2450.12]],"ltp":1.35,"tv":12003.36,"id":11439844}],"tv":12666.98}]}
{"op":"mcm","clk":"4234394716","pt":1631545135222,"mc":[{"id":"1.187560677","rc":[{"trd":[[1.35,4853.36]],"batl":[[0,1.35,2426.91]],"ltp":1.35,"tv":12049.77,"id":11439844}],"tv":12713.39}]}
{"op":"mcm","clk":"4234394939","pt":1631545138603,"mc":[{"id":"1.187560677","rc":[{"batl":[[1,1.5,2.13],[2,1.52,0.53]],"ltp":1.35,"tv":12049.77,"id":11439844}]}]}
{"op":"mcm","clk":"4234395050","pt":1631545140530,"mc":[{"id":"1.187560677","rc":[{"batb":[[0,1.2,127.75],[1,1.18,286.89],[2,1.12,60.22]],"ltp":1.35,"tv":12049.77,"id":11439844}]}]}
{"op":"mcm","clk":"4234395110","pt":1631545141314,"mc":[{"id":"1.187560677","rc":[{"batb":[[1,1.18,3]],"ltp":1.35,"tv":12049.77,"id":11439844}]}]}
{"op":"mcm","clk":"4234395363","pt":1631545145412,"mc":[{"id":"1.187560677","rc":[{"trd":[[1.35,4877.12]],"batb":[[2,1.15,340.66]],"batl":[[0,1.35,2415.02]],"ltp":1.35,"tv":12073.53,"id":11439844}],"tv":12737.15}]}
{"op":"mcm","clk":"4234396220","pt":1631545157660,"mc":[{"id":"1.187560677","rc":[{"trd":[[1.35,4924.64]],"batl":[[0,1.35,2391.25]],"ltp":1.35,"tv":12121.04,"id":11439844}],"tv":12784.66}]}
{"op":"mcm","clk":"4234396275","pt":1631545158027,"mc":[{"id":"1.187560677","rc":[{"trd":[[1.35,4977.7]],"batl":[[0,1.35,2364.7]],"ltp":1.35,"tv":12174.11,"id":11439844}],"tv":12837.73}]}
{"op":"mcm","clk":"4234396356","pt":1631545159332,"mc":[{"id":"1.187560677","rc":[{"trd":[[1.35,5106.74]],"batl":[[0,1.35,2300.15]],"ltp":1.35,"tv":12303.15,"id":11439844}],"tv":12966.77}]}
{"op":"mcm","clk":"4234396444","pt":1631545160656,"mc":[{"id":"1.187560677","rc":[{"trd":[[1.35,5726.76]],"batl":[[0,1.35,1990.01]],"ltp":1.35,"tv":12923.16,"id":11439844}],"tv":13586.78}]}
{"op":"mcm","clk":"4234396515","pt":1631545161564,"mc":[{"id":"1.187560677","rc":[{"trd":[[1.35,5819.75]],"batl":[[0,1.35,1943.48]],"ltp":1.35,"tv":13016.16,"id":11439844}],"tv":13679.78}]}
{"op":"mcm","clk":"4234396607","pt":1631545162448,"mc":[{"id":"1.187560677","rc":[{"trd":[[1.35,6119.6]],"batl":[[0,1.35,1793.52]],"ltp":1.35,"tv":13316.0,"id":11439844}],"tv":13979.62}]}
{"op":"mcm","clk":"4234396679","pt":1631545163274,"mc":[{"id":"1.187560677","rc":[{"trd":[[1.35,6364.47]],"batl":[[0,1.35,1671.04]],"ltp":1.35,"tv":13560.88,"id":11439844}],"tv":14224.5}]}
{"op":"mcm","clk":"4234396736","pt":1631545163958,"mc":[{"id":"1.187560677","rc":[{"trd":[[1.35,6475.97]],"batl":[[0,1.35,1615.26]],"ltp":1.35,"tv":13672.38,"id":11439844}],"tv":14336.0}]}
{"op":"mcm","clk":"4234396849","pt":1631545165463,"mc":[{"id":"1.187560677","rc":[{"trd":[[1.35,6958.85]],"batl":[[0,1.35,1373.74]],"ltp":1.35,"tv":14155.26,"id":11439844}],"tv":14818.88}]}
{"op":"mcm","clk":"4234396917","pt":1631545166359,"mc":[{"id":"1.187560677","rc":[{"trd":[[1.35,7180.33]],"batl":[[0,1.35,1262.96]],"ltp":1.35,"tv":14376.74,"id":11439844}],"tv":15040.36}]}
{"op":"mcm","clk":"4234397001","pt":1631545167559,"mc":[{"id":"1.187560677","rc":[{"trd":[[1.35,7349.19]],"batl":[[0,1.35,1178.53]],"ltp":1.35,"tv":14545.59,"id":11439844}],"tv":15209.21}]}
{"op":"mcm","clk":"4234397026","pt":1631545167864,"mc":[{"id":"1.187560677","rc":[{"trd":[[1.35,7411.46]],"batl":[[0,1.35,1147.39]],"ltp":1.35,"tv":14607.87,"id":11439844}],"tv":15271.49}]}
{"op":"mcm","clk":"4234397203","pt":1631545170076,"mc":[{"id":"1.187560677","rc":[{"trd":[[1.35,7473.74]],"batl":[[0,1.35,1116.26]],"ltp":1.35,"tv":14670.14,"id":11439844}],"tv":15333.76}]}
{"op":"mcm","clk":"4234397329","pt":1631545171559,"mc":[{"id":"1.187560677","rc":[{"trd":[[1.35,7598.29]],"batl":[[0,1.35,1053.99]],"ltp":1.35,"tv":14794.69,"id":11439844}],"tv":15458.31}]}
{"op":"mcm","clk":"4234397416","pt":1631545172668,"mc":[{"id":"1.187560677","rc":[{"trd":[[1.35,7622.05]],"batb":[[0,1.25,97.55],[1,1.2,127.75],[2,1.18,3]],"batl":[[0,1.35,1042.1]],"ltp":1.35,"tv":14818.45,"id":11439844}],"tv":15482.07}]}
{"op":"mcm","clk":"4234397641","pt":1631545175672,"mc":[{"id":"1.187560677","rc":[{"trd":[[3.85,99.5]],"ltp":3.85,"tv":673.54,"id":7588306},{"trd":[[1.35,7650.35]],"batl":[[0,1.35,1013.79]],"ltp":1.35,"tv":14846.76,"id":11439844}],"tv":15520.31}]}
{"op":"mcm","clk":"4234397838","pt":1631545178177,"mc":[{"id":"1.187560677","rc":[{"batb":[[0,1.26,98.26],[1,1.25,97.55],[2,1.2,127.75]],"ltp":1.35,"tv":14846.76,"id":11439844}]}]}
{"op":"mcm","clk":"4234397970","pt":1631545179683,"mc":[{"id":"1.187560677","rc":[{"trd":[[1.35,7830.5]],"batb":[[2,1.18,3]],"batl":[[0,1.35,923.68]],"ltp":1.35,"tv":15026.9,"id":11439844}],"tv":15700.45}]}
{"op":"mcm","clk":"4234398008","pt":1631545180052,"mc":[{"id":"1.187560677","rc":[{"trd":[[1.35,7975.6]],"batl":[[0,1.35,851.09]],"ltp":1.35,"tv":15172.01,"id":11439844}],"tv":15845.56}]}
{"op":"mcm","clk":"4234398097","pt":1631545181293,"mc":[{"id":"1.187560677","rc":[{"trd":[[1.35,8381.2]],"batl":[[0,1.35,648.18]],"ltp":1.35,"tv":15577.6,"id":11439844}],"tv":16251.15}]}
{"op":"mcm","clk":"4234398198","pt":1631545182490,"mc":[{"id":"1.187560677","rc":[{"trd":[[1.35,8668.96]],"batl":[[0,1.35,504.23]],"ltp":1.35,"tv":15865.37,"id":11439844}],"tv":16538.92}]}
{"op":"mcm","clk":"4234398256","pt":1631545183180,"mc":[{"id":"1.187560677","rc":[{"trd":[[1.35,8758.55]],"batl":[[0,1.35,459.41]],"ltp":1.35,"tv":15954.96,"id":11439844}],"tv":16628.51}]}
{"op":"mcm","clk":"4234398339","pt":1631545184380,"mc":[{"id":"1.187560677","rc":[{"trd":[[1.35,8820.82]],"batl":[[0,1.35,428.28]],"ltp":1.35,"tv":16017.23,"id":11439844}],"tv":16690.78}]}
{"op":"mcm","clk":"4234398386","pt":1631545184907,"mc":[{"id":"1.187560677","rc":[{"trd":[[1.35,8883.1]],"batl":[[0,1.35,397.14]],"ltp":1.35,"tv":16079.51,"id":11439844}],"tv":16753.06}]}
{"op":"mcm","clk":"4234398515","pt":1631545186497,"mc":[{"id":"1.187560677","rc":[{"trd":[[1.35,8953.7]],"batl":[[0,1.35,361.82]],"ltp":1.35,"tv":16150.11,"id":11439844}],"tv":16823.66}]}
{"op":"mcm","clk":"4234398580","pt":1631545187364,"mc":[{"id":"1.187560677","rc":[{"trd":[[1.35,9016.02]],"batl":[[0,1.35,330.65],[1,1.52,0.53],[2,1.52,0]],"ltp":1.35,"tv":16212.43,"id":11439844}],"tv":16885.98}]}
{"op":"mcm","clk":"4234398727","pt":1631545189392,"mc":[{"id":"1.187560677","rc":[{"batb":[[0,2,85.16],[1,1.6,766.48],[2,1.3,5]],"ltp":3.85,"tv":673.54,"id":7588306},{"batb":[[1,1.18,3],[2,1.15,340.66]],"ltp":1.35,"tv":16212.43,"id":11439844}]}]}
{"op":"mcm","clk":"4234398873","pt":1631545191892,"mc":[{"id":"1.187560677","rc":[{"batb":[[0,1.27,97.55],[1,1.26,98.26],[2,1.18,3]],"ltp":1.35,"tv":16212.43,"id":11439844}]}]}
{"op":"mcm","clk":"4234399190","pt":1631545196705,"mc":[{"id":"1.187560677","rc":[{"batb":[[1,1.65,65.51],[2,1.6,766.48]],"ltp":3.85,"tv":673.54,"id":7588306},{"batb":[[1,1.18,3],[2,1.15,340.66]],"ltp":1.35,"tv":16212.43,"id":11439844}]}]}
{"op":"mcm","clk":"4234399212","pt":1631545197016,"mc":[{"id":"1.187560677","rc":[{"batb":[[1,1.65,131.02]],"ltp":3.85,"tv":673.54,"id":7588306},{"trd":[[1.35,9109.51]],"batl":[[0,1.35,283.88]],"ltp":1.35,"tv":16305.92,"id":11439844}],"tv":16979.47}]}
{"op":"mcm","clk":"4234399304","pt":1631545198321,"mc":[{"id":"1.187560677","rc":[{"trd":[[1.35,9247.31]],"batb":[[0,1.28,91.25],[1,1.27,97.55],[2,1.18,3]],"batl":[[0,1.35,214.94]],"ltp":1.35,"tv":16443.72,"id":11439844}],"tv":17117.27}]}
{"op":"mcm","clk":"4234399337","pt":1631545198950,"mc":[{"id":"1.187560677","rc":[{"trd":[[1.35,9340.31]],"batl":[[0,1.35,168.42]],"ltp":1.35,"tv":16536.72,"id":11439844}],"tv":17210.27}]}
{"op":"mcm","clk":"4234399453","pt":1631545200566,"mc":[{"id":"1.187560677","rc":[{"batb":[[0,1.65,131.02],[1,1.6,766.48],[2,1.3,5]],"ltp":3.85,"tv":673.54,"id":7588306},{"trd":[[1.35,9433.31]],"batl":[[0,1.35,121.89]],"ltp":1.35,"tv":16629.72,"id":11439844}],"tv":17303.26}]}
{"op":"mcm","clk":"4234399941","pt":1631545205464,"mc":[{"id":"1.187560677","rc":[{"trd":[[3.55,305.97],[3.65,55.49],[3.75,36.73],[3.85,99.45],[3.9,126.07],[3.95,15.91]],"batb":[[0,1.65,131.17],[1,1.6,767.39]],"ltp":3.85,"tv":673.11,"id":7588306},{"trd":[[1.15,33.16],[1.32,27.06],[1.33,33.16],[1.34,1951.08],[1.35,9612.93],[1.36,114.38],[1.37,419.16],[1.38,109.52],[1.39,3520.59],[1.4,727.39],[1.41,60.84],[1.42,189.29]],"batb":[[0,1.28,91.35],[1,1.27,97.44]],"batl":[[0,1.35,32.97]],"ltp":1.35,"tv":16815.41,"id":11439844}],"tv":17488.53}]}
{"op":"mcm","clk":"4234400228","pt":1631545208632,"mc":[{"id":"1.187560677","rc":[{"trd":[[1.35,9678.88]],"batb":[[0,1.35,1.33],[1,1.28,91.35]],"batl":[[0,1.52,0.53],[1,1.52,0]],"ltp":1.35,"tv":16881.36,"id":11439844}],"tv":17554.47}]}
{"op":"mcm","clk":"4234400310","pt":1631545209267,"mc":[{"id":"1.187560677","rc":[{"batb":[[0,1.35,71.03]],"ltp":1.35,"tv":16881.36,"id":11439844}]}]}
{"op":"mcm","clk":"4234400448","pt":1631545210540,"mc":[{"id":"1.187560677","rc":[{"batb":[[0,1.35,41.8]],"ltp":1.35,"tv":16881.36,"id":11439844}]}]}
{"op":"mcm","clk":"4234400489","pt":1631545210958,"mc":[{"id":"1.187560677","rc":[{"batb":[[0,1.35,40.46],[1,1.29,97.44],[2,1.28,91.35]],"ltp":1.35,"tv":16881.36,"id":11439844}]}]}
{"op":"mcm","clk":"4234400740","pt":1631545213733,"mc":[{"id":"1.187560677","rc":[{"batb":[[0,1.29,97.44],[1,1.28,91.35],[2,1.18,3]],"ltp":1.35,"tv":16881.36,"id":11439844}]}]}
{"op":"mcm","clk":"4234400868","pt":1631545215458,"mc":[{"id":"1.187560677","rc":[{"batb":[[1,1.18,3],[2,1.15,341.06]],"ltp":1.35,"tv":16881.36,"id":11439844}]}]}
{"op":"mcm","clk":"4234401177","pt":1631545219768,"mc":[{"id":"1.187560677","rc":[{"batb":[[0,1.18,3],[1,1.15,341.06],[2,1.12,60.16]],"ltp":1.35,"tv":16881.36,"id":11439844}]}]}
{"op":"mcm","clk":"4234401357","pt":1631545221955,"mc":[{"id":"1.187560677","rc":[{"batb":[[0,1.2,127.9],[1,1.18,3],[2,1.15,341.06]],"ltp":1.35,"tv":16881.36,"id":11439844}]}]}
{"op":"mcm","clk":"4234403346","pt":1631545246967,"mc":[{"id":"1.187560677","rc":[{"batb":[[0,1.3,283.94],[1,1.2,127.9],[2,1.18,3]],"ltp":1.35,"tv":16881.36,"id":11439844}]}]}
{"op":"mcm","clk":"4234410894","pt":1631545337651,"mc":[{"id":"1.187560677","rc":[{"batb":[[0,1.66,767.39],[1,1.65,131.17],[2,1.6,767.39]],"ltp":3.85,"tv":673.11,"id":7588306}]}]}
{"op":"mcm","clk":"4234411347","pt":1631545342993,"mc":[{"id":"1.187560677","rc":[{"batb":[[0,1.66,700.89]],"ltp":3.85,"tv":673.11,"id":7588306}]}]}
{"op":"mcm","clk":"4234413216","pt":1631545363989,"mc":[{"id":"1.187560677","rc":[{"batb":[[1,1.6,767.39],[2,1.3,5]],"ltp":3.85,"tv":673.11,"id":7588306}]}]}
{"op":"mcm","clk":"4234413325","pt":1631545365188,"mc":[{"id":"1.187560677","rc":[{"batb":[[0,1.68,24.73],[1,1.66,700.89],[2,1.6,767.39]],"ltp":3.85,"tv":673.11,"id":7588306}]}]}
{"op":"mcm","clk":"4234413485","pt":1631545367117,"mc":[{"id":"1.187560677","rc":[{"batb":[[0,1.7,131.17],[1,1.68,24.73],[2,1.66,700.89]],"ltp":3.85,"tv":673.11,"id":7588306}]}]}
{"op":"mcm","clk":"4234414115","pt":1631545373623,"mc":[{"id":"1.187560677","rc":[{"batb":[[2,1.6,767.39]],"ltp":3.85,"tv":673.11,"id":7588306},{"batb":[[2,1.15,341.06]],"ltp":1.35,"tv":16881.36,"id":11439844}]}]}
{"op":"mcm","clk":"4234414364","pt":1631545376691,"mc":[{"id":"1.187560677","rc":[{"batb":[[0,1.75,700.89],[1,1.7,131.17],[2,1.68,24.73]],"ltp":3.85,"tv":673.11,"id":7588306},{"batb":[[0,1.35,3],[1,1.3,283.94],[2,1.2,127.9]],"ltp":1.35,"tv":16881.36,"id":11439844}]}]}
{"op":"mcm","clk":"4234414860","pt":1631545382396,"mc":[{"id":"1.187560677","rc":[{"batb":[[1,1.68,24.73],[2,1.6,767.39]],"ltp":3.85,"tv":673.11,"id":7588306}]}]}
{"op":"mcm","clk":"4234415112","pt":1631545385529,"mc":[{"id":"1.187560677","rc":[{"batb":[[0,1.77,131.17],[1,1.75,700.89],[2,1.68,24.73]],"ltp":3.85,"tv":673.11,"id":7588306}]}]}
{"op":"mcm","clk":"4234415879","pt":1631545395222,"mc":[{"id":"1.187560677","rc":[{"batb":[[1,1.68,24.73],[2,1.6,767.39]],"ltp":3.85,"tv":673.11,"id":7588306}]}]}
{"op":"mcm","clk":"4234416113","pt":1631545398345,"mc":[{"id":"1.187560677","rc":[{"batb":[[0,1.79,700.89],[1,1.77,131.17],[2,1.68,24.73]],"ltp":3.85,"tv":673.11,"id":7588306}]}]}
{"op":"mcm","clk":"4234416213","pt":1631545399646,"mc":[{"id":"1.187560677","rc":[{"batb":[[0,1.8,29],[1,1.79,700.89],[2,1.77,131.17]],"ltp":3.85,"tv":673.11,"id":7588306}]}]}
{"op":"mcm","clk":"4234416517","pt":1631545403137,"mc":[{"id":"1.187560677","rc":[{"batb":[[2,1.68,24.73]],"ltp":3.85,"tv":673.11,"id":7588306}]}]}
{"op":"mcm","clk":"4234416774","pt":1631545406229,"mc":[{"id":"1.187560677","rc":[{"batb":[[0,1.82,131.17],[1,1.8,29],[2,1.79,700.89]],"ltp":3.85,"tv":673.11,"id":7588306}]}]}
{"op":"mcm","clk":"4234417277","pt":1631545411442,"mc":[{"id":"1.187560677","rc":[{"batl":[[0,1000,0.6]],"ltp":1.35,"tv":16881.36,"id":11439844}]}]}
{"op":"mcm","clk":"4234417307","pt":1631545411756,"mc":[{"id":"1.187560677","rc":[{"batl":[[0,1.52,0.53]],"ltp":1.35,"tv":16881.36,"id":11439844}]}]}
{"op":"mcm","clk":"4234417425","pt":1631545413052,"mc":[{"id":"1.187560677","rc":[{"batb":[[0,1.83,700.89],[1,1.82,131.17],[2,1.8,29]],"ltp":3.85,"tv":673.11,"id":7588306}]}]}
{"op":"mcm","clk":"4234417658","pt":1631545415672,"mc":[{"id":"1.187560677","rc":[{"batb":[[1,1.82,65.59]],"ltp":3.85,"tv":673.11,"id":7588306},{"batl":[[0,810,0.6]],"ltp":1.35,"tv":16881.36,"id":11439844}]}]}
{"op":"mcm","clk":"4234417668","pt":1631545415775,"mc":[{"id":"1.187560677","rc":[{"batb":[[1,1.8,29],[2,1.79,700.89]],"ltp":3.85,"tv":673.11,"id":7588306}]}]}
{"op":"mcm","clk":"4234417818","pt":1631545417656,"mc":[{"id":"1.187560677","rc":[{"batb":[[1,1.79,700.89],[2,1.68,24.73]],"ltp":3.85,"tv":673.11,"id":7588306}]}]}
{"op":"mcm","clk":"4234417923","pt":1631545418852,"mc":[{"id":"1.187560677","rc":[{"batb":[[0,1.85,131.17],[1,1.83,700.89],[2,1.79,700.89]],"ltp":3.85,"tv":673.11,"id":7588306}]}]}
{"op":"mcm","clk":"4234418083","pt":1631545420778,"mc":[{"id":"1.187560677","rc":[{"batb":[[0,1.97,29],[1,1.85,131.17],[2,1.83,700.89]],"ltp":3.85,"tv":673.11,"id":7588306}]}]}
{"op":"mcm","clk":"4234418487","pt":1631545425082,"mc":[{"id":"1.187560677","rc":[{"batb":[[2,1.68,24.73]],"ltp":3.85,"tv":673.11,"id":7588306}]}]}
{"op":"mcm","clk":"4234418772","pt":1631545428198,"mc":[{"id":"1.187560677","rc":[{"batb":[[0,2,700.89],[1,1.97,29],[2,1.9,700.89]],"ltp":3.85,"tv":673.11,"id":7588306}]}]}
{"op":"mcm","clk":"4234419200","pt":1631545432805,"mc":[{"id":"1.187560677","rc":[{"batl":[[0,820,0.67]],"ltp":1.35,"tv":16881.36,"id":11439844}]}]}
{"op":"mcm","clk":"4234419443","pt":1631545435682,"mc":[{"id":"1.187560677","rc":[{"batl":[[0,1.94,524.36],[1,820,0.14]],"ltp":1.35,"tv":16881.36,"id":11439844}]}]}
{"op":"mcm","clk":"4234419460","pt":1631545435888,"mc":[{"id":"1.187560677","rc":[{"batl":[[0,820,0.67],[1,820,0]],"ltp":1.35,"tv":16881.36,"id":11439844}]}]}
{"op":"mcm","clk":"4234419579","pt":1631545437560,"mc":[{"id":"1.187560677","rc":[{"batb":[[0,2.04,41],[1,2,700.89],[2,1.97,29]],"ltp":3.85,"tv":673.11,"id":7588306}]}]}
{"op":"mcm","clk":"4234419648","pt":1631545438293,"mc":[{"id":"1.187560677","rc":[{"batb":[[0,2.04,81.99]],"ltp":3.85,"tv":673.11,"id":7588306}]}]}
{"op":"mcm","clk":"4234419727","pt":1631545439017,"mc":[{"id":"1.187560677","rc":[{"batl":[[0,2.26,450.85],[1,820,0.14]],"ltp":1.35,"tv":16881.36,"id":11439844}]}]}
{"op":"mcm","clk":"4234420032","pt":1631545442606,"mc":[{"id":"1.187560677","rc":[{"batb":[[1,1.97,29],[2,1.9,700.89]],"ltp":3.85,"tv":673.11,"id":7588306}]}]}
{"op":"mcm","clk":"4234420169","pt":1631545443727,"mc":[{"id":"1.187560677","rc":[{"batb":[[1,1.9,700.89],[2,1.68,24.73]],"ltp":3.85,"tv":673.11,"id":7588306}]}]}
{"op":"mcm","clk":"4234420385","pt":1631545445727,"mc":[{"id":"1.187560677","rc":[{"batb":[[0,2.06,700.89],[1,2.04,81.99],[2,1.9,700.89]],"ltp":3.85,"tv":673.11,"id":7588306}]}]}
{"op":"mcm","clk":"4234420490","pt":1631545446904,"mc":[{"id":"1.187560677","rc":[{"batb":[[0,2.26,29],[1,2.06,700.89],[2,2.04,81.99]],"ltp":3.85,"tv":673.11,"id":7588306}]}]}
{"op":"mcm","clk":"4234420689","pt":1631545449399,"mc":[{"id":"1.187560677","rc":[{"batl":[[0,1.94,3.61]],"ltp":1.35,"tv":16881.36,"id":11439844}]}]}
{"op":"mcm","clk":"4234420935","pt":1631545452523,"mc":[{"id":"1.187560677","rc":[{"batl":[[0,1.86,546.64],[1,1.94,3.08],[2,820,0.14]],"ltp":1.35,"tv":16881.36,"id":11439844}]}]}
{"op":"mcm","clk":"4234421182","pt":1631545455533,"mc":[{"id":"1.187560677","rc":[{"batb":[[0,2.3,142.39],[1,2.26,29],[2,2.06,700.89]],"ltp":3.85,"tv":673.11,"id":7588306}]}]}
{"op":"mcm","clk":"4234421488","pt":1631545459639,"mc":[{"id":"1.187560677","rc":[{"batb":[[2,1.15,341.06]],"ltp":1.35,"tv":16881.36,"id":11439844}]}]}
{"op":"mcm","clk":"4234421642","pt":1631545461620,"mc":[{"id":"1.187560677","rc":[{"batl":[[0,1.84,870.24],[1,1.86,546.11],[2,1.94,3.08]],"ltp":1.35,"tv":16881.36,"id":11439844}]}]}
{"op":"mcm","clk":"4234422439","pt":1631545471358,"mc":[{"id":"1.187560677","rc":[{"batb":[[2,1.17,726.47]],"batl":[[1,1.94,3.08],[2,820,0.14]],"ltp":1.35,"tv":16881.36,"id":11439844}]}]}
{"op":"mcm","clk":"4234422707","pt":1631545474538,"mc":[{"id":"1.187560677","rc":[{"batl":[[0,1.83,555.5],[1,1.84,869.71],[2,1.94,3.08]],"ltp":1.35,"tv":16881.36,"id":11439844}]}]}
{"op":"mcm","clk":"4234423321","pt":1631545483684,"mc":[{"id":"1.187560677","rc":[{"batb":[[1,2.06,700.89],[2,1.9,700.89]],"ltp":3.85,"tv":673.11,"id":7588306}]}]}
{"op":"mcm","clk":"4234423545","pt":1631545486873,"mc":[{"id":"1.187560677","rc":[{"batb":[[0,2.32,29],[1,2.3,142.39],[2,2.06,700.89]],"ltp":3.85,"tv":673.11,"id":7588306}]}]}
{"op":"mcm","clk":"4234424151","pt":1631545495390,"mc":[{"id":"1.187560677","rc":[{"batb":[[1,2.06,700.89],[2,1.9,700.89]],"ltp":3.85,"tv":673.11,"id":7588306},{"batl":[[1,1.94,3.08],[2,820,0.14]],"ltp":1.35,"tv":16881.36,"id":11439844}]}]}
{"op":"mcm","clk":"4234424186","pt":1631545496067,"mc":[{"id":"1.187560677","rc":[{"batl":[[0,1.94,3.61],[1,820,0.14],[2,820,0]],"ltp":1.35,"tv":16881.36,"id":11439844}]}]}
{"op":"mcm","clk":"4234424334","pt":1631545498494,"mc":[{"id":"1.187560677","rc":[{"batb":[[0,2.36,142.39],[1,2.32,29],[2,2.06,700.89]],"ltp":3.85,"tv":673.11,"id":7588306},{"batl":[[0,1.82,870.24],[1,1.94,3.08],[2,820,0.14]],"ltp":1.35,"tv":16881.36,"id":11439844}]}]}
{"op":"mcm","clk":"4234424754","pt":1631545504002,"mc":[{"id":"1.187560677","rc":[{"batb":[[1,1.17,726.47],[2,1.15,341.06]],"ltp":1.35,"tv":16881.36,"id":11439844}]}]}
{"op":"mcm","clk":"4234424850","pt":1631545504788,"mc":[{"id":"1.187560677","rc":[{"batb":[[1,2.06,700.89],[2,1.9,700.89]],"ltp":3.85,"tv":673.11,"id":7588306}]}]}
{"op":"mcm","clk":"4234425106","pt":1631545507923,"mc":[{"id":"1.187560677","rc":[{"batb":[[0,2.36,171.39]],"ltp":3.85,"tv":673.11,"id":7588306}]}]}
{"op":"mcm","clk":"4234425507","pt":1631545512820,"mc":[{"id":"1.187560677","rc":[{"batb":[[0,2.36,142.39]],"ltp":3.85,"tv":673.11,"id":7588306}]}]}
{"op":"mcm","clk":"4234425733","pt":1631545516003,"mc":[{"id":"1.187560677","rc":[{"batb":[[0,2.38,29],[1,2.36,142.39],[2,2.06,700.89]],"ltp":3.85,"tv":673.11,"id":7588306}]}]}
{"op":"mcm","clk":"4234425957","pt":1631545518716,"mc":[{"id":"1.187560677","rc":[{"batb":[[1,2.06,700.89],[2,1.9,700.89]],"ltp":3.85,"tv":673.11,"id":7588306}]}]}
{"op":"mcm","clk":"4234426157","pt":1631545521308,"mc":[{"id":"1.187560677","rc":[{"trd":[[1.35,9684.88]],"batb":[[0,1.17,726.47],[1,1.15,341.06],[2,1.07,365.42]],"batl":[[0,1.35,2],[1,1.82,870.24],[2,1.94,3.08]],"ltp":1.35,"tv":16887.36,"id":11439844}],"tv":17560.47}]}
{"op":"mcm","clk":"4234426210","pt":1631545521818,"mc":[{"id":"1.187560677","rc":[{"batb":[[0,2.4,142.39],[1,2.38,29],[2,2.06,700.89]],"ltp":3.85,"tv":673.11,"id":7588306}]}]}
{"op":"mcm","clk":"4234426954","pt":1631545532344,"mc":[{"id":"1.187560677","rc":[{"batb":[[0,1.18,142.11],[1,1.17,726.47]],"ltp":1.35,"tv":16887.36,"id":11439844}]}]}
{"op":"mcm","clk":"4234427655","pt":1631545541224,"mc":[{"id":"1.187560677","rc":[{"batb":[[0,1.19,179.91],[1,1.18,142.11],[2,1.17,726.47]],"ltp":1.35,"tv":16887.36,"id":11439844}]}]}
{"op":"mcm","clk":"4234427815","pt":1631545543736,"mc":[{"id":"1.187560677","rc":[{"batb":[[1,2.06,700.89],[2,1.9,700.89]],"ltp":3.85,"tv":673.11,"id":7588306}]}]}
{"op":"mcm","clk":"4234428298","pt":1631545550261,"mc":[{"id":"1.187560677","rc":[{"batb":[[0,1.2,127.9],[1,1.19,179.91]],"ltp":1.35,"tv":16887.36,"id":11439844}]}]}
{"op":"mcm","clk":"4234428960","pt":1631545559967,"mc":[{"id":"1.187560677","rc":[{"batb":[[1,1.17,726.47],[2,1.07,365.42]],"ltp":1.35,"tv":16887.36,"id":11439844}]}]}
{"op":"mcm","clk":"4234429155","pt":1631545562636,"mc":[{"id":"1.187560677","rc":[{"batb":[[0,1.21,29],[1,1.2,127.9],[2,1.17,726.47]],"ltp":1.35,"tv":16887.36,"id":11439844}]}]}
{"op":"mcm","clk":"4234429182","pt":1631545563054,"mc":[{"id":"1.187560677","rc":[{"batb":[[0,1.21,208.91]],"ltp":1.35,"tv":16887.36,"id":11439844}]}]}
{"op":"mcm","clk":"4234429562","pt":1631545569260,"mc":[{"id":"1.187560677","rc":[{"batb":[[0,1.22,116.27],[1,1.21,208.91]],"ltp":1.35,"tv":16887.36,"id":11439844}]}]}
{"op":"mcm","clk":"4234429593","pt":1631545569776,"mc":[{"id":"1.187560677","rc":[{"batb":[[1,1.21,179.91]],"ltp":1.35,"tv":16887.36,"id":11439844}]}]}
{"op":"mcm","clk":"4234429810","pt":1631545572844,"mc":[{"id":"1.187560677","rc":[{"batb":[[0,1.22,145.27]],"ltp":1.35,"tv":16887.36,"id":11439844}]}]}
{"op":"mcm","clk":"4234430127","pt":1631545577866,"mc":[{"id":"1.187560677","rc":[{"batb":[[0,1.22,116.27]],"ltp":1.35,"tv":16887.36,"id":11439844}]}]}
{"op":"mcm","clk":"4234430316","pt":1631545581081,"mc":[{"id":"1.187560677","rc":[{"batb":[[0,1.25,29],[1,1.22,116.27],[2,1.21,179.91]],"ltp":1.35,"tv":16887.36,"id":11439844}]}]}
{"op":"mcm","clk":"4234430887","pt":1631545589364,"mc":[{"id":"1.187560677","rc":[{"batb":[[0,1.26,32.79],[1,1.25,29],[2,1.22,116.27]],"ltp":1.35,"tv":16887.36,"id":11439844}]}]}
{"op":"mcm","clk":"4234430967","pt":1631545590606,"mc":[{"id":"1.187560677","rc":[{"batb":[[0,1.26,182.86]],"ltp":1.35,"tv":16887.36,"id":11439844}]}]}
{"op":"mcm","clk":"4234431263","pt":1631545594876,"mc":[{"id":"1.187560677","rc":[{"batb":[[0,1.27,150.07],[1,1.26,182.86],[2,1.25,29]],"ltp":1.35,"tv":16887.36,"id":11439844}]}]}
{"op":"mcm","clk":"4234431543","pt":1631545599821,"mc":[{"id":"1.187560677","rc":[{"batb":[[1,1.26,150.07]],"ltp":1.35,"tv":16887.36,"id":11439844}]}]}
{"op":"mcm","clk":"4234432104","pt":1631545609103,"mc":[{"id":"1.187560677","rc":[{"batb":[[0,1.3,283.94],[1,1.27,150.07],[2,1.26,150.07]],"ltp":1.35,"tv":16887.36,"id":11439844}]}]}
{"op":"mcm","clk":"4234432498","pt":1631545615553,"mc":[{"id":"1.187560677","rc":[{"batb":[[0,1.31,150.07],[1,1.3,283.94],[2,1.25,29]],"ltp":1.35,"tv":16887.36,"id":11439844}]}]}
{"op":"mcm","clk":"4234433015","pt":1631545622714,"mc":[{"id":"1.187560677","rc":[{"batb":[[2,1.22,116.27]],"ltp":1.35,"tv":16887.36,"id":11439844}]}]}
{"op":"mcm","clk":"4234433216","pt":1631545625524,"mc":[{"id":"1.187560677","rc":[{"batb":[[1,1.22,116.27],[2,1.15,726.47]],"ltp":1.35,"tv":16887.36,"id":11439844}]}]}
{"op":"mcm","clk":"4234433249","pt":1631545625939,"mc":[{"id":"1.187560677","rc":[{"batb":[[0,1.32,29],[1,1.31,150.07],[2,1.22,116.27]],"ltp":1.35,"tv":16887.36,"id":11439844}]}]}
{"op":"mcm","clk":"4234433438","pt":1631545628638,"mc":[{"id":"1.187560677","rc":[{"batb":[[0,1.32,312.93]],"ltp":1.35,"tv":16887.36,"id":11439844}]}]}
{"op":"mcm","clk":"4234433643","pt":1631545632164,"mc":[{"id":"1.187560677","rc":[{"batb":[[2,1.15,726.47]],"ltp":1.35,"tv":16887.36,"id":11439844}]}]}
{"op":"mcm","clk":"4234434249","pt":1631545640673,"mc":[{"id":"1.187560677","rc":[{"trd":[[1.35,9688.88]],"batb":[[0,1.35,54.27],[1,1.32,312.93],[2,1.31,150.07]],"batl":[[0,1.82,870.24],[1,1.94,3.08],[2,820,0.14]],"ltp":1.35,"tv":16891.36,"id":11439844}],"tv":17564.48}]}
{"op":"mcm","clk":"4234434321","pt":1631545641661,"mc":[{"id":"1.187560677","rc":[{"batb":[[1,1.33,56.28],[2,1.32,312.93]],"ltp":1.35,"tv":16891.36,"id":11439844}]}]}
{"op":"mcm","clk":"4234434348","pt":1631545641969,"mc":[{"id":"1.187560677","rc":[{"trd":[[2.4,49.46],[2.92,0.27]],"batb":[[0,2.4,117.67]],"ltp":2.4,"tv":722.84,"id":7588306},{"trd":[[1.52,0.53]],"batl":[[0,1.82,869.71]],"ltp":1.52,"tv":16891.89,"id":11439844}],"tv":17614.73}]}
{"op":"mcm","clk":"4234434786","pt":1631545648641,"mc":[{"id":"1.187560677","rc":[{"batl":[[0,1.52,56.28],[1,1.82,869.71],[2,1.94,3.08]],"ltp":1.52,"tv":16891.89,"id":11439844}]}]}
{"op":"mcm","clk":"4234435349","pt":1631545657788,"mc":[{"id":"1.187560677","rc":[{"batb":[[2,1.32,283.94]],"ltp":1.52,"tv":16891.89,"id":11439844}]}]}
{"op":"mcm","clk":"4234437650","pt":1631545692391,"mc":[{"id":"1.187560677","rc":[{"batb":[[0,1.4,34.62],[1,1.35,54.27],[2,1.33,56.28]],"ltp":1.52,"tv":16891.89,"id":11439844}]}]}
{"op":"mcm","clk":"4234448127","pt":1631545854018,"mc":[{"id":"1.187560677","rc":[{"trd":[[1.4,795.61]],"batb":[[0,1.35,54.78],[1,1.33,56.28],[2,1.31,150.07]],"ltp":1.4,"tv":16960.1,"id":11439844}],"tv":17682.95}]}
{"op":"mcm","clk":"4234448466","pt":1631545859489,"mc":[{"id":"1.187560677","rc":[{"batb":[[0,1.15,1084.9],[1,1.12,767.39],[2,1.11,271.16]],"batl":[[0,1.82,869.71],[1,1.94,3.08],[2,1.94,0]],"ltp":1.4,"tv":16960.1,"id":11439844}]}]}
{"op":"mcm","clk":"4234449566","pt":1631545877033,"mc":[{"id":"1.187560677","rc":[{"batb":[[0,1.16,107.09],[1,1.15,1084.39],[2,1.12,767.39]],"ltp":1.4,"tv":16960.1,"id":11439844}]}]}
{"op":"mcm","clk":"4234449806","pt":1631545880724,"mc":[{"id":"1.187560677","rc":[{"batb":[[0,1.17,87.51],[1,1.16,106.58],[2,1.15,1084.39]],"ltp":1.4,"tv":16960.1,"id":11439844}]}]}
{"op":"mcm","clk":"4234450686","pt":1631545893842,"mc":[{"id":"1.187560677","rc":[{"batb":[[1,1.15,1084.39],[2,1.12,767.39]],"ltp":1.4,"tv":16960.1,"id":11439844}]}]}
{"op":"mcm","clk":"4234450907","pt":1631545896920,"mc":[{"id":"1.187560677","rc":[{"batb":[[0,1.18,107.09],[1,1.17,87],[2,1.15,1084.39]],"ltp":1.4,"tv":16960.1,"id":11439844}]}]}
{"op":"mcm","clk":"4234451444","pt":1631545904758,"mc":[{"id":"1.187560677","rc":[{"batb":[[1,1.15,1084.39],[2,1.12,767.39]],"ltp":1.4,"tv":16960.1,"id":11439844}]}]}
{"op":"mcm","clk":"4234451682","pt":1631545907930,"mc":[{"id":"1.187560677","rc":[{"batb":[[0,1.2,87.51],[1,1.18,106.58],[2,1.15,1084.39]],"ltp":1.4,"tv":16960.1,"id":11439844}]}]}
{"op":"mcm","clk":"4234451803","pt":1631545909547,"mc":[{"id":"1.187560677","rc":[{"batb":[[0,3.05,279.48],[1,2.4,117.67],[2,2.06,700.89]],"batl":[[0,3.4,213.48]],"ltp":2.4,"tv":722.84,"id":7588306},{"batb":[[0,1.44,11.74],[1,1.2,87.51],[2,1.18,106.58]],"batl":[[0,1.46,13.78],[1,1.82,869.71],[2,1.94,3.08]],"ltp":1.4,"tv":16960.1,"id":11439844}]}]}
{"op":"mcm","clk":"4234451889","pt":1631545911055,"mc":[{"id":"1.187560677","rc":[{"batb":[[2,1.15,1084.39]],"ltp":1.4,"tv":16960.1,"id":11439844}]}]}
{"op":"mcm","clk":"4234452056","pt":1631545913237,"mc":[{"id":"1.187560677","rc":[{"trd":[[1.46,27.28]],"batl":[[0,1.82,869.85],[1,1.94,3.08],[2,1.94,0]],"ltp":1.46,"tv":16987.38,"id":11439844}],"tv":17710.23}]}
{"op":"mcm","clk":"4234452117","pt":1631545914172,"mc":[{"id":"1.187560677","rc":[{"batb":[[1,1.21,107.09],[2,1.2,87]],"ltp":1.46,"tv":16987.38,"id":11439844}]}]}
{"op":"mcm","clk":"4234452481","pt":1631545919550,"mc":[{"id":"1.187560677","rc":[{"batl":[[0,1.81,394.11],[1,1.82,869.71],[2,1.94,3.08]],"ltp":1.46,"tv":16987.38,"id":11439844}]}]}
{"op":"mcm","clk":"4234452495","pt":1631545919753,"mc":[{"id":"1.187560677","rc":[{"batl":[[0,1.82,869.85],[1,1.94,3.08],[2,1.94,0]],"ltp":1.46,"tv":16987.38,"id":11439844}]}]}
{"op":"mcm","clk":"4234452788","pt":1631545923484,"mc":[{"id":"1.187560677","rc":[{"batb":[[0,1.21,107.09],[1,1.2,87],[2,1.15,1084.39]],"batl":[[0,1.82,869.71]],"ltp":1.46,"tv":16987.38,"id":11439844}]}]}
{"op":"mcm","clk":"4234452975","pt":1631545925579,"mc":[{"id":"1.187560677","rc":[{"batl":[[0,1.44,1.88],[1,1.82,869.71],[2,1.94,3.08]],"ltp":1.46,"tv":16987.38,"id":11439844}]}]}
{"op":"mcm","clk":"4234453019","pt":1631545926358,"mc":[{"id":"1.187560677","rc":[{"trd":[[1.44,3.76]],"batb":[[0,1.45,10.56],[1,1.21,107.09],[2,1.2,87]],"batl":[[0,1.47,12.18]],"ltp":1.44,"tv":16991.14,"id":11439844}],"tv":17713.98}]}
{"op":"mcm","clk":"4234453120","pt":1631545927449,"mc":[{"id":"1.187560677","rc":[{"batb":[[0,2.4,117.67],[1,2.06,700.89],[2,1.9,700.89]],"ltp":2.4,"tv":722.84,"id":7588306},{"batb":[[0,1.21,107.09],[1,1.2,87],[2,1.15,1084.39]],"batl":[[0,1.48,56.28]],"ltp":1.44,"tv":16991.14,"id":11439844}]}]}
{"op":"mcm","clk":"4234453429","pt":1631545930681,"mc":[{"id":"1.187560677","rc":[{"trd":[[1.48,23.87]],"batl":[[0,1.48,44.34]],"ltp":1.48,"tv":17015.01,"id":11439844}],"tv":17737.86}]}
{"op":"mcm","clk":"4234454624","pt":1631545949487,"mc":[{"id":"1.187560677","rc":[{"batl":[[1,1.55,56.28],[2,1.82,869.71]],"ltp":1.48,"tv":17015.01,"id":11439844}]}]}
{"op":"mcm","clk":"4234454685","pt":1631545950522,"mc":[{"id":"1.187560677","rc":[{"batl":[[2,1.67,56.28]],"ltp":1.48,"tv":17015.01,"id":11439844}]}]}
{"op":"mcm","clk":"4234454721","pt":1631545951214,"mc":[{"id":"1.187560677","rc":[{"batl":[[2,1.67,112.55]],"ltp":1.48,"tv":17015.01,"id":11439844}]}]}
{"op":"mcm","clk":"4234454805","pt":1631545952626,"mc":[{"id":"1.187560677","rc":[{"batl":[[2,1.67,168.83]],"ltp":1.48,"tv":17015.01,"id":11439844}]}]}
{"op":"mcm","clk":"4234455030","pt":1631545956330,"mc":[{"id":"1.187560677","rc":[{"batb":[[0,1.22,709.92],[1,1.21,106.58],[2,1.2,87]],"ltp":1.48,"tv":17015.01,"id":11439844}]}]}
{"op":"mcm","clk":"4234455254","pt":1631545960536,"mc":[{"id":"1.187560677","rc":[{"batb":[[0,3.35,5.17],[1,3.3,190.58],[2,2.4,117.67]],"batl":[[0,3.5,4.86]],"ltp":2.4,"tv":722.84,"id":7588306},{"batb":[[0,1.4,12.67],[1,1.38,560.99],[2,1.22,709.41]],"ltp":1.48,"tv":17015.01,"id":11439844}]}]}
{"op":"mcm","clk":"4234455302","pt":1631545961217,"mc":[{"id":"1.187560677","rc":[{"trd":[[3.5,29.86]],"batb":[[2,2.06,700.89]],"ltp":3.5,"tv":727.7,"id":7588306},{"trd":[[1.38,222.08],[1.4,833.1]],"batb":[[0,1.38,504.71],[1,1.22,709.41],[2,1.21,106.58]],"batl":[[0,1.39,31.45],[1,1.41,56.28],[2,1.48,44.34]],"ltp":1.38,"tv":17165.06,"id":11439844}],"tv":17892.77}]}
{"op":"mcm","clk":"4234455498","pt":1631545964645,"mc":[{"id":"1.187560677","rc":[{"batb":[[2,2.5,117.67]],"ltp":3.5,"tv":727.7,"id":7588306},{"trd":[[1.39,3581.98]],"batl":[[0,1.41,57.03],[1,1.48,44.34],[2,1.55,56.28]],"ltp":1.39,"tv":17226.45,"id":11439844}],"tv":17954.16}]}
{"op":"mcm","clk":"4234455508","pt":1631545964813,"mc":[{"id":"1.187560677","rc":[{"batb":[[1,1.23,87],[2,1.22,709.41]],"ltp":1.39,"tv":17226.45,"id":11439844}]}]}
{"op":"mcm","clk":"4234455644","pt":1631545967635,"mc":[{"id":"1.187560677","rc":[{"batl":[[0,3.9,2.95]],"ltp":3.5,"tv":727.7,"id":7588306},{"batl":[[1,1.48,96.33],[2,1.51,51.5]],"ltp":1.39,"tv":17226.45,"id":11439844}]}]}
{"op":"mcm","clk":"4234455699","pt":1631545968529,"mc":[{"id":"1.187560677","rc":[{"batl":[[0,3.75,2.94],[1,3.9,2.95]],"ltp":3.5,"tv":727.7,"id":7588306}]}]}
{"op":"mcm","clk":"4234455780","pt":1631545969619,"mc":[{"id":"1.187560677","rc":[{"batl":[[2,14.5,2.6]],"ltp":3.5,"tv":727.7,"id":7588306}]}]}
{"op":"mcm","clk":"4234455812","pt":1631545970236,"mc":[{"id":"1.187560677","rc":[{"batl":[[2,14.5,0]],"ltp":3.5,"tv":727.7,"id":7588306}]}]}
{"op":"mcm","clk":"4234455855","pt":1631545971120,"mc":[{"id":"1.187560677","rc":[{"batb":[[0,3.3,190.58],[1,2.5,117.67],[2,2.06,700.89]],"ltp":3.5,"tv":727.7,"id":7588306}]}]}
{"op":"mcm","clk":"4234456084","pt":1631545974551,"mc":[{"id":"1.187560677","rc":[{"trd":[[3.55,306.27]],"batl":[[0,3.55,4.41],[1,3.75,2.94],[2,3.9,2.95]],"ltp":3.55,"tv":728.0,"id":7588306},{"trd":[[1.39,3582.74]],"batl":[[0,1.41,70.94]],"ltp":1.39,"tv":17227.21,"id":11439844}],"tv":17955.22}]}
{"op":"mcm","clk":"4234456251","pt":1631545977161,"mc":[{"id":"1.187560677","rc":[{"trd":[[1.41,122.23]],"batl":[[0,1.41,40.24]],"ltp":1.41,"tv":17288.6,"id":11439844}],"tv":18016.61}]}
{"op":"mcm","clk":"4234456628","pt":1631545982645,"mc":[{"id":"1.187560677","rc":[{"batb":[[0,2.5,117.67],[1,2.06,700.89],[2,2,11.93]],"batl":[[0,3.75,2.94],[1,3.9,2.95],[2,3.9,0]],"ltp":3.55,"tv":728.0,"id":7588306},{"batb":[[0,1.23,87],[1,1.22,709.41],[2,1.15,1084.39]],"batl":[[0,1.41,25.58]],"ltp":1.41,"tv":17288.6,"id":11439844}]}]}
{"op":"mcm","clk":"4234456665","pt":1631545983216,"mc":[{"id":"1.187560677","rc":[{"batl":[[1,3.9,0]],"ltp":3.55,"tv":728.0,"id":7588306},{"batb":[[1,1.15,1084.39],[2,1.12,767.39]],"ltp":1.41,"tv":17288.6,"id":11439844}]}]}
{"op":"mcm","clk":"4234456811","pt":1631545985649,"mc":[{"id":"1.187560677","rc":[{"batb":[[0,3.05,4.29],[1,2.96,4.38],[2,2.5,117.67]],"ltp":3.55,"tv":728.0,"id":7588306},{"batb":[[0,1.37,65.77],[1,1.23,87],[2,1.15,1084.39]],"ltp":1.41,"tv":17288.6,"id":11439844}]}]}
{"op":"mcm","clk":"4234456867","pt":1631545986339,"mc":[{"id":"1.187560677","rc":[{"batb":[[1,1.24,709.41],[2,1.23,87]],"ltp":1.41,"tv":17288.6,"id":11439844}]}]}
{"op":"mcm","clk":"4234457966","pt":1631546003076,"mc":[{"id":"1.187560677","rc":[{"trd":[[3.75,39.67],[3.85,119.18]],"batb":[[0,3.5,89.34],[1,3.05,4.29],[2,2.96,4.38]],"batl":[[0,3.85,177.35]],"ltp":3.85,"tv":750.67,"id":7588306},{"trd":[[1.35,9745.15],[1.36,155.89],[1.37,550.7]],"batb":[[0,1.24,709.41],[1,1.23,87],[2,1.15,1084.39]],"batl":[[0,1.36,21.97],[1,1.38,16.53],[2,1.4,223.36]],"ltp":1.35,"tv":17517.93,"id":11439844}],"tv":18268.6}]}
{"op":"mcm","clk":"4234458442","pt":1631546009546,"mc":[{"id":"1.187560677","rc":[{"batb":[[1,3.35,3.87],[2,3.25,3.45]],"batl":[[1,3.9,3.15],[2,3.95,2.9]],"ltp":3.85,"tv":750.67,"id":7588306},{"batb":[[0,1.35,76.27],[1,1.34,85.22],[2,1.24,709.41]],"ltp":1.35,"tv":17517.93,"id":11439844}]}]}
{"op":"mcm","clk":"4234458495","pt":1631546010128,"mc":[{"id":"1.187560677","rc":[{"batb":[[2,1.3,320.69]],"ltp":1.35,"tv":17517.93,"id":11439844}]}]}
{"op":"mcm","clk":"4234458685","pt":1631546013222,"mc":[{"id":"1.187560677","rc":[{"batl":[[1,1.4,223.36],[2,1.41,25.58]],"ltp":1.35,"tv":17517.93,"id":11439844}]}]}
{"op":"mcm","clk":"4234458882","pt":1631546016528,"mc":[{"id":"1.187560677","rc":[{"batb":[[0,3.35,3.87],[1,3.25,3.45],[2,3.05,4.29]],"batl":[[0,3.9,3.15],[1,3.95,2.9],[2,3.95,0]],"ltp":3.85,"tv":750.67,"id":7588306},{"batl":[[1,1.41,25.58],[2,1.42,53.75]],"ltp":1.35,"tv":17517.93,"id":11439844}]}]}
{"op":"mcm","clk":"4234458896","pt":1631546016843,"mc":[{"id":"1.187560677","rc":[{"batb":[[0,3.25,3.45],[1,2.5,117.67],[2,2.06,700.89]],"batl":[[0,3.95,2.9],[1,3.95,0]],"ltp":3.85,"tv":750.67,"id":7588306},{"batb":[[0,1.34,85.22],[1,1.3,320.69],[2,1.26,112.55]],"batl":[[2,1.44,57.08]],"ltp":1.35,"tv":17517.93,"id":11439844}]}]}
{"op":"mcm","clk":"4234459320","pt":1631546023551,"mc":[{"id":"1.187560677","rc":[{"batb":[[0,3.35,4.07],[1,3.25,3.45],[2,2.5,117.67]],"batl":[[0,3.9,2.75],[1,3.95,2.9]],"ltp":3.85,"tv":750.67,"id":7588306},{"batb":[[0,1.35,71.07],[1,1.34,85.22],[2,1.3,320.69]],"batl":[[2,1.42,61.75]],"ltp":1.35,"tv":17517.93,"id":11439844}]}]}
{"op":"mcm","clk":"4234459331","pt":1631546023759,"mc":[{"id":"1.187560677","rc":[{"batb":[[0,3.25,3.45],[1,2.5,117.67],[2,2.06,700.89]],"batl":[[0,3.95,2.9],[1,3.95,0]],"ltp":3.85,"tv":750.67,"id":7588306},{"batb":[[0,1.34,85.22],[1,1.3,320.69],[2,1.26,112.55]],"batl":[[2,1.44,57.08]],"ltp":1.35,"tv":17517.93,"id":11439844}]}]}
{"op":"mcm","clk":"4234460005","pt":1631546030632,"mc":[{"id":"1.187560677","rc":[{"batb":[[0,3.35,3.87],[1,3.25,3.45],[2,2.5,117.67]],"batl":[[0,3.9,2.75],[1,3.95,2.9]],"ltp":3.85,"tv":750.67,"id":7588306},{"batb":[[0,1.35,82.27],[1,1.34,85.22],[2,1.3,320.69]],"batl":[[2,1.42,54.25]],"ltp":1.35,"tv":17517.93,"id":11439844}]}]}
{"op":"mcm","clk":"4234460129","pt":1631546031448,"mc":[{"id":"1.187560677","rc":[{"batb":[[0,3.25,3.45],[1,2.5,117.67],[2,2.06,700.89]],"batl":[[0,3.95,2.9],[1,3.95,0]],"ltp":3.85,"tv":750.67,"id":7588306},{"batb":[[0,1.34,85.22],[1,1.3,320.69],[2,1.26,112.55]],"batl":[[0,1.44,57.08],[1,1.48,44.34],[2,1.55,56.28]],"ltp":1.35,"tv":17517.93,"id":11439844}]}]}
{"op":"mcm","clk":"4234460588","pt":1631546034238,"mc":[{"id":"1.187560677","rc":[{"batl":[[0,3.6,11.12],[1,3.95,2.9]],"ltp":3.85,"tv":750.67,"id":7588306},{"batb":[[0,1.39,12.08],[1,1.38,189.29],[2,1.37,189.29]],"batl":[[0,1.41,18.23],[1,1.44,479.84],[2,1.48,44.34]],"ltp":1.35,"tv":17517.93,"id":11439844}]}]}
{"op":"mcm","clk":"4234461463","pt":1631546040508,"mc":[{"id":"1.187560677","rc":[{"batb":[[1,3.15,3.63],[2,2.5,117.67]],"batl":[[1,3.8,3.02],[2,3.95,2.9]],"ltp":3.85,"tv":750.67,"id":7588306},{"batl":[[2,1.46,55.75]],"ltp":1.35,"tv":17517.93,"id":11439844}]}]}
{"op":"mcm","clk":"4234462050","pt":1631546046510,"mc":[{"id":"1.187560677","rc":[{"batl":[[0,3.8,3.02],[1,3.95,2.9],[2,3.95,0]],"ltp":3.85,"tv":750.67,"id":7588306},{"batb":[[0,1.38,189.29],[1,1.37,189.29],[2,1.36,258.72]],"batl":[[0,1.44,57.08],[1,1.46,55.75],[2,1.48,44.34]],"ltp":1.35,"tv":17517.93,"id":11439844}]}]}
{"op":"mcm","clk":"4234462075","pt":1631546046782,"mc":[{"id":"1.187560677","rc":[{"batb":[[0,3.15,3.63],[1,2.5,117.67],[2,2.06,700.89]],"ltp":3.85,"tv":750.67,"id":7588306},{"batl":[[0,1.46,55.75],[1,1.48,44.34],[2,1.55,56.28]],"ltp":1.35,"tv":17517.93,"id":11439844}]}]}
{"op":"mcm","clk":"4234462770","pt":1631546053709,"mc":[{"id":"1.187560677","rc":[{"batb":[[0,3.35,18.67],[1,3.25,4.21],[2,3.15,3.63]],"batl":[[0,3.5,18.45],[1,3.8,3.02],[2,3.95,2.9]],"ltp":3.85,"tv":750.67,"id":7588306},{"batl":[[0,1.42,20.25],[1,1.44,55.58],[2,1.46,55.75]],"ltp":1.35,"tv":17517.93,"id":11439844}]}]}
{"op":"mcm","clk":"4234462789","pt":1631546053921,"mc":[{"id":"1.187560677","rc":[{"batb":[[0,3.15,3.63],[1,2.5,117.67],[2,2.06,700.89]],"batl":[[0,3.8,3.02],[1,3.95,2.9],[2,3.95,0]],"ltp":3.85,"tv":750.67,"id":7588306},{"batl":[[0,1.46,55.75],[1,1.48,44.34],[2,1.55,56.28]],"ltp":1.35,"tv":17517.93,"id":11439844}]}]}
{"op":"mcm","clk":"4234465167","pt":1631546064629,"mc":[{"id":"1.187560677","rc":[{"batb":[[0,3.25,3.77],[1,3.15,3.63],[2,2.5,117.67]],"ltp":3.85,"tv":750.67,"id":7588306},{"batl":[[0,1.44,60.33],[1,1.46,55.75],[2,1.48,44.34]],"ltp":1.35,"tv":17517.93,"id":11439844}]}]}
{"op":"mcm","clk":"4234465228","pt":1631546064845,"mc":[{"id":"1.187560677","rc":[{"batb":[[0,3.15,3.63],[1,2.5,117.67],[2,2.06,700.89]],"ltp":3.85,"tv":750.67,"id":7588306},{"batl":[[0,1.46,55.75],[1,1.48,44.34],[2,1.55,56.28]],"ltp":1.35,"tv":17517.93,"id":11439844}]}]}
{"op":"mcm","clk":"4234465725","pt":1631546070448,"mc":[{"id":"1.187560677","rc":[{"batl":[[1,3.95,0]],"ltp":3.85,"tv":750.67,"id":7588306},{"batl":[[0,1.48,44.34],[1,1.55,56.28],[2,1.67,168.83]],"ltp":1.35,"tv":17517.93,"id":11439844}]}]}
{"op":"mcm","clk":"4234465794","pt":1631546071541,"mc":[{"id":"1.187560677","rc":[{"batb":[[0,3.25,3.65],[1,3.15,3.63],[2,2.5,117.67]],"ltp":3.85,"tv":750.67,"id":7588306},{"batb":[[0,1.36,69.43],[1,1.3,320.69],[2,1.26,112.55]],"batl":[[0,1.44,54.83],[1,1.48,44.34],[2,1.55,56.28]],"ltp":1.35,"tv":17517.93,"id":11439844}]}]}
{"op":"mcm","clk":"4234465807","pt":1631546071749,"mc":[{"id":"1.187560677","rc":[{"batb":[[0,3.15,3.63],[1,2.5,117.67],[2,2.06,700.89]],"ltp":3.85,"tv":750.67,"id":7588306},{"batl":[[0,1.48,44.34],[1,1.55,56.28],[2,1.67,168.83]],"ltp":1.35,"tv":17517.93,"id":11439844}]}]}
{"op":"mcm","clk":"4234465917","pt":1631546073420,"mc":[{"id":"1.187560677","rc":[{"batb":[[0,3.55,4.99],[1,3.15,3.63],[2,2.5,117.67]],"batl":[[1,3.85,255.36]],"ltp":3.85,"tv":750.67,"id":7588306},{"batb":[[1,1.26,112.55],[2,1.23,87]],"batl":[[0,1.37,56.28],[1,1.38,79.64],[2,1.39,38.5]],"ltp":1.35,"tv":17517.93,"id":11439844}]}]}
{"op":"mcm","clk":"4234466041","pt":1631546075149,"mc":[{"id":"1.187560677","rc":[{"batl":[[0,1.38,79.64],[1,1.39,38.5],[2,1.4,28.58]],"ltp":1.35,"tv":17517.93,"id":11439844}]}]}
{"op":"mcm","clk":"4234468687","pt":1631546117019,"mc":[{"id":"1.187560677","rc":[{"trd":[[1.38,225.92]],"batl":[[0,1.38,77.72]],"ltp":1.38,"tv":17521.77,"id":11439844}],"tv":18272.44}]}
{"op":"mcm","clk":"4234469299","pt":1631546127109,"mc":[{"id":"1.187560677","rc":[{"batl":[[1,3.85,246.07]],"ltp":3.85,"tv":750.67,"id":7588306},{"batl":[[0,1.38,56.28]],"ltp":1.38,"tv":17521.77,"id":11439844}]}]}
{"op":"mcm","clk":"4234469476","pt":1631546130133,"mc":[{"id":"1.187560677","rc":[{"batb":[[0,1.36,81.39]],"batl":[[0,1.38,77.72]],"ltp":1.38,"tv":17521.77,"id":11439844}]}]}
{"op":"mcm","clk":"4234469696","pt":1631546133635,"mc":[{"id":"1.187560677","rc":[{"batb":[[1,3.5,3.28],[2,3.4,3.56]],"batl":[[2,4.2,2.33]],"ltp":3.85,"tv":750.67,"id":7588306},{"batb":[[1,1.32,86.64],[2,1.3,81.98]],"batl":[[2,1.4,89.27]],"ltp":1.38,"tv":17521.77,"id":11439844}]}]}
{"op":"mcm","clk":"4234469819","pt":1631546136124,"mc":[{"id":"1.187560677","rc":[{"batb":[[0,3.4,3.56],[1,2.5,117.67],[2,2.06,700.89]],"batl":[[0,4.4,2.44],[1,3.85,0],[2,4.2,0]],"ltp":3.85,"tv":750.67,"id":7588306},{"batb":[[0,1.3,81.98],[1,1.26,112.55],[2,1.23,87]],"batl":[[0,1.38,56.28],[1,1.41,171.05],[2,1.48,44.34]],"ltp":1.38,"tv":17521.77,"id":11439844}]}]}
{"op":"mcm","clk":"4234470147","pt":1631546141250,"mc":[{"id":"1.187560677","rc":[{"batl":[[0,1.41,171.05],[1,1.48,44.34],[2,1.55,56.28]],"ltp":1.38,"tv":17521.77,"id":11439844}]}]}
{"op":"mcm","clk":"4234470223","pt":1631546142655,"mc":[{"id":"1.187560677","rc":[{"batb":[[0,3.5,3.24],[1,3.4,3.56],[2,2.5,117.67]],"ltp":3.85,"tv":750.67,"id":7588306},{"batl":[[0,1.4,64.24],[1,1.41,58.5],[2,1.48,44.34]],"ltp":1.38,"tv":17521.77,"id":11439844}]}]}
{"op":"mcm","clk":"4234470304","pt":1631546143650,"mc":[{"id":"1.187560677","rc":[{"batb":[[0,3.4,11.9],[1,3.25,191.2]],"batl":[[0,3.55,6.51],[1,3.7,10.82],[2,3.85,671.02]],"ltp":3.85,"tv":750.67,"id":7588306},{"batl":[[0,1.41,58.5],[1,1.48,44.34],[2,1.55,56.28]],"ltp":1.38,"tv":17521.77,"id":11439844}]}]}
{"op":"mcm","clk":"4234470520","pt":1631546145555,"mc":[{"id":"1.187560677","rc":[{"batb":[[2,1.25,512.59]],"ltp":1.38,"tv":17521.77,"id":11439844}]}]}
{"op":"mcm","clk":"4234470618","pt":1631546146260,"mc":[{"id":"1.187560677","rc":[{"batb":[[0,1.38,302.1],[1,1.3,81.98],[2,1.26,112.55]],"ltp":1.38,"tv":17521.77,"id":11439844}]}]}
{"op":"mcm","clk":"4234471125","pt":1631546149670,"mc":[{"id":"1.187560677","rc":[{"trd":[[3.4,11.9]],"batb":[[0,3.25,191.2],[1,2.5,117.67],[2,2.06,700.89]],"ltp":3.4,"tv":762.57,"id":7588306},{"trd":[[1.41,239.23],[1.42,217.79]],"batb":[[0,1.42,206.59],[1,1.38,302.1],[2,1.3,81.98]],"batl":[[0,1.48,44.34],[1,1.55,56.28],[2,1.67,168.83]],"ltp":1.42,"tv":17667.27,"id":11439844}],"tv":18429.84}]}
{"op":"mcm","clk":"4234471243","pt":1631546150260,"mc":[{"id":"1.187560677","rc":[{"batb":[[0,3.35,4.07],[1,3.3,3.28],[2,3.25,191.2]],"batl":[[2,3.8,2.57]],"ltp":3.4,"tv":762.57,"id":7588306},{"trd":[[1.42,332.29]],"batb":[[0,1.38,302.1],[1,1.36,75.43],[2,1.34,71.72]],"batl":[[0,1.43,57.5],[1,1.48,44.34],[2,1.55,56.28]],"ltp":1.42,"tv":17781.76,"id":11439844}],"tv":18544.34}]}
{"op":"mcm","clk":"4234471750","pt":1631546153452,"mc":[{"id":"1.187560677","rc":[{"batl":[[1,1.46,61.25],[2,1.47,53.5]],"ltp":1.42,"tv":17781.76,"id":11439844}]}]}
{"op":"mcm","clk":"4234471868","pt":1631546154248,"mc":[{"id":"1.187560677","rc":[{"batb":[[2,3.25,194.81]],"ltp":3.4,"tv":762.57,"id":7588306},{"batl":[[1,1.44,49.33],[2,1.46,61.25]],"ltp":1.42,"tv":17781.76,"id":11439844}]}]}
{"op":"mcm","clk":"4234471998","pt":1631546155153,"mc":[{"id":"1.187560677","rc":[{"batl":[[0,1.43,113.78]],"ltp":1.42,"tv":17781.76,"id":11439844}]}]}
{"op":"mcm","clk":"4234472595","pt":1631546159614,"mc":[{"id":"1.187560677","rc":[{"batb":[[0,3.25,3.61],[1,2.5,117.67],[2,2.06,700.89]],"batl":[[0,3.8,2.57],[1,3.95,2.7],[2,4.1,3.05]],"ltp":3.4,"tv":762.57,"id":7588306},{"batl":[[0,1.43,56.28],[1,1.48,44.34],[2,1.52,112.55]],"ltp":1.42,"tv":17781.76,"id":11439844}]}]}
{"op":"mcm","clk":"4234472969","pt":1631546163122,"mc":[{"id":"1.187560677","rc":[{"batl":[[1,1.44,63.08],[2,1.48,44.34]],"ltp":1.42,"tv":17781.76,"id":11439844}]}]}
{"op":"mcm","clk":"4234473704","pt":1631546169404,"mc":[{"id":"1.187560677","rc":[{"batl":[[0,3.95,2.7],[1,3.95,0],[2,4.1,0]],"ltp":3.4,"tv":762.57,"id":7588306},{"batb":[[0,1.34,71.72],[1,1.26,112.55],[2,1.15,357.92]],"batl":[[1,1.48,44.34],[2,1.52,112.55]],"ltp":1.42,"tv":17781.76,"id":11439844}]}]}
{"op":"mcm","clk":"4234473921","pt":1631546171225,"mc":[{"id":"1.187560677","rc":[{"batb":[[0,3.45,11.6],[1,3.25,3.61],[2,2.5,117.67]],"batl":[[0,3.85,8.52],[1,3.95,2.7]],"ltp":3.4,"tv":762.57,"id":7588306},{"batb":[[0,1.34,621.65]],"batl":[[0,1.38,24.7],[1,1.43,1577.33],[2,1.48,44.34]],"ltp":1.42,"tv":17781.76,"id":11439844}]}]}
{"op":"mcm","clk":"4234474386","pt":1631546175896,"mc":[{"id":"1.187560677","rc":[{"batl":[[1,1.4,56.28],[2,1.43,1577.33]],"ltp":1.42,"tv":17781.76,"id":11439844}]}]}
{"op":"mcm","clk":"4234474712","pt":1631546179196,"mc":[{"id":"1.187560677","rc":[{"batb":[[0,3.5,3.14],[1,3.45,11.6],[2,3.35,3.87]],"batl":[[2,4.3,2.65]],"ltp":3.4,"tv":762.57,"id":7588306},{"batb":[[1,1.31,82.79],[2,1.29,91.81]],"batl":[[0,1.38,97.7],[1,1.4,123.47],[2,1.42,57.25]],"ltp":1.42,"tv":17781.76,"id":11439844}]}]}
{"op":"mcm","clk":"4234475853","pt":1631546191333,"mc":[{"id":"1.187560677","rc":[{"batb":[[0,3.35,3.87],[1,2.5,117.67],[2,2.06,700.89]],"batl":[[0,4.5,2.57],[1,3.95,0],[2,4.3,0]],"ltp":3.4,"tv":762.57,"id":7588306},{"batb":[[0,1.29,91.81],[1,1.26,112.55],[2,1.15,357.92]],"batl":[[0,1.4,56.28],[1,1.43,56.28],[2,1.48,44.34]],"ltp":1.42,"tv":17781.76,"id":11439844}]}]}
{"op":"mcm","clk":"4234476114","pt":1631546194532,"mc":[{"id":"1.187560677","rc":[{"batl":[[0,4.3,2.35],[1,4.5,2.57]],"ltp":3.4,"tv":762.57,"id":7588306},{"batb":[[0,1.31,81.79],[1,1.29,91.81],[2,1.26,112.55]],"batl":[[1,1.42,64.75],[2,1.43,56.28]],"ltp":1.42,"tv":17781.76,"id":11439844}]}]}
{"op":"mcm","clk":"4234476126","pt":1631546194752,"mc":[{"id":"1.187560677","rc":[{"batl":[[0,4.5,2.57],[1,4.5,0]],"ltp":3.4,"tv":762.57,"id":7588306},{"batb":[[0,1.29,91.81],[1,1.26,112.55],[2,1.15,357.92]],"ltp":1.42,"tv":17781.76,"id":11439844}]}]}
{"op":"mcm","clk":"4234476723","pt":1631546201443,"mc":[{"id":"1.187560677","rc":[{"batl":[[0,4.3,2.95],[1,4.5,2.57]],"ltp":3.4,"tv":762.57,"id":7588306},{"batb":[[0,1.31,81.79],[1,1.29,91.81],[2,1.26,112.55]],"ltp":1.42,"tv":17781.76,"id":11439844}]}]}
{"op":"mcm","clk":"4234476757","pt":1631546201759,"mc":[{"id":"1.187560677","rc":[{"batl":[[0,4.5,2.57],[1,4.5,0]],"ltp":3.4,"tv":762.57,"id":7588306},{"batb":[[0,1.29,91.81],[1,1.26,112.55],[2,1.15,357.92]],"ltp":1.42,"tv":17781.76,"id":11439844}]}]}
{"op":"mcm","clk":"4234477268","pt":1631546207065,"mc":[{"id":"1.187560677","rc":[{"trd":[[3.5,29.88]],"ltp":3.5,"tv":762.59,"id":7588306},{"trd":[[1.4,833.15]],"batl":[[0,1.4,56.22]],"ltp":1.4,"tv":17781.81,"id":11439844}],"tv":18544.41}]}
{"op":"mcm","clk":"4234477426","pt":1631546208530,"mc":[{"id":"1.187560677","rc":[{"batl":[[0,4.3,2.25],[1,4.5,2.57]],"ltp":3.5,"tv":762.59,"id":7588306},{"batb":[[0,1.31,82.79],[1,1.29,91.81],[2,1.26,112.55]],"ltp":1.4,"tv":17781.81,"id":11439844}]}]}
{"op":"mcm","clk":"4234477444","pt":1631546208748,"mc":[{"id":"1.187560677","rc":[{"batl":[[0,4.5,2.57],[1,4.5,0]],"ltp":3.5,"tv":762.59,"id":7588306},{"batb":[[0,1.29,91.81],[1,1.26,112.55],[2,1.15,357.92]],"ltp":1.4,"tv":17781.81,"id":11439844}]}]}
{"op":"mcm","clk":"4234477683","pt":1631546211629,"mc":[{"id":"1.187560677","rc":[{"batb":[[0,3.5,4.08],[1,3.35,3.87],[2,2.5,117.67]],"ltp":3.5,"tv":762.59,"id":7588306}]}]}
{"op":"mcm","clk":"4234477741","pt":1631546212103,"mc":[{"id":"1.187560677","rc":[{"batb":[[0,3.35,3.87],[1,2.5,117.67],[2,2.06,700.89]],"ltp":3.5,"tv":762.59,"id":7588306}]}]}
{"op":"mcm","clk":"4234477869","pt":1631546213481,"mc":[{"id":"1.187560677","rc":[{"batl":[[0,1.42,64.75],[1,1.43,56.28],[2,1.48,44.34]],"ltp":1.4,"tv":17781.81,"id":11439844}]}]}
{"op":"mcm","clk":"4234478059","pt":1631546215486,"mc":[{"id":"1.187560677","rc":[{"batl":[[1,1.48,44.34],[2,1.52,112.55]],"ltp":1.4,"tv":17781.81,"id":11439844}]}]}
{"op":"mcm","clk":"4234478128","pt":1631546216324,"mc":[{"id":"1.187560677","rc":[{"batb":[[0,3.4,6.29],[1,3.35,3.87],[2,3.3,200.63]],"batl":[[0,3.55,8.33],[1,3.65,14.46],[2,4.5,2.57]],"ltp":3.5,"tv":762.59,"id":7588306},{"batb":[[0,1.39,112.55],[1,1.38,661.82],[2,1.37,112.55]],"ltp":1.4,"tv":17781.81,"id":11439844}]}]}
{"op":"mcm","clk":"4234478785","pt":1631546224035,"mc":[{"id":"1.187560677","rc":[{"batb":[[2,3.3,204.41]],"batl":[[2,3.8,2.72]],"ltp":3.5,"tv":762.59,"id":7588306},{"batl":[[1,1.43,57.5],[2,1.44,63.08]],"ltp":1.4,"tv":17781.81,"id":11439844}]}]}
{"op":"mcm","clk":"4234479056","pt":1631546227245,"mc":[{"id":"1.187560677","rc":[{"batl":[[0,1.42,117.75]],"ltp":1.4,"tv":17781.81,"id":11439844}]}]}
{"op":"mcm","clk":"4234479362","pt":1631546230712,"mc":[{"id":"1.187560677","rc":[{"trd":[[3.4,16.94]],"batb":[[0,3.4,3.77]],"ltp":3.4,"tv":767.63,"id":7588306}],"tv":18549.44}]}
{"op":"mcm","clk":"4234479681","pt":1631546234428,"mc":[{"id":"1.187560677","rc":[{"batb":[[0,3.35,3.87],[1,3.3,3.78],[2,3.25,3.85]],"batl":[[0,3.65,3.5],[1,3.8,2.72],[2,3.95,2.7]],"ltp":3.4,"tv":767.63,"id":7588306},{"batb":[[1,1.38,140.51]],"ltp":1.4,"tv":17781.81,"id":11439844}]}]}
{"op":"mcm","clk":"4234479747","pt":1631546235328,"mc":[{"id":"1.187560677","rc":[{"batb":[[0,3.25,3.85],[1,2.5,117.67],[2,2.06,700.89]],"batl":[[0,3.8,2.72],[1,3.95,2.7],[2,4.5,2.57]],"ltp":3.4,"tv":767.63,"id":7588306},{"batb":[[1,1.38,112.55]],"batl":[[0,1.48,44.34],[1,1.52,112.55],[2,1.55,56.28]],"ltp":1.4,"tv":17781.81,"id":11439844}]}]}
{"op":"mcm","clk":"4234479992","pt":1631546238224,"mc":[{"id":"1.187560677","rc":[{"batl":[[0,1.44,52.33],[1,1.48,44.34],[2,1.52,112.55]],"ltp":1.4,"tv":17781.81,"id":11439844}]}]}
{"op":"mcm","clk":"4234480306","pt":1631546241620,"mc":[{"id":"1.187560677","rc":[{"batb":[[0,3.3,3.48],[1,3.25,3.85],[2,3.1,238.58]],"batl":[[0,3.45,3.7],[1,3.5,197.48],[2,3.8,2.72]],"ltp":3.4,"tv":767.63,"id":7588306},{"trd":[[1.43,21.34]],"batb":[[0,1.41,169.12],[1,1.4,493.69],[2,1.39,112.55]],"batl":[[0,1.43,42.83],[1,1.44,52.33],[2,1.46,14.93]],"ltp":1.43,"tv":17803.15,"id":11439844}],"tv":18570.78}]}
{"op":"mcm","clk":"4234480314","pt":1631546241724,"mc":[{"id":"1.187560677","rc":[{"batb":[[0,3.25,3.85],[1,3.1,238.58],[2,2.5,117.67]],"ltp":3.4,"tv":767.63,"id":7588306},{"batb":[[0,1.42,112.55],[1,1.41,168.19],[2,1.4,493.69]],"batl":[[0,1.44,52.33],[1,1.48,44.34],[2,1.52,112.55]],"ltp":1.43,"tv":17803.15,"id":11439844}]}]}
{"op":"mcm","clk":"4234480544","pt":1631546244643,"mc":[{"id":"1.187560677","rc":[{"trd":[[1.44,24.96]],"batl":[[0,1.44,41.73],[1,1.46,14.93],[2,1.48,44.34]],"ltp":1.44,"tv":17824.35,"id":11439844}],"tv":18591.98}]}
{"op":"mcm","clk":"4234480882","pt":1631546249345,"mc":[{"id":"1.187560677","rc":[{"batb":[[1,3.2,3.42],[2,3.1,238.58]],"batl":[[1,3.5,200.47],[2,3.6,2.96]],"ltp":3.4,"tv":767.63,"id":7588306},{"batb":[[2,1.4,553.65]],"batl":[[1,1.45,53.5],[2,1.46,14.93]],"ltp":1.44,"tv":17824.35,"id":11439844}]}]}
{"op":"mcm","clk":"4234481061","pt":1631546251761,"mc":[{"id":"1.187560677","rc":[{"batl":[[2,1.48,44.34]],"ltp":1.44,"tv":17824.35,"id":11439844}]}]}
{"op":"mcm","clk":"4234481317","pt":1631546254645,"mc":[{"id":"1.187560677","rc":[{"batb":[[0,1.42,129.61]],"batl":[[0,1.44,52.33]],"ltp":1.44,"tv":17824.35,"id":11439844}]}]}
{"op":"mcm","clk":"4234481339","pt":1631546254853,"mc":[{"id":"1.187560677","rc":[{"batb":[[0,1.42,112.55]],"batl":[[0,1.44,41.73]],"ltp":1.44,"tv":17824.35,"id":11439844}]}]}
{"op":"mcm","clk":"4234481613","pt":1631546257738,"mc":[{"id":"1.187560677","rc":[{"batb":[[0,1.42,129.61]],"batl":[[0,1.44,52.33]],"ltp":1.44,"tv":17824.35,"id":11439844}]}]}
{"op":"mcm","clk":"4234481853","pt":1631546260165,"mc":[{"id":"1.187560677","rc":[{"batb":[[0,3.2,3.42],[1,2.5,117.67],[2,2.06,700.89]],"batl":[[0,3.5,2.99],[1,3.6,2.96],[2,3.8,2.72]],"ltp":3.4,"tv":767.63,"id":7588306},{"batb":[[0,1.42,112.55],[1,1.41,112.55],[2,1.4,59.96]],"batl":[[0,1.48,44.34],[1,1.52,112.55],[2,1.55,56.28]],"ltp":1.44,"tv":17824.35,"id":11439844}]}]}
{"op":"mcm","clk":"4234482161","pt":1631546263665,"mc":[{"id":"1.187560677","rc":[{"batl":[[0,1.45,54.1],[1,1.48,44.34],[2,1.52,112.55]],"ltp":1.44,"tv":17824.35,"id":11439844}]}]}
{"op":"mcm","clk":"4234491247","pt":1631546269654,"mc":[{"id":"1.187560677","rc":[{"batb":[[1,3,96.49],[2,2.5,117.67]],"batl":[[0,3.25,202.66],[1,3.35,162.5],[2,3.5,2.99]],"ltp":3.4,"tv":767.63,"id":7588306},{"trd":[[1.45,23.82]],"batb":[[0,1.43,139.86],[1,1.42,112.55],[2,1.41,112.55]],"batl":[[0,1.45,42.19],[1,1.47,13.29],[2,1.48,44.34]],"ltp":1.45,"tv":17848.17,"id":11439844}],"tv":18615.8}]}
{"op":"mcm","clk":"4234491292","pt":1631546270068,"mc":[{"id":"1.187560677","rc":[{"batl":[[1,3.4,5.19]],"ltp":3.4,"tv":767.63,"id":7588306},{"batb":[[0,1.43,140.53],[1,1.42,149.99]],"ltp":1.45,"tv":17848.17,"id":11439844}]}]}
{"op":"mcm","clk":"4234491712","pt":1631546274682,"mc":[{"id":"1.187560677","rc":[{"trd":[[1.45,108.2]],"batb":[[0,1.45,104.51],[1,1.43,140.53],[2,1.42,149.99]],"batl":[[0,1.47,13.29],[1,1.48,44.34],[2,1.5,192.98]],"ltp":1.45,"tv":17932.55,"id":11439844}],"tv":18700.18}]}
{"op":"mcm","clk":"4234491902","pt":1631546277293,"mc":[{"id":"1.187560677","rc":[{"batb":[[2,2.96,4.88]],"batl":[[2,3.45,3.3]],"ltp":3.4,"tv":767.63,"id":7588306}]}]}
{"op":"mcm","clk":"4234492124","pt":1631546280182,"mc":[{"id":"1.187560677","rc":[{"batl":[[0,1.48,44.34],[1,1.5,192.98],[2,1.51,50.5]],"ltp":1.45,"tv":17932.55,"id":11439844}]}]}
{"op":"mcm","clk":"4234492329","pt":1631546282652,"mc":[{"id":"1.187560677","rc":[{"batb":[[1,1.44,13.36],[2,1.43,140.53]],"batl":[[0,1.46,12.79],[1,1.48,44.34],[2,1.5,192.98]],"ltp":1.45,"tv":17932.55,"id":11439844}]}]}
{"op":"mcm","clk":"4234492370","pt":1631546283279,"mc":[{"id":"1.187560677","rc":[{"trd":[[1.45,111.85]],"batb":[[0,1.45,102.69]],"ltp":1.45,"tv":17936.21,"id":11439844}],"tv":18703.84}]}
{"op":"mcm","clk":"4234493113","pt":1631546294374,"mc":[{"id":"1.187560677","rc":[{"trd":[[1.45,282.38]],"batb":[[0,1.45,17.42]],"ltp":1.45,"tv":18106.74,"id":11439844}],"tv":18874.37}]}
{"op":"mcm","clk":"4234493613","pt":1631546301512,"mc":[{"id":"1.187560677","rc":[{"batb":[[0,2.88,4.71],[1,2.84,3.97],[2,2,11.93]],"batl":[[0,3.45,3.3],[1,3.5,2.99],[2,3.6,2.96]],"ltp":3.4,"tv":767.63,"id":7588306},{"batb":[[1,1.43,112.55],[2,1.42,112.55]],"batl":[[0,1.48,44.34],[1,1.52,112.55],[2,1.53,46.5]],"ltp":1.45,"tv":18106.74,"id":11439844}]}]}
{"op":"mcm","clk":"4234493640","pt":1631546301829,"mc":[{"id":"1.187560677","rc":[{"batb":[[0,2.84,3.97],[1,2,11.93],[2,1.8,11.93]],"ltp":3.4,"tv":767.63,"id":7588306},{"batl":[[2,1.54,44.25]],"ltp":1.45,"tv":18106.74,"id":11439844}]}]}
{"op":"mcm","clk":"4234494041","pt":1631546306525,"mc":[{"id":"1.187560677","rc":[{"batl":[[0,3.5,2.99],[1,3.6,2.96],[2,3.8,2.72]],"ltp":3.4,"tv":767.63,"id":7588306}]}]}
{"op":"mcm","clk":"4234494057","pt":1631546306734,"mc":[{"id":"1.187560677","rc":[{"batb":[[0,1.41,112.55],[1,1.4,59.96],[2,1.39,168.46]],"ltp":1.45,"tv":18106.74,"id":11439844}]}]}
{"op":"mcm","clk":"4234494256","pt":1631546309233,"mc":[{"id":"1.187560677","rc":[{"batb":[[0,3.35,7.32],[1,3.15,249.79],[2,2.84,3.97]],"batl":[[0,3.5,145.88]],"ltp":3.4,"tv":767.63,"id":7588306},{"batb":[[1,1.4,417.2]],"batl":[[0,1.43,56.28],[1,1.44,56.28],[2,1.45,56.28]],"ltp":1.45,"tv":18106.74,"id":11439844}]}]}
{"op":"mcm","clk":"4234494909","pt":1631546316905,"mc":[{"id":"1.187560677","rc":[{"batb":[[1,3.2,3.77],[2,3.15,253.82]],"ltp":3.4,"tv":767.63,"id":7588306},{"batl":[[0,1.43,185.28],[2,1.45,108.98]],"ltp":1.45,"tv":18106.74,"id":11439844}]}]}
{"op":"mcm","clk":"4234495267","pt":1631546321822,"mc":[{"id":"1.187560677","rc":[{"batb":[[0,3.2,3.77],[1,3.15,4.03],[2,2.84,3.97]],"batl":[[0,3.5,2.99]],"ltp":3.4,"tv":767.63,"id":7588306},{"batb":[[1,1.4,59.96]],"ltp":1.45,"tv":18106.74,"id":11439844}]}]}
{"op":"mcm","clk":"4234495490","pt":1631546324421,"mc":[{"id":"1.187560677","rc":[{"batl":[[0,1.43,56.28]],"ltp":1.45,"tv":18106.74,"id":11439844}]}]}
{"op":"mcm","clk":"4234495520","pt":1631546324737,"mc":[{"id":"1.187560677","rc":[{"batb":[[0,3.15,4.03],[1,2.84,3.97],[2,2,11.93]],"ltp":3.4,"tv":767.63,"id":7588306},{"batl":[[2,1.45,56.28]],"ltp":1.45,"tv":18106.74,"id":11439844}]}]}
{"op":"mcm","clk":"4234496035","pt":1631546330659,"mc":[{"id":"1.187560677","rc":[{"batb":[[0,1.4,59.96],[1,1.39,55.91],[2,1.38,112.55]],"ltp":1.45,"tv":18106.74,"id":11439844}]}]}
{"op":"mcm","clk":"4234496096","pt":1631546331537,"mc":[{"id":"1.187560677","rc":[{"batb":[[0,3.2,3.57],[1,3.15,4.03],[2,2.84,3.97]],"batl":[[0,3.6,2.96],[1,3.8,2.72],[2,3.95,2.7]],"ltp":3.4,"tv":767.63,"id":7588306},{"batb":[[0,1.39,55.91],[1,1.38,112.55],[2,1.37,112.55]],"batl":[[2,1.45,113.58]],"ltp":1.45,"tv":18106.74,"id":11439844}]}]}
{"op":"mcm","clk":"4234496117","pt":1631546331752,"mc":[{"id":"1.187560677","rc":[{"batb":[[0,3.15,4.03],[1,2.84,3.97],[2,2,11.93]],"ltp":3.4,"tv":767.63,"id":7588306},{"batl":[[2,1.45,56.28]],"ltp":1.45,"tv":18106.74,"id":11439844}]}]}
{"op":"mcm","clk":"4234496238","pt":1631546333150,"mc":[{"id":"1.187560677","rc":[{"batb":[[0,3.55,4.31],[1,3.35,11.94],[2,3.15,4.03]],"batl":[[1,3.7,9.13],[2,3.8,2.72]],"ltp":3.4,"tv":767.63,"id":7588306},{"batb":[[1,1.38,586.97]],"batl":[[0,1.4,56.28],[1,1.41,56.28],[2,1.43,499.47]],"ltp":1.45,"tv":18106.74,"id":11439844}]}]}
{"op":"mcm","clk":"4234496363","pt":1631546334451,"mc":[{"id":"1.187560677","rc":[{"batl":[[0,1.41,56.28],[1,1.43,499.47],[2,1.44,56.28]],"ltp":1.45,"tv":18106.74,"id":11439844}]}]}
{"op":"mcm","clk":"4234496633","pt":1631546338027,"mc":[{"id":"1.187560677","rc":[{"batl":[[1,1.43,503.24]],"ltp":1.45,"tv":18106.74,"id":11439844}]}]}
{"op":"mcm","clk":"4234496782","pt":1631546340263,"mc":[{"id":"1.187560677","rc":[{"batb":[[2,3.3,3.58]],"batl":[[1,3.65,3.1],[2,3.7,9.13]],"ltp":3.4,"tv":767.63,"id":7588306},{"batb":[[1,1.38,648.43],[2,1.37,181.32]],"batl":[[1,1.43,563.74]],"ltp":1.45,"tv":18106.74,"id":11439844}]}]}
{"op":"mcm","clk":"4234496870","pt":1631546341259,"mc":[{"id":"1.187560677","rc":[{"batl":[[0,1.4,243],[1,1.41,56.28],[2,1.43,563.74]],"ltp":1.45,"tv":18106.74,"id":11439844}]}]}
{"op":"mcm","clk":"4234497287","pt":1631546346566,"mc":[{"id":"1.187560677","rc":[{"batb":[[0,3.3,3.58],[1,3.2,3.67],[2,3.15,4.03]],"batl":[[0,3.75,3.02],[1,3.8,2.72],[2,3.95,2.7]],"ltp":3.4,"tv":767.63,"id":7588306},{"batb":[[0,1.38,112.55],[1,1.37,181.32],[2,1.36,60.93]],"batl":[[2,1.43,120.55]],"ltp":1.45,"tv":18106.74,"id":11439844}]}]}
{"op":"mcm","clk":"4234497353","pt":1631546347558,"mc":[{"id":"1.187560677","rc":[{"batb":[[0,3.2,3.67],[1,2.84,3.97],[2,2,11.93]],"ltp":3.4,"tv":767.63,"id":7588306},{"batl":[[0,1.41,56.28],[1,1.43,60.05],[2,1.44,56.28]],"ltp":1.45,"tv":18106.74,"id":11439844}]}]}
{"op":"mcm","clk":"4234497498","pt":1631546349344,"mc":[{"id":"1.187560677","rc":[{"batb":[[1,2,11.93],[2,1.8,11.93]],"ltp":3.4,"tv":767.63,"id":7588306},{"batl":[[1,1.43,56.28]],"ltp":1.45,"tv":18106.74,"id":11439844}]}]}
{"op":"mcm","clk":"4234497646","pt":1631546351057,"mc":[{"id":"1.187560677","rc":[{"batb":[[0,1.37,181.32],[1,1.36,60.93],[2,1.34,71.22]],"ltp":1.45,"tv":18106.74,"id":11439844}]}]}
{"op":"mcm","clk":"4234497718","pt":1631546352054,"mc":[{"id":"1.187560677","rc":[{"batl":[[2,3.85,8.89]],"ltp":3.4,"tv":767.63,"id":7588306},{"batb":[[1,1.36,563.26]],"batl":[[0,1.38,24.61],[1,1.4,28.58],[2,1.41,589.11]],"ltp":1.45,"tv":18106.74,"id":11439844}]}]}
{"op":"mcm","clk":"4234498239","pt":1631546358572,"mc":[{"id":"1.187560677","rc":[{"batb":[[0,3.4,3.41],[1,3.3,3.78],[2,3.2,3.67]],"ltp":3.4,"tv":767.63,"id":7588306},{"batl":[[2,1.41,645.61]],"ltp":1.45,"tv":18106.74,"id":11439844}]}]}
{"op":"mcm","clk":"4234498549","pt":1631546361770,"mc":[{"id":"1.187560677","rc":[{"batl":[[0,1.38,236.61]],"ltp":1.45,"tv":18106.74,"id":11439844}]}]}
{"op":"mcm","clk":"4234499207","pt":1631546369496,"mc":[{"id":"1.187560677","rc":[{"batb":[[2,2,11.93]],"batl":[[0,3.8,2.72],[1,3.95,2.7],[2,4.5,2.57]],"ltp":3.4,"tv":767.63,"id":7588306},{"batb":[[0,1.37,112.55],[1,1.36,60.93]],"batl":[[0,1.38,212],[1,1.41,112.78],[2,1.43,116.78]],"ltp":1.45,"tv":18106.74,"id":11439844}]}]}
{"op":"mcm","clk":"4234499291","pt":1631546370592,"mc":[{"id":"1.187560677","rc":[{"batb":[[0,3.3,3.78],[1,2,11.93],[2,1.8,11.93]],"batl":[[1,3.95,0],[2,4.5,0]],"ltp":3.4,"tv":767.63,"id":7588306},{"batb":[[2,1.26,112.55]],"batl":[[0,1.41,56.28],[1,1.43,116.78],[2,1.44,56.28]],"ltp":1.45,"tv":18106.74,"id":11439844}]}]}
{"op":"mcm","clk":"4234499482","pt":1631546372688,"mc":[{"id":"1.187560677","rc":[{"batl":[[0,3.75,2.74],[1,3.8,2.72]],"ltp":3.4,"tv":767.63,"id":7588306},{"batb":[[0,1.37,174.32]],"ltp":1.45,"tv":18106.74,"id":11439844}]}]}
{"op":"mcm","clk":"4234499508","pt":1631546372894,"mc":[{"id":"1.187560677","rc":[{"batl":[[0,3.8,2.72],[1,3.8,0]],"ltp":3.4,"tv":767.63,"id":7588306},{"batb":[[0,1.37,112.55]],"ltp":1.45,"tv":18106.74,"id":11439844}]}]}
{"op":"mcm","clk":"4234499610","pt":1631546374302,"mc":[{"id":"1.187560677","rc":[{"batl":[[1,1.43,56.28]],"ltp":1.45,"tv":18106.74,"id":11439844}]}]}
{"op":"mcm","clk":"4234499706","pt":1631546375605,"mc":[{"id":"1.187560677","rc":[{"batb":[[0,1.36,60.93],[1,1.26,112.55],[2,1.15,357.92]],"ltp":1.45,"tv":18106.74,"id":11439844}]}]}
{"op":"mcm","clk":"4234499867","pt":1631546377393,"mc":[{"id":"1.187560677","rc":[{"batl":[[1,3.85,138.23],[2,3.9,4.67]],"ltp":3.4,"tv":767.63,"id":7588306},{"trd":[[1.36,183.25]],"batb":[[0,1.36,47.25]],"batl":[[0,1.39,387.81],[1,1.4,28.58],[2,1.41,56.28]],"ltp":1.36,"tv":18134.1,"id":11439844}],"tv":18901.73}]}
{"op":"mcm","clk":"4234499995","pt":1631546379113,"mc":[{"id":"1.187560677","rc":[{"batb":[[2,1.2,538.74]],"ltp":1.36,"tv":18134.1,"id":11439844}]}]}
{"op":"mcm","clk":"4234500116","pt":1631546380685,"mc":[{"id":"1.187560677","rc":[{"batb":[[1,1.2,538.74],[2,1.15,357.92]],"batl":[[2,1.66,588.41]],"ltp":1.36,"tv":18134.1,"id":11439844}]}]}
{"op":"mcm","clk":"4234500250","pt":1631546382192,"mc":[{"id":"1.187560677","rc":[{"batb":[[0,1.37,18.43],[1,1.36,47.25],[2,1.2,538.74]],"ltp":1.36,"tv":18134.1,"id":11439844}]}]}
{"op":"mcm","clk":"4234500325","pt":1631546382885,"mc":[{"id":"1.187560677","rc":[{"trd":[[1.39,3657.74]],"batl":[[0,1.39,350.31]],"ltp":1.39,"tv":18209.1,"id":11439844}],"tv":18976.73}]}
{"op":"mcm","clk":"4234500406","pt":1631546383978,"mc":[{"id":"1.187560677","rc":[{"batl":[[0,1.38,195],[1,1.39,350.31],[2,1.4,28.58]],"ltp":1.39,"tv":18209.1,"id":11439844}]}]}
{"op":"mcm","clk":"4234500643","pt":1631546387208,"mc":[{"id":"1.187560677","rc":[{"batl":[[2,3.9,0]],"ltp":3.4,"tv":767.63,"id":7588306}]}]}
{"op":"mcm","clk":"4234500855","pt":1631546390074,"mc":[{"id":"1.187560677","rc":[{"batl":[[1,3.85,143.91]],"ltp":3.4,"tv":767.63,"id":7588306},{"trd":[[1.37,584.34]],"batb":[[0,1.37,1.61]],"ltp":1.37,"tv":18242.74,"id":11439844}],"tv":19010.37}]}
{"op":"mcm","clk":"4234501041","pt":1631546392689,"mc":[{"id":"1.187560677","rc":[{"batb":[[0,1.36,47.25],[1,1.2,538.74],[2,1.15,357.92]],"ltp":1.37,"tv":18242.74,"id":11439844}]}]}
{"op":"mcm","clk":"4234501563","pt":1631546400412,"mc":[{"id":"1.187560677","rc":[{"batl":[[1,3.85,138.23]],"ltp":3.4,"tv":767.63,"id":7588306},{"trd":[[1.38,229.12]],"batl":[[0,1.38,193.4]],"ltp":1.38,"tv":18245.94,"id":11439844}],"tv":19013.57}]}
{"op":"mcm","clk":"4234501819","pt":1631546403202,"mc":[{"id":"1.187560677","rc":[{"batb":[[0,1.36,64.2]],"batl":[[0,1.38,209.46]],"ltp":1.38,"tv":18245.94,"id":11439844}]}]}
{"op":"mcm","clk":"4234507575","pt":1631546468126,"mc":[{"id":"1.187560677","rc":[{"batb":[[0,3.35,3.87],[1,3.3,3.78],[2,3.25,3.53]],"batl":[[2,4.2,2.83]],"ltp":3.4,"tv":767.63,"id":7588306},{"batb":[[1,1.32,79.14],[2,1.3,94.48]],"ltp":1.38,"tv":18245.94,"id":11439844}]}]}
{"op":"mcm","clk":"4234507780","pt":1631546470632,"mc":[{"id":"1.187560677","rc":[{"batb":[[1,3.25,3.53],[2,2,11.93]],"batl":[[0,4.4,2.64],[1,3.85,0],[2,4.2,0]],"ltp":3.4,"tv":767.63,"id":7588306},{"batb":[[0,1.3,94.48],[1,1.2,538.74],[2,1.15,357.92]],"batl":[[0,1.38,193.4],[1,1.42,61.25],[2,1.44,57.83]],"ltp":1.38,"tv":18245.94,"id":11439844}]}]}
{"op":"mcm","clk":"4234507876","pt":1631546471523,"mc":[{"id":"1.187560677","rc":[{"batb":[[0,3.25,3.53],[1,2,11.93],[2,1.8,11.93]],"ltp":3.4,"tv":767.63,"id":7588306},{"batl":[[0,1.44,57.83],[1,1.66,588.41],[2,1.94,3.08]],"ltp":1.38,"tv":18245.94,"id":11439844}]}]}
{"op":"mcm","clk":"4234508064","pt":1631546473706,"mc":[{"id":"1.187560677","rc":[{"batb":[[0,1.38,1.92],[1,1.3,94.48],[2,1.2,538.74]],"ltp":1.38,"tv":18245.94,"id":11439844}]}]}
{"op":"mcm","clk":"4234508132","pt":1631546474703,"mc":[{"id":"1.187560677","rc":[{"batb":[[0,3.35,4.07],[1,3.25,3.53],[2,2,11.93]],"ltp":3.4,"tv":767.63,"id":7588306},{"batl":[[0,1.42,67.25],[1,1.44,57.83],[2,1.66,588.41]],"ltp":1.38,"tv":18245.94,"id":11439844}]}]}
{"op":"mcm","clk":"4234508138","pt":1631546474905,"mc":[{"id":"1.187560677","rc":[{"batb":[[0,3.25,3.53],[1,2,11.93],[2,1.8,11.93]],"ltp":3.4,"tv":767.63,"id":7588306},{"batl":[[0,1.44,57.83],[1,1.66,588.41],[2,1.94,3.08]],"ltp":1.38,"tv":18245.94,"id":11439844}]}]}
{"op":"mcm","clk":"4234508330","pt":1631546477420,"mc":[{"id":"1.187560677","rc":[{"batl":[[0,4.2,2.28],[1,4.4,2.64]],"ltp":3.4,"tv":767.63,"id":7588306},{"batb":[[1,1.32,74.89],[2,1.3,94.48]],"ltp":1.38,"tv":18245.94,"id":11439844}]}]}
{"op":"mcm","clk":"4234508397","pt":1631546478430,"mc":[{"id":"1.187560677","rc":[{"batl":[[0,4.4,2.64],[1,4.4,0]],"ltp":3.4,"tv":767.63,"id":7588306},{"batb":[[1,1.3,94.48],[2,1.2,538.74]],"ltp":1.38,"tv":18245.94,"id":11439844}]}]}
{"op":"mcm","clk":"4234508506","pt":1631546479818,"mc":[{"id":"1.187560677","rc":[{"batb":[[0,1.3,94.48],[1,1.2,538.74],[2,1.15,357.92]],"batl":[[0,1.66,588.41],[1,1.94,3.08],[2,44,7.22]],"ltp":1.38,"tv":18245.94,"id":11439844}]}]}
{"op":"mcm","clk":"4234508675","pt":1631546481640,"mc":[{"id":"1.187560677","rc":[{"batb":[[0,3.35,3.27],[1,3.25,3.53],[2,2,11.93]],"ltp":3.4,"tv":767.63,"id":7588306},{"batb":[[1,1.15,357.92],[2,1.11,271.16]],"batl":[[0,1.42,56.25],[1,1.66,588.41],[2,1.94,3.08]],"ltp":1.38,"tv":18245.94,"id":11439844}]}]}
{"op":"mcm","clk":"4234508765","pt":1631546482644,"mc":[{"id":"1.187560677","rc":[{"batb":[[0,3.4,5.51],[1,3.3,187.95],[2,3.25,3.53]],"batl":[[0,3.5,4.39],[1,3.6,162.6],[2,3.65,62.5]],"ltp":3.4,"tv":767.63,"id":7588306},{"batb":[[0,1.38,61.46],[1,1.3,94.48],[2,1.15,357.92]],"batl":[[0,1.66,588.41],[1,1.94,3.08],[2,44,7.22]],"ltp":1.38,"tv":18245.94,"id":11439844}]}]}
{"op":"mcm","clk":"4234508779","pt":1631546482751,"mc":[{"id":"1.187560677","rc":[{"batl":[[2,3.65,18.66]],"ltp":3.4,"tv":767.63,"id":7588306}]}]}
{"op":"mcm","clk":"4234509007","pt":1631546485416,"mc":[{"id":"1.187560677","rc":[{"batb":[[2,1.23,524.14]],"ltp":1.38,"tv":18245.94,"id":11439844}]}]}
{"op":"mcm","clk":"4234509257","pt":1631546488608,"mc":[{"id":"1.187560677","rc":[{"batl":[[0,1.42,163],[1,1.66,588.41],[2,1.94,3.08]],"ltp":1.38,"tv":18245.94,"id":11439844}]}]}
{"op":"mcm","clk":"4234509321","pt":1631546489338,"mc":[{"id":"1.187560677","rc":[{"batb":[[1,3.3,191.83]],"ltp":3.4,"tv":767.63,"id":7588306},{"batb":[[1,1.37,64.77],[2,1.35,67.27]],"batl":[[1,1.43,54.5],[2,1.44,63.33]],"ltp":1.38,"tv":18245.94,"id":11439844}]}]}
{"op":"mcm","clk":"4234509749","pt":1631546494455,"mc":[{"id":"1.187560677","rc":[{"trd":[[3.5,30.68]],"batl":[[0,3.5,3.59]],"ltp":3.5,"tv":768.43,"id":7588306},{"trd":[[1.4,835.15]],"ltp":1.4,"tv":18247.94,"id":11439844}],"tv":19016.37}]}
{"op":"mcm","clk":"4234509820","pt":1631546495669,"mc":[{"id":"1.187560677","rc":[{"batb":[[0,3.3,3.88],[1,3.25,3.53],[2,2,11.93]],"batl":[[0,3.9,3.05],[1,3.6,0],[2,3.65,0]],"ltp":3.5,"tv":768.43,"id":7588306},{"batb":[[0,1.23,524.14],[1,1.15,357.92],[2,1.11,271.16]],"ltp":1.4,"tv":18247.94,"id":11439844}]}]}
{"op":"mcm","clk":"4234509907","pt":1631546496459,"mc":[{"id":"1.187560677","rc":[{"batb":[[0,3.25,3.53],[1,2,11.93],[2,1.8,11.93]],"ltp":3.5,"tv":768.43,"id":7588306},{"batl":[[0,1.44,63.33],[1,1.66,588.41],[2,1.94,3.08]],"ltp":1.4,"tv":18247.94,"id":11439844}]}]}
{"op":"mcm","clk":"4234510163","pt":1631546499640,"mc":[{"id":"1.187560677","rc":[{"trd":[[3.25,35.12]],"batb":[[0,3.3,3.28]],"batl":[[0,3.4,11.72],[1,3.9,3.05]],"ltp":3.25,"tv":803.55,"id":7588306},{"trd":[[1.44,88.29]],"batb":[[0,1.35,75.67],[1,1.23,524.14],[2,1.15,357.92]],"batl":[[0,1.43,61.5]],"ltp":1.44,"tv":18311.27,"id":11439844}],"tv":19114.83}]}
{"op":"mcm","clk":"4234510185","pt":1631546499955,"mc":[{"id":"1.187560677","rc":[{"batb":[[0,2,11.93],[1,1.8,11.93],[2,1.7,17.05]],"ltp":3.25,"tv":803.55,"id":7588306},{"batl":[[0,1.66,588.41],[1,1.94,3.08],[2,44,7.22]],"ltp":1.44,"tv":18311.27,"id":11439844}]}]}
{"op":"mcm","clk":"4234510448","pt":1631546502640,"mc":[{"id":"1.187560677","rc":[{"trd":[[3.4,40.38]],"batb":[[0,3.25,3.85],[1,2,11.93],[2,1.8,11.93]],"batl":[[0,3.9,3.05],[1,3.9,0]],"ltp":3.4,"tv":826.99,"id":7588306}],"tv":19138.27}]}
{"op":"mcm","clk":"4234510565","pt":1631546504164,"mc":[{"id":"1.187560677","rc":[{"batl":[[0,3.4,86.43],[1,3.9,3.05]],"ltp":3.4,"tv":826.99,"id":7588306}]}]}
{"op":"mcm","clk":"4234510711","pt":1631546505839,"mc":[{"id":"1.187560677","rc":[{"batl":[[1,3.75,4.14],[2,3.9,3.05]],"ltp":3.4,"tv":826.99,"id":7588306},{"batb":[[0,1.37,93.77],[1,1.35,75.67],[2,1.23,524.14]],"ltp":1.44,"tv":18311.27,"id":11439844}]}]}
{"op":"mcm","clk":"4234511391","pt":1631546513854,"mc":[{"id":"1.187560677","rc":[{"batb":[[0,3.3,3.78],[1,3.25,3.85],[2,2,11.93]],"ltp":3.4,"tv":826.99,"id":7588306},{"batl":[[0,1.43,62.5],[1,1.66,588.41],[2,1.94,3.08]],"ltp":1.44,"tv":18311.27,"id":11439844}]}]}
{"op":"mcm","clk":"4234511540","pt":1631546515851,"mc":[{"id":"1.187560677","rc":[{"batb":[[0,3.25,3.85],[1,2,11.93],[2,1.8,11.93]],"ltp":3.4,"tv":826.99,"id":7588306},{"batl":[[0,1.66,588.41],[1,1.94,3.08],[2,44,7.22]],"ltp":1.44,"tv":18311.27,"id":11439844}]}]}
{"op":"mcm","clk":"4234511808","pt":1631546519486,"mc":[{"id":"1.187560677","rc":[{"batb":[[2,1.15,357.92]],"ltp":1.44,"tv":18311.27,"id":11439844}]}]}
{"op":"mcm","clk":"4234511906","pt":1631546520589,"mc":[{"id":"1.187560677","rc":[{"batl":[[1,3.45,13.1],[2,3.55,473.3]],"ltp":3.4,"tv":826.99,"id":7588306},{"batb":[[0,1.43,14.31],[1,1.42,28.16],[2,1.41,96.89]],"batl":[[0,1.45,12.15],[1,1.47,395.36],[2,1.66,588.41]],"ltp":1.44,"tv":18311.27,"id":11439844}]}]}
{"op":"mcm","clk":"4234512772","pt":1631546531682,"mc":[{"id":"1.187560677","rc":[{"batb":[[1,3.2,3.57],[2,3.15,4.23]],"ltp":3.4,"tv":826.99,"id":7588306},{"batl":[[0,1.45,64.25],[1,1.46,59.25],[2,1.47,395.36]],"ltp":1.44,"tv":18311.27,"id":11439844}]}]}
{"op":"mcm","clk":"4234512963","pt":1631546534403,"mc":[{"id":"1.187560677","rc":[{"batl":[[0,1.45,228.25]],"ltp":1.44,"tv":18311.27,"id":11439844}]}]}
{"op":"mcm","clk":"4234513687","pt":1631546542102,"mc":[{"id":"1.187560677","rc":[{"batb":[[0,3.15,4.23],[1,2,11.93],[2,1.8,11.93]],"batl":[[1,3.6,4.11],[2,3.75,4.14]],"ltp":3.4,"tv":826.99,"id":7588306},{"batb":[[0,1.39,93.91],[1,1.37,93.77],[2,1.35,75.67]],"batl":[[0,1.45,164],[2,1.66,588.41]],"ltp":1.44,"tv":18311.27,"id":11439844}]}]}
{"op":"mcm","clk":"4234513792","pt":1631546543308,"mc":[{"id":"1.187560677","rc":[{"batl":[[0,1.46,59.25],[1,1.66,588.41],[2,1.94,3.08]],"ltp":1.44,"tv":18311.27,"id":11439844}]}]}
{"op":"mcm","clk":"4234514037","pt":1631546546418,"mc":[{"id":"1.187560677","rc":[{"batl":[[1,1.94,3.08],[2,44,7.22]],"ltp":1.44,"tv":18311.27,"id":11439844}]}]}
{"op":"mcm","clk":"4234514099","pt":1631546547521,"mc":[{"id":"1.187560677","rc":[{"batb":[[1,3,100.85],[2,2,11.93]],"batl":[[0,3.25,192.68],[1,3.3,60.6],[2,3.4,86.43]],"ltp":3.4,"tv":826.99,"id":7588306},{"trd":[[1.46,49.2]],"batl":[[0,1.46,48.29],[1,1.48,13.24],[2,1.5,201.7]],"ltp":1.46,"tv":18333.19,"id":11439844}],"tv":19160.19}]}
{"op":"mcm","clk":"4234514128","pt":1631546547834,"mc":[{"id":"1.187560677","rc":[{"batl":[[1,3.3,12.12],[2,3.4,99.52]],"ltp":3.4,"tv":826.99,"id":7588306},{"batb":[[0,1.42,94.44],[1,1.39,93.91],[2,1.37,93.77]],"ltp":1.46,"tv":18333.19,"id":11439844}]}]}
{"op":"mcm","clk":"4234514659","pt":1631546554615,"mc":[{"id":"1.187560677","rc":[{"batb":[[1,3.1,4.14],[2,3,100.85]],"ltp":3.4,"tv":826.99,"id":7588306},{"batb":[[1,1.41,98.89],[2,1.39,93.91]],"batl":[[1,1.47,59.5],[2,1.48,13.24]],"ltp":1.46,"tv":18333.19,"id":11439844}]}]}
{"op":"mcm","clk":"4234514852","pt":1631546557698,"mc":[{"id":"1.187560677","rc":[{"batl":[[2,1.5,201.7]],"ltp":1.46,"tv":18333.19,"id":11439844}]}]}
{"op":"mcm","clk":"4234514858","pt":1631546557801,"mc":[{"id":"1.187560677","rc":[{"batl":[[0,1.46,173.29]],"ltp":1.46,"tv":18333.19,"id":11439844}]}]}
{"op":"mcm","clk":"4234515085","pt":1631546560623,"mc":[{"id":"1.187560677","rc":[{"batb":[[0,1.45,12.83],[1,1.42,94.44],[2,1.41,98.89]],"batl":[[1,1.47,71.78]],"ltp":1.46,"tv":18333.19,"id":11439844}]}]}
{"op":"mcm","clk":"4234515137","pt":1631546561509,"mc":[{"id":"1.187560677","rc":[{"batb":[[0,3.1,4.14],[1,2,11.93],[2,1.8,11.93]],"batl":[[0,3.4,86.43],[1,3.45,4.7],[2,3.6,4.11]],"ltp":3.4,"tv":826.99,"id":7588306},{"batb":[[0,1.41,98.89],[1,1.39,93.91],[2,1.37,93.77]],"batl":[[0,1.46,125],[1,1.47,59.5],[2,1.82,476.07]],"ltp":1.46,"tv":18333.19,"id":11439844}]}]}
{"op":"mcm","clk":"4234515197","pt":1631546562244,"mc":[{"id":"1.187560677","rc":[{"batl":[[0,1.47,59.5],[1,1.82,476.07],[2,1.94,3.08]],"ltp":1.46,"tv":18333.19,"id":11439844}]}]}
{"op":"mcm","clk":"4234515381","pt":1631546563524,"mc":[{"id":"1.187560677","rc":[{"batl":[[0,3.45,4.7],[1,3.45,0],[2,3.6,0]],"ltp":3.4,"tv":826.99,"id":7588306},{"batb":[[1,1.28,493.1],[2,1.15,357.92]],"ltp":1.46,"tv":18333.19,"id":11439844}]}]}
{"op":"mcm","clk":"4234515534","pt":1631546564433,"mc":[{"id":"1.187560677","rc":[{"batl":[[1,3.5,4.67]],"ltp":3.4,"tv":826.99,"id":7588306},{"batb":[[1,1.4,93.41],[2,1.28,493.1]],"ltp":1.46,"tv":18333.19,"id":11439844}]}]}
{"op":"mcm","clk":"4234515874","pt":1631546568457,"mc":[{"id":"1.187560677","rc":[{"trd":[[3.15,32.21]],"batb":[[1,3,5.7],[2,2,11.93]],"batl":[[0,3.15,164.1],[1,3.25,12.3],[2,3.4,4.74]],"ltp":3.15,"tv":859.2,"id":7588306},{"trd":[[1.46,100.45],[1.47,24.2]],"batb":[[0,1.42,106.94],[1,1.41,98.89],[2,1.4,93.41]],"batl":[[0,1.47,47.4],[1,1.5,11.39],[2,1.52,380.31]],"ltp":1.47,"tv":18408.64,"id":11439844}],"tv":19267.85}]}
{"op":"mcm","clk":"4234516351","pt":1631546574343,"mc":[{"id":"1.187560677","rc":[{"batl":[[0,1.47,218.4]],"ltp":1.47,"tv":18408.64,"id":11439844}]}]}
{"op":"mcm","clk":"4234516646","pt":1631546578308,"mc":[{"id":"1.187560677","rc":[{"trd":[[3.15,35.26]],"batb":[[1,2,11.93],[2,1.8,11.93]],"batl":[[0,3.15,162.07]],"ltp":3.15,"tv":862.26,"id":7588306},{"trd":[[1.46,102.63]],"batl":[[1,1.52,380.31],[2,1.82,476.07]],"ltp":1.46,"tv":18410.82,"id":11439844}],"tv":19273.08}]}
{"op":"mcm","clk":"4234516844","pt":1631546581255,"mc":[{"id":"1.187560677","rc":[{"batb":[[0,1.46,12.55],[1,1.42,106.94],[2,1.41,98.89]],"batl":[[1,1.48,12.03],[2,1.52,380.31]],"ltp":1.46,"tv":18410.82,"id":11439844}]}]}
{"op":"mcm","clk":"4234517039","pt":1631546583967,"mc":[{"id":"1.187560677","rc":[{"trd":[[1.47,41.44]],"batl":[[0,1.47,209.78]],"ltp":1.47,"tv":18428.06,"id":11439844}],"tv":19290.32}]}
{"op":"mcm","clk":"4234517324","pt":1631546587696,"mc":[{"id":"1.187560677","rc":[{"trd":[[3.1,90.57]],"batb":[[0,2,11.93],[1,1.8,11.93],[2,1.7,17.05]],"ltp":3.1,"tv":952.83,"id":7588306},{"trd":[[1.47,214.98]],"batl":[[0,1.47,36.24]],"ltp":1.47,"tv":18601.6,"id":11439844}],"tv":19554.43}]}
{"op":"mcm","clk":"4234517352","pt":1631546587971,"mc":[{"id":"1.187560677","rc":[{"trd":[[1.46,105.51]],"batb":[[0,1.46,11.11]],"ltp":1.46,"tv":18604.48,"id":11439844}],"tv":19557.31}]}
{"op":"mcm","clk":"4234517565","pt":1631546590880,"mc":[{"id":"1.187560677","rc":[{"batb":[[0,2.02,11.02],[1,2,11.93],[2,1.8,11.93]],"ltp":3.1,"tv":952.83,"id":7588306}]}]}
{"op":"mcm","clk":"4234518178","pt":1631546598181,"mc":[{"id":"1.187560677","rc":[{"batb":[[0,1.42,106.94],[1,1.41,98.89],[2,1.4,93.41]],"batl":[[1,1.52,380.31],[2,1.82,476.07]],"ltp":1.46,"tv":18604.48,"id":11439844}]}]}
{"op":"mcm","clk":"4234518439","pt":1631546601478,"mc":[{"id":"1.187560677","rc":[{"batb":[[0,1.46,11.11],[1,1.42,106.94],[2,1.41,98.89]],"batl":[[0,1.47,171],[1,1.48,13.45],[2,1.52,380.31]],"ltp":1.46,"tv":18604.48,"id":11439844}]}]}
{"op":"mcm","clk":"4234518611","pt":1631546603584,"mc":[{"id":"1.187560677","rc":[{"batb":[[0,2,11.93],[1,1.8,11.93],[2,1.7,17.05]],"batl":[[0,3.6,5.26],[1,3.25,0],[2,3.4,0]],"ltp":3.1,"tv":952.83,"id":7588306},{"batb":[[0,1.39,145.91],[1,1.28,493.1],[2,1.15,357.92]],"batl":[[0,1.82,476.07],[1,1.94,3.08],[2,44,7.22]],"ltp":1.46,"tv":18604.48,"id":11439844}]}]}
{"op":"mcm","clk":"4234519130","pt":1631546610502,"mc":[{"id":"1.187560677","rc":[{"batb":[[0,3.1,204.42],[1,2,11.93],[2,1.8,11.93]],"ltp":3.1,"tv":952.83,"id":7588306},{"batb":[[0,1.42,504.91],[1,1.39,145.91],[2,1.28,493.1]],"batl":[[0,1.44,13.9],[1,1.82,476.07],[2,1.94,3.08]],"ltp":1.46,"tv":18604.48,"id":11439844}]}]}
{"op":"mcm","clk":"4234519671","pt":1631546616996,"mc":[{"id":"1.187560677","rc":[{"batl":[[0,3.45,7.1],[1,3.5,7.37],[2,3.6,5.26]],"ltp":3.1,"tv":952.83,"id":7588306},{"batb":[[1,1.41,156.89],[2,1.4,164.31]],"ltp":1.46,"tv":18604.48,"id":11439844}]}]}
{"op":"mcm","clk":"4234519928","pt":1631546620199,"mc":[{"id":"1.187560677","rc":[{"batl":[[0,1.44,181.9]],"ltp":1.46,"tv":18604.48,"id":11439844}]}]}
{"op":"mcm","clk":"4234520554","pt":1631546628407,"mc":[{"id":"1.187560677","rc":[{"batb":[[0,2,11.93],[1,1.8,11.93],[2,1.7,17.05]],"batl":[[0,3.5,7.37],[1,3.5,0],[2,3.6,0]],"ltp":3.1,"tv":952.83,"id":7588306},{"batb":[[0,1.28,493.1],[1,1.15,357.92],[2,1.11,271.16]],"batl":[[0,1.82,476.07],[1,1.94,3.08],[2,44,7.22]],"ltp":1.46,"tv":18604.48,"id":11439844}]}]}
{"op":"mcm","clk":"4234520777","pt":1631546631508,"mc":[{"id":"1.187560677","rc":[{"batb":[[0,1.4,178.06],[1,1.28,493.1],[2,1.15,357.92]],"ltp":1.46,"tv":18604.48,"id":11439844}]}]}
{"op":"mcm","clk":"4234520862","pt":1631546632832,"mc":[{"id":"1.187560677","rc":[{"batb":[[1,1.15,357.92],[2,1.11,271.16]],"batl":[[0,1.94,3.08],[1,44,7.22],[2,44,0]],"ltp":1.46,"tv":18604.48,"id":11439844}]}]}
{"op":"mcm","clk":"4234521005","pt":1631546634549,"mc":[{"id":"1.187560677","rc":[{"batb":[[0,3.25,199.28],[1,2,11.93],[2,1.8,11.93]],"batl":[[1,3.55,193.85]],"ltp":3.1,"tv":952.83,"id":7588306},{"batl":[[0,1.41,14.57],[1,1.46,27.4],[2,1.94,3.08]],"ltp":1.46,"tv":18604.48,"id":11439844}]}]}
{"op":"mcm","clk":"4234521124","pt":1631546636360,"mc":[{"id":"1.187560677","rc":[{"batb":[[1,1.23,524.14],[2,1.15,357.92]],"batl":[[2,1.73,535.39]],"ltp":1.46,"tv":18604.48,"id":11439844}]}]}
{"op":"mcm","clk":"4234521565","pt":1631546641631,"mc":[{"id":"1.187560677","rc":[{"batl":[[2,3.6,7.46]],"ltp":3.1,"tv":952.83,"id":7588306},{"batb":[[1,1.39,174.91],[2,1.38,161.46]],"batl":[[0,1.41,264.57]],"ltp":1.46,"tv":18604.48,"id":11439844}]}]}
{"op":"mcm","clk":"4234521817","pt":1631546645446,"mc":[{"id":"1.187560677","rc":[{"batb":[[0,2,11.93],[1,1.8,11.93],[2,1.7,17.05]],"batl":[[0,3.65,7.5],[1,3.55,0],[2,3.6,0]],"ltp":3.1,"tv":952.83,"id":7588306},{"batb":[[0,1.38,161.46],[1,1.23,524.14],[2,1.15,357.92]],"batl":[[0,1.41,250],[1,1.73,535.39],[2,1.94,3.08]],"ltp":1.46,"tv":18604.48,"id":11439844}]}]}
{"op":"mcm","clk":"4234521886","pt":1631546646266,"mc":[{"id":"1.187560677","rc":[{"batl":[[0,1.73,535.39],[1,1.94,3.08],[2,44,7.22]],"ltp":1.46,"tv":18604.48,"id":11439844}]}]}
{"op":"mcm","clk":"4234522106","pt":1631546648658,"mc":[{"id":"1.187560677","rc":[{"batl":[[0,3.6,7.16],[1,3.65,7.5]],"ltp":3.1,"tv":952.83,"id":7588306},{"batb":[[0,1.39,177.91],[1,1.38,161.46],[2,1.23,524.14]],"ltp":1.46,"tv":18604.48,"id":11439844}]}]}
{"op":"mcm","clk":"4234522122","pt":1631546648867,"mc":[{"id":"1.187560677","rc":[{"batl":[[0,3.65,7.5],[1,3.65,0]],"ltp":3.1,"tv":952.83,"id":7588306},{"batb":[[0,1.38,161.46],[1,1.23,524.14],[2,1.15,357.92]],"ltp":1.46,"tv":18604.48,"id":11439844}]}]}
{"op":"mcm","clk":"4234522336","pt":1631546652463,"mc":[{"id":"1.187560677","rc":[{"batl":[[1,3.7,212.07]],"ltp":3.1,"tv":952.83,"id":7588306},{"trd":[[1.39,3690.96]],"batl":[[0,1.42,429.55],[1,1.46,27.4],[2,1.73,535.39]],"ltp":1.39,"tv":18637.7,"id":11439844}],"tv":19590.53}]}
{"op":"mcm","clk":"4234522918","pt":1631546660480,"mc":[{"id":"1.187560677","rc":[{"batl":[[0,3.6,7.46],[1,3.65,7.5],[2,3.7,212.07]],"ltp":3.1,"tv":952.83,"id":7588306}]}]}
{"op":"mcm","clk":"4234523037","pt":1631546662266,"mc":[{"id":"1.187560677","rc":[{"batl":[[2,3.7,206.43]],"ltp":3.1,"tv":952.83,"id":7588306}]}]}
{"op":"mcm","clk":"4234523114","pt":1631546663156,"mc":[{"id":"1.187560677","rc":[{"batl":[[0,1.41,108],[1,1.42,429.55],[2,1.46,27.4]],"ltp":1.39,"tv":18637.7,"id":11439844}]}]}
{"op":"mcm","clk":"4234523243","pt":1631546664565,"mc":[{"id":"1.187560677","rc":[{"batl":[[2,3.7,0]],"ltp":3.1,"tv":952.83,"id":7588306},{"batl":[[1,1.73,535.39],[2,1.94,3.08]],"ltp":1.39,"tv":18637.7,"id":11439844}]}]}
{"op":"mcm","clk":"4234523325","pt":1631546665469,"mc":[{"id":"1.187560677","rc":[{"batl":[[0,3.65,7.5],[1,3.65,0]],"ltp":3.1,"tv":952.83,"id":7588306},{"batb":[[0,1.23,524.14],[1,1.15,357.92],[2,1.11,271.16]],"batl":[[0,1.73,535.39],[1,1.94,3.08],[2,44,7.22]],"ltp":1.39,"tv":18637.7,"id":11439844}]}]}
{"op":"mcm","clk":"4234523560","pt":1631546668395,"mc":[{"id":"1.187560677","rc":[{"batb":[[0,1.38,147.46],[1,1.23,524.14],[2,1.15,357.92]],"ltp":1.39,"tv":18637.7,"id":11439844}]}]}
{"op":"mcm","clk":"4234523782","pt":1631546671574,"mc":[{"id":"1.187560677","rc":[{"batl":[[0,3.6,6.66],[1,3.65,7.5]],"ltp":3.1,"tv":952.83,"id":7588306}]}]}
{"op":"mcm","clk":"4234523802","pt":1631546671886,"mc":[{"id":"1.187560677","rc":[{"batl":[[0,3.65,7.5],[1,3.65,0]],"ltp":3.1,"tv":952.83,"id":7588306}]}]}
{"op":"mcm","clk":"4234524272","pt":1631546678597,"mc":[{"id":"1.187560677","rc":[{"batl":[[0,3.6,6.96],[1,3.65,7.5]],"ltp":3.1,"tv":952.83,"id":7588306}]}]}
{"op":"mcm","clk":"4234524292","pt":1631546678905,"mc":[{"id":"1.187560677","rc":[{"batl":[[0,3.65,7.5],[1,3.65,0]],"ltp":3.1,"tv":952.83,"id":7588306}]}]}
{"op":"mcm","clk":"4234524805","pt":1631546685591,"mc":[{"id":"1.187560677","rc":[{"batl":[[0,3.6,7.16],[1,3.65,7.5]],"ltp":3.1,"tv":952.83,"id":7588306},{"batb":[[0,1.39,155.91],[1,1.38,147.46],[2,1.23,524.14]],"ltp":1.39,"tv":18637.7,"id":11439844}]}]}
{"op":"mcm","clk":"4234524826","pt":1631546685901,"mc":[{"id":"1.187560677","rc":[{"batl":[[0,3.65,7.5],[1,3.65,0]],"ltp":3.1,"tv":952.83,"id":7588306},{"batb":[[0,1.38,147.46],[1,1.23,524.14],[2,1.15,357.92]],"ltp":1.39,"tv":18637.7,"id":11439844}]}]}
{"op":"mcm","clk":"4234525271","pt":1631546691995,"mc":[{"id":"1.187560677","rc":[{"batb":[[1,1.15,357.92],[2,1.11,271.16]],"ltp":1.39,"tv":18637.7,"id":11439844}]}]}
{"op":"mcm","clk":"4234525327","pt":1631546692820,"mc":[{"id":"1.187560677","rc":[{"batl":[[0,3.6,6.96],[1,3.65,7.5]],"ltp":3.1,"tv":952.83,"id":7588306},{"batb":[[0,1.39,175.91],[1,1.38,147.46],[2,1.15,357.92]],"ltp":1.39,"tv":18637.7,"id":11439844}]}]}
{"op":"mcm","clk":"4234525459","pt":1631546694440,"mc":[{"id":"1.187560677","rc":[{"batb":[[0,3.2,188.59],[1,2,11.93],[2,1.8,11.93]],"ltp":3.1,"tv":952.83,"id":7588306},{"batb":[[0,1.41,45.05],[1,1.39,175.91],[2,1.38,1332.89]],"batl":[[0,1.43,11.61],[1,1.73,535.39],[2,1.94,3.08]],"ltp":1.39,"tv":18637.7,"id":11439844}]}]}
{"op":"mcm","clk":"4234525781","pt":1631546699235,"mc":[{"id":"1.187560677","rc":[{"trd":[[3.45,9.35]],"ltp":3.45,"tv":953.74,"id":7588306},{"trd":[[1.41,246.01]],"batb":[[0,1.41,40.54]],"ltp":1.41,"tv":18644.48,"id":11439844}],"tv":19598.22}]}
{"op":"mcm","clk":"4234525960","pt":1631546701343,"mc":[{"id":"1.187560677","rc":[{"batb":[[1,3.05,50.88],[2,3,71.72]],"batl":[[0,3.5,6.67],[1,3.55,45.69],[2,3.6,79.59]],"ltp":3.45,"tv":953.74,"id":7588306},{"batb":[[1,1.4,158.96],[2,1.39,322.22]],"batl":[[1,1.49,144.61],[2,1.5,116.08]],"ltp":1.41,"tv":18644.48,"id":11439844}]}]}
{"op":"mcm","clk":"4234526059","pt":1631546702443,"mc":[{"id":"1.187560677","rc":[{"batl":[[0,1.43,182.61]],"ltp":1.41,"tv":18644.48,"id":11439844}]}]}
{"op":"mcm","clk":"4234527092","pt":1631546714954,"mc":[{"id":"1.187560677","rc":[{"trd":[[1.41,256.83]],"batb":[[0,1.41,35.13]],"ltp":1.41,"tv":18655.3,"id":11439844}],"tv":19609.04}]}
{"op":"mcm","clk":"4234527263","pt":1631546717665,"mc":[{"id":"1.187560677","rc":[{"batb":[[0,3.05,50.88],[1,3,71.72],[2,2.98,78.57]],"ltp":3.45,"tv":953.74,"id":7588306},{"batb":[[0,1.4,158.96],[1,1.39,322.22],[2,1.38,311.29]],"batl":[[0,1.43,171]],"ltp":1.41,"tv":18655.3,"id":11439844}]}]}
{"op":"mcm","clk":"4234527283","pt":1631546717939,"mc":[{"id":"1.187560677","rc":[{"batl":[[0,3.55,45.69],[1,3.6,79.59],[2,3.65,74.23]],"ltp":3.45,"tv":953.74,"id":7588306},{"batb":[[0,1.39,322.22],[1,1.38,311.29],[2,1.37,182.44]],"ltp":1.41,"tv":18655.3,"id":11439844}]}]}
{"op":"mcm","clk":"4234527435","pt":1631546720253,"mc":[{"id":"1.187560677","rc":[{"batl":[[0,1.49,144.61],[1,1.5,116.08],[2,1.51,162.33]],"ltp":1.41,"tv":18655.3,"id":11439844}]}]}
{"op":"mcm","clk":"4234527675","pt":1631546723571,"mc":[{"id":"1.187560677","rc":[{"batb":[[0,2,11.93],[1,1.8,11.93],[2,1.7,17.05]],"batl":[[2,3.65,66.73]],"ltp":3.45,"tv":953.74,"id":7588306},{"batb":[[1,1.38,163.83]],"batl":[[0,1.73,535.39],[1,1.94,3.08],[2,44,7.22]],"ltp":1.41,"tv":18655.3,"id":11439844}]}]}
{"op":"mcm","clk":"4234527737","pt":1631546724564,"mc":[{"id":"1.187560677","rc":[{"batl":[[0,3.5,7.35],[1,3.55,45.69],[2,3.6,79.59]],"ltp":3.45,"tv":953.74,"id":7588306},{"batb":[[0,1.4,157.96],[1,1.39,322.22],[2,1.38,163.83]],"ltp":1.41,"tv":18655.3,"id":11439844}]}]}
{"op":"mcm","clk":"4234527786","pt":1631546725349,"mc":[{"id":"1.187560677","rc":[{"batl":[[0,3.55,45.69],[1,3.6,79.59],[2,3.65,66.73]],"ltp":3.45,"tv":953.74,"id":7588306},{"batb":[[0,1.39,322.22],[1,1.38,163.83],[2,1.37,182.44]],"ltp":1.41,"tv":18655.3,"id":11439844}]}]}
{"op":"mcm","clk":"4234527858","pt":1631546726483,"mc":[{"id":"1.187560677","rc":[{"batb":[[0,3.25,12.3],[1,2,11.93],[2,1.8,11.93]],"batl":[[0,3.55,50.98],[1,3.6,245.76]],"ltp":3.45,"tv":953.74,"id":7588306},{"batl":[[0,1.41,13.25],[1,1.43,382.28],[2,1.73,535.39]],"ltp":1.41,"tv":18655.3,"id":11439844}]}]}
{"op":"mcm","clk":"4234528332","pt":1631546733489,"mc":[{"id":"1.187560677","rc":[{"batb":[[1,3.05,70.5],[2,3,73.9]],"ltp":3.45,"tv":953.74,"id":7588306},{"batl":[[2,1.48,138.92]],"ltp":1.41,"tv":18655.3,"id":11439844}]}]}
{"op":"mcm","clk":"4234528973","pt":1631546743185,"mc":[{"id":"1.187560677","rc":[{"batl":[[0,1.41,211.25]],"ltp":1.41,"tv":18655.3,"id":11439844}]}]}
{"op":"mcm","clk":"4234529492","pt":1631546749490,"mc":[{"id":"1.187560677","rc":[{"trd":[[1.41,257.01]],"batl":[[0,1.41,211.16]],"ltp":1.41,"tv":18655.48,"id":11439844}],"tv":19609.23}]}
{"op":"mcm","clk":"4234530305","pt":1631546759728,"mc":[{"id":"1.187560677","rc":[{"batl":[[0,3.55,45.69]],"ltp":3.45,"tv":953.74,"id":7588306},{"batl":[[0,1.41,198]],"ltp":1.41,"tv":18655.48,"id":11439844}]}]}
{"op":"mcm","clk":"4234530544","pt":1631546762609,"mc":[{"id":"1.187560677","rc":[{"batl":[[0,3.55,51.01]],"ltp":3.45,"tv":953.74,"id":7588306},{"batl":[[0,1.41,211.16]],"ltp":1.41,"tv":18655.48,"id":11439844}]}]}
{"op":"mcm","clk":"4234530583","pt":1631546763121,"mc":[{"id":"1.187560677","rc":[{"trd":[[3.4,70.38]],"ltp":3.4,"tv":983.74,"id":7588306},{"trd":[[1.41,329.35]],"batl":[[0,1.41,138.82]],"ltp":1.41,"tv":18727.82,"id":11439844}],"tv":19711.57}]}
{"op":"mcm","clk":"4234532607","pt":1631546792378,"mc":[{"id":"1.187560677","rc":[{"batl":[[0,1.41,148.82]],"ltp":1.41,"tv":18727.82,"id":11439844}]}]}
{"op":"mcm","clk":"4234534924","pt":1631546824610,"mc":[{"id":"1.187560677","rc":[{"batb":[[0,3.05,70.5],[1,3,73.9],[2,2.98,90.27]],"batl":[[0,3.9,45.7],[1,3.95,67.97],[2,4,66.44]],"ltp":3.4,"tv":983.74,"id":7588306},{"batb":[[0,1.35,140.08],[1,1.34,307.92],[2,1.33,217.12]],"batl":[[0,1.41,135.66],[1,1.48,138.92],[2,1.49,120.46]],"ltp":1.41,"tv":18727.82,"id":11439844}]}]}
{"op":"mcm","clk":"4234534965","pt":1631546825294,"mc":[{"id":"1.187560677","rc":[{"batl":[[0,1.41,10]],"ltp":1.41,"tv":18727.82,"id":11439844}]}]}
{"op":"mcm","clk":"4234536175","pt":1631546841434,"mc":[{"id":"1.187560677","rc":[{"batl":[[0,1.48,138.92],[1,1.49,120.46],[2,1.5,181.25]],"ltp":1.41,"tv":18727.82,"id":11439844}]}]}
{"op":"mcm","clk":"4234536690","pt":1631546849229,"mc":[{"id":"1.187560677","rc":[{"batb":[[0,2,11.93],[1,1.8,11.93],[2,1.7,17.05]],"ltp":3.4,"tv":983.74,"id":7588306},{"batl":[[0,1.94,3.08],[1,44,7.22],[2,1.5,0]],"ltp":1.41,"tv":18727.82,"id":11439844}]}]}
{"op":"mcm","clk":"4234536863","pt":1631546852348,"mc":[{"id":"1.187560677","rc":[{"batb":[[0,3.6,11.12],[1,3.4,758.88],[2,2,11.93]],"ltp":3.4,"tv":983.74,"id":7588306},{"trd":[[1.35,9785.08]],"batb":[[0,1.35,120.11],[2,1.33,234.07]],"ltp":1.35,"tv":18767.74,"id":11439844}],"tv":19751.49}]}
{"op":"mcm","clk":"4234537160","pt":1631546857265,"mc":[{"id":"1.187560677","rc":[{"trd":[[3.9,127.7]],"batl":[[0,3.9,44.88]],"ltp":3.9,"tv":985.37,"id":7588306},{"trd":[[1.35,9789.91]],"batb":[[0,1.35,117.7]],"ltp":1.35,"tv":18772.57,"id":11439844}],"tv":19757.95}]}
{"op":"mcm","clk":"4234537276","pt":1631546859077,"mc":[{"id":"1.187560677","rc":[{"batb":[[1,3.5,121.76],[2,3.4,758.88]],"ltp":3.9,"tv":985.37,"id":7588306},{"batl":[[0,1.4,304.4],[1,1.94,3.08],[2,44,7.22]],"ltp":1.35,"tv":18772.57,"id":11439844}]}]}
{"op":"mcm","clk":"4234537374","pt":1631546860438,"mc":[{"id":"1.187560677","rc":[{"batb":[[1,3.55,131.54],[2,3.5,121.76]],"ltp":3.9,"tv":985.37,"id":7588306},{"batl":[[0,1.39,403.95],[1,1.4,304.4],[2,1.94,3.08]],"ltp":1.35,"tv":18772.57,"id":11439844}]}]}
{"op":"mcm","clk":"4234537521","pt":1631546862561,"mc":[{"id":"1.187560677","rc":[{"batb":[[2,1.33,217.12]],"batl":[[0,1.39,335.95]],"ltp":1.35,"tv":18772.57,"id":11439844}]}]}
{"op":"mcm","clk":"4234537743","pt":1631546865682,"mc":[{"id":"1.187560677","rc":[{"batb":[[1,1.34,325.98]],"batl":[[0,1.36,17.06],[1,1.38,101],[2,1.39,335.95]],"ltp":1.35,"tv":18772.57,"id":11439844}]}]}
{"op":"mcm","clk":"4234537858","pt":1631546867465,"mc":[{"id":"1.187560677","rc":[{"batb":[[1,3.4,758.88],[2,2,11.93]],"ltp":3.9,"tv":985.37,"id":7588306},{"batl":[[2,1.94,3.08]],"ltp":1.35,"tv":18772.57,"id":11439844}]}]}
{"op":"mcm","clk":"4234537885","pt":1631546867880,"mc":[{"id":"1.187560677","rc":[{"batl":[[1,1.94,3.08],[2,44,7.22]],"ltp":1.35,"tv":18772.57,"id":11439844}]}]}
{"op":"mcm","clk":"4234538031","pt":1631546869695,"mc":[{"id":"1.187560677","rc":[{"batb":[[0,2,11.93],[1,1.8,11.93],[2,1.7,17.05]],"batl":[[0,5,4.89],[1,3.95,0],[2,4,0]],"ltp":3.9,"tv":985.37,"id":7588306},{"batb":[[0,1.25,162.49],[1,1.15,357.92],[2,1.11,271.16]],"batl":[[0,1.94,3.08],[1,44,7.22],[2,44,0]],"ltp":1.35,"tv":18772.57,"id":11439844}]}]}
{"op":"mcm","clk":"4234538446","pt":1631546875588,"mc":[{"id":"1.187560677","rc":[{"batb":[[0,3.85,20.37],[1,2,11.93],[2,1.8,11.93]],"batl":[[0,4,21.4],[1,5,4.89]],"ltp":3.9,"tv":985.37,"id":7588306},{"batl":[[0,1.36,22.07],[1,1.94,3.08],[2,44,7.22]],"ltp":1.35,"tv":18772.57,"id":11439844}]}]}
{"op":"mcm","clk":"4234538509","pt":1631546876575,"mc":[{"id":"1.187560677","rc":[{"batb":[[0,2,11.93],[1,1.8,11.93],[2,1.7,17.05]],"batl":[[0,4.6,5.16]],"ltp":3.9,"tv":985.37,"id":7588306},{"batb":[[0,1.28,173.91],[1,1.25,162.49],[2,1.15,357.92]],"batl":[[0,1.94,3.08],[1,44,7.22],[2,44,0]],"ltp":1.35,"tv":18772.57,"id":11439844}]}]}
{"op":"mcm","clk":"4234538535","pt":1631546876892,"mc":[{"id":"1.187560677","rc":[{"batl":[[0,5,4.89],[1,5,0]],"ltp":3.9,"tv":985.37,"id":7588306},{"batb":[[0,1.25,162.49],[1,1.15,357.92],[2,1.11,271.16]],"ltp":1.35,"tv":18772.57,"id":11439844}]}]}
{"op":"mcm","clk":"4234539015","pt":1631546883682,"mc":[{"id":"1.187560677","rc":[{"batl":[[0,4.6,5.26],[1,5,4.89]],"ltp":3.9,"tv":985.37,"id":7588306},{"batb":[[0,1.28,166.41],[1,1.25,162.49],[2,1.15,357.92]],"ltp":1.35,"tv":18772.57,"id":11439844}]}]}
{"op":"mcm","clk":"4234539034","pt":1631546883888,"mc":[{"id":"1.187560677","rc":[{"batl":[[0,5,4.89],[1,5,0]],"ltp":3.9,"tv":985.37,"id":7588306},{"batb":[[0,1.25,162.49],[1,1.15,357.92],[2,1.11,271.16]],"ltp":1.35,"tv":18772.57,"id":11439844}]}]}
{"op":"mcm","clk":"4234539474","pt":1631546890610,"mc":[{"id":"1.187560677","rc":[{"batl":[[0,4.6,5.46],[1,5,4.89]],"ltp":3.9,"tv":985.37,"id":7588306},{"batb":[[0,1.28,176.41],[1,1.25,162.49],[2,1.15,357.92]],"ltp":1.35,"tv":18772.57,"id":11439844}]}]}
{"op":"mcm","clk":"4234539501","pt":1631546890912,"mc":[{"id":"1.187560677","rc":[{"batl":[[0,5,4.89],[1,5,0]],"ltp":3.9,"tv":985.37,"id":7588306},{"batb":[[0,1.25,162.49],[1,1.15,357.92],[2,1.11,271.16]],"ltp":1.35,"tv":18772.57,"id":11439844}]}]}
{"op":"mcm","clk":"4234539988","pt":1631546897428,"mc":[{"id":"1.187560677","rc":[{"batb":[[0,3.4,185.92],[1,2,11.93],[2,1.8,11.93]],"batl":[[0,3.6,7.27],[1,3.65,21.3],[2,3.75,192.92]],"ltp":3.9,"tv":985.37,"id":7588306},{"batb":[[0,1.38,167.96],[1,1.25,162.49],[2,1.15,357.92]],"batl":[[0,1.41,19.03],[1,1.94,3.08],[2,44,7.22]],"ltp":1.35,"tv":18772.57,"id":11439844}]}]}
{"op":"mcm","clk":"4234540296","pt":1631546901634,"mc":[{"id":"1.187560677","rc":[{"trd":[[3.6,14.54]],"batb":[[0,3.6,13.3],[1,3.4,185.92],[2,2,11.93]],"batl":[[0,3.65,21.3],[1,3.75,192.92],[2,3.85,10.38]],"ltp":3.6,"tv":999.91,"id":7588306}],"tv":19772.49}]}
{"op":"mcm","clk":"4234540327","pt":1631546902049,"mc":[{"id":"1.187560677","rc":[{"batb":[[0,3.4,185.92],[1,2,11.93],[2,1.8,11.93]],"ltp":3.6,"tv":999.91,"id":7588306}]}]}
{"op":"mcm","clk":"4234540542","pt":1631546904825,"mc":[{"id":"1.187560677","rc":[{"batb":[[1,1.32,172.39],[2,1.29,148.81]],"batl":[[0,1.39,200],[1,1.41,19.03],[2,1.94,3.08]],"ltp":1.35,"tv":18772.57,"id":11439844}]}]}
{"op":"mcm","clk":"4234540634","pt":1631546905860,"mc":[{"id":"1.187560677","rc":[{"batb":[[2,1.31,167.79]],"ltp":1.35,"tv":18772.57,"id":11439844}]}]}
{"op":"mcm","clk":"4234540944","pt":1631546910333,"mc":[{"id":"1.187560677","rc":[{"trd":[[1.38,249.12]],"batb":[[0,1.38,157.96]],"ltp":1.38,"tv":18792.57,"id":11439844}],"tv":19792.49}]}
{"op":"mcm","clk":"4234541040","pt":1631546911835,"mc":[{"id":"1.187560677","rc":[{"batl":[[1,1.94,3.08],[2,44,7.22]],"ltp":1.38,"tv":18792.57,"id":11439844}]}]}
{"op":"mcm","clk":"4234541232","pt":1631546914735,"mc":[{"id":"1.187560677","rc":[{"batb":[[0,3.55,4.58],[1,3.4,185.92],[2,2,11.93]],"batl":[[1,3.7,8.64],[2,3.75,192.92]],"ltp":3.6,"tv":999.91,"id":7588306}]}]}
{"op":"mcm","clk":"4234541681","pt":1631546920667,"mc":[{"id":"1.187560677","rc":[{"batb":[[0,2,11.93],[1,1.8,11.93],[2,1.7,17.05]],"batl":[[1,4.2,5.98],[2,4.3,5.65]],"ltp":3.6,"tv":999.91,"id":7588306}]}]}
{"op":"mcm","clk":"4234541733","pt":1631546921346,"mc":[{"id":"1.187560677","rc":[{"batl":[[0,4.6,5.16],[1,4.2,0],[2,4.3,0]],"ltp":3.6,"tv":999.91,"id":7588306},{"batb":[[0,1.28,151.66],[1,1.15,357.92],[2,1.1,298.27]],"batl":[[0,1.94,3.08],[1,44,7.22],[2,44,0]],"ltp":1.38,"tv":18792.57,"id":11439844}]}]}
{"op":"mcm","clk":"4234542638","pt":1631546934685,"mc":[{"id":"1.187560677","rc":[{"batl":[[0,4.3,5.05],[1,4.6,5.16]],"ltp":3.6,"tv":999.91,"id":7588306},{"batb":[[0,1.31,154.79],[1,1.28,151.66],[2,1.15,357.92]],"ltp":1.38,"tv":18792.57,"id":11439844}]}]}
{"op":"mcm","clk":"4234542696","pt":1631546935368,"mc":[{"id":"1.187560677","rc":[{"batl":[[0,3.45,21.7],[1,3.7,660.65],[2,4.6,5.16]],"ltp":3.6,"tv":999.91,"id":7588306},{"batb":[[0,1.42,16.56],[1,1.41,188.25],[2,1.28,151.66]],"batl":[[0,1.44,10.86],[1,1.47,494.57],[2,1.94,3.08]],"ltp":1.38,"tv":18792.57,"id":11439844}]}]}
{"op":"mcm","clk":"4234542817","pt":1631546937165,"mc":[{"id":"1.187560677","rc":[{"batl":[[2,1.77,508.04]],"ltp":1.38,"tv":18792.57,"id":11439844}]}]}
{"op":"mcm","clk":"4234543210","pt":1631546942805,"mc":[{"id":"1.187560677","rc":[{"batl":[[1,3.65,6.7],[2,3.7,660.65]],"ltp":3.6,"tv":999.91,"id":7588306},{"batb":[[2,1.38,148.96]],"ltp":1.38,"tv":18792.57,"id":11439844}]}]}
{"op":"mcm","clk":"4234543464","pt":1631546946406,"mc":[{"id":"1.187560677","rc":[{"batl":[[2,3.8,5.52]],"ltp":3.6,"tv":999.91,"id":7588306},{"batb":[[0,1.41,159.89],[1,1.38,148.96],[2,1.36,157.93]],"batl":[[0,1.44,120],[1,1.77,508.04],[2,1.94,3.08]],"ltp":1.38,"tv":18792.57,"id":11439844}]}]}
{"op":"mcm","clk":"4234543546","pt":1631546947386,"mc":[{"id":"1.187560677","rc":[{"batl":[[0,3.8,5.52],[1,3.65,0],[2,3.8,0]],"ltp":3.6,"tv":999.91,"id":7588306},{"batb":[[0,1.25,512.59],[1,1.15,357.92],[2,1.1,298.27]],"batl":[[0,1.77,508.04],[1,1.94,3.08],[2,44,7.22]],"ltp":1.38,"tv":18792.57,"id":11439844}]}]}
{"op":"mcm","clk":"4234543708","pt":1631546950188,"mc":[{"id":"1.187560677","rc":[{"batb":[[0,1.36,153.93],[1,1.25,512.59],[2,1.15,357.92]],"ltp":1.38,"tv":18792.57,"id":11439844}]}]}
{"op":"mcm","clk":"4234543871","pt":1631546952623,"mc":[{"id":"1.187560677","rc":[{"batb":[[0,3.35,20.67],[1,2,11.93],[2,1.8,11.93]],"batl":[[0,3.45,21.3],[1,3.8,5.52]],"ltp":3.6,"tv":999.91,"id":7588306},{"batl":[[0,1.43,18.64],[1,1.77,508.04],[2,1.94,3.08]],"ltp":1.38,"tv":18792.57,"id":11439844}]}]}
{"op":"mcm","clk":"4234543956","pt":1631546953711,"mc":[{"id":"1.187560677","rc":[{"batb":[[0,2,11.93],[1,1.8,11.93],[2,1.7,17.05]],"batl":[[0,3.65,6.1]],"ltp":3.6,"tv":999.91,"id":7588306},{"batb":[[0,1.38,147.46],[1,1.36,153.93],[2,1.25,512.59]],"batl":[[0,1.77,508.04],[1,1.94,3.08],[2,44,7.22]],"ltp":1.38,"tv":18792.57,"id":11439844}]}]}
{"op":"mcm","clk":"4234543975","pt":1631546954023,"mc":[{"id":"1.187560677","rc":[{"batl":[[0,3.8,5.52],[1,3.8,0]],"ltp":3.6,"tv":999.91,"id":7588306},{"batb":[[0,1.36,153.93],[1,1.25,512.59],[2,1.15,357.92]],"ltp":1.38,"tv":18792.57,"id":11439844}]}]}
{"op":"mcm","clk":"4234544449","pt":1631546959951,"mc":[{"id":"1.187560677","rc":[{"batb":[[1,1.15,357.92],[2,1.1,298.27]],"batl":[[0,1.94,3.08],[1,44,7.22],[2,44,0]],"ltp":1.38,"tv":18792.57,"id":11439844}]}]}
{"op":"mcm","clk":"4234544679","pt":1631546962603,"mc":[{"id":"1.187560677","rc":[{"batl":[[0,3.65,6.1],[1,3.8,5.52]],"ltp":3.6,"tv":999.91,"id":7588306},{"batb":[[0,1.38,155.96],[1,1.36,153.93],[2,1.15,357.92]],"ltp":1.38,"tv":18792.57,"id":11439844}]}]}
{"op":"mcm","clk":"4234544692","pt":1631546962910,"mc":[{"id":"1.187560677","rc":[{"batl":[[0,3.8,5.52],[1,3.8,0]],"ltp":3.6,"tv":999.91,"id":7588306},{"batb":[[0,1.36,153.93],[1,1.15,357.92],[2,1.1,298.27]],"ltp":1.38,"tv":18792.57,"id":11439844}]}]}
{"op":"mcm","clk":"4234544874","pt":1631546965503,"mc":[{"id":"1.187560677","rc":[{"batl":[[1,3.9,216.53]],"ltp":3.6,"tv":999.91,"id":7588306},{"batb":[[0,1.36,168.39]],"batl":[[0,1.38,18.65],[1,1.4,28.58],[2,1.41,722.57]],"ltp":1.38,"tv":18792.57,"id":11439844}]}]}
{"op":"mcm","clk":"4234545339","pt":1631546972346,"mc":[{"id":"1.187560677","rc":[{"batb":[[0,2.38,91.81],[1,2,11.93],[2,1.8,11.93]],"batl":[[2,4.8,4.42]],"ltp":3.6,"tv":999.91,"id":7588306},{"batb":[[1,1.27,156.87],[2,1.24,146.77]],"ltp":1.38,"tv":18792.57,"id":11439844}]}]}
{"op":"mcm","clk":"4234545517","pt":1631546975422,"mc":[{"id":"1.187560677","rc":[{"batl":[[0,1.38,146.65]],"ltp":1.38,"tv":18792.57,"id":11439844}]}]}
{"op":"mcm","clk":"4234545544","pt":1631546975836,"mc":[{"id":"1.187560677","rc":[{"batb":[[0,2,11.93],[1,1.8,11.93],[2,1.7,17.05]],"ltp":3.6,"tv":999.91,"id":7588306}]}]}
{"op":"mcm","clk":"4234545776","pt":1631546978917,"mc":[{"id":"1.187560677","rc":[{"batb":[[0,2.3,58.24],[1,2,11.93],[2,1.8,11.93]],"ltp":3.6,"tv":999.91,"id":7588306}]}]}
{"op":"mcm","clk":"4234545861","pt":1631546980425,"mc":[{"id":"1.187560677","rc":[{"batb":[[0,2,11.93],[1,1.8,11.93],[2,1.7,17.05]],"ltp":3.6,"tv":999.91,"id":7588306}]}]}
{"op":"mcm","clk":"4234546059","pt":1631546983534,"mc":[{"id":"1.187560677","rc":[{"trd":[[3.8,10]],"batb":[[0,2.26,17.75],[1,2,11.93],[2,1.8,11.93]],"batl":[[0,3.9,217.05],[1,4.8,4.42],[2,5.2,4.08]],"ltp":3.8,"tv":1009.91,"id":7588306}],"tv":19802.49}]}
{"op":"mcm","clk":"4234546076","pt":1631546983740,"mc":[{"id":"1.187560677","rc":[{"batb":[[0,2,11.93],[1,1.8,11.93],[2,1.7,17.05]],"ltp":3.8,"tv":1009.91,"id":7588306}]}]}
{"op":"mcm","clk":"4234546284","pt":1631546986864,"mc":[{"id":"1.187560677","rc":[{"batb":[[0,2.54,16.01],[1,2,11.93],[2,1.8,11.93]],"ltp":3.8,"tv":1009.91,"id":7588306}]}]}
{"op":"mcm","clk":"4234546430","pt":1631546988649,"mc":[{"id":"1.187560677","rc":[{"batb":[[0,2,11.93],[1,1.8,11.93],[2,1.7,17.05]],"batl":[[0,4.8,4.42],[1,5.2,4.08],[2,5.2,0]],"ltp":3.8,"tv":1009.91,"id":7588306},{"batb":[[0,1.27,156.87],[1,1.24,146.77],[2,1.15,357.92]],"batl":[[0,1.38,128],[1,1.94,3.08],[2,44,7.22]],"ltp":1.38,"tv":18792.57,"id":11439844}]}]}
{"op":"mcm","clk":"4234546496","pt":1631546989275,"mc":[{"id":"1.187560677","rc":[{"batl":[[0,5.2,4.08],[1,5.2,0]],"ltp":3.8,"tv":1009.91,"id":7588306},{"batb":[[0,1.24,146.77],[1,1.15,357.92],[2,1.1,298.27]],"batl":[[0,1.94,3.08],[1,44,7.22],[2,44,0]],"ltp":1.38,"tv":18792.57,"id":11439844}]}]}
{"op":"mcm","clk":"4234547089","pt":1631546995448,"mc":[{"id":"1.187560677","rc":[{"batb":[[0,3.3,4.59],[1,3.15,222.38],[2,2,11.93]],"batl":[[0,3.4,6.08],[1,3.45,21.1],[2,3.5,122.54]],"ltp":3.8,"tv":1009.91,"id":7588306},{"batb":[[0,1.41,153.89],[1,1.4,306.36],[2,1.38,28.98]],"ltp":1.38,"tv":18792.57,"id":11439844}]}]}
{"op":"mcm","clk":"4234548018","pt":1631547006181,"mc":[{"id":"1.187560677","rc":[{"batl":[[0,1.44,66],[1,1.94,3.08],[2,44,7.22]],"ltp":1.38,"tv":18792.57,"id":11439844}]}]}
{"op":"mcm","clk":"4234548794","pt":1631547014106,"mc":[{"id":"1.187560677","rc":[{"batl":[[0,1.94,3.08],[1,44,7.22],[2,44,0]],"ltp":1.38,"tv":18792.57,"id":11439844}]}]}
{"op":"mcm","clk":"4234549042","pt":1631547017274,"mc":[{"id":"1.187560677","rc":[{"batl":[[0,1.43,257],[1,1.94,3.08],[2,44,7.22]],"ltp":1.38,"tv":18792.57,"id":11439844}]}]}
{"op":"mcm","clk":"4234549396","pt":1631547021692,"mc":[{"id":"1.187560677","rc":[{"batb":[[0,2,11.93],[1,1.8,11.93],[2,1.7,17.05]],"batl":[[0,3.9,5.85],[1,3.45,0],[2,3.5,0]],"ltp":3.8,"tv":1009.91,"id":7588306},{"batb":[[0,1.35,139.07],[1,1.15,357.92],[2,1.1,298.27]],"ltp":1.38,"tv":18792.57,"id":11439844}]}]}
{"op":"mcm","clk":"4234549443","pt":1631547022320,"mc":[{"id":"1.187560677","rc":[{"batl":[[0,1.94,3.08],[1,44,7.22],[2,44,0]],"ltp":1.38,"tv":18792.57,"id":11439844}]}]}
{"op":"mcm","clk":"4234549534","pt":1631547023100,"mc":[{"id":"1.187560677","rc":[{"batl":[[0,3.3,20],[1,3.9,5.85]],"ltp":3.8,"tv":1009.91,"id":7588306}]}]}
{"op":"mcm","clk":"4234550035","pt":1631547028517,"mc":[{"id":"1.187560677","rc":[{"batl":[[1,3.75,6.3],[2,3.9,5.85]],"ltp":3.8,"tv":1009.91,"id":7588306},{"batb":[[0,1.37,134.77],[1,1.35,139.07],[2,1.15,357.92]],"ltp":1.38,"tv":18792.57,"id":11439844}]}]}
{"op":"mcm","clk":"4234550074","pt":1631547028990,"mc":[{"id":"1.187560677","rc":[{"trd":[[3.3,20]],"batb":[[0,3.55,197.47],[1,2,11.93],[2,1.8,11.93]],"batl":[[0,3.85,4.93],[1,3.9,5.85],[2,4,237.21]],"ltp":3.3,"tv":1029.91,"id":7588306},{"trd":[[1.37,844.12],[1.43,67.49]],"batb":[[0,1.35,139.07],[1,1.15,357.92],[2,1.1,298.27]],"ltp":1.37,"tv":19098.5,"id":11439844}],"tv":20128.42}]}
{"op":"mcm","clk":"4234550393","pt":1631547032642,"mc":[{"id":"1.187560677","rc":[{"batb":[[1,3.3,11.12],[2,2,11.93]],"ltp":3.3,"tv":1029.91,"id":7588306}]}]}
{"op":"mcm","clk":"4234550516","pt":1631547034101,"mc":[{"id":"1.187560677","rc":[{"batb":[[1,2,11.93],[2,1.8,11.93]],"ltp":3.3,"tv":1029.91,"id":7588306}]}]}
{"op":"mcm","clk":"4234550749","pt":1631547037302,"mc":[{"id":"1.187560677","rc":[{"batb":[[1,3.35,8.07],[2,3.25,8.65]],"ltp":3.3,"tv":1029.91,"id":7588306},{"batb":[[1,1.28,92.66],[2,1.25,95.61]],"batl":[[0,1.42,6.75],[1,1.44,6.33],[2,1.94,3.08]],"ltp":1.37,"tv":19098.5,"id":11439844}]}]}
{"op":"mcm","clk":"4234550812","pt":1631547038093,"mc":[{"id":"1.187560677","rc":[{"trd":[[1.35,9960.44]],"batb":[[0,1.35,53.8]],"ltp":1.35,"tv":19269.04,"id":11439844}],"tv":20298.96}]}
{"op":"mcm","clk":"4234550910","pt":1631547038976,"mc":[{"id":"1.187560677","rc":[{"batl":[[0,3.9,5.85],[1,4,237.21],[2,4.6,2.86]],"ltp":3.3,"tv":1029.91,"id":7588306}]}]}
{"op":"mcm","clk":"4234551173","pt":1631547041950,"mc":[{"id":"1.187560677","rc":[{"batb":[[0,1.36,16.82],[1,1.35,53.8],[2,1.28,92.66]],"batl":[[0,1.38,15.93],[1,1.42,6.75],[2,1.44,6.33]],"ltp":1.35,"tv":19269.04,"id":11439844}]}]}
{"op":"mcm","clk":"4234551381","pt":1631547044386,"mc":[{"id":"1.187560677","rc":[{"batb":[[0,2,11.93],[1,1.8,11.93],[2,1.7,17.05]],"batl":[[0,5,2.62],[1,4,0],[2,4.6,0]],"ltp":3.3,"tv":1029.91,"id":7588306},{"batb":[[0,1.25,95.61],[1,1.15,357.92],[2,1.1,298.27]],"batl":[[0,1.94,3.08],[1,44,7.22],[2,1.44,0]],"ltp":1.35,"tv":19269.04,"id":11439844}]}]}
{"op":"mcm","clk":"4234551512","pt":1631547046360,"mc":[{"id":"1.187560677","rc":[{"batb":[[0,3.25,3.65],[1,2,11.93],[2,1.8,11.93]],"batl":[[1,5.4,2.04]],"ltp":3.3,"tv":1029.91,"id":7588306},{"batb":[[1,1.23,112.63],[2,1.15,357.92]],"batl":[[0,1.44,60.58],[1,1.94,3.08],[2,44,7.22]],"ltp":1.35,"tv":19269.04,"id":11439844}]}]}
{"op":"mcm","clk":"4234551600","pt":1631547047554,"mc":[{"id":"1.187560677","rc":[{"batb":[[0,3.35,8.67],[1,3.25,11.3],[2,2,11.93]],"ltp":3.3,"tv":1029.91,"id":7588306},{"batl":[[0,1.42,6.25],[1,1.44,66.41],[2,1.94,3.08]],"ltp":1.35,"tv":19269.04,"id":11439844}]}]}
{"op":"mcm","clk":"4234551615","pt":1631547047761,"mc":[{"id":"1.187560677","rc":[{"batb":[[0,3.25,3.65],[1,2,11.93],[2,1.8,11.93]],"ltp":3.3,"tv":1029.91,"id":7588306},{"batl":[[0,1.44,60.58],[1,1.94,3.08],[2,44,7.22]],"ltp":1.35,"tv":19269.04,"id":11439844}]}]}
{"op":"mcm","clk":"4234551780","pt":1631547049582,"mc":[{"id":"1.187560677","rc":[{"batb":[[0,3.35,3.87],[1,3.25,3.65],[2,2,11.93]],"ltp":3.3,"tv":1029.91,"id":7588306},{"batl":[[0,1.42,58.25],[1,1.44,60.58],[2,1.94,3.08]],"ltp":1.35,"tv":19269.04,"id":11439844}]}]}
{"op":"mcm","clk":"4234551828","pt":1631547050098,"mc":[{"id":"1.187560677","rc":[{"batb":[[0,3.25,3.65],[1,2,11.93],[2,1.8,11.93]],"ltp":3.3,"tv":1029.91,"id":7588306},{"batl":[[0,1.44,60.58],[1,1.94,3.08],[2,44,7.22]],"ltp":1.35,"tv":19269.04,"id":11439844}]}]}
{"op":"mcm","clk":"4234552191","pt":1631547054504,"mc":[{"id":"1.187560677","rc":[{"batb":[[0,3.35,8.47],[1,3.25,11.94],[2,2,11.93]],"batl":[[0,4.6,2.06],[1,5,2.62],[2,5.4,2.04]],"ltp":3.3,"tv":1029.91,"id":7588306},{"batb":[[0,1.28,88.91],[1,1.25,95.61],[2,1.23,112.63]],"batl":[[0,1.42,6.75],[1,1.44,66.41],[2,1.94,3.08]],"ltp":1.35,"tv":19269.04,"id":11439844}]}]}
{"op":"mcm","clk":"4234552213","pt":1631547054815,"mc":[{"id":"1.187560677","rc":[{"batb":[[0,3.25,3.65],[1,2,11.93],[2,1.8,11.93]],"batl":[[0,5,2.62],[1,5.4,2.04],[2,5.4,0]],"ltp":3.3,"tv":1029.91,"id":7588306},{"batb":[[0,1.25,95.61],[1,1.23,112.63],[2,1.15,357.92]],"batl":[[0,1.44,60.58],[1,1.94,3.08],[2,44,7.22]],"ltp":1.35,"tv":19269.04,"id":11439844}]}]}
{"op":"mcm","clk":"4234552721","pt":1631547061469,"mc":[{"id":"1.187560677","rc":[{"batb":[[0,3.35,7.87],[1,3.25,12.18],[2,2,11.93]],"batl":[[0,4.6,2.01],[1,5,2.62],[2,5.4,2.04]],"ltp":3.3,"tv":1029.91,"id":7588306},{"batb":[[0,1.28,79.41],[1,1.25,95.61],[2,1.23,112.63]],"batl":[[0,1.42,6.25],[1,1.44,66.91],[2,1.94,3.08]],"ltp":1.35,"tv":19269.04,"id":11439844}]}]}
{"op":"mcm","clk":"4234552746","pt":1631547061787,"mc":[{"id":"1.187560677","rc":[{"batb":[[0,3.25,3.65],[1,2,11.93],[2,1.8,11.93]],"batl":[[0,5,2.62],[1,5.4,2.04],[2,5.4,0]],"ltp":3.3,"tv":1029.91,"id":7588306},{"batb":[[0,1.25,95.61],[1,1.23,112.63],[2,1.15,357.92]],"batl":[[0,1.44,60.58],[1,1.94,3.08],[2,44,7.22]],"ltp":1.35,"tv":19269.04,"id":11439844}]}]}
{"op":"mcm","clk":"4234553019","pt":1631547065387,"mc":[{"id":"1.187560677","rc":[{"batl":[[0,1.94,3.08],[1,44,7.22],[2,44,0]],"ltp":1.35,"tv":19269.04,"id":11439844}]}]}
{"op":"mcm","clk":"4234553162","pt":1631547067517,"mc":[{"id":"1.187560677","rc":[{"batb":[[0,4.4,4.75],[1,4.2,5.27],[2,3.6,1177.94]],"batl":[[0,5,140.7]],"ltp":3.3,"tv":1029.91,"id":7588306},{"batb":[[0,1.28,15.54],[1,1.25,647.95],[2,1.23,112.63]],"batl":[[0,1.31,36.17],[1,1.94,3.08],[2,44,7.22]],"ltp":1.35,"tv":19269.04,"id":11439844}]}]}
{"op":"mcm","clk":"4234553404","pt":1631547070488,"mc":[{"id":"1.187560677","rc":[{"trd":[[4.4,1.26]],"batb":[[0,4.4,4.12]],"ltp":4.4,"tv":1031.17,"id":7588306}],"tv":20300.22}]}
{"op":"mcm","clk":"4234553580","pt":1631547072626,"mc":[{"id":"1.187560677","rc":[{"trd":[[4.4,1.74]],"batb":[[0,4.4,3.64]],"ltp":4.4,"tv":1031.65,"id":7588306},{"trd":[[1.3,1.62]],"ltp":1.3,"tv":19270.66,"id":11439844}],"tv":20302.32}]}
{"op":"mcm","clk":"4234553700","pt":1631547074091,"mc":[{"id":"1.187560677","rc":[{"batb":[[2,3.6,1185.08]],"batl":[[2,8.2,2]],"ltp":4.4,"tv":1031.65,"id":7588306},{"batl":[[1,1.38,5.75],[2,1.41,6.11]],"ltp":1.3,"tv":19270.66,"id":11439844}]}]}
{"op":"mcm","clk":"4234554147","pt":1631547079247,"mc":[{"id":"1.187560677","rc":[{"trd":[[1.25,197],[1.28,31.08]],"batb":[[0,1.25,549.45],[1,1.23,112.63],[2,1.15,357.92]],"ltp":1.25,"tv":19498.74,"id":11439844}],"tv":20530.4}]}
{"op":"mcm","clk":"4234554235","pt":1631547080546,"mc":[{"id":"1.187560677","rc":[{"batb":[[0,4.2,5.27],[1,3.6,1185.08],[2,3.4,7.51]],"ltp":4.4,"tv":1031.65,"id":7588306}]}]}
{"op":"mcm","clk":"4234554743","pt":1631547086521,"mc":[{"id":"1.187560677","rc":[{"batl":[[0,4.7,7.43],[1,5,140.7],[2,5.4,2.04]],"ltp":4.4,"tv":1031.65,"id":7588306},{"batl":[[0,1.29,18.85],[1,1.31,36.17],[2,1.38,5.75]],"ltp":1.25,"tv":19498.74,"id":11439844}]}]}
{"op":"mcm","clk":"4234554830","pt":1631547087812,"mc":[{"id":"1.187560677","rc":[{"batb":[[1,3.6,1188.62],[2,3.4,11.32]],"ltp":4.4,"tv":1031.65,"id":7588306},{"trd":[[1.29,0.7]],"batl":[[0,1.29,18.5],[2,1.38,66]],"ltp":1.29,"tv":19499.43,"id":11439844}],"tv":20531.09}]}
{"op":"mcm","clk":"4234554936","pt":1631547089427,"mc":[{"id":"1.187560677","rc":[{"batl":[[0,5,140.7],[1,5.4,2.04],[2,8.2,2]],"ltp":4.4,"tv":1031.65,"id":7588306},{"batl":[[0,1.31,36.17],[1,1.38,66],[2,1.41,66.61]],"ltp":1.29,"tv":19499.43,"id":11439844}]}]}
{"op":"mcm","clk":"4234555053","pt":1631547091037,"mc":[{"id":"1.187560677","rc":[{"trd":[[1.31,0.04]],"batl":[[0,1.31,36.15]],"ltp":1.31,"tv":19499.47,"id":11439844}],"tv":20531.13}]}
{"op":"mcm","clk":"4234555147","pt":1631547092446,"mc":[{"id":"1.187560677","rc":[{"batl":[[0,4.7,7.52],[1,5,140.7],[2,5.4,2.04]],"ltp":4.4,"tv":1031.65,"id":7588306},{"batl":[[0,1.29,18.5],[1,1.31,36.15],[2,1.38,66]],"ltp":1.31,"tv":19499.47,"id":11439844}]}]}
{"op":"mcm","clk":"4234555205","pt":1631547093425,"mc":[{"id":"1.187560677","rc":[{"batb":[[1,3.4,3.81],[2,2.2,42.6]],"batl":[[0,8.8,2],[1,12.5,2],[2,13.5,2]],"ltp":4.4,"tv":1031.65,"id":7588306},{"batb":[[0,1.15,357.92],[1,1.13,197.73],[2,1.1,298.27]],"batl":[[0,1.31,5.63],[1,1.94,3.08],[2,44,7.22]],"ltp":1.31,"tv":19499.47,"id":11439844}]}]}
{"op":"mcm","clk":"4234555280","pt":1631547094563,"mc":[{"id":"1.187560677","rc":[{"batb":[[0,3.4,3.81],[1,2.2,42.6],[2,2,11.93]],"ltp":4.4,"tv":1031.65,"id":7588306},{"batl":[[0,1.94,3.08],[1,44,7.22],[2,44,0]],"ltp":1.31,"tv":19499.47,"id":11439844}]}]}
{"op":"mcm","clk":"4234555439","pt":1631547096638,"mc":[{"id":"1.187560677","rc":[{"batb":[[0,3.6,10.43],[1,3.4,11.52],[2,2.2,42.6]],"batl":[[0,8.2,2],[1,8.8,2],[2,12.5,2]],"ltp":4.4,"tv":1031.65,"id":7588306},{"batb":[[1,1.14,168.32],[2,1.13,197.73]],"batl":[[0,1.38,77.5],[1,1.41,72.61],[2,1.94,3.08]],"ltp":1.31,"tv":19499.47,"id":11439844}]}]}
{"op":"mcm","clk":"4234555477","pt":1631547097257,"mc":[{"id":"1.187560677","rc":[{"batb":[[0,3.4,3.81],[1,2.2,42.6],[2,2,11.93]],"ltp":4.4,"tv":1031.65,"id":7588306},{"batl":[[0,1.27,5],[1,1.41,66.5]],"ltp":1.31,"tv":19499.47,"id":11439844}]}]}
{"op":"mcm","clk":"4234555652","pt":1631547099637,"mc":[{"id":"1.187560677","rc":[{"trd":[[4.7,1.35]],"batl":[[0,8.2,2.81]],"ltp":4.7,"tv":1033.0,"id":7588306},{"trd":[[1.27,5]],"batl":[[0,1.3,473.48]],"ltp":1.27,"tv":19504.47,"id":11439844}],"tv":20537.48}]}
{"op":"mcm","clk":"4234555708","pt":1631547100571,"mc":[{"id":"1.187560677","rc":[{"trd":[[4.4,3.36]],"batb":[[1,2.6,3.73],[2,2.2,42.6]],"batl":[[0,8.2,2]],"ltp":4.4,"tv":1034.62,"id":7588306},{"batl":[[0,1.41,66.5],[1,1.94,3.08],[2,8.8,7.22]],"ltp":1.27,"tv":19504.47,"id":11439844}],"tv":20539.1}]}
{"op":"mcm","clk":"4234555915","pt":1631547103630,"mc":[{"id":"1.187560677","rc":[{"batb":[[0,3.6,10.03],[1,3.4,11.42],[2,2.6,3.73]],"ltp":4.4,"tv":1034.62,"id":7588306},{"batl":[[0,1.38,82.5],[1,1.41,72.22],[2,1.94,3.08]],"ltp":1.27,"tv":19504.47,"id":11439844}]}]}
{"op":"mcm","clk":"4234555942","pt":1631547104044,"mc":[{"id":"1.187560677","rc":[{"batb":[[0,3.4,3.81],[1,2.6,3.73],[2,2.2,42.6]],"ltp":4.4,"tv":1034.62,"id":7588306},{"batl":[[0,1.41,66.5],[1,1.94,3.08],[2,8.8,7.22]],"ltp":1.27,"tv":19504.47,"id":11439844}]}]}
{"op":"mcm","clk":"4234556739","pt":1631547114254,"mc":[{"id":"1.187560677","rc":[{"batb":[[0,3.6,7.69],[1,3.4,11.32],[2,2.6,3.73]],"ltp":4.4,"tv":1034.62,"id":7588306},{"batl":[[0,1.38,6.25],[1,1.41,72.61],[2,1.94,3.08]],"ltp":1.27,"tv":19504.47,"id":11439844}]}]}
{"op":"mcm","clk":"4234556774","pt":1631547114818,"mc":[{"id":"1.187560677","rc":[{"batb":[[0,3.4,3.81],[1,2.6,3.73],[2,2.2,42.6]],"ltp":4.4,"tv":1034.62,"id":7588306},{"batl":[[0,1.41,66.5],[1,1.94,3.08],[2,8.8,7.22]],"ltp":1.27,"tv":19504.47,"id":11439844}]}]}
{"op":"mcm","clk":"4234557148","pt":1631547119678,"mc":[{"id":"1.187560677","rc":[{"batl":[[0,4.2,3.86],[1,8.2,2],[2,8.8,2]],"ltp":4.4,"tv":1034.62,"id":7588306}]}]}
{"op":"mcm","clk":"4234557185","pt":1631547120136,"mc":[{"id":"1.187560677","rc":[{"trd":[[3.75,44.4]],"batb":[[0,3.75,2.84],[1,3.4,3.81]],"batl":[[0,3.8,10.52],[1,3.9,6.05],[2,4.1,247.36]],"ltp":3.75,"tv":1039.35,"id":7588306},{"trd":[[1.37,846.12]],"batl":[[0,1.39,691.98],[1,1.41,66.5],[2,1.94,3.08]],"ltp":1.37,"tv":19506.47,"id":11439844}],"tv":20545.83}]}
{"op":"mcm","clk":"4234557303","pt":1631547121546,"mc":[{"id":"1.187560677","rc":[{"batb":[[0,1.2,538.74],[1,1.15,357.92],[2,1.14,168.32]],"batl":[[2,1.66,588.41]],"ltp":1.37,"tv":19506.47,"id":11439844}]}]}
{"op":"mcm","clk":"4234557470","pt":1631547123628,"mc":[{"id":"1.187560677","rc":[{"trd":[[3.8,29.45]],"batb":[[0,3.8,12.22],[1,3.75,2.84],[2,3.4,3.81]],"batl":[[0,3.9,6.05],[1,4.1,247.36],[2,8.2,2]],"ltp":3.8,"tv":1058.8,"id":7588306},{"trd":[[1.35,9964.92]],"batl":[[0,1.35,132.84],[1,1.39,691.98],[2,1.41,66.5]],"ltp":1.35,"tv":19510.95,"id":11439844}],"tv":20569.76}]}
{"op":"mcm","clk":"4234557482","pt":1631547123837,"mc":[{"id":"1.187560677","rc":[{"batb":[[0,3.8,2]],"ltp":3.8,"tv":1058.8,"id":7588306},{"batl":[[0,1.39,691.98],[1,1.41,66.5],[2,1.66,588.41]],"ltp":1.35,"tv":19510.95,"id":11439844}]}]}
{"op":"mcm","clk":"4234557538","pt":1631547124766,"mc":[{"id":"1.187560677","rc":[{"batb":[[0,3.75,2.84],[1,3.4,3.81],[2,2.2,42.6]],"ltp":3.8,"tv":1058.8,"id":7588306}]}]}
{"op":"mcm","clk":"4234557670","pt":1631547126840,"mc":[{"id":"1.187560677","rc":[{"batb":[[1,3.4,11.47],[2,3.3,11.06]],"batl":[[2,4.9,2.15]],"ltp":3.8,"tv":1058.8,"id":7588306},{"batb":[[0,1.26,96.98],[1,1.23,103.63],[2,1.2,538.74]],"batl":[[1,1.41,73],[2,1.43,62]],"ltp":1.35,"tv":19510.95,"id":11439844}]}]}
{"op":"mcm","clk":"4234557923","pt":1631547129971,"mc":[{"id":"1.187560677","rc":[{"batb":[[0,3.4,11.47],[1,3.3,11.06],[2,2.2,42.6]],"batl":[[0,4.1,247.36],[1,4.9,2.15],[2,5.4,2.04]],"ltp":3.8,"tv":1058.8,"id":7588306}]}]}
{"op":"mcm","clk":"4234558108","pt":1631547132877,"mc":[{"id":"1.187560677","rc":[{"batl":[[0,3.85,4.97],[1,4.1,247.36],[2,4.9,2.15]],"ltp":3.8,"tv":1058.8,"id":7588306},{"batl":[[0,1.37,18.2],[1,1.39,691.98],[2,1.41,73]],"ltp":1.35,"tv":19510.95,"id":11439844}]}]}
{"op":"mcm","clk":"4234559086","pt":1631547147068,"mc":[{"id":"1.187560677","rc":[{"batl":[[0,1.37,207.2]],"ltp":1.35,"tv":19510.95,"id":11439844}]}]}
{"op":"mcm","clk":"4234559523","pt":1631547153477,"mc":[{"id":"1.187560677","rc":[{"batb":[[0,3.3,3.58],[1,2.2,42.6],[2,2,11.93]],"batl":[[0,5.4,2.04],[1,8.2,2],[2,8.8,2]],"ltp":3.8,"tv":1058.8,"id":7588306},{"batb":[[0,1.2,538.74],[1,1.15,357.92],[2,1.14,168.32]],"batl":[[0,1.43,55.5],[1,1.66,588.41],[2,1.94,3.08]],"ltp":1.35,"tv":19510.95,"id":11439844}]}]}
{"op":"mcm","clk":"4234559782","pt":1631547156699,"mc":[{"id":"1.187560677","rc":[{"batb":[[0,3.4,10.82],[1,3.3,12.26],[2,2.2,42.6]],"ltp":3.8,"tv":1058.8,"id":7588306},{"batb":[[0,1.23,103.63],[1,1.2,538.74],[2,1.15,357.92]],"batl":[[0,1.41,66.22],[1,1.43,61.21],[2,1.66,588.41]],"ltp":1.35,"tv":19510.95,"id":11439844}]}]}
{"op":"mcm","clk":"4234559825","pt":1631547157122,"mc":[{"id":"1.187560677","rc":[{"batb":[[0,3.3,3.58],[1,2.2,42.6],[2,2,11.93]],"ltp":3.8,"tv":1058.8,"id":7588306},{"batl":[[0,1.43,55.5],[1,1.66,588.41],[2,1.94,3.08]],"ltp":1.35,"tv":19510.95,"id":11439844}]}]}
{"op":"mcm","clk":"4234560335","pt":1631547163713,"mc":[{"id":"1.187560677","rc":[{"batb":[[0,3.4,7.21],[1,3.3,11.96],[2,2.2,42.6]],"batl":[[0,4.9,2.15],[1,5.4,2.04],[2,8.2,2]],"ltp":3.8,"tv":1058.8,"id":7588306},{"batb":[[0,1.26,102.98],[1,1.23,103.63],[2,1.2,538.74]],"batl":[[0,1.41,6.11],[1,1.43,61.35],[2,1.66,588.41]],"ltp":1.35,"tv":19510.95,"id":11439844}]}]}
{"op":"mcm","clk":"4234560370","pt":1631547164081,"mc":[{"id":"1.187560677","rc":[{"batb":[[0,3.3,3.58],[1,2.2,42.6],[2,2,11.93]],"batl":[[0,5.4,2.04],[1,8.2,2],[2,8.8,2]],"ltp":3.8,"tv":1058.8,"id":7588306},{"batb":[[0,1.23,103.63],[1,1.2,538.74],[2,1.15,357.92]],"batl":[[0,1.43,55.5],[1,1.66,588.41],[2,1.94,3.08]],"ltp":1.35,"tv":19510.95,"id":11439844}]}]}
{"op":"mcm","clk":"4234560547","pt":1631547166580,"mc":[{"id":"1.187560677","rc":[{"batb":[[1,1.15,357.92],[2,1.14,168.32]],"batl":[[1,1.94,3.08],[2,8.8,7.22]],"ltp":1.35,"tv":19510.95,"id":11439844}]}]}
{"op":"mcm","clk":"4234560613","pt":1631547167612,"mc":[{"id":"1.187560677","rc":[{"batb":[[0,4.5,4.94],[1,4.3,217.52],[2,3.3,3.58]],"batl":[[0,4.7,5.12],[1,5,93.21],[2,5.4,2.04]],"ltp":3.8,"tv":1058.8,"id":7588306},{"batb":[[0,1.25,372.85],[1,1.23,103.63],[2,1.15,357.92]],"batl":[[0,1.29,2983.8]],"ltp":1.35,"tv":19510.95,"id":11439844}]}]}
{"op":"mcm","clk":"4234560635","pt":1631547167878,"mc":[{"id":"1.187560677","rc":[{"batb":[[1,4.4,6.96],[2,4.3,217.52]],"ltp":3.8,"tv":1058.8,"id":7588306},{"batl":[[0,1.29,40.07]],"ltp":1.35,"tv":19510.95,"id":11439844}]}]}
{"op":"mcm","clk":"4234560798","pt":1631547170100,"mc":[{"id":"1.187560677","rc":[{"batl":[[1,1.56,685.62],[2,1.94,3.08]],"ltp":1.35,"tv":19510.95,"id":11439844}]}]}
{"op":"mcm","clk":"4234561354","pt":1631547177831,"mc":[{"id":"1.187560677","rc":[{"batl":[[1,1.37,74.46],[2,1.4,69.23]],"ltp":1.35,"tv":19510.95,"id":11439844}]}]}
{"op":"mcm","clk":"4234561602","pt":1631547181032,"mc":[{"id":"1.187560677","rc":[{"batl":[[0,1.29,152.07]],"ltp":1.35,"tv":19510.95,"id":11439844}]}]}
{"op":"mcm","clk":"4234561856","pt":1631547184141,"mc":[{"id":"1.187560677","rc":[{"batl":[[0,1.29,40.07]],"ltp":1.35,"tv":19510.95,"id":11439844}]}]}
{"op":"mcm","clk":"4234562100","pt":1631547187217,"mc":[{"id":"1.187560677","rc":[{"batl":[[0,1.28,351],[1,1.29,40.07],[2,1.37,74.46]],"ltp":1.35,"tv":19510.95,"id":11439844}]}]}
{"op":"mcm","clk":"4234562462","pt":1631547191624,"mc":[{"id":"1.187560677","rc":[{"batb":[[0,4.4,6.96],[1,3.7,9.44],[2,3.5,12.14]],"batl":[[0,5.4,2.04],[1,8.2,2],[2,8.8,2]],"ltp":3.8,"tv":1058.8,"id":7588306},{"batb":[[0,1.23,103.63],[1,1.15,357.92],[2,1.14,805.56]],"batl":[[1,1.29,9.07]],"ltp":1.35,"tv":19510.95,"id":11439844}]}]}
{"op":"mcm","clk":"4234562482","pt":1631547191837,"mc":[{"id":"1.187560677","rc":[{"batb":[[0,4.4,4.96]],"batl":[[0,8.8,2],[1,12.5,2],[2,13.5,2]],"ltp":3.8,"tv":1058.8,"id":7588306},{"batb":[[0,1.15,357.92],[1,1.14,637.24],[2,1.13,197.73]],"batl":[[0,1.29,5.88],[1,1.37,74.46],[2,1.4,69.23]],"ltp":1.35,"tv":19510.95,"id":11439844}]}]}
{"op":"mcm","clk":"4234562831","pt":1631547195561,"mc":[{"id":"1.187560677","rc":[{"batb":[[0,3.5,4.08],[1,2.6,3.73],[2,2.2,42.6]],"ltp":3.8,"tv":1058.8,"id":7588306},{"batb":[[1,1.13,197.73],[2,1.1,298.27]],"batl":[[0,1.4,62.54],[1,1.56,685.62],[2,1.94,3.08]],"ltp":1.35,"tv":19510.95,"id":11439844}]}]}
{"op":"mcm","clk":"4234562940","pt":1631547196617,"mc":[{"id":"1.187560677","rc":[{"batb":[[0,4.8,20.38],[1,3.5,4.08],[2,2.6,3.73]],"batl":[[0,5.3,19.85],[1,8.8,2],[2,12.5,2]],"ltp":3.8,"tv":1058.8,"id":7588306},{"batl":[[0,1.27,20.5],[1,1.4,62.54],[2,1.56,685.62]],"ltp":1.35,"tv":19510.95,"id":11439844}]}]}
{"op":"mcm","clk":"4234562990","pt":1631547197141,"mc":[{"id":"1.187560677","rc":[{"batb":[[0,3.5,4.08],[1,2.6,3.73],[2,2.2,42.6]],"batl":[[0,12.5,2],[1,13.5,2],[2,12.5,0]],"ltp":3.8,"tv":1058.8,"id":7588306},{"batb":[[0,1.1,298.27],[1,1.09,280.61],[2,1.08,1063.95]],"batl":[[0,1.4,62.54],[1,1.56,685.62],[2,1.94,3.08]],"ltp":1.35,"tv":19510.95,"id":11439844}]}]}
{"op":"mcm","clk":"4234563130","pt":1631547198560,"mc":[{"id":"1.187560677","rc":[{"batb":[[0,1.13,639.32],[1,1.1,298.27],[2,1.09,280.61]],"ltp":1.35,"tv":19510.95,"id":11439844}]}]}
{"op":"mcm","clk":"4234563290","pt":1631547200352,"mc":[{"id":"1.187560677","rc":[{"batl":[[0,8.8,2],[1,12.5,2],[2,13.5,2]],"ltp":3.8,"tv":1058.8,"id":7588306},{"batb":[[0,1.13,831.05]],"ltp":1.35,"tv":19510.95,"id":11439844}]}]}
{"op":"mcm","clk":"4234563491","pt":1631547202553,"mc":[{"id":"1.187560677","rc":[{"batb":[[0,3.7,10.64],[1,3.5,12.14],[2,2.6,3.73]],"ltp":3.8,"tv":1058.8,"id":7588306},{"batl":[[0,1.37,81.19],[1,1.4,68.58],[2,1.56,685.62]],"ltp":1.35,"tv":19510.95,"id":11439844}]}]}
{"op":"mcm","clk":"4234563524","pt":1631547202877,"mc":[{"id":"1.187560677","rc":[{"batb":[[0,3.5,4.08],[1,2.6,3.73],[2,2.2,42.6]],"ltp":3.8,"tv":1058.8,"id":7588306},{"batl":[[0,1.4,62.54],[1,1.56,685.62],[2,1.94,3.08]],"ltp":1.35,"tv":19510.95,"id":11439844}]}]}
{"op":"mcm","clk":"4234564106","pt":1631547209693,"mc":[{"id":"1.187560677","rc":[{"batb":[[0,3.7,10.34],[1,3.5,12.14],[2,2.6,3.73]],"ltp":3.8,"tv":1058.8,"id":7588306},{"batl":[[0,1.37,75.46],[1,1.4,68.63],[2,1.56,685.62]],"ltp":1.35,"tv":19510.95,"id":11439844}]}]}
{"op":"mcm","clk":"4234564137","pt":1631547209977,"mc":[{"id":"1.187560677","rc":[{"batb":[[0,3.5,4.08],[1,2.6,3.73],[2,2.2,42.6]],"ltp":3.8,"tv":1058.8,"id":7588306},{"batl":[[0,1.4,62.54],[1,1.56,685.62],[2,1.94,3.08]],"ltp":1.35,"tv":19510.95,"id":11439844}]}]}
{"op":"mcm","clk":"4234564658","pt":1631547216653,"mc":[{"id":"1.187560677","rc":[{"batb":[[0,3.7,9.94],[1,3.5,12.14],[2,2.6,3.73]],"ltp":3.8,"tv":1058.8,"id":7588306},{"batl":[[0,1.37,73.46],[1,1.4,68.28],[2,1.56,685.62]],"ltp":1.35,"tv":19510.95,"id":11439844}]}]}
{"op":"mcm","clk":"4234564692","pt":1631547217290,"mc":[{"id":"1.187560677","rc":[{"batb":[[0,3.5,4.08],[1,2.6,3.73],[2,2.2,42.6]],"ltp":3.8,"tv":1058.8,"id":7588306},{"batl":[[0,1.56,685.62],[1,1.94,3.08],[2,8.8,7.22]],"ltp":1.35,"tv":19510.95,"id":11439844}]}]}
{"op":"mcm","clk":"4234564810","pt":1631547218701,"mc":[{"id":"1.187560677","rc":[{"batl":[[0,12.5,2],[1,13.5,2],[2,13.5,0]],"ltp":3.8,"tv":1058.8,"id":7588306},{"batb":[[0,1.1,298.27],[1,1.09,280.61],[2,1.08,1063.95]],"batl":[[0,1.94,3.08],[1,8.8,7.22],[2,44,7.22]],"ltp":1.35,"tv":19510.95,"id":11439844}]}]}
{"op":"mcm","clk":"4234564957","pt":1631547220479,"mc":[{"id":"1.187560677","rc":[{"batl":[[0,6.8,6.74],[1,7.6,259.82],[2,12.5,2]],"ltp":3.8,"tv":1058.8,"id":7588306},{"batb":[[0,1.09,280.61],[1,1.08,1063.95],[2,1.03,497.12]],"batl":[[0,1.19,29.7],[1,1.21,1295.01],[2,1.24,32.26]],"ltp":1.35,"tv":19510.95,"id":11439844}]}]}
{"op":"mcm","clk":"4234565033","pt":1631547221683,"mc":[{"id":"1.187560677","rc":[{"batb":[[1,1.08,1900.87]],"ltp":1.35,"tv":19510.95,"id":11439844}]}]}
{"op":"mcm","clk":"4234565159","pt":1631547223404,"mc":[{"id":"1.187560677","rc":[{"batb":[[1,1.08,1133.47]],"ltp":1.35,"tv":19510.95,"id":11439844}]}]}
{"op":"mcm","clk":"4234565317","pt":1631547225309,"mc":[{"id":"1.187560677","rc":[{"batl":[[0,1.19,523.7]],"ltp":1.35,"tv":19510.95,"id":11439844}]}]}
{"op":"mcm","clk":"4234565481","pt":1631547227558,"mc":[{"id":"1.187560677","rc":[{"batb":[[0,5.1,46.36],[1,5,40.93],[2,4.9,56.73]],"batl":[[1,7.2,39.32],[2,7.4,37.93]],"ltp":3.8,"tv":1058.8,"id":7588306},{"batb":[[0,1.16,189.98],[1,1.15,217.39],[2,1.14,241.92]],"batl":[[0,1.19,29.7]],"ltp":1.35,"tv":19510.95,"id":11439844}]}]}
{"op":"mcm","clk":"4234565556","pt":1631547228554,"mc":[{"id":"1.187560677","rc":[{"batb":[[0,5.7,5.92],[1,5.3,6.56],[2,5.1,46.36]],"ltp":3.8,"tv":1058.8,"id":7588306},{"batb":[[1,1.15,378.42]],"batl":[[1,1.21,1433.25],[2,1.22,104]],"ltp":1.35,"tv":19510.95,"id":11439844}]}]}
{"op":"mcm","clk":"4234565575","pt":1631547228868,"mc":[{"id":"1.187560677","rc":[{"batb":[[1,1.15,217.39]],"ltp":1.35,"tv":19510.95,"id":11439844}]}]}
{"op":"mcm","clk":"4234565725","pt":1631547230768,"mc":[{"id":"1.187560677","rc":[{"batl":[[0,1.18,1230],[1,1.19,29.7],[2,1.21,1433.25]],"ltp":1.35,"tv":19510.95,"id":11439844}]}]}
{"op":"mcm","clk":"4234566059","pt":1631547234548,"mc":[{"id":"1.187560677","rc":[{"trd":[[1.18,68.54]],"batl":[[0,1.18,1204.15]],"ltp":1.18,"tv":19562.65,"id":11439844}],"tv":20621.46}]}
{"op":"mcm","clk":"4234566149","pt":1631547235548,"mc":[{"id":"1.187560677","rc":[{"batb":[[1,1.15,403.42]],"ltp":1.18,"tv":19562.65,"id":11439844}]}]}
{"op":"mcm","clk":"4234566200","pt":1631547236280,"mc":[{"id":"1.187560677","rc":[{"trd":[[6.8,0.34]],"batl":[[0,6.8,6.4]],"ltp":6.8,"tv":1059.14,"id":7588306},{"trd":[[1.17,2]],"batb":[[1,1.15,217.39]],"ltp":1.17,"tv":19564.65,"id":11439844}],"tv":20623.8}]}
{"op":"mcm","clk":"4234566431","pt":1631547239165,"mc":[{"id":"1.187560677","rc":[{"batb":[[1,1.15,377.62]],"ltp":1.17,"tv":19564.65,"id":11439844}]}]}
{"op":"mcm","clk":"4234566771","pt":1631547243047,"mc":[{"id":"1.187560677","rc":[{"trd":[[6.4,18.05]],"ltp":6.4,"tv":1077.19,"id":7588306},{"trd":[[1.18,166.43]],"batb":[[1,1.15,217.39]],"batl":[[0,1.18,1106.26]],"ltp":1.18,"tv":19662.54,"id":11439844}],"tv":20739.74}]}
{"op":"mcm","clk":"4234567032","pt":1631547246573,"mc":[{"id":"1.187560677","rc":[{"batl":[[0,7.2,39.32],[1,7.4,37.93],[2,7.6,300.47]],"ltp":6.4,"tv":1077.19,"id":7588306},{"batl":[[1,1.21,1433.25],[2,1.22,104]],"ltp":1.18,"tv":19662.54,"id":11439844}]}]}
{"op":"mcm","clk":"4234567252","pt":1631547249367,"mc":[{"id":"1.187560677","rc":[{"batl":[[0,6.8,6.4],[1,7.2,39.32],[2,7.4,37.93]],"ltp":6.4,"tv":1077.19,"id":7588306},{"batl":[[1,1.19,31.64],[2,1.21,1433.25]],"ltp":1.18,"tv":19662.54,"id":11439844}]}]}
{"op":"mcm","clk":"4234567435","pt":1631547251892,"mc":[{"id":"1.187560677","rc":[{"batl":[[0,7.2,39.32],[1,7.4,37.93],[2,7.6,40.65]],"ltp":6.4,"tv":1077.19,"id":7588306},{"batl":[[1,1.21,138.24],[2,1.22,104]],"ltp":1.18,"tv":19662.54,"id":11439844}]}]}
{"op":"mcm","clk":"4234567569","pt":1631547253568,"mc":[{"id":"1.187560677","rc":[{"batb":[[0,5.3,6.56],[1,5.1,46.36],[2,5,40.93]],"ltp":6.4,"tv":1077.19,"id":7588306},{"batb":[[1,1.15,392.22]],"batl":[[0,1.22,6.26],[1,1.23,115],[2,1.25,190.02]],"ltp":1.18,"tv":19662.54,"id":11439844}]}]}
{"op":"mcm","clk":"4234567587","pt":1631547253776,"mc":[{"id":"1.187560677","rc":[{"batb":[[0,5.3,2.08]],"ltp":6.4,"tv":1077.19,"id":7588306},{"batl":[[0,1.23,108.51],[1,1.25,190.02],[2,1.26,186.94]],"ltp":1.18,"tv":19662.54,"id":11439844}]}]}
{"op":"mcm","clk":"4234568086","pt":1631547260675,"mc":[{"id":"1.187560677","rc":[{"batb":[[0,5.3,6.36],[1,3,5.96],[2,2.6,3.73]],"batl":[[0,7.8,2],[1,13.5,2],[2,7.6,0]],"ltp":6.4,"tv":1077.19,"id":7588306},{"batb":[[0,1.15,174.83],[1,1.08,1133.47],[2,1.03,497.12]],"batl":[[0,1.22,6.76],[1,1.23,115],[2,1.39,17.9]],"ltp":1.18,"tv":19662.54,"id":11439844}]}]}
{"op":"mcm","clk":"4234568208","pt":1631547262289,"mc":[{"id":"1.187560677","rc":[{"batb":[[0,5.3,2.08]],"ltp":6.4,"tv":1077.19,"id":7588306},{"batl":[[0,1.23,108.51],[1,1.39,17.9],[2,1.45,852.3]],"ltp":1.18,"tv":19662.54,"id":11439844}]}]}
{"op":"mcm","clk":"4234568279","pt":1631547263495,"mc":[{"id":"1.187560677","rc":[{"batb":[[1,1.13,180.73],[2,1.12,194.54]],"ltp":1.18,"tv":19662.54,"id":11439844}]}]}
{"op":"mcm","clk":"4234568322","pt":1631547264174,"mc":[{"id":"1.187560677","rc":[{"batb":[[1,1.08,1133.47],[2,1.03,497.12]],"ltp":1.18,"tv":19662.54,"id":11439844}]}]}
{"op":"mcm","clk":"4234568621","pt":1631547268622,"mc":[{"id":"1.187560677","rc":[{"batb":[[0,5.3,6.16]],"ltp":6.4,"tv":1077.19,"id":7588306},{"batl":[[0,1.22,6.76],[1,1.23,115],[2,1.39,17.9]],"ltp":1.18,"tv":19662.54,"id":11439844}]}]}
{"op":"mcm","clk":"4234568635","pt":1631547268782,"mc":[{"id":"1.187560677","rc":[{"batb":[[0,5.3,2.08]],"ltp":6.4,"tv":1077.19,"id":7588306},{"batl":[[0,1.23,108.51],[1,1.39,17.9],[2,1.45,852.3]],"ltp":1.18,"tv":19662.54,"id":11439844}]}]}
{"op":"mcm","clk":"4234568754","pt":1631547270615,"mc":[{"id":"1.187560677","rc":[{"batb":[[1,1.13,194.73],[2,1.12,235.04]],"ltp":1.18,"tv":19662.54,"id":11439844}]}]}
{"op":"mcm","clk":"4234568829","pt":1631547271624,"mc":[{"id":"1.187560677","rc":[{"batb":[[0,5.7,2.12],[1,5.3,2.08],[2,3,5.96]],"ltp":6.4,"tv":1077.19,"id":7588306},{"batb":[[1,1.08,1133.47],[2,1.03,497.12]],"batl":[[0,1.21,134.51],[1,1.22,122.25],[2,1.23,108.5]],"ltp":1.18,"tv":19662.54,"id":11439844}]}]}
{"op":"mcm","clk":"4234568889","pt":1631547272313,"mc":[{"id":"1.187560677","rc":[{"batb":[[0,5.3,2.08],[1,3,5.96],[2,2.6,3.73]],"ltp":6.4,"tv":1077.19,"id":7588306},{"batl":[[0,1.23,108.51],[1,1.39,17.9],[2,1.45,852.3]],"ltp":1.18,"tv":19662.54,"id":11439844}]}]}
{"op":"mcm","clk":"4234569053","pt":1631547274691,"mc":[{"id":"1.187560677","rc":[{"batl":[[0,6.6,2.83],[1,7.8,2],[2,13.5,2]],"ltp":6.4,"tv":1077.19,"id":7588306},{"trd":[[1.17,2.01]],"batl":[[0,1.23,108.5]],"ltp":1.17,"tv":19662.55,"id":11439844}],"tv":20739.75}]}
{"op":"mcm","clk":"4234569095","pt":1631547275110,"mc":[{"id":"1.187560677","rc":[{"batl":[[0,5.7,3.58],[1,6.2,6.46],[2,6.8,503.22]],"ltp":6.4,"tv":1077.19,"id":7588306},{"batb":[[1,1.08,296.56]],"batl":[[0,1.23,144.24],[1,1.24,923.05]],"ltp":1.17,"tv":19662.55,"id":11439844}]}]}
{"op":"mcm","clk":"4234569352","pt":1631547278624,"mc":[{"id":"1.187560677","rc":[{"batb":[[1,1.11,694.47],[2,1.08,296.56]],"ltp":1.17,"tv":19662.55,"id":11439844}]}]}
{"op":"mcm","clk":"4234569631","pt":1631547281935,"mc":[{"id":"1.187560677","rc":[{"batb":[[1,4.5,7.52],[2,4.3,8.16]],"ltp":6.4,"tv":1077.19,"id":7588306},{"batb":[[0,1.17,164.97],[1,1.15,174.83],[2,1.11,694.47]],"batl":[[2,1.28,85.18]],"ltp":1.17,"tv":19662.55,"id":11439844}]}]}
{"op":"mcm","clk":"4234569772","pt":1631547284142,"mc":[{"id":"1.187560677","rc":[{"batb":[[2,1.08,296.56]],"ltp":1.17,"tv":19662.55,"id":11439844}]}]}
{"op":"mcm","clk":"4234569849","pt":1631547285133,"mc":[{"id":"1.187560677","rc":[{"batl":[[0,1.22,269],[1,1.23,144.24],[2,1.24,923.05]],"ltp":1.17,"tv":19662.55,"id":11439844}]}]}
{"op":"mcm","clk":"4234570469","pt":1631547293448,"mc":[{"id":"1.187560677","rc":[{"batb":[[0,5.5,62.6],[1,5.3,2.08],[2,4.5,7.52]],"ltp":6.4,"tv":1077.19,"id":7588306},{"batl":[[0,1.22,551.23]],"ltp":1.17,"tv":19662.55,"id":11439844}]}]}
{"op":"mcm","clk":"4234570598","pt":1631547295235,"mc":[{"id":"1.187560677","rc":[{"batl":[[1,6,54.06],[2,6.2,6.46]],"ltp":6.4,"tv":1077.19,"id":7588306},{"batb":[[0,1.2,270.29],[1,1.17,164.97],[2,1.15,174.83]],"ltp":1.17,"tv":19662.55,"id":11439844}]}]}
{"op":"mcm","clk":"4234570755","pt":1631547297671,"mc":[{"id":"1.187560677","rc":[{"batb":[[0,4.5,7.52],[1,4.3,8.16],[2,3,5.96]],"batl":[[0,7.8,2],[1,6,0],[2,6.2,0]],"ltp":6.4,"tv":1077.19,"id":7588306},{"batb":[[0,1.15,174.83],[1,1.05,477.27],[2,1.03,497.12]],"batl":[[0,1.22,269],[1,1.28,85.18],[2,1.3,95.5]],"ltp":1.17,"tv":19662.55,"id":11439844}]}]}
{"op":"mcm","clk":"4234570829","pt":1631547298566,"mc":[{"id":"1.187560677","rc":[{"batb":[[0,4.3,2.38],[1,3,5.96],[2,2.6,3.73]],"ltp":6.4,"tv":1077.19,"id":7588306},{"batl":[[0,1.3,88.85],[1,1.56,73.64],[2,1.94,3.08]],"ltp":1.17,"tv":19662.55,"id":11439844}]}]}
{"op":"mcm","clk":"4234570998","pt":1631547300582,"mc":[{"id":"1.187560677","rc":[{"batb":[[0,1.16,148.53],[1,1.15,174.83],[2,1.05,477.27]],"ltp":1.17,"tv":19662.55,"id":11439844}]}]}
{"op":"mcm","clk":"4234571080","pt":1631547301685,"mc":[{"id":"1.187560677","rc":[{"batb":[[0,4.5,5.28],[1,4.3,8.36],[2,3,5.96]],"ltp":6.4,"tv":1077.19,"id":7588306},{"batb":[[0,1.15,174.83],[1,1.05,477.27],[2,1.03,497.12]],"batl":[[0,1.28,5.84],[1,1.3,95.4],[2,1.56,73.64]],"ltp":1.17,"tv":19662.55,"id":11439844}]}]}
{"op":"mcm","clk":"4234571125","pt":1631547302242,"mc":[{"id":"1.187560677","rc":[{"batb":[[0,4.3,2.38],[1,3,5.96],[2,2.6,3.73]],"ltp":6.4,"tv":1077.19,"id":7588306},{"batl":[[0,1.3,88.85],[1,1.56,73.64],[2,1.94,3.08]],"ltp":1.17,"tv":19662.55,"id":11439844}]}]}
{"op":"mcm","clk":"4234571287","pt":1631547304551,"mc":[{"id":"1.187560677","rc":[{"batl":[[0,7,2],[1,7.8,2]],"ltp":6.4,"tv":1077.19,"id":7588306},{"batb":[[0,1.17,145.97],[1,1.15,174.83],[2,1.05,477.27]],"ltp":1.17,"tv":19662.55,"id":11439844}]}]}
