{"op":"mcm","clk":"4227240137","pt":1631469486062,"mc":[{"id":"1.187560634","marketDefinition":{"bspMarket":false,"turnInPlayEnabled":true,"persistenceEnabled":true,"marketBaseRate":5.0,"eventId":"30896276","eventTypeId":"2","numberOfWinners":1,"bettingType":"ODDS","marketType":"MATCH_ODDS","marketTime":"2021-09-13T15:00:00.000Z","suspendTime":"2021-09-13T15:00:00.000Z","bspReconciled":false,"complete":true,"inPlay":false,"crossMatching":false,"runnersVoidable":false,"numberOfActiveRunners":2,"betDelay":0,"status":"OPEN","runners":[{"status":"ACTIVE","sortPriority":1,"id":9629296,"name":"Gijs Brouwer"},{"status":"ACTIVE","sortPriority":2,"id":12343905,"name":"Rinky Hijikata"}],"regulators":["MR_INT"],"countryCode":"US","discountAllowed":false,"timezone":"UTC","openDate":"2021-09-13T15:00:00.000Z","version":4029419639,"name":"Match Odds","eventName":"Brouwer v Ri Hijikata"},"rc":[{"batb":[[0,1.01,25]],"ltp":0.0,"tv":0.0,"id":9629296},{"batb":[[0,1.01,25]],"ltp":0.0,"tv":0.0,"id":12343905}]}]}
{"op":"mcm","clk":"4227240202","pt":1631469486681,"mc":[{"id":"1.187560634","marketDefinition":{"bspMarket":false,"turnInPlayEnabled":true,"persistenceEnabled":true,"marketBaseRate":5.0,"eventId":"30896276","eventTypeId":"2","numberOfWinners":1,"bettingType":"ODDS","marketType":"MATCH_ODDS","marketTime":"2021-09-13T15:00:00.000Z","suspendTime":"2021-09-13T15:00:00.000Z","bspReconciled":false,"complete":true,"inPlay":false,"crossMatching":false,"runnersVoidable":false,"numberOfActiveRunners":2,"betDelay":0,"status":"OPEN","runners":[{"status":"ACTIVE","sortPriority":1,"id":9629296,"name":"Gijs Brouwer"},{"status":"ACTIVE","sortPriority":2,"id":12343905,"name":"Rinky Hijikata"}],"regulators":["MR_INT"],"countryCode":"US","discountAllowed":false,"timezone":"UTC","openDate":"2021-09-13T15:00:00.000Z","version":4029419639,"name":"Match Odds","eventName":"Brouwer v Ri Hijikata"}}]}
{"op":"mcm","clk":"4227240427","pt":1631469488694,"mc":[{"id":"1.187560634","marketDefinition":{"bspMarket":false,"turnInPlayEnabled":true,"persistenceEnabled":true,"marketBaseRate":5.0,"eventId":"30896276","eventTypeId":"2","numberOfWinners":1,"bettingType":"ODDS","marketType":"MATCH_ODDS","marketTime":"2021-09-13T15:00:00.000Z","suspendTime":"2021-09-13T15:00:00.000Z","bspReconciled":false,"complete":true,"inPlay":false,"crossMatching":false,"runnersVoidable":false,"numberOfActiveRunners":2,"betDelay":0,"status":"OPEN","runners":[{"status":"ACTIVE","sortPriority":1,"id":9629296,"name":"Gijs Brouwer"},{"status":"ACTIVE","sortPriority":2,"id":12343905,"name":"Rinky Hijikata"}],"regulators":["MR_INT"],"countryCode":"US","discountAllowed":true,"timezone":"UTC","openDate":"2021-09-13T15:00:00.000Z","version":4029419639,"name":"Match Odds","eventName":"Brouwer v Ri Hijikata"}}]}
{"op":"mcm","clk":"4227253345","pt":1631469611590,"mc":[{"id":"1.187560634","rc":[{"batb":[[0,1.01,7]],"ltp":0.0,"tv":0.0,"id":9629296},{"batb":[[0,1.01,7]],"ltp":0.0,"tv":0.0,"id":12343905}]}]}
{"op":"mcm","clk":"4227339910","pt":1631470339165,"mc":[{"id":"1.187560634","rc":[{"batl":[[0,990,2.2]],"ltp":0.0,"tv":0.0,"id":9629296},{"batl":[[0,990,2.2]],"ltp":0.0,"tv":0.0,"id":12343905}]}]}
{"op":"mcm","clk":"4227365499","pt":1631470548994,"mc":[{"id":"1.187560634","rc":[{"batb":[[0,1.01,100.94]],"ltp":0.0,"tv":0.0,"id":9629296},{"batb":[[0,1.01,100.94]],"ltp":0.0,"tv":0.0,"id":12343905}]}]}
{"op":"mcm","clk":"4227651030","pt":1631472840527,"mc":[{"id":"1.187560634","rc":[{"batb":[[0,1.01,573.8]],"ltp":0.0,"tv":0.0,"id":9629296},{"batb":[[0,1.01,573.8]],"ltp":0.0,"tv":0.0,"id":12343905}]}]}
{"op":"mcm","clk":"4227651071","pt":1631472840843,"mc":[{"id":"1.187560634","rc":[{"batb":[[0,1.02,108.45],[1,1.01,573.8]],"ltp":0.0,"tv":0.0,"id":9629296}]}]}
{"op":"mcm","clk":"4227653063","pt":1631472859493,"mc":[{"id":"1.187560634","marketDefinition":{"bspMarket":false,"turnInPlayEnabled":true,"persistenceEnabled":true,"marketBaseRate":5.0,"eventId":"30896276","eventTypeId":"2","numberOfWinners":1,"bettingType":"ODDS","marketType":"MATCH_ODDS","marketTime":"2021-09-13T15:00:00.000Z","suspendTime":"2021-09-13T15:00:00.000Z","bspReconciled":false,"complete":true,"inPlay":false,"crossMatching":true,"runnersVoidable":false,"numberOfActiveRunners":2,"betDelay":0,"status":"OPEN","runners":[{"status":"ACTIVE","sortPriority":1,"id":9629296,"name":"Gijs Brouwer"},{"status":"ACTIVE","sortPriority":2,"id":12343905,"name":"Rinky Hijikata"}],"regulators":["MR_INT"],"countryCode":"US","discountAllowed":true,"timezone":"UTC","openDate":"2021-09-13T15:00:00.000Z","version":4029419639,"name":"Match Odds","eventName":"Brouwer v Ri Hijikata"}}]}
{"op":"mcm","clk":"4228043291","pt":1631477169732,"mc":[{"id":"1.187560634","rc":[{"batb":[[1,1.01,578.76]],"ltp":0.0,"tv":0.0,"id":9629296},{"batb":[[0,1.01,578.76]],"ltp":0.0,"tv":0.0,"id":12343905}]}]}
{"op":"mcm","clk":"4228506362","pt":1631484954869,"mc":[{"id":"1.187560634","rc":[{"batb":[[0,1.02,118.23],[1,1.01,578.68]],"ltp":0.0,"tv":0.0,"id":9629296},{"batb":[[0,1.01,578.68]],"ltp":0.0,"tv":0.0,"id":12343905}]}]}
{"op":"mcm","clk":"4228561855","pt":1631485935587,"mc":[{"id":"1.187560634","rc":[{"batb":[[0,1.25,768.51],[1,1.02,118.23],[2,1.01,578.68]],"ltp":0.0,"tv":0.0,"id":9629296},{"batb":[[0,1.2,768.51],[1,1.01,578.68]],"ltp":0.0,"tv":0.0,"id":12343905}]}]}
{"op":"mcm","clk":"4228561974","pt":1631485938482,"mc":[{"id":"1.187560634","rc":[{"batb":[[1,1.02,108.43]],"ltp":0.0,"tv":0.0,"id":9629296}]}]}
{"op":"mcm","clk":"4228562115","pt":1631485941213,"mc":[{"id":"1.187560634","rc":[{"batb":[[0,1.26,35.01],[1,1.25,768.51],[2,1.02,108.43]],"ltp":0.0,"tv":0.0,"id":9629296},{"batb":[[0,1.21,39.28],[1,1.2,768.51],[2,1.01,578.68]],"ltp":0.0,"tv":0.0,"id":12343905}]}]}
{"op":"mcm","clk":"4228562281","pt":1631485945083,"mc":[{"id":"1.187560634","rc":[{"batb":[[0,1.26,42.95]],"ltp":0.0,"tv":0.0,"id":9629296}]}]}
{"op":"mcm","clk":"4228585107","pt":1631486698020,"mc":[{"id":"1.187560634","rc":[{"batb":[[0,1.26,49.48]],"ltp":0.0,"tv":0.0,"id":9629296},{"batb":[[0,1.21,45.21]],"ltp":0.0,"tv":0.0,"id":12343905}]}]}
{"op":"mcm","clk":"4228652714","pt":1631488665731,"mc":[{"id":"1.187560634","rc":[{"batb":[[0,1.26,49.47],[1,1.25,768.38],[2,1.02,108.42]],"ltp":0.0,"tv":0.0,"id":9629296},{"batb":[[0,1.21,45.21],[1,1.2,768.38],[2,1.01,578.63]],"ltp":0.0,"tv":0.0,"id":12343905}]}]}
{"op":"mcm","clk":"4228807448","pt":1631492615623,"mc":[{"id":"1.187560634","rc":[{"batb":[[0,1.27,15.37],[1,1.26,49.47],[2,1.25,768.38]],"ltp":0.0,"tv":0.0,"id":9629296},{"batb":[[0,1.22,15.37],[1,1.21,45.21],[2,1.2,768.38]],"ltp":0.0,"tv":0.0,"id":12343905}]}]}
{"op":"mcm","clk":"4228807468","pt":1631492616037,"mc":[{"id":"1.187560634","rc":[{"batl":[[0,12,3.42],[1,990,2.2]],"ltp":0.0,"tv":0.0,"id":9629296},{"batl":[[0,12,3.42],[1,990,2.2]],"ltp":0.0,"tv":0.0,"id":12343905}]}]}
{"op":"mcm","clk":"4229031107","pt":1631499465733,"mc":[{"id":"1.187560634","rc":[{"batb":[[0,1.27,15.36],[1,1.26,49.45],[2,1.25,767.98]],"batl":[[0,12,3.41]],"ltp":0.0,"tv":0.0,"id":9629296},{"batb":[[0,1.22,15.36],[1,1.21,45.19],[2,1.2,767.98]],"batl":[[0,12,3.41]],"ltp":0.0,"tv":0.0,"id":12343905}]}]}
{"op":"mcm","clk":"4229198096","pt":1631504865737,"mc":[{"id":"1.187560634","rc":[{"batb":[[0,1.27,15.36],[1,1.26,49.44],[2,1.25,767.79]],"ltp":0.0,"tv":0.0,"id":9629296},{"batb":[[0,1.22,15.36],[1,1.21,45.18],[2,1.2,767.79]],"ltp":0.0,"tv":0.0,"id":12343905}]}]}
{"op":"mcm","clk":"4229292547","pt":1631510130939,"mc":[{"id":"1.187560634","rc":[{"batb":[[0,1.27,15.36],[1,1.26,49.45],[2,1.25,767.85]],"batl":[[0,3.5,42.66],[1,12,3.41],[2,990,2.2]],"ltp":0.0,"tv":0.0,"id":9629296},{"batb":[[0,1.22,15.36],[1,1.21,45.18],[2,1.2,767.85]],"ltp":0.0,"tv":0.0,"id":12343905}]}]}
{"op":"mcm","clk":"4229292568","pt":1631510133148,"mc":[{"id":"1.187560634","rc":[{"batl":[[1,990,2.2],[2,990,0]],"ltp":0.0,"tv":0.0,"id":9629296}]}]}
{"op":"mcm","clk":"4229292639","pt":1631510138136,"mc":[{"id":"1.187560634","rc":[{"batl":[[0,3.5,42.66],[1,12,3.41],[2,990,2.2]],"ltp":0.0,"tv":0.0,"id":12343905}]}]}
{"op":"mcm","clk":"4229292680","pt":1631510141067,"mc":[{"id":"1.187560634","rc":[{"batb":[[1,1.26,41.51]],"ltp":0.0,"tv":0.0,"id":9629296}]}]}
{"op":"mcm","clk":"4229292757","pt":1631510147677,"mc":[{"id":"1.187560634","rc":[{"batb":[[0,1.4,7.14],[1,1.27,15.36],[2,1.26,41.51]],"ltp":0.0,"tv":0.0,"id":9629296}]}]}
{"op":"mcm","clk":"4229293541","pt":1631510199526,"mc":[{"id":"1.187560634","rc":[{"batb":[[1,1.26,41.51],[2,1.25,767.85]],"batl":[[0,3.45,3.41],[1,3.5,42.66],[2,990,2.2]],"ltp":0.0,"tv":0.0,"id":9629296},{"batl":[[1,990,2.2],[2,990,0]],"ltp":0.0,"tv":0.0,"id":12343905}]}]}
{"op":"mcm","clk":"4229300624","pt":1631510267604,"mc":[{"id":"1.187560634","rc":[{"batb":[[0,1.41,15.36],[1,1.4,7.14],[2,1.26,41.51]],"ltp":0.0,"tv":0.0,"id":9629296},{"batl":[[0,3.45,3.41],[1,3.5,42.66],[2,990,2.2]],"ltp":0.0,"tv":0.0,"id":12343905}]}]}
{"op":"mcm","clk":"4229319115","pt":1631511769345,"mc":[{"id":"1.187560634","rc":[{"batb":[[1,1.21,39.25]],"ltp":0.0,"tv":0.0,"id":12343905}]}]}
{"op":"mcm","clk":"4229328458","pt":1631512497710,"mc":[{"id":"1.187560634","rc":[{"batl":[[2,46,29.03]],"ltp":0.0,"tv":0.0,"id":9629296},{"batl":[[2,46,29.03]],"ltp":0.0,"tv":0.0,"id":12343905}]}]}
{"op":"mcm","clk":"4229612399","pt":1631521065811,"mc":[{"id":"1.187560634","rc":[{"batb":[[0,1.41,15.36],[2,1.26,41.53]],"batl":[[1,3.5,42.67],[2,46,29.07]],"ltp":0.0,"tv":0.0,"id":9629296},{"batb":[[0,1.22,15.36],[1,1.21,39.25],[2,1.2,767.98]],"batl":[[1,3.5,42.67],[2,46,29.07]],"ltp":0.0,"tv":0.0,"id":12343905}]}]}
{"op":"mcm","clk":"4229842035","pt":1631525514795,"mc":[{"id":"1.187560634","rc":[{"batb":[[0,1.41,15.36],[2,1.26,41.53]],"batl":[[0,2.2,25],[1,3.45,3.41],[2,3.5,42.67]],"ltp":0.0,"tv":0.0,"id":9629296},{"batb":[[0,1.22,15.36],[1,1.21,39.26],[2,1.2,768.11]],"batl":[[0,2.2,25],[1,3.45,3.41],[2,3.5,42.67]],"ltp":0.0,"tv":0.0,"id":12343905}]}]}
{"op":"mcm","clk":"4229842245","pt":1631525518884,"mc":[{"id":"1.187560634","rc":[{"batb":[[1,1.26,41.53],[2,1.25,768.11]],"ltp":0.0,"tv":0.0,"id":9629296}]}]}
{"op":"mcm","clk":"4229842618","pt":1631525525500,"mc":[{"id":"1.187560634","rc":[{"batb":[[0,1.83,5.46],[1,1.41,15.36],[2,1.26,41.53]],"ltp":0.0,"tv":0.0,"id":9629296}]}]}
{"op":"mcm","clk":"4229844447","pt":1631525552548,"mc":[{"id":"1.187560634","rc":[{"batl":[[1,3.5,42.67],[2,46,29.05]],"ltp":0.0,"tv":0.0,"id":12343905}]}]}
{"op":"mcm","clk":"4229844483","pt":1631525553110,"mc":[{"id":"1.187560634","rc":[{"batb":[[1,1.26,41.53],[2,1.25,768.11]],"batl":[[1,3.5,42.67],[2,46,29.05]],"ltp":0.0,"tv":0.0,"id":9629296}]}]}
{"op":"mcm","clk":"4229857912","pt":1631525740318,"mc":[{"id":"1.187560634","rc":[{"batb":[[0,1.83,43.2]],"ltp":0.0,"tv":0.0,"id":9629296},{"batb":[[0,1.83,37.74],[1,1.22,15.36],[2,1.21,39.26]],"ltp":0.0,"tv":0.0,"id":12343905}]}]}
{"op":"mcm","clk":"4229863597","pt":1631525831550,"mc":[{"id":"1.187560634","rc":[{"batb":[[1,1.21,39.26],[2,1.2,768.11]],"ltp":0.0,"tv":0.0,"id":12343905}]}]}
{"op":"mcm","clk":"4229867487","pt":1631525872700,"mc":[{"id":"1.187560634","rc":[{"batl":[[0,2.2,25.53]],"ltp":0.0,"tv":0.0,"id":12343905}]}]}
{"op":"mcm","clk":"4229896015","pt":1631526269632,"mc":[{"id":"1.187560634","rc":[{"batb":[[1,1.26,34.99]],"ltp":0.0,"tv":0.0,"id":9629296}]}]}
{"op":"mcm","clk":"4229963579","pt":1631527187406,"mc":[{"id":"1.187560634","rc":[{"batb":[[1,1.33,53.91],[2,1.26,34.99]],"ltp":0.0,"tv":0.0,"id":9629296},{"batb":[[1,1.33,59.29],[2,1.25,43.43]],"ltp":0.0,"tv":0.0,"id":12343905}]}]}
{"op":"mcm","clk":"4230183286","pt":1631529991524,"mc":[{"id":"1.187560634","rc":[{"batb":[[0,1.91,34.42],[1,1.83,5.46],[2,1.33,53.91]],"ltp":0.0,"tv":0.0,"id":9629296},{"batb":[[0,1.8,39.15]],"ltp":0.0,"tv":0.0,"id":12343905}]}]}
{"op":"mcm","clk":"4230183618","pt":1631529995333,"mc":[{"id":"1.187560634","rc":[{"batb":[[1,1.33,53.91],[2,1.26,34.99]],"ltp":0.0,"tv":0.0,"id":9629296}]}]}
{"op":"mcm","clk":"4230184216","pt":1631530002133,"mc":[{"id":"1.187560634","rc":[{"batb":[[0,1.91,39.66]],"ltp":0.0,"tv":0.0,"id":9629296}]}]}
{"op":"mcm","clk":"4230232096","pt":1631530606780,"mc":[{"id":"1.187560634","rc":[{"batb":[[0,1.91,5.24],[1,1.83,37.74],[2,1.33,53.91]],"ltp":0.0,"tv":0.0,"id":9629296},{"batb":[[0,1.83,37.74]],"ltp":0.0,"tv":0.0,"id":12343905}]}]}
{"op":"mcm","clk":"4230342943","pt":1631531865820,"mc":[{"id":"1.187560634","rc":[{"batb":[[2,1.33,53.87]],"batl":[[1,3.5,42.59],[2,46,29.02]],"ltp":0.0,"tv":0.0,"id":9629296},{"batb":[[1,1.33,59.25],[2,1.25,43.39]],"batl":[[1,3.5,42.59],[2,46,29.02]],"ltp":0.0,"tv":0.0,"id":12343905}]}]}
{"op":"mcm","clk":"4230376956","pt":1631532260670,"mc":[{"id":"1.187560634","rc":[{"batb":[[2,1.42,34.92]],"ltp":0.0,"tv":0.0,"id":9629296},{"batb":[[1,1.42,39.18],[2,1.41,766.61]],"ltp":0.0,"tv":0.0,"id":12343905}]}]}
{"op":"mcm","clk":"4230423339","pt":1631532837188,"mc":[{"id":"1.187560634","rc":[{"batl":[[0,2.08,1.38],[1,2.2,25],[2,3.5,42.59]],"ltp":0.0,"tv":0.0,"id":12343905}]}]}
{"op":"mcm","clk":"4230494342","pt":1631533624675,"mc":[{"id":"1.187560634","rc":[{"batl":[[1,2.56,2.66],[2,3.5,42.59]],"ltp":0.0,"tv":0.0,"id":9629296}]}]}
{"op":"mcm","clk":"4230714564","pt":1631535795198,"mc":[{"id":"1.187560634","rc":[{"trd":[[2.2,50]],"batl":[[0,2.56,2.66],[1,3.5,42.59],[2,46,29.02]],"ltp":2.2,"tv":50.0,"id":9629296}],"tv":50.0}]}
{"op":"mcm","clk":"4230715744","pt":1631535807116,"mc":[{"id":"1.187560634","rc":[{"trd":[[1.83,25.55]],"batb":[[0,1.83,24.97]],"ltp":1.83,"tv":25.54,"id":12343905}],"tv":75.54}]}
{"op":"mcm","clk":"4230716060","pt":1631535810052,"mc":[{"id":"1.187560634","rc":[{"batb":[[0,1.83,37.74]],"ltp":1.83,"tv":25.54,"id":12343905}]}]}
{"op":"mcm","clk":"4230733800","pt":1631536019957,"mc":[{"id":"1.187560634","rc":[{"batl":[[0,2.54,2.72],[1,2.56,2.66],[2,3.5,42.59]],"ltp":2.2,"tv":50.0,"id":9629296}]}]}
{"op":"mcm","clk":"4230786696","pt":1631536618893,"mc":[{"id":"1.187560634","rc":[{"trd":[[1.92,4.83],[1.94,0.56]],"batl":[[0,2.56,2.66],[1,3.5,42.59],[2,46,29.02]],"ltp":1.92,"tv":55.38,"id":9629296},{"trd":[[2.06,0.53],[2.08,0.85]],"batl":[[0,2.2,25],[1,3.5,42.59],[2,46,29.02]],"ltp":2.08,"tv":26.92,"id":12343905}],"tv":82.31}]}
{"op":"mcm","clk":"4230788822","pt":1631536636893,"mc":[{"id":"1.187560634","rc":[{"batb":[[1,1.44,97.07],[2,1.42,39.18]],"batl":[[1,2.9,43.73],[2,3.5,42.59]],"ltp":2.08,"tv":26.92,"id":12343905}]}]}
{"op":"mcm","clk":"4230799188","pt":1631536742507,"mc":[{"id":"1.187560634","rc":[{"batl":[[0,2.48,2.77],[1,2.56,2.66],[2,3.5,42.59]],"ltp":1.92,"tv":55.38,"id":9629296}]}]}
{"op":"mcm","clk":"4230811170","pt":1631536866668,"mc":[{"id":"1.187560634","rc":[{"batl":[[0,2.56,2.66],[1,3.5,42.59],[2,46,29.02]],"ltp":1.92,"tv":55.38,"id":9629296}]}]}
{"op":"mcm","clk":"4230835413","pt":1631537125798,"mc":[{"id":"1.187560634","rc":[{"batl":[[0,2.52,2.68],[1,2.56,2.66],[2,3.5,42.59]],"ltp":1.92,"tv":55.38,"id":9629296}]}]}
{"op":"mcm","clk":"4230895418","pt":1631537686614,"mc":[{"id":"1.187560634","rc":[{"batb":[[2,1.42,44.88]],"ltp":2.08,"tv":26.92,"id":12343905}]}]}
{"op":"mcm","clk":"4230902629","pt":1631537761607,"mc":[{"id":"1.187560634","rc":[{"batb":[[2,1.45,43.57]],"ltp":1.92,"tv":55.38,"id":9629296},{"batb":[[2,1.42,91.57]],"ltp":2.08,"tv":26.92,"id":12343905}]}]}
{"op":"mcm","clk":"4230923564","pt":1631538001248,"mc":[{"id":"1.187560634","rc":[{"batb":[[1,1.83,50.32]],"ltp":1.92,"tv":55.38,"id":9629296},{"batb":[[0,1.83,50.32]],"ltp":2.08,"tv":26.92,"id":12343905}]}]}
{"op":"mcm","clk":"4230980885","pt":1631538640698,"mc":[{"id":"1.187560634","rc":[{"trd":[[2.2,50]],"batb":[[2,1.45,43.54]],"batl":[[0,2.56,2.66],[1,3.5,42.58],[2,46,29]],"ltp":1.92,"tv":55.38,"id":9629296},{"trd":[[1.83,25.54]],"batb":[[1,1.44,97.01],[2,1.42,91.53]],"batl":[[1,2.9,43.7],[2,3.5,42.58]],"ltp":2.08,"tv":26.92,"id":12343905}],"tv":82.3}]}
{"op":"mcm","clk":"4231011129","pt":1631538909941,"mc":[{"id":"1.187560634","rc":[{"batl":[[0,2.46,2.65],[1,2.56,2.66],[2,3.5,42.58]],"ltp":1.92,"tv":55.38,"id":9629296}]}]}
{"op":"mcm","clk":"4231048093","pt":1631539224750,"mc":[{"id":"1.187560634","rc":[{"batl":[[2,46,29]],"ltp":1.92,"tv":55.38,"id":9629296},{"batl":[[2,46,29]],"ltp":2.08,"tv":26.92,"id":12343905}]}]}
{"op":"mcm","clk":"4231090537","pt":1631539678394,"mc":[{"id":"1.187560634","rc":[{"trd":[[1.83,3.34],[1.91,10.48]],"batb":[[0,1.83,48.65],[1,1.45,43.54],[2,1.42,34.92]],"ltp":1.83,"tv":69.2,"id":9629296}],"tv":96.13}]}
{"op":"mcm","clk":"4231090968","pt":1631539682984,"mc":[{"id":"1.187560634","rc":[{"batb":[[0,1.83,50.32]],"ltp":1.83,"tv":69.2,"id":9629296}]}]}
{"op":"mcm","clk":"4231132495","pt":1631540164693,"mc":[{"id":"1.187560634","rc":[{"batb":[[0,1.83,50.84]],"ltp":1.83,"tv":69.2,"id":9629296}]}]}
{"op":"mcm","clk":"4231253123","pt":1631541601126,"mc":[{"id":"1.187560634","rc":[{"batb":[[0,1.84,15.73],[1,1.83,50.32],[2,1.45,43.54]],"ltp":1.83,"tv":69.2,"id":9629296},{"batb":[[0,1.84,15.21],[1,1.83,50.32],[2,1.44,97.01]],"ltp":2.08,"tv":26.92,"id":12343905}]}]}
{"op":"mcm","clk":"4231417885","pt":1631543584093,"mc":[{"id":"1.187560634","rc":[{"batb":[[2,1.8,3.61]],"ltp":1.83,"tv":69.2,"id":9629296},{"batb":[[2,1.8,2.32]],"ltp":2.08,"tv":26.92,"id":12343905}]}]}
{"op":"mcm","clk":"4231494863","pt":1631544525989,"mc":[{"id":"1.187560634","rc":[{"trd":[[1.89,5.11]],"ltp":1.89,"tv":32.03,"id":12343905}],"tv":101.24}]}
{"op":"mcm","clk":"4231502118","pt":1631544635642,"mc":[{"id":"1.187560634","rc":[{"batb":[[0,1.91,45.89],[1,1.84,15.73]],"ltp":1.83,"tv":69.2,"id":9629296},{"batb":[[1,1.8,54.52],[2,1.44,97.01]],"ltp":1.89,"tv":32.03,"id":12343905}]}]}
{"op":"mcm","clk":"4231502181","pt":1631544636325,"mc":[{"id":"1.187560634","rc":[{"batb":[[0,1.92,13.88],[1,1.91,45.89],[2,1.84,15.73]],"ltp":1.83,"tv":69.2,"id":9629296},{"batb":[[0,1.81,15.77]],"ltp":1.89,"tv":32.03,"id":12343905}]}]}
{"op":"mcm","clk":"4231514353","pt":1631544821081,"mc":[{"id":"1.187560634","rc":[{"batb":[[0,1.92,14.41],[2,1.84,15.21]],"ltp":1.83,"tv":69.2,"id":9629296}]}]}
{"op":"mcm","clk":"4231520643","pt":1631544910861,"mc":[{"id":"1.187560634","rc":[{"trd":[[1.81,19.99]],"batb":[[0,1.81,5.78]],"ltp":1.81,"tv":52.02,"id":12343905}],"tv":121.23}]}
{"op":"mcm","clk":"4231527405","pt":1631545002338,"mc":[{"id":"1.187560634","rc":[{"batb":[[2,1.67,1.4]],"ltp":1.81,"tv":52.02,"id":12343905}]}]}
{"op":"mcm","clk":"4231527989","pt":1631545009967,"mc":[{"id":"1.187560634","marketDefinition":{"bspMarket":false,"turnInPlayEnabled":true,"persistenceEnabled":true,"marketBaseRate":5.0,"eventId":"30896276","eventTypeId":"2","numberOfWinners":1,"bettingType":"ODDS","marketType":"MATCH_ODDS","marketTime":"2021-09-13T14:55:00.000Z","suspendTime":"2021-09-13T14:55:00.000Z","bspReconciled":false,"complete":true,"inPlay":false,"crossMatching":true,"runnersVoidable":false,"numberOfActiveRunners":2,"betDelay":0,"status":"OPEN","runners":[{"status":"ACTIVE","sortPriority":1,"id":9629296,"name":"Gijs Brouwer"},{"status":"ACTIVE","sortPriority":2,"id":12343905,"name":"Rinky Hijikata"}],"regulators":["MR_INT"],"countryCode":"US","discountAllowed":true,"timezone":"UTC","openDate":"2021-09-13T15:00:00.000Z","version":4030797564,"name":"Match Odds","eventName":"Brouwer v Ri Hijikata"}}]}
{"op":"mcm","clk":"4231529099","pt":1631545024154,"mc":[{"id":"1.187560634","marketDefinition":{"bspMarket":false,"turnInPlayEnabled":true,"persistenceEnabled":true,"marketBaseRate":5.0,"eventId":"30896276","eventTypeId":"2","numberOfWinners":1,"bettingType":"ODDS","marketType":"MATCH_ODDS","marketTime":"2021-09-13T14:55:00.000Z","suspendTime":"2021-09-13T14:55:00.000Z","bspReconciled":false,"complete":true,"inPlay":false,"crossMatching":true,"runnersVoidable":false,"numberOfActiveRunners":2,"betDelay":0,"status":"OPEN","runners":[{"status":"ACTIVE","sortPriority":1,"id":9629296,"name":"Gijs Brouwer"},{"status":"ACTIVE","sortPriority":2,"id":12343905,"name":"Rinky Hijikata"}],"regulators":["MR_INT"],"countryCode":"US","discountAllowed":true,"timezone":"UTC","openDate":"2021-09-13T14:55:00.000Z","version":4030797564,"name":"Match Odds","eventName":"Brouwer v Ri Hijikata"},"rc":[{"batl":[[0,2.56,2.66],[1,46,29],[2,990,2.2]],"ltp":1.83,"tv":69.2,"id":9629296}]}]}
{"op":"mcm","clk":"4231529311","pt":1631545026994,"mc":[{"id":"1.187560634","rc":[{"batl":[[0,2.46,4.32],[1,2.56,2.66],[2,46,29]],"ltp":1.83,"tv":69.2,"id":9629296}]}]}
{"op":"mcm","clk":"4231529615","pt":1631545031652,"mc":[{"id":"1.187560634","rc":[{"batb":[[0,1.96,13.31],[1,1.95,48.36],[2,1.92,14.41]],"ltp":1.83,"tv":69.2,"id":9629296},{"batb":[[0,1.85,15.03],[1,1.84,29.03],[2,1.81,5.78]],"ltp":1.81,"tv":52.02,"id":12343905}]}]}
{"op":"mcm","clk":"4231531842","pt":1631545061511,"mc":[{"id":"1.187560634","rc":[{"batb":[[2,1.83,50.32]],"ltp":1.81,"tv":52.02,"id":12343905}]}]}
{"op":"mcm","clk":"4231534469","pt":1631545097127,"mc":[{"id":"1.187560634","rc":[{"batb":[[0,2,41.76],[1,1.96,13.31],[2,1.95,48.36]],"ltp":1.83,"tv":69.2,"id":9629296},{"batb":[[2,1.81,5.78]],"ltp":1.81,"tv":52.02,"id":12343905}]}]}
{"op":"mcm","clk":"4231535914","pt":1631545116670,"mc":[{"id":"1.187560634","rc":[{"batl":[[0,2.18,15.69],[1,2.2,25],[2,2.9,43.7]],"ltp":1.81,"tv":52.02,"id":12343905}]}]}
{"op":"mcm","clk":"4231541498","pt":1631545200990,"mc":[{"id":"1.187560634","rc":[{"batb":[[0,2,42.28]],"ltp":1.83,"tv":69.2,"id":9629296}]}]}
{"op":"mcm","clk":"4231541567","pt":1631545201890,"mc":[{"id":"1.187560634","rc":[{"batb":[[0,2,55.06]],"ltp":1.83,"tv":69.2,"id":9629296}]}]}
{"op":"mcm","clk":"4231542093","pt":1631545208684,"mc":[{"id":"1.187560634","rc":[{"trd":[[1.83,3.35],[1.91,10.49],[1.92,4.83],[2.2,50.03]],"batb":[[0,2,55.07],[1,1.96,13.33],[2,1.95,48.48]],"batl":[[2,46,28.97]],"ltp":1.83,"tv":69.25,"id":9629296},{"trd":[[1.81,20],[1.83,25.56],[1.89,5.12],[2.08,0.85]],"batb":[[0,1.85,15.05],[1,1.84,29.11],[2,1.81,5.79]],"batl":[[0,2.18,16.48],[2,2.9,43.65]],"ltp":1.81,"tv":52.05,"id":12343905}],"tv":121.31}]}
{"op":"mcm","clk":"4231542502","pt":1631545214369,"mc":[{"id":"1.187560634","rc":[{"batb":[[0,2,13.31]],"ltp":1.83,"tv":69.25,"id":9629296},{"batb":[[2,1.83,50.32]],"batl":[[0,2.2,25.79],[1,2.9,43.65],[2,46,28.97]],"ltp":1.81,"tv":52.05,"id":12343905}]}]}
{"op":"mcm","clk":"4231542532","pt":1631545214889,"mc":[{"id":"1.187560634","rc":[{"batb":[[0,1.96,13.85],[1,1.95,48.48],[2,1.92,13.9]],"ltp":1.83,"tv":69.25,"id":9629296}]}]}
{"op":"mcm","clk":"4231544513","pt":1631545243729,"mc":[{"id":"1.187560634","rc":[{"batl":[[0,1.99,1.31],[1,2.2,25],[2,2.9,43.65]],"ltp":1.81,"tv":52.05,"id":12343905}]}]}
{"op":"mcm","clk":"4231554746","pt":1631545377623,"mc":[{"id":"1.187560634","rc":[{"trd":[[1.85,30.1]],"batb":[[0,1.84,29.11],[1,1.83,50.32],[2,1.81,5.79]],"batl":[[0,1.85,14.95],[1,1.99,1.31],[2,2.2,25]],"ltp":1.85,"tv":82.15,"id":12343905}],"tv":151.41}]}
{"op":"mcm","clk":"4231554795","pt":1631545378198,"mc":[{"id":"1.187560634","rc":[{"batb":[[0,2.08,11.84],[1,1.96,13.85],[2,1.95,48.48]],"batl":[[0,2.56,2.66],[1,46,28.97],[2,990,2.2]],"ltp":1.83,"tv":69.25,"id":9629296},{"batb":[[2,1.8,2.32]],"ltp":1.85,"tv":82.15,"id":12343905}]}]}
{"op":"mcm","clk":"4231557196","pt":1631545408671,"mc":[{"id":"1.187560634","rc":[{"batb":[[1,1.96,62]],"ltp":1.83,"tv":69.25,"id":9629296},{"trd":[[1.84,29.9]],"batb":[[0,1.84,14.16],[1,1.83,79.59]],"batl":[[0,1.99,1.31],[1,2.2,25],[2,2.9,43.65]],"ltp":1.84,"tv":112.05,"id":12343905}],"tv":181.31}]}
{"op":"mcm","clk":"4231557233","pt":1631545409038,"mc":[{"id":"1.187560634","rc":[{"batb":[[0,1.96,62],[1,1.92,13.9],[2,1.83,50.32]],"batl":[[0,2.46,4.24],[1,2.56,2.66],[2,46,28.97]],"ltp":1.83,"tv":69.25,"id":9629296},{"batb":[[0,1.83,79.59],[1,1.8,2.32],[2,1.67,1.4]],"ltp":1.84,"tv":112.05,"id":12343905}]}]}
{"op":"mcm","clk":"4231565453","pt":1631545509065,"mc":[{"id":"1.187560634","rc":[{"batl":[[0,2.18,32.93]],"ltp":1.84,"tv":112.05,"id":12343905}]}]}
{"op":"mcm","clk":"4231565534","pt":1631545510105,"mc":[{"id":"1.187560634","rc":[{"batb":[[0,1.84,15.23],[1,1.83,79.59],[2,1.8,2.32]],"ltp":1.84,"tv":112.05,"id":12343905}]}]}
{"op":"mcm","clk":"4231565826","pt":1631545513809,"mc":[{"id":"1.187560634","rc":[{"batl":[[0,2.18,32.14]],"ltp":1.84,"tv":112.05,"id":12343905}]}]}
{"op":"mcm","clk":"4231565981","pt":1631545515679,"mc":[{"id":"1.187560634","rc":[{"batb":[[0,1.96,61.47]],"ltp":1.83,"tv":69.25,"id":9629296}]}]}
{"op":"mcm","clk":"4231566808","pt":1631545526716,"mc":[{"id":"1.187560634","rc":[{"batl":[[0,2.18,32.84]],"ltp":1.84,"tv":112.05,"id":12343905}]}]}
{"op":"mcm","clk":"4231571125","pt":1631545582788,"mc":[{"id":"1.187560634","rc":[{"trd":[[1.84,35.38]],"batb":[[0,1.84,12.49]],"ltp":1.84,"tv":117.53,"id":12343905}],"tv":186.79}]}
{"op":"mcm","clk":"4231574885","pt":1631545630661,"mc":[{"id":"1.187560634","rc":[{"trd":[[1.96,41.97],[2.04,0.67]],"batb":[[0,1.96,40.49]],"ltp":1.96,"tv":111.9,"id":9629296},{"trd":[[1.96,0.7]],"batl":[[0,2.18,32.14]],"ltp":1.96,"tv":118.23,"id":12343905}],"tv":230.13}]}
{"op":"mcm","clk":"4231574948","pt":1631545631444,"mc":[{"id":"1.187560634","rc":[{"batb":[[0,1.97,13.18],[1,1.96,40.49],[2,1.92,13.9]],"ltp":1.96,"tv":111.9,"id":9629296},{"batb":[[0,1.84,41.68],[1,1.83,50.32]],"ltp":1.96,"tv":118.23,"id":12343905}]}]}
{"op":"mcm","clk":"4231578209","pt":1631545670277,"mc":[{"id":"1.187560634","rc":[{"batb":[[0,1.96,53.81],[1,1.92,13.9],[2,1.9,46.4]],"ltp":1.96,"tv":111.9,"id":9629296},{"batb":[[0,1.9,60.61],[1,1.84,41.68]],"ltp":1.96,"tv":118.23,"id":12343905}]}]}
{"op":"mcm","clk":"4231578961","pt":1631545679581,"mc":[{"id":"1.187560634","marketDefinition":{"bspMarket":false,"turnInPlayEnabled":true,"persistenceEnabled":true,"marketBaseRate":5.0,"eventId":"30896276","eventTypeId":"2","numberOfWinners":1,"bettingType":"ODDS","marketType":"MATCH_ODDS","marketTime":"2021-09-13T14:55:00.000Z","suspendTime":"2021-09-13T14:55:00.000Z","bspReconciled":false,"complete":true,"inPlay":false,"crossMatching":true,"runnersVoidable":false,"numberOfActiveRunners":2,"betDelay":0,"status":"OPEN","runners":[{"status":"ACTIVE","sortPriority":1,"id":9629296,"name":"Gijs Brouwer"},{"status":"ACTIVE","sortPriority":2,"id":12343905,"name":"Rinky Hijikata"}],"regulators":["MR_INT"],"countryCode":"US","discountAllowed":true,"timezone":"UTC","openDate":"2021-09-13T14:55:00.000Z","version":4030797564,"name":"Match Odds","eventName":"Brouwer v Ri Hijikata"},"rc":[{"batb":[[0,1.96,13.33]],"ltp":1.96,"tv":111.9,"id":9629296},{"batb":[[1,1.84,12.49]],"ltp":1.96,"tv":118.23,"id":12343905}]}]}
{"op":"mcm","clk":"4231579015","pt":1631545680116,"mc":[{"id":"1.187560634","marketDefinition":{"bspMarket":false,"turnInPlayEnabled":true,"persistenceEnabled":true,"marketBaseRate":5.0,"eventId":"30896276","eventTypeId":"2","numberOfWinners":1,"bettingType":"ODDS","marketType":"MATCH_ODDS","marketTime":"2021-09-13T14:55:00.000Z","suspendTime":"2021-09-13T14:55:00.000Z","bspReconciled":false,"complete":true,"inPlay":true,"crossMatching":true,"runnersVoidable":false,"numberOfActiveRunners":2,"betDelay":3,"status":"OPEN","runners":[{"status":"ACTIVE","sortPriority":1,"id":9629296,"name":"Gijs Brouwer"},{"status":"ACTIVE","sortPriority":2,"id":12343905,"name":"Rinky Hijikata"}],"regulators":["MR_INT"],"countryCode":"US","discountAllowed":true,"timezone":"UTC","openDate":"2021-09-13T14:55:00.000Z","version":4030812099,"name":"Match Odds","eventName":"Brouwer v Ri Hijikata"},"rc":[{"batb":[[0,1.25,28.88],[1,1.01,577.96],[2,1.9,0]],"ltp":1.96,"tv":111.9,"id":9629296},{"batb":[[0,1.67,1.4],[1,1.25,28.88],[2,1.1,2]],"ltp":1.96,"tv":118.23,"id":12343905}]}]}
{"op":"mcm","clk":"4231579433","pt":1631545684597,"mc":[{"id":"1.187560634","rc":[{"batl":[[0,2.12,240.82]],"ltp":1.96,"tv":111.9,"id":9629296}]}]}
{"op":"mcm","clk":"4231580707","pt":1631545700513,"mc":[{"id":"1.187560634","rc":[{"batl":[[0,1.89,13.79],[1,1.92,129.07],[2,2.06,6.96]],"ltp":1.96,"tv":111.9,"id":9629296},{"batl":[[0,2.2,13.09],[1,2.24,117.53]],"ltp":1.96,"tv":118.23,"id":12343905}]}]}
{"op":"mcm","clk":"4231580723","pt":1631545700722,"mc":[{"id":"1.187560634","rc":[{"batl":[[2,2.06,0]],"ltp":1.96,"tv":111.9,"id":9629296}]}]}
{"op":"mcm","clk":"4231580815","pt":1631545701928,"mc":[{"id":"1.187560634","rc":[{"batb":[[0,1.84,29.19],[1,1.72,36.74],[2,1.25,28.88]],"ltp":1.96,"tv":111.9,"id":9629296},{"batb":[[0,1.95,48.31],[1,1.86,27.93],[2,1.67,1.4]],"ltp":1.96,"tv":118.23,"id":12343905}]}]}
{"op":"mcm","clk":"4231581087","pt":1631545705546,"mc":[{"id":"1.187560634","rc":[{"batl":[[2,1.94,46.24]],"ltp":1.96,"tv":111.9,"id":9629296},{"batl":[[0,2.14,38.88],[1,2.2,13.09],[2,2.24,117.53]],"ltp":1.96,"tv":118.23,"id":12343905}]}]}
{"op":"mcm","clk":"4231581100","pt":1631545705753,"mc":[{"id":"1.187560634","rc":[{"batl":[[2,1.94,0]],"ltp":1.96,"tv":111.9,"id":9629296},{"batl":[[0,2.2,13.09],[1,2.24,117.53],[2,2.24,0]],"ltp":1.96,"tv":118.23,"id":12343905}]}]}
{"op":"mcm","clk":"4231582114","pt":1631545718162,"mc":[{"id":"1.187560634","rc":[{"batb":[[0,1.72,36.74],[1,1.25,28.88],[2,1.01,577.96]],"ltp":1.96,"tv":111.9,"id":9629296},{"batb":[[0,1.86,27.93],[1,1.67,1.4],[2,1.25,28.88]],"ltp":1.96,"tv":118.23,"id":12343905}]}]}
{"op":"mcm","clk":"4231582672","pt":1631545726458,"mc":[{"id":"1.187560634","rc":[{"batb":[[0,1.94,7.02],[1,1.72,36.74],[2,1.25,28.88]],"batl":[[0,1.98,10.67],[1,2.02,104.49]],"ltp":1.96,"tv":111.9,"id":9629296},{"batl":[[0,2.12,105.52]],"ltp":1.96,"tv":118.23,"id":12343905}]}]}
{"op":"mcm","clk":"4231582754","pt":1631545727647,"mc":[{"id":"1.187560634","rc":[{"batb":[[1,1.93,50.5],[2,1.8,31.45]],"ltp":1.96,"tv":111.9,"id":9629296},{"batb":[[1,1.78,32.29],[2,1.67,1.4]],"ltp":1.96,"tv":118.23,"id":12343905}]}]}
{"op":"mcm","clk":"4231583580","pt":1631545739495,"mc":[{"id":"1.187560634","rc":[{"batb":[[0,1.8,31.45],[1,1.25,28.88],[2,1.05,477.24]],"ltp":1.96,"tv":111.9,"id":9629296},{"batb":[[0,1.78,32.29],[1,1.67,1.4],[2,1.25,28.88]],"ltp":1.96,"tv":118.23,"id":12343905}]}]}
{"op":"mcm","clk":"4231583796","pt":1631545742303,"mc":[{"id":"1.187560634","rc":[{"batb":[[2,1.11,271.16]],"ltp":1.96,"tv":111.9,"id":9629296}]}]}
{"op":"mcm","clk":"4231583986","pt":1631545744964,"mc":[{"id":"1.187560634","rc":[{"batb":[[0,1.91,59.12],[1,1.89,81.39],[2,1.78,32.29]],"batl":[[0,1.98,82.91],[1,2,69.73]],"ltp":1.96,"tv":118.23,"id":12343905}]}]}
{"op":"mcm","clk":"4231584222","pt":1631545748177,"mc":[{"id":"1.187560634","rc":[{"trd":[[2.02,20.5]],"ltp":2.02,"tv":132.4,"id":9629296},{"trd":[[1.98,20.92]],"batl":[[0,1.98,61.99]],"ltp":1.98,"tv":139.15,"id":12343905}],"tv":271.56}]}
{"op":"mcm","clk":"4231584477","pt":1631545751188,"mc":[{"id":"1.187560634","rc":[{"batb":[[0,1.78,32.29],[1,1.67,1.4],[2,1.25,28.88]],"ltp":1.98,"tv":139.15,"id":12343905}]}]}
{"op":"mcm","clk":"4231584710","pt":1631545754191,"mc":[{"id":"1.187560634","rc":[{"batb":[[0,1.8,57.91],[1,1.78,131.01],[2,1.67,1.4]],"batl":[[0,2.12,73.01],[1,2.14,57.28]],"ltp":1.98,"tv":139.15,"id":12343905}]}]}
{"op":"mcm","clk":"4231585755","pt":1631545768226,"mc":[{"id":"1.187560634","rc":[{"batb":[[2,1.2,387.76]],"ltp":2.02,"tv":132.4,"id":9629296}]}]}
{"op":"mcm","clk":"4231586026","pt":1631545771504,"mc":[{"id":"1.187560634","rc":[{"batb":[[1,1.4,149.14],[2,1.3,198.84]],"ltp":2.02,"tv":132.4,"id":9629296}]}]}
{"op":"mcm","clk":"4231586299","pt":1631545775038,"mc":[{"id":"1.187560634","rc":[{"batb":[[0,1.78,32.29],[1,1.67,1.4],[2,1.3,198.84]],"ltp":1.98,"tv":139.15,"id":12343905}]}]}
{"op":"mcm","clk":"4231586495","pt":1631545777635,"mc":[{"id":"1.187560634","rc":[{"batb":[[1,1.74,177.42],[2,1.4,149.14]],"batl":[[0,1.83,11.53],[1,1.89,257.24],[2,1.9,39.68]],"ltp":2.02,"tv":132.4,"id":9629296},{"batl":[[0,2.28,12.89]],"ltp":1.98,"tv":139.15,"id":12343905}]}]}
{"op":"mcm","clk":"4231586565","pt":1631545778613,"mc":[{"id":"1.187560634","rc":[{"trd":[[1.83,26.41],[1.89,164.22]],"batb":[[1,1.76,85.24],[2,1.75,42.62]],"batl":[[0,1.89,175.13],[1,1.9,7.94],[2,1.91,7.94]],"ltp":1.89,"tv":319.68,"id":9629296}],"tv":458.84}]}
{"op":"mcm","clk":"4231586614","pt":1631545779335,"mc":[{"id":"1.187560634","rc":[{"batb":[[1,1.76,17.04],[2,1.75,8.52]],"ltp":1.89,"tv":319.68,"id":9629296},{"batb":[[0,2,44.71],[1,1.89,26.59],[2,1.67,1.4]],"ltp":1.98,"tv":139.15,"id":12343905}]}]}
{"op":"mcm","clk":"4231586781","pt":1631545781415,"mc":[{"id":"1.187560634","rc":[{"batb":[[0,1.88,83.96],[1,1.86,85.7],[2,1.8,31.45]],"ltp":1.89,"tv":319.68,"id":9629296}]}]}
{"op":"mcm","clk":"4231586894","pt":1631545782621,"mc":[{"id":"1.187560634","rc":[{"batl":[[0,1.89,221.97]],"ltp":1.89,"tv":319.68,"id":9629296},{"batl":[[0,2.2,34.52],[1,2.28,12.89]],"ltp":1.98,"tv":139.15,"id":12343905}]}]}
{"op":"mcm","clk":"4231586905","pt":1631545782731,"mc":[{"id":"1.187560634","rc":[{"batl":[[0,1.89,175.13]],"ltp":1.89,"tv":319.68,"id":9629296},{"batl":[[0,2.28,12.89],[1,2.28,0]],"ltp":1.98,"tv":139.15,"id":12343905}]}]}
{"op":"mcm","clk":"4231587049","pt":1631545784806,"mc":[{"id":"1.187560634","rc":[{"trd":[[1.89,219.96]],"batl":[[0,1.89,147.26]],"ltp":1.89,"tv":375.42,"id":9629296}],"tv":514.58}]}
{"op":"mcm","clk":"4231587524","pt":1631545791356,"mc":[{"id":"1.187560634","rc":[{"trd":[[1.88,31.7]],"batb":[[0,1.88,68.11]],"ltp":1.88,"tv":407.12,"id":9629296},{"batl":[[0,2.24,10.7]],"ltp":1.98,"tv":139.15,"id":12343905}],"tv":546.28}]}
{"op":"mcm","clk":"4231587811","pt":1631545794417,"mc":[{"id":"1.187560634","rc":[{"batb":[[0,1.88,75.2]],"ltp":1.88,"tv":407.12,"id":9629296}]}]}
{"op":"mcm","clk":"4231588605","pt":1631545804664,"mc":[{"id":"1.187560634","rc":[{"batb":[[0,1.76,17.04],[1,1.75,8.52],[2,1.74,8.52]],"batl":[[0,1.9,7.94],[1,1.91,7.94],[2,1.91,0]],"ltp":1.88,"tv":407.12,"id":9629296},{"batb":[[0,1.89,26.59],[1,1.67,1.4],[2,1.5,107.38]],"ltp":1.98,"tv":139.15,"id":12343905}]}]}
{"op":"mcm","clk":"4231588823","pt":1631545807534,"mc":[{"id":"1.187560634","rc":[{"batl":[[2,2.08,67.2]],"ltp":1.88,"tv":407.12,"id":9629296}]}]}
{"op":"mcm","clk":"4231589174","pt":1631545812478,"mc":[{"id":"1.187560634","rc":[{"batl":[[2,2.08,0]],"ltp":1.88,"tv":407.12,"id":9629296}]}]}
{"op":"mcm","clk":"4231589383","pt":1631545815489,"mc":[{"id":"1.187560634","rc":[{"trd":[[1.9,7.94],[1.91,18.43],[2,8.52]],"batl":[[0,2,61.55],[1,1.91,0]],"ltp":2.0,"tv":431.52,"id":9629296},{"trd":[[2,148.66],[2.08,8.14],[2.1,7.18]],"batb":[[0,1.93,56.69],[1,1.91,78.76],[2,1.89,26.59]],"batl":[[0,2.02,67.71],[1,2.06,12.85],[2,2.16,109.59]],"ltp":2.0,"tv":302.28,"id":12343905}],"tv":733.81}]}
{"op":"mcm","clk":"4231589467","pt":1631545816575,"mc":[{"id":"1.187560634","rc":[{"batb":[[0,1.9,26.59],[1,1.76,17.04],[2,1.75,43.5]],"ltp":2.0,"tv":431.52,"id":9629296},{"batb":[[0,1.89,26.59],[1,1.79,31.96],[2,1.67,1.4]],"ltp":2.0,"tv":302.28,"id":12343905}]}]}
{"op":"mcm","clk":"4231589618","pt":1631545818849,"mc":[{"id":"1.187560634","rc":[{"batb":[[0,1.94,63.04],[1,1.92,77.49],[2,1.89,26.59]],"batl":[[0,2.02,102.54],[1,2.04,65.76],[2,2.06,12.85]],"ltp":2.0,"tv":302.28,"id":12343905}]}]}
{"op":"mcm","clk":"4231590129","pt":1631545825691,"mc":[{"id":"1.187560634","rc":[{"batl":[[2,2.16,109.59]],"ltp":2.0,"tv":302.28,"id":12343905}]}]}
{"op":"mcm","clk":"4231590372","pt":1631545828595,"mc":[{"id":"1.187560634","rc":[{"batl":[[1,2.02,8.14]],"ltp":2.0,"tv":431.52,"id":9629296},{"batl":[[0,2.02,110.67]],"ltp":2.0,"tv":302.28,"id":12343905}]}]}
{"op":"mcm","clk":"4231591110","pt":1631545837670,"mc":[{"id":"1.187560634","rc":[{"batb":[[1,1.75,34.98],[2,1.4,149.14]],"ltp":2.0,"tv":431.52,"id":9629296},{"batb":[[0,1.89,26.59],[1,1.79,31.96],[2,1.67,1.4]],"ltp":2.0,"tv":302.28,"id":12343905}]}]}
{"op":"mcm","clk":"4231591121","pt":1631545837780,"mc":[{"id":"1.187560634","rc":[{"batb":[[0,1.75,34.98],[1,1.4,149.14],[2,1.3,198.84]],"ltp":2.0,"tv":431.52,"id":9629296},{"batb":[[0,1.79,31.96],[1,1.67,1.4],[2,1.5,107.38]],"ltp":2.0,"tv":302.28,"id":12343905}]}]}
{"op":"mcm","clk":"4231591327","pt":1631545840578,"mc":[{"id":"1.187560634","rc":[{"batb":[[0,1.82,93.37],[1,1.8,95.18],[2,1.79,31.96]],"batl":[[0,2.24,47.47],[1,2.26,49.19]],"ltp":2.0,"tv":302.28,"id":12343905}]}]}
{"op":"mcm","clk":"4231591703","pt":1631545845673,"mc":[{"id":"1.187560634","rc":[{"batb":[[0,2.02,44.04],[1,1.89,27.09],[2,1.75,34.98]],"batl":[[0,2.16,135.9]],"ltp":2.0,"tv":431.52,"id":9629296},{"batl":[[0,1.89,84.98],[1,1.91,80.02],[2,1.92,15.93]],"ltp":2.0,"tv":302.28,"id":12343905}]}]}
{"op":"mcm","clk":"4231591728","pt":1631545845988,"mc":[{"id":"1.187560634","rc":[{"batb":[[2,1.4,149.14]],"ltp":2.0,"tv":431.52,"id":9629296}]}]}
{"op":"mcm","clk":"4231591892","pt":1631545847987,"mc":[{"id":"1.187560634","rc":[{"batb":[[2,1.5,107.38]],"ltp":2.0,"tv":431.52,"id":9629296}]}]}
{"op":"mcm","clk":"4231592534","pt":1631545856412,"mc":[{"id":"1.187560634","rc":[{"trd":[[1.89,7.12]],"batl":[[0,1.89,83.98]],"ltp":1.89,"tv":304.28,"id":12343905}],"tv":735.81}]}
{"op":"mcm","clk":"4231593570","pt":1631545868640,"mc":[{"id":"1.187560634","rc":[{"batb":[[0,1.89,27.09],[1,1.5,107.38],[2,1.4,149.14]],"ltp":2.0,"tv":431.52,"id":9629296},{"batb":[[0,1.72,35.98],[1,1.67,1.4],[2,1.4,149.14]],"ltp":1.89,"tv":304.28,"id":12343905}]}]}
{"op":"mcm","clk":"4231593830","pt":1631545871620,"mc":[{"id":"1.187560634","rc":[{"batb":[[0,1.75,87.39],[1,1.73,108.56],[2,1.72,35.98]],"batl":[[0,2.04,94.85],[1,2.06,63.92]],"ltp":1.89,"tv":304.28,"id":12343905}]}]}
{"op":"mcm","clk":"4231594423","pt":1631545878748,"mc":[{"id":"1.187560634","rc":[{"batb":[[0,1.72,35.98],[1,1.67,1.4],[2,1.4,149.14]],"ltp":1.89,"tv":304.28,"id":12343905}]}]}
{"op":"mcm","clk":"4231594646","pt":1631545881610,"mc":[{"id":"1.187560634","rc":[{"batl":[[0,2,169.17],[1,2.02,74.26],[2,2.04,37.14]],"ltp":2.0,"tv":431.52,"id":9629296},{"batb":[[0,2,69.17],[1,1.96,63.65],[2,1.94,75.06]],"batl":[[1,2.06,76.31],[2,2.16,102.28]],"ltp":1.89,"tv":304.28,"id":12343905}]}]}
{"op":"mcm","clk":"4231594727","pt":1631545882642,"mc":[{"id":"1.187560634","rc":[{"batb":[[0,1.91,78.52],[1,1.9,39.26],[2,1.89,66.35]],"batl":[[1,2.02,14.86],[2,2.04,7.42]],"ltp":2.0,"tv":431.52,"id":9629296}]}]}
{"op":"mcm","clk":"4231594736","pt":1631545882750,"mc":[{"id":"1.187560634","rc":[{"batb":[[0,1.91,15.7],[1,1.9,7.86],[2,1.89,34.95]],"ltp":2.0,"tv":431.52,"id":9629296}]}]}
{"op":"mcm","clk":"4231595861","pt":1631545897337,"mc":[{"id":"1.187560634","rc":[{"trd":[[2,9.35]],"batl":[[0,2,168.34]],"ltp":2.0,"tv":432.35,"id":9629296},{"trd":[[2,287.83]],"batb":[[0,1.96,63.65],[1,1.94,75.06],[2,1.9,52.17]],"ltp":2.0,"tv":443.45,"id":12343905}],"tv":875.81}]}
{"op":"mcm","clk":"4231596565","pt":1631545907466,"mc":[{"id":"1.187560634","rc":[{"batb":[[0,1.73,36.07],[1,1.5,107.38],[2,1.4,149.14]],"ltp":2.0,"tv":432.35,"id":9629296},{"batb":[[0,1.81,30.87],[1,1.67,1.4],[2,1.5,107.38]],"ltp":2.0,"tv":443.45,"id":12343905}]}]}
{"op":"mcm","clk":"4231596889","pt":1631545912191,"mc":[{"id":"1.187560634","rc":[{"batb":[[0,1.93,70.05],[1,1.91,78.78],[2,1.73,36.07]],"batl":[[0,2,65.78],[1,2.02,67.76]],"ltp":2.0,"tv":432.35,"id":9629296}]}]}
{"op":"mcm","clk":"4231597433","pt":1631545918763,"mc":[{"id":"1.187560634","rc":[{"batb":[[0,1.73,36.07],[1,1.5,107.38],[2,1.4,149.14]],"ltp":2.0,"tv":432.35,"id":9629296}]}]}
{"op":"mcm","clk":"4231597692","pt":1631545921680,"mc":[{"id":"1.187560634","rc":[{"batb":[[0,1.79,58.7],[1,1.77,100.78],[2,1.73,36.07]],"batl":[[0,2.2,90.09],[1,2.22,51.64]],"ltp":2.0,"tv":432.35,"id":9629296}]}]}
{"op":"mcm","clk":"4231599217","pt":1631545939220,"mc":[{"id":"1.187560634","rc":[{"batl":[[0,1.83,16.38],[1,1.84,48.91],[2,1.85,114.47]],"ltp":2.0,"tv":432.35,"id":9629296},{"batl":[[0,2.28,8.74],[1,2.4,88.96]],"ltp":2.0,"tv":443.45,"id":12343905}]}]}
{"op":"mcm","clk":"4231599294","pt":1631545940315,"mc":[{"id":"1.187560634","rc":[{"batb":[[2,1.75,17.14]],"batl":[[1,1.84,16.3],[2,1.85,98.17]],"ltp":2.0,"tv":432.35,"id":9629296},{"batb":[[0,2.1,38.67],[1,1.92,50.83],[2,1.67,1.4]],"ltp":2.0,"tv":443.45,"id":12343905}]}]}
{"op":"mcm","clk":"4231599443","pt":1631545941992,"mc":[{"id":"1.187560634","rc":[{"trd":[[1.83,33.64]],"batl":[[0,1.83,12.76]],"ltp":1.83,"tv":439.59,"id":9629296}],"tv":883.04}]}
{"op":"mcm","clk":"4231599918","pt":1631545948528,"mc":[{"id":"1.187560634","rc":[{"trd":[[1.83,59.12]],"batl":[[0,1.84,16.32],[1,1.85,98.17],[2,1.86,72.67]],"ltp":1.83,"tv":465.07,"id":9629296}],"tv":908.52}]}
{"op":"mcm","clk":"4231600003","pt":1631545949635,"mc":[{"id":"1.187560634","rc":[{"trd":[[1.83,59.16]],"batb":[[0,1.83,127.37],[1,1.79,58.7],[2,1.77,100.78]],"batl":[[0,1.84,16.3]],"ltp":1.83,"tv":465.1,"id":9629296}],"tv":908.56}]}
{"op":"mcm","clk":"4231600076","pt":1631545950641,"mc":[{"id":"1.187560634","rc":[{"batb":[[0,1.83,188.72]],"ltp":1.83,"tv":465.1,"id":9629296}]}]}
{"op":"mcm","clk":"4231600147","pt":1631545951530,"mc":[{"id":"1.187560634","rc":[{"batb":[[0,1.83,38.14]],"ltp":1.83,"tv":465.1,"id":9629296}]}]}
{"op":"mcm","clk":"4231600224","pt":1631545952629,"mc":[{"id":"1.187560634","rc":[{"batb":[[0,1.83,88.01]],"ltp":1.83,"tv":465.1,"id":9629296},{"batl":[[0,2.4,88.96],[1,2.4,0]],"ltp":2.0,"tv":443.45,"id":12343905}]}]}
{"op":"mcm","clk":"4231600306","pt":1631545953517,"mc":[{"id":"1.187560634","rc":[{"batb":[[0,1.79,58.7],[1,1.77,100.78],[2,1.75,17.14]],"ltp":1.83,"tv":465.1,"id":9629296}]}]}
{"op":"mcm","clk":"4231600463","pt":1631545955538,"mc":[{"id":"1.187560634","rc":[{"trd":[[1.84,32.6]],"batb":[[0,1.84,16.18],[1,1.79,58.7],[2,1.77,100.78]],"batl":[[0,1.85,98.17],[1,1.86,88.32],[2,1.87,85.71]],"ltp":1.84,"tv":497.71,"id":9629296},{"batl":[[0,2.24,10.57],[1,2.4,88.96]],"ltp":2.0,"tv":443.45,"id":12343905}],"tv":941.16}]}
{"op":"mcm","clk":"4231600539","pt":1631545956436,"mc":[{"id":"1.187560634","rc":[{"batb":[[0,1.84,58.41]],"ltp":1.84,"tv":497.71,"id":9629296}]}]}
{"op":"mcm","clk":"4231600635","pt":1631545957518,"mc":[{"id":"1.187560634","rc":[{"batb":[[0,1.84,31.87]],"ltp":1.84,"tv":497.71,"id":9629296}]}]}
{"op":"mcm","clk":"4231600682","pt":1631545958034,"mc":[{"id":"1.187560634","rc":[{"batb":[[0,1.84,64.93]],"ltp":1.84,"tv":497.71,"id":9629296}]}]}
{"op":"mcm","clk":"4231600803","pt":1631545959537,"mc":[{"id":"1.187560634","rc":[{"batb":[[0,1.79,58.7],[1,1.77,100.78],[2,1.75,17.14]],"batl":[[1,1.86,72.67]],"ltp":1.84,"tv":497.71,"id":9629296},{"batl":[[0,2.4,88.96],[1,2.4,0]],"ltp":2.0,"tv":443.45,"id":12343905}]}]}
{"op":"mcm","clk":"4231601069","pt":1631545962302,"mc":[{"id":"1.187560634","rc":[{"trd":[[1.85,81.25]],"batl":[[0,1.85,57.55]],"ltp":1.85,"tv":578.96,"id":9629296}],"tv":1022.41}]}
{"op":"mcm","clk":"4231601193","pt":1631545963602,"mc":[{"id":"1.187560634","rc":[{"trd":[[1.85,196.35]],"batb":[[0,1.85,15.68],[1,1.79,58.7],[2,1.77,100.78]],"batl":[[0,1.86,14.83],[1,1.87,85.71],[2,1.87,0]],"ltp":1.85,"tv":694.05,"id":9629296}],"tv":1137.51}]}
{"op":"mcm","clk":"4231601269","pt":1631545964387,"mc":[{"id":"1.187560634","rc":[{"batb":[[0,1.85,35.74],[1,1.55,53.01],[2,1.4,149.14]],"ltp":1.85,"tv":694.05,"id":9629296},{"batb":[[0,1.92,50.83],[1,1.67,1.4],[2,1.6,99.42]],"ltp":2.0,"tv":443.45,"id":12343905}]}]}
{"op":"mcm","clk":"4231601368","pt":1631545965585,"mc":[{"id":"1.187560634","rc":[{"trd":[[1.85,211.49]],"batb":[[0,1.55,53.01],[1,1.4,149.14],[2,1.3,198.84]],"ltp":1.85,"tv":709.19,"id":9629296}],"tv":1152.65}]}
{"op":"mcm","clk":"4231601505","pt":1631545967274,"mc":[{"id":"1.187560634","rc":[{"batb":[[0,1.59,78.27],[1,1.58,75.73],[2,1.55,53.01]],"batl":[[0,2.04,75.09],[1,2.06,63.92]],"ltp":1.85,"tv":709.19,"id":9629296}]}]}
{"op":"mcm","clk":"4231601713","pt":1631545969610,"mc":[{"id":"1.187560634","rc":[{"batb":[[0,1.55,53.01],[1,1.4,149.14],[2,1.3,198.84]],"ltp":1.85,"tv":709.19,"id":9629296}]}]}
{"op":"mcm","clk":"4231601987","pt":1631545972514,"mc":[{"id":"1.187560634","rc":[{"batb":[[0,1.75,87.76],[1,1.73,108.83],[2,1.55,53.01]],"batl":[[0,1.81,79.45],[1,1.83,91.68]],"ltp":1.85,"tv":709.19,"id":9629296}]}]}
{"op":"mcm","clk":"4231602520","pt":1631545979194,"mc":[{"id":"1.187560634","rc":[{"batb":[[0,1.55,53.01],[1,1.4,149.14],[2,1.3,198.84]],"ltp":1.85,"tv":709.19,"id":9629296}]}]}
{"op":"mcm","clk":"4231602794","pt":1631545982216,"mc":[{"id":"1.187560634","rc":[{"batb":[[0,1.59,83.16],[1,1.58,75.74],[2,1.55,53.01]],"batl":[[0,2.04,71.3],[1,2.06,63.92]],"ltp":1.85,"tv":709.19,"id":9629296}]}]}
{"op":"mcm","clk":"4231603101","pt":1631545985648,"mc":[{"id":"1.187560634","rc":[{"batl":[[2,1000,2.17]],"ltp":1.85,"tv":709.19,"id":9629296}]}]}
{"op":"mcm","clk":"4231603146","pt":1631545986126,"mc":[{"id":"1.187560634","rc":[{"batl":[[2,1000,0]],"ltp":1.85,"tv":709.19,"id":9629296}]}]}
{"op":"mcm","clk":"4231603430","pt":1631545989223,"mc":[{"id":"1.187560634","rc":[{"batl":[[2,810,0.07]],"ltp":1.85,"tv":709.19,"id":9629296}]}]}
{"op":"mcm","clk":"4231603710","pt":1631545992538,"mc":[{"id":"1.187560634","rc":[{"batl":[[2,1000,2.24]],"ltp":1.85,"tv":709.19,"id":9629296}]}]}
{"op":"mcm","clk":"4231603746","pt":1631545992955,"mc":[{"id":"1.187560634","rc":[{"batl":[[2,810,0.07]],"ltp":1.85,"tv":709.19,"id":9629296}]}]}
{"op":"mcm","clk":"4231604012","pt":1631545996048,"mc":[{"id":"1.187560634","rc":[{"batl":[[2,820,0.14]],"ltp":1.85,"tv":709.19,"id":9629296}]}]}
{"op":"mcm","clk":"4231604561","pt":1631546002276,"mc":[{"id":"1.187560634","rc":[{"batl":[[0,820,0.14],[1,2.06,0],[2,820,0]],"ltp":1.85,"tv":709.19,"id":9629296}]}]}
{"op":"mcm","clk":"4231604815","pt":1631546005340,"mc":[{"id":"1.187560634","rc":[{"batl":[[0,1.62,212.99],[1,1.64,119.16],[2,1.65,64.27]],"ltp":1.85,"tv":709.19,"id":9629296},{"batb":[[0,2.52,11.9],[1,2.5,85.96],[2,2.48,5.96]],"batl":[[0,2.72,9.91],[1,3,55.65]],"ltp":2.0,"tv":443.45,"id":12343905}]}]}
{"op":"mcm","clk":"4231604890","pt":1631546006235,"mc":[{"id":"1.187560634","rc":[{"batl":[[0,2.72,20.95],[1,2.74,5.52],[2,2.76,5.52]],"ltp":2.0,"tv":443.45,"id":12343905}]}]}
{"op":"mcm","clk":"4231606074","pt":1631546020471,"mc":[{"id":"1.187560634","rc":[{"trd":[[1.62,110.28]],"batl":[[0,1.62,157.85]],"ltp":1.62,"tv":819.48,"id":9629296}],"tv":1262.93}]}
{"op":"mcm","clk":"4231606091","pt":1631546020683,"mc":[{"id":"1.187560634","rc":[{"trd":[[1.62,141.16]],"batl":[[0,1.62,142.41]],"ltp":1.62,"tv":850.36,"id":9629296}],"tv":1293.81}]}
{"op":"mcm","clk":"4231606417","pt":1631546024397,"mc":[{"id":"1.187560634","rc":[{"trd":[[1.62,251.19]],"batl":[[0,1.62,87.4]],"ltp":1.62,"tv":960.38,"id":9629296}],"tv":1403.84}]}
{"op":"mcm","clk":"4231606639","pt":1631546027007,"mc":[{"id":"1.187560634","rc":[{"trd":[[1.62,271.19]],"batl":[[0,1.62,77.4]],"ltp":1.62,"tv":980.38,"id":9629296}],"tv":1423.84}]}
{"op":"mcm","clk":"4231607177","pt":1631546031015,"mc":[{"id":"1.187560634","rc":[{"trd":[[1.62,305.27]],"batl":[[0,1.62,60.36]],"ltp":1.62,"tv":1014.46,"id":9629296}],"tv":1457.92}]}
{"op":"mcm","clk":"4231607297","pt":1631546031841,"mc":[{"id":"1.187560634","rc":[{"trd":[[1.59,1.18]],"batb":[[0,1.59,82.57]],"ltp":1.59,"tv":1015.64,"id":9629296}],"tv":1459.1}]}
{"op":"mcm","clk":"4231608875","pt":1631546042452,"mc":[{"id":"1.187560634","rc":[{"batb":[[0,1.55,53.01],[1,1.5,604.51],[2,1.3,198.84]],"batl":[[1,2.3,314.34],[2,810,0.07]],"ltp":1.59,"tv":1015.64,"id":9629296}]}]}
{"op":"mcm","clk":"4231609096","pt":1631546044249,"mc":[{"id":"1.187560634","rc":[{"trd":[[1.62,339.35]],"batl":[[0,1.62,43.32]],"ltp":1.62,"tv":1049.72,"id":9629296}],"tv":1493.18}]}
{"op":"mcm","clk":"4231609186","pt":1631546045352,"mc":[{"id":"1.187560634","rc":[{"batb":[[1,1.54,72.51],[2,1.53,85.65]],"batl":[[1,1.74,101.72],[2,1.76,103.94]],"ltp":1.62,"tv":1049.72,"id":9629296}]}]}
{"op":"mcm","clk":"4231610359","pt":1631546055380,"mc":[{"id":"1.187560634","rc":[{"trd":[[1.58,0.13]],"ltp":1.58,"tv":1049.85,"id":9629296},{"trd":[[2.72,0.08]],"batl":[[0,2.72,20.87]],"ltp":2.72,"tv":443.53,"id":12343905}],"tv":1493.39}]}
{"op":"mcm","clk":"4231610792","pt":1631546058983,"mc":[{"id":"1.187560634","rc":[{"trd":[[1.62,373.01]],"batl":[[0,1.62,26.49]],"ltp":1.62,"tv":1083.51,"id":9629296}],"tv":1527.05}]}
{"op":"mcm","clk":"4231612019","pt":1631546062576,"mc":[{"id":"1.187560634","rc":[{"trd":[[1.62,406.67]],"batl":[[0,1.62,9.66]],"ltp":1.62,"tv":1117.17,"id":9629296}],"tv":1560.71}]}
{"op":"mcm","clk":"4231612727","pt":1631546065489,"mc":[{"id":"1.187560634","rc":[{"batl":[[0,1.74,101.72],[1,1.76,103.94],[2,2.3,314.34]],"ltp":1.62,"tv":1117.17,"id":9629296},{"batl":[[0,2.72,11.04]],"ltp":2.72,"tv":443.53,"id":12343905}]}]}
{"op":"mcm","clk":"4231613016","pt":1631546068470,"mc":[{"id":"1.187560634","rc":[{"batl":[[0,1.62,9.79],[1,1.74,101.72],[2,1.76,103.94]],"ltp":1.62,"tv":1117.17,"id":9629296},{"batl":[[0,2.72,24.41]],"ltp":2.72,"tv":443.53,"id":12343905}]}]}
{"op":"mcm","clk":"4231613133","pt":1631546069672,"mc":[{"id":"1.187560634","rc":[{"batb":[[0,1.54,72.51],[1,1.53,85.65],[2,1.5,493.21]],"batl":[[0,1.74,101.72],[1,1.76,103.94],[2,2.3,314.34]],"ltp":1.62,"tv":1117.17,"id":9629296},{"batb":[[0,2.24,31.45],[1,1.7,17.05],[2,1.67,1.4]],"ltp":2.72,"tv":443.53,"id":12343905}]}]}
{"op":"mcm","clk":"4231613310","pt":1631546071700,"mc":[{"id":"1.187560634","rc":[{"batb":[[1,1.8,11.93],[2,1.7,17.05]],"ltp":2.72,"tv":443.53,"id":12343905}]}]}
{"op":"mcm","clk":"4231614293","pt":1631546082999,"mc":[{"id":"1.187560634","rc":[{"batb":[[0,1.5,493.21],[1,1.3,198.84],[2,1.25,28.88]],"ltp":1.62,"tv":1117.17,"id":9629296}]}]}
{"op":"mcm","clk":"4231614477","pt":1631546085605,"mc":[{"id":"1.187560634","rc":[{"batb":[[0,1.5,59.97]],"ltp":1.62,"tv":1117.17,"id":9629296},{"batl":[[0,2.48,615.72],[1,2.64,5.51]],"ltp":2.72,"tv":443.53,"id":12343905}]}]}
{"op":"mcm","clk":"4231614555","pt":1631546086604,"mc":[{"id":"1.187560634","rc":[{"batb":[[0,1.68,103.07],[1,1.66,125.73],[2,1.64,43.62]],"batl":[[0,1.74,208.91]],"ltp":1.62,"tv":1117.17,"id":9629296},{"batb":[[0,2.36,12.42],[1,2.24,31.45],[2,2.06,40.35]],"batl":[[0,2.46,11.57],[1,2.48,36.29],[2,2.5,18.14]],"ltp":2.72,"tv":443.53,"id":12343905}]}]}
{"op":"mcm","clk":"4231614597","pt":1631546087010,"mc":[{"id":"1.187560634","rc":[{"batb":[[1,2.32,12.94],[2,2.3,6.46]],"batl":[[1,2.48,12.1],[2,2.5,6.04]],"ltp":2.72,"tv":443.53,"id":12343905}]}]}
{"op":"mcm","clk":"4231615369","pt":1631546096598,"mc":[{"id":"1.187560634","rc":[{"batl":[[0,1.74,101.72]],"ltp":1.62,"tv":1117.17,"id":9629296}]}]}
{"op":"mcm","clk":"4231615418","pt":1631546097121,"mc":[{"id":"1.187560634","rc":[{"batb":[[0,1.58,422.65],[1,1.57,50.41],[2,1.3,198.84]],"batl":[[0,2.3,314.34],[1,810,0.07],[2,2.3,0]],"ltp":1.62,"tv":1117.17,"id":9629296},{"batb":[[0,2.06,40.35],[1,1.7,17.05],[2,1.67,1.4]],"ltp":2.72,"tv":443.53,"id":12343905}]}]}
{"op":"mcm","clk":"4231615647","pt":1631546099898,"mc":[{"id":"1.187560634","rc":[{"batb":[[0,1.61,93.99],[1,1.6,72.3],[2,1.58,422.65]],"batl":[[0,1.88,84.17],[1,1.9,81.49],[2,2.3,314.34]],"ltp":1.62,"tv":1117.17,"id":9629296}]}]}
{"op":"mcm","clk":"4231616471","pt":1631546109754,"mc":[{"id":"1.187560634","rc":[{"batb":[[0,1.58,422.65],[1,1.57,50.41],[2,1.3,198.84]],"ltp":1.62,"tv":1117.17,"id":9629296}]}]}
{"op":"mcm","clk":"4231616590","pt":1631546111024,"mc":[{"id":"1.187560634","rc":[{"batb":[[0,1.57,50.41],[1,1.3,198.84],[2,1.25,28.88]],"batl":[[2,810,0.07]],"ltp":1.62,"tv":1117.17,"id":9629296}]}]}
{"op":"mcm","clk":"4231616744","pt":1631546112644,"mc":[{"id":"1.187560634","rc":[{"batb":[[0,1.81,82.88],[1,1.8,41.44],[2,1.79,41.44]],"batl":[[1,1.89,18.49],[2,1.9,81.49]],"ltp":1.62,"tv":1117.17,"id":9629296},{"batb":[[0,2.12,91.63],[1,2.06,40.35]],"batl":[[0,2.2,8.61],[1,2.36,84.74]],"ltp":2.72,"tv":443.53,"id":12343905}]}]}
{"op":"mcm","clk":"4231616821","pt":1631546113533,"mc":[{"id":"1.187560634","rc":[{"batb":[[0,1.81,149.18],[1,1.8,24.86],[2,1.79,121.94]],"ltp":1.62,"tv":1117.17,"id":9629296},{"batb":[[1,2.1,71.44],[2,2.08,35.72]],"batl":[[1,2.36,50.84]],"ltp":2.72,"tv":443.53,"id":12343905}]}]}
{"op":"mcm","clk":"4231616842","pt":1631546113742,"mc":[{"id":"1.187560634","rc":[{"batb":[[0,1.81,116.03],[1,1.8,8.28],[2,1.79,105.36]],"ltp":1.62,"tv":1117.17,"id":9629296},{"batb":[[1,2.1,14.28],[2,2.08,7.14]],"ltp":2.72,"tv":443.53,"id":12343905}]}]}
{"op":"mcm","clk":"4231617088","pt":1631546116655,"mc":[{"id":"1.187560634","rc":[{"trd":[[2.2,13.38]],"batl":[[0,2.2,1.92]],"ltp":2.2,"tv":456.91,"id":12343905}],"tv":1574.09}]}
{"op":"mcm","clk":"4231617192","pt":1631546117663,"mc":[{"id":"1.187560634","rc":[{"trd":[[1.81,109.48]],"batb":[[0,1.81,61.29]],"ltp":1.81,"tv":1226.65,"id":9629296},{"trd":[[2.2,17.22]],"batl":[[0,2.36,50.84],[1,2.36,0]],"ltp":2.2,"tv":460.75,"id":12343905}],"tv":1687.41}]}
{"op":"mcm","clk":"4231617212","pt":1631546117818,"mc":[{"id":"1.187560634","rc":[{"batl":[[0,1.89,18.49],[1,2.72,245.13],[2,810,0.07]],"ltp":1.81,"tv":1226.65,"id":9629296}]}]}
{"op":"mcm","clk":"4231617443","pt":1631546120742,"mc":[{"id":"1.187560634","rc":[{"batb":[[0,1.81,78.36]],"batl":[[0,1.87,62.89],[1,1.89,101.4],[2,2.72,245.13]],"ltp":1.81,"tv":1226.65,"id":9629296}]}]}
{"op":"mcm","clk":"4231617991","pt":1631546126912,"mc":[{"id":"1.187560634","rc":[{"batl":[[1,1.89,82.91]],"ltp":1.81,"tv":1226.65,"id":9629296}]}]}
{"op":"mcm","clk":"4231618287","pt":1631546130605,"mc":[{"id":"1.187560634","rc":[{"batb":[[0,1.67,456.52],[1,1.3,198.84],[2,1.25,28.88]],"batl":[[0,2.72,245.13],[1,810,0.07],[2,2.72,0]],"ltp":1.81,"tv":1226.65,"id":9629296},{"batb":[[0,1.9,52.34],[1,1.67,1.4],[2,1.6,99.42]],"ltp":2.2,"tv":460.75,"id":12343905}]}]}
{"op":"mcm","clk":"4231618550","pt":1631546133530,"mc":[{"id":"1.187560634","rc":[{"batb":[[0,1.72,79.63],[1,1.7,115.61],[2,1.67,456.52]],"batl":[[0,2.06,112.15],[1,2.08,62.17],[2,2.72,245.13]],"ltp":1.81,"tv":1226.65,"id":9629296}]}]}
{"op":"mcm","clk":"4231618573","pt":1631546133840,"mc":[{"id":"1.187560634","rc":[{"batb":[[0,1.67,456.52],[1,1.3,198.84],[2,1.25,28.88]],"batl":[[0,2.72,245.13],[1,810,0.07],[2,2.72,0]],"ltp":1.81,"tv":1226.65,"id":9629296}]}]}
{"op":"mcm","clk":"4231618714","pt":1631546135499,"mc":[{"id":"1.187560634","rc":[{"batb":[[0,1.84,76.91],[1,1.82,91.92],[2,1.67,456.52]],"batl":[[0,1.91,92.69],[1,1.93,77.68],[2,2.72,245.13]],"ltp":1.81,"tv":1226.65,"id":9629296}]}]}
{"op":"mcm","clk":"4231618999","pt":1631546139153,"mc":[{"id":"1.187560634","rc":[{"batb":[[0,1.67,456.52],[1,1.3,198.84],[2,1.25,28.88]],"batl":[[0,2.72,245.13],[1,810,0.07],[2,2.72,0]],"ltp":1.81,"tv":1226.65,"id":9629296}]}]}
{"op":"mcm","clk":"4231619317","pt":1631546142814,"mc":[{"id":"1.187560634","rc":[{"batb":[[0,1.67,40.68]],"ltp":1.81,"tv":1226.65,"id":9629296}]}]}
{"op":"mcm","clk":"4231619473","pt":1631546144333,"mc":[{"id":"1.187560634","rc":[{"batb":[[0,1.96,76.52],[1,1.95,58.78],[2,1.94,38.26]],"batl":[[0,2.04,10.44],[1,2.12,164.46],[2,2.72,245.13]],"ltp":1.81,"tv":1226.65,"id":9629296},{"batb":[[2,1.5,107.38]],"batl":[[0,2.02,13.62],[1,2.06,97.71]],"ltp":2.2,"tv":460.75,"id":12343905}]}]}
{"op":"mcm","clk":"4231619604","pt":1631546145444,"mc":[{"id":"1.187560634","rc":[{"batb":[[0,1.96,15.3],[1,1.95,28.18],[2,1.94,7.66]],"ltp":1.81,"tv":1226.65,"id":9629296},{"batb":[[0,1.96,56.32],[1,1.94,90.5],[2,1.93,7.74]],"batl":[[1,2.04,101.85],[2,2.06,161.63]],"ltp":2.2,"tv":460.75,"id":12343905}]}]}
{"op":"mcm","clk":"4231620226","pt":1631546149241,"mc":[{"id":"1.187560634","rc":[{"trd":[[1.96,71.49],[1.98,13.9]],"batb":[[0,1.95,28.72],[1,1.94,7.66],[2,1.89,27.01]],"ltp":1.96,"tv":1270.07,"id":9629296},{"trd":[[2.02,13.62]],"batl":[[0,2.04,101.85],[1,2.06,161.63],[2,2.06,0]],"ltp":2.02,"tv":474.37,"id":12343905}],"tv":1744.45}]}
{"op":"mcm","clk":"4231621377","pt":1631546155572,"mc":[{"id":"1.187560634","rc":[{"batb":[[0,1.81,30.78],[1,1.74,410.28],[2,1.4,149.14]],"batl":[[0,2.72,245.13],[1,810,0.07],[2,2.72,0]],"ltp":1.96,"tv":1270.07,"id":9629296},{"batb":[[0,1.79,31.71],[1,1.67,1.4],[2,1.5,107.38]],"ltp":2.02,"tv":474.37,"id":12343905}]}]}
{"op":"mcm","clk":"4231621832","pt":1631546158464,"mc":[{"id":"1.187560634","rc":[{"batb":[[0,1.83,91.03],[1,1.81,93.47],[2,1.79,31.71]],"batl":[[0,2.14,95.72],[1,2.16,55.82]],"ltp":2.02,"tv":474.37,"id":12343905}]}]}
{"op":"mcm","clk":"4231622982","pt":1631546166365,"mc":[{"id":"1.187560634","rc":[{"batb":[[1,1.4,149.14],[2,1.3,198.84]],"batl":[[0,810,0.07],[1,810,0]],"ltp":1.96,"tv":1270.07,"id":9629296}]}]}
{"op":"mcm","clk":"4231623184","pt":1631546167667,"mc":[{"id":"1.187560634","rc":[{"batl":[[0,2.2,15.93],[1,2.28,100.71],[2,810,0.07]],"ltp":1.96,"tv":1270.07,"id":9629296},{"batl":[[0,1.89,73.9],[1,1.9,130.31],[2,1.91,23.69]],"ltp":2.02,"tv":474.37,"id":12343905}]}]}
{"op":"mcm","clk":"4231623296","pt":1631546168557,"mc":[{"id":"1.187560634","rc":[{"batb":[[0,2,44.29],[1,1.88,27.34],[2,1.4,149.14]],"ltp":1.96,"tv":1270.07,"id":9629296},{"batb":[[1,1.81,110.05],[2,1.8,8.28]],"ltp":2.02,"tv":474.37,"id":12343905}]}]}
{"op":"mcm","clk":"4231623420","pt":1631546169655,"mc":[{"id":"1.187560634","rc":[{"batb":[[2,1.82,407.19]],"batl":[[2,3.15,203.39]],"ltp":1.96,"tv":1270.07,"id":9629296}]}]}
{"op":"mcm","clk":"4231623733","pt":1631546172377,"mc":[{"id":"1.187560634","rc":[{"trd":[[2.12,19.51]],"ltp":2.12,"tv":1289.58,"id":9629296},{"trd":[[1.89,29]],"batl":[[0,1.89,52.02]],"ltp":1.89,"tv":496.25,"id":12343905}],"tv":1785.84}]}
{"op":"mcm","clk":"4231627343","pt":1631546203602,"mc":[{"id":"1.187560634","rc":[{"batl":[[0,3.15,203.39],[1,810,0.07],[2,3.15,0]],"ltp":2.12,"tv":1289.58,"id":9629296},{"batb":[[0,1.79,31.71],[1,1.72,36.32],[2,1.67,1.4]],"ltp":1.89,"tv":496.25,"id":12343905}]}]}
{"op":"mcm","clk":"4231627358","pt":1631546203707,"mc":[{"id":"1.187560634","rc":[{"batb":[[0,1.88,27.34],[1,1.82,407.19],[2,1.4,149.14]],"ltp":2.12,"tv":1289.58,"id":9629296},{"batb":[[0,1.72,36.32],[1,1.67,1.4],[2,1.4,149.14]],"ltp":1.89,"tv":496.25,"id":12343905}]}]}
{"op":"mcm","clk":"4231627687","pt":1631546206536,"mc":[{"id":"1.187560634","rc":[{"batb":[[0,1.75,111.01],[1,1.73,108.69],[2,1.72,36.32]],"batl":[[0,2.04,58.61],[1,2.06,63.92]],"ltp":1.89,"tv":496.25,"id":12343905}]}]}
{"op":"mcm","clk":"4231628756","pt":1631546215326,"mc":[{"id":"1.187560634","rc":[{"batb":[[1,1.4,149.14],[2,1.3,198.84]],"ltp":2.12,"tv":1289.58,"id":9629296}]}]}
{"op":"mcm","clk":"4231628961","pt":1631546217138,"mc":[{"id":"1.187560634","rc":[{"batb":[[0,2.22,40.54],[1,2.2,20.27],[2,2.18,20.27]],"batl":[[0,2.28,5.96],[1,3.15,203.39],[2,810,0.07]],"ltp":2.12,"tv":1289.58,"id":9629296},{"batb":[[2,1.72,160.8]],"batl":[[0,1.82,102.53],[1,1.83,235.52],[2,1.84,89.81]],"ltp":1.89,"tv":496.25,"id":12343905}]}]}
{"op":"mcm","clk":"4231629104","pt":1631546218128,"mc":[{"id":"1.187560634","rc":[{"batb":[[1,1.73,126.03],[2,1.72,169.48]],"ltp":1.89,"tv":496.25,"id":12343905}]}]}
{"op":"mcm","clk":"4231629579","pt":1631546222030,"mc":[{"id":"1.187560634","rc":[{"trd":[[2.22,35.72]],"batb":[[0,2.22,22.68]],"ltp":2.22,"tv":1325.3,"id":9629296}],"tv":1821.56}]}
{"op":"mcm","clk":"4231630329","pt":1631546228559,"mc":[{"id":"1.187560634","rc":[{"trd":[[2.22,50.32]],"batb":[[0,2.22,15.38]],"ltp":2.22,"tv":1339.9,"id":9629296}],"tv":1836.16}]}
{"op":"mcm","clk":"4231632443","pt":1631546247575,"mc":[{"id":"1.187560634","rc":[{"batb":[[0,1.98,46.72],[1,1.92,400.77],[2,1.6,99.42]],"batl":[[0,3.15,203.39],[1,810,0.07],[2,810,0]],"ltp":2.22,"tv":1339.9,"id":9629296},{"batb":[[0,1.67,1.4],[1,1.66,40.68],[2,1.4,149.14]],"ltp":1.89,"tv":496.25,"id":12343905}]}]}
{"op":"mcm","clk":"4231632712","pt":1631546250195,"mc":[{"id":"1.187560634","rc":[{"batb":[[0,1.69,116.31],[1,1.67,124.19],[2,1.66,40.68]],"batl":[[0,1.93,78],[1,1.95,75.18]],"ltp":1.89,"tv":496.25,"id":12343905}]}]}
{"op":"mcm","clk":"4231632816","pt":1631546250979,"mc":[{"id":"1.187560634","rc":[{"batb":[[0,1.67,1.4],[1,1.66,40.68],[2,1.4,149.14]],"ltp":1.89,"tv":496.25,"id":12343905}]}]}
{"op":"mcm","clk":"4231632955","pt":1631546252186,"mc":[{"id":"1.187560634","rc":[{"batl":[[0,810,0.07],[1,810,0]],"ltp":2.22,"tv":1339.9,"id":9629296}]}]}
{"op":"mcm","clk":"4231633112","pt":1631546253602,"mc":[{"id":"1.187560634","rc":[{"batl":[[0,1.87,7.72]],"ltp":1.89,"tv":496.25,"id":12343905}]}]}
{"op":"mcm","clk":"4231633172","pt":1631546254182,"mc":[{"id":"1.187560634","rc":[{"batb":[[0,2.32,98.96],[1,2.3,100],[2,2.28,6.52]],"batl":[[0,2.5,88.9],[1,810,0.07]],"ltp":2.22,"tv":1339.9,"id":9629296},{"batb":[[0,1.72,10.39],[1,1.69,116.31],[2,1.67,124.19]],"batl":[[0,1.75,82.27],[1,1.77,101.75]],"ltp":1.89,"tv":496.25,"id":12343905}]}]}
{"op":"mcm","clk":"4231633275","pt":1631546255278,"mc":[{"id":"1.187560634","rc":[{"batl":[[0,2.46,12.2],[1,2.48,6.1],[2,2.5,95]],"ltp":2.22,"tv":1339.9,"id":9629296}]}]}
{"op":"mcm","clk":"4231633636","pt":1631546258905,"mc":[{"id":"1.187560634","rc":[{"trd":[[2.32,15.52]],"batb":[[0,2.32,91.2]],"ltp":2.32,"tv":1355.42,"id":9629296}],"tv":1851.68}]}
{"op":"mcm","clk":"4231635337","pt":1631546275108,"mc":[{"id":"1.187560634","rc":[{"batb":[[0,2.1,39.17],[1,1.92,400.77],[2,1.7,17.05]],"batl":[[0,3.65,172.94],[1,810,0.07],[2,2.5,0]],"ltp":2.32,"tv":1355.42,"id":9629296},{"batb":[[0,1.67,1.4],[1,1.62,44.79],[2,1.3,198.84]],"ltp":1.89,"tv":496.25,"id":12343905}]}]}
{"op":"mcm","clk":"4231635971","pt":1631546280609,"mc":[{"id":"1.187560634","rc":[{"batl":[[0,2.42,212.49],[1,3.65,172.94],[2,810,0.07]],"ltp":2.32,"tv":1355.42,"id":9629296}]}]}
{"op":"mcm","clk":"4231636002","pt":1631546280933,"mc":[{"id":"1.187560634","rc":[{"batl":[[0,3.65,172.94],[1,810,0.07],[2,810,0]],"ltp":2.32,"tv":1355.42,"id":9629296},{"batb":[[0,1.71,81.86],[1,1.69,117.63],[2,1.67,1.4]],"batl":[[0,1.77,104.18],[1,1.79,98.03]],"ltp":1.89,"tv":496.25,"id":12343905}]}]}
{"op":"mcm","clk":"4231636797","pt":1631546287945,"mc":[{"id":"1.187560634","rc":[{"batb":[[0,1.67,1.4],[1,1.62,44.79],[2,1.3,198.84]],"ltp":1.89,"tv":496.25,"id":12343905}]}]}
{"op":"mcm","clk":"4231636947","pt":1631546289554,"mc":[{"id":"1.187560634","rc":[{"batl":[[1,810,0]],"ltp":2.32,"tv":1355.42,"id":9629296}]}]}
{"op":"mcm","clk":"4231637092","pt":1631546291128,"mc":[{"id":"1.187560634","rc":[{"batl":[[0,1.83,77.8],[1,1.85,88.37]],"ltp":1.89,"tv":496.25,"id":12343905}]}]}
{"op":"mcm","clk":"4231637358","pt":1631546293435,"mc":[{"id":"1.187560634","rc":[{"batb":[[2,1.6,99.42]],"ltp":2.32,"tv":1355.42,"id":9629296},{"batb":[[0,1.8,8.02],[1,1.79,16.76],[2,1.78,8.38]],"batl":[[0,1.83,86.66],[2,1.86,164.81]],"ltp":1.89,"tv":496.25,"id":12343905}]}]}
{"op":"mcm","clk":"4231637470","pt":1631546294536,"mc":[{"id":"1.187560634","rc":[{"batb":[[0,2.14,14.02],[1,2.12,7],[2,2.1,46.17]],"ltp":2.32,"tv":1355.42,"id":9629296}]}]}
{"op":"mcm","clk":"4231637606","pt":1631546295947,"mc":[{"id":"1.187560634","rc":[{"batl":[[0,3.3,194.76]],"ltp":2.32,"tv":1355.42,"id":9629296}]}]}
{"op":"mcm","clk":"4231637871","pt":1631546298334,"mc":[{"id":"1.187560634","rc":[{"trd":[[2.2,57.4]],"ltp":2.2,"tv":1362.79,"id":9629296},{"trd":[[1.83,34.42]],"batl":[[0,1.83,77.8]],"ltp":1.83,"tv":505.11,"id":12343905}],"tv":1867.91}]}
{"op":"mcm","clk":"4231638457","pt":1631546304485,"mc":[{"id":"1.187560634","rc":[{"batl":[[0,3.2,5.13],[1,3.3,194.76]],"ltp":2.2,"tv":1362.79,"id":9629296}]}]}
{"op":"mcm","clk":"4231639605","pt":1631546317590,"mc":[{"id":"1.187560634","rc":[{"batb":[[0,1.95,48.65],[1,1.92,400.77],[2,1.6,99.42]],"batl":[[0,3.3,194.76],[1,3.3,0]],"ltp":2.2,"tv":1362.79,"id":9629296},{"batb":[[0,1.67,1.4],[1,1.66,40.85],[2,1.3,198.84]],"ltp":1.83,"tv":505.11,"id":12343905}]}]}
{"op":"mcm","clk":"4231639837","pt":1631546320410,"mc":[{"id":"1.187560634","rc":[{"batb":[[0,1.7,88.27],[1,1.68,120.09],[2,1.67,1.4]],"batl":[[0,1.96,59.78],[1,1.98,71.82]],"ltp":1.83,"tv":505.11,"id":12343905}]}]}
{"op":"mcm","clk":"4231640749","pt":1631546330498,"mc":[{"id":"1.187560634","rc":[{"batl":[[0,2.46,72.28]],"ltp":2.2,"tv":1362.79,"id":9629296},{"batb":[[0,1.72,18],[1,1.7,88.27],[2,1.68,120.09]],"batl":[[0,1.76,111.44],[1,1.77,50.86],[2,1.78,266.84]],"ltp":1.83,"tv":505.11,"id":12343905}]}]}
{"op":"mcm","clk":"4231640848","pt":1631546331592,"mc":[{"id":"1.187560634","rc":[{"batb":[[0,2.2,33.8],[1,2.1,39.09],[2,1.95,48.65]],"batl":[[0,2.44,12.3],[1,2.46,78.42],[2,2.48,6.14]],"ltp":2.2,"tv":1362.79,"id":9629296},{"batl":[[1,1.77,16.96],[2,1.78,249.89]],"ltp":1.83,"tv":505.11,"id":12343905}]}]}
{"op":"mcm","clk":"4231640899","pt":1631546332006,"mc":[{"id":"1.187560634","rc":[{"batb":[[2,1.92,400.77]],"ltp":2.2,"tv":1362.79,"id":9629296}]}]}
{"op":"mcm","clk":"4231641215","pt":1631546335390,"mc":[{"id":"1.187560634","rc":[{"trd":[[2.3,6.94]],"ltp":2.3,"tv":1369.73,"id":9629296},{"trd":[[1.76,9.07]],"batl":[[0,1.76,102.37]],"ltp":1.76,"tv":514.18,"id":12343905}],"tv":1883.92}]}
{"op":"mcm","clk":"4231642147","pt":1631546345527,"mc":[{"id":"1.187560634","rc":[{"batb":[[0,1.7,88.27],[1,1.68,120.09],[2,1.67,1.4]],"ltp":1.76,"tv":514.18,"id":12343905}]}]}
{"op":"mcm","clk":"4231642394","pt":1631546348345,"mc":[{"id":"1.187560634","rc":[{"batb":[[0,1.74,12.78],[1,1.7,88.27],[2,1.68,120.09]],"batl":[[2,1.78,262.01]],"ltp":1.76,"tv":514.18,"id":12343905}]}]}
{"op":"mcm","clk":"4231643055","pt":1631546355652,"mc":[{"id":"1.187560634","rc":[{"batl":[[1,2.46,6.14]],"ltp":2.3,"tv":1369.73,"id":9629296},{"batb":[[0,1.7,88.27],[1,1.68,120.09],[2,1.67,1.4]],"batl":[[2,1.78,108.29]],"ltp":1.76,"tv":514.18,"id":12343905}]}]}
{"op":"mcm","clk":"4231643090","pt":1631546356123,"mc":[{"id":"1.187560634","rc":[{"batb":[[0,2.1,39.09],[1,1.92,400.77],[2,1.7,17.05]],"batl":[[0,3.65,172.94],[1,2.46,0],[2,2.48,0]],"ltp":2.3,"tv":1369.73,"id":9629296},{"batb":[[0,1.67,1.4],[1,1.62,44.37],[2,1.3,198.84]],"ltp":1.76,"tv":514.18,"id":12343905}]}]}
{"op":"mcm","clk":"4231643422","pt":1631546359625,"mc":[{"id":"1.187560634","rc":[{"batb":[[1,1.66,70.36],[2,1.65,64.31]],"batl":[[0,1.74,88.23],[1,1.83,60.74],[2,1.85,88.4]],"ltp":1.76,"tv":514.18,"id":12343905}]}]}
{"op":"mcm","clk":"4231643500","pt":1631546360565,"mc":[{"id":"1.187560634","rc":[{"batl":[[0,1.74,24.7],[1,1.83,0],[2,1.85,0]],"ltp":1.76,"tv":514.18,"id":12343905}]}]}
{"op":"mcm","clk":"4231643741","pt":1631546363334,"mc":[{"id":"1.187560634","rc":[{"batb":[[0,2.36,8.28],[1,2.1,39.09],[2,1.92,400.77]],"batl":[[0,2.42,6.78],[1,2.56,93.81],[2,3.65,172.94]],"ltp":2.3,"tv":1369.73,"id":9629296},{"batl":[[0,1.71,88.53],[1,1.72,69.77],[2,1.73,161.67]],"ltp":1.76,"tv":514.18,"id":12343905}]}]}
{"op":"mcm","clk":"4231643831","pt":1631546364376,"mc":[{"id":"1.187560634","rc":[{"batb":[[1,2.28,30.87],[2,2.16,35.98]],"ltp":2.3,"tv":1369.73,"id":9629296},{"batb":[[2,1.65,82.49]],"batl":[[2,1.73,126.98]],"ltp":1.76,"tv":514.18,"id":12343905}]}]}
{"op":"mcm","clk":"4231644194","pt":1631546368144,"mc":[{"id":"1.187560634","rc":[{"trd":[[2.4,2.97]],"ltp":2.4,"tv":1372.7,"id":9629296},{"trd":[[1.71,4.17]],"batl":[[0,1.71,84.36]],"ltp":1.71,"tv":518.35,"id":12343905}],"tv":1891.06}]}
{"op":"mcm","clk":"4231645797","pt":1631546386119,"mc":[{"id":"1.187560634","rc":[{"trd":[[2.42,0.7]],"batl":[[0,2.42,6.08]],"ltp":2.42,"tv":1373.4,"id":9629296},{"trd":[[1.7,0.99]],"ltp":1.7,"tv":519.34,"id":12343905}],"tv":1892.75}]}
{"op":"mcm","clk":"4231646648","pt":1631546396315,"mc":[{"id":"1.187560634","rc":[{"batb":[[0,2.28,30.87],[1,2.16,35.98],[2,2.1,39.09]],"batl":[[0,2.56,93.81],[1,3.65,172.94],[2,3.65,0]],"ltp":2.42,"tv":1373.4,"id":9629296}]}]}
{"op":"mcm","clk":"4231646878","pt":1631546399218,"mc":[{"id":"1.187560634","rc":[{"batb":[[0,2.36,9],[1,2.28,30.87],[2,2.16,35.98]],"batl":[[0,2.42,6.08],[1,2.56,93.81],[2,3.65,172.94]],"ltp":2.42,"tv":1373.4,"id":9629296}]}]}
{"op":"mcm","clk":"4231653184","pt":1631546465302,"mc":[{"id":"1.187560634","rc":[{"batb":[[0,2.16,35.98],[1,1.92,400.77],[2,1.7,17.05]],"batl":[[0,3.65,172.94],[1,2.56,0],[2,3.65,0]],"ltp":2.42,"tv":1373.4,"id":9629296},{"batb":[[1,1.54,54.35],[2,1.3,198.84]],"ltp":1.7,"tv":519.34,"id":12343905}]}]}
{"op":"mcm","clk":"4231653448","pt":1631546468226,"mc":[{"id":"1.187560634","rc":[{"batb":[[1,1.56,132.38],[2,1.55,81.28]],"batl":[[0,1.79,100.57],[1,1.81,94.58]],"ltp":1.7,"tv":519.34,"id":12343905}]}]}
{"op":"mcm","clk":"4231653981","pt":1631546473710,"mc":[{"id":"1.187560634","rc":[{"batb":[[1,1.54,54.35],[2,1.3,198.84]],"ltp":1.7,"tv":519.34,"id":12343905}]}]}
{"op":"mcm","clk":"4231654237","pt":1631546476642,"mc":[{"id":"1.187560634","rc":[{"batb":[[2,1.6,99.42]],"batl":[[0,2.46,147.59]],"ltp":2.42,"tv":1373.4,"id":9629296},{"batb":[[0,1.76,16.31],[1,1.75,85.72],[2,1.74,42.86]],"batl":[[1,1.8,114.71],[2,1.81,94.58]],"ltp":1.7,"tv":519.34,"id":12343905}]}]}
{"op":"mcm","clk":"4231654312","pt":1631546477423,"mc":[{"id":"1.187560634","rc":[{"batb":[[0,2.2,68.18],[1,2.18,34.1],[2,2.16,70.08]],"ltp":2.42,"tv":1373.4,"id":9629296},{"batb":[[1,1.75,17.14],[2,1.74,8.58]],"ltp":1.7,"tv":519.34,"id":12343905}]}]}
{"op":"mcm","clk":"4231654389","pt":1631546478119,"mc":[{"id":"1.187560634","rc":[{"batb":[[0,2.2,13.64],[1,2.18,6.82],[2,2.16,42.8]],"ltp":2.42,"tv":1373.4,"id":9629296}]}]}
{"op":"mcm","clk":"4231654537","pt":1631546479422,"mc":[{"id":"1.187560634","rc":[{"batl":[[1,3.45,183.07]],"ltp":2.42,"tv":1373.4,"id":9629296}]}]}
{"op":"mcm","clk":"4231654777","pt":1631546481642,"mc":[{"id":"1.187560634","rc":[{"trd":[[2.26,10.55]],"ltp":2.26,"tv":1383.95,"id":9629296},{"trd":[[1.79,13.32]],"batl":[[0,1.79,87.25]],"ltp":1.79,"tv":532.66,"id":12343905}],"tv":1916.62}]}
{"op":"mcm","clk":"4231655151","pt":1631546485526,"mc":[{"id":"1.187560634","rc":[{"batb":[[0,2.16,35.98],[1,2.06,41.1],[2,1.92,400.77]],"batl":[[0,3.45,183.07],[1,3.45,0]],"ltp":2.26,"tv":1383.95,"id":9629296},{"batb":[[0,1.73,82.51],[1,1.71,112.9],[2,1.69,38.58]],"batl":[[1,1.81,94.58],[2,1.81,0]],"ltp":1.79,"tv":532.66,"id":12343905}]}]}
{"op":"mcm","clk":"4231655202","pt":1631546485951,"mc":[{"id":"1.187560634","rc":[{"batb":[[0,2.06,41.1],[1,1.92,400.77],[2,1.6,99.42]],"ltp":2.26,"tv":1383.95,"id":9629296},{"batb":[[0,1.67,1.4],[1,1.6,46.22],[2,1.3,198.84]],"ltp":1.79,"tv":532.66,"id":12343905}]}]}
{"op":"mcm","clk":"4231655672","pt":1631546491057,"mc":[{"id":"1.187560634","rc":[{"batb":[[0,1.71,90.34],[1,1.69,117.6],[2,1.67,1.4]],"batl":[[0,1.77,95.92],[1,1.79,98.01]],"ltp":1.79,"tv":532.66,"id":12343905}]}]}
{"op":"mcm","clk":"4231656137","pt":1631546495774,"mc":[{"id":"1.187560634","rc":[{"batb":[[0,1.67,1.4],[1,1.6,46.22],[2,1.3,198.84]],"ltp":1.79,"tv":532.66,"id":12343905}]}]}
{"op":"mcm","clk":"4231656366","pt":1631546498656,"mc":[{"id":"1.187560634","rc":[{"batb":[[1,1.64,85.59],[2,1.63,67.2]],"batl":[[0,1.86,82.22],[1,1.88,84]],"ltp":1.79,"tv":532.66,"id":12343905}]}]}
{"op":"mcm","clk":"4231657211","pt":1631546508165,"mc":[{"id":"1.187560634","rc":[{"batb":[[1,1.6,46.22],[2,1.3,198.84]],"ltp":1.79,"tv":532.66,"id":12343905}]}]}
{"op":"mcm","clk":"4231657522","pt":1631546511089,"mc":[{"id":"1.187560634","rc":[{"batl":[[0,2.2,7.87],[1,2.24,53.57]],"ltp":2.26,"tv":1383.95,"id":9629296},{"batb":[[0,1.81,49.73],[1,1.8,86.49],[2,1.79,24.86]],"batl":[[0,1.86,171.92],[2,1.89,19.73]],"ltp":1.79,"tv":532.66,"id":12343905}]}]}
{"op":"mcm","clk":"4231657647","pt":1631546512098,"mc":[{"id":"1.187560634","rc":[{"batb":[[0,2.1,14.28],[1,2.08,7.14],[2,2.06,48.24]],"ltp":2.26,"tv":1383.95,"id":9629296}]}]}
{"op":"mcm","clk":"4231657756","pt":1631546513594,"mc":[{"id":"1.187560634","rc":[{"batl":[[2,3.3,194.76]],"ltp":2.26,"tv":1383.95,"id":9629296}]}]}
{"op":"mcm","clk":"4231657970","pt":1631546515966,"mc":[{"id":"1.187560634","rc":[{"trd":[[2.16,12.31]],"ltp":2.16,"tv":1396.26,"id":9629296},{"trd":[[1.86,14.3]],"batl":[[0,1.86,157.62]],"ltp":1.86,"tv":546.96,"id":12343905}],"tv":1943.23}]}
{"op":"mcm","clk":"4231658173","pt":1631546518260,"mc":[{"id":"1.187560634","rc":[{"trd":[[2.16,31.65]],"ltp":2.16,"tv":1415.6,"id":9629296},{"trd":[[1.86,36.76]],"batl":[[0,1.86,135.16]],"ltp":1.86,"tv":569.42,"id":12343905}],"tv":1985.03}]}
{"op":"mcm","clk":"4231658242","pt":1631546519081,"mc":[{"id":"1.187560634","rc":[{"batb":[[1,1.8,94.66]],"ltp":1.86,"tv":569.42,"id":12343905}]}]}
{"op":"mcm","clk":"4231658483","pt":1631546521575,"mc":[{"id":"1.187560634","rc":[{"batb":[[0,2.06,41.1],[1,1.99,45.46],[2,1.92,400.77]],"batl":[[0,3.3,194.76],[1,2.24,0],[2,3.3,0]],"ltp":2.16,"tv":1415.6,"id":9629296},{"batb":[[0,1.8,69.8],[1,1.78,98.61],[2,1.75,34.14]],"batl":[[0,1.86,45.46],[2,1.89,0]],"ltp":1.86,"tv":569.42,"id":12343905}]}]}
{"op":"mcm","clk":"4231658514","pt":1631546521995,"mc":[{"id":"1.187560634","rc":[{"batb":[[0,1.99,45.46],[1,1.92,400.77],[2,1.6,99.42]],"ltp":2.16,"tv":1415.6,"id":9629296},{"batb":[[0,1.68,39.34],[1,1.67,1.4],[2,1.3,198.84]],"ltp":1.86,"tv":569.42,"id":12343905}]}]}
{"op":"mcm","clk":"4231658663","pt":1631546523617,"mc":[{"id":"1.187560634","rc":[{"batl":[[0,1.83,300]],"ltp":1.86,"tv":569.42,"id":12343905}]}]}
{"op":"mcm","clk":"4231659003","pt":1631546527291,"mc":[{"id":"1.187560634","rc":[{"batb":[[0,1.78,103.3],[1,1.76,102.45],[2,1.68,39.34]],"batl":[[1,1.85,93.95],[2,1.87,85.32]],"ltp":1.86,"tv":569.42,"id":12343905}]}]}
{"op":"mcm","clk":"4231659190","pt":1631546529113,"mc":[{"id":"1.187560634","rc":[{"batb":[[0,1.68,39.34],[1,1.67,1.4],[2,1.3,198.84]],"batl":[[1,1.85,0],[2,1.87,0]],"ltp":1.86,"tv":569.42,"id":12343905}]}]}
{"op":"mcm","clk":"4231659447","pt":1631546531997,"mc":[{"id":"1.187560634","rc":[{"batb":[[0,1.72,101.1],[1,1.7,115.21],[2,1.68,39.34]],"batl":[[1,1.92,64.37],[2,1.94,76.3]],"ltp":1.86,"tv":569.42,"id":12343905}]}]}
{"op":"mcm","clk":"4231659626","pt":1631546533979,"mc":[{"id":"1.187560634","rc":[{"batb":[[0,2.2,10],[1,1.99,45.46],[2,1.92,400.77]],"ltp":2.16,"tv":1415.6,"id":9629296}]}]}
{"op":"mcm","clk":"4231659697","pt":1631546534715,"mc":[{"id":"1.187560634","rc":[{"trd":[[2.2,77.32]],"batb":[[0,1.99,45.5],[1,1.92,400.77],[2,1.6,99.42]],"ltp":2.2,"tv":1435.52,"id":9629296}],"tv":2004.95}]}
{"op":"mcm","clk":"4231659792","pt":1631546536025,"mc":[{"id":"1.187560634","rc":[{"batb":[[0,1.68,39.34],[1,1.67,1.4],[2,1.3,198.84]],"ltp":1.86,"tv":569.42,"id":12343905}]}]}
{"op":"mcm","clk":"4231660085","pt":1631546539010,"mc":[{"id":"1.187560634","rc":[{"trd":[[2.2,326.96]],"batb":[[0,1.99,45.46]],"batl":[[0,2.16,1.33],[1,2.24,111.02],[2,3.3,194.76]],"ltp":2.2,"tv":1685.16,"id":9629296},{"trd":[[1.83,334.42]],"batb":[[0,1.86,57.39],[1,1.84,88.51],[2,1.68,39.34]],"batl":[[0,1.92,181.49],[1,1.94,76.3],[2,1.94,0]],"ltp":1.83,"tv":869.42,"id":12343905}],"tv":2554.59}]}
{"op":"mcm","clk":"4231660209","pt":1631546540336,"mc":[{"id":"1.187560634","rc":[{"batb":[[1,1.95,48.82],[2,1.92,400.77]],"ltp":2.2,"tv":1685.16,"id":9629296},{"batb":[[2,1.8,30.95]],"batl":[[2,1.98,15.16]],"ltp":1.83,"tv":869.42,"id":12343905}]}]}
{"op":"mcm","clk":"4231660352","pt":1631546541900,"mc":[{"id":"1.187560634","rc":[{"trd":[[2.16,34.31]],"batl":[[0,2.24,111.02],[1,3.3,194.76],[2,3.3,0]],"ltp":2.16,"tv":1687.82,"id":9629296}],"tv":2557.25}]}
{"op":"mcm","clk":"4231661055","pt":1631546548922,"mc":[{"id":"1.187560634","rc":[{"batl":[[0,1.92,173.8]],"ltp":1.83,"tv":869.42,"id":12343905}]}]}
{"op":"mcm","clk":"4231661296","pt":1631546551643,"mc":[{"id":"1.187560634","rc":[{"batl":[[0,3.3,194.76],[1,3.3,0]],"ltp":2.16,"tv":1687.82,"id":9629296},{"batb":[[0,1.8,30.95],[1,1.75,34.31],[2,1.67,1.4]],"ltp":1.83,"tv":869.42,"id":12343905}]}]}
{"op":"mcm","clk":"4231661339","pt":1631546552012,"mc":[{"id":"1.187560634","rc":[{"batb":[[0,1.95,48.82],[1,1.92,400.77],[2,1.5,107.38]],"ltp":2.16,"tv":1687.82,"id":9629296},{"batb":[[0,1.75,34.31],[1,1.67,1.4],[2,1.4,149.15]],"ltp":1.83,"tv":869.42,"id":12343905}]}]}
{"op":"mcm","clk":"4231661602","pt":1631546554561,"mc":[{"id":"1.187560634","rc":[{"batb":[[0,1.8,65.36],[1,1.78,98.57],[2,1.75,34.31]],"batl":[[0,1.97,86.4],[1,1.99,70.68]],"ltp":1.83,"tv":869.42,"id":12343905}]}]}
{"op":"mcm","clk":"4231661623","pt":1631546554725,"mc":[{"id":"1.187560634","rc":[{"batb":[[0,1.75,34.31],[1,1.67,1.4],[2,1.4,149.15]],"ltp":1.83,"tv":869.42,"id":12343905}]}]}
{"op":"mcm","clk":"4231661838","pt":1631546556926,"mc":[{"id":"1.187560634","rc":[{"batb":[[0,1.84,93.45],[1,1.82,91.75],[2,1.75,34.31]],"batl":[[0,1.91,76.13],[1,1.93,77.48]],"ltp":1.83,"tv":869.42,"id":12343905}]}]}
{"op":"mcm","clk":"4231662495","pt":1631546563534,"mc":[{"id":"1.187560634","rc":[{"batb":[[0,1.75,34.31],[1,1.67,1.4],[2,1.4,149.15]],"ltp":1.83,"tv":869.42,"id":12343905}]}]}
{"op":"mcm","clk":"4231662927","pt":1631546566572,"mc":[{"id":"1.187560634","rc":[{"batb":[[0,1.8,65.36],[1,1.78,98.57],[2,1.75,34.31]],"batl":[[0,1.97,86.4],[1,1.99,70.68]],"ltp":1.83,"tv":869.42,"id":12343905}]}]}
{"op":"mcm","clk":"4231663031","pt":1631546567665,"mc":[{"id":"1.187560634","rc":[{"batb":[[0,1.75,34.31],[1,1.67,1.4],[2,1.4,149.15]],"ltp":1.83,"tv":869.42,"id":12343905}]}]}
{"op":"mcm","clk":"4231663303","pt":1631546570675,"mc":[{"id":"1.187560634","rc":[{"batb":[[1,1.5,107.38],[2,1.4,149.14]],"batl":[[0,2.12,94.34],[1,2.16,15.81]],"ltp":2.16,"tv":1687.82,"id":9629296},{"batb":[[0,1.9,74.63],[1,1.89,7.9],[2,1.88,90.58]],"batl":[[0,1.92,10.37],[1,1.96,112.84],[2,1.97,86.4]],"ltp":1.83,"tv":869.42,"id":12343905}]}]}
{"op":"mcm","clk":"4231663384","pt":1631546571473,"mc":[{"id":"1.187560634","rc":[{"batb":[[0,1.99,75.38],[1,1.98,37.68],[2,1.97,37.68]],"ltp":2.16,"tv":1687.82,"id":9629296}]}]}
{"op":"mcm","clk":"4231663434","pt":1631546571985,"mc":[{"id":"1.187560634","rc":[{"batb":[[0,1.99,15.08],[1,1.98,7.54],[2,1.97,7.54]],"ltp":2.16,"tv":1687.82,"id":9629296}]}]}
{"op":"mcm","clk":"4231663572","pt":1631546573564,"mc":[{"id":"1.187560634","rc":[{"batl":[[2,3,216.62]],"ltp":2.16,"tv":1687.82,"id":9629296}]}]}
{"op":"mcm","clk":"4231666123","pt":1631546601632,"mc":[{"id":"1.187560634","rc":[{"batb":[[0,1.81,30.78],[1,1.77,408.24],[2,1.5,107.38]],"batl":[[0,3,216.62],[1,2.16,0],[2,3,0]],"ltp":2.16,"tv":1687.82,"id":9629296},{"batb":[[0,1.76,33.3],[1,1.67,1.4],[2,1.4,149.15]],"ltp":1.83,"tv":869.42,"id":12343905}]}]}
{"op":"mcm","clk":"4231666387","pt":1631546604418,"mc":[{"id":"1.187560634","rc":[{"batb":[[2,1.4,149.14]],"batl":[[0,1.94,2.48],[1,3,216.62]],"ltp":2.16,"tv":1687.82,"id":9629296},{"batb":[[0,1.81,77.63],[1,1.79,96.81],[2,1.76,33.3]],"batl":[[0,2.14,76.8],[1,2.16,55.79]],"ltp":1.83,"tv":869.42,"id":12343905}]}]}
{"op":"mcm","clk":"4231666468","pt":1631546605314,"mc":[{"id":"1.187560634","rc":[{"trd":[[1.94,0.64]],"batl":[[0,1.94,2.4]],"ltp":1.94,"tv":1687.9,"id":9629296},{"trd":[[2.06,0.61]],"batb":[[0,1.76,33.3],[1,1.67,1.4],[2,1.4,149.15]],"ltp":2.06,"tv":869.5,"id":12343905}],"tv":2557.41}]}
{"op":"mcm","clk":"4231666623","pt":1631546607243,"mc":[{"id":"1.187560634","rc":[{"batb":[[2,1.5,107.39]],"ltp":2.06,"tv":869.5,"id":12343905}]}]}
{"op":"mcm","clk":"4231666725","pt":1631546608445,"mc":[{"id":"1.187560634","rc":[{"trd":[[1.94,5.52]],"batl":[[0,3,216.62],[1,810,0.07]],"ltp":1.94,"tv":1692.78,"id":9629296},{"trd":[[2.06,5.21]],"batb":[[0,1.93,56.98],[1,1.91,78.69],[2,1.76,33.3]],"batl":[[0,2,73.45],[1,2.02,67.64]],"ltp":2.06,"tv":874.1,"id":12343905}],"tv":2566.89}]}
{"op":"mcm","clk":"4231666996","pt":1631546611543,"mc":[{"id":"1.187560634","rc":[{"batb":[[2,1.5,107.39]],"ltp":1.94,"tv":1692.78,"id":9629296}]}]}
{"op":"mcm","clk":"4231667195","pt":1631546613912,"mc":[{"id":"1.187560634","rc":[{"batb":[[0,1.76,33.3],[1,1.67,1.4],[2,1.5,107.39]],"ltp":2.06,"tv":874.1,"id":12343905}]}]}
{"op":"mcm","clk":"4231667488","pt":1631546617631,"mc":[{"id":"1.187560634","rc":[{"batb":[[0,1.81,80.52],[1,1.79,96.82],[2,1.76,33.3]],"batl":[[0,2.14,74.35],[1,2.16,55.79]],"ltp":2.06,"tv":874.1,"id":12343905}]}]}
{"op":"mcm","clk":"4231667516","pt":1631546618038,"mc":[{"id":"1.187560634","rc":[{"batb":[[0,1.76,33.3],[1,1.67,1.4],[2,1.5,107.39]],"ltp":2.06,"tv":874.1,"id":12343905}]}]}
{"op":"mcm","clk":"4231667658","pt":1631546619622,"mc":[{"id":"1.187560634","rc":[{"batl":[[0,810,0.07],[1,810,0]],"ltp":1.94,"tv":1692.78,"id":9629296}]}]}
{"op":"mcm","clk":"4231667782","pt":1631546621133,"mc":[{"id":"1.187560634","rc":[{"batb":[[0,1.88,72.86],[1,1.86,85.65],[2,1.81,30.78]],"batl":[[0,1.95,80.55],[1,1.97,72.99],[2,1.98,57.73]],"ltp":1.94,"tv":1692.78,"id":9629296},{"batb":[[0,2.04,58.82],[1,1.76,33.3],[2,1.67,1.4]],"batl":[[0,2.08,10.87],[1,2.16,155.95]],"ltp":2.06,"tv":874.1,"id":12343905}]}]}
{"op":"mcm","clk":"4231667882","pt":1631546622138,"mc":[{"id":"1.187560634","rc":[{"batb":[[0,1.88,88.82],[1,1.87,7.98],[2,1.86,93.63]],"ltp":1.94,"tv":1692.78,"id":9629296},{"batb":[[1,1.98,45.8],[2,1.87,27.43]],"ltp":2.06,"tv":874.1,"id":12343905}]}]}
{"op":"mcm","clk":"4231668242","pt":1631546626053,"mc":[{"id":"1.187560634","rc":[{"trd":[[1.92,12.78]],"ltp":1.92,"tv":1700.73,"id":9629296},{"trd":[[2.08,15.48]],"batl":[[0,2.08,3.53]],"ltp":2.08,"tv":881.44,"id":12343905}],"tv":2582.18}]}
{"op":"mcm","clk":"4231668719","pt":1631546631612,"mc":[{"id":"1.187560634","rc":[{"trd":[[1.95,1.7]],"batl":[[0,1.95,79.7]],"ltp":1.95,"tv":1702.44,"id":9629296},{"trd":[[2.04,6.82]],"batb":[[0,2.04,55.41]],"ltp":2.04,"tv":888.26,"id":12343905}],"tv":2590.7}]}
{"op":"mcm","clk":"4231668890","pt":1631546633403,"mc":[{"id":"1.187560634","rc":[{"trd":[[1.95,103.7]],"batb":[[0,1.88,15.96],[2,1.86,7.98]],"batl":[[0,1.98,57.73],[1,1.99,22.73],[2,2,22.73]],"ltp":1.95,"tv":1804.44,"id":9629296}],"tv":2692.7}]}
{"op":"mcm","clk":"4231669161","pt":1631546636309,"mc":[{"id":"1.187560634","rc":[{"batb":[[0,1.89,60.68],[1,1.88,15.96],[2,1.87,92.15]],"batl":[[0,1.96,88.51],[1,1.98,117.33],[2,1.99,22.73]],"ltp":1.95,"tv":1804.44,"id":9629296},{"batl":[[0,2.16,155.95],[1,2.16,0]],"ltp":2.04,"tv":888.26,"id":12343905}]}]}
{"op":"mcm","clk":"4231669283","pt":1631546637714,"mc":[{"id":"1.187560634","rc":[{"batb":[[0,1.95,235.29],[1,1.89,60.68],[2,1.88,15.96]],"ltp":1.95,"tv":1804.44,"id":9629296}]}]}
{"op":"mcm","clk":"4231669384","pt":1631546639011,"mc":[{"id":"1.187560634","rc":[{"batl":[[0,1.96,100.02]],"ltp":1.95,"tv":1804.44,"id":9629296},{"batl":[[0,2.12,17.68],[1,2.16,155.95]],"ltp":2.04,"tv":888.26,"id":12343905}]}]}
{"op":"mcm","clk":"4231670186","pt":1631546648337,"mc":[{"id":"1.187560634","rc":[{"batb":[[1,1.77,408.24],[2,1.67,40.68]],"batl":[[0,2.72,245.13],[1,810,0.07],[2,1.99,0]],"ltp":1.95,"tv":1804.44,"id":9629296},{"batb":[[0,1.87,27.43],[1,1.67,1.4],[2,1.5,107.39]],"ltp":2.04,"tv":888.26,"id":12343905}]}]}
{"op":"mcm","clk":"4231670363","pt":1631546650333,"mc":[{"id":"1.187560634","rc":[{"trd":[[1.95,155.08]],"batb":[[0,1.95,209.6]],"ltp":1.95,"tv":1855.82,"id":9629296}],"tv":2744.08}]}
{"op":"mcm","clk":"4231670419","pt":1631546651114,"mc":[{"id":"1.187560634","rc":[{"batb":[[2,1.73,64.19]],"batl":[[0,2.08,55.19],[1,2.1,60.41],[2,2.72,245.13]],"ltp":1.95,"tv":1855.82,"id":9629296}]}]}
{"op":"mcm","clk":"4231670633","pt":1631546654350,"mc":[{"id":"1.187560634","rc":[{"batb":[[2,1.67,40.68]],"batl":[[0,2.72,245.13],[1,810,0.07],[2,2.72,0]],"ltp":1.95,"tv":1855.82,"id":9629296}]}]}
{"op":"mcm","clk":"4231670840","pt":1631546657436,"mc":[{"id":"1.187560634","rc":[{"batl":[[0,2.08,10.89],[1,2.16,137.78],[2,2.72,245.13]],"ltp":1.95,"tv":1855.82,"id":9629296},{"batb":[[0,1.92,82.91],[1,1.9,80.01],[2,1.87,27.43]],"batl":[[0,1.97,45.68],[1,1.98,35.2],[2,1.99,79.25]],"ltp":2.04,"tv":888.26,"id":12343905}]}]}
{"op":"mcm","clk":"4231670929","pt":1631546658642,"mc":[{"id":"1.187560634","rc":[{"batb":[[1,1.91,51.59],[2,1.77,441.87]],"ltp":1.95,"tv":1855.82,"id":9629296},{"batb":[[2,1.87,43.47]],"ltp":2.04,"tv":888.26,"id":12343905}]}]}
{"op":"mcm","clk":"4231672224","pt":1631546675571,"mc":[{"id":"1.187560634","rc":[{"batb":[[1,1.77,441.87],[2,1.4,149.14]],"batl":[[0,2.72,245.13],[1,810,0.07],[2,2.72,0]],"ltp":1.95,"tv":1855.82,"id":9629296},{"batb":[[0,1.77,32.63],[1,1.67,1.4],[2,1.5,107.39]],"ltp":2.04,"tv":888.26,"id":12343905}]}]}
{"op":"mcm","clk":"4231672452","pt":1631546678647,"mc":[{"id":"1.187560634","rc":[{"batb":[[2,1.5,107.39]],"ltp":1.95,"tv":1855.82,"id":9629296}]}]}
{"op":"mcm","clk":"4231672650","pt":1631546681154,"mc":[{"id":"1.187560634","rc":[{"batb":[[0,1.96,65.32],[1,1.94,75],[2,1.77,32.63]],"batl":[[0,2.04,93.06],[1,2.06,63.88]],"ltp":2.04,"tv":888.26,"id":12343905}]}]}
{"op":"mcm","clk":"4231673169","pt":1631546688596,"mc":[{"id":"1.187560634","rc":[{"batb":[[0,2.04,51],[1,1.95,209.6],[2,1.77,441.87]],"ltp":1.95,"tv":1855.82,"id":9629296},{"batb":[[0,1.77,32.63],[1,1.67,1.4],[2,1.4,149.15]],"ltp":2.04,"tv":888.26,"id":12343905}]}]}
{"op":"mcm","clk":"4231673351","pt":1631546691096,"mc":[{"id":"1.187560634","rc":[{"batb":[[0,1.95,209.6],[1,1.77,441.87],[2,1.5,107.39]],"ltp":1.95,"tv":1855.82,"id":9629296},{"batb":[[0,1.82,69.33],[1,1.8,95.07],[2,1.77,32.63]],"batl":[[0,2.2,57.69],[1,2.22,51.64]],"ltp":2.04,"tv":888.26,"id":12343905}]}]}
{"op":"mcm","clk":"4231673574","pt":1631546694181,"mc":[{"id":"1.187560634","rc":[{"batb":[[0,2.06,51],[1,1.95,209.6],[2,1.77,441.87]],"ltp":1.95,"tv":1855.82,"id":9629296}]}]}
{"op":"mcm","clk":"4231673766","pt":1631546696792,"mc":[{"id":"1.187560634","rc":[{"batb":[[0,1.95,209.6],[1,1.77,441.87],[2,1.5,107.39]],"ltp":1.95,"tv":1855.82,"id":9629296}]}]}
{"op":"mcm","clk":"4231673864","pt":1631546698773,"mc":[{"id":"1.187560634","rc":[{"trd":[[1.95,175.18]],"batb":[[0,1.95,199.55]],"ltp":1.95,"tv":1875.92,"id":9629296}],"tv":2764.18}]}
{"op":"mcm","clk":"4231673924","pt":1631546699867,"mc":[{"id":"1.187560634","rc":[{"batb":[[0,2,51],[1,1.95,199.55],[2,1.77,441.87]],"ltp":1.95,"tv":1875.92,"id":9629296}]}]}
{"op":"mcm","clk":"4231674099","pt":1631546702600,"mc":[{"id":"1.187560634","rc":[{"batb":[[0,1.95,199.55],[1,1.77,441.87],[2,1.5,107.39]],"ltp":1.95,"tv":1875.92,"id":9629296}]}]}
{"op":"mcm","clk":"4231674329","pt":1631546705701,"mc":[{"id":"1.187560634","rc":[{"batb":[[0,1.98,51],[1,1.95,199.55],[2,1.77,441.87]],"ltp":1.95,"tv":1875.92,"id":9629296}]}]}
{"op":"mcm","clk":"4231675033","pt":1631546713600,"mc":[{"id":"1.187560634","rc":[{"batb":[[0,1.95,199.55],[1,1.77,441.87],[2,1.5,107.39]],"ltp":1.95,"tv":1875.92,"id":9629296}]}]}
{"op":"mcm","clk":"4231675307","pt":1631546716728,"mc":[{"id":"1.187560634","rc":[{"batb":[[0,2,51],[1,1.95,199.55],[2,1.77,441.87]],"ltp":1.95,"tv":1875.92,"id":9629296}]}]}
{"op":"mcm","clk":"4231675486","pt":1631546719035,"mc":[{"id":"1.187560634","rc":[{"batb":[[0,1.95,199.55],[1,1.77,441.87],[2,1.5,107.39]],"ltp":1.95,"tv":1875.92,"id":9629296}]}]}
{"op":"mcm","clk":"4231675738","pt":1631546722313,"mc":[{"id":"1.187560634","rc":[{"batb":[[0,1.98,51],[1,1.95,199.55],[2,1.77,441.87]],"ltp":1.95,"tv":1875.92,"id":9629296},{"batb":[[0,1.77,32.63],[1,1.67,1.4],[2,1.4,149.15]],"ltp":2.04,"tv":888.26,"id":12343905}]}]}
{"op":"mcm","clk":"4231676003","pt":1631546725339,"mc":[{"id":"1.187560634","rc":[{"trd":[[1.95,574.28],[1.98,115.9]],"batb":[[0,1.86,7.61],[1,1.83,84.53],[2,1.81,93.56]],"batl":[[0,1.89,7.5],[1,1.9,89.51],[2,1.92,94.52]],"ltp":1.95,"tv":2377.02,"id":9629296},{"batl":[[0,2.24,147.69]],"ltp":2.04,"tv":888.26,"id":12343905}],"tv":3265.28}]}
{"op":"mcm","clk":"4231676081","pt":1631546726225,"mc":[{"id":"1.187560634","rc":[{"batb":[[2,1.82,16.48]],"ltp":1.95,"tv":2377.02,"id":9629296},{"batb":[[0,2.04,41.69],[1,1.9,26.34],[2,1.67,1.4]],"ltp":2.04,"tv":888.26,"id":12343905}]}]}
{"op":"mcm","clk":"4231676870","pt":1631546736251,"mc":[{"id":"1.187560634","rc":[{"trd":[[1.89,229.96]],"batl":[[0,1.89,2.5]],"ltp":1.89,"tv":2387.02,"id":9629296}],"tv":3275.28}]}
{"op":"mcm","clk":"4231677684","pt":1631546746361,"mc":[{"id":"1.187560634","rc":[{"batb":[[0,1.83,84.53],[1,1.82,16.48],[2,1.81,101.8]],"batl":[[0,1.9,89.51],[1,1.92,94.52],[2,1.93,7.82]],"ltp":1.89,"tv":2387.02,"id":9629296}]}]}
{"op":"mcm","clk":"4231677975","pt":1631546749591,"mc":[{"id":"1.187560634","rc":[{"trd":[[1.81,184.76],[1.82,32.96],[1.83,228.22]],"batb":[[0,1.81,8.24],[1,1.8,8.24],[2,1.77,441.87]],"batl":[[0,1.9,81.62],[1,1.92,32.31]],"ltp":1.81,"tv":2664.31,"id":9629296},{"batl":[[0,2.16,10.01],[1,2.24,147.69]],"ltp":2.04,"tv":888.26,"id":12343905}],"tv":3552.58}]}
{"op":"mcm","clk":"4231678219","pt":1631546752452,"mc":[{"id":"1.187560634","rc":[{"batb":[[0,1.82,63.57],[1,1.81,8.24],[2,1.8,103.59]],"batl":[[0,1.88,73.49],[1,1.9,81.62],[2,1.92,32.31]],"ltp":1.81,"tv":2664.31,"id":9629296}]}]}
{"op":"mcm","clk":"4231678377","pt":1631546754373,"mc":[{"id":"1.187560634","rc":[{"batb":[[0,1.77,441.87],[1,1.61,46.55],[2,1.4,149.14]],"batl":[[0,2.72,245.13],[1,810,0.07],[2,1.92,0]],"ltp":1.81,"tv":2664.31,"id":9629296}]}]}
{"op":"mcm","clk":"4231678400","pt":1631546754685,"mc":[{"id":"1.187560634","rc":[{"batb":[[0,1.77,408.24]],"ltp":1.81,"tv":2664.31,"id":9629296},{"batb":[[0,1.9,26.34],[1,1.67,1.4],[2,1.5,107.39]],"ltp":2.04,"tv":888.26,"id":12343905}]}]}
{"op":"mcm","clk":"4231678644","pt":1631546757287,"mc":[{"id":"1.187560634","rc":[{"batb":[[1,1.64,100.11],[2,1.63,67.72]],"batl":[[0,2.04,111.61],[1,2.06,63.96],[2,2.72,245.13]],"ltp":1.81,"tv":2664.31,"id":9629296}]}]}
{"op":"mcm","clk":"4231679098","pt":1631546762187,"mc":[{"id":"1.187560634","rc":[{"batl":[[0,2.72,245.13],[1,810,0.07],[2,2.72,0]],"ltp":1.81,"tv":2664.31,"id":9629296}]}]}
{"op":"mcm","clk":"4231679249","pt":1631546764210,"mc":[{"id":"1.187560634","rc":[{"batb":[[0,1.64,100.11],[1,1.63,67.72],[2,1.61,46.55]],"batl":[[0,810,0.07],[1,810,0]],"ltp":1.81,"tv":2664.31,"id":9629296}]}]}
{"op":"mcm","clk":"4231679318","pt":1631546765202,"mc":[{"id":"1.187560634","rc":[{"batb":[[0,1.68,11.28],[1,1.64,100.11],[2,1.63,67.72]],"batl":[[0,1.69,72.94],[1,1.71,114.93],[2,1.72,23.26]],"ltp":1.81,"tv":2664.31,"id":9629296},{"batb":[[0,2.4,8.89],[1,1.9,26.34],[2,1.67,1.4]],"batl":[[0,2.56,97.34]],"ltp":2.04,"tv":888.26,"id":12343905}]}]}
{"op":"mcm","clk":"4231679424","pt":1631546766402,"mc":[{"id":"1.187560634","rc":[{"batb":[[1,2.3,29.19],[2,2.12,36.91]],"batl":[[0,2.52,11.9],[1,2.54,5.96],[2,2.56,103.3]],"ltp":2.04,"tv":888.26,"id":12343905}]}]}
{"op":"mcm","clk":"4231679936","pt":1631546772913,"mc":[{"id":"1.187560634","rc":[{"trd":[[1.68,0.16]],"batb":[[0,1.68,11.2]],"ltp":1.68,"tv":2664.47,"id":9629296}],"tv":3552.74}]}
{"op":"mcm","clk":"4231680729","pt":1631546783115,"mc":[{"id":"1.187560634","rc":[{"batb":[[0,1.64,100.11],[1,1.63,67.72],[2,1.61,46.55]],"ltp":1.68,"tv":2664.47,"id":9629296},{"batb":[[0,2.3,29.19],[1,2.12,36.91],[2,1.67,1.4]],"ltp":2.04,"tv":888.26,"id":12343905}]}]}
{"op":"mcm","clk":"4231680966","pt":1631546786223,"mc":[{"id":"1.187560634","rc":[{"batb":[[0,1.55,426.74],[1,1.48,63.75],[2,1.3,198.84]],"batl":[[0,2.42,290.77],[1,810,0.07],[2,1.72,0]],"ltp":1.68,"tv":2664.47,"id":9629296},{"batb":[[0,2.12,36.91],[1,1.67,1.4],[2,1.5,107.39]],"ltp":2.04,"tv":888.26,"id":12343905}]}]}
{"op":"mcm","clk":"4231681191","pt":1631546788616,"mc":[{"id":"1.187560634","rc":[{"batb":[[0,1.48,63.75],[1,1.3,198.84],[2,1.25,28.88]],"batl":[[0,810,0.07],[1,810,0]],"ltp":1.68,"tv":2664.47,"id":9629296}]}]}
{"op":"mcm","clk":"4231681248","pt":1631546789299,"mc":[{"id":"1.187560634","rc":[{"batb":[[2,1.6,99.43]],"ltp":2.04,"tv":888.26,"id":12343905}]}]}
{"op":"mcm","clk":"4231681315","pt":1631546790239,"mc":[{"id":"1.187560634","rc":[{"batl":[[0,1.95,7.27],[1,810,0.07]],"ltp":1.68,"tv":2664.47,"id":9629296}]}]}
{"op":"mcm","clk":"4231681397","pt":1631546791127,"mc":[{"id":"1.187560634","rc":[{"batb":[[0,1.61,111.1],[1,1.6,72.56],[2,1.48,63.75]],"batl":[[0,1.66,80.5],[1,1.68,122.09],[2,1.95,7.27]],"ltp":1.68,"tv":2664.47,"id":9629296}]}]}
{"op":"mcm","clk":"4231681653","pt":1631546794148,"mc":[{"id":"1.187560634","rc":[{"batb":[[1,1.7,17.05],[2,1.67,1.4]],"ltp":2.04,"tv":888.26,"id":12343905}]}]}
{"op":"mcm","clk":"4231681914","pt":1631546797637,"mc":[{"id":"1.187560634","rc":[{"batb":[[0,1.48,63.75],[1,1.3,198.84],[2,1.25,28.88]],"batl":[[0,1.95,7.27],[1,810,0.07],[2,1.95,0]],"ltp":1.68,"tv":2664.47,"id":9629296}]}]}
{"op":"mcm","clk":"4231682154","pt":1631546800563,"mc":[{"id":"1.187560634","rc":[{"batb":[[0,1.51,74.03],[1,1.5,93.08],[2,1.48,63.75]],"batl":[[0,1.81,99.29],[1,1.83,91.81],[2,1.95,7.27]],"ltp":1.68,"tv":2664.47,"id":9629296}]}]}
{"op":"mcm","clk":"4231682288","pt":1631546802143,"mc":[{"id":"1.187560634","rc":[{"batb":[[0,1.48,63.75],[1,1.3,198.84],[2,1.25,28.88]],"ltp":1.68,"tv":2664.47,"id":9629296}]}]}
{"op":"mcm","clk":"4231682553","pt":1631546805275,"mc":[{"id":"1.187560634","rc":[{"batb":[[0,1.75,67.62],[1,1.74,51.72],[2,1.73,134.81]],"batl":[[1,1.83,104.44],[2,1.89,176.55]],"ltp":1.68,"tv":2664.47,"id":9629296},{"batb":[[1,1.67,1.4],[2,1.6,99.43]],"batl":[[0,2.28,11.71],[1,2.38,50.42],[2,2.5,339.9]],"ltp":2.04,"tv":888.26,"id":12343905}]}]}
{"op":"mcm","clk":"4231682611","pt":1631546806260,"mc":[{"id":"1.187560634","rc":[{"batb":[[1,1.74,17.24],[2,1.73,117.57]],"ltp":1.68,"tv":2664.47,"id":9629296},{"batb":[[0,2.22,13.52],[1,2.2,6.76],[2,2.18,6.76]],"ltp":2.04,"tv":888.26,"id":12343905}]}]}
{"op":"mcm","clk":"4231683107","pt":1631546812175,"mc":[{"id":"1.187560634","rc":[{"trd":[[1.81,284.05],[1.83,243.71]],"batl":[[0,1.83,88.95],[1,1.89,176.55],[2,1.95,7.27]],"ltp":1.83,"tv":2779.25,"id":9629296},{"trd":[[2.2,43.63],[2.22,107.99]],"batb":[[0,2.18,6.76],[1,2.12,36.91],[2,1.91,51.5]],"ltp":2.2,"tv":1022.66,"id":12343905}],"tv":3801.92}]}
{"op":"mcm","clk":"4231683167","pt":1631546812806,"mc":[{"id":"1.187560634","rc":[{"batb":[[0,1.74,17.24],[1,1.73,8.62],[2,1.72,8.62]],"batl":[[0,1.83,12.63]],"ltp":1.83,"tv":2779.25,"id":9629296}]}]}
{"op":"mcm","clk":"4231683461","pt":1631546816495,"mc":[{"id":"1.187560634","rc":[{"trd":[[1.78,10.83]],"batb":[[0,1.76,80.31],[1,1.74,123.94],[2,1.73,8.62]],"batl":[[0,1.82,82.04],[1,1.83,12.63],[2,1.84,90.11]],"ltp":1.78,"tv":2790.08,"id":9629296},{"trd":[[2.28,8.45]],"batl":[[0,2.28,3.26]],"ltp":2.28,"tv":1031.11,"id":12343905}],"tv":3821.2}]}
{"op":"mcm","clk":"4231684149","pt":1631546824399,"mc":[{"id":"1.187560634","rc":[{"trd":[[1.82,197.04]],"batb":[[0,1.82,37.96],[1,1.74,17.24]],"batl":[[0,1.83,12.63],[1,1.89,176.55],[2,1.95,7.27]],"ltp":1.82,"tv":2954.16,"id":9629296}],"tv":3985.28}]}
{"op":"mcm","clk":"4231684366","pt":1631546827393,"mc":[{"id":"1.187560634","rc":[{"batb":[[1,1.77,75.23],[2,1.75,104.53]],"batl":[[0,1.83,82.11],[1,1.85,88.47],[2,1.89,176.55]],"ltp":1.82,"tv":2954.16,"id":9629296},{"batl":[[0,2.38,50.42],[1,2.5,339.9],[2,2.5,0]],"ltp":2.28,"tv":1031.11,"id":12343905}]}]}
{"op":"mcm","clk":"4231684408","pt":1631546827913,"mc":[{"id":"1.187560634","rc":[{"batb":[[0,1.77,75.23],[1,1.75,104.53],[2,1.74,17.24]],"ltp":1.82,"tv":2954.16,"id":9629296}]}]}
{"op":"mcm","clk":"4231684531","pt":1631546829597,"mc":[{"id":"1.187560634","rc":[{"batb":[[1,1.76,17.2],[2,1.75,104.53]],"ltp":1.82,"tv":2954.16,"id":9629296},{"batb":[[0,2.24,8.37],[1,2.18,6.76],[2,2.12,36.91]],"ltp":2.28,"tv":1031.11,"id":12343905}]}]}
{"op":"mcm","clk":"4231684818","pt":1631546833525,"mc":[{"id":"1.187560634","rc":[{"batb":[[0,1.51,59.39],[1,1.3,198.84],[2,1.25,28.88]],"batl":[[0,1.95,7.27],[1,810,0.07],[2,1.89,0]],"ltp":1.82,"tv":2954.16,"id":9629296},{"batb":[[0,1.91,51.5],[1,1.67,1.4],[2,1.6,99.43]],"ltp":2.28,"tv":1031.11,"id":12343905}]}]}
{"op":"mcm","clk":"4231685069","pt":1631546836511,"mc":[{"id":"1.187560634","rc":[{"batl":[[1,2.04,75.7],[2,2.06,63.87]],"ltp":1.82,"tv":2954.16,"id":9629296}]}]}
{"op":"mcm","clk":"4231685279","pt":1631546839195,"mc":[{"id":"1.187560634","rc":[{"trd":[[1.95,581.56]],"batb":[[0,1.96,90.22],[1,1.94,178.05],[2,1.91,15.7]],"batl":[[0,2,5.06]],"ltp":1.95,"tv":2961.44,"id":9629296},{"trd":[[2.04,13.77]],"batb":[[0,2,5.06],[1,1.91,51.5],[2,1.67,1.4]],"ltp":2.04,"tv":1038.06,"id":12343905}],"tv":3999.5}]}
{"op":"mcm","clk":"4231685365","pt":1631546840238,"mc":[{"id":"1.187560634","rc":[{"batl":[[1,2.02,14.86],[2,2.04,83.12]],"ltp":1.95,"tv":2961.44,"id":9629296},{"batb":[[2,1.78,32.13]],"ltp":2.04,"tv":1038.06,"id":12343905}]}]}
{"op":"mcm","clk":"4231685975","pt":1631546847621,"mc":[{"id":"1.187560634","rc":[{"batl":[[0,2.9,8.96]],"ltp":2.04,"tv":1038.06,"id":12343905}]}]}
{"op":"mcm","clk":"4231686631","pt":1631546855658,"mc":[{"id":"1.187560634","rc":[{"trd":[[2,14.41],[2.02,35.36],[2.04,11.06]],"batb":[[0,1.96,6.96],[1,1.94,103.1]],"batl":[[0,2.04,7.42],[1,2.06,7.42],[2,2.08,100.94]],"ltp":2.04,"tv":2991.75,"id":9629296},{"trd":[[1.96,11.51],[1.98,36.08],[2,303.01]],"batb":[[0,1.91,51.5],[1,1.78,32.13],[2,1.67,1.4]],"ltp":1.96,"tv":1079.22,"id":12343905}],"tv":4070.97}]}
{"op":"mcm","clk":"4231686857","pt":1631546858561,"mc":[{"id":"1.187560634","rc":[{"batb":[[0,1.96,78.46],[1,1.94,74.97],[2,1.91,51.5]],"batl":[[0,2.04,80.32],[1,2.06,63.86],[2,2.9,8.96]],"ltp":1.96,"tv":1079.22,"id":12343905}]}]}
{"op":"mcm","clk":"4231686874","pt":1631546858768,"mc":[{"id":"1.187560634","rc":[{"batl":[[2,2.9,0]],"ltp":1.96,"tv":1079.22,"id":12343905}]}]}
{"op":"mcm","clk":"4231687327","pt":1631546864539,"mc":[{"id":"1.187560634","rc":[{"batb":[[0,1.88,27.43],[1,1.69,38.67],[2,1.4,149.15]],"batl":[[0,810,0.07],[1,2.06,0],[2,2.08,0]],"ltp":2.04,"tv":2991.75,"id":9629296}]}]}
{"op":"mcm","clk":"4231687354","pt":1631546864860,"mc":[{"id":"1.187560634","rc":[{"batb":[[0,1.69,38.67],[1,1.4,149.15],[2,1.3,198.84]],"ltp":2.04,"tv":2991.75,"id":9629296},{"batb":[[0,1.78,32.13],[1,1.67,1.4],[2,1.5,107.39]],"ltp":1.96,"tv":1079.22,"id":12343905}]}]}
{"op":"mcm","clk":"4231687591","pt":1631546867674,"mc":[{"id":"1.187560634","rc":[{"batb":[[0,1.82,89.31],[1,1.8,95.12],[2,1.78,32.13]],"batl":[[0,2.32,53.97],[1,2.34,44.64]],"ltp":1.96,"tv":1079.22,"id":12343905}]}]}
{"op":"mcm","clk":"4231687803","pt":1631546870493,"mc":[{"id":"1.187560634","rc":[{"batb":[[0,2.1,166.68],[1,2.08,35.72],[2,2.06,35.72]],"batl":[[0,2.2,15.5],[1,2.24,99.8],[2,810,0.07]],"ltp":2.04,"tv":2991.75,"id":9629296},{"batl":[[0,1.89,10.96],[1,1.93,1565.04],[2,2.02,7.1]],"ltp":1.96,"tv":1079.22,"id":12343905}]}]}
{"op":"mcm","clk":"4231687906","pt":1631546871594,"mc":[{"id":"1.187560634","rc":[{"batb":[[0,2.1,109.52],[1,2.08,7.14],[2,2.06,7.14]],"ltp":2.04,"tv":2991.75,"id":9629296},{"batb":[[1,1.81,82.88],[2,1.8,136.56]],"batl":[[0,1.89,99.7],[1,1.91,79.99],[2,2.04,388.36]],"ltp":1.96,"tv":1079.22,"id":12343905}]}]}
{"op":"mcm","clk":"4231687924","pt":1631546871894,"mc":[{"id":"1.187560634","rc":[{"batb":[[1,1.81,16.58],[2,1.8,103.4]],"ltp":1.96,"tv":1079.22,"id":12343905}]}]}
{"op":"mcm","clk":"4231689482","pt":1631546891603,"mc":[{"id":"1.187560634","rc":[{"batb":[[0,2.02,43.79],[1,1.87,28.02],[2,1.4,149.15]],"batl":[[0,810,0.07],[1,2.24,0],[2,810,0]],"ltp":2.04,"tv":2991.75,"id":9629296},{"batb":[[0,1.78,32.13],[1,1.7,37.66],[2,1.67,1.4]],"ltp":1.96,"tv":1079.22,"id":12343905}]}]}
{"op":"mcm","clk":"4231689499","pt":1631546891809,"mc":[{"id":"1.187560634","rc":[{"batb":[[0,1.87,28.02],[1,1.4,149.15],[2,1.3,198.84]],"ltp":2.04,"tv":2991.75,"id":9629296},{"batb":[[0,1.7,37.66],[1,1.67,1.4],[2,1.4,149.15]],"ltp":1.96,"tv":1079.22,"id":12343905}]}]}
{"op":"mcm","clk":"4231689754","pt":1631546894522,"mc":[{"id":"1.187560634","rc":[{"batb":[[0,1.73,108.42],[1,1.71,113.03],[2,1.7,37.66]],"batl":[[0,2.06,74.26],[1,2.08,62.1]],"ltp":1.96,"tv":1079.22,"id":12343905}]}]}
{"op":"mcm","clk":"4231689778","pt":1631546894932,"mc":[{"id":"1.187560634","rc":[{"batb":[[1,1.5,107.39],[2,1.4,149.15]],"ltp":2.04,"tv":2991.75,"id":9629296},{"batb":[[0,1.7,37.66],[1,1.67,1.4],[2,1.4,149.15]],"ltp":1.96,"tv":1079.22,"id":12343905}]}]}
{"op":"mcm","clk":"4231689888","pt":1631546896442,"mc":[{"id":"1.187560634","rc":[{"batb":[[0,1.85,86.16],[1,1.83,90.14],[2,1.7,37.66]],"batl":[[0,1.92,79.05],[1,1.94,76.3]],"ltp":1.96,"tv":1079.22,"id":12343905}]}]}
{"op":"mcm","clk":"4231690362","pt":1631546903463,"mc":[{"id":"1.187560634","rc":[{"batb":[[0,1.7,37.66],[1,1.67,1.4],[2,1.4,149.15]],"ltp":1.96,"tv":1079.22,"id":12343905}]}]}
{"op":"mcm","clk":"4231690569","pt":1631546906544,"mc":[{"id":"1.187560634","rc":[{"batb":[[0,1.73,108.42],[1,1.71,113.03],[2,1.7,37.66]],"batl":[[0,2.06,74.26],[1,2.08,62.1]],"ltp":1.96,"tv":1079.22,"id":12343905}]}]}
{"op":"mcm","clk":"4231690806","pt":1631546910345,"mc":[{"id":"1.187560634","rc":[{"batb":[[0,1.7,37.66],[1,1.67,1.4],[2,1.4,149.15]],"ltp":1.96,"tv":1079.22,"id":12343905}]}]}
{"op":"mcm","clk":"4231691007","pt":1631546913346,"mc":[{"id":"1.187560634","rc":[{"batb":[[0,1.95,53.74],[1,1.93,76.16],[2,1.87,28.02]],"batl":[[0,2,104.63],[1,2.02,74.79],[2,2.04,65.72]],"ltp":2.04,"tv":2991.75,"id":9629296},{"batb":[[0,2,4.63],[1,1.97,15.22],[2,1.96,7.62]],"batl":[[0,2.04,6.86],[1,2.12,153.82]],"ltp":1.96,"tv":1079.22,"id":12343905}]}]}
{"op":"mcm","clk":"4231691073","pt":1631546914372,"mc":[{"id":"1.187560634","rc":[{"batb":[[2,1.92,15.62]],"ltp":2.04,"tv":2991.75,"id":9629296}]}]}
{"op":"mcm","clk":"4231692599","pt":1631546937615,"mc":[{"id":"1.187560634","rc":[{"batb":[[2,1.87,28.02]],"batl":[[0,2.02,74.79],[1,2.04,65.72],[2,2.04,0]],"ltp":2.04,"tv":2991.75,"id":9629296},{"batb":[[0,1.92,50.33],[1,1.8,31.45],[2,1.67,1.4]],"ltp":1.96,"tv":1079.22,"id":12343905}]}]}
{"op":"mcm","clk":"4231692621","pt":1631546937787,"mc":[{"id":"1.187560634","rc":[{"batb":[[0,1.69,39.26],[1,1.5,107.39],[2,1.4,149.15]],"ltp":2.04,"tv":2991.75,"id":9629296},{"batb":[[0,1.8,31.45],[1,1.67,1.4],[2,1.5,107.39]],"ltp":1.96,"tv":1079.22,"id":12343905}]}]}
{"op":"mcm","clk":"4231692796","pt":1631546940581,"mc":[{"id":"1.187560634","rc":[{"batb":[[0,1.74,85.62],[1,1.72,110.88],[2,1.69,39.26]],"batl":[[0,2.2,84.15],[1,2.22,51.59]],"ltp":2.04,"tv":2991.75,"id":9629296}]}]}
{"op":"mcm","clk":"4231692812","pt":1631546940787,"mc":[{"id":"1.187560634","rc":[{"batb":[[0,1.69,39.26],[1,1.5,107.39],[2,1.4,149.15]],"ltp":2.04,"tv":2991.75,"id":9629296}]}]}
{"op":"mcm","clk":"4231692933","pt":1631546942499,"mc":[{"id":"1.187560634","rc":[{"batl":[[0,2.04,250.96]],"ltp":2.04,"tv":2991.75,"id":9629296}]}]}
{"op":"mcm","clk":"4231692962","pt":1631546942812,"mc":[{"id":"1.187560634","rc":[{"batb":[[0,1.9,75.6],[1,1.88,82.71],[2,1.69,39.26]],"batl":[[0,1.97,70.36],[1,1.99,70.73]],"ltp":2.04,"tv":2991.75,"id":9629296}]}]}
{"op":"mcm","clk":"4231693046","pt":1631546944215,"mc":[{"id":"1.187560634","rc":[{"batl":[[2,2.72,245.13]],"ltp":2.04,"tv":2991.75,"id":9629296}]}]}
{"op":"mcm","clk":"4231693403","pt":1631546949930,"mc":[{"id":"1.187560634","rc":[{"batb":[[0,1.69,39.26],[1,1.67,415.84],[2,1.5,107.39]],"batl":[[0,2.72,245.13],[1,1.99,0],[2,2.72,0]],"ltp":2.04,"tv":2991.75,"id":9629296}]}]}
{"op":"mcm","clk":"4231693640","pt":1631546952826,"mc":[{"id":"1.187560634","rc":[{"batb":[[0,1.74,85.62],[1,1.72,110.88],[2,1.69,39.26]],"batl":[[0,2.2,84.15],[1,2.22,51.59],[2,2.72,245.13]],"ltp":2.04,"tv":2991.75,"id":9629296}]}]}
{"op":"mcm","clk":"4231694116","pt":1631546959901,"mc":[{"id":"1.187560634","rc":[{"batl":[[2,2.72,0]],"ltp":2.04,"tv":2991.75,"id":9629296}]}]}
{"op":"mcm","clk":"4231694501","pt":1631546965351,"mc":[{"id":"1.187560634","rc":[{"batb":[[0,1.69,39.26],[1,1.5,107.39],[2,1.4,149.15]],"ltp":2.04,"tv":2991.75,"id":9629296}]}]}
{"op":"mcm","clk":"4231694731","pt":1631546968516,"mc":[{"id":"1.187560634","rc":[{"batb":[[0,2.08,14.42],[1,2.06,96.32],[2,2.04,7.22]],"batl":[[0,2.16,11.29]],"ltp":2.04,"tv":2991.75,"id":9629296},{"batb":[[0,1.84,70.63],[1,1.83,103.88],[2,1.82,91.71]],"batl":[[0,1.88,106.38],[1,1.9,58.52],[2,1.92,94.26]],"ltp":1.96,"tv":1079.22,"id":12343905}]}]}
{"op":"mcm","clk":"4231694810","pt":1631546969501,"mc":[{"id":"1.187560634","rc":[{"batl":[[1,2.2,13.64],[2,2.22,6.82]],"ltp":2.04,"tv":2991.75,"id":9629296}]}]}
{"op":"mcm","clk":"4231695079","pt":1631546973447,"mc":[{"id":"1.187560634","rc":[{"trd":[[2.12,23.38]],"ltp":2.12,"tv":2995.62,"id":9629296},{"trd":[[1.88,4.36]],"batl":[[0,1.88,102.02]],"ltp":1.88,"tv":1083.58,"id":12343905}],"tv":4079.2}]}
{"op":"mcm","clk":"4231695295","pt":1631546976518,"mc":[{"id":"1.187560634","rc":[{"trd":[[1.88,124.36]],"batl":[[0,1.88,42.02]],"ltp":1.88,"tv":1203.58,"id":12343905}],"tv":4199.2}]}
{"op":"mcm","clk":"4231695354","pt":1631546977451,"mc":[{"id":"1.187560634","rc":[{"trd":[[1.88,124.52]],"batl":[[0,1.88,41.94]],"ltp":1.88,"tv":1203.74,"id":12343905}],"tv":4199.36}]}
{"op":"mcm","clk":"4231695766","pt":1631546983741,"mc":[{"id":"1.187560634","rc":[{"trd":[[1.88,148.52]],"batl":[[0,1.88,29.94]],"ltp":1.88,"tv":1227.74,"id":12343905}],"tv":4223.36}]}
{"op":"mcm","clk":"4231696239","pt":1631546990273,"mc":[{"id":"1.187560634","rc":[{"trd":[[1.88,160.52]],"batl":[[0,1.88,23.94]],"ltp":1.88,"tv":1239.74,"id":12343905}],"tv":4235.36}]}
{"op":"mcm","clk":"4231696292","pt":1631546990962,"mc":[{"id":"1.187560634","rc":[{"batb":[[0,1.86,28.52],[1,1.5,107.39],[2,1.4,149.15]],"ltp":2.12,"tv":2995.62,"id":9629296},{"batb":[[0,1.71,37.07],[1,1.67,1.4],[2,1.4,149.15]],"ltp":1.88,"tv":1239.74,"id":12343905}]}]}
{"op":"mcm","clk":"4231696532","pt":1631546993952,"mc":[{"id":"1.187560634","rc":[{"batb":[[0,1.75,70.67],[1,1.73,108.49],[2,1.71,37.07]],"batl":[[0,2.08,69.32],[1,2.1,60.4]],"ltp":1.88,"tv":1239.74,"id":12343905}]}]}
{"op":"mcm","clk":"4231696944","pt":1631547001094,"mc":[{"id":"1.187560634","rc":[{"batb":[[0,1.71,37.07],[1,1.67,1.4],[2,1.4,149.15]],"ltp":1.88,"tv":1239.74,"id":12343905}]}]}
{"op":"mcm","clk":"4231697209","pt":1631547004292,"mc":[{"id":"1.187560634","rc":[{"batb":[[0,1.94,7.24],[1,1.93,58.99],[2,1.91,78.68]],"batl":[[0,1.98,10.34],[1,1.99,60.3],[2,2,76.12]],"ltp":2.12,"tv":2995.62,"id":9629296},{"batl":[[0,2.12,99.63]],"ltp":1.88,"tv":1239.74,"id":12343905}]}]}
{"op":"mcm","clk":"4231697301","pt":1631547005556,"mc":[{"id":"1.187560634","rc":[{"batb":[[2,1.91,125.79]],"ltp":2.12,"tv":2995.62,"id":9629296},{"batb":[[0,1.94,49.41],[1,1.81,30.62],[2,1.67,1.4]],"ltp":1.88,"tv":1239.74,"id":12343905}]}]}
{"op":"mcm","clk":"4231697417","pt":1631547007283,"mc":[{"id":"1.187560634","rc":[{"batb":[[2,1.91,94.38]],"ltp":2.12,"tv":2995.62,"id":9629296}]}]}
{"op":"mcm","clk":"4231698171","pt":1631547017325,"mc":[{"id":"1.187560634","rc":[{"trd":[[1.98,120.96]],"batl":[[0,1.98,7.81]],"ltp":1.98,"tv":3000.68,"id":9629296}],"tv":4240.42}]}
{"op":"mcm","clk":"4231698809","pt":1631547027321,"mc":[{"id":"1.187560634","rc":[{"batb":[[0,1.67,40.26],[1,1.4,149.15],[2,1.3,198.84]],"ltp":1.98,"tv":3000.68,"id":9629296},{"batb":[[0,1.81,30.62],[1,1.67,1.4],[2,1.5,107.39]],"ltp":1.88,"tv":1239.74,"id":12343905}]}]}
{"op":"mcm","clk":"4231699191","pt":1631547032329,"mc":[{"id":"1.187560634","rc":[{"batb":[[0,1.88,86.2],[1,1.86,85.59],[2,1.67,40.26]],"batl":[[0,1.95,67.48],[1,1.97,72.92]],"ltp":1.98,"tv":3000.68,"id":9629296}]}]}
{"op":"mcm","clk":"4231699671","pt":1631547039239,"mc":[{"id":"1.187560634","rc":[{"batb":[[0,1.67,40.26],[1,1.4,149.15],[2,1.3,198.84]],"ltp":1.98,"tv":3000.68,"id":9629296}]}]}
{"op":"mcm","clk":"4231699883","pt":1631547042474,"mc":[{"id":"1.187560634","rc":[{"batb":[[0,1.73,62.8],[1,1.71,113.04],[2,1.67,40.26]],"batl":[[0,2.18,91.2],[1,2.2,52.93]],"ltp":1.98,"tv":3000.68,"id":9629296}]}]}
{"op":"mcm","clk":"4231700325","pt":1631547048284,"mc":[{"id":"1.187560634","rc":[{"batb":[[0,1.67,40.26],[1,1.4,149.15],[2,1.3,198.84]],"ltp":1.98,"tv":3000.68,"id":9629296}]}]}
{"op":"mcm","clk":"4231700587","pt":1631547051399,"mc":[{"id":"1.187560634","rc":[{"batb":[[0,2.06,72.82],[1,2.04,36.4],[2,2.02,36.4]],"batl":[[0,2.16,17.3],[1,2.2,127.14]],"ltp":1.98,"tv":3000.68,"id":9629296},{"batb":[[0,1.85,96.26],[1,1.83,90.15],[2,1.81,30.62]],"batl":[[0,1.89,21.16],[1,1.92,78.1],[2,1.94,76.31]],"ltp":1.88,"tv":1239.74,"id":12343905}]}]}
{"op":"mcm","clk":"4231700691","pt":1631547052488,"mc":[{"id":"1.187560634","rc":[{"batb":[[0,2.06,14.56],[1,2.04,7.28],[2,2.02,7.28]],"ltp":1.98,"tv":3000.68,"id":9629296},{"batb":[[0,1.85,112.48],[1,1.84,8.1],[2,1.83,98.25]],"ltp":1.88,"tv":1239.74,"id":12343905}]}]}
{"op":"mcm","clk":"4231703053","pt":1631547083137,"mc":[{"id":"1.187560634","rc":[{"batb":[[0,1.84,29.53],[1,1.4,149.15],[2,1.3,198.84]],"ltp":1.98,"tv":3000.68,"id":9629296},{"batb":[[0,1.72,36.24],[1,1.67,1.4],[2,1.4,149.15]],"ltp":1.88,"tv":1239.74,"id":12343905}]}]}
{"op":"mcm","clk":"4231703391","pt":1631547087602,"mc":[{"id":"1.187560634","rc":[{"batl":[[0,2.2,233.43]],"ltp":1.98,"tv":3000.68,"id":9629296}]}]}
{"op":"mcm","clk":"4231703407","pt":1631547087917,"mc":[{"id":"1.187560634","rc":[{"batb":[[0,1.89,56.45],[1,1.87,84.07],[2,1.72,36.24]],"batl":[[0,1.95,55.69],[1,1.97,72.87]],"ltp":1.88,"tv":1239.74,"id":12343905}]}]}
{"op":"mcm","clk":"4231703918","pt":1631547094928,"mc":[{"id":"1.187560634","rc":[{"batb":[[0,1.72,36.24],[1,1.67,1.4],[2,1.4,149.15]],"ltp":1.88,"tv":1239.74,"id":12343905}]}]}
{"op":"mcm","clk":"4231704124","pt":1631547097933,"mc":[{"id":"1.187560634","rc":[{"batb":[[0,1.76,86.14],[1,1.74,106.45],[2,1.72,36.24]],"batl":[[0,2.1,65.42],[1,2.12,58.78]],"ltp":1.88,"tv":1239.74,"id":12343905}]}]}
{"op":"mcm","clk":"4231704856","pt":1631547108657,"mc":[{"id":"1.187560634","rc":[{"batb":[[0,2.22,67.56],[1,2.2,41.03],[2,2.18,33.78]],"ltp":1.98,"tv":3000.68,"id":9629296},{"batb":[[0,1.8,10.06],[1,1.76,239.09],[2,1.74,106.45]],"batl":[[0,1.84,108.7],[1,1.89,154.92]],"ltp":1.88,"tv":1239.74,"id":12343905}]}]}
{"op":"mcm","clk":"4231704911","pt":1631547109536,"mc":[{"id":"1.187560634","rc":[{"batb":[[0,2.22,13.52],[1,2.2,14.01],[2,2.18,6.76]],"ltp":1.98,"tv":3000.68,"id":9629296},{"batb":[[2,1.74,192.65]],"batl":[[0,1.82,75.65],[1,1.84,198.56],[2,1.89,154.92]],"ltp":1.88,"tv":1239.74,"id":12343905}]}]}
{"op":"mcm","clk":"4231704947","pt":1631547110057,"mc":[{"id":"1.187560634","rc":[{"batb":[[2,1.74,123.69]],"ltp":1.88,"tv":1239.74,"id":12343905}]}]}
{"op":"mcm","clk":"4231705040","pt":1631547111556,"mc":[{"id":"1.187560634","rc":[{"batl":[[0,3.15,203.39]],"ltp":1.98,"tv":3000.68,"id":9629296}]}]}
{"op":"mcm","clk":"4231705185","pt":1631547113576,"mc":[{"id":"1.187560634","rc":[{"trd":[[2.22,63.42]],"batb":[[0,2.22,6.97]],"ltp":2.22,"tv":3013.78,"id":9629296}],"tv":4253.52}]}
{"op":"mcm","clk":"4231705720","pt":1631547121558,"mc":[{"id":"1.187560634","rc":[{"batl":[[0,3.1,7.12],[1,3.15,203.39]],"ltp":2.22,"tv":3013.78,"id":9629296}]}]}
{"op":"mcm","clk":"4231706685","pt":1631547137198,"mc":[{"id":"1.187560634","rc":[{"trd":[[2.2,360.32],[2.22,77.36]],"batb":[[0,2.18,6.76],[1,2.1,38.5],[2,2,45.38]],"ltp":2.2,"tv":3061.08,"id":9629296},{"trd":[[1.82,6.47]],"batl":[[0,1.82,69.18]],"ltp":1.82,"tv":1246.21,"id":12343905}],"tv":4307.3}]}
{"op":"mcm","clk":"4231707320","pt":1631547147019,"mc":[{"id":"1.187560634","rc":[{"batb":[[0,1.76,239.09],[1,1.74,123.69],[2,1.73,8.62]],"ltp":1.82,"tv":1246.21,"id":12343905}]}]}
{"op":"mcm","clk":"4231707522","pt":1631547150208,"mc":[{"id":"1.187560634","rc":[{"batl":[[0,2.24,12.22]],"ltp":2.2,"tv":3061.08,"id":9629296},{"batl":[[2,1.86,14.09]],"ltp":1.82,"tv":1246.21,"id":12343905}]}]}
{"op":"mcm","clk":"4231707739","pt":1631547152400,"mc":[{"id":"1.187560634","rc":[{"batl":[[0,2.24,38.21]],"ltp":2.2,"tv":3061.08,"id":9629296},{"trd":[[1.82,62.47]],"batl":[[0,1.84,108.7],[1,1.86,14.09],[2,1.89,154.92]],"ltp":1.82,"tv":1302.21,"id":12343905}],"tv":4363.3}]}
{"op":"mcm","clk":"4231707915","pt":1631547155410,"mc":[{"id":"1.187560634","rc":[{"batb":[[0,1.76,258.79]],"batl":[[0,1.83,101.77],[1,1.84,108.7],[2,1.85,88.21]],"ltp":1.82,"tv":1302.21,"id":12343905}]}]}
{"op":"mcm","clk":"4231708420","pt":1631547163519,"mc":[{"id":"1.187560634","rc":[{"batl":[[0,2.24,12.22]],"ltp":2.2,"tv":3061.08,"id":9629296}]}]}
{"op":"mcm","clk":"4231708619","pt":1631547166640,"mc":[{"id":"1.187560634","rc":[{"batl":[[1,2.26,25.99],[2,3.15,203.39]],"ltp":2.2,"tv":3061.08,"id":9629296}]}]}
{"op":"mcm","clk":"4231709290","pt":1631547177058,"mc":[{"id":"1.187560634","rc":[{"trd":[[2.24,12.22]],"batl":[[0,2.26,25.99],[1,3.15,203.39],[2,3.15,0]],"ltp":2.24,"tv":3073.3,"id":9629296},{"trd":[[1.8,15.21]],"batl":[[0,1.8,14.79],[1,1.83,101.77],[2,1.84,108.7]],"ltp":1.8,"tv":1317.42,"id":12343905}],"tv":4390.73}]}
{"op":"mcm","clk":"4231709681","pt":1631547182365,"mc":[{"id":"1.187560634","rc":[{"batl":[[0,1.83,101.77],[1,1.84,108.7],[2,1.85,88.21]],"ltp":1.8,"tv":1317.42,"id":12343905}]}]}
{"op":"mcm","clk":"4231709921","pt":1631547185464,"mc":[{"id":"1.187560634","rc":[{"trd":[[2.26,22.27]],"batl":[[0,2.26,14.27]],"ltp":2.26,"tv":3085.02,"id":9629296},{"trd":[[1.79,28.11]],"ltp":1.79,"tv":1332.21,"id":12343905}],"tv":4417.23}]}
{"op":"mcm","clk":"4231710239","pt":1631547190160,"mc":[{"id":"1.187560634","rc":[{"batl":[[1,2.28,11.65],[2,3.15,203.39]],"ltp":2.26,"tv":3085.02,"id":9629296},{"batl":[[0,1.83,114.89]],"ltp":1.79,"tv":1332.21,"id":12343905}]}]}
{"op":"mcm","clk":"4231711725","pt":1631547209596,"mc":[{"id":"1.187560634","rc":[{"batb":[[0,2.1,38.5],[1,2,45.38],[2,1.9,16.76]],"batl":[[1,3.15,203.39],[2,3.15,0]],"ltp":2.26,"tv":3085.02,"id":9629296},{"batb":[[0,1.76,105.84],[1,1.74,106.45],[2,1.72,36.24]],"batl":[[0,1.83,101.77],[1,1.85,88.21],[2,1.85,0]],"ltp":1.79,"tv":1332.21,"id":12343905}]}]}
{"op":"mcm","clk":"4231711749","pt":1631547210019,"mc":[{"id":"1.187560634","rc":[{"batb":[[0,2,45.38],[1,1.9,16.76],[2,1.82,407.19]],"ltp":2.26,"tv":3085.02,"id":9629296},{"batb":[[0,1.67,1.4],[1,1.61,45.55],[2,1.4,149.15]],"ltp":1.79,"tv":1332.21,"id":12343905}]}]}
{"op":"mcm","clk":"4231712184","pt":1631547214607,"mc":[{"id":"1.187560634","rc":[{"batb":[[0,1.74,82.38],[1,1.72,110.62],[2,1.67,1.4]],"batl":[[0,1.8,88.36],[1,1.82,92.93]],"ltp":1.79,"tv":1332.21,"id":12343905}]}]}
{"op":"mcm","clk":"4231712434","pt":1631547218015,"mc":[{"id":"1.187560634","rc":[{"batb":[[0,1.67,1.4],[1,1.61,45.55],[2,1.4,149.15]],"ltp":1.79,"tv":1332.21,"id":12343905}]}]}
{"op":"mcm","clk":"4231712631","pt":1631547221001,"mc":[{"id":"1.187560634","rc":[{"batb":[[1,1.65,72.2],[2,1.64,65.68]],"batl":[[0,1.92,91.15],[1,1.94,76.24]],"ltp":1.79,"tv":1332.21,"id":12343905}]}]}
{"op":"mcm","clk":"4231713675","pt":1631547236281,"mc":[{"id":"1.187560634","rc":[{"batb":[[0,1.76,20],[1,1.67,1.4],[2,1.65,72.2]],"ltp":1.79,"tv":1332.21,"id":12343905}]}]}
{"op":"mcm","clk":"4231714121","pt":1631547242887,"mc":[{"id":"1.187560634","rc":[{"batb":[[0,1.67,1.4],[1,1.65,72.2],[2,1.64,65.68]],"ltp":1.79,"tv":1332.21,"id":12343905}]}]}
{"op":"mcm","clk":"4231715578","pt":1631547264014,"mc":[{"id":"1.187560634","rc":[{"batb":[[2,1.6,99.43]],"ltp":2.26,"tv":3085.02,"id":9629296}]}]}
{"op":"mcm","clk":"4231715664","pt":1631547265274,"mc":[{"id":"1.187560634","rc":[{"trd":[[2.26,36.54]],"batb":[[0,2.32,116.75],[1,2,45.38],[2,1.9,16.76]],"batl":[[0,2.5,9.59],[1,2.56,112.18],[2,3.15,203.39]],"ltp":2.26,"tv":3099.29,"id":9629296},{"trd":[[1.79,46.13]],"batl":[[0,1.7,101.89],[1,1.72,227.42],[2,1.73,8.72]],"ltp":1.79,"tv":1350.23,"id":12343905}],"tv":4449.53}]}
{"op":"mcm","clk":"4231715764","pt":1631547266590,"mc":[{"id":"1.187560634","rc":[{"batb":[[1,2.3,29.95],[2,2.14,36.66]],"batl":[[1,2.56,123.9],[2,2.58,5.86]],"ltp":2.26,"tv":3099.29,"id":9629296}]}]}
{"op":"mcm","clk":"4231716031","pt":1631547270303,"mc":[{"id":"1.187560634","rc":[{"trd":[[1.7,34.83]],"batl":[[0,1.7,84.97]],"ltp":1.7,"tv":1384.07,"id":12343905}],"tv":4483.37}]}
{"op":"mcm","clk":"4231716318","pt":1631547273412,"mc":[{"id":"1.187560634","rc":[{"trd":[[1.7,68.27]],"batl":[[0,1.7,68.25]],"ltp":1.7,"tv":1417.51,"id":12343905}],"tv":4516.81}]}
{"op":"mcm","clk":"4231716595","pt":1631547276893,"mc":[{"id":"1.187560634","rc":[{"batb":[[1,1.65,85.65]],"batl":[[0,1.7,78.81]],"ltp":1.7,"tv":1417.51,"id":12343905}]}]}
{"op":"mcm","clk":"4231716868","pt":1631547280008,"mc":[{"id":"1.187560634","rc":[{"batl":[[0,2.56,123.9],[1,2.58,5.86],[2,2.6,5.86]],"ltp":2.26,"tv":3099.29,"id":9629296}]}]}
{"op":"mcm","clk":"4231717075","pt":1631547283035,"mc":[{"id":"1.187560634","rc":[{"batb":[[0,2.4,7.04],[1,2.32,116.75],[2,2.3,29.95]],"batl":[[0,2.46,7.42],[1,2.56,123.9],[2,2.58,5.86]],"ltp":2.26,"tv":3099.29,"id":9629296}]}]}
{"op":"mcm","clk":"4231717387","pt":1631547287236,"mc":[{"id":"1.187560634","rc":[{"batb":[[0,2.14,36.66],[1,1.9,16.76],[2,1.7,17.05]],"ltp":2.26,"tv":3099.29,"id":9629296},{"batb":[[1,1.5,59.72],[2,1.3,198.84]],"ltp":1.7,"tv":1417.51,"id":12343905}]}]}
{"op":"mcm","clk":"4231717745","pt":1631547291863,"mc":[{"id":"1.187560634","rc":[{"trd":[[1.67,2.8]],"batb":[[0,1.62,118.27],[1,1.61,70.36],[2,1.5,59.72]],"batl":[[0,1.67,63.28],[1,1.69,118.65]],"ltp":1.67,"tv":1420.31,"id":12343905}],"tv":4519.61}]}
{"op":"mcm","clk":"4231718356","pt":1631547298770,"mc":[{"id":"1.187560634","rc":[{"batb":[[0,1.5,59.72],[1,1.3,198.84],[2,1.25,28.88]],"ltp":1.67,"tv":1420.31,"id":12343905}]}]}
{"op":"mcm","clk":"4231718630","pt":1631547301956,"mc":[{"id":"1.187560634","rc":[{"batb":[[0,1.53,91.62],[1,1.52,87.4],[2,1.5,59.72]],"ltp":1.67,"tv":1420.31,"id":12343905}]}]}
{"op":"mcm","clk":"4231718842","pt":1631547304060,"mc":[{"id":"1.187560634","rc":[{"batb":[[0,2.72,5.21],[1,2.68,85.82],[2,2.66,5.6]],"batl":[[0,2.78,5.3],[1,2.92,101.86]],"ltp":2.26,"tv":3099.29,"id":9629296},{"batl":[[0,1.57,79.87],[1,1.58,74.76]],"ltp":1.67,"tv":1420.31,"id":12343905}]}]}
{"op":"mcm","clk":"4231718948","pt":1631547305328,"mc":[{"id":"1.187560634","rc":[{"batl":[[1,2.88,10.42],[2,2.9,5.2]],"ltp":2.26,"tv":3099.29,"id":9629296}]}]}
{"op":"mcm","clk":"4231719596","pt":1631547312351,"mc":[{"id":"1.187560634","rc":[{"trd":[[2.78,10.6],[2.88,20.84],[2.9,58.74]],"batb":[[0,2.9,58.64],[1,2.72,5.21],[2,2.68,85.82]],"batl":[[0,2.92,107.06],[1,2.88,0],[2,2.9,0]],"ltp":2.9,"tv":3189.47,"id":9629296},{"trd":[[1.53,91.62]],"batb":[[0,1.52,87.4],[1,1.5,59.72],[2,1.4,78.85]],"ltp":1.53,"tv":1511.93,"id":12343905}],"tv":4701.41}]}
{"op":"mcm","clk":"4231719840","pt":1631547315237,"mc":[{"id":"1.187560634","rc":[{"trd":[[2.9,176.02]],"batb":[[0,2.72,5.21],[1,2.68,85.82],[2,2.66,5.6]],"ltp":2.9,"tv":3306.75,"id":9629296},{"batb":[[0,1.52,128.68],[1,1.51,90.25],[2,1.5,59.72]],"batl":[[0,1.57,129.26]],"ltp":1.53,"tv":1511.93,"id":12343905}],"tv":4818.69}]}
{"op":"mcm","clk":"4231720042","pt":1631547317475,"mc":[{"id":"1.187560634","rc":[{"batb":[[0,2.38,27.34],[1,1.9,16.76],[2,1.7,17.05]],"ltp":2.9,"tv":3306.75,"id":9629296},{"batb":[[0,1.4,78.85],[1,1.25,28.88],[2,1.2,447.4]],"ltp":1.53,"tv":1511.93,"id":12343905}]}]}
{"op":"mcm","clk":"4231720564","pt":1631547323967,"mc":[{"id":"1.187560634","rc":[{"batb":[[0,1.5,115.56],[1,1.49,95.15],[2,1.4,78.85]],"batl":[[0,1.54,80.1],[1,1.55,80.58]],"ltp":1.53,"tv":1511.93,"id":12343905}]}]}
{"op":"mcm","clk":"4231720627","pt":1631547324788,"mc":[{"id":"1.187560634","rc":[{"batb":[[0,1.4,78.85],[1,1.25,28.88],[2,1.2,447.4]],"ltp":1.53,"tv":1511.93,"id":12343905}]}]}
{"op":"mcm","clk":"4231720722","pt":1631547325989,"mc":[{"id":"1.187560634","rc":[{"batl":[[0,2.9,14.44]],"ltp":2.9,"tv":3306.75,"id":9629296}]}]}
{"op":"mcm","clk":"4231720924","pt":1631547328502,"mc":[{"id":"1.187560634","rc":[{"batb":[[0,1.42,114.21],[1,1.41,120.38],[2,1.4,78.85]],"ltp":1.53,"tv":1511.93,"id":12343905}]}]}
{"op":"mcm","clk":"4231721093","pt":1631547330589,"mc":[{"id":"1.187560634","rc":[{"trd":[[2.9,204.9]],"batb":[[0,3.25,47.1],[1,3.15,9.52],[2,3.1,4.76]],"batl":[[0,3.4,79.36]],"ltp":2.9,"tv":3335.63,"id":9629296},{"batb":[[0,1.44,10.74],[1,1.42,114.21],[2,1.41,120.38]],"batl":[[0,1.46,172.26],[1,1.47,98.57],[2,1.6,758.65]],"ltp":1.53,"tv":1511.93,"id":12343905}],"tv":4847.57}]}
{"op":"mcm","clk":"4231721189","pt":1631547331595,"mc":[{"id":"1.187560634","rc":[{"batb":[[2,1.41,226.76]],"ltp":1.53,"tv":1511.93,"id":12343905}]}]}
{"op":"mcm","clk":"4231721222","pt":1631547331897,"mc":[{"id":"1.187560634","rc":[{"batb":[[2,1.41,141.66]],"ltp":1.53,"tv":1511.93,"id":12343905}]}]}
{"op":"mcm","clk":"4231721421","pt":1631547334211,"mc":[{"id":"1.187560634","rc":[{"batl":[[1,4.9,128.15]],"ltp":2.9,"tv":3335.63,"id":9629296}]}]}
{"op":"mcm","clk":"4231722177","pt":1631547343179,"mc":[{"id":"1.187560634","rc":[{"batb":[[0,2.74,18.54],[1,2.3,390.8],[2,1.9,16.76]],"batl":[[0,4.9,128.15],[1,4.9,0]],"ltp":2.9,"tv":3335.63,"id":9629296},{"batb":[[0,1.33,99.65],[1,1.2,447.4],[2,1.1,300.27]],"ltp":1.53,"tv":1511.93,"id":12343905}]}]}
{"op":"mcm","clk":"4231722415","pt":1631547346103,"mc":[{"id":"1.187560634","rc":[{"batb":[[0,1.35,188.29],[1,1.34,154.03],[2,1.33,99.65]],"batl":[[0,1.51,108.97],[1,1.52,86.65]],"ltp":1.53,"tv":1511.93,"id":12343905}]}]}
{"op":"mcm","clk":"4231722540","pt":1631547347707,"mc":[{"id":"1.187560634","rc":[{"batb":[[0,1.33,99.65],[1,1.2,447.4],[2,1.1,300.27]],"ltp":1.53,"tv":1511.93,"id":12343905}]}]}
{"op":"mcm","clk":"4231722756","pt":1631547350418,"mc":[{"id":"1.187560634","rc":[{"batb":[[0,2.96,5.36],[1,2.74,18.54],[2,2.3,390.8]],"batl":[[0,3.05,7.31],[1,3.1,65.59]],"ltp":2.9,"tv":3335.63,"id":9629296},{"batb":[[0,1.48,135.14],[1,1.47,102.04],[2,1.46,51.02]],"batl":[[2,1.54,119.51]],"ltp":1.53,"tv":1511.93,"id":12343905}]}]}
{"op":"mcm","clk":"4231722868","pt":1631547351638,"mc":[{"id":"1.187560634","rc":[{"batb":[[1,2.9,51.72],[2,2.88,25.86]],"batl":[[2,3.6,14.44]],"ltp":2.9,"tv":3335.63,"id":9629296},{"batb":[[1,1.47,131.96],[2,1.46,113.68]],"ltp":1.53,"tv":1511.93,"id":12343905}]}]}
{"op":"mcm","clk":"4231722950","pt":1631547352413,"mc":[{"id":"1.187560634","rc":[{"batb":[[1,2.9,10.34],[2,2.88,5.18]],"ltp":2.9,"tv":3335.63,"id":9629296}]}]}
{"op":"mcm","clk":"4231723100","pt":1631547354410,"mc":[{"id":"1.187560634","rc":[{"trd":[[1.51,3.42]],"batl":[[0,1.51,107.26]],"ltp":1.51,"tv":1515.34,"id":12343905}],"tv":4850.98}]}
{"op":"mcm","clk":"4231723339","pt":1631547357626,"mc":[{"id":"1.187560634","rc":[{"batb":[[0,2.9,10.34],[1,2.88,5.18],[2,2.86,5.18]],"batl":[[0,3.6,14.44],[1,4.6,138.07],[2,3.6,0]],"ltp":2.9,"tv":3335.63,"id":9629296},{"batl":[[2,1.54,0]],"ltp":1.51,"tv":1515.34,"id":12343905}]}]}
{"op":"mcm","clk":"4231723383","pt":1631547358107,"mc":[{"id":"1.187560634","rc":[{"batb":[[0,2.48,24.33],[1,2.3,390.8],[2,1.9,16.76]],"ltp":2.9,"tv":3335.63,"id":9629296},{"batb":[[0,1.35,94.7],[1,1.2,447.4],[2,1.1,300.27]],"ltp":1.51,"tv":1515.34,"id":12343905}]}]}
{"op":"mcm","clk":"4231723958","pt":1631547364527,"mc":[{"id":"1.187560634","rc":[{"batb":[[0,1.45,94.87],[1,1.44,109.59],[2,1.35,94.7]],"batl":[[0,1.49,143.44],[1,1.5,91]],"ltp":1.51,"tv":1515.34,"id":12343905}]}]}
{"op":"mcm","clk":"4231723975","pt":1631547364842,"mc":[{"id":"1.187560634","rc":[{"batb":[[0,1.35,94.7],[1,1.2,447.4],[2,1.1,300.27]],"ltp":1.51,"tv":1515.34,"id":12343905}]}]}
{"op":"mcm","clk":"4231724153","pt":1631547367217,"mc":[{"id":"1.187560634","rc":[{"batb":[[2,1.15,357.95]],"ltp":1.51,"tv":1515.34,"id":12343905}]}]}
{"op":"mcm","clk":"4231724198","pt":1631547367837,"mc":[{"id":"1.187560634","rc":[{"batb":[[0,1.37,76.32],[1,1.36,141.82],[2,1.35,94.7]],"batl":[[0,1.6,116.77],[1,1.61,69.88]],"ltp":1.51,"tv":1515.34,"id":12343905}]}]}
{"op":"mcm","clk":"4231724435","pt":1631547370823,"mc":[{"id":"1.187560634","rc":[{"batl":[[0,1.47,58.05],[1,1.6,116.77],[2,1.61,69.88]],"ltp":1.51,"tv":1515.34,"id":12343905}]}]}
{"op":"mcm","clk":"4231724977","pt":1631547377349,"mc":[{"id":"1.187560634","rc":[{"batl":[[1,1.6,0],[2,1.61,0]],"ltp":1.51,"tv":1515.34,"id":12343905}]}]}
{"op":"mcm","clk":"4231725094","pt":1631547379031,"mc":[{"id":"1.187560634","rc":[{"batl":[[1,4.6,0]],"ltp":2.9,"tv":3335.63,"id":9629296}]}]}
{"op":"mcm","clk":"4231725203","pt":1631547380434,"mc":[{"id":"1.187560634","rc":[{"batb":[[0,3.5,4.49],[1,3.4,26.47],[2,3.35,49.06]],"batl":[[1,3.7,9.31],[2,3.85,95.36]],"ltp":2.9,"tv":3335.63,"id":9629296},{"batl":[[0,1.4,151.5],[1,1.41,117.7],[2,1.43,203.07]],"ltp":1.51,"tv":1515.34,"id":12343905}]}]}
{"op":"mcm","clk":"4231725314","pt":1631547381639,"mc":[{"id":"1.187560634","rc":[{"batb":[[1,3.4,8.82],[2,3.35,40.24]],"batl":[[2,3.75,8]],"ltp":2.9,"tv":3335.63,"id":9629296}]}]}
{"op":"mcm","clk":"4231726254","pt":1631547392243,"mc":[{"id":"1.187560634","rc":[{"batl":[[0,3.7,9.31],[1,3.75,8],[2,3.8,4]],"ltp":2.9,"tv":3335.63,"id":9629296}]}]}
{"op":"mcm","clk":"4231726560","pt":1631547395666,"mc":[{"id":"1.187560634","rc":[{"batl":[[0,3.55,14.44],[1,3.7,9.31],[2,3.75,8]],"ltp":2.9,"tv":3335.63,"id":9629296}]}]}
{"op":"mcm","clk":"4231727376","pt":1631547406473,"mc":[{"id":"1.187560634","rc":[{"trd":[[3.55,14.44],[3.7,9.31]],"batl":[[0,3.75,8],[1,3.8,4],[2,3.85,99.36]],"ltp":3.7,"tv":3359.38,"id":9629296},{"trd":[[1.37,177.78],[1.39,36.88]],"batb":[[0,1.36,141.82],[1,1.35,94.7],[2,1.31,109.38]],"batl":[[0,1.37,11.66],[1,1.4,151.5],[2,1.41,117.7]],"ltp":1.37,"tv":1730.0,"id":12343905}],"tv":5089.39}]}
{"op":"mcm","clk":"4231727418","pt":1631547407050,"mc":[{"id":"1.187560634","rc":[{"trd":[[1.37,187.78]],"batl":[[0,1.37,6.66]],"ltp":1.37,"tv":1740.0,"id":12343905}],"tv":5099.39}]}
{"op":"mcm","clk":"4231727596","pt":1631547409462,"mc":[{"id":"1.187560634","rc":[{"trd":[[1.37,201.1]],"batb":[[0,1.36,176.23],[1,1.35,243.55]],"batl":[[0,1.4,192.81],[1,1.41,117.7],[2,1.43,203.07]],"ltp":1.37,"tv":1753.32,"id":12343905}],"tv":5112.71}]}
{"op":"mcm","clk":"4231727750","pt":1631547411384,"mc":[{"id":"1.187560634","rc":[{"batb":[[0,2.84,41.6],[1,2.3,390.8],[2,2,11.93]],"batl":[[0,5.5,116.76],[1,3.8,0],[2,3.85,0]],"ltp":3.7,"tv":3359.38,"id":9629296},{"batb":[[0,1.31,109.38],[1,1.15,357.95],[2,1.1,300.27]],"batl":[[0,1.47,58.05],[1,44,7.22],[2,1.43,0]],"ltp":1.37,"tv":1753.32,"id":12343905}]}]}
{"op":"mcm","clk":"4231728136","pt":1631547416276,"mc":[{"id":"1.187560634","rc":[{"batb":[[0,1.38,78.55],[1,1.37,137.49],[2,1.31,109.38]],"batl":[[0,1.41,128.6],[1,1.42,114.7],[2,1.47,58.05]],"ltp":1.37,"tv":1753.32,"id":12343905}]}]}
{"op":"mcm","clk":"4231728725","pt":1631547423405,"mc":[{"id":"1.187560634","rc":[{"batb":[[0,1.31,109.38],[1,1.15,357.95],[2,1.1,300.27]],"batl":[[0,1.47,58.05],[1,44,7.22],[2,1.47,0]],"ltp":1.37,"tv":1753.32,"id":12343905}]}]}
{"op":"mcm","clk":"4231728866","pt":1631547424876,"mc":[{"id":"1.187560634","rc":[{"batl":[[0,1.39,2],[1,1.47,58.05],[2,44,7.22]],"ltp":1.37,"tv":1753.32,"id":12343905}]}]}
{"op":"mcm","clk":"4231729009","pt":1631547426292,"mc":[{"id":"1.187560634","rc":[{"batb":[[0,1.32,230.58],[1,1.31,283.69],[2,1.15,357.95]],"batl":[[1,1.47,180.01],[2,1.48,96.53]],"ltp":1.37,"tv":1753.32,"id":12343905}]}]}
{"op":"mcm","clk":"4231730367","pt":1631547440499,"mc":[{"id":"1.187560634","rc":[{"batl":[[1,1.47,58.05],[2,44,7.22]],"ltp":1.37,"tv":1753.32,"id":12343905}]}]}
{"op":"mcm","clk":"4231730486","pt":1631547442013,"mc":[{"id":"1.187560634","rc":[{"batb":[[1,2,11.93],[2,1.9,16.76]],"ltp":3.7,"tv":3359.38,"id":9629296}]}]}
{"op":"mcm","clk":"4231730604","pt":1631547443423,"mc":[{"id":"1.187560634","rc":[{"batb":[[0,3.75,10.66],[1,3.6,91.45],[2,2.84,41.6]],"batl":[[0,4.1,83.16],[1,5.5,116.76]],"ltp":3.7,"tv":3359.38,"id":9629296},{"batl":[[0,1.34,13.76],[1,1.36,313.65],[2,1.37,188.89]],"ltp":1.37,"tv":1753.32,"id":12343905}]}]}
{"op":"mcm","clk":"4231730720","pt":1631547444499,"mc":[{"id":"1.187560634","rc":[{"batb":[[2,3.45,25.42]],"batl":[[1,4.2,7.14],[2,4.3,3.58]],"ltp":3.7,"tv":3359.38,"id":9629296},{"batb":[[2,1.28,122.97]],"batl":[[1,1.36,269.54],[2,1.37,166.83]],"ltp":1.37,"tv":1753.32,"id":12343905}]}]}
{"op":"mcm","clk":"4231731174","pt":1631547449701,"mc":[{"id":"1.187560634","rc":[{"trd":[[1.34,7.52]],"batl":[[0,1.34,10]],"ltp":1.34,"tv":1760.85,"id":12343905}],"tv":5120.23}]}
{"op":"mcm","clk":"4231732015","pt":1631547459836,"mc":[{"id":"1.187560634","rc":[{"batl":[[0,4.1,76.42]],"ltp":3.7,"tv":3359.38,"id":9629296},{"batl":[[0,1.36,269.54],[1,1.37,166.83],[2,1.38,33.08]],"ltp":1.34,"tv":1760.85,"id":12343905}]}]}
{"op":"mcm","clk":"4231732296","pt":1631547462827,"mc":[{"id":"1.187560634","rc":[{"batb":[[0,3.9,6.55],[1,3.75,10.66],[2,3.6,91.45]],"batl":[[0,4.1,84.39]],"ltp":3.7,"tv":3359.38,"id":9629296}]}]}
{"op":"mcm","clk":"4231732472","pt":1631547464800,"mc":[{"id":"1.187560634","rc":[{"trd":[[3.9,6.55]],"batb":[[0,3.75,10.66],[1,3.6,91.45],[2,3.45,25.42]],"ltp":3.9,"tv":3365.93,"id":9629296},{"trd":[[1.35,18.92],[1.36,42.16]],"batl":[[0,1.36,248.46]],"ltp":1.36,"tv":1821.93,"id":12343905}],"tv":5187.86}]}
{"op":"mcm","clk":"4231733262","pt":1631547474332,"mc":[{"id":"1.187560634","rc":[{"batb":[[0,3.05,33.64],[1,2.52,387.12],[2,2.2,42.6]],"batl":[[0,5.5,116.76],[1,4.2,0],[2,4.3,0]],"ltp":3.9,"tv":3365.93,"id":9629296},{"batb":[[0,1.28,122.97],[1,1.15,357.95],[2,1.1,300.27]],"batl":[[0,1.39,2],[1,1.47,58.05],[2,1.52,3.1]],"ltp":1.36,"tv":1821.93,"id":12343905}]}]}
{"op":"mcm","clk":"4231733504","pt":1631547477257,"mc":[{"id":"1.187560634","rc":[{"batb":[[0,1.3,80.13],[1,1.29,186.68],[2,1.28,122.97]],"batl":[[1,1.41,92.32],[2,1.42,115.08]],"ltp":1.36,"tv":1821.93,"id":12343905}]}]}
{"op":"mcm","clk":"4231733600","pt":1631547478657,"mc":[{"id":"1.187560634","rc":[{"batb":[[0,1.28,122.97],[1,1.15,357.95],[2,1.1,300.27]],"ltp":1.36,"tv":1821.93,"id":12343905}]}]}
{"op":"mcm","clk":"4231733827","pt":1631547481658,"mc":[{"id":"1.187560634","rc":[{"batb":[[0,3.3,60.85],[1,3.05,33.64],[2,2.52,387.12]],"batl":[[0,3.7,99.45],[1,3.75,4.06],[2,3.8,4.06]],"ltp":3.9,"tv":3365.93,"id":9629296},{"trd":[[1.39,40.88]],"batb":[[0,1.39,11.79],[1,1.38,116.85],[2,1.37,137.95]],"batl":[[0,1.41,109.05],[1,1.42,115.08],[2,1.47,58.05]],"ltp":1.39,"tv":1825.93,"id":12343905}],"tv":5191.86}]}
{"op":"mcm","clk":"4231733909","pt":1631547482649,"mc":[{"id":"1.187560634","rc":[{"batb":[[0,3.35,8.96],[1,3.3,65.33],[2,3.25,4.48]],"ltp":3.9,"tv":3365.93,"id":9629296},{"batb":[[2,1.37,226.61]],"ltp":1.39,"tv":1825.93,"id":12343905}]}]}
{"op":"mcm","clk":"4231734214","pt":1631547486361,"mc":[{"id":"1.187560634","rc":[{"batl":[[2,1.46,150.86]],"ltp":1.39,"tv":1825.93,"id":12343905}]}]}
{"op":"mcm","clk":"4231734643","pt":1631547491578,"mc":[{"id":"1.187560634","rc":[{"batb":[[0,1.38,116.85],[1,1.37,226.61],[2,1.36,147.06]],"batl":[[0,1.41,92.32]],"ltp":1.39,"tv":1825.93,"id":12343905}]}]}
{"op":"mcm","clk":"4231734919","pt":1631547494524,"mc":[{"id":"1.187560634","rc":[{"batb":[[0,1.39,11.79],[1,1.38,116.85],[2,1.37,226.61]],"batl":[[0,1.41,111.02]],"ltp":1.39,"tv":1825.93,"id":12343905}]}]}
{"op":"mcm","clk":"4231735091","pt":1631547496436,"mc":[{"id":"1.187560634","rc":[{"trd":[[1.39,41.04]],"batb":[[0,1.39,11.71]],"batl":[[2,1.46,206.11]],"ltp":1.39,"tv":1826.09,"id":12343905}],"tv":5192.02}]}
{"op":"mcm","clk":"4231735619","pt":1631547502809,"mc":[{"id":"1.187560634","rc":[{"trd":[[1.41,2.34]],"batl":[[0,1.41,109.85]],"ltp":1.41,"tv":1828.43,"id":12343905}],"tv":5194.36}]}
{"op":"mcm","clk":"4231735727","pt":1631547504007,"mc":[{"id":"1.187560634","rc":[{"batb":[[0,2.76,18.29],[1,2.52,387.12],[2,2.2,42.6]],"batl":[[0,5.5,116.76],[1,3.75,0],[2,3.8,0]],"ltp":3.9,"tv":3365.93,"id":9629296},{"batb":[[0,1.31,106.78],[1,1.15,357.95],[2,1.1,300.27]],"batl":[[0,1.46,150.86],[1,1.47,115.55],[2,1.48,49.99]],"ltp":1.41,"tv":1828.43,"id":12343905}]}]}
{"op":"mcm","clk":"4231735868","pt":1631547505621,"mc":[{"id":"1.187560634","rc":[{"batb":[[0,3.1,4.44],[1,3,5],[2,2.76,18.29]],"ltp":3.9,"tv":3365.93,"id":9629296},{"batb":[[1,1.3,94.58],[2,1.15,357.95]],"ltp":1.41,"tv":1828.43,"id":12343905}]}]}
{"op":"mcm","clk":"4231736011","pt":1631547507196,"mc":[{"id":"1.187560634","rc":[{"batl":[[0,4.4,2.14],[1,5.5,116.76]],"ltp":3.9,"tv":3365.93,"id":9629296},{"batb":[[0,1.33,187.98],[1,1.32,166.85],[2,1.31,106.78]],"ltp":1.41,"tv":1828.43,"id":12343905}]}]}
{"op":"mcm","clk":"4231736082","pt":1631547508235,"mc":[{"id":"1.187560634","rc":[{"batb":[[0,1.31,106.78],[1,1.3,94.58],[2,1.15,357.95]],"ltp":1.41,"tv":1828.43,"id":12343905}]}]}
{"op":"mcm","clk":"4231736319","pt":1631547511400,"mc":[{"id":"1.187560634","rc":[{"batl":[[0,3.5,21.99],[1,4.4,2.14],[2,5.5,116.76]],"ltp":3.9,"tv":3365.93,"id":9629296},{"batb":[[0,1.4,20.91],[1,1.39,193.54],[2,1.38,134.16]],"batl":[[0,1.42,18.75],[1,1.43,121.47],[2,1.44,108.1]],"ltp":1.41,"tv":1828.43,"id":12343905}]}]}
{"op":"mcm","clk":"4231736345","pt":1631547511714,"mc":[{"id":"1.187560634","rc":[{"batl":[[0,4.4,2.14],[1,5.5,116.76],[2,5.5,0]],"ltp":3.9,"tv":3365.93,"id":9629296},{"batb":[[0,1.39,193.54],[1,1.38,134.16],[2,1.31,106.78]],"batl":[[0,1.43,121.47],[1,1.44,108.1],[2,1.46,150.86]],"ltp":1.41,"tv":1828.43,"id":12343905}]}]}
{"op":"mcm","clk":"4231736821","pt":1631547517618,"mc":[{"id":"1.187560634","rc":[{"batb":[[0,1.31,106.78],[1,1.3,94.58],[2,1.15,357.95]],"batl":[[0,1.46,150.86],[1,1.47,115.55],[2,1.48,49.99]],"ltp":1.41,"tv":1828.43,"id":12343905}]}]}
{"op":"mcm","clk":"4231737037","pt":1631547520646,"mc":[{"id":"1.187560634","rc":[{"batb":[[0,1.33,187.98],[1,1.32,166.85],[2,1.31,106.78]],"ltp":1.41,"tv":1828.43,"id":12343905}]}]}
{"op":"mcm","clk":"4231737413","pt":1631547525545,"mc":[{"id":"1.187560634","rc":[{"batb":[[0,1.31,106.78],[1,1.3,94.58],[2,1.15,357.95]],"ltp":1.41,"tv":1828.43,"id":12343905}]}]}
{"op":"mcm","clk":"4231737538","pt":1631547527217,"mc":[{"id":"1.187560634","rc":[{"batl":[[1,5.5,0]],"ltp":3.9,"tv":3365.93,"id":9629296}]}]}
{"op":"mcm","clk":"4231737625","pt":1631547528470,"mc":[{"id":"1.187560634","rc":[{"batb":[[0,3,10.43],[1,2.88,82.84]],"batl":[[0,3.2,86.42],[1,3.25,4.68],[2,3.3,4.68]],"ltp":3.9,"tv":3365.93,"id":9629296},{"trd":[[1.46,301.72]],"batb":[[0,1.46,149.9],[1,1.45,107.18],[2,1.31,106.78]],"batl":[[0,1.47,58.05],[1,1.5,147.63],[2,1.51,89.38]],"ltp":1.46,"tv":2130.15,"id":12343905}],"tv":5496.08}]}
{"op":"mcm","clk":"4231737709","pt":1631547529466,"mc":[{"id":"1.187560634","rc":[{"batb":[[1,2.94,10.2],[2,2.92,5.1]],"ltp":3.9,"tv":3365.93,"id":9629296},{"batb":[[1,1.45,176.21],[2,1.38,85.22]],"ltp":1.46,"tv":2130.15,"id":12343905}]}]}
{"op":"mcm","clk":"4231738281","pt":1631547536329,"mc":[{"id":"1.187560634","rc":[{"batb":[[2,1.39,65.91]],"ltp":1.46,"tv":2130.15,"id":12343905}]}]}
{"op":"mcm","clk":"4231738422","pt":1631547538253,"mc":[{"id":"1.187560634","rc":[{"batb":[[0,3,5]],"ltp":3.9,"tv":3365.93,"id":9629296},{"batl":[[1,1.5,136.76]],"ltp":1.46,"tv":2130.15,"id":12343905}]}]}
{"op":"mcm","clk":"4231738652","pt":1631547541252,"mc":[{"id":"1.187560634","rc":[{"batb":[[0,1.46,162.6]],"batl":[[1,1.48,12.16],[2,1.5,136.76]],"ltp":1.46,"tv":2130.15,"id":12343905}]}]}
{"op":"mcm","clk":"4231739496","pt":1631547551488,"mc":[{"id":"1.187560634","rc":[{"batb":[[0,2.76,18.29],[1,2.68,5.11],[2,2.58,5.56]],"batl":[[0,3.6,2.96],[1,3.8,3.32],[2,4.4,2.14]],"ltp":3.9,"tv":3365.93,"id":9629296},{"batb":[[0,1.45,69.03],[1,1.39,65.91],[2,1.38,85.22]],"batl":[[1,1.52,3.1],[2,1.59,42.5]],"ltp":1.46,"tv":2130.15,"id":12343905}]}]}
{"op":"mcm","clk":"4231739509","pt":1631547551697,"mc":[{"id":"1.187560634","rc":[{"batb":[[0,2.68,5.11],[1,2.58,5.56],[2,2.4,26.76]],"batl":[[0,3.8,3.32],[1,4.6,138.07],[2,4.4,0]],"ltp":3.9,"tv":3365.93,"id":9629296},{"batb":[[0,1.38,85.22],[1,1.36,67.93],[2,1.15,357.95]],"ltp":1.46,"tv":2130.15,"id":12343905}]}]}
{"op":"mcm","clk":"4231739750","pt":1631547554671,"mc":[{"id":"1.187560634","rc":[{"batl":[[1,4.6,0]],"ltp":3.9,"tv":3365.93,"id":9629296},{"batb":[[0,1.39,192.44],[1,1.38,219.36],[2,1.36,67.93]],"ltp":1.46,"tv":2130.15,"id":12343905}]}]}
{"op":"mcm","clk":"4231739900","pt":1631547556596,"mc":[{"id":"1.187560634","rc":[{"batb":[[0,3.4,8.24],[1,3.35,44.78],[2,3.3,22.4]],"batl":[[0,3.55,71.77],[1,3.8,3.32]],"ltp":3.9,"tv":3365.93,"id":9629296},{"batl":[[0,1.42,393.06],[1,1.47,58.05],[2,1.52,3.1]],"ltp":1.46,"tv":2130.15,"id":12343905}]}]}
{"op":"mcm","clk":"4231739976","pt":1631547557592,"mc":[{"id":"1.187560634","rc":[{"batb":[[1,3.35,8.96],[2,3.3,4.48]],"batl":[[1,3.7,40.54],[2,3.75,20.26]],"ltp":3.9,"tv":3365.93,"id":9629296},{"batl":[[0,1.43,122.51],[1,1.44,108.09],[2,1.47,58.05]],"ltp":1.46,"tv":2130.15,"id":12343905}]}]}
{"op":"mcm","clk":"4231740052","pt":1631547558478,"mc":[{"id":"1.187560634","rc":[{"batl":[[1,3.7,8.1],[2,3.75,4.06]],"ltp":3.9,"tv":3365.93,"id":9629296}]}]}
{"op":"mcm","clk":"4231740307","pt":1631547561508,"mc":[{"id":"1.187560634","rc":[{"trd":[[3.35,17.58],[3.4,16.48]],"batb":[[0,3.3,4.65],[1,3.25,4.48],[2,3.15,63.5]],"ltp":3.35,"tv":3399.99,"id":9629296}],"tv":5530.14}]}
{"op":"mcm","clk":"4231741093","pt":1631547571601,"mc":[{"id":"1.187560634","rc":[{"batl":[[0,3.55,64.93]],"ltp":3.35,"tv":3399.99,"id":9629296}]}]}
{"op":"mcm","clk":"4231741350","pt":1631547574627,"mc":[{"id":"1.187560634","rc":[{"batb":[[0,3.35,5.5],[1,3.3,4.48],[2,3.25,4.48]],"batl":[[0,3.5,5.01],[1,3.55,64.93],[2,3.7,8.1]],"ltp":3.35,"tv":3399.99,"id":9629296},{"batb":[[0,1.4,12.54],[1,1.39,192.44],[2,1.38,219.36]],"ltp":1.46,"tv":2130.15,"id":12343905}]}]}
{"op":"mcm","clk":"4231741511","pt":1631547576521,"mc":[{"id":"1.187560634","rc":[{"batl":[[2,1.52,3.1]],"ltp":1.46,"tv":2130.15,"id":12343905}]}]}
{"op":"mcm","clk":"4231742155","pt":1631547584651,"mc":[{"id":"1.187560634","rc":[{"batb":[[0,3.3,2.41],[1,3.25,2.24],[2,3.15,31.75]],"batl":[[0,3.7,4.05],[1,3.75,2.03],[2,3.8,5.35]],"ltp":3.35,"tv":3399.99,"id":9629296},{"batb":[[0,1.39,192.44],[1,1.38,219.36],[2,1.36,67.93]],"ltp":1.46,"tv":2130.15,"id":12343905}]}]}
{"op":"mcm","clk":"4231742185","pt":1631547585019,"mc":[{"id":"1.187560634","rc":[{"batb":[[0,2.74,4.52],[1,2.62,21.05],[2,2,11.93]],"batl":[[0,4.3,2.65],[1,3.75,0],[2,3.8,0]],"ltp":3.35,"tv":3399.99,"id":9629296},{"batb":[[0,1.31,198.07],[1,1.15,357.95],[2,1.1,300.27]],"batl":[[0,1.52,3.1],[1,1.57,46.5],[2,44,7.22]],"ltp":1.46,"tv":2130.15,"id":12343905}]}]}
{"op":"mcm","clk":"4231742521","pt":1631547589561,"mc":[{"id":"1.187560634","rc":[{"batl":[[0,3.55,157.9],[1,4.3,2.65]],"ltp":3.35,"tv":3399.99,"id":9629296}]}]}
{"op":"mcm","clk":"4231742563","pt":1631547589932,"mc":[{"id":"1.187560634","rc":[{"batl":[[0,4.3,2.65],[1,4.3,0]],"ltp":3.35,"tv":3399.99,"id":9629296},{"batb":[[0,1.42,78.93],[1,1.41,120.45],[2,1.31,198.07]],"batl":[[0,1.45,89.8],[1,1.46,102.31],[2,1.52,3.1]],"ltp":1.46,"tv":2130.15,"id":12343905}]}]}
{"op":"mcm","clk":"4231742698","pt":1631547591644,"mc":[{"id":"1.187560634","rc":[{"batb":[[0,2.88,4.71],[1,2.74,4.52],[2,2.62,21.05]],"batl":[[0,3.95,2.9],[1,4.3,2.65]],"ltp":3.35,"tv":3399.99,"id":9629296},{"batb":[[2,1.34,80.22]],"ltp":1.46,"tv":2130.15,"id":12343905}]}]}
{"op":"mcm","clk":"4231742786","pt":1631547592840,"mc":[{"id":"1.187560634","rc":[{"batl":[[2,4.9,128.15]],"ltp":3.35,"tv":3399.99,"id":9629296}]}]}
{"op":"mcm","clk":"4231743133","pt":1631547597270,"mc":[{"id":"1.187560634","rc":[{"batb":[[0,2.74,4.52],[1,2.62,21.05],[2,2,11.93]],"batl":[[0,4.3,2.65],[1,4.9,128.15],[2,4.9,0]],"ltp":3.35,"tv":3399.99,"id":9629296},{"batb":[[0,1.31,198.07],[1,1.15,357.95],[2,1.1,300.27]],"batl":[[0,1.52,3.1],[1,1.57,46.5],[2,44,7.22]],"ltp":1.46,"tv":2130.15,"id":12343905}]}]}
{"op":"mcm","clk":"4231743394","pt":1631547600671,"mc":[{"id":"1.187560634","rc":[{"batb":[[0,2.88,3.96],[1,2.74,4.52],[2,2.62,21.05]],"batl":[[0,3.95,2.9],[1,4.3,2.65],[2,4.9,128.15]],"ltp":3.35,"tv":3399.99,"id":9629296},{"batb":[[0,1.34,78.72],[1,1.33,202.13],[2,1.32,167.08]],"batl":[[0,1.42,100],[1,1.52,3.1],[2,1.53,45.5]],"ltp":1.46,"tv":2130.15,"id":12343905}]}]}
{"op":"mcm","clk":"4231743466","pt":1631547601567,"mc":[{"id":"1.187560634","rc":[{"batb":[[0,2.74,4.52],[1,2.62,21.05],[2,2,11.93]],"batl":[[0,4.3,2.65],[1,4.9,128.15],[2,4.9,0]],"ltp":3.35,"tv":3399.99,"id":9629296},{"batb":[[0,1.33,202.13],[1,1.32,167.08],[2,1.31,198.07]],"batl":[[0,1.52,3.1],[1,1.55,92.67],[2,1.56,78.84]],"ltp":1.46,"tv":2130.15,"id":12343905}]}]}
{"op":"mcm","clk":"4231743954","pt":1631547607645,"mc":[{"id":"1.187560634","rc":[{"batb":[[0,2.88,5.21],[1,2.74,4.52],[2,2.62,21.05]],"batl":[[0,3.95,3.1],[1,4.3,2.65],[2,4.9,128.15]],"ltp":3.35,"tv":3399.99,"id":9629296},{"batb":[[0,1.34,73.72],[1,1.33,202.13],[2,1.32,167.08]],"batl":[[1,1.53,47.5],[2,1.55,92.67]],"ltp":1.46,"tv":2130.15,"id":12343905}]}]}
{"op":"mcm","clk":"4231743975","pt":1631547607855,"mc":[{"id":"1.187560634","rc":[{"batb":[[0,2.74,4.52],[1,2.62,21.05],[2,2,11.93]],"batl":[[0,4.3,2.65],[1,4.9,128.15],[2,4.9,0]],"ltp":3.35,"tv":3399.99,"id":9629296},{"batb":[[0,1.33,202.13],[1,1.32,167.08],[2,1.31,198.07]],"batl":[[1,1.55,92.67],[2,1.56,78.84]],"ltp":1.46,"tv":2130.15,"id":12343905}]}]}
{"op":"mcm","clk":"4231744300","pt":1631547611473,"mc":[{"id":"1.187560634","rc":[{"batl":[[1,1.57,46.5],[2,44,7.22]],"ltp":1.46,"tv":2130.15,"id":12343905}]}]}
{"op":"mcm","clk":"4231744409","pt":1631547612580,"mc":[{"id":"1.187560634","rc":[{"batl":[[1,4.9,0]],"ltp":3.35,"tv":3399.99,"id":9629296}]}]}
{"op":"mcm","clk":"4231744438","pt":1631547612847,"mc":[{"id":"1.187560634","rc":[{"batl":[[0,1.57,46.5],[1,44,7.22],[2,44,0]],"ltp":1.46,"tv":2130.15,"id":12343905}]}]}
{"op":"mcm","clk":"4231744615","pt":1631547614674,"mc":[{"id":"1.187560634","rc":[{"batb":[[0,3.75,5.37],[1,3.65,63.02],[2,3.6,4.12]],"batl":[[0,3.9,6.51],[1,4,60.06],[2,4.1,36.6]],"ltp":3.35,"tv":3399.99,"id":9629296},{"batl":[[0,1.37,209.8],[1,1.38,129.26],[2,1.43,522.58]],"ltp":1.46,"tv":2130.15,"id":12343905}]}]}
{"op":"mcm","clk":"4231744661","pt":1631547615149,"mc":[{"id":"1.187560634","rc":[{"batl":[[2,4.1,7.32]],"ltp":3.35,"tv":3399.99,"id":9629296}]}]}
{"op":"mcm","clk":"4231745073","pt":1631547620824,"mc":[{"id":"1.187560634","rc":[{"batl":[[2,1.41,58.5]],"ltp":1.46,"tv":2130.15,"id":12343905}]}]}
{"op":"mcm","clk":"4231745610","pt":1631547627722,"mc":[{"id":"1.187560634","rc":[{"trd":[[3.9,13.06]],"batl":[[0,4,60.06],[1,4.1,7.32],[2,4.2,3.66]],"ltp":3.9,"tv":3406.5,"id":9629296},{"trd":[[1.34,26.47]],"batl":[[0,1.34,81.05],[1,1.37,209.8],[2,1.38,129.26]],"ltp":1.34,"tv":2149.1,"id":12343905}],"tv":5555.6}]}
{"op":"mcm","clk":"4231745690","pt":1631547628819,"mc":[{"id":"1.187560634","rc":[{"batl":[[0,1.37,209.8],[1,1.38,129.26],[2,1.41,58.5]],"ltp":1.34,"tv":2149.1,"id":12343905}]}]}
{"op":"mcm","clk":"4231745826","pt":1631547630534,"mc":[{"id":"1.187560634","rc":[{"trd":[[1.37,203.24]],"batl":[[0,1.37,208.73]],"ltp":1.37,"tv":2151.24,"id":12343905}],"tv":5557.74}]}
{"op":"mcm","clk":"4231746410","pt":1631547637530,"mc":[{"id":"1.187560634","rc":[{"batb":[[0,3.4,29.45],[1,3.3,3.98],[2,3.25,3.77]],"batl":[[0,4.3,2.65],[1,4.4,2.39],[2,4.5,2.67]],"ltp":3.9,"tv":3406.5,"id":9629296}]}]}
{"op":"mcm","clk":"4231746449","pt":1631547638000,"mc":[{"id":"1.187560634","rc":[{"batb":[[0,3.3,3.98],[1,3,36.24],[2,2.52,387.12]],"batl":[[0,4.5,2.67],[1,6,107.75],[2,4.5,0]],"ltp":3.9,"tv":3406.5,"id":9629296},{"batb":[[0,1.29,96.81],[1,1.27,126.74],[2,1.15,357.95]],"batl":[[0,1.43,52.5],[1,44,7.22],[2,1.41,0]],"ltp":1.37,"tv":2151.24,"id":12343905}]}]}
{"op":"mcm","clk":"4231746770","pt":1631547642013,"mc":[{"id":"1.187560634","rc":[{"batl":[[1,6,0]],"ltp":3.9,"tv":3406.5,"id":9629296},{"batl":[[1,1.47,58.05],[2,44,7.22]],"ltp":1.37,"tv":2151.24,"id":12343905}]}]}
{"op":"mcm","clk":"4231746901","pt":1631547643527,"mc":[{"id":"1.187560634","rc":[{"batb":[[0,1.35,106.17],[1,1.34,153.35],[2,1.29,96.81]],"batl":[[0,1.38,137.36],[1,1.39,125.87],[2,1.43,52.5]],"ltp":1.37,"tv":2151.24,"id":12343905}]}]}
{"op":"mcm","clk":"4231746999","pt":1631547644826,"mc":[{"id":"1.187560634","rc":[{"batb":[[0,3.4,3.81],[1,3.3,3.98],[2,3,36.24]],"batl":[[0,4.3,2.45],[1,4.5,2.67]],"ltp":3.9,"tv":3406.5,"id":9629296},{"batb":[[2,1.31,80.79]],"batl":[[2,1.41,56.5]],"ltp":1.37,"tv":2151.24,"id":12343905}]}]}
{"op":"mcm","clk":"4231747118","pt":1631547646436,"mc":[{"id":"1.187560634","rc":[{"batl":[[2,5.5,116.76]],"ltp":3.9,"tv":3406.5,"id":9629296}]}]}
{"op":"mcm","clk":"4231747327","pt":1631547649512,"mc":[{"id":"1.187560634","rc":[{"batb":[[0,1.31,80.79],[1,1.29,96.81],[2,1.27,126.74]],"batl":[[0,1.41,56.5],[1,1.43,52.5],[2,1.47,58.05]],"ltp":1.37,"tv":2151.24,"id":12343905}]}]}
{"op":"mcm","clk":"4231747373","pt":1631547650137,"mc":[{"id":"1.187560634","rc":[{"batb":[[0,3.3,3.98],[1,3,36.24],[2,2.52,387.12]],"batl":[[0,4.5,2.67],[1,5.5,116.76],[2,5.5,0]],"ltp":3.9,"tv":3406.5,"id":9629296},{"batb":[[0,1.29,96.81],[1,1.27,126.74],[2,1.15,357.95]],"batl":[[0,1.43,52.5],[1,1.47,58.05],[2,44,7.22]],"ltp":1.37,"tv":2151.24,"id":12343905}]}]}
{"op":"mcm","clk":"4231747584","pt":1631547652658,"mc":[{"id":"1.187560634","rc":[{"batb":[[0,1.29,327.15],[1,1.28,197.72],[2,1.27,126.74]],"batl":[[1,1.44,100.75],[2,1.45,105.08]],"ltp":1.37,"tv":2151.24,"id":12343905}]}]}
{"op":"mcm","clk":"4231747740","pt":1631547653612,"mc":[{"id":"1.187560634","rc":[{"batl":[[0,1.35,81],[1,1.43,52.5],[2,1.44,100.75]],"ltp":1.37,"tv":2151.24,"id":12343905}]}]}
{"op":"mcm","clk":"4231747857","pt":1631547654433,"mc":[{"id":"1.187560634","rc":[{"batl":[[0,1.43,52.5],[1,1.44,100.75],[2,1.45,105.08]],"ltp":1.37,"tv":2151.24,"id":12343905}]}]}
{"op":"mcm","clk":"4231748021","pt":1631547655625,"mc":[{"id":"1.187560634","rc":[{"batl":[[1,5.5,0]],"ltp":3.9,"tv":3406.5,"id":9629296},{"batb":[[0,1.29,96.81],[1,1.27,126.74],[2,1.15,357.95]],"ltp":1.37,"tv":2151.24,"id":12343905}]}]}
{"op":"mcm","clk":"4231748401","pt":1631547657641,"mc":[{"id":"1.187560634","rc":[{"batb":[[0,3.35,7.6],[1,3.3,3.98],[2,3.15,73.74]],"batl":[[0,3.5,3.99],[1,4,309.03],[2,4.5,2.67]],"ltp":3.9,"tv":3406.5,"id":9629296},{"batb":[[0,1.4,2711.02],[1,1.39,195.68],[2,1.38,189.92]],"ltp":1.37,"tv":2151.24,"id":12343905}]}]}
{"op":"mcm","clk":"4231748547","pt":1631547658638,"mc":[{"id":"1.187560634","rc":[{"batb":[[0,1.41,76.4],[1,1.4,352.52],[2,1.39,97.84]],"ltp":1.37,"tv":2151.24,"id":12343905}]}]}
{"op":"mcm","clk":"4231748938","pt":1631547662537,"mc":[{"id":"1.187560634","rc":[{"trd":[[3.35,30.16]],"batb":[[0,3.35,1.31]],"ltp":3.35,"tv":3419.08,"id":9629296}],"tv":5570.32}]}
{"op":"mcm","clk":"4231749083","pt":1631547664233,"mc":[{"id":"1.187560634","rc":[{"batl":[[1,3.9,2.95],[2,4,309.03]],"ltp":3.35,"tv":3419.08,"id":9629296}]}]}
{"op":"mcm","clk":"4231749536","pt":1631547668338,"mc":[{"id":"1.187560634","rc":[{"trd":[[1.41,155.14]],"batb":[[0,1.4,352.52],[1,1.39,97.84],[2,1.38,218.67]],"batl":[[0,1.41,3.6],[1,1.43,52.5],[2,1.44,100.75]],"ltp":1.41,"tv":2304.04,"id":12343905}],"tv":5723.12}]}
{"op":"mcm","clk":"4231749637","pt":1631547669633,"mc":[{"id":"1.187560634","rc":[{"batb":[[0,1.4,134.21]],"batl":[[0,1.43,52.5],[1,1.44,100.75],[2,1.45,105.08]],"ltp":1.41,"tv":2304.04,"id":12343905}]}]}
{"op":"mcm","clk":"4231749776","pt":1631547671324,"mc":[{"id":"1.187560634","rc":[{"trd":[[1.43,1.86]],"batb":[[0,1.4,168.65],[1,1.39,227.52]],"batl":[[0,1.43,51.57],[1,1.44,142.11]],"ltp":1.43,"tv":2305.9,"id":12343905}],"tv":5724.98}]}
{"op":"mcm","clk":"4231749897","pt":1631547672735,"mc":[{"id":"1.187560634","rc":[{"batb":[[0,3.3,3.98],[1,3.15,73.74],[2,3,36.24]],"batl":[[0,3.9,2.95],[1,4,309.03],[2,4.1,2.85]],"ltp":3.35,"tv":3419.08,"id":9629296},{"batb":[[0,1.4,158.67]],"ltp":1.43,"tv":2305.9,"id":12343905}]}]}
{"op":"mcm","clk":"4231750159","pt":1631547675636,"mc":[{"id":"1.187560634","rc":[{"batb":[[0,3.3,10.84]],"ltp":3.35,"tv":3419.08,"id":9629296},{"batb":[[0,1.41,19.55],[1,1.4,158.67],[2,1.39,227.52]],"ltp":1.43,"tv":2305.9,"id":12343905}]}]}
{"op":"mcm","clk":"4231751253","pt":1631547682135,"mc":[{"id":"1.187560634","rc":[{"batb":[[0,2.72,4.84],[1,2.58,21.72],[2,2.52,387.12]],"batl":[[0,4.2,2.33],[1,4.5,2.67],[2,4.9,128.15]],"ltp":3.35,"tv":3419.08,"id":9629296},{"batb":[[0,1.38,40],[1,1.32,180.98],[2,1.29,96.81]],"batl":[[0,1.58,37.75],[1,44,7.22],[2,1.45,0]],"ltp":1.43,"tv":2305.9,"id":12343905}]}]}
{"op":"mcm","clk":"4231752009","pt":1631547685653,"mc":[{"id":"1.187560634","rc":[{"batb":[[1,1.34,133.17],[2,1.33,160.23]],"ltp":1.43,"tv":2305.9,"id":12343905}]}]}
{"op":"mcm","clk":"4231752244","pt":1631547686934,"mc":[{"id":"1.187560634","rc":[{"batl":[[2,4.9,0]],"ltp":3.35,"tv":3419.08,"id":9629296}]}]}
{"op":"mcm","clk":"4231752367","pt":1631547688551,"mc":[{"id":"1.187560634","rc":[{"batl":[[0,3.85,6.36],[1,4.2,2.33],[2,4.5,2.67]],"ltp":3.35,"tv":3419.08,"id":9629296},{"trd":[[1.38,80]],"batb":[[0,1.34,318.12],[1,1.33,160.23],[2,1.32,180.98]],"batl":[[0,1.36,29.42],[1,1.37,142.23],[2,1.38,239.44]],"ltp":1.38,"tv":2385.9,"id":12343905}],"tv":5804.98}]}
{"op":"mcm","clk":"4231752431","pt":1631547689484,"mc":[{"id":"1.187560634","rc":[{"batb":[[0,3.35,27.26],[1,2.94,38],[2,2.72,4.84]],"batl":[[1,4,7.5],[2,4.1,3.76]],"ltp":3.35,"tv":3419.08,"id":9629296},{"batl":[[2,1.38,152.48]],"ltp":1.38,"tv":2385.9,"id":12343905}]}]}
{"op":"mcm","clk":"4231752689","pt":1631547693175,"mc":[{"id":"1.187560634","rc":[{"trd":[[3.75,9.75]],"ltp":3.75,"tv":3428.83,"id":9629296},{"trd":[[1.36,69.04]],"batl":[[0,1.36,2.54]],"ltp":1.36,"tv":2412.78,"id":12343905}],"tv":5841.61}]}
{"op":"mcm","clk":"4231752842","pt":1631547695152,"mc":[{"id":"1.187560634","rc":[{"batb":[[0,3.35,30.93],[1,3.25,3.93],[2,2.94,38]],"ltp":3.75,"tv":3428.83,"id":9629296}]}]}
{"op":"mcm","clk":"4231753955","pt":1631547710388,"mc":[{"id":"1.187560634","rc":[{"batb":[[0,3.25,3.93],[1,2.94,38],[2,2.52,387.12]],"batl":[[0,4.4,2.34],[1,4.5,2.67],[2,5.5,116.76]],"ltp":3.75,"tv":3428.83,"id":9629296},{"batb":[[0,1.3,83.58],[1,1.29,96.81],[2,1.28,122.88]],"batl":[[0,1.44,62.83],[1,44,7.22],[2,1.38,0]],"ltp":1.36,"tv":2412.78,"id":12343905}]}]}
{"op":"mcm","clk":"4231753984","pt":1631547710705,"mc":[{"id":"1.187560634","rc":[{"batl":[[1,5.5,116.76],[2,5.5,0]],"ltp":3.75,"tv":3428.83,"id":9629296},{"batb":[[1,1.28,122.88],[2,1.15,357.95]],"ltp":1.36,"tv":2412.78,"id":12343905}]}]}
{"op":"mcm","clk":"4231754198","pt":1631547713575,"mc":[{"id":"1.187560634","rc":[{"batb":[[0,3.35,3.47],[1,3.25,3.93],[2,2.94,38]],"batl":[[0,4.2,2.63],[1,4.4,2.34],[2,5.5,116.76]],"ltp":3.75,"tv":3428.83,"id":9629296},{"batb":[[0,1.32,78.39],[1,1.3,83.58],[2,1.28,122.88]],"batl":[[0,1.42,61.75],[1,1.44,62.83],[2,44,7.22]],"ltp":1.36,"tv":2412.78,"id":12343905}]}]}
{"op":"mcm","clk":"4231754227","pt":1631547713884,"mc":[{"id":"1.187560634","rc":[{"batb":[[0,3.25,3.93],[1,2.94,38],[2,2.52,387.12]],"batl":[[0,4.4,2.34],[1,5.5,116.76],[2,5.5,0]],"ltp":3.75,"tv":3428.83,"id":9629296},{"batb":[[0,1.3,83.58],[1,1.28,122.88],[2,1.15,357.95]],"batl":[[0,1.44,62.83],[1,44,7.22],[2,44,0]],"ltp":1.36,"tv":2412.78,"id":12343905}]}]}
{"op":"mcm","clk":"4231754351","pt":1631547715602,"mc":[{"id":"1.187560634","rc":[{"batl":[[0,3.9,19.65],[1,3.95,146.82],[2,4.4,2.34]],"ltp":3.75,"tv":3428.83,"id":9629296},{"batb":[[0,1.35,21.07],[1,1.3,83.58],[2,1.28,122.88]],"batl":[[0,1.37,20.5],[1,1.44,62.83],[2,44,7.22]],"ltp":1.36,"tv":2412.78,"id":12343905}]}]}
{"op":"mcm","clk":"4231754377","pt":1631547715903,"mc":[{"id":"1.187560634","rc":[{"batl":[[0,4.4,2.34],[1,5.5,116.76],[2,4.4,0]],"ltp":3.75,"tv":3428.83,"id":9629296},{"batb":[[0,1.35,190.05],[1,1.34,155.06],[2,1.3,83.58]],"batl":[[0,1.39,186.78],[1,1.4,121.81],[2,1.44,62.83]],"ltp":1.36,"tv":2412.78,"id":12343905}]}]}
{"op":"mcm","clk":"4231754462","pt":1631547717106,"mc":[{"id":"1.187560634","rc":[{"batb":[[0,3.35,3.67],[1,3.25,3.93],[2,2.94,38]],"batl":[[0,4.2,2.63],[1,4.4,2.34],[2,5.5,116.76]],"ltp":3.75,"tv":3428.83,"id":9629296},{"batb":[[2,1.32,72.89]],"batl":[[2,1.42,53.75]],"ltp":1.36,"tv":2412.78,"id":12343905}]}]}
{"op":"mcm","clk":"4231754834","pt":1631547722515,"mc":[{"id":"1.187560634","rc":[{"batb":[[0,3.25,3.93],[1,2.94,38],[2,2.52,387.12]],"batl":[[0,4.4,2.34],[1,5.5,116.76],[2,5.5,0]],"ltp":3.75,"tv":3428.83,"id":9629296},{"batb":[[0,1.3,83.58],[1,1.28,122.88],[2,1.15,357.95]],"batl":[[0,1.44,62.83],[1,44,7.22],[2,1.42,0]],"ltp":1.36,"tv":2412.78,"id":12343905}]}]}
{"op":"mcm","clk":"4231755047","pt":1631547725414,"mc":[{"id":"1.187560634","rc":[{"batl":[[1,1.45,129.96],[2,1.46,102.24]],"ltp":1.36,"tv":2412.78,"id":12343905}]}]}
{"op":"mcm","clk":"4231755078","pt":1631547725785,"mc":[{"id":"1.187560634","rc":[{"batb":[[0,3.35,4.27],[1,3.25,3.93],[2,2.94,38]],"batl":[[0,4.2,2.78],[1,4.4,2.34],[2,5.5,116.76]],"ltp":3.75,"tv":3428.83,"id":9629296},{"batb":[[0,1.32,77.89],[1,1.3,83.58],[2,1.28,122.88]],"batl":[[0,1.42,54.75],[1,1.44,62.83],[2,1.45,129.96]],"ltp":1.36,"tv":2412.78,"id":12343905}]}]}
{"op":"mcm","clk":"4231755177","pt":1631547726884,"mc":[{"id":"1.187560634","rc":[{"batb":[[0,3.25,3.93],[1,2.94,38],[2,2.52,387.12]],"batl":[[0,4.4,2.34],[1,4.4,0],[2,5.5,0]],"ltp":3.75,"tv":3428.83,"id":9629296},{"batb":[[0,1.3,83.58],[1,1.28,122.88],[2,1.15,357.95]],"batl":[[0,1.44,62.83],[1,1.45,129.96],[2,1.46,102.24]],"ltp":1.36,"tv":2412.78,"id":12343905}]}]}
{"op":"mcm","clk":"4231755313","pt":1631547728602,"mc":[{"id":"1.187560634","rc":[{"batb":[[0,3.25,10.97],[1,3.1,77.95],[2,2.94,38]],"batl":[[0,3.5,48.79],[1,4.4,2.34]],"ltp":3.75,"tv":3428.83,"id":9629296},{"batb":[[0,1.42,17.93],[1,1.41,315.11],[2,1.4,344.61]],"ltp":1.36,"tv":2412.78,"id":12343905}]}]}
{"op":"mcm","clk":"4231755433","pt":1631547730111,"mc":[{"id":"1.187560634","rc":[{"batl":[[2,4.9,128.15]],"ltp":3.75,"tv":3428.83,"id":9629296}]}]}
{"op":"mcm","clk":"4231755705","pt":1631547733598,"mc":[{"id":"1.187560634","rc":[{"trd":[[3.25,23.14]],"batb":[[0,3.1,77.95],[1,2.94,38],[2,2.56,22.23]],"ltp":3.25,"tv":3451.97,"id":9629296},{"trd":[[1.44,2.71]],"batl":[[0,1.44,60.12]],"ltp":1.44,"tv":2415.49,"id":12343905}],"tv":5867.46}]}
{"op":"mcm","clk":"4231755789","pt":1631547734793,"mc":[{"id":"1.187560634","rc":[{"batb":[[2,2.8,4.43]],"batl":[[1,3.9,2.75],[2,4.2,2.93]],"ltp":3.25,"tv":3451.97,"id":9629296}]}]}
{"op":"mcm","clk":"4231756125","pt":1631547740129,"mc":[{"id":"1.187560634","rc":[{"batb":[[1,1.41,158.31]],"ltp":1.44,"tv":2415.49,"id":12343905}]}]}
{"op":"mcm","clk":"4231756366","pt":1631547743238,"mc":[{"id":"1.187560634","rc":[{"batb":[[0,1.41,158.31],[1,1.4,344.61],[2,1.39,175.06]],"ltp":1.44,"tv":2415.49,"id":12343905}]}]}
{"op":"mcm","clk":"4231756582","pt":1631547746246,"mc":[{"id":"1.187560634","rc":[{"batb":[[0,3.2,5.92],[1,3.1,77.95],[2,2.94,38]],"batl":[[0,3.3,5.66],[1,3.5,48.79],[2,3.9,2.75]],"ltp":3.25,"tv":3451.97,"id":9629296}]}]}
{"op":"mcm","clk":"4231757213","pt":1631547754649,"mc":[{"id":"1.187560634","rc":[{"batb":[[0,2.94,38],[1,2.68,5.11],[2,2.66,5.28]],"batl":[[0,3.9,2.75],[1,4.2,2.93],[2,4.4,2.34]],"ltp":3.25,"tv":3451.97,"id":9629296},{"batb":[[1,1.4,125.49],[2,1.39,80.78]],"batl":[[0,1.45,129.96],[1,1.46,102.24],[2,1.59,42.5]],"ltp":1.44,"tv":2415.49,"id":12343905}]}]}
{"op":"mcm","clk":"4231757249","pt":1631547755061,"mc":[{"id":"1.187560634","rc":[{"batb":[[0,2.66,5.28],[1,2.56,22.23],[2,2.52,387.12]],"batl":[[0,4.2,2.93],[1,4.4,2.34],[2,4.9,128.15]],"ltp":3.25,"tv":3451.97,"id":9629296},{"batb":[[0,1.33,101.66],[1,1.32,90.14],[2,1.3,83.58]],"batl":[[0,1.6,43.31],[1,44,7.22],[2,1.59,0]],"ltp":1.44,"tv":2415.49,"id":12343905}]}]}
{"op":"mcm","clk":"4231757438","pt":1631547757654,"mc":[{"id":"1.187560634","rc":[{"batb":[[0,2.74,4.79],[1,2.66,5.28],[2,2.62,5.04]],"ltp":3.25,"tv":3451.97,"id":9629296},{"batl":[[0,1.57,44.5],[1,1.6,43.31],[2,1.61,41.5]],"ltp":1.44,"tv":2415.49,"id":12343905}]}]}
{"op":"mcm","clk":"4231757514","pt":1631547758550,"mc":[{"id":"1.187560634","rc":[{"batb":[[0,2.66,5.28],[1,2.62,5.04],[2,2.56,22.23]],"ltp":3.25,"tv":3451.97,"id":9629296},{"batb":[[0,1.35,97.67],[1,1.34,153.87],[2,1.33,101.66]],"batl":[[0,1.57,72.96],[1,1.58,75.5],[2,1.6,43.31]],"ltp":1.44,"tv":2415.49,"id":12343905}]}]}
{"op":"mcm","clk":"4231757843","pt":1631547762850,"mc":[{"id":"1.187560634","rc":[{"batb":[[0,1.33,101.66],[1,1.32,90.14],[2,1.3,83.58]],"ltp":1.44,"tv":2415.49,"id":12343905}]}]}
{"op":"mcm","clk":"4231757972","pt":1631547764661,"mc":[{"id":"1.187560634","rc":[{"batb":[[0,2.78,4.66],[1,2.66,5.28],[2,2.62,5.04]],"batl":[[2,4.9,0]],"ltp":3.25,"tv":3451.97,"id":9629296},{"batl":[[0,1.56,41.17],[1,1.57,72.96],[2,1.58,75.5]],"ltp":1.44,"tv":2415.49,"id":12343905}]}]}
{"op":"mcm","clk":"4231758039","pt":1631547765661,"mc":[{"id":"1.187560634","rc":[{"batb":[[0,2.66,5.28],[1,2.62,5.04],[2,2.56,22.23]],"batl":[[0,2.84,11.49],[1,2.92,1130.1],[2,2.94,25.68]],"ltp":3.25,"tv":3451.97,"id":9629296},{"batb":[[0,1.55,129.04],[1,1.33,101.66],[2,1.32,90.14]],"batl":[[0,1.57,72.96],[1,1.58,89.52],[2,1.6,43.31]],"ltp":1.44,"tv":2415.49,"id":12343905}]}]}
{"op":"mcm","clk":"4231758112","pt":1631547766657,"mc":[{"id":"1.187560634","rc":[{"batl":[[1,2.9,2],[2,2.92,10.28]],"ltp":3.25,"tv":3451.97,"id":9629296},{"batb":[[1,1.53,108.44],[2,1.52,88.26]],"batl":[[1,1.58,184.46],[2,1.59,47.46]],"ltp":1.44,"tv":2415.49,"id":12343905}]}]}
{"op":"mcm","clk":"4231758136","pt":1631547766969,"mc":[{"id":"1.187560634","rc":[{"batl":[[1,1.58,108.5],[2,1.59,9.5]],"ltp":1.44,"tv":2415.49,"id":12343905}]}]}
{"op":"mcm","clk":"4231758722","pt":1631547774598,"mc":[{"id":"1.187560634","rc":[{"batb":[[1,1.53,97.88]],"ltp":1.44,"tv":2415.49,"id":12343905}]}]}
{"op":"mcm","clk":"4231758943","pt":1631547777573,"mc":[{"id":"1.187560634","rc":[{"batl":[[0,1.57,83.26]],"ltp":1.44,"tv":2415.49,"id":12343905}]}]}
{"op":"mcm","clk":"4231759945","pt":1631547790592,"mc":[{"id":"1.187560634","rc":[{"trd":[[1.57,166.52]],"batb":[[0,1.57,16.74],[1,1.55,129.04],[2,1.53,97.88]],"batl":[[0,1.58,108.5],[1,1.59,9.5],[2,1.6,52.81]],"ltp":1.57,"tv":2582.01,"id":12343905}],"tv":6033.98}]}
{"op":"mcm","clk":"4231760213","pt":1631547793620,"mc":[{"id":"1.187560634","rc":[{"batb":[[0,2.56,22.23],[1,2.24,6.27],[2,2.14,43.56]],"batl":[[0,3.45,3.7],[1,3.8,3.02],[2,3.9,160.59]],"ltp":3.25,"tv":3451.97,"id":9629296},{"batb":[[1,1.51,58.8],[2,1.41,66.89]],"batl":[[0,1.8,32.27],[1,1.85,28.3],[2,1.87,28.5]],"ltp":1.57,"tv":2582.01,"id":12343905}]}]}
{"op":"mcm","clk":"4231760271","pt":1631547794309,"mc":[{"id":"1.187560634","rc":[{"batb":[[0,2.14,43.56],[1,2.04,399.94],[2,1.9,16.76]],"ltp":3.25,"tv":3451.97,"id":9629296},{"batb":[[1,1.41,66.89],[2,1.4,79.69]],"batl":[[0,1.85,28.3],[1,1.87,28.5],[2,44,7.22]],"ltp":1.57,"tv":2582.01,"id":12343905}]}]}
{"op":"mcm","clk":"4231760444","pt":1631547796508,"mc":[{"id":"1.187560634","rc":[{"batb":[[1,1.42,182.29],[2,1.41,188.34]],"batl":[[0,1.8,98.38],[1,1.82,93.42],[2,1.85,28.3]],"ltp":1.57,"tv":2582.01,"id":12343905}]}]}
{"op":"mcm","clk":"4231760483","pt":1631547797000,"mc":[{"id":"1.187560634","rc":[{"batb":[[0,2.16,7.78],[1,2.14,43.56],[2,2.04,399.94]],"batl":[[0,3.8,3.02],[1,3.9,160.59],[2,4.2,2.93]],"ltp":3.25,"tv":3451.97,"id":9629296},{"batb":[[1,1.4,79.69],[2,1.36,70.18]],"batl":[[0,1.85,28.3],[1,1.87,28.5],[2,44,7.22]],"ltp":1.57,"tv":2582.01,"id":12343905}]}]}
{"op":"mcm","clk":"4231760664","pt":1631547799627,"mc":[{"id":"1.187560634","rc":[{"batl":[[0,2.8,18.67],[1,3.8,3.02],[2,3.9,160.59]],"ltp":3.25,"tv":3451.97,"id":9629296},{"batb":[[0,1.57,123.29],[1,1.56,99.97],[2,1.4,79.69]],"batl":[[0,1.61,19.5],[1,1.62,111.18],[2,1.63,67.15]],"ltp":1.57,"tv":2582.01,"id":12343905}]}]}
{"op":"mcm","clk":"4231760714","pt":1631547800203,"mc":[{"id":"1.187560634","rc":[{"batb":[[0,2.28,6.66],[1,2.16,7.78],[2,2.14,43.56]],"batl":[[0,3.45,3.9]],"ltp":3.25,"tv":3451.97,"id":9629296},{"batb":[[1,1.56,79.64],[2,1.41,53.89]],"batl":[[0,1.62,111.18],[1,1.63,67.15],[2,1.78,32.75]],"ltp":1.57,"tv":2582.01,"id":12343905}]}]}
{"op":"mcm","clk":"4231761294","pt":1631547807528,"mc":[{"id":"1.187560634","rc":[{"batb":[[0,2.16,7.78],[1,2.14,43.56],[2,2.04,399.94]],"batl":[[0,3.25,4.8],[1,3.45,3.9],[2,3.8,3.02]],"ltp":3.25,"tv":3451.97,"id":9629296},{"batb":[[0,1.57,16.74],[1,1.41,53.89],[2,1.4,79.69]],"batl":[[0,1.85,28.3],[1,1.87,28.5],[2,44,7.22]],"ltp":1.57,"tv":2582.01,"id":12343905}]}]}
{"op":"mcm","clk":"4231761380","pt":1631547808526,"mc":[{"id":"1.187560634","rc":[{"batl":[[1,3.8,3.02],[2,3.9,160.59]],"ltp":3.25,"tv":3451.97,"id":9629296},{"batb":[[0,1.4,79.69],[1,1.36,70.18],[2,1.32,90.14]],"ltp":1.57,"tv":2582.01,"id":12343905}]}]}
{"op":"mcm","clk":"4231761460","pt":1631547809627,"mc":[{"id":"1.187560634","rc":[{"batb":[[0,1.42,182.29],[1,1.41,121.45],[2,1.4,79.69]],"batl":[[0,1.8,98.38],[1,1.82,93.42],[2,1.85,28.3]],"ltp":1.57,"tv":2582.01,"id":12343905}]}]}
{"op":"mcm","clk":"4231761597","pt":1631547811420,"mc":[{"id":"1.187560634","rc":[{"batb":[[0,1.62,16.74],[1,1.42,182.29],[2,1.41,121.45]],"ltp":1.57,"tv":2582.01,"id":12343905}]}]}
{"op":"mcm","clk":"4231761629","pt":1631547811740,"mc":[{"id":"1.187560634","rc":[{"batl":[[1,3.45,3.5],[2,3.8,3.02]],"ltp":3.25,"tv":3451.97,"id":9629296},{"batb":[[2,1.41,181.34]],"ltp":1.57,"tv":2582.01,"id":12343905}]}]}
{"op":"mcm","clk":"4231762218","pt":1631547820636,"mc":[{"id":"1.187560634","rc":[{"batb":[[0,2.28,6.41],[1,2.16,7.78],[2,2.14,43.56]],"batl":[[1,3.8,3.02],[2,3.9,160.59]],"ltp":3.25,"tv":3451.97,"id":9629296},{"batb":[[1,1.4,79.69],[2,1.36,70.18]],"batl":[[0,1.78,27.75],[1,1.8,98.38],[2,1.82,93.42]],"ltp":1.57,"tv":2582.01,"id":12343905}]}]}
{"op":"mcm","clk":"4231762253","pt":1631547821155,"mc":[{"id":"1.187560634","rc":[{"batb":[[0,2.16,7.78],[1,2.14,43.56],[2,1.9,16.76]],"batl":[[2,3.9,0]],"ltp":3.25,"tv":3451.97,"id":9629296},{"batl":[[0,1.8,98.38],[1,1.82,93.42],[2,1.85,28.3]],"ltp":1.57,"tv":2582.01,"id":12343905}]}]}
{"op":"mcm","clk":"4231762366","pt":1631547822655,"mc":[{"id":"1.187560634","rc":[{"batl":[[0,2.32,1304.64],[1,2.38,63.04],[2,2.4,31.52]],"ltp":3.25,"tv":3451.97,"id":9629296},{"batb":[[0,1.76,15.14],[1,1.75,114.28],[2,1.62,16.74]],"batl":[[0,1.8,107.33]],"ltp":1.57,"tv":2582.01,"id":12343905}]}]}
{"op":"mcm","clk":"4231762447","pt":1631547823556,"mc":[{"id":"1.187560634","rc":[{"batb":[[0,2.24,66.96],[1,2.22,33.48],[2,2.2,33.48]],"batl":[[0,2.38,37.82],[1,2.4,18.91],[2,2.42,139.6]],"ltp":3.25,"tv":3451.97,"id":9629296},{"batb":[[1,1.75,68.57],[2,1.74,73.61]],"ltp":1.57,"tv":2582.01,"id":12343905}]}]}
{"op":"mcm","clk":"4231762504","pt":1631547824132,"mc":[{"id":"1.187560634","rc":[{"batb":[[0,2.24,13.4],[1,2.22,6.7],[2,2.2,6.7]],"ltp":3.25,"tv":3451.97,"id":9629296}]}]}
{"op":"mcm","clk":"4231762710","pt":1631547826636,"mc":[{"id":"1.187560634","rc":[{"trd":[[1.76,39.35]],"batb":[[0,1.75,68.57],[1,1.74,73.61],[2,1.72,111.19]],"batl":[[0,1.76,42.84],[1,1.8,107.33],[2,1.82,93.42]],"ltp":1.76,"tv":2612.29,"id":12343905}],"tv":6064.26}]}
{"op":"mcm","clk":"4231762781","pt":1631547827528,"mc":[{"id":"1.187560634","rc":[{"batl":[[0,2.26,6.9],[1,2.38,37.82],[2,2.4,18.91]],"ltp":3.25,"tv":3451.97,"id":9629296},{"batl":[[0,1.8,107.33],[1,1.82,93.42],[2,1.85,28.3]],"ltp":1.76,"tv":2612.29,"id":12343905}]}]}
{"op":"mcm","clk":"4231762797","pt":1631547827738,"mc":[{"id":"1.187560634","rc":[{"batl":[[0,2.38,37.82],[1,2.4,18.91],[2,2.42,139.6]],"ltp":3.25,"tv":3451.97,"id":9629296}]}]}
{"op":"mcm","clk":"4231763081","pt":1631547831541,"mc":[{"id":"1.187560634","rc":[{"batb":[[0,2.26,6.77],[1,2.24,13.4],[2,2.22,6.7]],"ltp":3.25,"tv":3451.97,"id":9629296}]}]}
{"op":"mcm","clk":"4231763413","pt":1631547836574,"mc":[{"id":"1.187560634","rc":[{"batl":[[0,1.8,98.38]],"ltp":1.76,"tv":2612.29,"id":12343905}]}]}
{"op":"mcm","clk":"4231763591","pt":1631547839571,"mc":[{"id":"1.187560634","rc":[{"batb":[[1,1.74,86.45]],"batl":[[0,1.78,12.17],[1,1.8,98.38],[2,1.82,93.42]],"ltp":1.76,"tv":2612.29,"id":12343905}]}]}
{"op":"mcm","clk":"4231764312","pt":1631547849398,"mc":[{"id":"1.187560634","rc":[{"trd":[[1.78,24.34],[1.8,172.87]],"batl":[[0,1.8,19.55],[1,1.82,93.42],[2,1.85,28.3]],"ltp":1.8,"tv":2794.29,"id":12343905}],"tv":6246.26}]}
{"op":"mcm","clk":"4231764433","pt":1631547850275,"mc":[{"id":"1.187560634","rc":[{"trd":[[1.75,1.06]],"batb":[[0,1.75,68.04],[1,1.74,12.84],[2,1.7,37.83]],"batl":[[0,1.85,28.3],[1,1.86,160.8],[2,1.87,28.5]],"ltp":1.75,"tv":2795.35,"id":12343905}],"tv":6247.32}]}
{"op":"mcm","clk":"4231764798","pt":1631547852999,"mc":[{"id":"1.187560634","rc":[{"batb":[[0,1.75,132.68],[2,1.73,108.84]],"batl":[[0,1.81,101.81],[1,1.83,91.66],[2,1.85,28.3]],"ltp":1.75,"tv":2795.35,"id":12343905}]}]}
{"op":"mcm","clk":"4231765000","pt":1631547854903,"mc":[{"id":"1.187560634","rc":[{"trd":[[2.26,40.54]],"batb":[[0,2.26,4.77]],"ltp":2.26,"tv":3455.97,"id":9629296}],"tv":6251.33}]}
{"op":"mcm","clk":"4231765643","pt":1631547859597,"mc":[{"id":"1.187560634","rc":[{"batb":[[1,1.73,108.84],[2,1.7,37.83]],"ltp":1.75,"tv":2795.35,"id":12343905}]}]}
{"op":"mcm","clk":"4231765671","pt":1631547859705,"mc":[{"id":"1.187560634","rc":[{"batb":[[0,2.28,18.77],[1,2.26,4.77],[2,2.24,13.4]],"ltp":2.26,"tv":3455.97,"id":9629296}]}]}
{"op":"mcm","clk":"4231766034","pt":1631547862600,"mc":[{"id":"1.187560634","rc":[{"batb":[[0,1.76,12.32],[1,1.75,132.68],[2,1.73,108.84]],"batl":[[0,1.8,11.71],[1,1.81,101.81],[2,1.83,91.66]],"ltp":1.75,"tv":2795.35,"id":12343905}]}]}
{"op":"mcm","clk":"4231766459","pt":1631547865917,"mc":[{"id":"1.187560634","rc":[{"trd":[[2.28,11.04]],"batb":[[0,2.28,13.25]],"ltp":2.28,"tv":3467.02,"id":9629296}],"tv":6262.37}]}
{"op":"mcm","clk":"4231770459","pt":1631547902317,"mc":[{"id":"1.187560634","rc":[{"trd":[[1.76,63.99]],"batb":[[0,1.75,132.68],[1,1.73,108.84],[2,1.7,37.83]],"ltp":1.76,"tv":2819.99,"id":12343905}],"tv":6287.01}]}
{"op":"mcm","clk":"4231770884","pt":1631547906107,"mc":[{"id":"1.187560634","rc":[{"trd":[[1.75,266.42]],"batb":[[0,1.7,37.83],[1,1.62,16.74],[2,1.58,48.99]],"batl":[[1,1.85,28.3],[2,1.86,160.8]],"ltp":1.75,"tv":3085.35,"id":12343905}],"tv":6552.37}]}
{"op":"mcm","clk":"4231771157","pt":1631547909041,"mc":[{"id":"1.187560634","rc":[{"batb":[[0,1.74,82.77],[1,1.72,111.21],[2,1.7,37.83]],"batl":[[0,1.8,101.28],[1,1.82,93.43],[2,1.85,28.3]],"ltp":1.75,"tv":3085.35,"id":12343905}]}]}
{"op":"mcm","clk":"4231771478","pt":1631547912252,"mc":[{"id":"1.187560634","rc":[{"batl":[[0,1.8,89.57]],"ltp":1.75,"tv":3085.35,"id":12343905}]}]}
{"op":"mcm","clk":"4231771549","pt":1631547912830,"mc":[{"id":"1.187560634","rc":[{"batl":[[2,1.83,30.5]],"ltp":1.75,"tv":3085.35,"id":12343905}]}]}
{"op":"mcm","clk":"4231771770","pt":1631547915145,"mc":[{"id":"1.187560634","rc":[{"batb":[[0,1.74,95.61]],"batl":[[0,1.78,12.18],[1,1.8,89.57],[2,1.82,93.43]],"ltp":1.75,"tv":3085.35,"id":12343905}]}]}
{"op":"mcm","clk":"4231772537","pt":1631547923271,"mc":[{"id":"1.187560634","rc":[{"batb":[[2,2.16,7.78]],"batl":[[0,2.94,4.25],[1,3.25,4.8],[2,2.42,0]],"ltp":2.28,"tv":3467.02,"id":9629296},{"batb":[[0,1.62,16.74],[1,1.58,48.99],[2,1.52,48.74]],"batl":[[0,1.86,29.25],[1,3,5.2],[2,1.82,0]],"ltp":1.75,"tv":3085.35,"id":12343905}]}]}
{"op":"mcm","clk":"4231772848","pt":1631547926589,"mc":[{"id":"1.187560634","rc":[{"batl":[[0,2.74,5.25],[1,2.94,4.25],[2,3.25,4.8]],"ltp":2.28,"tv":3467.02,"id":9629296},{"batb":[[1,1.61,123.17],[2,1.6,72.45]],"batl":[[1,1.9,61.33],[2,1.92,79.13]],"ltp":1.75,"tv":3085.35,"id":12343905}]}]}
{"op":"mcm","clk":"4231773159","pt":1631547930160,"mc":[{"id":"1.187560634","rc":[{"batb":[[2,2.2,6.72]],"ltp":2.28,"tv":3467.02,"id":9629296},{"batl":[[0,1.83,31.5],[1,1.86,29.25],[2,1.9,61.33]],"ltp":1.75,"tv":3085.35,"id":12343905}]}]}
{"op":"mcm","clk":"4231773222","pt":1631547930899,"mc":[{"id":"1.187560634","rc":[{"batb":[[2,2.16,7.78]],"ltp":2.28,"tv":3467.02,"id":9629296},{"batl":[[0,1.86,29.25],[1,1.9,61.33],[2,1.92,79.13]],"ltp":1.75,"tv":3085.35,"id":12343905}]}]}
{"op":"mcm","clk":"4231773408","pt":1631547933170,"mc":[{"id":"1.187560634","rc":[{"batb":[[1,2.16,7.78],[2,2,60.53]],"ltp":2.28,"tv":3467.02,"id":9629296}]}]}
{"op":"mcm","clk":"4231773602","pt":1631547935386,"mc":[{"id":"1.187560634","rc":[{"batb":[[0,2.3,6.56],[1,2.28,13.25],[2,2.16,7.78]],"ltp":2.28,"tv":3467.02,"id":9629296},{"trd":[[1.62,0.1]],"batb":[[0,1.62,16.69]],"ltp":1.62,"tv":3085.45,"id":12343905}],"tv":6552.47}]}
{"op":"mcm","clk":"4231773778","pt":1631547937487,"mc":[{"id":"1.187560634","rc":[{"batl":[[1,3,5.2],[2,1.92,0]],"ltp":1.62,"tv":3085.45,"id":12343905}]}]}
{"op":"mcm","clk":"4231774057","pt":1631547940610,"mc":[{"id":"1.187560634","rc":[{"batb":[[0,2.5,36],[1,2.48,18],[2,2.46,18]],"batl":[[0,2.6,6.52],[1,2.66,95.83],[2,2.74,5.25]],"ltp":2.28,"tv":3467.02,"id":9629296},{"batl":[[0,1.66,85.56],[1,1.68,121.85],[2,1.7,120.84]],"ltp":1.62,"tv":3085.45,"id":12343905}]}]}
{"op":"mcm","clk":"4231774163","pt":1631547941618,"mc":[{"id":"1.187560634","rc":[{"batl":[[2,2.68,11.2]],"ltp":2.28,"tv":3467.02,"id":9629296}]}]}
{"op":"mcm","clk":"4231775062","pt":1631547950512,"mc":[{"id":"1.187560634","rc":[{"batb":[[0,2.32,6.39],[1,2.18,35.15],[2,2.04,399.94]],"batl":[[0,3.25,4.8],[1,3.3,3.25],[2,3.9,160.59]],"ltp":2.28,"tv":3467.02,"id":9629296},{"batb":[[1,1.46,66.68],[2,1.44,54.92]],"batl":[[0,1.75,36.34],[1,3,5.2],[2,1.7,0]],"ltp":1.62,"tv":3085.45,"id":12343905}]}]}
{"op":"mcm","clk":"4231775354","pt":1631547953399,"mc":[{"id":"1.187560634","rc":[{"batb":[[0,1.62,17.19]],"batl":[[1,1.77,74.01],[2,1.79,98.61]],"ltp":1.62,"tv":3085.45,"id":12343905}]}]}
{"op":"mcm","clk":"4231775472","pt":1631547954128,"mc":[{"id":"1.187560634","rc":[{"batl":[[2,3.9,0]],"ltp":2.28,"tv":3467.02,"id":9629296}]}]}
{"op":"mcm","clk":"4231775665","pt":1631547956124,"mc":[{"id":"1.187560634","rc":[{"batb":[[0,2.32,19.96]],"batl":[[0,2.4,7.39],[1,2.44,2],[2,3.25,4.8]],"ltp":2.28,"tv":3467.02,"id":9629296},{"batb":[[0,1.71,167.62],[1,1.7,215.12],[2,1.69,144.62]],"ltp":1.62,"tv":3085.45,"id":12343905}]}]}
{"op":"mcm","clk":"4231775753","pt":1631547957020,"mc":[{"id":"1.187560634","rc":[{"batb":[[0,1.71,132.53],[1,1.7,197.58],[2,1.69,127.08]],"batl":[[2,1.79,115.37]],"ltp":1.62,"tv":3085.45,"id":12343905}]}]}
{"op":"mcm","clk":"4231776171","pt":1631547961125,"mc":[{"id":"1.187560634","rc":[{"trd":[[2.32,26.58]],"batb":[[0,2.32,14.43]],"ltp":2.32,"tv":3478.08,"id":9629296}],"tv":6563.53}]}
{"op":"mcm","clk":"4231776315","pt":1631547962301,"mc":[{"id":"1.187560634","rc":[{"batb":[[1,2.2,7.22],[2,2.18,35.15]],"batl":[[2,2.74,4.98]],"ltp":2.32,"tv":3478.08,"id":9629296}]}]}
{"op":"mcm","clk":"4231776644","pt":1631547965616,"mc":[{"id":"1.187560634","rc":[{"batb":[[0,2.16,7.78],[1,2.04,399.94],[2,2,60.11]],"batl":[[0,2.74,4.98],[1,2.9,4.55],[2,3.25,4.8]],"ltp":2.32,"tv":3478.08,"id":9629296},{"trd":[[1.75,267.42]],"batb":[[0,1.62,17.19],[1,1.58,41.06],[2,1.54,53.35]],"batl":[[0,1.86,28.75],[1,3,5.2],[2,1.79,0]],"ltp":1.75,"tv":3086.45,"id":12343905}],"tv":6564.53}]}
{"op":"mcm","clk":"4231776672","pt":1631547965826,"mc":[{"id":"1.187560634","rc":[{"batl":[[0,2.9,4.55],[1,3.25,4.8],[2,3.45,183.07]],"ltp":2.32,"tv":3478.08,"id":9629296},{"batb":[[1,1.54,53.35],[2,1.53,52.33]],"ltp":1.75,"tv":3086.45,"id":12343905}]}]}
{"op":"mcm","clk":"4231776846","pt":1631547967354,"mc":[{"id":"1.187560634","rc":[{"trd":[[1.62,1.88],[1.66,1]],"batb":[[0,1.62,15.8]],"ltp":1.62,"tv":3089.22,"id":12343905}],"tv":6567.31}]}
{"op":"mcm","clk":"4231776961","pt":1631547968525,"mc":[{"id":"1.187560634","rc":[{"batb":[[1,1.57,136.27],[2,1.56,79.75]],"batl":[[1,1.89,65.46],[2,1.91,80.4]],"ltp":1.62,"tv":3089.22,"id":12343905}]}]}
{"op":"mcm","clk":"4231777182","pt":1631547970850,"mc":[{"id":"1.187560634","rc":[{"batb":[[1,1.54,53.35],[2,1.53,52.33]],"ltp":1.62,"tv":3089.22,"id":12343905}]}]}
{"op":"mcm","clk":"4231777386","pt":1631547972540,"mc":[{"id":"1.187560634","rc":[{"batb":[[0,2.2,7.17],[1,2.16,7.78]],"batl":[[0,2.74,4.75],[1,2.9,4.55],[2,3.25,4.8]],"ltp":2.32,"tv":3478.08,"id":9629296},{"batb":[[1,1.58,43.56],[2,1.54,53.35]],"batl":[[0,1.83,31.5],[1,1.86,28.75],[2,1.89,65.46]],"ltp":1.62,"tv":3089.22,"id":12343905}]}]}
{"op":"mcm","clk":"4231777499","pt":1631547973646,"mc":[{"id":"1.187560634","rc":[{"batb":[[0,2.16,7.78],[1,2,60.11],[2,1.7,17.05]],"batl":[[0,2.24,79.24],[1,2.26,33.48],[2,2.28,154.72]],"ltp":2.32,"tv":3478.08,"id":9629296},{"batb":[[0,1.81,119.79],[1,1.62,15.8]],"batl":[[0,1.86,46.04],[1,1.89,65.46],[2,1.91,80.4]],"ltp":1.62,"tv":3089.22,"id":12343905}]}]}
{"op":"mcm","clk":"4231777616","pt":1631547974649,"mc":[{"id":"1.187560634","rc":[{"batb":[[2,1.9,26.67]],"batl":[[0,2.24,25.68],[1,2.26,6.7],[2,2.28,127.94]],"ltp":2.32,"tv":3478.08,"id":9629296},{"batb":[[0,1.83,68.39],[1,1.81,213.58],[2,1.79,31.79]],"batl":[[2,1.9,78.96]],"ltp":1.62,"tv":3089.22,"id":12343905}]}]}
{"op":"mcm","clk":"4231777631","pt":1631547974763,"mc":[{"id":"1.187560634","rc":[{"batl":[[2,1.9,15.8]],"ltp":1.62,"tv":3089.22,"id":12343905}]}]}
{"op":"mcm","clk":"4231778194","pt":1631547980665,"mc":[{"id":"1.187560634","rc":[{"batb":[[1,2.08,7.06],[2,2.04,8.12]],"ltp":2.32,"tv":3478.08,"id":9629296}]}]}
{"op":"mcm","clk":"4231778289","pt":1631547981664,"mc":[{"id":"1.187560634","rc":[{"batl":[[0,2.24,2.73],[1,2.4,6.24],[2,2.48,6.49]],"ltp":2.32,"tv":3478.08,"id":9629296},{"batb":[[1,1.81,103.08]],"batl":[[0,1.86,28.75],[2,1.91,80.4]],"ltp":1.62,"tv":3089.22,"id":12343905}]}]}
{"op":"mcm","clk":"4231778326","pt":1631547982074,"mc":[{"id":"1.187560634","rc":[{"batb":[[0,2,15.91],[1,1.9,26.67],[2,1.82,407.19]],"batl":[[0,2.48,6.49],[1,3.15,203.39],[2,3.25,4.8]],"ltp":2.32,"tv":3478.08,"id":9629296},{"batb":[[0,1.68,39.86],[1,1.66,41.1],[2,1.62,15.8]],"batl":[[0,1.95,25.1],[1,3,5.2],[2,1.91,0]],"ltp":1.62,"tv":3089.22,"id":12343905}]}]}
{"op":"mcm","clk":"4231778654","pt":1631547985462,"mc":[{"id":"1.187560634","rc":[{"batb":[[0,2.04,7.62],[1,2,15.91],[2,1.9,26.67]],"ltp":2.32,"tv":3478.08,"id":9629296}]}]}
{"op":"mcm","clk":"4231778746","pt":1631547986572,"mc":[{"id":"1.187560634","rc":[{"batl":[[0,1.87,273.46],[1,1.95,25.1],[2,3,5.2]],"ltp":1.62,"tv":3089.22,"id":12343905}]}]}
{"op":"mcm","clk":"4231778837","pt":1631547987473,"mc":[{"id":"1.187560634","rc":[{"batb":[[0,2.1,21.66],[1,2.04,7.62],[2,2,15.91]],"ltp":2.32,"tv":3478.08,"id":9629296},{"batb":[[0,1.8,72.64],[1,1.78,99.09],[2,1.68,39.86]],"batl":[[0,1.86,72.89],[1,1.88,84.42],[2,1.95,25.1]],"ltp":1.62,"tv":3089.22,"id":12343905}]}]}
{"op":"mcm","clk":"4231778947","pt":1631547988660,"mc":[{"id":"1.187560634","rc":[{"batb":[[1,2.08,8.31],[2,2.04,7.62]],"batl":[[0,2.4,6.49],[1,2.48,6.49],[2,3.15,203.39]],"ltp":2.32,"tv":3478.08,"id":9629296},{"trd":[[1.86,182.54]],"batb":[[0,1.86,77.11],[1,1.8,72.64],[2,1.78,99.09]],"batl":[[0,1.88,84.42],[1,1.92,28.31]],"ltp":1.86,"tv":3235.0,"id":12343905}],"tv":6713.09}]}
{"op":"mcm","clk":"4231778968","pt":1631547988973,"mc":[{"id":"1.187560634","rc":[{"batb":[[1,2.04,7.62],[2,2,15.91]],"batl":[[0,2.48,6.49],[1,3.15,203.39],[2,3.25,4.8]],"ltp":2.32,"tv":3478.08,"id":9629296},{"batb":[[1,1.68,39.86],[2,1.66,41.1]],"batl":[[0,1.95,25.1],[1,3,5.2],[2,1.95,0]],"ltp":1.86,"tv":3235.0,"id":12343905}]}]}
{"op":"mcm","clk":"4231779472","pt":1631547994965,"mc":[{"id":"1.187560634","rc":[{"batl":[[1,2.02,77.12],[2,2.04,65.97]],"ltp":1.86,"tv":3235.0,"id":12343905}]}]}
{"op":"mcm","clk":"4231779630","pt":1631547996484,"mc":[{"id":"1.187560634","rc":[{"trd":[[2.04,41.02],[2.1,43.32]],"batb":[[0,2,15.91],[1,1.9,26.67],[2,1.6,99.43]],"batl":[[1,3.25,4.8],[2,3.25,0]],"ltp":2.04,"tv":3551.36,"id":9629296},{"trd":[[1.95,15.4]],"batl":[[0,1.95,9.7]],"ltp":1.95,"tv":3250.4,"id":12343905}],"tv":6801.76}]}
{"op":"mcm","clk":"4231779743","pt":1631547997662,"mc":[{"id":"1.187560634","rc":[{"batb":[[0,2,69.1]],"batl":[[0,2.08,96.16],[1,2.12,12.33],[2,2.16,1539.3]],"ltp":2.04,"tv":3551.36,"id":9629296},{"batb":[[0,1.91,78.52],[1,1.9,48.02],[2,1.89,39.26]],"batl":[[0,1.94,11.51],[1,1.95,9.7],[2,2,53.19]],"ltp":1.95,"tv":3250.4,"id":12343905}]}]}
{"op":"mcm","clk":"4231779826","pt":1631547998595,"mc":[{"id":"1.187560634","rc":[{"batb":[[2,1.4,149.15]],"batl":[[0,2.08,19.24],[2,2.16,137.46]],"ltp":2.04,"tv":3551.36,"id":9629296},{"trd":[[1.94,23.02]],"batb":[[0,1.94,78.87],[1,1.92,77.72],[2,1.91,78.52]],"batl":[[0,1.95,9.7],[1,2,53.19],[2,2.02,151.38]],"ltp":1.94,"tv":3273.42,"id":12343905}],"tv":6824.78}]}
{"op":"mcm","clk":"4231779920","pt":1631547999658,"mc":[{"id":"1.187560634","rc":[{"batb":[[2,1.82,30.2]],"ltp":2.04,"tv":3551.36,"id":9629296},{"batb":[[2,1.91,47.11]],"batl":[[2,2.02,91.98]],"ltp":1.94,"tv":3273.42,"id":12343905}]}]}
{"op":"mcm","clk":"4231780064","pt":1631548001384,"mc":[{"id":"1.187560634","rc":[{"trd":[[2.08,47.14]],"batl":[[0,2.12,12.33],[1,2.16,137.46],[2,2.48,6.49]],"ltp":2.08,"tv":3598.5,"id":9629296},{"trd":[[1.94,32.32]],"batb":[[0,1.94,69.57]],"ltp":1.94,"tv":3282.72,"id":12343905}],"tv":6881.23}]}
{"op":"mcm","clk":"4231780180","pt":1631548002599,"mc":[{"id":"1.187560634","rc":[{"trd":[[2.04,45.31],[2.08,66.2]],"ltp":2.04,"tv":3621.85,"id":9629296},{"trd":[[1.94,52.76],[1.95,19.89]],"batb":[[0,1.94,49.13]],"batl":[[0,1.95,5.21]],"ltp":1.95,"tv":3307.65,"id":12343905}],"tv":6929.51}]}
{"op":"mcm","clk":"4231780373","pt":1631548004484,"mc":[{"id":"1.187560634","rc":[{"batb":[[0,2,92.68],[1,1.99,26.51],[2,1.9,26.67]],"batl":[[2,2.18,6.75]],"ltp":2.04,"tv":3621.85,"id":9629296},{"batb":[[0,1.94,58.45]],"batl":[[1,1.99,25.5],[2,2,53.19]],"ltp":1.95,"tv":3307.65,"id":12343905}]}]}
{"op":"mcm","clk":"4231780533","pt":1631548006290,"mc":[{"id":"1.187560634","rc":[{"batb":[[0,2,15.91],[1,1.82,30.2],[2,1.4,149.15]],"batl":[[0,3.25,4.8],[1,2.16,0],[2,2.18,0]],"ltp":2.04,"tv":3621.85,"id":9629296},{"trd":[[1.94,61.28]],"batb":[[0,1.86,77.11],[1,1.82,29.14],[2,1.8,31.2]],"batl":[[0,2.02,7.75],[1,3,5.2],[2,2,0]],"ltp":1.94,"tv":3316.18,"id":12343905}],"tv":6938.03}]}
{"op":"mcm","clk":"4231780842","pt":1631548009478,"mc":[{"id":"1.187560634","rc":[{"batb":[[0,2,38.94],[1,1.99,26.51],[2,1.82,30.2]],"batl":[[0,2.18,7.25],[1,2.22,6.75],[2,3.25,4.8]],"ltp":2.04,"tv":3621.85,"id":9629296},{"batb":[[1,1.85,30.97],[2,1.82,29.14]],"batl":[[0,1.99,23.5],[1,2.02,7.75],[2,3,5.2]],"ltp":1.94,"tv":3316.18,"id":12343905}]}]}
{"op":"mcm","clk":"4231780869","pt":1631548009793,"mc":[{"id":"1.187560634","rc":[{"batb":[[0,2,15.91]],"batl":[[0,2.22,6.75],[1,3.25,4.8],[2,3.25,0]],"ltp":2.04,"tv":3621.85,"id":9629296},{"batb":[[1,1.82,29.14],[2,1.8,31.2]],"batl":[[0,2.02,7.75],[1,3,5.2],[2,3,0]],"ltp":1.94,"tv":3316.18,"id":12343905}]}]}
{"op":"mcm","clk":"4231781022","pt":1631548011271,"mc":[{"id":"1.187560634","rc":[{"batb":[[0,1.92,59.41],[1,1.9,80.29],[2,1.86,77.11]],"batl":[[0,1.99,80.01],[1,2.02,110.12],[2,3,5.2]],"ltp":1.94,"tv":3316.18,"id":12343905}]}]}
{"op":"mcm","clk":"4231781203","pt":1631548013167,"mc":[{"id":"1.187560634","rc":[{"batb":[[2,1.82,29.14]],"ltp":1.94,"tv":3316.18,"id":12343905}]}]}
{"op":"mcm","clk":"4231781418","pt":1631548015406,"mc":[{"id":"1.187560634","rc":[{"batb":[[0,1.82,29.14],[1,1.8,31.2],[2,1.62,15.8]],"batl":[[0,2.02,7.75],[1,3,5.2],[2,3,0]],"ltp":1.94,"tv":3316.18,"id":12343905}]}]}
{"op":"mcm","clk":"4231781495","pt":1631548016502,"mc":[{"id":"1.187560634","rc":[{"batb":[[0,2,39.49]],"batl":[[0,2.18,7.25],[1,2.22,6.75],[2,3.25,4.8]],"ltp":2.04,"tv":3621.85,"id":9629296},{"batb":[[0,1.85,28.97],[1,1.82,29.14],[2,1.8,31.2]],"batl":[[0,1.99,22.5],[1,2.02,7.75],[2,3,5.2]],"ltp":1.94,"tv":3316.18,"id":12343905}]}]}
{"op":"mcm","clk":"4231781541","pt":1631548016976,"mc":[{"id":"1.187560634","rc":[{"batb":[[0,2,15.91]],"batl":[[0,2.22,6.75],[1,3.25,4.8],[2,3.25,0]],"ltp":2.04,"tv":3621.85,"id":9629296},{"batb":[[0,1.82,29.14],[1,1.8,31.2],[2,1.62,15.8]],"batl":[[0,2.02,7.75],[1,3,5.2],[2,3,0]],"ltp":1.94,"tv":3316.18,"id":12343905}]}]}
{"op":"mcm","clk":"4231781934","pt":1631548021409,"mc":[{"id":"1.187560634","rc":[{"trd":[[1.99,53.02],[2,46.23]],"batb":[[0,1.92,54.06],[1,1.9,80.32]],"batl":[[0,1.99,42.8],[1,2.02,184.94],[2,2.04,37.14]],"ltp":1.99,"tv":3706.69,"id":9629296},{"batb":[[0,1.97,20.3],[1,1.95,22.51],[2,1.92,154.86]],"batl":[[0,2.02,15.72],[1,2.06,100.91],[2,3,5.2]],"ltp":1.94,"tv":3316.18,"id":12343905}],"tv":7022.87}]}
{"op":"mcm","clk":"4231782036","pt":1631548022627,"mc":[{"id":"1.187560634","rc":[{"batb":[[1,1.91,15.7],[2,1.9,88.18]],"batl":[[1,2.02,125.54],[2,2.04,7.42]],"ltp":1.99,"tv":3706.69,"id":9629296},{"batb":[[0,1.97,66.94]],"ltp":1.94,"tv":3316.18,"id":12343905}]}]}
{"op":"mcm","clk":"4231782285","pt":1631548025230,"mc":[{"id":"1.187560634","rc":[{"batb":[[0,1.92,78.43]],"batl":[[0,1.99,61.74]],"ltp":1.99,"tv":3706.69,"id":9629296}]}]}
{"op":"mcm","clk":"4231782556","pt":1631548027893,"mc":[{"id":"1.187560634","rc":[{"batl":[[2,2.28,6.34]],"ltp":1.94,"tv":3316.18,"id":12343905}]}]}
{"op":"mcm","clk":"4231782765","pt":1631548030411,"mc":[{"id":"1.187560634","rc":[{"trd":[[1.99,114.76],[2.02,121.01]],"batb":[[2,1.9,7.86]],"batl":[[0,2.02,39.89],[1,2.04,7.42],[2,2.06,14.67]],"ltp":2.02,"tv":3854.08,"id":9629296},{"trd":[[1.98,123.46],[2,364.45]],"ltp":1.98,"tv":3465.0,"id":12343905}],"tv":7319.08}]}
{"op":"mcm","clk":"4231782810","pt":1631548030933,"mc":[{"id":"1.187560634","rc":[{"trd":[[1.98,123.25]],"ltp":1.98,"tv":3856.37,"id":9629296},{"trd":[[2.02,15.86]],"batl":[[0,2.02,13.48]],"ltp":2.02,"tv":3467.24,"id":12343905}],"tv":7323.61}]}
{"op":"mcm","clk":"4231783057","pt":1631548033451,"mc":[{"id":"1.187560634","rc":[{"batb":[[0,1.94,71.7],[1,1.92,78.43],[2,1.91,15.7]],"batl":[[0,2.02,95.08],[1,2.04,73.39]],"ltp":1.98,"tv":3856.37,"id":9629296},{"batl":[[0,2.02,13.57]],"ltp":2.02,"tv":3467.24,"id":12343905}]}]}
{"op":"mcm","clk":"4231783099","pt":1631548033920,"mc":[{"id":"1.187560634","rc":[{"batl":[[2,2.24,7.23]],"ltp":2.02,"tv":3467.24,"id":12343905}]}]}
{"op":"mcm","clk":"4231783463","pt":1631548038210,"mc":[{"id":"1.187560634","rc":[{"trd":[[2,364.64],[2.02,32.38]],"batl":[[0,2.02,5.22]],"ltp":2.02,"tv":3483.94,"id":12343905}],"tv":7340.32}]}
{"op":"mcm","clk":"4231783608","pt":1631548040256,"mc":[{"id":"1.187560634","rc":[{"batl":[[0,2.06,100.91],[1,2.24,7.23],[2,2.28,6.34]],"ltp":2.02,"tv":3483.94,"id":12343905}]}]}
{"op":"mcm","clk":"4231783860","pt":1631548043254,"mc":[{"id":"1.187560634","rc":[{"batl":[[1,2.04,84]],"ltp":1.98,"tv":3856.37,"id":9629296},{"trd":[[2.06,5.29]],"batl":[[0,2.02,13.5],[1,2.06,100.87],[2,2.24,7.23]],"ltp":2.06,"tv":3484.02,"id":12343905}],"tv":7340.4}]}
{"op":"mcm","clk":"4231784309","pt":1631548048420,"mc":[{"id":"1.187560634","rc":[{"batl":[[1,2.04,73.39]],"ltp":1.98,"tv":3856.37,"id":9629296},{"batl":[[0,2.06,100.87],[1,2.24,7.23],[2,2.28,6.34]],"ltp":2.06,"tv":3484.02,"id":12343905}]}]}
{"op":"mcm","clk":"4231784531","pt":1631548051356,"mc":[{"id":"1.187560634","rc":[{"batl":[[1,2.04,84]],"ltp":1.98,"tv":3856.37,"id":9629296},{"batl":[[0,2.02,13.5],[1,2.06,100.87],[2,2.24,7.23]],"ltp":2.06,"tv":3484.02,"id":12343905}]}]}
{"op":"mcm","clk":"4231784651","pt":1631548052573,"mc":[{"id":"1.187560634","rc":[{"batb":[[2,1.82,30.2]],"batl":[[1,2.04,65.97],[2,2.06,7.25]],"ltp":1.98,"tv":3856.37,"id":9629296},{"batb":[[0,1.97,46.64],[2,1.87,12]],"batl":[[0,2.24,7.23],[1,2.28,6.34],[2,2.32,6.61]],"ltp":2.06,"tv":3484.02,"id":12343905}]}]}
{"op":"mcm","clk":"4231784722","pt":1631548053364,"mc":[{"id":"1.187560634","rc":[{"batb":[[0,1.67,456.69],[1,1.4,149.15],[2,1.3,198.84]],"batl":[[0,2.24,6.43],[1,3.25,4.8],[2,2.06,0]],"ltp":1.98,"tv":3856.37,"id":9629296},{"batb":[[0,1.87,12],[1,1.84,28.85],[2,1.81,36.29]],"batl":[[0,2.32,6.61],[1,3,5.2],[2,2.32,0]],"ltp":2.06,"tv":3484.02,"id":12343905}]}]}
{"op":"mcm","clk":"4231784974","pt":1631548056467,"mc":[{"id":"1.187560634","rc":[{"batb":[[0,1.76,93.35],[1,1.74,141.42],[2,1.67,456.69]],"batl":[[0,2.16,51.45],[1,2.18,62.77],[2,2.24,6.23]],"ltp":1.98,"tv":3856.37,"id":9629296},{"batb":[[1,1.85,36.97],[2,1.84,28.85]],"batl":[[1,2.36,6.32],[2,3,5.2]],"ltp":2.06,"tv":3484.02,"id":12343905}]}]}
{"op":"mcm","clk":"4231785033","pt":1631548057259,"mc":[{"id":"1.187560634","rc":[{"trd":[[1.94,5.92]],"batb":[[0,1.96,35.9],[1,1.76,93.35],[2,1.74,141.42]],"batl":[[0,2.16,51.25],[1,2.18,54.52]],"ltp":1.94,"tv":3856.77,"id":9629296},{"batb":[[1,1.84,28.85],[2,1.81,36.29]],"ltp":2.06,"tv":3484.02,"id":12343905}],"tv":7340.8}]}
{"op":"mcm","clk":"4231785095","pt":1631548058063,"mc":[{"id":"1.187560634","rc":[{"batb":[[1,1.74,34.52],[2,1.67,456.69]],"batl":[[0,2.24,6.23],[1,3.25,4.8],[2,2.24,0]],"ltp":1.94,"tv":3856.77,"id":9629296}]}]}
{"op":"mcm","clk":"4231785232","pt":1631548059443,"mc":[{"id":"1.187560634","rc":[{"batb":[[1,1.8,27.78],[2,1.74,34.52]],"ltp":1.94,"tv":3856.77,"id":9629296},{"batl":[[0,2.26,6.75],[1,2.32,6.61],[2,2.36,6.32]],"ltp":2.06,"tv":3484.02,"id":12343905}]}]}
{"op":"mcm","clk":"4231785360","pt":1631548060651,"mc":[{"id":"1.187560634","rc":[{"batb":[[0,1.74,34.52],[1,1.67,40.85],[2,1.4,149.15]],"ltp":1.94,"tv":3856.77,"id":9629296},{"batb":[[1,1.86,36.18],[2,1.84,28.85]],"batl":[[0,1.91,1574.94],[1,1.92,78.12],[2,1.93,39.06]],"ltp":2.06,"tv":3484.02,"id":12343905}]}]}
{"op":"mcm","clk":"4231785391","pt":1631548060971,"mc":[{"id":"1.187560634","rc":[{"batb":[[1,1.86,76.26],[2,1.84,117.8]],"batl":[[0,1.89,7.46],[1,1.92,101.74],[2,1.93,23.44]],"ltp":2.06,"tv":3484.02,"id":12343905}]}]}
{"op":"mcm","clk":"4231785537","pt":1631548062566,"mc":[{"id":"1.187560634","rc":[{"batb":[[0,1.95,48.9],[1,1.8,31.62],[2,1.74,444.8]],"ltp":1.94,"tv":3856.77,"id":9629296},{"batl":[[1,1.92,70.49],[2,1.93,7.82]],"ltp":2.06,"tv":3484.02,"id":12343905}]}]}
{"op":"mcm","clk":"4231793716","pt":1631548067560,"mc":[{"id":"1.187560634","rc":[{"batb":[[0,1.99,22.51],[1,1.95,65.34],[2,1.93,25.93]],"batl":[[1,2.28,6.84],[2,2.32,7.11]],"ltp":1.94,"tv":3856.77,"id":9629296}]}]}
{"op":"mcm","clk":"4231793953","pt":1631548070471,"mc":[{"id":"1.187560634","rc":[{"trd":[[2.12,23.47]],"ltp":2.12,"tv":3856.86,"id":9629296},{"trd":[[1.89,29.1]],"batl":[[0,1.89,7.36]],"ltp":1.89,"tv":3484.12,"id":12343905}],"tv":7340.99}]}
{"op":"mcm","clk":"4231794827","pt":1631548080662,"mc":[{"id":"1.187560634","rc":[{"batb":[[0,1.95,48.9],[1,1.8,31.62],[2,1.74,410.28]],"batl":[[0,2.28,6.84],[1,2.32,7.11],[2,3.25,4.8]],"ltp":2.12,"tv":3856.86,"id":9629296},{"batb":[[1,1.84,28.85],[2,1.79,42.31]],"batl":[[0,2.08,7.69],[1,3,5.2],[2,1.93,0]],"ltp":1.89,"tv":3484.12,"id":12343905}]}]}
{"op":"mcm","clk":"4231794869","pt":1631548080977,"mc":[{"id":"1.187560634","rc":[{"batb":[[0,1.8,31.62],[1,1.74,410.28],[2,1.4,149.15]],"batl":[[0,2.32,7.11],[1,3.25,4.8],[2,3.25,0]],"ltp":2.12,"tv":3856.86,"id":9629296},{"batb":[[1,1.76,38.48],[2,1.74,34.81]],"ltp":1.89,"tv":3484.12,"id":12343905}]}]}
{"op":"mcm","clk":"4231795143","pt":1631548083660,"mc":[{"id":"1.187560634","rc":[{"batb":[[1,1.76,133.98],[2,1.74,141.87]],"batl":[[1,2.1,52.09],[2,2.12,59]],"ltp":1.89,"tv":3484.12,"id":12343905}]}]}
{"op":"mcm","clk":"4231795211","pt":1631548084355,"mc":[{"id":"1.187560634","rc":[{"batb":[[0,1.93,29.93],[1,1.8,31.62],[2,1.74,410.28]],"ltp":2.12,"tv":3856.86,"id":9629296},{"batb":[[1,1.76,38.48],[2,1.74,34.81]],"batl":[[1,3,5.2],[2,2.12,0]],"ltp":1.89,"tv":3484.12,"id":12343905}]}]}
{"op":"mcm","clk":"4231795385","pt":1631548086384,"mc":[{"id":"1.187560634","rc":[{"batl":[[0,2.14,20.75],[1,2.32,7.11],[2,3.25,4.8]],"ltp":2.12,"tv":3856.86,"id":9629296},{"batb":[[0,1.89,72.1],[1,1.88,18.71],[2,1.87,96.47]],"batl":[[0,1.92,20.06],[1,1.96,78.43],[2,1.98,72.11]],"ltp":1.89,"tv":3484.12,"id":12343905}]}]}
{"op":"mcm","clk":"4231795501","pt":1631548087666,"mc":[{"id":"1.187560634","rc":[{"batl":[[0,2.28,7.34]],"ltp":2.12,"tv":3856.86,"id":9629296},{"batb":[[1,1.87,96.47],[2,1.79,42.31]],"batl":[[0,1.96,78.43],[1,1.98,72.11],[2,2.08,7.69]],"ltp":1.89,"tv":3484.12,"id":12343905}]}]}
{"op":"mcm","clk":"4231795595","pt":1631548088824,"mc":[{"id":"1.187560634","rc":[{"trd":[[1.89,31.08]],"batb":[[0,1.89,71.11]],"ltp":1.89,"tv":3486.1,"id":12343905}],"tv":7342.97}]}
{"op":"mcm","clk":"4231796057","pt":1631548093478,"mc":[{"id":"1.187560634","rc":[{"batb":[[0,1.87,12],[1,1.79,42.31],[2,1.76,38.48]],"batl":[[0,2.08,7.69],[1,3,5.2],[2,2.08,0]],"ltp":1.89,"tv":3486.1,"id":12343905}]}]}
{"op":"mcm","clk":"4231796274","pt":1631548096483,"mc":[{"id":"1.187560634","rc":[{"batb":[[2,1.76,133.39]],"batl":[[1,2.1,52.59],[2,2.12,59]],"ltp":1.89,"tv":3486.1,"id":12343905}]}]}
{"op":"mcm","clk":"4231796369","pt":1631548097582,"mc":[{"id":"1.187560634","rc":[{"batb":[[0,1.99,22.51],[1,1.93,29.93],[2,1.8,31.62]],"ltp":2.12,"tv":3856.86,"id":9629296},{"batl":[[0,2.02,8.75],[1,2.08,7.69],[2,2.1,52.59]],"ltp":1.89,"tv":3486.1,"id":12343905}]}]}
{"op":"mcm","clk":"4231796457","pt":1631548098624,"mc":[{"id":"1.187560634","rc":[{"batb":[[0,1.94,28.88]],"ltp":2.12,"tv":3856.86,"id":9629296},{"batb":[[0,1.96,1.02],[1,1.87,12],[2,1.79,42.31]],"batl":[[0,2.08,7.69],[1,2.1,52.59],[2,2.12,59]],"ltp":1.89,"tv":3486.1,"id":12343905}]}]}
{"op":"mcm","clk":"4231796846","pt":1631548102899,"mc":[{"id":"1.187560634","rc":[{"trd":[[1.87,8.18],[1.96,13.56]],"batb":[[0,1.87,7.91],[1,1.79,42.31],[2,1.76,133.39]],"ltp":1.87,"tv":3496.33,"id":12343905}],"tv":7353.2}]}
{"op":"mcm","clk":"4231797016","pt":1631548104634,"mc":[{"id":"1.187560634","rc":[{"batb":[[0,1.99,23.51],[1,1.94,28.88],[2,1.93,29.93]],"ltp":2.12,"tv":3856.86,"id":9629296},{"batl":[[0,2.02,8.75],[1,2.08,7.69],[2,2.1,52.59]],"ltp":1.87,"tv":3496.33,"id":12343905}]}]}
{"op":"mcm","clk":"4231797051","pt":1631548104903,"mc":[{"id":"1.187560634","rc":[{"batb":[[0,1.94,28.88],[1,1.93,29.93],[2,1.8,31.62]],"ltp":2.12,"tv":3856.86,"id":9629296},{"batl":[[0,2.08,7.69],[1,2.1,52.59],[2,2.12,59]],"ltp":1.87,"tv":3496.33,"id":12343905}]}]}
{"op":"mcm","clk":"4231797183","pt":1631548106340,"mc":[{"id":"1.187560634","rc":[{"batb":[[2,1.76,38.48]],"batl":[[1,3,5.2],[2,2.12,0]],"ltp":1.87,"tv":3496.33,"id":12343905}]}]}
{"op":"mcm","clk":"4231797451","pt":1631548109345,"mc":[{"id":"1.187560634","rc":[{"batb":[[2,1.9,94.84]],"batl":[[0,1.97,52.81],[1,1.99,71],[2,2,19.28]],"ltp":2.12,"tv":3856.86,"id":9629296},{"batb":[[0,2,19.28],[1,1.99,15.08],[2,1.98,7.54]],"batl":[[0,2.06,12.89],[1,2.08,7.69],[2,2.12,117.46]],"ltp":1.87,"tv":3496.33,"id":12343905}]}]}
{"op":"mcm","clk":"4231797535","pt":1631548110305,"mc":[{"id":"1.187560634","rc":[{"batb":[[2,1.9,110.64]],"ltp":2.12,"tv":3856.86,"id":9629296},{"batb":[[0,2,63.82]],"ltp":1.87,"tv":3496.33,"id":12343905}]}]}
{"op":"mcm","clk":"4231797847","pt":1631548113519,"mc":[{"id":"1.187560634","rc":[{"trd":[[1.97,16.26]],"batb":[[2,1.9,15.8]],"batl":[[0,2,19.28],[1,2.2,437.07],[2,2.28,7.34]],"ltp":1.97,"tv":3873.12,"id":9629296},{"trd":[[2.02,48.24]],"ltp":2.02,"tv":3512.19,"id":12343905}],"tv":7385.32}]}
{"op":"mcm","clk":"4231798024","pt":1631548115645,"mc":[{"id":"1.187560634","rc":[{"batl":[[1,2.14,7.75],[2,2.2,445.1]],"ltp":1.97,"tv":3873.12,"id":9629296}]}]}
{"op":"mcm","clk":"4231798093","pt":1631548116452,"mc":[{"id":"1.187560634","rc":[{"batb":[[2,1.91,63.46]],"batl":[[0,1.98,79.47],[1,2,89.2],[2,2.14,7.75]],"ltp":1.97,"tv":3873.12,"id":9629296}]}]}
{"op":"mcm","clk":"4231798169","pt":1631548117255,"mc":[{"id":"1.187560634","rc":[{"trd":[[1.98,154.68]],"batl":[[0,1.98,63.71]],"ltp":1.98,"tv":3904.55,"id":9629296},{"trd":[[2.02,48.34]],"ltp":2.02,"tv":3512.29,"id":12343905}],"tv":7416.84}]}
{"op":"mcm","clk":"4231798411","pt":1631548120135,"mc":[{"id":"1.187560634","rc":[{"batb":[[2,1.91,72.44]],"batl":[[0,1.98,70.72]],"ltp":1.98,"tv":3904.55,"id":9629296}]}]}
{"op":"mcm","clk":"4231798906","pt":1631548126955,"mc":[{"id":"1.187560634","rc":[{"trd":[[1.98,156.42]],"batl":[[0,1.98,68.98]],"ltp":1.98,"tv":3906.29,"id":9629296},{"trd":[[2.02,50.04]],"ltp":2.02,"tv":3513.99,"id":12343905}],"tv":7420.29}]}
{"op":"mcm","clk":"4231799197","pt":1631548131652,"mc":[{"id":"1.187560634","rc":[{"batb":[[1,1.91,72.44],[2,1.89,81.63]],"batl":[[1,2,69.92]],"ltp":1.98,"tv":3906.29,"id":9629296},{"batb":[[0,2,44.54],[1,1.88,40.96],[2,1.87,7.91]],"batl":[[0,3,5.2],[1,2.08,0],[2,2.12,0]],"ltp":2.02,"tv":3513.99,"id":12343905}]}]}
{"op":"mcm","clk":"4231799242","pt":1631548132434,"mc":[{"id":"1.187560634","rc":[{"batb":[[0,1.94,28.97],[1,1.74,410.28],[2,1.63,44.37]],"batl":[[0,2.2,8.03],[1,3.25,4.8],[2,2.14,0]],"ltp":1.98,"tv":3906.29,"id":9629296},{"batb":[[0,1.87,7.91],[1,1.85,28.69],[2,1.84,35.22]],"ltp":2.02,"tv":3513.99,"id":12343905}]}]}
{"op":"mcm","clk":"4231799468","pt":1631548135375,"mc":[{"id":"1.187560634","rc":[{"batb":[[2,1.71,85.3]],"batl":[[0,2.16,71.47],[1,2.18,54.54],[2,2.2,8.03]],"ltp":1.98,"tv":3906.29,"id":9629296}]}]}
{"op":"mcm","clk":"4231799747","pt":1631548138662,"mc":[{"id":"1.187560634","rc":[{"batl":[[0,2.14,6.75],[1,2.16,71.47],[2,2.18,54.54]],"ltp":1.98,"tv":3906.29,"id":9629296},{"batb":[[0,1.88,36.46],[1,1.87,7.91],[2,1.85,28.69]],"ltp":2.02,"tv":3513.99,"id":12343905}]}]}
{"op":"mcm","clk":"4231799808","pt":1631548139496,"mc":[{"id":"1.187560634","rc":[{"batb":[[2,1.63,44.37]],"batl":[[0,2.2,8.03],[1,3.25,4.8],[2,2.18,0]],"ltp":1.98,"tv":3906.29,"id":9629296},{"batb":[[0,1.87,7.91],[1,1.85,28.69],[2,1.84,35.22]],"ltp":2.02,"tv":3513.99,"id":12343905}]}]}
{"op":"mcm","clk":"4231800019","pt":1631548142474,"mc":[{"id":"1.187560634","rc":[{"batl":[[0,2.16,11.94],[1,2.2,115.81],[2,3.25,4.8]],"ltp":1.98,"tv":3906.29,"id":9629296},{"batb":[[1,1.86,91.99],[2,1.85,28.69]],"batl":[[0,1.92,14.73],[1,1.93,70.84],[2,1.94,46.39]],"ltp":2.02,"tv":3513.99,"id":12343905}]}]}
{"op":"mcm","clk":"4231800114","pt":1631548143578,"mc":[{"id":"1.187560634","rc":[{"batb":[[0,1.94,78.13],[1,1.78,32.71],[2,1.74,410.28]],"ltp":1.98,"tv":3906.29,"id":9629296},{"batl":[[2,1.94,15.46]],"ltp":2.02,"tv":3513.99,"id":12343905}]}]}
{"op":"mcm","clk":"4231800330","pt":1631548146570,"mc":[{"id":"1.187560634","rc":[{"batb":[[0,1.94,78.03]],"ltp":1.98,"tv":3906.29,"id":9629296}]}]}
{"op":"mcm","clk":"4231800578","pt":1631548149459,"mc":[{"id":"1.187560634","rc":[{"batb":[[0,1.95,24.11],[1,1.94,78.03],[2,1.9,23.26]],"batl":[[2,2.26,6.75]],"ltp":1.98,"tv":3906.29,"id":9629296}]}]}
{"op":"mcm","clk":"4231800809","pt":1631548152187,"mc":[{"id":"1.187560634","rc":[{"trd":[[2.08,66.3]],"ltp":2.08,"tv":3906.38,"id":9629296},{"trd":[[1.92,0.1]],"batl":[[0,1.92,14.63]],"ltp":1.92,"tv":3514.09,"id":12343905}],"tv":7420.48}]}
{"op":"mcm","clk":"4231801108","pt":1631548155355,"mc":[{"id":"1.187560634","rc":[{"batb":[[1,1.94,49.15]],"ltp":2.08,"tv":3906.38,"id":9629296}]}]}
{"op":"mcm","clk":"4231801396","pt":1631548158506,"mc":[{"id":"1.187560634","rc":[{"batb":[[0,1.95,52.99]],"ltp":2.08,"tv":3906.38,"id":9629296}]}]}
{"op":"mcm","clk":"4231801824","pt":1631548162403,"mc":[{"id":"1.187560634","rc":[{"batl":[[0,2.2,115.81],[1,2.26,6.75],[2,2.3,5.95]],"ltp":2.08,"tv":3906.38,"id":9629296},{"batl":[[0,1.93,70.84],[1,1.94,15.46],[2,1.95,83.25]],"ltp":1.92,"tv":3514.09,"id":12343905}]}]}
{"op":"mcm","clk":"4231802063","pt":1631548165291,"mc":[{"id":"1.187560634","rc":[{"batl":[[0,2.16,12.03],[1,2.2,115.81],[2,2.26,6.75]],"ltp":2.08,"tv":3906.38,"id":9629296},{"batl":[[0,1.92,14.63],[1,1.93,70.84],[2,1.94,15.46]],"ltp":1.92,"tv":3514.09,"id":12343905}]}]}
{"op":"mcm","clk":"4231802515","pt":1631548171507,"mc":[{"id":"1.187560634","rc":[{"batb":[[0,1.95,28.88],[1,1.9,23.26],[2,1.78,32.71]],"batl":[[0,2.3,5.95],[1,3.25,4.8],[2,2.26,0]],"ltp":2.08,"tv":3906.38,"id":9629296},{"batb":[[1,1.77,38.37],[2,1.73,35.4]],"batl":[[0,2.12,7.46],[1,3,5.2],[2,1.94,0]],"ltp":1.92,"tv":3514.09,"id":12343905}]}]}
{"op":"mcm","clk":"4231802748","pt":1631548174503,"mc":[{"id":"1.187560634","rc":[{"batb":[[0,1.95,53.59]],"batl":[[0,2.26,7.25],[1,2.3,5.95],[2,3.25,4.8]],"ltp":2.08,"tv":3906.38,"id":9629296},{"batb":[[1,1.8,37.38],[2,1.77,38.37]],"batl":[[0,2.06,7.25],[1,2.12,7.46],[2,2.14,62.69]],"ltp":1.92,"tv":3514.09,"id":12343905}]}]}
{"op":"mcm","clk":"4231802776","pt":1631548174812,"mc":[{"id":"1.187560634","rc":[{"batb":[[0,1.95,28.88]],"batl":[[0,2.3,5.95],[1,3.25,4.8],[2,3.25,0]],"ltp":2.08,"tv":3906.38,"id":9629296},{"batb":[[1,1.77,38.37],[2,1.75,96.96]],"batl":[[0,2.12,7.46],[1,2.14,62.69],[2,2.16,55.94]],"ltp":1.92,"tv":3514.09,"id":12343905}]}]}
{"op":"mcm","clk":"4231803253","pt":1631548180329,"mc":[{"id":"1.187560634","rc":[{"batl":[[1,3,5.2],[2,2.16,0]],"ltp":1.92,"tv":3514.09,"id":12343905}]}]}
{"op":"mcm","clk":"4231803352","pt":1631548181599,"mc":[{"id":"1.187560634","rc":[{"batb":[[0,1.95,55.19]],"batl":[[0,2.26,7.25],[1,2.3,5.95],[2,3.25,4.8]],"ltp":2.08,"tv":3906.38,"id":9629296},{"batb":[[1,1.8,42.73],[2,1.77,38.37]],"batl":[[0,2.06,8.25],[1,2.12,7.46],[2,3,5.2]],"ltp":1.92,"tv":3514.09,"id":12343905}]}]}
{"op":"mcm","clk":"4231803373","pt":1631548181816,"mc":[{"id":"1.187560634","rc":[{"batb":[[0,1.95,28.88]],"batl":[[0,2.3,5.95],[1,3.25,4.8],[2,3.25,0]],"ltp":2.08,"tv":3906.38,"id":9629296},{"batb":[[1,1.77,38.37],[2,1.75,96.96]],"batl":[[0,2.12,7.46],[1,3,5.2],[2,3,0]],"ltp":1.92,"tv":3514.09,"id":12343905}]}]}
{"op":"mcm","clk":"4231803508","pt":1631548183341,"mc":[{"id":"1.187560634","rc":[{"batb":[[0,2.24,6.01],[1,1.95,28.88],[2,1.9,23.26]],"ltp":2.08,"tv":3906.38,"id":9629296},{"trd":[[1.87,24]],"batb":[[0,1.78,8.08]],"batl":[[0,1.81,71.63],[1,1.83,108.41],[2,1.84,116.9]],"ltp":1.87,"tv":3529.91,"id":12343905}],"tv":7436.3}]}
{"op":"mcm","clk":"4231803620","pt":1631548184343,"mc":[{"id":"1.187560634","rc":[{"batb":[[1,2.08,39.51],[2,1.96,48.15]],"ltp":2.08,"tv":3906.38,"id":9629296}]}]}
{"op":"mcm","clk":"4231803775","pt":1631548186138,"mc":[{"id":"1.187560634","rc":[{"batl":[[1,3.15,193.68],[2,3.25,4.8]],"ltp":2.08,"tv":3906.38,"id":9629296}]}]}
{"op":"mcm","clk":"4231804100","pt":1631548189822,"mc":[{"id":"1.187560634","rc":[{"batb":[[1,2.14,6.82],[2,2.1,7.14]],"batl":[[1,2.36,6.57],[2,2.4,6.89]],"ltp":2.08,"tv":3906.38,"id":9629296}]}]}
{"op":"mcm","clk":"4231804536","pt":1631548195131,"mc":[{"id":"1.187560634","rc":[{"trd":[[1.77,49.84],[1.78,40.5]],"batb":[[0,1.77,13.45],[1,1.75,96.96],[2,1.74,221.49]],"ltp":1.77,"tv":3595.91,"id":12343905}],"tv":7502.3}]}
{"op":"mcm","clk":"4231805100","pt":1631548201340,"mc":[{"id":"1.187560634","rc":[{"batl":[[0,1.78,1.71],[1,1.81,71.63],[2,1.83,108.41]],"ltp":1.77,"tv":3595.91,"id":12343905}]}]}
{"op":"mcm","clk":"4231805429","pt":1631548205334,"mc":[{"id":"1.187560634","rc":[{"batb":[[0,2.14,6.82],[1,2.1,7.14],[2,2.08,39.51]],"batl":[[2,2.38,5.75]],"ltp":2.08,"tv":3906.38,"id":9629296}]}]}
{"op":"mcm","clk":"4231805685","pt":1631548208563,"mc":[{"id":"1.187560634","rc":[{"batb":[[1,1.76,12.35],[2,1.75,96.96]],"batl":[[1,1.8,11.74],[2,1.81,71.63]],"ltp":1.77,"tv":3595.91,"id":12343905}]}]}
{"op":"mcm","clk":"4231805742","pt":1631548209253,"mc":[{"id":"1.187560634","rc":[{"batb":[[0,2.1,7.14],[1,1.96,48.15],[2,1.95,28.88]],"batl":[[0,2.42,5.75],[1,3.15,193.68],[2,3.25,4.8]],"ltp":2.08,"tv":3906.38,"id":9629296},{"batb":[[0,1.71,34.19],[1,1.67,40.01],[2,1.4,149.15]],"batl":[[1,1.9,26.15],[2,3,5.2]],"ltp":1.77,"tv":3595.91,"id":12343905}]}]}
{"op":"mcm","clk":"4231806226","pt":1631548215365,"mc":[{"id":"1.187560634","rc":[{"batb":[[0,1.77,91.02],[1,1.75,105.02],[2,1.71,34.19]],"batl":[[1,1.83,68.17],[2,1.85,88.9]],"ltp":1.77,"tv":3595.91,"id":12343905}]}]}
{"op":"mcm","clk":"4231806294","pt":1631548215846,"mc":[{"id":"1.187560634","rc":[{"batb":[[0,2.14,7.32],[1,2.1,7.14],[2,1.96,48.15]],"batl":[[0,2.38,6.25],[1,2.42,5.75],[2,3.15,193.68]],"ltp":2.08,"tv":3906.38,"id":9629296},{"batb":[[2,1.73,36.13]],"ltp":1.77,"tv":3595.91,"id":12343905}]}]}
{"op":"mcm","clk":"4231806666","pt":1631548219787,"mc":[{"id":"1.187560634","rc":[{"batb":[[0,2.1,7.14],[1,1.96,48.15],[2,1.95,28.88]],"ltp":2.08,"tv":3906.38,"id":9629296}]}]}
{"op":"mcm","clk":"4231806772","pt":1631548220940,"mc":[{"id":"1.187560634","rc":[{"batl":[[0,2.42,5.75],[1,3.15,193.68],[2,3.25,4.8]],"ltp":2.08,"tv":3906.38,"id":9629296},{"batb":[[0,1.71,34.19],[1,1.67,40.01],[2,1.4,149.15]],"batl":[[1,1.9,26.15],[2,3,5.2]],"ltp":1.77,"tv":3595.91,"id":12343905}]}]}
{"op":"mcm","clk":"4231806872","pt":1631548222090,"mc":[{"id":"1.187560634","rc":[{"batl":[[0,1.9,26.15],[1,3,5.2],[2,3,0]],"ltp":1.77,"tv":3595.91,"id":12343905}]}]}
{"op":"mcm","clk":"4231807007","pt":1631548223663,"mc":[{"id":"1.187560634","rc":[{"batb":[[1,1.69,101.46],[2,1.67,163.49]],"batl":[[1,1.92,75.75],[2,1.94,76.7]],"ltp":1.77,"tv":3595.91,"id":12343905}]}]}
{"op":"mcm","clk":"4231807147","pt":1631548225448,"mc":[{"id":"1.187560634","rc":[{"batl":[[0,1.76,1.71],[1,1.9,26.15],[2,3,5.2]],"ltp":1.77,"tv":3595.91,"id":12343905}]}]}
{"op":"mcm","clk":"4231807216","pt":1631548226495,"mc":[{"id":"1.187560634","rc":[{"batb":[[0,2.14,8.32],[1,2.1,7.14],[2,1.96,48.15]],"ltp":2.08,"tv":3906.38,"id":9629296},{"batl":[[1,1.87,27.73],[2,1.9,26.15]],"ltp":1.77,"tv":3595.91,"id":12343905}]}]}
{"op":"mcm","clk":"4231807239","pt":1631548226755,"mc":[{"id":"1.187560634","rc":[{"batb":[[0,2.1,7.14],[1,1.96,48.15],[2,1.95,28.88]],"ltp":2.08,"tv":3906.38,"id":9629296},{"batl":[[1,1.9,26.15],[2,3,5.2]],"ltp":1.77,"tv":3595.91,"id":12343905}]}]}
{"op":"mcm","clk":"4231807403","pt":1631548228586,"mc":[{"id":"1.187560634","rc":[{"batb":[[0,2.32,13.38],[1,2.1,7.14],[2,1.96,48.15]],"batl":[[0,2.4,7.58],[1,2.42,91.79],[2,3.15,193.68]],"ltp":2.08,"tv":3906.38,"id":9629296},{"batl":[[0,1.75,149.99],[1,1.76,27.43],[2,1.77,128.11]],"ltp":1.77,"tv":3595.91,"id":12343905}]}]}
{"op":"mcm","clk":"4231807495","pt":1631548229589,"mc":[{"id":"1.187560634","rc":[{"batb":[[1,2.18,34.56],[2,2.1,7.14]],"ltp":2.08,"tv":3906.38,"id":9629296},{"batb":[[2,1.67,181.45]],"batl":[[0,1.75,115.7],[1,1.76,10.29],[2,1.77,110.97]],"ltp":1.77,"tv":3595.91,"id":12343905}]}]}
{"op":"mcm","clk":"4231807895","pt":1631548234271,"mc":[{"id":"1.187560634","rc":[{"trd":[[2.4,10.55],[2.42,6.83]],"batl":[[0,2.42,85.66],[1,3.15,193.68],[2,3.25,4.8]],"ltp":2.42,"tv":3920.09,"id":9629296},{"trd":[[1.7,77],[1.71,83.19]],"batb":[[0,1.69,101.46],[1,1.67,181.45],[2,1.66,8.98]],"batl":[[0,1.71,9.87],[1,1.75,115.7],[2,1.76,10.29]],"ltp":1.7,"tv":3683.66,"id":12343905}],"tv":7603.76}]}
{"op":"mcm","clk":"4231808538","pt":1631548240880,"mc":[{"id":"1.187560634","rc":[{"trd":[[2.42,37.04]],"batl":[[0,2.42,55.45]],"ltp":2.42,"tv":3950.3,"id":9629296},{"trd":[[1.7,120]],"ltp":1.7,"tv":3726.66,"id":12343905}],"tv":7676.97}]}
{"op":"mcm","clk":"4231808804","pt":1631548243877,"mc":[{"id":"1.187560634","rc":[{"batb":[[0,2.18,34.56],[1,2.1,7.14],[2,2.02,43.03]],"ltp":2.42,"tv":3950.3,"id":9629296}]}]}
{"op":"mcm","clk":"4231809115","pt":1631548247183,"mc":[{"id":"1.187560634","rc":[{"batb":[[0,2.36,10.29],[1,2.18,34.56],[2,2.1,7.14]],"ltp":2.42,"tv":3950.3,"id":9629296},{"batb":[[0,1.7,10],[1,1.69,101.46],[2,1.67,181.45]],"ltp":1.7,"tv":3726.66,"id":12343905}]}]}
{"op":"mcm","clk":"4231810106","pt":1631548257915,"mc":[{"id":"1.187560634","rc":[{"trd":[[1.7,120.04]],"batb":[[0,1.7,9.98]],"ltp":1.7,"tv":3726.7,"id":12343905}],"tv":7677.01}]}
{"op":"mcm","clk":"4231810238","pt":1631548259329,"mc":[{"id":"1.187560634","rc":[{"trd":[[2.4,14.57]],"ltp":2.4,"tv":3954.33,"id":9629296},{"trd":[[1.71,88.83]],"batl":[[0,1.71,4.23]],"ltp":1.71,"tv":3732.35,"id":12343905}],"tv":7686.68}]}
