{"op":"mcm","clk":"4223820849","pt":1631450276634,"mc":[{"id":"1.187553972","marketDefinition":{"bspMarket":false,"turnInPlayEnabled":true,"persistenceEnabled":true,"marketBaseRate":5.0,"eventId":"30895616","eventTypeId":"2","numberOfWinners":1,"bettingType":"ODDS","marketType":"MATCH_ODDS","marketTime":"2021-09-12T14:00:00.000Z","suspendTime":"2021-09-12T14:00:00.000Z","bspReconciled":false,"complete":true,"inPlay":false,"crossMatching":false,"runnersVoidable":false,"numberOfActiveRunners":2,"betDelay":0,"status":"OPEN","runners":[{"status":"ACTIVE","sortPriority":1,"id":25088664,"name":"S Garakani"},{"status":"ACTIVE","sortPriority":2,"id":11772893,"name":"J Garland"}],"regulators":["MR_INT"],"countryCode":"GB","discountAllowed":false,"timezone":"GMT","openDate":"2021-09-12T15:00:00.000Z","version":4028154852,"name":"Match Odds","eventName":"S Garakani v J Garland"},"rc":[{"batb":[[0,1.01,25]],"ltp":0.0,"tv":0.0,"id":25088664},{"batb":[[0,1.01,25]],"ltp":0.0,"tv":0.0,"id":11772893}]}]}
{"op":"mcm","clk":"4223821189","pt":1631450278362,"mc":[{"id":"1.187553972","marketDefinition":{"bspMarket":false,"turnInPlayEnabled":true,"persistenceEnabled":true,"marketBaseRate":5.0,"eventId":"30895616","eventTypeId":"2","numberOfWinners":1,"bettingType":"ODDS","marketType":"MATCH_ODDS","marketTime":"2021-09-12T14:00:00.000Z","suspendTime":"2021-09-12T14:00:00.000Z","bspReconciled":false,"complete":true,"inPlay":false,"crossMatching":false,"runnersVoidable":false,"numberOfActiveRunners":2,"betDelay":0,"status":"OPEN","runners":[{"status":"ACTIVE","sortPriority":1,"id":25088664,"name":"S Garakani"},{"status":"ACTIVE","sortPriority":2,"id":11772893,"name":"J Garland"}],"regulators":["MR_INT"],"countryCode":"GB","discountAllowed":true,"timezone":"GMT","openDate":"2021-09-12T15:00:00.000Z","version":4028154852,"name":"Match Odds","eventName":"S Garakani v J Garland"}}]}
{"op":"mcm","clk":"4223899144","pt":1631450658022,"mc":[{"id":"1.187553972","rc":[{"batl":[[0,2,80]],"ltp":0.0,"tv":0.0,"id":11772893}]}]}
{"op":"mcm","clk":"4223909827","pt":1631450707086,"mc":[{"id":"1.187553972","rc":[{"batb":[[0,1.01,7]],"ltp":0.0,"tv":0.0,"id":25088664},{"batb":[[0,1.01,7]],"ltp":0.0,"tv":0.0,"id":11772893}]}]}
{"op":"mcm","clk":"4223954814","pt":1631450893692,"mc":[{"id":"1.187553972","rc":[{"batl":[[0,1.98,43.98],[1,2,80]],"ltp":0.0,"tv":0.0,"id":11772893}]}]}
{"op":"mcm","clk":"4224098798","pt":1631451739912,"mc":[{"id":"1.187553972","rc":[{"batb":[[0,40,10],[1,1.01,7]],"ltp":0.0,"tv":0.0,"id":25088664}]}]}
{"op":"mcm","clk":"4224101257","pt":1631451752008,"mc":[{"id":"1.187553972","marketDefinition":{"bspMarket":false,"turnInPlayEnabled":true,"persistenceEnabled":true,"marketBaseRate":5.0,"eventId":"30895616","eventTypeId":"2","numberOfWinners":1,"bettingType":"ODDS","marketType":"MATCH_ODDS","marketTime":"2021-09-12T14:00:00.000Z","suspendTime":"2021-09-12T14:00:00.000Z","bspReconciled":false,"complete":true,"inPlay":false,"crossMatching":true,"runnersVoidable":false,"numberOfActiveRunners":2,"betDelay":0,"status":"OPEN","runners":[{"status":"ACTIVE","sortPriority":1,"id":25088664,"name":"S Garakani"},{"status":"ACTIVE","sortPriority":2,"id":11772893,"name":"J Garland"}],"regulators":["MR_INT"],"countryCode":"GB","discountAllowed":true,"timezone":"GMT","openDate":"2021-09-12T15:00:00.000Z","version":4028154852,"name":"Match Odds","eventName":"S Garakani v J Garland"}}]}
{"op":"mcm","clk":"4224181078","pt":1631452119129,"mc":[{"id":"1.187553972","rc":[{"batl":[[0,1.68,2.66],[1,1.98,43.98],[2,2,80]],"ltp":0.0,"tv":0.0,"id":11772893}]}]}
{"op":"mcm","clk":"4224436319","pt":1631453308150,"mc":[{"id":"1.187553972","rc":[{"batl":[[0,1.6,43.98],[1,1.68,2.66]],"ltp":0.0,"tv":0.0,"id":11772893}]}]}
{"op":"mcm","clk":"4224683070","pt":1631454604905,"mc":[{"id":"1.187553972","rc":[{"batb":[[1,14.5,11.11],[2,1.01,7]],"ltp":0.0,"tv":0.0,"id":25088664}]}]}
{"op":"mcm","clk":"4224830088","pt":1631455449098,"mc":[{"id":"1.187553972","rc":[{"batl":[[0,1.21,80],[1,1.6,43.98],[2,1.68,2.66]],"ltp":0.0,"tv":0.0,"id":11772893}]}]}
{"op":"mcm","clk":"4225164313","pt":1631457074076,"mc":[{"id":"1.187553972","rc":[{"batl":[[0,1.2,43.98],[1,1.21,80]],"ltp":0.0,"tv":0.0,"id":11772893}]}]}
{"op":"mcm","clk":"4225413221","pt":1631458349494,"mc":[{"id":"1.187553972","rc":[{"batl":[[0,1.02,364.58],[1,1.2,43.98],[2,1.21,80]],"ltp":0.0,"tv":0.0,"id":11772893}]}]}
{"op":"mcm","clk":"4225423007","pt":1631458407330,"mc":[{"id":"1.187553972","rc":[{"batl":[[0,1.05,364.58]],"ltp":0.0,"tv":0.0,"id":11772893}]}]}
{"op":"mcm","clk":"4225423721","pt":1631458411629,"mc":[{"id":"1.187553972","rc":[{"batl":[[0,1.05,108.98]],"ltp":0.0,"tv":0.0,"id":11772893}]}]}
{"op":"mcm","clk":"4225425317","pt":1631458421142,"mc":[{"id":"1.187553972","rc":[{"batl":[[0,1.03,72.71],[1,1.05,108.98],[2,1.2,43.98]],"ltp":0.0,"tv":0.0,"id":11772893}]}]}
{"op":"mcm","clk":"4225456289","pt":1631458599537,"mc":[{"id":"1.187553972","rc":[{"batb":[[0,42,6.34],[1,40,10],[2,14.5,11.11]],"ltp":0.0,"tv":0.0,"id":25088664}]}]}
{"op":"mcm","clk":"4225489737","pt":1631458796282,"mc":[{"id":"1.187553972","rc":[{"batb":[[0,40,10],[1,14.5,11.11],[2,1.01,7]],"ltp":0.0,"tv":0.0,"id":25088664}]}]}
{"op":"mcm","clk":"4225490034","pt":1631458797969,"mc":[{"id":"1.187553972","rc":[{"batb":[[0,55,6.34],[1,40,10],[2,14.5,11.11]],"ltp":0.0,"tv":0.0,"id":25088664}]}]}
{"op":"mcm","clk":"4225507491","pt":1631458888328,"mc":[{"id":"1.187553972","marketDefinition":{"bspMarket":false,"turnInPlayEnabled":true,"persistenceEnabled":true,"marketBaseRate":5.0,"eventId":"30895616","eventTypeId":"2","numberOfWinners":1,"bettingType":"ODDS","marketType":"MATCH_ODDS","marketTime":"2021-09-12T14:00:00.000Z","suspendTime":"2021-09-12T14:00:00.000Z","bspReconciled":false,"complete":true,"inPlay":false,"crossMatching":true,"runnersVoidable":false,"numberOfActiveRunners":2,"betDelay":0,"status":"SUSPENDED","runners":[{"status":"ACTIVE","sortPriority":1,"id":25088664,"name":"S Garakani"},{"status":"ACTIVE","sortPriority":2,"id":11772893,"name":"J Garland"}],"regulators":["MR_INT"],"countryCode":"GB","discountAllowed":true,"timezone":"GMT","openDate":"2021-09-12T15:00:00.000Z","version":4028773765,"name":"Match Odds","eventName":"S Garakani v J Garland"}}]}
{"op":"mcm","clk":"4225507523","pt":1631458888513,"mc":[{"id":"1.187553972","marketDefinition":{"bspMarket":false,"turnInPlayEnabled":true,"persistenceEnabled":true,"marketBaseRate":5.0,"eventId":"30895616","eventTypeId":"2","numberOfWinners":1,"bettingType":"ODDS","marketType":"MATCH_ODDS","marketTime":"2021-09-12T14:00:00.000Z","suspendTime":"2021-09-12T14:00:00.000Z","bspReconciled":false,"complete":true,"inPlay":true,"crossMatching":true,"runnersVoidable":false,"numberOfActiveRunners":2,"betDelay":5,"status":"OPEN","runners":[{"status":"ACTIVE","sortPriority":1,"id":25088664,"name":"S Garakani"},{"status":"ACTIVE","sortPriority":2,"id":11772893,"name":"J Garland"}],"regulators":["MR_INT"],"countryCode":"GB","discountAllowed":true,"timezone":"GMT","openDate":"2021-09-12T15:00:00.000Z","version":4028773769,"name":"Match Odds","eventName":"S Garakani v J Garland"},"rc":[{"batb":[[0,1.01,7],[1,40,0],[2,14.5,0]],"ltp":0.0,"tv":0.0,"id":25088664},{"batl":[[2,1.21,80]],"ltp":0.0,"tv":0.0,"id":11772893}]}]}
{"op":"mcm","clk":"4225603438","pt":1631459378931,"mc":[{"id":"1.187553972","marketDefinition":{"bspMarket":false,"turnInPlayEnabled":true,"persistenceEnabled":true,"marketBaseRate":5.0,"eventId":"30895616","eventTypeId":"2","numberOfWinners":1,"bettingType":"ODDS","marketType":"MATCH_ODDS","marketTime":"2021-09-12T15:09:38.000Z","suspendTime":"2021-09-12T15:09:38.000Z","bspReconciled":false,"complete":true,"inPlay":true,"crossMatching":true,"runnersVoidable":false,"numberOfActiveRunners":2,"betDelay":5,"status":"OPEN","runners":[{"status":"ACTIVE","sortPriority":1,"id":25088664,"name":"S Garakani"},{"status":"ACTIVE","sortPriority":2,"id":11772893,"name":"J Garland"}],"regulators":["MR_INT"],"countryCode":"GB","discountAllowed":true,"timezone":"GMT","openDate":"2021-09-12T15:00:00.000Z","version":4028804091,"name":"Match Odds","eventName":"S Garakani v J Garland"}}]}
{"op":"mcm","clk":"4225604093","pt":1631459381967,"mc":[{"id":"1.187553972","marketDefinition":{"bspMarket":false,"turnInPlayEnabled":true,"persistenceEnabled":true,"marketBaseRate":5.0,"eventId":"30895616","eventTypeId":"2","numberOfWinners":1,"bettingType":"ODDS","marketType":"MATCH_ODDS","marketTime":"2021-09-12T15:09:38.000Z","suspendTime":"2021-09-12T15:09:38.000Z","bspReconciled":false,"complete":true,"inPlay":true,"crossMatching":true,"runnersVoidable":false,"numberOfActiveRunners":2,"betDelay":5,"status":"OPEN","runners":[{"status":"ACTIVE","sortPriority":1,"id":25088664,"name":"S Garakani"},{"status":"ACTIVE","sortPriority":2,"id":11772893,"name":"J Garland"}],"regulators":["MR_INT"],"countryCode":"GB","discountAllowed":true,"timezone":"GMT","openDate":"2021-09-12T15:09:38.000Z","version":4028804091,"name":"Match Odds","eventName":"S Garakani v J Garland"}}]}
{"op":"mcm","clk":"4225633456","pt":1631459534199,"mc":[{"id":"1.187553972","rc":[{"batb":[[0,4.6,380.58],[1,1.01,7]],"ltp":0.0,"tv":0.0,"id":25088664}]}]}
{"op":"mcm","clk":"4225641780","pt":1631459573188,"mc":[{"id":"1.187553972","rc":[{"trd":[[1.03,145.42]],"batb":[[0,1.03,927.29],[1,1.01,7]],"batl":[[0,1.05,108.98],[1,1.21,80],[2,1.21,0]],"ltp":1.03,"tv":145.41,"id":11772893}],"tv":145.41}]}
{"op":"mcm","clk":"4225647777","pt":1631459602360,"mc":[{"id":"1.187553972","rc":[{"batl":[[0,1.21,80],[1,1.21,0]],"ltp":1.03,"tv":145.41,"id":11772893}]}]}
{"op":"mcm","clk":"4225648268","pt":1631459604441,"mc":[{"id":"1.187553972","rc":[{"batl":[[0,1.04,105.52],[1,1.21,80]],"ltp":1.03,"tv":145.41,"id":11772893}]}]}
{"op":"mcm","clk":"4225648875","pt":1631459607465,"mc":[{"id":"1.187553972","rc":[{"batl":[[1,1.08,108.98],[2,1.21,80]],"ltp":1.03,"tv":145.41,"id":11772893}]}]}
{"op":"mcm","clk":"4225649932","pt":1631459612260,"mc":[{"id":"1.187553972","rc":[{"batl":[[1,1.21,80],[2,1.21,0]],"ltp":1.03,"tv":145.41,"id":11772893}]}]}
{"op":"mcm","clk":"4225651009","pt":1631459617375,"mc":[{"id":"1.187553972","rc":[{"batl":[[1,1.09,108.98],[2,1.21,80]],"ltp":1.03,"tv":145.41,"id":11772893}]}]}
{"op":"mcm","clk":"4225658987","pt":1631459656358,"mc":[{"id":"1.187553972","rc":[{"batb":[[0,1.01,7],[1,1.01,0]],"ltp":0.0,"tv":0.0,"id":25088664}]}]}
{"op":"mcm","clk":"4225660360","pt":1631459662552,"mc":[{"id":"1.187553972","rc":[{"batb":[[0,1.01,7],[1,1.01,0]],"ltp":1.03,"tv":145.41,"id":11772893}]}]}
{"op":"mcm","clk":"4225661497","pt":1631459667633,"mc":[{"id":"1.187553972","rc":[{"trd":[[1.04,211.04]],"batb":[[0,1.04,821.77],[1,1.01,7]],"batl":[[0,1.09,108.98],[1,1.21,80],[2,1.21,0]],"ltp":1.04,"tv":356.46,"id":11772893}],"tv":356.46}]}
{"op":"mcm","clk":"4225676094","pt":1631459735303,"mc":[{"id":"1.187553972","rc":[{"trd":[[1.04,321.04]],"batb":[[0,1.04,766.77]],"ltp":1.04,"tv":466.46,"id":11772893}],"tv":466.46}]}
{"op":"mcm","clk":"4225676121","pt":1631459735413,"mc":[{"id":"1.187553972","rc":[{"batb":[[0,1.01,7],[1,1.01,0]],"ltp":1.04,"tv":466.46,"id":11772893}]}]}
{"op":"mcm","clk":"4225702748","pt":1631459859024,"mc":[{"id":"1.187553972","rc":[{"batl":[[0,1.03,105.52],[1,1.09,108.98],[2,1.21,80]],"ltp":1.04,"tv":466.46,"id":11772893}]}]}
{"op":"mcm","clk":"4225713481","pt":1631459914538,"mc":[{"id":"1.187553972","rc":[{"trd":[[1.01,14]],"batl":[[0,1.01,10.08],[1,1.03,105.52],[2,1.09,108.98]],"ltp":1.01,"tv":480.46,"id":11772893}],"tv":480.46}]}
{"op":"mcm","clk":"4225742926","pt":1631460065402,"mc":[{"id":"1.187553972","rc":[{"trd":[[1.01,27.02]],"batl":[[0,1.01,3.57]],"ltp":1.01,"tv":493.48,"id":11772893}],"tv":493.48}]}
{"op":"mcm","clk":"4225747063","pt":1631460086133,"mc":[{"id":"1.187553972","rc":[{"batl":[[1,1.02,5.78],[2,1.03,105.52]],"ltp":1.01,"tv":493.48,"id":11772893}]}]}
{"op":"mcm","clk":"4225756649","pt":1631460134488,"mc":[{"id":"1.187553972","rc":[{"batl":[[2,1.09,108.98]],"ltp":1.01,"tv":493.48,"id":11772893}]}]}
{"op":"mcm","clk":"4225757631","pt":1631460139595,"mc":[{"id":"1.187553972","rc":[{"batl":[[1,1.02,111.31]],"ltp":1.01,"tv":493.48,"id":11772893}]}]}
{"op":"mcm","clk":"4225950074","pt":1631461234554,"mc":[{"id":"1.187553972","rc":[{"batl":[[1,1.02,5.78]],"ltp":1.01,"tv":493.48,"id":11772893}]}]}
{"op":"mcm","clk":"4225950990","pt":1631461239649,"mc":[{"id":"1.187553972","rc":[{"batl":[[2,1.03,105.52]],"ltp":1.01,"tv":493.48,"id":11772893}]}]}
{"op":"mcm","clk":"4225951723","pt":1631461243654,"mc":[{"id":"1.187553972","rc":[{"batb":[[0,290,3.63],[1,1.01,7]],"ltp":0.0,"tv":0.0,"id":25088664}]}]}
{"op":"mcm","clk":"4226013925","pt":1631461586956,"mc":[{"id":"1.187553972","marketDefinition":{"bspMarket":false,"turnInPlayEnabled":true,"persistenceEnabled":true,"marketBaseRate":5.0,"eventId":"30895616","eventTypeId":"2","numberOfWinners":1,"bettingType":"ODDS","marketType":"MATCH_ODDS","marketTime":"2021-09-12T15:09:38.000Z","suspendTime":"2021-09-12T15:09:38.000Z","bspReconciled":false,"complete":true,"inPlay":true,"crossMatching":true,"runnersVoidable":false,"numberOfActiveRunners":2,"betDelay":5,"status":"SUSPENDED","runners":[{"status":"ACTIVE","sortPriority":1,"id":25088664,"name":"S Garakani"},{"status":"ACTIVE","sortPriority":2,"id":11772893,"name":"J Garland"}],"regulators":["MR_INT"],"countryCode":"GB","discountAllowed":true,"timezone":"GMT","openDate":"2021-09-12T15:09:38.000Z","version":4028946763,"name":"Match Odds","eventName":"S Garakani v J Garland"}}]}
{"op":"mcm","clk":"4226014318","pt":1631461588996,"mc":[{"id":"1.187553972","marketDefinition":{"bspMarket":false,"turnInPlayEnabled":true,"persistenceEnabled":true,"marketBaseRate":5.0,"eventId":"30895616","eventTypeId":"2","numberOfWinners":1,"bettingType":"ODDS","marketType":"MATCH_ODDS","marketTime":"2021-09-12T15:09:38.000Z","suspendTime":"2021-09-12T15:09:38.000Z","bspReconciled":false,"complete":true,"inPlay":true,"crossMatching":false,"runnersVoidable":false,"numberOfActiveRunners":0,"betDelay":5,"status":"CLOSED","settledTime":"2021-09-12T15:46:27.000Z","runners":[{"status":"LOSER","sortPriority":1,"id":25088664,"name":"S Garakani"},{"status":"WINNER","sortPriority":2,"id":11772893,"name":"J Garland"}],"regulators":["MR_INT"],"countryCode":"GB","discountAllowed":true,"timezone":"GMT","openDate":"2021-09-12T15:09:38.000Z","version":4028946981,"name":"Match Odds","eventName":"S Garakani v J Garland"},"tv":0.0}]}
