{"op":"mcm","clk":"4229503643","pt":1631518765916,"mc":[{"id":"1.187595434","marketDefinition":{"bspMarket":false,"turnInPlayEnabled":true,"persistenceEnabled":true,"marketBaseRate":5.0,"eventId":"30897890","eventTypeId":"2","numberOfWinners":1,"bettingType":"ODDS","marketType":"MATCH_ODDS","marketTime":"2021-09-13T06:30:00.000Z","suspendTime":"2021-09-13T06:30:00.000Z","bspReconciled":false,"complete":true,"inPlay":false,"crossMatching":false,"runnersVoidable":false,"numberOfActiveRunners":2,"betDelay":0,"status":"OPEN","runners":[{"status":"ACTIVE","sortPriority":1,"id":9589287,"name":"A Carreras"},{"status":"ACTIVE","sortPriority":2,"id":21397559,"name":"O Selekhmeteva"}],"regulators":["MR_INT"],"countryCode":"GB","discountAllowed":false,"timezone":"GMT","openDate":"2021-09-13T09:30:00.000Z","version":4030167316,"name":"Match Odds","eventName":"A Carreras v O Selekhmeteva"},"rc":[{"batb":[[0,1.01,25]],"ltp":0.0,"tv":0.0,"id":21397559},{"batb":[[0,1.01,25]],"ltp":0.0,"tv":0.0,"id":9589287}]}]}
{"op":"mcm","clk":"4229503711","pt":1631518767640,"mc":[{"id":"1.187595434","marketDefinition":{"bspMarket":false,"turnInPlayEnabled":true,"persistenceEnabled":true,"marketBaseRate":5.0,"eventId":"30897890","eventTypeId":"2","numberOfWinners":1,"bettingType":"ODDS","marketType":"MATCH_ODDS","marketTime":"2021-09-13T06:30:00.000Z","suspendTime":"2021-09-13T06:30:00.000Z","bspReconciled":false,"complete":true,"inPlay":false,"crossMatching":false,"runnersVoidable":false,"numberOfActiveRunners":2,"betDelay":0,"status":"OPEN","runners":[{"status":"ACTIVE","sortPriority":1,"id":9589287,"name":"A Carreras"},{"status":"ACTIVE","sortPriority":2,"id":21397559,"name":"O Selekhmeteva"}],"regulators":["MR_INT"],"countryCode":"GB","discountAllowed":true,"timezone":"GMT","openDate":"2021-09-13T09:30:00.000Z","version":4030167316,"name":"Match Odds","eventName":"A Carreras v O Selekhmeteva"}}]}
{"op":"mcm","clk":"4229517273","pt":1631519123030,"mc":[{"id":"1.187595434","rc":[{"batb":[[0,1.01,7]],"ltp":0.0,"tv":0.0,"id":21397559},{"batb":[[0,1.01,7]],"ltp":0.0,"tv":0.0,"id":9589287}]}]}
{"op":"mcm","clk":"4229671731","pt":1631522286716,"mc":[{"id":"1.187595434","rc":[{"batl":[[0,1.82,2.66]],"ltp":0.0,"tv":0.0,"id":21397559}]}]}
{"op":"mcm","clk":"4229671899","pt":1631522291341,"mc":[{"id":"1.187595434","rc":[{"batb":[[0,1.03,53.23],[1,1.01,7]],"ltp":0.0,"tv":0.0,"id":21397559}]}]}
{"op":"mcm","clk":"4229695594","pt":1631522805685,"mc":[{"id":"1.187595434","rc":[{"batb":[[0,1.05,880.88],[1,1.03,53.23],[2,1.01,7]],"ltp":0.0,"tv":0.0,"id":21397559},{"batb":[[0,1.05,880.88],[1,1.01,7]],"ltp":0.0,"tv":0.0,"id":9589287}]}]}
{"op":"mcm","clk":"4229740568","pt":1631523736281,"mc":[{"id":"1.187595434","rc":[{"batb":[[0,1.05,880.36],[1,1.03,53.28]],"batl":[[0,1.8,100],[1,1.82,2.66]],"ltp":0.0,"tv":0.0,"id":21397559},{"batb":[[0,1.05,880.36]],"ltp":0.0,"tv":0.0,"id":9589287}]}]}
{"op":"mcm","clk":"4229741891","pt":1631523763264,"mc":[{"id":"1.187595434","marketDefinition":{"bspMarket":false,"turnInPlayEnabled":true,"persistenceEnabled":true,"marketBaseRate":5.0,"eventId":"30897890","eventTypeId":"2","numberOfWinners":1,"bettingType":"ODDS","marketType":"MATCH_ODDS","marketTime":"2021-09-13T06:30:00.000Z","suspendTime":"2021-09-13T06:30:00.000Z","bspReconciled":false,"complete":true,"inPlay":false,"crossMatching":true,"runnersVoidable":false,"numberOfActiveRunners":2,"betDelay":0,"status":"OPEN","runners":[{"status":"ACTIVE","sortPriority":1,"id":9589287,"name":"A Carreras"},{"status":"ACTIVE","sortPriority":2,"id":21397559,"name":"O Selekhmeteva"}],"regulators":["MR_INT"],"countryCode":"GB","discountAllowed":true,"timezone":"GMT","openDate":"2021-09-13T09:30:00.000Z","version":4030167316,"name":"Match Odds","eventName":"A Carreras v O Selekhmeteva"}}]}
{"op":"mcm","clk":"4229743023","pt":1631523785965,"mc":[{"id":"1.187595434","rc":[{"batb":[[0,1.17,245.69],[1,1.05,880.36],[2,1.03,53.28]],"ltp":0.0,"tv":0.0,"id":21397559},{"batb":[[0,4.5,11.93],[1,1.05,880.36],[2,1.01,7]],"ltp":0.0,"tv":0.0,"id":9589287}]}]}
{"op":"mcm","clk":"4229761156","pt":1631524103828,"mc":[{"id":"1.187595434","rc":[{"batb":[[1,1.01,7],[2,1.01,0]],"ltp":0.0,"tv":0.0,"id":9589287}]}]}
{"op":"mcm","clk":"4229761522","pt":1631524109743,"mc":[{"id":"1.187595434","rc":[{"batl":[[0,1.78,44.02],[1,1.8,100],[2,1.82,2.66]],"ltp":0.0,"tv":0.0,"id":21397559}]}]}
{"op":"mcm","clk":"4229804028","pt":1631524820298,"mc":[{"id":"1.187595434","rc":[{"batb":[[1,1.16,2.66],[2,1.05,880.36]],"ltp":0.0,"tv":0.0,"id":21397559},{"batb":[[1,4.4,2.66],[2,1.01,7]],"ltp":0.0,"tv":0.0,"id":9589287}]}]}
{"op":"mcm","clk":"4229804352","pt":1631524825203,"mc":[{"id":"1.187595434","rc":[{"batl":[[0,1.28,100],[1,1.78,44.02]],"ltp":0.0,"tv":0.0,"id":21397559}]}]}
{"op":"mcm","clk":"4229824037","pt":1631525174530,"mc":[{"id":"1.187595434","marketDefinition":{"bspMarket":false,"turnInPlayEnabled":true,"persistenceEnabled":true,"marketBaseRate":5.0,"eventId":"30897890","eventTypeId":"2","numberOfWinners":1,"bettingType":"ODDS","marketType":"MATCH_ODDS","marketTime":"2021-09-13T09:25:00.000Z","suspendTime":"2021-09-13T09:25:00.000Z","bspReconciled":false,"complete":true,"inPlay":false,"crossMatching":true,"runnersVoidable":false,"numberOfActiveRunners":2,"betDelay":0,"status":"OPEN","runners":[{"status":"ACTIVE","sortPriority":1,"id":9589287,"name":"A Carreras"},{"status":"ACTIVE","sortPriority":2,"id":21397559,"name":"O Selekhmeteva"}],"regulators":["MR_INT"],"countryCode":"GB","discountAllowed":true,"timezone":"GMT","openDate":"2021-09-13T09:30:00.000Z","version":4030502536,"name":"Match Odds","eventName":"A Carreras v O Selekhmeteva"}}]}
{"op":"mcm","clk":"4229824247","pt":1631525178551,"mc":[{"id":"1.187595434","marketDefinition":{"bspMarket":false,"turnInPlayEnabled":true,"persistenceEnabled":true,"marketBaseRate":5.0,"eventId":"30897890","eventTypeId":"2","numberOfWinners":1,"bettingType":"ODDS","marketType":"MATCH_ODDS","marketTime":"2021-09-13T09:25:00.000Z","suspendTime":"2021-09-13T09:25:00.000Z","bspReconciled":false,"complete":true,"inPlay":false,"crossMatching":true,"runnersVoidable":false,"numberOfActiveRunners":2,"betDelay":0,"status":"OPEN","runners":[{"status":"ACTIVE","sortPriority":1,"id":9589287,"name":"A Carreras"},{"status":"ACTIVE","sortPriority":2,"id":21397559,"name":"O Selekhmeteva"}],"regulators":["MR_INT"],"countryCode":"GB","discountAllowed":true,"timezone":"GMT","openDate":"2021-09-13T09:25:00.000Z","version":4030502536,"name":"Match Odds","eventName":"A Carreras v O Selekhmeteva"}}]}
{"op":"mcm","clk":"4229824341","pt":1631525180310,"mc":[{"id":"1.187595434","rc":[{"batb":[[0,4.4,2.66],[1,4,13.92]],"ltp":0.0,"tv":0.0,"id":9589287}]}]}
{"op":"mcm","clk":"4229830101","pt":1631525290150,"mc":[{"id":"1.187595434","marketDefinition":{"bspMarket":false,"turnInPlayEnabled":true,"persistenceEnabled":true,"marketBaseRate":5.0,"eventId":"30897890","eventTypeId":"2","numberOfWinners":1,"bettingType":"ODDS","marketType":"MATCH_ODDS","marketTime":"2021-09-13T09:25:00.000Z","suspendTime":"2021-09-13T09:25:00.000Z","bspReconciled":false,"complete":true,"inPlay":true,"crossMatching":true,"runnersVoidable":false,"numberOfActiveRunners":2,"betDelay":5,"status":"OPEN","runners":[{"status":"ACTIVE","sortPriority":1,"id":9589287,"name":"A Carreras"},{"status":"ACTIVE","sortPriority":2,"id":21397559,"name":"O Selekhmeteva"}],"regulators":["MR_INT"],"countryCode":"GB","discountAllowed":true,"timezone":"GMT","openDate":"2021-09-13T09:25:00.000Z","version":4030503798,"name":"Match Odds","eventName":"A Carreras v O Selekhmeteva"},"rc":[{"batb":[[0,1.01,7],[1,1.16,0],[2,1.05,0]],"batl":[[1,1.78,0],[2,1.82,0]],"ltp":0.0,"tv":0.0,"id":21397559},{"batb":[[0,1.01,7],[1,4,0],[2,1.01,0]],"ltp":0.0,"tv":0.0,"id":9589287}]}]}
{"op":"mcm","clk":"4229871238","pt":1631525929267,"mc":[{"id":"1.187595434","marketDefinition":{"bspMarket":false,"turnInPlayEnabled":true,"persistenceEnabled":true,"marketBaseRate":5.0,"eventId":"30897890","eventTypeId":"2","numberOfWinners":1,"bettingType":"ODDS","marketType":"MATCH_ODDS","marketTime":"2021-09-13T09:38:48.000Z","suspendTime":"2021-09-13T09:38:48.000Z","bspReconciled":false,"complete":true,"inPlay":true,"crossMatching":true,"runnersVoidable":false,"numberOfActiveRunners":2,"betDelay":5,"status":"OPEN","runners":[{"status":"ACTIVE","sortPriority":1,"id":9589287,"name":"A Carreras"},{"status":"ACTIVE","sortPriority":2,"id":21397559,"name":"O Selekhmeteva"}],"regulators":["MR_INT"],"countryCode":"GB","discountAllowed":true,"timezone":"GMT","openDate":"2021-09-13T09:25:00.000Z","version":4030511421,"name":"Match Odds","eventName":"A Carreras v O Selekhmeteva"}}]}
{"op":"mcm","clk":"4229871428","pt":1631525932282,"mc":[{"id":"1.187595434","marketDefinition":{"bspMarket":false,"turnInPlayEnabled":true,"persistenceEnabled":true,"marketBaseRate":5.0,"eventId":"30897890","eventTypeId":"2","numberOfWinners":1,"bettingType":"ODDS","marketType":"MATCH_ODDS","marketTime":"2021-09-13T09:38:48.000Z","suspendTime":"2021-09-13T09:38:48.000Z","bspReconciled":false,"complete":true,"inPlay":true,"crossMatching":true,"runnersVoidable":false,"numberOfActiveRunners":2,"betDelay":5,"status":"OPEN","runners":[{"status":"ACTIVE","sortPriority":1,"id":9589287,"name":"A Carreras"},{"status":"ACTIVE","sortPriority":2,"id":21397559,"name":"O Selekhmeteva"}],"regulators":["MR_INT"],"countryCode":"GB","discountAllowed":true,"timezone":"GMT","openDate":"2021-09-13T09:38:48.000Z","version":4030511421,"name":"Match Odds","eventName":"A Carreras v O Selekhmeteva"}}]}
{"op":"mcm","clk":"4229875216","pt":1631525990580,"mc":[{"id":"1.187595434","rc":[{"trd":[[1.28,66.67]],"batl":[[0,1.28,33.33]],"ltp":1.28,"tv":66.67,"id":21397559},{"trd":[[4.5,18.96]],"ltp":4.5,"tv":18.96,"id":9589287}],"tv":85.63}]}
{"op":"mcm","clk":"4229875567","pt":1631525995412,"mc":[{"id":"1.187595434","rc":[{"trd":[[1.28,91.05]],"batl":[[0,1.28,21.14]],"ltp":1.28,"tv":91.04,"id":21397559}],"tv":110.01}]}
{"op":"mcm","clk":"4229875650","pt":1631525996497,"mc":[{"id":"1.187595434","rc":[{"trd":[[1.28,112.19]],"ltp":1.28,"tv":112.18,"id":21397559},{"trd":[[4.5,24.97]],"batl":[[0,4.5,2.99]],"ltp":4.5,"tv":24.97,"id":9589287}],"tv":137.16}]}
{"op":"mcm","clk":"4229877500","pt":1631526022158,"mc":[{"id":"1.187595434","rc":[{"batb":[[0,1.27,256.04],[1,1.18,256.04],[2,1.01,7]],"ltp":1.28,"tv":112.18,"id":21397559}]}]}
{"op":"mcm","clk":"4229891995","pt":1631526204089,"mc":[{"id":"1.187595434","rc":[{"batb":[[0,1.18,256.04],[1,1.01,7],[2,1.01,0]],"ltp":1.28,"tv":112.18,"id":21397559}]}]}
{"op":"mcm","clk":"4229892133","pt":1631526206218,"mc":[{"id":"1.187595434","rc":[{"batb":[[0,1.01,7],[1,1.01,0]],"ltp":1.28,"tv":112.18,"id":21397559}]}]}
{"op":"mcm","clk":"4229892407","pt":1631526209803,"mc":[{"id":"1.187595434","rc":[{"batb":[[0,1.24,256.04],[1,1.01,7]],"ltp":1.28,"tv":112.18,"id":21397559}]}]}
{"op":"mcm","clk":"4229894594","pt":1631526245836,"mc":[{"id":"1.187595434","rc":[{"batb":[[0,1.01,7],[1,1.01,0]],"ltp":1.28,"tv":112.18,"id":21397559}]}]}
{"op":"mcm","clk":"4229894978","pt":1631526251576,"mc":[{"id":"1.187595434","rc":[{"batb":[[0,1.18,256.04],[1,1.01,7]],"ltp":1.28,"tv":112.18,"id":21397559}]}]}
{"op":"mcm","clk":"4229895135","pt":1631526254175,"mc":[{"id":"1.187595434","rc":[{"batl":[[0,1.43,256.04]],"ltp":1.28,"tv":112.18,"id":21397559}]}]}
{"op":"mcm","clk":"4229897094","pt":1631526286710,"mc":[{"id":"1.187595434","rc":[{"trd":[[1.18,512.08]],"batb":[[0,1.01,7],[1,1.01,0]],"batl":[[0,1.18,20.21]],"ltp":1.18,"tv":624.26,"id":21397559}],"tv":649.23}]}
{"op":"mcm","clk":"4229897373","pt":1631526290733,"mc":[{"id":"1.187595434","rc":[{"batl":[[1,1.51,256.04]],"ltp":1.18,"tv":624.26,"id":21397559}]}]}
{"op":"mcm","clk":"4229897698","pt":1631526295490,"mc":[{"id":"1.187595434","rc":[{"trd":[[1.18,552.51]],"batb":[[0,1.18,33.35],[1,1.01,7]],"batl":[[0,1.51,256.04],[1,1.51,0]],"ltp":1.18,"tv":664.69,"id":21397559}],"tv":689.67}]}
{"op":"mcm","clk":"4229897772","pt":1631526296625,"mc":[{"id":"1.187595434","rc":[{"batb":[[0,1.18,245.36]],"batl":[[0,1.27,237.89],[1,1.51,256.04]],"ltp":1.18,"tv":664.69,"id":21397559}]}]}
{"op":"mcm","clk":"4229897843","pt":1631526297532,"mc":[{"id":"1.187595434","rc":[{"batb":[[0,1.18,212.18]],"ltp":1.18,"tv":664.69,"id":21397559}]}]}
{"op":"mcm","clk":"4229897920","pt":1631526298409,"mc":[{"id":"1.187595434","rc":[{"batb":[[0,1.19,256.04],[1,1.18,173.42],[2,1.01,7]],"ltp":1.18,"tv":664.69,"id":21397559}]}]}
{"op":"mcm","clk":"4229897993","pt":1631526299538,"mc":[{"id":"1.187595434","rc":[{"batb":[[1,1.18,53.75]],"ltp":1.18,"tv":664.69,"id":21397559}]}]}
{"op":"mcm","clk":"4229898066","pt":1631526300531,"mc":[{"id":"1.187595434","rc":[{"batb":[[1,1.18,180]],"ltp":1.18,"tv":664.69,"id":21397559}]}]}
{"op":"mcm","clk":"4229898153","pt":1631526301626,"mc":[{"id":"1.187595434","rc":[{"batb":[[1,1.18,120]],"ltp":1.18,"tv":664.69,"id":21397559}]}]}
{"op":"mcm","clk":"4229898204","pt":1631526302416,"mc":[{"id":"1.187595434","rc":[{"batb":[[1,1.18,20]],"ltp":1.18,"tv":664.69,"id":21397559}]}]}
{"op":"mcm","clk":"4229898252","pt":1631526303035,"mc":[{"id":"1.187595434","rc":[{"batb":[[0,1.2,256.04],[1,1.19,256.04]],"ltp":1.18,"tv":664.69,"id":21397559}]}]}
{"op":"mcm","clk":"4229898468","pt":1631526305825,"mc":[{"id":"1.187595434","rc":[{"batb":[[0,1.19,256.04],[1,1.01,7],[2,1.01,0]],"ltp":1.18,"tv":664.69,"id":21397559}]}]}
{"op":"mcm","clk":"4229898725","pt":1631526309333,"mc":[{"id":"1.187595434","rc":[{"batl":[[0,1.51,256.04],[1,1.51,0]],"ltp":1.18,"tv":664.69,"id":21397559}]}]}
{"op":"mcm","clk":"4229898980","pt":1631526313414,"mc":[{"id":"1.187595434","rc":[{"batl":[[0,1.22,247.64],[1,1.51,256.04]],"ltp":1.18,"tv":664.69,"id":21397559}]}]}
{"op":"mcm","clk":"4229899176","pt":1631526316569,"mc":[{"id":"1.187595434","rc":[{"batb":[[1,1.15,256.04],[2,1.1,256.04]],"ltp":1.18,"tv":664.69,"id":21397559}]}]}
{"op":"mcm","clk":"4229899426","pt":1631526319942,"mc":[{"id":"1.187595434","rc":[{"trd":[[1.22,9.7]],"batl":[[0,1.22,237.94]],"ltp":1.22,"tv":674.39,"id":21397559},{"trd":[[5.5,2.15]],"ltp":5.5,"tv":27.12,"id":9589287}],"tv":701.51}]}
{"op":"mcm","clk":"4229900549","pt":1631526336662,"mc":[{"id":"1.187595434","rc":[{"trd":[[1.22,149.61]],"batl":[[0,1.22,167.99]],"ltp":1.22,"tv":814.3,"id":21397559}],"tv":841.43}]}
{"op":"mcm","clk":"4229900773","pt":1631526340286,"mc":[{"id":"1.187595434","rc":[{"batl":[[0,1.51,256.04],[1,1.51,0]],"ltp":1.22,"tv":814.3,"id":21397559}]}]}
{"op":"mcm","clk":"4229901158","pt":1631526345987,"mc":[{"id":"1.187595434","rc":[{"batb":[[0,2.42,387.76],[1,1.01,7]],"batl":[[0,5.5,116.87]],"ltp":5.5,"tv":27.12,"id":9589287}]}]}
{"op":"mcm","clk":"4229901208","pt":1631526346878,"mc":[{"id":"1.187595434","rc":[{"batl":[[0,1.3,157.65],[1,1.51,256.04]],"ltp":1.22,"tv":814.3,"id":21397559}]}]}
{"op":"mcm","clk":"4229901306","pt":1631526348183,"mc":[{"id":"1.187595434","rc":[{"batb":[[0,1.25,256.04],[1,1.23,256.04],[2,1.19,256.04]],"ltp":1.22,"tv":814.3,"id":21397559}]}]}
{"op":"mcm","clk":"4229903002","pt":1631526375506,"mc":[{"id":"1.187595434","rc":[{"batl":[[0,1.51,256.04],[1,1.51,0]],"ltp":1.22,"tv":814.3,"id":21397559}]}]}
{"op":"mcm","clk":"4229903487","pt":1631526384211,"mc":[{"id":"1.187595434","rc":[{"batl":[[0,1.3,157.65],[1,1.51,256.04]],"ltp":1.22,"tv":814.3,"id":21397559}]}]}
{"op":"mcm","clk":"4229903895","pt":1631526391134,"mc":[{"id":"1.187595434","rc":[{"batb":[[1,1.19,256.04],[2,1.15,256.04]],"ltp":1.22,"tv":814.3,"id":21397559}]}]}
{"op":"mcm","clk":"4229904805","pt":1631526404716,"mc":[{"id":"1.187595434","rc":[{"trd":[[1.3,131.3]],"batl":[[0,1.3,92]],"ltp":1.3,"tv":945.6,"id":21397559}],"tv":972.72}]}
{"op":"mcm","clk":"4229905031","pt":1631526408143,"mc":[{"id":"1.187595434","rc":[{"batl":[[0,1.51,256.04],[1,1.51,0]],"ltp":1.3,"tv":945.6,"id":21397559}]}]}
{"op":"mcm","clk":"4229905325","pt":1631526412860,"mc":[{"id":"1.187595434","rc":[{"batl":[[0,4.9,128.27]],"ltp":5.5,"tv":27.12,"id":9589287}]}]}
{"op":"mcm","clk":"4229905395","pt":1631526413948,"mc":[{"id":"1.187595434","rc":[{"batb":[[1,1.15,256.04],[2,1.1,256.04]],"ltp":1.3,"tv":945.6,"id":21397559}]}]}
{"op":"mcm","clk":"4229905483","pt":1631526414933,"mc":[{"id":"1.187595434","rc":[{"batb":[[1,1.1,256.04],[2,1.01,7]],"batl":[[0,1.35,88.6],[1,1.51,256.04]],"ltp":1.3,"tv":945.6,"id":21397559}]}]}
{"op":"mcm","clk":"4229905769","pt":1631526418150,"mc":[{"id":"1.187595434","rc":[{"batb":[[0,1.3,256.04],[1,1.25,256.04],[2,1.1,256.04]],"ltp":1.3,"tv":945.6,"id":21397559}]}]}
{"op":"mcm","clk":"4229906040","pt":1631526421061,"mc":[{"id":"1.187595434","rc":[{"batb":[[2,1.17,256.04]],"ltp":1.3,"tv":945.6,"id":21397559}]}]}
{"op":"mcm","clk":"4229906103","pt":1631526421740,"mc":[{"id":"1.187595434","rc":[{"batb":[[2,1.2,256.04]],"ltp":1.3,"tv":945.6,"id":21397559}]}]}
{"op":"mcm","clk":"4229920386","pt":1631526516076,"mc":[{"id":"1.187595434","rc":[{"batb":[[0,1.01,7],[1,1.01,0]],"ltp":5.5,"tv":27.12,"id":9589287}]}]}
{"op":"mcm","clk":"4229920453","pt":1631526516962,"mc":[{"id":"1.187595434","rc":[{"batl":[[0,1.51,256.04],[1,1.51,0]],"ltp":1.3,"tv":945.6,"id":21397559}]}]}
{"op":"mcm","clk":"4229920861","pt":1631526522298,"mc":[{"id":"1.187595434","rc":[{"batb":[[0,2.12,394.79],[1,1.01,7]],"batl":[[0,4.2,150.36]],"ltp":5.5,"tv":27.12,"id":9589287}]}]}
{"op":"mcm","clk":"4229920902","pt":1631526522896,"mc":[{"id":"1.187595434","rc":[{"batb":[[0,1.4,256.04],[1,1.3,256.04],[2,1.25,256.04]],"ltp":1.3,"tv":945.6,"id":21397559}]}]}
{"op":"mcm","clk":"4229921260","pt":1631526527402,"mc":[{"id":"1.187595434","rc":[{"batl":[[0,1.45,82.49]],"ltp":1.3,"tv":945.6,"id":21397559}]}]}
{"op":"mcm","clk":"4229922833","pt":1631526550133,"mc":[{"id":"1.187595434","rc":[{"batb":[[0,1.3,256.04],[1,1.25,256.04],[2,1.2,256.04]],"ltp":1.3,"tv":945.6,"id":21397559}]}]}
{"op":"mcm","clk":"4229923324","pt":1631526558347,"mc":[{"id":"1.187595434","rc":[{"batl":[[0,1.4,85.43]],"ltp":1.3,"tv":945.6,"id":21397559}]}]}
{"op":"mcm","clk":"4229923967","pt":1631526567924,"mc":[{"id":"1.187595434","rc":[{"batb":[[0,1.01,7],[1,1.01,0]],"ltp":5.5,"tv":27.12,"id":9589287}]}]}
{"op":"mcm","clk":"4229924273","pt":1631526571838,"mc":[{"id":"1.187595434","rc":[{"batb":[[0,1.25,256.04],[1,1.2,256.04],[2,1.17,256.04]],"ltp":1.3,"tv":945.6,"id":21397559}]}]}
{"op":"mcm","clk":"4229924414","pt":1631526573829,"mc":[{"id":"1.187595434","rc":[{"batb":[[0,2.38,388.33],[1,1.01,7]],"batl":[[0,5.3,120.66]],"ltp":5.5,"tv":27.12,"id":9589287}]}]}
{"op":"mcm","clk":"4229924730","pt":1631526578547,"mc":[{"id":"1.187595434","rc":[{"batl":[[0,1.3,92],[1,1.4,85.43]],"ltp":1.3,"tv":945.6,"id":21397559}]}]}
{"op":"mcm","clk":"4229924805","pt":1631526579542,"mc":[{"id":"1.187595434","rc":[{"batl":[[1,1.4,0]],"ltp":1.3,"tv":945.6,"id":21397559}]}]}
{"op":"mcm","clk":"4229924856","pt":1631526580255,"mc":[{"id":"1.187595434","rc":[{"batb":[[0,1.28,256.04],[1,1.25,256.04],[2,1.2,256.04]],"ltp":1.3,"tv":945.6,"id":21397559}]}]}
{"op":"mcm","clk":"4229925635","pt":1631526593354,"mc":[{"id":"1.187595434","rc":[{"batl":[[0,1.33,89.93]],"ltp":1.3,"tv":945.6,"id":21397559}]}]}
{"op":"mcm","clk":"4229928270","pt":1631526631997,"mc":[{"id":"1.187595434","rc":[{"batl":[[0,4.6,138.2]],"ltp":5.5,"tv":27.12,"id":9589287}]}]}
{"op":"mcm","clk":"4229928332","pt":1631526633025,"mc":[{"id":"1.187595434","rc":[{"batb":[[0,1.36,256.04],[1,1.28,256.04],[2,1.25,256.04]],"ltp":1.3,"tv":945.6,"id":21397559}]}]}
{"op":"mcm","clk":"4229928424","pt":1631526634419,"mc":[{"id":"1.187595434","rc":[{"batl":[[0,1.41,84.83]],"ltp":1.3,"tv":945.6,"id":21397559}]}]}
{"op":"mcm","clk":"4229929721","pt":1631526653644,"mc":[{"id":"1.187595434","rc":[{"batb":[[0,1.28,256.04],[1,1.25,256.04],[2,1.2,256.04]],"ltp":1.3,"tv":945.6,"id":21397559}]}]}
{"op":"mcm","clk":"4229929955","pt":1631526657663,"mc":[{"id":"1.187595434","rc":[{"batl":[[0,5.5,116.87]],"ltp":5.5,"tv":27.12,"id":9589287}]}]}
{"op":"mcm","clk":"4229930063","pt":1631526659261,"mc":[{"id":"1.187595434","rc":[{"batb":[[0,1.25,256.04],[1,1.2,256.04],[2,1.17,256.04]],"ltp":1.3,"tv":945.6,"id":21397559}]}]}
{"op":"mcm","clk":"4229930337","pt":1631526663467,"mc":[{"id":"1.187595434","rc":[{"batl":[[0,1.3,92],[1,1.41,84.83]],"ltp":1.3,"tv":945.6,"id":21397559}]}]}
{"op":"mcm","clk":"4229930939","pt":1631526672482,"mc":[{"id":"1.187595434","rc":[{"batb":[[0,1.01,7],[1,1.01,0]],"ltp":5.5,"tv":27.12,"id":9589287}]}]}
{"op":"mcm","clk":"4229931178","pt":1631526676201,"mc":[{"id":"1.187595434","rc":[{"batb":[[0,1.2,256.04],[1,1.17,256.04],[2,1.1,256.04]],"ltp":1.3,"tv":945.6,"id":21397559}]}]}
{"op":"mcm","clk":"4229931327","pt":1631526678312,"mc":[{"id":"1.187595434","rc":[{"batb":[[0,2.52,387.48],[1,1.01,7]],"ltp":5.5,"tv":27.12,"id":9589287}]}]}
{"op":"mcm","clk":"4229931395","pt":1631526679202,"mc":[{"id":"1.187595434","rc":[{"batl":[[0,1.41,84.83],[1,1.41,0]],"ltp":1.3,"tv":945.6,"id":21397559}]}]}
{"op":"mcm","clk":"4229931616","pt":1631526682508,"mc":[{"id":"1.187595434","rc":[{"batb":[[0,1.23,256.04],[1,1.2,256.04],[2,1.17,256.04]],"ltp":1.3,"tv":945.6,"id":21397559}]}]}
{"op":"mcm","clk":"4229931696","pt":1631526683799,"mc":[{"id":"1.187595434","rc":[{"batl":[[0,1.28,93.45]],"ltp":1.3,"tv":945.6,"id":21397559}]}]}
{"op":"mcm","clk":"4229933957","pt":1631526715776,"mc":[{"id":"1.187595434","rc":[{"batl":[[0,1.3,92]],"ltp":1.3,"tv":945.6,"id":21397559}]}]}
{"op":"mcm","clk":"4229934497","pt":1631526722677,"mc":[{"id":"1.187595434","rc":[{"batb":[[0,1.27,256.04],[1,1.23,256.04],[2,1.2,256.04]],"ltp":1.3,"tv":945.6,"id":21397559}]}]}
{"op":"mcm","clk":"4229936131","pt":1631526745907,"mc":[{"id":"1.187595434","rc":[{"batb":[[0,1.23,256.04],[1,1.2,256.04],[2,1.17,256.04]],"ltp":1.3,"tv":945.6,"id":21397559}]}]}
{"op":"mcm","clk":"4229936473","pt":1631526750090,"mc":[{"id":"1.187595434","rc":[{"batl":[[0,1.25,95.68],[1,1.3,92]],"ltp":1.3,"tv":945.6,"id":21397559}]}]}
{"op":"mcm","clk":"4229937653","pt":1631526768440,"mc":[{"id":"1.187595434","rc":[{"batl":[[0,1.3,92],[1,1.3,0]],"ltp":1.3,"tv":945.6,"id":21397559}]}]}
{"op":"mcm","clk":"4229939718","pt":1631526798384,"mc":[{"id":"1.187595434","rc":[{"batb":[[0,1.2,256.04],[1,1.17,256.04],[2,1.1,256.04]],"ltp":1.3,"tv":945.6,"id":21397559}]}]}
{"op":"mcm","clk":"4229940179","pt":1631526805806,"mc":[{"id":"1.187595434","rc":[{"batl":[[0,1.26,94.92],[1,1.3,92]],"ltp":1.3,"tv":945.6,"id":21397559}]}]}
{"op":"mcm","clk":"4229941488","pt":1631526828539,"mc":[{"id":"1.187595434","rc":[{"batl":[[0,1.3,92],[1,1.3,0]],"ltp":1.3,"tv":945.6,"id":21397559}]}]}
{"op":"mcm","clk":"4229941869","pt":1631526836414,"mc":[{"id":"1.187595434","rc":[{"batl":[[0,1.33,89.93]],"ltp":1.3,"tv":945.6,"id":21397559}]}]}
{"op":"mcm","clk":"4229941897","pt":1631526837031,"mc":[{"id":"1.187595434","rc":[{"batb":[[0,1.3,256.04],[1,1.2,256.04],[2,1.17,256.04]],"ltp":1.3,"tv":945.6,"id":21397559}]}]}
{"op":"mcm","clk":"4229942521","pt":1631526849956,"mc":[{"id":"1.187595434","rc":[{"batb":[[0,1.2,256.04],[1,1.17,256.04],[2,1.1,256.04]],"ltp":1.3,"tv":945.6,"id":21397559}]}]}
{"op":"mcm","clk":"4229942891","pt":1631526857660,"mc":[{"id":"1.187595434","rc":[{"batl":[[0,1.28,93.45]],"ltp":1.3,"tv":945.6,"id":21397559}]}]}
{"op":"mcm","clk":"4229944623","pt":1631526886968,"mc":[{"id":"1.187595434","rc":[{"batl":[[0,6.6,100.51]],"ltp":5.5,"tv":27.12,"id":9589287}]}]}
{"op":"mcm","clk":"4229944926","pt":1631526893006,"mc":[{"id":"1.187595434","rc":[{"batl":[[0,1.22,98.04]],"ltp":1.3,"tv":945.6,"id":21397559}]}]}
{"op":"mcm","clk":"4229945479","pt":1631526902293,"mc":[{"id":"1.187595434","rc":[{"batl":[[0,5.3,120.66]],"ltp":5.5,"tv":27.12,"id":9589287}]}]}
{"op":"mcm","clk":"4229945677","pt":1631526905096,"mc":[{"id":"1.187595434","rc":[{"batl":[[0,1.34,89.25]],"ltp":1.3,"tv":945.6,"id":21397559}]}]}
{"op":"mcm","clk":"4229945761","pt":1631526906080,"mc":[{"id":"1.187595434","rc":[{"batb":[[0,1.3,256.04],[1,1.2,256.04],[2,1.17,256.04]],"ltp":1.3,"tv":945.6,"id":21397559}]}]}
{"op":"mcm","clk":"4229946835","pt":1631526924737,"mc":[{"id":"1.187595434","rc":[{"batb":[[0,1.01,7],[1,1.01,0]],"ltp":5.5,"tv":27.12,"id":9589287}]}]}
{"op":"mcm","clk":"4229947181","pt":1631526930516,"mc":[{"id":"1.187595434","rc":[{"batb":[[0,2.22,390.59],[1,1.01,7]],"batl":[[0,4.6,138.2]],"ltp":5.5,"tv":27.12,"id":9589287}]}]}
{"op":"mcm","clk":"4229947295","pt":1631526932326,"mc":[{"id":"1.187595434","rc":[{"batb":[[0,1.34,11.95],[1,1.3,256.04],[2,1.2,256.04]],"ltp":1.3,"tv":945.6,"id":21397559}]}]}
{"op":"mcm","clk":"4229947331","pt":1631526933046,"mc":[{"id":"1.187595434","rc":[{"batb":[[0,1.3,256.04],[1,1.2,256.04],[2,1.17,256.04]],"ltp":1.3,"tv":945.6,"id":21397559}]}]}
{"op":"mcm","clk":"4229947376","pt":1631526934125,"mc":[{"id":"1.187595434","rc":[{"batl":[[0,1.4,85.43]],"ltp":1.3,"tv":945.6,"id":21397559}]}]}
{"op":"mcm","clk":"4229947484","pt":1631526936353,"mc":[{"id":"1.187595434","rc":[{"batb":[[0,1.36,256.04],[1,1.35,256.04],[2,1.3,256.04]],"ltp":1.3,"tv":945.6,"id":21397559}]}]}
{"op":"mcm","clk":"4229950769","pt":1631526995297,"mc":[{"id":"1.187595434","rc":[{"batb":[[1,1.3,256.04],[2,1.2,256.04]],"ltp":1.3,"tv":945.6,"id":21397559}]}]}
{"op":"mcm","clk":"4229953390","pt":1631527040107,"mc":[{"id":"1.187595434","rc":[{"batl":[[0,3.9,160.74]],"ltp":5.5,"tv":27.12,"id":9589287}]}]}
{"op":"mcm","clk":"4229953435","pt":1631527041199,"mc":[{"id":"1.187595434","rc":[{"batb":[[0,1.44,256.04],[1,1.36,256.04],[2,1.3,256.04]],"ltp":1.3,"tv":945.6,"id":21397559}]}]}
{"op":"mcm","clk":"4229953529","pt":1631527042910,"mc":[{"id":"1.187595434","rc":[{"batl":[[0,1.48,80.81]],"ltp":1.3,"tv":945.6,"id":21397559}]}]}
{"op":"mcm","clk":"4229955229","pt":1631527070333,"mc":[{"id":"1.187595434","rc":[{"batb":[[0,1.01,7],[1,1.01,0]],"ltp":5.5,"tv":27.12,"id":9589287}]}]}
{"op":"mcm","clk":"4229955613","pt":1631527076542,"mc":[{"id":"1.187595434","rc":[{"batb":[[0,1.97,401.09],[1,1.01,7]],"batl":[[0,3.65,173.1]],"ltp":5.5,"tv":27.12,"id":9589287}]}]}
{"op":"mcm","clk":"4229955642","pt":1631527076954,"mc":[{"id":"1.187595434","rc":[{"batb":[[0,1.5,256.04],[1,1.44,256.04],[2,1.36,256.04]],"ltp":1.3,"tv":945.6,"id":21397559}]}]}
{"op":"mcm","clk":"4229955725","pt":1631527078344,"mc":[{"id":"1.187595434","rc":[{"batl":[[0,1.57,76.18]],"ltp":1.3,"tv":945.6,"id":21397559}]}]}
{"op":"mcm","clk":"4229956008","pt":1631527082863,"mc":[{"id":"1.187595434","rc":[{"batl":[[0,1.52,78.69],[1,1.57,76.18]],"ltp":1.3,"tv":945.6,"id":21397559}]}]}
{"op":"mcm","clk":"4229956108","pt":1631527084363,"mc":[{"id":"1.187595434","rc":[{"batl":[[2,1000,0.12]],"ltp":1.3,"tv":945.6,"id":21397559}]}]}
{"op":"mcm","clk":"4229956175","pt":1631527085355,"mc":[{"id":"1.187595434","rc":[{"trd":[[1.52,78.69],[1.57,37.52]],"ltp":1.57,"tv":1061.81,"id":21397559},{"trd":[[2.74,21.5],[2.92,40.96]],"ltp":2.74,"tv":89.58,"id":9589287}],"tv":1151.39}]}
{"op":"mcm","clk":"4229956444","pt":1631527089741,"mc":[{"id":"1.187595434","rc":[{"trd":[[1.5,0.24]],"batb":[[0,1.5,255.92]],"ltp":1.5,"tv":1062.05,"id":21397559}],"tv":1151.63}]}
{"op":"mcm","clk":"4229956499","pt":1631527090674,"mc":[{"id":"1.187595434","rc":[{"batb":[[2,1.3,256.04]],"ltp":1.5,"tv":1062.05,"id":21397559}]}]}
{"op":"mcm","clk":"4229956660","pt":1631527092781,"mc":[{"id":"1.187595434","rc":[{"batb":[[0,1.54,38.25],[1,1.5,255.92],[2,1.44,256.04]],"ltp":1.5,"tv":1062.05,"id":21397559}]}]}
{"op":"mcm","clk":"4229956804","pt":1631527094755,"mc":[{"id":"1.187595434","rc":[{"batb":[[1,1.53,256.04],[2,1.5,255.92]],"ltp":1.5,"tv":1062.05,"id":21397559}]}]}
{"op":"mcm","clk":"4229957107","pt":1631527100191,"mc":[{"id":"1.187595434","rc":[{"batl":[[0,1.73,256.04]],"ltp":1.5,"tv":1062.05,"id":21397559}]}]}
{"op":"mcm","clk":"4229957198","pt":1631527101385,"mc":[{"id":"1.187595434","rc":[{"batb":[[0,1.5,255.92],[1,1.44,256.04],[2,1.3,256.04]],"ltp":1.5,"tv":1062.05,"id":21397559}]}]}
{"op":"mcm","clk":"4229957233","pt":1631527101756,"mc":[{"id":"1.187595434","rc":[{"batl":[[0,3.15,203.58]],"ltp":2.74,"tv":89.58,"id":9589287}]}]}
{"op":"mcm","clk":"4229957319","pt":1631527102947,"mc":[{"id":"1.187595434","rc":[{"batb":[[0,1.62,256.04],[1,1.5,255.92]],"ltp":1.5,"tv":1062.05,"id":21397559}]}]}
{"op":"mcm","clk":"4229957392","pt":1631527104075,"mc":[{"id":"1.187595434","rc":[{"batb":[[0,1.7,34.55],[1,1.62,256.04],[2,1.5,255.92]],"ltp":1.5,"tv":1062.05,"id":21397559}]}]}
{"op":"mcm","clk":"4229958477","pt":1631527117987,"mc":[{"id":"1.187595434","rc":[{"batl":[[0,1.83,256.04]],"ltp":1.5,"tv":1062.05,"id":21397559}]}]}
{"op":"mcm","clk":"4229958722","pt":1631527120785,"mc":[{"id":"1.187595434","rc":[{"batb":[[0,1.75,33.56],[1,1.7,34.55],[2,1.62,256.04]],"ltp":1.5,"tv":1062.05,"id":21397559}]}]}
{"op":"mcm","clk":"4229958991","pt":1631527124203,"mc":[{"id":"1.187595434","rc":[{"batb":[[0,1.8,256.04],[1,1.75,33.56],[2,1.7,34.55]],"ltp":1.5,"tv":1062.05,"id":21397559}]}]}
{"op":"mcm","clk":"4229959207","pt":1631527127472,"mc":[{"id":"1.187595434","rc":[{"batb":[[0,1.75,33.56],[1,1.62,256.04],[2,1.5,255.92]],"ltp":1.5,"tv":1062.05,"id":21397559}]}]}
{"op":"mcm","clk":"4229959278","pt":1631527128509,"mc":[{"id":"1.187595434","rc":[{"batb":[[1,1.5,255.92],[2,1.01,7]],"ltp":1.5,"tv":1062.05,"id":21397559}]}]}
{"op":"mcm","clk":"4229959339","pt":1631527129700,"mc":[{"id":"1.187595434","rc":[{"batl":[[0,2,256.04]],"ltp":1.5,"tv":1062.05,"id":21397559}]}]}
{"op":"mcm","clk":"4229959401","pt":1631527130685,"mc":[{"id":"1.187595434","rc":[{"batb":[[1,1.01,7],[2,1.01,0]],"ltp":1.5,"tv":1062.05,"id":21397559}]}]}
{"op":"mcm","clk":"4229959820","pt":1631527136429,"mc":[{"id":"1.187595434","rc":[{"batb":[[0,1.01,7],[1,1.01,0]],"ltp":1.5,"tv":1062.05,"id":21397559}]}]}
{"op":"mcm","clk":"4229959967","pt":1631527138600,"mc":[{"id":"1.187595434","rc":[{"batb":[[0,1.8,32.63],[1,1.01,7]],"ltp":1.5,"tv":1062.05,"id":21397559}]}]}
{"op":"mcm","clk":"4229960002","pt":1631527139228,"mc":[{"id":"1.187595434","rc":[{"batb":[[0,1.01,7],[1,1.01,0]],"ltp":1.5,"tv":1062.05,"id":21397559}]}]}
{"op":"mcm","clk":"4229960223","pt":1631527142599,"mc":[{"id":"1.187595434","rc":[{"batb":[[0,1.73,33.94],[1,1.01,7]],"ltp":1.5,"tv":1062.05,"id":21397559}]}]}
{"op":"mcm","clk":"4229960651","pt":1631527148334,"mc":[{"id":"1.187595434","rc":[{"batb":[[1,1.56,256.04],[2,1.01,7]],"ltp":1.5,"tv":1062.05,"id":21397559}]}]}
{"op":"mcm","clk":"4229960707","pt":1631527149109,"mc":[{"id":"1.187595434","rc":[{"batb":[[1,1.57,256.04],[2,1.56,256.04]],"ltp":1.5,"tv":1062.05,"id":21397559}]}]}
{"op":"mcm","clk":"4229961362","pt":1631527158414,"mc":[{"id":"1.187595434","rc":[{"batb":[[0,1.57,256.04],[1,1.56,256.04],[2,1.01,7]],"ltp":1.5,"tv":1062.05,"id":21397559}]}]}
{"op":"mcm","clk":"4229961803","pt":1631527162724,"mc":[{"id":"1.187595434","rc":[{"batb":[[0,1.8,32.63],[1,1.57,256.04],[2,1.56,256.04]],"ltp":1.5,"tv":1062.05,"id":21397559}]}]}
{"op":"mcm","clk":"4229962205","pt":1631527167743,"mc":[{"id":"1.187595434","rc":[{"batb":[[2,1.01,7]],"ltp":1.5,"tv":1062.05,"id":21397559}]}]}
{"op":"mcm","clk":"4229965429","pt":1631527210911,"mc":[{"id":"1.187595434","rc":[{"batb":[[0,1.57,256.04],[1,1.01,7],[2,1.01,0]],"ltp":1.5,"tv":1062.05,"id":21397559}]}]}
{"op":"mcm","clk":"4229965986","pt":1631527217545,"mc":[{"id":"1.187595434","rc":[{"batb":[[0,1.77,33.18],[1,1.57,256.04],[2,1.01,7]],"ltp":1.5,"tv":1062.05,"id":21397559}]}]}
{"op":"mcm","clk":"4229966807","pt":1631527228933,"mc":[{"id":"1.187595434","rc":[{"batb":[[0,1.57,256.04],[1,1.01,7],[2,1.01,0]],"ltp":1.5,"tv":1062.05,"id":21397559}]}]}
{"op":"mcm","clk":"4229967001","pt":1631527231526,"mc":[{"id":"1.187595434","rc":[{"batb":[[0,1.01,7],[1,1.01,0]],"ltp":1.5,"tv":1062.05,"id":21397559}]}]}
{"op":"mcm","clk":"4229967058","pt":1631527232458,"mc":[{"id":"1.187595434","rc":[{"batl":[[0,3.65,173.1]],"ltp":2.74,"tv":89.58,"id":9589287}]}]}
{"op":"mcm","clk":"4229967214","pt":1631527234338,"mc":[{"id":"1.187595434","rc":[{"batb":[[0,2.3,167.42],[1,1.97,401.09],[2,1.01,7]],"ltp":2.74,"tv":89.58,"id":9589287}]}]}
{"op":"mcm","clk":"4229967308","pt":1631527235540,"mc":[{"id":"1.187595434","rc":[{"batb":[[0,1.7,34.55],[1,1.01,7]],"ltp":1.5,"tv":1062.05,"id":21397559},{"batb":[[0,2.3,151.01]],"ltp":2.74,"tv":89.58,"id":9589287}]}]}
{"op":"mcm","clk":"4229967367","pt":1631527236384,"mc":[{"id":"1.187595434","rc":[{"batb":[[0,1.97,401.09],[1,1.01,7],[2,1.01,0]],"ltp":2.74,"tv":89.58,"id":9589287}]}]}
{"op":"mcm","clk":"4229967447","pt":1631527237236,"mc":[{"id":"1.187595434","rc":[{"batl":[[0,1.8,256.04],[1,2,256.04]],"ltp":1.5,"tv":1062.05,"id":21397559}]}]}
{"op":"mcm","clk":"4229969413","pt":1631527264773,"mc":[{"id":"1.187595434","rc":[{"batb":[[0,1.01,7],[1,1.01,0]],"ltp":1.5,"tv":1062.05,"id":21397559}]}]}
{"op":"mcm","clk":"4229969697","pt":1631527268592,"mc":[{"id":"1.187595434","rc":[{"batl":[[1,2,0]],"ltp":1.5,"tv":1062.05,"id":21397559}]}]}
{"op":"mcm","clk":"4229969927","pt":1631527271500,"mc":[{"id":"1.187595434","rc":[{"batb":[[0,1.6,36.71],[1,1.01,7]],"ltp":1.5,"tv":1062.05,"id":21397559}]}]}
{"op":"mcm","clk":"4229970001","pt":1631527272575,"mc":[{"id":"1.187595434","rc":[{"batl":[[0,1.7,256.04],[1,1.8,256.04]],"ltp":1.5,"tv":1062.05,"id":21397559}]}]}
{"op":"mcm","clk":"4229970623","pt":1631527282409,"mc":[{"id":"1.187595434","rc":[{"batb":[[0,1.01,7],[1,1.01,0]],"ltp":2.74,"tv":89.58,"id":9589287}]}]}
{"op":"mcm","clk":"4229970752","pt":1631527284375,"mc":[{"id":"1.187595434","rc":[{"batb":[[0,1.01,7],[1,1.01,0]],"ltp":1.5,"tv":1062.05,"id":21397559}]}]}
{"op":"mcm","clk":"4229971033","pt":1631527288099,"mc":[{"id":"1.187595434","rc":[{"batl":[[1,1.8,0]],"ltp":1.5,"tv":1062.05,"id":21397559},{"batb":[[0,2.12,394.79],[1,1.01,7]],"batl":[[0,4.2,150.36]],"ltp":2.74,"tv":89.58,"id":9589287}]}]}
{"op":"mcm","clk":"4229971327","pt":1631527291975,"mc":[{"id":"1.187595434","rc":[{"batl":[[0,1.6,256.04],[1,1.7,256.04]],"ltp":1.5,"tv":1062.05,"id":21397559}]}]}
{"op":"mcm","clk":"4229971578","pt":1631527295296,"mc":[{"id":"1.187595434","rc":[{"batb":[[0,1.5,39.15],[1,1.01,7]],"ltp":1.5,"tv":1062.05,"id":21397559}]}]}
{"op":"mcm","clk":"4229976595","pt":1631527371698,"mc":[{"id":"1.187595434","rc":[{"batb":[[0,1.01,7],[1,1.01,0]],"ltp":2.74,"tv":89.58,"id":9589287}]}]}
{"op":"mcm","clk":"4229976694","pt":1631527373145,"mc":[{"id":"1.187595434","rc":[{"batb":[[0,1.01,7],[1,1.01,0]],"ltp":1.5,"tv":1062.05,"id":21397559}]}]}
{"op":"mcm","clk":"4229976931","pt":1631527377246,"mc":[{"id":"1.187595434","rc":[{"batb":[[0,2.3,391.17],[1,1.01,7]],"batl":[[0,4.9,128.27]],"ltp":2.74,"tv":89.58,"id":9589287}]}]}
{"op":"mcm","clk":"4229977057","pt":1631527379008,"mc":[{"id":"1.187595434","rc":[{"batl":[[0,1.47,256.04],[1,1.6,256.04],[2,1.7,256.04]],"ltp":1.5,"tv":1062.05,"id":21397559}]}]}
{"op":"mcm","clk":"4229977284","pt":1631527381713,"mc":[{"id":"1.187595434","rc":[{"batb":[[0,1.45,40.51],[1,1.01,7]],"ltp":1.5,"tv":1062.05,"id":21397559}]}]}
{"op":"mcm","clk":"4229978069","pt":1631527392771,"mc":[{"id":"1.187595434","rc":[{"batb":[[0,1.01,7],[1,1.01,0]],"ltp":1.5,"tv":1062.05,"id":21397559}]}]}
{"op":"mcm","clk":"4229978238","pt":1631527395369,"mc":[{"id":"1.187595434","rc":[{"batl":[[0,5.5,116.87]],"ltp":2.74,"tv":89.58,"id":9589287}]}]}
{"op":"mcm","clk":"4229978720","pt":1631527401770,"mc":[{"id":"1.187595434","rc":[{"batb":[[0,1.38,42.55],[1,1.01,7]],"ltp":1.5,"tv":1062.05,"id":21397559}]}]}
{"op":"mcm","clk":"4229978867","pt":1631527403845,"mc":[{"id":"1.187595434","rc":[{"batl":[[2,1.7,0]],"ltp":1.5,"tv":1062.05,"id":21397559}]}]}
{"op":"mcm","clk":"4229978941","pt":1631527404779,"mc":[{"id":"1.187595434","rc":[{"batl":[[1,1.6,0]],"ltp":1.5,"tv":1062.05,"id":21397559}]}]}
{"op":"mcm","clk":"4229979616","pt":1631527415493,"mc":[{"id":"1.187595434","rc":[{"batb":[[0,1.01,7],[1,1.01,0]],"ltp":2.74,"tv":89.58,"id":9589287}]}]}
{"op":"mcm","clk":"4229980090","pt":1631527421687,"mc":[{"id":"1.187595434","rc":[{"batb":[[0,2.52,387.48],[1,1.01,7]],"ltp":2.74,"tv":89.58,"id":9589287}]}]}
{"op":"mcm","clk":"4229982305","pt":1631527453747,"mc":[{"id":"1.187595434","rc":[{"batb":[[0,1.01,7],[1,1.01,0]],"ltp":1.5,"tv":1062.05,"id":21397559}]}]}
{"op":"mcm","clk":"4229982604","pt":1631527458510,"mc":[{"id":"1.187595434","rc":[{"batl":[[0,1.38,25.6],[1,1.47,256.04]],"ltp":1.5,"tv":1062.05,"id":21397559},{"batl":[[0,6.6,100.51]],"ltp":2.74,"tv":89.58,"id":9589287}]}]}
{"op":"mcm","clk":"4229982682","pt":1631527459605,"mc":[{"id":"1.187595434","rc":[{"batl":[[0,1.38,425.75]],"ltp":1.5,"tv":1062.05,"id":21397559}]}]}
{"op":"mcm","clk":"4229982726","pt":1631527460327,"mc":[{"id":"1.187595434","rc":[{"batb":[[0,1.34,43.83],[1,1.01,7]],"batl":[[0,1.38,320.18]],"ltp":1.5,"tv":1062.05,"id":21397559}]}]}
{"op":"mcm","clk":"4229982814","pt":1631527461521,"mc":[{"id":"1.187595434","rc":[{"trd":[[1.38,4]],"batl":[[0,1.38,28]],"ltp":1.38,"tv":1066.05,"id":21397559}],"tv":1155.63}]}
{"op":"mcm","clk":"4229982870","pt":1631527462247,"mc":[{"id":"1.187595434","rc":[{"batl":[[0,1.47,256.04],[1,1.47,0]],"ltp":1.38,"tv":1066.05,"id":21397559}]}]}
{"op":"mcm","clk":"4229982951","pt":1631527463440,"mc":[{"id":"1.187595434","rc":[{"batl":[[0,1.42,256.04],[1,1.47,256.04]],"ltp":1.38,"tv":1066.05,"id":21397559}]}]}
{"op":"mcm","clk":"4229984311","pt":1631527484480,"mc":[{"id":"1.187595434","rc":[{"batb":[[0,1.01,7],[1,1.01,0]],"ltp":2.74,"tv":89.58,"id":9589287}]}]}
{"op":"mcm","clk":"4229984629","pt":1631527489964,"mc":[{"id":"1.187595434","rc":[{"trd":[[1.34,87.65]],"batb":[[0,1.01,7],[1,1.01,0]],"ltp":1.34,"tv":1153.7,"id":21397559}],"tv":1243.28}]}
{"op":"mcm","clk":"4229984685","pt":1631527490687,"mc":[{"id":"1.187595434","rc":[{"batb":[[0,2.84,381.34],[1,1.01,7]],"batl":[[0,8.2,86.81]],"ltp":2.74,"tv":89.58,"id":9589287}]}]}
{"op":"mcm","clk":"4229985491","pt":1631527503193,"mc":[{"id":"1.187595434","rc":[{"batl":[[1,1.47,0]],"ltp":1.34,"tv":1153.7,"id":21397559}]}]}
{"op":"mcm","clk":"4229985810","pt":1631527507020,"mc":[{"id":"1.187595434","rc":[{"batl":[[0,1.3,256.04],[1,1.42,256.04]],"ltp":1.34,"tv":1153.7,"id":21397559}]}]}
{"op":"mcm","clk":"4229985934","pt":1631527508618,"mc":[{"id":"1.187595434","rc":[{"batl":[[0,1.42,256.04],[1,1.42,0]],"ltp":1.34,"tv":1153.7,"id":21397559}]}]}
{"op":"mcm","clk":"4229986030","pt":1631527509813,"mc":[{"id":"1.187595434","rc":[{"batl":[[0,6.6,100.51]],"ltp":2.74,"tv":89.58,"id":9589287}]}]}
{"op":"mcm","clk":"4229986204","pt":1631527511524,"mc":[{"id":"1.187595434","rc":[{"batb":[[0,1.17,256.04],[1,1.14,256.04],[2,1.01,7]],"ltp":1.34,"tv":1153.7,"id":21397559}]}]}
{"op":"mcm","clk":"4229986263","pt":1631527512402,"mc":[{"id":"1.187595434","rc":[{"batb":[[0,1.25,256.04],[1,1.17,256.04],[2,1.14,256.04]],"ltp":1.34,"tv":1153.7,"id":21397559}]}]}
{"op":"mcm","clk":"4229987197","pt":1631527527151,"mc":[{"id":"1.187595434","rc":[{"batb":[[0,1.17,256.04],[1,1.14,256.04],[2,1.01,7]],"ltp":1.34,"tv":1153.7,"id":21397559}]}]}
{"op":"mcm","clk":"4229987570","pt":1631527533032,"mc":[{"id":"1.187595434","rc":[{"batl":[[0,8.2,86.81]],"ltp":2.74,"tv":89.58,"id":9589287}]}]}
{"op":"mcm","clk":"4229987668","pt":1631527534424,"mc":[{"id":"1.187595434","rc":[{"batl":[[0,1.3,256.04],[1,1.42,256.04]],"ltp":1.34,"tv":1153.7,"id":21397559}]}]}
{"op":"mcm","clk":"4229989355","pt":1631527560685,"mc":[{"id":"1.187595434","rc":[{"batb":[[0,1.01,7],[1,1.01,0]],"ltp":2.74,"tv":89.58,"id":9589287}]}]}
{"op":"mcm","clk":"4229989589","pt":1631527564018,"mc":[{"id":"1.187595434","rc":[{"batb":[[0,1.14,256.04],[1,1.01,7],[2,1.01,0]],"ltp":1.34,"tv":1153.7,"id":21397559}]}]}
{"op":"mcm","clk":"4229989765","pt":1631527566590,"mc":[{"id":"1.187595434","rc":[{"batb":[[0,1.01,7],[1,1.01,0]],"ltp":1.34,"tv":1153.7,"id":21397559},{"batb":[[0,3.1,379.68],[1,1.01,7]],"batl":[[0,10.5,73.47]],"ltp":2.74,"tv":89.58,"id":9589287}]}]}
{"op":"mcm","clk":"4229990004","pt":1631527570214,"mc":[{"id":"1.187595434","rc":[{"batl":[[0,1.24,256.04],[1,1.42,0]],"ltp":1.34,"tv":1153.7,"id":21397559}]}]}
{"op":"mcm","clk":"4229990096","pt":1631527571607,"mc":[{"id":"1.187595434","rc":[{"batb":[[0,1.13,256.04],[1,1.01,7]],"ltp":1.34,"tv":1153.7,"id":21397559}]}]}
{"op":"mcm","clk":"4229990131","pt":1631527572124,"mc":[{"id":"1.187595434","rc":[{"batb":[[1,1.12,256.04],[2,1.01,7]],"ltp":1.34,"tv":1153.7,"id":21397559}]}]}
{"op":"mcm","clk":"4229991144","pt":1631527586828,"mc":[{"id":"1.187595434","rc":[{"batl":[[0,12,68.85]],"ltp":2.74,"tv":89.58,"id":9589287}]}]}
{"op":"mcm","clk":"4229991893","pt":1631527598816,"mc":[{"id":"1.187595434","rc":[{"batl":[[0,9.4,79.27]],"ltp":2.74,"tv":89.58,"id":9589287}]}]}
{"op":"mcm","clk":"4229992017","pt":1631527601035,"mc":[{"id":"1.187595434","rc":[{"batl":[[0,1.3,256.04]],"ltp":1.34,"tv":1153.7,"id":21397559}]}]}
{"op":"mcm","clk":"4229992947","pt":1631527615283,"mc":[{"id":"1.187595434","rc":[{"batb":[[1,1.01,7],[2,1.01,0]],"ltp":1.34,"tv":1153.7,"id":21397559}]}]}
{"op":"mcm","clk":"4229993172","pt":1631527619157,"mc":[{"id":"1.187595434","rc":[{"batb":[[0,1.15,256.04],[1,1.13,256.04],[2,1.01,7]],"ltp":1.34,"tv":1153.7,"id":21397559}]}]}
{"op":"mcm","clk":"4229993374","pt":1631527622062,"mc":[{"id":"1.187595434","rc":[{"batb":[[1,1.01,7],[2,1.01,0]],"ltp":1.34,"tv":1153.7,"id":21397559}]}]}
{"op":"mcm","clk":"4229993933","pt":1631527630700,"mc":[{"id":"1.187595434","rc":[{"batb":[[0,1.01,7],[1,1.01,0]],"ltp":1.34,"tv":1153.7,"id":21397559}]}]}
{"op":"mcm","clk":"4229994280","pt":1631527635356,"mc":[{"id":"1.187595434","rc":[{"batl":[[0,13.5,65.08]],"ltp":2.74,"tv":89.58,"id":9589287}]}]}
{"op":"mcm","clk":"4229994379","pt":1631527636956,"mc":[{"id":"1.187595434","rc":[{"batl":[[0,1.21,256.04]],"ltp":1.34,"tv":1153.7,"id":21397559}]}]}
{"op":"mcm","clk":"4229994480","pt":1631527638506,"mc":[{"id":"1.187595434","rc":[{"batl":[[0,1.2,256.04],[1,1.21,256.04]],"ltp":1.34,"tv":1153.7,"id":21397559}]}]}
{"op":"mcm","clk":"4229994557","pt":1631527639594,"mc":[{"id":"1.187595434","rc":[{"batb":[[0,1.1,256.04],[1,1.01,7]],"ltp":1.34,"tv":1153.7,"id":21397559}]}]}
{"op":"mcm","clk":"4229994566","pt":1631527639696,"mc":[{"id":"1.187595434","rc":[{"batl":[[1,1.21,0]],"ltp":1.34,"tv":1153.7,"id":21397559}]}]}
{"op":"mcm","clk":"4230000160","pt":1631527714888,"mc":[{"id":"1.187595434","rc":[{"batb":[[0,1.01,7],[1,1.01,0]],"ltp":2.74,"tv":89.58,"id":9589287}]}]}
{"op":"mcm","clk":"4230000240","pt":1631527715873,"mc":[{"id":"1.187595434","rc":[{"batb":[[0,1.01,7],[1,1.01,0]],"ltp":1.34,"tv":1153.7,"id":21397559}]}]}
{"op":"mcm","clk":"4230000584","pt":1631527720375,"mc":[{"id":"1.187595434","rc":[{"batb":[[0,3.5,382.15],[1,1.01,7]],"batl":[[0,18,57.1]],"ltp":2.74,"tv":89.58,"id":9589287}]}]}
{"op":"mcm","clk":"4230000732","pt":1631527722295,"mc":[{"id":"1.187595434","rc":[{"batb":[[0,1.07,256.04],[1,1.01,7]],"ltp":1.34,"tv":1153.7,"id":21397559}]}]}
{"op":"mcm","clk":"4230000812","pt":1631527723382,"mc":[{"id":"1.187595434","rc":[{"batl":[[0,1.14,256.04],[1,1.15,256.04],[2,1.2,256.04]],"ltp":1.34,"tv":1153.7,"id":21397559}]}]}
{"op":"mcm","clk":"4230001371","pt":1631527730977,"mc":[{"id":"1.187595434","rc":[{"batl":[[1,1.2,256.04],[2,1.2,0]],"ltp":1.34,"tv":1153.7,"id":21397559}]}]}
{"op":"mcm","clk":"4230001430","pt":1631527731702,"mc":[{"id":"1.187595434","rc":[{"batl":[[1,1.2,0]],"ltp":1.34,"tv":1153.7,"id":21397559}]}]}
{"op":"mcm","clk":"4230002012","pt":1631527738621,"mc":[{"id":"1.187595434","rc":[{"batl":[[0,23,52.05]],"ltp":2.74,"tv":89.58,"id":9589287}]}]}
{"op":"mcm","clk":"4230002228","pt":1631527741025,"mc":[{"id":"1.187595434","rc":[{"batb":[[1,1.05,256.04],[2,1.01,7]],"ltp":1.34,"tv":1153.7,"id":21397559}]}]}
{"op":"mcm","clk":"4230002466","pt":1631527743423,"mc":[{"id":"1.187595434","rc":[{"batb":[[2,1.04,256.04]],"ltp":1.34,"tv":1153.7,"id":21397559}]}]}
{"op":"mcm","clk":"4230002706","pt":1631527746321,"mc":[{"id":"1.187595434","rc":[{"batb":[[1,1.06,256.04],[2,1.05,256.04]],"ltp":1.34,"tv":1153.7,"id":21397559}]}]}
{"op":"mcm","clk":"4230002886","pt":1631527748348,"mc":[{"id":"1.187595434","rc":[{"batl":[[0,1.12,256.04],[1,1.14,256.04]],"ltp":1.34,"tv":1153.7,"id":21397559}]}]}
{"op":"mcm","clk":"4230003117","pt":1631527750941,"mc":[{"id":"1.187595434","rc":[{"batl":[[1,1.14,0]],"ltp":1.34,"tv":1153.7,"id":21397559}]}]}
{"op":"mcm","clk":"4230003370","pt":1631527753947,"mc":[{"id":"1.187595434","rc":[{"batl":[[0,21,54.32]],"ltp":2.74,"tv":89.58,"id":9589287}]}]}
{"op":"mcm","clk":"4230004250","pt":1631527763849,"mc":[{"id":"1.187595434","rc":[{"batb":[[0,1.06,256.04],[1,1.05,256.04],[2,1.04,256.04]],"ltp":1.34,"tv":1153.7,"id":21397559}]}]}
{"op":"mcm","clk":"4230004693","pt":1631527769137,"mc":[{"id":"1.187595434","rc":[{"batl":[[0,26,50.16]],"ltp":2.74,"tv":89.58,"id":9589287}]}]}
{"op":"mcm","clk":"4230007578","pt":1631527807603,"mc":[{"id":"1.187595434","rc":[{"batl":[[0,34,46.8]],"ltp":2.74,"tv":89.58,"id":9589287}]}]}
{"op":"mcm","clk":"4230009852","pt":1631527839039,"mc":[{"id":"1.187595434","rc":[{"batl":[[0,26,50.16]],"ltp":2.74,"tv":89.58,"id":9589287}]}]}
{"op":"mcm","clk":"4230016963","pt":1631527933703,"mc":[{"id":"1.187595434","rc":[{"batb":[[0,1.01,7],[1,1.01,0]],"ltp":2.74,"tv":89.58,"id":9589287}]}]}
{"op":"mcm","clk":"4230028007","pt":1631528028293,"mc":[{"id":"1.187595434","rc":[{"batb":[[0,1.04,256.04],[1,1.03,256.04],[2,1.02,256.04]],"ltp":1.34,"tv":1153.7,"id":21397559}]}]}
{"op":"mcm","clk":"4230031815","pt":1631528054366,"mc":[{"id":"1.187595434","rc":[{"batb":[[0,1.03,256.04],[1,1.02,256.04],[2,1.01,263.04]],"ltp":1.34,"tv":1153.7,"id":21397559}]}]}
{"op":"mcm","clk":"4230035062","pt":1631528077879,"mc":[{"id":"1.187595434","rc":[{"batb":[[0,1.02,256.04],[1,1.01,263.04],[2,1.01,0]],"ltp":1.34,"tv":1153.7,"id":21397559}]}]}
{"op":"mcm","clk":"4230035184","pt":1631528078962,"mc":[{"id":"1.187595434","rc":[{"batb":[[0,4.2,376.8],[1,1.01,7]],"batl":[[0,85,39.75]],"ltp":2.74,"tv":89.58,"id":9589287}]}]}
{"op":"mcm","clk":"4230035914","pt":1631528084293,"mc":[{"id":"1.187595434","rc":[{"batl":[[0,1.11,256.04],[1,1.12,256.04]],"ltp":1.34,"tv":1153.7,"id":21397559}]}]}
{"op":"mcm","clk":"4230035996","pt":1631528084772,"mc":[{"id":"1.187595434","rc":[{"batl":[[0,1.1,256.04],[1,1.11,256.04],[2,1.12,256.04]],"ltp":1.34,"tv":1153.7,"id":21397559}]}]}
{"op":"mcm","clk":"4230040427","pt":1631528116504,"mc":[{"id":"1.187595434","rc":[{"batl":[[0,60,41.62]],"ltp":2.74,"tv":89.58,"id":9589287}]}]}
{"op":"mcm","clk":"4230042501","pt":1631528145672,"mc":[{"id":"1.187595434","rc":[{"batl":[[0,1.11,256.04],[1,1.12,256.04],[2,1.12,0]],"ltp":1.34,"tv":1153.7,"id":21397559}]}]}
{"op":"mcm","clk":"4230042591","pt":1631528146973,"mc":[{"id":"1.187595434","rc":[{"batl":[[0,1.12,256.04],[1,1.12,0]],"ltp":1.34,"tv":1153.7,"id":21397559},{"batl":[[0,46,43.64]],"ltp":2.74,"tv":89.58,"id":9589287}]}]}
{"op":"mcm","clk":"4230042961","pt":1631528152960,"mc":[{"id":"1.187595434","rc":[{"batb":[[0,1.03,256.04],[1,1.02,256.04],[2,1.01,263.04]],"ltp":1.34,"tv":1153.7,"id":21397559}]}]}
{"op":"mcm","clk":"4230044884","pt":1631528179495,"mc":[{"id":"1.187595434","rc":[{"batl":[[0,85,39.75]],"ltp":2.74,"tv":89.58,"id":9589287}]}]}
{"op":"mcm","clk":"4230044959","pt":1631528180492,"mc":[{"id":"1.187595434","rc":[{"batb":[[0,1.02,256.04],[1,1.01,263.04],[2,1.01,0]],"ltp":1.34,"tv":1153.7,"id":21397559}]}]}
{"op":"mcm","clk":"4230050066","pt":1631528251697,"mc":[{"id":"1.187595434","rc":[{"batl":[[0,170,37.56]],"ltp":2.74,"tv":89.58,"id":9589287}]}]}
{"op":"mcm","clk":"4230051245","pt":1631528269917,"mc":[{"id":"1.187595434","rc":[{"batl":[[0,85,39.75]],"ltp":2.74,"tv":89.58,"id":9589287}]}]}
{"op":"mcm","clk":"4230052225","pt":1631528285259,"mc":[{"id":"1.187595434","rc":[{"batl":[[0,340,36.45]],"ltp":2.74,"tv":89.58,"id":9589287}]}]}
{"op":"mcm","clk":"4230054413","pt":1631528315795,"mc":[{"id":"1.187595434","rc":[{"batl":[[0,170,37.56]],"ltp":2.74,"tv":89.58,"id":9589287}]}]}
{"op":"mcm","clk":"4230056587","pt":1631528350246,"mc":[{"id":"1.187595434","rc":[{"batl":[[0,340,36.45]],"ltp":2.74,"tv":89.58,"id":9589287}]}]}
{"op":"mcm","clk":"4230058222","pt":1631528379783,"mc":[{"id":"1.187595434","rc":[{"batl":[[0,170,37.56]],"ltp":2.74,"tv":89.58,"id":9589287}]}]}
{"op":"mcm","clk":"4230059825","pt":1631528405232,"mc":[{"id":"1.187595434","rc":[{"batl":[[0,340,36.45]],"ltp":2.74,"tv":89.58,"id":9589287}]}]}
{"op":"mcm","clk":"4230061922","pt":1631528432844,"mc":[{"id":"1.187595434","rc":[{"batb":[[0,1.01,263.04],[1,1.01,0]],"ltp":1.34,"tv":1153.7,"id":21397559}]}]}
{"op":"mcm","clk":"4230062012","pt":1631528433935,"mc":[{"id":"1.187595434","rc":[{"batb":[[0,1.01,7]],"ltp":1.34,"tv":1153.7,"id":21397559}]}]}
{"op":"mcm","clk":"4230062399","pt":1631528440560,"mc":[{"id":"1.187595434","rc":[{"batl":[[0,1.09,256.04],[1,1.1,256.04],[2,1.12,256.04]],"ltp":1.34,"tv":1153.7,"id":21397559}]}]}
{"op":"mcm","clk":"4230062911","pt":1631528448364,"mc":[{"id":"1.187595434","rc":[{"batl":[[1,1.1,0],[2,1.12,0]],"ltp":1.34,"tv":1153.7,"id":21397559}]}]}
{"op":"mcm","clk":"4230064364","pt":1631528471383,"mc":[{"id":"1.187595434","rc":[{"batl":[[0,340,36.45]],"ltp":2.74,"tv":89.58,"id":9589287}]}]}
{"op":"mcm","clk":"4230075506","pt":1631528630406,"mc":[{"id":"1.187595434","rc":[{"trd":[[1.01,14.01]],"batl":[[0,1.01,1273.18]],"ltp":1.01,"tv":1167.71,"id":21397559}],"tv":1257.29}]}
{"op":"mcm","clk":"4230088343","pt":1631528812474,"mc":[{"id":"1.187595434","rc":[{"batb":[[0,1.01,7],[1,1.01,0]],"ltp":2.74,"tv":89.58,"id":9589287}]}]}
{"op":"mcm","clk":"4230093309","pt":1631528874542,"mc":[{"id":"1.187595434","rc":[{"batb":[[0,4.7,377.45],[1,1.01,7]],"ltp":2.74,"tv":89.58,"id":9589287}]}]}
{"op":"mcm","clk":"4230095731","pt":1631528908603,"mc":[{"id":"1.187595434","rc":[{"batl":[[0,1.01,1290.25]],"ltp":1.01,"tv":1167.71,"id":21397559}]}]}
{"op":"mcm","clk":"4230112715","pt":1631529114187,"mc":[{"id":"1.187595434","rc":[{"trd":[[1.01,314.09]],"batl":[[0,1.01,1140.17]],"ltp":1.01,"tv":1467.79,"id":21397559}],"tv":1557.37}]}
{"op":"mcm","clk":"4230114054","pt":1631529129617,"mc":[{"id":"1.187595434","rc":[{"trd":[[1.01,714.19]],"batl":[[0,1.01,940.07]],"ltp":1.01,"tv":1867.89,"id":21397559}],"tv":1957.47}]}
{"op":"mcm","clk":"4230120474","pt":1631529208591,"mc":[{"id":"1.187595434","rc":[{"batl":[[0,340,36.45]],"ltp":2.74,"tv":89.58,"id":9589287}]}]}
{"op":"mcm","clk":"4230124407","pt":1631529260904,"mc":[{"id":"1.187595434","rc":[{"batb":[[0,1.01,7],[1,1.01,0]],"ltp":2.74,"tv":89.58,"id":9589287}]}]}
{"op":"mcm","clk":"4230126215","pt":1631529284709,"mc":[{"id":"1.187595434","rc":[{"batb":[[0,4.7,377.45],[1,1.01,7]],"ltp":2.74,"tv":89.58,"id":9589287}]}]}
{"op":"mcm","clk":"4230126951","pt":1631529294532,"mc":[{"id":"1.187595434","rc":[{"batb":[[0,1.01,7],[1,1.01,0]],"ltp":2.74,"tv":89.58,"id":9589287}]}]}
{"op":"mcm","clk":"4230127849","pt":1631529307045,"mc":[{"id":"1.187595434","rc":[{"batb":[[0,4.8,372.55],[1,1.01,7]],"ltp":2.74,"tv":89.58,"id":9589287}]}]}
{"op":"mcm","clk":"4230134591","pt":1631529393769,"mc":[{"id":"1.187595434","rc":[{"batb":[[0,1.01,7],[1,1.01,0]],"ltp":2.74,"tv":89.58,"id":9589287}]}]}
{"op":"mcm","clk":"4230144051","pt":1631529516309,"mc":[{"id":"1.187595434","rc":[{"batl":[[0,1.01,17.07]],"ltp":1.01,"tv":1867.89,"id":21397559}]}]}
{"op":"mcm","clk":"4230148110","pt":1631529565645,"mc":[{"id":"1.187595434","marketDefinition":{"bspMarket":false,"turnInPlayEnabled":true,"persistenceEnabled":true,"marketBaseRate":5.0,"eventId":"30897890","eventTypeId":"2","numberOfWinners":1,"bettingType":"ODDS","marketType":"MATCH_ODDS","marketTime":"2021-09-13T09:38:48.000Z","suspendTime":"2021-09-13T09:38:48.000Z","bspReconciled":false,"complete":true,"inPlay":true,"crossMatching":true,"runnersVoidable":false,"numberOfActiveRunners":2,"betDelay":5,"status":"SUSPENDED","runners":[{"status":"ACTIVE","sortPriority":1,"id":9589287,"name":"A Carreras"},{"status":"ACTIVE","sortPriority":2,"id":21397559,"name":"O Selekhmeteva"}],"regulators":["MR_INT"],"countryCode":"GB","discountAllowed":true,"timezone":"GMT","openDate":"2021-09-13T09:38:48.000Z","version":4030549760,"name":"Match Odds","eventName":"A Carreras v O Selekhmeteva"}}]}
{"op":"mcm","clk":"4230148476","pt":1631529570309,"mc":[{"id":"1.187595434","tv":0.0}]}
{"op":"mcm","clk":"4230148582","pt":1631529571675,"mc":[{"id":"1.187595434","marketDefinition":{"bspMarket":false,"turnInPlayEnabled":true,"persistenceEnabled":true,"marketBaseRate":5.0,"eventId":"30897890","eventTypeId":"2","numberOfWinners":1,"bettingType":"ODDS","marketType":"MATCH_ODDS","marketTime":"2021-09-13T09:38:48.000Z","suspendTime":"2021-09-13T09:38:48.000Z","bspReconciled":false,"complete":true,"inPlay":true,"crossMatching":false,"runnersVoidable":false,"numberOfActiveRunners":0,"betDelay":5,"status":"CLOSED","settledTime":"2021-09-13T10:39:26.000Z","runners":[{"status":"LOSER","sortPriority":1,"id":9589287,"name":"A Carreras"},{"status":"WINNER","sortPriority":2,"id":21397559,"name":"O Selekhmeteva"}],"regulators":["MR_INT"],"countryCode":"GB","discountAllowed":true,"timezone":"GMT","openDate":"2021-09-13T09:38:48.000Z","version":4030549790,"name":"Match Odds","eventName":"A Carreras v O Selekhmeteva"}}]}
