{"op":"mcm","clk":"4233914808","pt":1631539990724,"mc":[{"id":"1.187557759","rc":[{"trd":[[1.04,7607.65]],"batb":[[0,1.02,9.8],[1,1.01,107.09],[2,1.01,0]],"batl":[[0,1.04,1476.1],[1,1.05,395.16],[2,1.06,344.13]],"ltp":1.04,"tv":34991.84,"id":9634485},{"trd":[[26,76.99]],"batl":[[0,30,2.34],[1,34,179.98],[2,990,0.01]],"ltp":26.0,"tv":1715.79,"id":9712888}],"tv":36707.64}]}
{"op":"mcm","clk":"4233915106","pt":1631539993733,"mc":[{"id":"1.187557759","rc":[{"trd":[[1.04,8944.47]],"batl":[[0,1.04,807.69],[1,1.05,846.96]],"ltp":1.04,"tv":36328.66,"id":9634485}],"tv":38044.46}]}
{"op":"mcm","clk":"4233915138","pt":1631539993997,"mc":[{"id":"1.187557759","rc":[{"batl":[[2,1.06,135.87]],"ltp":1.04,"tv":36328.66,"id":9634485}]}]}
{"op":"mcm","clk":"4233915424","pt":1631539997227,"mc":[{"id":"1.187557759","rc":[{"trd":[[1.04,9596.13]],"batb":[[0,1.03,345.9],[1,1.02,9.8],[2,1.01,107.09]],"batl":[[0,1.04,481.86],[1,1.05,1057.21]],"ltp":1.04,"tv":36980.32,"id":9634485}],"tv":38696.12}]}
{"op":"mcm","clk":"4233915702","pt":1631540000408,"mc":[{"id":"1.187557759","rc":[{"trd":[[1.04,9890.21]],"batb":[[0,1.03,526.42]],"batl":[[0,1.04,334.82],[2,1.07,11.05]],"ltp":1.04,"tv":37274.4,"id":9634485}],"tv":38990.2}]}
{"op":"mcm","clk":"4233915970","pt":1631540003418,"mc":[{"id":"1.187557759","rc":[{"batb":[[0,1.03,674.9]],"batl":[[1,1.05,1144.2]],"ltp":1.04,"tv":37274.4,"id":9634485},{"batb":[[0,21,30.53]],"batl":[[1,34,188.41]],"ltp":26.0,"tv":1715.79,"id":9712888}]}]}
{"op":"mcm","clk":"4233916259","pt":1631540006831,"mc":[{"id":"1.187557759","rc":[{"trd":[[1.04,9894.54]],"batl":[[0,1.04,332.65]],"ltp":1.04,"tv":37278.74,"id":9634485}],"tv":38994.54}]}
{"op":"mcm","clk":"4233916354","pt":1631540007826,"mc":[{"id":"1.187557759","rc":[{"batb":[[1,1.01,107.09],[2,1.01,0]],"batl":[[1,1.05,451.8],[2,1.07,1.7]],"ltp":1.04,"tv":37278.74,"id":9634485},{"batb":[[0,1.01,115.38],[1,17,0],[2,16,0]],"batl":[[0,990,0.01],[1,34,0],[2,990,0]],"ltp":26.0,"tv":1715.79,"id":9712888}]}]}
{"op":"mcm","clk":"4233916399","pt":1631540008343,"mc":[{"id":"1.187557759","rc":[{"batb":[[1,1.01,21.7]],"ltp":1.04,"tv":37278.74,"id":9634485}]}]}
{"op":"mcm","clk":"4233916627","pt":1631540010745,"mc":[{"id":"1.187557759","rc":[{"batl":[[2,1.06,209.02]],"ltp":1.04,"tv":37278.74,"id":9634485}]}]}
{"op":"mcm","clk":"4233917579","pt":1631540021323,"mc":[{"id":"1.187557759","rc":[{"batl":[[1,1.07,1.7],[2,1.11,3.53]],"ltp":1.04,"tv":37278.74,"id":9634485}]}]}
{"op":"mcm","clk":"4233917775","pt":1631540023764,"mc":[{"id":"1.187557759","rc":[{"batl":[[0,1.04,393.14],[1,1.05,1492.63],[2,1.06,9.43]],"ltp":1.04,"tv":37278.74,"id":9634485},{"batb":[[0,21,74.63],[1,19,10.52],[2,18.5,8.12]],"batl":[[0,34,101.22],[1,990,0.01]],"ltp":26.0,"tv":1715.79,"id":9712888}]}]}
{"op":"mcm","clk":"4233917862","pt":1631540024784,"mc":[{"id":"1.187557759","rc":[{"batb":[[1,1.02,9.8],[2,1.01,107.09]],"batl":[[0,1.04,1008]],"ltp":1.04,"tv":37278.74,"id":9634485},{"batb":[[2,18.5,1.62]],"ltp":26.0,"tv":1715.79,"id":9712888}]}]}
{"op":"mcm","clk":"4233918393","pt":1631540030754,"mc":[{"id":"1.187557759","rc":[{"batb":[[1,1.02,1133.12],[2,1.01,2911.98]],"batl":[[2,1.06,396.68]],"ltp":1.04,"tv":37278.74,"id":9634485},{"batl":[[1,55,2],[2,110,2]],"ltp":26.0,"tv":1715.79,"id":9712888}]}]}
{"op":"mcm","clk":"4233918642","pt":1631540033566,"mc":[{"id":"1.187557759","rc":[{"trd":[[1.04,9898.88]],"batl":[[0,1.04,1005.83]],"ltp":1.04,"tv":37283.08,"id":9634485}],"tv":38998.88}]}
{"op":"mcm","clk":"4233919277","pt":1631540040098,"mc":[{"id":"1.187557759","rc":[{"trd":[[1.03,2916.06]],"batb":[[0,1.03,673.2]],"ltp":1.03,"tv":37286.48,"id":9634485}],"tv":39002.28}]}
{"op":"mcm","clk":"4233919848","pt":1631540045587,"mc":[{"id":"1.187557759","rc":[{"batb":[[0,1.01,2826.59],[1,1.02,0],[2,1.01,0]],"batl":[[0,1.04,330.48],[1,1.06,387.25],[2,1.07,353.2]],"ltp":1.03,"tv":37286.48,"id":9634485},{"batb":[[0,17.5,2],[1,16,9.04],[2,15,2]],"batl":[[0,110,2],[1,990,0.01],[2,110,0]],"ltp":26.0,"tv":1715.79,"id":9712888}]}]}
{"op":"mcm","clk":"4233920146","pt":1631540048809,"mc":[{"id":"1.187557759","rc":[{"batb":[[0,1.02,2390.21],[1,1.01,3876.59]],"batl":[[1,1.05,662.05],[2,1.06,484.25]],"ltp":1.03,"tv":37286.48,"id":9634485},{"batb":[[0,17.5,4],[2,15,5]],"batl":[[0,55,4],[1,110,4],[2,990,0.01]],"ltp":26.0,"tv":1715.79,"id":9712888}]}]}
{"op":"mcm","clk":"4233920507","pt":1631540052817,"mc":[{"id":"1.187557759","rc":[{"batl":[[1,1.06,484.25],[2,1.07,443.2]],"ltp":1.03,"tv":37286.48,"id":9634485}]}]}
{"op":"mcm","clk":"4233920540","pt":1631540053076,"mc":[{"id":"1.187557759","rc":[{"batl":[[1,1.06,97],[2,1.07,91.7]],"ltp":1.03,"tv":37286.48,"id":9634485},{"batb":[[0,17.5,2]],"ltp":26.0,"tv":1715.79,"id":9712888}]}]}
{"op":"mcm","clk":"4233920639","pt":1631540054223,"mc":[{"id":"1.187557759","rc":[{"batl":[[2,1.07,1.7]],"ltp":1.03,"tv":37286.48,"id":9634485},{"batb":[[2,15,2]],"ltp":26.0,"tv":1715.79,"id":9712888}]}]}
{"op":"mcm","clk":"4233920778","pt":1631540055707,"mc":[{"id":"1.187557759","rc":[{"batl":[[0,1.03,801.57],[1,1.04,6169.08],[2,1.05,9.52]],"ltp":1.03,"tv":37286.48,"id":9634485},{"batb":[[0,27,5.56],[1,26,66.45],[2,22,9.1]],"batl":[[0,50,92.2],[1,55,4],[2,110,4]],"ltp":26.0,"tv":1715.79,"id":9712888}]}]}
{"op":"mcm","clk":"4233920843","pt":1631540056497,"mc":[{"id":"1.187557759","rc":[{"batb":[[1,1.01,3886.49]],"batl":[[1,1.04,2329.2]],"ltp":1.03,"tv":37286.48,"id":9634485}]}]}
{"op":"mcm","clk":"4233920943","pt":1631540057325,"mc":[{"id":"1.187557759","rc":[{"batl":[[1,1.04,2433.2],[2,1.05,107.52]],"ltp":1.03,"tv":37286.48,"id":9634485},{"batb":[[1,26,68.45],[2,22,5.46]],"ltp":26.0,"tv":1715.79,"id":9712888}]}]}
{"op":"mcm","clk":"4233921191","pt":1631540059320,"mc":[{"id":"1.187557759","rc":[{"batb":[[2,22,1.82]],"ltp":26.0,"tv":1715.79,"id":9712888}]}]}
{"op":"mcm","clk":"4233921563","pt":1631540062804,"mc":[{"id":"1.187557759","rc":[{"trd":[[1.02,0.1]],"batb":[[0,1.02,2390.16]],"batl":[[2,1.05,635.82]],"ltp":1.02,"tv":37286.58,"id":9634485}],"tv":39002.38}]}
{"op":"mcm","clk":"4233921573","pt":1631540062904,"mc":[{"id":"1.187557759","rc":[{"trd":[[1.03,2916.24]],"batl":[[0,1.03,801.48]],"ltp":1.03,"tv":37286.77,"id":9634485}],"tv":39002.57}]}
{"op":"mcm","clk":"4233921953","pt":1631540067353,"mc":[{"id":"1.187557759","rc":[{"batl":[[1,1.04,2095.56]],"ltp":1.03,"tv":37286.77,"id":9634485}]}]}
{"op":"mcm","clk":"4233922494","pt":1631540073139,"mc":[{"id":"1.187557759","rc":[{"batl":[[0,1.03,655.78]],"ltp":1.03,"tv":37286.77,"id":9634485},{"batl":[[0,50,88.1]],"ltp":26.0,"tv":1715.79,"id":9712888}]}]}
{"op":"mcm","clk":"4233922656","pt":1631540074816,"mc":[{"id":"1.187557759","rc":[{"batb":[[1,1.01,3876.59]],"batl":[[1,1.04,484.36],[2,1.05,626.3]],"ltp":1.03,"tv":37286.77,"id":9634485},{"batb":[[0,26,4],[1,21,4],[2,20,7.61]],"batl":[[0,55,4],[1,110,4],[2,990,0.01]],"ltp":26.0,"tv":1715.79,"id":9712888}]}]}
{"op":"mcm","clk":"4233922727","pt":1631540075545,"mc":[{"id":"1.187557759","rc":[{"batb":[[0,1.01,3876.59],[1,1.01,0]],"batl":[[0,1.04,330.48],[1,1.05,626.3],[2,1.06,518.75]],"ltp":1.03,"tv":37286.77,"id":9634485},{"batb":[[0,21,4],[1,17.5,10.36],[2,15,2]],"batl":[[0,110,4],[1,990,0.01],[2,990,0]],"ltp":26.0,"tv":1715.79,"id":9712888}]}]}
{"op":"mcm","clk":"4233922953","pt":1631540077847,"mc":[{"id":"1.187557759","rc":[{"batb":[[0,1.01,4564.86]],"batl":[[0,1.04,986.47]],"ltp":1.03,"tv":37286.77,"id":9634485}]}]}
{"op":"mcm","clk":"4233922996","pt":1631540078419,"mc":[{"id":"1.187557759","rc":[{"batb":[[2,15,5]],"ltp":26.0,"tv":1715.79,"id":9712888}]}]}
{"op":"mcm","clk":"4233923382","pt":1631540082545,"mc":[{"id":"1.187557759","rc":[{"batb":[[0,1.01,3876.59]],"ltp":1.03,"tv":37286.77,"id":9634485}]}]}
{"op":"mcm","clk":"4233923510","pt":1631540084090,"mc":[{"id":"1.187557759","rc":[{"batb":[[2,15,2]],"ltp":26.0,"tv":1715.79,"id":9712888}]}]}
{"op":"mcm","clk":"4233923684","pt":1631540085766,"mc":[{"id":"1.187557759","rc":[{"batb":[[0,1.03,674.9],[1,1.02,4352.76],[2,1.01,3961.98]],"batl":[[0,1.04,1049.88],[1,1.05,2100.23]],"ltp":1.03,"tv":37286.77,"id":9634485},{"batb":[[0,21,77.7]],"batl":[[0,32,1.24],[1,34,3.41],[2,50,244.74]],"ltp":26.0,"tv":1715.79,"id":9712888}]}]}
{"op":"mcm","clk":"4233923778","pt":1631540086764,"mc":[{"id":"1.187557759","rc":[{"batb":[[1,1.02,360.81]],"batl":[[2,1.06,528.18]],"ltp":1.03,"tv":37286.77,"id":9634485},{"batb":[[0,23,1.3],[1,21,77.7],[2,17.5,10.36]],"ltp":26.0,"tv":1715.79,"id":9712888}]}]}
{"op":"mcm","clk":"4233923868","pt":1631540087650,"mc":[{"id":"1.187557759","rc":[{"batb":[[0,1.03,1057.9],[1,1.02,910.81],[2,1.01,7892.24]],"batl":[[0,1.04,1144.88]],"ltp":1.03,"tv":37286.77,"id":9634485},{"batb":[[0,26,2],[1,23,1.3],[2,21,77.7]],"batl":[[2,36,2]],"ltp":26.0,"tv":1715.79,"id":9712888}]}]}
{"op":"mcm","clk":"4233924341","pt":1631540091983,"mc":[{"id":"1.187557759","rc":[{"batb":[[1,1.02,2289.01]],"ltp":1.03,"tv":37286.77,"id":9634485}]}]}
{"op":"mcm","clk":"4233924941","pt":1631540097464,"mc":[{"id":"1.187557759","rc":[{"batb":[[1,1.02,1938]],"ltp":1.03,"tv":37286.77,"id":9634485}]}]}
{"op":"mcm","clk":"4233925190","pt":1631540099762,"mc":[{"id":"1.187557759","rc":[{"batb":[[0,1.03,383],[1,1.02,1928.2],[2,1.01,7806.86]],"batl":[[0,1.04,425.48],[1,1.05,98],[2,1.06,518.75]],"ltp":1.03,"tv":37286.77,"id":9634485},{"batb":[[1,21,2],[2,17.5,10.36]],"batl":[[0,36,2],[1,55,4],[2,110,4]],"ltp":26.0,"tv":1715.79,"id":9712888}]}]}
{"op":"mcm","clk":"4233925229","pt":1631540100179,"mc":[{"id":"1.187557759","rc":[{"batb":[[0,1.02,1928.2],[1,1.01,7806.86],[2,1.01,0]],"batl":[[0,1.04,330.48]],"ltp":1.03,"tv":37286.77,"id":9634485},{"batb":[[0,21,2],[1,17.5,4],[2,16,8.62]],"batl":[[0,55,4],[1,110,4],[2,990,0.01]],"ltp":26.0,"tv":1715.79,"id":9712888}]}]}
{"op":"mcm","clk":"4233925707","pt":1631540104774,"mc":[{"id":"1.187557759","rc":[{"batb":[[0,1.03,674.9],[1,1.02,1928.2],[2,1.01,7806.86]],"batl":[[0,1.04,998.89]],"ltp":1.03,"tv":37286.77,"id":9634485}]}]}
{"op":"mcm","clk":"4233926371","pt":1631540111478,"mc":[{"id":"1.187557759","rc":[{"batb":[[0,1.02,1928.2],[1,1.01,7806.86],[2,1.01,0]],"batl":[[0,1.04,330.48]],"ltp":1.03,"tv":37286.77,"id":9634485}]}]}
{"op":"mcm","clk":"4233926660","pt":1631540114510,"mc":[{"id":"1.187557759","rc":[{"batb":[[0,1.02,2609.72]],"batl":[[1,1.05,760.05]],"ltp":1.03,"tv":37286.77,"id":9634485}]}]}
{"op":"mcm","clk":"4233926785","pt":1631540115580,"mc":[{"id":"1.187557759","rc":[{"batl":[[1,1.05,98],[2,1.06,97]],"ltp":1.03,"tv":37286.77,"id":9634485},{"batb":[[1,17.5,2]],"ltp":26.0,"tv":1715.79,"id":9712888}]}]}
{"op":"mcm","clk":"4233926917","pt":1631540117096,"mc":[{"id":"1.187557759","rc":[{"batl":[[2,1.07,1.7]],"ltp":1.03,"tv":37286.77,"id":9634485},{"batb":[[1,16,8.62],[2,15,2]],"ltp":26.0,"tv":1715.79,"id":9712888}]}]}
{"op":"mcm","clk":"4233927075","pt":1631540118824,"mc":[{"id":"1.187557759","rc":[{"batb":[[1,1.01,3876.59]],"batl":[[0,1.03,865.45],[1,1.04,2329.2],[2,1.05,107.52]],"ltp":1.03,"tv":37286.77,"id":9634485},{"batb":[[0,29,5.16],[1,26,66.45],[2,21,2]],"batl":[[0,50,88.56],[1,55,4],[2,110,4]],"ltp":26.0,"tv":1715.79,"id":9712888}]}]}
{"op":"mcm","clk":"4233927127","pt":1631540119299,"mc":[{"id":"1.187557759","rc":[{"batb":[[1,1.01,3886.49]],"ltp":1.03,"tv":37286.77,"id":9634485}]}]}
{"op":"mcm","clk":"4233927197","pt":1631540119928,"mc":[{"id":"1.187557759","rc":[{"batl":[[0,1.03,958.45],[1,1.04,2430.2]],"ltp":1.03,"tv":37286.77,"id":9634485},{"batb":[[0,34,2],[1,29,5.16],[2,26,68.45]],"ltp":26.0,"tv":1715.79,"id":9712888}]}]}
{"op":"mcm","clk":"4233927728","pt":1631540124807,"mc":[{"id":"1.187557759","rc":[{"batl":[[2,1.05,616.02]],"ltp":1.03,"tv":37286.77,"id":9634485}]}]}
{"op":"mcm","clk":"4233928291","pt":1631540130220,"mc":[{"id":"1.187557759","rc":[{"batl":[[1,1.04,2092.56]],"ltp":1.03,"tv":37286.77,"id":9634485}]}]}
{"op":"mcm","clk":"4233928653","pt":1631540133717,"mc":[{"id":"1.187557759","rc":[{"batb":[[0,1.02,550],[1,1.01,3876.59]],"batl":[[0,1.03,93],[1,1.04,431.48],[2,1.05,606.5]],"ltp":1.03,"tv":37286.77,"id":9634485},{"batb":[[1,26,2],[2,21,4]],"batl":[[0,55,2],[1,110,4],[2,520,36.01]],"ltp":26.0,"tv":1715.79,"id":9712888}]}]}
{"op":"mcm","clk":"4233928687","pt":1631540134090,"mc":[{"id":"1.187557759","rc":[{"batb":[[0,1.01,3876.59],[1,1.01,0]],"batl":[[0,1.04,330.48],[1,1.05,606.5],[2,1.06,412.25]],"ltp":1.03,"tv":37286.77,"id":9634485},{"batb":[[0,21,4],[1,17.5,8.27],[2,15,2]],"batl":[[0,110,4],[1,520,36.01],[2,990,0.01]],"ltp":26.0,"tv":1715.79,"id":9712888}]}]}
{"op":"mcm","clk":"4233928930","pt":1631540136447,"mc":[{"id":"1.187557759","rc":[{"batb":[[0,1.01,4564.86]],"batl":[[0,1.04,998.89]],"ltp":1.03,"tv":37286.77,"id":9634485}]}]}
{"op":"mcm","clk":"4233928978","pt":1631540136918,"mc":[{"id":"1.187557759","rc":[{"batl":[[2,1.06,512.25]],"ltp":1.03,"tv":37286.77,"id":9634485},{"batb":[[1,17.5,10.27]],"ltp":26.0,"tv":1715.79,"id":9712888}]}]}
{"op":"mcm","clk":"4233929121","pt":1631540138234,"mc":[{"id":"1.187557759","rc":[{"batb":[[0,1.01,4565.64]],"ltp":1.03,"tv":37286.77,"id":9634485}]}]}
{"op":"mcm","clk":"4233929807","pt":1631540144645,"mc":[{"id":"1.187557759","rc":[{"batb":[[0,1.01,4564.86]],"batl":[[1,1.05,706.5]],"ltp":1.03,"tv":37286.77,"id":9634485}]}]}
{"op":"mcm","clk":"4233929865","pt":1631540145266,"mc":[{"id":"1.187557759","rc":[{"batb":[[0,1.01,3876.59]],"ltp":1.03,"tv":37286.77,"id":9634485}]}]}
{"op":"mcm","clk":"4233930029","pt":1631540146638,"mc":[{"id":"1.187557759","rc":[{"batl":[[1,990,0.01],[2,990,0]],"ltp":26.0,"tv":1715.79,"id":9712888}]}]}
{"op":"mcm","clk":"4233930219","pt":1631540148629,"mc":[{"id":"1.187557759","rc":[{"batb":[[0,1.03,674.9],[1,1.02,360.81],[2,1.01,3961.98]],"batl":[[0,1.04,1065.2],[1,1.05,2229.69]],"ltp":1.03,"tv":37286.77,"id":9634485},{"batb":[[0,21,80.16]],"batl":[[0,30,1.34],[1,34,82.1],[2,110,4]],"ltp":26.0,"tv":1715.79,"id":9712888}]}]}
{"op":"mcm","clk":"4233930347","pt":1631540149837,"mc":[{"id":"1.187557759","rc":[{"batb":[[0,1.03,1057.9],[1,1.02,910.81]],"batl":[[0,1.04,1167.2],[2,1.06,521.68]],"ltp":1.03,"tv":37286.77,"id":9634485},{"batb":[[0,26,2],[1,24,1.24],[2,21,80.16]],"batl":[[2,36,2]],"ltp":26.0,"tv":1715.79,"id":9712888}]}]}
{"op":"mcm","clk":"4233930467","pt":1631540150947,"mc":[{"id":"1.187557759","rc":[{"batb":[[2,1.01,7892.24]],"ltp":1.03,"tv":37286.77,"id":9634485}]}]}
{"op":"mcm","clk":"4233930863","pt":1631540154636,"mc":[{"id":"1.187557759","rc":[{"batb":[[1,1.02,2085.6]],"ltp":1.03,"tv":37286.77,"id":9634485}]}]}
{"op":"mcm","clk":"4233930908","pt":1631540155054,"mc":[{"id":"1.187557759","rc":[{"trd":[[1.04,9899.66]],"batl":[[0,1.04,1166.82]],"ltp":1.04,"tv":37287.54,"id":9634485}],"tv":39003.34}]}
{"op":"mcm","clk":"4233931364","pt":1631540159207,"mc":[{"id":"1.187557759","rc":[{"batl":[[1,1.05,2129.69]],"ltp":1.04,"tv":37287.54,"id":9634485}]}]}
{"op":"mcm","clk":"4233931463","pt":1631540160049,"mc":[{"id":"1.187557759","rc":[{"batb":[[1,1.02,1734.59]],"ltp":1.04,"tv":37287.54,"id":9634485}]}]}
{"op":"mcm","clk":"4233931758","pt":1631540162379,"mc":[{"id":"1.187557759","rc":[{"trd":[[1.03,2919.65]],"batb":[[0,1.03,1056.2]],"batl":[[2,1.06,621.68]],"ltp":1.03,"tv":37290.94,"id":9634485}],"tv":39006.74}]}
{"op":"mcm","clk":"4233931947","pt":1631540163797,"mc":[{"id":"1.187557759","rc":[{"batb":[[0,1.02,1724.79],[1,1.01,7806.86],[2,1.01,0]],"batl":[[0,1.04,330.1],[1,1.05,606.5],[2,1.06,612.25]],"ltp":1.03,"tv":37290.94,"id":9634485},{"batb":[[0,21,4],[1,17.5,4],[2,16,8.62]],"batl":[[0,55,4],[1,110,4],[2,990,0.01]],"ltp":26.0,"tv":1715.79,"id":9712888}]}]}
{"op":"mcm","clk":"4233932267","pt":1631540166679,"mc":[{"id":"1.187557759","rc":[{"batb":[[0,1.02,2406.31]],"batl":[[1,1.05,1268.55]],"ltp":1.03,"tv":37290.94,"id":9634485}]}]}
{"op":"mcm","clk":"4233932998","pt":1631540173286,"mc":[{"id":"1.187557759","rc":[{"batl":[[1,1.05,606.5],[2,1.06,200]],"ltp":1.03,"tv":37290.94,"id":9634485}]}]}
{"op":"mcm","clk":"4233933105","pt":1631540174383,"mc":[{"id":"1.187557759","rc":[{"batl":[[2,1.06,100]],"ltp":1.03,"tv":37290.94,"id":9634485},{"batb":[[1,17.5,2]],"ltp":26.0,"tv":1715.79,"id":9712888}]}]}
{"op":"mcm","clk":"4233933271","pt":1631540175796,"mc":[{"id":"1.187557759","rc":[{"trd":[[1.02,400.1]],"batb":[[0,1.02,2206.31],[1,1.01,3876.59]],"batl":[[0,1.03,351.76],[1,1.04,1941.3],[2,1.05,616.02]],"ltp":1.02,"tv":37690.94,"id":9634485},{"batb":[[0,28,5.36],[1,26,64.45],[2,21,4]],"batl":[[0,50,85.02],[1,55,4],[2,110,4]],"ltp":26.0,"tv":1715.79,"id":9712888}],"tv":39406.74}]}
{"op":"mcm","clk":"4233933385","pt":1631540176734,"mc":[{"id":"1.187557759","rc":[{"batb":[[1,1.01,3886.49]],"batl":[[0,1.03,871.32],[1,1.04,1991.18]],"ltp":1.02,"tv":37690.94,"id":9634485},{"batb":[[1,26,66.45]],"ltp":26.0,"tv":1715.79,"id":9712888}]}]}
{"op":"mcm","clk":"4233933450","pt":1631540177310,"mc":[{"id":"1.187557759","rc":[{"batl":[[0,1.03,965.32],[1,1.04,2099.18]],"ltp":1.02,"tv":37690.94,"id":9634485},{"batb":[[0,34,2],[1,28,5.36],[2,26,68.45]],"ltp":26.0,"tv":1715.79,"id":9712888}]}]}
{"op":"mcm","clk":"4233933778","pt":1631540180707,"mc":[{"id":"1.187557759","rc":[{"batl":[[2,1.05,1674.78]],"ltp":1.02,"tv":37690.94,"id":9634485},{"batl":[[0,38,4.01],[1,50,85.02],[2,55,4]],"ltp":26.0,"tv":1715.79,"id":9712888}]}]}
{"op":"mcm","clk":"4233933812","pt":1631540181038,"mc":[{"id":"1.187557759","rc":[{"batl":[[2,1.05,616.02]],"ltp":1.02,"tv":37690.94,"id":9634485},{"batl":[[0,50,85.02],[1,55,4],[2,110,4]],"ltp":26.0,"tv":1715.79,"id":9712888}]}]}
{"op":"mcm","clk":"4233935388","pt":1631540195848,"mc":[{"id":"1.187557759","rc":[{"batb":[[0,1.01,3876.59],[1,1.01,0]],"batl":[[0,1.04,330.1],[1,1.05,606.5],[2,1.06,522.25]],"ltp":1.02,"tv":37690.94,"id":9634485},{"batb":[[0,21,4],[1,17.5,8.19],[2,1.01,115.38]],"batl":[[0,110,4],[1,520,36.01],[2,990,0.01]],"ltp":26.0,"tv":1715.79,"id":9712888}]}]}
{"op":"mcm","clk":"4233935677","pt":1631540198839,"mc":[{"id":"1.187557759","rc":[{"batl":[[0,1.04,1016.73],[2,1.06,623.25]],"ltp":1.02,"tv":37690.94,"id":9634485},{"batb":[[0,26,2],[1,21,4],[2,17.5,10.19]],"ltp":26.0,"tv":1715.79,"id":9712888}]}]}
{"op":"mcm","clk":"4233935852","pt":1631540200568,"mc":[{"id":"1.187557759","rc":[{"batb":[[0,1.02,681.52],[1,1.01,3876.59]],"batl":[[0,1.03,674.9],[1,1.04,1016.73],[2,1.05,606.5]],"ltp":1.02,"tv":37690.94,"id":9634485}]}]}
{"op":"mcm","clk":"4233936458","pt":1631540206574,"mc":[{"id":"1.187557759","rc":[{"batb":[[0,1.01,3876.59],[1,1.01,0]],"batl":[[0,1.04,1016.73],[1,1.05,606.5],[2,1.06,623.25]],"ltp":1.02,"tv":37690.94,"id":9634485}]}]}
{"op":"mcm","clk":"4233936651","pt":1631540208460,"mc":[{"id":"1.187557759","rc":[{"batl":[[1,990,0.01],[2,990,0]],"ltp":26.0,"tv":1715.79,"id":9712888}]}]}
{"op":"mcm","clk":"4233936740","pt":1631540209462,"mc":[{"id":"1.187557759","rc":[{"batb":[[0,1.01,4564.86]],"batl":[[0,1.04,1685.14]],"ltp":1.02,"tv":37690.94,"id":9634485}]}]}
{"op":"mcm","clk":"4233937017","pt":1631540212646,"mc":[{"id":"1.187557759","rc":[{"batl":[[0,1.04,1016.73],[1,1.05,98],[2,1.06,201]],"ltp":1.02,"tv":37690.94,"id":9634485},{"batb":[[2,17.5,8.19]],"ltp":26.0,"tv":1715.79,"id":9712888}]}]}
{"op":"mcm","clk":"4233937147","pt":1631540213950,"mc":[{"id":"1.187557759","rc":[{"batl":[[2,1.06,100]],"ltp":1.02,"tv":37690.94,"id":9634485},{"batb":[[2,17.5,6.19]],"ltp":26.0,"tv":1715.79,"id":9712888}]}]}
{"op":"mcm","clk":"4233937314","pt":1631540215661,"mc":[{"id":"1.187557759","rc":[{"batl":[[0,1.02,1002.48],[1,1.03,3602.12],[2,1.04,1026.35]],"ltp":1.02,"tv":37690.94,"id":9634485},{"batb":[[0,50,2],[1,26,2],[2,21,4]],"batl":[[0,100,75.8],[1,110,4],[2,990,0.01]],"ltp":26.0,"tv":1715.79,"id":9712888}]}]}
{"op":"mcm","clk":"4233937391","pt":1631540216400,"mc":[{"id":"1.187557759","rc":[{"batb":[[1,26,6.86],[2,21,10.59]],"ltp":26.0,"tv":1715.79,"id":9712888}]}]}
{"op":"mcm","clk":"4233937541","pt":1631540217688,"mc":[{"id":"1.187557759","rc":[{"batl":[[1,1.03,3695.12],[2,1.04,1124.35]],"ltp":1.02,"tv":37690.94,"id":9634485},{"batb":[[1,34,2],[2,26,8.86]],"ltp":26.0,"tv":1715.79,"id":9712888}]}]}
{"op":"mcm","clk":"4233937932","pt":1631540221808,"mc":[{"id":"1.187557759","rc":[{"batl":[[1,1.03,4547.62]],"ltp":1.02,"tv":37690.94,"id":9634485},{"batb":[[1,34,4]],"ltp":26.0,"tv":1715.79,"id":9712888}]}]}
{"op":"mcm","clk":"4233938333","pt":1631540226203,"mc":[{"id":"1.187557759","rc":[{"trd":[[1.02,833.72]],"batl":[[0,1.02,785.67]],"ltp":1.02,"tv":38124.56,"id":9634485}],"tv":39840.36}]}
{"op":"mcm","clk":"4233938432","pt":1631540227297,"mc":[{"id":"1.187557759","rc":[{"trd":[[1.02,838.06]],"batl":[[0,1.02,783.5],[1,1.03,4206.74]],"ltp":1.02,"tv":38128.9,"id":9634485}],"tv":39844.7}]}
{"op":"mcm","clk":"4233938936","pt":1631540232691,"mc":[{"id":"1.187557759","rc":[{"batb":[[0,1.01,3876.59]],"batl":[[0,1.03,93],[1,1.04,1114.73],[2,1.05,648.7]],"ltp":1.02,"tv":38128.9,"id":9634485},{"batb":[[0,34,2],[1,26,4],[2,21,10.59]],"batl":[[0,110,4],[1,990,0.01],[2,990,0]],"ltp":26.0,"tv":1715.79,"id":9712888}]}]}
{"op":"mcm","clk":"4233939015","pt":1631540233785,"mc":[{"id":"1.187557759","rc":[{"batb":[[0,1.01,21.7]],"batl":[[0,1.04,1114.73],[1,1.05,648.7],[2,1.06,100]],"ltp":1.02,"tv":38128.9,"id":9634485},{"batb":[[0,26,4],[1,21,10.59],[2,1.02,6]],"batl":[[0,990,0.01],[1,990,0]],"ltp":26.0,"tv":1715.79,"id":9712888}]}]}
{"op":"mcm","clk":"4233939206","pt":1631540235814,"mc":[{"id":"1.187557759","rc":[{"batl":[[0,1.03,830.5],[1,1.04,1114.73],[2,1.05,648.7]],"ltp":1.02,"tv":38128.9,"id":9634485},{"batb":[[0,34,2],[1,26,4],[2,21,10.59]],"ltp":26.0,"tv":1715.79,"id":9712888}]}]}
{"op":"mcm","clk":"4233939293","pt":1631540236799,"mc":[{"id":"1.187557759","rc":[{"batb":[[0,1.01,709.97]],"batl":[[0,1.02,681.52]],"ltp":1.02,"tv":38128.9,"id":9634485},{"batb":[[0,26,4],[1,21,10.59],[2,17.5,2]],"ltp":26.0,"tv":1715.79,"id":9712888}]}]}
{"op":"mcm","clk":"4233939322","pt":1631540237214,"mc":[{"id":"1.187557759","rc":[{"trd":[[1.01,1419.94]],"batl":[[0,1.01,454.03],[1,1.02,681.52],[2,1.04,1114.73]],"ltp":1.01,"tv":39548.84,"id":9634485}],"tv":41264.64}]}
{"op":"mcm","clk":"4233939441","pt":1631540238619,"mc":[{"id":"1.187557759","rc":[{"batl":[[0,1.02,681.52],[1,1.04,1114.73],[2,1.05,648.7]],"ltp":1.01,"tv":39548.84,"id":9634485}]}]}
{"op":"mcm","clk":"4233939517","pt":1631540239296,"mc":[{"id":"1.187557759","rc":[{"batl":[[1,1.03,787.5],[2,1.04,1114.73]],"ltp":1.01,"tv":39548.84,"id":9634485},{"batb":[[0,34,2],[1,26,4],[2,21,10.59]],"ltp":26.0,"tv":1715.79,"id":9712888}]}]}
{"op":"mcm","clk":"4233939598","pt":1631540240231,"mc":[{"id":"1.187557759","rc":[{"batb":[[0,1.01,688.27]],"ltp":1.01,"tv":39548.84,"id":9634485}]}]}
{"op":"mcm","clk":"4233939768","pt":1631540242245,"mc":[{"id":"1.187557759","rc":[{"batl":[[0,1.04,1114.73],[1,1.05,648.7],[2,1.06,209]],"ltp":1.01,"tv":39548.84,"id":9634485},{"batb":[[0,26,4],[1,21,10.59],[2,17.5,2]],"ltp":26.0,"tv":1715.79,"id":9712888}]}]}
{"op":"mcm","clk":"4233939993","pt":1631540244938,"mc":[{"id":"1.187557759","rc":[{"batl":[[0,1.03,674.9],[1,1.04,1114.73],[2,1.05,648.7]],"ltp":1.01,"tv":39548.84,"id":9634485}]}]}
{"op":"mcm","clk":"4233940168","pt":1631540246648,"mc":[{"id":"1.187557759","rc":[{"batl":[[0,1.04,428.1],[1,1.05,98],[2,1.06,209]],"ltp":1.01,"tv":39548.84,"id":9634485},{"batb":[[1,21,2]],"ltp":26.0,"tv":1715.79,"id":9712888}]}]}
{"op":"mcm","clk":"4233940267","pt":1631540247734,"mc":[{"id":"1.187557759","rc":[{"batl":[[0,1.04,330.1],[1,1.06,100],[2,1.07,1.7]],"ltp":1.01,"tv":39548.84,"id":9634485},{"batb":[[0,26,2],[1,1.02,6],[2,1.01,115.38]],"ltp":26.0,"tv":1715.79,"id":9712888}]}]}
{"op":"mcm","clk":"4233940424","pt":1631540249545,"mc":[{"id":"1.187557759","rc":[{"batl":[[0,1.01,790.66],[1,1.02,29.42],[2,1.03,24.41]],"ltp":1.01,"tv":39548.84,"id":9634485},{"batb":[[0,140,23.18],[1,100,2],[2,26,2]],"ltp":26.0,"tv":1715.79,"id":9712888}]}]}
{"op":"mcm","clk":"4233940564","pt":1631540251162,"mc":[{"id":"1.187557759","rc":[{"batl":[[2,1.03,24.54]],"ltp":1.01,"tv":39548.84,"id":9634485}]}]}
{"op":"mcm","clk":"4233941709","pt":1631540265065,"mc":[{"id":"1.187557759","rc":[{"batl":[[0,1.01,1041.9]],"ltp":1.01,"tv":39548.84,"id":9634485},{"trd":[[140,3.4]],"batb":[[0,140,21.48]],"ltp":140.0,"tv":1719.2,"id":9712888}],"tv":41268.04}]}
{"op":"mcm","clk":"4233942292","pt":1631540271672,"mc":[{"id":"1.187557759","rc":[{"batl":[[2,1.03,279.74]],"ltp":1.01,"tv":39548.84,"id":9634485}]}]}
{"op":"mcm","clk":"4233944166","pt":1631540294106,"mc":[{"id":"1.187557759","rc":[{"batl":[[0,1.01,942.4]],"ltp":1.01,"tv":39548.84,"id":9634485},{"batb":[[0,1.02,6],[1,1.01,115.38],[2,26,0]],"ltp":140.0,"tv":1719.2,"id":9712888}]}]}
{"op":"mcm","clk":"4233944445","pt":1631540297614,"mc":[{"id":"1.187557759","rc":[{"batl":[[1,1.02,131.42],[2,1.03,377.74]],"ltp":1.01,"tv":39548.84,"id":9634485},{"batb":[[0,50,2],[1,34,2],[2,26,2]],"ltp":140.0,"tv":1719.2,"id":9712888}]}]}
{"op":"mcm","clk":"4233945881","pt":1631540316760,"mc":[{"id":"1.187557759","rc":[{"batl":[[0,1.01,3956.94]],"ltp":1.01,"tv":39548.84,"id":9634485},{"batl":[[0,230,85.62],[1,290,45.55],[2,990,0.01]],"ltp":140.0,"tv":1719.2,"id":9712888}]}]}
{"op":"mcm","clk":"4233945956","pt":1631540317756,"mc":[{"id":"1.187557759","rc":[{"batl":[[0,290,45.55],[1,990,0.01],[2,990,0]],"ltp":140.0,"tv":1719.2,"id":9712888}]}]}
{"op":"mcm","clk":"4233946280","pt":1631540321791,"mc":[{"id":"1.187557759","rc":[{"batl":[[2,1.03,2342.79]],"ltp":1.01,"tv":39548.84,"id":9634485},{"batl":[[0,160,1.16],[1,290,45.55],[2,990,0.01]],"ltp":140.0,"tv":1719.2,"id":9712888}]}]}
{"op":"mcm","clk":"4233946294","pt":1631540322010,"mc":[{"id":"1.187557759","rc":[{"batl":[[2,1.03,377.74]],"ltp":1.01,"tv":39548.84,"id":9634485},{"batl":[[0,290,45.55],[1,990,0.01],[2,990,0]],"ltp":140.0,"tv":1719.2,"id":9712888}]}]}
{"op":"mcm","clk":"4233947194","pt":1631540332276,"mc":[{"id":"1.187557759","rc":[{"batl":[[0,1.01,254.13]],"ltp":1.01,"tv":39548.84,"id":9634485},{"batl":[[0,990,0.01],[1,990,0]],"ltp":140.0,"tv":1719.2,"id":9712888}]}]}
{"op":"mcm","clk":"4233947513","pt":1631540335796,"mc":[{"id":"1.187557759","rc":[{"batl":[[1,1.02,29.42]],"ltp":1.01,"tv":39548.84,"id":9634485},{"batb":[[0,34,2],[1,26,2],[2,1.02,6]],"ltp":140.0,"tv":1719.2,"id":9712888}]}]}
{"op":"mcm","clk":"4233947656","pt":1631540337471,"mc":[{"id":"1.187557759","rc":[{"batl":[[0,1.01,942.4]],"ltp":1.01,"tv":39548.84,"id":9634485}]}]}
{"op":"mcm","clk":"4233947745","pt":1631540338678,"mc":[{"id":"1.187557759","rc":[{"batb":[[2,21,2]],"ltp":140.0,"tv":1719.2,"id":9712888}]}]}
{"op":"mcm","clk":"4233948223","pt":1631540344290,"mc":[{"id":"1.187557759","rc":[{"batl":[[0,1.01,254.13]],"ltp":1.01,"tv":39548.84,"id":9634485}]}]}
{"op":"mcm","clk":"4233948509","pt":1631540347599,"mc":[{"id":"1.187557759","rc":[{"batl":[[1,1.02,710.94]],"ltp":1.01,"tv":39548.84,"id":9634485}]}]}
{"op":"mcm","clk":"4233948607","pt":1631540348823,"mc":[{"id":"1.187557759","rc":[{"trd":[[1.01,1928.19]],"batb":[[0,1.01,392.14]],"batl":[[0,1.02,3919.52],[1,1.03,377.74],[2,1.04,443.8]],"ltp":1.01,"tv":40057.09,"id":9634485},{"batl":[[0,140,115.68],[1,990,0.01]],"ltp":140.0,"tv":1719.2,"id":9712888}],"tv":41776.29}]}
{"op":"mcm","clk":"4233948684","pt":1631540349724,"mc":[{"id":"1.187557759","rc":[{"batb":[[2,25,5.96]],"batl":[[0,990,0.01],[1,990,0]],"ltp":140.0,"tv":1719.2,"id":9712888}]}]}
{"op":"mcm","clk":"4233949010","pt":1631540353704,"mc":[{"id":"1.187557759","rc":[{"batl":[[1,1.03,1985.03]],"ltp":1.01,"tv":40057.09,"id":9634485},{"batl":[[0,100,2],[1,990,0.01]],"ltp":140.0,"tv":1719.2,"id":9712888}]}]}
{"op":"mcm","clk":"4233949024","pt":1631540354020,"mc":[{"id":"1.187557759","rc":[{"batl":[[1,1.03,377.74]],"ltp":1.01,"tv":40057.09,"id":9634485},{"batl":[[0,990,0.01],[1,990,0]],"ltp":140.0,"tv":1719.2,"id":9712888}]}]}
{"op":"mcm","clk":"4233949126","pt":1631540355396,"mc":[{"id":"1.187557759","rc":[{"batl":[[0,1.02,5284.22],[1,1.03,1180.24],[2,1.04,1033.68]],"ltp":1.01,"tv":40057.09,"id":9634485},{"batb":[[0,50,2],[1,34,4],[2,26,2]],"ltp":140.0,"tv":1719.2,"id":9712888}]}]}
{"op":"mcm","clk":"4233950013","pt":1631540364616,"mc":[{"id":"1.187557759","rc":[{"trd":[[1.01,1943.67],[1.02,841.1]],"batb":[[0,1.01,384.4]],"batl":[[0,1.02,5282.7]],"ltp":1.01,"tv":40075.61,"id":9634485}],"tv":41794.81}]}
{"op":"mcm","clk":"4233950095","pt":1631540365715,"mc":[{"id":"1.187557759","rc":[{"batl":[[0,1.01,620.55],[1,1.03,1057.83],[2,1.04,1018.98]],"ltp":1.01,"tv":40075.61,"id":9634485},{"batb":[[0,34,2],[1,26,2],[2,25,5.96]],"ltp":140.0,"tv":1719.2,"id":9712888}]}]}
{"op":"mcm","clk":"4233950282","pt":1631540368525,"mc":[{"id":"1.187557759","rc":[{"batl":[[1,1.02,681.52],[2,1.03,1057.83]],"ltp":1.01,"tv":40075.61,"id":9634485}]}]}
{"op":"mcm","clk":"4233950376","pt":1631540369727,"mc":[{"id":"1.187557759","rc":[{"batl":[[0,120,19.16],[1,990,0.01]],"ltp":140.0,"tv":1719.2,"id":9712888}]}]}
{"op":"mcm","clk":"4233950436","pt":1631540370461,"mc":[{"id":"1.187557759","rc":[{"trd":[[1.01,3184.77]],"batb":[[0,1.01,67.72]],"batl":[[0,1.02,681.52],[1,1.03,1057.83],[2,1.04,1018.98]],"ltp":1.01,"tv":41316.71,"id":9634485},{"batl":[[0,990,0.01],[1,990,0]],"ltp":140.0,"tv":1719.2,"id":9712888}],"tv":43035.91}]}
{"op":"mcm","clk":"4233950496","pt":1631540371249,"mc":[{"id":"1.187557759","rc":[{"batl":[[1,1.03,1159.83]],"ltp":1.01,"tv":41316.71,"id":9634485},{"batb":[[0,34,4]],"ltp":140.0,"tv":1719.2,"id":9712888}]}]}
{"op":"mcm","clk":"4233950678","pt":1631540373353,"mc":[{"id":"1.187557759","rc":[{"batb":[[0,1.01,538.61]],"batl":[[0,1.02,2038.1]],"ltp":1.01,"tv":41316.71,"id":9634485},{"batb":[[0,50,2],[1,46,2],[2,42,2]],"ltp":140.0,"tv":1719.2,"id":9712888}]}]}
{"op":"mcm","clk":"4233951098","pt":1631540378071,"mc":[{"id":"1.187557759","rc":[{"batl":[[0,1.02,2038.27]],"ltp":1.01,"tv":41316.71,"id":9634485}]}]}
{"op":"mcm","clk":"4233951475","pt":1631540382759,"mc":[{"id":"1.187557759","rc":[{"batl":[[0,1.01,100.17],[1,1.02,2038.1],[2,1.03,357.33]],"ltp":1.01,"tv":41316.71,"id":9634485}]}]}
{"op":"mcm","clk":"4233951482","pt":1631540382866,"mc":[{"id":"1.187557759","rc":[{"batl":[[1,1.02,1356.58]],"ltp":1.01,"tv":41316.71,"id":9634485}]}]}
{"op":"mcm","clk":"4233951709","pt":1631540385750,"mc":[{"id":"1.187557759","rc":[{"batl":[[0,1.01,848.94],[1,1.02,4877.11],[2,1.03,367.04]],"ltp":1.01,"tv":41316.71,"id":9634485},{"batb":[[0,100,2],[1,50,2],[2,46,2]],"batl":[[0,190,34.91],[1,990,0.01]],"ltp":140.0,"tv":1719.2,"id":9712888}]}]}
{"op":"mcm","clk":"4233951907","pt":1631540387850,"mc":[{"id":"1.187557759","rc":[{"batl":[[0,1.01,848.77]],"ltp":1.01,"tv":41316.71,"id":9634485}]}]}
{"op":"mcm","clk":"4233953315","pt":1631540404177,"mc":[{"id":"1.187557759","rc":[{"batl":[[0,1.01,848.89]],"ltp":1.01,"tv":41316.71,"id":9634485}]}]}
{"op":"mcm","clk":"4233953568","pt":1631540407316,"mc":[{"id":"1.187557759","rc":[{"batl":[[0,1.01,100.12],[1,1.02,1356.58]],"ltp":1.01,"tv":41316.71,"id":9634485},{"batb":[[0,50,2],[1,46,2],[2,42,2]],"batl":[[0,990,0.01],[1,990,0]],"ltp":140.0,"tv":1719.2,"id":9712888}]}]}
{"op":"mcm","clk":"4233953865","pt":1631540410632,"mc":[{"id":"1.187557759","rc":[{"batl":[[1,1.02,2038.1]],"ltp":1.01,"tv":41316.71,"id":9634485}]}]}
{"op":"mcm","clk":"4233953953","pt":1631540411731,"mc":[{"id":"1.187557759","rc":[{"batl":[[1,1.02,1356.58]],"ltp":1.01,"tv":41316.71,"id":9634485}]}]}
{"op":"mcm","clk":"4233954206","pt":1631540414593,"mc":[{"id":"1.187557759","rc":[{"batl":[[0,1.01,808.89]],"ltp":1.01,"tv":41316.71,"id":9634485}]}]}
{"op":"mcm","clk":"4233954243","pt":1631540415011,"mc":[{"id":"1.187557759","rc":[{"batl":[[0,1.01,788.39]],"ltp":1.01,"tv":41316.71,"id":9634485}]}]}
{"op":"mcm","clk":"4233954730","pt":1631540421535,"mc":[{"id":"1.187557759","rc":[{"batl":[[0,1.01,100.12]],"ltp":1.01,"tv":41316.71,"id":9634485}]}]}
{"op":"mcm","clk":"4233955212","pt":1631540426845,"mc":[{"id":"1.187557759","rc":[{"batl":[[0,1.01,3850.12],[1,1.02,1381.58]],"ltp":1.01,"tv":41316.71,"id":9634485},{"batb":[[0,140,21.56],[1,50,2],[2,46,2]],"batl":[[0,490,36.98],[1,990,0.01]],"ltp":140.0,"tv":1719.2,"id":9712888}]}]}
{"op":"mcm","clk":"4233955233","pt":1631540427058,"mc":[{"id":"1.187557759","rc":[{"batl":[[0,1.01,834.89],[1,1.02,1356.58]],"ltp":1.01,"tv":41316.71,"id":9634485},{"batb":[[1,100,2],[2,50,2]],"ltp":140.0,"tv":1719.2,"id":9712888}]}]}
{"op":"mcm","clk":"4233955591","pt":1631540431817,"mc":[{"id":"1.187557759","rc":[{"batl":[[2,1.03,2499.48]],"ltp":1.01,"tv":41316.71,"id":9634485},{"batl":[[0,490,37.62]],"ltp":140.0,"tv":1719.2,"id":9712888}]}]}
{"op":"mcm","clk":"4233955598","pt":1631540431922,"mc":[{"id":"1.187557759","rc":[{"batl":[[2,1.03,367.04]],"ltp":1.01,"tv":41316.71,"id":9634485},{"batl":[[0,490,36.98]],"ltp":140.0,"tv":1719.2,"id":9712888}]}]}
{"op":"mcm","clk":"4233956479","pt":1631540442766,"mc":[{"id":"1.187557759","rc":[{"batb":[[0,100,2],[1,50,2],[2,46,2]],"batl":[[0,990,0.01],[1,990,0]],"ltp":140.0,"tv":1719.2,"id":9712888}]}]}
{"op":"mcm","clk":"4233956506","pt":1631540443085,"mc":[{"id":"1.187557759","rc":[{"batl":[[0,1.01,541.59]],"ltp":1.01,"tv":41316.71,"id":9634485},{"batb":[[0,50,2],[1,46,2],[2,42,2]],"ltp":140.0,"tv":1719.2,"id":9712888}]}]}
{"op":"mcm","clk":"4233956770","pt":1631540446493,"mc":[{"id":"1.187557759","rc":[{"batl":[[1,1.02,1461.58]],"ltp":1.01,"tv":41316.71,"id":9634485},{"batb":[[0,50,4]],"ltp":140.0,"tv":1719.2,"id":9712888}]}]}
{"op":"mcm","clk":"4233956871","pt":1631540447805,"mc":[{"id":"1.187557759","rc":[{"batl":[[0,1.01,807.89]],"ltp":1.01,"tv":41316.71,"id":9634485}]}]}
{"op":"mcm","clk":"4233956903","pt":1631540448179,"mc":[{"id":"1.187557759","rc":[{"batl":[[0,1.01,788.39]],"ltp":1.01,"tv":41316.71,"id":9634485}]}]}
{"op":"mcm","clk":"4233957403","pt":1631540454701,"mc":[{"id":"1.187557759","rc":[{"batl":[[0,1.01,541.59]],"ltp":1.01,"tv":41316.71,"id":9634485}]}]}
{"op":"mcm","clk":"4233957640","pt":1631540457686,"mc":[{"id":"1.187557759","rc":[{"batl":[[1,1.02,1705.95]],"ltp":1.01,"tv":41316.71,"id":9634485}]}]}
{"op":"mcm","clk":"4233958165","pt":1631540464496,"mc":[{"id":"1.187557759","rc":[{"batl":[[1,1.02,105]],"ltp":1.01,"tv":41316.71,"id":9634485},{"batb":[[0,50,2],[1,38,1.06],[2,34,2]],"ltp":140.0,"tv":1719.2,"id":9712888}]}]}
{"op":"mcm","clk":"4233958430","pt":1631540467817,"mc":[{"id":"1.187557759","rc":[{"batl":[[0,1.01,817.89]],"ltp":1.01,"tv":41316.71,"id":9634485},{"batb":[[0,290,11.24],[1,100,2],[2,50,2]],"batl":[[0,990,6.62]],"ltp":140.0,"tv":1719.2,"id":9712888}]}]}
{"op":"mcm","clk":"4233959930","pt":1631540485325,"mc":[{"id":"1.187557759","rc":[{"batl":[[0,1.01,788.39]],"ltp":1.01,"tv":41316.71,"id":9634485},{"batb":[[0,50,2],[1,38,1.06],[2,34,2]],"batl":[[0,990,0.01]],"ltp":140.0,"tv":1719.2,"id":9712888}]}]}
{"op":"mcm","clk":"4233960393","pt":1631540491745,"mc":[{"id":"1.187557759","rc":[{"batl":[[0,1.01,808.89]],"ltp":1.01,"tv":41316.71,"id":9634485}]}]}
{"op":"mcm","clk":"4233960405","pt":1631540491957,"mc":[{"id":"1.187557759","rc":[{"batl":[[0,1.01,788.39]],"ltp":1.01,"tv":41316.71,"id":9634485}]}]}
{"op":"mcm","clk":"4233961333","pt":1631540504568,"mc":[{"id":"1.187557759","rc":[{"batl":[[0,1.01,936.71]],"ltp":1.01,"tv":41316.71,"id":9634485}]}]}
{"op":"mcm","clk":"4233961430","pt":1631540505757,"mc":[{"id":"1.187557759","marketDefinition":{"bspMarket":false,"turnInPlayEnabled":true,"persistenceEnabled":true,"marketBaseRate":5.0,"eventId":"30896122","eventTypeId":"2","numberOfWinners":1,"bettingType":"ODDS","marketType":"MATCH_ODDS","marketTime":"2021-09-13T12:06:00.000Z","suspendTime":"2021-09-13T12:06:00.000Z","bspReconciled":false,"complete":true,"inPlay":true,"crossMatching":true,"runnersVoidable":false,"numberOfActiveRunners":2,"betDelay":3,"status":"SUSPENDED","runners":[{"status":"ACTIVE","sortPriority":1,"id":9634485,"name":"Nicola Kuhn"},{"status":"ACTIVE","sortPriority":2,"id":9712888,"name":"Matteo Martineau"}],"regulators":["MR_INT"],"countryCode":"PL","discountAllowed":true,"timezone":"UTC","openDate":"2021-09-13T12:06:00.000Z","version":4030725288,"name":"Match Odds","eventName":"Kuhn v Martineau"}}]}
{"op":"mcm","clk":"4233961742","pt":1631540509783,"mc":[{"id":"1.187557759","rc":[{"batl":[[1,1.03,265.04],[2,1.04,330.1]],"ltp":1.01,"tv":41316.71,"id":9634485},{"batb":[[0,38,1.06],[1,1.02,6],[2,1.01,115.38]],"ltp":140.0,"tv":1719.2,"id":9712888}]}]}
{"op":"mcm","clk":"4233961954","pt":1631540512301,"mc":[{"id":"1.187557759","rc":[{"batl":[[1,1.03,255.33]],"ltp":1.01,"tv":41316.71,"id":9634485},{"batb":[[0,1.02,6],[1,1.01,115.38],[2,1.01,0]],"ltp":140.0,"tv":1719.2,"id":9712888}]}]}
{"op":"mcm","clk":"4233961999","pt":1631540512895,"mc":[{"id":"1.187557759","rc":[{"batl":[[0,1.03,0.25],[1,1.03,0],[2,1.04,0]],"ltp":1.01,"tv":41316.71,"id":9634485}]}]}
{"op":"mcm","clk":"4233965316","pt":1631540554431,"mc":[{"id":"1.187557759","tv":0.0}]}
{"op":"mcm","clk":"4233965501","pt":1631540556996,"mc":[{"id":"1.187557759","marketDefinition":{"bspMarket":false,"turnInPlayEnabled":true,"persistenceEnabled":true,"marketBaseRate":5.0,"eventId":"30896122","eventTypeId":"2","numberOfWinners":1,"bettingType":"ODDS","marketType":"MATCH_ODDS","marketTime":"2021-09-13T12:06:00.000Z","suspendTime":"2021-09-13T12:06:00.000Z","bspReconciled":false,"complete":true,"inPlay":true,"crossMatching":false,"runnersVoidable":false,"numberOfActiveRunners":0,"betDelay":3,"status":"CLOSED","settledTime":"2021-09-13T13:42:24.000Z","runners":[{"status":"WINNER","sortPriority":1,"id":9634485,"name":"Nicola Kuhn"},{"status":"LOSER","sortPriority":2,"id":9712888,"name":"Matteo Martineau"}],"regulators":["MR_INT"],"countryCode":"PL","discountAllowed":true,"timezone":"UTC","openDate":"2021-09-13T12:06:00.000Z","version":4030725814,"name":"Match Odds","eventName":"Kuhn v Martineau"}}]}
