{"op":"mcm","clk":"4230322413","pt":1631531697573,"mc":[{"id":"1.187557247","rc":[{"batl":[[0,1.83,2.32],[1,1.88,50],[2,2,148.3]],"ltp":1.83,"tv":17558.0,"id":10350473}]}]}
{"op":"mcm","clk":"4230322562","pt":1631531699743,"mc":[{"id":"1.187557247","rc":[{"batl":[[0,1.76,8.52],[1,1.83,2.32],[2,1.88,50]],"ltp":1.83,"tv":17558.0,"id":10350473}]}]}
{"op":"mcm","clk":"4230322607","pt":1631531700262,"mc":[{"id":"1.187557247","rc":[{"batl":[[1,1.83,10.84]],"ltp":1.83,"tv":17558.0,"id":10350473}]}]}
{"op":"mcm","clk":"4230322707","pt":1631531701261,"mc":[{"id":"1.187557247","rc":[{"batb":[[0,1.71,112.36],[1,1.7,4],[2,1.45,719.75]],"ltp":1.83,"tv":17558.0,"id":10350473}]}]}
{"op":"mcm","clk":"4230322801","pt":1631531702249,"mc":[{"id":"1.187557247","rc":[{"batl":[[1,1.83,8.52]],"ltp":1.83,"tv":17558.0,"id":10350473}]}]}
{"op":"mcm","clk":"4230323031","pt":1631531704756,"mc":[{"id":"1.187557247","rc":[{"trd":[[1.76,1706],[1.83,275.73],[1.88,100]],"batb":[[0,1.92,17.3],[1,1.91,1001.32],[2,1.9,971.86]],"batl":[[0,2,148.3],[1,2.02,142.57],[2,2.1,7.35]],"ltp":1.88,"tv":17692.08,"id":10350473},{"batb":[[2,1.97,533.95]],"batl":[[1,2.5,8],[2,2.82,234.47]],"ltp":1.9,"tv":4142.49,"id":9304761}],"tv":21834.57}]}
{"op":"mcm","clk":"4230323113","pt":1631531705690,"mc":[{"id":"1.187557247","rc":[{"trd":[[1.92,22.34]],"batb":[[0,1.92,79.43]],"ltp":1.92,"tv":17714.42,"id":10350473},{"batb":[[0,2.02,58.82],[1,2,119.66],[2,1.99,68.51]],"batl":[[0,2.2,54.77],[1,2.28,144.64],[2,2.42,4]],"ltp":1.9,"tv":4142.49,"id":9304761}],"tv":21856.91}]}
{"op":"mcm","clk":"4230323167","pt":1631531706369,"mc":[{"id":"1.187557247","rc":[{"batb":[[0,2.02,87.92]],"batl":[[1,2.42,4],[2,2.5,8]],"ltp":1.9,"tv":4142.49,"id":9304761}]}]}
{"op":"mcm","clk":"4230323278","pt":1631531707675,"mc":[{"id":"1.187557247","rc":[{"batb":[[0,1.92,259.97],[2,1.9,1129.7]],"batl":[[0,1.98,60],[1,1.99,4],[2,2,160.83]],"ltp":1.92,"tv":17714.42,"id":10350473},{"batb":[[0,2.02,91.92],[1,2,124.66],[2,1.97,533.95]],"ltp":1.9,"tv":4142.49,"id":9304761}]}]}
{"op":"mcm","clk":"4230323384","pt":1631531708667,"mc":[{"id":"1.187557247","rc":[{"batl":[[0,1.98,64]],"ltp":1.92,"tv":17714.42,"id":10350473},{"batb":[[0,2.04,5],[1,2.02,91.92],[2,2,124.66]],"ltp":1.9,"tv":4142.49,"id":9304761}]}]}
{"op":"mcm","clk":"4230323459","pt":1631531709600,"mc":[{"id":"1.187557247","rc":[{"batl":[[0,2.18,39.93],[1,2.2,54.77],[2,2.42,4]],"ltp":1.9,"tv":4142.49,"id":9304761}]}]}
{"op":"mcm","clk":"4230323553","pt":1631531710601,"mc":[{"id":"1.187557247","rc":[{"trd":[[1.92,30.14]],"batb":[[0,1.92,256.07]],"batl":[[0,1.97,5],[1,1.98,98.45],[2,1.99,4]],"ltp":1.92,"tv":17722.22,"id":10350473},{"batl":[[0,2.42,4],[1,2.5,8],[2,2.82,234.47]],"ltp":1.9,"tv":4142.49,"id":9304761}],"tv":21864.71}]}
{"op":"mcm","clk":"4230323722","pt":1631531712686,"mc":[{"id":"1.187557247","rc":[{"batl":[[0,2.2,253.79],[1,2.42,4],[2,2.5,8]],"ltp":1.9,"tv":4142.49,"id":9304761}]}]}
{"op":"mcm","clk":"4230323820","pt":1631531713685,"mc":[{"id":"1.187557247","rc":[{"trd":[[1.92,34.79]],"batb":[[0,1.92,253.75]],"ltp":1.92,"tv":17726.87,"id":10350473},{"batl":[[0,2.18,55.23],[1,2.2,253.79],[2,2.36,39.93]],"ltp":1.9,"tv":4142.49,"id":9304761}],"tv":21869.36}]}
{"op":"mcm","clk":"4230323860","pt":1631531714207,"mc":[{"id":"1.187557247","rc":[{"trd":[[1.92,51.83]],"batb":[[0,1.92,245.23]],"ltp":1.92,"tv":17743.91,"id":10350473},{"batl":[[2,2.42,4]],"ltp":1.9,"tv":4142.49,"id":9304761}],"tv":21886.4}]}
{"op":"mcm","clk":"4230323979","pt":1631531715714,"mc":[{"id":"1.187557247","rc":[{"trd":[[1.97,15.18],[1.98,196.9]],"batb":[[0,1.98,32.55],[1,1.92,245.23],[2,1.91,1001.32]],"batl":[[0,1.99,4],[1,2,160.83],[2,2.02,142.57]],"ltp":1.98,"tv":17955.99,"id":10350473},{"trd":[[2.04,122.4]],"batb":[[0,2.02,33.1],[1,2,124.66],[2,1.97,533.95]],"batl":[[0,2.2,253.79],[1,2.42,4],[2,2.5,8]],"ltp":2.04,"tv":4147.49,"id":9304761}],"tv":22103.48}]}
{"op":"mcm","clk":"4230324237","pt":1631531718679,"mc":[{"id":"1.187557247","rc":[{"trd":[[1.92,87.1],[1.98,262]],"batb":[[0,1.92,227.6],[1,1.91,1001.32],[2,1.9,1129.7]],"batl":[[0,1.98,32.55],[1,1.99,4],[2,2,160.83]],"ltp":1.92,"tv":18056.35,"id":10350473}],"tv":22203.85}]}
{"op":"mcm","clk":"4230324325","pt":1631531719669,"mc":[{"id":"1.187557247","rc":[{"batl":[[0,1.98,20]],"ltp":1.92,"tv":18056.35,"id":10350473},{"batb":[[2,1.99,60.3]],"batl":[[0,2.16,55.7],[1,2.2,253.79],[2,2.42,4]],"ltp":2.04,"tv":4147.49,"id":9304761}]}]}
{"op":"mcm","clk":"4230324407","pt":1631531720704,"mc":[{"id":"1.187557247","rc":[{"trd":[[1.98,318.32]],"batl":[[0,1.99,4],[1,2,160.83],[2,2.02,201.97]],"ltp":1.98,"tv":18112.67,"id":10350473},{"batb":[[1,2,119.66]],"ltp":2.04,"tv":4147.49,"id":9304761}],"tv":22260.17}]}
{"op":"mcm","clk":"4230324573","pt":1631531722683,"mc":[{"id":"1.187557247","rc":[{"trd":[[1.92,96.86]],"batb":[[0,1.92,222.72]],"ltp":1.92,"tv":18122.44,"id":10350473}],"tv":22269.93}]}
{"op":"mcm","clk":"4230324663","pt":1631531723575,"mc":[{"id":"1.187557247","rc":[{"batb":[[0,1.88,15.99],[1,1.78,93.81],[2,1.71,6]],"batl":[[0,1.98,131.73],[1,1.99,4],[2,2.02,59.4]],"ltp":1.92,"tv":18122.44,"id":10350473},{"batb":[[0,2.04,4],[1,2.02,4]],"batl":[[1,2.42,4],[2,2.82,234.47]],"ltp":2.04,"tv":4147.49,"id":9304761}]}]}
{"op":"mcm","clk":"4230324734","pt":1631531724507,"mc":[{"id":"1.187557247","rc":[{"batb":[[0,1.78,93.81],[1,1.71,6],[2,1.45,719.75]],"batl":[[0,1.98,147.73],[1,2.12,7.71],[2,2.16,4.24]],"ltp":1.92,"tv":18122.44,"id":10350473},{"batb":[[0,1.9,63.66],[1,1.87,74.48],[2,1.84,73.72]],"batl":[[0,2.42,4],[1,2.82,234.47],[2,3.45,53.16]],"ltp":2.04,"tv":4147.49,"id":9304761}]}]}
{"op":"mcm","clk":"4230324820","pt":1631531725710,"mc":[{"id":"1.187557247","rc":[{"batl":[[0,1.98,9.58]],"ltp":1.92,"tv":18122.44,"id":10350473}]}]}
{"op":"mcm","clk":"4230324898","pt":1631531726697,"mc":[{"id":"1.187557247","rc":[{"batb":[[0,1.77,94.31]],"batl":[[0,1.92,9.88]],"ltp":1.92,"tv":18122.44,"id":10350473},{"batb":[[1,1.88,74.06]],"ltp":2.04,"tv":4147.49,"id":9304761}]}]}
{"op":"mcm","clk":"4230324977","pt":1631531727689,"mc":[{"id":"1.187557247","rc":[{"batb":[[0,1.78,5],[1,1.77,99.31],[2,1.71,6]],"ltp":1.92,"tv":18122.44,"id":10350473},{"batl":[[0,2.3,3],[1,2.42,4],[2,2.82,234.47]],"ltp":2.04,"tv":4147.49,"id":9304761}]}]}
{"op":"mcm","clk":"4230325030","pt":1631531728314,"mc":[{"id":"1.187557247","rc":[{"batl":[[0,1.92,7.56]],"ltp":1.92,"tv":18122.44,"id":10350473}]}]}
{"op":"mcm","clk":"4230325132","pt":1631531729507,"mc":[{"id":"1.187557247","rc":[{"batb":[[2,1.76,2]],"ltp":1.92,"tv":18122.44,"id":10350473}]}]}
{"op":"mcm","clk":"4230325232","pt":1631531730709,"mc":[{"id":"1.187557247","rc":[{"batb":[[0,1.89,178.02],[1,1.87,165.89],[2,1.78,83.94]],"batl":[[0,1.96,115.82],[1,1.98,141.48],[2,2.12,7.71]],"ltp":1.92,"tv":18122.44,"id":10350473},{"batb":[[0,1.91,106.3],[1,1.9,63.66],[2,1.88,74.06]],"ltp":2.04,"tv":4147.49,"id":9304761}]}]}
{"op":"mcm","clk":"4230325464","pt":1631531733699,"mc":[{"id":"1.187557247","rc":[{"batb":[[2,1.78,5]],"ltp":1.92,"tv":18122.44,"id":10350473},{"batb":[[0,1.9,63.66],[1,1.88,74.06],[2,1.84,73.72]],"ltp":2.04,"tv":4147.49,"id":9304761}]}]}
{"op":"mcm","clk":"4230325504","pt":1631531734231,"mc":[{"id":"1.187557247","rc":[{"batb":[[0,1.78,5],[1,1.77,99.31],[2,1.76,2]],"batl":[[0,2.16,4.24],[1,2.2,6.58],[2,2.12,0]],"ltp":1.92,"tv":18122.44,"id":10350473},{"batb":[[0,1.88,74.06],[1,1.84,73.72],[2,1.78,2.32]],"ltp":2.04,"tv":4147.49,"id":9304761}]}]}
{"op":"mcm","clk":"4230325735","pt":1631531737606,"mc":[{"id":"1.187557247","rc":[{"batb":[[0,1.78,194.13],[2,1.76,203.73]],"batl":[[0,2.12,4],[1,2.14,4],[2,2.16,204.49]],"ltp":1.92,"tv":18122.44,"id":10350473},{"batb":[[0,1.89,4],[1,1.88,79.06],[2,1.87,4]],"ltp":2.04,"tv":4147.49,"id":9304761}]}]}
{"op":"mcm","clk":"4230325868","pt":1631531739633,"mc":[{"id":"1.187557247","rc":[{"batb":[[0,1.83,50],[1,1.78,194.13],[2,1.77,99.31]],"batl":[[0,1.89,6.51],[1,2.12,4],[2,2.14,4]],"ltp":1.92,"tv":18122.44,"id":10350473}]}]}
{"op":"mcm","clk":"4230325883","pt":1631531739862,"mc":[{"id":"1.187557247","rc":[{"batb":[[2,1.77,94.31]],"ltp":1.92,"tv":18122.44,"id":10350473},{"batl":[[1,2.82,234.47],[2,3.45,53.16]],"ltp":2.04,"tv":4147.49,"id":9304761}]}]}
{"op":"mcm","clk":"4230326767","pt":1631531751759,"mc":[{"id":"1.187557247","rc":[{"batl":[[2,2.16,4.24]],"ltp":1.92,"tv":18122.44,"id":10350473},{"batb":[[1,1.88,74.06],[2,1.84,73.72]],"ltp":2.04,"tv":4147.49,"id":9304761}]}]}
{"op":"mcm","clk":"4230326942","pt":1631531753641,"mc":[{"id":"1.187557247","rc":[{"trd":[[1.89,26.86]],"batb":[[1,1.78,189.13]],"batl":[[0,1.89,4.51]],"ltp":1.89,"tv":18126.44,"id":10350473},{"batl":[[0,2.82,234.47],[1,3.45,53.16],[2,3.45,0]],"ltp":2.04,"tv":4147.49,"id":9304761}],"tv":22273.93}]}
{"op":"mcm","clk":"4230327026","pt":1631531754735,"mc":[{"id":"1.187557247","rc":[{"trd":[[1.83,375.73]],"batb":[[0,1.78,189.13],[1,1.77,94.31],[2,1.76,201.73]],"batl":[[0,1.83,48.33],[1,1.85,196.27],[2,1.86,1028.22]],"ltp":1.83,"tv":18226.44,"id":10350473},{"batb":[[0,2.2,23.77],[1,1.94,626.63],[2,1.89,4]],"batl":[[0,2.34,449.53],[1,2.36,436.3],[2,2.38,436.3]],"ltp":2.04,"tv":4147.49,"id":9304761}],"tv":22373.93}]}
{"op":"mcm","clk":"4230327113","pt":1631531755619,"mc":[{"id":"1.187557247","rc":[{"batl":[[0,1.83,60.26]],"ltp":1.83,"tv":18226.44,"id":10350473},{"batb":[[0,2.2,115.4],[1,2.06,110.46]],"ltp":2.04,"tv":4147.49,"id":9304761}]}]}
{"op":"mcm","clk":"4230327208","pt":1631531756759,"mc":[{"id":"1.187557247","rc":[{"batl":[[0,1.83,64.26]],"ltp":1.83,"tv":18226.44,"id":10350473},{"batb":[[0,2.22,3],[1,2.2,119.4],[2,2.1,54.54]],"batl":[[0,2.3,52.62],[1,2.34,449.53],[2,2.36,436.3]],"ltp":2.04,"tv":4147.49,"id":9304761}]}]}
{"op":"mcm","clk":"4230327276","pt":1631531757748,"mc":[{"id":"1.187557247","rc":[{"trd":[[1.82,3.66],[1.83,380.93]],"batl":[[0,1.82,4],[1,1.83,61.66],[2,1.85,196.27]],"ltp":1.83,"tv":18235.3,"id":10350473},{"trd":[[2.22,3]],"batb":[[0,2.2,119.4],[1,2.1,54.54],[2,2.06,110.46]],"ltp":2.22,"tv":4150.49,"id":9304761}],"tv":22385.79}]}
{"op":"mcm","clk":"4230327421","pt":1631531759667,"mc":[{"id":"1.187557247","rc":[{"batl":[[1,1.83,94.21]],"ltp":1.83,"tv":18235.3,"id":10350473},{"batl":[[1,2.34,537.77]],"ltp":2.22,"tv":4150.49,"id":9304761}]}]}
{"op":"mcm","clk":"4230327501","pt":1631531760758,"mc":[{"id":"1.187557247","rc":[{"batb":[[2,1.76,270.55]],"ltp":1.83,"tv":18235.3,"id":10350473},{"batb":[[0,2.2,144.9],[1,2.06,110.46],[2,1.89,4]],"ltp":2.22,"tv":4150.49,"id":9304761}]}]}
{"op":"mcm","clk":"4230327573","pt":1631531761444,"mc":[{"id":"1.187557247","rc":[{"batl":[[1,1.83,82.28]],"ltp":1.83,"tv":18235.3,"id":10350473},{"batb":[[1,2.08,8.81],[2,2.06,110.46]],"ltp":2.22,"tv":4150.49,"id":9304761}]}]}
{"op":"mcm","clk":"4230327757","pt":1631531763677,"mc":[{"id":"1.187557247","rc":[{"trd":[[1.82,8.3]],"batl":[[0,1.82,1.68]],"ltp":1.82,"tv":18239.94,"id":10350473},{"batb":[[1,2.14,52.63],[2,2.08,8.81]],"ltp":2.22,"tv":4150.49,"id":9304761}],"tv":22390.43}]}
{"op":"mcm","clk":"4230327812","pt":1631531764350,"mc":[{"id":"1.187557247","rc":[{"trd":[[1.78,319.45]],"batb":[[0,1.78,137.42]],"ltp":1.78,"tv":18343.35,"id":10350473}],"tv":22493.84}]}
{"op":"mcm","clk":"4230327909","pt":1631531765660,"mc":[{"id":"1.187557247","rc":[{"trd":[[1.78,404.63]],"batb":[[0,1.78,94.83]],"batl":[[2,1.86,1028.22]],"ltp":1.78,"tv":18428.53,"id":10350473}],"tv":22579.02}]}
{"op":"mcm","clk":"4230328155","pt":1631531768764,"mc":[{"id":"1.187557247","rc":[{"trd":[[1.78,678.67],[1.82,11.66],[1.83,383.57]],"batb":[[0,1.77,94.31],[1,1.76,68.82],[2,1.69,37.21]],"batl":[[0,1.78,35.04],[1,1.83,76.96]],"ltp":1.78,"tv":18708.57,"id":10350473}],"tv":22859.06}]}
{"op":"mcm","clk":"4230328364","pt":1631531771567,"mc":[{"id":"1.187557247","rc":[{"trd":[[1.78,726.76]],"batb":[[0,1.77,171.79],[2,1.75,205.95]],"batl":[[0,1.78,11],[1,1.83,136.57],[2,1.85,174.2]],"ltp":1.78,"tv":18756.66,"id":10350473},{"batb":[[0,2.14,52.63],[1,2.06,110.46],[2,2.04,8.87]],"batl":[[1,2.58,5.44],[2,2.82,234.47]],"ltp":2.22,"tv":4150.49,"id":9304761}],"tv":22907.15}]}
{"op":"mcm","clk":"4230328449","pt":1631531772471,"mc":[{"id":"1.187557247","rc":[{"batb":[[0,1.66,151.85],[1,1.64,44.07],[2,1.6,41.54]],"batl":[[1,1.89,4.51],[2,1.91,56.5]],"ltp":1.78,"tv":18756.66,"id":10350473},{"batb":[[0,2.06,110.46],[1,2.04,8.87],[2,2.02,8.24]],"batl":[[0,2.52,6.01],[2,2.68,4.64]],"ltp":2.22,"tv":4150.49,"id":9304761}]}]}
{"op":"mcm","clk":"4230328488","pt":1631531772874,"mc":[{"id":"1.187557247","rc":[{"batb":[[0,1.66,117.07]],"ltp":1.78,"tv":18756.66,"id":10350473},{"batl":[[0,2.58,5.44],[1,2.68,4.64],[2,2.82,234.47]],"ltp":2.22,"tv":4150.49,"id":9304761}]}]}
{"op":"mcm","clk":"4230328703","pt":1631531775679,"mc":[{"id":"1.187557247","rc":[{"batb":[[0,1.66,122.07],[1,1.65,5],[2,1.64,44.07]],"batl":[[0,1.77,1.7],[1,1.78,11],[2,1.89,4.51]],"ltp":1.78,"tv":18756.66,"id":10350473},{"batl":[[0,2.52,3],[1,2.58,5.44],[2,2.68,4.64]],"ltp":2.22,"tv":4150.49,"id":9304761}]}]}
{"op":"mcm","clk":"4230328877","pt":1631531777762,"mc":[{"id":"1.187557247","rc":[{"batb":[[0,1.75,162.34],[1,1.73,214.04],[2,1.69,5]],"batl":[[2,1.81,163.34]],"ltp":1.78,"tv":18756.66,"id":10350473},{"batl":[[0,2.46,3],[1,2.5,3],[2,2.52,3]],"ltp":2.22,"tv":4150.49,"id":9304761}]}]}
{"op":"mcm","clk":"4230328907","pt":1631531778172,"mc":[{"id":"1.187557247","rc":[{"trd":[[1.77,0.58]],"batb":[[2,1.69,39.21]],"batl":[[0,1.77,1.12]],"ltp":1.77,"tv":18757.24,"id":10350473},{"trd":[[2.28,0.45]],"batl":[[0,2.46,9.25]],"ltp":2.28,"tv":4150.94,"id":9304761}],"tv":22908.18}]}
{"op":"mcm","clk":"4230328987","pt":1631531779256,"mc":[{"id":"1.187557247","rc":[{"batb":[[0,2.08,95.42],[1,2.06,110.46],[2,2.04,8.87]],"ltp":2.28,"tv":4150.94,"id":9304761}]}]}
{"op":"mcm","clk":"4230329102","pt":1631531780570,"mc":[{"id":"1.187557247","rc":[{"batl":[[0,1.78,11],[1,1.81,163.34],[2,1.83,180.19]],"ltp":1.77,"tv":18757.24,"id":10350473},{"batb":[[0,2.06,110.46],[1,2.04,8.87],[2,2.02,8.24]],"ltp":2.28,"tv":4150.94,"id":9304761}]}]}
{"op":"mcm","clk":"4230329174","pt":1631531781395,"mc":[{"id":"1.187557247","rc":[{"batb":[[0,1.69,5],[1,1.68,5],[2,1.67,6]],"batl":[[1,1.89,4.51],[2,1.91,56.5]],"ltp":1.77,"tv":18757.24,"id":10350473},{"batb":[[0,2.08,8.06],[1,2.06,110.46],[2,2.04,8.87]],"batl":[[0,2.46,3]],"ltp":2.28,"tv":4150.94,"id":9304761}]}]}
{"op":"mcm","clk":"4230329266","pt":1631531782694,"mc":[{"id":"1.187557247","rc":[{"batb":[[0,2.06,110.46],[1,2.04,8.87],[2,2.02,8.24]],"batl":[[0,2.44,37.97],[1,2.46,3],[2,2.5,3]],"ltp":2.28,"tv":4150.94,"id":9304761}]}]}
{"op":"mcm","clk":"4230329334","pt":1631531783685,"mc":[{"id":"1.187557247","rc":[{"batb":[[2,1.67,204.22]],"ltp":1.77,"tv":18757.24,"id":10350473},{"batl":[[0,2.46,3],[1,2.5,3],[2,2.52,3]],"ltp":2.28,"tv":4150.94,"id":9304761}]}]}
{"op":"mcm","clk":"4230329504","pt":1631531786002,"mc":[{"id":"1.187557247","rc":[{"batb":[[0,2.08,8.81],[1,2.06,110.46],[2,2.04,8.87]],"ltp":2.28,"tv":4150.94,"id":9304761}]}]}
{"op":"mcm","clk":"4230329591","pt":1631531787264,"mc":[{"id":"1.187557247","rc":[{"batl":[[0,1.89,4.51],[1,1.93,129.05],[2,1.95,148.38]],"ltp":1.77,"tv":18757.24,"id":10350473},{"batb":[[0,2.06,110.46],[1,2.04,8.87],[2,2.02,8.24]],"ltp":2.28,"tv":4150.94,"id":9304761}]}]}
{"op":"mcm","clk":"4230329819","pt":1631531790485,"mc":[{"id":"1.187557247","rc":[{"batb":[[1,1.67,198.22],[2,1.66,241.31]],"batl":[[0,1.75,4.41],[1,1.89,4.51],[2,1.91,51.5]],"ltp":1.77,"tv":18757.24,"id":10350473},{"batb":[[0,2.08,8.31],[1,2.06,110.46],[2,2.04,8.87]],"batl":[[1,2.58,5.44],[2,2.68,4.64]],"ltp":2.28,"tv":4150.94,"id":9304761}]}]}
{"op":"mcm","clk":"4230329897","pt":1631531791680,"mc":[{"id":"1.187557247","rc":[{"batl":[[2,1.96,45.87]],"ltp":1.77,"tv":18757.24,"id":10350473},{"batb":[[0,2.06,110.46],[1,2.04,8.87],[2,2.02,8.24]],"ltp":2.28,"tv":4150.94,"id":9304761}]}]}
{"op":"mcm","clk":"4230330061","pt":1631531793721,"mc":[{"id":"1.187557247","rc":[{"batb":[[0,1.67,198.22],[1,1.66,241.31],[2,1.64,44.07]],"ltp":1.77,"tv":18757.24,"id":10350473},{"batl":[[0,2.58,5.44],[1,2.68,4.64],[2,2.82,234.47]],"ltp":2.28,"tv":4150.94,"id":9304761}]}]}
{"op":"mcm","clk":"4230330165","pt":1631531794717,"mc":[{"id":"1.187557247","rc":[{"trd":[[1.67,24.7],[1.75,140.24]],"batb":[[0,1.67,185.87]],"batl":[[0,1.72,66.66],[1,1.73,212.22],[2,1.75,1302.76]],"ltp":1.67,"tv":18786.58,"id":10350473},{"batb":[[0,2.38,16.46],[1,2.08,930.16],[2,2.06,110.46]],"batl":[[0,2.56,410.88],[1,2.58,404.24],[2,2.6,398.8]],"ltp":2.28,"tv":4150.94,"id":9304761}],"tv":22937.53}]}
{"op":"mcm","clk":"4230330255","pt":1631531795608,"mc":[{"id":"1.187557247","rc":[{"batb":[[0,2.4,72.13],[1,2.38,16.46],[2,2.18,93.14]],"ltp":2.28,"tv":4150.94,"id":9304761}]}]}
{"op":"mcm","clk":"4230330336","pt":1631531796696,"mc":[{"id":"1.187557247","rc":[{"batl":[[2,1.74,5]],"ltp":1.67,"tv":18786.58,"id":10350473},{"batb":[[2,2.34,3]],"ltp":2.28,"tv":4150.94,"id":9304761}]}]}
{"op":"mcm","clk":"4230330414","pt":1631531797680,"mc":[{"id":"1.187557247","rc":[{"batl":[[0,1.71,5],[1,1.72,66.66],[2,1.73,212.22]],"ltp":1.67,"tv":18786.58,"id":10350473},{"batb":[[0,2.4,75.13],[1,2.38,20.46]],"ltp":2.28,"tv":4150.94,"id":9304761}]}]}
{"op":"mcm","clk":"4230330561","pt":1631531799596,"mc":[{"id":"1.187557247","rc":[{"batl":[[1,1.72,97.16]],"ltp":1.67,"tv":18786.58,"id":10350473}]}]}
{"op":"mcm","clk":"4230330661","pt":1631531800695,"mc":[{"id":"1.187557247","rc":[{"batb":[[0,1.67,259.17]],"ltp":1.67,"tv":18786.58,"id":10350473},{"batl":[[0,2.54,25.27],[1,2.56,410.88],[2,2.58,404.24]],"ltp":2.28,"tv":4150.94,"id":9304761}]}]}
{"op":"mcm","clk":"4230330842","pt":1631531802721,"mc":[{"id":"1.187557247","rc":[{"trd":[[1.71,4.64]],"batl":[[0,1.71,2.68]],"ltp":1.71,"tv":18791.23,"id":10350473}],"tv":22942.17}]}
{"op":"mcm","clk":"4230330915","pt":1631531803605,"mc":[{"id":"1.187557247","rc":[{"batb":[[0,1.67,375.24]],"ltp":1.71,"tv":18791.23,"id":10350473},{"batb":[[1,2.38,93.35]],"batl":[[0,2.48,49.31],[1,2.54,25.27],[2,2.56,410.88]],"ltp":2.28,"tv":4150.94,"id":9304761}]}]}
{"op":"mcm","clk":"4230330938","pt":1631531803921,"mc":[{"id":"1.187557247","rc":[{"batb":[[1,1.66,124.24]],"ltp":1.71,"tv":18791.23,"id":10350473},{"batb":[[0,2.4,3]],"ltp":2.28,"tv":4150.94,"id":9304761}]}]}
{"op":"mcm","clk":"4230331397","pt":1631531809744,"mc":[{"id":"1.187557247","rc":[{"trd":[[1.67,785.8]],"batb":[[0,1.66,124.24],[1,1.64,44.07],[2,1.6,41.54]],"ltp":1.67,"tv":19552.32,"id":10350473},{"trd":[[2.48,7.19]],"batb":[[1,2.38,89.35],[2,2.18,93.14]],"batl":[[0,2.54,25.27],[1,2.56,410.88],[2,2.58,404.24]],"ltp":2.48,"tv":4158.1,"id":9304761}],"tv":23710.43}]}
{"op":"mcm","clk":"4230331417","pt":1631531810005,"mc":[{"id":"1.187557247","rc":[{"batb":[[0,1.69,8.37],[1,1.66,124.24],[2,1.64,44.07]],"batl":[[0,1.71,52.68],[2,1.75,1092.86]],"ltp":1.67,"tv":19552.32,"id":10350473}]}]}
{"op":"mcm","clk":"4230331614","pt":1631531812703,"mc":[{"id":"1.187557247","rc":[{"trd":[[1.71,22.76]],"batb":[[2,1.65,74.42]],"batl":[[0,1.71,43.62]],"ltp":1.71,"tv":19570.44,"id":10350473}],"tv":23728.54}]}
{"op":"mcm","clk":"4230331676","pt":1631531813535,"mc":[{"id":"1.187557247","rc":[{"trd":[[1.71,46.38]],"batb":[[1,1.66,331.62],[2,1.65,201.75]],"batl":[[0,1.71,31.81],[1,1.72,309.26],[2,1.74,212.38]],"ltp":1.71,"tv":19594.06,"id":10350473},{"batb":[[0,2.4,74.13],[1,2.38,16.46],[2,2.34,44.77]],"batl":[[0,2.54,73.61]],"ltp":2.48,"tv":4158.1,"id":9304761}],"tv":23752.16}]}
{"op":"mcm","clk":"4230331767","pt":1631531814724,"mc":[{"id":"1.187557247","rc":[{"trd":[[1.66,221.6],[1.69,164.68]],"batb":[[0,1.66,317.99],[1,1.65,201.75],[2,1.64,44.07]],"ltp":1.66,"tv":19638.06,"id":10350473}],"tv":23796.16}]}
{"op":"mcm","clk":"4230331817","pt":1631531815502,"mc":[{"id":"1.187557247","rc":[{"batl":[[0,1.67,2.09],[1,1.71,31.81],[2,1.72,309.26]],"ltp":1.66,"tv":19638.06,"id":10350473}]}]}
{"op":"mcm","clk":"4230332046","pt":1631531818709,"mc":[{"id":"1.187557247","rc":[{"batb":[[0,1.66,316.98]],"ltp":1.66,"tv":19638.06,"id":10350473}]}]}
{"op":"mcm","clk":"4230332178","pt":1631531820323,"mc":[{"id":"1.187557247","rc":[{"batl":[[0,1.71,31.81],[1,1.72,309.26],[2,1.74,212.38]],"ltp":1.66,"tv":19638.06,"id":10350473}]}]}
{"op":"mcm","clk":"4230332404","pt":1631531823161,"mc":[{"id":"1.187557247","rc":[{"trd":[[1.66,225.78],[1.71,110]],"batb":[[0,1.71,3497.6],[1,1.66,314.89],[2,1.65,201.75]],"batl":[[0,1.72,309.26],[1,1.74,212.38],[2,1.75,1152.86]],"ltp":1.71,"tv":19705.86,"id":10350473},{"batl":[[0,2.54,48.34]],"ltp":2.48,"tv":4158.1,"id":9304761}],"tv":23863.96}]}
{"op":"mcm","clk":"4230332487","pt":1631531824246,"mc":[{"id":"1.187557247","rc":[{"batb":[[1,1.7,8.37],[2,1.66,314.89]],"ltp":1.71,"tv":19705.86,"id":10350473}]}]}
{"op":"mcm","clk":"4230332654","pt":1631531826437,"mc":[{"id":"1.187557247","rc":[{"trd":[[1.71,126.25]],"batb":[[0,1.71,3487.35]],"ltp":1.71,"tv":19722.11,"id":10350473},{"trd":[[2.42,4.4]],"batb":[[0,2.4,95.56]],"ltp":2.42,"tv":4161.1,"id":9304761}],"tv":23883.21}]}
{"op":"mcm","clk":"4230332886","pt":1631531829642,"mc":[{"id":"1.187557247","rc":[{"batb":[[0,1.71,3801.35],[2,1.66,313.97]],"ltp":1.71,"tv":19722.11,"id":10350473}]}]}
{"op":"mcm","clk":"4230332951","pt":1631531830637,"mc":[{"id":"1.187557247","rc":[{"trd":[[1.72,44.48]],"batl":[[0,1.72,309.18]],"ltp":1.72,"tv":19722.27,"id":10350473}],"tv":23883.37}]}
{"op":"mcm","clk":"4230333295","pt":1631531836232,"mc":[{"id":"1.187557247","rc":[{"trd":[[1.72,44.64]],"batl":[[0,1.72,309.1]],"ltp":1.72,"tv":19722.43,"id":10350473}],"tv":23883.53}]}
{"op":"mcm","clk":"4230333361","pt":1631531837172,"mc":[{"id":"1.187557247","rc":[{"trd":[[1.71,170.25]],"batb":[[0,1.71,3779.35]],"ltp":1.71,"tv":19766.43,"id":10350473}],"tv":23927.53}]}
{"op":"mcm","clk":"4230333590","pt":1631531840336,"mc":[{"id":"1.187557247","rc":[{"trd":[[1.71,175.91]],"batb":[[0,1.71,3773.69]],"ltp":1.71,"tv":19772.09,"id":10350473},{"trd":[[2.42,8.4]],"ltp":2.42,"tv":4165.1,"id":9304761}],"tv":23937.19}]}
{"op":"mcm","clk":"4230333818","pt":1631531843446,"mc":[{"id":"1.187557247","rc":[{"trd":[[1.71,185.91]],"batb":[[0,1.71,3768.69]],"ltp":1.71,"tv":19782.09,"id":10350473}],"tv":23947.19}]}
{"op":"mcm","clk":"4230334284","pt":1631531850382,"mc":[{"id":"1.187557247","rc":[{"trd":[[1.72,61.38]],"batl":[[0,1.72,300.73]],"ltp":1.72,"tv":19798.82,"id":10350473}],"tv":23963.93}]}
{"op":"mcm","clk":"4230334414","pt":1631531852173,"mc":[{"id":"1.187557247","rc":[{"trd":[[1.71,189.91]],"batb":[[0,1.71,3766.69]],"ltp":1.71,"tv":19802.82,"id":10350473}],"tv":23967.93}]}
{"op":"mcm","clk":"4230334642","pt":1631531855482,"mc":[{"id":"1.187557247","rc":[{"trd":[[1.71,194.16]],"batb":[[0,1.71,3762.44]],"ltp":1.71,"tv":19807.07,"id":10350473},{"trd":[[2.42,11.4]],"ltp":2.42,"tv":4168.1,"id":9304761}],"tv":23975.18}]}
{"op":"mcm","clk":"4230334889","pt":1631531858692,"mc":[{"id":"1.187557247","rc":[{"trd":[[1.71,206.16]],"batb":[[0,1.71,3756.44]],"ltp":1.71,"tv":19819.07,"id":10350473}],"tv":23987.18}]}
{"op":"mcm","clk":"4230343152","pt":1631531866586,"mc":[{"id":"1.187557247","rc":[{"batb":[[0,1.71,314]],"ltp":1.71,"tv":19819.07,"id":10350473}]}]}
{"op":"mcm","clk":"4230343595","pt":1631531872020,"mc":[{"id":"1.187557247","rc":[{"trd":[[1.71,211.82]],"batb":[[0,1.71,308.34]],"ltp":1.71,"tv":19824.73,"id":10350473},{"trd":[[2.42,15.4]],"ltp":2.42,"tv":4172.1,"id":9304761}],"tv":23996.84}]}
{"op":"mcm","clk":"4230343691","pt":1631531873105,"mc":[{"id":"1.187557247","rc":[{"trd":[[1.71,223.82]],"batb":[[0,1.71,302.34]],"ltp":1.71,"tv":19836.73,"id":10350473}],"tv":24008.84}]}
{"op":"mcm","clk":"4230344751","pt":1631531886932,"mc":[{"id":"1.187557247","rc":[{"trd":[[1.71,229.48]],"batb":[[0,1.71,296.68]],"ltp":1.71,"tv":19842.39,"id":10350473},{"trd":[[2.42,19.4]],"ltp":2.42,"tv":4176.1,"id":9304761}],"tv":24018.5}]}
{"op":"mcm","clk":"4230344847","pt":1631531888229,"mc":[{"id":"1.187557247","rc":[{"trd":[[1.71,239.48],[1.72,80.9]],"batb":[[0,1.71,291.68]],"batl":[[0,1.72,290.97]],"ltp":1.72,"tv":19871.92,"id":10350473}],"tv":24048.02}]}
{"op":"mcm","clk":"4230345103","pt":1631531891639,"mc":[{"id":"1.187557247","rc":[{"batl":[[0,1.72,260.47]],"ltp":1.72,"tv":19871.92,"id":10350473},{"batb":[[0,2.4,74.13]],"ltp":2.42,"tv":4176.1,"id":9304761}]}]}
{"op":"mcm","clk":"4230345130","pt":1631531891904,"mc":[{"id":"1.187557247","rc":[{"trd":[[1.72,99.64]],"batl":[[0,1.72,251.1]],"ltp":1.72,"tv":19890.66,"id":10350473}],"tv":24066.76}]}
{"op":"mcm","clk":"4230345805","pt":1631531899531,"mc":[{"id":"1.187557247","rc":[{"batl":[[0,1.72,285.72]],"ltp":1.72,"tv":19890.66,"id":10350473},{"batb":[[0,2.4,95.56]],"ltp":2.42,"tv":4176.1,"id":9304761}]}]}
{"op":"mcm","clk":"4230345910","pt":1631531900722,"mc":[{"id":"1.187557247","rc":[{"trd":[[1.71,346.48]],"batb":[[0,1.71,238.18],[2,1.66,363.97]],"ltp":1.71,"tv":19997.66,"id":10350473}],"tv":24173.76}]}
{"op":"mcm","clk":"4230346116","pt":1631531902760,"mc":[{"id":"1.187557247","rc":[{"trd":[[1.71,360.14]],"batb":[[0,1.71,228.52]],"ltp":1.71,"tv":20011.32,"id":10350473},{"trd":[[2.42,23.4]],"ltp":2.42,"tv":4180.1,"id":9304761}],"tv":24191.42}]}
{"op":"mcm","clk":"4230346449","pt":1631531906752,"mc":[{"id":"1.187557247","rc":[{"batb":[[2,1.66,50]],"batl":[[0,1.75,60],[1,1.82,48.75],[2,1.87,48.5]],"ltp":1.71,"tv":20011.32,"id":10350473},{"batb":[[0,2.34,44.77],[1,2.18,93.39],[2,2.14,7.82]],"batl":[[1,2.6,5.46],[2,2.7,4.75]],"ltp":2.42,"tv":4180.1,"id":9304761}]}]}
{"op":"mcm","clk":"4230346534","pt":1631531907639,"mc":[{"id":"1.187557247","rc":[{"batb":[[0,1.7,8.37],[1,1.66,50],[2,1.59,183.76]],"batl":[[0,1.87,48.5],[1,1.89,4.51],[2,1.9,2]],"ltp":1.71,"tv":20011.32,"id":10350473},{"batb":[[0,2.18,93.39],[1,2.14,7.82],[2,1.82,406.77]],"batl":[[0,2.7,4.75],[1,3.15,203.19],[2,3.45,53.16]],"ltp":2.42,"tv":4180.1,"id":9304761}]}]}
{"op":"mcm","clk":"4230346688","pt":1631531909558,"mc":[{"id":"1.187557247","rc":[{"batl":[[0,1.71,10],[1,1.84,190.52],[2,1.86,172.37]],"ltp":1.71,"tv":20011.32,"id":10350473},{"batb":[[0,2.2,6.87],[1,2.18,93.39],[2,2.14,7.82]],"ltp":2.42,"tv":4180.1,"id":9304761}]}]}
{"op":"mcm","clk":"4230346786","pt":1631531910754,"mc":[{"id":"1.187557247","rc":[{"batl":[[1,1.82,4],[2,1.84,190.52]],"ltp":1.71,"tv":20011.32,"id":10350473},{"batb":[[0,2.2,3],[1,2.18,97.39]],"ltp":2.42,"tv":4180.1,"id":9304761}]}]}
{"op":"mcm","clk":"4230346866","pt":1631531911538,"mc":[{"id":"1.187557247","rc":[{"batl":[[2,1.85,4]],"ltp":1.71,"tv":20011.32,"id":10350473},{"batb":[[2,2.16,4]],"ltp":2.42,"tv":4180.1,"id":9304761}]}]}
{"op":"mcm","clk":"4230347152","pt":1631531914759,"mc":[{"id":"1.187557247","rc":[{"trd":[[1.59,9.88],[1.62,7.8],[1.63,108.7],[1.66,325.78],[1.7,108.51]],"batb":[[0,1.59,178.82],[1,1.58,262.04],[2,1.57,152.47]],"batl":[[0,1.63,148.78],[1,1.64,128.91],[2,1.65,1159.1]],"ltp":1.59,"tv":20226.19,"id":10350473},{"trd":[[2.6,22.56]],"batb":[[0,2.5,26.44],[1,2.22,1542.23],[2,2.2,3]],"ltp":2.6,"tv":4184.96,"id":9304761}],"tv":24411.15}]}
{"op":"mcm","clk":"4230347241","pt":1631531915755,"mc":[{"id":"1.187557247","rc":[{"batb":[[0,2.56,59.83],[1,2.5,66.44],[2,2.34,76.23]],"batl":[[1,2.78,44.97],[2,3.15,209.54]],"ltp":2.6,"tv":4184.96,"id":9304761}]}]}
{"op":"mcm","clk":"4230347313","pt":1631531916638,"mc":[{"id":"1.187557247","rc":[{"batb":[[2,2.44,4]],"ltp":2.6,"tv":4184.96,"id":9304761}]}]}
{"op":"mcm","clk":"4230347387","pt":1631531917569,"mc":[{"id":"1.187557247","rc":[{"batl":[[1,1.64,134.91]],"ltp":1.59,"tv":20226.19,"id":10350473},{"batb":[[0,2.6,3],[1,2.58,3],[2,2.56,59.83]],"ltp":2.6,"tv":4184.96,"id":9304761}]}]}
{"op":"mcm","clk":"4230347582","pt":1631531919650,"mc":[{"id":"1.187557247","rc":[{"batl":[[0,1.63,198.78]],"ltp":1.59,"tv":20226.19,"id":10350473},{"batb":[[1,2.58,25.71]],"ltp":2.6,"tv":4184.96,"id":9304761}]}]}
{"op":"mcm","clk":"4230347723","pt":1631531921259,"mc":[{"id":"1.187557247","rc":[{"batl":[[2,2.8,4.67]],"ltp":2.6,"tv":4184.96,"id":9304761}]}]}
{"op":"mcm","clk":"4230347814","pt":1631531922254,"mc":[{"id":"1.187557247","rc":[{"batl":[[2,1.65,1219.1]],"ltp":1.59,"tv":20226.19,"id":10350473}]}]}
{"op":"mcm","clk":"4230347995","pt":1631531924687,"mc":[{"id":"1.187557247","rc":[{"trd":[[1.63,391.06]],"batb":[[0,1.59,132.71],[1,1.58,148.23],[2,1.56,120.25]],"batl":[[0,1.64,134.91],[1,1.65,60],[2,1.66,5.75]],"ltp":1.63,"tv":20508.55,"id":10350473},{"batb":[[1,2.58,3]],"batl":[[0,2.78,44.97],[1,2.8,4.67],[2,2.9,4.55]],"ltp":2.6,"tv":4184.96,"id":9304761}],"tv":24693.51}]}
{"op":"mcm","clk":"4230348064","pt":1631531925363,"mc":[{"id":"1.187557247","rc":[{"batb":[[0,1.56,80.17],[1,1.53,50.33],[2,1.52,159.91]],"batl":[[0,1.64,6]],"ltp":1.63,"tv":20508.55,"id":10350473},{"batb":[[2,2.54,41.96]],"batl":[[1,2.9,4.55],[2,3.15,203.19]],"ltp":2.6,"tv":4184.96,"id":9304761}]}]}
{"op":"mcm","clk":"4230348192","pt":1631531926661,"mc":[{"id":"1.187557247","rc":[{"batb":[[0,1.53,50.33],[1,1.52,159.91],[2,1.45,719.75]],"batl":[[0,1.66,5.75],[1,1.75,61.38],[2,1.87,48.5]],"ltp":1.63,"tv":20508.55,"id":10350473},{"batb":[[0,2.5,13.22],[1,2.34,76.23],[2,2.32,5.64]],"batl":[[0,2.9,4.55],[1,3.15,203.19],[2,3.45,53.16]],"ltp":2.6,"tv":4184.96,"id":9304761}]}]}
{"op":"mcm","clk":"4230348404","pt":1631531928682,"mc":[{"id":"1.187557247","rc":[{"batb":[[0,1.56,38.58],[1,1.53,200.05],[2,1.52,331.01]],"batl":[[1,1.74,195.66],[2,1.75,61.38]],"ltp":1.63,"tv":20508.55,"id":10350473},{"batl":[[0,2.8,4.52],[1,2.9,4.55],[2,3.15,203.19]],"ltp":2.6,"tv":4184.96,"id":9304761}]}]}
{"op":"mcm","clk":"4230348525","pt":1631531929728,"mc":[{"id":"1.187557247","rc":[{"batb":[[0,1.64,4],[1,1.63,8.37],[2,1.53,205.05]],"ltp":1.63,"tv":20508.55,"id":10350473},{"batl":[[0,2.9,7.55],[1,3.15,203.19],[2,3.45,53.16]],"ltp":2.6,"tv":4184.96,"id":9304761}]}]}
{"op":"mcm","clk":"4230348603","pt":1631531930453,"mc":[{"id":"1.187557247","rc":[{"batl":[[2,1.75,68.04]],"ltp":1.63,"tv":20508.55,"id":10350473},{"batb":[[2,2.32,18.53]],"ltp":2.6,"tv":4184.96,"id":9304761}]}]}
{"op":"mcm","clk":"4230348784","pt":1631531932629,"mc":[{"id":"1.187557247","rc":[{"batb":[[2,1.56,53.33]],"ltp":1.63,"tv":20508.55,"id":10350473},{"batl":[[0,2.8,7.12],[1,2.9,7.55],[2,3.15,203.19]],"ltp":2.6,"tv":4184.96,"id":9304761}]}]}
{"op":"mcm","clk":"4230348869","pt":1631531933669,"mc":[{"id":"1.187557247","rc":[{"batb":[[2,1.56,6]],"ltp":1.63,"tv":20508.55,"id":10350473},{"batl":[[0,2.8,3]],"ltp":2.6,"tv":4184.96,"id":9304761}]}]}
{"op":"mcm","clk":"4230348943","pt":1631531934756,"mc":[{"id":"1.187557247","rc":[{"trd":[[1.63,397.14],[1.64,148.82]],"batb":[[0,1.63,5.33],[1,1.56,6],[2,1.55,5]],"ltp":1.63,"tv":20522.63,"id":10350473},{"batl":[[2,3.45,53.16]],"ltp":2.6,"tv":4184.96,"id":9304761}],"tv":24707.6}]}
{"op":"mcm","clk":"4230349045","pt":1631531935757,"mc":[{"id":"1.187557247","rc":[{"trd":[[1.66,337.28],[1.67,805.59]],"batb":[[0,1.68,2201.92],[1,1.66,2551.57],[2,1.65,2236.44]],"batl":[[0,1.74,195.66],[1,1.75,68.04],[2,1.76,204.32]],"ltp":1.67,"tv":20553.92,"id":10350473},{"trd":[[2.5,13.22]],"batb":[[0,2.34,76.23],[1,2.32,18.53],[2,2.3,1663.04]],"batl":[[1,2.9,14.45]],"ltp":2.5,"tv":4198.18,"id":9304761}],"tv":24752.11}]}
{"op":"mcm","clk":"4230349126","pt":1631531936748,"mc":[{"id":"1.187557247","rc":[{"trd":[[1.68,35]],"batb":[[0,1.69,111.63],[1,1.68,208.06],[2,1.66,1399.47]],"ltp":1.68,"tv":20578.46,"id":10350473},{"batb":[[2,2.3,457.34]],"ltp":2.5,"tv":4198.18,"id":9304761}],"tv":24776.65}]}
{"op":"mcm","clk":"4230349190","pt":1631531937634,"mc":[{"id":"1.187557247","rc":[{"batl":[[2,1.76,264.32]],"ltp":1.68,"tv":20578.46,"id":10350473},{"batl":[[0,2.56,48.03],[1,2.8,3],[2,2.9,14.45]],"ltp":2.5,"tv":4198.18,"id":9304761}]}]}
{"op":"mcm","clk":"4230349282","pt":1631531938663,"mc":[{"id":"1.187557247","rc":[{"trd":[[1.69,174.44]],"batb":[[0,1.69,106.75]],"ltp":1.69,"tv":20588.22,"id":10350473},{"batb":[[0,2.36,4],[1,2.34,79.23],[2,2.32,18.53]],"ltp":2.5,"tv":4198.18,"id":9304761}],"tv":24786.41}]}
{"op":"mcm","clk":"4230349310","pt":1631531938978,"mc":[{"id":"1.187557247","rc":[{"batl":[[0,1.73,34.79],[1,1.74,195.66],[2,1.75,68.04]],"ltp":1.69,"tv":20588.22,"id":10350473},{"batb":[[0,2.36,29.69],[2,2.32,63.98]],"ltp":2.5,"tv":4198.18,"id":9304761}]}]}
{"op":"mcm","clk":"4230349466","pt":1631531940841,"mc":[{"id":"1.187557247","rc":[{"batl":[[0,2.54,25.5],[1,2.56,48.03],[2,2.8,3]],"ltp":2.5,"tv":4198.18,"id":9304761}]}]}
{"op":"mcm","clk":"4230349584","pt":1631531942252,"mc":[{"id":"1.187557247","rc":[{"trd":[[1.69,181.94]],"batb":[[0,1.69,103]],"batl":[[0,1.72,5],[1,1.73,34.79],[2,1.74,195.66]],"ltp":1.69,"tv":20595.72,"id":10350473},{"batb":[[0,2.38,4],[1,2.36,29.69],[2,2.34,79.23]],"ltp":2.5,"tv":4198.18,"id":9304761}],"tv":24793.91}]}
{"op":"mcm","clk":"4230349863","pt":1631531945475,"mc":[{"id":"1.187557247","rc":[{"batl":[[0,2.8,3],[1,2.9,11.45],[2,3,216.4]],"ltp":2.5,"tv":4198.18,"id":9304761}]}]}
{"op":"mcm","clk":"4230349961","pt":1631531946468,"mc":[{"id":"1.187557247","rc":[{"trd":[[1.72,109.64],[1.73,46.48]],"batb":[[0,1.69,177]],"batl":[[0,1.73,11.55],[1,1.74,195.66],[2,1.75,68.04]],"ltp":1.73,"tv":20652.2,"id":10350473}],"tv":24850.39}]}
{"op":"mcm","clk":"4230350057","pt":1631531947676,"mc":[{"id":"1.187557247","rc":[{"batb":[[0,1.69,103],[1,1.68,204.29]],"batl":[[0,1.73,61.55]],"ltp":1.73,"tv":20652.2,"id":10350473}]}]}
{"op":"mcm","clk":"4230350133","pt":1631531948661,"mc":[{"id":"1.187557247","rc":[{"batl":[[0,2.52,48.66],[1,2.78,598.33],[2,2.8,3]],"ltp":2.5,"tv":4198.18,"id":9304761}]}]}
{"op":"mcm","clk":"4230350222","pt":1631531949759,"mc":[{"id":"1.187557247","rc":[{"batb":[[2,1.66,247.35]],"batl":[[0,1.73,50]],"ltp":1.73,"tv":20652.2,"id":10350473},{"batb":[[1,2.36,4]],"batl":[[1,2.8,3],[2,2.9,4.55]],"ltp":2.5,"tv":4198.18,"id":9304761}]}]}
{"op":"mcm","clk":"4230350276","pt":1631531950689,"mc":[{"id":"1.187557247","rc":[{"batb":[[0,1.65,74.42],[1,1.63,5.33],[2,1.59,137.15]],"batl":[[0,1.69,3],[1,1.73,50],[2,1.76,60]],"ltp":1.73,"tv":20652.2,"id":10350473},{"batb":[[0,2.32,45.45],[1,2.18,7.36],[2,2.14,7.82]],"batl":[[2,3,216.4]],"ltp":2.5,"tv":4198.18,"id":9304761}]}]}
{"op":"mcm","clk":"4230350320","pt":1631531951470,"mc":[{"id":"1.187557247","rc":[{"batb":[[0,1.63,5.33],[1,1.59,137.15],[2,1.56,6]],"batl":[[0,1.69,5.32],[2,1.84,54.53]],"ltp":1.73,"tv":20652.2,"id":10350473},{"batb":[[0,2.18,7.36],[1,2.14,7.82],[2,2.12,101.42]],"batl":[[0,2.8,3],[1,3,216.4],[2,3.45,53.16]],"ltp":2.5,"tv":4198.18,"id":9304761}]}]}
{"op":"mcm","clk":"4230350457","pt":1631531953600,"mc":[{"id":"1.187557247","rc":[{"batb":[[1,1.59,340.28],[2,1.58,148.23]],"ltp":1.73,"tv":20652.2,"id":10350473}]}]}
{"op":"mcm","clk":"4230350515","pt":1631531954386,"mc":[{"id":"1.187557247","rc":[{"batb":[[1,1.59,137.15],[2,1.56,6]],"ltp":1.73,"tv":20652.2,"id":10350473}]}]}
{"op":"mcm","clk":"4230350587","pt":1631531955169,"mc":[{"id":"1.187557247","rc":[{"trd":[[1.69,185.29]],"batl":[[0,1.69,1.97]],"ltp":1.69,"tv":20655.56,"id":10350473},{"trd":[[2.44,2.32]],"ltp":2.44,"tv":4200.5,"id":9304761}],"tv":24856.06}]}
{"op":"mcm","clk":"4230350701","pt":1631531956466,"mc":[{"id":"1.187557247","rc":[{"batl":[[0,2.5,409.59],[1,2.8,3],[2,3,216.4]],"ltp":2.44,"tv":4200.5,"id":9304761}]}]}
{"op":"mcm","clk":"4230350802","pt":1631531957469,"mc":[{"id":"1.187557247","rc":[{"trd":[[1.69,189.23]],"batb":[[0,1.71,143.75],[1,1.69,232.28],[2,1.63,5.33]],"batl":[[0,1.73,50],[1,1.76,121.96],[2,1.78,197.5]],"ltp":1.69,"tv":20659.5,"id":10350473},{"batl":[[0,2.8,3],[1,3,216.4],[2,3.45,53.16]],"ltp":2.44,"tv":4200.5,"id":9304761}],"tv":24860.0}]}
{"op":"mcm","clk":"4230350865","pt":1631531958090,"mc":[{"id":"1.187557247","rc":[{"batb":[[2,1.64,26.65]],"ltp":1.69,"tv":20659.5,"id":10350473},{"batb":[[0,2.2,36.8],[1,2.18,7.36],[2,2.14,7.82]],"batl":[[0,2.74,15],[1,2.8,3],[2,3,216.4]],"ltp":2.44,"tv":4200.5,"id":9304761}]}]}
{"op":"mcm","clk":"4230351181","pt":1631531962091,"mc":[{"id":"1.187557247","rc":[{"batb":[[0,1.71,255.75]],"ltp":1.69,"tv":20659.5,"id":10350473}]}]}
{"op":"mcm","clk":"4230351341","pt":1631531963978,"mc":[{"id":"1.187557247","rc":[{"batb":[[0,1.71,112],[1,1.63,5.33],[2,1.59,137.15]],"batl":[[1,1.84,54.53],[2,1.85,60.3]],"ltp":1.69,"tv":20659.5,"id":10350473},{"batb":[[0,2.18,7.36],[1,2.14,7.82],[2,2.12,101.42]],"batl":[[0,2.8,3],[1,3,216.4],[2,3.45,53.16]],"ltp":2.44,"tv":4200.5,"id":9304761}]}]}
{"op":"mcm","clk":"4230351644","pt":1631531967263,"mc":[{"id":"1.187557247","rc":[{"trd":[[1.73,117.06]],"batb":[[0,1.63,5.33],[1,1.59,340.28],[2,1.58,148.23]],"batl":[[0,1.73,14.71]],"ltp":1.73,"tv":20730.08,"id":10350473}],"tv":24930.58}]}
{"op":"mcm","clk":"4230352235","pt":1631531974168,"mc":[{"id":"1.187557247","rc":[{"batl":[[0,1.71,2.56],[1,1.73,14.71],[2,1.84,54.53]],"ltp":1.73,"tv":20730.08,"id":10350473}]}]}
{"op":"mcm","clk":"4230352358","pt":1631531975668,"mc":[{"id":"1.187557247","rc":[{"trd":[[1.59,24.7],[1.63,407.8]],"batb":[[0,1.59,332.87],[1,1.58,148.23],[2,1.56,6]],"batl":[[0,1.64,2001.9],[1,1.71,2.56],[2,1.73,14.71]],"ltp":1.59,"tv":20755.56,"id":10350473},{"batb":[[0,2.56,17.08],[1,2.54,1505.9],[2,2.52,1461.62]],"batl":[[0,2.78,1375.9],[1,2.8,1338.44],[2,2.82,1335.44]],"ltp":2.44,"tv":4200.5,"id":9304761}],"tv":24956.06}]}
{"op":"mcm","clk":"4230352436","pt":1631531976685,"mc":[{"id":"1.187557247","rc":[{"batb":[[2,1.45,719.75]],"batl":[[0,1.64,287.71],[1,1.65,125.7],[2,1.71,2.56]],"ltp":1.59,"tv":20755.56,"id":10350473},{"batb":[[1,2.54,752.94],[2,2.52,730.82]],"batl":[[0,2.78,378.37],[1,2.8,367.25],[2,2.82,367.25]],"ltp":2.44,"tv":4200.5,"id":9304761}]}]}
{"op":"mcm","clk":"4230352530","pt":1631531977721,"mc":[{"id":"1.187557247","rc":[{"batb":[[2,1.56,80.17]],"batl":[[2,1.66,60]],"ltp":1.59,"tv":20755.56,"id":10350473},{"batb":[[0,2.56,77.08],[2,2.52,770.29]],"batl":[[0,2.78,438.34]],"ltp":2.44,"tv":4200.5,"id":9304761}]}]}
{"op":"mcm","clk":"4230352555","pt":1631531977987,"mc":[{"id":"1.187557247","rc":[{"batl":[[0,2.78,423.34]],"ltp":2.44,"tv":4200.5,"id":9304761}]}]}
{"op":"mcm","clk":"4230352663","pt":1631531979384,"mc":[{"id":"1.187557247","rc":[{"batl":[[0,1.63,5],[1,1.64,287.71],[2,1.65,125.7]],"ltp":1.59,"tv":20755.56,"id":10350473},{"batb":[[0,2.6,3],[1,2.58,4],[2,2.56,81.08]],"ltp":2.44,"tv":4200.5,"id":9304761}]}]}
{"op":"mcm","clk":"4230352763","pt":1631531980577,"mc":[{"id":"1.187557247","rc":[{"batl":[[2,1.65,163.61]],"ltp":1.59,"tv":20755.56,"id":10350473},{"batl":[[0,2.68,58.57],[1,2.78,423.34],[2,2.8,367.25]],"ltp":2.44,"tv":4200.5,"id":9304761}]}]}
{"op":"mcm","clk":"4230352840","pt":1631531981615,"mc":[{"id":"1.187557247","rc":[{"batl":[[0,1.63,36],[2,1.65,125.7]],"ltp":1.59,"tv":20755.56,"id":10350473},{"batb":[[1,2.58,40.8]],"batl":[[0,2.76,19.6]],"ltp":2.44,"tv":4200.5,"id":9304761}]}]}
{"op":"mcm","clk":"4230352923","pt":1631531982604,"mc":[{"id":"1.187557247","rc":[{"batl":[[2,1.65,185.7]],"ltp":1.59,"tv":20755.56,"id":10350473}]}]}
{"op":"mcm","clk":"4230353065","pt":1631531984533,"mc":[{"id":"1.187557247","rc":[{"trd":[[1.63,484.59],[1.64,631.94]],"batb":[[0,1.59,273.9],[1,1.56,80.17],[2,1.55,42.39]],"batl":[[0,1.65,185.7],[1,1.69,68.5],[2,1.73,60.5]],"ltp":1.64,"tv":21315.47,"id":10350473},{"trd":[[2.6,25.56]],"batb":[[0,2.58,40.8],[1,2.56,81.08],[2,2.54,791.9]],"ltp":2.6,"tv":4203.5,"id":9304761}],"tv":25518.97}]}
{"op":"mcm","clk":"4230353237","pt":1631531986616,"mc":[{"id":"1.187557247","rc":[{"trd":[[1.64,633.94]],"ltp":1.64,"tv":21317.47,"id":10350473},{"trd":[[2.58,1.27]],"batb":[[0,2.58,39.53]],"ltp":2.58,"tv":4204.77,"id":9304761}],"tv":25522.24}]}
{"op":"mcm","clk":"4230353322","pt":1631531987703,"mc":[{"id":"1.187557247","rc":[{"batb":[[0,1.63,2.32],[1,1.6,139.78],[2,1.59,273.9]],"batl":[[0,1.65,295.36],[1,1.67,241.58],[2,1.69,68.5]],"ltp":1.64,"tv":21317.47,"id":10350473},{"batb":[[0,2.58,16.38]],"batl":[[0,2.6,17.04],[1,2.76,19.6],[2,2.78,423.34]],"ltp":2.58,"tv":4204.77,"id":9304761}]}]}
{"op":"mcm","clk":"4230353366","pt":1631531988224,"mc":[{"id":"1.187557247","rc":[{"batl":[[0,1.64,37.6],[1,1.65,295.36],[2,1.67,241.58]],"ltp":1.64,"tv":21317.47,"id":10350473}]}]}
{"op":"mcm","clk":"4230353636","pt":1631531991544,"mc":[{"id":"1.187557247","rc":[{"trd":[[1.64,650.68]],"batl":[[0,1.64,29.23]],"ltp":1.64,"tv":21334.2,"id":10350473},{"batb":[[1,2.56,77.08]],"ltp":2.58,"tv":4204.77,"id":9304761}],"tv":25538.98}]}
{"op":"mcm","clk":"4230353759","pt":1631531992740,"mc":[{"id":"1.187557247","rc":[{"trd":[[1.64,713.43],[1.65,275.29]],"batl":[[0,1.65,187.7],[1,1.67,241.58],[2,1.71,32.81]],"ltp":1.65,"tv":21612.27,"id":10350473},{"trd":[[2.58,4]],"batb":[[0,2.56,60],[1,2.54,38.96],[2,2.4,5.21]],"batl":[[1,2.78,44.97],[2,2.82,5.25]],"ltp":2.58,"tv":4207.5,"id":9304761}],"tv":25819.78}]}
{"op":"mcm","clk":"4230353776","pt":1631531993049,"mc":[{"id":"1.187557247","rc":[{"batb":[[1,1.56,80.17],[2,1.55,42.39]],"batl":[[0,1.65,60],[1,1.71,32.81],[2,1.75,35.94]],"ltp":1.65,"tv":21612.27,"id":10350473},{"batb":[[0,2.54,38.96],[1,2.4,5.21],[2,2.32,85.13]],"ltp":2.58,"tv":4207.5,"id":9304761}]}]}
{"op":"mcm","clk":"4230353909","pt":1631531994719,"mc":[{"id":"1.187557247","rc":[{"trd":[[1.63,488.59]],"batb":[[0,1.63,432.42],[1,1.52,162.34],[2,1.51,50.99]],"batl":[[0,1.75,35.94],[1,1.89,4.51],[2,1.9,2]],"ltp":1.63,"tv":21616.27,"id":10350473},{"trd":[[2.6,31.56]],"batb":[[0,2.32,85.13],[1,1.82,406.77],[2,1.8,11.88]],"batl":[[0,2.6,14.04],[1,2.98,5.25],[2,3,216.4]],"ltp":2.6,"tv":4213.5,"id":9304761}],"tv":25829.78}]}
{"op":"mcm","clk":"4230353977","pt":1631531995708,"mc":[{"id":"1.187557247","rc":[{"batb":[[0,1.63,35.71]],"ltp":1.63,"tv":21616.27,"id":10350473},{"batb":[[0,2.58,3],[1,2.32,85.13],[2,1.82,406.77]],"batl":[[0,2.98,5.25],[1,3,216.4],[2,3.45,53.16]],"ltp":2.6,"tv":4213.5,"id":9304761}]}]}
{"op":"mcm","clk":"4230354057","pt":1631531996743,"mc":[{"id":"1.187557247","rc":[{"batb":[[0,1.63,35.38],[1,1.52,332.59]],"ltp":1.63,"tv":21616.27,"id":10350473},{"batb":[[0,2.32,85.13],[1,1.82,406.77],[2,1.8,11.88]],"ltp":2.6,"tv":4213.5,"id":9304761}]}]}
{"op":"mcm","clk":"4230354065","pt":1631531996848,"mc":[{"id":"1.187557247","rc":[{"batb":[[1,1.53,166.95],[2,1.52,332.59]],"batl":[[1,1.77,213.97],[2,1.79,192.75]],"ltp":1.63,"tv":21616.27,"id":10350473}]}]}
{"op":"mcm","clk":"4230354198","pt":1631531998617,"mc":[{"id":"1.187557247","rc":[{"batb":[[2,1.52,338.59]],"batl":[[0,1.75,40.94]],"ltp":1.63,"tv":21616.27,"id":10350473},{"batb":[[0,2.32,89.13],[1,2.3,3],[2,1.82,406.77]],"batl":[[0,2.94,4],[1,2.98,5.25],[2,3,216.4]],"ltp":2.6,"tv":4213.5,"id":9304761}]}]}
{"op":"mcm","clk":"4230354343","pt":1631532000434,"mc":[{"id":"1.187557247","rc":[{"batb":[[1,1.52,168.34],[2,1.51,56.99]],"ltp":1.63,"tv":21616.27,"id":10350473}]}]}
{"op":"mcm","clk":"4230354449","pt":1631532001742,"mc":[{"id":"1.187557247","rc":[{"batb":[[1,1.55,43.39],[2,1.52,168.34]],"batl":[[0,1.71,36.5],[1,1.75,40.94],[2,1.77,213.97]],"ltp":1.63,"tv":21616.27,"id":10350473},{"batb":[[0,2.4,5.81],[1,2.32,89.13],[2,2.3,3]],"batl":[[0,2.82,4.75],[1,2.94,4],[2,2.98,5.25]],"ltp":2.6,"tv":4213.5,"id":9304761}]}]}
{"op":"mcm","clk":"4230354524","pt":1631532002526,"mc":[{"id":"1.187557247","rc":[{"batb":[[1,1.52,168.34],[2,1.51,56.99]],"batl":[[0,1.75,40.94],[1,1.77,213.97],[2,1.79,192.75]],"ltp":1.63,"tv":21616.27,"id":10350473},{"batb":[[0,2.32,89.13],[1,2.3,3],[2,1.82,406.77]],"batl":[[0,2.94,4],[1,2.98,5.25],[2,3,216.4]],"ltp":2.6,"tv":4213.5,"id":9304761}]}]}
{"op":"mcm","clk":"4230354635","pt":1631532003679,"mc":[{"id":"1.187557247","rc":[{"trd":[[1.63,517.52]],"batb":[[0,1.71,148.78],[1,1.69,231.38],[2,1.63,20.92]],"batl":[[2,1.79,780.39]],"ltp":1.63,"tv":21645.2,"id":10350473},{"batl":[[0,2.46,777.44],[1,2.48,754.56],[2,2.5,754.56]],"ltp":2.6,"tv":4213.5,"id":9304761}],"tv":25858.71}]}
{"op":"mcm","clk":"4230354733","pt":1631532004727,"mc":[{"id":"1.187557247","rc":[{"trd":[[1.71,384.54]],"batb":[[0,1.71,136.58],[1,1.7,108.28],[2,1.69,231.38]],"batl":[[1,1.77,60],[2,1.79,587.64]],"ltp":1.71,"tv":21669.6,"id":10350473},{"batb":[[0,2.32,111.75],[1,2.3,49.15],[2,2.04,112.72]],"ltp":2.6,"tv":4213.5,"id":9304761}],"tv":25883.11}]}
{"op":"mcm","clk":"4230354762","pt":1631532005037,"mc":[{"id":"1.187557247","rc":[{"batb":[[0,2.32,89.13]],"ltp":2.6,"tv":4213.5,"id":9304761}]}]}
{"op":"mcm","clk":"4230354871","pt":1631532006248,"mc":[{"id":"1.187557247","rc":[{"batl":[[0,1.74,5],[1,1.75,40.94],[2,1.77,60]],"ltp":1.71,"tv":21669.6,"id":10350473},{"batb":[[0,2.34,4],[1,2.32,89.13],[2,2.3,49.15]],"ltp":2.6,"tv":4213.5,"id":9304761}]}]}
{"op":"mcm","clk":"4230354998","pt":1631532007653,"mc":[{"id":"1.187557247","rc":[{"trd":[[1.71,388.54]],"batb":[[0,1.71,134.58]],"batl":[[2,1.76,121.52]],"ltp":1.71,"tv":21673.6,"id":10350473}],"tv":25887.11}]}
{"op":"mcm","clk":"4230355098","pt":1631532008640,"mc":[{"id":"1.187557247","rc":[{"batb":[[2,1.69,463.53]],"ltp":1.71,"tv":21673.6,"id":10350473},{"batl":[[0,2.46,798.97]],"ltp":2.6,"tv":4213.5,"id":9304761}]}]}
{"op":"mcm","clk":"4230355212","pt":1631532009733,"mc":[{"id":"1.187557247","rc":[{"batb":[[0,2.36,3],[1,2.34,4],[2,2.32,85.13]],"ltp":2.6,"tv":4213.5,"id":9304761}]}]}
{"op":"mcm","clk":"4230355297","pt":1631532010557,"mc":[{"id":"1.187557247","rc":[{"batl":[[2,2.5,803.54]],"ltp":2.6,"tv":4213.5,"id":9304761}]}]}
{"op":"mcm","clk":"4230355398","pt":1631532011653,"mc":[{"id":"1.187557247","rc":[{"trd":[[1.74,439.6],[1.75,192.68]],"batb":[[0,1.71,202.58]],"batl":[[0,1.75,14.72],[1,1.76,121.52],[2,1.77,60]],"ltp":1.75,"tv":21740.11,"id":10350473},{"trd":[[2.36,88.83]],"batb":[[0,2.34,4],[1,2.32,85.13],[2,2.3,46.15]],"ltp":2.36,"tv":4216.5,"id":9304761}],"tv":25956.62}]}
{"op":"mcm","clk":"4230355433","pt":1631532012122,"mc":[{"id":"1.187557247","rc":[{"batb":[[0,1.71,134.58]],"batl":[[1,1.76,353.67]],"ltp":1.75,"tv":21740.11,"id":10350473}]}]}
{"op":"mcm","clk":"4230355660","pt":1631532014732,"mc":[{"id":"1.187557247","rc":[{"trd":[[1.74,445.6]],"batb":[[0,1.74,20.43],[1,1.71,134.58],[2,1.7,108.28]],"ltp":1.74,"tv":21746.11,"id":10350473}],"tv":25962.62}]}
{"op":"mcm","clk":"4230355806","pt":1631532016562,"mc":[{"id":"1.187557247","rc":[{"trd":[[1.71,407.68],[1.74,486.46]],"batb":[[0,1.71,125.01],[1,1.7,108.28],[2,1.69,463.53]],"ltp":1.71,"tv":21806.11,"id":10350473}],"tv":26022.61}]}
{"op":"mcm","clk":"4230356119","pt":1631532020266,"mc":[{"id":"1.187557247","rc":[{"trd":[[1.71,412.33]],"batb":[[0,1.71,122.69]],"ltp":1.71,"tv":21810.75,"id":10350473}],"tv":26027.26}]}
{"op":"mcm","clk":"4230356248","pt":1631532021633,"mc":[{"id":"1.187557247","rc":[{"trd":[[1.75,227.47],[1.76,2371.74]],"batl":[[0,1.76,20.81],[1,1.77,60],[2,1.78,196.7]],"ltp":1.76,"tv":22511.28,"id":10350473},{"trd":[[2.34,36.36]],"batb":[[0,2.32,85.13],[1,2.3,46.15],[2,2.08,8.56]],"ltp":2.34,"tv":4220.5,"id":9304761}],"tv":26731.78}]}
{"op":"mcm","clk":"4230356287","pt":1631532022048,"mc":[{"id":"1.187557247","rc":[{"batl":[[0,1.74,4],[1,1.76,20.81],[2,1.77,60]],"ltp":1.76,"tv":22511.28,"id":10350473}]}]}
{"op":"mcm","clk":"4230356383","pt":1631532023351,"mc":[{"id":"1.187557247","rc":[{"batb":[[0,1.69,232.15],[1,1.66,73.85],[2,1.63,20.92]],"ltp":1.76,"tv":22511.28,"id":10350473},{"batb":[[0,2.3,46.15],[1,2.08,8.56],[2,2.06,9.58]],"batl":[[0,2.5,48.98],[1,2.68,5.14],[2,2.86,4.25]],"ltp":2.34,"tv":4220.5,"id":9304761}]}]}
{"op":"mcm","clk":"4230356492","pt":1631532024752,"mc":[{"id":"1.187557247","rc":[{"batb":[[1,1.63,20.92],[2,1.6,42.59]],"batl":[[0,1.76,20.81],[1,1.89,4.51],[2,2.02,8.25]],"ltp":1.76,"tv":22511.28,"id":10350473},{"batb":[[0,2.04,112.72],[1,1.99,23.51],[2,1.97,26.17]],"batl":[[0,2.68,5.14],[1,2.86,4.25],[2,2.9,4.55]],"ltp":2.34,"tv":4220.5,"id":9304761}]}]}
{"op":"mcm","clk":"4230356559","pt":1631532025536,"mc":[{"id":"1.187557247","rc":[{"batl":[[0,1.71,20],[1,1.76,20.81],[2,1.89,4.51]],"ltp":1.76,"tv":22511.28,"id":10350473},{"batl":[[0,2.6,17.04],[1,2.68,5.14],[2,2.86,4.25]],"ltp":2.34,"tv":4220.5,"id":9304761}]}]}
{"op":"mcm","clk":"4230356627","pt":1631532026572,"mc":[{"id":"1.187557247","rc":[{"batb":[[0,2.3,3],[1,2.04,112.72],[2,1.99,23.51]],"ltp":2.34,"tv":4220.5,"id":9304761}]}]}
{"op":"mcm","clk":"4230356675","pt":1631532027247,"mc":[{"id":"1.187557247","rc":[{"trd":[[1.71,452.32]],"batb":[[0,1.72,196.26],[1,1.69,232.15],[2,1.63,20.92]],"batl":[[0,1.76,20.81],[1,1.89,4.51],[2,1.96,123.35]],"ltp":1.71,"tv":22551.28,"id":10350473},{"batb":[[0,2.04,112.72],[1,1.99,23.51],[2,1.97,26.17]],"ltp":2.34,"tv":4220.5,"id":9304761}],"tv":26771.78}]}
{"op":"mcm","clk":"4230356748","pt":1631532027970,"mc":[{"id":"1.187557247","rc":[{"batl":[[2,1.92,24.56]],"ltp":1.71,"tv":22551.28,"id":10350473},{"batb":[[0,2.08,7.81],[1,2.04,112.72],[2,1.99,23.51]],"ltp":2.34,"tv":4220.5,"id":9304761}]}]}
{"op":"mcm","clk":"4230356837","pt":1631532029075,"mc":[{"id":"1.187557247","rc":[{"batl":[[2,1.96,123.35]],"ltp":1.71,"tv":22551.28,"id":10350473},{"batb":[[0,2.04,112.72],[1,1.99,23.51],[2,1.97,26.17]],"ltp":2.34,"tv":4220.5,"id":9304761}]}]}
{"op":"mcm","clk":"4230356908","pt":1631532029854,"mc":[{"id":"1.187557247","rc":[{"trd":[[1.72,114.28]],"batb":[[0,1.72,193.94]],"ltp":1.72,"tv":22555.92,"id":10350473}],"tv":26776.43}]}
{"op":"mcm","clk":"4230357045","pt":1631532031055,"mc":[{"id":"1.187557247","rc":[{"batb":[[1,1.63,20.92],[2,1.6,42.59]],"ltp":1.72,"tv":22555.92,"id":10350473}]}]}
{"op":"mcm","clk":"4230357551","pt":1631532037201,"mc":[{"id":"1.187557247","rc":[{"trd":[[1.72,134.29]],"batb":[[0,1.72,183.94]],"ltp":1.72,"tv":22575.92,"id":10350473}],"tv":26796.43}]}
{"op":"mcm","clk":"4230357846","pt":1631532041002,"mc":[{"id":"1.187557247","rc":[{"batl":[[0,2.68,5.14],[1,2.86,4.25],[2,2.9,4.55]],"ltp":2.34,"tv":4220.5,"id":9304761}]}]}
{"op":"mcm","clk":"4230358118","pt":1631532044303,"mc":[{"id":"1.187557247","rc":[{"trd":[[1.72,135.55]],"batb":[[0,1.72,183.31]],"ltp":1.72,"tv":22577.18,"id":10350473}],"tv":26797.69}]}
{"op":"mcm","clk":"4230358200","pt":1631532045494,"mc":[{"id":"1.187557247","rc":[{"trd":[[1.76,2376.38]],"batl":[[0,1.76,18.49]],"ltp":1.76,"tv":22581.83,"id":10350473}],"tv":26802.33}]}
{"op":"mcm","clk":"4230358338","pt":1631532047167,"mc":[{"id":"1.187557247","rc":[{"batl":[[0,1.89,4.51],[1,1.96,123.35],[2,1.98,142.37]],"ltp":1.76,"tv":22581.83,"id":10350473}]}]}
{"op":"mcm","clk":"4230358461","pt":1631532048509,"mc":[{"id":"1.187557247","rc":[{"trd":[[1.89,35.88]],"batb":[[0,1.89,2516.76],[1,1.87,2045.46],[2,1.86,1985.3]],"batl":[[0,1.96,123.35],[1,1.98,142.37],[2,2,1912.5]],"ltp":1.89,"tv":22590.85,"id":10350473},{"batl":[[0,2.54,7.87],[1,2.68,5.14],[2,2.86,4.25]],"ltp":2.34,"tv":4220.5,"id":9304761}],"tv":26811.35}]}
{"op":"mcm","clk":"4230358570","pt":1631532049612,"mc":[{"id":"1.187557247","rc":[{"trd":[[1.89,58.36]],"batb":[[0,1.89,182.41],[1,1.88,77.66],[2,1.87,1189.66]],"batl":[[2,2,525.94]],"ltp":1.89,"tv":22613.33,"id":10350473}],"tv":26833.83}]}
{"op":"mcm","clk":"4230358664","pt":1631532050706,"mc":[{"id":"1.187557247","rc":[{"batl":[[0,1.94,60],[1,1.96,123.35],[2,1.98,142.37]],"ltp":1.89,"tv":22613.33,"id":10350473},{"batb":[[0,2.08,4],[1,2.06,4],[2,2.04,196.98]],"batl":[[0,2.26,53.45],[1,2.38,3],[2,2.54,7.87]],"ltp":2.34,"tv":4220.5,"id":9304761}]}]}
{"op":"mcm","clk":"4230358757","pt":1631532051700,"mc":[{"id":"1.187557247","rc":[{"batl":[[1,1.95,3],[2,1.96,150.18]],"ltp":1.89,"tv":22613.33,"id":10350473},{"batb":[[2,2.04,200.98]],"ltp":2.34,"tv":4220.5,"id":9304761}]}]}
{"op":"mcm","clk":"4230358963","pt":1631532053692,"mc":[{"id":"1.187557247","rc":[{"batb":[[0,1.91,167.32],[1,1.89,182.41],[2,1.88,77.66]],"batl":[[0,1.93,4],[1,1.94,60],[2,1.95,3]],"ltp":1.89,"tv":22613.33,"id":10350473},{"batl":[[0,2.38,3],[1,2.54,7.87],[2,2.68,5.14]],"ltp":2.34,"tv":4220.5,"id":9304761}]}]}
{"op":"mcm","clk":"4230359140","pt":1631532055627,"mc":[{"id":"1.187557247","rc":[{"batb":[[2,2.04,143.29]],"batl":[[0,2.26,91.72],[1,2.38,3],[2,2.44,5.58]],"ltp":2.34,"tv":4220.5,"id":9304761}]}]}
{"op":"mcm","clk":"4230359301","pt":1631532057711,"mc":[{"id":"1.187557247","rc":[{"batl":[[0,2.24,53.88],[1,2.26,91.72],[2,2.38,3]],"ltp":2.34,"tv":4220.5,"id":9304761}]}]}
{"op":"mcm","clk":"4230359437","pt":1631532059222,"mc":[{"id":"1.187557247","rc":[{"trd":[[1.91,212.5]],"batb":[[0,1.91,155.32]],"ltp":1.91,"tv":22637.33,"id":10350473},{"batb":[[1,2.06,60.6]],"ltp":2.34,"tv":4220.5,"id":9304761}],"tv":26857.83}]}
{"op":"mcm","clk":"4230359545","pt":1631532060587,"mc":[{"id":"1.187557247","rc":[{"batb":[[1,1.89,173.66]],"ltp":1.91,"tv":22637.33,"id":10350473},{"batl":[[0,2.22,54.44],[1,2.24,53.88],[2,2.26,91.72]],"ltp":2.34,"tv":4220.5,"id":9304761}]}]}
{"op":"mcm","clk":"4230360026","pt":1631532065715,"mc":[{"id":"1.187557247","rc":[{"trd":[[1.93,52.6],[1.94,17.86]],"batl":[[0,1.96,150.18],[1,1.98,374.52],[2,2,525.94]],"ltp":1.94,"tv":22659.19,"id":10350473},{"trd":[[2.06,141.78],[2.08,8]],"batb":[[0,2.04,139.29],[1,1.99,23.51],[2,1.97,26.17]],"batl":[[1,2.38,3],[2,2.44,5.58]],"ltp":2.06,"tv":4370.28,"id":9304761}],"tv":27029.47}]}
{"op":"mcm","clk":"4230360059","pt":1631532066229,"mc":[{"id":"1.187557247","rc":[{"batb":[[0,1.93,9.76],[1,1.91,155.32],[2,1.89,173.66]],"ltp":1.94,"tv":22659.19,"id":10350473},{"batl":[[0,2.38,3],[1,2.44,5.58],[2,2.54,7.87]],"ltp":2.06,"tv":4370.28,"id":9304761}]}]}
{"op":"mcm","clk":"4230360177","pt":1631532067639,"mc":[{"id":"1.187557247","rc":[{"trd":[[1.91,292.98],[1.93,72.12]],"batb":[[0,1.91,115.08],[1,1.89,173.66],[2,1.88,77.66]],"ltp":1.91,"tv":22759.19,"id":10350473}],"tv":27129.47}]}
{"op":"mcm","clk":"4230360271","pt":1631532068748,"mc":[{"id":"1.187557247","rc":[{"batl":[[0,1.93,5],[1,1.96,150.18],[2,1.98,374.52]],"ltp":1.91,"tv":22759.19,"id":10350473},{"batb":[[0,2.08,4],[1,2.06,3],[2,2.04,139.29]],"ltp":2.06,"tv":4370.28,"id":9304761}]}]}
{"op":"mcm","clk":"4230360318","pt":1631532069308,"mc":[{"id":"1.187557247","rc":[{"batl":[[1,1.95,4],[2,1.96,150.18]],"ltp":1.91,"tv":22759.19,"id":10350473},{"batb":[[0,2.06,3],[1,2.04,143.29],[2,2.02,58.82]],"batl":[[0,2.22,54.32],[1,2.38,3],[2,2.44,5.58]],"ltp":2.06,"tv":4370.28,"id":9304761}]}]}
{"op":"mcm","clk":"4230360488","pt":1631532071442,"mc":[{"id":"1.187557247","rc":[{"batb":[[1,1.84,65.46],[2,1.73,4]],"batl":[[2,1.97,60]],"ltp":1.91,"tv":22759.19,"id":10350473},{"batb":[[1,2.04,4]],"ltp":2.06,"tv":4370.28,"id":9304761}]}]}
{"op":"mcm","clk":"4230360611","pt":1631532072740,"mc":[{"id":"1.187557247","rc":[{"batb":[[1,1.72,183.31],[2,1.71,106.86]],"batl":[[0,1.98,232.15],[1,2.44,6.08],[2,1.97,0]],"ltp":1.91,"tv":22759.19,"id":10350473},{"batb":[[0,1.81,82.93],[1,1.78,2.32],[2,1.76,2.32]],"batl":[[0,2.44,5.58],[1,2.68,5.14],[2,2.7,5.05]],"ltp":2.06,"tv":4370.28,"id":9304761}]}]}
{"op":"mcm","clk":"4230360784","pt":1631532074717,"mc":[{"id":"1.187557247","rc":[{"batb":[[1,1.87,232.15],[2,1.72,347.49]],"batl":[[1,2.26,146.3],[2,2.28,94.81]],"ltp":1.91,"tv":22759.19,"id":10350473},{"batb":[[2,1.77,33.37]],"ltp":2.06,"tv":4370.28,"id":9304761}]}]}
{"op":"mcm","clk":"4230360820","pt":1631532075342,"mc":[{"id":"1.187557247","rc":[{"batb":[[2,1.72,183.31]],"batl":[[1,2.3,7.25],[2,2.44,6.08]],"ltp":1.91,"tv":22759.19,"id":10350473}]}]}
{"op":"mcm","clk":"4230360884","pt":1631532076128,"mc":[{"id":"1.187557247","rc":[{"batb":[[0,1.87,232.15],[1,1.72,183.31],[2,1.71,106.86]],"ltp":1.91,"tv":22759.19,"id":10350473}]}]}
{"op":"mcm","clk":"4230361010","pt":1631532077636,"mc":[{"id":"1.187557247","rc":[{"batl":[[0,2.16,469.36],[1,2.44,5.58],[2,2.68,5.14]],"ltp":2.06,"tv":4370.28,"id":9304761}]}]}
{"op":"mcm","clk":"4230361100","pt":1631532078722,"mc":[{"id":"1.187557247","rc":[{"batb":[[0,1.96,2.32],[1,1.94,155.05],[2,1.92,154]],"batl":[[1,2.02,175.02],[2,2.04,130.61]],"ltp":1.91,"tv":22759.19,"id":10350473},{"batl":[[0,2.44,5.58],[1,2.68,5.14],[2,2.7,5.05]],"ltp":2.06,"tv":4370.28,"id":9304761}]}]}
{"op":"mcm","clk":"4230361160","pt":1631532079449,"mc":[{"id":"1.187557247","rc":[{"batb":[[0,1.83,125.9],[1,1.81,82.93],[2,1.78,2.32]],"batl":[[0,2.32,27.9],[1,2.44,5.58],[2,2.68,5.14]],"ltp":2.06,"tv":4370.28,"id":9304761}]}]}
{"op":"mcm","clk":"4230361344","pt":1631532081742,"mc":[{"id":"1.187557247","rc":[{"batb":[[1,1.87,232.15],[2,1.72,183.31]],"batl":[[1,2.3,7.25],[2,2.44,6.08]],"ltp":1.91,"tv":22759.19,"id":10350473},{"batb":[[0,1.81,82.93],[1,1.78,2.32],[2,1.77,33.37]],"batl":[[0,2.44,5.58],[1,2.68,5.14],[2,2.7,5.05]],"ltp":2.06,"tv":4370.28,"id":9304761}]}]}
{"op":"mcm","clk":"4230361605","pt":1631532084657,"mc":[{"id":"1.187557247","rc":[{"batb":[[2,1.72,347.49]],"batl":[[1,2.26,146.3],[2,2.28,94.81]],"ltp":1.91,"tv":22759.19,"id":10350473}]}]}
{"op":"mcm","clk":"4230361624","pt":1631532084863,"mc":[{"id":"1.187557247","rc":[{"trd":[[1.98,741.84]],"batl":[[0,1.98,20.39]],"ltp":1.98,"tv":23182.71,"id":10350473}],"tv":27552.99}]}
{"op":"mcm","clk":"4230361830","pt":1631532087132,"mc":[{"id":"1.187557247","rc":[{"batb":[[0,1.87,232.15],[1,1.72,347.49],[2,1.71,106.86]],"ltp":1.98,"tv":23182.71,"id":10350473}]}]}
{"op":"mcm","clk":"4230362979","pt":1631532100563,"mc":[{"id":"1.187557247","rc":[{"trd":[[1.87,464.3]],"batb":[[0,1.72,347.49],[1,1.71,106.86],[2,1.7,263.59]],"batl":[[1,2.26,0],[2,2.28,0]],"ltp":1.87,"tv":23647.01,"id":10350473},{"batb":[[2,1.76,2.32]],"ltp":2.06,"tv":4370.28,"id":9304761}],"tv":28017.29}]}
{"op":"mcm","clk":"4230363147","pt":1631532102586,"mc":[{"id":"1.187557247","rc":[{"trd":[[1.72,159.79]],"batb":[[0,1.72,335.37]],"batl":[[0,1.74,2701.14],[1,1.77,16.5],[2,1.79,1312.84]],"ltp":1.72,"tv":23671.25,"id":10350473},{"batb":[[0,2.28,4.16],[1,1.81,82.93],[2,1.78,2.32]],"ltp":2.06,"tv":4370.28,"id":9304761}],"tv":28041.54}]}
{"op":"mcm","clk":"4230363260","pt":1631532103681,"mc":[{"id":"1.187557247","rc":[{"batb":[[0,1.72,164.18],[1,1.71,1481.14],[2,1.7,950.73]],"batl":[[2,1.78,188.52]],"ltp":1.72,"tv":23671.25,"id":10350473},{"batb":[[0,2.3,79.91],[1,2.28,4.16],[2,2.04,113.97]],"ltp":2.06,"tv":4370.28,"id":9304761}]}]}
{"op":"mcm","clk":"4230363349","pt":1631532104757,"mc":[{"id":"1.187557247","rc":[{"batb":[[1,1.71,278.65],[2,1.7,421.19]],"ltp":1.72,"tv":23671.25,"id":10350473},{"batb":[[2,2.22,49.18]],"batl":[[0,2.44,55.58]],"ltp":2.06,"tv":4370.28,"id":9304761}]}]}
{"op":"mcm","clk":"4230363519","pt":1631532106572,"mc":[{"id":"1.187557247","rc":[{"batb":[[1,2.28,695.2]],"ltp":2.06,"tv":4370.28,"id":9304761}]}]}
{"op":"mcm","clk":"4230363629","pt":1631532107765,"mc":[{"id":"1.187557247","rc":[{"trd":[[1.74,698.08]],"batl":[[0,1.74,2595.33]],"ltp":1.74,"tv":23882.87,"id":10350473},{"batb":[[0,2.3,100.71],[1,2.28,4.16]],"ltp":2.06,"tv":4370.28,"id":9304761}],"tv":28253.15}]}
{"op":"mcm","clk":"4230363711","pt":1631532108554,"mc":[{"id":"1.187557247","rc":[{"batb":[[0,1.72,321.18]],"ltp":1.74,"tv":23882.87,"id":10350473},{"batb":[[2,2.04,116.97]],"ltp":2.06,"tv":4370.28,"id":9304761}]}]}
{"op":"mcm","clk":"4230363760","pt":1631532109277,"mc":[{"id":"1.187557247","rc":[{"batb":[[2,2.06,7.58]],"batl":[[1,2.62,5.75],[2,2.68,5.14]],"ltp":2.06,"tv":4370.28,"id":9304761}]}]}
{"op":"mcm","clk":"4230363977","pt":1631532111675,"mc":[{"id":"1.187557247","rc":[{"trd":[[1.74,4933.38]],"batl":[[0,1.74,477.68]],"ltp":1.74,"tv":28118.17,"id":10350473},{"batb":[[2,2.24,48.38]],"ltp":2.06,"tv":4370.28,"id":9304761}],"tv":32488.45}]}
{"op":"mcm","clk":"4230364155","pt":1631532113657,"mc":[{"id":"1.187557247","rc":[{"trd":[[1.74,4957.38]],"batl":[[0,1.74,465.68]],"ltp":1.74,"tv":28142.17,"id":10350473}],"tv":32512.45}]}
{"op":"mcm","clk":"4230364339","pt":1631532115558,"mc":[{"id":"1.187557247","rc":[{"trd":[[1.74,5057.38]],"batl":[[0,1.74,415.68]],"ltp":1.74,"tv":28242.17,"id":10350473}],"tv":32612.45}]}
{"op":"mcm","clk":"4230364657","pt":1631532119195,"mc":[{"id":"1.187557247","rc":[{"trd":[[1.74,5888.74]],"batb":[[0,1.74,7.85],[1,1.72,321.18],[2,1.71,278.65]],"batl":[[0,1.77,16.5],[1,1.78,188.52],[2,1.79,262.56]],"ltp":1.74,"tv":29073.53,"id":10350473}],"tv":33443.81}]}
{"op":"mcm","clk":"4230364941","pt":1631532122274,"mc":[{"id":"1.187557247","rc":[{"batl":[[0,1.76,4],[1,1.77,118.45],[2,1.78,188.52]],"ltp":1.74,"tv":29073.53,"id":10350473},{"batb":[[0,2.32,4],[1,2.3,103.71],[2,2.28,4.16]],"ltp":2.06,"tv":4370.28,"id":9304761}]}]}
{"op":"mcm","clk":"4230365038","pt":1631532123266,"mc":[{"id":"1.187557247","rc":[{"batb":[[0,1.72,321.18],[1,1.71,278.65],[2,1.7,421.19]],"ltp":1.74,"tv":29073.53,"id":10350473}]}]}
{"op":"mcm","clk":"4230365158","pt":1631532124575,"mc":[{"id":"1.187557247","rc":[{"batb":[[0,1.7,71.71],[1,1.63,20.92],[2,1.62,41.04]],"batl":[[0,1.8,60],[1,1.97,4],[2,2.04,7.38]],"ltp":1.74,"tv":29073.53,"id":10350473},{"batb":[[0,2.24,48.38],[1,2.04,116.97],[2,1.97,25.17]],"batl":[[0,2.44,50]],"ltp":2.06,"tv":4370.28,"id":9304761}]}]}
{"op":"mcm","clk":"4230365268","pt":1631532125718,"mc":[{"id":"1.187557247","rc":[{"batb":[[0,1.74,2.32]],"batl":[[0,1.97,4],[1,2.04,7.38],[2,2.06,7.42]],"ltp":1.74,"tv":29073.53,"id":10350473},{"batb":[[0,2.04,116.97],[1,1.97,25.17],[2,1.95,26.91]],"batl":[[0,2.62,5.75],[1,2.68,5.14],[2,2.7,5.05]],"ltp":2.06,"tv":4370.28,"id":9304761}]}]}
{"op":"mcm","clk":"4230365347","pt":1631532126510,"mc":[{"id":"1.187557247","rc":[{"batl":[[0,1.95,26.3],[1,1.97,4],[2,2.04,7.38]],"ltp":1.74,"tv":29073.53,"id":10350473}]}]}
{"op":"mcm","clk":"4230365470","pt":1631532127612,"mc":[{"id":"1.187557247","rc":[{"batl":[[0,1.97,137.81],[1,1.99,140.26]],"ltp":1.74,"tv":29073.53,"id":10350473}]}]}
{"op":"mcm","clk":"4230365667","pt":1631532129696,"mc":[{"id":"1.187557247","rc":[{"batl":[[0,1.95,2],[1,1.97,4]],"ltp":1.74,"tv":29073.53,"id":10350473},{"batb":[[1,2.02,4],[2,1.97,25.17]],"ltp":2.06,"tv":4370.28,"id":9304761}]}]}
{"op":"mcm","clk":"4230365745","pt":1631532130631,"mc":[{"id":"1.187557247","rc":[{"batl":[[0,1.94,2],[1,1.95,2],[2,1.97,4]],"ltp":1.74,"tv":29073.53,"id":10350473}]}]}
{"op":"mcm","clk":"4230365852","pt":1631532131720,"mc":[{"id":"1.187557247","rc":[{"trd":[[1.63,543.16],[1.74,5893.38]],"batb":[[0,1.63,8.1],[1,1.62,41.04],[2,1.6,225.71]],"batl":[[0,1.64,16.93],[1,1.65,1727.04],[2,1.94,2]],"ltp":1.63,"tv":29103.81,"id":10350473},{"batb":[[0,2.56,3.83],[1,2.52,1517.86],[2,2.5,1473.22]],"ltp":2.06,"tv":4370.28,"id":9304761}],"tv":33474.1}]}
{"op":"mcm","clk":"4230365969","pt":1631532132715,"mc":[{"id":"1.187557247","rc":[{"batb":[[1,1.6,183.12],[2,1.59,323.27]],"batl":[[1,1.65,205.44],[2,1.67,240.84]],"ltp":1.63,"tv":29103.81,"id":10350473},{"batb":[[0,2.56,63.75],[1,2.52,758.94],[2,2.5,736.6]],"batl":[[0,2.7,5.05],[1,2.74,383.89],[2,2.76,377.62]],"ltp":2.06,"tv":4370.28,"id":9304761}]}]}
{"op":"mcm","clk":"4230366038","pt":1631532133390,"mc":[{"id":"1.187557247","rc":[{"batl":[[1,2.74,429.37]],"ltp":2.06,"tv":4370.28,"id":9304761}]}]}
{"op":"mcm","clk":"4230366167","pt":1631532134690,"mc":[{"id":"1.187557247","rc":[{"trd":[[1.63,554.57]],"batb":[[0,1.6,183.12],[1,1.59,323.27],[2,1.57,130.04]],"batl":[[0,1.64,17.62]],"ltp":1.63,"tv":29115.22,"id":10350473},{"trd":[[2.6,34.56]],"batb":[[0,2.58,3],[1,2.56,63.75],[2,2.52,758.94]],"ltp":2.6,"tv":4373.28,"id":9304761}],"tv":33488.51}]}
{"op":"mcm","clk":"4230366362","pt":1631532136719,"mc":[{"id":"1.187557247","rc":[{"batl":[[0,1.64,54.56]],"ltp":1.63,"tv":29115.22,"id":10350473},{"batb":[[1,2.56,166.04]],"ltp":2.6,"tv":4373.28,"id":9304761}]}]}
{"op":"mcm","clk":"4230366533","pt":1631532138592,"mc":[{"id":"1.187557247","rc":[{"batb":[[0,1.6,1124.83]],"ltp":1.63,"tv":29115.22,"id":10350473}]}]}
{"op":"mcm","clk":"4230366680","pt":1631532140307,"mc":[{"id":"1.187557247","rc":[{"batl":[[2,1.67,300.84]],"ltp":1.63,"tv":29115.22,"id":10350473}]}]}
{"op":"mcm","clk":"4230367026","pt":1631532143588,"mc":[{"id":"1.187557247","rc":[{"trd":[[1.63,555.95],[1.64,722.05]],"batl":[[0,1.64,49.56],[1,1.65,191.32]],"ltp":1.64,"tv":29125.22,"id":10350473}],"tv":33498.51}]}
{"op":"mcm","clk":"4230367215","pt":1631532145722,"mc":[{"id":"1.187557247","rc":[{"trd":[[1.64,792.63]],"batb":[[0,1.6,183.12],[1,1.59,281.16],[2,1.57,79.47]],"batl":[[0,1.65,191.32],[1,1.67,300.84],[2,1.73,43]],"ltp":1.64,"tv":29195.8,"id":10350473},{"batb":[[1,2.56,59.92],[2,2.5,40]],"batl":[[0,2.74,45.48],[1,2.82,4.25],[2,2.86,4.25]],"ltp":2.6,"tv":4373.28,"id":9304761}],"tv":33569.09}]}
{"op":"mcm","clk":"4230367304","pt":1631532146612,"mc":[{"id":"1.187557247","rc":[{"batb":[[0,1.57,79.47],[1,1.55,43.19],[2,1.54,48.62]],"batl":[[0,1.6,15],[1,1.65,232.15],[2,1.67,60]],"ltp":1.64,"tv":29195.8,"id":10350473},{"batb":[[0,2.5,40],[1,2.36,21.11],[2,2.3,81.42]],"ltp":2.6,"tv":4373.28,"id":9304761}]}]}
{"op":"mcm","clk":"4230367412","pt":1631532147706,"mc":[{"id":"1.187557247","rc":[{"batb":[[0,1.55,232.15],[1,1.52,41.99],[2,1.51,50.99]],"batl":[[2,1.73,43]],"ltp":1.64,"tv":29195.8,"id":10350473},{"batb":[[0,2.36,21.11],[1,2.3,81.42],[2,2.28,21.82]],"batl":[[0,2.94,5.25],[1,2.98,5.25],[2,3.3,194.57]],"ltp":2.6,"tv":4373.28,"id":9304761}]}]}
{"op":"mcm","clk":"4230367500","pt":1631532148695,"mc":[{"id":"1.187557247","rc":[{"trd":[[1.6,100.75]],"batb":[[2,1.51,322.22]],"batl":[[0,1.6,14.25]],"ltp":1.6,"tv":29196.55,"id":10350473},{"trd":[[2.66,0.45]],"batb":[[0,2.6,3],[1,2.36,21.11],[2,2.3,81.42]],"ltp":2.66,"tv":4373.73,"id":9304761}],"tv":33570.29}]}
{"op":"mcm","clk":"4230367582","pt":1631532149624,"mc":[{"id":"1.187557247","rc":[{"trd":[[1.6,109.27]],"batl":[[0,1.6,9.99]],"ltp":1.6,"tv":29205.07,"id":10350473},{"batb":[[0,2.36,21.11],[1,2.3,81.42],[2,2.28,21.82]],"ltp":2.66,"tv":4373.73,"id":9304761}],"tv":33578.81}]}
{"op":"mcm","clk":"4230367655","pt":1631532150612,"mc":[{"id":"1.187557247","rc":[{"trd":[[1.6,121.58]],"batb":[[0,1.55,238.15],[1,1.54,5],[2,1.52,41.99]],"batl":[[0,1.65,232.15],[1,1.73,43],[2,1.78,40]],"ltp":1.6,"tv":29217.39,"id":10350473},{"trd":[[2.66,5.07]],"batl":[[0,2.58,12.42],[1,2.82,4],[2,2.94,5.25]],"ltp":2.66,"tv":4378.34,"id":9304761}],"tv":33595.74}]}
{"op":"mcm","clk":"4230367695","pt":1631532151128,"mc":[{"id":"1.187557247","rc":[{"batb":[[0,1.55,289.14]],"ltp":1.6,"tv":29217.39,"id":10350473},{"batl":[[1,2.82,9.25],[2,2.94,8.25]],"ltp":2.66,"tv":4378.34,"id":9304761}]}]}
{"op":"mcm","clk":"4230368064","pt":1631532155203,"mc":[{"id":"1.187557247","rc":[{"batl":[[0,1.78,40],[1,1.79,243.48],[2,1.81,185.9]],"ltp":1.6,"tv":29217.39,"id":10350473},{"batb":[[0,2.3,81.42],[1,2.28,21.82],[2,2.26,21.46]],"ltp":2.66,"tv":4378.34,"id":9304761}]}]}
{"op":"mcm","clk":"4230368195","pt":1631532156712,"mc":[{"id":"1.187557247","rc":[{"batb":[[0,1.73,2853.14],[1,1.55,289.14],[2,1.54,5]],"ltp":1.6,"tv":29217.39,"id":10350473},{"batl":[[0,2.82,9.25],[1,2.94,8.25],[2,2.98,5.25]],"ltp":2.66,"tv":4378.34,"id":9304761}]}]}
{"op":"mcm","clk":"4230368271","pt":1631532157703,"mc":[{"id":"1.187557247","rc":[{"batb":[[0,1.73,138.33],[1,1.71,221.98],[2,1.69,216.97]],"ltp":1.6,"tv":29217.39,"id":10350473},{"batl":[[0,2.4,796.88],[1,2.42,773.44],[2,2.44,773.44]],"ltp":2.66,"tv":4378.34,"id":9304761}]}]}
{"op":"mcm","clk":"4230368361","pt":1631532158596,"mc":[{"id":"1.187557247","rc":[{"trd":[[1.73,141.3]],"batb":[[0,1.73,126.21],[1,1.72,105.1],[2,1.71,221.98]],"batl":[[2,1.81,245.9]],"ltp":1.73,"tv":29241.63,"id":10350473}],"tv":33619.98}]}
{"op":"mcm","clk":"4230368556","pt":1631532160630,"mc":[{"id":"1.187557247","rc":[{"batl":[[0,1.76,5],[1,1.78,69.68],[2,1.79,243.48]],"ltp":1.73,"tv":29241.63,"id":10350473},{"batb":[[0,2.32,4],[1,2.3,85.42],[2,2.28,21.82]],"ltp":2.66,"tv":4378.34,"id":9304761}]}]}
{"op":"mcm","clk":"4230368733","pt":1631532162501,"mc":[{"id":"1.187557247","rc":[{"batl":[[2,2.44,823.44]],"ltp":2.66,"tv":4378.34,"id":9304761}]}]}
{"op":"mcm","clk":"4230369136","pt":1631532167435,"mc":[{"id":"1.187557247","rc":[{"trd":[[2.32,2.94]],"batb":[[0,2.32,2.53]],"ltp":2.32,"tv":4381.28,"id":9304761}],"tv":33622.92}]}
{"op":"mcm","clk":"4230369623","pt":1631532173716,"mc":[{"id":"1.187557247","rc":[{"trd":[[1.73,151.3]],"batb":[[0,1.73,121.21]],"ltp":1.73,"tv":29251.63,"id":10350473}],"tv":33632.92}]}
{"op":"mcm","clk":"4230369659","pt":1631532174233,"mc":[{"id":"1.187557247","rc":[{"trd":[[1.73,160.59]],"batb":[[0,1.73,116.57]],"batl":[[2,1.79,40]],"ltp":1.73,"tv":29260.92,"id":10350473},{"batb":[[1,2.3,81.42]],"ltp":2.32,"tv":4381.28,"id":9304761}],"tv":33642.2}]}
{"op":"mcm","clk":"4230369836","pt":1631532176615,"mc":[{"id":"1.187557247","rc":[{"trd":[[1.76,2381.03]],"batb":[[0,1.7,71.71],[1,1.69,216.97],[2,1.64,34.32]],"batl":[[0,1.76,2.68],[1,1.78,6.25],[2,1.79,6.5]],"ltp":1.76,"tv":29265.56,"id":10350473},{"batb":[[1,2.28,15.16],[2,2.26,14.48]],"batl":[[0,2.44,50],[1,2.58,5.94],[2,2.7,5.35]],"ltp":2.32,"tv":4381.28,"id":9304761}],"tv":33646.85}]}
{"op":"mcm","clk":"4230369919","pt":1631532177757,"mc":[{"id":"1.187557247","rc":[{"batb":[[0,1.69,216.97],[1,1.64,34.32],[2,1.6,133.72]],"batl":[[0,1.8,232.15],[1,1.87,4.92],[2,1.96,26.62]],"ltp":1.76,"tv":29265.56,"id":10350473},{"batb":[[0,2.04,7.62],[1,2.02,116.48],[2,1.97,25.17]],"batl":[[0,2.58,5.94],[1,2.7,5.35],[2,2.82,9.25]],"ltp":2.32,"tv":4381.28,"id":9304761}]}]}
{"op":"mcm","clk":"4230370064","pt":1631532179515,"mc":[{"id":"1.187557247","rc":[{"batb":[[2,1.6,390.73]],"ltp":1.76,"tv":29265.56,"id":10350473}]}]}
{"op":"mcm","clk":"4230370410","pt":1631532182852,"mc":[{"id":"1.187557247","rc":[{"batl":[[0,1.73,4.88],[1,1.8,232.15],[2,1.87,4.92]],"ltp":1.76,"tv":29265.56,"id":10350473}]}]}
{"op":"mcm","clk":"4230370866","pt":1631532188145,"mc":[{"id":"1.187557247","rc":[{"batl":[[0,1.8,232.15],[1,1.87,4.92],[2,1.96,26.62]],"ltp":1.76,"tv":29265.56,"id":10350473}]}]}
{"op":"mcm","clk":"4230371132","pt":1631532191358,"mc":[{"id":"1.187557247","rc":[{"batb":[[0,1.6,390.73],[1,1.59,184.25],[2,1.55,289.14]],"ltp":1.76,"tv":29265.56,"id":10350473},{"batl":[[0,2.7,5.35],[1,2.82,9.25],[2,2.94,5.25]],"ltp":2.32,"tv":4381.28,"id":9304761}]}]}
{"op":"mcm","clk":"4230371344","pt":1631532193739,"mc":[{"id":"1.187557247","rc":[{"trd":[[1.6,147.22]],"batb":[[0,1.6,377.91]],"batl":[[0,1.63,216.97],[1,1.65,1792.57],[2,1.66,243.21]],"ltp":1.6,"tv":29291.2,"id":10350473},{"batb":[[0,2.52,1519.86],[1,2.5,1473.22],[2,2.48,1473.22]],"batl":[[1,2.74,1395.98],[2,2.76,1354.92]],"ltp":2.32,"tv":4381.28,"id":9304761}],"tv":33672.49}]}
{"op":"mcm","clk":"4230371422","pt":1631532194724,"mc":[{"id":"1.187557247","rc":[{"batb":[[0,1.6,382.91],[1,1.59,190.25],[2,1.55,283.14]],"batl":[[1,1.65,24.47]],"ltp":1.6,"tv":29291.2,"id":10350473},{"batb":[[0,2.54,61.84],[1,2.52,760.94],[2,2.5,736.6]],"batl":[[0,2.68,3],[1,2.7,5.35],[2,2.74,383.89]],"ltp":2.32,"tv":4381.28,"id":9304761}]}]}
{"op":"mcm","clk":"4230371513","pt":1631532195764,"mc":[{"id":"1.187557247","rc":[{"batb":[[0,1.6,377.91],[1,1.59,184.25],[2,1.58,78.78]],"ltp":1.6,"tv":29291.2,"id":10350473},{"batl":[[0,2.7,5.35],[1,2.72,45.74]],"ltp":2.32,"tv":4381.28,"id":9304761}]}]}
{"op":"mcm","clk":"4230371590","pt":1631532196751,"mc":[{"id":"1.187557247","rc":[{"batl":[[1,1.64,4],[2,1.65,24.47]],"ltp":1.6,"tv":29291.2,"id":10350473}]}]}
{"op":"mcm","clk":"4230371640","pt":1631532197368,"mc":[{"id":"1.187557247","rc":[{"batb":[[0,2.6,3],[1,2.58,3],[2,2.54,61.84]],"ltp":2.32,"tv":4381.28,"id":9304761}]}]}
{"op":"mcm","clk":"4230371749","pt":1631532198567,"mc":[{"id":"1.187557247","rc":[{"batl":[[2,1.65,60.41]],"ltp":1.6,"tv":29291.2,"id":10350473},{"batl":[[0,2.68,59.81],[1,2.7,5.35],[2,2.72,45.74]],"ltp":2.32,"tv":4381.28,"id":9304761}]}]}
{"op":"mcm","clk":"4230371790","pt":1631532199028,"mc":[{"id":"1.187557247","rc":[{"batl":[[2,1.65,24.47]],"ltp":1.6,"tv":29291.2,"id":10350473},{"batb":[[2,2.54,99.94]],"batl":[[0,2.7,5.35],[1,2.72,45.74],[2,2.74,383.89]],"ltp":2.32,"tv":4381.28,"id":9304761}]}]}
{"op":"mcm","clk":"4230372108","pt":1631532202152,"mc":[{"id":"1.187557247","rc":[{"batb":[[0,1.6,435.91]],"ltp":1.6,"tv":29291.2,"id":10350473}]}]}
{"op":"mcm","clk":"4230372224","pt":1631532203554,"mc":[{"id":"1.187557247","rc":[{"trd":[[1.63,567.95]],"batl":[[0,1.63,210.96]],"ltp":1.63,"tv":29303.2,"id":10350473}],"tv":33684.49}]}
{"op":"mcm","clk":"4230372289","pt":1631532204279,"mc":[{"id":"1.187557247","rc":[{"trd":[[1.63,990.67]],"batl":[[0,1.64,4],[1,1.65,24.47],[2,1.66,243.21]],"ltp":1.63,"tv":29725.93,"id":10350473},{"trd":[[2.6,35.06]],"batb":[[0,2.6,2.5]],"ltp":2.6,"tv":4381.78,"id":9304761}],"tv":34107.72}]}
{"op":"mcm","clk":"4230372405","pt":1631532205582,"mc":[{"id":"1.187557247","rc":[{"batl":[[1,1.65,7.5]],"ltp":1.63,"tv":29725.93,"id":10350473},{"trd":[[2.6,40.07]],"batb":[[0,2.58,3],[1,2.54,99.94],[2,2.52,760.94]],"batl":[[0,2.6,14.53],[1,2.7,5.35],[2,2.72,45.74]],"ltp":2.6,"tv":4386.79,"id":9304761}],"tv":34112.72}]}
{"op":"mcm","clk":"4230372435","pt":1631532205947,"mc":[{"id":"1.187557247","rc":[{"batb":[[0,1.63,30],[1,1.6,435.91],[2,1.59,184.25]],"ltp":1.63,"tv":29725.93,"id":10350473}]}]}
{"op":"mcm","clk":"4230372598","pt":1631532207767,"mc":[{"id":"1.187557247","rc":[{"batb":[[0,1.63,32.32]],"ltp":1.63,"tv":29725.93,"id":10350473},{"batb":[[2,2.52,2]],"ltp":2.6,"tv":4386.79,"id":9304761}]}]}
{"op":"mcm","clk":"4230372689","pt":1631532208755,"mc":[{"id":"1.187557247","rc":[{"trd":[[1.63,1002.67]],"batb":[[0,1.63,26.32],[1,1.6,58],[2,1.58,78.78]],"batl":[[0,1.67,60],[1,1.73,31.5],[2,1.78,29.25]],"ltp":1.63,"tv":29737.93,"id":10350473},{"batb":[[0,2.5,40],[1,2.36,6.18],[2,2.28,88.75]],"batl":[[1,2.72,45.74],[2,2.8,4.72]],"ltp":2.6,"tv":4386.79,"id":9304761}],"tv":34124.72}]}
{"op":"mcm","clk":"4230372744","pt":1631532209485,"mc":[{"id":"1.187557247","rc":[{"batb":[[1,1.55,50.99],[2,1.52,41.99]],"batl":[[0,1.78,29.25],[1,1.79,29.69],[2,1.8,232.15]],"ltp":1.63,"tv":29737.93,"id":10350473},{"batb":[[0,2.28,88.75],[1,2.26,6.48],[2,2.04,7.62]],"batl":[[1,2.82,5.25],[2,2.94,5.25]],"ltp":2.6,"tv":4386.79,"id":9304761}]}]}
{"op":"mcm","clk":"4230372833","pt":1631532210581,"mc":[{"id":"1.187557247","rc":[{"batb":[[1,1.59,222.43],[2,1.55,50.99]],"ltp":1.63,"tv":29737.93,"id":10350473},{"batl":[[0,2.6,4.56]],"ltp":2.6,"tv":4386.79,"id":9304761}]}]}
{"op":"mcm","clk":"4230373012","pt":1631532212557,"mc":[{"id":"1.187557247","rc":[{"batl":[[0,1.73,30.5],[1,1.78,29.25],[2,1.79,29.69]],"ltp":1.63,"tv":29737.93,"id":10350473},{"batb":[[0,2.36,6.18],[1,2.28,88.75],[2,2.26,6.48]],"ltp":2.6,"tv":4386.79,"id":9304761}]}]}
{"op":"mcm","clk":"4230373040","pt":1631532212870,"mc":[{"id":"1.187557247","rc":[{"batl":[[0,1.78,29.25],[1,1.79,29.69],[2,1.8,232.15]],"ltp":1.63,"tv":29737.93,"id":10350473},{"batb":[[0,2.28,88.75],[1,2.26,6.48],[2,2.04,7.62]],"ltp":2.6,"tv":4386.79,"id":9304761}]}]}
{"op":"mcm","clk":"4230373221","pt":1631532214696,"mc":[{"id":"1.187557247","rc":[{"batb":[[1,1.61,21.09],[2,1.59,222.43]],"batl":[[0,1.64,21.18],[1,1.65,216.97],[2,1.78,29.25]],"ltp":1.63,"tv":29737.93,"id":10350473},{"batl":[[1,2.64,19.43],[2,2.82,5.25]],"ltp":2.6,"tv":4386.79,"id":9304761}]}]}
{"op":"mcm","clk":"4230373274","pt":1631532215478,"mc":[{"id":"1.187557247","rc":[{"batb":[[0,1.63,197.35],[1,1.62,134.44]],"batl":[[0,1.65,216.97],[1,1.68,168.57],[2,1.7,227.27]],"ltp":1.63,"tv":29737.93,"id":10350473},{"batl":[[1,2.82,5.25],[2,2.94,5.25]],"ltp":2.6,"tv":4386.79,"id":9304761}]}]}
{"op":"mcm","clk":"4230373370","pt":1631532216575,"mc":[{"id":"1.187557247","rc":[{"batb":[[0,2.36,5.43],[1,2.3,85.22],[2,2.28,88.75]],"ltp":2.6,"tv":4386.79,"id":9304761}]}]}
{"op":"mcm","clk":"4230373391","pt":1631532216879,"mc":[{"id":"1.187557247","rc":[{"batb":[[1,2.28,88.75],[2,2.26,6.48]],"ltp":2.6,"tv":4386.79,"id":9304761}]}]}
{"op":"mcm","clk":"4230373490","pt":1631532218083,"mc":[{"id":"1.187557247","rc":[{"batb":[[0,1.63,322.35]],"ltp":1.63,"tv":29737.93,"id":10350473}]}]}
{"op":"mcm","clk":"4230373671","pt":1631532220365,"mc":[{"id":"1.187557247","rc":[{"batb":[[0,1.63,26.32],[1,1.59,222.43],[2,1.55,50.99]],"batl":[[1,1.73,29.87],[2,1.78,29.25]],"ltp":1.63,"tv":29737.93,"id":10350473}]}]}
{"op":"mcm","clk":"4230373817","pt":1631532222086,"mc":[{"id":"1.187557247","rc":[{"batb":[[1,1.55,50.99],[2,1.52,41.99]],"ltp":1.63,"tv":29737.93,"id":10350473}]}]}
{"op":"mcm","clk":"4230373962","pt":1631532223699,"mc":[{"id":"1.187557247","rc":[{"trd":[[1.65,698.81]],"batb":[[2,1.52,209.96]],"batl":[[0,1.65,5.21]],"ltp":1.65,"tv":30161.45,"id":10350473}],"tv":34548.24}]}
{"op":"mcm","clk":"4230374039","pt":1631532224686,"mc":[{"id":"1.187557247","rc":[{"batl":[[1,1.78,29.25],[2,1.79,166.5]],"ltp":1.65,"tv":30161.45,"id":10350473},{"batb":[[0,2.28,88.75],[1,2.26,6.48],[2,2.04,7.62]],"batl":[[0,2.82,5.25],[1,2.94,5.25],[2,2.98,5.25]],"ltp":2.6,"tv":4386.79,"id":9304761}]}]}
{"op":"mcm","clk":"4230374068","pt":1631532224997,"mc":[{"id":"1.187557247","rc":[{"trd":[[1.65,703.46]],"batl":[[0,1.65,2.89]],"ltp":1.65,"tv":30166.09,"id":10350473}],"tv":34552.88}]}
{"op":"mcm","clk":"4230374407","pt":1631532229686,"mc":[{"id":"1.187557247","rc":[{"batb":[[0,1.63,24]],"ltp":1.65,"tv":30166.09,"id":10350473}]}]}
{"op":"mcm","clk":"4230374476","pt":1631532230619,"mc":[{"id":"1.187557247","rc":[{"batl":[[1,1.73,33.5],[2,1.78,29.25]],"ltp":1.65,"tv":30166.09,"id":10350473},{"batb":[[0,2.36,6.43],[1,2.28,88.75],[2,2.26,6.48]],"ltp":2.6,"tv":4386.79,"id":9304761}]}]}
{"op":"mcm","clk":"4230374512","pt":1631532230993,"mc":[{"id":"1.187557247","rc":[{"batl":[[1,1.78,29.25],[2,1.79,166.5]],"ltp":1.65,"tv":30166.09,"id":10350473},{"batb":[[0,2.28,88.75],[1,2.26,6.48],[2,2.04,7.62]],"ltp":2.6,"tv":4386.79,"id":9304761}]}]}
{"op":"mcm","clk":"4230374658","pt":1631532232712,"mc":[{"id":"1.187557247","rc":[{"trd":[[1.65,706.34]],"batl":[[0,1.78,29.25],[1,1.79,166.5],[2,1.8,232.15]],"ltp":1.65,"tv":30168.98,"id":10350473},{"trd":[[2.52,45.39]],"batl":[[0,2.52,2.37],[1,2.82,5.25],[2,2.94,5.25]],"ltp":2.52,"tv":4388.68,"id":9304761}],"tv":34557.66}]}
{"op":"mcm","clk":"4230374731","pt":1631532233496,"mc":[{"id":"1.187557247","rc":[{"batb":[[0,1.73,2164.08],[1,1.63,24],[2,1.55,50.99]],"ltp":1.65,"tv":30168.98,"id":10350473}]}]}
{"op":"mcm","clk":"4230374817","pt":1631532234432,"mc":[{"id":"1.187557247","rc":[{"trd":[[1.73,227.59]],"batb":[[0,1.73,2130.58]],"ltp":1.73,"tv":30235.98,"id":10350473}],"tv":34624.66}]}
{"op":"mcm","clk":"4230375089","pt":1631532237614,"mc":[{"id":"1.187557247","rc":[{"trd":[[1.73,286.84]],"batb":[[0,1.73,2100.95]],"ltp":1.73,"tv":30295.23,"id":10350473},{"batb":[[0,2.36,6.68],[1,2.28,88.75],[2,2.26,6.48]],"batl":[[0,2.82,5.25],[1,2.94,5.25],[2,2.98,5.25]],"ltp":2.52,"tv":4388.68,"id":9304761}],"tv":34683.92}]}
{"op":"mcm","clk":"4230375159","pt":1631532238504,"mc":[{"id":"1.187557247","rc":[{"batb":[[0,2.28,88.75],[1,2.26,6.48],[2,2.04,7.62]],"ltp":2.52,"tv":4388.68,"id":9304761}]}]}
{"op":"mcm","clk":"4230375261","pt":1631532239713,"mc":[{"id":"1.187557247","rc":[{"batb":[[0,1.73,2526.27],[1,1.72,11.34],[2,1.71,222.39]],"ltp":1.73,"tv":30295.23,"id":10350473},{"batb":[[2,2.22,473.81]],"batl":[[0,2.4,799.57],[1,2.42,773.44],[2,2.44,773.44]],"ltp":2.52,"tv":4388.68,"id":9304761}]}]}
{"op":"mcm","clk":"4230375351","pt":1631532240707,"mc":[{"id":"1.187557247","rc":[{"trd":[[1.73,311.08]],"batb":[[0,1.73,430.38],[1,1.72,114.85]],"ltp":1.73,"tv":30319.47,"id":10350473},{"batb":[[2,2.22,522.99]],"batl":[[2,2.44,823.44]],"ltp":2.52,"tv":4388.68,"id":9304761}],"tv":34708.16}]}
{"op":"mcm","clk":"4230375455","pt":1631532241903,"mc":[{"id":"1.187557247","rc":[{"trd":[[1.73,313.83]],"batb":[[0,1.73,427.63]],"ltp":1.73,"tv":30322.22,"id":10350473},{"trd":[[2.38,2]],"ltp":2.38,"tv":4390.68,"id":9304761}],"tv":34712.91}]}
{"op":"mcm","clk":"4230375622","pt":1631532243630,"mc":[{"id":"1.187557247","rc":[{"batb":[[0,1.75,67.77],[1,1.73,427.63],[2,1.72,114.85]],"batl":[[0,1.76,74.4],[1,1.78,29.25],[2,1.79,166.5]],"ltp":1.73,"tv":30322.22,"id":10350473}]}]}
{"op":"mcm","clk":"4230375704","pt":1631532244626,"mc":[{"id":"1.187557247","rc":[{"batb":[[1,1.74,73.8],[2,1.73,427.63]],"batl":[[1,1.77,58.62],[2,1.78,29.25]],"ltp":1.73,"tv":30322.22,"id":10350473},{"batl":[[2,2.44,773.44]],"ltp":2.38,"tv":4390.68,"id":9304761}]}]}
{"op":"mcm","clk":"4230375826","pt":1631532246132,"mc":[{"id":"1.187557247","rc":[{"trd":[[1.75,237.47]],"batb":[[0,1.75,62.77]],"ltp":1.75,"tv":30332.22,"id":10350473}],"tv":34722.91}]}
{"op":"mcm","clk":"4230376020","pt":1631532248535,"mc":[{"id":"1.187557247","rc":[{"batl":[[1,1.77,138.95]],"ltp":1.75,"tv":30332.22,"id":10350473},{"batl":[[1,2.42,823.79]],"ltp":2.38,"tv":4390.68,"id":9304761}]}]}
{"op":"mcm","clk":"4230376225","pt":1631532251438,"mc":[{"id":"1.187557247","rc":[{"batb":[[2,1.73,425.32]],"ltp":1.75,"tv":30332.22,"id":10350473}]}]}
{"op":"mcm","clk":"4230376301","pt":1631532252436,"mc":[{"id":"1.187557247","rc":[{"batb":[[0,1.73,216.97],[1,1.71,71.2],[2,1.64,9.69]],"batl":[[0,1.8,232.15],[1,1.82,60],[2,1.86,11.18]],"ltp":1.75,"tv":30332.22,"id":10350473},{"batb":[[0,2.22,49.18],[1,2.04,7.62],[2,2.02,118.66]],"batl":[[0,2.42,50.35],[1,2.6,5.81],[2,2.62,5.25]],"ltp":2.38,"tv":4390.68,"id":9304761}]}]}
{"op":"mcm","clk":"4230376411","pt":1631532253633,"mc":[{"id":"1.187557247","rc":[{"batb":[[1,1.64,9.69],[2,1.63,61.23]],"batl":[[1,1.86,11.18],[2,1.87,4.92]],"ltp":1.75,"tv":30332.22,"id":10350473},{"batb":[[0,2.04,7.62],[1,2.02,118.66],[2,1.97,25.17]],"batl":[[0,2.6,5.81],[1,2.62,5.25],[2,2.76,4.77]],"ltp":2.38,"tv":4390.68,"id":9304761}]}]}
{"op":"mcm","clk":"4230376585","pt":1631532255759,"mc":[{"id":"1.187557247","rc":[{"trd":[[1.75,237.65]],"batb":[[0,1.76,70.5],[1,1.73,216.97],[2,1.64,9.69]],"ltp":1.75,"tv":30332.41,"id":10350473}],"tv":34723.09}]}
{"op":"mcm","clk":"4230376864","pt":1631532259360,"mc":[{"id":"1.187557247","rc":[{"batb":[[0,1.73,216.97],[1,1.64,9.69],[2,1.63,61.23]],"batl":[[0,1.87,4.92],[1,1.89,4.91],[2,1.96,26.62]],"ltp":1.75,"tv":30332.41,"id":10350473}]}]}
{"op":"mcm","clk":"4230377033","pt":1631532261761,"mc":[{"id":"1.187557247","rc":[{"trd":[[1.87,469.23],[1.89,63.26]],"batb":[[0,1.9,2013.16],[1,1.89,1953.94],[2,1.88,1953.94]],"batl":[[0,1.96,26.62],[1,1.99,145.67],[2,2.02,202.34]],"ltp":1.89,"tv":30342.23,"id":10350473},{"trd":[[2.12,19.37],[2.14,4.3]],"batb":[[2,1.98,1931.82]],"batl":[[0,2.12,2826.15],[1,2.52,7.94],[2,2.6,5.81]],"ltp":2.12,"tv":4399.35,"id":9304761}],"tv":34741.59}]}
{"op":"mcm","clk":"4230377104","pt":1631532262753,"mc":[{"id":"1.187557247","rc":[{"trd":[[1.9,177.12],[1.92,119.2]],"batb":[[0,1.92,118.05],[1,1.91,73.89],[2,1.9,1125.77]],"batl":[[0,1.99,145.67],[1,2.02,202.34],[2,2.04,7.38]],"ltp":1.92,"tv":30464.57,"id":10350473},{"batb":[[0,2.02,118.66],[1,1.98,531.26],[2,1.97,540.8]],"batl":[[0,2.12,3.21]],"ltp":2.12,"tv":4399.35,"id":9304761}],"tv":34863.93}]}
{"op":"mcm","clk":"4230377151","pt":1631532263367,"mc":[{"id":"1.187557247","rc":[{"batl":[[0,1.99,205.67]],"ltp":1.92,"tv":30464.57,"id":10350473},{"batb":[[1,2,60],[2,1.98,531.26]],"batl":[[1,2.18,55.23],[2,2.34,29.05]],"ltp":2.12,"tv":4399.35,"id":9304761}]}]}
{"op":"mcm","clk":"4230377193","pt":1631532263944,"mc":[{"id":"1.187557247","rc":[{"batl":[[2,2.36,4]],"ltp":2.12,"tv":4399.35,"id":9304761}]}]}
{"op":"mcm","clk":"4230377289","pt":1631532265283,"mc":[{"id":"1.187557247","rc":[{"batl":[[0,1.99,232.12]],"ltp":1.92,"tv":30464.57,"id":10350473}]}]}
{"op":"mcm","clk":"4230377389","pt":1631532266749,"mc":[{"id":"1.187557247","rc":[{"trd":[[1.92,341.06],[1.94,171.37]],"batb":[[0,1.92,7.12]],"batl":[[0,1.95,12.7],[1,1.96,2.97],[2,1.97,73.64]],"ltp":1.92,"tv":30839.94,"id":10350473},{"batl":[[1,2.14,81.33],[2,2.18,55.23]],"ltp":2.12,"tv":4399.35,"id":9304761}],"tv":35239.3}]}
{"op":"mcm","clk":"4230377432","pt":1631532267262,"mc":[{"id":"1.187557247","rc":[{"batb":[[0,1.93,79.24],[2,1.9,966.94]],"batl":[[0,1.96,2.97],[1,1.97,73.64],[2,1.98,77.77]],"ltp":1.92,"tv":30839.94,"id":10350473},{"batl":[[0,2.12,32.26],[1,2.36,4],[2,2.52,7.94]],"ltp":2.12,"tv":4399.35,"id":9304761}]}]}
{"op":"mcm","clk":"4230377575","pt":1631532269078,"mc":[{"id":"1.187557247","rc":[{"batb":[[0,1.91,73.89],[1,1.9,966.94],[2,1.89,976.96]],"batl":[[0,1.99,86.45],[1,2.04,7.38],[2,2.06,7.42]],"ltp":1.92,"tv":30839.94,"id":10350473},{"batl":[[1,2.34,5.75],[2,2.36,4]],"ltp":2.12,"tv":4399.35,"id":9304761}]}]}
{"op":"mcm","clk":"4230377684","pt":1631532270476,"mc":[{"id":"1.187557247","rc":[{"batb":[[0,1.91,215.61],[2,1.89,1138.52]],"batl":[[0,1.98,140.64],[1,1.99,86.45],[2,2,138.33]],"ltp":1.92,"tv":30839.94,"id":10350473},{"batl":[[1,2.16,55.7],[2,2.34,5.75]],"ltp":2.12,"tv":4399.35,"id":9304761}]}]}
{"op":"mcm","clk":"4230377750","pt":1631532271269,"mc":[{"id":"1.187557247","rc":[{"batb":[[2,1.99,12.73]],"ltp":2.12,"tv":4399.35,"id":9304761}]}]}
{"op":"mcm","clk":"4230378081","pt":1631532275685,"mc":[{"id":"1.187557247","rc":[{"batl":[[0,2.12,3.21]],"ltp":2.12,"tv":4399.35,"id":9304761}]}]}
{"op":"mcm","clk":"4230378394","pt":1631532279954,"mc":[{"id":"1.187557247","rc":[{"trd":[[1.91,297.63]],"batb":[[0,1.91,213.29]],"ltp":1.91,"tv":30844.59,"id":10350473}],"tv":35243.95}]}
{"op":"mcm","clk":"4230378626","pt":1631532283207,"mc":[{"id":"1.187557247","rc":[{"batb":[[0,1.86,64.69],[1,1.84,9.34],[2,1.75,36.11]],"batl":[[0,1.99,60],[1,2.3,5.95],[2,2.48,5.49]],"ltp":1.91,"tv":30844.59,"id":10350473},{"batb":[[0,2,60],[1,1.99,12.73],[2,1.78,89.6]],"batl":[[0,2.16,55.7],[1,2.34,5.75],[2,2.36,4]],"ltp":2.12,"tv":4399.35,"id":9304761}]}]}
{"op":"mcm","clk":"4230378748","pt":1631532284664,"mc":[{"id":"1.187557247","rc":[{"batb":[[0,1.84,9.34],[1,1.74,5],[2,1.73,319.06]],"batl":[[0,2.3,5.95],[1,2.48,5.49],[2,2.48,0]],"ltp":1.91,"tv":30844.59,"id":10350473},{"batb":[[0,1.99,12.73],[1,1.78,89.6],[2,1.77,34.37]],"batl":[[0,2.36,4],[1,2.52,6.01],[2,2.82,234.47]],"ltp":2.12,"tv":4399.35,"id":9304761}]}]}
{"op":"mcm","clk":"4230378774","pt":1631532285081,"mc":[{"id":"1.187557247","rc":[{"batl":[[0,1.9,4],[1,2.3,5.95],[2,2.48,5.49]],"ltp":1.91,"tv":30844.59,"id":10350473}]}]}
{"op":"mcm","clk":"4230378887","pt":1631532286587,"mc":[{"id":"1.187557247","rc":[{"batb":[[2,1.73,518.73]],"batl":[[0,2.28,152.32],[1,2.3,98.57]],"ltp":1.91,"tv":30844.59,"id":10350473}]}]}
{"op":"mcm","clk":"4230378917","pt":1631532286901,"mc":[{"id":"1.187557247","rc":[{"batb":[[1,1.75,406.66],[2,1.74,5]],"ltp":1.91,"tv":30844.59,"id":10350473}]}]}
{"op":"mcm","clk":"4230378984","pt":1631532287870,"mc":[{"id":"1.187557247","rc":[{"batb":[[1,1.75,444.17]],"ltp":1.91,"tv":30844.59,"id":10350473},{"batl":[[0,2.34,6.25],[1,2.36,4],[2,2.52,6.01]],"ltp":2.12,"tv":4399.35,"id":9304761}]}]}
{"op":"mcm","clk":"4230379107","pt":1631532289477,"mc":[{"id":"1.187557247","rc":[{"batl":[[0,2.3,5.95],[1,2.48,5.49],[2,2.48,0]],"ltp":1.91,"tv":30844.59,"id":10350473},{"batb":[[0,1.78,89.6],[1,1.77,34.37],[2,1.76,2.32]],"ltp":2.12,"tv":4399.35,"id":9304761}]}]}
{"op":"mcm","clk":"4230379146","pt":1631532289780,"mc":[{"id":"1.187557247","rc":[{"batb":[[1,1.75,406.66]],"batl":[[0,2.48,5.49],[1,2.48,0]],"ltp":1.91,"tv":30844.59,"id":10350473},{"batb":[[1,1.76,2.32],[2,1.7,414.97]],"batl":[[0,2.36,4],[1,2.82,234.47],[2,3.45,53.16]],"ltp":2.12,"tv":4399.35,"id":9304761}]}]}
{"op":"mcm","clk":"4230379242","pt":1631532291175,"mc":[{"id":"1.187557247","rc":[{"batb":[[2,1.68,42.11]],"batl":[[1,3.45,53.16],[2,3.45,0]],"ltp":2.12,"tv":4399.35,"id":9304761}]}]}
{"op":"mcm","clk":"4230379359","pt":1631532292609,"mc":[{"id":"1.187557247","rc":[{"trd":[[2.16,43.56]],"batb":[[1,1.74,5],[2,1.73,319.06]],"ltp":2.16,"tv":30846.92,"id":10350473},{"trd":[[1.85,105.91]],"batb":[[0,1.78,300.19],[1,1.76,208.35]],"batl":[[0,1.85,185.83],[1,1.87,423.13],[2,1.88,125.66]],"ltp":1.85,"tv":4402.06,"id":9304761}],"tv":35248.98}]}
{"op":"mcm","clk":"4230379423","pt":1631532293578,"mc":[{"id":"1.187557247","rc":[{"trd":[[2.16,53.95]],"batb":[[0,2.18,99.83],[1,2.04,57.69],[2,2.02,125.19]],"batl":[[0,2.24,53.88],[1,2.48,5.49]],"ltp":2.16,"tv":30857.3,"id":10350473},{"trd":[[1.85,118.04]],"batb":[[0,1.81,66.66],[1,1.78,254.63],[2,1.77,82.51]],"batl":[[0,1.85,173.7]],"ltp":1.85,"tv":4414.19,"id":9304761}],"tv":35271.5}]}
{"op":"mcm","clk":"4230379496","pt":1631532294707,"mc":[{"id":"1.187557247","rc":[{"batl":[[1,2.46,27.45],[2,2.48,5.49]],"ltp":2.16,"tv":30857.3,"id":10350473},{"batb":[[1,1.78,284.84]],"ltp":1.85,"tv":4414.19,"id":9304761}]}]}
{"op":"mcm","clk":"4230379622","pt":1631532296513,"mc":[{"id":"1.187557247","rc":[{"batb":[[0,1.83,8.61],[1,1.82,17.33],[2,1.81,92.79]],"batl":[[0,1.84,66.64],[1,1.85,173.7],[2,1.87,423.13]],"ltp":1.85,"tv":4414.19,"id":9304761}]}]}
{"op":"mcm","clk":"4230379822","pt":1631532298581,"mc":[{"id":"1.187557247","rc":[{"batb":[[1,2.02,125.19],[2,1.97,46.7]],"ltp":2.16,"tv":30857.3,"id":10350473}]}]}
{"op":"mcm","clk":"4230379899","pt":1631532299716,"mc":[{"id":"1.187557247","rc":[{"batb":[[1,2.04,7.87],[2,2.02,125.19]],"batl":[[1,2.36,5.82],[2,2.46,32.7]],"ltp":2.16,"tv":30857.3,"id":10350473}]}]}
{"op":"mcm","clk":"4230380053","pt":1631532301705,"mc":[{"id":"1.187557247","rc":[{"trd":[[1.84,27.05]],"batb":[[0,1.83,94.76],[1,1.82,65.12],[2,1.81,66.66]],"batl":[[0,1.84,64.31]],"ltp":1.84,"tv":4418.84,"id":9304761}],"tv":35276.15}]}
{"op":"mcm","clk":"4230380306","pt":1631532305115,"mc":[{"id":"1.187557247","rc":[{"batl":[[0,1.84,173.31]],"ltp":1.84,"tv":4418.84,"id":9304761}]}]}
{"op":"mcm","clk":"4230380477","pt":1631532307709,"mc":[{"id":"1.187557247","rc":[{"trd":[[2.18,28.52]],"batb":[[0,2.18,95.83]],"ltp":2.18,"tv":30865.3,"id":10350473}],"tv":35284.15}]}
{"op":"mcm","clk":"4230380942","pt":1631532313604,"mc":[{"id":"1.187557247","rc":[{"batb":[[0,2.04,7.87],[1,2.02,125.19],[2,1.99,25.51]],"batl":[[2,2.46,5.25]],"ltp":2.18,"tv":30865.3,"id":10350473},{"batb":[[0,1.81,66.66],[1,1.78,1749.58],[2,1.76,2.32]],"batl":[[0,1.84,109],[1,1.88,13.14],[2,1.96,29.87]],"ltp":1.84,"tv":4418.84,"id":9304761}]}]}
{"op":"mcm","clk":"4230381022","pt":1631532314531,"mc":[{"id":"1.187557247","rc":[{"batb":[[0,2.02,125.19],[1,1.99,25.51],[2,1.85,4]],"batl":[[0,2.36,5.82],[1,2.46,5.25],[2,2.48,5.49]],"ltp":2.18,"tv":30865.3,"id":10350473},{"batb":[[0,1.78,1749.58],[1,1.76,2.32],[2,1.74,34.52]],"batl":[[0,1.88,13.14],[1,2.02,9.25],[2,2.18,4]],"ltp":1.84,"tv":4418.84,"id":9304761}]}]}
{"op":"mcm","clk":"4230381096","pt":1631532315321,"mc":[{"id":"1.187557247","rc":[{"batl":[[0,2.46,5.25],[1,2.46,0],[2,2.48,0]],"ltp":2.18,"tv":30865.3,"id":10350473},{"batb":[[0,1.78,2.32],[2,1.69,53.4]],"ltp":1.84,"tv":4418.84,"id":9304761}]}]}
{"op":"mcm","clk":"4230381247","pt":1631532316737,"mc":[{"id":"1.187557247","rc":[{"batb":[[0,2.06,56.6],[1,2.02,125.19],[2,1.99,25.51]],"ltp":2.18,"tv":30865.3,"id":10350473},{"batb":[[2,1.69,253.18]],"batl":[[1,1.97,106.26],[2,1.99,141.84]],"ltp":1.84,"tv":4418.84,"id":9304761}]}]}
{"op":"mcm","clk":"4230381346","pt":1631532317722,"mc":[{"id":"1.187557247","rc":[{"batb":[[0,2.04,8.37]],"ltp":2.18,"tv":30865.3,"id":10350473},{"batl":[[1,1.96,28.37],[2,1.97,106.26]],"ltp":1.84,"tv":4418.84,"id":9304761}]}]}
{"op":"mcm","clk":"4230381436","pt":1631532318646,"mc":[{"id":"1.187557247","rc":[{"batb":[[0,2.02,125.19],[1,1.99,25.51],[2,1.85,4]],"batl":[[0,2.36,6.07],[1,2.46,5.25]],"ltp":2.18,"tv":30865.3,"id":10350473},{"batb":[[2,1.74,33.52]],"batl":[[1,1.97,106.26],[2,1.99,141.84]],"ltp":1.84,"tv":4418.84,"id":9304761}]}]}
{"op":"mcm","clk":"4230381471","pt":1631532318915,"mc":[{"id":"1.187557247","rc":[{"batl":[[0,2.46,5.25],[1,2.46,0]],"ltp":2.18,"tv":30865.3,"id":10350473},{"batb":[[2,1.69,253.18]],"ltp":1.84,"tv":4418.84,"id":9304761}]}]}
{"op":"mcm","clk":"4230381855","pt":1631532323223,"mc":[{"id":"1.187557247","rc":[{"batb":[[2,1.69,239.99]],"batl":[[1,2.02,9.25],[2,2.18,4]],"ltp":1.84,"tv":4418.84,"id":9304761}]}]}
{"op":"mcm","clk":"4230382149","pt":1631532326738,"mc":[{"id":"1.187557247","rc":[{"trd":[[2.12,10]],"batb":[[0,2.28,2.91],[1,2.04,973.72],[2,2.02,125.19]],"ltp":2.12,"tv":30875.3,"id":10350473},{"trd":[[1.76,4.64],[1.78,17.51],[1.88,11.28]],"batb":[[0,1.69,239.99],[1,1.68,105.52],[2,1.67,247.22]],"batl":[[0,1.75,211.04],[1,1.76,1086.64],[2,1.77,1270.53]],"ltp":1.76,"tv":4439.4,"id":9304761}],"tv":35314.71}]}
{"op":"mcm","clk":"4230382225","pt":1631532327556,"mc":[{"id":"1.187557247","rc":[{"trd":[[2.34,155.06]],"batb":[[0,2.34,71.74],[1,2.28,2.91],[2,2.2,50]],"batl":[[0,2.4,50.7],[1,2.46,26.93]],"ltp":2.34,"tv":30894.16,"id":10350473},{"batb":[[0,1.71,71.2],[1,1.69,239.99],[2,1.68,105.52]],"ltp":1.76,"tv":4439.4,"id":9304761}],"tv":35333.57}]}
{"op":"mcm","clk":"4230382275","pt":1631532328135,"mc":[{"id":"1.187557247","rc":[{"trd":[[2.34,235.06]],"batb":[[0,2.34,31.74]],"ltp":2.34,"tv":30974.16,"id":10350473}],"tv":35413.57}]}
{"op":"mcm","clk":"4230382430","pt":1631532330339,"mc":[{"id":"1.187557247","rc":[{"batb":[[0,1.73,17.64],[1,1.72,35.49],[2,1.71,124.75]],"batl":[[0,1.74,66.69],[1,1.75,211.04],[2,1.76,1086.64]],"ltp":1.76,"tv":4439.4,"id":9304761}]}]}
{"op":"mcm","clk":"4230382533","pt":1631532331659,"mc":[{"id":"1.187557247","rc":[{"batb":[[2,2.16,101.34]],"ltp":2.34,"tv":30974.16,"id":10350473},{"trd":[[1.74,378],[1.75,97.2]],"batl":[[0,1.75,196.1],[1,1.76,1086.64],[2,1.77,1270.53]],"ltp":1.75,"tv":4602.66,"id":9304761}],"tv":35576.83}]}
{"op":"mcm","clk":"4230382619","pt":1631532332683,"mc":[{"id":"1.187557247","rc":[{"batb":[[0,2.34,335.87]],"ltp":2.34,"tv":30974.16,"id":10350473}]}]}
{"op":"mcm","clk":"4230382673","pt":1631532333409,"mc":[{"id":"1.187557247","rc":[{"batb":[[2,2.22,7.43]],"batl":[[2,2.52,5.01]],"ltp":2.34,"tv":30974.16,"id":10350473},{"trd":[[1.71,4.1],[1.72,70.99],[1.73,607.52]],"batb":[[0,1.71,122.7],[1,1.7,71.18],[2,1.69,239.99]],"ltp":1.71,"tv":4713.04,"id":9304761}],"tv":35687.2}]}
{"op":"mcm","clk":"4230382849","pt":1631532335695,"mc":[{"id":"1.187557247","rc":[{"batb":[[0,1.73,172.93],[1,1.72,76.58],[2,1.71,69.15]],"batl":[[0,1.74,75.9],[1,1.75,196.1],[2,1.76,1086.64]],"ltp":1.71,"tv":4713.04,"id":9304761}]}]}
{"op":"mcm","clk":"4230382898","pt":1631532336627,"mc":[{"id":"1.187557247","rc":[{"batb":[[2,1.71,71.2]],"ltp":1.71,"tv":4713.04,"id":9304761}]}]}
{"op":"mcm","clk":"4230382927","pt":1631532337046,"mc":[{"id":"1.187557247","rc":[{"trd":[[1.73,748.7]],"batb":[[0,1.73,102.34]],"ltp":1.73,"tv":4854.21,"id":9304761}],"tv":35828.38}]}
{"op":"mcm","clk":"4230383062","pt":1631532338703,"mc":[{"id":"1.187557247","rc":[{"trd":[[2.34,248.27]],"batb":[[0,2.34,329.27]],"ltp":2.34,"tv":30987.37,"id":10350473},{"trd":[[1.73,758.46]],"batb":[[0,1.73,97.46]],"ltp":1.73,"tv":4863.97,"id":9304761}],"tv":35851.35}]}
{"op":"mcm","clk":"4230383132","pt":1631532339731,"mc":[{"id":"1.187557247","rc":[{"trd":[[1.74,412.04]],"batl":[[0,1.74,268.88]],"ltp":1.74,"tv":4898.01,"id":9304761}],"tv":35885.39}]}
{"op":"mcm","clk":"4230383241","pt":1631532341328,"mc":[{"id":"1.187557247","rc":[{"trd":[[2.34,258.27]],"batb":[[0,2.34,324.27]],"ltp":2.34,"tv":30997.37,"id":10350473}],"tv":35895.39}]}
{"op":"mcm","clk":"4230383326","pt":1631532342622,"mc":[{"id":"1.187557247","rc":[{"batb":[[0,2.34,304.13],[1,2.22,7.43],[2,2.16,107.62]],"batl":[[1,2.52,5.01],[2,2.62,5.46]],"ltp":2.34,"tv":30997.37,"id":10350473},{"batb":[[0,1.71,71.2],[1,1.68,9.97],[2,1.66,41.28]],"batl":[[0,1.74,210],[1,1.81,32.71],[2,1.82,32.25]],"ltp":1.74,"tv":4898.01,"id":9304761}]}]}
{"op":"mcm","clk":"4230383410","pt":1631532343607,"mc":[{"id":"1.187557247","rc":[{"batl":[[0,2.62,5.46],[1,2.52,0],[2,2.62,0]],"ltp":2.34,"tv":30997.37,"id":10350473},{"batb":[[0,1.68,9.97],[1,1.62,38.04],[2,1.61,125.1]],"batl":[[0,1.73,24.59]],"ltp":1.74,"tv":4898.01,"id":9304761}]}]}
{"op":"mcm","clk":"4230383571","pt":1631532345732,"mc":[{"id":"1.187557247","rc":[{"batb":[[0,2.22,7.43],[1,2.16,6.28],[2,2.14,4]],"ltp":2.34,"tv":30997.37,"id":10350473},{"trd":[[1.68,639.16]],"batb":[[0,1.68,3.59],[2,1.61,363.68]],"ltp":1.68,"tv":4910.79,"id":9304761}],"tv":35908.16}]}
{"op":"mcm","clk":"4230383763","pt":1631532348121,"mc":[{"id":"1.187557247","rc":[{"trd":[[1.73,777.15]],"batl":[[0,1.73,15.25]],"ltp":1.73,"tv":4929.48,"id":9304761}],"tv":35926.85}]}
{"op":"mcm","clk":"4230383960","pt":1631532350913,"mc":[{"id":"1.187557247","rc":[{"trd":[[1.73,795.84]],"batl":[[0,1.73,5.9]],"ltp":1.73,"tv":4948.17,"id":9304761}],"tv":35945.54}]}
{"op":"mcm","clk":"4230384531","pt":1631532359116,"mc":[{"id":"1.187557247","rc":[{"batb":[[0,2.16,6.28],[1,2.14,4],[2,2.12,103.09]],"ltp":2.34,"tv":30997.37,"id":10350473},{"batl":[[0,1.85,28.5],[1,1.86,194.78],[2,1.87,3]],"ltp":1.73,"tv":4948.17,"id":9304761}]}]}
{"op":"mcm","clk":"4230384797","pt":1631532362549,"mc":[{"id":"1.187557247","rc":[{"batb":[[0,2.16,9.28]],"ltp":2.34,"tv":30997.37,"id":10350473},{"batl":[[0,1.85,31.5]],"ltp":1.73,"tv":4948.17,"id":9304761}]}]}
{"op":"mcm","clk":"4230384826","pt":1631532362962,"mc":[{"id":"1.187557247","rc":[{"batb":[[2,1.61,123.18]],"batl":[[1,1.86,182.68]],"ltp":1.73,"tv":4948.17,"id":9304761}]}]}
{"op":"mcm","clk":"4230385034","pt":1631532365767,"mc":[{"id":"1.187557247","rc":[{"trd":[[2.16,73.23]],"batb":[[0,2.14,4],[1,2.12,103.09],[2,1.99,32.12]],"batl":[[0,2.52,5.01],[1,2.62,5.46]],"ltp":2.16,"tv":31016.65,"id":10350473},{"trd":[[1.85,118.88]],"batb":[[0,1.79,2436.5],[1,1.77,2161.02],[2,1.76,2097.46]],"batl":[[0,1.85,30.66]],"ltp":1.85,"tv":4949.01,"id":9304761}],"tv":35965.66}]}
{"op":"mcm","clk":"4230385120","pt":1631532366757,"mc":[{"id":"1.187557247","rc":[{"batb":[[0,2.12,103.09],[1,1.99,32.12],[2,1.97,66.11]],"ltp":2.16,"tv":31016.65,"id":10350473},{"batb":[[0,1.8,84.6],[1,1.79,226.44],[2,1.77,1282.6]],"batl":[[0,1.85,27.66],[2,1.88,168.89]],"ltp":1.85,"tv":4949.01,"id":9304761}]}]}
{"op":"mcm","clk":"4230385208","pt":1631532367747,"mc":[{"id":"1.187557247","rc":[{"batb":[[1,2.08,55.55],[2,1.99,32.12]],"batl":[[0,2.26,53.45],[1,2.52,32.31],[2,2.62,5.46]],"ltp":2.16,"tv":31016.65,"id":10350473},{"batb":[[1,1.79,293.94]],"ltp":1.85,"tv":4949.01,"id":9304761}]}]}
{"op":"mcm","clk":"4230385285","pt":1631532368731,"mc":[{"id":"1.187557247","rc":[{"batb":[[0,2.14,20],[1,2.12,103.09],[2,2.08,55.55]],"ltp":2.16,"tv":31016.65,"id":10350473}]}]}
{"op":"mcm","clk":"4230385437","pt":1631532370751,"mc":[{"id":"1.187557247","rc":[{"batb":[[0,2.16,329.47],[1,2.14,20],[2,2.12,103.09]],"batl":[[0,2.52,32.31],[1,2.62,5.46],[2,2.62,0]],"ltp":2.16,"tv":31016.65,"id":10350473},{"batb":[[0,1.82,132.68],[1,1.81,72.72],[2,1.8,84.6]],"batl":[[0,1.83,59.76],[1,1.84,60.24],[2,1.85,27.66]],"ltp":1.85,"tv":4949.01,"id":9304761}]}]}
{"op":"mcm","clk":"4230385448","pt":1631532370958,"mc":[{"id":"1.187557247","rc":[{"batl":[[0,2.52,5.01]],"ltp":2.16,"tv":31016.65,"id":10350473},{"trd":[[1.82,11.57]],"batb":[[0,1.82,126.9]],"ltp":1.82,"tv":4960.58,"id":9304761}],"tv":35977.23}]}
{"op":"mcm","clk":"4230385494","pt":1631532371835,"mc":[{"id":"1.187557247","rc":[{"batl":[[0,2.42,6.25],[1,2.52,5.01],[2,2.62,5.46]],"ltp":2.16,"tv":31016.65,"id":10350473}]}]}
{"op":"mcm","clk":"4230385629","pt":1631532373762,"mc":[{"id":"1.187557247","rc":[{"batl":[[2,2.54,5.75]],"ltp":2.16,"tv":31016.65,"id":10350473},{"trd":[[1.82,152.75]],"batb":[[0,1.82,56.31]],"ltp":1.82,"tv":5101.75,"id":9304761}],"tv":36118.41}]}
{"op":"mcm","clk":"4230385678","pt":1631532374749,"mc":[{"id":"1.187557247","rc":[{"batl":[[0,2.24,53.88],[1,2.42,6.25],[2,2.5,27.3]],"ltp":2.16,"tv":31016.65,"id":10350473},{"batb":[[1,1.81,216.79]],"batl":[[0,1.83,44.21],[1,1.84,117.94]],"ltp":1.82,"tv":5101.75,"id":9304761}]}]}
{"op":"mcm","clk":"4230385687","pt":1631532374957,"mc":[{"id":"1.187557247","rc":[{"batb":[[1,1.81,139.38]],"batl":[[1,1.84,60.24]],"ltp":1.82,"tv":5101.75,"id":9304761}]}]}
{"op":"mcm","clk":"4230385792","pt":1631532376465,"mc":[{"id":"1.187557247","rc":[{"batl":[[0,1.83,145.21]],"ltp":1.82,"tv":5101.75,"id":9304761}]}]}
{"op":"mcm","clk":"4230385950","pt":1631532378690,"mc":[{"id":"1.187557247","rc":[{"trd":[[2.2,3.9]],"ltp":2.2,"tv":31020.55,"id":10350473},{"trd":[[1.83,4.69]],"batl":[[0,1.83,140.51]],"ltp":1.83,"tv":5106.45,"id":9304761}],"tv":36127.0}]}
{"op":"mcm","clk":"4230386010","pt":1631532379679,"mc":[{"id":"1.187557247","rc":[{"trd":[[1.83,8.7]],"batl":[[0,1.83,138.51]],"ltp":1.83,"tv":5110.45,"id":9304761}],"tv":36131.01}]}
{"op":"mcm","clk":"4230386050","pt":1631532380195,"mc":[{"id":"1.187557247","rc":[{"trd":[[1.82,265.37]],"batb":[[0,1.81,139.38],[1,1.8,84.6],[2,1.79,203.27]],"batl":[[0,1.83,138.67]],"ltp":1.82,"tv":5223.07,"id":9304761}],"tv":36243.63}]}
{"op":"mcm","clk":"4230386123","pt":1631532381178,"mc":[{"id":"1.187557247","rc":[{"trd":[[2.24,25.54]],"batl":[[0,2.24,48.88]],"ltp":2.24,"tv":31030.55,"id":10350473}],"tv":36253.63}]}
{"op":"mcm","clk":"4230386289","pt":1631532383359,"mc":[{"id":"1.187557247","rc":[{"batb":[[2,1.78,10.81]],"ltp":1.82,"tv":5223.07,"id":9304761}]}]}
{"op":"mcm","clk":"4230386354","pt":1631532384400,"mc":[{"id":"1.187557247","rc":[{"batl":[[0,2.24,53.88]],"ltp":2.24,"tv":31030.55,"id":10350473}]}]}
{"op":"mcm","clk":"4230386477","pt":1631532385700,"mc":[{"id":"1.187557247","rc":[{"batb":[[1,1.8,203.67],[2,1.78,208.95]],"ltp":1.82,"tv":5223.07,"id":9304761}]}]}
{"op":"mcm","clk":"4230386616","pt":1631532387568,"mc":[{"id":"1.187557247","rc":[{"batb":[[1,2.08,55.55],[2,2.02,5]],"batl":[[1,2.52,5.01],[2,2.54,5.75]],"ltp":2.24,"tv":31030.55,"id":10350473},{"trd":[[1.82,265.69],[1.83,41.5]],"batb":[[0,1.81,66.66],[1,1.78,10.81],[2,1.69,104.35]],"batl":[[0,1.83,84.6],[1,1.87,9.4],[2,1.97,24.5]],"ltp":1.83,"tv":5256.19,"id":9304761}],"tv":36286.75}]}
{"op":"mcm","clk":"4230386683","pt":1631532388501,"mc":[{"id":"1.187557247","rc":[{"batb":[[1,2.02,5],[2,1.99,32.12]],"batl":[[0,2.52,5.01],[1,2.54,5.75],[2,2.62,5.46]],"ltp":2.24,"tv":31030.55,"id":10350473},{"batb":[[0,1.78,10.81],[1,1.69,104.35],[2,1.66,36.78]],"batl":[[0,1.87,9.4],[1,1.97,24.5],[2,2.02,9.25]],"ltp":1.83,"tv":5256.19,"id":9304761}]}]}
{"op":"mcm","clk":"4230386826","pt":1631532390477,"mc":[{"id":"1.187557247","rc":[{"batl":[[0,1.97,24.5],[1,2.02,9.25],[2,2.04,8.88]],"ltp":1.83,"tv":5256.19,"id":9304761}]}]}
{"op":"mcm","clk":"4230387041","pt":1631532393685,"mc":[{"id":"1.187557247","rc":[{"batb":[[1,2.02,13.74]],"ltp":2.24,"tv":31030.55,"id":10350473}]}]}
{"op":"mcm","clk":"4230387126","pt":1631532394676,"mc":[{"id":"1.187557247","rc":[{"batb":[[1,2.02,5]],"ltp":2.24,"tv":31030.55,"id":10350473},{"batb":[[0,1.82,184],[1,1.8,191.01],[2,1.78,10.81]],"batl":[[0,1.89,172.83],[1,1.91,160.76],[2,1.97,24.5]],"ltp":1.83,"tv":5256.19,"id":9304761}]}]}
{"op":"mcm","clk":"4230387176","pt":1631532395297,"mc":[{"id":"1.187557247","rc":[{"batl":[[0,2.46,25.05],[1,2.52,5.01],[2,2.54,5.75]],"ltp":2.24,"tv":31030.55,"id":10350473},{"batl":[[2,1.96,54.73]],"ltp":1.83,"tv":5256.19,"id":9304761}]}]}
{"op":"mcm","clk":"4230387351","pt":1631532397492,"mc":[{"id":"1.187557247","rc":[{"batb":[[1,2.02,12.74]],"ltp":2.24,"tv":31030.55,"id":10350473}]}]}
{"op":"mcm","clk":"4230387412","pt":1631532398424,"mc":[{"id":"1.187557247","rc":[{"batb":[[1,2.02,5]],"batl":[[0,2.42,6.75]],"ltp":2.24,"tv":31030.55,"id":10350473},{"batb":[[0,1.82,232.53]],"ltp":1.83,"tv":5256.19,"id":9304761}]}]}
{"op":"mcm","clk":"4230387494","pt":1631532399517,"mc":[{"id":"1.187557247","rc":[{"batb":[[0,2.02,5],[1,1.99,6.61],[2,1.97,451.53]],"batl":[[0,2.52,5.01],[1,2.54,5.75],[2,2.62,5.46]],"ltp":2.24,"tv":31030.55,"id":10350473},{"batb":[[0,1.78,10.81],[1,1.69,104.35],[2,1.66,36.78]],"batl":[[0,2,12.1],[1,2.04,8.88],[2,2.5,278.33]],"ltp":1.83,"tv":5256.19,"id":9304761}]}]}
{"op":"mcm","clk":"4230387704","pt":1631532402719,"mc":[{"id":"1.187557247","rc":[{"batb":[[1,2,4],[2,1.99,6.61]],"batl":[[0,2.42,5.75],[1,2.52,5.01],[2,2.54,5.75]],"ltp":2.24,"tv":31030.55,"id":10350473},{"batb":[[1,1.71,38.19],[2,1.69,263.34]],"batl":[[0,1.97,30.83],[1,1.99,4],[2,2,12.1]],"ltp":1.83,"tv":5256.19,"id":9304761}]}]}
{"op":"mcm","clk":"4230387786","pt":1631532403610,"mc":[{"id":"1.187557247","rc":[{"batl":[[0,2.52,5.01],[1,2.54,5.75],[2,2.62,5.46]],"ltp":2.24,"tv":31030.55,"id":10350473},{"batb":[[1,1.71,18.08]],"batl":[[0,1.97,5]],"ltp":1.83,"tv":5256.19,"id":9304761}]}]}
{"op":"mcm","clk":"4230387864","pt":1631532404648,"mc":[{"id":"1.187557247","rc":[{"batb":[[0,2.02,12.74]],"ltp":2.24,"tv":31030.55,"id":10350473}]}]}
{"op":"mcm","clk":"4230387890","pt":1631532404910,"mc":[{"id":"1.187557247","rc":[{"batb":[[0,2.02,5]],"ltp":2.24,"tv":31030.55,"id":10350473}]}]}
{"op":"mcm","clk":"4230388185","pt":1631532408509,"mc":[{"id":"1.187557247","rc":[{"batb":[[2,1.69,104.35]],"batl":[[2,2.02,215.14]],"ltp":1.83,"tv":5256.19,"id":9304761}]}]}
{"op":"mcm","clk":"4230388287","pt":1631532409712,"mc":[{"id":"1.187557247","rc":[{"batl":[[0,2.42,6.75],[1,2.52,5.01],[2,2.54,5.75]],"ltp":2.24,"tv":31030.55,"id":10350473},{"batb":[[1,1.71,58.27]],"batl":[[0,1.97,32.5]],"ltp":1.83,"tv":5256.19,"id":9304761}]}]}
{"op":"mcm","clk":"4230388380","pt":1631532410752,"mc":[{"id":"1.187557247","rc":[{"trd":[[1.98,745.93],[1.99,295.58]],"batb":[[0,1.97,451.53],[1,1.93,1981.86],[2,1.73,216.97]],"batl":[[0,2.52,5.01],[1,2.54,5.75],[2,2.62,5.46]],"ltp":1.98,"tv":31047.86,"id":10350473},{"trd":[[2.02,4.01]],"batb":[[0,1.92,1992.18],[1,1.91,1933.6],[2,1.9,1933.6]],"batl":[[0,2.02,211.13],[1,2.04,140.59],[2,2.5,278.33]],"ltp":2.02,"tv":5260.2,"id":9304761}],"tv":36308.07}]}
{"op":"mcm","clk":"4230388470","pt":1631532411739,"mc":[{"id":"1.187557247","rc":[{"batb":[[1,1.93,545.02],[2,1.92,528.99]],"batl":[[0,2.08,216.97],[1,2.52,5.01],[2,2.54,5.75]],"ltp":1.98,"tv":31047.86,"id":10350473},{"batb":[[0,1.94,114.01],[1,1.92,1151.14],[2,1.91,966.8]],"batl":[[2,2.36,8.47]],"ltp":2.02,"tv":5260.2,"id":9304761}]}]}
{"op":"mcm","clk":"4230388557","pt":1631532412727,"mc":[{"id":"1.187557247","rc":[{"batb":[[1,1.94,61.88],[2,1.93,545.02]],"batl":[[1,2.1,57.2],[2,2.52,5.01]],"ltp":1.98,"tv":31047.86,"id":10350473},{"batb":[[0,1.94,180.54],[2,1.91,1029.69]],"batl":[[2,2.08,57.73]],"ltp":2.02,"tv":5260.2,"id":9304761}]}]}
{"op":"mcm","clk":"4230388669","pt":1631532413924,"mc":[{"id":"1.187557247","rc":[{"batb":[[0,1.97,477.43]],"ltp":1.98,"tv":31047.86,"id":10350473}]}]}
{"op":"mcm","clk":"4230388816","pt":1631532415754,"mc":[{"id":"1.187557247","rc":[{"batl":[[0,2.06,17],[1,2.08,216.97]],"ltp":1.98,"tv":31047.86,"id":10350473},{"batb":[[0,1.96,65.95],[1,1.94,180.54],[2,1.92,1151.14]],"batl":[[0,1.97,22.56],[1,1.98,44.89],[2,1.99,63.56]],"ltp":2.02,"tv":5260.2,"id":9304761}]}]}
{"op":"mcm","clk":"4230388862","pt":1631532416231,"mc":[{"id":"1.187557247","rc":[{"batl":[[0,2.08,244.09],[1,2.52,5.01],[2,2.54,5.75]],"ltp":1.98,"tv":31047.86,"id":10350473},{"batb":[[1,1.95,78.74],[2,1.94,180.54]],"ltp":2.02,"tv":5260.2,"id":9304761}]}]}
{"op":"mcm","clk":"4230388983","pt":1631532417531,"mc":[{"id":"1.187557247","rc":[{"batb":[[2,1.93,913.76]],"ltp":1.98,"tv":31047.86,"id":10350473}]}]}
{"op":"mcm","clk":"4230389073","pt":1631532418751,"mc":[{"id":"1.187557247","rc":[{"batl":[[0,2.08,301.82],[1,2.26,7.25],[2,2.36,6.32]],"ltp":1.98,"tv":31047.86,"id":10350473}]}]}
{"op":"mcm","clk":"4230389235","pt":1631532420638,"mc":[{"id":"1.187557247","rc":[{"trd":[[1.97,27.07],[1.98,36.89]],"batb":[[0,1.96,59.14]],"batl":[[0,1.97,1.86],[1,1.98,11.74],[2,1.99,90.36]],"ltp":1.98,"tv":5304.19,"id":9304761}],"tv":36352.05}]}
{"op":"mcm","clk":"4230389293","pt":1631532421264,"mc":[{"id":"1.187557247","rc":[{"trd":[[1.96,447.49]],"batb":[[0,1.96,56.81]],"batl":[[0,1.97,158.86]],"ltp":1.96,"tv":5308.84,"id":9304761}],"tv":36356.7}]}
{"op":"mcm","clk":"4230389493","pt":1631532423460,"mc":[{"id":"1.187557247","rc":[{"batb":[[1,1.93,913.76],[2,1.92,528.99]],"batl":[[0,2.08,244.09]],"ltp":1.98,"tv":31047.86,"id":10350473},{"trd":[[1.94,386.74],[1.95,592.07],[1.96,561.11]],"batb":[[0,1.92,996.08],[1,1.91,966.8],[2,1.9,966.8]],"batl":[[0,1.94,389.79],[1,1.97,158.86],[2,1.98,11.74]],"ltp":1.94,"tv":5941.02,"id":9304761}],"tv":36988.88}]}
{"op":"mcm","clk":"4230389562","pt":1631532424353,"mc":[{"id":"1.187557247","rc":[{"batb":[[0,2.06,40],[1,1.97,451.53],[2,1.93,913.76]],"batl":[[0,2.08,216.97]],"ltp":1.98,"tv":31047.86,"id":10350473}]}]}
{"op":"mcm","clk":"4230389699","pt":1631532425674,"mc":[{"id":"1.187557247","rc":[{"trd":[[2.08,10]],"batl":[[0,2.08,211.97]],"ltp":2.08,"tv":31057.86,"id":10350473},{"batl":[[2,2.02,135.59]],"ltp":1.94,"tv":5941.02,"id":9304761}],"tv":36998.88}]}
{"op":"mcm","clk":"4230389773","pt":1631532426651,"mc":[{"id":"1.187557247","rc":[{"trd":[[1.94,1166.32]],"batb":[[0,1.94,241.89],[1,1.93,184.36],[2,1.92,996.08]],"batl":[[0,1.97,158.86],[1,2,139.21]],"ltp":1.94,"tv":6720.6,"id":9304761}],"tv":37778.46}]}
{"op":"mcm","clk":"4230389867","pt":1631532427745,"mc":[{"id":"1.187557247","rc":[{"batb":[[1,1.98,30.01],[2,1.97,451.53]],"ltp":2.08,"tv":31057.86,"id":10350473},{"batb":[[0,1.94,353.45]],"ltp":1.94,"tv":6720.6,"id":9304761}]}]}
{"op":"mcm","clk":"4230389954","pt":1631532428737,"mc":[{"id":"1.187557247","rc":[{"trd":[[2.06,90.87]],"batb":[[0,1.97,451.53],[1,1.93,913.76],[2,1.92,528.99]],"batl":[[0,2.06,192.15],[1,2.08,236.86],[2,2.26,7.25]],"ltp":2.06,"tv":31137.86,"id":10350473},{"batb":[[0,1.94,297.49]],"ltp":1.94,"tv":6720.6,"id":9304761}],"tv":37858.46}]}
{"op":"mcm","clk":"4230390028","pt":1631532429672,"mc":[{"id":"1.187557247","rc":[{"trd":[[2.02,65.07]],"ltp":2.02,"tv":31138.58,"id":10350473},{"trd":[[1.97,27.81]],"batb":[[1,1.93,246.57]],"batl":[[0,1.97,156.26]],"ltp":1.97,"tv":6721.34,"id":9304761}],"tv":37859.92}]}
{"op":"mcm","clk":"4230390047","pt":1631532429834,"mc":[{"id":"1.187557247","rc":[{"batl":[[1,2.08,294.59]],"ltp":2.02,"tv":31138.58,"id":10350473},{"batb":[[0,1.94,185.93]],"ltp":1.97,"tv":6721.34,"id":9304761}]}]}
{"op":"mcm","clk":"4230390208","pt":1631532431658,"mc":[{"id":"1.187557247","rc":[{"batb":[[1,1.93,975.97]],"ltp":2.02,"tv":31138.58,"id":10350473},{"batb":[[0,1.93,192.52],[1,1.92,996.08],[2,1.91,1124.42]],"ltp":1.97,"tv":6721.34,"id":9304761}]}]}
{"op":"mcm","clk":"4230390243","pt":1631532432178,"mc":[{"id":"1.187557247","rc":[{"trd":[[2.06,159.1]],"batb":[[0,1.97,481.54]],"batl":[[0,2.06,123.92]],"ltp":2.06,"tv":31206.81,"id":10350473},{"trd":[[1.94,1238.77]],"ltp":1.94,"tv":6793.79,"id":9304761}],"tv":38000.6}]}
{"op":"mcm","clk":"4230390346","pt":1631532433688,"mc":[{"id":"1.187557247","rc":[{"batb":[[1,1.93,430.95],[2,1.9,27.16]],"ltp":2.06,"tv":31206.81,"id":10350473},{"batb":[[1,1.91,157.62],[2,1.82,10.5]],"ltp":1.94,"tv":6793.79,"id":9304761}]}]}
{"op":"mcm","clk":"4230390423","pt":1631532434678,"mc":[{"id":"1.187557247","rc":[{"batb":[[0,1.97,361.25],[2,1.89,5]],"batl":[[0,2.08,269.7],[1,2.26,7.25],[2,2.36,6.32]],"ltp":2.06,"tv":31206.81,"id":10350473},{"batb":[[0,1.93,62.21],[1,1.82,10.5],[2,1.81,83.43]],"batl":[[1,2.14,8.25],[2,2.16,6.97]],"ltp":1.94,"tv":6793.79,"id":9304761}]}]}
{"op":"mcm","clk":"4230390486","pt":1631532435355,"mc":[{"id":"1.187557247","rc":[{"batb":[[1,1.93,368.74]],"batl":[[0,2.08,211.97]],"ltp":2.06,"tv":31206.81,"id":10350473},{"batb":[[0,1.82,10.5],[1,1.81,83.43],[2,1.8,35.68]],"batl":[[0,2.14,8.25],[1,2.16,6.97],[2,2.22,7.25]],"ltp":1.94,"tv":6793.79,"id":9304761}]}]}
{"op":"mcm","clk":"4230390651","pt":1631532437588,"mc":[{"id":"1.187557247","rc":[{"batb":[[1,1.8,237.33],[2,1.78,198.22]],"batl":[[2,2.18,128.71]],"ltp":1.94,"tv":6793.79,"id":9304761}]}]}
{"op":"mcm","clk":"4230390733","pt":1631532438690,"mc":[{"id":"1.187557247","rc":[{"batl":[[0,2.26,7.25],[1,2.36,6.32],[2,2.38,5.25]],"ltp":2.06,"tv":31206.81,"id":10350473}]}]}
{"op":"mcm","clk":"4230391011","pt":1631532442462,"mc":[{"id":"1.187557247","rc":[{"batb":[[0,1.8,237.33],[1,1.78,198.22],[2,1.74,31.52]],"batl":[[0,1.86,1477.14],[1,2.14,8.25],[2,2.16,6.97]],"ltp":1.94,"tv":6793.79,"id":9304761}]}]}
{"op":"mcm","clk":"4230391265","pt":1631532445749,"mc":[{"id":"1.187557247","rc":[{"batb":[[0,2.16,2.03],[1,2.14,216.97],[2,1.93,368.74]],"ltp":2.06,"tv":31206.81,"id":10350473},{"trd":[[1.85,131.08],[1.86,549.3]],"batb":[[2,1.75,601.07]],"batl":[[0,1.86,171.24],[1,1.88,168.99],[2,1.89,1011.9]],"ltp":1.86,"tv":7355.29,"id":9304761}],"tv":38562.1}]}
{"op":"mcm","clk":"4230391341","pt":1631532446596,"mc":[{"id":"1.187557247","rc":[{"trd":[[2.16,85.31]],"batb":[[0,2.14,321.23],[1,2.04,57.69],[2,1.94,70.79]],"batl":[[0,2.24,53.88],[1,2.26,7.25],[2,2.36,6.32]],"ltp":2.16,"tv":31218.89,"id":10350473},{"trd":[[1.86,747.51]],"batb":[[0,1.81,150.34],[1,1.8,152.65],[2,1.78,198.22]],"batl":[[0,1.86,67.48]],"ltp":1.86,"tv":7553.5,"id":9304761}],"tv":38772.4}]}
{"op":"mcm","clk":"4230391421","pt":1631532447586,"mc":[{"id":"1.187557247","rc":[{"batl":[[0,1.89,1011.9],[1,1.9,982.14],[2,1.91,982.14]],"ltp":1.86,"tv":7553.5,"id":9304761}]}]}
{"op":"mcm","clk":"4230391595","pt":1631532449567,"mc":[{"id":"1.187557247","rc":[{"batb":[[0,1.83,67.35],[1,1.81,150.34],[2,1.8,152.65]],"batl":[[0,1.84,269.25],[1,1.89,1011.9],[2,1.9,982.14]],"ltp":1.86,"tv":7553.5,"id":9304761}]}]}
{"op":"mcm","clk":"4230391692","pt":1631532450668,"mc":[{"id":"1.187557247","rc":[{"batb":[[0,2.14,429.66],[1,1.94,70.79],[2,1.93,368.74]],"ltp":2.16,"tv":31218.89,"id":10350473},{"batb":[[1,1.82,65.7],[2,1.81,150.34]],"batl":[[1,1.85,70.81],[2,1.87,192.13]],"ltp":1.86,"tv":7553.5,"id":9304761}]}]}
{"op":"mcm","clk":"4230391782","pt":1631532451666,"mc":[{"id":"1.187557247","rc":[{"batb":[[0,2.14,344.17],[1,1.95,23.51],[2,1.94,70.79]],"ltp":2.16,"tv":31218.89,"id":10350473}]}]}
{"op":"mcm","clk":"4230391970","pt":1631532453756,"mc":[{"id":"1.187557247","rc":[{"batb":[[1,2.06,56.6],[2,1.97,25.17]],"ltp":2.16,"tv":31218.89,"id":10350473},{"trd":[[1.81,49.76],[1.82,397.09],[1.83,176.2]],"batb":[[0,1.81,142.21],[1,1.8,218.9],[2,1.78,198.22]],"ltp":1.81,"tv":7835.86,"id":9304761}],"tv":39054.76}]}
{"op":"mcm","clk":"4230392035","pt":1631532454592,"mc":[{"id":"1.187557247","rc":[{"batb":[[0,1.82,64.79],[1,1.81,142.21],[2,1.8,218.9]],"batl":[[0,1.83,32.73],[1,1.84,139.05],[2,1.85,167.93]],"ltp":1.81,"tv":7835.86,"id":9304761}]}]}
{"op":"mcm","clk":"4230392096","pt":1631532455375,"mc":[{"id":"1.187557247","rc":[{"batb":[[0,2.14,321.23]],"ltp":2.16,"tv":31218.89,"id":10350473},{"batl":[[1,1.84,278.05]],"ltp":1.81,"tv":7835.86,"id":9304761}]}]}
{"op":"mcm","clk":"4230392486","pt":1631532460306,"mc":[{"id":"1.187557247","rc":[{"batb":[[0,2.14,216.97]],"batl":[[1,2.5,4.99],[2,2.68,5.64]],"ltp":2.16,"tv":31218.89,"id":10350473},{"batb":[[0,1.81,66.66],[1,1.79,9.36],[2,1.67,562.86]],"batl":[[0,1.84,139],[1,1.9,12.84],[2,2.04,8.63]],"ltp":1.81,"tv":7835.86,"id":9304761}]}]}
{"op":"mcm","clk":"4230392584","pt":1631532461508,"mc":[{"id":"1.187557247","rc":[{"trd":[[2.18,32.52]],"batb":[[1,1.97,25.17],[2,1.95,23.51]],"batl":[[0,2.5,4.99],[1,2.68,5.64],[2,2.68,0]],"ltp":2.18,"tv":31222.89,"id":10350473},{"trd":[[1.84,31.79]],"batb":[[0,1.79,9.36],[1,1.67,562.86],[2,1.6,39.44]],"batl":[[0,1.84,134.26]],"ltp":1.84,"tv":7840.6,"id":9304761}],"tv":39063.5}]}
{"op":"mcm","clk":"4230392600","pt":1631532461771,"mc":[{"id":"1.187557247","rc":[{"trd":[[2.18,72.52]],"ltp":2.18,"tv":31262.89,"id":10350473},{"trd":[[1.84,79.18]],"batl":[[0,1.82,56.47],[1,1.84,86.87],[2,1.9,12.84]],"ltp":1.84,"tv":7887.99,"id":9304761}],"tv":39150.89}]}
{"op":"mcm","clk":"4230392735","pt":1631532463490,"mc":[{"id":"1.187557247","rc":[{"batb":[[0,1.97,25.17],[1,1.95,23.51],[2,1.94,70.79]],"ltp":2.18,"tv":31262.89,"id":10350473},{"batl":[[2,2.02,4]],"ltp":1.84,"tv":7887.99,"id":9304761}]}]}
{"op":"mcm","clk":"4230392900","pt":1631532465416,"mc":[{"id":"1.187557247","rc":[{"batl":[[0,2.02,4],[1,2.04,8.63],[2,2.06,7.25]],"ltp":1.84,"tv":7887.99,"id":9304761}]}]}
{"op":"mcm","clk":"4230392992","pt":1631532466410,"mc":[{"id":"1.187557247","rc":[{"batb":[[0,1.94,70.79],[1,1.93,368.74],[2,1.89,5]],"ltp":2.18,"tv":31262.89,"id":10350473},{"batl":[[1,2.14,8.25],[2,2.16,6.97]],"ltp":1.84,"tv":7887.99,"id":9304761}]}]}
{"op":"mcm","clk":"4230393088","pt":1631532467716,"mc":[{"id":"1.187557247","rc":[{"batl":[[0,2.22,144.64],[1,2.46,24.95],[2,2.5,4.99]],"ltp":2.18,"tv":31262.89,"id":10350473},{"batb":[[0,1.84,74.37],[1,1.83,204.82],[2,1.81,187.55]],"batl":[[0,1.9,156.22],[1,1.92,158.2],[2,2.02,4]],"ltp":1.84,"tv":7887.99,"id":9304761}]}]}
{"op":"mcm","clk":"4230393163","pt":1631532468605,"mc":[{"id":"1.187557247","rc":[{"batb":[[0,1.97,3],[1,1.96,5],[2,1.94,70.79]],"batl":[[0,2.5,4.99],[1,2.68,5.64],[2,2.5,0]],"ltp":2.18,"tv":31262.89,"id":10350473},{"batl":[[2,2,20]],"ltp":1.84,"tv":7887.99,"id":9304761}]}]}
{"op":"mcm","clk":"4230393213","pt":1631532469180,"mc":[{"id":"1.187557247","rc":[{"batb":[[0,1.97,30.17],[2,1.95,4]],"ltp":2.18,"tv":31262.89,"id":10350473},{"trd":[[1.84,137.75]],"batb":[[0,1.84,45.09]],"ltp":1.84,"tv":7946.56,"id":9304761}],"tv":39209.45}]}
{"op":"mcm","clk":"4230393338","pt":1631532470478,"mc":[{"id":"1.187557247","rc":[{"batb":[[0,1.99,77.07],[1,1.97,30.17],[2,1.96,5]],"ltp":2.18,"tv":31262.89,"id":10350473},{"batb":[[0,1.83,204.82],[1,1.81,187.55],[2,1.8,44.02]],"ltp":1.84,"tv":7946.56,"id":9304761}]}]}
{"op":"mcm","clk":"4230393434","pt":1631532471723,"mc":[{"id":"1.187557247","rc":[{"batb":[[0,1.97,3],[1,1.96,5],[2,1.95,4]],"ltp":2.18,"tv":31262.89,"id":10350473},{"batb":[[0,1.79,9.36],[1,1.67,562.86],[2,1.6,39.44]],"batl":[[0,1.9,12.27],[1,2.02,4],[2,2.14,8.25]],"ltp":1.84,"tv":7946.56,"id":9304761}]}]}
{"op":"mcm","clk":"4230393669","pt":1631532474284,"mc":[{"id":"1.187557247","rc":[{"batb":[[1,1.67,725.44],[2,1.66,127.01]],"batl":[[2,2.06,157.36]],"ltp":1.84,"tv":7946.56,"id":9304761}]}]}
{"op":"mcm","clk":"4230394005","pt":1631532478391,"mc":[{"id":"1.187557247","rc":[{"batb":[[0,1.97,29.17]],"ltp":2.18,"tv":31262.89,"id":10350473},{"batl":[[2,2.04,7.63]],"ltp":1.84,"tv":7946.56,"id":9304761}]}]}
{"op":"mcm","clk":"4230394037","pt":1631532478816,"mc":[{"id":"1.187557247","rc":[{"batb":[[0,1.97,3]],"ltp":2.18,"tv":31262.89,"id":10350473},{"batl":[[2,2.06,157.36]],"ltp":1.84,"tv":7946.56,"id":9304761}]}]}
{"op":"mcm","clk":"4230394333","pt":1631532482300,"mc":[{"id":"1.187557247","rc":[{"batb":[[1,1.94,70.79],[2,1.93,368.74]],"ltp":2.18,"tv":31262.89,"id":10350473}]}]}
{"op":"mcm","clk":"4230394613","pt":1631532485618,"mc":[{"id":"1.187557247","rc":[{"batb":[[0,1.97,29.17]],"ltp":2.18,"tv":31262.89,"id":10350473},{"batl":[[2,2.04,8.88]],"ltp":1.84,"tv":7946.56,"id":9304761}]}]}
{"op":"mcm","clk":"4230394696","pt":1631532486396,"mc":[{"id":"1.187557247","rc":[{"batb":[[0,1.97,3]],"ltp":2.18,"tv":31262.89,"id":10350473},{"batb":[[1,1.67,562.86],[2,1.6,39.44]],"batl":[[0,2.14,8.25],[1,2.16,6.97],[2,2.22,7.25]],"ltp":1.84,"tv":7946.56,"id":9304761}]}]}
{"op":"mcm","clk":"4230394886","pt":1631532488621,"mc":[{"id":"1.187557247","rc":[{"batb":[[0,1.98,1830.22],[1,1.79,9.36],[2,1.67,562.86]],"ltp":1.84,"tv":7946.56,"id":9304761}]}]}
{"op":"mcm","clk":"4230394977","pt":1631532489718,"mc":[{"id":"1.187557247","rc":[{"trd":[[1.94,187.23],[1.97,21.18]],"batb":[[0,1.96,4],[1,1.95,116.76],[2,1.94,62.86]],"batl":[[0,2.02,139.07],[1,2.04,348.49],[2,2.5,4.99]],"ltp":1.94,"tv":31284.75,"id":10350473},{"batb":[[0,1.99,124.18],[1,1.96,975.78],[2,1.95,947.06]],"batl":[[0,2.04,4],[1,2.14,8.25],[2,2.16,6.97]],"ltp":1.84,"tv":7946.56,"id":9304761}],"tv":39231.31}]}
{"op":"mcm","clk":"4230395054","pt":1631532490707,"mc":[{"id":"1.187557247","rc":[{"batb":[[0,1.95,116.76],[1,1.94,62.86],[2,1.93,521.26]],"batl":[[2,2.08,57.73]],"ltp":1.94,"tv":31284.75,"id":10350473},{"batl":[[0,2.14,8.25],[1,2.16,6.97],[2,2.22,7.25]],"ltp":1.84,"tv":7946.56,"id":9304761}]}]}
{"op":"mcm","clk":"4230395203","pt":1631532492211,"mc":[{"id":"1.187557247","rc":[{"batl":[[0,2,4],[1,2.02,143.07],[2,2.04,352.49]],"ltp":1.94,"tv":31284.75,"id":10350473},{"batb":[[0,1.99,129.18],[1,1.98,5],[2,1.97,4]],"ltp":1.84,"tv":7946.56,"id":9304761}]}]}
{"op":"mcm","clk":"4230395334","pt":1631532493612,"mc":[{"id":"1.187557247","rc":[{"batb":[[0,1.98,304.13],[1,1.97,59.56],[2,1.96,75.89]],"batl":[[0,1.99,76.49],[1,2,68.95],[2,2.02,143.07]],"ltp":1.94,"tv":31284.75,"id":10350473},{"batb":[[0,2,4],[1,1.99,129.18],[2,1.98,5]],"ltp":1.84,"tv":7946.56,"id":9304761}]}]}
{"op":"mcm","clk":"4230395394","pt":1631532494231,"mc":[{"id":"1.187557247","rc":[{"batl":[[0,2.12,56.69],[1,2.14,8.25],[2,2.16,6.97]],"ltp":1.84,"tv":7946.56,"id":9304761}]}]}
{"op":"mcm","clk":"4230395682","pt":1631532497301,"mc":[{"id":"1.187557247","rc":[{"batl":[[0,2.1,41.25],[1,2.12,56.69],[2,2.14,8.25]],"ltp":1.84,"tv":7946.56,"id":9304761}]}]}
{"op":"mcm","clk":"4230395755","pt":1631532498132,"mc":[{"id":"1.187557247","rc":[{"batb":[[0,1.98,101.38],[1,1.97,212.39]],"batl":[[0,1.99,26.06]],"ltp":1.94,"tv":31284.75,"id":10350473}]}]}
{"op":"mcm","clk":"4230395915","pt":1631532499640,"mc":[{"id":"1.187557247","rc":[{"batl":[[0,2.14,8.25],[1,2.16,6.97],[2,2.22,7.25]],"ltp":1.84,"tv":7946.56,"id":9304761}]}]}
{"op":"mcm","clk":"4230395971","pt":1631532500347,"mc":[{"id":"1.187557247","rc":[{"trd":[[1.99,305.58]],"batb":[[0,1.98,243.38]],"batl":[[0,1.99,21.06]],"ltp":1.99,"tv":31294.75,"id":10350473}],"tv":39241.31}]}
{"op":"mcm","clk":"4230396077","pt":1631532501409,"mc":[{"id":"1.187557247","rc":[{"trd":[[1.99,347.7]],"batb":[[0,1.99,18.94],[1,1.98,243.38],[2,1.97,212.39]],"batl":[[0,2,68.95],[1,2.02,143.07],[2,2.04,352.49]],"ltp":1.99,"tv":31336.87,"id":10350473}],"tv":39283.43}]}
{"op":"mcm","clk":"4230396191","pt":1631532502619,"mc":[{"id":"1.187557247","rc":[{"trd":[[2,1.54]],"batb":[[0,2,3.23]],"batl":[[0,2.1,57.2],[1,2.14,234.84],[2,2.16,6.97]],"ltp":2.0,"tv":7948.1,"id":9304761}],"tv":39284.97}]}
{"op":"mcm","clk":"4230396266","pt":1631532503630,"mc":[{"id":"1.187557247","rc":[{"batb":[[1,1.99,124.18],[2,1.97,4]],"ltp":2.0,"tv":7948.1,"id":9304761}]}]}
{"op":"mcm","clk":"4230396358","pt":1631532504541,"mc":[{"id":"1.187557247","rc":[{"batb":[[0,1.99,21.26]],"batl":[[1,2.02,139.07],[2,2.04,348.49]],"ltp":1.99,"tv":31336.87,"id":10350473},{"batb":[[2,1.96,975.78]],"ltp":2.0,"tv":7948.1,"id":9304761}]}]}
{"op":"mcm","clk":"4230396466","pt":1631532505648,"mc":[{"id":"1.187557247","rc":[{"batl":[[0,2.08,41.25],[1,2.1,57.2],[2,2.14,8.25]],"ltp":2.0,"tv":7948.1,"id":9304761}]}]}
{"op":"mcm","clk":"4230396485","pt":1631532505963,"mc":[{"id":"1.187557247","rc":[{"trd":[[2,68.95]],"batl":[[0,2.02,139.07],[1,2.04,348.49],[2,2.06,58.27]],"ltp":2.0,"tv":31405.82,"id":10350473},{"trd":[[1.99,109.76],[2,76.95]],"batb":[[0,1.99,69.3],[1,1.96,975.78],[2,1.95,1008.61]],"ltp":1.99,"tv":8133.27,"id":9304761}],"tv":39539.09}]}
{"op":"mcm","clk":"4230396685","pt":1631532508557,"mc":[{"id":"1.187557247","rc":[{"batb":[[0,1.99,23.59]],"ltp":2.0,"tv":31405.82,"id":10350473}]}]}
{"op":"mcm","clk":"4230396863","pt":1631532510746,"mc":[{"id":"1.187557247","rc":[{"batb":[[1,1.95,61.55],[2,1.82,11.84]],"ltp":1.99,"tv":8133.27,"id":9304761}]}]}
{"op":"mcm","clk":"4230396892","pt":1631532511055,"mc":[{"id":"1.187557247","rc":[{"batl":[[0,2.04,216.97],[1,2.06,58.27],[2,2.28,7.34]],"ltp":2.0,"tv":31405.82,"id":10350473},{"batb":[[0,1.95,61.55],[1,1.82,11.84],[2,1.81,83.6]],"batl":[[0,2.1,57.2],[1,2.32,6.11],[2,2.5,278.33]],"ltp":1.99,"tv":8133.27,"id":9304761}]}]}
{"op":"mcm","clk":"4230397004","pt":1631532512451,"mc":[{"id":"1.187557247","rc":[{"batb":[[1,1.93,368.74],[2,1.92,13.24]],"batl":[[1,2.28,7.34],[2,2.42,6.25]],"ltp":2.0,"tv":31405.82,"id":10350473},{"batb":[[0,1.82,11.84],[1,1.81,83.6],[2,1.79,32.31]],"batl":[[0,2.32,6.11],[1,2.5,278.33],[2,2.54,5.75]],"ltp":1.99,"tv":8133.27,"id":9304761}]}]}
{"op":"mcm","clk":"4230397198","pt":1631532514621,"mc":[{"id":"1.187557247","rc":[{"batb":[[2,1.89,500]],"batl":[[1,2.24,120.82],[2,2.26,98.55]],"ltp":2.0,"tv":31405.82,"id":10350473},{"batb":[[1,1.8,84.52]],"ltp":1.99,"tv":8133.27,"id":9304761}]}]}
{"op":"mcm","clk":"4230397253","pt":1631532515447,"mc":[{"id":"1.187557247","rc":[{"batl":[[0,2.42,6.25],[1,2.5,4.99],[2,2.26,0]],"ltp":2.0,"tv":31405.82,"id":10350473},{"batb":[[2,1.71,33.19]],"ltp":1.99,"tv":8133.27,"id":9304761}]}]}
{"op":"mcm","clk":"4230397341","pt":1631532516334,"mc":[{"id":"1.187557247","rc":[{"batl":[[1,2.54,5.75],[2,3.45,53.16]],"ltp":1.99,"tv":8133.27,"id":9304761}]}]}
{"op":"mcm","clk":"4230397456","pt":1631532517730,"mc":[{"id":"1.187557247","rc":[{"trd":[[1.99,394.88]],"batb":[[0,1.93,368.74],[1,1.89,500],[2,1.76,129.88]],"batl":[[0,1.98,112.69],[1,2.42,6.25],[2,2.5,4.99]],"ltp":1.99,"tv":31453.0,"id":10350473}],"tv":39586.28}]}
{"op":"mcm","clk":"4230397479","pt":1631532518039,"mc":[{"id":"1.187557247","rc":[{"batb":[[1,1.91,132.21],[2,1.89,662.74]],"batl":[[0,1.98,150.01],[1,2,139.35],[2,2.42,6.25]],"ltp":1.99,"tv":31453.0,"id":10350473}]}]}
{"op":"mcm","clk":"4230397582","pt":1631532519533,"mc":[{"id":"1.187557247","rc":[{"batl":[[2,2.18,263.4]],"ltp":1.99,"tv":31453.0,"id":10350473},{"batb":[[0,1.84,59.2],[1,1.82,11.84],[2,1.8,84.52]],"batl":[[0,2.3,30.55],[1,2.32,6.11],[2,2.54,5.75]],"ltp":1.99,"tv":8133.27,"id":9304761}]}]}
{"op":"mcm","clk":"4230397722","pt":1631532521443,"mc":[{"id":"1.187557247","rc":[{"trd":[[1.98,781.23]],"batl":[[0,1.98,132.36]],"ltp":1.98,"tv":31488.3,"id":10350473}],"tv":39621.58}]}
{"op":"mcm","clk":"4230397965","pt":1631532524548,"mc":[{"id":"1.187557247","rc":[{"batb":[[1,1.89,500],[2,1.76,129.88]],"batl":[[0,2.18,232.15],[1,2.28,6.59],[2,2.42,6.25]],"ltp":1.98,"tv":31488.3,"id":10350473}]}]}
{"op":"mcm","clk":"4230398223","pt":1631532527454,"mc":[{"id":"1.187557247","rc":[{"batb":[[0,1.89,500],[1,1.77,124.51]],"batl":[[0,2.16,96.1],[1,2.18,232.15],[2,2.24,112.15]],"ltp":1.98,"tv":31488.3,"id":10350473}]}]}
{"op":"mcm","clk":"4230398292","pt":1631532528593,"mc":[{"id":"1.187557247","rc":[{"batb":[[0,1.77,124.51],[1,1.76,129.88],[2,1.75,208.41]],"batl":[[2,2.28,6.59]],"ltp":1.98,"tv":31488.3,"id":10350473}]}]}
{"op":"mcm","clk":"4230398355","pt":1631532529366,"mc":[{"id":"1.187557247","rc":[{"batl":[[2,2.28,0]],"ltp":1.98,"tv":31488.3,"id":10350473},{"batl":[[0,2.32,6.11],[1,2.54,5.75],[2,2.82,234.95]],"ltp":1.99,"tv":8133.27,"id":9304761}]}]}
{"op":"mcm","clk":"4230398477","pt":1631532530663,"mc":[{"id":"1.187557247","rc":[{"batb":[[0,1.89,30.7],[1,1.77,124.51],[2,1.76,129.88]],"ltp":1.98,"tv":31488.3,"id":10350473}]}]}
{"op":"mcm","clk":"4230398544","pt":1631532531590,"mc":[{"id":"1.187557247","rc":[{"trd":[[1.77,24.24]],"batb":[[0,1.77,112.68],[1,1.76,96.15],[2,1.75,208.41]],"batl":[[0,1.81,2596.68],[1,1.83,185.13],[2,1.85,176.28]],"ltp":1.77,"tv":31511.96,"id":10350473},{"batb":[[0,1.88,638.05],[1,1.84,59.2],[2,1.82,11.84]],"batl":[[0,2.54,5.75],[1,2.82,234.95],[2,3.45,53.16]],"ltp":1.99,"tv":8133.27,"id":9304761}],"tv":39645.24}]}
{"op":"mcm","clk":"4230398633","pt":1631532532677,"mc":[{"id":"1.187557247","rc":[{"batb":[[0,1.77,165.96],[1,1.76,179.13],[2,1.75,82.98]],"ltp":1.77,"tv":31511.96,"id":10350473},{"batb":[[0,2.22,89.87],[1,2,119.41]],"batl":[[1,2.74,7.3],[2,2.82,234.95]],"ltp":1.99,"tv":8133.27,"id":9304761}]}]}
{"op":"mcm","clk":"4230398710","pt":1631532533757,"mc":[{"id":"1.187557247","rc":[{"batl":[[1,1.83,156.59]],"ltp":1.77,"tv":31511.96,"id":10350473},{"batb":[[2,1.71,33.19]],"ltp":1.99,"tv":8133.27,"id":9304761}]}]}
{"op":"mcm","clk":"4230398765","pt":1631532534584,"mc":[{"id":"1.187557247","rc":[{"batb":[[2,1.77,407]],"batl":[[0,2.52,28.75],[1,2.54,5.75],[2,2.74,7.3]],"ltp":1.99,"tv":8133.27,"id":9304761}]}]}
{"op":"mcm","clk":"4230398837","pt":1631532535568,"mc":[{"id":"1.187557247","rc":[{"batb":[[1,2,178.61]],"ltp":1.99,"tv":8133.27,"id":9304761}]}]}
{"op":"mcm","clk":"4230398913","pt":1631532536755,"mc":[{"id":"1.187557247","rc":[{"batb":[[0,1.77,320],[2,1.75,360.68]],"ltp":1.77,"tv":31511.96,"id":10350473},{"batl":[[0,2.34,51.83]],"ltp":1.99,"tv":8133.27,"id":9304761}]}]}
{"op":"mcm","clk":"4230398959","pt":1631532537378,"mc":[{"id":"1.187557247","rc":[{"batl":[[1,1.83,138.75]],"ltp":1.77,"tv":31511.96,"id":10350473}]}]}
{"op":"mcm","clk":"4230399130","pt":1631532539706,"mc":[{"id":"1.187557247","rc":[{"trd":[[1.81,19.64]],"batl":[[0,1.81,2594.36]],"ltp":1.81,"tv":31516.6,"id":10350473},{"batl":[[0,2.34,80.58]],"ltp":1.99,"tv":8133.27,"id":9304761}],"tv":39649.88}]}
{"op":"mcm","clk":"4230399217","pt":1631532540698,"mc":[{"id":"1.187557247","rc":[{"batb":[[0,1.79,527.94],[1,1.77,338.45],[2,1.76,178.63]],"ltp":1.81,"tv":31516.6,"id":10350473},{"batb":[[0,2.2,90.38]],"ltp":1.99,"tv":8133.27,"id":9304761}]}]}
{"op":"mcm","clk":"4230399230","pt":1631532540897,"mc":[{"id":"1.187557247","rc":[{"batb":[[1,2,119.41]],"ltp":1.99,"tv":8133.27,"id":9304761}]}]}
{"op":"mcm","clk":"4230399381","pt":1631532542666,"mc":[{"id":"1.187557247","rc":[{"batb":[[1,2.16,51.72],[2,2,119.41]],"ltp":1.99,"tv":8133.27,"id":9304761}]}]}
{"op":"mcm","clk":"4230399455","pt":1631532543708,"mc":[{"id":"1.187557247","rc":[{"trd":[[1.81,119.64]],"batl":[[0,1.81,2544.36]],"ltp":1.81,"tv":31616.6,"id":10350473}],"tv":39749.88}]}
{"op":"mcm","clk":"4230399529","pt":1631532544589,"mc":[{"id":"1.187557247","rc":[{"batb":[[0,2.2,112.95],[1,2,119.41],[2,1.77,407]],"ltp":1.99,"tv":8133.27,"id":9304761}]}]}
{"op":"mcm","clk":"4230399610","pt":1631532545468,"mc":[{"id":"1.187557247","rc":[{"batb":[[0,1.79,682.94]],"ltp":1.81,"tv":31616.6,"id":10350473}]}]}
{"op":"mcm","clk":"4230399736","pt":1631532547593,"mc":[{"id":"1.187557247","rc":[{"trd":[[1.81,119.8]],"batl":[[0,1.81,2544.28]],"ltp":1.81,"tv":31616.76,"id":10350473}],"tv":39750.04}]}
{"op":"mcm","clk":"4230399829","pt":1631532548677,"mc":[{"id":"1.187557247","rc":[{"batl":[[2,1.85,236.28]],"ltp":1.81,"tv":31616.76,"id":10350473},{"batb":[[1,2.18,50.84],[2,2,119.41]],"ltp":1.99,"tv":8133.27,"id":9304761}]}]}
{"op":"mcm","clk":"4230399967","pt":1631532550388,"mc":[{"id":"1.187557247","rc":[{"trd":[[1.81,119.94]],"batl":[[0,1.81,2544.14]],"ltp":1.81,"tv":31616.9,"id":10350473},{"trd":[[2.22,3.12]],"ltp":2.22,"tv":8133.39,"id":9304761}],"tv":39750.3}]}
{"op":"mcm","clk":"4230400046","pt":1631532551419,"mc":[{"id":"1.187557247","rc":[{"trd":[[1.81,141.94]],"batl":[[0,1.81,2533.14]],"ltp":1.81,"tv":31638.9,"id":10350473}],"tv":39772.3}]}
{"op":"mcm","clk":"4230400268","pt":1631532554520,"mc":[{"id":"1.187557247","rc":[{"trd":[[1.79,4.65]],"batb":[[0,1.79,680.62]],"ltp":1.79,"tv":31643.55,"id":10350473}],"tv":39776.94}]}
{"op":"mcm","clk":"4230400427","pt":1631532556594,"mc":[{"id":"1.187557247","rc":[{"trd":[[1.79,175.01]],"batb":[[0,1.79,595.44]],"ltp":1.79,"tv":31813.91,"id":10350473},{"batl":[[0,2.54,5.75],[1,2.74,7.3],[2,2.82,234.95]],"ltp":2.22,"tv":8133.39,"id":9304761}],"tv":39947.3}]}
{"op":"mcm","clk":"4230400525","pt":1631532557626,"mc":[{"id":"1.187557247","rc":[{"trd":[[1.79,186.98]],"batb":[[0,1.79,589.45]],"ltp":1.79,"tv":31825.89,"id":10350473}],"tv":39959.28}]}
{"op":"mcm","clk":"4230400692","pt":1631532559493,"mc":[{"id":"1.187557247","rc":[{"batl":[[0,2.36,51.44],[1,2.52,28.75],[2,2.54,5.75]],"ltp":2.22,"tv":8133.39,"id":9304761}]}]}
{"op":"mcm","clk":"4230400787","pt":1631532560426,"mc":[{"id":"1.187557247","rc":[{"trd":[[1.79,200]],"batb":[[0,1.79,582.94]],"ltp":1.79,"tv":31838.9,"id":10350473},{"batb":[[0,2.22,89.71],[1,2.2,22.57],[2,2.18,50.84]],"batl":[[1,2.54,5.75],[2,2.74,7.3]],"ltp":2.22,"tv":8133.39,"id":9304761}],"tv":39972.29}]}
{"op":"mcm","clk":"4230401015","pt":1631532562916,"mc":[{"id":"1.187557247","rc":[{"trd":[[1.79,200.01]],"batb":[[0,1.79,582.93]],"ltp":1.79,"tv":31838.92,"id":10350473},{"batl":[[0,2.34,28.75],[1,2.36,51.44],[2,2.54,5.75]],"ltp":2.22,"tv":8133.39,"id":9304761}],"tv":39972.31}]}
{"op":"mcm","clk":"4230401878","pt":1631532575529,"mc":[{"id":"1.187557247","rc":[{"trd":[[1.79,203.92]],"batb":[[0,1.79,580.98]],"ltp":1.79,"tv":31842.82,"id":10350473}],"tv":39976.21}]}
{"op":"mcm","clk":"4230402042","pt":1631532578123,"mc":[{"id":"1.187557247","rc":[{"batb":[[0,1.8,461.6],[1,1.79,580.98],[2,1.77,338.45]],"ltp":1.79,"tv":31842.82,"id":10350473}]}]}
{"op":"mcm","clk":"4230402124","pt":1631532579107,"mc":[{"id":"1.187557247","rc":[{"trd":[[1.81,189.94]],"batl":[[0,1.81,2509.14]],"ltp":1.81,"tv":31890.82,"id":10350473}],"tv":40024.21}]}
{"op":"mcm","clk":"4230402983","pt":1631532590555,"mc":[{"id":"1.187557247","rc":[{"trd":[[1.81,194.59]],"batl":[[0,1.81,2506.82]],"ltp":1.81,"tv":31895.47,"id":10350473}],"tv":40028.86}]}
{"op":"mcm","clk":"4230403375","pt":1631532596432,"mc":[{"id":"1.187557247","rc":[{"trd":[[1.81,1037.13]],"batl":[[0,1.81,2085.55]],"ltp":1.81,"tv":32738.01,"id":10350473}],"tv":40871.4}]}
{"op":"mcm","clk":"4230403764","pt":1631532602337,"mc":[{"id":"1.187557247","rc":[{"trd":[[1.81,5208.23]],"batb":[[0,1.81,1443.86],[1,1.8,461.6],[2,1.79,580.98]],"batl":[[0,1.83,138.75],[1,1.85,236.28],[2,1.86,252.68]],"ltp":1.81,"tv":36909.11,"id":10350473}],"tv":45042.5}]}
{"op":"mcm","clk":"4230403798","pt":1631532602865,"mc":[{"id":"1.187557247","rc":[{"batb":[[1,1.79,580.98],[2,1.77,338.45]],"ltp":1.81,"tv":36909.11,"id":10350473}]}]}
{"op":"mcm","clk":"4230403936","pt":1631532604654,"mc":[{"id":"1.187557247","rc":[{"batb":[[1,1.79,155]],"ltp":1.81,"tv":36909.11,"id":10350473}]}]}
{"op":"mcm","clk":"4230404733","pt":1631532614474,"mc":[{"id":"1.187557247","rc":[{"trd":[[1.82,121.08]],"batb":[[0,1.82,347.1],[1,1.81,1506.36],[2,1.8,67.39]],"batl":[[0,1.83,200.36],[1,1.84,56.85],[2,1.85,236.28]],"ltp":1.82,"tv":37018.53,"id":10350473},{"trd":[[2.22,92.82]],"batb":[[0,2.2,22.57],[1,2.18,50.84],[2,2,119.24]],"ltp":2.22,"tv":8223.09,"id":9304761}],"tv":45241.62}]}
{"op":"mcm","clk":"4230405067","pt":1631532618798,"mc":[{"id":"1.187557247","rc":[{"batb":[[1,1.81,62.5]],"ltp":1.82,"tv":37018.53,"id":10350473}]}]}
{"op":"mcm","clk":"4230405278","pt":1631532621972,"mc":[{"id":"1.187557247","rc":[{"batl":[[1,2.36,58.26],[2,2.44,5.58]],"ltp":2.22,"tv":8223.09,"id":9304761}]}]}
{"op":"mcm","clk":"4230405401","pt":1631532623694,"mc":[{"id":"1.187557247","rc":[{"batb":[[0,1.82,57.85],[1,1.81,178.84],[2,1.8,242.87]],"ltp":1.82,"tv":37018.53,"id":10350473}]}]}
{"op":"mcm","clk":"4230405856","pt":1631532628994,"mc":[{"id":"1.187557247","rc":[{"batb":[[0,2.18,50.84],[1,2,119.24],[2,1.97,25.17]],"batl":[[0,2.36,58.26],[1,2.44,5.58],[2,2.54,5.75]],"ltp":2.22,"tv":8223.09,"id":9304761}]}]}
{"op":"mcm","clk":"4230407215","pt":1631532645720,"mc":[{"id":"1.187557247","rc":[{"trd":[[1.82,149.59]],"batb":[[0,1.82,43.6]],"ltp":1.82,"tv":37047.03,"id":10350473}],"tv":45270.12}]}
{"op":"mcm","clk":"4230407494","pt":1631532649521,"mc":[{"id":"1.187557247","rc":[{"trd":[[1.82,236.3]],"batb":[[0,1.81,179.09],[1,1.8,242.87],[2,1.79,155]],"ltp":1.82,"tv":37133.74,"id":10350473}],"tv":45356.84}]}
{"op":"mcm","clk":"4230407665","pt":1631532651399,"mc":[{"id":"1.187557247","rc":[{"batl":[[0,1.83,61.61],[2,1.85,60]],"ltp":1.82,"tv":37133.74,"id":10350473},{"batl":[[0,2.36,51.44],[1,2.82,234.95],[2,3.45,53.16]],"ltp":2.22,"tv":8223.09,"id":9304761}]}]}
{"op":"mcm","clk":"4230407770","pt":1631532652429,"mc":[{"id":"1.187557247","rc":[{"batb":[[2,1.65,118.91]],"batl":[[2,2.04,8.88]],"ltp":1.82,"tv":37133.74,"id":10350473},{"batb":[[0,2,119.24],[1,1.97,25.17],[2,1.88,25.21]],"batl":[[0,2.82,234.95],[1,3.45,53.16],[2,3.45,0]],"ltp":2.22,"tv":8223.09,"id":9304761}]}]}
{"op":"mcm","clk":"4230407857","pt":1631532653313,"mc":[{"id":"1.187557247","rc":[{"batb":[[2,1.73,33.13]],"ltp":1.82,"tv":37133.74,"id":10350473},{"batl":[[0,2.38,5.75],[1,2.48,6.24],[2,2.82,234.95]],"ltp":2.22,"tv":8223.09,"id":9304761}]}]}
{"op":"mcm","clk":"4230407959","pt":1631532654613,"mc":[{"id":"1.187557247","rc":[{"batb":[[2,1.74,30.02]],"batl":[[2,1.99,136.88]],"ltp":1.82,"tv":37133.74,"id":10350473},{"batl":[[0,2.36,6.57],[1,2.44,5.33],[2,2.48,6.24]],"ltp":2.22,"tv":8223.09,"id":9304761}]}]}
{"op":"mcm","clk":"4230408098","pt":1631532656429,"mc":[{"id":"1.187557247","rc":[{"batb":[[0,1.7,36.82],[1,1.68,36.36],[2,1.67,244.56]],"batl":[[2,2.04,8.88]],"ltp":1.82,"tv":37133.74,"id":10350473},{"batl":[[0,2.44,5.33],[1,2.48,6.24],[2,2.82,234.95]],"ltp":2.22,"tv":8223.09,"id":9304761}]}]}
{"op":"mcm","clk":"4230408248","pt":1631532658299,"mc":[{"id":"1.187557247","rc":[{"batl":[[2,3.45,53.16]],"ltp":2.22,"tv":8223.09,"id":9304761}]}]}
{"op":"mcm","clk":"4230408331","pt":1631532659639,"mc":[{"id":"1.187557247","rc":[{"trd":[[1.7,133.35]],"batb":[[0,1.7,28.4],[1,1.69,4],[2,1.68,36.36]],"batl":[[0,1.72,172.82],[1,1.74,213.71],[2,1.75,1092.86]],"ltp":1.7,"tv":37158.58,"id":10350473},{"batb":[[0,2.02,2941.17],[1,2,119.24],[2,1.97,25.17]],"batl":[[0,2.44,8.33],[2,2.56,410.88]],"ltp":2.22,"tv":8223.09,"id":9304761}],"tv":45381.68}]}
{"op":"mcm","clk":"4230408423","pt":1631532660685,"mc":[{"id":"1.187557247","rc":[{"batb":[[0,1.7,24.4],[1,1.68,36.36],[2,1.67,244.56]],"batl":[[1,1.73,60],[2,1.74,399.64]],"ltp":1.7,"tv":37158.58,"id":10350473},{"batb":[[0,2.38,72.63],[1,2.36,44.11],[2,2.16,95.81]],"batl":[[0,2.44,5.33]],"ltp":2.22,"tv":8223.09,"id":9304761}]}]}
{"op":"mcm","clk":"4230408485","pt":1631532661265,"mc":[{"id":"1.187557247","rc":[{"batl":[[2,1.74,427.53]],"ltp":1.7,"tv":37158.58,"id":10350473}]}]}
{"op":"mcm","clk":"4230408736","pt":1631532663680,"mc":[{"id":"1.187557247","rc":[{"batb":[[0,1.71,308.13],[1,1.7,294.11],[2,1.68,36.36]],"batl":[[0,1.72,242.16],[1,1.73,71.77],[2,1.74,213.71]],"ltp":1.7,"tv":37158.58,"id":10350473}]}]}
{"op":"mcm","clk":"4230408810","pt":1631532664668,"mc":[{"id":"1.187557247","rc":[{"trd":[[1.71,516.94]],"batb":[[0,1.71,275.82],[2,1.69,60.24]],"batl":[[0,1.72,273.89]],"ltp":1.71,"tv":37223.2,"id":10350473},{"batb":[[0,2.38,98.32],[1,2.16,95.81],[2,1.97,25.17]],"ltp":2.22,"tv":8223.09,"id":9304761}],"tv":45446.3}]}
{"op":"mcm","clk":"4230408989","pt":1631532666693,"mc":[{"id":"1.187557247","rc":[{"trd":[[1.71,1068.58]],"batb":[[0,1.7,294.11],[1,1.69,60.24],[2,1.68,36.36]],"batl":[[0,1.71,74.84],[1,1.72,333.89],[2,1.73,71.77]],"ltp":1.71,"tv":37774.84,"id":10350473},{"batb":[[2,2.14,7.82]],"ltp":2.22,"tv":8223.09,"id":9304761}],"tv":45997.94}]}
{"op":"mcm","clk":"4230409058","pt":1631532667569,"mc":[{"id":"1.187557247","rc":[{"batl":[[2,2.54,5.75]],"ltp":2.22,"tv":8223.09,"id":9304761}]}]}
{"op":"mcm","clk":"4230409155","pt":1631532668761,"mc":[{"id":"1.187557247","rc":[{"batb":[[1,1.68,36.36],[2,1.67,244.56]],"batl":[[0,1.72,333.89],[1,1.74,213.71],[2,1.75,1105.25]],"ltp":1.71,"tv":37774.84,"id":10350473},{"batb":[[0,2.4,42.85],[1,2.38,98.32],[2,2.16,95.81]],"ltp":2.22,"tv":8223.09,"id":9304761}]}]}
{"op":"mcm","clk":"4230409219","pt":1631532669693,"mc":[{"id":"1.187557247","rc":[{"batb":[[0,1.7,193],[1,1.66,10.65],[2,1.64,34.57]],"batl":[[0,1.72,60],[1,1.75,12.39],[2,1.87,28.5]],"ltp":1.71,"tv":37774.84,"id":10350473},{"batb":[[1,2.16,95.81],[2,2.14,7.82]],"batl":[[0,2.58,5.44],[1,2.62,5.46],[2,2.68,5.89]],"ltp":2.22,"tv":8223.09,"id":9304761}]}]}
{"op":"mcm","clk":"4230409291","pt":1631532670467,"mc":[{"id":"1.187557247","rc":[{"batb":[[0,1.66,10.65],[1,1.63,24],[2,1.62,39.04]],"batl":[[0,1.71,27.89]],"ltp":1.71,"tv":37774.84,"id":10350473},{"batb":[[0,2.16,95.81],[1,2.14,7.82],[2,2.06,7.08]],"batl":[[0,2.62,5.46],[1,2.64,4.93],[2,3.3,195.03]],"ltp":2.22,"tv":8223.09,"id":9304761}]}]}
{"op":"mcm","clk":"4230409468","pt":1631532672700,"mc":[{"id":"1.187557247","rc":[{"batb":[[1,1.65,36.33],[2,1.63,24]],"batl":[[0,1.75,12.39],[1,1.85,177.5],[2,1.87,198.9]],"ltp":1.71,"tv":37774.84,"id":10350473},{"batl":[[0,2.54,5.75],[1,2.62,5.46],[2,2.64,4.93]],"ltp":2.22,"tv":8223.09,"id":9304761}]}]}
{"op":"mcm","clk":"4230409518","pt":1631532673276,"mc":[{"id":"1.187557247","rc":[{"batb":[[1,1.63,24],[2,1.62,39.04]],"batl":[[0,1.94,28.25],[1,1.95,30.1],[2,2.04,8.88]],"ltp":1.71,"tv":37774.84,"id":10350473},{"batb":[[1,2.06,7.08],[2,2.04,7.37]],"batl":[[0,2.62,5.46],[1,2.64,4.93],[2,3.3,195.03]],"ltp":2.22,"tv":8223.09,"id":9304761}]}]}
{"op":"mcm","clk":"4230409725","pt":1631532675669,"mc":[{"id":"1.187557247","rc":[{"batl":[[0,2.48,4],[1,2.62,5.46],[2,2.64,4.93]],"ltp":2.22,"tv":8223.09,"id":9304761}]}]}
{"op":"mcm","clk":"4230409819","pt":1631532676710,"mc":[{"id":"1.187557247","rc":[{"batb":[[0,1.67,33.14],[1,1.66,10.65],[2,1.65,39.33]],"batl":[[0,1.87,28.5],[1,1.89,124.61],[2,1.94,28.25]],"ltp":1.71,"tv":37774.84,"id":10350473},{"batb":[[0,2.18,84.72],[1,2.16,95.81],[2,2.14,7.32]],"batl":[[0,2.54,5.25],[1,2.6,27.3],[2,2.62,5.46]],"ltp":2.22,"tv":8223.09,"id":9304761}]}]}
{"op":"mcm","clk":"4230409903","pt":1631532677607,"mc":[{"id":"1.187557247","rc":[{"batb":[[0,1.66,10.65],[1,1.63,24],[2,1.62,39.04]],"batl":[[0,1.85,177.5],[1,1.87,170.4]],"ltp":1.71,"tv":37774.84,"id":10350473},{"batb":[[0,2.16,95.81],[1,2.06,7.08],[2,2.04,7.37]],"batl":[[0,2.62,5.46],[1,2.64,4.93],[2,3.3,195.03]],"ltp":2.22,"tv":8223.09,"id":9304761}]}]}
{"op":"mcm","clk":"4230409936","pt":1631532678008,"mc":[{"id":"1.187557247","rc":[{"batl":[[0,2.4,2.56],[1,2.62,5.46],[2,2.64,4.93]],"ltp":2.22,"tv":8223.09,"id":9304761}]}]}
{"op":"mcm","clk":"4230410079","pt":1631532679671,"mc":[{"id":"1.187557247","rc":[{"batb":[[0,1.71,2.32],[1,1.66,10.65],[2,1.63,24]],"ltp":1.71,"tv":37774.84,"id":10350473},{"batl":[[0,2.62,5.46],[1,2.64,4.93],[2,3.3,195.03]],"ltp":2.22,"tv":8223.09,"id":9304761}]}]}
{"op":"mcm","clk":"4230410176","pt":1631532680604,"mc":[{"id":"1.187557247","rc":[{"batl":[[1,1.87,197.9]],"ltp":1.71,"tv":37774.84,"id":10350473},{"batb":[[1,2.14,7.82],[2,2.06,7.08]],"batl":[[0,2.62,6.18]],"ltp":2.22,"tv":8223.09,"id":9304761}]}]}
{"op":"mcm","clk":"4230410681","pt":1631532686515,"mc":[{"id":"1.187557247","rc":[{"batl":[[2,3.45,53.16]],"ltp":2.22,"tv":8223.09,"id":9304761}]}]}
{"op":"mcm","clk":"4230410846","pt":1631532688731,"mc":[{"id":"1.187557247","rc":[{"batb":[[0,1.78,216.41],[1,1.77,1080.52],[2,1.76,1253.42]],"ltp":1.71,"tv":37774.84,"id":10350473},{"batb":[[2,2.12,496.17]],"batl":[[0,2.6,261.96],[1,2.62,5.46],[2,2.64,4.93]],"ltp":2.22,"tv":8223.09,"id":9304761}]}]}
{"op":"mcm","clk":"4230410924","pt":1631532689715,"mc":[{"id":"1.187557247","rc":[{"trd":[[1.78,750.28]],"batb":[[0,1.79,90.54],[1,1.78,204.65],[2,1.77,1080.52]],"batl":[[0,1.85,237.5]],"ltp":1.78,"tv":37798.36,"id":10350473},{"batb":[[0,2.18,50.84],[1,2.16,95.81],[2,2.14,7.82]],"batl":[[0,2.38,51.07],[1,2.5,3.72],[2,2.62,5.46]],"ltp":2.22,"tv":8223.09,"id":9304761}],"tv":46021.46}]}
{"op":"mcm","clk":"4230410967","pt":1631532690284,"mc":[{"id":"1.187557247","rc":[{"batl":[[0,1.85,264.53]],"ltp":1.78,"tv":37798.36,"id":10350473},{"batb":[[1,2.16,125.58]],"ltp":2.22,"tv":8223.09,"id":9304761}]}]}
{"op":"mcm","clk":"4230411172","pt":1631532692612,"mc":[{"id":"1.187557247","rc":[{"trd":[[1.79,208.1],[1.81,5228.23]],"batb":[[0,1.81,52.7],[1,1.8,56.58],[2,1.79,88.45]],"batl":[[0,1.83,57.64],[1,1.84,73.76],[2,1.85,264.53]],"ltp":1.81,"tv":37822.54,"id":10350473}],"tv":46045.64}]}
{"op":"mcm","clk":"4230411244","pt":1631532693492,"mc":[{"id":"1.187557247","rc":[{"batl":[[0,2.36,40.56],[1,2.38,51.07],[2,2.5,3.72]],"ltp":2.22,"tv":8223.09,"id":9304761}]}]}
{"op":"mcm","clk":"4230411334","pt":1631532694634,"mc":[{"id":"1.187557247","rc":[{"batl":[[2,2.42,6.47]],"ltp":2.22,"tv":8223.09,"id":9304761}]}]}
{"op":"mcm","clk":"4230411362","pt":1631532695096,"mc":[{"id":"1.187557247","rc":[{"batl":[[0,2.42,6.47],[1,2.5,3],[2,2.52,5.26]],"ltp":2.22,"tv":8223.09,"id":9304761}]}]}
{"op":"mcm","clk":"4230411502","pt":1631532696698,"mc":[{"id":"1.187557247","rc":[{"batl":[[0,2.4,6.81],[1,2.42,5.75],[2,2.5,8.23]],"ltp":2.22,"tv":8223.09,"id":9304761}]}]}
{"op":"mcm","clk":"4230411530","pt":1631532697109,"mc":[{"id":"1.187557247","rc":[{"batb":[[1,1.8,130.06]],"batl":[[0,1.82,3.31],[1,1.83,62.59],[2,1.84,73.76]],"ltp":1.81,"tv":37822.54,"id":10350473}]}]}
{"op":"mcm","clk":"4230411646","pt":1631532698505,"mc":[{"id":"1.187557247","rc":[{"batl":[[0,2.36,51.44],[1,2.4,6.81],[2,2.42,624.43]],"ltp":2.22,"tv":8223.09,"id":9304761}]}]}
{"op":"mcm","clk":"4230411743","pt":1631532700009,"mc":[{"id":"1.187557247","rc":[{"batb":[[0,1.81,266.7]],"ltp":1.81,"tv":37822.54,"id":10350473}]}]}
{"op":"mcm","clk":"4230411867","pt":1631532701626,"mc":[{"id":"1.187557247","rc":[{"batl":[[0,2.34,40.56],[1,2.36,51.44],[2,2.4,6.81]],"ltp":2.22,"tv":8223.09,"id":9304761}]}]}
{"op":"mcm","clk":"4230412055","pt":1631532703751,"mc":[{"id":"1.187557247","rc":[{"trd":[[1.81,5241.24]],"batb":[[0,1.81,260.19],[2,1.73,13.02]],"ltp":1.81,"tv":37835.55,"id":10350473},{"batb":[[1,1.95,130.71],[2,1.93,26.36]],"batl":[[0,2.36,51.44],[1,2.42,6.47],[2,2.5,8.23]],"ltp":2.22,"tv":8223.09,"id":9304761}],"tv":46058.65}]}
{"op":"mcm","clk":"4230412118","pt":1631532704522,"mc":[{"id":"1.187557247","rc":[{"batb":[[0,1.73,13.02],[1,1.71,2.32],[2,1.66,151.01]],"batl":[[0,1.85,60],[1,1.93,11.06],[2,2.08,7.94]],"ltp":1.81,"tv":37835.55,"id":10350473},{"batl":[[0,2.5,3.72],[1,2.52,5.26],[2,2.62,5.46]],"ltp":2.22,"tv":8223.09,"id":9304761}]}]}
{"op":"mcm","clk":"4230412195","pt":1631532705457,"mc":[{"id":"1.187557247","rc":[{"batl":[[0,1.93,11.06],[1,2.08,7.94],[2,2.14,7.75]],"ltp":1.81,"tv":37835.55,"id":10350473},{"batb":[[0,1.95,130.71],[1,1.93,26.36],[2,1.88,25.21]],"ltp":2.22,"tv":8223.09,"id":9304761}]}]}
{"op":"mcm","clk":"4230412307","pt":1631532706754,"mc":[{"id":"1.187557247","rc":[{"batb":[[2,1.66,358.62]],"batl":[[1,2.04,173.55],[2,2.06,128.19]],"ltp":1.81,"tv":37835.55,"id":10350473}]}]}
{"op":"mcm","clk":"4230412387","pt":1631532707739,"mc":[{"id":"1.187557247","rc":[{"batb":[[1,1.71,39.51]],"ltp":1.81,"tv":37835.55,"id":10350473},{"batl":[[0,2.42,5.97],[1,2.5,3],[2,2.52,5.26]],"ltp":2.22,"tv":8223.09,"id":9304761}]}]}
{"op":"mcm","clk":"4230412483","pt":1631532708725,"mc":[{"id":"1.187557247","rc":[{"batb":[[0,1.71,2.32],[1,1.66,358.62],[2,1.65,128]],"batl":[[1,2.08,7.94],[2,2.14,7.75]],"ltp":1.81,"tv":37835.55,"id":10350473},{"batl":[[0,2.5,3.72],[1,2.52,5.26],[2,2.62,5.46]],"ltp":2.22,"tv":8223.09,"id":9304761}]}]}
{"op":"mcm","clk":"4230412649","pt":1631532710737,"mc":[{"id":"1.187557247","rc":[{"batl":[[0,1.72,6.04],[1,1.93,11.06],[2,2.08,7.94]],"ltp":1.81,"tv":37835.55,"id":10350473}]}]}
{"op":"mcm","clk":"4230412727","pt":1631532711716,"mc":[{"id":"1.187557247","rc":[{"trd":[[1.71,1093.42]],"batb":[[0,1.66,358.62],[1,1.65,128],[2,1.63,1197.32]],"batl":[[0,1.72,216.72],[1,1.73,1105.48],[2,1.74,1286.39]],"ltp":1.71,"tv":37860.4,"id":10350473},{"batb":[[0,2.3,2],[1,1.95,130.71],[2,1.93,26.36]],"batl":[[0,2.52,5.98],[1,2.62,5.46],[2,2.64,4.93]],"ltp":2.22,"tv":8223.09,"id":9304761}],"tv":46083.5}]}
{"op":"mcm","clk":"4230412802","pt":1631532712648,"mc":[{"id":"1.187557247","rc":[{"trd":[[2.4,1.44]],"batb":[[0,2.4,71.66],[1,2.3,2],[2,2.14,97.82]],"batl":[[0,2.52,5.26]],"ltp":2.4,"tv":8224.53,"id":9304761}],"tv":46084.94}]}
{"op":"mcm","clk":"4230412880","pt":1631532713631,"mc":[{"id":"1.187557247","rc":[{"batb":[[1,2.38,43.47],[2,2.3,2]],"batl":[[1,2.62,52.6]],"ltp":2.4,"tv":8224.53,"id":9304761}]}]}
{"op":"mcm","clk":"4230413038","pt":1631532715752,"mc":[{"id":"1.187557247","rc":[{"batb":[[0,1.68,60.84],[1,1.66,358.62],[2,1.65,128]],"batl":[[0,1.69,17.68],[1,1.7,61.32],[2,1.72,216.72]],"ltp":1.71,"tv":37860.4,"id":10350473}]}]}
{"op":"mcm","clk":"4230413113","pt":1631532716755,"mc":[{"id":"1.187557247","rc":[{"batb":[[1,1.67,80.47],[2,1.66,358.62]],"batl":[[2,1.71,67.01]],"ltp":1.71,"tv":37860.4,"id":10350473}]}]}
{"op":"mcm","clk":"4230413193","pt":1631532717737,"mc":[{"id":"1.187557247","rc":[{"batb":[[1,2.3,2],[2,2.16,111.62]],"ltp":2.4,"tv":8224.53,"id":9304761}]}]}
{"op":"mcm","clk":"4230413251","pt":1631532718561,"mc":[{"id":"1.187557247","rc":[{"batb":[[2,2.18,6.36]],"batl":[[1,2.58,5.44],[2,2.62,52.6]],"ltp":2.4,"tv":8224.53,"id":9304761}]}]}
{"op":"mcm","clk":"4230413352","pt":1631532719646,"mc":[{"id":"1.187557247","rc":[{"batb":[[1,1.67,312.62]],"ltp":1.71,"tv":37860.4,"id":10350473}]}]}
{"op":"mcm","clk":"4230413432","pt":1631532720736,"mc":[{"id":"1.187557247","rc":[{"batb":[[0,1.68,57.88],[1,1.67,374.3]],"batl":[[0,1.69,5.89],[1,1.7,70.11],[2,1.71,195.14]],"ltp":1.71,"tv":37860.4,"id":10350473},{"batb":[[0,2.4,114.51]],"ltp":2.4,"tv":8224.53,"id":9304761}]}]}
{"op":"mcm","clk":"4230413447","pt":1631532720944,"mc":[{"id":"1.187557247","rc":[{"batb":[[1,1.67,312.62]],"batl":[[2,1.71,127.01]],"ltp":1.71,"tv":37860.4,"id":10350473}]}]}
{"op":"mcm","clk":"4230413593","pt":1631532722654,"mc":[{"id":"1.187557247","rc":[{"batb":[[2,1.66,324.34]],"ltp":1.71,"tv":37860.4,"id":10350473},{"batb":[[1,2.18,6.36],[2,2.14,97.82]],"batl":[[0,2.62,47.14],[1,2.64,4.93],[2,2.68,4.39]],"ltp":2.4,"tv":8224.53,"id":9304761}]}]}
{"op":"mcm","clk":"4230413682","pt":1631532723642,"mc":[{"id":"1.187557247","rc":[{"trd":[[1.69,195.13],[1.7,139.67]],"batb":[[2,1.64,11.56]],"batl":[[0,1.7,63.79],[1,1.71,127.01],[2,1.72,232.15]],"ltp":1.7,"tv":37872.61,"id":10350473},{"trd":[[2.42,27.84],[2.44,6.4]],"batb":[[0,2.4,42.85]],"ltp":2.42,"tv":8233.05,"id":9304761}],"tv":46105.67}]}
{"op":"mcm","clk":"4230413739","pt":1631532724460,"mc":[{"id":"1.187557247","rc":[{"batl":[[1,1.71,67.01]],"ltp":1.7,"tv":37872.61,"id":10350473},{"batb":[[0,2.18,6.36],[1,2.14,97.82],[2,2.1,8.84]],"batl":[[0,2.64,4.93],[1,2.68,4.39],[2,2.76,4.77]],"ltp":2.42,"tv":8233.05,"id":9304761}]}]}
{"op":"mcm","clk":"4230413834","pt":1631532725752,"mc":[{"id":"1.187557247","rc":[{"trd":[[1.7,152.64]],"batl":[[0,1.7,50.82]],"ltp":1.7,"tv":37885.59,"id":10350473},{"trd":[[2.42,36.95]],"ltp":2.42,"tv":8242.16,"id":9304761}],"tv":46127.75}]}
{"op":"mcm","clk":"4230414390","pt":1631532732675,"mc":[{"id":"1.187557247","rc":[{"batl":[[0,1.84,30.03],[1,1.86,140.97],[2,1.88,167.78]],"ltp":1.7,"tv":37885.59,"id":10350473}]}]}
{"op":"mcm","clk":"4230414416","pt":1631532732986,"mc":[{"id":"1.187557247","rc":[{"batl":[[0,1.86,140.97],[1,1.88,167.78],[2,1.9,23.85]],"ltp":1.7,"tv":37885.59,"id":10350473},{"batb":[[0,2.14,97.82],[1,2.1,8.84],[2,2.08,7.56]],"ltp":2.42,"tv":8242.16,"id":9304761}]}]}
{"op":"mcm","clk":"4230414516","pt":1631532734481,"mc":[{"id":"1.187557247","rc":[{"batl":[[0,2.64,5.65]],"ltp":2.42,"tv":8242.16,"id":9304761}]}]}
{"op":"mcm","clk":"4230414599","pt":1631532735672,"mc":[{"id":"1.187557247","rc":[{"batb":[[0,1.82,216.97],[1,1.8,144.63],[2,1.79,216.97]],"batl":[[2,1.89,556.55]],"ltp":1.7,"tv":37885.59,"id":10350473},{"batl":[[1,2.68,11.85]],"ltp":2.42,"tv":8242.16,"id":9304761}]}]}
{"op":"mcm","clk":"4230414688","pt":1631532736661,"mc":[{"id":"1.187557247","rc":[{"trd":[[1.82,259.7]],"batb":[[0,1.82,205.27],[1,1.8,233.58]],"batl":[[0,1.86,200.97]],"ltp":1.82,"tv":37908.99,"id":10350473},{"batb":[[0,2.16,51.72],[1,2.14,125.05],[2,2.1,8.84]],"batl":[[0,2.38,51.07],[1,2.52,25.37],[2,2.64,4.93]],"ltp":2.42,"tv":8242.16,"id":9304761}],"tv":46151.15}]}
{"op":"mcm","clk":"4230414771","pt":1631532737696,"mc":[{"id":"1.187557247","rc":[{"batl":[[1,2.46,4.72]],"ltp":2.42,"tv":8242.16,"id":9304761}]}]}
{"op":"mcm","clk":"4230414923","pt":1631532739562,"mc":[{"id":"1.187557247","rc":[{"batb":[[0,1.84,7],[1,1.83,55.56],[2,1.82,205.27]],"batl":[[0,1.85,66.28],[1,1.86,277.84],[2,1.88,167.78]],"ltp":1.82,"tv":37908.99,"id":10350473}]}]}
{"op":"mcm","clk":"4230415035","pt":1631532740654,"mc":[{"id":"1.187557247","rc":[{"trd":[[1.84,9.74]],"batb":[[0,1.84,2.13],[2,1.82,261.02]],"batl":[[2,1.87,64.04]],"ltp":1.84,"tv":37918.73,"id":10350473},{"batl":[[0,2.36,50.36],[1,2.38,51.07],[2,2.46,4.72]],"ltp":2.42,"tv":8242.16,"id":9304761}],"tv":46160.9}]}
{"op":"mcm","clk":"4230415099","pt":1631532741583,"mc":[{"id":"1.187557247","rc":[{"batl":[[1,2.38,1169.51]],"ltp":2.42,"tv":8242.16,"id":9304761}]}]}
{"op":"mcm","clk":"4230415153","pt":1631532742256,"mc":[{"id":"1.187557247","rc":[{"trd":[[1.83,479.31],[1.84,14]],"batb":[[0,1.83,7.69],[1,1.82,261.02],[2,1.81,72.42]],"ltp":1.83,"tv":38018.73,"id":10350473},{"batl":[[1,2.38,1118.44],[2,2.44,6.8]],"ltp":2.42,"tv":8242.16,"id":9304761}],"tv":46260.9}]}
{"op":"mcm","clk":"4230415272","pt":1631532743757,"mc":[{"id":"1.187557247","rc":[{"trd":[[1.83,483.96]],"batb":[[0,1.83,5.37]],"ltp":1.83,"tv":38023.38,"id":10350473}],"tv":46265.55}]}
{"op":"mcm","clk":"4230415307","pt":1631532744276,"mc":[{"id":"1.187557247","rc":[{"batb":[[0,1.83,76.8],[1,1.82,205.27],[2,1.8,233.58]],"batl":[[1,1.86,200.97],[2,1.88,167.78]],"ltp":1.83,"tv":38023.38,"id":10350473}]}]}
{"op":"mcm","clk":"4230415393","pt":1631532745360,"mc":[{"id":"1.187557247","rc":[{"batb":[[0,1.84,220],[1,1.83,76.8],[2,1.82,205.27]],"ltp":1.83,"tv":38023.38,"id":10350473},{"batl":[[0,2.34,51.83],[1,2.44,6.8],[2,2.46,4]],"ltp":2.42,"tv":8242.16,"id":9304761}]}]}
{"op":"mcm","clk":"4230415681","pt":1631532748598,"mc":[{"id":"1.187557247","rc":[{"batl":[[0,2.32,50.36],[1,2.34,135.22],[2,2.44,6.08]],"ltp":2.42,"tv":8242.16,"id":9304761}]}]}
{"op":"mcm","clk":"4230415890","pt":1631532751292,"mc":[{"id":"1.187557247","rc":[{"batl":[[1,1.86,60],[2,1.89,9.35]],"ltp":1.83,"tv":38023.38,"id":10350473},{"batb":[[1,1.9,98.59],[2,1.88,25.21]],"batl":[[0,2.34,51.83],[1,2.44,6.08],[2,2.6,4.66]],"ltp":2.42,"tv":8242.16,"id":9304761}]}]}
{"op":"mcm","clk":"4230416003","pt":1631532752490,"mc":[{"id":"1.187557247","rc":[{"batb":[[0,1.82,205.27],[1,1.79,227.32],[2,1.7,39.82]],"batl":[[0,1.89,9.35],[1,2.12,7.46],[2,2.14,7.75]],"ltp":1.83,"tv":38023.38,"id":10350473},{"batb":[[0,1.9,98.59],[1,1.88,25.21],[2,1.86,403.32]],"batl":[[0,2.44,6.08],[1,2.6,4.66],[2,2.64,4.93]],"ltp":2.42,"tv":8242.16,"id":9304761}]}]}
{"op":"mcm","clk":"4230416086","pt":1631532753372,"mc":[{"id":"1.187557247","rc":[{"batb":[[1,1.79,10.35]],"ltp":1.83,"tv":38023.38,"id":10350473}]}]}
{"op":"mcm","clk":"4230416199","pt":1631532754673,"mc":[{"id":"1.187557247","rc":[{"batl":[[1,2.12,203.55],[2,2.14,122.91]],"ltp":1.83,"tv":38023.38,"id":10350473}]}]}
{"op":"mcm","clk":"4230416424","pt":1631532757316,"mc":[{"id":"1.187557247","rc":[{"batb":[[0,1.79,10.35],[1,1.7,39.82],[2,1.64,354.13]],"ltp":1.83,"tv":38023.38,"id":10350473}]}]}
{"op":"mcm","clk":"4230416805","pt":1631532761197,"mc":[{"id":"1.187557247","rc":[{"batb":[[2,1.64,121.76]],"batl":[[0,2.2,6.98],[1,2.22,6.75],[2,2.26,6.75]],"ltp":1.83,"tv":38023.38,"id":10350473},{"batb":[[0,1.9,71.63],[1,1.86,403.32],[2,1.84,29.72]],"ltp":2.42,"tv":8242.16,"id":9304761}]}]}
{"op":"mcm","clk":"4230417061","pt":1631532763694,"mc":[{"id":"1.187557247","rc":[{"batb":[[1,1.85,2067.56],[2,1.84,2036.48]],"batl":[[0,1.98,1931.82],[1,1.99,1875],[2,2,1875]],"ltp":2.42,"tv":8242.16,"id":9304761}]}]}
{"op":"mcm","clk":"4230417163","pt":1631532764681,"mc":[{"id":"1.187557247","rc":[{"trd":[[2.02,75.65]],"batb":[[0,2,216.97],[1,1.79,10.35],[2,1.7,39.82]],"ltp":2.02,"tv":38033.96,"id":10350473},{"trd":[[1.97,38.66]],"batb":[[0,1.9,232.04],[1,1.88,166.41],[2,1.85,1033.78]],"batl":[[0,1.97,122.19],[1,1.98,965.92],[2,1.99,1079.89]],"ltp":1.97,"tv":8253.01,"id":9304761}],"tv":46286.98}]}
{"op":"mcm","clk":"4230417235","pt":1631532765405,"mc":[{"id":"1.187557247","rc":[{"batb":[[0,2.04,122.51],[1,2,216.97],[2,1.92,62.55]],"batl":[[0,2.08,57.73],[1,2.2,6.98],[2,2.22,6.75]],"ltp":2.02,"tv":38033.96,"id":10350473},{"batb":[[0,1.91,62.89],[1,1.9,232.04],[2,1.88,166.41]],"ltp":1.97,"tv":8253.01,"id":9304761}]}]}
{"op":"mcm","clk":"4230417364","pt":1631532766715,"mc":[{"id":"1.187557247","rc":[{"batl":[[1,2.18,34.9],[2,2.2,6.98]],"ltp":2.02,"tv":38033.96,"id":10350473}]}]}
{"op":"mcm","clk":"4230417567","pt":1631532768648,"mc":[{"id":"1.187557247","rc":[{"batb":[[0,1.93,108.26],[1,1.92,69.68],[2,1.91,62.89]],"batl":[[0,1.94,58.43],[1,1.95,68.63],[2,1.97,122.19]],"ltp":1.97,"tv":8253.01,"id":9304761}]}]}
{"op":"mcm","clk":"4230417612","pt":1631532769213,"mc":[{"id":"1.187557247","rc":[{"trd":[[2.06,159.19]],"batb":[[2,1.85,51.75]],"ltp":2.06,"tv":38034.05,"id":10350473},{"trd":[[1.94,1238.87]],"batb":[[2,1.91,118.97]],"batl":[[0,1.94,58.33],[2,1.97,182.74]],"ltp":1.94,"tv":8253.11,"id":9304761}],"tv":46287.17}]}
{"op":"mcm","clk":"4230417883","pt":1631532771718,"mc":[{"id":"1.187557247","rc":[{"batb":[[2,1.85,78.92]],"ltp":2.06,"tv":38034.05,"id":10350473},{"batl":[[0,1.94,171.33]],"ltp":1.94,"tv":8253.11,"id":9304761}]}]}
{"op":"mcm","clk":"4230417983","pt":1631532772702,"mc":[{"id":"1.187557247","rc":[{"batb":[[2,1.86,9.11]],"ltp":2.06,"tv":38034.05,"id":10350473},{"batb":[[0,1.93,132.11],[1,1.92,127.71]],"batl":[[0,1.94,147.64],[2,1.96,62.48]],"ltp":1.94,"tv":8253.11,"id":9304761}]}]}
{"op":"mcm","clk":"4230418032","pt":1631532773224,"mc":[{"id":"1.187557247","rc":[{"batb":[[2,1.85,78.92]],"batl":[[0,2.18,34.9],[1,2.2,6.98],[2,2.22,6.75]],"ltp":2.06,"tv":38034.05,"id":10350473},{"batb":[[0,1.91,62.89],[1,1.9,232.04],[2,1.89,12.46]],"batl":[[0,1.94,113],[1,1.97,122.19],[2,1.98,965.92]],"ltp":1.94,"tv":8253.11,"id":9304761}]}]}
{"op":"mcm","clk":"4230418324","pt":1631532776708,"mc":[{"id":"1.187557247","rc":[{"batl":[[0,2.12,56.69]],"ltp":2.06,"tv":38034.05,"id":10350473},{"trd":[[1.94,1240.42]],"batl":[[0,1.94,112.23]],"ltp":1.94,"tv":8254.66,"id":9304761}],"tv":46288.71}]}
{"op":"mcm","clk":"4230418329","pt":1631532776811,"mc":[{"id":"1.187557247","rc":[{"trd":[[2.06,209.19]],"ltp":2.06,"tv":38084.05,"id":10350473},{"trd":[[1.94,1293.51]],"batl":[[0,1.94,59.14]],"ltp":1.94,"tv":8307.75,"id":9304761}],"tv":46391.8}]}
{"op":"mcm","clk":"4230418466","pt":1631532778524,"mc":[{"id":"1.187557247","rc":[{"trd":[[2.06,221.19]],"ltp":2.06,"tv":38096.05,"id":10350473},{"trd":[[1.94,1306.25]],"batl":[[0,1.94,46.4]],"ltp":1.94,"tv":8320.49,"id":9304761}],"tv":46416.54}]}
{"op":"mcm","clk":"4230418538","pt":1631532779410,"mc":[{"id":"1.187557247","rc":[{"batl":[[0,2.12,91.59]],"ltp":2.06,"tv":38096.05,"id":10350473}]}]}
{"op":"mcm","clk":"4230418599","pt":1631532780236,"mc":[{"id":"1.187557247","rc":[{"trd":[[2.06,222.09]],"ltp":2.06,"tv":38096.95,"id":10350473},{"trd":[[1.94,1307.21]],"batl":[[0,1.94,45.44]],"ltp":1.94,"tv":8321.45,"id":9304761}],"tv":46418.4}]}
{"op":"mcm","clk":"4230418716","pt":1631532781650,"mc":[{"id":"1.187557247","rc":[{"batb":[[0,2,216.97],[1,1.85,27.17],[2,1.84,29.72]],"batl":[[0,2.12,56.69],[1,2.6,6.01],[2,3,4.6]],"ltp":2.06,"tv":38096.95,"id":10350473},{"trd":[[1.94,1311.85]],"batb":[[1,1.89,12.46],[2,1.67,414.63]],"batl":[[0,1.94,43.12],[1,2.18,7.75],[2,2.2,5.83]],"ltp":1.94,"tv":8326.09,"id":9304761}],"tv":46423.05}]}
{"op":"mcm","clk":"4230418802","pt":1631532782433,"mc":[{"id":"1.187557247","rc":[{"batl":[[0,2.6,6.01],[1,3,4.6],[2,3.05,4.1]],"ltp":2.06,"tv":38096.95,"id":10350473},{"batb":[[0,1.89,12.46],[1,1.67,414.63],[2,1.66,112.05]],"batl":[[0,2.18,7.75],[1,2.2,5.83],[2,2.26,3]],"ltp":1.94,"tv":8326.09,"id":9304761}]}]}
{"op":"mcm","clk":"4230419018","pt":1631532784720,"mc":[{"id":"1.187557247","rc":[{"batb":[[0,1.94,2.32],[1,1.89,12.46],[2,1.67,617.93]],"batl":[[2,2.24,101.77]],"ltp":1.94,"tv":8326.09,"id":9304761}]}]}
{"op":"mcm","clk":"4230419102","pt":1631532785654,"mc":[{"id":"1.187557247","rc":[{"batb":[[1,1.67,617.93],[2,1.66,238.81]],"ltp":1.94,"tv":8326.09,"id":9304761}]}]}
{"op":"mcm","clk":"4230419167","pt":1631532786435,"mc":[{"id":"1.187557247","rc":[{"batb":[[1,1.67,414.63],[2,1.66,112.05]],"batl":[[2,2.26,3]],"ltp":1.94,"tv":8326.09,"id":9304761}]}]}
{"op":"mcm","clk":"4230419293","pt":1631532787740,"mc":[{"id":"1.187557247","rc":[{"batb":[[0,2.04,19.87],[1,2,216.97],[2,1.85,27.17]],"batl":[[0,2.14,21.25],[1,2.6,6.01],[2,3,4.6]],"ltp":2.06,"tv":38096.95,"id":10350473},{"batl":[[0,1.97,18.83],[1,2.18,7.75],[2,2.2,5.83]],"ltp":1.94,"tv":8326.09,"id":9304761}]}]}
{"op":"mcm","clk":"4230419323","pt":1631532788055,"mc":[{"id":"1.187557247","rc":[{"batb":[[0,2,216.97],[1,1.85,27.17],[2,1.84,29.72]],"batl":[[0,2.6,6.01],[1,3,4.6],[2,3.05,4.1]],"ltp":2.06,"tv":38096.95,"id":10350473},{"trd":[[1.94,1316.5]],"batb":[[0,1.67,414.63],[1,1.66,112.05],[2,1.63,42.23]],"batl":[[0,2.18,7.75],[1,2.2,5.83],[2,2.26,3]],"ltp":1.94,"tv":8330.74,"id":9304761}],"tv":46427.7}]}
{"op":"mcm","clk":"4230419439","pt":1631532789354,"mc":[{"id":"1.187557247","rc":[{"batb":[[0,2.1,232.15],[1,2.02,51.7],[2,2,216.97]],"batl":[[0,2.42,30.05],[1,2.6,6.01],[2,3,4.6]],"ltp":2.06,"tv":38096.95,"id":10350473},{"batb":[[0,1.85,166.67],[1,1.83,181.75],[2,1.67,414.63]],"batl":[[0,1.92,166.37],[1,1.94,154],[2,2.12,38.75]],"ltp":1.94,"tv":8330.74,"id":9304761}]}]}
{"op":"mcm","clk":"4230419603","pt":1631532791018,"mc":[{"id":"1.187557247","rc":[{"batb":[[2,1.7,134.69]],"ltp":1.94,"tv":8330.74,"id":9304761}]}]}
{"op":"mcm","clk":"4230419800","pt":1631532793250,"mc":[{"id":"1.187557247","rc":[{"batb":[[1,2,216.97],[2,1.85,27.17]],"batl":[[0,2.6,6.01],[1,3,4.6],[2,3.05,4.1]],"ltp":2.06,"tv":38096.95,"id":10350473},{"batb":[[0,1.67,414.63],[1,1.66,112.05],[2,1.64,9.14]],"batl":[[0,2.18,7.75],[1,2.2,5.83],[2,2.26,3]],"ltp":1.94,"tv":8330.74,"id":9304761}]}]}
{"op":"mcm","clk":"4230419902","pt":1631532794542,"mc":[{"id":"1.187557247","rc":[{"batb":[[1,1.85,27.17],[2,1.84,29.72]],"ltp":2.06,"tv":38096.95,"id":10350473}]}]}
{"op":"mcm","clk":"4230420037","pt":1631532796163,"mc":[{"id":"1.187557247","rc":[{"batb":[[0,1.67,617.93],[1,1.66,238.81]],"batl":[[2,2.24,101.77]],"ltp":1.94,"tv":8330.74,"id":9304761}]}]}
{"op":"mcm","clk":"4230420409","pt":1631532800464,"mc":[{"id":"1.187557247","rc":[{"batb":[[0,1.8,93.62],[1,1.77,31.37],[2,1.76,33.98]],"ltp":2.06,"tv":38096.95,"id":10350473},{"batl":[[0,2.24,101.77],[1,2.26,100.99],[2,2.3,6.85]],"ltp":1.94,"tv":8330.74,"id":9304761}]}]}
{"op":"mcm","clk":"4230420682","pt":1631532803727,"mc":[{"id":"1.187557247","rc":[{"batb":[[0,1.85,29.77],[1,1.8,93.62],[2,1.79,4]],"ltp":2.06,"tv":38096.95,"id":10350473},{"batl":[[0,2.18,7.25],[1,2.24,105.77],[2,2.26,100.99]],"ltp":1.94,"tv":8330.74,"id":9304761}]}]}
{"op":"mcm","clk":"4230420710","pt":1631532804037,"mc":[{"id":"1.187557247","rc":[{"batb":[[0,1.8,93.62],[1,1.79,4],[2,1.77,31.37]],"ltp":2.06,"tv":38096.95,"id":10350473},{"batl":[[0,2.24,105.77],[1,2.26,100.99],[2,2.3,6.85]],"ltp":1.94,"tv":8330.74,"id":9304761}]}]}
{"op":"mcm","clk":"4230421193","pt":1631532810662,"mc":[{"id":"1.187557247","rc":[{"batb":[[0,1.85,30.97],[1,1.8,93.62],[2,1.79,4]],"ltp":2.06,"tv":38096.95,"id":10350473},{"batl":[[0,2.18,8.25],[1,2.24,105.77],[2,2.26,100.99]],"ltp":1.94,"tv":8330.74,"id":9304761}]}]}
{"op":"mcm","clk":"4230421211","pt":1631532810869,"mc":[{"id":"1.187557247","rc":[{"batb":[[0,1.8,93.62],[1,1.79,4],[2,1.77,31.37]],"ltp":2.06,"tv":38096.95,"id":10350473},{"batl":[[0,2.24,105.77],[1,2.26,100.99],[2,2.3,6.85]],"ltp":1.94,"tv":8330.74,"id":9304761}]}]}
{"op":"mcm","clk":"4230421359","pt":1631532812749,"mc":[{"id":"1.187557247","rc":[{"batb":[[2,1.63,42.23]],"batl":[[0,2.24,4],[1,2.26,3]],"ltp":1.94,"tv":8330.74,"id":9304761}]}]}
{"op":"mcm","clk":"4230421412","pt":1631532813471,"mc":[{"id":"1.187557247","rc":[{"batl":[[2,2.6,261.61]],"ltp":1.94,"tv":8330.74,"id":9304761}]}]}
{"op":"mcm","clk":"4230421595","pt":1631532815755,"mc":[{"id":"1.187557247","rc":[{"batb":[[0,2.36,199.16],[1,2.34,99.58],[2,2.32,316.55]],"ltp":2.06,"tv":38096.95,"id":10350473},{"batb":[[0,1.67,203.3]],"batl":[[0,1.72,2732.56],[1,1.73,219.84],[2,1.75,214.8]],"ltp":1.94,"tv":8330.74,"id":9304761}]}]}
{"op":"mcm","clk":"4230421689","pt":1631532816748,"mc":[{"id":"1.187557247","rc":[{"trd":[[2.38,9.17]],"batb":[[0,2.4,75.81],[1,2.36,199.16],[2,2.34,99.58]],"batl":[[0,2.58,30.05],[1,2.6,6.01],[2,3,4.6]],"ltp":2.38,"tv":38106.12,"id":10350473},{"trd":[[1.72,83.68]],"batb":[[1,1.66,415.77],[2,1.65,88.48]],"batl":[[0,1.72,2719.87]],"ltp":1.72,"tv":8343.43,"id":9304761}],"tv":46449.56}]}
{"op":"mcm","clk":"4230421838","pt":1631532818670,"mc":[{"id":"1.187557247","rc":[{"trd":[[1.72,212.54]],"batl":[[0,1.72,2655.44],[1,1.73,199.54]],"ltp":1.72,"tv":8472.29,"id":9304761}],"tv":46578.42}]}
{"op":"mcm","clk":"4230421995","pt":1631532820748,"mc":[{"id":"1.187557247","rc":[{"batb":[[1,2.36,308.2]],"batl":[[0,2.44,8.73],[1,2.5,48.98],[2,2.58,30.05]],"ltp":2.38,"tv":38106.12,"id":10350473},{"trd":[[1.7,220.93]],"batb":[[0,1.69,117.79],[1,1.68,75.59],[2,1.67,226.81]],"batl":[[0,1.7,56.58],[1,1.71,73.21],[2,1.72,2655.44]],"ltp":1.7,"tv":8476.94,"id":9304761}],"tv":46583.07}]}
{"op":"mcm","clk":"4230422063","pt":1631532821677,"mc":[{"id":"1.187557247","rc":[{"batl":[[1,2.58,30.05],[2,2.6,6.01]],"ltp":2.38,"tv":38106.12,"id":10350473}]}]}
{"op":"mcm","clk":"4230422109","pt":1631532822299,"mc":[{"id":"1.187557247","rc":[{"batb":[[1,1.68,148.35]],"ltp":1.7,"tv":8476.94,"id":9304761}]}]}
{"op":"mcm","clk":"4230422325","pt":1631532824577,"mc":[{"id":"1.187557247","rc":[{"batb":[[0,1.69,157.45],[1,1.68,211.36]],"batl":[[0,1.7,36.87],[1,1.71,133.48]],"ltp":1.7,"tv":8476.94,"id":9304761}]}]}
{"op":"mcm","clk":"4230422367","pt":1631532825047,"mc":[{"id":"1.187557247","rc":[{"batl":[[1,2.46,49.65],[2,2.58,30.05]],"ltp":2.38,"tv":38106.12,"id":10350473},{"batb":[[0,1.69,117.79],[1,1.68,148.35]],"batl":[[1,1.71,73.21]],"ltp":1.7,"tv":8476.94,"id":9304761}]}]}
{"op":"mcm","clk":"4230422594","pt":1631532827699,"mc":[{"id":"1.187557247","rc":[{"batl":[[0,1.7,203.87]],"ltp":1.7,"tv":8476.94,"id":9304761}]}]}
{"op":"mcm","clk":"4230423304","pt":1631532836712,"mc":[{"id":"1.187557247","rc":[{"trd":[[2.42,9.96]],"batb":[[1,2.24,4],[2,2.22,6.34]],"batl":[[2,2.6,6.01]],"ltp":2.42,"tv":38112.08,"id":10350473},{"trd":[[1.7,229.42]],"batl":[[0,1.7,195.38],[2,1.73,199.54]],"ltp":1.7,"tv":8485.42,"id":9304761}],"tv":46597.51}]}
{"op":"mcm","clk":"4230423386","pt":1631532837705,"mc":[{"id":"1.187557247","rc":[{"trd":[[2.42,14.96]],"batb":[[0,2.24,4],[1,2.22,10.34],[2,2.2,96.65]],"batl":[[2,2.64,5.43]],"ltp":2.42,"tv":38117.08,"id":10350473},{"trd":[[1.7,236.54]],"batb":[[0,1.68,72.76],[1,1.61,45.09],[2,1.57,58.7]],"batl":[[0,1.7,167],[1,1.74,9.97],[2,1.81,33.5]],"ltp":1.7,"tv":8492.54,"id":9304761}],"tv":46609.63}]}
{"op":"mcm","clk":"4230423473","pt":1631532838694,"mc":[{"id":"1.187557247","rc":[{"trd":[[2.44,1.05]],"batb":[[0,2.22,6.34],[1,2.2,96.65],[2,2.14,8.82]],"batl":[[0,2.44,8.67],[1,2.76,5.27],[2,3,4.6]],"ltp":2.44,"tv":38117.14,"id":10350473},{"trd":[[1.69,731.12]],"batb":[[0,1.57,58.7],[1,1.56,137.74],[2,1.52,430.59]],"batl":[[0,1.74,9.97],[1,1.81,33.5],[2,1.82,29.25]],"ltp":1.69,"tv":8492.62,"id":9304761}],"tv":46609.77}]}
{"op":"mcm","clk":"4230423597","pt":1631532840407,"mc":[{"id":"1.187557247","rc":[{"batb":[[0,1.59,154.94],[1,1.58,153.66],[2,1.57,195.44]],"ltp":1.69,"tv":8492.62,"id":9304761}]}]}
{"op":"mcm","clk":"4230423836","pt":1631532843224,"mc":[{"id":"1.187557247","rc":[{"batb":[[2,1.57,184.3]],"ltp":1.69,"tv":8492.62,"id":9304761}]}]}
{"op":"mcm","clk":"4230423953","pt":1631532844627,"mc":[{"id":"1.187557247","rc":[{"batl":[[0,2.76,5.27],[1,3,4.6],[2,3.05,4.1]],"ltp":2.44,"tv":38117.14,"id":10350473},{"batl":[[0,1.64,2091.48],[1,1.74,9.97],[2,1.81,33.5]],"ltp":1.69,"tv":8492.62,"id":9304761}]}]}
{"op":"mcm","clk":"4230424023","pt":1631532845622,"mc":[{"id":"1.187557247","rc":[{"batl":[[0,2.42,19.52],[1,2.64,5.68],[2,2.76,5.27]],"ltp":2.44,"tv":38117.14,"id":10350473},{"batb":[[0,1.61,37.09],[1,1.59,154.94],[2,1.58,153.66]],"batl":[[0,1.74,9.97],[1,1.81,33.5],[2,1.82,29.25]],"ltp":1.69,"tv":8492.62,"id":9304761}]}]}
{"op":"mcm","clk":"4230424117","pt":1631532846722,"mc":[{"id":"1.187557247","rc":[{"trd":[[2.42,54.01]],"batb":[[0,2.54,752.94],[1,2.52,730.82],[2,2.5,730.82]],"batl":[[0,2.76,5.27],[1,2.78,378.37],[2,2.8,367.25]],"ltp":2.42,"tv":38156.18,"id":10350473},{"batb":[[0,1.59,154.94],[1,1.58,153.66],[2,1.57,184.3]],"batl":[[0,1.64,253.56],[1,1.65,130.48],[2,1.74,9.97]],"ltp":1.69,"tv":8492.62,"id":9304761}],"tv":46648.81}]}
{"op":"mcm","clk":"4230424214","pt":1631532847712,"mc":[{"id":"1.187557247","rc":[{"trd":[[2.62,17.24]],"batb":[[0,2.62,51.71],[1,2.54,752.94],[2,2.52,730.82]],"batl":[[0,2.74,17.55],[1,2.76,5.27],[2,2.78,378.37]],"ltp":2.62,"tv":38173.42,"id":10350473},{"batl":[[2,1.73,49.85]],"ltp":1.69,"tv":8492.62,"id":9304761}],"tv":46666.05}]}
{"op":"mcm","clk":"4230424309","pt":1631532848702,"mc":[{"id":"1.187557247","rc":[{"trd":[[2.62,17.56]],"batb":[[0,2.62,51.39]],"ltp":2.62,"tv":38173.75,"id":10350473},{"trd":[[1.62,0.52]],"batl":[[2,1.73,4]],"ltp":1.62,"tv":8493.15,"id":9304761}],"tv":46666.9}]}
{"op":"mcm","clk":"4230424376","pt":1631532849634,"mc":[{"id":"1.187557247","rc":[{"batb":[[2,1.57,2575.29]],"ltp":1.62,"tv":8493.15,"id":9304761}]}]}
{"op":"mcm","clk":"4230424455","pt":1631532850415,"mc":[{"id":"1.187557247","rc":[{"batb":[[0,1.61,155.61],[1,1.6,69.32],[2,1.59,154.94]],"batl":[[0,1.62,57],[1,1.63,58.89],[2,1.64,253.56]],"ltp":1.62,"tv":8493.15,"id":9304761}]}]}
{"op":"mcm","clk":"4230424567","pt":1631532851718,"mc":[{"id":"1.187557247","rc":[{"trd":[[2.62,50.74]],"batb":[[0,2.62,34.8]],"batl":[[0,2.68,46.29],[1,2.74,17.55],[2,2.76,5.27]],"ltp":2.62,"tv":38206.93,"id":10350473},{"batb":[[2,1.59,233.05]],"batl":[[2,1.64,303.41]],"ltp":1.62,"tv":8493.15,"id":9304761}],"tv":46700.08}]}
{"op":"mcm","clk":"4230424637","pt":1631532852539,"mc":[{"id":"1.187557247","rc":[{"trd":[[2.62,71.66]],"batb":[[0,2.62,24.34]],"ltp":2.62,"tv":38227.85,"id":10350473}],"tv":46721.0}]}
{"op":"mcm","clk":"4230424855","pt":1631532854730,"mc":[{"id":"1.187557247","rc":[{"batb":[[1,2.46,5.51],[2,2.44,5.92]],"ltp":2.62,"tv":38227.85,"id":10350473}]}]}
{"op":"mcm","clk":"4230424935","pt":1631532855658,"mc":[{"id":"1.187557247","rc":[{"batb":[[0,2.4,76.82],[1,2.36,7.18],[2,2.22,6.34]],"batl":[[1,2.9,4.25],[2,3,4.6]],"ltp":2.62,"tv":38227.85,"id":10350473},{"batb":[[0,1.59,78.11],[1,1.53,49.33],[2,1.51,12.16]],"batl":[[0,1.68,9.31],[1,1.69,60],[2,1.73,33.5]],"ltp":1.62,"tv":8493.15,"id":9304761}]}]}
{"op":"mcm","clk":"4230425002","pt":1631532856442,"mc":[{"id":"1.187557247","rc":[{"batl":[[0,2.9,4.25],[1,3,4.6],[2,3.05,4.1]],"ltp":2.62,"tv":38227.85,"id":10350473},{"batb":[[0,1.62,2.32]],"batl":[[1,1.73,33.5],[2,1.81,33.5]],"ltp":1.62,"tv":8493.15,"id":9304761}]}]}
{"op":"mcm","clk":"4230425208","pt":1631532858526,"mc":[{"id":"1.187557247","rc":[{"batb":[[0,2.38,77.66]],"batl":[[0,3,4.6],[1,3.05,4.1],[2,3.05,0]],"ltp":2.62,"tv":38227.85,"id":10350473},{"trd":[[1.62,5.17]],"batb":[[0,1.51,292.6],[1,1.5,241.92],[2,1.49,219.03]],"batl":[[1,1.73,174.24],[2,1.75,215.04]],"ltp":1.62,"tv":8497.79,"id":9304761}],"tv":46725.64}]}
{"op":"mcm","clk":"4230425317","pt":1631532859728,"mc":[{"id":"1.187557247","rc":[{"batl":[[0,3.05,4.1],[1,3.05,0]],"ltp":2.62,"tv":38227.85,"id":10350473},{"batb":[[0,1.51,12.16],[1,1.49,219.03],[2,1.44,441.39]],"batl":[[0,1.73,33.5],[1,1.81,33.5],[2,1.82,29.25]],"ltp":1.62,"tv":8497.79,"id":9304761}]}]}
{"op":"mcm","clk":"4230425327","pt":1631532859831,"mc":[{"id":"1.187557247","rc":[{"batl":[[0,1.61,141.18],[1,1.73,33.5],[2,1.81,33.5]],"ltp":1.62,"tv":8497.79,"id":9304761}]}]}
{"op":"mcm","clk":"4230425566","pt":1631532862632,"mc":[{"id":"1.187557247","rc":[{"trd":[[2.52,20]],"ltp":2.52,"tv":38247.85,"id":10350473},{"trd":[[1.61,282.36],[1.65,30.55]],"batb":[[0,1.6,263.21],[1,1.59,150.43],[2,1.51,12.16]],"batl":[[0,1.65,106.26],[1,1.66,128.08],[2,1.73,33.5]],"ltp":1.65,"tv":8810.7,"id":9304761}],"tv":47058.55}]}
{"op":"mcm","clk":"4230425659","pt":1631532863764,"mc":[{"id":"1.187557247","rc":[{"batb":[[0,1.6,146.44],[1,1.51,12.16],[2,1.49,219.03]],"batl":[[0,1.66,128.08],[1,1.73,33.5],[2,1.81,33.5]],"ltp":1.65,"tv":8810.7,"id":9304761}]}]}
{"op":"mcm","clk":"4230425725","pt":1631532864550,"mc":[{"id":"1.187557247","rc":[{"batb":[[0,2.4,57.4],[1,2.38,77.66],[2,2.36,7.18]],"batl":[[0,3,20.5],[1,3.05,4.1]],"ltp":2.52,"tv":38247.85,"id":10350473},{"batb":[[1,1.52,60.8],[2,1.51,12.16]],"batl":[[1,1.72,10.3],[2,1.73,33.5]],"ltp":1.65,"tv":8810.7,"id":9304761}]}]}
{"op":"mcm","clk":"4230425811","pt":1631532865748,"mc":[{"id":"1.187557247","rc":[{"batb":[[0,2.44,5.67]],"batl":[[0,3.05,4.1],[1,3.05,0]],"ltp":2.52,"tv":38247.85,"id":10350473},{"batb":[[0,1.51,12.16],[1,1.49,219.03],[2,1.44,441.39]],"batl":[[0,1.69,39.5]],"ltp":1.65,"tv":8810.7,"id":9304761}]}]}
{"op":"mcm","clk":"4230425892","pt":1631532866736,"mc":[{"id":"1.187557247","rc":[{"batb":[[0,2.38,77.66],[1,2.36,7.18],[2,2.22,6.34]],"ltp":2.52,"tv":38247.85,"id":10350473},{"batl":[[0,1.72,10.3],[1,1.73,33.5],[2,1.81,33.5]],"ltp":1.65,"tv":8810.7,"id":9304761}]}]}
{"op":"mcm","clk":"4230426064","pt":1631532868756,"mc":[{"id":"1.187557247","rc":[{"batb":[[0,1.61,1.45],[1,1.51,12.16],[2,1.49,219.03]],"ltp":1.65,"tv":8810.7,"id":9304761}]}]}
{"op":"mcm","clk":"4230426121","pt":1631532869436,"mc":[{"id":"1.187557247","rc":[{"batb":[[2,2.14,8.82]],"ltp":2.52,"tv":38247.85,"id":10350473},{"batl":[[0,1.73,33.5],[1,1.87,32.5],[2,1.88,29.29]],"ltp":1.65,"tv":8810.7,"id":9304761}]}]}
{"op":"mcm","clk":"4230426297","pt":1631532871675,"mc":[{"id":"1.187557247","rc":[{"trd":[[2.38,27.51]],"batb":[[0,2.38,68.49],[2,2.3,1663.04]],"batl":[[0,2.54,2.38],[1,3.05,4.1]],"ltp":2.38,"tv":38266.19,"id":10350473},{"batb":[[0,1.68,2963.18],[1,1.65,2328.71],[2,1.64,2250]],"ltp":1.65,"tv":8810.7,"id":9304761}],"tv":47076.89}]}
{"op":"mcm","clk":"4230426386","pt":1631532872669,"mc":[{"id":"1.187557247","rc":[{"batb":[[2,2.3,457.34]],"ltp":2.38,"tv":38266.19,"id":10350473},{"batb":[[0,1.68,197.09],[1,1.67,109.62],[2,1.66,254.64]],"batl":[[0,1.73,167.78],[1,1.75,215.07],[2,1.87,32.5]],"ltp":1.65,"tv":8810.7,"id":9304761}]}]}
{"op":"mcm","clk":"4230426470","pt":1631532873561,"mc":[{"id":"1.187557247","rc":[{"batl":[[0,2.5,48.98],[1,2.54,2.38],[2,2.78,20.5]],"ltp":2.38,"tv":38266.19,"id":10350473},{"batb":[[1,1.67,182.92]],"batl":[[2,1.79,60]],"ltp":1.65,"tv":8810.7,"id":9304761}]}]}
{"op":"mcm","clk":"4230426571","pt":1631532874766,"mc":[{"id":"1.187557247","rc":[{"batl":[[2,3.05,4.1]],"ltp":2.38,"tv":38266.19,"id":10350473}]}]}
{"op":"mcm","clk":"4230426789","pt":1631532876758,"mc":[{"id":"1.187557247","rc":[{"batb":[[0,1.7,78.11],[1,1.69,66.15],[2,1.68,429.24]],"batl":[[0,1.71,139.19],[1,1.72,64.09],[2,1.73,167.78]],"ltp":1.65,"tv":8810.7,"id":9304761}]}]}
{"op":"mcm","clk":"4230426805","pt":1631532876963,"mc":[{"id":"1.187557247","rc":[{"batl":[[0,2.5,70.24]],"ltp":2.38,"tv":38266.19,"id":10350473}]}]}
{"op":"mcm","clk":"4230427029","pt":1631532879677,"mc":[{"id":"1.187557247","rc":[{"batl":[[2,2.8,4.57]],"ltp":2.38,"tv":38266.19,"id":10350473},{"batb":[[2,1.68,197.09]],"ltp":1.65,"tv":8810.7,"id":9304761}]}]}
{"op":"mcm","clk":"4230427103","pt":1631532880470,"mc":[{"id":"1.187557247","rc":[{"trd":[[1.7,241.19]],"batb":[[0,1.7,75.78],[2,1.68,269.85]],"batl":[[0,1.71,278.19]],"ltp":1.7,"tv":8815.35,"id":9304761}],"tv":47081.54}]}
{"op":"mcm","clk":"4230427227","pt":1631532882286,"mc":[{"id":"1.187557247","rc":[{"trd":[[1.7,251.6]],"batb":[[0,1.7,70.58]],"ltp":1.7,"tv":8825.76,"id":9304761}],"tv":47091.95}]}
{"op":"mcm","clk":"4230427344","pt":1631532883662,"mc":[{"id":"1.187557247","rc":[{"batb":[[0,1.69,132.56],[1,1.68,241.67],[2,1.67,109.62]],"batl":[[0,1.7,58.9],[1,1.71,278.19],[2,1.72,64.09]],"ltp":1.7,"tv":8825.76,"id":9304761}]}]}
{"op":"mcm","clk":"4230427438","pt":1631532884764,"mc":[{"id":"1.187557247","rc":[{"batb":[[0,1.69,66.15]],"batl":[[1,1.71,139],[2,1.73,167.78]],"ltp":1.7,"tv":8825.76,"id":9304761}]}]}
{"op":"mcm","clk":"4230427507","pt":1631532885545,"mc":[{"id":"1.187557247","rc":[{"batb":[[0,2.18,6.47],[1,2.16,102.51],[2,2.14,8.82]],"batl":[[0,2.5,48.98],[1,2.8,4.57],[2,3,3.82]],"ltp":2.38,"tv":38266.19,"id":10350473},{"batb":[[0,1.68,72.76],[1,1.65,232.15],[2,1.57,13.22]],"batl":[[0,1.71,139],[1,1.74,11.64],[2,1.77,232.15]],"ltp":1.7,"tv":8825.76,"id":9304761}]}]}
{"op":"mcm","clk":"4230427565","pt":1631532886383,"mc":[{"id":"1.187557247","rc":[{"batl":[[0,2.8,4.57],[1,3,3.82],[2,3.05,4.1]],"ltp":2.38,"tv":38266.19,"id":10350473},{"batb":[[0,1.65,232.15],[1,1.57,13.22],[2,1.56,420.23]],"batl":[[0,1.74,11.64],[1,1.77,232.15],[2,1.84,29.03]],"ltp":1.7,"tv":8825.76,"id":9304761}]}]}
{"op":"mcm","clk":"4230427668","pt":1631532887582,"mc":[{"id":"1.187557247","rc":[{"batl":[[2,1.83,31.5]],"ltp":1.7,"tv":8825.76,"id":9304761}]}]}
{"op":"mcm","clk":"4230427747","pt":1631532888681,"mc":[{"id":"1.187557247","rc":[{"batb":[[1,1.58,207.75],[2,1.57,170.81]],"batl":[[2,1.84,29.03]],"ltp":1.7,"tv":8825.76,"id":9304761}]}]}
{"op":"mcm","clk":"4230427933","pt":1631532890786,"mc":[{"id":"1.187557247","rc":[{"batl":[[0,2.4,6.51],[1,2.8,4.57],[2,3,3.82]],"ltp":2.38,"tv":38266.19,"id":10350473}]}]}
{"op":"mcm","clk":"4230428083","pt":1631532892559,"mc":[{"id":"1.187557247","rc":[{"batb":[[1,1.57,13.22],[2,1.56,420.23]],"batl":[[0,1.77,232.15],[1,1.84,29.03],[2,1.86,119.01]],"ltp":1.7,"tv":8825.76,"id":9304761}]}]}
{"op":"mcm","clk":"4230428189","pt":1631532893764,"mc":[{"id":"1.187557247","rc":[{"batl":[[0,1.84,29.03],[1,1.86,119.01],[2,1.87,32.5]],"ltp":1.7,"tv":8825.76,"id":9304761}]}]}
{"op":"mcm","clk":"4230428232","pt":1631532894183,"mc":[{"id":"1.187557247","rc":[{"batb":[[0,2.16,102.51],[1,2.14,8.82],[2,2.12,7.29]],"ltp":2.38,"tv":38266.19,"id":10350473},{"batl":[[0,1.86,119.01],[1,1.87,32.5],[2,1.88,199.89]],"ltp":1.7,"tv":8825.76,"id":9304761}]}]}
{"op":"mcm","clk":"4230428359","pt":1631532895578,"mc":[{"id":"1.187557247","rc":[{"trd":[[2.16,105.11]],"batb":[[0,2.16,92.61]],"batl":[[0,2.32,2.61],[1,2.4,6.51],[2,2.8,4.57]],"ltp":2.16,"tv":38285.99,"id":10350473},{"batb":[[0,1.8,2478.55],[1,1.79,216.97],[2,1.78,200.13]],"ltp":1.7,"tv":8825.76,"id":9304761}],"tv":47111.75}]}
{"op":"mcm","clk":"4230428451","pt":1631532896688,"mc":[{"id":"1.187557247","rc":[{"batl":[[0,2.3,52.62],[1,2.32,2.61],[2,2.4,6.51]],"ltp":2.16,"tv":38285.99,"id":10350473},{"batb":[[0,1.8,280.01]],"ltp":1.7,"tv":8825.76,"id":9304761}]}]}
{"op":"mcm","clk":"4230428713","pt":1631532899551,"mc":[{"id":"1.187557247","rc":[{"batb":[[0,1.82,56.5],[1,1.8,280.01],[2,1.79,216.97]],"batl":[[0,1.83,61.77],[1,1.84,78.77],[2,1.86,119.01]],"ltp":1.7,"tv":8825.76,"id":9304761}]}]}
{"op":"mcm","clk":"4230428836","pt":1631532900765,"mc":[{"id":"1.187557247","rc":[{"batb":[[1,2.14,12.82]],"batl":[[0,2.28,32.55],[1,2.3,52.62],[2,2.32,2.61]],"ltp":2.16,"tv":38285.99,"id":10350473},{"batb":[[1,1.81,78.95],[2,1.8,280.01]],"batl":[[2,1.85,73.5]],"ltp":1.7,"tv":8825.76,"id":9304761}]}]}
{"op":"mcm","clk":"4230428847","pt":1631532900872,"mc":[{"id":"1.187557247","rc":[{"batb":[[1,2.14,8.82]],"ltp":2.16,"tv":38285.99,"id":10350473},{"batb":[[2,1.8,350.34]],"ltp":1.7,"tv":8825.76,"id":9304761}]}]}
{"op":"mcm","clk":"4230429264","pt":1631532905534,"mc":[{"id":"1.187557247","rc":[{"batl":[[1,2.32,2.61],[2,2.4,6.51]],"ltp":2.16,"tv":38285.99,"id":10350473}]}]}
{"op":"mcm","clk":"4230429289","pt":1631532905852,"mc":[{"id":"1.187557247","rc":[{"batl":[[0,2.32,2.61],[1,2.4,6.51],[2,2.58,4.75]],"ltp":2.16,"tv":38285.99,"id":10350473}]}]}
{"op":"mcm","clk":"4230429457","pt":1631532907676,"mc":[{"id":"1.187557247","rc":[{"batb":[[0,1.82,46.15],[2,1.8,258.09]],"batl":[[0,1.83,221.59],[1,1.84,109.49]],"ltp":1.7,"tv":8825.76,"id":9304761}]}]}
{"op":"mcm","clk":"4230429472","pt":1631532907894,"mc":[{"id":"1.187557247","rc":[{"batl":[[1,2.58,4.75],[2,2.8,4.57]],"ltp":2.16,"tv":38285.99,"id":10350473}]}]}
{"op":"mcm","clk":"4230429600","pt":1631532909250,"mc":[{"id":"1.187557247","rc":[{"batl":[[0,2.28,53.03],[1,2.32,2.61],[2,2.58,4.75]],"ltp":2.16,"tv":38285.99,"id":10350473}]}]}
{"op":"mcm","clk":"4230429887","pt":1631532912564,"mc":[{"id":"1.187557247","rc":[{"trd":[[2.22,45.99]],"batb":[[0,2.1,54.54],[1,1.98,66.69],[2,1.93,30.93]],"batl":[[1,2.58,4.75],[2,2.8,4.57]],"ltp":2.22,"tv":38291.99,"id":10350473},{"trd":[[1.82,404.4]],"batb":[[0,1.82,38.83],[2,1.79,216.97]],"ltp":1.82,"tv":8833.08,"id":9304761}],"tv":47125.07}]}
{"op":"mcm","clk":"4230429976","pt":1631532913392,"mc":[{"id":"1.187557247","rc":[{"batb":[[0,1.98,66.69],[1,1.93,30.93],[2,1.63,24]],"batl":[[0,2.58,4.75],[1,2.8,4.57],[2,2.82,4.25]],"ltp":2.22,"tv":38291.99,"id":10350473},{"batb":[[0,1.79,216.97],[1,1.68,9.27],[2,1.67,108.37]],"batl":[[0,1.89,232.15],[1,1.95,12.53],[2,1.99,24.5]],"ltp":1.82,"tv":8833.08,"id":9304761}]}]}
{"op":"mcm","clk":"4230430200","pt":1631532915742,"mc":[{"id":"1.187557247","rc":[{"batb":[[1,1.68,226.69]],"ltp":1.82,"tv":8833.08,"id":9304761}]}]}
{"op":"mcm","clk":"4230430243","pt":1631532916269,"mc":[{"id":"1.187557247","rc":[{"batb":[[1,1.68,9.27]],"batl":[[1,1.99,24.5],[2,2.02,4]],"ltp":1.82,"tv":8833.08,"id":9304761}]}]}
{"op":"mcm","clk":"4230430369","pt":1631532917686,"mc":[{"id":"1.187557247","rc":[{"batl":[[0,1.99,24.5],[1,2.02,4],[2,2.08,7.44]],"ltp":1.82,"tv":8833.08,"id":9304761}]}]}
{"op":"mcm","clk":"4230430414","pt":1631532918159,"mc":[{"id":"1.187557247","rc":[{"batl":[[0,2.02,4],[1,2.08,7.44],[2,2.22,3]],"ltp":1.82,"tv":8833.08,"id":9304761}]}]}
{"op":"mcm","clk":"4230430544","pt":1631532919566,"mc":[{"id":"1.187557247","rc":[{"batb":[[0,1.83,142.15],[1,1.81,189.29],[2,1.79,216.97]],"batl":[[0,1.89,125.41],[1,1.91,162.37],[2,2.02,4]],"ltp":1.82,"tv":8833.08,"id":9304761}]}]}
{"op":"mcm","clk":"4230430657","pt":1631532920765,"mc":[{"id":"1.187557247","rc":[{"batb":[[0,1.99,79.5],[1,1.98,66.69],[2,1.93,30.93]],"batl":[[0,2.46,23.75],[1,2.58,4.75],[2,2.8,4.57]],"ltp":2.22,"tv":38291.99,"id":10350473},{"batb":[[2,1.8,41.35]],"batl":[[2,1.98,10.3]],"ltp":1.82,"tv":8833.08,"id":9304761}]}]}
{"op":"mcm","clk":"4230430700","pt":1631532921288,"mc":[{"id":"1.187557247","rc":[{"batb":[[1,1.98,70.69],[2,1.97,4]],"ltp":2.22,"tv":38291.99,"id":10350473},{"batl":[[2,1.96,232.15]],"ltp":1.82,"tv":8833.08,"id":9304761}]}]}
{"op":"mcm","clk":"4230430825","pt":1631532922693,"mc":[{"id":"1.187557247","rc":[{"batb":[[0,1.98,70.69],[1,1.97,4],[2,1.93,30.93]],"batl":[[0,2.58,4.75],[1,2.8,4.57],[2,2.82,4.25]],"ltp":2.22,"tv":38291.99,"id":10350473},{"batb":[[0,1.79,216.97],[1,1.68,9.27],[2,1.67,108.37]],"batl":[[0,1.96,232.15],[1,1.98,10.3],[2,1.99,23.5]],"ltp":1.82,"tv":8833.08,"id":9304761}]}]}
{"op":"mcm","clk":"4230431075","pt":1631532925502,"mc":[{"id":"1.187557247","rc":[{"trd":[[1.79,423.52]],"batb":[[0,1.79,5.21],[1,1.68,226.69]],"ltp":1.79,"tv":9256.59,"id":9304761}],"tv":47548.59}]}
{"op":"mcm","clk":"4230431750","pt":1631532933199,"mc":[{"id":"1.187557247","rc":[{"batb":[[1,1.93,30.93],[2,1.63,24]],"ltp":2.22,"tv":38291.99,"id":10350473}]}]}
{"op":"mcm","clk":"4230432183","pt":1631532937626,"mc":[{"id":"1.187557247","rc":[{"batb":[[0,1.68,226.69],[1,1.67,108.37],[2,1.66,254.86]],"batl":[[0,1.74,1746.9],[2,2.02,148.28]],"ltp":1.79,"tv":9256.59,"id":9304761}]}]}
{"op":"mcm","clk":"4230432289","pt":1631532938721,"mc":[{"id":"1.187557247","rc":[{"batb":[[0,1.68,217.42]],"batl":[[2,2.02,4]],"ltp":1.79,"tv":9256.59,"id":9304761}]}]}
{"op":"mcm","clk":"4230432380","pt":1631532939730,"mc":[{"id":"1.187557247","rc":[{"batb":[[0,2,24.42],[1,1.98,70.69],[2,1.93,30.93]],"ltp":2.22,"tv":38291.99,"id":10350473}]}]}
{"op":"mcm","clk":"4230432457","pt":1631532940620,"mc":[{"id":"1.187557247","rc":[{"batb":[[0,1.98,70.69],[1,1.93,30.93],[2,1.63,24]],"ltp":2.22,"tv":38291.99,"id":10350473},{"batl":[[2,1.99,23.5]],"ltp":1.79,"tv":9256.59,"id":9304761}]}]}
{"op":"mcm","clk":"4230432552","pt":1631532941608,"mc":[{"id":"1.187557247","rc":[{"batl":[[0,1.71,216.97],[1,1.74,1943.17],[2,1.75,1092.86]],"ltp":1.79,"tv":9256.59,"id":9304761}]}]}
{"op":"mcm","clk":"4230432652","pt":1631532942705,"mc":[{"id":"1.187557247","rc":[{"trd":[[2.4,9.26]],"batb":[[0,2.38,78.66],[1,2.24,48.38],[2,2.1,110.29]],"batl":[[0,2.5,48.98],[1,2.58,4.75],[2,2.8,4.57]],"ltp":2.4,"tv":38301.25,"id":10350473},{"trd":[[1.71,17.1]],"batb":[[0,1.68,290.18]],"batl":[[0,1.71,203.97],[1,1.74,196.27]],"ltp":1.71,"tv":9269.59,"id":9304761}],"tv":47570.84}]}
{"op":"mcm","clk":"4230432757","pt":1631532943694,"mc":[{"id":"1.187557247","rc":[{"batb":[[2,2.12,111.08]],"ltp":2.4,"tv":38301.25,"id":10350473}]}]}
{"op":"mcm","clk":"4230432777","pt":1631532943904,"mc":[{"id":"1.187557247","rc":[{"batb":[[1,2.22,3],[2,2.2,4]],"batl":[[0,2.58,4.75],[1,2.8,4.57],[2,2.82,4.25]],"ltp":2.4,"tv":38301.25,"id":10350473},{"batb":[[0,1.68,217.42]],"ltp":1.71,"tv":9269.59,"id":9304761}]}]}
{"op":"mcm","clk":"4230432929","pt":1631532945696,"mc":[{"id":"1.187557247","rc":[{"batb":[[0,1.69,77.43],[1,1.68,217.42],[2,1.67,108.37]],"batl":[[0,1.7,141.3],[1,1.71,203.97],[2,1.74,196.27]],"ltp":1.71,"tv":9269.59,"id":9304761}]}]}
{"op":"mcm","clk":"4230433022","pt":1631532946692,"mc":[{"id":"1.187557247","rc":[{"batb":[[1,1.68,288.22]],"batl":[[1,1.71,273.48]],"ltp":1.71,"tv":9269.59,"id":9304761}]}]}
{"op":"mcm","clk":"4230433120","pt":1631532947739,"mc":[{"id":"1.187557247","rc":[{"batl":[[0,2.54,48.34],[1,2.58,4.75],[2,2.8,4.57]],"ltp":2.4,"tv":38301.25,"id":10350473},{"trd":[[1.7,390.94]],"batb":[[2,1.67,169.96]],"batl":[[0,1.7,71.64],[1,1.71,330.48],[2,1.72,59.86]],"ltp":1.7,"tv":9408.93,"id":9304761}],"tv":47710.18}]}
{"op":"mcm","clk":"4230433297","pt":1631532949718,"mc":[{"id":"1.187557247","rc":[{"trd":[[1.7,395.59]],"batl":[[0,1.7,69.31]],"ltp":1.7,"tv":9413.58,"id":9304761}],"tv":47714.83}]}
{"op":"mcm","clk":"4230433384","pt":1631532950604,"mc":[{"id":"1.187557247","rc":[{"trd":[[2.42,54.15]],"batb":[[1,2.3,46.15],[2,2.22,3]],"ltp":2.42,"tv":38301.39,"id":10350473},{"trd":[[1.68,907.82],[1.69,885.98],[1.7,403.03]],"batb":[[0,1.68,153.89],[1,1.67,169.96],[2,1.66,328.71]],"batl":[[0,1.7,65.49]],"ltp":1.68,"tv":9844.54,"id":9304761}],"tv":48145.93}]}
{"op":"mcm","clk":"4230433541","pt":1631532952430,"mc":[{"id":"1.187557247","rc":[{"trd":[[2.42,56.65]],"ltp":2.42,"tv":38303.89,"id":10350473},{"trd":[[1.7,406.59]],"batl":[[0,1.7,61.93]],"ltp":1.7,"tv":9848.1,"id":9304761}],"tv":48151.99}]}
{"op":"mcm","clk":"4230433661","pt":1631532953730,"mc":[{"id":"1.187557247","rc":[{"trd":[[2.42,61.65]],"batl":[[0,2.52,27.73],[1,2.54,48.34],[2,2.58,4.75]],"ltp":2.42,"tv":38308.89,"id":10350473},{"trd":[[1.7,413.71]],"batb":[[0,1.69,59.18],[1,1.68,83.09],[2,1.67,108.37]],"batl":[[0,1.7,125.49],[1,1.71,260.97],[2,1.73,12.34]],"ltp":1.7,"tv":9855.22,"id":9304761}],"tv":48164.11}]}
{"op":"mcm","clk":"4230433716","pt":1631532954251,"mc":[{"id":"1.187557247","rc":[{"trd":[[1.7,418.36]],"batb":[[1,1.68,131.54]],"batl":[[0,1.7,123.16],[2,1.73,183.41]],"ltp":1.7,"tv":9859.87,"id":9304761}],"tv":48168.76}]}
{"op":"mcm","clk":"4230433836","pt":1631532955711,"mc":[{"id":"1.187557247","rc":[{"batl":[[0,2.9,4.35],[1,3,3.82],[2,3.05,4.1]],"ltp":2.42,"tv":38308.89,"id":10350473},{"batl":[[1,1.71,57]],"ltp":1.7,"tv":9859.87,"id":9304761}]}]}
{"op":"mcm","clk":"4230433911","pt":1631532956665,"mc":[{"id":"1.187557247","rc":[{"batb":[[0,2.3,46.15],[1,2.1,110.29],[2,2.04,7.87]],"ltp":2.42,"tv":38308.89,"id":10350473},{"batb":[[0,1.66,73.85],[1,1.65,232.15],[2,1.57,9.85]],"batl":[[0,1.71,57],[1,1.73,12.34],[2,1.76,60]],"ltp":1.7,"tv":9859.87,"id":9304761}]}]}
{"op":"mcm","clk":"4230434002","pt":1631532957457,"mc":[{"id":"1.187557247","rc":[{"batb":[[0,2.1,110.29],[1,2.04,7.87],[2,2.02,8.74]],"ltp":2.42,"tv":38308.89,"id":10350473},{"batb":[[0,1.65,232.15],[1,1.57,9.85],[2,1.54,146.36]],"batl":[[0,1.73,12.34],[1,1.96,25.87],[2,1.97,26.5]],"ltp":1.7,"tv":9859.87,"id":9304761}]}]}
{"op":"mcm","clk":"4230434230","pt":1631532959454,"mc":[{"id":"1.187557247","rc":[{"batb":[[2,1.55,293.99]],"batl":[[1,1.9,185.59],[2,1.92,159.89]],"ltp":1.7,"tv":9859.87,"id":9304761}]}]}
{"op":"mcm","clk":"4230434341","pt":1631532960658,"mc":[{"id":"1.187557247","rc":[{"batb":[[2,1.63,24]],"batl":[[0,3.25,3.54],[1,3,0],[2,3.05,0]],"ltp":2.42,"tv":38308.89,"id":10350473},{"batb":[[0,1.57,9.85],[1,1.54,146.36],[2,1.52,430.52]],"batl":[[1,1.96,25.87],[2,1.97,26.5]],"ltp":1.7,"tv":9859.87,"id":9304761}]}]}
{"op":"mcm","clk":"4230434384","pt":1631532961236,"mc":[{"id":"1.187557247","rc":[{"batb":[[0,1.71,3.62],[1,1.57,9.85],[2,1.54,146.36]],"ltp":1.7,"tv":9859.87,"id":9304761}]}]}
{"op":"mcm","clk":"4230434641","pt":1631532963751,"mc":[{"id":"1.187557247","rc":[{"batb":[[1,1.68,131.54],[2,1.66,1108.4]],"batl":[[0,1.73,183.41],[1,1.75,215.28],[2,1.96,25.87]],"ltp":1.7,"tv":9859.87,"id":9304761}]}]}
{"op":"mcm","clk":"4230434660","pt":1631532963956,"mc":[{"id":"1.187557247","rc":[{"batb":[[2,1.66,254.87]],"ltp":1.7,"tv":9859.87,"id":9304761}]}]}
{"op":"mcm","clk":"4230434846","pt":1631532966045,"mc":[{"id":"1.187557247","rc":[{"batb":[[0,1.57,9.85],[1,1.54,146.36],[2,1.52,430.52]],"batl":[[0,1.73,12.34],[1,1.96,25.87],[2,1.97,26.5]],"ltp":1.7,"tv":9859.87,"id":9304761}]}]}
{"op":"mcm","clk":"4230434918","pt":1631532967025,"mc":[{"id":"1.187557247","rc":[{"trd":[[2.36,2.6]],"ltp":2.36,"tv":38311.49,"id":10350473},{"trd":[[1.73,799.39]],"batl":[[0,1.73,8.79]],"ltp":1.73,"tv":9863.42,"id":9304761}],"tv":48174.92}]}
{"op":"mcm","clk":"4230435341","pt":1631532971764,"mc":[{"id":"1.187557247","rc":[{"batb":[[1,1.55,293.99],[2,1.54,316.91]],"batl":[[1,1.9,185.59],[2,1.92,159.89]],"ltp":1.73,"tv":9863.42,"id":9304761}]}]}
{"op":"mcm","clk":"4230435512","pt":1631532973854,"mc":[{"id":"1.187557247","rc":[{"batb":[[1,1.54,146.36],[2,1.52,430.52]],"batl":[[1,1.96,25.87],[2,1.97,26.5]],"ltp":1.73,"tv":9863.42,"id":9304761}]}]}
{"op":"mcm","clk":"4230435854","pt":1631532977660,"mc":[{"id":"1.187557247","rc":[{"batb":[[0,2.12,612.14],[1,2.1,110.29],[2,2.04,7.87]],"ltp":2.36,"tv":38311.49,"id":10350473},{"batb":[[0,1.68,131.54],[1,1.66,254.87],[2,1.59,892.55]],"batl":[[0,1.73,179.86],[1,1.75,215.28],[2,1.96,25.87]],"ltp":1.73,"tv":9863.42,"id":9304761}]}]}
{"op":"mcm","clk":"4230436622","pt":1631532985742,"mc":[{"id":"1.187557247","rc":[{"batb":[[0,2.1,110.29],[1,2.04,7.87],[2,1.63,24]],"ltp":2.36,"tv":38311.49,"id":10350473},{"batb":[[0,1.57,9.85],[1,1.54,146.36],[2,1.52,430.52]],"batl":[[0,1.73,8.79],[1,1.96,25.87],[2,1.97,26.5]],"ltp":1.73,"tv":9863.42,"id":9304761}]}]}
{"op":"mcm","clk":"4230436727","pt":1631532986890,"mc":[{"id":"1.187557247","rc":[{"trd":[[1.73,811.1]],"batl":[[0,1.73,2.93]],"ltp":1.73,"tv":9875.14,"id":9304761}],"tv":48186.63}]}
{"op":"mcm","clk":"4230436898","pt":1631532988673,"mc":[{"id":"1.187557247","rc":[{"batb":[[1,1.55,293.99],[2,1.54,316.91]],"batl":[[1,1.9,185.59],[2,1.92,159.89]],"ltp":1.73,"tv":9875.14,"id":9304761}]}]}
{"op":"mcm","clk":"4230437109","pt":1631532990872,"mc":[{"id":"1.187557247","rc":[{"batb":[[1,1.54,146.36],[2,1.52,430.52]],"batl":[[0,1.96,25.87],[1,1.97,26.5],[2,2.22,334.11]],"ltp":1.73,"tv":9875.14,"id":9304761}]}]}
{"op":"mcm","clk":"4230437362","pt":1631532993586,"mc":[{"id":"1.187557247","rc":[{"batl":[[0,2.5,411.97],[1,3.25,3.54]],"ltp":2.36,"tv":38311.49,"id":10350473}]}]}
{"op":"mcm","clk":"4230437444","pt":1631532994384,"mc":[{"id":"1.187557247","rc":[{"batb":[[0,2.1,114.29],[1,2.08,4],[2,2.04,7.87]],"batl":[[0,3.25,3.54],[1,3.25,0]],"ltp":2.36,"tv":38311.49,"id":10350473},{"batb":[[0,1.7,464.84],[1,1.68,244.63],[2,1.57,9.85]],"batl":[[0,1.76,159.37],[1,1.78,203.53],[2,1.91,4]],"ltp":1.73,"tv":9875.14,"id":9304761}]}]}
{"op":"mcm","clk":"4230437533","pt":1631532995464,"mc":[{"id":"1.187557247","rc":[{"batb":[[0,2.12,90.32],[1,2.1,114.29],[2,2.08,4]],"batl":[[0,2.7,17.7],[1,3.25,3.54]],"ltp":2.36,"tv":38311.49,"id":10350473}]}]}
{"op":"mcm","clk":"4230437699","pt":1631532997386,"mc":[{"id":"1.187557247","rc":[{"batb":[[0,2.1,114.29],[1,2.08,4],[2,2.04,7.87]],"batl":[[0,3.25,3.54],[1,3.25,0]],"ltp":2.36,"tv":38311.49,"id":10350473},{"batb":[[0,1.7,232.15],[1,1.57,9.85],[2,1.54,146.36]],"batl":[[0,1.91,4],[1,1.96,25.87],[2,1.97,26.5]],"ltp":1.73,"tv":9875.14,"id":9304761}]}]}
{"op":"mcm","clk":"4230437960","pt":1631533000577,"mc":[{"id":"1.187557247","rc":[{"batb":[[2,1.55,293.99]],"batl":[[0,1.9,190.59],[1,1.91,4],[2,1.92,159.89]],"ltp":1.73,"tv":9875.14,"id":9304761}]}]}
{"op":"mcm","clk":"4230438033","pt":1631533001464,"mc":[{"id":"1.187557247","rc":[{"trd":[[1.7,882.66]],"batb":[[0,1.57,9.85],[1,1.55,293.99],[2,1.54,316.91]],"batl":[[0,1.7,191.38],[1,1.9,190.59],[2,1.91,4]],"ltp":1.7,"tv":10339.44,"id":9304761}],"tv":48650.94}]}
{"op":"mcm","clk":"4230438274","pt":1631533004372,"mc":[{"id":"1.187557247","rc":[{"batb":[[1,1.54,146.36],[2,1.52,430.52]],"ltp":1.7,"tv":10339.44,"id":9304761}]}]}
{"op":"mcm","clk":"4230438500","pt":1631533006678,"mc":[{"id":"1.187557247","rc":[{"trd":[[1.7,1265.42]],"batl":[[0,1.9,190.59],[1,1.91,4],[2,1.92,159.89]],"ltp":1.7,"tv":10722.2,"id":9304761}],"tv":49033.7}]}
{"op":"mcm","clk":"4230438605","pt":1631533007713,"mc":[{"id":"1.187557247","rc":[{"trd":[[2.1,140.51]],"batb":[[0,2.1,100.09],[1,2.04,7.87],[2,1.63,24]],"batl":[[0,2.26,623.89],[1,2.28,311.94],[2,2.3,311.94]],"ltp":2.1,"tv":38331.89,"id":10350473},{"batb":[[0,1.83,164.95],[1,1.82,216.97],[2,1.81,189.51]],"batl":[[0,1.9,185.59],[1,1.92,159.89],[2,1.93,1486.4]],"ltp":1.7,"tv":10722.2,"id":9304761}],"tv":49054.1}]}
{"op":"mcm","clk":"4230438715","pt":1631533008708,"mc":[{"id":"1.187557247","rc":[{"batb":[[2,1.89,76.48]],"ltp":2.1,"tv":38331.89,"id":10350473},{"batb":[[0,1.84,79.33],[1,1.83,164.95],[2,1.82,216.97]],"ltp":1.7,"tv":10722.2,"id":9304761}]}]}
{"op":"mcm","clk":"4230438835","pt":1631533010109,"mc":[{"id":"1.187557247","rc":[{"batb":[[2,2,5]],"ltp":2.1,"tv":38331.89,"id":10350473},{"batl":[[1,1.91,60],[2,1.92,159.89]],"ltp":1.7,"tv":10722.2,"id":9304761}]}]}
{"op":"mcm","clk":"4230438974","pt":1631533011682,"mc":[{"id":"1.187557247","rc":[{"batb":[[0,1.86,75.26],[1,1.84,79.33],[2,1.83,164.95]],"batl":[[0,1.87,48.08],[1,1.88,73.46],[2,1.89,60.56]],"ltp":1.7,"tv":10722.2,"id":9304761}]}]}
{"op":"mcm","clk":"4230439058","pt":1631533012612,"mc":[{"id":"1.187557247","rc":[{"trd":[[2.16,116.59]],"batb":[[0,2.1,154.63]],"ltp":2.16,"tv":38343.37,"id":10350473},{"trd":[[1.83,540.65],[1.84,296.41],[1.85,252.07],[1.86,911.36]],"batb":[[0,1.83,1624.73],[1,1.82,216.97],[2,1.66,110.46]],"ltp":1.83,"tv":11530.15,"id":9304761}],"tv":49873.53}]}
{"op":"mcm","clk":"4230439127","pt":1631533013292,"mc":[{"id":"1.187557247","rc":[{"batl":[[0,2.24,33.67],[1,2.26,623.89],[2,2.28,311.94]],"ltp":2.16,"tv":38343.37,"id":10350473},{"batb":[[0,1.84,70.37],[1,1.83,1624.73],[2,1.82,216.97]],"ltp":1.83,"tv":11530.15,"id":9304761}]}]}
{"op":"mcm","clk":"4230439170","pt":1631533013809,"mc":[{"id":"1.187557247","rc":[{"batb":[[2,1.66,110.46]],"ltp":1.83,"tv":11530.15,"id":9304761}]}]}
{"op":"mcm","clk":"4230439336","pt":1631533015584,"mc":[{"id":"1.187557247","rc":[{"batl":[[2,2.28,364.97]],"ltp":2.16,"tv":38343.37,"id":10350473},{"batb":[[2,1.82,217.08]],"batl":[[0,1.87,189.08],[2,1.89,252.72]],"ltp":1.83,"tv":11530.15,"id":9304761}]}]}
{"op":"mcm","clk":"4230439636","pt":1631533018623,"mc":[{"id":"1.187557247","rc":[{"trd":[[2.14,2.5]],"ltp":2.14,"tv":38345.87,"id":10350473},{"trd":[[1.87,2.86]],"batb":[[0,1.85,2.52],[1,1.84,70.37]],"batl":[[0,1.87,186.22]],"ltp":1.87,"tv":11533.01,"id":9304761}],"tv":49878.89}]}
{"op":"mcm","clk":"4230439744","pt":1631533019717,"mc":[{"id":"1.187557247","rc":[{"trd":[[1.85,273.84],[1.87,8.07]],"batb":[[0,1.84,70.37],[1,1.82,217.08],[2,1.81,9.49]],"batl":[[0,1.85,176.2],[1,1.86,67.64],[2,1.87,141]],"ltp":1.85,"tv":11559.99,"id":9304761}],"tv":49905.87}]}
{"op":"mcm","clk":"4230439883","pt":1631533021296,"mc":[{"id":"1.187557247","rc":[{"trd":[[2.2,9.9]],"ltp":2.2,"tv":38351.87,"id":10350473},{"trd":[[1.84,429.98]],"batb":[[0,1.82,217.08],[1,1.81,9.49],[2,1.8,193.11]],"batl":[[0,1.84,7.39],[1,1.85,176.2],[2,1.86,67.64]],"ltp":1.84,"tv":11693.57,"id":9304761}],"tv":50045.44}]}
{"op":"mcm","clk":"4230440023","pt":1631533022631,"mc":[{"id":"1.187557247","rc":[{"trd":[[1.84,444.76],[1.85,629.06]],"batl":[[0,1.85,15.68],[1,1.86,69.96],[2,1.87,141]],"ltp":1.85,"tv":12063.56,"id":9304761}],"tv":50415.44}]}
{"op":"mcm","clk":"4230440489","pt":1631533026719,"mc":[{"id":"1.187557247","rc":[{"batl":[[1,2.28,53.03],[2,3.25,3.54]],"ltp":2.2,"tv":38351.87,"id":10350473}]}]}
{"op":"mcm","clk":"4230440556","pt":1631533027342,"mc":[{"id":"1.187557247","rc":[{"batb":[[0,2.1,54.54],[1,1.89,76.48],[2,1.63,24]],"batl":[[0,2.28,53.03],[1,3.25,3.54],[2,3.25,0]],"ltp":2.2,"tv":38351.87,"id":10350473},{"batb":[[0,1.81,9.49],[1,1.79,67.5],[2,1.66,110.46]],"batl":[[0,1.84,2.32],[1,1.85,15.68],[2,1.86,2.32]],"ltp":1.85,"tv":12063.56,"id":9304761}]}]}
{"op":"mcm","clk":"4230440682","pt":1631533028448,"mc":[{"id":"1.187557247","rc":[{"batb":[[0,1.89,76.48],[1,1.63,24],[2,1.45,719.75]],"batl":[[0,3.25,3.54],[1,3.25,0]],"ltp":2.2,"tv":38351.87,"id":10350473},{"batb":[[1,1.66,110.46],[2,1.52,430.52]],"ltp":1.85,"tv":12063.56,"id":9304761}]}]}
{"op":"mcm","clk":"4230440879","pt":1631533030632,"mc":[{"id":"1.187557247","rc":[{"batb":[[0,2,4],[1,1.9,75.4],[2,1.63,24]],"ltp":2.2,"tv":38351.87,"id":10350473},{"batb":[[1,1.67,187.4],[2,1.66,238.97]],"ltp":1.85,"tv":12063.56,"id":9304761}]}]}
{"op":"mcm","clk":"4230441139","pt":1631533033035,"mc":[{"id":"1.187557247","rc":[{"batb":[[1,1.66,110.46],[2,1.52,430.52]],"ltp":1.85,"tv":12063.56,"id":9304761}]}]}
{"op":"mcm","clk":"4230441378","pt":1631533035644,"mc":[{"id":"1.187557247","rc":[{"batl":[[0,2.22,458.48],[1,3.25,3.54]],"ltp":2.2,"tv":38351.87,"id":10350473}]}]}
{"op":"mcm","clk":"4230441444","pt":1631533036325,"mc":[{"id":"1.187557247","rc":[{"batl":[[0,3.25,3.54],[1,3.25,0]],"ltp":2.2,"tv":38351.87,"id":10350473},{"trd":[[1.84,449.41],[1.85,660.42],[1.86,916.01]],"batb":[[0,1.86,117.91],[1,1.84,179.61],[2,1.81,9.49]],"batl":[[0,1.92,128],[1,1.94,154.99],[2,2.02,4]],"ltp":1.86,"tv":12104.22,"id":9304761}],"tv":50456.1}]}
{"op":"mcm","clk":"4230441549","pt":1631533037522,"mc":[{"id":"1.187557247","rc":[{"batb":[[0,2.02,20],[1,2,4],[2,1.9,75.4]],"batl":[[0,2.4,17.7],[1,3.25,3.54]],"ltp":2.2,"tv":38351.87,"id":10350473},{"batl":[[1,1.93,11.77],[2,1.94,154.99]],"ltp":1.86,"tv":12104.22,"id":9304761}]}]}
{"op":"mcm","clk":"4230441626","pt":1631533038387,"mc":[{"id":"1.187557247","rc":[{"batl":[[0,3.25,3.54],[1,3.25,0]],"ltp":2.2,"tv":38351.87,"id":10350473},{"batb":[[1,1.84,411.76]],"ltp":1.86,"tv":12104.22,"id":9304761}]}]}
{"op":"mcm","clk":"4230441665","pt":1631533038825,"mc":[{"id":"1.187557247","rc":[{"batb":[[2,1.99,4]],"ltp":2.2,"tv":38351.87,"id":10350473}]}]}
{"op":"mcm","clk":"4230441821","pt":1631533040658,"mc":[{"id":"1.187557247","rc":[{"batb":[[0,2,4],[1,1.99,4],[2,1.9,75.4]],"ltp":2.2,"tv":38351.87,"id":10350473},{"batb":[[0,1.84,232.15],[1,1.81,9.49],[2,1.66,110.46]],"batl":[[0,1.93,11.77],[1,2.02,4],[2,2.22,334.11]],"ltp":1.86,"tv":12104.22,"id":9304761}]}]}
{"op":"mcm","clk":"4230441906","pt":1631533041650,"mc":[{"id":"1.187557247","rc":[{"batl":[[0,2.18,29.4],[1,3.25,3.54]],"ltp":2.2,"tv":38351.87,"id":10350473},{"batb":[[0,1.81,9.49],[1,1.66,110.46],[2,1.52,430.52]],"ltp":1.86,"tv":12104.22,"id":9304761}]}]}
{"op":"mcm","clk":"4230441941","pt":1631533041959,"mc":[{"id":"1.187557247","rc":[{"batl":[[0,3.25,3.54],[1,3.25,0]],"ltp":2.2,"tv":38351.87,"id":10350473}]}]}
{"op":"mcm","clk":"4230442007","pt":1631533042841,"mc":[{"id":"1.187557247","rc":[{"batb":[[1,1.67,187.4],[2,1.66,238.97]],"batl":[[2,2.1,194.27]],"ltp":1.86,"tv":12104.22,"id":9304761}]}]}
{"op":"mcm","clk":"4230442106","pt":1631533044252,"mc":[{"id":"1.187557247","rc":[{"batl":[[0,1.86,352.94],[1,1.93,11.77],[2,2.02,4]],"ltp":1.86,"tv":12104.22,"id":9304761}]}]}
{"op":"mcm","clk":"4230442246","pt":1631533046233,"mc":[{"id":"1.187557247","rc":[{"batl":[[0,1.93,11.77],[1,2.02,4],[2,2.1,194.27]],"ltp":1.86,"tv":12104.22,"id":9304761}]}]}
{"op":"mcm","clk":"4230442351","pt":1631533047532,"mc":[{"id":"1.187557247","rc":[{"trd":[[2,72.95]],"batb":[[0,1.99,4],[1,1.9,75.4],[2,1.63,24]],"ltp":2.0,"tv":38355.87,"id":10350473},{"trd":[[1.93,23.85],[2,80.95]],"batb":[[0,2,1974.49],[1,1.86,111.56],[2,1.81,9.49]],"batl":[[0,2.02,4],[1,2.1,194.27],[2,2.12,118.9]],"ltp":2.0,"tv":12131.77,"id":9304761}],"tv":50487.64}]}
{"op":"mcm","clk":"4230442423","pt":1631533048470,"mc":[{"id":"1.187557247","rc":[{"batb":[[1,1.86,297.49],[2,1.67,187.4]],"batl":[[1,2.22,334.11],[2,3.45,53.16]],"ltp":2.0,"tv":12131.77,"id":9304761}]}]}
{"op":"mcm","clk":"4230442595","pt":1631533050444,"mc":[{"id":"1.187557247","rc":[{"batb":[[1,1.98,4],[2,1.9,75.4]],"ltp":2.0,"tv":38355.87,"id":10350473},{"batb":[[1,1.86,185.93]],"ltp":2.0,"tv":12131.77,"id":9304761}]}]}
{"op":"mcm","clk":"4230442693","pt":1631533051740,"mc":[{"id":"1.187557247","rc":[{"batl":[[0,2.56,410.88],[1,2.58,398.8],[2,2.6,398.8]],"ltp":2.0,"tv":38355.87,"id":10350473},{"trd":[[1.86,1287.87],[2,4029.93]],"batb":[[0,1.67,187.4],[1,1.66,238.97],[2,1.52,430.52]],"batl":[[0,1.72,128.3],[1,1.74,219.88],[2,1.75,1092.86]],"ltp":1.86,"tv":16452.6,"id":9304761}],"tv":54808.48}]}
{"op":"mcm","clk":"4230442783","pt":1631533052696,"mc":[{"id":"1.187557247","rc":[{"trd":[[2.38,36.77]],"batb":[[0,2.4,75.9],[1,2.28,46.87],[2,2.12,107.7]],"batl":[[0,2.54,48.34],[1,2.56,410.88],[2,2.58,398.8]],"ltp":2.38,"tv":38365.13,"id":10350473},{"trd":[[1.72,225.35]],"batb":[[2,1.53,148.2]],"batl":[[0,1.75,1092.86],[1,1.76,530.36],[2,1.77,530.36]],"ltp":1.72,"tv":16465.41,"id":9304761}],"tv":54830.55}]}
{"op":"mcm","clk":"4230442852","pt":1631533053476,"mc":[{"id":"1.187557247","rc":[{"batb":[[2,2.12,127.7]],"ltp":2.38,"tv":38365.13,"id":10350473}]}]}
{"op":"mcm","clk":"4230442960","pt":1631533054765,"mc":[{"id":"1.187557247","rc":[{"batb":[[1,2.12,127.7],[2,2,4]],"batl":[[0,2.56,410.88],[1,2.58,398.8],[2,2.6,398.8]],"ltp":2.38,"tv":38365.13,"id":10350473},{"batb":[[0,1.67,223.13]],"ltp":1.72,"tv":16465.41,"id":9304761}]}]}
{"op":"mcm","clk":"4230443054","pt":1631533055753,"mc":[{"id":"1.187557247","rc":[{"batb":[[0,1.69,62.84],[1,1.68,64.53],[2,1.67,223.13]],"batl":[[0,1.7,78.92],[1,1.71,77.73],[2,1.73,231.95]],"ltp":1.72,"tv":16465.41,"id":9304761}]}]}
{"op":"mcm","clk":"4230443148","pt":1631533056749,"mc":[{"id":"1.187557247","rc":[{"batl":[[0,2.52,30.74],[1,2.56,410.88],[2,2.58,398.8]],"ltp":2.38,"tv":38365.13,"id":10350473},{"batb":[[2,1.67,3103.02]],"ltp":1.72,"tv":16465.41,"id":9304761}]}]}
{"op":"mcm","clk":"4230443217","pt":1631533057468,"mc":[{"id":"1.187557247","rc":[{"batb":[[1,2.12,134.74],[2,2.02,7.24]],"batl":[[0,2.54,48.34]],"ltp":2.38,"tv":38365.13,"id":10350473},{"batb":[[2,1.67,2257.25]],"ltp":1.72,"tv":16465.41,"id":9304761}]}]}
{"op":"mcm","clk":"4230443304","pt":1631533058465,"mc":[{"id":"1.187557247","rc":[{"trd":[[1.7,1423.26]],"batl":[[0,1.71,77.73],[1,1.73,231.95],[2,1.74,66.1]],"ltp":1.7,"tv":16623.25,"id":9304761}],"tv":54988.39}]}
