{"op":"mcm","clk":"4230486326","pt":1631533545620,"mc":[{"id":"1.187557995","rc":[{"batb":[[0,1.29,3.45],[1,1.28,327.69],[2,1.26,99.98]],"batl":[[0,1.4,60.94],[1,1.43,7],[2,1.46,56.25]],"ltp":1.35,"tv":16723.0,"id":9342449},{"batb":[[0,3.5,4.08],[1,3.3,83.84],[2,3.15,3.83]],"batl":[[0,4.9,2.15],[1,5,2.07],[2,4.9,0]],"ltp":3.85,"tv":7350.14,"id":9633869}]}]}
{"op":"mcm","clk":"4230486498","pt":1631533547299,"mc":[{"id":"1.187557995","rc":[{"batb":[[0,1.3,204.28],[1,1.29,385.66],[2,1.28,327.69]],"batl":[[1,1.43,304.75],[2,1.44,219.55]],"ltp":1.35,"tv":16723.0,"id":9342449}]}]}
{"op":"mcm","clk":"4230486641","pt":1631533548617,"mc":[{"id":"1.187557995","rc":[{"batb":[[0,1.29,13.45],[1,1.28,336.69],[2,1.26,99.98]],"batl":[[1,1.43,7],[2,1.82,475.58]],"ltp":1.35,"tv":16723.0,"id":9342449},{"batb":[[0,3.5,6.08],[1,3.45,2],[2,3.3,83.84]],"batl":[[0,4.6,3],[1,4.9,2.15],[2,5,2.07]],"ltp":3.85,"tv":7350.14,"id":9633869}]}]}
{"op":"mcm","clk":"4230486702","pt":1631533549244,"mc":[{"id":"1.187557995","rc":[{"batl":[[0,1.4,64.94]],"ltp":1.35,"tv":16723.0,"id":9342449}]}]}
{"op":"mcm","clk":"4230486805","pt":1631533550443,"mc":[{"id":"1.187557995","rc":[{"batl":[[0,4.4,3],[1,4.6,3],[2,4.9,2.15]],"ltp":3.85,"tv":7350.14,"id":9633869}]}]}
{"op":"mcm","clk":"4230486923","pt":1631533551605,"mc":[{"id":"1.187557995","rc":[{"batb":[[0,1.33,437.07],[1,1.32,340.97],[2,1.29,13.45]],"batl":[[0,1.37,412.12],[1,1.38,264.14],[2,1.4,64.94]],"ltp":1.35,"tv":16723.0,"id":9342449},{"batl":[[1,4.5,3],[2,4.6,3]],"ltp":3.85,"tv":7350.14,"id":9633869}]}]}
{"op":"mcm","clk":"4230487008","pt":1631533552441,"mc":[{"id":"1.187557995","rc":[{"batb":[[2,1.29,101.26]],"batl":[[1,1.38,326.39]],"ltp":1.35,"tv":16723.0,"id":9342449},{"batb":[[0,3.6,3.14],[1,3.5,6.08],[2,3.45,2]],"batl":[[1,4.5,5.35]],"ltp":3.85,"tv":7350.14,"id":9633869}]}]}
{"op":"mcm","clk":"4230487094","pt":1631533553224,"mc":[{"id":"1.187557995","rc":[{"batl":[[2,1.39,67.58]],"ltp":1.35,"tv":16723.0,"id":9342449}]}]}
{"op":"mcm","clk":"4230487358","pt":1631533555634,"mc":[{"id":"1.187557995","rc":[{"batb":[[0,1.29,13.45],[1,1.28,336.69],[2,1.26,99.98]],"batl":[[0,1.36,204.7],[1,1.4,64.94],[2,1.43,7]],"ltp":1.35,"tv":16723.0,"id":9342449},{"batb":[[0,3.5,6.08],[1,3.45,2],[2,3.3,83.84]],"batl":[[1,4.5,3]],"ltp":3.85,"tv":7350.14,"id":9633869}]}]}
{"op":"mcm","clk":"4230487435","pt":1631533556516,"mc":[{"id":"1.187557995","rc":[{"batl":[[0,1.4,64.94],[1,1.43,7],[2,1.82,475.58]],"ltp":1.35,"tv":16723.0,"id":9342449}]}]}
{"op":"mcm","clk":"4230487670","pt":1631533558655,"mc":[{"id":"1.187557995","rc":[{"batb":[[0,1.3,204.28],[1,1.29,488.47],[2,1.28,336.69]],"batl":[[0,1.38,72.25],[1,1.4,64.94],[2,1.43,304.75]],"ltp":1.35,"tv":16723.0,"id":9342449},{"batb":[[0,3.6,2.99],[1,3.5,6.08],[2,3.45,2]],"batl":[[1,4.5,5.37]],"ltp":3.85,"tv":7350.14,"id":9633869}]}]}
{"op":"mcm","clk":"4230487695","pt":1631533558858,"mc":[{"id":"1.187557995","rc":[{"batl":[[0,1.4,64.94],[1,1.43,304.75],[2,1.44,219.55]],"ltp":1.35,"tv":16723.0,"id":9342449},{"batb":[[0,3.5,6.08],[1,3.45,2],[2,3.3,83.84]],"ltp":3.85,"tv":7350.14,"id":9633869}]}]}
{"op":"mcm","clk":"4230488115","pt":1631533562426,"mc":[{"id":"1.187557995","rc":[{"batb":[[2,1.28,327.69]],"batl":[[1,1.43,297.75]],"ltp":1.35,"tv":16723.0,"id":9342449},{"batb":[[1,3.3,81.84],[2,2.2,42.67]],"batl":[[0,4.5,5.37],[1,4.9,2.15],[2,5,2.07]],"ltp":3.85,"tv":7350.14,"id":9633869}]}]}
{"op":"mcm","clk":"4230488442","pt":1631533565667,"mc":[{"id":"1.187557995","rc":[{"batl":[[0,1.38,66.25],[1,1.4,64.94],[2,1.43,297.75]],"ltp":1.35,"tv":16723.0,"id":9342449},{"batb":[[0,3.6,2.89],[1,3.5,6.08],[2,3.45,3]],"batl":[[0,4.4,2],[1,4.5,5.37],[2,4.9,2.15]],"ltp":3.85,"tv":7350.14,"id":9633869}]}]}
{"op":"mcm","clk":"4230488550","pt":1631533566639,"mc":[{"id":"1.187557995","rc":[{"trd":[[1.3,0.12]],"batb":[[0,1.29,13.45],[1,1.28,327.69],[2,1.26,99.98]],"batl":[[0,1.4,64.94],[1,1.82,475.58],[2,2.08,1]],"ltp":1.3,"tv":16723.12,"id":9342449},{"batb":[[0,3.5,6.08],[1,3.45,3],[2,3.3,81.84]],"batl":[[1,4.5,3]],"ltp":3.85,"tv":7350.14,"id":9633869}],"tv":24073.27}]}
{"op":"mcm","clk":"4230488777","pt":1631533568586,"mc":[{"id":"1.187557995","rc":[{"batl":[[1,2.08,1],[2,44,7.23]],"ltp":1.3,"tv":16723.12,"id":9342449}]}]}
{"op":"mcm","clk":"4230488909","pt":1631533569676,"mc":[{"id":"1.187557995","rc":[{"batb":[[0,1.3,204.25],[1,1.29,395.66],[2,1.28,1149.47]],"batl":[[0,1.33,454.52],[1,1.34,303.52],[2,1.38,60.25]],"ltp":1.3,"tv":16723.12,"id":9342449},{"batb":[[0,3.9,490.4],[1,3.85,475.96],[2,3.8,475.96]],"ltp":3.85,"tv":7350.14,"id":9633869}]}]}
{"op":"mcm","clk":"4230489047","pt":1631533570637,"mc":[{"id":"1.187557995","rc":[{"batb":[[2,1.28,1158.47]],"ltp":1.3,"tv":16723.12,"id":9342449},{"trd":[[4,10.38]],"batb":[[0,4,94.39],[1,3.9,490.4],[2,3.85,475.96]],"ltp":4.0,"tv":7360.52,"id":9633869}],"tv":24083.65}]}
{"op":"mcm","clk":"4230489140","pt":1631533571445,"mc":[{"id":"1.187557995","rc":[{"batb":[[1,1.29,453.93],[2,1.28,1186.81]],"batl":[[2,1.36,15]],"ltp":1.3,"tv":16723.12,"id":9342449},{"batl":[[0,4.4,12],[2,4.6,7.9]],"ltp":4.0,"tv":7360.52,"id":9633869}]}]}
{"op":"mcm","clk":"4230489254","pt":1631533572338,"mc":[{"id":"1.187557995","rc":[{"batb":[[0,1.3,213.25]],"ltp":1.3,"tv":16723.12,"id":9342449},{"batb":[[2,3.85,477.96]],"ltp":4.0,"tv":7360.52,"id":9633869}]}]}
{"op":"mcm","clk":"4230489509","pt":1631533574537,"mc":[{"id":"1.187557995","rc":[{"trd":[[1.32,20.56]],"batl":[[0,1.32,388.75],[1,1.33,454.52],[2,1.34,303.52]],"ltp":1.32,"tv":16743.68,"id":9342449},{"trd":[[4.1,6.62]],"ltp":4.1,"tv":7367.14,"id":9633869}],"tv":24110.83}]}
{"op":"mcm","clk":"4230489642","pt":1631533575688,"mc":[{"id":"1.187557995","rc":[{"trd":[[1.3,426.62]],"batb":[[0,1.29,453.93],[1,1.28,1186.81],[2,1.27,797.6]],"batl":[[0,1.3,176.54],[1,1.32,388.75],[2,1.33,484.84]],"ltp":1.3,"tv":17170.18,"id":9342449},{"batb":[[0,4,124.79]],"ltp":4.1,"tv":7367.14,"id":9633869}],"tv":24537.33}]}
{"op":"mcm","clk":"4230489740","pt":1631533576582,"mc":[{"id":"1.187557995","rc":[{"batb":[[2,1.27,1027.34]],"ltp":1.3,"tv":17170.18,"id":9342449},{"batb":[[1,3.9,492.96]],"ltp":4.1,"tv":7367.14,"id":9633869}]}]}
{"op":"mcm","clk":"4230489840","pt":1631533577477,"mc":[{"id":"1.187557995","rc":[{"batb":[[1,3.9,498.13]],"ltp":4.1,"tv":7367.14,"id":9633869}]}]}
{"op":"mcm","clk":"4230489973","pt":1631533578644,"mc":[{"id":"1.187557995","rc":[{"trd":[[1.3,462.66]],"batb":[[0,1.29,546.11],[1,1.28,1592.97]],"batl":[[0,1.3,158.52],[1,1.31,183.75],[2,1.32,635.52]],"ltp":1.3,"tv":17206.22,"id":9342449},{"batl":[[1,4.6,7.9],[2,4.7,48.18]],"ltp":4.1,"tv":7367.14,"id":9633869}],"tv":24573.37}]}
{"op":"mcm","clk":"4230490050","pt":1631533579268,"mc":[{"id":"1.187557995","rc":[{"batl":[[2,1.32,719.63]],"ltp":1.3,"tv":17206.22,"id":9342449},{"batb":[[0,4.1,2.34],[1,4,124.79],[2,3.9,498.13]],"ltp":4.1,"tv":7367.14,"id":9633869}]}]}
{"op":"mcm","clk":"4230490371","pt":1631533582268,"mc":[{"id":"1.187557995","rc":[{"batb":[[1,1.28,1583.97]],"batl":[[0,1.3,171.54]],"ltp":1.3,"tv":17206.22,"id":9342449}]}]}
{"op":"mcm","clk":"4230490968","pt":1631533588705,"mc":[{"id":"1.187557995","rc":[{"trd":[[4.4,7.12]],"batl":[[0,4.4,8.44]],"ltp":4.4,"tv":7374.26,"id":9633869}],"tv":24580.49}]}
{"op":"mcm","clk":"4230491002","pt":1631533589114,"mc":[{"id":"1.187557995","rc":[{"batl":[[0,4.6,7.9],[1,4.7,48.18],[2,4.8,65.26]],"ltp":4.4,"tv":7374.26,"id":9633869}]}]}
{"op":"mcm","clk":"4230491266","pt":1631533592247,"mc":[{"id":"1.187557995","rc":[{"trd":[[1.3,478.66]],"batl":[[0,1.3,163.54]],"ltp":1.3,"tv":17222.22,"id":9342449},{"batl":[[0,4.4,3],[1,4.6,7.9],[2,4.7,48.18]],"ltp":4.4,"tv":7374.26,"id":9633869}],"tv":24596.49}]}
{"op":"mcm","clk":"4230491592","pt":1631533595647,"mc":[{"id":"1.187557995","rc":[{"batb":[[0,1.29,487.84],[1,1.28,762.19],[2,1.27,229.74]],"ltp":1.3,"tv":17222.22,"id":9342449},{"batb":[[1,4,94.39],[2,3.9,7.73]],"ltp":4.4,"tv":7374.26,"id":9633869}]}]}
{"op":"mcm","clk":"4230491688","pt":1631533596646,"mc":[{"id":"1.187557995","rc":[{"trd":[[1.29,3.86]],"batb":[[0,1.29,11.52],[1,1.28,28.34]],"batl":[[1,1.32,84.11],[2,1.34,74.25]],"ltp":1.29,"tv":17226.08,"id":9342449},{"batb":[[1,3.9,7.73],[2,3.85,2]],"batl":[[0,4.4,22.4]],"ltp":4.4,"tv":7374.26,"id":9633869}],"tv":24600.35}]}
{"op":"mcm","clk":"4230491777","pt":1631533597630,"mc":[{"id":"1.187557995","rc":[{"batb":[[0,1.29,1.52],[1,1.27,229.74],[2,1.26,201.51]],"ltp":1.29,"tv":17226.08,"id":9342449},{"batb":[[1,3.9,2.56]],"batl":[[0,4.7,48.18],[1,4.8,65.26],[2,4.9,70.35]],"ltp":4.4,"tv":7374.26,"id":9633869}]}]}
{"op":"mcm","clk":"4230491931","pt":1631533599145,"mc":[{"id":"1.187557995","rc":[{"batb":[[2,1.26,548.48]],"ltp":1.29,"tv":17226.08,"id":9342449}]}]}
{"op":"mcm","clk":"4230492264","pt":1631533603163,"mc":[{"id":"1.187557995","rc":[{"batb":[[1,1.25,512.06],[2,1.24,483.57]],"ltp":1.29,"tv":17226.08,"id":9342449},{"batl":[[0,5.2,2.23],[1,5.8,2.02],[2,6,2.01]],"ltp":4.4,"tv":7374.26,"id":9633869}]}]}
{"op":"mcm","clk":"4230492391","pt":1631533604525,"mc":[{"id":"1.187557995","rc":[{"batl":[[0,1.3,13.02],[1,1.34,74.25],[2,1.36,377.58]],"ltp":1.29,"tv":17226.08,"id":9342449},{"batb":[[0,3.9,2.56],[1,3.85,2],[2,3.75,3.11]],"ltp":4.4,"tv":7374.26,"id":9633869}]}]}
{"op":"mcm","clk":"4230492478","pt":1631533605624,"mc":[{"id":"1.187557995","rc":[{"trd":[[1.3,504.7]],"batl":[[0,1.34,74.25],[1,1.36,377.58],[2,1.37,415.63]],"ltp":1.3,"tv":17252.12,"id":9342449},{"batb":[[1,3.75,3.11],[2,3.7,126.66]],"ltp":4.4,"tv":7374.26,"id":9633869}],"tv":24626.39}]}
{"op":"mcm","clk":"4230492576","pt":1631533606522,"mc":[{"id":"1.187557995","rc":[{"trd":[[1.34,8.73]],"batb":[[0,1.33,257.22],[1,1.32,1788.91],[2,1.31,1406.26]],"batl":[[0,1.34,65.52]],"ltp":1.34,"tv":17260.85,"id":9342449},{"trd":[[3.9,8.12]],"batb":[[0,3.75,3.11],[1,3.7,126.66],[2,3.65,353.2]],"batl":[[0,4.4,6.94],[1,5.2,2.23],[2,5.8,2.02]],"ltp":3.9,"tv":7382.38,"id":9633869}],"tv":24643.24}]}
{"op":"mcm","clk":"4230492669","pt":1631533607465,"mc":[{"id":"1.187557995","rc":[{"batb":[[0,1.33,535.79],[1,1.32,1881.87]],"ltp":1.34,"tv":17260.85,"id":9342449},{"batl":[[0,4.3,8.25],[1,4.4,6.94],[2,4.9,2]],"ltp":3.9,"tv":7382.38,"id":9633869}]}]}
{"op":"mcm","clk":"4230492771","pt":1631533608614,"mc":[{"id":"1.187557995","rc":[{"batl":[[0,4,2],[1,4.3,11.25],[2,4.4,6.94]],"ltp":3.9,"tv":7382.38,"id":9633869}]}]}
{"op":"mcm","clk":"4230492867","pt":1631533609661,"mc":[{"id":"1.187557995","rc":[{"batb":[[0,1.33,544.79],[1,1.32,1843.39]],"batl":[[1,1.36,309.76]],"ltp":1.34,"tv":17260.85,"id":9342449},{"batb":[[0,3.7,126.66],[1,3.65,353.2],[2,3.6,380.89]],"batl":[[1,4.1,3],[2,4.3,11.25]],"ltp":3.9,"tv":7382.38,"id":9633869}]}]}
{"op":"mcm","clk":"4230492948","pt":1631533610522,"mc":[{"id":"1.187557995","rc":[{"batb":[[0,1.33,590.13],[1,1.32,1796.91],[2,1.31,1433.2]],"batl":[[1,1.35,199.86],[2,1.36,309.76]],"ltp":1.34,"tv":17260.85,"id":9342449},{"batl":[[1,4.1,23.01]],"ltp":3.9,"tv":7382.38,"id":9633869}]}]}
{"op":"mcm","clk":"4230493022","pt":1631533611363,"mc":[{"id":"1.187557995","rc":[{"trd":[[1.33,294.26],[1.34,23.54]],"batb":[[0,1.33,443]],"batl":[[0,1.34,50.71]],"ltp":1.33,"tv":17569.92,"id":9342449},{"trd":[[3.9,13.21]],"batl":[[1,4.1,3]],"ltp":3.9,"tv":7387.47,"id":9633869}],"tv":24957.4}]}
{"op":"mcm","clk":"4230493125","pt":1631533612473,"mc":[{"id":"1.187557995","rc":[{"batb":[[0,3.7,141.24]],"batl":[[2,4.3,3]],"ltp":3.9,"tv":7387.47,"id":9633869}]}]}
{"op":"mcm","clk":"4230493206","pt":1631533613149,"mc":[{"id":"1.187557995","rc":[{"batl":[[0,1.34,218.71]],"ltp":1.33,"tv":17569.92,"id":9342449}]}]}
{"op":"mcm","clk":"4230493327","pt":1631533614448,"mc":[{"id":"1.187557995","rc":[{"batl":[[0,4,12]],"ltp":3.9,"tv":7387.47,"id":9633869}]}]}
{"op":"mcm","clk":"4230493458","pt":1631533615646,"mc":[{"id":"1.187557995","rc":[{"batb":[[0,1.33,508.82]],"batl":[[2,1.36,389.21]],"ltp":1.33,"tv":17569.92,"id":9342449},{"batl":[[2,4.2,8.38]],"ltp":3.9,"tv":7387.47,"id":9633869}]}]}
{"op":"mcm","clk":"4230493581","pt":1631533616954,"mc":[{"id":"1.187557995","rc":[{"batl":[[0,1.34,425.71]],"ltp":1.33,"tv":17569.92,"id":9342449}]}]}
{"op":"mcm","clk":"4230494304","pt":1631533624366,"mc":[{"id":"1.187557995","rc":[{"batb":[[0,1.31,26.94],[1,1.29,1.52],[2,1.27,197.02]],"batl":[[0,1.34,168],[1,1.39,68.5],[2,1.4,60.94]],"ltp":1.33,"tv":17569.92,"id":9342449},{"batb":[[0,3.6,5.76],[1,3.55,2.99],[2,3.5,4.08]],"batl":[[0,4.2,8.38],[1,4.7,48.51],[2,4.8,72.15]],"ltp":3.9,"tv":7387.47,"id":9633869}]}]}
{"op":"mcm","clk":"4230494411","pt":1631533625455,"mc":[{"id":"1.187557995","rc":[{"batb":[[0,1.29,1.52],[1,1.27,197.02],[2,1.26,644.78]],"batl":[[0,1.42,220.12],[1,1.43,150.02],[2,1.44,189.25]],"ltp":1.33,"tv":17569.92,"id":9342449},{"batb":[[0,3.35,63.25],[1,3.3,70.83],[2,3.25,176.97]],"batl":[[0,4.7,48.51],[1,4.8,72.15],[2,4.9,59]],"ltp":3.9,"tv":7387.47,"id":9633869}]}]}
{"op":"mcm","clk":"4230494600","pt":1631533627587,"mc":[{"id":"1.187557995","rc":[{"batb":[[1,1.27,466.99],[2,1.26,1087.05]],"batl":[[0,1.42,445.77],[1,1.43,378.75]],"ltp":1.33,"tv":17569.92,"id":9342449}]}]}
{"op":"mcm","clk":"4230494723","pt":1631533628687,"mc":[{"id":"1.187557995","rc":[{"batl":[[0,1.39,67.5],[1,1.42,451.77],[2,1.43,378.75]],"ltp":1.33,"tv":17569.92,"id":9342449},{"batb":[[0,3.55,3.79],[1,3.35,66.25],[2,3.3,73.83]],"ltp":3.9,"tv":7387.47,"id":9633869}]}]}
{"op":"mcm","clk":"4230494802","pt":1631533629465,"mc":[{"id":"1.187557995","rc":[{"batb":[[1,1.28,500],[2,1.27,466.99]],"ltp":1.33,"tv":17569.92,"id":9342449}]}]}
{"op":"mcm","clk":"4230495129","pt":1631533633270,"mc":[{"id":"1.187557995","rc":[{"batb":[[2,1.26,371.79]],"batl":[[0,1.39,7]],"ltp":1.33,"tv":17569.92,"id":9342449},{"batb":[[0,3.35,66.25],[1,3.3,73.83],[2,3.25,176.97]],"batl":[[0,5.2,2.23],[1,5.8,2.02],[2,6,2.01]],"ltp":3.9,"tv":7387.47,"id":9633869}]}]}
{"op":"mcm","clk":"4230495201","pt":1631533634162,"mc":[{"id":"1.187557995","rc":[{"batb":[[1,1.26,371.79],[2,1.24,91.02]],"ltp":1.33,"tv":17569.92,"id":9342449}]}]}
{"op":"mcm","clk":"4230495328","pt":1631533635670,"mc":[{"id":"1.187557995","rc":[{"trd":[[1.39,14]],"batb":[[0,1.34,84.22],[1,1.29,1.52],[2,1.26,371.79]],"batl":[[0,1.42,451.77],[1,1.43,378.75],[2,1.44,2845.49]],"ltp":1.39,"tv":17583.92,"id":9342449},{"trd":[[3.35,31.24]],"batb":[[0,3.35,60.19]],"batl":[[0,3.75,1020],[1,3.8,990],[2,3.85,990]],"ltp":3.35,"tv":7399.6,"id":9633869}],"tv":24983.52}]}
{"op":"mcm","clk":"4230495412","pt":1631533636657,"mc":[{"id":"1.187557995","rc":[{"batb":[[0,1.39,187.36],[1,1.38,272.6],[2,1.34,84.22]],"batl":[[0,1.42,445.77],[2,1.44,1517.37]],"ltp":1.39,"tv":17583.92,"id":9342449},{"batb":[[0,3.35,57.19],[1,3.3,70.83]],"batl":[[0,3.75,510],[1,3.8,495],[2,3.85,495]],"ltp":3.35,"tv":7399.6,"id":9633869}]}]}
{"op":"mcm","clk":"4230495467","pt":1631533637390,"mc":[{"id":"1.187557995","rc":[{"batb":[[0,1.39,410.2],[2,1.36,25]],"ltp":1.39,"tv":17583.92,"id":9342449},{"batl":[[0,3.75,519.04]],"ltp":3.35,"tv":7399.6,"id":9633869}]}]}
{"op":"mcm","clk":"4230495582","pt":1631533638695,"mc":[{"id":"1.187557995","rc":[{"batb":[[2,1.34,84.22]],"ltp":1.39,"tv":17583.92,"id":9342449},{"batl":[[0,3.7,3],[1,3.75,519.04],[2,3.8,495]],"ltp":3.35,"tv":7399.6,"id":9633869}]}]}
{"op":"mcm","clk":"4230495626","pt":1631533639072,"mc":[{"id":"1.187557995","rc":[{"batb":[[2,1.37,7]],"ltp":1.39,"tv":17583.92,"id":9342449},{"batl":[[0,3.55,3],[1,3.7,3],[2,3.75,519.04]],"ltp":3.35,"tv":7399.6,"id":9633869}]}]}
{"op":"mcm","clk":"4230495777","pt":1631533640675,"mc":[{"id":"1.187557995","rc":[{"trd":[[1.41,436.51]],"batb":[[0,1.39,456.16]],"batl":[[0,1.41,172.21],[1,1.42,445.77],[2,1.43,378.75]],"ltp":1.41,"tv":17595.9,"id":9342449},{"trd":[[3.4,4.97]],"ltp":3.4,"tv":7404.57,"id":9633869}],"tv":25000.47}]}
{"op":"mcm","clk":"4230495850","pt":1631533641611,"mc":[{"id":"1.187557995","rc":[{"batb":[[2,1.37,31.65]],"ltp":1.41,"tv":17595.9,"id":9342449},{"batl":[[2,3.75,510]],"ltp":3.4,"tv":7404.57,"id":9633869}]}]}
{"op":"mcm","clk":"4230496049","pt":1631533643702,"mc":[{"id":"1.187557995","rc":[{"batb":[[2,3.25,180.62]],"ltp":3.4,"tv":7404.57,"id":9633869}]}]}
{"op":"mcm","clk":"4230496116","pt":1631533644376,"mc":[{"id":"1.187557995","rc":[{"batl":[[1,3.7,12.12]],"ltp":3.4,"tv":7404.57,"id":9633869}]}]}
{"op":"mcm","clk":"4230496394","pt":1631533647295,"mc":[{"id":"1.187557995","rc":[{"batl":[[0,1.41,277.21]],"ltp":1.41,"tv":17595.9,"id":9342449}]}]}
{"op":"mcm","clk":"4230496716","pt":1631533650410,"mc":[{"id":"1.187557995","rc":[{"batl":[[0,3.55,33.59]],"ltp":3.4,"tv":7404.57,"id":9633869}]}]}
{"op":"mcm","clk":"4230496785","pt":1631533651199,"mc":[{"id":"1.187557995","rc":[{"batb":[[0,1.37,24.65],[1,1.34,208.76],[2,1.33,201.71]],"batl":[[0,1.41,105],[1,1.44,56.08],[2,1.45,56.7]],"ltp":1.41,"tv":17595.9,"id":9342449},{"batb":[[0,3.25,3.65],[1,3.2,11.13],[2,3.15,3.63]],"batl":[[0,3.7,9.12],[1,3.95,67.81],[2,4,63.4]],"ltp":3.4,"tv":7404.57,"id":9633869}]}]}
{"op":"mcm","clk":"4230496930","pt":1631533652711,"mc":[{"id":"1.187557995","rc":[{"batb":[[0,1.34,208.76],[1,1.33,201.71],[2,1.32,476.47]],"batl":[[0,1.46,64.25],[1,1.49,157.7],[2,1.5,183.12]],"ltp":1.41,"tv":17595.9,"id":9342449},{"batb":[[0,3.15,3.63],[1,3.05,75.62],[2,3,197.83]],"batl":[[0,3.95,67.81],[1,4,63.4],[2,4.1,72.44]],"ltp":3.4,"tv":7404.57,"id":9633869}]}]}
{"op":"mcm","clk":"4230497088","pt":1631533654298,"mc":[{"id":"1.187557995","rc":[{"batb":[[1,1.33,387.29],[2,1.32,816.66]],"batl":[[1,1.49,427.14],[2,1.5,370.04]],"ltp":1.41,"tv":17595.9,"id":9342449}]}]}
{"op":"mcm","clk":"4230497201","pt":1631533655683,"mc":[{"id":"1.187557995","rc":[{"batb":[[0,1.32,280.25],[1,1.31,478.9],[2,1.3,94.88]],"ltp":1.41,"tv":17595.9,"id":9342449},{"batl":[[0,4.4,2.54],[1,5,2.22],[2,5.2,2.23]],"ltp":3.4,"tv":7404.57,"id":9633869}]}]}
{"op":"mcm","clk":"4230497441","pt":1631533658590,"mc":[{"id":"1.187557995","rc":[{"trd":[[1.46,6.32]],"batb":[[0,1.45,228.88],[1,1.44,224.81],[2,1.39,85.91]],"batl":[[0,1.46,57.93]],"ltp":1.46,"tv":17602.22,"id":9342449},{"trd":[[3.15,10.19]],"batb":[[0,3.15,3],[1,3.1,3],[2,3.05,75.62]],"batl":[[0,3.3,579.56],[1,3.35,562.5],[2,3.4,562.5]],"ltp":3.15,"tv":7414.76,"id":9633869}],"tv":25016.98}]}
{"op":"mcm","clk":"4230497538","pt":1631533659625,"mc":[{"id":"1.187557995","rc":[{"batb":[[1,1.44,414.51],[2,1.39,311.43]],"ltp":1.46,"tv":17602.22,"id":9342449},{"batb":[[0,3.05,75.62],[1,3,197.83],[2,2.98,92.55]],"ltp":3.15,"tv":7414.76,"id":9633869}]}]}
{"op":"mcm","clk":"4230497747","pt":1631533661709,"mc":[{"id":"1.187557995","rc":[{"trd":[[1.44,142.88],[1.45,464.38]],"batb":[[0,1.44,356.01],[1,1.43,7]],"batl":[[1,1.49,351.05],[2,1.5,183.12]],"ltp":1.44,"tv":18195.6,"id":9342449},{"trd":[[3.2,3]],"batl":[[0,3.25,3],[1,3.3,579.56],[2,3.35,562.5]],"ltp":3.2,"tv":7417.76,"id":9633869}],"tv":25613.36}]}
{"op":"mcm","clk":"4230497826","pt":1631533662598,"mc":[{"id":"1.187557995","rc":[{"batb":[[2,1.42,23.14]],"ltp":1.44,"tv":18195.6,"id":9342449}]}]}
{"op":"mcm","clk":"4230497926","pt":1631533663629,"mc":[{"id":"1.187557995","rc":[{"batb":[[2,1.39,311.43]],"batl":[[1,1.47,158.07],[2,1.49,351.05]],"ltp":1.44,"tv":18195.6,"id":9342449}]}]}
{"op":"mcm","clk":"4230498023","pt":1631533664615,"mc":[{"id":"1.187557995","rc":[{"batb":[[0,1.45,50.95],[1,1.44,488.07],[2,1.43,423.66]],"batl":[[0,1.46,382.81],[2,1.48,235.08]],"ltp":1.44,"tv":18195.6,"id":9342449},{"batl":[[2,3.35,640.67]],"ltp":3.2,"tv":7417.76,"id":9633869}]}]}
{"op":"mcm","clk":"4230498164","pt":1631533666036,"mc":[{"id":"1.187557995","rc":[{"batb":[[2,1.43,446.53]],"ltp":1.44,"tv":18195.6,"id":9342449}]}]}
{"op":"mcm","clk":"4230498268","pt":1631533667024,"mc":[{"id":"1.187557995","rc":[{"batl":[[1,3.3,589.45]],"ltp":3.2,"tv":7417.76,"id":9633869}]}]}
{"op":"mcm","clk":"4230498686","pt":1631533671133,"mc":[{"id":"1.187557995","rc":[{"batb":[[2,1.43,666.69]],"ltp":1.44,"tv":18195.6,"id":9342449},{"batl":[[1,3.3,684.85]],"ltp":3.2,"tv":7417.76,"id":9633869}]}]}
{"op":"mcm","clk":"4230498959","pt":1631533674309,"mc":[{"id":"1.187557995","rc":[{"batb":[[1,1.44,482.07],[2,1.43,659.69]],"ltp":1.44,"tv":18195.6,"id":9342449},{"batl":[[0,3.2,15],[1,3.25,3],[2,3.3,684.85]],"ltp":3.2,"tv":7417.76,"id":9633869}]}]}
{"op":"mcm","clk":"4230499081","pt":1631533675713,"mc":[{"id":"1.187557995","rc":[{"batb":[[0,1.45,6],[1,1.43,22.87],[2,1.4,155.15]],"batl":[[0,1.46,169],[1,1.54,124.39],[2,1.55,138.99]],"ltp":1.44,"tv":18195.6,"id":9342449},{"batb":[[0,2.9,7.89],[1,2.84,112.73],[2,2.82,75.72]],"batl":[[0,3.25,3],[1,3.3,9.89],[2,3.45,59.9]],"ltp":3.2,"tv":7417.76,"id":9633869}]}]}
{"op":"mcm","clk":"4230499138","pt":1631533676422,"mc":[{"id":"1.187557995","rc":[{"batb":[[0,1.4,155.15],[1,1.39,398.85],[2,1.38,207.67]],"batl":[[0,1.54,124.39],[1,1.55,138.99],[2,1.56,159.04]],"ltp":1.44,"tv":18195.6,"id":9342449},{"batb":[[0,2.84,112.73],[1,2.82,75.72],[2,2.8,89.33]],"batl":[[0,3.45,59.9],[1,3.5,86.93],[2,3.55,70.55]],"ltp":3.2,"tv":7417.76,"id":9633869}]}]}
{"op":"mcm","clk":"4230499202","pt":1631533677136,"mc":[{"id":"1.187557995","rc":[{"batb":[[0,2.88,3],[1,2.86,3],[2,2.84,112.73]],"ltp":3.2,"tv":7417.76,"id":9633869}]}]}
{"op":"mcm","clk":"4230499326","pt":1631533678537,"mc":[{"id":"1.187557995","rc":[{"batb":[[2,1.38,492.6]],"batl":[[1,1.55,425.42],[2,1.56,320.25]],"ltp":1.44,"tv":18195.6,"id":9342449}]}]}
{"op":"mcm","clk":"4230499429","pt":1631533679631,"mc":[{"id":"1.187557995","rc":[{"batl":[[0,1.53,7],[1,1.54,129.39],[2,1.55,425.42]],"ltp":1.44,"tv":18195.6,"id":9342449},{"batb":[[0,2.9,3],[1,2.88,3],[2,2.86,3]],"ltp":3.2,"tv":7417.76,"id":9633869}]}]}
{"op":"mcm","clk":"4230499504","pt":1631533680418,"mc":[{"id":"1.187557995","rc":[{"batb":[[0,1.41,500],[1,1.4,155.15],[2,1.39,398.85]],"ltp":1.44,"tv":18195.6,"id":9342449}]}]}
{"op":"mcm","clk":"4230499598","pt":1631533681449,"mc":[{"id":"1.187557995","rc":[{"batl":[[2,1.55,138.99]],"ltp":1.44,"tv":18195.6,"id":9342449}]}]}
{"op":"mcm","clk":"4230499887","pt":1631533684625,"mc":[{"id":"1.187557995","rc":[{"batb":[[0,1.43,232.6],[1,1.42,240.54],[2,1.41,500]],"batl":[[0,1.47,313.97],[1,1.48,198.24],[2,1.53,7]],"ltp":1.44,"tv":18195.6,"id":9342449}]}]}
{"op":"mcm","clk":"4230500089","pt":1631533686433,"mc":[{"id":"1.187557995","rc":[{"batl":[[2,1.52,35]],"ltp":1.44,"tv":18195.6,"id":9342449},{"batb":[[0,2.92,15],[1,2.9,3],[2,2.88,3]],"batl":[[0,3.4,31.92],[1,3.45,59.9],[2,3.5,86.93]],"ltp":3.2,"tv":7417.76,"id":9633869}]}]}
{"op":"mcm","clk":"4230500228","pt":1631533687936,"mc":[{"id":"1.187557995","rc":[{"batb":[[0,1.41,500],[1,1.4,155.15],[2,1.39,398.85]],"batl":[[0,1.53,7],[1,1.54,129.39],[2,1.55,138.99]],"ltp":1.44,"tv":18195.6,"id":9342449},{"batb":[[0,2.9,3],[1,2.88,3],[2,2.86,3]],"batl":[[0,3.45,59.9],[1,3.5,86.93],[2,3.55,70.55]],"ltp":3.2,"tv":7417.76,"id":9633869}]}]}
{"op":"mcm","clk":"4230500388","pt":1631533689545,"mc":[{"id":"1.187557995","rc":[{"batb":[[0,1.44,71.08],[1,1.41,500],[2,1.4,155.15]],"ltp":1.44,"tv":18195.6,"id":9342449},{"batb":[[1,2.84,115.73],[2,2.82,78.72]],"ltp":3.2,"tv":7417.76,"id":9633869}]}]}
{"op":"mcm","clk":"4230500418","pt":1631533689818,"mc":[{"id":"1.187557995","rc":[{"batb":[[0,1.41,500],[1,1.4,155.15],[2,1.39,398.85]],"ltp":1.44,"tv":18195.6,"id":9342449}]}]}
{"op":"mcm","clk":"4230500518","pt":1631533690857,"mc":[{"id":"1.187557995","rc":[{"batl":[[2,1.55,425.42]],"ltp":1.44,"tv":18195.6,"id":9342449}]}]}
{"op":"mcm","clk":"4230500796","pt":1631533693437,"mc":[{"id":"1.187557995","rc":[{"batb":[[1,1.39,225.52],[2,1.36,95.68]],"batl":[[1,1.54,124.39]],"ltp":1.44,"tv":18195.6,"id":9342449},{"batb":[[1,2.88,3],[2,2.84,112.73]],"batl":[[0,3.8,3.72],[1,4.3,3.05],[2,3.55,0]],"ltp":3.2,"tv":7417.76,"id":9633869}]}]}
{"op":"mcm","clk":"4230501111","pt":1631533696664,"mc":[{"id":"1.187557995","rc":[{"batb":[[0,1.5,291.88],[1,1.49,1479.14],[2,1.48,1245.82]],"batl":[[0,1.54,124.39],[1,1.55,425.42],[2,1.56,320.25]],"ltp":1.44,"tv":18195.6,"id":9342449},{"trd":[[2.84,14.08]],"batb":[[0,2.84,105.69],[1,2.82,75.72],[2,2.8,89.33]],"batl":[[0,3.4,12.39],[1,3.8,3.72],[2,4.3,3.05]],"ltp":2.84,"tv":7431.84,"id":9633869}],"tv":25627.44}]}
{"op":"mcm","clk":"4230501213","pt":1631533697659,"mc":[{"id":"1.187557995","rc":[{"batb":[[0,1.5,455.64]],"ltp":1.44,"tv":18195.6,"id":9342449},{"batl":[[0,3.35,18.6],[1,3.4,12.39],[2,3.8,3.72]],"ltp":2.84,"tv":7431.84,"id":9633869}]}]}
{"op":"mcm","clk":"4230501291","pt":1631533698656,"mc":[{"id":"1.187557995","rc":[{"batb":[[0,1.51,7],[1,1.5,461.64],[2,1.49,1479.14]],"ltp":1.44,"tv":18195.6,"id":9342449},{"batl":[[0,2.98,4]],"ltp":2.84,"tv":7431.84,"id":9633869}]}]}
{"op":"mcm","clk":"4230501361","pt":1631533699237,"mc":[{"id":"1.187557995","rc":[{"batb":[[2,1.49,1486.14]],"ltp":1.44,"tv":18195.6,"id":9342449},{"batl":[[1,3,3],[2,3.4,15.39]],"ltp":2.84,"tv":7431.84,"id":9633869}]}]}
{"op":"mcm","clk":"4230501503","pt":1631533700654,"mc":[{"id":"1.187557995","rc":[{"batl":[[0,1.53,116.37],[1,1.54,124.39],[2,1.55,425.42]],"ltp":1.44,"tv":18195.6,"id":9342449}]}]}
{"op":"mcm","clk":"4230501588","pt":1631533701538,"mc":[{"id":"1.187557995","rc":[{"batb":[[0,1.51,42]],"ltp":1.44,"tv":18195.6,"id":9342449}]}]}
{"op":"mcm","clk":"4230501644","pt":1631533702254,"mc":[{"id":"1.187557995","rc":[{"batl":[[0,2.96,3],[1,2.98,4],[2,3,3]],"ltp":2.84,"tv":7431.84,"id":9633869}]}]}
{"op":"mcm","clk":"4230501879","pt":1631533704449,"mc":[{"id":"1.187557995","rc":[{"batb":[[2,1.49,1507.56]],"batl":[[1,1.54,238.13]],"ltp":1.44,"tv":18195.6,"id":9342449},{"batl":[[0,2.96,18]],"ltp":2.84,"tv":7431.84,"id":9633869}]}]}
{"op":"mcm","clk":"4230501975","pt":1631533705538,"mc":[{"id":"1.187557995","rc":[{"batb":[[1,1.5,459.47]],"ltp":1.44,"tv":18195.6,"id":9342449},{"batb":[[0,2.84,64.19],[1,2.82,125.09]],"ltp":2.84,"tv":7431.84,"id":9633869}]}]}
{"op":"mcm","clk":"4230502026","pt":1631533706159,"mc":[{"id":"1.187557995","rc":[{"batl":[[0,1.53,221.37]],"ltp":1.44,"tv":18195.6,"id":9342449}]}]}
{"op":"mcm","clk":"4230502487","pt":1631533711269,"mc":[{"id":"1.187557995","rc":[{"batb":[[1,1.5,453.47],[2,1.49,1500.56]],"ltp":1.44,"tv":18195.6,"id":9342449},{"batl":[[1,3.05,105.02],[2,3.1,99.66]],"ltp":2.84,"tv":7431.84,"id":9633869}]}]}
{"op":"mcm","clk":"4230502547","pt":1631533711962,"mc":[{"id":"1.187557995","rc":[{"trd":[[1.53,48.45]],"batl":[[0,1.53,200.48]],"ltp":1.53,"tv":18237.38,"id":9342449}],"tv":25669.22}]}
{"op":"mcm","clk":"4230502663","pt":1631533713047,"mc":[{"id":"1.187557995","rc":[{"batb":[[1,1.5,659.6]],"ltp":1.53,"tv":18237.38,"id":9342449},{"batl":[[1,3,103.07],[2,3.05,105.02]],"ltp":2.84,"tv":7431.84,"id":9633869}]}]}
{"op":"mcm","clk":"4230502841","pt":1631533715052,"mc":[{"id":"1.187557995","rc":[{"batb":[[2,1.49,1706.69]],"ltp":1.53,"tv":18237.38,"id":9342449},{"batl":[[2,3.05,205.72]],"ltp":2.84,"tv":7431.84,"id":9633869}]}]}
{"op":"mcm","clk":"4230503256","pt":1631533719501,"mc":[{"id":"1.187557995","rc":[{"trd":[[1.5,573.11],[1.51,145.88]],"batb":[[0,1.5,383.94],[1,1.49,1706.69],[2,1.48,1440.67]],"batl":[[2,1.55,304.87]],"ltp":1.5,"tv":18907.98,"id":9342449},{"trd":[[2.96,31.57]],"batl":[[0,3,103.07],[1,3.05,205.72],[2,3.1,99.66]],"ltp":2.96,"tv":7449.84,"id":9633869}],"tv":26357.82}]}
{"op":"mcm","clk":"4230503539","pt":1631533722481,"mc":[{"id":"1.187557995","rc":[{"batb":[[0,1.51,5],[1,1.5,514.26],[2,1.49,1706.69]],"batl":[[1,1.54,507.38]],"ltp":1.5,"tv":18907.98,"id":9342449},{"batl":[[0,2.98,3],[1,3,103.07],[2,3.05,205.72]],"ltp":2.96,"tv":7449.84,"id":9633869}]}]}
{"op":"mcm","clk":"4230503609","pt":1631533723154,"mc":[{"id":"1.187557995","rc":[{"batb":[[1,1.5,556.95]],"ltp":1.5,"tv":18907.98,"id":9342449},{"batl":[[0,2.98,21.21]],"ltp":2.96,"tv":7449.84,"id":9633869}]}]}
{"op":"mcm","clk":"4230503831","pt":1631533725391,"mc":[{"id":"1.187557995","rc":[{"batl":[[0,2.96,3],[1,2.98,21.21],[2,3,103.07]],"ltp":2.96,"tv":7449.84,"id":9633869}]}]}
{"op":"mcm","clk":"4230503908","pt":1631533726183,"mc":[{"id":"1.187557995","rc":[{"trd":[[1.49,1191.34],[1.5,1935.28],[1.51,161.76]],"batb":[[0,1.49,1111.02],[1,1.48,1440.67],[2,1.47,1455.98]],"batl":[[0,1.53,95.48],[1,1.54,409.05],[2,1.55,138.99]],"ltp":1.49,"tv":21477.37,"id":9342449},{"trd":[[2.96,34.57],[2.98,21.21],[3,111.96]],"batl":[[0,3.05,205.72],[1,3.1,99.66],[2,3.15,80.07]],"ltp":3.0,"tv":7577.11,"id":9633869}],"tv":29054.49}]}
{"op":"mcm","clk":"4230504249","pt":1631533729565,"mc":[{"id":"1.187557995","rc":[{"batb":[[0,1.49,1344.7],[1,1.48,1642.92]],"batl":[[0,1.52,126.86],[1,1.53,269.99],[2,1.54,533.24]],"ltp":1.49,"tv":21477.37,"id":9342449},{"batb":[[0,2.86,47.87],[1,2.84,64.19],[2,2.82,125.09]],"batl":[[0,3,3],[1,3.05,205.72],[2,3.1,99.66]],"ltp":3.0,"tv":7577.11,"id":9633869}]}]}
{"op":"mcm","clk":"4230504282","pt":1631533729974,"mc":[{"id":"1.187557995","rc":[{"batb":[[0,1.49,1389.69]],"ltp":1.49,"tv":21477.37,"id":9342449},{"batb":[[2,2.82,75.72]],"batl":[[1,3.05,229.12]],"ltp":3.0,"tv":7577.11,"id":9633869}]}]}
{"op":"mcm","clk":"4230504532","pt":1631533732694,"mc":[{"id":"1.187557995","rc":[{"trd":[[1.49,3296.98],[1.5,1941.28]],"batb":[[0,1.5,33.16],[1,1.49,336.87],[2,1.48,1642.92]],"ltp":1.49,"tv":23589.01,"id":9342449},{"trd":[[3,114.96]],"batl":[[0,3.05,229.12],[1,3.1,99.66],[2,3.15,80.07]],"ltp":3.0,"tv":7580.11,"id":9633869}],"tv":31169.13}]}
{"op":"mcm","clk":"4230504695","pt":1631533734196,"mc":[{"id":"1.187557995","rc":[{"batl":[[0,1.52,491.86]],"ltp":1.49,"tv":23589.01,"id":9342449}]}]}
{"op":"mcm","clk":"4230504868","pt":1631533735585,"mc":[{"id":"1.187557995","rc":[{"batb":[[1,1.49,424.37],[2,1.48,1729.52]],"batl":[[1,1.53,375.04],[2,1.54,657.43]],"ltp":1.49,"tv":23589.01,"id":9342449}]}]}
{"op":"mcm","clk":"4230505019","pt":1631533736700,"mc":[{"id":"1.187557995","rc":[{"batb":[[0,1.51,7],[1,1.5,39.16],[2,1.49,424.37]],"ltp":1.49,"tv":23589.01,"id":9342449},{"batl":[[0,2.98,3],[1,3.05,229.12],[2,3.1,99.66]],"ltp":3.0,"tv":7580.11,"id":9633869}]}]}
{"op":"mcm","clk":"4230505094","pt":1631533737378,"mc":[{"id":"1.187557995","rc":[{"batb":[[2,1.49,474]],"ltp":1.49,"tv":23589.01,"id":9342449}]}]}
{"op":"mcm","clk":"4230505328","pt":1631533739616,"mc":[{"id":"1.187557995","rc":[{"trd":[[1.49,3757.44],[1.5,2025.56],[1.51,175.76]],"batb":[[0,1.49,156.27],[1,1.48,1729.52],[2,1.47,1455.98]],"batl":[[1,1.53,271.72],[2,1.54,486.51]],"ltp":1.49,"tv":24147.75,"id":9342449},{"trd":[[2.98,24.21]],"batl":[[0,3.05,229.12],[1,3.1,99.66],[2,3.15,80.07]],"ltp":2.98,"tv":7583.11,"id":9633869}],"tv":31730.87}]}
{"op":"mcm","clk":"4230505354","pt":1631533739891,"mc":[{"id":"1.187557995","rc":[{"batl":[[0,1.51,178.89],[1,1.52,491.86],[2,1.53,271.72]],"ltp":1.49,"tv":24147.75,"id":9342449}]}]}
{"op":"mcm","clk":"4230505670","pt":1631533742705,"mc":[{"id":"1.187557995","rc":[{"batb":[[0,1.49,94.62],[1,1.48,2014.51],[2,1.47,1665.29]],"batl":[[1,1.52,629.93]],"ltp":1.49,"tv":24147.75,"id":9342449},{"batb":[[0,2.9,46.86]],"ltp":2.98,"tv":7583.11,"id":9633869}]}]}
{"op":"mcm","clk":"4230505960","pt":1631533745688,"mc":[{"id":"1.187557995","rc":[{"batb":[[0,1.49,99.62]],"ltp":1.49,"tv":24147.75,"id":9342449},{"batl":[[0,3,3],[1,3.05,229.12],[2,3.1,99.66]],"ltp":2.98,"tv":7583.11,"id":9633869}]}]}
{"op":"mcm","clk":"4230506006","pt":1631533746307,"mc":[{"id":"1.187557995","rc":[{"trd":[[1.49,3956.68],[1.5,2031.56]],"batb":[[0,1.48,2014.51],[1,1.47,1665.29],[2,1.46,172.74]],"batl":[[0,1.49,106.14],[1,1.51,178.89],[2,1.52,629.93]],"ltp":1.49,"tv":24352.99,"id":9342449},{"trd":[[3,117.96]],"batl":[[0,3.05,229.12],[1,3.1,99.66],[2,3.15,80.07]],"ltp":3.0,"tv":7586.11,"id":9633869}],"tv":31939.11}]}
{"op":"mcm","clk":"4230506363","pt":1631533749603,"mc":[{"id":"1.187557995","rc":[{"trd":[[1.49,4168.96]],"batb":[[0,1.49,92.33],[1,1.48,2020.51],[2,1.47,1665.29]],"batl":[[0,1.51,178.89],[1,1.52,629.93],[2,1.53,271.72]],"ltp":1.49,"tv":24565.28,"id":9342449},{"batb":[[2,2.82,83.96]],"batl":[[0,3.05,326.07]],"ltp":3.0,"tv":7586.11,"id":9633869}],"tv":32151.39}]}
{"op":"mcm","clk":"4230506415","pt":1631533750222,"mc":[{"id":"1.187557995","rc":[{"batb":[[0,1.49,128.91]],"ltp":1.49,"tv":24565.28,"id":9342449}]}]}
{"op":"mcm","clk":"4230506600","pt":1631533752319,"mc":[{"id":"1.187557995","rc":[{"batb":[[0,1.5,5],[1,1.49,128.91],[2,1.48,2020.51]],"ltp":1.49,"tv":24565.28,"id":9342449}]}]}
{"op":"mcm","clk":"4230506709","pt":1631533753525,"mc":[{"id":"1.187557995","rc":[{"trd":[[1.48,4801.78],[1.49,4426.78],[1.5,2041.56]],"batb":[[0,1.48,177.95],[1,1.47,1665.29],[2,1.46,172.74]],"ltp":1.48,"tv":28518.21,"id":9342449},{"batl":[[0,3.05,315.6]],"ltp":3.0,"tv":7586.11,"id":9633869}],"tv":36104.33}]}
{"op":"mcm","clk":"4230506862","pt":1631533755525,"mc":[{"id":"1.187557995","rc":[{"batl":[[0,2.98,2],[1,3.05,315.6],[2,3.1,99.66]],"ltp":3.0,"tv":7586.11,"id":9633869}]}]}
{"op":"mcm","clk":"4230506946","pt":1631533756530,"mc":[{"id":"1.187557995","rc":[{"batb":[[1,1.47,1752.8]],"ltp":1.48,"tv":28518.21,"id":9342449},{"batl":[[0,3.05,315.6],[1,3.1,99.66],[2,3.15,80.07]],"ltp":3.0,"tv":7586.11,"id":9633869}]}]}
{"op":"mcm","clk":"4230507055","pt":1631533757528,"mc":[{"id":"1.187557995","rc":[{"batb":[[0,1.49,32.92],[1,1.48,319.01],[2,1.47,1752.8]],"batl":[[1,1.52,799.19]],"ltp":1.48,"tv":28518.21,"id":9342449},{"batl":[[2,3.15,90.29]],"ltp":3.0,"tv":7586.11,"id":9633869}]}]}
{"op":"mcm","clk":"4230507077","pt":1631533757726,"mc":[{"id":"1.187557995","rc":[{"batb":[[0,1.48,319.01],[1,1.47,1752.8],[2,1.46,172.74]],"ltp":1.48,"tv":28518.21,"id":9342449}]}]}
{"op":"mcm","clk":"4230507279","pt":1631533759929,"mc":[{"id":"1.187557995","rc":[{"batb":[[0,1.49,5],[1,1.48,319.01],[2,1.47,1752.8]],"ltp":1.48,"tv":28518.21,"id":9342449},{"batl":[[0,3,3],[1,3.05,315.6],[2,3.1,99.66]],"ltp":3.0,"tv":7586.11,"id":9633869}]}]}
{"op":"mcm","clk":"4230507375","pt":1631533760933,"mc":[{"id":"1.187557995","rc":[{"batb":[[1,1.48,362.41]],"ltp":1.48,"tv":28518.21,"id":9342449}]}]}
{"op":"mcm","clk":"4230507688","pt":1631533764429,"mc":[{"id":"1.187557995","rc":[{"trd":[[1.48,5203.3],[1.49,4436.78],[1.5,2047.56]],"batb":[[0,1.48,161.65],[1,1.47,1752.8],[2,1.46,172.74]],"ltp":1.48,"tv":28935.73,"id":9342449},{"trd":[[3,120.96]],"batl":[[0,3.05,315.6],[1,3.1,99.66],[2,3.15,90.29]],"ltp":3.0,"tv":7589.11,"id":9633869}],"tv":36524.85}]}
{"op":"mcm","clk":"4230507762","pt":1631533765112,"mc":[{"id":"1.187557995","rc":[{"batb":[[0,1.48,43.4]],"batl":[[1,1.52,673.72],[2,1.53,95.48]],"ltp":1.48,"tv":28935.73,"id":9342449}]}]}
{"op":"mcm","clk":"4230508009","pt":1631533767621,"mc":[{"id":"1.187557995","rc":[{"batb":[[0,1.48,50.4]],"ltp":1.48,"tv":28935.73,"id":9342449}]}]}
{"op":"mcm","clk":"4230508046","pt":1631533768037,"mc":[{"id":"1.187557995","rc":[{"batb":[[1,1.47,1883.85],[2,1.46,389.5]],"batl":[[0,1.51,319.47],[1,1.52,842.37]],"ltp":1.48,"tv":28935.73,"id":9342449},{"batb":[[0,2.92,87.79],[1,2.9,46.86],[2,2.84,64.19]],"ltp":3.0,"tv":7589.11,"id":9633869}]}]}
{"op":"mcm","clk":"4230508148","pt":1631533769128,"mc":[{"id":"1.187557995","rc":[{"batl":[[0,3.05,292.2]],"ltp":3.0,"tv":7589.11,"id":9633869}]}]}
{"op":"mcm","clk":"4230508346","pt":1631533771041,"mc":[{"id":"1.187557995","rc":[{"trd":[[1.48,5394.88]],"batb":[[0,1.47,1883.85],[1,1.46,389.5],[2,1.42,289.69]],"ltp":1.48,"tv":29127.31,"id":9342449},{"trd":[[3.05,44.05]],"batl":[[0,3.05,248.14]],"ltp":3.05,"tv":7633.17,"id":9633869}],"tv":36760.48}]}
{"op":"mcm","clk":"4230508470","pt":1631533772139,"mc":[{"id":"1.187557995","rc":[{"batb":[[0,1.47,1260.94]],"ltp":1.48,"tv":29127.31,"id":9342449}]}]}
{"op":"mcm","clk":"4230508712","pt":1631533774238,"mc":[{"id":"1.187557995","rc":[{"trd":[[1.5,2055.56]],"batb":[[0,1.49,5],[1,1.47,1265.94],[2,1.46,389.5]],"batl":[[0,1.5,218.76],[1,1.51,319.47],[2,1.52,842.37]],"ltp":1.5,"tv":29135.31,"id":9342449},{"trd":[[3,124.96]],"ltp":3.0,"tv":7637.17,"id":9633869}],"tv":36772.48}]}
{"op":"mcm","clk":"4230508796","pt":1631533775016,"mc":[{"id":"1.187557995","rc":[{"batb":[[1,1.48,36.83],[2,1.47,1265.94]],"ltp":1.5,"tv":29135.31,"id":9342449}]}]}
{"op":"mcm","clk":"4230508995","pt":1631533777212,"mc":[{"id":"1.187557995","rc":[{"trd":[[1.5,2069.56]],"batb":[[1,1.48,88.74]],"batl":[[0,1.5,211.76]],"ltp":1.5,"tv":29149.31,"id":9342449}],"tv":36786.48}]}
{"op":"mcm","clk":"4230509114","pt":1631533778517,"mc":[{"id":"1.187557995","rc":[{"trd":[[1.47,2321.94],[1.48,6083.74],[1.49,4446.78]],"batb":[[0,1.47,106.35],[1,1.46,389.5],[2,1.42,289.69]],"ltp":1.47,"tv":32167.35,"id":9342449},{"trd":[[3.05,292.2]],"batl":[[0,3.1,99.66],[1,3.15,90.29],[2,3.4,12.39]],"ltp":3.05,"tv":7885.31,"id":9633869}],"tv":40052.66}]}
{"op":"mcm","clk":"4230509393","pt":1631533781546,"mc":[{"id":"1.187557995","rc":[{"batb":[[0,1.47,213.28],[2,1.45,89.44]],"batl":[[1,1.51,447.71]],"ltp":1.47,"tv":32167.35,"id":9342449},{"batl":[[0,3.1,119.72]],"ltp":3.05,"tv":7885.31,"id":9633869}]}]}
{"op":"mcm","clk":"4230509486","pt":1631533782436,"mc":[{"id":"1.187557995","rc":[{"batb":[[0,1.48,33.15],[1,1.47,213.28],[2,1.46,389.5]],"ltp":1.47,"tv":32167.35,"id":9342449},{"batb":[[1,2.9,54.75]],"batl":[[0,3.1,20.06]],"ltp":3.05,"tv":7885.31,"id":9633869}]}]}
{"op":"mcm","clk":"4230509755","pt":1631533785141,"mc":[{"id":"1.187557995","rc":[{"batb":[[0,1.47,213.28],[1,1.46,389.5],[2,1.45,89.44]],"ltp":1.47,"tv":32167.35,"id":9342449}]}]}
{"op":"mcm","clk":"4230509912","pt":1631533786652,"mc":[{"id":"1.187557995","rc":[{"batl":[[0,1.49,1411.77],[1,1.5,211.76],[2,1.51,447.71]],"ltp":1.47,"tv":32167.35,"id":9342449}]}]}
{"op":"mcm","clk":"4230510079","pt":1631533788337,"mc":[{"id":"1.187557995","rc":[{"trd":[[1.49,4466.82]],"batb":[[0,1.47,258.7]],"batl":[[0,1.49,1398.73]],"ltp":1.49,"tv":32187.39,"id":9342449},{"trd":[[3,127.96]],"ltp":3.0,"tv":7888.31,"id":9633869}],"tv":40075.7}]}
{"op":"mcm","clk":"4230510151","pt":1631533789367,"mc":[{"id":"1.187557995","rc":[{"batb":[[0,1.48,7],[1,1.47,258.7],[2,1.46,389.5]],"batl":[[0,1.49,1596.52]],"ltp":1.49,"tv":32187.39,"id":9342449}]}]}
{"op":"mcm","clk":"4230510485","pt":1631533792663,"mc":[{"id":"1.187557995","rc":[{"trd":[[1.48,6097.74]],"batb":[[0,1.47,213.28],[1,1.46,389.5],[2,1.45,89.44]],"batl":[[0,1.48,213.26],[1,1.49,1596.52],[2,1.5,211.76]],"ltp":1.48,"tv":32201.39,"id":9342449},{"batl":[[0,3.15,90.29],[1,3.4,12.39],[2,3.45,4.3]],"ltp":3.0,"tv":7888.31,"id":9633869}],"tv":40089.7}]}
{"op":"mcm","clk":"4230510605","pt":1631533793760,"mc":[{"id":"1.187557995","rc":[{"trd":[[1.48,6119.12]],"batl":[[0,1.48,202.57]],"ltp":1.48,"tv":32222.77,"id":9342449}],"tv":40111.08}]}
{"op":"mcm","clk":"4230511134","pt":1631533798677,"mc":[{"id":"1.187557995","rc":[{"trd":[[1.48,6524.26]],"batb":[[0,1.48,2636.72],[1,1.47,213.28],[2,1.46,216.76]],"batl":[[0,1.49,1596.52],[1,1.5,211.76],[2,1.51,447.71]],"ltp":1.48,"tv":32627.91,"id":9342449},{"batb":[[0,2.9,54.75],[1,2.84,64.19],[2,2.82,75.72]],"batl":[[0,3.15,10.22]],"ltp":3.0,"tv":7888.31,"id":9633869}],"tv":40516.23}]}
{"op":"mcm","clk":"4230511244","pt":1631533799578,"mc":[{"id":"1.187557995","rc":[{"batb":[[1,2.7,2],[2,2.62,61]],"batl":[[0,3.05,3],[1,3.15,10.22],[2,3.4,12.39]],"ltp":3.0,"tv":7888.31,"id":9633869}]}]}
{"op":"mcm","clk":"4230511442","pt":1631533801385,"mc":[{"id":"1.187557995","rc":[{"batl":[[0,1.5,211.76],[1,1.51,447.71],[2,1.52,673.72]],"ltp":1.48,"tv":32627.91,"id":9342449}]}]}
{"op":"mcm","clk":"4230511584","pt":1631533802650,"mc":[{"id":"1.187557995","rc":[{"trd":[[1.5,2075.56]],"batb":[[0,1.49,5],[1,1.48,2636.72],[2,1.47,456.01]],"batl":[[0,1.5,205.76]],"ltp":1.5,"tv":32633.91,"id":9342449},{"trd":[[3,130.96]],"ltp":3.0,"tv":7891.31,"id":9633869}],"tv":40525.23}]}
{"op":"mcm","clk":"4230511777","pt":1631533804548,"mc":[{"id":"1.187557995","rc":[{"trd":[[1.5,2085.56]],"batb":[[1,1.48,2928.2]],"batl":[[0,1.5,200.76]],"ltp":1.5,"tv":32643.91,"id":9342449}],"tv":40535.23}]}
{"op":"mcm","clk":"4230511910","pt":1631533806074,"mc":[{"id":"1.187557995","rc":[{"batb":[[0,1.49,283.98]],"batl":[[0,1.51,447.71],[1,1.52,673.72],[2,1.53,15]],"ltp":1.5,"tv":32643.91,"id":9342449}]}]}
{"op":"mcm","clk":"4230512539","pt":1631533812992,"mc":[{"id":"1.187557995","rc":[{"batb":[[0,2.9,71.48]],"ltp":3.0,"tv":7891.31,"id":9633869}]}]}
{"op":"mcm","clk":"4230512774","pt":1631533815602,"mc":[{"id":"1.187557995","rc":[{"batb":[[1,1.48,291.48],[2,1.47,451.01]],"ltp":1.5,"tv":32643.91,"id":9342449}]}]}
{"op":"mcm","clk":"4230512854","pt":1631533816359,"mc":[{"id":"1.187557995","rc":[{"batb":[[1,1.48,285.48]],"ltp":1.5,"tv":32643.91,"id":9342449},{"batb":[[1,2.72,3],[2,2.7,2]],"ltp":3.0,"tv":7891.31,"id":9633869}]}]}
{"op":"mcm","clk":"4230512948","pt":1631533817459,"mc":[{"id":"1.187557995","rc":[{"batb":[[0,1.45,89.44],[1,1.42,200.25],[2,1.41,89.89]],"batl":[[0,1.52,365],[1,1.53,15],[2,1.95,418.98]],"ltp":1.5,"tv":32643.91,"id":9342449},{"batb":[[0,2.9,7.89]],"batl":[[0,3.15,10.22],[1,3.45,4.3],[2,3.8,3.72]],"ltp":3.0,"tv":7891.31,"id":9633869}]}]}
{"op":"mcm","clk":"4230513074","pt":1631533818601,"mc":[{"id":"1.187557995","rc":[{"batb":[[0,1.42,200.25],[1,1.41,89.89],[2,1.38,449.59]],"batl":[[0,1.95,418.98],[1,2.08,1],[2,8.8,7.23]],"ltp":1.5,"tv":32643.91,"id":9342449},{"batb":[[0,2.72,3],[1,2.7,2],[2,2.62,61]],"batl":[[0,3,3]],"ltp":3.0,"tv":7891.31,"id":9633869}]}]}
{"op":"mcm","clk":"4230513126","pt":1631533819080,"mc":[{"id":"1.187557995","rc":[{"batl":[[0,3.45,4.3],[1,3.8,3.72],[2,3.8,0]],"ltp":3.0,"tv":7891.31,"id":9633869}]}]}
{"op":"mcm","clk":"4230513286","pt":1631533820695,"mc":[{"id":"1.187557995","rc":[{"batb":[[1,1.41,392.13],[2,1.4,262.58]],"batl":[[0,1.59,193.35],[1,1.6,149.43],[2,1.95,418.98]],"ltp":1.5,"tv":32643.91,"id":9342449},{"batb":[[2,2.64,59.16]],"ltp":3.0,"tv":7891.31,"id":9633869}]}]}
{"op":"mcm","clk":"4230513377","pt":1631533821700,"mc":[{"id":"1.187557995","rc":[{"batb":[[1,1.41,89.89],[2,1.38,449.59]],"batl":[[0,1.59,5],[1,1.95,418.98],[2,2.08,1]],"ltp":1.5,"tv":32643.91,"id":9342449}]}]}
{"op":"mcm","clk":"4230513417","pt":1631533821864,"mc":[{"id":"1.187557995","rc":[{"batb":[[0,1.5,59.63],[1,1.42,200.25],[2,1.41,89.89]],"ltp":1.5,"tv":32643.91,"id":9342449}]}]}
{"op":"mcm","clk":"4230513680","pt":1631533824578,"mc":[{"id":"1.187557995","rc":[{"batb":[[1,1.48,303.92],[2,1.47,210.97]],"batl":[[0,1.52,198.5],[1,1.53,177.72],[2,1.59,5]],"ltp":1.5,"tv":32643.91,"id":9342449},{"batb":[[0,2.92,41.94],[1,2.72,3],[2,2.7,2]],"batl":[[0,3.05,40.9],[1,3.45,4.3],[2,3.8,3.72]],"ltp":3.0,"tv":7891.31,"id":9633869}]}]}
{"op":"mcm","clk":"4230513788","pt":1631533825465,"mc":[{"id":"1.187557995","rc":[{"batl":[[0,1.52,158.74],[2,1.58,25]],"ltp":1.5,"tv":32643.91,"id":9342449},{"batb":[[0,2.74,15]],"batl":[[0,3.4,21.5]],"ltp":3.0,"tv":7891.31,"id":9633869}]}]}
{"op":"mcm","clk":"4230514051","pt":1631533828170,"mc":[{"id":"1.187557995","rc":[{"batb":[[1,1.42,200.25],[2,1.41,89.89]],"batl":[[0,1.59,5],[1,1.95,418.98],[2,2.08,1]],"ltp":1.5,"tv":32643.91,"id":9342449},{"batb":[[0,2.72,3],[1,2.64,59.16],[2,2,11.88]],"batl":[[0,3.45,4.3],[1,3.8,3.72],[2,3.8,0]],"ltp":3.0,"tv":7891.31,"id":9633869}]}]}
{"op":"mcm","clk":"4230514176","pt":1631533829604,"mc":[{"id":"1.187557995","rc":[{"batb":[[0,1.5,242.18]],"batl":[[0,1.52,189.76],[1,1.59,5],[2,1.95,418.98]],"ltp":1.5,"tv":32643.91,"id":9342449}]}]}
{"op":"mcm","clk":"4230514194","pt":1631533829829,"mc":[{"id":"1.187557995","rc":[{"batb":[[0,1.5,59.63]],"batl":[[0,1.59,5],[1,1.95,418.98],[2,2.08,1]],"ltp":1.5,"tv":32643.91,"id":9342449}]}]}
{"op":"mcm","clk":"4230514338","pt":1631533831413,"mc":[{"id":"1.187557995","rc":[{"batb":[[2,1.41,392.13]],"batl":[[0,1.59,198.35],[1,1.6,149.43],[2,1.95,418.98]],"ltp":1.5,"tv":32643.91,"id":9342449},{"batb":[[1,2.7,3],[2,2.64,59.16]],"ltp":3.0,"tv":7891.31,"id":9633869}]}]}
{"op":"mcm","clk":"4230514679","pt":1631533834912,"mc":[{"id":"1.187557995","rc":[{"batl":[[0,1.59,5],[1,1.95,418.98],[2,2.08,1]],"ltp":1.5,"tv":32643.91,"id":9342449}]}]}
{"op":"mcm","clk":"4230514811","pt":1631533836378,"mc":[{"id":"1.187557995","rc":[{"batb":[[0,1.42,700.25],[1,1.41,392.13],[2,1.4,262.58]],"ltp":1.5,"tv":32643.91,"id":9342449}]}]}
{"op":"mcm","clk":"4230514920","pt":1631533837587,"mc":[{"id":"1.187557995","rc":[{"batl":[[0,1.47,2602.04],[1,1.48,2525.5],[2,1.49,2525.5]],"ltp":1.5,"tv":32643.91,"id":9342449}]}]}
{"op":"mcm","clk":"4230515006","pt":1631533838570,"mc":[{"id":"1.187557995","rc":[{"trd":[[1.45,478.86]],"batl":[[0,1.45,302.14],[1,1.46,214.48],[2,1.47,1301.02]],"ltp":1.45,"tv":32658.39,"id":9342449},{"trd":[[3.2,9.56]],"ltp":3.2,"tv":7897.87,"id":9633869}],"tv":40556.27}]}
{"op":"mcm","clk":"4230515118","pt":1631533839668,"mc":[{"id":"1.187557995","rc":[{"batb":[[0,3.15,92.38],[1,3.1,7.14],[2,2.86,48.03]],"batl":[[1,3.5,9.48],[2,3.8,3.72]],"ltp":3.2,"tv":7897.87,"id":9633869}]}]}
{"op":"mcm","clk":"4230515209","pt":1631533840710,"mc":[{"id":"1.187557995","rc":[{"batb":[[0,1.43,6],[1,1.42,707.25],[2,1.41,392.13]],"ltp":1.45,"tv":32658.39,"id":9342449},{"batl":[[0,3.35,3],[1,3.4,15.02],[2,3.45,4.3]],"ltp":3.2,"tv":7897.87,"id":9633869}]}]}
{"op":"mcm","clk":"4230515392","pt":1631533842591,"mc":[{"id":"1.187557995","rc":[{"trd":[[1.44,154.63]],"batb":[[0,1.43,275.81]],"batl":[[0,1.44,66.09],[1,1.45,501.06],[2,1.46,214.48]],"ltp":1.44,"tv":32670.15,"id":9342449},{"trd":[[3.25,11.36]],"ltp":3.25,"tv":7903.08,"id":9633869}],"tv":40573.23}]}
{"op":"mcm","clk":"4230515483","pt":1631533843580,"mc":[{"id":"1.187557995","rc":[{"batb":[[0,3.15,110.29]],"ltp":3.25,"tv":7903.08,"id":9633869}]}]}
{"op":"mcm","clk":"4230515545","pt":1631533844212,"mc":[{"id":"1.187557995","rc":[{"trd":[[1.44,285.81]],"batl":[[0,1.45,650.56],[1,1.46,214.48],[2,1.47,1301.02]],"ltp":1.44,"tv":32801.32,"id":9342449},{"batb":[[1,2.86,48.03],[2,2.74,3]],"batl":[[0,3.3,3],[1,3.35,3],[2,3.4,15.02]],"ltp":3.25,"tv":7903.08,"id":9633869}],"tv":40704.41}]}
{"op":"mcm","clk":"4230515679","pt":1631533845613,"mc":[{"id":"1.187557995","rc":[{"batb":[[2,1.41,2885.17]],"ltp":1.44,"tv":32801.32,"id":9342449},{"batb":[[1,2.9,72.44],[2,2.88,88.85]],"ltp":3.25,"tv":7903.08,"id":9633869}]}]}
{"op":"mcm","clk":"4230515751","pt":1631533846297,"mc":[{"id":"1.187557995","rc":[{"batb":[[2,1.41,392.13]],"batl":[[1,1.46,229.48]],"ltp":1.44,"tv":32801.32,"id":9342449}]}]}
{"op":"mcm","clk":"4230515831","pt":1631533847183,"mc":[{"id":"1.187557995","rc":[{"batb":[[0,3.15,117.26]],"ltp":3.25,"tv":7903.08,"id":9633869}]}]}
{"op":"mcm","clk":"4230516035","pt":1631533849419,"mc":[{"id":"1.187557995","rc":[{"batl":[[0,1.45,726.89]],"ltp":1.44,"tv":32801.32,"id":9342449}]}]}
{"op":"mcm","clk":"4230516144","pt":1631533850514,"mc":[{"id":"1.187557995","rc":[{"batb":[[0,1.43,78.33],[1,1.42,500],[2,1.39,356.69]],"batl":[[0,1.45,225.83],[1,1.46,15],[2,1.53,125.46]],"ltp":1.44,"tv":32801.32,"id":9342449},{"batb":[[0,3.15,6.97]],"batl":[[0,3.5,9.48],[1,3.55,73.54],[2,3.6,80.83]],"ltp":3.25,"tv":7903.08,"id":9633869}]}]}
{"op":"mcm","clk":"4230516251","pt":1631533851529,"mc":[{"id":"1.187557995","rc":[{"batb":[[0,1.39,260.62],[1,1.38,228.19],[2,1.37,442.05]],"batl":[[0,1.53,125.46],[1,1.54,157.71],[2,1.55,155.43]],"ltp":1.44,"tv":32801.32,"id":9342449},{"batb":[[0,2.9,72.44],[1,2.88,88.85],[2,2.86,147.98]],"batl":[[0,3.55,73.54],[1,3.6,80.83],[2,3.65,77.78]],"ltp":3.25,"tv":7903.08,"id":9633869}]}]}
{"op":"mcm","clk":"4230516436","pt":1631533853306,"mc":[{"id":"1.187557995","rc":[{"batl":[[0,1.52,281.75],[1,1.53,302.58],[2,1.54,157.71]],"ltp":1.44,"tv":32801.32,"id":9342449}]}]}
{"op":"mcm","clk":"4230516567","pt":1631533854622,"mc":[{"id":"1.187557995","rc":[{"batl":[[0,1.53,131.46],[1,1.54,157.71],[2,1.55,155.43]],"ltp":1.44,"tv":32801.32,"id":9342449},{"batb":[[0,2.9,75.44],[1,2.88,91.85]],"ltp":3.25,"tv":7903.08,"id":9633869}]}]}
{"op":"mcm","clk":"4230516611","pt":1631533855029,"mc":[{"id":"1.187557995","rc":[{"batl":[[0,1.43,3.41],[1,1.53,131.46],[2,1.54,157.71]],"ltp":1.44,"tv":32801.32,"id":9342449}]}]}
{"op":"mcm","clk":"4230516789","pt":1631533856601,"mc":[{"id":"1.187557995","rc":[{"batb":[[0,1.4,500],[1,1.39,260.62],[2,1.38,228.19]],"batl":[[1,1.52,5],[2,1.53,131.46]],"ltp":1.44,"tv":32801.32,"id":9342449},{"batb":[[0,2.92,3],[1,2.9,75.44],[2,2.88,91.85]],"ltp":3.25,"tv":7903.08,"id":9633869}]}]}
{"op":"mcm","clk":"4230516889","pt":1631533857596,"mc":[{"id":"1.187557995","rc":[{"batb":[[0,1.42,364.86],[1,1.41,254.45],[2,1.4,500]],"batl":[[1,1.46,252.87],[2,1.47,208.87]],"ltp":1.44,"tv":32801.32,"id":9342449},{"batb":[[0,3.15,21.23],[1,2.92,3],[2,2.9,75.44]],"batl":[[0,3.35,20.9],[1,3.55,73.54],[2,3.6,80.83]],"ltp":3.25,"tv":7903.08,"id":9633869}]}]}
{"op":"mcm","clk":"4230516919","pt":1631533857910,"mc":[{"id":"1.187557995","rc":[{"batl":[[1,1.46,231.62]],"ltp":1.44,"tv":32801.32,"id":9342449},{"batb":[[0,2.92,3],[1,2.9,75.44],[2,2.88,91.85]],"batl":[[0,3.55,73.54],[1,3.6,80.83],[2,3.65,77.78]],"ltp":3.25,"tv":7903.08,"id":9633869}]}]}
{"op":"mcm","clk":"4230517070","pt":1631533859630,"mc":[{"id":"1.187557995","rc":[{"batl":[[0,3.5,34.22],[1,3.55,73.54],[2,3.6,80.83]],"ltp":3.25,"tv":7903.08,"id":9633869}]}]}
{"op":"mcm","clk":"4230517138","pt":1631533860412,"mc":[{"id":"1.187557995","rc":[{"batl":[[0,1.46,231.62],[1,1.47,208.87],[2,1.52,5]],"ltp":1.44,"tv":32801.32,"id":9342449}]}]}
{"op":"mcm","clk":"4230517233","pt":1631533861311,"mc":[{"id":"1.187557995","rc":[{"batb":[[0,1.4,500],[1,1.39,260.62],[2,1.38,228.19]],"batl":[[0,1.52,5],[1,1.53,131.46],[2,1.54,157.71]],"ltp":1.44,"tv":32801.32,"id":9342449},{"batl":[[0,3.55,73.54],[1,3.6,80.83],[2,3.65,77.78]],"ltp":3.25,"tv":7903.08,"id":9633869}]}]}
{"op":"mcm","clk":"4230517453","pt":1631533863514,"mc":[{"id":"1.187557995","rc":[{"trd":[[1.42,105.88]],"batb":[[0,1.43,145.16],[1,1.4,500],[2,1.39,260.62]],"batl":[[0,1.45,168.45],[1,1.52,5],[2,1.53,131.46]],"ltp":1.42,"tv":32808.14,"id":9342449}],"tv":40711.22}]}
{"op":"mcm","clk":"4230517539","pt":1631533864510,"mc":[{"id":"1.187557995","rc":[{"batb":[[0,1.43,111.56]],"batl":[[0,1.52,286.75],[1,1.53,308.58],[2,1.54,157.71]],"ltp":1.42,"tv":32808.14,"id":9342449}]}]}
{"op":"mcm","clk":"4230517635","pt":1631533865707,"mc":[{"id":"1.187557995","rc":[{"batl":[[0,1.52,5],[1,1.53,6],[2,1.59,5]],"ltp":1.42,"tv":32808.14,"id":9342449},{"batb":[[1,2.9,3],[2,2.88,3]],"ltp":3.25,"tv":7903.08,"id":9633869}]}]}
{"op":"mcm","clk":"4230517649","pt":1631533865809,"mc":[{"id":"1.187557995","rc":[{"batb":[[0,2.94,3],[1,2.92,3],[2,2.9,3]],"ltp":3.25,"tv":7903.08,"id":9633869}]}]}
{"op":"mcm","clk":"4230517781","pt":1631533867113,"mc":[{"id":"1.187557995","rc":[{"batb":[[0,1.4,500],[1,1.39,260.62],[2,1.38,228.19]],"batl":[[1,2.08,1],[2,8.8,7.23]],"ltp":1.42,"tv":32808.14,"id":9342449},{"batb":[[2,2.86,48.03]],"ltp":3.25,"tv":7903.08,"id":9633869}]}]}
{"op":"mcm","clk":"4230517950","pt":1631533868638,"mc":[{"id":"1.187557995","rc":[{"trd":[[1.4,1119.38]],"batb":[[0,1.38,228.19],[1,1.37,442.05],[2,1.36,522.84]],"batl":[[1,1.54,12.99],[2,2.08,1]],"ltp":1.4,"tv":33808.14,"id":9342449},{"batb":[[0,3.5,546.44],[1,3.45,530.36],[2,3.4,530.36]],"batl":[[0,3.65,77.78],[1,3.8,3.72],[2,3.65,0]],"ltp":3.25,"tv":7903.08,"id":9633869}],"tv":41711.22}]}
{"op":"mcm","clk":"4230518044","pt":1631533869559,"mc":[{"id":"1.187557995","rc":[{"batb":[[0,1.37,442.05],[1,1.36,522.84],[2,1.35,314.57]],"batl":[[0,1.4,351.71],[1,1.41,249.51],[2,1.52,5]],"ltp":1.4,"tv":33808.14,"id":9342449},{"trd":[[3.5,16.38]],"batb":[[0,3.5,540.29],[1,3.45,606.43]],"batl":[[0,3.8,3.72],[1,3.8,0]],"ltp":3.5,"tv":7915.38,"id":9633869}],"tv":41723.52}]}
{"op":"mcm","clk":"4230518141","pt":1631533870642,"mc":[{"id":"1.187557995","rc":[{"batl":[[2,1.49,25]],"ltp":1.4,"tv":33808.14,"id":9342449}]}]}
{"op":"mcm","clk":"4230518206","pt":1631533871317,"mc":[{"id":"1.187557995","rc":[{"batl":[[0,3.6,3],[1,3.8,3.72]],"ltp":3.5,"tv":7915.38,"id":9633869}]}]}
{"op":"mcm","clk":"4230518271","pt":1631533871943,"mc":[{"id":"1.187557995","rc":[{"batb":[[0,1.38,7],[1,1.37,485.29],[2,1.36,522.84]],"ltp":1.4,"tv":33808.14,"id":9342449},{"batl":[[1,3.7,3],[2,3.75,17.26]],"ltp":3.5,"tv":7915.38,"id":9633869}]}]}
{"op":"mcm","clk":"4230518543","pt":1631533873620,"mc":[{"id":"1.187557995","rc":[{"batb":[[0,1.38,297.81]],"batl":[[0,1.39,75.19],[1,1.4,526.18],[2,1.41,264.51]],"ltp":1.4,"tv":33808.14,"id":9342449},{"trd":[[3.5,30.06]],"batb":[[0,3.5,533.45]],"ltp":3.5,"tv":7929.06,"id":9633869}],"tv":41737.2}]}
{"op":"mcm","clk":"4230518622","pt":1631533874516,"mc":[{"id":"1.187557995","rc":[{"batl":[[2,1.41,249.51]],"ltp":1.4,"tv":33808.14,"id":9342449}]}]}
{"op":"mcm","clk":"4230518718","pt":1631533875557,"mc":[{"id":"1.187557995","rc":[{"batb":[[1,1.37,3334.61]],"ltp":1.4,"tv":33808.14,"id":9342449},{"batl":[[2,3.75,21.24]],"ltp":3.5,"tv":7929.06,"id":9633869}]}]}
{"op":"mcm","clk":"4230518877","pt":1631533877425,"mc":[{"id":"1.187557995","rc":[{"batb":[[0,1.38,518.42]],"batl":[[0,1.39,309.19],[1,1.4,541.18]],"ltp":1.4,"tv":33808.14,"id":9342449},{"batb":[[0,3.5,539.45]],"batl":[[1,3.65,83.41],[2,3.7,3]],"ltp":3.5,"tv":7929.06,"id":9633869}]}]}
{"op":"mcm","clk":"4230519011","pt":1631533878929,"mc":[{"id":"1.187557995","rc":[{"trd":[[1.39,19.95]],"batb":[[2,1.36,750.27]],"batl":[[0,1.39,306.21]],"ltp":1.39,"tv":33814.09,"id":9342449}],"tv":41743.15}]}
{"op":"mcm","clk":"4230519172","pt":1631533880547,"mc":[{"id":"1.187557995","rc":[{"trd":[[1.39,35.75]],"batb":[[0,1.38,503.96],[1,1.37,3478.26]],"batl":[[0,1.39,396.22],[1,1.4,610.63]],"ltp":1.39,"tv":33829.89,"id":9342449}],"tv":41758.96}]}
{"op":"mcm","clk":"4230519284","pt":1631533881659,"mc":[{"id":"1.187557995","rc":[{"batb":[[0,1.38,378.06],[1,1.37,715.71]],"batl":[[1,1.4,541.18]],"ltp":1.39,"tv":33829.89,"id":9342449}]}]}
{"op":"mcm","clk":"4230519386","pt":1631533882527,"mc":[{"id":"1.187557995","rc":[{"batb":[[0,1.37,8],[1,1.36,95.68],[2,1.34,530.43]],"batl":[[0,1.39,226.1],[1,1.4,15],[2,1.45,159.19]],"ltp":1.39,"tv":33829.89,"id":9342449},{"batb":[[0,3.5,6],[1,3.25,79.28],[2,3.2,92.24]],"batl":[[0,3.8,3.72],[1,3.9,60.6],[2,3.95,83.22]],"ltp":3.5,"tv":7929.06,"id":9633869}]}]}
{"op":"mcm","clk":"4230519484","pt":1631533883460,"mc":[{"id":"1.187557995","rc":[{"batb":[[1,1.34,530.43],[2,1.33,213.12]],"batl":[[0,1.45,159.19],[1,1.46,145.52],[2,1.47,219.11]],"ltp":1.39,"tv":33829.89,"id":9342449},{"batb":[[0,3.25,79.28],[1,3.2,92.24],[2,3.15,103.61]],"batl":[[0,3.9,60.6],[1,3.95,74.49],[2,4,80.53]],"ltp":3.5,"tv":7929.06,"id":9633869}]}]}
{"op":"mcm","clk":"4230519696","pt":1631533885548,"mc":[{"id":"1.187557995","rc":[{"trd":[[1.37,755.74]],"batb":[[0,1.36,9],[2,1.33,535.95]],"batl":[[0,1.37,7050.83],[1,1.45,474.25],[2,1.46,359.95]],"ltp":1.37,"tv":33845.89,"id":9342449},{"batl":[[0,3.75,2],[1,3.8,2],[2,3.9,60.6]],"ltp":3.5,"tv":7929.06,"id":9633869}],"tv":41774.96}]}
{"op":"mcm","clk":"4230519814","pt":1631533886644,"mc":[{"id":"1.187557995","rc":[{"batl":[[1,1.45,481.25]],"ltp":1.37,"tv":33845.89,"id":9342449},{"batb":[[0,3.25,82.28]],"ltp":3.5,"tv":7929.06,"id":9633869}]}]}
{"op":"mcm","clk":"4230520000","pt":1631533888671,"mc":[{"id":"1.187557995","rc":[{"batb":[[1,1.35,9],[2,1.34,538.43]],"batl":[[0,1.45,481.25],[1,1.46,359.95],[2,1.47,219.11]],"ltp":1.37,"tv":33845.89,"id":9342449},{"batl":[[2,3.9,63.6]],"ltp":3.5,"tv":7929.06,"id":9633869}]}]}
{"op":"mcm","clk":"4230521228","pt":1631533900380,"mc":[{"id":"1.187557995","rc":[{"batb":[[1,1.34,530.43],[2,1.33,535.95]],"ltp":1.37,"tv":33845.89,"id":9342449},{"batb":[[1,3.2,89.24]],"batl":[[1,3.9,60.6],[2,3.95,74.49]],"ltp":3.5,"tv":7929.06,"id":9633869}]}]}
{"op":"mcm","clk":"4230521341","pt":1631533901478,"mc":[{"id":"1.187557995","rc":[{"batl":[[0,1.45,7],[1,1.82,479.32],[2,2.08,1]],"ltp":1.37,"tv":33845.89,"id":9342449},{"batb":[[0,3.25,3],[1,3.1,95.9],[2,2,11.88]],"ltp":3.5,"tv":7929.06,"id":9633869}]}]}
{"op":"mcm","clk":"4230521572","pt":1631533903569,"mc":[{"id":"1.187557995","rc":[{"batb":[[1,1.35,7],[2,1.34,530.43]],"ltp":1.37,"tv":33845.89,"id":9342449},{"batb":[[1,3.2,2],[2,3.1,95.9]],"ltp":3.5,"tv":7929.06,"id":9633869}]}]}
{"op":"mcm","clk":"4230521673","pt":1631533904596,"mc":[{"id":"1.187557995","rc":[{"trd":[[1.36,64.41]],"batb":[[0,1.35,7],[1,1.34,530.43],[2,1.33,535.95]],"batl":[[0,1.36,264.27],[1,1.37,1682.03],[2,1.38,1354.92]],"ltp":1.36,"tv":33869.4,"id":9342449},{"trd":[[3.75,2]],"batl":[[0,3.9,60.6],[1,3.95,74.49],[2,4,80.53]],"ltp":3.75,"tv":7931.06,"id":9633869}],"tv":41800.47}]}
{"op":"mcm","clk":"4230521801","pt":1631533905707,"mc":[{"id":"1.187557995","rc":[{"trd":[[1.36,80.4]],"batl":[[0,1.36,248.28]],"ltp":1.36,"tv":33885.39,"id":9342449},{"trd":[[3.75,7.8]],"batb":[[0,3.65,65.27],[1,3.4,77.24],[2,3.25,3]],"ltp":3.75,"tv":7936.86,"id":9633869}],"tv":41822.26}]}
{"op":"mcm","clk":"4230521874","pt":1631533906373,"mc":[{"id":"1.187557995","rc":[{"batb":[[2,3.3,15]],"ltp":3.75,"tv":7936.86,"id":9633869}]}]}
{"op":"mcm","clk":"4230522001","pt":1631533907577,"mc":[{"id":"1.187557995","rc":[{"batl":[[0,1.36,263.28]],"ltp":1.36,"tv":33885.39,"id":9342449},{"batb":[[2,3.3,2]],"batl":[[0,3.85,3],[1,3.9,60.6],[2,3.95,74.49]],"ltp":3.75,"tv":7936.86,"id":9633869}]}]}
{"op":"mcm","clk":"4230522099","pt":1631533908571,"mc":[{"id":"1.187557995","rc":[{"batb":[[0,1.35,84.42],[1,1.34,3617.28]],"batl":[[0,1.36,327.56]],"ltp":1.36,"tv":33885.39,"id":9342449},{"batb":[[0,3.75,5.45],[1,3.65,65.27],[2,3.4,77.24]],"ltp":3.75,"tv":7936.86,"id":9633869}]}]}
{"op":"mcm","clk":"4230522182","pt":1631533909394,"mc":[{"id":"1.187557995","rc":[{"batb":[[1,1.34,3789.04]],"batl":[[0,1.36,519.09]],"ltp":1.36,"tv":33885.39,"id":9342449},{"trd":[[3.75,16.08]],"batb":[[0,3.75,1.31]],"ltp":3.75,"tv":7945.14,"id":9633869}],"tv":41830.54}]}
{"op":"mcm","clk":"4230522283","pt":1631533910389,"mc":[{"id":"1.187557995","rc":[{"trd":[[1.34,882.35],[1.35,1508.26]],"batb":[[0,1.34,3359.63],[1,1.33,535.95],[2,1.32,880.94]],"ltp":1.34,"tv":34921.59,"id":9342449},{"trd":[[3.85,99.15]],"batb":[[1,3.7,15],[2,3.65,65.27]],"batl":[[0,3.9,60.6],[1,3.95,74.49],[2,4,80.53]],"ltp":3.85,"tv":7948.14,"id":9633869}],"tv":42869.74}]}
{"op":"mcm","clk":"4230522374","pt":1631533911377,"mc":[{"id":"1.187557995","rc":[{"batb":[[1,1.33,627.48]],"batl":[[0,1.36,739.09]],"ltp":1.34,"tv":34921.59,"id":9342449}]}]}
{"op":"mcm","clk":"4230522463","pt":1631533912380,"mc":[{"id":"1.187557995","rc":[{"batb":[[0,3.75,21.81]],"ltp":3.85,"tv":7948.14,"id":9633869}]}]}
{"op":"mcm","clk":"4230522586","pt":1631533913577,"mc":[{"id":"1.187557995","rc":[{"batb":[[0,1.34,3368.63]],"ltp":1.34,"tv":34921.59,"id":9342449}]}]}
{"op":"mcm","clk":"4230522885","pt":1631533916493,"mc":[{"id":"1.187557995","rc":[{"batb":[[0,1.34,574.42]],"ltp":1.34,"tv":34921.59,"id":9342449},{"batl":[[0,3.95,146.44],[1,4,80.53],[2,4.1,3.65]],"ltp":3.85,"tv":7948.14,"id":9633869}]}]}
{"op":"mcm","clk":"4230522992","pt":1631533917486,"mc":[{"id":"1.187557995","rc":[{"trd":[[1.34,2031.19]],"batb":[[0,1.33,623.9],[1,1.32,880.94],[2,1.29,1.52]],"batl":[[0,1.34,2954.98],[1,1.36,674.81],[2,1.37,1682.03]],"ltp":1.34,"tv":36070.44,"id":9342449},{"batl":[[0,3.95,75.45],[1,4.1,71.62],[2,4.2,250.45]],"ltp":3.85,"tv":7948.14,"id":9633869}],"tv":44018.59}]}
{"op":"mcm","clk":"4230523110","pt":1631533918687,"mc":[{"id":"1.187557995","rc":[{"trd":[[1.34,2047.19]],"batl":[[0,1.34,2946.98]],"ltp":1.34,"tv":36086.44,"id":9342449},{"batb":[[1,3.65,65.27],[2,3.4,77.24]],"ltp":3.85,"tv":7948.14,"id":9633869}],"tv":44034.59}]}
{"op":"mcm","clk":"4230523223","pt":1631533919676,"mc":[{"id":"1.187557995","rc":[{"trd":[[1.34,2053.01]],"batb":[[0,1.32,289.53],[1,1.29,1.52],[2,1.28,487.18]],"batl":[[0,1.34,2941.16],[1,1.36,235],[2,1.45,7]],"ltp":1.34,"tv":36092.26,"id":9342449},{"trd":[[3.9,15.21]],"batb":[[1,3.4,77.24],[2,3.3,2]],"ltp":3.9,"tv":7950.14,"id":9633869}],"tv":44042.41}]}
{"op":"mcm","clk":"4230523339","pt":1631533920694,"mc":[{"id":"1.187557995","rc":[{"trd":[[1.34,5255.45]],"batl":[[0,1.34,1339.94],[1,1.38,65.75],[2,1.4,61.54]],"ltp":1.34,"tv":39294.7,"id":9342449},{"batb":[[0,3.6,3.04],[1,3.5,4.08],[2,3.4,77.24]],"ltp":3.9,"tv":7950.14,"id":9633869}],"tv":47244.85}]}
{"op":"mcm","clk":"4230523427","pt":1631533921608,"mc":[{"id":"1.187557995","rc":[{"batb":[[0,1.32,371.67],[1,1.31,72.79],[2,1.29,1.52]],"ltp":1.34,"tv":39294.7,"id":9342449},{"batb":[[0,3.8,20.7],[1,3.6,3.04],[2,3.5,4.08]],"batl":[[0,4.2,2.73],[1,4.3,2.55]],"ltp":3.9,"tv":7950.14,"id":9633869}]}]}
{"op":"mcm","clk":"4230523544","pt":1631533922603,"mc":[{"id":"1.187557995","rc":[{"trd":[[1.34,5423.89]],"batb":[[0,1.33,77.53],[1,1.32,82.14],[2,1.31,712.29]],"batl":[[0,1.38,65.75],[1,1.39,250.77],[2,1.4,320.04]],"ltp":1.34,"tv":39463.14,"id":9342449},{"batb":[[0,3.6,3.04],[1,3.5,77.72],[2,3.4,3.21]],"batl":[[0,4.1,3.15],[1,4.2,2.73],[2,4.3,2.55]],"ltp":3.9,"tv":7950.14,"id":9633869}],"tv":47413.29}]}
{"op":"mcm","clk":"4230523637","pt":1631533923501,"mc":[{"id":"1.187557995","rc":[{"batb":[[1,1.32,9],[2,1.31,720.29]],"batl":[[0,1.39,250.77],[1,1.4,320.04],[2,1.41,60.5]],"ltp":1.34,"tv":39463.14,"id":9342449},{"batb":[[0,3.5,77.72],[1,3.4,3.21],[2,3.3,2]],"batl":[[1,4.3,2.55],[2,4.5,3]],"ltp":3.9,"tv":7950.14,"id":9633869}]}]}
{"op":"mcm","clk":"4230523690","pt":1631533924024,"mc":[{"id":"1.187557995","rc":[{"batb":[[0,1.34,3.62],[1,1.33,77.53],[2,1.32,9]],"ltp":1.34,"tv":39463.14,"id":9342449},{"batl":[[1,4.2,3],[2,4.3,2.55]],"ltp":3.9,"tv":7950.14,"id":9633869}]}]}
{"op":"mcm","clk":"4230523855","pt":1631533925702,"mc":[{"id":"1.187557995","rc":[{"batl":[[0,3.95,3.1],[1,4.1,3.15],[2,4.2,3]],"ltp":3.9,"tv":7950.14,"id":9633869}]}]}
{"op":"mcm","clk":"4230523959","pt":1631533926594,"mc":[{"id":"1.187557995","rc":[{"batl":[[0,1.39,6],[1,1.4,61.54]],"ltp":1.34,"tv":39463.14,"id":9342449},{"batb":[[0,3.55,3],[1,3.5,80.72],[2,3.4,3.21]],"batl":[[0,4.1,3.15],[1,4.2,3],[2,4.3,2.55]],"ltp":3.9,"tv":7950.14,"id":9633869}]}]}
{"op":"mcm","clk":"4230524062","pt":1631533927598,"mc":[{"id":"1.187557995","rc":[{"batb":[[0,1.33,77.53],[1,1.32,509],[2,1.31,380.7]],"ltp":1.34,"tv":39463.14,"id":9342449}]}]}
{"op":"mcm","clk":"4230524267","pt":1631533929522,"mc":[{"id":"1.187557995","rc":[{"batb":[[0,1.34,185.5],[1,1.33,414.04],[2,1.32,509]],"batl":[[0,1.37,376.57],[1,1.38,275.1],[2,1.39,6]],"ltp":1.34,"tv":39463.14,"id":9342449}]}]}
{"op":"mcm","clk":"4230524387","pt":1631533930525,"mc":[{"id":"1.187557995","rc":[{"batb":[[1,1.33,460.69]],"batl":[[1,1.38,340.35]],"ltp":1.34,"tv":39463.14,"id":9342449},{"batb":[[0,3.6,3.04],[1,3.55,3],[2,3.5,80.72]],"batl":[[0,4,13.14],[1,4.1,3.15],[2,4.2,3]],"ltp":3.9,"tv":7950.14,"id":9633869}]}]}
{"op":"mcm","clk":"4230524586","pt":1631533932305,"mc":[{"id":"1.187557995","rc":[{"batb":[[0,1.33,77.53],[1,1.32,509],[2,1.31,380.7]],"batl":[[0,1.39,6],[1,1.4,61.54],[2,1.41,60.5]],"ltp":1.34,"tv":39463.14,"id":9342449},{"batb":[[0,3.55,3],[1,3.5,80.72],[2,3.4,3.21]],"batl":[[0,4.1,3.15],[1,4.2,3],[2,4.3,2.55]],"ltp":3.9,"tv":7950.14,"id":9633869}]}]}
{"op":"mcm","clk":"4230524739","pt":1631533933712,"mc":[{"id":"1.187557995","rc":[{"batl":[[0,1.37,35.48],[1,1.39,6],[2,1.4,61.54]],"ltp":1.34,"tv":39463.14,"id":9342449},{"batb":[[0,3.65,18.71],[1,3.55,3],[2,3.5,80.72]],"ltp":3.9,"tv":7950.14,"id":9633869}]}]}
{"op":"mcm","clk":"4230524760","pt":1631533933920,"mc":[{"id":"1.187557995","rc":[{"batl":[[0,1.39,6],[1,1.4,61.54],[2,1.41,60.5]],"ltp":1.34,"tv":39463.14,"id":9342449},{"batb":[[0,3.55,3],[1,3.5,80.72],[2,3.4,3.21]],"ltp":3.9,"tv":7950.14,"id":9633869}]}]}
{"op":"mcm","clk":"4230524918","pt":1631533935535,"mc":[{"id":"1.187557995","rc":[{"batb":[[2,1.31,712.29]],"batl":[[0,1.38,63.25],[1,1.39,256.77],[2,1.4,320.04]],"ltp":1.34,"tv":39463.14,"id":9342449},{"batb":[[0,3.6,3.34],[1,3.55,3],[2,3.5,80.72]],"ltp":3.9,"tv":7950.14,"id":9633869}]}]}
{"op":"mcm","clk":"4230525018","pt":1631533936638,"mc":[{"id":"1.187557995","rc":[{"batl":[[0,1.39,256.77],[1,1.4,320.04],[2,1.41,60.5]],"ltp":1.34,"tv":39463.14,"id":9342449},{"batb":[[0,3.55,3],[1,3.5,80.72],[2,3.4,3.21]],"batl":[[0,3.95,2.9],[1,4.1,3.15],[2,4.2,3]],"ltp":3.9,"tv":7950.14,"id":9633869}]}]}
{"op":"mcm","clk":"4230525045","pt":1631533936947,"mc":[{"id":"1.187557995","rc":[{"batl":[[0,4.1,3.15],[1,4.2,3],[2,4.3,2.55]],"ltp":3.9,"tv":7950.14,"id":9633869}]}]}
{"op":"mcm","clk":"4230525211","pt":1631533938624,"mc":[{"id":"1.187557995","rc":[{"batb":[[2,1.31,372.7]],"ltp":1.34,"tv":39463.14,"id":9342449},{"batb":[[1,3.5,77.72]],"ltp":3.9,"tv":7950.14,"id":9633869}]}]}
{"op":"mcm","clk":"4230525406","pt":1631533940446,"mc":[{"id":"1.187557995","rc":[{"batl":[[0,1.39,250.77]],"ltp":1.34,"tv":39463.14,"id":9342449},{"batb":[[0,3.5,77.72],[1,3.4,3.21],[2,2,11.88]],"batl":[[0,3.95,2.7],[1,4.1,3.15],[2,4.2,3]],"ltp":3.9,"tv":7950.14,"id":9633869}]}]}
{"op":"mcm","clk":"4230525496","pt":1631533941333,"mc":[{"id":"1.187557995","rc":[{"trd":[[1.39,51.23]],"batb":[[0,1.36,259.12],[1,1.35,1729.23],[2,1.34,1384.22]],"batl":[[0,1.39,235.29]],"ltp":1.39,"tv":39478.62,"id":9342449},{"trd":[[3.55,6.06]],"batb":[[1,3.45,304.89],[2,3.4,299.13]],"ltp":3.55,"tv":7956.2,"id":9633869}],"tv":47434.83}]}
{"op":"mcm","clk":"4230525602","pt":1631533942638,"mc":[{"id":"1.187557995","rc":[{"batb":[[0,1.36,503.22],[2,1.34,1453.62]],"batl":[[0,1.39,250.29]],"ltp":1.39,"tv":39478.62,"id":9342449},{"batb":[[0,3.55,23.52],[1,3.5,77.72],[2,3.45,304.89]],"batl":[[1,4,15.75],[2,4.1,11.66]],"ltp":3.55,"tv":7956.2,"id":9633869}]}]}
{"op":"mcm","clk":"4230525693","pt":1631533943675,"mc":[{"id":"1.187557995","rc":[{"batb":[[0,1.37,7],[1,1.36,512.22],[2,1.35,1729.23]],"ltp":1.39,"tv":39478.62,"id":9342449},{"batb":[[1,3.5,95.95]],"batl":[[0,3.75,3],[1,3.9,2],[2,3.95,2.7]],"ltp":3.55,"tv":7956.2,"id":9633869}]}]}
{"op":"mcm","clk":"4230525760","pt":1631533944472,"mc":[{"id":"1.187557995","rc":[{"batb":[[0,1.37,11.13],[2,1.35,1737.23]],"ltp":1.39,"tv":39478.62,"id":9342449},{"batl":[[1,3.85,3],[2,3.9,2]],"ltp":3.55,"tv":7956.2,"id":9633869}]}]}
{"op":"mcm","clk":"4230525864","pt":1631533945446,"mc":[{"id":"1.187557995","rc":[{"batb":[[0,1.37,329.75]],"batl":[[0,1.38,498.28],[1,1.39,250.29],[2,1.4,320.04]],"ltp":1.39,"tv":39478.62,"id":9342449}]}]}
{"op":"mcm","clk":"4230525977","pt":1631533946587,"mc":[{"id":"1.187557995","rc":[{"batb":[[1,1.36,3351.51]],"batl":[[1,1.39,599.19]],"ltp":1.39,"tv":39478.62,"id":9342449},{"batl":[[0,3.7,3],[1,3.75,3],[2,3.85,3]],"ltp":3.55,"tv":7956.2,"id":9633869}]}]}
{"op":"mcm","clk":"4230526039","pt":1631533947276,"mc":[{"id":"1.187557995","rc":[{"batl":[[1,1.39,775.19]],"ltp":1.39,"tv":39478.62,"id":9342449}]}]}
{"op":"mcm","clk":"4230526178","pt":1631533948681,"mc":[{"id":"1.187557995","rc":[{"batb":[[2,1.35,1803.3]],"ltp":1.39,"tv":39478.62,"id":9342449}]}]}
{"op":"mcm","clk":"4230526370","pt":1631533950657,"mc":[{"id":"1.187557995","rc":[{"batb":[[2,1.35,386.64]],"ltp":1.39,"tv":39478.62,"id":9342449},{"batb":[[1,3.5,77.72],[2,3.4,3.21]],"ltp":3.55,"tv":7956.2,"id":9633869}]}]}
{"op":"mcm","clk":"4230526426","pt":1631533951285,"mc":[{"id":"1.187557995","rc":[{"batb":[[0,1.37,72.57],[1,1.36,2839.29],[2,1.35,74.07]],"batl":[[0,1.38,133.65],[1,1.39,15],[2,1.4,61.54]],"ltp":1.39,"tv":39478.62,"id":9342449},{"batb":[[1,3.5,4.08]],"batl":[[0,3.85,3],[1,3.9,4.65],[2,3.95,48.21]],"ltp":3.55,"tv":7956.2,"id":9633869}]}]}
{"op":"mcm","clk":"4230526570","pt":1631533952599,"mc":[{"id":"1.187557995","rc":[{"batl":[[1,1.4,61.54],[2,1.41,60.5]],"ltp":1.39,"tv":39478.62,"id":9342449},{"batb":[[0,3.5,4.08],[1,3.4,3.21],[2,3.35,3.47]],"ltp":3.55,"tv":7956.2,"id":9633869}]}]}
{"op":"mcm","clk":"4230526676","pt":1631533953697,"mc":[{"id":"1.187557995","rc":[{"trd":[[1.36,5758.99],[1.37,900.89]],"batb":[[0,1.35,8],[1,1.34,174.41],[2,1.33,738.63]],"batl":[[0,1.36,617.55],[1,1.38,133.65],[2,1.4,61.54]],"ltp":1.36,"tv":45302.35,"id":9342449},{"batl":[[1,3.9,2]],"ltp":3.55,"tv":7956.2,"id":9633869}],"tv":53258.55}]}
{"op":"mcm","clk":"4230526769","pt":1631533954574,"mc":[{"id":"1.187557995","rc":[{"trd":[[1.36,5767.25]],"batb":[[1,1.34,8],[2,1.33,523.99]],"batl":[[0,1.36,613.42],[1,1.4,61.54],[2,1.41,60.5]],"ltp":1.36,"tv":45310.61,"id":9342449},{"batl":[[2,4.1,3.15]],"ltp":3.55,"tv":7956.2,"id":9633869}],"tv":53266.82}]}
{"op":"mcm","clk":"4230526954","pt":1631533956609,"mc":[{"id":"1.187557995","rc":[{"batb":[[1,1.33,516.99],[2,1.32,349.74]],"ltp":1.36,"tv":45310.61,"id":9342449},{"batl":[[1,4.1,3.15],[2,4.3,2.55]],"ltp":3.55,"tv":7956.2,"id":9633869}]}]}
{"op":"mcm","clk":"4230527149","pt":1631533958396,"mc":[{"id":"1.187557995","rc":[{"batl":[[0,1.82,479.32],[1,2.08,1],[2,8.8,7.23]],"ltp":1.36,"tv":45310.61,"id":9342449},{"batb":[[0,3.35,3.47],[1,3.15,92.47],[2,2,11.88]],"ltp":3.55,"tv":7956.2,"id":9633869}]}]}
{"op":"mcm","clk":"4230527217","pt":1631533959075,"mc":[{"id":"1.187557995","rc":[{"batb":[[1,1.34,500],[2,1.33,516.99]],"ltp":1.36,"tv":45310.61,"id":9342449}]}]}
{"op":"mcm","clk":"4230527389","pt":1631533960600,"mc":[{"id":"1.187557995","rc":[{"batb":[[0,1.34,500],[1,1.33,516.99],[2,1.32,349.74]],"batl":[[0,1.37,2791.98],[1,1.38,2709.86],[2,1.39,2709.86]],"ltp":1.36,"tv":45310.61,"id":9342449},{"batl":[[0,4.1,3.15],[1,4.2,910.72],[2,4.3,886.49]],"ltp":3.55,"tv":7956.2,"id":9633869}]}]}
{"op":"mcm","clk":"4230527511","pt":1631533961601,"mc":[{"id":"1.187557995","rc":[{"trd":[[1.36,5806.5]],"batl":[[0,1.36,397.84],[1,1.37,1680.1],[2,1.38,1354.92]],"ltp":1.36,"tv":45349.86,"id":9342449},{"trd":[[3.75,23.79]],"batb":[[0,3.7,62.68],[1,3.45,73.89],[2,3.4,380.44]],"batl":[[1,4.2,250.45],[2,4.3,245.63]],"ltp":3.75,"tv":7963.91,"id":9633869}],"tv":53313.78}]}
{"op":"mcm","clk":"4230527635","pt":1631533962606,"mc":[{"id":"1.187557995","rc":[{"batl":[[0,1.36,412.84]],"ltp":1.36,"tv":45349.86,"id":9342449},{"batb":[[2,3.35,6.47]],"ltp":3.75,"tv":7963.91,"id":9633869}]}]}
{"op":"mcm","clk":"4230527750","pt":1631533963494,"mc":[{"id":"1.187557995","rc":[{"batl":[[0,1.36,397.84]],"ltp":1.36,"tv":45349.86,"id":9342449},{"batb":[[2,3.4,2]],"ltp":3.75,"tv":7963.91,"id":9633869}]}]}
{"op":"mcm","clk":"4230527869","pt":1631533964691,"mc":[{"id":"1.187557995","rc":[{"batb":[[0,1.34,636.29]],"batl":[[0,1.36,686.06]],"ltp":1.36,"tv":45349.86,"id":9342449}]}]}
{"op":"mcm","clk":"4230527967","pt":1631533965691,"mc":[{"id":"1.187557995","rc":[{"batb":[[0,1.34,693.14]],"batl":[[0,1.35,328.13],[1,1.36,766.55],[2,1.37,1680.1]],"ltp":1.36,"tv":45349.86,"id":9342449},{"batb":[[0,3.8,21.42],[1,3.7,62.68],[2,3.45,73.89]],"ltp":3.75,"tv":7963.91,"id":9633869}]}]}
{"op":"mcm","clk":"4230528040","pt":1631533966325,"mc":[{"id":"1.187557995","rc":[{"batl":[[0,1.35,153.59]],"ltp":1.36,"tv":45349.86,"id":9342449},{"batb":[[0,3.7,62.68],[1,3.45,73.89],[2,3.4,2]],"ltp":3.75,"tv":7963.91,"id":9633869}]}]}
{"op":"mcm","clk":"4230528149","pt":1631533967224,"mc":[{"id":"1.187557995","rc":[{"batl":[[0,4.1,14.83]],"ltp":3.75,"tv":7963.91,"id":9633869}]}]}
{"op":"mcm","clk":"4230528290","pt":1631533968676,"mc":[{"id":"1.187557995","rc":[{"batb":[[1,1.33,524.99]],"batl":[[2,1.37,1739.6]],"ltp":1.36,"tv":45349.86,"id":9342449},{"batb":[[0,3.7,65.5],[1,3.6,3.54],[2,3.55,3.39]],"ltp":3.75,"tv":7963.91,"id":9633869}]}]}
{"op":"mcm","clk":"4230528401","pt":1631533969712,"mc":[{"id":"1.187557995","rc":[{"batb":[[0,1.34,767.3]],"batl":[[0,1.35,444.59],[1,1.36,845.45]],"ltp":1.36,"tv":45349.86,"id":9342449},{"batb":[[0,3.8,21.42],[1,3.7,65.5],[2,3.6,3.54]],"ltp":3.75,"tv":7963.91,"id":9633869}]}]}
{"op":"mcm","clk":"4230528431","pt":1631533970021,"mc":[{"id":"1.187557995","rc":[{"batl":[[1,1.36,766.55]],"ltp":1.36,"tv":45349.86,"id":9342449}]}]}
{"op":"mcm","clk":"4230528676","pt":1631533972418,"mc":[{"id":"1.187557995","rc":[{"trd":[[1.35,1515.49]],"batl":[[0,1.35,712.08]],"ltp":1.35,"tv":45357.1,"id":9342449}],"tv":53321.01}]}
{"op":"mcm","clk":"4230528775","pt":1631533973408,"mc":[{"id":"1.187557995","rc":[{"trd":[[1.34,6958.48]],"batb":[[0,1.33,524.99],[1,1.32,349.74],[2,1.31,72.79]],"batl":[[0,1.34,2071.72],[1,1.35,712.08],[2,1.36,686.06]],"ltp":1.34,"tv":46891.68,"id":9342449}],"tv":54855.6}]}
{"op":"mcm","clk":"4230528880","pt":1631533974708,"mc":[{"id":"1.187557995","rc":[{"batb":[[0,3.95,20],[1,3.8,21.42],[2,3.7,65.5]],"ltp":3.75,"tv":7963.91,"id":9633869}]}]}
{"op":"mcm","clk":"4230528922","pt":1631533975118,"mc":[{"id":"1.187557995","rc":[{"batl":[[0,1.34,2636.43],[1,1.35,562.11]],"ltp":1.34,"tv":46891.68,"id":9342449}]}]}
{"op":"mcm","clk":"4230529060","pt":1631533976634,"mc":[{"id":"1.187557995","rc":[{"trd":[[1.34,6976.48]],"batb":[[0,1.33,633.36]],"batl":[[0,1.34,2899.27]],"ltp":1.34,"tv":46909.69,"id":9342449},{"batl":[[0,4,2],[1,4.1,14.83],[2,4.2,250.45]],"ltp":3.75,"tv":7963.91,"id":9633869}],"tv":54873.6}]}
{"op":"mcm","clk":"4230529099","pt":1631533977094,"mc":[{"id":"1.187557995","rc":[{"batb":[[1,1.32,2479.21]],"ltp":1.34,"tv":46909.69,"id":9342449}]}]}
{"op":"mcm","clk":"4230529271","pt":1631533978704,"mc":[{"id":"1.187557995","rc":[{"batl":[[0,1.34,3003.85]],"ltp":1.34,"tv":46909.69,"id":9342449},{"trd":[[3.95,6]],"batb":[[0,3.95,17]],"ltp":3.95,"tv":7969.91,"id":9633869}],"tv":54879.6}]}
{"op":"mcm","clk":"4230529403","pt":1631533980003,"mc":[{"id":"1.187557995","rc":[{"batb":[[1,3.7,65.5],[2,3.6,3.54]],"ltp":3.95,"tv":7969.91,"id":9633869}]}]}
{"op":"mcm","clk":"4230529648","pt":1631533982431,"mc":[{"id":"1.187557995","rc":[{"trd":[[1.33,1000.14]],"batb":[[0,1.33,172.05],[1,1.32,2550.13]],"ltp":1.33,"tv":47615.57,"id":9342449},{"batb":[[0,3.7,65.5],[1,3.6,3.54],[2,3.55,3.39]],"ltp":3.95,"tv":7969.91,"id":9633869}],"tv":55585.48}]}
{"op":"mcm","clk":"4230529732","pt":1631533983215,"mc":[{"id":"1.187557995","rc":[{"batb":[[0,3.85,21.05],[1,3.7,65.5],[2,3.6,3.54]],"ltp":3.95,"tv":7969.91,"id":9633869}]}]}
{"op":"mcm","clk":"4230530003","pt":1631533985635,"mc":[{"id":"1.187557995","rc":[{"batl":[[0,1.34,2439.14]],"ltp":1.33,"tv":47615.57,"id":9342449},{"trd":[[4,14.38]],"batb":[[0,4,15],[1,3.85,21.05],[2,3.75,16.98]],"batl":[[0,4.1,14.83],[1,4.2,250.45],[2,4.3,245.63]],"ltp":4.0,"tv":7973.91,"id":9633869}],"tv":55589.48}]}
{"op":"mcm","clk":"4230530102","pt":1631533986527,"mc":[{"id":"1.187557995","rc":[{"batb":[[1,1.32,420.66]],"batl":[[0,1.34,376.43]],"ltp":1.33,"tv":47615.57,"id":9342449}]}]}
{"op":"mcm","clk":"4230530419","pt":1631533989706,"mc":[{"id":"1.187557995","rc":[{"batb":[[0,1.33,296.4]],"batl":[[0,1.34,271.84]],"ltp":1.33,"tv":47615.57,"id":9342449},{"trd":[[4,44.38]],"batb":[[0,3.85,21.05],[1,3.75,16.98],[2,3.7,65.5]],"ltp":4.0,"tv":8003.91,"id":9633869}],"tv":55619.48}]}
{"op":"mcm","clk":"4230530510","pt":1631533990641,"mc":[{"id":"1.187557995","rc":[{"batb":[[0,1.29,405.26],[1,1.28,575.59],[2,1.2,2]],"batl":[[0,1.35,291],[1,1.37,59.5],[2,1.38,63.75]],"ltp":1.33,"tv":47615.57,"id":9342449},{"batb":[[1,3.7,2.82],[2,3.6,3.54]],"batl":[[0,4.4,8.13],[1,4.5,2.39],[2,4.6,2.36]],"ltp":4.0,"tv":8003.91,"id":9633869}]}]}
{"op":"mcm","clk":"4230530596","pt":1631533991525,"mc":[{"id":"1.187557995","rc":[{"batl":[[0,1.39,62.5],[1,1.42,6],[2,1.82,479.32]],"ltp":1.33,"tv":47615.57,"id":9342449},{"batb":[[0,3.55,3.39],[1,3.45,73.89],[2,3.4,2]],"batl":[[0,4.5,2.39],[1,4.6,2.36],[2,4.6,0]],"ltp":4.0,"tv":8003.91,"id":9633869}]}]}
{"op":"mcm","clk":"4230530816","pt":1631533993707,"mc":[{"id":"1.187557995","rc":[{"batb":[[0,1.3,10],[1,1.29,455.81],[2,1.28,1326.84]],"batl":[[1,1.4,382.84],[2,1.41,248.87]],"ltp":1.33,"tv":47615.57,"id":9342449},{"batb":[[0,3.55,73.77],[1,3.4,2],[2,2,11.88]],"batl":[[0,4.4,2],[1,4.5,2.39],[2,4.6,2.36]],"ltp":4.0,"tv":8003.91,"id":9633869}]}]}
{"op":"mcm","clk":"4230530857","pt":1631533994126,"mc":[{"id":"1.187557995","rc":[{"batb":[[0,1.29,9.52],[1,1.28,919.15],[2,1.2,2]],"batl":[[1,1.42,6],[2,1.82,479.32]],"ltp":1.33,"tv":47615.57,"id":9342449},{"batl":[[1,4.6,2.36],[2,4.6,0]],"ltp":4.0,"tv":8003.91,"id":9633869}]}]}
{"op":"mcm","clk":"4230530942","pt":1631533995117,"mc":[{"id":"1.187557995","rc":[{"batl":[[0,1.33,50],[1,1.39,70.5],[2,1.42,6]],"ltp":1.33,"tv":47615.57,"id":9342449},{"batb":[[0,3.55,75.77],[1,3.5,2],[2,3.4,2]],"batl":[[1,4.5,3],[2,4.6,2.36]],"ltp":4.0,"tv":8003.91,"id":9633869}]}]}
{"op":"mcm","clk":"4230531078","pt":1631533996626,"mc":[{"id":"1.187557995","rc":[{"batl":[[1,1.34,41.75],[2,1.39,70.5]],"ltp":1.33,"tv":47615.57,"id":9342449},{"batb":[[0,3.95,38.31],[1,3.55,75.77],[2,3.5,2]],"batl":[[0,4.1,41.75],[1,4.4,2],[2,4.5,3]],"ltp":4.0,"tv":8003.91,"id":9633869}]}]}
{"op":"mcm","clk":"4230531169","pt":1631533997516,"mc":[{"id":"1.187557995","rc":[{"batl":[[1,1.39,70.5],[2,1.42,6]],"ltp":1.33,"tv":47615.57,"id":9342449},{"batb":[[0,3.55,75.77],[1,3.5,2],[2,3.4,2]],"batl":[[0,4.4,2],[1,4.5,3],[2,4.6,2.36]],"ltp":4.0,"tv":8003.91,"id":9633869}]}]}
{"op":"mcm","clk":"4230531244","pt":1631533998347,"mc":[{"id":"1.187557995","rc":[{"batb":[[0,1.32,255.85],[1,1.31,365.33],[2,1.3,47.6]],"batl":[[1,1.35,373.27],[2,1.36,294.79]],"ltp":1.33,"tv":47615.57,"id":9342449},{"batb":[[0,3.6,47.93],[1,3.55,75.77],[2,3.5,2]],"batl":[[0,4.3,10],[1,4.4,2],[2,4.5,3]],"ltp":4.0,"tv":8003.91,"id":9633869}]}]}
{"op":"mcm","clk":"4230531348","pt":1631533999544,"mc":[{"id":"1.187557995","rc":[{"batb":[[0,3.7,3.02],[1,3.6,47.93],[2,3.55,75.77]],"ltp":4.0,"tv":8003.91,"id":9633869}]}]}
{"op":"mcm","clk":"4230531418","pt":1631534000232,"mc":[{"id":"1.187557995","rc":[{"batb":[[0,1.29,9.52],[1,1.28,919.15],[2,1.2,2]],"batl":[[1,1.39,70.5],[2,1.42,6]],"ltp":1.33,"tv":47615.57,"id":9342449},{"batb":[[0,3.55,75.77],[1,3.5,2],[2,3.4,2]],"batl":[[0,4.4,2],[1,4.5,3],[2,4.6,2.36]],"ltp":4.0,"tv":8003.91,"id":9633869}]}]}
{"op":"mcm","clk":"4230531540","pt":1631534001538,"mc":[{"id":"1.187557995","rc":[{"batl":[[0,1.39,70.5],[1,1.42,6],[2,1.82,479.32]],"ltp":1.33,"tv":47615.57,"id":9342449}]}]}
{"op":"mcm","clk":"4230531733","pt":1631534003472,"mc":[{"id":"1.187557995","rc":[{"batl":[[0,1.37,68.5],[1,1.39,70.5],[2,1.42,6]],"ltp":1.33,"tv":47615.57,"id":9342449},{"batb":[[0,3.7,2.72],[1,3.55,75.77],[2,3.5,2]],"ltp":4.0,"tv":8003.91,"id":9633869}]}]}
{"op":"mcm","clk":"4230531841","pt":1631534004669,"mc":[{"id":"1.187557995","rc":[{"trd":[[1.3,604.7]],"batl":[[0,1.39,70.5],[1,1.42,6],[2,1.82,479.32]],"ltp":1.3,"tv":47715.57,"id":9342449},{"batb":[[0,3.55,75.77],[1,3.5,2],[2,3.4,2]],"ltp":4.0,"tv":8003.91,"id":9633869}],"tv":55719.48}]}
{"op":"mcm","clk":"4230531939","pt":1631534005665,"mc":[{"id":"1.187557995","rc":[{"batb":[[0,1.33,179.29],[1,1.32,349.75],[2,1.29,9.52]],"batl":[[0,1.36,412.38],[1,1.37,284.12],[2,1.39,70.5]],"ltp":1.3,"tv":47715.57,"id":9342449},{"batl":[[0,4.4,2.09]],"ltp":4.0,"tv":8003.91,"id":9633869}]}]}
{"op":"mcm","clk":"4230532048","pt":1631534006656,"mc":[{"id":"1.187557995","rc":[{"batb":[[2,1.3,1674.82]],"batl":[[0,1.34,23.86],[1,1.36,724.81],[2,1.37,284.12]],"ltp":1.3,"tv":47715.57,"id":9342449},{"batb":[[1,2,11.88],[2,1.97,1.05]],"batl":[[1,4.6,2.36],[2,4.6,0]],"ltp":4.0,"tv":8003.91,"id":9633869}]}]}
{"op":"mcm","clk":"4230532131","pt":1631534007440,"mc":[{"id":"1.187557995","rc":[{"batb":[[2,1.3,1722.42]],"batl":[[1,1.36,781.92]],"ltp":1.3,"tv":47715.57,"id":9342449}]}]}
{"op":"mcm","clk":"4230532255","pt":1631534008646,"mc":[{"id":"1.187557995","rc":[{"batl":[[0,1.35,293.36]],"ltp":1.3,"tv":47715.57,"id":9342449}]}]}
{"op":"mcm","clk":"4230532288","pt":1631534008956,"mc":[{"id":"1.187557995","rc":[{"batl":[[1,1.36,724.81]],"ltp":1.3,"tv":47715.57,"id":9342449}]}]}
{"op":"mcm","clk":"4230532472","pt":1631534010642,"mc":[{"id":"1.187557995","rc":[{"batb":[[0,1.33,183.19],[2,1.3,1674.82]],"ltp":1.3,"tv":47715.57,"id":9342449},{"batl":[[0,4.4,2]],"ltp":4.0,"tv":8003.91,"id":9633869}]}]}
{"op":"mcm","clk":"4230532543","pt":1631534011376,"mc":[{"id":"1.187557995","rc":[{"batb":[[0,1.33,3.9],[1,1.29,9.52],[2,1.28,911.15]],"batl":[[0,1.39,70.5],[1,1.82,479.32],[2,2.08,1]],"ltp":1.3,"tv":47715.57,"id":9342449}]}]}
{"op":"mcm","clk":"4230532769","pt":1631534013640,"mc":[{"id":"1.187557995","rc":[{"batb":[[0,3.85,13.5],[1,3.55,75.77],[2,2,11.88]],"ltp":4.0,"tv":8003.91,"id":9633869}]}]}
{"op":"mcm","clk":"4230532820","pt":1631534014161,"mc":[{"id":"1.187557995","rc":[{"batb":[[1,1.29,264.59],[2,1.28,1326.84]],"batl":[[1,1.4,382.84],[2,1.41,248.87]],"ltp":1.3,"tv":47715.57,"id":9342449},{"batb":[[0,3.55,75.77],[1,3.5,3]],"ltp":4.0,"tv":8003.91,"id":9633869}]}]}
{"op":"mcm","clk":"4230533186","pt":1631534017984,"mc":[{"id":"1.187557995","rc":[{"batb":[[1,1.29,9.52],[2,1.28,911.15]],"batl":[[0,1.39,8]],"ltp":1.3,"tv":47715.57,"id":9342449}]}]}
{"op":"mcm","clk":"4230533332","pt":1631534019295,"mc":[{"id":"1.187557995","rc":[{"trd":[[1.33,1007.95]],"batb":[[0,1.29,9.52],[1,1.28,911.15],[2,1.2,2]],"batl":[[0,1.33,23.36],[1,1.36,23.51],[2,1.39,8]],"ltp":1.33,"tv":47723.37,"id":9342449}],"tv":55727.29}]}
{"op":"mcm","clk":"4230533446","pt":1631534020493,"mc":[{"id":"1.187557995","rc":[{"trd":[[1.33,1054.66],[1.36,5853.52]],"batb":[[0,1.36,2812.5],[1,1.35,2729.78],[2,1.34,2729.78]],"batl":[[0,1.4,382.84],[1,1.41,248.87],[2,1.82,479.32]],"ltp":1.36,"tv":47817.11,"id":9342449},{"trd":[[3.55,18.18]],"batb":[[0,3.55,67.71],[1,3.35,1141.78],[2,3.3,1108.2]],"ltp":3.55,"tv":8016.03,"id":9633869}],"tv":55833.15}]}
{"op":"mcm","clk":"4230533586","pt":1631534021695,"mc":[{"id":"1.187557995","rc":[{"batb":[[0,1.36,1798.36],[1,1.35,1931.05],[2,1.34,3242.68]],"batl":[[2,1.53,13.07]],"ltp":1.36,"tv":47817.11,"id":9342449},{"batb":[[1,3.35,395.33],[2,3.3,304.76]],"ltp":3.55,"tv":8016.03,"id":9633869}]}]}
{"op":"mcm","clk":"4230533700","pt":1631534022699,"mc":[{"id":"1.187557995","rc":[{"batb":[[2,1.34,1364.88]],"ltp":1.36,"tv":47817.11,"id":9342449},{"batl":[[0,4.1,8.51],[1,4.3,10],[2,4.4,2]],"ltp":3.55,"tv":8016.03,"id":9633869}]}]}
{"op":"mcm","clk":"4230533786","pt":1631534023581,"mc":[{"id":"1.187557995","rc":[{"batb":[[0,1.37,6],[1,1.36,1806.36],[2,1.35,1931.05]],"batl":[[0,1.39,36.24],[1,1.4,382.84],[2,1.41,248.87]],"ltp":1.36,"tv":47817.11,"id":9342449},{"batl":[[0,3.75,3],[1,4.1,8.51],[2,4.3,2]],"ltp":3.55,"tv":8016.03,"id":9633869}]}]}
{"op":"mcm","clk":"4230534017","pt":1631534025673,"mc":[{"id":"1.187557995","rc":[{"batb":[[0,1.37,72.45],[2,1.35,4851.47]],"batl":[[0,1.38,273.91],[1,1.39,366.17],[2,1.4,382.84]],"ltp":1.36,"tv":47817.11,"id":9342449}]}]}
{"op":"mcm","clk":"4230534139","pt":1631534026687,"mc":[{"id":"1.187557995","rc":[{"trd":[[1.36,6692.56],[1.37,1045.78]],"batb":[[0,1.36,1386.84],[1,1.35,4851.47],[2,1.34,1364.88]],"batl":[[2,1.4,397.84]],"ltp":1.36,"tv":48801.05,"id":9342449},{"batb":[[1,3.5,24],[2,3.35,395.33]],"batl":[[0,3.7,3],[1,3.75,3],[2,4,25.07]],"ltp":3.55,"tv":8016.03,"id":9633869}],"tv":56817.08}]}
{"op":"mcm","clk":"4230534187","pt":1631534027198,"mc":[{"id":"1.187557995","rc":[{"batl":[[1,1.39,567.17]],"ltp":1.36,"tv":48801.05,"id":9342449}]}]}
{"op":"mcm","clk":"4230534254","pt":1631534027985,"mc":[{"id":"1.187557995","rc":[{"batl":[[0,1.38,525.04]],"ltp":1.36,"tv":48801.05,"id":9342449}]}]}
{"op":"mcm","clk":"4230534423","pt":1631534029713,"mc":[{"id":"1.187557995","rc":[{"batb":[[0,1.37,60.58],[1,1.36,1386.84],[2,1.35,4851.47]],"batl":[[0,1.38,593.53]],"ltp":1.36,"tv":48801.05,"id":9342449},{"batb":[[0,3.55,121.58]],"ltp":3.55,"tv":8016.03,"id":9633869}]}]}
{"op":"mcm","clk":"4230534525","pt":1631534030699,"mc":[{"id":"1.187557995","rc":[{"trd":[[1.36,9474.51],[1.37,1175.04]],"batb":[[0,1.35,4851.47],[1,1.34,1364.88],[2,1.33,104.44]],"batl":[[0,1.36,2065.62],[1,1.38,593.53],[2,1.39,488.01]],"ltp":1.36,"tv":51712.26,"id":9342449},{"trd":[[3.7,3],[3.75,26.79]],"batl":[[0,4.3,2],[1,4.4,2],[2,4.6,2.36]],"ltp":3.75,"tv":8022.03,"id":9633869}],"tv":59734.29}]}
{"op":"mcm","clk":"4230534611","pt":1631534031593,"mc":[{"id":"1.187557995","rc":[{"batl":[[1,1.38,251.13]],"ltp":1.36,"tv":51712.26,"id":9342449},{"batl":[[0,3.95,8.73],[1,4.3,2],[2,4.4,2]],"ltp":3.75,"tv":8022.03,"id":9633869}]}]}
{"op":"mcm","clk":"4230534831","pt":1631534033681,"mc":[{"id":"1.187557995","rc":[{"trd":[[1.36,10570.73]],"batb":[[0,1.35,4908.07]],"batl":[[0,1.36,1517.51],[1,1.37,281.19],[2,1.38,251.13]],"ltp":1.36,"tv":52808.48,"id":9342449},{"batb":[[0,3.55,191.19]],"batl":[[1,4.2,25.07],[2,4.3,2]],"ltp":3.75,"tv":8022.03,"id":9633869}],"tv":60830.51}]}
{"op":"mcm","clk":"4230534944","pt":1631534034677,"mc":[{"id":"1.187557995","rc":[{"batb":[[0,1.35,575.17],[1,1.33,104.44],[2,1.31,293.22]],"batl":[[0,1.37,281.19],[1,1.38,251.13],[2,1.39,722.75]],"ltp":1.36,"tv":52808.48,"id":9342449},{"batb":[[0,3.55,67.71],[2,3.35,81.34]],"batl":[[1,4.3,2],[2,4.4,2]],"ltp":3.75,"tv":8022.03,"id":9633869}]}]}
{"op":"mcm","clk":"4230535030","pt":1631534035408,"mc":[{"id":"1.187557995","rc":[{"batb":[[0,1.35,9.53],[2,1.31,292.97]],"batl":[[0,1.4,15],[1,1.82,479.32],[2,2.08,1]],"ltp":1.36,"tv":52808.48,"id":9342449},{"batb":[[0,3.5,24],[1,3.35,81.34],[2,2,11.88]],"batl":[[2,4.6,2.36]],"ltp":3.75,"tv":8022.03,"id":9633869}]}]}
{"op":"mcm","clk":"4230535194","pt":1631534036712,"mc":[{"id":"1.187557995","rc":[{"batb":[[0,1.31,293.5],[1,1.29,1.52],[2,1.28,575.59]],"batl":[[0,1.82,479.32],[1,2.08,1],[2,8.8,7.23]],"ltp":1.36,"tv":52808.48,"id":9342449},{"batb":[[0,3.35,81.34],[1,2,11.88],[2,1.97,1.05]],"batl":[[0,4.3,2],[1,4.6,2.36],[2,4.6,0]],"ltp":3.75,"tv":8022.03,"id":9633869}]}]}
{"op":"mcm","clk":"4230535288","pt":1631534037605,"mc":[{"id":"1.187557995","rc":[{"trd":[[1.38,636.88]],"batb":[[0,1.36,9],[1,1.31,292.97],[2,1.29,1.52]],"ltp":1.38,"tv":52809.54,"id":9342449},{"batl":[[0,3.75,3],[1,3.85,2],[2,4.3,2]],"ltp":3.75,"tv":8022.03,"id":9633869}],"tv":60831.57}]}
{"op":"mcm","clk":"4230535413","pt":1631534038699,"mc":[{"id":"1.187557995","rc":[{"batb":[[0,1.31,292.97],[1,1.29,1.52],[2,1.28,575.59]],"ltp":1.38,"tv":52809.54,"id":9342449},{"batl":[[0,4.3,2],[1,4.6,2.36],[2,4.3,0]],"ltp":3.75,"tv":8022.03,"id":9633869}]}]}
{"op":"mcm","clk":"4230535503","pt":1631534039479,"mc":[{"id":"1.187557995","rc":[{"batl":[[0,1.43,6],[1,1.82,479.32],[2,2.08,1]],"ltp":1.38,"tv":52809.54,"id":9342449},{"batb":[[0,3.35,84.34],[1,3.3,2],[2,2,11.88]],"ltp":3.75,"tv":8022.03,"id":9633869}]}]}
{"op":"mcm","clk":"4230535636","pt":1631534040686,"mc":[{"id":"1.187557995","rc":[{"batb":[[0,1.31,301.97],[1,1.3,9],[2,1.29,1.52]],"batl":[[0,1.4,4],[1,1.43,6],[2,1.82,479.32]],"ltp":1.38,"tv":52809.54,"id":9342449}]}]}
{"op":"mcm","clk":"4230535744","pt":1631534041577,"mc":[{"id":"1.187557995","rc":[{"batb":[[0,1.34,470.9],[1,1.33,343.43],[2,1.31,301.97]],"batl":[[0,1.37,402.94],[1,1.38,396.86],[2,1.39,268.7]],"ltp":1.38,"tv":52809.54,"id":9342449}]}]}
{"op":"mcm","clk":"4230535829","pt":1631534042417,"mc":[{"id":"1.187557995","rc":[{"batb":[[2,1.32,71.13]],"ltp":1.38,"tv":52809.54,"id":9342449},{"batb":[[0,3.4,48.9],[1,3.35,84.34],[2,3.3,2]],"batl":[[0,4.2,10],[1,4.3,2],[2,4.6,2.36]],"ltp":3.75,"tv":8022.03,"id":9633869}]}]}
{"op":"mcm","clk":"4230535958","pt":1631534043680,"mc":[{"id":"1.187557995","rc":[{"batb":[[0,3.5,3],[1,3.45,3],[2,3.4,48.9]],"ltp":3.75,"tv":8022.03,"id":9633869}]}]}
{"op":"mcm","clk":"4230535993","pt":1631534043994,"mc":[{"id":"1.187557995","rc":[{"batb":[[2,3.35,84.34]],"ltp":3.75,"tv":8022.03,"id":9633869}]}]}
{"op":"mcm","clk":"4230536182","pt":1631534045622,"mc":[{"id":"1.187557995","rc":[{"batb":[[0,1.34,678.9]],"batl":[[0,1.37,444.17]],"ltp":1.38,"tv":52809.54,"id":9342449}]}]}
{"op":"mcm","clk":"4230536270","pt":1631534046512,"mc":[{"id":"1.187557995","rc":[{"batb":[[2,1.31,301.97]],"ltp":1.38,"tv":52809.54,"id":9342449},{"batl":[[0,4.3,2],[1,4.6,2.36],[2,4.6,0]],"ltp":3.75,"tv":8022.03,"id":9633869}]}]}
{"op":"mcm","clk":"4230536338","pt":1631534047294,"mc":[{"id":"1.187557995","rc":[{"batb":[[0,1.31,301.97],[1,1.3,9],[2,1.29,1.52]],"batl":[[0,1.37,11.57],[1,1.4,6],[2,1.42,6]],"ltp":1.38,"tv":52809.54,"id":9342449}]}]}
{"op":"mcm","clk":"4230536562","pt":1631534049695,"mc":[{"id":"1.187557995","rc":[{"batb":[[0,1.31,793.62],[1,1.3,397.8]],"batl":[[2,1.42,186.87]],"ltp":1.38,"tv":52809.54,"id":9342449}]}]}
{"op":"mcm","clk":"4230536668","pt":1631534050739,"mc":[{"id":"1.187557995","rc":[{"batl":[[2,1.42,6]],"ltp":1.38,"tv":52809.54,"id":9342449}]}]}
{"op":"mcm","clk":"4230536861","pt":1631534052635,"mc":[{"id":"1.187557995","rc":[{"batb":[[1,1.3,388.8]],"ltp":1.38,"tv":52809.54,"id":9342449},{"batb":[[2,3.35,81.34]],"ltp":3.75,"tv":8022.03,"id":9633869}]}]}
{"op":"mcm","clk":"4230536962","pt":1631534053628,"mc":[{"id":"1.187557995","rc":[{"batb":[[2,1.29,2966.64]],"batl":[[0,1.34,199.55],[1,1.35,311.58],[2,1.37,11.57]],"ltp":1.38,"tv":52809.54,"id":9342449},{"batb":[[0,3.9,980.78],[1,3.85,951.92],[2,3.8,951.92]],"ltp":3.75,"tv":8022.03,"id":9633869}]}]}
{"op":"mcm","clk":"4230537063","pt":1631534054514,"mc":[{"id":"1.187557995","rc":[{"batb":[[2,1.29,1484.08]],"ltp":1.38,"tv":52809.54,"id":9342449},{"trd":[[3.9,26.63]],"batb":[[0,3.9,484.69],[1,3.85,533.36],[2,3.8,475.96]],"ltp":3.9,"tv":8033.45,"id":9633869}],"tv":60842.99}]}
{"op":"mcm","clk":"4230537148","pt":1631534055416,"mc":[{"id":"1.187557995","rc":[{"batb":[[0,1.32,500],[1,1.31,793.62],[2,1.3,388.8]],"batl":[[2,1.36,15]],"ltp":1.38,"tv":52809.54,"id":9342449},{"batb":[[2,3.8,497.38]],"batl":[[1,4.4,8.13],[2,4.6,2.36]],"ltp":3.9,"tv":8033.45,"id":9633869}]}]}
{"op":"mcm","clk":"4230537216","pt":1631534056142,"mc":[{"id":"1.187557995","rc":[{"batb":[[2,1.3,398.8]],"ltp":1.38,"tv":52809.54,"id":9342449}]}]}
{"op":"mcm","clk":"4230537351","pt":1631534057706,"mc":[{"id":"1.187557995","rc":[{"batl":[[2,1.4,6]],"ltp":1.38,"tv":52809.54,"id":9342449}]}]}
{"op":"mcm","clk":"4230537434","pt":1631534058644,"mc":[{"id":"1.187557995","rc":[{"batb":[[0,1.32,697.58],[1,1.31,869.95]],"batl":[[0,1.33,492.79],[1,1.34,618.41],[2,1.35,373.37]],"ltp":1.38,"tv":52809.54,"id":9342449},{"batb":[[0,3.95,12.75],[1,3.9,484.69],[2,3.85,533.36]],"batl":[[0,4.2,3],[1,4.3,12],[2,4.4,8.13]],"ltp":3.9,"tv":8033.45,"id":9633869}]}]}
{"op":"mcm","clk":"4230537499","pt":1631534059330,"mc":[{"id":"1.187557995","rc":[{"batb":[[0,1.32,705.58]],"batl":[[1,1.34,806.41]],"ltp":1.38,"tv":52809.54,"id":9342449},{"batl":[[0,4.1,3],[1,4.2,3],[2,4.3,12]],"ltp":3.9,"tv":8033.45,"id":9633869}]}]}
{"op":"mcm","clk":"4230537714","pt":1631534061528,"mc":[{"id":"1.187557995","rc":[{"batb":[[1,1.31,3163.92]],"batl":[[2,1.35,388.37]],"ltp":1.38,"tv":52809.54,"id":9342449}]}]}
{"op":"mcm","clk":"4230537810","pt":1631534062534,"mc":[{"id":"1.187557995","rc":[{"batb":[[0,1.32,785.07]],"batl":[[1,1.34,863.59]],"ltp":1.38,"tv":52809.54,"id":9342449},{"batb":[[1,3.9,505.37]],"ltp":3.9,"tv":8033.45,"id":9633869}]}]}
{"op":"mcm","clk":"4230537901","pt":1631534063522,"mc":[{"id":"1.187557995","rc":[{"trd":[[1.33,1055.01]],"batb":[[0,1.32,705.58],[1,1.31,3087.58]],"batl":[[0,1.33,492.44],[2,1.35,326.58]],"ltp":1.33,"tv":52809.88,"id":9342449},{"trd":[[4,44.5]],"ltp":4.0,"tv":8033.57,"id":9633869}],"tv":60843.46}]}
{"op":"mcm","clk":"4230538087","pt":1631534065552,"mc":[{"id":"1.187557995","rc":[{"trd":[[1.33,1155.01]],"batl":[[0,1.33,442.44]],"ltp":1.33,"tv":52909.88,"id":9342449}],"tv":60943.46}]}
{"op":"mcm","clk":"4230538174","pt":1631534066540,"mc":[{"id":"1.187557995","rc":[{"batb":[[0,1.32,583.6],[1,1.31,2207.17],[2,1.3,10]],"batl":[[1,1.34,245.18],[2,1.35,15]],"ltp":1.33,"tv":52909.88,"id":9342449},{"batb":[[0,3.9,20.68],[1,3.7,3.12],[2,3.65,3]],"batl":[[2,4.3,2]],"ltp":4.0,"tv":8033.57,"id":9633869}]}]}
{"op":"mcm","clk":"4230538248","pt":1631534067530,"mc":[{"id":"1.187557995","rc":[{"batb":[[0,1.32,575.6],[1,1.29,1.52],[2,1.28,575.59]],"batl":[[1,1.34,57.18],[2,1.37,72.5]],"ltp":1.33,"tv":52909.88,"id":9342449},{"batb":[[0,3.7,3.12],[1,3.65,3],[2,3.6,2]],"batl":[[0,4.6,2.36],[1,5,2.15],[2,4.3,0]],"ltp":4.0,"tv":8033.57,"id":9633869}]}]}
{"op":"mcm","clk":"4230538282","pt":1631534067946,"mc":[{"id":"1.187557995","rc":[{"batb":[[0,1.32,75.6]],"ltp":1.33,"tv":52909.88,"id":9342449},{"batb":[[1,3.6,2],[2,3.55,69.87]],"ltp":4.0,"tv":8033.57,"id":9633869}]}]}
{"op":"mcm","clk":"4230538428","pt":1631534069559,"mc":[{"id":"1.187557995","rc":[{"batb":[[0,1.29,1.52],[1,1.28,575.59],[2,1.27,348.78]],"batl":[[0,1.4,66.69],[1,1.82,479.32],[2,2.08,1]],"ltp":1.33,"tv":52909.88,"id":9342449},{"batb":[[0,3.6,2],[1,3.55,69.87],[2,3.5,7.08]],"ltp":4.0,"tv":8033.57,"id":9633869}]}]}
{"op":"mcm","clk":"4230538508","pt":1631534070645,"mc":[{"id":"1.187557995","rc":[{"batl":[[0,4.5,3],[1,4.6,2.36],[2,5,2.15]],"ltp":4.0,"tv":8033.57,"id":9633869}]}]}
{"op":"mcm","clk":"4230538529","pt":1631534070848,"mc":[{"id":"1.187557995","rc":[{"batl":[[0,4.6,2.36],[1,5,2.15],[2,5,0]],"ltp":4.0,"tv":8033.57,"id":9633869}]}]}
{"op":"mcm","clk":"4230538644","pt":1631534072352,"mc":[{"id":"1.187557995","rc":[{"batb":[[0,1.31,174.9],[1,1.3,384.22],[2,1.29,1.52]],"batl":[[0,1.32,104.59],[1,1.33,173.73],[2,1.34,323.75]],"ltp":1.33,"tv":52909.88,"id":9342449},{"batb":[[0,3.7,3.22],[1,3.6,2],[2,3.55,72.87]],"batl":[[0,4.6,5.36]],"ltp":4.0,"tv":8033.57,"id":9633869}]}]}
{"op":"mcm","clk":"4230538742","pt":1631534073444,"mc":[{"id":"1.187557995","rc":[{"batb":[[2,1.29,9.12]],"ltp":1.33,"tv":52909.88,"id":9342449},{"batl":[[0,4.5,11.8],[1,4.6,5.36],[2,5,2.15]],"ltp":4.0,"tv":8033.57,"id":9633869}]}]}
{"op":"mcm","clk":"4230538778","pt":1631534073815,"mc":[{"id":"1.187557995","rc":[{"batb":[[2,1.29,509.12]],"ltp":1.33,"tv":52909.88,"id":9342449}]}]}
{"op":"mcm","clk":"4230538922","pt":1631534075523,"mc":[{"id":"1.187557995","rc":[{"trd":[[1.32,80.06]],"batb":[[2,1.29,501.52]],"batl":[[0,1.32,145.84]],"ltp":1.32,"tv":52969.38,"id":9342449},{"batl":[[0,4.6,5.36],[1,5,2.15],[2,5,0]],"ltp":4.0,"tv":8033.57,"id":9633869}],"tv":61002.96}]}
{"op":"mcm","clk":"4230539035","pt":1631534076658,"mc":[{"id":"1.187557995","rc":[{"batb":[[0,1.29,501.52],[1,1.28,586.59],[2,1.27,356.78]],"batl":[[0,1.32,74.84],[1,1.37,68.5],[2,1.38,7]],"ltp":1.32,"tv":52969.38,"id":9342449},{"batb":[[0,3.75,16.1],[1,3.7,3.22],[2,3.6,2]],"ltp":4.0,"tv":8033.57,"id":9633869}]}]}
{"op":"mcm","clk":"4230539060","pt":1631534076923,"mc":[{"id":"1.187557995","rc":[{"batl":[[1,1.38,7],[2,1.39,7]],"ltp":1.32,"tv":52969.38,"id":9342449},{"batb":[[0,3.6,2],[1,3.55,72.87],[2,3.5,4.08]],"ltp":4.0,"tv":8033.57,"id":9633869}]}]}
{"op":"mcm","clk":"4230539290","pt":1631534079633,"mc":[{"id":"1.187557995","rc":[{"batb":[[0,1.29,510.52]],"ltp":1.32,"tv":52969.38,"id":9342449}]}]}
{"op":"mcm","clk":"4230539501","pt":1631534082070,"mc":[{"id":"1.187557995","rc":[{"batb":[[0,1.29,501.52],[1,1.28,775.59],[2,1.27,348.78]],"batl":[[1,1.4,60.69],[2,1.82,479.32]],"ltp":1.32,"tv":52969.38,"id":9342449},{"batb":[[0,3.55,69.87],[1,3.5,4.08],[2,2.2,42.67]],"batl":[[0,4.6,2.36]],"ltp":4.0,"tv":8033.57,"id":9633869}]}]}
{"op":"mcm","clk":"4230539668","pt":1631534083630,"mc":[{"id":"1.187557995","rc":[{"batl":[[1,1.37,70.5],[2,1.4,60.69]],"ltp":1.32,"tv":52969.38,"id":9342449},{"batb":[[0,3.7,2.82],[1,3.55,69.87],[2,3.5,4.08]],"ltp":4.0,"tv":8033.57,"id":9633869}]}]}
{"op":"mcm","clk":"4230539738","pt":1631534084461,"mc":[{"id":"1.187557995","rc":[{"batb":[[1,1.28,575.59]],"batl":[[1,1.4,60.69],[2,1.82,479.32]],"ltp":1.32,"tv":52969.38,"id":9342449},{"batb":[[0,3.55,69.87],[1,3.5,4.08],[2,2.2,42.67]],"ltp":4.0,"tv":8033.57,"id":9633869}]}]}
{"op":"mcm","clk":"4230539948","pt":1631534086648,"mc":[{"id":"1.187557995","rc":[{"batl":[[1,1.39,358.47],[2,1.4,320.96]],"ltp":1.32,"tv":52969.38,"id":9342449}]}]}
{"op":"mcm","clk":"4230540050","pt":1631534087636,"mc":[{"id":"1.187557995","rc":[{"trd":[[1.32,229.73]],"batb":[[0,1.35,1923.04],[1,1.29,501.52],[2,1.28,575.59]],"batl":[[0,1.37,77.5]],"ltp":1.32,"tv":53119.06,"id":9342449},{"batb":[[0,3.7,3.02],[1,3.55,69.87],[2,3.5,4.08]],"ltp":4.0,"tv":8033.57,"id":9633869}],"tv":61152.63}]}
{"op":"mcm","clk":"4230540162","pt":1631534088677,"mc":[{"id":"1.187557995","rc":[{"trd":[[1.37,1183.25]],"batb":[[0,1.36,154.42],[1,1.35,1731.24],[2,1.34,1375]],"batl":[[0,1.39,358.47],[1,1.4,320.96],[2,1.82,479.32]],"ltp":1.37,"tv":53127.27,"id":9342449},{"trd":[[3.7,12.08]],"batb":[[0,3.55,69.87],[1,3.5,4.08],[2,3.45,304.89]],"ltp":3.7,"tv":8042.65,"id":9633869}],"tv":61169.92}]}
{"op":"mcm","clk":"4230540267","pt":1631534089668,"mc":[{"id":"1.187557995","rc":[{"batb":[[1,1.35,1985.04]],"batl":[[2,1.53,13.07]],"ltp":1.37,"tv":53127.27,"id":9342449},{"batl":[[0,4.1,8.51],[1,4.6,2.36],[2,5,2.15]],"ltp":3.7,"tv":8042.65,"id":9633869}]}]}
{"op":"mcm","clk":"4230540352","pt":1631534090655,"mc":[{"id":"1.187557995","rc":[{"batb":[[0,3.6,15.29],[1,3.55,69.87],[2,3.5,4.08]],"ltp":3.7,"tv":8042.65,"id":9633869}]}]}
{"op":"mcm","clk":"4230540435","pt":1631534091639,"mc":[{"id":"1.187557995","rc":[{"batb":[[0,1.36,162.42],[1,1.35,1993.04]],"batl":[[0,1.39,408.07],[1,1.4,335.96]],"ltp":1.37,"tv":53127.27,"id":9342449},{"batl":[[0,3.75,3],[1,3.85,3],[2,4.1,10.51]],"ltp":3.7,"tv":8042.65,"id":9633869}]}]}
{"op":"mcm","clk":"4230540515","pt":1631534092579,"mc":[{"id":"1.187557995","rc":[{"batb":[[0,1.37,71.73],[1,1.36,162.42],[2,1.35,4913.46]],"batl":[[0,1.38,351.5],[1,1.39,800.48],[2,1.4,335.96]],"ltp":1.37,"tv":53127.27,"id":9342449}]}]}
{"op":"mcm","clk":"4230540638","pt":1631534093679,"mc":[{"id":"1.187557995","rc":[{"batb":[[2,3.5,28.08]],"batl":[[2,4,20.74]],"ltp":3.7,"tv":8042.65,"id":9633869}]}]}
{"op":"mcm","clk":"4230540688","pt":1631534094251,"mc":[{"id":"1.187557995","rc":[{"batl":[[1,1.39,724.48]],"ltp":1.37,"tv":53127.27,"id":9342449}]}]}
{"op":"mcm","clk":"4230540786","pt":1631534095346,"mc":[{"id":"1.187557995","rc":[{"batl":[[0,1.38,654.25]],"ltp":1.37,"tv":53127.27,"id":9342449}]}]}
{"op":"mcm","clk":"4230540995","pt":1631534097486,"mc":[{"id":"1.187557995","rc":[{"batl":[[0,1.38,982.17]],"ltp":1.37,"tv":53127.27,"id":9342449}]}]}
{"op":"mcm","clk":"4230541102","pt":1631534098564,"mc":[{"id":"1.187557995","rc":[{"batl":[[2,3.95,8.73]],"ltp":3.7,"tv":8042.65,"id":9633869}]}]}
{"op":"mcm","clk":"4230541587","pt":1631534103367,"mc":[{"id":"1.187557995","rc":[{"batb":[[0,1.36,162.42],[1,1.35,4905.46],[2,1.34,1375]],"batl":[[0,1.38,563.75]],"ltp":1.37,"tv":53127.27,"id":9342449},{"batl":[[1,3.95,8.73],[2,4,20.74]],"ltp":3.7,"tv":8042.65,"id":9633869}]}]}
{"op":"mcm","clk":"4230541932","pt":1631534106976,"mc":[{"id":"1.187557995","rc":[{"batl":[[1,1.39,788.98]],"ltp":1.37,"tv":53127.27,"id":9342449},{"batb":[[1,3.55,73.66]],"ltp":3.7,"tv":8042.65,"id":9633869}]}]}
{"op":"mcm","clk":"4230542277","pt":1631534110378,"mc":[{"id":"1.187557995","rc":[{"batb":[[1,1.35,1985.04]],"ltp":1.37,"tv":53127.27,"id":9342449}]}]}
{"op":"mcm","clk":"4230542399","pt":1631534111575,"mc":[{"id":"1.187557995","rc":[{"batb":[[0,1.33,104.44],[1,1.31,374.28],[2,1.3,89.68]],"batl":[[0,1.38,261],[1,1.39,64.5],[2,1.4,75.69]],"ltp":1.37,"tv":53127.27,"id":9342449},{"batb":[[0,3.55,3.79],[1,3.5,28.08],[2,3.35,87.72]],"batl":[[0,3.95,8.73],[1,4.3,2.85],[2,4.4,2.44]],"ltp":3.7,"tv":8042.65,"id":9633869}]}]}
{"op":"mcm","clk":"4230542494","pt":1631534112511,"mc":[{"id":"1.187557995","rc":[{"batb":[[0,1.31,374.28],[1,1.3,89.68],[2,1.29,1.52]],"batl":[[0,1.4,60.69],[1,1.42,56.75],[2,1.82,479.32]],"ltp":1.37,"tv":53127.27,"id":9342449},{"batb":[[0,3.5,4.08],[1,3.35,87.72],[2,3.3,3]],"batl":[[0,4.3,2.85],[1,4.4,2.44],[2,4.6,2.36]],"ltp":3.7,"tv":8042.65,"id":9633869}]}]}
{"op":"mcm","clk":"4230542650","pt":1631534114077,"mc":[{"id":"1.187557995","rc":[{"batb":[[0,1.31,787.05],[1,1.3,477.34]],"batl":[[2,1.43,233.24]],"ltp":1.37,"tv":53127.27,"id":9342449}]}]}
{"op":"mcm","clk":"4230542821","pt":1631534115699,"mc":[{"id":"1.187557995","rc":[{"batl":[[0,1.4,68.69]],"ltp":1.37,"tv":53127.27,"id":9342449},{"batb":[[0,3.5,7.08],[1,3.45,2],[2,3.35,87.72]],"ltp":3.7,"tv":8042.65,"id":9633869}]}]}
{"op":"mcm","clk":"4230542873","pt":1631534116387,"mc":[{"id":"1.187557995","rc":[{"batb":[[2,1.29,501.52]],"batl":[[1,1.43,233.24],[2,1.44,230.32]],"ltp":1.37,"tv":53127.27,"id":9342449},{"batb":[[2,3.35,84.25]],"ltp":3.7,"tv":8042.65,"id":9633869}]}]}
{"op":"mcm","clk":"4230543073","pt":1631534118692,"mc":[{"id":"1.187557995","rc":[{"batl":[[1,1.82,479.32],[2,2.08,1]],"ltp":1.37,"tv":53127.27,"id":9342449}]}]}
{"op":"mcm","clk":"4230543170","pt":1631534119675,"mc":[{"id":"1.187557995","rc":[{"batl":[[0,1.39,73.5],[1,1.4,68.69],[2,1.82,479.32]],"ltp":1.37,"tv":53127.27,"id":9342449}]}]}
{"op":"mcm","clk":"4230543184","pt":1631534119777,"mc":[{"id":"1.187557995","rc":[{"batl":[[0,1.4,68.69],[1,1.82,479.32],[2,2.08,1]],"ltp":1.37,"tv":53127.27,"id":9342449}]}]}
{"op":"mcm","clk":"4230543386","pt":1631534121717,"mc":[{"id":"1.187557995","rc":[{"batb":[[2,1.29,1316.93]],"batl":[[0,1.34,273.36],[1,1.35,353.78],[2,1.4,246.49]],"ltp":1.37,"tv":53127.27,"id":9342449},{"batb":[[0,3.9,490.4],[1,3.85,481.13],[2,3.8,475.96]],"ltp":3.7,"tv":8042.65,"id":9633869}]}]}
{"op":"mcm","clk":"4230543485","pt":1631534122605,"mc":[{"id":"1.187557995","rc":[{"batl":[[2,1.4,68.69]],"ltp":1.37,"tv":53127.27,"id":9342449},{"trd":[[3.9,38.05]],"batb":[[0,3.9,540.42]],"ltp":3.9,"tv":8054.07,"id":9633869}],"tv":61181.34}]}
{"op":"mcm","clk":"4230543588","pt":1631534123389,"mc":[{"id":"1.187557995","rc":[{"batb":[[2,1.29,1428.34]],"batl":[[2,1.36,15]],"ltp":1.37,"tv":53127.27,"id":9342449},{"batb":[[2,3.8,497.38]],"batl":[[0,4.3,14.84],[2,4.5,8.01]],"ltp":3.9,"tv":8054.07,"id":9633869}]}]}
{"op":"mcm","clk":"4230543713","pt":1631534124495,"mc":[{"id":"1.187557995","rc":[{"batb":[[0,1.32,7],[1,1.31,796.05],[2,1.3,477.34]],"ltp":1.37,"tv":53127.27,"id":9342449},{"batl":[[0,4.2,3],[1,4.3,14.84],[2,4.4,2.44]],"ltp":3.9,"tv":8054.07,"id":9633869}]}]}
{"op":"mcm","clk":"4230543840","pt":1631534125698,"mc":[{"id":"1.187557995","rc":[{"batb":[[0,1.32,285.7]],"batl":[[0,1.33,632.55],[1,1.34,273.36],[2,1.35,353.78]],"ltp":1.37,"tv":53127.27,"id":9342449}]}]}
{"op":"mcm","clk":"4230543949","pt":1631534126684,"mc":[{"id":"1.187557995","rc":[{"trd":[[1.33,1161.32]],"batb":[[1,1.31,1077.88]],"batl":[[0,1.33,615.61],[1,1.34,675.06]],"ltp":1.33,"tv":53133.58,"id":9342449},{"trd":[[4,46.6]],"batb":[[0,3.95,35.4],[1,3.9,540.42],[2,3.85,481.13]],"ltp":4.0,"tv":8056.17,"id":9633869}],"tv":61189.75}]}
{"op":"mcm","clk":"4230544033","pt":1631534127510,"mc":[{"id":"1.187557995","rc":[{"batb":[[2,1.3,2748.78]],"batl":[[1,1.34,984.54]],"ltp":1.33,"tv":53133.58,"id":9342449},{"batb":[[0,3.95,14.47]],"ltp":4.0,"tv":8056.17,"id":9633869}]}]}
{"op":"mcm","clk":"4230544210","pt":1631534129394,"mc":[{"id":"1.187557995","rc":[{"batl":[[1,1.34,924.54],[2,1.35,368.78]],"ltp":1.33,"tv":53133.58,"id":9342449}]}]}
{"op":"mcm","clk":"4230544335","pt":1631534130718,"mc":[{"id":"1.187557995","rc":[{"trd":[[1.32,243.74]],"batb":[[0,1.31,1077.88],[1,1.3,2748.78],[2,1.29,928.34]],"batl":[[0,1.32,75.42],[1,1.33,521.47],[2,1.34,667.98]],"ltp":1.32,"tv":53147.58,"id":9342449},{"batb":[[1,3.9,561.1]],"ltp":4.0,"tv":8056.17,"id":9633869}],"tv":61203.76}]}
{"op":"mcm","clk":"4230544506","pt":1631534132410,"mc":[{"id":"1.187557995","rc":[{"batl":[[1,1.33,746.47]],"ltp":1.32,"tv":53147.58,"id":9342449}]}]}
{"op":"mcm","clk":"4230544637","pt":1631534133624,"mc":[{"id":"1.187557995","rc":[{"batb":[[0,1.31,1003.09],[1,1.3,2659.1],[2,1.29,112.93]],"batl":[[2,1.34,522.84]],"ltp":1.32,"tv":53147.58,"id":9342449},{"batb":[[0,3.9,76.41],[1,3.7,3.62],[2,3.55,75.98]],"batl":[[1,4.5,8.01],[2,5,2.15]],"ltp":4.0,"tv":8056.17,"id":9633869}]}]}
{"op":"mcm","clk":"4230544704","pt":1631534134203,"mc":[{"id":"1.187557995","rc":[{"batb":[[0,1.31,281.82],[1,1.29,112.93],[2,1.28,487.18]],"batl":[[1,1.33,264.26],[2,1.35,15]],"ltp":1.32,"tv":53147.58,"id":9342449},{"batb":[[0,3.9,20.68],[2,3.55,73.98]],"batl":[[0,4.5,8.01],[1,4.9,2.15]],"ltp":4.0,"tv":8056.17,"id":9633869}]}]}
{"op":"mcm","clk":"4230544826","pt":1631534135508,"mc":[{"id":"1.187557995","rc":[{"batb":[[1,1.29,1.52]],"batl":[[1,1.33,28.11],[2,1.39,6]],"ltp":1.32,"tv":53147.58,"id":9342449},{"batb":[[0,3.55,70.79],[1,3.5,4.08],[2,2.2,42.67]],"batl":[[0,4.9,2.15],[1,5,2.15],[2,5.2,2.08]],"ltp":4.0,"tv":8056.17,"id":9633869}]}]}
{"op":"mcm","clk":"4230544981","pt":1631534136986,"mc":[{"id":"1.187557995","rc":[{"batb":[[0,1.29,1.52],[1,1.28,487.18],[2,1.27,292.87]],"batl":[[0,1.39,6],[1,1.4,461.23],[2,1.41,251.56]],"ltp":1.32,"tv":53147.58,"id":9342449},{"batl":[[0,4.8,2.17],[1,4.9,2.15],[2,5,2.15]],"ltp":4.0,"tv":8056.17,"id":9633869}]}]}
{"op":"mcm","clk":"4230545150","pt":1631534138714,"mc":[{"id":"1.187557995","rc":[{"batl":[[0,1.37,67.5],[1,1.39,6],[2,1.4,461.23]],"ltp":1.32,"tv":53147.58,"id":9342449},{"batb":[[0,3.7,3.42],[1,3.55,70.79],[2,3.5,4.08]],"ltp":4.0,"tv":8056.17,"id":9633869}]}]}
{"op":"mcm","clk":"4230545174","pt":1631534138978,"mc":[{"id":"1.187557995","rc":[{"batl":[[0,1.39,6],[1,1.4,461.23],[2,1.41,251.56]],"ltp":1.32,"tv":53147.58,"id":9342449},{"batb":[[0,3.55,70.79],[1,3.5,4.08],[2,2.2,42.67]],"ltp":4.0,"tv":8056.17,"id":9633869}]}]}
{"op":"mcm","clk":"4230545290","pt":1631534140075,"mc":[{"id":"1.187557995","rc":[{"batl":[[0,4.6,2],[1,4.8,2.17],[2,4.9,2.15]],"ltp":4.0,"tv":8056.17,"id":9633869}]}]}
{"op":"mcm","clk":"4230545806","pt":1631534145672,"mc":[{"id":"1.187557995","rc":[{"batl":[[0,1.37,64.5],[1,1.39,6],[2,1.4,461.23]],"ltp":1.32,"tv":53147.58,"id":9342449},{"batb":[[0,3.7,3.42],[1,3.55,70.79],[2,3.5,4.08]],"ltp":4.0,"tv":8056.17,"id":9633869}]}]}
{"op":"mcm","clk":"4230545842","pt":1631534145994,"mc":[{"id":"1.187557995","rc":[{"batl":[[0,1.39,6],[1,1.4,461.23],[2,1.41,251.56]],"ltp":1.32,"tv":53147.58,"id":9342449},{"batb":[[0,3.55,70.79],[1,3.5,4.08],[2,2.2,42.67]],"ltp":4.0,"tv":8056.17,"id":9633869}]}]}
{"op":"mcm","clk":"4230546246","pt":1631534150293,"mc":[{"id":"1.187557995","rc":[{"batl":[[1,1.82,479.32],[2,2.08,1]],"ltp":1.32,"tv":53147.58,"id":9342449}]}]}
{"op":"mcm","clk":"4230546366","pt":1631534151609,"mc":[{"id":"1.187557995","rc":[{"batb":[[1,1.27,292.87],[2,1.26,555.36]],"batl":[[1,2.08,1],[2,8.8,7.23]],"ltp":1.32,"tv":53147.58,"id":9342449},{"batl":[[0,4.8,2.17],[1,4.9,2.15],[2,5,2.15]],"ltp":4.0,"tv":8056.17,"id":9633869}]}]}
{"op":"mcm","clk":"4230546491","pt":1631534152601,"mc":[{"id":"1.187557995","rc":[{"trd":[[1.29,6.9]],"batb":[[0,1.27,292.87],[1,1.26,555.36],[2,1.25,973.75]],"ltp":1.29,"tv":53150.62,"id":9342449}],"tv":61206.8}]}
{"op":"mcm","clk":"4230546616","pt":1631534153708,"mc":[{"id":"1.187557995","rc":[{"batl":[[0,1.29,510.28],[1,1.3,1846.14],[2,1.31,1427.88]],"ltp":1.29,"tv":53150.62,"id":9342449},{"batb":[[0,4.4,4.56],[1,3.55,70.79],[2,3.5,4.08]],"ltp":4.0,"tv":8056.17,"id":9633869}]}]}
{"op":"mcm","clk":"4230546716","pt":1631534154599,"mc":[{"id":"1.187557995","rc":[{"batl":[[1,1.3,1861.14]],"ltp":1.29,"tv":53150.62,"id":9342449},{"trd":[[4.4,17.38]],"batb":[[0,4.4,81.19],[1,4.3,18.18],[2,3.9,55.65]],"ltp":4.4,"tv":8066.43,"id":9633869}],"tv":61217.06}]}
{"op":"mcm","clk":"4230547025","pt":1631534157717,"mc":[{"id":"1.187557995","rc":[{"batl":[[0,1.28,365.18],[1,1.29,1083.66],[2,1.3,2145.13]],"ltp":1.29,"tv":53150.62,"id":9342449}]}]}
{"op":"mcm","clk":"4230547117","pt":1631534158611,"mc":[{"id":"1.187557995","rc":[{"trd":[[1.28,18.67]],"batb":[[1,1.26,833.81]],"batl":[[0,1.28,346.51],[1,1.29,1145.48]],"ltp":1.28,"tv":53169.29,"id":9342449},{"trd":[[4.5,5.31]],"batb":[[0,4.5,14.4],[1,4.4,81.19]],"ltp":4.5,"tv":8071.74,"id":9633869}],"tv":61241.04}]}
{"op":"mcm","clk":"4230547199","pt":1631534159601,"mc":[{"id":"1.187557995","rc":[{"batb":[[2,1.25,3699.48]],"batl":[[1,1.29,1269.48]],"ltp":1.28,"tv":53169.29,"id":9342449},{"batb":[[2,4.1,2.64]],"ltp":4.5,"tv":8071.74,"id":9633869}]}]}
{"op":"mcm","clk":"4230547323","pt":1631534160704,"mc":[{"id":"1.187557995","rc":[{"trd":[[1.28,70.27]],"batb":[[0,1.27,595.05]],"batl":[[0,1.28,586.82]],"ltp":1.28,"tv":53220.89,"id":9342449}],"tv":61292.63}]}
{"op":"mcm","clk":"4230547394","pt":1631534161382,"mc":[{"id":"1.187557995","rc":[{"batl":[[1,1.29,1284.48]],"ltp":1.28,"tv":53220.89,"id":9342449},{"batb":[[1,4.4,98.83]],"ltp":4.5,"tv":8071.74,"id":9633869}]}]}
{"op":"mcm","clk":"4230547487","pt":1631534162433,"mc":[{"id":"1.187557995","rc":[{"batb":[[1,1.26,555.36]],"batl":[[2,1.3,1846.14]],"ltp":1.28,"tv":53220.89,"id":9342449}]}]}
{"op":"mcm","clk":"4230547566","pt":1631534163357,"mc":[{"id":"1.187557995","rc":[{"batb":[[1,1.26,753.83]],"ltp":1.28,"tv":53220.89,"id":9342449}]}]}
{"op":"mcm","clk":"4230547660","pt":1631534164194,"mc":[{"id":"1.187557995","rc":[{"batb":[[0,1.27,351.76],[2,1.25,4096.41]],"ltp":1.28,"tv":53220.89,"id":9342449}]}]}
{"op":"mcm","clk":"4230548045","pt":1631534168590,"mc":[{"id":"1.187557995","rc":[{"batb":[[0,1.27,292.87]],"batl":[[0,1.28,266.11],[1,1.29,986.02]],"ltp":1.28,"tv":53220.89,"id":9342449}]}]}
{"op":"mcm","clk":"4230548692","pt":1631534176314,"mc":[{"id":"1.187557995","rc":[{"batb":[[2,1.25,1370.69]],"batl":[[0,1.29,986.02],[1,1.3,1846.14],[2,1.31,1427.88]],"ltp":1.28,"tv":53220.89,"id":9342449}]}]}
{"op":"mcm","clk":"4230548881","pt":1631534178624,"mc":[{"id":"1.187557995","rc":[{"batb":[[0,1.27,200],[1,1.26,198.47],[2,1.25,772.58]],"batl":[[0,1.29,139],[1,1.32,87.86],[2,1.34,74.75]],"ltp":1.28,"tv":53220.89,"id":9342449},{"batb":[[0,4.4,98.83],[1,4.1,2.64],[2,3.9,58.71]],"batl":[[0,5.1,7.4],[1,5.8,2.02],[2,6.6,2]],"ltp":4.5,"tv":8071.74,"id":9633869}]}]}
{"op":"mcm","clk":"4230548952","pt":1631534179514,"mc":[{"id":"1.187557995","rc":[{"trd":[[1.27,8.26]],"batb":[[0,1.27,195.87],[2,1.25,396.93]],"batl":[[0,1.34,74.75],[1,1.35,76.7],[2,1.36,7]],"ltp":1.27,"tv":53229.16,"id":9342449},{"batb":[[0,3.9,58.71],[1,3.85,2.97],[2,3.6,3]],"batl":[[0,5.8,2.02],[1,6.6,2],[2,7,2]],"ltp":4.5,"tv":8071.74,"id":9633869}],"tv":61300.9}]}
{"op":"mcm","clk":"4230549124","pt":1631534181651,"mc":[{"id":"1.187557995","rc":[{"batb":[[1,1.22,524.8],[2,1.21,110.69]],"ltp":1.27,"tv":53229.16,"id":9342449}]}]}
{"op":"mcm","clk":"4230549251","pt":1631534183225,"mc":[{"id":"1.187557995","rc":[{"batl":[[0,1.34,83.75]],"ltp":1.27,"tv":53229.16,"id":9342449},{"batb":[[0,3.9,61.71],[1,3.85,5.97]],"ltp":4.5,"tv":8071.74,"id":9633869}]}]}
{"op":"mcm","clk":"4230549412","pt":1631534184645,"mc":[{"id":"1.187557995","rc":[{"batb":[[1,1.25,451.24],[2,1.24,514.26]],"batl":[[0,1.28,1424.78],[1,1.29,390.32],[2,1.34,83.75]],"ltp":1.27,"tv":53229.16,"id":9342449},{"batb":[[0,4.6,18.54],[1,3.9,61.71],[2,3.85,5.97]],"batl":[[0,4.8,21.52],[1,5.8,2.02],[2,6.6,2]],"ltp":4.5,"tv":8071.74,"id":9633869}]}]}
{"op":"mcm","clk":"4230549491","pt":1631534185428,"mc":[{"id":"1.187557995","rc":[{"batl":[[0,1.28,1403.94]],"ltp":1.27,"tv":53229.16,"id":9342449},{"batb":[[0,3.9,61.71],[1,3.85,5.97],[2,3.6,3]],"batl":[[0,5.8,2.02],[1,6.6,2],[2,7,2]],"ltp":4.5,"tv":8071.74,"id":9633869}]}]}
{"op":"mcm","clk":"4230549568","pt":1631534186415,"mc":[{"id":"1.187557995","rc":[{"batl":[[2,1.32,76.86]],"ltp":1.27,"tv":53229.16,"id":9342449},{"batb":[[0,4.1,59.26],[1,3.9,61.71],[2,3.85,5.97]],"batl":[[0,5.7,10.1],[1,5.8,2.02],[2,6.6,2]],"ltp":4.5,"tv":8071.74,"id":9633869}]}]}
{"op":"mcm","clk":"4230549600","pt":1631534186842,"mc":[{"id":"1.187557995","rc":[{"batb":[[0,4.1,2.44]],"ltp":4.5,"tv":8071.74,"id":9633869}]}]}
{"op":"mcm","clk":"4230549722","pt":1631534188454,"mc":[{"id":"1.187557995","rc":[{"batl":[[0,1.28,604.88]],"ltp":1.27,"tv":53229.16,"id":9342449}]}]}
{"op":"mcm","clk":"4230549848","pt":1631534189655,"mc":[{"id":"1.187557995","rc":[{"batb":[[1,1.23,236.8],[2,1.22,524.8]],"batl":[[0,1.28,88.94],[1,1.33,198.47],[2,1.34,83.75]],"ltp":1.27,"tv":53229.16,"id":9342449},{"batb":[[0,3.9,61.71],[1,3.85,5.97],[2,3.6,3]],"batl":[[0,5.8,2.02],[1,6.6,2],[2,7,2]],"ltp":4.5,"tv":8071.74,"id":9633869}]}]}
{"op":"mcm","clk":"4230550025","pt":1631534191672,"mc":[{"id":"1.187557995","rc":[{"batl":[[0,1.28,331.94]],"ltp":1.27,"tv":53229.16,"id":9342449}]}]}
{"op":"mcm","clk":"4230550088","pt":1631534192245,"mc":[{"id":"1.187557995","rc":[{"batl":[[0,1.28,88.94],[2,1.34,354.26]],"ltp":1.27,"tv":53229.16,"id":9342449}]}]}
{"op":"mcm","clk":"4230550487","pt":1631534196641,"mc":[{"id":"1.187557995","rc":[{"batb":[[1,3.85,2.97],[2,2.6,3.72]],"ltp":4.5,"tv":8071.74,"id":9633869}]}]}
{"op":"mcm","clk":"4230550549","pt":1631534197345,"mc":[{"id":"1.187557995","rc":[{"batb":[[2,1.21,650.17]],"ltp":1.27,"tv":53229.16,"id":9342449}]}]}
{"op":"mcm","clk":"4230550664","pt":1631534198660,"mc":[{"id":"1.187557995","rc":[{"batb":[[1,1.21,650.17],[2,1.2,1107.99]],"batl":[[1,1.34,354.26],[2,1.35,387.4]],"ltp":1.27,"tv":53229.16,"id":9342449}]}]}
{"op":"mcm","clk":"4230550814","pt":1631534200448,"mc":[{"id":"1.187557995","rc":[{"batb":[[1,1.21,110.69],[2,1.2,502]],"batl":[[0,1.34,354.26],[1,1.35,387.4],[2,1.49,2.99]],"ltp":1.27,"tv":53229.16,"id":9342449}]}]}
{"op":"mcm","clk":"4230550945","pt":1631534201878,"mc":[{"id":"1.187557995","rc":[{"batl":[[0,1.34,345.26]],"ltp":1.27,"tv":53229.16,"id":9342449},{"batb":[[0,3.9,58.71]],"ltp":4.5,"tv":8071.74,"id":9633869}]}]}
{"op":"mcm","clk":"4230551112","pt":1631534203557,"mc":[{"id":"1.187557995","rc":[{"batb":[[0,1.31,484.51],[1,1.3,1858.83],[2,1.29,1427.88]],"ltp":1.27,"tv":53229.16,"id":9342449},{"trd":[[3.9,49.31]],"batb":[[0,3.9,53.08],[1,3.85,4.97],[2,3.8,276.8]],"ltp":3.9,"tv":8083.0,"id":9633869}],"tv":61312.16}]}
{"op":"mcm","clk":"4230551218","pt":1631534204656,"mc":[{"id":"1.187557995","rc":[{"batb":[[1,1.3,2161.59]],"batl":[[1,1.35,402.4],[2,1.48,13.51]],"ltp":1.27,"tv":53229.16,"id":9342449},{"batb":[[0,3.9,73.76],[1,3.85,2.97]],"batl":[[0,4.5,8.01],[1,4.7,3],[2,5.8,2.02]],"ltp":3.9,"tv":8083.0,"id":9633869}]}]}
{"op":"mcm","clk":"4230551312","pt":1631534205553,"mc":[{"id":"1.187557995","rc":[{"batl":[[0,1.34,390.15]],"ltp":1.27,"tv":53229.16,"id":9342449},{"batb":[[0,3.95,14.47],[1,3.9,73.76],[2,3.85,2.97]],"ltp":3.9,"tv":8083.0,"id":9633869}]}]}
{"op":"mcm","clk":"4230551402","pt":1631534206462,"mc":[{"id":"1.187557995","rc":[{"batb":[[0,1.32,9],[1,1.31,494.51],[2,1.3,4433.03]],"ltp":1.27,"tv":53229.16,"id":9342449},{"batl":[[0,4.2,2],[1,4.5,8.01],[2,4.7,3]],"ltp":3.9,"tv":8083.0,"id":9633869}]}]}
{"op":"mcm","clk":"4230551515","pt":1631534207552,"mc":[{"id":"1.187557995","rc":[{"batb":[[0,1.32,73.67]],"batl":[[0,1.33,389.22],[1,1.34,798.66],[2,1.35,402.4]],"ltp":1.27,"tv":53229.16,"id":9342449}]}]}
{"op":"mcm","clk":"4230551617","pt":1631534208555,"mc":[{"id":"1.187557995","rc":[{"batb":[[1,1.31,571.98]],"ltp":1.27,"tv":53229.16,"id":9342449}]}]}
{"op":"mcm","clk":"4230551666","pt":1631534209183,"mc":[{"id":"1.187557995","rc":[{"batl":[[1,4.4,18.05],[2,4.5,8.01]],"ltp":3.9,"tv":8083.0,"id":9633869}]}]}
{"op":"mcm","clk":"4230551787","pt":1631534210482,"mc":[{"id":"1.187557995","rc":[{"batl":[[0,1.33,619.38]],"ltp":1.27,"tv":53229.16,"id":9342449}]}]}
{"op":"mcm","clk":"4230551947","pt":1631534212375,"mc":[{"id":"1.187557995","rc":[{"batb":[[1,1.31,494.51]],"batl":[[1,1.34,718.29]],"ltp":1.27,"tv":53229.16,"id":9342449}]}]}
{"op":"mcm","clk":"4230552091","pt":1631534213887,"mc":[{"id":"1.187557995","rc":[{"batb":[[2,1.3,2161.59]],"ltp":1.27,"tv":53229.16,"id":9342449}]}]}
{"op":"mcm","clk":"4230552205","pt":1631534215155,"mc":[{"id":"1.187557995","rc":[{"trd":[[1.33,1167.1]],"batb":[[1,1.31,425.79]],"batl":[[0,1.33,616.5]],"ltp":1.33,"tv":53234.93,"id":9342449}],"tv":61317.93}]}
{"op":"mcm","clk":"4230552521","pt":1631534218594,"mc":[{"id":"1.187557995","rc":[{"batb":[[0,1.32,9],[1,1.31,415.79]],"batl":[[0,1.33,230.16]],"ltp":1.33,"tv":53234.93,"id":9342449}]}]}
{"op":"mcm","clk":"4230552812","pt":1631534221569,"mc":[{"id":"1.187557995","rc":[{"batl":[[1,1.34,627.29]],"ltp":1.33,"tv":53234.93,"id":9342449}]}]}
{"op":"mcm","clk":"4230552998","pt":1631534223572,"mc":[{"id":"1.187557995","rc":[{"batb":[[0,1.29,111.41],[1,1.27,195.87],[2,1.26,334.65]],"batl":[[0,1.35,15],[1,1.38,65.75],[2,1.49,2.99]],"ltp":1.33,"tv":53234.93,"id":9342449},{"batb":[[0,3.9,20.68],[1,3.6,2.99],[2,3.55,69.37]],"batl":[[0,4.5,8.01],[1,4.9,2.15],[2,5.4,2.04]],"ltp":3.9,"tv":8083.0,"id":9633869}]}]}
{"op":"mcm","clk":"4230553088","pt":1631534224567,"mc":[{"id":"1.187557995","rc":[{"batb":[[0,1.27,195.87],[1,1.26,334.65],[2,1.25,377.57]],"batl":[[0,1.38,65.75],[1,1.49,2.99],[2,1.62,618.19]],"ltp":1.33,"tv":53234.93,"id":9342449},{"batb":[[0,3.6,2.99],[1,3.55,69.37],[2,2.2,42.67]],"batl":[[0,4.9,2.15],[1,5.4,2.04],[2,5.6,2.01]],"ltp":3.9,"tv":8083.0,"id":9633869}]}]}
{"op":"mcm","clk":"4230553275","pt":1631534226699,"mc":[{"id":"1.187557995","rc":[{"batb":[[1,1.26,785.42],[2,1.25,866.38]],"batl":[[1,1.4,398],[2,1.41,251.59]],"ltp":1.33,"tv":53234.93,"id":9342449}]}]}
{"op":"mcm","clk":"4230553379","pt":1631534227697,"mc":[{"id":"1.187557995","rc":[{"batb":[[0,1.27,705.87],[1,1.26,793.42]],"ltp":1.33,"tv":53234.93,"id":9342449},{"batl":[[0,4.8,2],[1,4.9,2.15],[2,5.4,2.04]],"ltp":3.9,"tv":8083.0,"id":9633869}]}]}
{"op":"mcm","clk":"4230553522","pt":1631534229113,"mc":[{"id":"1.187557995","rc":[{"batb":[[1,1.26,342.65],[2,1.25,377.57]],"batl":[[0,1.38,274.44]],"ltp":1.33,"tv":53234.93,"id":9342449}]}]}
{"op":"mcm","clk":"4230553688","pt":1631534230678,"mc":[{"id":"1.187557995","rc":[{"trd":[[1.36,10723.87]],"batb":[[0,1.36,5861.59],[1,1.27,705.87],[2,1.26,96.48]],"batl":[[0,1.38,65.75]],"ltp":1.36,"tv":53388.07,"id":9342449}],"tv":61471.07}]}
{"op":"mcm","clk":"4230553775","pt":1631534231685,"mc":[{"id":"1.187557995","rc":[{"trd":[[1.38,645.12]],"batb":[[0,1.36,2812.5],[1,1.35,2729.78],[2,1.34,2729.78]],"batl":[[0,1.38,57.51]],"ltp":1.38,"tv":53396.31,"id":9342449},{"trd":[[3.6,47.84]],"batb":[[0,3.55,69.37],[1,3.35,1141.78],[2,3.3,1108.2]],"ltp":3.6,"tv":8092.14,"id":9633869}],"tv":61488.45}]}
{"op":"mcm","clk":"4230553885","pt":1631534232677,"mc":[{"id":"1.187557995","rc":[{"batb":[[0,1.36,1794.8],[1,1.35,1681.94],[2,1.34,1364.88]],"ltp":1.38,"tv":53396.31,"id":9342449},{"batb":[[1,3.35,313.99],[2,3.3,304.76]],"ltp":3.6,"tv":8092.14,"id":9633869}]}]}
{"op":"mcm","clk":"4230553970","pt":1631534233672,"mc":[{"id":"1.187557995","rc":[{"batb":[[0,1.36,1871.23],[1,1.35,1936.66]],"batl":[[2,1.41,266.59]],"ltp":1.38,"tv":53396.31,"id":9342449},{"batb":[[1,3.45,24.48],[2,3.35,313.99]],"batl":[[0,4,8.66],[1,4.4,10],[2,4.8,2]],"ltp":3.6,"tv":8092.14,"id":9633869}]}]}
{"op":"mcm","clk":"4230554078","pt":1631534234715,"mc":[{"id":"1.187557995","rc":[{"batb":[[0,1.36,1794.8]],"ltp":1.38,"tv":53396.31,"id":9342449},{"batl":[[1,4.5,3],[2,4.7,2]],"ltp":3.6,"tv":8092.14,"id":9633869}]}]}
{"op":"mcm","clk":"4230554136","pt":1631534235321,"mc":[{"id":"1.187557995","rc":[{"batb":[[0,1.37,8],[1,1.36,1803.8],[2,1.35,1936.66]],"ltp":1.38,"tv":53396.31,"id":9342449},{"batb":[[0,3.55,83.7]],"batl":[[0,3.75,3],[1,4,8.66],[2,4.5,3]],"ltp":3.6,"tv":8092.14,"id":9633869}]}]}
{"op":"mcm","clk":"4230554268","pt":1631534236676,"mc":[{"id":"1.187557995","rc":[{"trd":[[1.37,1199.25]],"batb":[[0,1.36,1883.78],[1,1.35,2011.53],[2,1.34,1364.88]],"batl":[[0,1.37,288.83],[1,1.38,289.47],[2,1.39,56.86]],"ltp":1.37,"tv":53412.31,"id":9342449}],"tv":61504.45}]}
{"op":"mcm","clk":"4230554364","pt":1631534237581,"mc":[{"id":"1.187557995","rc":[{"batb":[[0,1.36,4723.08]],"ltp":1.37,"tv":53412.31,"id":9342449},{"batl":[[1,3.95,22.63],[2,4,8.66]],"ltp":3.6,"tv":8092.14,"id":9633869}]}]}
{"op":"mcm","clk":"4230554474","pt":1631534238577,"mc":[{"id":"1.187557995","rc":[{"trd":[[1.37,1207.35]],"batl":[[0,1.37,280.73]],"ltp":1.37,"tv":53420.41,"id":9342449},{"trd":[[3.7,15.08]],"batb":[[1,3.5,4.08],[2,3.45,24.48]],"ltp":3.7,"tv":8095.14,"id":9633869}],"tv":61515.55}]}
{"op":"mcm","clk":"4230554545","pt":1631534239447,"mc":[{"id":"1.187557995","rc":[{"batb":[[2,1.34,1467.77]],"ltp":1.37,"tv":53420.41,"id":9342449}]}]}
{"op":"mcm","clk":"4230554668","pt":1631534240670,"mc":[{"id":"1.187557995","rc":[{"batb":[[0,1.36,4803.09]],"batl":[[0,1.37,582.73],[1,1.38,365.16],[2,1.39,116.36]],"ltp":1.37,"tv":53420.41,"id":9342449},{"batb":[[0,3.55,87.09]],"batl":[[2,4.3,2.95]],"ltp":3.7,"tv":8095.14,"id":9633869}]}]}
{"op":"mcm","clk":"4230554702","pt":1631534240985,"mc":[{"id":"1.187557995","rc":[{"batb":[[0,1.36,4723.08],[1,1.35,1936.66]],"batl":[[1,1.38,289.47],[2,1.39,59.5]],"ltp":1.37,"tv":53420.41,"id":9342449}]}]}
{"op":"mcm","clk":"4230554934","pt":1631534243699,"mc":[{"id":"1.187557995","rc":[{"batb":[[0,1.36,2928.28],[1,1.35,254.72],[2,1.34,102.89]],"batl":[[1,1.38,231.96]],"ltp":1.37,"tv":53420.41,"id":9342449},{"batb":[[0,3.55,72.76]],"batl":[[1,3.9,8.8]],"ltp":3.7,"tv":8095.14,"id":9633869}]}]}
{"op":"mcm","clk":"4230555033","pt":1631534244697,"mc":[{"id":"1.187557995","rc":[{"batb":[[0,1.36,79.98],[1,1.31,305.22],[2,1.3,305.35]],"batl":[[0,1.37,280.73],[1,1.38,61.36]],"ltp":1.37,"tv":53420.41,"id":9342449},{"batb":[[0,3.55,3.39],[2,3.4,3.71]],"batl":[[0,4.3,2.95],[1,4.5,3],[2,4.6,2.46]],"ltp":3.7,"tv":8095.14,"id":9633869}]}]}
{"op":"mcm","clk":"4230555206","pt":1631534246590,"mc":[{"id":"1.187557995","rc":[{"batb":[[0,1.31,697.15],[1,1.3,692.81],[2,1.29,10]],"ltp":1.37,"tv":53420.41,"id":9342449}]}]}
{"op":"mcm","clk":"4230555304","pt":1631534247599,"mc":[{"id":"1.187557995","rc":[{"batb":[[0,1.31,305.22],[1,1.3,305.35]],"batl":[[0,1.36,29.75],[1,1.41,304.82],[2,1.42,57.25]],"ltp":1.37,"tv":53420.41,"id":9342449},{"batb":[[0,3.4,3.71],[1,3.35,3.27],[2,3.3,82.68]],"ltp":3.7,"tv":8095.14,"id":9633869}]}]}
{"op":"mcm","clk":"4230555483","pt":1631534249634,"mc":[{"id":"1.187557995","rc":[{"batl":[[1,1.41,59.5]],"ltp":1.37,"tv":53420.41,"id":9342449}]}]}
{"op":"mcm","clk":"4230555560","pt":1631534250516,"mc":[{"id":"1.187557995","rc":[{"batb":[[0,1.35,368.8],[1,1.34,329.24],[2,1.31,312.22]],"batl":[[1,1.38,183.78],[2,1.39,343.34]],"ltp":1.37,"tv":53420.41,"id":9342449},{"batb":[[0,3.55,3.39],[1,3.4,3.71]],"batl":[[0,4.3,5.95]],"ltp":3.7,"tv":8095.14,"id":9633869}]}]}
{"op":"mcm","clk":"4230555679","pt":1631534251619,"mc":[{"id":"1.187557995","rc":[{"batb":[[2,1.32,86.62]],"ltp":1.37,"tv":53420.41,"id":9342449},{"batl":[[0,4.2,14.75],[1,4.3,5.95],[2,4.5,3]],"ltp":3.7,"tv":8095.14,"id":9633869}]}]}
{"op":"mcm","clk":"4230555964","pt":1631534254497,"mc":[{"id":"1.187557995","rc":[{"batb":[[0,1.31,312.22],[1,1.3,313.35],[2,1.29,10]],"batl":[[1,1.39,72.5],[2,1.41,59.5]],"ltp":1.37,"tv":53420.41,"id":9342449},{"batl":[[0,4.3,5.95],[1,4.5,3],[2,4.6,2.46]],"ltp":3.7,"tv":8095.14,"id":9633869}]}]}
{"op":"mcm","clk":"4230555994","pt":1631534254816,"mc":[{"id":"1.187557995","rc":[{"batl":[[1,1.41,59.5],[2,1.43,227.43]],"ltp":1.37,"tv":53420.41,"id":9342449},{"batb":[[0,3.4,3.71],[1,3.3,82.68],[2,2.2,42.67]],"ltp":3.7,"tv":8095.14,"id":9633869}]}]}
{"op":"mcm","clk":"4230556250","pt":1631534257634,"mc":[{"id":"1.187557995","rc":[{"batb":[[0,1.31,697.15],[1,1.3,700.81]],"ltp":1.37,"tv":53420.41,"id":9342449}]}]}
{"op":"mcm","clk":"4230556381","pt":1631534259040,"mc":[{"id":"1.187557995","rc":[{"batb":[[0,1.31,469.72]],"batl":[[2,1.49,2.99]],"ltp":1.37,"tv":53420.41,"id":9342449}]}]}
{"op":"mcm","clk":"4230556548","pt":1631534260714,"mc":[{"id":"1.187557995","rc":[{"batb":[[2,1.29,825.41]],"batl":[[0,1.34,293.13],[1,1.35,310.6],[2,1.36,29.75]],"ltp":1.37,"tv":53420.41,"id":9342449},{"batb":[[0,3.9,490.4],[1,3.85,475.96],[2,3.8,475.96]],"ltp":3.7,"tv":8095.14,"id":9633869}]}]}
{"op":"mcm","clk":"4230556638","pt":1631534261708,"mc":[{"id":"1.187557995","rc":[{"batb":[[2,1.29,926.82]],"batl":[[2,1.36,44.75]],"ltp":1.37,"tv":53420.41,"id":9342449},{"trd":[[3.9,60.57]],"batb":[[0,3.95,54.98],[1,3.9,484.77],[2,3.85,497.01]],"batl":[[1,4.5,8.01]],"ltp":3.9,"tv":8106.4,"id":9633869}],"tv":61526.81}]}
{"op":"mcm","clk":"4230556697","pt":1631534262330,"mc":[{"id":"1.187557995","rc":[{"batl":[[1,1.35,310.52]],"ltp":1.37,"tv":53420.41,"id":9342449},{"batl":[[0,4.3,17.51]],"ltp":3.9,"tv":8106.4,"id":9633869}]}]}
{"op":"mcm","clk":"4230556762","pt":1631534263107,"mc":[{"id":"1.187557995","rc":[{"batb":[[0,1.32,8],[1,1.31,469.72],[2,1.3,700.81]],"ltp":1.37,"tv":53420.41,"id":9342449},{"batl":[[0,4.2,2],[1,4.3,17.51],[2,4.5,8.01]],"ltp":3.9,"tv":8106.4,"id":9633869}]}]}
{"op":"mcm","clk":"4230556891","pt":1631534264620,"mc":[{"id":"1.187557995","rc":[{"batb":[[0,1.32,70.74],[1,1.31,477.72]],"batl":[[0,1.33,363.74],[1,1.34,293.13],[2,1.35,310.52]],"ltp":1.37,"tv":53420.41,"id":9342449}]}]}
{"op":"mcm","clk":"4230556986","pt":1631534265517,"mc":[{"id":"1.187557995","rc":[{"batb":[[1,1.31,633.04]],"batl":[[1,1.34,779.43]],"ltp":1.37,"tv":53420.41,"id":9342449},{"batb":[[0,3.95,73.53],[2,3.85,475.96]],"ltp":3.9,"tv":8106.4,"id":9633869}]}]}
{"op":"mcm","clk":"4230557089","pt":1631534266607,"mc":[{"id":"1.187557995","rc":[{"batb":[[2,1.3,2972.25]],"batl":[[1,1.34,779.35]],"ltp":1.37,"tv":53420.41,"id":9342449}]}]}
{"op":"mcm","clk":"4230557257","pt":1631534268431,"mc":[{"id":"1.187557995","rc":[{"batl":[[0,1.33,923.36],[2,1.35,325.52]],"ltp":1.37,"tv":53420.41,"id":9342449}]}]}
{"op":"mcm","clk":"4230557351","pt":1631534269422,"mc":[{"id":"1.187557995","rc":[{"batl":[[0,1.33,923.44]],"ltp":1.37,"tv":53420.41,"id":9342449},{"batb":[[1,3.9,505.45]],"ltp":3.9,"tv":8106.4,"id":9633869}]}]}
{"op":"mcm","clk":"4230557491","pt":1631534270940,"mc":[{"id":"1.187557995","rc":[{"batl":[[1,1.34,710.5]],"ltp":1.37,"tv":53420.41,"id":9342449}]}]}
{"op":"mcm","clk":"4230557643","pt":1631534272562,"mc":[{"id":"1.187557995","rc":[{"batb":[[0,1.32,126.66]],"batl":[[0,1.33,994.67]],"ltp":1.37,"tv":53420.41,"id":9342449}]}]}
{"op":"mcm","clk":"4230557662","pt":1631534272769,"mc":[{"id":"1.187557995","rc":[{"batb":[[0,1.32,70.74],[1,1.31,559.04]],"batl":[[0,1.33,923.44]],"ltp":1.37,"tv":53420.41,"id":9342449}]}]}
{"op":"mcm","clk":"4230557834","pt":1631534274745,"mc":[{"id":"1.187557995","rc":[{"batb":[[0,1.32,8]],"batl":[[0,1.33,559.7]],"ltp":1.37,"tv":53420.41,"id":9342449}]}]}
{"op":"mcm","clk":"4230558290","pt":1631534280033,"mc":[{"id":"1.187557995","rc":[{"batb":[[1,1.31,551.04],[2,1.3,692.81]],"ltp":1.37,"tv":53420.41,"id":9342449},{"batl":[[1,4.3,14.51]],"ltp":3.9,"tv":8106.4,"id":9633869}]}]}
{"op":"mcm","clk":"4230558576","pt":1631534283266,"mc":[{"id":"1.187557995","rc":[{"batb":[[1,1.31,558.04]],"ltp":1.37,"tv":53420.41,"id":9342449}]}]}
{"op":"mcm","clk":"4230558690","pt":1631534284581,"mc":[{"id":"1.187557995","rc":[{"batb":[[0,1.29,111.41],[1,1.28,434.41],[2,1.27,195.87]],"batl":[[0,1.33,238.08],[1,1.35,15],[2,1.36,69.07]],"ltp":1.37,"tv":53420.41,"id":9342449},{"batb":[[0,3.9,20.68],[1,3.75,3.27],[2,3.7,3.42]],"batl":[[0,4.5,8.01],[1,4.9,2.15],[2,5.4,2.04]],"ltp":3.9,"tv":8106.4,"id":9633869}]}]}
{"op":"mcm","clk":"4230558791","pt":1631534285540,"mc":[{"id":"1.187557995","rc":[{"batb":[[0,1.28,434.41],[1,1.27,195.87],[2,1.26,88.48]],"batl":[[0,1.37,179.81],[1,1.38,64.75],[2,1.39,59.5]],"ltp":1.37,"tv":53420.41,"id":9342449},{"batb":[[0,3.6,71.32],[1,3.55,3.59],[2,3.4,3.71]],"batl":[[0,4.9,2.15],[1,5.4,2.04],[2,5.6,2.01]],"ltp":3.9,"tv":8106.4,"id":9633869}]}]}
{"op":"mcm","clk":"4230558943","pt":1631534287335,"mc":[{"id":"1.187557995","rc":[{"batb":[[2,1.26,516.15]],"batl":[[2,1.39,217.47]],"ltp":1.37,"tv":53420.41,"id":9342449}]}]}
{"op":"mcm","clk":"4230559058","pt":1631534288550,"mc":[{"id":"1.187557995","rc":[{"batb":[[0,1.29,10],[1,1.28,445.41],[2,1.27,203.87]],"batl":[[2,1.39,59.5]],"ltp":1.37,"tv":53420.41,"id":9342449},{"batl":[[0,4.5,2],[1,4.6,3],[2,4.9,2.15]],"ltp":3.9,"tv":8106.4,"id":9633869}]}]}
{"op":"mcm","clk":"4230559316","pt":1631534291455,"mc":[{"id":"1.187557995","rc":[{"batb":[[0,1.3,383.26],[1,1.29,414.46],[2,1.28,445.41]],"batl":[[0,1.32,427.66],[1,1.33,339.76],[2,1.34,321.71]],"ltp":1.37,"tv":53420.41,"id":9342449}]}]}
{"op":"mcm","clk":"4230559425","pt":1631534292659,"mc":[{"id":"1.187557995","rc":[{"batb":[[1,1.29,461.06]],"batl":[[1,1.33,339.68]],"ltp":1.37,"tv":53420.41,"id":9342449},{"batb":[[0,3.75,2.99],[1,3.6,71.32],[2,3.55,3.59]],"batl":[[0,4.4,10],[1,4.5,2],[2,4.6,3]],"ltp":3.9,"tv":8106.4,"id":9633869}]}]}
{"op":"mcm","clk":"4230559605","pt":1631534294491,"mc":[{"id":"1.187557995","rc":[{"batb":[[0,1.29,10],[1,1.28,445.41],[2,1.27,203.87]],"batl":[[1,1.36,75.07],[2,1.37,179.73]],"ltp":1.37,"tv":53420.41,"id":9342449},{"batl":[[0,4.5,2],[1,4.6,3],[2,4.9,2.15]],"ltp":3.9,"tv":8106.4,"id":9633869}]}]}
{"op":"mcm","clk":"4230559709","pt":1631534295551,"mc":[{"id":"1.187557995","rc":[{"batl":[[0,1.32,300.55]],"ltp":1.37,"tv":53420.41,"id":9342449}]}]}
{"op":"mcm","clk":"4230560231","pt":1631534301571,"mc":[{"id":"1.187557995","rc":[{"batl":[[0,1.36,75.15],[1,1.37,179.73],[2,1.38,64.75]],"ltp":1.37,"tv":53420.41,"id":9342449}]}]}
{"op":"mcm","clk":"4230560324","pt":1631534302570,"mc":[{"id":"1.187557995","rc":[{"batb":[[1,1.28,434.41],[2,1.27,195.87]],"batl":[[0,1.38,64.83],[1,1.39,217.47],[2,1.4,262.19]],"ltp":1.37,"tv":53420.41,"id":9342449},{"batb":[[0,3.6,71.32],[1,3.55,3.59],[2,3.4,3.71]],"batl":[[1,4.9,2.15],[2,5.4,2.04]],"ltp":3.9,"tv":8106.4,"id":9633869}]}]}
{"op":"mcm","clk":"4230560429","pt":1631534303675,"mc":[{"id":"1.187557995","rc":[{"trd":[[1.32,243.9]],"batb":[[0,1.36,18.24],[1,1.29,10],[2,1.28,434.41]],"batl":[[0,1.38,64.75]],"ltp":1.32,"tv":53420.57,"id":9342449}],"tv":61526.97}]}
{"op":"mcm","clk":"4230560529","pt":1631534304676,"mc":[{"id":"1.187557995","rc":[{"batb":[[0,1.36,412.3],[1,1.35,1733.61],[2,1.34,1389.22]],"ltp":1.32,"tv":53420.57,"id":9342449},{"trd":[[3.6,60.14]],"batb":[[0,3.6,65.17],[2,3.45,304.89]],"batl":[[0,3.95,2],[1,4.5,2],[2,4.9,2.15]],"ltp":3.6,"tv":8118.7,"id":9633869}],"tv":61539.27}]}
{"op":"mcm","clk":"4230560633","pt":1631534305698,"mc":[{"id":"1.187557995","rc":[{"batb":[[1,1.35,1991.85]],"ltp":1.32,"tv":53420.57,"id":9342449},{"batb":[[2,3.45,329.37]],"batl":[[1,4,8.66],[2,4.5,2]],"ltp":3.6,"tv":8118.7,"id":9633869}]}]}
{"op":"mcm","clk":"4230560783","pt":1631534307002,"mc":[{"id":"1.187557995","rc":[{"trd":[[1.36,10760.35]],"batb":[[0,1.37,8],[1,1.36,402.06],[2,1.35,1991.85]],"ltp":1.36,"tv":53457.05,"id":9342449},{"batl":[[0,3.75,3],[1,3.95,2],[2,4,8.66]],"ltp":3.6,"tv":8118.7,"id":9633869}],"tv":61575.75}]}
{"op":"mcm","clk":"4230560926","pt":1631534308613,"mc":[{"id":"1.187557995","rc":[{"trd":[[1.37,1223.35]],"batb":[[0,1.36,473.85],[1,1.35,1991.85],[2,1.34,1389.22]],"batl":[[0,1.37,272.73],[1,1.38,134.82],[2,1.39,236.77]],"ltp":1.37,"tv":53473.05,"id":9342449},{"batb":[[1,3.45,329.37],[2,3.4,299.63]],"ltp":3.6,"tv":8118.7,"id":9633869}],"tv":61591.75}]}
{"op":"mcm","clk":"4230561046","pt":1631534309706,"mc":[{"id":"1.187557995","rc":[{"batb":[[1,1.35,2062.09]],"batl":[[1,1.38,328.75]],"ltp":1.37,"tv":53473.05,"id":9342449},{"batl":[[1,3.9,10],[2,3.95,2]],"ltp":3.6,"tv":8118.7,"id":9633869}]}]}
{"op":"mcm","clk":"4230561091","pt":1631534310179,"mc":[{"id":"1.187557995","rc":[{"trd":[[1.37,1231.45]],"batb":[[1,1.35,4982.5]],"batl":[[0,1.37,264.63],[1,1.38,604.75]],"ltp":1.37,"tv":53481.15,"id":9342449},{"trd":[[3.7,18.08]],"ltp":3.7,"tv":8121.7,"id":9633869}],"tv":61602.85}]}
{"op":"mcm","clk":"4230561195","pt":1631534311394,"mc":[{"id":"1.187557995","rc":[{"batb":[[1,3.5,3.2],[2,3.45,329.37]],"ltp":3.7,"tv":8121.7,"id":9633869}]}]}
{"op":"mcm","clk":"4230561283","pt":1631534312318,"mc":[{"id":"1.187557995","rc":[{"batb":[[2,1.34,1492.11]],"batl":[[2,1.39,302.27]],"ltp":1.37,"tv":53481.15,"id":9342449},{"batb":[[1,3.55,3.79],[2,3.5,3.2]],"ltp":3.7,"tv":8121.7,"id":9633869}]}]}
{"op":"mcm","clk":"4230561340","pt":1631534312909,"mc":[{"id":"1.187557995","rc":[{"batl":[[1,3.9,18.8]],"ltp":3.7,"tv":8121.7,"id":9633869}]}]}
{"op":"mcm","clk":"4230561528","pt":1631534314901,"mc":[{"id":"1.187557995","rc":[{"batl":[[2,1.39,223.47]],"ltp":1.37,"tv":53481.15,"id":9342449}]}]}
{"op":"mcm","clk":"4230561663","pt":1631534316580,"mc":[{"id":"1.187557995","rc":[{"batb":[[0,1.36,446.29],[1,1.35,4912.27]],"ltp":1.37,"tv":53481.15,"id":9342449}]}]}
{"op":"mcm","clk":"4230561760","pt":1631534317631,"mc":[{"id":"1.187557995","rc":[{"batb":[[0,1.36,71.79],[1,1.35,2920.42],[2,1.34,102.89]],"batl":[[1,1.38,346.07],[2,1.39,65.5]],"ltp":1.37,"tv":53481.15,"id":9342449},{"batb":[[0,3.55,3.79],[1,3.5,3.2],[2,3.45,24.48]],"batl":[[0,3.9,8.8],[1,4.1,61.23],[2,4.2,57.05]],"ltp":3.7,"tv":8121.7,"id":9633869}]}]}
{"op":"mcm","clk":"4230561847","pt":1631534318609,"mc":[{"id":"1.187557995","rc":[{"batb":[[0,1.32,512.75],[1,1.31,214.34],[2,1.3,576.02]],"batl":[[0,1.39,65.5],[1,1.4,62.94],[2,1.41,59.5]],"ltp":1.37,"tv":53481.15,"id":9342449},{"batb":[[2,3.4,3.71]],"batl":[[0,4.1,61.23],[1,4.2,57.05],[2,4.3,69.63]],"ltp":3.7,"tv":8121.7,"id":9633869}]}]}
{"op":"mcm","clk":"4230561879","pt":1631534319029,"mc":[{"id":"1.187557995","rc":[{"batl":[[0,1.41,59.5],[1,1.45,156.76],[2,1.46,176.23]],"ltp":1.37,"tv":53481.15,"id":9342449},{"batb":[[0,3.4,3.71],[1,3.35,81.84],[2,3.25,65.22]],"ltp":3.7,"tv":8121.7,"id":9633869}]}]}
{"op":"mcm","clk":"4230562006","pt":1631534320615,"mc":[{"id":"1.187557995","rc":[{"batb":[[1,1.31,592.66],[2,1.3,963.28]],"batl":[[1,1.45,479.06],[2,1.46,392.7]],"ltp":1.37,"tv":53481.15,"id":9342449},{"batb":[[2,3.3,82.17]],"ltp":3.7,"tv":8121.7,"id":9633869}]}]}
{"op":"mcm","clk":"4230562040","pt":1631534321124,"mc":[{"id":"1.187557995","rc":[{"batb":[[2,1.3,962.36]],"ltp":1.37,"tv":53481.15,"id":9342449},{"batb":[[1,3.3,82.17],[2,3.25,65.22]],"ltp":3.7,"tv":8121.7,"id":9633869}]}]}
{"op":"mcm","clk":"4230562171","pt":1631534322707,"mc":[{"id":"1.187557995","rc":[{"batb":[[0,1.33,7],[1,1.32,521.75],[2,1.31,602.66]],"batl":[[1,1.49,2.99],[2,1.62,618.19]],"ltp":1.37,"tv":53481.15,"id":9342449},{"batb":[[2,2.2,42.67]],"batl":[[0,4.1,64.23]],"ltp":3.7,"tv":8121.7,"id":9633869}]}]}
{"op":"mcm","clk":"4230562247","pt":1631534323698,"mc":[{"id":"1.187557995","rc":[{"batb":[[0,1.37,6.51],[1,1.32,275.1],[2,1.31,592.66]],"batl":[[1,1.42,210.39],[2,1.49,2.99]],"ltp":1.37,"tv":53481.15,"id":9342449},{"batl":[[0,4.1,61.23]],"ltp":3.7,"tv":8121.7,"id":9633869}]}]}
{"op":"mcm","clk":"4230562323","pt":1631534324530,"mc":[{"id":"1.187557995","rc":[{"batb":[[1,1.33,500],[2,1.32,196.46]],"ltp":1.37,"tv":53481.15,"id":9342449},{"batl":[[1,4.2,54.42]],"ltp":3.7,"tv":8121.7,"id":9633869}]}]}
{"op":"mcm","clk":"4230562411","pt":1631534325632,"mc":[{"id":"1.187557995","rc":[{"trd":[[1.37,1244.47]],"batb":[[0,1.33,500],[1,1.32,196.46],[2,1.31,592.66]],"batl":[[0,1.34,305.86],[1,1.35,310.37],[2,1.41,59.5]],"ltp":1.37,"tv":53494.16,"id":9342449},{"batb":[[0,3.9,980.78],[1,3.85,951.92],[2,3.8,951.92]],"ltp":3.7,"tv":8121.7,"id":9633869}],"tv":61615.87}]}
{"op":"mcm","clk":"4230562480","pt":1631534326637,"mc":[{"id":"1.187557995","rc":[{"trd":[[3.95,17.26]],"batb":[[0,3.95,102.32],[1,3.9,490.4],[2,3.85,475.96]],"ltp":3.95,"tv":8132.96,"id":9633869}],"tv":61627.13}]}
{"op":"mcm","clk":"4230562552","pt":1631534327631,"mc":[{"id":"1.187557995","rc":[{"batb":[[2,3.85,497.01]],"ltp":3.95,"tv":8132.96,"id":9633869}]}]}
{"op":"mcm","clk":"4230562616","pt":1631534328626,"mc":[{"id":"1.187557995","rc":[{"batl":[[2,1.4,6]],"ltp":1.37,"tv":53494.16,"id":9342449}]}]}
{"op":"mcm","clk":"4230562766","pt":1631534330618,"mc":[{"id":"1.187557995","rc":[{"batb":[[0,1.33,557.39],[1,1.32,263.19]],"batl":[[0,1.34,636.27],[1,1.35,615.89],[2,1.36,15]],"ltp":1.37,"tv":53494.16,"id":9342449}]}]}
{"op":"mcm","clk":"4230562865","pt":1631534331617,"mc":[{"id":"1.187557995","rc":[{"batl":[[0,1.34,682.6],[2,1.38,218.91]],"ltp":1.37,"tv":53494.16,"id":9342449},{"batb":[[0,3.95,120.87],[2,3.85,475.96]],"ltp":3.95,"tv":8132.96,"id":9633869}]}]}
{"op":"mcm","clk":"4230562974","pt":1631534332606,"mc":[{"id":"1.187557995","rc":[{"trd":[[1.34,6992.16]],"batl":[[0,1.34,913.76],[2,1.37,61.5]],"ltp":1.34,"tv":53509.84,"id":9342449}],"tv":61642.81}]}
{"op":"mcm","clk":"4230563148","pt":1631534334637,"mc":[{"id":"1.187557995","rc":[{"batl":[[1,1.35,630.89]],"ltp":1.34,"tv":53509.84,"id":9342449},{"batb":[[1,3.9,511.08]],"ltp":3.95,"tv":8132.96,"id":9633869}]}]}
{"op":"mcm","clk":"4230563216","pt":1631534335331,"mc":[{"id":"1.187557995","rc":[{"batb":[[1,1.32,196.46]],"batl":[[0,1.34,1159.76],[1,1.35,572.4]],"ltp":1.34,"tv":53509.84,"id":9342449}]}]}
{"op":"mcm","clk":"4230563386","pt":1631534337154,"mc":[{"id":"1.187557995","rc":[{"batb":[[1,1.32,205.46],[2,1.31,601.66]],"ltp":1.34,"tv":53509.84,"id":9342449}]}]}
{"op":"mcm","clk":"4230563493","pt":1631534338517,"mc":[{"id":"1.187557995","rc":[{"batl":[[0,1.34,1240.23]],"ltp":1.34,"tv":53509.84,"id":9342449}]}]}
{"op":"mcm","clk":"4230563669","pt":1631534340463,"mc":[{"id":"1.187557995","rc":[{"batb":[[0,1.33,500]],"batl":[[0,1.34,850.02]],"ltp":1.34,"tv":53509.84,"id":9342449}]}]}
{"op":"mcm","clk":"4230564054","pt":1631534344728,"mc":[{"id":"1.187557995","rc":[{"batl":[[0,1.34,1056.78]],"ltp":1.34,"tv":53509.84,"id":9342449},{"batb":[[1,3.9,589.21]],"ltp":3.95,"tv":8132.96,"id":9633869}]}]}
{"op":"mcm","clk":"4230564221","pt":1631534346767,"mc":[{"id":"1.187557995","rc":[{"batl":[[1,1.35,788.75]],"ltp":1.34,"tv":53509.84,"id":9342449},{"batb":[[2,3.85,551.82]],"ltp":3.95,"tv":8132.96,"id":9633869}]}]}
{"op":"mcm","clk":"4230564338","pt":1631534347868,"mc":[{"id":"1.187557995","rc":[{"trd":[[1.33,1208.44]],"batb":[[0,1.33,479.33]],"ltp":1.33,"tv":53551.18,"id":9342449}],"tv":61684.15}]}
{"op":"mcm","clk":"4230564490","pt":1631534349240,"mc":[{"id":"1.187557995","rc":[{"batb":[[2,1.31,592.66]],"batl":[[2,1.36,237.65]],"ltp":1.33,"tv":53551.18,"id":9342449}]}]}
{"op":"mcm","clk":"4230564776","pt":1631534352427,"mc":[{"id":"1.187557995","rc":[{"batb":[[2,1.31,600.66]],"ltp":1.33,"tv":53551.18,"id":9342449}]}]}
{"op":"mcm","clk":"4230564948","pt":1631534354305,"mc":[{"id":"1.187557995","rc":[{"batl":[[2,1.36,454.22]],"ltp":1.33,"tv":53551.18,"id":9342449}]}]}
{"op":"mcm","clk":"4230565745","pt":1631534362535,"mc":[{"id":"1.187557995","rc":[{"batb":[[1,1.32,9],[2,1.31,8]],"batl":[[0,1.34,485],[1,1.35,262.03],[2,1.37,61.5]],"ltp":1.33,"tv":53551.18,"id":9342449},{"batb":[[0,3.95,102.32],[1,3.9,20.68],[2,3.7,3.12]],"batl":[[0,4.4,3],[1,4.6,62.04],[2,4.7,73.23]],"ltp":3.95,"tv":8132.96,"id":9633869}]}]}
{"op":"mcm","clk":"4230565853","pt":1631534363436,"mc":[{"id":"1.187557995","rc":[{"batb":[[0,1.3,202.73],[1,1.29,405.45],[2,1.28,177.89]],"batl":[[0,1.38,218.91],[1,1.39,60.5],[2,1.4,139.87]],"ltp":1.33,"tv":53551.18,"id":9342449},{"batb":[[0,3.6,67.7],[1,3.55,3.39],[2,3.5,73.25]],"batl":[[0,4.6,62.04],[1,4.7,73.23],[2,4.8,75.64]],"ltp":3.95,"tv":8132.96,"id":9633869}]}]}
{"op":"mcm","clk":"4230566083","pt":1631534365526,"mc":[{"id":"1.187557995","rc":[{"batl":[[1,1.39,224.74],[2,1.4,401.97]],"ltp":1.33,"tv":53551.18,"id":9342449}]}]}
{"op":"mcm","clk":"4230566117","pt":1631534365945,"mc":[{"id":"1.187557995","rc":[{"batb":[[0,1.29,405.45],[1,1.28,177.89],[2,1.27,416.44]],"ltp":1.33,"tv":53551.18,"id":9342449}]}]}
{"op":"mcm","clk":"4230566256","pt":1631534367526,"mc":[{"id":"1.187557995","rc":[{"batl":[[1,1.39,60.5],[2,1.4,139.87]],"ltp":1.33,"tv":53551.18,"id":9342449}]}]}
{"op":"mcm","clk":"4230566474","pt":1631534369634,"mc":[{"id":"1.187557995","rc":[{"batb":[[0,1.3,423.35],[1,1.29,820.7],[2,1.28,187.89]],"batl":[[0,1.33,348.16],[1,1.34,321.55],[2,1.36,4]],"ltp":1.33,"tv":53551.18,"id":9342449},{"batb":[[0,3.65,44.75],[1,3.6,67.7],[2,3.55,3.39]],"batl":[[0,4.5,26.26],[1,4.6,62.04],[2,4.7,73.23]],"ltp":3.95,"tv":8132.96,"id":9633869}]}]}
{"op":"mcm","clk":"4230566569","pt":1631534370539,"mc":[{"id":"1.187557995","rc":[{"batb":[[0,1.3,373.99]],"batl":[[0,1.33,757.04],[2,1.37,75.5]],"ltp":1.33,"tv":53551.18,"id":9342449},{"batb":[[0,3.7,3.12]],"batl":[[0,4.5,2]],"ltp":3.95,"tv":8132.96,"id":9633869}]}]}
{"op":"mcm","clk":"4230566767","pt":1631534372544,"mc":[{"id":"1.187557995","rc":[{"batb":[[0,1.29,416.45],[1,1.28,187.89],[2,1.27,416.44]],"batl":[[0,1.33,408.88],[1,1.37,75.5],[2,1.38,218.91]],"ltp":1.33,"tv":53551.18,"id":9342449}]}]}
{"op":"mcm","clk":"4230566889","pt":1631534373750,"mc":[{"id":"1.187557995","rc":[{"batl":[[0,1.33,21.69]],"ltp":1.33,"tv":53551.18,"id":9342449}]}]}
{"op":"mcm","clk":"4230567443","pt":1631534379549,"mc":[{"id":"1.187557995","rc":[{"batb":[[1,1.28,10],[2,1.27,195.87]],"batl":[[0,1.37,75.5],[1,1.38,218.91],[2,1.39,224.74]],"ltp":1.33,"tv":53551.18,"id":9342449},{"batl":[[1,4.9,2.15],[2,5.4,2.04]],"ltp":3.95,"tv":8132.96,"id":9633869}]}]}
{"op":"mcm","clk":"4230567465","pt":1631534379759,"mc":[{"id":"1.187557995","rc":[{"batl":[[0,1.38,218.91],[1,1.39,224.74],[2,1.4,401.97]],"ltp":1.33,"tv":53551.18,"id":9342449},{"batb":[[0,3.6,67.7],[1,3.55,3.39],[2,3.5,73.25]],"ltp":3.95,"tv":8132.96,"id":9633869}]}]}
{"op":"mcm","clk":"4230567618","pt":1631534381288,"mc":[{"id":"1.187557995","rc":[{"batb":[[1,1.27,195.87],[2,1.26,88.48]],"batl":[[0,1.39,224.74],[1,1.4,401.97],[2,1.41,215.35]],"ltp":1.33,"tv":53551.18,"id":9342449}]}]}
{"op":"mcm","clk":"4230567780","pt":1631534382674,"mc":[{"id":"1.187557995","rc":[{"batb":[[0,1.36,414.11],[1,1.35,1733.49],[2,1.34,1388.72]],"ltp":1.33,"tv":53551.18,"id":9342449},{"trd":[[3.6,72.44]],"batb":[[0,3.6,61.55]],"batl":[[0,3.95,2],[1,4.5,2],[2,4.9,2.15]],"ltp":3.6,"tv":8145.26,"id":9633869}],"tv":61696.45}]}
{"op":"mcm","clk":"4230567870","pt":1631534383464,"mc":[{"id":"1.187557995","rc":[{"batb":[[1,1.35,1992.65]],"batl":[[1,1.4,416.97]],"ltp":1.33,"tv":53551.18,"id":9342449},{"batb":[[2,3.5,97.25]],"batl":[[1,4,8.66],[2,4.5,2]],"ltp":3.6,"tv":8145.26,"id":9633869}]}]}
{"op":"mcm","clk":"4230568042","pt":1631534385249,"mc":[{"id":"1.187557995","rc":[{"batb":[[0,1.37,8],[1,1.36,423.11],[2,1.35,1992.65]],"ltp":1.33,"tv":53551.18,"id":9342449},{"batl":[[0,3.75,3],[1,3.95,2],[2,4,8.66]],"ltp":3.6,"tv":8145.26,"id":9633869}]}]}
{"op":"mcm","clk":"4230568187","pt":1631534386670,"mc":[{"id":"1.187557995","rc":[{"batb":[[0,1.37,75.57]],"batl":[[0,1.38,508.4],[1,1.39,224.74],[2,1.4,416.97]],"ltp":1.33,"tv":53551.18,"id":9342449}]}]}
{"op":"mcm","clk":"4230568311","pt":1631534387681,"mc":[{"id":"1.187557995","rc":[{"trd":[[1.37,1284.91]],"batb":[[0,1.37,55.35],[1,1.36,3328.29]],"batl":[[1,1.39,302.17]],"ltp":1.37,"tv":53591.63,"id":9342449},{"batl":[[1,3.9,10],[2,3.95,2]],"ltp":3.6,"tv":8145.26,"id":9633869}],"tv":61736.89}]}
{"op":"mcm","clk":"4230568411","pt":1631534388577,"mc":[{"id":"1.187557995","rc":[{"batl":[[1,1.39,559.45]],"ltp":1.37,"tv":53591.63,"id":9342449},{"batl":[[0,3.7,3],[1,3.75,3],[2,3.9,10]],"ltp":3.6,"tv":8145.26,"id":9633869}]}]}
{"op":"mcm","clk":"4230568496","pt":1631534389370,"mc":[{"id":"1.187557995","rc":[{"batl":[[2,1.4,485.51]],"ltp":1.37,"tv":53591.63,"id":9342449},{"batb":[[2,3.5,101.33]],"ltp":3.6,"tv":8145.26,"id":9633869}]}]}
{"op":"mcm","clk":"4230568676","pt":1631534391580,"mc":[{"id":"1.187557995","rc":[{"batl":[[2,3.9,18.8]],"ltp":3.6,"tv":8145.26,"id":9633869}]}]}
{"op":"mcm","clk":"4230568950","pt":1631534394577,"mc":[{"id":"1.187557995","rc":[{"trd":[[1.37,1293.01]],"batb":[[0,1.36,3273.93],[1,1.35,1992.65],[2,1.34,1491.61]],"batl":[[0,1.37,213.42],[1,1.38,245.68],[2,1.39,482.02]],"ltp":1.37,"tv":53599.73,"id":9342449},{"trd":[[3.7,21.08]],"batl":[[0,3.75,3],[1,3.9,18.8],[2,3.95,2]],"ltp":3.7,"tv":8148.26,"id":9633869}],"tv":61747.99}]}
{"op":"mcm","clk":"4230569132","pt":1631534396484,"mc":[{"id":"1.187557995","rc":[{"batb":[[0,1.36,3208.04]],"batl":[[0,1.38,183.12],[1,1.39,482.02],[2,1.4,485.51]],"ltp":1.37,"tv":53599.73,"id":9342449}]}]}
{"op":"mcm","clk":"4230569244","pt":1631534397588,"mc":[{"id":"1.187557995","rc":[{"trd":[[1.37,1293.31]],"batl":[[0,1.37,29.6],[1,1.38,183.12],[2,1.39,482.02]],"ltp":1.37,"tv":53600.03,"id":9342449}],"tv":61748.29}]}
{"op":"mcm","clk":"4230569433","pt":1631534399708,"mc":[{"id":"1.187557995","rc":[{"trd":[[1.37,1352.51]],"batb":[[0,1.37,61.28],[1,1.36,3208.04],[2,1.35,1992.65]],"batl":[[0,1.38,183.12],[1,1.39,482.02],[2,1.4,485.51]],"ltp":1.37,"tv":53659.23,"id":9342449}],"tv":61807.49}]}
{"op":"mcm","clk":"4230569510","pt":1631534400611,"mc":[{"id":"1.187557995","rc":[{"batb":[[0,1.36,2839.29],[1,1.34,102.89],[2,1.33,145.59]],"batl":[[0,1.39,83],[1,1.4,15],[2,1.41,59.5]],"ltp":1.37,"tv":53659.23,"id":9342449},{"batb":[[0,3.5,24],[1,3.4,3.71],[2,3.35,81]],"batl":[[0,3.9,8.8],[1,4.1,51.59],[2,4.2,77.63]],"ltp":3.7,"tv":8148.26,"id":9633869}]}]}
{"op":"mcm","clk":"4230569611","pt":1631534401421,"mc":[{"id":"1.187557995","rc":[{"batb":[[0,1.33,145.59],[1,1.32,699.32],[2,1.31,241.64]],"batl":[[0,1.41,59.5],[1,1.45,126.15],[2,1.46,203.83]],"ltp":1.37,"tv":53659.23,"id":9342449},{"batb":[[0,3.4,3.71],[1,3.35,81],[2,3.25,73.25]],"batl":[[0,4.1,51.59],[1,4.2,77.63],[2,4.3,81.64]],"ltp":3.7,"tv":8148.26,"id":9633869}]}]}
{"op":"mcm","clk":"4230569975","pt":1631534404694,"mc":[{"id":"1.187557995","rc":[{"batb":[[0,1.34,9],[1,1.33,154.59],[2,1.32,707.32]],"ltp":1.37,"tv":53659.23,"id":9342449}]}]}
{"op":"mcm","clk":"4230570084","pt":1631534405696,"mc":[{"id":"1.187557995","rc":[{"batb":[[0,1.35,349.75],[1,1.34,337.98],[2,1.33,154.59]],"batl":[[0,1.38,201.65],[1,1.39,270.63],[2,1.41,59.5]],"ltp":1.37,"tv":53659.23,"id":9342449},{"batl":[[0,4.1,54.59]],"ltp":3.7,"tv":8148.26,"id":9633869}]}]}
{"op":"mcm","clk":"4230570122","pt":1631534406117,"mc":[{"id":"1.187557995","rc":[{"batb":[[1,1.34,544.96],[2,1.33,654.59]],"ltp":1.37,"tv":53659.23,"id":9342449}]}]}
{"op":"mcm","clk":"4230570247","pt":1631534407484,"mc":[{"id":"1.187557995","rc":[{"batb":[[1,1.34,596.61]],"batl":[[1,1.39,341.13],[2,1.4,63.81]],"ltp":1.37,"tv":53659.23,"id":9342449},{"batb":[[0,3.55,3.39],[1,3.4,3.71],[2,3.35,81]],"batl":[[0,4,21.93],[1,4.1,54.59],[2,4.2,77.63]],"ltp":3.7,"tv":8148.26,"id":9633869}]}]}
{"op":"mcm","clk":"4230570377","pt":1631534408699,"mc":[{"id":"1.187557995","rc":[{"batl":[[0,1.37,2077.05],[1,1.38,201.65],[2,1.39,341.13]],"ltp":1.37,"tv":53659.23,"id":9342449}]}]}
{"op":"mcm","clk":"4230570588","pt":1631534410612,"mc":[{"id":"1.187557995","rc":[{"batb":[[0,1.36,73.41],[1,1.35,349.75],[2,1.34,596.61]],"batl":[[0,1.37,2436.95],[1,1.38,284.65]],"ltp":1.37,"tv":53659.23,"id":9342449},{"batb":[[0,3.6,18.55],[1,3.55,3.39],[2,3.4,3.71]],"ltp":3.7,"tv":8148.26,"id":9633869}]}]}
{"op":"mcm","clk":"4230570606","pt":1631534410822,"mc":[{"id":"1.187557995","rc":[{"batb":[[0,1.35,349.75],[1,1.34,596.61],[2,1.33,654.59]],"ltp":1.37,"tv":53659.23,"id":9342449},{"batb":[[0,3.55,3.39],[1,3.4,3.71],[2,3.35,81]],"ltp":3.7,"tv":8148.26,"id":9633869}]}]}
{"op":"mcm","clk":"4230570774","pt":1631534412627,"mc":[{"id":"1.187557995","rc":[{"batb":[[0,1.35,428.39],[1,1.34,544.96]],"ltp":1.37,"tv":53659.23,"id":9342449},{"batl":[[0,4.1,54.59],[1,4.2,77.63],[2,4.3,81.64]],"ltp":3.7,"tv":8148.26,"id":9633869}]}]}
{"op":"mcm","clk":"4230570837","pt":1631534413210,"mc":[{"id":"1.187557995","rc":[{"batb":[[0,1.34,215.98],[1,1.33,654.59],[2,1.32,707.32]],"batl":[[0,1.37,2077.05],[1,1.39,70.5],[2,1.41,59.5]],"ltp":1.37,"tv":53659.23,"id":9342449}]}]}
{"op":"mcm","clk":"4230571147","pt":1631534416217,"mc":[{"id":"1.187557995","rc":[{"batb":[[1,1.33,645.59],[2,1.32,699.32]],"ltp":1.37,"tv":53659.23,"id":9342449}]}]}
{"op":"mcm","clk":"4230571418","pt":1631534419227,"mc":[{"id":"1.187557995","rc":[{"batb":[[1,1.33,652.59]],"ltp":1.37,"tv":53659.23,"id":9342449}]}]}
{"op":"mcm","clk":"4230571807","pt":1631534423431,"mc":[{"id":"1.187557995","rc":[{"trd":[[1.34,7424.1]],"batb":[[0,1.33,507],[1,1.32,520.11],[2,1.3,309.12]],"ltp":1.34,"tv":54091.16,"id":9342449},{"batl":[[0,4.1,3],[1,4.2,2.38],[2,4.5,2.33]],"ltp":3.7,"tv":8148.26,"id":9633869}],"tv":62239.42}]}
{"op":"mcm","clk":"4230571998","pt":1631534425117,"mc":[{"id":"1.187557995","rc":[{"batb":[[1,1.32,83.14]],"ltp":1.34,"tv":54091.16,"id":9342449}]}]}
{"op":"mcm","clk":"4230572144","pt":1631534426518,"mc":[{"id":"1.187557995","rc":[{"trd":[[1.37,5507.15],[1.39,192.23],[1.4,1127.98],[1.41,548.64]],"batb":[[0,1.37,13.77],[1,1.33,7],[2,1.29,88.81]],"batl":[[0,1.49,2.99],[1,1.82,2.89],[2,2.08,1]],"ltp":1.41,"tv":58507.53,"id":9342449},{"trd":[[3.4,15.24],[3.55,21.57]],"batb":[[0,2.2,42.67],[1,2,11.88],[2,1.97,1.05]],"batl":[[0,3.75,2],[1,4.1,3]],"ltp":3.4,"tv":8161.92,"id":9633869}],"tv":66669.45}]}
{"op":"mcm","clk":"4230572234","pt":1631534427418,"mc":[{"id":"1.187557995","rc":[{"batb":[[0,1.41,9.39],[1,1.37,2785.33],[2,1.36,6]],"batl":[[1,1.59,12.58],[2,1.82,2.89]],"ltp":1.41,"tv":58507.53,"id":9342449},{"batl":[[0,3.45,144.64],[1,3.7,2],[2,3.75,2]],"ltp":3.4,"tv":8161.92,"id":9633869}]}]}
{"op":"mcm","clk":"4230572353","pt":1631534428643,"mc":[{"id":"1.187557995","rc":[{"batb":[[0,1.41,132.2],[1,1.37,2776.33],[2,1.29,88.81]],"batl":[[2,1.82,482.28]],"ltp":1.41,"tv":58507.53,"id":9342449},{"batl":[[0,3.75,2],[1,4.5,2.33],[2,3.75,0]],"ltp":3.4,"tv":8161.92,"id":9633869}]}]}
{"op":"mcm","clk":"4230572460","pt":1631534429640,"mc":[{"id":"1.187557995","rc":[{"batb":[[0,1.41,2625.24],[1,1.38,1309.61],[2,1.37,3012.27]],"batl":[[0,1.46,41.1],[1,1.49,2.99],[2,1.59,12.58]],"ltp":1.41,"tv":58507.53,"id":9342449},{"batb":[[0,3.15,27.9],[1,2.84,81.51],[2,2.52,640.2]],"batl":[[0,3.45,2],[1,3.75,2],[2,4.5,2.33]],"ltp":3.4,"tv":8161.92,"id":9633869}]}]}
{"op":"mcm","clk":"4230572552","pt":1631534430540,"mc":[{"id":"1.187557995","rc":[{"batb":[[0,1.41,2615.85],[1,1.37,13.77],[2,1.29,88.81]],"batl":[[0,1.42,195.32]],"ltp":1.41,"tv":58507.53,"id":9342449},{"batb":[[0,2.2,42.67],[1,2,11.88],[2,1.97,1.05]],"batl":[[0,3.65,3]],"ltp":3.4,"tv":8161.92,"id":9633869}]}]}
{"op":"mcm","clk":"4230572583","pt":1631534430852,"mc":[{"id":"1.187557995","rc":[{"batb":[[0,1.37,13.77],[1,1.29,88.81],[2,1.27,195.87]],"batl":[[0,1.49,2.99],[1,1.59,12.58],[2,1.82,2.89]],"ltp":1.41,"tv":58507.53,"id":9342449},{"batl":[[0,3.75,2],[1,4.5,2.33],[2,4.5,0]],"ltp":3.4,"tv":8161.92,"id":9633869}]}]}
{"op":"mcm","clk":"4230572882","pt":1631534434554,"mc":[{"id":"1.187557995","rc":[{"trd":[[1.36,10765.87],[1.37,5534.7]],"batb":[[0,1.29,88.81],[1,1.27,195.87],[2,1.2,2]],"batl":[[0,1.34,187.69],[1,1.49,2.99],[2,1.59,12.58]],"ltp":1.36,"tv":58540.6,"id":9342449},{"trd":[[3.75,28.79]],"batl":[[0,4.5,2.33],[1,4.5,0]],"ltp":3.75,"tv":8163.92,"id":9633869}],"tv":66704.52}]}
{"op":"mcm","clk":"4230573369","pt":1631534439357,"mc":[{"id":"1.187557995","rc":[{"batl":[[1,1.41,1022.15],[2,1.49,2.99]],"ltp":1.36,"tv":58540.6,"id":9342449}]}]}
{"op":"mcm","clk":"4230573565","pt":1631534441153,"mc":[{"id":"1.187557995","rc":[{"trd":[[1.34,7489.24]],"batb":[[0,1.31,350.99],[1,1.3,387.2],[2,1.29,88.81]],"batl":[[0,1.34,487.46],[1,1.35,310.33]],"ltp":1.34,"tv":58605.74,"id":9342449}],"tv":66769.66}]}
{"op":"mcm","clk":"4230573717","pt":1631534442677,"mc":[{"id":"1.187557995","rc":[{"batb":[[1,1.3,1582.44]],"ltp":1.34,"tv":58605.74,"id":9342449},{"batb":[[0,3.45,68.36],[1,2.58,507.71],[2,2.2,42.67]],"batl":[[0,4.4,11.65],[1,4.5,2.33]],"ltp":3.75,"tv":8163.92,"id":9633869}]}]}
{"op":"mcm","clk":"4230573888","pt":1631534444673,"mc":[{"id":"1.187557995","rc":[{"batb":[[0,1.32,64.89],[1,1.31,360.99],[2,1.3,1582.44]],"batl":[[0,1.33,348.44],[1,1.34,487.46],[2,1.35,310.33]],"ltp":1.34,"tv":58605.74,"id":9342449},{"batl":[[0,4.2,3],[1,4.4,3],[2,4.5,2.33]],"ltp":3.75,"tv":8163.92,"id":9633869}]}]}
{"op":"mcm","clk":"4230573943","pt":1631534445168,"mc":[{"id":"1.187557995","rc":[{"batb":[[1,1.31,432.42]],"batl":[[1,1.34,559.55]],"ltp":1.34,"tv":58605.74,"id":9342449}]}]}
{"op":"mcm","clk":"4230574185","pt":1631534447567,"mc":[{"id":"1.187557995","rc":[{"batl":[[0,4.1,3],[1,4.2,3],[2,4.4,3]],"ltp":3.75,"tv":8163.92,"id":9633869}]}]}
{"op":"mcm","clk":"4230574244","pt":1631534448174,"mc":[{"id":"1.187557995","rc":[{"trd":[[1.33,1216.73]],"batb":[[1,1.31,81.43],[2,1.27,195.87]],"batl":[[0,1.33,342.92],[1,1.34,227.21],[2,1.49,2.99]],"ltp":1.33,"tv":58614.03,"id":9342449},{"trd":[[4,47.51]],"batb":[[0,2.2,42.67],[1,2,11.88],[2,1.97,1.05]],"ltp":4.0,"tv":8164.83,"id":9633869}],"tv":66778.87}]}
{"op":"mcm","clk":"4230574507","pt":1631534451469,"mc":[{"id":"1.187557995","rc":[{"batl":[[1,1.34,72.09],[2,1.39,193.79]],"ltp":1.33,"tv":58614.03,"id":9342449}]}]}
{"op":"mcm","clk":"4230574612","pt":1631534452574,"mc":[{"id":"1.187557995","rc":[{"batb":[[0,1.32,141.64]],"batl":[[1,1.34,129.38],[2,1.49,2.99]],"ltp":1.33,"tv":58614.03,"id":9342449}]}]}
{"op":"mcm","clk":"4230574689","pt":1631534453467,"mc":[{"id":"1.187557995","rc":[{"trd":[[1.33,1276.24]],"batb":[[1,1.31,10]],"batl":[[0,1.33,313.16],[1,1.34,72.09]],"ltp":1.33,"tv":58673.54,"id":9342449}],"tv":66838.38}]}
{"op":"mcm","clk":"4230574784","pt":1631534454663,"mc":[{"id":"1.187557995","rc":[{"batb":[[0,1.32,9]],"batl":[[0,1.49,2.99],[1,1.59,12.58],[2,1.82,2.89]],"ltp":1.33,"tv":58673.54,"id":9342449}]}]}
{"op":"mcm","clk":"4230574865","pt":1631534455556,"mc":[{"id":"1.187557995","rc":[{"batb":[[1,1.31,360.99],[2,1.3,387.2]],"batl":[[0,1.34,332.34],[1,1.35,310.33],[2,1.49,2.99]],"ltp":1.33,"tv":58673.54,"id":9342449}]}]}
{"op":"mcm","clk":"4230574886","pt":1631534455764,"mc":[{"id":"1.187557995","rc":[{"batb":[[1,1.31,464.04]],"batl":[[0,1.33,389.76],[1,1.34,332.34],[2,1.35,310.33]],"ltp":1.33,"tv":58673.54,"id":9342449}]}]}
{"op":"mcm","clk":"4230575128","pt":1631534458663,"mc":[{"id":"1.187557995","rc":[{"batb":[[1,1.28,235.95],[2,1.27,195.87]],"batl":[[0,1.49,8.99],[1,1.59,12.58],[2,1.82,2.89]],"ltp":1.33,"tv":58673.54,"id":9342449},{"batb":[[0,2.68,3],[1,2.66,4],[2,2.2,42.67]],"batl":[[1,4.2,0],[2,4.4,0]],"ltp":4.0,"tv":8164.83,"id":9633869}]}]}
{"op":"mcm","clk":"4230575230","pt":1631534459870,"mc":[{"id":"1.187557995","rc":[{"trd":[[1.32,271.22]],"batb":[[0,1.28,235.95],[1,1.27,195.87],[2,1.2,2]],"batl":[[0,1.32,138.75],[1,1.49,8.99],[2,1.59,12.58]],"ltp":1.32,"tv":58700.86,"id":9342449},{"trd":[[4.1,9.62]],"ltp":4.1,"tv":8167.83,"id":9633869}],"tv":66868.7}]}
{"op":"mcm","clk":"4230575401","pt":1631534461672,"mc":[{"id":"1.187557995","rc":[{"batb":[[0,1.31,8],[1,1.28,235.95],[2,1.27,195.87]],"batl":[[1,1.39,193.79],[2,1.4,262.09]],"ltp":1.32,"tv":58700.86,"id":9342449},{"batb":[[0,3,3],[1,2.98,3],[2,2.68,3]],"ltp":4.1,"tv":8167.83,"id":9633869}]}]}
{"op":"mcm","clk":"4230575551","pt":1631534463085,"mc":[{"id":"1.187557995","rc":[{"trd":[[1.32,337.43]],"batb":[[1,1.29,9],[2,1.28,243.95]],"batl":[[0,1.32,105.64]],"ltp":1.32,"tv":58767.07,"id":9342449},{"batl":[[0,4.2,3],[1,4.6,2]],"ltp":4.1,"tv":8167.83,"id":9633869}],"tv":66934.91}]}
{"op":"mcm","clk":"4230575707","pt":1631534464606,"mc":[{"id":"1.187557995","rc":[{"batb":[[1,1.3,7],[2,1.29,9]],"batl":[[0,1.39,193.79],[1,1.4,262.09],[2,1.49,8.99]],"ltp":1.32,"tv":58767.07,"id":9342449},{"batl":[[1,4.3,3],[2,4.6,2]],"ltp":4.1,"tv":8167.83,"id":9633869}]}]}
{"op":"mcm","clk":"4230575842","pt":1631534465675,"mc":[{"id":"1.187557995","rc":[{"batb":[[0,1.36,329.38],[1,1.35,316.81],[2,1.32,103.89]],"ltp":1.32,"tv":58767.07,"id":9342449}]}]}
{"op":"mcm","clk":"4230575932","pt":1631534466701,"mc":[{"id":"1.187557995","rc":[{"batb":[[2,1.31,8]],"ltp":1.32,"tv":58767.07,"id":9342449}]}]}
{"op":"mcm","clk":"4230576045","pt":1631534467705,"mc":[{"id":"1.187557995","rc":[{"batb":[[2,1.33,104.44]],"batl":[[1,1.4,277.09]],"ltp":1.32,"tv":58767.07,"id":9342449},{"batb":[[0,3.45,24.48],[1,3,3],[2,2.98,3]],"batl":[[0,4,8.66],[1,4.1,3],[2,4.2,3]],"ltp":4.1,"tv":8167.83,"id":9633869}]}]}
{"op":"mcm","clk":"4230576141","pt":1631534468704,"mc":[{"id":"1.187557995","rc":[{"trd":[[1.36,10970.92]],"batb":[[0,1.37,7],[1,1.36,235.86],[2,1.35,316.81]],"ltp":1.36,"tv":58972.13,"id":9342449},{"batl":[[0,3.75,3],[1,4,8.66],[2,4.1,3]],"ltp":4.1,"tv":8167.83,"id":9633869}],"tv":67139.97}]}
{"op":"mcm","clk":"4230576331","pt":1631534470612,"mc":[{"id":"1.187557995","rc":[{"batb":[[0,1.37,66.22],[1,1.36,344.86]],"batl":[[0,1.38,294.25],[1,1.39,574.61],[2,1.4,277.09]],"ltp":1.36,"tv":58972.13,"id":9342449}]}]}
{"op":"mcm","clk":"4230576438","pt":1631534471706,"mc":[{"id":"1.187557995","rc":[{"trd":[[1.38,659.12]],"batb":[[1,1.36,390.73]],"batl":[[0,1.38,287.25],[1,1.39,629.88]],"ltp":1.38,"tv":58986.13,"id":9342449},{"batb":[[0,3.5,15],[1,3.45,24.48],[2,3,3]],"batl":[[1,3.95,26.98],[2,4,8.66]],"ltp":4.1,"tv":8167.83,"id":9633869}],"tv":67153.97}]}
{"op":"mcm","clk":"4230576474","pt":1631534472098,"mc":[{"id":"1.187557995","rc":[{"batl":[[1,1.39,602]],"ltp":1.38,"tv":58986.13,"id":9342449},{"batl":[[0,3.7,3],[1,3.75,3],[2,3.95,26.98]],"ltp":4.1,"tv":8167.83,"id":9633869}]}]}
{"op":"mcm","clk":"4230576615","pt":1631534473295,"mc":[{"id":"1.187557995","rc":[{"batb":[[1,1.36,3230.03]],"batl":[[0,1.38,571.47]],"ltp":1.38,"tv":58986.13,"id":9342449}]}]}
{"op":"mcm","clk":"4230576801","pt":1631534475299,"mc":[{"id":"1.187557995","rc":[{"batb":[[1,1.36,3258.68]],"ltp":1.38,"tv":58986.13,"id":9342449},{"batl":[[0,3.65,2],[1,3.7,3],[2,3.75,3]],"ltp":4.1,"tv":8167.83,"id":9633869}]}]}
{"op":"mcm","clk":"4230576923","pt":1631534476610,"mc":[{"id":"1.187557995","rc":[{"batb":[[0,1.37,59.22],[1,1.36,3209.68]],"ltp":1.38,"tv":58986.13,"id":9342449},{"batb":[[0,3,3],[1,2.2,42.67],[2,2,11.88]],"batl":[[0,4,8.66],[1,4.3,3],[2,3.75,0]],"ltp":4.1,"tv":8167.83,"id":9633869}]}]}
{"op":"mcm","clk":"4230577009","pt":1631534477505,"mc":[{"id":"1.187557995","rc":[{"batb":[[0,1.37,116.09],[1,1.36,2908.3],[2,1.33,302.05]],"batl":[[0,1.38,346.98],[1,1.39,71.42],[2,1.4,15]],"ltp":1.38,"tv":58986.13,"id":9342449}]}]}
{"op":"mcm","clk":"4230577099","pt":1631534478540,"mc":[{"id":"1.187557995","rc":[{"batb":[[0,1.37,59.22],[1,1.33,197.61],[2,1.3,7]],"batl":[[0,1.38,287.25],[1,1.49,8.99],[2,1.82,2.89]],"ltp":1.38,"tv":58986.13,"id":9342449},{"batl":[[0,4.3,3],[1,4.3,0]],"ltp":4.1,"tv":8167.83,"id":9633869}]}]}
{"op":"mcm","clk":"4230577224","pt":1631534479701,"mc":[{"id":"1.187557995","rc":[{"batb":[[0,1.33,197.61],[1,1.31,305.07],[2,1.3,394.1]],"batl":[[0,1.44,154.68],[1,1.45,224.45],[2,1.49,8.99]],"ltp":1.38,"tv":58986.13,"id":9342449}]}]}
{"op":"mcm","clk":"4230577276","pt":1631534480219,"mc":[{"id":"1.187557995","rc":[{"batb":[[1,1.3,7],[2,1.27,195.87]],"batl":[[0,1.49,8.99],[1,1.82,2.89],[2,2.08,1]],"ltp":1.38,"tv":58986.13,"id":9342449}]}]}
{"op":"mcm","clk":"4230577523","pt":1631534482628,"mc":[{"id":"1.187557995","rc":[{"batb":[[0,1.35,290.22],[1,1.34,328.98],[2,1.33,197.61]],"batl":[[0,1.37,363.75],[1,1.38,259.73],[2,1.39,270.66]],"ltp":1.38,"tv":58986.13,"id":9342449}]}]}
{"op":"mcm","clk":"4230577565","pt":1631534483008,"mc":[{"id":"1.187557995","rc":[{"batl":[[0,1.38,259.73],[1,1.39,270.66],[2,1.44,6]],"ltp":1.38,"tv":58986.13,"id":9342449},{"batb":[[0,3.25,2],[1,3.2,3],[2,3,3]],"ltp":4.1,"tv":8167.83,"id":9633869}]}]}
{"op":"mcm","clk":"4230577700","pt":1631534484353,"mc":[{"id":"1.187557995","rc":[{"batb":[[1,1.34,386.57]],"ltp":1.38,"tv":58986.13,"id":9342449},{"batl":[[0,4.2,15],[1,4.3,3]],"ltp":4.1,"tv":8167.83,"id":9633869}]}]}
{"op":"mcm","clk":"4230577803","pt":1631534485306,"mc":[{"id":"1.187557995","rc":[{"batb":[[1,1.34,328.98],[2,1.32,245.32]],"ltp":1.38,"tv":58986.13,"id":9342449}]}]}
{"op":"mcm","clk":"4230578044","pt":1631534487503,"mc":[{"id":"1.187557995","rc":[{"batl":[[0,1.38,509.72]],"ltp":1.38,"tv":58986.13,"id":9342449}]}]}
{"op":"mcm","clk":"4230578083","pt":1631534487819,"mc":[{"id":"1.187557995","rc":[{"batb":[[0,1.35,347.81]],"ltp":1.38,"tv":58986.13,"id":9342449}]}]}
{"op":"mcm","clk":"4230578247","pt":1631534489646,"mc":[{"id":"1.187557995","rc":[{"batb":[[0,1.35,57.59],[1,1.32,245.32],[2,1.3,7]],"batl":[[0,1.38,249.99],[1,1.44,6],[2,1.47,44.95]],"ltp":1.38,"tv":58986.13,"id":9342449}]}]}
{"op":"mcm","clk":"4230578292","pt":1631534490023,"mc":[{"id":"1.187557995","rc":[{"batb":[[0,1.32,245.32],[1,1.3,7],[2,1.27,195.87]],"batl":[[0,1.44,6],[1,1.49,8.99],[2,1.82,2.89]],"ltp":1.38,"tv":58986.13,"id":9342449}]}]}
{"op":"mcm","clk":"4230578452","pt":1631534491649,"mc":[{"id":"1.187557995","rc":[{"batl":[[0,4.3,3],[1,4.3,0]],"ltp":4.1,"tv":8167.83,"id":9633869}]}]}
{"op":"mcm","clk":"4230578547","pt":1631534492646,"mc":[{"id":"1.187557995","rc":[{"batb":[[1,1.31,305.07],[2,1.3,394.1]],"batl":[[0,1.44,160.68],[1,1.45,224.45],[2,1.49,8.99]],"ltp":1.38,"tv":58986.13,"id":9342449}]}]}
{"op":"mcm","clk":"4230578629","pt":1631534493455,"mc":[{"id":"1.187557995","rc":[{"batb":[[0,1.32,251.32],[1,1.31,311.07]],"ltp":1.38,"tv":58986.13,"id":9342449},{"batl":[[0,4.2,3],[1,4.3,3]],"ltp":4.1,"tv":8167.83,"id":9633869}]}]}
{"op":"mcm","clk":"4230578853","pt":1631534495242,"mc":[{"id":"1.187557995","rc":[{"batb":[[0,1.32,251.55]],"batl":[[2,1.49,2.99]],"ltp":1.38,"tv":58986.13,"id":9342449},{"batb":[[1,2.2,42.67],[2,2,11.88]],"ltp":4.1,"tv":8167.83,"id":9633869}]}]}
{"op":"mcm","clk":"4230578958","pt":1631534496139,"mc":[{"id":"1.187557995","rc":[{"batb":[[0,1.32,245.55],[1,1.31,305.07]],"batl":[[0,1.43,8],[1,1.44,6]],"ltp":1.38,"tv":58986.13,"id":9342449},{"batb":[[0,3.3,3],[1,3.25,2],[2,2.2,42.67]],"batl":[[0,4.3,3],[1,4.3,0]],"ltp":4.1,"tv":8167.83,"id":9633869}]}]}
{"op":"mcm","clk":"4230579094","pt":1631534497439,"mc":[{"id":"1.187557995","rc":[{"batb":[[0,1.33,500.23]],"batl":[[0,1.43,255.02]],"ltp":1.38,"tv":58986.13,"id":9342449}]}]}
{"op":"mcm","clk":"4230579236","pt":1631534498618,"mc":[{"id":"1.187557995","rc":[{"trd":[[1.38,659.58]],"batb":[[0,1.31,305.07],[1,1.3,394.1],[2,1.29,2965.12]],"batl":[[0,1.34,2392.1],[1,1.43,255.02],[2,1.44,6]],"ltp":1.38,"tv":58986.59,"id":9342449},{"batb":[[0,3.9,980.78],[1,3.85,951.92],[2,3.8,951.92]],"ltp":4.1,"tv":8167.83,"id":9633869}],"tv":67154.43}]}
{"op":"mcm","clk":"4230579328","pt":1631534499650,"mc":[{"id":"1.187557995","rc":[{"batb":[[2,1.29,815.41]],"batl":[[0,1.34,399.34],[1,1.35,310.26],[2,1.43,8]],"ltp":1.38,"tv":58986.59,"id":9342449},{"trd":[[3.9,71.83]],"batb":[[0,3.9,484.77],[1,3.85,475.96],[2,3.8,475.96]],"ltp":3.9,"tv":8179.09,"id":9633869}],"tv":67165.69}]}
{"op":"mcm","clk":"4230579432","pt":1631534500647,"mc":[{"id":"1.187557995","rc":[{"batl":[[0,1.34,431.91],[1,1.35,325.26],[2,1.41,40]],"ltp":1.38,"tv":58986.59,"id":9342449},{"batb":[[1,3.85,497.01]],"batl":[[0,4.3,17.97],[1,4.5,8.01]],"ltp":3.9,"tv":8179.09,"id":9633869}]}]}
{"op":"mcm","clk":"4230579634","pt":1631534502638,"mc":[{"id":"1.187557995","rc":[{"batb":[[0,1.31,2503.24]],"ltp":1.38,"tv":58986.59,"id":9342449},{"batb":[[1,3.85,475.96]],"ltp":3.9,"tv":8179.09,"id":9633869}]}]}
{"op":"mcm","clk":"4230579736","pt":1631534503636,"mc":[{"id":"1.187557995","rc":[{"batb":[[0,1.32,58.64],[1,1.31,2571.18],[2,1.3,394.1]],"batl":[[0,1.33,298.73],[1,1.34,698.97],[2,1.35,325.26]],"ltp":1.38,"tv":58986.59,"id":9342449}]}]}
{"op":"mcm","clk":"4230579831","pt":1631534504456,"mc":[{"id":"1.187557995","rc":[{"batl":[[2,1.35,310.26]],"ltp":1.38,"tv":58986.59,"id":9342449},{"batb":[[0,3.9,500.31]],"ltp":3.9,"tv":8179.09,"id":9633869}]}]}
{"op":"mcm","clk":"4230579945","pt":1631534505665,"mc":[{"id":"1.187557995","rc":[{"batb":[[0,3.95,20.33],[1,3.9,500.31],[2,3.85,475.96]],"ltp":3.9,"tv":8179.09,"id":9633869}]}]}
{"op":"mcm","clk":"4230580036","pt":1631534506567,"mc":[{"id":"1.187557995","rc":[{"batl":[[0,4.1,3],[1,4.3,17.97],[2,4.5,8.01]],"ltp":3.9,"tv":8179.09,"id":9633869}]}]}
{"op":"mcm","clk":"4230580142","pt":1631534507660,"mc":[{"id":"1.187557995","rc":[{"batl":[[1,1.34,713.97]],"ltp":1.38,"tv":58986.59,"id":9342449}]}]}
{"op":"mcm","clk":"4230580161","pt":1631534507868,"mc":[{"id":"1.187557995","rc":[{"batl":[[1,1.34,681.4]],"ltp":1.38,"tv":58986.59,"id":9342449}]}]}
{"op":"mcm","clk":"4230580419","pt":1631534510665,"mc":[{"id":"1.187557995","rc":[{"batl":[[0,1.33,536.22],[1,1.34,658.88]],"ltp":1.38,"tv":58986.59,"id":9342449}]}]}
{"op":"mcm","clk":"4230580526","pt":1631534511657,"mc":[{"id":"1.187557995","rc":[{"trd":[[1.32,403.56]],"batb":[[0,1.32,106.1],[1,1.31,2503.24]],"batl":[[1,1.34,602.36]],"ltp":1.32,"tv":59052.73,"id":9342449}],"tv":67231.82}]}
{"op":"mcm","clk":"4230580661","pt":1631534513290,"mc":[{"id":"1.187557995","rc":[{"batb":[[0,1.31,2503.24],[1,1.3,394.1],[2,1.29,815.41]],"batl":[[0,1.33,237.49]],"ltp":1.32,"tv":59052.73,"id":9342449}]}]}
{"op":"mcm","clk":"4230580951","pt":1631534516086,"mc":[{"id":"1.187557995","rc":[{"batb":[[0,1.32,8],[1,1.31,2512.24],[2,1.3,394.1]],"ltp":1.32,"tv":59052.73,"id":9342449}]}]}
{"op":"mcm","clk":"4230581205","pt":1631534518494,"mc":[{"id":"1.187557995","rc":[{"batb":[[0,1.31,2503.24],[1,1.3,387.1],[2,1.29,815.41]],"batl":[[0,1.34,602.36],[1,1.35,310.26],[2,1.39,189.1]],"ltp":1.32,"tv":59052.73,"id":9342449},{"batb":[[1,3.9,484.77]],"batl":[[0,4.5,8.01],[1,4.3,0],[2,4.5,0]],"ltp":3.9,"tv":8179.09,"id":9633869}]}]}
{"op":"mcm","clk":"4230581442","pt":1631534520504,"mc":[{"id":"1.187557995","rc":[{"batb":[[0,1.31,305.07],[2,1.28,113.38]],"ltp":1.32,"tv":59052.73,"id":9342449},{"batb":[[1,2.2,42.67],[2,2,11.88]],"ltp":3.9,"tv":8179.09,"id":9633869}]}]}
{"op":"mcm","clk":"4230581490","pt":1631534520927,"mc":[{"id":"1.187557995","rc":[{"batb":[[0,1.28,113.38],[1,1.27,421.59],[2,1.22,524.56]],"batl":[[0,1.34,15],[1,1.39,189.1],[2,1.49,2.99]],"ltp":1.32,"tv":59052.73,"id":9342449}]}]}
{"op":"mcm","clk":"4230581666","pt":1631534522503,"mc":[{"id":"1.187557995","rc":[{"batb":[[0,1.27,421.59],[1,1.22,524.56],[2,1.2,2]],"batl":[[0,1.39,189.1],[1,1.49,2.99],[2,1.71,553.48]],"ltp":1.32,"tv":59052.73,"id":9342449},{"batb":[[0,2.2,42.67],[1,2,11.88],[2,1.97,1.05]],"ltp":3.9,"tv":8179.09,"id":9633869}]}]}
{"op":"mcm","clk":"4230581808","pt":1631534523812,"mc":[{"id":"1.187557995","rc":[{"batb":[[1,1.26,330.01],[2,1.25,487.9]],"batl":[[0,1.39,420.1],[1,1.4,262.04],[2,1.49,2.99]],"ltp":1.32,"tv":59052.73,"id":9342449}]}]}
{"op":"mcm","clk":"4230581991","pt":1631534525700,"mc":[{"id":"1.187557995","rc":[{"batb":[[0,1.27,522.46]],"batl":[[0,1.36,64.07],[1,1.38,75.25],[2,1.39,420.1]],"ltp":1.32,"tv":59052.73,"id":9342449},{"batb":[[0,3.75,2.87],[1,3.6,3.59],[2,2.2,42.67]],"batl":[[0,4.8,2.57],[1,5.2,2.18]],"ltp":3.9,"tv":8179.09,"id":9633869}]}]}
{"op":"mcm","clk":"4230582041","pt":1631534526223,"mc":[{"id":"1.187557995","rc":[{"batl":[[0,1.38,75.25],[1,1.39,420.1],[2,1.4,262.04]],"ltp":1.32,"tv":59052.73,"id":9342449},{"batb":[[0,3.6,3.59],[1,2.2,42.67],[2,2,11.88]],"ltp":3.9,"tv":8179.09,"id":9633869}]}]}
{"op":"mcm","clk":"4230582246","pt":1631534528112,"mc":[{"id":"1.187557995","rc":[{"batb":[[0,1.28,500],[1,1.27,522.46],[2,1.26,330.01]],"ltp":1.32,"tv":59052.73,"id":9342449}]}]}
{"op":"mcm","clk":"4230582398","pt":1631534529529,"mc":[{"id":"1.187557995","rc":[{"batl":[[0,1.36,65.57],[1,1.38,75.25],[2,1.39,420.1]],"ltp":1.32,"tv":59052.73,"id":9342449},{"batb":[[0,3.75,3.07],[1,3.6,3.59],[2,2.2,42.67]],"ltp":3.9,"tv":8179.09,"id":9633869}]}]}
{"op":"mcm","clk":"4230582492","pt":1631534530420,"mc":[{"id":"1.187557995","rc":[{"batb":[[2,1.24,114.77]],"batl":[[0,1.38,75.25],[1,1.39,420.1],[2,1.4,262.04]],"ltp":1.32,"tv":59052.73,"id":9342449},{"batb":[[0,3.6,3.59],[1,2.2,42.67],[2,2,11.88]],"ltp":3.9,"tv":8179.09,"id":9633869}]}]}
{"op":"mcm","clk":"4230582721","pt":1631534532501,"mc":[{"id":"1.187557995","rc":[{"batb":[[0,1.27,522.46],[1,1.24,114.77],[2,1.2,2]],"batl":[[1,1.39,231]],"ltp":1.32,"tv":59052.73,"id":9342449}]}]}
{"op":"mcm","clk":"4230582885","pt":1631534533710,"mc":[{"id":"1.187557995","rc":[{"trd":[[1.36,11124.56]],"batb":[[0,1.36,331.91],[1,1.35,1733.39],[2,1.34,1457.72]],"ltp":1.36,"tv":59206.37,"id":9342449},{"trd":[[3.6,79.06],[3.75,34.29]],"batb":[[0,3.45,305.17],[1,3.4,295.92],[2,3.35,295.92]],"batl":[[0,3.95,9.5],[1,4.8,2.57],[2,5.2,2.18]],"ltp":3.6,"tv":8191.21,"id":9633869}],"tv":67397.58}]}
{"op":"mcm","clk":"4230583014","pt":1631534534713,"mc":[{"id":"1.187557995","rc":[{"batl":[[2,1.4,277.04]],"ltp":1.36,"tv":59206.37,"id":9342449},{"batb":[[0,3.5,24.28],[1,3.45,304.89],[2,3.4,295.92]],"batl":[[1,4.1,8.51],[2,4.3,12.85]],"ltp":3.6,"tv":8191.21,"id":9633869}]}]}
{"op":"mcm","clk":"4230583135","pt":1631534535615,"mc":[{"id":"1.187557995","rc":[{"batl":[[2,4.5,3]],"ltp":3.6,"tv":8191.21,"id":9633869}]}]}
{"op":"mcm","clk":"4230583251","pt":1631534536510,"mc":[{"id":"1.187557995","rc":[{"batb":[[0,1.37,6],[1,1.36,374.17],[2,1.35,1742.39]],"ltp":1.36,"tv":59206.37,"id":9342449},{"batb":[[0,3.5,39.2]],"batl":[[0,3.75,3],[1,3.95,9.5],[2,4.1,8.51]],"ltp":3.6,"tv":8191.21,"id":9633869}]}]}
{"op":"mcm","clk":"4230583399","pt":1631534537511,"mc":[{"id":"1.187557995","rc":[{"trd":[[1.37,5546.7]],"batb":[[0,1.36,453.28],[1,1.35,1742.39],[2,1.34,1457.72]],"batl":[[0,1.37,253.31],[1,1.38,396.55],[2,1.39,231]],"ltp":1.37,"tv":59218.37,"id":9342449}],"tv":67409.59}]}
{"op":"mcm","clk":"4230583502","pt":1631534538615,"mc":[{"id":"1.187557995","rc":[{"batb":[[0,1.36,453.98],[1,1.35,1811.15]],"batl":[[2,1.39,290.28]],"ltp":1.37,"tv":59218.37,"id":9342449},{"batl":[[1,3.9,23.27],[2,3.95,9.5]],"ltp":3.6,"tv":8191.21,"id":9633869}]}]}
{"op":"mcm","clk":"4230583611","pt":1631534539663,"mc":[{"id":"1.187557995","rc":[{"trd":[[1.37,5566.1]],"batb":[[0,1.36,417.02]],"batl":[[0,1.37,240.91]],"ltp":1.37,"tv":59237.77,"id":9342449},{"trd":[[3.7,23.08]],"ltp":3.7,"tv":8193.21,"id":9633869}],"tv":67430.99}]}
{"op":"mcm","clk":"4230583710","pt":1631534540513,"mc":[{"id":"1.187557995","rc":[{"trd":[[1.37,6047.88]],"batb":[[0,1.37,12.44],[1,1.36,417.02],[2,1.35,1811.15]],"batl":[[0,1.38,396.55],[1,1.39,290.28],[2,1.4,333.48]],"ltp":1.37,"tv":59719.55,"id":9342449},{"batb":[[0,3.5,43.28]],"ltp":3.7,"tv":8193.21,"id":9633869}],"tv":67912.77}]}
{"op":"mcm","clk":"4230583807","pt":1631534541308,"mc":[{"id":"1.187557995","rc":[{"batb":[[0,1.36,417.02],[1,1.35,1811.15],[2,1.34,1457.72]],"batl":[[1,1.39,353.78]],"ltp":1.37,"tv":59719.55,"id":9342449},{"batb":[[0,3.55,4.27],[1,3.5,43],[2,3.45,304.89]],"ltp":3.7,"tv":8193.21,"id":9633869}]}]}
{"op":"mcm","clk":"4230584273","pt":1631534545628,"mc":[{"id":"1.187557995","rc":[{"batb":[[0,1.36,376.12],[1,1.35,1742.39]],"batl":[[1,1.39,294.5]],"ltp":1.37,"tv":59719.55,"id":9342449}]}]}
{"op":"mcm","clk":"4230584474","pt":1631534547466,"mc":[{"id":"1.187557995","rc":[{"trd":[[1.38,666.2]],"batb":[[0,1.36,297.01]],"batl":[[0,1.38,323.71]],"ltp":1.38,"tv":59726.17,"id":9342449},{"trd":[[3.6,80.27]],"batb":[[0,3.55,3.99]],"ltp":3.6,"tv":8194.42,"id":9633869}],"tv":67920.59}]}
{"op":"mcm","clk":"4230584608","pt":1631534548523,"mc":[{"id":"1.187557995","rc":[{"batb":[[0,1.36,6],[1,1.33,104.44],[2,1.32,562.3]],"batl":[[0,1.4,15],[1,1.49,2.99],[2,1.71,553.48]],"ltp":1.38,"tv":59726.17,"id":9342449},{"batb":[[0,3.5,24],[1,3.35,3.27],[2,3.25,85.61]],"batl":[[1,4,8.66],[2,4.2,4.38]],"ltp":3.6,"tv":8194.42,"id":9633869}]}]}
{"op":"mcm","clk":"4230584750","pt":1631534549632,"mc":[{"id":"1.187557995","rc":[{"batb":[[0,1.32,562.3],[1,1.31,294.47],[2,1.29,116.81]],"batl":[[0,1.49,2.99],[1,1.71,553.48],[2,1.82,2.89]],"ltp":1.38,"tv":59726.17,"id":9342449},{"batb":[[0,3.35,3.27],[1,3.25,85.61],[2,2.2,42.67]],"batl":[[0,4.2,4.38],[1,4.5,3.91],[2,4.8,2.57]],"ltp":3.6,"tv":8194.42,"id":9633869}]}]}
{"op":"mcm","clk":"4230584850","pt":1631534550633,"mc":[{"id":"1.187557995","rc":[{"batb":[[0,1.37,8],[1,1.32,562.3],[2,1.31,294.47]],"ltp":1.38,"tv":59726.17,"id":9342449}]}]}
{"op":"mcm","clk":"4230584935","pt":1631534551474,"mc":[{"id":"1.187557995","rc":[{"batb":[[0,1.32,562.3],[1,1.31,587.36],[2,1.3,386.92]],"batl":[[0,1.44,161.85],[1,1.45,224.4],[2,1.49,2.99]],"ltp":1.38,"tv":59726.17,"id":9342449}]}]}
{"op":"mcm","clk":"4230585076","pt":1631534552632,"mc":[{"id":"1.187557995","rc":[{"batl":[[0,1.43,8],[1,1.44,161.85],[2,1.45,224.4]],"ltp":1.38,"tv":59726.17,"id":9342449},{"batb":[[0,3.35,6.27],[1,3.3,3],[2,3.25,85.61]],"ltp":3.6,"tv":8194.42,"id":9633869}]}]}
{"op":"mcm","clk":"4230585096","pt":1631534552840,"mc":[{"id":"1.187557995","rc":[{"batb":[[0,1.32,568.3],[1,1.31,594.36]],"ltp":1.38,"tv":59726.17,"id":9342449},{"batl":[[0,4.2,7.38]],"ltp":3.6,"tv":8194.42,"id":9633869}]}]}
{"op":"mcm","clk":"4230585315","pt":1631534554879,"mc":[{"id":"1.187557995","rc":[{"batb":[[0,1.33,500],[1,1.32,568.3],[2,1.31,594.36]],"batl":[[0,1.43,235.43]],"ltp":1.38,"tv":59726.17,"id":9342449}]}]}
{"op":"mcm","clk":"4230585505","pt":1631534556553,"mc":[{"id":"1.187557995","rc":[{"batb":[[2,1.31,301.47]],"batl":[[0,1.43,227.43]],"ltp":1.38,"tv":59726.17,"id":9342449},{"batb":[[0,3.35,3.27],[1,3.25,85.61],[2,2.2,42.67]],"batl":[[2,4.8,0]],"ltp":3.6,"tv":8194.42,"id":9633869}]}]}
{"op":"mcm","clk":"4230585618","pt":1631534557656,"mc":[{"id":"1.187557995","rc":[{"batb":[[1,1.32,133.89]],"batl":[[0,1.44,161.85],[1,1.45,224.4],[2,1.49,2.99]],"ltp":1.38,"tv":59726.17,"id":9342449}]}]}
{"op":"mcm","clk":"4230585886","pt":1631534559650,"mc":[{"id":"1.187557995","rc":[{"batb":[[0,1.41,239.92],[1,1.4,264.79],[2,1.39,1375.9]],"batl":[[2,1.47,715.56]],"ltp":1.38,"tv":59726.17,"id":9342449},{"trd":[[3.25,17.72],[3.35,37.78]],"batb":[[0,3.25,82.42],[1,2.2,42.67],[2,2,11.88]],"batl":[[0,3.75,15.7],[1,4,3],[2,4.2,3]],"ltp":3.25,"tv":8207.32,"id":9633869}],"tv":67933.49}]}
{"op":"mcm","clk":"4230585986","pt":1631534560650,"mc":[{"id":"1.187557995","rc":[{"batb":[[1,1.4,482.61]],"batl":[[2,1.46,15]],"ltp":1.38,"tv":59726.17,"id":9342449},{"batb":[[1,3.2,27.27],[2,2.86,47.95]],"ltp":3.25,"tv":8207.32,"id":9633869}]}]}
{"op":"mcm","clk":"4230586108","pt":1631534561589,"mc":[{"id":"1.187557995","rc":[{"batb":[[0,1.42,6],[1,1.41,239.92],[2,1.4,3037.98]],"ltp":1.38,"tv":59726.17,"id":9342449},{"batl":[[0,3.35,3],[1,3.75,15.7],[2,4,3]],"ltp":3.25,"tv":8207.32,"id":9633869}]}]}
{"op":"mcm","clk":"4230586217","pt":1631534562591,"mc":[{"id":"1.187557995","rc":[{"batb":[[1,1.41,245.92],[2,1.4,3045.98]],"ltp":1.38,"tv":59726.17,"id":9342449},{"batl":[[1,3.4,2],[2,3.55,3]],"ltp":3.25,"tv":8207.32,"id":9633869}]}]}
{"op":"mcm","clk":"4230586326","pt":1631534563584,"mc":[{"id":"1.187557995","rc":[{"batb":[[0,1.42,84],[1,1.41,2738.96]],"batl":[[0,1.43,64.7],[1,1.44,161.85],[2,1.45,224.4]],"ltp":1.38,"tv":59726.17,"id":9342449}]}]}
{"op":"mcm","clk":"4230586434","pt":1631534564479,"mc":[{"id":"1.187557995","rc":[{"batb":[[0,1.42,6]],"batl":[[0,1.44,405.98],[1,1.45,224.4],[2,1.46,15]],"ltp":1.38,"tv":59726.17,"id":9342449}]}]}
{"op":"mcm","clk":"4230587014","pt":1631534569375,"mc":[{"id":"1.187557995","rc":[{"batb":[[2,1.4,3042.71]],"ltp":1.38,"tv":59726.17,"id":9342449},{"batb":[[2,2.84,49.04]],"batl":[[2,3.55,12.39]],"ltp":3.25,"tv":8207.32,"id":9633869}]}]}
{"op":"mcm","clk":"4230587258","pt":1631534571490,"mc":[{"id":"1.187557995","rc":[{"batb":[[0,1.42,81.3]],"batl":[[0,1.43,71.14],[1,1.44,405.98],[2,1.45,224.4]],"ltp":1.38,"tv":59726.17,"id":9342449}]}]}
{"op":"mcm","clk":"4230587544","pt":1631534573473,"mc":[{"id":"1.187557995","rc":[{"batb":[[0,1.42,6]],"batl":[[0,1.44,405.98],[1,1.45,224.4],[2,1.46,15]],"ltp":1.38,"tv":59726.17,"id":9342449}]}]}
{"op":"mcm","clk":"4230587646","pt":1631534574408,"mc":[{"id":"1.187557995","rc":[{"trd":[[1.44,291.09]],"batb":[[1,1.41,2732.96],[2,1.4,3034.71]],"batl":[[0,1.44,577.1]],"ltp":1.44,"tv":59731.44,"id":9342449},{"trd":[[3.25,20.05]],"batb":[[0,3.25,158.24]],"batl":[[1,3.55,9.39],[2,3.6,36.9]],"ltp":3.25,"tv":8209.65,"id":9633869}],"tv":67941.1}]}
{"op":"mcm","clk":"4230587814","pt":1631534575715,"mc":[{"id":"1.187557995","rc":[{"batl":[[0,3.35,5.32]],"ltp":3.25,"tv":8209.65,"id":9633869}]}]}
{"op":"mcm","clk":"4230587932","pt":1631534576602,"mc":[{"id":"1.187557995","rc":[{"batb":[[0,1.43,8],[1,1.42,6],[2,1.41,2732.96]],"ltp":1.44,"tv":59731.44,"id":9342449}]}]}
{"op":"mcm","clk":"4230588069","pt":1631534577603,"mc":[{"id":"1.187557995","rc":[{"batb":[[0,1.43,33.75],[2,1.41,2944.42]],"batl":[[1,1.45,422.01]],"ltp":1.44,"tv":59731.44,"id":9342449},{"batb":[[0,3.25,76.98],[1,3.2,205.76],[2,2.82,50.04]],"ltp":3.25,"tv":8209.65,"id":9633869}]}]}
{"op":"mcm","clk":"4230588416","pt":1631534580573,"mc":[{"id":"1.187557995","rc":[{"batl":[[2,1.46,188.76]],"ltp":1.44,"tv":59731.44,"id":9342449},{"batb":[[2,3.15,80.54]],"ltp":3.25,"tv":8209.65,"id":9633869}]}]}
{"op":"mcm","clk":"4230588501","pt":1631534581324,"mc":[{"id":"1.187557995","rc":[{"batb":[[0,1.43,8]],"ltp":1.44,"tv":59731.44,"id":9342449}]}]}
{"op":"mcm","clk":"4230589075","pt":1631534585694,"mc":[{"id":"1.187557995","rc":[{"batl":[[1,3.45,90.29],[2,3.55,9.39]],"ltp":3.25,"tv":8209.65,"id":9633869}]}]}
{"op":"mcm","clk":"4230589122","pt":1631534586113,"mc":[{"id":"1.187557995","rc":[{"trd":[[1.44,341.43]],"batl":[[0,1.44,551.93]],"ltp":1.44,"tv":59781.78,"id":9342449}],"tv":67991.44}]}
{"op":"mcm","clk":"4230589207","pt":1631534586796,"mc":[{"id":"1.187557995","rc":[{"batl":[[2,3.5,89.44]],"ltp":3.25,"tv":8209.65,"id":9633869}]}]}
{"op":"mcm","clk":"4230589550","pt":1631534589687,"mc":[{"id":"1.187557995","rc":[{"batb":[[2,1.41,3159.07]],"ltp":1.44,"tv":59781.78,"id":9342449},{"batl":[[1,3.45,178.02]],"ltp":3.25,"tv":8209.65,"id":9633869}]}]}
{"op":"mcm","clk":"4230589574","pt":1631534589896,"mc":[{"id":"1.187557995","rc":[{"batb":[[1,1.41,3159.07],[2,1.4,3266.25]],"ltp":1.44,"tv":59781.78,"id":9342449}]}]}
{"op":"mcm","clk":"4230589900","pt":1631534592690,"mc":[{"id":"1.187557995","rc":[{"trd":[[1.43,16]],"batb":[[0,1.41,3159.07],[1,1.4,3042.65],[2,1.39,1471.97]],"batl":[[0,1.43,164.85],[1,1.44,551.93],[2,1.45,422.01]],"ltp":1.43,"tv":59797.78,"id":9342449}],"tv":68007.44}]}
{"op":"mcm","clk":"4230590318","pt":1631534596007,"mc":[{"id":"1.187557995","rc":[{"trd":[[1.43,30]],"batb":[[0,1.42,7],[1,1.41,3323.87],[2,1.4,3042.65]],"batl":[[0,1.43,375.63]],"ltp":1.43,"tv":59811.78,"id":9342449}],"tv":68021.44}]}
{"op":"mcm","clk":"4230590804","pt":1631534600538,"mc":[{"id":"1.187557995","rc":[{"batl":[[0,1.43,217.78]],"ltp":1.43,"tv":59811.78,"id":9342449}]}]}
{"op":"mcm","clk":"4230591126","pt":1631534603637,"mc":[{"id":"1.187557995","rc":[{"trd":[[1.41,825.25],[1.42,132.45]],"batb":[[0,1.41,3182.29],[1,1.4,3042.65],[2,1.39,1471.97]],"ltp":1.41,"tv":60114.95,"id":9342449},{"trd":[[3.35,43.11]],"batl":[[0,3.45,178.02],[1,3.5,89.44],[2,3.55,9.39]],"ltp":3.35,"tv":8214.98,"id":9633869}],"tv":68329.94}]}
{"op":"mcm","clk":"4230591180","pt":1631534604115,"mc":[{"id":"1.187557995","rc":[{"batb":[[0,1.41,3056.53]],"ltp":1.41,"tv":60114.95,"id":9342449}]}]}
{"op":"mcm","clk":"4230591476","pt":1631534607141,"mc":[{"id":"1.187557995","rc":[{"batb":[[0,1.41,3134.17]],"batl":[[1,1.44,639]],"ltp":1.41,"tv":60114.95,"id":9342449},{"batl":[[0,3.4,3],[1,3.45,214.92],[2,3.5,89.44]],"ltp":3.35,"tv":8214.98,"id":9633869}]}]}
{"op":"mcm","clk":"4230591804","pt":1631534610336,"mc":[{"id":"1.187557995","rc":[{"trd":[[1.43,42]],"batb":[[0,1.42,91.35],[1,1.41,3134.17],[2,1.4,3042.65]],"batl":[[0,1.43,211.78]],"ltp":1.43,"tv":60126.95,"id":9342449},{"batl":[[0,3.35,2],[1,3.4,3],[2,3.45,214.92]],"ltp":3.35,"tv":8214.98,"id":9633869}],"tv":68341.94}]}
{"op":"mcm","clk":"4230592425","pt":1631534616043,"mc":[{"id":"1.187557995","rc":[{"batb":[[0,1.42,296.28],[1,1.41,2925.97]],"ltp":1.43,"tv":60126.95,"id":9342449},{"batb":[[1,3.2,116.81],[2,3.15,173.17]],"ltp":3.35,"tv":8214.98,"id":9633869}]}]}
{"op":"mcm","clk":"4230592605","pt":1631534617621,"mc":[{"id":"1.187557995","rc":[{"trd":[[1.43,53.72]],"batl":[[0,1.44,639],[1,1.45,422.01],[2,1.46,188.76]],"ltp":1.43,"tv":60138.67,"id":9342449}],"tv":68353.65}]}
{"op":"mcm","clk":"4230593369","pt":1631534624545,"mc":[{"id":"1.187557995","rc":[{"batl":[[1,3.45,214.92],[2,3.5,89.44]],"ltp":3.35,"tv":8214.98,"id":9633869}]}]}
{"op":"mcm","clk":"4230593698","pt":1631534627450,"mc":[{"id":"1.187557995","rc":[{"batb":[[0,1.43,6],[1,1.42,296.28],[2,1.41,2925.97]],"ltp":1.43,"tv":60138.67,"id":9342449}]}]}
{"op":"mcm","clk":"4230595138","pt":1631534640516,"mc":[{"id":"1.187557995","rc":[{"batb":[[1,1.42,289.28]],"ltp":1.43,"tv":60138.67,"id":9342449}]}]}
{"op":"mcm","clk":"4230595458","pt":1631534643674,"mc":[{"id":"1.187557995","rc":[{"trd":[[1.43,65.72]],"batb":[[0,1.42,289.28],[1,1.41,2925.97],[2,1.4,487.29]],"batl":[[0,1.43,176.65],[1,1.44,639],[2,1.45,422.01]],"ltp":1.43,"tv":60150.67,"id":9342449}],"tv":68365.65}]}
{"op":"mcm","clk":"4230595507","pt":1631534644176,"mc":[{"id":"1.187557995","rc":[{"batb":[[0,1.42,204.93]],"ltp":1.43,"tv":60150.67,"id":9342449}]}]}
{"op":"mcm","clk":"4230595779","pt":1631534646710,"mc":[{"id":"1.187557995","rc":[{"batb":[[0,1.42,261.97]],"batl":[[1,1.44,700.04],[2,1.45,484.87]],"ltp":1.43,"tv":60150.67,"id":9342449}]}]}
{"op":"mcm","clk":"4230595832","pt":1631534647232,"mc":[{"id":"1.187557995","rc":[{"trd":[[1.43,81.72]],"batb":[[0,1.42,267.97],[1,1.41,2983.57]],"batl":[[0,1.44,700.04],[1,1.45,422.01],[2,1.46,188.76]],"ltp":1.43,"tv":60166.67,"id":9342449}],"tv":68381.65}]}
{"op":"mcm","clk":"4230596420","pt":1631534652337,"mc":[{"id":"1.187557995","rc":[{"batb":[[0,1.42,210.93],[1,1.41,2925.97]],"batl":[[0,1.44,639]],"ltp":1.43,"tv":60166.67,"id":9342449}]}]}
{"op":"mcm","clk":"4230596970","pt":1631534656915,"mc":[{"id":"1.187557995","rc":[{"batb":[[1,1.41,2886.93]],"ltp":1.43,"tv":60166.67,"id":9342449},{"batl":[[1,3.45,178.02]],"ltp":3.35,"tv":8214.98,"id":9633869}]}]}
{"op":"mcm","clk":"4230597327","pt":1631534660129,"mc":[{"id":"1.187557995","rc":[{"batl":[[0,3.3,3],[1,3.35,2],[2,3.45,178.02]],"ltp":3.35,"tv":8214.98,"id":9633869}]}]}
{"op":"mcm","clk":"4230597652","pt":1631534663233,"mc":[{"id":"1.187557995","rc":[{"batb":[[0,1.43,8],[1,1.42,210.93],[2,1.41,2886.93]],"ltp":1.43,"tv":60166.67,"id":9342449}]}]}
{"op":"mcm","clk":"4230597763","pt":1631534664225,"mc":[{"id":"1.187557995","rc":[{"trd":[[1.44,347.18]],"batl":[[0,1.44,636.12]],"ltp":1.44,"tv":60172.43,"id":9342449},{"trd":[[3.25,22.59]],"batb":[[0,3.25,75.72]],"ltp":3.25,"tv":8217.52,"id":9633869}],"tv":68389.95}]}
{"op":"mcm","clk":"4230598920","pt":1631534675431,"mc":[{"id":"1.187557995","rc":[{"batl":[[0,1.44,605.07]],"ltp":1.44,"tv":60172.43,"id":9342449}]}]}
{"op":"mcm","clk":"4230598949","pt":1631534675742,"mc":[{"id":"1.187557995","rc":[{"batb":[[1,1.42,204.93]],"ltp":1.44,"tv":60172.43,"id":9342449},{"batl":[[1,3.45,178.02],[2,3.5,89.44]],"ltp":3.25,"tv":8217.52,"id":9633869}]}]}
{"op":"mcm","clk":"4230599211","pt":1631534678470,"mc":[{"id":"1.187557995","rc":[{"batb":[[2,1.41,2921.73]],"ltp":1.44,"tv":60172.43,"id":9342449}]}]}
{"op":"mcm","clk":"4230599251","pt":1631534678940,"mc":[{"id":"1.187557995","rc":[{"batb":[[2,1.41,428.69]],"ltp":1.44,"tv":60172.43,"id":9342449}]}]}
{"op":"mcm","clk":"4230600674","pt":1631534692655,"mc":[{"id":"1.187557995","rc":[{"trd":[[1.43,88.52]],"batb":[[0,1.43,4.6]],"ltp":1.43,"tv":60179.22,"id":9342449}],"tv":68396.75}]}
{"op":"mcm","clk":"4230600861","pt":1631534694488,"mc":[{"id":"1.187557995","rc":[{"batb":[[1,1.39,96.07],[2,1.38,207.84]],"batl":[[0,1.46,15],[1,1.49,2.99],[2,1.82,2.89]],"ltp":1.43,"tv":60179.22,"id":9342449},{"batb":[[0,3.2,27.27],[1,2.96,2],[2,2.78,52.3]],"batl":[[1,3.55,9.39],[2,3.9,4.45]],"ltp":3.25,"tv":8217.52,"id":9633869}]}]}
{"op":"mcm","clk":"4230600981","pt":1631534695486,"mc":[{"id":"1.187557995","rc":[{"batb":[[1,1.38,207.84],[2,1.36,247.95]],"batl":[[0,1.49,2.99],[1,1.82,2.89],[2,1.89,444.94]],"ltp":1.43,"tv":60179.22,"id":9342449},{"batb":[[0,2.96,2],[1,2.78,52.3],[2,2.2,42.67]],"batl":[[1,3.9,4.45],[2,4.3,4.25]],"ltp":3.25,"tv":8217.52,"id":9633869}]}]}
{"op":"mcm","clk":"4230601045","pt":1631534696095,"mc":[{"id":"1.187557995","rc":[{"batb":[[0,1.38,207.84],[1,1.36,247.95],[2,1.35,136.47]],"ltp":1.43,"tv":60179.22,"id":9342449},{"batb":[[1,2.94,3],[2,2.78,52.3]],"batl":[[0,3.9,4.45],[1,4.3,4.25],[2,4.3,0]],"ltp":3.25,"tv":8217.52,"id":9633869}]}]}
{"op":"mcm","clk":"4230601541","pt":1631534700390,"mc":[{"id":"1.187557995","rc":[{"batb":[[0,1.42,342.94],[1,1.41,257.06],[2,1.38,207.84]],"batl":[[0,1.46,262.43],[1,1.47,211.12],[2,1.49,2.99]],"ltp":1.43,"tv":60179.22,"id":9342449}]}]}
{"op":"mcm","clk":"4230601729","pt":1631534702273,"mc":[{"id":"1.187557995","rc":[{"batl":[[2,1.48,14.95]],"ltp":1.43,"tv":60179.22,"id":9342449},{"batb":[[0,2.98,10],[1,2.96,2],[2,2.94,3]],"batl":[[0,3.75,22.25],[1,3.9,4.45],[2,4.3,4.25]],"ltp":3.25,"tv":8217.52,"id":9633869}]}]}
{"op":"mcm","clk":"4230601829","pt":1631534703009,"mc":[{"id":"1.187557995","rc":[{"batb":[[0,1.38,207.84],[1,1.36,247.95],[2,1.35,136.47]],"batl":[[0,1.49,2.99],[1,1.52,236.8],[2,1.82,2.89]],"ltp":1.43,"tv":60179.22,"id":9342449},{"batb":[[0,2.96,2],[1,2.94,3],[2,2.78,52.3]],"batl":[[0,3.9,4.45],[1,4.3,4.25],[2,4.3,0]],"ltp":3.25,"tv":8217.52,"id":9633869}]}]}
{"op":"mcm","clk":"4230602256","pt":1631534705874,"mc":[{"id":"1.187557995","rc":[{"batb":[[2,1.35,463.5]],"batl":[[2,1.53,238.02]],"ltp":1.43,"tv":60179.22,"id":9342449}]}]}
{"op":"mcm","clk":"4230602662","pt":1631534709514,"mc":[{"id":"1.187557995","rc":[{"batl":[[2,1.82,2.89]],"ltp":1.43,"tv":60179.22,"id":9342449}]}]}
{"op":"mcm","clk":"4230602778","pt":1631534710617,"mc":[{"id":"1.187557995","rc":[{"batb":[[0,1.36,247.95],[1,1.35,463.5],[2,1.34,329.82]],"batl":[[1,1.82,2.89],[2,1.89,444.94]],"ltp":1.43,"tv":60179.22,"id":9342449},{"batb":[[1,2.78,52.3],[2,2.2,42.67]],"ltp":3.25,"tv":8217.52,"id":9633869}]}]}
{"op":"mcm","clk":"4230602808","pt":1631534710890,"mc":[{"id":"1.187557995","rc":[{"batl":[[2,2.08,1]],"ltp":1.43,"tv":60179.22,"id":9342449}]}]}
{"op":"mcm","clk":"4230602966","pt":1631534712624,"mc":[{"id":"1.187557995","rc":[{"batl":[[0,1.38,230.2],[1,1.39,1647.24],[2,1.4,1335.42]],"ltp":1.43,"tv":60179.22,"id":9342449}]}]}
{"op":"mcm","clk":"4230603060","pt":1631534713403,"mc":[{"id":"1.187557995","rc":[{"trd":[[1.38,681.77]],"batl":[[0,1.38,214.63],[2,1.4,1350.42]],"ltp":1.38,"tv":60194.79,"id":9342449},{"trd":[[3.6,86.24]],"batb":[[0,3.5,96.13],[1,3.05,101.42],[2,3,590.93]],"batl":[[1,4,8.66],[2,4.3,4.25]],"ltp":3.6,"tv":8223.49,"id":9633869}],"tv":68418.29}]}
{"op":"mcm","clk":"4230603187","pt":1631534714506,"mc":[{"id":"1.187557995","rc":[{"batb":[[1,3.1,10],[2,3.05,101.42]],"batl":[[0,3.85,16.5],[1,3.9,4.45],[2,4,8.66]],"ltp":3.6,"tv":8223.49,"id":9633869}]}]}
{"op":"mcm","clk":"4230603279","pt":1631534715406,"mc":[{"id":"1.187557995","rc":[{"batb":[[0,1.37,3],[1,1.36,251.95],[2,1.35,463.5]],"ltp":1.38,"tv":60194.79,"id":9342449},{"batb":[[1,3.05,101.42],[2,2.98,3]],"batl":[[0,3.75,2],[1,3.85,16.5],[2,3.9,4.45]],"ltp":3.6,"tv":8223.49,"id":9633869}]}]}
{"op":"mcm","clk":"4230603405","pt":1631534716507,"mc":[{"id":"1.187557995","rc":[{"batl":[[0,1.38,338.21]],"ltp":1.38,"tv":60194.79,"id":9342449},{"batb":[[1,3.05,104.42],[2,3,3]],"ltp":3.6,"tv":8223.49,"id":9633869}]}]}
{"op":"mcm","clk":"4230603520","pt":1631534717397,"mc":[{"id":"1.187557995","rc":[{"batl":[[2,1.4,1335.42]],"ltp":1.38,"tv":60194.79,"id":9342449}]}]}
{"op":"mcm","clk":"4230603647","pt":1631534718630,"mc":[{"id":"1.187557995","rc":[{"batb":[[1,1.36,3091.24]],"ltp":1.38,"tv":60194.79,"id":9342449},{"batb":[[0,3.5,114.36]],"batl":[[0,3.7,2],[1,3.75,2],[2,3.85,16.5]],"ltp":3.6,"tv":8223.49,"id":9633869}]}]}
{"op":"mcm","clk":"4230603868","pt":1631534720621,"mc":[{"id":"1.187557995","rc":[{"batl":[[1,1.39,1662.24]],"ltp":1.38,"tv":60194.79,"id":9342449}]}]}
{"op":"mcm","clk":"4230604164","pt":1631534723234,"mc":[{"id":"1.187557995","rc":[{"batl":[[0,1.38,516.21]],"ltp":1.38,"tv":60194.79,"id":9342449}]}]}
{"op":"mcm","clk":"4230604439","pt":1631534725501,"mc":[{"id":"1.187557995","rc":[{"batb":[[0,1.36,2839.29],[1,1.33,660.38],[2,1.31,415.33]],"batl":[[0,1.38,178],[1,1.39,15],[2,1.44,246.17]],"ltp":1.38,"tv":60194.79,"id":9342449},{"batb":[[0,3.5,24]],"batl":[[0,4,8.66],[1,4.1,4.95],[2,4.3,4.25]],"ltp":3.6,"tv":8223.49,"id":9633869}]}]}
{"op":"mcm","clk":"4230604548","pt":1631534726441,"mc":[{"id":"1.187557995","rc":[{"batb":[[0,1.33,555.94],[1,1.31,415.33],[2,1.3,126.28]],"batl":[[0,1.44,246.17],[1,1.49,2.99],[2,1.77,511.35]],"ltp":1.38,"tv":60194.79,"id":9342449},{"batb":[[0,3.05,104.42],[1,3,3],[2,2.98,3]],"batl":[[0,4.1,4.95],[1,4.3,4.25],[2,4.4,4.44]],"ltp":3.6,"tv":8223.49,"id":9633869}]}]}
{"op":"mcm","clk":"4230604680","pt":1631534727539,"mc":[{"id":"1.187557995","rc":[{"batb":[[0,3.1,100],[1,3.05,104.42],[2,3,3]],"ltp":3.6,"tv":8223.49,"id":9633869}]}]}
{"op":"mcm","clk":"4230604819","pt":1631534728612,"mc":[{"id":"1.187557995","rc":[{"batb":[[2,1.3,644.33]],"batl":[[1,1.45,187.86],[2,1.46,217.8]],"ltp":1.38,"tv":60194.79,"id":9342449},{"batb":[[2,2.2,42.67]],"ltp":3.6,"tv":8223.49,"id":9633869}]}]}
{"op":"mcm","clk":"4230605102","pt":1631534730853,"mc":[{"id":"1.187557995","rc":[{"batb":[[2,1.3,126.28]],"batl":[[1,1.49,2.99],[2,1.77,511.35]],"ltp":1.38,"tv":60194.79,"id":9342449}]}]}
{"op":"mcm","clk":"4230605470","pt":1631534734259,"mc":[{"id":"1.187557995","rc":[{"batb":[[0,1.36,405.38],[1,1.35,318.21],[2,1.33,555.94]],"batl":[[0,1.4,385.81],[1,1.41,252.54],[2,1.44,246.17]],"ltp":1.38,"tv":60194.79,"id":9342449}]}]}
{"op":"mcm","clk":"4230605618","pt":1631534735553,"mc":[{"id":"1.187557995","rc":[{"batl":[[2,1.43,69.62]],"ltp":1.38,"tv":60194.79,"id":9342449},{"batb":[[0,3.15,57.29],[1,3.1,100],[2,3.05,104.42]],"batl":[[0,4,24.75],[1,4.1,4.95],[2,4.3,4.25]],"ltp":3.6,"tv":8223.49,"id":9633869}]}]}
{"op":"mcm","clk":"4230605669","pt":1631534735953,"mc":[{"id":"1.187557995","rc":[{"trd":[[1.4,1132.24]],"batl":[[0,1.4,381.55]],"ltp":1.4,"tv":60199.05,"id":9342449},{"trd":[[3.5,31.76]],"ltp":3.5,"tv":8225.19,"id":9633869}],"tv":68424.25}]}
{"op":"mcm","clk":"4230605960","pt":1631534738647,"mc":[{"id":"1.187557995","rc":[{"batb":[[0,1.37,94.89],[1,1.36,405.38],[2,1.35,318.21]],"batl":[[0,1.39,181.81],[1,1.4,381.55],[2,1.41,252.54]],"ltp":1.4,"tv":60199.05,"id":9342449}]}]}
{"op":"mcm","clk":"4230606023","pt":1631534739259,"mc":[{"id":"1.187557995","rc":[{"trd":[[1.44,347.53]],"batb":[[0,1.33,555.94],[1,1.31,415.33],[2,1.3,126.28]],"batl":[[0,1.44,245.82],[1,1.49,2.99],[2,1.77,511.35]],"ltp":1.44,"tv":60199.4,"id":9342449},{"trd":[[3.25,22.75]],"batb":[[0,3.1,100],[1,3.05,104.42],[2,2.2,42.67]],"batl":[[0,4.1,4.95],[1,4.3,4.25],[2,4.4,4.44]],"ltp":3.25,"tv":8225.35,"id":9633869}],"tv":68424.75}]}
{"op":"mcm","clk":"4230606305","pt":1631534742028,"mc":[{"id":"1.187557995","rc":[{"batb":[[2,1.3,646.9]],"batl":[[1,1.45,185.6],[2,1.46,217.8]],"ltp":1.44,"tv":60199.4,"id":9342449}]}]}
{"op":"mcm","clk":"4230606526","pt":1631534743958,"mc":[{"id":"1.187557995","rc":[{"batb":[[2,1.3,126.28]],"ltp":1.44,"tv":60199.4,"id":9342449}]}]}
{"op":"mcm","clk":"4230606828","pt":1631534746647,"mc":[{"id":"1.187557995","rc":[{"trd":[[1.45,493.34]],"batb":[[0,1.41,9.26],[1,1.4,2732.14],[2,1.39,2651.78]],"batl":[[0,1.45,171.12],[1,1.46,217.8],[2,1.47,2602.04]],"ltp":1.45,"tv":60213.88,"id":9342449},{"trd":[[3.2,16.12]],"ltp":3.2,"tv":8231.91,"id":9633869}],"tv":68445.79}]}
{"op":"mcm","clk":"4230606978","pt":1631534747644,"mc":[{"id":"1.187557995","rc":[{"trd":[[1.44,359.53]],"batb":[[0,1.44,178.17],[1,1.42,194.73],[2,1.41,265.2]],"batl":[[2,1.47,715.56]],"ltp":1.44,"tv":60225.88,"id":9342449},{"batb":[[1,3.05,101.42]],"batl":[[0,3.5,17.71],[1,4.1,4.95],[2,4.3,4.25]],"ltp":3.2,"tv":8231.91,"id":9633869}],"tv":68457.79}]}
{"op":"mcm","clk":"4230607076","pt":1631534748435,"mc":[{"id":"1.187557995","rc":[{"batb":[[0,1.44,191.04]],"batl":[[2,1.47,730.56]],"ltp":1.44,"tv":60225.88,"id":9342449},{"batb":[[0,3.15,27.9],[1,3.1,100],[2,3.05,101.42]],"batl":[[1,3.55,9.39],[2,4.1,4.95]],"ltp":3.2,"tv":8231.91,"id":9633869}]}]}
{"op":"mcm","clk":"4230607198","pt":1631534749436,"mc":[{"id":"1.187557995","rc":[{"batb":[[1,3.1,118.64]],"ltp":3.2,"tv":8231.91,"id":9633869}]}]}
{"op":"mcm","clk":"4230607307","pt":1631534750532,"mc":[{"id":"1.187557995","rc":[{"batb":[[1,1.42,2628.41]],"ltp":1.44,"tv":60225.88,"id":9342449}]}]}
{"op":"mcm","clk":"4230607420","pt":1631534751643,"mc":[{"id":"1.187557995","rc":[{"trd":[[1.45,503.62]],"batb":[[1,1.42,3867.01]],"batl":[[0,1.45,327.19]],"ltp":1.45,"tv":60236.16,"id":9342449},{"trd":[[3.2,20.78]],"ltp":3.2,"tv":8236.57,"id":9633869}],"tv":68472.73}]}
{"op":"mcm","clk":"4230607530","pt":1631534752642,"mc":[{"id":"1.187557995","rc":[{"batl":[[0,3.45,26.58],[1,3.5,17.71]],"ltp":3.2,"tv":8236.57,"id":9633869}]}]}
{"op":"mcm","clk":"4230607653","pt":1631534753686,"mc":[{"id":"1.187557995","rc":[{"batb":[[0,1.44,266.21],[1,1.43,57.34],[2,1.42,2628.41]],"batl":[[0,1.45,401.57],[1,1.46,282.63]],"ltp":1.45,"tv":60236.16,"id":9342449},{"batl":[[2,3.75,4.62]],"ltp":3.2,"tv":8236.57,"id":9633869}]}]}
{"op":"mcm","clk":"4230607855","pt":1631534755474,"mc":[{"id":"1.187557995","rc":[{"batl":[[0,1.45,630.57],[1,1.46,442.66]],"ltp":1.45,"tv":60236.16,"id":9342449},{"batl":[[1,3.5,27.19]],"ltp":3.2,"tv":8236.57,"id":9633869}]}]}
{"op":"mcm","clk":"4230608175","pt":1631534758677,"mc":[{"id":"1.187557995","rc":[{"trd":[[1.42,5388.86],[1.43,203.19],[1.44,891.83]],"batb":[[0,1.41,255.94],[1,1.4,1498.94],[2,1.39,1325.88]],"batl":[[0,1.42,592.87],[1,1.45,630.57],[2,1.46,442.66]],"ltp":1.42,"tv":66139.54,"id":9342449}],"tv":74376.11}]}
{"op":"mcm","clk":"4230608286","pt":1631534759686,"mc":[{"id":"1.187557995","rc":[{"batb":[[1,1.4,132.86],[2,1.37,556.85]],"batl":[[1,1.45,556.19],[2,1.46,377.83]],"ltp":1.42,"tv":66139.54,"id":9342449},{"batb":[[1,3.1,100]],"batl":[[0,3.5,27.19],[1,3.75,4.62],[2,4.1,4.95]],"ltp":3.2,"tv":8236.57,"id":9633869}]}]}
{"op":"mcm","clk":"4230608344","pt":1631534760166,"mc":[{"id":"1.187557995","rc":[{"trd":[[1.42,5509.51]],"batb":[[0,1.37,442.08],[1,1.36,242.76],[2,1.33,121.53]],"batl":[[0,1.42,532.55],[1,1.45,58.43],[2,1.47,15]],"ltp":1.42,"tv":66260.2,"id":9342449},{"batb":[[2,2.64,59.66]],"batl":[[0,3.5,9.48],[1,4.1,4.95],[2,4.3,4.25]],"ltp":3.2,"tv":8236.57,"id":9633869}],"tv":74496.77}]}
{"op":"mcm","clk":"4230608499","pt":1631534761484,"mc":[{"id":"1.187557995","rc":[{"batl":[[1,1.49,2.99],[2,1.77,511.35]],"ltp":1.42,"tv":66260.2,"id":9342449},{"batb":[[0,2.64,59.66],[1,2,11.88],[2,1.97,1.05]],"batl":[[0,4.1,4.95],[1,4.3,4.25],[2,4.4,4.44]],"ltp":3.2,"tv":8236.57,"id":9633869}]}]}
{"op":"mcm","clk":"4230608629","pt":1631534762611,"mc":[{"id":"1.187557995","rc":[{"trd":[[1.42,6574.61]],"batb":[[0,1.42,9.48],[1,1.37,442.08],[2,1.36,242.76]],"batl":[[0,1.49,2.99],[1,1.77,511.35],[2,1.82,2.89]],"ltp":1.42,"tv":67325.3,"id":9342449}],"tv":75561.87}]}
{"op":"mcm","clk":"4230608762","pt":1631534763685,"mc":[{"id":"1.187557995","rc":[{"trd":[[1.42,6593.57]],"batb":[[0,1.37,577.85],[1,1.36,378.44],[2,1.35,212.91]],"batl":[[1,1.55,215.12],[2,1.56,166.38]],"ltp":1.42,"tv":67344.26,"id":9342449},{"batb":[[0,2.68,57.66]],"batl":[[0,3.75,5.14],[1,3.8,5.12],[2,4.1,4.95]],"ltp":3.2,"tv":8236.57,"id":9633869}],"tv":75580.83}]}
{"op":"mcm","clk":"4230608794","pt":1631534763991,"mc":[{"id":"1.187557995","rc":[{"batb":[[0,1.37,794.2]],"ltp":1.42,"tv":67344.26,"id":9342449}]}]}
{"op":"mcm","clk":"4230609104","pt":1631534766604,"mc":[{"id":"1.187557995","rc":[{"batl":[[1,1.77,511.35],[2,1.82,2.89]],"ltp":1.42,"tv":67344.26,"id":9342449}]}]}
{"op":"mcm","clk":"4230609299","pt":1631534768293,"mc":[{"id":"1.187557995","rc":[{"batb":[[0,1.36,378.44],[1,1.35,212.91],[2,1.34,329.46]],"batl":[[1,1.54,216.35],[2,1.77,511.35]],"ltp":1.42,"tv":67344.26,"id":9342449},{"batl":[[0,3.8,5.12],[1,4.1,4.95],[2,4.3,4.25]],"ltp":3.2,"tv":8236.57,"id":9633869}]}]}
{"op":"mcm","clk":"4230609460","pt":1631534769693,"mc":[{"id":"1.187557995","rc":[{"batl":[[0,1.38,336.4],[1,1.39,1646.99],[2,1.4,1335.42]],"ltp":1.42,"tv":67344.26,"id":9342449},{"batb":[[0,2.82,100],[1,2.68,57.66],[2,2,11.88]],"ltp":3.2,"tv":8236.57,"id":9633869}]}]}
{"op":"mcm","clk":"4230609559","pt":1631534770593,"mc":[{"id":"1.187557995","rc":[{"trd":[[1.38,697.34]],"batl":[[0,1.38,320.83]],"ltp":1.38,"tv":67359.83,"id":9342449},{"trd":[[3.6,92.21]],"batb":[[0,3.5,71.46],[1,3,105.52],[2,2.82,100]],"ltp":3.6,"tv":8242.54,"id":9633869}],"tv":75602.37}]}
{"op":"mcm","clk":"4230609655","pt":1631534771389,"mc":[{"id":"1.187557995","rc":[{"batl":[[2,1.4,1350.42]],"ltp":1.38,"tv":67359.83,"id":9342449},{"batb":[[0,3.5,95.46],[2,2,11.88]],"batl":[[1,4,8.66],[2,4.1,4.95]],"ltp":3.6,"tv":8242.54,"id":9633869}]}]}
{"op":"mcm","clk":"4230610040","pt":1631534774699,"mc":[{"id":"1.187557995","rc":[{"batl":[[0,1.38,491.37],[2,1.4,1335.42]],"ltp":1.38,"tv":67359.83,"id":9342449},{"batb":[[0,3.55,13.83],[1,3.5,95.46],[2,3,105.52]],"ltp":3.6,"tv":8242.54,"id":9633869}]}]}
{"op":"mcm","clk":"4230610149","pt":1631534775802,"mc":[{"id":"1.187557995","rc":[{"batb":[[1,3.5,71.46]],"ltp":3.6,"tv":8242.54,"id":9633869}]}]}
{"op":"mcm","clk":"4230610372","pt":1631534777690,"mc":[{"id":"1.187557995","rc":[{"batb":[[0,1.36,3278.76],[1,1.35,290.58]],"batl":[[0,1.37,201.4],[1,1.38,689.86],[2,1.39,1661.99]],"ltp":1.38,"tv":67359.83,"id":9342449}]}]}
{"op":"mcm","clk":"4230610427","pt":1631534778208,"mc":[{"id":"1.187557995","rc":[{"batb":[[2,3.05,100]],"ltp":3.6,"tv":8242.54,"id":9633869}]}]}
{"op":"mcm","clk":"4230610532","pt":1631534779307,"mc":[{"id":"1.187557995","rc":[{"batl":[[1,1.38,564.86]],"ltp":1.38,"tv":67359.83,"id":9342449},{"batb":[[0,3.55,37.35]],"ltp":3.6,"tv":8242.54,"id":9633869}]}]}
{"op":"mcm","clk":"4230610671","pt":1631534780412,"mc":[{"id":"1.187557995","rc":[{"batl":[[2,1.39,1726.95]],"ltp":1.38,"tv":67359.83,"id":9342449},{"batb":[[0,3.55,23.52]],"ltp":3.6,"tv":8242.54,"id":9633869}]}]}
{"op":"mcm","clk":"4230610766","pt":1631534781199,"mc":[{"id":"1.187557995","rc":[{"batb":[[0,1.36,439.47]],"ltp":1.38,"tv":67359.83,"id":9342449}]}]}
{"op":"mcm","clk":"4230610934","pt":1631534782519,"mc":[{"id":"1.187557995","rc":[{"batb":[[0,1.36,61.03],[1,1.35,77.67],[2,1.33,576.33]],"batl":[[0,1.37,626.4],[1,1.38,73.49],[2,1.39,79.96]],"ltp":1.38,"tv":67359.83,"id":9342449},{"batb":[[1,3.05,100],[2,3,105.52]],"batl":[[0,4,8.66],[1,4.2,4.93],[2,4.3,4.25]],"ltp":3.6,"tv":8242.54,"id":9633869}]}]}
{"op":"mcm","clk":"4230611054","pt":1631534783510,"mc":[{"id":"1.187557995","rc":[{"batb":[[2,1.33,471.89]],"batl":[[0,1.37,201.4],[2,1.39,64.96]],"ltp":1.38,"tv":67359.83,"id":9342449},{"batb":[[0,3.6,16.7]],"batl":[[0,4.2,4.93],[1,4.3,4.25],[2,4.4,4.44]],"ltp":3.6,"tv":8242.54,"id":9633869}]}]}
{"op":"mcm","clk":"4230611192","pt":1631534784615,"mc":[{"id":"1.187557995","rc":[{"batb":[[0,1.36,139.79],[1,1.33,471.89],[2,1.32,133.39]],"batl":[[2,1.45,197.61]],"ltp":1.38,"tv":67359.83,"id":9342449},{"batb":[[0,3.05,100],[1,3,105.52],[2,2,11.88]],"ltp":3.6,"tv":8242.54,"id":9633869}]}]}
{"op":"mcm","clk":"4230611325","pt":1631534785921,"mc":[{"id":"1.187557995","rc":[{"batb":[[0,1.33,471.89],[1,1.32,133.39],[2,1.31,123.79]],"batl":[[0,1.45,197.61],[1,1.46,274.05],[2,1.47,211.53]],"ltp":1.38,"tv":67359.83,"id":9342449}]}]}
{"op":"mcm","clk":"4230612167","pt":1631534793718,"mc":[{"id":"1.187557995","rc":[{"batl":[[0,1.38,24.2],[1,1.45,197.61],[2,1.49,2.99]],"ltp":1.38,"tv":67359.83,"id":9342449}]}]}
{"op":"mcm","clk":"4230612268","pt":1631534794512,"mc":[{"id":"1.187557995","rc":[{"batb":[[0,1.3,428.79],[1,1.29,685.79],[2,1.28,428.51]],"batl":[[0,1.49,2.99],[1,1.77,511.35],[2,1.82,2.89]],"ltp":1.38,"tv":67359.83,"id":9342449},{"batl":[[0,4.4,4.44],[1,4.5,4.25],[2,4.4,0]],"ltp":3.6,"tv":8242.54,"id":9633869}]}]}
{"op":"mcm","clk":"4230612495","pt":1631534796337,"mc":[{"id":"1.187557995","rc":[{"batl":[[0,1.32,235.38],[1,1.33,1776.1],[2,1.34,1395.68]],"ltp":1.38,"tv":67359.83,"id":9342449},{"batl":[[2,4.7,223.81]],"ltp":3.6,"tv":8242.54,"id":9633869}]}]}
{"op":"mcm","clk":"4230612657","pt":1631534797712,"mc":[{"id":"1.187557995","rc":[{"trd":[[1.32,420.36]],"batl":[[0,1.32,218.58]],"ltp":1.32,"tv":67376.63,"id":9342449},{"trd":[[4.1,15.03]],"batb":[[0,3.9,55.73],[1,3.5,71.46],[2,3.05,100]],"batl":[[2,4.6,7.9]],"ltp":4.1,"tv":8247.95,"id":9633869}],"tv":75624.58}]}
{"op":"mcm","clk":"4230612988","pt":1631534800713,"mc":[{"id":"1.187557995","rc":[{"batb":[[1,1.29,3035.55]],"batl":[[0,1.32,424.35],[2,1.34,1410.68]],"ltp":1.32,"tv":67376.63,"id":9342449},{"batb":[[2,2.2,42.67]],"ltp":4.1,"tv":8247.95,"id":9633869}]}]}
{"op":"mcm","clk":"4230613117","pt":1631534801643,"mc":[{"id":"1.187557995","rc":[{"batl":[[2,1.34,1395.68]],"ltp":1.32,"tv":67376.63,"id":9342449},{"batb":[[0,3.95,20.33],[1,3.9,55.73],[2,3.5,71.46]],"ltp":4.1,"tv":8247.95,"id":9633869}]}]}
{"op":"mcm","clk":"4230613239","pt":1631534802651,"mc":[{"id":"1.187557995","rc":[{"batb":[[2,1.28,664.46]],"ltp":1.32,"tv":67376.63,"id":9342449}]}]}
{"op":"mcm","clk":"4230613344","pt":1631534803642,"mc":[{"id":"1.187557995","rc":[{"batb":[[0,1.3,438.79],[1,1.29,3043.55],[2,1.28,1034.31]],"ltp":1.32,"tv":67376.63,"id":9342449},{"batl":[[0,4.4,6.44],[2,4.6,12.26]],"ltp":4.1,"tv":8247.95,"id":9633869}]}]}
{"op":"mcm","clk":"4230613467","pt":1631534804646,"mc":[{"id":"1.187557995","rc":[{"batl":[[1,1.33,1791.1]],"ltp":1.32,"tv":67376.63,"id":9342449}]}]}
{"op":"mcm","clk":"4230613587","pt":1631534805650,"mc":[{"id":"1.187557995","rc":[{"batb":[[0,1.3,509.54]],"batl":[[0,1.31,210.62],[1,1.32,491.39],[2,1.33,1791.1]],"ltp":1.32,"tv":67376.63,"id":9342449}]}]}
{"op":"mcm","clk":"4230613644","pt":1631534806229,"mc":[{"id":"1.187557995","rc":[{"batl":[[1,1.32,606.39]],"ltp":1.32,"tv":67376.63,"id":9342449}]}]}
{"op":"mcm","clk":"4230613754","pt":1631534807227,"mc":[{"id":"1.187557995","rc":[{"trd":[[1.31,149.91]],"batl":[[0,1.31,135.66]],"ltp":1.31,"tv":67526.54,"id":9342449}],"tv":75774.49}]}
{"op":"mcm","clk":"4230613918","pt":1631534808647,"mc":[{"id":"1.187557995","rc":[{"batb":[[0,1.3,383.26],[1,1.29,555.98]],"batl":[[2,1.33,353.14]],"ltp":1.31,"tv":67526.54,"id":9342449},{"batl":[[0,4.4,2],[1,4.6,12.26],[2,4.6,0]],"ltp":4.1,"tv":8247.95,"id":9633869}]}]}
{"op":"mcm","clk":"4230614026","pt":1631534809658,"mc":[{"id":"1.187557995","rc":[{"batb":[[0,1.3,70.76],[1,1.28,605.8],[2,1.27,660.04]],"batl":[[1,1.32,67.04],[2,1.33,15]],"ltp":1.31,"tv":67526.54,"id":9342449},{"batb":[[1,3.5,71.46],[2,2.2,42.67]],"batl":[[0,4.6,12.26],[1,4.9,4.15]],"ltp":4.1,"tv":8247.95,"id":9633869}]}]}
{"op":"mcm","clk":"4230614136","pt":1631534810551,"mc":[{"id":"1.187557995","rc":[{"trd":[[1.3,746.2]],"batb":[[0,1.28,605.8],[1,1.27,544.57],[2,1.26,146.48]],"batl":[[0,1.29,3458.66],[1,1.31,135.66],[2,1.32,67.04]],"ltp":1.3,"tv":67668.05,"id":9342449},{"batb":[[0,3.5,71.46],[1,2.2,42.67],[2,2,11.88]],"batl":[[0,4.6,4.36]],"ltp":4.1,"tv":8247.95,"id":9633869}],"tv":75916.0}]}
