{"op":"mcm","clk":"4234795340","pt":1631549986791,"mc":[{"id":"1.187562121","rc":[{"batb":[[0,1.27,173.94],[1,1.25,23.64],[2,1.23,97.63]],"batl":[[0,1.39,42.51],[1,1.41,20.95],[2,1.47,54.5]],"ltp":1.3,"tv":16725.79,"id":20955040},{"batb":[[0,3.7,41.52],[1,3.1,4.24],[2,2.98,36.91]],"batl":[[0,5.4,2.04],[1,6,2.01],[2,7,2]],"ltp":4.3,"tv":3282.77,"id":9625551}]}]}
{"op":"mcm","clk":"4234795398","pt":1631549987410,"mc":[{"id":"1.187562121","rc":[{"batb":[[0,1.21,173.55],[1,1.2,136.77],[2,1.17,147.97]],"batl":[[0,1.52,49.76],[1,3.8,27.43],[2,8.8,7.22]],"ltp":1.3,"tv":16725.79,"id":20955040},{"batb":[[0,2.98,36.91],[1,2.92,4.44],[2,1.46,3.41]],"batl":[[0,6,2.01],[1,7,2],[2,990,0.01]],"ltp":4.3,"tv":3282.77,"id":9625551}]}]}
{"op":"mcm","clk":"4234795622","pt":1631549989548,"mc":[{"id":"1.187562121","rc":[{"batb":[[0,1.32,2],[1,1.21,173.55],[2,1.2,136.77]],"ltp":1.3,"tv":16725.79,"id":20955040}]}]}
{"op":"mcm","clk":"4234795735","pt":1631549990597,"mc":[{"id":"1.187562121","rc":[{"batb":[[1,1.23,118.63],[2,1.21,173.55]],"batl":[[0,1.47,56.5],[1,1.52,49.76],[2,3.8,27.43]],"ltp":1.3,"tv":16725.79,"id":20955040},{"batb":[[0,3.1,3.54],[1,2.98,36.91],[2,2.92,4.44]],"batl":[[0,5.4,2],[1,6,2.01],[2,7,2]],"ltp":4.3,"tv":3282.77,"id":9625551}]}]}
{"op":"mcm","clk":"4234796083","pt":1631549994911,"mc":[{"id":"1.187562121","rc":[{"batb":[[1,1.21,173.55],[2,1.2,136.77]],"batl":[[0,1.52,49.76],[1,3.8,27.43],[2,8.8,7.22]],"ltp":1.3,"tv":16725.79,"id":20955040},{"batb":[[0,2.98,36.91],[1,2.92,4.44],[2,1.46,3.41]],"batl":[[0,4.4,4]],"ltp":4.3,"tv":3282.77,"id":9625551}]}]}
{"op":"mcm","clk":"4234796101","pt":1631549995121,"mc":[{"id":"1.187562121","rc":[{"batl":[[0,6,2.01],[1,7,2],[2,990,0.01]],"ltp":4.3,"tv":3282.77,"id":9625551}]}]}
{"op":"mcm","clk":"4234796325","pt":1631549997521,"mc":[{"id":"1.187562121","rc":[{"batb":[[1,1.23,119.63],[2,1.21,173.55]],"batl":[[0,1.47,57.5],[1,1.52,49.76],[2,3.8,27.43]],"ltp":1.3,"tv":16725.79,"id":20955040},{"batb":[[0,3.1,3.74],[1,2.98,36.91],[2,2.92,4.44]],"batl":[[0,5.4,2.04],[1,6,2.01],[2,7,2]],"ltp":4.3,"tv":3282.77,"id":9625551}]}]}
{"op":"mcm","clk":"4234796520","pt":1631549999949,"mc":[{"id":"1.187562121","rc":[{"batl":[[0,1.52,49.76],[1,3.8,27.43],[2,8.8,7.22]],"ltp":1.3,"tv":16725.79,"id":20955040},{"batb":[[0,2.98,36.91],[1,2.92,4.44],[2,1.46,3.41]],"ltp":4.3,"tv":3282.77,"id":9625551}]}]}
{"op":"mcm","clk":"4234797834","pt":1631550012766,"mc":[{"id":"1.187562121","rc":[{"trd":[[1.32,4]],"batb":[[0,1.24,18.67],[1,1.23,981.03],[2,1.21,222.38]],"batl":[[0,1.26,196.77],[1,1.28,841.77],[2,1.31,45.11]],"ltp":1.32,"tv":16729.79,"id":20955040},{"batb":[[0,4.8,6.24],[1,4.7,3.12],[2,4.6,3.12]],"ltp":4.3,"tv":3282.77,"id":9625551}],"tv":20012.57}]}
{"op":"mcm","clk":"4234797950","pt":1631550013865,"mc":[{"id":"1.187562121","rc":[{"batb":[[2,1.22,8.2]],"ltp":1.32,"tv":16729.79,"id":20955040}]}]}
{"op":"mcm","clk":"4234798001","pt":1631550014336,"mc":[{"id":"1.187562121","rc":[{"batl":[[0,1.25,133.54],[1,1.26,196.77],[2,1.28,841.77]],"ltp":1.32,"tv":16729.79,"id":20955040}]}]}
{"op":"mcm","clk":"4234798622","pt":1631550020751,"mc":[{"id":"1.187562121","rc":[{"batl":[[2,6.6,2]],"ltp":4.3,"tv":3282.77,"id":9625551}]}]}
{"op":"mcm","clk":"4234799395","pt":1631550028829,"mc":[{"id":"1.187562121","rc":[{"batb":[[0,1.21,173.55],[1,1.2,136.77],[2,1.18,144.86]],"batl":[[1,1.31,78.5],[2,1.33,80.5]],"ltp":1.32,"tv":16729.79,"id":20955040},{"batb":[[0,4.4,26.59],[1,4.2,2.52],[2,4,3.18]],"batl":[[0,6,2.01],[1,6.6,2],[2,7,2]],"ltp":4.3,"tv":3282.77,"id":9625551}]}]}
{"op":"mcm","clk":"4234799447","pt":1631550029305,"mc":[{"id":"1.187562121","rc":[{"batb":[[0,1.18,144.86],[1,1.16,220.44],[2,1.01,107.79]],"ltp":1.32,"tv":16729.79,"id":20955040},{"batb":[[0,4.2,2.52],[1,4,3.18],[2,3.65,43.03]],"batl":[[0,6.6,2],[1,990,0.01],[2,7,0]],"ltp":4.3,"tv":3282.77,"id":9625551}]}]}
{"op":"mcm","clk":"4234799511","pt":1631550029929,"mc":[{"id":"1.187562121","rc":[{"batl":[[0,1.24,186.73],[1,1.25,133.54],[2,1.31,78.5]],"ltp":1.32,"tv":16729.79,"id":20955040}]}]}
{"op":"mcm","clk":"4234799765","pt":1631550032551,"mc":[{"id":"1.187562121","rc":[{"batb":[[0,1.2,124.97],[1,1.18,144.86],[2,1.16,220.44]],"ltp":1.32,"tv":16729.79,"id":20955040},{"batl":[[0,6,2.01],[1,6.6,2],[2,990,0.01]],"ltp":4.3,"tv":3282.77,"id":9625551}]}]}
{"op":"mcm","clk":"4234799812","pt":1631550032970,"mc":[{"id":"1.187562121","rc":[{"batb":[[0,1.18,144.86],[1,1.16,220.44],[2,1.01,107.79]],"ltp":1.32,"tv":16729.79,"id":20955040},{"batl":[[0,6.6,2],[1,990,0.01],[2,990,0]],"ltp":4.3,"tv":3282.77,"id":9625551}]}]}
{"op":"mcm","clk":"4234800238","pt":1631550037318,"mc":[{"id":"1.187562121","rc":[{"batl":[[0,1.25,133.54],[1,3.8,27.43],[2,8.8,7.22]],"ltp":1.32,"tv":16729.79,"id":20955040},{"batb":[[0,4,3.18],[1,3.65,43.03],[2,1.46,3.41]],"ltp":4.3,"tv":3282.77,"id":9625551}]}]}
{"op":"mcm","clk":"4234800499","pt":1631550039838,"mc":[{"id":"1.187562121","rc":[{"batb":[[1,1.17,50.5],[2,1.16,220.44]],"batl":[[0,1.22,1141.16],[1,1.23,162.6],[2,1.24,1084.27]],"ltp":1.32,"tv":16729.79,"id":20955040},{"batb":[[0,5.5,27.28],[1,5.4,13.64],[2,5.3,13.64]],"batl":[[0,6,6.64],[1,6.2,232.34],[2,6.6,2]],"ltp":4.3,"tv":3282.77,"id":9625551}]}]}
{"op":"mcm","clk":"4234800589","pt":1631550040724,"mc":[{"id":"1.187562121","rc":[{"batb":[[0,1.18,153.33]],"batl":[[0,1.22,37.44],[1,1.23,97.56]],"ltp":1.32,"tv":16729.79,"id":20955040},{"batb":[[0,5.5,16.37],[1,5.4,8.18],[2,5.3,8.18]],"ltp":4.3,"tv":3282.77,"id":9625551}]}]}
{"op":"mcm","clk":"4234800934","pt":1631550044861,"mc":[{"id":"1.187562121","rc":[{"trd":[[1.2,167.97]],"batl":[[0,1.2,21.86],[1,1.22,37.44],[2,1.23,97.56]],"ltp":1.2,"tv":16847.04,"id":20955040},{"trd":[[6,23.85]],"batl":[[0,6.2,232.34],[1,6.6,2],[2,990,0.01]],"ltp":6.0,"tv":3306.22,"id":9625551}],"tv":20153.27}]}
{"op":"mcm","clk":"4234801209","pt":1631550047827,"mc":[{"id":"1.187562121","rc":[{"batl":[[2,8.2,2]],"ltp":6.0,"tv":3306.22,"id":9625551}]}]}
{"op":"mcm","clk":"4234801495","pt":1631550050654,"mc":[{"id":"1.187562121","rc":[{"trd":[[1.19,949.38]],"ltp":1.19,"tv":16976.6,"id":20955040},{"trd":[[6.2,112.97]],"batl":[[0,6.2,207.47]],"ltp":6.2,"tv":3331.09,"id":9625551}],"tv":20307.7}]}
{"op":"mcm","clk":"4234801873","pt":1631550054367,"mc":[{"id":"1.187562121","rc":[{"batl":[[1,1.23,97.56],[2,1.24,1197]],"ltp":1.19,"tv":16976.6,"id":20955040}]}]}
{"op":"mcm","clk":"4234802148","pt":1631550057243,"mc":[{"id":"1.187562121","rc":[{"batl":[[1,1.21,36.68],[2,1.23,97.56]],"ltp":1.19,"tv":16976.6,"id":20955040},{"batl":[[0,6.2,213.4]],"ltp":6.2,"tv":3331.09,"id":9625551}]}]}
{"op":"mcm","clk":"4234802532","pt":1631550061652,"mc":[{"id":"1.187562121","rc":[{"trd":[[1.2,169.77]],"batl":[[0,1.2,20.96]],"ltp":1.2,"tv":16978.4,"id":20955040}],"tv":20309.5}]}
{"op":"mcm","clk":"4234802970","pt":1631550066881,"mc":[{"id":"1.187562121","rc":[{"batb":[[0,1.16,220.44],[1,1.14,167.32],[2,1.12,534.69]],"batl":[[1,3.8,27.43],[2,8.8,7.22]],"ltp":1.2,"tv":16978.4,"id":20955040},{"batb":[[0,5.1,18.45],[1,4.8,2.03],[2,4.5,25.75]],"batl":[[0,8.2,2],[1,9.4,2],[2,10.5,2]],"ltp":6.2,"tv":3331.09,"id":9625551}]}]}
{"op":"mcm","clk":"4234803012","pt":1631550067345,"mc":[{"id":"1.187562121","rc":[{"batb":[[0,1.12,534.69],[1,1.11,263.59],[2,1.01,107.79]],"ltp":1.2,"tv":16978.4,"id":20955040},{"batb":[[0,4.8,2.03],[1,4.5,25.75],[2,1.46,3.41]],"batl":[[0,9.4,2],[1,10.5,2],[2,990,0.01]],"ltp":6.2,"tv":3331.09,"id":9625551}]}]}
{"op":"mcm","clk":"4234803273","pt":1631550070749,"mc":[{"id":"1.187562121","rc":[{"batl":[[1,1.26,102.75],[2,3.8,27.43]],"ltp":1.2,"tv":16978.4,"id":20955040}]}]}
{"op":"mcm","clk":"4234803353","pt":1631550071582,"mc":[{"id":"1.187562121","rc":[{"trd":[[1.2,178.79]],"batl":[[0,1.2,16.45]],"ltp":1.2,"tv":16987.42,"id":20955040}],"tv":20318.52}]}
{"op":"mcm","clk":"4234804035","pt":1631550079773,"mc":[{"id":"1.187562121","rc":[{"batb":[[0,1.14,160.82],[1,1.12,534.69],[2,1.11,263.59]],"ltp":1.2,"tv":16987.42,"id":20955040},{"batl":[[0,8.2,2],[1,9.4,2],[2,10.5,2]],"ltp":6.2,"tv":3331.09,"id":9625551}]}]}
{"op":"mcm","clk":"4234804053","pt":1631550080085,"mc":[{"id":"1.187562121","rc":[{"batb":[[0,1.12,534.69],[1,1.11,263.59],[2,1.01,107.79]],"ltp":1.2,"tv":16987.42,"id":20955040},{"batl":[[0,9.4,2],[1,10.5,2],[2,990,0.01]],"ltp":6.2,"tv":3331.09,"id":9625551}]}]}
{"op":"mcm","clk":"4234804691","pt":1631550086789,"mc":[{"id":"1.187562121","rc":[{"batb":[[0,1.14,186.82],[1,1.12,534.69],[2,1.11,263.59]],"ltp":1.2,"tv":16987.42,"id":20955040},{"batl":[[0,8.2,2],[1,9.4,2],[2,10.5,2]],"ltp":6.2,"tv":3331.09,"id":9625551}]}]}
{"op":"mcm","clk":"4234804717","pt":1631550086995,"mc":[{"id":"1.187562121","rc":[{"batb":[[0,1.12,534.69],[1,1.11,263.59],[2,1.01,107.79]],"ltp":1.2,"tv":16987.42,"id":20955040},{"batl":[[0,9.4,2],[1,10.5,2],[2,990,0.01]],"ltp":6.2,"tv":3331.09,"id":9625551}]}]}
{"op":"mcm","clk":"4234805165","pt":1631550091595,"mc":[{"id":"1.187562121","rc":[{"trd":[[1.2,195.24]],"batb":[[0,1.23,2.63],[1,1.22,163.94],[2,1.21,8.26]],"batl":[[0,1.24,16.87],[2,1.27,628.82]],"ltp":1.2,"tv":17003.87,"id":20955040},{"trd":[[6,27.14]],"batl":[[0,5.4,2],[1,5.5,9.19],[2,5.7,5.26]],"ltp":6.0,"tv":3334.38,"id":9625551}],"tv":20338.26}]}
{"op":"mcm","clk":"4234805252","pt":1631550092587,"mc":[{"id":"1.187562121","rc":[{"batb":[[0,5,6],[1,4.9,3],[2,4.8,5.03]],"ltp":6.0,"tv":3334.38,"id":9625551}]}]}
{"op":"mcm","clk":"4234805775","pt":1631550098415,"mc":[{"id":"1.187562121","rc":[{"batl":[[2,1.27,719.32]],"ltp":1.2,"tv":17003.87,"id":20955040}]}]}
{"op":"mcm","clk":"4234806235","pt":1631550103695,"mc":[{"id":"1.187562121","rc":[{"batb":[[0,1.17,136.97],[1,1.16,229.58],[2,1.12,231.04]],"batl":[[0,3.8,27.43],[1,8.8,7.22],[2,44,7.22]],"ltp":1.2,"tv":17003.87,"id":20955040},{"batb":[[0,4.4,2.51],[1,4,33.05],[2,1.46,3.41]],"batl":[[0,7,2],[1,9.4,2],[2,10.5,2]],"ltp":6.0,"tv":3334.38,"id":9625551}]}]}
{"op":"mcm","clk":"4234806509","pt":1631550106821,"mc":[{"id":"1.187562121","rc":[{"batl":[[0,1.29,85.5],[1,3.8,27.43],[2,8.8,7.22]],"ltp":1.2,"tv":17003.87,"id":20955040}]}]}
{"op":"mcm","clk":"4234806773","pt":1631550109896,"mc":[{"id":"1.187562121","rc":[{"batb":[[0,1.26,17.75],[1,1.24,8.06],[2,1.17,136.97]],"batl":[[0,1.28,37.71],[1,1.29,85.5],[2,3.8,27.43]],"ltp":1.2,"tv":17003.87,"id":20955040},{"batb":[[1,4.3,165.77],[2,4,33.05]],"batl":[[0,4.8,167.24],[1,4.9,42.82],[2,5,30]],"ltp":6.0,"tv":3334.38,"id":9625551}]}]}
{"op":"mcm","clk":"4234806851","pt":1631550110731,"mc":[{"id":"1.187562121","rc":[{"batb":[[1,1.24,157.95],[2,1.23,48.04]],"batl":[[2,1.31,7.63]],"ltp":1.2,"tv":17003.87,"id":20955040},{"batl":[[1,4.9,26.49],[2,5,18]],"ltp":6.0,"tv":3334.38,"id":9625551}]}]}
{"op":"mcm","clk":"4234807382","pt":1631550116528,"mc":[{"id":"1.187562121","rc":[{"batb":[[2,1.23,160.67]],"batl":[[2,1.3,76.45]],"ltp":1.2,"tv":17003.87,"id":20955040},{"batb":[[1,4.3,168.45]],"ltp":6.0,"tv":3334.38,"id":9625551}]}]}
{"op":"mcm","clk":"4234807780","pt":1631550120401,"mc":[{"id":"1.187562121","rc":[{"trd":[[1.26,46.27]],"batb":[[0,1.26,13.24]],"ltp":1.26,"tv":17012.89,"id":20955040}],"tv":20347.28}]}
{"op":"mcm","clk":"4234808107","pt":1631550123858,"mc":[{"id":"1.187562121","rc":[{"batb":[[0,1.21,123.69],[1,1.2,179.67],[2,1.17,136.97]],"batl":[[0,3.8,27.43],[1,8.8,7.22],[2,44,7.22]],"ltp":1.26,"tv":17012.89,"id":20955040},{"batb":[[0,4.3,2.68],[1,3.8,38.92],[2,1.46,3.41]],"batl":[[0,5.8,2.02],[1,7,2],[2,9.4,2]],"ltp":6.0,"tv":3334.38,"id":9625551}]}]}
{"op":"mcm","clk":"4234808399","pt":1631550126871,"mc":[{"id":"1.187562121","rc":[{"batl":[[0,1.3,78.85],[1,3.8,27.43],[2,8.8,7.22]],"ltp":1.26,"tv":17012.89,"id":20955040}]}]}
{"op":"mcm","clk":"4234809035","pt":1631550133648,"mc":[{"id":"1.187562121","rc":[{"batl":[[0,1.29,82.5],[1,1.3,78.85],[2,3.8,27.43]],"ltp":1.26,"tv":17012.89,"id":20955040},{"batb":[[0,4.4,2.51],[1,4.3,2.68],[2,3.8,38.92]],"ltp":6.0,"tv":3334.38,"id":9625551}]}]}
{"op":"mcm","clk":"4234809103","pt":1631550134433,"mc":[{"id":"1.187562121","rc":[{"batl":[[0,1.3,78.85],[1,3.8,27.43],[2,8.8,7.22]],"ltp":1.26,"tv":17012.89,"id":20955040},{"batb":[[0,4.3,2.68],[1,3.8,38.92],[2,1.46,3.41]],"ltp":6.0,"tv":3334.38,"id":9625551}]}]}
{"op":"mcm","clk":"4234809416","pt":1631550137774,"mc":[{"id":"1.187562121","rc":[{"batb":[[0,1.23,112.63],[1,1.21,123.69],[2,1.2,179.67]],"ltp":1.26,"tv":17012.89,"id":20955040}]}]}
{"op":"mcm","clk":"4234809440","pt":1631550137981,"mc":[{"id":"1.187562121","rc":[{"batb":[[0,1.21,123.69],[1,1.2,179.67],[2,1.17,136.97]],"ltp":1.26,"tv":17012.89,"id":20955040}]}]}
{"op":"mcm","clk":"4234809685","pt":1631550140748,"mc":[{"id":"1.187562121","rc":[{"batl":[[0,1.29,91.5],[1,1.3,78.85],[2,3.8,27.43]],"ltp":1.26,"tv":17012.89,"id":20955040},{"batb":[[0,4.4,2.51],[1,4.3,2.68],[2,3.8,38.92]],"ltp":6.0,"tv":3334.38,"id":9625551}]}]}
{"op":"mcm","clk":"4234809757","pt":1631550141480,"mc":[{"id":"1.187562121","rc":[{"batl":[[0,1.3,78.85],[1,3.8,27.43],[2,8.8,7.22]],"ltp":1.26,"tv":17012.89,"id":20955040},{"batb":[[0,4.3,2.68],[1,3.8,38.92],[2,1.46,3.41]],"ltp":6.0,"tv":3334.38,"id":9625551}]}]}
{"op":"mcm","clk":"4234810082","pt":1631550144772,"mc":[{"id":"1.187562121","rc":[{"batb":[[0,1.23,119.63],[1,1.21,123.69],[2,1.2,179.67]],"ltp":1.26,"tv":17012.89,"id":20955040}]}]}
{"op":"mcm","clk":"4234810105","pt":1631550144980,"mc":[{"id":"1.187562121","rc":[{"batb":[[0,1.21,123.69],[1,1.2,179.67],[2,1.17,136.97]],"ltp":1.26,"tv":17012.89,"id":20955040}]}]}
{"op":"mcm","clk":"4234810766","pt":1631550151881,"mc":[{"id":"1.187562121","rc":[{"batl":[[0,1.28,14.25],[1,1.3,78.85],[2,3.8,27.43]],"ltp":1.26,"tv":17012.89,"id":20955040}]}]}
{"op":"mcm","clk":"4234810838","pt":1631550152820,"mc":[{"id":"1.187562121","rc":[{"batb":[[0,1.23,783.05],[1,1.21,123.69],[2,1.2,228.91]],"batl":[[0,1.24,26.75],[1,1.27,94.49],[2,1.28,1243.5]],"ltp":1.26,"tv":17012.89,"id":20955040},{"batb":[[0,4.9,18.36],[1,4.8,9.18],[2,4.7,9.18]],"batl":[[0,5.5,6.91],[1,5.8,2.02],[2,7,2]],"ltp":6.0,"tv":3334.38,"id":9625551}]}]}
{"op":"mcm","clk":"4234810895","pt":1631550153293,"mc":[{"id":"1.187562121","rc":[{"batb":[[1,1.22,24.6],[2,1.21,144.25]],"ltp":1.26,"tv":17012.89,"id":20955040},{"batb":[[0,4.9,6.12],[1,4.8,3.06],[2,4.7,3.06]],"ltp":6.0,"tv":3334.38,"id":9625551}]}]}
{"op":"mcm","clk":"4234811254","pt":1631550157201,"mc":[{"id":"1.187562121","rc":[{"trd":[[1.24,92.63]],"batl":[[0,1.27,94.49],[1,1.28,1243.5],[2,1.3,78.85]],"ltp":1.24,"tv":17039.64,"id":20955040},{"trd":[[5.1,29.57]],"ltp":5.1,"tv":3340.88,"id":9625551}],"tv":20380.53}]}
{"op":"mcm","clk":"4234811388","pt":1631550158705,"mc":[{"id":"1.187562121","rc":[{"batl":[[1,1.28,1334.59]],"ltp":1.24,"tv":17039.64,"id":20955040},{"batl":[[2,6.4,2]],"ltp":5.1,"tv":3340.88,"id":9625551}]}]}
{"op":"mcm","clk":"4234811581","pt":1631550160579,"mc":[{"id":"1.187562121","rc":[{"batl":[[2,1.29,89.5]],"ltp":1.24,"tv":17039.64,"id":20955040}]}]}
{"op":"mcm","clk":"4234812184","pt":1631550167196,"mc":[{"id":"1.187562121","rc":[{"batl":[[0,5.8,2.02],[1,6.4,2],[2,7,2]],"ltp":5.1,"tv":3340.88,"id":9625551}]}]}
{"op":"mcm","clk":"4234812459","pt":1631550170124,"mc":[{"id":"1.187562121","rc":[{"batl":[[0,1.25,14.58],[1,1.27,94.49],[2,1.28,1334.59]],"ltp":1.24,"tv":17039.64,"id":20955040},{"batb":[[0,5,3.64],[1,4.9,6.12],[2,4.8,3.06]],"batl":[[0,5.3,5.42],[1,5.8,2.02],[2,6.4,2]],"ltp":5.1,"tv":3340.88,"id":9625551}]}]}
{"op":"mcm","clk":"4234813395","pt":1631550179520,"mc":[{"id":"1.187562121","rc":[{"batb":[[0,1.01,107.79],[1,1.22,0],[2,1.21,0]],"batl":[[0,3.8,27.43],[1,8.8,7.22],[2,44,7.22]],"ltp":1.24,"tv":17039.64,"id":20955040},{"batb":[[0,4.3,2.68],[1,1.46,3.41],[2,1.01,105.79]],"batl":[[0,7,2],[1,990,0.01],[2,6.4,0]],"ltp":5.1,"tv":3340.88,"id":9625551}]}]}
{"op":"mcm","clk":"4234813691","pt":1631550182704,"mc":[{"id":"1.187562121","rc":[{"batb":[[0,1.19,130.71],[1,1.17,159.97],[2,1.01,107.79]],"batl":[[0,1.28,103.34],[1,1.3,73.45],[2,3.8,27.43]],"ltp":1.24,"tv":17039.64,"id":20955040},{"batb":[[0,4.5,2.58],[1,4.3,2.68],[2,1.46,3.41]],"batl":[[0,6.4,2],[1,7,2],[2,990,0.01]],"ltp":5.1,"tv":3340.88,"id":9625551}]}]}
{"op":"mcm","clk":"4234813717","pt":1631550183010,"mc":[{"id":"1.187562121","rc":[{"batb":[[0,1.17,159.97],[1,1.01,107.79],[2,1.01,0]],"batl":[[0,1.3,73.45],[1,3.8,27.43],[2,8.8,7.22]],"ltp":1.24,"tv":17039.64,"id":20955040},{"batb":[[0,4.3,2.68],[1,1.46,3.41],[2,1.01,105.79]],"batl":[[0,7,2],[1,990,0.01],[2,990,0]],"ltp":5.1,"tv":3340.88,"id":9625551}]}]}
{"op":"mcm","clk":"4234814534","pt":1631550189840,"mc":[{"id":"1.187562121","rc":[{"batb":[[0,1.26,119.04],[1,1.25,59.52],[2,1.24,59.52]],"batl":[[0,1.28,94.34],[1,1.3,73.45],[2,1.31,657.81]],"ltp":1.24,"tv":17039.64,"id":20955040},{"batb":[[0,4.5,8.7],[1,4.3,2.68],[2,1.46,3.41]],"batl":[[0,4.7,774.62],[1,5,2],[2,5.1,39.22]],"ltp":5.1,"tv":3340.88,"id":9625551}]}]}
{"op":"mcm","clk":"4234814648","pt":1631550190829,"mc":[{"id":"1.187562121","rc":[{"batb":[[0,1.27,2.61],[1,1.26,71.42],[2,1.25,35.71]],"batl":[[0,1.3,188.83],[1,1.31,715.49],[2,1.32,65.26]],"ltp":1.24,"tv":17039.64,"id":20955040},{"batb":[[0,4.5,6.12]],"batl":[[0,4.7,4.76],[1,4.8,2],[2,5,2]],"ltp":5.1,"tv":3340.88,"id":9625551}]}]}
{"op":"mcm","clk":"4234814670","pt":1631550191140,"mc":[{"id":"1.187562121","rc":[{"batb":[[1,1.26,23.8],[2,1.25,11.9]],"batl":[[0,1.3,96.53],[1,1.31,669.35],[2,1.32,19.12]],"ltp":1.24,"tv":17039.64,"id":20955040}]}]}
{"op":"mcm","clk":"4234815157","pt":1631550194821,"mc":[{"id":"1.187562121","rc":[{"batl":[[2,1.32,207.65]],"ltp":1.24,"tv":17039.64,"id":20955040},{"batl":[[0,4.6,23.88],[1,4.7,4.76],[2,4.8,2]],"ltp":5.1,"tv":3340.88,"id":9625551}]}]}
{"op":"mcm","clk":"4234815176","pt":1631550195033,"mc":[{"id":"1.187562121","rc":[{"batl":[[2,1.32,19.12]],"ltp":1.24,"tv":17039.64,"id":20955040},{"batl":[[0,4.7,4.76],[1,4.8,2],[2,5,2]],"ltp":5.1,"tv":3340.88,"id":9625551}]}]}
{"op":"mcm","clk":"4234815317","pt":1631550196537,"mc":[{"id":"1.187562121","rc":[{"batl":[[1,1.31,755.85]],"ltp":1.24,"tv":17039.64,"id":20955040},{"batb":[[2,4.2,2.42]],"ltp":5.1,"tv":3340.88,"id":9625551}]}]}
{"op":"mcm","clk":"4234815584","pt":1631550199447,"mc":[{"id":"1.187562121","rc":[{"trd":[[1.27,37.02]],"batb":[[0,1.26,23.8],[1,1.25,11.9],[2,1.24,178.08]],"ltp":1.27,"tv":17059.31,"id":20955040},{"trd":[[4.7,8.05]],"batl":[[0,4.8,2.86],[1,5,2],[2,5.1,23.53]],"ltp":4.7,"tv":3344.78,"id":9625551}],"tv":20404.09}]}
{"op":"mcm","clk":"4234815900","pt":1631550202740,"mc":[{"id":"1.187562121","rc":[{"batb":[[0,1.22,125.34],[1,1.01,107.79],[2,1.24,0]],"batl":[[0,1.31,86.5],[1,3.8,27.43],[2,8.8,7.22]],"ltp":1.27,"tv":17059.31,"id":20955040},{"batb":[[0,4.2,2.42],[1,1.46,3.41],[2,1.01,105.79]],"batl":[[0,5.6,2.01],[1,990,0.01],[2,5.1,0]],"ltp":4.7,"tv":3344.78,"id":9625551}]}]}
{"op":"mcm","clk":"4234816164","pt":1631550205753,"mc":[{"id":"1.187562121","rc":[{"batb":[[0,1.24,95.02],[1,1.22,125.34],[2,1.01,107.79]],"batl":[[0,1.3,86.05],[1,1.31,86.5],[2,3.8,27.43]],"ltp":1.27,"tv":17059.31,"id":20955040},{"batb":[[0,4.3,2.88],[1,4.2,2.42],[2,1.46,3.41]],"batl":[[0,5.2,2.03],[1,5.6,2.01],[2,990,0.01]],"ltp":4.7,"tv":3344.78,"id":9625551}]}]}
{"op":"mcm","clk":"4234816194","pt":1631550206067,"mc":[{"id":"1.187562121","rc":[{"batb":[[0,1.22,125.34],[1,1.01,107.79],[2,1.01,0]],"batl":[[0,1.31,86.5],[1,3.8,27.43],[2,8.8,7.22]],"ltp":1.27,"tv":17059.31,"id":20955040},{"batb":[[0,4.2,2.42],[1,1.46,3.41],[2,1.01,105.79]],"batl":[[0,5.6,2.01],[1,990,0.01],[2,990,0]],"ltp":4.7,"tv":3344.78,"id":9625551}]}]}
{"op":"mcm","clk":"4234816557","pt":1631550210341,"mc":[{"id":"1.187562121","rc":[{"batb":[[0,1.29,2],[1,1.28,23.44],[2,1.27,11.72]],"batl":[[1,1.33,542.62],[2,1.38,42.82]],"ltp":1.27,"tv":17059.31,"id":20955040},{"batl":[[0,4.5,2],[1,4.7,44.69],[2,4.8,530.56]],"ltp":4.7,"tv":3344.78,"id":9625551}]}]}
{"op":"mcm","clk":"4234816643","pt":1631550211331,"mc":[{"id":"1.187562121","rc":[{"batl":[[1,1.32,22.72],[2,1.33,553.98]],"ltp":1.27,"tv":17059.31,"id":20955040}]}]}
{"op":"mcm","clk":"4234816788","pt":1631550213045,"mc":[{"id":"1.187562121","rc":[{"batl":[[0,1.3,16.56],[1,1.31,86.5],[2,1.32,22.72]],"ltp":1.27,"tv":17059.31,"id":20955040},{"batl":[[0,4.5,7.05]],"ltp":4.7,"tv":3344.78,"id":9625551}]}]}
{"op":"mcm","clk":"4234816980","pt":1631550215131,"mc":[{"id":"1.187562121","rc":[{"trd":[[1.3,194.71]],"batl":[[0,1.31,86.5],[1,1.32,22.72],[2,1.33,553.98]],"ltp":1.3,"tv":17075.87,"id":20955040},{"trd":[[4.3,72.42]],"ltp":4.3,"tv":3349.79,"id":9625551}],"tv":20425.66}]}
{"op":"mcm","clk":"4234817828","pt":1631550225172,"mc":[{"id":"1.187562121","rc":[{"batl":[[0,4.5,2]],"ltp":4.3,"tv":3349.79,"id":9625551}]}]}
{"op":"mcm","clk":"4234818059","pt":1631550227671,"mc":[{"id":"1.187562121","rc":[{"trd":[[1.31,294.99],[1.32,57.12],[1.33,1109.6]],"batb":[[0,1.33,158.86],[1,1.29,2],[2,1.28,23.44]],"batl":[[0,1.34,18.82],[1,1.38,42.82],[2,1.4,21.11]],"ltp":1.33,"tv":18409.53,"id":20955040},{"trd":[[4.2,35.78]],"batb":[[0,1.46,3.41],[1,1.01,105.79],[2,1.01,0]],"ltp":4.2,"tv":3352.21,"id":9625551}],"tv":21761.75}]}
{"op":"mcm","clk":"4234818101","pt":1631550228192,"mc":[{"id":"1.187562121","rc":[{"trd":[[1.33,1154.05]],"batb":[[0,1.33,136.64]],"ltp":1.33,"tv":18453.98,"id":20955040},{"batl":[[0,4.4,4.05],[1,4.5,2],[2,4.7,44.69]],"ltp":4.2,"tv":3352.21,"id":9625551}],"tv":21806.19}]}
{"op":"mcm","clk":"4234818367","pt":1631550230854,"mc":[{"id":"1.187562121","rc":[{"trd":[[1.33,1313.83]],"batb":[[0,1.33,56.78]],"ltp":1.33,"tv":18613.76,"id":20955040}],"tv":21965.98}]}
{"op":"mcm","clk":"4234818479","pt":1631550231890,"mc":[{"id":"1.187562121","rc":[{"trd":[[1.33,1342.45]],"batb":[[0,1.33,42.47],[1,1.31,18.04],[2,1.29,2]],"ltp":1.33,"tv":18642.38,"id":20955040}],"tv":21994.6}]}
{"op":"mcm","clk":"4234818987","pt":1631550237506,"mc":[{"id":"1.187562121","rc":[{"batb":[[0,2.62,10.21],[1,1.46,3.41],[2,1.01,105.79]],"ltp":4.2,"tv":3352.21,"id":9625551}]}]}
{"op":"mcm","clk":"4234819059","pt":1631550238278,"mc":[{"id":"1.187562121","rc":[{"batl":[[0,4.5,2],[1,4.7,44.69],[2,4.8,530.56]],"ltp":4.2,"tv":3352.21,"id":9625551}]}]}
{"op":"mcm","clk":"4234819335","pt":1631550241303,"mc":[{"id":"1.187562121","rc":[{"trd":[[1.33,1383.76]],"batb":[[0,1.33,21.83]],"ltp":1.33,"tv":18683.69,"id":20955040},{"batl":[[0,4.3,4.81],[1,4.5,2],[2,4.7,44.69]],"ltp":4.2,"tv":3352.21,"id":9625551}],"tv":22035.9}]}
{"op":"mcm","clk":"4234819521","pt":1631550243103,"mc":[{"id":"1.187562121","rc":[{"trd":[[1.33,1401.79]],"batb":[[0,1.33,12.81]],"ltp":1.33,"tv":18701.72,"id":20955040}],"tv":22053.94}]}
{"op":"mcm","clk":"4234820222","pt":1631550250175,"mc":[{"id":"1.187562121","rc":[{"trd":[[1.33,1415.31]],"batb":[[0,1.33,6.06]],"ltp":1.33,"tv":18715.24,"id":20955040}],"tv":22067.45}]}
{"op":"mcm","clk":"4234820336","pt":1631550251487,"mc":[{"id":"1.187562121","rc":[{"batl":[[0,4.5,2],[1,4.7,44.69],[2,4.8,530.56]],"ltp":4.2,"tv":3352.21,"id":9625551}]}]}
{"op":"mcm","clk":"4234820627","pt":1631550254471,"mc":[{"id":"1.187562121","rc":[{"trd":[[1.33,1427.42]],"batb":[[0,1.31,18.04],[1,1.29,2],[2,1.28,23.44]],"batl":[[0,1.33,13.71],[1,1.34,18.82],[2,1.38,42.82]],"ltp":1.33,"tv":18727.35,"id":20955040},{"batl":[[0,4.2,4.99],[1,4.5,2],[2,4.7,44.69]],"ltp":4.2,"tv":3352.21,"id":9625551}],"tv":22079.57}]}
{"op":"mcm","clk":"4234821629","pt":1631550264651,"mc":[{"id":"1.187562121","rc":[{"batl":[[0,1.34,18.82],[1,1.38,42.82],[2,1.4,21.11]],"ltp":1.33,"tv":18727.35,"id":20955040},{"batl":[[0,4.5,2],[1,4.7,44.69],[2,4.8,530.56]],"ltp":4.2,"tv":3352.21,"id":9625551}]}]}
{"op":"mcm","clk":"4234821905","pt":1631550267577,"mc":[{"id":"1.187562121","rc":[{"batl":[[0,1.33,13.71],[1,1.34,18.82],[2,1.38,42.82]],"ltp":1.33,"tv":18727.35,"id":20955040},{"batl":[[0,4.2,6.91],[1,4.5,2],[2,4.7,44.69]],"ltp":4.2,"tv":3352.21,"id":9625551}]}]}
{"op":"mcm","clk":"4234824797","pt":1631550297798,"mc":[{"id":"1.187562121","rc":[{"batl":[[2,3.8,27.43]],"ltp":1.33,"tv":18727.35,"id":20955040},{"batb":[[0,1.46,3.41],[1,1.01,105.79],[2,1.01,0]],"ltp":4.2,"tv":3352.21,"id":9625551}]}]}
{"op":"mcm","clk":"4234824866","pt":1631550298728,"mc":[{"id":"1.187562121","rc":[{"batb":[[2,1.22,125.34]],"batl":[[1,3.8,27.43],[2,8.8,7.22]],"ltp":1.33,"tv":18727.35,"id":20955040},{"batl":[[2,4.8,530.56]],"ltp":4.2,"tv":3352.21,"id":9625551}]}]}
{"op":"mcm","clk":"4234824895","pt":1631550299037,"mc":[{"id":"1.187562121","rc":[{"batb":[[1,1.22,125.34],[2,1.01,107.79]],"batl":[[0,3.8,27.43],[1,8.8,7.22],[2,44,7.22]],"ltp":1.33,"tv":18727.35,"id":20955040},{"batl":[[0,5.6,2.01],[1,990,0.01],[2,4.8,0]],"ltp":4.2,"tv":3352.21,"id":9625551}]}]}
{"op":"mcm","clk":"4234825234","pt":1631550302234,"mc":[{"id":"1.187562121","rc":[{"batb":[[1,1.25,93.33],[2,1.22,125.34]],"batl":[[0,1.44,56.08],[1,3.8,27.43],[2,8.8,7.22]],"ltp":1.33,"tv":18727.35,"id":20955040},{"batb":[[0,3.25,3.33],[1,1.46,3.41],[2,1.01,105.79]],"batl":[[0,5,2.12],[1,5.6,2.01],[2,990,0.01]],"ltp":4.2,"tv":3352.21,"id":9625551}]}]}
{"op":"mcm","clk":"4234825630","pt":1631550305750,"mc":[{"id":"1.187562121","rc":[{"batb":[[0,1.31,17.14]],"batl":[[0,1.41,57.5],[1,1.44,56.08],[2,3.8,27.43]],"ltp":1.33,"tv":18727.35,"id":20955040},{"batb":[[0,3.4,3.46],[1,3.25,3.33],[2,1.46,3.41]],"batl":[[0,4,2.25],[1,5,2.12],[2,5.6,2.01]],"ltp":4.2,"tv":3352.21,"id":9625551}]}]}
{"op":"mcm","clk":"4234825665","pt":1631550306120,"mc":[{"id":"1.187562121","rc":[{"batl":[[0,1.44,56.08],[1,3.8,27.43],[2,8.8,7.22]],"ltp":1.33,"tv":18727.35,"id":20955040},{"batb":[[0,3.25,3.33],[1,1.46,3.41],[2,1.01,105.79]],"ltp":4.2,"tv":3352.21,"id":9625551}]}]}
{"op":"mcm","clk":"4234826166","pt":1631550310740,"mc":[{"id":"1.187562121","rc":[{"batb":[[0,1.35,222],[1,1.31,17.14],[2,1.25,93.33]],"ltp":1.33,"tv":18727.35,"id":20955040}]}]}
{"op":"mcm","clk":"4234826341","pt":1631550312846,"mc":[{"id":"1.187562121","rc":[{"batl":[[0,1.41,69.5],[1,1.44,56.08],[2,3.8,27.43]],"ltp":1.33,"tv":18727.35,"id":20955040},{"batb":[[0,3.4,3.26],[1,3.25,3.33],[2,1.46,3.41]],"ltp":4.2,"tv":3352.21,"id":9625551}]}]}
{"op":"mcm","clk":"4234826369","pt":1631550313151,"mc":[{"id":"1.187562121","rc":[{"batl":[[0,1.44,56.08],[1,3.8,27.43],[2,8.8,7.22]],"ltp":1.33,"tv":18727.35,"id":20955040},{"batb":[[0,3.25,3.33],[1,1.46,3.41],[2,1.01,105.79]],"ltp":4.2,"tv":3352.21,"id":9625551}]}]}
{"op":"mcm","clk":"4234826540","pt":1631550315030,"mc":[{"id":"1.187562121","rc":[{"batb":[[2,1.27,222]],"ltp":1.33,"tv":18727.35,"id":20955040}]}]}
{"op":"mcm","clk":"4234826726","pt":1631550316766,"mc":[{"id":"1.187562121","rc":[{"batl":[[0,5,2.12],[1,5.6,2.01],[2,990,0.01]],"ltp":4.2,"tv":3352.21,"id":9625551}]}]}
{"op":"mcm","clk":"4234826995","pt":1631550319252,"mc":[{"id":"1.187562121","rc":[{"batb":[[0,1.31,17.14],[1,1.25,93.33],[2,1.22,125.34]],"ltp":1.33,"tv":18727.35,"id":20955040}]}]}
{"op":"mcm","clk":"4234827247","pt":1631550321652,"mc":[{"id":"1.187562121","rc":[{"trd":[[1.31,329.27]],"batb":[[0,1.26,625.47],[2,1.22,173.77]],"batl":[[0,1.29,21.14],[1,1.3,30.77],[2,1.31,11.54]],"ltp":1.31,"tv":18761.63,"id":20955040},{"batb":[[0,4.3,195.34],[1,3.25,3.33],[2,1.46,3.41]],"batl":[[0,4.7,7.22],[1,5,2.12],[2,5.6,2.01]],"ltp":4.2,"tv":3352.21,"id":9625551}],"tv":22113.85}]}
{"op":"mcm","clk":"4234827346","pt":1631550322647,"mc":[{"id":"1.187562121","rc":[{"batb":[[2,1.24,24.2]],"ltp":1.31,"tv":18761.63,"id":20955040}]}]}
{"op":"mcm","clk":"4234827662","pt":1631550325771,"mc":[{"id":"1.187562121","rc":[{"batb":[[0,1.27,222],[1,1.26,625.47],[2,1.25,93.33]],"ltp":1.31,"tv":18761.63,"id":20955040}]}]}
{"op":"mcm","clk":"4234827743","pt":1631550326556,"mc":[{"id":"1.187562121","rc":[{"batb":[[2,1.25,315.33]],"ltp":1.31,"tv":18761.63,"id":20955040}]}]}
{"op":"mcm","clk":"4234827970","pt":1631550328855,"mc":[{"id":"1.187562121","rc":[{"batb":[[1,4,2.79],[2,3.85,2.97]],"batl":[[2,5.4,2.04]],"ltp":4.2,"tv":3352.21,"id":9625551}]}]}
{"op":"mcm","clk":"4234828649","pt":1631550336485,"mc":[{"id":"1.187562121","rc":[{"trd":[[1.29,55.66]],"batl":[[0,1.29,20.69]],"ltp":1.29,"tv":18762.53,"id":20955040}],"tv":22114.75}]}
{"op":"mcm","clk":"4234829278","pt":1631550344085,"mc":[{"id":"1.187562121","rc":[{"trd":[[1.29,61.48]],"batl":[[0,1.29,14.87]],"ltp":1.29,"tv":18768.35,"id":20955040},{"trd":[[4.4,65.15]],"ltp":4.4,"tv":3353.92,"id":9625551}],"tv":22122.28}]}
{"op":"mcm","clk":"4234829446","pt":1631550345878,"mc":[{"id":"1.187562121","rc":[{"batb":[[1,1.25,315.33],[2,1.23,109.63]],"batl":[[0,1.33,120.93],[1,1.35,96.38],[2,1.4,222]],"ltp":1.29,"tv":18768.35,"id":20955040},{"batb":[[0,4,2.79],[1,3.85,2.97],[2,3.6,22.31]],"batl":[[0,5,2.12],[1,5.4,2.04],[2,5.6,2.01]],"ltp":4.4,"tv":3353.92,"id":9625551}]}]}
{"op":"mcm","clk":"4234829464","pt":1631550346085,"mc":[{"id":"1.187562121","rc":[{"batb":[[1,1.25,222]],"batl":[[0,1.35,74.5],[1,1.4,222],[2,1.44,56.08]],"ltp":1.29,"tv":18768.35,"id":20955040},{"batb":[[0,3.85,2.97],[1,3.6,22.31],[2,3.25,3.33]],"batl":[[0,5.4,2.04],[1,5.6,2.01],[2,5.8,2.02]],"ltp":4.4,"tv":3353.92,"id":9625551}]}]}
{"op":"mcm","clk":"4234830129","pt":1631550352794,"mc":[{"id":"1.187562121","rc":[{"batl":[[0,1.33,68.5],[1,1.35,74.5],[2,1.4,222]],"ltp":1.29,"tv":18768.35,"id":20955040},{"batb":[[0,4,3.04],[1,3.85,2.97],[2,3.6,22.31]],"ltp":4.4,"tv":3353.92,"id":9625551}]}]}
{"op":"mcm","clk":"4234830161","pt":1631550353099,"mc":[{"id":"1.187562121","rc":[{"batl":[[0,1.35,74.5],[1,1.4,222],[2,1.44,56.08]],"ltp":1.29,"tv":18768.35,"id":20955040},{"batb":[[0,3.85,2.97],[1,3.6,22.31],[2,3.25,3.33]],"ltp":4.4,"tv":3353.92,"id":9625551}]}]}
{"op":"mcm","clk":"4234830373","pt":1631550354789,"mc":[{"id":"1.187562121","rc":[{"batl":[[0,1.33,222],[1,1.35,74.5],[2,1.4,222]],"ltp":1.29,"tv":18768.35,"id":20955040}]}]}
{"op":"mcm","clk":"4234830416","pt":1631550355212,"mc":[{"id":"1.187562121","rc":[{"batl":[[2,1.44,56.08]],"ltp":1.29,"tv":18768.35,"id":20955040}]}]}
{"op":"mcm","clk":"4234830511","pt":1631550356310,"mc":[{"id":"1.187562121","rc":[{"batl":[[0,1.33,294.5]],"ltp":1.29,"tv":18768.35,"id":20955040},{"batb":[[0,4,3.18],[1,3.85,2.97],[2,3.6,22.31]],"ltp":4.4,"tv":3353.92,"id":9625551}]}]}
{"op":"mcm","clk":"4234831479","pt":1631550365901,"mc":[{"id":"1.187562121","rc":[{"batb":[[0,1.23,109.63],[1,1.22,125.34],[2,1.21,115.69]],"ltp":1.29,"tv":18768.35,"id":20955040}]}]}
{"op":"mcm","clk":"4234831508","pt":1631550366210,"mc":[{"id":"1.187562121","rc":[{"batb":[[0,1.21,115.69],[1,1.2,180.68],[2,1.01,107.79]],"ltp":1.29,"tv":18768.35,"id":20955040},{"batl":[[0,5.8,2.02],[1,990,0.01],[2,5.8,0]],"ltp":4.4,"tv":3353.92,"id":9625551}]}]}
{"op":"mcm","clk":"4234831656","pt":1631550367789,"mc":[{"id":"1.187562121","rc":[{"batl":[[0,1.26,19.24],[1,1.27,803.26],[2,1.28,59.06]],"ltp":1.29,"tv":18768.35,"id":20955040},{"batb":[[0,4.5,44.44],[1,4,3.18],[2,3.85,2.97]],"batl":[[0,5.1,6.1],[1,5.3,141.88],[2,5.8,2.02]],"ltp":4.4,"tv":3353.92,"id":9625551}]}]}
{"op":"mcm","clk":"4234831758","pt":1631550368885,"mc":[{"id":"1.187562121","rc":[{"batb":[[0,1.21,123.95],[2,1.19,49.66]],"ltp":1.29,"tv":18768.35,"id":20955040},{"batb":[[0,4.5,33.88],[1,4,36.65]],"ltp":4.4,"tv":3353.92,"id":9625551}]}]}
{"op":"mcm","clk":"4234832083","pt":1631550372815,"mc":[{"id":"1.187562121","rc":[{"trd":[[1.26,80.66]],"batb":[[0,1.24,222],[1,1.21,123.95],[2,1.2,180.68]],"batl":[[0,1.26,2.04],[1,1.27,1028.9]],"ltp":1.26,"tv":18802.74,"id":20955040},{"batl":[[1,5.3,158.78]],"ltp":4.4,"tv":3353.92,"id":9625551}],"tv":22156.67}]}
{"op":"mcm","clk":"4234832161","pt":1631550373705,"mc":[{"id":"1.187562121","rc":[{"batb":[[1,1.22,222],[2,1.21,345.95]],"batl":[[1,1.27,803.26]],"ltp":1.26,"tv":18802.74,"id":20955040},{"batl":[[1,5.3,141.88]],"ltp":4.4,"tv":3353.92,"id":9625551}]}]}
{"op":"mcm","clk":"4234832362","pt":1631550376009,"mc":[{"id":"1.187562121","rc":[{"batb":[[1,1.22,340.84]],"batl":[[2,1.28,150.9]],"ltp":1.26,"tv":18802.74,"id":20955040},{"batb":[[0,4.5,36.46],[1,4.4,2.61],[2,4,36.65]],"batl":[[2,5.6,2.01]],"ltp":4.4,"tv":3353.92,"id":9625551}]}]}
{"op":"mcm","clk":"4234832972","pt":1631550382996,"mc":[{"id":"1.187562121","rc":[{"batl":[[0,1.27,803.26],[1,1.28,150.9],[2,1.29,139.56]],"ltp":1.26,"tv":18802.74,"id":20955040},{"batl":[[0,5.3,141.88],[1,5.6,2.01],[2,5.8,2.02]],"ltp":4.4,"tv":3353.92,"id":9625551}]}]}
{"op":"mcm","clk":"4234833217","pt":1631550385929,"mc":[{"id":"1.187562121","rc":[{"batl":[[0,1.27,830.27]],"ltp":1.26,"tv":18802.74,"id":20955040},{"batl":[[0,5,6.23],[1,5.3,141.88],[2,5.6,2.01]],"ltp":4.4,"tv":3353.92,"id":9625551}]}]}
{"op":"mcm","clk":"4234833339","pt":1631550387027,"mc":[{"id":"1.187562121","rc":[{"batb":[[2,4.2,2.62]],"ltp":4.4,"tv":3353.92,"id":9625551}]}]}
{"op":"mcm","clk":"4234833586","pt":1631550389808,"mc":[{"id":"1.187562121","rc":[{"batb":[[2,1.21,337.69]],"batl":[[0,1.27,114],[1,1.29,80.5],[2,1.3,45.45]],"ltp":1.26,"tv":18802.74,"id":20955040},{"batb":[[0,4.5,25]],"batl":[[0,5.6,2.01],[1,5.8,2.02],[2,6,2.01]],"ltp":4.4,"tv":3353.92,"id":9625551}]}]}
{"op":"mcm","clk":"4234833628","pt":1631550390242,"mc":[{"id":"1.187562121","rc":[{"batl":[[2,1.3,93.25]],"ltp":1.26,"tv":18802.74,"id":20955040},{"batb":[[0,4.4,2.61],[1,4.3,2.88]],"ltp":4.4,"tv":3353.92,"id":9625551}]}]}
{"op":"mcm","clk":"4234833739","pt":1631550391315,"mc":[{"id":"1.187562121","rc":[{"batl":[[0,1.3,93.25],[1,1.33,294.5],[2,1.35,74.5]],"ltp":1.26,"tv":18802.74,"id":20955040},{"batb":[[0,4.3,2.88],[1,4,36.65],[2,3.85,2.97]],"ltp":4.4,"tv":3353.92,"id":9625551}]}]}
{"op":"mcm","clk":"4234834348","pt":1631550397725,"mc":[{"id":"1.187562121","rc":[{"batb":[[0,1.22,118.84],[1,1.21,115.69],[2,1.2,125.52]],"batl":[[2,1.46,222]],"ltp":1.26,"tv":18802.74,"id":20955040},{"batb":[[2,1.46,3.41]],"ltp":4.4,"tv":3353.92,"id":9625551}]}]}
{"op":"mcm","clk":"4234834430","pt":1631550398825,"mc":[{"id":"1.187562121","rc":[{"batb":[[0,1.2,125.52],[1,1.18,204.83],[2,1.01,107.79]],"ltp":1.26,"tv":18802.74,"id":20955040},{"batl":[[0,6,2.01],[1,990,0.01],[2,6,0]],"ltp":4.4,"tv":3353.92,"id":9625551}]}]}
{"op":"mcm","clk":"4234834511","pt":1631550399759,"mc":[{"id":"1.187562121","rc":[{"batl":[[0,1.24,4.3],[1,1.25,21.79],[2,1.27,1727.32]],"ltp":1.26,"tv":18802.74,"id":20955040},{"batb":[[0,5,3.45],[1,4.9,30.6],[2,4.8,15.3]],"batl":[[0,5.3,5.1],[1,5.7,178.43],[2,6,2.01]],"ltp":4.4,"tv":3353.92,"id":9625551}]}]}
{"op":"mcm","clk":"4234834605","pt":1631550400759,"mc":[{"id":"1.187562121","rc":[{"batb":[[1,1.19,8.4],[2,1.18,204.83]],"ltp":1.26,"tv":18802.74,"id":20955040},{"batb":[[1,4.9,26.84],[2,4.8,3.06]],"batl":[[1,5.6,26.8],[2,5.7,191.83]],"ltp":4.4,"tv":3353.92,"id":9625551}]}]}
{"op":"mcm","clk":"4234834629","pt":1631550401067,"mc":[{"id":"1.187562121","rc":[{"batl":[[1,5.6,5.36],[2,5.7,181.11]],"ltp":4.4,"tv":3353.92,"id":9625551}]}]}
{"op":"mcm","clk":"4234834945","pt":1631550404731,"mc":[{"id":"1.187562121","rc":[{"batl":[[1,1.25,262.39]],"ltp":1.26,"tv":18802.74,"id":20955040},{"batl":[[1,5.6,14.16]],"ltp":4.4,"tv":3353.92,"id":9625551}]}]}
{"op":"mcm","clk":"4234835024","pt":1631550405470,"mc":[{"id":"1.187562121","rc":[{"batl":[[0,1.25,21.79],[1,1.27,1727.32],[2,1.28,46.16]],"ltp":1.26,"tv":18802.74,"id":20955040},{"batl":[[1,5.6,5.36]],"ltp":4.4,"tv":3353.92,"id":9625551}]}]}
{"op":"mcm","clk":"4234835206","pt":1631550407245,"mc":[{"id":"1.187562121","rc":[{"batb":[[0,1.22,121.84],[1,1.21,112.69],[2,1.2,125.52]],"batl":[[0,1.25,110.13],[1,1.26,85.75],[2,1.27,1727.32]],"ltp":1.26,"tv":18802.74,"id":20955040},{"batb":[[0,5,5.74],[2,4.8,5.34]],"batl":[[1,5.6,7.37]],"ltp":4.4,"tv":3353.92,"id":9625551}]}]}
{"op":"mcm","clk":"4234835679","pt":1631550412484,"mc":[{"id":"1.187562121","rc":[{"batb":[[0,1.21,112.69],[1,1.16,221.95],[2,1.01,107.79]],"batl":[[0,3.8,27.43],[1,8.8,7.22],[2,44,7.22]],"ltp":1.26,"tv":18802.74,"id":20955040},{"batb":[[0,4.8,2.28],[1,4.5,25.5],[2,1.46,3.41]],"batl":[[0,5.8,2.02],[1,990,0.01],[2,5.7,0]],"ltp":4.4,"tv":3353.92,"id":9625551}]}]}
{"op":"mcm","clk":"4234835945","pt":1631550415551,"mc":[{"id":"1.187562121","rc":[{"batb":[[0,1.22,117.84],[1,1.21,112.69],[2,1.16,221.95]],"batl":[[0,1.25,98.98],[1,1.26,102.75],[2,3.8,27.43]],"ltp":1.26,"tv":18802.74,"id":20955040},{"batb":[[0,5,2.18],[1,4.8,2.28],[2,4.5,25.5]],"batl":[[0,5.6,2.11],[1,5.8,2.02],[2,990,0.01]],"ltp":4.4,"tv":3353.92,"id":9625551}]}]}
{"op":"mcm","clk":"4234835974","pt":1631550415919,"mc":[{"id":"1.187562121","rc":[{"trd":[[1.2,205],[1.21,332.18],[1.22,1657.23]],"batb":[[0,1.16,221.95],[1,1.01,107.79],[2,1.16,0]],"batl":[[0,1.2,579.43]],"ltp":1.2,"tv":19283.17,"id":20955040},{"trd":[[5.6,5.93],[5.8,2.02]],"batb":[[0,4.8,2.28],[1,4.5,25.5],[2,1.46,3.41]],"batl":[[0,990,0.01],[1,5.8,0],[2,990,0]],"ltp":5.8,"tv":3358.05,"id":9625551}],"tv":22641.22}]}
{"op":"mcm","clk":"4234836250","pt":1631550418754,"mc":[{"id":"1.187562121","rc":[{"trd":[[1.2,784.43]],"batb":[[0,1.2,634.06],[1,1.16,221.95],[2,1.01,107.79]],"batl":[[0,1.24,764.09]],"ltp":1.2,"tv":19862.6,"id":20955040},{"trd":[[6,143.1]],"batb":[[0,5.1,39.22],[1,5,30],[2,4.9,15]],"batl":[[0,6,17.01],[1,990,0.01]],"ltp":6.0,"tv":3474.01,"id":9625551}],"tv":23336.61}]}
{"op":"mcm","clk":"4234836350","pt":1631550419753,"mc":[{"id":"1.187562121","rc":[{"batb":[[1,1.18,8.47],[2,1.16,272.89]],"batl":[[1,1.26,149.65],[2,1.28,23.08]],"ltp":1.2,"tv":19862.6,"id":20955040},{"batb":[[0,5.1,41.82],[1,5,18],[2,4.9,9]],"batl":[[0,5.7,26.32],[1,5.8,13.16],[2,5.9,13.16]],"ltp":6.0,"tv":3474.01,"id":9625551}]}]}
{"op":"mcm","clk":"4234836383","pt":1631550420159,"mc":[{"id":"1.187562121","rc":[{"trd":[[1.21,352.52]],"ltp":1.21,"tv":19882.94,"id":20955040},{"trd":[[5.7,11.13]],"batl":[[0,5.7,2.63],[1,5.8,2.64],[2,5.9,2.64]],"ltp":5.7,"tv":3478.33,"id":9625551}],"tv":23361.27}]}
{"op":"mcm","clk":"4234836639","pt":1631550423679,"mc":[{"id":"1.187562121","rc":[{"batl":[[0,1.24,1004.24]],"ltp":1.21,"tv":19882.94,"id":20955040},{"batl":[[1,5.8,12.42]],"ltp":5.7,"tv":3478.33,"id":9625551}]}]}
{"op":"mcm","clk":"4234836659","pt":1631550423990,"mc":[{"id":"1.187562121","rc":[{"batl":[[0,1.24,764.09]],"ltp":1.21,"tv":19882.94,"id":20955040},{"batl":[[1,5.8,2.64]],"ltp":5.7,"tv":3478.33,"id":9625551}]}]}
{"op":"mcm","clk":"4234837079","pt":1631550428984,"mc":[{"id":"1.187562121","rc":[{"batl":[[0,1.24,738.44]],"ltp":1.21,"tv":19882.94,"id":20955040}]}]}
{"op":"mcm","clk":"4234837330","pt":1631550431875,"mc":[{"id":"1.187562121","rc":[{"trd":[[1.24,835.58]],"batl":[[0,1.23,26.64]],"ltp":1.24,"tv":20625.89,"id":20955040},{"trd":[[5,241.47],[5.1,291.52]],"batb":[[0,5,14.38],[1,4.9,9],[2,4.8,11.28]],"batl":[[0,5.7,8.87]],"ltp":5.0,"tv":3747.52,"id":9625551}],"tv":24373.41}]}
{"op":"mcm","clk":"4234837797","pt":1631550437690,"mc":[{"id":"1.187562121","rc":[{"trd":[[1.21,372.02],[1.23,177.67]],"batl":[[0,1.23,19.42]],"ltp":1.23,"tv":20659.83,"id":20955040},{"trd":[[5.7,15.27]],"batl":[[0,5.7,4.73]],"ltp":5.7,"tv":3751.66,"id":9625551}],"tv":24411.49}]}
{"op":"mcm","clk":"4234837943","pt":1631550439180,"mc":[{"id":"1.187562121","rc":[{"trd":[[5.7,15.61]],"batl":[[0,5.7,4.56]],"ltp":5.7,"tv":3751.99,"id":9625551}],"tv":24411.83}]}
{"op":"mcm","clk":"4234838741","pt":1631550447724,"mc":[{"id":"1.187562121","rc":[{"batl":[[0,1.26,149.65],[1,1.28,23.08],[2,1.3,89.35]],"ltp":1.23,"tv":20659.83,"id":20955040},{"batl":[[0,5.8,2.64],[1,5.9,2.64],[2,6,17.01]],"ltp":5.7,"tv":3751.99,"id":9625551}]}]}
{"op":"mcm","clk":"4234838934","pt":1631550449515,"mc":[{"id":"1.187562121","rc":[{"batb":[[0,1.09,380.23],[1,1.01,107.79],[2,1.16,0]],"batl":[[0,3.8,27.43],[1,8.8,7.22],[2,44,7.22]],"ltp":1.23,"tv":20659.83,"id":20955040},{"batb":[[0,4.2,29.19],[1,4,2.93],[2,1.46,3.41]],"batl":[[0,990,0.01],[1,5.9,0],[2,6,0]],"ltp":5.7,"tv":3751.99,"id":9625551}]}]}
{"op":"mcm","clk":"4234839094","pt":1631550451001,"mc":[{"id":"1.187562121","rc":[{"batl":[[0,990,0.46]],"ltp":5.7,"tv":3751.99,"id":9625551}]}]}
{"op":"mcm","clk":"4234839250","pt":1631550452720,"mc":[{"id":"1.187562121","rc":[{"batb":[[0,1.1,372.43]],"batl":[[0,1.33,75.5],[1,3.8,27.43],[2,8.8,7.22]],"ltp":1.23,"tv":20659.83,"id":20955040}]}]}
{"op":"mcm","clk":"4234839456","pt":1631550454990,"mc":[{"id":"1.187562121","rc":[{"trd":[[1.32,75.76]],"ltp":1.32,"tv":20678.47,"id":20955040},{"trd":[[4.2,41.64]],"batb":[[0,4.2,23.33]],"ltp":4.2,"tv":3757.85,"id":9625551}],"tv":24436.32}]}
{"op":"mcm","clk":"4234839552","pt":1631550456193,"mc":[{"id":"1.187562121","rc":[{"batl":[[0,990,0.01]],"ltp":4.2,"tv":3757.85,"id":9625551}]}]}
{"op":"mcm","clk":"4234839907","pt":1631550460312,"mc":[{"id":"1.187562121","rc":[{"batl":[[0,1.33,76.27]],"ltp":1.32,"tv":20678.47,"id":20955040}]}]}
{"op":"mcm","clk":"4234840279","pt":1631550464743,"mc":[{"id":"1.187562121","rc":[{"batl":[[0,1.23,43.27],[1,1.33,75.5],[2,3.8,27.43]],"ltp":1.32,"tv":20678.47,"id":20955040},{"batb":[[0,5.5,39.92],[1,4.2,23.33],[2,4,2.93]],"batl":[[0,6.2,36.93],[1,990,0.01]],"ltp":4.2,"tv":3757.85,"id":9625551}]}]}
{"op":"mcm","clk":"4234840304","pt":1631550465012,"mc":[{"id":"1.187562121","rc":[{"batl":[[0,1.33,76.27],[1,3.8,27.43],[2,8.8,7.22]],"ltp":1.32,"tv":20678.47,"id":20955040},{"batb":[[0,4.2,23.33],[1,4,2.93],[2,1.46,3.41]],"batl":[[0,990,0.01],[1,990,0]],"ltp":4.2,"tv":3757.85,"id":9625551}]}]}
{"op":"mcm","clk":"4234841101","pt":1631550474623,"mc":[{"id":"1.187562121","rc":[{"trd":[[1.23,178.45]],"batb":[[0,1.28,21.37],[1,1.24,8.06],[2,1.1,372.43]],"batl":[[0,1.3,25.17],[1,1.33,75.5],[2,3.8,27.43]],"ltp":1.23,"tv":20679.24,"id":20955040},{"trd":[[5.3,54.02]],"batb":[[1,4.1,215.1],[2,4,2.93]],"batl":[[0,4.7,31.92],[1,4.8,331.51],[2,4.9,15.96]],"ltp":5.3,"tv":3758.03,"id":9625551}],"tv":24437.28}]}
{"op":"mcm","clk":"4234841205","pt":1631550475735,"mc":[{"id":"1.187562121","rc":[{"batb":[[2,1.23,158.62]],"batl":[[0,1.3,32.86],[1,1.33,119.93],[2,1.35,21.88]],"ltp":1.23,"tv":20679.24,"id":20955040},{"batb":[[0,4.2,59.05],[1,4.1,232.96],[2,4,20.79]],"batl":[[0,4.7,19.15],[1,4.8,308.47],[2,4.9,9.58]],"ltp":5.3,"tv":3758.03,"id":9625551}]}]}
{"op":"mcm","clk":"4234841233","pt":1631550476042,"mc":[{"id":"1.187562121","rc":[{"batb":[[0,4.2,30.47],[1,4.1,218.68],[2,4,6.51]],"batl":[[0,4.7,6.38],[1,4.8,302.09],[2,4.9,3.2]],"ltp":5.3,"tv":3758.03,"id":9625551}]}]}
{"op":"mcm","clk":"4234842332","pt":1631550488766,"mc":[{"id":"1.187562121","rc":[{"batb":[[0,1.22,48.43],[1,1.2,24.62],[2,1.17,211.88]],"batl":[[0,1.33,44.43],[1,1.35,21.88],[2,1.5,53.43]],"ltp":1.23,"tv":20679.24,"id":20955040},{"batb":[[0,3.3,28.1],[1,3,5],[2,1.46,3.41]],"batl":[[0,990,0.01],[1,4.8,0],[2,4.9,0]],"ltp":5.3,"tv":3758.03,"id":9625551}]}]}
{"op":"mcm","clk":"4234842361","pt":1631550488973,"mc":[{"id":"1.187562121","rc":[{"batb":[[0,1.17,211.88],[1,1.01,107.79],[2,1.17,0]],"batl":[[0,1.5,53.43],[1,3.8,27.43],[2,8.8,7.22]],"ltp":1.23,"tv":20679.24,"id":20955040}]}]}
{"op":"mcm","clk":"4234842763","pt":1631550492767,"mc":[{"id":"1.187562121","rc":[{"batb":[[0,3.25,28.44]],"ltp":5.3,"tv":3758.03,"id":9625551}]}]}
{"op":"mcm","clk":"4234842890","pt":1631550493980,"mc":[{"id":"1.187562121","rc":[{"batl":[[0,1.5,54.33]],"ltp":1.23,"tv":20679.24,"id":20955040}]}]}
{"op":"mcm","clk":"4234843069","pt":1631550495566,"mc":[{"id":"1.187562121","rc":[{"batl":[[0,1.45,57.8],[1,1.5,53.43],[2,3.8,27.43]],"ltp":1.23,"tv":20679.24,"id":20955040},{"batb":[[1,3.2,3.57],[2,3,5]],"ltp":5.3,"tv":3758.03,"id":9625551}]}]}
{"op":"mcm","clk":"4234843111","pt":1631550495972,"mc":[{"id":"1.187562121","rc":[{"batl":[[0,1.5,54.33],[1,3.8,27.43],[2,8.8,7.22]],"ltp":1.23,"tv":20679.24,"id":20955040},{"batb":[[1,3,5],[2,1.46,3.41]],"ltp":5.3,"tv":3758.03,"id":9625551}]}]}
{"op":"mcm","clk":"4234843201","pt":1631550497083,"mc":[{"id":"1.187562121","rc":[{"batl":[[0,1.5,53.43]],"ltp":1.23,"tv":20679.24,"id":20955040}]}]}
{"op":"mcm","clk":"4234843421","pt":1631550499771,"mc":[{"id":"1.187562121","rc":[{"batb":[[0,1.2,693.33],[1,1.17,262.38],[2,1.15,25.69]],"batl":[[0,1.23,18.63],[1,1.24,84.23],[2,1.25,8]],"ltp":1.23,"tv":20679.24,"id":20955040},{"batb":[[0,5.1,6.74],[1,5,6],[2,4.9,3]],"batl":[[0,5.7,8.06],[1,6,138.67],[2,990,0.01]],"ltp":5.3,"tv":3758.03,"id":9625551}]}]}
{"op":"mcm","clk":"4234843515","pt":1631550500667,"mc":[{"id":"1.187562121","rc":[{"batb":[[1,1.18,8.47],[2,1.17,262.38]],"ltp":1.23,"tv":20679.24,"id":20955040},{"batb":[[1,5,25.46]],"batl":[[0,5.7,13.32],[1,5.8,2.64],[2,5.9,2.64]],"ltp":5.3,"tv":3758.03,"id":9625551}]}]}
{"op":"mcm","clk":"4234843579","pt":1631550501393,"mc":[{"id":"1.187562121","rc":[{"trd":[[1.23,197.08],[1.24,919.81],[1.25,336.54],[1.26,361.22]],"batl":[[0,1.26,1067.42],[1,1.27,46.53],[2,1.29,22.9]],"ltp":1.26,"tv":21070.66,"id":20955040},{"trd":[[4.8,106.44],[4.9,33.6],[5,294.39],[5.1,325.48],[5.3,58.34]],"batb":[[0,3.7,42.02],[1,3,5],[2,1.46,3.41]],"ltp":4.8,"tv":3934.88,"id":9625551}],"tv":25005.54}]}
{"op":"mcm","clk":"4234844053","pt":1631550506279,"mc":[{"id":"1.187562121","rc":[{"batb":[[2,1.17,414.35]],"ltp":1.26,"tv":21070.66,"id":20955040},{"batb":[[1,3.55,2.99],[2,3.25,3.57]],"ltp":4.8,"tv":3934.88,"id":9625551}]}]}
{"op":"mcm","clk":"4234844449","pt":1631550510700,"mc":[{"id":"1.187562121","rc":[{"batb":[[0,1.17,151.97],[1,1.15,149.23],[2,1.12,301.46]],"batl":[[0,1.39,75.5],[1,1.44,60.58],[2,1.5,53.43]],"ltp":1.26,"tv":21070.66,"id":20955040},{"batl":[[0,7,2],[1,7.8,2],[2,990,0.01]],"ltp":4.8,"tv":3934.88,"id":9625551}]}]}
{"op":"mcm","clk":"4234844481","pt":1631550511010,"mc":[{"id":"1.187562121","rc":[{"batb":[[0,1.15,149.23],[1,1.12,301.46],[2,1.01,107.79]],"ltp":1.26,"tv":21070.66,"id":20955040},{"batl":[[0,7.8,2],[1,990,0.01],[2,990,0]],"ltp":4.8,"tv":3934.88,"id":9625551}]}]}
{"op":"mcm","clk":"4234844714","pt":1631550513905,"mc":[{"id":"1.187562121","rc":[{"batb":[[1,3.65,43.45],[2,3.55,2.99]],"ltp":4.8,"tv":3934.88,"id":9625551}]}]}
{"op":"mcm","clk":"4234844782","pt":1631550514591,"mc":[{"id":"1.187562121","rc":[{"batb":[[1,1.12,294.92]],"ltp":1.26,"tv":21070.66,"id":20955040},{"batb":[[0,3.65,43.45],[1,3.55,2.99],[2,3.25,3.57]],"ltp":4.8,"tv":3934.88,"id":9625551}]}]}
{"op":"mcm","clk":"4234844866","pt":1631550515491,"mc":[{"id":"1.187562121","rc":[{"batb":[[0,1.15,149.73]],"ltp":1.26,"tv":21070.66,"id":20955040},{"batl":[[0,7.8,2.45]],"ltp":4.8,"tv":3934.88,"id":9625551}]}]}
{"op":"mcm","clk":"4234845002","pt":1631550516689,"mc":[{"id":"1.187562121","rc":[{"trd":[[1.26,363.93]],"batb":[[0,1.15,149.23]],"ltp":1.26,"tv":21073.37,"id":20955040},{"trd":[[4.8,106.89]],"batl":[[0,7.8,2]],"ltp":4.8,"tv":3935.33,"id":9625551}],"tv":25008.7}]}
{"op":"mcm","clk":"4234845113","pt":1631550517793,"mc":[{"id":"1.187562121","rc":[{"batb":[[0,1.17,145.97],[1,1.15,149.23],[2,1.12,294.92]],"ltp":1.26,"tv":21073.37,"id":20955040},{"batl":[[0,7,2],[1,7.8,2],[2,990,0.01]],"ltp":4.8,"tv":3935.33,"id":9625551}]}]}
{"op":"mcm","clk":"4234845213","pt":1631550518897,"mc":[{"id":"1.187562121","rc":[{"batb":[[0,1.19,222],[1,1.16,222],[2,1.15,149.23]],"ltp":1.26,"tv":21073.37,"id":20955040},{"batl":[[0,7.8,2],[1,990,0.01],[2,990,0]],"ltp":4.8,"tv":3935.33,"id":9625551}]}]}
{"op":"mcm","clk":"4234845335","pt":1631550520511,"mc":[{"id":"1.187562121","rc":[{"batl":[[0,1.35,222],[1,1.39,75.5],[2,1.44,60.58]],"ltp":1.26,"tv":21073.37,"id":20955040}]}]}
{"op":"mcm","clk":"4234845409","pt":1631550521502,"mc":[{"id":"1.187562121","rc":[{"batb":[[1,1.17,144.97],[2,1.16,222]],"ltp":1.26,"tv":21073.37,"id":20955040},{"batl":[[0,7,2],[1,7.8,2],[2,990,0.01]],"ltp":4.8,"tv":3935.33,"id":9625551}]}]}
{"op":"mcm","clk":"4234845727","pt":1631550525418,"mc":[{"id":"1.187562121","rc":[{"batb":[[1,1.16,222],[2,1.15,149.23]],"batl":[[2,3.8,27.43]],"ltp":1.26,"tv":21073.37,"id":20955040},{"batl":[[0,7.8,2],[1,990,0.01],[2,990,0]],"ltp":4.8,"tv":3935.33,"id":9625551}]}]}
{"op":"mcm","clk":"4234845793","pt":1631550526204,"mc":[{"id":"1.187562121","rc":[{"batb":[[0,1.15,149.23],[1,1.12,294.92],[2,1.01,107.79]],"ltp":1.26,"tv":21073.37,"id":20955040}]}]}
{"op":"mcm","clk":"4234845958","pt":1631550528291,"mc":[{"id":"1.187562121","rc":[{"batb":[[0,1.15,1281.26],[2,1.11,53.23]],"batl":[[0,1.18,66.13],[1,1.19,8.4],[2,1.21,48.84]],"ltp":1.26,"tv":21073.37,"id":20955040},{"batb":[[0,6.4,2],[1,6.2,4.84],[2,6,2.42]],"batl":[[0,7.2,5.61],[1,7.8,2],[2,990,0.01]],"ltp":4.8,"tv":3935.33,"id":9625551}]}]}
{"op":"mcm","clk":"4234846049","pt":1631550529285,"mc":[{"id":"1.187562121","rc":[{"batb":[[1,1.13,8.85],[2,1.12,294.92]],"ltp":1.26,"tv":21073.37,"id":20955040},{"batb":[[2,6,26.16]],"batl":[[0,7.2,9.77],[1,7.4,2.08],[2,7.6,2.08]],"ltp":4.8,"tv":3935.33,"id":9625551}]}]}
{"op":"mcm","clk":"4234846429","pt":1631550533693,"mc":[{"id":"1.187562121","rc":[{"batl":[[0,1.18,288.13],[2,1.21,270.84]],"ltp":1.26,"tv":21073.37,"id":20955040}]}]}
{"op":"mcm","clk":"4234847001","pt":1631550539312,"mc":[{"id":"1.187562121","rc":[{"trd":[[1.18,302.65]],"batl":[[0,1.18,287.23]],"ltp":1.18,"tv":21075.17,"id":20955040}],"tv":25010.5}]}
{"op":"mcm","clk":"4234847295","pt":1631550542833,"mc":[{"id":"1.187562121","rc":[{"trd":[[1.18,303.55]],"batl":[[0,1.18,286.78]],"ltp":1.18,"tv":21076.07,"id":20955040}],"tv":25011.4}]}
{"op":"mcm","clk":"4234847333","pt":1631550543416,"mc":[{"id":"1.187562121","rc":[{"trd":[[1.18,318.63]],"batl":[[0,1.18,276.21]],"ltp":1.18,"tv":21091.15,"id":20955040},{"trd":[[6.4,8.11]],"batb":[[0,6.2,4.84],[1,6,26.16],[2,5.9,2.42]],"ltp":6.4,"tv":3940.44,"id":9625551}],"tv":25031.6}]}
{"op":"mcm","clk":"4234847408","pt":1631550544347,"mc":[{"id":"1.187562121","rc":[{"trd":[[1.18,330.83]],"batl":[[0,1.18,264.01]],"ltp":1.18,"tv":21103.35,"id":20955040},{"trd":[[6.4,10.36]],"ltp":6.4,"tv":3942.69,"id":9625551}],"tv":25046.05}]}
{"op":"mcm","clk":"4234847502","pt":1631550545552,"mc":[{"id":"1.187562121","rc":[{"trd":[[1.18,336.25]],"batl":[[0,1.18,261.3],[2,1.21,222]],"ltp":1.18,"tv":21108.77,"id":20955040}],"tv":25051.47}]}
{"op":"mcm","clk":"4234847601","pt":1631550546868,"mc":[{"id":"1.187562121","rc":[{"batb":[[0,1.15,149.23],[1,1.12,294.92],[2,1.09,277.61]],"batl":[[0,1.18,242.25],[1,1.21,222],[2,1.23,108.5]],"ltp":1.18,"tv":21108.77,"id":20955040},{"batb":[[0,6,23.74],[1,5.3,2.08],[2,5,2.14]],"batl":[[0,7.8,2],[1,12.5,2],[2,18,2]],"ltp":6.4,"tv":3942.69,"id":9625551}]}]}
{"op":"mcm","clk":"4234847688","pt":1631550547777,"mc":[{"id":"1.187562121","rc":[{"batb":[[0,1.06,392.58],[1,1.05,601.5],[2,1.01,107.79]],"batl":[[0,1.18,222]],"ltp":1.18,"tv":21108.77,"id":20955040},{"batb":[[0,5.3,2.08],[1,5,2.14],[2,4.9,20.55]],"batl":[[0,18,2],[1,990,0.01],[2,18,0]],"ltp":6.4,"tv":3942.69,"id":9625551}]}]}
{"op":"mcm","clk":"4234847970","pt":1631550550897,"mc":[{"id":"1.187562121","rc":[{"trd":[[1.18,346.17]],"batl":[[0,1.18,217.04]],"ltp":1.18,"tv":21118.69,"id":20955040}],"tv":25061.39}]}
{"op":"mcm","clk":"4234848508","pt":1631550556453,"mc":[{"id":"1.187562121","rc":[{"batb":[[0,1.1,222],[1,1.06,392.58],[2,1.05,601.5]],"ltp":1.18,"tv":21118.69,"id":20955040}]}]}
{"op":"mcm","clk":"4234848657","pt":1631550557875,"mc":[{"id":"1.187562121","rc":[{"batb":[[1,1.09,276.61],[2,1.07,550.07]],"ltp":1.18,"tv":21118.69,"id":20955040},{"batl":[[0,12.5,2],[1,18,2],[2,990,0.01]],"ltp":6.4,"tv":3942.69,"id":9625551}]}]}
{"op":"mcm","clk":"4234849154","pt":1631550562881,"mc":[{"id":"1.187562121","rc":[{"batb":[[0,1.09,276.61],[1,1.07,328.07],[2,1.06,392.58]],"ltp":1.18,"tv":21118.69,"id":20955040}]}]}
{"op":"mcm","clk":"4234849217","pt":1631550563517,"mc":[{"id":"1.187562121","rc":[{"batb":[[0,1.12,56.28],[1,1.09,276.61],[2,1.07,328.07]],"ltp":1.18,"tv":21118.69,"id":20955040}]}]}
{"op":"mcm","clk":"4234849355","pt":1631550564780,"mc":[{"id":"1.187562121","rc":[{"batb":[[0,1.09,276.61],[1,1.08,50.18],[2,1.07,2587.37]],"batl":[[0,1.1,37.58],[1,1.11,5910.44],[2,1.13,22.51]],"ltp":1.18,"tv":21118.69,"id":20955040},{"batb":[[0,11,3.76],[1,10.5,14.28],[2,10,7.14]],"batl":[[1,13.5,4.01],[2,18,2]],"ltp":6.4,"tv":3942.69,"id":9625551}]}]}
{"op":"mcm","clk":"4234849459","pt":1631550565834,"mc":[{"id":"1.187562121","rc":[{"batb":[[1,1.08,189.06],[2,1.07,2656.81]],"batl":[[1,1.11,2160.44],[2,1.13,52.29]],"ltp":1.18,"tv":21118.69,"id":20955040},{"batb":[[1,10.5,2.86],[2,10,1.42]],"ltp":6.4,"tv":3942.69,"id":9625551}]}]}
{"op":"mcm","clk":"4234849513","pt":1631550566309,"mc":[{"id":"1.187562121","rc":[{"batb":[[1,1.08,77.96],[2,1.07,2601.25]],"ltp":1.18,"tv":21118.69,"id":20955040}]}]}
{"op":"mcm","clk":"4234849831","pt":1631550569815,"mc":[{"id":"1.187562121","rc":[{"batb":[[0,1.09,498.61],[1,1.08,299.96]],"batl":[[1,1.11,2628.14]],"ltp":1.18,"tv":21118.69,"id":20955040},{"batl":[[0,12.5,6.49]],"ltp":6.4,"tv":3942.69,"id":9625551}]}]}
{"op":"mcm","clk":"4234849850","pt":1631550570027,"mc":[{"id":"1.187562121","rc":[{"batl":[[1,1.11,2170.86]],"ltp":1.18,"tv":21118.69,"id":20955040},{"batl":[[0,12.5,2]],"ltp":6.4,"tv":3942.69,"id":9625551}]}]}
{"op":"mcm","clk":"4234850132","pt":1631550573000,"mc":[{"id":"1.187562121","rc":[{"batl":[[1,1.11,2160.44]],"ltp":1.18,"tv":21118.69,"id":20955040}]}]}
{"op":"mcm","clk":"4234850506","pt":1631550577822,"mc":[{"id":"1.187562121","rc":[{"batl":[[1,1.11,2151.43]],"ltp":1.18,"tv":21118.69,"id":20955040}]}]}
{"op":"mcm","clk":"4234850604","pt":1631550578762,"mc":[{"id":"1.187562121","rc":[{"batb":[[0,1.09,222],[1,1.08,222],[2,1.02,1331.05]],"batl":[[0,1.15,6.1],[1,1.16,166.44],[2,1.18,217.04]],"ltp":1.18,"tv":21118.69,"id":20955040},{"batb":[[0,7.4,14.34],[1,7.2,4.92],[2,5.3,2.08]],"batl":[[0,55,2],[1,990,0.01],[2,18,0]],"ltp":6.4,"tv":3942.69,"id":9625551}]}]}
{"op":"mcm","clk":"4234850633","pt":1631550579027,"mc":[{"id":"1.187562121","rc":[{"batl":[[0,1.16,166.44],[1,1.18,217.04],[2,1.21,222]],"ltp":1.18,"tv":21118.69,"id":20955040}]}]}
{"op":"mcm","clk":"4234850898","pt":1631550581607,"mc":[{"id":"1.187562121","rc":[{"batb":[[0,7.6,13.5]],"ltp":6.4,"tv":3942.69,"id":9625551}]}]}
{"op":"mcm","clk":"4234851107","pt":1631550583712,"mc":[{"id":"1.187562121","rc":[{"trd":[[1.09,47.66]],"batb":[[0,1.09,198.16]],"batl":[[0,1.15,56.28],[1,1.16,166.44],[2,1.18,217.04]],"ltp":1.09,"tv":21166.36,"id":20955040}],"tv":25109.05}]}
{"op":"mcm","clk":"4234851162","pt":1631550584233,"mc":[{"id":"1.187562121","rc":[{"trd":[[1.09,47.8]],"batb":[[0,1.09,198.09]],"ltp":1.09,"tv":21166.49,"id":20955040}],"tv":25109.19}]}
{"op":"mcm","clk":"4234851303","pt":1631550585710,"mc":[{"id":"1.187562121","rc":[{"batb":[[0,1.01,107.79],[1,1.08,0],[2,1.02,0]],"batl":[[0,1.15,62.78]],"ltp":1.09,"tv":21166.49,"id":20955040},{"batl":[[0,990,0.01],[1,990,0]],"ltp":6.4,"tv":3942.69,"id":9625551}]}]}
{"op":"mcm","clk":"4234851401","pt":1631550586705,"mc":[{"id":"1.187562121","rc":[{"batl":[[0,1.15,56.28]],"ltp":1.09,"tv":21166.49,"id":20955040}]}]}
{"op":"mcm","clk":"4234851608","pt":1631550588899,"mc":[{"id":"1.187562121","rc":[{"batb":[[0,1.01,2618.02]],"batl":[[0,1.14,186.5],[1,1.15,215.38],[2,1.16,166.44]],"ltp":1.09,"tv":21166.49,"id":20955040},{"batb":[[0,8,4.7],[1,7.6,13.5],[2,7.4,5.01]],"batl":[[0,60,2],[1,65,2],[2,990,0.01]],"ltp":6.4,"tv":3942.69,"id":9625551}]}]}
{"op":"mcm","clk":"4234851672","pt":1631550589528,"mc":[{"id":"1.187562121","rc":[{"batl":[[0,1.15,56.28],[1,1.16,166.44],[2,1.18,217.04]],"ltp":1.09,"tv":21166.49,"id":20955040},{"batb":[[0,7.6,13.5],[1,7.2,4.92],[2,5.3,2.08]],"batl":[[0,990,0.01],[1,65,0],[2,990,0]],"ltp":6.4,"tv":3942.69,"id":9625551}]}]}
{"op":"mcm","clk":"4234851786","pt":1631550590730,"mc":[{"id":"1.187562121","rc":[{"batb":[[0,1.02,56.28],[1,1.01,2618.02]],"batl":[[0,1.14,17.72],[1,1.15,56.28],[2,1.16,166.44]],"ltp":1.09,"tv":21166.49,"id":20955040}]}]}
{"op":"mcm","clk":"4234851850","pt":1631550591307,"mc":[{"id":"1.187562121","rc":[{"batb":[[0,1.02,112.55]],"ltp":1.09,"tv":21166.49,"id":20955040}]}]}
{"op":"mcm","clk":"4234851999","pt":1631550592721,"mc":[{"id":"1.187562121","rc":[{"batb":[[0,1.03,56.28],[1,1.02,1340.25],[2,1.01,2618.02]],"batl":[[0,1.04,31.38],[1,1.05,1617.07],[2,1.06,9.43]],"ltp":1.09,"tv":21166.49,"id":20955040},{"batb":[[0,21,82.57],[1,20,1.5],[2,13.5,14.82]],"batl":[[0,34,5.44],[1,50,184.79],[2,55,2]],"ltp":6.4,"tv":3942.69,"id":9625551}]}]}
{"op":"mcm","clk":"4234852077","pt":1631550593457,"mc":[{"id":"1.187562121","rc":[{"batb":[[1,1.02,1350.05]],"ltp":1.09,"tv":21166.49,"id":20955040},{"batb":[[2,17.5,6.54]],"batl":[[0,34,6.32]],"ltp":6.4,"tv":3942.69,"id":9625551}]}]}
{"op":"mcm","clk":"4234852214","pt":1631550594762,"mc":[{"id":"1.187562121","rc":[{"batb":[[0,1.03,278.28],[1,1.02,1572.05]],"ltp":1.09,"tv":21166.49,"id":20955040}]}]}
{"op":"mcm","clk":"4234852517","pt":1631550597850,"mc":[{"id":"1.187562121","rc":[{"batl":[[2,1.06,20]],"ltp":1.09,"tv":21166.49,"id":20955040}]}]}
{"op":"mcm","clk":"4234852618","pt":1631550598844,"mc":[{"id":"1.187562121","rc":[{"batb":[[2,1.01,2730.57]],"ltp":1.09,"tv":21166.49,"id":20955040}]}]}
{"op":"mcm","clk":"4234852834","pt":1631550600749,"mc":[{"id":"1.187562121","rc":[{"batl":[[2,1.06,76.28]],"ltp":1.09,"tv":21166.49,"id":20955040}]}]}
{"op":"mcm","clk":"4234853092","pt":1631550602882,"mc":[{"id":"1.187562121","rc":[{"batb":[[0,1.03,500.28]],"batl":[[0,1.04,253.38]],"ltp":1.09,"tv":21166.49,"id":20955040}]}]}
{"op":"mcm","clk":"4234853183","pt":1631550603471,"mc":[{"id":"1.187562121","rc":[{"batl":[[0,1.04,475.38]],"ltp":1.09,"tv":21166.49,"id":20955040}]}]}
{"op":"mcm","clk":"4234853627","pt":1631550606746,"mc":[{"id":"1.187562121","rc":[{"trd":[[1.03,199.98],[1.04,2.78]],"batb":[[0,1.03,400.3]],"batl":[[0,1.04,473.99]],"ltp":1.04,"tv":21369.24,"id":20955040}],"tv":25311.94}]}
{"op":"mcm","clk":"4234853736","pt":1631550607951,"mc":[{"id":"1.187562121","rc":[{"trd":[[1.04,11.8]],"batl":[[0,1.04,469.48]],"ltp":1.04,"tv":21378.26,"id":20955040}],"tv":25320.96}]}
{"op":"mcm","clk":"4234854455","pt":1631550614865,"mc":[{"id":"1.187562121","rc":[{"batb":[[1,1.02,1562.25]],"batl":[[0,1.04,444],[1,1.05,5.7],[2,1.06,66.85]],"ltp":1.04,"tv":21378.26,"id":20955040},{"batb":[[0,21,2],[1,17.5,7.29],[2,13.5,7.41]],"batl":[[0,55,2.44],[1,110,2],[2,990,0.01]],"ltp":6.4,"tv":3942.69,"id":9625551}]}]}
{"op":"mcm","clk":"4234854512","pt":1631550615493,"mc":[{"id":"1.187562121","rc":[{"batb":[[1,1.02,334.55]],"ltp":1.04,"tv":21378.26,"id":20955040},{"batb":[[1,12,4.08],[2,10.5,14.01]],"batl":[[0,110,2],[1,990,0.01],[2,990,0]],"ltp":6.4,"tv":3942.69,"id":9625551}]}]}
{"op":"mcm","clk":"4234854640","pt":1631550616750,"mc":[{"id":"1.187562121","rc":[{"batb":[[0,1.03,456.58]],"batl":[[0,1.05,5.7],[1,1.06,66.85],[2,1.08,56.28]],"ltp":1.04,"tv":21378.26,"id":20955040}]}]}
{"op":"mcm","clk":"4234854730","pt":1631550617691,"mc":[{"id":"1.187562121","rc":[{"batb":[[0,1.03,56.28],[1,1.02,112.55]],"ltp":1.04,"tv":21378.26,"id":20955040}]}]}
{"op":"mcm","clk":"4234854868","pt":1631550618894,"mc":[{"id":"1.187562121","rc":[{"batb":[[0,1.04,9.02],[1,1.03,56.28],[2,1.02,112.55]],"batl":[[1,1.06,56.28]],"ltp":1.04,"tv":21378.26,"id":20955040},{"batb":[[2,11,12.16]],"ltp":6.4,"tv":3942.69,"id":9625551}]}]}
{"op":"mcm","clk":"4234854940","pt":1631550619689,"mc":[{"id":"1.187562121","rc":[{"batl":[[0,1.06,56.28],[1,1.08,56.28],[2,1.09,377.55]],"ltp":1.04,"tv":21378.26,"id":20955040},{"batb":[[0,12,4.08],[1,11,12.16],[2,10,4.24]],"ltp":6.4,"tv":3942.69,"id":9625551}]}]}
{"op":"mcm","clk":"4234855448","pt":1631550624367,"mc":[{"id":"1.187562121","rc":[{"batl":[[0,1.05,947.31],[1,1.06,56.28],[2,1.08,56.28]],"ltp":1.04,"tv":21378.26,"id":20955040}]}]}
{"op":"mcm","clk":"4234855522","pt":1631550625108,"mc":[{"id":"1.187562121","rc":[{"batb":[[0,1.03,56.28],[1,1.02,112.55],[2,1.01,2730.57]],"ltp":1.04,"tv":21378.26,"id":20955040}]}]}
{"op":"mcm","clk":"4234855731","pt":1631550627095,"mc":[{"id":"1.187562121","rc":[{"trd":[[1.03,312.55]],"batb":[[0,1.02,112.55],[1,1.01,2730.57],[2,1.01,0]],"batl":[[0,1.03,243.7],[1,1.05,947.31],[2,1.06,56.28]],"ltp":1.03,"tv":21490.84,"id":20955040}],"tv":25433.53}]}
{"op":"mcm","clk":"4234855896","pt":1631550628571,"mc":[{"id":"1.187562121","rc":[{"trd":[[1.03,314.55]],"batl":[[0,1.03,242.7]],"ltp":1.03,"tv":21492.84,"id":20955040}],"tv":25435.53}]}
{"op":"mcm","clk":"4234856525","pt":1631550634718,"mc":[{"id":"1.187562121","rc":[{"batb":[[0,1.01,2730.57],[1,1.01,0]],"ltp":1.03,"tv":21492.84,"id":20955040}]}]}
{"op":"mcm","clk":"4234856671","pt":1631550636393,"mc":[{"id":"1.187562121","rc":[{"trd":[[1.03,315.33]],"batl":[[0,1.03,242.31]],"ltp":1.03,"tv":21493.61,"id":20955040}],"tv":25436.31}]}
{"op":"mcm","clk":"4234856773","pt":1631550637492,"mc":[{"id":"1.187562121","rc":[{"batl":[[0,1.02,155.36],[1,1.03,4682.53],[2,1.04,84.65]],"ltp":1.03,"tv":21493.61,"id":20955040},{"batb":[[0,32,2.82],[1,23,5.22],[2,12,4.08]],"batl":[[0,100,63.41],[1,110,2],[2,990,0.01]],"ltp":6.4,"tv":3942.69,"id":9625551}]}]}
{"op":"mcm","clk":"4234856849","pt":1631550638293,"mc":[{"id":"1.187562121","rc":[{"batb":[[1,27,3.66],[2,23,5.22]],"ltp":6.4,"tv":3942.69,"id":9625551}]}]}
{"op":"mcm","clk":"4234856926","pt":1631550639126,"mc":[{"id":"1.187562121","rc":[{"batl":[[0,1.02,219.3]],"ltp":1.03,"tv":21493.61,"id":20955040}]}]}
{"op":"mcm","clk":"4234857367","pt":1631550643892,"mc":[{"id":"1.187562121","rc":[{"batl":[[1,1.03,4440.22]],"ltp":1.03,"tv":21493.61,"id":20955040}]}]}
{"op":"mcm","clk":"4234857399","pt":1631550644205,"mc":[{"id":"1.187562121","rc":[{"trd":[[1.02,9.02]],"batl":[[0,1.02,214.79]],"ltp":1.02,"tv":21502.63,"id":20955040}],"tv":25445.33}]}
{"op":"mcm","clk":"4234857652","pt":1631550646933,"mc":[{"id":"1.187562121","rc":[{"batl":[[0,1.02,150.85]],"ltp":1.02,"tv":21502.63,"id":20955040}]}]}
{"op":"mcm","clk":"4234857817","pt":1631550648296,"mc":[{"id":"1.187562121","rc":[{"batl":[[0,1.02,305.85]],"ltp":1.02,"tv":21502.63,"id":20955040}]}]}
{"op":"mcm","clk":"4234858139","pt":1631550651497,"mc":[{"id":"1.187562121","rc":[{"trd":[[1.01,5.78]],"batb":[[0,1.01,2727.68]],"ltp":1.01,"tv":21508.41,"id":20955040}],"tv":25451.11}]}
{"op":"mcm","clk":"4234858254","pt":1631550652496,"mc":[{"id":"1.187562121","rc":[{"trd":[[1.01,771.78]],"batb":[[0,1.01,2344.68]],"ltp":1.01,"tv":22274.41,"id":20955040}],"tv":26217.11}]}
{"op":"mcm","clk":"4234858465","pt":1631550654322,"mc":[{"id":"1.187562121","rc":[{"batl":[[0,1.02,155]],"ltp":1.01,"tv":22274.41,"id":20955040},{"batl":[[0,100,58.29]],"ltp":6.4,"tv":3942.69,"id":9625551}]}]}
{"op":"mcm","clk":"4234858841","pt":1631550657837,"mc":[{"id":"1.187562121","rc":[{"batl":[[0,1.02,305.85]],"ltp":1.01,"tv":22274.41,"id":20955040},{"batl":[[0,100,63.46]],"ltp":6.4,"tv":3942.69,"id":9625551}]}]}
{"op":"mcm","clk":"4234861180","pt":1631550681662,"mc":[{"id":"1.187562121","rc":[{"batb":[[0,1.01,112.55]],"batl":[[0,1.02,155],[1,1.03,75.03],[2,1.04,75.03]],"ltp":1.01,"tv":22274.41,"id":20955040},{"batb":[[0,21,2],[1,17.5,8.46],[2,12,4.08]],"batl":[[0,990,0.01],[1,110,0],[2,990,0]],"ltp":6.4,"tv":3942.69,"id":9625551}]}]}
{"op":"mcm","clk":"4234861287","pt":1631550682644,"mc":[{"id":"1.187562121","rc":[{"batl":[[0,1.02,156.74]],"ltp":1.01,"tv":22274.41,"id":20955040}]}]}
{"op":"mcm","clk":"4234861560","pt":1631550685261,"mc":[{"id":"1.187562121","rc":[{"batb":[[1,20,2],[2,18.5,2]],"ltp":6.4,"tv":3942.69,"id":9625551}]}]}
{"op":"mcm","clk":"4234861677","pt":1631550686358,"mc":[{"id":"1.187562121","rc":[{"trd":[[1.02,27.06]],"batl":[[0,1.02,147.72]],"ltp":1.02,"tv":22292.45,"id":20955040}],"tv":26235.15}]}
{"op":"mcm","clk":"4234861985","pt":1631550689470,"mc":[{"id":"1.187562121","rc":[{"batb":[[0,17.5,2],[1,12,2.08],[2,10,2.24]],"ltp":6.4,"tv":3942.69,"id":9625551}]}]}
{"op":"mcm","clk":"4234862250","pt":1631550691843,"mc":[{"id":"1.187562121","rc":[{"batl":[[0,1.01,353.5],[1,1.02,4512.91],[2,1.03,84.74]],"ltp":1.02,"tv":22292.45,"id":20955040},{"batb":[[0,100,2],[1,30,6.66],[2,17.5,2]],"batl":[[0,490,20.82],[1,990,0.01]],"ltp":6.4,"tv":3942.69,"id":9625551}]}]}
{"op":"mcm","clk":"4234862327","pt":1631550692583,"mc":[{"id":"1.187562121","rc":[{"batl":[[1,1.02,4587.94],[2,1.03,159.78]],"ltp":1.02,"tv":22292.45,"id":20955040},{"batb":[[1,30,1.34]],"ltp":6.4,"tv":3942.69,"id":9625551}]}]}
{"op":"mcm","clk":"4234862601","pt":1631550695161,"mc":[{"id":"1.187562121","rc":[{"trd":[[1.01,783.7]],"batl":[[0,1.01,347.54]],"ltp":1.01,"tv":22304.37,"id":20955040}],"tv":26247.07}]}
{"op":"mcm","clk":"4234863153","pt":1631550700411,"mc":[{"id":"1.187562121","rc":[{"batl":[[0,1.01,2347.54]],"ltp":1.01,"tv":22304.37,"id":20955040}]}]}
{"op":"mcm","clk":"4234863805","pt":1631550707596,"mc":[{"id":"1.187562121","rc":[{"trd":[[1.01,839.16]],"batl":[[0,1.01,2319.81]],"ltp":1.01,"tv":22359.83,"id":20955040}],"tv":26302.53}]}
{"op":"mcm","clk":"4234864283","pt":1631550712437,"mc":[{"id":"1.187562121","rc":[{"batl":[[0,1.01,2000],[1,1.02,222.75]],"ltp":1.01,"tv":22359.83,"id":20955040},{"batb":[[0,30,1.34],[1,12,2.08],[2,10,2.24]],"batl":[[0,990,0.01],[1,990,0]],"ltp":6.4,"tv":3942.69,"id":9625551}]}]}
{"op":"mcm","clk":"4234865688","pt":1631550724673,"mc":[{"id":"1.187562121","marketDefinition":{"bspMarket":false,"turnInPlayEnabled":true,"persistenceEnabled":true,"marketBaseRate":5.0,"eventId":"30896488","eventTypeId":"2","numberOfWinners":1,"bettingType":"ODDS","marketType":"MATCH_ODDS","marketTime":"2021-09-13T14:56:00.000Z","suspendTime":"2021-09-13T14:56:00.000Z","bspReconciled":false,"complete":true,"inPlay":true,"crossMatching":true,"runnersVoidable":false,"numberOfActiveRunners":2,"betDelay":3,"status":"SUSPENDED","runners":[{"status":"ACTIVE","sortPriority":1,"id":20955040,"name":"Shintaro Mochizuki"},{"status":"ACTIVE","sortPriority":2,"id":9625551,"name":"Evan Song"}],"regulators":["MR_INT"],"countryCode":"US","discountAllowed":true,"timezone":"UTC","openDate":"2021-09-13T14:56:00.000Z","version":4030917369,"name":"Match Odds","eventName":"Sh Mochizuki v E Song"}}]}
{"op":"mcm","clk":"4234865834","pt":1631550725965,"mc":[{"id":"1.187562121","rc":[{"batl":[[1,1.02,147.72],[2,1.03,9.71]],"ltp":1.01,"tv":22359.83,"id":20955040}]}]}
{"op":"mcm","clk":"4234866456","pt":1631550732363,"mc":[{"id":"1.187562121","rc":[{"batl":[[0,1.02,147.72],[1,1.03,9.71],[2,1.05,947.31]],"ltp":1.01,"tv":22359.83,"id":20955040}]}]}
{"op":"mcm","clk":"4234867850","pt":1631550746171,"mc":[{"id":"1.187562121","rc":[{"batb":[[1,1.46,3.41],[2,1.01,105.79]],"ltp":6.4,"tv":3942.69,"id":9625551}]}]}
{"op":"mcm","clk":"4234869802","pt":1631550764707,"mc":[{"id":"1.187562121","rc":[{"batb":[[0,1.46,3.41],[1,1.01,105.79],[2,1.01,0]],"ltp":6.4,"tv":3942.69,"id":9625551}]}]}
{"op":"mcm","clk":"4234869865","pt":1631550765293,"mc":[{"id":"1.187562121","rc":[{"batl":[[0,1.03,9.71],[1,1.03,0],[2,1.05,0]],"ltp":1.01,"tv":22359.83,"id":20955040}]}]}
{"op":"mcm","clk":"4234873645","pt":1631550802749,"mc":[{"id":"1.187562121","tv":0.0}]}
{"op":"mcm","clk":"4234873934","pt":1631550805601,"mc":[{"id":"1.187562121","marketDefinition":{"bspMarket":false,"turnInPlayEnabled":true,"persistenceEnabled":true,"marketBaseRate":5.0,"eventId":"30896488","eventTypeId":"2","numberOfWinners":1,"bettingType":"ODDS","marketType":"MATCH_ODDS","marketTime":"2021-09-13T14:56:00.000Z","suspendTime":"2021-09-13T14:56:00.000Z","bspReconciled":false,"complete":true,"inPlay":true,"crossMatching":false,"runnersVoidable":false,"numberOfActiveRunners":0,"betDelay":3,"status":"CLOSED","settledTime":"2021-09-13T16:33:17.000Z","runners":[{"status":"WINNER","sortPriority":1,"id":20955040,"name":"Shintaro Mochizuki"},{"status":"LOSER","sortPriority":2,"id":9625551,"name":"Evan Song"}],"regulators":["MR_INT"],"countryCode":"US","discountAllowed":true,"timezone":"UTC","openDate":"2021-09-13T14:56:00.000Z","version":4030922735,"name":"Match Odds","eventName":"Sh Mochizuki v E Song"}}]}
