{"op":"mcm","clk":"4221868162","pt":1631438901992,"mc":[{"id":"1.187552294","marketDefinition":{"bspMarket":false,"turnInPlayEnabled":true,"persistenceEnabled":true,"marketBaseRate":5.0,"eventId":"30895223","eventTypeId":"2","numberOfWinners":1,"bettingType":"ODDS","marketType":"MATCH_ODDS","marketTime":"2021-09-12T12:00:00.000Z","suspendTime":"2021-09-12T12:00:00.000Z","bspReconciled":false,"complete":true,"inPlay":false,"crossMatching":false,"runnersVoidable":false,"numberOfActiveRunners":2,"betDelay":0,"status":"OPEN","runners":[{"status":"ACTIVE","sortPriority":1,"id":25156643,"name":"S Pinto"},{"status":"ACTIVE","sortPriority":2,"id":9628686,"name":"H Kuwata"}],"regulators":["MR_INT"],"countryCode":"GB","discountAllowed":false,"timezone":"GMT","openDate":"2021-09-12T12:00:00.000Z","version":4027604620,"name":"Match Odds","eventName":"S Pinto v H Kuwata"},"rc":[{"batb":[[0,1.01,25]],"ltp":0.0,"tv":0.0,"id":25156643},{"batb":[[0,1.01,25]],"ltp":0.0,"tv":0.0,"id":9628686}]}]}
{"op":"mcm","clk":"4221868333","pt":1631438903730,"mc":[{"id":"1.187552294","marketDefinition":{"bspMarket":false,"turnInPlayEnabled":true,"persistenceEnabled":true,"marketBaseRate":5.0,"eventId":"30895223","eventTypeId":"2","numberOfWinners":1,"bettingType":"ODDS","marketType":"MATCH_ODDS","marketTime":"2021-09-12T12:00:00.000Z","suspendTime":"2021-09-12T12:00:00.000Z","bspReconciled":false,"complete":true,"inPlay":false,"crossMatching":false,"runnersVoidable":false,"numberOfActiveRunners":2,"betDelay":0,"status":"OPEN","runners":[{"status":"ACTIVE","sortPriority":1,"id":25156643,"name":"S Pinto"},{"status":"ACTIVE","sortPriority":2,"id":9628686,"name":"H Kuwata"}],"regulators":["MR_INT"],"countryCode":"GB","discountAllowed":true,"timezone":"GMT","openDate":"2021-09-12T12:00:00.000Z","version":4027604620,"name":"Match Odds","eventName":"S Pinto v H Kuwata"}}]}
{"op":"mcm","clk":"4221880375","pt":1631439019494,"mc":[{"id":"1.187552294","rc":[{"batb":[[0,1.01,7]],"ltp":0.0,"tv":0.0,"id":25156643},{"batb":[[0,1.01,7]],"ltp":0.0,"tv":0.0,"id":9628686}]}]}
{"op":"mcm","clk":"4221948300","pt":1631439582861,"mc":[{"id":"1.187552294","rc":[{"batl":[[0,490,6.16]],"ltp":0.0,"tv":0.0,"id":25156643},{"batl":[[0,490,6.16]],"ltp":0.0,"tv":0.0,"id":9628686}]}]}
{"op":"mcm","clk":"4222117115","pt":1631440790695,"mc":[{"id":"1.187552294","rc":[{"batb":[[0,1.05,879.5],[1,1.01,7]],"ltp":0.0,"tv":0.0,"id":25156643},{"batb":[[0,1.01,4404.52]],"ltp":0.0,"tv":0.0,"id":9628686}]}]}
{"op":"mcm","clk":"4222138794","pt":1631440928852,"mc":[{"id":"1.187552294","rc":[{"batb":[[0,11,10],[1,1.05,879.5],[2,1.01,7]],"ltp":0.0,"tv":0.0,"id":25156643},{"batb":[[0,1.02,500],[1,1.01,4404.52]],"ltp":0.0,"tv":0.0,"id":9628686}]}]}
{"op":"mcm","clk":"4222143229","pt":1631440957946,"mc":[{"id":"1.187552294","marketDefinition":{"bspMarket":false,"turnInPlayEnabled":true,"persistenceEnabled":true,"marketBaseRate":5.0,"eventId":"30895223","eventTypeId":"2","numberOfWinners":1,"bettingType":"ODDS","marketType":"MATCH_ODDS","marketTime":"2021-09-12T12:00:00.000Z","suspendTime":"2021-09-12T12:00:00.000Z","bspReconciled":false,"complete":true,"inPlay":false,"crossMatching":true,"runnersVoidable":false,"numberOfActiveRunners":2,"betDelay":0,"status":"OPEN","runners":[{"status":"ACTIVE","sortPriority":1,"id":25156643,"name":"S Pinto"},{"status":"ACTIVE","sortPriority":2,"id":9628686,"name":"H Kuwata"}],"regulators":["MR_INT"],"countryCode":"GB","discountAllowed":true,"timezone":"GMT","openDate":"2021-09-12T12:00:00.000Z","version":4027604620,"name":"Match Odds","eventName":"S Pinto v H Kuwata"}}]}
{"op":"mcm","clk":"4222418170","pt":1631442537007,"mc":[{"id":"1.187552294","rc":[{"batl":[[0,1.04,105.52],[1,490,6.16]],"ltp":0.0,"tv":0.0,"id":9628686}]}]}
{"op":"mcm","clk":"4222421050","pt":1631442551632,"mc":[{"id":"1.187552294","rc":[{"batl":[[1,1.08,82.38],[2,490,6.16]],"ltp":0.0,"tv":0.0,"id":9628686}]}]}
{"op":"mcm","clk":"4222439109","pt":1631442643854,"mc":[{"id":"1.187552294","rc":[{"batb":[[1,1.01,9528.78]],"ltp":0.0,"tv":0.0,"id":9628686}]}]}
{"op":"mcm","clk":"4222584426","pt":1631443465763,"mc":[{"id":"1.187552294","rc":[{"batb":[[1,1.01,7],[2,1.01,0]],"ltp":0.0,"tv":0.0,"id":25156643}]}]}
{"op":"mcm","clk":"4222585677","pt":1631443472687,"mc":[{"id":"1.187552294","rc":[{"batl":[[2,1.2,43.98]],"ltp":0.0,"tv":0.0,"id":9628686}]}]}
{"op":"mcm","clk":"4222743225","pt":1631444494867,"mc":[{"id":"1.187552294","rc":[{"batb":[[1,1.01,12]],"ltp":0.0,"tv":0.0,"id":25156643},{"batb":[[1,1.01,9533.78]],"ltp":0.0,"tv":0.0,"id":9628686}]}]}
{"op":"mcm","clk":"4222795419","pt":1631444785359,"mc":[{"id":"1.187552294","rc":[{"batb":[[0,11.5,2.66],[1,11,10],[2,1.01,12]],"ltp":0.0,"tv":0.0,"id":25156643}]}]}
{"op":"mcm","clk":"4222999537","pt":1631445819528,"mc":[{"id":"1.187552294","rc":[{"batb":[[2,1.02,108.45]],"ltp":0.0,"tv":0.0,"id":25156643},{"trd":[[1.04,5.78]],"batb":[[0,1.02,608.45]],"batl":[[0,1.04,102.63]],"ltp":1.04,"tv":5.78,"id":9628686}],"tv":5.78}]}
{"op":"mcm","clk":"4223059094","pt":1631446136732,"mc":[{"id":"1.187552294","rc":[{"batb":[[0,19.5,2.66],[1,11.5,2.66],[2,11,10]],"ltp":0.0,"tv":0.0,"id":25156643}]}]}
{"op":"mcm","clk":"4223154996","pt":1631446607148,"mc":[{"id":"1.187552294","rc":[{"batb":[[0,20,2.66],[1,19.5,2.66],[2,11.5,2.66]],"ltp":0.0,"tv":0.0,"id":25156643}]}]}
{"op":"mcm","clk":"4223213665","pt":1631446910192,"mc":[{"id":"1.187552294","rc":[{"batl":[[0,1.04,105.52]],"ltp":1.04,"tv":5.78,"id":9628686}]}]}
{"op":"mcm","clk":"4223309566","pt":1631447403086,"mc":[{"id":"1.187552294","rc":[{"batb":[[2,12.5,13.04]],"ltp":0.0,"tv":0.0,"id":25156643}]}]}
{"op":"mcm","clk":"4223406165","pt":1631447993887,"mc":[{"id":"1.187552294","rc":[{"batl":[[0,1.04,107.52]],"ltp":1.04,"tv":5.78,"id":9628686}]}]}
{"op":"mcm","clk":"4223423741","pt":1631448081966,"mc":[{"id":"1.187552294","marketDefinition":{"bspMarket":false,"turnInPlayEnabled":true,"persistenceEnabled":true,"marketBaseRate":5.0,"eventId":"30895223","eventTypeId":"2","numberOfWinners":1,"bettingType":"ODDS","marketType":"MATCH_ODDS","marketTime":"2021-09-12T12:00:00.000Z","suspendTime":"2021-09-12T12:00:00.000Z","bspReconciled":false,"complete":true,"inPlay":true,"crossMatching":true,"runnersVoidable":false,"numberOfActiveRunners":2,"betDelay":5,"status":"OPEN","runners":[{"status":"ACTIVE","sortPriority":1,"id":25156643,"name":"S Pinto"},{"status":"ACTIVE","sortPriority":2,"id":9628686,"name":"H Kuwata"}],"regulators":["MR_INT"],"countryCode":"GB","discountAllowed":true,"timezone":"GMT","openDate":"2021-09-12T12:00:00.000Z","version":4028036210,"name":"Match Odds","eventName":"S Pinto v H Kuwata"},"rc":[{"batb":[[0,1.01,12],[1,19.5,0],[2,12.5,0]],"ltp":0.0,"tv":0.0,"id":25156643},{"batb":[[0,1.01,12],[1,1.01,0]],"batl":[[0,1.04,105.52],[2,1.2,0]],"ltp":1.04,"tv":5.78,"id":9628686}]}]}
{"op":"mcm","clk":"4223424785","pt":1631448087271,"mc":[{"id":"1.187552294","rc":[{"batl":[[2,11.5,8.68]],"ltp":1.04,"tv":5.78,"id":9628686}]}]}
{"op":"mcm","clk":"4223441347","pt":1631448173037,"mc":[{"id":"1.187552294","rc":[{"trd":[[26,4.22]],"batl":[[0,26,95.78]],"ltp":26.0,"tv":4.22,"id":25156643},{"trd":[[1.04,111.31]],"batl":[[0,1.08,82.38],[1,11.5,8.68],[2,11.5,0]],"ltp":1.04,"tv":111.3,"id":9628686}],"tv":115.52}]}
{"op":"mcm","clk":"4223506665","pt":1631448515796,"mc":[{"id":"1.187552294","rc":[{"batl":[[0,1.04,105.52],[1,1.08,82.38],[2,11.5,8.68]],"ltp":1.04,"tv":111.3,"id":9628686}]}]}
{"op":"mcm","clk":"4223519642","pt":1631448586072,"mc":[{"id":"1.187552294","rc":[{"trd":[[26,8.44]],"batl":[[0,26,141.57]],"ltp":26.0,"tv":8.44,"id":25156643},{"trd":[[1.04,216.83]],"batl":[[0,1.08,82.38],[1,11.5,8.68],[2,11.5,0]],"ltp":1.04,"tv":216.83,"id":9628686}],"tv":225.27}]}
{"op":"mcm","clk":"4223529262","pt":1631448638715,"mc":[{"id":"1.187552294","rc":[{"batl":[[0,1.06,70.98],[1,1.08,82.38],[2,11.5,8.68]],"ltp":1.04,"tv":216.83,"id":9628686}]}]}
{"op":"mcm","clk":"4223607563","pt":1631449043730,"mc":[{"id":"1.187552294","marketDefinition":{"bspMarket":false,"turnInPlayEnabled":true,"persistenceEnabled":true,"marketBaseRate":5.0,"eventId":"30895223","eventTypeId":"2","numberOfWinners":1,"bettingType":"ODDS","marketType":"MATCH_ODDS","marketTime":"2021-09-12T12:17:22.000Z","suspendTime":"2021-09-12T12:17:22.000Z","bspReconciled":false,"complete":true,"inPlay":true,"crossMatching":true,"runnersVoidable":false,"numberOfActiveRunners":2,"betDelay":5,"status":"OPEN","runners":[{"status":"ACTIVE","sortPriority":1,"id":25156643,"name":"S Pinto"},{"status":"ACTIVE","sortPriority":2,"id":9628686,"name":"H Kuwata"}],"regulators":["MR_INT"],"countryCode":"GB","discountAllowed":true,"timezone":"GMT","openDate":"2021-09-12T12:00:00.000Z","version":4028096886,"name":"Match Odds","eventName":"S Pinto v H Kuwata"}}]}
{"op":"mcm","clk":"4223608060","pt":1631449046750,"mc":[{"id":"1.187552294","marketDefinition":{"bspMarket":false,"turnInPlayEnabled":true,"persistenceEnabled":true,"marketBaseRate":5.0,"eventId":"30895223","eventTypeId":"2","numberOfWinners":1,"bettingType":"ODDS","marketType":"MATCH_ODDS","marketTime":"2021-09-12T12:17:22.000Z","suspendTime":"2021-09-12T12:17:22.000Z","bspReconciled":false,"complete":true,"inPlay":true,"crossMatching":true,"runnersVoidable":false,"numberOfActiveRunners":2,"betDelay":5,"status":"OPEN","runners":[{"status":"ACTIVE","sortPriority":1,"id":25156643,"name":"S Pinto"},{"status":"ACTIVE","sortPriority":2,"id":9628686,"name":"H Kuwata"}],"regulators":["MR_INT"],"countryCode":"GB","discountAllowed":true,"timezone":"GMT","openDate":"2021-09-12T12:17:22.000Z","version":4028096886,"name":"Match Odds","eventName":"S Pinto v H Kuwata"}}]}
{"op":"mcm","clk":"4223620184","pt":1631449118626,"mc":[{"id":"1.187552294","rc":[{"trd":[[17.5,4.3]],"batl":[[0,17.5,32.55]],"ltp":17.5,"tv":12.73,"id":25156643},{"trd":[[1.06,70.98]],"batl":[[0,1.08,82.38],[1,11.5,8.68],[2,11.5,0]],"ltp":1.06,"tv":287.81,"id":9628686}],"tv":300.55}]}
{"op":"mcm","clk":"4223620233","pt":1631449118900,"mc":[{"id":"1.187552294","rc":[{"batl":[[1,11.5,0]],"ltp":1.06,"tv":287.81,"id":9628686}]}]}
{"op":"mcm","clk":"4223621099","pt":1631449124223,"mc":[{"id":"1.187552294","rc":[{"trd":[[17.5,4.47]],"batl":[[0,17.5,32.38]],"ltp":17.5,"tv":12.91,"id":25156643},{"trd":[[1.06,73.82]],"batl":[[1,11.5,8.68]],"ltp":1.06,"tv":290.64,"id":9628686}],"tv":303.55}]}
{"op":"mcm","clk":"4223664856","pt":1631449381867,"mc":[{"id":"1.187552294","rc":[{"batb":[[0,3.7,376.92],[1,1.01,12]],"batl":[[0,23,52.09]],"ltp":17.5,"tv":12.91,"id":25156643}]}]}
{"op":"mcm","clk":"4223672141","pt":1631449426399,"mc":[{"id":"1.187552294","rc":[{"batl":[[0,21,54.36]],"ltp":17.5,"tv":12.91,"id":25156643}]}]}
{"op":"mcm","clk":"4223677263","pt":1631449455762,"mc":[{"id":"1.187552294","rc":[{"batl":[[0,18,57.14]],"ltp":17.5,"tv":12.91,"id":25156643}]}]}
{"op":"mcm","clk":"4223682914","pt":1631449488274,"mc":[{"id":"1.187552294","rc":[{"batl":[[0,23,52.09]],"ltp":17.5,"tv":12.91,"id":25156643}]}]}
{"op":"mcm","clk":"4223683944","pt":1631449494699,"mc":[{"id":"1.187552294","rc":[{"batl":[[0,11.5,8.68],[1,11.5,0]],"ltp":1.06,"tv":290.64,"id":9628686}]}]}
{"op":"mcm","clk":"4223685595","pt":1631449504497,"mc":[{"id":"1.187552294","rc":[{"batl":[[0,1.11,41.62],[1,11.5,8.68]],"ltp":1.06,"tv":290.64,"id":9628686}]}]}
{"op":"mcm","clk":"4223695097","pt":1631449558577,"mc":[{"id":"1.187552294","rc":[{"batb":[[0,1.01,12],[1,1.01,0]],"ltp":17.5,"tv":12.91,"id":25156643}]}]}
{"op":"mcm","clk":"4223698078","pt":1631449576909,"mc":[{"id":"1.187552294","rc":[{"batb":[[0,3.9,376.1],[1,1.01,12]],"batl":[[0,34,46.84]],"ltp":17.5,"tv":12.91,"id":25156643}]}]}
{"op":"mcm","clk":"4223701727","pt":1631449599583,"mc":[{"id":"1.187552294","rc":[{"batl":[[0,60,41.65]],"ltp":17.5,"tv":12.91,"id":25156643}]}]}
{"op":"mcm","clk":"4223710793","pt":1631449656423,"mc":[{"id":"1.187552294","rc":[{"batl":[[0,46,43.67]],"ltp":17.5,"tv":12.91,"id":25156643}]}]}
{"op":"mcm","clk":"4223721049","pt":1631449717125,"mc":[{"id":"1.187552294","rc":[{"batl":[[0,34,46.84]],"ltp":17.5,"tv":12.91,"id":25156643}]}]}
{"op":"mcm","clk":"4223726048","pt":1631449746469,"mc":[{"id":"1.187552294","rc":[{"batl":[[0,11.5,8.68],[1,11.5,0]],"ltp":1.06,"tv":290.64,"id":9628686}]}]}
{"op":"mcm","clk":"4223726913","pt":1631449751560,"mc":[{"id":"1.187552294","rc":[{"batl":[[0,1.08,41.62],[1,11.5,8.68]],"ltp":1.06,"tv":290.64,"id":9628686}]}]}
{"op":"mcm","clk":"4223726965","pt":1631449751882,"mc":[{"id":"1.187552294","rc":[{"batl":[[0,46,43.67]],"ltp":17.5,"tv":12.91,"id":25156643}]}]}
{"op":"mcm","clk":"4223729490","pt":1631449767899,"mc":[{"id":"1.187552294","rc":[{"batl":[[0,60,41.65]],"ltp":17.5,"tv":12.91,"id":25156643}]}]}
{"op":"mcm","clk":"4223736222","pt":1631449809585,"mc":[{"id":"1.187552294","rc":[{"batl":[[0,34,46.84]],"ltp":17.5,"tv":12.91,"id":25156643}]}]}
{"op":"mcm","clk":"4223742715","pt":1631449849135,"mc":[{"id":"1.187552294","rc":[{"batl":[[0,46,43.67]],"ltp":17.5,"tv":12.91,"id":25156643}]}]}
{"op":"mcm","clk":"4223748266","pt":1631449880072,"mc":[{"id":"1.187552294","rc":[{"batl":[[0,34,46.84]],"ltp":17.5,"tv":12.91,"id":25156643}]}]}
{"op":"mcm","clk":"4223751517","pt":1631449900116,"mc":[{"id":"1.187552294","rc":[{"batl":[[0,46,43.67]],"ltp":17.5,"tv":12.91,"id":25156643}]}]}
{"op":"mcm","clk":"4223755925","pt":1631449924561,"mc":[{"id":"1.187552294","rc":[{"batl":[[0,34,46.84]],"ltp":17.5,"tv":12.91,"id":25156643}]}]}
{"op":"mcm","clk":"4223762280","pt":1631449960099,"mc":[{"id":"1.187552294","rc":[{"batl":[[0,26,50.19]],"ltp":17.5,"tv":12.91,"id":25156643}]}]}
{"op":"mcm","clk":"4223781942","pt":1631450069180,"mc":[{"id":"1.187552294","rc":[{"batl":[[0,21,54.36]],"ltp":17.5,"tv":12.91,"id":25156643}]}]}
{"op":"mcm","clk":"4223785003","pt":1631450087397,"mc":[{"id":"1.187552294","rc":[{"batl":[[0,26,50.19]],"ltp":17.5,"tv":12.91,"id":25156643}]}]}
{"op":"mcm","clk":"4223788270","pt":1631450105702,"mc":[{"id":"1.187552294","rc":[{"batl":[[0,23,52.09]],"ltp":17.5,"tv":12.91,"id":25156643}]}]}
{"op":"mcm","clk":"4223793360","pt":1631450133270,"mc":[{"id":"1.187552294","rc":[{"batl":[[0,34,46.84]],"ltp":17.5,"tv":12.91,"id":25156643}]}]}
{"op":"mcm","clk":"4223806151","pt":1631450201186,"mc":[{"id":"1.187552294","rc":[{"batl":[[0,46,43.67]],"ltp":17.5,"tv":12.91,"id":25156643}]}]}
{"op":"mcm","clk":"4223816125","pt":1631450251158,"mc":[{"id":"1.187552294","rc":[{"batl":[[0,60,41.65]],"ltp":17.5,"tv":12.91,"id":25156643}]}]}
{"op":"mcm","clk":"4223819558","pt":1631450270159,"mc":[{"id":"1.187552294","rc":[{"batl":[[0,34,46.84]],"ltp":17.5,"tv":12.91,"id":25156643}]}]}
{"op":"mcm","clk":"4223823022","pt":1631450288409,"mc":[{"id":"1.187552294","rc":[{"batl":[[0,46,43.67]],"ltp":17.5,"tv":12.91,"id":25156643}]}]}
{"op":"mcm","clk":"4223832047","pt":1631450337377,"mc":[{"id":"1.187552294","rc":[{"batl":[[0,34,46.84]],"ltp":17.5,"tv":12.91,"id":25156643}]}]}
{"op":"mcm","clk":"4223839465","pt":1631450375945,"mc":[{"id":"1.187552294","rc":[{"batl":[[0,46,43.67]],"ltp":17.5,"tv":12.91,"id":25156643}]}]}
{"op":"mcm","clk":"4223844780","pt":1631450403498,"mc":[{"id":"1.187552294","rc":[{"batl":[[0,34,46.84]],"ltp":17.5,"tv":12.91,"id":25156643}]}]}
{"op":"mcm","clk":"4223851518","pt":1631450434867,"mc":[{"id":"1.187552294","rc":[{"batl":[[0,46,43.67]],"ltp":17.5,"tv":12.91,"id":25156643}]}]}
{"op":"mcm","clk":"4223858814","pt":1631450470402,"mc":[{"id":"1.187552294","rc":[{"batl":[[0,34,46.84]],"ltp":17.5,"tv":12.91,"id":25156643}]}]}
{"op":"mcm","clk":"4223864222","pt":1631450499016,"mc":[{"id":"1.187552294","rc":[{"batl":[[0,26,50.19]],"ltp":17.5,"tv":12.91,"id":25156643}]}]}
{"op":"mcm","clk":"4223872282","pt":1631450534227,"mc":[{"id":"1.187552294","rc":[{"batb":[[0,1.01,12],[1,1.01,0]],"ltp":17.5,"tv":12.91,"id":25156643}]}]}
{"op":"mcm","clk":"4223898024","pt":1631450652886,"mc":[{"id":"1.187552294","rc":[{"batl":[[0,11.5,8.68],[1,11.5,0]],"ltp":1.06,"tv":290.64,"id":9628686}]}]}
{"op":"mcm","clk":"4223899161","pt":1631450658024,"mc":[{"id":"1.187552294","rc":[{"batl":[[0,1.09,41.62],[1,11.5,8.68]],"ltp":1.06,"tv":290.64,"id":9628686}]}]}
{"op":"mcm","clk":"4223908678","pt":1631450701636,"mc":[{"id":"1.187552294","rc":[{"batb":[[0,3.7,376.92],[1,1.01,12]],"batl":[[0,23,52.09]],"ltp":17.5,"tv":12.91,"id":25156643}]}]}
{"op":"mcm","clk":"4223912750","pt":1631450721968,"mc":[{"id":"1.187552294","rc":[{"batl":[[0,21,54.36]],"ltp":17.5,"tv":12.91,"id":25156643}]}]}
{"op":"mcm","clk":"4223920403","pt":1631450762627,"mc":[{"id":"1.187552294","rc":[{"batl":[[0,34,46.84]],"ltp":17.5,"tv":12.91,"id":25156643}]}]}
{"op":"mcm","clk":"4223929870","pt":1631450811326,"mc":[{"id":"1.187552294","rc":[{"batl":[[0,26,50.19]],"ltp":17.5,"tv":12.91,"id":25156643}]}]}
{"op":"mcm","clk":"4223931916","pt":1631450822448,"mc":[{"id":"1.187552294","rc":[{"batl":[[0,46,43.67]],"ltp":17.5,"tv":12.91,"id":25156643}]}]}
{"op":"mcm","clk":"4223938849","pt":1631450860003,"mc":[{"id":"1.187552294","rc":[{"batl":[[0,34,46.84]],"ltp":17.5,"tv":12.91,"id":25156643}]}]}
{"op":"mcm","clk":"4223956094","pt":1631450900751,"mc":[{"id":"1.187552294","rc":[{"batl":[[0,46,43.67]],"ltp":17.5,"tv":12.91,"id":25156643}]}]}
{"op":"mcm","clk":"4223962835","pt":1631450941282,"mc":[{"id":"1.187552294","rc":[{"batl":[[0,60,41.65]],"ltp":17.5,"tv":12.91,"id":25156643}]}]}
{"op":"mcm","clk":"4223966366","pt":1631450961499,"mc":[{"id":"1.187552294","rc":[{"batl":[[0,46,43.67]],"ltp":17.5,"tv":12.91,"id":25156643}]}]}
{"op":"mcm","clk":"4223972011","pt":1631450995564,"mc":[{"id":"1.187552294","rc":[{"batb":[[0,1.01,12],[1,1.01,0]],"ltp":17.5,"tv":12.91,"id":25156643}]}]}
{"op":"mcm","clk":"4223973033","pt":1631451001289,"mc":[{"id":"1.187552294","rc":[{"batb":[[0,4.2,377.06],[1,1.01,12]],"batl":[[0,85,39.77]],"ltp":17.5,"tv":12.91,"id":25156643}]}]}
{"op":"mcm","clk":"4223979541","pt":1631451040557,"mc":[{"id":"1.187552294","rc":[{"batl":[[0,340,36.48]],"ltp":17.5,"tv":12.91,"id":25156643}]}]}
{"op":"mcm","clk":"4224055288","pt":1631451509018,"mc":[{"id":"1.187552294","rc":[{"trd":[[1.01,24]],"batl":[[0,1.01,5.08],[1,1.09,41.62],[2,11.5,8.68]],"ltp":1.01,"tv":314.64,"id":9628686}],"tv":327.55}]}
{"op":"mcm","clk":"4224172199","pt":1631452077914,"mc":[{"id":"1.187552294","rc":[{"batb":[[0,1.01,12],[1,1.01,0]],"ltp":17.5,"tv":12.91,"id":25156643}]}]}
{"op":"mcm","clk":"4224271649","pt":1631452516441,"mc":[{"id":"1.187552294","rc":[{"batb":[[0,4.8,372.81],[1,1.01,12]],"ltp":17.5,"tv":12.91,"id":25156643}]}]}
{"op":"mcm","clk":"4224345356","pt":1631452841046,"mc":[{"id":"1.187552294","rc":[{"batb":[[0,1.01,12],[1,1.01,0]],"ltp":17.5,"tv":12.91,"id":25156643}]}]}
{"op":"mcm","clk":"4224425000","pt":1631453248814,"mc":[{"id":"1.187552294","marketDefinition":{"bspMarket":false,"turnInPlayEnabled":true,"persistenceEnabled":true,"marketBaseRate":5.0,"eventId":"30895223","eventTypeId":"2","numberOfWinners":1,"bettingType":"ODDS","marketType":"MATCH_ODDS","marketTime":"2021-09-12T12:17:22.000Z","suspendTime":"2021-09-12T12:17:22.000Z","bspReconciled":false,"complete":true,"inPlay":true,"crossMatching":true,"runnersVoidable":false,"numberOfActiveRunners":2,"betDelay":5,"status":"SUSPENDED","runners":[{"status":"ACTIVE","sortPriority":1,"id":25156643,"name":"S Pinto"},{"status":"ACTIVE","sortPriority":2,"id":9628686,"name":"H Kuwata"}],"regulators":["MR_INT"],"countryCode":"GB","discountAllowed":true,"timezone":"GMT","openDate":"2021-09-12T12:17:22.000Z","version":4028366168,"name":"Match Odds","eventName":"S Pinto v H Kuwata"}}]}
{"op":"mcm","clk":"4224427080","pt":1631453259473,"mc":[{"id":"1.187552294","tv":0.0}]}
{"op":"mcm","clk":"4224427341","pt":1631453260855,"mc":[{"id":"1.187552294","marketDefinition":{"bspMarket":false,"turnInPlayEnabled":true,"persistenceEnabled":true,"marketBaseRate":5.0,"eventId":"30895223","eventTypeId":"2","numberOfWinners":1,"bettingType":"ODDS","marketType":"MATCH_ODDS","marketTime":"2021-09-12T12:17:22.000Z","suspendTime":"2021-09-12T12:17:22.000Z","bspReconciled":false,"complete":true,"inPlay":true,"crossMatching":false,"runnersVoidable":false,"numberOfActiveRunners":0,"betDelay":5,"status":"CLOSED","settledTime":"2021-09-12T13:27:38.000Z","runners":[{"status":"LOSER","sortPriority":1,"id":25156643,"name":"S Pinto"},{"status":"WINNER","sortPriority":2,"id":9628686,"name":"H Kuwata"}],"regulators":["MR_INT"],"countryCode":"GB","discountAllowed":true,"timezone":"GMT","openDate":"2021-09-12T12:17:22.000Z","version":4028366456,"name":"Match Odds","eventName":"S Pinto v H Kuwata"}}]}
