{"op":"mcm","clk":"4234593872","pt":1631547645240,"mc":[{"id":"1.187562121","rc":[{"batl":[[0,1.52,69.01],[1,1.53,75.5],[2,3.8,27.43]],"ltp":1.28,"tv":10605.43,"id":20955040},{"batb":[[0,2.92,46.29]],"ltp":4.3,"tv":1566.38,"id":9625551}]}]}
{"op":"mcm","clk":"4234593962","pt":1631547646644,"mc":[{"id":"1.187562121","rc":[{"batb":[[0,1.25,2]],"batl":[[0,1.47,88.5],[1,1.52,69.01],[2,1.53,75.5]],"ltp":1.28,"tv":10605.43,"id":20955040},{"batb":[[0,3.1,4.14],[1,2.92,46.29],[2,2.88,4.71]],"batl":[[0,4.5,2],[1,6.4,3],[2,7,3]],"ltp":4.3,"tv":1566.38,"id":9625551}]}]}
{"op":"mcm","clk":"4234594019","pt":1631547647847,"mc":[{"id":"1.187562121","rc":[{"batl":[[0,3.8,27.43],[1,8.8,7.22],[2,44,7.22]],"ltp":1.28,"tv":10605.43,"id":20955040},{"batb":[[0,2.92,46.29],[1,2.88,4.71],[2,2.2,42.6]],"ltp":4.3,"tv":1566.38,"id":9625551}]}]}
{"op":"mcm","clk":"4234594113","pt":1631547649355,"mc":[{"id":"1.187562121","rc":[{"batb":[[1,1.2,179.41],[2,1.18,2]],"ltp":1.28,"tv":10605.43,"id":20955040},{"batl":[[0,4.2,33.36],[1,4.5,2]],"ltp":4.3,"tv":1566.38,"id":9625551}]}]}
{"op":"mcm","clk":"4234594209","pt":1631547650659,"mc":[{"id":"1.187562121","rc":[{"trd":[[1.25,13.42],[1.28,59.03],[1.31,122.05]],"batb":[[0,1.2,831.52],[1,1.18,2],[2,1.17,109]],"batl":[[0,1.24,22.31],[1,1.25,156.9],[2,1.26,95.24]],"ltp":1.25,"tv":10723.42,"id":20955040},{"trd":[[4.2,33.36],[4.5,2]],"batb":[[0,5,13.07],[1,4.9,18.36],[2,4.8,9.18]],"batl":[[0,5.5,7.36],[1,6,130.42]],"ltp":4.5,"tv":1601.74,"id":9625551}],"tv":12325.16}]}
{"op":"mcm","clk":"4234594303","pt":1631547651813,"mc":[{"id":"1.187562121","rc":[{"batb":[[0,1.22,24.6],[1,1.21,12.3],[2,1.2,852.15]],"batl":[[0,1.25,156.9],[1,1.26,95.24],[2,1.27,7.87]],"ltp":1.25,"tv":10723.42,"id":20955040},{"batb":[[1,4.9,6.12],[2,4.8,3.06]],"batl":[[0,6,130.42],[1,7,3],[2,7.4,3]],"ltp":4.5,"tv":1601.74,"id":9625551}]}]}
{"op":"mcm","clk":"4234594411","pt":1631547652652,"mc":[{"id":"1.187562121","rc":[{"batl":[[0,1.24,231],[1,1.25,156.9],[2,1.26,95.24]],"ltp":1.25,"tv":10723.42,"id":20955040}]}]}
{"op":"mcm","clk":"4234594710","pt":1631547654791,"mc":[{"id":"1.187562121","rc":[{"batl":[[0,1.24,253.31]],"ltp":1.25,"tv":10723.42,"id":20955040},{"batl":[[0,5.5,7.36],[1,6,130.42],[2,7,3]],"ltp":4.5,"tv":1601.74,"id":9625551}]}]}
{"op":"mcm","clk":"4234594894","pt":1631547655828,"mc":[{"id":"1.187562121","rc":[{"batl":[[2,1.26,340.47]],"ltp":1.25,"tv":10723.42,"id":20955040},{"batl":[[0,5.4,4.22],[1,5.5,7.36],[2,6,130.42]],"ltp":4.5,"tv":1601.74,"id":9625551}]}]}
{"op":"mcm","clk":"4234594909","pt":1631547655933,"mc":[{"id":"1.187562121","rc":[{"batl":[[2,1.26,95.24]],"ltp":1.25,"tv":10723.42,"id":20955040},{"batl":[[0,5.5,7.36],[1,6,130.42],[2,7,3]],"ltp":4.5,"tv":1601.74,"id":9625551}]}]}
{"op":"mcm","clk":"4234596036","pt":1631547667027,"mc":[{"id":"1.187562121","rc":[{"batl":[[1,6,148.52]],"ltp":4.5,"tv":1601.74,"id":9625551}]}]}
{"op":"mcm","clk":"4234596256","pt":1631547669739,"mc":[{"id":"1.187562121","rc":[{"batb":[[0,1.2,179.41],[1,1.18,2],[2,1.17,109]],"batl":[[0,1.24,231],[1,1.33,101.5],[2,1.37,86.5]],"ltp":1.25,"tv":10723.42,"id":20955040},{"batb":[[0,4.6,25.75],[1,4,3.43],[2,3.7,25.95]],"batl":[[0,6,18.1],[1,7,3],[2,7.4,3]],"ltp":4.5,"tv":1601.74,"id":9625551}]}]}
{"op":"mcm","clk":"4234596329","pt":1631547670634,"mc":[{"id":"1.187562121","rc":[{"batb":[[0,1.2,2]],"batl":[[0,1.37,86.5],[1,3.8,27.43],[2,8.8,7.22]],"ltp":1.25,"tv":10723.42,"id":20955040},{"batb":[[0,3.7,25.95],[1,3,5.96],[2,2.6,3.73]],"ltp":4.5,"tv":1601.74,"id":9625551}]}]}
{"op":"mcm","clk":"4234597139","pt":1631547678779,"mc":[{"id":"1.187562121","rc":[{"batl":[[1,1.58,903.84],[2,3.8,27.43]],"ltp":1.25,"tv":10723.42,"id":20955040}]}]}
{"op":"mcm","clk":"4234597952","pt":1631547682883,"mc":[{"id":"1.187562121","rc":[{"batl":[[1,3.8,27.43],[2,8.8,7.22]],"ltp":1.25,"tv":10723.42,"id":20955040}]}]}
{"op":"mcm","clk":"4234598967","pt":1631547689744,"mc":[{"id":"1.187562121","rc":[{"batb":[[0,1.29,27.38],[1,1.28,11.62],[2,1.27,11.62]],"batl":[[0,1.32,20.23],[1,1.37,86.5],[2,3.8,27.43]],"ltp":1.25,"tv":10723.42,"id":20955040},{"batb":[[0,4,245.33],[1,3.7,25.95]],"batl":[[0,4.3,51.38],[1,4.5,2],[2,4.6,2.17]],"ltp":4.5,"tv":1601.74,"id":9625551}]}]}
{"op":"mcm","clk":"4234599014","pt":1631547690571,"mc":[{"id":"1.187562121","rc":[{"batb":[[1,1.28,133.5]],"batl":[[1,1.33,22.56],[2,1.34,11.28]],"ltp":1.25,"tv":10723.42,"id":20955040},{"batb":[[2,2.88,43.2]],"ltp":4.5,"tv":1601.74,"id":9625551}]}]}
{"op":"mcm","clk":"4234599042","pt":1631547690988,"mc":[{"id":"1.187562121","rc":[{"trd":[[1.28,182.88],[1.29,54.76],[1.3,172.21]],"batb":[[0,1.28,50.31],[1,1.27,11.62],[2,1.21,170.95]],"ltp":1.28,"tv":11071.98,"id":20955040},{"trd":[[4.3,62.56],[4.5,6],[4.6,16.17]],"batl":[[0,4.7,283.89],[1,6,18.1],[2,6.4,3]],"ltp":4.6,"tv":1673.29,"id":9625551}],"tv":12745.28}]}
{"op":"mcm","clk":"4234599306","pt":1631547696084,"mc":[{"id":"1.187562121","rc":[{"batb":[[2,1.23,5.76]],"ltp":1.28,"tv":11071.98,"id":20955040},{"batb":[[2,3.05,4.49]],"batl":[[1,5.4,2],[2,6,20.1]],"ltp":4.6,"tv":1673.29,"id":9625551}]}]}
{"op":"mcm","clk":"4234599600","pt":1631547701872,"mc":[{"id":"1.187562121","rc":[{"batb":[[1,1.27,5.81]],"batl":[[0,1.33,11.28],[1,1.34,5.64],[2,1.35,5.64]],"ltp":1.28,"tv":11071.98,"id":20955040}]}]}
{"op":"mcm","clk":"4234599641","pt":1631547702861,"mc":[{"id":"1.187562121","rc":[{"batb":[[0,1.21,170.95],[1,1.2,308.53],[2,1.19,103]],"batl":[[0,1.54,76.75],[1,1.66,831.03],[2,3.8,27.43]],"ltp":1.28,"tv":11071.98,"id":20955040},{"batb":[[0,2.88,43.2],[1,2.84,4.72],[2,2.6,3.73]],"batl":[[0,6,2],[1,6.4,3],[2,7,3]],"ltp":4.6,"tv":1673.29,"id":9625551}]}]}
{"op":"mcm","clk":"4234599745","pt":1631547704571,"mc":[{"id":"1.187562121","rc":[{"batl":[[1,3.8,27.43],[2,8.8,7.22]],"ltp":1.28,"tv":11071.98,"id":20955040}]}]}
{"op":"mcm","clk":"4234599836","pt":1631547705773,"mc":[{"id":"1.187562121","rc":[{"batb":[[0,1.2,483.17],[1,1.19,103],[2,1.18,108]],"batl":[[0,1.48,83.99],[1,1.54,76.75],[2,3.8,27.43]],"ltp":1.28,"tv":11071.98,"id":20955040},{"batb":[[0,3.05,4.69],[1,2.9,41.94],[2,2.84,4.72]],"ltp":4.6,"tv":1673.29,"id":9625551}]}]}
{"op":"mcm","clk":"4234599875","pt":1631547706399,"mc":[{"id":"1.187562121","rc":[{"batl":[[0,1.54,76.75],[1,3.8,27.43],[2,8.8,7.22]],"ltp":1.28,"tv":11071.98,"id":20955040},{"batb":[[0,2.9,41.94],[1,2.84,4.72],[2,2.6,3.73]],"ltp":4.6,"tv":1673.29,"id":9625551}]}]}
{"op":"mcm","clk":"4234600214","pt":1631547712897,"mc":[{"id":"1.187562121","rc":[{"batl":[[0,1.48,75.99]],"ltp":1.28,"tv":11071.98,"id":20955040},{"batb":[[0,3.05,4.29],[1,2.9,41.94],[2,2.84,4.72]],"ltp":4.6,"tv":1673.29,"id":9625551}]}]}
{"op":"mcm","clk":"4234600243","pt":1631547713510,"mc":[{"id":"1.187562121","rc":[{"batl":[[0,3.8,27.43],[1,8.8,7.22],[2,44,7.22]],"ltp":1.28,"tv":11071.98,"id":20955040},{"batb":[[0,2.9,41.94],[1,2.84,4.72],[2,2.6,3.73]],"ltp":4.6,"tv":1673.29,"id":9625551}]}]}
{"op":"mcm","clk":"4234600320","pt":1631547714497,"mc":[{"id":"1.187562121","rc":[{"batb":[[0,1.2,282.41],[1,1.18,108],[2,1.17,109]],"ltp":1.28,"tv":11071.98,"id":20955040},{"batl":[[1,7,3],[2,7.4,3]],"ltp":4.6,"tv":1673.29,"id":9625551}]}]}
{"op":"mcm","clk":"4234600401","pt":1631547715721,"mc":[{"id":"1.187562121","rc":[{"batb":[[0,1.21,919.7],[1,1.2,282.41],[2,1.18,108]],"batl":[[0,1.24,21.91],[1,1.25,317.02],[2,1.27,7.87]],"ltp":1.28,"tv":11071.98,"id":20955040},{"batb":[[0,5,13.08],[1,4.9,6.12],[2,4.8,3.06]],"batl":[[0,5.5,7.61],[1,6,2],[2,7,3]],"ltp":4.6,"tv":1673.29,"id":9625551}]}]}
{"op":"mcm","clk":"4234600465","pt":1631547716590,"mc":[{"id":"1.187562121","rc":[{"batb":[[0,1.21,927.96]],"ltp":1.28,"tv":11071.98,"id":20955040},{"batl":[[1,5.6,5.36],[2,5.7,2.68]],"ltp":4.6,"tv":1673.29,"id":9625551}]}]}
{"op":"mcm","clk":"4234600510","pt":1631547717303,"mc":[{"id":"1.187562121","rc":[{"batl":[[0,1.23,2],[1,1.24,21.91],[2,1.25,317.02]],"ltp":1.28,"tv":11071.98,"id":20955040}]}]}
{"op":"mcm","clk":"4234600997","pt":1631547724903,"mc":[{"id":"1.187562121","rc":[{"batb":[[0,1.2,107.77],[1,1.18,108],[2,1.17,109]],"batl":[[1,1.34,97.25],[2,1.38,88.75]],"ltp":1.28,"tv":11071.98,"id":20955040},{"batb":[[0,3.9,3.56],[1,3.7,22.65],[2,3.6,3.49]],"batl":[[0,6,2],[1,7,3],[2,7.4,3]],"ltp":4.6,"tv":1673.29,"id":9625551}]}]}
{"op":"mcm","clk":"4234601058","pt":1631547725726,"mc":[{"id":"1.187562121","rc":[{"batb":[[0,1.2,2]],"batl":[[0,1.38,88.75],[1,3.8,27.43],[2,8.8,7.22]],"ltp":1.28,"tv":11071.98,"id":20955040},{"batb":[[0,3.7,22.65],[1,3.6,3.49],[2,3,5.96]],"batl":[[0,7,3],[1,7.4,3],[2,7.8,3]],"ltp":4.6,"tv":1673.29,"id":9625551}]}]}
{"op":"mcm","clk":"4234601227","pt":1631547728499,"mc":[{"id":"1.187562121","rc":[{"batl":[[0,5.1,10.65],[1,7,3],[2,7.4,3]],"ltp":4.6,"tv":1673.29,"id":9625551}]}]}
{"op":"mcm","clk":"4234601437","pt":1631547731721,"mc":[{"id":"1.187562121","rc":[{"batl":[[0,1.34,88.75],[1,1.38,88.75],[2,3.8,27.43]],"ltp":1.28,"tv":11071.98,"id":20955040},{"batb":[[0,3.9,3.26],[1,3.7,22.65],[2,3.6,3.49]],"ltp":4.6,"tv":1673.29,"id":9625551}]}]}
{"op":"mcm","clk":"4234601451","pt":1631547731923,"mc":[{"id":"1.187562121","rc":[{"batl":[[0,1.38,88.75],[1,3.8,27.43],[2,8.8,7.22]],"ltp":1.28,"tv":11071.98,"id":20955040},{"batb":[[0,3.7,22.65],[1,3.6,3.49],[2,3,5.96]],"ltp":4.6,"tv":1673.29,"id":9625551}]}]}
{"op":"mcm","clk":"4234601786","pt":1631547737808,"mc":[{"id":"1.187562121","rc":[{"batb":[[2,1.16,333.94]],"ltp":1.28,"tv":11071.98,"id":20955040},{"batl":[[1,7.4,3],[2,7.8,3]],"ltp":4.6,"tv":1673.29,"id":9625551}]}]}
{"op":"mcm","clk":"4234601856","pt":1631547738833,"mc":[{"id":"1.187562121","rc":[{"trd":[[1.2,50.72],[1.24,45.79]],"batb":[[0,1.18,108],[1,1.16,333.94],[2,1.15,103.43]],"batl":[[0,1.2,8.97],[1,1.21,3356.53],[2,1.23,8.13]],"ltp":1.2,"tv":11119.77,"id":20955040},{"trd":[[5.1,23.07]],"batb":[[0,5.9,25.42],[1,5.8,12.72],[2,5.7,190.14]],"batl":[[0,6.4,6.74],[1,6.8,225.96],[2,7.4,3]],"ltp":5.1,"tv":1683.94,"id":9625551}],"tv":12803.71}]}
{"op":"mcm","clk":"4234601908","pt":1631547739827,"mc":[{"id":"1.187562121","rc":[{"batb":[[1,1.17,8.55],[2,1.16,333.94]],"batl":[[1,1.21,149.5]],"ltp":1.2,"tv":11119.77,"id":20955040},{"batb":[[0,5.9,15.25],[1,5.8,7.63],[2,5.7,195.47]],"batl":[[1,6.8,248.02],[2,7,11.02]],"ltp":5.1,"tv":1683.94,"id":9625551}]}]}
{"op":"mcm","clk":"4234601945","pt":1631547740606,"mc":[{"id":"1.187562121","rc":[{"batl":[[0,1.19,91],[1,1.2,109.97],[2,1.21,149.5]],"ltp":1.2,"tv":11119.77,"id":20955040},{"batb":[[0,6.2,6],[1,6,7],[2,5.9,15.25]],"batl":[[1,6.8,230.38],[2,7,2.2]],"ltp":5.1,"tv":1683.94,"id":9625551}]}]}
{"op":"mcm","clk":"4234602209","pt":1631547745420,"mc":[{"id":"1.187562121","rc":[{"batb":[[2,1.16,341.72]],"ltp":1.2,"tv":11119.77,"id":20955040}]}]}
{"op":"mcm","clk":"4234602391","pt":1631547749035,"mc":[{"id":"1.187562121","rc":[{"batl":[[1,1.2,101]],"ltp":1.2,"tv":11119.77,"id":20955040},{"batl":[[0,6.8,230.38],[1,7,2.2],[2,7.2,2.2]],"ltp":5.1,"tv":1683.94,"id":9625551}]}]}
{"op":"mcm","clk":"4234602551","pt":1631547752046,"mc":[{"id":"1.187562121","rc":[{"trd":[[1.19,812.25]],"batl":[[0,1.19,72.54],[1,1.2,110.97]],"ltp":1.19,"tv":11156.69,"id":20955040}],"tv":12840.63}]}
{"op":"mcm","clk":"4234602640","pt":1631547753825,"mc":[{"id":"1.187562121","rc":[{"trd":[[1.19,819.82]],"batl":[[0,1.19,64.97]],"ltp":1.19,"tv":11164.26,"id":20955040},{"trd":[[6.2,88.1]],"batb":[[0,6,7],[1,5.9,15.25],[2,5.8,7.63]],"ltp":6.2,"tv":1697.39,"id":9625551}],"tv":12861.66}]}
{"op":"mcm","clk":"4234602753","pt":1631547756733,"mc":[{"id":"1.187562121","rc":[{"batb":[[1,1.16,120.78],[2,1.15,112.06]],"batl":[[1,1.2,101],[2,1.24,108.98]],"ltp":1.19,"tv":11164.26,"id":20955040},{"batb":[[1,5.1,3.04],[2,4.8,2.93]],"batl":[[0,7.4,5],[1,7.8,5],[2,8.2,3]],"ltp":6.2,"tv":1697.39,"id":9625551}]}]}
{"op":"mcm","clk":"4234602783","pt":1631547757246,"mc":[{"id":"1.187562121","rc":[{"batb":[[0,1.18,2],[1,1.16,113]],"batl":[[0,1.26,109.25],[1,1.53,963.96],[2,3.8,27.43]],"ltp":1.19,"tv":11164.26,"id":20955040},{"batb":[[0,4.8,2.93],[1,4.4,28.18],[2,3,5.96]],"batl":[[0,7.4,3]],"ltp":6.2,"tv":1697.39,"id":9625551}]}]}
{"op":"mcm","clk":"4234602831","pt":1631547758235,"mc":[{"id":"1.187562121","rc":[{"batl":[[1,3.8,27.43],[2,8.8,7.22]],"ltp":1.19,"tv":11164.26,"id":20955040}]}]}
{"op":"mcm","clk":"4234603185","pt":1631547766755,"mc":[{"id":"1.187562121","rc":[{"batb":[[2,1.15,103.43]],"ltp":1.19,"tv":11164.26,"id":20955040},{"batl":[[1,7.8,3]],"ltp":6.2,"tv":1697.39,"id":9625551}]}]}
{"op":"mcm","clk":"4234603284","pt":1631547768845,"mc":[{"id":"1.187562121","rc":[{"trd":[[1.18,271.01]],"batb":[[0,1.16,113],[1,1.15,103.43],[2,1.14,121]],"batl":[[0,1.18,3664.96],[1,1.19,1056.08],[2,1.2,166.66]],"ltp":1.18,"tv":11168.26,"id":20955040},{"batb":[[0,6.8,3.47],[1,6.6,22.72],[2,6.4,11.36]],"batl":[[0,7.2,5.22],[1,7.4,3],[2,7.6,228.62]],"ltp":6.2,"tv":1697.39,"id":9625551}],"tv":12865.66}]}
{"op":"mcm","clk":"4234603345","pt":1631547769831,"mc":[{"id":"1.187562121","rc":[{"batb":[[1,1.15,112.13],[2,1.14,172.83]],"batl":[[0,1.19,1056.08],[1,1.2,166.66],[2,1.21,8.26]],"ltp":1.18,"tv":11168.26,"id":20955040},{"batb":[[1,6.6,4.54],[2,6.4,2.28]],"ltp":6.2,"tv":1697.39,"id":9625551}]}]}
{"op":"mcm","clk":"4234603398","pt":1631547770762,"mc":[{"id":"1.187562121","rc":[{"batb":[[1,1.15,8.7]],"ltp":1.18,"tv":11168.26,"id":20955040}]}]}
{"op":"mcm","clk":"4234603574","pt":1631547773879,"mc":[{"id":"1.187562121","rc":[{"trd":[[1.18,291.01]],"batl":[[0,1.18,107],[1,1.19,1423.06],[2,1.2,268.66]],"ltp":1.18,"tv":11188.26,"id":20955040},{"trd":[[6.8,7.89]],"batb":[[0,6.6,4.54],[1,6.4,8.28],[2,6.2,8.28]],"ltp":6.8,"tv":1700.86,"id":9625551}],"tv":12889.13}]}
{"op":"mcm","clk":"4234603628","pt":1631547774659,"mc":[{"id":"1.187562121","rc":[{"batl":[[1,1.19,1149.08]],"ltp":1.18,"tv":11188.26,"id":20955040}]}]}
{"op":"mcm","clk":"4234603964","pt":1631547780655,"mc":[{"id":"1.187562121","rc":[{"trd":[[1.16,262.28]],"batb":[[0,1.16,109.1]],"ltp":1.16,"tv":11196.06,"id":20955040}],"tv":12896.93}]}
{"op":"mcm","clk":"4234604057","pt":1631547782662,"mc":[{"id":"1.187562121","rc":[{"trd":[[7.2,1.12]],"batl":[[0,7.2,4.66]],"ltp":7.2,"tv":1701.98,"id":9625551}],"tv":12898.04}]}
{"op":"mcm","clk":"4234604091","pt":1631547783490,"mc":[{"id":"1.187562121","rc":[{"batl":[[0,7.4,3],[1,7.6,228.62],[2,7.8,3.84]],"ltp":7.2,"tv":1701.98,"id":9625551}]}]}
{"op":"mcm","clk":"4234604152","pt":1631547784765,"mc":[{"id":"1.187562121","rc":[{"trd":[[1.16,310.82]],"batb":[[0,1.16,84.83]],"ltp":1.16,"tv":11244.6,"id":20955040}],"tv":12946.58}]}
{"op":"mcm","clk":"4234604231","pt":1631547786497,"mc":[{"id":"1.187562121","rc":[{"batl":[[0,1.18,142.63]],"ltp":1.16,"tv":11244.6,"id":20955040},{"batl":[[0,7.2,7.95],[1,7.4,3],[2,7.6,228.62]],"ltp":7.2,"tv":1701.98,"id":9625551}]}]}
{"op":"mcm","clk":"4234604499","pt":1631547793308,"mc":[{"id":"1.187562121","rc":[{"batb":[[0,1.17,14.44],[1,1.16,84.83],[2,1.15,8.7]],"batl":[[0,1.18,107]],"ltp":1.16,"tv":11244.6,"id":20955040},{"batl":[[0,7.4,3],[1,7.6,228.62],[2,7.8,3.84]],"ltp":7.2,"tv":1701.98,"id":9625551}]}]}
{"op":"mcm","clk":"4234604607","pt":1631547795971,"mc":[{"id":"1.187562121","rc":[{"batl":[[0,1.18,142.63]],"ltp":1.16,"tv":11244.6,"id":20955040},{"batl":[[0,7.2,7.95],[1,7.4,3],[2,7.6,228.62]],"ltp":7.2,"tv":1701.98,"id":9625551}]}]}
{"op":"mcm","clk":"4234606459","pt":1631547832633,"mc":[{"id":"1.187562121","rc":[{"trd":[[1.18,298.07]],"batl":[[0,1.18,139.1]],"ltp":1.18,"tv":11251.66,"id":20955040}],"tv":12953.64}]}
{"op":"mcm","clk":"4234608271","pt":1631547856512,"mc":[{"id":"1.187562121","rc":[{"trd":[[1.17,431.29]],"batb":[[0,1.17,14.36]],"ltp":1.17,"tv":11251.82,"id":20955040}],"tv":12953.8}]}
{"op":"mcm","clk":"4234611156","pt":1631547882191,"mc":[{"id":"1.187562121","rc":[{"trd":[[1.17,444.29]],"batb":[[0,1.17,7.86]],"ltp":1.17,"tv":11264.82,"id":20955040}],"tv":12966.8}]}
{"op":"mcm","clk":"4234611825","pt":1631547890727,"mc":[{"id":"1.187562121","rc":[{"batb":[[2,1.14,121]],"batl":[[0,1.18,103.47],[1,1.19,93],[2,1.2,102]],"ltp":1.17,"tv":11264.82,"id":20955040},{"batb":[[0,6.4,6],[1,6.2,6],[2,6,7]],"batl":[[0,7.4,3],[1,8.2,3],[2,8.8,3]],"ltp":7.2,"tv":1701.98,"id":9625551}]}]}
{"op":"mcm","clk":"4234612772","pt":1631547901947,"mc":[{"id":"1.187562121","rc":[{"trd":[[1.18,300.85]],"batl":[[0,1.18,102.08]],"ltp":1.18,"tv":11267.59,"id":20955040}],"tv":12969.57}]}
{"op":"mcm","clk":"4234613617","pt":1631547910146,"mc":[{"id":"1.187562121","rc":[{"batl":[[0,1.2,102],[1,1.39,17.9],[2,1.49,489.22]],"ltp":1.18,"tv":11267.59,"id":20955040},{"batb":[[0,6,7],[1,5.4,34.47],[2,1.46,3.41]],"ltp":7.2,"tv":1701.98,"id":9625551}]}]}
{"op":"mcm","clk":"4234613716","pt":1631547911409,"mc":[{"id":"1.187562121","rc":[{"batb":[[0,1.17,16.41],[1,1.16,135.77]],"batl":[[0,1.2,117.99],[1,1.21,933.35],[2,1.25,47.27]],"ltp":1.18,"tv":11267.59,"id":20955040},{"batl":[[0,6.4,4.75],[1,6.8,209.44],[2,7,30.78]],"ltp":7.2,"tv":1701.98,"id":9625551}]}]}
{"op":"mcm","clk":"4234613848","pt":1631547912730,"mc":[{"id":"1.187562121","rc":[{"batb":[[2,1.15,233.19]],"batl":[[2,1.23,8.13]],"ltp":1.18,"tv":11267.59,"id":20955040},{"batb":[[1,5.7,5.26],[2,5.6,2.64]],"ltp":7.2,"tv":1701.98,"id":9625551}]}]}
{"op":"mcm","clk":"4234613926","pt":1631547913621,"mc":[{"id":"1.187562121","rc":[{"batb":[[0,1.18,106],[1,1.17,16.41],[2,1.16,135.77]],"ltp":1.18,"tv":11267.59,"id":20955040}]}]}
{"op":"mcm","clk":"4234614289","pt":1631547917829,"mc":[{"id":"1.187562121","rc":[{"batb":[[2,1.16,288.05]],"batl":[[1,1.21,1051.85],[2,1.22,129.75]],"ltp":1.18,"tv":11267.59,"id":20955040},{"batb":[[1,5.7,8.38]],"ltp":7.2,"tv":1701.98,"id":9625551}]}]}
{"op":"mcm","clk":"4234614295","pt":1631547917933,"mc":[{"id":"1.187562121","rc":[{"batb":[[2,1.16,295.58]],"ltp":1.18,"tv":11267.59,"id":20955040}]}]}
{"op":"mcm","clk":"4234614878","pt":1631547924763,"mc":[{"id":"1.187562121","rc":[{"batb":[[1,1.17,7.86]],"batl":[[0,1.2,102],[1,1.21,118.5]],"ltp":1.18,"tv":11267.59,"id":20955040},{"batb":[[1,5.7,3.12],[2,5.5,2.8]],"batl":[[0,7.4,7],[1,7.8,7],[2,8.2,3]],"ltp":7.2,"tv":1701.98,"id":9625551}]}]}
{"op":"mcm","clk":"4234614963","pt":1631547925711,"mc":[{"id":"1.187562121","rc":[{"batb":[[0,1.17,7.86],[1,1.16,84.83],[2,1.15,307.86]],"batl":[[0,1.22,129.75],[1,1.39,17.9],[2,1.49,489.22]],"ltp":1.18,"tv":11267.59,"id":20955040},{"batb":[[0,5.5,2.8],[1,5.1,20.22],[2,1.46,3.41]],"batl":[[0,7.4,3]],"ltp":7.2,"tv":1701.98,"id":9625551}]}]}
{"op":"mcm","clk":"4234615237","pt":1631547928895,"mc":[{"id":"1.187562121","rc":[{"batb":[[1,1.16,255.89]],"batl":[[0,1.21,119.5],[1,1.22,129.75],[2,1.39,17.9]],"ltp":1.18,"tv":11267.59,"id":20955040},{"batb":[[0,5.7,2.82],[1,5.5,2.8],[2,5.1,20.22]],"batl":[[0,6,2.52],[1,7.4,7],[2,7.8,7]],"ltp":7.2,"tv":1701.98,"id":9625551}]}]}
{"op":"mcm","clk":"4234615272","pt":1631547929310,"mc":[{"id":"1.187562121","rc":[{"batb":[[1,1.16,84.83]],"batl":[[0,1.22,129.75],[1,1.39,17.9],[2,1.49,489.22]],"ltp":1.18,"tv":11267.59,"id":20955040},{"batb":[[0,5.5,2.8],[1,5.1,20.22],[2,1.46,3.41]],"batl":[[1,7.4,3]],"ltp":7.2,"tv":1701.98,"id":9625551}]}]}
{"op":"mcm","clk":"4234615832","pt":1631547935909,"mc":[{"id":"1.187562121","rc":[{"batb":[[1,1.16,242.61]],"batl":[[0,1.21,120.5],[1,1.22,129.75],[2,1.39,17.9]],"ltp":1.18,"tv":11267.59,"id":20955040},{"batb":[[0,5.7,3.22],[1,5.5,2.8],[2,5.1,20.22]],"batl":[[1,7.4,5]],"ltp":7.2,"tv":1701.98,"id":9625551}]}]}
{"op":"mcm","clk":"4234615873","pt":1631547936386,"mc":[{"id":"1.187562121","rc":[{"batb":[[1,1.16,84.83]],"batl":[[0,1.22,129.75],[1,1.39,17.9],[2,1.49,489.22]],"ltp":1.18,"tv":11267.59,"id":20955040},{"batb":[[0,5.5,2.8],[1,5.1,20.22],[2,1.46,3.41]],"batl":[[0,7.4,3],[1,7.8,7],[2,8.2,3]],"ltp":7.2,"tv":1701.98,"id":9625551}]}]}
{"op":"mcm","clk":"4234615991","pt":1631547937909,"mc":[{"id":"1.187562121","rc":[{"batb":[[0,1.2,22.65],[1,1.19,100.84],[2,1.18,8.47]],"batl":[[0,1.22,166.05],[1,1.23,983.09],[2,1.27,46.53]],"ltp":1.18,"tv":11267.59,"id":20955040},{"batl":[[0,6,5.41],[1,6.2,182.1],[2,6.4,7.26]],"ltp":7.2,"tv":1701.98,"id":9625551}]}]}
{"op":"mcm","clk":"4234616072","pt":1631547938801,"mc":[{"id":"1.187562121","rc":[{"batl":[[1,1.23,1007.49],[2,1.24,12.2]],"ltp":1.18,"tv":11267.59,"id":20955040},{"batb":[[2,4.8,22.98]],"ltp":7.2,"tv":1701.98,"id":9625551}]}]}
{"op":"mcm","clk":"4234616166","pt":1631547939809,"mc":[{"id":"1.187562121","rc":[{"batb":[[1,1.19,203.84],[2,1.18,114.47]],"batl":[[0,1.22,168.05]],"ltp":1.18,"tv":11267.59,"id":20955040},{"batl":[[2,6.4,10.26]],"ltp":7.2,"tv":1701.98,"id":9625551}]}]}
{"op":"mcm","clk":"4234616517","pt":1631547944205,"mc":[{"id":"1.187562121","rc":[{"batb":[[2,1.18,281.69]],"batl":[[1,1.23,1136.99]],"ltp":1.18,"tv":11267.59,"id":20955040},{"batb":[[1,5.3,3.38],[2,5.1,20.22]],"ltp":7.2,"tv":1701.98,"id":9625551}]}]}
{"op":"mcm","clk":"4234616861","pt":1631547948201,"mc":[{"id":"1.187562121","rc":[{"trd":[[1.22,172.05]],"batl":[[0,1.23,1136.99],[1,1.24,12.2],[2,1.25,20.2]],"ltp":1.22,"tv":11435.64,"id":20955040},{"trd":[[5.5,53.38]],"batb":[[0,5.3,3.38],[1,5.1,20.22],[2,4.8,22.98]],"batl":[[0,5.5,9.92],[1,6,5.41],[2,6.2,182.1]],"ltp":5.5,"tv":1744.86,"id":9625551}],"tv":13180.5}]}
{"op":"mcm","clk":"4234617005","pt":1631547949725,"mc":[{"id":"1.187562121","rc":[{"batb":[[0,1.2,5.62],[1,1.19,103],[2,1.18,273.22]],"batl":[[0,1.23,129.5],[1,1.27,46.53],[2,1.49,489.22]],"ltp":1.22,"tv":11435.64,"id":20955040},{"batl":[[1,6,2],[2,6.4,3]],"ltp":5.5,"tv":1744.86,"id":9625551}]}]}
{"op":"mcm","clk":"4234617077","pt":1631547950621,"mc":[{"id":"1.187562121","rc":[{"batb":[[1,1.18,273.22],[2,1.17,254.8]],"batl":[[0,1.49,489.22],[1,3.8,27.43],[2,8.8,7.22]],"ltp":1.22,"tv":11435.64,"id":20955040},{"batb":[[0,4.8,22.98],[1,1.46,3.41],[2,1.01,105.79]],"batl":[[2,6.6,4]],"ltp":5.5,"tv":1744.86,"id":9625551}]}]}
{"op":"mcm","clk":"4234617151","pt":1631547951613,"mc":[{"id":"1.187562121","rc":[{"batb":[[1,1.18,106]],"batl":[[0,1.24,112.73],[1,1.25,102.98],[2,1.49,489.22]],"ltp":1.22,"tv":11435.64,"id":20955040},{"trd":[[5.5,57.38]],"batb":[[0,5.1,2.34],[1,5,2.31],[2,4.8,22.98]],"batl":[[0,5.5,7.92],[2,7,7]],"ltp":5.5,"tv":1748.86,"id":9625551}],"tv":13184.5}]}
{"op":"mcm","clk":"4234617194","pt":1631547952092,"mc":[{"id":"1.187562121","rc":[{"batl":[[0,1.25,102.98],[1,1.49,489.22],[2,3.8,27.43]],"ltp":1.22,"tv":11435.64,"id":20955040},{"batb":[[0,5,2.31],[1,4.8,22.98],[2,1.46,3.41]],"ltp":5.5,"tv":1748.86,"id":9625551}]}]}
{"op":"mcm","clk":"4234617300","pt":1631547953191,"mc":[{"id":"1.187562121","rc":[{"trd":[[1.22,207.75]],"batl":[[0,1.23,122.5],[1,1.25,102.98],[2,1.49,489.22]],"ltp":1.22,"tv":11471.34,"id":20955040},{"trd":[[5.5,65.3]],"batb":[[0,5.3,2.08],[1,5,2.31],[2,4.8,22.98]],"batl":[[0,6,2],[1,7,7],[2,7.4,7]],"ltp":5.5,"tv":1756.78,"id":9625551}],"tv":13228.12}]}
{"op":"mcm","clk":"4234618162","pt":1631547961824,"mc":[{"id":"1.187562121","rc":[{"batb":[[1,1.18,113.47]],"ltp":1.22,"tv":11471.34,"id":20955040},{"batl":[[1,6.6,2],[2,7,7]],"ltp":5.5,"tv":1756.78,"id":9625551}]}]}
{"op":"mcm","clk":"4234618193","pt":1631547962147,"mc":[{"id":"1.187562121","rc":[{"batb":[[1,1.18,106]],"ltp":1.22,"tv":11471.34,"id":20955040},{"batl":[[1,7,7],[2,7.4,7]],"ltp":5.5,"tv":1756.78,"id":9625551}]}]}
{"op":"mcm","clk":"4234618525","pt":1631547965723,"mc":[{"id":"1.187562121","rc":[{"batb":[[0,1.18,106],[1,1.17,254.8],[2,1.16,269.14]],"ltp":1.22,"tv":11471.34,"id":20955040},{"batl":[[0,7,7],[1,7.4,7],[2,7.8,5]],"ltp":5.5,"tv":1756.78,"id":9625551}]}]}
{"op":"mcm","clk":"4234618971","pt":1631547970743,"mc":[{"id":"1.187562121","rc":[{"batb":[[0,5.5,2.12],[1,5.3,2.08],[2,5,2.31]],"ltp":5.5,"tv":1756.78,"id":9625551}]}]}
{"op":"mcm","clk":"4234618998","pt":1631547971116,"mc":[{"id":"1.187562121","rc":[{"batb":[[0,5.3,2.08],[1,5,2.31],[2,4.8,22.98]],"ltp":5.5,"tv":1756.78,"id":9625551}]}]}
{"op":"mcm","clk":"4234619145","pt":1631547973114,"mc":[{"id":"1.187562121","rc":[{"trd":[[1.23,10.65]],"batl":[[0,1.23,120.62]],"ltp":1.23,"tv":11473.22,"id":20955040},{"trd":[[5.3,46.89]],"batb":[[0,5,2.31],[1,4.8,22.98],[2,1.46,3.41]],"ltp":5.3,"tv":1761.37,"id":9625551}],"tv":13234.6}]}
{"op":"mcm","clk":"4234619495","pt":1631547976857,"mc":[{"id":"1.187562121","rc":[{"batb":[[0,1.2,657.15],[1,1.18,106],[2,1.17,254.8]],"batl":[[1,1.24,713.28],[2,1.25,102.98]],"ltp":1.23,"tv":11473.22,"id":20955040},{"batb":[[0,5.3,2.08],[1,5,2.31],[2,4.8,22.98]],"batl":[[0,5.5,36.01],[1,5.6,13.64],[2,5.7,730.02]],"ltp":5.3,"tv":1761.37,"id":9625551}]}]}
{"op":"mcm","clk":"4234619593","pt":1631547977857,"mc":[{"id":"1.187562121","rc":[{"batb":[[1,1.19,240.82],[2,1.18,106]],"ltp":1.23,"tv":11473.22,"id":20955040},{"batb":[[2,4.8,54.22]],"batl":[[0,5.5,14.19],[1,5.6,2.72],[2,5.7,37.8]],"ltp":5.3,"tv":1761.37,"id":9625551}]}]}
{"op":"mcm","clk":"4234619675","pt":1631547978760,"mc":[{"id":"1.187562121","rc":[{"batb":[[0,1.2,757.15],[1,1.19,343.82]],"batl":[[0,1.23,122.62]],"ltp":1.23,"tv":11473.22,"id":20955040},{"batb":[[2,4.8,29.22]],"ltp":5.3,"tv":1761.37,"id":9625551}]}]}
{"op":"mcm","clk":"4234619927","pt":1631547981762,"mc":[{"id":"1.187562121","rc":[{"batl":[[2,1.25,367.41]],"ltp":1.23,"tv":11473.22,"id":20955040},{"batl":[[1,5.6,5.8]],"ltp":5.3,"tv":1761.37,"id":9625551}]}]}
{"op":"mcm","clk":"4234619951","pt":1631547981970,"mc":[{"id":"1.187562121","rc":[{"batl":[[2,1.25,102.98]],"ltp":1.23,"tv":11473.22,"id":20955040},{"batl":[[1,5.6,2.72]],"ltp":5.3,"tv":1761.37,"id":9625551}]}]}
{"op":"mcm","clk":"4234620099","pt":1631547983254,"mc":[{"id":"1.187562121","rc":[{"batb":[[0,1.2,879.32]],"batl":[[1,1.24,817.51]],"ltp":1.23,"tv":11473.22,"id":20955040},{"batb":[[1,5.1,2.04],[2,5,2.31]],"ltp":5.3,"tv":1761.37,"id":9625551}]}]}
{"op":"mcm","clk":"4234621000","pt":1631547995655,"mc":[{"id":"1.187562121","rc":[{"batb":[[0,1.2,222.17]],"batl":[[1,1.24,104.23]],"ltp":1.23,"tv":11473.22,"id":20955040},{"batl":[[0,6,2],[1,6.4,3],[2,7,7]],"ltp":5.3,"tv":1761.37,"id":9625551}]}]}
{"op":"mcm","clk":"4234621104","pt":1631547996866,"mc":[{"id":"1.187562121","rc":[{"batb":[[1,1.19,103]],"batl":[[0,1.24,104.23],[1,3.8,27.43],[2,8.8,7.22]],"ltp":1.23,"tv":11473.22,"id":20955040},{"batb":[[0,5.1,2.04],[1,4.6,25.33],[2,1.46,3.41]],"ltp":5.3,"tv":1761.37,"id":9625551}]}]}
{"op":"mcm","clk":"4234621518","pt":1631548002849,"mc":[{"id":"1.187562121","rc":[{"batl":[[0,1.23,117.5],[1,1.24,104.23],[2,3.8,27.43]],"ltp":1.23,"tv":11473.22,"id":20955040},{"batb":[[0,5.3,2.08],[1,5.1,2.04],[2,4.6,25.33]],"ltp":5.3,"tv":1761.37,"id":9625551}]}]}
{"op":"mcm","clk":"4234621532","pt":1631548003077,"mc":[{"id":"1.187562121","rc":[{"batl":[[0,1.24,104.23],[1,3.8,27.43],[2,8.8,7.22]],"ltp":1.23,"tv":11473.22,"id":20955040},{"batb":[[0,5.1,2.04],[1,4.6,25.33],[2,1.46,3.41]],"ltp":5.3,"tv":1761.37,"id":9625551}]}]}
{"op":"mcm","clk":"4234622050","pt":1631548009795,"mc":[{"id":"1.187562121","rc":[{"batl":[[0,1.23,62.4],[1,1.24,124.49],[2,1.25,172.2]],"ltp":1.23,"tv":11473.22,"id":20955040},{"batb":[[0,5.5,146.59],[1,5.1,2.04],[2,4.6,25.33]],"batl":[[0,5.7,3.53],[1,6,2],[2,6.2,138.9]],"ltp":5.3,"tv":1761.37,"id":9625551}]}]}
{"op":"mcm","clk":"4234622139","pt":1631548010796,"mc":[{"id":"1.187562121","rc":[{"batb":[[1,1.19,128.2],[2,1.18,127.07]],"ltp":1.23,"tv":11473.22,"id":20955040},{"batb":[[1,5.1,21.67],[2,4.9,22.14]],"ltp":5.3,"tv":1761.37,"id":9625551}]}]}
{"op":"mcm","clk":"4234622206","pt":1631548011483,"mc":[{"id":"1.187562121","rc":[{"batl":[[0,1.23,64.4]],"ltp":1.23,"tv":11473.22,"id":20955040}]}]}
{"op":"mcm","clk":"4234622630","pt":1631548016402,"mc":[{"id":"1.187562121","rc":[{"batb":[[1,1.19,278.91]],"ltp":1.23,"tv":11473.22,"id":20955040}]}]}
{"op":"mcm","clk":"4234622741","pt":1631548017804,"mc":[{"id":"1.187562121","rc":[{"batl":[[0,1.23,146.4]],"ltp":1.23,"tv":11473.22,"id":20955040}]}]}
{"op":"mcm","clk":"4234622889","pt":1631548019581,"mc":[{"id":"1.187562121","rc":[{"batl":[[0,1.23,256.9]],"ltp":1.23,"tv":11473.22,"id":20955040},{"batb":[[1,5.3,2.08],[2,5.1,21.67]],"ltp":5.3,"tv":1761.37,"id":9625551}]}]}
{"op":"mcm","clk":"4234623360","pt":1631548025805,"mc":[{"id":"1.187562121","rc":[{"batb":[[0,1.2,100],[1,1.19,253.71],[2,1.18,106]],"batl":[[0,1.23,84],[1,3.8,27.43],[2,8.8,7.22]],"ltp":1.23,"tv":11473.22,"id":20955040},{"batb":[[0,5.1,2.04],[1,4.9,22.14],[2,1.46,3.41]],"batl":[[0,6.4,5.02],[1,7,7],[2,7.4,7]],"ltp":5.3,"tv":1761.37,"id":9625551}]}]}
{"op":"mcm","clk":"4234623448","pt":1631548026901,"mc":[{"id":"1.187562121","rc":[{"batb":[[0,1.19,253.71],[1,1.18,106],[2,1.17,246.94]],"batl":[[0,3.8,27.43],[1,8.8,7.22],[2,44,7.22]],"ltp":1.23,"tv":11473.22,"id":20955040}]}]}
{"op":"mcm","clk":"4234623593","pt":1631548028730,"mc":[{"id":"1.187562121","rc":[{"batb":[[0,1.2,125.87],[1,1.19,253.71],[2,1.18,106]],"batl":[[0,1.23,112.5],[1,1.24,91.48],[2,3.8,27.43]],"ltp":1.23,"tv":11473.22,"id":20955040},{"batb":[[0,5.3,2.08],[1,5.1,2.04],[2,4.9,22.14]],"batl":[[0,6,2],[1,6.4,5.02],[2,7,7]],"ltp":5.3,"tv":1761.37,"id":9625551}]}]}
{"op":"mcm","clk":"4234623621","pt":1631548028994,"mc":[{"id":"1.187562121","rc":[{"batb":[[0,1.19,253.71],[1,1.18,106],[2,1.17,246.94]],"batl":[[0,1.24,91.48],[1,3.8,27.43],[2,8.8,7.22]],"ltp":1.23,"tv":11473.22,"id":20955040},{"batb":[[0,5.1,2.04],[1,4.9,22.14],[2,1.46,3.41]],"batl":[[0,6.4,5.02],[1,7,7],[2,7.4,7]],"ltp":5.3,"tv":1761.37,"id":9625551}]}]}
{"op":"mcm","clk":"4234623933","pt":1631548032717,"mc":[{"id":"1.187562121","rc":[{"batb":[[0,1.2,140.92],[1,1.19,253.71],[2,1.18,106]],"batl":[[0,1.23,106.5],[1,1.24,91.48],[2,3.8,27.43]],"ltp":1.23,"tv":11473.22,"id":20955040},{"batb":[[0,5.3,2.08],[1,5.1,2.04],[2,4.9,22.14]],"batl":[[0,6,2.01],[1,6.4,5.02],[2,7,7]],"ltp":5.3,"tv":1761.37,"id":9625551}]}]}
{"op":"mcm","clk":"4234623963","pt":1631548033245,"mc":[{"id":"1.187562121","rc":[{"batb":[[0,1.19,253.71],[1,1.18,106],[2,1.17,246.94]],"batl":[[0,1.24,91.48],[1,3.8,27.43],[2,8.8,7.22]],"ltp":1.23,"tv":11473.22,"id":20955040},{"batb":[[0,5.1,2.04],[1,4.9,22.14],[2,1.46,3.41]],"batl":[[0,6.4,5.02],[1,7,7],[2,7.4,7]],"ltp":5.3,"tv":1761.37,"id":9625551}]}]}
{"op":"mcm","clk":"4234624453","pt":1631548039671,"mc":[{"id":"1.187562121","rc":[{"batl":[[0,1.23,55],[1,1.24,91.48],[2,3.8,27.43]],"ltp":1.23,"tv":11473.22,"id":20955040}]}]}
{"op":"mcm","clk":"4234624508","pt":1631548040257,"mc":[{"id":"1.187562121","rc":[{"batl":[[0,1.24,91.48],[1,3.8,27.43],[2,8.8,7.22]],"ltp":1.23,"tv":11473.22,"id":20955040}]}]}
{"op":"mcm","clk":"4234625522","pt":1631548052736,"mc":[{"id":"1.187562121","rc":[{"batb":[[0,1.19,150.71],[1,1.17,137.94],[2,1.16,184.31]],"ltp":1.23,"tv":11473.22,"id":20955040},{"batl":[[0,6.4,2.02],[1,7,4],[2,7.4,4]],"ltp":5.3,"tv":1761.37,"id":9625551}]}]}
{"op":"mcm","clk":"4234625554","pt":1631548053049,"mc":[{"id":"1.187562121","rc":[{"batb":[[1,1.17,6.97],[2,1.16,7.28]],"ltp":1.23,"tv":11473.22,"id":20955040},{"batl":[[1,7,2],[2,7.4,2]],"ltp":5.3,"tv":1761.37,"id":9625551}]}]}
{"op":"mcm","clk":"4234626119","pt":1631548059276,"mc":[{"id":"1.187562121","rc":[{"batb":[[0,1.19,174.81],[2,1.16,58.22]],"batl":[[0,1.21,1391.08],[1,1.22,8.2],[2,1.24,91.48]],"ltp":1.23,"tv":11473.22,"id":20955040},{"batb":[[0,5.8,15.52],[1,5.7,10.97],[2,5.6,29.18]],"batl":[[1,6.8,134.12],[2,7,2]],"ltp":5.3,"tv":1761.37,"id":9625551}]}]}
{"op":"mcm","clk":"4234626210","pt":1631548060386,"mc":[{"id":"1.187562121","rc":[{"batb":[[2,1.16,66.84]],"ltp":1.23,"tv":11473.22,"id":20955040},{"batb":[[0,5.8,5.18],[1,5.7,5.8],[2,5.6,55.88]],"batl":[[1,6.6,4.54],[2,6.8,136.4]],"ltp":5.3,"tv":1761.37,"id":9625551}]}]}
{"op":"mcm","clk":"4234626645","pt":1631548065791,"mc":[{"id":"1.187562121","rc":[{"batb":[[1,1.17,172.94],[2,1.16,199.12]],"batl":[[2,1.23,113.5]],"ltp":1.23,"tv":11473.22,"id":20955040}]}]}
{"op":"mcm","clk":"4234626940","pt":1631548069088,"mc":[{"id":"1.187562121","rc":[{"batl":[[0,1.21,1455.08]],"ltp":1.23,"tv":11473.22,"id":20955040}]}]}
{"op":"mcm","clk":"4234627883","pt":1631548079913,"mc":[{"id":"1.187562121","rc":[{"batb":[[0,1.12,302.3],[1,1.11,694.47],[2,1.01,107.79]],"batl":[[0,1.21,64],[1,1.23,113.5],[2,1.24,91.48]],"ltp":1.23,"tv":11473.22,"id":20955040},{"batb":[[0,5.3,2.08],[1,5.2,19.63],[2,5.1,2.04]],"batl":[[0,7.4,2],[1,990,0.01],[2,6.8,0]],"ltp":5.3,"tv":1761.37,"id":9625551}]}]}
{"op":"mcm","clk":"4234627974","pt":1631548080876,"mc":[{"id":"1.187562121","rc":[{"batl":[[0,1.23,113.5],[1,1.24,91.48],[2,3.8,27.43]],"ltp":1.23,"tv":11473.22,"id":20955040}]}]}
{"op":"mcm","clk":"4234627999","pt":1631548081189,"mc":[{"id":"1.187562121","rc":[{"batl":[[0,1.24,91.48],[1,3.8,27.43],[2,8.8,7.22]],"ltp":1.23,"tv":11473.22,"id":20955040},{"batb":[[0,5.2,19.63],[1,5.1,2.04],[2,1.46,3.41]],"ltp":5.3,"tv":1761.37,"id":9625551}]}]}
{"op":"mcm","clk":"4234628134","pt":1631548082702,"mc":[{"id":"1.187562121","rc":[{"batb":[[0,1.17,166.97],[1,1.16,136.53],[2,1.12,302.3]],"ltp":1.23,"tv":11473.22,"id":20955040},{"batl":[[0,7,2],[1,7.4,2],[2,990,0.01]],"ltp":5.3,"tv":1761.37,"id":9625551}]}]}
{"op":"mcm","clk":"4234628160","pt":1631548082970,"mc":[{"id":"1.187562121","rc":[{"batb":[[0,1.16,136.53],[1,1.12,302.3],[2,1.11,694.47]],"ltp":1.23,"tv":11473.22,"id":20955040},{"batl":[[0,7.4,2],[1,990,0.01],[2,990,0]],"ltp":5.3,"tv":1761.37,"id":9625551}]}]}
{"op":"mcm","clk":"4234628299","pt":1631548084676,"mc":[{"id":"1.187562121","rc":[{"batl":[[0,1.23,98.5],[1,1.24,91.48],[2,3.8,27.43]],"ltp":1.23,"tv":11473.22,"id":20955040},{"batb":[[0,5.3,2.08],[1,5.2,19.63],[2,5.1,2.04]],"ltp":5.3,"tv":1761.37,"id":9625551}]}]}
{"op":"mcm","clk":"4234628320","pt":1631548084994,"mc":[{"id":"1.187562121","rc":[{"batl":[[0,1.24,91.48],[1,3.8,27.43],[2,8.8,7.22]],"ltp":1.23,"tv":11473.22,"id":20955040},{"batb":[[0,5.2,19.63],[1,5.1,2.04],[2,1.46,3.41]],"ltp":5.3,"tv":1761.37,"id":9625551}]}]}
{"op":"mcm","clk":"4234628499","pt":1631548087184,"mc":[{"id":"1.187562121","rc":[{"batb":[[2,1.01,107.79]],"ltp":1.23,"tv":11473.22,"id":20955040}]}]}
{"op":"mcm","clk":"4234628656","pt":1631548088889,"mc":[{"id":"1.187562121","rc":[{"trd":[[1.21,94.33]],"batb":[[0,1.18,58.55],[1,1.16,136.53],[2,1.12,302.3]],"batl":[[0,1.23,1143.83],[1,1.24,91.48],[2,1.28,46.16]],"ltp":1.21,"tv":11475.22,"id":20955040},{"trd":[[5.7,6.79]],"batb":[[0,5.3,2.08],[1,5.2,19.63],[2,5.1,2.04]],"batl":[[0,5.7,4.24],[1,5.8,5.18],[2,5.9,36.48]],"ltp":5.7,"tv":1761.79,"id":9625551}],"tv":13237.02}]}
{"op":"mcm","clk":"4234628752","pt":1631548089789,"mc":[{"id":"1.187562121","rc":[{"batb":[[1,1.17,212.3],[2,1.16,136.53]],"batl":[[2,1.25,8]],"ltp":1.21,"tv":11475.22,"id":20955040},{"batb":[[2,5.1,7.92]],"ltp":5.7,"tv":1761.79,"id":9625551}]}]}
{"op":"mcm","clk":"4234628893","pt":1631548091904,"mc":[{"id":"1.187562121","rc":[{"batl":[[0,1.23,1035.33]],"ltp":1.21,"tv":11475.22,"id":20955040},{"batb":[[0,5.2,19.63],[1,5.1,7.92],[2,5,2.94]],"ltp":5.7,"tv":1761.79,"id":9625551}]}]}
{"op":"mcm","clk":"4234628905","pt":1631548092110,"mc":[{"id":"1.187562121","rc":[{"batb":[[0,1.19,2],[1,1.18,58.55],[2,1.17,212.3]],"ltp":1.21,"tv":11475.22,"id":20955040}]}]}
{"op":"mcm","clk":"4234629068","pt":1631548093904,"mc":[{"id":"1.187562121","rc":[{"batl":[[0,1.23,1117.33]],"ltp":1.21,"tv":11475.22,"id":20955040}]}]}
{"op":"mcm","clk":"4234629353","pt":1631548096807,"mc":[{"id":"1.187562121","rc":[{"trd":[[1.21,94.41]],"ltp":1.21,"tv":11475.3,"id":20955040},{"trd":[[5.7,6.81]],"batl":[[0,5.7,4.22]],"ltp":5.7,"tv":1761.81,"id":9625551}],"tv":13237.12}]}
{"op":"mcm","clk":"4234629382","pt":1631548097113,"mc":[{"id":"1.187562121","rc":[{"batl":[[0,5.7,54.22]],"ltp":5.7,"tv":1761.81,"id":9625551}]}]}
{"op":"mcm","clk":"4234629538","pt":1631548099102,"mc":[{"id":"1.187562121","rc":[{"batl":[[0,1.23,1084.3]],"ltp":1.21,"tv":11475.3,"id":20955040},{"batl":[[0,5.7,50]],"ltp":5.7,"tv":1761.81,"id":9625551}]}]}
{"op":"mcm","clk":"4234629828","pt":1631548102000,"mc":[{"id":"1.187562121","rc":[{"batl":[[0,1.23,1119.37]],"ltp":1.21,"tv":11475.3,"id":20955040},{"batl":[[0,5.7,4.22]],"ltp":5.7,"tv":1761.81,"id":9625551}]}]}
{"op":"mcm","clk":"4234630071","pt":1631548105013,"mc":[{"id":"1.187562121","rc":[{"batl":[[0,5.6,50],[1,5.7,4.22],[2,5.8,5.18]],"ltp":5.7,"tv":1761.81,"id":9625551}]}]}
{"op":"mcm","clk":"4234630227","pt":1631548107084,"mc":[{"id":"1.187562121","rc":[{"batl":[[0,1.23,1084.3]],"ltp":1.21,"tv":11475.3,"id":20955040},{"batl":[[1,5.8,5.18],[2,5.9,36.48]],"ltp":5.7,"tv":1761.81,"id":9625551}]}]}
{"op":"mcm","clk":"4234630425","pt":1631548109940,"mc":[{"id":"1.187562121","rc":[{"batl":[[0,1.23,1119.37]],"ltp":1.21,"tv":11475.3,"id":20955040},{"batl":[[1,5.7,4.22],[2,5.8,5.18]],"ltp":5.7,"tv":1761.81,"id":9625551}]}]}
{"op":"mcm","clk":"4234631598","pt":1631548125758,"mc":[{"id":"1.187562121","rc":[{"batb":[[1,1.18,8.47]],"ltp":1.21,"tv":11475.3,"id":20955040}]}]}
{"op":"mcm","clk":"4234633413","pt":1631548148991,"mc":[{"id":"1.187562121","rc":[{"batb":[[0,1.2,123.57],[1,1.19,134.71],[2,1.18,8.47]],"ltp":1.21,"tv":11475.3,"id":20955040}]}]}
{"op":"mcm","clk":"4234633928","pt":1631548154887,"mc":[{"id":"1.187562121","rc":[{"batb":[[2,1.15,235.87]],"batl":[[0,1.29,76.5],[1,3.8,27.43],[2,8.8,7.22]],"ltp":1.21,"tv":11475.3,"id":20955040},{"batb":[[0,4.5,26.76],[1,4.4,2.46],[2,1.46,3.41]],"batl":[[1,6,2],[2,6.4,2.04]],"ltp":5.7,"tv":1761.81,"id":9625551}]}]}
{"op":"mcm","clk":"4234634471","pt":1631548159881,"mc":[{"id":"1.187562121","rc":[{"batl":[[1,5.9,113.08],[2,6,2]],"ltp":5.7,"tv":1761.81,"id":9625551}]}]}
{"op":"mcm","clk":"4234634533","pt":1631548160299,"mc":[{"id":"1.187562121","rc":[{"batl":[[1,6,2],[2,6.4,2.04]],"ltp":5.7,"tv":1761.81,"id":9625551}]}]}
{"op":"mcm","clk":"4234634947","pt":1631548164718,"mc":[{"id":"1.187562121","rc":[{"batl":[[0,1.27,91.5],[1,1.29,76.5],[2,3.8,27.43]],"ltp":1.21,"tv":11475.3,"id":20955040},{"batb":[[0,4.7,2.32],[1,4.5,26.76],[2,4.4,2.46]],"ltp":5.7,"tv":1761.81,"id":9625551}]}]}
{"op":"mcm","clk":"4234634968","pt":1631548164987,"mc":[{"id":"1.187562121","rc":[{"batl":[[0,1.29,76.5],[1,3.8,27.43],[2,8.8,7.22]],"ltp":1.21,"tv":11475.3,"id":20955040},{"batb":[[0,4.5,26.76],[1,4.4,2.46],[2,1.46,3.41]],"ltp":5.7,"tv":1761.81,"id":9625551}]}]}
{"op":"mcm","clk":"4234635513","pt":1631548171813,"mc":[{"id":"1.187562121","rc":[{"batl":[[0,1.27,82.5],[1,1.29,76.5],[2,3.8,27.43]],"ltp":1.21,"tv":11475.3,"id":20955040},{"batb":[[0,4.7,2.32],[1,4.5,26.76],[2,4.4,2.46]],"ltp":5.7,"tv":1761.81,"id":9625551}]}]}
{"op":"mcm","clk":"4234635536","pt":1631548172084,"mc":[{"id":"1.187562121","rc":[{"batl":[[0,1.29,76.5],[1,3.8,27.43],[2,8.8,7.22]],"ltp":1.21,"tv":11475.3,"id":20955040},{"batb":[[0,4.5,26.76],[1,4.4,2.46],[2,1.46,3.41]],"ltp":5.7,"tv":1761.81,"id":9625551}]}]}
{"op":"mcm","clk":"4234635681","pt":1631548173809,"mc":[{"id":"1.187562121","rc":[{"trd":[[1.25,15.42]],"batb":[[0,1.22,8.2],[1,1.21,48.84],[2,1.2,123.57]],"batl":[[0,1.27,881.12],[1,1.29,76.5],[2,1.32,44.76]],"ltp":1.25,"tv":11477.3,"id":20955040},{"trd":[[5,0.5]],"batl":[[0,5,5.07],[1,5.1,45.1],[2,5.2,2.94]],"ltp":5.0,"tv":1762.31,"id":9625551}],"tv":13239.62}]}
{"op":"mcm","clk":"4234635733","pt":1631548174394,"mc":[{"id":"1.187562121","rc":[{"batb":[[2,1.2,296.53]],"batl":[[1,1.29,84.25]],"ltp":1.25,"tv":11477.3,"id":20955040},{"batb":[[0,4.5,33.42],[1,4.4,5.8],[2,4.3,3.34]],"ltp":5.0,"tv":1762.31,"id":9625551}]}]}
{"op":"mcm","clk":"4234636039","pt":1631548177912,"mc":[{"id":"1.187562121","rc":[{"batb":[[1,1.21,50.84]],"batl":[[1,1.28,240.75],[2,1.29,84.25]],"ltp":1.25,"tv":11477.3,"id":20955040},{"batl":[[1,5.1,52.4]],"ltp":5.0,"tv":1762.31,"id":9625551}]}]}
{"op":"mcm","clk":"4234636064","pt":1631548178126,"mc":[{"id":"1.187562121","rc":[{"batl":[[1,1.29,84.25],[2,1.32,44.76]],"ltp":1.25,"tv":11477.3,"id":20955040},{"batl":[[1,5.1,45.1]],"ltp":5.0,"tv":1762.31,"id":9625551}]}]}
{"op":"mcm","clk":"4234636193","pt":1631548179495,"mc":[{"id":"1.187562121","rc":[{"batb":[[0,1.22,121.04]],"batl":[[2,1.32,129.62]],"ltp":1.25,"tv":11477.3,"id":20955040}]}]}
{"op":"mcm","clk":"4234636253","pt":1631548180226,"mc":[{"id":"1.187562121","rc":[{"batl":[[0,1.27,953.12]],"ltp":1.25,"tv":11477.3,"id":20955040}]}]}
{"op":"mcm","clk":"4234636560","pt":1631548183812,"mc":[{"id":"1.187562121","rc":[{"batb":[[0,1.21,2],[1,1.2,123.57],[2,1.19,134.71]],"batl":[[0,1.34,72.25],[1,3.8,27.43],[2,8.8,7.22]],"ltp":1.25,"tv":11477.3,"id":20955040},{"batb":[[0,3.95,37.66],[1,3.9,3.16],[2,1.46,3.41]],"batl":[[0,5.6,50],[1,6,2],[2,6.4,2.04]],"ltp":5.0,"tv":1762.31,"id":9625551}]}]}
{"op":"mcm","clk":"4234637571","pt":1631548197733,"mc":[{"id":"1.187562121","rc":[{"batb":[[0,1.22,105.34],[1,1.21,2],[2,1.2,123.57]],"batl":[[0,1.32,80.86],[1,1.34,72.25],[2,3.8,27.43]],"ltp":1.25,"tv":11477.3,"id":20955040},{"batb":[[0,4.1,2.74],[1,3.95,37.66],[2,3.9,3.16]],"batl":[[0,5.6,52.01]],"ltp":5.0,"tv":1762.31,"id":9625551}]}]}
{"op":"mcm","clk":"4234637661","pt":1631548198839,"mc":[{"id":"1.187562121","rc":[{"batb":[[0,1.21,2],[1,1.2,554.04],[2,1.19,134.71]],"batl":[[0,1.24,3211.79],[1,1.26,7.94],[2,1.27,2637.55]],"ltp":1.25,"tv":11477.3,"id":20955040},{"batb":[[0,5.1,3.74],[1,5,30],[2,4.9,15]],"batl":[[0,5.5,4.11],[1,5.6,50],[2,6,88.09]],"ltp":5.0,"tv":1762.31,"id":9625551}]}]}
{"op":"mcm","clk":"4234637740","pt":1631548199740,"mc":[{"id":"1.187562121","rc":[{"batb":[[2,1.19,192.77]],"batl":[[0,1.24,81.29]],"ltp":1.25,"tv":11477.3,"id":20955040},{"batb":[[1,5,27.39],[2,4.9,3]],"batl":[[2,5.7,26.32]],"ltp":5.0,"tv":1762.31,"id":9625551}]}]}
{"op":"mcm","clk":"4234637769","pt":1631548200260,"mc":[{"id":"1.187562121","rc":[{"batl":[[2,5.7,5.26]],"ltp":5.0,"tv":1762.31,"id":9625551}]}]}
{"op":"mcm","clk":"4234638200","pt":1631548204853,"mc":[{"id":"1.187562121","rc":[{"trd":[[1.22,209.46]],"ltp":1.22,"tv":11479.01,"id":20955040},{"trd":[[5.5,65.68]],"batl":[[0,5.5,3.73]],"ltp":5.5,"tv":1762.69,"id":9625551}],"tv":13241.7}]}
{"op":"mcm","clk":"4234638283","pt":1631548205861,"mc":[{"id":"1.187562121","rc":[{"batb":[[2,1.19,184.37]],"batl":[[1,1.27,2637.55],[2,1.28,82.84]],"ltp":1.22,"tv":11479.01,"id":20955040}]}]}
{"op":"mcm","clk":"4234638328","pt":1631548206342,"mc":[{"id":"1.187562121","rc":[{"batb":[[1,1.2,123.57],[2,1.19,134.71]],"batl":[[0,1.3,84.45],[1,1.34,72.25],[2,3.8,27.43]],"ltp":1.22,"tv":11479.01,"id":20955040},{"batb":[[0,4.3,32.91],[1,3.9,3.16],[2,1.46,3.41]],"batl":[[0,5.6,50],[1,6,2],[2,6.4,2.04]],"ltp":5.5,"tv":1762.69,"id":9625551}]}]}
{"op":"mcm","clk":"4234638642","pt":1631548209797,"mc":[{"id":"1.187562121","rc":[{"batl":[[0,1.28,75.59],[1,1.3,84.45],[2,1.34,72.25]],"ltp":1.22,"tv":11479.01,"id":20955040},{"batb":[[0,4.5,2.58],[1,4.3,32.91],[2,3.9,3.16]],"ltp":5.5,"tv":1762.69,"id":9625551}]}]}
{"op":"mcm","clk":"4234638666","pt":1631548210171,"mc":[{"id":"1.187562121","rc":[{"batl":[[0,1.3,84.45],[1,1.34,72.25],[2,3.8,27.43]],"ltp":1.22,"tv":11479.01,"id":20955040},{"batb":[[0,4.3,32.91],[1,3.9,3.16],[2,1.46,3.41]],"ltp":5.5,"tv":1762.69,"id":9625551}]}]}
{"op":"mcm","clk":"4234639243","pt":1631548216370,"mc":[{"id":"1.187562121","rc":[{"batb":[[0,1.25,96],[1,1.23,56.17],[2,1.21,2]],"batl":[[0,1.29,780.44],[1,1.3,84.45],[2,1.34,116.35]],"ltp":1.22,"tv":11479.01,"id":20955040},{"batl":[[0,4.8,18.74],[1,4.9,9.37],[2,5,9.37]],"ltp":5.5,"tv":1762.69,"id":9625551}]}]}
{"op":"mcm","clk":"4234639347","pt":1631548217479,"mc":[{"id":"1.187562121","rc":[{"batb":[[2,1.22,158.03]],"batl":[[1,1.3,92.14]],"ltp":1.22,"tv":11479.01,"id":20955040},{"batb":[[0,4.3,39.89],[1,4.2,3.48],[2,4.1,3.48]],"batl":[[0,4.8,6.24],[1,4.9,3.12],[2,5,3.12]],"ltp":5.5,"tv":1762.69,"id":9625551}]}]}
{"op":"mcm","clk":"4234639514","pt":1631548219682,"mc":[{"id":"1.187562121","rc":[{"batb":[[0,4.5,6.34],[1,4.3,39.89],[2,4.2,3.48]],"batl":[[0,4.7,4.15],[1,4.8,6.24],[2,4.9,3.12]],"ltp":5.5,"tv":1762.69,"id":9625551}]}]}
{"op":"mcm","clk":"4234639765","pt":1631548222874,"mc":[{"id":"1.187562121","rc":[{"batb":[[1,1.23,166.8]],"ltp":1.22,"tv":11479.01,"id":20955040}]}]}
{"op":"mcm","clk":"4234640105","pt":1631548227382,"mc":[{"id":"1.187562121","rc":[{"trd":[[1.23,133.29],[1.25,232.15],[1.26,25.77],[1.27,15.36]],"batb":[[0,1.23,105.48],[1,1.22,158.03],[2,1.21,121.69]],"ltp":1.23,"tv":11857.51,"id":20955040},{"trd":[[4.7,4.15],[4.8,6.77],[4.9,15.36],[5,3.62]],"batl":[[0,5.4,2.04],[1,5.6,50],[2,5.7,616.85]],"ltp":5.0,"tv":1779.32,"id":9625551}],"tv":13636.83}]}
{"op":"mcm","clk":"4234640397","pt":1631548230904,"mc":[{"id":"1.187562121","rc":[{"batb":[[0,1.21,121.69],[1,1.2,123.57],[2,1.19,324.28]],"batl":[[0,1.36,76.82],[1,1.39,60.5],[2,3.8,27.43]],"ltp":1.23,"tv":11857.51,"id":20955040},{"batb":[[0,3.75,3.39],[1,3.7,22.31],[2,3.55,3.39]],"batl":[[0,5.6,50],[1,5.8,2.02],[2,6,2]],"ltp":5.0,"tv":1779.32,"id":9625551}]}]}
{"op":"mcm","clk":"4234640427","pt":1631548231280,"mc":[{"id":"1.187562121","rc":[{"batl":[[0,1.39,60.5],[1,3.8,27.43],[2,8.8,7.22]],"ltp":1.23,"tv":11857.51,"id":20955040},{"batb":[[0,3.7,22.31],[1,3.55,3.39],[2,1.46,3.41]],"ltp":5.0,"tv":1779.32,"id":9625551}]}]}
{"op":"mcm","clk":"4234640708","pt":1631548233903,"mc":[{"id":"1.187562121","rc":[{"batb":[[0,1.23,105.63],[1,1.21,121.69],[2,1.2,123.57]],"ltp":1.23,"tv":11857.51,"id":20955040},{"batl":[[0,5.4,2.04],[1,5.6,50],[2,5.8,2.02]],"ltp":5.0,"tv":1779.32,"id":9625551}]}]}
{"op":"mcm","clk":"4234640731","pt":1631548234112,"mc":[{"id":"1.187562121","rc":[{"batb":[[0,1.21,121.69],[1,1.2,123.57],[2,1.19,324.28]],"ltp":1.23,"tv":11857.51,"id":20955040},{"batl":[[0,5.6,50],[1,5.8,2.02],[2,6,2]],"ltp":5.0,"tv":1779.32,"id":9625551}]}]}
{"op":"mcm","clk":"4234641292","pt":1631548239828,"mc":[{"id":"1.187562121","rc":[{"batl":[[0,1.36,67.32],[1,1.39,60.5],[2,3.8,27.43]],"ltp":1.23,"tv":11857.51,"id":20955040},{"batb":[[0,3.75,2.55],[1,3.7,22.31],[2,3.55,3.39]],"ltp":5.0,"tv":1779.32,"id":9625551}]}]}
{"op":"mcm","clk":"4234641374","pt":1631548240881,"mc":[{"id":"1.187562121","rc":[{"batb":[[0,1.23,116.63],[1,1.21,121.69],[2,1.2,123.57]],"batl":[[0,1.39,60.5],[1,3.8,27.43],[2,8.8,7.22]],"ltp":1.23,"tv":11857.51,"id":20955040},{"batb":[[0,3.7,22.31],[1,3.55,3.39],[2,1.46,3.41]],"batl":[[0,5.4,2.04],[1,5.6,50],[2,5.8,2.02]],"ltp":5.0,"tv":1779.32,"id":9625551}]}]}
{"op":"mcm","clk":"4234641439","pt":1631548241672,"mc":[{"id":"1.187562121","rc":[{"batb":[[0,1.21,121.69],[1,1.2,123.57],[2,1.19,324.28]],"ltp":1.23,"tv":11857.51,"id":20955040},{"batl":[[0,5.6,50],[1,5.8,2.02],[2,6,2]],"ltp":5.0,"tv":1779.32,"id":9625551}]}]}
{"op":"mcm","clk":"4234641681","pt":1631548244661,"mc":[{"id":"1.187562121","rc":[{"batb":[[1,1.2,662.31]],"batl":[[1,1.66,588.41],[2,3.8,27.43]],"ltp":1.23,"tv":11857.51,"id":20955040},{"batl":[[0,5.6,50.82]],"ltp":5.0,"tv":1779.32,"id":9625551}]}]}
{"op":"mcm","clk":"4234641721","pt":1631548245290,"mc":[{"id":"1.187562121","rc":[{"trd":[[3.7,0.42]],"batb":[[0,3.7,22.1]],"ltp":3.7,"tv":1779.74,"id":9625551}],"tv":13637.25}]}
{"op":"mcm","clk":"4234641847","pt":1631548246862,"mc":[{"id":"1.187562121","rc":[{"batl":[[0,1.36,65.07],[1,1.39,60.5],[2,1.66,588.41]],"ltp":1.23,"tv":11857.51,"id":20955040},{"batb":[[0,3.75,2.79],[1,3.7,22.1],[2,3.55,3.39]],"ltp":3.7,"tv":1779.74,"id":9625551}]}]}
{"op":"mcm","clk":"4234641908","pt":1631548247904,"mc":[{"id":"1.187562121","rc":[{"batb":[[0,1.23,106.63],[1,1.21,121.69],[2,1.2,662.31]],"batl":[[0,1.39,60.5],[1,1.66,588.41],[2,3.8,27.43]],"ltp":1.23,"tv":11857.51,"id":20955040},{"batb":[[0,3.7,22.1],[1,3.55,3.39],[2,1.46,3.41]],"batl":[[0,5.4,2.86],[1,5.6,50],[2,5.8,2.02]],"ltp":3.7,"tv":1779.74,"id":9625551}]}]}
{"op":"mcm","clk":"4234641926","pt":1631548248065,"mc":[{"id":"1.187562121","rc":[{"batb":[[0,1.21,121.69],[1,1.2,662.31],[2,1.19,324.28]],"ltp":1.23,"tv":11857.51,"id":20955040},{"batl":[[0,5.6,50.82],[1,5.8,2.02],[2,6,2]],"ltp":3.7,"tv":1779.74,"id":9625551}]}]}
{"op":"mcm","clk":"4234642135","pt":1631548250684,"mc":[{"id":"1.187562121","rc":[{"batb":[[1,1.2,123.57]],"ltp":1.23,"tv":11857.51,"id":20955040}]}]}
{"op":"mcm","clk":"4234642223","pt":1631548251682,"mc":[{"id":"1.187562121","rc":[{"batb":[[0,1.32,90.91],[1,1.28,46.16],[2,1.26,23.45]],"batl":[[0,1.36,26.42],[1,1.37,677.23],[2,1.39,60.5]],"ltp":1.23,"tv":11857.51,"id":20955040},{"batl":[[0,4,7.77],[1,4.3,23.26],[2,4.4,10.46]],"ltp":3.7,"tv":1779.74,"id":9625551}]}]}
{"op":"mcm","clk":"4234642324","pt":1631548252671,"mc":[{"id":"1.187562121","rc":[{"trd":[[1.33,2]],"batb":[[1,1.28,166.28]],"batl":[[2,1.38,7.25]],"ltp":1.33,"tv":11859.51,"id":20955040},{"trd":[[4,0.67]],"batb":[[0,3.7,30.2],[1,3.65,4.06],[2,3.6,4.06]],"batl":[[0,4,7.1],[1,4.3,9.31],[2,4.4,3.48]],"ltp":4.0,"tv":1780.41,"id":9625551}],"tv":13639.92}]}
{"op":"mcm","clk":"4234642565","pt":1631548255289,"mc":[{"id":"1.187562121","rc":[{"batb":[[2,1.27,2]],"ltp":1.33,"tv":11859.51,"id":20955040}]}]}
{"op":"mcm","clk":"4234643093","pt":1631548260901,"mc":[{"id":"1.187562121","rc":[{"trd":[[1.36,75.3]],"batb":[[1,1.29,78.81],[2,1.28,166.28]],"batl":[[0,1.36,24.16]],"ltp":1.36,"tv":11861.77,"id":20955040},{"trd":[[3.75,48.67]],"ltp":3.75,"tv":1781.23,"id":9625551}],"tv":13643.0}]}
{"op":"mcm","clk":"4234643228","pt":1631548262314,"mc":[{"id":"1.187562121","rc":[{"batl":[[0,1.37,677.23],[1,1.38,7.25],[2,1.39,60.5]],"ltp":1.36,"tv":11861.77,"id":20955040},{"batl":[[0,4.3,9.31],[1,4.4,3.48],[2,4.5,5.89]],"ltp":3.75,"tv":1781.23,"id":9625551}]}]}
{"op":"mcm","clk":"4234643464","pt":1631548265199,"mc":[{"id":"1.187562121","rc":[{"batl":[[0,1.36,26.13],[1,1.37,677.23],[2,1.38,7.25]],"ltp":1.36,"tv":11861.77,"id":20955040},{"batl":[[0,4,7.87],[1,4.3,9.31],[2,4.4,3.48]],"ltp":3.75,"tv":1781.23,"id":9625551}]}]}
{"op":"mcm","clk":"4234643584","pt":1631548266820,"mc":[{"id":"1.187562121","rc":[{"batb":[[0,1.27,96.87],[1,1.24,142.26],[2,1.23,524.14]],"batl":[[0,1.46,56.25],[1,1.66,588.41],[2,3.8,27.43]],"ltp":1.36,"tv":11861.77,"id":20955040},{"batb":[[0,3.2,31.79],[1,3.15,4.23],[2,1.46,3.41]],"batl":[[0,4.8,2.02],[1,5.6,50],[2,5.8,2.02]],"ltp":3.75,"tv":1781.23,"id":9625551}]}]}
{"op":"mcm","clk":"4234643598","pt":1631548267020,"mc":[{"id":"1.187562121","rc":[{"batl":[[0,1.35,7.22],[1,1.46,56.25],[2,1.66,588.41]],"ltp":1.36,"tv":11861.77,"id":20955040}]}]}
{"op":"mcm","clk":"4234643798","pt":1631548269802,"mc":[{"id":"1.187562121","rc":[{"batb":[[0,1.29,82.81],[1,1.27,96.87],[2,1.24,142.26]],"batl":[[1,1.43,64.5],[2,1.46,56.25]],"ltp":1.36,"tv":11861.77,"id":20955040},{"batb":[[0,3.3,3.78],[1,3.2,31.79],[2,3.15,4.23]],"batl":[[0,4.5,2.11],[1,4.8,2.02],[2,5.6,50]],"ltp":3.75,"tv":1781.23,"id":9625551}]}]}
{"op":"mcm","clk":"4234643811","pt":1631548270009,"mc":[{"id":"1.187562121","rc":[{"batb":[[0,1.27,96.87],[1,1.24,142.26],[2,1.23,524.14]],"batl":[[0,1.46,56.25],[1,1.66,588.41],[2,3.8,27.43]],"ltp":1.36,"tv":11861.77,"id":20955040},{"batb":[[0,3.2,31.79],[1,3.15,4.23],[2,1.46,3.41]],"batl":[[0,4.8,2.02],[1,5.6,50],[2,5.8,2.02]],"ltp":3.75,"tv":1781.23,"id":9625551}]}]}
{"op":"mcm","clk":"4234644350","pt":1631548276727,"mc":[{"id":"1.187562121","rc":[{"batb":[[0,1.29,80.81],[1,1.27,96.87],[2,1.24,142.26]],"batl":[[0,1.43,59.5],[1,1.46,56.25],[2,1.66,588.41]],"ltp":1.36,"tv":11861.77,"id":20955040},{"batb":[[0,3.3,3.58],[1,3.2,31.79],[2,3.15,4.23]],"batl":[[0,4.5,2.57],[1,4.8,2.02],[2,5.6,50]],"ltp":3.75,"tv":1781.23,"id":9625551}]}]}
{"op":"mcm","clk":"4234644399","pt":1631548277303,"mc":[{"id":"1.187562121","rc":[{"batb":[[0,1.27,96.87],[1,1.24,142.26],[2,1.23,524.14]],"batl":[[0,1.46,56.25],[1,1.66,588.41],[2,3.8,27.43]],"ltp":1.36,"tv":11861.77,"id":20955040},{"trd":[[3.2,15.75]],"batb":[[0,3.2,29.42],[1,3.15,4.23],[2,1.46,3.41]],"batl":[[0,4.8,2.02],[1,5.6,50],[2,5.8,2.02]],"ltp":3.2,"tv":1785.98,"id":9625551}],"tv":13647.75}]}
{"op":"mcm","clk":"4234644537","pt":1631548279154,"mc":[{"id":"1.187562121","rc":[{"batb":[[2,1.21,121.69]],"batl":[[1,3.8,27.43],[2,8.8,7.22]],"ltp":1.36,"tv":11861.77,"id":20955040}]}]}
{"op":"mcm","clk":"4234644652","pt":1631548280626,"mc":[{"id":"1.187562121","rc":[{"trd":[[1.43,645.44]],"batb":[[0,1.41,63.83],[1,1.4,117.63],[2,1.39,31.91]],"batl":[[0,1.45,14.34],[1,1.46,56.25],[2,1.47,627.93]],"ltp":1.43,"tv":11887.67,"id":20955040},{"batl":[[0,3.55,285.54],[1,3.65,2.74],[2,4.5,2.29]],"ltp":3.2,"tv":1785.98,"id":9625551}],"tv":13673.65}]}
{"op":"mcm","clk":"4234644739","pt":1631548281530,"mc":[{"id":"1.187562121","rc":[{"batl":[[1,1.46,83.64],[2,1.47,638.21]],"ltp":1.43,"tv":11887.67,"id":20955040},{"batb":[[2,3.05,37.24]],"ltp":3.2,"tv":1785.98,"id":9625551}]}]}
{"op":"mcm","clk":"4234644955","pt":1631548283730,"mc":[{"id":"1.187562121","rc":[{"batl":[[2,4.5,2.99]],"ltp":3.2,"tv":1785.98,"id":9625551}]}]}
{"op":"mcm","clk":"4234645226","pt":1631548286841,"mc":[{"id":"1.187562121","rc":[{"batb":[[2,3.1,3.74]],"batl":[[2,3.95,3.1]],"ltp":3.2,"tv":1785.98,"id":9625551}]}]}
{"op":"mcm","clk":"4234645271","pt":1631548287259,"mc":[{"id":"1.187562121","rc":[{"batb":[[2,3.05,37.24]],"ltp":3.2,"tv":1785.98,"id":9625551}]}]}
{"op":"mcm","clk":"4234645367","pt":1631548288724,"mc":[{"id":"1.187562121","rc":[{"batl":[[0,1.45,65.24]],"ltp":1.43,"tv":11887.67,"id":20955040},{"batb":[[0,3.2,33.19]],"ltp":3.2,"tv":1785.98,"id":9625551}]}]}
{"op":"mcm","clk":"4234645556","pt":1631548290760,"mc":[{"id":"1.187562121","rc":[{"batl":[[0,1.45,50.9],[2,1.47,692.71]],"ltp":1.43,"tv":11887.67,"id":20955040},{"batb":[[2,3.1,3.74]],"ltp":3.2,"tv":1785.98,"id":9625551}]}]}
{"op":"mcm","clk":"4234645679","pt":1631548292264,"mc":[{"id":"1.187562121","rc":[{"trd":[[1.45,1219.43],[1.46,304.8],[1.47,775.41]],"batl":[[0,1.47,320.16],[1,1.48,50.21],[2,1.5,19.7]],"ltp":1.47,"tv":12974.57,"id":20955040},{"trd":[[3.2,48.94]],"batb":[[0,3.15,4.23],[1,3.1,3.74],[2,3.05,37.24]],"ltp":3.2,"tv":1819.17,"id":9625551}],"tv":14793.74}]}
{"op":"mcm","clk":"4234645760","pt":1631548293363,"mc":[{"id":"1.187562121","rc":[{"batb":[[0,1.42,14.51],[1,1.41,63.83],[2,1.4,117.63]],"batl":[[0,1.44,13.86],[1,1.47,320.16],[2,1.48,50.21]],"ltp":1.47,"tv":12974.57,"id":20955040}]}]}
{"op":"mcm","clk":"4234645932","pt":1631548295639,"mc":[{"id":"1.187562121","rc":[{"batl":[[1,1.46,56.75],[2,1.47,320.16]],"ltp":1.47,"tv":12974.57,"id":20955040}]}]}
{"op":"mcm","clk":"4234646210","pt":1631548298871,"mc":[{"id":"1.187562121","rc":[{"batl":[[0,1.44,110.86]],"ltp":1.47,"tv":12974.57,"id":20955040}]}]}
{"op":"mcm","clk":"4234646255","pt":1631548299360,"mc":[{"id":"1.187562121","rc":[{"trd":[[1.44,206.26]],"batl":[[0,1.44,110.08]],"ltp":1.44,"tv":12976.13,"id":20955040}],"tv":14795.3}]}
{"op":"mcm","clk":"4234646854","pt":1631548307649,"mc":[{"id":"1.187562121","rc":[{"trd":[[1.44,206.28]],"batl":[[0,1.44,110.07]],"ltp":1.44,"tv":12976.15,"id":20955040}],"tv":14795.33}]}
{"op":"mcm","clk":"4234646980","pt":1631548309510,"mc":[{"id":"1.187562121","rc":[{"batb":[[0,1.41,63.83],[1,1.4,117.63],[2,1.39,31.91]],"batl":[[0,1.44,97]],"ltp":1.44,"tv":12976.15,"id":20955040}]}]}
{"op":"mcm","clk":"4234647048","pt":1631548310709,"mc":[{"id":"1.187562121","rc":[{"batb":[[0,1.31,559.38],[1,1.3,110.13],[2,1.29,79.81]],"batl":[[1,1.89,441.74],[2,3.8,27.43]],"ltp":1.44,"tv":12976.15,"id":20955040},{"batb":[[0,3.05,37.24],[1,1.46,3.41],[2,1.01,105.79]],"batl":[[0,4.3,3.25],[1,4.5,2.29],[2,4.8,2.02]],"ltp":3.2,"tv":1819.17,"id":9625551}]}]}
{"op":"mcm","clk":"4234647067","pt":1631548310918,"mc":[{"id":"1.187562121","rc":[{"batl":[[0,1.89,441.74],[1,3.8,27.43],[2,8.8,7.22]],"ltp":1.44,"tv":12976.15,"id":20955040}]}]}
{"op":"mcm","clk":"4234647318","pt":1631548313823,"mc":[{"id":"1.187562121","rc":[{"batb":[[0,1.31,666.75]],"batl":[[0,1.47,53.5],[1,1.48,46.74],[2,1.89,441.74]],"ltp":1.44,"tv":12976.15,"id":20955040},{"batb":[[0,3.1,4.04],[1,3.05,41.33],[2,3,38.58]],"ltp":3.2,"tv":1819.17,"id":9625551}]}]}
{"op":"mcm","clk":"4234647343","pt":1631548314135,"mc":[{"id":"1.187562121","rc":[{"batb":[[1,1.29,79.81],[2,1.27,96.87]],"ltp":1.44,"tv":12976.15,"id":20955040},{"batb":[[1,3.05,4.09]],"ltp":3.2,"tv":1819.17,"id":9625551}]}]}
{"op":"mcm","clk":"4234647941","pt":1631548321837,"mc":[{"id":"1.187562121","rc":[{"batb":[[0,1.34,75.22],[1,1.31,666.75],[2,1.29,79.81]],"ltp":1.44,"tv":12976.15,"id":20955040},{"batl":[[0,3.95,2.9],[1,4.3,3.25],[2,4.5,2.29]],"ltp":3.2,"tv":1819.17,"id":9625551}]}]}
{"op":"mcm","clk":"4234647981","pt":1631548322358,"mc":[{"id":"1.187562121","rc":[{"batb":[[0,1.31,666.75],[1,1.29,79.81],[2,1.27,96.87]],"ltp":1.44,"tv":12976.15,"id":20955040},{"batl":[[0,4.3,3.25],[1,4.5,2.29],[2,4.8,2.02]],"ltp":3.2,"tv":1819.17,"id":9625551}]}]}
{"op":"mcm","clk":"4234648648","pt":1631548330836,"mc":[{"id":"1.187562121","rc":[{"batl":[[0,1.46,56.75],[1,1.47,53.5],[2,1.48,46.74]],"ltp":1.44,"tv":12976.15,"id":20955040},{"batb":[[0,3.15,3.63],[1,3.1,4.04],[2,3.05,4.09]],"ltp":3.2,"tv":1819.17,"id":9625551}]}]}
{"op":"mcm","clk":"4234648667","pt":1631548331150,"mc":[{"id":"1.187562121","rc":[{"batl":[[0,1.47,53.5],[1,1.48,46.74],[2,1.89,441.74]],"ltp":1.44,"tv":12976.15,"id":20955040},{"batb":[[0,3.1,4.04],[1,3.05,4.09],[2,3,38.58]],"ltp":3.2,"tv":1819.17,"id":9625551}]}]}
{"op":"mcm","clk":"4234649078","pt":1631548335898,"mc":[{"id":"1.187562121","rc":[{"batb":[[0,1.34,75.72],[1,1.31,666.75],[2,1.29,79.81]],"ltp":1.44,"tv":12976.15,"id":20955040},{"batl":[[0,3.95,2.9],[1,4.3,3.25],[2,4.5,2.29]],"ltp":3.2,"tv":1819.17,"id":9625551}]}]}
{"op":"mcm","clk":"4234649108","pt":1631548336164,"mc":[{"id":"1.187562121","rc":[{"batb":[[0,1.31,666.75],[1,1.29,79.81],[2,1.27,96.87]],"ltp":1.44,"tv":12976.15,"id":20955040},{"batl":[[0,4.3,3.25],[1,4.5,2.29],[2,4.8,2.02]],"ltp":3.2,"tv":1819.17,"id":9625551}]}]}
{"op":"mcm","clk":"4234649246","pt":1631548337877,"mc":[{"id":"1.187562121","rc":[{"batl":[[0,1.46,55.25],[1,1.47,53.5],[2,1.48,46.74]],"ltp":1.44,"tv":12976.15,"id":20955040},{"batb":[[0,3.15,3.83],[1,3.1,4.04],[2,3.05,4.09]],"ltp":3.2,"tv":1819.17,"id":9625551}]}]}
{"op":"mcm","clk":"4234649276","pt":1631548338186,"mc":[{"id":"1.187562121","rc":[{"batl":[[0,1.47,53.5],[1,1.48,46.74],[2,1.89,441.74]],"ltp":1.44,"tv":12976.15,"id":20955040},{"batb":[[0,3.1,4.04],[1,3.05,4.09],[2,3,38.58]],"ltp":3.2,"tv":1819.17,"id":9625551}]}]}
{"op":"mcm","clk":"4234649787","pt":1631548344576,"mc":[{"id":"1.187562121","rc":[{"batb":[[0,1.31,182.16],[1,1.3,45.45],[2,1.29,79.81]],"batl":[[0,1.38,15.43],[1,1.39,21.58],[2,1.4,10.8]],"ltp":1.44,"tv":12976.15,"id":20955040},{"batb":[[0,3.3,60.6],[1,3.1,4.04],[2,3.05,4.09]],"batl":[[0,3.75,4.59],[1,3.85,259.22],[2,4.3,3.25]],"ltp":3.2,"tv":1819.17,"id":9625551}]}]}
{"op":"mcm","clk":"4234649866","pt":1631548345565,"mc":[{"id":"1.187562121","rc":[{"batb":[[0,1.34,22.38],[1,1.33,11.2],[2,1.32,11.2]],"ltp":1.44,"tv":12976.15,"id":20955040},{"batb":[[0,3.5,26.09],[1,3.3,60.6],[2,3.25,31.45]],"batl":[[2,4.1,3.14]],"ltp":3.2,"tv":1819.17,"id":9625551}]}]}
{"op":"mcm","clk":"4234650196","pt":1631548349792,"mc":[{"id":"1.187562121","rc":[{"batl":[[2,4.1,2.44]],"ltp":3.2,"tv":1819.17,"id":9625551}]}]}
{"op":"mcm","clk":"4234650334","pt":1631548351367,"mc":[{"id":"1.187562121","rc":[{"batb":[[1,3.3,63.98]],"ltp":3.2,"tv":1819.17,"id":9625551}]}]}
{"op":"mcm","clk":"4234650426","pt":1631548352458,"mc":[{"id":"1.187562121","rc":[{"batl":[[0,1.38,136.43]],"ltp":1.44,"tv":12976.15,"id":20955040}]}]}
{"op":"mcm","clk":"4234650634","pt":1631548354597,"mc":[{"id":"1.187562121","rc":[{"batb":[[1,3.4,3.61],[2,3.3,63.98]],"ltp":3.2,"tv":1819.17,"id":9625551}]}]}
{"op":"mcm","clk":"4234651162","pt":1631548360871,"mc":[{"id":"1.187562121","rc":[{"batb":[[0,1.31,182.16],[1,1.3,128.13],[2,1.29,79.81]],"batl":[[0,1.38,121],[1,1.41,70.5],[2,1.42,41.61]],"ltp":1.44,"tv":12976.15,"id":20955040},{"batb":[[2,3.3,3.38]],"batl":[[0,4.3,2.55],[1,4.4,2.29],[2,4.5,2.29]],"ltp":3.2,"tv":1819.17,"id":9625551}]}]}
{"op":"mcm","clk":"4234651201","pt":1631548361494,"mc":[{"id":"1.187562121","rc":[{"batb":[[0,1.27,96.87],[1,1.26,132.87],[2,1.25,512.59]],"batl":[[0,1.43,54.5],[1,1.77,508.04],[2,3.8,27.43]],"ltp":1.44,"tv":12976.15,"id":20955040},{"batb":[[0,3.3,3.38],[1,3.25,31.45],[2,1.46,3.41]],"batl":[[0,4.8,2.02],[1,5.6,50],[2,5.8,2.02]],"ltp":3.2,"tv":1819.17,"id":9625551}]}]}
{"op":"mcm","clk":"4234651281","pt":1631548362372,"mc":[{"id":"1.187562121","rc":[{"batl":[[0,3.6,2.71],[1,4.8,2.02],[2,5.6,50]],"ltp":3.2,"tv":1819.17,"id":9625551}]}]}
{"op":"mcm","clk":"4234651501","pt":1631548364885,"mc":[{"id":"1.187562121","rc":[{"batl":[[0,1.41,67.5],[1,1.43,54.5],[2,1.77,508.04]],"ltp":1.44,"tv":12976.15,"id":20955040},{"batb":[[0,3.4,3.26],[1,3.3,3.38],[2,3.25,31.45]],"ltp":3.2,"tv":1819.17,"id":9625551}]}]}
{"op":"mcm","clk":"4234651573","pt":1631548365720,"mc":[{"id":"1.187562121","rc":[{"batl":[[0,1.43,54.5],[1,1.77,508.04],[2,3.8,27.43]],"ltp":1.44,"tv":12976.15,"id":20955040},{"batb":[[0,3.3,3.38],[1,3.25,31.45],[2,1.46,3.41]],"batl":[[0,4.8,2.02],[1,5.6,50],[2,5.8,2.02]],"ltp":3.2,"tv":1819.17,"id":9625551}]}]}
{"op":"mcm","clk":"4234651620","pt":1631548366395,"mc":[{"id":"1.187562121","rc":[{"batb":[[2,1.21,121.69]],"ltp":1.44,"tv":12976.15,"id":20955040}]}]}
{"op":"mcm","clk":"4234651779","pt":1631548368319,"mc":[{"id":"1.187562121","rc":[{"batb":[[0,1.41,141.84],[1,1.4,301.35],[2,1.39,27.91]],"batl":[[1,1.46,491.49],[2,1.47,40.2]],"ltp":1.44,"tv":12976.15,"id":20955040},{"batb":[[0,3.35,5.24],[1,3.3,3.38],[2,3.25,31.45]],"batl":[[0,3.5,120.54],[1,3.55,8.44],[2,3.6,7.78]],"ltp":3.2,"tv":1819.17,"id":9625551}]}]}
{"op":"mcm","clk":"4234651875","pt":1631548369472,"mc":[{"id":"1.187562121","rc":[{"batl":[[1,1.45,6.9],[2,1.46,491.49]],"ltp":1.44,"tv":12976.15,"id":20955040},{"batb":[[2,3.25,40.69]],"ltp":3.2,"tv":1819.17,"id":9625551}]}]}
{"op":"mcm","clk":"4234652380","pt":1631548375655,"mc":[{"id":"1.187562121","rc":[{"batl":[[2,1.46,549.74]],"ltp":1.44,"tv":12976.15,"id":20955040}]}]}
{"op":"mcm","clk":"4234652609","pt":1631548378710,"mc":[{"id":"1.187562121","rc":[{"trd":[[1.41,108.99]],"batb":[[0,1.41,131.84]],"ltp":1.41,"tv":12996.15,"id":20955040}],"tv":14815.33}]}
{"op":"mcm","clk":"4234652774","pt":1631548380857,"mc":[{"id":"1.187562121","rc":[{"batb":[[0,1.29,115.17],[1,1.28,493.1],[2,1.27,96.87]],"batl":[[0,1.77,508.04],[1,3.8,27.43],[2,8.8,7.22]],"ltp":1.41,"tv":12996.15,"id":20955040},{"batb":[[0,3.05,4.49],[1,3,37.66],[2,1.46,3.41]],"batl":[[0,4.3,2.55],[1,4.8,2.02],[2,5.6,50]],"ltp":3.2,"tv":1819.17,"id":9625551}]}]}
{"op":"mcm","clk":"4234653033","pt":1631548384252,"mc":[{"id":"1.187562121","rc":[{"batb":[[0,1.31,74.79],[1,1.29,115.17],[2,1.28,493.1]],"batl":[[0,1.48,52.99],[1,1.77,508.04],[2,3.8,27.43]],"ltp":1.41,"tv":12996.15,"id":20955040}]}]}
{"op":"mcm","clk":"4234653357","pt":1631548388736,"mc":[{"id":"1.187562121","rc":[{"batb":[[2,1.27,96.87]],"ltp":1.41,"tv":12996.15,"id":20955040}]}]}
{"op":"mcm","clk":"4234653439","pt":1631548389838,"mc":[{"id":"1.187562121","rc":[{"batb":[[0,1.45,470.56],[1,1.44,104.16],[2,1.43,79.51]],"ltp":1.41,"tv":12996.15,"id":20955040},{"batb":[[0,3.1,6.31],[1,3.05,4.49],[2,3,37.66]],"batl":[[0,3.2,6.52],[1,3.3,1050.96],[2,3.35,3.9]],"ltp":3.2,"tv":1819.17,"id":9625551}]}]}
{"op":"mcm","clk":"4234653495","pt":1631548390773,"mc":[{"id":"1.187562121","rc":[{"batb":[[1,1.44,20.84],[2,1.43,37.85]],"batl":[[1,1.49,6.71],[2,1.52,38.88]],"ltp":1.41,"tv":12996.15,"id":20955040},{"batb":[[2,3,87.66]],"batl":[[1,3.3,60.6]],"ltp":3.2,"tv":1819.17,"id":9625551}]}]}
{"op":"mcm","clk":"4234653513","pt":1631548390990,"mc":[{"id":"1.187562121","rc":[{"batb":[[2,3,47.66]],"ltp":3.2,"tv":1819.17,"id":9625551}]}]}
{"op":"mcm","clk":"4234653782","pt":1631548394735,"mc":[{"id":"1.187562121","rc":[{"batl":[[0,1.46,144.45],[1,1.48,52.99],[2,1.49,6.71]],"ltp":1.41,"tv":12996.15,"id":20955040}]}]}
{"op":"mcm","clk":"4234653793","pt":1631548394942,"mc":[{"id":"1.187562121","rc":[{"batl":[[0,1.48,52.99],[1,1.49,6.71],[2,1.52,38.88]],"ltp":1.41,"tv":12996.15,"id":20955040}]}]}
{"op":"mcm","clk":"4234653888","pt":1631548396448,"mc":[{"id":"1.187562121","rc":[{"batl":[[2,1.5,54.01]],"ltp":1.41,"tv":12996.15,"id":20955040},{"batb":[[2,3,52.66]],"ltp":3.2,"tv":1819.17,"id":9625551}]}]}
{"op":"mcm","clk":"4234654269","pt":1631548402675,"mc":[{"id":"1.187562121","rc":[{"trd":[[3.1,24.14]],"batb":[[0,3.1,2.88]],"ltp":3.1,"tv":1826.02,"id":9625551}],"tv":14822.18}]}
{"op":"mcm","clk":"4234654421","pt":1631548404558,"mc":[{"id":"1.187562121","rc":[{"batb":[[0,1.38,71.96],[1,1.34,98.31],[2,1.31,559.38]],"batl":[[0,1.48,88],[1,1.52,46.76],[2,1.77,508.04]],"ltp":1.41,"tv":12996.15,"id":20955040},{"batb":[[0,2.92,4.69],[1,2.88,43.11],[2,1.46,3.41]],"batl":[[0,3.65,3.1],[1,4.3,2.55],[2,4.8,2.02]],"ltp":3.1,"tv":1826.02,"id":9625551}]}]}
{"op":"mcm","clk":"4234654450","pt":1631548404972,"mc":[{"id":"1.187562121","rc":[{"batl":[[0,1.52,46.76],[1,1.77,508.04],[2,3.8,27.43]],"ltp":1.41,"tv":12996.15,"id":20955040}]}]}
{"op":"mcm","clk":"4234655105","pt":1631548414814,"mc":[{"id":"1.187562121","rc":[{"batb":[[0,1.4,71.61],[1,1.38,71.96],[2,1.34,98.31]],"batl":[[0,1.5,46.63],[1,1.52,46.76],[2,1.77,508.04]],"ltp":1.41,"tv":12996.15,"id":20955040},{"batb":[[0,3,4],[1,2.92,4.69],[2,2.88,43.11]],"batl":[[0,3.5,3.41],[1,3.65,3.1],[2,4.3,2.55]],"ltp":3.1,"tv":1826.02,"id":9625551}]}]}
{"op":"mcm","clk":"4234655128","pt":1631548415072,"mc":[{"id":"1.187562121","rc":[{"batb":[[0,1.38,71.96],[1,1.34,98.31],[2,1.31,559.38]],"batl":[[0,1.52,46.76],[1,1.77,508.04],[2,3.8,27.43]],"ltp":1.41,"tv":12996.15,"id":20955040},{"batb":[[0,2.92,4.69],[1,2.88,43.11],[2,1.46,3.41]],"batl":[[0,3.65,3.1],[1,4.3,2.55],[2,4.8,2.02]],"ltp":3.1,"tv":1826.02,"id":9625551}]}]}
{"op":"mcm","clk":"4234655292","pt":1631548417313,"mc":[{"id":"1.187562121","rc":[{"batb":[[2,1.27,2]],"batl":[[1,3.8,27.43],[2,8.8,7.22]],"ltp":1.41,"tv":12996.15,"id":20955040},{"batl":[[1,5.6,50],[2,5.8,2.02]],"ltp":3.1,"tv":1826.02,"id":9625551}]}]}
{"op":"mcm","clk":"4234655394","pt":1631548418823,"mc":[{"id":"1.187562121","rc":[{"batb":[[0,1.5,8.36],[1,1.48,236.5],[2,1.47,77.35]],"batl":[[1,1.56,472.62],[2,3.8,27.43]],"ltp":1.41,"tv":12996.15,"id":20955040},{"batb":[[1,2.88,52.93]],"batl":[[0,3,4.18],[1,3.1,1034.82],[2,3.15,4.1]],"ltp":3.1,"tv":1826.02,"id":9625551}]}]}
{"op":"mcm","clk":"4234655480","pt":1631548419809,"mc":[{"id":"1.187562121","rc":[{"batb":[[1,1.48,141.9],[2,1.47,57.08]],"batl":[[1,1.53,6.54],[2,1.54,97.4]],"ltp":1.41,"tv":12996.15,"id":20955040},{"batb":[[2,2.76,19.12]],"batl":[[1,3.15,4.1],[2,3.2,658.83]],"ltp":3.1,"tv":1826.02,"id":9625551}]}]}
{"op":"mcm","clk":"4234655535","pt":1631548420484,"mc":[{"id":"1.187562121","rc":[{"batb":[[1,1.48,101.36],[2,1.47,36.81]],"batl":[[2,1.54,19.48]],"ltp":1.41,"tv":12996.15,"id":20955040}]}]}
{"op":"mcm","clk":"4234655758","pt":1631548423826,"mc":[{"id":"1.187562121","rc":[{"trd":[[1.5,47.47]],"batb":[[0,1.48,101.36],[1,1.47,36.81],[2,1.46,10.14]],"batl":[[0,1.5,120.84],[1,1.52,46.76],[2,1.53,6.54]],"ltp":1.5,"tv":13021.23,"id":20955040},{"trd":[[3,8.48]],"batl":[[0,3.15,4.1],[1,3.2,669.23],[2,3.3,3.03]],"ltp":3.0,"tv":1830.2,"id":9625551}],"tv":14851.44}]}
{"op":"mcm","clk":"4234655772","pt":1631548423985,"mc":[{"id":"1.187562121","rc":[{"batl":[[0,1.52,46.76],[1,1.53,6.54],[2,1.54,19.48]],"ltp":1.5,"tv":13021.23,"id":20955040},{"batl":[[1,3.2,658.83]],"ltp":3.0,"tv":1830.2,"id":9625551}]}]}
{"op":"mcm","clk":"4234655975","pt":1631548426493,"mc":[{"id":"1.187562121","rc":[{"batb":[[2,1.46,62.02]],"batl":[[1,1.53,61.04],[2,1.54,72.73]],"ltp":1.5,"tv":13021.23,"id":20955040},{"batb":[[1,2.88,57.89],[2,2.84,4.97]],"batl":[[1,3.2,662.21],[2,3.3,6.88]],"ltp":3.0,"tv":1830.2,"id":9625551}]}]}
{"op":"mcm","clk":"4234656036","pt":1631548427226,"mc":[{"id":"1.187562121","rc":[{"batl":[[0,1.51,49.5],[1,1.52,46.76],[2,1.53,61.04]],"ltp":1.5,"tv":13021.23,"id":20955040},{"batb":[[0,2.96,4.38],[1,2.92,4.69],[2,2.88,57.89]],"batl":[[2,3.25,4.1]],"ltp":3.0,"tv":1830.2,"id":9625551}]}]}
{"op":"mcm","clk":"4234656483","pt":1631548434007,"mc":[{"id":"1.187562121","rc":[{"batb":[[2,2.88,48.07]],"ltp":3.0,"tv":1830.2,"id":9625551}]}]}
{"op":"mcm","clk":"4234656701","pt":1631548436906,"mc":[{"id":"1.187562121","rc":[{"batb":[[0,2.96,10.3]],"batl":[[0,3.05,7.07],[1,3.15,4.1],[2,3.2,662.21]],"ltp":3.0,"tv":1830.2,"id":9625551}]}]}
{"op":"mcm","clk":"4234656833","pt":1631548438844,"mc":[{"id":"1.187562121","rc":[{"batb":[[0,1.44,52.17],[1,1.39,82.62],[2,1.34,472.33]],"batl":[[0,1.95,415.94],[1,3.8,27.43],[2,8.8,7.22]],"ltp":1.5,"tv":13021.23,"id":20955040},{"trd":[[2.76,38.25],[2.88,96.15]],"batb":[[0,1.46,3.41],[1,1.01,105.79],[2,2.88,0]],"batl":[[0,2.92,654.77],[1,3.3,3.85],[2,5.6,50]],"ltp":2.76,"tv":1964.6,"id":9625551}],"tv":14985.84}]}
{"op":"mcm","clk":"4234657041","pt":1631548441858,"mc":[{"id":"1.187562121","rc":[{"trd":[[1.52,3249.48]],"batb":[[0,1.46,51.88],[1,1.44,52.17],[2,1.39,82.62]],"batl":[[0,1.53,50.5],[1,1.95,415.94],[2,3.8,27.43]],"ltp":1.52,"tv":13070.24,"id":20955040},{"trd":[[2.92,567.35]],"batl":[[0,2.92,625.07],[1,3.2,4.03],[2,3.3,3.85]],"ltp":2.92,"tv":1998.49,"id":9625551}],"tv":15068.74}]}
{"op":"mcm","clk":"4234657052","pt":1631548442018,"mc":[{"id":"1.187562121","rc":[{"batb":[[0,2.88,4.21],[1,1.46,3.41],[2,1.01,105.79]],"ltp":2.92,"tv":1998.49,"id":9625551}]}]}
{"op":"mcm","clk":"4234657440","pt":1631548447441,"mc":[{"id":"1.187562121","rc":[{"batb":[[0,1.5,59.6],[1,1.49,80.53],[2,1.46,51.88]],"batl":[[1,1.54,12.37],[2,1.59,37.16]],"ltp":1.52,"tv":13070.24,"id":20955040},{"batl":[[1,2.96,10.24],[2,2.98,30.2]],"ltp":2.92,"tv":1998.49,"id":9625551}]}]}
{"op":"mcm","clk":"4234657512","pt":1631548448438,"mc":[{"id":"1.187562121","rc":[{"batb":[[2,1.48,63.58]],"batl":[[2,1.56,6.41]],"ltp":1.52,"tv":13070.24,"id":20955040},{"batb":[[1,2.78,10.8],[2,2.76,5.4]],"batl":[[2,2.98,10.06]],"ltp":2.92,"tv":1998.49,"id":9625551}]}]}
{"op":"mcm","clk":"4234658266","pt":1631548455675,"mc":[{"id":"1.187562121","rc":[{"trd":[[1.52,3256.13]],"ltp":1.52,"tv":13076.89,"id":20955040},{"trd":[[2.92,570.81]],"batl":[[0,2.92,621.61]],"ltp":2.92,"tv":2001.95,"id":9625551}],"tv":15078.85}]}
{"op":"mcm","clk":"4234658896","pt":1631548462534,"mc":[{"id":"1.187562121","rc":[{"batl":[[0,2.96,10.24],[1,2.98,10.06],[2,3,14.97]],"ltp":2.92,"tv":2001.95,"id":9625551}]}]}
{"op":"mcm","clk":"4234660097","pt":1631548477860,"mc":[{"id":"1.187562121","rc":[{"trd":[[1.51,645.72]],"ltp":1.51,"tv":13083.93,"id":20955040},{"trd":[[2.96,272.62]],"batl":[[0,2.96,6.65]],"ltp":2.96,"tv":2005.54,"id":9625551}],"tv":15089.48}]}
{"op":"mcm","clk":"4234660366","pt":1631548481173,"mc":[{"id":"1.187562121","rc":[{"trd":[[2.88,103.19]],"batb":[[0,2.78,11.49],[1,2.76,5.4],[2,2.74,5.4]],"ltp":2.88,"tv":2012.58,"id":9625551}],"tv":15096.52}]}
{"op":"mcm","clk":"4234660638","pt":1631548484995,"mc":[{"id":"1.187562121","rc":[{"trd":[[1.53,50.5]],"batl":[[0,1.54,12.37],[1,1.56,6.41],[2,1.59,37.16]],"ltp":1.53,"tv":13134.43,"id":20955040},{"trd":[[2.88,131.4]],"batb":[[0,2.78,10.8]],"batl":[[0,2.88,189.07],[1,2.96,6.65],[2,2.98,10.06]],"ltp":2.88,"tv":2040.79,"id":9625551}],"tv":15175.23}]}
{"op":"mcm","clk":"4234660914","pt":1631548488087,"mc":[{"id":"1.187562121","rc":[{"batl":[[0,1.56,6.41],[1,1.59,37.16],[2,1.6,639.25]],"ltp":1.53,"tv":13134.43,"id":20955040},{"batl":[[1,2.98,10.06],[2,3,14.97]],"ltp":2.88,"tv":2040.79,"id":9625551}]}]}
{"op":"mcm","clk":"4234661132","pt":1631548491005,"mc":[{"id":"1.187562121","rc":[{"trd":[[2.88,142.94]],"batl":[[0,2.88,183.3],[1,2.96,6.65],[2,2.98,10.06]],"ltp":2.88,"tv":2052.33,"id":9625551}],"tv":15186.77}]}
{"op":"mcm","clk":"4234661426","pt":1631548494190,"mc":[{"id":"1.187562121","rc":[{"batl":[[0,1.56,199.41]],"ltp":1.53,"tv":13134.43,"id":20955040}]}]}
{"op":"mcm","clk":"4234661650","pt":1631548496378,"mc":[{"id":"1.187562121","rc":[{"batl":[[0,1.56,6.41]],"ltp":1.53,"tv":13134.43,"id":20955040},{"batl":[[0,2.96,6.65],[1,2.98,10.06],[2,3,14.97]],"ltp":2.88,"tv":2052.33,"id":9625551}]}]}
{"op":"mcm","clk":"4234661861","pt":1631548499184,"mc":[{"id":"1.187562121","rc":[{"trd":[[1.56,38.72]],"batl":[[0,1.59,37.16],[1,1.6,639.25],[2,1.61,18.35]],"ltp":1.56,"tv":13140.84,"id":20955040},{"trd":[[2.78,32.38]],"batb":[[0,2.76,5.4],[1,2.74,5.4],[2,2.64,20.22]],"batl":[[0,2.78,168.9],[1,2.96,6.65],[2,2.98,10.06]],"ltp":2.78,"tv":2077.53,"id":9625551}],"tv":15218.37}]}
{"op":"mcm","clk":"4234662020","pt":1631548501241,"mc":[{"id":"1.187562121","rc":[{"batl":[[1,2.98,10.06],[2,3,14.97]],"ltp":2.78,"tv":2077.53,"id":9625551}]}]}
{"op":"mcm","clk":"4234662126","pt":1631548502396,"mc":[{"id":"1.187562121","rc":[{"trd":[[1.56,59.51]],"ltp":1.56,"tv":13161.63,"id":20955040},{"trd":[[2.78,44.04]],"batl":[[0,2.78,157.24]],"ltp":2.78,"tv":2089.2,"id":9625551}],"tv":15250.83}]}
{"op":"mcm","clk":"4234662294","pt":1631548504438,"mc":[{"id":"1.187562121","rc":[{"batl":[[0,1.57,219],[1,1.59,37.16],[2,1.6,639.25]],"ltp":1.56,"tv":13161.63,"id":20955040},{"trd":[[2.78,57.4]],"batl":[[0,2.78,150.56],[1,2.92,6.26],[2,2.98,10.06]],"ltp":2.78,"tv":2102.55,"id":9625551}],"tv":15264.19}]}
{"op":"mcm","clk":"4234663089","pt":1631548513635,"mc":[{"id":"1.187562121","rc":[{"batl":[[0,2.92,6.26],[1,2.98,10.06],[2,3,14.97]],"ltp":2.78,"tv":2102.55,"id":9625551}]}]}
{"op":"mcm","clk":"4234663150","pt":1631548514316,"mc":[{"id":"1.187562121","rc":[{"batl":[[0,1.59,37.16],[1,1.6,639.25],[2,1.61,18.35]],"ltp":1.56,"tv":13161.63,"id":20955040},{"batl":[[0,2.98,10.06],[1,3,14.97],[2,3.05,617.5]],"ltp":2.78,"tv":2102.55,"id":9625551}]}]}
{"op":"mcm","clk":"4234663213","pt":1631548515043,"mc":[{"id":"1.187562121","rc":[{"batb":[[0,2.76,5.44]],"ltp":2.78,"tv":2102.55,"id":9625551}]}]}
{"op":"mcm","clk":"4234663363","pt":1631548516756,"mc":[{"id":"1.187562121","rc":[{"trd":[[2.76,49.05],[2.78,57.48]],"batb":[[0,2.74,5.4],[1,2.64,20.22],[2,2.5,23.82]],"batl":[[0,2.76,145.12],[1,2.98,10.06],[2,3,14.97]],"ltp":2.76,"tv":2113.44,"id":9625551}],"tv":15275.08}]}
{"op":"mcm","clk":"4234663402","pt":1631548517226,"mc":[{"id":"1.187562121","rc":[{"trd":[[1.56,75.96]],"ltp":1.56,"tv":13178.08,"id":20955040},{"trd":[[2.76,58.35]],"batl":[[0,2.76,135.82],[1,2.88,6.46],[2,2.98,10.06]],"ltp":2.76,"tv":2122.74,"id":9625551}],"tv":15300.82}]}
{"op":"mcm","clk":"4234663607","pt":1631548519951,"mc":[{"id":"1.187562121","rc":[{"batl":[[0,1.58,226],[1,1.59,37.16],[2,1.6,639.25]],"ltp":1.56,"tv":13178.08,"id":20955040}]}]}
{"op":"mcm","clk":"4234664273","pt":1631548527428,"mc":[{"id":"1.187562121","rc":[{"batl":[[0,1.59,37.16],[1,1.6,639.25],[2,1.61,18.35]],"ltp":1.56,"tv":13178.08,"id":20955040},{"batl":[[0,2.98,10.06],[1,3,14.97],[2,3.05,617.5]],"ltp":2.76,"tv":2122.74,"id":9625551}]}]}
{"op":"mcm","clk":"4234664530","pt":1631548530340,"mc":[{"id":"1.187562121","rc":[{"batl":[[0,1.58,18.9],[1,1.59,37.16],[2,1.6,639.25]],"ltp":1.56,"tv":13178.08,"id":20955040},{"trd":[[2.74,35.8]],"batb":[[0,2.64,20.22],[1,2.5,23.82],[2,1.46,3.41]],"batl":[[0,2.74,130.42],[1,2.84,9.05],[2,2.98,10.06]],"ltp":2.74,"tv":2133.54,"id":9625551}],"tv":15311.62}]}
{"op":"mcm","clk":"4234664720","pt":1631548532449,"mc":[{"id":"1.187562121","rc":[{"trd":[[1.58,4.16]],"batl":[[0,1.58,18.82]],"ltp":1.58,"tv":13178.24,"id":20955040}],"tv":15311.78}]}
{"op":"mcm","clk":"4234664842","pt":1631548534375,"mc":[{"id":"1.187562121","rc":[{"batl":[[1,1.6,639.25],[2,1.95,415.94]],"ltp":1.58,"tv":13178.24,"id":20955040}]}]}
{"op":"mcm","clk":"4234664937","pt":1631548535833,"mc":[{"id":"1.187562121","rc":[{"batl":[[0,1.58,203.82]],"ltp":1.58,"tv":13178.24,"id":20955040}]}]}
{"op":"mcm","clk":"4234665149","pt":1631548538859,"mc":[{"id":"1.187562121","rc":[{"batb":[[2,1.48,146.34]],"batl":[[2,1.62,39.25]],"ltp":1.58,"tv":13178.24,"id":20955040},{"batb":[[1,2.6,5.69],[2,2.56,5.83]],"ltp":2.74,"tv":2133.54,"id":9625551}]}]}
{"op":"mcm","clk":"4234665491","pt":1631548542859,"mc":[{"id":"1.187562121","rc":[{"batb":[[1,1.48,146.34],[2,1.46,51.88]],"batl":[[0,1.58,185],[1,1.62,39.25],[2,1.64,44.18]],"ltp":1.58,"tv":13178.24,"id":20955040},{"trd":[[2.74,35.88]],"batl":[[0,2.74,130.37],[1,3,9.93],[2,3.1,4.65]],"ltp":2.74,"tv":2133.62,"id":9625551}],"tv":15311.87}]}
{"op":"mcm","clk":"4234665575","pt":1631548543854,"mc":[{"id":"1.187562121","rc":[{"batb":[[0,1.48,82.76],[1,1.45,147.68],[2,1.38,455.1]],"batl":[[0,1.62,39.25],[1,1.64,44.18],[2,1.95,415.94]],"ltp":1.58,"tv":13178.24,"id":20955040},{"batb":[[0,2.6,5.69],[1,2.56,5.83],[2,2.5,23.82]],"batl":[[1,3.1,4.65],[2,3.25,4.5]],"ltp":2.74,"tv":2133.62,"id":9625551}]}]}
{"op":"mcm","clk":"4234665644","pt":1631548544892,"mc":[{"id":"1.187562121","rc":[{"batl":[[0,1.64,44.18],[1,1.95,415.94],[2,3.8,27.43]],"ltp":1.58,"tv":13178.24,"id":20955040},{"batb":[[0,2.56,5.83],[1,2.5,23.82],[2,1.46,3.41]],"batl":[[0,3.1,4.65],[1,3.25,4.5],[2,5.6,50]],"ltp":2.74,"tv":2133.62,"id":9625551}]}]}
{"op":"mcm","clk":"4234665712","pt":1631548545779,"mc":[{"id":"1.187562121","rc":[{"batb":[[0,1.45,147.68],[1,1.38,455.1],[2,1.27,2]],"ltp":1.58,"tv":13178.24,"id":20955040},{"batl":[[0,3.25,4.5],[1,5.6,50],[2,990,0.01]],"ltp":2.74,"tv":2133.62,"id":9625551}]}]}
{"op":"mcm","clk":"4234665900","pt":1631548548352,"mc":[{"id":"1.187562121","rc":[{"batb":[[0,1.48,77.51],[1,1.45,147.68],[2,1.38,455.1]],"ltp":1.58,"tv":13178.24,"id":20955040},{"batl":[[0,2.72,130.37],[1,3.1,4.55],[2,3.25,4.5]],"ltp":2.74,"tv":2133.62,"id":9625551}]}]}
{"op":"mcm","clk":"4234666081","pt":1631548550693,"mc":[{"id":"1.187562121","rc":[{"batl":[[0,1.62,42.75],[1,1.64,44.18],[2,1.95,415.94]],"ltp":1.58,"tv":13178.24,"id":20955040},{"batb":[[0,2.6,5.54],[1,2.56,5.83],[2,2.5,23.82]],"ltp":2.74,"tv":2133.62,"id":9625551}]}]}
{"op":"mcm","clk":"4234666105","pt":1631548550951,"mc":[{"id":"1.187562121","rc":[{"batl":[[0,1.64,44.18],[1,1.95,415.94],[2,3.8,27.43]],"ltp":1.58,"tv":13178.24,"id":20955040},{"batb":[[0,2.56,5.83],[1,2.5,23.82],[2,1.46,3.41]],"ltp":2.74,"tv":2133.62,"id":9625551}]}]}
{"op":"mcm","clk":"4234666716","pt":1631548557899,"mc":[{"id":"1.187562121","rc":[{"batl":[[0,1.62,41.75],[1,1.64,44.18],[2,1.95,415.94]],"ltp":1.58,"tv":13178.24,"id":20955040},{"batb":[[0,2.6,5.69],[1,2.56,5.83],[2,2.5,23.82]],"ltp":2.74,"tv":2133.62,"id":9625551}]}]}
{"op":"mcm","clk":"4234666739","pt":1631548558206,"mc":[{"id":"1.187562121","rc":[{"batl":[[0,1.64,44.18],[1,1.95,415.94],[2,3.8,27.43]],"ltp":1.58,"tv":13178.24,"id":20955040},{"batb":[[0,2.56,5.83],[1,2.5,23.82],[2,1.46,3.41]],"ltp":2.74,"tv":2133.62,"id":9625551}]}]}
{"op":"mcm","clk":"4234667120","pt":1631548562819,"mc":[{"id":"1.187562121","rc":[{"batb":[[2,1.27,2]],"ltp":1.58,"tv":13178.24,"id":20955040}]}]}
{"op":"mcm","clk":"4234667292","pt":1631548564694,"mc":[{"id":"1.187562121","rc":[{"batb":[[0,1.48,117.44],[1,1.46,20.24],[2,1.45,147.68]],"batl":[[0,1.64,80.21],[1,1.66,627.53],[2,1.95,415.94]],"ltp":1.58,"tv":13178.24,"id":20955040},{"batb":[[0,2.6,5.47],[1,2.56,5.83],[2,2.5,23.82]],"batl":[[0,2.66,6.46],[1,2.72,130.37],[2,2.74,73]],"ltp":2.74,"tv":2133.62,"id":9625551}]}]}
{"op":"mcm","clk":"4234667375","pt":1631548565586,"mc":[{"id":"1.187562121","rc":[{"batb":[[0,1.54,55.36],[1,1.5,61.23],[2,1.48,117.44]],"batl":[[0,1.61,6.21],[1,1.64,80.21],[2,1.66,627.53]],"ltp":1.58,"tv":13178.24,"id":20955040}]}]}
{"op":"mcm","clk":"4234667695","pt":1631548569491,"mc":[{"id":"1.187562121","rc":[{"trd":[[1.58,115.99],[1.6,74.33]],"ltp":1.58,"tv":13300.81,"id":20955040},{"trd":[[2.66,31.67],[2.72,64.96]],"batl":[[0,2.72,65.41],[1,2.74,73],[2,2.76,10.88]],"ltp":2.72,"tv":2205.04,"id":9625551}],"tv":15505.86}]}
{"op":"mcm","clk":"4234667968","pt":1631548572701,"mc":[{"id":"1.187562121","rc":[{"batb":[[1,1.53,89.33],[2,1.51,78.99]],"batl":[[0,1.61,84.21],[2,1.66,670.78]],"ltp":1.58,"tv":13300.81,"id":20955040},{"batb":[[2,2.5,29.51]],"ltp":2.72,"tv":2205.04,"id":9625551}]}]}
{"op":"mcm","clk":"4234668176","pt":1631548575501,"mc":[{"id":"1.187562121","rc":[{"batl":[[0,2.74,73],[1,2.76,10.88],[2,2.78,348.37]],"ltp":2.72,"tv":2205.04,"id":9625551}]}]}
{"op":"mcm","clk":"4234668431","pt":1631548578590,"mc":[{"id":"1.187562121","rc":[{"trd":[[1.61,84.21]],"batl":[[0,1.64,80.21],[1,1.66,670.78],[2,1.67,43.5]],"ltp":1.61,"tv":13385.02,"id":20955040},{"trd":[[2.62,51.75]],"batl":[[0,2.62,13.66],[1,2.74,73],[2,2.76,10.88]],"ltp":2.62,"tv":2256.79,"id":9625551}],"tv":15641.82}]}
{"op":"mcm","clk":"4234668532","pt":1631548579636,"mc":[{"id":"1.187562121","rc":[{"batl":[[1,1.65,38.3],[2,1.66,670.78]],"ltp":1.61,"tv":13385.02,"id":20955040},{"batb":[[0,2.56,5.83],[1,2.52,5.99]],"ltp":2.62,"tv":2256.79,"id":9625551}]}]}
{"op":"mcm","clk":"4234668646","pt":1631548580843,"mc":[{"id":"1.187562121","rc":[{"batb":[[0,1.53,89.33],[1,1.51,78.99],[2,1.5,141.23]],"batl":[[0,1.95,415.94],[1,3.8,27.43],[2,8.8,7.22]],"ltp":1.61,"tv":13385.02,"id":20955040},{"batb":[[0,2.34,28.69],[1,1.46,3.41],[2,1.01,105.79]],"batl":[[0,2.6,8.53],[1,2.62,13.66],[2,2.9,4.95]],"ltp":2.62,"tv":2256.79,"id":9625551}]}]}
{"op":"mcm","clk":"4234668815","pt":1631548582738,"mc":[{"id":"1.187562121","rc":[{"trd":[[1.62,17.68]],"ltp":1.62,"tv":13398.7,"id":20955040},{"trd":[[2.6,8.53]],"batl":[[0,2.62,13.66],[1,2.9,4.95],[2,2.98,4.75]],"ltp":2.6,"tv":2265.32,"id":9625551}],"tv":15664.03}]}
{"op":"mcm","clk":"4234668919","pt":1631548583842,"mc":[{"id":"1.187562121","rc":[{"batl":[[0,1.67,38.5],[1,1.71,31.5],[2,1.95,415.94]],"ltp":1.62,"tv":13398.7,"id":20955040},{"batb":[[0,2.48,5.76],[1,2.4,5.71],[2,2.34,28.69]],"ltp":2.6,"tv":2265.32,"id":9625551}]}]}
{"op":"mcm","clk":"4234669460","pt":1631548590663,"mc":[{"id":"1.187562121","rc":[{"batl":[[0,1.65,41.1],[1,1.67,38.5],[2,1.71,31.5]],"ltp":1.62,"tv":13398.7,"id":20955040},{"batb":[[0,2.52,5.99],[1,2.48,5.76],[2,2.4,5.71]],"ltp":2.6,"tv":2265.32,"id":9625551}]}]}
{"op":"mcm","clk":"4234669479","pt":1631548590964,"mc":[{"id":"1.187562121","rc":[{"batl":[[0,1.67,38.5],[1,1.71,31.5],[2,1.95,415.94]],"ltp":1.62,"tv":13398.7,"id":20955040},{"batb":[[0,2.48,5.76],[1,2.4,5.71],[2,2.34,28.69]],"ltp":2.6,"tv":2265.32,"id":9625551}]}]}
{"op":"mcm","clk":"4234669596","pt":1631548592736,"mc":[{"id":"1.187562121","rc":[{"trd":[[1.61,106.44]],"batl":[[0,1.57,6.37],[1,1.6,426.46],[2,1.62,18.24]],"ltp":1.61,"tv":13420.93,"id":20955040},{"trd":[[2.62,65.41]],"batb":[[0,2.62,57.24],[1,2.6,28.62],[2,2.58,28.62]],"batl":[[0,2.88,259.58]],"ltp":2.62,"tv":2278.98,"id":9625551}],"tv":15699.92}]}
{"op":"mcm","clk":"4234669644","pt":1631548593361,"mc":[{"id":"1.187562121","rc":[{"batb":[[0,2.62,11.44],[1,2.6,26.94],[2,2.58,5.72]],"batl":[[0,2.8,10.72],[1,2.82,5.36],[2,2.84,5.36]],"ltp":2.62,"tv":2278.98,"id":9625551}]}]}
{"op":"mcm","clk":"4234669816","pt":1631548595865,"mc":[{"id":"1.187562121","rc":[{"batl":[[0,1.57,261.37],[1,1.6,446.83]],"ltp":1.61,"tv":13420.93,"id":20955040},{"batl":[[0,2.78,8.45],[1,2.8,10.72],[2,2.82,5.36]],"ltp":2.62,"tv":2278.98,"id":9625551}]}]}
{"op":"mcm","clk":"4234669900","pt":1631548597168,"mc":[{"id":"1.187562121","rc":[{"trd":[[1.54,741.74],[1.55,19.37],[1.56,91.02]],"ltp":1.54,"tv":13475.06,"id":20955040},{"trd":[[2.78,65.93],[2.8,10.72],[2.82,5.36],[2.84,11.53]],"batl":[[0,2.88,259.58],[1,2.9,4.95],[2,2.98,4.75]],"ltp":2.84,"tv":2308.87,"id":9625551}],"tv":15783.94}]}
{"op":"mcm","clk":"4234670026","pt":1631548598849,"mc":[{"id":"1.187562121","rc":[{"batb":[[1,1.52,91.74],[2,1.51,78.99]],"batl":[[2,1.62,59.49]],"ltp":1.54,"tv":13475.06,"id":20955040},{"batb":[[1,2.6,32.33]],"batl":[[2,2.94,4.75]],"ltp":2.84,"tv":2308.87,"id":9625551}]}]}
{"op":"mcm","clk":"4234670210","pt":1631548600881,"mc":[{"id":"1.187562121","rc":[{"batl":[[2,1.61,42.5]],"ltp":1.54,"tv":13475.06,"id":20955040},{"batb":[[0,2.62,16.98],[2,2.58,10.78]],"ltp":2.84,"tv":2308.87,"id":9625551}]}]}
{"op":"mcm","clk":"4234670543","pt":1631548606248,"mc":[{"id":"1.187562121","rc":[{"batb":[[0,1.54,216.59],[1,1.53,89.33],[2,1.52,91.74]],"ltp":1.54,"tv":13475.06,"id":20955040}]}]}
{"op":"mcm","clk":"4234670628","pt":1631548607194,"mc":[{"id":"1.187562121","rc":[{"batl":[[1,1.6,426.46]],"ltp":1.54,"tv":13475.06,"id":20955040}]}]}
{"op":"mcm","clk":"4234670729","pt":1631548608499,"mc":[{"id":"1.187562121","rc":[{"batb":[[1,1.52,91.74],[2,1.51,78.99]],"batl":[[0,1.57,255],[1,1.61,42.5],[2,1.62,41.25]],"ltp":1.54,"tv":13475.06,"id":20955040},{"batb":[[0,2.62,5.54],[1,2.6,5.39],[2,2.58,5.06]],"batl":[[0,2.94,4.75],[1,2.98,4.75],[2,3,4.66]],"ltp":2.84,"tv":2308.87,"id":9625551}]}]}
{"op":"mcm","clk":"4234670819","pt":1631548609756,"mc":[{"id":"1.187562121","rc":[{"batb":[[0,1.52,91.74],[1,1.51,78.99],[2,1.46,67.36]],"batl":[[0,1.63,44.5],[1,1.95,415.94],[2,3.8,27.43]],"ltp":1.54,"tv":13475.06,"id":20955040},{"batb":[[0,2.58,5.06],[1,2.44,25.16],[2,1.46,3.41]],"batl":[[2,5.6,50]],"ltp":2.84,"tv":2308.87,"id":9625551}]}]}
{"op":"mcm","clk":"4234671925","pt":1631548624815,"mc":[{"id":"1.187562121","rc":[{"batb":[[2,1.5,231.45]],"batl":[[0,1.54,20.74],[1,1.55,2051.64],[2,1.58,709.44]],"ltp":1.54,"tv":13475.06,"id":20955040},{"batb":[[0,2.8,53.56],[1,2.78,26.78],[2,2.76,99.24]],"batl":[[1,2.96,9.11],[2,2.98,4.75]],"ltp":2.84,"tv":2308.87,"id":9625551}]}]}
{"op":"mcm","clk":"4234672009","pt":1631548625909,"mc":[{"id":"1.187562121","rc":[{"batl":[[1,1.56,37.88],[2,1.58,728.14]],"ltp":1.54,"tv":13475.06,"id":20955040},{"batb":[[0,2.8,10.72],[1,2.78,5.36],[2,2.76,77.82]],"ltp":2.84,"tv":2308.87,"id":9625551}]}]}
{"op":"mcm","clk":"4234672232","pt":1631548628827,"mc":[{"id":"1.187562121","rc":[{"trd":[[1.54,783.22]],"batb":[[0,1.54,21.13],[1,1.52,91.74],[2,1.51,78.99]],"batl":[[0,1.56,37.88],[1,1.58,728.14],[2,1.63,44.5]],"ltp":1.54,"tv":13516.54,"id":20955040}],"tv":15825.42}]}
{"op":"mcm","clk":"4234672322","pt":1631548629816,"mc":[{"id":"1.187562121","rc":[{"trd":[[1.52,3366.55],[1.54,825.48]],"batb":[[0,1.52,36.53],[1,1.51,78.99],[2,1.5,231.45]],"ltp":1.52,"tv":13669.23,"id":20955040}],"tv":15978.1}]}
{"op":"mcm","clk":"4234672358","pt":1631548630231,"mc":[{"id":"1.187562121","rc":[{"trd":[[1.52,3370.84]],"batb":[[0,1.52,34.38]],"ltp":1.52,"tv":13673.52,"id":20955040},{"trd":[[2.94,2.18]],"batl":[[0,2.94,3.66]],"ltp":2.94,"tv":2311.05,"id":9625551}],"tv":15984.57}]}
{"op":"mcm","clk":"4234672421","pt":1631548631328,"mc":[{"id":"1.187562121","rc":[{"batb":[[2,1.5,313.13]],"batl":[[1,1.57,44.5],[2,1.58,728.14]],"ltp":1.52,"tv":13673.52,"id":20955040}]}]}
{"op":"mcm","clk":"4234672497","pt":1631548632521,"mc":[{"id":"1.187562121","rc":[{"batl":[[2,1.58,769.89]],"ltp":1.52,"tv":13673.52,"id":20955040}]}]}
{"op":"mcm","clk":"4234672606","pt":1631548633928,"mc":[{"id":"1.187562121","rc":[{"batl":[[0,1.56,96.88]],"ltp":1.52,"tv":13673.52,"id":20955040}]}]}
{"op":"mcm","clk":"4234672963","pt":1631548639043,"mc":[{"id":"1.187562121","rc":[{"batl":[[1,2.98,4.75],[2,3,120.33]],"ltp":2.94,"tv":2311.05,"id":9625551}]}]}
{"op":"mcm","clk":"4234673199","pt":1631548641916,"mc":[{"id":"1.187562121","rc":[{"batl":[[0,1.56,116.72]],"ltp":1.52,"tv":13673.52,"id":20955040},{"batl":[[0,2.92,10.64],[1,2.94,3.66],[2,2.98,4.75]],"ltp":2.94,"tv":2311.05,"id":9625551}]}]}
{"op":"mcm","clk":"4234673595","pt":1631548646713,"mc":[{"id":"1.187562121","rc":[{"batb":[[0,1.46,67.36],[1,1.43,72.89],[2,1.4,457.69]],"batl":[[0,1.56,59],[1,1.95,415.94],[2,3.8,27.43]],"ltp":1.52,"tv":13673.52,"id":20955040},{"batb":[[0,2.72,24.21],[1,2.58,21.98],[2,1.46,3.41]],"batl":[[0,2.98,4.75],[1,5.6,50],[2,990,0.01]],"ltp":2.94,"tv":2311.05,"id":9625551}]}]}
{"op":"mcm","clk":"4234673610","pt":1631548646922,"mc":[{"id":"1.187562121","rc":[{"batb":[[0,1.43,72.89],[1,1.4,457.69],[2,1.27,2]],"batl":[[0,1.95,415.94],[1,3.8,27.43],[2,8.8,7.22]],"ltp":1.52,"tv":13673.52,"id":20955040},{"batb":[[0,2.72,5.34]],"ltp":2.94,"tv":2311.05,"id":9625551}]}]}
{"op":"mcm","clk":"4234673854","pt":1631548650451,"mc":[{"id":"1.187562121","rc":[{"batb":[[0,1.51,51.99],[1,1.43,72.89],[2,1.4,457.69]],"batl":[[0,1.58,44.75],[1,1.95,415.94],[2,3.8,27.43]],"ltp":1.52,"tv":13673.52,"id":20955040}]}]}
{"op":"mcm","clk":"4234674478","pt":1631548659864,"mc":[{"id":"1.187562121","rc":[{"batl":[[0,1.55,20.7],[1,1.58,44.75],[2,1.95,415.94]],"ltp":1.52,"tv":13673.52,"id":20955040},{"batb":[[0,2.8,18.43],[1,2.72,5.34],[2,2.58,21.98]],"batl":[[0,2.86,20.75],[1,2.98,4.75],[2,5.6,50]],"ltp":2.94,"tv":2311.05,"id":9625551}]}]}
{"op":"mcm","clk":"4234674532","pt":1631548660645,"mc":[{"id":"1.187562121","rc":[{"batb":[[0,1.52,60.24],[1,1.51,51.99],[2,1.43,72.89]],"batl":[[0,1.57,43.5]],"ltp":1.52,"tv":13673.52,"id":20955040},{"batb":[[0,2.74,4.79]],"batl":[[0,2.94,4.25]],"ltp":2.94,"tv":2311.05,"id":9625551}]}]}
{"op":"mcm","clk":"4234674552","pt":1631548660958,"mc":[{"id":"1.187562121","rc":[{"batb":[[0,1.51,51.99],[1,1.43,72.89],[2,1.4,457.69]],"batl":[[0,1.58,44.75],[1,1.95,415.94],[2,3.8,27.43]],"ltp":1.52,"tv":13673.52,"id":20955040},{"batb":[[0,2.72,5.34],[1,2.58,21.98],[2,1.46,3.41]],"batl":[[0,2.98,4.75],[1,5.6,50],[2,990,0.01]],"ltp":2.94,"tv":2311.05,"id":9625551}]}]}
{"op":"mcm","clk":"4234675015","pt":1631548667831,"mc":[{"id":"1.187562121","rc":[{"batb":[[0,1.52,55.74],[1,1.51,51.99],[2,1.43,72.89]],"batl":[[0,1.57,43.5],[1,1.58,44.75],[2,1.95,415.94]],"ltp":1.52,"tv":13673.52,"id":20955040},{"batb":[[0,2.74,5.52],[1,2.72,5.34],[2,2.58,21.98]],"batl":[[0,2.94,4.25],[1,2.98,4.75],[2,5.6,50]],"ltp":2.94,"tv":2311.05,"id":9625551}]}]}
{"op":"mcm","clk":"4234675039","pt":1631548668147,"mc":[{"id":"1.187562121","rc":[{"batb":[[0,1.51,51.99],[1,1.43,72.89],[2,1.4,457.69]],"batl":[[0,1.58,44.75],[1,1.95,415.94],[2,3.8,27.43]],"ltp":1.52,"tv":13673.52,"id":20955040},{"batb":[[0,2.72,5.34],[1,2.58,21.98],[2,1.46,3.41]],"batl":[[0,2.98,4.75],[1,5.6,50],[2,990,0.01]],"ltp":2.94,"tv":2311.05,"id":9625551}]}]}
{"op":"mcm","clk":"4234675812","pt":1631548678565,"mc":[{"id":"1.187562121","rc":[{"batb":[[0,1.52,55.99],[1,1.51,51.99],[2,1.43,72.89]],"batl":[[0,1.57,45.5],[1,1.58,44.75],[2,1.95,415.94]],"ltp":1.52,"tv":13673.52,"id":20955040},{"batb":[[0,2.74,4.79],[1,2.72,5.34],[2,2.58,21.98]],"batl":[[0,2.94,4.25],[1,2.98,4.75],[2,5.6,50]],"ltp":2.94,"tv":2311.05,"id":9625551}]}]}
{"op":"mcm","clk":"4234675859","pt":1631548679354,"mc":[{"id":"1.187562121","rc":[{"batb":[[0,1.51,51.99],[1,1.43,72.89],[2,1.27,2]],"batl":[[0,1.58,44.75],[1,1.95,415.94],[2,3.8,27.43]],"ltp":1.52,"tv":13673.52,"id":20955040},{"batb":[[0,2.72,5.34],[1,2.58,21.98],[2,1.46,3.41]],"batl":[[0,2.98,4.75],[1,5.6,50],[2,990,0.01]],"ltp":2.94,"tv":2311.05,"id":9625551}]}]}
{"op":"mcm","clk":"4234675967","pt":1631548680668,"mc":[{"id":"1.187562121","rc":[{"batb":[[2,1.4,42.21]],"batl":[[0,1.52,6.58],[1,1.54,38.37],[2,1.56,953.6]],"ltp":1.52,"tv":13673.52,"id":20955040},{"batb":[[0,2.92,5.25],[1,2.86,31.46],[2,2.84,57.98]],"batl":[[1,3,6.56],[2,3.1,198.78]],"ltp":2.94,"tv":2311.05,"id":9625551}]}]}
{"op":"mcm","clk":"4234676063","pt":1631548681778,"mc":[{"id":"1.187562121","rc":[{"batb":[[1,1.48,20.28],[2,1.47,10.14]],"ltp":1.52,"tv":13673.52,"id":20955040},{"batb":[[1,2.86,10.48],[2,2.84,47.49]],"ltp":2.94,"tv":2311.05,"id":9625551}]}]}
{"op":"mcm","clk":"4234676334","pt":1631548685582,"mc":[{"id":"1.187562121","rc":[{"trd":[[1.48,901.4],[1.5,67.84],[1.51,749.69]],"batb":[[0,1.48,13.64],[1,1.47,10.14],[2,1.46,10.14]],"ltp":1.48,"tv":13811.15,"id":20955040},{"trd":[[2.98,5.85],[3,15.04]],"batl":[[0,3.1,198.78],[1,3.35,2.99],[2,5.6,50]],"ltp":3.0,"tv":2323.46,"id":9625551}],"tv":16134.61}]}
{"op":"mcm","clk":"4234676438","pt":1631548686994,"mc":[{"id":"1.187562121","rc":[{"batb":[[0,1.5,55.2],[1,1.49,59.01],[2,1.48,13.64]],"batl":[[2,1.55,42.9]],"ltp":1.48,"tv":13811.15,"id":20955040},{"batl":[[0,3,4.25],[1,3.05,3.9],[2,3.1,198.78]],"ltp":3.0,"tv":2323.46,"id":9625551}]}]}
{"op":"mcm","clk":"4234676595","pt":1631548689096,"mc":[{"id":"1.187562121","rc":[{"batb":[[2,1.48,67.9]],"ltp":1.48,"tv":13811.15,"id":20955040},{"batl":[[2,3.1,203.23]],"ltp":3.0,"tv":2323.46,"id":9625551}]}]}
{"op":"mcm","clk":"4234677037","pt":1631548695596,"mc":[{"id":"1.187562121","rc":[{"batb":[[0,2.86,10.48],[1,2.84,47.49],[2,2.82,5.24]],"ltp":3.0,"tv":2323.46,"id":9625551}]}]}
{"op":"mcm","clk":"4234677179","pt":1631548697476,"mc":[{"id":"1.187562121","rc":[{"batb":[[0,1.41,77.92],[1,1.34,472.33],[2,1.27,2]],"batl":[[0,1.57,41.5],[1,1.95,415.94],[2,3.8,27.43]],"ltp":1.48,"tv":13811.15,"id":20955040},{"batb":[[0,2.74,5.02],[1,2.7,19.38],[2,1.46,3.41]],"batl":[[0,3.05,3.9],[1,5.6,50],[2,990,0.01]],"ltp":3.0,"tv":2323.46,"id":9625551}]}]}
{"op":"mcm","clk":"4234677370","pt":1631548700765,"mc":[{"id":"1.187562121","rc":[{"batb":[[0,1.49,51.01],[1,1.41,77.92],[2,1.34,472.33]],"ltp":1.48,"tv":13811.15,"id":20955040}]}]}
{"op":"mcm","clk":"4234677548","pt":1631548702907,"mc":[{"id":"1.187562121","rc":[{"batb":[[0,1.52,1.6],[1,1.49,51.01],[2,1.42,72.2]],"ltp":1.48,"tv":13811.15,"id":20955040}]}]}
{"op":"mcm","clk":"4234677567","pt":1631548703068,"mc":[{"id":"1.187562121","rc":[{"batb":[[2,1.42,144.39]],"ltp":1.48,"tv":13811.15,"id":20955040}]}]}
{"op":"mcm","clk":"4234677734","pt":1631548704904,"mc":[{"id":"1.187562121","rc":[{"trd":[[1.52,3374.04]],"batb":[[0,1.49,51.01],[1,1.42,144.39],[2,1.41,77.92]],"ltp":1.52,"tv":13814.35,"id":20955040}],"tv":16137.81}]}
{"op":"mcm","clk":"4234678024","pt":1631548708913,"mc":[{"id":"1.187562121","rc":[{"batb":[[0,1.55,23.1],[1,1.49,51.01],[2,1.42,144.39]],"ltp":1.52,"tv":13814.35,"id":20955040}]}]}
{"op":"mcm","clk":"4234678180","pt":1631548710902,"mc":[{"id":"1.187562121","rc":[{"trd":[[1.55,65.57]],"batb":[[0,1.5,51.26]],"batl":[[0,1.55,20],[1,1.57,41.5],[2,1.95,415.94]],"ltp":1.55,"tv":13860.55,"id":20955040},{"batb":[[0,2.8,4.03],[1,2.74,5.02],[2,2.7,19.38]],"batl":[[0,3,3.59],[1,3.05,3.9],[2,5.6,50]],"ltp":3.0,"tv":2323.46,"id":9625551}],"tv":16184.01}]}
{"op":"mcm","clk":"4234678196","pt":1631548711109,"mc":[{"id":"1.187562121","rc":[{"batb":[[0,1.49,51.01],[1,1.42,144.39],[2,1.41,77.92]],"batl":[[0,1.57,41.5],[1,1.95,415.94],[2,3.8,27.43]],"ltp":1.55,"tv":13860.55,"id":20955040},{"batb":[[0,2.74,5.02],[1,2.7,19.38],[2,1.46,3.41]],"batl":[[0,3.05,3.9],[1,5.6,50],[2,990,0.01]],"ltp":3.0,"tv":2323.46,"id":9625551}]}]}
{"op":"mcm","clk":"4234678975","pt":1631548722207,"mc":[{"id":"1.187562121","rc":[{"trd":[[2.74,44.9]],"batb":[[0,2.7,19.89],[1,1.46,3.41],[2,1.01,105.79]],"ltp":2.74,"tv":2332.48,"id":9625551}],"tv":16193.03}]}
{"op":"mcm","clk":"4234679168","pt":1631548724819,"mc":[{"id":"1.187562121","rc":[{"batl":[[1,3.8,27.43],[2,8.8,7.22]],"ltp":1.55,"tv":13860.55,"id":20955040}]}]}
{"op":"mcm","clk":"4234679454","pt":1631548728837,"mc":[{"id":"1.187562121","rc":[{"batb":[[1,1.47,14.83],[2,1.46,412.85]],"batl":[[0,1.5,17.18],[1,1.52,170.46],[2,1.54,19.19]],"ltp":1.55,"tv":13860.55,"id":20955040},{"batb":[[0,3,5.25],[1,2.96,174.93],[2,2.94,51.02]],"ltp":2.74,"tv":2332.48,"id":9625551}]}]}
{"op":"mcm","clk":"4234679516","pt":1631548729829,"mc":[{"id":"1.187562121","rc":[{"batb":[[2,1.46,515.59]],"ltp":1.55,"tv":13860.55,"id":20955040},{"batb":[[2,2.94,10.2]],"batl":[[1,3.45,2.9],[2,5.6,50]],"ltp":2.74,"tv":2332.48,"id":9625551}]}]}
{"op":"mcm","clk":"4234679522","pt":1631548729935,"mc":[{"id":"1.187562121","rc":[{"batb":[[2,1.46,433.39]],"ltp":1.55,"tv":13860.55,"id":20955040}]}]}
{"op":"mcm","clk":"4234679791","pt":1631548733836,"mc":[{"id":"1.187562121","rc":[{"trd":[[1.49,102.22]],"batb":[[0,1.49,8.92]],"ltp":1.49,"tv":13944.73,"id":20955040}],"tv":16277.21}]}
{"op":"mcm","clk":"4234679858","pt":1631548734827,"mc":[{"id":"1.187562121","rc":[{"trd":[[1.49,120.06]],"batb":[[0,1.47,14.83],[1,1.46,433.39],[2,1.45,10.28]],"batl":[[0,1.49,7.08],[1,1.5,17.18],[2,1.52,170.46]],"ltp":1.49,"tv":13962.57,"id":20955040}],"tv":16295.05}]}
{"op":"mcm","clk":"4234679919","pt":1631548735608,"mc":[{"id":"1.187562121","rc":[{"batl":[[1,3.35,3.7],[2,3.45,6]],"ltp":2.74,"tv":2332.48,"id":9625551}]}]}
{"op":"mcm","clk":"4234680056","pt":1631548737611,"mc":[{"id":"1.187562121","rc":[{"trd":[[1.49,134.22]],"batl":[[0,1.5,17.18],[1,1.52,170.46],[2,1.54,19.19]],"ltp":1.49,"tv":13976.73,"id":20955040}],"tv":16309.22}]}
{"op":"mcm","clk":"4234680105","pt":1631548738454,"mc":[{"id":"1.187562121","rc":[{"batl":[[2,3.4,3.64]],"ltp":2.74,"tv":2332.48,"id":9625551}]}]}
{"op":"mcm","clk":"4234680357","pt":1631548741343,"mc":[{"id":"1.187562121","rc":[{"batl":[[0,1.5,172.18]],"ltp":1.49,"tv":13976.73,"id":20955040}]}]}
{"op":"mcm","clk":"4234680581","pt":1631548744638,"mc":[{"id":"1.187562121","rc":[{"trd":[[1.5,67.94]],"batl":[[0,1.5,172.13]],"ltp":1.5,"tv":13976.83,"id":20955040}],"tv":16309.31}]}
{"op":"mcm","clk":"4234680947","pt":1631548749361,"mc":[{"id":"1.187562121","rc":[{"batl":[[0,3.05,5.9]],"ltp":2.74,"tv":2332.48,"id":9625551}]}]}
{"op":"mcm","clk":"4234681234","pt":1631548752633,"mc":[{"id":"1.187562121","rc":[{"batl":[[0,3.05,3.9]],"ltp":2.74,"tv":2332.48,"id":9625551}]}]}
{"op":"mcm","clk":"4234681451","pt":1631548755762,"mc":[{"id":"1.187562121","rc":[{"trd":[[3,19.04]],"batb":[[0,3,3.25]],"ltp":3.0,"tv":2336.48,"id":9625551}],"tv":16313.31}]}
{"op":"mcm","clk":"4234682291","pt":1631548765874,"mc":[{"id":"1.187562121","rc":[{"batb":[[0,1.46,433.39],[1,1.45,10.28],[2,1.44,10.28]],"batl":[[0,1.5,161.62],[1,1.52,131.58],[2,1.56,43.42]],"ltp":1.5,"tv":13976.83,"id":20955040},{"batb":[[0,2.96,174.93],[1,2.94,10.2],[2,2.92,5.1]],"ltp":3.0,"tv":2336.48,"id":9625551}]}]}
{"op":"mcm","clk":"4234682396","pt":1631548766874,"mc":[{"id":"1.187562121","rc":[{"batb":[[0,1.39,55.91],[1,1.35,94.87],[2,1.27,2]],"batl":[[0,1.5,155],[1,1.56,43.42],[2,1.57,41.5]],"ltp":1.5,"tv":13976.83,"id":20955040},{"batb":[[0,2.78,5.16],[1,2.76,18.29],[2,2.72,5.1]],"batl":[[0,3.6,3.46],[1,5.6,50],[2,990,0.01]],"ltp":3.0,"tv":2336.48,"id":9625551}]}]}
{"op":"mcm","clk":"4234682458","pt":1631548767501,"mc":[{"id":"1.187562121","rc":[{"batl":[[0,1.59,42.5],[1,3.8,27.43],[2,8.8,7.22]],"ltp":1.5,"tv":13976.83,"id":20955040},{"batb":[[0,2.76,18.29],[1,2.68,4.61],[2,1.46,3.41]],"ltp":3.0,"tv":2336.48,"id":9625551}]}]}
{"op":"mcm","clk":"4234682576","pt":1631548768866,"mc":[{"id":"1.187562121","rc":[{"batl":[[0,1.5,8.51],[1,1.59,42.5],[2,3.8,27.43]],"ltp":1.5,"tv":13976.83,"id":20955040},{"batb":[[0,3,4.25],[1,2.76,18.29],[2,2.68,4.61]],"batl":[[0,3.1,5.3],[1,3.6,3.46],[2,5.6,50]],"ltp":3.0,"tv":2336.48,"id":9625551}]}]}
{"op":"mcm","clk":"4234682655","pt":1631548769826,"mc":[{"id":"1.187562121","rc":[{"batb":[[0,1.42,57.94],[1,1.39,55.91],[2,1.35,94.87]],"batl":[[0,1.59,42.5],[1,3.8,27.43],[2,8.8,7.22]],"ltp":1.5,"tv":13976.83,"id":20955040},{"batb":[[0,2.76,18.29],[1,2.68,4.61],[2,1.46,3.41]],"batl":[[0,3.4,3.64]],"ltp":3.0,"tv":2336.48,"id":9625551}]}]}
{"op":"mcm","clk":"4234682732","pt":1631548770666,"mc":[{"id":"1.187562121","rc":[{"batb":[[0,1.39,55.91],[1,1.35,94.87],[2,1.27,2]],"batl":[[0,1.56,42.92],[1,1.59,42.5],[2,3.8,27.43]],"ltp":1.5,"tv":13976.83,"id":20955040},{"batb":[[0,2.78,5.16],[1,2.76,18.29],[2,2.68,4.61]],"batl":[[0,3.6,3.46],[1,5.6,50],[2,990,0.01]],"ltp":3.0,"tv":2336.48,"id":9625551}]}]}
{"op":"mcm","clk":"4234682758","pt":1631548770986,"mc":[{"id":"1.187562121","rc":[{"batl":[[0,1.59,42.5],[1,3.8,27.43],[2,8.8,7.22]],"ltp":1.5,"tv":13976.83,"id":20955040},{"batb":[[0,2.76,18.29],[1,2.68,4.61],[2,1.46,3.41]],"ltp":3.0,"tv":2336.48,"id":9625551}]}]}
{"op":"mcm","clk":"4234683102","pt":1631548774781,"mc":[{"id":"1.187562121","rc":[{"batl":[[0,1.5,40.19],[1,1.59,42.5],[2,3.8,27.43]],"ltp":1.5,"tv":13976.83,"id":20955040},{"batb":[[0,3,40],[1,2.76,18.29],[2,2.68,4.61]],"batl":[[0,3.15,37.9],[1,3.6,3.46],[2,5.6,50]],"ltp":3.0,"tv":2336.48,"id":9625551}]}]}
{"op":"mcm","clk":"4234683125","pt":1631548775086,"mc":[{"id":"1.187562121","rc":[{"batl":[[0,1.59,42.5],[1,3.8,27.43],[2,8.8,7.22]],"ltp":1.5,"tv":13976.83,"id":20955040},{"batb":[[0,2.76,18.29],[1,2.68,4.61],[2,1.46,3.41]],"batl":[[0,3.6,3.46],[1,5.6,50],[2,990,0.01]],"ltp":3.0,"tv":2336.48,"id":9625551}]}]}
{"op":"mcm","clk":"4234683363","pt":1631548777869,"mc":[{"id":"1.187562121","rc":[{"batl":[[0,1.56,45.67],[1,1.59,42.5],[2,3.8,27.43]],"ltp":1.5,"tv":13976.83,"id":20955040},{"batb":[[0,2.78,5.16],[1,2.76,18.29],[2,2.68,4.61]],"ltp":3.0,"tv":2336.48,"id":9625551}]}]}
{"op":"mcm","clk":"4234683386","pt":1631548778181,"mc":[{"id":"1.187562121","rc":[{"batl":[[0,1.59,42.5],[1,3.8,27.43],[2,8.8,7.22]],"ltp":1.5,"tv":13976.83,"id":20955040},{"batb":[[0,2.76,18.29],[1,2.68,4.61],[2,1.46,3.41]],"ltp":3.0,"tv":2336.48,"id":9625551}]}]}
{"op":"mcm","clk":"4234683631","pt":1631548780905,"mc":[{"id":"1.187562121","rc":[{"batl":[[0,3.8,27.43],[1,8.8,7.22],[2,44,7.22]],"ltp":1.5,"tv":13976.83,"id":20955040}]}]}
{"op":"mcm","clk":"4234683863","pt":1631548783895,"mc":[{"id":"1.187562121","rc":[{"batb":[[0,1.4,12.4],[1,1.39,55.91],[2,1.35,94.87]],"batl":[[0,1.44,6.94],[1,1.45,62.06],[2,1.46,153.69]],"ltp":1.5,"tv":13976.83,"id":20955040},{"batb":[[0,3.35,5.69],[1,3,434.79],[2,2.76,18.29]],"batl":[[0,3.5,4.96],[1,3.6,248.19],[2,5.6,50]],"ltp":3.0,"tv":2336.48,"id":9625551}]}]}
{"op":"mcm","clk":"4234683947","pt":1631548784888,"mc":[{"id":"1.187562121","rc":[{"batl":[[1,1.45,20.68],[2,1.46,133]],"ltp":1.5,"tv":13976.83,"id":20955040},{"batb":[[1,3.15,30.78],[2,3,434.79]],"batl":[[1,3.55,8.44],[2,3.6,252.41]],"ltp":3.0,"tv":2336.48,"id":9625551}]}]}
{"op":"mcm","clk":"4234684346","pt":1631548790378,"mc":[{"id":"1.187562121","rc":[{"batb":[[2,3,439.79]],"ltp":3.0,"tv":2336.48,"id":9625551}]}]}
{"op":"mcm","clk":"4234684808","pt":1631548795786,"mc":[{"id":"1.187562121","rc":[{"batb":[[0,1.35,94.87],[1,1.31,74.79],[2,1.29,120.79]],"batl":[[0,1.53,53.5],[1,3.8,27.43],[2,8.8,7.22]],"ltp":1.5,"tv":13976.83,"id":20955040},{"batb":[[0,3.15,30.78],[1,2.96,37.33],[2,2.88,4.96]],"batl":[[0,4.3,2.45],[1,5.6,50],[2,990,0.01]],"ltp":3.0,"tv":2336.48,"id":9625551}]}]}
{"op":"mcm","clk":"4234684844","pt":1631548796207,"mc":[{"id":"1.187562121","rc":[{"batb":[[0,1.31,74.79],[1,1.29,120.79],[2,1.27,2]],"ltp":1.5,"tv":13976.83,"id":20955040},{"batb":[[0,2.96,37.33],[1,2.88,4.96],[2,1.46,3.41]],"ltp":3.0,"tv":2336.48,"id":9625551}]}]}
{"op":"mcm","clk":"4234685052","pt":1631548798790,"mc":[{"id":"1.187562121","rc":[{"batl":[[0,1.43,132],[1,1.53,53.5],[2,3.8,27.43]],"ltp":1.5,"tv":13976.83,"id":20955040}]}]}
{"op":"mcm","clk":"4234685091","pt":1631548799316,"mc":[{"id":"1.187562121","rc":[{"batl":[[0,1.53,53.5],[1,3.8,27.43],[2,8.8,7.22]],"ltp":1.5,"tv":13976.83,"id":20955040}]}]}
{"op":"mcm","clk":"4234685184","pt":1631548800011,"mc":[{"id":"1.187562121","rc":[{"batl":[[0,3.35,2.25],[1,4.3,2.45],[2,5.6,50]],"ltp":3.0,"tv":2336.48,"id":9625551}]}]}
{"op":"mcm","clk":"4234685536","pt":1631548802830,"mc":[{"id":"1.187562121","rc":[{"trd":[[3.35,22.26]],"batl":[[0,4.3,2.45],[1,5.6,50],[2,990,0.01]],"ltp":3.35,"tv":2340.98,"id":9625551}],"tv":16317.81}]}
{"op":"mcm","clk":"4234686829","pt":1631548816633,"mc":[{"id":"1.187562121","rc":[{"batb":[[0,1.34,77.72],[1,1.31,74.79],[2,1.29,120.79]],"batl":[[0,1.5,45.51],[1,1.53,53.5],[2,3.8,27.43]],"ltp":1.5,"tv":13976.83,"id":20955040},{"batb":[[0,3,5],[1,2.96,37.33],[2,2.88,4.96]],"batl":[[0,3.95,2.7],[1,4.3,2.45],[2,5.6,50]],"ltp":3.35,"tv":2340.98,"id":9625551}]}]}
{"op":"mcm","clk":"4234686890","pt":1631548817421,"mc":[{"id":"1.187562121","rc":[{"batb":[[0,1.31,74.79],[1,1.29,120.79],[2,1.27,2]],"batl":[[0,1.53,53.5],[1,3.8,27.43],[2,8.8,7.22]],"ltp":1.5,"tv":13976.83,"id":20955040},{"batb":[[0,2.96,37.33],[1,2.88,4.96],[2,1.46,3.41]],"batl":[[0,4.3,2.45],[1,5.6,50],[2,990,0.01]],"ltp":3.35,"tv":2340.98,"id":9625551}]}]}
{"op":"mcm","clk":"4234687276","pt":1631548822644,"mc":[{"id":"1.187562121","rc":[{"batl":[[0,3.8,27.43],[1,8.8,7.22],[2,44,7.22]],"ltp":1.5,"tv":13976.83,"id":20955040}]}]}
{"op":"mcm","clk":"4234687361","pt":1631548823638,"mc":[{"id":"1.187562121","rc":[{"batb":[[0,1.34,69.72],[1,1.31,74.79],[2,1.29,120.79]],"batl":[[0,1.5,47.93],[1,3.8,27.43],[2,8.8,7.22]],"ltp":1.5,"tv":13976.83,"id":20955040},{"batb":[[0,3,5],[1,2.96,37.33],[2,2.88,4.96]],"batl":[[0,3.95,2.5],[1,4.3,2.45],[2,5.6,50]],"ltp":3.35,"tv":2340.98,"id":9625551}]}]}
{"op":"mcm","clk":"4234687384","pt":1631548823950,"mc":[{"id":"1.187562121","rc":[{"batb":[[0,1.31,74.79],[1,1.29,120.79],[2,1.27,2]],"batl":[[0,3.8,27.43],[1,8.8,7.22],[2,44,7.22]],"ltp":1.5,"tv":13976.83,"id":20955040},{"batb":[[0,2.96,37.33],[1,2.88,4.96],[2,1.46,3.41]],"batl":[[0,4.3,2.45],[1,5.6,50],[2,990,0.01]],"ltp":3.35,"tv":2340.98,"id":9625551}]}]}
{"op":"mcm","clk":"4234687513","pt":1631548825566,"mc":[{"id":"1.187562121","rc":[{"batb":[[2,1.27,48.53]],"batl":[[0,1.35,14.35],[1,1.37,7.3],[2,1.39,42.51]],"ltp":1.5,"tv":13976.83,"id":20955040},{"batb":[[0,3.8,10.52],[1,3.75,40],[2,3.7,230.84]],"batl":[[0,4,5.79],[1,4.2,244.8],[2,4.3,2.45]],"ltp":3.35,"tv":2340.98,"id":9625551}]}]}
{"op":"mcm","clk":"4234687639","pt":1631548826669,"mc":[{"id":"1.187562121","rc":[{"batb":[[0,1.32,22.72],[1,1.31,86.15],[2,1.3,11.36]],"ltp":1.5,"tv":13976.83,"id":20955040},{"batb":[[1,3.75,8],[2,3.7,214.84]],"ltp":3.35,"tv":2340.98,"id":9625551}]}]}
{"op":"mcm","clk":"4234688264","pt":1631548833843,"mc":[{"id":"1.187562121","rc":[{"batl":[[0,1.35,139.35]],"ltp":1.5,"tv":13976.83,"id":20955040}]}]}
{"op":"mcm","clk":"4234688993","pt":1631548842480,"mc":[{"id":"1.187562121","rc":[{"batl":[[2,1.43,58.5]],"ltp":1.5,"tv":13976.83,"id":20955040}]}]}
{"op":"mcm","clk":"4234689638","pt":1631548849669,"mc":[{"id":"1.187562121","rc":[{"batb":[[0,1.29,119.61],[1,1.27,84.87],[2,1.24,95.77]],"batl":[[0,1.35,125],[1,1.43,58.5],[2,1.46,49.25]],"ltp":1.5,"tv":13976.83,"id":20955040},{"batb":[[0,3.6,22.48],[1,3.3,31.71],[2,3.15,4.23]],"batl":[[0,4.8,2.07],[1,5.2,2.03],[2,5.6,50]],"ltp":3.35,"tv":2340.98,"id":9625551}]}]}
{"op":"mcm","clk":"4234689686","pt":1631548850164,"mc":[{"id":"1.187562121","rc":[{"batb":[[0,1.27,2],[1,1.24,95.77],[2,1.23,154.42]],"batl":[[0,1.46,49.25],[1,3.8,27.43],[2,8.8,7.22]],"ltp":1.5,"tv":13976.83,"id":20955040},{"batb":[[0,3.3,27.93],[1,3.15,4.23],[2,1.46,3.41]],"batl":[[0,5.2,2.03],[1,5.6,50],[2,990,0.01]],"ltp":3.35,"tv":2340.98,"id":9625551}]}]}
{"op":"mcm","clk":"4234690838","pt":1631548862016,"mc":[{"id":"1.187562121","rc":[{"batl":[[0,3.8,27.43],[1,8.8,7.22],[2,44,7.22]],"ltp":1.5,"tv":13976.83,"id":20955040}]}]}
{"op":"mcm","clk":"4234690987","pt":1631548863907,"mc":[{"id":"1.187562121","rc":[{"batb":[[0,1.27,90.87]],"batl":[[0,1.43,52.5],[1,3.8,27.43],[2,8.8,7.22]],"ltp":1.5,"tv":13976.83,"id":20955040},{"batb":[[0,3.3,31.71]],"batl":[[0,4.8,2.27],[1,5.2,2.03],[2,5.6,50]],"ltp":3.35,"tv":2340.98,"id":9625551}]}]}
{"op":"mcm","clk":"4234691058","pt":1631548864588,"mc":[{"id":"1.187562121","rc":[{"batb":[[0,1.27,2],[1,1.25,428.72],[2,1.24,95.77]],"batl":[[0,1.29,93.02],[1,1.3,664.16],[2,1.31,7.63]],"ltp":1.5,"tv":13976.83,"id":20955040},{"batb":[[0,4.5,7.25],[1,4.4,20.46],[2,4.3,10.22]],"batl":[[0,4.8,8.24],[1,5,107.18],[2,5.2,2.03]],"ltp":3.35,"tv":2340.98,"id":9625551}]}]}
{"op":"mcm","clk":"4234691159","pt":1631548865590,"mc":[{"id":"1.187562121","rc":[{"batb":[[2,1.24,103.83]],"ltp":1.5,"tv":13976.83,"id":20955040},{"batb":[[1,4.4,6.82],[2,4.3,3.4]],"batl":[[1,4.9,6.12],[2,5,110.24]],"ltp":3.35,"tv":2340.98,"id":9625551}]}]}
{"op":"mcm","clk":"4234691776","pt":1631548872593,"mc":[{"id":"1.187562121","rc":[{"batl":[[0,1.29,448.02]],"ltp":1.5,"tv":13976.83,"id":20955040}]}]}
{"op":"mcm","clk":"4234692092","pt":1631548876406,"mc":[{"id":"1.187562121","rc":[{"trd":[[1.27,17.36]],"batb":[[0,1.25,428.72],[1,1.24,103.83],[2,1.23,154.42]],"ltp":1.27,"tv":13978.83,"id":20955040},{"trd":[[4.8,23.77],[4.9,27.6],[5,210.14]],"batl":[[0,5,6.95],[1,5.1,3.06],[2,5.2,2.03]],"ltp":5.0,"tv":2576.74,"id":9625551}],"tv":16555.58}]}
{"op":"mcm","clk":"4234692310","pt":1631548878811,"mc":[{"id":"1.187562121","rc":[{"batb":[[0,1.24,95.77],[1,1.23,154.42],[2,1.22,168.77]],"batl":[[0,1.29,355],[1,1.33,44.43],[2,1.35,99.98]],"ltp":1.27,"tv":13978.83,"id":20955040},{"batb":[[0,4.1,31.62],[1,3.85,2.97],[2,3.8,38.5]],"batl":[[0,5.2,2.03],[1,5.6,2.01],[2,990,0.01]],"ltp":5.0,"tv":2576.74,"id":9625551}]}]}
{"op":"mcm","clk":"4234692342","pt":1631548879336,"mc":[{"id":"1.187562121","rc":[{"batb":[[0,1.22,120.34],[1,1.21,2],[2,1.19,189.64]],"batl":[[0,1.38,61.25],[1,3.8,27.43],[2,8.8,7.22]],"ltp":1.27,"tv":13978.83,"id":20955040},{"batb":[[0,3.8,38.5],[1,3.6,3.09],[2,1.46,3.41]],"batl":[[0,5.6,2.01],[1,990,0.01],[2,990,0]],"ltp":5.0,"tv":2576.74,"id":9625551}]}]}
{"op":"mcm","clk":"4234692418","pt":1631548880426,"mc":[{"id":"1.187562121","rc":[{"batb":[[1,1.21,115.69]],"ltp":1.27,"tv":13978.83,"id":20955040},{"batl":[[1,5.8,2.02],[2,990,0.01]],"ltp":5.0,"tv":2576.74,"id":9625551}]}]}
{"op":"mcm","clk":"4234693109","pt":1631548885842,"mc":[{"id":"1.187562121","rc":[{"batb":[[0,1.24,98.02],[1,1.22,120.34],[2,1.21,115.69]],"ltp":1.27,"tv":13978.83,"id":20955040},{"batl":[[0,5.2,2.03],[1,5.6,2.01],[2,5.8,2.02]],"ltp":5.0,"tv":2576.74,"id":9625551}]}]}
{"op":"mcm","clk":"4234693219","pt":1631548886418,"mc":[{"id":"1.187562121","rc":[{"batb":[[0,1.22,120.34],[1,1.21,115.69],[2,1.19,189.64]],"ltp":1.27,"tv":13978.83,"id":20955040},{"batl":[[0,5.6,2.01],[1,5.8,2.02],[2,990,0.01]],"ltp":5.0,"tv":2576.74,"id":9625551}]}]}
{"op":"mcm","clk":"4234693666","pt":1631548889724,"mc":[{"id":"1.187562121","rc":[{"batl":[[0,1.35,69.1],[1,1.38,61.25],[2,3.8,27.43]],"ltp":1.27,"tv":13978.83,"id":20955040},{"batb":[[0,3.85,3.17],[1,3.8,38.5],[2,3.6,3.09]],"ltp":5.0,"tv":2576.74,"id":9625551}]}]}
{"op":"mcm","clk":"4234693687","pt":1631548889932,"mc":[{"id":"1.187562121","rc":[{"batl":[[0,1.38,61.25],[1,3.8,27.43],[2,8.8,7.22]],"ltp":1.27,"tv":13978.83,"id":20955040},{"batb":[[0,3.8,38.5],[1,3.6,3.09],[2,1.46,3.41]],"ltp":5.0,"tv":2576.74,"id":9625551}]}]}
{"op":"mcm","clk":"4234694124","pt":1631548894129,"mc":[{"id":"1.187562121","rc":[{"trd":[[1.22,213.33]],"batb":[[0,1.22,118.4]],"ltp":1.22,"tv":13982.71,"id":20955040}],"tv":16559.45}]}
{"op":"mcm","clk":"4234694267","pt":1631548895730,"mc":[{"id":"1.187562121","rc":[{"trd":[[1.22,450.13]],"batb":[[0,1.21,115.69],[1,1.2,621.21]],"batl":[[0,1.22,45.54],[1,1.23,29.94],[2,1.24,120.96]],"ltp":1.22,"tv":14219.51,"id":20955040},{"batl":[[1,5.7,5.86],[2,5.8,2.02]],"ltp":5.0,"tv":2576.74,"id":9625551}],"tv":16796.25}]}
{"op":"mcm","clk":"4234694416","pt":1631548896731,"mc":[{"id":"1.187562121","rc":[{"batb":[[1,1.2,629.54],[2,1.19,239.3]],"batl":[[0,1.22,16.39],[2,1.24,72.58]],"ltp":1.22,"tv":14219.51,"id":20955040},{"batb":[[0,4.6,23.65],[1,4,32.96],[2,3.8,38.5]],"ltp":5.0,"tv":2576.74,"id":9625551}]}]}
{"op":"mcm","clk":"4234694444","pt":1631548897036,"mc":[{"id":"1.187562121","rc":[{"batl":[[2,1.24,24.2]],"ltp":1.22,"tv":14219.51,"id":20955040},{"batb":[[2,3.6,3.09]],"ltp":5.0,"tv":2576.74,"id":9625551}]}]}
{"op":"mcm","clk":"4234694660","pt":1631548898932,"mc":[{"id":"1.187562121","rc":[{"trd":[[1.22,482.9]],"batl":[[0,1.23,29.94],[1,1.24,24.2],[2,1.25,12.1]],"ltp":1.22,"tv":14252.28,"id":20955040}],"tv":16829.02}]}
{"op":"mcm","clk":"4234694864","pt":1631548900735,"mc":[{"id":"1.187562121","rc":[{"trd":[[1.23,163.23]],"batl":[[0,1.24,24.2],[1,1.25,12.1],[2,1.26,20.04]],"ltp":1.23,"tv":14282.22,"id":20955040},{"trd":[[5.3,53.84]],"batl":[[0,5.3,25.25],[1,5.6,2.01],[2,5.7,5.86]],"ltp":5.3,"tv":2583.69,"id":9625551}],"tv":16865.91}]}
{"op":"mcm","clk":"4234694887","pt":1631548900949,"mc":[{"id":"1.187562121","rc":[{"batl":[[0,5.6,2.01],[1,5.7,5.86],[2,5.8,2.02]],"ltp":5.3,"tv":2583.69,"id":9625551}]}]}
{"op":"mcm","clk":"4234695655","pt":1631548907551,"mc":[{"id":"1.187562121","rc":[{"trd":[[1.24,65.88]],"batl":[[0,1.24,14.15]],"ltp":1.24,"tv":14302.31,"id":20955040}],"tv":16886.01}]}
{"op":"mcm","clk":"4234695993","pt":1631548910967,"mc":[{"id":"1.187562121","rc":[{"batl":[[1,5.8,2.02],[2,5.9,5.08]],"ltp":5.3,"tv":2583.69,"id":9625551}]}]}
{"op":"mcm","clk":"4234696280","pt":1631548913906,"mc":[{"id":"1.187562121","rc":[{"batl":[[0,1.24,43.98]],"ltp":1.24,"tv":14302.31,"id":20955040},{"batl":[[0,5.5,5.57],[1,5.6,2.01],[2,5.8,2.02]],"ltp":5.3,"tv":2583.69,"id":9625551}]}]}
{"op":"mcm","clk":"4234698599","pt":1631548937779,"mc":[{"id":"1.187562121","rc":[{"trd":[[1.22,508]],"batl":[[0,1.22,909.13],[1,1.24,43.98],[2,1.25,12.1]],"ltp":1.22,"tv":14327.41,"id":20955040},{"trd":[[5.5,71.25]],"batl":[[0,5.6,2.01],[1,5.8,2.02],[2,5.9,5.08]],"ltp":5.5,"tv":2589.26,"id":9625551}],"tv":16916.67}]}
{"op":"mcm","clk":"4234699456","pt":1631548948053,"mc":[{"id":"1.187562121","rc":[{"batl":[[1,1.24,14.15]],"ltp":1.22,"tv":14327.41,"id":20955040}]}]}
{"op":"mcm","clk":"4234699589","pt":1631548949947,"mc":[{"id":"1.187562121","rc":[{"trd":[[1.21,97.11]],"batb":[[0,1.21,114.34]],"ltp":1.21,"tv":14330.11,"id":20955040}],"tv":16919.37}]}
{"op":"mcm","clk":"4234699680","pt":1631548950946,"mc":[{"id":"1.187562121","rc":[{"batl":[[1,1.23,24.89],[2,1.24,14.15]],"ltp":1.21,"tv":14330.11,"id":20955040},{"batl":[[1,5.7,6.95],[2,5.8,2.02]],"ltp":5.5,"tv":2589.26,"id":9625551}]}]}
{"op":"mcm","clk":"4234701564","pt":1631548970186,"mc":[{"id":"1.187562121","rc":[{"batb":[[0,1.21,113.69],[2,1.19,237.3]],"ltp":1.21,"tv":14330.11,"id":20955040}]}]}
{"op":"mcm","clk":"4234701829","pt":1631548973039,"mc":[{"id":"1.187562121","rc":[{"trd":[[1.22,515.19]],"batl":[[0,1.22,905.54]],"ltp":1.22,"tv":14337.3,"id":20955040}],"tv":16926.57}]}
{"op":"mcm","clk":"4234702821","pt":1631548983061,"mc":[{"id":"1.187562121","rc":[{"batb":[[2,1.19,187.64]],"ltp":1.22,"tv":14337.3,"id":20955040}]}]}
{"op":"mcm","clk":"4234703138","pt":1631548986451,"mc":[{"id":"1.187562121","rc":[{"batb":[[2,1.19,327.35]],"ltp":1.22,"tv":14337.3,"id":20955040},{"batb":[[1,4,41.72],[2,3.7,10.84]],"ltp":5.5,"tv":2589.26,"id":9625551}]}]}
{"op":"mcm","clk":"4234704086","pt":1631548996879,"mc":[{"id":"1.187562121","rc":[{"batb":[[0,1.18,143.86],[1,1.17,216.24],[2,1.01,107.79]],"batl":[[1,1.33,84],[2,1.37,71]],"ltp":1.22,"tv":14337.3,"id":20955040},{"batb":[[0,4,41.72],[1,3.7,10.84],[2,1.46,3.41]],"batl":[[0,6.6,2],[1,990,0.01],[2,5.8,0]],"ltp":5.5,"tv":2589.26,"id":9625551}]}]}
{"op":"mcm","clk":"4234704355","pt":1631548999888,"mc":[{"id":"1.187562121","rc":[{"trd":[[1.22,517]],"batl":[[0,1.22,904.64]],"ltp":1.22,"tv":14339.1,"id":20955040}],"tv":16928.37}]}
{"op":"mcm","clk":"4234705366","pt":1631549010517,"mc":[{"id":"1.187562121","rc":[{"trd":[[1.22,1421.63]],"batb":[[0,1.26,19.14],[1,1.24,8.06],[2,1.23,48.04]],"batl":[[0,1.28,32.63],[2,1.34,44.1]],"ltp":1.22,"tv":15243.74,"id":20955040},{"trd":[[5.5,272.03]],"batb":[[0,4.4,218.82],[1,4,41.72],[2,3.7,10.84]],"batl":[[0,5,40],[1,5.1,245.97],[2,5.2,2.94]],"ltp":5.5,"tv":2790.04,"id":9625551}],"tv":18033.79}]}
{"op":"mcm","clk":"4234705464","pt":1631549011408,"mc":[{"id":"1.187562121","rc":[{"batb":[[1,1.24,158.21]],"batl":[[1,1.31,7.63],[2,1.33,84]],"ltp":1.22,"tv":15243.74,"id":20955040},{"batb":[[0,4.5,6.66],[1,4.4,222.16],[2,4.3,3.34]],"ltp":5.5,"tv":2790.04,"id":9625551}]}]}
{"op":"mcm","clk":"4234705921","pt":1631549016829,"mc":[{"id":"1.187562121","rc":[{"batb":[[1,1.24,247.98],[2,1.23,165.67]],"ltp":1.22,"tv":15243.74,"id":20955040},{"batl":[[2,5.2,4.97]],"ltp":5.5,"tv":2790.04,"id":9625551}]}]}
{"op":"mcm","clk":"4234706209","pt":1631549019905,"mc":[{"id":"1.187562121","rc":[{"batb":[[0,1.23,117.63],[1,1.22,113.34],[2,1.2,178.16]],"batl":[[0,1.36,69.32],[1,1.37,71],[2,1.39,58.5]],"ltp":1.22,"tv":15243.74,"id":20955040},{"batb":[[0,3.75,2.75],[1,3.7,10.84],[2,3.55,3.19]],"batl":[[0,5.4,2.09],[1,5.6,2.01],[2,6.6,2]],"ltp":5.5,"tv":2790.04,"id":9625551}]}]}
{"op":"mcm","clk":"4234706244","pt":1631549020219,"mc":[{"id":"1.187562121","rc":[{"batb":[[1,1.2,178.16],[2,1.18,143.86]],"batl":[[0,1.39,58.5],[1,3.8,27.43],[2,8.8,7.22]],"ltp":1.22,"tv":15243.74,"id":20955040},{"batb":[[0,3.55,3.19],[1,3.5,23.65],[2,1.46,3.41]],"batl":[[1,6.6,2],[2,990,0.01]],"ltp":5.5,"tv":2790.04,"id":9625551}]}]}
{"op":"mcm","clk":"4234706559","pt":1631549023710,"mc":[{"id":"1.187562121","rc":[{"batl":[[0,1.36,60.07],[1,1.39,58.5],[2,3.8,27.43]],"ltp":1.22,"tv":15243.74,"id":20955040},{"batb":[[0,3.75,3.19],[1,3.55,3.19],[2,3.5,23.65]],"ltp":5.5,"tv":2790.04,"id":9625551}]}]}
{"op":"mcm","clk":"4234706647","pt":1631549024608,"mc":[{"id":"1.187562121","rc":[{"batl":[[0,1.39,59.4],[1,3.8,27.43],[2,8.8,7.22]],"ltp":1.22,"tv":15243.74,"id":20955040},{"batb":[[0,3.55,3.19],[1,3.5,23.65],[2,1.46,3.41]],"ltp":5.5,"tv":2790.04,"id":9625551}]}]}
{"op":"mcm","clk":"4234706995","pt":1631549028859,"mc":[{"id":"1.187562121","rc":[{"trd":[[1.26,26.67]],"batl":[[0,1.34,12.23],[1,1.37,756.1],[2,1.39,58.5]],"ltp":1.26,"tv":15244.64,"id":20955040},{"trd":[[4.8,24.01]],"batl":[[0,4.1,56.21],[1,4.2,314.52],[2,4.3,318.67]],"ltp":4.8,"tv":2790.28,"id":9625551}],"tv":18034.93}]}
{"op":"mcm","clk":"4234707060","pt":1631549029749,"mc":[{"id":"1.187562121","rc":[{"batb":[[0,1.3,115.17],[1,1.29,45.81],[2,1.27,23.26]],"batl":[[2,1.38,7.25]],"ltp":1.26,"tv":15244.64,"id":20955040},{"batb":[[0,3.8,39.48],[1,3.75,19.74],[2,3.7,19.74]],"batl":[[0,4.1,17.19],[1,4.2,35.72]],"ltp":4.8,"tv":2790.28,"id":9625551}]}]}
{"op":"mcm","clk":"4234707085","pt":1631549029956,"mc":[{"id":"1.187562121","rc":[{"batb":[[0,3.8,7.9],[1,3.75,3.94],[2,3.7,3.94]],"batl":[[1,4.2,7.14],[2,4.3,304.39]],"ltp":4.8,"tv":2790.28,"id":9625551}]}]}
{"op":"mcm","clk":"4234707670","pt":1631549036614,"mc":[{"id":"1.187562121","rc":[{"batb":[[2,1.28,89.66]],"ltp":1.26,"tv":15244.64,"id":20955040}]}]}
{"op":"mcm","clk":"4234708028","pt":1631549040732,"mc":[{"id":"1.187562121","rc":[{"batb":[[0,1.26,242.29],[1,1.23,117.63],[2,1.18,143.86]],"batl":[[0,1.44,60.33],[1,3.8,27.43],[2,8.8,7.22]],"ltp":1.26,"tv":15244.64,"id":20955040},{"batb":[[0,3.25,3.85],[1,3.05,33.72],[2,1.46,3.41]],"batl":[[0,4.9,2.05],[1,5.4,2.09],[2,6.6,2]],"ltp":4.8,"tv":2790.28,"id":9625551}]}]}
{"op":"mcm","clk":"4234708885","pt":1631549050887,"mc":[{"id":"1.187562121","rc":[{"batb":[[0,1.28,21.49],[1,1.26,242.29],[2,1.23,117.63]],"batl":[[0,1.3,64.73],[1,1.31,114.5],[2,1.32,907.76]],"ltp":1.26,"tv":15244.64,"id":20955040},{"batb":[[0,4.3,50.4],[1,3.25,3.85],[2,3.05,33.72]],"batl":[[0,4.7,173.73],[1,4.9,2.05],[2,5.4,2.09]],"ltp":4.8,"tv":2790.28,"id":9625551}]}]}
{"op":"mcm","clk":"4234708996","pt":1631549051879,"mc":[{"id":"1.187562121","rc":[{"batb":[[2,1.25,47.27]],"batl":[[1,1.31,22.9],[2,1.32,861.96]],"ltp":1.26,"tv":15244.64,"id":20955040},{"batb":[[1,3.85,37.49],[2,3.25,32.37]],"batl":[[1,4.8,8.32],[2,4.9,5.17]],"ltp":4.8,"tv":2790.28,"id":9625551}]}]}
{"op":"mcm","clk":"4234709677","pt":1631549059274,"mc":[{"id":"1.187562121","rc":[{"batb":[[2,3.6,3.14]],"ltp":4.8,"tv":2790.28,"id":9625551}]}]}
{"op":"mcm","clk":"4234709986","pt":1631549062663,"mc":[{"id":"1.187562121","rc":[{"batb":[[0,1.22,126.84],[1,1.21,169.86],[2,1.18,143.86]],"batl":[[0,1.41,57.5],[1,3.8,27.43],[2,8.8,7.22]],"ltp":1.26,"tv":15244.64,"id":20955040},{"batb":[[0,3.4,3.56],[1,3.25,28.52],[2,1.46,3.41]],"batl":[[0,5.6,2.01],[1,6.6,2],[2,990,0.01]],"ltp":4.8,"tv":2790.28,"id":9625551}]}]}
{"op":"mcm","clk":"4234710246","pt":1631549065886,"mc":[{"id":"1.187562121","rc":[{"batb":[[0,1.24,88.52],[1,1.22,126.84],[2,1.21,169.86]],"batl":[[0,1.38,68.75],[1,1.41,57.5],[2,3.8,27.43]],"ltp":1.26,"tv":15244.64,"id":20955040},{"batb":[[0,3.6,2.89],[1,3.4,3.56],[2,3.25,28.52]],"batl":[[0,5.2,2.13],[1,5.6,2.01],[2,6.6,2]],"ltp":4.8,"tv":2790.28,"id":9625551}]}]}
{"op":"mcm","clk":"4234710298","pt":1631549066356,"mc":[{"id":"1.187562121","rc":[{"batb":[[0,1.22,126.84],[1,1.21,169.86],[2,1.18,143.86]],"batl":[[0,1.41,57.5],[1,3.8,27.43],[2,8.8,7.22]],"ltp":1.26,"tv":15244.64,"id":20955040},{"batb":[[0,3.4,3.56],[1,3.25,28.52],[2,1.46,3.41]],"batl":[[0,5.6,2.01],[1,6.6,2],[2,990,0.01]],"ltp":4.8,"tv":2790.28,"id":9625551}]}]}
{"op":"mcm","clk":"4234711222","pt":1631549076699,"mc":[{"id":"1.187562121","rc":[{"batb":[[0,1.24,115.02],[1,1.22,126.84],[2,1.21,169.86]],"batl":[[0,1.38,65.75],[1,1.41,57.5],[2,3.8,27.43]],"ltp":1.26,"tv":15244.64,"id":20955040},{"batb":[[0,3.6,3.59],[1,3.4,3.56],[2,3.25,28.52]],"batl":[[0,5.2,2.03],[1,5.6,2.01],[2,6.6,2]],"ltp":4.8,"tv":2790.28,"id":9625551}]}]}
{"op":"mcm","clk":"4234711241","pt":1631549076961,"mc":[{"id":"1.187562121","rc":[{"batb":[[0,1.22,126.84],[1,1.21,169.86],[2,1.18,143.86]],"batl":[[0,1.41,57.5],[1,3.8,27.43],[2,8.8,7.22]],"ltp":1.26,"tv":15244.64,"id":20955040},{"batb":[[0,3.4,3.56],[1,3.25,28.52],[2,1.46,3.41]],"batl":[[0,5.6,2.01],[1,6.6,2],[2,990,0.01]],"ltp":4.8,"tv":2790.28,"id":9625551}]}]}
{"op":"mcm","clk":"4234711569","pt":1631549080768,"mc":[{"id":"1.187562121","rc":[{"batb":[[0,1.24,101.52],[1,1.22,126.84],[2,1.21,169.86]],"batl":[[0,1.38,58.75],[1,1.41,57.5],[2,3.8,27.43]],"ltp":1.26,"tv":15244.64,"id":20955040},{"batb":[[0,3.6,3.49],[1,3.4,3.56],[2,3.25,28.52]],"batl":[[0,5.2,2.03],[1,5.6,2.01],[2,6.6,2]],"ltp":4.8,"tv":2790.28,"id":9625551}]}]}
{"op":"mcm","clk":"4234711593","pt":1631549080989,"mc":[{"id":"1.187562121","rc":[{"batb":[[0,1.22,126.84],[1,1.21,169.86],[2,1.18,143.86]],"batl":[[0,1.41,57.5],[1,3.8,27.43],[2,8.8,7.22]],"ltp":1.26,"tv":15244.64,"id":20955040},{"batb":[[0,3.4,3.56],[1,3.25,28.52],[2,1.46,3.41]],"batl":[[0,5.6,2.01],[1,6.6,2],[2,990,0.01]],"ltp":4.8,"tv":2790.28,"id":9625551}]}]}
{"op":"mcm","clk":"4234712183","pt":1631549087701,"mc":[{"id":"1.187562121","rc":[{"batb":[[0,1.24,110.02],[1,1.22,126.84],[2,1.21,169.86]],"batl":[[0,1.38,70.25],[1,1.41,57.5],[2,3.8,27.43]],"ltp":1.26,"tv":15244.64,"id":20955040},{"batb":[[0,3.6,3.24],[1,3.4,3.56],[2,3.25,28.52]],"batl":[[0,5.2,2.03],[1,5.6,2.01],[2,6.6,2]],"ltp":4.8,"tv":2790.28,"id":9625551}]}]}
{"op":"mcm","clk":"4234712350","pt":1631549089536,"mc":[{"id":"1.187562121","rc":[{"batb":[[0,1.22,126.84],[1,1.21,169.86],[2,1.18,143.86]],"batl":[[0,1.41,57.5],[1,3.8,27.43],[2,8.8,7.22]],"ltp":1.26,"tv":15244.64,"id":20955040},{"batb":[[0,3.4,3.56],[1,3.25,28.52],[2,1.46,3.41]],"batl":[[0,5.6,2.01],[1,6.6,2],[2,990,0.01]],"ltp":4.8,"tv":2790.28,"id":9625551}]}]}
{"op":"mcm","clk":"4234712647","pt":1631549092809,"mc":[{"id":"1.187562121","rc":[{"batb":[[0,1.24,112.52],[1,1.22,126.84],[2,1.21,169.86]],"batl":[[0,1.38,61.75],[1,1.41,57.5],[2,3.8,27.43]],"ltp":1.26,"tv":15244.64,"id":20955040},{"batb":[[0,3.6,3.69],[1,3.4,3.56],[2,3.25,28.52]],"batl":[[0,5.2,2.03],[1,5.6,2.01],[2,6.6,2]],"ltp":4.8,"tv":2790.28,"id":9625551}]}]}
{"op":"mcm","clk":"4234712705","pt":1631549093387,"mc":[{"id":"1.187562121","rc":[{"batb":[[0,1.34,29.86],[1,1.32,44.76],[2,1.3,22.73]],"batl":[[0,1.39,19.2],[2,1.42,705.55]],"ltp":1.26,"tv":15244.64,"id":20955040},{"batb":[[0,3.4,3.56],[1,3.25,28.52],[2,1.46,3.41]],"batl":[[0,3.7,5.09],[1,3.85,38.96],[2,3.9,313.27]],"ltp":4.8,"tv":2790.28,"id":9625551}]}]}
{"op":"mcm","clk":"4234712796","pt":1631549094385,"mc":[{"id":"1.187562121","rc":[{"batb":[[1,1.33,100.32],[2,1.32,44.76]],"batl":[[2,1.42,712.59]],"ltp":1.26,"tv":15244.64,"id":20955040},{"batb":[[0,3.5,8.58],[1,3.45,4.28],[2,3.4,7.84]],"batl":[[1,3.85,7.8],[2,3.9,297.69]],"ltp":4.8,"tv":2790.28,"id":9625551}]}]}
{"op":"mcm","clk":"4234715415","pt":1631549115856,"mc":[{"id":"1.187562121","rc":[{"batb":[[0,1.28,123.3],[1,1.27,86.87],[2,1.22,126.84]],"batl":[[0,1.51,51.5],[1,3.8,27.43],[2,8.8,7.22]],"ltp":1.26,"tv":15244.64,"id":20955040},{"batb":[[0,2.96,3.88],[1,2.82,42.02],[2,1.46,3.41]],"batl":[[0,4.8,2.37],[1,5.6,2.01],[2,6.6,2]],"ltp":4.8,"tv":2790.28,"id":9625551}]}]}
{"op":"mcm","clk":"4234716191","pt":1631549122727,"mc":[{"id":"1.187562121","rc":[{"batb":[[0,1.3,88.68],[1,1.28,123.3],[2,1.27,86.87]],"ltp":1.26,"tv":15244.64,"id":20955040},{"batl":[[0,4.4,2.24],[1,4.8,2.37],[2,5.6,2.01]],"ltp":4.8,"tv":2790.28,"id":9625551}]}]}
{"op":"mcm","clk":"4234716216","pt":1631549122934,"mc":[{"id":"1.187562121","rc":[{"batb":[[0,1.28,123.3],[1,1.27,86.87],[2,1.22,126.84]],"ltp":1.26,"tv":15244.64,"id":20955040},{"batl":[[0,4.8,2.37],[1,5.6,2.01],[2,6.6,2]],"ltp":4.8,"tv":2790.28,"id":9625551}]}]}
{"op":"mcm","clk":"4234717030","pt":1631549129488,"mc":[{"id":"1.187562121","rc":[{"batb":[[0,1.48,11.28],[1,1.45,686.77],[2,1.4,42.21]],"batl":[[0,1.5,6.33],[1,1.51,51.5],[2,1.54,598.44]],"ltp":1.26,"tv":15244.64,"id":20955040},{"batl":[[0,3.2,9.38],[1,3.25,4.68],[2,3.3,7.71]],"ltp":4.8,"tv":2790.28,"id":9625551}]}]}
{"op":"mcm","clk":"4234717350","pt":1631549130686,"mc":[{"id":"1.187562121","rc":[{"batb":[[2,1.43,74.57]],"batl":[[2,1.53,6.54]],"ltp":1.26,"tv":15244.64,"id":20955040},{"batb":[[1,2.94,10.2],[2,2.92,5.1]],"ltp":4.8,"tv":2790.28,"id":9625551}]}]}
{"op":"mcm","clk":"4234718505","pt":1631549142661,"mc":[{"id":"1.187562121","rc":[{"trd":[[1.48,910.85]],"batb":[[0,1.48,1.83]],"ltp":1.48,"tv":15254.09,"id":20955040},{"trd":[[3.1,28.65]],"ltp":3.1,"tv":2794.79,"id":9625551}],"tv":18048.89}]}
{"op":"mcm","clk":"4234719304","pt":1631549152770,"mc":[{"id":"1.187562121","rc":[{"batb":[[0,1.45,686.77],[1,1.43,74.57],[2,1.4,42.21]],"batl":[[0,1.51,51.5],[1,1.53,6.54],[2,1.54,645.19]],"ltp":1.48,"tv":15254.09,"id":20955040}]}]}
{"op":"mcm","clk":"4234719437","pt":1631549154586,"mc":[{"id":"1.187562121","rc":[{"batb":[[0,1.36,91.51],[1,1.33,88.53],[2,1.27,86.87]],"batl":[[0,1.56,46.92],[1,3.8,27.43],[2,8.8,7.22]],"ltp":1.48,"tv":15254.09,"id":20955040},{"batb":[[0,2.78,5.16],[1,2.68,19.63],[2,1.46,3.41]],"batl":[[0,4.1,2.85],[1,4.8,2.37],[2,5.6,2.01]],"ltp":3.1,"tv":2794.79,"id":9625551}]}]}
{"op":"mcm","clk":"4234719737","pt":1631549157782,"mc":[{"id":"1.187562121","rc":[{"batb":[[0,1.37,160.69]],"batl":[[0,1.54,44.75],[1,1.56,46.92],[2,3.8,27.43]],"ltp":1.48,"tv":15254.09,"id":20955040},{"batb":[[0,2.84,4.97],[1,2.78,5.16],[2,2.66,19.88]],"batl":[[0,3.75,3.06],[1,4.1,2.85],[2,4.8,2.37]],"ltp":3.1,"tv":2794.79,"id":9625551}]}]}
{"op":"mcm","clk":"4234719753","pt":1631549157990,"mc":[{"id":"1.187562121","rc":[{"batb":[[0,1.37,89.92]],"batl":[[0,1.56,46.92],[1,3.8,27.43],[2,8.8,7.22]],"ltp":1.48,"tv":15254.09,"id":20955040},{"batb":[[0,2.78,5.16],[1,2.66,19.88],[2,1.46,3.41]],"batl":[[0,4.1,2.85],[1,4.8,2.37],[2,5.6,2.01]],"ltp":3.1,"tv":2794.79,"id":9625551}]}]}
{"op":"mcm","clk":"4234720069","pt":1631549161817,"mc":[{"id":"1.187562121","rc":[{"batb":[[0,1.53,130.72],[1,1.45,40.75],[2,1.43,20.66]],"batl":[[0,1.56,71.83],[1,1.6,728.68],[2,1.62,18.24]],"ltp":1.48,"tv":15254.09,"id":20955040},{"batl":[[0,2.92,8.36],[1,2.98,50.34],[2,3,25.18]],"ltp":3.1,"tv":2794.79,"id":9625551}]}]}
{"op":"mcm","clk":"4234720172","pt":1631549162872,"mc":[{"id":"1.187562121","rc":[{"batb":[[0,1.53,78.43],[1,1.48,64.5],[2,1.45,40.75]],"batl":[[1,1.58,6.33],[2,1.6,728.68]],"ltp":1.48,"tv":15254.09,"id":20955040},{"batb":[[1,2.76,10.88],[2,2.74,5.44]],"batl":[[1,2.98,10.06],[2,3,5.04]],"ltp":3.1,"tv":2794.79,"id":9625551}]}]}
{"op":"mcm","clk":"4234720712","pt":1631549169813,"mc":[{"id":"1.187562121","rc":[{"batl":[[2,1.59,41.5]],"ltp":1.48,"tv":15254.09,"id":20955040}]}]}
{"op":"mcm","clk":"4234721112","pt":1631549174608,"mc":[{"id":"1.187562121","rc":[{"batb":[[0,1.48,64.5],[1,1.45,40.75],[2,1.44,57.42]],"batl":[[0,1.6,36.93],[1,1.61,38.5],[2,1.62,18.24]],"ltp":1.48,"tv":15254.09,"id":20955040},{"batb":[[0,2.66,19.88],[1,2.62,6.04],[2,2.5,23.49]],"batl":[[0,3.3,3.55],[1,3.5,3.13],[2,4.1,2.85]],"ltp":3.1,"tv":2794.79,"id":9625551}]}]}
{"op":"mcm","clk":"4234721185","pt":1631549175328,"mc":[{"id":"1.187562121","rc":[{"batb":[[0,1.42,76.58],[1,1.4,65.41],[2,1.33,88.53]],"batl":[[0,1.61,38.5],[1,3.8,27.43],[2,8.8,7.22]],"ltp":1.48,"tv":15254.09,"id":20955040},{"batb":[[0,2.62,6.04],[1,2.5,23.49],[2,1.46,3.41]],"batl":[[0,3.5,3.13],[1,4.1,2.85],[2,4.8,2.37]],"ltp":3.1,"tv":2794.79,"id":9625551}]}]}
{"op":"mcm","clk":"4234721443","pt":1631549177841,"mc":[{"id":"1.187562121","rc":[{"batl":[[0,1.59,40.5],[1,1.61,38.5],[2,3.8,27.43]],"ltp":1.48,"tv":15254.09,"id":20955040},{"batb":[[0,2.68,5.11],[1,2.62,6.04],[2,2.5,23.49]],"ltp":3.1,"tv":2794.79,"id":9625551}]}]}
{"op":"mcm","clk":"4234721539","pt":1631549178727,"mc":[{"id":"1.187562121","rc":[{"batb":[[0,1.41,77.84]],"batl":[[0,1.61,38.5],[1,3.8,27.43],[2,8.8,7.22]],"ltp":1.48,"tv":15254.09,"id":20955040},{"batb":[[0,2.62,6.04],[1,2.52,22.98],[2,1.46,3.41]],"ltp":3.1,"tv":2794.79,"id":9625551}]}]}
{"op":"mcm","clk":"4234721804","pt":1631549181399,"mc":[{"id":"1.187562121","rc":[{"batl":[[0,1.59,44.5],[1,1.61,38.5],[2,3.8,27.43]],"ltp":1.48,"tv":15254.09,"id":20955040},{"batb":[[0,2.68,5.86],[1,2.62,6.04],[2,2.52,22.98]],"ltp":3.1,"tv":2794.79,"id":9625551}]}]}
{"op":"mcm","clk":"4234721898","pt":1631549182197,"mc":[{"id":"1.187562121","rc":[{"batl":[[0,1.61,38.5],[1,3.8,27.43],[2,8.8,7.22]],"ltp":1.48,"tv":15254.09,"id":20955040},{"batb":[[0,2.62,6.04],[1,2.52,22.98],[2,1.46,3.41]],"ltp":3.1,"tv":2794.79,"id":9625551}]}]}
{"op":"mcm","clk":"4234722170","pt":1631549184401,"mc":[{"id":"1.187562121","rc":[{"batb":[[0,1.56,76.92],[1,1.49,39.66],[2,1.47,20.1]],"batl":[[0,1.6,13],[1,1.61,38.5],[2,1.64,423.3]],"ltp":1.48,"tv":15254.09,"id":20955040},{"batl":[[0,2.78,321.12],[1,2.8,16.19],[2,2.82,16.19]],"ltp":3.1,"tv":2794.79,"id":9625551}]}]}
{"op":"mcm","clk":"4234722323","pt":1631549185547,"mc":[{"id":"1.187562121","rc":[{"batb":[[1,1.52,57.29],[2,1.49,39.66]],"batl":[[2,1.62,6.17]],"ltp":1.48,"tv":15254.09,"id":20955040},{"batb":[[2,2.42,25.84]],"batl":[[0,2.78,299.54],[1,2.8,5.4],[2,2.82,5.4]],"ltp":3.1,"tv":2794.79,"id":9625551}]}]}
{"op":"mcm","clk":"4234722995","pt":1631549190844,"mc":[{"id":"1.187562121","rc":[{"batb":[[2,1.51,49.99]],"batl":[[2,1.62,45.92]],"ltp":1.48,"tv":15254.09,"id":20955040},{"batb":[[1,2.6,4.59],[2,2.52,22.98]],"ltp":3.1,"tv":2794.79,"id":9625551}]}]}
{"op":"mcm","clk":"4234723161","pt":1631549192719,"mc":[{"id":"1.187562121","rc":[{"batl":[[0,1.6,52.81]],"ltp":1.48,"tv":15254.09,"id":20955040},{"batb":[[0,2.66,5.78],[1,2.62,6.04],[2,2.6,4.59]],"ltp":3.1,"tv":2794.79,"id":9625551}]}]}
{"op":"mcm","clk":"4234723493","pt":1631549196736,"mc":[{"id":"1.187562121","rc":[{"batb":[[0,1.52,57.29],[1,1.49,39.66],[2,1.47,86.7]],"batl":[[0,1.65,35.81],[1,1.67,17.69],[2,3.8,27.43]],"ltp":1.48,"tv":15254.09,"id":20955040},{"batb":[[0,2.6,4.59],[1,2.52,22.98],[2,2.42,25.84]],"batl":[[0,3.1,3.85],[1,4.1,2.85],[2,4.8,2.37]],"ltp":3.1,"tv":2794.79,"id":9625551}]}]}
{"op":"mcm","clk":"4234723523","pt":1631549197048,"mc":[{"id":"1.187562121","rc":[{"batb":[[0,1.47,66.6],[1,1.33,88.53],[2,1.27,86.87]],"batl":[[0,3.8,27.43],[1,8.8,7.22],[2,44,7.22]],"ltp":1.48,"tv":15254.09,"id":20955040},{"batb":[[1,2.42,25.84],[2,1.46,3.41]],"ltp":3.1,"tv":2794.79,"id":9625551}]}]}
{"op":"mcm","clk":"4234723816","pt":1631549200327,"mc":[{"id":"1.187562121","rc":[{"batb":[[0,1.48,52.26],[1,1.47,66.6],[2,1.33,88.53]],"batl":[[0,1.62,38.25],[1,3.8,27.43],[2,8.8,7.22]],"ltp":1.48,"tv":15254.09,"id":20955040}]}]}
{"op":"mcm","clk":"4234724209","pt":1631549204764,"mc":[{"id":"1.187562121","rc":[{"batb":[[0,1.51,47.99],[1,1.48,52.26],[2,1.47,66.6]],"batl":[[0,1.61,44.5],[1,1.62,38.25],[2,3.8,27.43]],"ltp":1.48,"tv":15254.09,"id":20955040},{"batb":[[0,2.62,5.54],[1,2.6,4.59],[2,2.42,25.84]],"batl":[[0,2.98,5.25],[1,3.1,3.85],[2,4.1,2.85]],"ltp":3.1,"tv":2794.79,"id":9625551}]}]}
{"op":"mcm","clk":"4234724234","pt":1631549205025,"mc":[{"id":"1.187562121","rc":[{"batb":[[0,1.48,52.26],[1,1.47,66.6],[2,1.33,88.53]],"batl":[[0,1.62,38.25],[1,3.8,27.43],[2,8.8,7.22]],"ltp":1.48,"tv":15254.09,"id":20955040},{"batb":[[0,2.6,4.59],[1,2.42,25.84],[2,1.46,3.41]],"batl":[[0,3.1,3.85],[1,4.1,2.85],[2,4.8,2.37]],"ltp":3.1,"tv":2794.79,"id":9625551}]}]}
{"op":"mcm","clk":"4234724705","pt":1631549210876,"mc":[{"id":"1.187562121","rc":[{"batb":[[0,1.59,94.34],[1,1.58,47.18],[2,1.57,47.18]],"batl":[[1,1.64,12.64],[2,1.68,393.18]],"ltp":1.48,"tv":15254.09,"id":20955040},{"batl":[[0,2.66,278.19],[1,2.72,73.52],[2,2.82,3.55]],"ltp":3.1,"tv":2794.79,"id":9625551}]}]}
{"op":"mcm","clk":"4234724789","pt":1631549211866,"mc":[{"id":"1.187562121","rc":[{"batb":[[2,1.57,98.93]],"batl":[[2,1.66,6.02]],"ltp":1.48,"tv":15254.09,"id":20955040},{"batb":[[1,2.52,59.52],[2,2.5,29.76]],"batl":[[1,2.72,14.7]],"ltp":3.1,"tv":2794.79,"id":9625551}]}]}
{"op":"mcm","clk":"4234724814","pt":1631549212071,"mc":[{"id":"1.187562121","rc":[{"batb":[[0,1.59,56.6],[1,1.58,28.31],[2,1.57,80.06]],"ltp":1.48,"tv":15254.09,"id":20955040},{"batb":[[1,2.52,11.9],[2,2.5,5.96]],"ltp":3.1,"tv":2794.79,"id":9625551}]}]}
{"op":"mcm","clk":"4234725035","pt":1631549214346,"mc":[{"id":"1.187562121","rc":[{"trd":[[1.62,55.93]],"batl":[[0,1.64,12.64],[1,1.66,6.02],[2,1.68,393.18]],"ltp":1.62,"tv":15292.34,"id":20955040},{"trd":[[2.6,41.54]],"batb":[[0,2.52,11.9],[1,2.5,5.96],[2,2.48,5.96]],"batl":[[0,2.6,21.58],[1,2.66,278.19],[2,2.72,14.7]],"ltp":2.6,"tv":2827.8,"id":9625551}],"tv":18120.15}]}
{"op":"mcm","clk":"4234725321","pt":1631549217577,"mc":[{"id":"1.187562121","rc":[{"batl":[[0,1.63,47.5],[1,1.64,50.32],[2,1.66,6.02]],"ltp":1.62,"tv":15292.34,"id":20955040},{"batb":[[0,2.58,5.56],[1,2.56,5.33],[2,2.52,11.9]],"ltp":2.6,"tv":2827.8,"id":9625551}]}]}
{"op":"mcm","clk":"4234725423","pt":1631549218882,"mc":[{"id":"1.187562121","rc":[{"batl":[[2,1.65,39.5]],"ltp":1.62,"tv":15292.34,"id":20955040},{"batb":[[2,2.52,17.39]],"ltp":2.6,"tv":2827.8,"id":9625551}]}]}
{"op":"mcm","clk":"4234726077","pt":1631549226491,"mc":[{"id":"1.187562121","rc":[{"batb":[[0,1.55,42.19],[1,1.52,57.88],[2,1.48,52.26]],"batl":[[0,3.8,27.43],[1,8.8,7.22],[2,44,7.22]],"ltp":1.62,"tv":15292.34,"id":20955040},{"batb":[[0,2.52,5.49],[1,2.36,28.1],[2,1.46,3.41]],"batl":[[1,2.82,4.75],[2,3.1,3.85]],"ltp":2.6,"tv":2827.8,"id":9625551}]}]}
{"op":"mcm","clk":"4234726188","pt":1631549227545,"mc":[{"id":"1.187562121","rc":[{"batb":[[0,1.55,42.73]],"ltp":1.62,"tv":15292.34,"id":20955040}]}]}
{"op":"mcm","clk":"4234726398","pt":1631549229694,"mc":[{"id":"1.187562121","rc":[{"trd":[[1.64,33.88]],"batb":[[0,1.55,42.19]],"batl":[[0,1.64,37.14],[1,1.65,34.5],[2,3.8,27.43]],"ltp":1.64,"tv":15293.42,"id":20955040},{"batb":[[0,2.56,5.33],[1,2.52,5.49],[2,2.36,28.1]],"ltp":2.6,"tv":2827.8,"id":9625551}],"tv":18121.23}]}
{"op":"mcm","clk":"4234726445","pt":1631549230017,"mc":[{"id":"1.187562121","rc":[{"batb":[[2,1.01,107.79]],"batl":[[0,1.65,34.5],[1,3.8,27.43],[2,8.8,7.22]],"ltp":1.64,"tv":15293.42,"id":20955040},{"batb":[[0,2.52,5.49],[1,2.36,28.1],[2,1.46,3.41]],"batl":[[2,990,0.01]],"ltp":2.6,"tv":2827.8,"id":9625551}]}]}
{"op":"mcm","clk":"4234726664","pt":1631549231888,"mc":[{"id":"1.187562121","rc":[{"batb":[[0,1.55,80.31],[1,1.53,19.31],[2,1.52,57.88]],"batl":[[1,1.66,8.78],[2,1.7,319.88]],"ltp":1.64,"tv":15293.42,"id":20955040},{"batl":[[0,2.6,385.42],[1,2.62,105.18],[2,2.64,28.84]],"ltp":2.6,"tv":2827.8,"id":9625551}]}]}
{"op":"mcm","clk":"4234726775","pt":1631549232879,"mc":[{"id":"1.187562121","rc":[{"batb":[[0,1.6,48.23],[1,1.56,52.42],[2,1.55,80.31]],"batl":[[2,1.68,5.95]],"ltp":1.64,"tv":15293.42,"id":20955040},{"batb":[[2,2.24,32.46]],"batl":[[0,2.6,339.28],[1,2.62,82.1],[2,2.64,5.76]],"ltp":2.6,"tv":2827.8,"id":9625551}]}]}
{"op":"mcm","clk":"4234727695","pt":1631549243116,"mc":[{"id":"1.187562121","rc":[{"trd":[[1.65,34.5]],"batl":[[0,1.66,8.78],[1,1.68,5.95],[2,1.7,337.52]],"ltp":1.65,"tv":15327.92,"id":20955040},{"trd":[[2.52,33.57]],"batb":[[0,2.36,28.1],[1,2.24,32.46],[2,1.46,3.41]],"batl":[[0,2.52,21.92],[1,2.6,339.28],[2,2.62,82.1]],"ltp":2.52,"tv":2861.37,"id":9625551}],"tv":18189.3}]}
{"op":"mcm","clk":"4234728585","pt":1631549252737,"mc":[{"id":"1.187562121","rc":[{"trd":[[1.66,12.78],[1.68,5.95],[1.7,263.75]],"batl":[[0,1.7,73.77],[1,1.71,8.82],[2,1.72,43.17]],"ltp":1.7,"tv":15606.4,"id":20955040},{"trd":[[2.42,185.16],[2.46,4.06],[2.5,5.83]],"ltp":2.42,"tv":3056.42,"id":9625551}],"tv":18662.83}]}
{"op":"mcm","clk":"4234729240","pt":1631549259791,"mc":[{"id":"1.187562121","rc":[{"trd":[[1.65,35.04]],"ltp":1.65,"tv":15606.94,"id":20955040},{"trd":[[2.52,33.92]],"batl":[[0,2.52,21.57]],"ltp":2.52,"tv":3056.77,"id":9625551}],"tv":18663.72}]}
{"op":"mcm","clk":"4234729435","pt":1631549261986,"mc":[{"id":"1.187562121","rc":[{"trd":[[1.65,37.17]],"ltp":1.65,"tv":15609.07,"id":20955040},{"trd":[[2.52,35.31]],"batl":[[0,2.52,20.18]],"ltp":2.52,"tv":3058.16,"id":9625551}],"tv":18667.24}]}
{"op":"mcm","clk":"4234729514","pt":1631549262931,"mc":[{"id":"1.187562121","rc":[{"batl":[[1,2.6,326.67]],"ltp":2.52,"tv":3058.16,"id":9625551}]}]}
{"op":"mcm","clk":"4234729801","pt":1631549265940,"mc":[{"id":"1.187562121","rc":[{"batl":[[0,1.68,15.31],[1,1.7,73.77],[2,1.71,8.82]],"ltp":1.65,"tv":15609.07,"id":20955040},{"batl":[[1,2.56,9.88],[2,2.6,326.67]],"ltp":2.52,"tv":3058.16,"id":9625551}]}]}
{"op":"mcm","clk":"4234731096","pt":1631549279856,"mc":[{"id":"1.187562121","rc":[{"batb":[[0,1.66,14.44],[1,1.6,48.23],[2,1.56,52.42]],"ltp":1.65,"tv":15609.07,"id":20955040}]}]}
{"op":"mcm","clk":"4234732064","pt":1631549289355,"mc":[{"id":"1.187562121","rc":[{"batb":[[1,1.65,8.66],[2,1.6,48.23]],"ltp":1.65,"tv":15609.07,"id":20955040}]}]}
{"op":"mcm","clk":"4234732481","pt":1631549293746,"mc":[{"id":"1.187562121","rc":[{"trd":[[1.66,25.04]],"batb":[[0,1.66,8.31]],"ltp":1.66,"tv":15621.33,"id":20955040}],"tv":18679.5}]}
{"op":"mcm","clk":"4234733865","pt":1631549308501,"mc":[{"id":"1.187562121","rc":[{"trd":[[1.66,25.2]],"batb":[[0,1.66,8.23]],"ltp":1.66,"tv":15621.49,"id":20955040}],"tv":18679.65}]}
{"op":"mcm","clk":"4234735106","pt":1631549323501,"mc":[{"id":"1.187562121","rc":[{"batl":[[2,1.71,41.63]],"ltp":1.66,"tv":15621.49,"id":20955040},{"batb":[[0,2.4,5.81],[1,2.36,34.28],[2,2.24,32.46]],"ltp":2.52,"tv":3058.16,"id":9625551}]}]}
{"op":"mcm","clk":"4234735976","pt":1631549333613,"mc":[{"id":"1.187562121","rc":[{"trd":[[1.68,8.11]],"batb":[[0,1.65,8.66],[1,1.6,48.23],[2,1.57,43.57]],"batl":[[0,1.68,14.23]],"ltp":1.68,"tv":15623.64,"id":20955040}],"tv":18681.81}]}
{"op":"mcm","clk":"4234736269","pt":1631549336736,"mc":[{"id":"1.187562121","rc":[{"batb":[[0,1.67,8.23],[1,1.65,8.66],[2,1.6,48.23]],"ltp":1.68,"tv":15623.64,"id":20955040}]}]}
{"op":"mcm","clk":"4234736361","pt":1631549337732,"mc":[{"id":"1.187562121","rc":[{"batl":[[0,3.8,27.43],[1,8.8,7.22],[2,44,7.22]],"ltp":1.68,"tv":15623.64,"id":20955040},{"batb":[[0,2.36,34.28],[1,2.24,32.46],[2,1.46,3.41]],"batl":[[1,2.6,21.58],[2,2.74,4.75]],"ltp":2.52,"tv":3058.16,"id":9625551}]}]}
{"op":"mcm","clk":"4234736387","pt":1631549338044,"mc":[{"id":"1.187562121","rc":[{"batb":[[2,1.58,37.56]],"ltp":1.68,"tv":15623.64,"id":20955040},{"batb":[[0,2.36,6.18]],"ltp":2.52,"tv":3058.16,"id":9625551}]}]}
{"op":"mcm","clk":"4234736736","pt":1631549341226,"mc":[{"id":"1.187562121","rc":[{"batl":[[0,1.72,35.41],[1,3.8,27.43],[2,8.8,7.22]],"ltp":1.68,"tv":15623.64,"id":20955040},{"batb":[[0,2.38,6.46],[1,2.36,6.18],[2,2.24,32.46]],"ltp":2.52,"tv":3058.16,"id":9625551}]}]}
{"op":"mcm","clk":"4234737782","pt":1631549351844,"mc":[{"id":"1.187562121","rc":[{"trd":[[1.67,16.47]],"batb":[[0,1.65,8.66],[1,1.62,390.67]],"batl":[[0,1.66,18.49],[1,1.68,17.86],[2,1.69,43.88]],"ltp":1.67,"tv":15640.11,"id":20955040},{"batb":[[0,2.48,80.64],[1,2.44,25.42],[2,2.38,6.46]],"ltp":2.52,"tv":3058.16,"id":9625551}],"tv":18698.28}]}
{"op":"mcm","clk":"4234737846","pt":1631549352366,"mc":[{"id":"1.187562121","rc":[{"batb":[[2,1.61,18.64]],"ltp":1.67,"tv":15640.11,"id":20955040}]}]}
{"op":"mcm","clk":"4234738321","pt":1631549356557,"mc":[{"id":"1.187562121","rc":[{"trd":[[1.65,85.32]],"batb":[[0,1.65,91.84]],"ltp":1.65,"tv":15688.27,"id":20955040},{"trd":[[2.52,55.49]],"batl":[[0,2.6,21.58],[1,2.74,4.75],[2,2.76,4.77]],"ltp":2.52,"tv":3078.34,"id":9625551}],"tv":18766.61}]}
{"op":"mcm","clk":"4234738692","pt":1631549359847,"mc":[{"id":"1.187562121","rc":[{"batb":[[1,1.54,55.61],[2,1.01,107.79]],"batl":[[0,1.67,41.5],[1,1.69,36.5],[2,3.8,27.43]],"ltp":1.65,"tv":15688.27,"id":20955040},{"batb":[[0,2.48,5.51],[1,2.44,6.67],[2,2.32,29.36]],"batl":[[2,990,0.01]],"ltp":2.52,"tv":3078.34,"id":9625551}]}]}
{"op":"mcm","clk":"4234738735","pt":1631549360358,"mc":[{"id":"1.187562121","rc":[{"trd":[[1.65,86.1]],"batb":[[0,1.54,55.61],[1,1.01,107.79],[2,1.01,0]],"batl":[[0,1.69,36.5],[1,3.8,27.43],[2,8.8,7.22]],"ltp":1.65,"tv":15689.05,"id":20955040},{"batb":[[0,2.44,6.67],[1,2.32,29.36],[2,1.46,3.41]],"ltp":2.52,"tv":3078.34,"id":9625551}],"tv":18767.39}]}
{"op":"mcm","clk":"4234738899","pt":1631549361765,"mc":[{"id":"1.187562121","rc":[{"trd":[[2.44,3.42]],"batb":[[0,2.44,4.96]],"ltp":2.44,"tv":3081.76,"id":9625551}],"tv":18770.81}]}
{"op":"mcm","clk":"4234738998","pt":1631549362762,"mc":[{"id":"1.187562121","rc":[{"batb":[[0,1.6,35.39],[1,1.58,41.56],[2,1.54,55.61]],"batl":[[0,1.68,36.64],[1,1.69,36.5],[2,3.8,27.43]],"ltp":1.65,"tv":15689.05,"id":20955040},{"batb":[[0,2.46,5.88],[1,2.44,4.96],[2,2.32,29.36]],"batl":[[1,2.68,5.14],[2,2.74,4.75]],"ltp":2.44,"tv":3081.76,"id":9625551}]}]}
{"op":"mcm","clk":"4234739085","pt":1631549363657,"mc":[{"id":"1.187562121","rc":[{"batb":[[0,1.67,91.45]],"batl":[[0,1.69,36.5],[1,3.8,27.43],[2,8.8,7.22]],"ltp":1.65,"tv":15689.05,"id":20955040},{"batb":[[0,2.44,4.96],[1,2.32,29.36],[2,1.46,3.41]],"batl":[[1,2.74,4.75],[2,990,0.01]],"ltp":2.44,"tv":3081.76,"id":9625551}]}]}
{"op":"mcm","clk":"4234739409","pt":1631549366835,"mc":[{"id":"1.187562121","rc":[{"trd":[[1.67,58.06]],"batb":[[0,1.67,70.65],[1,1.6,34.94],[2,1.58,41.56]],"batl":[[0,1.68,38.89],[1,1.69,36.5],[2,3.8,27.43]],"ltp":1.67,"tv":15730.64,"id":20955040},{"batb":[[0,2.46,5.51],[1,2.44,4.96],[2,2.32,29.36]],"batl":[[1,2.68,5.14],[2,2.74,4.75]],"ltp":2.44,"tv":3081.76,"id":9625551}],"tv":18812.4}]}
{"op":"mcm","clk":"4234739447","pt":1631549367148,"mc":[{"id":"1.187562121","rc":[{"batb":[[1,1.58,41.56],[2,1.54,55.61]],"batl":[[0,1.69,36.5],[1,3.8,27.43],[2,8.8,7.22]],"ltp":1.67,"tv":15730.64,"id":20955040},{"batb":[[0,2.44,4.96],[1,2.32,29.36],[2,1.46,3.41]],"batl":[[1,2.74,4.75],[2,990,0.01]],"ltp":2.44,"tv":3081.76,"id":9625551}]}]}
{"op":"mcm","clk":"4234739817","pt":1631549370771,"mc":[{"id":"1.187562121","rc":[{"batb":[[0,1.58,41.56],[1,1.54,55.61],[2,1.01,107.79]],"ltp":1.67,"tv":15730.64,"id":20955040}]}]}
{"op":"mcm","clk":"4234739908","pt":1631549371773,"mc":[{"id":"1.187562121","rc":[{"batb":[[0,1.6,343.8],[1,1.58,41.56],[2,1.54,55.61]],"batl":[[0,1.64,6.1],[1,1.66,125.96],[2,1.67,45.18]],"ltp":1.67,"tv":15730.64,"id":20955040},{"trd":[[2.6,53.46]],"batb":[[0,2.54,15.74],[1,2.5,245.74],[2,2.44,4.96]],"batl":[[0,2.6,15.62],[1,2.66,6.17],[2,2.74,4.75]],"ltp":2.6,"tv":3093.68,"id":9625551}],"tv":18824.32}]}
{"op":"mcm","clk":"4234739997","pt":1631549372774,"mc":[{"id":"1.187562121","rc":[{"batb":[[1,1.59,18.86],[2,1.58,69.87]],"batl":[[1,1.66,53.68],[2,1.67,9.04]],"ltp":1.67,"tv":15730.64,"id":20955040},{"batb":[[1,2.5,269.48]],"ltp":2.6,"tv":3093.68,"id":9625551}]}]}
{"op":"mcm","clk":"4234740102","pt":1631549373870,"mc":[{"id":"1.187562121","rc":[{"trd":[[1.64,46.08],[1.65,110.33]],"batb":[[0,1.65,40.32],[1,1.6,343.8],[2,1.59,18.86]],"batl":[[0,1.66,53.68],[1,1.67,9.04],[2,1.68,26.62]],"ltp":1.65,"tv":15767.07,"id":20955040},{"trd":[[2.54,15.74]],"batb":[[0,2.5,269.48],[1,2.44,4.96],[2,2.4,26.51]],"ltp":2.54,"tv":3109.42,"id":9625551}],"tv":18876.49}]}
{"op":"mcm","clk":"4234740393","pt":1631549376778,"mc":[{"id":"1.187562121","rc":[{"trd":[[1.62,77.02],[1.65,190.97]],"batb":[[0,1.6,343.8],[1,1.59,18.86],[2,1.58,51]],"batl":[[0,1.64,101.68],[1,1.66,53.68],[2,1.67,9.04]],"ltp":1.62,"tv":15868.8,"id":20955040},{"trd":[[2.6,71.55]],"batl":[[0,2.66,6.17],[1,2.74,4.75],[2,2.88,3.47]],"ltp":2.6,"tv":3127.51,"id":9625551}],"tv":18996.32}]}
{"op":"mcm","clk":"4234740572","pt":1631549378489,"mc":[{"id":"1.187562121","rc":[{"batb":[[1,1.59,58.97]],"batl":[[2,1.67,51.54]],"ltp":1.62,"tv":15868.8,"id":20955040},{"batb":[[1,2.48,6.01],[2,2.46,6.38]],"batl":[[1,2.7,4.75],[2,2.74,4.75]],"ltp":2.6,"tv":3127.51,"id":9625551}]}]}
{"op":"mcm","clk":"4234740680","pt":1631549379682,"mc":[{"id":"1.187562121","rc":[{"trd":[[1.64,46.24]],"batb":[[0,1.6,388.89]],"batl":[[0,1.64,101.6],[1,1.65,40.3],[2,1.66,88.43]],"ltp":1.64,"tv":15868.96,"id":20955040},{"batb":[[0,2.52,5.49],[1,2.5,275.1],[2,2.48,6.01]],"batl":[[1,2.68,5.14],[2,2.7,4.75]],"ltp":2.6,"tv":3127.51,"id":9625551}],"tv":18996.47}]}
{"op":"mcm","clk":"4234740816","pt":1631549380881,"mc":[{"id":"1.187562121","rc":[{"batb":[[0,1.51,59.81],[1,1.01,107.79],[2,1.58,0]],"batl":[[2,1.66,34.75]],"ltp":1.64,"tv":15868.96,"id":20955040},{"batb":[[1,2.5,5.62]],"batl":[[0,2.68,5.14],[1,990,0.01],[2,2.7,0]],"ltp":2.6,"tv":3127.51,"id":9625551}]}]}
{"op":"mcm","clk":"4234740853","pt":1631549381249,"mc":[{"id":"1.187562121","rc":[{"batl":[[0,1.65,40.3],[1,3.8,27.43],[2,8.8,7.22]],"ltp":1.64,"tv":15868.96,"id":20955040},{"batb":[[1,2.4,26.51],[2,1.46,3.41]],"ltp":2.6,"tv":3127.51,"id":9625551}]}]}
{"op":"mcm","clk":"4234741086","pt":1631549383766,"mc":[{"id":"1.187562121","rc":[{"batb":[[0,1.6,41.19],[1,1.51,59.81],[2,1.01,107.79]],"ltp":1.64,"tv":15868.96,"id":20955040}]}]}
{"op":"mcm","clk":"4234741345","pt":1631549386898,"mc":[{"id":"1.187562121","rc":[{"batl":[[0,1.62,17.99],[1,1.63,92.02],[2,1.64,46]],"ltp":1.64,"tv":15868.96,"id":20955040},{"batb":[[0,2.58,77.52],[1,2.52,5.49],[2,2.4,26.51]],"batl":[[1,2.72,227.11],[2,990,0.01]],"ltp":2.6,"tv":3127.51,"id":9625551}]}]}
{"op":"mcm","clk":"4234741418","pt":1631549387882,"mc":[{"id":"1.187562121","rc":[{"batb":[[2,1.49,63.16]],"batl":[[2,1.64,82.03]],"ltp":1.64,"tv":15868.96,"id":20955040},{"batb":[[0,2.58,37.31],[2,2.48,24.41]],"batl":[[2,2.78,53.96]],"ltp":2.6,"tv":3127.51,"id":9625551}]}]}
{"op":"mcm","clk":"4234741442","pt":1631549388220,"mc":[{"id":"1.187562121","rc":[{"batl":[[1,1.63,55.21],[2,1.64,63.63]],"ltp":1.64,"tv":15868.96,"id":20955040},{"batl":[[2,2.78,10.8]],"ltp":2.6,"tv":3127.51,"id":9625551}]}]}
{"op":"mcm","clk":"4234741818","pt":1631549391885,"mc":[{"id":"1.187562121","rc":[{"trd":[[1.6,110.09]],"batb":[[0,1.6,23.31]],"ltp":1.6,"tv":15904.72,"id":20955040}],"tv":19032.23}]}
{"op":"mcm","clk":"4234741927","pt":1631549393285,"mc":[{"id":"1.187562121","rc":[{"batl":[[0,1.62,163.99]],"ltp":1.6,"tv":15904.72,"id":20955040}]}]}
{"op":"mcm","clk":"4234742125","pt":1631549395476,"mc":[{"id":"1.187562121","rc":[{"batb":[[0,1.59,45.11],[1,1.49,63.16],[2,1.01,107.79]],"batl":[[0,1.62,146],[1,1.63,38.5],[2,1.64,35.18]],"ltp":1.6,"tv":15904.72,"id":20955040},{"batb":[[0,2.58,5.56],[1,2.56,6.08],[2,2.52,5.49]],"batl":[[0,2.7,4.65],[1,990,0.01],[2,2.78,0]],"ltp":2.6,"tv":3127.51,"id":9625551}]}]}
{"op":"mcm","clk":"4234742201","pt":1631549396300,"mc":[{"id":"1.187562121","rc":[{"batl":[[0,1.64,35.18],[1,3.8,27.43],[2,8.8,7.22]],"ltp":1.6,"tv":15904.72,"id":20955040},{"batb":[[0,2.68,4.51],[2,2.48,24.41]],"ltp":2.6,"tv":3127.51,"id":9625551}]}]}
{"op":"mcm","clk":"4234742450","pt":1631549398903,"mc":[{"id":"1.187562121","rc":[{"trd":[[1.6,117.64]],"ltp":1.6,"tv":15912.27,"id":20955040},{"trd":[[2.68,4.51]],"batb":[[0,2.56,6.08],[1,2.48,24.41],[2,1.46,3.41]],"ltp":2.68,"tv":3132.02,"id":9625551}],"tv":19044.29}]}
{"op":"mcm","clk":"4234743109","pt":1631549405470,"mc":[{"id":"1.187562121","rc":[{"batl":[[0,2.68,4.64],[1,2.7,4.65],[2,990,0.01]],"ltp":2.68,"tv":3132.02,"id":9625551}]}]}
{"op":"mcm","clk":"4234743246","pt":1631549406815,"mc":[{"id":"1.187562121","rc":[{"batl":[[0,2.7,4.65],[1,990,0.01],[2,990,0]],"ltp":2.68,"tv":3132.02,"id":9625551}]}]}
{"op":"mcm","clk":"4234743807","pt":1631549412804,"mc":[{"id":"1.187562121","rc":[{"batl":[[0,2.68,5.39],[1,2.7,4.65],[2,990,0.01]],"ltp":2.68,"tv":3132.02,"id":9625551}]}]}
{"op":"mcm","clk":"4234743890","pt":1631549413695,"mc":[{"id":"1.187562121","rc":[{"batl":[[0,2.7,4.65],[1,990,0.01],[2,990,0]],"ltp":2.68,"tv":3132.02,"id":9625551}]}]}
{"op":"mcm","clk":"4234744145","pt":1631549416814,"mc":[{"id":"1.187562121","rc":[{"batb":[[0,1.62,11.75],[1,1.61,98.43],[2,1.6,46.58]],"batl":[[1,1.66,20.97],[2,1.67,35.38]],"ltp":1.6,"tv":15912.27,"id":20955040},{"batl":[[0,2.64,2],[1,2.66,268.59],[2,2.7,4.65]],"ltp":2.68,"tv":3132.02,"id":9625551}]}]}
{"op":"mcm","clk":"4234744223","pt":1631549417699,"mc":[{"id":"1.187562121","rc":[{"batb":[[1,1.61,23.91],[2,1.6,9.32]],"batl":[[1,1.65,6.06],[2,1.66,20.97]],"ltp":1.6,"tv":15912.27,"id":20955040},{"batb":[[2,2.38,27.18]],"ltp":2.68,"tv":3132.02,"id":9625551}]}]}
{"op":"mcm","clk":"4234744585","pt":1631549421502,"mc":[{"id":"1.187562121","rc":[{"trd":[[1.61,132.52],[1.62,98.56]],"batb":[[0,1.61,10.87],[1,1.6,9.32],[2,1.59,54.43]],"ltp":1.61,"tv":15959.89,"id":20955040},{"trd":[[2.62,66.62]],"ltp":2.62,"tv":3133.24,"id":9625551}],"tv":19093.13}]}
{"op":"mcm","clk":"4234744763","pt":1631549423318,"mc":[{"id":"1.187562121","rc":[{"batl":[[0,1.64,169.18],[1,1.65,48.36],[2,1.66,59.22]],"ltp":1.61,"tv":15959.89,"id":20955040},{"batb":[[1,2.52,5.49],[2,2.5,5.49]],"ltp":2.62,"tv":3133.24,"id":9625551}]}]}
{"op":"mcm","clk":"4234744931","pt":1631549424929,"mc":[{"id":"1.187562121","rc":[{"batl":[[2,2.68,4.39]],"ltp":2.62,"tv":3133.24,"id":9625551}]}]}
{"op":"mcm","clk":"4234745114","pt":1631549426906,"mc":[{"id":"1.187562121","rc":[{"batb":[[0,1.55,54.27],[1,1.52,58.21],[2,1.51,39.13]],"batl":[[0,1.64,134],[1,1.65,42.3],[2,1.66,38.25]],"ltp":1.61,"tv":15959.89,"id":20955040},{"batb":[[0,2.52,5.49],[1,2.5,5.49],[2,2.48,24.41]],"batl":[[0,2.68,4.39],[1,990,0.01],[2,2.68,0]],"ltp":2.62,"tv":3133.24,"id":9625551}]}]}
{"op":"mcm","clk":"4234745143","pt":1631549427219,"mc":[{"id":"1.187562121","rc":[{"batb":[[0,1.52,58.21],[1,1.01,107.79],[2,1.51,0]],"batl":[[2,3.8,27.43]],"ltp":1.61,"tv":15959.89,"id":20955040},{"batb":[[1,2.38,27.18],[2,1.46,3.41]],"ltp":2.62,"tv":3133.24,"id":9625551}]}]}
{"op":"mcm","clk":"4234745221","pt":1631549427947,"mc":[{"id":"1.187562121","rc":[{"batl":[[0,1.65,42.3],[1,3.8,27.43],[2,8.8,7.22]],"ltp":1.61,"tv":15959.89,"id":20955040}]}]}
{"op":"mcm","clk":"4234745401","pt":1631549429821,"mc":[{"id":"1.187562121","rc":[{"batb":[[0,1.6,40.74],[1,1.52,58.21],[2,1.01,107.79]],"ltp":1.61,"tv":15959.89,"id":20955040}]}]}
{"op":"mcm","clk":"4234745515","pt":1631549431028,"mc":[{"id":"1.187562121","rc":[{"batb":[[0,1.62,14.44],[1,1.6,40.74],[2,1.52,58.21]],"ltp":1.61,"tv":15959.89,"id":20955040}]}]}
{"op":"mcm","clk":"4234745780","pt":1631549433739,"mc":[{"id":"1.187562121","rc":[{"batb":[[1,1.61,39.09],[2,1.6,40.74]],"batl":[[0,1.64,38.68],[1,1.65,42.3],[2,3.8,27.43]],"ltp":1.61,"tv":15959.89,"id":20955040},{"batb":[[0,2.56,5.83],[1,2.52,5.49],[2,2.38,27.18]],"batl":[[0,2.64,4.93],[1,2.68,4.39],[2,990,0.01]],"ltp":2.62,"tv":3133.24,"id":9625551}]}]}
{"op":"mcm","clk":"4234745805","pt":1631549434049,"mc":[{"id":"1.187562121","rc":[{"batb":[[1,1.6,40.74],[2,1.52,58.21]],"batl":[[0,1.65,42.3],[1,3.8,27.43],[2,8.8,7.22]],"ltp":1.61,"tv":15959.89,"id":20955040},{"batb":[[0,2.52,5.49],[1,2.38,27.18],[2,1.46,3.41]],"batl":[[0,2.68,4.39],[1,990,0.01],[2,990,0]],"ltp":2.62,"tv":3133.24,"id":9625551}]}]}
{"op":"mcm","clk":"4234746386","pt":1631549440844,"mc":[{"id":"1.187562121","rc":[{"batb":[[1,1.61,38.09],[2,1.6,40.74]],"batl":[[0,1.64,37.43],[1,1.65,42.3],[2,3.8,27.43]],"ltp":1.61,"tv":15959.89,"id":20955040},{"batb":[[0,2.56,4.83],[1,2.52,5.49],[2,2.38,27.18]],"batl":[[0,2.64,5.43],[1,2.68,4.39],[2,990,0.01]],"ltp":2.62,"tv":3133.24,"id":9625551}]}]}
{"op":"mcm","clk":"4234746418","pt":1631549441152,"mc":[{"id":"1.187562121","rc":[{"batb":[[1,1.6,40.74],[2,1.52,58.21]],"batl":[[0,1.65,42.3],[1,3.8,27.43],[2,8.8,7.22]],"ltp":1.61,"tv":15959.89,"id":20955040},{"batb":[[0,2.52,5.49],[1,2.38,27.18],[2,1.46,3.41]],"batl":[[0,2.68,4.39],[1,990,0.01],[2,990,0]],"ltp":2.62,"tv":3133.24,"id":9625551}]}]}
{"op":"mcm","clk":"4234746645","pt":1631549443768,"mc":[{"id":"1.187562121","rc":[{"trd":[[1.62,127.45]],"batb":[[0,1.6,40.74],[1,1.52,58.21],[2,1.01,107.79]],"batl":[[0,1.62,1.24],[1,1.63,6.13],[2,1.64,91.46]],"ltp":1.62,"tv":15988.78,"id":20955040},{"batb":[[0,2.54,78.74],[1,2.52,5.49],[2,2.38,27.18]],"batl":[[1,2.72,321],[2,990,0.01]],"ltp":2.62,"tv":3133.24,"id":9625551}],"tv":19122.02}]}
{"op":"mcm","clk":"4234746728","pt":1631549444763,"mc":[{"id":"1.187562121","rc":[{"batb":[[1,1.57,95.54],[2,1.56,47.78]],"batl":[[2,1.64,54.88]],"ltp":1.62,"tv":15988.78,"id":20955040},{"batb":[[0,2.54,69.72]],"batl":[[2,2.92,3.42]],"ltp":2.62,"tv":3133.24,"id":9625551}]}]}
{"op":"mcm","clk":"4234746779","pt":1631549445375,"mc":[{"id":"1.187562121","rc":[{"batb":[[1,1.58,9.02],[2,1.57,19.1]],"ltp":1.62,"tv":15988.78,"id":20955040}]}]}
{"op":"mcm","clk":"4234747124","pt":1631549448774,"mc":[{"id":"1.187562121","rc":[{"batl":[[2,2.82,62.6]],"ltp":2.62,"tv":3133.24,"id":9625551}]}]}
{"op":"mcm","clk":"4234747156","pt":1631549448988,"mc":[{"id":"1.187562121","rc":[{"batl":[[2,2.92,3.42]],"ltp":2.62,"tv":3133.24,"id":9625551}]}]}
{"op":"mcm","clk":"4234747350","pt":1631549450451,"mc":[{"id":"1.187562121","rc":[{"trd":[[1.62,129.93],[1.63,12.26]],"batb":[[0,1.63,1.28],[1,1.6,40.74],[2,1.58,9.02]],"batl":[[0,1.64,54.88],[1,1.65,105.54],[2,1.66,459.51]],"ltp":1.63,"tv":16003.52,"id":20955040},{"batb":[[2,2.46,5.88]],"ltp":2.62,"tv":3133.24,"id":9625551}],"tv":19136.76}]}
{"op":"mcm","clk":"4234747549","pt":1631549452584,"mc":[{"id":"1.187562121","rc":[{"batb":[[0,1.6,40.74],[1,1.58,9.02],[2,1.57,19.1]],"ltp":1.63,"tv":16003.52,"id":20955040}]}]}
{"op":"mcm","clk":"4234747713","pt":1631549454257,"mc":[{"id":"1.187562121","rc":[{"batl":[[1,2.72,309.82]],"ltp":2.62,"tv":3133.24,"id":9625551}]}]}
{"op":"mcm","clk":"4234747982","pt":1631549456873,"mc":[{"id":"1.187562121","rc":[{"batl":[[0,1.64,71.52]],"ltp":1.63,"tv":16003.52,"id":20955040},{"batl":[[0,2.66,9.37],[1,2.68,4.39],[2,2.72,309.82]],"ltp":2.62,"tv":3133.24,"id":9625551}]}]}
{"op":"mcm","clk":"4234748036","pt":1631549457345,"mc":[{"id":"1.187562121","rc":[{"batl":[[0,1.63,1.11],[1,1.64,71.52],[2,1.65,105.54]],"ltp":1.63,"tv":16003.52,"id":20955040}]}]}
{"op":"mcm","clk":"4234748262","pt":1631549459868,"mc":[{"id":"1.187562121","rc":[{"trd":[[1.63,14.48],[1.64,46.58]],"batl":[[0,1.64,71.35],[1,1.65,105.54],[2,1.66,459.51]],"ltp":1.64,"tv":16006.08,"id":20955040}],"tv":19139.32}]}
{"op":"mcm","clk":"4234748326","pt":1631549460591,"mc":[{"id":"1.187562121","rc":[{"batl":[[0,1.64,54.71]],"ltp":1.64,"tv":16006.08,"id":20955040},{"batl":[[0,2.68,4.39],[1,2.72,309.82],[2,2.92,3.42]],"ltp":2.62,"tv":3133.24,"id":9625551}]}]}
{"op":"mcm","clk":"4234748570","pt":1631549463180,"mc":[{"id":"1.187562121","rc":[{"batl":[[0,1.64,71.35]],"ltp":1.64,"tv":16006.08,"id":20955040},{"batl":[[0,2.66,9.37],[1,2.68,4.39],[2,2.72,309.82]],"ltp":2.62,"tv":3133.24,"id":9625551}]}]}
{"op":"mcm","clk":"4234748883","pt":1631549466365,"mc":[{"id":"1.187562121","rc":[{"trd":[[1.64,46.72]],"batl":[[0,1.64,71.21]],"ltp":1.64,"tv":16006.22,"id":20955040},{"trd":[[2.56,21.1]],"ltp":2.56,"tv":3133.33,"id":9625551}],"tv":19139.55}]}
{"op":"mcm","clk":"4234749218","pt":1631549469870,"mc":[{"id":"1.187562121","rc":[{"batb":[[0,1.58,9.02],[1,1.52,104.7],[2,1.51,49.99]],"batl":[[0,1.65,35.81],[1,1.67,17.69],[2,1.68,36.89]],"ltp":1.64,"tv":16006.22,"id":20955040},{"batb":[[0,2.54,22.48],[1,2.46,5.88],[2,2.44,6.42]],"batl":[[0,2.94,4.25],[1,2.98,3.75],[2,3.05,4.5]],"ltp":2.56,"tv":3133.33,"id":9625551}]}]}
{"op":"mcm","clk":"4234749237","pt":1631549470127,"mc":[{"id":"1.187562121","rc":[{"batb":[[1,1.52,46.49]],"batl":[[0,1.7,31.85],[1,3.8,27.43],[2,8.8,7.22]],"ltp":1.64,"tv":16006.22,"id":20955040},{"batb":[[0,2.42,5.44],[1,2.38,27.18],[2,1.46,3.41]],"ltp":2.56,"tv":3133.33,"id":9625551}]}]}
{"op":"mcm","clk":"4234749856","pt":1631549476905,"mc":[{"id":"1.187562121","rc":[{"batl":[[0,1.68,38.39],[1,1.7,31.85],[2,3.8,27.43]],"ltp":1.64,"tv":16006.22,"id":20955040},{"batb":[[0,2.46,5.88],[1,2.42,5.44],[2,2.38,27.18]],"ltp":2.56,"tv":3133.33,"id":9625551}]}]}
{"op":"mcm","clk":"4234749914","pt":1631549477320,"mc":[{"id":"1.187562121","rc":[{"batl":[[0,1.7,31.85],[1,3.8,27.43],[2,8.8,7.22]],"ltp":1.64,"tv":16006.22,"id":20955040},{"batb":[[0,2.42,5.44],[1,2.38,27.18],[2,1.46,3.41]],"ltp":2.56,"tv":3133.33,"id":9625551}]}]}
{"op":"mcm","clk":"4234750258","pt":1631549480534,"mc":[{"id":"1.187562121","rc":[{"batl":[[0,1.68,36.14],[1,1.7,31.85],[2,3.8,27.43]],"ltp":1.64,"tv":16006.22,"id":20955040},{"batb":[[0,2.46,6.38],[1,2.42,5.44],[2,2.38,27.18]],"ltp":2.56,"tv":3133.33,"id":9625551}]}]}
{"op":"mcm","clk":"4234750367","pt":1631549481688,"mc":[{"id":"1.187562121","rc":[{"batb":[[0,1.68,8.88],[1,1.65,90.92],[2,1.64,45.46]],"batl":[[0,1.7,31.85],[1,3.8,27.43],[2,8.8,7.22]],"ltp":1.64,"tv":16006.22,"id":20955040},{"batb":[[0,2.42,11.7],[1,2.38,27.18],[2,2.36,245.09]],"batl":[[0,2.56,367.32],[1,2.74,3.65],[2,2.94,4.25]],"ltp":2.56,"tv":3133.33,"id":9625551}]}]}
{"op":"mcm","clk":"4234750481","pt":1631549482720,"mc":[{"id":"1.187562121","rc":[{"batb":[[1,1.67,5.47],[2,1.65,54.55]],"batl":[[0,1.69,5.92],[1,1.7,31.85],[2,1.72,34.35]],"ltp":1.64,"tv":16006.22,"id":20955040},{"batl":[[0,2.5,2],[1,2.56,367.32],[2,2.74,3.65]],"ltp":2.56,"tv":3133.33,"id":9625551}]}]}
{"op":"mcm","clk":"4234750545","pt":1631549483294,"mc":[{"id":"1.187562121","rc":[{"batb":[[2,1.65,18.18]],"ltp":1.64,"tv":16006.22,"id":20955040}]}]}
{"op":"mcm","clk":"4234750930","pt":1631549486811,"mc":[{"id":"1.187562121","rc":[{"trd":[[1.66,25.32],[1.67,69],[1.68,25.87]],"batb":[[0,1.65,18.18],[1,1.64,9.1],[2,1.63,9.1]],"ltp":1.66,"tv":16035.04,"id":20955040},{"trd":[[2.5,5.91]],"batl":[[0,2.5,1.92]],"ltp":2.5,"tv":3133.41,"id":9625551}],"tv":19168.45}]}
{"op":"mcm","clk":"4234751175","pt":1631549488905,"mc":[{"id":"1.187562121","rc":[{"batl":[[2,2.68,5.14]],"ltp":2.5,"tv":3133.41,"id":9625551}]}]}
{"op":"mcm","clk":"4234751332","pt":1631549490433,"mc":[{"id":"1.187562121","rc":[{"batb":[[2,2.36,250.52]],"ltp":2.5,"tv":3133.41,"id":9625551}]}]}
{"op":"mcm","clk":"4234751492","pt":1631549491891,"mc":[{"id":"1.187562121","rc":[{"batb":[[0,1.6,46.09],[1,1.58,58.43],[2,1.57,42.57]],"batl":[[0,1.69,96]],"ltp":1.66,"tv":16035.04,"id":20955040},{"batb":[[0,2.42,5.44],[2,2.36,5.43]],"batl":[[1,2.68,5.14],[2,2.76,4.77]],"ltp":2.5,"tv":3133.41,"id":9625551}]}]}
{"op":"mcm","clk":"4234751538","pt":1631549492305,"mc":[{"id":"1.187562121","rc":[{"batb":[[0,1.58,9.02],[1,1.57,42.57],[2,1.5,61.57]],"batl":[[1,1.75,28.98],[2,3.8,27.43]],"ltp":1.66,"tv":16035.04,"id":20955040},{"batb":[[0,2.32,5.64],[1,2.26,31.12],[2,1.46,3.41]],"batl":[[0,2.76,4.77],[1,990,0.01],[2,2.76,0]],"ltp":2.5,"tv":3133.41,"id":9625551}]}]}
{"op":"mcm","clk":"4234751618","pt":1631549493042,"mc":[{"id":"1.187562121","rc":[{"batl":[[0,1.75,28.98],[1,3.8,27.43],[2,8.8,7.22]],"ltp":1.66,"tv":16035.04,"id":20955040}]}]}
{"op":"mcm","clk":"4234752137","pt":1631549498744,"mc":[{"id":"1.187562121","rc":[{"batl":[[0,1.73,31.5],[1,1.75,28.98],[2,3.8,27.43]],"ltp":1.66,"tv":16035.04,"id":20955040},{"batb":[[0,2.36,6.18],[1,2.32,5.64],[2,2.26,31.12]],"ltp":2.5,"tv":3133.41,"id":9625551}]}]}
{"op":"mcm","clk":"4234752200","pt":1631549499217,"mc":[{"id":"1.187562121","rc":[{"batl":[[0,1.75,28.98],[1,3.8,27.43],[2,8.8,7.22]],"ltp":1.66,"tv":16035.04,"id":20955040},{"batb":[[0,2.32,5.64],[1,2.26,31.12],[2,1.46,3.41]],"ltp":2.5,"tv":3133.41,"id":9625551}]}]}
{"op":"mcm","clk":"4234752796","pt":1631549505878,"mc":[{"id":"1.187562121","rc":[{"batl":[[0,1.73,36.5],[1,1.75,28.98],[2,3.8,27.43]],"ltp":1.66,"tv":16035.04,"id":20955040},{"batb":[[0,2.36,5.68],[1,2.32,5.64],[2,2.26,31.12]],"ltp":2.5,"tv":3133.41,"id":9625551}]}]}
{"op":"mcm","clk":"4234752820","pt":1631549506191,"mc":[{"id":"1.187562121","rc":[{"batl":[[0,1.75,28.98],[1,3.8,27.43],[2,8.8,7.22]],"ltp":1.66,"tv":16035.04,"id":20955040},{"batb":[[0,2.32,5.64],[1,2.26,31.12],[2,1.46,3.41]],"ltp":2.5,"tv":3133.41,"id":9625551}]}]}
{"op":"mcm","clk":"4234753104","pt":1631549509487,"mc":[{"id":"1.187562121","rc":[{"batb":[[0,1.58,18.29]],"batl":[[0,1.6,9.21],[1,1.61,6.21],[2,1.62,55.56]],"ltp":1.66,"tv":16035.04,"id":20955040},{"batb":[[0,2.54,47.24],[1,2.32,5.64],[2,2.26,31.12]],"batl":[[1,2.78,257.08],[2,990,0.01]],"ltp":2.5,"tv":3133.41,"id":9625551}]}]}
{"op":"mcm","clk":"4234753200","pt":1631549510576,"mc":[{"id":"1.187562121","rc":[{"batl":[[2,1.62,18.52]],"ltp":1.66,"tv":16035.04,"id":20955040},{"batb":[[0,2.62,21.05],[1,2.54,47.24],[2,2.42,25.92]],"batl":[[2,2.8,10.72]],"ltp":2.5,"tv":3133.41,"id":9625551}]}]}
{"op":"mcm","clk":"4234753536","pt":1631549514488,"mc":[{"id":"1.187562121","rc":[{"trd":[[1.58,123.65]],"batb":[[0,1.58,14.47]],"ltp":1.58,"tv":16042.69,"id":20955040}],"tv":19176.11}]}
{"op":"mcm","clk":"4234753662","pt":1631549515798,"mc":[{"id":"1.187562121","rc":[{"batb":[[2,2.46,6.38]],"ltp":2.5,"tv":3133.41,"id":9625551}]}]}
{"op":"mcm","clk":"4234754427","pt":1631549523800,"mc":[{"id":"1.187562121","rc":[{"batb":[[0,1.44,55.67],[1,1.4,80.02],[2,1.01,107.79]],"batl":[[0,3.8,27.43],[1,8.8,7.22],[2,44,7.22]],"ltp":1.58,"tv":16042.69,"id":20955040},{"batb":[[0,2.42,25.92],[1,2.4,6.06],[2,1.46,3.41]],"batl":[[0,3.3,3.45],[1,990,0.01],[2,2.8,0]],"ltp":2.5,"tv":3133.41,"id":9625551}]}]}
{"op":"mcm","clk":"4234754713","pt":1631549526725,"mc":[{"id":"1.187562121","rc":[{"batb":[[0,1.6,5.2],[1,1.44,55.67],[2,1.4,80.02]],"batl":[[0,1.68,36.39],[1,1.71,31.81],[2,3.8,27.43]],"ltp":1.58,"tv":16042.69,"id":20955040},{"batb":[[0,2.46,5.51],[1,2.42,25.92],[2,2.4,6.06]],"ltp":2.5,"tv":3133.41,"id":9625551}]}]}
{"op":"mcm","clk":"4234754766","pt":1631549527135,"mc":[{"id":"1.187562121","rc":[{"batl":[[0,1.71,31.81],[1,3.8,27.43],[2,8.8,7.22]],"ltp":1.58,"tv":16042.69,"id":20955040},{"batb":[[0,2.42,25.92],[1,2.4,6.06],[2,1.46,3.41]],"ltp":2.5,"tv":3133.41,"id":9625551}]}]}
{"op":"mcm","clk":"4234755044","pt":1631549529714,"mc":[{"id":"1.187562121","rc":[{"batb":[[0,1.6,5.74]],"ltp":1.58,"tv":16042.69,"id":20955040}]}]}
{"op":"mcm","clk":"4234755411","pt":1631549533820,"mc":[{"id":"1.187562121","rc":[{"batl":[[0,1.68,36.39],[1,1.71,31.81],[2,3.8,27.43]],"ltp":1.58,"tv":16042.69,"id":20955040},{"batb":[[0,2.46,4.88],[1,2.42,25.92],[2,2.4,6.06]],"ltp":2.5,"tv":3133.41,"id":9625551}]}]}
{"op":"mcm","clk":"4234755470","pt":1631549534544,"mc":[{"id":"1.187562121","rc":[{"trd":[[1.6,129.12]],"batb":[[0,1.47,13.58],[1,1.45,644.44],[2,1.44,55.67]],"batl":[[0,1.5,11.31],[1,1.51,6.62],[2,1.54,38.37]],"ltp":1.6,"tv":16054.17,"id":20955040},{"batb":[[0,3,72.32],[1,2.94,10.2],[2,2.92,5.1]],"ltp":2.5,"tv":3133.41,"id":9625551}],"tv":19187.59}]}
{"op":"mcm","clk":"4234755562","pt":1631549535628,"mc":[{"id":"1.187562121","rc":[{"batb":[[2,2.92,43.6]],"batl":[[0,3.2,9.38],[1,3.25,4.68],[2,3.3,8.13]],"ltp":2.5,"tv":3133.41,"id":9625551}]}]}
{"op":"mcm","clk":"4234755878","pt":1631549539327,"mc":[{"id":"1.187562121","rc":[{"batb":[[0,1.47,235.58]],"ltp":1.6,"tv":16054.17,"id":20955040}]}]}
{"op":"mcm","clk":"4234756177","pt":1631549543021,"mc":[{"id":"1.187562121","rc":[{"trd":[[1.5,73.72]],"batl":[[0,1.5,8.42]],"ltp":1.5,"tv":16059.95,"id":20955040}],"tv":19193.36}]}
{"op":"mcm","clk":"4234756835","pt":1631549550584,"mc":[{"id":"1.187562121","rc":[{"trd":[[1.5,73.92]],"batl":[[0,1.5,8.32]],"ltp":1.5,"tv":16060.15,"id":20955040}],"tv":19193.56}]}
{"op":"mcm","clk":"4234756920","pt":1631549551733,"mc":[{"id":"1.187562121","rc":[{"batb":[[0,1.47,222],[1,1.36,71.68],[2,1.32,71.64]],"batl":[[0,3.8,27.43],[1,8.8,7.22],[2,44,7.22]],"ltp":1.5,"tv":16060.15,"id":20955040},{"batb":[[0,2.66,19.96],[1,2.56,4.83],[2,1.46,3.41]],"batl":[[0,3.8,3.47],[1,4.2,2.83],[2,990,0.01]],"ltp":2.5,"tv":3133.41,"id":9625551}]}]}
{"op":"mcm","clk":"4234757087","pt":1631549553295,"mc":[{"id":"1.187562121","rc":[{"trd":[[1.47,1167.45]],"batb":[[0,1.47,25.92],[1,1.32,71.64],[2,1.31,110.89]],"ltp":1.47,"tv":16452.2,"id":20955040},{"batl":[[0,4.2,2.83],[1,990,0.01],[2,990,0]],"ltp":2.5,"tv":3133.41,"id":9625551}],"tv":19585.61}]}
{"op":"mcm","clk":"4234757251","pt":1631549554911,"mc":[{"id":"1.187562121","rc":[{"batb":[[0,1.32,71.64],[1,1.31,110.89],[2,1.01,107.79]],"batl":[[0,1.64,35.68],[1,3.8,27.43],[2,8.8,7.22]],"ltp":1.47,"tv":16452.2,"id":20955040}]}]}
{"op":"mcm","clk":"4234757598","pt":1631549558400,"mc":[{"id":"1.187562121","rc":[{"batl":[[0,1.59,181.28],[1,1.64,35.68],[2,3.8,27.43]],"ltp":1.47,"tv":16452.2,"id":20955040}]}]}
{"op":"mcm","clk":"4234757669","pt":1631549559128,"mc":[{"id":"1.187562121","rc":[{"batl":[[0,1.64,35.68],[1,3.8,27.43],[2,8.8,7.22]],"ltp":1.47,"tv":16452.2,"id":20955040}]}]}
{"op":"mcm","clk":"4234757817","pt":1631549560699,"mc":[{"id":"1.187562121","rc":[{"batb":[[0,1.54,581.17],[1,1.53,107.65],[2,1.52,29.22]],"batl":[[0,1.62,36.48],[1,1.64,53.69],[2,3.8,27.43]],"ltp":1.47,"tv":16452.2,"id":20955040},{"batb":[[1,2.6,269.03],[2,2.56,4.83]],"batl":[[0,3.05,3.28],[1,4.2,2.83],[2,990,0.01]],"ltp":2.5,"tv":3133.41,"id":9625551}]}]}
{"op":"mcm","clk":"4234757902","pt":1631549561532,"mc":[{"id":"1.187562121","rc":[{"batb":[[0,1.54,542.21],[1,1.53,88.17],[2,1.52,9.74]],"batl":[[0,1.59,6.29],[1,1.62,36.48],[2,1.64,53.69]],"ltp":1.47,"tv":16452.2,"id":20955040},{"batb":[[0,2.66,31.24],[1,2.64,5.64],[2,2.62,5.64]],"ltp":2.5,"tv":3133.41,"id":9625551}]}]}
{"op":"mcm","clk":"4234758086","pt":1631549563729,"mc":[{"id":"1.187562121","rc":[{"batl":[[1,1.6,23.77],[2,1.62,36.48]],"ltp":1.47,"tv":16452.2,"id":20955040},{"batl":[[0,2.78,6.76],[1,3.05,3.28],[2,4.2,2.83]],"ltp":2.5,"tv":3133.41,"id":9625551}]}]}
{"op":"mcm","clk":"4234758140","pt":1631549564412,"mc":[{"id":"1.187562121","rc":[{"batl":[[0,1.59,187.57]],"ltp":1.47,"tv":16452.2,"id":20955040}]}]}
{"op":"mcm","clk":"4234758326","pt":1631549566715,"mc":[{"id":"1.187562121","rc":[{"batl":[[2,3.45,3.7]],"ltp":2.5,"tv":3133.41,"id":9625551}]}]}
{"op":"mcm","clk":"4234758371","pt":1631549567232,"mc":[{"id":"1.187562121","rc":[{"batl":[[2,3.35,3.9]],"ltp":2.5,"tv":3133.41,"id":9625551}]}]}
{"op":"mcm","clk":"4234758958","pt":1631549573826,"mc":[{"id":"1.187562121","rc":[{"batb":[[0,1.48,64.25],[1,1.38,57.46],[2,1.37,89.58]],"batl":[[0,1.59,181.28],[1,1.68,41.14],[2,1.72,31.41]],"ltp":1.47,"tv":16452.2,"id":20955040},{"batb":[[0,2.66,19.96],[1,2.46,5.88],[2,2.42,25.84]],"batl":[[0,3.65,3.5],[1,990,0.01],[2,3.35,0]],"ltp":2.5,"tv":3133.41,"id":9625551}]}]}
{"op":"mcm","clk":"4234758968","pt":1631549573933,"mc":[{"id":"1.187562121","rc":[{"batb":[[0,1.38,57.46],[1,1.37,89.58],[2,1.01,107.79]],"ltp":1.47,"tv":16452.2,"id":20955040},{"batb":[[0,2.46,5.88],[1,2.42,25.84],[2,2.38,6.46]],"ltp":2.5,"tv":3133.41,"id":9625551}]}]}
{"op":"mcm","clk":"4234759228","pt":1631549576860,"mc":[{"id":"1.187562121","rc":[{"batb":[[0,1.43,60.43],[1,1.38,57.46],[2,1.37,89.58]],"ltp":1.47,"tv":16452.2,"id":20955040},{"batl":[[0,3.35,3.7],[1,3.65,3.5],[2,990,0.01]],"ltp":2.5,"tv":3133.41,"id":9625551}]}]}
{"op":"mcm","clk":"4234759251","pt":1631549577172,"mc":[{"id":"1.187562121","rc":[{"batb":[[0,1.38,57.46],[1,1.37,89.58],[2,1.01,107.79]],"ltp":1.47,"tv":16452.2,"id":20955040},{"batl":[[0,3.65,3.5],[1,990,0.01],[2,990,0]],"ltp":2.5,"tv":3133.41,"id":9625551}]}]}
{"op":"mcm","clk":"4234759361","pt":1631549578732,"mc":[{"id":"1.187562121","rc":[{"batl":[[0,1.72,31.41],[1,3.8,27.43],[2,8.8,7.22]],"ltp":1.47,"tv":16452.2,"id":20955040},{"batb":[[0,2.42,25.84],[1,2.38,6.46],[2,1.46,3.41]],"batl":[[0,2.68,2],[1,3.65,3.5],[2,990,0.01]],"ltp":2.5,"tv":3133.41,"id":9625551}]}]}
{"op":"mcm","clk":"4234759491","pt":1631549580258,"mc":[{"id":"1.187562121","rc":[{"batb":[[0,1.66,2.37],[1,1.63,122.7],[2,1.55,38.12]],"batl":[[0,1.7,13.53],[1,1.72,65.76],[2,1.74,16.98]],"ltp":1.47,"tv":16452.2,"id":20955040},{"batb":[[2,2.32,455.97]],"batl":[[0,2.5,7.59],[1,2.52,2],[2,2.56,325.39]],"ltp":2.5,"tv":3133.41,"id":9625551}]}]}
{"op":"mcm","clk":"4234759573","pt":1631549581260,"mc":[{"id":"1.187562121","rc":[{"batb":[[2,1.56,51.84]],"batl":[[0,1.69,5.92],[1,1.7,13.53],[2,1.72,65.76]],"ltp":1.47,"tv":16452.2,"id":20955040},{"batb":[[1,2.4,12.5],[2,2.38,12.7]],"ltp":2.5,"tv":3133.41,"id":9625551}]}]}
{"op":"mcm","clk":"4234759868","pt":1631549584572,"mc":[{"id":"1.187562121","rc":[{"batl":[[1,1.7,183.08]],"ltp":1.47,"tv":16452.2,"id":20955040}]}]}
{"op":"mcm","clk":"4234760040","pt":1631549586646,"mc":[{"id":"1.187562121","rc":[{"batb":[[2,1.57,46.57]],"ltp":1.47,"tv":16452.2,"id":20955040}]}]}
{"op":"mcm","clk":"4234760607","pt":1631549593891,"mc":[{"id":"1.187562121","rc":[{"batb":[[1,1.57,46.57],[2,1.56,51.84]],"batl":[[0,1.7,169.55],[1,1.72,65.76],[2,1.74,52.23]],"ltp":1.47,"tv":16452.2,"id":20955040},{"trd":[[2.5,6.09]],"batb":[[1,2.38,6.46],[2,2.34,6.22]],"batl":[[0,2.44,2],[2,2.76,4.77]],"ltp":2.5,"tv":3133.59,"id":9625551}],"tv":19585.79}]}
{"op":"mcm","clk":"4234760645","pt":1631549594396,"mc":[{"id":"1.187562121","rc":[{"batb":[[0,1.57,46.57],[1,1.54,51.62],[2,1.53,47.33]],"batl":[[1,1.75,33.94],[2,1.77,38.5]],"ltp":1.47,"tv":16452.2,"id":20955040},{"batb":[[0,2.32,6.39],[1,2.28,5.91],[2,2.26,31.29]],"batl":[[1,2.76,4.77],[2,2.86,4.75]],"ltp":2.5,"tv":3133.59,"id":9625551}]}]}
{"op":"mcm","clk":"4234760881","pt":1631549597285,"mc":[{"id":"1.187562121","rc":[{"trd":[[1.69,0.54]],"ltp":1.69,"tv":16452.74,"id":20955040},{"trd":[[2.44,3.79]],"batl":[[0,2.44,1.63]],"ltp":2.44,"tv":3133.96,"id":9625551}],"tv":19586.7}]}
{"op":"mcm","clk":"4234761227","pt":1631549601666,"mc":[{"id":"1.187562121","rc":[{"batl":[[1,1.71,304.39],[2,1.75,33.94]],"ltp":1.69,"tv":16452.74,"id":20955040}]}]}
{"op":"mcm","clk":"4234761306","pt":1631549602877,"mc":[{"id":"1.187562121","rc":[{"batb":[[0,1.53,47.33],[1,1.47,66.35],[2,1.01,107.79]],"batl":[[1,1.75,33.94],[2,1.77,38.5]],"ltp":1.69,"tv":16452.74,"id":20955040},{"trd":[[2.44,7.05]],"batl":[[0,2.9,4.25],[1,990,0.01],[2,2.86,0]],"ltp":2.44,"tv":3137.22,"id":9625551}],"tv":19589.96}]}
{"op":"mcm","clk":"4234761465","pt":1631549604678,"mc":[{"id":"1.187562121","rc":[{"batl":[[0,1.68,222]],"ltp":1.69,"tv":16452.74,"id":20955040}]}]}
{"op":"mcm","clk":"4234761732","pt":1631549608584,"mc":[{"id":"1.187562121","rc":[{"batl":[[1,1.78,30.25],[2,3.8,27.43]],"ltp":1.69,"tv":16452.74,"id":20955040},{"batb":[[0,2.28,5.91],[1,2.26,31.29],[2,1.46,3.41]],"ltp":2.44,"tv":3137.22,"id":9625551}]}]}
{"op":"mcm","clk":"4234761817","pt":1631549609681,"mc":[{"id":"1.187562121","rc":[{"batb":[[0,1.57,44.57],[1,1.53,47.33],[2,1.47,66.35]],"ltp":1.69,"tv":16452.74,"id":20955040},{"batl":[[0,2.76,4.52],[1,2.9,4.25],[2,990,0.01]],"ltp":2.44,"tv":3137.22,"id":9625551}]}]}
{"op":"mcm","clk":"4234761845","pt":1631549609998,"mc":[{"id":"1.187562121","rc":[{"batb":[[0,1.53,47.33],[1,1.47,66.35],[2,1.01,107.79]],"ltp":1.69,"tv":16452.74,"id":20955040},{"batl":[[0,2.9,4.25],[1,990,0.01],[2,990,0]],"ltp":2.44,"tv":3137.22,"id":9625551}]}]}
{"op":"mcm","clk":"4234762861","pt":1631549622811,"mc":[{"id":"1.187562121","rc":[{"batl":[[0,1.78,30.25],[1,3.8,27.43],[2,8.8,7.22]],"ltp":1.69,"tv":16452.74,"id":20955040}]}]}
{"op":"mcm","clk":"4234762896","pt":1631549623228,"mc":[{"id":"1.187562121","rc":[{"batl":[[0,2.46,2],[1,2.9,4.25],[2,990,0.01]],"ltp":2.44,"tv":3137.22,"id":9625551}]}]}
{"op":"mcm","clk":"4234763116","pt":1631549625906,"mc":[{"id":"1.187562121","rc":[{"trd":[[1.68,28.8]],"batl":[[0,1.58,139.99],[1,1.59,1977.89],[2,1.6,93.76]],"ltp":1.68,"tv":16455.67,"id":20955040},{"trd":[[2.46,6.06]],"batb":[[0,2.42,1218.71],[1,2.28,5.91],[2,2.26,31.29]],"batl":[[0,2.84,12.44],[1,2.88,278.01],[2,2.9,4.25]],"ltp":2.46,"tv":3139.22,"id":9625551}],"tv":19594.89}]}
{"op":"mcm","clk":"4234763226","pt":1631549626906,"mc":[{"id":"1.187562121","rc":[{"batb":[[2,1.46,40.47]],"batl":[[0,1.58,89.36],[1,1.59,6.29],[2,1.6,56.26]],"ltp":1.68,"tv":16455.67,"id":20955040},{"batb":[[0,2.7,19.21],[1,2.44,25],[2,2.42,1218.71]],"batl":[[1,2.86,52.44],[2,2.88,304.23]],"ltp":2.46,"tv":3139.22,"id":9625551}]}]}
{"op":"mcm","clk":"4234763301","pt":1631549627794,"mc":[{"id":"1.187562121","rc":[{"batl":[[2,1.6,18.76]],"ltp":1.68,"tv":16455.67,"id":20955040},{"batl":[[1,2.86,10.48],[2,2.88,283.25]],"ltp":2.46,"tv":3139.22,"id":9625551}]}]}
{"op":"mcm","clk":"4234763553","pt":1631549630891,"mc":[{"id":"1.187562121","rc":[{"batl":[[0,1.57,19.73],[1,1.58,89.36],[2,1.59,6.29]],"ltp":1.68,"tv":16455.67,"id":20955040}]}]}
{"op":"mcm","clk":"4234763564","pt":1631549631097,"mc":[{"id":"1.187562121","rc":[{"batl":[[0,1.58,89.36],[1,1.59,6.29],[2,1.6,18.76]],"ltp":1.68,"tv":16455.67,"id":20955040}]}]}
{"op":"mcm","clk":"4234763644","pt":1631549632423,"mc":[{"id":"1.187562121","rc":[{"batl":[[0,1.57,183.59],[1,1.58,89.36],[2,1.59,6.29]],"ltp":1.68,"tv":16455.67,"id":20955040}]}]}
{"op":"mcm","clk":"4234763782","pt":1631549634102,"mc":[{"id":"1.187562121","rc":[{"trd":[[1.57,210.65]],"batl":[[0,1.57,161.46]],"ltp":1.57,"tv":16499.91,"id":20955040}],"tv":19639.14}]}
{"op":"mcm","clk":"4234764172","pt":1631549638711,"mc":[{"id":"1.187562121","rc":[{"trd":[[1.57,219.27]],"batl":[[0,1.57,157.15]],"ltp":1.57,"tv":16508.53,"id":20955040}],"tv":19647.76}]}
{"op":"mcm","clk":"4234764616","pt":1631549643252,"mc":[{"id":"1.187562121","rc":[{"batb":[[2,1.36,92.18]],"ltp":1.57,"tv":16508.53,"id":20955040}]}]}
{"op":"mcm","clk":"4234764748","pt":1631549645139,"mc":[{"id":"1.187562121","rc":[{"trd":[[1.57,222.87]],"batl":[[0,1.57,155.35]],"ltp":1.57,"tv":16512.13,"id":20955040}],"tv":19651.36}]}
{"op":"mcm","clk":"4234764901","pt":1631549646771,"mc":[{"id":"1.187562121","rc":[{"batb":[[0,1.47,66.35],[1,1.36,92.18],[2,1.01,107.79]],"batl":[[1,3.8,27.43],[2,8.8,7.22]],"ltp":1.57,"tv":16512.13,"id":20955040},{"batb":[[2,1.46,3.41]],"batl":[[0,990,0.01],[1,2.86,0],[2,2.88,0]],"ltp":2.46,"tv":3139.22,"id":9625551}]}]}
{"op":"mcm","clk":"4234764932","pt":1631549647083,"mc":[{"id":"1.187562121","rc":[{"batb":[[0,1.36,91.6],[1,1.01,107.79],[2,1.01,0]],"ltp":1.57,"tv":16512.13,"id":20955040},{"batb":[[0,2.44,25],[1,1.46,3.41],[2,1.01,105.79]],"ltp":2.46,"tv":3139.22,"id":9625551}]}]}
{"op":"mcm","clk":"4234765728","pt":1631549654765,"mc":[{"id":"1.187562121","rc":[{"batb":[[0,1.42,17.58],[1,1.4,336.86],[2,1.36,91.6]],"batl":[[0,1.44,11],[1,1.46,109.59],[2,1.47,2273.1]],"ltp":1.57,"tv":16512.13,"id":20955040},{"batb":[[0,3.3,60.6],[1,2.44,25],[2,1.46,3.41]],"batl":[[0,3.5,134.74],[1,990,0.01]],"ltp":2.46,"tv":3139.22,"id":9625551}]}]}
{"op":"mcm","clk":"4234765831","pt":1631549655760,"mc":[{"id":"1.187562121","rc":[{"batb":[[1,1.4,444],[2,1.39,53.58]],"batl":[[1,1.46,68.49],[2,1.47,30.82]],"ltp":1.57,"tv":16512.13,"id":20955040},{"batb":[[0,3.3,36.36],[1,3.1,32.21],[2,2.74,18.71]],"batl":[[1,3.65,2.74],[2,990,0.01]],"ltp":2.46,"tv":3139.22,"id":9625551}]}]}
{"op":"mcm","clk":"4234765863","pt":1631549656081,"mc":[{"id":"1.187562121","rc":[{"batb":[[1,1.4,358.28],[2,1.39,10.72]],"ltp":1.57,"tv":16512.13,"id":20955040}]}]}
{"op":"mcm","clk":"4234766241","pt":1631549659789,"mc":[{"id":"1.187562121","rc":[{"trd":[[1.42,235.19]],"batb":[[0,1.4,358.28],[1,1.39,10.72],[2,1.38,10.72]],"batl":[[0,1.42,154.18],[1,1.44,11],[2,1.45,24.64]],"ltp":1.42,"tv":16547.29,"id":20955040},{"batl":[[0,3.45,60.87],[1,3.5,134.74],[2,3.65,2.74]],"ltp":2.46,"tv":3139.22,"id":9625551}],"tv":19686.52}]}
{"op":"mcm","clk":"4234766257","pt":1631549659948,"mc":[{"id":"1.187562121","rc":[{"batl":[[2,1.46,68.49]],"ltp":1.42,"tv":16547.29,"id":20955040},{"batl":[[0,3.5,134.74],[1,3.65,2.74],[2,990,0.01]],"ltp":2.46,"tv":3139.22,"id":9625551}]}]}
{"op":"mcm","clk":"4234767145","pt":1631549669772,"mc":[{"id":"1.187562121","rc":[{"batl":[[1,1.46,68.49],[2,1.47,30.82]],"ltp":1.42,"tv":16547.29,"id":20955040}]}]}
{"op":"mcm","clk":"4234767302","pt":1631549671607,"mc":[{"id":"1.187562121","rc":[{"batb":[[0,1.36,91.6],[1,1.26,93.98],[2,1.24,147.29]],"batl":[[1,1.57,40.5],[2,1.62,37.25]],"ltp":1.42,"tv":16547.29,"id":20955040},{"batb":[[0,3.1,32.21],[1,2.74,23.23],[2,2.6,4.94]],"batl":[[0,4.9,2.05],[1,5.8,2.02]],"ltp":2.46,"tv":3139.22,"id":9625551}]}]}
{"op":"mcm","clk":"4234767385","pt":1631549672603,"mc":[{"id":"1.187562121","rc":[{"trd":[[1.42,237.31]],"batb":[[0,1.41,15.19],[1,1.24,147.29],[2,1.21,121.69]],"batl":[[0,1.42,152.06],[1,1.43,14.49],[2,1.57,40.5]],"ltp":1.42,"tv":16549.41,"id":20955040},{"trd":[[3.35,23.16]],"batb":[[0,2.74,23.23],[1,2.6,4.94],[2,1.46,3.41]],"batl":[[0,5.8,2.02],[1,990,0.01],[2,990,0]],"ltp":3.35,"tv":3140.12,"id":9625551}],"tv":19689.54}]}
{"op":"mcm","clk":"4234767405","pt":1631549672914,"mc":[{"id":"1.187562121","rc":[{"batb":[[0,1.24,147.29],[1,1.21,121.69],[2,1.01,107.79]],"batl":[[1,1.57,40.5],[2,1.62,37.25]],"ltp":1.42,"tv":16549.41,"id":20955040}]}]}
{"op":"mcm","clk":"4234767804","pt":1631549677366,"mc":[{"id":"1.187562121","rc":[{"batl":[[1,3.8,27.43],[2,8.8,7.22]],"ltp":1.42,"tv":16549.41,"id":20955040},{"batb":[[0,2.74,18.71]],"ltp":3.35,"tv":3140.12,"id":9625551}]}]}
{"op":"mcm","clk":"4234767930","pt":1631549678890,"mc":[{"id":"1.187562121","rc":[{"batb":[[0,1.26,109.98],[1,1.24,147.29],[2,1.21,121.69]],"ltp":1.42,"tv":16549.41,"id":20955040},{"batl":[[0,4.9,2.25],[1,5.8,2.02],[2,990,0.01]],"ltp":3.35,"tv":3140.12,"id":9625551}]}]}
{"op":"mcm","clk":"4234767948","pt":1631549679046,"mc":[{"id":"1.187562121","rc":[{"batb":[[0,1.24,147.29],[1,1.21,121.69],[2,1.01,107.79]],"ltp":1.42,"tv":16549.41,"id":20955040},{"batl":[[0,5.8,2.02],[1,990,0.01],[2,990,0]],"ltp":3.35,"tv":3140.12,"id":9625551}]}]}
{"op":"mcm","clk":"4234768100","pt":1631549680866,"mc":[{"id":"1.187562121","rc":[{"batb":[[0,1.25,594.23],[1,1.24,194.95],[2,1.22,24.22]],"batl":[[0,1.28,14.38],[1,1.32,7.58],[2,1.36,43.45]],"ltp":1.42,"tv":16549.41,"id":20955040},{"batb":[[0,4.6,43.48],[1,4.3,6.98],[2,4.2,3.48]],"batl":[[0,4.8,7.85],[1,5,148.56],[2,5.8,2.02]],"ltp":3.35,"tv":3140.12,"id":9625551}]}]}
{"op":"mcm","clk":"4234768134","pt":1631549681356,"mc":[{"id":"1.187562121","rc":[{"batl":[[1,4.9,3.06],[2,5,152.09]],"ltp":3.35,"tv":3140.12,"id":9625551}]}]}
{"op":"mcm","clk":"4234768244","pt":1631549682811,"mc":[{"id":"1.187562121","rc":[{"batl":[[1,4.9,6.12],[2,5,153.62]],"ltp":3.35,"tv":3140.12,"id":9625551}]}]}
{"op":"mcm","clk":"4234768368","pt":1631549684816,"mc":[{"id":"1.187562121","rc":[{"batl":[[0,1.28,183.07]],"ltp":1.42,"tv":16549.41,"id":20955040}]}]}
{"op":"mcm","clk":"4234768399","pt":1631549685289,"mc":[{"id":"1.187562121","rc":[{"trd":[[1.28,201.13]],"batl":[[0,1.28,164.82]],"ltp":1.28,"tv":16567.66,"id":20955040},{"trd":[[4.5,11.19],[4.6,103.13]],"batb":[[0,4.3,6.98],[1,4.2,3.48],[2,4.1,3.48]],"ltp":4.5,"tv":3232.27,"id":9625551}],"tv":19799.94}]}
{"op":"mcm","clk":"4234768788","pt":1631549689715,"mc":[{"id":"1.187562121","rc":[{"trd":[[1.26,37.25]],"ltp":1.26,"tv":16578.24,"id":20955040},{"trd":[[4.8,26.79]],"batl":[[0,4.8,5.07]],"ltp":4.8,"tv":3235.05,"id":9625551}],"tv":19813.3}]}
{"op":"mcm","clk":"4234769031","pt":1631549692732,"mc":[{"id":"1.187562121","rc":[{"trd":[[1.28,209.75]],"batl":[[0,1.28,160.51]],"ltp":1.28,"tv":16586.86,"id":20955040}],"tv":19821.92}]}
{"op":"mcm","clk":"4234769257","pt":1631549695249,"mc":[{"id":"1.187562121","rc":[{"trd":[[1.28,211.55]],"batl":[[0,1.28,159.61]],"ltp":1.28,"tv":16588.66,"id":20955040},{"batl":[[0,4.9,6.12],[1,5,153.62],[2,5.1,3.06]],"ltp":4.8,"tv":3235.05,"id":9625551}],"tv":19823.72}]}
{"op":"mcm","clk":"4234769518","pt":1631549698140,"mc":[{"id":"1.187562121","rc":[{"batb":[[0,4.5,6.93],[1,4.3,6.98],[2,4.2,3.48]],"batl":[[0,4.7,3.92],[1,4.9,6.12],[2,5,153.62]],"ltp":4.8,"tv":3235.05,"id":9625551}]}]}
{"op":"mcm","clk":"4234769664","pt":1631549699820,"mc":[{"id":"1.187562121","rc":[{"trd":[[4.5,14.43]],"batb":[[0,4.3,6.98],[1,4.2,3.48],[2,4.1,3.48]],"batl":[[0,4.9,6.12],[1,5,153.62],[2,5.1,3.06]],"ltp":4.5,"tv":3238.29,"id":9625551}],"tv":19826.96}]}
{"op":"mcm","clk":"4234769956","pt":1631549702841,"mc":[{"id":"1.187562121","rc":[{"batb":[[0,4.5,5.31],[1,4.3,6.98],[2,4.2,3.48]],"batl":[[0,4.7,5.48],[1,4.9,6.12],[2,5,153.62]],"ltp":4.5,"tv":3238.29,"id":9625551}]}]}
{"op":"mcm","clk":"4234770196","pt":1631549704837,"mc":[{"id":"1.187562121","rc":[{"batl":[[0,1.28,381.61]],"ltp":1.28,"tv":16588.66,"id":20955040}]}]}
{"op":"mcm","clk":"4234770621","pt":1631549709432,"mc":[{"id":"1.187562121","rc":[{"batb":[[0,4.3,6.98],[1,4.2,3.48],[2,4.1,3.48]],"batl":[[0,4.9,6.12],[1,5,153.62],[2,5.1,3.06]],"ltp":4.5,"tv":3238.29,"id":9625551}]}]}
{"op":"mcm","clk":"4234770916","pt":1631549712324,"mc":[{"id":"1.187562121","rc":[{"batb":[[0,4.5,5.31],[1,4.3,6.98],[2,4.2,3.48]],"batl":[[0,4.7,5.48],[1,4.9,6.12],[2,5,153.62]],"ltp":4.5,"tv":3238.29,"id":9625551}]}]}
{"op":"mcm","clk":"4234774981","pt":1631549757145,"mc":[{"id":"1.187562121","rc":[{"trd":[[1.28,216.97]],"batl":[[0,1.28,378.9]],"ltp":1.28,"tv":16594.08,"id":20955040}],"tv":19832.38}]}
{"op":"mcm","clk":"4234775299","pt":1631549760830,"mc":[{"id":"1.187562121","rc":[{"trd":[[1.28,218.77]],"batl":[[0,1.28,378]],"ltp":1.28,"tv":16595.88,"id":20955040}],"tv":19834.18}]}
{"op":"mcm","clk":"4234775813","pt":1631549767229,"mc":[{"id":"1.187562121","rc":[{"batb":[[1,1.24,147.29],[2,1.21,121.69]],"batl":[[2,1.53,15.36]],"ltp":1.28,"tv":16595.88,"id":20955040}]}]}
{"op":"mcm","clk":"4234776076","pt":1631549770469,"mc":[{"id":"1.187562121","rc":[{"batb":[[1,1.24,242.56],[2,1.22,111.34]],"batl":[[2,1.41,67.5]],"ltp":1.28,"tv":16595.88,"id":20955040}]}]}
{"op":"mcm","clk":"4234776572","pt":1631549776873,"mc":[{"id":"1.187562121","rc":[{"batb":[[0,1.24,242.56],[1,1.22,111.34],[2,1.21,121.69]],"batl":[[1,1.41,67.5],[2,1.46,56.75]],"ltp":1.28,"tv":16595.88,"id":20955040},{"batb":[[0,4,33.3],[1,3.45,25.16],[2,3.4,3.71]],"batl":[[0,5.2,2.03],[1,5.6,2.01],[2,5.8,2.02]],"ltp":4.5,"tv":3238.29,"id":9625551}]}]}
{"op":"mcm","clk":"4234776624","pt":1631549777608,"mc":[{"id":"1.187562121","rc":[{"batb":[[0,1.22,111.34],[1,1.2,179.25],[2,1.01,107.79]],"ltp":1.28,"tv":16595.88,"id":20955040},{"batb":[[0,3.45,25.16],[1,3.4,3.71],[2,3.15,3.83]],"batl":[[0,5.6,2.01],[1,990,0.01],[2,5.8,0]],"ltp":4.5,"tv":3238.29,"id":9625551}]}]}
{"op":"mcm","clk":"4234776833","pt":1631549780377,"mc":[{"id":"1.187562121","rc":[{"batb":[[0,1.24,100.52],[1,1.22,111.34],[2,1.2,179.25]],"ltp":1.28,"tv":16595.88,"id":20955040},{"batl":[[0,5.2,2.18],[1,5.6,2.01],[2,990,0.01]],"ltp":4.5,"tv":3238.29,"id":9625551}]}]}
{"op":"mcm","clk":"4234776897","pt":1631549781212,"mc":[{"id":"1.187562121","rc":[{"trd":[[1.28,219.16]],"batb":[[0,1.22,111.34],[1,1.2,179.25],[2,1.01,107.79]],"batl":[[0,1.28,377.81]],"ltp":1.28,"tv":16596.27,"id":20955040},{"batl":[[0,5.6,2.01],[1,990,0.01],[2,990,0]],"ltp":4.5,"tv":3238.29,"id":9625551}],"tv":19834.56}]}
{"op":"mcm","clk":"4234777527","pt":1631549787796,"mc":[{"id":"1.187562121","rc":[{"batb":[[0,1.24,107.27],[1,1.22,111.34],[2,1.2,179.25]],"ltp":1.28,"tv":16596.27,"id":20955040},{"batl":[[0,5.2,2.03],[1,5.6,2.01],[2,990,0.01]],"ltp":4.5,"tv":3238.29,"id":9625551}]}]}
{"op":"mcm","clk":"4234777554","pt":1631549788105,"mc":[{"id":"1.187562121","rc":[{"batb":[[0,1.22,111.34],[1,1.2,179.25],[2,1.01,107.79]],"ltp":1.28,"tv":16596.27,"id":20955040},{"batl":[[0,5.6,2.01],[1,990,0.01],[2,990,0]],"ltp":4.5,"tv":3238.29,"id":9625551}]}]}
{"op":"mcm","clk":"4234777840","pt":1631549791291,"mc":[{"id":"1.187562121","rc":[{"batl":[[2,1.53,15.36]],"ltp":1.28,"tv":16596.27,"id":20955040}]}]}
{"op":"mcm","clk":"4234778031","pt":1631549793804,"mc":[{"id":"1.187562121","rc":[{"trd":[[1.28,244.56]],"batl":[[0,1.28,352.41]],"ltp":1.28,"tv":16621.67,"id":20955040},{"trd":[[4.5,21.65]],"ltp":4.5,"tv":3245.51,"id":9625551}],"tv":19867.18}]}
{"op":"mcm","clk":"4234778106","pt":1631549794704,"mc":[{"id":"1.187562121","rc":[{"batb":[[0,1.23,656.9],[1,1.22,111.34],[2,1.21,48.84]],"batl":[[0,1.25,109.17],[1,1.27,745.29],[2,1.28,360.22]],"ltp":1.28,"tv":16621.67,"id":20955040},{"batb":[[0,4.9,18.36],[1,4.8,9.18],[2,4.7,9.18]],"batl":[[0,5.3,6.01],[1,5.6,2.01],[2,990,0.01]],"ltp":4.5,"tv":3245.51,"id":9625551}]}]}
{"op":"mcm","clk":"4234778163","pt":1631549795441,"mc":[{"id":"1.187562121","rc":[{"batb":[[1,1.22,135.94],[2,1.21,69.4]],"ltp":1.28,"tv":16621.67,"id":20955040}]}]}
{"op":"mcm","clk":"4234778400","pt":1631549798712,"mc":[{"id":"1.187562121","rc":[{"batl":[[2,1.28,7.81]],"ltp":1.28,"tv":16621.67,"id":20955040}]}]}
{"op":"mcm","clk":"4234778451","pt":1631549799339,"mc":[{"id":"1.187562121","rc":[{"trd":[[1.25,328.47]],"batl":[[0,1.25,12.85]],"ltp":1.25,"tv":16717.99,"id":20955040},{"trd":[[5,234.22]],"ltp":5.0,"tv":3269.59,"id":9625551}],"tv":19987.58}]}
{"op":"mcm","clk":"4234778558","pt":1631549800797,"mc":[{"id":"1.187562121","rc":[{"batb":[[2,1.21,191.09]],"ltp":1.25,"tv":16717.99,"id":20955040},{"batl":[[2,5.8,2.02]],"ltp":5.0,"tv":3269.59,"id":9625551}]}]}
{"op":"mcm","clk":"4234778705","pt":1631549802823,"mc":[{"id":"1.187562121","rc":[{"batl":[[1,1.26,132.48],[2,1.27,745.29]],"ltp":1.25,"tv":16717.99,"id":20955040}]}]}
{"op":"mcm","clk":"4234778876","pt":1631549804817,"mc":[{"id":"1.187562121","rc":[{"batb":[[0,1.2,139.42],[1,1.17,213.64],[2,1.01,107.79]],"batl":[[0,1.26,132.48],[1,1.32,79.61],[2,1.35,65.9]],"ltp":1.25,"tv":16717.99,"id":20955040},{"batb":[[0,4.1,2.64],[1,3.9,36.49],[2,3.85,3.17]],"batl":[[0,6,2],[1,990,0.01],[2,5.8,0]],"ltp":5.0,"tv":3269.59,"id":9625551}]}]}
{"op":"mcm","clk":"4234779114","pt":1631549807845,"mc":[{"id":"1.187562121","rc":[{"batb":[[0,1.21,108.69],[1,1.2,139.42],[2,1.17,213.64]],"ltp":1.25,"tv":16717.99,"id":20955040},{"batl":[[0,5.8,2.02],[1,6,2],[2,990,0.01]],"ltp":5.0,"tv":3269.59,"id":9625551}]}]}
{"op":"mcm","clk":"4234779132","pt":1631549808109,"mc":[{"id":"1.187562121","rc":[{"batb":[[0,1.2,139.42],[1,1.17,213.64],[2,1.01,107.79]],"ltp":1.25,"tv":16717.99,"id":20955040},{"batl":[[0,6,2],[1,990,0.01],[2,990,0]],"ltp":5.0,"tv":3269.59,"id":9625551}]}]}
{"op":"mcm","clk":"4234779300","pt":1631549810047,"mc":[{"id":"1.187562121","rc":[{"batl":[[1,1.31,222],[2,1.32,79.61]],"ltp":1.25,"tv":16717.99,"id":20955040}]}]}
{"op":"mcm","clk":"4234780649","pt":1631549826290,"mc":[{"id":"1.187562121","rc":[{"batl":[[0,1.35,65.9],[1,1.41,67.5],[2,1.53,15.36]],"ltp":1.25,"tv":16717.99,"id":20955040},{"batb":[[0,3.9,36.49],[1,3.85,3.17],[2,3.4,3.71]],"ltp":5.0,"tv":3269.59,"id":9625551}]}]}
{"op":"mcm","clk":"4234780844","pt":1631549828288,"mc":[{"id":"1.187562121","rc":[{"batb":[[0,1.28,3.16],[1,1.27,157.48],[2,1.26,46.9]],"batl":[[0,1.3,17.75],[1,1.33,778.44],[2,1.35,65.9]],"ltp":1.25,"tv":16717.99,"id":20955040},{"batl":[[0,4.5,4.52],[1,4.6,2],[2,4.7,6.38]],"ltp":5.0,"tv":3269.59,"id":9625551}]}]}
{"op":"mcm","clk":"4234780941","pt":1631549829386,"mc":[{"id":"1.187562121","rc":[{"batl":[[1,1.33,785.96]],"ltp":1.25,"tv":16717.99,"id":20955040}]}]}
{"op":"mcm","clk":"4234781161","pt":1631549832130,"mc":[{"id":"1.187562121","rc":[{"batl":[[1,1.32,126.46],[2,1.33,785.96]],"ltp":1.25,"tv":16717.99,"id":20955040}]}]}
{"op":"mcm","clk":"4234782062","pt":1631549843749,"mc":[{"id":"1.187562121","rc":[{"trd":[[1.28,246.36]],"batb":[[0,1.28,2.26]],"ltp":1.28,"tv":16719.79,"id":20955040}],"tv":19989.38}]}
{"op":"mcm","clk":"4234782254","pt":1631549845739,"mc":[{"id":"1.187562121","rc":[{"batb":[[0,1.22,95.34],[1,1.21,174.22],[2,1.2,139.42]],"batl":[[0,1.32,126.46],[1,1.41,67.5],[2,1.45,47.7]],"ltp":1.28,"tv":16719.79,"id":20955040},{"batb":[[0,3.4,3.71],[1,3.25,29.02],[2,3.2,3.82]],"batl":[[0,5.6,2.01],[1,6,2],[2,990,0.01]],"ltp":5.0,"tv":3269.59,"id":9625551}]}]}
{"op":"mcm","clk":"4234782505","pt":1631549848817,"mc":[{"id":"1.187562121","rc":[{"batb":[[1,1.2,175.56],[2,1.01,107.79]],"ltp":1.28,"tv":16719.79,"id":20955040},{"batb":[[1,3.25,28.77]],"batl":[[1,990,0.01],[2,990,0]],"ltp":5.0,"tv":3269.59,"id":9625551}]}]}
{"op":"mcm","clk":"4234782564","pt":1631549849738,"mc":[{"id":"1.187562121","rc":[{"batl":[[0,1.45,47.7],[1,1.53,15.36],[2,3.8,27.43]],"ltp":1.28,"tv":16719.79,"id":20955040},{"batb":[[0,3.25,28.77],[1,3.2,3.82],[2,1.46,3.41]],"batl":[[0,4.3,1.39],[1,5.6,2.01],[2,990,0.01]],"ltp":5.0,"tv":3269.59,"id":9625551}]}]}
{"op":"mcm","clk":"4234782830","pt":1631549852747,"mc":[{"id":"1.187562121","rc":[{"batb":[[0,1.24,102.77],[1,1.22,95.34],[2,1.2,175.56]],"batl":[[0,1.41,62.5],[1,1.45,47.7],[2,1.53,15.36]],"ltp":1.28,"tv":16719.79,"id":20955040},{"batb":[[0,3.4,3.31],[1,3.25,28.77],[2,3.2,3.82]],"ltp":5.0,"tv":3269.59,"id":9625551}]}]}
{"op":"mcm","clk":"4234782868","pt":1631549853069,"mc":[{"id":"1.187562121","rc":[{"batb":[[0,1.22,95.34],[1,1.2,175.56],[2,1.01,107.79]],"batl":[[0,1.35,123.65]],"ltp":1.28,"tv":16719.79,"id":20955040},{"batb":[[0,3.25,28.77],[1,3.2,3.82],[2,1.46,3.41]],"ltp":5.0,"tv":3269.59,"id":9625551}]}]}
{"op":"mcm","clk":"4234783177","pt":1631549856663,"mc":[{"id":"1.187562121","rc":[{"batl":[[1,1.41,65.5],[2,1.45,47.7]],"ltp":1.28,"tv":16719.79,"id":20955040},{"batb":[[0,3.4,3.76],[1,3.25,28.77],[2,3.2,3.82]],"ltp":5.0,"tv":3269.59,"id":9625551}]}]}
{"op":"mcm","clk":"4234783445","pt":1631549859844,"mc":[{"id":"1.187562121","rc":[{"batb":[[0,1.24,90.02],[1,1.22,95.34],[2,1.2,175.56]],"ltp":1.28,"tv":16719.79,"id":20955040},{"batl":[[0,4.3,1.53],[1,5.2,2.13],[2,5.6,2.01]],"ltp":5.0,"tv":3269.59,"id":9625551}]}]}
{"op":"mcm","clk":"4234783471","pt":1631549860162,"mc":[{"id":"1.187562121","rc":[{"batb":[[0,1.22,95.34],[1,1.2,175.56],[2,1.01,107.79]],"ltp":1.28,"tv":16719.79,"id":20955040},{"batl":[[1,5.6,2.01],[2,990,0.01]],"ltp":5.0,"tv":3269.59,"id":9625551}]}]}
{"op":"mcm","clk":"4234783746","pt":1631549862725,"mc":[{"id":"1.187562121","rc":[{"batb":[[0,1.24,15.67],[1,1.22,95.34],[2,1.21,48.84]],"batl":[[0,1.26,40.85],[1,1.28,967.43],[2,1.31,45.11]],"ltp":1.28,"tv":16719.79,"id":20955040},{"trd":[[4.3,65.62]],"batb":[[0,4.8,6.24],[1,4.7,3.12],[2,4.6,3.12]],"batl":[[0,5.3,165.64]],"ltp":4.3,"tv":3272.65,"id":9625551}],"tv":19992.44}]}
{"op":"mcm","clk":"4234783836","pt":1631549863765,"mc":[{"id":"1.187562121","rc":[{"batb":[[1,1.22,103.54]],"ltp":1.28,"tv":16719.79,"id":20955040},{"batl":[[1,5.4,5.56],[2,5.5,2.78]],"ltp":4.3,"tv":3272.65,"id":9625551}]}]}
{"op":"mcm","clk":"4234784326","pt":1631549868838,"mc":[{"id":"1.187562121","rc":[{"batl":[[1,1.27,131.44],[2,1.28,967.43]],"ltp":1.28,"tv":16719.79,"id":20955040}]}]}
{"op":"mcm","clk":"4234784356","pt":1631549869258,"mc":[{"id":"1.187562121","rc":[{"batb":[[2,1.21,154.53]],"ltp":1.28,"tv":16719.79,"id":20955040}]}]}
{"op":"mcm","clk":"4234784968","pt":1631549875877,"mc":[{"id":"1.187562121","rc":[{"batb":[[1,1.22,95.34]],"batl":[[2,1.28,959.62]],"ltp":1.28,"tv":16719.79,"id":20955040}]}]}
{"op":"mcm","clk":"4234785034","pt":1631549876357,"mc":[{"id":"1.187562121","rc":[{"batb":[[0,1.19,145.71],[1,1.17,216.58],[2,1.01,107.79]],"batl":[[0,1.27,131.44],[1,1.31,76.5],[2,1.32,81.61]],"ltp":1.28,"tv":16719.79,"id":20955040},{"batb":[[0,4.2,2.62],[1,4.1,2.74],[2,4,2.93]],"batl":[[0,6.4,2],[1,990,0.01],[2,5.5,0]],"ltp":4.3,"tv":3272.65,"id":9625551}]}]}
{"op":"mcm","clk":"4234785555","pt":1631549881702,"mc":[{"id":"1.187562121","rc":[{"batl":[[0,1.31,76.5],[1,1.32,81.61],[2,1.33,85.5]],"ltp":1.28,"tv":16719.79,"id":20955040}]}]}
{"op":"mcm","clk":"4234785587","pt":1631549882063,"mc":[{"id":"1.187562121","rc":[{"batl":[[0,1.33,85.5],[1,1.41,65.5],[2,1.45,47.7]],"ltp":1.28,"tv":16719.79,"id":20955040},{"batb":[[0,4,2.93],[1,3.75,40.35],[2,3.4,3.76]],"ltp":4.3,"tv":3272.65,"id":9625551}]}]}
{"op":"mcm","clk":"4234785925","pt":1631549885257,"mc":[{"id":"1.187562121","rc":[{"batl":[[0,1.29,129.4],[1,1.31,78.5],[2,1.33,85.5]],"ltp":1.28,"tv":16719.79,"id":20955040},{"batb":[[0,4.2,2.52],[1,4,2.93],[2,3.75,40.35]],"ltp":4.3,"tv":3272.65,"id":9625551}]}]}
{"op":"mcm","clk":"4234786283","pt":1631549889888,"mc":[{"id":"1.187562121","rc":[{"batb":[[0,1.21,116.69],[1,1.19,145.71],[2,1.17,216.58]],"ltp":1.28,"tv":16719.79,"id":20955040},{"batl":[[0,5.8,2.02],[1,6.4,2],[2,990,0.01]],"ltp":4.3,"tv":3272.65,"id":9625551}]}]}
{"op":"mcm","clk":"4234786301","pt":1631549890100,"mc":[{"id":"1.187562121","rc":[{"batb":[[0,1.19,145.71],[1,1.17,216.58],[2,1.01,107.79]],"ltp":1.28,"tv":16719.79,"id":20955040},{"batl":[[0,6.4,2],[1,990,0.01],[2,990,0]],"ltp":4.3,"tv":3272.65,"id":9625551}]}]}
{"op":"mcm","clk":"4234786489","pt":1631549892813,"mc":[{"id":"1.187562121","rc":[{"batl":[[0,1.33,85.5],[1,1.41,65.5],[2,1.45,47.7]],"ltp":1.28,"tv":16719.79,"id":20955040},{"batb":[[0,4,2.93],[1,3.75,40.35],[2,3.4,3.76]],"ltp":4.3,"tv":3272.65,"id":9625551}]}]}
{"op":"mcm","clk":"4234786536","pt":1631549893284,"mc":[{"id":"1.187562121","rc":[{"batb":[[0,1.21,109.69],[1,1.19,145.71],[2,1.17,216.58]],"ltp":1.28,"tv":16719.79,"id":20955040},{"batl":[[0,5.8,2.02],[1,6.4,2],[2,990,0.01]],"ltp":4.3,"tv":3272.65,"id":9625551}]}]}
{"op":"mcm","clk":"4234786640","pt":1631549894707,"mc":[{"id":"1.187562121","rc":[{"batb":[[0,1.3,16.36],[1,1.29,713.7],[2,1.27,46.53]],"batl":[[0,1.32,27.18],[1,1.33,85.5],[2,1.38,42.82]],"ltp":1.28,"tv":16719.79,"id":20955040},{"batb":[[1,3.9,229.19],[2,3.75,40.35]],"batl":[[0,4.4,47.74],[1,4.5,12.22],[2,4.6,10.22]],"ltp":4.3,"tv":3272.65,"id":9625551}]}]}
{"op":"mcm","clk":"4234786732","pt":1631549895800,"mc":[{"id":"1.187562121","rc":[{"batb":[[2,1.27,176.96]],"batl":[[2,1.35,7.41]],"ltp":1.28,"tv":16719.79,"id":20955040}]}]}
{"op":"mcm","clk":"4234787314","pt":1631549903085,"mc":[{"id":"1.187562121","rc":[{"trd":[[1.3,172.37]],"batb":[[0,1.3,16.28]],"ltp":1.3,"tv":16719.95,"id":20955040}],"tv":19992.6}]}
{"op":"mcm","clk":"4234787926","pt":1631549909694,"mc":[{"id":"1.187562121","rc":[{"batb":[[0,1.27,130.43],[1,1.23,104.63],[2,1.2,303.47]],"batl":[[0,1.46,50.25],[1,1.47,54.5],[2,1.51,55.5]],"ltp":1.3,"tv":16719.95,"id":20955040},{"batb":[[0,3.75,40.35],[1,3.15,4.03],[2,3.1,3.64]],"batl":[[0,5.4,2.04],[1,6,2.01],[2,6.4,2]],"ltp":4.3,"tv":3272.65,"id":9625551}]}]}
{"op":"mcm","clk":"4234787997","pt":1631549910535,"mc":[{"id":"1.187562121","rc":[{"batb":[[0,1.2,303.47],[1,1.19,145.71],[2,1.01,107.79]],"batl":[[0,1.51,55.5],[1,3.8,27.43],[2,8.8,7.22]],"ltp":1.3,"tv":16719.95,"id":20955040},{"batb":[[0,3,35.23],[1,2.96,3.88],[2,1.46,3.41]],"batl":[[0,6,2.01],[1,6.4,2],[2,990,0.01]],"ltp":4.3,"tv":3272.65,"id":9625551}]}]}
{"op":"mcm","clk":"4234788133","pt":1631549911995,"mc":[{"id":"1.187562121","rc":[{"batl":[[0,1.3,1.8],[1,1.51,55.5],[2,3.8,27.43]],"ltp":1.3,"tv":16719.95,"id":20955040}]}]}
{"op":"mcm","clk":"4234788289","pt":1631549913792,"mc":[{"id":"1.187562121","rc":[{"batb":[[0,1.23,93.63],[1,1.2,303.47],[2,1.19,145.71]],"batl":[[0,1.3,7.58],[1,1.46,50.75],[2,1.51,55.5]],"ltp":1.3,"tv":16719.95,"id":20955040},{"batb":[[0,3.15,4.03],[1,3,35.23],[2,2.96,3.88]],"batl":[[0,5.4,2.04],[1,6,2.01],[2,6.4,2]],"ltp":4.3,"tv":3272.65,"id":9625551}]}]}
{"op":"mcm","clk":"4234788324","pt":1631549914267,"mc":[{"id":"1.187562121","rc":[{"batb":[[0,1.2,303.47],[1,1.19,145.71],[2,1.01,107.79]],"batl":[[1,1.51,55.5],[2,3.8,27.43]],"ltp":1.3,"tv":16719.95,"id":20955040},{"batb":[[0,3,35.23],[1,2.96,3.88],[2,1.46,3.41]],"batl":[[0,4.4,5.55]],"ltp":4.3,"tv":3272.65,"id":9625551}]}]}
{"op":"mcm","clk":"4234788426","pt":1631549915426,"mc":[{"id":"1.187562121","rc":[{"batl":[[0,1.3,1.8]],"ltp":1.3,"tv":16719.95,"id":20955040}]}]}
{"op":"mcm","clk":"4234788549","pt":1631549916423,"mc":[{"id":"1.187562121","rc":[{"batl":[[0,1.51,55.5],[1,3.8,27.43],[2,8.8,7.22]],"ltp":1.3,"tv":16719.95,"id":20955040}]}]}
{"op":"mcm","clk":"4234788978","pt":1631549920835,"mc":[{"id":"1.187562121","rc":[{"batb":[[0,1.23,100.63],[1,1.2,303.47],[2,1.19,145.71]],"batl":[[0,1.46,48.25],[1,1.51,55.5],[2,3.8,27.43]],"ltp":1.3,"tv":16719.95,"id":20955040},{"batb":[[0,3.15,3.63],[1,3,35.23],[2,2.96,3.88]],"batl":[[0,5.4,2.04]],"ltp":4.3,"tv":3272.65,"id":9625551}]}]}
{"op":"mcm","clk":"4234789005","pt":1631549921128,"mc":[{"id":"1.187562121","rc":[{"batb":[[0,1.2,303.47],[1,1.19,145.71],[2,1.01,107.79]],"batl":[[0,1.51,55.5],[1,3.8,27.43],[2,8.8,7.22]],"ltp":1.3,"tv":16719.95,"id":20955040},{"batb":[[0,3,35.23],[1,2.96,3.88],[2,1.46,3.41]],"batl":[[0,6,2.01],[1,6.4,2],[2,990,0.01]],"ltp":4.3,"tv":3272.65,"id":9625551}]}]}
{"op":"mcm","clk":"4234789612","pt":1631549927913,"mc":[{"id":"1.187562121","rc":[{"batb":[[0,1.23,101.63],[1,1.2,303.47],[2,1.19,145.71]],"batl":[[0,1.46,50.75],[1,1.51,55.5],[2,3.8,27.43]],"ltp":1.3,"tv":16719.95,"id":20955040},{"batb":[[0,3.15,3.83],[1,3,35.23],[2,2.96,3.88]],"batl":[[0,5.4,2.04],[1,6,2.01],[2,6.4,2]],"ltp":4.3,"tv":3272.65,"id":9625551}]}]}
{"op":"mcm","clk":"4234789638","pt":1631549928225,"mc":[{"id":"1.187562121","rc":[{"batb":[[0,1.2,303.47],[1,1.19,145.71],[2,1.01,107.79]],"batl":[[0,1.51,55.5],[1,3.8,27.43],[2,8.8,7.22]],"ltp":1.3,"tv":16719.95,"id":20955040},{"batb":[[0,3,35.23],[1,2.96,3.88],[2,1.46,3.41]],"batl":[[0,6,2.01],[1,6.4,2],[2,990,0.01]],"ltp":4.3,"tv":3272.65,"id":9625551}]}]}
{"op":"mcm","clk":"4234789906","pt":1631549930740,"mc":[{"id":"1.187562121","rc":[{"trd":[[3,27.36]],"batb":[[0,3,31.07]],"ltp":3.0,"tv":3280.97,"id":9625551}],"tv":20000.92}]}
{"op":"mcm","clk":"4234790159","pt":1631549933329,"mc":[{"id":"1.187562121","rc":[{"batb":[[0,1.2,352.71],[2,1.18,25.04]],"batl":[[0,1.25,11.51],[1,1.28,7.81],[2,1.31,45.11]],"ltp":1.3,"tv":16719.95,"id":20955040},{"batb":[[0,4.8,18.74],[1,4.7,9.37],[2,4.6,9.37]],"batl":[[0,5.3,6.83],[1,5.5,250.87],[2,6,2.01]],"ltp":3.0,"tv":3280.97,"id":9625551}]}]}
{"op":"mcm","clk":"4234790293","pt":1631549934425,"mc":[{"id":"1.187562121","rc":[{"batb":[[0,1.21,8.26],[1,1.2,352.71],[2,1.19,145.71]],"ltp":1.3,"tv":16719.95,"id":20955040}]}]}
{"op":"mcm","clk":"4234790745","pt":1631549939461,"mc":[{"id":"1.187562121","rc":[{"batl":[[0,1.25,145.05]],"ltp":1.3,"tv":16719.95,"id":20955040}]}]}
{"op":"mcm","clk":"4234790805","pt":1631549940148,"mc":[{"id":"1.187562121","rc":[{"batl":[[2,1.31,126.61]],"ltp":1.3,"tv":16719.95,"id":20955040}]}]}
{"op":"mcm","clk":"4234791269","pt":1631549945366,"mc":[{"id":"1.187562121","rc":[{"trd":[[1.25,328.54]],"batl":[[0,1.25,144.98]],"ltp":1.25,"tv":16720.02,"id":20955040},{"trd":[[5,234.24]],"ltp":5.0,"tv":3280.98,"id":9625551}],"tv":20001.01}]}
{"op":"mcm","clk":"4234791595","pt":1631549948856,"mc":[{"id":"1.187562121","rc":[{"batb":[[0,1.2,303.47],[1,1.19,145.71],[2,1.17,147.97]],"batl":[[0,1.25,133.54],[1,1.31,81.5],[2,1.34,78.75]],"ltp":1.25,"tv":16720.02,"id":20955040},{"batb":[[0,4.5,25.5],[1,4.2,2.42],[2,3.9,2.86]],"batl":[[0,6,2.01],[1,6.4,2],[2,7,2]],"ltp":5.0,"tv":3280.98,"id":9625551}]}]}
{"op":"mcm","clk":"4234791639","pt":1631549949279,"mc":[{"id":"1.187562121","rc":[{"batb":[[0,1.17,147.97],[1,1.16,223.37],[2,1.01,107.79]],"ltp":1.25,"tv":16720.02,"id":20955040},{"batb":[[0,4.2,2.42],[1,3.9,2.86],[2,3.7,41.52]],"batl":[[0,7,2],[1,990,0.01],[2,7,0]],"ltp":5.0,"tv":3280.98,"id":9625551}]}]}
{"op":"mcm","clk":"4234792734","pt":1631549959364,"mc":[{"id":"1.187562121","rc":[{"batb":[[0,1.19,111.71],[1,1.17,147.97],[2,1.16,223.37]],"ltp":1.25,"tv":16720.02,"id":20955040},{"batl":[[0,6.4,2],[1,7,2],[2,990,0.01]],"ltp":5.0,"tv":3280.98,"id":9625551}]}]}
{"op":"mcm","clk":"4234792888","pt":1631549960773,"mc":[{"id":"1.187562121","rc":[{"batb":[[0,1.17,147.97],[1,1.16,223.37],[2,1.01,107.79]],"ltp":1.25,"tv":16720.02,"id":20955040},{"batl":[[0,7,2],[1,990,0.01],[2,990,0]],"ltp":5.0,"tv":3280.98,"id":9625551}]}]}
{"op":"mcm","clk":"4234793182","pt":1631549963803,"mc":[{"id":"1.187562121","rc":[{"batl":[[0,1.26,18.75],[1,1.34,78.75],[2,1.51,55.5]],"ltp":1.25,"tv":16720.02,"id":20955040},{"batb":[[0,4.8,19.38]],"batl":[[0,5.2,20.13],[1,7,2],[2,990,0.01]],"ltp":5.0,"tv":3280.98,"id":9625551}]}]}
{"op":"mcm","clk":"4234793247","pt":1631549964483,"mc":[{"id":"1.187562121","rc":[{"batl":[[0,1.34,78.75],[1,1.51,55.5],[2,3.8,27.43]],"ltp":1.25,"tv":16720.02,"id":20955040},{"batb":[[0,3.9,2.86],[1,3.7,41.52],[2,2.96,3.88]],"batl":[[0,7,2],[1,990,0.01],[2,990,0]],"ltp":5.0,"tv":3280.98,"id":9625551}]}]}
{"op":"mcm","clk":"4234793573","pt":1631549967660,"mc":[{"id":"1.187562121","rc":[{"batb":[[0,1.19,115.71],[1,1.17,147.97],[2,1.16,223.37]],"ltp":1.25,"tv":16720.02,"id":20955040},{"batl":[[0,6.4,2.04],[1,7,2],[2,990,0.01]],"ltp":5.0,"tv":3280.98,"id":9625551}]}]}
{"op":"mcm","clk":"4234793604","pt":1631549968022,"mc":[{"id":"1.187562121","rc":[{"batb":[[0,1.17,147.97],[1,1.16,223.37],[2,1.01,107.79]],"batl":[[0,1.27,131.44],[1,1.34,78.75],[2,1.51,55.5]],"ltp":1.25,"tv":16720.02,"id":20955040},{"batl":[[0,7,2],[1,990,0.01],[2,990,0]],"ltp":5.0,"tv":3280.98,"id":9625551}]}]}
{"op":"mcm","clk":"4234793791","pt":1631549970216,"mc":[{"id":"1.187562121","rc":[{"batl":[[1,1.31,84.5],[2,1.34,78.75]],"ltp":1.25,"tv":16720.02,"id":20955040},{"batb":[[0,4.2,2.57],[1,3.9,2.86],[2,3.7,41.52]],"ltp":5.0,"tv":3280.98,"id":9625551}]}]}
{"op":"mcm","clk":"4234794052","pt":1631549972773,"mc":[{"id":"1.187562121","rc":[{"batl":[[0,1.34,78.75],[1,1.51,55.5],[2,3.8,27.43]],"ltp":1.25,"tv":16720.02,"id":20955040},{"batb":[[0,3.9,2.86],[1,3.7,41.52],[2,2.96,3.88]],"ltp":5.0,"tv":3280.98,"id":9625551}]}]}
{"op":"mcm","clk":"4234794233","pt":1631549974601,"mc":[{"id":"1.187562121","rc":[{"batb":[[0,1.29,72.58],[1,1.28,34.88],[2,1.27,81.41]],"batl":[[0,1.32,15.77],[1,1.34,78.75],[2,1.36,955.76]],"ltp":1.25,"tv":16720.02,"id":20955040},{"batl":[[0,4.3,34.36],[1,4.5,2],[2,4.6,2.17]],"ltp":5.0,"tv":3280.98,"id":9625551}]}]}
{"op":"mcm","clk":"4234794323","pt":1631549975487,"mc":[{"id":"1.187562121","rc":[{"batb":[[2,1.27,208.82]],"batl":[[2,1.35,7.41]],"ltp":1.25,"tv":16720.02,"id":20955040},{"batb":[[2,2.98,36.91]],"ltp":5.0,"tv":3280.98,"id":9625551}]}]}
{"op":"mcm","clk":"4234794859","pt":1631549981295,"mc":[{"id":"1.187562121","rc":[{"batb":[[2,3.1,4.24]],"ltp":5.0,"tv":3280.98,"id":9625551}]}]}
{"op":"mcm","clk":"4234794919","pt":1631549982026,"mc":[{"id":"1.187562121","rc":[{"trd":[[1.3,178.15]],"ltp":1.3,"tv":16725.79,"id":20955040},{"trd":[[4.3,67.37]],"batl":[[0,4.3,32.61]],"ltp":4.3,"tv":3282.73,"id":9625551}],"tv":20008.53}]}
{"op":"mcm","clk":"4234795004","pt":1631549983119,"mc":[{"id":"1.187562121","rc":[{"trd":[[4.3,67.41]],"batl":[[0,4.3,32.59]],"ltp":4.3,"tv":3282.77,"id":9625551}],"tv":20008.57}]}
