{"op":"mcm","clk":"4229490599","pt":1631518387105,"mc":[{"id":"1.187594322","marketDefinition":{"bspMarket":false,"turnInPlayEnabled":true,"persistenceEnabled":true,"marketBaseRate":5.0,"eventId":"30897917","eventTypeId":"2","numberOfWinners":1,"bettingType":"ODDS","marketType":"MATCH_ODDS","marketTime":"2021-09-13T07:30:00.000Z","suspendTime":"2021-09-13T07:30:00.000Z","bspReconciled":false,"complete":true,"inPlay":false,"crossMatching":false,"runnersVoidable":false,"numberOfActiveRunners":2,"betDelay":0,"status":"OPEN","runners":[{"status":"ACTIVE","sortPriority":1,"id":7429606,"name":"E Bogdan"},{"status":"ACTIVE","sortPriority":2,"id":9628072,"name":"A Moratelli"}],"regulators":["MR_INT"],"countryCode":"GB","discountAllowed":false,"timezone":"GMT","openDate":"2021-09-13T10:30:00.000Z","version":4030164803,"name":"Match Odds","eventName":"E Bogdan v A Moratelli"},"rc":[{"batb":[[0,1.01,25]],"ltp":0.0,"tv":0.0,"id":7429606},{"batb":[[0,1.01,25]],"ltp":0.0,"tv":0.0,"id":9628072}]}]}
{"op":"mcm","clk":"4229490648","pt":1631518388646,"mc":[{"id":"1.187594322","marketDefinition":{"bspMarket":false,"turnInPlayEnabled":true,"persistenceEnabled":true,"marketBaseRate":5.0,"eventId":"30897917","eventTypeId":"2","numberOfWinners":1,"bettingType":"ODDS","marketType":"MATCH_ODDS","marketTime":"2021-09-13T07:30:00.000Z","suspendTime":"2021-09-13T07:30:00.000Z","bspReconciled":false,"complete":true,"inPlay":false,"crossMatching":false,"runnersVoidable":false,"numberOfActiveRunners":2,"betDelay":0,"status":"OPEN","runners":[{"status":"ACTIVE","sortPriority":1,"id":7429606,"name":"E Bogdan"},{"status":"ACTIVE","sortPriority":2,"id":9628072,"name":"A Moratelli"}],"regulators":["MR_INT"],"countryCode":"GB","discountAllowed":true,"timezone":"GMT","openDate":"2021-09-13T10:30:00.000Z","version":4030164803,"name":"Match Odds","eventName":"E Bogdan v A Moratelli"}}]}
{"op":"mcm","clk":"4229517266","pt":1631519122776,"mc":[{"id":"1.187594322","rc":[{"batb":[[0,1.01,7]],"ltp":0.0,"tv":0.0,"id":7429606},{"batb":[[0,1.01,7]],"ltp":0.0,"tv":0.0,"id":9628072}]}]}
{"op":"mcm","clk":"4229523514","pt":1631519303658,"mc":[{"id":"1.187594322","rc":[{"batb":[[0,1.05,880.88],[1,1.01,7]],"ltp":0.0,"tv":0.0,"id":7429606},{"batb":[[0,1.05,880.88],[1,1.01,7]],"ltp":0.0,"tv":0.0,"id":9628072}]}]}
{"op":"mcm","clk":"4229676569","pt":1631522398937,"mc":[{"id":"1.187594322","rc":[{"batl":[[0,2.16,2.66]],"ltp":0.0,"tv":0.0,"id":9628072}]}]}
{"op":"mcm","clk":"4229676855","pt":1631522405128,"mc":[{"id":"1.187594322","rc":[{"batb":[[0,1.16,15.97],[1,1.05,880.88],[2,1.01,7]],"ltp":0.0,"tv":0.0,"id":9628072}]}]}
{"op":"mcm","clk":"4229678582","pt":1631522446893,"mc":[{"id":"1.187594322","rc":[{"batl":[[0,1.67,10.53],[1,2.16,2.66]],"ltp":0.0,"tv":0.0,"id":9628072}]}]}
{"op":"mcm","clk":"4229679922","pt":1631522482794,"mc":[{"id":"1.187594322","marketDefinition":{"bspMarket":false,"turnInPlayEnabled":true,"persistenceEnabled":true,"marketBaseRate":5.0,"eventId":"30897917","eventTypeId":"2","numberOfWinners":1,"bettingType":"ODDS","marketType":"MATCH_ODDS","marketTime":"2021-09-13T07:30:00.000Z","suspendTime":"2021-09-13T07:30:00.000Z","bspReconciled":false,"complete":true,"inPlay":false,"crossMatching":true,"runnersVoidable":false,"numberOfActiveRunners":2,"betDelay":0,"status":"OPEN","runners":[{"status":"ACTIVE","sortPriority":1,"id":7429606,"name":"E Bogdan"},{"status":"ACTIVE","sortPriority":2,"id":9628072,"name":"A Moratelli"}],"regulators":["MR_INT"],"countryCode":"GB","discountAllowed":true,"timezone":"GMT","openDate":"2021-09-13T10:30:00.000Z","version":4030164803,"name":"Match Odds","eventName":"E Bogdan v A Moratelli"}}]}
{"op":"mcm","clk":"4229687928","pt":1631522656740,"mc":[{"id":"1.187594322","rc":[{"batb":[[1,1.01,7],[2,1.01,0]],"ltp":0.0,"tv":0.0,"id":9628072}]}]}
{"op":"mcm","clk":"4229688270","pt":1631522663617,"mc":[{"id":"1.187594322","rc":[{"batb":[[0,1.18,246.65],[1,1.16,15.97],[2,1.01,7]],"ltp":0.0,"tv":0.0,"id":9628072}]}]}
{"op":"mcm","clk":"4229693157","pt":1631522762129,"mc":[{"id":"1.187594322","marketDefinition":{"bspMarket":false,"turnInPlayEnabled":true,"persistenceEnabled":true,"marketBaseRate":5.0,"eventId":"30897917","eventTypeId":"2","numberOfWinners":1,"bettingType":"ODDS","marketType":"MATCH_ODDS","marketTime":"2021-09-13T12:30:00.000Z","suspendTime":"2021-09-13T12:30:00.000Z","bspReconciled":false,"complete":true,"inPlay":false,"crossMatching":true,"runnersVoidable":false,"numberOfActiveRunners":2,"betDelay":0,"status":"OPEN","runners":[{"status":"ACTIVE","sortPriority":1,"id":7429606,"name":"E Bogdan"},{"status":"ACTIVE","sortPriority":2,"id":9628072,"name":"A Moratelli"}],"regulators":["MR_INT"],"countryCode":"GB","discountAllowed":true,"timezone":"GMT","openDate":"2021-09-13T10:30:00.000Z","version":4030340778,"name":"Match Odds","eventName":"E Bogdan v A Moratelli"}}]}
{"op":"mcm","clk":"4229693273","pt":1631522764138,"mc":[{"id":"1.187594322","marketDefinition":{"bspMarket":false,"turnInPlayEnabled":true,"persistenceEnabled":true,"marketBaseRate":5.0,"eventId":"30897917","eventTypeId":"2","numberOfWinners":1,"bettingType":"ODDS","marketType":"MATCH_ODDS","marketTime":"2021-09-13T12:30:00.000Z","suspendTime":"2021-09-13T12:30:00.000Z","bspReconciled":false,"complete":true,"inPlay":false,"crossMatching":true,"runnersVoidable":false,"numberOfActiveRunners":2,"betDelay":0,"status":"OPEN","runners":[{"status":"ACTIVE","sortPriority":1,"id":7429606,"name":"E Bogdan"},{"status":"ACTIVE","sortPriority":2,"id":9628072,"name":"A Moratelli"}],"regulators":["MR_INT"],"countryCode":"GB","discountAllowed":true,"timezone":"GMT","openDate":"2021-09-13T12:30:00.000Z","version":4030340778,"name":"Match Odds","eventName":"E Bogdan v A Moratelli"}}]}
{"op":"mcm","clk":"4229743013","pt":1631523785914,"mc":[{"id":"1.187594322","rc":[{"batb":[[0,2.24,25.26],[1,1.05,880.36],[2,1.01,7]],"ltp":0.0,"tv":0.0,"id":7429606},{"batb":[[0,1.57,54.95],[1,1.18,246.5],[2,1.16,15.98]],"batl":[[1,2.16,2.66]],"ltp":0.0,"tv":0.0,"id":9628072}]}]}
{"op":"mcm","clk":"4229759969","pt":1631524083839,"mc":[{"id":"1.187594322","rc":[{"batb":[[1,1.01,7],[2,1.01,0]],"ltp":0.0,"tv":0.0,"id":7429606}]}]}
{"op":"mcm","clk":"4229760338","pt":1631524089811,"mc":[{"id":"1.187594322","rc":[{"batl":[[2,2.4,44.02]],"ltp":0.0,"tv":0.0,"id":9628072}]}]}
{"op":"mcm","clk":"4229776905","pt":1631524351772,"mc":[{"id":"1.187594322","rc":[{"batl":[[0,990,2.2]],"ltp":0.0,"tv":0.0,"id":7429606}]}]}
{"op":"mcm","clk":"4229829314","pt":1631525273289,"mc":[{"id":"1.187594322","rc":[{"batb":[[0,1.64,3],[1,1.57,54.95],[2,1.18,246.5]],"ltp":0.0,"tv":0.0,"id":9628072}]}]}
{"op":"mcm","clk":"4229832124","pt":1631525327799,"mc":[{"id":"1.187594322","rc":[{"batb":[[0,1.57,54.95],[1,1.18,246.5],[2,1.16,15.98]],"ltp":0.0,"tv":0.0,"id":9628072}]}]}
{"op":"mcm","clk":"4229832545","pt":1631525337207,"mc":[{"id":"1.187594322","rc":[{"batl":[[0,1.59,3],[1,1.67,10.53],[2,2.16,2.66]],"ltp":0.0,"tv":0.0,"id":9628072}]}]}
{"op":"mcm","clk":"4229834666","pt":1631525378828,"mc":[{"id":"1.187594322","rc":[{"batl":[[0,1.67,10.53],[1,2.16,2.66],[2,2.4,44.02]],"ltp":0.0,"tv":0.0,"id":9628072}]}]}
{"op":"mcm","clk":"4229835449","pt":1631525394886,"mc":[{"id":"1.187594322","rc":[{"trd":[[1.66,6]],"ltp":1.66,"tv":6.0,"id":9628072}],"tv":6.0}]}
{"op":"mcm","clk":"4229836853","pt":1631525418590,"mc":[{"id":"1.187594322","rc":[{"batb":[[0,1.64,3],[1,1.57,54.95],[2,1.18,246.5]],"ltp":1.66,"tv":6.0,"id":9628072}]}]}
{"op":"mcm","clk":"4229840516","pt":1631525486369,"mc":[{"id":"1.187594322","rc":[{"batl":[[0,3.9,2.21],[1,990,2.2]],"ltp":0.0,"tv":0.0,"id":7429606}]}]}
{"op":"mcm","clk":"4229852112","pt":1631525653745,"mc":[{"id":"1.187594322","rc":[{"batb":[[2,1.16,15.98]],"ltp":1.66,"tv":6.0,"id":9628072}]}]}
{"op":"mcm","clk":"4229853159","pt":1631525663618,"mc":[{"id":"1.187594322","rc":[{"batb":[[2,1.28,158.46]],"ltp":1.66,"tv":6.0,"id":9628072}]}]}
{"op":"mcm","clk":"4229854298","pt":1631525681360,"mc":[{"id":"1.187594322","rc":[{"batb":[[0,1.57,54.95],[1,1.28,158.46],[2,1.16,15.98]],"ltp":1.66,"tv":6.0,"id":9628072}]}]}
{"op":"mcm","clk":"4229855665","pt":1631525703378,"mc":[{"id":"1.187594322","rc":[{"batl":[[0,1.6,3],[1,1.67,10.53],[2,2.16,2.66]],"ltp":1.66,"tv":6.0,"id":9628072}]}]}
{"op":"mcm","clk":"4229871555","pt":1631525934141,"mc":[{"id":"1.187594322","rc":[{"batl":[[0,1.67,10.53],[1,2.16,2.66],[2,2.4,44.02]],"ltp":1.66,"tv":6.0,"id":9628072}]}]}
{"op":"mcm","clk":"4229872149","pt":1631525942745,"mc":[{"id":"1.187594322","rc":[{"batb":[[0,1.61,12],[1,1.57,54.95],[2,1.28,158.46]],"ltp":1.66,"tv":6.0,"id":9628072}]}]}
{"op":"mcm","clk":"4229873526","pt":1631525964603,"mc":[{"id":"1.187594322","rc":[{"batb":[[0,1.63,4],[1,1.61,12],[2,1.57,54.95]],"ltp":1.66,"tv":6.0,"id":9628072}]}]}
{"op":"mcm","clk":"4229873714","pt":1631525967194,"mc":[{"id":"1.187594322","rc":[{"batl":[[0,990,2.2],[1,990,0]],"ltp":0.0,"tv":0.0,"id":7429606}]}]}
{"op":"mcm","clk":"4229873845","pt":1631525969416,"mc":[{"id":"1.187594322","rc":[{"batb":[[1,1.57,54.95],[2,1.28,158.46]],"ltp":1.66,"tv":6.0,"id":9628072}]}]}
{"op":"mcm","clk":"4229874389","pt":1631525977514,"mc":[{"id":"1.187594322","rc":[{"trd":[[1.66,12]],"ltp":1.66,"tv":12.0,"id":9628072}],"tv":12.0}]}
{"op":"mcm","clk":"4229874509","pt":1631525979533,"mc":[{"id":"1.187594322","rc":[{"batb":[[0,1.66,3],[1,1.63,4],[2,1.57,54.95]],"ltp":1.66,"tv":12.0,"id":9628072}]}]}
{"op":"mcm","clk":"4229881562","pt":1631526086382,"mc":[{"id":"1.187594322","rc":[{"batl":[[0,3.9,17.74],[1,990,2.2]],"ltp":0.0,"tv":0.0,"id":7429606}]}]}
{"op":"mcm","clk":"4229892227","pt":1631526207620,"mc":[{"id":"1.187594322","marketDefinition":{"bspMarket":false,"turnInPlayEnabled":true,"persistenceEnabled":true,"marketBaseRate":5.0,"eventId":"30897917","eventTypeId":"2","numberOfWinners":1,"bettingType":"ODDS","marketType":"MATCH_ODDS","marketTime":"2021-09-13T12:45:00.000Z","suspendTime":"2021-09-13T12:45:00.000Z","bspReconciled":false,"complete":true,"inPlay":false,"crossMatching":true,"runnersVoidable":false,"numberOfActiveRunners":2,"betDelay":0,"status":"OPEN","runners":[{"status":"ACTIVE","sortPriority":1,"id":7429606,"name":"E Bogdan"},{"status":"ACTIVE","sortPriority":2,"id":9628072,"name":"A Moratelli"}],"regulators":["MR_INT"],"countryCode":"GB","discountAllowed":true,"timezone":"GMT","openDate":"2021-09-13T12:30:00.000Z","version":4030512634,"name":"Match Odds","eventName":"E Bogdan v A Moratelli"}}]}
{"op":"mcm","clk":"4229892307","pt":1631526208624,"mc":[{"id":"1.187594322","marketDefinition":{"bspMarket":false,"turnInPlayEnabled":true,"persistenceEnabled":true,"marketBaseRate":5.0,"eventId":"30897917","eventTypeId":"2","numberOfWinners":1,"bettingType":"ODDS","marketType":"MATCH_ODDS","marketTime":"2021-09-13T12:45:00.000Z","suspendTime":"2021-09-13T12:45:00.000Z","bspReconciled":false,"complete":true,"inPlay":false,"crossMatching":true,"runnersVoidable":false,"numberOfActiveRunners":2,"betDelay":0,"status":"OPEN","runners":[{"status":"ACTIVE","sortPriority":1,"id":7429606,"name":"E Bogdan"},{"status":"ACTIVE","sortPriority":2,"id":9628072,"name":"A Moratelli"}],"regulators":["MR_INT"],"countryCode":"GB","discountAllowed":true,"timezone":"GMT","openDate":"2021-09-13T12:45:00.000Z","version":4030512634,"name":"Match Odds","eventName":"E Bogdan v A Moratelli"}}]}
{"op":"mcm","clk":"4229892331","pt":1631526208872,"mc":[{"id":"1.187594322","rc":[{"batl":[[0,990,2.2],[1,990,0]],"ltp":0.0,"tv":0.0,"id":7429606}]}]}
{"op":"mcm","clk":"4229903609","pt":1631526386588,"mc":[{"id":"1.187594322","rc":[{"batb":[[0,2.26,4.71],[1,2.24,25.26],[2,1.01,7]],"batl":[[0,4.1,5.43],[1,990,2.2]],"ltp":0.0,"tv":0.0,"id":7429606}]}]}
{"op":"mcm","clk":"4229903621","pt":1631526386793,"mc":[{"id":"1.187594322","rc":[{"batb":[[0,2.24,25.26],[1,1.01,7],[2,1.01,0]],"ltp":0.0,"tv":0.0,"id":7429606}]}]}
{"op":"mcm","clk":"4229904131","pt":1631526394807,"mc":[{"id":"1.187594322","rc":[{"batb":[[0,1.63,4],[1,1.57,54.95],[2,1.28,158.46]],"ltp":1.66,"tv":12.0,"id":9628072}]}]}
{"op":"mcm","clk":"4229904690","pt":1631526403625,"mc":[{"id":"1.187594322","rc":[{"batl":[[0,1.65,5],[1,1.67,10.53],[2,2.16,2.66]],"ltp":1.66,"tv":12.0,"id":9628072}]}]}
{"op":"mcm","clk":"4229905657","pt":1631526416858,"mc":[{"id":"1.187594322","rc":[{"batb":[[0,1.57,54.95],[1,1.28,158.46],[2,1.16,15.98]],"ltp":1.66,"tv":12.0,"id":9628072}]}]}
{"op":"mcm","clk":"4229906156","pt":1631526422359,"mc":[{"id":"1.187594322","rc":[{"batl":[[0,1.59,3],[1,1.65,5],[2,1.67,10.53]],"ltp":1.66,"tv":12.0,"id":9628072}]}]}
{"op":"mcm","clk":"4229908824","pt":1631526456823,"mc":[{"id":"1.187594322","rc":[{"batb":[[0,2.28,2.46],[1,2.24,25.26],[2,1.01,7]],"ltp":0.0,"tv":0.0,"id":7429606}]}]}
{"op":"mcm","clk":"4229931201","pt":1631526676456,"mc":[{"id":"1.187594322","rc":[{"batb":[[0,1.6,1],[1,1.57,54.95],[2,1.28,158.46]],"batl":[[0,1.65,5],[1,1.67,10.53],[2,2.16,2.66]],"ltp":1.66,"tv":12.0,"id":9628072}]}]}
{"op":"mcm","clk":"4229939466","pt":1631526794149,"mc":[{"id":"1.187594322","rc":[{"batb":[[0,1.63,3],[1,1.6,1],[2,1.57,54.95]],"ltp":1.66,"tv":12.0,"id":9628072}]}]}
{"op":"mcm","clk":"4229951706","pt":1631527013025,"mc":[{"id":"1.187594322","rc":[{"batb":[[1,1.57,54.95],[2,1.28,158.46]],"ltp":1.66,"tv":12.0,"id":9628072}]}]}
{"op":"mcm","clk":"4229983126","pt":1631527466186,"mc":[{"id":"1.187594322","rc":[{"batb":[[0,1.57,54.95],[1,1.28,158.46],[2,1.16,15.98]],"ltp":1.66,"tv":12.0,"id":9628072}]}]}
{"op":"mcm","clk":"4229983650","pt":1631527473804,"mc":[{"id":"1.187594322","rc":[{"batl":[[0,1.6,3],[1,1.65,5],[2,1.67,10.53]],"ltp":1.66,"tv":12.0,"id":9628072}]}]}
{"op":"mcm","clk":"4230010788","pt":1631527851929,"mc":[{"id":"1.187594322","marketDefinition":{"bspMarket":false,"turnInPlayEnabled":true,"persistenceEnabled":true,"marketBaseRate":5.0,"eventId":"30897917","eventTypeId":"2","numberOfWinners":1,"bettingType":"ODDS","marketType":"MATCH_ODDS","marketTime":"2021-09-13T13:05:00.000Z","suspendTime":"2021-09-13T13:05:00.000Z","bspReconciled":false,"complete":true,"inPlay":false,"crossMatching":true,"runnersVoidable":false,"numberOfActiveRunners":2,"betDelay":0,"status":"OPEN","runners":[{"status":"ACTIVE","sortPriority":1,"id":7429606,"name":"E Bogdan"},{"status":"ACTIVE","sortPriority":2,"id":9628072,"name":"A Moratelli"}],"regulators":["MR_INT"],"countryCode":"GB","discountAllowed":true,"timezone":"GMT","openDate":"2021-09-13T12:45:00.000Z","version":4030529130,"name":"Match Odds","eventName":"E Bogdan v A Moratelli"}}]}
{"op":"mcm","clk":"4230010953","pt":1631527854192,"mc":[{"id":"1.187594322","marketDefinition":{"bspMarket":false,"turnInPlayEnabled":true,"persistenceEnabled":true,"marketBaseRate":5.0,"eventId":"30897917","eventTypeId":"2","numberOfWinners":1,"bettingType":"ODDS","marketType":"MATCH_ODDS","marketTime":"2021-09-13T13:05:00.000Z","suspendTime":"2021-09-13T13:05:00.000Z","bspReconciled":false,"complete":true,"inPlay":false,"crossMatching":true,"runnersVoidable":false,"numberOfActiveRunners":2,"betDelay":0,"status":"OPEN","runners":[{"status":"ACTIVE","sortPriority":1,"id":7429606,"name":"E Bogdan"},{"status":"ACTIVE","sortPriority":2,"id":9628072,"name":"A Moratelli"}],"regulators":["MR_INT"],"countryCode":"GB","discountAllowed":true,"timezone":"GMT","openDate":"2021-09-13T13:05:00.000Z","version":4030529130,"name":"Match Odds","eventName":"E Bogdan v A Moratelli"},"rc":[{"batb":[[0,2.24,25.26],[1,1.01,7],[2,1.01,0]],"batl":[[0,990,2.2],[1,990,0]],"ltp":0.0,"tv":0.0,"id":7429606}]}]}
{"op":"mcm","clk":"4230011102","pt":1631527856000,"mc":[{"id":"1.187594322","rc":[{"batb":[[0,2.26,2.48],[1,2.24,25.26],[2,1.01,7]],"batl":[[0,3.25,2.03],[1,990,2.2]],"ltp":0.0,"tv":0.0,"id":7429606}]}]}
{"op":"mcm","clk":"4230115899","pt":1631529150482,"mc":[{"id":"1.187594322","rc":[{"batb":[[0,2.24,25.26],[1,1.01,7],[2,1.01,0]],"ltp":0.0,"tv":0.0,"id":7429606},{"batl":[[0,1.59,3],[1,1.6,3],[2,1.65,5]],"ltp":1.66,"tv":12.0,"id":9628072}]}]}
{"op":"mcm","clk":"4230131728","pt":1631529355746,"mc":[{"id":"1.187594322","rc":[{"batb":[[0,2.28,11.33],[1,2.24,25.26],[2,1.01,7]],"ltp":0.0,"tv":0.0,"id":7429606}]}]}
{"op":"mcm","clk":"4230134341","pt":1631529390450,"mc":[{"id":"1.187594322","rc":[{"batb":[[0,2.24,25.26],[1,1.01,7],[2,1.01,0]],"ltp":0.0,"tv":0.0,"id":7429606},{"batl":[[0,1.6,3],[1,1.65,5],[2,1.67,10.53]],"ltp":1.66,"tv":12.0,"id":9628072}]}]}
{"op":"mcm","clk":"4230157828","pt":1631529690666,"mc":[{"id":"1.187594322","rc":[{"batb":[[0,2.32,6.83],[1,2.24,25.26],[2,1.01,7]],"ltp":0.0,"tv":0.0,"id":7429606}]}]}
{"op":"mcm","clk":"4230170539","pt":1631529848819,"mc":[{"id":"1.187594322","rc":[{"trd":[[1.57,74.89]],"batb":[[0,1.57,17.51]],"ltp":1.57,"tv":86.88,"id":9628072}],"tv":86.88}]}
{"op":"mcm","clk":"4230170918","pt":1631529854001,"mc":[{"id":"1.187594322","rc":[{"batb":[[0,1.57,54.95]],"ltp":1.57,"tv":86.88,"id":9628072}]}]}
{"op":"mcm","clk":"4230171539","pt":1631529861618,"mc":[{"id":"1.187594322","rc":[{"batl":[[1,1.65,15.53],[2,2.16,2.66]],"ltp":1.57,"tv":86.88,"id":9628072}]}]}
{"op":"mcm","clk":"4230171558","pt":1631529861817,"mc":[{"id":"1.187594322","rc":[{"batb":[[0,2.24,25.26],[1,1.01,7],[2,1.01,0]],"ltp":0.0,"tv":0.0,"id":7429606}]}]}
{"op":"mcm","clk":"4230183210","pt":1631529990718,"mc":[{"id":"1.187594322","rc":[{"batb":[[0,2.28,4.19],[1,2.24,25.26],[2,1.01,7]],"ltp":0.0,"tv":0.0,"id":7429606}]}]}
{"op":"mcm","clk":"4230193568","pt":1631530113355,"mc":[{"id":"1.187594322","rc":[{"batb":[[0,2.24,25.26],[1,1.01,7],[2,1.01,0]],"ltp":0.0,"tv":0.0,"id":7429606}]}]}
{"op":"mcm","clk":"4230208458","pt":1631530290708,"mc":[{"id":"1.187594322","rc":[{"batb":[[0,2.38,4.04],[1,2.24,25.26],[2,1.01,7]],"ltp":0.0,"tv":0.0,"id":7429606}]}]}
{"op":"mcm","clk":"4230231461","pt":1631530597290,"mc":[{"id":"1.187594322","marketDefinition":{"bspMarket":false,"turnInPlayEnabled":true,"persistenceEnabled":true,"marketBaseRate":5.0,"eventId":"30897917","eventTypeId":"2","numberOfWinners":1,"bettingType":"ODDS","marketType":"MATCH_ODDS","marketTime":"2021-09-13T12:30:00.000Z","suspendTime":"2021-09-13T12:30:00.000Z","bspReconciled":false,"complete":true,"inPlay":false,"crossMatching":true,"runnersVoidable":false,"numberOfActiveRunners":2,"betDelay":0,"status":"OPEN","runners":[{"status":"ACTIVE","sortPriority":1,"id":7429606,"name":"E Bogdan"},{"status":"ACTIVE","sortPriority":2,"id":9628072,"name":"A Moratelli"}],"regulators":["MR_INT"],"countryCode":"GB","discountAllowed":true,"timezone":"GMT","openDate":"2021-09-13T13:05:00.000Z","version":4030566529,"name":"Match Odds","eventName":"E Bogdan v A Moratelli"}}]}
{"op":"mcm","clk":"4230233299","pt":1631530622442,"mc":[{"id":"1.187594322","marketDefinition":{"bspMarket":false,"turnInPlayEnabled":true,"persistenceEnabled":true,"marketBaseRate":5.0,"eventId":"30897917","eventTypeId":"2","numberOfWinners":1,"bettingType":"ODDS","marketType":"MATCH_ODDS","marketTime":"2021-09-13T12:30:00.000Z","suspendTime":"2021-09-13T12:30:00.000Z","bspReconciled":false,"complete":true,"inPlay":false,"crossMatching":true,"runnersVoidable":false,"numberOfActiveRunners":2,"betDelay":0,"status":"OPEN","runners":[{"status":"ACTIVE","sortPriority":1,"id":7429606,"name":"E Bogdan"},{"status":"ACTIVE","sortPriority":2,"id":9628072,"name":"A Moratelli"}],"regulators":["MR_INT"],"countryCode":"GB","discountAllowed":true,"timezone":"GMT","openDate":"2021-09-13T12:30:00.000Z","version":4030566529,"name":"Match Odds","eventName":"E Bogdan v A Moratelli"}}]}
{"op":"mcm","clk":"4230233339","pt":1631530622892,"mc":[{"id":"1.187594322","rc":[{"batb":[[0,2.32,3.5]],"batl":[[0,3.6,2.98]],"ltp":0.0,"tv":0.0,"id":7429606}]}]}
{"op":"mcm","clk":"4230233673","pt":1631530627308,"mc":[{"id":"1.187594322","rc":[{"batb":[[1,2.24,33.68]],"ltp":0.0,"tv":0.0,"id":7429606},{"batb":[[0,1.57,73.27]],"ltp":1.57,"tv":86.88,"id":9628072}]}]}
{"op":"mcm","clk":"4230317067","pt":1631531630828,"mc":[{"id":"1.187594322","marketDefinition":{"bspMarket":false,"turnInPlayEnabled":true,"persistenceEnabled":true,"marketBaseRate":5.0,"eventId":"30897917","eventTypeId":"2","numberOfWinners":1,"bettingType":"ODDS","marketType":"MATCH_ODDS","marketTime":"2021-09-13T12:40:00.000Z","suspendTime":"2021-09-13T12:40:00.000Z","bspReconciled":false,"complete":true,"inPlay":false,"crossMatching":true,"runnersVoidable":false,"numberOfActiveRunners":2,"betDelay":0,"status":"OPEN","runners":[{"status":"ACTIVE","sortPriority":1,"id":7429606,"name":"E Bogdan"},{"status":"ACTIVE","sortPriority":2,"id":9628072,"name":"A Moratelli"}],"regulators":["MR_INT"],"countryCode":"GB","discountAllowed":true,"timezone":"GMT","openDate":"2021-09-13T12:30:00.000Z","version":4030580891,"name":"Match Odds","eventName":"E Bogdan v A Moratelli"}}]}
{"op":"mcm","clk":"4230317327","pt":1631531634100,"mc":[{"id":"1.187594322","marketDefinition":{"bspMarket":false,"turnInPlayEnabled":true,"persistenceEnabled":true,"marketBaseRate":5.0,"eventId":"30897917","eventTypeId":"2","numberOfWinners":1,"bettingType":"ODDS","marketType":"MATCH_ODDS","marketTime":"2021-09-13T12:40:00.000Z","suspendTime":"2021-09-13T12:40:00.000Z","bspReconciled":false,"complete":true,"inPlay":false,"crossMatching":true,"runnersVoidable":false,"numberOfActiveRunners":2,"betDelay":0,"status":"OPEN","runners":[{"status":"ACTIVE","sortPriority":1,"id":7429606,"name":"E Bogdan"},{"status":"ACTIVE","sortPriority":2,"id":9628072,"name":"A Moratelli"}],"regulators":["MR_INT"],"countryCode":"GB","discountAllowed":true,"timezone":"GMT","openDate":"2021-09-13T12:40:00.000Z","version":4030580891,"name":"Match Odds","eventName":"E Bogdan v A Moratelli"},"rc":[{"batb":[[0,2.24,33.68],[1,1.01,7],[2,1.01,0]],"batl":[[0,990,2.2],[1,990,0]],"ltp":0.0,"tv":0.0,"id":7429606},{"trd":[[1.57,74.82]],"batb":[[1,1.28,158.31],[2,1.16,15.95]],"batl":[[1,1.65,15.51],[2,2.16,2.66]],"ltp":1.57,"tv":86.82,"id":9628072}],"tv":86.82}]}
{"op":"mcm","clk":"4230317599","pt":1631531637693,"mc":[{"id":"1.187594322","rc":[{"batb":[[0,2.3,3.54],[1,2.24,33.68],[2,1.01,7]],"batl":[[0,3.95,2.72],[1,990,2.2]],"ltp":0.0,"tv":0.0,"id":7429606}]}]}
{"op":"mcm","clk":"4230447003","pt":1631533096288,"mc":[{"id":"1.187594322","rc":[{"batb":[[0,2.24,33.68],[1,1.01,7],[2,1.01,0]],"batl":[[0,990,2.2],[1,990,0]],"ltp":0.0,"tv":0.0,"id":7429606}]}]}
{"op":"mcm","clk":"4230455720","pt":1631533201264,"mc":[{"id":"1.187594322","rc":[{"batb":[[0,2.46,8.75],[1,2.24,33.68],[2,1.01,7]],"ltp":0.0,"tv":0.0,"id":7429606},{"batb":[[1,1.52,24.57],[2,1.28,158.31]],"ltp":1.57,"tv":86.82,"id":9628072}]}]}
{"op":"mcm","clk":"4230472415","pt":1631533401003,"mc":[{"id":"1.187594322","rc":[{"batb":[[0,2.46,12.05]],"batl":[[0,3.7,2.9],[1,990,2.2]],"ltp":0.0,"tv":0.0,"id":7429606}]}]}
{"op":"mcm","clk":"4230472539","pt":1631533402057,"mc":[{"id":"1.187594322","rc":[{"batb":[[0,2.5,8.52],[1,2.46,12.05],[2,2.24,33.68]],"ltp":0.0,"tv":0.0,"id":7429606}]}]}
{"op":"mcm","clk":"4230472765","pt":1631533404296,"mc":[{"id":"1.187594322","rc":[{"batb":[[1,2.46,8.75]],"ltp":0.0,"tv":0.0,"id":7429606}]}]}
{"op":"mcm","clk":"4230501546","pt":1631533701060,"mc":[{"id":"1.187594322","rc":[{"batb":[[0,2.5,12.06]],"ltp":0.0,"tv":0.0,"id":7429606}]}]}
{"op":"mcm","clk":"4230641119","pt":1631535063563,"mc":[{"id":"1.187594322","rc":[{"batb":[[1,1.55,3.31],[2,1.52,24.57]],"ltp":1.57,"tv":86.82,"id":9628072}]}]}
{"op":"mcm","clk":"4230641178","pt":1631535064043,"mc":[{"id":"1.187594322","rc":[{"batb":[[2,2.44,1.32]],"ltp":0.0,"tv":0.0,"id":7429606}]}]}
{"op":"mcm","clk":"4230643868","pt":1631535092614,"mc":[{"id":"1.187594322","rc":[{"batb":[[2,1.52,27.23]],"ltp":1.57,"tv":86.82,"id":9628072}]}]}
{"op":"mcm","clk":"4230781974","pt":1631536571229,"mc":[{"id":"1.187594322","marketDefinition":{"bspMarket":false,"turnInPlayEnabled":true,"persistenceEnabled":true,"marketBaseRate":5.0,"eventId":"30897917","eventTypeId":"2","numberOfWinners":1,"bettingType":"ODDS","marketType":"MATCH_ODDS","marketTime":"2021-09-13T12:50:00.000Z","suspendTime":"2021-09-13T12:50:00.000Z","bspReconciled":false,"complete":true,"inPlay":false,"crossMatching":true,"runnersVoidable":false,"numberOfActiveRunners":2,"betDelay":0,"status":"OPEN","runners":[{"status":"ACTIVE","sortPriority":1,"id":7429606,"name":"E Bogdan"},{"status":"ACTIVE","sortPriority":2,"id":9628072,"name":"A Moratelli"}],"regulators":["MR_INT"],"countryCode":"GB","discountAllowed":true,"timezone":"GMT","openDate":"2021-09-13T12:40:00.000Z","version":4030646926,"name":"Match Odds","eventName":"E Bogdan v A Moratelli"}}]}
{"op":"mcm","clk":"4230782292","pt":1631536574414,"mc":[{"id":"1.187594322","marketDefinition":{"bspMarket":false,"turnInPlayEnabled":true,"persistenceEnabled":true,"marketBaseRate":5.0,"eventId":"30897917","eventTypeId":"2","numberOfWinners":1,"bettingType":"ODDS","marketType":"MATCH_ODDS","marketTime":"2021-09-13T12:50:00.000Z","suspendTime":"2021-09-13T12:50:00.000Z","bspReconciled":false,"complete":true,"inPlay":false,"crossMatching":true,"runnersVoidable":false,"numberOfActiveRunners":2,"betDelay":0,"status":"OPEN","runners":[{"status":"ACTIVE","sortPriority":1,"id":7429606,"name":"E Bogdan"},{"status":"ACTIVE","sortPriority":2,"id":9628072,"name":"A Moratelli"}],"regulators":["MR_INT"],"countryCode":"GB","discountAllowed":true,"timezone":"GMT","openDate":"2021-09-13T12:50:00.000Z","version":4030646926,"name":"Match Odds","eventName":"E Bogdan v A Moratelli"},"rc":[{"batb":[[0,2.5,8.52]],"batl":[[0,990,2.2],[1,990,0]],"ltp":0.0,"tv":0.0,"id":7429606}]}]}
{"op":"mcm","clk":"4230782764","pt":1631536579172,"mc":[{"id":"1.187594322","rc":[{"batl":[[0,3.55,3.02],[1,990,2.2]],"ltp":0.0,"tv":0.0,"id":7429606}]}]}
{"op":"mcm","clk":"4230785020","pt":1631536601687,"mc":[{"id":"1.187594322","rc":[{"trd":[[2.76,1.43]],"ltp":2.76,"tv":1.43,"id":7429606},{"trd":[[1.57,77.34]],"batb":[[0,1.57,70.75]],"ltp":1.57,"tv":89.34,"id":9628072}],"tv":90.77}]}
{"op":"mcm","clk":"4230785173","pt":1631536603257,"mc":[{"id":"1.187594322","rc":[{"batb":[[0,1.57,73.27]],"ltp":1.57,"tv":89.34,"id":9628072}]}]}
{"op":"mcm","clk":"4230811136","pt":1631536866591,"mc":[{"id":"1.187594322","rc":[{"batl":[[0,990,2.2],[1,990,0]],"ltp":2.76,"tv":1.43,"id":7429606}]}]}
{"op":"mcm","clk":"4230846736","pt":1631537244887,"mc":[{"id":"1.187594322","marketDefinition":{"bspMarket":false,"turnInPlayEnabled":true,"persistenceEnabled":true,"marketBaseRate":5.0,"eventId":"30897917","eventTypeId":"2","numberOfWinners":1,"bettingType":"ODDS","marketType":"MATCH_ODDS","marketTime":"2021-09-13T13:00:00.000Z","suspendTime":"2021-09-13T13:00:00.000Z","bspReconciled":false,"complete":true,"inPlay":false,"crossMatching":true,"runnersVoidable":false,"numberOfActiveRunners":2,"betDelay":0,"status":"OPEN","runners":[{"status":"ACTIVE","sortPriority":1,"id":7429606,"name":"E Bogdan"},{"status":"ACTIVE","sortPriority":2,"id":9628072,"name":"A Moratelli"}],"regulators":["MR_INT"],"countryCode":"GB","discountAllowed":true,"timezone":"GMT","openDate":"2021-09-13T12:50:00.000Z","version":4030659512,"name":"Match Odds","eventName":"E Bogdan v A Moratelli"}}]}
{"op":"mcm","clk":"4230847040","pt":1631537247903,"mc":[{"id":"1.187594322","marketDefinition":{"bspMarket":false,"turnInPlayEnabled":true,"persistenceEnabled":true,"marketBaseRate":5.0,"eventId":"30897917","eventTypeId":"2","numberOfWinners":1,"bettingType":"ODDS","marketType":"MATCH_ODDS","marketTime":"2021-09-13T13:00:00.000Z","suspendTime":"2021-09-13T13:00:00.000Z","bspReconciled":false,"complete":true,"inPlay":false,"crossMatching":true,"runnersVoidable":false,"numberOfActiveRunners":2,"betDelay":0,"status":"OPEN","runners":[{"status":"ACTIVE","sortPriority":1,"id":7429606,"name":"E Bogdan"},{"status":"ACTIVE","sortPriority":2,"id":9628072,"name":"A Moratelli"}],"regulators":["MR_INT"],"countryCode":"GB","discountAllowed":true,"timezone":"GMT","openDate":"2021-09-13T13:00:00.000Z","version":4030659512,"name":"Match Odds","eventName":"E Bogdan v A Moratelli"}}]}
{"op":"mcm","clk":"4230847253","pt":1631537250123,"mc":[{"id":"1.187594322","rc":[{"batl":[[0,4.4,2.44],[1,990,2.2]],"ltp":2.76,"tv":1.43,"id":7429606}]}]}
{"op":"mcm","clk":"4230910889","pt":1631537853015,"mc":[{"id":"1.187594322","marketDefinition":{"bspMarket":false,"turnInPlayEnabled":true,"persistenceEnabled":true,"marketBaseRate":5.0,"eventId":"30897917","eventTypeId":"2","numberOfWinners":1,"bettingType":"ODDS","marketType":"MATCH_ODDS","marketTime":"2021-09-13T13:10:00.000Z","suspendTime":"2021-09-13T13:10:00.000Z","bspReconciled":false,"complete":true,"inPlay":false,"crossMatching":true,"runnersVoidable":false,"numberOfActiveRunners":2,"betDelay":0,"status":"OPEN","runners":[{"status":"ACTIVE","sortPriority":1,"id":7429606,"name":"E Bogdan"},{"status":"ACTIVE","sortPriority":2,"id":9628072,"name":"A Moratelli"}],"regulators":["MR_INT"],"countryCode":"GB","discountAllowed":true,"timezone":"GMT","openDate":"2021-09-13T13:00:00.000Z","version":4030666591,"name":"Match Odds","eventName":"E Bogdan v A Moratelli"}}]}
{"op":"mcm","clk":"4230913972","pt":1631537889485,"mc":[{"id":"1.187594322","marketDefinition":{"bspMarket":false,"turnInPlayEnabled":true,"persistenceEnabled":true,"marketBaseRate":5.0,"eventId":"30897917","eventTypeId":"2","numberOfWinners":1,"bettingType":"ODDS","marketType":"MATCH_ODDS","marketTime":"2021-09-13T13:10:00.000Z","suspendTime":"2021-09-13T13:10:00.000Z","bspReconciled":false,"complete":true,"inPlay":false,"crossMatching":true,"runnersVoidable":false,"numberOfActiveRunners":2,"betDelay":0,"status":"OPEN","runners":[{"status":"ACTIVE","sortPriority":1,"id":7429606,"name":"E Bogdan"},{"status":"ACTIVE","sortPriority":2,"id":9628072,"name":"A Moratelli"}],"regulators":["MR_INT"],"countryCode":"GB","discountAllowed":true,"timezone":"GMT","openDate":"2021-09-13T13:10:00.000Z","version":4030666591,"name":"Match Odds","eventName":"E Bogdan v A Moratelli"},"rc":[{"batl":[[0,990,2.2],[1,990,0]],"ltp":2.76,"tv":1.43,"id":7429606}]}]}
{"op":"mcm","clk":"4230914044","pt":1631537890167,"mc":[{"id":"1.187594322","rc":[{"batl":[[0,3.9,2.75],[1,990,2.2]],"ltp":2.76,"tv":1.43,"id":7429606}]}]}
{"op":"mcm","clk":"4230921465","pt":1631537974678,"mc":[{"id":"1.187594322","marketDefinition":{"bspMarket":false,"turnInPlayEnabled":true,"persistenceEnabled":true,"marketBaseRate":5.0,"eventId":"30897917","eventTypeId":"2","numberOfWinners":1,"bettingType":"ODDS","marketType":"MATCH_ODDS","marketTime":"2021-09-13T13:05:00.000Z","suspendTime":"2021-09-13T13:05:00.000Z","bspReconciled":false,"complete":true,"inPlay":false,"crossMatching":true,"runnersVoidable":false,"numberOfActiveRunners":2,"betDelay":0,"status":"OPEN","runners":[{"status":"ACTIVE","sortPriority":1,"id":7429606,"name":"E Bogdan"},{"status":"ACTIVE","sortPriority":2,"id":9628072,"name":"A Moratelli"}],"regulators":["MR_INT"],"countryCode":"GB","discountAllowed":true,"timezone":"GMT","openDate":"2021-09-13T13:10:00.000Z","version":4030671035,"name":"Match Odds","eventName":"E Bogdan v A Moratelli"}}]}
{"op":"mcm","clk":"4230921702","pt":1631537977970,"mc":[{"id":"1.187594322","marketDefinition":{"bspMarket":false,"turnInPlayEnabled":true,"persistenceEnabled":true,"marketBaseRate":5.0,"eventId":"30897917","eventTypeId":"2","numberOfWinners":1,"bettingType":"ODDS","marketType":"MATCH_ODDS","marketTime":"2021-09-13T13:05:00.000Z","suspendTime":"2021-09-13T13:05:00.000Z","bspReconciled":false,"complete":true,"inPlay":false,"crossMatching":true,"runnersVoidable":false,"numberOfActiveRunners":2,"betDelay":0,"status":"OPEN","runners":[{"status":"ACTIVE","sortPriority":1,"id":7429606,"name":"E Bogdan"},{"status":"ACTIVE","sortPriority":2,"id":9628072,"name":"A Moratelli"}],"regulators":["MR_INT"],"countryCode":"GB","discountAllowed":true,"timezone":"GMT","openDate":"2021-09-13T13:05:00.000Z","version":4030671035,"name":"Match Odds","eventName":"E Bogdan v A Moratelli"},"rc":[{"batl":[[0,3.85,2.78]],"ltp":2.76,"tv":1.43,"id":7429606}]}]}
{"op":"mcm","clk":"4230938544","pt":1631538171871,"mc":[{"id":"1.187594322","marketDefinition":{"bspMarket":false,"turnInPlayEnabled":true,"persistenceEnabled":true,"marketBaseRate":5.0,"eventId":"30897917","eventTypeId":"2","numberOfWinners":1,"bettingType":"ODDS","marketType":"MATCH_ODDS","marketTime":"2021-09-13T13:05:00.000Z","suspendTime":"2021-09-13T13:05:00.000Z","bspReconciled":false,"complete":true,"inPlay":true,"crossMatching":true,"runnersVoidable":false,"numberOfActiveRunners":2,"betDelay":5,"status":"OPEN","runners":[{"status":"ACTIVE","sortPriority":1,"id":7429606,"name":"E Bogdan"},{"status":"ACTIVE","sortPriority":2,"id":9628072,"name":"A Moratelli"}],"regulators":["MR_INT"],"countryCode":"GB","discountAllowed":true,"timezone":"GMT","openDate":"2021-09-13T13:05:00.000Z","version":4030681339,"name":"Match Odds","eventName":"E Bogdan v A Moratelli"},"rc":[{"batb":[[0,1.01,7],[1,2.46,0],[2,2.44,0]],"ltp":2.76,"tv":1.43,"id":7429606},{"trd":[[1.57,77.33]],"batb":[[0,1.01,7],[1,1.55,0],[2,1.52,0]],"batl":[[0,1.65,10.5],[1,1.65,0],[2,2.16,0]],"ltp":1.57,"tv":89.32,"id":9628072}],"tv":90.75}]}
{"op":"mcm","clk":"4230938959","pt":1631538177079,"mc":[{"id":"1.187594322","rc":[{"batb":[[0,2.2,24.99],[1,1.01,7]],"ltp":2.76,"tv":1.43,"id":7429606},{"batb":[[0,1.55,54.54],[1,1.01,7]],"ltp":1.57,"tv":89.32,"id":9628072}]}]}
{"op":"mcm","clk":"4230953536","pt":1631538339795,"mc":[{"id":"1.187594322","marketDefinition":{"bspMarket":false,"turnInPlayEnabled":true,"persistenceEnabled":true,"marketBaseRate":5.0,"eventId":"30897917","eventTypeId":"2","numberOfWinners":1,"bettingType":"ODDS","marketType":"MATCH_ODDS","marketTime":"2021-09-13T13:00:00.000Z","suspendTime":"2021-09-13T13:00:00.000Z","bspReconciled":false,"complete":true,"inPlay":true,"crossMatching":true,"runnersVoidable":false,"numberOfActiveRunners":2,"betDelay":5,"status":"OPEN","runners":[{"status":"ACTIVE","sortPriority":1,"id":7429606,"name":"E Bogdan"},{"status":"ACTIVE","sortPriority":2,"id":9628072,"name":"A Moratelli"}],"regulators":["MR_INT"],"countryCode":"GB","discountAllowed":true,"timezone":"GMT","openDate":"2021-09-13T13:05:00.000Z","version":4030684919,"name":"Match Odds","eventName":"E Bogdan v A Moratelli"}}]}
{"op":"mcm","clk":"4230953687","pt":1631538341817,"mc":[{"id":"1.187594322","marketDefinition":{"bspMarket":false,"turnInPlayEnabled":true,"persistenceEnabled":true,"marketBaseRate":5.0,"eventId":"30897917","eventTypeId":"2","numberOfWinners":1,"bettingType":"ODDS","marketType":"MATCH_ODDS","marketTime":"2021-09-13T13:00:00.000Z","suspendTime":"2021-09-13T13:00:00.000Z","bspReconciled":false,"complete":true,"inPlay":true,"crossMatching":true,"runnersVoidable":false,"numberOfActiveRunners":2,"betDelay":5,"status":"OPEN","runners":[{"status":"ACTIVE","sortPriority":1,"id":7429606,"name":"E Bogdan"},{"status":"ACTIVE","sortPriority":2,"id":9628072,"name":"A Moratelli"}],"regulators":["MR_INT"],"countryCode":"GB","discountAllowed":true,"timezone":"GMT","openDate":"2021-09-13T13:00:00.000Z","version":4030684919,"name":"Match Odds","eventName":"E Bogdan v A Moratelli"}}]}
{"op":"mcm","clk":"4230964041","pt":1631538459455,"mc":[{"id":"1.187594322","marketDefinition":{"bspMarket":false,"turnInPlayEnabled":true,"persistenceEnabled":true,"marketBaseRate":5.0,"eventId":"30897917","eventTypeId":"2","numberOfWinners":1,"bettingType":"ODDS","marketType":"MATCH_ODDS","marketTime":"2021-09-13T13:07:38.000Z","suspendTime":"2021-09-13T13:07:38.000Z","bspReconciled":false,"complete":true,"inPlay":true,"crossMatching":true,"runnersVoidable":false,"numberOfActiveRunners":2,"betDelay":5,"status":"OPEN","runners":[{"status":"ACTIVE","sortPriority":1,"id":7429606,"name":"E Bogdan"},{"status":"ACTIVE","sortPriority":2,"id":9628072,"name":"A Moratelli"}],"regulators":["MR_INT"],"countryCode":"GB","discountAllowed":true,"timezone":"GMT","openDate":"2021-09-13T13:00:00.000Z","version":4030686899,"name":"Match Odds","eventName":"E Bogdan v A Moratelli"},"rc":[{"batb":[[0,1.01,7],[1,1.01,0]],"ltp":2.76,"tv":1.43,"id":7429606},{"batb":[[0,1.01,7],[1,1.01,0]],"ltp":1.57,"tv":89.32,"id":9628072}]}]}
{"op":"mcm","clk":"4230964331","pt":1631538463476,"mc":[{"id":"1.187594322","marketDefinition":{"bspMarket":false,"turnInPlayEnabled":true,"persistenceEnabled":true,"marketBaseRate":5.0,"eventId":"30897917","eventTypeId":"2","numberOfWinners":1,"bettingType":"ODDS","marketType":"MATCH_ODDS","marketTime":"2021-09-13T13:07:38.000Z","suspendTime":"2021-09-13T13:07:38.000Z","bspReconciled":false,"complete":true,"inPlay":true,"crossMatching":true,"runnersVoidable":false,"numberOfActiveRunners":2,"betDelay":5,"status":"OPEN","runners":[{"status":"ACTIVE","sortPriority":1,"id":7429606,"name":"E Bogdan"},{"status":"ACTIVE","sortPriority":2,"id":9628072,"name":"A Moratelli"}],"regulators":["MR_INT"],"countryCode":"GB","discountAllowed":true,"timezone":"GMT","openDate":"2021-09-13T13:07:38.000Z","version":4030686899,"name":"Match Odds","eventName":"E Bogdan v A Moratelli"}}]}
{"op":"mcm","clk":"4230964378","pt":1631538464084,"mc":[{"id":"1.187594322","rc":[{"batb":[[0,2.26,23.8],[1,1.01,7]],"ltp":2.76,"tv":1.43,"id":7429606},{"batb":[[0,1.58,51.72],[1,1.01,7]],"ltp":1.57,"tv":89.32,"id":9628072}]}]}
{"op":"mcm","clk":"4230965798","pt":1631538482381,"mc":[{"id":"1.187594322","rc":[{"batb":[[0,1.01,7],[1,1.01,0]],"ltp":2.76,"tv":1.43,"id":7429606},{"batb":[[0,1.01,7],[1,1.01,0]],"ltp":1.57,"tv":89.32,"id":9628072}]}]}
{"op":"mcm","clk":"4230966270","pt":1631538487306,"mc":[{"id":"1.187594322","rc":[{"batb":[[0,2.1,27.27],[1,1.01,7]],"ltp":2.76,"tv":1.43,"id":7429606}]}]}
{"op":"mcm","clk":"4230967161","pt":1631538497504,"mc":[{"id":"1.187594322","rc":[{"trd":[[2.52,6.88]],"batl":[[0,2.52,6.87]],"ltp":2.52,"tv":8.31,"id":7429606},{"trd":[[1.65,10.5]],"ltp":1.65,"tv":99.82,"id":9628072}],"tv":108.14}]}
{"op":"mcm","clk":"4230967607","pt":1631538502410,"mc":[{"id":"1.187594322","rc":[{"batb":[[0,1.65,46.15],[1,1.01,7]],"ltp":1.65,"tv":99.82,"id":9628072}]}]}
{"op":"mcm","clk":"4230969057","pt":1631538518723,"mc":[{"id":"1.187594322","rc":[{"batb":[[0,1.01,7],[1,1.01,0]],"ltp":2.52,"tv":8.31,"id":7429606},{"batb":[[0,1.01,7],[1,1.01,0]],"ltp":1.65,"tv":99.82,"id":9628072}]}]}
{"op":"mcm","clk":"4230969507","pt":1631538523633,"mc":[{"id":"1.187594322","rc":[{"batb":[[0,2,30],[1,1.01,7]],"ltp":2.52,"tv":8.31,"id":7429606},{"batb":[[0,1.73,41.09],[1,1.01,7]],"ltp":1.65,"tv":99.82,"id":9628072}]}]}
{"op":"mcm","clk":"4230971904","pt":1631538548264,"mc":[{"id":"1.187594322","rc":[{"batb":[[0,1.01,7],[1,1.01,0]],"ltp":2.52,"tv":8.31,"id":7429606},{"batb":[[0,1.01,7],[1,1.01,0]],"ltp":1.65,"tv":99.82,"id":9628072}]}]}
{"op":"mcm","clk":"4230972314","pt":1631538553285,"mc":[{"id":"1.187594322","rc":[{"batb":[[0,1.88,34.09],[1,1.01,7]],"ltp":2.52,"tv":8.31,"id":7429606},{"batb":[[0,1.85,35.29],[1,1.01,7]],"ltp":1.65,"tv":99.82,"id":9628072}]}]}
{"op":"mcm","clk":"4230975134","pt":1631538583596,"mc":[{"id":"1.187594322","rc":[{"batb":[[0,1.01,7],[1,1.01,0]],"ltp":2.52,"tv":8.31,"id":7429606},{"batb":[[0,1.01,7],[1,1.01,0]],"ltp":1.65,"tv":99.82,"id":9628072}]}]}
{"op":"mcm","clk":"4230975578","pt":1631538588506,"mc":[{"id":"1.187594322","rc":[{"batb":[[0,2,30],[1,1.01,7]],"ltp":2.52,"tv":8.31,"id":7429606},{"batb":[[0,1.73,41.09],[1,1.01,7]],"ltp":1.65,"tv":99.82,"id":9628072}]}]}
{"op":"mcm","clk":"4230977456","pt":1631538606565,"mc":[{"id":"1.187594322","rc":[{"batb":[[0,1.01,7],[1,1.01,0]],"ltp":2.52,"tv":8.31,"id":7429606},{"batb":[[0,1.01,7],[1,1.01,0]],"ltp":1.65,"tv":99.82,"id":9628072}]}]}
{"op":"mcm","clk":"4230977957","pt":1631538611428,"mc":[{"id":"1.187594322","rc":[{"batb":[[0,2.1,27.27],[1,1.01,7]],"ltp":2.52,"tv":8.31,"id":7429606},{"batb":[[0,1.65,46.15],[1,1.01,7]],"ltp":1.65,"tv":99.82,"id":9628072}]}]}
{"op":"mcm","clk":"4230980849","pt":1631538640642,"mc":[{"id":"1.187594322","rc":[{"batb":[[0,1.01,7],[1,1.01,0]],"ltp":2.52,"tv":8.31,"id":7429606},{"batb":[[0,1.01,7],[1,1.01,0]],"ltp":1.65,"tv":99.82,"id":9628072}]}]}
{"op":"mcm","clk":"4230981515","pt":1631538645466,"mc":[{"id":"1.187594322","rc":[{"batb":[[0,1.98,30.61],[1,1.01,7]],"ltp":2.52,"tv":8.31,"id":7429606},{"batb":[[0,1.78,38.46],[1,1.01,7]],"ltp":1.65,"tv":99.82,"id":9628072}]}]}
{"op":"mcm","clk":"4230989141","pt":1631538722890,"mc":[{"id":"1.187594322","rc":[{"batb":[[0,1.01,7],[1,1.01,0]],"ltp":2.52,"tv":8.31,"id":7429606},{"batb":[[0,1.01,7],[1,1.01,0]],"ltp":1.65,"tv":99.82,"id":9628072}]}]}
{"op":"mcm","clk":"4230990107","pt":1631538727779,"mc":[{"id":"1.187594322","rc":[{"batb":[[0,1.85,35.29],[1,1.01,7]],"ltp":2.52,"tv":8.31,"id":7429606},{"batb":[[0,1.88,34.09],[1,1.01,7]],"ltp":1.65,"tv":99.82,"id":9628072}]}]}
{"op":"mcm","clk":"4230990286","pt":1631538728781,"mc":[{"id":"1.187594322","rc":[{"batb":[[1,1.62,421.1],[2,1.01,7]],"batl":[[0,2.6,261.08]],"ltp":2.52,"tv":8.31,"id":7429606}]}]}
{"op":"mcm","clk":"4230994715","pt":1631538749206,"mc":[{"id":"1.187594322","rc":[{"batb":[[0,1.62,421.1],[1,1.01,7],[2,1.01,0]],"ltp":2.52,"tv":8.31,"id":7429606},{"batb":[[0,1.01,7],[1,1.01,0]],"ltp":1.65,"tv":99.82,"id":9628072}]}]}
{"op":"mcm","clk":"4230994825","pt":1631538749997,"mc":[{"id":"1.187594322","rc":[{"batb":[[0,1.01,7],[1,1.01,0]],"ltp":2.52,"tv":8.31,"id":7429606}]}]}
{"op":"mcm","clk":"4230995298","pt":1631538754069,"mc":[{"id":"1.187594322","rc":[{"batb":[[0,1.98,30.61],[1,1.01,7]],"ltp":2.52,"tv":8.31,"id":7429606},{"batb":[[0,1.78,38.46],[1,1.01,7]],"ltp":1.65,"tv":99.82,"id":9628072}]}]}
{"op":"mcm","clk":"4230995502","pt":1631538756096,"mc":[{"id":"1.187594322","rc":[{"batb":[[1,1.67,415.35],[2,1.01,7]],"ltp":2.52,"tv":8.31,"id":7429606}]}]}
{"op":"mcm","clk":"4230997738","pt":1631538779611,"mc":[{"id":"1.187594322","rc":[{"batb":[[1,1.01,7],[2,1.01,0]],"ltp":2.52,"tv":8.31,"id":7429606}]}]}
{"op":"mcm","clk":"4230997870","pt":1631538780918,"mc":[{"id":"1.187594322","rc":[{"batb":[[0,1.01,7],[1,1.01,0]],"ltp":2.52,"tv":8.31,"id":7429606},{"batb":[[0,1.01,7],[1,1.01,0]],"ltp":1.65,"tv":99.82,"id":9628072}]}]}
{"op":"mcm","clk":"4230998335","pt":1631538785817,"mc":[{"id":"1.187594322","rc":[{"batb":[[0,2.1,27.27],[1,1.01,7]],"ltp":2.52,"tv":8.31,"id":7429606},{"batb":[[0,1.65,46.15],[1,1.01,7]],"ltp":1.65,"tv":99.82,"id":9628072}]}]}
{"op":"mcm","clk":"4231000157","pt":1631538803162,"mc":[{"id":"1.187594322","rc":[{"batb":[[0,1.01,7],[1,1.01,0]],"ltp":2.52,"tv":8.31,"id":7429606},{"batb":[[0,1.01,7],[1,1.01,0]],"ltp":1.65,"tv":99.82,"id":9628072}]}]}
{"op":"mcm","clk":"4231000625","pt":1631538808048,"mc":[{"id":"1.187594322","rc":[{"batb":[[0,2.2,24.99],[1,1.01,7]],"ltp":2.52,"tv":8.31,"id":7429606},{"batb":[[0,1.6,49.99],[1,1.01,7]],"ltp":1.65,"tv":99.82,"id":9628072}]}]}
{"op":"mcm","clk":"4231005735","pt":1631538856975,"mc":[{"id":"1.187594322","rc":[{"batb":[[0,1.01,7],[1,1.01,0]],"ltp":2.52,"tv":8.31,"id":7429606},{"batb":[[0,1.01,7],[1,1.01,0]],"ltp":1.65,"tv":99.82,"id":9628072}]}]}
{"op":"mcm","clk":"4231006316","pt":1631538861910,"mc":[{"id":"1.187594322","rc":[{"batb":[[0,2.34,22.38],[1,1.01,7]],"ltp":2.52,"tv":8.31,"id":7429606},{"batb":[[0,1.55,54.54],[1,1.01,7]],"ltp":1.65,"tv":99.82,"id":9628072}]}]}
{"op":"mcm","clk":"4231009729","pt":1631538896646,"mc":[{"id":"1.187594322","rc":[{"batb":[[0,1.01,7],[1,1.01,0]],"ltp":2.52,"tv":8.31,"id":7429606},{"batb":[[0,1.01,7],[1,1.01,0]],"ltp":1.65,"tv":99.82,"id":9628072}]}]}
{"op":"mcm","clk":"4231010204","pt":1631538901440,"mc":[{"id":"1.187594322","rc":[{"batb":[[0,2.5,20],[1,1.01,7]],"ltp":2.52,"tv":8.31,"id":7429606},{"batb":[[0,1.48,62.5],[1,1.01,7]],"ltp":1.65,"tv":99.82,"id":9628072}]}]}
{"op":"mcm","clk":"4231012184","pt":1631538920025,"mc":[{"id":"1.187594322","rc":[{"batb":[[0,1.01,7],[1,1.01,0]],"ltp":2.52,"tv":8.31,"id":7429606},{"batb":[[0,1.01,7],[1,1.01,0]],"ltp":1.65,"tv":99.82,"id":9628072}]}]}
{"op":"mcm","clk":"4231012732","pt":1631538925037,"mc":[{"id":"1.187594322","rc":[{"batb":[[0,2.58,18.98],[1,1.01,7]],"ltp":2.52,"tv":8.31,"id":7429606},{"batb":[[0,1.45,66.66],[1,1.01,7]],"ltp":1.65,"tv":99.82,"id":9628072}]}]}
{"op":"mcm","clk":"4231013258","pt":1631538930083,"mc":[{"id":"1.187594322","rc":[{"batb":[[0,1.01,7],[1,1.01,0]],"ltp":2.52,"tv":8.31,"id":7429606},{"batb":[[0,1.01,7],[1,1.01,0]],"ltp":1.65,"tv":99.82,"id":9628072}]}]}
{"op":"mcm","clk":"4231013861","pt":1631538934986,"mc":[{"id":"1.187594322","rc":[{"batb":[[0,2.34,22.38],[1,1.01,7]],"ltp":2.52,"tv":8.31,"id":7429606},{"batb":[[0,1.55,54.54],[1,1.01,7]],"ltp":1.65,"tv":99.82,"id":9628072}]}]}
{"op":"mcm","clk":"4231014114","pt":1631538936957,"mc":[{"id":"1.187594322","rc":[{"batb":[[1,1.86,404.05],[2,1.01,7]],"batl":[[0,3.3,194.53]],"ltp":2.52,"tv":8.31,"id":7429606}]}]}
{"op":"mcm","clk":"4231016227","pt":1631538955662,"mc":[{"id":"1.187594322","rc":[{"batb":[[0,1.86,404.05],[1,1.01,7],[2,1.01,0]],"ltp":2.52,"tv":8.31,"id":7429606},{"batb":[[0,1.01,7],[1,1.01,0]],"ltp":1.65,"tv":99.82,"id":9628072}]}]}
{"op":"mcm","clk":"4231016763","pt":1631538960688,"mc":[{"id":"1.187594322","rc":[{"batb":[[0,2.16,25.86],[1,1.86,404.05],[2,1.01,7]],"ltp":2.52,"tv":8.31,"id":7429606},{"batb":[[0,1.63,47.61],[1,1.01,7]],"ltp":1.65,"tv":99.82,"id":9628072}]}]}
{"op":"mcm","clk":"4231018970","pt":1631538976825,"mc":[{"id":"1.187594322","rc":[{"batb":[[0,1.86,404.05],[1,1.01,7],[2,1.01,0]],"ltp":2.52,"tv":8.31,"id":7429606},{"batb":[[0,1.01,7],[1,1.01,0]],"ltp":1.65,"tv":99.82,"id":9628072}]}]}
{"op":"mcm","clk":"4231019556","pt":1631538981683,"mc":[{"id":"1.187594322","rc":[{"batb":[[0,2.06,28.3],[1,1.86,404.05],[2,1.01,7]],"ltp":2.52,"tv":8.31,"id":7429606},{"batb":[[0,1.71,42.25],[1,1.01,7]],"ltp":1.65,"tv":99.82,"id":9628072}]}]}
{"op":"mcm","clk":"4231019947","pt":1631538984829,"mc":[{"id":"1.187594322","rc":[{"batl":[[0,2.92,224.27]],"ltp":2.52,"tv":8.31,"id":7429606}]}]}
{"op":"mcm","clk":"4231023556","pt":1631539014673,"mc":[{"id":"1.187594322","rc":[{"batb":[[0,1.86,404.05],[1,1.01,7],[2,1.01,0]],"ltp":2.52,"tv":8.31,"id":7429606},{"batb":[[0,1.01,7],[1,1.01,0]],"ltp":1.65,"tv":99.82,"id":9628072}]}]}
{"op":"mcm","clk":"4231024210","pt":1631539019645,"mc":[{"id":"1.187594322","rc":[{"batb":[[0,2.16,25.86],[1,1.86,404.05],[2,1.01,7]],"ltp":2.52,"tv":8.31,"id":7429606},{"batb":[[0,1.63,47.61],[1,1.01,7]],"ltp":1.65,"tv":99.82,"id":9628072}]}]}
{"op":"mcm","clk":"4231027404","pt":1631539047374,"mc":[{"id":"1.187594322","rc":[{"batb":[[0,1.86,404.05],[1,1.01,7],[2,1.01,0]],"ltp":2.52,"tv":8.31,"id":7429606},{"batb":[[0,1.01,7],[1,1.01,0]],"ltp":1.65,"tv":99.82,"id":9628072}]}]}
{"op":"mcm","clk":"4231027454","pt":1631539047789,"mc":[{"id":"1.187594322","rc":[{"batb":[[0,1.01,7],[1,1.01,0]],"ltp":2.52,"tv":8.31,"id":7429606}]}]}
{"op":"mcm","clk":"4231027919","pt":1631539052302,"mc":[{"id":"1.187594322","rc":[{"batb":[[0,2,30],[1,1.01,7]],"ltp":2.52,"tv":8.31,"id":7429606},{"batb":[[0,1.73,41.09],[1,1.01,7]],"ltp":1.65,"tv":99.82,"id":9628072}]}]}
{"op":"mcm","clk":"4231028093","pt":1631539053715,"mc":[{"id":"1.187594322","rc":[{"batb":[[1,1.7,414.9],[2,1.01,7]],"ltp":2.52,"tv":8.31,"id":7429606}]}]}
{"op":"mcm","clk":"4231029522","pt":1631539066398,"mc":[{"id":"1.187594322","rc":[{"trd":[[1.73,82.18]],"batb":[[0,1.01,7],[1,1.01,0]],"batl":[[0,1.73,31.9]],"ltp":1.73,"tv":182.01,"id":9628072}],"tv":190.32}]}
{"op":"mcm","clk":"4231030127","pt":1631539071632,"mc":[{"id":"1.187594322","rc":[{"batb":[[0,1.66,45.45],[1,1.01,7]],"ltp":1.73,"tv":182.01,"id":9628072}]}]}
{"op":"mcm","clk":"4231032043","pt":1631539087641,"mc":[{"id":"1.187594322","rc":[{"trd":[[1.73,145.97]],"batl":[[0,1.73,0.01]],"ltp":1.73,"tv":245.79,"id":9628072}],"tv":254.11}]}
{"op":"mcm","clk":"4231041242","pt":1631539163354,"mc":[{"id":"1.187594322","rc":[{"batb":[[0,1.7,414.9],[1,1.01,7],[2,1.01,0]],"ltp":2.52,"tv":8.31,"id":7429606},{"batb":[[0,1.01,7],[1,1.01,0]],"ltp":1.73,"tv":245.79,"id":9628072}]}]}
{"op":"mcm","clk":"4231041391","pt":1631539164570,"mc":[{"id":"1.187594322","rc":[{"batb":[[0,1.01,7],[1,1.01,0]],"ltp":2.52,"tv":8.31,"id":7429606}]}]}
{"op":"mcm","clk":"4231041817","pt":1631539168382,"mc":[{"id":"1.187594322","rc":[{"batb":[[0,2.1,27.27],[1,1.01,7]],"ltp":2.52,"tv":8.31,"id":7429606},{"batb":[[0,1.65,46.15],[1,1.01,7]],"ltp":1.73,"tv":245.79,"id":9628072}]}]}
{"op":"mcm","clk":"4231042000","pt":1631539170116,"mc":[{"id":"1.187594322","rc":[{"batb":[[1,1.77,407.75],[2,1.01,7]],"ltp":2.52,"tv":8.31,"id":7429606}]}]}
{"op":"mcm","clk":"4231044691","pt":1631539195035,"mc":[{"id":"1.187594322","rc":[{"batb":[[0,1.01,7],[1,1.77,0],[2,1.01,0]],"ltp":2.52,"tv":8.31,"id":7429606},{"batb":[[0,1.01,7],[1,1.01,0]],"ltp":1.73,"tv":245.79,"id":9628072}]}]}
{"op":"mcm","clk":"4231045234","pt":1631539199513,"mc":[{"id":"1.187594322","rc":[{"batb":[[0,2.26,23.8],[1,1.01,7]],"ltp":2.52,"tv":8.31,"id":7429606},{"batb":[[0,1.58,51.72],[1,1.01,7]],"ltp":1.73,"tv":245.79,"id":9628072}]}]}
{"op":"mcm","clk":"4231045444","pt":1631539201314,"mc":[{"id":"1.187594322","rc":[{"batb":[[1,1.86,404.05],[2,1.01,7]],"batl":[[0,3.3,194.53]],"ltp":2.52,"tv":8.31,"id":7429606}]}]}
{"op":"mcm","clk":"4231047241","pt":1631539217034,"mc":[{"id":"1.187594322","rc":[{"batb":[[0,1.86,404.05],[1,1.01,7],[2,1.01,0]],"ltp":2.52,"tv":8.31,"id":7429606},{"batb":[[0,1.01,7],[1,1.01,0]],"ltp":1.73,"tv":245.79,"id":9628072}]}]}
{"op":"mcm","clk":"4231047788","pt":1631539222086,"mc":[{"id":"1.187594322","rc":[{"batb":[[0,2.42,21.12],[1,1.86,404.05],[2,1.01,7]],"ltp":2.52,"tv":8.31,"id":7429606},{"batb":[[0,1.51,58.82],[1,1.01,7]],"ltp":1.73,"tv":245.79,"id":9628072}]}]}
{"op":"mcm","clk":"4231049609","pt":1631539238907,"mc":[{"id":"1.187594322","rc":[{"batb":[[0,1.01,7],[1,1.86,0],[2,1.01,0]],"ltp":2.52,"tv":8.31,"id":7429606},{"batb":[[0,1.01,7],[1,1.01,0]],"ltp":1.73,"tv":245.79,"id":9628072}]}]}
{"op":"mcm","clk":"4231050060","pt":1631539243807,"mc":[{"id":"1.187594322","rc":[{"batb":[[0,2.5,20],[1,1.01,7]],"ltp":2.52,"tv":8.31,"id":7429606},{"batb":[[0,1.48,62.5],[1,1.01,7]],"ltp":1.73,"tv":245.79,"id":9628072}]}]}
{"op":"mcm","clk":"4231050171","pt":1631539244793,"mc":[{"id":"1.187594322","rc":[{"batb":[[1,1.97,400.24],[2,1.01,7]],"batl":[[0,3.65,172.73]],"ltp":2.52,"tv":8.31,"id":7429606}]}]}
{"op":"mcm","clk":"4231053723","pt":1631539279020,"mc":[{"id":"1.187594322","rc":[{"batb":[[0,1.97,400.24],[1,1.01,7],[2,1.01,0]],"ltp":2.52,"tv":8.31,"id":7429606},{"batb":[[0,1.01,7],[1,1.01,0]],"ltp":1.73,"tv":245.79,"id":9628072}]}]}
{"op":"mcm","clk":"4231054224","pt":1631539284066,"mc":[{"id":"1.187594322","rc":[{"batb":[[0,2.66,18.07],[1,1.97,400.24],[2,1.01,7]],"ltp":2.52,"tv":8.31,"id":7429606},{"batb":[[0,1.42,71.42],[1,1.01,7]],"ltp":1.73,"tv":245.79,"id":9628072}]}]}
{"op":"mcm","clk":"4231056193","pt":1631539304848,"mc":[{"id":"1.187594322","rc":[{"batb":[[0,1.58,3],[1,1.42,71.42],[2,1.01,7]],"ltp":1.73,"tv":245.79,"id":9628072}]}]}
{"op":"mcm","clk":"4231056568","pt":1631539308898,"mc":[{"id":"1.187594322","rc":[{"batb":[[0,1.01,7],[1,1.97,0],[2,1.01,0]],"ltp":2.52,"tv":8.31,"id":7429606},{"batb":[[1,1.01,7],[2,1.01,0]],"ltp":1.73,"tv":245.79,"id":9628072}]}]}
{"op":"mcm","clk":"4231057088","pt":1631539313592,"mc":[{"id":"1.187594322","rc":[{"trd":[[2.74,1.73]],"batb":[[0,2.84,14.57],[1,1.01,7]],"ltp":2.74,"tv":10.04,"id":7429606},{"trd":[[1.58,3]],"batb":[[0,1.38,78.94]],"ltp":1.58,"tv":248.79,"id":9628072}],"tv":258.84}]}
{"op":"mcm","clk":"4231057126","pt":1631539313860,"mc":[{"id":"1.187594322","rc":[{"batb":[[0,1.01,7],[1,1.01,0]],"ltp":2.74,"tv":10.04,"id":7429606}]}]}
{"op":"mcm","clk":"4231057219","pt":1631539314774,"mc":[{"id":"1.187594322","rc":[{"batb":[[0,2.12,393.94],[1,1.01,7]],"batl":[[0,4.2,150.04]],"ltp":2.74,"tv":10.04,"id":7429606}]}]}
{"op":"mcm","clk":"4231057638","pt":1631539318788,"mc":[{"id":"1.187594322","rc":[{"batb":[[0,2.84,16.3],[1,2.12,393.94],[2,1.01,7]],"ltp":2.74,"tv":10.04,"id":7429606}]}]}
{"op":"mcm","clk":"4231058245","pt":1631539324200,"mc":[{"id":"1.187594322","rc":[{"trd":[[2.84,1.64]],"batb":[[0,2.12,393.94],[1,1.01,7],[2,1.01,0]],"ltp":2.84,"tv":11.68,"id":7429606},{"trd":[[1.55,3]],"ltp":1.55,"tv":251.79,"id":9628072}],"tv":263.48}]}
{"op":"mcm","clk":"4231058806","pt":1631539329182,"mc":[{"id":"1.187594322","rc":[{"batb":[[0,2.84,16.3],[1,2.12,393.94],[2,1.01,7]],"ltp":2.84,"tv":11.68,"id":7429606}]}]}
{"op":"mcm","clk":"4231059069","pt":1631539331601,"mc":[{"id":"1.187594322","rc":[{"trd":[[2.84,3.28]],"batb":[[0,2.12,393.94],[1,1.01,7],[2,1.01,0]],"ltp":2.84,"tv":13.32,"id":7429606},{"trd":[[1.55,6]],"ltp":1.55,"tv":254.79,"id":9628072}],"tv":268.12}]}
{"op":"mcm","clk":"4231059533","pt":1631539336610,"mc":[{"id":"1.187594322","rc":[{"batb":[[0,2.84,16.3],[1,2.12,393.94],[2,1.01,7]],"ltp":2.84,"tv":13.32,"id":7429606}]}]}
{"op":"mcm","clk":"4231060168","pt":1631539343033,"mc":[{"id":"1.187594322","rc":[{"trd":[[2.84,4.92]],"batb":[[0,2.12,393.94],[1,1.01,7],[2,1.01,0]],"ltp":2.84,"tv":14.96,"id":7429606},{"trd":[[1.55,9]],"ltp":1.55,"tv":257.79,"id":9628072}],"tv":272.76}]}
{"op":"mcm","clk":"4231060437","pt":1631539345903,"mc":[{"id":"1.187594322","rc":[{"batb":[[0,1.01,7],[1,1.01,0]],"ltp":1.55,"tv":257.79,"id":9628072}]}]}
{"op":"mcm","clk":"4231060792","pt":1631539349808,"mc":[{"id":"1.187594322","rc":[{"batb":[[0,1.64,3],[1,1.01,7]],"ltp":1.55,"tv":257.79,"id":9628072}]}]}
{"op":"mcm","clk":"4231060875","pt":1631539350843,"mc":[{"id":"1.187594322","rc":[{"batb":[[1,1.34,88.23],[2,1.01,7]],"ltp":1.55,"tv":257.79,"id":9628072}]}]}
{"op":"mcm","clk":"4231061109","pt":1631539353313,"mc":[{"id":"1.187594322","rc":[{"trd":[[2.58,1.91]],"ltp":2.58,"tv":16.87,"id":7429606},{"trd":[[1.64,3]],"batb":[[0,1.34,88.23],[1,1.01,7],[2,1.01,0]],"ltp":1.64,"tv":260.79,"id":9628072}],"tv":277.67}]}
{"op":"mcm","clk":"4231061612","pt":1631539358513,"mc":[{"id":"1.187594322","rc":[{"batb":[[0,1.01,7],[1,1.01,0]],"ltp":1.64,"tv":260.79,"id":9628072}]}]}
{"op":"mcm","clk":"4231062035","pt":1631539363423,"mc":[{"id":"1.187594322","rc":[{"batb":[[0,2.84,16.3],[1,2.12,393.94],[2,1.01,7]],"ltp":2.58,"tv":16.87,"id":7429606},{"batb":[[0,1.38,78.94],[1,1.01,7]],"ltp":1.64,"tv":260.79,"id":9628072}]}]}
{"op":"mcm","clk":"4231064046","pt":1631539384094,"mc":[{"id":"1.187594322","rc":[{"batb":[[0,2.12,393.94],[1,1.01,7],[2,1.01,0]],"ltp":2.58,"tv":16.87,"id":7429606},{"batb":[[0,1.01,7],[1,1.01,0]],"ltp":1.64,"tv":260.79,"id":9628072}]}]}
{"op":"mcm","clk":"4231064531","pt":1631539389086,"mc":[{"id":"1.187594322","rc":[{"batb":[[0,2.5,20],[1,2.12,393.94],[2,1.01,7]],"ltp":2.58,"tv":16.87,"id":7429606},{"batb":[[0,1.48,62.5],[1,1.01,7]],"ltp":1.64,"tv":260.79,"id":9628072}]}]}
{"op":"mcm","clk":"4231064696","pt":1631539390661,"mc":[{"id":"1.187594322","rc":[{"batl":[[0,3.65,172.73]],"ltp":2.58,"tv":16.87,"id":7429606}]}]}
{"op":"mcm","clk":"4231066870","pt":1631539412392,"mc":[{"id":"1.187594322","rc":[{"batl":[[0,1.52,3]],"ltp":1.64,"tv":260.79,"id":9628072}]}]}
{"op":"mcm","clk":"4231067916","pt":1631539424400,"mc":[{"id":"1.187594322","rc":[{"batb":[[0,2.12,393.94],[1,1.01,7],[2,1.01,0]],"ltp":2.58,"tv":16.87,"id":7429606},{"batb":[[0,1.01,7],[1,1.01,0]],"ltp":1.64,"tv":260.79,"id":9628072}]}]}
{"op":"mcm","clk":"4231068022","pt":1631539425602,"mc":[{"id":"1.187594322","rc":[{"batb":[[0,1.01,7],[1,1.01,0]],"ltp":2.58,"tv":16.87,"id":7429606}]}]}
{"op":"mcm","clk":"4231068378","pt":1631539429321,"mc":[{"id":"1.187594322","rc":[{"batb":[[0,2.26,23.8],[1,1.01,7]],"ltp":2.58,"tv":16.87,"id":7429606}]}]}
{"op":"mcm","clk":"4231068568","pt":1631539431139,"mc":[{"id":"1.187594322","rc":[{"batb":[[1,1.86,404.05],[2,1.01,7]],"batl":[[0,3.3,194.53]],"ltp":2.58,"tv":16.87,"id":7429606}]}]}
{"op":"mcm","clk":"4231069426","pt":1631539440219,"mc":[{"id":"1.187594322","rc":[{"trd":[[1.52,6]],"batb":[[0,1.52,26.49],[1,1.01,7]],"ltp":1.52,"tv":266.79,"id":9628072}],"tv":283.66}]}
{"op":"mcm","clk":"4231069452","pt":1631539440643,"mc":[{"id":"1.187594322","rc":[{"batb":[[0,1.01,7],[1,1.01,0]],"ltp":1.52,"tv":266.79,"id":9628072}]}]}
{"op":"mcm","clk":"4231069913","pt":1631539445420,"mc":[{"id":"1.187594322","rc":[{"batb":[[0,1.58,51.72],[1,1.01,7]],"ltp":1.52,"tv":266.79,"id":9628072}]}]}
{"op":"mcm","clk":"4231070670","pt":1631539453154,"mc":[{"id":"1.187594322","rc":[{"batb":[[0,1.86,404.05],[1,1.01,7],[2,1.01,0]],"ltp":2.58,"tv":16.87,"id":7429606},{"batb":[[0,1.01,7],[1,1.01,0]],"ltp":1.52,"tv":266.79,"id":9628072}]}]}
{"op":"mcm","clk":"4231071175","pt":1631539457883,"mc":[{"id":"1.187594322","rc":[{"batb":[[0,2.06,28.3],[1,1.86,404.05],[2,1.01,7]],"ltp":2.58,"tv":16.87,"id":7429606},{"batb":[[0,1.71,42.25],[1,1.01,7]],"ltp":1.52,"tv":266.79,"id":9628072}]}]}
{"op":"mcm","clk":"4231071337","pt":1631539459350,"mc":[{"id":"1.187594322","rc":[{"batl":[[0,3,216.36]],"ltp":2.58,"tv":16.87,"id":7429606}]}]}
{"op":"mcm","clk":"4231072762","pt":1631539472594,"mc":[{"id":"1.187594322","rc":[{"trd":[[1.71,4]],"batb":[[0,1.01,7],[1,1.01,0]],"batl":[[0,1.71,2]],"ltp":1.71,"tv":270.79,"id":9628072}],"tv":287.66}]}
{"op":"mcm","clk":"4231073259","pt":1631539477598,"mc":[{"id":"1.187594322","rc":[{"trd":[[1.71,12]],"ltp":1.71,"tv":278.79,"id":9628072}],"tv":295.66}]}
{"op":"mcm","clk":"4231073736","pt":1631539482502,"mc":[{"id":"1.187594322","rc":[{"batb":[[0,1.71,42.25],[1,1.01,7]],"ltp":1.71,"tv":278.79,"id":9628072}]}]}
{"op":"mcm","clk":"4231073879","pt":1631539483870,"mc":[{"id":"1.187594322","rc":[{"batl":[[0,1.85,6]],"ltp":1.71,"tv":278.79,"id":9628072}]}]}
{"op":"mcm","clk":"4231078805","pt":1631539539067,"mc":[{"id":"1.187594322","rc":[{"batl":[[0,1.74,3],[1,1.85,6]],"ltp":1.71,"tv":278.79,"id":9628072}]}]}
{"op":"mcm","clk":"4231080106","pt":1631539553917,"mc":[{"id":"1.187594322","rc":[{"batl":[[0,1.85,6],[1,1.85,0]],"ltp":1.71,"tv":278.79,"id":9628072}]}]}
{"op":"mcm","clk":"4231081594","pt":1631539569270,"mc":[{"id":"1.187594322","rc":[{"batb":[[0,1.77,3],[1,1.71,42.25],[2,1.01,7]],"ltp":1.71,"tv":278.79,"id":9628072}]}]}
{"op":"mcm","clk":"4231082287","pt":1631539576979,"mc":[{"id":"1.187594322","rc":[{"batb":[[0,1.86,404.05],[1,1.01,7],[2,1.01,0]],"ltp":2.58,"tv":16.87,"id":7429606},{"batb":[[1,1.01,7],[2,1.01,0]],"ltp":1.71,"tv":278.79,"id":9628072}]}]}
{"op":"mcm","clk":"4231082396","pt":1631539578286,"mc":[{"id":"1.187594322","rc":[{"batb":[[0,1.01,7],[1,1.01,0]],"ltp":2.58,"tv":16.87,"id":7429606}]}]}
{"op":"mcm","clk":"4231082498","pt":1631539579421,"mc":[{"id":"1.187594322","rc":[{"batb":[[0,1.87,3],[1,1.77,3],[2,1.01,7]],"ltp":1.71,"tv":278.79,"id":9628072}]}]}
{"op":"mcm","clk":"4231082761","pt":1631539582002,"mc":[{"id":"1.187594322","rc":[{"batb":[[0,1.88,34.09],[1,1.01,7]],"ltp":2.58,"tv":16.87,"id":7429606},{"batb":[[1,1.85,35.29],[2,1.77,3]],"ltp":1.71,"tv":278.79,"id":9628072}]}]}
{"op":"mcm","clk":"4231082946","pt":1631539583980,"mc":[{"id":"1.187594322","rc":[{"batb":[[1,1.67,415.35],[2,1.01,7]],"batl":[[0,2.72,244.84]],"ltp":2.58,"tv":16.87,"id":7429606}]}]}
{"op":"mcm","clk":"4231084409","pt":1631539603104,"mc":[{"id":"1.187594322","rc":[{"batl":[[0,1.94,3],[1,2.72,244.84]],"ltp":2.58,"tv":16.87,"id":7429606}]}]}
{"op":"mcm","clk":"4231084694","pt":1631539606439,"mc":[{"id":"1.187594322","rc":[{"batb":[[0,1.67,415.35],[1,1.01,7],[2,1.01,0]],"ltp":2.58,"tv":16.87,"id":7429606},{"batb":[[1,1.77,3],[2,1.01,7]],"ltp":1.71,"tv":278.79,"id":9628072}]}]}
{"op":"mcm","clk":"4231084876","pt":1631539607755,"mc":[{"id":"1.187594322","rc":[{"batl":[[1,2.72,0]],"ltp":2.58,"tv":16.87,"id":7429606}]}]}
{"op":"mcm","clk":"4231085172","pt":1631539611449,"mc":[{"id":"1.187594322","rc":[{"batb":[[0,1.78,38.46],[1,1.67,415.35],[2,1.01,7]],"ltp":2.58,"tv":16.87,"id":7429606},{"batb":[[0,1.98,30.61],[1,1.87,3],[2,1.77,3]],"ltp":1.71,"tv":278.79,"id":9628072}]}]}
{"op":"mcm","clk":"4231085297","pt":1631539613117,"mc":[{"id":"1.187594322","rc":[{"batl":[[1,2.5,278.28]],"ltp":2.58,"tv":16.87,"id":7429606}]}]}
{"op":"mcm","clk":"4231086664","pt":1631539630059,"mc":[{"id":"1.187594322","rc":[{"batb":[[0,1.67,415.35],[1,1.01,7],[2,1.01,0]],"ltp":2.58,"tv":16.87,"id":7429606},{"batb":[[0,1.87,3],[1,1.77,3],[2,1.01,7]],"ltp":1.71,"tv":278.79,"id":9628072}]}]}
{"op":"mcm","clk":"4231087093","pt":1631539635447,"mc":[{"id":"1.187594322","rc":[{"batb":[[0,1.88,34.09],[1,1.82,8],[2,1.67,415.35]],"ltp":2.58,"tv":16.87,"id":7429606},{"batb":[[0,1.88,34.09],[1,1.87,3],[2,1.77,3]],"ltp":1.71,"tv":278.79,"id":9628072}]}]}
{"op":"mcm","clk":"4231090067","pt":1631539672506,"mc":[{"id":"1.187594322","rc":[{"batb":[[1,1.67,415.35],[2,1.01,7]],"ltp":2.58,"tv":16.87,"id":7429606}]}]}
{"op":"mcm","clk":"4231091217","pt":1631539685695,"mc":[{"id":"1.187594322","rc":[{"batb":[[0,1.67,415.35],[1,1.01,7],[2,1.01,0]],"ltp":2.58,"tv":16.87,"id":7429606},{"batb":[[0,1.87,3],[1,1.77,3],[2,1.01,7]],"ltp":1.71,"tv":278.79,"id":9628072}]}]}
{"op":"mcm","clk":"4231091621","pt":1631539690696,"mc":[{"id":"1.187594322","rc":[{"batb":[[0,1.71,42.25],[1,1.67,415.35],[2,1.01,7]],"ltp":2.58,"tv":16.87,"id":7429606},{"batb":[[0,2.06,28.3],[1,1.87,3],[2,1.77,3]],"ltp":1.71,"tv":278.79,"id":9628072}]}]}
{"op":"mcm","clk":"4231091866","pt":1631539693710,"mc":[{"id":"1.187594322","rc":[{"batb":[[0,1.72,10],[1,1.71,42.25],[2,1.67,415.35]],"ltp":2.58,"tv":16.87,"id":7429606}]}]}
{"op":"mcm","clk":"4231093169","pt":1631539711084,"mc":[{"id":"1.187594322","rc":[{"batb":[[1,1.67,415.35],[2,1.01,7]],"ltp":2.58,"tv":16.87,"id":7429606},{"batb":[[0,1.87,3],[1,1.77,3],[2,1.01,7]],"ltp":1.71,"tv":278.79,"id":9628072}]}]}
{"op":"mcm","clk":"4231093268","pt":1631539712386,"mc":[{"id":"1.187594322","rc":[{"batb":[[1,1.01,7],[2,1.01,0]],"ltp":2.58,"tv":16.87,"id":7429606}]}]}
{"op":"mcm","clk":"4231093580","pt":1631539716040,"mc":[{"id":"1.187594322","rc":[{"batb":[[1,1.65,46.15],[2,1.01,7]],"ltp":2.58,"tv":16.87,"id":7429606},{"batb":[[0,2.1,27.27],[1,1.87,3],[2,1.77,3]],"ltp":1.71,"tv":278.79,"id":9628072}]}]}
{"op":"mcm","clk":"4231093797","pt":1631539718603,"mc":[{"id":"1.187594322","rc":[{"batb":[[2,1.55,426.23]],"ltp":2.58,"tv":16.87,"id":7429606}]}]}
{"op":"mcm","clk":"4231093856","pt":1631539719231,"mc":[{"id":"1.187594322","rc":[{"batb":[[0,1.65,46.15],[1,1.55,426.23],[2,1.01,7]],"ltp":2.58,"tv":16.87,"id":7429606}]}]}
{"op":"mcm","clk":"4231097077","pt":1631539757092,"mc":[{"id":"1.187594322","rc":[{"batb":[[0,1.55,426.23],[1,1.01,7],[2,1.01,0]],"batl":[[1,2.5,0]],"ltp":2.58,"tv":16.87,"id":7429606},{"batb":[[0,1.87,3],[1,1.77,3],[2,1.01,7]],"ltp":1.71,"tv":278.79,"id":9628072}]}]}
{"op":"mcm","clk":"4231097495","pt":1631539761778,"mc":[{"id":"1.187594322","rc":[{"batb":[[0,1.58,51.72],[1,1.55,426.23],[2,1.01,7]],"ltp":2.58,"tv":16.87,"id":7429606},{"batb":[[0,2.26,23.8],[1,1.87,3],[2,1.77,3]],"ltp":1.71,"tv":278.79,"id":9628072}]}]}
{"op":"mcm","clk":"4231097584","pt":1631539762879,"mc":[{"id":"1.187594322","rc":[{"batl":[[1,2.3,313.97]],"ltp":2.58,"tv":16.87,"id":7429606}]}]}
{"op":"mcm","clk":"4231098924","pt":1631539778990,"mc":[{"id":"1.187594322","rc":[{"batb":[[0,1.6,12],[1,1.58,51.72],[2,1.55,426.23]],"ltp":2.58,"tv":16.87,"id":7429606}]}]}
{"op":"mcm","clk":"4231099733","pt":1631539788179,"mc":[{"id":"1.187594322","rc":[{"batb":[[0,1.78,3],[1,1.6,12],[2,1.58,51.72]],"ltp":2.58,"tv":16.87,"id":7429606}]}]}
{"op":"mcm","clk":"4231100050","pt":1631539792297,"mc":[{"id":"1.187594322","rc":[{"batb":[[2,1.55,426.23]],"ltp":2.58,"tv":16.87,"id":7429606},{"batb":[[0,1.87,3],[1,1.77,3],[2,1.01,7]],"ltp":1.71,"tv":278.79,"id":9628072}]}]}
{"op":"mcm","clk":"4231100144","pt":1631539793604,"mc":[{"id":"1.187594322","rc":[{"batb":[[2,1.01,7]],"batl":[[1,2.3,0]],"ltp":2.58,"tv":16.87,"id":7429606}]}]}
{"op":"mcm","clk":"4231100439","pt":1631539797311,"mc":[{"id":"1.187594322","rc":[{"trd":[[1.78,3]],"batb":[[0,1.6,12],[1,1.51,58.82]],"ltp":1.78,"tv":19.87,"id":7429606},{"trd":[[2.3,2.32]],"batb":[[0,2.42,18.8],[1,1.87,3],[2,1.77,3]],"ltp":2.3,"tv":281.11,"id":9628072}],"tv":300.98}]}
{"op":"mcm","clk":"4231100473","pt":1631539797726,"mc":[{"id":"1.187594322","rc":[{"batb":[[0,1.87,3],[1,1.77,3],[2,1.01,7]],"ltp":2.3,"tv":281.11,"id":9628072}]}]}
{"op":"mcm","clk":"4231100614","pt":1631539799196,"mc":[{"id":"1.187594322","rc":[{"batb":[[2,1.44,442.12]],"batl":[[1,2.16,347.49]],"ltp":1.78,"tv":19.87,"id":7429606}]}]}
{"op":"mcm","clk":"4231100807","pt":1631539801607,"mc":[{"id":"1.187594322","rc":[{"batl":[[0,1.78,2],[1,1.94,3],[2,2.16,347.49]],"ltp":1.78,"tv":19.87,"id":7429606}]}]}
{"op":"mcm","clk":"4231100896","pt":1631539802538,"mc":[{"id":"1.187594322","rc":[{"batb":[[0,1.51,58.82],[1,1.44,442.12],[2,1.01,7]],"batl":[[0,1.94,3],[1,2.16,347.49],[2,2.16,0]],"ltp":1.78,"tv":19.87,"id":7429606},{"batb":[[0,2.42,21.12],[1,1.87,3],[2,1.77,3]],"ltp":2.3,"tv":281.11,"id":9628072}]}]}
{"op":"mcm","clk":"4231102531","pt":1631539822644,"mc":[{"id":"1.187594322","rc":[{"batl":[[0,1.7,4],[1,1.94,3],[2,2.16,347.49]],"ltp":1.78,"tv":19.87,"id":7429606}]}]}
{"op":"mcm","clk":"4231103168","pt":1631539830480,"mc":[{"id":"1.187594322","rc":[{"batb":[[0,1.44,442.12],[1,1.01,7],[2,1.01,0]],"ltp":1.78,"tv":19.87,"id":7429606},{"batb":[[0,1.87,3],[1,1.77,3],[2,1.01,7]],"ltp":2.3,"tv":281.11,"id":9628072}]}]}
{"op":"mcm","clk":"4231103286","pt":1631539832211,"mc":[{"id":"1.187594322","rc":[{"batb":[[0,1.01,7],[1,1.01,0]],"batl":[[2,2.16,0]],"ltp":1.78,"tv":19.87,"id":7429606}]}]}
{"op":"mcm","clk":"4231103560","pt":1631539835510,"mc":[{"id":"1.187594322","rc":[{"batb":[[0,1.45,66.66],[1,1.01,7]],"ltp":1.78,"tv":19.87,"id":7429606},{"batb":[[0,2.58,18.98],[1,1.87,3],[2,1.77,3]],"ltp":2.3,"tv":281.11,"id":9628072}]}]}
{"op":"mcm","clk":"4231103775","pt":1631539837801,"mc":[{"id":"1.187594322","rc":[{"batb":[[1,1.38,454.56],[2,1.01,7]],"batl":[[2,2.04,388.23]],"ltp":1.78,"tv":19.87,"id":7429606}]}]}
{"op":"mcm","clk":"4231104685","pt":1631539847731,"mc":[{"id":"1.187594322","rc":[{"batb":[[0,1.38,454.56],[1,1.01,7],[2,1.01,0]],"ltp":1.78,"tv":19.87,"id":7429606},{"batb":[[0,1.87,3],[1,1.77,3],[2,1.01,7]],"ltp":2.3,"tv":281.11,"id":9628072}]}]}
{"op":"mcm","clk":"4231104973","pt":1631539850125,"mc":[{"id":"1.187594322","rc":[{"batl":[[0,1.54,3],[1,1.7,4],[2,1.94,3]],"ltp":1.78,"tv":19.87,"id":7429606}]}]}
{"op":"mcm","clk":"4231105092","pt":1631539851330,"mc":[{"id":"1.187594322","rc":[{"batl":[[0,1.45,72.27],[1,1.54,3],[2,1.7,4]],"ltp":1.78,"tv":19.87,"id":7429606}]}]}
{"op":"mcm","clk":"4231105214","pt":1631539852635,"mc":[{"id":"1.187594322","rc":[{"batb":[[0,1.42,71.42],[1,1.38,454.56],[2,1.01,7]],"ltp":1.78,"tv":19.87,"id":7429606},{"batb":[[0,2.66,18.07],[1,1.87,3],[2,1.77,3]],"ltp":2.3,"tv":281.11,"id":9628072}]}]}
{"op":"mcm","clk":"4231105304","pt":1631539853620,"mc":[{"id":"1.187594322","rc":[{"batl":[[0,1.54,3],[1,1.7,4],[2,1.94,3]],"ltp":1.78,"tv":19.87,"id":7429606}]}]}
{"op":"mcm","clk":"4231106242","pt":1631539863638,"mc":[{"id":"1.187594322","rc":[{"trd":[[1.42,142.84]],"batb":[[0,1.38,454.56],[1,1.01,7],[2,1.01,0]],"batl":[[0,1.54,3.85]],"ltp":1.42,"tv":162.7,"id":7429606}],"tv":443.82}]}
{"op":"mcm","clk":"4231106344","pt":1631539864842,"mc":[{"id":"1.187594322","rc":[{"batb":[[0,1.87,3],[1,1.77,3],[2,1.01,7]],"ltp":2.3,"tv":281.11,"id":9628072}]}]}
{"op":"mcm","clk":"4231106502","pt":1631539866558,"mc":[{"id":"1.187594322","rc":[{"batl":[[0,1.54,3]],"ltp":1.42,"tv":162.7,"id":7429606}]}]}
{"op":"mcm","clk":"4231106654","pt":1631539868370,"mc":[{"id":"1.187594322","rc":[{"batl":[[0,1.49,3],[1,1.54,3],[2,1.7,4]],"ltp":1.42,"tv":162.7,"id":7429606}]}]}
{"op":"mcm","clk":"4231106804","pt":1631539869851,"mc":[{"id":"1.187594322","rc":[{"batb":[[0,2.84,16.3],[1,1.87,3],[2,1.77,3]],"ltp":2.3,"tv":281.11,"id":9628072}]}]}
{"op":"mcm","clk":"4231107158","pt":1631539873921,"mc":[{"id":"1.187594322","rc":[{"batb":[[0,1.38,533.5]],"ltp":1.42,"tv":162.7,"id":7429606}]}]}
{"op":"mcm","clk":"4231108293","pt":1631539886848,"mc":[{"id":"1.187594322","rc":[{"batl":[[0,1.44,3],[1,1.49,3],[2,1.54,3]],"ltp":1.42,"tv":162.7,"id":7429606}]}]}
{"op":"mcm","clk":"4231108598","pt":1631539890384,"mc":[{"id":"1.187594322","rc":[{"batl":[[1,1.54,3],[2,1.7,4]],"ltp":1.42,"tv":162.7,"id":7429606}]}]}
{"op":"mcm","clk":"4231108730","pt":1631539891761,"mc":[{"id":"1.187594322","rc":[{"batl":[[0,1.54,3],[1,1.7,4],[2,1.94,3]],"ltp":1.42,"tv":162.7,"id":7429606}]}]}
{"op":"mcm","clk":"4231111091","pt":1631539917484,"mc":[{"id":"1.187594322","rc":[{"batb":[[0,1.42,12],[1,1.38,533.5],[2,1.01,7]],"ltp":1.42,"tv":162.7,"id":7429606}]}]}
{"op":"mcm","clk":"4231112595","pt":1631539932888,"mc":[{"id":"1.187594322","rc":[{"batl":[[0,1.46,3],[1,1.54,3],[2,1.7,4]],"ltp":1.42,"tv":162.7,"id":7429606}]}]}
{"op":"mcm","clk":"4231117158","pt":1631539984022,"mc":[{"id":"1.187594322","rc":[{"batb":[[1,1.38,454.56]],"ltp":1.42,"tv":162.7,"id":7429606},{"batb":[[0,1.87,3],[1,1.77,3],[2,1.01,7]],"ltp":2.3,"tv":281.11,"id":9628072}]}]}
{"op":"mcm","clk":"4231117361","pt":1631539986414,"mc":[{"id":"1.187594322","rc":[{"batb":[[1,1.01,7],[2,1.01,0]],"ltp":1.42,"tv":162.7,"id":7429606}]}]}
{"op":"mcm","clk":"4231117557","pt":1631539989006,"mc":[{"id":"1.187594322","rc":[{"batb":[[1,1.34,88.23],[2,1.01,7]],"ltp":1.42,"tv":162.7,"id":7429606},{"batb":[[0,3,15],[1,1.87,3],[2,1.77,3]],"ltp":2.3,"tv":281.11,"id":9628072}]}]}
{"op":"mcm","clk":"4231117834","pt":1631539992532,"mc":[{"id":"1.187594322","rc":[{"batb":[[2,1.28,492.51]],"ltp":1.42,"tv":162.7,"id":7429606}]}]}
{"op":"mcm","clk":"4231118086","pt":1631539995607,"mc":[{"id":"1.187594322","rc":[{"batb":[[0,1.34,88.23],[1,1.28,492.51],[2,1.01,7]],"ltp":1.42,"tv":162.7,"id":7429606}]}]}
{"op":"mcm","clk":"4231121333","pt":1631540034453,"mc":[{"id":"1.187594322","rc":[{"batb":[[0,1.37,12],[1,1.34,88.23],[2,1.28,492.51]],"ltp":1.42,"tv":162.7,"id":7429606}]}]}
{"op":"mcm","clk":"4231123195","pt":1631540055073,"mc":[{"id":"1.187594322","rc":[{"batb":[[0,1.44,3],[1,1.37,12],[2,1.34,88.23]],"ltp":1.42,"tv":162.7,"id":7429606}]}]}
{"op":"mcm","clk":"4231125552","pt":1631540083415,"mc":[{"id":"1.187594322","rc":[{"batb":[[0,1.37,12],[1,1.34,88.23],[2,1.23,523.51]],"ltp":1.42,"tv":162.7,"id":7429606}]}]}
{"op":"mcm","clk":"4231128029","pt":1631540113060,"mc":[{"id":"1.187594322","rc":[{"batb":[[0,1.34,88.23],[1,1.23,523.51],[2,1.01,7]],"ltp":1.42,"tv":162.7,"id":7429606}]}]}
{"op":"mcm","clk":"4231128153","pt":1631540114678,"mc":[{"id":"1.187594322","rc":[{"batb":[[0,1.23,523.51],[1,1.01,7],[2,1.01,0]],"ltp":1.42,"tv":162.7,"id":7429606},{"batb":[[0,1.87,3],[1,1.77,3],[2,1.01,7]],"ltp":2.3,"tv":281.11,"id":9628072}]}]}
{"op":"mcm","clk":"4231128288","pt":1631540116163,"mc":[{"id":"1.187594322","rc":[{"batb":[[0,1.01,7],[1,1.01,0]],"ltp":1.42,"tv":162.7,"id":7429606}]}]}
{"op":"mcm","clk":"4231128576","pt":1631540119671,"mc":[{"id":"1.187594322","rc":[{"batb":[[0,1.28,107.14],[1,1.01,7]],"ltp":1.42,"tv":162.7,"id":7429606},{"batb":[[0,3.3,13.04],[1,1.87,3],[2,1.77,3]],"ltp":2.3,"tv":281.11,"id":9628072}]}]}
{"op":"mcm","clk":"4231128720","pt":1631540121360,"mc":[{"id":"1.187594322","rc":[{"batb":[[1,1.2,538.09],[2,1.01,7]],"batl":[[2,1.66,587.71]],"ltp":1.42,"tv":162.7,"id":7429606}]}]}
{"op":"mcm","clk":"4231130363","pt":1631540140470,"mc":[{"id":"1.187594322","rc":[{"batl":[[0,1.33,3],[1,1.46,3],[2,1.54,3]],"ltp":1.42,"tv":162.7,"id":7429606}]}]}
{"op":"mcm","clk":"4231137164","pt":1631540222028,"mc":[{"id":"1.187594322","rc":[{"batl":[[2,1.66,587.71]],"ltp":1.42,"tv":162.7,"id":7429606}]}]}
{"op":"mcm","clk":"4231138217","pt":1631540233947,"mc":[{"id":"1.187594322","rc":[{"batb":[[0,1.2,538.09],[1,1.01,7],[2,1.01,0]],"ltp":1.42,"tv":162.7,"id":7429606},{"batb":[[0,1.87,3],[1,1.77,3],[2,1.01,7]],"ltp":2.3,"tv":281.11,"id":9628072}]}]}
{"op":"mcm","clk":"4231138339","pt":1631540235878,"mc":[{"id":"1.187594322","rc":[{"batb":[[0,1.01,7],[1,1.01,0]],"ltp":1.42,"tv":162.7,"id":7429606}]}]}
{"op":"mcm","clk":"4231138573","pt":1631540238838,"mc":[{"id":"1.187594322","rc":[{"batb":[[0,3,15],[1,1.87,3],[2,1.77,3]],"ltp":2.3,"tv":281.11,"id":9628072}]}]}
{"op":"mcm","clk":"4231138799","pt":1631540241732,"mc":[{"id":"1.187594322","rc":[{"batb":[[0,1.23,523.51],[1,1.01,7]],"ltp":1.42,"tv":162.7,"id":7429606}]}]}
{"op":"mcm","clk":"4231139838","pt":1631540255581,"mc":[{"id":"1.187594322","rc":[{"batb":[[0,1.87,3],[1,1.77,3],[2,1.01,7]],"ltp":2.3,"tv":281.11,"id":9628072}]}]}
{"op":"mcm","clk":"4231140223","pt":1631540260509,"mc":[{"id":"1.187594322","rc":[{"batb":[[0,1.31,96.77],[1,1.23,523.51],[2,1.01,7]],"ltp":1.42,"tv":162.7,"id":7429606},{"batb":[[0,3.15,13.95],[1,1.87,3],[2,1.77,3]],"ltp":2.3,"tv":281.11,"id":9628072}]}]}
{"op":"mcm","clk":"4231141535","pt":1631540276087,"mc":[{"id":"1.187594322","rc":[{"batb":[[0,1.23,523.51],[1,1.01,7],[2,1.01,0]],"ltp":1.42,"tv":162.7,"id":7429606},{"batb":[[0,1.87,3],[1,1.77,3],[2,1.01,7]],"ltp":2.3,"tv":281.11,"id":9628072}]}]}
{"op":"mcm","clk":"4231141665","pt":1631540277499,"mc":[{"id":"1.187594322","rc":[{"batb":[[0,1.01,7],[1,1.01,0]],"ltp":1.42,"tv":162.7,"id":7429606}]}]}
{"op":"mcm","clk":"4231141983","pt":1631540281099,"mc":[{"id":"1.187594322","rc":[{"batb":[[0,1.23,130.43],[1,1.01,7]],"ltp":1.42,"tv":162.7,"id":7429606},{"batb":[[0,3.7,11.11],[1,1.87,3],[2,1.77,3]],"ltp":2.3,"tv":281.11,"id":9628072}]}]}
{"op":"mcm","clk":"4231142165","pt":1631540283318,"mc":[{"id":"1.187594322","rc":[{"batb":[[1,1.18,557.21],[2,1.01,7]],"ltp":1.42,"tv":162.7,"id":7429606}]}]}
{"op":"mcm","clk":"4231142794","pt":1631540291316,"mc":[{"id":"1.187594322","rc":[{"batb":[[0,1.18,557.21],[1,1.01,7],[2,1.01,0]],"ltp":1.42,"tv":162.7,"id":7429606},{"batb":[[0,1.87,3],[1,1.77,3],[2,1.01,7]],"ltp":2.3,"tv":281.11,"id":9628072}]}]}
{"op":"mcm","clk":"4231143198","pt":1631540296316,"mc":[{"id":"1.187594322","rc":[{"batb":[[0,1.27,111.11],[1,1.18,557.21],[2,1.01,7]],"ltp":1.42,"tv":162.7,"id":7429606},{"batb":[[0,3.4,12.5],[1,1.87,3],[2,1.77,3]],"ltp":2.3,"tv":281.11,"id":9628072}]}]}
{"op":"mcm","clk":"4231143686","pt":1631540302618,"mc":[{"id":"1.187594322","rc":[{"batb":[[0,1.28,8],[1,1.27,111.11],[2,1.18,557.21]],"ltp":1.42,"tv":162.7,"id":7429606}]}]}
{"op":"mcm","clk":"4231144273","pt":1631540310967,"mc":[{"id":"1.187594322","rc":[{"batb":[[1,1.18,557.21],[2,1.01,7]],"batl":[[2,1.66,0]],"ltp":1.42,"tv":162.7,"id":7429606},{"batb":[[0,1.87,3],[1,1.77,3],[2,1.01,7]],"ltp":2.3,"tv":281.11,"id":9628072}]}]}
{"op":"mcm","clk":"4231144621","pt":1631540315554,"mc":[{"id":"1.187594322","rc":[{"batb":[[1,1.2,150],[2,1.18,557.21]],"ltp":1.42,"tv":162.7,"id":7429606},{"batb":[[0,4,10],[1,1.87,3],[2,1.77,3]],"ltp":2.3,"tv":281.11,"id":9628072}]}]}
{"op":"mcm","clk":"4231144691","pt":1631540316395,"mc":[{"id":"1.187594322","rc":[{"batl":[[2,1.58,659.44]],"ltp":1.42,"tv":162.7,"id":7429606}]}]}
{"op":"mcm","clk":"4231145404","pt":1631540324808,"mc":[{"id":"1.187594322","rc":[{"trd":[[1.2,25.42],[1.28,16]],"batb":[[0,1.18,557.21],[1,1.01,7],[2,1.18,0]],"ltp":1.2,"tv":204.12,"id":7429606}],"tv":485.24}]}
{"op":"mcm","clk":"4231145814","pt":1631540329842,"mc":[{"id":"1.187594322","rc":[{"batb":[[0,1.2,150],[1,1.18,557.21],[2,1.01,7]],"ltp":1.2,"tv":204.12,"id":7429606}]}]}
{"op":"mcm","clk":"4231146352","pt":1631540336635,"mc":[{"id":"1.187594322","rc":[{"trd":[[4,0.32]],"batb":[[0,4,9.84]],"ltp":4.0,"tv":281.43,"id":9628072}],"tv":485.55}]}
{"op":"mcm","clk":"4231146374","pt":1631540336846,"mc":[{"id":"1.187594322","rc":[{"batb":[[0,1.87,3],[1,1.77,3],[2,1.01,7]],"ltp":4.0,"tv":281.43,"id":9628072}]}]}
{"op":"mcm","clk":"4231146802","pt":1631540341831,"mc":[{"id":"1.187594322","rc":[{"batb":[[0,4,10],[1,1.87,3],[2,1.77,3]],"ltp":4.0,"tv":281.43,"id":9628072}]}]}
{"op":"mcm","clk":"4231148491","pt":1631540360958,"mc":[{"id":"1.187594322","rc":[{"batb":[[0,1.18,557.21],[1,1.01,7],[2,1.01,0]],"ltp":1.2,"tv":204.12,"id":7429606},{"batb":[[0,1.87,3],[1,1.77,3],[2,1.01,7]],"ltp":4.0,"tv":281.43,"id":9628072}]}]}
{"op":"mcm","clk":"4231148987","pt":1631540365981,"mc":[{"id":"1.187594322","rc":[{"batb":[[0,1.23,130.43],[1,1.18,557.21],[2,1.01,7]],"ltp":1.2,"tv":204.12,"id":7429606},{"batb":[[0,3.7,11.11],[1,1.87,3],[2,1.77,3]],"ltp":4.0,"tv":281.43,"id":9628072}]}]}
{"op":"mcm","clk":"4231150789","pt":1631540389012,"mc":[{"id":"1.187594322","rc":[{"batb":[[0,1.26,8],[1,1.23,130.43],[2,1.18,557.21]],"ltp":1.2,"tv":204.12,"id":7429606}]}]}
{"op":"mcm","clk":"4231151244","pt":1631540394836,"mc":[{"id":"1.187594322","rc":[{"batb":[[1,1.18,557.21],[2,1.01,7]],"ltp":1.2,"tv":204.12,"id":7429606},{"batb":[[0,1.87,3],[1,1.77,3],[2,1.01,7]],"ltp":4.0,"tv":281.43,"id":9628072}]}]}
{"op":"mcm","clk":"4231151548","pt":1631540398728,"mc":[{"id":"1.187594322","rc":[{"batl":[[0,1.46,3],[1,1.58,659.44],[2,1.58,0]],"ltp":1.2,"tv":204.12,"id":7429606}]}]}
{"op":"mcm","clk":"4231151645","pt":1631540399829,"mc":[{"id":"1.187594322","rc":[{"batb":[[1,1.18,723.87]],"ltp":1.2,"tv":204.12,"id":7429606},{"batb":[[0,4.1,10],[1,1.87,3],[2,1.77,3]],"ltp":4.0,"tv":281.43,"id":9628072}]}]}
{"op":"mcm","clk":"4231152717","pt":1631540411638,"mc":[{"id":"1.187594322","rc":[{"batb":[[0,1.18,723.87],[1,1.01,7],[2,1.01,0]],"ltp":1.2,"tv":204.12,"id":7429606}]}]}
{"op":"mcm","clk":"4231154287","pt":1631540430449,"mc":[{"id":"1.187594322","rc":[{"batb":[[0,1.22,10],[1,1.18,723.87],[2,1.01,7]],"ltp":1.2,"tv":204.12,"id":7429606}]}]}
{"op":"mcm","clk":"4231157887","pt":1631540472523,"mc":[{"id":"1.187594322","rc":[{"batb":[[1,1.18,557.21]],"ltp":1.2,"tv":204.12,"id":7429606},{"batb":[[0,1.87,3],[1,1.77,3],[2,1.01,7]],"ltp":4.0,"tv":281.43,"id":9628072}]}]}
{"op":"mcm","clk":"4231157974","pt":1631540473517,"mc":[{"id":"1.187594322","rc":[{"batb":[[1,1.01,7],[2,1.01,0]],"batl":[[1,1.58,0]],"ltp":1.2,"tv":204.12,"id":7429606}]}]}
{"op":"mcm","clk":"4231158526","pt":1631540479627,"mc":[{"id":"1.187594322","rc":[{"batb":[[1,1.12,659.2],[2,1.01,7]],"batl":[[1,1.51,751.18]],"ltp":1.2,"tv":204.12,"id":7429606}]}]}
{"op":"mcm","clk":"4231158580","pt":1631540480517,"mc":[{"id":"1.187594322","rc":[{"batb":[[1,1.01,7],[2,1.01,0]],"ltp":1.2,"tv":204.12,"id":7429606}]}]}
{"op":"mcm","clk":"4231158760","pt":1631540482505,"mc":[{"id":"1.187594322","rc":[{"batb":[[1,1.18,166.66],[2,1.01,7]],"ltp":1.2,"tv":204.12,"id":7429606},{"batb":[[0,4.1,10],[1,1.87,3],[2,1.77,3]],"ltp":4.0,"tv":281.43,"id":9628072}]}]}
{"op":"mcm","clk":"4231158788","pt":1631540482818,"mc":[{"id":"1.187594322","rc":[{"batb":[[1,1.01,7],[2,1.01,0]],"ltp":1.2,"tv":204.12,"id":7429606},{"batb":[[0,1.87,3],[1,1.77,3],[2,1.01,7]],"ltp":4.0,"tv":281.43,"id":9628072}]}]}
{"op":"mcm","clk":"4231159116","pt":1631540486734,"mc":[{"id":"1.187594322","rc":[{"batb":[[1,1.18,557.21],[2,1.01,7]],"ltp":1.2,"tv":204.12,"id":7429606}]}]}
{"op":"mcm","clk":"4231159201","pt":1631540487728,"mc":[{"id":"1.187594322","rc":[{"batb":[[0,1.23,130.43],[1,1.22,10],[2,1.18,557.21]],"ltp":1.2,"tv":204.12,"id":7429606},{"batb":[[0,3.7,11.11],[1,1.87,3],[2,1.77,3]],"ltp":4.0,"tv":281.43,"id":9628072}]}]}
{"op":"mcm","clk":"4231160199","pt":1631540499113,"mc":[{"id":"1.187594322","rc":[{"batb":[[0,1.22,10],[1,1.18,557.21],[2,1.01,7]],"ltp":1.2,"tv":204.12,"id":7429606},{"batb":[[0,1.87,3],[1,1.77,3],[2,1.01,7]],"ltp":4.0,"tv":281.43,"id":9628072}]}]}
{"op":"mcm","clk":"4231160325","pt":1631540500846,"mc":[{"id":"1.187594322","rc":[{"batb":[[1,1.01,7],[2,1.01,0]],"batl":[[1,1.51,0]],"ltp":1.2,"tv":204.12,"id":7429606}]}]}
{"op":"mcm","clk":"4231160588","pt":1631540504050,"mc":[{"id":"1.187594322","rc":[{"batb":[[0,1.28,107.14],[1,1.22,10],[2,1.01,7]],"ltp":1.2,"tv":204.12,"id":7429606},{"batb":[[0,3.3,13.04],[1,1.87,3],[2,1.77,3]],"ltp":4.0,"tv":281.43,"id":9628072}]}]}
{"op":"mcm","clk":"4231160841","pt":1631540506959,"mc":[{"id":"1.187594322","rc":[{"batb":[[2,1.2,538.09]],"batl":[[1,1.66,587.71]],"ltp":1.2,"tv":204.12,"id":7429606}]}]}
{"op":"mcm","clk":"4231161356","pt":1631540514415,"mc":[{"id":"1.187594322","rc":[{"batb":[[0,1.22,10],[1,1.2,538.09],[2,1.01,7]],"ltp":1.2,"tv":204.12,"id":7429606},{"batb":[[0,1.87,3],[1,1.77,3],[2,1.01,7]],"ltp":4.0,"tv":281.43,"id":9628072}]}]}
{"op":"mcm","clk":"4231161770","pt":1631540519408,"mc":[{"id":"1.187594322","rc":[{"batb":[[0,1.23,130.43],[1,1.22,10],[2,1.2,538.09]],"ltp":1.2,"tv":204.12,"id":7429606},{"batb":[[0,3.7,11.11],[1,1.87,3],[2,1.77,3]],"ltp":4.0,"tv":281.43,"id":9628072}]}]}
{"op":"mcm","clk":"4231163027","pt":1631540534345,"mc":[{"id":"1.187594322","rc":[{"batb":[[2,1.01,7]],"batl":[[1,1.66,0]],"ltp":1.2,"tv":204.12,"id":7429606}]}]}
{"op":"mcm","clk":"4231163962","pt":1631540545220,"mc":[{"id":"1.187594322","rc":[{"batb":[[0,1.22,10],[1,1.01,7],[2,1.01,0]],"ltp":1.2,"tv":204.12,"id":7429606},{"batb":[[0,1.87,3],[1,1.77,3],[2,1.01,7]],"ltp":4.0,"tv":281.43,"id":9628072}]}]}
{"op":"mcm","clk":"4231164414","pt":1631540550150,"mc":[{"id":"1.187594322","rc":[{"batb":[[0,1.28,107.14],[1,1.22,10],[2,1.01,7]],"ltp":1.2,"tv":204.12,"id":7429606},{"batb":[[0,3.3,13.04],[1,1.87,3],[2,1.77,3]],"ltp":4.0,"tv":281.43,"id":9628072}]}]}
{"op":"mcm","clk":"4231165438","pt":1631540561178,"mc":[{"id":"1.187594322","rc":[{"batb":[[0,1.22,10],[1,1.01,7],[2,1.01,0]],"ltp":1.2,"tv":204.12,"id":7429606},{"batb":[[0,1.87,3],[1,1.77,3],[2,1.01,7]],"ltp":4.0,"tv":281.43,"id":9628072}]}]}
{"op":"mcm","clk":"4231165869","pt":1631540566157,"mc":[{"id":"1.187594322","rc":[{"batb":[[0,1.27,111.11],[1,1.22,10],[2,1.01,7]],"ltp":1.2,"tv":204.12,"id":7429606},{"batb":[[0,3.4,12.5],[1,1.87,3],[2,1.77,3]],"ltp":4.0,"tv":281.43,"id":9628072}]}]}
{"op":"mcm","clk":"4231167329","pt":1631540582075,"mc":[{"id":"1.187594322","rc":[{"batb":[[0,1.22,10],[1,1.01,7],[2,1.01,0]],"ltp":1.2,"tv":204.12,"id":7429606},{"batb":[[0,1.87,3],[1,1.77,3],[2,1.01,7]],"ltp":4.0,"tv":281.43,"id":9628072}]}]}
{"op":"mcm","clk":"4231167809","pt":1631540587077,"mc":[{"id":"1.187594322","rc":[{"batb":[[0,1.31,96.77],[1,1.22,10],[2,1.01,7]],"ltp":1.2,"tv":204.12,"id":7429606},{"batb":[[0,3.15,13.95],[1,1.87,3],[2,1.77,3]],"ltp":4.0,"tv":281.43,"id":9628072}]}]}
{"op":"mcm","clk":"4231169962","pt":1631540609102,"mc":[{"id":"1.187594322","rc":[{"batb":[[1,1.77,3],[2,1.01,7]],"ltp":4.0,"tv":281.43,"id":9628072}]}]}
{"op":"mcm","clk":"4231170085","pt":1631540610399,"mc":[{"id":"1.187594322","rc":[{"batb":[[0,1.35,5],[1,1.31,96.77],[2,1.22,10]],"ltp":1.2,"tv":204.12,"id":7429606},{"batb":[[1,1.01,7],[2,1.01,0]],"ltp":4.0,"tv":281.43,"id":9628072}]}]}
{"op":"mcm","clk":"4231171729","pt":1631540627620,"mc":[{"id":"1.187594322","rc":[{"batb":[[0,1.44,3],[1,1.35,5],[2,1.31,96.77]],"ltp":1.2,"tv":204.12,"id":7429606}]}]}
{"op":"mcm","clk":"4231172084","pt":1631540631611,"mc":[{"id":"1.187594322","rc":[{"batb":[[2,1.22,10]],"ltp":1.2,"tv":204.12,"id":7429606},{"batb":[[0,1.01,7],[1,1.01,0]],"ltp":4.0,"tv":281.43,"id":9628072}]}]}
{"op":"mcm","clk":"4231172563","pt":1631540636540,"mc":[{"id":"1.187594322","rc":[{"batb":[[1,1.38,78.94],[2,1.35,5]],"ltp":1.2,"tv":204.12,"id":7429606},{"batb":[[0,2.84,16.3],[1,1.01,7]],"ltp":4.0,"tv":281.43,"id":9628072}]}]}
{"op":"mcm","clk":"4231173891","pt":1631540649567,"mc":[{"id":"1.187594322","rc":[{"batb":[[0,1.51,3],[1,1.44,3],[2,1.38,78.94]],"ltp":1.2,"tv":204.12,"id":7429606}]}]}
{"op":"mcm","clk":"4231175173","pt":1631540662451,"mc":[{"id":"1.187594322","rc":[{"trd":[[1.51,6]],"batb":[[0,1.44,3],[1,1.35,5],[2,1.22,10]],"batl":[[0,1.51,5.94]],"ltp":1.51,"tv":210.12,"id":7429606},{"batb":[[0,1.01,7],[1,1.01,0]],"ltp":4.0,"tv":281.43,"id":9628072}],"tv":491.55}]}
{"op":"mcm","clk":"4231175293","pt":1631540663566,"mc":[{"id":"1.187594322","rc":[{"trd":[[1.51,10]],"batl":[[0,1.51,14.9]],"ltp":1.51,"tv":214.12,"id":7429606}],"tv":495.55}]}
{"op":"mcm","clk":"4231175377","pt":1631540664575,"mc":[{"id":"1.187594322","rc":[{"batl":[[0,1.51,11.92]],"ltp":1.51,"tv":214.12,"id":7429606}]}]}
{"op":"mcm","clk":"4231175459","pt":1631540665459,"mc":[{"id":"1.187594322","rc":[{"trd":[[1.51,21.96]],"batb":[[0,1.55,4.02],[1,1.44,3],[2,1.35,5]],"ltp":1.51,"tv":226.08,"id":7429606}],"tv":507.51}]}
{"op":"mcm","clk":"4231175487","pt":1631540665875,"mc":[{"id":"1.187594322","rc":[{"trd":[[1.55,8.04]],"batb":[[0,1.44,3],[1,1.35,5],[2,1.22,10]],"batl":[[0,1.5,65.56],[1,1.51,1.94]],"ltp":1.55,"tv":234.12,"id":7429606}],"tv":515.55}]}
{"op":"mcm","clk":"4231175612","pt":1631540667177,"mc":[{"id":"1.187594322","rc":[{"batb":[[2,1.31,96.77]],"batl":[[1,1.51,0]],"ltp":1.55,"tv":234.12,"id":7429606},{"batb":[[0,3.15,13.95],[1,1.01,7]],"ltp":4.0,"tv":281.43,"id":9628072}]}]}
{"op":"mcm","clk":"4231175827","pt":1631540669469,"mc":[{"id":"1.187594322","rc":[{"trd":[[1.44,5.96]],"batb":[[0,1.35,5.02],[1,1.31,96.77],[2,1.22,10]],"ltp":1.44,"tv":240.08,"id":7429606}],"tv":521.51}]}
{"op":"mcm","clk":"4231175942","pt":1631540670557,"mc":[{"id":"1.187594322","rc":[{"trd":[[1.44,6]],"batb":[[0,1.35,5]],"batl":[[0,1.44,11.94],[1,1.5,65.56]],"ltp":1.44,"tv":240.12,"id":7429606}],"tv":521.55}]}
{"op":"mcm","clk":"4231176069","pt":1631540671595,"mc":[{"id":"1.187594322","rc":[{"batl":[[2,1.55,18]],"ltp":1.44,"tv":240.12,"id":7429606}]}]}
{"op":"mcm","clk":"4231176210","pt":1631540672598,"mc":[{"id":"1.187594322","rc":[{"batl":[[0,1.44,29.96],[1,1.55,16],[2,1.55,0]],"ltp":1.44,"tv":240.12,"id":7429606}]}]}
{"op":"mcm","clk":"4231176301","pt":1631540673469,"mc":[{"id":"1.187594322","rc":[{"batl":[[0,1.44,9],[1,1.55,0]],"ltp":1.44,"tv":240.12,"id":7429606}]}]}
{"op":"mcm","clk":"4231176929","pt":1631540679359,"mc":[{"id":"1.187594322","rc":[{"batl":[[0,1.44,65.56]],"ltp":1.44,"tv":240.12,"id":7429606}]}]}
{"op":"mcm","clk":"4231177668","pt":1631540686984,"mc":[{"id":"1.187594322","rc":[{"batb":[[1,1.22,10],[2,1.01,7]],"ltp":1.44,"tv":240.12,"id":7429606},{"batb":[[0,1.01,7],[1,1.01,0]],"ltp":4.0,"tv":281.43,"id":9628072}]}]}
{"op":"mcm","clk":"4231178176","pt":1631540692001,"mc":[{"id":"1.187594322","rc":[{"batb":[[1,1.27,111.11],[2,1.22,10]],"ltp":1.44,"tv":240.12,"id":7429606},{"batb":[[0,3.4,12.5],[1,1.01,7]],"ltp":4.0,"tv":281.43,"id":9628072}]}]}
{"op":"mcm","clk":"4231178408","pt":1631540694290,"mc":[{"id":"1.187594322","rc":[{"batl":[[1,1.66,587.71]],"ltp":1.44,"tv":240.12,"id":7429606}]}]}
{"op":"mcm","clk":"4231179554","pt":1631540705111,"mc":[{"id":"1.187594322","rc":[{"batb":[[1,1.22,10],[2,1.2,538.09]],"ltp":1.44,"tv":240.12,"id":7429606},{"batb":[[0,1.01,7],[1,1.01,0]],"ltp":4.0,"tv":281.43,"id":9628072}]}]}
{"op":"mcm","clk":"4231180091","pt":1631540710049,"mc":[{"id":"1.187594322","rc":[{"batb":[[1,1.28,107.14],[2,1.22,10]],"ltp":1.44,"tv":240.12,"id":7429606},{"batb":[[0,3.3,13.04],[1,1.01,7]],"ltp":4.0,"tv":281.43,"id":9628072}]}]}
{"op":"mcm","clk":"4231180631","pt":1631540715607,"mc":[{"id":"1.187594322","rc":[{"batb":[[1,1.22,10],[2,1.01,7]],"batl":[[1,1.66,0]],"ltp":1.44,"tv":240.12,"id":7429606},{"batb":[[0,1.01,7],[1,1.01,0]],"ltp":4.0,"tv":281.43,"id":9628072}]}]}
{"op":"mcm","clk":"4231181084","pt":1631540719985,"mc":[{"id":"1.187594322","rc":[{"trd":[[1.35,5]],"batb":[[0,1.22,10],[1,1.2,150]],"ltp":1.35,"tv":245.12,"id":7429606},{"trd":[[3.9,1.73]],"ltp":3.9,"tv":283.16,"id":9628072}],"tv":528.28}]}
{"op":"mcm","clk":"4231181224","pt":1631540721478,"mc":[{"id":"1.187594322","rc":[{"batb":[[2,1.16,583.98]],"batl":[[1,1.58,659.44]],"ltp":1.35,"tv":245.12,"id":7429606}]}]}
{"op":"mcm","clk":"4231181409","pt":1631540723501,"mc":[{"id":"1.187594322","rc":[{"batl":[[0,1.35,14.82],[1,1.44,65.56],[2,1.58,659.44]],"ltp":1.35,"tv":245.12,"id":7429606}]}]}
{"op":"mcm","clk":"4231181524","pt":1631540724592,"mc":[{"id":"1.187594322","rc":[{"batl":[[0,1.35,9.88]],"ltp":1.35,"tv":245.12,"id":7429606}]}]}
{"op":"mcm","clk":"4231181632","pt":1631540725580,"mc":[{"id":"1.187594322","rc":[{"batl":[[0,1.44,65.56],[1,1.58,659.44],[2,1.58,0]],"ltp":1.35,"tv":245.12,"id":7429606},{"batb":[[0,3.95,10.16],[1,1.01,7]],"ltp":3.9,"tv":283.16,"id":9628072}]}]}
{"op":"mcm","clk":"4231182997","pt":1631540739314,"mc":[{"id":"1.187594322","rc":[{"batb":[[0,1.01,7],[1,1.01,0]],"ltp":3.9,"tv":283.16,"id":9628072}]}]}
{"op":"mcm","clk":"4231183155","pt":1631540741030,"mc":[{"id":"1.187594322","rc":[{"batb":[[2,1.01,7]],"ltp":1.35,"tv":245.12,"id":7429606}]}]}
{"op":"mcm","clk":"4231183454","pt":1631540744224,"mc":[{"id":"1.187594322","rc":[{"batb":[[0,3.7,11.11],[1,1.01,7]],"ltp":3.9,"tv":283.16,"id":9628072}]}]}
{"op":"mcm","clk":"4231183685","pt":1631540746926,"mc":[{"id":"1.187594322","rc":[{"batb":[[2,1.18,557.21]],"ltp":1.35,"tv":245.12,"id":7429606}]}]}
{"op":"mcm","clk":"4231183779","pt":1631540747812,"mc":[{"id":"1.187594322","rc":[{"batb":[[1,1.18,557.21],[2,1.01,7]],"ltp":1.35,"tv":245.12,"id":7429606},{"batb":[[0,1.01,7],[1,1.01,0]],"ltp":3.9,"tv":283.16,"id":9628072}]}]}
{"op":"mcm","clk":"4231183914","pt":1631540749112,"mc":[{"id":"1.187594322","rc":[{"batb":[[1,1.01,7],[2,1.01,0]],"ltp":1.35,"tv":245.12,"id":7429606}]}]}
{"op":"mcm","clk":"4231184251","pt":1631540752737,"mc":[{"id":"1.187594322","rc":[{"batb":[[0,1.27,111.11],[1,1.22,10],[2,1.01,7]],"ltp":1.35,"tv":245.12,"id":7429606},{"batb":[[0,3.4,12.5],[1,1.01,7]],"ltp":3.9,"tv":283.16,"id":9628072}]}]}
{"op":"mcm","clk":"4231184443","pt":1631540754660,"mc":[{"id":"1.187594322","rc":[{"batb":[[2,1.2,538.09]],"ltp":1.35,"tv":245.12,"id":7429606}]}]}
{"op":"mcm","clk":"4231186340","pt":1631540773777,"mc":[{"id":"1.187594322","rc":[{"batl":[[0,1.35,3],[1,1.44,65.56],[2,1.58,659.44]],"ltp":1.35,"tv":245.12,"id":7429606}]}]}
{"op":"mcm","clk":"4231186494","pt":1631540775485,"mc":[{"id":"1.187594322","rc":[{"batb":[[0,1.22,10],[1,1.01,7],[2,1.2,0]],"ltp":1.35,"tv":245.12,"id":7429606},{"batb":[[0,1.01,7],[1,1.01,0]],"ltp":3.9,"tv":283.16,"id":9628072}]}]}
{"op":"mcm","clk":"4231186921","pt":1631540779586,"mc":[{"id":"1.187594322","rc":[{"batl":[[1,1.58,659.44],[2,1.58,0]],"ltp":1.35,"tv":245.12,"id":7429606}]}]}
{"op":"mcm","clk":"4231186943","pt":1631540779793,"mc":[{"id":"1.187594322","rc":[{"batb":[[0,1.34,88.23],[1,1.22,10],[2,1.01,7]],"ltp":1.35,"tv":245.12,"id":7429606},{"batb":[[0,3,15],[1,1.01,7]],"ltp":3.9,"tv":283.16,"id":9628072}]}]}
{"op":"mcm","clk":"4231187079","pt":1631540781145,"mc":[{"id":"1.187594322","rc":[{"batb":[[1,1.23,523.51],[2,1.22,10]],"ltp":1.35,"tv":245.12,"id":7429606}]}]}
{"op":"mcm","clk":"4231187548","pt":1631540785688,"mc":[{"id":"1.187594322","rc":[{"batl":[[0,1.58,659.44],[1,1.58,0]],"ltp":1.35,"tv":245.12,"id":7429606}]}]}
{"op":"mcm","clk":"4231187931","pt":1631540789685,"mc":[{"id":"1.187594322","rc":[{"batl":[[0,1.49,65.56],[1,1.58,659.44]],"ltp":1.35,"tv":245.12,"id":7429606}]}]}
{"op":"mcm","clk":"4231188907","pt":1631540798875,"mc":[{"id":"1.187594322","rc":[{"batb":[[0,1.23,523.51],[1,1.22,10],[2,1.01,7]],"ltp":1.35,"tv":245.12,"id":7429606},{"batb":[[0,1.01,7],[1,1.01,0]],"ltp":3.9,"tv":283.16,"id":9628072}]}]}
{"op":"mcm","clk":"4231188996","pt":1631540799712,"mc":[{"id":"1.187594322","rc":[{"batb":[[0,1.22,10],[1,1.01,7],[2,1.01,0]],"ltp":1.35,"tv":245.12,"id":7429606}]}]}
{"op":"mcm","clk":"4231189406","pt":1631540803774,"mc":[{"id":"1.187594322","rc":[{"batb":[[0,1.27,111.11],[1,1.22,10],[2,1.01,7]],"ltp":1.35,"tv":245.12,"id":7429606},{"batb":[[0,3.4,12.5],[1,1.01,7]],"ltp":3.9,"tv":283.16,"id":9628072}]}]}
{"op":"mcm","clk":"4231189571","pt":1631540805385,"mc":[{"id":"1.187594322","rc":[{"batb":[[2,1.2,538.09]],"ltp":1.35,"tv":245.12,"id":7429606}]}]}
{"op":"mcm","clk":"4231190504","pt":1631540814798,"mc":[{"id":"1.187594322","rc":[{"batb":[[0,1.22,10],[1,1.2,538.09],[2,1.01,7]],"ltp":1.35,"tv":245.12,"id":7429606},{"batb":[[0,1.01,7],[1,1.01,0]],"ltp":3.9,"tv":283.16,"id":9628072}]}]}
{"op":"mcm","clk":"4231191043","pt":1631540819840,"mc":[{"id":"1.187594322","rc":[{"batb":[[0,1.28,107.14],[1,1.22,10],[2,1.2,538.09]],"ltp":1.35,"tv":245.12,"id":7429606},{"batb":[[0,3.3,13.04],[1,1.01,7]],"ltp":3.9,"tv":283.16,"id":9628072}]}]}
{"op":"mcm","clk":"4231192088","pt":1631540830341,"mc":[{"id":"1.187594322","rc":[{"batb":[[0,1.22,10],[1,1.2,538.09],[2,1.01,7]],"ltp":1.35,"tv":245.12,"id":7429606},{"batb":[[0,1.01,7],[1,1.01,0]],"ltp":3.9,"tv":283.16,"id":9628072}]}]}
{"op":"mcm","clk":"4231192282","pt":1631540832148,"mc":[{"id":"1.187594322","rc":[{"batb":[[1,1.01,7],[2,1.01,0]],"ltp":1.35,"tv":245.12,"id":7429606}]}]}
{"op":"mcm","clk":"4231192627","pt":1631540835250,"mc":[{"id":"1.187594322","rc":[{"batb":[[0,1.34,88.23],[1,1.22,10],[2,1.01,7]],"ltp":1.35,"tv":245.12,"id":7429606},{"batb":[[0,3,15],[1,1.01,7]],"ltp":3.9,"tv":283.16,"id":9628072}]}]}
{"op":"mcm","clk":"4231192911","pt":1631540837758,"mc":[{"id":"1.187594322","rc":[{"batb":[[1,1.23,523.51],[2,1.22,10]],"ltp":1.35,"tv":245.12,"id":7429606}]}]}
{"op":"mcm","clk":"4231196330","pt":1631540872772,"mc":[{"id":"1.187594322","rc":[{"batb":[[0,1.22,10],[1,1.01,7],[2,1.22,0]],"batl":[[1,1.58,0]],"ltp":1.35,"tv":245.12,"id":7429606},{"batb":[[0,1.01,7],[1,1.01,0]],"ltp":3.9,"tv":283.16,"id":9628072}]}]}
{"op":"mcm","clk":"4231196838","pt":1631540877686,"mc":[{"id":"1.187594322","rc":[{"batb":[[0,1.42,71.42],[1,1.22,10],[2,1.01,7]],"ltp":1.35,"tv":245.12,"id":7429606},{"batb":[[0,2.66,18.07],[1,1.01,7]],"ltp":3.9,"tv":283.16,"id":9628072}]}]}
{"op":"mcm","clk":"4231196986","pt":1631540879091,"mc":[{"id":"1.187594322","rc":[{"batb":[[1,1.31,484.01],[2,1.22,10]],"batl":[[1,1.89,441.21]],"ltp":1.35,"tv":245.12,"id":7429606}]}]}
{"op":"mcm","clk":"4231197198","pt":1631540881179,"mc":[{"id":"1.187594322","rc":[{"batl":[[0,1.89,441.21],[1,1.89,0]],"ltp":1.35,"tv":245.12,"id":7429606}]}]}
{"op":"mcm","clk":"4231198452","pt":1631540892322,"mc":[{"id":"1.187594322","rc":[{"batl":[[0,1.6,65.56],[1,1.89,441.21]],"ltp":1.35,"tv":245.12,"id":7429606}]}]}
{"op":"mcm","clk":"4231200385","pt":1631540911559,"mc":[{"id":"1.187594322","rc":[{"batb":[[0,1.31,484.01],[1,1.22,10],[2,1.01,7]],"ltp":1.35,"tv":245.12,"id":7429606},{"batb":[[0,1.01,7],[1,1.01,0]],"ltp":3.9,"tv":283.16,"id":9628072}]}]}
{"op":"mcm","clk":"4231200465","pt":1631540912400,"mc":[{"id":"1.187594322","rc":[{"batb":[[0,1.22,10],[1,1.01,7],[2,1.01,0]],"batl":[[0,1.89,441.21],[1,1.89,0]],"ltp":1.35,"tv":245.12,"id":7429606}]}]}
{"op":"mcm","clk":"4231200885","pt":1631540916460,"mc":[{"id":"1.187594322","rc":[{"batb":[[0,1.58,51.72],[1,1.22,10],[2,1.01,7]],"ltp":1.35,"tv":245.12,"id":7429606},{"batb":[[0,2.26,23.8],[1,1.01,7]],"ltp":3.9,"tv":283.16,"id":9628072}]}]}
{"op":"mcm","clk":"4231201081","pt":1631540918588,"mc":[{"id":"1.187594322","rc":[{"batb":[[1,1.38,454.56],[2,1.22,10]],"ltp":1.35,"tv":245.12,"id":7429606}]}]}
{"op":"mcm","clk":"4231201983","pt":1631540928195,"mc":[{"id":"1.187594322","rc":[{"batl":[[0,1.75,65.56],[1,1.89,441.21]],"ltp":1.35,"tv":245.12,"id":7429606}]}]}
{"op":"mcm","clk":"4231203463","pt":1631540943523,"mc":[{"id":"1.187594322","rc":[{"batl":[[0,1.7,9],[1,1.75,65.56],[2,1.89,441.21]],"ltp":1.35,"tv":245.12,"id":7429606}]}]}
{"op":"mcm","clk":"4231205255","pt":1631540961175,"mc":[{"id":"1.187594322","rc":[{"trd":[[1.58,3.4]],"batb":[[0,1.38,454.56],[1,1.22,10],[2,1.01,7]],"ltp":1.58,"tv":248.52,"id":7429606}],"tv":531.69}]}
{"op":"mcm","clk":"4231205744","pt":1631540966056,"mc":[{"id":"1.187594322","rc":[{"batb":[[0,1.58,51.72],[1,1.38,454.56],[2,1.22,10]],"ltp":1.58,"tv":248.52,"id":7429606}]}]}
{"op":"mcm","clk":"4231206134","pt":1631540970151,"mc":[{"id":"1.187594322","rc":[{"batb":[[1,1.5,131.12],[2,1.38,454.56]],"ltp":1.58,"tv":248.52,"id":7429606}]}]}
{"op":"mcm","clk":"4231206533","pt":1631540974367,"mc":[{"id":"1.187594322","rc":[{"batb":[[2,1.22,10]],"batl":[[2,1.89,0]],"ltp":1.58,"tv":248.52,"id":7429606}]}]}
{"op":"mcm","clk":"4231210243","pt":1631541011891,"mc":[{"id":"1.187594322","rc":[{"batb":[[0,1.5,131.12],[1,1.22,10],[2,1.01,7]],"ltp":1.58,"tv":248.52,"id":7429606},{"batb":[[0,1.01,7],[1,1.01,0]],"ltp":3.9,"tv":283.16,"id":9628072}]}]}
{"op":"mcm","clk":"4231210423","pt":1631541013606,"mc":[{"id":"1.187594322","rc":[{"batb":[[0,1.22,10],[1,1.01,7],[2,1.01,0]],"ltp":1.58,"tv":248.52,"id":7429606}]}]}
{"op":"mcm","clk":"4231210740","pt":1631541016923,"mc":[{"id":"1.187594322","rc":[{"batb":[[0,1.48,62.5],[1,1.22,10],[2,1.01,7]],"ltp":1.58,"tv":248.52,"id":7429606},{"batb":[[0,2.5,20],[1,1.01,7]],"ltp":3.9,"tv":283.16,"id":9628072}]}]}
{"op":"mcm","clk":"4231210895","pt":1631541018635,"mc":[{"id":"1.187594322","rc":[{"batl":[[1,1.75,0]],"ltp":1.58,"tv":248.52,"id":7429606}]}]}
{"op":"mcm","clk":"4231211416","pt":1631541024521,"mc":[{"id":"1.187594322","rc":[{"batl":[[0,1.66,65.56]],"ltp":1.58,"tv":248.52,"id":7429606}]}]}
{"op":"mcm","clk":"4231212975","pt":1631541040635,"mc":[{"id":"1.187594322","rc":[{"batl":[[0,1.63,8],[1,1.66,65.56]],"ltp":1.58,"tv":248.52,"id":7429606}]}]}
{"op":"mcm","clk":"4231214319","pt":1631541055665,"mc":[{"id":"1.187594322","rc":[{"batb":[[0,1.22,10],[1,1.01,7],[2,1.01,0]],"ltp":1.58,"tv":248.52,"id":7429606},{"batb":[[0,1.01,7],[1,1.01,0]],"ltp":3.9,"tv":283.16,"id":9628072}]}]}
{"op":"mcm","clk":"4231214663","pt":1631541060588,"mc":[{"id":"1.187594322","rc":[{"batb":[[0,1.38,78.94],[1,1.22,10],[2,1.01,7]],"ltp":1.58,"tv":248.52,"id":7429606},{"batb":[[0,2.84,16.3],[1,1.01,7]],"ltp":3.9,"tv":283.16,"id":9628072}]}]}
{"op":"mcm","clk":"4231214869","pt":1631541062688,"mc":[{"id":"1.187594322","rc":[{"batl":[[1,1.66,0]],"ltp":1.58,"tv":248.52,"id":7429606}]}]}
{"op":"mcm","clk":"4231217915","pt":1631541101637,"mc":[{"id":"1.187594322","rc":[{"batb":[[0,1.22,10],[1,1.01,7],[2,1.01,0]],"ltp":1.58,"tv":248.52,"id":7429606},{"batb":[[0,1.01,7],[1,1.01,0]],"ltp":3.9,"tv":283.16,"id":9628072}]}]}
{"op":"mcm","clk":"4231218250","pt":1631541106635,"mc":[{"id":"1.187594322","rc":[{"batb":[[0,1.45,66.66],[1,1.22,10],[2,1.01,7]],"ltp":1.58,"tv":248.52,"id":7429606},{"batb":[[0,2.58,18.98],[1,1.01,7]],"ltp":3.9,"tv":283.16,"id":9628072}]}]}
{"op":"mcm","clk":"4231221068","pt":1631541144253,"mc":[{"id":"1.187594322","rc":[{"batb":[[0,1.22,10],[1,1.01,7],[2,1.01,0]],"ltp":1.58,"tv":248.52,"id":7429606},{"batb":[[0,1.01,7],[1,1.01,0]],"ltp":3.9,"tv":283.16,"id":9628072}]}]}
{"op":"mcm","clk":"4231221427","pt":1631541149263,"mc":[{"id":"1.187594322","rc":[{"batb":[[0,1.38,78.94],[1,1.22,10],[2,1.01,7]],"ltp":1.58,"tv":248.52,"id":7429606},{"batb":[[0,2.84,16.3],[1,1.01,7]],"ltp":3.9,"tv":283.16,"id":9628072}]}]}
{"op":"mcm","clk":"4231221492","pt":1631541150151,"mc":[{"id":"1.187594322","rc":[{"batl":[[0,1.45,65.56],[1,1.63,8]],"ltp":1.58,"tv":248.52,"id":7429606}]}]}
{"op":"mcm","clk":"4231221672","pt":1631541152484,"mc":[{"id":"1.187594322","rc":[{"batl":[[0,1.63,8],[1,1.63,0]],"ltp":1.58,"tv":248.52,"id":7429606}]}]}
{"op":"mcm","clk":"4231221846","pt":1631541154474,"mc":[{"id":"1.187594322","rc":[{"batb":[[1,1.33,131.12],[2,1.22,10]],"ltp":1.58,"tv":248.52,"id":7429606}]}]}
{"op":"mcm","clk":"4231221917","pt":1631541155281,"mc":[{"id":"1.187594322","rc":[{"batb":[[1,1.33,196.68]],"ltp":1.58,"tv":248.52,"id":7429606}]}]}
{"op":"mcm","clk":"4231222159","pt":1631541158283,"mc":[{"id":"1.187594322","rc":[{"batl":[[0,1.5,65.56],[1,1.63,8]],"ltp":1.58,"tv":248.52,"id":7429606}]}]}
{"op":"mcm","clk":"4231223384","pt":1631541174727,"mc":[{"id":"1.187594322","rc":[{"batb":[[0,1.33,196.68],[1,1.22,10],[2,1.01,7]],"ltp":1.58,"tv":248.52,"id":7429606},{"batb":[[0,1.01,7],[1,1.01,0]],"ltp":3.9,"tv":283.16,"id":9628072}]}]}
{"op":"mcm","clk":"4231223508","pt":1631541176433,"mc":[{"id":"1.187594322","rc":[{"batb":[[0,1.22,10],[1,1.01,7],[2,1.01,0]],"ltp":1.58,"tv":248.52,"id":7429606}]}]}
{"op":"mcm","clk":"4231223772","pt":1631541179698,"mc":[{"id":"1.187594322","rc":[{"batb":[[0,1.31,96.77],[1,1.22,10],[2,1.01,7]],"ltp":1.58,"tv":248.52,"id":7429606},{"batb":[[0,3.15,13.95],[1,1.01,7]],"ltp":3.9,"tv":283.16,"id":9628072}]}]}
{"op":"mcm","clk":"4231223936","pt":1631541181889,"mc":[{"id":"1.187594322","rc":[{"batl":[[0,1.63,8],[1,1.63,0]],"ltp":1.58,"tv":248.52,"id":7429606}]}]}
{"op":"mcm","clk":"4231224190","pt":1631541185296,"mc":[{"id":"1.187594322","rc":[{"batb":[[1,1.28,196.68],[2,1.22,10]],"ltp":1.58,"tv":248.52,"id":7429606}]}]}
{"op":"mcm","clk":"4231224345","pt":1631541187633,"mc":[{"id":"1.187594322","rc":[{"batl":[[0,1.45,65.56],[1,1.63,8]],"ltp":1.58,"tv":248.52,"id":7429606}]}]}
{"op":"mcm","clk":"4231225153","pt":1631541199432,"mc":[{"id":"1.187594322","rc":[{"batl":[[0,1.36,3],[1,1.45,65.56],[2,1.63,8]],"ltp":1.58,"tv":248.52,"id":7429606}]}]}
{"op":"mcm","clk":"4231225640","pt":1631541207047,"mc":[{"id":"1.187594322","rc":[{"batb":[[0,1.28,196.68],[1,1.22,10],[2,1.01,7]],"ltp":1.58,"tv":248.52,"id":7429606},{"batb":[[0,1.01,7],[1,1.01,0]],"ltp":3.9,"tv":283.16,"id":9628072}]}]}
{"op":"mcm","clk":"4231225743","pt":1631541208957,"mc":[{"id":"1.187594322","rc":[{"batb":[[0,1.22,10],[1,1.01,7],[2,1.01,0]],"ltp":1.58,"tv":248.52,"id":7429606}]}]}
{"op":"mcm","clk":"4231225913","pt":1631541212047,"mc":[{"id":"1.187594322","rc":[{"batb":[[0,1.23,130.43],[1,1.22,10],[2,1.01,7]],"ltp":1.58,"tv":248.52,"id":7429606},{"batb":[[0,3.7,11.11],[1,1.01,7]],"ltp":3.9,"tv":283.16,"id":9628072}]}]}
{"op":"mcm","clk":"4231226066","pt":1631541214558,"mc":[{"id":"1.187594322","rc":[{"batl":[[1,1.63,8],[2,1.63,0]],"ltp":1.58,"tv":248.52,"id":7429606}]}]}
{"op":"mcm","clk":"4231226333","pt":1631541218444,"mc":[{"id":"1.187594322","rc":[{"batb":[[1,1.22,272.24]],"ltp":1.58,"tv":248.52,"id":7429606}]}]}
{"op":"mcm","clk":"4231226418","pt":1631541219845,"mc":[{"id":"1.187594322","rc":[{"batl":[[0,1.35,65.56],[1,1.36,3],[2,1.63,8]],"ltp":1.58,"tv":248.52,"id":7429606}]}]}
{"op":"mcm","clk":"4231226767","pt":1631541224839,"mc":[{"id":"1.187594322","rc":[{"batl":[[1,1.63,8],[2,1.63,0]],"ltp":1.58,"tv":248.52,"id":7429606}]}]}
{"op":"mcm","clk":"4231227224","pt":1631541231553,"mc":[{"id":"1.187594322","rc":[{"batb":[[0,1.22,272.24],[1,1.01,7],[2,1.01,0]],"ltp":1.58,"tv":248.52,"id":7429606},{"batb":[[0,1.01,7],[1,1.01,0]],"ltp":3.9,"tv":283.16,"id":9628072}]}]}
{"op":"mcm","clk":"4231227303","pt":1631541232951,"mc":[{"id":"1.187594322","rc":[{"batb":[[0,1.22,10]],"ltp":1.58,"tv":248.52,"id":7429606}]}]}
{"op":"mcm","clk":"4231227528","pt":1631541236588,"mc":[{"id":"1.187594322","rc":[{"batb":[[1,1.2,150],[2,1.01,7]],"ltp":1.58,"tv":248.52,"id":7429606},{"batb":[[0,4,10],[1,1.01,7]],"ltp":3.9,"tv":283.16,"id":9628072}]}]}
{"op":"mcm","clk":"4231227672","pt":1631541238572,"mc":[{"id":"1.187594322","rc":[{"batl":[[0,1.63,8],[1,1.63,0]],"ltp":1.58,"tv":248.52,"id":7429606}]}]}
{"op":"mcm","clk":"4231227941","pt":1631541241622,"mc":[{"id":"1.187594322","rc":[{"batb":[[1,1.2,346.68]],"ltp":1.58,"tv":248.52,"id":7429606}]}]}
{"op":"mcm","clk":"4231227969","pt":1631541241992,"mc":[{"id":"1.187594322","rc":[{"batb":[[1,1.2,477.8]],"ltp":1.58,"tv":248.52,"id":7429606}]}]}
{"op":"mcm","clk":"4231228160","pt":1631541244597,"mc":[{"id":"1.187594322","rc":[{"batl":[[0,1.33,65.56],[1,1.63,8]],"ltp":1.58,"tv":248.52,"id":7429606}]}]}
{"op":"mcm","clk":"4231229063","pt":1631541256190,"mc":[{"id":"1.187594322","rc":[{"batb":[[1,1.2,327.8]],"ltp":1.58,"tv":248.52,"id":7429606},{"batb":[[0,1.01,7],[1,1.01,0]],"ltp":3.9,"tv":283.16,"id":9628072}]}]}
{"op":"mcm","clk":"4231229149","pt":1631541257384,"mc":[{"id":"1.187594322","rc":[{"batl":[[0,1.63,8],[1,1.63,0]],"ltp":1.58,"tv":248.52,"id":7429606}]}]}
{"op":"mcm","clk":"4231229400","pt":1631541261193,"mc":[{"id":"1.187594322","rc":[{"batb":[[0,1.23,130.43],[1,1.22,10]],"ltp":1.58,"tv":248.52,"id":7429606},{"batb":[[0,3.7,11.11],[1,1.01,7]],"ltp":3.9,"tv":283.16,"id":9628072}]}]}
{"op":"mcm","clk":"4231229624","pt":1631541265028,"mc":[{"id":"1.187594322","rc":[{"batl":[[0,1.4,65.56],[1,1.63,8]],"ltp":1.58,"tv":248.52,"id":7429606}]}]}
{"op":"mcm","clk":"4231229776","pt":1631541267622,"mc":[{"id":"1.187594322","rc":[{"batb":[[1,1.22,272.24]],"ltp":1.58,"tv":248.52,"id":7429606}]}]}
{"op":"mcm","clk":"4231229881","pt":1631541269132,"mc":[{"id":"1.187594322","rc":[{"batb":[[1,1.22,10]],"batl":[[0,1.63,8],[1,1.63,0]],"ltp":1.58,"tv":248.52,"id":7429606}]}]}
{"op":"mcm","clk":"4231230784","pt":1631541283270,"mc":[{"id":"1.187594322","rc":[{"batb":[[0,1.22,10],[1,1.01,7],[2,1.01,0]],"ltp":1.58,"tv":248.52,"id":7429606},{"batb":[[0,1.01,7],[1,1.01,0]],"ltp":3.9,"tv":283.16,"id":9628072}]}]}
{"op":"mcm","clk":"4231231046","pt":1631541288166,"mc":[{"id":"1.187594322","rc":[{"batb":[[1,1.18,166.66],[2,1.01,7]],"ltp":1.58,"tv":248.52,"id":7429606},{"batb":[[0,4.1,10],[1,1.01,7]],"ltp":3.9,"tv":283.16,"id":9628072}]}]}
{"op":"mcm","clk":"4231232569","pt":1631541313607,"mc":[{"id":"1.187594322","rc":[{"batb":[[0,3.05,13.24]],"ltp":3.9,"tv":283.16,"id":9628072}]}]}
{"op":"mcm","clk":"4231232622","pt":1631541314486,"mc":[{"id":"1.187594322","rc":[{"batb":[[0,1.18,166.66],[1,1.01,7],[2,1.01,0]],"ltp":1.58,"tv":248.52,"id":7429606}]}]}
{"op":"mcm","clk":"4231232870","pt":1631541318512,"mc":[{"id":"1.187594322","rc":[{"batb":[[0,4.3,10],[1,3.05,13.24],[2,1.01,7]],"ltp":3.9,"tv":283.16,"id":9628072}]}]}
{"op":"mcm","clk":"4231232893","pt":1631541318877,"mc":[{"id":"1.187594322","rc":[{"batb":[[1,1.14,618.77],[2,1.01,7]],"batl":[[0,1.55,700.17],[1,1.63,8]],"ltp":1.58,"tv":248.52,"id":7429606}]}]}
{"op":"mcm","clk":"4231233868","pt":1631541333821,"mc":[{"id":"1.187594322","rc":[{"batb":[[0,1.22,4],[1,1.18,166.66],[2,1.14,618.77]],"ltp":1.58,"tv":248.52,"id":7429606}]}]}
{"op":"mcm","clk":"4231234721","pt":1631541348170,"mc":[{"id":"1.187594322","rc":[{"batb":[[0,1.28,3],[1,1.22,4],[2,1.18,166.66]],"ltp":1.58,"tv":248.52,"id":7429606}]}]}
{"op":"mcm","clk":"4231236455","pt":1631541374878,"mc":[{"id":"1.187594322","rc":[{"batl":[[0,1.3,65.56],[1,1.55,700.17],[2,1.63,8]],"ltp":1.58,"tv":248.52,"id":7429606}]}]}
{"op":"mcm","clk":"4231237289","pt":1631541386508,"mc":[{"id":"1.187594322","rc":[{"trd":[[1.28,18.76]],"batb":[[0,1.28,1.62]],"ltp":1.28,"tv":251.28,"id":7429606}],"tv":534.45}]}
{"op":"mcm","clk":"4231237969","pt":1631541396249,"mc":[{"id":"1.187594322","rc":[{"batb":[[0,1.22,4],[1,1.18,166.66],[2,1.14,618.77]],"ltp":1.28,"tv":251.28,"id":7429606}]}]}
{"op":"mcm","clk":"4231239097","pt":1631541410677,"mc":[{"id":"1.187594322","rc":[{"batl":[[0,1.24,3],[1,1.3,65.56],[2,1.55,700.17]],"ltp":1.28,"tv":251.28,"id":7429606}]}]}
{"op":"mcm","clk":"4231240105","pt":1631541425190,"mc":[{"id":"1.187594322","rc":[{"batb":[[1,1.14,618.77],[2,1.01,7]],"ltp":1.28,"tv":251.28,"id":7429606},{"batb":[[0,3.05,13.24],[1,1.01,7],[2,1.01,0]],"ltp":3.9,"tv":283.16,"id":9628072}]}]}
{"op":"mcm","clk":"4231240462","pt":1631541430184,"mc":[{"id":"1.187594322","rc":[{"batb":[[1,1.15,200],[2,1.14,618.77]],"ltp":1.28,"tv":251.28,"id":7429606},{"batb":[[0,4.8,10],[1,3.05,13.24],[2,1.01,7]],"ltp":3.9,"tv":283.16,"id":9628072}]}]}
{"op":"mcm","clk":"4231240700","pt":1631541432983,"mc":[{"id":"1.187594322","rc":[{"batb":[[1,1.14,618.77],[2,1.01,7]],"ltp":1.28,"tv":251.28,"id":7429606},{"batb":[[0,3.05,13.24],[1,1.01,7],[2,1.01,0]],"ltp":3.9,"tv":283.16,"id":9628072}]}]}
{"op":"mcm","clk":"4231240805","pt":1631541434373,"mc":[{"id":"1.187594322","rc":[{"trd":[[1.22,8]],"batb":[[0,1.01,7],[1,1.14,0],[2,1.01,0]],"batl":[[0,1.22,2.51],[1,1.24,3],[2,1.3,65.56]],"ltp":1.22,"tv":259.28,"id":7429606}],"tv":542.45}]}
{"op":"mcm","clk":"4231241100","pt":1631541438098,"mc":[{"id":"1.187594322","rc":[{"batb":[[0,1.11,272.72],[1,1.01,7]],"batl":[[2,1.63,8]],"ltp":1.22,"tv":259.28,"id":7429606},{"batb":[[0,5.8,10],[1,3.05,13.24],[2,1.01,7]],"ltp":3.9,"tv":283.16,"id":9628072}]}]}
{"op":"mcm","clk":"4231241240","pt":1631541440276,"mc":[{"id":"1.187594322","rc":[{"batb":[[1,1.1,733.06],[2,1.01,7]],"batl":[[2,1.48,795.63]],"ltp":1.22,"tv":259.28,"id":7429606}]}]}
{"op":"mcm","clk":"4231241573","pt":1631541445193,"mc":[{"id":"1.187594322","rc":[{"batb":[[0,1.12,131.12],[1,1.11,272.72],[2,1.1,733.06]],"ltp":1.22,"tv":259.28,"id":7429606}]}]}
{"op":"mcm","clk":"4231241648","pt":1631541446486,"mc":[{"id":"1.187594322","rc":[{"batb":[[0,1.12,262.24]],"ltp":1.22,"tv":259.28,"id":7429606}]}]}
{"op":"mcm","clk":"4231241817","pt":1631541449437,"mc":[{"id":"1.187594322","rc":[{"batb":[[0,1.18,3],[1,1.12,262.24],[2,1.11,272.72]],"ltp":1.22,"tv":259.28,"id":7429606}]}]}
{"op":"mcm","clk":"4231243209","pt":1631541468431,"mc":[{"id":"1.187594322","rc":[{"batb":[[2,1.1,733.06]],"ltp":1.22,"tv":259.28,"id":7429606},{"batb":[[0,3.05,13.24],[1,1.01,7],[2,1.01,0]],"ltp":3.9,"tv":283.16,"id":9628072}]}]}
{"op":"mcm","clk":"4231243308","pt":1631541469870,"mc":[{"id":"1.187594322","rc":[{"batb":[[2,1.01,7]],"ltp":1.22,"tv":259.28,"id":7429606}]}]}
{"op":"mcm","clk":"4231243555","pt":1631541473444,"mc":[{"id":"1.187594322","rc":[{"batb":[[0,1.18,169.66]],"ltp":1.22,"tv":259.28,"id":7429606},{"batb":[[0,4.3,10],[1,3.05,13.24],[2,1.01,7]],"ltp":3.9,"tv":283.16,"id":9628072}]}]}
{"op":"mcm","clk":"4231243702","pt":1631541475567,"mc":[{"id":"1.187594322","rc":[{"batb":[[1,1.14,618.77],[2,1.12,262.24]],"ltp":1.22,"tv":259.28,"id":7429606}]}]}
{"op":"mcm","clk":"4231243729","pt":1631541475873,"mc":[{"id":"1.187594322","rc":[{"batb":[[2,1.01,7]],"ltp":1.22,"tv":259.28,"id":7429606}]}]}
{"op":"mcm","clk":"4231243983","pt":1631541479458,"mc":[{"id":"1.187594322","rc":[{"batb":[[1,1.16,131.12],[2,1.14,618.77]],"ltp":1.22,"tv":259.28,"id":7429606}]}]}
{"op":"mcm","clk":"4231244031","pt":1631541480083,"mc":[{"id":"1.187594322","rc":[{"batb":[[1,1.16,196.68]],"batl":[[1,1.48,795.63],[2,1.63,8]],"ltp":1.22,"tv":259.28,"id":7429606}]}]}
{"op":"mcm","clk":"4231244579","pt":1631541488386,"mc":[{"id":"1.187594322","rc":[{"trd":[[1.22,13.01]],"batb":[[0,1.22,1.49],[1,1.18,169.66],[2,1.16,196.68]],"batl":[[0,1.48,795.63],[1,1.63,8],[2,1.63,0]],"ltp":1.22,"tv":264.3,"id":7429606}],"tv":547.46}]}
{"op":"mcm","clk":"4231244997","pt":1631541493312,"mc":[{"id":"1.187594322","rc":[{"batb":[[0,1.22,3.49]],"ltp":1.22,"tv":264.3,"id":7429606}]}]}
{"op":"mcm","clk":"4231245702","pt":1631541502621,"mc":[{"id":"1.187594322","rc":[{"batb":[[1,1.18,3]],"ltp":1.22,"tv":264.3,"id":7429606},{"batb":[[0,3.05,13.24],[1,1.01,7],[2,1.01,0]],"ltp":3.9,"tv":283.16,"id":9628072}]}]}
{"op":"mcm","clk":"4231246092","pt":1631541507513,"mc":[{"id":"1.187594322","rc":[{"trd":[[1.22,16.5]],"batb":[[0,1.18,3],[1,1.16,196.68],[2,1.08,374.99]],"ltp":1.22,"tv":267.79,"id":7429606},{"trd":[[5.6,0.76]],"batb":[[0,5.8,9.24],[1,3.05,13.24],[2,1.01,7]],"ltp":5.6,"tv":283.92,"id":9628072}],"tv":551.71}]}
{"op":"mcm","clk":"4231246162","pt":1631541508391,"mc":[{"id":"1.187594322","rc":[{"batb":[[1,1.08,374.99],[2,1.01,7]],"ltp":1.22,"tv":267.79,"id":7429606},{"batb":[[0,3.05,13.24],[1,1.01,7],[2,1.01,0]],"ltp":5.6,"tv":283.92,"id":9628072}]}]}
{"op":"mcm","clk":"4231246280","pt":1631541509790,"mc":[{"id":"1.187594322","rc":[{"batb":[[1,1.1,733.06],[2,1.08,374.99]],"ltp":1.22,"tv":267.79,"id":7429606}]}]}
{"op":"mcm","clk":"4231246486","pt":1631541512808,"mc":[{"id":"1.187594322","rc":[{"batb":[[0,5.8,10],[1,3.05,13.24],[2,1.01,7]],"ltp":5.6,"tv":283.92,"id":9628072}]}]}
{"op":"mcm","clk":"4231246814","pt":1631541517411,"mc":[{"id":"1.187594322","rc":[{"batb":[[1,1.12,196.68],[2,1.1,733.06]],"ltp":1.22,"tv":267.79,"id":7429606}]}]}
{"op":"mcm","clk":"4231247078","pt":1631541520724,"mc":[{"id":"1.187594322","rc":[{"batb":[[1,1.12,262.24]],"ltp":1.22,"tv":267.79,"id":7429606}]}]}
{"op":"mcm","clk":"4231247959","pt":1631541532073,"mc":[{"id":"1.187594322","rc":[{"batb":[[0,3.05,13.24],[1,1.01,7],[2,1.01,0]],"ltp":5.6,"tv":283.92,"id":9628072}]}]}
{"op":"mcm","clk":"4231248003","pt":1631541532644,"mc":[{"id":"1.187594322","rc":[{"batb":[[2,1.08,374.99]],"ltp":1.22,"tv":267.79,"id":7429606}]}]}
{"op":"mcm","clk":"4231248315","pt":1631541537057,"mc":[{"id":"1.187594322","rc":[{"batb":[[0,6,10],[1,3.05,13.24],[2,1.01,7]],"ltp":5.6,"tv":283.92,"id":9628072}]}]}
{"op":"mcm","clk":"4231248396","pt":1631541538453,"mc":[{"id":"1.187594322","rc":[{"batb":[[2,1.09,763.32]],"ltp":1.22,"tv":267.79,"id":7429606}]}]}
{"op":"mcm","clk":"4231249008","pt":1631541547293,"mc":[{"id":"1.187594322","rc":[{"batb":[[0,3.05,13.24],[1,1.01,7],[2,1.01,0]],"ltp":5.6,"tv":283.92,"id":9628072}]}]}
{"op":"mcm","clk":"4231249199","pt":1631541549988,"mc":[{"id":"1.187594322","rc":[{"batb":[[2,1.01,7]],"ltp":1.22,"tv":267.79,"id":7429606}]}]}
{"op":"mcm","clk":"4231249358","pt":1631541552173,"mc":[{"id":"1.187594322","rc":[{"batb":[[1,1.15,200],[2,1.12,262.24]],"ltp":1.22,"tv":267.79,"id":7429606},{"batb":[[0,4.8,10],[1,3.05,13.24],[2,1.01,7]],"ltp":5.6,"tv":283.92,"id":9628072}]}]}
{"op":"mcm","clk":"4231249597","pt":1631541555692,"mc":[{"id":"1.187594322","rc":[{"batb":[[2,1.14,618.77]],"ltp":1.22,"tv":267.79,"id":7429606}]}]}
{"op":"mcm","clk":"4231250250","pt":1631541563497,"mc":[{"id":"1.187594322","rc":[{"batb":[[0,1.26,3],[1,1.18,3],[2,1.15,200]],"ltp":1.22,"tv":267.79,"id":7429606}]}]}
{"op":"mcm","clk":"4231250557","pt":1631541567442,"mc":[{"id":"1.187594322","rc":[{"batb":[[2,1.16,131.12]],"ltp":1.22,"tv":267.79,"id":7429606}]}]}
{"op":"mcm","clk":"4231252525","pt":1631541593888,"mc":[{"id":"1.187594322","rc":[{"batb":[[0,3.05,13.24],[1,1.01,7],[2,1.01,0]],"ltp":5.6,"tv":283.92,"id":9628072}]}]}
{"op":"mcm","clk":"4231252900","pt":1631541598762,"mc":[{"id":"1.187594322","rc":[{"batb":[[1,1.2,150],[2,1.18,3]],"ltp":1.22,"tv":267.79,"id":7429606},{"batb":[[0,3.95,10.16],[1,3.05,13.24],[2,1.01,7]],"ltp":5.6,"tv":283.92,"id":9628072}]}]}
{"op":"mcm","clk":"4231253163","pt":1631541601491,"mc":[{"id":"1.187594322","rc":[{"batb":[[0,1.27,65.56],[1,1.26,3],[2,1.2,150]],"ltp":1.22,"tv":267.79,"id":7429606}]}]}
{"op":"mcm","clk":"4231253215","pt":1631541602012,"mc":[{"id":"1.187594322","rc":[{"batb":[[0,1.26,3],[1,1.2,150],[2,1.18,560.21]],"ltp":1.22,"tv":267.79,"id":7429606}]}]}
{"op":"mcm","clk":"4231253605","pt":1631541606129,"mc":[{"id":"1.187594322","rc":[{"batb":[[0,3.05,13.24],[1,1.01,7],[2,1.01,0]],"ltp":5.6,"tv":283.92,"id":9628072}]}]}
{"op":"mcm","clk":"4231253994","pt":1631541611034,"mc":[{"id":"1.187594322","rc":[{"batb":[[0,4,10],[1,3.05,13.24],[2,1.01,7]],"ltp":5.6,"tv":283.92,"id":9628072}]}]}
{"op":"mcm","clk":"4231254460","pt":1631541617130,"mc":[{"id":"1.187594322","rc":[{"batb":[[1,1.18,3],[2,1.01,7]],"batl":[[0,1.63,8],[1,1.63,0]],"ltp":1.22,"tv":267.79,"id":7429606},{"batb":[[0,3.05,13.24],[1,1.01,7],[2,1.01,0]],"ltp":5.6,"tv":283.92,"id":9628072}]}]}
{"op":"mcm","clk":"4231254813","pt":1631541621826,"mc":[{"id":"1.187594322","rc":[{"batb":[[0,1.28,107.14],[1,1.26,3],[2,1.18,3]],"ltp":1.22,"tv":267.79,"id":7429606},{"batb":[[0,3.3,13.04],[1,3.05,13.24],[2,1.01,7]],"ltp":5.6,"tv":283.92,"id":9628072}]}]}
{"op":"mcm","clk":"4231254924","pt":1631541623173,"mc":[{"id":"1.187594322","rc":[{"batb":[[2,1.2,538.09]],"batl":[[1,1.66,587.71]],"ltp":1.22,"tv":267.79,"id":7429606}]}]}
{"op":"mcm","clk":"4231255554","pt":1631541631668,"mc":[{"id":"1.187594322","rc":[{"batb":[[0,1.4,3],[1,1.28,107.14],[2,1.26,3]],"ltp":1.22,"tv":267.79,"id":7429606}]}]}
{"op":"mcm","clk":"4231255756","pt":1631541634785,"mc":[{"id":"1.187594322","rc":[{"trd":[[1.4,6]],"batb":[[0,1.28,107.14],[1,1.26,3],[2,1.2,538.09]],"batl":[[0,1.4,62.56],[1,1.63,8],[2,1.66,587.71]],"ltp":1.4,"tv":273.79,"id":7429606}],"tv":557.71}]}
{"op":"mcm","clk":"4231255986","pt":1631541638293,"mc":[{"id":"1.187594322","rc":[{"batl":[[0,1.4,64.56]],"ltp":1.4,"tv":273.79,"id":7429606}]}]}
{"op":"mcm","clk":"4231256052","pt":1631541638978,"mc":[{"id":"1.187594322","rc":[{"batl":[[0,1.4,62.56]],"ltp":1.4,"tv":273.79,"id":7429606}]}]}
{"op":"mcm","clk":"4231257053","pt":1631541651601,"mc":[{"id":"1.187594322","rc":[{"batb":[[0,1.26,3],[1,1.2,538.09],[2,1.18,3]],"ltp":1.4,"tv":273.79,"id":7429606},{"batb":[[0,3.05,13.24],[1,1.01,7],[2,1.01,0]],"ltp":5.6,"tv":283.92,"id":9628072}]}]}
{"op":"mcm","clk":"4231257339","pt":1631541655418,"mc":[{"id":"1.187594322","rc":[{"batb":[[0,1.37,3],[1,1.26,3],[2,1.2,538.09]],"ltp":1.4,"tv":273.79,"id":7429606}]}]}
{"op":"mcm","clk":"4231257423","pt":1631541656613,"mc":[{"id":"1.187594322","rc":[{"trd":[[1.37,3]],"batb":[[0,1.26,3],[1,1.2,688.09],[2,1.18,3]],"ltp":1.37,"tv":276.79,"id":7429606},{"trd":[[3.75,1.1]],"batb":[[0,3.95,9.06],[1,3.05,13.24],[2,1.01,7]],"ltp":3.75,"tv":285.02,"id":9628072}],"tv":561.81}]}
{"op":"mcm","clk":"4231257437","pt":1631541656821,"mc":[{"id":"1.187594322","rc":[{"batb":[[0,3.05,13.24],[1,1.01,7],[2,1.01,0]],"ltp":3.75,"tv":285.02,"id":9628072}]}]}
{"op":"mcm","clk":"4231257771","pt":1631541661723,"mc":[{"id":"1.187594322","rc":[{"batb":[[0,3.95,10.16],[1,3.05,13.24],[2,1.01,7]],"ltp":3.75,"tv":285.02,"id":9628072}]}]}
{"op":"mcm","clk":"4231257910","pt":1631541663443,"mc":[{"id":"1.187594322","rc":[{"trd":[[1.26,2.76]],"batb":[[0,1.26,1.62]],"ltp":1.26,"tv":279.55,"id":7429606}],"tv":564.58}]}
{"op":"mcm","clk":"4231258457","pt":1631541670050,"mc":[{"id":"1.187594322","rc":[{"batb":[[0,3.05,13.24],[1,1.01,7],[2,1.01,0]],"ltp":3.75,"tv":285.02,"id":9628072}]}]}
{"op":"mcm","clk":"4231258903","pt":1631541675049,"mc":[{"id":"1.187594322","rc":[{"batb":[[0,3.7,11.11],[1,3.05,13.24],[2,1.01,7]],"ltp":3.75,"tv":285.02,"id":9628072}]}]}
{"op":"mcm","clk":"4231260462","pt":1631541690767,"mc":[{"id":"1.187594322","rc":[{"batb":[[1,1.2,538.09]],"ltp":1.26,"tv":279.55,"id":7429606},{"batb":[[0,3.05,13.24],[1,1.01,7],[2,1.01,0]],"ltp":3.75,"tv":285.02,"id":9628072}]}]}
{"op":"mcm","clk":"4231260592","pt":1631541692282,"mc":[{"id":"1.187594322","rc":[{"batb":[[1,1.18,3],[2,1.01,7]],"batl":[[2,1.66,0]],"ltp":1.26,"tv":279.55,"id":7429606}]}]}
{"op":"mcm","clk":"4231260896","pt":1631541695772,"mc":[{"id":"1.187594322","rc":[{"batb":[[1,1.18,169.66]],"ltp":1.26,"tv":279.55,"id":7429606},{"batb":[[0,4.3,10],[1,3.05,13.24],[2,1.01,7]],"ltp":3.75,"tv":285.02,"id":9628072}]}]}
{"op":"mcm","clk":"4231261063","pt":1631541697550,"mc":[{"id":"1.187594322","rc":[{"batl":[[0,1.63,8],[1,1.63,0]],"ltp":1.26,"tv":279.55,"id":7429606}]}]}
{"op":"mcm","clk":"4231261135","pt":1631541698387,"mc":[{"id":"1.187594322","rc":[{"batb":[[2,1.16,583.98]],"batl":[[0,1.58,659.44],[1,1.63,8]],"ltp":1.26,"tv":279.55,"id":7429606}]}]}
{"op":"mcm","clk":"4231261311","pt":1631541700578,"mc":[{"id":"1.187594322","rc":[{"batb":[[0,1.18,169.66],[1,1.16,583.98],[2,1.01,7]],"ltp":1.26,"tv":279.55,"id":7429606}]}]}
{"op":"mcm","clk":"4231262466","pt":1631541713413,"mc":[{"id":"1.187594322","rc":[{"batb":[[0,1.2,150],[1,1.18,169.66],[2,1.16,583.98]],"ltp":1.26,"tv":279.55,"id":7429606}]}]}
{"op":"mcm","clk":"4231262544","pt":1631541714304,"mc":[{"id":"1.187594322","rc":[{"batb":[[0,1.2,300]],"ltp":1.26,"tv":279.55,"id":7429606}]}]}
{"op":"mcm","clk":"4231262868","pt":1631541718375,"mc":[{"id":"1.187594322","rc":[{"batl":[[0,1.22,3],[1,1.58,659.44],[2,1.63,8]],"ltp":1.26,"tv":279.55,"id":7429606}]}]}
{"op":"mcm","clk":"4231263066","pt":1631541721095,"mc":[{"id":"1.187594322","rc":[{"batb":[[1,1.18,3]],"ltp":1.26,"tv":279.55,"id":7429606},{"batb":[[0,3.05,13.24],[1,1.01,7],[2,1.01,0]],"ltp":3.75,"tv":285.02,"id":9628072}]}]}
{"op":"mcm","clk":"4231263155","pt":1631541721884,"mc":[{"id":"1.187594322","rc":[{"batb":[[2,1.01,7]],"ltp":1.26,"tv":279.55,"id":7429606}]}]}
{"op":"mcm","clk":"4231263537","pt":1631541726118,"mc":[{"id":"1.187594322","rc":[{"batb":[[2,1.15,200]],"ltp":1.26,"tv":279.55,"id":7429606},{"batb":[[0,4.8,10],[1,3.05,13.24],[2,1.01,7]],"ltp":3.75,"tv":285.02,"id":9628072}]}]}
{"op":"mcm","clk":"4231263684","pt":1631541727522,"mc":[{"id":"1.187594322","rc":[{"batb":[[0,1.18,3],[1,1.15,200],[2,1.01,7]],"ltp":1.26,"tv":279.55,"id":7429606}]}]}
{"op":"mcm","clk":"4231263709","pt":1631541727830,"mc":[{"id":"1.187594322","rc":[{"batb":[[2,1.14,618.77]],"ltp":1.26,"tv":279.55,"id":7429606}]}]}
{"op":"mcm","clk":"4231264273","pt":1631541733598,"mc":[{"id":"1.187594322","rc":[{"batb":[[1,1.16,100],[2,1.15,200]],"ltp":1.26,"tv":279.55,"id":7429606}]}]}
{"op":"mcm","clk":"4231264301","pt":1631541733906,"mc":[{"id":"1.187594322","rc":[{"batb":[[1,1.16,200]],"ltp":1.26,"tv":279.55,"id":7429606}]}]}
{"op":"mcm","clk":"4231265347","pt":1631541746450,"mc":[{"id":"1.187594322","rc":[{"batb":[[2,1.14,618.77]],"ltp":1.26,"tv":279.55,"id":7429606},{"batb":[[0,3.05,13.24],[1,1.01,7],[2,1.01,0]],"ltp":3.75,"tv":285.02,"id":9628072}]}]}
{"op":"mcm","clk":"4231265636","pt":1631541750546,"mc":[{"id":"1.187594322","rc":[{"batl":[[0,1.58,659.44],[1,1.63,8],[2,1.63,0]],"ltp":1.26,"tv":279.55,"id":7429606}]}]}
{"op":"mcm","clk":"4231265690","pt":1631541751328,"mc":[{"id":"1.187594322","rc":[{"batb":[[0,1.18,169.66]],"ltp":1.26,"tv":279.55,"id":7429606},{"batb":[[0,4.3,10],[1,3.05,13.24],[2,1.01,7]],"ltp":3.75,"tv":285.02,"id":9628072}]}]}
{"op":"mcm","clk":"4231267856","pt":1631541778891,"mc":[{"id":"1.187594322","rc":[{"batb":[[0,1.18,3]],"ltp":1.26,"tv":279.55,"id":7429606},{"batb":[[0,3.05,13.24],[1,1.01,7],[2,1.01,0]],"ltp":3.75,"tv":285.02,"id":9628072}]}]}
{"op":"mcm","clk":"4231268014","pt":1631541780877,"mc":[{"id":"1.187594322","rc":[{"batb":[[2,1.01,7]],"ltp":1.26,"tv":279.55,"id":7429606}]}]}
{"op":"mcm","clk":"4231268269","pt":1631541783890,"mc":[{"id":"1.187594322","rc":[{"batb":[[0,1.2,150],[1,1.18,3],[2,1.16,200]],"ltp":1.26,"tv":279.55,"id":7429606},{"batb":[[0,3.95,10.16],[1,3.05,13.24],[2,1.01,7]],"ltp":3.75,"tv":285.02,"id":9628072}]}]}
{"op":"mcm","clk":"4231268442","pt":1631541786417,"mc":[{"id":"1.187594322","rc":[{"batb":[[2,1.16,783.98]],"ltp":1.26,"tv":279.55,"id":7429606}]}]}
{"op":"mcm","clk":"4231269921","pt":1631541806254,"mc":[{"id":"1.187594322","rc":[{"batb":[[2,1.16,200]],"ltp":1.26,"tv":279.55,"id":7429606}]}]}
{"op":"mcm","clk":"4231270307","pt":1631541811693,"mc":[{"id":"1.187594322","rc":[{"batb":[[1,1.18,560.21]],"ltp":1.26,"tv":279.55,"id":7429606}]}]}
{"op":"mcm","clk":"4231270994","pt":1631541820983,"mc":[{"id":"1.187594322","rc":[{"trd":[[1.2,28.18]],"batb":[[0,1.18,560.21],[1,1.16,200],[2,1.01,7]],"ltp":1.2,"tv":282.31,"id":7429606}],"tv":567.34}]}
{"op":"mcm","clk":"4231271198","pt":1631541823483,"mc":[{"id":"1.187594322","rc":[{"batb":[[0,3.05,13.24],[1,1.01,7],[2,1.01,0]],"ltp":3.75,"tv":285.02,"id":9628072}]}]}
{"op":"mcm","clk":"4231271357","pt":1631541825573,"mc":[{"id":"1.187594322","rc":[{"batb":[[0,1.18,3]],"ltp":1.2,"tv":282.31,"id":7429606}]}]}
{"op":"mcm","clk":"4231271575","pt":1631541828486,"mc":[{"id":"1.187594322","rc":[{"batb":[[0,3.15,13.95],[1,3.05,13.24],[2,1.01,7]],"ltp":3.75,"tv":285.02,"id":9628072}]}]}
{"op":"mcm","clk":"4231271642","pt":1631541829113,"mc":[{"id":"1.187594322","rc":[{"batb":[[1,1.01,7],[2,1.01,0]],"ltp":1.2,"tv":282.31,"id":7429606}]}]}
{"op":"mcm","clk":"4231271788","pt":1631541831222,"mc":[{"id":"1.187594322","rc":[{"batb":[[0,1.31,96.77],[1,1.22,530.12],[2,1.18,3]],"ltp":1.2,"tv":282.31,"id":7429606},{"batb":[[1,1.01,7],[2,1.01,0]],"ltp":3.75,"tv":285.02,"id":9628072}]}]}
{"op":"mcm","clk":"4231272188","pt":1631541836512,"mc":[{"id":"1.187594322","rc":[{"batb":[[1,1.28,50],[2,1.22,530.12]],"ltp":1.2,"tv":282.31,"id":7429606}]}]}
{"op":"mcm","clk":"4231272233","pt":1631541836983,"mc":[{"id":"1.187594322","rc":[{"batb":[[0,1.4,3],[1,1.31,96.77],[2,1.28,200]],"ltp":1.2,"tv":282.31,"id":7429606}]}]}
{"op":"mcm","clk":"4231272360","pt":1631541838494,"mc":[{"id":"1.187594322","rc":[{"batl":[[0,1.46,62.56],[1,1.58,659.44],[2,1.63,8]],"ltp":1.2,"tv":282.31,"id":7429606}]}]}
{"op":"mcm","clk":"4231272768","pt":1631541843816,"mc":[{"id":"1.187594322","rc":[{"batb":[[1,1.28,200],[2,1.22,530.12]],"ltp":1.2,"tv":282.31,"id":7429606},{"batb":[[0,1.01,7],[1,1.01,0]],"ltp":3.75,"tv":285.02,"id":9628072}]}]}
{"op":"mcm","clk":"4231272959","pt":1631541845806,"mc":[{"id":"1.187594322","rc":[{"batb":[[2,1.18,3]],"ltp":1.2,"tv":282.31,"id":7429606}]}]}
{"op":"mcm","clk":"4231273060","pt":1631541847119,"mc":[{"id":"1.187594322","rc":[{"batb":[[1,1.18,3],[2,1.01,7]],"ltp":1.2,"tv":282.31,"id":7429606}]}]}
{"op":"mcm","clk":"4231273217","pt":1631541849129,"mc":[{"id":"1.187594322","rc":[{"trd":[[1.4,9]],"batb":[[0,1.2,150]],"ltp":1.4,"tv":285.31,"id":7429606},{"trd":[[3.5,1.2]],"ltp":3.5,"tv":286.22,"id":9628072}],"tv":571.54}]}
{"op":"mcm","clk":"4231273417","pt":1631541851524,"mc":[{"id":"1.187594322","rc":[{"batb":[[1,1.18,560.21]],"batl":[[0,1.4,2],[1,1.46,62.56],[2,1.58,659.44]],"ltp":1.4,"tv":285.31,"id":7429606}]}]}
{"op":"mcm","clk":"4231273493","pt":1631541852411,"mc":[{"id":"1.187594322","rc":[{"batl":[[0,1.4,8.94]],"ltp":1.4,"tv":285.31,"id":7429606}]}]}
{"op":"mcm","clk":"4231273588","pt":1631541853615,"mc":[{"id":"1.187594322","rc":[{"batl":[[0,1.4,47.69]],"ltp":1.4,"tv":285.31,"id":7429606}]}]}
{"op":"mcm","clk":"4231273678","pt":1631541854629,"mc":[{"id":"1.187594322","rc":[{"batl":[[0,1.4,14.9]],"ltp":1.4,"tv":285.31,"id":7429606},{"batb":[[0,3.95,10.16],[1,1.01,7]],"ltp":3.5,"tv":286.22,"id":9628072}]}]}
{"op":"mcm","clk":"4231273730","pt":1631541855365,"mc":[{"id":"1.187594322","rc":[{"batl":[[0,1.4,2.98],[1,1.58,659.44],[2,1.63,8]],"ltp":1.4,"tv":285.31,"id":7429606}]}]}
{"op":"mcm","clk":"4231273763","pt":1631541855745,"mc":[{"id":"1.187594322","rc":[{"batl":[[0,1.58,659.44],[1,1.63,8],[2,1.63,0]],"ltp":1.4,"tv":285.31,"id":7429606}]}]}
{"op":"mcm","clk":"4231273927","pt":1631541857628,"mc":[{"id":"1.187594322","rc":[{"batb":[[0,1.22,100],[1,1.2,150],[2,1.18,560.21]],"ltp":1.4,"tv":285.31,"id":7429606}]}]}
{"op":"mcm","clk":"4231273973","pt":1631541858349,"mc":[{"id":"1.187594322","rc":[{"batb":[[0,1.22,300]],"ltp":1.4,"tv":285.31,"id":7429606}]}]}
{"op":"mcm","clk":"4231274176","pt":1631541861163,"mc":[{"id":"1.187594322","rc":[{"batl":[[0,1.37,62.56],[1,1.58,659.44],[2,1.63,8]],"ltp":1.4,"tv":285.31,"id":7429606}]}]}
{"op":"mcm","clk":"4231274512","pt":1631541865269,"mc":[{"id":"1.187594322","rc":[{"batb":[[1,1.18,3],[2,1.01,7]],"ltp":1.4,"tv":285.31,"id":7429606},{"batb":[[0,1.01,7],[1,1.01,0]],"ltp":3.5,"tv":286.22,"id":9628072}]}]}
{"op":"mcm","clk":"4231274629","pt":1631541866788,"mc":[{"id":"1.187594322","rc":[{"batb":[[0,1.18,3],[1,1.01,7],[2,1.01,0]],"ltp":1.4,"tv":285.31,"id":7429606}]}]}
{"op":"mcm","clk":"4231274855","pt":1631541869761,"mc":[{"id":"1.187594322","rc":[{"batb":[[1,1.15,200],[2,1.01,7]],"ltp":1.4,"tv":285.31,"id":7429606},{"batb":[[0,4.8,10],[1,1.01,7]],"ltp":3.5,"tv":286.22,"id":9628072}]}]}
{"op":"mcm","clk":"4231274980","pt":1631541871283,"mc":[{"id":"1.187594322","rc":[{"batb":[[2,1.14,618.77]],"ltp":1.4,"tv":285.31,"id":7429606}]}]}
{"op":"mcm","clk":"4231275269","pt":1631541875078,"mc":[{"id":"1.187594322","rc":[{"batl":[[0,1.58,659.44],[1,1.63,8],[2,1.63,0]],"ltp":1.4,"tv":285.31,"id":7429606}]}]}
{"op":"mcm","clk":"4231275582","pt":1631541878583,"mc":[{"id":"1.187594322","rc":[{"batb":[[1,1.16,150],[2,1.15,200]],"ltp":1.4,"tv":285.31,"id":7429606}]}]}
{"op":"mcm","clk":"4231275619","pt":1631541879093,"mc":[{"id":"1.187594322","rc":[{"batb":[[1,1.16,300]],"ltp":1.4,"tv":285.31,"id":7429606}]}]}
{"op":"mcm","clk":"4231275796","pt":1631541881393,"mc":[{"id":"1.187594322","rc":[{"batl":[[0,1.3,62.56],[1,1.58,659.44],[2,1.63,8]],"ltp":1.4,"tv":285.31,"id":7429606}]}]}
{"op":"mcm","clk":"4231284761","pt":1631541988320,"mc":[{"id":"1.187594322","rc":[{"batb":[[1,1.15,200],[2,1.14,618.77]],"batl":[[0,1.58,659.44],[1,1.63,8],[2,1.63,0]],"ltp":1.4,"tv":285.31,"id":7429606}]}]}
{"op":"mcm","clk":"4231287337","pt":1631542020455,"mc":[{"id":"1.187594322","rc":[{"trd":[[1.15,9.9],[1.18,3]],"batb":[[0,1.14,618.77],[1,1.01,7],[2,1.14,0]],"ltp":1.15,"tv":298.21,"id":7429606},{"trd":[[6.6,0.54],[7.8,1.46]],"ltp":7.8,"tv":288.22,"id":9628072}],"tv":586.44}]}
{"op":"mcm","clk":"4231287798","pt":1631542025475,"mc":[{"id":"1.187594322","rc":[{"batb":[[0,1.15,200],[1,1.14,618.77],[2,1.01,7]],"ltp":1.15,"tv":298.21,"id":7429606}]}]}
{"op":"mcm","clk":"4231288239","pt":1631542030464,"mc":[{"id":"1.187594322","rc":[{"batb":[[0,1.14,618.77],[1,1.01,7],[2,1.01,0]],"ltp":1.15,"tv":298.21,"id":7429606},{"batb":[[0,1.01,7],[1,1.01,0]],"ltp":7.8,"tv":288.22,"id":9628072}]}]}
{"op":"mcm","clk":"4231288322","pt":1631542031546,"mc":[{"id":"1.187594322","rc":[{"batb":[[0,1.16,100],[1,1.14,618.77],[2,1.01,7]],"ltp":1.15,"tv":298.21,"id":7429606}]}]}
{"op":"mcm","clk":"4231288374","pt":1631542032067,"mc":[{"id":"1.187594322","rc":[{"batb":[[0,1.16,200]],"ltp":1.15,"tv":298.21,"id":7429606}]}]}
{"op":"mcm","clk":"4231288435","pt":1631542032743,"mc":[{"id":"1.187594322","rc":[{"batb":[[1,1.01,7],[2,1.01,0]],"batl":[[0,1.63,8],[1,1.63,0]],"ltp":1.15,"tv":298.21,"id":7429606}]}]}
{"op":"mcm","clk":"4231288548","pt":1631542034089,"mc":[{"id":"1.187594322","rc":[{"batb":[[0,1.01,7],[1,1.01,0]],"ltp":1.15,"tv":298.21,"id":7429606}]}]}
{"op":"mcm","clk":"4231288682","pt":1631542035443,"mc":[{"id":"1.187594322","rc":[{"batb":[[0,1.08,374.99],[1,1.01,7]],"ltp":1.15,"tv":298.21,"id":7429606},{"batb":[[0,6,10],[1,1.01,7]],"ltp":7.8,"tv":288.22,"id":9628072}]}]}
{"op":"mcm","clk":"4231288959","pt":1631542038473,"mc":[{"id":"1.187594322","rc":[{"batb":[[0,1.1,733.06],[1,1.08,374.99],[2,1.01,7]],"batl":[[0,1.48,795.63],[1,1.63,8]],"ltp":1.15,"tv":298.21,"id":7429606}]}]}
{"op":"mcm","clk":"4231289179","pt":1631542041077,"mc":[{"id":"1.187594322","rc":[{"batb":[[0,1.12,150],[1,1.1,733.06],[2,1.08,374.99]],"ltp":1.15,"tv":298.21,"id":7429606}]}]}
{"op":"mcm","clk":"4231290767","pt":1631542060130,"mc":[{"id":"1.187594322","rc":[{"batb":[[1,1.08,374.99],[2,1.01,7]],"ltp":1.15,"tv":298.21,"id":7429606}]}]}
{"op":"mcm","clk":"4231291208","pt":1631542065706,"mc":[{"id":"1.187594322","rc":[{"batb":[[1,1.09,763.32],[2,1.08,374.99]],"ltp":1.15,"tv":298.21,"id":7429606}]}]}
{"op":"mcm","clk":"4231291307","pt":1631542067115,"mc":[{"id":"1.187594322","rc":[{"batb":[[2,1.01,7]],"ltp":1.15,"tv":298.21,"id":7429606},{"batb":[[0,1.01,7],[1,1.01,0]],"ltp":7.8,"tv":288.22,"id":9628072}]}]}
{"op":"mcm","clk":"4231291507","pt":1631542069307,"mc":[{"id":"1.187594322","rc":[{"batb":[[1,1.01,7],[2,1.01,0]],"batl":[[0,1.63,8],[1,1.63,0]],"ltp":1.15,"tv":298.21,"id":7429606}]}]}
{"op":"mcm","clk":"4231291621","pt":1631542070819,"mc":[{"id":"1.187594322","rc":[{"batb":[[0,1.01,7],[1,1.01,0]],"ltp":1.15,"tv":298.21,"id":7429606}]}]}
{"op":"mcm","clk":"4231291729","pt":1631542072122,"mc":[{"id":"1.187594322","rc":[{"batb":[[0,1.05,599.99],[1,1.01,7]],"ltp":1.15,"tv":298.21,"id":7429606},{"batb":[[0,7.6,10],[1,1.01,7]],"ltp":7.8,"tv":288.22,"id":9628072}]}]}
{"op":"mcm","clk":"4231291952","pt":1631542074835,"mc":[{"id":"1.187594322","rc":[{"batb":[[0,1.06,1007.44],[1,1.05,599.99],[2,1.01,7]],"batl":[[0,1.41,914.95],[1,1.63,8]],"ltp":1.15,"tv":298.21,"id":7429606}]}]}
{"op":"mcm","clk":"4231292206","pt":1631542077917,"mc":[{"id":"1.187594322","rc":[{"batb":[[0,1.08,50],[1,1.06,1007.44],[2,1.05,599.99]],"ltp":1.15,"tv":298.21,"id":7429606}]}]}
{"op":"mcm","clk":"4231292317","pt":1631542079225,"mc":[{"id":"1.187594322","rc":[{"batb":[[0,1.08,250]],"ltp":1.15,"tv":298.21,"id":7429606}]}]}
{"op":"mcm","clk":"4231293855","pt":1631542097880,"mc":[{"id":"1.187594322","rc":[{"batb":[[2,1.01,7]],"ltp":1.15,"tv":298.21,"id":7429606},{"batb":[[0,1.01,7],[1,1.01,0]],"ltp":7.8,"tv":288.22,"id":9628072}]}]}
{"op":"mcm","clk":"4231294005","pt":1631542099655,"mc":[{"id":"1.187594322","rc":[{"batb":[[1,1.01,7],[2,1.01,0]],"ltp":1.15,"tv":298.21,"id":7429606}]}]}
{"op":"mcm","clk":"4231294294","pt":1631542102844,"mc":[{"id":"1.187594322","rc":[{"batb":[[1,1.04,749.99],[2,1.01,7]],"ltp":1.15,"tv":298.21,"id":7429606},{"batb":[[0,8,10],[1,1.01,7]],"ltp":7.8,"tv":288.22,"id":9628072}]}]}
{"op":"mcm","clk":"4231294532","pt":1631542105353,"mc":[{"id":"1.187594322","rc":[{"batb":[[1,1.06,949.57],[2,1.04,749.99]],"ltp":1.15,"tv":298.21,"id":7429606}]}]}
{"op":"mcm","clk":"4231295531","pt":1631542117635,"mc":[{"id":"1.187594322","rc":[{"batb":[[0,1.06,949.57],[1,1.01,7],[2,1.04,0]],"ltp":1.15,"tv":298.21,"id":7429606},{"batb":[[0,1.01,7],[1,1.01,0]],"ltp":7.8,"tv":288.22,"id":9628072}]}]}
{"op":"mcm","clk":"4231295546","pt":1631542117843,"mc":[{"id":"1.187594322","rc":[{"batb":[[0,1.01,7],[1,1.01,0]],"ltp":1.15,"tv":298.21,"id":7429606}]}]}
{"op":"mcm","clk":"4231295843","pt":1631542121737,"mc":[{"id":"1.187594322","rc":[{"batb":[[0,1.02,1499.99],[1,1.01,7]],"ltp":1.15,"tv":298.21,"id":7429606},{"batb":[[0,10,10],[1,1.01,7]],"ltp":7.8,"tv":288.22,"id":9628072}]}]}
{"op":"mcm","clk":"4231296029","pt":1631542123781,"mc":[{"id":"1.187594322","rc":[{"batb":[[0,1.04,1251.37],[1,1.02,1499.99],[2,1.01,7]],"ltp":1.15,"tv":298.21,"id":7429606}]}]}
{"op":"mcm","clk":"4231296255","pt":1631542126361,"mc":[{"id":"1.187594322","rc":[{"batb":[[0,1.05,50],[1,1.04,1251.37],[2,1.02,1499.99]],"ltp":1.15,"tv":298.21,"id":7429606}]}]}
{"op":"mcm","clk":"4231296312","pt":1631542126985,"mc":[{"id":"1.187594322","rc":[{"batb":[[0,1.05,100]],"ltp":1.15,"tv":298.21,"id":7429606}]}]}
{"op":"mcm","clk":"4231296461","pt":1631542128557,"mc":[{"id":"1.187594322","rc":[{"batl":[[0,1.08,8.52],[1,1.41,914.95],[2,1.63,8]],"ltp":1.15,"tv":298.21,"id":7429606}]}]}
{"op":"mcm","clk":"4231296540","pt":1631542129282,"mc":[{"id":"1.187594322","rc":[{"batb":[[1,1.04,1401.37]],"ltp":1.15,"tv":298.21,"id":7429606}]}]}
{"op":"mcm","clk":"4231298011","pt":1631542146886,"mc":[{"id":"1.187594322","rc":[{"batl":[[0,1.41,914.95],[1,1.63,8],[2,1.63,0]],"ltp":1.15,"tv":298.21,"id":7429606}]}]}
{"op":"mcm","clk":"4231298167","pt":1631542148560,"mc":[{"id":"1.187594322","rc":[{"trd":[[1.05,10]],"batb":[[0,1.05,95]],"ltp":1.05,"tv":308.21,"id":7429606}],"tv":596.44}]}
{"op":"mcm","clk":"4231298272","pt":1631542149762,"mc":[{"id":"1.187594322","rc":[{"batb":[[2,1.01,7]],"ltp":1.05,"tv":308.21,"id":7429606},{"batb":[[0,1.01,7],[1,1.01,0]],"ltp":7.8,"tv":288.22,"id":9628072}]}]}
{"op":"mcm","clk":"4231298420","pt":1631542151381,"mc":[{"id":"1.187594322","rc":[{"batb":[[1,1.04,150]],"ltp":1.05,"tv":308.21,"id":7429606}]}]}
{"op":"mcm","clk":"4231298717","pt":1631542154680,"mc":[{"id":"1.187594322","rc":[{"batb":[[1,1.04,899.99]],"ltp":1.05,"tv":308.21,"id":7429606},{"batb":[[0,8.6,10],[1,1.01,7]],"ltp":7.8,"tv":288.22,"id":9628072}]}]}
{"op":"mcm","clk":"4231298917","pt":1631542157088,"mc":[{"id":"1.187594322","rc":[{"batb":[[0,1.05,1179.16]],"ltp":1.05,"tv":308.21,"id":7429606}]}]}
{"op":"mcm","clk":"4231299642","pt":1631542164405,"mc":[{"id":"1.187594322","rc":[{"trd":[[1.05,35.56]],"batb":[[0,1.05,1166.37]],"ltp":1.05,"tv":333.78,"id":7429606}],"tv":622.0}]}
{"op":"mcm","clk":"4231299814","pt":1631542166482,"mc":[{"id":"1.187594322","rc":[{"trd":[[8.6,0.4]],"batb":[[0,1.01,7],[1,1.01,0]],"ltp":8.6,"tv":288.62,"id":9628072}],"tv":622.41}]}
{"op":"mcm","clk":"4231299913","pt":1631542167676,"mc":[{"id":"1.187594322","rc":[{"batb":[[1,1.04,150]],"ltp":1.05,"tv":333.78,"id":7429606}]}]}
{"op":"mcm","clk":"4231299990","pt":1631542168714,"mc":[{"id":"1.187594322","rc":[{"batb":[[0,1.05,82.21]],"ltp":1.05,"tv":333.78,"id":7429606}]}]}
{"op":"mcm","clk":"4231300188","pt":1631542171425,"mc":[{"id":"1.187594322","rc":[{"batb":[[0,8.6,10],[1,1.01,7]],"ltp":8.6,"tv":288.62,"id":9628072}]}]}
{"op":"mcm","clk":"4231300285","pt":1631542172623,"mc":[{"id":"1.187594322","rc":[{"batb":[[0,1.06,499.99],[1,1.05,82.21],[2,1.04,150]],"ltp":1.05,"tv":333.78,"id":7429606},{"batb":[[0,1.01,7],[1,1.01,0]],"ltp":8.6,"tv":288.62,"id":9628072}]}]}
{"op":"mcm","clk":"4231300398","pt":1631542174188,"mc":[{"id":"1.187594322","rc":[{"batb":[[0,1.08,811.87],[1,1.06,499.99],[2,1.05,82.21]],"ltp":1.05,"tv":333.78,"id":7429606}]}]}
{"op":"mcm","clk":"4231300576","pt":1631542176589,"mc":[{"id":"1.187594322","rc":[{"batb":[[0,7,10],[1,1.01,7]],"ltp":8.6,"tv":288.62,"id":9628072}]}]}
{"op":"mcm","clk":"4231301149","pt":1631542184395,"mc":[{"id":"1.187594322","rc":[{"batb":[[2,1.04,150]],"ltp":1.05,"tv":333.78,"id":7429606}]}]}
{"op":"mcm","clk":"4231301187","pt":1631542184920,"mc":[{"id":"1.187594322","rc":[{"batb":[[0,1.06,499.99],[1,1.01,7],[2,1.04,0]],"batl":[[0,1.63,8],[1,1.63,0]],"ltp":1.05,"tv":333.78,"id":7429606}]}]}
{"op":"mcm","clk":"4231302493","pt":1631542201254,"mc":[{"id":"1.187594322","rc":[{"batb":[[0,1.01,7],[1,1.01,0]],"ltp":1.05,"tv":333.78,"id":7429606},{"batb":[[0,1.01,7],[1,1.01,0]],"ltp":8.6,"tv":288.62,"id":9628072}]}]}
{"op":"mcm","clk":"4231302938","pt":1631542206276,"mc":[{"id":"1.187594322","rc":[{"batb":[[0,1.12,249.99],[1,1.01,7]],"ltp":1.05,"tv":333.78,"id":7429606},{"batb":[[0,5.3,10],[1,1.01,7]],"ltp":8.6,"tv":288.62,"id":9628072}]}]}
{"op":"mcm","clk":"4231303074","pt":1631542207638,"mc":[{"id":"1.187594322","rc":[{"batb":[[0,1.12,909.19]],"batl":[[0,1.51,751.18],[1,1.63,8]],"ltp":1.05,"tv":333.78,"id":7429606}]}]}
{"op":"mcm","clk":"4231305045","pt":1631542228591,"mc":[{"id":"1.187594322","rc":[{"batb":[[0,1.01,7],[1,1.01,0]],"batl":[[0,1.63,8],[1,1.63,0]],"ltp":1.05,"tv":333.78,"id":7429606},{"batb":[[0,1.01,7],[1,1.01,0]],"ltp":8.6,"tv":288.62,"id":9628072}]}]}
{"op":"mcm","clk":"4231305416","pt":1631542232681,"mc":[{"id":"1.187594322","rc":[{"batb":[[0,1.06,499.99],[1,1.01,7]],"ltp":1.05,"tv":333.78,"id":7429606},{"batb":[[0,7,10],[1,1.01,7]],"ltp":8.6,"tv":288.62,"id":9628072}]}]}
{"op":"mcm","clk":"4231305584","pt":1631542234886,"mc":[{"id":"1.187594322","rc":[{"batb":[[0,1.08,811.87],[1,1.06,499.99],[2,1.01,7]],"batl":[[0,1.44,869.43],[1,1.63,8]],"ltp":1.05,"tv":333.78,"id":7429606}]}]}
{"op":"mcm","clk":"4231306125","pt":1631542241390,"mc":[{"id":"1.187594322","rc":[{"batb":[[0,1.1,100],[1,1.08,811.87],[2,1.06,499.99]],"ltp":1.05,"tv":333.78,"id":7429606}]}]}
{"op":"mcm","clk":"4231306785","pt":1631542248901,"mc":[{"id":"1.187594322","rc":[{"batb":[[1,1.06,499.99],[2,1.01,7]],"batl":[[0,1.63,8],[1,1.63,0]],"ltp":1.05,"tv":333.78,"id":7429606}]}]}
{"op":"mcm","clk":"4231306862","pt":1631542249897,"mc":[{"id":"1.187594322","rc":[{"batb":[[1,1.01,7],[2,1.01,0]],"ltp":1.05,"tv":333.78,"id":7429606},{"batb":[[0,1.01,7],[1,1.01,0]],"ltp":8.6,"tv":288.62,"id":9628072}]}]}
{"op":"mcm","clk":"4231307231","pt":1631542254803,"mc":[{"id":"1.187594322","rc":[{"batb":[[0,1.12,249.99],[1,1.1,100],[2,1.01,7]],"ltp":1.05,"tv":333.78,"id":7429606},{"batb":[[0,5.3,10],[1,1.01,7]],"ltp":8.6,"tv":288.62,"id":9628072}]}]}
{"op":"mcm","clk":"4231307438","pt":1631542257219,"mc":[{"id":"1.187594322","rc":[{"batb":[[0,1.12,909.19],[1,1.01,7],[2,1.01,0]],"batl":[[0,1.51,751.18],[1,1.63,8]],"ltp":1.05,"tv":333.78,"id":7429606}]}]}
{"op":"mcm","clk":"4231307561","pt":1631542259208,"mc":[{"id":"1.187594322","rc":[{"batb":[[0,1.14,100],[1,1.12,909.19],[2,1.01,7]],"ltp":1.05,"tv":333.78,"id":7429606}]}]}
{"op":"mcm","clk":"4231309265","pt":1631542281543,"mc":[{"id":"1.187594322","rc":[{"batb":[[1,1.01,7],[2,1.01,0]],"batl":[[0,1.63,8],[1,1.63,0]],"ltp":1.05,"tv":333.78,"id":7429606},{"batb":[[0,1.01,7],[1,1.01,0]],"ltp":8.6,"tv":288.62,"id":9628072}]}]}
{"op":"mcm","clk":"4231309395","pt":1631542283463,"mc":[{"id":"1.187594322","rc":[{"batb":[[0,1.01,7],[1,1.01,0]],"ltp":1.05,"tv":333.78,"id":7429606}]}]}
{"op":"mcm","clk":"4231309533","pt":1631542285762,"mc":[{"id":"1.187594322","rc":[{"batb":[[0,1.06,499.99],[1,1.01,7]],"ltp":1.05,"tv":333.78,"id":7429606},{"batb":[[0,7,10],[1,1.01,7]],"ltp":8.6,"tv":288.62,"id":9628072}]}]}
{"op":"mcm","clk":"4231309652","pt":1631542287436,"mc":[{"id":"1.187594322","rc":[{"batb":[[0,1.06,1507.43]],"batl":[[0,1.41,914.95],[1,1.63,8]],"ltp":1.05,"tv":333.78,"id":7429606}]}]}
{"op":"mcm","clk":"4231310259","pt":1631542296470,"mc":[{"id":"1.187594322","rc":[{"batb":[[0,1.08,150],[1,1.06,499.99],[2,1.01,7]],"batl":[[0,1.63,8],[1,1.63,0]],"ltp":1.05,"tv":333.78,"id":7429606}]}]}
{"op":"mcm","clk":"4231310319","pt":1631542297257,"mc":[{"id":"1.187594322","rc":[{"batb":[[0,1.08,200]],"ltp":1.05,"tv":333.78,"id":7429606}]}]}
{"op":"mcm","clk":"4231310376","pt":1631542297875,"mc":[{"id":"1.187594322","rc":[{"batb":[[0,1.08,250]],"ltp":1.05,"tv":333.78,"id":7429606}]}]}
{"op":"mcm","clk":"4231310873","pt":1631542305396,"mc":[{"id":"1.187594322","rc":[{"batb":[[1,1.01,7],[2,1.01,0]],"ltp":1.05,"tv":333.78,"id":7429606},{"batb":[[0,1.01,7],[1,1.01,0]],"ltp":8.6,"tv":288.62,"id":9628072}]}]}
{"op":"mcm","clk":"4231310974","pt":1631542306800,"mc":[{"id":"1.187594322","rc":[{"batb":[[0,1.01,7],[1,1.01,0]],"ltp":1.05,"tv":333.78,"id":7429606}]}]}
{"op":"mcm","clk":"4231311241","pt":1631542310598,"mc":[{"id":"1.187594322","rc":[{"batb":[[0,1.03,1556.77],[1,1.01,7]],"batl":[[0,1.35,1087.64],[1,1.63,8]],"ltp":1.05,"tv":333.78,"id":7429606},{"batb":[[0,14,10],[1,1.01,7]],"ltp":8.6,"tv":288.62,"id":9628072}]}]}
{"op":"mcm","clk":"4231311407","pt":1631542313503,"mc":[{"id":"1.187594322","rc":[{"batb":[[0,1.04,150],[1,1.03,1556.77],[2,1.01,7]],"ltp":1.05,"tv":333.78,"id":7429606}]}]}
{"op":"mcm","clk":"4231311500","pt":1631542314603,"mc":[{"id":"1.187594322","rc":[{"batb":[[1,1.03,1656.77]],"ltp":1.05,"tv":333.78,"id":7429606}]}]}
{"op":"mcm","clk":"4231311575","pt":1631542315589,"mc":[{"id":"1.187594322","rc":[{"batb":[[1,1.03,1706.77],[2,1.02,50]],"ltp":1.05,"tv":333.78,"id":7429606}]}]}
{"op":"mcm","clk":"4231311664","pt":1631542316491,"mc":[{"id":"1.187594322","rc":[{"batb":[[2,1.02,150]],"ltp":1.05,"tv":333.78,"id":7429606}]}]}
{"op":"mcm","clk":"4231312219","pt":1631542323897,"mc":[{"id":"1.187594322","rc":[{"batl":[[1,1.48,26],[2,1.63,8]],"ltp":1.05,"tv":333.78,"id":7429606}]}]}
{"op":"mcm","clk":"4231312866","pt":1631542333694,"mc":[{"id":"1.187594322","rc":[{"batb":[[0,1.04,200]],"ltp":1.05,"tv":333.78,"id":7429606}]}]}
{"op":"mcm","clk":"4231313640","pt":1631542345005,"mc":[{"id":"1.187594322","rc":[{"batb":[[0,1.01,7],[1,1.01,0]],"ltp":8.6,"tv":288.62,"id":9628072}]}]}
{"op":"mcm","clk":"4231313743","pt":1631542346502,"mc":[{"id":"1.187594322","rc":[{"batb":[[1,1.03,150]],"ltp":1.05,"tv":333.78,"id":7429606}]}]}
{"op":"mcm","clk":"4231313759","pt":1631542346713,"mc":[{"id":"1.187594322","rc":[{"batb":[[0,1.03,150],[1,1.02,150],[2,1.01,157]],"ltp":1.05,"tv":333.78,"id":7429606}]}]}
{"op":"mcm","clk":"4231313867","pt":1631542348121,"mc":[{"id":"1.187594322","rc":[{"batb":[[0,1.02,150],[1,1.01,157],[2,1.01,0]],"ltp":1.05,"tv":333.78,"id":7429606}]}]}
{"op":"mcm","clk":"4231313992","pt":1631542349996,"mc":[{"id":"1.187594322","rc":[{"batb":[[0,19.5,10],[1,1.01,7]],"ltp":8.6,"tv":288.62,"id":9628072}]}]}
{"op":"mcm","clk":"4231314183","pt":1631542352292,"mc":[{"id":"1.187594322","rc":[{"batb":[[1,1.01,4123]],"ltp":1.05,"tv":333.78,"id":7429606}]}]}
{"op":"mcm","clk":"4231314806","pt":1631542360809,"mc":[{"id":"1.187594322","rc":[{"trd":[[1.02,36.17]],"batb":[[0,1.02,131.91]],"ltp":1.02,"tv":369.95,"id":7429606}],"tv":658.58}]}
{"op":"mcm","clk":"4231315036","pt":1631542363585,"mc":[{"id":"1.187594322","rc":[{"batb":[[1,1.01,157]],"batl":[[0,1.48,26],[1,1.63,8],[2,1.63,0]],"ltp":1.02,"tv":369.95,"id":7429606}]}]}
{"op":"mcm","clk":"4231315466","pt":1631542369128,"mc":[{"id":"1.187594322","rc":[{"batb":[[0,1.01,7],[1,1.01,0]],"ltp":8.6,"tv":288.62,"id":9628072}]}]}
{"op":"mcm","clk":"4231315731","pt":1631542372413,"mc":[{"id":"1.187594322","rc":[{"batb":[[0,1.01,157],[1,1.01,0]],"ltp":1.02,"tv":369.95,"id":7429606}]}]}
{"op":"mcm","clk":"4231316048","pt":1631542376506,"mc":[{"id":"1.187594322","rc":[{"batl":[[0,1.28,1326.95],[1,1.48,26],[2,1.63,8]],"ltp":1.02,"tv":369.95,"id":7429606}]}]}
{"op":"mcm","clk":"4231316281","pt":1631542379518,"mc":[{"id":"1.187594322","rc":[{"batb":[[0,1.01,357]],"ltp":1.02,"tv":369.95,"id":7429606}]}]}
{"op":"mcm","clk":"4231316654","pt":1631542384837,"mc":[{"id":"1.187594322","rc":[{"batl":[[0,1.02,1000],[1,1.28,1326.95],[2,1.48,26]],"ltp":1.02,"tv":369.95,"id":7429606}]}]}
{"op":"mcm","clk":"4231317118","pt":1631542391042,"mc":[{"id":"1.187594322","rc":[{"batl":[[1,1.48,26],[2,1.63,8]],"ltp":1.02,"tv":369.95,"id":7429606}]}]}
{"op":"mcm","clk":"4231317338","pt":1631542393968,"mc":[{"id":"1.187594322","rc":[{"batb":[[0,1.01,7]],"ltp":1.02,"tv":369.95,"id":7429606}]}]}
{"op":"mcm","clk":"4231317777","pt":1631542399577,"mc":[{"id":"1.187594322","rc":[{"batl":[[0,1.48,26],[1,1.63,8],[2,1.63,0]],"ltp":1.02,"tv":369.95,"id":7429606}]}]}
{"op":"mcm","clk":"4231318024","pt":1631542402666,"mc":[{"id":"1.187594322","rc":[{"batl":[[0,1.27,1412.67],[1,1.48,26],[2,1.63,8]],"ltp":1.02,"tv":369.95,"id":7429606}]}]}
{"op":"mcm","clk":"4231318282","pt":1631542406384,"mc":[{"id":"1.187594322","rc":[{"trd":[[1.01,13.99]],"batl":[[0,1.01,10.04],[1,1.27,1412.67],[2,1.48,26]],"ltp":1.01,"tv":383.94,"id":7429606}],"tv":672.57}]}
{"op":"mcm","clk":"4231318434","pt":1631542408374,"mc":[{"id":"1.187594322","rc":[{"batl":[[0,1.01,1010.04]],"ltp":1.01,"tv":383.94,"id":7429606}]}]}
{"op":"mcm","clk":"4231318952","pt":1631542415287,"mc":[{"id":"1.187594322","rc":[{"batl":[[1,1.48,26],[2,1.63,8]],"ltp":1.01,"tv":383.94,"id":7429606}]}]}
{"op":"mcm","clk":"4231320147","pt":1631542431121,"mc":[{"id":"1.187594322","rc":[{"batl":[[1,1.28,1366.24],[2,1.48,26]],"ltp":1.01,"tv":383.94,"id":7429606}]}]}
{"op":"mcm","clk":"4231321154","pt":1631542444744,"mc":[{"id":"1.187594322","rc":[{"batl":[[0,1.01,10.04]],"ltp":1.01,"tv":383.94,"id":7429606}]}]}
{"op":"mcm","clk":"4231321733","pt":1631542451943,"mc":[{"id":"1.187594322","rc":[{"batl":[[1,1.48,26],[2,1.63,8]],"ltp":1.01,"tv":383.94,"id":7429606}]}]}
{"op":"mcm","clk":"4231322916","pt":1631542465481,"mc":[{"id":"1.187594322","rc":[{"batl":[[1,1.28,1352.39],[2,1.48,26]],"ltp":1.01,"tv":383.94,"id":7429606}]}]}
{"op":"mcm","clk":"4231323071","pt":1631542467061,"mc":[{"id":"1.187594322","rc":[{"batl":[[1,1.48,26],[2,1.63,8]],"ltp":1.01,"tv":383.94,"id":7429606}]}]}
{"op":"mcm","clk":"4231323966","pt":1631542477794,"mc":[{"id":"1.187594322","rc":[{"batl":[[1,1.3,1265.64],[2,1.48,26]],"ltp":1.01,"tv":383.94,"id":7429606},{"batl":[[0,340,36.37]],"ltp":8.6,"tv":288.62,"id":9628072}]}]}
{"op":"mcm","clk":"4231324169","pt":1631542480202,"mc":[{"id":"1.187594322","rc":[{"trd":[[1.01,34.08]],"batb":[[0,1.01,1989.95]],"batl":[[0,1.3,1265.64],[1,1.48,26],[2,1.63,8]],"ltp":1.01,"tv":404.03,"id":7429606}],"tv":692.66}]}
{"op":"mcm","clk":"4231324891","pt":1631542489107,"mc":[{"id":"1.187594322","rc":[{"batb":[[0,19.5,10],[1,1.01,7]],"ltp":8.6,"tv":288.62,"id":9628072}]}]}
{"op":"mcm","clk":"4231324992","pt":1631542490483,"mc":[{"id":"1.187594322","rc":[{"batl":[[0,1.48,26],[1,1.63,8],[2,1.63,0]],"ltp":1.01,"tv":404.03,"id":7429606}]}]}
{"op":"mcm","clk":"4231326340","pt":1631542507646,"mc":[{"id":"1.187594322","rc":[{"batb":[[0,1.01,7],[1,1.01,0]],"ltp":8.6,"tv":288.62,"id":9628072}]}]}
{"op":"mcm","clk":"4231329352","pt":1631542545955,"mc":[{"id":"1.187594322","marketDefinition":{"bspMarket":false,"turnInPlayEnabled":true,"persistenceEnabled":true,"marketBaseRate":5.0,"eventId":"30897917","eventTypeId":"2","numberOfWinners":1,"bettingType":"ODDS","marketType":"MATCH_ODDS","marketTime":"2021-09-13T13:07:38.000Z","suspendTime":"2021-09-13T13:07:38.000Z","bspReconciled":false,"complete":true,"inPlay":true,"crossMatching":true,"runnersVoidable":false,"numberOfActiveRunners":2,"betDelay":5,"status":"SUSPENDED","runners":[{"status":"ACTIVE","sortPriority":1,"id":7429606,"name":"E Bogdan"},{"status":"ACTIVE","sortPriority":2,"id":9628072,"name":"A Moratelli"}],"regulators":["MR_INT"],"countryCode":"GB","discountAllowed":true,"timezone":"GMT","openDate":"2021-09-13T13:07:38.000Z","version":4030758028,"name":"Match Odds","eventName":"E Bogdan v A Moratelli"}}]}
{"op":"mcm","clk":"4231330065","pt":1631542553919,"mc":[{"id":"1.187594322","tv":0.0}]}
{"op":"mcm","clk":"4231330161","pt":1631542555009,"mc":[{"id":"1.187594322","marketDefinition":{"bspMarket":false,"turnInPlayEnabled":true,"persistenceEnabled":true,"marketBaseRate":5.0,"eventId":"30897917","eventTypeId":"2","numberOfWinners":1,"bettingType":"ODDS","marketType":"MATCH_ODDS","marketTime":"2021-09-13T13:07:38.000Z","suspendTime":"2021-09-13T13:07:38.000Z","bspReconciled":false,"complete":true,"inPlay":true,"crossMatching":false,"runnersVoidable":false,"numberOfActiveRunners":0,"betDelay":5,"status":"CLOSED","settledTime":"2021-09-13T14:15:48.000Z","runners":[{"status":"WINNER","sortPriority":1,"id":7429606,"name":"E Bogdan"},{"status":"LOSER","sortPriority":2,"id":9628072,"name":"A Moratelli"}],"regulators":["MR_INT"],"countryCode":"GB","discountAllowed":true,"timezone":"GMT","openDate":"2021-09-13T13:07:38.000Z","version":4030758179,"name":"Match Odds","eventName":"E Bogdan v A Moratelli"}}]}
