{"op":"mcm","clk":"4228101080","pt":1631459600439,"mc":[{"id":"1.187551081","rc":[{"batl":[[0,5,11.58],[1,5.1,3],[2,5.2,47.67]],"ltp":5.0,"tv":1246.45,"id":7445998}]}]}
{"op":"mcm","clk":"4228101620","pt":1631459603643,"mc":[{"id":"1.187551081","rc":[{"batb":[[0,4.1,4.74],[1,3.85,4.17],[2,3.8,55.85]],"batl":[[0,5.1,3],[1,7.2,91.22],[2,5.2,0]],"ltp":5.0,"tv":1246.45,"id":7445998},{"batb":[[0,1.24,189.21],[1,1.17,6.16],[2,1.16,664.13]],"batl":[[0,1.32,120.61],[1,1.35,111.1],[2,1.36,110.32]],"ltp":1.25,"tv":11043.75,"id":9629022}]}]}
{"op":"mcm","clk":"4228101745","pt":1631459604234,"mc":[{"id":"1.187551081","rc":[{"batb":[[0,3.85,4.17],[1,3.8,55.85],[2,3.45,3]],"batl":[[0,7.2,91.22],[1,7.2,0]],"ltp":5.0,"tv":1246.45,"id":7445998},{"batb":[[0,1.17,6.16],[1,1.16,664.13],[2,1.13,1.28]],"batl":[[0,1.35,111.1],[1,1.4,8],[2,2,30]],"ltp":1.25,"tv":11043.75,"id":9629022}]}]}
{"op":"mcm","clk":"4228101992","pt":1631459605619,"mc":[{"id":"1.187551081","rc":[{"batb":[[2,1.13,11.84]],"ltp":1.25,"tv":11043.75,"id":9629022}]}]}
{"op":"mcm","clk":"4228102134","pt":1631459606637,"mc":[{"id":"1.187551081","rc":[{"batb":[[0,1.25,146.99],[1,1.17,301.09],[2,1.16,1476.95]],"batl":[[0,1.34,438.96],[1,1.35,416.31],[2,1.4,8]],"ltp":1.25,"tv":11043.75,"id":9629022}]}]}
{"op":"mcm","clk":"4228102275","pt":1631459607634,"mc":[{"id":"1.187551081","rc":[{"batb":[[0,3.9,3],[1,3.85,7.17],[2,3.8,58.85]],"batl":[[0,7.2,94.22]],"ltp":5.0,"tv":1246.45,"id":7445998},{"batb":[[0,1.17,316.09],[1,1.16,1492.95],[2,1.13,11.84]],"batl":[[1,1.35,423.31]],"ltp":1.25,"tv":11043.75,"id":9629022}]}]}
{"op":"mcm","clk":"4228102578","pt":1631459609843,"mc":[{"id":"1.187551081","rc":[{"batl":[[0,7,3],[1,7.2,94.22]],"ltp":5.0,"tv":1246.45,"id":7445998},{"batl":[[0,1.34,446.96]],"ltp":1.25,"tv":11043.75,"id":9629022}]}]}
{"op":"mcm","clk":"4228104018","pt":1631459619583,"mc":[{"id":"1.187551081","rc":[{"batb":[[1,3.85,4.17],[2,3.8,55.85]],"ltp":5.0,"tv":1246.45,"id":7445998},{"batb":[[0,1.17,21.16],[1,1.16,664.13]],"batl":[[1,1.35,416.31],[2,2,30]],"ltp":1.25,"tv":11043.75,"id":9629022}]}]}
{"op":"mcm","clk":"4228104169","pt":1631459620564,"mc":[{"id":"1.187551081","rc":[{"batb":[[0,3.85,4.17],[1,3.8,55.85],[2,2.72,379.61]],"ltp":5.0,"tv":1246.45,"id":7445998},{"batl":[[0,1.34,438.96]],"ltp":1.25,"tv":11043.75,"id":9629022}]}]}
{"op":"mcm","clk":"4228104351","pt":1631459621664,"mc":[{"id":"1.187551081","rc":[{"batb":[[0,4.1,4.54],[1,3.85,4.17],[2,3.8,55.85]],"batl":[[1,7.2,0]],"ltp":5.0,"tv":1246.45,"id":7445998},{"batl":[[0,1.32,122.36],[1,1.34,438.96],[2,1.35,416.31]],"ltp":1.25,"tv":11043.75,"id":9629022}]}]}
{"op":"mcm","clk":"4228104478","pt":1631459622349,"mc":[{"id":"1.187551081","rc":[{"batb":[[0,3.85,4.17],[1,3.8,55.85],[2,2.72,379.61]],"ltp":5.0,"tv":1246.45,"id":7445998},{"batb":[[0,1.31,225.04],[1,1.3,7360.1],[2,1.17,21.16]],"batl":[[0,1.34,438.96],[1,1.35,416.31],[2,2,30]],"ltp":1.25,"tv":11043.75,"id":9629022}]}]}
{"op":"mcm","clk":"4228104683","pt":1631459623600,"mc":[{"id":"1.187551081","rc":[{"batb":[[2,3.65,3]],"batl":[[0,4.3,2],[1,6.8,3],[2,7,3]],"ltp":5.0,"tv":1246.45,"id":7445998},{"batb":[[0,1.32,299.36],[1,1.31,225.04],[2,1.3,436.65]],"ltp":1.25,"tv":11043.75,"id":9629022}]}]}
{"op":"mcm","clk":"4228105002","pt":1631459625576,"mc":[{"id":"1.187551081","rc":[{"batl":[[0,4.2,3],[1,4.3,2],[2,6,104.94]],"ltp":5.0,"tv":1246.45,"id":7445998},{"batb":[[0,1.32,309.36],[1,1.31,235.04],[2,1.3,446.65]],"ltp":1.25,"tv":11043.75,"id":9629022}]}]}
{"op":"mcm","clk":"4228105138","pt":1631459626485,"mc":[{"id":"1.187551081","rc":[{"batb":[[0,1.32,448.56]],"ltp":1.25,"tv":11043.75,"id":9629022}]}]}
{"op":"mcm","clk":"4228105649","pt":1631459629591,"mc":[{"id":"1.187551081","rc":[{"batl":[[0,4.1,15],[1,4.2,3],[2,4.3,2]],"ltp":5.0,"tv":1246.45,"id":7445998},{"batb":[[0,1.33,63.49],[1,1.32,448.56],[2,1.31,235.04]],"batl":[[2,1.39,123.5]],"ltp":1.25,"tv":11043.75,"id":9629022}]}]}
{"op":"mcm","clk":"4228105944","pt":1631459631404,"mc":[{"id":"1.187551081","rc":[{"trd":[[1.34,753.76]],"batl":[[0,1.34,118.96]],"ltp":1.34,"tv":11683.75,"id":9629022}],"tv":12930.2}]}
{"op":"mcm","clk":"4228106513","pt":1631459634583,"mc":[{"id":"1.187551081","rc":[{"trd":[[3.9,1.15]],"ltp":3.9,"tv":1246.76,"id":7445998},{"trd":[[1.34,754.66]],"batb":[[0,1.33,199.76],[2,1.31,416.41]],"batl":[[0,1.34,261.22]],"ltp":1.34,"tv":11684.65,"id":9629022}],"tv":12931.41}]}
{"op":"mcm","clk":"4228106986","pt":1631459637403,"mc":[{"id":"1.187551081","rc":[{"batb":[[2,3.6,2]],"batl":[[2,5.1,45.77]],"ltp":3.9,"tv":1246.76,"id":7445998},{"trd":[[1.34,757.42]],"batb":[[2,1.31,406.41]],"batl":[[0,1.34,259.84]],"ltp":1.34,"tv":11687.4,"id":9629022}],"tv":12934.17}]}
{"op":"mcm","clk":"4228107610","pt":1631459641319,"mc":[{"id":"1.187551081","rc":[{"trd":[[1.34,977.3]],"batl":[[0,1.34,149.9]],"ltp":1.34,"tv":11907.28,"id":9629022}],"tv":13154.05}]}
{"op":"mcm","clk":"4228108154","pt":1631459644513,"mc":[{"id":"1.187551081","rc":[{"batb":[[0,3.35,5.27],[1,3.2,60.79],[2,3.15,148.33]],"batl":[[0,5.1,45.77],[1,5.2,42.8],[2,5.3,57.44]],"ltp":3.9,"tv":1246.76,"id":7445998},{"batb":[[0,1.24,170.66],[1,1.23,618.45],[2,1.22,266.54]],"batl":[[0,1.42,105.75],[1,1.45,119.77],[2,1.46,169.59]],"ltp":1.34,"tv":11907.28,"id":9629022}]}]}
{"op":"mcm","clk":"4228108681","pt":1631459647606,"mc":[{"id":"1.187551081","rc":[{"batb":[[0,3.55,4.99],[1,3.35,5.27],[2,3.2,60.79]],"batl":[[0,5.1,48.77]],"ltp":3.9,"tv":1246.76,"id":7445998},{"batb":[[0,1.34,15.72],[1,1.24,446.76],[2,1.23,1152.15]],"batl":[[0,1.39,118.5],[1,1.42,105.75],[2,1.43,244.9]],"ltp":1.34,"tv":11907.28,"id":9629022}]}]}
{"op":"mcm","clk":"4228108714","pt":1631459647814,"mc":[{"id":"1.187551081","rc":[{"batb":[[0,3.35,5.27],[1,3.2,60.79],[2,3.15,148.33]],"ltp":3.9,"tv":1246.76,"id":7445998},{"batl":[[0,1.42,105.75],[1,1.43,244.9],[2,1.44,227.12]],"ltp":1.34,"tv":11907.28,"id":9629022}]}]}
{"op":"mcm","clk":"4228109301","pt":1631459651315,"mc":[{"id":"1.187551081","rc":[{"batb":[[0,1.24,446.76],[1,1.23,1152.15],[2,1.22,266.54]],"ltp":1.34,"tv":11907.28,"id":9629022}]}]}
{"op":"mcm","clk":"4228109843","pt":1631459654629,"mc":[{"id":"1.187551081","rc":[{"batb":[[0,3.55,5.79],[1,3.35,5.27],[2,3.2,60.79]],"ltp":3.9,"tv":1246.76,"id":7445998},{"batl":[[0,1.39,136.5],[1,1.42,105.75],[2,1.43,244.9]],"ltp":1.34,"tv":11907.28,"id":9629022}]}]}
{"op":"mcm","clk":"4228109954","pt":1631459654906,"mc":[{"id":"1.187551081","rc":[{"batb":[[0,3.35,5.27],[1,3.2,60.79],[2,3.15,148.33]],"ltp":3.9,"tv":1246.76,"id":7445998},{"batl":[[0,1.42,105.75],[1,1.43,244.9],[2,1.44,227.12]],"ltp":1.34,"tv":11907.28,"id":9629022}]}]}
{"op":"mcm","clk":"4228110884","pt":1631459660651,"mc":[{"id":"1.187551081","rc":[{"batl":[[0,5.1,3],[1,5.2,0],[2,5.3,0]],"ltp":3.9,"tv":1246.76,"id":7445998},{"batb":[[0,1.24,276.1],[1,1.23,965.03],[2,1.17,6.16]],"ltp":1.34,"tv":11907.28,"id":9629022}]}]}
{"op":"mcm","clk":"4228111056","pt":1631459661627,"mc":[{"id":"1.187551081","rc":[{"batb":[[0,3.55,5.79],[1,3.35,5.27],[2,3.2,60.79]],"ltp":3.9,"tv":1246.76,"id":7445998},{"batb":[[0,1.24,12],[1,1.23,431.33]],"batl":[[0,1.39,130.5],[1,1.42,105.75],[2,1.43,244.9]],"ltp":1.34,"tv":11907.28,"id":9629022}]}]}
{"op":"mcm","clk":"4228111084","pt":1631459661832,"mc":[{"id":"1.187551081","rc":[{"batb":[[0,3.35,5.27],[1,3.2,60.79],[2,3.15,148.33]],"ltp":3.9,"tv":1246.76,"id":7445998},{"batl":[[0,1.42,105.75],[1,1.43,244.9],[2,1.44,227.12]],"ltp":1.34,"tv":11907.28,"id":9629022}]}]}
{"op":"mcm","clk":"4228111531","pt":1631459664601,"mc":[{"id":"1.187551081","rc":[{"trd":[[1.4,149.94]],"batb":[[0,1.4,121.1],[1,1.39,269.47],[2,1.24,12]],"ltp":1.4,"tv":11992.19,"id":9629022}],"tv":13238.95}]}
{"op":"mcm","clk":"4228111685","pt":1631459665625,"mc":[{"id":"1.187551081","rc":[{"batl":[[0,3.85,15],[1,5.1,3]],"ltp":3.9,"tv":1246.76,"id":7445998},{"trd":[[1.42,211.5]],"batb":[[0,1.42,110.96],[2,1.35,60]],"batl":[[0,1.43,244.9],[1,1.44,227.12],[2,1.45,119.77]],"ltp":1.42,"tv":12203.69,"id":9629022}],"tv":13450.45}]}
{"op":"mcm","clk":"4228111737","pt":1631459665895,"mc":[{"id":"1.187551081","rc":[{"batb":[[2,1.34,278.35]],"ltp":1.42,"tv":12203.69,"id":9629022}]}]}
{"op":"mcm","clk":"4228112032","pt":1631459667619,"mc":[{"id":"1.187551081","rc":[{"batl":[[1,4.9,124.71],[2,5,3]],"ltp":3.9,"tv":1246.76,"id":7445998},{"batb":[[1,1.39,410.68],[2,1.38,281.52]],"batl":[[0,1.43,267.85]],"ltp":1.42,"tv":12203.69,"id":9629022}]}]}
{"op":"mcm","clk":"4228112192","pt":1631459668537,"mc":[{"id":"1.187551081","rc":[{"batl":[[1,4,81.68],[2,4.9,124.71]],"ltp":3.9,"tv":1246.76,"id":7445998},{"trd":[[1.42,433.42]],"batb":[[0,1.41,111.87]],"ltp":1.42,"tv":12425.61,"id":9629022}],"tv":13672.38}]}
{"op":"mcm","clk":"4228112274","pt":1631459669028,"mc":[{"id":"1.187551081","rc":[{"batl":[[1,5,3],[2,5.1,3]],"ltp":3.9,"tv":1246.76,"id":7445998},{"batb":[[0,1.42,60],[1,1.41,111.87],[2,1.39,410.68]],"ltp":1.42,"tv":12425.61,"id":9629022}]}]}
{"op":"mcm","clk":"4228112630","pt":1631459671147,"mc":[{"id":"1.187551081","rc":[{"batl":[[1,3.9,59.86],[2,3.95,53.58]],"ltp":3.9,"tv":1246.76,"id":7445998},{"batb":[[2,1.4,111.72]],"ltp":1.42,"tv":12425.61,"id":9629022}]}]}
{"op":"mcm","clk":"4228112958","pt":1631459673270,"mc":[{"id":"1.187551081","rc":[{"batb":[[1,3.3,127.25],[2,3.2,143.61]],"ltp":3.9,"tv":1246.76,"id":7445998},{"batb":[[1,1.41,335.53]],"batl":[[1,1.44,518.73]],"ltp":1.42,"tv":12425.61,"id":9629022}]}]}
{"op":"mcm","clk":"4228113186","pt":1631459674539,"mc":[{"id":"1.187551081","rc":[{"batl":[[0,3.45,133.23]],"ltp":3.9,"tv":1246.76,"id":7445998},{"trd":[[1.43,61.44]],"batb":[[2,1.4,440.03]],"batl":[[0,1.43,252.13]],"ltp":1.43,"tv":12457.05,"id":9629022}],"tv":13703.82}]}
{"op":"mcm","clk":"4228113376","pt":1631459675640,"mc":[{"id":"1.187551081","rc":[{"trd":[[1.42,456.29]],"batb":[[0,1.42,48.57]],"ltp":1.42,"tv":12479.92,"id":9629022}],"tv":13726.68}]}
{"op":"mcm","clk":"4228113647","pt":1631459677336,"mc":[{"id":"1.187551081","rc":[{"batb":[[2,1.4,589.01]],"ltp":1.42,"tv":12479.92,"id":9629022}]}]}
{"op":"mcm","clk":"4228113722","pt":1631459677824,"mc":[{"id":"1.187551081","rc":[{"batl":[[0,3.4,17.45],[1,3.45,133.23],[2,3.9,59.86]],"ltp":3.9,"tv":1246.76,"id":7445998}]}]}
{"op":"mcm","clk":"4228114027","pt":1631459679627,"mc":[{"id":"1.187551081","rc":[{"trd":[[1.43,341.44]],"batl":[[0,1.43,112.13]],"ltp":1.43,"tv":12759.92,"id":9629022}],"tv":14006.68}]}
{"op":"mcm","clk":"4228114154","pt":1631459680372,"mc":[{"id":"1.187551081","rc":[{"trd":[[1.42,490.45]],"batb":[[0,1.41,335.53],[1,1.4,589.01],[2,1.39,410.68]],"ltp":1.42,"tv":12794.08,"id":9629022}],"tv":14040.84}]}
{"op":"mcm","clk":"4228114352","pt":1631459681550,"mc":[{"id":"1.187551081","rc":[{"batl":[[2,3.55,112.73]],"ltp":3.9,"tv":1246.76,"id":7445998},{"batb":[[2,1.39,698.6]],"ltp":1.42,"tv":12794.08,"id":9629022}]}]}
{"op":"mcm","clk":"4228114533","pt":1631459682640,"mc":[{"id":"1.187551081","rc":[{"batb":[[1,3.2,143.61],[2,3.15,62]],"batl":[[1,3.9,59.86],[2,3.95,53.58]],"ltp":3.9,"tv":1246.76,"id":7445998},{"batb":[[1,1.4,260.7],[2,1.39,410.68]],"batl":[[1,1.44,227.12]],"ltp":1.42,"tv":12794.08,"id":9629022}]}]}
{"op":"mcm","clk":"4228114666","pt":1631459683379,"mc":[{"id":"1.187551081","rc":[{"batl":[[0,5,3],[1,3.9,0],[2,3.95,0]],"ltp":3.9,"tv":1246.76,"id":7445998},{"batb":[[1,1.4,339.87]],"batl":[[0,1.43,181.8]],"ltp":1.42,"tv":12794.08,"id":9629022}]}]}
{"op":"mcm","clk":"4228114893","pt":1631459684584,"mc":[{"id":"1.187551081","rc":[{"batb":[[0,1.41,385.96]],"ltp":1.42,"tv":12794.08,"id":9629022}]}]}
{"op":"mcm","clk":"4228115001","pt":1631459685157,"mc":[{"id":"1.187551081","rc":[{"trd":[[1.41,5.8]],"batb":[[0,1.41,383.06]],"batl":[[0,1.42,10.14],[1,1.43,181.8],[2,1.44,227.12]],"ltp":1.41,"tv":12799.88,"id":9629022}],"tv":14046.64}]}
{"op":"mcm","clk":"4228115244","pt":1631459686468,"mc":[{"id":"1.187551081","rc":[{"batl":[[0,3.85,45.26],[1,3.9,66.03],[2,3.95,75.22]],"ltp":3.9,"tv":1246.76,"id":7445998}]}]}
{"op":"mcm","clk":"4228115453","pt":1631459687657,"mc":[{"id":"1.187551081","rc":[{"batl":[[0,3.45,87.11],[1,3.5,100.78],[2,3.85,45.26]],"ltp":3.9,"tv":1246.76,"id":7445998},{"batb":[[1,1.4,806.48]],"ltp":1.41,"tv":12799.88,"id":9629022}]}]}
{"op":"mcm","clk":"4228115502","pt":1631459687973,"mc":[{"id":"1.187551081","rc":[{"trd":[[1.42,510.73]],"batb":[[0,1.42,96.96],[1,1.41,383.06],[2,1.4,806.48]],"batl":[[0,1.43,181.8],[1,1.44,227.12],[2,1.45,119.77]],"ltp":1.42,"tv":12820.16,"id":9629022}],"tv":14066.93}]}
{"op":"mcm","clk":"4228115796","pt":1631459689666,"mc":[{"id":"1.187551081","rc":[{"batb":[[0,3.35,46.26],[1,3.3,49.53],[2,3.2,143.61]],"ltp":3.9,"tv":1246.76,"id":7445998},{"batl":[[0,1.43,277.83],[1,1.44,340.63]],"ltp":1.42,"tv":12820.16,"id":9629022}]}]}
{"op":"mcm","clk":"4228116209","pt":1631459692095,"mc":[{"id":"1.187551081","rc":[{"batb":[[1,1.41,332.63]],"batl":[[0,1.43,242]],"ltp":1.42,"tv":12820.16,"id":9629022}]}]}
{"op":"mcm","clk":"4228116354","pt":1631459692996,"mc":[{"id":"1.187551081","rc":[{"batl":[[0,3.4,16.26],[1,3.45,87.11],[2,3.5,100.78]],"ltp":3.9,"tv":1246.76,"id":7445998}]}]}
{"op":"mcm","clk":"4228116757","pt":1631459695330,"mc":[{"id":"1.187551081","rc":[{"batb":[[0,1.42,147.39],[2,1.4,843.16]],"ltp":1.42,"tv":12820.16,"id":9629022}]}]}
{"op":"mcm","clk":"4228117951","pt":1631459702438,"mc":[{"id":"1.187551081","rc":[{"batb":[[2,3.25,82.15]],"ltp":3.9,"tv":1246.76,"id":7445998},{"batb":[[2,1.4,1068.24]],"ltp":1.42,"tv":12820.16,"id":9629022}]}]}
{"op":"mcm","clk":"4228118010","pt":1631459702834,"mc":[{"id":"1.187551081","rc":[{"batb":[[1,1.41,108.97]],"ltp":1.42,"tv":12820.16,"id":9629022}]}]}
{"op":"mcm","clk":"4228118711","pt":1631459707139,"mc":[{"id":"1.187551081","rc":[{"trd":[[1.42,512.24]],"batb":[[0,1.42,146.64]],"ltp":1.42,"tv":12821.66,"id":9629022}],"tv":14068.43}]}
{"op":"mcm","clk":"4228119995","pt":1631459715454,"mc":[{"id":"1.187551081","rc":[{"trd":[[1.43,381.44]],"batl":[[0,1.43,96.03]],"ltp":1.43,"tv":12861.66,"id":9629022}],"tv":14108.43}]}
{"op":"mcm","clk":"4228120402","pt":1631459718360,"mc":[{"id":"1.187551081","rc":[{"batl":[[1,1.44,474.62],[2,1.45,338.43]],"ltp":1.43,"tv":12861.66,"id":9629022}]}]}
{"op":"mcm","clk":"4228120583","pt":1631459719647,"mc":[{"id":"1.187551081","rc":[{"trd":[[1.42,522.38]],"batb":[[0,1.42,141.57]],"ltp":1.42,"tv":12871.81,"id":9629022}],"tv":14118.57}]}
{"op":"mcm","clk":"4228120901","pt":1631459722005,"mc":[{"id":"1.187551081","rc":[{"trd":[[1.42,544.92]],"batb":[[0,1.42,130.3]],"ltp":1.42,"tv":12894.35,"id":9629022}],"tv":14141.11}]}
{"op":"mcm","clk":"4228121131","pt":1631459723458,"mc":[{"id":"1.187551081","rc":[{"trd":[[1.43,421.44]],"batl":[[0,1.43,76.03]],"ltp":1.43,"tv":12934.35,"id":9629022}],"tv":14181.11}]}
{"op":"mcm","clk":"4228124371","pt":1631459744494,"mc":[{"id":"1.187551081","rc":[{"batb":[[0,1.41,108.97],[1,1.4,1068.24],[2,1.39,410.68]],"ltp":1.43,"tv":12934.35,"id":9629022}]}]}
{"op":"mcm","clk":"4228124805","pt":1631459747499,"mc":[{"id":"1.187551081","rc":[{"batl":[[0,1.43,134.37]],"ltp":1.43,"tv":12934.35,"id":9629022}]}]}
{"op":"mcm","clk":"4228124837","pt":1631459747708,"mc":[{"id":"1.187551081","rc":[{"batb":[[0,1.41,155.98]],"ltp":1.43,"tv":12934.35,"id":9629022}]}]}
{"op":"mcm","clk":"4228125109","pt":1631459749508,"mc":[{"id":"1.187551081","rc":[{"batl":[[0,1.42,5],[1,1.43,134.37],[2,1.44,474.62]],"ltp":1.43,"tv":12934.35,"id":9629022}]}]}
{"op":"mcm","clk":"4228126656","pt":1631459759330,"mc":[{"id":"1.187551081","rc":[{"batl":[[2,1.44,340.67]],"ltp":1.43,"tv":12934.35,"id":9629022}]}]}
{"op":"mcm","clk":"4228126799","pt":1631459760249,"mc":[{"id":"1.187551081","rc":[{"batl":[[0,3.45,87.11],[1,3.5,100.78],[2,3.85,45.26]],"ltp":3.9,"tv":1246.76,"id":7445998},{"batb":[[0,1.41,108.97]],"ltp":1.43,"tv":12934.35,"id":9629022}]}]}
{"op":"mcm","clk":"4228127167","pt":1631459762530,"mc":[{"id":"1.187551081","rc":[{"batl":[[1,1.43,293.52]],"ltp":1.43,"tv":12934.35,"id":9629022}]}]}
{"op":"mcm","clk":"4228127313","pt":1631459763434,"mc":[{"id":"1.187551081","rc":[{"batl":[[0,1.42,44.01]],"ltp":1.43,"tv":12934.35,"id":9629022}]}]}
{"op":"mcm","clk":"4228127851","pt":1631459766554,"mc":[{"id":"1.187551081","rc":[{"trd":[[3.35,13.43]],"batb":[[0,3.35,45.95]],"ltp":3.35,"tv":1247.38,"id":7445998},{"trd":[[1.41,15.8]],"batb":[[0,1.41,103.97]],"ltp":1.41,"tv":12944.35,"id":9629022}],"tv":14191.73}]}
{"op":"mcm","clk":"4228129958","pt":1631459779387,"mc":[{"id":"1.187551081","rc":[{"batl":[[0,3.4,16.26],[1,3.45,87.11],[2,3.5,100.78]],"ltp":3.35,"tv":1247.38,"id":7445998},{"batb":[[0,1.41,154.4]],"ltp":1.41,"tv":12944.35,"id":9629022}]}]}
{"op":"mcm","clk":"4228132400","pt":1631459794419,"mc":[{"id":"1.187551081","rc":[{"batb":[[0,3,2],[1,2.88,5.21],[2,2.74,109.2]],"batl":[[0,3.85,45.26],[1,3.9,66.03],[2,3.95,75.22]],"ltp":3.35,"tv":1247.38,"id":7445998},{"batb":[[0,1.35,149.01],[1,1.34,184.91],[2,1.33,458.96]],"batl":[[0,1.53,64.5],[1,1.58,156.49],[2,1.59,126.85]],"ltp":1.41,"tv":12944.35,"id":9629022}]}]}
{"op":"mcm","clk":"4228132466","pt":1631459794814,"mc":[{"id":"1.187551081","rc":[{"batb":[[1,2.74,109.2],[2,2.72,90.48]],"ltp":3.35,"tv":1247.38,"id":7445998},{"batl":[[0,1.58,156.49],[1,1.59,126.85],[2,1.6,167.35]],"ltp":1.41,"tv":12944.35,"id":9629022}]}]}
{"op":"mcm","clk":"4228132925","pt":1631459797631,"mc":[{"id":"1.187551081","rc":[{"batb":[[1,2.76,49.66],[2,2.74,58.87]],"ltp":3.35,"tv":1247.38,"id":7445998},{"batb":[[0,1.35,156.01],[1,1.34,193.91],[2,1.33,815.14]],"batl":[[0,1.56,291.99],[1,1.57,160.32],[2,1.58,156.49]],"ltp":1.41,"tv":12944.35,"id":9629022}]}]}
{"op":"mcm","clk":"4228133042","pt":1631459798333,"mc":[{"id":"1.187551081","rc":[{"batb":[[2,2.72,5.34]],"ltp":3.35,"tv":1247.38,"id":7445998},{"batl":[[0,1.58,57.75],[1,2,30],[2,3.8,27.47]],"ltp":1.41,"tv":12944.35,"id":9629022}]}]}
{"op":"mcm","clk":"4228133489","pt":1631459801236,"mc":[{"id":"1.187551081","rc":[{"batl":[[0,3.95,75.22],[1,5,3],[2,3.95,0]],"ltp":3.35,"tv":1247.38,"id":7445998},{"batb":[[0,1.34,184.91],[1,1.33,815.14],[2,1.32,348.65]],"batl":[[0,1.36,236.36],[1,1.37,282.88],[2,1.58,57.75]],"ltp":1.41,"tv":12944.35,"id":9629022}]}]}
{"op":"mcm","clk":"4228133669","pt":1631459802428,"mc":[{"id":"1.187551081","rc":[{"batb":[[0,3.75,57.61],[1,3.15,96.92],[2,3,2]],"ltp":3.35,"tv":1247.38,"id":7445998},{"batl":[[2,1.46,169.49]],"ltp":1.41,"tv":12944.35,"id":9629022}]}]}
{"op":"mcm","clk":"4228133862","pt":1631459803530,"mc":[{"id":"1.187551081","rc":[{"batl":[[2,5.5,113.67]],"ltp":3.35,"tv":1247.38,"id":7445998}]}]}
{"op":"mcm","clk":"4228134037","pt":1631459804490,"mc":[{"id":"1.187551081","rc":[{"batl":[[0,3.9,13.88],[1,3.95,75.22],[2,5,3]],"ltp":3.35,"tv":1247.38,"id":7445998},{"batb":[[0,1.34,235.58]],"ltp":1.41,"tv":12944.35,"id":9629022}]}]}
{"op":"mcm","clk":"4228134167","pt":1631459805304,"mc":[{"id":"1.187551081","rc":[{"batb":[[0,1.34,388.85]],"ltp":1.41,"tv":12944.35,"id":9629022}]}]}
{"op":"mcm","clk":"4228134300","pt":1631459806235,"mc":[{"id":"1.187551081","rc":[{"trd":[[3.9,5.34]],"batl":[[0,3.9,11.78]],"ltp":3.9,"tv":1251.57,"id":7445998},{"trd":[[1.34,983.07]],"batb":[[0,1.34,385.96]],"ltp":1.34,"tv":12950.12,"id":9629022}],"tv":14201.7}]}
{"op":"mcm","clk":"4228134640","pt":1631459808130,"mc":[{"id":"1.187551081","rc":[{"batb":[[0,3.75,139.6],[1,3.7,91.38],[2,3.35,3.67]],"batl":[[2,4.2,3.08]],"ltp":3.9,"tv":1251.57,"id":7445998},{"batb":[[2,1.32,433.29]],"batl":[[1,1.37,507.3],[2,1.38,245.01]],"ltp":1.34,"tv":12950.12,"id":9629022}]}]}
{"op":"mcm","clk":"4228134850","pt":1631459809515,"mc":[{"id":"1.187551081","rc":[{"batb":[[0,3.35,3.67],[1,3.15,90.75],[2,3.1,59.42]],"batl":[[0,4.2,3.08],[1,4.4,45.36],[2,4.5,53.76]],"ltp":3.9,"tv":1251.57,"id":7445998},{"batb":[[0,1.33,12.31],[1,1.32,84.64],[2,1.3,84.68]],"batl":[[0,1.42,72.75],[1,1.46,64.75],[2,1.47,141.81]],"ltp":1.34,"tv":12950.12,"id":9629022}]}]}
{"op":"mcm","clk":"4228134896","pt":1631459809827,"mc":[{"id":"1.187551081","rc":[{"batb":[[0,3.15,90.75],[1,3.1,59.42],[2,3.05,60.92]],"batl":[[0,4.4,45.36],[1,4.5,53.76],[2,4.6,54.54]],"ltp":3.9,"tv":1251.57,"id":7445998},{"batb":[[1,1.3,84.68],[2,1.29,177.19]],"batl":[[0,1.34,320]],"ltp":1.34,"tv":12950.12,"id":9629022}]}]}
{"op":"mcm","clk":"4228135360","pt":1631459812446,"mc":[{"id":"1.187551081","rc":[{"batl":[[0,1.45,212.54],[1,1.46,278.64]],"ltp":1.34,"tv":12950.12,"id":9629022}]}]}
{"op":"mcm","clk":"4228135519","pt":1631459813329,"mc":[{"id":"1.187551081","rc":[{"batb":[[0,3.15,93.75],[1,3.1,62.42]],"ltp":3.9,"tv":1251.57,"id":7445998}]}]}
{"op":"mcm","clk":"4228135923","pt":1631459815641,"mc":[{"id":"1.187551081","rc":[{"batb":[[0,3.2,3],[1,3.15,93.75],[2,3.1,62.42]],"ltp":3.9,"tv":1251.57,"id":7445998},{"batl":[[0,1.45,217.54],[1,1.46,285.64]],"ltp":1.34,"tv":12950.12,"id":9629022}]}]}
{"op":"mcm","clk":"4228136070","pt":1631459816548,"mc":[{"id":"1.187551081","rc":[{"batb":[[0,3.35,3.67],[1,3.2,3],[2,3.15,93.75]],"batl":[[0,4.2,2.58],[1,4.4,45.36],[2,4.5,53.76]],"ltp":3.9,"tv":1251.57,"id":7445998},{"batb":[[1,1.32,80.39],[2,1.3,84.68]],"batl":[[0,1.42,77.25],[1,1.45,217.54],[2,1.46,285.64]],"ltp":1.34,"tv":12950.12,"id":9629022}]}]}
{"op":"mcm","clk":"4228136115","pt":1631459816831,"mc":[{"id":"1.187551081","rc":[{"batb":[[0,3.2,3],[1,3.15,93.75],[2,3.1,62.42]],"batl":[[0,4.4,45.36],[1,4.5,53.76],[2,4.6,54.54]],"ltp":3.9,"tv":1251.57,"id":7445998},{"batb":[[1,1.3,84.68],[2,1.29,177.19]],"batl":[[0,1.45,217.54],[1,1.46,285.64],[2,1.47,141.81]],"ltp":1.34,"tv":12950.12,"id":9629022}]}]}
{"op":"mcm","clk":"4228137278","pt":1631459824439,"mc":[{"id":"1.187551081","rc":[{"batb":[[1,3.15,90.75],[2,3.1,59.42]],"ltp":3.9,"tv":1251.57,"id":7445998}]}]}
{"op":"mcm","clk":"4228137889","pt":1631459827630,"mc":[{"id":"1.187551081","rc":[{"batb":[[0,3.35,3.87],[1,3.2,3],[2,3.15,93.75]],"batl":[[0,4.2,2.63],[1,4.4,45.36],[2,4.5,53.76]],"ltp":3.9,"tv":1251.57,"id":7445998},{"batb":[[1,1.32,85.89],[2,1.3,84.68]],"batl":[[0,1.42,67.75],[1,1.45,217.54],[2,1.46,285.64]],"ltp":1.34,"tv":12950.12,"id":9629022}]}]}
{"op":"mcm","clk":"4228138009","pt":1631459828058,"mc":[{"id":"1.187551081","rc":[{"batb":[[0,3.2,3],[1,3.15,93.75],[2,3.1,59.42]],"batl":[[0,4.4,45.36],[1,4.5,53.76],[2,4.6,54.54]],"ltp":3.9,"tv":1251.57,"id":7445998},{"batb":[[1,1.3,84.68],[2,1.29,177.19]],"batl":[[0,1.45,217.54],[1,1.46,278.64],[2,1.47,141.81]],"ltp":1.34,"tv":12950.12,"id":9629022}]}]}
{"op":"mcm","clk":"4228138464","pt":1631459830449,"mc":[{"id":"1.187551081","rc":[{"batb":[[2,2.2,42.66]],"ltp":3.9,"tv":1251.57,"id":7445998},{"batl":[[0,1.45,5],[1,1.46,64.75],[2,2,30]],"ltp":1.34,"tv":12950.12,"id":9629022}]}]}
{"op":"mcm","clk":"4228138937","pt":1631459833243,"mc":[{"id":"1.187551081","rc":[{"batb":[[0,3.9,10.36],[1,3.2,3],[2,3.15,93.75]],"ltp":3.9,"tv":1251.57,"id":7445998},{"trd":[[1.33,33.29]],"batb":[[0,1.3,84.68],[1,1.29,177.19],[2,1.28,555.44]],"batl":[[0,1.31,383.42],[1,1.32,336.68],[2,1.34,91.25]],"ltp":1.33,"tv":12974.75,"id":9629022}],"tv":14226.33}]}
{"op":"mcm","clk":"4228139133","pt":1631459834335,"mc":[{"id":"1.187551081","rc":[{"batb":[[0,4.2,84.83],[1,3.9,10.36],[2,3.7,58.28]],"ltp":3.9,"tv":1251.57,"id":7445998}]}]}
{"op":"mcm","clk":"4228139345","pt":1631459835479,"mc":[{"id":"1.187551081","rc":[{"batl":[[0,4.4,56.68]],"ltp":3.9,"tv":1251.57,"id":7445998}]}]}
{"op":"mcm","clk":"4228139658","pt":1631459837358,"mc":[{"id":"1.187551081","rc":[{"batb":[[1,1.29,334.64]],"ltp":1.33,"tv":12974.75,"id":9629022}]}]}
{"op":"mcm","clk":"4228139868","pt":1631459838661,"mc":[{"id":"1.187551081","rc":[{"trd":[[4.4,7.04]],"batb":[[0,4.2,165.96],[1,4.1,91.38],[2,3.9,10.36]],"batl":[[0,4.4,55.8]],"ltp":4.4,"tv":1253.33,"id":7445998},{"trd":[[1.3,108.74]],"batb":[[0,1.3,81.81]],"batl":[[1,1.32,594.83],[2,1.33,281.7]],"ltp":1.3,"tv":12980.49,"id":9629022}],"tv":14233.82}]}
{"op":"mcm","clk":"4228140176","pt":1631459840306,"mc":[{"id":"1.187551081","rc":[{"batl":[[2,4.6,56.85]],"ltp":4.4,"tv":1253.33,"id":7445998},{"batb":[[2,1.28,642.1]],"ltp":1.3,"tv":12980.49,"id":9629022}]}]}
{"op":"mcm","clk":"4228141879","pt":1631459850436,"mc":[{"id":"1.187551081","rc":[{"batb":[[0,3.75,3.15],[1,3.7,58.28],[2,3.55,53.92]],"batl":[[0,4.6,2.31],[1,4.8,50.9],[2,4.9,42.66]],"ltp":4.4,"tv":1253.33,"id":7445998},{"batb":[[0,1.28,86.66],[1,1.26,240.92],[2,1.25,162.76]],"batl":[[0,1.36,82.57],[1,1.39,219.63],[2,1.4,130.01]],"ltp":1.3,"tv":12980.49,"id":9629022}]}]}
{"op":"mcm","clk":"4228141920","pt":1631459850716,"mc":[{"id":"1.187551081","rc":[{"batb":[[0,3.7,58.28],[1,3.55,53.92],[2,3.5,67.58]],"batl":[[0,4.8,50.9],[1,4.9,42.66],[2,5,54.61]],"ltp":4.4,"tv":1253.33,"id":7445998},{"batb":[[0,1.26,240.92],[1,1.25,162.76],[2,1.24,205.86]],"batl":[[0,1.39,219.63],[1,1.4,130.01],[2,1.41,154.91]],"ltp":1.3,"tv":12980.49,"id":9629022}]}]}
{"op":"mcm","clk":"4228142369","pt":1631459853615,"mc":[{"id":"1.187551081","rc":[{"batl":[[0,4.6,2],[1,4.8,50.9],[2,4.9,42.66]],"ltp":4.4,"tv":1253.33,"id":7445998},{"batb":[[0,1.28,9],[1,1.27,10],[2,1.26,240.92]],"ltp":1.3,"tv":12980.49,"id":9629022}]}]}
{"op":"mcm","clk":"4228142502","pt":1631459854429,"mc":[{"id":"1.187551081","rc":[{"batl":[[1,4.8,53.9]],"ltp":4.4,"tv":1253.33,"id":7445998},{"batb":[[2,1.26,249.92]],"batl":[[0,1.38,8],[1,1.39,219.63],[2,1.4,130.01]],"ltp":1.3,"tv":12980.49,"id":9629022}]}]}
{"op":"mcm","clk":"4228142798","pt":1631459856235,"mc":[{"id":"1.187551081","rc":[{"batb":[[0,1.29,387.16],[1,1.28,421.28],[2,1.27,10]],"batl":[[0,1.32,348.29],[1,1.33,324.72],[2,1.38,8]],"ltp":1.3,"tv":12980.49,"id":9629022}]}]}
{"op":"mcm","clk":"4228142999","pt":1631459857422,"mc":[{"id":"1.187551081","rc":[{"batb":[[0,3.75,35.28],[1,3.7,58.28],[2,3.55,53.92]],"batl":[[0,4.5,10],[1,4.6,2],[2,4.8,53.9]],"ltp":4.4,"tv":1253.33,"id":7445998},{"batl":[[2,1.38,138.39]],"ltp":1.3,"tv":12980.49,"id":9629022}]}]}
{"op":"mcm","clk":"4228143086","pt":1631459858053,"mc":[{"id":"1.187551081","rc":[{"batb":[[0,3.75,3.27]],"batl":[[1,4.6,4.21]],"ltp":4.4,"tv":1253.33,"id":7445998},{"batb":[[1,1.28,517.19]],"batl":[[2,1.36,82.57]],"ltp":1.3,"tv":12980.49,"id":9629022}]}]}
{"op":"mcm","clk":"4228143480","pt":1631459860523,"mc":[{"id":"1.187551081","rc":[{"batb":[[0,1.3,138.02],[1,1.29,387.16],[2,1.28,517.19]],"ltp":1.3,"tv":12980.49,"id":9629022}]}]}
{"op":"mcm","clk":"4228143606","pt":1631459861442,"mc":[{"id":"1.187551081","rc":[{"batb":[[0,3.8,16.35],[1,3.75,3.27],[2,3.7,58.28]],"ltp":4.4,"tv":1253.33,"id":7445998},{"batb":[[0,1.3,187.51]],"ltp":1.3,"tv":12980.49,"id":9629022}]}]}
{"op":"mcm","clk":"4228143643","pt":1631459861727,"mc":[{"id":"1.187551081","rc":[{"batb":[[0,3.75,3.27],[1,3.7,58.28],[2,3.55,53.92]],"ltp":4.4,"tv":1253.33,"id":7445998}]}]}
{"op":"mcm","clk":"4228143903","pt":1631459863550,"mc":[{"id":"1.187551081","rc":[{"batb":[[1,1.28,104.91],[2,1.27,10]],"batl":[[0,1.36,82.57],[1,1.38,8],[2,1.39,226.63]],"ltp":1.3,"tv":12980.49,"id":9629022}]}]}
{"op":"mcm","clk":"4228143917","pt":1631459863715,"mc":[{"id":"1.187551081","rc":[{"batb":[[0,3.7,58.28],[1,3.55,53.92],[2,3.5,67.58]],"ltp":4.4,"tv":1253.33,"id":7445998},{"batl":[[0,1.38,8],[1,1.39,226.63],[2,1.4,130.01]],"ltp":1.3,"tv":12980.49,"id":9629022}]}]}
{"op":"mcm","clk":"4228144151","pt":1631459865271,"mc":[{"id":"1.187551081","rc":[{"batl":[[2,4.8,50.9]],"ltp":4.4,"tv":1253.33,"id":7445998},{"batb":[[0,1.32,40],[1,1.3,187.51],[2,1.28,104.91]],"batl":[[0,1.39,226.63],[1,1.4,130.01],[2,1.41,154.91]],"ltp":1.3,"tv":12980.49,"id":9629022}]}]}
{"op":"mcm","clk":"4228153858","pt":1631459866468,"mc":[{"id":"1.187551081","rc":[{"batb":[[0,1.32,60],[1,1.31,122.7],[2,1.3,187.51]],"batl":[[0,1.37,433.49],[1,1.38,270.99],[2,1.39,226.63]],"ltp":1.3,"tv":12980.49,"id":9629022}]}]}
{"op":"mcm","clk":"4228153970","pt":1631459867380,"mc":[{"id":"1.187551081","rc":[{"batb":[[0,1.32,40]],"ltp":1.3,"tv":12980.49,"id":9629022}]}]}
{"op":"mcm","clk":"4228154125","pt":1631459868542,"mc":[{"id":"1.187551081","rc":[{"batb":[[0,3.85,24.51],[1,3.7,58.28],[2,3.55,53.92]],"batl":[[0,4.6,4.21],[1,4.8,50.9],[2,4.9,42.66]],"ltp":4.4,"tv":1253.33,"id":7445998},{"batb":[[1,1.28,104.91],[2,1.26,240.92]],"batl":[[1,1.38,278.99]],"ltp":1.3,"tv":12980.49,"id":9629022}]}]}
{"op":"mcm","clk":"4228154298","pt":1631459869591,"mc":[{"id":"1.187551081","rc":[{"batb":[[0,3.7,58.28],[1,3.55,53.92],[2,3.5,67.58]],"batl":[[0,4.6,2]],"ltp":4.4,"tv":1253.33,"id":7445998},{"batb":[[1,1.28,9]],"ltp":1.3,"tv":12980.49,"id":9629022}]}]}
{"op":"mcm","clk":"4228154487","pt":1631459870547,"mc":[{"id":"1.187551081","rc":[{"batb":[[0,3.75,3.31],[1,3.7,58.28],[2,3.55,53.92]],"ltp":4.4,"tv":1253.33,"id":7445998},{"batl":[[0,1.36,79.82],[1,1.37,433.49],[2,1.38,278.99]],"ltp":1.3,"tv":12980.49,"id":9629022}]}]}
{"op":"mcm","clk":"4228154582","pt":1631459871156,"mc":[{"id":"1.187551081","rc":[{"batb":[[0,3.7,58.28],[1,3.55,53.92],[2,3.5,67.58]],"ltp":4.4,"tv":1253.33,"id":7445998},{"batb":[[0,1.28,9],[1,1.26,240.92],[2,1.25,472.27]],"batl":[[0,1.37,433.49],[1,1.38,278.99],[2,1.39,226.63]],"ltp":1.3,"tv":12980.49,"id":9629022}]}]}
{"op":"mcm","clk":"4228154748","pt":1631459872360,"mc":[{"id":"1.187551081","rc":[{"batl":[[0,1.37,440.49]],"ltp":1.3,"tv":12980.49,"id":9629022}]}]}
{"op":"mcm","clk":"4228155039","pt":1631459874514,"mc":[{"id":"1.187551081","rc":[{"batb":[[1,1.27,10],[2,1.26,240.92]],"ltp":1.3,"tv":12980.49,"id":9629022}]}]}
{"op":"mcm","clk":"4228155210","pt":1631459875575,"mc":[{"id":"1.187551081","rc":[{"batb":[[0,1.28,69],[1,1.27,50]],"batl":[[0,1.37,7],[1,1.38,8]],"ltp":1.3,"tv":12980.49,"id":9629022}]}]}
{"op":"mcm","clk":"4228155327","pt":1631459876288,"mc":[{"id":"1.187551081","rc":[{"batb":[[1,3.55,3.19],[2,3.25,2]],"batl":[[0,4.6,4.21]],"ltp":4.4,"tv":1253.33,"id":7445998},{"batb":[[0,1.28,157.66]],"batl":[[2,1.39,83.5]],"ltp":1.3,"tv":12980.49,"id":9629022}]}]}
{"op":"mcm","clk":"4228155546","pt":1631459877655,"mc":[{"id":"1.187551081","rc":[{"batb":[[0,3.75,3.27],[1,3.7,58.28],[2,3.55,3.19]],"batl":[[0,4.8,50.9],[1,4.9,42.66],[2,5,51.61]],"ltp":4.4,"tv":1253.33,"id":7445998},{"batb":[[0,1.28,60],[1,1.27,40]],"batl":[[0,1.36,83.32],[1,1.37,7],[2,1.38,8]],"ltp":1.3,"tv":12980.49,"id":9629022}]}]}
{"op":"mcm","clk":"4228155662","pt":1631459878565,"mc":[{"id":"1.187551081","rc":[{"batb":[[0,4.2,9.62]],"ltp":4.4,"tv":1253.33,"id":7445998},{"trd":[[1.27,550.59],[1.28,366.7]],"batb":[[0,1.26,240.92],[1,1.25,472.27],[2,1.24,689.74]],"batl":[[0,1.27,107.44],[1,1.28,400.08],[2,1.31,93.5]],"ltp":1.27,"tv":13180.49,"id":9629022}],"tv":14433.82}]}
{"op":"mcm","clk":"4228155800","pt":1631459879594,"mc":[{"id":"1.187551081","rc":[{"batb":[[0,4.7,65.99],[1,4.3,81.56],[2,3.7,58.28]],"batl":[[0,4.9,42.66],[1,5,51.61],[2,6.6,97.86]],"ltp":4.4,"tv":1253.33,"id":7445998},{"batl":[[0,1.28,400.08],[1,1.37,7],[2,1.38,8]],"ltp":1.27,"tv":13180.49,"id":9629022}]}]}
{"op":"mcm","clk":"4228155920","pt":1631459880422,"mc":[{"id":"1.187551081","rc":[{"batb":[[2,3.9,64.1]],"ltp":4.4,"tv":1253.33,"id":7445998},{"batl":[[1,1.35,35],[2,1.36,9]],"ltp":1.27,"tv":13180.49,"id":9629022}]}]}
{"op":"mcm","clk":"4228156066","pt":1631459881285,"mc":[{"id":"1.187551081","rc":[{"batl":[[1,1.35,41]],"ltp":1.27,"tv":13180.49,"id":9629022}]}]}
{"op":"mcm","clk":"4228156201","pt":1631459882000,"mc":[{"id":"1.187551081","rc":[{"batb":[[1,4.3,83.56],[2,4.2,2]],"batl":[[0,4.9,55.42]],"ltp":4.4,"tv":1253.33,"id":7445998},{"batb":[[0,1.26,279.79],[1,1.25,528.8]],"batl":[[0,1.28,550.81],[1,1.29,375.66],[2,1.35,41]],"ltp":1.27,"tv":13180.49,"id":9629022}]}]}
{"op":"mcm","clk":"4228156431","pt":1631459883620,"mc":[{"id":"1.187551081","rc":[{"trd":[[4.9,8.69]],"batl":[[0,4.9,54.71]],"ltp":4.9,"tv":1254.75,"id":7445998},{"trd":[[1.26,185.63]],"batb":[[0,1.26,396.47]],"ltp":1.26,"tv":13185.97,"id":9629022}],"tv":14440.73}]}
{"op":"mcm","clk":"4228156492","pt":1631459884007,"mc":[{"id":"1.187551081","rc":[{"batl":[[0,1.27,20],[1,1.28,550.81],[2,1.29,375.66]],"ltp":1.26,"tv":13185.97,"id":9629022}]}]}
{"op":"mcm","clk":"4228156748","pt":1631459885667,"mc":[{"id":"1.187551081","rc":[{"batl":[[1,5,53.61],[2,5.1,49.25]],"ltp":4.9,"tv":1254.75,"id":7445998},{"batb":[[1,1.25,629.45],[2,1.24,985.97]],"ltp":1.26,"tv":13185.97,"id":9629022}]}]}
{"op":"mcm","clk":"4228158422","pt":1631459895494,"mc":[{"id":"1.187551081","rc":[{"batb":[[0,4.3,81.56],[1,4.1,2.74],[2,4,45.21]],"batl":[[0,5,2],[1,5.1,49.25],[2,5.2,48.88]],"ltp":4.9,"tv":1254.75,"id":7445998},{"batb":[[0,1.25,100.65],[1,1.24,296.23],[2,1.23,223.55]],"batl":[[1,1.32,86.86],[2,1.33,168.16]],"ltp":1.26,"tv":13185.97,"id":9629022}]}]}
{"op":"mcm","clk":"4228158885","pt":1631459898422,"mc":[{"id":"1.187551081","rc":[{"batl":[[0,5,5]],"ltp":4.9,"tv":1254.75,"id":7445998},{"batb":[[2,1.23,799.54]],"batl":[[1,1.3,190.66],[2,1.31,352.45]],"ltp":1.26,"tv":13185.97,"id":9629022}]}]}
{"op":"mcm","clk":"4228158979","pt":1631459899019,"mc":[{"id":"1.187551081","rc":[{"batl":[[2,5.2,46.5]],"ltp":4.9,"tv":1254.75,"id":7445998},{"batb":[[0,1.25,110.65],[1,1.24,189.96]],"ltp":1.26,"tv":13185.97,"id":9629022}]}]}
{"op":"mcm","clk":"4228159608","pt":1631459902906,"mc":[{"id":"1.187551081","rc":[{"batl":[[1,1.29,40],[2,1.3,190.66]],"ltp":1.26,"tv":13185.97,"id":9629022}]}]}
{"op":"mcm","clk":"4228160036","pt":1631459905623,"mc":[{"id":"1.187551081","rc":[{"batl":[[0,4.9,2.25],[1,5,5],[2,5.1,49.25]],"ltp":4.9,"tv":1254.75,"id":7445998},{"batb":[[0,1.26,94.48],[1,1.25,110.65],[2,1.24,189.96]],"ltp":1.26,"tv":13185.97,"id":9629022}]}]}
{"op":"mcm","clk":"4228160141","pt":1631459906326,"mc":[{"id":"1.187551081","rc":[{"batl":[[0,5,5],[1,5.1,49.25],[2,5.2,46.5]],"ltp":4.9,"tv":1254.75,"id":7445998},{"batb":[[0,1.25,110.65],[1,1.24,189.96],[2,1.23,799.54]],"batl":[[0,1.29,40],[1,1.3,190.66],[2,1.31,352.45]],"ltp":1.26,"tv":13185.97,"id":9629022}]}]}
{"op":"mcm","clk":"4228161155","pt":1631459912629,"mc":[{"id":"1.187551081","rc":[{"batl":[[0,4.9,2.15],[1,5,5],[2,5.1,49.25]],"ltp":4.9,"tv":1254.75,"id":7445998},{"batb":[[0,1.26,87.48],[1,1.25,110.65],[2,1.24,189.96]],"ltp":1.26,"tv":13185.97,"id":9629022}]}]}
{"op":"mcm","clk":"4228161195","pt":1631459912920,"mc":[{"id":"1.187551081","rc":[{"batl":[[0,5,5],[1,5.1,49.25],[2,5.2,46.5]],"ltp":4.9,"tv":1254.75,"id":7445998},{"batb":[[0,1.25,110.65],[1,1.24,181.96],[2,1.23,799.54]],"ltp":1.26,"tv":13185.97,"id":9629022}]}]}
{"op":"mcm","clk":"4228161779","pt":1631459916449,"mc":[{"id":"1.187551081","rc":[{"batb":[[1,1.24,190.96]],"ltp":1.26,"tv":13185.97,"id":9629022}]}]}
{"op":"mcm","clk":"4228163930","pt":1631459929167,"mc":[{"id":"1.187551081","rc":[{"batb":[[1,1.24,181.96]],"ltp":1.26,"tv":13185.97,"id":9629022}]}]}
{"op":"mcm","clk":"4228164137","pt":1631459930506,"mc":[{"id":"1.187551081","rc":[{"batb":[[2,3.85,2.97]],"ltp":4.9,"tv":1254.75,"id":7445998},{"batl":[[1,1.32,86.86],[2,1.35,6]],"ltp":1.26,"tv":13185.97,"id":9629022}]}]}
{"op":"mcm","clk":"4228164310","pt":1631459931493,"mc":[{"id":"1.187551081","rc":[{"batl":[[0,5,2]],"ltp":4.9,"tv":1254.75,"id":7445998},{"batb":[[0,1.25,100.65]],"ltp":1.26,"tv":13185.97,"id":9629022}]}]}
{"op":"mcm","clk":"4228164458","pt":1631459932350,"mc":[{"id":"1.187551081","rc":[{"batb":[[1,1.24,191.96]],"ltp":1.26,"tv":13185.97,"id":9629022}]}]}
{"op":"mcm","clk":"4228164648","pt":1631459933454,"mc":[{"id":"1.187551081","rc":[{"batl":[[0,4.9,3],[1,5,2],[2,5.1,49.25]],"ltp":4.9,"tv":1254.75,"id":7445998},{"batb":[[1,1.24,181.96]],"batl":[[0,1.26,478.13],[1,1.27,411.15],[2,1.29,40]],"ltp":1.26,"tv":13185.97,"id":9629022}]}]}
{"op":"mcm","clk":"4228164829","pt":1631459934493,"mc":[{"id":"1.187551081","rc":[{"trd":[[5,104.59]],"batb":[[0,5,29.44],[1,4.5,2],[2,4.4,3]],"batl":[[0,5.3,48.58],[1,5,0],[2,5.1,0]],"ltp":5.0,"tv":1283.92,"id":7445998},{"trd":[[1.25,1848.12]],"batb":[[0,1.23,799.54],[1,1.22,775.2],[2,1.21,481.24]],"batl":[[2,1.28,7]],"ltp":1.25,"tv":13286.62,"id":9629022}],"tv":14570.54}]}
{"op":"mcm","clk":"4228165016","pt":1631459935565,"mc":[{"id":"1.187551081","rc":[{"batb":[[2,4.4,36.18]],"batl":[[1,7.8,87.04]],"ltp":5.0,"tv":1283.92,"id":7445998},{"batl":[[0,1.25,60],[1,1.26,508.13],[2,1.27,411.15]],"ltp":1.25,"tv":13286.62,"id":9629022}]}]}
{"op":"mcm","clk":"4228165344","pt":1631459937667,"mc":[{"id":"1.187551081","rc":[{"trd":[[5,118.53]],"batb":[[0,5,22.47]],"batl":[[0,5.2,15.67],[1,5.3,48.58],[2,7.8,87.04]],"ltp":5.0,"tv":1297.86,"id":7445998},{"batb":[[0,1.24,172.56],[1,1.23,799.54],[2,1.22,775.2]],"ltp":1.25,"tv":13286.62,"id":9629022}],"tv":14584.48}]}
{"op":"mcm","clk":"4228165429","pt":1631459938155,"mc":[{"id":"1.187551081","rc":[{"batb":[[1,1.23,925.48]],"ltp":1.25,"tv":13286.62,"id":9629022}]}]}
{"op":"mcm","clk":"4228165668","pt":1631459939566,"mc":[{"id":"1.187551081","rc":[{"batb":[[0,5,65.76],[1,4.9,87.11],[2,4.5,2]],"batl":[[0,5.2,2],[1,7.8,87.04],[2,7.8,0]],"ltp":5.0,"tv":1297.86,"id":7445998},{"batb":[[0,1.2,6.16],[1,1.17,635.32],[2,1.13,1.28]],"batl":[[0,1.25,323.05],[1,1.26,368.77],[2,1.28,7]],"ltp":1.25,"tv":13286.62,"id":9629022}]}]}
{"op":"mcm","clk":"4228165760","pt":1631459940175,"mc":[{"id":"1.187551081","rc":[{"batb":[[0,4.3,80.97],[1,4,57.18],[2,3.95,48.69]],"batl":[[0,6.4,34.72],[1,6.6,38.96],[2,6.8,55.59]],"ltp":5.0,"tv":1297.86,"id":7445998},{"batb":[[1,1.19,225.71],[2,1.18,275.56]],"batl":[[0,1.25,60],[1,1.26,30],[2,1.33,109.5]],"ltp":1.25,"tv":13286.62,"id":9629022}]}]}
{"op":"mcm","clk":"4228166164","pt":1631459942567,"mc":[{"id":"1.187551081","rc":[{"batb":[[0,4.4,79.13]],"ltp":5.0,"tv":1297.86,"id":7445998},{"batb":[[1,1.19,482.49],[2,1.18,969.14]],"batl":[[1,1.31,420.13],[2,1.32,335.08]],"ltp":1.25,"tv":13286.62,"id":9629022}]}]}
{"op":"mcm","clk":"4228166325","pt":1631459943608,"mc":[{"id":"1.187551081","rc":[{"batl":[[0,6.4,2],[1,7,2],[2,7.8,87.04]],"ltp":5.0,"tv":1297.86,"id":7445998},{"batb":[[1,1.16,646.21],[2,1.13,1.28]],"ltp":1.25,"tv":13286.62,"id":9629022}]}]}
{"op":"mcm","clk":"4228166359","pt":1631459943761,"mc":[{"id":"1.187551081","rc":[{"trd":[[5,125.47]],"ltp":5.0,"tv":1304.8,"id":7445998},{"trd":[[1.25,1875.88]],"batl":[[0,1.25,32.24]],"ltp":1.25,"tv":13314.38,"id":9629022}],"tv":14619.18}]}
{"op":"mcm","clk":"4228166623","pt":1631459945399,"mc":[{"id":"1.187551081","rc":[{"batl":[[2,7.8,0]],"ltp":5.0,"tv":1304.8,"id":7445998},{"batl":[[0,1.31,420.13],[1,1.32,335.08],[2,1.33,109.5]],"ltp":1.25,"tv":13314.38,"id":9629022}]}]}
{"op":"mcm","clk":"4228166809","pt":1631459946482,"mc":[{"id":"1.187551081","rc":[{"trd":[[1.24,1551.59],[1.28,385.7]],"batb":[[0,1.28,320.93],[1,1.27,429.2],[2,1.2,6.16]],"ltp":1.24,"tv":13394.38,"id":9629022}],"tv":14699.18}]}
{"op":"mcm","clk":"4228166970","pt":1631459947495,"mc":[{"id":"1.187551081","rc":[{"batl":[[0,5.1,10],[1,6.4,2],[2,7,2]],"ltp":5.0,"tv":1304.8,"id":7445998},{"batb":[[2,1.26,384.53]],"ltp":1.24,"tv":13394.38,"id":9629022}]}]}
{"op":"mcm","clk":"4228167160","pt":1631459948476,"mc":[{"id":"1.187551081","rc":[{"batb":[[1,4,59.18],[2,3.95,50.69]],"batl":[[0,5,3],[1,6.2,2],[2,6.4,2]],"ltp":5.0,"tv":1304.8,"id":7445998}]}]}
{"op":"mcm","clk":"4228167516","pt":1631459950624,"mc":[{"id":"1.187551081","rc":[{"batb":[[0,1.29,120.24],[1,1.28,320.93],[2,1.27,429.2]],"ltp":1.24,"tv":13394.38,"id":9629022}]}]}
{"op":"mcm","clk":"4228167679","pt":1631459951488,"mc":[{"id":"1.187551081","rc":[{"trd":[[4.5,2.39]],"batl":[[0,4.6,20.64],[1,5,3],[2,6.2,2]],"ltp":4.5,"tv":1305.55,"id":7445998},{"trd":[[1.29,164.05]],"batb":[[0,1.29,156.32]],"ltp":1.29,"tv":13402.32,"id":9629022}],"tv":14707.87}]}
{"op":"mcm","clk":"4228167709","pt":1631459951700,"mc":[{"id":"1.187551081","rc":[{"batl":[[0,5,3],[1,6.2,2],[2,6.4,2]],"ltp":4.5,"tv":1305.55,"id":7445998}]}]}
{"op":"mcm","clk":"4228168005","pt":1631459953544,"mc":[{"id":"1.187551081","rc":[{"batl":[[1,5.3,44.16],[2,5.4,51.44]],"ltp":4.5,"tv":1305.55,"id":7445998}]}]}
{"op":"mcm","clk":"4228168349","pt":1631459955526,"mc":[{"id":"1.187551081","rc":[{"batl":[[0,4.9,20.64],[1,5,3],[2,5.3,44.16]],"ltp":4.5,"tv":1305.55,"id":7445998}]}]}
{"op":"mcm","clk":"4228168539","pt":1631459956563,"mc":[{"id":"1.187551081","rc":[{"batb":[[1,3.9,4.46],[2,3.85,107.27]],"batl":[[0,5.3,44.16],[1,5.4,51.44],[2,5.5,54.18]],"ltp":4.5,"tv":1305.55,"id":7445998},{"batb":[[0,1.26,384.53],[1,1.23,203.8],[2,1.22,197.31]],"batl":[[0,1.34,137.25],[1,1.37,126.5],[2,1.38,164.1]],"ltp":1.29,"tv":13402.32,"id":9629022}]}]}
{"op":"mcm","clk":"4228168613","pt":1631459956998,"mc":[{"id":"1.187551081","rc":[{"batb":[[0,3.85,107.27],[1,3.7,4.12],[2,3.6,48.71]],"ltp":4.5,"tv":1305.55,"id":7445998},{"batb":[[0,1.23,203.8],[1,1.22,197.31],[2,1.21,754.88]],"batl":[[0,1.37,126.5],[1,1.38,164.1],[2,1.39,185.16]],"ltp":1.29,"tv":13402.32,"id":9629022}]}]}
{"op":"mcm","clk":"4228168918","pt":1631459958644,"mc":[{"id":"1.187551081","rc":[{"batl":[[0,4.5,76.01],[1,4.6,99.07],[2,5.3,44.16]],"ltp":4.5,"tv":1305.55,"id":7445998},{"batb":[[0,1.28,267.22],[1,1.27,358.83],[2,1.23,203.8]],"ltp":1.29,"tv":13402.32,"id":9629022}]}]}
{"op":"mcm","clk":"4228169025","pt":1631459959394,"mc":[{"id":"1.187551081","rc":[{"batl":[[0,5.3,44.16],[1,5.4,51.44],[2,5.5,54.18]],"ltp":4.5,"tv":1305.55,"id":7445998},{"batb":[[0,1.23,602.63],[1,1.22,749.24],[2,1.21,754.88]],"batl":[[0,1.36,326.58],[1,1.37,407.36],[2,1.38,164.1]],"ltp":1.29,"tv":13402.32,"id":9629022}]}]}
{"op":"mcm","clk":"4228169219","pt":1631459960535,"mc":[{"id":"1.187551081","rc":[{"batl":[[0,5.3,47.16]],"ltp":4.5,"tv":1305.55,"id":7445998},{"batb":[[1,1.22,758.24]],"batl":[[0,1.36,333.58]],"ltp":1.29,"tv":13402.32,"id":9629022}]}]}
{"op":"mcm","clk":"4228169660","pt":1631459963541,"mc":[{"id":"1.187551081","rc":[{"batb":[[0,1.23,612.63]],"ltp":1.29,"tv":13402.32,"id":9629022}]}]}
{"op":"mcm","clk":"4228170230","pt":1631459967544,"mc":[{"id":"1.187551081","rc":[{"batb":[[0,3.9,4.96],[1,3.85,107.27],[2,3.7,4.12]],"ltp":4.5,"tv":1305.55,"id":7445998},{"batl":[[0,1.34,132.75],[1,1.36,333.58],[2,1.37,407.36]],"ltp":1.29,"tv":13402.32,"id":9629022}]}]}
{"op":"mcm","clk":"4228170275","pt":1631459967880,"mc":[{"id":"1.187551081","rc":[{"batb":[[0,3.85,107.27],[1,3.7,4.12],[2,3.6,48.71]],"ltp":4.5,"tv":1305.55,"id":7445998},{"batl":[[0,1.36,333.58],[1,1.37,407.36],[2,1.38,164.1]],"ltp":1.29,"tv":13402.32,"id":9629022}]}]}
{"op":"mcm","clk":"4228170548","pt":1631459969393,"mc":[{"id":"1.187551081","rc":[{"batb":[[0,1.3,5],[1,1.23,612.63],[2,1.22,758.24]],"ltp":1.29,"tv":13402.32,"id":9629022}]}]}
{"op":"mcm","clk":"4228170905","pt":1631459971430,"mc":[{"id":"1.187551081","rc":[{"batb":[[2,2.62,380.45]],"batl":[[0,5.3,44.16]],"ltp":4.5,"tv":1305.55,"id":7445998},{"batb":[[1,1.23,602.63],[2,1.22,749.24]],"batl":[[0,1.36,7],[1,2,30],[2,3.8,27.47]],"ltp":1.29,"tv":13402.32,"id":9629022}]}]}
{"op":"mcm","clk":"4228171110","pt":1631459972668,"mc":[{"id":"1.187551081","rc":[{"trd":[[1.3,118.74]],"batb":[[0,1.23,602.63],[1,1.22,749.24],[2,1.21,754.88]],"batl":[[0,1.26,7.14],[1,1.36,7],[2,2,30]],"ltp":1.3,"tv":13412.32,"id":9629022}],"tv":14717.87}]}
{"op":"mcm","clk":"4228171129","pt":1631459972780,"mc":[{"id":"1.187551081","rc":[{"batl":[[0,1.36,7],[1,2,30],[2,3.8,27.47]],"ltp":1.3,"tv":13412.32,"id":9629022}]}]}
{"op":"mcm","clk":"4228171381","pt":1631459974240,"mc":[{"id":"1.187551081","rc":[{"trd":[[3.85,16.06]],"batb":[[0,4.7,14.72],[1,3.9,3],[2,3.85,107.24]],"ltp":3.85,"tv":1311.61,"id":7445998},{"batl":[[0,1.25,204.03],[1,1.26,436.9],[2,1.27,163.5]],"ltp":1.3,"tv":13412.32,"id":9629022}],"tv":14723.94}]}
{"op":"mcm","clk":"4228171589","pt":1631459975568,"mc":[{"id":"1.187551081","rc":[{"batb":[[0,5.1,54.26],[1,4.7,14.72],[2,4.3,80.81]],"ltp":3.85,"tv":1311.61,"id":7445998}]}]}
{"op":"mcm","clk":"4228171680","pt":1631459976166,"mc":[{"id":"1.187551081","rc":[{"batl":[[0,5.2,10.69],[1,5.3,44.16],[2,5.4,51.44]],"ltp":3.85,"tv":1311.61,"id":7445998},{"trd":[[1.25,1890.16]],"batb":[[0,1.23,674.92]],"batl":[[0,1.25,196.89]],"ltp":1.25,"tv":13426.6,"id":9629022}],"tv":14738.22}]}
{"op":"mcm","clk":"4228171916","pt":1631459977557,"mc":[{"id":"1.187551081","rc":[{"trd":[[1.25,1907.24]],"batl":[[0,1.25,188.35]],"ltp":1.25,"tv":13443.68,"id":9629022}],"tv":14755.3}]}
{"op":"mcm","clk":"4228172051","pt":1631459978456,"mc":[{"id":"1.187551081","rc":[{"batb":[[0,1.23,808.45]],"ltp":1.25,"tv":13443.68,"id":9629022}]}]}
{"op":"mcm","clk":"4228172144","pt":1631459979144,"mc":[{"id":"1.187551081","rc":[{"trd":[[5.2,134.9]],"batl":[[0,5.2,10.07]],"ltp":5.2,"tv":1312.85,"id":7445998},{"trd":[[1.23,139.98]],"batb":[[0,1.23,806.08]],"ltp":1.23,"tv":13448.41,"id":9629022}],"tv":14761.27}]}
{"op":"mcm","clk":"4228172454","pt":1631459981252,"mc":[{"id":"1.187551081","rc":[{"batb":[[2,4.4,4.21]],"ltp":5.2,"tv":1312.85,"id":7445998}]}]}
{"op":"mcm","clk":"4228172742","pt":1631459983187,"mc":[{"id":"1.187551081","rc":[{"trd":[[1.23,179.98]],"batb":[[0,1.23,786.08]],"ltp":1.23,"tv":13488.41,"id":9629022}],"tv":14801.27}]}
{"op":"mcm","clk":"4228173266","pt":1631459986558,"mc":[{"id":"1.187551081","rc":[{"trd":[[1.23,350.79]],"batb":[[0,1.23,700.68]],"ltp":1.23,"tv":13659.22,"id":9629022}],"tv":14972.08}]}
{"op":"mcm","clk":"4228173560","pt":1631459988665,"mc":[{"id":"1.187551081","rc":[{"batb":[[0,4.3,80.81],[1,4.1,4.04],[2,3.95,59.08]],"batl":[[0,6.6,38.66],[1,6.8,37.98],[2,7,39.66]],"ltp":5.2,"tv":1312.85,"id":7445998},{"batb":[[0,1.18,214.61],[1,1.17,206.93],[2,1.16,247.94]],"batl":[[0,1.32,120.86],[1,1.34,121.74],[2,1.35,162.17]],"ltp":1.23,"tv":13659.22,"id":9629022}]}]}
{"op":"mcm","clk":"4228173978","pt":1631459991581,"mc":[{"id":"1.187551081","rc":[{"batb":[[0,1.18,519.08],[1,1.17,962.65]],"batl":[[0,1.31,268.62],[1,1.32,458.56],[2,1.34,121.74]],"ltp":1.23,"tv":13659.22,"id":9629022}]}]}
{"op":"mcm","clk":"4228174071","pt":1631459992161,"mc":[{"id":"1.187551081","rc":[{"batl":[[0,6.6,41.66]],"ltp":5.2,"tv":1312.85,"id":7445998}]}]}
{"op":"mcm","clk":"4228174291","pt":1631459993577,"mc":[{"id":"1.187551081","rc":[{"batl":[[0,4.5,265.34],[1,6.6,3],[2,8.6,81.16]],"ltp":5.2,"tv":1312.85,"id":7445998},{"batb":[[0,1.18,13],[1,1.17,13],[2,1.15,691.09]],"ltp":1.23,"tv":13659.22,"id":9629022}]}]}
{"op":"mcm","clk":"4228174392","pt":1631459994285,"mc":[{"id":"1.187551081","rc":[{"batl":[[0,6.6,3],[1,8.6,81.16],[2,8.6,0]],"ltp":5.2,"tv":1312.85,"id":7445998},{"batl":[[0,1.3,40],[1,1.31,268.62],[2,1.32,458.56]],"ltp":1.23,"tv":13659.22,"id":9629022}]}]}
{"op":"mcm","clk":"4228174587","pt":1631459995369,"mc":[{"id":"1.187551081","rc":[{"batb":[[0,4.4,4.41],[1,4.3,80.81],[2,4.1,4.04]],"batl":[[1,8.6,0]],"ltp":5.2,"tv":1312.85,"id":7445998},{"batl":[[0,1.29,139.5],[1,1.3,40],[2,1.31,268.62]],"ltp":1.23,"tv":13659.22,"id":9629022}]}]}
{"op":"mcm","clk":"4228174767","pt":1631459996623,"mc":[{"id":"1.187551081","rc":[{"batb":[[0,4.3,83.81],[1,4.2,2]],"ltp":5.2,"tv":1312.85,"id":7445998},{"batb":[[0,1.28,577.16],[1,1.27,432.59],[2,1.18,13]],"batl":[[0,1.31,275.62],[1,1.32,458.56],[2,1.34,121.74]],"ltp":1.23,"tv":13659.22,"id":9629022}]}]}
{"op":"mcm","clk":"4228174928","pt":1631459997452,"mc":[{"id":"1.187551081","rc":[{"batb":[[0,4.3,80.81],[1,4.1,4.04],[2,3.95,59.08]],"ltp":5.2,"tv":1312.85,"id":7445998},{"batb":[[2,1.26,378.83]],"batl":[[0,1.3,7],[1,1.31,268.62],[2,1.32,458.56]],"ltp":1.23,"tv":13659.22,"id":9629022}]}]}
{"op":"mcm","clk":"4228175061","pt":1631459998117,"mc":[{"id":"1.187551081","rc":[{"batb":[[2,3.95,62.08]],"batl":[[0,5.1,15],[1,6.4,2],[2,6.6,3]],"ltp":5.2,"tv":1312.85,"id":7445998},{"trd":[[1.28,425.7]],"batb":[[0,1.28,557.16]],"batl":[[0,1.31,268.62],[1,1.32,458.56],[2,1.34,121.74]],"ltp":1.28,"tv":13699.22,"id":9629022}],"tv":15012.08}]}
{"op":"mcm","clk":"4228175317","pt":1631459999516,"mc":[{"id":"1.187551081","rc":[{"batl":[[0,4.5,2],[2,6.6,100.86]],"ltp":5.2,"tv":1312.85,"id":7445998}]}]}
{"op":"mcm","clk":"4228175485","pt":1631460000608,"mc":[{"id":"1.187551081","rc":[{"batb":[[0,1.28,712.95]],"ltp":1.28,"tv":13699.22,"id":9629022}]}]}
{"op":"mcm","clk":"4228175593","pt":1631460001221,"mc":[{"id":"1.187551081","rc":[{"trd":[[4.5,3.83]],"batl":[[0,4.5,1.28]],"ltp":4.5,"tv":1314.3,"id":7445998},{"trd":[[1.29,169.19]],"batb":[[0,1.29,62.43],[1,1.28,712.95],[2,1.27,432.59]],"ltp":1.29,"tv":13704.36,"id":9629022}],"tv":15018.66}]}
{"op":"mcm","clk":"4228175850","pt":1631460002620,"mc":[{"id":"1.187551081","rc":[{"batl":[[0,4.4,15],[1,4.5,1.28],[2,6.4,2]],"ltp":4.5,"tv":1314.3,"id":7445998},{"batb":[[0,1.29,72.43]],"ltp":1.29,"tv":13704.36,"id":9629022}]}]}
{"op":"mcm","clk":"4228176008","pt":1631460003488,"mc":[{"id":"1.187551081","rc":[{"batb":[[0,4.3,149.75],[1,4.2,87.63],[2,4.1,4.04]],"batl":[[0,4.4,6.4],[2,5.3,42.79]],"ltp":4.5,"tv":1314.3,"id":7445998},{"batl":[[0,1.3,228.03],[1,1.31,549.6],[2,1.32,458.56]],"ltp":1.29,"tv":13704.36,"id":9629022}]}]}
{"op":"mcm","clk":"4228176148","pt":1631460004426,"mc":[{"id":"1.187551081","rc":[{"batb":[[0,1.29,221.19]],"ltp":1.29,"tv":13704.36,"id":9629022}]}]}
{"op":"mcm","clk":"4228176341","pt":1631460005611,"mc":[{"id":"1.187551081","rc":[{"batl":[[1,4.5,71.31],[2,4.6,91.38]],"ltp":4.5,"tv":1314.3,"id":7445998},{"batb":[[0,1.29,211.19],[1,1.28,959.15],[2,1.27,763.57]],"ltp":1.29,"tv":13704.36,"id":9629022}]}]}
{"op":"mcm","clk":"4228176495","pt":1631460006485,"mc":[{"id":"1.187551081","rc":[{"batb":[[0,3.75,62.27],[1,3.7,4.82],[2,3.5,48.96]],"batl":[[0,5.3,42.79],[1,5.4,51.17],[2,5.5,47.18]],"ltp":4.5,"tv":1314.3,"id":7445998},{"batb":[[0,1.23,172.55],[1,1.22,198.42],[2,1.21,268.5]],"batl":[[0,1.36,133.07],[1,1.37,119.5],[2,1.4,153.86]],"ltp":1.29,"tv":13704.36,"id":9629022}]}]}
{"op":"mcm","clk":"4228176778","pt":1631460008089,"mc":[{"id":"1.187551081","rc":[{"batb":[[0,1.3,10],[1,1.23,172.55],[2,1.22,198.42]],"ltp":1.29,"tv":13704.36,"id":9629022}]}]}
{"op":"mcm","clk":"4228177012","pt":1631460009585,"mc":[{"id":"1.187551081","rc":[{"batb":[[0,3.9,4.56],[1,3.75,62.27],[2,3.7,4.82]],"ltp":4.5,"tv":1314.3,"id":7445998},{"batb":[[0,1.23,422.7],[1,1.22,746.09],[2,1.21,268.5]],"batl":[[0,1.34,129.25],[1,1.36,133.07],[2,1.37,348.23]],"ltp":1.29,"tv":13704.36,"id":9629022}]}]}
{"op":"mcm","clk":"4228177056","pt":1631460009908,"mc":[{"id":"1.187551081","rc":[{"batb":[[0,3.75,64.27],[1,3.7,6.82],[2,3.5,48.96]],"ltp":4.5,"tv":1314.3,"id":7445998},{"batl":[[0,1.36,141.07],[1,1.37,348.23],[2,1.38,272.66]],"ltp":1.29,"tv":13704.36,"id":9629022}]}]}
{"op":"mcm","clk":"4228178315","pt":1631460017221,"mc":[{"id":"1.187551081","rc":[{"batb":[[2,2.9,377.47]],"ltp":4.5,"tv":1314.3,"id":7445998},{"batl":[[1,1.37,125.5],[2,2,30]],"ltp":1.29,"tv":13704.36,"id":9629022}]}]}
{"op":"mcm","clk":"4228178501","pt":1631460018398,"mc":[{"id":"1.187551081","rc":[{"batb":[[0,1.24,5.87],[1,1.23,422.7],[2,1.22,746.09]],"ltp":1.29,"tv":13704.36,"id":9629022}]}]}
{"op":"mcm","clk":"4228178656","pt":1631460019209,"mc":[{"id":"1.187551081","rc":[{"batb":[[0,1.23,422.7],[1,1.22,746.09],[2,1.21,268.5]],"ltp":1.29,"tv":13704.36,"id":9629022}]}]}
{"op":"mcm","clk":"4228178868","pt":1631460020441,"mc":[{"id":"1.187551081","rc":[{"batb":[[0,4.8,14.83],[1,3.75,64.27],[2,3.7,6.82]],"batl":[[0,5.4,51.17],[1,5.5,47.18],[2,6.4,2]],"ltp":4.5,"tv":1314.3,"id":7445998},{"batl":[[0,1.25,372.44],[1,1.26,604.81],[2,1.36,141.07]],"ltp":1.29,"tv":13704.36,"id":9629022}]}]}
{"op":"mcm","clk":"4228179009","pt":1631460021327,"mc":[{"id":"1.187551081","rc":[{"batb":[[0,5.2,52.42],[1,4.8,14.83],[2,4.2,88.43]],"ltp":4.5,"tv":1314.3,"id":7445998}]}]}
{"op":"mcm","clk":"4228179185","pt":1631460022317,"mc":[{"id":"1.187551081","rc":[{"batb":[[2,4.2,146.58]],"batl":[[0,5.3,12.74],[1,5.4,51.17],[2,5.5,47.18]],"ltp":4.5,"tv":1314.3,"id":7445998},{"batb":[[0,1.23,486.22]],"batl":[[2,1.32,189.39]],"ltp":1.29,"tv":13704.36,"id":9629022}]}]}
{"op":"mcm","clk":"4228179433","pt":1631460023613,"mc":[{"id":"1.187551081","rc":[{"batl":[[0,5.3,15.74]],"ltp":4.5,"tv":1314.3,"id":7445998}]}]}
{"op":"mcm","clk":"4228179560","pt":1631460024416,"mc":[{"id":"1.187551081","rc":[{"batb":[[0,1.23,635.43]],"ltp":1.29,"tv":13704.36,"id":9629022}]}]}
{"op":"mcm","clk":"4228179722","pt":1631460025233,"mc":[{"id":"1.187551081","rc":[{"trd":[[5.3,4.38]],"batl":[[0,5.3,15.13]],"ltp":5.3,"tv":1315.52,"id":7445998},{"trd":[[1.23,355.99]],"batb":[[0,1.23,632.83]],"ltp":1.23,"tv":13709.56,"id":9629022}],"tv":15025.08}]}
{"op":"mcm","clk":"4228179935","pt":1631460026528,"mc":[{"id":"1.187551081","rc":[{"batb":[[2,4.4,4.46]],"ltp":5.3,"tv":1315.52,"id":7445998},{"batl":[[2,1.29,121.5]],"ltp":1.23,"tv":13709.56,"id":9629022}]}]}
{"op":"mcm","clk":"4228180152","pt":1631460027715,"mc":[{"id":"1.187551081","rc":[{"trd":[[5.2,137.29]],"batb":[[0,5.2,50.04]],"ltp":5.2,"tv":1317.9,"id":7445998},{"trd":[[1.24,1561.59]],"ltp":1.24,"tv":13719.56,"id":9629022}],"tv":15037.47}]}
{"op":"mcm","clk":"4228180326","pt":1631460028736,"mc":[{"id":"1.187551081","rc":[{"trd":[[5.2,147.93]],"batb":[[0,5.2,44.71]],"ltp":5.2,"tv":1328.55,"id":7445998}],"tv":15048.11}]}
{"op":"mcm","clk":"4228180780","pt":1631460031532,"mc":[{"id":"1.187551081","rc":[{"trd":[[5.2,148.95]],"batb":[[0,5.2,43.7]],"ltp":5.2,"tv":1329.56,"id":7445998},{"trd":[[1.23,995.99],[1.24,1565.86]],"batb":[[0,1.23,312.83]],"batl":[[0,1.25,342.72]],"ltp":1.23,"tv":14363.83,"id":9629022}],"tv":15693.4}]}
{"op":"mcm","clk":"4228180954","pt":1631460032655,"mc":[{"id":"1.187551081","rc":[{"batb":[[0,4.2,88.43],[1,4.1,3.94],[2,3.8,3]],"batl":[[0,8.6,81.16],[1,5.4,0],[2,5.5,0]],"ltp":5.2,"tv":1329.56,"id":7445998},{"batb":[[0,1.15,20],[1,1.14,768.88],[2,1.13,1.28]],"batl":[[0,1.32,120.36],[1,1.35,8],[2,1.36,141.07]],"ltp":1.23,"tv":14363.83,"id":9629022}]}]}
{"op":"mcm","clk":"4228181383","pt":1631460035555,"mc":[{"id":"1.187551081","rc":[{"batb":[[0,4.2,2],[1,4.1,95.87]],"ltp":5.2,"tv":1329.56,"id":7445998},{"batb":[[1,1.14,765.78]],"batl":[[1,1.36,133.07],[2,1.37,119.5]],"ltp":1.23,"tv":14363.83,"id":9629022}]}]}
{"op":"mcm","clk":"4228181514","pt":1631460036245,"mc":[{"id":"1.187551081","rc":[{"batl":[[0,7.8,3],[1,8.6,81.16]],"ltp":5.2,"tv":1329.56,"id":7445998},{"batb":[[0,1.16,553.62],[1,1.15,676.83],[2,1.14,782.78]],"batl":[[0,1.32,370.6],[1,1.33,326.77],[2,1.36,133.07]],"ltp":1.23,"tv":14363.83,"id":9629022}]}]}
{"op":"mcm","clk":"4228181875","pt":1631460038558,"mc":[{"id":"1.187551081","rc":[{"batb":[[2,4,2]],"ltp":5.2,"tv":1329.56,"id":7445998}]}]}
{"op":"mcm","clk":"4228181998","pt":1631460039362,"mc":[{"id":"1.187551081","rc":[{"batl":[[0,7.4,3],[1,7.8,3],[2,8.6,81.16]],"ltp":5.2,"tv":1329.56,"id":7445998}]}]}
{"op":"mcm","clk":"4228182454","pt":1631460042533,"mc":[{"id":"1.187551081","rc":[{"batb":[[0,4.4,3.81],[1,4.2,2],[2,4.1,95.87]],"ltp":5.2,"tv":1329.56,"id":7445998},{"batl":[[0,1.29,117.5],[1,1.32,370.6],[2,1.33,326.77]],"ltp":1.23,"tv":14363.83,"id":9629022}]}]}
{"op":"mcm","clk":"4228182607","pt":1631460043649,"mc":[{"id":"1.187551081","rc":[{"batb":[[0,4.2,2],[1,4.1,95.87],[2,4,2]],"ltp":5.2,"tv":1329.56,"id":7445998},{"batb":[[0,1.17,109.94],[1,1.16,553.62],[2,1.15,676.83]],"batl":[[0,1.32,370.6],[1,1.33,326.77],[2,1.36,133.07]],"ltp":1.23,"tv":14363.83,"id":9629022}]}]}
{"op":"mcm","clk":"4228183022","pt":1631460046664,"mc":[{"id":"1.187551081","rc":[{"batl":[[0,1.32,128.36],[1,1.36,133.07],[2,1.37,119.5]],"ltp":1.23,"tv":14363.83,"id":9629022}]}]}
{"op":"mcm","clk":"4228183035","pt":1631460046755,"mc":[{"id":"1.187551081","rc":[{"batl":[[1,2,30],[2,3.8,27.47]],"ltp":1.23,"tv":14363.83,"id":9629022}]}]}
{"op":"mcm","clk":"4228183261","pt":1631460048570,"mc":[{"id":"1.187551081","rc":[{"batl":[[2,8.6,0]],"ltp":5.2,"tv":1329.56,"id":7445998},{"batb":[[2,1.15,656.83]],"ltp":1.23,"tv":14363.83,"id":9629022}]}]}
{"op":"mcm","clk":"4228183413","pt":1631460049568,"mc":[{"id":"1.187551081","rc":[{"batb":[[0,6.4,12.46],[1,4.2,2],[2,4.1,92.87]],"ltp":5.2,"tv":1329.56,"id":7445998},{"batl":[[0,1.18,721.08],[1,1.19,623.96],[2,1.32,128.36]],"ltp":1.23,"tv":14363.83,"id":9629022}]}]}
{"op":"mcm","clk":"4228183581","pt":1631460050666,"mc":[{"id":"1.187551081","rc":[{"batb":[[0,6.8,55.52],[1,6.4,12.46],[2,5.2,52.42]],"ltp":5.2,"tv":1329.56,"id":7445998}]}]}
{"op":"mcm","clk":"4228183693","pt":1631460051482,"mc":[{"id":"1.187551081","rc":[{"batb":[[2,5.5,10]],"batl":[[0,7.2,12.49],[1,7.4,3]],"ltp":5.2,"tv":1329.56,"id":7445998},{"batl":[[2,1.23,203.25]],"ltp":1.23,"tv":14363.83,"id":9629022}]}]}
{"op":"mcm","clk":"4228183890","pt":1631460052766,"mc":[{"id":"1.187551081","rc":[{"batl":[[2,12.5,65.62]],"ltp":5.2,"tv":1329.56,"id":7445998}]}]}
{"op":"mcm","clk":"4228184164","pt":1631460054661,"mc":[{"id":"1.187551081","rc":[{"trd":[[7,31.36]],"ltp":7.0,"tv":1330.0,"id":7445998},{"trd":[[1.17,1006.41]],"batb":[[0,1.17,32.25],[1,1.16,726.41]],"ltp":1.17,"tv":14516.62,"id":9629022}],"tv":15846.62}]}
{"op":"mcm","clk":"4228184502","pt":1631460056480,"mc":[{"id":"1.187551081","rc":[{"batb":[[1,6.4,65.84],[2,6.2,73.43]],"ltp":7.0,"tv":1330.0,"id":7445998},{"trd":[[1.17,1070.92]],"batb":[[0,1.16,726.41],[1,1.15,656.83],[2,1.14,765.78]],"batl":[[0,1.17,114.28],[1,1.18,1010.6],[2,1.19,1006.57]],"ltp":1.17,"tv":14581.13,"id":9629022}],"tv":15911.13}]}
{"op":"mcm","clk":"4228184535","pt":1631460056801,"mc":[{"id":"1.187551081","rc":[{"batl":[[0,1.17,124.28]],"ltp":1.17,"tv":14581.13,"id":9629022}]}]}
{"op":"mcm","clk":"4228184764","pt":1631460058367,"mc":[{"id":"1.187551081","rc":[{"trd":[[1.16,1016.17]],"batb":[[0,1.16,716.41]],"ltp":1.16,"tv":14601.13,"id":9629022}],"tv":15931.13}]}
{"op":"mcm","clk":"4228184951","pt":1631460059575,"mc":[{"id":"1.187551081","rc":[{"batb":[[0,1.16,800.43]],"batl":[[0,1.17,114.28]],"ltp":1.16,"tv":14601.13,"id":9629022}]}]}
{"op":"mcm","clk":"4228185180","pt":1631460060895,"mc":[{"id":"1.187551081","rc":[{"batl":[[1,7.4,50.66],[2,7.8,51.87]],"ltp":7.0,"tv":1330.0,"id":7445998},{"batb":[[0,1.16,1104.47],[1,1.15,1008.7]],"ltp":1.16,"tv":14601.13,"id":9629022}]}]}
{"op":"mcm","clk":"4228185386","pt":1631460062190,"mc":[{"id":"1.187551081","rc":[{"trd":[[1.16,1026.17]],"batb":[[0,1.16,1099.47]],"batl":[[1,1.18,1047.41]],"ltp":1.16,"tv":14611.13,"id":9629022}],"tv":15941.13}]}
{"op":"mcm","clk":"4228185767","pt":1631460064287,"mc":[{"id":"1.187551081","rc":[{"batb":[[0,5.3,3.08],[1,5.2,52.42],[2,5.1,3.04]],"batl":[[0,12.5,65.62],[1,7.4,0],[2,7.8,0]],"ltp":7.0,"tv":1330.0,"id":7445998},{"batb":[[0,1.13,1.28],[1,1.08,1311.34],[2,1.03,494.18]],"batl":[[1,1.23,109.5],[2,1.24,110.23]],"ltp":1.16,"tv":14611.13,"id":9629022}]}]}
{"op":"mcm","clk":"4228186061","pt":1631460066110,"mc":[{"id":"1.187551081","rc":[{"trd":[[1.17,1082.88]],"batl":[[0,1.17,108.3]],"ltp":1.17,"tv":14623.09,"id":9629022}],"tv":15953.09}]}
{"op":"mcm","clk":"4228186294","pt":1631460067395,"mc":[{"id":"1.187551081","rc":[{"batl":[[0,12.5,67.62]],"ltp":7.0,"tv":1330.0,"id":7445998},{"batb":[[1,1.08,1341.34],[2,1.07,27]],"ltp":1.17,"tv":14623.09,"id":9629022}]}]}
{"op":"mcm","clk":"4228186777","pt":1631460070387,"mc":[{"id":"1.187551081","rc":[{"batl":[[0,8,18.9],[1,12.5,67.62]],"ltp":7.0,"tv":1330.0,"id":7445998},{"batb":[[0,1.14,19.32],[1,1.13,1.28],[2,1.08,1341.34]],"batl":[[0,1.17,128.8]],"ltp":1.17,"tv":14623.09,"id":9629022}]}]}
{"op":"mcm","clk":"4228186969","pt":1631460071531,"mc":[{"id":"1.187551081","rc":[{"batb":[[0,5.8,15.4],[1,5.3,3.08],[2,5.2,52.42]],"batl":[[0,8.8,25.64]],"ltp":7.0,"tv":1330.0,"id":7445998},{"batb":[[0,1.15,365.33],[1,1.14,840.24],[2,1.13,1.28]],"batl":[[0,1.17,888.61],[1,1.18,394.11],[2,1.23,109.5]],"ltp":1.17,"tv":14623.09,"id":9629022}]}]}
{"op":"mcm","clk":"4228187218","pt":1631460072914,"mc":[{"id":"1.187551081","rc":[{"batb":[[0,5.3,3.08],[1,5.2,52.42],[2,5.1,3.04]],"batl":[[0,12.5,67.62],[1,12.5,0]],"ltp":7.0,"tv":1330.0,"id":7445998},{"batb":[[0,1.13,1.28],[1,1.08,1341.34],[2,1.07,27]],"batl":[[0,1.17,108.3],[1,1.23,109.5],[2,1.24,110.23]],"ltp":1.17,"tv":14623.09,"id":9629022}]}]}
{"op":"mcm","clk":"4228187602","pt":1631460075405,"mc":[{"id":"1.187551081","rc":[{"batl":[[0,1.23,109.5],[1,1.24,110.23],[2,1.25,104.18]],"ltp":1.17,"tv":14623.09,"id":9629022}]}]}
{"op":"mcm","clk":"4228187663","pt":1631460075782,"mc":[{"id":"1.187551081","rc":[{"batb":[[0,5.2,52.42],[1,5.1,3.04],[2,4.8,2.93]],"ltp":7.0,"tv":1330.0,"id":7445998},{"batb":[[1,1.1,877.17],[2,1.09,379.01]],"batl":[[0,1.24,110.23],[1,1.25,597.17],[2,1.26,548.99]],"ltp":1.17,"tv":14623.09,"id":9629022}]}]}
{"op":"mcm","clk":"4228187926","pt":1631460077629,"mc":[{"id":"1.187551081","rc":[{"batl":[[1,1.25,104.18],[2,1.26,116.75]],"ltp":1.17,"tv":14623.09,"id":9629022}]}]}
{"op":"mcm","clk":"4228188102","pt":1631460078609,"mc":[{"id":"1.187551081","rc":[{"batb":[[1,4.8,2.93],[2,4.3,2]],"ltp":7.0,"tv":1330.0,"id":7445998},{"trd":[[1.13,190.86]],"batb":[[0,1.1,877.17],[1,1.09,379.01],[2,1.08,1341.34]],"batl":[[0,1.31,9],[1,1.39,17.79],[2,2,30]],"ltp":1.13,"tv":14625.65,"id":9629022}],"tv":15955.65}]}
{"op":"mcm","clk":"4228188406","pt":1631460080514,"mc":[{"id":"1.187551081","rc":[{"trd":[[11,9.48]],"batl":[[0,12.5,2]],"ltp":11.0,"tv":1339.48,"id":7445998},{"trd":[[1.1,648.5]],"batb":[[0,1.1,505.52]],"batl":[[0,1.12,1072.06],[1,1.31,9],[2,1.39,17.79]],"ltp":1.1,"tv":15274.15,"id":9629022}],"tv":16613.63}]}
{"op":"mcm","clk":"4228188599","pt":1631460081668,"mc":[{"id":"1.187551081","rc":[{"batb":[[0,10,58.53],[1,8,39.36],[2,4.8,2.93]],"ltp":11.0,"tv":1339.48,"id":7445998},{"batl":[[0,1.12,1036.41]],"ltp":1.1,"tv":15274.15,"id":9629022}]}]}
{"op":"mcm","clk":"4228188775","pt":1631460082622,"mc":[{"id":"1.187551081","rc":[{"batb":[[1,8,54.26],[2,5.4,3]],"batl":[[0,10.5,2],[1,12.5,2]],"ltp":11.0,"tv":1339.48,"id":7445998},{"batb":[[0,1.1,607.27]],"batl":[[1,1.22,13],[2,1.23,9]],"ltp":1.1,"tv":15274.15,"id":9629022}]}]}
{"op":"mcm","clk":"4228189103","pt":1631460084424,"mc":[{"id":"1.187551081","rc":[{"batl":[[2,21,53.46]],"ltp":11.0,"tv":1339.48,"id":7445998},{"batb":[[0,1.1,773.54],[1,1.09,586.28]],"batl":[[0,1.11,195.7],[1,1.12,1036.41],[2,1.22,13]],"ltp":1.1,"tv":15274.15,"id":9629022}]}]}
{"op":"mcm","clk":"4228189298","pt":1631460085488,"mc":[{"id":"1.187551081","rc":[{"batb":[[0,1.1,983.71]],"batl":[[1,1.12,1093.45]],"ltp":1.1,"tv":15274.15,"id":9629022}]}]}
{"op":"mcm","clk":"4228189375","pt":1631460085901,"mc":[{"id":"1.187551081","rc":[{"batl":[[1,1.12,1310.84]],"ltp":1.1,"tv":15274.15,"id":9629022}]}]}
{"op":"mcm","clk":"4228189604","pt":1631460087503,"mc":[{"id":"1.187551081","rc":[{"batb":[[2,6.6,35.37]],"batl":[[2,13,19.87]],"ltp":11.0,"tv":1339.48,"id":7445998},{"batb":[[2,1.08,1605.86]],"batl":[[2,1.18,226.29]],"ltp":1.1,"tv":15274.15,"id":9629022}]}]}
{"op":"mcm","clk":"4228189717","pt":1631460088218,"mc":[{"id":"1.187551081","rc":[{"batl":[[1,11,40.65],[2,12.5,52.04]],"ltp":11.0,"tv":1339.48,"id":7445998},{"batb":[[0,1.1,1390.23],[1,1.09,1160.2]],"ltp":1.1,"tv":15274.15,"id":9629022}]}]}
{"op":"mcm","clk":"4228189899","pt":1631460089403,"mc":[{"id":"1.187551081","rc":[{"batb":[[0,10,102.7],[1,9.2,59.99],[2,8,54.26]],"ltp":11.0,"tv":1339.48,"id":7445998},{"batl":[[0,1.11,593.68],[1,1.12,1803.62]],"ltp":1.1,"tv":15274.15,"id":9629022}]}]}
{"op":"mcm","clk":"4228190401","pt":1631460092521,"mc":[{"id":"1.187551081","rc":[{"batl":[[0,10.5,18.34]],"ltp":11.0,"tv":1339.48,"id":7445998},{"batl":[[0,1.11,703.76]],"ltp":1.1,"tv":15274.15,"id":9629022}]}]}
{"op":"mcm","clk":"4228190447","pt":1631460092842,"mc":[{"id":"1.187551081","rc":[{"trd":[[10,24]],"batb":[[0,10,90.7]],"batl":[[0,10.5,8.07]],"ltp":10.0,"tv":1363.47,"id":7445998}],"tv":16637.63}]}
{"op":"mcm","clk":"4228190609","pt":1631460093846,"mc":[{"id":"1.187551081","rc":[{"batb":[[2,1.08,1591.96]],"ltp":1.1,"tv":15274.15,"id":9629022}]}]}
{"op":"mcm","clk":"4228195100","pt":1631460124076,"mc":[{"id":"1.187551081","rc":[{"batl":[[2,12.5,50.04]],"ltp":10.0,"tv":1363.47,"id":7445998},{"trd":[[1.11,649.5]],"batb":[[1,1.09,1097.78]],"batl":[[0,1.11,508.06]],"ltp":1.11,"tv":15474.15,"id":9629022}],"tv":16837.63}]}
{"op":"mcm","clk":"4228195622","pt":1631460127079,"mc":[{"id":"1.187551081","rc":[{"batb":[[0,1.1,1452.08]],"batl":[[1,1.12,1980.4]],"ltp":1.11,"tv":15474.15,"id":9629022}]}]}
{"op":"mcm","clk":"4228196803","pt":1631460134492,"mc":[{"id":"1.187551081","rc":[{"trd":[[1.11,654.02]],"batl":[[0,1.11,505.8]],"ltp":1.11,"tv":15478.67,"id":9629022}],"tv":16842.15}]}
{"op":"mcm","clk":"4228197357","pt":1631460137786,"mc":[{"id":"1.187551081","rc":[{"batb":[[0,1.1,1300.48]],"batl":[[1,1.12,1715.19]],"ltp":1.11,"tv":15478.67,"id":9629022}]}]}
{"op":"mcm","clk":"4228197556","pt":1631460139107,"mc":[{"id":"1.187551081","rc":[{"trd":[[1.11,654.06]],"batl":[[0,1.11,505.78]],"ltp":1.11,"tv":15478.71,"id":9629022}],"tv":16842.19}]}
{"op":"mcm","clk":"4228197974","pt":1631460141590,"mc":[{"id":"1.187551081","rc":[{"trd":[[10.5,16.14]],"batb":[[0,10.5,46.53],[1,10,44.17],[2,9.2,59.99]],"batl":[[0,11,40.65],[1,12.5,50.04],[2,13,19.87]],"ltp":10.5,"tv":1379.61,"id":7445998},{"batb":[[0,1.1,1191.57],[1,1.09,1250.77]],"batl":[[0,1.11,790.72],[1,1.12,1608.15]],"ltp":1.11,"tv":15478.71,"id":9629022}],"tv":16858.33}]}
{"op":"mcm","clk":"4228198415","pt":1631460144399,"mc":[{"id":"1.187551081","rc":[{"trd":[[1.1,651.64]],"batb":[[0,1.1,1121.47],[1,1.09,1360.68]],"batl":[[0,1.11,898.72],[1,1.12,1540.82]],"ltp":1.1,"tv":15481.85,"id":9629022}],"tv":16861.47}]}
{"op":"mcm","clk":"4228198612","pt":1631460145507,"mc":[{"id":"1.187551081","rc":[{"trd":[[10.5,31]],"batb":[[0,10.5,39.1]],"ltp":10.5,"tv":1394.47,"id":7445998},{"trd":[[1.1,652.1]],"batb":[[0,1.1,1121.24]],"ltp":1.1,"tv":15482.31,"id":9629022}],"tv":16876.79}]}
{"op":"mcm","clk":"4228199030","pt":1631460148107,"mc":[{"id":"1.187551081","rc":[{"batb":[[0,1.1,1078.89],[1,1.09,1430.72]],"batl":[[0,1.11,967.51],[1,1.12,1497.45]],"ltp":1.1,"tv":15482.31,"id":9629022}]}]}
{"op":"mcm","clk":"4228199460","pt":1631460151072,"mc":[{"id":"1.187551081","rc":[{"batb":[[1,1.09,1474.39]],"batl":[[0,1.11,1010.42]],"ltp":1.1,"tv":15482.31,"id":9629022}]}]}
{"op":"mcm","clk":"4228199796","pt":1631460153211,"mc":[{"id":"1.187551081","rc":[{"trd":[[1.1,836.9]],"batb":[[0,1.1,986.49]],"batl":[[1,1.12,1447.3]],"ltp":1.1,"tv":15667.11,"id":9629022}],"tv":17061.59}]}
{"op":"mcm","clk":"4228200273","pt":1631460156138,"mc":[{"id":"1.187551081","rc":[{"batb":[[0,1.1,1027.81],[1,1.09,1525.95]],"batl":[[0,1.11,1061.01]],"ltp":1.1,"tv":15667.11,"id":9629022}]}]}
{"op":"mcm","clk":"4228200544","pt":1631460157821,"mc":[{"id":"1.187551081","rc":[{"trd":[[10.5,56.6]],"batb":[[0,10.5,26.3]],"ltp":10.5,"tv":1420.07,"id":7445998}],"tv":17087.19}]}
{"op":"mcm","clk":"4228200866","pt":1631460159961,"mc":[{"id":"1.187551081","rc":[{"trd":[[10.5,56.79]],"batb":[[0,10.5,26.2]],"ltp":10.5,"tv":1420.26,"id":7445998},{"batb":[[0,1.1,718.44]],"batl":[[1,1.12,1319.61]],"ltp":1.1,"tv":15667.11,"id":9629022}],"tv":17087.38}]}
{"op":"mcm","clk":"4228201352","pt":1631460162828,"mc":[{"id":"1.187551081","rc":[{"batb":[[1,1.09,1838.15]],"batl":[[0,1.11,1189.85]],"ltp":1.1,"tv":15667.11,"id":9629022}]}]}
{"op":"mcm","clk":"4228201756","pt":1631460165438,"mc":[{"id":"1.187551081","rc":[{"batl":[[0,11,48.94]],"ltp":10.5,"tv":1420.26,"id":7445998}]}]}
{"op":"mcm","clk":"4228202890","pt":1631460172958,"mc":[{"id":"1.187551081","rc":[{"batl":[[2,1.14,181.75]],"ltp":1.1,"tv":15667.11,"id":9629022}]}]}
{"op":"mcm","clk":"4228203139","pt":1631460174623,"mc":[{"id":"1.187551081","rc":[{"trd":[[10.5,71.25]],"batb":[[0,10.5,18.97]],"ltp":10.5,"tv":1434.72,"id":7445998}],"tv":17101.84}]}
{"op":"mcm","clk":"4228203566","pt":1631460177580,"mc":[{"id":"1.187551081","rc":[{"batl":[[0,11,40.65]],"ltp":10.5,"tv":1434.72,"id":7445998},{"batb":[[0,1.1,616.69]],"batl":[[1,1.12,1102.22]],"ltp":1.1,"tv":15667.11,"id":9629022}]}]}
{"op":"mcm","clk":"4228206848","pt":1631460199022,"mc":[{"id":"1.187551081","rc":[{"batl":[[0,11,48.85]],"ltp":10.5,"tv":1434.72,"id":7445998},{"batb":[[0,1.1,698.66]],"ltp":1.1,"tv":15667.11,"id":9629022}]}]}
{"op":"mcm","clk":"4228208108","pt":1631460206830,"mc":[{"id":"1.187551081","rc":[{"trd":[[1.1,846.9]],"batb":[[0,1.1,693.66]],"ltp":1.1,"tv":15677.11,"id":9629022}],"tv":17111.84}]}
{"op":"mcm","clk":"4228209253","pt":1631460214059,"mc":[{"id":"1.187551081","rc":[{"batb":[[0,8.4,36.09],[1,8,2],[2,7.2,2]],"batl":[[0,13,19.87],[1,13.5,30.21],[2,14,37.14]],"ltp":10.5,"tv":1434.72,"id":7445998},{"batb":[[0,1.08,264.52],[1,1.07,353.49],[2,1.06,2536.54]],"batl":[[0,1.14,181.75],[1,1.16,179.97],[2,1.18,226.29]],"ltp":1.1,"tv":15677.11,"id":9629022}]}]}
{"op":"mcm","clk":"4228209815","pt":1631460217441,"mc":[{"id":"1.187551081","rc":[{"batb":[[0,8.6,34.08]],"ltp":10.5,"tv":1434.72,"id":7445998}]}]}
{"op":"mcm","clk":"4228210212","pt":1631460219633,"mc":[{"id":"1.187551081","rc":[{"batb":[[0,1.1,959.33],[1,1.09,296.1],[2,1.08,264.52]],"batl":[[0,1.12,1103.76],[1,1.13,10],[2,1.14,181.75]],"ltp":1.1,"tv":15677.11,"id":9629022}]}]}
{"op":"mcm","clk":"4228210356","pt":1631460220448,"mc":[{"id":"1.187551081","rc":[{"batb":[[0,8.8,11.4],[1,8.6,34.08],[2,8,2]],"batl":[[0,12,18.66],[1,13,19.87],[2,13.5,30.21]],"ltp":10.5,"tv":1434.72,"id":7445998},{"batb":[[1,1.09,509.04]],"batl":[[1,1.13,122.12]],"ltp":1.1,"tv":15677.11,"id":9629022}]}]}
{"op":"mcm","clk":"4228210538","pt":1631460221544,"mc":[{"id":"1.187551081","rc":[{"batb":[[1,1.09,296.1]],"ltp":1.1,"tv":15677.11,"id":9629022}]}]}
{"op":"mcm","clk":"4228210754","pt":1631460222837,"mc":[{"id":"1.187551081","rc":[{"batl":[[1,1.13,112.12]],"ltp":1.1,"tv":15677.11,"id":9629022}]}]}
{"op":"mcm","clk":"4228210960","pt":1631460224134,"mc":[{"id":"1.187551081","rc":[{"batb":[[0,1.11,49.75],[1,1.1,1393],[2,1.09,296.1]],"batl":[[0,1.12,1470.59]],"ltp":1.1,"tv":15677.11,"id":9629022}]}]}
{"op":"mcm","clk":"4228211072","pt":1631460224922,"mc":[{"id":"1.187551081","rc":[{"batb":[[0,8.6,34.08],[1,8,2],[2,7.2,2]],"batl":[[0,13,19.87],[1,13.5,30.21],[2,14,37.14]],"ltp":10.5,"tv":1434.72,"id":7445998},{"batb":[[0,1.08,264.52],[1,1.07,353.49],[2,1.06,2536.54]],"batl":[[0,1.13,10],[1,1.14,181.75],[2,1.16,179.97]],"ltp":1.1,"tv":15677.11,"id":9629022}]}]}
{"op":"mcm","clk":"4228211482","pt":1631460227714,"mc":[{"id":"1.187551081","rc":[{"batb":[[0,1.08,1024.28],[1,1.07,874.49]],"batl":[[1,1.14,735.94],[2,1.15,648.89]],"ltp":1.1,"tv":15677.11,"id":9629022}]}]}
{"op":"mcm","clk":"4228212661","pt":1631460235624,"mc":[{"id":"1.187551081","rc":[{"batl":[[0,8.8,1060.26],[1,13,19.87],[2,13.5,30.21]],"ltp":10.5,"tv":1434.72,"id":7445998},{"batb":[[0,1.12,10.14],[1,1.08,1024.28],[2,1.07,874.49]],"ltp":1.1,"tv":15677.11,"id":9629022}]}]}
{"op":"mcm","clk":"4228212696","pt":1631460235821,"mc":[{"id":"1.187551081","rc":[{"batl":[[0,13,19.87],[1,13.5,30.21],[2,14,37.14]],"ltp":10.5,"tv":1434.72,"id":7445998},{"batb":[[0,1.08,1024.28],[1,1.07,874.49],[2,1.06,2536.54]],"ltp":1.1,"tv":15677.11,"id":9629022}]}]}
{"op":"mcm","clk":"4228212915","pt":1631460237219,"mc":[{"id":"1.187551081","rc":[{"batl":[[0,18,2],[1,21,53.46],[2,990,0.01]],"ltp":10.5,"tv":1434.72,"id":7445998},{"batb":[[0,1.06,2101.73],[1,1.01,30],[2,1.06,0]],"ltp":1.1,"tv":15677.11,"id":9629022}]}]}
{"op":"mcm","clk":"4228213112","pt":1631460238401,"mc":[{"id":"1.187551081","rc":[{"batl":[[1,990,0.01],[2,990,0]],"ltp":10.5,"tv":1434.72,"id":7445998}]}]}
{"op":"mcm","clk":"4228213208","pt":1631460238926,"mc":[{"id":"1.187551081","rc":[{"batl":[[0,1.14,735.94],[1,1.15,648.89],[2,1.16,179.97]],"ltp":1.1,"tv":15677.11,"id":9629022}]}]}
{"op":"mcm","clk":"4228213408","pt":1631460240325,"mc":[{"id":"1.187551081","rc":[{"batl":[[0,9.4,2],[1,15.5,2],[2,18,2]],"ltp":10.5,"tv":1434.72,"id":7445998},{"batb":[[0,1.12,1174.11],[1,1.06,2110.73],[2,1.05,10]],"ltp":1.1,"tv":15677.11,"id":9629022}]}]}
{"op":"mcm","clk":"4228213590","pt":1631460241619,"mc":[{"id":"1.187551081","rc":[{"trd":[[8.6,8.85]],"batb":[[0,8.6,29.66]],"ltp":8.6,"tv":1443.57,"id":7445998},{"batb":[[1,1.1,1031.15],[2,1.08,1311]],"ltp":1.1,"tv":15677.11,"id":9629022}],"tv":17120.68}]}
{"op":"mcm","clk":"4228213741","pt":1631460242633,"mc":[{"id":"1.187551081","rc":[{"batl":[[1,14,62.31],[2,15.5,2]],"ltp":8.6,"tv":1443.57,"id":7445998}]}]}
{"op":"mcm","clk":"4228213859","pt":1631460243439,"mc":[{"id":"1.187551081","rc":[{"trd":[[8.6,12.85]],"batb":[[0,8.6,27.66]],"ltp":8.6,"tv":1447.57,"id":7445998}],"tv":17124.68}]}
{"op":"mcm","clk":"4228213965","pt":1631460244232,"mc":[{"id":"1.187551081","rc":[{"batb":[[1,7.2,2],[2,6.6,96.59]],"ltp":8.6,"tv":1447.57,"id":7445998},{"batb":[[2,1.09,24]],"batl":[[0,1.14,554.19]],"ltp":1.1,"tv":15677.11,"id":9629022}]}]}
{"op":"mcm","clk":"4228214113","pt":1631460245248,"mc":[{"id":"1.187551081","rc":[{"batl":[[0,9.2,10],[1,9.4,2],[2,14,62.31]],"ltp":8.6,"tv":1447.57,"id":7445998},{"trd":[[1.13,200.86]],"batb":[[0,1.13,96.26],[1,1.12,1608],[2,1.1,1031.15]],"batl":[[0,1.14,895.44]],"ltp":1.13,"tv":15687.11,"id":9629022}],"tv":17134.68}]}
{"op":"mcm","clk":"4228214431","pt":1631460247345,"mc":[{"id":"1.187551081","rc":[{"batl":[[2,11,2]],"ltp":8.6,"tv":1447.57,"id":7445998},{"batb":[[2,1.1,1270.29]],"ltp":1.13,"tv":15687.11,"id":9629022}]}]}
{"op":"mcm","clk":"4228214614","pt":1631460248528,"mc":[{"id":"1.187551081","rc":[{"batb":[[0,1.13,496.04]],"ltp":1.13,"tv":15687.11,"id":9629022}]}]}
{"op":"mcm","clk":"4228215146","pt":1631460252447,"mc":[{"id":"1.187551081","rc":[{"batb":[[0,6.6,61.21],[1,6.2,2.01],[2,5.7,31.65]],"batl":[[0,11.5,27.69],[1,12,33.76],[2,12.5,33.07]],"ltp":8.6,"tv":1447.57,"id":7445998},{"batb":[[0,1.09,656.94],[1,1.08,2005.8],[2,1.07,389.02]],"batl":[[0,1.17,10],[1,1.19,134.5],[2,1.2,143.38]],"ltp":1.13,"tv":15687.11,"id":9629022}]}]}
{"op":"mcm","clk":"4228215701","pt":1631460255667,"mc":[{"id":"1.187551081","rc":[{"batb":[[0,6.6,63.21],[1,6.4,2]],"batl":[[0,11,2],[1,11.5,29.69],[2,12,33.76]],"ltp":8.6,"tv":1447.57,"id":7445998},{"batb":[[0,1.1,273.64],[1,1.09,328.33],[2,1.08,2005.8]],"batl":[[1,1.22,361.08],[2,1.23,226.31]],"ltp":1.13,"tv":15687.11,"id":9629022}]}]}
{"op":"mcm","clk":"4228215809","pt":1631460256268,"mc":[{"id":"1.187551081","rc":[{"batl":[[0,11.5,29.69],[1,12,33.76],[2,12.5,33.07]],"ltp":8.6,"tv":1447.57,"id":7445998},{"batb":[[0,1.09,328.33],[1,1.08,1975.8],[2,1.07,354.02]],"ltp":1.13,"tv":15687.11,"id":9629022}]}]}
{"op":"mcm","clk":"4228216088","pt":1631460257970,"mc":[{"id":"1.187551081","rc":[{"batb":[[0,1.12,1163.57],[1,1.09,328.33],[2,1.08,1975.8]],"batl":[[0,1.14,554.19],[1,1.15,648.89],[2,1.17,10]],"ltp":1.13,"tv":15687.11,"id":9629022}]}]}
{"op":"mcm","clk":"4228216304","pt":1631460259443,"mc":[{"id":"1.187551081","rc":[{"batb":[[2,1.08,1983.8]],"ltp":1.13,"tv":15687.11,"id":9629022}]}]}
{"op":"mcm","clk":"4228216547","pt":1631460261145,"mc":[{"id":"1.187551081","rc":[{"batb":[[0,1.12,1507.84]],"batl":[[0,1.14,803.16]],"ltp":1.13,"tv":15687.11,"id":9629022}]}]}
{"op":"mcm","clk":"4228216725","pt":1631460262371,"mc":[{"id":"1.187551081","rc":[{"trd":[[8,24.84]],"ltp":8.0,"tv":1455.57,"id":7445998},{"trd":[[1.14,190.56]],"batl":[[0,1.14,747.02]],"ltp":1.14,"tv":15743.25,"id":9629022}],"tv":17198.82}]}
{"op":"mcm","clk":"4228216983","pt":1631460264040,"mc":[{"id":"1.187551081","rc":[{"batb":[[0,1.09,328.33],[1,1.08,1983.8],[2,1.07,354.02]],"batl":[[0,1.17,10],[1,1.22,361.08],[2,1.23,226.31]],"ltp":1.14,"tv":15743.25,"id":9629022}]}]}
{"op":"mcm","clk":"4228217383","pt":1631460267272,"mc":[{"id":"1.187551081","rc":[{"batb":[[1,5.7,31.65],[2,5.6,39.71]],"ltp":8.0,"tv":1455.57,"id":7445998},{"batb":[[0,1.1,901.75],[1,1.09,682.53],[2,1.08,1983.8]],"batl":[[1,1.18,281.08],[2,1.19,670.42]],"ltp":1.14,"tv":15743.25,"id":9629022}]}]}
{"op":"mcm","clk":"4228217831","pt":1631460270456,"mc":[{"id":"1.187551081","rc":[{"batb":[[1,6.4,2],[2,5.7,31.65]],"ltp":8.0,"tv":1455.57,"id":7445998}]}]}
{"op":"mcm","clk":"4228218611","pt":1631460275884,"mc":[{"id":"1.187551081","rc":[{"batb":[[2,5.5,2.12]],"ltp":8.0,"tv":1455.57,"id":7445998},{"batb":[[2,1.08,1975.8]],"batl":[[1,1.21,20],[2,1.22,147.25]],"ltp":1.14,"tv":15743.25,"id":9629022}]}]}
{"op":"mcm","clk":"4228219027","pt":1631460278667,"mc":[{"id":"1.187551081","rc":[{"batl":[[0,1.12,1146.06],[1,1.17,10],[2,1.21,20]],"ltp":1.14,"tv":15743.25,"id":9629022}]}]}
{"op":"mcm","clk":"4228219135","pt":1631460279588,"mc":[{"id":"1.187551081","rc":[{"batb":[[0,10,59.04],[1,7.8,74.17],[2,6.6,63.21]],"batl":[[0,11,14.78],[1,11.5,29.69],[2,12,33.76]],"ltp":8.0,"tv":1455.57,"id":7445998},{"batb":[[0,1.11,47.54],[1,1.1,909.75],[2,1.09,682.53]],"batl":[[1,1.15,50],[2,1.17,10]],"ltp":1.14,"tv":15743.25,"id":9629022}]}]}
{"op":"mcm","clk":"4228219258","pt":1631460280580,"mc":[{"id":"1.187551081","rc":[{"batb":[[2,6.8,2]],"batl":[[0,10.5,2],[1,11,14.78],[2,11.5,29.69]],"ltp":8.0,"tv":1455.57,"id":7445998},{"batb":[[0,1.11,64.54]],"ltp":1.14,"tv":15743.25,"id":9629022}]}]}
{"op":"mcm","clk":"4228219316","pt":1631460280995,"mc":[{"id":"1.187551081","rc":[{"batl":[[1,11,2]],"ltp":8.0,"tv":1455.57,"id":7445998},{"batl":[[2,1.16,14]],"ltp":1.14,"tv":15743.25,"id":9629022}]}]}
{"op":"mcm","clk":"4228219665","pt":1631460283601,"mc":[{"id":"1.187551081","rc":[{"batb":[[1,1.1,1260.25]],"batl":[[0,1.12,1399.44]],"ltp":1.14,"tv":15743.25,"id":9629022}]}]}
{"op":"mcm","clk":"4228219792","pt":1631460284532,"mc":[{"id":"1.187551081","rc":[{"batl":[[0,10.5,63.46],[1,11,65.2]],"ltp":8.0,"tv":1455.57,"id":7445998},{"batb":[[1,1.1,2356.92]],"ltp":1.14,"tv":15743.25,"id":9629022}]}]}
{"op":"mcm","clk":"4228219937","pt":1631460285599,"mc":[{"id":"1.187551081","rc":[{"batb":[[1,9.2,45.26],[2,9,51.24]],"ltp":8.0,"tv":1455.57,"id":7445998},{"batl":[[1,1.13,776.64],[2,1.15,50]],"ltp":1.14,"tv":15743.25,"id":9629022}]}]}
{"op":"mcm","clk":"4228220600","pt":1631460289640,"mc":[{"id":"1.187551081","rc":[{"trd":[[1.11,654.36]],"batb":[[0,1.11,64.39]],"ltp":1.11,"tv":15743.56,"id":9629022}],"tv":17199.13}]}
{"op":"mcm","clk":"4228220866","pt":1631460291416,"mc":[{"id":"1.187551081","rc":[{"batl":[[1,11,63.2],[2,11.5,27.69]],"ltp":8.0,"tv":1455.57,"id":7445998},{"trd":[[1.12,5.13]],"batb":[[1,1.1,2348.92],[2,1.09,658.53]],"batl":[[0,1.12,1397.73]],"ltp":1.12,"tv":15746.97,"id":9629022}],"tv":17202.55}]}
{"op":"mcm","clk":"4228220926","pt":1631460291836,"mc":[{"id":"1.187551081","rc":[{"batb":[[1,1.1,2210.59]],"ltp":1.12,"tv":15746.97,"id":9629022}]}]}
{"op":"mcm","clk":"4228221426","pt":1631460294898,"mc":[{"id":"1.187551081","rc":[{"batb":[[2,1.09,798.14]],"batl":[[0,1.12,1483.75]],"ltp":1.12,"tv":15746.97,"id":9629022}]}]}
{"op":"mcm","clk":"4228221892","pt":1631460298053,"mc":[{"id":"1.187551081","rc":[{"batb":[[0,7.8,42.12],[1,6.8,2],[2,6.2,35.83]],"batl":[[0,13.5,21.52],[1,14,30.6],[2,14.5,27.95]],"ltp":8.0,"tv":1455.57,"id":7445998},{"batb":[[0,1.08,571.35],[1,1.07,405.52],[2,1.06,2222.49]],"batl":[[0,1.17,10],[1,1.19,217.07],[2,1.2,234.32]],"ltp":1.12,"tv":15746.97,"id":9629022}]}]}
{"op":"mcm","clk":"4228222261","pt":1631460300527,"mc":[{"id":"1.187551081","rc":[{"batb":[[0,1.08,1468.6],[1,1.07,787.75]],"batl":[[0,1.15,484.41],[1,1.16,707.7],[2,1.17,10]],"ltp":1.12,"tv":15746.97,"id":9629022}]}]}
{"op":"mcm","clk":"4228222415","pt":1631460301328,"mc":[{"id":"1.187551081","rc":[{"batl":[[0,13.5,23.52]],"ltp":8.0,"tv":1455.57,"id":7445998},{"batb":[[0,1.08,1493.6],[1,1.07,815.75]],"batl":[[2,1.19,217.07]],"ltp":1.12,"tv":15746.97,"id":9629022}]}]}
{"op":"mcm","clk":"4228222680","pt":1631460302922,"mc":[{"id":"1.187551081","rc":[{"batl":[[0,1.13,20],[1,1.14,10],[2,1.15,484.41]],"ltp":1.12,"tv":15746.97,"id":9629022}]}]}
{"op":"mcm","clk":"4228223660","pt":1631460309708,"mc":[{"id":"1.187551081","rc":[{"batl":[[0,1.13,10]],"ltp":1.12,"tv":15746.97,"id":9629022}]}]}
{"op":"mcm","clk":"4228223886","pt":1631460311244,"mc":[{"id":"1.187551081","rc":[{"batl":[[0,13.5,4],[1,21,53.46],[2,990,0.01]],"ltp":8.0,"tv":1455.57,"id":7445998},{"batb":[[0,1.08,333.31],[1,1.07,28],[2,1.06,1751.05]],"ltp":1.12,"tv":15746.97,"id":9629022}]}]}
{"op":"mcm","clk":"4228224246","pt":1631460313628,"mc":[{"id":"1.187551081","rc":[{"batl":[[1,990,0.01],[2,990,0]],"ltp":8.0,"tv":1455.57,"id":7445998},{"batb":[[0,1.13,8070.84],[1,1.08,333.31]],"batl":[[0,1.15,484.41],[1,1.16,707.7],[2,1.19,217.07]],"ltp":1.12,"tv":15746.97,"id":9629022}]}]}
{"op":"mcm","clk":"4228224335","pt":1631460314127,"mc":[{"id":"1.187551081","rc":[{"batb":[[1,6.2,35.83],[2,6,36.78]],"ltp":8.0,"tv":1455.57,"id":7445998},{"batb":[[0,1.13,1089.86]],"ltp":1.12,"tv":15746.97,"id":9629022}]}]}
{"op":"mcm","clk":"4228224534","pt":1631460315472,"mc":[{"id":"1.187551081","rc":[{"batb":[[1,1.12,907.22],[2,1.09,1238.99]],"ltp":1.12,"tv":15746.97,"id":9629022}]}]}
{"op":"mcm","clk":"4228224710","pt":1631460316661,"mc":[{"id":"1.187551081","rc":[{"trd":[[7.8,4]],"batb":[[0,7.8,40.12]],"ltp":7.8,"tv":1459.57,"id":7445998},{"batb":[[2,1.09,1266.99]],"ltp":1.12,"tv":15746.97,"id":9629022}],"tv":17206.55}]}
{"op":"mcm","clk":"4228224758","pt":1631460317052,"mc":[{"id":"1.187551081","rc":[{"batl":[[0,12.5,65.62],[1,13.5,4],[2,990,0.01]],"ltp":7.8,"tv":1459.57,"id":7445998},{"batb":[[0,1.14,16],[1,1.13,1106.86],[2,1.12,907.22]],"ltp":1.12,"tv":15746.97,"id":9629022}]}]}
{"op":"mcm","clk":"4228224999","pt":1631460318545,"mc":[{"id":"1.187551081","rc":[{"batl":[[0,8,20],[1,12.5,65.62],[2,13.5,4]],"ltp":7.8,"tv":1459.57,"id":7445998},{"batb":[[0,1.14,226.16],[1,1.13,1447.75]],"batl":[[0,1.15,730.78]],"ltp":1.12,"tv":15746.97,"id":9629022}]}]}
{"op":"mcm","clk":"4228225068","pt":1631460319037,"mc":[{"id":"1.187551081","rc":[{"batl":[[0,12.5,65.62],[1,13.5,4],[2,990,0.01]],"ltp":7.8,"tv":1459.57,"id":7445998},{"batb":[[0,1.14,96]],"ltp":1.12,"tv":15746.97,"id":9629022}]}]}
{"op":"mcm","clk":"4228225287","pt":1631460320478,"mc":[{"id":"1.187551081","rc":[{"batb":[[1,7.6,52.59],[2,7.2,73.47]],"ltp":7.8,"tv":1459.57,"id":7445998},{"batl":[[0,1.15,1078.38],[1,1.16,1163.76]],"ltp":1.12,"tv":15746.97,"id":9629022}]}]}
{"op":"mcm","clk":"4228225436","pt":1631460321659,"mc":[{"id":"1.187551081","rc":[{"batl":[[0,11,2],[1,12.5,65.62],[2,13.5,4]],"ltp":7.8,"tv":1459.57,"id":7445998}]}]}
{"op":"mcm","clk":"4228225491","pt":1631460322085,"mc":[{"id":"1.187551081","rc":[{"trd":[[7.8,18.04]],"batb":[[0,7.8,33.1]],"batl":[[0,8.2,52.24],[1,8.8,64.26],[2,11,2]],"ltp":7.8,"tv":1473.61,"id":7445998},{"batb":[[0,1.14,471.78],[1,1.13,1948.22]],"ltp":1.12,"tv":15746.97,"id":9629022}],"tv":17220.59}]}
{"op":"mcm","clk":"4228225962","pt":1631460325057,"mc":[{"id":"1.187551081","rc":[{"batb":[[0,1.14,790.91]],"ltp":1.12,"tv":15746.97,"id":9629022}]}]}
{"op":"mcm","clk":"4228227929","pt":1631460338510,"mc":[{"id":"1.187551081","rc":[{"batb":[[0,5.9,78.96],[1,5.5,2.12],[2,4.8,2.58]],"batl":[[0,11,2],[1,12.5,65.62],[2,13.5,4]],"ltp":7.8,"tv":1473.61,"id":7445998},{"batb":[[0,1.1,286.44],[1,1.09,1538.89],[2,1.08,308.31]],"batl":[[0,1.22,134.25],[1,1.24,102.98],[2,1.26,98.25]],"ltp":1.12,"tv":15746.97,"id":9629022}]}]}
{"op":"mcm","clk":"4228228016","pt":1631460338994,"mc":[{"id":"1.187551081","rc":[{"batl":[[0,12.5,65.62],[1,13.5,4],[2,15.5,2]],"ltp":7.8,"tv":1473.61,"id":7445998},{"batb":[[0,1.09,1538.89],[1,1.08,308.31],[2,1.07,350.07]],"ltp":1.12,"tv":15746.97,"id":9629022}]}]}
{"op":"mcm","clk":"4228228382","pt":1631460341662,"mc":[{"id":"1.187551081","rc":[{"batb":[[1,4.8,2.58],[2,3.6,376.71]],"ltp":7.8,"tv":1473.61,"id":7445998},{"batb":[[0,1.1,19],[1,1.09,1538.89],[2,1.08,308.31]],"ltp":1.12,"tv":15746.97,"id":9629022}]}]}
{"op":"mcm","clk":"4228228477","pt":1631460342362,"mc":[{"id":"1.187551081","rc":[{"batb":[[0,5.9,81.96],[1,5.8,2],[2,4.8,2.58]],"batl":[[0,11,2],[1,12.5,67.62],[2,13.5,4]],"ltp":7.8,"tv":1473.61,"id":7445998},{"batb":[[2,1.08,340.31]],"batl":[[0,1.21,10],[1,1.22,134.25],[2,1.24,102.98]],"ltp":1.12,"tv":15746.97,"id":9629022}]}]}
{"op":"mcm","clk":"4228228810","pt":1631460344576,"mc":[{"id":"1.187551081","rc":[{"batb":[[0,1.14,743.41],[1,1.13,240.24],[2,1.1,19]],"batl":[[0,1.16,457.44],[1,1.17,501.63],[2,1.21,10]],"ltp":1.12,"tv":15746.97,"id":9629022}]}]}
{"op":"mcm","clk":"4228228971","pt":1631460345598,"mc":[{"id":"1.187551081","rc":[{"batb":[[0,6,32.97],[1,5.9,81.96],[2,5.8,2]],"batl":[[0,8.6,10],[1,11,4],[2,12.5,67.62]],"ltp":7.8,"tv":1473.61,"id":7445998},{"batb":[[2,1.1,261.04]],"batl":[[2,1.2,50]],"ltp":1.12,"tv":15746.97,"id":9629022}]}]}
{"op":"mcm","clk":"4228229326","pt":1631460347600,"mc":[{"id":"1.187551081","rc":[{"batb":[[0,5.9,81.96],[1,5.8,2],[2,5.5,2.12]],"batl":[[0,11,4],[1,12.5,67.62],[2,13.5,4]],"ltp":7.8,"tv":1473.61,"id":7445998},{"batb":[[0,1.1,261.04],[1,1.09,1538.89],[2,1.08,340.31]],"batl":[[0,1.21,10],[1,1.22,144.25],[2,1.24,102.98]],"ltp":1.12,"tv":15746.97,"id":9629022}]}]}
{"op":"mcm","clk":"4228229467","pt":1631460348581,"mc":[{"id":"1.187551081","rc":[{"batl":[[0,11,2]],"ltp":7.8,"tv":1473.61,"id":7445998},{"batb":[[0,1.15,95],[1,1.1,19],[2,1.09,1538.89]],"ltp":1.12,"tv":15746.97,"id":9629022}]}]}
{"op":"mcm","clk":"4228229575","pt":1631460349290,"mc":[{"id":"1.187551081","rc":[{"batb":[[0,1.1,19],[1,1.09,1538.89],[2,1.08,340.31]],"ltp":1.12,"tv":15746.97,"id":9629022}]}]}
{"op":"mcm","clk":"4228229990","pt":1631460352295,"mc":[{"id":"1.187551081","rc":[{"batb":[[0,1.1,1271.74]],"batl":[[0,1.2,434.59],[1,1.21,620.76],[2,1.22,144.25]],"ltp":1.12,"tv":15746.97,"id":9629022}]}]}
{"op":"mcm","clk":"4228230321","pt":1631460354317,"mc":[{"id":"1.187551081","rc":[{"batb":[[1,5.5,2.12],[2,4.8,2.58]],"batl":[[1,12.5,65.62],[2,13.5,2]],"ltp":7.8,"tv":1473.61,"id":7445998},{"batb":[[0,1.1,1281.74],[1,1.09,1510.89],[2,1.08,308.31]],"ltp":1.12,"tv":15746.97,"id":9629022}]}]}
{"op":"mcm","clk":"4228230374","pt":1631460354710,"mc":[{"id":"1.187551081","rc":[{"batl":[[0,11,4]],"ltp":7.8,"tv":1473.61,"id":7445998},{"batb":[[0,1.1,1545.48]],"ltp":1.12,"tv":15746.97,"id":9629022}]}]}
{"op":"mcm","clk":"4228230770","pt":1631460357525,"mc":[{"id":"1.187551081","rc":[{"batb":[[0,1.1,1535.48],[1,1.09,1539.89]],"ltp":1.12,"tv":15746.97,"id":9629022}]}]}
{"op":"mcm","clk":"4228230822","pt":1631460357701,"mc":[{"id":"1.187551081","rc":[{"batl":[[2,1.22,134.25]],"ltp":1.12,"tv":15746.97,"id":9629022}]}]}
{"op":"mcm","clk":"4228231158","pt":1631460360015,"mc":[{"id":"1.187551081","rc":[{"batb":[[0,1.11,10],[1,1.1,1535.48],[2,1.09,1539.89]],"ltp":1.12,"tv":15746.97,"id":9629022}]}]}
{"op":"mcm","clk":"4228233221","pt":1631460373634,"mc":[{"id":"1.187551081","rc":[{"batb":[[2,1.09,1510.89]],"batl":[[0,1.21,10],[1,1.22,134.25],[2,1.24,102.98]],"ltp":1.12,"tv":15746.97,"id":9629022}]}]}
{"op":"mcm","clk":"4228233488","pt":1631460375526,"mc":[{"id":"1.187551081","rc":[{"batl":[[1,13.5,2],[2,15.5,2]],"ltp":7.8,"tv":1473.61,"id":7445998},{"batb":[[0,1.1,1535.48],[1,1.09,1510.89],[2,1.08,308.31]],"ltp":1.12,"tv":15746.97,"id":9629022}]}]}
{"op":"mcm","clk":"4228233621","pt":1631460376523,"mc":[{"id":"1.187551081","rc":[{"batb":[[0,1.11,9],[1,1.1,1535.48],[2,1.09,1510.89]],"batl":[[0,1.12,873.74],[1,1.13,353.47],[2,1.21,10]],"ltp":1.12,"tv":15746.97,"id":9629022}]}]}
{"op":"mcm","clk":"4228233723","pt":1631460377328,"mc":[{"id":"1.187551081","rc":[{"batb":[[0,9.6,65.15],[1,7,53.59],[2,5.9,3]],"ltp":7.8,"tv":1473.61,"id":7445998}]}]}
{"op":"mcm","clk":"4228233811","pt":1631460377934,"mc":[{"id":"1.187551081","rc":[{"batb":[[1,7.6,32.89],[2,7,53.59]],"batl":[[0,10.5,11.7],[1,11,4],[2,13.5,2]],"ltp":7.8,"tv":1473.61,"id":7445998},{"batb":[[0,1.11,59],[2,1.09,1532.89]],"batl":[[2,1.15,50]],"ltp":1.12,"tv":15746.97,"id":9629022}]}]}
{"op":"mcm","clk":"4228234032","pt":1631460379443,"mc":[{"id":"1.187551081","rc":[{"batb":[[1,8.4,3],[2,8.2,3]],"batl":[[0,10.5,14.7]],"ltp":7.8,"tv":1473.61,"id":7445998}]}]}
{"op":"mcm","clk":"4228234192","pt":1631460380456,"mc":[{"id":"1.187551081","rc":[{"trd":[[1.12,9.13]],"batb":[[0,1.11,61],[1,1.1,1793.39]],"batl":[[0,1.12,998.82]],"ltp":1.12,"tv":15750.97,"id":9629022}],"tv":17224.59}]}
{"op":"mcm","clk":"4228234337","pt":1631460381335,"mc":[{"id":"1.187551081","rc":[{"batl":[[0,10,2],[1,10.5,3],[2,11,4]],"ltp":7.8,"tv":1473.61,"id":7445998}]}]}
{"op":"mcm","clk":"4228234664","pt":1631460383663,"mc":[{"id":"1.187551081","rc":[{"batb":[[1,9.2,42.83],[2,8.6,53.98]],"ltp":7.8,"tv":1473.61,"id":7445998},{"batl":[[0,1.12,1350.69],[1,1.13,741.99]],"ltp":1.12,"tv":15750.97,"id":9629022}]}]}
{"op":"mcm","clk":"4228234778","pt":1631460384479,"mc":[{"id":"1.187551081","rc":[{"batl":[[0,9.8,14.7],[1,10,2],[2,10.5,3]],"ltp":7.8,"tv":1473.61,"id":7445998}]}]}
{"op":"mcm","clk":"4228234914","pt":1631460385340,"mc":[{"id":"1.187551081","rc":[{"batl":[[0,9.8,8.32],[2,10.5,51.68]],"ltp":7.8,"tv":1473.61,"id":7445998},{"batb":[[1,1.1,2796.11]],"ltp":1.12,"tv":15750.97,"id":9629022}]}]}
{"op":"mcm","clk":"4228235071","pt":1631460386349,"mc":[{"id":"1.187551081","rc":[{"trd":[[1.11,714.42],[1.12,9.23]],"batb":[[0,1.11,12]],"batl":[[0,1.12,1375.11]],"ltp":1.11,"tv":15811.14,"id":9629022}],"tv":17284.75}]}
{"op":"mcm","clk":"4228235237","pt":1631460387460,"mc":[{"id":"1.187551081","rc":[{"trd":[[1.12,344.19]],"batl":[[0,1.12,1207.63]],"ltp":1.12,"tv":16146.1,"id":9629022}],"tv":17619.71}]}
{"op":"mcm","clk":"4228235674","pt":1631460390464,"mc":[{"id":"1.187551081","rc":[{"batb":[[0,1.11,10]],"ltp":1.12,"tv":16146.1,"id":9629022}]}]}
{"op":"mcm","clk":"4228235729","pt":1631460390759,"mc":[{"id":"1.187551081","rc":[{"batl":[[2,10.5,48.68]],"ltp":7.8,"tv":1473.61,"id":7445998},{"trd":[[1.12,347.6]],"batb":[[2,1.09,1510.89]],"batl":[[0,1.12,1280.75],[1,1.13,833.88]],"ltp":1.12,"tv":16149.51,"id":9629022}],"tv":17623.13}]}
{"op":"mcm","clk":"4228236100","pt":1631460393352,"mc":[{"id":"1.187551081","rc":[{"trd":[[1.12,353.39]],"batl":[[0,1.12,1277.86]],"ltp":1.12,"tv":16155.3,"id":9629022}],"tv":17628.91}]}
{"op":"mcm","clk":"4228236287","pt":1631460394672,"mc":[{"id":"1.187551081","rc":[{"trd":[[9.6,55.11]],"batb":[[0,9.6,37.59]],"ltp":9.6,"tv":1528.72,"id":7445998}],"tv":17684.02}]}
{"op":"mcm","clk":"4228236689","pt":1631460397463,"mc":[{"id":"1.187551081","rc":[{"batl":[[1,10.5,48.68],[2,11,55.8]],"ltp":9.6,"tv":1528.72,"id":7445998},{"batb":[[2,1.09,1515.89]],"ltp":1.12,"tv":16155.3,"id":9629022}]}]}
{"op":"mcm","clk":"4228237217","pt":1631460401359,"mc":[{"id":"1.187551081","rc":[{"batb":[[1,8.4,3],[2,8.2,2]],"batl":[[0,9.8,3],[1,11,2],[2,13.5,2]],"ltp":9.6,"tv":1528.72,"id":7445998},{"batb":[[0,1.1,282.74],[1,1.09,1515.89],[2,1.08,313.31]],"batl":[[0,1.19,135.5],[1,1.2,14],[2,1.21,106.5]],"ltp":1.12,"tv":16155.3,"id":9629022}]}]}
{"op":"mcm","clk":"4228237339","pt":1631460402161,"mc":[{"id":"1.187551081","rc":[{"batb":[[0,7,53.59],[1,6.2,2.02],[2,5.5,2.12]],"batl":[[0,17,57.21],[1,26,2],[2,990,0.01]],"ltp":9.6,"tv":1528.72,"id":7445998},{"batb":[[0,1.09,5],[1,1.08,5],[2,1.06,2191.19]],"ltp":1.12,"tv":16155.3,"id":9629022}]}]}
{"op":"mcm","clk":"4228237492","pt":1631460403383,"mc":[{"id":"1.187551081","rc":[{"batb":[[0,1.12,10]],"ltp":1.12,"tv":16155.3,"id":9629022}]}]}
{"op":"mcm","clk":"4228237625","pt":1631460404369,"mc":[{"id":"1.187551081","rc":[{"batb":[[1,1.08,565.95],[2,1.07,721.67]],"batl":[[0,1.17,738.96],[1,1.18,435.1],[2,1.19,135.5]],"ltp":1.12,"tv":16155.3,"id":9629022}]}]}
{"op":"mcm","clk":"4228237763","pt":1631460405382,"mc":[{"id":"1.187551081","rc":[{"batb":[[0,6.8,55.77]],"batl":[[0,15.5,4],[1,17,59.21],[2,26,2]],"ltp":9.6,"tv":1528.72,"id":7445998},{"batb":[[2,1.07,1060.74]],"ltp":1.12,"tv":16155.3,"id":9629022}]}]}
{"op":"mcm","clk":"4228238016","pt":1631460407062,"mc":[{"id":"1.187551081","rc":[{"batb":[[2,1.07,1070.74]],"ltp":1.12,"tv":16155.3,"id":9629022}]}]}
{"op":"mcm","clk":"4228238180","pt":1631460408301,"mc":[{"id":"1.187551081","rc":[{"batb":[[1,6.2,2],[2,6,3]],"ltp":9.6,"tv":1528.72,"id":7445998},{"batl":[[0,1.2,14],[1,1.23,105.5],[2,1.39,17.79]],"ltp":1.12,"tv":16155.3,"id":9629022}]}]}
{"op":"mcm","clk":"4228238313","pt":1631460409170,"mc":[{"id":"1.187551081","rc":[{"batl":[[1,17,2]],"ltp":9.6,"tv":1528.72,"id":7445998}]}]}
{"op":"mcm","clk":"4228238528","pt":1631460410578,"mc":[{"id":"1.187551081","rc":[{"trd":[[1.12,373.39],[1.15,179.96]],"batb":[[0,1.08,565.95],[1,1.07,1070.74],[2,1.06,2149.66]],"batl":[[0,1.09,613.72],[1,1.1,634.68],[2,1.2,14]],"ltp":1.12,"tv":16198.78,"id":9629022}],"tv":17727.5}]}
{"op":"mcm","clk":"4228238688","pt":1631460411581,"mc":[{"id":"1.187551081","rc":[{"batb":[[0,12.5,35.42],[1,9.2,71.09],[2,6.2,2]],"ltp":9.6,"tv":1528.72,"id":7445998},{"batl":[[2,1.11,130.83]],"ltp":1.12,"tv":16198.78,"id":9629022}]}]}
{"op":"mcm","clk":"4228238760","pt":1631460412003,"mc":[{"id":"1.187551081","rc":[{"batb":[[1,9.8,25.51],[2,9.2,71.09]],"batl":[[0,15,13.29],[1,15.5,4],[2,17,2]],"ltp":9.6,"tv":1528.72,"id":7445998},{"batl":[[2,1.13,70]],"ltp":1.12,"tv":16198.78,"id":9629022}]}]}
{"op":"mcm","clk":"4228238978","pt":1631460413633,"mc":[{"id":"1.187551081","rc":[{"batl":[[2,1.12,10]],"ltp":1.12,"tv":16198.78,"id":9629022}]}]}
{"op":"mcm","clk":"4228239162","pt":1631460414585,"mc":[{"id":"1.187551081","rc":[{"trd":[[12,20.33],[12.5,70.84]],"batb":[[0,9.8,25.51],[1,9.2,71.09],[2,7.8,3]],"batl":[[0,13,2]],"ltp":12.0,"tv":1619.89,"id":7445998},{"trd":[[1.09,305.41]],"batb":[[0,1.08,659.97],[1,1.07,1326.93]],"batl":[[0,1.09,349.08],[1,1.1,790.94]],"ltp":1.09,"tv":16504.19,"id":9629022}],"tv":18124.08}]}
{"op":"mcm","clk":"4228239296","pt":1631460415478,"mc":[{"id":"1.187551081","rc":[{"batl":[[0,12.5,2],[1,13,2],[2,15.5,4]],"ltp":12.0,"tv":1619.89,"id":7445998},{"batb":[[1,1.07,1200.54]],"ltp":1.09,"tv":16504.19,"id":9629022}]}]}
{"op":"mcm","clk":"4228239571","pt":1631460417412,"mc":[{"id":"1.187551081","rc":[{"batb":[[1,9.2,73.09],[2,8,2]],"batl":[[1,13,15.29],[2,15.5,2]],"ltp":12.0,"tv":1619.89,"id":7445998},{"batb":[[0,1.08,688.54]],"batl":[[1,1.1,818.94],[2,1.12,241.71]],"ltp":1.09,"tv":16504.19,"id":9629022}]}]}
{"op":"mcm","clk":"4228239660","pt":1631460418021,"mc":[{"id":"1.187551081","rc":[{"batb":[[0,1.08,808.76]],"batl":[[0,1.09,471.6],[1,1.1,941.69]],"ltp":1.09,"tv":16504.19,"id":9629022}]}]}
{"op":"mcm","clk":"4228239917","pt":1631460419598,"mc":[{"id":"1.187551081","rc":[{"batb":[[0,12,45.22],[1,11,62.09],[2,9.8,25.51]],"ltp":12.0,"tv":1619.89,"id":7445998},{"batl":[[0,1.09,969.51],[1,1.1,1562.58]],"ltp":1.09,"tv":16504.19,"id":9629022}]}]}
{"op":"mcm","clk":"4228240053","pt":1631460420507,"mc":[{"id":"1.187551081","rc":[{"trd":[[12.5,71.18]],"batl":[[0,12.5,1.83]],"ltp":12.5,"tv":1620.23,"id":7445998},{"trd":[[1.09,325.41]],"batl":[[0,1.09,959.51]],"ltp":1.09,"tv":16524.19,"id":9629022}],"tv":18144.42}]}
{"op":"mcm","clk":"4228240185","pt":1631460421215,"mc":[{"id":"1.187551081","rc":[{"batb":[[0,1.08,1090.9]],"ltp":1.09,"tv":16524.19,"id":9629022}]}]}
{"op":"mcm","clk":"4228240439","pt":1631460422789,"mc":[{"id":"1.187551081","rc":[{"batl":[[0,1.09,1131.62]],"ltp":1.09,"tv":16524.19,"id":9629022}]}]}
{"op":"mcm","clk":"4228240801","pt":1631460425201,"mc":[{"id":"1.187551081","rc":[{"batl":[[1,13,59.7],[2,13.5,58.93]],"ltp":12.5,"tv":1620.23,"id":7445998},{"batb":[[0,1.08,2362.08]],"ltp":1.09,"tv":16524.19,"id":9629022}]}]}
{"op":"mcm","clk":"4228241139","pt":1631460427505,"mc":[{"id":"1.187551081","rc":[{"batl":[[1,13,57.7]],"ltp":12.5,"tv":1620.23,"id":7445998}]}]}
{"op":"mcm","clk":"4228241566","pt":1631460430420,"mc":[{"id":"1.187551081","rc":[{"batb":[[0,9.2,73.09],[1,8,2],[2,7.8,3]],"batl":[[0,18,2],[1,26,2],[2,30,47.33]],"ltp":12.5,"tv":1620.23,"id":7445998},{"batb":[[0,1.08,282.14],[1,1.07,295.03],[2,1.06,392.08]],"batl":[[0,1.12,231.71],[1,1.13,248.5],[2,1.14,201.75]],"ltp":1.09,"tv":16524.19,"id":9629022}]}]}
{"op":"mcm","clk":"4228241694","pt":1631460431310,"mc":[{"id":"1.187551081","rc":[{"batb":[[0,9.2,71.09]],"batl":[[0,26,2],[1,30,47.33],[2,990,0.01]],"ltp":12.5,"tv":1620.23,"id":7445998},{"batb":[[0,1.07,10],[1,1.04,3153.4],[2,1.01,30]],"batl":[[0,1.13,248.5],[1,1.14,201.75],[2,1.23,135.15]],"ltp":1.09,"tv":16524.19,"id":9629022}]}]}
{"op":"mcm","clk":"4228242002","pt":1631460433532,"mc":[{"id":"1.187551081","rc":[{"batb":[[1,9,30.4],[2,8,2]],"ltp":12.5,"tv":1620.23,"id":7445998},{"batb":[[0,1.06,1300.01]],"batl":[[0,1.12,333.97],[1,1.13,1136.96],[2,1.14,201.75]],"ltp":1.09,"tv":16524.19,"id":9629022}]}]}
{"op":"mcm","clk":"4228242165","pt":1631460434635,"mc":[{"id":"1.187551081","rc":[{"batb":[[0,9,30.4],[1,8,2],[2,7.8,3]],"batl":[[0,18,2],[1,21,2],[2,26,4]],"ltp":12.5,"tv":1620.23,"id":7445998},{"batb":[[0,1.06,446.08],[1,1.05,521.89],[2,1.04,3057.1]],"batl":[[0,1.13,30],[1,1.14,201.75],[2,1.23,29.65]],"ltp":1.09,"tv":16524.19,"id":9629022}]}]}
{"op":"mcm","clk":"4228242266","pt":1631460435431,"mc":[{"id":"1.187551081","rc":[{"batl":[[0,21,2],[1,26,4],[2,990,0.01]],"ltp":12.5,"tv":1620.23,"id":7445998},{"batb":[[0,1.04,3057.1],[1,1.01,30],[2,1.04,0]],"ltp":1.09,"tv":16524.19,"id":9629022}]}]}
{"op":"mcm","clk":"4228242438","pt":1631460436630,"mc":[{"id":"1.187551081","rc":[{"batl":[[0,14,133.44],[1,21,2],[2,26,4]],"ltp":12.5,"tv":1620.23,"id":7445998},{"batb":[[0,1.05,10],[1,1.04,3057.1],[2,1.01,30]],"ltp":1.09,"tv":16524.19,"id":9629022}]}]}
{"op":"mcm","clk":"4228242571","pt":1631460437629,"mc":[{"id":"1.187551081","rc":[{"batb":[[0,9.2,2],[1,9,30.4],[2,8,2]],"batl":[[0,21,2],[1,26,4],[2,990,0.01]],"ltp":12.5,"tv":1620.23,"id":7445998},{"batb":[[0,1.08,1275.94],[1,1.05,40],[2,1.04,3108.1]],"batl":[[0,1.1,989.44],[1,1.11,260.92],[2,1.12,204.96]],"ltp":1.09,"tv":16524.19,"id":9629022}]}]}
{"op":"mcm","clk":"4228242709","pt":1631460438530,"mc":[{"id":"1.187551081","rc":[{"batb":[[0,9.2,29.17]],"batl":[[0,14,10],[1,18,2],[2,21,2]],"ltp":12.5,"tv":1620.23,"id":7445998},{"batb":[[1,1.07,233.64],[2,1.06,454.08]],"batl":[[2,1.12,354.96]],"ltp":1.09,"tv":16524.19,"id":9629022}]}]}
{"op":"mcm","clk":"4228242803","pt":1631460439132,"mc":[{"id":"1.187551081","rc":[{"batb":[[0,9.2,2]],"ltp":12.5,"tv":1620.23,"id":7445998},{"batb":[[1,1.06,454.08],[2,1.05,567.09]],"ltp":1.09,"tv":16524.19,"id":9629022}]}]}
{"op":"mcm","clk":"4228243256","pt":1631460441540,"mc":[{"id":"1.187551081","rc":[{"batb":[[0,1.08,1592.36],[2,1.05,597.09]],"batl":[[0,1.1,1192.1]],"ltp":1.09,"tv":16524.19,"id":9629022}]}]}
{"op":"mcm","clk":"4228243414","pt":1631460442541,"mc":[{"id":"1.187551081","rc":[{"batb":[[0,9,30.4],[1,8,2],[2,7.8,3]],"batl":[[0,21,2],[1,24,50.59],[2,26,4]],"ltp":12.5,"tv":1620.23,"id":7445998},{"batb":[[0,1.05,115],[1,1.04,3108.1],[2,1.03,58]],"batl":[[0,1.13,222.5],[1,1.14,201.75],[2,1.23,29.65]],"ltp":1.09,"tv":16524.19,"id":9629022}]}]}
{"op":"mcm","clk":"4228243752","pt":1631460444628,"mc":[{"id":"1.187551081","rc":[{"batb":[[0,1.06,1300.01],[1,1.05,115],[2,1.04,3108.1]],"batl":[[0,1.12,333.97],[1,1.13,1110.96],[2,1.14,201.75]],"ltp":1.09,"tv":16524.19,"id":9629022}]}]}
{"op":"mcm","clk":"4228243926","pt":1631460445753,"mc":[{"id":"1.187551081","rc":[{"batb":[[0,9.2,2],[1,9,30.4],[2,8,2]],"batl":[[0,18,2],[1,21,2],[2,24,50.59]],"ltp":12.5,"tv":1620.23,"id":7445998},{"batb":[[0,1.06,1716.59],[1,1.05,551.49]],"batl":[[0,1.12,533.93]],"ltp":1.09,"tv":16524.19,"id":9629022}]}]}
{"op":"mcm","clk":"4228245220","pt":1631460453495,"mc":[{"id":"1.187551081","rc":[{"batb":[[0,1.11,8209.5],[1,1.06,1716.59],[2,1.05,551.49]],"ltp":1.09,"tv":16524.19,"id":9629022}]}]}
{"op":"mcm","clk":"4228245259","pt":1631460453804,"mc":[{"id":"1.187551081","rc":[{"batb":[[0,1.11,8190.06]],"ltp":1.09,"tv":16524.19,"id":9629022}]}]}
{"op":"mcm","clk":"4228245522","pt":1631460455477,"mc":[{"id":"1.187551081","rc":[{"batb":[[1,1.07,200],[2,1.06,1716.59]],"ltp":1.09,"tv":16524.19,"id":9629022}]}]}
{"op":"mcm","clk":"4228245709","pt":1631460456286,"mc":[{"id":"1.187551081","rc":[{"batb":[[0,9,30.4],[1,8,2],[2,7.8,3]],"ltp":12.5,"tv":1620.23,"id":7445998},{"batb":[[2,1.06,416.58]],"batl":[[0,1.12,333.97],[1,1.13,1080.96]],"ltp":1.09,"tv":16524.19,"id":9629022}]}]}
{"op":"mcm","clk":"4228245925","pt":1631460457575,"mc":[{"id":"1.187551081","rc":[{"batl":[[2,26,2]],"ltp":12.5,"tv":1620.23,"id":7445998},{"trd":[[1.11,774.42]],"batb":[[0,1.11,8160.06]],"ltp":1.11,"tv":16584.19,"id":9629022}],"tv":18204.42}]}
{"op":"mcm","clk":"4228245997","pt":1631460457966,"mc":[{"id":"1.187551081","rc":[{"trd":[[1.11,894.42]],"batb":[[0,1.11,8100.06]],"ltp":1.11,"tv":16704.19,"id":9629022}],"tv":18324.42}]}
{"op":"mcm","clk":"4228246239","pt":1631460459560,"mc":[{"id":"1.187551081","rc":[{"batl":[[0,11,2],[1,18,2],[2,21,2]],"ltp":12.5,"tv":1620.23,"id":7445998},{"batb":[[0,1.11,507.35],[1,1.1,816.91],[2,1.07,200]],"batl":[[2,1.14,171.75]],"ltp":1.11,"tv":16704.19,"id":9629022}]}]}
{"op":"mcm","clk":"4228246338","pt":1631460460273,"mc":[{"id":"1.187551081","rc":[{"batb":[[0,1.11,613.55],[1,1.1,1942.01]],"ltp":1.11,"tv":16704.19,"id":9629022}]}]}
{"op":"mcm","clk":"4228246516","pt":1631460461378,"mc":[{"id":"1.187551081","rc":[{"batl":[[0,10,2],[1,11,2],[2,17,57.21]],"ltp":12.5,"tv":1620.23,"id":7445998},{"trd":[[1.12,413.39]],"batb":[[0,1.11,636.55]],"batl":[[0,1.12,313.97]],"ltp":1.12,"tv":16744.19,"id":9629022}],"tv":18364.42}]}
{"op":"mcm","clk":"4228246687","pt":1631460462565,"mc":[{"id":"1.187551081","rc":[{"trd":[[1.12,533.39]],"batb":[[1,1.1,1896.86]],"batl":[[0,1.12,253.97]],"ltp":1.12,"tv":16864.19,"id":9629022}],"tv":18484.42}]}
{"op":"mcm","clk":"4228246804","pt":1631460463384,"mc":[{"id":"1.187551081","rc":[{"batl":[[1,10.5,10],[2,11,2]],"ltp":12.5,"tv":1620.23,"id":7445998},{"batb":[[1,1.1,2217.25],[2,1.06,2059.77]],"batl":[[1,1.13,1291.39]],"ltp":1.12,"tv":16864.19,"id":9629022}]}]}
{"op":"mcm","clk":"4228246916","pt":1631460464184,"mc":[{"id":"1.187551081","rc":[{"batl":[[0,9.8,2],[1,10,2]],"ltp":12.5,"tv":1620.23,"id":7445998}]}]}
{"op":"mcm","clk":"4228247105","pt":1631460465515,"mc":[{"id":"1.187551081","rc":[{"batb":[[0,9.2,48.65],[1,9,30.4],[2,8.6,65.42]],"ltp":12.5,"tv":1620.23,"id":7445998},{"batb":[[0,1.11,681.29]],"batl":[[0,1.12,689.39],[1,1.13,1833.18]],"ltp":1.12,"tv":16864.19,"id":9629022}]}]}
{"op":"mcm","clk":"4228247269","pt":1631460466588,"mc":[{"id":"1.187551081","rc":[{"trd":[[1.12,573.39]],"batb":[[1,1.1,2417.25],[2,1.08,308.31]],"batl":[[0,1.12,669.39]],"ltp":1.12,"tv":16904.19,"id":9629022}],"tv":18524.42}]}
{"op":"mcm","clk":"4228247339","pt":1631460467173,"mc":[{"id":"1.187551081","rc":[{"batl":[[0,9.6,2],[1,9.8,2],[2,10,2]],"ltp":12.5,"tv":1620.23,"id":7445998}]}]}
{"op":"mcm","clk":"4228247815","pt":1631460470409,"mc":[{"id":"1.187551081","rc":[{"batl":[[0,9.4,2],[1,9.6,12],[2,9.8,2]],"ltp":12.5,"tv":1620.23,"id":7445998},{"batb":[[0,1.11,1012.5]],"ltp":1.12,"tv":16904.19,"id":9629022}]}]}
{"op":"mcm","clk":"4228247920","pt":1631460471001,"mc":[{"id":"1.187551081","rc":[{"batb":[[0,1.11,947.5]],"ltp":1.12,"tv":16904.19,"id":9629022}]}]}
{"op":"mcm","clk":"4228248141","pt":1631460472297,"mc":[{"id":"1.187551081","rc":[{"batb":[[1,1.1,2217.25]],"ltp":1.12,"tv":16904.19,"id":9629022}]}]}
{"op":"mcm","clk":"4228248365","pt":1631460473595,"mc":[{"id":"1.187551081","rc":[{"batb":[[0,6.4,63.31],[1,5.3,2.08],[2,3.6,376.71]],"batl":[[0,13.5,2],[1,17,57.21],[2,18,2]],"ltp":12.5,"tv":1620.23,"id":7445998},{"batb":[[0,1.08,308.31],[1,1.07,333.07],[2,1.06,2059.77]],"batl":[[0,1.21,134.5],[1,1.23,151.15],[2,1.25,14.82]],"ltp":1.12,"tv":16904.19,"id":9629022}]}]}
{"op":"mcm","clk":"4228248459","pt":1631460474097,"mc":[{"id":"1.187551081","rc":[{"batb":[[1,6,2.04],[2,5.1,2.04]],"batl":[[0,17,57.21],[1,18,2],[2,26,2]],"ltp":12.5,"tv":1620.23,"id":7445998},{"batb":[[0,1.06,2059.77],[1,1.05,506.49],[2,1.04,664.37]],"batl":[[0,1.2,134.73],[1,1.22,119.75],[2,1.23,151.15]],"ltp":1.12,"tv":16904.19,"id":9629022}]}]}
{"op":"mcm","clk":"4228248638","pt":1631460475247,"mc":[{"id":"1.187551081","rc":[{"trd":[[1.12,605.39]],"batb":[[0,1.11,200],[1,1.06,2059.77],[2,1.05,506.49]],"ltp":1.12,"tv":16936.19,"id":9629022}],"tv":18556.42}]}
{"op":"mcm","clk":"4228248979","pt":1631460477416,"mc":[{"id":"1.187551081","rc":[{"batb":[[0,6.4,65.31],[1,6.2,3],[2,5.3,2.08]],"batl":[[0,13.5,2],[1,15.5,2],[2,17,59.21]],"ltp":12.5,"tv":1620.23,"id":7445998},{"batb":[[0,1.12,500],[1,1.11,200],[2,1.08,1450.31]],"batl":[[0,1.17,226.87],[1,1.18,721.64],[2,1.19,10]],"ltp":1.12,"tv":16936.19,"id":9629022}]}]}
{"op":"mcm","clk":"4228249432","pt":1631460480113,"mc":[{"id":"1.187551081","rc":[{"batb":[[1,6.2,5.02]],"ltp":12.5,"tv":1620.23,"id":7445998},{"batl":[[2,1.19,149.5]],"ltp":1.12,"tv":16936.19,"id":9629022}]}]}
{"op":"mcm","clk":"4228249708","pt":1631460481836,"mc":[{"id":"1.187551081","rc":[{"batb":[[0,1.11,200],[1,1.08,1450.31],[2,1.07,371.07]],"ltp":1.12,"tv":16936.19,"id":9629022}]}]}
{"op":"mcm","clk":"4228250532","pt":1631460487056,"mc":[{"id":"1.187551081","rc":[{"batb":[[0,1.08,1450.31],[1,1.07,371.07],[2,1.06,2090.77]],"ltp":1.12,"tv":16936.19,"id":9629022}]}]}
{"op":"mcm","clk":"4228251037","pt":1631460490338,"mc":[{"id":"1.187551081","rc":[{"batb":[[1,6.2,2.02]],"batl":[[2,17,57.21]],"ltp":12.5,"tv":1620.23,"id":7445998},{"batb":[[0,1.12,200],[1,1.09,18.89],[2,1.08,1450.31]],"batl":[[0,1.19,149.5],[1,1.21,135.5],[2,1.23,151.15]],"ltp":1.12,"tv":16936.19,"id":9629022}]}]}
{"op":"mcm","clk":"4228251376","pt":1631460492643,"mc":[{"id":"1.187551081","rc":[{"batl":[[2,18,2]],"ltp":12.5,"tv":1620.23,"id":7445998},{"trd":[[1.12,702.99]],"batb":[[0,1.12,151.2]],"ltp":1.12,"tv":17033.79,"id":9629022}],"tv":18654.02}]}
{"op":"mcm","clk":"4228251512","pt":1631460493546,"mc":[{"id":"1.187551081","rc":[{"batb":[[0,12,39.69],[1,8.8,31.4],[2,6.4,65.31]],"ltp":12.5,"tv":1620.23,"id":7445998},{"trd":[[1.12,1005.39]],"batb":[[0,1.09,18.89],[1,1.08,1450.31],[2,1.07,371.07]],"batl":[[0,1.1,1101.54],[1,1.19,149.5],[2,1.21,135.5]],"ltp":1.12,"tv":17336.19,"id":9629022}],"tv":18956.42}]}
{"op":"mcm","clk":"4228251667","pt":1631460494525,"mc":[{"id":"1.187551081","rc":[{"batb":[[1,9.6,26.04],[2,8.8,31.4]],"batl":[[0,13,7.41],[1,13.5,2],[2,15.5,2]],"ltp":12.5,"tv":1620.23,"id":7445998},{"batl":[[1,1.13,221.24],[2,1.19,149.5]],"ltp":1.12,"tv":17336.19,"id":9629022}]}]}
{"op":"mcm","clk":"4228251838","pt":1631460495649,"mc":[{"id":"1.187551081","rc":[{"batb":[[2,9.4,2]],"ltp":12.5,"tv":1620.23,"id":7445998},{"batl":[[1,1.13,16],[2,1.18,13]],"ltp":1.12,"tv":17336.19,"id":9629022}]}]}
{"op":"mcm","clk":"4228251977","pt":1631460496564,"mc":[{"id":"1.187551081","rc":[{"batl":[[0,13,2]],"ltp":12.5,"tv":1620.23,"id":7445998},{"trd":[[1.1,863.9]],"batb":[[1,1.08,1537.69]],"batl":[[0,1.1,1244.24]],"ltp":1.1,"tv":17353.19,"id":9629022}],"tv":18973.42}]}
{"op":"mcm","clk":"4228252050","pt":1631460497045,"mc":[{"id":"1.187551081","rc":[{"batb":[[1,1.08,1902.74]],"batl":[[0,1.1,1496.94]],"ltp":1.1,"tv":17353.19,"id":9629022}]}]}
{"op":"mcm","clk":"4228252215","pt":1631460498281,"mc":[{"id":"1.187551081","rc":[{"batl":[[0,12.5,2],[1,13,2],[2,13.5,2]],"ltp":12.5,"tv":1620.23,"id":7445998},{"trd":[[1.09,363.19]],"batb":[[0,1.08,1902.74],[1,1.07,371.07],[2,1.06,2090.77]],"batl":[[0,1.1,1572.54]],"ltp":1.09,"tv":17390.97,"id":9629022}],"tv":19011.2}]}
{"op":"mcm","clk":"4228252430","pt":1631460499668,"mc":[{"id":"1.187551081","rc":[{"batl":[[0,12.5,9.41]],"ltp":12.5,"tv":1620.23,"id":7445998},{"batl":[[1,1.12,213.71],[2,1.13,225.5]],"ltp":1.09,"tv":17390.97,"id":9629022}]}]}
{"op":"mcm","clk":"4228252523","pt":1631460500263,"mc":[{"id":"1.187551081","rc":[{"batb":[[1,11,45.78],[2,10,60.01]],"ltp":12.5,"tv":1620.23,"id":7445998},{"batl":[[0,1.1,2030.31],[1,1.11,540.61],[2,1.12,213.71]],"ltp":1.09,"tv":17390.97,"id":9629022}]}]}
{"op":"mcm","clk":"4228252617","pt":1631460500977,"mc":[{"id":"1.187551081","rc":[{"batb":[[0,1.08,2025.83]],"ltp":1.09,"tv":17390.97,"id":9629022}]}]}
{"op":"mcm","clk":"4228253672","pt":1631460508374,"mc":[{"id":"1.187551081","rc":[{"batl":[[1,13.5,44.02],[2,15.5,52.7]],"ltp":12.5,"tv":1620.23,"id":7445998},{"batb":[[0,1.08,2551.07],[1,1.07,1134.59]],"ltp":1.09,"tv":17390.97,"id":9629022}]}]}
{"op":"mcm","clk":"4228253904","pt":1631460509974,"mc":[{"id":"1.187551081","rc":[{"batb":[[2,1.06,2140.77]],"ltp":1.09,"tv":17390.97,"id":9629022}]}]}
{"op":"mcm","clk":"4228254085","pt":1631460511272,"mc":[{"id":"1.187551081","rc":[{"trd":[[12,99.72]],"batb":[[0,11,45.78],[1,10,60.01],[2,9.6,26.04]],"batl":[[0,12,1.98],[1,12.5,9.41],[2,13.5,44.02]],"ltp":12.0,"tv":1699.61,"id":7445998}],"tv":19090.58}]}
{"op":"mcm","clk":"4228254147","pt":1631460511703,"mc":[{"id":"1.187551081","rc":[{"batb":[[2,9.4,2]],"ltp":12.0,"tv":1699.61,"id":7445998}]}]}
{"op":"mcm","clk":"4228254549","pt":1631460514593,"mc":[{"id":"1.187551081","rc":[{"batb":[[0,8.8,31.4],[1,8,2],[2,6.2,2.02]],"batl":[[1,26,2],[2,30,47.33]],"ltp":12.0,"tv":1699.61,"id":7445998},{"batb":[[0,1.06,50],[1,1.04,2995.55],[2,1.01,30]],"batl":[[0,1.13,209.5],[1,1.14,181.25],[2,1.19,139.5]],"ltp":1.09,"tv":17390.97,"id":9629022}]}]}
{"op":"mcm","clk":"4228254666","pt":1631460515363,"mc":[{"id":"1.187551081","rc":[{"batb":[[1,8.6,2],[2,8,2]],"ltp":12.0,"tv":1699.61,"id":7445998},{"batb":[[0,1.09,1.38],[1,1.06,50],[2,1.04,2995.55]],"batl":[[2,1.15,172.7]],"ltp":1.09,"tv":17390.97,"id":9629022}]}]}
{"op":"mcm","clk":"4228254996","pt":1631460517451,"mc":[{"id":"1.187551081","rc":[{"batb":[[0,8.6,35.66],[1,8,2],[2,7.6,2]],"ltp":12.0,"tv":1699.61,"id":7445998},{"batb":[[1,1.06,1350.01],[2,1.04,2898.92]],"batl":[[0,1.13,1108.43],[1,1.14,498.98]],"ltp":1.09,"tv":17390.97,"id":9629022}]}]}
{"op":"mcm","clk":"4228255052","pt":1631460517889,"mc":[{"id":"1.187551081","rc":[{"batl":[[1,18,2],[2,26,2]],"ltp":12.0,"tv":1699.61,"id":7445998},{"batb":[[1,1.06,1808.09],[2,1.05,465.89]],"ltp":1.09,"tv":17390.97,"id":9629022}]}]}
{"op":"mcm","clk":"4228255268","pt":1631460519582,"mc":[{"id":"1.187551081","rc":[{"batb":[[0,1.06,1808.09],[1,1.05,465.89],[2,1.04,2898.92]],"ltp":1.09,"tv":17390.97,"id":9629022}]}]}
{"op":"mcm","clk":"4228255401","pt":1631460520471,"mc":[{"id":"1.187551081","rc":[{"batb":[[1,1.05,615.89]],"ltp":1.09,"tv":17390.97,"id":9629022}]}]}
{"op":"mcm","clk":"4228256104","pt":1631460526163,"mc":[{"id":"1.187551081","rc":[{"trd":[[12,101.7]],"batl":[[0,18,2],[1,26,2],[2,30,47.33]],"ltp":12.0,"tv":1701.59,"id":7445998},{"trd":[[1.09,384.98]],"batl":[[0,1.08,7643.15],[1,1.13,1108.43],[2,1.14,498.98]],"ltp":1.09,"tv":17412.76,"id":9629022}],"tv":19114.35}]}
{"op":"mcm","clk":"4228256259","pt":1631460527566,"mc":[{"id":"1.187551081","rc":[{"batb":[[0,8.6,33.66]],"ltp":12.0,"tv":1701.59,"id":7445998},{"batb":[[0,1.06,1780.4]],"batl":[[0,1.23,29.65],[1,1.25,14.82],[2,1.39,17.79]],"ltp":1.09,"tv":17412.76,"id":9629022}]}]}
{"op":"mcm","clk":"4228256501","pt":1631460529403,"mc":[{"id":"1.187551081","rc":[{"batl":[[2,990,0.01]],"ltp":12.0,"tv":1701.59,"id":7445998},{"batl":[[0,1.21,11.86],[1,1.23,29.65],[2,1.25,14.82]],"ltp":1.09,"tv":17412.76,"id":9629022}]}]}
{"op":"mcm","clk":"4228256649","pt":1631460530306,"mc":[{"id":"1.187551081","rc":[{"batb":[[0,1.06,1730.4]],"batl":[[0,1.08,1248.75],[1,1.1,14.5],[2,1.21,11.86]],"ltp":1.09,"tv":17412.76,"id":9629022}]}]}
{"op":"mcm","clk":"4228256808","pt":1631460531428,"mc":[{"id":"1.187551081","rc":[{"batb":[[0,15,23.36],[1,13,33.16],[2,9.4,3]],"batl":[[0,17.5,2],[1,18,2],[2,26,2]],"ltp":12.0,"tv":1701.59,"id":7445998},{"batl":[[2,1.11,21]],"ltp":1.09,"tv":17412.76,"id":9629022}]}]}
{"op":"mcm","clk":"4228256933","pt":1631460532238,"mc":[{"id":"1.187551081","rc":[{"batb":[[2,12.5,19.74]],"ltp":12.0,"tv":1701.59,"id":7445998},{"batb":[[0,1.06,1858.39]],"ltp":1.09,"tv":17412.76,"id":9629022}]}]}
{"op":"mcm","clk":"4228257219","pt":1631460534428,"mc":[{"id":"1.187551081","rc":[{"batl":[[0,17,2],[1,17.5,2],[2,18,2]],"ltp":12.0,"tv":1701.59,"id":7445998},{"batb":[[0,1.06,2369.47]],"batl":[[0,1.08,1695.8]],"ltp":1.09,"tv":17412.76,"id":9629022}]}]}
{"op":"mcm","clk":"4228257377","pt":1631460535495,"mc":[{"id":"1.187551081","rc":[{"batl":[[0,1.08,1844.05]],"ltp":1.09,"tv":17412.76,"id":9629022}]}]}
{"op":"mcm","clk":"4228257514","pt":1631460536471,"mc":[{"id":"1.187551081","rc":[{"batb":[[1,13.5,34.78],[2,13,33.16]],"ltp":12.0,"tv":1701.59,"id":7445998},{"batl":[[0,1.08,2278.76],[1,1.09,499.62],[2,1.1,14.5]],"ltp":1.09,"tv":17412.76,"id":9629022}]}]}
{"op":"mcm","clk":"4228257655","pt":1631460537358,"mc":[{"id":"1.187551081","rc":[{"batl":[[0,16.5,2],[1,17,2],[2,17.5,2]],"ltp":12.0,"tv":1701.59,"id":7445998},{"batb":[[0,1.06,2927.16],[1,1.05,1290.58]],"ltp":1.09,"tv":17412.76,"id":9629022}]}]}
{"op":"mcm","clk":"4228257838","pt":1631460538634,"mc":[{"id":"1.187551081","rc":[{"batl":[[0,16.5,9.25]],"ltp":12.0,"tv":1701.59,"id":7445998}]}]}
{"op":"mcm","clk":"4228257884","pt":1631460538951,"mc":[{"id":"1.187551081","rc":[{"batl":[[0,1.07,1.71],[1,1.08,2278.76],[2,1.09,499.62]],"ltp":1.09,"tv":17412.76,"id":9629022}]}]}
{"op":"mcm","clk":"4228258117","pt":1631460540408,"mc":[{"id":"1.187551081","rc":[{"batl":[[0,16,2],[1,16.5,9.25],[2,17,2]],"ltp":12.0,"tv":1701.59,"id":7445998}]}]}
{"op":"mcm","clk":"4228258403","pt":1631460542334,"mc":[{"id":"1.187551081","rc":[{"batl":[[0,1.08,2278.76],[1,1.09,499.62],[2,1.1,14.5]],"ltp":1.09,"tv":17412.76,"id":9629022}]}]}
{"op":"mcm","clk":"4228258472","pt":1631460542717,"mc":[{"id":"1.187551081","rc":[{"batb":[[1,1.05,1140.58]],"ltp":1.09,"tv":17412.76,"id":9629022}]}]}
{"op":"mcm","clk":"4228258888","pt":1631460545546,"mc":[{"id":"1.187551081","rc":[{"trd":[[15,0.62]],"batb":[[0,15,23.05]],"ltp":15.0,"tv":1702.21,"id":7445998},{"batb":[[2,1.04,2898]],"ltp":1.09,"tv":17412.76,"id":9629022}],"tv":19114.97}]}
{"op":"mcm","clk":"4228259799","pt":1631460551835,"mc":[{"id":"1.187551081","rc":[{"batl":[[1,16.5,7.25],[2,18,34.84]],"ltp":15.0,"tv":1702.21,"id":7445998},{"trd":[[1.08,0.12]],"batl":[[0,1.08,2278.7]],"ltp":1.08,"tv":17412.88,"id":9629022}],"tv":19115.09}]}
{"op":"mcm","clk":"4228260670","pt":1631460558046,"mc":[{"id":"1.187551081","rc":[{"batb":[[0,1.07,1.38],[1,1.06,2927.16],[2,1.05,1140.58]],"ltp":1.08,"tv":17412.88,"id":9629022}]}]}
{"op":"mcm","clk":"4228261401","pt":1631460562887,"mc":[{"id":"1.187551081","rc":[{"batl":[[0,15.5,37.67],[1,16,2],[2,16.5,7.25]],"ltp":15.0,"tv":1702.21,"id":7445998},{"batb":[[0,1.07,547.11],[1,1.06,3595.02]],"ltp":1.08,"tv":17412.88,"id":9629022}]}]}
{"op":"mcm","clk":"4228262841","pt":1631460572278,"mc":[{"id":"1.187551081","rc":[{"batb":[[0,1.07,545.73]],"ltp":1.08,"tv":17412.88,"id":9629022}]}]}
{"op":"mcm","clk":"4228263260","pt":1631460574982,"mc":[{"id":"1.187551081","rc":[{"trd":[[1.07,42.7]],"batb":[[0,1.07,524.38]],"ltp":1.07,"tv":17455.58,"id":9629022}],"tv":19157.8}]}
{"op":"mcm","clk":"4228264185","pt":1631460581223,"mc":[{"id":"1.187551081","rc":[{"trd":[[1.08,1.14]],"batl":[[0,1.08,2278.19]],"ltp":1.08,"tv":17456.6,"id":9629022}],"tv":19158.82}]}
{"op":"mcm","clk":"4228264763","pt":1631460585408,"mc":[{"id":"1.187551081","rc":[{"trd":[[1.08,4.56]],"batl":[[0,1.08,2276.48]],"ltp":1.08,"tv":17460.02,"id":9629022}],"tv":19162.24}]}
{"op":"mcm","clk":"4228264883","pt":1631460586176,"mc":[{"id":"1.187551081","rc":[{"trd":[[1.08,7.32]],"batl":[[0,1.08,2275.1]],"ltp":1.08,"tv":17462.78,"id":9629022}],"tv":19164.99}]}
{"op":"mcm","clk":"4228265104","pt":1631460587609,"mc":[{"id":"1.187551081","rc":[{"trd":[[15,7.38]],"batb":[[0,15,19.67]],"ltp":15.0,"tv":1708.97,"id":7445998},{"trd":[[1.07,62.7]],"batb":[[0,1.07,514.38]],"ltp":1.07,"tv":17482.78,"id":9629022}],"tv":19191.75}]}
{"op":"mcm","clk":"4228265416","pt":1631460589823,"mc":[{"id":"1.187551081","rc":[{"trd":[[1.07,66.7]],"batb":[[0,1.07,512.38]],"ltp":1.07,"tv":17486.78,"id":9629022}],"tv":19195.75}]}
{"op":"mcm","clk":"4228265693","pt":1631460591608,"mc":[{"id":"1.187551081","rc":[{"trd":[[15,38.79]],"batb":[[0,15,3.97]],"ltp":15.0,"tv":1740.38,"id":7445998},{"batb":[[2,1.05,3364.25]],"ltp":1.07,"tv":17486.78,"id":9629022}],"tv":19227.16}]}
{"op":"mcm","clk":"4228266108","pt":1631460594289,"mc":[{"id":"1.187551081","rc":[{"trd":[[1.08,9.06]],"batl":[[0,1.08,2274.23]],"ltp":1.08,"tv":17488.52,"id":9629022}],"tv":19228.9}]}
{"op":"mcm","clk":"4228266865","pt":1631460599416,"mc":[{"id":"1.187551081","rc":[{"batb":[[0,15,24.48]],"ltp":15.0,"tv":1740.38,"id":7445998}]}]}
{"op":"mcm","clk":"4228266923","pt":1631460599834,"mc":[{"id":"1.187551081","rc":[{"batb":[[2,12.5,54.41]],"ltp":15.0,"tv":1740.38,"id":7445998},{"batb":[[2,1.05,3318.19]],"ltp":1.08,"tv":17488.52,"id":9629022}]}]}
{"op":"mcm","clk":"4228269187","pt":1631460611621,"mc":[{"id":"1.187551081","rc":[{"trd":[[1.08,19.06]],"batl":[[0,1.08,2269.23]],"ltp":1.08,"tv":17498.52,"id":9629022}],"tv":19238.9}]}
{"op":"mcm","clk":"4228269959","pt":1631460615299,"mc":[{"id":"1.187551081","rc":[{"trd":[[15,43.13]],"batb":[[0,15,22.31]],"ltp":15.0,"tv":1744.72,"id":7445998}],"tv":19243.24}]}
{"op":"mcm","clk":"4228270600","pt":1631460619420,"mc":[{"id":"1.187551081","rc":[{"batb":[[0,14.5,24.62]],"ltp":15.0,"tv":1744.72,"id":7445998},{"batb":[[2,1.05,3311.91]],"ltp":1.08,"tv":17498.52,"id":9629022}]}]}
{"op":"mcm","clk":"4228270652","pt":1631460619743,"mc":[{"id":"1.187551081","rc":[{"batb":[[2,12.5,34.67]],"ltp":15.0,"tv":1744.72,"id":7445998}]}]}
{"op":"mcm","clk":"4228271075","pt":1631460622017,"mc":[{"id":"1.187551081","rc":[{"batb":[[0,1.07,1112.17]],"ltp":1.08,"tv":17498.52,"id":9629022}]}]}
{"op":"mcm","clk":"4228271257","pt":1631460623240,"mc":[{"id":"1.187551081","rc":[{"batb":[[0,14.5,29.2]],"ltp":15.0,"tv":1744.72,"id":7445998}]}]}
{"op":"mcm","clk":"4228276563","pt":1631460656597,"mc":[{"id":"1.187551081","rc":[{"batl":[[0,15,1.38],[1,15.5,37.67],[2,16,2]],"ltp":15.0,"tv":1744.72,"id":7445998}]}]}
{"op":"mcm","clk":"4228277473","pt":1631460662071,"mc":[{"id":"1.187551081","rc":[{"trd":[[1.08,91.36]],"batl":[[0,1.08,2233.08]],"ltp":1.08,"tv":17570.82,"id":9629022}],"tv":19315.54}]}
{"op":"mcm","clk":"4228278002","pt":1631460665398,"mc":[{"id":"1.187551081","rc":[{"batl":[[0,1.08,2278.76]],"ltp":1.08,"tv":17570.82,"id":9629022}]}]}
{"op":"mcm","clk":"4228280018","pt":1631460677338,"mc":[{"id":"1.187551081","rc":[{"batl":[[2,1.11,21]],"ltp":1.08,"tv":17570.82,"id":9629022}]}]}
{"op":"mcm","clk":"4228280401","pt":1631460679610,"mc":[{"id":"1.187551081","rc":[{"batl":[[0,15.5,37.67],[1,16,2],[2,16.5,7.25]],"ltp":15.0,"tv":1744.72,"id":7445998}]}]}
{"op":"mcm","clk":"4228280913","pt":1631460682712,"mc":[{"id":"1.187551081","rc":[{"trd":[[14.5,2.76]],"batb":[[0,14.5,27.82]],"ltp":14.5,"tv":1747.48,"id":7445998}],"tv":19318.3}]}
{"op":"mcm","clk":"4228283892","pt":1631460702343,"mc":[{"id":"1.187551081","rc":[{"trd":[[1.08,94.96]],"batl":[[0,1.08,2276.96]],"ltp":1.08,"tv":17574.42,"id":9629022}],"tv":19321.9}]}
{"op":"mcm","clk":"4228286448","pt":1631460718651,"mc":[{"id":"1.187551081","rc":[{"batb":[[0,14.5,23.24],[1,12.5,34.67],[2,9.4,3]],"batl":[[0,42,43.97],[1,990,0.01],[2,16.5,0]],"ltp":14.5,"tv":1747.48,"id":7445998},{"batb":[[0,1.05,2171.33],[1,1.04,2701.47],[2,1.01,30]],"batl":[[0,1.11,21],[1,1.19,14.82],[2,1.21,11.86]],"ltp":1.08,"tv":17574.42,"id":9629022}]}]}
{"op":"mcm","clk":"4228286456","pt":1631460718753,"mc":[{"id":"1.187551081","rc":[{"batb":[[0,12.5,34.67],[1,9.4,3],[2,3.6,376.71]],"ltp":14.5,"tv":1747.48,"id":7445998},{"batb":[[0,1.04,2696.62],[1,1.01,30],[2,1.01,0]],"ltp":1.08,"tv":17574.42,"id":9629022}]}]}
{"op":"mcm","clk":"4228286951","pt":1631460721556,"mc":[{"id":"1.187551081","rc":[{"batb":[[0,1.05,1284.44],[1,1.04,2696.62],[2,1.01,30]],"batl":[[0,1.09,1104.52],[1,1.1,24],[2,1.11,21]],"ltp":1.08,"tv":17574.42,"id":9629022}]}]}
{"op":"mcm","clk":"4228287043","pt":1631460722094,"mc":[{"id":"1.187551081","rc":[{"batl":[[0,26,2],[1,42,43.97],[2,990,0.01]],"ltp":14.5,"tv":1747.48,"id":7445998},{"batb":[[1,1.04,2744.62],[2,1.03,69]],"ltp":1.08,"tv":17574.42,"id":9629022}]}]}
{"op":"mcm","clk":"4228287190","pt":1631460722961,"mc":[{"id":"1.187551081","rc":[{"batb":[[0,1.04,2744.62],[1,1.03,69],[2,1.01,30]],"batl":[[0,1.1,24],[1,1.11,21],[2,1.19,14.82]],"ltp":1.08,"tv":17574.42,"id":9629022}]}]}
{"op":"mcm","clk":"4228287418","pt":1631460724307,"mc":[{"id":"1.187551081","rc":[{"batb":[[2,1.01,30]],"batl":[[1,990,0.01],[2,990,0]],"ltp":14.5,"tv":1747.48,"id":7445998}]}]}
{"op":"mcm","clk":"4228287693","pt":1631460725880,"mc":[{"id":"1.187551081","rc":[{"batb":[[0,1.06,1262.01],[1,1.04,2744.62],[2,1.03,69]],"batl":[[0,1.07,399.33],[1,1.08,853.13],[2,1.1,24]],"ltp":1.08,"tv":17574.42,"id":9629022}]}]}
{"op":"mcm","clk":"4228287908","pt":1631460727177,"mc":[{"id":"1.187551081","rc":[{"batb":[[0,13,17.87],[1,12.5,34.67],[2,9.4,3]],"batl":[[0,20,10],[1,26,2],[2,990,0.01]],"ltp":14.5,"tv":1747.48,"id":7445998},{"batl":[[2,1.09,120]],"ltp":1.08,"tv":17574.42,"id":9629022}]}]}
{"op":"mcm","clk":"4228288121","pt":1631460728385,"mc":[{"id":"1.187551081","rc":[{"batl":[[2,65,41.05]],"ltp":14.5,"tv":1747.48,"id":7445998}]}]}
{"op":"mcm","clk":"4228288286","pt":1631460729259,"mc":[{"id":"1.187551081","rc":[{"batb":[[0,12.5,34.67],[1,9.4,3],[2,4.1,377.07]],"batl":[[0,26,2],[1,65,41.05],[2,990,0.01]],"ltp":14.5,"tv":1747.48,"id":7445998},{"batb":[[0,1.04,2744.62],[1,1.03,69],[2,1.01,30]],"batl":[[0,1.1,24],[1,1.11,21],[2,1.19,14.82]],"ltp":1.08,"tv":17574.42,"id":9629022}]}]}
{"op":"mcm","clk":"4228288837","pt":1631460732561,"mc":[{"id":"1.187551081","rc":[{"batb":[[0,1.05,1284.44],[1,1.04,2744.62],[2,1.03,69]],"batl":[[0,1.09,1104.52],[1,1.1,24],[2,1.11,21]],"ltp":1.08,"tv":17574.42,"id":9629022}]}]}
{"op":"mcm","clk":"4228289409","pt":1631460736288,"mc":[{"id":"1.187551081","rc":[{"batb":[[2,1.01,30]],"batl":[[0,1.1,24],[1,1.19,14.82],[2,1.21,11.86]],"ltp":1.08,"tv":17574.42,"id":9629022}]}]}
{"op":"mcm","clk":"4228289590","pt":1631460737459,"mc":[{"id":"1.187551081","rc":[{"batl":[[1,990,0.01],[2,990,0]],"ltp":14.5,"tv":1747.48,"id":7445998}]}]}
{"op":"mcm","clk":"4228289879","pt":1631460739398,"mc":[{"id":"1.187551081","rc":[{"batb":[[0,13,2],[1,12.5,36.67],[2,9.4,3]],"batl":[[0,20,2],[1,26,2],[2,990,0.01]],"ltp":14.5,"tv":1747.48,"id":7445998},{"trd":[[1.06,50]],"batb":[[0,1.05,1312.44],[2,1.01,45.79]],"batl":[[0,1.06,336.92],[1,1.07,901.88],[2,1.08,22]],"ltp":1.06,"tv":17624.42,"id":9629022}],"tv":19371.9}]}
{"op":"mcm","clk":"4228290032","pt":1631460740209,"mc":[{"id":"1.187551081","rc":[{"batb":[[0,17,17.42],[1,14.5,25.04],[2,13,2]],"ltp":14.5,"tv":1747.48,"id":7445998},{"batb":[[0,1.05,1443.52],[2,1.03,3464.24]],"batl":[[2,1.08,142]],"ltp":1.06,"tv":17624.42,"id":9629022}]}]}
{"op":"mcm","clk":"4228290276","pt":1631460741664,"mc":[{"id":"1.187551081","rc":[{"batl":[[2,95,39.22]],"ltp":14.5,"tv":1747.48,"id":7445998},{"trd":[[1.06,63.78]],"batl":[[0,1.06,330.03]],"ltp":1.06,"tv":17638.2,"id":9629022}],"tv":19385.68}]}
{"op":"mcm","clk":"4228290400","pt":1631460742471,"mc":[{"id":"1.187551081","rc":[{"batl":[[0,19.5,2],[1,20,2],[2,26,2]],"ltp":14.5,"tv":1747.48,"id":7445998}]}]}
{"op":"mcm","clk":"4228290559","pt":1631460743578,"mc":[{"id":"1.187551081","rc":[{"batb":[[0,17,18.32]],"batl":[[0,19.5,5.46]],"ltp":14.5,"tv":1747.48,"id":7445998}]}]}
{"op":"mcm","clk":"4228290651","pt":1631460744103,"mc":[{"id":"1.187551081","rc":[{"batb":[[0,1.05,2008.72]],"batl":[[1,1.07,1420.24]],"ltp":1.06,"tv":17638.2,"id":9629022}]}]}
{"op":"mcm","clk":"4228290874","pt":1631460745492,"mc":[{"id":"1.187551081","rc":[{"batb":[[1,15,2],[2,14.5,25.04]],"batl":[[2,26,4]],"ltp":14.5,"tv":1747.48,"id":7445998},{"batb":[[1,1.04,3395.24],[2,1.03,4296.07]],"batl":[[1,1.07,1815.74],[2,1.08,503.69]],"ltp":1.06,"tv":17638.2,"id":9629022}]}]}
{"op":"mcm","clk":"4228290975","pt":1631460746111,"mc":[{"id":"1.187551081","rc":[{"batl":[[0,19,2],[1,19.5,5.46],[2,20,2]],"ltp":14.5,"tv":1747.48,"id":7445998},{"batb":[[1,1.04,3868.19],[2,1.03,4924.88]],"ltp":1.06,"tv":17638.2,"id":9629022}]}]}
{"op":"mcm","clk":"4228291624","pt":1631460750421,"mc":[{"id":"1.187551081","rc":[{"batb":[[0,15,2],[1,14.5,25.04],[2,13.5,2]],"batl":[[0,24,20.06],[1,25,17.24],[2,26,29.54]],"ltp":14.5,"tv":1747.48,"id":7445998},{"batb":[[0,1.04,1171.57],[1,1.03,4924.88],[2,1.02,2159.67]],"batl":[[0,1.07,395.5],[1,1.08,383.69],[2,1.09,314.5]],"ltp":1.06,"tv":17638.2,"id":9629022}]}]}
{"op":"mcm","clk":"4228291689","pt":1631460750804,"mc":[{"id":"1.187551081","rc":[{"batb":[[0,14.5,25.04],[1,13.5,2],[2,13,2]],"ltp":14.5,"tv":1747.48,"id":7445998},{"batl":[[0,1.08,383.69],[1,1.09,314.5],[2,1.1,24]],"ltp":1.06,"tv":17638.2,"id":9629022}]}]}
{"op":"mcm","clk":"4228291994","pt":1631460752424,"mc":[{"id":"1.187551081","rc":[{"batl":[[1,1.11,211.29],[2,1.12,295.32]],"ltp":1.06,"tv":17638.2,"id":9629022}]}]}
{"op":"mcm","clk":"4228292217","pt":1631460753633,"mc":[{"id":"1.187551081","rc":[{"batb":[[1,1.03,4986.88]],"ltp":1.06,"tv":17638.2,"id":9629022}]}]}
{"op":"mcm","clk":"4228292348","pt":1631460754315,"mc":[{"id":"1.187551081","rc":[{"batb":[[0,14.5,27.04],[1,14,2],[2,13.5,2]],"ltp":14.5,"tv":1747.48,"id":7445998}]}]}
{"op":"mcm","clk":"4228292544","pt":1631460755510,"mc":[{"id":"1.187551081","rc":[{"batb":[[0,1.05,1200.28],[1,1.04,1171.57],[2,1.03,4986.88]],"batl":[[0,1.06,857.81],[1,1.07,431.67],[2,1.08,383.69]],"ltp":1.06,"tv":17638.2,"id":9629022}]}]}
{"op":"mcm","clk":"4228292583","pt":1631460755726,"mc":[{"id":"1.187551081","rc":[{"batb":[[0,1.05,1178.19]],"batl":[[0,1.06,836.56]],"ltp":1.06,"tv":17638.2,"id":9629022}]}]}
{"op":"mcm","clk":"4228293013","pt":1631460758307,"mc":[{"id":"1.187551081","rc":[{"batb":[[0,15,2],[1,14.5,27.04],[2,14,2]],"batl":[[0,23,8.11],[1,24,20.06],[2,25,17.24]],"ltp":14.5,"tv":1747.48,"id":7445998},{"batb":[[0,1.05,1277.77]],"batl":[[1,1.07,803.17]],"ltp":1.06,"tv":17638.2,"id":9629022}]}]}
{"op":"mcm","clk":"4228293195","pt":1631460759543,"mc":[{"id":"1.187551081","rc":[{"batb":[[0,14.5,27.04],[1,14,2],[2,13.5,2]],"batl":[[0,24,20.06],[1,25,17.24],[2,26,29.54]],"ltp":14.5,"tv":1747.48,"id":7445998},{"batb":[[0,1.04,1171.57],[1,1.03,4986.88],[2,1.02,2159.67]],"batl":[[0,1.08,383.69],[1,1.09,268.5],[2,1.11,211.29]],"ltp":1.06,"tv":17638.2,"id":9629022}]}]}
{"op":"mcm","clk":"4228293553","pt":1631460761613,"mc":[{"id":"1.187551081","rc":[{"batl":[[0,1.06,231.58],[1,1.08,383.69],[2,1.09,268.5]],"ltp":1.06,"tv":17638.2,"id":9629022}]}]}
{"op":"mcm","clk":"4228293628","pt":1631460762125,"mc":[{"id":"1.187551081","rc":[{"batb":[[0,1.04,2468.36]],"batl":[[0,1.08,1632.44],[1,1.09,268.5],[2,1.11,211.29]],"ltp":1.06,"tv":17638.2,"id":9629022}]}]}
{"op":"mcm","clk":"4228293832","pt":1631460763421,"mc":[{"id":"1.187551081","rc":[{"batl":[[0,1.08,383.69],[2,1.17,29.65]],"ltp":1.06,"tv":17638.2,"id":9629022}]}]}
{"op":"mcm","clk":"4228293863","pt":1631460763695,"mc":[{"id":"1.187551081","rc":[{"batl":[[0,1.08,22],[1,1.17,29.65],[2,1.19,14.82]],"ltp":1.06,"tv":17638.2,"id":9629022}]}]}
{"op":"mcm","clk":"4228294293","pt":1631460766626,"mc":[{"id":"1.187551081","rc":[{"batb":[[0,15,2],[1,14.5,27.04]],"batl":[[0,25,17.24],[1,26,29.54],[2,36,2]],"ltp":14.5,"tv":1747.48,"id":7445998},{"batb":[[1,1.03,4924.88]],"batl":[[0,1.05,724.18],[1,1.06,554.97],[2,1.07,327.5]],"ltp":1.06,"tv":17638.2,"id":9629022}]}]}
{"op":"mcm","clk":"4228294391","pt":1631460767238,"mc":[{"id":"1.187551081","rc":[{"batb":[[0,20,22.61],[1,17.5,34],[2,15,2]],"ltp":14.5,"tv":1747.48,"id":7445998},{"trd":[[1.05,600]],"batb":[[2,1.02,6562.7]],"batl":[[0,1.05,424.18]],"ltp":1.05,"tv":18238.2,"id":9629022}],"tv":19985.68}]}
{"op":"mcm","clk":"4228294752","pt":1631460769619,"mc":[{"id":"1.187551081","rc":[{"batb":[[2,15,4]],"batl":[[0,24,2.91],[1,25,17.24],[2,26,29.54]],"ltp":14.5,"tv":1747.48,"id":7445998},{"batb":[[0,1.04,2607.12]],"batl":[[1,1.06,594.97],[2,1.07,356.5]],"ltp":1.05,"tv":18238.2,"id":9629022}]}]}
{"op":"mcm","clk":"4228294857","pt":1631460770239,"mc":[{"id":"1.187551081","rc":[{"batl":[[0,24,4.91]],"ltp":14.5,"tv":1747.48,"id":7445998},{"batl":[[0,1.05,558.39],[1,1.06,759.19]],"ltp":1.05,"tv":18238.2,"id":9629022}]}]}
{"op":"mcm","clk":"4228295260","pt":1631460772655,"mc":[{"id":"1.187551081","rc":[{"batb":[[0,21,3.26],[1,20,22.61],[2,17.5,34]],"ltp":14.5,"tv":1747.48,"id":7445998},{"batb":[[0,1.04,3173]],"batl":[[0,1.05,668.39],[1,1.06,1275.95]],"ltp":1.05,"tv":18238.2,"id":9629022}]}]}
{"op":"mcm","clk":"4228295382","pt":1631460773435,"mc":[{"id":"1.187551081","rc":[{"batb":[[2,17.5,36]],"ltp":14.5,"tv":1747.48,"id":7445998},{"batb":[[1,1.03,5486.75],[2,1.02,7224.34]],"batl":[[1,1.06,1640.7]],"ltp":1.05,"tv":18238.2,"id":9629022}]}]}
{"op":"mcm","clk":"4228296615","pt":1631460781541,"mc":[{"id":"1.187551081","rc":[{"batb":[[0,21,35.63],[2,17.5,80.89]],"batl":[[2,26,27.54]],"ltp":14.5,"tv":1747.48,"id":7445998},{"batl":[[0,1.05,1315.76],[1,1.06,2382.01],[2,1.07,327.5]],"ltp":1.05,"tv":18238.2,"id":9629022}]}]}
{"op":"mcm","clk":"4228297042","pt":1631460784454,"mc":[{"id":"1.187551081","rc":[{"batl":[[0,1.05,2070.24]],"ltp":1.05,"tv":18238.2,"id":9629022}]}]}
{"op":"mcm","clk":"4228297676","pt":1631460788649,"mc":[{"id":"1.187551081","rc":[{"batb":[[0,20,22.61],[1,17.5,36],[2,15,4]],"batl":[[0,24,2],[1,29,14.97],[2,30,21.45]],"ltp":14.5,"tv":1747.48,"id":7445998},{"batb":[[0,1.04,613.88],[1,1.03,4857.94],[2,1.02,6375.7]],"batl":[[0,1.05,754.48],[1,1.06,1523.03]],"ltp":1.05,"tv":18238.2,"id":9629022}]}]}
{"op":"mcm","clk":"4228297718","pt":1631460788936,"mc":[{"id":"1.187551081","rc":[{"batb":[[0,17.5,36],[1,15,4],[2,13.5,2]],"batl":[[0,29,14.97],[1,30,21.45],[2,32,22.8]],"ltp":14.5,"tv":1747.48,"id":7445998},{"batb":[[0,1.03,1393.7],[1,1.02,6375.7],[2,1.01,3424.33]],"batl":[[0,1.06,966.27],[1,1.07,327.5],[2,1.08,281.44]],"ltp":1.05,"tv":18238.2,"id":9629022}]}]}
{"op":"mcm","clk":"4228297977","pt":1631460790559,"mc":[{"id":"1.187551081","rc":[{"batl":[[0,1.06,619.8]],"ltp":1.05,"tv":18238.2,"id":9629022}]}]}
{"op":"mcm","clk":"4228298261","pt":1631460792137,"mc":[{"id":"1.187551081","rc":[{"batb":[[0,1.03,1466.7],[1,1.02,6489.7]],"ltp":1.05,"tv":18238.2,"id":9629022}]}]}
{"op":"mcm","clk":"4228298464","pt":1631460793442,"mc":[{"id":"1.187551081","rc":[{"batb":[[0,1.04,1317.16],[1,1.03,1466.7],[2,1.02,6489.7]],"batl":[[0,1.05,1047.85],[1,1.06,619.8],[2,1.07,327.5]],"ltp":1.05,"tv":18238.2,"id":9629022}]}]}
{"op":"mcm","clk":"4228298513","pt":1631460793761,"mc":[{"id":"1.187551081","rc":[{"batb":[[0,1.04,1296.79]],"batl":[[0,1.05,1026.95]],"ltp":1.05,"tv":18238.2,"id":9629022}]}]}
{"op":"mcm","clk":"4228298662","pt":1631460794685,"mc":[{"id":"1.187551081","rc":[{"batb":[[0,18.5,13.51],[1,17.5,36],[2,15,4]],"batl":[[0,28,6.21],[1,29,14.97],[2,30,21.45]],"ltp":14.5,"tv":1747.48,"id":7445998},{"batb":[[0,1.04,1400.17]],"batl":[[0,1.05,1135.09]],"ltp":1.05,"tv":18238.2,"id":9629022}]}]}
{"op":"mcm","clk":"4228299216","pt":1631460798579,"mc":[{"id":"1.187551081","rc":[{"batb":[[0,17.5,36],[1,15,4],[2,13.5,2]],"batl":[[0,29,14.97],[1,30,21.45],[2,32,22.8]],"ltp":14.5,"tv":1747.48,"id":7445998},{"batb":[[0,1.03,1466.7],[1,1.02,6489.7],[2,1.01,3424.33]],"batl":[[0,1.06,619.8],[1,1.07,327.5],[2,1.08,281.44]],"ltp":1.05,"tv":18238.2,"id":9629022}]}]}
{"op":"mcm","clk":"4228299642","pt":1631460801281,"mc":[{"id":"1.187551081","rc":[{"batb":[[0,1.03,2776.07]],"batl":[[0,1.06,966.27],[1,1.07,992.02]],"ltp":1.05,"tv":18238.2,"id":9629022}]}]}
{"op":"mcm","clk":"4228299739","pt":1631460801970,"mc":[{"id":"1.187551081","rc":[{"batl":[[0,21,1.38],[1,29,14.97],[2,30,21.45]],"ltp":14.5,"tv":1747.48,"id":7445998}]}]}
{"op":"mcm","clk":"4228301123","pt":1631460811160,"mc":[{"id":"1.187551081","rc":[{"batl":[[0,29,14.97],[1,30,21.45],[2,32,22.8]],"ltp":14.5,"tv":1747.48,"id":7445998},{"batb":[[1,1.02,6375.7]],"ltp":1.05,"tv":18238.2,"id":9629022}]}]}
{"op":"mcm","clk":"4228301716","pt":1631460814367,"mc":[{"id":"1.187551081","rc":[{"batl":[[0,27,1.38],[1,29,14.97],[2,30,21.45]],"ltp":14.5,"tv":1747.48,"id":7445998},{"batb":[[1,1.02,6483.7]],"ltp":1.05,"tv":18238.2,"id":9629022}]}]}
{"op":"mcm","clk":"4228302272","pt":1631460818091,"mc":[{"id":"1.187551081","rc":[{"batl":[[0,29,14.97],[1,30,21.45],[2,32,22.8]],"ltp":14.5,"tv":1747.48,"id":7445998}]}]}
{"op":"mcm","clk":"4228302465","pt":1631460819285,"mc":[{"id":"1.187551081","rc":[{"batb":[[2,4.1,377.07]],"ltp":14.5,"tv":1747.48,"id":7445998},{"batl":[[0,1.06,364.75],[1,1.15,14.82],[2,1.17,29.65]],"ltp":1.05,"tv":18238.2,"id":9629022}]}]}
{"op":"mcm","clk":"4228302917","pt":1631460822384,"mc":[{"id":"1.187551081","rc":[{"batl":[[0,32,22.8],[1,36,2],[2,55,2]],"ltp":14.5,"tv":1747.48,"id":7445998},{"batl":[[0,1.04,333.99],[1,1.05,953.62],[2,1.06,364.75]],"ltp":1.05,"tv":18238.2,"id":9629022}]}]}
{"op":"mcm","clk":"4228303101","pt":1631460823578,"mc":[{"id":"1.187551081","rc":[{"batb":[[0,24,12.53],[1,22,11.36],[2,21,19.41]],"batl":[[0,29,1.82],[1,32,22.8],[2,36,2]],"ltp":14.5,"tv":1747.48,"id":7445998},{"batb":[[0,1.03,2974.67],[1,1.02,2080.66]],"batl":[[1,1.05,1191.72]],"ltp":1.05,"tv":18238.2,"id":9629022}]}]}
{"op":"mcm","clk":"4228303261","pt":1631460824494,"mc":[{"id":"1.187551081","rc":[{"batb":[[1,21,19.41],[2,17.5,2]],"batl":[[0,32,22.8],[1,36,2],[2,55,2]],"ltp":14.5,"tv":1747.48,"id":7445998},{"batl":[[1,1.05,953.62]],"ltp":1.05,"tv":18238.2,"id":9629022}]}]}
{"op":"mcm","clk":"4228303442","pt":1631460825468,"mc":[{"id":"1.187551081","rc":[{"batb":[[2,18,2]],"batl":[[0,30,2],[1,32,22.8],[2,36,2]],"ltp":14.5,"tv":1747.48,"id":7445998},{"batl":[[1,1.05,987.62]],"ltp":1.05,"tv":18238.2,"id":9629022}]}]}
{"op":"mcm","clk":"4228303710","pt":1631460827074,"mc":[{"id":"1.187551081","rc":[{"batb":[[0,25,11.36],[1,24,12.53],[2,21,19.41]],"batl":[[0,29,1.82],[1,30,2],[2,32,22.8]],"ltp":14.5,"tv":1747.48,"id":7445998},{"batb":[[0,1.03,3709.77],[1,1.02,1972.66]],"batl":[[0,1.04,572.09],[1,1.05,1708.71]],"ltp":1.05,"tv":18238.2,"id":9629022}]}]}
{"op":"mcm","clk":"4228303927","pt":1631460828360,"mc":[{"id":"1.187551081","rc":[{"batb":[[0,24,12.53],[1,21,21.41],[2,18,2]],"ltp":14.5,"tv":1747.48,"id":7445998},{"batl":[[0,1.04,391.31],[1,1.05,2210.21]],"ltp":1.05,"tv":18238.2,"id":9629022}]}]}
{"op":"mcm","clk":"4228304025","pt":1631460829041,"mc":[{"id":"1.187551081","rc":[{"batl":[[0,29,3.82]],"ltp":14.5,"tv":1747.48,"id":7445998},{"batb":[[0,1.03,4294.18],[1,1.02,2736.76],[2,1.01,4709.13]],"ltp":1.05,"tv":18238.2,"id":9629022}]}]}
{"op":"mcm","clk":"4228304845","pt":1631460834216,"mc":[{"id":"1.187551081","rc":[{"batb":[[0,25,4.13],[1,24,12.53],[2,21,21.41]],"ltp":14.5,"tv":1747.48,"id":7445998}]}]}
{"op":"mcm","clk":"4228305074","pt":1631460835619,"mc":[{"id":"1.187551081","rc":[{"batb":[[0,21,21.41],[1,18,2],[2,17.5,4]],"batl":[[0,34,17.78],[1,36,15.71],[2,38,16.32]],"ltp":14.5,"tv":1747.48,"id":7445998},{"batb":[[0,1.03,2350.21],[1,1.02,2075.12],[2,1.01,3661.08]],"batl":[[0,1.05,1489.12],[1,1.06,364.75],[2,1.07,389.5]],"ltp":1.05,"tv":18238.2,"id":9629022}]}]}
{"op":"mcm","clk":"4228305086","pt":1631460835747,"mc":[{"id":"1.187551081","rc":[{"batl":[[1,36,13.71]],"ltp":14.5,"tv":1747.48,"id":7445998},{"batb":[[0,1.03,1518.38]],"ltp":1.05,"tv":18238.2,"id":9629022}]}]}
{"op":"mcm","clk":"4228305472","pt":1631460838529,"mc":[{"id":"1.187551081","rc":[{"batb":[[2,17.5,2]],"ltp":14.5,"tv":1747.48,"id":7445998},{"batb":[[1,1.02,2454.2]],"batl":[[0,1.05,1819.94]],"ltp":1.05,"tv":18238.2,"id":9629022}]}]}
{"op":"mcm","clk":"4228305509","pt":1631460838824,"mc":[{"id":"1.187551081","rc":[{"batb":[[0,24,2],[1,23,2],[2,21,23.41]],"ltp":14.5,"tv":1747.48,"id":7445998}]}]}
{"op":"mcm","clk":"4228305747","pt":1631460840408,"mc":[{"id":"1.187551081","rc":[{"batb":[[1,1.02,2075.12]],"batl":[[0,1.05,1156.72]],"ltp":1.05,"tv":18238.2,"id":9629022}]}]}
{"op":"mcm","clk":"4228306275","pt":1631460843592,"mc":[{"id":"1.187551081","rc":[{"batb":[[0,1.03,1912.61]],"batl":[[0,1.04,688.72],[1,1.05,1156.72],[2,1.06,364.75]],"ltp":1.05,"tv":18238.2,"id":9629022}]}]}
{"op":"mcm","clk":"4228306323","pt":1631460843939,"mc":[{"id":"1.187551081","rc":[{"batb":[[0,1.03,1893.78]],"batl":[[0,1.04,669.59]],"ltp":1.05,"tv":18238.2,"id":9629022}]}]}
{"op":"mcm","clk":"4228306574","pt":1631460845640,"mc":[{"id":"1.187551081","rc":[{"batb":[[0,25,5.29],[1,24,2],[2,23,2]],"batl":[[0,32,3.8],[1,34,17.78],[2,36,13.71]],"ltp":14.5,"tv":1747.48,"id":7445998},{"batb":[[0,1.03,2071.63]],"batl":[[0,1.04,753.75]],"ltp":1.05,"tv":18238.2,"id":9629022}]}]}
{"op":"mcm","clk":"4228306816","pt":1631460847142,"mc":[{"id":"1.187551081","rc":[{"batl":[[0,1.04,787.91]],"ltp":1.05,"tv":18238.2,"id":9629022}]}]}
{"op":"mcm","clk":"4228306929","pt":1631460847748,"mc":[{"id":"1.187551081","rc":[{"batb":[[0,24,2],[1,23,2],[2,21,23.41]],"batl":[[0,34,17.78],[1,36,13.71],[2,38,16.32]],"ltp":14.5,"tv":1747.48,"id":7445998},{"batb":[[0,1.03,1518.38]],"batl":[[0,1.04,34.16]],"ltp":1.05,"tv":18238.2,"id":9629022}]}]}
{"op":"mcm","clk":"4228307442","pt":1631460850653,"mc":[{"id":"1.187551081","rc":[{"batb":[[1,1.02,2454.2]],"batl":[[1,1.05,1819.94]],"ltp":1.05,"tv":18238.2,"id":9629022}]}]}
{"op":"mcm","clk":"4228307503","pt":1631460850932,"mc":[{"id":"1.187551081","rc":[{"batb":[[1,21,21.41],[2,17.5,2]],"ltp":14.5,"tv":1747.48,"id":7445998}]}]}
{"op":"mcm","clk":"4228307743","pt":1631460852345,"mc":[{"id":"1.187551081","rc":[{"batl":[[1,1.05,535.5]],"ltp":1.05,"tv":18238.2,"id":9629022}]}]}
{"op":"mcm","clk":"4228308054","pt":1631460854158,"mc":[{"id":"1.187551081","rc":[{"batb":[[1,23,2],[2,21,21.41]],"ltp":14.5,"tv":1747.48,"id":7445998}]}]}
{"op":"mcm","clk":"4228308294","pt":1631460855658,"mc":[{"id":"1.187551081","rc":[{"batb":[[0,25,2],[1,24,2],[2,23,2]],"ltp":14.5,"tv":1747.48,"id":7445998},{"batb":[[0,1.03,1551.38],[1,1.02,2482.2]],"batl":[[0,1.04,1330.95]],"ltp":1.05,"tv":18238.2,"id":9629022}]}]}
{"op":"mcm","clk":"4228308397","pt":1631460856248,"mc":[{"id":"1.187551081","rc":[{"batb":[[0,28,13.47],[1,25,2],[2,24,2]],"ltp":14.5,"tv":1747.48,"id":7445998},{"batb":[[0,1.03,1602.59]],"batl":[[0,1.04,1501.75]],"ltp":1.05,"tv":18238.2,"id":9629022}]}]}
{"op":"mcm","clk":"4228308955","pt":1631460859627,"mc":[{"id":"1.187551081","rc":[{"batb":[[0,29,4.33],[1,28,13.47],[2,25,2]],"ltp":14.5,"tv":1747.48,"id":7445998},{"batb":[[0,1.03,2352.84]],"batl":[[0,1.04,2244.79]],"ltp":1.05,"tv":18238.2,"id":9629022}]}]}
{"op":"mcm","clk":"4228311112","pt":1631460873662,"mc":[{"id":"1.187551081","rc":[{"trd":[[1.04,500]],"batl":[[0,1.04,1994.79]],"ltp":1.04,"tv":18738.2,"id":9629022}],"tv":20485.68}]}
{"op":"mcm","clk":"4228311212","pt":1631460874276,"mc":[{"id":"1.187551081","rc":[{"batb":[[1,1.02,2332.44]],"ltp":1.04,"tv":18738.2,"id":9629022}]}]}
{"op":"mcm","clk":"4228311756","pt":1631460877456,"mc":[{"id":"1.187551081","rc":[{"batb":[[0,1.03,2473.42],[1,1.02,2435.44]],"batl":[[0,1.04,2210.63]],"ltp":1.04,"tv":18738.2,"id":9629022}]}]}
{"op":"mcm","clk":"4228311915","pt":1631460878662,"mc":[{"id":"1.187551081","rc":[{"trd":[[29,6]],"batb":[[0,28,13.47],[1,25,2],[2,23,15.09]],"ltp":29.0,"tv":1753.48,"id":7445998}],"tv":20491.68}]}
{"op":"mcm","clk":"4228311992","pt":1631460879188,"mc":[{"id":"1.187551081","rc":[{"trd":[[1.04,600]],"batb":[[1,1.02,2407.23]],"batl":[[0,1.04,2160.63]],"ltp":1.04,"tv":18838.2,"id":9629022}],"tv":20591.68}]}
{"op":"mcm","clk":"4228312361","pt":1631460881636,"mc":[{"id":"1.187551081","rc":[{"batl":[[0,34,19.31]],"ltp":29.0,"tv":1753.48,"id":7445998}]}]}
{"op":"mcm","clk":"4228312443","pt":1631460882120,"mc":[{"id":"1.187551081","rc":[{"batb":[[0,1.03,2501.36]],"batl":[[0,1.04,2210.63]],"ltp":1.04,"tv":18838.2,"id":9629022}]}]}
{"op":"mcm","clk":"4228312566","pt":1631460882825,"mc":[{"id":"1.187551081","rc":[{"batb":[[0,29,4.03],[1,28,13.47],[2,25,2]],"ltp":29.0,"tv":1753.48,"id":7445998}]}]}
{"op":"mcm","clk":"4228313733","pt":1631460890446,"mc":[{"id":"1.187551081","rc":[{"batb":[[0,1.03,2518.44],[1,1.02,2304.23]],"ltp":1.04,"tv":18838.2,"id":9629022}]}]}
{"op":"mcm","clk":"4228313865","pt":1631460891139,"mc":[{"id":"1.187551081","rc":[{"trd":[[1.04,627.56]],"batl":[[0,1.04,2196.85]],"ltp":1.04,"tv":18865.75,"id":9629022}],"tv":20619.24}]}
{"op":"mcm","clk":"4228314042","pt":1631460892168,"mc":[{"id":"1.187551081","rc":[{"batb":[[0,1.03,1435.95]],"batl":[[0,1.04,913.84]],"ltp":1.04,"tv":18865.75,"id":9629022}]}]}
{"op":"mcm","clk":"4228314278","pt":1631460893647,"mc":[{"id":"1.187551081","rc":[{"batb":[[1,1.02,2403.23]],"ltp":1.04,"tv":18865.75,"id":9629022}]}]}
{"op":"mcm","clk":"4228314315","pt":1631460893853,"mc":[{"id":"1.187551081","rc":[{"trd":[[1.03,452.61],[1.04,630.76]],"batb":[[0,1.03,1209.65]],"batl":[[0,1.04,912.24]],"ltp":1.03,"tv":19321.56,"id":9629022}],"tv":21075.04}]}
{"op":"mcm","clk":"4228314512","pt":1631460895143,"mc":[{"id":"1.187551081","rc":[{"batb":[[2,26,26.13]],"ltp":29.0,"tv":1753.48,"id":7445998},{"batb":[[1,1.02,3496.33]],"batl":[[0,1.04,1565.58],[1,1.05,2494.63]],"ltp":1.03,"tv":19321.56,"id":9629022}]}]}
{"op":"mcm","clk":"4228314775","pt":1631460896794,"mc":[{"id":"1.187551081","rc":[{"batl":[[1,1.05,3139.2]],"ltp":1.03,"tv":19321.56,"id":9629022}]}]}
{"op":"mcm","clk":"4228316854","pt":1631460909590,"mc":[{"id":"1.187551081","rc":[{"batb":[[0,28,13.47],[1,23,15.09],[2,21,2]],"batl":[[0,55,2],[1,110,2],[2,990,0.01]],"ltp":29.0,"tv":1753.48,"id":7445998},{"batb":[[0,1.03,17.08],[1,1.02,2732.23],[2,1.01,2376.27]],"batl":[[0,1.05,1785.94],[1,1.06,364.75],[2,1.13,11.86]],"ltp":1.03,"tv":19321.56,"id":9629022}]}]}
{"op":"mcm","clk":"4228316903","pt":1631460909892,"mc":[{"id":"1.187551081","rc":[{"batb":[[0,23,15.09],[1,21,2],[2,17.5,2]],"ltp":29.0,"tv":1753.48,"id":7445998}]}]}
{"op":"mcm","clk":"4228317203","pt":1631460911582,"mc":[{"id":"1.187551081","rc":[{"batb":[[1,1.02,1639.13]],"batl":[[0,1.05,501.5]],"ltp":1.03,"tv":19321.56,"id":9629022}]}]}
{"op":"mcm","clk":"4228317405","pt":1631460912584,"mc":[{"id":"1.187551081","rc":[{"batb":[[1,17.5,2],[2,4.1,377.07]],"ltp":29.0,"tv":1753.48,"id":7445998},{"trd":[[1.03,453.38]],"batb":[[0,1.03,16.7],[1,1.02,99]],"batl":[[0,1.06,364.75],[1,1.13,11.86],[2,1.15,14.82]],"ltp":1.03,"tv":19322.33,"id":9629022}],"tv":21075.82}]}
{"op":"mcm","clk":"4228317774","pt":1631460914557,"mc":[{"id":"1.187551081","rc":[{"batb":[[0,1.03,58.53]],"batl":[[0,1.04,38.13],[1,1.06,364.75],[2,1.13,11.86]],"ltp":1.03,"tv":19322.33,"id":9629022}]}]}
{"op":"mcm","clk":"4228317884","pt":1631460915279,"mc":[{"id":"1.187551081","rc":[{"batb":[[1,21,2],[2,17.5,2]],"batl":[[0,55,4]],"ltp":29.0,"tv":1753.48,"id":7445998},{"batb":[[0,1.03,1326.07],[1,1.02,1346.65]],"batl":[[0,1.04,1296.79],[1,1.05,533.5],[2,1.06,384.75]],"ltp":1.03,"tv":19322.33,"id":9629022}]}]}
{"op":"mcm","clk":"4228318078","pt":1631460916596,"mc":[{"id":"1.187551081","rc":[{"batb":[[0,24,10.42],[1,23,15.09],[2,21,2]],"batl":[[0,38,5.44],[1,55,4],[2,110,2]],"ltp":29.0,"tv":1753.48,"id":7445998},{"batb":[[0,1.03,1409.57]],"batl":[[1,1.05,771.6]],"ltp":1.03,"tv":19322.33,"id":9629022}]}]}
{"op":"mcm","clk":"4228318126","pt":1631460916892,"mc":[{"id":"1.187551081","rc":[{"batl":[[1,1.05,533.5]],"ltp":1.03,"tv":19322.33,"id":9629022}]}]}
{"op":"mcm","clk":"4228318419","pt":1631460918472,"mc":[{"id":"1.187551081","rc":[{"batb":[[0,1.03,2039.43]],"batl":[[0,1.04,1903.94]],"ltp":1.03,"tv":19322.33,"id":9629022}]}]}
{"op":"mcm","clk":"4228318575","pt":1631460919486,"mc":[{"id":"1.187551081","rc":[{"trd":[[1.04,1635.62]],"batl":[[0,1.04,1401.51]],"ltp":1.04,"tv":20327.19,"id":9629022}],"tv":22080.67}]}
{"op":"mcm","clk":"4228318662","pt":1631460919995,"mc":[{"id":"1.187551081","rc":[{"batl":[[0,1.04,1639.61]],"ltp":1.04,"tv":20327.19,"id":9629022}]}]}
{"op":"mcm","clk":"4228318907","pt":1631460921695,"mc":[{"id":"1.187551081","rc":[{"batb":[[0,1.03,730.06]],"batl":[[0,1.04,845.25]],"ltp":1.04,"tv":20327.19,"id":9629022}]}]}
{"op":"mcm","clk":"4228319200","pt":1631460923613,"mc":[{"id":"1.187551081","rc":[{"batb":[[0,23,15.09],[1,21,2],[2,17.5,2]],"batl":[[0,55,4],[1,110,2],[2,990,0.01]],"ltp":29.0,"tv":1753.48,"id":7445998},{"batb":[[0,1.03,646.56]],"batl":[[0,1.04,607.15]],"ltp":1.04,"tv":20327.19,"id":9629022}]}]}
{"op":"mcm","clk":"4228319354","pt":1631460924609,"mc":[{"id":"1.187551081","rc":[{"batl":[[0,55,2]],"ltp":29.0,"tv":1753.48,"id":7445998},{"batb":[[0,1.03,16.7],[1,1.02,1421.21]],"batl":[[0,1.05,1817.94],[1,1.06,384.75],[2,1.13,11.86]],"ltp":1.04,"tv":20327.19,"id":9629022}]}]}
{"op":"mcm","clk":"4228319863","pt":1631460927626,"mc":[{"id":"1.187551081","rc":[{"batl":[[0,55,4]],"ltp":29.0,"tv":1753.48,"id":7445998},{"batb":[[1,1.02,2666.17]],"ltp":1.04,"tv":20327.19,"id":9629022}]}]}
{"op":"mcm","clk":"4228319937","pt":1631460928009,"mc":[{"id":"1.187551081","rc":[{"batb":[[0,1.04,10],[1,1.03,16.7],[2,1.02,2666.17]],"ltp":1.04,"tv":20327.19,"id":9629022}]}]}
{"op":"mcm","clk":"4228320260","pt":1631460930019,"mc":[{"id":"1.187551081","rc":[{"batl":[[0,1.05,533.5]],"ltp":1.04,"tv":20327.19,"id":9629022}]}]}
{"op":"mcm","clk":"4228320878","pt":1631460933629,"mc":[{"id":"1.187551081","rc":[{"batb":[[0,26,17.23]],"ltp":29.0,"tv":1753.48,"id":7445998},{"trd":[[1.03,486.78],[1.04,1655.62]],"batb":[[0,1.02,2666.17],[1,1.01,2376.27],[2,1.02,0]],"batl":[[0,1.03,463.74],[1,1.04,811.05],[2,1.05,533.5]],"ltp":1.03,"tv":20380.59,"id":9629022}],"tv":22134.07}]}
{"op":"mcm","clk":"4228320969","pt":1631460934118,"mc":[{"id":"1.187551081","rc":[{"batb":[[0,30,8.33],[1,26,17.23],[2,21,2]],"batl":[[0,48,4.34],[1,55,4],[2,110,2]],"ltp":29.0,"tv":1753.48,"id":7445998}]}]}
{"op":"mcm","clk":"4228321357","pt":1631460936325,"mc":[{"id":"1.187551081","rc":[{"batb":[[2,24,2]],"batl":[[1,50,2],[2,55,4]],"ltp":29.0,"tv":1753.48,"id":7445998},{"batb":[[0,1.02,2911.27]],"batl":[[1,1.04,823.05]],"ltp":1.03,"tv":20380.59,"id":9629022}]}]}
{"op":"mcm","clk":"4228321587","pt":1631460937621,"mc":[{"id":"1.187551081","rc":[{"batl":[[0,46,2],[1,48,4.34],[2,50,2]],"ltp":29.0,"tv":1753.48,"id":7445998},{"batb":[[0,1.02,3460.45]],"batl":[[0,1.03,578.1],[1,1.04,2272.41]],"ltp":1.03,"tv":20380.59,"id":9629022}]}]}
{"op":"mcm","clk":"4228321638","pt":1631460937929,"mc":[{"id":"1.187551081","rc":[{"batl":[[1,50,2],[2,55,4]],"ltp":29.0,"tv":1753.48,"id":7445998},{"batl":[[1,1.04,1311.88]],"ltp":1.03,"tv":20380.59,"id":9629022}]}]}
{"op":"mcm","clk":"4228321834","pt":1631460939222,"mc":[{"id":"1.187551081","rc":[{"batb":[[1,26,21.23]],"ltp":29.0,"tv":1753.48,"id":7445998},{"batl":[[1,1.04,1963.14],[2,1.05,539.2]],"ltp":1.03,"tv":20380.59,"id":9629022}]}]}
{"op":"mcm","clk":"4228322017","pt":1631460940324,"mc":[{"id":"1.187551081","rc":[{"batl":[[0,44,2],[1,46,2],[2,50,2]],"ltp":29.0,"tv":1753.48,"id":7445998}]}]}
{"op":"mcm","clk":"4228322270","pt":1631460941846,"mc":[{"id":"1.187551081","rc":[{"trd":[[1.02,34.16]],"batb":[[0,1.02,3443.37]],"ltp":1.02,"tv":20414.75,"id":9629022}],"tv":22168.23}]}
{"op":"mcm","clk":"4228322527","pt":1631460943397,"mc":[{"id":"1.187551081","rc":[{"batl":[[0,42,2],[1,44,2],[2,46,2]],"ltp":29.0,"tv":1753.48,"id":7445998}]}]}
{"op":"mcm","clk":"4228322691","pt":1631460944402,"mc":[{"id":"1.187551081","rc":[{"batl":[[0,42,6.34]],"ltp":29.0,"tv":1753.48,"id":7445998}]}]}
{"op":"mcm","clk":"4228323602","pt":1631460950209,"mc":[{"id":"1.187551081","rc":[{"batl":[[2,55,2]],"ltp":29.0,"tv":1753.48,"id":7445998}]}]}
{"op":"mcm","clk":"4228323773","pt":1631460951295,"mc":[{"id":"1.187551081","rc":[{"batb":[[0,26,21.23],[1,24,2],[2,21,2]],"batl":[[0,55,2],[1,110,2],[2,990,0.01]],"ltp":29.0,"tv":1753.48,"id":7445998},{"batb":[[0,1.02,2567.17]],"batl":[[0,1.04,1462.31],[1,1.05,539.2],[2,1.06,370.5]],"ltp":1.02,"tv":20414.75,"id":9629022}]}]}
{"op":"mcm","clk":"4228324035","pt":1631460952689,"mc":[{"id":"1.187551081","rc":[{"batl":[[0,1.03,42.7],[1,1.04,1462.31],[2,1.05,539.2]],"ltp":1.02,"tv":20414.75,"id":9629022}]}]}
{"op":"mcm","clk":"4228324187","pt":1631460953708,"mc":[{"id":"1.187551081","rc":[{"batl":[[1,1.04,1860.17]],"ltp":1.02,"tv":20414.75,"id":9629022}]}]}
{"op":"mcm","clk":"4228324857","pt":1631460957971,"mc":[{"id":"1.187551081","rc":[{"trd":[[1.03,572.18],[1.04,1770.22]],"batl":[[0,1.04,1802.87],[1,1.05,539.2],[2,1.06,370.5]],"ltp":1.04,"tv":20614.75,"id":9629022}],"tv":22368.23}]}
{"op":"mcm","clk":"4228325413","pt":1631460961593,"mc":[{"id":"1.187551081","rc":[{"trd":[[1.04,1810.22]],"batl":[[0,1.04,1808.5]],"ltp":1.04,"tv":20654.75,"id":9629022}],"tv":22408.23}]}
{"op":"mcm","clk":"4228325596","pt":1631460962676,"mc":[{"id":"1.187551081","rc":[{"batb":[[2,4.1,377.07]],"ltp":29.0,"tv":1753.48,"id":7445998},{"batl":[[0,1.04,651.26],[1,1.05,5.7],[2,1.06,5.75]],"ltp":1.04,"tv":20654.75,"id":9629022}]}]}
{"op":"mcm","clk":"4228326150","pt":1631460965624,"mc":[{"id":"1.187551081","rc":[{"batb":[[0,34,2],[1,26,21.23],[2,24,2]],"ltp":29.0,"tv":1753.48,"id":7445998},{"batl":[[0,1.03,1315.21],[1,1.04,651.26],[2,1.05,5.7]],"ltp":1.04,"tv":20654.75,"id":9629022}]}]}
{"op":"mcm","clk":"4228326335","pt":1631460966518,"mc":[{"id":"1.187551081","rc":[{"batb":[[1,30,8.04],[2,26,21.23]],"batl":[[0,55,4]],"ltp":29.0,"tv":1753.48,"id":7445998},{"batb":[[0,1.02,2652.17],[1,1.01,2572.27]],"ltp":1.04,"tv":20654.75,"id":9629022}]}]}
{"op":"mcm","clk":"4228326393","pt":1631460966833,"mc":[{"id":"1.187551081","rc":[{"batb":[[0,36,6.94],[1,34,2],[2,30,8.04]],"batl":[[0,50,2.02],[1,55,4],[2,110,2]],"ltp":29.0,"tv":1753.48,"id":7445998},{"batb":[[0,1.02,2768.68]],"batl":[[0,1.03,1557.93]],"ltp":1.04,"tv":20654.75,"id":9629022}]}]}
{"op":"mcm","clk":"4228326733","pt":1631460969023,"mc":[{"id":"1.187551081","rc":[{"batl":[[0,50,2]],"ltp":29.0,"tv":1753.48,"id":7445998},{"batl":[[1,1.04,645.38],[2,1.06,15.05]],"ltp":1.04,"tv":20654.75,"id":9629022}]}]}
{"op":"mcm","clk":"4228326981","pt":1631460970590,"mc":[{"id":"1.187551081","rc":[{"batb":[[0,1.02,3466.63]],"batl":[[0,1.03,2249.1]],"ltp":1.04,"tv":20654.75,"id":9629022}]}]}
{"op":"mcm","clk":"4228327219","pt":1631460972138,"mc":[{"id":"1.187551081","rc":[{"batl":[[0,48,2.02],[1,50,2],[2,55,4]],"ltp":29.0,"tv":1753.48,"id":7445998},{"batl":[[1,1.04,651.51],[2,1.05,525.8]],"ltp":1.04,"tv":20654.75,"id":9629022}]}]}
{"op":"mcm","clk":"4228327755","pt":1631460975314,"mc":[{"id":"1.187551081","rc":[{"batb":[[1,34,4]],"ltp":29.0,"tv":1753.48,"id":7445998},{"batl":[[0,1.03,3064.6]],"ltp":1.04,"tv":20654.75,"id":9629022}]}]}
{"op":"mcm","clk":"4228328118","pt":1631460977625,"mc":[{"id":"1.187551081","rc":[{"batb":[[0,34,4],[1,30,8.04],[2,26,4]],"batl":[[0,110,2],[1,990,0.01],[2,55,0]],"ltp":29.0,"tv":1753.48,"id":7445998},{"batb":[[0,1.02,849.84]],"batl":[[0,1.03,821.34]],"ltp":1.04,"tv":20654.75,"id":9629022}]}]}
{"op":"mcm","clk":"4228328179","pt":1631460977936,"mc":[{"id":"1.187551081","rc":[{"batb":[[0,34,2]],"ltp":29.0,"tv":1753.48,"id":7445998},{"batl":[[0,1.03,5.84]],"ltp":1.04,"tv":20654.75,"id":9629022}]}]}
{"op":"mcm","clk":"4228328560","pt":1631460980313,"mc":[{"id":"1.187551081","rc":[{"batb":[[1,1.01,3049.31]],"batl":[[1,1.04,1948.3]],"ltp":1.04,"tv":20654.75,"id":9629022}]}]}
{"op":"mcm","clk":"4228328735","pt":1631460981405,"mc":[{"id":"1.187551081","rc":[{"batb":[[2,26,2]],"batl":[[0,990,0.01],[1,990,0]],"ltp":29.0,"tv":1753.48,"id":7445998},{"batb":[[1,1.01,226]],"batl":[[1,1.04,645.38],[2,1.09,11.86]],"ltp":1.04,"tv":20654.75,"id":9629022}]}]}
{"op":"mcm","clk":"4228329257","pt":1631460984533,"mc":[{"id":"1.187551081","rc":[{"batb":[[0,1.02,2120.82]],"batl":[[0,1.03,1315.21],[1,1.04,1428.63]],"ltp":1.04,"tv":20654.75,"id":9629022}]}]}
{"op":"mcm","clk":"4228329647","pt":1631460987252,"mc":[{"id":"1.187551081","rc":[{"batl":[[0,1.03,2071.44]],"ltp":1.04,"tv":20654.75,"id":9629022}]}]}
{"op":"mcm","clk":"4228330331","pt":1631460991546,"mc":[{"id":"1.187551081","rc":[{"batb":[[0,1.02,849.84]],"batl":[[0,1.03,5.84],[1,1.04,645.38]],"ltp":1.04,"tv":20654.75,"id":9629022}]}]}
{"op":"mcm","clk":"4228330495","pt":1631460992555,"mc":[{"id":"1.187551081","rc":[{"batb":[[0,30,8.04],[1,26,2],[2,24,2]],"ltp":29.0,"tv":1753.48,"id":7445998},{"batl":[[0,1.04,645.38],[1,1.09,11.86],[2,1.11,11.86]],"ltp":1.04,"tv":20654.75,"id":9629022}]}]}
{"op":"mcm","clk":"4228330796","pt":1631460994456,"mc":[{"id":"1.187551081","rc":[{"batb":[[1,1.01,703.04]],"batl":[[0,1.04,1942.17]],"ltp":1.04,"tv":20654.75,"id":9629022}]}]}
{"op":"mcm","clk":"4228331168","pt":1631460996645,"mc":[{"id":"1.187551081","rc":[{"batb":[[0,30,10.04],[1,29,2],[2,26,2]],"ltp":29.0,"tv":1753.48,"id":7445998},{"batl":[[0,1.03,8169.78],[1,1.04,698.38],[2,1.09,11.86]],"ltp":1.04,"tv":20654.75,"id":9629022}]}]}
{"op":"mcm","clk":"4228331203","pt":1631460996853,"mc":[{"id":"1.187551081","rc":[{"batl":[[1,1.04,53]],"ltp":1.04,"tv":20654.75,"id":9629022}]}]}
{"op":"mcm","clk":"4228331606","pt":1631460999650,"mc":[{"id":"1.187551081","rc":[{"batl":[[0,1.03,9479.15]],"ltp":1.04,"tv":20654.75,"id":9629022}]}]}
{"op":"mcm","clk":"4228331724","pt":1631461000459,"mc":[{"id":"1.187551081","rc":[{"batl":[[0,1.03,1309.37],[2,1.05,15.19]],"ltp":1.04,"tv":20654.75,"id":9629022}]}]}
{"op":"mcm","clk":"4228331824","pt":1631461001155,"mc":[{"id":"1.187551081","rc":[{"batb":[[0,40,6.25],[1,30,10.04],[2,29,2]],"ltp":29.0,"tv":1753.48,"id":7445998},{"batl":[[0,1.03,1552.09]],"ltp":1.04,"tv":20654.75,"id":9629022}]}]}
{"op":"mcm","clk":"4228332151","pt":1631461003360,"mc":[{"id":"1.187551081","rc":[{"batb":[[1,36,2],[2,34,2]],"batl":[[0,100,2],[1,990,0.01]],"ltp":29.0,"tv":1753.48,"id":7445998}]}]}
{"op":"mcm","clk":"4228332348","pt":1631461004651,"mc":[{"id":"1.187551081","rc":[{"batb":[[0,1.02,1535.55]],"batl":[[0,1.03,2231.14]],"ltp":1.04,"tv":20654.75,"id":9629022}]}]}
{"op":"mcm","clk":"4228332654","pt":1631461006565,"mc":[{"id":"1.187551081","rc":[{"batl":[[0,55,1.05],[1,100,2],[2,990,0.01]],"ltp":29.0,"tv":1753.48,"id":7445998}]}]}
{"op":"mcm","clk":"4228332769","pt":1631461007265,"mc":[{"id":"1.187551081","rc":[{"batl":[[0,95,2]],"ltp":29.0,"tv":1753.48,"id":7445998}]}]}
{"op":"mcm","clk":"4228333251","pt":1631461010386,"mc":[{"id":"1.187551081","rc":[{"batl":[[0,90,2],[1,95,2],[2,100,2]],"ltp":29.0,"tv":1753.48,"id":7445998}]}]}
{"op":"mcm","clk":"4228333449","pt":1631461011575,"mc":[{"id":"1.187551081","rc":[{"batb":[[0,36,2],[1,34,2],[2,30,8.04]],"ltp":29.0,"tv":1753.48,"id":7445998},{"batb":[[0,1.01,703.04],[1,1.01,0]],"batl":[[0,1.03,1309.37]],"ltp":1.04,"tv":20654.75,"id":9629022}]}]}
{"op":"mcm","clk":"4228333498","pt":1631461011897,"mc":[{"id":"1.187551081","rc":[{"batb":[[0,30,8.04],[1,4.1,377.07],[2,1.01,30]],"ltp":29.0,"tv":1753.48,"id":7445998},{"batl":[[2,1.09,11.86]],"ltp":1.04,"tv":20654.75,"id":9629022}]}]}
{"op":"mcm","clk":"4228333693","pt":1631461013279,"mc":[{"id":"1.187551081","rc":[{"batl":[[0,85,2],[1,90,2],[2,95,2]],"ltp":29.0,"tv":1753.48,"id":7445998}]}]}
{"op":"mcm","clk":"4228333869","pt":1631461014272,"mc":[{"id":"1.187551081","rc":[{"batb":[[0,1.01,1561.3]],"ltp":1.04,"tv":20654.75,"id":9629022}]}]}
{"op":"mcm","clk":"4228333969","pt":1631461014868,"mc":[{"id":"1.187551081","rc":[{"batb":[[0,30,10.04],[1,29,2],[2,4.1,377.07]],"ltp":29.0,"tv":1753.48,"id":7445998}]}]}
{"op":"mcm","clk":"4228334234","pt":1631461016494,"mc":[{"id":"1.187551081","rc":[{"batl":[[0,1.03,963.42]],"ltp":1.04,"tv":20654.75,"id":9629022}]}]}
{"op":"mcm","clk":"4228334342","pt":1631461017197,"mc":[{"id":"1.187551081","rc":[{"batb":[[0,30,2]],"ltp":29.0,"tv":1753.48,"id":7445998},{"batl":[[2,1.05,17.08]],"ltp":1.04,"tv":20654.75,"id":9629022}]}]}
{"op":"mcm","clk":"4228334663","pt":1631461019085,"mc":[{"id":"1.187551081","rc":[{"batl":[[2,990,0.01]],"ltp":29.0,"tv":1753.48,"id":7445998},{"batl":[[0,1.02,349.34],[1,1.03,963.42],[2,1.04,53]],"ltp":1.04,"tv":20654.75,"id":9629022}]}]}
{"op":"mcm","clk":"4228334862","pt":1631461020401,"mc":[{"id":"1.187551081","rc":[{"batb":[[0,46,5.43],[1,36,2],[2,34,2]],"batl":[[0,75,3.06],[1,80,2],[2,85,2]],"ltp":29.0,"tv":1753.48,"id":7445998},{"batb":[[0,1.01,1808.82]],"batl":[[0,1.02,487.56]],"ltp":1.04,"tv":20654.75,"id":9629022}]}]}
{"op":"mcm","clk":"4228335384","pt":1631461023597,"mc":[{"id":"1.187551081","rc":[{"batl":[[0,70,2]],"ltp":29.0,"tv":1753.48,"id":7445998},{"batb":[[0,1.01,2402.91]],"batl":[[1,1.03,1510.77]],"ltp":1.04,"tv":20654.75,"id":9629022}]}]}
{"op":"mcm","clk":"4228335823","pt":1631461026290,"mc":[{"id":"1.187551081","rc":[{"batl":[[0,65,5.06],[1,70,2],[2,80,2]],"ltp":29.0,"tv":1753.48,"id":7445998}]}]}
{"op":"mcm","clk":"4228336281","pt":1631461029290,"mc":[{"id":"1.187551081","rc":[{"batl":[[1,70,3.38]],"ltp":29.0,"tv":1753.48,"id":7445998}]}]}
{"op":"mcm","clk":"4228337407","pt":1631461036524,"mc":[{"id":"1.187551081","rc":[{"batb":[[2,4.1,377.07]],"batl":[[1,990,0.01],[2,80,0]],"ltp":29.0,"tv":1753.48,"id":7445998}]}]}
{"op":"mcm","clk":"4228337681","pt":1631461038510,"mc":[{"id":"1.187551081","rc":[{"trd":[[1.01,400]],"batb":[[0,1.01,2202.91]],"ltp":1.01,"tv":21054.75,"id":9629022}],"tv":22808.23}]}
{"op":"mcm","clk":"4228337794","pt":1631461039317,"mc":[{"id":"1.187551081","rc":[{"batl":[[0,60,1.38],[1,65,5.06],[2,990,0.01]],"ltp":29.0,"tv":1753.48,"id":7445998}]}]}
{"op":"mcm","clk":"4228338258","pt":1631461042523,"mc":[{"id":"1.187551081","rc":[{"batb":[[0,36,2],[1,4.1,377.07],[2,1.01,30]],"batl":[[1,990,0.01],[2,990,0]],"ltp":29.0,"tv":1753.48,"id":7445998},{"batb":[[0,1.01,1335.3]],"batl":[[0,1.03,963.42],[1,1.04,53],[2,1.05,17.08]],"ltp":1.01,"tv":21054.75,"id":9629022}]}]}
{"op":"mcm","clk":"4228338563","pt":1631461044636,"mc":[{"id":"1.187551081","rc":[{"batb":[[1,34,2],[2,26,2]],"batl":[[1,110,2],[2,990,0.01]],"ltp":29.0,"tv":1753.48,"id":7445998},{"batb":[[0,1.01,1337.5]],"batl":[[0,1.03,1734.92],[1,1.04,654.88],[2,1.05,562.98]],"ltp":1.01,"tv":21054.75,"id":9629022}]}]}
{"op":"mcm","clk":"4228338679","pt":1631461045321,"mc":[{"id":"1.187551081","rc":[{"batb":[[1,34,6],[2,26,4]],"ltp":29.0,"tv":1753.48,"id":7445998},{"batl":[[0,1.03,2165.37],[1,1.04,661.01],[2,1.05,568.88]],"ltp":1.01,"tv":21054.75,"id":9629022}]}]}
{"op":"mcm","clk":"4228338768","pt":1631461046007,"mc":[{"id":"1.187551081","rc":[{"batb":[[1,34,4]],"ltp":29.0,"tv":1753.48,"id":7445998},{"batb":[[0,1.01,2.2]],"batl":[[0,1.03,1393.87],[1,1.04,59.13],[2,1.05,22.98]],"ltp":1.01,"tv":21054.75,"id":9629022}]}]}
{"op":"mcm","clk":"4228339143","pt":1631461048614,"mc":[{"id":"1.187551081","rc":[{"batb":[[0,34,4],[1,26,4],[2,4.1,377.07]],"ltp":29.0,"tv":1753.48,"id":7445998},{"batb":[[0,1.02,1322.21],[1,1.01,2.2]],"ltp":1.01,"tv":21054.75,"id":9629022}]}]}
{"op":"mcm","clk":"4228339291","pt":1631461049420,"mc":[{"id":"1.187551081","rc":[{"batb":[[1,30,7.49],[2,26,4]],"ltp":29.0,"tv":1753.48,"id":7445998}]}]}
{"op":"mcm","clk":"4228339660","pt":1631461051489,"mc":[{"id":"1.187551081","rc":[{"batl":[[1,100,2],[2,110,2]],"ltp":29.0,"tv":1753.48,"id":7445998},{"batb":[[0,1.02,1444.21],[1,1.01,167.2]],"batl":[[0,1.03,1636.59]],"ltp":1.01,"tv":21054.75,"id":9629022}]}]}
{"op":"mcm","clk":"4228339725","pt":1631461051952,"mc":[{"id":"1.187551081","rc":[{"batb":[[0,34,2]],"batl":[[0,100,2],[1,110,2],[2,990,0.01]],"ltp":29.0,"tv":1753.48,"id":7445998},{"batl":[[0,1.03,1630.09]],"ltp":1.01,"tv":21054.75,"id":9629022}]}]}
{"op":"mcm","clk":"4228340214","pt":1631461054651,"mc":[{"id":"1.187551081","rc":[{"batb":[[0,1.02,590.13]],"batl":[[0,1.03,1494.66]],"ltp":1.01,"tv":21054.75,"id":9629022}]}]}
{"op":"mcm","clk":"4228340330","pt":1631461055431,"mc":[{"id":"1.187551081","rc":[{"batb":[[0,34,6]],"batl":[[0,990,0.01],[1,110,0],[2,990,0]],"ltp":29.0,"tv":1753.48,"id":7445998},{"batl":[[0,1.03,1738.17],[1,1.04,707.76],[2,1.05,516.88]],"ltp":1.01,"tv":21054.75,"id":9629022}]}]}
{"op":"mcm","clk":"4228340371","pt":1631461055742,"mc":[{"id":"1.187551081","rc":[{"batb":[[0,34,2],[2,26,2]],"ltp":29.0,"tv":1753.48,"id":7445998},{"batl":[[0,1.03,869.83],[1,1.04,701.63],[2,1.05,17.08]],"ltp":1.01,"tv":21054.75,"id":9629022}]}]}
{"op":"mcm","clk":"4228340681","pt":1631461057541,"mc":[{"id":"1.187551081","rc":[{"batb":[[0,1.01,1335.3]],"batl":[[1,1.04,1214.2]],"ltp":1.01,"tv":21054.75,"id":9629022}]}]}
{"op":"mcm","clk":"4228340775","pt":1631461058046,"mc":[{"id":"1.187551081","rc":[{"batb":[[1,32,2],[2,30,7.49]],"ltp":29.0,"tv":1753.48,"id":7445998},{"batl":[[1,1.04,512.57]],"ltp":1.01,"tv":21054.75,"id":9629022}]}]}
{"op":"mcm","clk":"4228341234","pt":1631461060638,"mc":[{"id":"1.187551081","rc":[{"batb":[[0,30,7.49],[1,26,2],[2,4.1,377.07]],"batl":[[0,55,2],[1,990,0.01]],"ltp":29.0,"tv":1753.48,"id":7445998},{"batb":[[0,1.02,1333.45]],"batl":[[0,1.03,791.83]],"ltp":1.01,"tv":21054.75,"id":9629022}]}]}
{"op":"mcm","clk":"4228341392","pt":1631461061564,"mc":[{"id":"1.187551081","rc":[{"batb":[[0,29,11.15]],"ltp":29.0,"tv":1753.48,"id":7445998}]}]}
{"op":"mcm","clk":"4228341504","pt":1631461062259,"mc":[{"id":"1.187551081","rc":[{"batb":[[0,1.02,1338.45]],"batl":[[0,1.03,948.78]],"ltp":1.01,"tv":21054.75,"id":9629022}]}]}
{"op":"mcm","clk":"4228341744","pt":1631461063728,"mc":[{"id":"1.187551081","rc":[{"batl":[[0,50,2],[1,55,2],[2,990,0.01]],"ltp":29.0,"tv":1753.48,"id":7445998}]}]}
{"op":"mcm","clk":"4228342024","pt":1631461065584,"mc":[{"id":"1.187551081","rc":[{"batb":[[0,1.02,1805.52]],"batl":[[0,1.03,1329.43]],"ltp":1.01,"tv":21054.75,"id":9629022}]}]}
{"op":"mcm","clk":"4228342257","pt":1631461067174,"mc":[{"id":"1.187551081","rc":[{"batb":[[1,26,4]],"batl":[[0,48,2],[1,50,2],[2,55,2]],"ltp":29.0,"tv":1753.48,"id":7445998},{"batb":[[1,1.01,2631.07]],"batl":[[1,1.04,1131.83],[2,1.05,542.48]],"ltp":1.01,"tv":21054.75,"id":9629022}]}]}
{"op":"mcm","clk":"4228342607","pt":1631461069369,"mc":[{"id":"1.187551081","rc":[{"trd":[[1.03,575.6]],"batl":[[0,1.03,1327.72]],"ltp":1.03,"tv":21058.17,"id":9629022}],"tv":22811.65}]}
{"op":"mcm","clk":"4228342753","pt":1631461070415,"mc":[{"id":"1.187551081","rc":[{"batb":[[0,34,4],[1,30,2],[2,29,13.15]],"batl":[[0,46,2],[1,48,2],[2,50,2]],"ltp":29.0,"tv":1753.48,"id":7445998},{"batl":[[0,1.03,2164.39]],"ltp":1.03,"tv":21058.17,"id":9629022}]}]}
{"op":"mcm","clk":"4228342934","pt":1631461071501,"mc":[{"id":"1.187551081","rc":[{"batb":[[1,29,11.15],[2,26,4]],"batl":[[0,110,2],[1,990,0.01],[2,50,0]],"ltp":29.0,"tv":1753.48,"id":7445998},{"batb":[[0,1.02,1322.21]],"batl":[[0,1.03,836.67]],"ltp":1.03,"tv":21058.17,"id":9629022}]}]}
{"op":"mcm","clk":"4228343026","pt":1631461072106,"mc":[{"id":"1.187551081","rc":[{"batb":[[0,29,11.15],[1,26,4],[2,4.1,377.07]],"ltp":29.0,"tv":1753.48,"id":7445998},{"batl":[[0,1.04,1131.83],[1,1.05,542.48],[2,1.09,11.86]],"ltp":1.03,"tv":21058.17,"id":9629022}]}]}
{"op":"mcm","clk":"4228343248","pt":1631461073411,"mc":[{"id":"1.187551081","rc":[{"batl":[[0,44,2],[1,110,2],[2,990,0.01]],"ltp":29.0,"tv":1753.48,"id":7445998}]}]}
{"op":"mcm","clk":"4228343356","pt":1631461073901,"mc":[{"id":"1.187551081","rc":[{"batl":[[0,110,2],[1,990,0.01],[2,990,0]],"ltp":29.0,"tv":1753.48,"id":7445998},{"batl":[[0,1.04,1916.05]],"ltp":1.03,"tv":21058.17,"id":9629022}]}]}
{"op":"mcm","clk":"4228343599","pt":1631461075427,"mc":[{"id":"1.187551081","rc":[{"batb":[[0,34,2],[1,29,11.15],[2,28,2]],"ltp":29.0,"tv":1753.48,"id":7445998},{"batl":[[0,1.03,6.17],[1,1.04,667.26],[2,1.05,23.98]],"ltp":1.03,"tv":21058.17,"id":9629022}]}]}
{"op":"mcm","clk":"4228343639","pt":1631461075705,"mc":[{"id":"1.187551081","rc":[{"batb":[[0,29,11.15],[1,28,2],[2,26,4]],"ltp":29.0,"tv":1753.48,"id":7445998},{"batl":[[0,1.04,667.26],[1,1.05,23.98],[2,1.09,11.86]],"ltp":1.03,"tv":21058.17,"id":9629022}]}]}
{"op":"mcm","clk":"4228344112","pt":1631461078390,"mc":[{"id":"1.187551081","rc":[{"batb":[[0,34,2],[1,29,11.15],[2,28,2]],"ltp":29.0,"tv":1753.48,"id":7445998},{"batl":[[0,1.03,1831.03],[1,1.04,667.26],[2,1.05,510.28]],"ltp":1.03,"tv":21058.17,"id":9629022}]}]}
{"op":"mcm","clk":"4228344228","pt":1631461078990,"mc":[{"id":"1.187551081","rc":[{"batb":[[0,34,4]],"ltp":29.0,"tv":1753.48,"id":7445998},{"batl":[[0,1.03,1837.53]],"ltp":1.03,"tv":21058.17,"id":9629022}]}]}
{"op":"mcm","clk":"4228344516","pt":1631461080501,"mc":[{"id":"1.187551081","rc":[{"batb":[[1,32,7.81],[2,29,11.15]],"batl":[[0,55,4.55],[1,110,2],[2,990,0.01]],"ltp":29.0,"tv":1753.48,"id":7445998},{"batb":[[0,1.02,1513.09]],"batl":[[0,1.03,2039.54]],"ltp":1.03,"tv":21058.17,"id":9629022}]}]}
{"op":"mcm","clk":"4228344671","pt":1631461081433,"mc":[{"id":"1.187551081","rc":[{"batb":[[1,29,11.15],[2,28,2]],"batl":[[0,110,2],[1,990,0.01],[2,990,0]],"ltp":29.0,"tv":1753.48,"id":7445998},{"batb":[[0,1.02,1322.21]],"batl":[[0,1.03,713]],"ltp":1.03,"tv":21058.17,"id":9629022}]}]}
{"op":"mcm","clk":"4228344858","pt":1631461082309,"mc":[{"id":"1.187551081","rc":[{"batb":[[0,29,11.15],[1,28,2],[2,26,4]],"ltp":29.0,"tv":1753.48,"id":7445998},{"batl":[[0,1.04,667.26],[1,1.05,510.28],[2,1.09,11.86]],"ltp":1.03,"tv":21058.17,"id":9629022}]}]}
{"op":"mcm","clk":"4228345217","pt":1631461084441,"mc":[{"id":"1.187551081","rc":[{"batl":[[0,1.04,1964.05]],"ltp":1.03,"tv":21058.17,"id":9629022}]}]}
{"op":"mcm","clk":"4228345385","pt":1631461085313,"mc":[{"id":"1.187551081","rc":[{"batb":[[0,34,4],[1,29,13.15],[2,28,2]],"ltp":29.0,"tv":1753.48,"id":7445998},{"batl":[[0,1.03,910.34],[1,1.04,1964.05],[2,1.05,510.28]],"ltp":1.03,"tv":21058.17,"id":9629022}]}]}
{"op":"mcm","clk":"4228345500","pt":1631461085911,"mc":[{"id":"1.187551081","rc":[{"batb":[[0,29,13.15],[1,28,2],[2,26,4]],"ltp":29.0,"tv":1753.48,"id":7445998},{"batl":[[0,1.04,1964.05],[1,1.05,510.28],[2,1.09,11.86]],"ltp":1.03,"tv":21058.17,"id":9629022}]}]}
{"op":"mcm","clk":"4228345805","pt":1631461087641,"mc":[{"id":"1.187551081","rc":[{"batl":[[0,1.04,54.63],[1,1.05,23.98]],"ltp":1.03,"tv":21058.17,"id":9629022}]}]}
{"op":"mcm","clk":"4228345857","pt":1631461087910,"mc":[{"id":"1.187551081","rc":[{"batb":[[2,26,2]],"ltp":29.0,"tv":1753.48,"id":7445998},{"batl":[[0,1.04,48],[1,1.05,17.08]],"ltp":1.03,"tv":21058.17,"id":9629022}]}]}
{"op":"mcm","clk":"4228346079","pt":1631461089177,"mc":[{"id":"1.187551081","rc":[{"batb":[[0,34,4],[1,29,13.15],[2,28,2]],"ltp":29.0,"tv":1753.48,"id":7445998},{"batl":[[0,1.03,834.67],[1,1.04,48],[2,1.05,17.08]],"ltp":1.03,"tv":21058.17,"id":9629022}]}]}
{"op":"mcm","clk":"4228346324","pt":1631461090526,"mc":[{"id":"1.187551081","rc":[{"batl":[[0,1.03,2144.04]],"ltp":1.03,"tv":21058.17,"id":9629022}]}]}
{"op":"mcm","clk":"4228346476","pt":1631461091323,"mc":[{"id":"1.187551081","rc":[{"batb":[[1,30,7.83],[2,29,2]],"ltp":29.0,"tv":1753.48,"id":7445998}]}]}
{"op":"mcm","clk":"4228346707","pt":1631461092616,"mc":[{"id":"1.187551081","rc":[{"batb":[[0,36,6.94],[1,34,4],[2,30,7.83]],"batl":[[0,60,3.69],[1,110,2],[2,990,0.01]],"ltp":29.0,"tv":1753.48,"id":7445998},{"batb":[[0,1.02,1519.81],[1,1.01,2824.07]],"batl":[[0,1.03,2384.04]],"ltp":1.03,"tv":21058.17,"id":9629022}]}]}
{"op":"mcm","clk":"4228346747","pt":1631461092929,"mc":[{"id":"1.187551081","rc":[{"batl":[[1,1.04,667.18],[2,1.05,718.25]],"ltp":1.03,"tv":21058.17,"id":9629022}]}]}
{"op":"mcm","clk":"4228346926","pt":1631461094055,"mc":[{"id":"1.187551081","rc":[{"batb":[[1,34,27.4]],"ltp":29.0,"tv":1753.48,"id":7445998},{"batl":[[0,1.03,3222.71],[1,1.04,1510.12]],"ltp":1.03,"tv":21058.17,"id":9629022}]}]}
{"op":"mcm","clk":"4228347179","pt":1631461095530,"mc":[{"id":"1.187551081","rc":[{"batl":[[0,55,18.23],[1,110,16.18]],"ltp":29.0,"tv":1753.48,"id":7445998},{"batb":[[0,1.02,3021.11],[1,1.01,4369.04]],"batl":[[0,1.03,3673.82]],"ltp":1.03,"tv":21058.17,"id":9629022}]}]}
{"op":"mcm","clk":"4228347341","pt":1631461096627,"mc":[{"id":"1.187551081","rc":[{"batl":[[1,1.04,1516.75],[2,1.05,724.75]],"ltp":1.03,"tv":21058.17,"id":9629022}]}]}
{"op":"mcm","clk":"4228347425","pt":1631461097240,"mc":[{"id":"1.187551081","rc":[{"batl":[[1,1.04,2113.38],[2,1.05,1217.85]],"ltp":1.03,"tv":21058.17,"id":9629022}]}]}
{"op":"mcm","clk":"4228347641","pt":1631461098443,"mc":[{"id":"1.187551081","rc":[{"batl":[[0,50,3.69],[1,55,18.23],[2,110,16.18]],"ltp":29.0,"tv":1753.48,"id":7445998}]}]}
{"op":"mcm","clk":"4228347825","pt":1631461099641,"mc":[{"id":"1.187551081","rc":[{"batb":[[0,34,2],[1,30,7.83],[2,26,4]],"batl":[[0,110,2],[1,990,0.01],[2,110,0]],"ltp":29.0,"tv":1753.48,"id":7445998},{"batb":[[0,1.01,2824.07],[1,1.01,0]],"batl":[[0,1.03,1090.54],[1,1.04,603.26],[2,1.05,516.68]],"ltp":1.03,"tv":21058.17,"id":9629022}]}]}
{"op":"mcm","clk":"4228347997","pt":1631461100525,"mc":[{"id":"1.187551081","rc":[{"batb":[[0,34,4],[2,26,2]],"batl":[[0,990,0.01],[1,990,0]],"ltp":29.0,"tv":1753.48,"id":7445998},{"batb":[[0,1.01,193]],"batl":[[0,1.03,262.04],[1,1.04,596.63],[2,1.05,17.08]],"ltp":1.03,"tv":21058.17,"id":9629022}]}]}
{"op":"mcm","clk":"4228348052","pt":1631461100847,"mc":[{"id":"1.187551081","rc":[{"batb":[[0,34,2]],"ltp":29.0,"tv":1753.48,"id":7445998}]}]}
{"op":"mcm","clk":"4228348471","pt":1631461103244,"mc":[{"id":"1.187551081","rc":[{"batb":[[1,30,9.83],[2,28,2]],"ltp":29.0,"tv":1753.48,"id":7445998},{"batl":[[0,1.03,1149.54],[1,1.04,603.26],[2,1.05,522.68]],"ltp":1.03,"tv":21058.17,"id":9629022}]}]}
{"op":"mcm","clk":"4228348696","pt":1631461104334,"mc":[{"id":"1.187551081","rc":[{"batb":[[1,30,7.83],[2,26,2]],"ltp":29.0,"tv":1753.48,"id":7445998},{"batb":[[0,1.02,1322.21],[1,1.01,193]],"batl":[[0,1.03,1315.54],[1,1.04,596.63],[2,1.05,17.08]],"ltp":1.03,"tv":21058.17,"id":9629022}]}]}
{"op":"mcm","clk":"4228348896","pt":1631461105424,"mc":[{"id":"1.187551081","rc":[{"batb":[[0,36,6.94],[1,34,2],[2,30,7.83]],"batl":[[0,110,2],[1,990,0.01]],"ltp":29.0,"tv":1753.48,"id":7445998},{"batb":[[0,1.02,1395.8]],"batl":[[0,1.03,1558.26]],"ltp":1.03,"tv":21058.17,"id":9629022}]}]}
{"op":"mcm","clk":"4228349084","pt":1631461106562,"mc":[{"id":"1.187551081","rc":[{"batb":[[2,30,9.83]],"ltp":29.0,"tv":1753.48,"id":7445998},{"batb":[[1,1.01,2784.04]],"ltp":1.03,"tv":21058.17,"id":9629022}]}]}
{"op":"mcm","clk":"4228349288","pt":1631461107640,"mc":[{"id":"1.187551081","rc":[{"batb":[[1,34,4],[2,30,11.83]],"ltp":29.0,"tv":1753.48,"id":7445998},{"batl":[[0,1.03,2320.76],[1,1.04,603.51],[2,1.05,555.08]],"ltp":1.03,"tv":21058.17,"id":9629022}]}]}
{"op":"mcm","clk":"4228349479","pt":1631461108642,"mc":[{"id":"1.187551081","rc":[{"batl":[[0,60,3.62],[1,110,2],[2,990,0.01]],"ltp":29.0,"tv":1753.48,"id":7445998}]}]}
{"op":"mcm","clk":"4228349695","pt":1631461109750,"mc":[{"id":"1.187551081","rc":[{"batb":[[0,1.02,2017.33]],"batl":[[0,1.03,2913.85]],"ltp":1.03,"tv":21058.17,"id":9629022}]}]}
{"op":"mcm","clk":"4228350005","pt":1631461111460,"mc":[{"id":"1.187551081","rc":[{"batb":[[0,1.02,695.12]],"batl":[[0,1.03,1860.35]],"ltp":1.03,"tv":21058.17,"id":9629022}]}]}
{"op":"mcm","clk":"4228350244","pt":1631461112655,"mc":[{"id":"1.187551081","rc":[{"batb":[[0,34,2],[1,30,7.83],[2,26,2]],"batl":[[0,990,0.01],[1,110,0],[2,990,0]],"ltp":29.0,"tv":1753.48,"id":7445998},{"batb":[[0,1.01,193],[1,1.01,0]],"batl":[[0,1.03,262.04],[1,1.04,596.63],[2,1.05,17.08]],"ltp":1.03,"tv":21058.17,"id":9629022}]}]}
{"op":"mcm","clk":"4228350590","pt":1631461114657,"mc":[{"id":"1.187551081","rc":[{"batb":[[0,1.01,2118.49]],"batl":[[1,1.04,1640]],"ltp":1.03,"tv":21058.17,"id":9629022}]}]}
{"op":"mcm","clk":"4228350765","pt":1631461115569,"mc":[{"id":"1.187551081","rc":[{"batb":[[0,1.01,4022.14]],"ltp":1.03,"tv":21058.17,"id":9629022}]}]}
{"op":"mcm","clk":"4228350988","pt":1631461116661,"mc":[{"id":"1.187551081","rc":[{"batb":[[0,34,4],[1,30,11.83],[2,28,4]],"ltp":29.0,"tv":1753.48,"id":7445998},{"batb":[[0,1.02,250],[1,1.01,4022.14]],"batl":[[0,1.03,1108.54],[1,1.04,1646.13],[2,1.05,454.48]],"ltp":1.03,"tv":21058.17,"id":9629022}]}]}
{"op":"mcm","clk":"4228351172","pt":1631461117585,"mc":[{"id":"1.187551081","rc":[{"batb":[[1,30,9.95]],"batl":[[0,110,2],[1,990,0.01]],"ltp":29.0,"tv":1753.48,"id":7445998},{"batl":[[1,1.04,6.13],[2,1.05,22.98]],"ltp":1.03,"tv":21058.17,"id":9629022}]}]}
{"op":"mcm","clk":"4228351552","pt":1631461119661,"mc":[{"id":"1.187551081","rc":[{"batb":[[0,50,2],[1,34,4],[2,30,9.95]],"ltp":29.0,"tv":1753.48,"id":7445998},{"trd":[[1.02,45.66]],"batb":[[0,1.02,244.25]],"ltp":1.02,"tv":21069.67,"id":9629022}],"tv":22823.15}]}
{"op":"mcm","clk":"4228351748","pt":1631461120654,"mc":[{"id":"1.187551081","rc":[{"batb":[[1,36,2],[2,34,6]],"ltp":29.0,"tv":1753.48,"id":7445998},{"trd":[[1.02,534.16]],"batb":[[0,1.01,4022.14],[1,1.01,0]],"batl":[[0,1.02,95.47],[1,1.03,1825.62],[2,1.04,6.13]],"ltp":1.02,"tv":21558.17,"id":9629022}],"tv":23311.65}]}
{"op":"mcm","clk":"4228351899","pt":1631461121471,"mc":[{"id":"1.187551081","rc":[{"batb":[[1,46,5.43],[2,36,2]],"batl":[[0,75,3.09],[1,110,2],[2,990,0.01]],"ltp":29.0,"tv":1753.48,"id":7445998},{"batl":[[0,1.02,231.15]],"ltp":1.02,"tv":21558.17,"id":9629022}]}]}
{"op":"mcm","clk":"4228351949","pt":1631461121746,"mc":[{"id":"1.187551081","rc":[{"batb":[[1,36,2],[2,34,6]],"ltp":29.0,"tv":1753.48,"id":7445998}]}]}
{"op":"mcm","clk":"4228352146","pt":1631461123054,"mc":[{"id":"1.187551081","rc":[{"batb":[[2,34,4]],"batl":[[1,100,2],[2,110,2]],"ltp":29.0,"tv":1753.48,"id":7445998},{"batb":[[0,1.01,4269.66]],"batl":[[0,1.02,340.42],[1,1.03,1953.12]],"ltp":1.02,"tv":21558.17,"id":9629022}]}]}
{"op":"mcm","clk":"4228352386","pt":1631461124481,"mc":[{"id":"1.187551081","rc":[{"batl":[[1,80,5.92],[2,100,2]],"ltp":29.0,"tv":1753.48,"id":7445998},{"batl":[[1,1.03,3041.22]],"ltp":1.02,"tv":21558.17,"id":9629022}]}]}
{"op":"mcm","clk":"4228352527","pt":1631461125195,"mc":[{"id":"1.187551081","rc":[{"batb":[[0,50,2.98]],"batl":[[0,70,2],[1,100,2],[2,110,2]],"ltp":29.0,"tv":1753.48,"id":7445998},{"batb":[[0,1.01,4859.85]],"batl":[[1,1.03,2495.15]],"ltp":1.02,"tv":21558.17,"id":9629022}]}]}
{"op":"mcm","clk":"4228352738","pt":1631461126277,"mc":[{"id":"1.187551081","rc":[{"batb":[[2,34,6]],"ltp":29.0,"tv":1753.48,"id":7445998},{"batl":[[1,1.03,2500.99],[2,1.04,557.01]],"ltp":1.02,"tv":21558.17,"id":9629022}]}]}
{"op":"mcm","clk":"4228353061","pt":1631461128181,"mc":[{"id":"1.187551081","rc":[{"batl":[[0,65,5.09],[1,70,2],[2,100,2]],"ltp":29.0,"tv":1753.48,"id":7445998}]}]}
{"op":"mcm","clk":"4228353819","pt":1631461132591,"mc":[{"id":"1.187551081","rc":[{"batb":[[0,50,2],[1,34,4],[2,30,9.95]],"batl":[[0,110,2],[1,990,0.01],[2,100,0]],"ltp":29.0,"tv":1753.48,"id":7445998},{"batb":[[0,1.01,3829.14]],"batl":[[0,1.03,1958.96],[1,1.04,557.01],[2,1.05,543.88]],"ltp":1.02,"tv":21558.17,"id":9629022}]}]}
{"op":"mcm","clk":"4228354079","pt":1631461134217,"mc":[{"id":"1.187551081","rc":[{"batb":[[0,1.02,3],[1,1.01,3829.14]],"ltp":1.02,"tv":21558.17,"id":9629022}]}]}
{"op":"mcm","clk":"4228354222","pt":1631461135102,"mc":[{"id":"1.187551081","rc":[{"batl":[[0,1.03,2161.71]],"ltp":1.02,"tv":21558.17,"id":9629022}]}]}
{"op":"mcm","clk":"4228354875","pt":1631461138946,"mc":[{"id":"1.187551081","rc":[{"trd":[[1.02,540.16]],"batb":[[0,1.01,3829.14],[1,1.01,0]],"ltp":1.02,"tv":21564.17,"id":9629022}],"tv":23317.65}]}
{"op":"mcm","clk":"4228355330","pt":1631461141621,"mc":[{"id":"1.187551081","rc":[{"batb":[[0,1.01,1335.3]],"batl":[[0,1.03,852.34]],"ltp":1.02,"tv":21564.17,"id":9629022}]}]}
{"op":"mcm","clk":"4228355490","pt":1631461142537,"mc":[{"id":"1.187551081","rc":[{"batb":[[1,34,2],[2,1.01,30]],"batl":[[0,990,0.01],[1,990,0]],"ltp":29.0,"tv":1753.48,"id":7445998},{"batl":[[0,1.05,17.08],[1,1.09,11.86],[2,1.11,11.86]],"ltp":1.02,"tv":21564.17,"id":9629022}]}]}
{"op":"mcm","clk":"4228355836","pt":1631461144623,"mc":[{"id":"1.187551081","rc":[{"batb":[[0,1.01,1531.3]],"batl":[[0,1.02,1327.96],[1,1.05,32.27],[2,1.09,11.86]],"ltp":1.02,"tv":21564.17,"id":9629022}]}]}
{"op":"mcm","clk":"4228356074","pt":1631461145940,"mc":[{"id":"1.187551081","rc":[{"batb":[[0,65,3.85],[1,50,2],[2,34,2]],"ltp":29.0,"tv":1753.48,"id":7445998},{"batb":[[0,1.01,1718.41]],"batl":[[0,1.02,1413.36]],"ltp":1.02,"tv":21564.17,"id":9629022}]}]}
{"op":"mcm","clk":"4228356357","pt":1631461147563,"mc":[{"id":"1.187551081","rc":[{"batb":[[1,34,2],[2,1.01,30]],"batl":[[0,100,2],[1,990,0.01]],"ltp":29.0,"tv":1753.48,"id":7445998},{"batl":[[0,1.02,1510.61]],"ltp":1.02,"tv":21564.17,"id":9629022}]}]}
{"op":"mcm","clk":"4228356409","pt":1631461147886,"mc":[{"id":"1.187551081","rc":[{"batl":[[0,1.02,1407.61]],"ltp":1.02,"tv":21564.17,"id":9629022}]}]}
{"op":"mcm","clk":"4228356685","pt":1631461149256,"mc":[{"id":"1.187551081","rc":[{"batb":[[0,1.01,2421.29]],"batl":[[0,1.02,2103.6]],"ltp":1.02,"tv":21564.17,"id":9629022}]}]}
{"op":"mcm","clk":"4228356918","pt":1631461150562,"mc":[{"id":"1.187551081","rc":[{"batb":[[1,50,4],[2,34,4]],"ltp":29.0,"tv":1753.48,"id":7445998},{"batl":[[0,1.02,3426.03],[1,1.03,828.01],[2,1.04,638.01]],"ltp":1.02,"tv":21564.17,"id":9629022}]}]}
{"op":"mcm","clk":"4228356974","pt":1631461150874,"mc":[{"id":"1.187551081","rc":[{"batb":[[1,34,4],[2,1.01,30]],"batl":[[0,95,3.45],[1,100,2],[2,990,0.01]],"ltp":29.0,"tv":1753.48,"id":7445998},{"batl":[[0,1.02,2103.6]],"ltp":1.02,"tv":21564.17,"id":9629022}]}]}
{"op":"mcm","clk":"4228357427","pt":1631461153367,"mc":[{"id":"1.187551081","rc":[{"batb":[[0,34,4],[1,1.01,30],[2,1.01,0]],"batl":[[0,990,0.01],[1,100,0],[2,990,0]],"ltp":29.0,"tv":1753.48,"id":7445998},{"batl":[[0,1.03,828.01],[1,1.04,5.88],[2,1.05,17.08]],"ltp":1.02,"tv":21564.17,"id":9629022}]}]}
{"op":"mcm","clk":"4228357622","pt":1631461154482,"mc":[{"id":"1.187551081","rc":[{"batb":[[0,34,2]],"ltp":29.0,"tv":1753.48,"id":7445998},{"batl":[[0,1.03,821.5],[1,1.05,17.08],[2,1.09,11.86]],"ltp":1.02,"tv":21564.17,"id":9629022}]}]}
{"op":"mcm","clk":"4228357961","pt":1631461156554,"mc":[{"id":"1.187551081","rc":[{"batb":[[0,34,4],[1,32,2],[2,1.01,30]],"ltp":29.0,"tv":1753.48,"id":7445998},{"batl":[[0,1.03,2186.87],[1,1.04,624.38],[2,1.05,17.08]],"ltp":1.02,"tv":21564.17,"id":9629022}]}]}
{"op":"mcm","clk":"4228357996","pt":1631461156776,"mc":[{"id":"1.187551081","rc":[{"batl":[[1,1.05,17.08],[2,1.09,11.86]],"ltp":1.02,"tv":21564.17,"id":9629022}]}]}
{"op":"mcm","clk":"4228358910","pt":1631461162382,"mc":[{"id":"1.187551081","rc":[{"batb":[[0,34,2],[1,1.01,30],[2,1.01,0]],"ltp":29.0,"tv":1753.48,"id":7445998},{"batl":[[0,1.03,821.5]],"ltp":1.02,"tv":21564.17,"id":9629022}]}]}
{"op":"mcm","clk":"4228359352","pt":1631461164990,"mc":[{"id":"1.187551081","rc":[{"batb":[[0,100,2],[1,34,2],[2,1.01,30]],"ltp":29.0,"tv":1753.48,"id":7445998},{"batl":[[0,1.01,1341.8],[1,1.03,821.5],[2,1.05,17.08]],"ltp":1.02,"tv":21564.17,"id":9629022}]}]}
{"op":"mcm","clk":"4228374931","pt":1631461261223,"mc":[{"id":"1.187551081","rc":[{"trd":[[1.01,500]],"batl":[[0,1.01,1291.8]],"ltp":1.01,"tv":21664.17,"id":9629022}],"tv":23417.65}]}
{"op":"mcm","clk":"4228375594","pt":1631461264523,"mc":[{"id":"1.187551081","rc":[{"batl":[[0,1.01,1341.8]],"ltp":1.01,"tv":21664.17,"id":9629022}]}]}
{"op":"mcm","clk":"4228378174","pt":1631461279539,"mc":[{"id":"1.187551081","rc":[{"batb":[[0,1.01,30],[1,34,0],[2,1.01,0]],"ltp":29.0,"tv":1753.48,"id":7445998},{"batl":[[0,1.05,17.08],[1,1.09,11.86],[2,1.11,11.86]],"ltp":1.01,"tv":21664.17,"id":9629022}]}]}
{"op":"mcm","clk":"4228379014","pt":1631461284556,"mc":[{"id":"1.187551081","rc":[{"batl":[[0,1.01,1378.8],[1,1.05,17.08],[2,1.09,11.86]],"ltp":1.01,"tv":21664.17,"id":9629022}]}]}
{"op":"mcm","clk":"4228379061","pt":1631461284778,"mc":[{"id":"1.187551081","rc":[{"batl":[[0,1.01,1335.3]],"ltp":1.01,"tv":21664.17,"id":9629022}]}]}
{"op":"mcm","clk":"4228380288","pt":1631461291693,"mc":[{"id":"1.187551081","rc":[{"batl":[[0,1.05,17.08],[1,1.09,11.86],[2,1.11,11.86]],"ltp":1.01,"tv":21664.17,"id":9629022}]}]}
{"op":"mcm","clk":"4228380920","pt":1631461294593,"mc":[{"id":"1.187551081","rc":[{"batl":[[0,1.02,1322.21],[1,1.05,17.08],[2,1.09,11.86]],"ltp":1.01,"tv":21664.17,"id":9629022}]}]}
{"op":"mcm","clk":"4228382117","pt":1631461301363,"mc":[{"id":"1.187551081","rc":[{"batb":[[0,1.01,234.56]],"ltp":1.01,"tv":21664.17,"id":9629022}]}]}
{"op":"mcm","clk":"4228382511","pt":1631461303577,"mc":[{"id":"1.187551081","rc":[{"batb":[[0,4.7,377.56],[1,1.01,30]],"ltp":29.0,"tv":1753.48,"id":7445998}]}]}
{"op":"mcm","clk":"4228382689","pt":1631461304577,"mc":[{"id":"1.187551081","rc":[{"batb":[[0,55,2],[1,50,2],[2,4.7,377.56]],"ltp":29.0,"tv":1753.48,"id":7445998}]}]}
{"op":"mcm","clk":"4228383043","pt":1631461306798,"mc":[{"id":"1.187551081","rc":[{"batl":[[0,1.02,1431.45]],"ltp":1.01,"tv":21664.17,"id":9629022}]}]}
{"op":"mcm","clk":"4228383216","pt":1631461307746,"mc":[{"id":"1.187551081","rc":[{"batb":[[0,60,2],[1,55,2],[2,50,2]],"ltp":29.0,"tv":1753.48,"id":7445998}]}]}
{"op":"mcm","clk":"4228383500","pt":1631461309362,"mc":[{"id":"1.187551081","rc":[{"batl":[[0,140,1.55],[1,990,0.01]],"ltp":29.0,"tv":1753.48,"id":7445998}]}]}
{"op":"mcm","clk":"4228383541","pt":1631461309701,"mc":[{"id":"1.187551081","rc":[{"batl":[[0,990,0.01],[1,990,0]],"ltp":29.0,"tv":1753.48,"id":7445998}]}]}
{"op":"mcm","clk":"4228383991","pt":1631461312619,"mc":[{"id":"1.187551081","rc":[{"batb":[[0,4.7,377.56],[1,1.01,30],[2,50,0]],"ltp":29.0,"tv":1753.48,"id":7445998},{"batl":[[0,1.02,1322.21]],"ltp":1.01,"tv":21664.17,"id":9629022}]}]}
{"op":"mcm","clk":"4228384469","pt":1631461315578,"mc":[{"id":"1.187551081","rc":[{"batb":[[0,7.6,3],[1,7.4,2],[2,4.7,377.56]],"ltp":29.0,"tv":1753.48,"id":7445998}]}]}
{"op":"mcm","clk":"4228386750","pt":1631461328517,"mc":[{"id":"1.187551081","rc":[{"batb":[[0,1.01,1335.3]],"batl":[[1,1.05,32.27]],"ltp":1.01,"tv":21664.17,"id":9629022}]}]}
{"op":"mcm","clk":"4228386952","pt":1631461329591,"mc":[{"id":"1.187551081","rc":[{"batb":[[1,4.7,377.56],[2,1.01,30]],"ltp":29.0,"tv":1753.48,"id":7445998}]}]}
{"op":"mcm","clk":"4228386993","pt":1631461329802,"mc":[{"id":"1.187551081","rc":[{"batb":[[0,70,3.57],[1,7.6,3],[2,4.7,377.56]],"ltp":29.0,"tv":1753.48,"id":7445998},{"batb":[[0,1.01,1340.3]],"batl":[[0,1.02,1567.31]],"ltp":1.01,"tv":21664.17,"id":9629022}]}]}
{"op":"mcm","clk":"4228387330","pt":1631461331693,"mc":[{"id":"1.187551081","rc":[{"batb":[[0,1.01,1543.3]],"ltp":1.01,"tv":21664.17,"id":9629022}]}]}
{"op":"mcm","clk":"4228387607","pt":1631461333430,"mc":[{"id":"1.187551081","rc":[{"batb":[[0,1.01,1761.04]],"ltp":1.01,"tv":21664.17,"id":9629022}]}]}
{"op":"mcm","clk":"4228387859","pt":1631461334820,"mc":[{"id":"1.187551081","rc":[{"batl":[[0,1.02,1638.48]],"ltp":1.01,"tv":21664.17,"id":9629022}]}]}
{"op":"mcm","clk":"4228388140","pt":1631461336502,"mc":[{"id":"1.187551081","rc":[{"batl":[[0,110,1.76],[1,990,0.01]],"ltp":29.0,"tv":1753.48,"id":7445998}]}]}
{"op":"mcm","clk":"4228388195","pt":1631461336819,"mc":[{"id":"1.187551081","rc":[{"batl":[[0,990,0.01],[1,990,0]],"ltp":29.0,"tv":1753.48,"id":7445998}]}]}
{"op":"mcm","clk":"4228388853","pt":1631461340551,"mc":[{"id":"1.187551081","rc":[{"batb":[[0,7.6,3],[1,4.7,377.56],[2,1.01,30]],"ltp":29.0,"tv":1753.48,"id":7445998},{"batb":[[0,1.01,1335.3]],"batl":[[0,1.02,818.68],[1,1.05,17.08]],"ltp":1.01,"tv":21664.17,"id":9629022}]}]}
{"op":"mcm","clk":"4228389706","pt":1631461345556,"mc":[{"id":"1.187551081","rc":[{"batl":[[0,990,0.21]],"ltp":29.0,"tv":1753.48,"id":7445998},{"batl":[[0,1.02,1322.21]],"ltp":1.01,"tv":21664.17,"id":9629022}]}]}
{"op":"mcm","clk":"4228389746","pt":1631461345710,"mc":[{"id":"1.187551081","rc":[{"batl":[[0,990,0.01]],"ltp":29.0,"tv":1753.48,"id":7445998}]}]}
{"op":"mcm","clk":"4228389949","pt":1631461346842,"mc":[{"id":"1.187551081","rc":[{"batb":[[0,65,3.85],[1,7.6,3],[2,4.7,377.56]],"ltp":29.0,"tv":1753.48,"id":7445998},{"batb":[[0,1.01,1527.62]],"batl":[[0,1.02,1567.31]],"ltp":1.01,"tv":21664.17,"id":9629022}]}]}
{"op":"mcm","clk":"4228390240","pt":1631461348617,"mc":[{"id":"1.187551081","rc":[{"batl":[[0,110,1.05],[1,990,0.01]],"ltp":29.0,"tv":1753.48,"id":7445998}]}]}
{"op":"mcm","clk":"4228390409","pt":1631461349626,"mc":[{"id":"1.187551081","rc":[{"batb":[[0,7.6,3],[1,4.7,377.56],[2,1.01,30]],"batl":[[0,990,0.01],[1,990,0]],"ltp":29.0,"tv":1753.48,"id":7445998},{"batb":[[0,1.01,1335.3]],"batl":[[0,1.02,818.68]],"ltp":1.01,"tv":21664.17,"id":9629022}]}]}
{"op":"mcm","clk":"4228390925","pt":1631461352553,"mc":[{"id":"1.187551081","rc":[{"batl":[[1,1.03,498.65],[2,1.05,17.08]],"ltp":1.01,"tv":21664.17,"id":9629022}]}]}
{"op":"mcm","clk":"4228392520","pt":1631461361633,"mc":[{"id":"1.187551081","rc":[{"batb":[[0,50,5],[1,30,5.36],[2,7.6,3]],"ltp":29.0,"tv":1753.48,"id":7445998},{"batb":[[0,1.01,1582.82]],"batl":[[0,1.02,1063.78],[2,1.05,32.27]],"ltp":1.01,"tv":21664.17,"id":9629022}]}]}
{"op":"mcm","clk":"4228393173","pt":1631461365590,"mc":[{"id":"1.187551081","rc":[{"batl":[[0,85,4.48],[1,990,0.01]],"ltp":29.0,"tv":1753.48,"id":7445998},{"batb":[[0,1.01,1765.82]],"batl":[[1,1.03,1692.32]],"ltp":1.01,"tv":21664.17,"id":9629022}]}]}
{"op":"mcm","clk":"4228393248","pt":1631461365951,"mc":[{"id":"1.187551081","rc":[{"batl":[[0,990,0.01],[1,990,0]],"ltp":29.0,"tv":1753.48,"id":7445998},{"batl":[[1,1.03,498.65]],"ltp":1.01,"tv":21664.17,"id":9629022}]}]}
{"op":"mcm","clk":"4228393472","pt":1631461367378,"mc":[{"id":"1.187551081","rc":[{"batb":[[1,34,4],[2,30,5.36]],"batl":[[0,100,2],[1,110,2],[2,990,0.01]],"ltp":29.0,"tv":1753.48,"id":7445998},{"batb":[[0,1.01,4340.6]],"batl":[[0,1.02,1245.8],[1,1.03,1311.99],[2,1.04,621.51]],"ltp":1.01,"tv":21664.17,"id":9629022}]}]}
{"op":"mcm","clk":"4228393688","pt":1631461368848,"mc":[{"id":"1.187551081","rc":[{"batl":[[0,80,4.32],[1,100,2],[2,110,2]],"ltp":29.0,"tv":1753.48,"id":7445998}]}]}
{"op":"mcm","clk":"4228393985","pt":1631461370561,"mc":[{"id":"1.187551081","rc":[{"batl":[[1,95,2],[2,100,2]],"ltp":29.0,"tv":1753.48,"id":7445998},{"batl":[[1,1.03,1566.05]],"ltp":1.01,"tv":21664.17,"id":9629022}]}]}
{"op":"mcm","clk":"4228394290","pt":1631461372288,"mc":[{"id":"1.187551081","rc":[{"batb":[[0,34,4],[1,30,5.36],[2,26,4]],"batl":[[0,110,2],[1,990,0.01],[2,100,0]],"ltp":29.0,"tv":1753.48,"id":7445998},{"batb":[[0,1.01,3585.52]],"batl":[[0,1.03,1311.99],[1,1.04,621.51],[2,1.05,467.48]],"ltp":1.01,"tv":21664.17,"id":9629022}]}]}
{"op":"mcm","clk":"4228394795","pt":1631461375357,"mc":[{"id":"1.187551081","rc":[{"batb":[[0,36,2],[1,34,6],[2,32,2]],"ltp":29.0,"tv":1753.48,"id":7445998},{"batl":[[0,1.03,2181.71]],"ltp":1.01,"tv":21664.17,"id":9629022}]}]}
{"op":"mcm","clk":"4228395513","pt":1631461379594,"mc":[{"id":"1.187551081","rc":[{"batl":[[0,1.03,872.34],[1,1.04,5.88],[2,1.05,23.38]],"ltp":1.01,"tv":21664.17,"id":9629022}]}]}
{"op":"mcm","clk":"4228396016","pt":1631461382484,"mc":[{"id":"1.187551081","rc":[{"batb":[[0,50,2],[1,36,2],[2,34,6]],"ltp":29.0,"tv":1753.48,"id":7445998},{"batb":[[0,1.01,3795.52]],"batl":[[0,1.02,1327.96],[1,1.03,872.34],[2,1.04,5.88]],"ltp":1.01,"tv":21664.17,"id":9629022}]}]}
{"op":"mcm","clk":"4228396328","pt":1631461384311,"mc":[{"id":"1.187551081","rc":[{"batb":[[0,60,4.17],[1,50,2],[2,36,2]],"batl":[[0,95,2.2],[1,110,2],[2,990,0.01]],"ltp":29.0,"tv":1753.48,"id":7445998},{"batb":[[0,1.01,4043.04]],"batl":[[0,1.02,1573.06]],"ltp":1.01,"tv":21664.17,"id":9629022}]}]}
{"op":"mcm","clk":"4228396581","pt":1631461385612,"mc":[{"id":"1.187551081","rc":[{"batl":[[1,100,2],[2,110,2]],"ltp":29.0,"tv":1753.48,"id":7445998},{"batl":[[1,1.03,865.5],[2,1.05,32.27]],"ltp":1.01,"tv":21664.17,"id":9629022}]}]}
{"op":"mcm","clk":"4228396901","pt":1631461387394,"mc":[{"id":"1.187551081","rc":[{"batl":[[0,90,2]],"ltp":29.0,"tv":1753.48,"id":7445998},{"batb":[[0,1.01,4498.15]],"batl":[[1,1.03,1223.56]],"ltp":1.01,"tv":21664.17,"id":9629022}]}]}
{"op":"mcm","clk":"4228397127","pt":1631461388582,"mc":[{"id":"1.187551081","rc":[{"batl":[[0,1.02,1934.63],[2,1.04,672.88]],"ltp":1.01,"tv":21664.17,"id":9629022}]}]}
{"op":"mcm","clk":"4228397160","pt":1631461388792,"mc":[{"id":"1.187551081","rc":[{"batl":[[1,1.03,1230.4],[2,1.04,678.76]],"ltp":1.01,"tv":21664.17,"id":9629022}]}]}
{"op":"mcm","clk":"4228397479","pt":1631461390505,"mc":[{"id":"1.187551081","rc":[{"batl":[[0,85,4.2],[1,90,2],[2,100,2]],"ltp":29.0,"tv":1753.48,"id":7445998}]}]}
{"op":"mcm","clk":"4228398016","pt":1631461393519,"mc":[{"id":"1.187551081","rc":[{"batb":[[0,50,2],[1,36,2],[2,34,2]],"batl":[[0,110,2],[1,990,0.01],[2,100,0]],"ltp":29.0,"tv":1753.48,"id":7445998},{"batb":[[0,1.01,3585.52]],"batl":[[0,1.02,5.75],[1,1.03,65.84]],"ltp":1.01,"tv":21664.17,"id":9629022}]}]}
{"op":"mcm","clk":"4228398050","pt":1631461393704,"mc":[{"id":"1.187551081","rc":[{"batb":[[2,30,12.06]],"ltp":29.0,"tv":1753.48,"id":7445998},{"batl":[[1,1.03,59]],"ltp":1.01,"tv":21664.17,"id":9629022}]}]}
{"op":"mcm","clk":"4228398397","pt":1631461395630,"mc":[{"id":"1.187551081","rc":[{"batl":[[1,1.03,1368.37]],"ltp":1.01,"tv":21664.17,"id":9629022}]}]}
{"op":"mcm","clk":"4228398747","pt":1631461397580,"mc":[{"id":"1.187551081","rc":[{"batl":[[1,1.03,59]],"ltp":1.01,"tv":21664.17,"id":9629022}]}]}
{"op":"mcm","clk":"4228399099","pt":1631461399614,"mc":[{"id":"1.187551081","rc":[{"batl":[[0,110,2.2]],"ltp":29.0,"tv":1753.48,"id":7445998}]}]}
{"op":"mcm","clk":"4228399305","pt":1631461400611,"mc":[{"id":"1.187551081","rc":[{"batb":[[2,34,2]],"batl":[[0,110,2]],"ltp":29.0,"tv":1753.48,"id":7445998},{"batl":[[0,1.02,1327.96],[1,1.03,1025.5]],"ltp":1.01,"tv":21664.17,"id":9629022}]}]}
{"op":"mcm","clk":"4228399485","pt":1631461401601,"mc":[{"id":"1.187551081","rc":[{"batb":[[2,34,4]],"ltp":29.0,"tv":1753.48,"id":7445998},{"batl":[[1,1.03,1031.67]],"ltp":1.01,"tv":21664.17,"id":9629022}]}]}
{"op":"mcm","clk":"4228399505","pt":1631461401720,"mc":[{"id":"1.187551081","rc":[{"batl":[[0,1.02,5.75]],"ltp":1.01,"tv":21664.17,"id":9629022}]}]}
{"op":"mcm","clk":"4228400020","pt":1631461404587,"mc":[{"id":"1.187551081","rc":[{"batl":[[1,1.03,2341.04]],"ltp":1.01,"tv":21664.17,"id":9629022}]}]}
{"op":"mcm","clk":"4228400834","pt":1631461409292,"mc":[{"id":"1.187551081","rc":[{"batb":[[0,36,2],[1,34,4],[2,30,12.06]],"ltp":29.0,"tv":1753.48,"id":7445998},{"batl":[[0,1.03,2341.04],[1,1.04,678.76],[2,1.05,512.08]],"ltp":1.01,"tv":21664.17,"id":9629022}]}]}
{"op":"mcm","clk":"4228401362","pt":1631461412429,"mc":[{"id":"1.187551081","rc":[{"batb":[[1,34,6]],"ltp":29.0,"tv":1753.48,"id":7445998},{"batb":[[0,1.01,2866.84]],"batl":[[1,1.04,5.88],[2,1.05,23.38]],"ltp":1.01,"tv":21664.17,"id":9629022}]}]}
{"op":"mcm","clk":"4228401540","pt":1631461413201,"mc":[{"id":"1.187551081","rc":[{"batb":[[2,30,5.36]],"ltp":29.0,"tv":1753.48,"id":7445998}]}]}
{"op":"mcm","clk":"4228401955","pt":1631461415356,"mc":[{"id":"1.187551081","rc":[{"batb":[[0,1.02,711.64],[1,1.01,2866.84]],"batl":[[2,1.05,38.57]],"ltp":1.01,"tv":21664.17,"id":9629022}]}]}
{"op":"mcm","clk":"4228402496","pt":1631461418556,"mc":[{"id":"1.187551081","rc":[{"batb":[[0,38,2],[1,36,2],[2,34,2]],"batl":[[0,100,2],[1,110,2],[2,990,0.01]],"ltp":29.0,"tv":1753.48,"id":7445998},{"batl":[[0,1.03,2334.87],[1,1.05,32.27],[2,1.09,11.86]],"ltp":1.01,"tv":21664.17,"id":9629022}]}]}
{"op":"mcm","clk":"4228403003","pt":1631461421552,"mc":[{"id":"1.187551081","rc":[{"batb":[[0,44,5.68],[1,38,2],[2,36,2]],"batl":[[0,70,3.14],[1,100,2],[2,110,2]],"ltp":29.0,"tv":1753.48,"id":7445998},{"trd":[[1.02,691.76]],"batb":[[0,1.02,635.84],[1,1.01,3425.23]],"batl":[[0,1.03,2833.59],[1,1.04,590.88],[2,1.05,520.17]],"ltp":1.02,"tv":21815.77,"id":9629022}],"tv":23569.25}]}
{"op":"mcm","clk":"4228403071","pt":1631461421965,"mc":[{"id":"1.187551081","rc":[{"batb":[[0,38,2],[1,36,2],[2,34,2]],"ltp":29.0,"tv":1753.48,"id":7445998},{"batl":[[1,1.04,597.01],[2,1.05,527.07]],"ltp":1.02,"tv":21815.77,"id":9629022}]}]}
{"op":"mcm","clk":"4228403623","pt":1631461425189,"mc":[{"id":"1.187551081","rc":[{"batb":[[1,34,4],[2,30,5.36]],"ltp":29.0,"tv":1753.48,"id":7445998},{"batb":[[0,1.02,669.75],[1,1.01,3467.53]],"batl":[[0,1.03,2840.09]],"ltp":1.02,"tv":21815.77,"id":9629022}]}]}
{"op":"mcm","clk":"4228404160","pt":1631461428390,"mc":[{"id":"1.187551081","rc":[{"batb":[[0,42,5.95],[1,38,2],[2,34,4]],"ltp":29.0,"tv":1753.48,"id":7445998}]}]}
{"op":"mcm","clk":"4228405942","pt":1631461438648,"mc":[{"id":"1.187551081","rc":[{"batb":[[0,1.02,675.91]],"ltp":1.02,"tv":21815.77,"id":9629022}]}]}
{"op":"mcm","clk":"4228406426","pt":1631461441359,"mc":[{"id":"1.187551081","rc":[{"trd":[[1.02,828.2]],"batb":[[0,1.02,607.69]],"ltp":1.02,"tv":21952.21,"id":9629022}],"tv":23705.69}]}
{"op":"mcm","clk":"4228407009","pt":1631461444877,"mc":[{"id":"1.187551081","rc":[{"batb":[[0,1.02,638.21],[1,1.01,3505.6]],"ltp":1.02,"tv":21952.21,"id":9629022}]}]}
{"op":"mcm","clk":"4228408282","pt":1631461452609,"mc":[{"id":"1.187551081","rc":[{"batb":[[0,1.02,6.16]],"batl":[[0,1.03,2778.62],[2,1.05,511.88]],"ltp":1.02,"tv":21952.21,"id":9629022}]}]}
{"op":"mcm","clk":"4228408792","pt":1631461455497,"mc":[{"id":"1.187551081","rc":[{"batb":[[1,1.01,4143.91]],"ltp":1.02,"tv":21952.21,"id":9629022}]}]}
{"op":"mcm","clk":"4228408909","pt":1631461456188,"mc":[{"id":"1.187551081","rc":[{"batl":[[0,65,2]],"ltp":29.0,"tv":1753.48,"id":7445998}]}]}
{"op":"mcm","clk":"4228409439","pt":1631461459287,"mc":[{"id":"1.187551081","rc":[{"batl":[[0,60,5.14],[1,65,2],[2,100,2]],"ltp":29.0,"tv":1753.48,"id":7445998}]}]}
{"op":"mcm","clk":"4228409830","pt":1631461461412,"mc":[{"id":"1.187551081","rc":[{"trd":[[1.02,840.52]],"batb":[[0,1.01,4143.91],[1,1.01,0]],"batl":[[0,1.02,55.81],[1,1.03,2778.62],[2,1.04,597.01]],"ltp":1.02,"tv":21964.53,"id":9629022}],"tv":23718.01}]}
{"op":"mcm","clk":"4228410392","pt":1631461464586,"mc":[{"id":"1.187551081","rc":[{"batb":[[0,34,4],[1,30,5.36],[2,26,4]],"batl":[[0,110,2],[1,990,0.01],[2,100,0]],"ltp":29.0,"tv":1753.48,"id":7445998},{"batb":[[0,1.01,3833.04]],"batl":[[0,1.03,2220.9],[1,1.04,597.01],[2,1.05,511.88]],"ltp":1.02,"tv":21964.53,"id":9629022}]}]}
{"op":"mcm","clk":"4228410440","pt":1631461464908,"mc":[{"id":"1.187551081","rc":[{"batb":[[0,1.01,3585.52]],"ltp":1.02,"tv":21964.53,"id":9629022}]}]}
{"op":"mcm","clk":"4228410870","pt":1631461467503,"mc":[{"id":"1.187551081","rc":[{"batb":[[0,1.01,2947.21]],"ltp":1.02,"tv":21964.53,"id":9629022}]}]}
{"op":"mcm","clk":"4228410899","pt":1631461467695,"mc":[{"id":"1.187551081","rc":[{"batb":[[0,30,5.36],[1,26,2],[2,4.7,377.56]],"batl":[[0,990,0.01],[1,990,0]],"ltp":29.0,"tv":1753.48,"id":7445998},{"batb":[[0,1.01,696.99]],"batl":[[0,1.03,1247.9],[1,1.04,590.88],[2,1.05,17.08]],"ltp":1.02,"tv":21964.53,"id":9629022}]}]}
{"op":"mcm","clk":"4228411339","pt":1631461470412,"mc":[{"id":"1.187551081","rc":[{"batb":[[0,1.02,632.05],[1,1.01,696.99]],"batl":[[0,1.03,1309.37]],"ltp":1.02,"tv":21964.53,"id":9629022}]}]}
{"op":"mcm","clk":"4228411441","pt":1631461470900,"mc":[{"id":"1.187551081","rc":[{"batb":[[0,30,7.36],[1,29,2],[2,26,2]],"ltp":29.0,"tv":1753.48,"id":7445998}]}]}
{"op":"mcm","clk":"4228411668","pt":1631461472231,"mc":[{"id":"1.187551081","rc":[{"batb":[[0,1.01,696.99],[1,1.01,0]],"batl":[[0,1.03,1247.9]],"ltp":1.02,"tv":21964.53,"id":9629022}]}]}
{"op":"mcm","clk":"4228411931","pt":1631461473640,"mc":[{"id":"1.187551081","rc":[{"batb":[[0,1.02,705.95],[1,1.01,696.99]],"batl":[[0,1.03,1947]],"ltp":1.02,"tv":21964.53,"id":9629022}]}]}
{"op":"mcm","clk":"4228411966","pt":1631461473829,"mc":[{"id":"1.187551081","rc":[{"batb":[[0,1.01,696.99],[1,1.01,0]],"batl":[[0,1.03,1247.9]],"ltp":1.02,"tv":21964.53,"id":9629022}]}]}
{"op":"mcm","clk":"4228412323","pt":1631461475641,"mc":[{"id":"1.187551081","rc":[{"batb":[[0,1.01,1335.3]],"ltp":1.02,"tv":21964.53,"id":9629022}]}]}
{"op":"mcm","clk":"4228413610","pt":1631461482950,"mc":[{"id":"1.187551081","rc":[{"batb":[[1,26,2],[2,4.7,377.56]],"ltp":29.0,"tv":1753.48,"id":7445998},{"batl":[[1,1.05,17.08],[2,1.09,11.86]],"ltp":1.02,"tv":21964.53,"id":9629022}]}]}
{"op":"mcm","clk":"4228414339","pt":1631461486667,"mc":[{"id":"1.187551081","rc":[{"batb":[[0,32,2],[1,30,2],[2,27,15.63]],"ltp":29.0,"tv":1753.48,"id":7445998},{"batb":[[0,1.02,1322.21]],"batl":[[2,1.06,15.05]],"ltp":1.02,"tv":21964.53,"id":9629022}]}]}
{"op":"mcm","clk":"4228414508","pt":1631461487541,"mc":[{"id":"1.187551081","rc":[{"batb":[[0,34,7.35],[1,32,2],[2,30,2]],"ltp":29.0,"tv":1753.48,"id":7445998},{"batb":[[1,1.01,5]],"batl":[[0,1.03,1490.45]],"ltp":1.02,"tv":21964.53,"id":9629022}]}]}
{"op":"mcm","clk":"4228414556","pt":1631461487836,"mc":[{"id":"1.187551081","rc":[{"batb":[[1,1.01,0]],"ltp":1.02,"tv":21964.53,"id":9629022}]}]}
{"op":"mcm","clk":"4228414784","pt":1631461489244,"mc":[{"id":"1.187551081","rc":[{"batl":[[0,50,2],[1,990,0.01]],"ltp":29.0,"tv":1753.48,"id":7445998}]}]}
{"op":"mcm","clk":"4228415020","pt":1631461490553,"mc":[{"id":"1.187551081","rc":[{"batl":[[1,60,7.58],[2,990,0.01]],"ltp":29.0,"tv":1753.48,"id":7445998},{"batl":[[1,1.04,1086.5],[2,1.05,17.08]],"ltp":1.02,"tv":21964.53,"id":9629022}]}]}
{"op":"mcm","clk":"4228415118","pt":1631461491062,"mc":[{"id":"1.187551081","rc":[{"batl":[[1,990,0.01],[2,990,0]],"ltp":29.0,"tv":1753.48,"id":7445998},{"batb":[[0,1.02,2168.06]],"batl":[[0,1.03,2161.19],[1,1.05,17.08],[2,1.06,15.05]],"ltp":1.02,"tv":21964.53,"id":9629022}]}]}
{"op":"mcm","clk":"4228415331","pt":1631461492277,"mc":[{"id":"1.187551081","rc":[{"batl":[[0,48,4.44],[1,50,2],[2,990,0.01]],"ltp":29.0,"tv":1753.48,"id":7445998}]}]}
{"op":"mcm","clk":"4228415548","pt":1631461493535,"mc":[{"id":"1.187551081","rc":[{"batl":[[0,48,2]],"ltp":29.0,"tv":1753.48,"id":7445998}]}]}
{"op":"mcm","clk":"4228416190","pt":1631461497268,"mc":[{"id":"1.187551081","rc":[{"batb":[[2,27,15.63]],"batl":[[0,46,2.44],[1,48,2],[2,50,2]],"ltp":29.0,"tv":1753.48,"id":7445998}]}]}
{"op":"mcm","clk":"4228416728","pt":1631461500486,"mc":[{"id":"1.187551081","rc":[{"batb":[[0,32,2],[1,27,15.63],[2,4.7,377.56]],"batl":[[0,990,0.01],[1,48,0],[2,50,0]],"ltp":29.0,"tv":1753.48,"id":7445998},{"batb":[[0,1.02,671.14]],"batl":[[0,1.05,17.08],[1,1.09,11.86],[2,1.11,11.86]],"ltp":1.02,"tv":21964.53,"id":9629022}]}]}
{"op":"mcm","clk":"4228417301","pt":1631461503380,"mc":[{"id":"1.187551081","rc":[{"batb":[[1,30,2],[2,27,15.63]],"ltp":29.0,"tv":1753.48,"id":7445998},{"batb":[[1,1.01,657.52]],"batl":[[0,1.04,1348.79],[1,1.05,17.08],[2,1.09,11.86]],"ltp":1.02,"tv":21964.53,"id":9629022}]}]}
{"op":"mcm","clk":"4228417710","pt":1631461505561,"mc":[{"id":"1.187551081","rc":[{"batb":[[0,1.02,550.43],[1,1.01,0]],"ltp":1.02,"tv":21964.53,"id":9629022}]}]}
{"op":"mcm","clk":"4228418244","pt":1631461508478,"mc":[{"id":"1.187551081","rc":[{"batb":[[0,27,15.63],[1,4.7,377.56],[2,1.01,30]],"ltp":29.0,"tv":1753.48,"id":7445998},{"batb":[[0,1.03,764.28],[1,1.02,550.43]],"batl":[[2,1.06,15.05]],"ltp":1.02,"tv":21964.53,"id":9629022}]}]}
{"op":"mcm","clk":"4228418427","pt":1631461509472,"mc":[{"id":"1.187551081","rc":[{"batb":[[1,23,14.24],[2,4.7,377.56]],"ltp":29.0,"tv":1753.48,"id":7445998}]}]}
{"op":"mcm","clk":"4228418605","pt":1631461510552,"mc":[{"id":"1.187551081","rc":[{"batb":[[0,32,3.17],[1,27,15.63],[2,23,14.24]],"batl":[[0,50,2],[1,990,0.01]],"ltp":29.0,"tv":1753.48,"id":7445998},{"batb":[[1,1.02,795.53]],"batl":[[0,1.04,1589.17]],"ltp":1.02,"tv":21964.53,"id":9629022}]}]}
{"op":"mcm","clk":"4228418672","pt":1631461510878,"mc":[{"id":"1.187551081","rc":[{"batb":[[0,28,2],[1,27,17.63]],"ltp":29.0,"tv":1753.48,"id":7445998}]}]}
{"op":"mcm","clk":"4228419106","pt":1631461513664,"mc":[{"id":"1.187551081","rc":[{"batb":[[0,1.03,1294.65]],"batl":[[0,1.04,2059.47]],"ltp":1.02,"tv":21964.53,"id":9629022}]}]}
{"op":"mcm","clk":"4228419175","pt":1631461514081,"mc":[{"id":"1.187551081","rc":[{"batb":[[0,29,7.59],[1,28,2],[2,27,17.63]],"batl":[[0,44,4.79],[1,50,2],[2,990,0.01]],"ltp":29.0,"tv":1753.48,"id":7445998}]}]}
{"op":"mcm","clk":"4228419570","pt":1631461516454,"mc":[{"id":"1.187551081","rc":[{"batb":[[0,23,14.24],[1,4.7,377.56],[2,1.01,30]],"batl":[[0,990,0.01],[1,50,0],[2,990,0]],"ltp":29.0,"tv":1753.48,"id":7445998},{"batb":[[0,1.02,1093.12],[1,1.02,0]],"batl":[[0,1.04,599.32],[2,1.11,11.86]],"ltp":1.02,"tv":21964.53,"id":9629022}]}]}
{"op":"mcm","clk":"4228419606","pt":1631461516715,"mc":[{"id":"1.187551081","rc":[{"batb":[[0,1.02,550.43]],"ltp":1.02,"tv":21964.53,"id":9629022}]}]}
{"op":"mcm","clk":"4228420091","pt":1631461519593,"mc":[{"id":"1.187551081","rc":[{"trd":[[1.04,2312.64]],"batb":[[0,1.02,1322.21]],"batl":[[0,1.04,348.11],[1,1.05,707.9]],"ltp":1.04,"tv":22466.95,"id":9629022}],"tv":24220.43}]}
{"op":"mcm","clk":"4228420722","pt":1631461523184,"mc":[{"id":"1.187551081","rc":[{"batl":[[0,1.04,460.5],[1,1.05,845.4]],"ltp":1.04,"tv":22466.95,"id":9629022}]}]}
{"op":"mcm","clk":"4228421006","pt":1631461524782,"mc":[{"id":"1.187551081","rc":[{"batl":[[1,1.05,17.08]],"ltp":1.04,"tv":22466.95,"id":9629022}]}]}
{"op":"mcm","clk":"4228421640","pt":1631461528499,"mc":[{"id":"1.187551081","rc":[{"batb":[[0,25,20.22],[1,23,14.24],[2,4.7,377.56]],"ltp":29.0,"tv":1753.48,"id":7445998},{"batl":[[0,1.03,755.28],[1,1.04,548.76],[2,1.05,17.08]],"ltp":1.04,"tv":22466.95,"id":9629022}]}]}
{"op":"mcm","clk":"4228421694","pt":1631461528815,"mc":[{"id":"1.187551081","rc":[{"batb":[[1,4.7,377.56],[2,1.01,30]],"ltp":29.0,"tv":1753.48,"id":7445998}]}]}
{"op":"mcm","clk":"4228421957","pt":1631461530108,"mc":[{"id":"1.187551081","rc":[{"batb":[[0,34,7.35],[1,27,2],[2,26,2]],"batl":[[0,50,2],[1,990,0.01]],"ltp":29.0,"tv":1753.48,"id":7445998},{"batb":[[0,1.02,1494.63]],"batl":[[0,1.03,991.19]],"ltp":1.04,"tv":22466.95,"id":9629022}]}]}
{"op":"mcm","clk":"4228422396","pt":1631461532592,"mc":[{"id":"1.187551081","rc":[{"batl":[[1,60,9.08],[2,990,0.01]],"ltp":29.0,"tv":1753.48,"id":7445998},{"batl":[[1,1.04,1597.13]],"ltp":1.04,"tv":22466.95,"id":9629022}]}]}
{"op":"mcm","clk":"4228422586","pt":1631461533593,"mc":[{"id":"1.187551081","rc":[{"batl":[[0,48,2],[1,50,2]],"ltp":29.0,"tv":1753.48,"id":7445998},{"batb":[[0,1.02,2021.42]],"batl":[[0,1.03,1453.98],[1,1.04,548.76]],"ltp":1.04,"tv":22466.95,"id":9629022}]}]}
{"op":"mcm","clk":"4228422678","pt":1631461534204,"mc":[{"id":"1.187551081","rc":[{"batb":[[2,26,6]],"batl":[[2,110,2]],"ltp":29.0,"tv":1753.48,"id":7445998},{"batb":[[1,1.01,2408.01]],"batl":[[1,1.04,1109.52],[2,1.05,477.48]],"ltp":1.04,"tv":22466.95,"id":9629022}]}]}
{"op":"mcm","clk":"4228423120","pt":1631461536720,"mc":[{"id":"1.187551081","rc":[{"batl":[[0,46,2.54],[1,48,2],[2,50,2]],"ltp":29.0,"tv":1753.48,"id":7445998}]}]}
