{"op":"mcm","clk":"4232350271","pt":1631518387236,"mc":[{"id":"1.187594318","marketDefinition":{"bspMarket":false,"turnInPlayEnabled":true,"persistenceEnabled":true,"marketBaseRate":5.0,"eventId":"30897871","eventTypeId":"2","numberOfWinners":1,"bettingType":"ODDS","marketType":"MATCH_ODDS","marketTime":"2021-09-13T07:30:00.000Z","suspendTime":"2021-09-13T07:30:00.000Z","bspReconciled":false,"complete":true,"inPlay":false,"crossMatching":false,"runnersVoidable":false,"numberOfActiveRunners":2,"betDelay":0,"status":"OPEN","runners":[{"status":"ACTIVE","sortPriority":1,"id":9183341,"name":"E Silva"},{"status":"ACTIVE","sortPriority":2,"id":9628686,"name":"H Kuwata"}],"regulators":["MR_INT"],"countryCode":"GB","discountAllowed":false,"timezone":"GMT","openDate":"2021-09-13T10:30:00.000Z","version":4030164793,"name":"Match Odds","eventName":"E Silva v H Kuwata"},"rc":[{"batb":[[0,1.01,25]],"ltp":0.0,"tv":0.0,"id":9183341},{"batb":[[0,1.01,25]],"ltp":0.0,"tv":0.0,"id":9628686}]}]}
{"op":"mcm","clk":"4232350344","pt":1631518388646,"mc":[{"id":"1.187594318","marketDefinition":{"bspMarket":false,"turnInPlayEnabled":true,"persistenceEnabled":true,"marketBaseRate":5.0,"eventId":"30897871","eventTypeId":"2","numberOfWinners":1,"bettingType":"ODDS","marketType":"MATCH_ODDS","marketTime":"2021-09-13T07:30:00.000Z","suspendTime":"2021-09-13T07:30:00.000Z","bspReconciled":false,"complete":true,"inPlay":false,"crossMatching":false,"runnersVoidable":false,"numberOfActiveRunners":2,"betDelay":0,"status":"OPEN","runners":[{"status":"ACTIVE","sortPriority":1,"id":9183341,"name":"E Silva"},{"status":"ACTIVE","sortPriority":2,"id":9628686,"name":"H Kuwata"}],"regulators":["MR_INT"],"countryCode":"GB","discountAllowed":true,"timezone":"GMT","openDate":"2021-09-13T10:30:00.000Z","version":4030164793,"name":"Match Odds","eventName":"E Silva v H Kuwata"}}]}
{"op":"mcm","clk":"4232396324","pt":1631519122003,"mc":[{"id":"1.187594318","rc":[{"batb":[[0,1.01,7]],"ltp":0.0,"tv":0.0,"id":9183341},{"batb":[[0,1.01,7]],"ltp":0.0,"tv":0.0,"id":9628686}]}]}
{"op":"mcm","clk":"4232412091","pt":1631519274738,"mc":[{"id":"1.187594318","rc":[{"batb":[[0,1.05,880.88],[1,1.01,7]],"ltp":0.0,"tv":0.0,"id":9183341},{"batb":[[0,1.05,880.88],[1,1.01,7]],"ltp":0.0,"tv":0.0,"id":9628686}]}]}
{"op":"mcm","clk":"4232607878","pt":1631522432785,"mc":[{"id":"1.187594318","rc":[{"batl":[[0,1.83,2.66]],"ltp":0.0,"tv":0.0,"id":9183341}]}]}
{"op":"mcm","clk":"4232608120","pt":1631522437461,"mc":[{"id":"1.187594318","rc":[{"batb":[[0,1.05,923.47]],"ltp":0.0,"tv":0.0,"id":9183341}]}]}
{"op":"mcm","clk":"4232626383","pt":1631522762130,"mc":[{"id":"1.187594318","marketDefinition":{"bspMarket":false,"turnInPlayEnabled":true,"persistenceEnabled":true,"marketBaseRate":5.0,"eventId":"30897871","eventTypeId":"2","numberOfWinners":1,"bettingType":"ODDS","marketType":"MATCH_ODDS","marketTime":"2021-09-13T11:00:00.000Z","suspendTime":"2021-09-13T11:00:00.000Z","bspReconciled":false,"complete":true,"inPlay":false,"crossMatching":false,"runnersVoidable":false,"numberOfActiveRunners":2,"betDelay":0,"status":"OPEN","runners":[{"status":"ACTIVE","sortPriority":1,"id":9183341,"name":"E Silva"},{"status":"ACTIVE","sortPriority":2,"id":9628686,"name":"H Kuwata"}],"regulators":["MR_INT"],"countryCode":"GB","discountAllowed":true,"timezone":"GMT","openDate":"2021-09-13T10:30:00.000Z","version":4030340772,"name":"Match Odds","eventName":"E Silva v H Kuwata"}}]}
{"op":"mcm","clk":"4232626492","pt":1631522764138,"mc":[{"id":"1.187594318","marketDefinition":{"bspMarket":false,"turnInPlayEnabled":true,"persistenceEnabled":true,"marketBaseRate":5.0,"eventId":"30897871","eventTypeId":"2","numberOfWinners":1,"bettingType":"ODDS","marketType":"MATCH_ODDS","marketTime":"2021-09-13T11:00:00.000Z","suspendTime":"2021-09-13T11:00:00.000Z","bspReconciled":false,"complete":true,"inPlay":false,"crossMatching":false,"runnersVoidable":false,"numberOfActiveRunners":2,"betDelay":0,"status":"OPEN","runners":[{"status":"ACTIVE","sortPriority":1,"id":9183341,"name":"E Silva"},{"status":"ACTIVE","sortPriority":2,"id":9628686,"name":"H Kuwata"}],"regulators":["MR_INT"],"countryCode":"GB","discountAllowed":true,"timezone":"GMT","openDate":"2021-09-13T11:00:00.000Z","version":4030340772,"name":"Match Odds","eventName":"E Silva v H Kuwata"}}]}
{"op":"mcm","clk":"4232673415","pt":1631523785964,"mc":[{"id":"1.187594318","rc":[{"batb":[[0,1.29,144.02],[1,1.05,922.98],[2,1.01,7]],"batl":[[0,1.83,2.66]],"ltp":0.0,"tv":0.0,"id":9183341},{"batb":[[0,3.25,18.56],[1,1.05,880.36],[2,1.01,7]],"ltp":0.0,"tv":0.0,"id":9628686}]}]}
{"op":"mcm","clk":"4232673808","pt":1631523791457,"mc":[{"id":"1.187594318","marketDefinition":{"bspMarket":false,"turnInPlayEnabled":true,"persistenceEnabled":true,"marketBaseRate":5.0,"eventId":"30897871","eventTypeId":"2","numberOfWinners":1,"bettingType":"ODDS","marketType":"MATCH_ODDS","marketTime":"2021-09-13T11:00:00.000Z","suspendTime":"2021-09-13T11:00:00.000Z","bspReconciled":false,"complete":true,"inPlay":false,"crossMatching":true,"runnersVoidable":false,"numberOfActiveRunners":2,"betDelay":0,"status":"OPEN","runners":[{"status":"ACTIVE","sortPriority":1,"id":9183341,"name":"E Silva"},{"status":"ACTIVE","sortPriority":2,"id":9628686,"name":"H Kuwata"}],"regulators":["MR_INT"],"countryCode":"GB","discountAllowed":true,"timezone":"GMT","openDate":"2021-09-13T11:00:00.000Z","version":4030340772,"name":"Match Odds","eventName":"E Silva v H Kuwata"}}]}
{"op":"mcm","clk":"4232816529","pt":1631526206614,"mc":[{"id":"1.187594318","marketDefinition":{"bspMarket":false,"turnInPlayEnabled":true,"persistenceEnabled":true,"marketBaseRate":5.0,"eventId":"30897871","eventTypeId":"2","numberOfWinners":1,"bettingType":"ODDS","marketType":"MATCH_ODDS","marketTime":"2021-09-13T11:15:00.000Z","suspendTime":"2021-09-13T11:15:00.000Z","bspReconciled":false,"complete":true,"inPlay":false,"crossMatching":true,"runnersVoidable":false,"numberOfActiveRunners":2,"betDelay":0,"status":"OPEN","runners":[{"status":"ACTIVE","sortPriority":1,"id":9183341,"name":"E Silva"},{"status":"ACTIVE","sortPriority":2,"id":9628686,"name":"H Kuwata"}],"regulators":["MR_INT"],"countryCode":"GB","discountAllowed":true,"timezone":"GMT","openDate":"2021-09-13T11:00:00.000Z","version":4030512628,"name":"Match Odds","eventName":"E Silva v H Kuwata"}}]}
{"op":"mcm","clk":"4232816672","pt":1631526208625,"mc":[{"id":"1.187594318","marketDefinition":{"bspMarket":false,"turnInPlayEnabled":true,"persistenceEnabled":true,"marketBaseRate":5.0,"eventId":"30897871","eventTypeId":"2","numberOfWinners":1,"bettingType":"ODDS","marketType":"MATCH_ODDS","marketTime":"2021-09-13T11:15:00.000Z","suspendTime":"2021-09-13T11:15:00.000Z","bspReconciled":false,"complete":true,"inPlay":false,"crossMatching":true,"runnersVoidable":false,"numberOfActiveRunners":2,"betDelay":0,"status":"OPEN","runners":[{"status":"ACTIVE","sortPriority":1,"id":9183341,"name":"E Silva"},{"status":"ACTIVE","sortPriority":2,"id":9628686,"name":"H Kuwata"}],"regulators":["MR_INT"],"countryCode":"GB","discountAllowed":true,"timezone":"GMT","openDate":"2021-09-13T11:15:00.000Z","version":4030512628,"name":"Match Odds","eventName":"E Silva v H Kuwata"}}]}
{"op":"mcm","clk":"4232907396","pt":1631527851929,"mc":[{"id":"1.187594318","marketDefinition":{"bspMarket":false,"turnInPlayEnabled":true,"persistenceEnabled":true,"marketBaseRate":5.0,"eventId":"30897871","eventTypeId":"2","numberOfWinners":1,"bettingType":"ODDS","marketType":"MATCH_ODDS","marketTime":"2021-09-13T11:35:00.000Z","suspendTime":"2021-09-13T11:35:00.000Z","bspReconciled":false,"complete":true,"inPlay":false,"crossMatching":true,"runnersVoidable":false,"numberOfActiveRunners":2,"betDelay":0,"status":"OPEN","runners":[{"status":"ACTIVE","sortPriority":1,"id":9183341,"name":"E Silva"},{"status":"ACTIVE","sortPriority":2,"id":9628686,"name":"H Kuwata"}],"regulators":["MR_INT"],"countryCode":"GB","discountAllowed":true,"timezone":"GMT","openDate":"2021-09-13T11:15:00.000Z","version":4030529126,"name":"Match Odds","eventName":"E Silva v H Kuwata"}}]}
{"op":"mcm","clk":"4232907488","pt":1631527853934,"mc":[{"id":"1.187594318","marketDefinition":{"bspMarket":false,"turnInPlayEnabled":true,"persistenceEnabled":true,"marketBaseRate":5.0,"eventId":"30897871","eventTypeId":"2","numberOfWinners":1,"bettingType":"ODDS","marketType":"MATCH_ODDS","marketTime":"2021-09-13T11:35:00.000Z","suspendTime":"2021-09-13T11:35:00.000Z","bspReconciled":false,"complete":true,"inPlay":false,"crossMatching":true,"runnersVoidable":false,"numberOfActiveRunners":2,"betDelay":0,"status":"OPEN","runners":[{"status":"ACTIVE","sortPriority":1,"id":9183341,"name":"E Silva"},{"status":"ACTIVE","sortPriority":2,"id":9628686,"name":"H Kuwata"}],"regulators":["MR_INT"],"countryCode":"GB","discountAllowed":true,"timezone":"GMT","openDate":"2021-09-13T11:35:00.000Z","version":4030529126,"name":"Match Odds","eventName":"E Silva v H Kuwata"}}]}
{"op":"mcm","clk":"4233007085","pt":1631529300855,"mc":[{"id":"1.187594318","rc":[{"batb":[[0,1.3,42.67],[1,1.29,144.02],[2,1.05,922.98]],"ltp":0.0,"tv":0.0,"id":9183341},{"batb":[[0,3.3,5.56],[1,3.25,18.56],[2,1.05,880.36]],"ltp":0.0,"tv":0.0,"id":9628686}]}]}
{"op":"mcm","clk":"4233012558","pt":1631529363821,"mc":[{"id":"1.187594318","rc":[{"batb":[[2,1.01,7]],"ltp":0.0,"tv":0.0,"id":9628686}]}]}
{"op":"mcm","clk":"4233013192","pt":1631529370643,"mc":[{"id":"1.187594318","rc":[{"batl":[[0,1.81,44.02],[1,1.83,2.66]],"ltp":0.0,"tv":0.0,"id":9183341}]}]}
{"op":"mcm","clk":"4233034017","pt":1631529725179,"mc":[{"id":"1.187594318","rc":[{"batl":[[0,1.43,50],[1,1.81,44.02],[2,1.83,2.66]],"ltp":0.0,"tv":0.0,"id":9183341}]}]}
{"op":"mcm","clk":"4233034767","pt":1631529739322,"mc":[{"id":"1.187594318","rc":[{"batl":[[1,1.57,50],[2,1.81,44.02]],"ltp":0.0,"tv":0.0,"id":9183341}]}]}
{"op":"mcm","clk":"4233069993","pt":1631530159543,"mc":[{"id":"1.187594318","rc":[{"batb":[[0,1.3,181.89],[1,1.05,922.98],[2,1.01,7]],"ltp":0.0,"tv":0.0,"id":9183341},{"batb":[[1,3.2,18.98]],"ltp":0.0,"tv":0.0,"id":9628686}]}]}
{"op":"mcm","clk":"4233101359","pt":1631530597289,"mc":[{"id":"1.187594318","marketDefinition":{"bspMarket":false,"turnInPlayEnabled":true,"persistenceEnabled":true,"marketBaseRate":5.0,"eventId":"30897871","eventTypeId":"2","numberOfWinners":1,"bettingType":"ODDS","marketType":"MATCH_ODDS","marketTime":"2021-09-13T11:00:00.000Z","suspendTime":"2021-09-13T11:00:00.000Z","bspReconciled":false,"complete":true,"inPlay":false,"crossMatching":true,"runnersVoidable":false,"numberOfActiveRunners":2,"betDelay":0,"status":"OPEN","runners":[{"status":"ACTIVE","sortPriority":1,"id":9183341,"name":"E Silva"},{"status":"ACTIVE","sortPriority":2,"id":9628686,"name":"H Kuwata"}],"regulators":["MR_INT"],"countryCode":"GB","discountAllowed":true,"timezone":"GMT","openDate":"2021-09-13T11:35:00.000Z","version":4030566533,"name":"Match Odds","eventName":"E Silva v H Kuwata"}}]}
{"op":"mcm","clk":"4233103169","pt":1631530622442,"mc":[{"id":"1.187594318","marketDefinition":{"bspMarket":false,"turnInPlayEnabled":true,"persistenceEnabled":true,"marketBaseRate":5.0,"eventId":"30897871","eventTypeId":"2","numberOfWinners":1,"bettingType":"ODDS","marketType":"MATCH_ODDS","marketTime":"2021-09-13T11:00:00.000Z","suspendTime":"2021-09-13T11:00:00.000Z","bspReconciled":false,"complete":true,"inPlay":false,"crossMatching":true,"runnersVoidable":false,"numberOfActiveRunners":2,"betDelay":0,"status":"OPEN","runners":[{"status":"ACTIVE","sortPriority":1,"id":9183341,"name":"E Silva"},{"status":"ACTIVE","sortPriority":2,"id":9628686,"name":"H Kuwata"}],"regulators":["MR_INT"],"countryCode":"GB","discountAllowed":true,"timezone":"GMT","openDate":"2021-09-13T11:00:00.000Z","version":4030566533,"name":"Match Odds","eventName":"E Silva v H Kuwata"}}]}
{"op":"mcm","clk":"4233105517","pt":1631530654980,"mc":[{"id":"1.187594318","rc":[{"batb":[[1,1.29,2.66],[2,1.05,922.98]],"ltp":0.0,"tv":0.0,"id":9183341},{"batb":[[1,3.25,2.66],[2,3.2,18.98]],"ltp":0.0,"tv":0.0,"id":9628686}]}]}
{"op":"mcm","clk":"4233119327","pt":1631530857316,"mc":[{"id":"1.187594318","marketDefinition":{"bspMarket":false,"turnInPlayEnabled":true,"persistenceEnabled":true,"marketBaseRate":5.0,"eventId":"30897871","eventTypeId":"2","numberOfWinners":1,"bettingType":"ODDS","marketType":"MATCH_ODDS","marketTime":"2021-09-13T11:00:00.000Z","suspendTime":"2021-09-13T11:00:00.000Z","bspReconciled":false,"complete":true,"inPlay":true,"crossMatching":true,"runnersVoidable":false,"numberOfActiveRunners":2,"betDelay":5,"status":"OPEN","runners":[{"status":"ACTIVE","sortPriority":1,"id":9183341,"name":"E Silva"},{"status":"ACTIVE","sortPriority":2,"id":9628686,"name":"H Kuwata"}],"regulators":["MR_INT"],"countryCode":"GB","discountAllowed":true,"timezone":"GMT","openDate":"2021-09-13T11:00:00.000Z","version":4030570054,"name":"Match Odds","eventName":"E Silva v H Kuwata"},"rc":[{"batb":[[0,1.01,7],[1,1.29,0],[2,1.05,0]],"batl":[[2,1.81,0]],"ltp":0.0,"tv":0.0,"id":9183341},{"batb":[[0,1.01,7],[1,3.25,0],[2,3.2,0]],"ltp":0.0,"tv":0.0,"id":9628686}]}]}
{"op":"mcm","clk":"4233183184","pt":1631531630827,"mc":[{"id":"1.187594318","marketDefinition":{"bspMarket":false,"turnInPlayEnabled":true,"persistenceEnabled":true,"marketBaseRate":5.0,"eventId":"30897871","eventTypeId":"2","numberOfWinners":1,"bettingType":"ODDS","marketType":"MATCH_ODDS","marketTime":"2021-09-13T11:10:00.000Z","suspendTime":"2021-09-13T11:10:00.000Z","bspReconciled":false,"complete":true,"inPlay":true,"crossMatching":true,"runnersVoidable":false,"numberOfActiveRunners":2,"betDelay":5,"status":"OPEN","runners":[{"status":"ACTIVE","sortPriority":1,"id":9183341,"name":"E Silva"},{"status":"ACTIVE","sortPriority":2,"id":9628686,"name":"H Kuwata"}],"regulators":["MR_INT"],"countryCode":"GB","discountAllowed":true,"timezone":"GMT","openDate":"2021-09-13T11:00:00.000Z","version":4030580895,"name":"Match Odds","eventName":"E Silva v H Kuwata"}}]}
{"op":"mcm","clk":"4233183424","pt":1631531633842,"mc":[{"id":"1.187594318","marketDefinition":{"bspMarket":false,"turnInPlayEnabled":true,"persistenceEnabled":true,"marketBaseRate":5.0,"eventId":"30897871","eventTypeId":"2","numberOfWinners":1,"bettingType":"ODDS","marketType":"MATCH_ODDS","marketTime":"2021-09-13T11:10:00.000Z","suspendTime":"2021-09-13T11:10:00.000Z","bspReconciled":false,"complete":true,"inPlay":true,"crossMatching":true,"runnersVoidable":false,"numberOfActiveRunners":2,"betDelay":5,"status":"OPEN","runners":[{"status":"ACTIVE","sortPriority":1,"id":9183341,"name":"E Silva"},{"status":"ACTIVE","sortPriority":2,"id":9628686,"name":"H Kuwata"}],"regulators":["MR_INT"],"countryCode":"GB","discountAllowed":true,"timezone":"GMT","openDate":"2021-09-13T11:10:00.000Z","version":4030580895,"name":"Match Odds","eventName":"E Silva v H Kuwata"}}]}
{"op":"mcm","clk":"4233198409","pt":1631531818831,"mc":[{"id":"1.187594318","marketDefinition":{"bspMarket":false,"turnInPlayEnabled":true,"persistenceEnabled":true,"marketBaseRate":5.0,"eventId":"30897871","eventTypeId":"2","numberOfWinners":1,"bettingType":"ODDS","marketType":"MATCH_ODDS","marketTime":"2021-09-13T11:16:57.000Z","suspendTime":"2021-09-13T11:16:57.000Z","bspReconciled":false,"complete":true,"inPlay":true,"crossMatching":true,"runnersVoidable":false,"numberOfActiveRunners":2,"betDelay":5,"status":"OPEN","runners":[{"status":"ACTIVE","sortPriority":1,"id":9183341,"name":"E Silva"},{"status":"ACTIVE","sortPriority":2,"id":9628686,"name":"H Kuwata"}],"regulators":["MR_INT"],"countryCode":"GB","discountAllowed":true,"timezone":"GMT","openDate":"2021-09-13T11:10:00.000Z","version":4030582385,"name":"Match Odds","eventName":"E Silva v H Kuwata"}}]}
{"op":"mcm","clk":"4233198580","pt":1631531820848,"mc":[{"id":"1.187594318","marketDefinition":{"bspMarket":false,"turnInPlayEnabled":true,"persistenceEnabled":true,"marketBaseRate":5.0,"eventId":"30897871","eventTypeId":"2","numberOfWinners":1,"bettingType":"ODDS","marketType":"MATCH_ODDS","marketTime":"2021-09-13T11:16:57.000Z","suspendTime":"2021-09-13T11:16:57.000Z","bspReconciled":false,"complete":true,"inPlay":true,"crossMatching":true,"runnersVoidable":false,"numberOfActiveRunners":2,"betDelay":5,"status":"OPEN","runners":[{"status":"ACTIVE","sortPriority":1,"id":9183341,"name":"E Silva"},{"status":"ACTIVE","sortPriority":2,"id":9628686,"name":"H Kuwata"}],"regulators":["MR_INT"],"countryCode":"GB","discountAllowed":true,"timezone":"GMT","openDate":"2021-09-13T11:16:57.000Z","version":4030582385,"name":"Match Odds","eventName":"E Silva v H Kuwata"}}]}
{"op":"mcm","clk":"4233201625","pt":1631531860609,"mc":[{"id":"1.187594318","rc":[{"batl":[[0,1.57,50],[1,1.57,0]],"ltp":0.0,"tv":0.0,"id":9183341}]}]}
{"op":"mcm","clk":"4233202048","pt":1631531865815,"mc":[{"id":"1.187594318","rc":[{"batl":[[0,1.5,50],[1,1.57,50]],"ltp":0.0,"tv":0.0,"id":9183341}]}]}
{"op":"mcm","clk":"4233205790","pt":1631531919593,"mc":[{"id":"1.187594318","rc":[{"trd":[[1.5,48.64]],"batl":[[0,1.5,1.36]],"ltp":1.5,"tv":48.64,"id":9183341},{"trd":[[3,24.32]],"ltp":3.0,"tv":24.32,"id":9628686}],"tv":72.96}]}
{"op":"mcm","clk":"4233205925","pt":1631531921571,"mc":[{"id":"1.187594318","rc":[{"trd":[[1.5,50]],"batl":[[0,1.57,50],[1,1.57,0]],"ltp":1.5,"tv":50.0,"id":9183341},{"trd":[[3,25]],"ltp":3.0,"tv":25.0,"id":9628686}],"tv":75.0}]}
{"op":"mcm","clk":"4233207564","pt":1631531944490,"mc":[{"id":"1.187594318","rc":[{"trd":[[1.57,50]],"ltp":1.57,"tv":100.0,"id":9183341},{"trd":[[2.74,28.65]],"batl":[[0,2.74,14.8]],"ltp":2.74,"tv":53.65,"id":9628686}],"tv":153.65}]}
{"op":"mcm","clk":"4233208136","pt":1631531952516,"mc":[{"id":"1.187594318","rc":[{"batl":[[0,2.74,7.06]],"ltp":2.74,"tv":53.65,"id":9628686}]}]}
{"op":"mcm","clk":"4233211385","pt":1631531998574,"mc":[{"id":"1.187594318","rc":[{"batl":[[0,2.74,3.62]],"ltp":2.74,"tv":53.65,"id":9628686}]}]}
{"op":"mcm","clk":"4233233598","pt":1631532317191,"mc":[{"id":"1.187594318","rc":[{"batb":[[0,1.22,108.48],[1,1.01,7]],"ltp":2.74,"tv":53.65,"id":9628686}]}]}
{"op":"mcm","clk":"4233254520","pt":1631532614619,"mc":[{"id":"1.187594318","rc":[{"batb":[[0,1.11,216.97],[1,1.01,7]],"ltp":1.57,"tv":100.0,"id":9183341}]}]}
{"op":"mcm","clk":"4233309366","pt":1631533272492,"mc":[{"id":"1.187594318","rc":[{"trd":[[1.22,55.12]],"batb":[[0,1.22,80.92]],"ltp":1.22,"tv":108.77,"id":9628686}],"tv":208.77}]}
{"op":"mcm","clk":"4233311668","pt":1631533307388,"mc":[{"id":"1.187594318","rc":[{"batl":[[0,1.7,20.25],[1,2.74,3.62]],"ltp":1.22,"tv":108.77,"id":9628686}]}]}
{"op":"mcm","clk":"4233312975","pt":1631533327201,"mc":[{"id":"1.187594318","rc":[{"batb":[[0,1.01,7],[1,1.01,0]],"ltp":1.22,"tv":108.77,"id":9628686}]}]}
{"op":"mcm","clk":"4233313287","pt":1631533332316,"mc":[{"id":"1.187594318","rc":[{"batb":[[0,1.14,80.92],[1,1.01,7]],"ltp":1.22,"tv":108.77,"id":9628686}]}]}
{"op":"mcm","clk":"4233313718","pt":1631533338315,"mc":[{"id":"1.187594318","rc":[{"batl":[[0,2.74,3.62],[1,2.74,0]],"ltp":1.22,"tv":108.77,"id":9628686}]}]}
{"op":"mcm","clk":"4233314055","pt":1631533343417,"mc":[{"id":"1.187594318","rc":[{"batl":[[0,1.6,20.25],[1,2.74,3.62]],"ltp":1.22,"tv":108.77,"id":9628686}]}]}
{"op":"mcm","clk":"4233314345","pt":1631533348247,"mc":[{"id":"1.187594318","rc":[{"batl":[[0,2.74,3.62],[1,2.74,0]],"ltp":1.22,"tv":108.77,"id":9628686}]}]}
{"op":"mcm","clk":"4233314507","pt":1631533350553,"mc":[{"id":"1.187594318","rc":[{"batb":[[0,1.6,10.39],[1,1.14,80.92],[2,1.01,7]],"ltp":1.22,"tv":108.77,"id":9628686}]}]}
{"op":"mcm","clk":"4233314709","pt":1631533353439,"mc":[{"id":"1.187594318","rc":[{"batl":[[0,1.68,20.25],[1,2.74,3.62]],"ltp":1.22,"tv":108.77,"id":9628686}]}]}
{"op":"mcm","clk":"4233314723","pt":1631533353644,"mc":[{"id":"1.187594318","rc":[{"batb":[[0,1.14,80.92],[1,1.01,7],[2,1.01,0]],"ltp":1.22,"tv":108.77,"id":9628686}]}]}
{"op":"mcm","clk":"4233316140","pt":1631533375191,"mc":[{"id":"1.187594318","rc":[{"trd":[[2.46,13.82]],"ltp":2.46,"tv":113.82,"id":9183341},{"trd":[[1.68,20.24]],"batl":[[0,2.74,3.62],[1,2.74,0]],"ltp":1.68,"tv":129.01,"id":9628686}],"tv":242.84}]}
{"op":"mcm","clk":"4233334821","pt":1631533612728,"mc":[{"id":"1.187594318","rc":[{"batb":[[0,1.7,10.85],[1,1.11,216.97],[2,1.01,7]],"ltp":2.46,"tv":113.82,"id":9183341}]}]}
{"op":"mcm","clk":"4233350295","pt":1631533810870,"mc":[{"id":"1.187594318","rc":[{"batb":[[0,1.2,29.05],[1,1.14,80.92],[2,1.01,7]],"ltp":1.68,"tv":129.01,"id":9628686}]}]}
{"op":"mcm","clk":"4233350944","pt":1631533819387,"mc":[{"id":"1.187594318","rc":[{"batb":[[1,1.01,7],[2,1.01,0]],"ltp":1.68,"tv":129.01,"id":9628686}]}]}
{"op":"mcm","clk":"4233351393","pt":1631533824473,"mc":[{"id":"1.187594318","rc":[{"batb":[[0,1.22,80.92],[1,1.2,29.05],[2,1.01,7]],"ltp":1.68,"tv":129.01,"id":9628686}]}]}
{"op":"mcm","clk":"4233352050","pt":1631533832816,"mc":[{"id":"1.187594318","rc":[{"batb":[[1,1.01,7],[2,1.01,0]],"ltp":1.68,"tv":129.01,"id":9628686}]}]}
{"op":"mcm","clk":"4233352427","pt":1631533837947,"mc":[{"id":"1.187594318","rc":[{"batb":[[0,1.23,29.05],[1,1.22,80.92],[2,1.01,7]],"ltp":1.68,"tv":129.01,"id":9628686}]}]}
{"op":"mcm","clk":"4233352980","pt":1631533844833,"mc":[{"id":"1.187594318","rc":[{"batl":[[0,2.74,3.62]],"ltp":1.68,"tv":129.01,"id":9628686}]}]}
{"op":"mcm","clk":"4233353398","pt":1631533850103,"mc":[{"id":"1.187594318","rc":[{"batb":[[0,1.11,216.97],[1,1.01,7],[2,1.01,0]],"ltp":2.46,"tv":113.82,"id":9183341}]}]}
{"op":"mcm","clk":"4233353789","pt":1631533855249,"mc":[{"id":"1.187594318","rc":[{"batb":[[0,1.6,10.85],[1,1.11,216.97],[2,1.01,7]],"ltp":2.46,"tv":113.82,"id":9183341}]}]}
{"op":"mcm","clk":"4233354246","pt":1631533860631,"mc":[{"id":"1.187594318","rc":[{"batb":[[1,1.01,7],[2,1.01,0]],"ltp":1.68,"tv":129.01,"id":9628686}]}]}
{"op":"mcm","clk":"4233354633","pt":1631533865766,"mc":[{"id":"1.187594318","rc":[{"batb":[[0,1.25,80.92],[1,1.23,29.05],[2,1.01,7]],"ltp":1.68,"tv":129.01,"id":9628686}]}]}
{"op":"mcm","clk":"4233357743","pt":1631533902825,"mc":[{"id":"1.187594318","rc":[{"batb":[[1,1.01,7],[2,1.01,0]],"ltp":1.68,"tv":129.01,"id":9628686}]}]}
{"op":"mcm","clk":"4233358156","pt":1631533907897,"mc":[{"id":"1.187594318","rc":[{"batb":[[0,1.27,29.05],[1,1.25,80.92],[2,1.01,7]],"ltp":1.68,"tv":129.01,"id":9628686}]}]}
{"op":"mcm","clk":"4233358757","pt":1631533914814,"mc":[{"id":"1.187594318","rc":[{"batb":[[1,1.01,7],[2,1.01,0]],"ltp":1.68,"tv":129.01,"id":9628686}]}]}
{"op":"mcm","clk":"4233359163","pt":1631533919933,"mc":[{"id":"1.187594318","rc":[{"batb":[[0,1.3,80.92],[1,1.27,29.05],[2,1.01,7]],"ltp":1.68,"tv":129.01,"id":9628686}]}]}
{"op":"mcm","clk":"4233360215","pt":1631533933649,"mc":[{"id":"1.187594318","rc":[{"batb":[[1,1.01,7],[2,1.01,0]],"ltp":1.68,"tv":129.01,"id":9628686}]}]}
{"op":"mcm","clk":"4233367718","pt":1631534043831,"mc":[{"id":"1.187594318","rc":[{"batb":[[0,1.01,7],[1,1.01,0]],"ltp":1.68,"tv":129.01,"id":9628686}]}]}
{"op":"mcm","clk":"4233368056","pt":1631534048961,"mc":[{"id":"1.187594318","rc":[{"batb":[[0,1.21,80.92],[1,1.01,7]],"ltp":1.68,"tv":129.01,"id":9628686}]}]}
{"op":"mcm","clk":"4233374500","pt":1631534145200,"mc":[{"id":"1.187594318","rc":[{"batb":[[0,1.01,7],[1,1.01,0]],"ltp":1.68,"tv":129.01,"id":9628686}]}]}
{"op":"mcm","clk":"4233374746","pt":1631534150306,"mc":[{"id":"1.187594318","rc":[{"batb":[[0,1.11,80.92],[1,1.01,7]],"ltp":1.68,"tv":129.01,"id":9628686}]}]}
{"op":"mcm","clk":"4233375145","pt":1631534157105,"mc":[{"id":"1.187594318","rc":[{"batb":[[1,1.01,7],[2,1.01,0]],"ltp":2.46,"tv":113.82,"id":9183341}]}]}
{"op":"mcm","clk":"4233377060","pt":1631534186156,"mc":[{"id":"1.187594318","rc":[{"batb":[[0,1.61,2],[1,1.6,10.85],[2,1.01,7]],"ltp":2.46,"tv":113.82,"id":9183341}]}]}
{"op":"mcm","clk":"4233379045","pt":1631534215829,"mc":[{"id":"1.187594318","rc":[{"batb":[[0,1.6,10.85],[1,1.01,7],[2,1.01,0]],"ltp":2.46,"tv":113.82,"id":9183341}]}]}
{"op":"mcm","clk":"4233390115","pt":1631534381288,"mc":[{"id":"1.187594318","rc":[{"batb":[[0,1.01,7],[1,1.01,0]],"ltp":1.68,"tv":129.01,"id":9628686}]}]}
{"op":"mcm","clk":"4233390506","pt":1631534386354,"mc":[{"id":"1.187594318","rc":[{"batb":[[0,1.08,80.92],[1,1.01,7]],"ltp":1.68,"tv":129.01,"id":9628686}]}]}
{"op":"mcm","clk":"4233452103","pt":1631535027093,"mc":[{"id":"1.187594318","rc":[{"batb":[[0,1.01,7],[1,1.01,0]],"ltp":1.68,"tv":129.01,"id":9628686}]}]}
{"op":"mcm","clk":"4233452583","pt":1631535032214,"mc":[{"id":"1.187594318","rc":[{"batb":[[0,1.16,80.92],[1,1.01,7]],"ltp":1.68,"tv":129.01,"id":9628686}]}]}
{"op":"mcm","clk":"4233464208","pt":1631535156454,"mc":[{"id":"1.187594318","rc":[{"batb":[[0,1.2,208.08],[1,1.16,80.92],[2,1.01,7]],"ltp":1.68,"tv":129.01,"id":9628686}]}]}
{"op":"mcm","clk":"4233464401","pt":1631535158560,"mc":[{"id":"1.187594318","rc":[{"batl":[[0,1.66,52.02],[1,2.74,3.62]],"ltp":1.68,"tv":129.01,"id":9628686}]}]}
{"op":"mcm","clk":"4233464851","pt":1631535163250,"mc":[{"id":"1.187594318","rc":[{"batb":[[0,3.4,12.5],[1,1.6,10.85],[2,1.01,7]],"ltp":2.46,"tv":113.82,"id":9183341},{"batb":[[0,1.27,111.11],[1,1.2,208.08],[2,1.16,80.92]],"ltp":1.68,"tv":129.01,"id":9628686}]}]}
{"op":"mcm","clk":"4233465954","pt":1631535174777,"mc":[{"id":"1.187594318","rc":[{"batb":[[0,1.6,10.85],[1,1.01,7],[2,1.01,0]],"ltp":2.46,"tv":113.82,"id":9183341},{"batb":[[0,1.2,208.08],[1,1.16,80.92],[2,1.01,7]],"ltp":1.68,"tv":129.01,"id":9628686}]}]}
{"op":"mcm","clk":"4233466432","pt":1631535179665,"mc":[{"id":"1.187594318","rc":[{"batb":[[0,4,10],[1,1.6,10.85],[2,1.01,7]],"ltp":2.46,"tv":113.82,"id":9183341},{"batb":[[0,1.2,358.08]],"ltp":1.68,"tv":129.01,"id":9628686}]}]}
{"op":"mcm","clk":"4233469292","pt":1631535210016,"mc":[{"id":"1.187594318","rc":[{"batl":[[0,2.74,3.62],[1,2.74,0]],"ltp":1.68,"tv":129.01,"id":9628686}]}]}
{"op":"mcm","clk":"4233469542","pt":1631535212536,"mc":[{"id":"1.187594318","rc":[{"batb":[[0,1.6,10.85],[1,1.01,7],[2,1.01,0]],"ltp":2.46,"tv":113.82,"id":9183341},{"batb":[[0,1.2,208.08]],"ltp":1.68,"tv":129.01,"id":9628686}]}]}
{"op":"mcm","clk":"4233470046","pt":1631535217545,"mc":[{"id":"1.187594318","rc":[{"batb":[[0,3.7,11.11],[1,1.6,10.85],[2,1.01,7]],"ltp":2.46,"tv":113.82,"id":9183341},{"batb":[[0,1.23,130.43],[1,1.2,208.08],[2,1.16,80.92]],"ltp":1.68,"tv":129.01,"id":9628686}]}]}
{"op":"mcm","clk":"4233476002","pt":1631535275634,"mc":[{"id":"1.187594318","rc":[{"batb":[[1,1.16,80.92],[2,1.01,7]],"ltp":1.68,"tv":129.01,"id":9628686}]}]}
{"op":"mcm","clk":"4233476664","pt":1631535281527,"mc":[{"id":"1.187594318","rc":[{"batb":[[1,1.01,7],[2,1.01,0]],"ltp":1.68,"tv":129.01,"id":9628686}]}]}
{"op":"mcm","clk":"4233477135","pt":1631535286667,"mc":[{"id":"1.187594318","rc":[{"batb":[[1,1.11,80.92],[2,1.01,7]],"ltp":1.68,"tv":129.01,"id":9628686}]}]}
{"op":"mcm","clk":"4233478901","pt":1631535304287,"mc":[{"id":"1.187594318","rc":[{"batb":[[0,1.6,10.85],[1,1.01,7],[2,1.01,0]],"ltp":2.46,"tv":113.82,"id":9183341},{"batb":[[0,1.11,80.92],[1,1.01,7],[2,1.01,0]],"ltp":1.68,"tv":129.01,"id":9628686}]}]}
{"op":"mcm","clk":"4233479431","pt":1631535309311,"mc":[{"id":"1.187594318","rc":[{"batb":[[0,4.1,10],[1,1.6,10.85],[2,1.01,7]],"ltp":2.46,"tv":113.82,"id":9183341},{"batb":[[0,1.18,166.66],[1,1.11,80.92],[2,1.01,7]],"ltp":1.68,"tv":129.01,"id":9628686}]}]}
{"op":"mcm","clk":"4233486082","pt":1631535379324,"mc":[{"id":"1.187594318","rc":[{"batb":[[1,1.01,7],[2,1.01,0]],"ltp":1.68,"tv":129.01,"id":9628686}]}]}
{"op":"mcm","clk":"4233486571","pt":1631535384468,"mc":[{"id":"1.187594318","rc":[{"batb":[[1,1.08,80.92],[2,1.01,7]],"ltp":1.68,"tv":129.01,"id":9628686}]}]}
{"op":"mcm","clk":"4233488485","pt":1631535404998,"mc":[{"id":"1.187594318","rc":[{"batb":[[0,1.6,10.85],[1,1.01,7],[2,1.01,0]],"ltp":2.46,"tv":113.82,"id":9183341},{"batb":[[0,1.08,80.92],[1,1.01,7],[2,1.01,0]],"ltp":1.68,"tv":129.01,"id":9628686}]}]}
{"op":"mcm","clk":"4233488949","pt":1631535409870,"mc":[{"id":"1.187594318","rc":[{"batb":[[0,3.4,12.5],[1,1.6,10.85],[2,1.01,7]],"ltp":2.46,"tv":113.82,"id":9183341},{"batb":[[0,1.27,111.11],[1,1.08,80.92],[2,1.01,7]],"ltp":1.68,"tv":129.01,"id":9628686}]}]}
{"op":"mcm","clk":"4233490957","pt":1631535430358,"mc":[{"id":"1.187594318","rc":[{"batb":[[0,1.6,10.85],[1,1.01,7],[2,1.01,0]],"ltp":2.46,"tv":113.82,"id":9183341},{"batb":[[0,1.08,80.92],[1,1.01,7],[2,1.01,0]],"ltp":1.68,"tv":129.01,"id":9628686}]}]}
{"op":"mcm","clk":"4233491455","pt":1631535435254,"mc":[{"id":"1.187594318","rc":[{"batb":[[0,4.1,10],[1,1.6,10.85],[2,1.01,7]],"ltp":2.46,"tv":113.82,"id":9183341},{"batb":[[0,1.18,166.66],[1,1.08,80.92],[2,1.01,7]],"ltp":1.68,"tv":129.01,"id":9628686}]}]}
{"op":"mcm","clk":"4233505123","pt":1631535468259,"mc":[{"id":"1.187594318","rc":[{"batb":[[0,1.6,10.85],[1,1.01,7],[2,1.01,0]],"ltp":2.46,"tv":113.82,"id":9183341},{"batb":[[0,1.08,80.92],[1,1.01,7],[2,1.01,0]],"ltp":1.68,"tv":129.01,"id":9628686}]}]}
{"op":"mcm","clk":"4233506229","pt":1631535473184,"mc":[{"id":"1.187594318","rc":[{"batb":[[0,3.4,12.5],[1,1.6,10.85],[2,1.01,7]],"ltp":2.46,"tv":113.82,"id":9183341},{"batb":[[0,1.27,111.11],[1,1.08,80.92],[2,1.01,7]],"ltp":1.68,"tv":129.01,"id":9628686}]}]}
{"op":"mcm","clk":"4233509394","pt":1631535492807,"mc":[{"id":"1.187594318","rc":[{"batb":[[0,1.6,10.85],[1,1.01,7],[2,1.01,0]],"ltp":2.46,"tv":113.82,"id":9183341},{"batb":[[0,1.08,80.92],[1,1.01,7],[2,1.01,0]],"ltp":1.68,"tv":129.01,"id":9628686}]}]}
{"op":"mcm","clk":"4233509927","pt":1631535497705,"mc":[{"id":"1.187594318","rc":[{"batb":[[0,3,15],[1,1.6,10.85],[2,1.01,7]],"ltp":2.46,"tv":113.82,"id":9183341},{"batb":[[0,1.34,88.23],[1,1.08,80.92],[2,1.01,7]],"ltp":1.68,"tv":129.01,"id":9628686}]}]}
{"op":"mcm","clk":"4233511224","pt":1631535509946,"mc":[{"id":"1.187594318","rc":[{"batb":[[0,1.6,10.85],[1,1.01,7],[2,1.01,0]],"ltp":2.46,"tv":113.82,"id":9183341},{"batb":[[0,1.08,80.92],[1,1.01,7],[2,1.01,0]],"ltp":1.68,"tv":129.01,"id":9628686}]}]}
{"op":"mcm","clk":"4233511845","pt":1631535514859,"mc":[{"id":"1.187594318","rc":[{"batb":[[0,3.4,12.5],[1,1.6,10.85],[2,1.01,7]],"ltp":2.46,"tv":113.82,"id":9183341},{"batb":[[0,1.27,111.11],[1,1.08,80.92],[2,1.01,7]],"ltp":1.68,"tv":129.01,"id":9628686}]}]}
{"op":"mcm","clk":"4233514044","pt":1631535533080,"mc":[{"id":"1.187594318","rc":[{"batb":[[0,1.6,10.85],[1,1.01,7],[2,1.01,0]],"ltp":2.46,"tv":113.82,"id":9183341},{"batb":[[0,1.08,80.92],[1,1.01,7],[2,1.01,0]],"ltp":1.68,"tv":129.01,"id":9628686}]}]}
{"op":"mcm","clk":"4233514578","pt":1631535537890,"mc":[{"id":"1.187594318","rc":[{"batb":[[0,4.3,10],[1,1.6,10.85],[2,1.01,7]],"ltp":2.46,"tv":113.82,"id":9183341},{"batb":[[0,1.18,166.66],[1,1.08,80.92],[2,1.01,7]],"ltp":1.68,"tv":129.01,"id":9628686}]}]}
{"op":"mcm","clk":"4233516164","pt":1631535551778,"mc":[{"id":"1.187594318","rc":[{"batb":[[0,1.6,10.85],[1,1.01,7],[2,1.01,0]],"ltp":2.46,"tv":113.82,"id":9183341},{"batb":[[0,1.08,80.92],[1,1.01,7],[2,1.01,0]],"ltp":1.68,"tv":129.01,"id":9628686}]}]}
{"op":"mcm","clk":"4233516658","pt":1631535556697,"mc":[{"id":"1.187594318","rc":[{"batb":[[0,4.8,10],[1,1.6,10.85],[2,1.01,7]],"ltp":2.46,"tv":113.82,"id":9183341},{"batb":[[0,1.15,200],[1,1.08,80.92],[2,1.01,7]],"ltp":1.68,"tv":129.01,"id":9628686}]}]}
{"op":"mcm","clk":"4233517264","pt":1631535561723,"mc":[{"id":"1.187594318","rc":[{"batb":[[0,1.6,10.85],[1,1.01,7],[2,1.01,0]],"ltp":2.46,"tv":113.82,"id":9183341},{"batb":[[0,1.08,80.92],[1,1.01,7],[2,1.01,0]],"ltp":1.68,"tv":129.01,"id":9628686}]}]}
{"op":"mcm","clk":"4233517788","pt":1631535566633,"mc":[{"id":"1.187594318","rc":[{"batb":[[0,6,10],[1,1.6,10.85],[2,1.01,7]],"ltp":2.46,"tv":113.82,"id":9183341},{"batb":[[0,1.08,455.91]],"ltp":1.68,"tv":129.01,"id":9628686}]}]}
{"op":"mcm","clk":"4233519385","pt":1631535581923,"mc":[{"id":"1.187594318","rc":[{"batb":[[0,1.6,10.85],[1,1.01,7],[2,1.01,0]],"ltp":2.46,"tv":113.82,"id":9183341},{"batb":[[0,1.08,80.92]],"ltp":1.68,"tv":129.01,"id":9628686}]}]}
{"op":"mcm","clk":"4233519468","pt":1631535582753,"mc":[{"id":"1.187594318","rc":[{"batb":[[0,1.01,7],[1,1.01,0]],"ltp":1.68,"tv":129.01,"id":9628686}]}]}
{"op":"mcm","clk":"4233519903","pt":1631535586857,"mc":[{"id":"1.187594318","rc":[{"batb":[[0,4.3,10],[1,1.6,10.85],[2,1.01,7]],"ltp":2.46,"tv":113.82,"id":9183341},{"batb":[[0,1.18,166.66],[1,1.01,7]],"ltp":1.68,"tv":129.01,"id":9628686}]}]}
{"op":"mcm","clk":"4233519999","pt":1631535587849,"mc":[{"id":"1.187594318","rc":[{"batb":[[1,1.02,80.92],[2,1.01,7]],"ltp":1.68,"tv":129.01,"id":9628686}]}]}
{"op":"mcm","clk":"4233522002","pt":1631535605867,"mc":[{"id":"1.187594318","rc":[{"batb":[[0,1.6,10.85],[1,1.01,7],[2,1.01,0]],"ltp":2.46,"tv":113.82,"id":9183341},{"batb":[[0,1.02,80.92],[1,1.01,7],[2,1.01,0]],"ltp":1.68,"tv":129.01,"id":9628686}]}]}
{"op":"mcm","clk":"4233522536","pt":1631535610894,"mc":[{"id":"1.187594318","rc":[{"batb":[[0,4.8,10],[1,1.6,10.85],[2,1.01,7]],"ltp":2.46,"tv":113.82,"id":9183341},{"batb":[[0,1.15,200],[1,1.02,80.92],[2,1.01,7]],"ltp":1.68,"tv":129.01,"id":9628686}]}]}
{"op":"mcm","clk":"4233523342","pt":1631535618304,"mc":[{"id":"1.187594318","rc":[{"batb":[[0,1.6,10.85],[1,1.01,7],[2,1.01,0]],"ltp":2.46,"tv":113.82,"id":9183341},{"batb":[[0,1.02,80.92],[1,1.01,7],[2,1.01,0]],"ltp":1.68,"tv":129.01,"id":9628686}]}]}
{"op":"mcm","clk":"4233523834","pt":1631535623234,"mc":[{"id":"1.187594318","rc":[{"batb":[[0,3.4,12.5],[1,1.6,10.85],[2,1.01,7]],"ltp":2.46,"tv":113.82,"id":9183341},{"batb":[[0,1.27,111.11],[1,1.02,80.92],[2,1.01,7]],"ltp":1.68,"tv":129.01,"id":9628686}]}]}
{"op":"mcm","clk":"4233525407","pt":1631535638353,"mc":[{"id":"1.187594318","rc":[{"batb":[[0,1.6,10.85],[1,1.01,7],[2,1.01,0]],"ltp":2.46,"tv":113.82,"id":9183341},{"batb":[[0,1.02,80.92],[1,1.01,7],[2,1.01,0]],"ltp":1.68,"tv":129.01,"id":9628686}]}]}
{"op":"mcm","clk":"4233525904","pt":1631535643244,"mc":[{"id":"1.187594318","rc":[{"batb":[[0,4.3,10]],"ltp":2.46,"tv":113.82,"id":9183341},{"batb":[[0,1.18,166.66]],"ltp":1.68,"tv":129.01,"id":9628686}]}]}
{"op":"mcm","clk":"4233529309","pt":1631535675124,"mc":[{"id":"1.187594318","rc":[{"batb":[[0,1.01,7],[1,1.01,0]],"ltp":2.46,"tv":113.82,"id":9183341},{"batb":[[0,1.01,7],[1,1.01,0]],"ltp":1.68,"tv":129.01,"id":9628686}]}]}
{"op":"mcm","clk":"4233529797","pt":1631535680044,"mc":[{"id":"1.187594318","rc":[{"batb":[[0,6,10],[1,1.01,7]],"ltp":2.46,"tv":113.82,"id":9183341},{"batb":[[0,1.08,374.99],[1,1.01,7]],"ltp":1.68,"tv":129.01,"id":9628686}]}]}
{"op":"mcm","clk":"4233532479","pt":1631535707107,"mc":[{"id":"1.187594318","rc":[{"batb":[[0,1.01,7],[1,1.01,0]],"ltp":2.46,"tv":113.82,"id":9183341},{"batb":[[0,1.01,7],[1,1.01,0]],"ltp":1.68,"tv":129.01,"id":9628686}]}]}
{"op":"mcm","clk":"4233532984","pt":1631535711976,"mc":[{"id":"1.187594318","rc":[{"batb":[[0,4.3,10],[1,1.01,7]],"ltp":2.46,"tv":113.82,"id":9183341},{"batb":[[0,1.18,166.66],[1,1.01,7]],"ltp":1.68,"tv":129.01,"id":9628686}]}]}
{"op":"mcm","clk":"4233534357","pt":1631535725433,"mc":[{"id":"1.187594318","rc":[{"batb":[[0,1.01,7],[1,1.01,0]],"ltp":2.46,"tv":113.82,"id":9183341},{"batb":[[0,1.01,7],[1,1.01,0]],"ltp":1.68,"tv":129.01,"id":9628686}]}]}
{"op":"mcm","clk":"4233534837","pt":1631535730320,"mc":[{"id":"1.187594318","rc":[{"batb":[[0,3.4,12.5],[1,1.01,7]],"ltp":2.46,"tv":113.82,"id":9183341},{"batb":[[0,1.27,111.11],[1,1.01,7]],"ltp":1.68,"tv":129.01,"id":9628686}]}]}
{"op":"mcm","clk":"4233537300","pt":1631535755653,"mc":[{"id":"1.187594318","rc":[{"batb":[[0,1.01,7],[1,1.01,0]],"ltp":2.46,"tv":113.82,"id":9183341},{"batb":[[0,1.01,7],[1,1.01,0]],"ltp":1.68,"tv":129.01,"id":9628686}]}]}
{"op":"mcm","clk":"4233537727","pt":1631535760557,"mc":[{"id":"1.187594318","rc":[{"batb":[[0,2.84,16.3],[1,1.01,7]],"ltp":2.46,"tv":113.82,"id":9183341},{"batb":[[0,1.38,78.94],[1,1.01,7]],"ltp":1.68,"tv":129.01,"id":9628686}]}]}
{"op":"mcm","clk":"4233538278","pt":1631535766460,"mc":[{"id":"1.187594318","rc":[{"trd":[[3.65,29.85]],"batb":[[0,3.65,14.11],[1,2.84,16.3],[2,1.01,7]],"ltp":3.65,"tv":143.67,"id":9183341},{"trd":[[1.38,78.94]],"batb":[[0,1.01,7],[1,1.01,0]],"batl":[[0,1.38,88.83],[1,2.74,3.62]],"ltp":1.38,"tv":207.95,"id":9628686}],"tv":351.63}]}
{"op":"mcm","clk":"4233538299","pt":1631535766673,"mc":[{"id":"1.187594318","rc":[{"batb":[[0,2.84,16.3],[1,1.01,7],[2,1.01,0]],"ltp":3.65,"tv":143.67,"id":9183341},{"batl":[[0,2.74,3.62],[1,2.74,0]],"ltp":1.38,"tv":207.95,"id":9628686}]}]}
{"op":"mcm","clk":"4233538799","pt":1631535771693,"mc":[{"id":"1.187594318","rc":[{"batb":[[0,1.31,96.77],[1,1.01,7]],"ltp":1.38,"tv":207.95,"id":9628686}]}]}
{"op":"mcm","clk":"4233541997","pt":1631535802566,"mc":[{"id":"1.187594318","rc":[{"batb":[[0,1.01,7],[1,1.01,0]],"ltp":3.65,"tv":143.67,"id":9183341},{"batb":[[0,1.01,7],[1,1.01,0]],"ltp":1.38,"tv":207.95,"id":9628686}]}]}
{"op":"mcm","clk":"4233542454","pt":1631535807432,"mc":[{"id":"1.187594318","rc":[{"batb":[[0,3.4,12.5],[1,1.01,7]],"ltp":3.65,"tv":143.67,"id":9183341},{"batb":[[0,1.27,111.11],[1,1.01,7]],"ltp":1.38,"tv":207.95,"id":9628686}]}]}
{"op":"mcm","clk":"4233543650","pt":1631535821293,"mc":[{"id":"1.187594318","rc":[{"batb":[[0,1.01,7],[1,1.01,0]],"ltp":3.65,"tv":143.67,"id":9183341},{"batb":[[0,1.01,7],[1,1.01,0]],"ltp":1.38,"tv":207.95,"id":9628686}]}]}
{"op":"mcm","clk":"4233544065","pt":1631535826075,"mc":[{"id":"1.187594318","rc":[{"batb":[[0,4.1,10],[1,1.01,7]],"ltp":3.65,"tv":143.67,"id":9183341},{"batb":[[0,1.18,166.66],[1,1.01,7]],"ltp":1.38,"tv":207.95,"id":9628686}]}]}
{"op":"mcm","clk":"4233545129","pt":1631535837500,"mc":[{"id":"1.187594318","rc":[{"batb":[[0,1.01,7],[1,1.01,0]],"ltp":3.65,"tv":143.67,"id":9183341},{"batb":[[0,1.01,7],[1,1.01,0]],"ltp":1.38,"tv":207.95,"id":9628686}]}]}
{"op":"mcm","clk":"4233545584","pt":1631535842410,"mc":[{"id":"1.187594318","rc":[{"batb":[[0,4,10],[1,1.01,7]],"ltp":3.65,"tv":143.67,"id":9183341},{"batb":[[0,1.2,150],[1,1.01,7]],"ltp":1.38,"tv":207.95,"id":9628686}]}]}
{"op":"mcm","clk":"4233545949","pt":1631535847414,"mc":[{"id":"1.187594318","rc":[{"batb":[[0,1.01,7],[1,1.01,0]],"ltp":3.65,"tv":143.67,"id":9183341},{"batb":[[0,1.01,7],[1,1.01,0]],"ltp":1.38,"tv":207.95,"id":9628686}]}]}
{"op":"mcm","clk":"4233546370","pt":1631535852355,"mc":[{"id":"1.187594318","rc":[{"batb":[[0,3.4,12.5],[1,1.01,7]],"ltp":3.65,"tv":143.67,"id":9183341},{"batb":[[0,1.27,111.11],[1,1.01,7]],"ltp":1.38,"tv":207.95,"id":9628686}]}]}
{"op":"mcm","clk":"4233548569","pt":1631535876466,"mc":[{"id":"1.187594318","rc":[{"batb":[[0,1.01,7],[1,1.01,0]],"ltp":3.65,"tv":143.67,"id":9183341},{"batb":[[0,1.01,7],[1,1.01,0]],"ltp":1.38,"tv":207.95,"id":9628686}]}]}
{"op":"mcm","clk":"4233548967","pt":1631535881380,"mc":[{"id":"1.187594318","rc":[{"batb":[[0,2.84,16.3],[1,1.01,7]],"ltp":3.65,"tv":143.67,"id":9183341},{"batb":[[0,1.38,78.94],[1,1.01,7]],"ltp":1.38,"tv":207.95,"id":9628686}]}]}
{"op":"mcm","clk":"4233550682","pt":1631535904891,"mc":[{"id":"1.187594318","rc":[{"batb":[[0,1.01,7],[1,1.01,0]],"ltp":3.65,"tv":143.67,"id":9183341},{"batb":[[0,1.01,7],[1,1.01,0]],"ltp":1.38,"tv":207.95,"id":9628686}]}]}
{"op":"mcm","clk":"4233551025","pt":1631535909889,"mc":[{"id":"1.187594318","rc":[{"batb":[[0,3.7,11.11],[1,1.01,7]],"ltp":3.65,"tv":143.67,"id":9183341},{"batb":[[0,1.23,130.43],[1,1.01,7]],"ltp":1.38,"tv":207.95,"id":9628686}]}]}
{"op":"mcm","clk":"4233553217","pt":1631535941398,"mc":[{"id":"1.187594318","rc":[{"batb":[[0,1.01,7],[1,1.01,0]],"ltp":3.65,"tv":143.67,"id":9183341},{"batb":[[0,1.01,7],[1,1.01,0]],"ltp":1.38,"tv":207.95,"id":9628686}]}]}
{"op":"mcm","clk":"4233553587","pt":1631535946312,"mc":[{"id":"1.187594318","rc":[{"batb":[[0,5.3,10],[1,1.01,7]],"ltp":3.65,"tv":143.67,"id":9183341},{"batb":[[0,1.12,249.99],[1,1.01,7]],"ltp":1.38,"tv":207.95,"id":9628686}]}]}
{"op":"mcm","clk":"4233560892","pt":1631536034703,"mc":[{"id":"1.187594318","rc":[{"batb":[[0,1.01,7],[1,1.01,0]],"ltp":3.65,"tv":143.67,"id":9183341},{"batb":[[0,1.01,7],[1,1.01,0]],"ltp":1.38,"tv":207.95,"id":9628686}]}]}
{"op":"mcm","clk":"4233561311","pt":1631536039725,"mc":[{"id":"1.187594318","rc":[{"batb":[[0,4,10],[1,1.01,7]],"ltp":3.65,"tv":143.67,"id":9183341},{"batb":[[0,1.2,150],[1,1.01,7]],"ltp":1.38,"tv":207.95,"id":9628686}]}]}
{"op":"mcm","clk":"4233563173","pt":1631536062652,"mc":[{"id":"1.187594318","rc":[{"batb":[[0,1.01,7],[1,1.01,0]],"ltp":3.65,"tv":143.67,"id":9183341},{"batb":[[0,1.01,7],[1,1.01,0]],"ltp":1.38,"tv":207.95,"id":9628686}]}]}
{"op":"mcm","clk":"4233563607","pt":1631536067558,"mc":[{"id":"1.187594318","rc":[{"batb":[[0,3.3,13.04],[1,1.01,7]],"ltp":3.65,"tv":143.67,"id":9183341},{"batb":[[0,1.28,107.14],[1,1.01,7]],"ltp":1.38,"tv":207.95,"id":9628686}]}]}
{"op":"mcm","clk":"4233565274","pt":1631536086405,"mc":[{"id":"1.187594318","rc":[{"batb":[[0,1.01,7],[1,1.01,0]],"ltp":3.65,"tv":143.67,"id":9183341},{"batb":[[0,1.01,7],[1,1.01,0]],"ltp":1.38,"tv":207.95,"id":9628686}]}]}
{"op":"mcm","clk":"4233565708","pt":1631536091213,"mc":[{"id":"1.187594318","rc":[{"batb":[[0,3.95,10.16],[1,1.01,7]],"ltp":3.65,"tv":143.67,"id":9183341},{"batb":[[0,1.2,150],[1,1.01,7]],"ltp":1.38,"tv":207.95,"id":9628686}]}]}
{"op":"mcm","clk":"4233566971","pt":1631536107853,"mc":[{"id":"1.187594318","rc":[{"batb":[[0,1.01,7],[1,1.01,0]],"ltp":3.65,"tv":143.67,"id":9183341},{"batb":[[0,1.01,7],[1,1.01,0]],"ltp":1.38,"tv":207.95,"id":9628686}]}]}
{"op":"mcm","clk":"4233567469","pt":1631536112722,"mc":[{"id":"1.187594318","rc":[{"batb":[[0,3.15,13.95],[1,1.01,7]],"ltp":3.65,"tv":143.67,"id":9183341},{"batb":[[0,1.31,96.77],[1,1.01,7]],"ltp":1.38,"tv":207.95,"id":9628686}]}]}
{"op":"mcm","clk":"4233569805","pt":1631536141185,"mc":[{"id":"1.187594318","rc":[{"batb":[[0,1.01,7],[1,1.01,0]],"ltp":3.65,"tv":143.67,"id":9183341},{"batb":[[0,1.01,7],[1,1.01,0]],"ltp":1.38,"tv":207.95,"id":9628686}]}]}
{"op":"mcm","clk":"4233570188","pt":1631536146090,"mc":[{"id":"1.187594318","rc":[{"batb":[[0,3.7,11.11],[1,1.01,7]],"ltp":3.65,"tv":143.67,"id":9183341},{"batb":[[0,1.23,130.43],[1,1.01,7]],"ltp":1.38,"tv":207.95,"id":9628686}]}]}
{"op":"mcm","clk":"4233571391","pt":1631536163262,"mc":[{"id":"1.187594318","rc":[{"batb":[[0,1.01,7],[1,1.01,0]],"ltp":3.65,"tv":143.67,"id":9183341},{"batb":[[0,1.01,7],[1,1.01,0]],"ltp":1.38,"tv":207.95,"id":9628686}]}]}
{"op":"mcm","clk":"4233571776","pt":1631536168262,"mc":[{"id":"1.187594318","rc":[{"batb":[[0,3,15],[1,1.01,7]],"ltp":3.65,"tv":143.67,"id":9183341},{"batb":[[0,1.34,88.23],[1,1.01,7]],"ltp":1.38,"tv":207.95,"id":9628686}]}]}
{"op":"mcm","clk":"4233572308","pt":1631536174584,"mc":[{"id":"1.187594318","rc":[{"trd":[[3.95,22.58]],"ltp":3.95,"tv":166.25,"id":9183341},{"trd":[[1.34,66.56]],"batb":[[0,1.34,21.67]],"ltp":1.34,"tv":274.51,"id":9628686}],"tv":440.77}]}
{"op":"mcm","clk":"4233572342","pt":1631536175067,"mc":[{"id":"1.187594318","rc":[{"trd":[[3.95,29.93]],"ltp":3.95,"tv":173.6,"id":9183341},{"trd":[[1.34,88.23]],"batb":[[0,1.01,7],[1,1.01,0]],"ltp":1.34,"tv":296.18,"id":9628686}],"tv":469.79}]}
{"op":"mcm","clk":"4233572759","pt":1631536179779,"mc":[{"id":"1.187594318","rc":[{"batb":[[0,1.34,88.23],[1,1.01,7]],"ltp":1.34,"tv":296.18,"id":9628686}]}]}
{"op":"mcm","clk":"4233574882","pt":1631536205123,"mc":[{"id":"1.187594318","rc":[{"trd":[[3,0.24]],"batb":[[0,1.01,7],[1,1.01,0]],"ltp":3.0,"tv":173.84,"id":9183341}],"tv":470.03}]}
{"op":"mcm","clk":"4233575258","pt":1631536210009,"mc":[{"id":"1.187594318","rc":[{"batb":[[0,3,15],[1,1.01,7]],"ltp":3.0,"tv":173.84,"id":9183341}]}]}
{"op":"mcm","clk":"4233576005","pt":1631536219368,"mc":[{"id":"1.187594318","rc":[{"batb":[[0,1.01,7],[1,1.01,0]],"ltp":3.0,"tv":173.84,"id":9183341},{"batb":[[0,1.01,7],[1,1.01,0]],"ltp":1.34,"tv":296.18,"id":9628686}]}]}
{"op":"mcm","clk":"4233576505","pt":1631536224243,"mc":[{"id":"1.187594318","rc":[{"batb":[[0,3.4,12.5],[1,1.01,7]],"ltp":3.0,"tv":173.84,"id":9183341},{"batb":[[0,1.27,111.11],[1,1.01,7]],"ltp":1.34,"tv":296.18,"id":9628686}]}]}
{"op":"mcm","clk":"4233578937","pt":1631536252402,"mc":[{"id":"1.187594318","rc":[{"batb":[[0,1.01,7],[1,1.01,0]],"ltp":3.0,"tv":173.84,"id":9183341},{"batb":[[0,1.01,7],[1,1.01,0]],"ltp":1.34,"tv":296.18,"id":9628686}]}]}
{"op":"mcm","clk":"4233579320","pt":1631536257312,"mc":[{"id":"1.187594318","rc":[{"batb":[[0,4.1,10],[1,1.01,7]],"ltp":3.0,"tv":173.84,"id":9183341},{"batb":[[0,1.18,166.66],[1,1.01,7]],"ltp":1.34,"tv":296.18,"id":9628686}]}]}
{"op":"mcm","clk":"4233581115","pt":1631536278535,"mc":[{"id":"1.187594318","rc":[{"batb":[[0,1.01,7],[1,1.01,0]],"ltp":3.0,"tv":173.84,"id":9183341},{"batb":[[0,1.01,7],[1,1.01,0]],"ltp":1.34,"tv":296.18,"id":9628686}]}]}
{"op":"mcm","clk":"4233581478","pt":1631536283345,"mc":[{"id":"1.187594318","rc":[{"batb":[[0,4,10],[1,1.01,7]],"ltp":3.0,"tv":173.84,"id":9183341},{"batb":[[0,1.2,150],[1,1.01,7]],"ltp":1.34,"tv":296.18,"id":9628686}]}]}
{"op":"mcm","clk":"4233582579","pt":1631536295871,"mc":[{"id":"1.187594318","rc":[{"batb":[[0,1.01,7],[1,1.01,0]],"ltp":3.0,"tv":173.84,"id":9183341},{"batb":[[0,1.01,7],[1,1.01,0]],"ltp":1.34,"tv":296.18,"id":9628686}]}]}
{"op":"mcm","clk":"4233582995","pt":1631536300879,"mc":[{"id":"1.187594318","rc":[{"batb":[[0,4.8,10],[1,1.01,7]],"ltp":3.0,"tv":173.84,"id":9183341},{"batb":[[0,1.15,200],[1,1.01,7]],"ltp":1.34,"tv":296.18,"id":9628686}]}]}
{"op":"mcm","clk":"4233586284","pt":1631536337465,"mc":[{"id":"1.187594318","rc":[{"batb":[[0,1.01,7],[1,1.01,0]],"ltp":3.0,"tv":173.84,"id":9183341},{"batb":[[0,1.01,7],[1,1.01,0]],"ltp":1.34,"tv":296.18,"id":9628686}]}]}
{"op":"mcm","clk":"4233586735","pt":1631536342381,"mc":[{"id":"1.187594318","rc":[{"batb":[[0,5.3,10],[1,1.01,7]],"ltp":3.0,"tv":173.84,"id":9183341},{"batb":[[0,1.12,249.99],[1,1.01,7]],"ltp":1.34,"tv":296.18,"id":9628686}]}]}
{"op":"mcm","clk":"4233594252","pt":1631536426902,"mc":[{"id":"1.187594318","rc":[{"batb":[[0,1.01,7],[1,1.01,0]],"ltp":3.0,"tv":173.84,"id":9183341},{"batb":[[0,1.01,7],[1,1.01,0]],"ltp":1.34,"tv":296.18,"id":9628686}]}]}
{"op":"mcm","clk":"4233594722","pt":1631536431821,"mc":[{"id":"1.187594318","rc":[{"batb":[[0,5.8,10],[1,1.01,7]],"ltp":3.0,"tv":173.84,"id":9183341},{"batb":[[0,1.11,272.72],[1,1.01,7]],"ltp":1.34,"tv":296.18,"id":9628686}]}]}
{"op":"mcm","clk":"4233595883","pt":1631536444374,"mc":[{"id":"1.187594318","rc":[{"batb":[[0,1.01,7],[1,1.01,0]],"ltp":3.0,"tv":173.84,"id":9183341},{"batb":[[0,1.01,7],[1,1.01,0]],"ltp":1.34,"tv":296.18,"id":9628686}]}]}
{"op":"mcm","clk":"4233596354","pt":1631536449261,"mc":[{"id":"1.187594318","rc":[{"batb":[[0,4.3,10],[1,1.01,7]],"ltp":3.0,"tv":173.84,"id":9183341},{"batb":[[0,1.18,166.66],[1,1.01,7]],"ltp":1.34,"tv":296.18,"id":9628686}]}]}
{"op":"mcm","clk":"4233599758","pt":1631536486454,"mc":[{"id":"1.187594318","rc":[{"batb":[[0,1.01,7],[1,1.01,0]],"ltp":3.0,"tv":173.84,"id":9183341},{"batb":[[0,1.01,7],[1,1.01,0]],"ltp":1.34,"tv":296.18,"id":9628686}]}]}
{"op":"mcm","clk":"4233600204","pt":1631536491358,"mc":[{"id":"1.187594318","rc":[{"batb":[[0,5.8,10],[1,1.01,7]],"ltp":3.0,"tv":173.84,"id":9183341},{"batb":[[0,1.11,272.72],[1,1.01,7]],"ltp":1.34,"tv":296.18,"id":9628686}]}]}
{"op":"mcm","clk":"4233602046","pt":1631536510776,"mc":[{"id":"1.187594318","rc":[{"batb":[[0,1.01,7],[1,1.01,0]],"ltp":3.0,"tv":173.84,"id":9183341},{"batb":[[0,1.01,7],[1,1.01,0]],"ltp":1.34,"tv":296.18,"id":9628686}]}]}
{"op":"mcm","clk":"4233602513","pt":1631536515809,"mc":[{"id":"1.187594318","rc":[{"batb":[[0,7.6,10],[1,1.01,7]],"ltp":3.0,"tv":173.84,"id":9183341},{"batb":[[0,1.05,599.99],[1,1.01,7]],"ltp":1.34,"tv":296.18,"id":9628686}]}]}
{"op":"mcm","clk":"4233603966","pt":1631536531513,"mc":[{"id":"1.187594318","rc":[{"batb":[[0,1.01,7],[1,1.01,0]],"ltp":3.0,"tv":173.84,"id":9183341},{"batb":[[0,1.01,7],[1,1.01,0]],"ltp":1.34,"tv":296.18,"id":9628686}]}]}
{"op":"mcm","clk":"4233604447","pt":1631536536311,"mc":[{"id":"1.187594318","rc":[{"batb":[[0,5.8,10],[1,1.01,7]],"ltp":3.0,"tv":173.84,"id":9183341},{"batb":[[0,1.11,272.72],[1,1.01,7]],"ltp":1.34,"tv":296.18,"id":9628686}]}]}
{"op":"mcm","clk":"4233607014","pt":1631536563458,"mc":[{"id":"1.187594318","rc":[{"batb":[[0,1.01,7],[1,1.01,0]],"ltp":3.0,"tv":173.84,"id":9183341},{"batb":[[0,1.01,7],[1,1.01,0]],"ltp":1.34,"tv":296.18,"id":9628686}]}]}
{"op":"mcm","clk":"4233607467","pt":1631536568277,"mc":[{"id":"1.187594318","rc":[{"batb":[[0,3.95,10.16],[1,1.01,7]],"ltp":3.0,"tv":173.84,"id":9183341},{"batb":[[0,1.2,150],[1,1.01,7]],"ltp":1.34,"tv":296.18,"id":9628686}]}]}
{"op":"mcm","clk":"4233609700","pt":1631536592801,"mc":[{"id":"1.187594318","rc":[{"batb":[[0,1.01,7],[1,1.01,0]],"ltp":3.0,"tv":173.84,"id":9183341},{"batb":[[0,1.01,7],[1,1.01,0]],"ltp":1.34,"tv":296.18,"id":9628686}]}]}
{"op":"mcm","clk":"4233610153","pt":1631536597706,"mc":[{"id":"1.187594318","rc":[{"batb":[[0,3.15,13.95],[1,1.01,7]],"ltp":3.0,"tv":173.84,"id":9183341},{"batb":[[0,1.31,96.77],[1,1.01,7]],"ltp":1.34,"tv":296.18,"id":9628686}]}]}
{"op":"mcm","clk":"4233615179","pt":1631536653433,"mc":[{"id":"1.187594318","rc":[{"batb":[[0,1.01,7],[1,1.01,0]],"ltp":3.0,"tv":173.84,"id":9183341},{"batb":[[0,1.01,7],[1,1.01,0]],"ltp":1.34,"tv":296.18,"id":9628686}]}]}
{"op":"mcm","clk":"4233615591","pt":1631536658300,"mc":[{"id":"1.187594318","rc":[{"batb":[[0,2.5,20],[1,1.01,7]],"ltp":3.0,"tv":173.84,"id":9183341},{"batb":[[0,1.48,62.5],[1,1.01,7]],"ltp":1.34,"tv":296.18,"id":9628686}]}]}
{"op":"mcm","clk":"4233618283","pt":1631536689083,"mc":[{"id":"1.187594318","rc":[{"batb":[[0,1.01,7],[1,1.01,0]],"ltp":3.0,"tv":173.84,"id":9183341},{"batb":[[0,1.01,7],[1,1.01,0]],"ltp":1.34,"tv":296.18,"id":9628686}]}]}
{"op":"mcm","clk":"4233618732","pt":1631536694128,"mc":[{"id":"1.187594318","rc":[{"batb":[[0,2.16,25.86],[1,1.01,7]],"ltp":3.0,"tv":173.84,"id":9183341},{"batb":[[0,1.63,47.61],[1,1.01,7]],"ltp":1.34,"tv":296.18,"id":9628686}]}]}
{"op":"mcm","clk":"4233620222","pt":1631536710743,"mc":[{"id":"1.187594318","rc":[{"batb":[[0,1.01,7],[1,1.01,0]],"ltp":3.0,"tv":173.84,"id":9183341},{"batb":[[0,1.01,7],[1,1.01,0]],"ltp":1.34,"tv":296.18,"id":9628686}]}]}
{"op":"mcm","clk":"4233620715","pt":1631536715611,"mc":[{"id":"1.187594318","rc":[{"batb":[[0,2.26,23.8],[1,1.01,7]],"ltp":3.0,"tv":173.84,"id":9183341},{"batb":[[0,1.58,51.72],[1,1.01,7]],"ltp":1.34,"tv":296.18,"id":9628686}]}]}
{"op":"mcm","clk":"4233621513","pt":1631536724328,"mc":[{"id":"1.187594318","rc":[{"batb":[[0,1.01,7],[1,1.01,0]],"ltp":3.0,"tv":173.84,"id":9183341},{"batb":[[0,1.01,7],[1,1.01,0]],"ltp":1.34,"tv":296.18,"id":9628686}]}]}
{"op":"mcm","clk":"4233621935","pt":1631536729251,"mc":[{"id":"1.187594318","rc":[{"batb":[[0,2.58,18.98],[1,1.01,7]],"ltp":3.0,"tv":173.84,"id":9183341},{"batb":[[0,1.45,66.66],[1,1.01,7]],"ltp":1.34,"tv":296.18,"id":9628686}]}]}
{"op":"mcm","clk":"4233624807","pt":1631536761634,"mc":[{"id":"1.187594318","rc":[{"batb":[[0,1.01,7],[1,1.01,0]],"ltp":3.0,"tv":173.84,"id":9183341},{"batb":[[0,1.01,7],[1,1.01,0]],"ltp":1.34,"tv":296.18,"id":9628686}]}]}
{"op":"mcm","clk":"4233625298","pt":1631536766515,"mc":[{"id":"1.187594318","rc":[{"batb":[[0,2.1,27.27],[1,1.01,7]],"ltp":3.0,"tv":173.84,"id":9183341},{"batb":[[0,1.65,46.15],[1,1.01,7]],"ltp":1.34,"tv":296.18,"id":9628686}]}]}
{"op":"mcm","clk":"4233628218","pt":1631536800905,"mc":[{"id":"1.187594318","rc":[{"batb":[[0,1.01,7],[1,1.01,0]],"ltp":3.0,"tv":173.84,"id":9183341},{"batb":[[0,1.01,7],[1,1.01,0]],"ltp":1.34,"tv":296.18,"id":9628686}]}]}
{"op":"mcm","clk":"4233628659","pt":1631536805833,"mc":[{"id":"1.187594318","rc":[{"batb":[[0,1.85,35.29],[1,1.01,7]],"ltp":3.0,"tv":173.84,"id":9183341},{"batb":[[0,1.88,34.09],[1,1.01,7]],"ltp":1.34,"tv":296.18,"id":9628686}]}]}
{"op":"mcm","clk":"4233630626","pt":1631536829359,"mc":[{"id":"1.187594318","rc":[{"batb":[[0,1.01,7],[1,1.01,0]],"ltp":3.0,"tv":173.84,"id":9183341},{"batb":[[0,1.01,7],[1,1.01,0]],"ltp":1.34,"tv":296.18,"id":9628686}]}]}
{"op":"mcm","clk":"4233631046","pt":1631536834238,"mc":[{"id":"1.187594318","rc":[{"batb":[[0,1.63,47.61],[1,1.01,7]],"ltp":3.0,"tv":173.84,"id":9183341},{"batb":[[0,2.16,25.86],[1,1.01,7]],"ltp":1.34,"tv":296.18,"id":9628686}]}]}
{"op":"mcm","clk":"4233632982","pt":1631536860532,"mc":[{"id":"1.187594318","rc":[{"trd":[[1.63,2.75]],"batb":[[0,1.01,7],[1,1.01,0]],"ltp":1.63,"tv":176.59,"id":9183341}],"tv":472.78}]}
{"op":"mcm","clk":"4233633418","pt":1631536865445,"mc":[{"id":"1.187594318","rc":[{"batb":[[0,1.63,47.61],[1,1.01,7]],"ltp":1.63,"tv":176.59,"id":9183341}]}]}
{"op":"mcm","clk":"4233635656","pt":1631536884135,"mc":[{"id":"1.187594318","rc":[{"batb":[[0,1.01,7],[1,1.01,0]],"ltp":1.63,"tv":176.59,"id":9183341},{"batb":[[0,1.01,7],[1,1.01,0]],"ltp":1.34,"tv":296.18,"id":9628686}]}]}
{"op":"mcm","clk":"4233636061","pt":1631536889070,"mc":[{"id":"1.187594318","rc":[{"batb":[[0,1.65,46.15],[1,1.01,7]],"ltp":1.63,"tv":176.59,"id":9183341},{"batb":[[0,2.1,27.27],[1,1.01,7]],"ltp":1.34,"tv":296.18,"id":9628686}]}]}
{"op":"mcm","clk":"4233636495","pt":1631536894658,"mc":[{"id":"1.187594318","rc":[{"batb":[[0,1.01,7],[1,1.01,0]],"ltp":1.63,"tv":176.59,"id":9183341},{"batb":[[0,1.01,7],[1,1.01,0]],"ltp":1.34,"tv":296.18,"id":9628686}]}]}
{"op":"mcm","clk":"4233636860","pt":1631536899558,"mc":[{"id":"1.187594318","rc":[{"batb":[[0,1.55,54.54],[1,1.01,7]],"ltp":1.63,"tv":176.59,"id":9183341},{"batb":[[0,2.34,22.38],[1,1.01,7]],"ltp":1.34,"tv":296.18,"id":9628686}]}]}
{"op":"mcm","clk":"4233638581","pt":1631536920613,"mc":[{"id":"1.187594318","rc":[{"trd":[[2.34,44.75]],"batb":[[0,1.01,7.01],[1,1.01,0]],"ltp":2.34,"tv":340.93,"id":9628686}],"tv":517.52}]}
{"op":"mcm","clk":"4233638611","pt":1631536920991,"mc":[{"id":"1.187594318","rc":[{"batb":[[0,1.01,7]],"ltp":2.34,"tv":340.93,"id":9628686}]}]}
{"op":"mcm","clk":"4233638983","pt":1631536925589,"mc":[{"id":"1.187594318","rc":[{"batl":[[0,2.34,13.17]],"ltp":2.34,"tv":340.93,"id":9628686}]}]}
{"op":"mcm","clk":"4233639012","pt":1631536925896,"mc":[{"id":"1.187594318","rc":[{"batb":[[0,2.2,24.99],[1,1.01,7]],"ltp":2.34,"tv":340.93,"id":9628686}]}]}
{"op":"mcm","clk":"4233639254","pt":1631536928716,"mc":[{"id":"1.187594318","rc":[{"batb":[[0,1.01,7],[1,1.01,0]],"ltp":1.63,"tv":176.59,"id":9183341},{"batb":[[0,1.01,7],[1,1.01,0]],"ltp":2.34,"tv":340.93,"id":9628686}]}]}
{"op":"mcm","clk":"4233639700","pt":1631536933595,"mc":[{"id":"1.187594318","rc":[{"batb":[[0,1.63,47.61],[1,1.01,7]],"ltp":1.63,"tv":176.59,"id":9183341},{"batb":[[0,2.16,25.86],[1,1.01,7]],"ltp":2.34,"tv":340.93,"id":9628686}]}]}
{"op":"mcm","clk":"4233642057","pt":1631536960151,"mc":[{"id":"1.187594318","rc":[{"batb":[[0,1.01,7],[1,1.01,0]],"ltp":1.63,"tv":176.59,"id":9183341},{"batb":[[0,1.01,7],[1,1.01,0]],"ltp":2.34,"tv":340.93,"id":9628686}]}]}
{"op":"mcm","clk":"4233642437","pt":1631536965068,"mc":[{"id":"1.187594318","rc":[{"batb":[[0,1.51,58.82],[1,1.01,7]],"ltp":1.63,"tv":176.59,"id":9183341},{"batb":[[0,2.42,21.12],[1,1.01,7]],"ltp":2.34,"tv":340.93,"id":9628686}]}]}
{"op":"mcm","clk":"4233644112","pt":1631536988223,"mc":[{"id":"1.187594318","rc":[{"trd":[[2.42,42.23]],"batb":[[0,1.01,7],[1,1.01,0]],"ltp":2.42,"tv":383.15,"id":9628686}],"tv":559.75}]}
{"op":"mcm","clk":"4233644487","pt":1631536993222,"mc":[{"id":"1.187594318","rc":[{"batb":[[0,2.28,23.43],[1,1.01,7]],"ltp":2.42,"tv":383.15,"id":9628686}]}]}
{"op":"mcm","clk":"4233659883","pt":1631537189083,"mc":[{"id":"1.187594318","rc":[{"batb":[[0,1.01,7],[1,1.01,0]],"ltp":1.63,"tv":176.59,"id":9183341},{"batb":[[0,1.01,7],[1,1.01,0]],"ltp":2.42,"tv":383.15,"id":9628686}]}]}
{"op":"mcm","clk":"4233660273","pt":1631537194089,"mc":[{"id":"1.187594318","rc":[{"batb":[[0,1.45,66.66],[1,1.01,7]],"ltp":1.63,"tv":176.59,"id":9183341},{"batb":[[0,2.58,18.98],[1,1.01,7]],"ltp":2.42,"tv":383.15,"id":9628686}]}]}
{"op":"mcm","clk":"4233662916","pt":1631537227221,"mc":[{"id":"1.187594318","rc":[{"batb":[[0,1.01,7],[1,1.01,0]],"ltp":1.63,"tv":176.59,"id":9183341},{"batb":[[0,1.01,7],[1,1.01,0]],"ltp":2.42,"tv":383.15,"id":9628686}]}]}
{"op":"mcm","clk":"4233663320","pt":1631537232264,"mc":[{"id":"1.187594318","rc":[{"batb":[[0,1.55,54.54],[1,1.01,7]],"ltp":1.63,"tv":176.59,"id":9183341},{"batb":[[0,2.34,22.38],[1,1.01,7]],"ltp":2.42,"tv":383.15,"id":9628686}]}]}
{"op":"mcm","clk":"4233663801","pt":1631537237544,"mc":[{"id":"1.187594318","rc":[{"trd":[[1.55,109.08]],"batb":[[0,1.01,7],[1,1.01,0]],"batl":[[0,1.55,53.91]],"ltp":1.55,"tv":285.67,"id":9183341}],"tv":668.83}]}
{"op":"mcm","clk":"4233663837","pt":1631537237962,"mc":[{"id":"1.187594318","rc":[{"batl":[[0,1.55,2]],"ltp":1.55,"tv":285.67,"id":9183341}]}]}
{"op":"mcm","clk":"4233663985","pt":1631537239641,"mc":[{"id":"1.187594318","rc":[{"batb":[[0,1.01,7],[1,1.01,0]],"ltp":2.42,"tv":383.15,"id":9628686}]}]}
{"op":"mcm","clk":"4233664184","pt":1631537242256,"mc":[{"id":"1.187594318","rc":[{"batl":[[0,1.55,25.55]],"ltp":1.55,"tv":285.67,"id":9183341}]}]}
{"op":"mcm","clk":"4233664269","pt":1631537243445,"mc":[{"id":"1.187594318","rc":[{"batb":[[0,1.48,62.5],[1,1.01,7]],"batl":[[0,1.55,72.4]],"ltp":1.55,"tv":285.67,"id":9183341}]}]}
{"op":"mcm","clk":"4233664355","pt":1631537244689,"mc":[{"id":"1.187594318","rc":[{"batb":[[0,2.5,20],[1,1.01,7]],"ltp":2.42,"tv":383.15,"id":9628686}]}]}
{"op":"mcm","clk":"4233664808","pt":1631537251120,"mc":[{"id":"1.187594318","rc":[{"trd":[[1.48,42.58]],"batb":[[0,1.01,7],[1,1.01,0]],"ltp":1.48,"tv":328.26,"id":9183341}],"tv":711.41}]}
{"op":"mcm","clk":"4233665209","pt":1631537256124,"mc":[{"id":"1.187594318","rc":[{"batb":[[0,1.48,62.5],[1,1.01,7]],"ltp":1.48,"tv":328.26,"id":9183341}]}]}
{"op":"mcm","clk":"4233665865","pt":1631537265331,"mc":[{"id":"1.187594318","rc":[{"batb":[[0,1.01,7],[1,1.01,0]],"ltp":1.48,"tv":328.26,"id":9183341},{"batb":[[0,1.01,7],[1,1.01,0]],"ltp":2.42,"tv":383.15,"id":9628686}]}]}
{"op":"mcm","clk":"4233666209","pt":1631537270207,"mc":[{"id":"1.187594318","rc":[{"batb":[[0,1.38,78.94],[1,1.01,7]],"ltp":1.48,"tv":328.26,"id":9183341},{"batb":[[0,2.84,16.3],[1,1.01,7]],"ltp":2.42,"tv":383.15,"id":9628686}]}]}
{"op":"mcm","clk":"4233667443","pt":1631537288965,"mc":[{"id":"1.187594318","rc":[{"batb":[[0,1.01,7],[1,1.01,0]],"ltp":1.48,"tv":328.26,"id":9183341},{"batb":[[0,1.01,7],[1,1.01,0]],"ltp":2.42,"tv":383.15,"id":9628686}]}]}
{"op":"mcm","clk":"4233667794","pt":1631537293860,"mc":[{"id":"1.187594318","rc":[{"batb":[[0,1.31,96.77],[1,1.01,7]],"ltp":1.48,"tv":328.26,"id":9183341},{"batb":[[0,3.15,13.95],[1,1.01,7]],"ltp":2.42,"tv":383.15,"id":9628686}]}]}
{"op":"mcm","clk":"4233669142","pt":1631537312925,"mc":[{"id":"1.187594318","rc":[{"batl":[[0,1.45,36.44]],"ltp":1.48,"tv":328.26,"id":9183341}]}]}
{"op":"mcm","clk":"4233669361","pt":1631537316104,"mc":[{"id":"1.187594318","rc":[{"batb":[[1,1.28,36.44],[2,1.01,7]],"ltp":1.48,"tv":328.26,"id":9183341}]}]}
{"op":"mcm","clk":"4233669416","pt":1631537316925,"mc":[{"id":"1.187594318","rc":[{"batb":[[1,1.28,72.88]],"ltp":1.48,"tv":328.26,"id":9183341}]}]}
{"op":"mcm","clk":"4233669745","pt":1631537322126,"mc":[{"id":"1.187594318","rc":[{"batb":[[0,1.28,72.88],[1,1.01,7],[2,1.01,0]],"ltp":1.48,"tv":328.26,"id":9183341},{"batb":[[0,1.01,7],[1,1.01,0]],"ltp":2.42,"tv":383.15,"id":9628686}]}]}
{"op":"mcm","clk":"4233669869","pt":1631537324140,"mc":[{"id":"1.187594318","rc":[{"batb":[[0,1.01,7],[1,1.01,0]],"ltp":1.48,"tv":328.26,"id":9183341}]}]}
{"op":"mcm","clk":"4233671557","pt":1631537348668,"mc":[{"id":"1.187594318","rc":[{"batl":[[0,1.35,36.44]],"ltp":1.48,"tv":328.26,"id":9183341}]}]}
{"op":"mcm","clk":"4233671670","pt":1631537350275,"mc":[{"id":"1.187594318","rc":[{"batb":[[0,1.16,109.32],[1,1.01,7]],"ltp":1.48,"tv":328.26,"id":9183341}]}]}
{"op":"mcm","clk":"4233673074","pt":1631537368477,"mc":[{"id":"1.187594318","rc":[{"batb":[[0,1.01,7],[1,1.01,0]],"ltp":1.48,"tv":328.26,"id":9183341},{"batb":[[0,2.02,26.47],[1,1.01,7]],"ltp":2.42,"tv":383.15,"id":9628686}]}]}
{"op":"mcm","clk":"4233673359","pt":1631537372498,"mc":[{"id":"1.187594318","rc":[{"batl":[[0,1.45,36.44]],"ltp":1.48,"tv":328.26,"id":9183341}]}]}
{"op":"mcm","clk":"4233673677","pt":1631537376517,"mc":[{"id":"1.187594318","rc":[{"batb":[[0,1.25,36.44],[1,1.01,7]],"ltp":1.48,"tv":328.26,"id":9183341}]}]}
{"op":"mcm","clk":"4233673708","pt":1631537376883,"mc":[{"id":"1.187594318","rc":[{"batb":[[0,1.25,145.76]],"ltp":1.48,"tv":328.26,"id":9183341}]}]}
{"op":"mcm","clk":"4233677579","pt":1631537430316,"mc":[{"id":"1.187594318","rc":[{"batb":[[0,1.01,7],[1,1.01,0]],"ltp":1.48,"tv":328.26,"id":9183341}]}]}
{"op":"mcm","clk":"4233678040","pt":1631537436094,"mc":[{"id":"1.187594318","rc":[{"batb":[[0,1.4,72.88],[1,1.01,7]],"ltp":1.48,"tv":328.26,"id":9183341}]}]}
{"op":"mcm","clk":"4233678267","pt":1631537438808,"mc":[{"id":"1.187594318","rc":[{"batl":[[0,1.66,36.44]],"ltp":1.48,"tv":328.26,"id":9183341}]}]}
{"op":"mcm","clk":"4233678671","pt":1631537444000,"mc":[{"id":"1.187594318","rc":[{"batb":[[0,1.01,7],[1,1.01,0]],"ltp":2.42,"tv":383.15,"id":9628686}]}]}
{"op":"mcm","clk":"4233680731","pt":1631537472141,"mc":[{"id":"1.187594318","rc":[{"batb":[[0,1.01,7],[1,1.01,0]],"ltp":1.48,"tv":328.26,"id":9183341}]}]}
{"op":"mcm","clk":"4233681387","pt":1631537482575,"mc":[{"id":"1.187594318","rc":[{"batb":[[0,1.24,36.44],[1,1.01,7]],"ltp":1.48,"tv":328.26,"id":9183341}]}]}
{"op":"mcm","clk":"4233681414","pt":1631537483080,"mc":[{"id":"1.187594318","rc":[{"batb":[[0,1.24,145.76]],"ltp":1.48,"tv":328.26,"id":9183341}]}]}
{"op":"mcm","clk":"4233681605","pt":1631537485687,"mc":[{"id":"1.187594318","rc":[{"batl":[[0,1.44,36.44]],"ltp":1.48,"tv":328.26,"id":9183341}]}]}
{"op":"mcm","clk":"4233683092","pt":1631537509826,"mc":[{"id":"1.187594318","rc":[{"batb":[[0,1.01,7],[1,1.01,0]],"ltp":1.48,"tv":328.26,"id":9183341}]}]}
{"op":"mcm","clk":"4233683413","pt":1631537515544,"mc":[{"id":"1.187594318","rc":[{"batl":[[0,3.25,99.32]],"ltp":2.42,"tv":383.15,"id":9628686}]}]}
{"op":"mcm","clk":"4233683498","pt":1631537516640,"mc":[{"id":"1.187594318","rc":[{"batl":[[0,3.25,64.05]],"ltp":2.42,"tv":383.15,"id":9628686}]}]}
{"op":"mcm","clk":"4233683647","pt":1631537518657,"mc":[{"id":"1.187594318","rc":[{"batl":[[0,1.7,36.44]],"ltp":1.48,"tv":328.26,"id":9183341}]}]}
{"op":"mcm","clk":"4233683914","pt":1631537521627,"mc":[{"id":"1.187594318","rc":[{"batb":[[0,1.48,36.44],[1,1.01,7]],"ltp":1.48,"tv":328.26,"id":9183341}]}]}
{"op":"mcm","clk":"4233683926","pt":1631537521833,"mc":[{"id":"1.187594318","rc":[{"batb":[[0,1.48,72.88]],"ltp":1.48,"tv":328.26,"id":9183341}]}]}
{"op":"mcm","clk":"4233685149","pt":1631537539061,"mc":[{"id":"1.187594318","rc":[{"batb":[[0,1.01,7],[1,1.01,0]],"ltp":1.48,"tv":328.26,"id":9183341}]}]}
{"op":"mcm","clk":"4233685504","pt":1631537544573,"mc":[{"id":"1.187594318","rc":[{"batl":[[0,1.48,204.21],[1,1.7,36.44]],"ltp":1.48,"tv":328.26,"id":9183341}]}]}
{"op":"mcm","clk":"4233685533","pt":1631537544948,"mc":[{"id":"1.187594318","rc":[{"batl":[[0,1.7,36.44],[1,1.7,0]],"ltp":1.48,"tv":328.26,"id":9183341}]}]}
{"op":"mcm","clk":"4233695581","pt":1631537708781,"mc":[{"id":"1.187594318","rc":[{"batb":[[0,1.08,80.89],[1,1.01,7]],"ltp":2.42,"tv":383.15,"id":9628686}]}]}
{"op":"mcm","clk":"4233696066","pt":1631537716203,"mc":[{"id":"1.187594318","rc":[{"trd":[[1.01,14]],"batl":[[0,1.01,10.03]],"ltp":1.01,"tv":342.26,"id":9183341}],"tv":725.42}]}
{"op":"mcm","clk":"4233696265","pt":1631537719599,"mc":[{"id":"1.187594318","rc":[{"batl":[[0,1.01,27.07]],"ltp":1.01,"tv":342.26,"id":9183341}]}]}
{"op":"mcm","clk":"4233702971","pt":1631537830006,"mc":[{"id":"1.187594318","rc":[{"batb":[[0,1.01,7],[1,1.01,0]],"ltp":2.42,"tv":383.15,"id":9628686}]}]}
{"op":"mcm","clk":"4233703275","pt":1631537835307,"mc":[{"id":"1.187594318","rc":[{"batb":[[0,1.05,80.89],[1,1.01,7]],"ltp":2.42,"tv":383.15,"id":9628686}]}]}
{"op":"mcm","clk":"4233703435","pt":1631537837933,"mc":[{"id":"1.187594318","marketDefinition":{"bspMarket":false,"turnInPlayEnabled":true,"persistenceEnabled":true,"marketBaseRate":5.0,"eventId":"30897871","eventTypeId":"2","numberOfWinners":1,"bettingType":"ODDS","marketType":"MATCH_ODDS","marketTime":"2021-09-13T11:16:57.000Z","suspendTime":"2021-09-13T11:16:57.000Z","bspReconciled":false,"complete":true,"inPlay":true,"crossMatching":true,"runnersVoidable":false,"numberOfActiveRunners":2,"betDelay":5,"status":"SUSPENDED","runners":[{"status":"ACTIVE","sortPriority":1,"id":9183341,"name":"E Silva"},{"status":"ACTIVE","sortPriority":2,"id":9628686,"name":"H Kuwata"}],"regulators":["MR_INT"],"countryCode":"GB","discountAllowed":true,"timezone":"GMT","openDate":"2021-09-13T11:16:57.000Z","version":4030666425,"name":"Match Odds","eventName":"E Silva v H Kuwata"}}]}
{"op":"mcm","clk":"4233703646","pt":1631537841835,"mc":[{"id":"1.187594318","tv":0.0}]}
{"op":"mcm","clk":"4233703713","pt":1631537842965,"mc":[{"id":"1.187594318","marketDefinition":{"bspMarket":false,"turnInPlayEnabled":true,"persistenceEnabled":true,"marketBaseRate":5.0,"eventId":"30897871","eventTypeId":"2","numberOfWinners":1,"bettingType":"ODDS","marketType":"MATCH_ODDS","marketTime":"2021-09-13T11:16:57.000Z","suspendTime":"2021-09-13T11:16:57.000Z","bspReconciled":false,"complete":true,"inPlay":true,"crossMatching":false,"runnersVoidable":false,"numberOfActiveRunners":0,"betDelay":5,"status":"CLOSED","settledTime":"2021-09-13T12:57:20.000Z","runners":[{"status":"WINNER","sortPriority":1,"id":9183341,"name":"E Silva"},{"status":"LOSER","sortPriority":2,"id":9628686,"name":"H Kuwata"}],"regulators":["MR_INT"],"countryCode":"GB","discountAllowed":true,"timezone":"GMT","openDate":"2021-09-13T11:16:57.000Z","version":4030666453,"name":"Match Odds","eventName":"E Silva v H Kuwata"}}]}
