{"op":"mcm","clk":"4226781253","pt":1631451353538,"mc":[{"id":"1.187552454","rc":[{"trd":[[17.5,49.59]],"batb":[[0,17,2],[1,15,4],[2,14.5,2]],"batl":[[0,17.5,6.54],[1,24,24.46],[2,55,2]],"ltp":17.5,"tv":5795.05,"id":9345630},{"batb":[[0,1.05,2096.6],[1,1.04,41.87],[2,1.03,948.84]],"ltp":1.04,"tv":72167.97,"id":9028621}],"tv":77963.03}]}
{"op":"mcm","clk":"4226781378","pt":1631451354475,"mc":[{"id":"1.187552454","rc":[{"batb":[[0,15,4],[1,14.5,4.44],[2,13.5,2]],"batl":[[1,22,13.09],[2,24,22.46]],"ltp":17.5,"tv":5795.05,"id":9345630},{"batb":[[0,1.05,2364.92],[1,1.04,91.87],[2,1.03,1005.84]],"batl":[[1,1.08,235.44]],"ltp":1.04,"tv":72167.97,"id":9028621}]}]}
{"op":"mcm","clk":"4226781530","pt":1631451355567,"mc":[{"id":"1.187552454","rc":[{"trd":[[17.5,59.07]],"batb":[[0,15.5,11.07],[1,15,4],[2,14.5,4.44]],"batl":[[0,17.5,1.8],[1,20,2],[2,22,22.81]],"ltp":17.5,"tv":5804.53,"id":9345630},{"batb":[[0,1.05,2579.16],[1,1.04,264.08]],"batl":[[0,1.07,2377.07]],"ltp":1.04,"tv":72167.97,"id":9028621}],"tv":77972.51}]}
{"op":"mcm","clk":"4226781651","pt":1631451356561,"mc":[{"id":"1.187552454","rc":[{"batb":[[0,15.5,2]],"ltp":17.5,"tv":5804.53,"id":9345630},{"batb":[[0,1.05,2716.93],[1,1.04,222.21]],"ltp":1.04,"tv":72167.97,"id":9028621}]}]}
{"op":"mcm","clk":"4226781805","pt":1631451357564,"mc":[{"id":"1.187552454","rc":[{"batb":[[1,15,2]],"ltp":17.5,"tv":5804.53,"id":9345630}]}]}
{"op":"mcm","clk":"4226781923","pt":1631451358459,"mc":[{"id":"1.187552454","rc":[{"batl":[[1,19.5,2],[2,20,2]],"ltp":17.5,"tv":5804.53,"id":9345630}]}]}
{"op":"mcm","clk":"4226781968","pt":1631451358746,"mc":[{"id":"1.187552454","rc":[{"batb":[[0,16,9.07],[1,15.5,2],[2,15,2]],"ltp":17.5,"tv":5804.53,"id":9345630}]}]}
{"op":"mcm","clk":"4226782079","pt":1631451359657,"mc":[{"id":"1.187552454","rc":[{"batb":[[2,1.03,1049.87]],"ltp":1.04,"tv":72167.97,"id":9028621}]}]}
{"op":"mcm","clk":"4226782465","pt":1631451362347,"mc":[{"id":"1.187552454","rc":[{"batl":[[0,19,2]],"ltp":17.5,"tv":5804.53,"id":9345630}]}]}
{"op":"mcm","clk":"4226782625","pt":1631451363492,"mc":[{"id":"1.187552454","rc":[{"batb":[[2,1.03,1008]],"ltp":1.04,"tv":72167.97,"id":9028621}]}]}
{"op":"mcm","clk":"4226782718","pt":1631451364064,"mc":[{"id":"1.187552454","rc":[{"batl":[[0,1.06,327.49],[1,1.07,2377.07],[2,1.08,235.44]],"ltp":1.04,"tv":72167.97,"id":9028621}]}]}
{"op":"mcm","clk":"4226782814","pt":1631451364891,"mc":[{"id":"1.187552454","rc":[{"batl":[[0,18.5,2],[1,19,2],[2,19.5,2]],"ltp":17.5,"tv":5804.53,"id":9345630}]}]}
{"op":"mcm","clk":"4226783066","pt":1631451366572,"mc":[{"id":"1.187552454","rc":[{"batl":[[0,18.5,4.98]],"ltp":17.5,"tv":5804.53,"id":9345630},{"trd":[[1.06,929.02]],"batl":[[0,1.06,285.62]],"ltp":1.06,"tv":72251.71,"id":9028621}],"tv":78056.24}]}
{"op":"mcm","clk":"4226783176","pt":1631451367571,"mc":[{"id":"1.187552454","rc":[{"batb":[[2,14.5,4.44]],"ltp":17.5,"tv":5804.53,"id":9345630},{"batb":[[1,1.04,172.21],[2,1.03,951]],"ltp":1.06,"tv":72251.71,"id":9028621}]}]}
{"op":"mcm","clk":"4226783520","pt":1631451370286,"mc":[{"id":"1.187552454","rc":[{"trd":[[1.06,1001.32]],"batb":[[0,1.05,2579.16],[1,1.03,951],[2,1.02,1635.08]],"batl":[[0,1.06,255.43]],"ltp":1.06,"tv":72324.01,"id":9028621}],"tv":78128.55}]}
{"op":"mcm","clk":"4226783948","pt":1631451373468,"mc":[{"id":"1.187552454","rc":[{"batb":[[1,1.03,1180.62]],"ltp":1.06,"tv":72324.01,"id":9028621}]}]}
{"op":"mcm","clk":"4226784082","pt":1631451374499,"mc":[{"id":"1.187552454","rc":[{"batl":[[1,21,13.41],[2,24,2]],"ltp":17.5,"tv":5804.53,"id":9345630},{"trd":[[1.05,378.69]],"batb":[[0,1.05,2571.36]],"ltp":1.05,"tv":72339.61,"id":9028621}],"tv":78144.14}]}
{"op":"mcm","clk":"4226784131","pt":1631451374798,"mc":[{"id":"1.187552454","rc":[{"trd":[[18.5,4]],"batb":[[0,18.5,4.37],[1,14.5,4.44],[2,13.5,2]],"batl":[[0,21,13.41],[1,36,2],[2,55,2]],"ltp":18.5,"tv":5808.52,"id":9345630},{"batb":[[0,1.05,268.32]],"batl":[[1,1.08,235.44],[2,1.09,139.69]],"ltp":1.05,"tv":72339.61,"id":9028621}],"tv":78148.14}]}
{"op":"mcm","clk":"4226784381","pt":1631451376505,"mc":[{"id":"1.187552454","rc":[{"batb":[[1,13.5,2],[2,12,2]],"batl":[[0,36,2],[1,55,2],[2,110,2]],"ltp":18.5,"tv":5808.52,"id":9345630},{"batb":[[0,1.03,1180.62],[1,1.02,1635.08],[2,1.01,6112.04]],"batl":[[1,1.08,175.44]],"ltp":1.05,"tv":72339.61,"id":9028621}]}]}
{"op":"mcm","clk":"4226784532","pt":1631451377508,"mc":[{"id":"1.187552454","rc":[{"batb":[[0,13.5,2],[1,12,2],[2,11,2]],"ltp":18.5,"tv":5808.52,"id":9345630},{"batb":[[0,1.03,3317.93]],"batl":[[2,1.09,2159.35]],"ltp":1.05,"tv":72339.61,"id":9028621}]}]}
{"op":"mcm","clk":"4226784727","pt":1631451379004,"mc":[{"id":"1.187552454","rc":[{"batb":[[0,1.03,1180.62]],"ltp":1.05,"tv":72339.61,"id":9028621}]}]}
{"op":"mcm","clk":"4226784926","pt":1631451380486,"mc":[{"id":"1.187552454","rc":[{"batl":[[0,14.5,1579.44],[1,16,146.88],[2,36,2]],"ltp":18.5,"tv":5808.52,"id":9345630},{"trd":[[1.06,1013.24]],"batl":[[0,1.08,175.44],[1,1.09,2159.35],[2,1.1,114.5]],"ltp":1.06,"tv":72351.53,"id":9028621}],"tv":78160.06}]}
{"op":"mcm","clk":"4226785042","pt":1631451381370,"mc":[{"id":"1.187552454","rc":[{"batl":[[0,16,7.34],[1,17.5,8.54]],"ltp":18.5,"tv":5808.52,"id":9345630},{"batb":[[2,1.01,2186.85]],"ltp":1.06,"tv":72351.53,"id":9028621}]}]}
{"op":"mcm","clk":"4226785191","pt":1631451382486,"mc":[{"id":"1.187552454","rc":[{"batl":[[0,16,36.72],[1,17.5,10.54]],"ltp":18.5,"tv":5808.52,"id":9345630},{"batb":[[0,1.07,2185.65],[1,1.04,15.34],[2,1.03,1190.62]],"ltp":1.06,"tv":72351.53,"id":9028621}]}]}
{"op":"mcm","clk":"4226785317","pt":1631451383479,"mc":[{"id":"1.187552454","rc":[{"trd":[[15.5,6.85]],"batb":[[1,12.5,5.21],[2,12,2]],"batl":[[0,15,144.6],[1,16,36.72],[2,17.5,25.31]],"ltp":15.5,"tv":5810.77,"id":9345630},{"trd":[[1.07,643.07]],"batb":[[0,1.07,2153.11]],"ltp":1.07,"tv":72384.07,"id":9028621}],"tv":78194.85}]}
{"op":"mcm","clk":"4226785430","pt":1631451384415,"mc":[{"id":"1.187552454","rc":[{"batb":[[1,12,2],[2,11,2]],"batl":[[0,15.5,2],[2,17.5,10.54]],"ltp":15.5,"tv":5810.77,"id":9345630},{"batb":[[0,1.07,2190.11],[1,1.06,42],[2,1.04,15.34]],"batl":[[1,1.09,2219.35]],"ltp":1.07,"tv":72384.07,"id":9028621}]}]}
{"op":"mcm","clk":"4226785591","pt":1631451385509,"mc":[{"id":"1.187552454","rc":[{"batb":[[1,11,2],[2,2.32,102.49]],"batl":[[0,15,2],[1,15.5,11.78],[2,16,36.72]],"ltp":15.5,"tv":5810.77,"id":9345630},{"batb":[[0,1.07,2430.49],[1,1.06,42.6]],"ltp":1.07,"tv":72384.07,"id":9028621}]}]}
{"op":"mcm","clk":"4226785720","pt":1631451386577,"mc":[{"id":"1.187552454","rc":[{"batl":[[0,14.5,2],[1,15,2],[2,15.5,2]],"ltp":15.5,"tv":5810.77,"id":9345630},{"batb":[[1,1.06,287.54]],"ltp":1.07,"tv":72384.07,"id":9028621}]}]}
{"op":"mcm","clk":"4226785792","pt":1631451387202,"mc":[{"id":"1.187552454","rc":[{"batb":[[1,11.5,5.71],[2,11,2]],"ltp":15.5,"tv":5810.77,"id":9345630}]}]}
{"op":"mcm","clk":"4226785961","pt":1631451388404,"mc":[{"id":"1.187552454","rc":[{"batb":[[2,1.04,17.46]],"ltp":1.07,"tv":72384.07,"id":9028621}]}]}
{"op":"mcm","clk":"4226786136","pt":1631451389586,"mc":[{"id":"1.187552454","rc":[{"trd":[[14.5,9.96]],"batb":[[1,12,2],[2,11.5,5.71]],"batl":[[0,14.5,8.8]],"ltp":14.5,"tv":5816.73,"id":9345630},{"trd":[[1.07,1137.35]],"batb":[[0,1.07,2062.59]],"ltp":1.07,"tv":72878.35,"id":9028621}],"tv":78695.09}]}
{"op":"mcm","clk":"4226786244","pt":1631451390422,"mc":[{"id":"1.187552454","rc":[{"batl":[[0,14,2],[1,14.5,8.8],[2,15,2]],"ltp":14.5,"tv":5816.73,"id":9345630}]}]}
{"op":"mcm","clk":"4226786493","pt":1631451392580,"mc":[{"id":"1.187552454","rc":[{"trd":[[14,8.01],[14.5,13.04]],"batl":[[0,14.5,7.26],[1,15,2],[2,15.5,2]],"ltp":14.5,"tv":5823.81,"id":9345630},{"batb":[[0,1.07,2214.03]],"ltp":1.07,"tv":72878.35,"id":9028621}],"tv":78702.17}]}
{"op":"mcm","clk":"4226786590","pt":1631451393390,"mc":[{"id":"1.187552454","rc":[{"trd":[[14.5,19.42]],"batl":[[0,14.5,4.07]],"ltp":14.5,"tv":5830.19,"id":9345630}],"tv":78708.55}]}
{"op":"mcm","clk":"4226786802","pt":1631451395180,"mc":[{"id":"1.187552454","rc":[{"batb":[[0,12,2],[1,11.5,5.71],[2,11,2]],"ltp":14.5,"tv":5830.19,"id":9345630},{"trd":[[1.08,1050.21]],"batb":[[1,1.06,245.54]],"batl":[[0,1.08,102.54]],"ltp":1.08,"tv":73024.15,"id":9028621}],"tv":78854.35}]}
{"op":"mcm","clk":"4226787023","pt":1631451397094,"mc":[{"id":"1.187552454","rc":[{"batl":[[2,16,36.72]],"ltp":14.5,"tv":5830.19,"id":9345630},{"trd":[[1.07,1194.37]],"batb":[[0,1.07,2185.52]],"ltp":1.07,"tv":73081.18,"id":9028621}],"tv":78911.37}]}
{"op":"mcm","clk":"4226787170","pt":1631451398421,"mc":[{"id":"1.187552454","rc":[{"batb":[[0,12.5,7.24],[1,12,2],[2,11.5,5.71]],"ltp":14.5,"tv":5830.19,"id":9345630},{"batb":[[1,1.06,244.94]],"ltp":1.07,"tv":73081.18,"id":9028621}]}]}
{"op":"mcm","clk":"4226787234","pt":1631451399019,"mc":[{"id":"1.187552454","rc":[{"batb":[[2,1.04,2.12]],"ltp":1.07,"tv":73081.18,"id":9028621}]}]}
{"op":"mcm","clk":"4226787497","pt":1631451401412,"mc":[{"id":"1.187552454","rc":[{"batb":[[0,12,2.2],[1,11.5,5.71],[2,11,2]],"batl":[[0,16.5,15.24],[1,17.5,2],[2,26,2]],"ltp":14.5,"tv":5830.19,"id":9345630},{"batb":[[0,1.06,244.94],[1,1.04,2.12],[2,1.03,2651.65]],"batl":[[0,1.09,199.69],[1,1.1,114.5],[2,1.11,114.5]],"ltp":1.07,"tv":73081.18,"id":9028621}]}]}
{"op":"mcm","clk":"4226787637","pt":1631451402531,"mc":[{"id":"1.187552454","rc":[{"batb":[[0,11,2.2],[1,2.32,102.49],[2,1.01,30]],"batl":[[0,26,2],[1,36,2],[2,55,2]],"ltp":14.5,"tv":5830.19,"id":9345630},{"batb":[[0,1.04,2.12],[1,1.03,2641.65],[2,1.02,1635.08]],"batl":[[0,1.1,114.69],[1,1.11,114.5],[2,1.13,14.83]],"ltp":1.07,"tv":73081.18,"id":9028621}]}]}
{"op":"mcm","clk":"4226787675","pt":1631451402830,"mc":[{"id":"1.187552454","rc":[{"batl":[[0,36,2],[1,55,2],[2,110,2]],"ltp":14.5,"tv":5830.19,"id":9345630},{"batb":[[0,1.03,2641.65],[1,1.02,1635.08],[2,1.01,2186.85]],"batl":[[1,1.13,14.83],[2,1.15,14.83]],"ltp":1.07,"tv":73081.18,"id":9028621}]}]}
{"op":"mcm","clk":"4226787889","pt":1631451404492,"mc":[{"id":"1.187552454","rc":[{"trd":[[14.5,19.82]],"batb":[[0,11,2]],"batl":[[0,13.5,3.2],[1,14,1.8],[2,36,2]],"ltp":14.5,"tv":5830.59,"id":9345630},{"trd":[[1.09,2236.09]],"batb":[[0,1.09,249.81],[1,1.05,790.47],[2,1.04,1319.31]],"batl":[[0,1.1,114.5],[1,1.11,1050.29],[2,1.12,924.64]],"ltp":1.09,"tv":73081.55,"id":9028621}],"tv":78912.15}]}
{"op":"mcm","clk":"4226787972","pt":1631451405188,"mc":[{"id":"1.187552454","rc":[{"batl":[[1,36,2],[2,55,2]],"ltp":14.5,"tv":5830.59,"id":9345630},{"trd":[[1.09,2545.09]],"batb":[[0,1.09,95.31]],"ltp":1.09,"tv":73390.55,"id":9028621}],"tv":79221.15}]}
{"op":"mcm","clk":"4226788096","pt":1631451406305,"mc":[{"id":"1.187552454","rc":[{"batl":[[1,26,4],[2,36,4]],"ltp":14.5,"tv":5830.59,"id":9345630},{"batb":[[2,1.04,1638.68]],"ltp":1.09,"tv":73390.55,"id":9028621}]}]}
{"op":"mcm","clk":"4226788203","pt":1631451407428,"mc":[{"id":"1.187552454","rc":[{"batl":[[0,26,4],[1,36,4],[2,55,2]],"ltp":14.5,"tv":5830.59,"id":9345630}]}]}
{"op":"mcm","clk":"4226788320","pt":1631451408416,"mc":[{"id":"1.187552454","rc":[{"batb":[[0,1.05,790.47],[1,1.04,2078.43],[2,1.03,2644.65]],"ltp":1.09,"tv":73390.55,"id":9028621}]}]}
{"op":"mcm","clk":"4226788527","pt":1631451410343,"mc":[{"id":"1.187552454","rc":[{"trd":[[11,12.96]],"batb":[[0,2.32,102.49],[1,1.01,30],[2,1.01,0]],"ltp":11.0,"tv":5836.8,"id":9345630},{"trd":[[1.1,2166.69]],"batl":[[0,1.1,92.47]],"ltp":1.1,"tv":73412.58,"id":9028621}],"tv":79249.39}]}
{"op":"mcm","clk":"4226788731","pt":1631451411754,"mc":[{"id":"1.187552454","rc":[{"batb":[[0,1.05,789.85]],"ltp":1.1,"tv":73412.58,"id":9028621}]}]}
{"op":"mcm","clk":"4226788916","pt":1631451413542,"mc":[{"id":"1.187552454","rc":[{"batb":[[0,10,2],[1,9.8,2],[2,2.32,102.49]],"ltp":11.0,"tv":5836.8,"id":9345630}]}]}
{"op":"mcm","clk":"4226789290","pt":1631451416869,"mc":[{"id":"1.187552454","rc":[{"batb":[[0,1.06,33.15],[1,1.05,789.85],[2,1.04,2078.43]],"ltp":1.1,"tv":73412.58,"id":9028621}]}]}
{"op":"mcm","clk":"4226789607","pt":1631451419455,"mc":[{"id":"1.187552454","rc":[{"trd":[[1.06,1079.54]],"batb":[[0,1.05,789.85],[1,1.04,2078.43],[2,1.03,2644.65]],"batl":[[0,1.06,68.07],[1,1.1,92.47],[2,1.11,1050.29]],"ltp":1.06,"tv":73478.89,"id":9028621}],"tv":79315.69}]}
{"op":"mcm","clk":"4226789649","pt":1631451419765,"mc":[{"id":"1.187552454","rc":[{"batl":[[1,36,2]],"ltp":11.0,"tv":5836.8,"id":9345630},{"batb":[[2,1.03,2641.65]],"batl":[[2,1.19,14.83]],"ltp":1.06,"tv":73478.89,"id":9028621}]}]}
{"op":"mcm","clk":"4226789904","pt":1631451421592,"mc":[{"id":"1.187552454","rc":[{"batb":[[0,16.5,5.8],[1,16,5.62],[2,15.5,5.62]],"ltp":11.0,"tv":5836.8,"id":9345630},{"batl":[[0,1.06,76.61]],"ltp":1.06,"tv":73478.89,"id":9028621}]}]}
{"op":"mcm","clk":"4226790031","pt":1631451422589,"mc":[{"id":"1.187552454","rc":[{"batb":[[0,16.5,20.05],[1,16,19.45],[2,15.5,19.45]],"batl":[[1,27,141.66],[2,28,137.5]],"ltp":11.0,"tv":5836.8,"id":9345630},{"trd":[[1.06,1096.62]],"batb":[[2,1.03,1180.62]],"batl":[[0,1.1,92.47],[1,1.19,14.83],[2,1.21,14.83]],"ltp":1.06,"tv":73495.97,"id":9028621}],"tv":79332.77}]}
{"op":"mcm","clk":"4226790135","pt":1631451423286,"mc":[{"id":"1.187552454","rc":[{"batb":[[0,16.5,12.93],[1,16,12.53],[2,15.5,12.53]],"batl":[[1,27,38.96],[2,28,37.81]],"ltp":11.0,"tv":5836.8,"id":9345630},{"batl":[[0,1.06,2076.82],[1,1.1,106.97],[2,1.12,7.12]],"ltp":1.06,"tv":73495.97,"id":9028621}]}]}
{"op":"mcm","clk":"4226790314","pt":1631451424501,"mc":[{"id":"1.187552454","rc":[{"batl":[[0,24,12.51],[1,26,4],[2,27,38.96]],"ltp":11.0,"tv":5836.8,"id":9345630},{"batb":[[1,1.04,2378.43]],"batl":[[1,1.08,60],[2,1.1,106.97]],"ltp":1.06,"tv":73495.97,"id":9028621}]}]}
{"op":"mcm","clk":"4226790600","pt":1631451426373,"mc":[{"id":"1.187552454","rc":[{"batl":[[1,1.1,106.97],[2,1.12,7.12]],"ltp":1.06,"tv":73495.97,"id":9028621}]}]}
{"op":"mcm","clk":"4226790744","pt":1631451427475,"mc":[{"id":"1.187552454","rc":[{"batl":[[1,25,19.13],[2,26,4]],"ltp":11.0,"tv":5836.8,"id":9345630},{"batb":[[1,1.04,1938.68]],"batl":[[0,1.06,2412.47]],"ltp":1.06,"tv":73495.97,"id":9028621}]}]}
{"op":"mcm","clk":"4226790830","pt":1631451428072,"mc":[{"id":"1.187552454","rc":[{"batb":[[0,17.5,2],[1,17,3],[2,16.5,12.93]],"batl":[[1,26,4],[2,27,38.96]],"ltp":11.0,"tv":5836.8,"id":9345630},{"batl":[[0,1.06,2109.82]],"ltp":1.06,"tv":73495.97,"id":9028621}]}]}
{"op":"mcm","clk":"4226791044","pt":1631451429591,"mc":[{"id":"1.187552454","rc":[{"batl":[[1,1.07,60],[2,1.1,106.97]],"ltp":1.06,"tv":73495.97,"id":9028621}]}]}
{"op":"mcm","clk":"4226791096","pt":1631451429961,"mc":[{"id":"1.187552454","rc":[{"batb":[[0,1.05,1229.6]],"ltp":1.06,"tv":73495.97,"id":9028621}]}]}
{"op":"mcm","clk":"4226791677","pt":1631451434297,"mc":[{"id":"1.187552454","rc":[{"trd":[[1.06,1113.7]],"batl":[[0,1.06,2101.28]],"ltp":1.06,"tv":73513.05,"id":9028621}],"tv":79349.85}]}
{"op":"mcm","clk":"4226791972","pt":1631451436386,"mc":[{"id":"1.187552454","rc":[{"batb":[[0,19.5,4],[1,17.5,2],[2,17,3]],"ltp":11.0,"tv":5836.8,"id":9345630},{"batl":[[2,1.09,18]],"ltp":1.06,"tv":73513.05,"id":9028621}]}]}
{"op":"mcm","clk":"4226792012","pt":1631451436716,"mc":[{"id":"1.187552454","rc":[{"batb":[[0,19.5,2],[1,17,3],[2,16.5,12.93]],"ltp":11.0,"tv":5836.8,"id":9345630},{"batl":[[0,1.06,2068.28],[2,1.09,9]],"ltp":1.06,"tv":73513.05,"id":9028621}]}]}
{"op":"mcm","clk":"4226792212","pt":1631451438403,"mc":[{"id":"1.187552454","rc":[{"batb":[[1,18,6.12],[2,17,3]],"batl":[[0,23,6.12],[1,24,12.51],[2,26,4]],"ltp":11.0,"tv":5836.8,"id":9345630},{"batb":[[0,1.05,1281.66]],"batl":[[0,1.06,2192.73]],"ltp":1.06,"tv":73513.05,"id":9028621}]}]}
{"op":"mcm","clk":"4226792368","pt":1631451439505,"mc":[{"id":"1.187552454","rc":[{"batb":[[1,17,3],[2,15.5,4.13]],"batl":[[0,24,12.51],[1,26,4],[2,36,2]],"ltp":11.0,"tv":5836.8,"id":9345630},{"batb":[[0,1.05,439.75],[1,1.04,619.37]],"batl":[[0,1.07,60],[1,1.09,9],[2,1.1,106.97]],"ltp":1.06,"tv":73513.05,"id":9028621}]}]}
{"op":"mcm","clk":"4226792415","pt":1631451439827,"mc":[{"id":"1.187552454","rc":[{"trd":[[19.5,0.11]],"batb":[[0,15.5,4.13],[1,2.32,102.49],[2,1.01,30]],"batl":[[1,110,2],[2,1000,0.32]],"ltp":19.5,"tv":5836.91,"id":9345630},{"trd":[[1.06,1115.65]],"batb":[[1,1.04,300],[2,1.03,1178.46]],"batl":[[1,1.17,29.67],[2,1.19,14.83]],"ltp":1.06,"tv":73515.0,"id":9028621}],"tv":79351.91}]}
{"op":"mcm","clk":"4226792677","pt":1631451441506,"mc":[{"id":"1.187552454","rc":[{"batb":[[0,2.32,102.49],[1,1.01,30],[2,1.01,0]],"batl":[[0,110,2],[1,1000,0.32],[2,1000,0]],"ltp":19.5,"tv":5836.91,"id":9345630},{"batb":[[0,1.06,1.55],[1,1.05,439.75]],"batl":[[0,1.17,29.67],[1,1.19,14.83],[2,1.21,14.83]],"ltp":1.06,"tv":73515.0,"id":9028621}]}]}
{"op":"mcm","clk":"4226792790","pt":1631451442518,"mc":[{"id":"1.187552454","rc":[{"batb":[[0,1.06,1.75]],"batl":[[0,1.09,2019.66],[1,1.17,29.67],[2,1.19,14.83]],"ltp":1.06,"tv":73515.0,"id":9028621}]}]}
{"op":"mcm","clk":"4226793090","pt":1631451444791,"mc":[{"id":"1.187552454","rc":[{"batb":[[0,6.8,2],[1,6.6,2],[2,2.32,102.49]],"ltp":19.5,"tv":5836.91,"id":9345630},{"batl":[[1,1.11,20],[2,1.17,45.67]],"ltp":1.06,"tv":73515.0,"id":9028621}]}]}
{"op":"mcm","clk":"4226793281","pt":1631451446423,"mc":[{"id":"1.187552454","rc":[{"batb":[[0,12,2],[1,11.5,2],[2,6.8,2]],"ltp":19.5,"tv":5836.91,"id":9345630},{"batl":[[0,1.09,2042.66]],"ltp":1.06,"tv":73515.0,"id":9028621}]}]}
{"op":"mcm","clk":"4226793368","pt":1631451447119,"mc":[{"id":"1.187552454","rc":[{"batl":[[0,1.08,35.1],[1,1.09,2042.66],[2,1.11,20]],"ltp":1.06,"tv":73515.0,"id":9028621}]}]}
{"op":"mcm","clk":"4226793656","pt":1631451449518,"mc":[{"id":"1.187552454","rc":[{"batl":[[0,14.5,162.07],[1,110,2],[2,1000,0.32]],"ltp":19.5,"tv":5836.91,"id":9345630},{"trd":[[1.08,1120.41]],"batb":[[0,1.08,73.35],[1,1.06,1.75],[2,1.05,439.75]],"batl":[[0,1.09,2042.66],[1,1.11,20],[2,1.17,45.67]],"ltp":1.08,"tv":73585.2,"id":9028621}],"tv":79422.11}]}
{"op":"mcm","clk":"4226793670","pt":1631451449619,"mc":[{"id":"1.187552454","rc":[{"trd":[[12,177.14]],"batb":[[0,11.5,2],[1,6.8,2],[2,6.6,2]],"batl":[[0,14.5,8.1]],"ltp":12.0,"tv":5847.45,"id":9345630},{"trd":[[1.09,2617.11]],"batl":[[0,1.09,1970.64]],"ltp":1.09,"tv":73657.22,"id":9028621}],"tv":79504.67}]}
{"op":"mcm","clk":"4226793939","pt":1631451451594,"mc":[{"id":"1.187552454","rc":[{"batl":[[0,14.5,40.51],[1,18,2.38],[2,110,2]],"ltp":12.0,"tv":5847.45,"id":9345630},{"batb":[[1,1.07,1741.28],[2,1.06,119.63]],"batl":[[0,1.09,1672.35],[2,1.12,14.25]],"ltp":1.09,"tv":73657.22,"id":9028621}]}]}
{"op":"mcm","clk":"4226794057","pt":1631451452523,"mc":[{"id":"1.187552454","rc":[{"trd":[[13.5,13.33]],"batb":[[0,11.5,7.71]],"batl":[[1,17,15],[2,17.5,2]],"ltp":13.5,"tv":5849.45,"id":9345630},{"trd":[[1.08,1242.11]],"batb":[[0,1.07,1741.28],[1,1.06,119.63],[2,1.05,439.75]],"batl":[[1,1.1,60],[2,1.11,20]],"ltp":1.08,"tv":73778.92,"id":9028621}],"tv":79628.37}]}
{"op":"mcm","clk":"4226794164","pt":1631451453316,"mc":[{"id":"1.187552454","rc":[{"batb":[[0,12,10],[1,11.5,2],[2,11,2]],"batl":[[0,14.5,45.28],[1,17.5,2],[2,18,2.38]],"ltp":13.5,"tv":5849.45,"id":9345630},{"batl":[[0,1.09,1790.03]],"ltp":1.08,"tv":73778.92,"id":9028621}]}]}
{"op":"mcm","clk":"4226794314","pt":1631451454517,"mc":[{"id":"1.187552454","rc":[{"batb":[[0,1.07,1760.96]],"ltp":1.08,"tv":73778.92,"id":9028621}]}]}
{"op":"mcm","clk":"4226794383","pt":1631451454999,"mc":[{"id":"1.187552454","rc":[{"batl":[[0,14,2],[1,14.5,45.28],[2,17.5,2]],"ltp":13.5,"tv":5849.45,"id":9345630},{"batb":[[0,1.07,1873.75],[1,1.06,683.88]],"batl":[[0,1.08,350.52],[1,1.09,1790.03],[2,1.1,60]],"ltp":1.08,"tv":73778.92,"id":9028621}]}]}
{"op":"mcm","clk":"4226794591","pt":1631451456336,"mc":[{"id":"1.187552454","rc":[{"batb":[[1,11.5,7.71]],"ltp":13.5,"tv":5849.45,"id":9345630}]}]}
{"op":"mcm","clk":"4226795003","pt":1631451459202,"mc":[{"id":"1.187552454","rc":[{"batl":[[2,16,15.49]],"ltp":13.5,"tv":5849.45,"id":9345630}]}]}
{"op":"mcm","clk":"4226796100","pt":1631451467449,"mc":[{"id":"1.187552454","rc":[{"trd":[[1.07,1196.44]],"batb":[[0,1.07,1872.52]],"ltp":1.07,"tv":73780.98,"id":9028621}],"tv":79630.43}]}
{"op":"mcm","clk":"4226796240","pt":1631451468417,"mc":[{"id":"1.187552454","rc":[{"batb":[[2,2.32,102.49]],"batl":[[0,14.5,45.28],[1,16,15.49],[2,17.5,2]],"ltp":13.5,"tv":5849.45,"id":9345630}]}]}
{"op":"mcm","clk":"4226796284","pt":1631451468732,"mc":[{"id":"1.187552454","rc":[{"trd":[[1.08,1242.78]],"batl":[[0,1.08,350.19]],"ltp":1.08,"tv":73781.65,"id":9028621}],"tv":79631.1}]}
{"op":"mcm","clk":"4226796526","pt":1631451470434,"mc":[{"id":"1.187552454","rc":[{"batb":[[0,14,7.32],[1,11.5,5.71]],"batl":[[0,16,15.49],[1,17.5,2],[2,26,2]],"ltp":13.5,"tv":5849.45,"id":9345630},{"batb":[[0,1.07,19.68],[1,1.06,246.49]],"batl":[[0,1.1,60],[1,1.11,20],[2,1.17,29.67]],"ltp":1.08,"tv":73781.65,"id":9028621}]}]}
{"op":"mcm","clk":"4226796692","pt":1631451471442,"mc":[{"id":"1.187552454","rc":[{"batb":[[1,2.32,102.49],[2,1.01,30]],"batl":[[0,26,2],[1,55,2],[2,110,2]],"ltp":13.5,"tv":5849.45,"id":9345630},{"batb":[[1,1.06,1.55]],"batl":[[0,1.11,20],[1,1.17,29.67],[2,1.19,14.83]],"ltp":1.08,"tv":73781.65,"id":9028621}]}]}
{"op":"mcm","clk":"4226796780","pt":1631451471930,"mc":[{"id":"1.187552454","rc":[{"batb":[[0,2.32,102.49],[1,1.01,30],[2,1.01,0]],"ltp":13.5,"tv":5849.45,"id":9345630},{"batb":[[0,1.06,1.55],[1,1.05,439.75],[2,1.04,328.12]],"ltp":1.08,"tv":73781.65,"id":9028621}]}]}
{"op":"mcm","clk":"4226797004","pt":1631451473514,"mc":[{"id":"1.187552454","rc":[{"batb":[[1,1.05,838.64],[2,1.04,2042.15]],"batl":[[0,1.11,1419.82],[1,1.12,578.24],[2,1.17,29.67]],"ltp":1.08,"tv":73781.65,"id":9028621}]}]}
{"op":"mcm","clk":"4226797202","pt":1631451475057,"mc":[{"id":"1.187552454","rc":[{"batb":[[0,10,2],[1,9.8,2],[2,2.32,102.49]],"ltp":13.5,"tv":5849.45,"id":9345630}]}]}
{"op":"mcm","clk":"4226797518","pt":1631451477342,"mc":[{"id":"1.187552454","rc":[{"batl":[[0,20,20.72],[1,26,2],[2,55,2]],"ltp":13.5,"tv":5849.45,"id":9345630},{"batb":[[0,1.06,24.51],[1,1.05,439.75],[2,1.04,328.12]],"batl":[[0,1.11,1355.97]],"ltp":1.08,"tv":73781.65,"id":9028621}]}]}
{"op":"mcm","clk":"4226797693","pt":1631451478453,"mc":[{"id":"1.187552454","rc":[{"trd":[[18,1.44],[20,28.56]],"batl":[[0,20,6.45]],"ltp":20.0,"tv":5879.45,"id":9345630},{"trd":[[1.06,1140.16]],"batb":[[0,1.05,439.75],[1,1.04,328.12],[2,1.03,3037.32]],"ltp":1.06,"tv":73806.16,"id":9028621}],"tv":79685.61}]}
{"op":"mcm","clk":"4226797870","pt":1631451479530,"mc":[{"id":"1.187552454","rc":[{"trd":[[10,10.54]],"batb":[[0,2.32,102.49],[1,1.01,30],[2,2.32,0]],"batl":[[0,12,7.97],[1,12.5,7.73],[2,13,7.73]],"ltp":10.0,"tv":5889.99,"id":9345630},{"trd":[[1.11,429.88]],"batl":[[0,1.11,1297.03],[2,1.19,14.83]],"ltp":1.11,"tv":73865.1,"id":9028621}],"tv":79755.09}]}
{"op":"mcm","clk":"4226797992","pt":1631451480453,"mc":[{"id":"1.187552454","rc":[{"batl":[[0,12,87.66],[1,12.5,89.08],[2,13,85.08]],"ltp":10.0,"tv":5889.99,"id":9345630},{"batb":[[0,1.09,1844.76],[1,1.08,133.56],[2,1.06,3076.27]],"batl":[[1,1.12,774.07],[2,1.13,190.07]],"ltp":1.11,"tv":73865.1,"id":9028621}]}]}
{"op":"mcm","clk":"4226798148","pt":1631451481456,"mc":[{"id":"1.187552454","rc":[{"batb":[[0,9.6,6.97],[1,2.32,102.49],[2,1.01,30]],"batl":[[1,12.5,87.08],[2,13,102.4]],"ltp":10.0,"tv":5889.99,"id":9345630},{"batb":[[1,1.08,336.69],[2,1.06,15.05]],"batl":[[1,1.12,834.07]],"ltp":1.11,"tv":73865.1,"id":9028621}]}]}
{"op":"mcm","clk":"4226798292","pt":1631451482465,"mc":[{"id":"1.187552454","rc":[{"batb":[[0,9.6,8.97],[1,9.4,2],[2,2.32,102.49]],"batl":[[0,11.5,2],[1,12,87.66],[2,12.5,87.08]],"ltp":10.0,"tv":5889.99,"id":9345630},{"batb":[[1,1.08,338.24],[2,1.06,54.05]],"batl":[[0,1.11,1360.12]],"ltp":1.11,"tv":73865.1,"id":9028621}]}]}
{"op":"mcm","clk":"4226798741","pt":1631451485565,"mc":[{"id":"1.187552454","rc":[{"batl":[[0,11.5,8.31]],"ltp":10.0,"tv":5889.99,"id":9345630},{"batb":[[0,1.09,2052.05]],"ltp":1.11,"tv":73865.1,"id":9028621}]}]}
{"op":"mcm","clk":"4226798893","pt":1631451486382,"mc":[{"id":"1.187552454","rc":[{"batb":[[2,1.06,262.63]],"ltp":1.11,"tv":73865.1,"id":9028621}]}]}
{"op":"mcm","clk":"4226799054","pt":1631451487491,"mc":[{"id":"1.187552454","rc":[{"batl":[[2,12.5,104.77]],"ltp":10.0,"tv":5889.99,"id":9345630}]}]}
{"op":"mcm","clk":"4226799284","pt":1631451489224,"mc":[{"id":"1.187552454","rc":[{"trd":[[11.5,16.21]],"batl":[[0,12,87.86],[1,12.5,104.77],[2,13,85.08]],"ltp":11.5,"tv":5906.2,"id":9345630}],"tv":79771.3}]}
{"op":"mcm","clk":"4226799858","pt":1631451493226,"mc":[{"id":"1.187552454","rc":[{"batb":[[0,1.09,2212.72]],"ltp":1.11,"tv":73865.1,"id":9028621}]}]}
{"op":"mcm","clk":"4226800075","pt":1631451494596,"mc":[{"id":"1.187552454","rc":[{"batb":[[1,2.32,102.49],[2,1.01,30]],"ltp":11.5,"tv":5906.2,"id":9345630},{"batb":[[1,1.08,518.99],[2,1.07,206.57]],"ltp":1.11,"tv":73865.1,"id":9028621}]}]}
{"op":"mcm","clk":"4226800291","pt":1631451496296,"mc":[{"id":"1.187552454","rc":[{"batb":[[0,9.8,11.39],[1,9.6,8.97],[2,2.32,102.49]],"ltp":11.5,"tv":5906.2,"id":9345630},{"trd":[[1.11,430.68]],"batl":[[0,1.11,1359.72]],"ltp":1.11,"tv":73865.89,"id":9028621}],"tv":79772.1}]}
{"op":"mcm","clk":"4226800385","pt":1631451497080,"mc":[{"id":"1.187552454","rc":[{"batl":[[0,11.5,3.2],[1,12,87.66],[2,12.5,104.77]],"ltp":11.5,"tv":5906.2,"id":9345630},{"trd":[[1.11,430.84]],"batl":[[0,1.11,1359.64]],"ltp":1.11,"tv":73866.05,"id":9028621}],"tv":79772.26}]}
{"op":"mcm","clk":"4226800445","pt":1631451497602,"mc":[{"id":"1.187552454","rc":[{"batb":[[2,9.4,2]],"ltp":11.5,"tv":5906.2,"id":9345630}]}]}
{"op":"mcm","clk":"4226800838","pt":1631451500522,"mc":[{"id":"1.187552454","rc":[{"trd":[[10,103.75]],"batb":[[0,9.6,8.97],[1,9.4,2],[2,2.32,102.49]],"batl":[[0,12.5,19.69],[1,18,2],[2,20,6.45]],"ltp":10.0,"tv":5999.41,"id":9345630},{"trd":[[1.11,1270.54]],"batb":[[0,1.09,160.67],[1,1.08,403.43]],"batl":[[0,1.12,60],[1,1.19,14.83],[2,1.21,14.83]],"ltp":1.11,"tv":74705.75,"id":9028621}],"tv":80705.16}]}
{"op":"mcm","clk":"4226800990","pt":1631451501523,"mc":[{"id":"1.187552454","rc":[{"batb":[[0,10.5,8.29],[1,9.6,2],[2,9.4,2]],"batl":[[0,18,2],[1,20,6.45],[2,26,2]],"ltp":10.0,"tv":5999.41,"id":9345630},{"batb":[[1,1.08,182.3]],"batl":[[0,1.1,134]],"ltp":1.11,"tv":74705.75,"id":9028621}]}]}
{"op":"mcm","clk":"4226801277","pt":1631451503437,"mc":[{"id":"1.187552454","rc":[{"batl":[[1,1.12,16],[2,1.19,14.83]],"ltp":1.11,"tv":74705.75,"id":9028621}]}]}
{"op":"mcm","clk":"4226801384","pt":1631451504343,"mc":[{"id":"1.187552454","rc":[{"trd":[[10.5,17.09],[11,26.35]],"batb":[[0,10.5,7.23]],"ltp":10.5,"tv":6014.93,"id":9345630},{"trd":[[1.1,2300.69]],"batl":[[0,1.12,16],[1,1.19,14.83],[2,1.21,14.83]],"ltp":1.1,"tv":74839.75,"id":9028621}],"tv":80854.69}]}
{"op":"mcm","clk":"4226801463","pt":1631451505022,"mc":[{"id":"1.187552454","rc":[{"batl":[[0,20,6.45],[1,26,2],[2,55,2]],"ltp":10.5,"tv":6014.93,"id":9345630},{"batb":[[0,1.08,1.55],[1,1.06,39],[2,1.05,708.2]],"ltp":1.1,"tv":74839.75,"id":9028621}]}]}
{"op":"mcm","clk":"4226801773","pt":1631451507434,"mc":[{"id":"1.187552454","rc":[{"trd":[[1.1,2340.79]],"batb":[[0,1.1,124.55],[1,1.09,1228.36],[2,1.08,705.65]],"batl":[[0,1.11,1794.3],[1,1.12,16],[2,1.19,14.83]],"ltp":1.1,"tv":74879.85,"id":9028621}],"tv":80894.79}]}
{"op":"mcm","clk":"4226801867","pt":1631451508226,"mc":[{"id":"1.187552454","rc":[{"batl":[[0,18,4],[1,20,8.45],[2,26,2]],"ltp":10.5,"tv":6014.93,"id":9345630}]}]}
{"op":"mcm","clk":"4226801944","pt":1631451508823,"mc":[{"id":"1.187552454","rc":[{"batb":[[0,10.5,14.36]],"batl":[[0,14,15.32],[1,18,4],[2,20,8.45]],"ltp":10.5,"tv":6014.93,"id":9345630},{"batb":[[0,1.09,1236.11],[1,1.08,705.65],[2,1.06,259.08]],"batl":[[0,1.11,1874.3]],"ltp":1.1,"tv":74879.85,"id":9028621}]}]}
{"op":"mcm","clk":"4226802162","pt":1631451510503,"mc":[{"id":"1.187552454","rc":[{"batb":[[2,1.07,19.68]],"ltp":1.1,"tv":74879.85,"id":9028621}]}]}
{"op":"mcm","clk":"4226802229","pt":1631451510929,"mc":[{"id":"1.187552454","rc":[{"batb":[[0,10.5,7.23],[2,2.32,102.49]],"batl":[[0,18,2],[1,20,8.45],[2,26,2]],"ltp":10.5,"tv":6014.93,"id":9345630},{"batb":[[0,1.07,19.68],[1,1.06,39],[2,1.05,752.2]],"batl":[[0,1.12,16.9],[1,1.19,14.83],[2,1.21,14.83]],"ltp":1.1,"tv":74879.85,"id":9028621}]}]}
{"op":"mcm","clk":"4226802598","pt":1631451513545,"mc":[{"id":"1.187552454","rc":[{"batb":[[0,1.07,1963.57]],"batl":[[1,1.13,555.46],[2,1.14,1244.07]],"ltp":1.1,"tv":74879.85,"id":9028621}]}]}
{"op":"mcm","clk":"4226802696","pt":1631451514244,"mc":[{"id":"1.187552454","rc":[{"batl":[[0,18,4]],"ltp":10.5,"tv":6014.93,"id":9345630},{"batb":[[1,1.06,246.08]],"ltp":1.1,"tv":74879.85,"id":9028621}]}]}
{"op":"mcm","clk":"4226802839","pt":1631451515419,"mc":[{"id":"1.187552454","rc":[{"batb":[[0,1.08,180.75],[1,1.07,1963.57],[2,1.06,246.08]],"ltp":1.1,"tv":74879.85,"id":9028621}]}]}
{"op":"mcm","clk":"4226802913","pt":1631451515950,"mc":[{"id":"1.187552454","rc":[{"trd":[[10.5,31.54]],"batb":[[0,9.6,2],[1,2.32,102.49],[2,1.01,30]],"ltp":10.5,"tv":6029.39,"id":9345630},{"batb":[[1,1.07,2170.14]],"ltp":1.1,"tv":74879.85,"id":9028621}],"tv":80909.24}]}
{"op":"mcm","clk":"4226803243","pt":1631451518554,"mc":[{"id":"1.187552454","rc":[{"batb":[[0,1.08,182.75]],"ltp":1.1,"tv":74879.85,"id":9028621}]}]}
{"op":"mcm","clk":"4226803366","pt":1631451519453,"mc":[{"id":"1.187552454","rc":[{"batb":[[1,9.4,3],[2,2.32,102.49]],"ltp":10.5,"tv":6029.39,"id":9345630},{"trd":[[1.11,1272.33]],"batb":[[1,1.07,206.57]],"batl":[[0,1.12,16]],"ltp":1.11,"tv":74881.64,"id":9028621}],"tv":80911.04}]}
{"op":"mcm","clk":"4226803484","pt":1631451520462,"mc":[{"id":"1.187552454","rc":[{"batb":[[0,2.32,102.49],[1,1.01,30],[2,2.32,0]],"batl":[[0,9.6,20.78],[1,18,4],[2,20,6.45]],"ltp":10.5,"tv":6029.39,"id":9345630},{"batb":[[0,1.08,2]],"batl":[[0,1.13,555.46],[1,1.14,1244.07],[2,1.23,29.67]],"ltp":1.11,"tv":74881.64,"id":9028621}]}]}
{"op":"mcm","clk":"4226803602","pt":1631451521521,"mc":[{"id":"1.187552454","rc":[{"batl":[[0,9.6,265.57]],"ltp":10.5,"tv":6029.39,"id":9345630}]}]}
{"op":"mcm","clk":"4226803715","pt":1631451522430,"mc":[{"id":"1.187552454","rc":[{"batl":[[0,9.6,69.74],[1,12.5,3.29],[2,18,4]],"ltp":10.5,"tv":6029.39,"id":9345630},{"batb":[[0,1.11,1939.51],[1,1.09,113.61],[2,1.08,2364]],"batl":[[2,1.17,13.64]],"ltp":1.11,"tv":74881.64,"id":9028621}]}]}
{"op":"mcm","clk":"4226803855","pt":1631451523545,"mc":[{"id":"1.187552454","rc":[{"trd":[[8.6,75.62]],"batb":[[0,8,8.57],[1,2.32,102.49],[2,1.01,30]],"batl":[[0,9.4,2],[1,9.6,71.74],[2,10.5,19.46]],"ltp":8.6,"tv":6033.39,"id":9345630},{"trd":[[1.12,950.45],[1.13,5158.29]],"batb":[[0,1.12,21.1],[1,1.11,1957.51],[2,1.1,189.73]],"batl":[[0,1.13,507.02],[2,1.15,60]],"ltp":1.12,"tv":74949.88,"id":9028621}],"tv":80983.27}]}
{"op":"mcm","clk":"4226803944","pt":1631451524130,"mc":[{"id":"1.187552454","rc":[{"batb":[[0,2.32,102.49],[1,1.01,30],[2,1.01,0]],"batl":[[1,9.6,78.11],[2,12.5,3.29]],"ltp":8.6,"tv":6033.39,"id":9345630},{"batb":[[2,1.09,152.61]],"batl":[[2,1.17,13.64]],"ltp":1.12,"tv":74949.88,"id":9028621}]}]}
{"op":"mcm","clk":"4226804251","pt":1631451526564,"mc":[{"id":"1.187552454","rc":[{"batl":[[2,11,42.17]],"ltp":8.6,"tv":6033.39,"id":9345630},{"batb":[[0,1.12,63.8]],"batl":[[0,1.13,649.71]],"ltp":1.12,"tv":74949.88,"id":9028621}]}]}
{"op":"mcm","clk":"4226804370","pt":1631451527467,"mc":[{"id":"1.187552454","rc":[{"batb":[[0,7.8,8.82],[1,2.32,102.49],[2,1.01,30]],"batl":[[2,12.5,3.29]],"ltp":8.6,"tv":6033.39,"id":9345630},{"batb":[[2,1.1,189.73]],"batl":[[0,1.13,507.02],[1,1.14,1304.07]],"ltp":1.12,"tv":74949.88,"id":9028621}]}]}
{"op":"mcm","clk":"4226804425","pt":1631451527960,"mc":[{"id":"1.187552454","rc":[{"batl":[[1,9.6,69.57]],"ltp":8.6,"tv":6033.39,"id":9345630}]}]}
{"op":"mcm","clk":"4226804747","pt":1631451530563,"mc":[{"id":"1.187552454","rc":[{"batl":[[2,10.5,19.46]],"ltp":8.6,"tv":6033.39,"id":9345630},{"trd":[[1.13,5162.29]],"batl":[[0,1.13,505.02]],"ltp":1.13,"tv":74953.88,"id":9028621}],"tv":80987.27}]}
{"op":"mcm","clk":"4226804926","pt":1631451531880,"mc":[{"id":"1.187552454","rc":[{"trd":[[1.12,953.75]],"batb":[[0,1.12,62.15]],"ltp":1.12,"tv":74957.18,"id":9028621}],"tv":80990.57}]}
{"op":"mcm","clk":"4226805081","pt":1631451533162,"mc":[{"id":"1.187552454","rc":[{"batl":[[0,1.13,550.25]],"ltp":1.12,"tv":74957.18,"id":9028621}]}]}
{"op":"mcm","clk":"4226805173","pt":1631451533843,"mc":[{"id":"1.187552454","rc":[{"batb":[[0,8,33.78],[1,7.8,8.82],[2,2.32,102.49]],"ltp":8.6,"tv":6033.39,"id":9345630}]}]}
{"op":"mcm","clk":"4226805374","pt":1631451535284,"mc":[{"id":"1.187552454","rc":[{"batb":[[0,2.32,102.49],[1,1.01,30],[2,2.32,0]],"batl":[[1,9.6,67.57]],"ltp":8.6,"tv":6033.39,"id":9345630},{"trd":[[1.12,955.55]],"batb":[[0,1.12,61.25],[1,1.11,1939.51]],"ltp":1.12,"tv":74958.98,"id":9028621}],"tv":80992.37}]}
{"op":"mcm","clk":"4226805526","pt":1631451536555,"mc":[{"id":"1.187552454","rc":[{"trd":[[1.13,5166.19]],"batb":[[0,1.12,501]],"batl":[[0,1.13,548.3]],"ltp":1.13,"tv":74962.88,"id":9028621}],"tv":80996.27}]}
{"op":"mcm","clk":"4226805776","pt":1631451538455,"mc":[{"id":"1.187552454","rc":[{"batb":[[0,7.4,33.78],[1,4.6,535.86],[2,2.32,102.49]],"ltp":8.6,"tv":6033.39,"id":9345630},{"trd":[[1.13,5166.86]],"batb":[[1,1.11,1958.51]],"batl":[[0,1.13,547.97]],"ltp":1.13,"tv":74963.54,"id":9028621}],"tv":80996.93}]}
{"op":"mcm","clk":"4226805802","pt":1631451538674,"mc":[{"id":"1.187552454","rc":[{"batb":[[1,2.32,102.49],[2,1.01,30]],"ltp":8.6,"tv":6033.39,"id":9345630}]}]}
{"op":"mcm","clk":"4226805928","pt":1631451539669,"mc":[{"id":"1.187552454","rc":[{"trd":[[1.12,955.65]],"batb":[[0,1.12,500.95]],"ltp":1.12,"tv":74963.64,"id":9028621}],"tv":80997.04}]}
{"op":"mcm","clk":"4226806166","pt":1631451541553,"mc":[{"id":"1.187552454","rc":[{"batb":[[0,7.8,8.82],[1,7.4,33.78],[2,2.32,102.49]],"ltp":8.6,"tv":6033.39,"id":9345630}]}]}
{"op":"mcm","clk":"4226806260","pt":1631451542091,"mc":[{"id":"1.187552454","rc":[{"batb":[[1,2.32,102.49],[2,1.01,30]],"ltp":8.6,"tv":6033.39,"id":9345630}]}]}
{"op":"mcm","clk":"4226806594","pt":1631451545055,"mc":[{"id":"1.187552454","rc":[{"batb":[[0,8,33.78],[1,7.8,8.82],[2,2.32,102.49]],"ltp":8.6,"tv":6033.39,"id":9345630}]}]}
{"op":"mcm","clk":"4226806718","pt":1631451546070,"mc":[{"id":"1.187552454","rc":[{"trd":[[1.12,958.83]],"batb":[[0,1.12,499.36]],"ltp":1.12,"tv":74966.82,"id":9028621}],"tv":81000.21}]}
{"op":"mcm","clk":"4226806932","pt":1631451548068,"mc":[{"id":"1.187552454","rc":[{"trd":[[1.12,959.23]],"batb":[[0,1.12,499.16]],"ltp":1.12,"tv":74967.22,"id":9028621}],"tv":81000.61}]}
{"op":"mcm","clk":"4226807052","pt":1631451549080,"mc":[{"id":"1.187552454","rc":[{"trd":[[1.12,961.02]],"batb":[[0,1.12,498.26]],"ltp":1.12,"tv":74969.02,"id":9028621}],"tv":81002.41}]}
{"op":"mcm","clk":"4226807215","pt":1631451550595,"mc":[{"id":"1.187552454","rc":[{"batb":[[1,2.32,102.49],[2,1.01,30]],"ltp":8.6,"tv":6033.39,"id":9345630},{"batb":[[1,1.11,1939.51]],"ltp":1.12,"tv":74969.02,"id":9028621}]}]}
{"op":"mcm","clk":"4226807282","pt":1631451551283,"mc":[{"id":"1.187552454","rc":[{"batb":[[0,2.32,102.49],[1,1.01,30],[2,1.01,0]],"ltp":8.6,"tv":6033.39,"id":9345630},{"batb":[[0,1.12,455.56]],"ltp":1.12,"tv":74969.02,"id":9028621}]}]}
{"op":"mcm","clk":"4226807531","pt":1631451553550,"mc":[{"id":"1.187552454","rc":[{"batb":[[0,8.2,8.33],[1,2.32,102.49],[2,1.01,30]],"ltp":8.6,"tv":6033.39,"id":9345630},{"trd":[[1.13,5252.26]],"batl":[[0,1.13,505.27]],"ltp":1.13,"tv":75054.42,"id":9028621}],"tv":81087.81}]}
{"op":"mcm","clk":"4226807621","pt":1631451554353,"mc":[{"id":"1.187552454","rc":[{"batb":[[1,4.7,524.41],[2,2.32,102.49]],"ltp":8.6,"tv":6033.39,"id":9345630},{"batb":[[1,1.11,1661.15]],"ltp":1.13,"tv":75054.42,"id":9028621}]}]}
{"op":"mcm","clk":"4226807745","pt":1631451555578,"mc":[{"id":"1.187552454","rc":[{"batb":[[0,4.7,524.41],[1,2.32,102.49],[2,1.01,30]],"ltp":8.6,"tv":6033.39,"id":9345630}]}]}
{"op":"mcm","clk":"4226807853","pt":1631451556581,"mc":[{"id":"1.187552454","rc":[{"trd":[[9.4,17.78]],"batl":[[0,9.6,67.6],[1,10.5,19.46],[2,12.5,3.29]],"ltp":9.4,"tv":6037.33,"id":9345630},{"trd":[[1.12,978.49]],"batb":[[0,1.12,446.83]],"ltp":1.12,"tv":75071.88,"id":9028621}],"tv":81109.21}]}
{"op":"mcm","clk":"4226807965","pt":1631451557478,"mc":[{"id":"1.187552454","rc":[{"batb":[[0,8.4,33.78],[1,4.7,524.41],[2,2.32,102.49]],"ltp":9.4,"tv":6037.33,"id":9345630},{"batb":[[0,1.12,744.51]],"ltp":1.12,"tv":75071.88,"id":9028621}]}]}
{"op":"mcm","clk":"4226808014","pt":1631451557799,"mc":[{"id":"1.187552454","rc":[{"batb":[[0,2.32,102.49],[1,1.01,30],[2,2.32,0]],"ltp":9.4,"tv":6037.33,"id":9345630}]}]}
{"op":"mcm","clk":"4226808190","pt":1631451559114,"mc":[{"id":"1.187552454","rc":[{"batb":[[0,7.8,8.82],[1,2.32,102.49],[2,1.01,30]],"ltp":9.4,"tv":6037.33,"id":9345630}]}]}
{"op":"mcm","clk":"4226808286","pt":1631451559709,"mc":[{"id":"1.187552454","rc":[{"trd":[[1.12,1264.34]],"batb":[[0,1.12,601.59]],"ltp":1.12,"tv":75357.74,"id":9028621}],"tv":81395.07}]}
{"op":"mcm","clk":"4226808453","pt":1631451561095,"mc":[{"id":"1.187552454","rc":[{"batb":[[1,5.5,447.85],[2,2.32,102.49]],"ltp":9.4,"tv":6037.33,"id":9345630},{"trd":[[1.12,1266.14],[1.13,5263.38]],"batb":[[0,1.12,600.69]],"batl":[[0,1.13,499.71]],"ltp":1.13,"tv":75370.65,"id":9028621}],"tv":81407.98}]}
{"op":"mcm","clk":"4226808663","pt":1631451562585,"mc":[{"id":"1.187552454","rc":[{"trd":[[8.6,95.62]],"ltp":8.6,"tv":6057.33,"id":9345630},{"trd":[[1.13,5419.77]],"batl":[[0,1.13,345.41]],"ltp":1.13,"tv":75527.04,"id":9028621}],"tv":81584.37}]}
{"op":"mcm","clk":"4226808751","pt":1631451563066,"mc":[{"id":"1.187552454","rc":[{"batb":[[0,1.12,619.69],[1,1.11,1591.09]],"ltp":1.13,"tv":75527.04,"id":9028621}]}]}
{"op":"mcm","clk":"4226808871","pt":1631451564184,"mc":[{"id":"1.187552454","rc":[{"batb":[[0,8,33.78],[1,7.8,8.82]],"ltp":8.6,"tv":6057.33,"id":9345630}]}]}
{"op":"mcm","clk":"4226808967","pt":1631451564970,"mc":[{"id":"1.187552454","rc":[{"trd":[[1.13,5430.89]],"batl":[[0,1.13,339.85]],"ltp":1.13,"tv":75538.16,"id":9028621}],"tv":81595.49}]}
{"op":"mcm","clk":"4226809143","pt":1631451566301,"mc":[{"id":"1.187552454","rc":[{"batb":[[0,2.32,102.49],[1,1.01,30],[2,2.32,0]],"ltp":8.6,"tv":6057.33,"id":9345630},{"batb":[[0,1.12,689.12]],"batl":[[0,1.13,456.5]],"ltp":1.13,"tv":75538.16,"id":9028621}]}]}
{"op":"mcm","clk":"4226809295","pt":1631451567579,"mc":[{"id":"1.187552454","rc":[{"trd":[[1.13,5447.97]],"batl":[[0,1.13,447.96]],"ltp":1.13,"tv":75555.24,"id":9028621}],"tv":81612.57}]}
{"op":"mcm","clk":"4226809542","pt":1631451569478,"mc":[{"id":"1.187552454","rc":[{"batb":[[0,8.2,8.33],[1,7.4,33.78],[2,3.9,631.75]],"ltp":8.6,"tv":6057.33,"id":9345630}]}]}
{"op":"mcm","clk":"4226809569","pt":1631451569691,"mc":[{"id":"1.187552454","rc":[{"batb":[[1,3.9,631.75],[2,2.32,102.49]],"ltp":8.6,"tv":6057.33,"id":9345630}]}]}
{"op":"mcm","clk":"4226809763","pt":1631451571495,"mc":[{"id":"1.187552454","rc":[{"batb":[[0,3.9,631.75],[1,2.32,102.49],[2,1.01,30]],"ltp":8.6,"tv":6057.33,"id":9345630},{"trd":[[1.12,1267.93]],"batb":[[0,1.12,688.22]],"ltp":1.12,"tv":75557.04,"id":9028621}],"tv":81614.37}]}
{"op":"mcm","clk":"4226809866","pt":1631451572385,"mc":[{"id":"1.187552454","rc":[{"trd":[[1.13,5661.49]],"batb":[[1,1.11,1538.12]],"batl":[[0,1.13,341.2]],"ltp":1.13,"tv":75770.55,"id":9028621}],"tv":81827.88}]}
{"op":"mcm","clk":"4226809933","pt":1631451572971,"mc":[{"id":"1.187552454","rc":[{"batb":[[0,2.32,102.49],[1,1.01,30],[2,1.01,0]],"ltp":8.6,"tv":6057.33,"id":9345630}]}]}
{"op":"mcm","clk":"4226810109","pt":1631451574503,"mc":[{"id":"1.187552454","rc":[{"batb":[[0,7.8,8.82],[1,2.32,102.49],[2,1.01,30]],"ltp":8.6,"tv":6057.33,"id":9345630},{"trd":[[1.12,1501.57]],"batb":[[0,1.12,571.4],[1,1.11,1516.12]],"ltp":1.12,"tv":76004.19,"id":9028621}],"tv":82061.52}]}
{"op":"mcm","clk":"4226810210","pt":1631451575402,"mc":[{"id":"1.187552454","rc":[{"batb":[[0,1.12,623.89]],"batl":[[0,1.13,410.04]],"ltp":1.12,"tv":76004.19,"id":9028621}]}]}
{"op":"mcm","clk":"4226810321","pt":1631451576313,"mc":[{"id":"1.187552454","rc":[{"trd":[[8.6,100.7]],"ltp":8.6,"tv":6062.4,"id":9345630},{"trd":[[1.13,5700.09]],"batl":[[0,1.13,371.44]],"ltp":1.13,"tv":76042.79,"id":9028621}],"tv":82105.19}]}
{"op":"mcm","clk":"4226810679","pt":1631451579382,"mc":[{"id":"1.187552454","rc":[{"batb":[[0,8,33.78],[1,7.8,8.82],[2,2.32,102.49]],"ltp":8.6,"tv":6062.4,"id":9345630}]}]}
{"op":"mcm","clk":"4226810931","pt":1631451581500,"mc":[{"id":"1.187552454","rc":[{"batb":[[0,2.32,102.49],[1,1.01,30],[2,2.32,0]],"ltp":8.6,"tv":6062.4,"id":9345630}]}]}
{"op":"mcm","clk":"4226811000","pt":1631451582148,"mc":[{"id":"1.187552454","rc":[{"trd":[[1.12,1503.36]],"batb":[[0,1.12,622.99]],"ltp":1.12,"tv":76044.58,"id":9028621}],"tv":82106.99}]}
{"op":"mcm","clk":"4226811318","pt":1631451584506,"mc":[{"id":"1.187552454","rc":[{"batb":[[0,8.2,8.33],[1,2.32,102.49],[2,1.01,30]],"ltp":8.6,"tv":6062.4,"id":9345630}]}]}
{"op":"mcm","clk":"4226811575","pt":1631451586613,"mc":[{"id":"1.187552454","rc":[{"batb":[[0,2.32,102.49],[1,1.01,30],[2,1.01,0]],"ltp":8.6,"tv":6062.4,"id":9345630}]}]}
{"op":"mcm","clk":"4226811774","pt":1631451588307,"mc":[{"id":"1.187552454","rc":[{"batb":[[0,1.12,725.42]],"ltp":1.12,"tv":76044.58,"id":9028621}]}]}
{"op":"mcm","clk":"4226811944","pt":1631451589828,"mc":[{"id":"1.187552454","rc":[{"batb":[[0,7.8,8.82],[1,2.32,102.49],[2,1.01,30]],"ltp":8.6,"tv":6062.4,"id":9345630}]}]}
{"op":"mcm","clk":"4226812142","pt":1631451591437,"mc":[{"id":"1.187552454","rc":[{"batb":[[1,7.4,33.78],[2,2.32,102.49]],"ltp":8.6,"tv":6062.4,"id":9345630}]}]}
{"op":"mcm","clk":"4226812193","pt":1631451591731,"mc":[{"id":"1.187552454","rc":[{"batb":[[1,2.32,102.49],[2,1.01,30]],"ltp":8.6,"tv":6062.4,"id":9345630}]}]}
{"op":"mcm","clk":"4226812481","pt":1631451594119,"mc":[{"id":"1.187552454","rc":[{"trd":[[1.13,5706.48]],"batl":[[0,1.13,368.24]],"ltp":1.13,"tv":76050.98,"id":9028621}],"tv":82113.38}]}
{"op":"mcm","clk":"4226812561","pt":1631451594853,"mc":[{"id":"1.187552454","rc":[{"batb":[[0,8,33.78],[1,7.8,8.82],[2,2.32,102.49]],"ltp":8.6,"tv":6062.4,"id":9345630}]}]}
{"op":"mcm","clk":"4226812842","pt":1631451597036,"mc":[{"id":"1.187552454","rc":[{"batb":[[0,2.32,102.49],[1,1.01,30],[2,2.32,0]],"ltp":8.6,"tv":6062.4,"id":9345630}]}]}
{"op":"mcm","clk":"4226813084","pt":1631451598938,"mc":[{"id":"1.187552454","rc":[{"trd":[[1.12,1505.16]],"batb":[[0,1.12,724.53]],"ltp":1.12,"tv":76052.78,"id":9028621}],"tv":82115.18}]}
{"op":"mcm","clk":"4226813269","pt":1631451600492,"mc":[{"id":"1.187552454","rc":[{"batb":[[0,8.2,8.33],[1,2.32,102.49],[2,1.01,30]],"ltp":8.6,"tv":6062.4,"id":9345630}]}]}
{"op":"mcm","clk":"4226813555","pt":1631451602063,"mc":[{"id":"1.187552454","rc":[{"batb":[[0,2.32,102.49],[1,1.01,30],[2,1.01,0]],"ltp":8.6,"tv":6062.4,"id":9345630},{"trd":[[1.12,1505.63]],"batb":[[0,1.12,724.29]],"ltp":1.12,"tv":76053.25,"id":9028621}],"tv":82115.65}]}
{"op":"mcm","clk":"4226814257","pt":1631451605125,"mc":[{"id":"1.187552454","rc":[{"batb":[[0,7.8,8.82],[1,2.32,102.49],[2,1.01,30]],"ltp":8.6,"tv":6062.4,"id":9345630}]}]}
{"op":"mcm","clk":"4226814780","pt":1631451607531,"mc":[{"id":"1.187552454","rc":[{"trd":[[1.13,5728.56]],"batl":[[0,1.13,357.2]],"ltp":1.13,"tv":76075.33,"id":9028621}],"tv":82137.73}]}
{"op":"mcm","clk":"4226815029","pt":1631451608835,"mc":[{"id":"1.187552454","rc":[{"trd":[[1.12,1507.42]],"batb":[[0,1.12,723.39]],"batl":[[2,1.22,17.08]],"ltp":1.12,"tv":76077.12,"id":9028621}],"tv":82139.53}]}
{"op":"mcm","clk":"4226815408","pt":1631451610643,"mc":[{"id":"1.187552454","rc":[{"batb":[[0,8,33.78],[1,7.8,8.82],[2,2.32,102.49]],"ltp":8.6,"tv":6062.4,"id":9345630}]}]}
{"op":"mcm","clk":"4226815729","pt":1631451612206,"mc":[{"id":"1.187552454","rc":[{"batb":[[0,2.32,102.49],[1,1.01,30],[2,2.32,0]],"ltp":8.6,"tv":6062.4,"id":9345630}]}]}
{"op":"mcm","clk":"4226816174","pt":1631451615427,"mc":[{"id":"1.187552454","rc":[{"batb":[[0,8.2,8.33],[1,7.4,33.78],[2,4.1,598.45]],"ltp":8.6,"tv":6062.4,"id":9345630}]}]}
{"op":"mcm","clk":"4226816323","pt":1631451616440,"mc":[{"id":"1.187552454","rc":[{"batb":[[1,4.1,598.45],[2,2.32,102.49]],"ltp":8.6,"tv":6062.4,"id":9345630},{"batl":[[1,1.14,1304.76],[2,1.22,17.77]],"ltp":1.12,"tv":76077.12,"id":9028621}]}]}
{"op":"mcm","clk":"4226816474","pt":1631451617531,"mc":[{"id":"1.187552454","rc":[{"batb":[[0,2.32,102.49],[1,1.01,30],[2,2.32,0]],"batl":[[0,10.5,19.49],[1,13.5,2],[2,18,2]],"ltp":8.6,"tv":6062.4,"id":9345630},{"batb":[[0,1.12,303.79],[1,1.1,189.73],[2,1.08,146.56]],"batl":[[0,1.14,60.69],[1,1.16,1.38]],"ltp":1.12,"tv":76077.12,"id":9028621}]}]}
{"op":"mcm","clk":"4226816597","pt":1631451618577,"mc":[{"id":"1.187552454","rc":[{"batl":[[0,13.5,2],[1,18,2],[2,20,6.45]],"ltp":8.6,"tv":6062.4,"id":9345630},{"trd":[[1.12,1509.22]],"batb":[[0,1.12,283.9],[1,1.08,146.56],[2,1.06,1059.83]],"batl":[[0,1.15,1.38],[1,1.17,1.38]],"ltp":1.12,"tv":76078.92,"id":9028621}],"tv":82141.32}]}
{"op":"mcm","clk":"4226816751","pt":1631451619366,"mc":[{"id":"1.187552454","rc":[{"batb":[[0,1.12,102.43]],"batl":[[2,1.19,1.38]],"ltp":1.12,"tv":76078.92,"id":9028621}]}]}
{"op":"mcm","clk":"4226816948","pt":1631451620542,"mc":[{"id":"1.187552454","rc":[{"batb":[[0,7.8,8.82],[1,2.32,102.49],[2,1.01,30]],"batl":[[0,18,2],[1,20,6.45],[2,1000,0.32]],"ltp":8.6,"tv":6062.4,"id":9345630},{"batb":[[0,1.09,1950.09],[1,1.06,1059.83],[2,1.05,27.55]],"batl":[[1,1.17,337.45],[2,1.18,963.99]],"ltp":1.12,"tv":76078.92,"id":9028621}]}]}
{"op":"mcm","clk":"4226817060","pt":1631451621345,"mc":[{"id":"1.187552454","rc":[{"batb":[[0,2.32,102.49],[1,1.01,30],[2,1.01,0]],"ltp":8.6,"tv":6062.4,"id":9345630},{"batl":[[1,1.17,1.38],[2,1.19,1.38]],"ltp":1.12,"tv":76078.92,"id":9028621}]}]}
{"op":"mcm","clk":"4226817197","pt":1631451622161,"mc":[{"id":"1.187552454","rc":[{"batb":[[0,5.5,2],[1,5.4,2],[2,2.32,102.49]],"ltp":8.6,"tv":6062.4,"id":9345630},{"batb":[[0,1.13,181.46],[1,1.09,1950.09],[2,1.06,1059.83]],"ltp":1.12,"tv":76078.92,"id":9028621}]}]}
{"op":"mcm","clk":"4226817387","pt":1631451623562,"mc":[{"id":"1.187552454","rc":[{"batl":[[0,13.5,4],[1,18,4],[2,20,6.45]],"ltp":8.6,"tv":6062.4,"id":9345630},{"trd":[[1.13,6091.49]],"batb":[[0,1.09,2086.66],[1,1.08,165.31],[2,1.07,17]],"batl":[[1,1.17,13.38]],"ltp":1.13,"tv":76441.85,"id":9028621}],"tv":82504.25}]}
{"op":"mcm","clk":"4226817521","pt":1631451624579,"mc":[{"id":"1.187552454","rc":[{"batb":[[0,9.2,61.84],[1,5.5,2],[2,5.4,2]],"ltp":8.6,"tv":6062.4,"id":9345630},{"trd":[[1.09,2634.19]],"batb":[[0,1.1,122.91],[1,1.09,2078.12],[2,1.08,165.31]],"batl":[[0,1.11,9427.14],[1,1.12,705.05],[2,1.14,14.69]],"ltp":1.09,"tv":76458.93,"id":9028621}],"tv":82521.33}]}
{"op":"mcm","clk":"4226817673","pt":1631451625593,"mc":[{"id":"1.187552454","rc":[{"batb":[[0,9.2,69.15],[1,8.8,3],[2,8.6,2]],"batl":[[0,12,2],[1,12.5,17.69],[2,13.5,4]],"ltp":8.6,"tv":6062.4,"id":9345630},{"batb":[[0,1.09,1941.55],[1,1.08,165.31],[2,1.07,17]],"batl":[[0,1.11,1306.07]],"ltp":1.09,"tv":76458.93,"id":9028621}]}]}
{"op":"mcm","clk":"4226817842","pt":1631451626495,"mc":[{"id":"1.187552454","rc":[{"batb":[[0,1.09,2032.19],[1,1.08,377.44]],"ltp":1.09,"tv":76458.93,"id":9028621}]}]}
{"op":"mcm","clk":"4226817982","pt":1631451627575,"mc":[{"id":"1.187552454","rc":[{"batb":[[0,9.4,3],[1,9.2,71.15],[2,8.8,3]],"ltp":8.6,"tv":6062.4,"id":9345630},{"batl":[[2,1.14,15.37]],"ltp":1.09,"tv":76458.93,"id":9028621}]}]}
{"op":"mcm","clk":"4226818256","pt":1631451629432,"mc":[{"id":"1.187552454","rc":[{"batb":[[0,9.4,22.74],[1,9.2,63.84]],"batl":[[0,11.5,3],[1,12,12],[2,12.5,17.69]],"ltp":8.6,"tv":6062.4,"id":9345630},{"batl":[[0,1.11,1394.88],[1,1.12,765.05]],"ltp":1.09,"tv":76458.93,"id":9028621}]}]}
{"op":"mcm","clk":"4226818390","pt":1631451630504,"mc":[{"id":"1.187552454","rc":[{"batb":[[0,9.4,3]],"ltp":8.6,"tv":6062.4,"id":9345630},{"batb":[[2,1.07,198.07]],"batl":[[0,1.11,1395.57]],"ltp":1.09,"tv":76458.93,"id":9028621}]}]}
{"op":"mcm","clk":"4226818495","pt":1631451631216,"mc":[{"id":"1.187552454","rc":[{"batb":[[0,1.1,171.69],[1,1.09,2032.19],[2,1.08,377.44]],"batl":[[1,1.12,765.74]],"ltp":1.09,"tv":76458.93,"id":9028621}]}]}
{"op":"mcm","clk":"4226818814","pt":1631451633435,"mc":[{"id":"1.187552454","rc":[{"batb":[[0,9.6,6.97],[1,9.4,3],[2,9.2,63.84]],"ltp":8.6,"tv":6062.4,"id":9345630}]}]}
{"op":"mcm","clk":"4226818854","pt":1631451633711,"mc":[{"id":"1.187552454","rc":[{"trd":[[11,31.45]],"ltp":11.0,"tv":6067.5,"id":9345630},{"trd":[[1.1,2391.79]],"batb":[[0,1.1,120.68]],"ltp":1.1,"tv":76509.93,"id":9028621}],"tv":82577.43}]}
{"op":"mcm","clk":"4226819204","pt":1631451636444,"mc":[{"id":"1.187552454","rc":[{"batb":[[0,9.8,19.74],[1,9.6,6.97],[2,9.4,3]],"ltp":11.0,"tv":6067.5,"id":9345630},{"batl":[[0,1.11,1317.61]],"ltp":1.1,"tv":76509.93,"id":9028621}]}]}
{"op":"mcm","clk":"4226819287","pt":1631451637038,"mc":[{"id":"1.187552454","rc":[{"batb":[[0,9.6,6.97],[1,8.2,2],[2,7,2]],"batl":[[0,12.5,17.69],[1,15.5,2],[2,18,2]],"ltp":11.0,"tv":6067.5,"id":9345630},{"batb":[[1,1.08,212.13],[2,1.07,181.07]],"batl":[[0,1.12,61.38],[1,1.14,1.38],[2,1.16,14.38]],"ltp":1.1,"tv":76509.93,"id":9028621}]}]}
{"op":"mcm","clk":"4226819499","pt":1631451638519,"mc":[{"id":"1.187552454","rc":[{"batb":[[0,7,2],[1,2.32,102.49],[2,1.01,30]],"batl":[[0,15.5,2],[1,18,2],[2,20,6.45]],"ltp":11.0,"tv":6067.5,"id":9345630},{"trd":[[1.1,2395.79]],"batb":[[0,1.1,118.69],[1,1.07,181.07],[2,1.06,207.08]],"batl":[[0,1.12,1.38]],"ltp":1.1,"tv":76513.93,"id":9028621}],"tv":82581.43}]}
{"op":"mcm","clk":"4226819762","pt":1631451640356,"mc":[{"id":"1.187552454","rc":[{"batl":[[2,1.15,1.38]],"ltp":1.1,"tv":76513.93,"id":9028621}]}]}
{"op":"mcm","clk":"4226819998","pt":1631451642030,"mc":[{"id":"1.187552454","rc":[{"batb":[[0,7.2,2],[1,7,2],[2,2.32,102.49]],"ltp":11.0,"tv":6067.5,"id":9345630}]}]}
{"op":"mcm","clk":"4226820222","pt":1631451643215,"mc":[{"id":"1.187552454","rc":[{"batb":[[0,8,2],[1,7.8,2],[2,7.2,2]],"ltp":11.0,"tv":6067.5,"id":9345630},{"batb":[[0,1.1,1071.42],[1,1.09,1013.62],[2,1.07,181.07]],"batl":[[0,1.12,1730.59]],"ltp":1.1,"tv":76513.93,"id":9028621}]}]}
{"op":"mcm","clk":"4226820331","pt":1631451644026,"mc":[{"id":"1.187552454","rc":[{"batb":[[0,8.4,10],[1,8,2],[2,7.8,2]],"batl":[[0,13,10],[1,15.5,2],[2,18,2]],"ltp":11.0,"tv":6067.5,"id":9345630},{"batb":[[0,1.1,1123.13]],"batl":[[0,1.12,1737.49]],"ltp":1.1,"tv":76513.93,"id":9028621}]}]}
{"op":"mcm","clk":"4226820515","pt":1631451645316,"mc":[{"id":"1.187552454","rc":[{"trd":[[1.11,1273.71],[1.12,1524.3]],"batl":[[0,1.12,1729.26]],"ltp":1.12,"tv":76530.39,"id":9028621}],"tv":82597.89}]}
{"op":"mcm","clk":"4226820903","pt":1631451648379,"mc":[{"id":"1.187552454","rc":[{"batb":[[0,1.1,1004.44]],"ltp":1.12,"tv":76530.39,"id":9028621}]}]}
{"op":"mcm","clk":"4226821205","pt":1631451650364,"mc":[{"id":"1.187552454","rc":[{"trd":[[1.12,1538.1]],"batb":[[0,1.12,109.67],[1,1.07,181.07],[2,1.06,207.08]],"batl":[[0,1.14,1.38],[1,1.15,1.38],[2,1.16,14.38]],"ltp":1.12,"tv":76544.19,"id":9028621}],"tv":82611.69}]}
{"op":"mcm","clk":"4226821265","pt":1631451650754,"mc":[{"id":"1.187552454","rc":[{"batb":[[0,8,2],[1,7.8,2],[2,7.2,2]],"batl":[[0,15.5,2],[1,18,2],[2,20,6.45]],"ltp":11.0,"tv":6067.5,"id":9345630}]}]}
{"op":"mcm","clk":"4226821431","pt":1631451651872,"mc":[{"id":"1.187552454","rc":[{"batl":[[0,1.14,2.07]],"ltp":1.12,"tv":76544.19,"id":9028621}]}]}
{"op":"mcm","clk":"4226821664","pt":1631451653480,"mc":[{"id":"1.187552454","rc":[{"batb":[[0,8.4,2],[1,8.2,2],[2,8,2]],"ltp":11.0,"tv":6067.5,"id":9345630},{"batb":[[0,1.07,2193.09],[1,1.06,207.08],[2,1.05,1252.73]],"batl":[[0,1.14,820.3],[1,1.15,1075.2]],"ltp":1.12,"tv":76544.19,"id":9028621}]}]}
{"op":"mcm","clk":"4226821780","pt":1631451654382,"mc":[{"id":"1.187552454","rc":[{"batb":[[2,2.32,102.49]],"ltp":11.0,"tv":6067.5,"id":9345630},{"batl":[[1,1.15,1087.2]],"ltp":1.12,"tv":76544.19,"id":9028621}]}]}
{"op":"mcm","clk":"4226822109","pt":1631451656387,"mc":[{"id":"1.187552454","rc":[{"batl":[[0,15.5,4]],"ltp":11.0,"tv":6067.5,"id":9345630},{"batb":[[0,1.07,2224.09],[1,1.06,248.08]],"batl":[[0,1.13,1.38],[1,1.14,819.61],[2,1.15,1087.2]],"ltp":1.12,"tv":76544.19,"id":9028621}]}]}
{"op":"mcm","clk":"4226822158","pt":1631451656665,"mc":[{"id":"1.187552454","rc":[{"batl":[[0,1.13,2.07]],"ltp":1.12,"tv":76544.19,"id":9028621}]}]}
{"op":"mcm","clk":"4226823997","pt":1631451668305,"mc":[{"id":"1.187552454","rc":[{"batb":[[1,2.32,102.49],[2,1.01,30]],"ltp":11.0,"tv":6067.5,"id":9345630},{"trd":[[1.07,1251.54]],"batb":[[0,1.07,2196.54],[1,1.06,207.08]],"batl":[[2,1.15,1075.2]],"ltp":1.07,"tv":76599.3,"id":9028621}],"tv":82666.8}]}
{"op":"mcm","clk":"4226824502","pt":1631451671489,"mc":[{"id":"1.187552454","rc":[{"batb":[[1,8.2,2],[2,2.32,102.49]],"ltp":11.0,"tv":6067.5,"id":9345630},{"batb":[[1,1.06,209.08]],"ltp":1.07,"tv":76599.3,"id":9028621}]}]}
{"op":"mcm","clk":"4226824618","pt":1631451672391,"mc":[{"id":"1.187552454","rc":[{"trd":[[1.12,1539.48]],"batl":[[0,1.13,1.38]],"ltp":1.12,"tv":76600.68,"id":9028621}],"tv":82668.18}]}
{"op":"mcm","clk":"4226824781","pt":1631451673495,"mc":[{"id":"1.187552454","rc":[{"batl":[[0,9.2,2063.82],[1,10,235],[2,15.5,4]],"ltp":11.0,"tv":6067.5,"id":9345630},{"batb":[[0,1.12,40.24],[1,1.07,184.52],[2,1.06,209.08]],"ltp":1.12,"tv":76600.68,"id":9028621}]}]}
{"op":"mcm","clk":"4226824902","pt":1631451674228,"mc":[{"id":"1.187552454","rc":[{"trd":[[8.4,11.64],[8.6,100.88]],"batb":[[0,2.32,102.49],[1,1.01,30],[2,2.32,0]],"batl":[[0,8.4,6.36],[1,10,11.75]],"ltp":8.4,"tv":6071.68,"id":9345630},{"trd":[[1.13,6092.87]],"batb":[[0,1.07,184.52],[1,1.06,209.08],[2,1.05,1252.73]],"batl":[[0,1.14,806.61],[1,1.15,1075.2],[2,1.16,1.38]],"ltp":1.13,"tv":76602.05,"id":9028621}],"tv":82673.73}]}
{"op":"mcm","clk":"4226825288","pt":1631451676430,"mc":[{"id":"1.187552454","rc":[{"batl":[[1,10,58.75],[2,11,3.67]],"ltp":8.4,"tv":6071.68,"id":9345630},{"batb":[[0,1.12,1418.23],[1,1.11,508.5],[2,1.1,99.04]],"ltp":1.13,"tv":76602.05,"id":9028621}]}]}
{"op":"mcm","clk":"4226825480","pt":1631451677510,"mc":[{"id":"1.187552454","rc":[{"trd":[[8.4,15.63]],"batb":[[0,8,8.57],[1,7,35.71],[2,2.32,102.49]],"batl":[[0,8.4,6.36]],"ltp":8.4,"tv":6075.67,"id":9345630},{"batb":[[2,1.1,505.1]],"batl":[[0,1.14,879.53],[1,1.15,1135.2]],"ltp":1.13,"tv":76602.05,"id":9028621}],"tv":82677.73}]}
{"op":"mcm","clk":"4226825569","pt":1631451678105,"mc":[{"id":"1.187552454","rc":[{"batb":[[1,2.32,102.49],[2,1.01,30]],"batl":[[0,8.4,10.63]],"ltp":8.4,"tv":6075.67,"id":9345630},{"batb":[[2,1.1,297.77]],"ltp":1.13,"tv":76602.05,"id":9028621}]}]}
{"op":"mcm","clk":"4226825695","pt":1631451679015,"mc":[{"id":"1.187552454","rc":[{"trd":[[1.14,1549.11]],"batb":[[0,1.12,1294.87]],"batl":[[0,1.14,772.47],[1,1.15,1010.66]],"ltp":1.14,"tv":76816.17,"id":9028621}],"tv":82891.85}]}
{"op":"mcm","clk":"4226825912","pt":1631451680404,"mc":[{"id":"1.187552454","rc":[{"batb":[[1,7.8,2],[2,7.6,2]],"batl":[[2,10.5,19.46]],"ltp":8.4,"tv":6075.67,"id":9345630}]}]}
{"op":"mcm","clk":"4226826064","pt":1631451681418,"mc":[{"id":"1.187552454","rc":[{"trd":[[8.4,26.27]],"batb":[[0,8.2,9.12],[1,8,8.57],[2,7.8,2]],"batl":[[0,10,58.75],[1,10.5,19.46],[2,11,3.67]],"ltp":8.4,"tv":6086.31,"id":9345630},{"trd":[[1.13,6171.92],[1.14,1649.11]],"batb":[[0,1.12,1357.09]],"batl":[[0,1.14,722.47]],"ltp":1.13,"tv":76995.22,"id":9028621}],"tv":83081.54}]}
{"op":"mcm","clk":"4226826207","pt":1631451682307,"mc":[{"id":"1.187552454","rc":[{"batb":[[0,1.12,1403.42],[1,1.11,564.1],[2,1.1,108.04]],"batl":[[0,1.14,908.29],[1,1.15,1055.76]],"ltp":1.13,"tv":76995.22,"id":9028621}]}]}
{"op":"mcm","clk":"4226826534","pt":1631451684289,"mc":[{"id":"1.187552454","rc":[{"batl":[[0,9.2,2],[1,9.8,12.19],[2,10,58.75]],"ltp":8.4,"tv":6086.31,"id":9345630}]}]}
{"op":"mcm","clk":"4226826618","pt":1631451684827,"mc":[{"id":"1.187552454","rc":[{"batl":[[1,10,58.75],[2,10.5,19.46]],"ltp":8.4,"tv":6086.31,"id":9345630},{"batb":[[1,1.11,745]],"batl":[[0,1.13,4.4],[1,1.14,908.29],[2,1.15,1055.76]],"ltp":1.13,"tv":76995.22,"id":9028621}]}]}
{"op":"mcm","clk":"4226826916","pt":1631451686548,"mc":[{"id":"1.187552454","rc":[{"trd":[[1.13,6180.72]],"batb":[[0,1.13,90.15],[1,1.12,1403.42],[2,1.11,745]],"batl":[[0,1.14,908.29],[1,1.15,1055.76],[2,1.16,1.38]],"ltp":1.13,"tv":77004.02,"id":9028621}],"tv":83090.33}]}
{"op":"mcm","clk":"4226827100","pt":1631451687536,"mc":[{"id":"1.187552454","rc":[{"batl":[[0,9,2],[1,9.2,2],[2,10,58.75]],"ltp":8.4,"tv":6086.31,"id":9345630}]}]}
{"op":"mcm","clk":"4226827160","pt":1631451687817,"mc":[{"id":"1.187552454","rc":[{"batl":[[1,9.2,14.19]],"ltp":8.4,"tv":6086.31,"id":9345630}]}]}
{"op":"mcm","clk":"4226827900","pt":1631451691827,"mc":[{"id":"1.187552454","rc":[{"trd":[[1.14,1808.02]],"batl":[[0,1.14,828.83]],"ltp":1.14,"tv":77162.93,"id":9028621}],"tv":83249.25}]}
{"op":"mcm","clk":"4226828195","pt":1631451693826,"mc":[{"id":"1.187552454","rc":[{"trd":[[8.8,8.16]],"ltp":8.8,"tv":6094.46,"id":9345630},{"trd":[[1.13,6244.23]],"batb":[[0,1.13,26.64]],"ltp":1.13,"tv":77226.45,"id":9028621}],"tv":83320.92}]}
{"op":"mcm","clk":"4226828434","pt":1631451695416,"mc":[{"id":"1.187552454","rc":[{"batb":[[0,1.12,1460.19],[1,1.11,745],[2,1.1,108.04]],"batl":[[0,1.14,902.55],[1,1.15,1111.01]],"ltp":1.13,"tv":77226.45,"id":9028621}]}]}
{"op":"mcm","clk":"4226828713","pt":1631451697334,"mc":[{"id":"1.187552454","rc":[{"batl":[[1,9.2,12.19]],"ltp":8.8,"tv":6094.46,"id":9345630}]}]}
{"op":"mcm","clk":"4226828888","pt":1631451698516,"mc":[{"id":"1.187552454","rc":[{"batl":[[2,10,47]],"ltp":8.8,"tv":6094.46,"id":9345630}]}]}
{"op":"mcm","clk":"4226828975","pt":1631451699271,"mc":[{"id":"1.187552454","rc":[{"batb":[[0,8,8.57],[1,2.32,102.49],[2,1.01,30]],"batl":[[0,10.5,19.46],[1,12.5,2],[2,15,21.32]],"ltp":8.8,"tv":6094.46,"id":9345630},{"batb":[[0,1.11,180.9],[1,1.09,130.61],[2,1.08,168.23]],"batl":[[0,1.15,61.38],[1,1.16,1.38],[2,1.17,1.38]],"ltp":1.13,"tv":77226.45,"id":9028621}]}]}
{"op":"mcm","clk":"4226829170","pt":1631451700574,"mc":[{"id":"1.187552454","rc":[{"batb":[[0,2.32,102.49],[1,1.01,30],[2,1.01,0]],"batl":[[0,12.5,2],[1,15,21.32],[2,15.5,2]],"ltp":8.8,"tv":6094.46,"id":9345630},{"batb":[[0,1.09,130.61],[1,1.08,168.23],[2,1.07,184.52]],"batl":[[0,1.15,1.38]],"ltp":1.13,"tv":77226.45,"id":9028621}]}]}
{"op":"mcm","clk":"4226829294","pt":1631451701017,"mc":[{"id":"1.187552454","rc":[{"batl":[[0,15,21.32],[1,15.5,2],[2,18,2]],"ltp":8.8,"tv":6094.46,"id":9345630},{"batb":[[0,1.08,2.17],[1,1.07,184.52],[2,1.06,1059.83]],"ltp":1.13,"tv":77226.45,"id":9028621}]}]}
{"op":"mcm","clk":"4226829819","pt":1631451704558,"mc":[{"id":"1.187552454","rc":[{"batb":[[0,5.5,3],[1,5.4,3],[2,2.32,102.49]],"batl":[[0,9.4,333.87],[1,12.5,2],[2,13.5,2]],"ltp":8.8,"tv":6094.46,"id":9345630},{"batb":[[0,1.09,134.61],[1,1.08,172.73],[2,1.07,184.52]],"ltp":1.13,"tv":77226.45,"id":9028621}]}]}
{"op":"mcm","clk":"4226829970","pt":1631451705367,"mc":[{"id":"1.187552454","rc":[{"batb":[[0,6.2,3],[1,6,2],[2,5.9,3]],"batl":[[0,13.5,2],[1,15,23.32],[2,15.5,2]],"ltp":8.8,"tv":6094.46,"id":9345630},{"batb":[[0,1.13,1144.82],[1,1.12,767.15],[2,1.08,21.17]],"batl":[[0,1.15,845.38],[1,1.16,1020.57]],"ltp":1.13,"tv":77226.45,"id":9028621}]}]}
{"op":"mcm","clk":"4226830144","pt":1631451706575,"mc":[{"id":"1.187552454","rc":[{"batb":[[0,6.8,35.67],[1,6.2,3],[2,6,2]],"batl":[[0,10.5,22.75],[1,13.5,2],[2,15,23.32]],"ltp":8.8,"tv":6094.46,"id":9345630},{"batb":[[2,1.11,10.85]],"batl":[[0,1.15,852.28]],"ltp":1.13,"tv":77226.45,"id":9028621}]}]}
{"op":"mcm","clk":"4226830224","pt":1631451706946,"mc":[{"id":"1.187552454","rc":[{"trd":[[8.8,29.85]],"batb":[[0,6.8,15]],"batl":[[0,10.5,10]],"ltp":8.8,"tv":6116.15,"id":9345630},{"trd":[[1.13,6413.15]],"batb":[[0,1.13,975.9],[2,1.08,21.17]],"ltp":1.13,"tv":77395.37,"id":9028621}],"tv":83511.53}]}
{"op":"mcm","clk":"4226830410","pt":1631451707972,"mc":[{"id":"1.187552454","rc":[{"batl":[[1,12.5,2],[2,13.5,2]],"ltp":8.8,"tv":6116.15,"id":9345630},{"batb":[[2,1.09,135.61]],"batl":[[1,1.16,949.6]],"ltp":1.13,"tv":77395.37,"id":9028621}]}]}
{"op":"mcm","clk":"4226830882","pt":1631451710550,"mc":[{"id":"1.187552454","rc":[{"batb":[[0,1.13,1120.66],[1,1.12,840.52]],"batl":[[0,1.15,923.86]],"ltp":1.13,"tv":77395.37,"id":9028621}]}]}
{"op":"mcm","clk":"4226831132","pt":1631451712270,"mc":[{"id":"1.187552454","rc":[{"batl":[[1,13.5,2],[2,15,23.32]],"ltp":8.8,"tv":6116.15,"id":9345630},{"batb":[[0,1.08,21.17],[1,1.07,184.52],[2,1.06,1059.83]],"batl":[[0,1.15,8.28],[1,1.16,1.38]],"ltp":1.13,"tv":77395.37,"id":9028621}]}]}
{"op":"mcm","clk":"4226831474","pt":1631451714249,"mc":[{"id":"1.187552454","rc":[{"trd":[[7.6,15.97]],"batl":[[0,7.6,23.86],[1,10.5,10],[2,13.5,2]],"ltp":7.6,"tv":6117.41,"id":9345630},{"trd":[[1.15,281.97]],"batl":[[0,1.16,1.38],[1,1.17,1.38],[2,1.18,1.38]],"ltp":1.15,"tv":77403.65,"id":9028621}],"tv":83521.06}]}
{"op":"mcm","clk":"4226831721","pt":1631451715580,"mc":[{"id":"1.187552454","rc":[{"trd":[[7.6,16.32]],"batl":[[0,7.6,23.51]],"ltp":7.6,"tv":6117.75,"id":9345630},{"trd":[[1.15,284.24]],"batb":[[0,1.11,105.85],[1,1.09,1975.1],[2,1.08,21.17]],"ltp":1.15,"tv":77405.92,"id":9028621}],"tv":83523.68}]}
{"op":"mcm","clk":"4226831824","pt":1631451716349,"mc":[{"id":"1.187552454","rc":[{"batb":[[0,6.2,3],[1,5.9,3],[2,2.32,102.49]],"batl":[[1,12.5,2]],"ltp":7.6,"tv":6117.75,"id":9345630},{"batb":[[0,1.09,2120.71],[1,1.08,157.98],[2,1.07,153.52]],"ltp":1.15,"tv":77405.92,"id":9028621}]}]}
{"op":"mcm","clk":"4226832154","pt":1631451718488,"mc":[{"id":"1.187552454","rc":[{"trd":[[7.6,17.36]],"batl":[[0,7.6,22.47]],"ltp":7.6,"tv":6118.79,"id":9345630},{"trd":[[1.15,291.14]],"ltp":1.15,"tv":77412.82,"id":9028621}],"tv":83531.62}]}
{"op":"mcm","clk":"4226832203","pt":1631451718782,"mc":[{"id":"1.187552454","rc":[{"batb":[[1,2.32,102.49],[2,1.01,30]],"ltp":7.6,"tv":6118.79,"id":9345630}]}]}
{"op":"mcm","clk":"4226832304","pt":1631451719606,"mc":[{"id":"1.187552454","rc":[{"batb":[[1,6,3],[2,2.32,102.49]],"ltp":7.6,"tv":6118.79,"id":9345630}]}]}
{"op":"mcm","clk":"4226833012","pt":1631451724537,"mc":[{"id":"1.187552454","rc":[{"trd":[[6.2,8.91],[6.4,21.8],[6.8,4.98],[7.2,0.22]],"batb":[[0,6,3],[1,2.32,102.49],[2,1.01,30]],"batl":[[0,6.2,18.53],[1,7.6,22.47],[2,12.5,2]],"ltp":6.2,"tv":6128.26,"id":9345630},{"trd":[[1.16,397.01],[1.17,1396.62],[1.18,504.02],[1.19,468.42]],"batl":[[0,1.2,1.38],[1,1.21,1.38],[2,1.22,19.15]],"ltp":1.19,"tv":77431.33,"id":9028621}],"tv":83559.6}]}
{"op":"mcm","clk":"4226833169","pt":1631451725497,"mc":[{"id":"1.187552454","rc":[{"trd":[[6.2,27.44],[7.6,39.83]],"batl":[[0,12.5,2],[1,13.5,2],[2,15,21.32]],"ltp":7.6,"tv":6169.27,"id":9345630},{"trd":[[1.09,2998.13],[1.15,439.65],[1.19,564.96]],"batb":[[0,1.09,1938.74]],"ltp":1.09,"tv":78040.32,"id":9028621}],"tv":84209.59}]}
{"op":"mcm","clk":"4226833330","pt":1631451726586,"mc":[{"id":"1.187552454","rc":[{"batb":[[0,10,2.24],[1,8.6,96.5],[2,6,3]],"ltp":7.6,"tv":6169.27,"id":9345630},{"batl":[[0,1.11,1164.19],[1,1.12,774.83],[2,1.14,14]],"ltp":1.09,"tv":78040.32,"id":9028621}]}]}
{"op":"mcm","clk":"4226833453","pt":1631451727405,"mc":[{"id":"1.187552454","rc":[{"batb":[[1,8.6,28.11]],"ltp":7.6,"tv":6169.27,"id":9345630},{"batl":[[1,1.12,698.44]],"ltp":1.09,"tv":78040.32,"id":9028621}]}]}
{"op":"mcm","clk":"4226833606","pt":1631451728469,"mc":[{"id":"1.187552454","rc":[{"batb":[[1,9.4,7.14],[2,9,17]],"batl":[[0,12,6.92],[1,12.5,4],[2,13,17.32]],"ltp":7.6,"tv":6169.27,"id":9345630},{"batb":[[0,1.09,2220.73],[1,1.08,370.11]],"batl":[[0,1.11,1241.28],[1,1.12,758.44]],"ltp":1.09,"tv":78040.32,"id":9028621}]}]}
{"op":"mcm","clk":"4226833758","pt":1631451729492,"mc":[{"id":"1.187552454","rc":[{"batb":[[2,9,2]],"batl":[[0,12,8.92]],"ltp":7.6,"tv":6169.27,"id":9345630},{"batl":[[2,1.13,20]],"ltp":1.09,"tv":78040.32,"id":9028621}]}]}
{"op":"mcm","clk":"4226833902","pt":1631451730273,"mc":[{"id":"1.187552454","rc":[{"batb":[[0,1.1,13.78],[1,1.09,2220.73],[2,1.08,370.11]],"ltp":1.09,"tv":78040.32,"id":9028621}]}]}
{"op":"mcm","clk":"4226834074","pt":1631451731499,"mc":[{"id":"1.187552454","rc":[{"batb":[[1,9,2],[2,8.8,2]],"batl":[[0,11.5,3],[1,12,8.92],[2,12.5,4]],"ltp":7.6,"tv":6169.27,"id":9345630},{"trd":[[1.1,2423.35]],"batb":[[0,1.09,2220.73],[1,1.08,370.11],[2,1.07,153.52]],"batl":[[0,1.1,42.05],[1,1.11,1241.28],[2,1.12,758.44]],"ltp":1.1,"tv":78067.88,"id":9028621}],"tv":84237.15}]}
{"op":"mcm","clk":"4226834149","pt":1631451731996,"mc":[{"id":"1.187552454","rc":[{"batb":[[0,10.5,5.77],[1,10,2.24],[2,9,2]],"ltp":7.6,"tv":6169.27,"id":9345630},{"batl":[[0,1.11,1241.28],[1,1.12,758.44],[2,1.13,20]],"ltp":1.1,"tv":78067.88,"id":9028621}]}]}
{"op":"mcm","clk":"4226834557","pt":1631451734521,"mc":[{"id":"1.187552454","rc":[{"trd":[[10.5,41.54]],"batb":[[0,10,3.01],[1,9.8,6.81]],"ltp":10.5,"tv":6179.27,"id":9345630},{"trd":[[1.11,2145.83]],"batl":[[0,1.11,805.22]],"ltp":1.11,"tv":78940.0,"id":9028621}],"tv":85119.27}]}
{"op":"mcm","clk":"4226834664","pt":1631451735114,"mc":[{"id":"1.187552454","rc":[{"batl":[[2,1.13,25.81]],"ltp":1.11,"tv":78940.0,"id":9028621}]}]}
{"op":"mcm","clk":"4226835044","pt":1631451737410,"mc":[{"id":"1.187552454","rc":[{"trd":[[10,125.22],[10.5,43.08]],"batb":[[0,9.8,6.81],[1,9,2],[2,8.8,2]],"ltp":10.0,"tv":6202.28,"id":9345630},{"trd":[[1.11,2298.89]],"batl":[[0,1.11,652.16]],"ltp":1.11,"tv":79093.06,"id":9028621}],"tv":85295.34}]}
{"op":"mcm","clk":"4226835212","pt":1631451738506,"mc":[{"id":"1.187552454","rc":[{"batl":[[0,1.11,988.57],[1,1.12,941.71]],"ltp":1.11,"tv":79093.06,"id":9028621}]}]}
{"op":"mcm","clk":"4226835358","pt":1631451739320,"mc":[{"id":"1.187552454","rc":[{"trd":[[10,126.12]],"ltp":10.0,"tv":6203.18,"id":9345630},{"trd":[[1.11,2307]],"batb":[[0,1.1,2.27],[1,1.09,2220.73],[2,1.08,370.11]],"batl":[[0,1.11,980.46]],"ltp":1.11,"tv":79101.17,"id":9028621}],"tv":85304.35}]}
{"op":"mcm","clk":"4226835548","pt":1631451740506,"mc":[{"id":"1.187552454","rc":[{"batl":[[2,12.5,2]],"ltp":10.0,"tv":6203.18,"id":9345630},{"batb":[[2,1.08,351.11]],"batl":[[0,1.11,1067.63],[1,1.12,1007.02]],"ltp":1.11,"tv":79101.17,"id":9028621}]}]}
{"op":"mcm","clk":"4226835692","pt":1631451741441,"mc":[{"id":"1.187552454","rc":[{"batb":[[0,10,11.19],[1,9.8,6.81],[2,9,2]],"batl":[[1,12,2]],"ltp":10.0,"tv":6203.18,"id":9345630},{"trd":[[1.11,2307.8]],"batl":[[0,1.11,1067.23]],"ltp":1.11,"tv":79101.96,"id":9028621}],"tv":85305.15}]}
{"op":"mcm","clk":"4226836071","pt":1631451743421,"mc":[{"id":"1.187552454","rc":[{"batb":[[0,9.8,6.81],[1,2.32,102.49],[2,1.01,30]],"batl":[[0,13,17.32],[1,15.5,2],[2,18,2]],"ltp":10.0,"tv":6203.18,"id":9345630},{"batb":[[0,1.11,28.51],[1,1.1,2.27],[2,1.08,216.01]],"batl":[[0,1.12,60.69],[1,1.22,17.91],[2,1.25,14.85]],"ltp":1.11,"tv":79101.96,"id":9028621}]}]}
{"op":"mcm","clk":"4226836256","pt":1631451744502,"mc":[{"id":"1.187552454","rc":[{"batb":[[0,2.32,102.49],[1,1.01,30],[2,1.01,0]],"batl":[[0,15.5,2],[1,18,2],[2,20,6.45]],"ltp":10.0,"tv":6203.18,"id":9345630},{"batb":[[2,1.08,2.17]],"batl":[[0,1.13,1.38],[1,1.15,1.52],[2,1.22,17.77]],"ltp":1.11,"tv":79101.96,"id":9028621}]}]}
{"op":"mcm","clk":"4226836437","pt":1631451745536,"mc":[{"id":"1.187552454","rc":[{"batl":[[0,18,2],[1,20,6.45],[2,1000,0.32]],"ltp":10.0,"tv":6203.18,"id":9345630},{"batl":[[2,1.17,1.38]],"ltp":1.11,"tv":79101.96,"id":9028621}]}]}
{"op":"mcm","clk":"4226836562","pt":1631451746488,"mc":[{"id":"1.187552454","rc":[{"trd":[[1.11,2364.08]],"batb":[[0,1.1,2.65],[1,1.08,2.17],[2,1.07,2012.02]],"batl":[[1,1.15,1064.25],[2,1.16,803.03]],"ltp":1.11,"tv":79158.24,"id":9028621}],"tv":85361.43}]}
{"op":"mcm","clk":"4226836635","pt":1631451747113,"mc":[{"id":"1.187552454","rc":[{"batb":[[0,1.1,2.73]],"batl":[[0,1.12,1.38],[1,1.14,1.38],[2,1.15,1063.56]],"ltp":1.11,"tv":79158.24,"id":9028621}]}]}
{"op":"mcm","clk":"4226836793","pt":1631451748318,"mc":[{"id":"1.187552454","rc":[{"batb":[[0,5.5,2],[1,5.4,2],[2,2.32,102.49]],"batl":[[0,15.5,2],[1,18,2],[2,20,6.45]],"ltp":10.0,"tv":6203.18,"id":9345630},{"batb":[[2,1.07,2192.09]],"batl":[[1,1.13,1.38],[2,1.14,1.38]],"ltp":1.11,"tv":79158.24,"id":9028621}]}]}
{"op":"mcm","clk":"4226836861","pt":1631451748818,"mc":[{"id":"1.187552454","rc":[{"batb":[[0,1.1,3.03]],"ltp":1.11,"tv":79158.24,"id":9028621}]}]}
{"op":"mcm","clk":"4226837107","pt":1631451750535,"mc":[{"id":"1.187552454","rc":[{"batl":[[0,15.5,4]],"ltp":10.0,"tv":6203.18,"id":9345630},{"batb":[[0,1.1,2.65]],"ltp":1.11,"tv":79158.24,"id":9028621}]}]}
{"op":"mcm","clk":"4226837711","pt":1631451754506,"mc":[{"id":"1.187552454","rc":[{"trd":[[1.08,1247.11],[1.1,2427.89],[1.11,2364.84]],"batb":[[0,1.07,2192.09],[1,1.06,207.08],[2,1.04,1155.85]],"ltp":1.08,"tv":79167.89,"id":9028621}],"tv":85371.07}]}
{"op":"mcm","clk":"4226837839","pt":1631451755406,"mc":[{"id":"1.187552454","rc":[{"batb":[[0,11,199.46],[1,5.5,2],[2,5.4,2]],"ltp":10.0,"tv":6203.18,"id":9345630}]}]}
{"op":"mcm","clk":"4226837916","pt":1631451755934,"mc":[{"id":"1.187552454","rc":[{"batb":[[0,11,9.97]],"ltp":10.0,"tv":6203.18,"id":9345630},{"batl":[[0,1.1,8.54],[1,1.12,1.38],[2,1.13,1.38]],"ltp":1.08,"tv":79167.89,"id":9028621}]}]}
{"op":"mcm","clk":"4226838189","pt":1631451757536,"mc":[{"id":"1.187552454","rc":[{"batb":[[0,13,2],[1,11,22.96],[2,5.5,2]],"ltp":10.0,"tv":6203.18,"id":9345630},{"batb":[[2,1.04,15.34]],"batl":[[0,1.09,1806.75],[1,1.1,20.19],[2,1.12,15.62]],"ltp":1.08,"tv":79167.89,"id":9028621}]}]}
{"op":"mcm","clk":"4226838346","pt":1631451758404,"mc":[{"id":"1.187552454","rc":[{"batb":[[1,11,38.96]],"batl":[[0,15,5.45],[1,15.5,4],[2,16.5,15.24]],"ltp":10.0,"tv":6203.18,"id":9345630},{"batb":[[0,1.07,2303.79],[1,1.06,471.02]],"batl":[[1,1.1,84.44]],"ltp":1.08,"tv":79167.89,"id":9028621}]}]}
{"op":"mcm","clk":"4226838522","pt":1631451759425,"mc":[{"id":"1.187552454","rc":[{"batb":[[1,11.5,2],[2,11,31.96]],"batl":[[0,15,2]],"ltp":10.0,"tv":6203.18,"id":9345630},{"trd":[[1.09,2998.53]],"batl":[[0,1.09,1834.55],[1,1.1,77.54]],"ltp":1.09,"tv":79168.29,"id":9028621}],"tv":85371.47}]}
{"op":"mcm","clk":"4226838701","pt":1631451760520,"mc":[{"id":"1.187552454","rc":[{"batl":[[0,1.09,1835.24]],"ltp":1.09,"tv":79168.29,"id":9028621}]}]}
{"op":"mcm","clk":"4226838861","pt":1631451761529,"mc":[{"id":"1.187552454","rc":[{"batl":[[0,14.5,2],[1,15,2],[2,15.5,4]],"ltp":10.0,"tv":6203.18,"id":9345630}]}]}
{"op":"mcm","clk":"4226839014","pt":1631451762571,"mc":[{"id":"1.187552454","rc":[{"batb":[[0,13,12]],"batl":[[0,14.5,7.45]],"ltp":10.0,"tv":6203.18,"id":9345630},{"batl":[[0,1.09,1976.44],[1,1.1,18.23],[2,1.12,16.31]],"ltp":1.09,"tv":79168.29,"id":9028621}]}]}
{"op":"mcm","clk":"4226839182","pt":1631451763539,"mc":[{"id":"1.187552454","rc":[{"batb":[[2,11,25.96]],"ltp":10.0,"tv":6203.18,"id":9345630},{"batl":[[2,1.12,17]],"ltp":1.09,"tv":79168.29,"id":9028621}]}]}
{"op":"mcm","clk":"4226839300","pt":1631451764238,"mc":[{"id":"1.187552454","rc":[{"batb":[[2,1.05,242.29]],"batl":[[0,1.08,488.56],[1,1.09,1976.44],[2,1.1,18.23]],"ltp":1.09,"tv":79168.29,"id":9028621}]}]}
{"op":"mcm","clk":"4226839524","pt":1631451765519,"mc":[{"id":"1.187552454","rc":[{"batl":[[1,1.09,2036.44]],"ltp":1.09,"tv":79168.29,"id":9028621}]}]}
{"op":"mcm","clk":"4226839575","pt":1631451765841,"mc":[{"id":"1.187552454","rc":[{"batb":[[1,12,5.45],[2,11.5,2]],"ltp":10.0,"tv":6203.18,"id":9345630},{"batl":[[2,1.1,9.69]],"ltp":1.09,"tv":79168.29,"id":9028621}]}]}
{"op":"mcm","clk":"4226839765","pt":1631451767031,"mc":[{"id":"1.187552454","rc":[{"batl":[[0,1.08,490.27]],"ltp":1.09,"tv":79168.29,"id":9028621}]}]}
{"op":"mcm","clk":"4226840579","pt":1631451772033,"mc":[{"id":"1.187552454","rc":[{"trd":[[13.5,14.07]],"batl":[[1,15.5,2],[2,16.5,15.24]],"ltp":13.5,"tv":6203.92,"id":9345630},{"trd":[[1.08,1256.4]],"batb":[[1,1.06,452.02]],"batl":[[0,1.08,480.98]],"ltp":1.08,"tv":79177.58,"id":9028621}],"tv":85381.5}]}
{"op":"mcm","clk":"4226841094","pt":1631451775469,"mc":[{"id":"1.187552454","rc":[{"batb":[[0,12,5.45],[1,11.5,2],[2,2.32,102.49]],"batl":[[0,14.5,2],[1,16.5,15.24],[2,18,2]],"ltp":13.5,"tv":6203.92,"id":9345630},{"trd":[[1.07,1271.22]],"batb":[[0,1.07,18]],"batl":[[1,1.09,88.69],[2,1.11,1.38]],"ltp":1.07,"tv":79197.26,"id":9028621}],"tv":85401.18}]}
{"op":"mcm","clk":"4226841243","pt":1631451776474,"mc":[{"id":"1.187552454","rc":[{"batb":[[0,2.32,102.49],[1,1.01,30],[2,2.32,0]],"batl":[[0,18,2],[1,20,6.45],[2,21,2]],"ltp":13.5,"tv":6203.92,"id":9345630},{"batb":[[0,1.06,207.08],[1,1.05,242.29],[2,1.04,324.87]],"batl":[[1,1.1,1.38],[2,1.12,2.76]],"ltp":1.07,"tv":79197.26,"id":9028621}]}]}
{"op":"mcm","clk":"4226841395","pt":1631451777407,"mc":[{"id":"1.187552454","rc":[{"batl":[[0,20,6.45],[1,21,2],[2,1000,0.32]],"ltp":13.5,"tv":6203.92,"id":9345630},{"trd":[[1.08,1258.07]],"batb":[[0,1.05,242.29],[1,1.04,324.87],[2,1.03,2409.87]],"batl":[[0,1.07,3.9],[1,1.08,480.15],[2,1.1,1.38]],"ltp":1.08,"tv":79198.92,"id":9028621}],"tv":85402.85}]}
{"op":"mcm","clk":"4226841709","pt":1631451779412,"mc":[{"id":"1.187552454","rc":[{"batl":[[0,16.5,2],[1,20,6.45],[2,21,2]],"ltp":13.5,"tv":6203.92,"id":9345630},{"batb":[[0,1.06,39],[1,1.05,292.29],[2,1.04,324.87]],"ltp":1.08,"tv":79198.92,"id":9028621}]}]}
{"op":"mcm","clk":"4226841793","pt":1631451779897,"mc":[{"id":"1.187552454","rc":[{"batl":[[1,18,4],[2,20,38.64]],"ltp":13.5,"tv":6203.92,"id":9345630},{"batb":[[0,1.06,239.08],[2,1.04,382.87]],"ltp":1.08,"tv":79198.92,"id":9028621}]}]}
{"op":"mcm","clk":"4226842037","pt":1631451781472,"mc":[{"id":"1.187552454","rc":[{"trd":[[13.5,52.48],[15,7.99]],"batl":[[0,12.5,1710.79],[1,16.5,2],[2,18,4]],"ltp":13.5,"tv":6242.61,"id":9345630},{"trd":[[1.07,1275.12],[1.08,1738.22]],"batb":[[0,1.08,1788.96],[1,1.06,239.08],[2,1.05,292.29]],"batl":[[0,1.11,1569.67],[1,1.12,366.54],[2,1.21,14.99]],"ltp":1.08,"tv":79682.98,"id":9028621}],"tv":85925.59}]}
{"op":"mcm","clk":"4226842205","pt":1631451782502,"mc":[{"id":"1.187552454","rc":[{"batl":[[0,13.5,11.25]],"ltp":13.5,"tv":6242.61,"id":9345630},{"batb":[[0,1.09,11409.85],[1,1.08,1034.34],[2,1.07,3.78]],"batl":[[2,1.14,14]],"ltp":1.08,"tv":79682.98,"id":9028621}]}]}
{"op":"mcm","clk":"4226842350","pt":1631451783392,"mc":[{"id":"1.187552454","rc":[{"batb":[[0,10,6.66],[1,2.32,102.49],[2,1.01,30]],"batl":[[0,12.5,2],[1,13.5,11.25],[2,14,16.64]],"ltp":13.5,"tv":6242.61,"id":9345630},{"batb":[[0,1.09,1642.25],[2,1.07,9]],"ltp":1.08,"tv":79682.98,"id":9028621}]}]}
{"op":"mcm","clk":"4226842646","pt":1631451785179,"mc":[{"id":"1.187552454","rc":[{"batb":[[0,10,9.66],[1,9.8,3],[2,2.32,102.49]],"batl":[[0,12,2],[1,12.5,2],[2,13.5,11.25]],"ltp":13.5,"tv":6242.61,"id":9345630},{"batl":[[0,1.11,1763.45]],"ltp":1.08,"tv":79682.98,"id":9028621}]}]}
{"op":"mcm","clk":"4226843038","pt":1631451787382,"mc":[{"id":"1.187552454","rc":[{"batb":[[0,10.5,26.53],[1,10,9.66],[2,9.8,3]],"batl":[[0,12,12]],"ltp":13.5,"tv":6242.61,"id":9345630},{"batb":[[0,1.09,1878.1]],"batl":[[0,1.11,1764.14],[1,1.12,367.23]],"ltp":1.08,"tv":79682.98,"id":9028621}]}]}
{"op":"mcm","clk":"4226843097","pt":1631451787708,"mc":[{"id":"1.187552454","rc":[{"batb":[[0,10.5,7.52]],"ltp":13.5,"tv":6242.61,"id":9345630},{"batb":[[0,1.09,1712.48]],"batl":[[2,1.14,14.69]],"ltp":1.08,"tv":79682.98,"id":9028621}]}]}
{"op":"mcm","clk":"4226843505","pt":1631451790396,"mc":[{"id":"1.187552454","rc":[{"batl":[[2,13.5,28.22]],"ltp":13.5,"tv":6242.61,"id":9345630},{"batb":[[1,1.08,1246.47]],"ltp":1.08,"tv":79682.98,"id":9028621}]}]}
{"op":"mcm","clk":"4226843696","pt":1631451791481,"mc":[{"id":"1.187552454","rc":[{"batb":[[0,1.09,5137.62]],"ltp":1.08,"tv":79682.98,"id":9028621}]}]}
{"op":"mcm","clk":"4226843838","pt":1631451792201,"mc":[{"id":"1.187552454","rc":[{"trd":[[1.09,3010.17]],"batb":[[0,1.09,5131.8]],"batl":[[2,1.14,15.37]],"ltp":1.09,"tv":79694.61,"id":9028621}],"tv":85937.23}]}
{"op":"mcm","clk":"4226844272","pt":1631451794505,"mc":[{"id":"1.187552454","rc":[{"trd":[[12,178.02]],"batl":[[0,12,11.56]],"ltp":12.0,"tv":6243.49,"id":9345630},{"batb":[[0,1.09,5026]],"batl":[[0,1.11,1764.83]],"ltp":1.09,"tv":79694.61,"id":9028621}],"tv":85938.1}]}
{"op":"mcm","clk":"4226844406","pt":1631451795211,"mc":[{"id":"1.187552454","rc":[{"batl":[[1,1.12,367.92]],"ltp":1.09,"tv":79694.61,"id":9028621}]}]}
{"op":"mcm","clk":"4226844525","pt":1631451795814,"mc":[{"id":"1.187552454","rc":[{"batl":[[2,1.14,16.06]],"ltp":1.09,"tv":79694.61,"id":9028621}]}]}
{"op":"mcm","clk":"4226844763","pt":1631451797301,"mc":[{"id":"1.187552454","rc":[{"batb":[[2,5.6,124.18]],"ltp":12.0,"tv":6243.49,"id":9345630},{"batl":[[2,1.13,1.38]],"ltp":1.09,"tv":79694.61,"id":9028621}]}]}
{"op":"mcm","clk":"4226845319","pt":1631451800535,"mc":[{"id":"1.187552454","rc":[{"batb":[[0,10,6.66],[1,5.6,124.18],[2,2.32,102.49]],"batl":[[0,10.5,2.85],[1,13.5,25.51],[2,18,2]],"ltp":12.0,"tv":6243.49,"id":9345630},{"batb":[[0,1.09,3425.14],[1,1.08,212.13],[2,1.06,200.08]],"batl":[[0,1.11,61.38],[1,1.12,1.38]],"ltp":1.09,"tv":79694.61,"id":9028621}]}]}
{"op":"mcm","clk":"4226845469","pt":1631451801513,"mc":[{"id":"1.187552454","rc":[{"batb":[[0,5.6,124.18],[1,2.32,102.49],[2,1.01,30]],"batl":[[1,13.5,8.54]],"ltp":12.0,"tv":6243.49,"id":9345630},{"batb":[[1,1.06,200.08],[2,1.05,242.29]],"batl":[[0,1.11,1.38]],"ltp":1.09,"tv":79694.61,"id":9028621}]}]}
{"op":"mcm","clk":"4226845758","pt":1631451803435,"mc":[{"id":"1.187552454","rc":[{"batb":[[1,1.06,2231.08]],"ltp":1.09,"tv":79694.61,"id":9028621}]}]}
{"op":"mcm","clk":"4226845832","pt":1631451803728,"mc":[{"id":"1.187552454","rc":[{"trd":[[10.5,48.64]],"batl":[[0,13.5,8.61],[1,18,2],[2,20,36.64]],"ltp":10.5,"tv":6249.05,"id":9345630}],"tv":85943.66}]}
{"op":"mcm","clk":"4226846076","pt":1631451805210,"mc":[{"id":"1.187552454","rc":[{"batb":[[0,6.2,2],[1,6,2],[2,5.6,124.18]],"ltp":10.5,"tv":6249.05,"id":9345630}]}]}
{"op":"mcm","clk":"4226846287","pt":1631451806428,"mc":[{"id":"1.187552454","rc":[{"batb":[[0,7.6,2],[1,7.4,2],[2,6.2,2]],"ltp":10.5,"tv":6249.05,"id":9345630}]}]}
{"op":"mcm","clk":"4226846802","pt":1631451809537,"mc":[{"id":"1.187552454","rc":[{"batl":[[0,18,2.07],[1,20,36.64],[2,21,2]],"ltp":10.5,"tv":6249.05,"id":9345630}]}]}
{"op":"mcm","clk":"4226846849","pt":1631451809851,"mc":[{"id":"1.187552454","rc":[{"trd":[[10.5,48.71]],"batl":[[0,18,2]],"ltp":10.5,"tv":6249.12,"id":9345630},{"trd":[[1.09,3862.88],[1.1,2428.55]],"batb":[[0,1.09,2998.78]],"ltp":1.09,"tv":80547.99,"id":9028621}],"tv":86797.11}]}
{"op":"mcm","clk":"4226847117","pt":1631451811525,"mc":[{"id":"1.187552454","rc":[{"batb":[[0,11.5,9.13],[1,7.6,2],[2,7.4,2]],"ltp":10.5,"tv":6249.12,"id":9345630},{"trd":[[1.09,9860.44]],"batb":[[0,1.06,2231.08],[1,1.05,242.29],[2,1.04,1480.72]],"batl":[[0,1.09,8.54],[1,1.15,18.14],[2,1.19,27.85]],"ltp":1.09,"tv":86545.55,"id":9028621}],"tv":92794.67}]}
{"op":"mcm","clk":"4226847272","pt":1631451812549,"mc":[{"id":"1.187552454","rc":[{"batb":[[0,11.5,21.51]],"ltp":10.5,"tv":6249.12,"id":9345630},{"batl":[[0,1.08,1823.9],[1,1.09,8.54],[2,1.11,14.37]],"ltp":1.09,"tv":86545.55,"id":9028621}]}]}
{"op":"mcm","clk":"4226847451","pt":1631451813527,"mc":[{"id":"1.187552454","rc":[{"batb":[[0,12.5,15.21],[1,11.5,21.51],[2,7.8,254.9]],"batl":[[0,17.5,7.17],[1,18,2],[2,19,14.14]],"ltp":10.5,"tv":6249.12,"id":9345630},{"batl":[[2,1.1,6.9]],"ltp":1.09,"tv":86545.55,"id":9028621}]}]}
{"op":"mcm","clk":"4226847604","pt":1631451814344,"mc":[{"id":"1.187552454","rc":[{"trd":[[17.5,67.07]],"batb":[[0,12.5,7.21],[1,12,2],[2,11.5,23.51]],"batl":[[0,17.5,2]],"ltp":17.5,"tv":6257.12,"id":9345630},{"trd":[[1.06,1176.16]],"batb":[[0,1.06,2339.89],[1,1.05,510.61],[2,1.04,324.87]],"batl":[[0,1.08,1848.9],[1,1.09,68.54],[2,1.11,14.37]],"ltp":1.06,"tv":86581.55,"id":9028621}],"tv":92838.67}]}
{"op":"mcm","clk":"4226847731","pt":1631451815047,"mc":[{"id":"1.187552454","rc":[{"batb":[[0,12.5,2]],"batl":[[2,20,36.64]],"ltp":17.5,"tv":6257.12,"id":9345630},{"batb":[[1,1.05,242.29]],"batl":[[1,1.11,14.37],[2,1.13,7.06]],"ltp":1.06,"tv":86581.55,"id":9028621}]}]}
{"op":"mcm","clk":"4226847956","pt":1631451816444,"mc":[{"id":"1.187552454","rc":[{"trd":[[1.08,1746.04]],"batl":[[0,1.07,24.3],[1,1.08,1844.99],[2,1.11,14.37]],"ltp":1.08,"tv":86589.38,"id":9028621}],"tv":92846.5}]}
{"op":"mcm","clk":"4226848147","pt":1631451817463,"mc":[{"id":"1.187552454","rc":[{"batb":[[0,13,15.26],[1,12.5,2],[2,12,2]],"batl":[[0,17,2],[1,17.5,2],[2,18,2]],"ltp":17.5,"tv":6257.12,"id":9345630},{"batl":[[0,1.08,1991.91],[1,1.11,14.37],[2,1.13,7.06]],"ltp":1.08,"tv":86589.38,"id":9028621}]}]}
{"op":"mcm","clk":"4226848341","pt":1631451818467,"mc":[{"id":"1.187552454","rc":[{"batl":[[0,17,7.35]],"ltp":17.5,"tv":6257.12,"id":9345630},{"batb":[[1,1.05,510.61]],"batl":[[1,1.09,60],[2,1.11,14.37]],"ltp":1.08,"tv":86589.38,"id":9028621}]}]}
{"op":"mcm","clk":"4226848446","pt":1631451819049,"mc":[{"id":"1.187552454","rc":[{"batl":[[0,17,2]],"ltp":17.5,"tv":6257.12,"id":9345630}]}]}
{"op":"mcm","clk":"4226848669","pt":1631451820246,"mc":[{"id":"1.187552454","rc":[{"batl":[[0,16.5,2],[1,17,2],[2,17.5,2]],"ltp":17.5,"tv":6257.12,"id":9345630}]}]}
{"op":"mcm","clk":"4226848871","pt":1631451821408,"mc":[{"id":"1.187552454","rc":[{"batb":[[0,13,20.26]],"ltp":17.5,"tv":6257.12,"id":9345630}]}]}
{"op":"mcm","clk":"4226848932","pt":1631451821821,"mc":[{"id":"1.187552454","rc":[{"batb":[[0,13,5]],"batl":[[0,16.5,7.35]],"ltp":17.5,"tv":6257.12,"id":9345630}]}]}
{"op":"mcm","clk":"4226849179","pt":1631451823383,"mc":[{"id":"1.187552454","rc":[{"batl":[[0,16,2],[1,16.5,7.35],[2,17,2]],"ltp":17.5,"tv":6257.12,"id":9345630},{"batb":[[0,1.07,439.94],[1,1.06,2339.89],[2,1.05,510.61]],"ltp":1.08,"tv":86589.38,"id":9028621}]}]}
{"op":"mcm","clk":"4226849422","pt":1631451824847,"mc":[{"id":"1.187552454","rc":[{"batb":[[0,13.5,15.26],[1,13,5],[2,12.5,2]],"ltp":17.5,"tv":6257.12,"id":9345630}]}]}
{"op":"mcm","clk":"4226850984","pt":1631451832449,"mc":[{"id":"1.187552454","rc":[{"trd":[[1.07,1567.2]],"batb":[[0,1.07,293.89]],"ltp":1.07,"tv":86881.46,"id":9028621}],"tv":93138.58}]}
{"op":"mcm","clk":"4226851062","pt":1631451832736,"mc":[{"id":"1.187552454","rc":[{"batl":[[1,16.5,5.35],[2,18,2]],"ltp":17.5,"tv":6257.12,"id":9345630}]}]}
{"op":"mcm","clk":"4226851400","pt":1631451834115,"mc":[{"id":"1.187552454","rc":[{"batb":[[0,1.07,782.46]],"ltp":1.07,"tv":86881.46,"id":9028621}]}]}
{"op":"mcm","clk":"4226851708","pt":1631451835529,"mc":[{"id":"1.187552454","rc":[{"trd":[[13.5,58.56]],"batb":[[0,13,5],[1,12.5,2],[2,11.5,21.51]],"ltp":13.5,"tv":6263.2,"id":9345630},{"batl":[[0,1.08,2003.54]],"ltp":1.07,"tv":86881.46,"id":9028621}],"tv":93144.66}]}
{"op":"mcm","clk":"4226852135","pt":1631451837416,"mc":[{"id":"1.187552454","rc":[{"trd":[[13.5,60.56]],"ltp":13.5,"tv":6265.2,"id":9345630},{"trd":[[1.07,1667.21],[1.08,1771.33]],"batb":[[0,1.07,732.45]],"batl":[[0,1.08,1978.4]],"ltp":1.08,"tv":87006.75,"id":9028621}],"tv":93271.95}]}
{"op":"mcm","clk":"4226852430","pt":1631451838514,"mc":[{"id":"1.187552454","rc":[{"batb":[[0,13.5,2],[1,13,7],[2,12.5,2]],"ltp":13.5,"tv":6265.2,"id":9345630}]}]}
{"op":"mcm","clk":"4226852587","pt":1631451839108,"mc":[{"id":"1.187552454","rc":[{"trd":[[1.07,1671.1]],"batb":[[0,1.07,730.51]],"ltp":1.07,"tv":87010.64,"id":9028621}],"tv":93275.84}]}
{"op":"mcm","clk":"4226853832","pt":1631451844522,"mc":[{"id":"1.187552454","rc":[{"batl":[[1,18.5,14.34],[2,20,36.64]],"ltp":13.5,"tv":6265.2,"id":9345630},{"batb":[[1,1.06,2031],[2,1.05,268.32]],"batl":[[0,1.08,1831.48],[2,1.14,2.35]],"ltp":1.07,"tv":87010.64,"id":9028621}]}]}
{"op":"mcm","clk":"4226854031","pt":1631451845422,"mc":[{"id":"1.187552454","rc":[{"batb":[[0,2.32,102.49],[1,1.01,30],[2,12.5,0]],"batl":[[0,20,36.64],[1,26,2],[2,55,2]],"ltp":13.5,"tv":6265.2,"id":9345630},{"batb":[[1,1.04,324.87],[2,1.03,471.83]],"batl":[[0,1.08,11.63],[1,1.14,2.35],[2,1.19,14.99]],"ltp":1.07,"tv":87010.64,"id":9028621}]}]}
{"op":"mcm","clk":"4226854291","pt":1631451846536,"mc":[{"id":"1.187552454","rc":[{"trd":[[1.07,1812.74]],"batb":[[0,1.07,659.69]],"batl":[[2,1.19,14.85]],"ltp":1.07,"tv":87152.28,"id":9028621}],"tv":93417.48}]}
{"op":"mcm","clk":"4226854645","pt":1631451848222,"mc":[{"id":"1.187552454","rc":[{"batb":[[1,1.05,1147.92],[2,1.04,1234.67]],"batl":[[1,1.09,488.26],[2,1.1,1472.09]],"ltp":1.07,"tv":87152.28,"id":9028621}]}]}
{"op":"mcm","clk":"4226854873","pt":1631451849259,"mc":[{"id":"1.187552454","rc":[{"batb":[[0,6.2,2],[1,6,3],[2,2.32,102.49]],"ltp":13.5,"tv":6265.2,"id":9345630},{"batb":[[0,1.07,171.12]],"ltp":1.07,"tv":87152.28,"id":9028621}]}]}
{"op":"mcm","clk":"4226856457","pt":1631451855869,"mc":[{"id":"1.187552454","rc":[{"trd":[[15.5,18.66],[20,101.85]],"batb":[[0,20,2.15],[1,6.2,2],[2,6,3]],"batl":[[0,26,2],[1,55,2],[2,1000,0.32]],"ltp":20.0,"tv":6350.3,"id":9345630},{"trd":[[1.07,1983.86]],"batb":[[0,1.05,1147.92],[1,1.04,1234.67],[2,1.03,517.75]],"ltp":1.07,"tv":87323.4,"id":9028621}],"tv":93673.71}]}
{"op":"mcm","clk":"4226856729","pt":1631451857033,"mc":[{"id":"1.187552454","rc":[{"batl":[[1,1.14,2.35],[2,1.19,14.85]],"ltp":1.07,"tv":87323.4,"id":9028621}]}]}
{"op":"mcm","clk":"4226857034","pt":1631451858036,"mc":[{"id":"1.187552454","rc":[{"batb":[[0,6.2,2],[1,6,3],[2,2.32,102.49]],"ltp":20.0,"tv":6350.3,"id":9345630}]}]}
{"op":"mcm","clk":"4226857444","pt":1631451859572,"mc":[{"id":"1.187552454","rc":[{"batb":[[0,16.5,115.91],[1,16,112.5],[2,15.5,112.5]],"batl":[[0,21,2],[1,26,2],[2,55,2]],"ltp":20.0,"tv":6350.3,"id":9345630},{"trd":[[1.05,1232.73]],"batb":[[0,1.05,733.9],[1,1.04,1247.67]],"batl":[[0,1.07,8.54],[1,1.08,11.63],[2,1.14,2.35]],"ltp":1.05,"tv":88177.45,"id":9028621}],"tv":94527.75}]}
{"op":"mcm","clk":"4226857637","pt":1631451860349,"mc":[{"id":"1.187552454","rc":[{"trd":[[21,30]],"batb":[[0,16.5,12.93],[1,16,12.53],[2,15.5,12.53]],"batl":[[0,26,2],[1,27,38.96],[2,28,37.81]],"ltp":21.0,"tv":6356.3,"id":9345630},{"trd":[[1.05,1272.73]],"batb":[[0,1.05,750.7]],"batl":[[0,1.06,1763.16],[1,1.07,8.54],[2,1.08,11.63]],"ltp":1.05,"tv":88217.45,"id":9028621}],"tv":94573.75}]}
{"op":"mcm","clk":"4226857964","pt":1631451861556,"mc":[{"id":"1.187552454","rc":[{"batl":[[0,25,12.24],[1,26,2],[2,27,38.96]],"ltp":21.0,"tv":6356.3,"id":9345630},{"batb":[[1,1.04,1547.67]],"batl":[[1,1.07,40.54],[2,1.08,71.63]],"ltp":1.05,"tv":88217.45,"id":9028621}]}]}
{"op":"mcm","clk":"4226858209","pt":1631451862569,"mc":[{"id":"1.187552454","rc":[{"batb":[[0,17,2],[1,16.5,14.93],[2,16,12.53]],"ltp":21.0,"tv":6356.3,"id":9345630},{"batb":[[0,1.05,984.79],[1,1.04,1787.47]],"batl":[[0,1.06,1954.54]],"ltp":1.05,"tv":88217.45,"id":9028621}]}]}
{"op":"mcm","clk":"4226858445","pt":1631451863563,"mc":[{"id":"1.187552454","rc":[{"batl":[[0,25,14.24]],"ltp":21.0,"tv":6356.3,"id":9345630}]}]}
{"op":"mcm","clk":"4226858658","pt":1631451864383,"mc":[{"id":"1.187552454","rc":[{"batl":[[2,1.08,11.63]],"ltp":1.05,"tv":88217.45,"id":9028621}]}]}
{"op":"mcm","clk":"4226858960","pt":1631451865475,"mc":[{"id":"1.187552454","rc":[{"batb":[[0,17,13.93],[2,16,16.53]],"batl":[[0,24,7.81],[1,25,14.24],[2,26,2]],"ltp":21.0,"tv":6356.3,"id":9345630},{"batl":[[0,1.06,2101.57]],"ltp":1.05,"tv":88217.45,"id":9028621}]}]}
{"op":"mcm","clk":"4226859231","pt":1631451866446,"mc":[{"id":"1.187552454","rc":[{"batb":[[0,17,2]],"ltp":21.0,"tv":6356.3,"id":9345630}]}]}
{"op":"mcm","clk":"4226859675","pt":1631451868458,"mc":[{"id":"1.187552454","rc":[{"trd":[[1.06,1176.56]],"batl":[[0,1.06,2101.37],[1,1.07,100.54]],"ltp":1.06,"tv":88217.85,"id":9028621}],"tv":94574.15}]}
{"op":"mcm","clk":"4226859931","pt":1631451869568,"mc":[{"id":"1.187552454","rc":[{"batb":[[0,17.5,11.93],[1,17,2],[2,16.5,14.93]],"ltp":21.0,"tv":6356.3,"id":9345630},{"batb":[[0,1.05,1473.35]],"ltp":1.06,"tv":88217.85,"id":9028621}]}]}
{"op":"mcm","clk":"4226860482","pt":1631451871487,"mc":[{"id":"1.187552454","rc":[{"trd":[[1.06,1180.54]],"batb":[[1,1.04,1774.47]],"batl":[[0,1.06,2099.38],[1,1.07,92]],"ltp":1.06,"tv":88221.82,"id":9028621}],"tv":94578.13}]}
{"op":"mcm","clk":"4226860748","pt":1631451872456,"mc":[{"id":"1.187552454","rc":[{"trd":[[1.05,1725.73]],"batb":[[0,1.05,1246.85]],"ltp":1.05,"tv":88674.82,"id":9028621}],"tv":95031.13}]}
{"op":"mcm","clk":"4226861258","pt":1631451874459,"mc":[{"id":"1.187552454","rc":[{"trd":[[1.05,2073.73]],"batb":[[0,1.05,1072.85]],"ltp":1.05,"tv":89022.82,"id":9028621}],"tv":95379.13}]}
{"op":"mcm","clk":"4226861485","pt":1631451875476,"mc":[{"id":"1.187552454","rc":[{"batb":[[2,16.5,12.93]],"ltp":21.0,"tv":6356.3,"id":9345630},{"batb":[[0,1.05,1646.97],[1,1.04,1948.03]],"batl":[[0,1.06,2220.02]],"ltp":1.05,"tv":89022.82,"id":9028621}]}]}
{"op":"mcm","clk":"4226861740","pt":1631451876491,"mc":[{"id":"1.187552454","rc":[{"batb":[[0,16,4],[1,15,79.63],[2,2.32,102.49]],"batl":[[0,25,12.24],[1,36,2],[2,55,2]],"ltp":21.0,"tv":6356.3,"id":9345630},{"batb":[[0,1.05,915.59],[1,1.04,300]],"batl":[[0,1.06,9],[1,1.07,60]],"ltp":1.05,"tv":89022.82,"id":9028621}]}]}
{"op":"mcm","clk":"4226861981","pt":1631451877472,"mc":[{"id":"1.187552454","rc":[{"trd":[[17.5,67.62]],"batb":[[0,15,79.63],[1,2.32,102.49],[2,1.01,30]],"batl":[[0,17.5,1.45]],"ltp":17.5,"tv":6356.85,"id":9345630},{"trd":[[1.06,1189.54]],"batb":[[1,1.03,517.75],[2,1.02,12082.96]],"batl":[[0,1.08,11.63],[1,1.14,2.35],[2,1.17,29.69]],"ltp":1.06,"tv":89031.82,"id":9028621}],"tv":95388.68}]}
{"op":"mcm","clk":"4226862154","pt":1631451878150,"mc":[{"id":"1.187552454","rc":[{"trd":[[17.5,69.07]],"batl":[[0,36,2],[1,55,2],[2,110,2]],"ltp":17.5,"tv":6358.3,"id":9345630},{"trd":[[1.05,2576.94],[1.06,1213.48]],"batb":[[0,1.05,663.98]],"ltp":1.05,"tv":89558.97,"id":9028621}],"tv":95917.28}]}
{"op":"mcm","clk":"4226862349","pt":1631451879175,"mc":[{"id":"1.187552454","rc":[{"batb":[[1,1.03,2709.95]],"batl":[[0,1.08,2102.34]],"ltp":1.05,"tv":89558.97,"id":9028621}]}]}
{"op":"mcm","clk":"4226862659","pt":1631451880461,"mc":[{"id":"1.187552454","rc":[{"batb":[[0,15.5,11.84],[1,15,79.63],[2,2.32,102.49]],"ltp":17.5,"tv":6358.3,"id":9345630},{"batb":[[0,1.05,427.02]],"ltp":1.05,"tv":89558.97,"id":9028621}]}]}
{"op":"mcm","clk":"4226862803","pt":1631451881159,"mc":[{"id":"1.187552454","rc":[{"batb":[[0,1.06,14.26],[1,1.05,427.02],[2,1.03,2709.95]],"batl":[[0,1.08,2123.34]],"ltp":1.05,"tv":89558.97,"id":9028621}]}]}
{"op":"mcm","clk":"4226863524","pt":1631451884585,"mc":[{"id":"1.187552454","rc":[{"trd":[[15,71.06],[15.5,42.35]],"batb":[[0,15,48.1],[1,2.32,102.49],[2,1.01,30]],"ltp":15.0,"tv":6445.06,"id":9345630}],"tv":96004.04}]}
{"op":"mcm","clk":"4226864060","pt":1631451887491,"mc":[{"id":"1.187552454","rc":[{"batb":[[0,1.05,427.02],[1,1.04,249.12]],"ltp":1.05,"tv":89558.97,"id":9028621}]}]}
{"op":"mcm","clk":"4226864333","pt":1631451888899,"mc":[{"id":"1.187552454","rc":[{"batb":[[2,1.03,517.75]],"batl":[[0,1.08,32.63]],"ltp":1.05,"tv":89558.97,"id":9028621}]}]}
{"op":"mcm","clk":"4226864874","pt":1631451891505,"mc":[{"id":"1.187552454","rc":[{"batl":[[0,1.07,4349.51],[1,1.08,32.63],[2,1.14,2.35]],"ltp":1.05,"tv":89558.97,"id":9028621}]}]}
{"op":"mcm","clk":"4226865093","pt":1631451892585,"mc":[{"id":"1.187552454","rc":[{"batb":[[1,1.04,2420.24]],"batl":[[0,1.06,2130.16]],"ltp":1.05,"tv":89558.97,"id":9028621}]}]}
{"op":"mcm","clk":"4226865151","pt":1631451892874,"mc":[{"id":"1.187552454","rc":[{"batb":[[0,17.5,14.29],[1,15,48.1],[2,2.32,102.49]],"batl":[[0,28,8.06],[1,36,2],[2,55,2]],"ltp":15.0,"tv":6445.06,"id":9345630},{"batl":[[0,1.06,2293.31]],"ltp":1.05,"tv":89558.97,"id":9028621}]}]}
{"op":"mcm","clk":"4226865587","pt":1631451895490,"mc":[{"id":"1.187552454","rc":[{"batb":[[0,15,48.1],[1,2.32,102.49],[2,1.01,30]],"batl":[[0,36,2],[1,55,2],[2,110,2]],"ltp":15.0,"tv":6445.06,"id":9345630},{"batb":[[1,1.04,249.12]],"batl":[[0,1.08,32.63],[1,1.14,2.35],[2,1.17,29.69]],"ltp":1.05,"tv":89558.97,"id":9028621}]}]}
{"op":"mcm","clk":"4226866116","pt":1631451898418,"mc":[{"id":"1.187552454","rc":[{"batb":[[2,1.03,2709.95]],"batl":[[0,1.08,2123.34]],"ltp":1.05,"tv":89558.97,"id":9028621}]}]}
{"op":"mcm","clk":"4226866418","pt":1631451900024,"mc":[{"id":"1.187552454","rc":[{"batl":[[0,55,2],[1,110,2],[2,1000,0.32]],"ltp":15.0,"tv":6445.06,"id":9345630},{"batb":[[0,1.04,249.12],[1,1.03,2238.12],[2,1.02,12082.96]],"batl":[[0,1.08,32.63]],"ltp":1.05,"tv":89558.97,"id":9028621}]}]}
{"op":"mcm","clk":"4226866898","pt":1631451902534,"mc":[{"id":"1.187552454","rc":[{"batb":[[0,21,5.59],[1,15,48.1],[2,2.32,102.49]],"ltp":15.0,"tv":6445.06,"id":9345630},{"batl":[[0,1.05,8.54],[1,1.08,32.63],[2,1.14,2.35]],"ltp":1.05,"tv":89558.97,"id":9028621}]}]}
{"op":"mcm","clk":"4226867120","pt":1631451903516,"mc":[{"id":"1.187552454","rc":[{"batb":[[0,21,12.09],[1,15.5,69.77],[2,15,48.1]],"ltp":15.0,"tv":6445.06,"id":9345630},{"trd":[[1.04,532.41]],"batb":[[0,1.03,2238.12],[1,1.02,12082.96],[2,1.01,1444.17]],"batl":[[0,1.04,1737.39],[1,1.05,8.54],[2,1.06,9]],"ltp":1.04,"tv":90057.21,"id":9028621}],"tv":96502.28}]}
{"op":"mcm","clk":"4226867308","pt":1631451904449,"mc":[{"id":"1.187552454","rc":[{"batb":[[0,27,28.91],[1,21,12.09],[2,20,85.25]],"batl":[[0,36,10.14],[1,55,2],[2,110,2]],"ltp":15.0,"tv":6445.06,"id":9345630},{"trd":[[1.04,632.41]],"batl":[[0,1.04,1687.39]],"ltp":1.04,"tv":90157.21,"id":9028621}],"tv":96602.28}]}
{"op":"mcm","clk":"4226867546","pt":1631451905590,"mc":[{"id":"1.187552454","rc":[{"batb":[[1,24,10.42],[2,21,12.09]],"batl":[[0,40,5.95]],"ltp":15.0,"tv":6445.06,"id":9345630},{"batl":[[0,1.04,1864.45]],"ltp":1.04,"tv":90157.21,"id":9028621}]}]}
{"op":"mcm","clk":"4226867754","pt":1631451906435,"mc":[{"id":"1.187552454","rc":[{"trd":[[26,45.11],[27,57.81]],"batb":[[0,21,12.09],[1,20,85.25],[2,19,3.33]],"batl":[[0,34,2],[1,40,5.95],[2,55,2]],"ltp":26.0,"tv":6547.99,"id":9345630},{"trd":[[1.04,2622.37]],"batb":[[0,1.03,2343.72],[1,1.02,12507.22]],"batl":[[0,1.04,442.18]],"ltp":1.04,"tv":92147.17,"id":9028621}],"tv":98695.17}]}
{"op":"mcm","clk":"4226867944","pt":1631451907246,"mc":[{"id":"1.187552454","rc":[{"batb":[[2,15.5,2]],"batl":[[1,55,2],[2,110,2]],"ltp":26.0,"tv":6547.99,"id":9345630}]}]}
{"op":"mcm","clk":"4226868218","pt":1631451908544,"mc":[{"id":"1.187552454","rc":[{"batb":[[0,26,10.85],[1,21,12.09],[2,20,85.25]],"batl":[[1,38,9.86],[2,50,2]],"ltp":26.0,"tv":6547.99,"id":9345630},{"batl":[[1,1.06,9],[2,1.08,47.4]],"ltp":1.04,"tv":92147.17,"id":9028621}]}]}
{"op":"mcm","clk":"4226868388","pt":1631451909366,"mc":[{"id":"1.187552454","rc":[{"batl":[[0,1.04,1087.79],[1,1.05,821.36],[2,1.06,9]],"ltp":1.04,"tv":92147.17,"id":9028621}]}]}
{"op":"mcm","clk":"4226868540","pt":1631451910030,"mc":[{"id":"1.187552454","rc":[{"batl":[[0,1.04,1324.12],[1,1.05,1014.3]],"ltp":1.04,"tv":92147.17,"id":9028621}]}]}
{"op":"mcm","clk":"4226868777","pt":1631451911149,"mc":[{"id":"1.187552454","rc":[{"batl":[[1,50,2],[2,55,2]],"ltp":26.0,"tv":6547.99,"id":9345630},{"trd":[[1.04,2662.37]],"batl":[[0,1.04,1304.12],[1,1.05,1074.3]],"ltp":1.04,"tv":92187.17,"id":9028621}],"tv":98735.17}]}
{"op":"mcm","clk":"4226868993","pt":1631451912361,"mc":[{"id":"1.187552454","rc":[{"batb":[[0,27,10.42],[1,26,10.85],[2,21,12.09]],"ltp":26.0,"tv":6547.99,"id":9345630},{"batl":[[1,1.05,1023.79]],"ltp":1.04,"tv":92187.17,"id":9028621}]}]}
{"op":"mcm","clk":"4226869249","pt":1631451913462,"mc":[{"id":"1.187552454","rc":[{"batb":[[0,27,5.17]],"ltp":26.0,"tv":6547.99,"id":9345630}]}]}
{"op":"mcm","clk":"4226869446","pt":1631451914373,"mc":[{"id":"1.187552454","rc":[{"batl":[[1,36,10.14],[2,50,2]],"ltp":26.0,"tv":6547.99,"id":9345630},{"trd":[[1.04,2696.59]],"batl":[[0,1.04,1287.01]],"ltp":1.04,"tv":92221.39,"id":9028621}],"tv":98769.38}]}
{"op":"mcm","clk":"4226869626","pt":1631451915265,"mc":[{"id":"1.187552454","rc":[{"trd":[[1.03,1.01],[1.04,2719.55]],"batb":[[0,1.03,2343.22]],"batl":[[0,1.04,1346.53]],"ltp":1.04,"tv":92245.37,"id":9028621}],"tv":98793.36}]}
{"op":"mcm","clk":"4226869895","pt":1631451916554,"mc":[{"id":"1.187552454","rc":[{"batl":[[0,34,7.95]],"ltp":26.0,"tv":6547.99,"id":9345630}]}]}
{"op":"mcm","clk":"4226870075","pt":1631451917572,"mc":[{"id":"1.187552454","rc":[{"batb":[[2,20,85.25]],"batl":[[0,34,4.93]],"ltp":26.0,"tv":6547.99,"id":9345630}]}]}
{"op":"mcm","clk":"4226870163","pt":1631451918067,"mc":[{"id":"1.187552454","rc":[{"batb":[[0,26,10.85],[1,20,85.25],[2,15.5,2]],"batl":[[0,36,10.14],[1,110,2],[2,160,36.78]],"ltp":26.0,"tv":6547.99,"id":9345630},{"batb":[[0,1.03,45.42],[1,1.02,429.26]],"batl":[[0,1.05,60],[1,1.06,9],[2,1.08,32.63]],"ltp":1.04,"tv":92245.37,"id":9028621}]}]}
{"op":"mcm","clk":"4226870421","pt":1631451919462,"mc":[{"id":"1.187552454","rc":[{"batl":[[0,110,2],[1,160,36.78],[2,1000,0.32]],"ltp":26.0,"tv":6547.99,"id":9345630},{"batb":[[1,1.02,5]],"batl":[[0,1.08,32.63],[1,1.13,14.85],[2,1.14,2.35]],"ltp":1.04,"tv":92245.37,"id":9028621}]}]}
{"op":"mcm","clk":"4226870575","pt":1631451920252,"mc":[{"id":"1.187552454","rc":[{"batl":[[0,160,36.78],[1,1000,0.32],[2,1000,0]],"ltp":26.0,"tv":6547.99,"id":9345630},{"batb":[[2,1.01,30]],"ltp":1.04,"tv":92245.37,"id":9028621}]}]}
{"op":"mcm","clk":"4226870842","pt":1631451921562,"mc":[{"id":"1.187552454","rc":[{"batb":[[1,19.5,89.1]],"ltp":26.0,"tv":6547.99,"id":9345630}]}]}
{"op":"mcm","clk":"4226871206","pt":1631451923462,"mc":[{"id":"1.187552454","rc":[{"batl":[[0,110,2],[1,160,36.78],[2,1000,0.32]],"ltp":26.0,"tv":6547.99,"id":9345630},{"batb":[[2,1.01,1277.88]],"ltp":1.04,"tv":92245.37,"id":9028621}]}]}
{"op":"mcm","clk":"4226871399","pt":1631451924558,"mc":[{"id":"1.187552454","rc":[{"batl":[[0,1000,0.32],[1,160,0],[2,1000,0]],"ltp":26.0,"tv":6547.99,"id":9345630},{"batb":[[0,1.03,2237.62],[2,1.01,30]],"batl":[[0,1.04,2171.12],[1,1.08,32.63],[2,1.13,14.85]],"ltp":1.04,"tv":92245.37,"id":9028621}]}]}
{"op":"mcm","clk":"4226871484","pt":1631451925074,"mc":[{"id":"1.187552454","rc":[{"trd":[[1.04,2722.59]],"batb":[[0,1.03,2192.2]],"batl":[[0,1.04,2169.6]],"ltp":1.04,"tv":92248.41,"id":9028621}],"tv":98796.4}]}
{"op":"mcm","clk":"4226871756","pt":1631451926561,"mc":[{"id":"1.187552454","rc":[{"batb":[[0,27,7.97],[1,26,10.85],[2,19.5,89.1]],"batl":[[0,42,1.65],[1,1000,0.32]],"ltp":26.0,"tv":6547.99,"id":9345630},{"trd":[[1.04,2924.18]],"batb":[[0,1.03,2239.61]],"batl":[[0,1.04,2231.96]],"ltp":1.04,"tv":92449.99,"id":9028621}],"tv":98997.98}]}
{"op":"mcm","clk":"4226871972","pt":1631451927765,"mc":[{"id":"1.187552454","rc":[{"batb":[[2,22,14.21]],"batl":[[1,110,2],[2,1000,0.32]],"ltp":26.0,"tv":6547.99,"id":9345630},{"batb":[[2,1.01,1281.51]],"ltp":1.04,"tv":92449.99,"id":9028621}]}]}
{"op":"mcm","clk":"4226872338","pt":1631451929573,"mc":[{"id":"1.187552454","rc":[{"batb":[[0,26,10.85],[1,22,14.21],[2,19.5,89.1]],"batl":[[0,520,35.68],[1,1000,0.32],[2,1000,0]],"ltp":26.0,"tv":6547.99,"id":9345630},{"batb":[[0,1.02,5],[1,1.01,30],[2,1.01,0]],"batl":[[0,1.04,101.52]],"ltp":1.04,"tv":92449.99,"id":9028621}]}]}
{"op":"mcm","clk":"4226872511","pt":1631451930568,"mc":[{"id":"1.187552454","rc":[{"batl":[[0,520,36.66]],"ltp":26.0,"tv":6547.99,"id":9345630},{"batl":[[0,1.08,32.63],[1,1.13,14.85],[2,1.14,2.35]],"ltp":1.04,"tv":92449.99,"id":9028621}]}]}
{"op":"mcm","clk":"4226872715","pt":1631451931577,"mc":[{"id":"1.187552454","rc":[{"batb":[[0,1.02,1789.22],[1,1.01,463.72]],"batl":[[0,1.05,25.26],[1,1.06,2130.16],[2,1.08,32.63]],"ltp":1.04,"tv":92449.99,"id":9028621}]}]}
{"op":"mcm","clk":"4226872843","pt":1631451932171,"mc":[{"id":"1.187552454","rc":[{"batl":[[0,110,2.98],[1,520,35.68],[2,1000,0.32]],"ltp":26.0,"tv":6547.99,"id":9345630},{"batb":[[1,1.01,1577.52]],"ltp":1.04,"tv":92449.99,"id":9028621}]}]}
{"op":"mcm","clk":"4226873035","pt":1631451933179,"mc":[{"id":"1.187552454","rc":[{"trd":[[19.5,164.68],[21,31.26],[22,28.43],[26,45.27]],"batb":[[0,19.5,6.81],[1,15.5,2],[2,2.32,102.49]],"ltp":19.5,"tv":6742.41,"id":9345630},{"trd":[[1.04,2928.08],[1.05,2602.19]],"batb":[[0,1.02,2228.97]],"batl":[[0,1.06,2130.16],[1,1.08,32.63],[2,1.13,14.85]],"ltp":1.05,"tv":92479.15,"id":9028621}],"tv":99221.56}]}
{"op":"mcm","clk":"4226873617","pt":1631451936463,"mc":[{"id":"1.187552454","rc":[{"batb":[[0,19.5,8.81],[1,19,2],[2,15.5,2]],"ltp":19.5,"tv":6742.41,"id":9345630},{"batl":[[0,1.06,2160.16]],"ltp":1.05,"tv":92479.15,"id":9028621}]}]}
{"op":"mcm","clk":"4226873790","pt":1631451937583,"mc":[{"id":"1.187552454","rc":[{"batb":[[1,1.01,1715.29]],"ltp":1.05,"tv":92479.15,"id":9028621}]}]}
{"op":"mcm","clk":"4226874104","pt":1631451939197,"mc":[{"id":"1.187552454","rc":[{"batb":[[0,1.02,444.75],[1,1.01,1281.57]],"ltp":1.05,"tv":92479.15,"id":9028621}]}]}
{"op":"mcm","clk":"4226874370","pt":1631451940567,"mc":[{"id":"1.187552454","rc":[{"batb":[[0,19.5,2]],"batl":[[0,32,58.76],[1,110,2],[2,520,35.68]],"ltp":19.5,"tv":6742.41,"id":9345630}]}]}
{"op":"mcm","clk":"4226874580","pt":1631451941571,"mc":[{"id":"1.187552454","rc":[{"batb":[[0,15.5,2],[1,2.32,102.49],[2,1.01,30]],"batl":[[0,19.5,8.54],[1,32,3.87],[2,110,2]],"ltp":19.5,"tv":6742.41,"id":9345630}]}]}
{"op":"mcm","clk":"4226874744","pt":1631451942363,"mc":[{"id":"1.187552454","rc":[{"batl":[[1,26,2],[2,32,17.39]],"ltp":19.5,"tv":6742.41,"id":9345630},{"batb":[[0,1.04,2266.74],[1,1.02,444.75],[2,1.01,1305.26]],"batl":[[2,1.09,14.64]],"ltp":1.05,"tv":92479.15,"id":9028621}]}]}
{"op":"mcm","clk":"4226874980","pt":1631451943590,"mc":[{"id":"1.187552454","rc":[{"trd":[[19.5,174.66]],"batb":[[0,18.5,48.82],[1,17,3.75],[2,15.5,2]],"batl":[[0,19.5,3.55],[2,27,11.76]],"ltp":19.5,"tv":6752.39,"id":9345630},{"batb":[[0,1.04,9536.8],[1,1.03,346.41],[2,1.02,13808.34]],"batl":[[0,1.06,2395.75],[1,1.07,60],[2,1.08,32.63]],"ltp":1.05,"tv":92479.15,"id":9028621}],"tv":99231.54}]}
{"op":"mcm","clk":"4226875138","pt":1631451944489,"mc":[{"id":"1.187552454","rc":[{"batb":[[1,18,2],[2,17.5,2]],"batl":[[1,25,2],[2,26,2]],"ltp":19.5,"tv":6752.39,"id":9345630},{"batb":[[0,1.04,9590.8],[1,1.03,415.41]],"ltp":1.05,"tv":92479.15,"id":9028621}]}]}
{"op":"mcm","clk":"4226875329","pt":1631451945574,"mc":[{"id":"1.187552454","rc":[{"batb":[[0,1.04,9625.24],[1,1.03,114.92]],"ltp":1.05,"tv":92479.15,"id":9028621}]}]}
{"op":"mcm","clk":"4226875645","pt":1631451947398,"mc":[{"id":"1.187552454","rc":[{"trd":[[19.5,181.77]],"batb":[[0,19.5,36.14],[1,18.5,48.82],[2,18,2]],"batl":[[0,25,2],[1,26,2],[2,30,2]],"ltp":19.5,"tv":6759.49,"id":9345630},{"batb":[[0,1.04,9867.96]],"ltp":1.05,"tv":92479.15,"id":9028621}],"tv":99238.65}]}
{"op":"mcm","clk":"4226875872","pt":1631451948596,"mc":[{"id":"1.187552454","rc":[{"batb":[[2,1.02,14438.08]],"ltp":1.05,"tv":92479.15,"id":9028621}]}]}
{"op":"mcm","clk":"4226875961","pt":1631451949084,"mc":[{"id":"1.187552454","rc":[{"trd":[[1.04,2931.49]],"batb":[[0,1.04,10166.25]],"batl":[[2,1.08,11.63]],"ltp":1.04,"tv":92482.57,"id":9028621}],"tv":99242.06}]}
{"op":"mcm","clk":"4226876204","pt":1631451950385,"mc":[{"id":"1.187552454","rc":[{"batl":[[0,24,2],[1,25,2],[2,26,14]],"ltp":19.5,"tv":6759.49,"id":9345630},{"trd":[[1.04,3378.01]],"batb":[[0,1.04,9942.99]],"ltp":1.04,"tv":92929.09,"id":9028621}],"tv":99688.58}]}
{"op":"mcm","clk":"4226876775","pt":1631451953431,"mc":[{"id":"1.187552454","rc":[{"batl":[[0,23,10.04],[1,24,2],[2,25,2]],"ltp":19.5,"tv":6759.49,"id":9345630}]}]}
{"op":"mcm","clk":"4226876830","pt":1631451953753,"mc":[{"id":"1.187552454","rc":[{"batl":[[0,23,4.53]],"ltp":19.5,"tv":6759.49,"id":9345630},{"batb":[[0,1.04,10167.96]],"ltp":1.04,"tv":92929.09,"id":9028621}]}]}
{"op":"mcm","clk":"4226877281","pt":1631451956039,"mc":[{"id":"1.187552454","rc":[{"trd":[[23,7.23]],"batl":[[0,24,2.92],[1,26,14],[2,32,18.41]],"ltp":23.0,"tv":6766.72,"id":9345630},{"batb":[[1,1.03,45.92],[2,1.02,13998.33]],"ltp":1.04,"tv":92929.09,"id":9028621}],"tv":99695.81}]}
{"op":"mcm","clk":"4226877895","pt":1631451959367,"mc":[{"id":"1.187552454","rc":[{"batb":[[1,1.03,485.68]],"ltp":1.04,"tv":92929.09,"id":9028621}]}]}
{"op":"mcm","clk":"4226878533","pt":1631451962447,"mc":[{"id":"1.187552454","rc":[{"trd":[[1.04,3378.41]],"batb":[[0,1.04,10167.76]],"ltp":1.04,"tv":92929.49,"id":9028621}],"tv":99696.21}]}
{"op":"mcm","clk":"4226878667","pt":1631451963160,"mc":[{"id":"1.187552454","rc":[{"batb":[[0,20,4.72],[1,19.5,36.14],[2,18.5,48.82]],"ltp":23.0,"tv":6766.72,"id":9345630}]}]}
{"op":"mcm","clk":"4226878926","pt":1631451964473,"mc":[{"id":"1.187552454","rc":[{"batl":[[2,32,2]],"ltp":23.0,"tv":6766.72,"id":9345630}]}]}
{"op":"mcm","clk":"4226879072","pt":1631451965188,"mc":[{"id":"1.187552454","rc":[{"batb":[[0,19.5,36.14],[1,17,3.75],[2,13.5,93.95]],"batl":[[0,26,12],[1,55,2],[2,110,2]],"ltp":23.0,"tv":6766.72,"id":9345630},{"batb":[[0,1.04,334.44]],"batl":[[0,1.07,60],[1,1.08,11.63],[2,1.13,14.85]],"ltp":1.04,"tv":92929.49,"id":9028621}]}]}
{"op":"mcm","clk":"4226879314","pt":1631451966496,"mc":[{"id":"1.187552454","rc":[{"batb":[[1,13.5,93.95],[2,2.32,102.49]],"batl":[[0,55,2],[1,110,2],[2,1000,0.32]],"ltp":23.0,"tv":6766.72,"id":9345630},{"batb":[[0,1.03,485.68],[1,1.02,13998.33],[2,1.01,5074.92]],"batl":[[0,1.08,11.63],[1,1.13,14.85],[2,1.14,2.35]],"ltp":1.04,"tv":92929.49,"id":9028621}]}]}
{"op":"mcm","clk":"4226879528","pt":1631451967584,"mc":[{"id":"1.187552454","rc":[{"batb":[[0,24,6.94],[1,19.5,36.14],[2,13.5,93.95]],"ltp":23.0,"tv":6766.72,"id":9345630},{"batb":[[1,1.02,16212.02],[2,1.01,1281.57]],"batl":[[0,1.08,2102.34]],"ltp":1.04,"tv":92929.49,"id":9028621}]}]}
{"op":"mcm","clk":"4226879820","pt":1631451969060,"mc":[{"id":"1.187552454","rc":[{"batb":[[0,19.5,36.14],[1,13.5,93.95],[2,2.32,102.49]],"ltp":23.0,"tv":6766.72,"id":9345630}]}]}
{"op":"mcm","clk":"4226881051","pt":1631451975281,"mc":[{"id":"1.187552454","rc":[{"trd":[[36,4.63]],"ltp":36.0,"tv":6771.35,"id":9345630},{"trd":[[1.03,162.8]],"batb":[[0,1.03,323.89]],"batl":[[0,1.04,37.07],[1,1.08,2102.34],[2,1.13,14.85]],"ltp":1.03,"tv":93091.27,"id":9028621}],"tv":99862.62}]}
{"op":"mcm","clk":"4226881235","pt":1631451976204,"mc":[{"id":"1.187552454","rc":[{"batb":[[1,1.02,13998.33]],"batl":[[1,1.08,11.63]],"ltp":1.03,"tv":93091.27,"id":9028621}]}]}
{"op":"mcm","clk":"4226881333","pt":1631451976693,"mc":[{"id":"1.187552454","rc":[{"batl":[[0,1.04,36.73]],"ltp":1.03,"tv":93091.27,"id":9028621}]}]}
{"op":"mcm","clk":"4226881850","pt":1631451979488,"mc":[{"id":"1.187552454","rc":[{"batb":[[0,1.04,2171.12],[1,1.03,323.89],[2,1.02,13998.33]],"batl":[[0,1.05,1251.08],[1,1.06,910.12],[2,1.08,11.63]],"ltp":1.03,"tv":93091.27,"id":9028621}]}]}
{"op":"mcm","clk":"4226881950","pt":1631451980052,"mc":[{"id":"1.187552454","rc":[{"batb":[[0,20,9.79],[1,19.5,36.14],[2,13.5,93.95]],"batl":[[0,30,7.19],[1,55,2],[2,110,2]],"ltp":36.0,"tv":6771.35,"id":9345630},{"batb":[[0,1.04,2256.87]],"batl":[[1,1.06,890.87]],"ltp":1.03,"tv":93091.27,"id":9028621}]}]}
{"op":"mcm","clk":"4226882337","pt":1631451982283,"mc":[{"id":"1.187552454","rc":[{"batl":[[0,1.05,1381.47]],"ltp":1.03,"tv":93091.27,"id":9028621}]}]}
{"op":"mcm","clk":"4226883099","pt":1631451986391,"mc":[{"id":"1.187552454","rc":[{"batb":[[0,19.5,36.14],[1,13.5,93.95],[2,2.32,102.49]],"batl":[[0,55,2],[1,110,2],[2,1000,0.32]],"ltp":36.0,"tv":6771.35,"id":9345630},{"batb":[[0,1.03,323.89],[1,1.02,13998.33],[2,1.01,1143.8]],"batl":[[0,1.08,11.63],[1,1.13,15.57],[2,1.14,2.35]],"ltp":1.03,"tv":93091.27,"id":9028621}]}]}
{"op":"mcm","clk":"4226883691","pt":1631451989580,"mc":[{"id":"1.187552454","rc":[{"batb":[[1,1.02,16212.02]],"batl":[[0,1.08,2126.34]],"ltp":1.03,"tv":93091.27,"id":9028621}]}]}
{"op":"mcm","clk":"4226884120","pt":1631451992026,"mc":[{"id":"1.187552454","rc":[{"batl":[[0,1.08,35.63]],"ltp":1.03,"tv":93091.27,"id":9028621}]}]}
{"op":"mcm","clk":"4226884497","pt":1631451994109,"mc":[{"id":"1.187552454","rc":[{"batb":[[0,23,4.3],[1,19.5,36.14],[2,13.5,93.95]],"ltp":36.0,"tv":6771.35,"id":9345630},{"batb":[[0,1.02,16212.02],[1,1.01,1143.8],[2,1.01,0]],"batl":[[0,1.03,8.54],[1,1.08,35.63],[2,1.13,15.57]],"ltp":1.03,"tv":93091.27,"id":9028621}]}]}
{"op":"mcm","clk":"4226884796","pt":1631451995582,"mc":[{"id":"1.187552454","rc":[{"batb":[[0,23,10.21],[1,21,81.26],[2,19.5,36.14]],"ltp":36.0,"tv":6771.35,"id":9345630},{"batl":[[1,1.04,2171.12],[2,1.07,417.87]],"ltp":1.03,"tv":93091.27,"id":9028621}]}]}
{"op":"mcm","clk":"4226884991","pt":1631451996499,"mc":[{"id":"1.187552454","rc":[{"batb":[[0,29,39.56],[1,23,10.21],[2,21,150.23]],"batl":[[0,48,8.75],[1,55,2],[2,110,2]],"ltp":36.0,"tv":6771.35,"id":9345630},{"batl":[[2,1.05,60]],"ltp":1.03,"tv":93091.27,"id":9028621}]}]}
{"op":"mcm","clk":"4226885181","pt":1631451997521,"mc":[{"id":"1.187552454","rc":[{"batb":[[0,30,8.33],[1,29,39.56],[2,23,10.21]],"batl":[[1,50,2],[2,55,2]],"ltp":36.0,"tv":6771.35,"id":9345630},{"batb":[[0,1.02,16881.38]],"batl":[[0,1.03,97.17]],"ltp":1.03,"tv":93091.27,"id":9028621}]}]}
{"op":"mcm","clk":"4226885757","pt":1631452000303,"mc":[{"id":"1.187552454","rc":[{"batl":[[0,46,2],[1,48,8.75],[2,50,2]],"ltp":36.0,"tv":6771.35,"id":9345630}]}]}
{"op":"mcm","clk":"4226885944","pt":1631452001222,"mc":[{"id":"1.187552454","rc":[{"trd":[[1.03,166.8]],"batl":[[0,1.03,86.62]],"ltp":1.03,"tv":93095.27,"id":9028621}],"tv":99866.62}]}
{"op":"mcm","clk":"4226886148","pt":1631452002363,"mc":[{"id":"1.187552454","rc":[{"batl":[[1,50,2],[2,55,2]],"ltp":36.0,"tv":6771.35,"id":9345630}]}]}
{"op":"mcm","clk":"4226886400","pt":1631452003537,"mc":[{"id":"1.187552454","rc":[{"batl":[[0,44,2],[1,46,2],[2,50,2]],"ltp":36.0,"tv":6771.35,"id":9345630},{"batb":[[1,1.01,1281.57]],"ltp":1.03,"tv":93095.27,"id":9028621}]}]}
{"op":"mcm","clk":"4226886765","pt":1631452005529,"mc":[{"id":"1.187552454","rc":[{"batl":[[0,44,11.14]],"ltp":36.0,"tv":6771.35,"id":9345630},{"trd":[[1.03,340.05]],"batb":[[0,1.03,89.28],[1,1.02,16881.38],[2,1.01,1281.57]],"batl":[[0,1.04,2171.12],[1,1.05,60],[2,1.07,23.91]],"ltp":1.03,"tv":93268.52,"id":9028621}],"tv":100039.88}]}
{"op":"mcm","clk":"4226886932","pt":1631452006432,"mc":[{"id":"1.187552454","rc":[{"trd":[[36,7.51],[42,4],[44,7.58]],"batl":[[0,44,7.35]],"ltp":44.0,"tv":6785.81,"id":9345630},{"trd":[[1.03,440.81]],"batb":[[0,1.02,16881.38],[1,1.01,1281.57],[2,1.01,0]],"ltp":1.03,"tv":93369.28,"id":9028621}],"tv":100155.1}]}
{"op":"mcm","clk":"4226887092","pt":1631452007398,"mc":[{"id":"1.187552454","rc":[{"batl":[[0,42,4.29],[1,44,7.35],[2,46,2]],"ltp":44.0,"tv":6785.81,"id":9345630}]}]}
{"op":"mcm","clk":"4226887399","pt":1631452009455,"mc":[{"id":"1.187552454","rc":[{"batb":[[0,21,68.97],[1,20,2],[2,19.5,36.14]],"batl":[[0,44,7.35],[1,55,2],[2,110,2]],"ltp":44.0,"tv":6785.81,"id":9345630},{"batb":[[0,1.02,1059]],"batl":[[0,1.05,60],[1,1.08,35.63],[2,1.11,11.88]],"ltp":1.03,"tv":93369.28,"id":9028621}]}]}
{"op":"mcm","clk":"4226887581","pt":1631452010529,"mc":[{"id":"1.187552454","rc":[{"batl":[[0,55,2],[1,110,2],[2,1000,0.32]],"ltp":44.0,"tv":6785.81,"id":9345630},{"batb":[[0,1.02,634.74]],"batl":[[0,1.08,35.63],[1,1.11,11.88],[2,1.13,15.57]],"ltp":1.03,"tv":93369.28,"id":9028621}]}]}
{"op":"mcm","clk":"4226887704","pt":1631452011228,"mc":[{"id":"1.187552454","rc":[{"batl":[[0,1000,0.32],[1,110,0],[2,1000,0]],"ltp":44.0,"tv":6785.81,"id":9345630},{"batb":[[0,1.02,5],[1,1.01,167.77]],"ltp":1.03,"tv":93369.28,"id":9028621}]}]}
{"op":"mcm","clk":"4226887907","pt":1631452012423,"mc":[{"id":"1.187552454","rc":[{"batb":[[1,1.01,2403.38]],"batl":[[0,1.05,2150.44],[1,1.08,35.63],[2,1.11,11.88]],"ltp":1.03,"tv":93369.28,"id":9028621}]}]}
{"op":"mcm","clk":"4226888138","pt":1631452013724,"mc":[{"id":"1.187552454","rc":[{"batl":[[1,1.06,34],[2,1.08,35.63]],"ltp":1.03,"tv":93369.28,"id":9028621}]}]}
{"op":"mcm","clk":"4226888315","pt":1631452014627,"mc":[{"id":"1.187552454","rc":[{"batl":[[0,1000,0.91]],"ltp":44.0,"tv":6785.81,"id":9345630}]}]}
{"op":"mcm","clk":"4226888546","pt":1631452016120,"mc":[{"id":"1.187552454","rc":[{"batl":[[0,1.06,34],[1,1.08,35.63],[2,1.11,11.88]],"ltp":1.03,"tv":93369.28,"id":9028621}]}]}
{"op":"mcm","clk":"4226888764","pt":1631452017457,"mc":[{"id":"1.187552454","rc":[{"batl":[[0,50,63.95],[1,1000,0.91]],"ltp":44.0,"tv":6785.81,"id":9345630}]}]}
{"op":"mcm","clk":"4226888984","pt":1631452018541,"mc":[{"id":"1.187552454","rc":[{"trd":[[50,8.78]],"batl":[[0,50,55.17]],"ltp":50.0,"tv":6794.6,"id":9345630},{"trd":[[1.02,440.56]],"batb":[[0,1.01,2403.38],[1,1.01,0]],"ltp":1.02,"tv":93809.85,"id":9028621}],"tv":100604.45}]}
{"op":"mcm","clk":"4226889139","pt":1631452019456,"mc":[{"id":"1.187552454","rc":[{"trd":[[50,58.34]],"batl":[[0,50,7.61]],"ltp":50.0,"tv":6844.15,"id":9345630},{"trd":[[1.02,2673.6]],"batb":[[0,1.01,2541.15]],"batl":[[0,1.03,236.47],[1,1.06,456.04],[2,1.08,43.01]],"ltp":1.02,"tv":96042.89,"id":9028621}],"tv":102887.04}]}
{"op":"mcm","clk":"4226889345","pt":1631452020523,"mc":[{"id":"1.187552454","rc":[{"batb":[[0,30,24.49]],"batl":[[1,90,6.35],[2,1000,0.91]],"ltp":50.0,"tv":6844.15,"id":9345630},{"batb":[[0,1.01,3141.15]],"batl":[[0,1.03,272.62],[1,1.04,60],[2,1.06,49.05]],"ltp":1.02,"tv":96042.89,"id":9028621}]}]}
{"op":"mcm","clk":"4226889501","pt":1631452021341,"mc":[{"id":"1.187552454","rc":[{"trd":[[50,62.63]],"batb":[[0,48,2],[1,30,24.49],[2,20,2]],"batl":[[0,50,5.32],[1,1000,0.91],[2,1000,0]],"ltp":50.0,"tv":6848.44,"id":9345630},{"trd":[[1.02,2688]],"batb":[[0,1.01,2541.15]],"batl":[[1,1.04,42]],"ltp":1.02,"tv":96057.28,"id":9028621}],"tv":102905.73}]}
{"op":"mcm","clk":"4226889710","pt":1631452022357,"mc":[{"id":"1.187552454","rc":[{"trd":[[50,67.95]],"batl":[[0,1000,0.91],[1,1000,0]],"ltp":50.0,"tv":6853.76,"id":9345630},{"trd":[[1.02,2948.8],[1.03,442.14]],"batl":[[0,1.02,1952.89],[1,1.03,271.95],[2,1.04,42]],"ltp":1.02,"tv":96319.42,"id":9028621}],"tv":103173.18}]}
{"op":"mcm","clk":"4226889902","pt":1631452023352,"mc":[{"id":"1.187552454","rc":[{"trd":[[50,72.22]],"ltp":50.0,"tv":6858.03,"id":9345630},{"trd":[[1.02,3158.12]],"batl":[[0,1.02,1743.57]],"ltp":1.02,"tv":96528.74,"id":9028621}],"tv":103386.77}]}
{"op":"mcm","clk":"4226890040","pt":1631452024034,"mc":[{"id":"1.187552454","rc":[{"batb":[[0,50,21.69],[1,48,2],[2,30,24.49]],"ltp":50.0,"tv":6858.03,"id":9345630}]}]}
{"op":"mcm","clk":"4226890313","pt":1631452025558,"mc":[{"id":"1.187552454","rc":[{"batb":[[0,75,3.33]],"batl":[[0,130,1.92],[1,1000,0.91]],"ltp":50.0,"tv":6858.03,"id":9345630},{"batl":[[0,1.02,1988.67],[1,1.03,235.8]],"ltp":1.02,"tv":96528.74,"id":9028621}]}]}
{"op":"mcm","clk":"4226890488","pt":1631452026571,"mc":[{"id":"1.187552454","rc":[{"batb":[[0,48,2],[1,30,24.49],[2,20,2]],"ltp":50.0,"tv":6858.03,"id":9345630},{"batb":[[0,1.01,2868.43]],"batl":[[0,1.02,2249.47]],"ltp":1.02,"tv":96528.74,"id":9028621}]}]}
{"op":"mcm","clk":"4226890544","pt":1631452026830,"mc":[{"id":"1.187552454","rc":[{"batl":[[0,1.02,2458.79]],"ltp":1.02,"tv":96528.74,"id":9028621}]}]}
{"op":"mcm","clk":"4226890820","pt":1631452028550,"mc":[{"id":"1.187552454","rc":[{"batl":[[0,1.02,2494.94]],"ltp":1.02,"tv":96528.74,"id":9028621}]}]}
{"op":"mcm","clk":"4226891254","pt":1631452031054,"mc":[{"id":"1.187552454","rc":[{"trd":[[1.02,3158.51]],"batl":[[0,1.02,2494.74]],"ltp":1.02,"tv":96529.13,"id":9028621}],"tv":103387.17}]}
{"op":"mcm","clk":"4226891555","pt":1631452032557,"mc":[{"id":"1.187552454","rc":[{"batb":[[0,70,3.57],[1,48,2],[2,30,24.49]],"ltp":50.0,"tv":6858.03,"id":9345630},{"batl":[[0,1.02,5153.75]],"ltp":1.02,"tv":96529.13,"id":9028621}]}]}
{"op":"mcm","clk":"4226892166","pt":1631452035574,"mc":[{"id":"1.187552454","rc":[{"trd":[[70,4]],"batb":[[0,70,1.57]],"ltp":70.0,"tv":6862.03,"id":9345630},{"trd":[[1.01,1208.41]],"batb":[[0,1.01,2264.23]],"ltp":1.01,"tv":97737.54,"id":9028621}],"tv":104599.58}]}
{"op":"mcm","clk":"4226892462","pt":1631452037298,"mc":[{"id":"1.187552454","rc":[{"batl":[[0,1.02,5157.32]],"ltp":1.01,"tv":97737.54,"id":9028621}]}]}
{"op":"mcm","clk":"4226892630","pt":1631452038378,"mc":[{"id":"1.187552454","rc":[{"trd":[[1.02,3175.59]],"batb":[[0,1.01,2699.87]],"batl":[[0,1.02,5148.78]],"ltp":1.02,"tv":97754.62,"id":9028621}],"tv":104616.66}]}
{"op":"mcm","clk":"4226892826","pt":1631452039466,"mc":[{"id":"1.187552454","rc":[{"trd":[[70,7.14]],"batb":[[0,48,2],[1,30,24.49],[2,2.32,102.49]],"batl":[[0,70,4.65],[1,130,1.92],[2,1000,0.91]],"ltp":70.0,"tv":6865.17,"id":9345630},{"trd":[[1.02,3198.56]],"batl":[[0,1.02,5137.3]],"ltp":1.02,"tv":97777.58,"id":9028621}],"tv":104642.76}]}
{"op":"mcm","clk":"4226893498","pt":1631452043363,"mc":[{"id":"1.187552454","rc":[{"trd":[[1.01,2527.66],[1.02,3379.32]],"batb":[[0,1.01,2040.24]],"batl":[[0,1.02,5046.92]],"ltp":1.01,"tv":99277.6,"id":9028621}],"tv":106142.78}]}
{"op":"mcm","clk":"4226893644","pt":1631452044289,"mc":[{"id":"1.187552454","rc":[{"batb":[[0,65,3.85],[1,48,2],[2,30,24.49]],"ltp":70.0,"tv":6865.17,"id":9345630},{"trd":[[1.01,3394.7],[1.02,3380.65]],"batb":[[0,1.01,1606.72]],"batl":[[0,1.02,5046.25]],"ltp":1.02,"tv":100145.97,"id":9028621}],"tv":107011.15}]}
{"op":"mcm","clk":"4226893853","pt":1631452045480,"mc":[{"id":"1.187552454","rc":[{"batb":[[2,36,13.03]],"ltp":70.0,"tv":6865.17,"id":9345630},{"batb":[[0,1.01,1611.85]],"ltp":1.02,"tv":100145.97,"id":9028621}]}]}
{"op":"mcm","clk":"4226894001","pt":1631452046297,"mc":[{"id":"1.187552454","rc":[{"batb":[[0,1.01,2272.27]],"batl":[[0,1.02,5156.85]],"ltp":1.02,"tv":100145.97,"id":9028621}]}]}
{"op":"mcm","clk":"4226894162","pt":1631452047360,"mc":[{"id":"1.187552454","rc":[{"trd":[[50,72.57],[65,7.7]],"batb":[[0,48,2],[1,36,13.03],[2,30,24.49]],"ltp":50.0,"tv":6873.23,"id":9345630},{"trd":[[1.02,3397.81]],"batb":[[0,1.01,2705.79]],"batl":[[0,1.02,5139.69]],"ltp":1.02,"tv":100163.13,"id":9028621}],"tv":107036.37}]}
{"op":"mcm","clk":"4226894248","pt":1631452047802,"mc":[{"id":"1.187552454","rc":[{"trd":[[1.02,3398.81]],"batl":[[0,1.02,5139.19]],"ltp":1.02,"tv":100164.13,"id":9028621}],"tv":107037.37}]}
{"op":"mcm","clk":"4226894725","pt":1631452050586,"mc":[{"id":"1.187552454","rc":[{"batl":[[1,1.03,237.8]],"ltp":1.02,"tv":100164.13,"id":9028621}]}]}
{"op":"mcm","clk":"4226894903","pt":1631452051595,"mc":[{"id":"1.187552454","rc":[{"batb":[[0,65,3.85],[1,48,2],[2,36,13.03]],"ltp":50.0,"tv":6873.23,"id":9345630}]}]}
{"op":"mcm","clk":"4226895041","pt":1631452052395,"mc":[{"id":"1.187552454","rc":[{"trd":[[1.01,3842.7],[1.02,3405]],"batb":[[0,1.01,2481.79]],"batl":[[0,1.02,5136.1]],"ltp":1.01,"tv":100618.32,"id":9028621}],"tv":107491.55}]}
{"op":"mcm","clk":"4226895214","pt":1631452053318,"mc":[{"id":"1.187552454","rc":[{"trd":[[36,17.64],[48,4],[50,177.34],[65,15.4]],"batb":[[0,36,7.97],[1,30,24.49],[2,2.32,102.49]],"ltp":36.0,"tv":6999.82,"id":9345630},{"trd":[[1.02,8541.1]],"batl":[[0,1.03,237.8],[1,1.04,42],[2,1.06,15.05]],"ltp":1.02,"tv":105754.42,"id":9028621}],"tv":112754.25}]}
{"op":"mcm","clk":"4226895334","pt":1631452054077,"mc":[{"id":"1.187552454","rc":[{"trd":[[70,13.14]],"batl":[[0,70,1.66]],"ltp":70.0,"tv":7005.82,"id":9345630}],"tv":112760.24}]}
{"op":"mcm","clk":"4226895494","pt":1631452055097,"mc":[{"id":"1.187552454","rc":[{"batl":[[2,1000,0.32]],"ltp":70.0,"tv":7005.82,"id":9345630},{"batb":[[0,1.01,2266.79]],"ltp":1.02,"tv":105754.42,"id":9028621}]}]}
{"op":"mcm","clk":"4226895739","pt":1631452056497,"mc":[{"id":"1.187552454","rc":[{"batb":[[0,1.01,2518.97]],"batl":[[0,1.02,84],[1,1.03,237.8],[2,1.04,42]],"ltp":1.02,"tv":105754.42,"id":9028621}]}]}
{"op":"mcm","clk":"4226895903","pt":1631452057409,"mc":[{"id":"1.187552454","rc":[{"batb":[[0,38,2],[1,36,53.53],[2,30,24.49]],"ltp":70.0,"tv":7005.82,"id":9345630},{"batl":[[0,1.02,2297.69]],"ltp":1.02,"tv":105754.42,"id":9028621}]}]}
{"op":"mcm","clk":"4226895935","pt":1631452057608,"mc":[{"id":"1.187552454","rc":[{"batb":[[0,65,3.85],[1,38,2],[2,36,53.53]],"ltp":70.0,"tv":7005.82,"id":9345630},{"batl":[[0,1.02,2542.79]],"ltp":1.02,"tv":105754.42,"id":9028621}]}]}
{"op":"mcm","clk":"4226896267","pt":1631452059511,"mc":[{"id":"1.187552454","rc":[{"trd":[[1.02,8541.64]],"batl":[[0,1.02,2542.52]],"ltp":1.02,"tv":105754.96,"id":9028621}],"tv":112760.78}]}
{"op":"mcm","clk":"4226896344","pt":1631452059899,"mc":[{"id":"1.187552454","rc":[{"trd":[[50,184.34],[65,23.09]],"batb":[[0,40,2]],"ltp":50.0,"tv":7020.51,"id":9345630},{"trd":[[1.02,8884.72]],"batl":[[0,1.02,2199.44]],"ltp":1.02,"tv":106098.04,"id":9028621}],"tv":113118.56}]}
{"op":"mcm","clk":"4226896967","pt":1631452063207,"mc":[{"id":"1.187552454","rc":[{"batb":[[2,36,9.97]],"ltp":50.0,"tv":7020.51,"id":9345630},{"batl":[[0,1.02,2458.79]],"ltp":1.02,"tv":106098.04,"id":9028621}]}]}
{"op":"mcm","clk":"4226897503","pt":1631452066240,"mc":[{"id":"1.187552454","rc":[{"batb":[[0,1.01,2746.97]],"ltp":1.02,"tv":106098.04,"id":9028621}]}]}
{"op":"mcm","clk":"4226897692","pt":1631452067564,"mc":[{"id":"1.187552454","rc":[{"trd":[[70,16.46]],"batb":[[0,40,2.65]],"batl":[[0,130,1.92],[1,1000,0.32],[2,1000,0]],"ltp":70.0,"tv":7023.83,"id":9345630},{"batl":[[0,1.02,4458.79]],"ltp":1.02,"tv":106098.04,"id":9028621}],"tv":113121.87}]}
{"op":"mcm","clk":"4226897747","pt":1631452067855,"mc":[{"id":"1.187552454","rc":[{"batb":[[0,40,2]],"ltp":70.0,"tv":7023.83,"id":9345630}]}]}
{"op":"mcm","clk":"4226898148","pt":1631452070571,"mc":[{"id":"1.187552454","rc":[{"batl":[[0,1.02,4507.01]],"ltp":1.02,"tv":106098.04,"id":9028621}]}]}
{"op":"mcm","clk":"4226898282","pt":1631452071486,"mc":[{"id":"1.187552454","rc":[{"trd":[[50,190.13]],"batb":[[1,36,7.97],[2,30,24.49]],"ltp":50.0,"tv":7029.62,"id":9345630},{"trd":[[1.02,9168.57]],"batl":[[0,1.02,4223.16]],"ltp":1.02,"tv":106381.89,"id":9028621}],"tv":113411.51}]}
{"op":"mcm","clk":"4226898388","pt":1631452072072,"mc":[{"id":"1.187552454","rc":[{"batb":[[0,60,4.17],[1,40,2],[2,36,7.97]],"ltp":50.0,"tv":7029.62,"id":9345630}]}]}
{"op":"mcm","clk":"4226898820","pt":1631452074496,"mc":[{"id":"1.187552454","rc":[{"trd":[[110,25.31]],"batl":[[0,90,6.35],[1,130,1.92],[2,1000,0.32]],"ltp":110.0,"tv":7054.93,"id":9345630},{"trd":[[1.01,6599.12]],"batb":[[0,1.01,590.55]],"batl":[[0,1.02,4507.01],[1,1.03,297.8]],"ltp":1.01,"tv":109138.31,"id":9028621}],"tv":116193.24}]}
{"op":"mcm","clk":"4226898844","pt":1631452074671,"mc":[{"id":"1.187552454","rc":[{"batl":[[1,1000,0.32],[2,1000,0]],"ltp":110.0,"tv":7054.93,"id":9345630}]}]}
{"op":"mcm","clk":"4226899338","pt":1631452077374,"mc":[{"id":"1.187552454","rc":[{"trd":[[1.02,9168.85]],"batb":[[0,1.01,2835.61]],"batl":[[0,1.02,4506.87]],"ltp":1.02,"tv":109138.59,"id":9028621}],"tv":116193.52}]}
{"op":"mcm","clk":"4226899477","pt":1631452078101,"mc":[{"id":"1.187552454","rc":[{"batb":[[0,1.01,3069.69]],"ltp":1.02,"tv":109138.59,"id":9028621}]}]}
{"op":"mcm","clk":"4226899754","pt":1631452079291,"mc":[{"id":"1.187552454","rc":[{"trd":[[1.02,9168.91]],"batl":[[0,1.02,4506.84]],"ltp":1.02,"tv":109138.65,"id":9028621}],"tv":116193.58}]}
{"op":"mcm","clk":"4226899985","pt":1631452080597,"mc":[{"id":"1.187552454","rc":[{"batb":[[0,1.01,3267.69]],"batl":[[0,1.02,4541.28]],"ltp":1.02,"tv":109138.65,"id":9028621}]}]}
{"op":"mcm","clk":"4226900147","pt":1631452081399,"mc":[{"id":"1.187552454","rc":[{"batb":[[2,30,24.49]],"ltp":110.0,"tv":7054.93,"id":9345630},{"batb":[[0,1.01,3069.69]],"batl":[[1,1.03,332.24]],"ltp":1.02,"tv":109138.65,"id":9028621}]}]}
{"op":"mcm","clk":"4226900484","pt":1631452083198,"mc":[{"id":"1.187552454","rc":[{"batb":[[0,1.01,3237.17]],"batl":[[1,1.03,366.69]],"ltp":1.02,"tv":109138.65,"id":9028621}]}]}
{"op":"mcm","clk":"4226900604","pt":1631452083899,"mc":[{"id":"1.187552454","rc":[{"batl":[[2,1.04,76.44]],"ltp":1.02,"tv":109138.65,"id":9028621}]}]}
{"op":"mcm","clk":"4226900849","pt":1631452085366,"mc":[{"id":"1.187552454","rc":[{"trd":[[1.02,9170.11]],"batl":[[0,1.02,4540.68]],"ltp":1.02,"tv":109139.85,"id":9028621}],"tv":116194.78}]}
{"op":"mcm","clk":"4226900999","pt":1631452086290,"mc":[{"id":"1.187552454","rc":[{"trd":[[90,2.28]],"batl":[[0,90,5.21]],"ltp":90.0,"tv":7057.2,"id":9345630}],"tv":116197.06}]}
{"op":"mcm","clk":"4226901228","pt":1631452087692,"mc":[{"id":"1.187552454","rc":[{"trd":[[1.02,9180.25]],"batl":[[0,1.02,4535.61]],"ltp":1.02,"tv":109149.99,"id":9028621}],"tv":116207.2}]}
{"op":"mcm","clk":"4226901844","pt":1631452091394,"mc":[{"id":"1.187552454","rc":[{"batl":[[0,1000,0.32],[1,1000,0]],"ltp":90.0,"tv":7057.2,"id":9345630},{"batl":[[1,1.03,401.13]],"ltp":1.02,"tv":109149.99,"id":9028621}]}]}
{"op":"mcm","clk":"4226902336","pt":1631452094510,"mc":[{"id":"1.187552454","rc":[{"batl":[[0,110,1.65],[1,1000,0.32]],"ltp":90.0,"tv":7057.2,"id":9345630}]}]}
{"op":"mcm","clk":"4226902482","pt":1631452095522,"mc":[{"id":"1.187552454","rc":[{"batl":[[0,100,6.03],[1,1000,0.62]],"ltp":90.0,"tv":7057.2,"id":9345630}]}]}
{"op":"mcm","clk":"4226902955","pt":1631452098612,"mc":[{"id":"1.187552454","rc":[{"batl":[[0,95,1.65],[1,100,6.03],[2,1000,0.62]],"ltp":90.0,"tv":7057.2,"id":9345630}]}]}
{"op":"mcm","clk":"4226903534","pt":1631452101423,"mc":[{"id":"1.187552454","rc":[{"trd":[[1.02,10034.29]],"batl":[[0,1.02,4108.59]],"ltp":1.02,"tv":110004.03,"id":9028621}],"tv":117061.24}]}
{"op":"mcm","clk":"4226903753","pt":1631452102621,"mc":[{"id":"1.187552454","rc":[{"trd":[[1.01,6655.49]],"batb":[[0,1.01,3208.99]],"ltp":1.01,"tv":110060.4,"id":9028621}],"tv":117117.6}]}
{"op":"mcm","clk":"4226904044","pt":1631452104308,"mc":[{"id":"1.187552454","rc":[{"batl":[[0,1000,0.62],[1,100,0],[2,1000,0]],"ltp":90.0,"tv":7057.2,"id":9345630},{"batl":[[0,1.02,4541.45]],"ltp":1.01,"tv":110060.4,"id":9028621}]}]}
{"op":"mcm","clk":"4226904353","pt":1631452106117,"mc":[{"id":"1.187552454","rc":[{"batb":[[0,1.01,3237.17]],"ltp":1.01,"tv":110060.4,"id":9028621}]}]}
{"op":"mcm","clk":"4226904592","pt":1631452107449,"mc":[{"id":"1.187552454","rc":[{"batb":[[1,55,5.21],[2,40,2]],"batl":[[0,90,6.35],[1,110,2.14],[2,1000,0.62]],"ltp":90.0,"tv":7057.2,"id":9345630}]}]}
{"op":"mcm","clk":"4226904947","pt":1631452109422,"mc":[{"id":"1.187552454","rc":[{"batl":[[0,1.02,4543.4],[1,1.03,2032.53],[2,1.04,1275.39]],"ltp":1.01,"tv":110060.4,"id":9028621}]}]}
{"op":"mcm","clk":"4226905468","pt":1631452112236,"mc":[{"id":"1.187552454","rc":[{"trd":[[55,10.42],[60,8.34]],"batb":[[0,40,2],[1,34,5.04],[2,30,24.49]],"batl":[[0,90,6.36],[1,1000,0.62],[2,1000,0]],"ltp":55.0,"tv":7075.97,"id":9345630}],"tv":117136.37}]}
{"op":"mcm","clk":"4226905577","pt":1631452112856,"mc":[{"id":"1.187552454","rc":[{"trd":[[1.01,6677.57]],"batb":[[0,1.01,3226.13]],"ltp":1.01,"tv":110082.48,"id":9028621}],"tv":117158.45}]}
{"op":"mcm","clk":"4226905989","pt":1631452115364,"mc":[{"id":"1.187552454","rc":[{"batl":[[0,90,8.49]],"ltp":55.0,"tv":7075.97,"id":9345630}]}]}
{"op":"mcm","clk":"4226906215","pt":1631452116531,"mc":[{"id":"1.187552454","rc":[{"batl":[[0,90,6.35]],"ltp":55.0,"tv":7075.97,"id":9345630},{"batb":[[0,1.01,767.48]],"batl":[[0,1.02,2084.61],[1,1.03,1796.73]],"ltp":1.01,"tv":110082.48,"id":9028621}]}]}
{"op":"mcm","clk":"4226906383","pt":1631452117460,"mc":[{"id":"1.187552454","rc":[{"batl":[[0,1000,0.62],[1,1000,0]],"ltp":55.0,"tv":7075.97,"id":9345630},{"batb":[[0,1.01,167.48]],"batl":[[1,1.03,1736.73]],"ltp":1.01,"tv":110082.48,"id":9028621}]}]}
{"op":"mcm","clk":"4226906829","pt":1631452119547,"mc":[{"id":"1.187552454","rc":[{"batl":[[1,1.03,3928.93]],"ltp":1.01,"tv":110082.48,"id":9028621}]}]}
{"op":"mcm","clk":"4226907412","pt":1631452122533,"mc":[{"id":"1.187552454","rc":[{"trd":[[110,26.85]],"batb":[[0,110,5.69],[1,40,2],[2,34,5.04]],"ltp":110.0,"tv":7077.51,"id":9345630},{"trd":[[1.01,6845.04]],"batl":[[0,1.01,4.89],[1,1.02,2084.61],[2,1.03,3928.93]],"ltp":1.01,"tv":110249.95,"id":9028621}],"tv":117327.46}]}
{"op":"mcm","clk":"4226907775","pt":1631452124569,"mc":[{"id":"1.187552454","rc":[{"trd":[[110,30.72]],"batb":[[0,110,1.81],[1,48,4.06],[2,40,2]],"ltp":110.0,"tv":7081.38,"id":9345630},{"trd":[[1.01,7276.96]],"batl":[[0,1.02,2084.61],[1,1.03,3928.93],[2,1.04,76.44]],"ltp":1.01,"tv":110681.87,"id":9028621}],"tv":117763.26}]}
{"op":"mcm","clk":"4226907910","pt":1631452125349,"mc":[{"id":"1.187552454","rc":[{"trd":[[50,196.86],[110,34.35]],"batb":[[0,40,2],[1,34,5.04],[2,30,24.49]],"ltp":50.0,"tv":7091.74,"id":9345630},{"trd":[[1.02,10364.19]],"batl":[[0,1.02,1754.71]],"ltp":1.02,"tv":111011.77,"id":9028621}],"tv":118103.51}]}
{"op":"mcm","clk":"4226908169","pt":1631452126530,"mc":[{"id":"1.187552454","rc":[{"batb":[[0,34,5.04],[1,30,24.49],[2,26,34]],"batl":[[0,85,9.6],[1,1000,0.62]],"ltp":50.0,"tv":7091.74,"id":9345630},{"trd":[[1.02,13120.75]],"batb":[[0,1.01,843.68]],"batl":[[0,1.02,376.43]],"ltp":1.02,"tv":113768.33,"id":9028621}],"tv":120860.07}]}
{"op":"mcm","clk":"4226908358","pt":1631452127459,"mc":[{"id":"1.187552454","rc":[{"batl":[[1,90,2],[2,1000,0.62]],"ltp":50.0,"tv":7091.74,"id":9345630},{"batl":[[2,1.04,136.44]],"ltp":1.02,"tv":113768.33,"id":9028621}]}]}
{"op":"mcm","clk":"4226908552","pt":1631452128565,"mc":[{"id":"1.187552454","rc":[{"batb":[[0,42,3.81],[1,34,5.04],[2,30,24.49]],"batl":[[0,60,3.1],[1,85,9.6],[2,90,2]],"ltp":50.0,"tv":7091.74,"id":9345630},{"trd":[[1.01,7320.93]],"batb":[[0,1.01,1426.69]],"ltp":1.01,"tv":113812.31,"id":9028621}],"tv":120904.05}]}
{"op":"mcm","clk":"4226908702","pt":1631452129368,"mc":[{"id":"1.187552454","rc":[{"batb":[[0,34,2],[1,30,24.49],[2,26,34]],"batl":[[1,80,2],[2,85,4.54]],"ltp":50.0,"tv":7091.74,"id":9345630},{"trd":[[1.02,13873.61]],"batb":[[0,1.02,379.13],[1,1.01,2050.57]],"batl":[[0,1.03,3896.43],[1,1.04,136.44],[2,1.07,14.91]],"ltp":1.02,"tv":114565.17,"id":9028621}],"tv":121656.91}]}
{"op":"mcm","clk":"4226909079","pt":1631452131453,"mc":[{"id":"1.187552454","rc":[{"batb":[[0,36,2],[1,34,4],[2,30,24.49]],"ltp":50.0,"tv":7091.74,"id":9345630}]}]}
{"op":"mcm","clk":"4226909264","pt":1631452132475,"mc":[{"id":"1.187552454","rc":[{"batb":[[0,38,6.58],[1,36,2],[2,34,6.87]],"ltp":50.0,"tv":7091.74,"id":9345630},{"batb":[[0,1.02,575.64],[1,1.01,6795.84]],"batl":[[0,1.03,4171.65],[1,1.04,1459.9],[2,1.05,1058.74]],"ltp":1.02,"tv":114565.17,"id":9028621}]}]}
{"op":"mcm","clk":"4226909300","pt":1631452132655,"mc":[{"id":"1.187552454","rc":[{"batb":[[0,1.02,648.41]],"ltp":1.02,"tv":114565.17,"id":9028621}]}]}
{"op":"mcm","clk":"4226909595","pt":1631452134264,"mc":[{"id":"1.187552454","rc":[{"batl":[[0,60,10.91]],"ltp":50.0,"tv":7091.74,"id":9345630}]}]}
{"op":"mcm","clk":"4226909908","pt":1631452136286,"mc":[{"id":"1.187552454","rc":[{"trd":[[1.02,13973.61]],"batb":[[0,1.02,598.41]],"ltp":1.02,"tv":114665.17,"id":9028621}],"tv":121756.91}]}
{"op":"mcm","clk":"4226910268","pt":1631452138376,"mc":[{"id":"1.187552454","rc":[{"trd":[[55,21.27]],"ltp":55.0,"tv":7102.58,"id":9345630},{"trd":[[1.02,14558.4]],"batb":[[0,1.02,13.62]],"ltp":1.02,"tv":115249.96,"id":9028621}],"tv":122352.55}]}
{"op":"mcm","clk":"4226910463","pt":1631452139487,"mc":[{"id":"1.187552454","rc":[{"trd":[[55,21.52]],"batb":[[0,55,9.48],[1,38,6.58],[2,36,2]],"ltp":55.0,"tv":7102.84,"id":9345630},{"trd":[[1.02,14572.02]],"batb":[[0,1.01,6795.84],[1,1.01,0]],"batl":[[0,1.03,4172.15]],"ltp":1.02,"tv":115263.58,"id":9028621}],"tv":122366.42}]}
{"op":"mcm","clk":"4226910609","pt":1631452140369,"mc":[{"id":"1.187552454","rc":[{"batl":[[0,1.02,850.61],[1,1.03,4171.65],[2,1.04,1459.9]],"ltp":1.02,"tv":115263.58,"id":9028621}]}]}
{"op":"mcm","clk":"4226910942","pt":1631452142200,"mc":[{"id":"1.187552454","rc":[{"batb":[[0,1.01,7377.18]],"ltp":1.02,"tv":115263.58,"id":9028621}]}]}
{"op":"mcm","clk":"4226911206","pt":1631452143596,"mc":[{"id":"1.187552454","rc":[{"trd":[[1.02,14703.01]],"batl":[[0,1.02,785.11]],"ltp":1.02,"tv":115394.56,"id":9028621}],"tv":122497.4}]}
{"op":"mcm","clk":"4226911371","pt":1631452144493,"mc":[{"id":"1.187552454","rc":[{"trd":[[60,30.03]],"batl":[[0,80,2.07],[1,85,4.54],[2,90,2]],"ltp":60.0,"tv":7124.52,"id":9345630}],"tv":122519.09}]}
{"op":"mcm","clk":"4226911541","pt":1631452145572,"mc":[{"id":"1.187552454","rc":[{"batb":[[0,38,6.58],[1,36,2],[2,34,4.87]],"ltp":60.0,"tv":7124.52,"id":9345630},{"batb":[[0,1.01,9022.11]],"ltp":1.02,"tv":115394.56,"id":9028621}]}]}
{"op":"mcm","clk":"4226911552","pt":1631452145676,"mc":[{"id":"1.187552454","rc":[{"batb":[[0,1.01,7377.18]],"ltp":1.02,"tv":115394.56,"id":9028621}]}]}
{"op":"mcm","clk":"4226911893","pt":1631452147429,"mc":[{"id":"1.187552454","rc":[{"batl":[[0,70,7.81],[1,75,2],[2,80,2]],"ltp":60.0,"tv":7124.52,"id":9345630}]}]}
{"op":"mcm","clk":"4226912074","pt":1631452148422,"mc":[{"id":"1.187552454","rc":[{"batl":[[0,65,3.92],[1,70,7.74],[2,75,2]],"ltp":60.0,"tv":7124.52,"id":9345630},{"batl":[[0,1.03,4171.65],[1,1.04,1459.9],[2,1.05,1058.74]],"ltp":1.02,"tv":115394.56,"id":9028621}]}]}
{"op":"mcm","clk":"4226912650","pt":1631452151580,"mc":[{"id":"1.187552454","rc":[{"batb":[[0,34,2.87],[1,26,37.49],[2,21,6.94]],"batl":[[0,60,2.07],[2,90,2]],"ltp":60.0,"tv":7124.52,"id":9345630},{"batl":[[0,1.03,137.83]],"ltp":1.02,"tv":115394.56,"id":9028621}]}]}
{"op":"mcm","clk":"4226912822","pt":1631452152460,"mc":[{"id":"1.187552454","rc":[{"trd":[[60,30.17],[70,31.21]],"batb":[[0,26,37.49],[1,21,6.94],[2,2.32,102.49]],"batl":[[0,110,2],[1,1000,0.62],[2,90,0]],"ltp":70.0,"tv":7139.42,"id":9345630},{"batb":[[0,1.01,6777.18]],"batl":[[0,1.03,105.33],[1,1.04,1399.9]],"ltp":1.02,"tv":115394.56,"id":9028621}],"tv":122533.99}]}
{"op":"mcm","clk":"4226912929","pt":1631452153005,"mc":[{"id":"1.187552454","rc":[{"batb":[[0,26,32]],"ltp":70.0,"tv":7139.42,"id":9345630},{"batl":[[1,1.04,76.44]],"ltp":1.02,"tv":115394.56,"id":9028621}]}]}
{"op":"mcm","clk":"4226913187","pt":1631452154389,"mc":[{"id":"1.187552454","rc":[{"batl":[[1,1.04,2247.56]],"ltp":1.02,"tv":115394.56,"id":9028621}]}]}
{"op":"mcm","clk":"4226913376","pt":1631452155386,"mc":[{"id":"1.187552454","rc":[{"batb":[[0,30,2],[1,29,2],[2,26,32]],"batl":[[0,1000,0.62],[1,1000,0]],"ltp":70.0,"tv":7139.42,"id":9345630},{"batl":[[1,1.04,76.44],[2,1.05,1079.41]],"ltp":1.02,"tv":115394.56,"id":9028621}]}]}
{"op":"mcm","clk":"4226913547","pt":1631452156377,"mc":[{"id":"1.187552454","rc":[{"batb":[[0,65,3.62],[1,30,2],[2,29,2]],"ltp":70.0,"tv":7139.42,"id":9345630},{"batl":[[1,1.04,108.32]],"ltp":1.02,"tv":115394.56,"id":9028621}]}]}
{"op":"mcm","clk":"4226913779","pt":1631452157585,"mc":[{"id":"1.187552454","rc":[{"trd":[[65,30.33]],"batb":[[0,30,2],[1,29,2],[2,26,36.44]],"batl":[[0,60,109.73],[1,1000,0.62]],"ltp":65.0,"tv":7146.66,"id":9345630},{"batl":[[0,1.03,2],[1,1.04,73.88],[2,1.05,1058.74]],"ltp":1.02,"tv":115394.56,"id":9028621}],"tv":122541.22}]}
{"op":"mcm","clk":"4226913904","pt":1631452158282,"mc":[{"id":"1.187552454","rc":[{"batl":[[0,1000,0.62],[1,1000,0]],"ltp":65.0,"tv":7146.66,"id":9345630},{"batb":[[0,1.02,2213.69]],"batl":[[0,1.03,2216.7]],"ltp":1.02,"tv":115394.56,"id":9028621}]}]}
{"op":"mcm","clk":"4226914157","pt":1631452159488,"mc":[{"id":"1.187552454","rc":[{"batl":[[0,70,3.1],[1,1000,0.62]],"ltp":65.0,"tv":7146.66,"id":9345630},{"batl":[[0,1.03,2436.92]],"ltp":1.02,"tv":115394.56,"id":9028621}]}]}
{"op":"mcm","clk":"4226914416","pt":1631452160586,"mc":[{"id":"1.187552454","rc":[{"trd":[[1.03,445.14]],"batl":[[0,1.03,2435.42]],"ltp":1.03,"tv":115397.56,"id":9028621}],"tv":122544.22}]}
{"op":"mcm","clk":"4226914518","pt":1631452161210,"mc":[{"id":"1.187552454","rc":[{"batb":[[0,34,7.35],[1,30,2],[2,29,2]],"batl":[[1,110,2],[2,1000,0.62]],"ltp":65.0,"tv":7146.66,"id":9345630},{"batb":[[1,1.01,5160.99]],"batl":[[0,1.03,2456.09],[1,1.04,1444.23]],"ltp":1.03,"tv":115397.56,"id":9028621}]}]}
{"op":"mcm","clk":"4226914788","pt":1631452162500,"mc":[{"id":"1.187552454","rc":[{"batl":[[1,1.04,1464.9],[2,1.05,1079.41]],"ltp":1.03,"tv":115397.56,"id":9028621}]}]}
{"op":"mcm","clk":"4226914960","pt":1631452163413,"mc":[{"id":"1.187552454","rc":[{"batb":[[0,1.02,2358.01]],"ltp":1.03,"tv":115397.56,"id":9028621}]}]}
{"op":"mcm","clk":"4226915307","pt":1631452165213,"mc":[{"id":"1.187552454","rc":[{"batl":[[1,1000,0.62],[2,1000,0]],"ltp":65.0,"tv":7146.66,"id":9345630},{"batb":[[0,1.02,144.32],[1,1.01,0]],"batl":[[0,1.03,127.02]],"ltp":1.03,"tv":115397.56,"id":9028621}]}]}
{"op":"mcm","clk":"4226915531","pt":1631452166398,"mc":[{"id":"1.187552454","rc":[{"batb":[[2,26,32]],"ltp":65.0,"tv":7146.66,"id":9345630},{"batl":[[1,1.04,62.67]],"ltp":1.03,"tv":115397.56,"id":9028621}]}]}
{"op":"mcm","clk":"4226915653","pt":1631452167109,"mc":[{"id":"1.187552454","rc":[{"batb":[[0,30,2],[1,26,32],[2,21,6.94]],"batl":[[0,1000,0.62],[1,1000,0]],"ltp":65.0,"tv":7146.66,"id":9345630},{"batl":[[0,1.03,21.17]],"ltp":1.03,"tv":115397.56,"id":9028621}]}]}
{"op":"mcm","clk":"4226915866","pt":1631452168401,"mc":[{"id":"1.187552454","rc":[{"batb":[[0,30,2.02]],"batl":[[0,110,2],[1,1000,0.62]],"ltp":65.0,"tv":7146.66,"id":9345630},{"batb":[[0,1.01,6987.14]],"batl":[[1,1.04,2233.79]],"ltp":1.03,"tv":115397.56,"id":9028621}]}]}
{"op":"mcm","clk":"4226915985","pt":1631452169101,"mc":[{"id":"1.187552454","rc":[{"batb":[[1,26,38.44]],"ltp":65.0,"tv":7146.66,"id":9345630},{"batl":[[1,1.04,3497.92]],"ltp":1.03,"tv":115397.56,"id":9028621}]}]}
{"op":"mcm","clk":"4226916220","pt":1631452170415,"mc":[{"id":"1.187552454","rc":[{"batb":[[1,29,2],[2,26,38.44]],"ltp":65.0,"tv":7146.66,"id":9345630}]}]}
{"op":"mcm","clk":"4226916597","pt":1631452172406,"mc":[{"id":"1.187552454","rc":[{"batb":[[0,30,2]],"ltp":65.0,"tv":7146.66,"id":9345630},{"batl":[[0,1.03,21.96]],"ltp":1.03,"tv":115397.56,"id":9028621}]}]}
{"op":"mcm","clk":"4226916835","pt":1631452173638,"mc":[{"id":"1.187552454","rc":[{"batb":[[0,55,18.08],[1,30,2],[2,29,2]],"ltp":65.0,"tv":7146.66,"id":9345630}]}]}
{"op":"mcm","clk":"4226917019","pt":1631452174623,"mc":[{"id":"1.187552454","rc":[{"trd":[[1.02,14704.18]],"batl":[[0,1.03,21.37]],"ltp":1.02,"tv":115398.73,"id":9028621}],"tv":122545.39}]}
{"op":"mcm","clk":"4226917898","pt":1631452179155,"mc":[{"id":"1.187552454","rc":[{"batb":[[0,1.01,7087.14]],"ltp":1.02,"tv":115398.73,"id":9028621}]}]}
{"op":"mcm","clk":"4226918193","pt":1631452180566,"mc":[{"id":"1.187552454","rc":[{"batb":[[0,1.01,6987.14]],"ltp":1.02,"tv":115398.73,"id":9028621}]}]}
{"op":"mcm","clk":"4226918538","pt":1631452182449,"mc":[{"id":"1.187552454","rc":[{"trd":[[55,21.56]],"batb":[[0,55,18.04],[2,26,38.44]],"ltp":55.0,"tv":7146.69,"id":9345630},{"trd":[[1.02,14706.3]],"batl":[[0,1.02,325.39],[1,1.03,21.17],[2,1.04,3497.92]],"ltp":1.02,"tv":115400.86,"id":9028621}],"tv":122547.55}]}
{"op":"mcm","clk":"4226918942","pt":1631452184560,"mc":[{"id":"1.187552454","rc":[{"batl":[[0,1.03,21.17],[1,1.04,3497.92],[2,1.05,1079.41]],"ltp":1.02,"tv":115400.86,"id":9028621}]}]}
{"op":"mcm","clk":"4226919348","pt":1631452186784,"mc":[{"id":"1.187552454","rc":[{"trd":[[55,22.49]],"batb":[[0,55,17.11]],"ltp":55.0,"tv":7147.62,"id":9345630},{"trd":[[1.02,14756.3]],"ltp":1.02,"tv":115450.86,"id":9028621}],"tv":122598.48}]}
{"op":"mcm","clk":"4226920587","pt":1631452193515,"mc":[{"id":"1.187552454","rc":[{"batb":[[1,30,74.99]],"ltp":55.0,"tv":7147.62,"id":9345630},{"trd":[[1.01,7338.01]],"batb":[[0,1.01,6978.6]],"batl":[[0,1.02,15000],[1,1.03,71.17],[2,1.04,1326.8]],"ltp":1.01,"tv":115467.94,"id":9028621}],"tv":122615.56}]}
{"op":"mcm","clk":"4226920683","pt":1631452194010,"mc":[{"id":"1.187552454","rc":[{"trd":[[55,22.67]],"batb":[[0,55,16.93],[1,30,5.65]],"ltp":55.0,"tv":7147.81,"id":9345630},{"trd":[[1.02,14766.3]],"batl":[[0,1.03,21.17],[1,1.04,1326.8],[2,1.05,53.17]],"ltp":1.02,"tv":115477.94,"id":9028621}],"tv":122625.75}]}
{"op":"mcm","clk":"4226920918","pt":1631452195485,"mc":[{"id":"1.187552454","rc":[{"batb":[[1,50,2.04],[2,30,28.05]],"ltp":55.0,"tv":7147.81,"id":9345630},{"batl":[[0,1.02,28.25],[1,1.03,21.17],[2,1.04,1326.8]],"ltp":1.02,"tv":115477.94,"id":9028621}]}]}
{"op":"mcm","clk":"4226921129","pt":1631452196585,"mc":[{"id":"1.187552454","rc":[{"batb":[[2,30,38.94]],"ltp":55.0,"tv":7147.81,"id":9345630},{"batb":[[0,1.01,7208.6]],"batl":[[0,1.02,2241.94]],"ltp":1.02,"tv":115477.94,"id":9028621}]}]}
{"op":"mcm","clk":"4226921273","pt":1631452197390,"mc":[{"id":"1.187552454","rc":[{"batb":[[0,60,4.17],[1,55,16.93],[2,50,2.04]],"batl":[[0,100,2.29],[1,110,2],[2,1000,0.62]],"ltp":55.0,"tv":7147.81,"id":9345630},{"batb":[[0,1.01,7443.6]],"batl":[[0,1.02,2347.79],[1,1.03,81.17]],"ltp":1.02,"tv":115477.94,"id":9028621}]}]}
{"op":"mcm","clk":"4226921618","pt":1631452199310,"mc":[{"id":"1.187552454","rc":[{"batl":[[0,1.02,2368.46],[1,1.03,101.83]],"ltp":1.02,"tv":115477.94,"id":9028621}]}]}
{"op":"mcm","clk":"4226921899","pt":1631452200946,"mc":[{"id":"1.187552454","rc":[{"batl":[[0,110,2],[1,1000,0.62],[2,1000,0]],"ltp":55.0,"tv":7147.81,"id":9345630}]}]}
{"op":"mcm","clk":"4226922186","pt":1631452202425,"mc":[{"id":"1.187552454","rc":[{"batl":[[1,1.03,1846.89]],"ltp":1.02,"tv":115477.94,"id":9028621}]}]}
{"op":"mcm","clk":"4226922654","pt":1631452204720,"mc":[{"id":"1.187552454","rc":[{"trd":[[1.01,7379.35]],"batb":[[0,1.01,7422.93]],"ltp":1.01,"tv":115519.27,"id":9028621}],"tv":122667.08}]}
{"op":"mcm","clk":"4226923160","pt":1631452207138,"mc":[{"id":"1.187552454","rc":[{"batl":[[0,100,2.29],[1,110,2],[2,1000,0.62]],"ltp":55.0,"tv":7147.81,"id":9345630}]}]}
{"op":"mcm","clk":"4226923405","pt":1631452208321,"mc":[{"id":"1.187552454","rc":[{"trd":[[1.02,14783.22]],"batl":[[0,1.02,2360]],"ltp":1.02,"tv":115536.19,"id":9028621}],"tv":122684.0}]}
{"op":"mcm","clk":"4226924153","pt":1631452212417,"mc":[{"id":"1.187552454","rc":[{"trd":[[1.02,14783.68]],"batl":[[0,1.02,2359.77]],"ltp":1.02,"tv":115536.65,"id":9028621}],"tv":122684.46}]}
{"op":"mcm","clk":"4226925060","pt":1631452217449,"mc":[{"id":"1.187552454","rc":[{"batb":[[0,55,16.93],[1,50,2.04],[2,34,2.91]],"batl":[[0,1000,0.62],[1,110,0],[2,1000,0]],"ltp":55.0,"tv":7147.81,"id":9345630},{"batl":[[0,1.02,40.23],[1,1.03,134.33]],"ltp":1.02,"tv":115536.65,"id":9028621}]}]}
{"op":"mcm","clk":"4226925268","pt":1631452218459,"mc":[{"id":"1.187552454","rc":[{"batb":[[0,100,2.17],[1,55,16.93],[2,50,2.04]],"ltp":55.0,"tv":7147.81,"id":9345630},{"batl":[[1,1.03,53.67]],"ltp":1.02,"tv":115536.65,"id":9028621}]}]}
{"op":"mcm","clk":"4226925669","pt":1631452220435,"mc":[{"id":"1.187552454","rc":[{"batl":[[1,1.03,2245.87]],"ltp":1.02,"tv":115536.65,"id":9028621}]}]}
{"op":"mcm","clk":"4226926189","pt":1631452223046,"mc":[{"id":"1.187552454","rc":[{"batb":[[0,100,2.18],[2,34,2.91]],"ltp":55.0,"tv":7147.81,"id":9345630},{"batl":[[0,1.02,20.67]],"ltp":1.02,"tv":115536.65,"id":9028621}]}]}
{"op":"mcm","clk":"4226926453","pt":1631452224468,"mc":[{"id":"1.187552454","rc":[{"trd":[[55,52.95],[100,2.18]],"batb":[[0,34,2.91],[1,30,30.81],[2,26,6.44]],"batl":[[0,55,771.21],[1,90,21.33],[2,1000,0.62]],"ltp":55.0,"tv":7180.26,"id":9345630},{"trd":[[1.02,15231.37]],"batl":[[0,1.03,2245.87],[1,1.04,1326.8],[2,1.05,998.27]],"ltp":1.02,"tv":115984.34,"id":9028621}],"tv":123164.6}]}
{"op":"mcm","clk":"4226926530","pt":1631452224840,"mc":[{"id":"1.187552454","rc":[{"batl":[[0,90,1.07],[1,100,8.54]],"ltp":55.0,"tv":7180.26,"id":9345630},{"batb":[[0,1.02,0.23]],"ltp":1.02,"tv":115984.34,"id":9028621}]}]}
{"op":"mcm","clk":"4226926844","pt":1631452226563,"mc":[{"id":"1.187552454","rc":[{"batl":[[0,55,2],[1,90,22.72],[2,100,8.54]],"ltp":55.0,"tv":7180.26,"id":9345630},{"batb":[[0,1.02,98.47]],"ltp":1.02,"tv":115984.34,"id":9028621}]}]}
{"op":"mcm","clk":"4226927026","pt":1631452227448,"mc":[{"id":"1.187552454","rc":[{"batl":[[1,90,7.4]],"ltp":55.0,"tv":7180.26,"id":9345630},{"batb":[[0,1.02,2312.16]],"batl":[[0,1.03,2315.87]],"ltp":1.02,"tv":115984.34,"id":9028621}]}]}
{"op":"mcm","clk":"4226927213","pt":1631452228465,"mc":[{"id":"1.187552454","rc":[{"batb":[[0,36,5.59],[1,34,4.91],[2,32,2]],"batl":[[0,50,3.48],[1,55,2],[2,75,6.97]],"ltp":55.0,"tv":7180.26,"id":9345630},{"batb":[[0,1.02,2407.16],[1,1.01,3292.91]],"batl":[[0,1.03,2558.59],[1,1.04,1386.8]],"ltp":1.02,"tv":115984.34,"id":9028621}]}]}
{"op":"mcm","clk":"4226927630","pt":1631452230537,"mc":[{"id":"1.187552454","rc":[{"batl":[[2,85,2]],"ltp":55.0,"tv":7180.26,"id":9345630},{"batb":[[0,1.02,2406.93]],"ltp":1.02,"tv":115984.34,"id":9028621}]}]}
{"op":"mcm","clk":"4226927808","pt":1631452231459,"mc":[{"id":"1.187552454","rc":[{"batb":[[1,34,2]],"batl":[[1,55,10.22]],"ltp":55.0,"tv":7180.26,"id":9345630},{"batb":[[0,1.02,2596.12]],"batl":[[0,1.03,2526.09],[1,1.04,2315.4],[2,1.05,965.57]],"ltp":1.02,"tv":115984.34,"id":9028621}]}]}
{"op":"mcm","clk":"4226928013","pt":1631452232346,"mc":[{"id":"1.187552454","rc":[{"batl":[[1,55,2]],"ltp":55.0,"tv":7180.26,"id":9345630},{"batb":[[0,1.02,2596.28],[1,1.01,820]],"batl":[[1,1.04,1354.92]],"ltp":1.02,"tv":115984.34,"id":9028621}]}]}
{"op":"mcm","clk":"4226928326","pt":1631452233970,"mc":[{"id":"1.187552454","rc":[{"batb":[[0,1.02,2596.68],[1,1.01,6171.79]],"batl":[[1,1.04,1387.8],[2,1.05,996.07]],"ltp":1.02,"tv":115984.34,"id":9028621}]}]}
{"op":"mcm","clk":"4226928947","pt":1631452237274,"mc":[{"id":"1.187552454","rc":[{"batb":[[0,1.02,2596.52]],"ltp":1.02,"tv":115984.34,"id":9028621}]}]}
{"op":"mcm","clk":"4226929381","pt":1631452239563,"mc":[{"id":"1.187552454","rc":[{"trd":[[50,203.82]],"batb":[[0,36,5.73]],"batl":[[0,55,2],[1,85,2],[2,90,7.4]],"ltp":50.0,"tv":7187.22,"id":9345630}],"tv":123171.56}]}
{"op":"mcm","clk":"4226929506","pt":1631452240264,"mc":[{"id":"1.187552454","rc":[{"batb":[[2,30,28.81]],"ltp":50.0,"tv":7187.22,"id":9345630},{"batb":[[1,1.01,5951.79]],"batl":[[0,1.03,2546.75],[1,1.04,1345.8]],"ltp":1.02,"tv":115984.34,"id":9028621}]}]}
{"op":"mcm","clk":"4226929765","pt":1631452241573,"mc":[{"id":"1.187552454","rc":[{"batl":[[2,90,2]],"ltp":50.0,"tv":7187.22,"id":9345630},{"batl":[[1,1.04,1366.46]],"ltp":1.02,"tv":115984.34,"id":9028621}]}]}
{"op":"mcm","clk":"4226929941","pt":1631452242464,"mc":[{"id":"1.187552454","rc":[{"batb":[[0,40,18.21],[1,26,5.49],[2,23,51.54]],"batl":[[0,90,2],[1,110,2],[2,1000,0.62]],"ltp":50.0,"tv":7187.22,"id":9345630},{"batb":[[0,1.01,5952.19],[1,1.01,0]],"batl":[[0,1.03,41.83]],"ltp":1.02,"tv":115984.34,"id":9028621}]}]}
{"op":"mcm","clk":"4226930158","pt":1631452243445,"mc":[{"id":"1.187552454","rc":[{"batb":[[1,26,3.49],[2,23,49.54]],"batl":[[0,110,2],[1,1000,0.62],[2,1000,0]],"ltp":50.0,"tv":7187.22,"id":9345630},{"batb":[[0,1.01,5549.19]],"batl":[[1,1.04,74.21]],"ltp":1.02,"tv":115984.34,"id":9028621}]}]}
{"op":"mcm","clk":"4226930372","pt":1631452244594,"mc":[{"id":"1.187552454","rc":[{"trd":[[50,204.1]],"batb":[[0,40,18.08],[1,23,49.54],[2,21,6.69]],"batl":[[0,1000,0.62],[1,1000,0]],"ltp":50.0,"tv":7187.49,"id":9345630},{"trd":[[1.03,448.42]],"batb":[[0,1.02,0.4]],"batl":[[0,1.03,40.19],[1,1.04,41.33]],"ltp":1.03,"tv":115987.61,"id":9028621}],"tv":123175.11}]}
{"op":"mcm","clk":"4226930524","pt":1631452245382,"mc":[{"id":"1.187552454","rc":[{"trd":[[1.03,449.28]],"batb":[[0,1.01,2236.01]],"batl":[[0,1.03,39.76],[1,1.04,1139.09],[2,1.05,2059.2]],"ltp":1.03,"tv":115988.48,"id":9028621}],"tv":123175.98}]}
{"op":"mcm","clk":"4226930639","pt":1631452246006,"mc":[{"id":"1.187552454","rc":[{"batb":[[1,26,2],[2,23,49.54]],"ltp":50.0,"tv":7187.49,"id":9345630},{"batl":[[1,1.04,2264.4]],"ltp":1.03,"tv":115988.48,"id":9028621}]}]}
{"op":"mcm","clk":"4226930959","pt":1631452247469,"mc":[{"id":"1.187552454","rc":[{"batb":[[2,24,6.36]],"batl":[[0,110,2],[1,1000,0.62]],"ltp":50.0,"tv":7187.49,"id":9345630},{"batb":[[0,1.01,7466.51]],"batl":[[0,1.03,63.86]],"ltp":1.03,"tv":115988.48,"id":9028621}]}]}
{"op":"mcm","clk":"4226931037","pt":1631452247911,"mc":[{"id":"1.187552454","rc":[{"batb":[[1,26,6.44]],"ltp":50.0,"tv":7187.49,"id":9345630},{"batl":[[1,1.04,2295.03]],"ltp":1.03,"tv":115988.48,"id":9028621}]}]}
{"op":"mcm","clk":"4226931376","pt":1631452249770,"mc":[{"id":"1.187552454","rc":[{"trd":[[1.02,15232.16]],"batb":[[0,1.01,7466.11]],"ltp":1.02,"tv":115989.27,"id":9028621}],"tv":123176.77}]}
{"op":"mcm","clk":"4226931593","pt":1631452250991,"mc":[{"id":"1.187552454","rc":[{"batb":[[1,32,3.33],[2,26,6.44]],"ltp":50.0,"tv":7187.49,"id":9345630},{"batl":[[0,1.03,13470.32]],"ltp":1.02,"tv":115989.27,"id":9028621}]}]}
{"op":"mcm","clk":"4226932060","pt":1631452253201,"mc":[{"id":"1.187552454","rc":[{"batl":[[0,1.03,13446.22]],"ltp":1.02,"tv":115989.27,"id":9028621}]}]}
{"op":"mcm","clk":"4226933268","pt":1631452259299,"mc":[{"id":"1.187552454","rc":[{"trd":[[40,0.29]],"batb":[[0,40,17.93]],"ltp":40.0,"tv":7187.78,"id":9345630}],"tv":123177.06}]}
{"op":"mcm","clk":"4226935355","pt":1631452269587,"mc":[{"id":"1.187552454","rc":[{"batl":[[1,1.04,1197.27],[2,1.05,996.07]],"ltp":1.02,"tv":115989.27,"id":9028621}]}]}
{"op":"mcm","clk":"4226935965","pt":1631452272565,"mc":[{"id":"1.187552454","rc":[{"batb":[[0,50,2.04],[1,40,17.93],[2,32,24.29]],"ltp":40.0,"tv":7187.78,"id":9345630},{"batl":[[0,1.02,2241.94],[1,1.03,13446.22],[2,1.04,1197.27]],"ltp":1.02,"tv":115989.27,"id":9028621}]}]}
{"op":"mcm","clk":"4226936186","pt":1631452273581,"mc":[{"id":"1.187552454","rc":[{"batb":[[2,32,7.52]],"ltp":40.0,"tv":7187.78,"id":9345630},{"batb":[[0,1.01,7637.11]],"batl":[[1,1.03,39.76]],"ltp":1.02,"tv":115989.27,"id":9028621}]}]}
{"op":"mcm","clk":"4226936388","pt":1631452274465,"mc":[{"id":"1.187552454","rc":[{"batb":[[0,55,4.55],[1,50,2.04],[2,40,17.93]],"batl":[[0,95,2.57],[1,110,2],[2,1000,0.62]],"ltp":40.0,"tv":7187.78,"id":9345630},{"trd":[[1.02,15238]],"batb":[[0,1.01,7884.63]],"batl":[[0,1.02,2484.12],[1,1.03,99.76]],"ltp":1.02,"tv":115995.11,"id":9028621}],"tv":123182.9}]}
{"op":"mcm","clk":"4226936604","pt":1631452275551,"mc":[{"id":"1.187552454","rc":[{"batb":[[2,42,2]],"batl":[[1,100,2],[2,110,2]],"ltp":40.0,"tv":7187.78,"id":9345630}]}]}
{"op":"mcm","clk":"4226937173","pt":1631452278595,"mc":[{"id":"1.187552454","rc":[{"batb":[[0,50,2.04],[1,40,17.93],[2,29,38.87]],"batl":[[0,1000,0.62],[1,100,0],[2,110,0]],"ltp":40.0,"tv":7187.78,"id":9345630},{"batl":[[0,1.02,28.25]],"ltp":1.02,"tv":115995.11,"id":9028621}]}]}
{"op":"mcm","clk":"4226937355","pt":1631452279467,"mc":[{"id":"1.187552454","rc":[{"batl":[[0,1.02,48.92],[1,1.03,39.76]],"ltp":1.02,"tv":115995.11,"id":9028621}]}]}
{"op":"mcm","clk":"4226937545","pt":1631452280479,"mc":[{"id":"1.187552454","rc":[{"batl":[[1,1.03,60.43]],"ltp":1.02,"tv":115995.11,"id":9028621}]}]}
{"op":"mcm","clk":"4226937776","pt":1631452281561,"mc":[{"id":"1.187552454","rc":[{"batl":[[1,1.03,683.05],[2,1.04,2751.76]],"ltp":1.02,"tv":115995.11,"id":9028621}]}]}
{"op":"mcm","clk":"4226938831","pt":1631452287193,"mc":[{"id":"1.187552454","rc":[{"batl":[[0,1.01,342.17],[1,1.02,48.92],[2,1.03,683.05]],"ltp":1.02,"tv":115995.11,"id":9028621}]}]}
{"op":"mcm","clk":"4226939013","pt":1631452288401,"mc":[{"id":"1.187552454","rc":[{"batb":[[2,32,2]],"ltp":40.0,"tv":7187.78,"id":9345630}]}]}
{"op":"mcm","clk":"4226939149","pt":1631452289104,"mc":[{"id":"1.187552454","rc":[{"batb":[[2,29,38.87]],"ltp":40.0,"tv":7187.78,"id":9345630}]}]}
{"op":"mcm","clk":"4226939551","pt":1631452291217,"mc":[{"id":"1.187552454","rc":[{"batl":[[0,1000,0.32]],"ltp":40.0,"tv":7187.78,"id":9345630}]}]}
{"op":"mcm","clk":"4226941205","pt":1631452299797,"mc":[{"id":"1.187552454","rc":[{"batb":[[0,40,17.93],[1,29,38.87],[2,26,6.44]],"ltp":40.0,"tv":7187.78,"id":9345630},{"batl":[[1,1.02,20.67]],"ltp":1.02,"tv":115995.11,"id":9028621}]}]}
{"op":"mcm","clk":"4226942841","pt":1631452308410,"mc":[{"id":"1.187552454","rc":[{"batl":[[0,44,875.22],[1,75,27.45],[2,100,8.54]],"ltp":40.0,"tv":7187.78,"id":9345630},{"trd":[[1.01,8063.69],[1.02,15279.34],[1.03,577.64]],"batl":[[0,1.03,618.87],[1,1.04,2751.76],[2,1.05,997.27]],"ltp":1.03,"tv":116849.15,"id":9028621}],"tv":124036.94}]}
{"op":"mcm","clk":"4226943009","pt":1631452309322,"mc":[{"id":"1.187552454","rc":[{"batl":[[0,75,1.37],[1,100,8.54],[2,1000,0.32]],"ltp":40.0,"tv":7187.78,"id":9345630},{"batb":[[0,1.01,1.23]],"ltp":1.03,"tv":116849.15,"id":9028621}]}]}
{"op":"mcm","clk":"4226943154","pt":1631452310107,"mc":[{"id":"1.187552454","rc":[{"batl":[[0,55,2],[1,75,6.79],[2,100,8.54]],"ltp":40.0,"tv":7187.78,"id":9345630},{"batb":[[0,1.02,2311.93],[1,1.01,1.23]],"ltp":1.03,"tv":116849.15,"id":9028621}]}]}
{"op":"mcm","clk":"4226943414","pt":1631452311450,"mc":[{"id":"1.187552454","rc":[{"batl":[[0,46,1.65],[1,55,2],[2,65,7.5]],"ltp":40.0,"tv":7187.78,"id":9345630},{"batb":[[0,1.02,15818.6],[1,1.01,601.97]],"batl":[[0,1.03,681.88],[1,1.04,2811.76]],"ltp":1.03,"tv":116849.15,"id":9028621}]}]}
{"op":"mcm","clk":"4226943631","pt":1631452312542,"mc":[{"id":"1.187552454","rc":[{"batb":[[0,1.02,15908.6],[1,1.01,3265.97]],"ltp":1.03,"tv":116849.15,"id":9028621}]}]}
{"op":"mcm","clk":"4226943818","pt":1631452313401,"mc":[{"id":"1.187552454","rc":[{"batb":[[2,26,2]],"batl":[[1,50,2],[2,55,2]],"ltp":40.0,"tv":7187.78,"id":9345630},{"batl":[[1,1.04,2781.13],[2,1.05,965.57]],"ltp":1.03,"tv":116849.15,"id":9028621}]}]}
{"op":"mcm","clk":"4226944358","pt":1631452316221,"mc":[{"id":"1.187552454","rc":[{"batl":[[1,48,2],[2,50,2]],"ltp":40.0,"tv":7187.78,"id":9345630},{"batb":[[1,1.01,5914.31]],"ltp":1.03,"tv":116849.15,"id":9028621}]}]}
{"op":"mcm","clk":"4226944586","pt":1631452317421,"mc":[{"id":"1.187552454","rc":[{"trd":[[46,2.9]],"batl":[[0,48,2],[1,50,2],[2,55,2]],"ltp":46.0,"tv":7190.68,"id":9345630},{"batb":[[1,1.01,5913.08]],"ltp":1.03,"tv":116849.15,"id":9028621}],"tv":124039.83}]}
{"op":"mcm","clk":"4226944665","pt":1631452317843,"mc":[{"id":"1.187552454","rc":[{"batl":[[0,46,2],[1,48,2],[2,50,2]],"ltp":46.0,"tv":7190.68,"id":9345630}]}]}
{"op":"mcm","clk":"4226945080","pt":1631452320012,"mc":[{"id":"1.187552454","rc":[{"trd":[[1.02,15386.26]],"batb":[[0,1.02,15855.14]],"ltp":1.02,"tv":116956.07,"id":9028621}],"tv":124146.76}]}
{"op":"mcm","clk":"4226945276","pt":1631452321058,"mc":[{"id":"1.187552454","rc":[{"batl":[[0,44,2],[1,46,2],[2,48,2]],"ltp":46.0,"tv":7190.68,"id":9345630}]}]}
{"op":"mcm","clk":"4226945471","pt":1631452321951,"mc":[{"id":"1.187552454","rc":[{"batl":[[1,1.04,2739.8],[2,1.05,944.9]],"ltp":1.02,"tv":116956.07,"id":9028621}]}]}
{"op":"mcm","clk":"4226946080","pt":1631452325255,"mc":[{"id":"1.187552454","rc":[{"batl":[[0,42,4.31],[1,44,2],[2,46,2]],"ltp":46.0,"tv":7190.68,"id":9345630},{"batb":[[1,1.01,5708.34]],"ltp":1.02,"tv":116956.07,"id":9028621}]}]}
{"op":"mcm","clk":"4226946666","pt":1631452328236,"mc":[{"id":"1.187552454","rc":[{"trd":[[42,12.62],[44,11.58],[46,4.73]],"batl":[[0,46,1.08],[1,48,2],[2,55,2]],"ltp":46.0,"tv":7205.14,"id":9345630},{"trd":[[1.02,15390.68],[1.03,674.16]],"batb":[[0,1.02,15852.93]],"batl":[[0,1.03,637.06]],"ltp":1.02,"tv":117057.02,"id":9028621}],"tv":124262.16}]}
{"op":"mcm","clk":"4226946896","pt":1631452329465,"mc":[{"id":"1.187552454","rc":[{"batl":[[1,55,2],[2,65,7.5]],"ltp":46.0,"tv":7205.14,"id":9345630},{"batl":[[1,1.04,2743.24],[2,1.05,948.34]],"ltp":1.02,"tv":117057.02,"id":9028621}]}]}
{"op":"mcm","clk":"4226947087","pt":1631452330370,"mc":[{"id":"1.187552454","rc":[{"batl":[[0,55,2],[1,65,7.5],[2,75,6.79]],"ltp":46.0,"tv":7205.14,"id":9345630}]}]}
{"op":"mcm","clk":"4226947688","pt":1631452333466,"mc":[{"id":"1.187552454","rc":[{"batl":[[0,50,2],[1,55,2],[2,65,7.5]],"ltp":46.0,"tv":7205.14,"id":9345630}]}]}
{"op":"mcm","clk":"4226947921","pt":1631452334578,"mc":[{"id":"1.187552454","rc":[{"batb":[[1,20,80.14],[2,13.5,2]],"batl":[[0,65,7.5],[1,700,2.19],[2,1000,0.32]],"ltp":46.0,"tv":7205.14,"id":9345630},{"batb":[[0,1.01,600],[1,1.01,0]],"batl":[[0,1.03,3.44],[1,1.04,63.44],[2,1.05,3.44]],"ltp":1.02,"tv":117057.02,"id":9028621}]}]}
{"op":"mcm","clk":"4226948096","pt":1631452335437,"mc":[{"id":"1.187552454","rc":[{"batl":[[0,700,2.19],[1,1000,0.32],[2,1000,0]],"ltp":46.0,"tv":7205.14,"id":9345630},{"batl":[[1,1.04,3.44]],"ltp":1.02,"tv":117057.02,"id":9028621}]}]}
{"op":"mcm","clk":"4226948466","pt":1631452337353,"mc":[{"id":"1.187552454","rc":[{"batb":[[0,1.01,2235.61]],"ltp":1.02,"tv":117057.02,"id":9028621}]}]}
{"op":"mcm","clk":"4226948766","pt":1631452339160,"mc":[{"id":"1.187552454","rc":[{"batb":[[0,55,2.89],[1,40,17.93],[2,20,80.14]],"ltp":46.0,"tv":7205.14,"id":9345630}]}]}
{"op":"mcm","clk":"4226948965","pt":1631452340343,"mc":[{"id":"1.187552454","rc":[{"trd":[[20,103.31],[21,31.43],[26,45.41],[34,0.1],[40,36.15],[55,58.73]],"batb":[[0,20,79.41],[1,13.5,2],[2,2.32,102.49]],"ltp":20.0,"tv":7248.65,"id":9345630},{"trd":[[1.03,677.61],[1.04,3381.86],[1.05,2605.64]],"batl":[[0,1.06,3.44],[1,1.07,3.44],[2,1.08,3.44]],"ltp":1.05,"tv":117067.35,"id":9028621}],"tv":124316.01}]}
{"op":"mcm","clk":"4226949181","pt":1631452341477,"mc":[{"id":"1.187552454","rc":[{"trd":[[1.01,8080.77]],"batb":[[0,1.01,2227.07]],"batl":[[0,1.03,93.57],[1,1.06,3.44],[2,1.07,3.44]],"ltp":1.01,"tv":117084.43,"id":9028621}],"tv":124333.09}]}
{"op":"mcm","clk":"4226949347","pt":1631452342276,"mc":[{"id":"1.187552454","rc":[{"batb":[[0,1.01,2398.07]],"batl":[[0,1.02,2213.69],[1,1.03,223.51],[2,1.06,18.49]],"ltp":1.01,"tv":117084.43,"id":9028621}]}]}
{"op":"mcm","clk":"4226949624","pt":1631452343552,"mc":[{"id":"1.187552454","rc":[{"batb":[[0,28,45.12],[1,21,2],[2,20,2]],"batl":[[0,100,2],[1,700,2.19],[2,1000,0.32]],"ltp":20.0,"tv":7248.65,"id":9345630},{"batb":[[0,1.01,2402.28]],"batl":[[1,1.03,283.51],[2,1.04,10]],"ltp":1.01,"tv":117084.43,"id":9028621}]}]}
{"op":"mcm","clk":"4226949770","pt":1631452344335,"mc":[{"id":"1.187552454","rc":[{"batb":[[0,55,4.55],[1,36,2],[2,34,2]],"ltp":20.0,"tv":7248.65,"id":9345630},{"batb":[[0,1.01,2649.8]],"batl":[[0,1.02,2230.89]],"ltp":1.01,"tv":117084.43,"id":9028621}]}]}
{"op":"mcm","clk":"4226950216","pt":1631452347043,"mc":[{"id":"1.187552454","rc":[{"batl":[[0,95,2],[1,100,2],[2,700,2.19]],"ltp":20.0,"tv":7248.65,"id":9345630}]}]}
{"op":"mcm","clk":"4226950467","pt":1631452348503,"mc":[{"id":"1.187552454","rc":[{"batl":[[2,1.04,1411.9]],"ltp":1.01,"tv":117084.43,"id":9028621}]}]}
{"op":"mcm","clk":"4226950728","pt":1631452349954,"mc":[{"id":"1.187552454","rc":[{"batl":[[0,90,2],[1,95,2],[2,100,2]],"ltp":20.0,"tv":7248.65,"id":9345630}]}]}
{"op":"mcm","clk":"4226950894","pt":1631452350872,"mc":[{"id":"1.187552454","rc":[{"batl":[[0,90,4.61]],"ltp":20.0,"tv":7248.65,"id":9345630}]}]}
{"op":"mcm","clk":"4226951380","pt":1631452353499,"mc":[{"id":"1.187552454","rc":[{"batl":[[0,85,2],[1,90,2],[2,95,2]],"ltp":20.0,"tv":7248.65,"id":9345630},{"trd":[[1.01,8104.18]],"batb":[[0,1.01,2638.1]],"batl":[[1,1.03,286.95]],"ltp":1.01,"tv":117107.83,"id":9028621}],"tv":124356.49}]}
{"op":"mcm","clk":"4226951513","pt":1631452354198,"mc":[{"id":"1.187552454","rc":[{"batl":[[2,1.04,1415.34]],"ltp":1.01,"tv":117107.83,"id":9028621}]}]}
{"op":"mcm","clk":"4226951700","pt":1631452355276,"mc":[{"id":"1.187552454","rc":[{"trd":[[55,59.81]],"batb":[[0,55,4.01]],"ltp":55.0,"tv":7249.73,"id":9345630},{"trd":[[1.02,15407.6]],"batl":[[0,1.02,2222.43]],"ltp":1.02,"tv":117124.75,"id":9028621}],"tv":124374.48}]}
{"op":"mcm","clk":"4226951928","pt":1631452356595,"mc":[{"id":"1.187552454","rc":[{"batl":[[0,80,2.61],[1,85,2],[2,90,2]],"ltp":55.0,"tv":7249.73,"id":9345630}]}]}
{"op":"mcm","clk":"4226951980","pt":1631452356859,"mc":[{"id":"1.187552454","rc":[{"batb":[[2,28,45.12]],"ltp":55.0,"tv":7249.73,"id":9345630}]}]}
{"op":"mcm","clk":"4226952211","pt":1631452358208,"mc":[{"id":"1.187552454","rc":[{"batb":[[0,28,45.12],[1,26,2],[2,17.5,2]],"batl":[[0,700,2.19],[1,1000,0.32],[2,90,0]],"ltp":55.0,"tv":7249.73,"id":9345630},{"batb":[[0,1.01,4.21]],"batl":[[0,1.03,63.44],[1,1.04,1415.34],[2,1.05,947.14]],"ltp":1.02,"tv":117124.75,"id":9028621}]}]}
{"op":"mcm","clk":"4226952423","pt":1631452359401,"mc":[{"id":"1.187552454","rc":[{"batb":[[1,17.5,2],[2,2.32,102.49]],"ltp":55.0,"tv":7249.73,"id":9345630},{"trd":[[1.01,8112.6]],"batl":[[0,1.01,1900.79],[1,1.03,3.44],[2,1.04,3.44]],"ltp":1.01,"tv":117133.17,"id":9028621}],"tv":124382.9}]}
{"op":"mcm","clk":"4226952810","pt":1631452361395,"mc":[{"id":"1.187552454","rc":[{"batb":[[0,28,47.12],[1,27,2],[2,21,2]],"ltp":55.0,"tv":7249.73,"id":9345630}]}]}
{"op":"mcm","clk":"4226952966","pt":1631452362196,"mc":[{"id":"1.187552454","rc":[{"batb":[[2,17.5,2]],"ltp":55.0,"tv":7249.73,"id":9345630},{"batl":[[1,1.02,3.44],[2,1.03,3.44]],"ltp":1.01,"tv":117133.17,"id":9028621}]}]}
{"op":"mcm","clk":"4226953181","pt":1631452363383,"mc":[{"id":"1.187552454","rc":[{"batl":[[0,1000,0.32],[1,1000,0]],"ltp":55.0,"tv":7249.73,"id":9345630},{"batl":[[0,1.02,3.44],[1,1.03,6.89],[2,1.04,3.44]],"ltp":1.01,"tv":117133.17,"id":9028621}]}]}
{"op":"mcm","clk":"4226953351","pt":1631452364294,"mc":[{"id":"1.187552454","rc":[{"batb":[[0,1.01,2235.61]],"batl":[[0,1.02,1261.56],[1,1.03,975.21]],"ltp":1.01,"tv":117133.17,"id":9028621}]}]}
{"op":"mcm","clk":"4226953470","pt":1631452364879,"mc":[{"id":"1.187552454","rc":[{"batl":[[0,1.02,1239.31]],"ltp":1.01,"tv":117133.17,"id":9028621}]}]}
{"op":"mcm","clk":"4226953962","pt":1631452367521,"mc":[{"id":"1.187552454","rc":[{"batb":[[0,48,5.21],[1,30,2],[2,28,47.12]],"batl":[[0,80,1.65],[1,1000,0.32]],"ltp":55.0,"tv":7249.73,"id":9345630},{"batb":[[0,1.01,2240.61]],"batl":[[0,1.02,1256.51],[2,1.04,1443.95]],"ltp":1.01,"tv":117133.17,"id":9028621}]}]}
{"op":"mcm","clk":"4226954220","pt":1631452368822,"mc":[{"id":"1.187552454","rc":[{"batb":[[0,1.01,2247.74]],"ltp":1.01,"tv":117133.17,"id":9028621}]}]}
{"op":"mcm","clk":"4226954436","pt":1631452369995,"mc":[{"id":"1.187552454","rc":[{"batb":[[0,1.01,2248.07]],"ltp":1.01,"tv":117133.17,"id":9028621}]}]}
{"op":"mcm","clk":"4226954689","pt":1631452371354,"mc":[{"id":"1.187552454","rc":[{"batb":[[0,1.01,12.46]],"batl":[[0,1.02,20.64],[1,1.03,6.89]],"ltp":1.01,"tv":117133.17,"id":9028621}]}]}
{"op":"mcm","clk":"4226954845","pt":1631452372227,"mc":[{"id":"1.187552454","rc":[{"batb":[[1,28,47.12],[2,27,2]],"ltp":55.0,"tv":7249.73,"id":9345630}]}]}
{"op":"mcm","clk":"4226955061","pt":1631452373323,"mc":[{"id":"1.187552454","rc":[{"batl":[[2,1.04,1447.4]],"ltp":1.01,"tv":117133.17,"id":9028621}]}]}
{"op":"mcm","clk":"4226955241","pt":1631452374237,"mc":[{"id":"1.187552454","rc":[{"batb":[[0,28,47.12],[1,26,2],[2,24,2]],"batl":[[0,1000,0.32],[1,1000,0]],"ltp":55.0,"tv":7249.73,"id":9345630},{"trd":[[1.01,8122.59]],"batb":[[0,1.01,6.61]],"batl":[[0,1.02,3.44],[2,1.04,3618.52]],"ltp":1.01,"tv":117143.17,"id":9028621}],"tv":124392.9}]}
{"op":"mcm","clk":"4226955333","pt":1631452374740,"mc":[{"id":"1.187552454","rc":[{"batb":[[0,80,1.45],[1,28,47.12],[2,26,2]],"ltp":55.0,"tv":7249.73,"id":9345630}]}]}
{"op":"mcm","clk":"4226955693","pt":1631452376760,"mc":[{"id":"1.187552454","rc":[{"batl":[[0,1.01,9.32],[1,1.02,3.44],[2,1.03,6.89]],"ltp":1.01,"tv":117143.17,"id":9028621}]}]}
{"op":"mcm","clk":"4226955931","pt":1631452378122,"mc":[{"id":"1.187552454","rc":[{"batb":[[2,27,2]],"ltp":55.0,"tv":7249.73,"id":9345630}]}]}
{"op":"mcm","clk":"4226956300","pt":1631452380229,"mc":[{"id":"1.187552454","rc":[{"batb":[[1,26,2],[2,24,2]],"ltp":55.0,"tv":7249.73,"id":9345630}]}]}
{"op":"mcm","clk":"4226956536","pt":1631452381554,"mc":[{"id":"1.187552454","rc":[{"batb":[[1,42,50.56],[2,26,2]],"ltp":55.0,"tv":7249.73,"id":9345630}]}]}
{"op":"mcm","clk":"4226956731","pt":1631452382548,"mc":[{"id":"1.187552454","rc":[{"batb":[[1,42,5.7]],"ltp":55.0,"tv":7249.73,"id":9345630},{"batl":[[0,1.01,2244.93]],"ltp":1.01,"tv":117143.17,"id":9028621}]}]}
{"op":"mcm","clk":"4226956904","pt":1631452383426,"mc":[{"id":"1.187552454","rc":[{"batl":[[2,1.03,66.89]],"ltp":1.01,"tv":117143.17,"id":9028621}]}]}
{"op":"mcm","clk":"4226957277","pt":1631452385537,"mc":[{"id":"1.187552454","rc":[{"batl":[[0,1.01,2248.38],[2,1.03,6.89]],"ltp":1.01,"tv":117143.17,"id":9028621}]}]}
{"op":"mcm","clk":"4226957842","pt":1631452388640,"mc":[{"id":"1.187552454","rc":[{"batl":[[1,1.02,63.44]],"ltp":1.01,"tv":117143.17,"id":9028621}]}]}
{"op":"mcm","clk":"4226958235","pt":1631452390563,"mc":[{"id":"1.187552454","rc":[{"batl":[[0,1000,0.62]],"ltp":55.0,"tv":7249.73,"id":9345630},{"batl":[[0,1.01,2247.56]],"ltp":1.01,"tv":117143.17,"id":9028621}]}]}
{"op":"mcm","clk":"4226959323","pt":1631452395969,"mc":[{"id":"1.187552454","rc":[{"batl":[[0,1.01,2247.22]],"ltp":1.01,"tv":117143.17,"id":9028621}]}]}
{"op":"mcm","clk":"4226959691","pt":1631452398042,"mc":[{"id":"1.187552454","rc":[{"batl":[[0,1.01,2246.83]],"ltp":1.01,"tv":117143.17,"id":9028621}]}]}
{"op":"mcm","clk":"4226960056","pt":1631452400238,"mc":[{"id":"1.187552454","rc":[{"trd":[[1.01,8124.92]],"batl":[[0,1.01,2245.67]],"ltp":1.01,"tv":117145.49,"id":9028621}],"tv":124395.22}]}
{"op":"mcm","clk":"4226960823","pt":1631452404362,"mc":[{"id":"1.187552454","rc":[{"batl":[[0,1.01,10.06]],"ltp":1.01,"tv":117145.49,"id":9028621}]}]}
{"op":"mcm","clk":"4226961006","pt":1631452405483,"mc":[{"id":"1.187552454","rc":[{"batl":[[1,1.02,3.44]],"ltp":1.01,"tv":117145.49,"id":9028621}]}]}
{"op":"mcm","clk":"4226961300","pt":1631452407283,"mc":[{"id":"1.187552454","rc":[{"batl":[[1,1.02,2217.13]],"ltp":1.01,"tv":117145.49,"id":9028621}]}]}
{"op":"mcm","clk":"4226962936","pt":1631452416504,"mc":[{"id":"1.187552454","rc":[{"batb":[[2,2.32,102.49]],"ltp":55.0,"tv":7249.73,"id":9345630},{"batl":[[1,1.02,3.44]],"ltp":1.01,"tv":117145.49,"id":9028621}]}]}
{"op":"mcm","clk":"4226963469","pt":1631452419608,"mc":[{"id":"1.187552454","rc":[{"trd":[[1.01,8145.03]],"batb":[[0,1.01,4.4]],"batl":[[0,1.02,3.44],[1,1.03,6.89],[2,1.04,6.89]],"ltp":1.01,"tv":117165.6,"id":9028621}],"tv":124415.34}]}
{"op":"mcm","clk":"4226964020","pt":1631452422512,"mc":[{"id":"1.187552454","rc":[{"batl":[[0,1.09,11.88],[1,1.11,11.88],[2,1.13,15.57]],"ltp":1.01,"tv":117165.6,"id":9028621}]}]}
{"op":"mcm","clk":"4226964508","pt":1631452425391,"mc":[{"id":"1.187552454","rc":[{"trd":[[1.01,8153.84]],"batl":[[0,1.01,47.94],[1,1.09,11.88],[2,1.11,11.88]],"ltp":1.01,"tv":117174.41,"id":9028621}],"tv":124424.14}]}
{"op":"mcm","clk":"4226964933","pt":1631452427528,"mc":[{"id":"1.187552454","marketDefinition":{"bspMarket":false,"turnInPlayEnabled":true,"persistenceEnabled":true,"marketBaseRate":5.0,"eventId":"30895321","eventTypeId":"2","numberOfWinners":1,"bettingType":"ODDS","marketType":"MATCH_ODDS","marketTime":"2021-09-12T11:40:00.000Z","suspendTime":"2021-09-12T11:40:00.000Z","bspReconciled":false,"complete":true,"inPlay":true,"crossMatching":true,"runnersVoidable":false,"numberOfActiveRunners":2,"betDelay":3,"status":"SUSPENDED","runners":[{"status":"ACTIVE","sortPriority":1,"id":9028621,"name":"Mayar Sherif"},{"status":"ACTIVE","sortPriority":2,"id":9345630,"name":"Martina Trevisan"}],"regulators":["MR_INT"],"discountAllowed":true,"timezone":"UTC","openDate":"2021-09-12T11:40:00.000Z","version":4028304642,"name":"Match Odds","eventName":"Ma Sherif v Trevisan"},"rc":[{"batl":[[1,1.14,3.06],[2,1.22,17.08]],"ltp":1.01,"tv":117174.41,"id":9028621}]}]}
{"op":"mcm","clk":"4226965300","pt":1631452429333,"mc":[{"id":"1.187552454","rc":[{"batb":[[0,42,5.7],[1,1.01,30],[2,2.32,0]],"ltp":55.0,"tv":7249.73,"id":9345630}]}]}
{"op":"mcm","clk":"4226974104","pt":1631452477372,"mc":[{"id":"1.187552454","tv":0.0}]}
{"op":"mcm","clk":"4226974434","pt":1631452478975,"mc":[{"id":"1.187552454","marketDefinition":{"bspMarket":false,"turnInPlayEnabled":true,"persistenceEnabled":true,"marketBaseRate":5.0,"eventId":"30895321","eventTypeId":"2","numberOfWinners":1,"bettingType":"ODDS","marketType":"MATCH_ODDS","marketTime":"2021-09-12T11:40:00.000Z","suspendTime":"2021-09-12T11:40:00.000Z","bspReconciled":false,"complete":true,"inPlay":true,"crossMatching":false,"runnersVoidable":false,"numberOfActiveRunners":0,"betDelay":3,"status":"CLOSED","settledTime":"2021-09-12T13:14:21.000Z","runners":[{"status":"WINNER","sortPriority":1,"id":9028621,"name":"Mayar Sherif"},{"status":"LOSER","sortPriority":2,"id":9345630,"name":"Martina Trevisan"}],"regulators":["MR_INT"],"discountAllowed":true,"timezone":"UTC","openDate":"2021-09-12T11:40:00.000Z","version":4028307683,"name":"Match Odds","eventName":"Ma Sherif v Trevisan"}}]}
