{"op":"mcm","clk":"4221654281","pt":1631437008992,"mc":[{"id":"1.187551126","marketDefinition":{"bspMarket":false,"turnInPlayEnabled":true,"persistenceEnabled":true,"marketBaseRate":5.0,"eventId":"30895124","eventTypeId":"2","numberOfWinners":1,"bettingType":"ODDS","marketType":"MATCH_ODDS","marketTime":"2021-09-12T14:00:00.000Z","suspendTime":"2021-09-12T14:00:00.000Z","bspReconciled":false,"complete":true,"inPlay":false,"crossMatching":false,"runnersVoidable":false,"numberOfActiveRunners":2,"betDelay":0,"status":"OPEN","runners":[{"status":"ACTIVE","sortPriority":1,"id":35773667,"name":"R Gonzalez Vilar"},{"status":"ACTIVE","sortPriority":2,"id":9629787,"name":"I Shymanovich"}],"regulators":["MR_INT"],"countryCode":"GB","discountAllowed":false,"timezone":"GMT","openDate":"2021-09-12T14:00:00.000Z","version":4027567373,"name":"Match Odds","eventName":"R Gonzalez Vilar v I Shymanovich"},"rc":[{"batb":[[0,1.01,25]],"ltp":0.0,"tv":0.0,"id":35773667},{"batb":[[0,1.01,25]],"ltp":0.0,"tv":0.0,"id":9629787}]}]}
{"op":"mcm","clk":"4221658155","pt":1631437050014,"mc":[{"id":"1.187551126","marketDefinition":{"bspMarket":false,"turnInPlayEnabled":true,"persistenceEnabled":true,"marketBaseRate":5.0,"eventId":"30895124","eventTypeId":"2","numberOfWinners":1,"bettingType":"ODDS","marketType":"MATCH_ODDS","marketTime":"2021-09-12T14:00:00.000Z","suspendTime":"2021-09-12T14:00:00.000Z","bspReconciled":false,"complete":true,"inPlay":false,"crossMatching":false,"runnersVoidable":false,"numberOfActiveRunners":2,"betDelay":0,"status":"OPEN","runners":[{"status":"ACTIVE","sortPriority":1,"id":35773667,"name":"R Gonzalez Vilar"},{"status":"ACTIVE","sortPriority":2,"id":9629787,"name":"I Shymanovich"}],"regulators":["MR_INT"],"countryCode":"GB","discountAllowed":true,"timezone":"GMT","openDate":"2021-09-12T14:00:00.000Z","version":4027567373,"name":"Match Odds","eventName":"R Gonzalez Vilar v I Shymanovich"}}]}
{"op":"mcm","clk":"4221674195","pt":1631437211488,"mc":[{"id":"1.187551126","rc":[{"batb":[[0,1.01,7]],"ltp":0.0,"tv":0.0,"id":35773667},{"batb":[[0,1.01,7]],"ltp":0.0,"tv":0.0,"id":9629787}]}]}
{"op":"mcm","clk":"4221754315","pt":1631437938782,"mc":[{"id":"1.187551126","rc":[{"batl":[[0,990,2.2]],"ltp":0.0,"tv":0.0,"id":35773667},{"batl":[[0,990,2.2]],"ltp":0.0,"tv":0.0,"id":9629787}]}]}
{"op":"mcm","clk":"4221778361","pt":1631438139933,"mc":[{"id":"1.187551126","rc":[{"batb":[[0,6,10],[1,1.01,7]],"ltp":0.0,"tv":0.0,"id":35773667},{"batb":[[0,1.1,338.19],[1,1.01,7]],"ltp":0.0,"tv":0.0,"id":9629787}]}]}
{"op":"mcm","clk":"4221781542","pt":1631438165802,"mc":[{"id":"1.187551126","marketDefinition":{"bspMarket":false,"turnInPlayEnabled":true,"persistenceEnabled":true,"marketBaseRate":5.0,"eventId":"30895124","eventTypeId":"2","numberOfWinners":1,"bettingType":"ODDS","marketType":"MATCH_ODDS","marketTime":"2021-09-12T14:00:00.000Z","suspendTime":"2021-09-12T14:00:00.000Z","bspReconciled":false,"complete":true,"inPlay":false,"crossMatching":true,"runnersVoidable":false,"numberOfActiveRunners":2,"betDelay":0,"status":"OPEN","runners":[{"status":"ACTIVE","sortPriority":1,"id":35773667,"name":"R Gonzalez Vilar"},{"status":"ACTIVE","sortPriority":2,"id":9629787,"name":"I Shymanovich"}],"regulators":["MR_INT"],"countryCode":"GB","discountAllowed":true,"timezone":"GMT","openDate":"2021-09-12T14:00:00.000Z","version":4027567373,"name":"Match Odds","eventName":"R Gonzalez Vilar v I Shymanovich"}}]}
{"op":"mcm","clk":"4222131237","pt":1631440882867,"mc":[{"id":"1.187551126","rc":[{"batb":[[0,1.11,5.85],[1,1.1,338.19],[2,1.01,7]],"ltp":0.0,"tv":0.0,"id":9629787}]}]}
{"op":"mcm","clk":"4222140729","pt":1631440940668,"mc":[{"id":"1.187551126","rc":[{"batl":[[0,490,19.35],[1,990,2.2]],"ltp":0.0,"tv":0.0,"id":35773667},{"batl":[[0,95,19.35],[1,990,2.2]],"ltp":0.0,"tv":0.0,"id":9629787}]}]}
{"op":"mcm","clk":"4222743245","pt":1631444494976,"mc":[{"id":"1.187551126","rc":[{"batb":[[1,1.01,12]],"ltp":0.0,"tv":0.0,"id":35773667},{"batb":[[2,1.01,12]],"ltp":0.0,"tv":0.0,"id":9629787}]}]}
{"op":"mcm","clk":"4222999588","pt":1631445819767,"mc":[{"id":"1.187551126","rc":[{"batb":[[1,1.02,108.45],[2,1.01,12]],"ltp":0.0,"tv":0.0,"id":35773667},{"batb":[[2,1.02,108.45]],"ltp":0.0,"tv":0.0,"id":9629787}]}]}
{"op":"mcm","clk":"4223202207","pt":1631446854683,"mc":[{"id":"1.187551126","rc":[{"batb":[[1,1.05,879.5],[2,1.02,108.45]],"ltp":0.0,"tv":0.0,"id":35773667},{"batb":[[2,1.03,1451.18]],"ltp":0.0,"tv":0.0,"id":9629787}]}]}
{"op":"mcm","clk":"4223407546","pt":1631448001562,"mc":[{"id":"1.187551126","rc":[{"batb":[[1,1.1,450.92]],"ltp":0.0,"tv":0.0,"id":9629787}]}]}
{"op":"mcm","clk":"4223921006","pt":1631450765638,"mc":[{"id":"1.187551126","rc":[{"batl":[[0,1.3,80],[1,95,19.35],[2,990,2.2]],"ltp":0.0,"tv":0.0,"id":9629787}]}]}
{"op":"mcm","clk":"4224070786","pt":1631451600743,"mc":[{"id":"1.187551126","rc":[{"batb":[[0,6,12.56]],"ltp":0.0,"tv":0.0,"id":35773667},{"batb":[[0,1.11,91.25]],"ltp":0.0,"tv":0.0,"id":9629787}]}]}
{"op":"mcm","clk":"4224144333","pt":1631451944995,"mc":[{"id":"1.187551126","rc":[{"batl":[[1,1.82,2.66],[2,95,19.35]],"ltp":0.0,"tv":0.0,"id":9629787}]}]}
{"op":"mcm","clk":"4224331865","pt":1631452774385,"mc":[{"id":"1.187551126","rc":[{"batb":[[0,6,10]],"ltp":0.0,"tv":0.0,"id":35773667},{"batb":[[0,1.11,5.85]],"ltp":0.0,"tv":0.0,"id":9629787}]}]}
{"op":"mcm","clk":"4224332067","pt":1631452775287,"mc":[{"id":"1.187551126","rc":[{"batb":[[0,6,12.56]],"ltp":0.0,"tv":0.0,"id":35773667},{"batb":[[0,1.11,91.25]],"ltp":0.0,"tv":0.0,"id":9629787}]}]}
{"op":"mcm","clk":"4224345764","pt":1631452843116,"mc":[{"id":"1.187551126","rc":[{"batb":[[0,6,10]],"ltp":0.0,"tv":0.0,"id":35773667},{"batb":[[0,1.11,5.85]],"ltp":0.0,"tv":0.0,"id":9629787}]}]}
{"op":"mcm","clk":"4224345988","pt":1631452844295,"mc":[{"id":"1.187551126","rc":[{"batb":[[0,6,12.56]],"ltp":0.0,"tv":0.0,"id":35773667},{"batb":[[0,1.11,91.25]],"ltp":0.0,"tv":0.0,"id":9629787}]}]}
{"op":"mcm","clk":"4224418335","pt":1631453214775,"mc":[{"id":"1.187551126","rc":[{"batb":[[1,1.02,108.45],[2,1.01,12]],"ltp":0.0,"tv":0.0,"id":35773667}]}]}
{"op":"mcm","clk":"4224419908","pt":1631453222674,"mc":[{"id":"1.187551126","rc":[{"batl":[[1,1.8,43.98],[2,1.82,2.66]],"ltp":0.0,"tv":0.0,"id":9629787}]}]}
{"op":"mcm","clk":"4224796349","pt":1631455274022,"mc":[{"id":"1.187551126","marketDefinition":{"bspMarket":false,"turnInPlayEnabled":true,"persistenceEnabled":true,"marketBaseRate":5.0,"eventId":"30895124","eventTypeId":"2","numberOfWinners":1,"bettingType":"ODDS","marketType":"MATCH_ODDS","marketTime":"2021-09-12T14:00:00.000Z","suspendTime":"2021-09-12T14:00:00.000Z","bspReconciled":false,"complete":true,"inPlay":true,"crossMatching":true,"runnersVoidable":false,"numberOfActiveRunners":2,"betDelay":5,"status":"OPEN","runners":[{"status":"ACTIVE","sortPriority":1,"id":35773667,"name":"R Gonzalez Vilar"},{"status":"ACTIVE","sortPriority":2,"id":9629787,"name":"I Shymanovich"}],"regulators":["MR_INT"],"countryCode":"GB","discountAllowed":true,"timezone":"GMT","openDate":"2021-09-12T14:00:00.000Z","version":4028507747,"name":"Match Odds","eventName":"R Gonzalez Vilar v I Shymanovich"},"rc":[{"batb":[[0,1.01,12],[1,1.02,0],[2,1.01,0]],"ltp":0.0,"tv":0.0,"id":35773667},{"batb":[[0,1.01,12],[1,1.1,0],[2,1.03,0]],"batl":[[1,1.8,0],[2,1.82,0]],"ltp":0.0,"tv":0.0,"id":9629787}]}]}
{"op":"mcm","clk":"4224797288","pt":1631455279200,"mc":[{"id":"1.187551126","rc":[{"batl":[[1,11.5,8.68]],"ltp":0.0,"tv":0.0,"id":9629787}]}]}
{"op":"mcm","clk":"4225097056","pt":1631456724984,"mc":[{"id":"1.187551126","marketDefinition":{"bspMarket":false,"turnInPlayEnabled":true,"persistenceEnabled":true,"marketBaseRate":5.0,"eventId":"30895124","eventTypeId":"2","numberOfWinners":1,"bettingType":"ODDS","marketType":"MATCH_ODDS","marketTime":"2021-09-12T14:25:24.000Z","suspendTime":"2021-09-12T14:25:24.000Z","bspReconciled":false,"complete":true,"inPlay":true,"crossMatching":true,"runnersVoidable":false,"numberOfActiveRunners":2,"betDelay":5,"status":"OPEN","runners":[{"status":"ACTIVE","sortPriority":1,"id":35773667,"name":"R Gonzalez Vilar"},{"status":"ACTIVE","sortPriority":2,"id":9629787,"name":"I Shymanovich"}],"regulators":["MR_INT"],"countryCode":"GB","discountAllowed":true,"timezone":"GMT","openDate":"2021-09-12T14:00:00.000Z","version":4028606442,"name":"Match Odds","eventName":"R Gonzalez Vilar v I Shymanovich"}}]}
{"op":"mcm","clk":"4225097496","pt":1631456726996,"mc":[{"id":"1.187551126","marketDefinition":{"bspMarket":false,"turnInPlayEnabled":true,"persistenceEnabled":true,"marketBaseRate":5.0,"eventId":"30895124","eventTypeId":"2","numberOfWinners":1,"bettingType":"ODDS","marketType":"MATCH_ODDS","marketTime":"2021-09-12T14:25:24.000Z","suspendTime":"2021-09-12T14:25:24.000Z","bspReconciled":false,"complete":true,"inPlay":true,"crossMatching":true,"runnersVoidable":false,"numberOfActiveRunners":2,"betDelay":5,"status":"OPEN","runners":[{"status":"ACTIVE","sortPriority":1,"id":35773667,"name":"R Gonzalez Vilar"},{"status":"ACTIVE","sortPriority":2,"id":9629787,"name":"I Shymanovich"}],"regulators":["MR_INT"],"countryCode":"GB","discountAllowed":true,"timezone":"GMT","openDate":"2021-09-12T14:25:24.000Z","version":4028606442,"name":"Match Odds","eventName":"R Gonzalez Vilar v I Shymanovich"}}]}
{"op":"mcm","clk":"4225226959","pt":1631457367559,"mc":[{"id":"1.187551126","rc":[{"trd":[[1.3,160]],"batl":[[0,11.5,8.68],[1,11.5,0]],"ltp":1.3,"tv":159.99,"id":9629787}],"tv":159.99}]}
{"op":"mcm","clk":"4225711908","pt":1631459906652,"mc":[{"id":"1.187551126","rc":[{"trd":[[1.01,24]],"batl":[[0,1.01,5.08],[1,11.5,8.68]],"ltp":1.01,"tv":183.99,"id":9629787}],"tv":183.99}]}
{"op":"mcm","clk":"4225991005","pt":1631461455597,"mc":[{"id":"1.187551126","rc":[{"trd":[[1.01,34.16]],"batb":[[0,1.01,1.26]],"batl":[[0,11.5,8.68],[1,11.5,0]],"ltp":1.01,"tv":194.16,"id":9629787}],"tv":194.16}]}
{"op":"mcm","clk":"4226206246","pt":1631462648905,"mc":[{"id":"1.187551126","rc":[{"batb":[[0,1.01,472.85]],"ltp":1.01,"tv":194.16,"id":9629787}]}]}
{"op":"mcm","clk":"4226378603","pt":1631463538345,"mc":[{"id":"1.187551126","rc":[{"batl":[[0,11.5,32.54]],"ltp":1.01,"tv":194.16,"id":9629787}]}]}
{"op":"mcm","clk":"4226382865","pt":1631463560656,"mc":[{"id":"1.187551126","marketDefinition":{"bspMarket":false,"turnInPlayEnabled":true,"persistenceEnabled":true,"marketBaseRate":5.0,"eventId":"30895124","eventTypeId":"2","numberOfWinners":1,"bettingType":"ODDS","marketType":"MATCH_ODDS","marketTime":"2021-09-12T14:25:24.000Z","suspendTime":"2021-09-12T14:25:24.000Z","bspReconciled":false,"complete":true,"inPlay":true,"crossMatching":true,"runnersVoidable":false,"numberOfActiveRunners":2,"betDelay":5,"status":"SUSPENDED","runners":[{"status":"ACTIVE","sortPriority":1,"id":35773667,"name":"R Gonzalez Vilar"},{"status":"ACTIVE","sortPriority":2,"id":9629787,"name":"I Shymanovich"}],"regulators":["MR_INT"],"countryCode":"GB","discountAllowed":true,"timezone":"GMT","openDate":"2021-09-12T14:25:24.000Z","version":4029079021,"name":"Match Odds","eventName":"R Gonzalez Vilar v I Shymanovich"}}]}
{"op":"mcm","clk":"4226396500","pt":1631463632789,"mc":[{"id":"1.187551126","tv":0.0}]}
{"op":"mcm","clk":"4226396745","pt":1631463634224,"mc":[{"id":"1.187551126","marketDefinition":{"bspMarket":false,"turnInPlayEnabled":true,"persistenceEnabled":true,"marketBaseRate":5.0,"eventId":"30895124","eventTypeId":"2","numberOfWinners":1,"bettingType":"ODDS","marketType":"MATCH_ODDS","marketTime":"2021-09-12T14:25:24.000Z","suspendTime":"2021-09-12T14:25:24.000Z","bspReconciled":false,"complete":true,"inPlay":true,"crossMatching":false,"runnersVoidable":false,"numberOfActiveRunners":0,"betDelay":5,"status":"CLOSED","settledTime":"2021-09-12T16:19:55.000Z","runners":[{"status":"LOSER","sortPriority":1,"id":35773667,"name":"R Gonzalez Vilar"},{"status":"WINNER","sortPriority":2,"id":9629787,"name":"I Shymanovich"}],"regulators":["MR_INT"],"countryCode":"GB","discountAllowed":true,"timezone":"GMT","openDate":"2021-09-12T14:25:24.000Z","version":4029083869,"name":"Match Odds","eventName":"R Gonzalez Vilar v I Shymanovich"}}]}
