{"op":"mcm","clk":"4229503644","pt":1631518765917,"mc":[{"id":"1.187595433","marketDefinition":{"bspMarket":false,"turnInPlayEnabled":true,"persistenceEnabled":true,"marketBaseRate":5.0,"eventId":"30897878","eventTypeId":"2","numberOfWinners":1,"bettingType":"ODDS","marketType":"MATCH_ODDS","marketTime":"2021-09-13T06:30:00.000Z","suspendTime":"2021-09-13T06:30:00.000Z","bspReconciled":false,"complete":true,"inPlay":false,"crossMatching":false,"runnersVoidable":false,"numberOfActiveRunners":2,"betDelay":0,"status":"OPEN","runners":[{"status":"ACTIVE","sortPriority":1,"id":9626775,"name":"A Gamiz"},{"status":"ACTIVE","sortPriority":2,"id":22955132,"name":"K Bartone"}],"regulators":["MR_INT"],"countryCode":"GB","discountAllowed":false,"timezone":"GMT","openDate":"2021-09-13T09:30:00.000Z","version":4030167318,"name":"Match Odds","eventName":"A Gamiz v K Bartone"},"rc":[{"batb":[[0,1.01,25]],"ltp":0.0,"tv":0.0,"id":9626775},{"batb":[[0,1.01,25]],"ltp":0.0,"tv":0.0,"id":22955132}]}]}
{"op":"mcm","clk":"4229503713","pt":1631518767640,"mc":[{"id":"1.187595433","marketDefinition":{"bspMarket":false,"turnInPlayEnabled":true,"persistenceEnabled":true,"marketBaseRate":5.0,"eventId":"30897878","eventTypeId":"2","numberOfWinners":1,"bettingType":"ODDS","marketType":"MATCH_ODDS","marketTime":"2021-09-13T06:30:00.000Z","suspendTime":"2021-09-13T06:30:00.000Z","bspReconciled":false,"complete":true,"inPlay":false,"crossMatching":false,"runnersVoidable":false,"numberOfActiveRunners":2,"betDelay":0,"status":"OPEN","runners":[{"status":"ACTIVE","sortPriority":1,"id":9626775,"name":"A Gamiz"},{"status":"ACTIVE","sortPriority":2,"id":22955132,"name":"K Bartone"}],"regulators":["MR_INT"],"countryCode":"GB","discountAllowed":true,"timezone":"GMT","openDate":"2021-09-13T09:30:00.000Z","version":4030167318,"name":"Match Odds","eventName":"A Gamiz v K Bartone"}}]}
{"op":"mcm","clk":"4229517271","pt":1631519122928,"mc":[{"id":"1.187595433","rc":[{"batb":[[0,1.01,7]],"ltp":0.0,"tv":0.0,"id":9626775},{"batb":[[0,1.01,7]],"ltp":0.0,"tv":0.0,"id":22955132}]}]}
{"op":"mcm","clk":"4229595840","pt":1631520877110,"mc":[{"id":"1.187595433","rc":[{"batl":[[0,2.88,106.47]],"ltp":0.0,"tv":0.0,"id":9626775}]}]}
{"op":"mcm","clk":"4229672301","pt":1631522300113,"mc":[{"id":"1.187595433","rc":[{"batl":[[0,2.16,2.66]],"ltp":0.0,"tv":0.0,"id":22955132}]}]}
{"op":"mcm","clk":"4229672498","pt":1631522304346,"mc":[{"id":"1.187595433","rc":[{"batb":[[0,1.16,15.97],[1,1.01,7]],"ltp":0.0,"tv":0.0,"id":22955132}]}]}
{"op":"mcm","clk":"4229708659","pt":1631523051673,"mc":[{"id":"1.187595433","rc":[{"batb":[[0,1.05,88.09],[1,1.01,7]],"ltp":0.0,"tv":0.0,"id":9626775}]}]}
{"op":"mcm","clk":"4229709133","pt":1631523059662,"mc":[{"id":"1.187595433","rc":[{"batb":[[0,1.18,246.65],[1,1.16,15.97],[2,1.01,7]],"ltp":0.0,"tv":0.0,"id":22955132}]}]}
{"op":"mcm","clk":"4229709233","pt":1631523061540,"mc":[{"id":"1.187595433","marketDefinition":{"bspMarket":false,"turnInPlayEnabled":true,"persistenceEnabled":true,"marketBaseRate":5.0,"eventId":"30897878","eventTypeId":"2","numberOfWinners":1,"bettingType":"ODDS","marketType":"MATCH_ODDS","marketTime":"2021-09-13T06:30:00.000Z","suspendTime":"2021-09-13T06:30:00.000Z","bspReconciled":false,"complete":true,"inPlay":false,"crossMatching":true,"runnersVoidable":false,"numberOfActiveRunners":2,"betDelay":0,"status":"OPEN","runners":[{"status":"ACTIVE","sortPriority":1,"id":9626775,"name":"A Gamiz"},{"status":"ACTIVE","sortPriority":2,"id":22955132,"name":"K Bartone"}],"regulators":["MR_INT"],"countryCode":"GB","discountAllowed":true,"timezone":"GMT","openDate":"2021-09-13T09:30:00.000Z","version":4030167318,"name":"Match Odds","eventName":"A Gamiz v K Bartone"}}]}
{"op":"mcm","clk":"4229743025","pt":1631523785965,"mc":[{"id":"1.187595433","rc":[{"batb":[[0,2.24,33.68],[1,1.05,88.04],[2,1.01,7]],"batl":[[0,2.88,106.55]],"ltp":0.0,"tv":0.0,"id":9626775},{"batb":[[0,1.57,73.27],[1,1.18,246.5],[2,1.16,15.98]],"batl":[[0,2.16,2.66]],"ltp":0.0,"tv":0.0,"id":22955132}]}]}
{"op":"mcm","clk":"4229762288","pt":1631524122825,"mc":[{"id":"1.187595433","rc":[{"batb":[[1,1.05,880.36]],"ltp":0.0,"tv":0.0,"id":9626775}]}]}
{"op":"mcm","clk":"4229805094","pt":1631524838249,"mc":[{"id":"1.187595433","rc":[{"batb":[[0,2.24,36.34]],"ltp":0.0,"tv":0.0,"id":9626775},{"batb":[[0,1.57,75.93]],"ltp":0.0,"tv":0.0,"id":22955132}]}]}
{"op":"mcm","clk":"4229822037","pt":1631525135701,"mc":[{"id":"1.187595433","rc":[{"trd":[[2.24,5.32]],"batb":[[0,2.24,33.68]],"ltp":2.24,"tv":5.32,"id":9626775}],"tv":5.32}]}
{"op":"mcm","clk":"4229822208","pt":1631525139520,"mc":[{"id":"1.187595433","rc":[{"batb":[[0,2.24,36.34]],"ltp":2.24,"tv":5.32,"id":9626775}]}]}
{"op":"mcm","clk":"4229840888","pt":1631525491703,"mc":[{"id":"1.187595433","marketDefinition":{"bspMarket":false,"turnInPlayEnabled":true,"persistenceEnabled":true,"marketBaseRate":5.0,"eventId":"30897878","eventTypeId":"2","numberOfWinners":1,"bettingType":"ODDS","marketType":"MATCH_ODDS","marketTime":"2021-09-13T06:30:00.000Z","suspendTime":"2021-09-13T06:30:00.000Z","bspReconciled":false,"complete":true,"inPlay":true,"crossMatching":true,"runnersVoidable":false,"numberOfActiveRunners":2,"betDelay":5,"status":"OPEN","runners":[{"status":"ACTIVE","sortPriority":1,"id":9626775,"name":"A Gamiz"},{"status":"ACTIVE","sortPriority":2,"id":22955132,"name":"K Bartone"}],"regulators":["MR_INT"],"countryCode":"GB","discountAllowed":true,"timezone":"GMT","openDate":"2021-09-13T09:30:00.000Z","version":4030508199,"name":"Match Odds","eventName":"A Gamiz v K Bartone"},"rc":[{"batb":[[0,1.01,7],[1,1.05,0],[2,1.01,0]],"ltp":2.24,"tv":5.32,"id":9626775},{"batb":[[0,1.01,7],[1,1.18,0],[2,1.16,0]],"ltp":0.0,"tv":0.0,"id":22955132}]}]}
{"op":"mcm","clk":"4229871828","pt":1631525938314,"mc":[{"id":"1.187595433","marketDefinition":{"bspMarket":false,"turnInPlayEnabled":true,"persistenceEnabled":true,"marketBaseRate":5.0,"eventId":"30897878","eventTypeId":"2","numberOfWinners":1,"bettingType":"ODDS","marketType":"MATCH_ODDS","marketTime":"2021-09-13T09:38:57.000Z","suspendTime":"2021-09-13T09:38:57.000Z","bspReconciled":false,"complete":true,"inPlay":true,"crossMatching":true,"runnersVoidable":false,"numberOfActiveRunners":2,"betDelay":5,"status":"OPEN","runners":[{"status":"ACTIVE","sortPriority":1,"id":9626775,"name":"A Gamiz"},{"status":"ACTIVE","sortPriority":2,"id":22955132,"name":"K Bartone"}],"regulators":["MR_INT"],"countryCode":"GB","discountAllowed":true,"timezone":"GMT","openDate":"2021-09-13T09:30:00.000Z","version":4030511453,"name":"Match Odds","eventName":"A Gamiz v K Bartone"}}]}
{"op":"mcm","clk":"4229872048","pt":1631525941326,"mc":[{"id":"1.187595433","marketDefinition":{"bspMarket":false,"turnInPlayEnabled":true,"persistenceEnabled":true,"marketBaseRate":5.0,"eventId":"30897878","eventTypeId":"2","numberOfWinners":1,"bettingType":"ODDS","marketType":"MATCH_ODDS","marketTime":"2021-09-13T09:38:57.000Z","suspendTime":"2021-09-13T09:38:57.000Z","bspReconciled":false,"complete":true,"inPlay":true,"crossMatching":true,"runnersVoidable":false,"numberOfActiveRunners":2,"betDelay":5,"status":"OPEN","runners":[{"status":"ACTIVE","sortPriority":1,"id":9626775,"name":"A Gamiz"},{"status":"ACTIVE","sortPriority":2,"id":22955132,"name":"K Bartone"}],"regulators":["MR_INT"],"countryCode":"GB","discountAllowed":true,"timezone":"GMT","openDate":"2021-09-13T09:38:57.000Z","version":4030511453,"name":"Match Odds","eventName":"A Gamiz v K Bartone"}}]}
{"op":"mcm","clk":"4229901375","pt":1631526349062,"mc":[{"id":"1.187595433","rc":[{"batb":[[0,1.7,415.78],[1,1.01,7]],"batl":[[0,2.82,234.93],[1,2.88,106.55]],"ltp":2.24,"tv":5.32,"id":9626775}]}]}
{"op":"mcm","clk":"4229903946","pt":1631526391910,"mc":[{"id":"1.187595433","rc":[{"batb":[[0,1.01,7],[1,1.01,0]],"batl":[[0,2.88,106.55],[1,2.88,0]],"ltp":2.24,"tv":5.32,"id":9626775}]}]}
{"op":"mcm","clk":"4229904315","pt":1631526397711,"mc":[{"id":"1.187595433","rc":[{"batb":[[0,1.82,407.57],[1,1.01,7]],"batl":[[1,3.15,203.58]],"ltp":2.24,"tv":5.32,"id":9626775}]}]}
{"op":"mcm","clk":"4229908981","pt":1631526459090,"mc":[{"id":"1.187595433","rc":[{"batl":[[1,3.15,0]],"ltp":2.24,"tv":5.32,"id":9626775}]}]}
{"op":"mcm","clk":"4229909409","pt":1631526464511,"mc":[{"id":"1.187595433","rc":[{"batl":[[1,2.92,224.75]],"ltp":2.24,"tv":5.32,"id":9626775}]}]}
{"op":"mcm","clk":"4229935753","pt":1631526740594,"mc":[{"id":"1.187595433","rc":[{"batb":[[0,1.01,7],[1,1.01,0]],"batl":[[1,2.92,0]],"ltp":2.24,"tv":5.32,"id":9626775}]}]}
{"op":"mcm","clk":"4229936153","pt":1631526746112,"mc":[{"id":"1.187595433","rc":[{"batb":[[0,1.62,421.99],[1,1.01,7]],"batl":[[0,2.6,261.64],[1,2.88,106.55]],"ltp":2.24,"tv":5.32,"id":9626775}]}]}
{"op":"mcm","clk":"4229942308","pt":1631526845327,"mc":[{"id":"1.187595433","rc":[{"batb":[[0,1.01,7],[1,1.01,0]],"ltp":2.24,"tv":5.32,"id":9626775}]}]}
{"op":"mcm","clk":"4229942580","pt":1631526851451,"mc":[{"id":"1.187595433","rc":[{"batb":[[0,1.7,415.78],[1,1.01,7]],"ltp":2.24,"tv":5.32,"id":9626775}]}]}
{"op":"mcm","clk":"4229948589","pt":1631526956256,"mc":[{"id":"1.187595433","rc":[{"batb":[[0,1.01,7],[1,1.01,0]],"batl":[[0,2.88,106.55],[1,2.88,0]],"ltp":2.24,"tv":5.32,"id":9626775}]}]}
{"op":"mcm","clk":"4229948885","pt":1631526961951,"mc":[{"id":"1.187595433","rc":[{"batb":[[0,1.77,408.62],[1,1.01,7]],"batl":[[1,3,216.82]],"ltp":2.24,"tv":5.32,"id":9626775}]}]}
{"op":"mcm","clk":"4229950226","pt":1631526985794,"mc":[{"id":"1.187595433","rc":[{"batb":[[0,1.01,7],[1,1.01,0]],"ltp":2.24,"tv":5.32,"id":9626775}]}]}
{"op":"mcm","clk":"4229950548","pt":1631526991210,"mc":[{"id":"1.187595433","rc":[{"batb":[[0,1.86,404.92],[1,1.01,7]],"ltp":2.24,"tv":5.32,"id":9626775}]}]}
{"op":"mcm","clk":"4229961603","pt":1631527160647,"mc":[{"id":"1.187595433","rc":[{"batb":[[0,1.01,7],[1,1.01,0]],"batl":[[1,3,0]],"ltp":2.24,"tv":5.32,"id":9626775}]}]}
{"op":"mcm","clk":"4229962102","pt":1631527166757,"mc":[{"id":"1.187595433","rc":[{"batb":[[0,1.97,401.09],[1,1.01,7]],"batl":[[1,3.65,173.1]],"ltp":2.24,"tv":5.32,"id":9626775}]}]}
{"op":"mcm","clk":"4229964486","pt":1631527200216,"mc":[{"id":"1.187595433","rc":[{"batl":[[1,3.65,0]],"ltp":2.24,"tv":5.32,"id":9626775}]}]}
{"op":"mcm","clk":"4229964998","pt":1631527206022,"mc":[{"id":"1.187595433","rc":[{"batl":[[1,3.3,194.95]],"ltp":2.24,"tv":5.32,"id":9626775}]}]}
{"op":"mcm","clk":"4229968477","pt":1631527250835,"mc":[{"id":"1.187595433","rc":[{"batb":[[0,1.01,7],[1,1.01,0]],"batl":[[1,3.3,0]],"ltp":2.24,"tv":5.32,"id":9626775}]}]}
{"op":"mcm","clk":"4229968877","pt":1631527256656,"mc":[{"id":"1.187595433","rc":[{"batb":[[0,1.74,410.67],[1,1.01,7]],"batl":[[1,2.92,224.75]],"ltp":2.24,"tv":5.32,"id":9626775}]}]}
{"op":"mcm","clk":"4229970427","pt":1631527279409,"mc":[{"id":"1.187595433","rc":[{"batl":[[1,2.92,0]],"ltp":2.24,"tv":5.32,"id":9626775}]}]}
{"op":"mcm","clk":"4229970803","pt":1631527284995,"mc":[{"id":"1.187595433","rc":[{"batl":[[0,2.72,245.36],[1,2.88,106.55]],"ltp":2.24,"tv":5.32,"id":9626775}]}]}
{"op":"mcm","clk":"4229981004","pt":1631527435675,"mc":[{"id":"1.187595433","rc":[{"batb":[[0,1.01,7],[1,1.01,0]],"batl":[[0,2.88,106.55],[1,2.88,0]],"ltp":2.24,"tv":5.32,"id":9626775}]}]}
{"op":"mcm","clk":"4229981469","pt":1631527442021,"mc":[{"id":"1.187595433","rc":[{"batb":[[0,1.62,421.99],[1,1.01,7]],"batl":[[0,2.6,261.64],[1,2.88,106.55]],"ltp":2.24,"tv":5.32,"id":9626775}]}]}
{"op":"mcm","clk":"4229981689","pt":1631527444821,"mc":[{"id":"1.187595433","rc":[{"batl":[[0,2.88,106.55],[1,2.88,0]],"ltp":2.24,"tv":5.32,"id":9626775}]}]}
{"op":"mcm","clk":"4229982127","pt":1631527451105,"mc":[{"id":"1.187595433","rc":[{"batl":[[0,2.5,278.88],[1,2.88,106.55]],"ltp":2.24,"tv":5.32,"id":9626775}]}]}
{"op":"mcm","clk":"4229986299","pt":1631527512920,"mc":[{"id":"1.187595433","rc":[{"batb":[[0,1.01,7],[1,1.01,0]],"batl":[[0,2.88,106.55],[1,2.88,0]],"ltp":2.24,"tv":5.32,"id":9626775}]}]}
{"op":"mcm","clk":"4229986700","pt":1631527518910,"mc":[{"id":"1.187595433","rc":[{"batb":[[0,1.74,410.67],[1,1.01,7]],"batl":[[1,2.92,224.75]],"ltp":2.24,"tv":5.32,"id":9626775}]}]}
{"op":"mcm","clk":"4229988424","pt":1631527546484,"mc":[{"id":"1.187595433","rc":[{"batb":[[0,1.01,7],[1,1.01,0]],"batl":[[1,2.92,0]],"ltp":2.24,"tv":5.32,"id":9626775}]}]}
{"op":"mcm","clk":"4229988799","pt":1631527552372,"mc":[{"id":"1.187595433","rc":[{"batb":[[0,1.62,421.99],[1,1.01,7]],"batl":[[0,2.6,261.64],[1,2.88,106.55]],"ltp":2.24,"tv":5.32,"id":9626775}]}]}
{"op":"mcm","clk":"4229989979","pt":1631527569799,"mc":[{"id":"1.187595433","rc":[{"batb":[[0,1.01,7],[1,1.01,0]],"ltp":2.24,"tv":5.32,"id":9626775}]}]}
{"op":"mcm","clk":"4229990375","pt":1631527575737,"mc":[{"id":"1.187595433","rc":[{"batb":[[0,1.67,416.23],[1,1.01,7]],"ltp":2.24,"tv":5.32,"id":9626775}]}]}
{"op":"mcm","clk":"4229991162","pt":1631527587035,"mc":[{"id":"1.187595433","rc":[{"batb":[[0,1.01,7],[1,1.01,0]],"batl":[[0,2.88,106.55],[1,2.88,0]],"ltp":2.24,"tv":5.32,"id":9626775}]}]}
{"op":"mcm","clk":"4229991502","pt":1631527592817,"mc":[{"id":"1.187595433","rc":[{"batb":[[0,1.74,410.67],[1,1.01,7]],"batl":[[1,2.92,224.75]],"ltp":2.24,"tv":5.32,"id":9626775}]}]}
{"op":"mcm","clk":"4229993011","pt":1631527616472,"mc":[{"id":"1.187595433","rc":[{"batb":[[0,1.01,7],[1,1.01,0]],"batl":[[1,2.92,0]],"ltp":2.24,"tv":5.32,"id":9626775}]}]}
{"op":"mcm","clk":"4229993385","pt":1631527622166,"mc":[{"id":"1.187595433","rc":[{"batb":[[0,1.62,421.99],[1,1.01,7]],"batl":[[0,2.6,261.64],[1,2.88,106.55]],"ltp":2.24,"tv":5.32,"id":9626775}]}]}
{"op":"mcm","clk":"4229995821","pt":1631527657008,"mc":[{"id":"1.187595433","rc":[{"batb":[[0,1.01,7],[1,1.01,0]],"batl":[[0,2.88,106.55],[1,2.88,0]],"ltp":2.24,"tv":5.32,"id":9626775}]}]}
{"op":"mcm","clk":"4229996210","pt":1631527662603,"mc":[{"id":"1.187595433","rc":[{"batb":[[0,1.74,410.67],[1,1.01,7]],"batl":[[1,2.92,224.75]],"ltp":2.24,"tv":5.32,"id":9626775}]}]}
{"op":"mcm","clk":"4229998832","pt":1631527698659,"mc":[{"id":"1.187595433","rc":[{"batb":[[0,1.01,7],[1,1.01,0]],"ltp":2.24,"tv":5.32,"id":9626775}]}]}
{"op":"mcm","clk":"4229999245","pt":1631527704154,"mc":[{"id":"1.187595433","rc":[{"batb":[[0,1.82,407.57],[1,1.01,7]],"ltp":2.24,"tv":5.32,"id":9626775}]}]}
{"op":"mcm","clk":"4230012519","pt":1631527875370,"mc":[{"id":"1.187595433","rc":[{"batb":[[0,1.01,7],[1,1.01,0]],"batl":[[1,2.92,0]],"ltp":2.24,"tv":5.32,"id":9626775}]}]}
{"op":"mcm","clk":"4230012968","pt":1631527881727,"mc":[{"id":"1.187595433","rc":[{"batb":[[0,1.97,401.09],[1,1.01,7]],"batl":[[1,3.65,173.1]],"ltp":2.24,"tv":5.32,"id":9626775}]}]}
{"op":"mcm","clk":"4230015795","pt":1631527920353,"mc":[{"id":"1.187595433","rc":[{"batl":[[1,3.65,0]],"ltp":2.24,"tv":5.32,"id":9626775}]}]}
{"op":"mcm","clk":"4230016308","pt":1631527926259,"mc":[{"id":"1.187595433","rc":[{"batl":[[1,3.15,203.58]],"ltp":2.24,"tv":5.32,"id":9626775}]}]}
{"op":"mcm","clk":"4230016966","pt":1631527933703,"mc":[{"id":"1.187595433","rc":[{"batb":[[0,1.01,7],[1,1.01,0]],"batl":[[1,3.15,0]],"ltp":2.24,"tv":5.32,"id":9626775}]}]}
{"op":"mcm","clk":"4230034465","pt":1631528073846,"mc":[{"id":"1.187595433","rc":[{"batb":[[0,1.62,421.99],[1,1.01,7]],"batl":[[0,2.6,261.64],[1,2.88,106.55]],"ltp":2.24,"tv":5.32,"id":9626775}]}]}
{"op":"mcm","clk":"4230045090","pt":1631528181881,"mc":[{"id":"1.187595433","rc":[{"batb":[[0,1.01,7],[1,1.01,0]],"batl":[[0,2.88,106.55],[1,2.88,0]],"ltp":2.24,"tv":5.32,"id":9626775}]}]}
{"op":"mcm","clk":"4230066279","pt":1631528499854,"mc":[{"id":"1.187595433","rc":[{"batb":[[0,1.52,432.21],[1,1.01,7]],"batl":[[0,2.36,303.89],[1,2.88,106.55]],"ltp":2.24,"tv":5.32,"id":9626775}]}]}
{"op":"mcm","clk":"4230067292","pt":1631528515276,"mc":[{"id":"1.187595433","rc":[{"batl":[[0,2.1,256.04],[1,2.36,303.89],[2,2.88,106.55]],"ltp":2.24,"tv":5.32,"id":9626775}]}]}
{"op":"mcm","clk":"4230067912","pt":1631528524894,"mc":[{"id":"1.187595433","rc":[{"batb":[[0,1.01,7],[1,1.01,0]],"batl":[[1,2.88,106.55],[2,2.88,0]],"ltp":2.24,"tv":5.32,"id":9626775}]}]}
{"op":"mcm","clk":"4230069423","pt":1631528547507,"mc":[{"id":"1.187595433","rc":[{"batb":[[0,1.38,455.53],[1,1.01,7]],"batl":[[0,2.04,389.06],[1,2.1,256.04],[2,2.88,106.55]],"ltp":2.24,"tv":5.32,"id":9626775}]}]}
{"op":"mcm","clk":"4230070425","pt":1631528562307,"mc":[{"id":"1.187595433","rc":[{"batl":[[1,2.88,106.55],[2,2.88,0]],"ltp":2.24,"tv":5.32,"id":9626775}]}]}
{"op":"mcm","clk":"4230070715","pt":1631528566409,"mc":[{"id":"1.187595433","rc":[{"batl":[[0,1.8,256.04],[1,2.04,389.06],[2,2.88,106.55]],"ltp":2.24,"tv":5.32,"id":9626775}]}]}
{"op":"mcm","clk":"4230070941","pt":1631528569515,"mc":[{"id":"1.187595433","rc":[{"batb":[[0,1.47,256.04],[1,1.38,455.53],[2,1.01,7]],"ltp":2.24,"tv":5.32,"id":9626775}]}]}
{"op":"mcm","clk":"4230071722","pt":1631528579249,"mc":[{"id":"1.187595433","rc":[{"batb":[[0,1.38,455.53],[1,1.01,7],[2,1.01,0]],"ltp":2.24,"tv":5.32,"id":9626775}]}]}
{"op":"mcm","clk":"4230071782","pt":1631528580256,"mc":[{"id":"1.187595433","rc":[{"batb":[[0,1.01,7],[1,1.01,0]],"batl":[[1,2.88,106.55],[2,2.88,0]],"ltp":2.24,"tv":5.32,"id":9626775}]}]}
{"op":"mcm","clk":"4230072165","pt":1631528585353,"mc":[{"id":"1.187595433","rc":[{"batb":[[0,1.4,256.04],[1,1.01,7]],"ltp":2.24,"tv":5.32,"id":9626775}]}]}
{"op":"mcm","clk":"4230072222","pt":1631528586138,"mc":[{"id":"1.187595433","rc":[{"batb":[[1,1.31,485.05],[2,1.01,7]],"batl":[[1,1.89,442.15],[2,2.88,106.55]],"ltp":2.24,"tv":5.32,"id":9626775}]}]}
{"op":"mcm","clk":"4230073042","pt":1631528596143,"mc":[{"id":"1.187595433","rc":[{"batl":[[0,1.6,256.04],[1,1.8,256.04],[2,1.89,442.15]],"ltp":2.24,"tv":5.32,"id":9626775}]}]}
{"op":"mcm","clk":"4230073915","pt":1631528607863,"mc":[{"id":"1.187595433","rc":[{"batb":[[1,1.01,7],[2,1.01,0]],"ltp":2.24,"tv":5.32,"id":9626775}]}]}
{"op":"mcm","clk":"4230074015","pt":1631528609160,"mc":[{"id":"1.187595433","rc":[{"batl":[[0,1.8,256.04],[1,1.89,442.15],[2,2.88,106.55]],"ltp":2.24,"tv":5.32,"id":9626775}]}]}
{"op":"mcm","clk":"4230074349","pt":1631528613471,"mc":[{"id":"1.187595433","rc":[{"batb":[[1,1.38,455.53],[2,1.01,7]],"batl":[[0,1.89,442.15],[1,2.88,106.55],[2,2.88,0]],"ltp":2.24,"tv":5.32,"id":9626775}]}]}
{"op":"mcm","clk":"4230074458","pt":1631528614874,"mc":[{"id":"1.187595433","rc":[{"batl":[[0,1.7,256.04],[1,1.89,442.15],[2,2.88,106.55]],"ltp":2.24,"tv":5.32,"id":9626775}]}]}
{"op":"mcm","clk":"4230074776","pt":1631528619081,"mc":[{"id":"1.187595433","rc":[{"batb":[[1,1.01,7],[2,1.01,0]],"batl":[[1,2.88,106.55],[2,2.88,0]],"ltp":2.24,"tv":5.32,"id":9626775}]}]}
{"op":"mcm","clk":"4230075169","pt":1631528624898,"mc":[{"id":"1.187595433","rc":[{"batb":[[0,1.44,443.07],[1,1.4,256.04],[2,1.01,7]],"batl":[[1,2.16,348.23],[2,2.88,106.55]],"ltp":2.24,"tv":5.32,"id":9626775}]}]}
{"op":"mcm","clk":"4230075577","pt":1631528631188,"mc":[{"id":"1.187595433","rc":[{"batl":[[0,2.16,348.23],[1,2.88,106.55],[2,2.88,0]],"ltp":2.24,"tv":5.32,"id":9626775}]}]}
{"op":"mcm","clk":"4230075880","pt":1631528635390,"mc":[{"id":"1.187595433","rc":[{"batb":[[0,1.56,256.04],[1,1.44,443.07],[2,1.4,256.04]],"ltp":2.24,"tv":5.32,"id":9626775}]}]}
{"op":"mcm","clk":"4230076017","pt":1631528637206,"mc":[{"id":"1.187595433","rc":[{"batl":[[0,1.8,256.04],[1,2.16,348.23],[2,2.88,106.55]],"ltp":2.24,"tv":5.32,"id":9626775}]}]}
{"op":"mcm","clk":"4230077126","pt":1631528651730,"mc":[{"id":"1.187595433","rc":[{"batb":[[1,1.4,256.04],[2,1.01,7]],"ltp":2.24,"tv":5.32,"id":9626775}]}]}
{"op":"mcm","clk":"4230077473","pt":1631528656552,"mc":[{"id":"1.187595433","rc":[{"batl":[[0,2.16,348.23],[1,2.88,106.55],[2,2.88,0]],"ltp":2.24,"tv":5.32,"id":9626775}]}]}
{"op":"mcm","clk":"4230077514","pt":1631528657230,"mc":[{"id":"1.187595433","rc":[{"batb":[[1,1.5,433.64],[2,1.4,256.04]],"ltp":2.24,"tv":5.32,"id":9626775}]}]}
{"op":"mcm","clk":"4230077690","pt":1631528660640,"mc":[{"id":"1.187595433","rc":[{"batb":[[0,1.66,256.04],[1,1.56,256.04],[2,1.5,433.64]],"ltp":2.24,"tv":5.32,"id":9626775}]}]}
{"op":"mcm","clk":"4230077861","pt":1631528663179,"mc":[{"id":"1.187595433","rc":[{"batl":[[0,1.9,256.04],[1,2.16,348.23],[2,2.88,106.55]],"ltp":2.24,"tv":5.32,"id":9626775}]}]}
{"op":"mcm","clk":"4230079347","pt":1631528684604,"mc":[{"id":"1.187595433","rc":[{"batb":[[2,1.4,256.04]],"batl":[[1,2.88,106.55],[2,2.88,0]],"ltp":2.24,"tv":5.32,"id":9626775}]}]}
{"op":"mcm","clk":"4230079525","pt":1631528687608,"mc":[{"id":"1.187595433","rc":[{"batl":[[0,2.88,106.55],[1,2.88,0]],"ltp":2.24,"tv":5.32,"id":9626775}]}]}
{"op":"mcm","clk":"4230079714","pt":1631528690811,"mc":[{"id":"1.187595433","rc":[{"batb":[[2,1.55,427.14]],"batl":[[0,2.42,291.05],[1,2.88,106.55]],"ltp":2.24,"tv":5.32,"id":9626775}]}]}
{"op":"mcm","clk":"4230079923","pt":1631528693803,"mc":[{"id":"1.187595433","rc":[{"batb":[[0,1.75,256.04],[1,1.66,256.04],[2,1.56,256.04]],"ltp":2.24,"tv":5.32,"id":9626775}]}]}
{"op":"mcm","clk":"4230080072","pt":1631528695919,"mc":[{"id":"1.187595433","rc":[{"batl":[[0,2.1,256.04],[1,2.42,291.05],[2,2.88,106.55]],"ltp":2.24,"tv":5.32,"id":9626775}]}]}
{"op":"mcm","clk":"4230082243","pt":1631528723439,"mc":[{"id":"1.187595433","rc":[{"batb":[[1,1.56,256.04],[2,1.55,427.14]],"ltp":2.24,"tv":5.32,"id":9626775}]}]}
{"op":"mcm","clk":"4230087199","pt":1631528795948,"mc":[{"id":"1.187595433","rc":[{"batb":[[2,1.4,256.04]],"ltp":2.24,"tv":5.32,"id":9626775}]}]}
{"op":"mcm","clk":"4230087555","pt":1631528801546,"mc":[{"id":"1.187595433","rc":[{"batb":[[1,1.62,421.99],[2,1.56,256.04]],"batl":[[0,2.42,291.05],[1,2.88,106.55],[2,2.88,0]],"ltp":2.24,"tv":5.32,"id":9626775}]}]}
{"op":"mcm","clk":"4230090214","pt":1631528837032,"mc":[{"id":"1.187595433","rc":[{"batb":[[1,1.56,256.04],[2,1.4,256.04]],"batl":[[0,2.88,106.55],[1,2.88,0]],"ltp":2.24,"tv":5.32,"id":9626775}]}]}
{"op":"mcm","clk":"4230090402","pt":1631528839533,"mc":[{"id":"1.187595433","rc":[{"batb":[[0,1.56,256.04],[1,1.4,256.04],[2,1.01,7]],"ltp":2.24,"tv":5.32,"id":9626775}]}]}
{"op":"mcm","clk":"4230090733","pt":1631528843341,"mc":[{"id":"1.187595433","rc":[{"batb":[[0,1.74,410.67],[1,1.56,256.04],[2,1.4,256.04]],"batl":[[1,2.92,224.75]],"ltp":2.24,"tv":5.32,"id":9626775},{"batl":[[0,2,256.04]],"ltp":0.0,"tv":0.0,"id":22955132}]}]}
{"op":"mcm","clk":"4230091468","pt":1631528851938,"mc":[{"id":"1.187595433","rc":[{"batb":[[0,1.65,256.04],[1,1.01,7]],"ltp":0.0,"tv":0.0,"id":22955132}]}]}
{"op":"mcm","clk":"4230093487","pt":1631528876880,"mc":[{"id":"1.187595433","rc":[{"batb":[[0,1.56,256.04],[1,1.4,256.04],[2,1.01,7]],"ltp":2.24,"tv":5.32,"id":9626775}]}]}
{"op":"mcm","clk":"4230093587","pt":1631528878289,"mc":[{"id":"1.187595433","rc":[{"batb":[[0,1.01,7],[1,1.01,0]],"ltp":0.0,"tv":0.0,"id":22955132}]}]}
{"op":"mcm","clk":"4230093933","pt":1631528882652,"mc":[{"id":"1.187595433","rc":[{"batb":[[0,1.82,407.57],[1,1.56,256.04],[2,1.4,256.04]],"ltp":2.24,"tv":5.32,"id":9626775}]}]}
{"op":"mcm","clk":"4230094158","pt":1631528885761,"mc":[{"id":"1.187595433","rc":[{"batb":[[0,1.56,256.04],[1,1.01,7]],"ltp":0.0,"tv":0.0,"id":22955132}]}]}
{"op":"mcm","clk":"4230094281","pt":1631528887165,"mc":[{"id":"1.187595433","rc":[{"batl":[[0,1.8,256.04]],"ltp":0.0,"tv":0.0,"id":22955132}]}]}
{"op":"mcm","clk":"4230098231","pt":1631528943840,"mc":[{"id":"1.187595433","rc":[{"batl":[[0,1.93,256.04]],"ltp":0.0,"tv":0.0,"id":22955132}]}]}
{"op":"mcm","clk":"4230098957","pt":1631528953441,"mc":[{"id":"1.187595433","rc":[{"batl":[[1,2.92,0]],"ltp":2.24,"tv":5.32,"id":9626775}]}]}
{"op":"mcm","clk":"4230099362","pt":1631528958943,"mc":[{"id":"1.187595433","rc":[{"batl":[[1,3.3,194.95]],"ltp":2.24,"tv":5.32,"id":9626775}]}]}
{"op":"mcm","clk":"4230101600","pt":1631528990309,"mc":[{"id":"1.187595433","rc":[{"batl":[[0,1.78,256.04]],"ltp":0.0,"tv":0.0,"id":22955132}]}]}
{"op":"mcm","clk":"4230102194","pt":1631528998400,"mc":[{"id":"1.187595433","rc":[{"batl":[[1,3.3,0]],"ltp":2.24,"tv":5.32,"id":9626775}]}]}
{"op":"mcm","clk":"4230102747","pt":1631529004613,"mc":[{"id":"1.187595433","rc":[{"batl":[[1,2.92,224.75]],"ltp":2.24,"tv":5.32,"id":9626775}]}]}
{"op":"mcm","clk":"4230102981","pt":1631529007438,"mc":[{"id":"1.187595433","rc":[{"batl":[[0,1.94,256.04]],"ltp":0.0,"tv":0.0,"id":22955132}]}]}
{"op":"mcm","clk":"4230103958","pt":1631529016856,"mc":[{"id":"1.187595433","rc":[{"batl":[[1,2.92,0]],"ltp":2.24,"tv":5.32,"id":9626775}]}]}
{"op":"mcm","clk":"4230104509","pt":1631529022842,"mc":[{"id":"1.187595433","rc":[{"batl":[[1,3.3,194.95]],"ltp":2.24,"tv":5.32,"id":9626775}]}]}
{"op":"mcm","clk":"4230106416","pt":1631529043571,"mc":[{"id":"1.187595433","rc":[{"batl":[[1,3.3,0]],"ltp":2.24,"tv":5.32,"id":9626775}]}]}
{"op":"mcm","clk":"4230106942","pt":1631529049486,"mc":[{"id":"1.187595433","rc":[{"batl":[[0,2.82,234.93],[1,2.88,106.55]],"ltp":2.24,"tv":5.32,"id":9626775}]}]}
{"op":"mcm","clk":"4230107260","pt":1631529052716,"mc":[{"id":"1.187595433","rc":[{"batb":[[0,1.75,256.04],[1,1.56,256.04],[2,1.01,7]],"ltp":0.0,"tv":0.0,"id":22955132}]}]}
{"op":"mcm","clk":"4230109751","pt":1631529080247,"mc":[{"id":"1.187595433","rc":[{"batb":[[0,1.56,256.04],[1,1.4,256.04],[2,1.01,7]],"batl":[[0,2.88,106.55],[1,2.88,0]],"ltp":2.24,"tv":5.32,"id":9626775}]}]}
{"op":"mcm","clk":"4230110277","pt":1631529085824,"mc":[{"id":"1.187595433","rc":[{"batb":[[0,1.62,421.99],[1,1.56,256.04],[2,1.4,256.04]],"batl":[[0,2.6,261.64],[1,2.88,106.55]],"ltp":2.24,"tv":5.32,"id":9626775},{"batb":[[0,1.56,256.04],[1,1.01,7],[2,1.01,0]],"ltp":0.0,"tv":0.0,"id":22955132}]}]}
{"op":"mcm","clk":"4230110426","pt":1631529087336,"mc":[{"id":"1.187595433","rc":[{"batb":[[0,1.01,7],[1,1.01,0]],"ltp":0.0,"tv":0.0,"id":22955132}]}]}
{"op":"mcm","clk":"4230110606","pt":1631529089768,"mc":[{"id":"1.187595433","rc":[{"batb":[[0,1.9,256.04],[1,1.01,7]],"ltp":0.0,"tv":0.0,"id":22955132}]}]}
{"op":"mcm","clk":"4230111310","pt":1631529098457,"mc":[{"id":"1.187595433","rc":[{"batl":[[0,2.88,106.55],[1,2.88,0]],"ltp":2.24,"tv":5.32,"id":9626775}]}]}
{"op":"mcm","clk":"4230111799","pt":1631529103971,"mc":[{"id":"1.187595433","rc":[{"batl":[[0,2.5,278.88],[1,2.88,106.55]],"ltp":2.24,"tv":5.32,"id":9626775}]}]}
{"op":"mcm","clk":"4230112521","pt":1631529112306,"mc":[{"id":"1.187595433","rc":[{"batb":[[0,1.01,7],[1,1.01,0]],"ltp":0.0,"tv":0.0,"id":22955132}]}]}
{"op":"mcm","clk":"4230116221","pt":1631529154065,"mc":[{"id":"1.187595433","rc":[{"batb":[[1,1.01,7],[2,1.4,0]],"ltp":2.24,"tv":5.32,"id":9626775}]}]}
{"op":"mcm","clk":"4230118171","pt":1631529179589,"mc":[{"id":"1.187595433","rc":[{"batl":[[0,1.81,10.53],[1,2.5,278.88],[2,2.88,106.55]],"ltp":2.24,"tv":5.32,"id":9626775}]}]}
{"op":"mcm","clk":"4230121679","pt":1631529226215,"mc":[{"id":"1.187595433","rc":[{"batb":[[0,1.01,7],[1,1.01,0]],"batl":[[1,2.88,106.55],[2,2.88,0]],"ltp":2.24,"tv":5.32,"id":9626775}]}]}
{"op":"mcm","clk":"4230122092","pt":1631529231960,"mc":[{"id":"1.187595433","rc":[{"batb":[[0,1.46,442.58],[1,1.01,7]],"batl":[[1,2.22,334.21],[2,2.88,106.55]],"ltp":2.24,"tv":5.32,"id":9626775}]}]}
{"op":"mcm","clk":"4230125099","pt":1631529270106,"mc":[{"id":"1.187595433","rc":[{"batb":[[0,1.01,7],[1,1.01,0]],"batl":[[1,2.88,106.55],[2,2.88,0]],"ltp":2.24,"tv":5.32,"id":9626775}]}]}
{"op":"mcm","clk":"4230125532","pt":1631529275505,"mc":[{"id":"1.187595433","rc":[{"batb":[[0,1.38,455.53],[1,1.01,7]],"batl":[[1,2.04,389.06],[2,2.88,106.55]],"ltp":2.24,"tv":5.32,"id":9626775}]}]}
{"op":"mcm","clk":"4230128597","pt":1631529316074,"mc":[{"id":"1.187595433","rc":[{"batb":[[0,1.01,7],[1,1.01,0]],"batl":[[1,2.88,106.55],[2,2.88,0]],"ltp":2.24,"tv":5.32,"id":9626775}]}]}
{"op":"mcm","clk":"4230129077","pt":1631529322272,"mc":[{"id":"1.187595433","rc":[{"batb":[[0,1.31,485.05],[1,1.01,7]],"batl":[[1,1.89,442.15],[2,2.88,106.55]],"ltp":2.24,"tv":5.32,"id":9626775}]}]}
{"op":"mcm","clk":"4230131033","pt":1631529346713,"mc":[{"id":"1.187595433","rc":[{"batb":[[0,1.01,7],[1,1.01,0]],"ltp":2.24,"tv":5.32,"id":9626775}]}]}
{"op":"mcm","clk":"4230131523","pt":1631529352712,"mc":[{"id":"1.187595433","rc":[{"batb":[[0,1.34,472.77],[1,1.01,7]],"ltp":2.24,"tv":5.32,"id":9626775}]}]}
{"op":"mcm","clk":"4230133310","pt":1631529376430,"mc":[{"id":"1.187595433","rc":[{"batb":[[0,1.01,7],[1,1.01,0]],"batl":[[1,2.88,106.55],[2,2.88,0]],"ltp":2.24,"tv":5.32,"id":9626775}]}]}
{"op":"mcm","clk":"4230133783","pt":1631529382460,"mc":[{"id":"1.187595433","rc":[{"batb":[[0,1.25,513.07],[1,1.01,7]],"batl":[[0,1.77,508.52],[1,1.81,10.53],[2,2.88,106.55]],"ltp":2.24,"tv":5.32,"id":9626775}]}]}
{"op":"mcm","clk":"4230152563","pt":1631529622960,"mc":[{"id":"1.187595433","rc":[{"batb":[[0,1.01,7],[1,1.01,0]],"ltp":2.24,"tv":5.32,"id":9626775}]}]}
{"op":"mcm","clk":"4230152983","pt":1631529629070,"mc":[{"id":"1.187595433","rc":[{"batb":[[0,1.31,485.05],[1,1.01,7]],"ltp":2.24,"tv":5.32,"id":9626775}]}]}
{"op":"mcm","clk":"4230154706","pt":1631529651496,"mc":[{"id":"1.187595433","rc":[{"batb":[[0,1.01,7],[1,1.01,0]],"batl":[[0,1.81,10.53],[1,2.88,106.55],[2,2.88,0]],"ltp":2.24,"tv":5.32,"id":9626775}]}]}
{"op":"mcm","clk":"4230155174","pt":1631529657628,"mc":[{"id":"1.187595433","rc":[{"batb":[[0,1.34,472.77],[1,1.01,7]],"batl":[[1,1.95,416.34],[2,2.88,106.55]],"ltp":2.24,"tv":5.32,"id":9626775}]}]}
{"op":"mcm","clk":"4230156172","pt":1631529668945,"mc":[{"id":"1.187595433","rc":[{"batb":[[0,1.01,7],[1,1.01,0]],"batl":[[1,2.88,106.55],[2,2.88,0]],"ltp":2.24,"tv":5.32,"id":9626775}]}]}
{"op":"mcm","clk":"4230156265","pt":1631529670035,"mc":[{"id":"1.187595433","rc":[{"batl":[[1,2.88,0]],"ltp":2.24,"tv":5.32,"id":9626775}]}]}
{"op":"mcm","clk":"4230156946","pt":1631529678918,"mc":[{"id":"1.187595433","rc":[{"batb":[[0,1.31,485.05],[1,1.01,7]],"batl":[[0,1.89,442.15]],"ltp":2.24,"tv":5.32,"id":9626775}]}]}
{"op":"mcm","clk":"4230157209","pt":1631529682240,"mc":[{"id":"1.187595433","rc":[{"batl":[[0,1.56,10.53],[1,1.89,442.15]],"ltp":2.24,"tv":5.32,"id":9626775}]}]}
{"op":"mcm","clk":"4230157549","pt":1631529686862,"mc":[{"id":"1.187595433","rc":[{"batl":[[0,1.56,5.35]],"ltp":2.24,"tv":5.32,"id":9626775}]}]}
{"op":"mcm","clk":"4230157715","pt":1631529689162,"mc":[{"id":"1.187595433","rc":[{"batb":[[0,1.01,7],[1,1.01,0]],"batl":[[1,1.89,0]],"ltp":2.24,"tv":5.32,"id":9626775}]}]}
{"op":"mcm","clk":"4230169483","pt":1631529835025,"mc":[{"id":"1.187595433","rc":[{"batb":[[0,1.18,558.4],[1,1.01,7]],"batl":[[1,1.62,624.1]],"ltp":2.24,"tv":5.32,"id":9626775}]}]}
{"op":"mcm","clk":"4230174234","pt":1631529896280,"mc":[{"id":"1.187595433","rc":[{"batb":[[0,1.01,7],[1,1.01,0]],"batl":[[1,1.62,0]],"ltp":2.24,"tv":5.32,"id":9626775}]}]}
{"op":"mcm","clk":"4230174869","pt":1631529901707,"mc":[{"id":"1.187595433","rc":[{"batb":[[0,1.14,620.09],[1,1.01,7]],"batl":[[0,1.55,701.66],[1,1.56,5.35]],"ltp":2.24,"tv":5.32,"id":9626775}]}]}
{"op":"mcm","clk":"4230175867","pt":1631529913524,"mc":[{"id":"1.187595433","rc":[{"batb":[[0,1.01,7],[1,1.01,0]],"ltp":2.24,"tv":5.32,"id":9626775}]}]}
{"op":"mcm","clk":"4230176334","pt":1631529919032,"mc":[{"id":"1.187595433","rc":[{"batb":[[0,1.12,660.6],[1,1.01,7]],"ltp":2.24,"tv":5.32,"id":9626775}]}]}
{"op":"mcm","clk":"4230177898","pt":1631529938865,"mc":[{"id":"1.187595433","rc":[{"batb":[[0,1.01,7],[1,1.01,0]],"ltp":2.24,"tv":5.32,"id":9626775}]}]}
{"op":"mcm","clk":"4230178457","pt":1631529945267,"mc":[{"id":"1.187595433","rc":[{"batb":[[0,1.14,620.09],[1,1.01,7]],"ltp":2.24,"tv":5.32,"id":9626775}]}]}
{"op":"mcm","clk":"4230181327","pt":1631529970400,"mc":[{"id":"1.187595433","rc":[{"batb":[[0,1.01,7],[1,1.01,0]],"ltp":2.24,"tv":5.32,"id":9626775}]}]}
{"op":"mcm","clk":"4230181874","pt":1631529976643,"mc":[{"id":"1.187595433","rc":[{"batb":[[0,1.18,558.4],[1,1.01,7]],"ltp":2.24,"tv":5.32,"id":9626775}]}]}
{"op":"mcm","clk":"4230185318","pt":1631530014170,"mc":[{"id":"1.187595433","rc":[{"batb":[[0,1.01,7],[1,1.01,0]],"ltp":2.24,"tv":5.32,"id":9626775}]}]}
{"op":"mcm","clk":"4230185810","pt":1631530020205,"mc":[{"id":"1.187595433","rc":[{"batb":[[0,1.2,539.24],[1,1.01,7]],"ltp":2.24,"tv":5.32,"id":9626775}]}]}
{"op":"mcm","clk":"4230187432","pt":1631530038545,"mc":[{"id":"1.187595433","rc":[{"batb":[[0,1.01,7],[1,1.01,0]],"batl":[[0,1.56,5.35],[1,1.56,0]],"ltp":2.24,"tv":5.32,"id":9626775}]}]}
{"op":"mcm","clk":"4230187935","pt":1631530044513,"mc":[{"id":"1.187595433","rc":[{"batb":[[0,1.22,531.25],[1,1.01,7]],"batl":[[1,1.71,550.62]],"ltp":2.24,"tv":5.32,"id":9626775}]}]}
{"op":"mcm","clk":"4230189360","pt":1631530061925,"mc":[{"id":"1.187595433","rc":[{"batb":[[0,1.01,7],[1,1.01,0]],"batl":[[1,1.71,0]],"ltp":2.24,"tv":5.32,"id":9626775}]}]}
{"op":"mcm","clk":"4230189886","pt":1631530067778,"mc":[{"id":"1.187595433","rc":[{"batb":[[0,1.16,585.23],[1,1.01,7]],"batl":[[1,1.58,660.85]],"ltp":2.24,"tv":5.32,"id":9626775}]}]}
{"op":"mcm","clk":"4230192047","pt":1631530093556,"mc":[{"id":"1.187595433","rc":[{"batb":[[0,1.01,7],[1,1.01,0]],"ltp":2.24,"tv":5.32,"id":9626775}]}]}
{"op":"mcm","clk":"4230192442","pt":1631530099206,"mc":[{"id":"1.187595433","rc":[{"batb":[[0,1.2,539.24],[1,1.01,7]],"ltp":2.24,"tv":5.32,"id":9626775}]}]}
{"op":"mcm","clk":"4230194117","pt":1631530121127,"mc":[{"id":"1.187595433","rc":[{"batb":[[0,1.01,7],[1,1.01,0]],"ltp":2.24,"tv":5.32,"id":9626775}]}]}
{"op":"mcm","clk":"4230194251","pt":1631530122831,"mc":[{"id":"1.187595433","rc":[{"batl":[[0,1.2,55],[1,1.56,5.35],[2,1.58,660.85]],"ltp":2.24,"tv":5.32,"id":9626775}]}]}
{"op":"mcm","clk":"4230194408","pt":1631530125118,"mc":[{"id":"1.187595433","rc":[{"batl":[[0,1.56,5.35],[1,1.58,660.85],[2,1.58,0]],"ltp":2.24,"tv":5.32,"id":9626775}]}]}
{"op":"mcm","clk":"4230194619","pt":1631530127434,"mc":[{"id":"1.187595433","rc":[{"batb":[[0,1.23,524.63],[1,1.01,7]],"ltp":2.24,"tv":5.32,"id":9626775}]}]}
{"op":"mcm","clk":"4230197871","pt":1631530164862,"mc":[{"id":"1.187595433","rc":[{"batb":[[0,1.01,7],[1,1.01,0]],"batl":[[1,1.58,0]],"ltp":2.24,"tv":5.32,"id":9626775}]}]}
{"op":"mcm","clk":"4230198368","pt":1631530171095,"mc":[{"id":"1.187595433","rc":[{"batb":[[0,1.28,493.56],[1,1.01,7]],"batl":[[1,1.82,476.51]],"ltp":2.24,"tv":5.32,"id":9626775}]}]}
{"op":"mcm","clk":"4230201210","pt":1631530204511,"mc":[{"id":"1.187595433","rc":[{"batb":[[0,1.01,7],[1,1.01,0]],"batl":[[1,1.82,0]],"ltp":2.24,"tv":5.32,"id":9626775}]}]}
{"op":"mcm","clk":"4230201720","pt":1631530210631,"mc":[{"id":"1.187595433","rc":[{"batb":[[0,1.23,524.63],[1,1.01,7]],"batl":[[1,1.73,535.9]],"ltp":2.24,"tv":5.32,"id":9626775}]}]}
{"op":"mcm","clk":"4230203537","pt":1631530230975,"mc":[{"id":"1.187595433","rc":[{"batb":[[0,1.01,7],[1,1.01,0]],"batl":[[1,1.73,0]],"ltp":2.24,"tv":5.32,"id":9626775}]}]}
{"op":"mcm","clk":"4230204074","pt":1631530236893,"mc":[{"id":"1.187595433","rc":[{"batb":[[0,1.2,539.24],[1,1.01,7]],"batl":[[1,1.66,588.96]],"ltp":2.24,"tv":5.32,"id":9626775}]}]}
{"op":"mcm","clk":"4230206101","pt":1631530262598,"mc":[{"id":"1.187595433","rc":[{"batb":[[0,1.01,7],[1,1.01,0]],"ltp":2.24,"tv":5.32,"id":9626775}]}]}
{"op":"mcm","clk":"4230206577","pt":1631530268226,"mc":[{"id":"1.187595433","rc":[{"batb":[[0,1.25,513.07],[1,1.01,7]],"ltp":2.24,"tv":5.32,"id":9626775}]}]}
{"op":"mcm","clk":"4230211809","pt":1631530329811,"mc":[{"id":"1.187595433","rc":[{"batb":[[0,1.01,7],[1,1.01,0]],"batl":[[1,1.66,0]],"ltp":2.24,"tv":5.32,"id":9626775}]}]}
{"op":"mcm","clk":"4230212349","pt":1631530335986,"mc":[{"id":"1.187595433","rc":[{"batb":[[0,1.31,485.05],[1,1.01,7]],"batl":[[1,1.89,442.15]],"ltp":2.24,"tv":5.32,"id":9626775}]}]}
{"op":"mcm","clk":"4230213594","pt":1631530351202,"mc":[{"id":"1.187595433","rc":[{"batb":[[0,1.01,7],[1,1.01,0]],"batl":[[1,1.89,0]],"ltp":2.24,"tv":5.32,"id":9626775}]}]}
{"op":"mcm","clk":"4230214096","pt":1631530357332,"mc":[{"id":"1.187595433","rc":[{"batb":[[0,1.25,513.07],[1,1.01,7]],"batl":[[1,1.77,508.52]],"ltp":2.24,"tv":5.32,"id":9626775}]}]}
{"op":"mcm","clk":"4230216028","pt":1631530384860,"mc":[{"id":"1.187595433","rc":[{"batb":[[0,1.01,7],[1,1.01,0]],"ltp":2.24,"tv":5.32,"id":9626775}]}]}
{"op":"mcm","clk":"4230216431","pt":1631530390777,"mc":[{"id":"1.187595433","rc":[{"batb":[[0,1.31,485.05],[1,1.01,7]],"ltp":2.24,"tv":5.32,"id":9626775}]}]}
{"op":"mcm","clk":"4230218804","pt":1631530424394,"mc":[{"id":"1.187595433","rc":[{"batb":[[0,1.01,7],[1,1.01,0]],"batl":[[1,1.77,0]],"ltp":2.24,"tv":5.32,"id":9626775}]}]}
{"op":"mcm","clk":"4230219256","pt":1631530430120,"mc":[{"id":"1.187595433","rc":[{"batb":[[0,1.38,455.53],[1,1.01,7]],"batl":[[1,2.04,389.06]],"ltp":2.24,"tv":5.32,"id":9626775}]}]}
{"op":"mcm","clk":"4230228788","pt":1631530560699,"mc":[{"id":"1.187595433","rc":[{"batb":[[0,1.01,7],[1,1.01,0]],"batl":[[1,2.04,0]],"ltp":2.24,"tv":5.32,"id":9626775}]}]}
{"op":"mcm","clk":"4230229223","pt":1631530566878,"mc":[{"id":"1.187595433","rc":[{"batb":[[0,1.28,493.56],[1,1.01,7]],"batl":[[1,1.82,476.51]],"ltp":2.24,"tv":5.32,"id":9626775}]}]}
{"op":"mcm","clk":"4230230500","pt":1631530584110,"mc":[{"id":"1.187595433","rc":[{"batb":[[0,1.01,7],[1,1.01,0]],"ltp":2.24,"tv":5.32,"id":9626775}]}]}
{"op":"mcm","clk":"4230230921","pt":1631530590057,"mc":[{"id":"1.187595433","rc":[{"batb":[[0,1.31,485.05],[1,1.01,7]],"ltp":2.24,"tv":5.32,"id":9626775}]}]}
{"op":"mcm","clk":"4230232147","pt":1631530607566,"mc":[{"id":"1.187595433","rc":[{"batb":[[0,1.01,7],[1,1.01,0]],"batl":[[1,1.82,0]],"ltp":2.24,"tv":5.32,"id":9626775}]}]}
{"op":"mcm","clk":"4230232591","pt":1631530613480,"mc":[{"id":"1.187595433","rc":[{"batb":[[0,1.38,455.53],[1,1.01,7]],"batl":[[1,2.04,389.06]],"ltp":2.24,"tv":5.32,"id":9626775}]}]}
{"op":"mcm","clk":"4230233840","pt":1631530630012,"mc":[{"id":"1.187595433","rc":[{"batb":[[0,1.01,7],[1,1.01,0]],"batl":[[1,2.04,0]],"ltp":2.24,"tv":5.32,"id":9626775}]}]}
{"op":"mcm","clk":"4230234257","pt":1631530635624,"mc":[{"id":"1.187595433","rc":[{"batb":[[0,1.31,485.05],[1,1.01,7]],"batl":[[1,1.89,442.15]],"ltp":2.24,"tv":5.32,"id":9626775}]}]}
{"op":"mcm","clk":"4230235954","pt":1631530658419,"mc":[{"id":"1.187595433","rc":[{"batb":[[0,1.01,7],[1,1.01,0]],"batl":[[1,1.89,0]],"ltp":2.24,"tv":5.32,"id":9626775}]}]}
{"op":"mcm","clk":"4230236369","pt":1631530664048,"mc":[{"id":"1.187595433","rc":[{"batb":[[0,1.23,524.63],[1,1.01,7]],"batl":[[1,1.73,535.9]],"ltp":2.24,"tv":5.32,"id":9626775}]}]}
{"op":"mcm","clk":"4230239703","pt":1631530707209,"mc":[{"id":"1.187595433","rc":[{"batb":[[0,1.01,7],[1,1.01,0]],"ltp":2.24,"tv":5.32,"id":9626775}]}]}
{"op":"mcm","clk":"4230240166","pt":1631530713519,"mc":[{"id":"1.187595433","rc":[{"batb":[[0,1.28,493.56],[1,1.01,7]],"ltp":2.24,"tv":5.32,"id":9626775}]}]}
{"op":"mcm","clk":"4230242949","pt":1631530750826,"mc":[{"id":"1.187595433","rc":[{"batb":[[0,1.01,7],[1,1.01,0]],"batl":[[1,1.73,0]],"ltp":2.24,"tv":5.32,"id":9626775}]}]}
{"op":"mcm","clk":"4230243359","pt":1631530757053,"mc":[{"id":"1.187595433","rc":[{"batb":[[0,1.34,472.77],[1,1.01,7]],"batl":[[1,1.95,416.34]],"ltp":2.24,"tv":5.32,"id":9626775}]}]}
{"op":"mcm","clk":"4230244571","pt":1631530773153,"mc":[{"id":"1.187595433","rc":[{"batb":[[0,1.01,7],[1,1.01,0]],"batl":[[1,1.95,0]],"ltp":2.24,"tv":5.32,"id":9626775}]}]}
{"op":"mcm","clk":"4230244923","pt":1631530779184,"mc":[{"id":"1.187595433","rc":[{"batb":[[0,1.28,493.56],[1,1.01,7]],"batl":[[1,1.82,476.51]],"ltp":2.24,"tv":5.32,"id":9626775}]}]}
{"op":"mcm","clk":"4230247987","pt":1631530817949,"mc":[{"id":"1.187595433","rc":[{"trd":[[2.24,5.32]],"batb":[[0,1.01,7],[1,1.01,0]],"batl":[[0,1.56,5.34],[1,1.82,0]],"ltp":2.24,"tv":5.31,"id":9626775}],"tv":5.31}]}
{"op":"mcm","clk":"4230248495","pt":1631530823744,"mc":[{"id":"1.187595433","rc":[{"batb":[[0,1.23,523.6],[1,1.01,7]],"batl":[[1,1.73,534.85]],"ltp":2.24,"tv":5.31,"id":9626775}]}]}
{"op":"mcm","clk":"4230250261","pt":1631530846372,"mc":[{"id":"1.187595433","rc":[{"batb":[[0,1.01,7],[1,1.01,0]],"ltp":2.24,"tv":5.31,"id":9626775}]}]}
{"op":"mcm","clk":"4230250709","pt":1631530852083,"mc":[{"id":"1.187595433","rc":[{"batb":[[0,1.31,484.1],[1,1.01,7]],"ltp":2.24,"tv":5.31,"id":9626775}]}]}
{"op":"mcm","clk":"4230253097","pt":1631530881021,"mc":[{"id":"1.187595433","rc":[{"batb":[[0,1.01,7],[1,1.01,0]],"ltp":2.24,"tv":5.31,"id":9626775}]}]}
{"op":"mcm","clk":"4230253538","pt":1631530887325,"mc":[{"id":"1.187595433","rc":[{"batb":[[0,1.23,523.6],[1,1.01,7]],"ltp":2.24,"tv":5.31,"id":9626775}]}]}
{"op":"mcm","clk":"4230257365","pt":1631530936756,"mc":[{"id":"1.187595433","rc":[{"batb":[[0,1.01,7],[1,1.01,0]],"ltp":2.24,"tv":5.31,"id":9626775}]}]}
{"op":"mcm","clk":"4230257800","pt":1631530942892,"mc":[{"id":"1.187595433","rc":[{"batb":[[0,1.31,484.1],[1,1.01,7]],"ltp":2.24,"tv":5.31,"id":9626775}]}]}
{"op":"mcm","clk":"4230260132","pt":1631530971338,"mc":[{"id":"1.187595433","rc":[{"batb":[[0,1.01,7],[1,1.01,0]],"ltp":2.24,"tv":5.31,"id":9626775}]}]}
{"op":"mcm","clk":"4230260591","pt":1631530977370,"mc":[{"id":"1.187595433","rc":[{"batb":[[0,1.25,512.06],[1,1.01,7]],"ltp":2.24,"tv":5.31,"id":9626775}]}]}
{"op":"mcm","clk":"4230263963","pt":1631531017101,"mc":[{"id":"1.187595433","rc":[{"batb":[[0,1.01,7],[1,1.01,0]],"batl":[[1,1.73,0]],"ltp":2.24,"tv":5.31,"id":9626775}]}]}
{"op":"mcm","clk":"4230264379","pt":1631531023002,"mc":[{"id":"1.187595433","rc":[{"batb":[[0,1.2,538.19],[1,1.01,7]],"batl":[[1,1.66,587.81]],"ltp":2.24,"tv":5.31,"id":9626775}]}]}
{"op":"mcm","clk":"4230265896","pt":1631531040790,"mc":[{"id":"1.187595433","rc":[{"batl":[[0,1.5,255.54],[1,1.56,5.34],[2,1.66,587.81]],"ltp":2.24,"tv":5.31,"id":9626775}]}]}
{"op":"mcm","clk":"4230267044","pt":1631531054731,"mc":[{"id":"1.187595433","rc":[{"batb":[[0,1.01,7],[1,1.01,0]],"batl":[[2,1.66,0]],"ltp":2.24,"tv":5.31,"id":9626775}]}]}
{"op":"mcm","clk":"4230267549","pt":1631531060428,"mc":[{"id":"1.187595433","rc":[{"batb":[[0,1.16,584.08],[1,1.01,7]],"batl":[[2,1.58,659.56]],"ltp":2.24,"tv":5.31,"id":9626775}]}]}
{"op":"mcm","clk":"4230267909","pt":1631531064823,"mc":[{"id":"1.187595433","rc":[{"batb":[[0,1.17,255.54],[1,1.16,584.08],[2,1.01,7]],"ltp":2.24,"tv":5.31,"id":9626775}]}]}
{"op":"mcm","clk":"4230275501","pt":1631531152278,"mc":[{"id":"1.187595433","rc":[{"batb":[[1,1.01,7],[2,1.01,0]],"batl":[[2,1.58,0]],"ltp":2.24,"tv":5.31,"id":9626775}]}]}
{"op":"mcm","clk":"4230275916","pt":1631531156563,"mc":[{"id":"1.187595433","rc":[{"batb":[[0,1.01,7],[1,1.01,0]],"ltp":2.24,"tv":5.31,"id":9626775}]}]}
{"op":"mcm","clk":"4230276115","pt":1631531158587,"mc":[{"id":"1.187595433","rc":[{"batb":[[0,1.12,659.31],[1,1.01,7]],"batl":[[1,1.51,751.3],[2,1.56,5.34]],"ltp":2.24,"tv":5.31,"id":9626775}]}]}
{"op":"mcm","clk":"4230276479","pt":1631531162407,"mc":[{"id":"1.187595433","rc":[{"batb":[[1,1.1,255.54],[2,1.01,7]],"ltp":2.24,"tv":5.31,"id":9626775}]}]}
{"op":"mcm","clk":"4230276586","pt":1631531163704,"mc":[{"id":"1.187595433","rc":[{"batl":[[0,1.3,255.54],[1,1.5,255.54],[2,1.51,751.3]],"ltp":2.24,"tv":5.31,"id":9626775}]}]}
{"op":"mcm","clk":"4230278240","pt":1631531181716,"mc":[{"id":"1.187595433","rc":[{"batb":[[0,1.1,255.54],[1,1.01,7],[2,1.01,0]],"ltp":2.24,"tv":5.31,"id":9626775}]}]}
{"op":"mcm","clk":"4230278770","pt":1631531187794,"mc":[{"id":"1.187595433","rc":[{"batb":[[0,1.16,584.08],[1,1.1,255.54],[2,1.01,7]],"ltp":2.24,"tv":5.31,"id":9626775}]}]}
{"op":"mcm","clk":"4230280864","pt":1631531210156,"mc":[{"id":"1.187595433","rc":[{"batb":[[0,1.1,255.54],[1,1.01,7],[2,1.01,0]],"ltp":2.24,"tv":5.31,"id":9626775}]}]}
{"op":"mcm","clk":"4230281342","pt":1631531214755,"mc":[{"id":"1.187595433","rc":[{"batl":[[1,1.51,751.3],[2,1.56,5.34]],"ltp":2.24,"tv":5.31,"id":9626775}]}]}
{"op":"mcm","clk":"4230281479","pt":1631531216064,"mc":[{"id":"1.187595433","rc":[{"batb":[[0,1.12,659.31],[1,1.1,255.54],[2,1.01,7]],"ltp":2.24,"tv":5.31,"id":9626775}]}]}
{"op":"mcm","clk":"4230283797","pt":1631531240573,"mc":[{"id":"1.187595433","rc":[{"batb":[[0,1.1,255.54],[1,1.01,7],[2,1.01,0]],"ltp":2.24,"tv":5.31,"id":9626775}]}]}
{"op":"mcm","clk":"4230284253","pt":1631531246572,"mc":[{"id":"1.187595433","rc":[{"batb":[[0,1.16,584.08],[1,1.1,255.54],[2,1.01,7]],"ltp":2.24,"tv":5.31,"id":9626775}]}]}
{"op":"mcm","clk":"4230284861","pt":1631531254302,"mc":[{"id":"1.187595433","rc":[{"batl":[[0,1.51,751.3],[1,1.56,5.34],[2,1.56,0]],"ltp":2.24,"tv":5.31,"id":9626775}]}]}
{"op":"mcm","clk":"4230285235","pt":1631531258915,"mc":[{"id":"1.187595433","rc":[{"batb":[[1,1.01,7],[2,1.01,0]],"ltp":2.24,"tv":5.31,"id":9626775}]}]}
{"op":"mcm","clk":"4230285338","pt":1631531260008,"mc":[{"id":"1.187595433","rc":[{"batl":[[0,1.4,255.54],[1,1.51,751.3],[2,1.56,5.34]],"ltp":2.24,"tv":5.31,"id":9626775}]}]}
{"op":"mcm","clk":"4230285497","pt":1631531261930,"mc":[{"id":"1.187595433","rc":[{"batb":[[0,1.2,255.54],[1,1.16,584.08],[2,1.01,7]],"ltp":2.24,"tv":5.31,"id":9626775}]}]}
{"op":"mcm","clk":"4230286744","pt":1631531278262,"mc":[{"id":"1.187595433","rc":[{"batb":[[1,1.01,7],[2,1.01,0]],"batl":[[1,1.56,5.34],[2,1.56,0]],"ltp":2.24,"tv":5.31,"id":9626775}]}]}
{"op":"mcm","clk":"4230287187","pt":1631531283930,"mc":[{"id":"1.187595433","rc":[{"batb":[[0,1.2,793.72]],"batl":[[2,1.66,587.81]],"ltp":2.24,"tv":5.31,"id":9626775}]}]}
{"op":"mcm","clk":"4230289642","pt":1631531313607,"mc":[{"id":"1.187595433","rc":[{"batb":[[0,1.2,255.54]],"ltp":2.24,"tv":5.31,"id":9626775}]}]}
{"op":"mcm","clk":"4230290112","pt":1631531319311,"mc":[{"id":"1.187595433","rc":[{"batb":[[0,1.23,523.6],[1,1.2,255.54],[2,1.01,7]],"ltp":2.24,"tv":5.31,"id":9626775}]}]}
{"op":"mcm","clk":"4230291085","pt":1631531331016,"mc":[{"id":"1.187595433","rc":[{"batl":[[0,1.56,5.34],[1,1.66,587.81],[2,1.66,0]],"ltp":2.24,"tv":5.31,"id":9626775}]}]}
{"op":"mcm","clk":"4230294840","pt":1631531374479,"mc":[{"id":"1.187595433","rc":[{"batb":[[0,1.2,255.54],[1,1.01,7],[2,1.01,0]],"batl":[[1,1.66,0]],"ltp":2.24,"tv":5.31,"id":9626775}]}]}
{"op":"mcm","clk":"4230295223","pt":1631531379892,"mc":[{"id":"1.187595433","rc":[{"batb":[[0,1.28,492.6],[1,1.2,255.54],[2,1.01,7]],"batl":[[1,1.82,475.58]],"ltp":2.24,"tv":5.31,"id":9626775}]}]}
{"op":"mcm","clk":"4230295590","pt":1631531384887,"mc":[{"id":"1.187595433","rc":[{"batb":[[0,1.3,255.54],[1,1.28,492.6],[2,1.2,255.54]],"ltp":2.24,"tv":5.31,"id":9626775}]}]}
{"op":"mcm","clk":"4230296418","pt":1631531394819,"mc":[{"id":"1.187595433","rc":[{"batb":[[1,1.2,255.54],[2,1.01,7]],"ltp":2.24,"tv":5.31,"id":9626775}]}]}
{"op":"mcm","clk":"4230296957","pt":1631531401121,"mc":[{"id":"1.187595433","rc":[{"batb":[[0,1.34,471.85],[1,1.3,255.54]],"ltp":2.24,"tv":5.31,"id":9626775}]}]}
{"op":"mcm","clk":"4230298042","pt":1631531413631,"mc":[{"id":"1.187595433","rc":[{"batl":[[0,1.82,475.58],[1,1.82,0]],"ltp":2.24,"tv":5.31,"id":9626775}]}]}
{"op":"mcm","clk":"4230299035","pt":1631531425148,"mc":[{"id":"1.187595433","rc":[{"batb":[[0,1.3,255.54],[1,1.01,7],[2,1.01,0]],"ltp":2.24,"tv":5.31,"id":9626775}]}]}
{"op":"mcm","clk":"4230299587","pt":1631531431350,"mc":[{"id":"1.187595433","rc":[{"batb":[[0,1.4,457.22],[1,1.3,255.54],[2,1.01,7]],"batl":[[0,2.1,368.32]],"ltp":2.24,"tv":5.31,"id":9626775}]}]}
{"op":"mcm","clk":"4230299696","pt":1631531432545,"mc":[{"id":"1.187595433","rc":[{"batb":[[0,1.4,712.76],[1,1.01,7],[2,1.01,0]],"ltp":2.24,"tv":5.31,"id":9626775}]}]}
{"op":"mcm","clk":"4230299761","pt":1631531433638,"mc":[{"id":"1.187595433","rc":[{"batb":[[0,1.5,255.54],[1,1.4,712.76],[2,1.01,7]],"ltp":2.24,"tv":5.31,"id":9626775}]}]}
{"op":"mcm","clk":"4230299926","pt":1631531435462,"mc":[{"id":"1.187595433","rc":[{"batl":[[0,1.8,255.54],[1,2.1,368.32]],"ltp":2.24,"tv":5.31,"id":9626775}]}]}
{"op":"mcm","clk":"4230300119","pt":1631531437856,"mc":[{"id":"1.187595433","rc":[{"batl":[[0,2.78,20.25]],"ltp":0.0,"tv":0.0,"id":22955132}]}]}
{"op":"mcm","clk":"4230300506","pt":1631531442575,"mc":[{"id":"1.187595433","rc":[{"batb":[[1,1.4,715.4]],"ltp":2.24,"tv":5.31,"id":9626775}]}]}
{"op":"mcm","clk":"4230300696","pt":1631531444492,"mc":[{"id":"1.187595433","rc":[{"batb":[[1,1.4,258.18]],"batl":[[1,2.1,0]],"ltp":2.24,"tv":5.31,"id":9626775}]}]}
{"op":"mcm","clk":"4230301783","pt":1631531457413,"mc":[{"id":"1.187595433","rc":[{"batb":[[1,1.4,2.64]],"ltp":2.24,"tv":5.31,"id":9626775}]}]}
{"op":"mcm","clk":"4230305301","pt":1631531501148,"mc":[{"id":"1.187595433","rc":[{"batb":[[0,1.4,2.64],[1,1.01,7],[2,1.01,0]],"ltp":2.24,"tv":5.31,"id":9626775}]}]}
{"op":"mcm","clk":"4230305881","pt":1631531507767,"mc":[{"id":"1.187595433","rc":[{"batb":[[0,1.4,258.18]],"ltp":2.24,"tv":5.31,"id":9626775}]}]}
{"op":"mcm","clk":"4230306101","pt":1631531510263,"mc":[{"id":"1.187595433","rc":[{"batl":[[0,1.6,255.54],[1,1.8,255.54]],"ltp":2.24,"tv":5.31,"id":9626775}]}]}
{"op":"mcm","clk":"4230307107","pt":1631531520465,"mc":[{"id":"1.187595433","rc":[{"batl":[[0,1.8,255.54],[1,1.8,0]],"ltp":2.24,"tv":5.31,"id":9626775}]}]}
{"op":"mcm","clk":"4230307196","pt":1631531521405,"mc":[{"id":"1.187595433","rc":[{"batb":[[0,1.4,2.64]],"ltp":2.24,"tv":5.31,"id":9626775}]}]}
{"op":"mcm","clk":"4230308099","pt":1631531529596,"mc":[{"id":"1.187595433","rc":[{"batl":[[0,1.5,255.54],[1,1.8,255.54]],"ltp":2.24,"tv":5.31,"id":9626775}]}]}
{"op":"mcm","clk":"4230308211","pt":1631531530796,"mc":[{"id":"1.187595433","rc":[{"batl":[[0,1.5,261.62]],"ltp":2.24,"tv":5.31,"id":9626775}]}]}
{"op":"mcm","clk":"4230308497","pt":1631531533876,"mc":[{"id":"1.187595433","rc":[{"batb":[[1,1.3,255.54],[2,1.01,7]],"ltp":2.24,"tv":5.31,"id":9626775}]}]}
{"op":"mcm","clk":"4230311353","pt":1631531566318,"mc":[{"id":"1.187595433","rc":[{"batb":[[1,1.01,7],[2,1.01,0]],"ltp":2.24,"tv":5.31,"id":9626775}]}]}
{"op":"mcm","clk":"4230311740","pt":1631531570545,"mc":[{"id":"1.187595433","rc":[{"trd":[[1.4,4]],"batb":[[0,1.01,7.64],[1,1.01,0]],"ltp":1.4,"tv":9.31,"id":9626775}],"tv":9.31}]}
{"op":"mcm","clk":"4230311765","pt":1631531570812,"mc":[{"id":"1.187595433","rc":[{"trd":[[1.4,5.28]],"batb":[[0,1.01,7]],"ltp":1.4,"tv":10.59,"id":9626775}],"tv":10.59}]}
{"op":"mcm","clk":"4230312492","pt":1631531579242,"mc":[{"id":"1.187595433","rc":[{"batb":[[0,1.2,255.54],[1,1.01,7]],"ltp":1.4,"tv":10.59,"id":9626775}]}]}
{"op":"mcm","clk":"4230313117","pt":1631531585350,"mc":[{"id":"1.187595433","rc":[{"batb":[[1,1.18,557.31],[2,1.01,7]],"batl":[[1,1.62,622.88],[2,1.8,255.54]],"ltp":1.4,"tv":10.59,"id":9626775}]}]}
{"op":"mcm","clk":"4230313575","pt":1631531590482,"mc":[{"id":"1.187595433","rc":[{"batb":[[1,1.01,7],[2,1.01,0]],"batl":[[1,1.8,255.54],[2,1.8,0]],"ltp":1.4,"tv":10.59,"id":9626775}]}]}
{"op":"mcm","clk":"4230313913","pt":1631531594252,"mc":[{"id":"1.187595433","rc":[{"batb":[[0,1.01,7],[1,1.01,0]],"ltp":1.4,"tv":10.59,"id":9626775}]}]}
{"op":"mcm","clk":"4230314098","pt":1631531596341,"mc":[{"id":"1.187595433","rc":[{"batb":[[0,1.14,618.88],[1,1.01,7]],"batl":[[1,1.55,700.29],[2,1.8,255.54]],"ltp":1.4,"tv":10.59,"id":9626775}]}]}
{"op":"mcm","clk":"4230314283","pt":1631531598466,"mc":[{"id":"1.187595433","rc":[{"batl":[[0,1.3,255.54],[1,1.5,261.62],[2,1.55,700.29]],"ltp":1.4,"tv":10.59,"id":9626775}]}]}
{"op":"mcm","clk":"4230314560","pt":1631531601434,"mc":[{"id":"1.187595433","rc":[{"batb":[[0,1.14,874.41]],"batl":[[1,1.5,270.74]],"ltp":1.4,"tv":10.59,"id":9626775}]}]}
{"op":"mcm","clk":"4230316153","pt":1631531619950,"mc":[{"id":"1.187595433","rc":[{"batl":[[0,8,6.6]],"ltp":0.0,"tv":0.0,"id":22955132}]}]}
{"op":"mcm","clk":"4230320673","pt":1631531676536,"mc":[{"id":"1.187595433","rc":[{"batl":[[1,1.5,264.66]],"ltp":1.4,"tv":10.59,"id":9626775}]}]}
{"op":"mcm","clk":"4230320997","pt":1631531680250,"mc":[{"id":"1.187595433","rc":[{"batl":[[1,1.5,9.12]],"ltp":1.4,"tv":10.59,"id":9626775}]}]}
{"op":"mcm","clk":"4230321139","pt":1631531682062,"mc":[{"id":"1.187595433","rc":[{"batb":[[0,1.14,255.54]],"batl":[[2,1.8,255.54]],"ltp":1.4,"tv":10.59,"id":9626775}]}]}
{"op":"mcm","clk":"4230321659","pt":1631531688334,"mc":[{"id":"1.187595433","rc":[{"trd":[[1.14,2.76]],"batb":[[0,1.14,254.16]],"ltp":1.14,"tv":13.35,"id":9626775}],"tv":13.35}]}
{"op":"mcm","clk":"4230321684","pt":1631531688659,"mc":[{"id":"1.187595433","rc":[{"batb":[[1,1.1,733.19],[2,1.01,7]],"batl":[[1,1.48,795.77],[2,1.5,9.12]],"ltp":1.14,"tv":13.35,"id":9626775}]}]}
{"op":"mcm","clk":"4230322006","pt":1631531692534,"mc":[{"id":"1.187595433","rc":[{"batb":[[0,1.1,733.19],[1,1.01,7],[2,1.01,0]],"ltp":1.14,"tv":13.35,"id":9626775}]}]}
{"op":"mcm","clk":"4230322584","pt":1631531699958,"mc":[{"id":"1.187595433","rc":[{"batb":[[0,1.12,255.54],[1,1.1,733.19],[2,1.01,7]],"ltp":1.14,"tv":13.35,"id":9626775}]}]}
{"op":"mcm","clk":"4230322763","pt":1631531701889,"mc":[{"id":"1.187595433","rc":[{"trd":[[1.14,4.14]],"ltp":1.14,"tv":14.73,"id":9626775},{"trd":[[8,0.2]],"batl":[[0,8,6.4]],"ltp":8.0,"tv":0.2,"id":22955132}],"tv":14.93}]}
{"op":"mcm","clk":"4230322945","pt":1631531703967,"mc":[{"id":"1.187595433","rc":[{"batb":[[1,1.01,7],[2,1.01,0]],"batl":[[1,1.5,9.12],[2,1.8,255.54]],"ltp":1.14,"tv":14.73,"id":9626775}]}]}
{"op":"mcm","clk":"4230323475","pt":1631531709662,"mc":[{"id":"1.187595433","rc":[{"batb":[[1,1.06,1007.61],[2,1.01,7]],"batl":[[1,1.41,915.1],[2,1.5,9.12]],"ltp":1.14,"tv":14.73,"id":9626775}]}]}
{"op":"mcm","clk":"4230323966","pt":1631531715606,"mc":[{"id":"1.187595433","rc":[{"batb":[[0,1.06,1007.61],[1,1.01,7],[2,1.01,0]],"ltp":1.14,"tv":14.73,"id":9626775}]}]}
{"op":"mcm","clk":"4230324269","pt":1631531719095,"mc":[{"id":"1.187595433","rc":[{"batl":[[0,1.41,915.1],[1,1.5,9.12],[2,1.8,255.54]],"ltp":1.14,"tv":14.73,"id":9626775}]}]}
{"op":"mcm","clk":"4230324457","pt":1631531721278,"mc":[{"id":"1.187595433","rc":[{"batb":[[0,1.08,255.54],[1,1.06,1007.61],[2,1.01,7]],"ltp":1.14,"tv":14.73,"id":9626775}]}]}
{"op":"mcm","clk":"4230324578","pt":1631531722685,"mc":[{"id":"1.187595433","rc":[{"batl":[[0,1.2,255.54],[1,1.41,915.1],[2,1.5,9.12]],"ltp":1.14,"tv":14.73,"id":9626775}]}]}
{"op":"mcm","clk":"4230324938","pt":1631531727369,"mc":[{"id":"1.187595433","rc":[{"batb":[[1,1.01,7],[2,1.01,0]],"ltp":1.14,"tv":14.73,"id":9626775}]}]}
{"op":"mcm","clk":"4230325411","pt":1631531733008,"mc":[{"id":"1.187595433","rc":[{"batb":[[0,1.09,763.45],[1,1.08,255.54],[2,1.01,7]],"ltp":1.14,"tv":14.73,"id":9626775}]}]}
{"op":"mcm","clk":"4230325665","pt":1631531736723,"mc":[{"id":"1.187595433","rc":[{"batb":[[0,1.11,255.54],[1,1.09,763.45],[2,1.08,255.54]],"ltp":1.14,"tv":14.73,"id":9626775}]}]}
{"op":"mcm","clk":"4230326026","pt":1631531741714,"mc":[{"id":"1.187595433","rc":[{"batl":[[0,7,6.4]],"ltp":8.0,"tv":0.2,"id":22955132}]}]}
{"op":"mcm","clk":"4230326411","pt":1631531747027,"mc":[{"id":"1.187595433","rc":[{"batl":[[2,1.8,255.54]],"ltp":1.14,"tv":14.73,"id":9626775}]}]}
{"op":"mcm","clk":"4230327216","pt":1631531756812,"mc":[{"id":"1.187595433","rc":[{"batb":[[1,1.08,255.54],[2,1.01,7]],"ltp":1.14,"tv":14.73,"id":9626775}]}]}
{"op":"mcm","clk":"4230327725","pt":1631531763211,"mc":[{"id":"1.187595433","rc":[{"batb":[[1,1.1,733.19],[2,1.08,255.54]],"ltp":1.14,"tv":14.73,"id":9626775}]}]}
{"op":"mcm","clk":"4230328039","pt":1631531767311,"mc":[{"id":"1.187595433","rc":[{"batl":[[0,1.41,915.1],[1,1.8,255.54],[2,1.8,0]],"ltp":1.14,"tv":14.73,"id":9626775}]}]}
{"op":"mcm","clk":"4230328088","pt":1631531767930,"mc":[{"id":"1.187595433","rc":[{"batb":[[1,1.08,255.54],[2,1.01,7]],"ltp":1.14,"tv":14.73,"id":9626775}]}]}
{"op":"mcm","clk":"4230328529","pt":1631531773339,"mc":[{"id":"1.187595433","rc":[{"batb":[[0,1.14,618.88],[1,1.11,255.54],[2,1.08,255.54]],"ltp":1.14,"tv":14.73,"id":9626775}]}]}
{"op":"mcm","clk":"4230328722","pt":1631531775935,"mc":[{"id":"1.187595433","rc":[{"batl":[[0,6,6.4]],"ltp":8.0,"tv":0.2,"id":22955132}]}]}
{"op":"mcm","clk":"4230330580","pt":1631531799755,"mc":[{"id":"1.187595433","rc":[{"batb":[[2,1.01,7]],"ltp":1.14,"tv":14.73,"id":9626775}]}]}
{"op":"mcm","clk":"4230330773","pt":1631531801944,"mc":[{"id":"1.187595433","rc":[{"batb":[[1,1.01,7],[2,1.01,0]],"ltp":1.14,"tv":14.73,"id":9626775}]}]}
{"op":"mcm","clk":"4230330981","pt":1631531804485,"mc":[{"id":"1.187595433","rc":[{"batb":[[0,1.01,7],[1,1.01,0]],"ltp":1.14,"tv":14.73,"id":9626775}]}]}
{"op":"mcm","clk":"4230331462","pt":1631531810781,"mc":[{"id":"1.187595433","rc":[{"batb":[[0,1.08,812.01],[1,1.01,7]],"ltp":1.14,"tv":14.73,"id":9626775}]}]}
{"op":"mcm","clk":"4230331592","pt":1631531812496,"mc":[{"id":"1.187595433","rc":[{"batl":[[0,8,6.4]],"ltp":8.0,"tv":0.2,"id":22955132}]}]}
{"op":"mcm","clk":"4230332685","pt":1631531826793,"mc":[{"id":"1.187595433","rc":[{"batb":[[0,1.01,7],[1,1.01,0]],"batl":[[0,1.8,255.54],[1,1.8,0]],"ltp":1.14,"tv":14.73,"id":9626775}]}]}
{"op":"mcm","clk":"4230333428","pt":1631531838001,"mc":[{"id":"1.187595433","rc":[{"batb":[[0,1.14,618.88],[1,1.01,7]],"batl":[[0,1.55,700.29],[1,1.8,255.54]],"ltp":1.14,"tv":14.73,"id":9626775}]}]}
{"op":"mcm","clk":"4230333844","pt":1631531843902,"mc":[{"id":"1.187595433","rc":[{"batl":[[0,6,6.4]],"ltp":8.0,"tv":0.2,"id":22955132}]}]}
{"op":"mcm","clk":"4230334821","pt":1631531857724,"mc":[{"id":"1.187595433","rc":[{"batl":[[0,1.54,29.05],[1,1.55,700.29],[2,1.8,255.54]],"ltp":1.14,"tv":14.73,"id":9626775}]}]}
{"op":"mcm","clk":"4230343853","pt":1631531875430,"mc":[{"id":"1.187595433","rc":[{"batb":[[0,1.01,7],[1,1.01,0]],"ltp":1.14,"tv":14.73,"id":9626775}]}]}
{"op":"mcm","clk":"4230344296","pt":1631531881542,"mc":[{"id":"1.187595433","rc":[{"batb":[[0,1.2,538.19],[1,1.01,7]],"ltp":1.14,"tv":14.73,"id":9626775}]}]}
{"op":"mcm","clk":"4230345361","pt":1631531894752,"mc":[{"id":"1.187595433","rc":[{"batl":[[0,1.55,700.29],[1,1.8,255.54],[2,1.8,0]],"ltp":1.14,"tv":14.73,"id":9626775}]}]}
{"op":"mcm","clk":"4230345831","pt":1631531899889,"mc":[{"id":"1.187595433","rc":[{"batl":[[1,1.79,29.05],[2,1.8,255.54]],"ltp":1.14,"tv":14.73,"id":9626775}]}]}
{"op":"mcm","clk":"4230346026","pt":1631531901766,"mc":[{"id":"1.187595433","rc":[{"batb":[[0,1.01,7],[1,1.01,0]],"ltp":1.14,"tv":14.73,"id":9626775}]}]}
{"op":"mcm","clk":"4230346554","pt":1631531907894,"mc":[{"id":"1.187595433","rc":[{"batb":[[0,1.14,618.88],[1,1.01,7]],"ltp":1.14,"tv":14.73,"id":9626775}]}]}
{"op":"mcm","clk":"4230347136","pt":1631531914603,"mc":[{"id":"1.187595433","rc":[{"batl":[[0,7,6.4]],"ltp":8.0,"tv":0.2,"id":22955132}]}]}
{"op":"mcm","clk":"4230348860","pt":1631531933514,"mc":[{"id":"1.187595433","rc":[{"batb":[[0,1.01,7],[1,1.01,0]],"batl":[[0,1.79,29.05],[1,1.8,255.54],[2,1.8,0]],"ltp":1.14,"tv":14.73,"id":9626775}]}]}
{"op":"mcm","clk":"4230349347","pt":1631531939437,"mc":[{"id":"1.187595433","rc":[{"batb":[[0,1.08,812.01],[1,1.01,7]],"batl":[[0,1.44,869.57],[1,1.79,29.05],[2,1.8,255.54]],"ltp":1.14,"tv":14.73,"id":9626775}]}]}
{"op":"mcm","clk":"4230349776","pt":1631531944538,"mc":[{"id":"1.187595433","rc":[{"batl":[[0,8,6.4]],"ltp":8.0,"tv":0.2,"id":22955132}]}]}
{"op":"mcm","clk":"4230350646","pt":1631531955844,"mc":[{"id":"1.187595433","rc":[{"batb":[[0,1.01,7],[1,1.01,0]],"batl":[[0,1.79,29.05],[1,1.8,255.54],[2,1.8,0]],"ltp":1.14,"tv":14.73,"id":9626775}]}]}
{"op":"mcm","clk":"4230351393","pt":1631531964555,"mc":[{"id":"1.187595433","rc":[{"trd":[[1.14,49.04]],"batb":[[0,1.04,1251.58],[1,1.01,7]],"batl":[[0,1.36,1040.12],[1,1.79,29.05],[2,1.8,255.54]],"ltp":1.14,"tv":59.64,"id":9626775},{"trd":[[8,6.6]],"ltp":8.0,"tv":6.6,"id":22955132}],"tv":66.24}]}
{"op":"mcm","clk":"4230351477","pt":1631531965544,"mc":[{"id":"1.187595433","rc":[{"batl":[[0,1.14,123.09],[1,1.36,1040.12],[2,1.79,29.05]],"ltp":1.14,"tv":59.64,"id":9626775}]}]}
{"op":"mcm","clk":"4230351526","pt":1631531965960,"mc":[{"id":"1.187595433","rc":[{"batl":[[0,1.36,1040.12],[1,1.79,29.05],[2,1.8,255.54]],"ltp":1.14,"tv":59.64,"id":9626775}]}]}
{"op":"mcm","clk":"4230353015","pt":1631531983754,"mc":[{"id":"1.187595433","rc":[{"batl":[[1,1.8,255.54],[2,1.8,0]],"ltp":1.14,"tv":59.64,"id":9626775}]}]}
{"op":"mcm","clk":"4230353430","pt":1631531988897,"mc":[{"id":"1.187595433","rc":[{"batl":[[0,1.35,29.05],[1,1.36,1040.12],[2,1.8,255.54]],"ltp":1.14,"tv":59.64,"id":9626775}]}]}
{"op":"mcm","clk":"4230356732","pt":1631532027928,"mc":[{"id":"1.187595433","rc":[{"batb":[[0,1.01,7],[1,1.01,0]],"ltp":1.14,"tv":59.64,"id":9626775}]}]}
{"op":"mcm","clk":"4230357223","pt":1631532033346,"mc":[{"id":"1.187595433","rc":[{"batb":[[0,1.06,949.73],[1,1.01,7]],"ltp":1.14,"tv":59.64,"id":9626775}]}]}
{"op":"mcm","clk":"4230357802","pt":1631532040431,"mc":[{"id":"1.187595433","rc":[{"batl":[[0,1.14,255.54],[1,1.15,255.54],[2,1.35,29.05]],"ltp":1.14,"tv":59.64,"id":9626775}]}]}
{"op":"mcm","clk":"4230358436","pt":1631532048251,"mc":[{"id":"1.187595433","rc":[{"batb":[[0,1.01,7],[1,1.01,0]],"ltp":1.14,"tv":59.64,"id":9626775}]}]}
{"op":"mcm","clk":"4230359051","pt":1631532054683,"mc":[{"id":"1.187595433","rc":[{"batb":[[0,1.04,1251.58],[1,1.01,7]],"ltp":1.14,"tv":59.64,"id":9626775}]}]}
{"op":"mcm","clk":"4230359711","pt":1631532062470,"mc":[{"id":"1.187595433","rc":[{"batb":[[0,1.01,7],[1,1.01,0]],"ltp":1.14,"tv":59.64,"id":9626775}]}]}
{"op":"mcm","clk":"4230360435","pt":1631532070864,"mc":[{"id":"1.187595433","rc":[{"batb":[[0,1.03,1557.04],[1,1.01,7]],"batl":[[2,1.35,1116.88]],"ltp":1.14,"tv":59.64,"id":9626775}]}]}
{"op":"mcm","clk":"4230360594","pt":1631532072581,"mc":[{"id":"1.187595433","rc":[{"batb":[[0,1.01,7],[1,1.01,0]],"batl":[[2,1.35,29.05]],"ltp":1.14,"tv":59.64,"id":9626775}]}]}
{"op":"mcm","clk":"4230361364","pt":1631532081997,"mc":[{"id":"1.187595433","rc":[{"batb":[[0,1.06,949.73],[1,1.01,7]],"ltp":1.14,"tv":59.64,"id":9626775}]}]}
{"op":"mcm","clk":"4230362663","pt":1631532097041,"mc":[{"id":"1.187595433","rc":[{"batb":[[0,1.01,7],[1,1.01,0]],"ltp":1.14,"tv":59.64,"id":9626775}]}]}
{"op":"mcm","clk":"4230363209","pt":1631532103258,"mc":[{"id":"1.187595433","rc":[{"batb":[[0,1.09,763.45],[1,1.01,7]],"ltp":1.14,"tv":59.64,"id":9626775}]}]}
{"op":"mcm","clk":"4230364314","pt":1631532115397,"mc":[{"id":"1.187595433","rc":[{"batb":[[0,1.01,7],[1,1.01,0]],"ltp":1.14,"tv":59.64,"id":9626775}]}]}
{"op":"mcm","clk":"4230364866","pt":1631532121491,"mc":[{"id":"1.187595433","rc":[{"batb":[[0,1.1,733.19],[1,1.01,7]],"ltp":1.14,"tv":59.64,"id":9626775}]}]}
{"op":"mcm","clk":"4230373066","pt":1631532213132,"mc":[{"id":"1.187595433","rc":[{"batb":[[0,1.01,7],[1,1.01,0]],"ltp":1.14,"tv":59.64,"id":9626775}]}]}
{"op":"mcm","clk":"4230373534","pt":1631532218602,"mc":[{"id":"1.187595433","rc":[{"batb":[[0,1.06,1007.61],[1,1.01,7]],"ltp":1.14,"tv":59.64,"id":9626775}]}]}
{"op":"mcm","clk":"4230374545","pt":1631532231460,"mc":[{"id":"1.187595433","rc":[{"batb":[[0,1.01,7],[1,1.01,0]],"ltp":1.14,"tv":59.64,"id":9626775}]}]}
{"op":"mcm","clk":"4230375376","pt":1631532240973,"mc":[{"id":"1.187595433","rc":[{"batb":[[0,1.03,1557.04],[1,1.01,7]],"batl":[[2,1.35,1116.88]],"ltp":1.14,"tv":59.64,"id":9626775}]}]}
{"op":"mcm","clk":"4230376496","pt":1631532254665,"mc":[{"id":"1.187595433","rc":[{"batb":[[0,1.01,7],[1,1.01,0]],"batl":[[2,1.35,29.05]],"ltp":1.14,"tv":59.64,"id":9626775}]}]}
{"op":"mcm","clk":"4230377280","pt":1631532265077,"mc":[{"id":"1.187595433","rc":[{"batl":[[2,1.28,1327.17]],"ltp":1.14,"tv":59.64,"id":9626775}]}]}
{"op":"mcm","clk":"4230377687","pt":1631532270477,"mc":[{"id":"1.187595433","rc":[{"trd":[[1.01,14]],"batl":[[0,1.01,10.03],[1,1.14,255.54],[2,1.15,255.54]],"ltp":1.01,"tv":73.64,"id":9626775}],"tv":80.24}]}
{"op":"mcm","clk":"4230379062","pt":1631532288909,"mc":[{"id":"1.187595433","rc":[{"batl":[[1,1.09,29.05],[2,1.14,255.54]],"ltp":1.01,"tv":73.64,"id":9626775}]}]}
{"op":"mcm","clk":"4230379491","pt":1631532294606,"mc":[{"id":"1.187595433","rc":[{"batl":[[0,1.01,5546.66]],"ltp":1.01,"tv":73.64,"id":9626775}]}]}
{"op":"mcm","clk":"4230379784","pt":1631532298329,"mc":[{"id":"1.187595433","rc":[{"batl":[[0,1.01,10278.35]],"ltp":1.01,"tv":73.64,"id":9626775}]}]}
{"op":"mcm","clk":"4230380954","pt":1631532313754,"mc":[{"id":"1.187595433","rc":[{"batl":[[0,1.01,5546.66]],"ltp":1.01,"tv":73.64,"id":9626775}]}]}
{"op":"mcm","clk":"4230381273","pt":1631532316986,"mc":[{"id":"1.187595433","rc":[{"batl":[[2,1.8,255.54]],"ltp":1.01,"tv":73.64,"id":9626775}]}]}
{"op":"mcm","clk":"4230381463","pt":1631532318855,"mc":[{"id":"1.187595433","rc":[{"batl":[[2,1.2,4731.69]],"ltp":1.01,"tv":73.64,"id":9626775}]}]}
{"op":"mcm","clk":"4230381532","pt":1631532319667,"mc":[{"id":"1.187595433","marketDefinition":{"bspMarket":false,"turnInPlayEnabled":true,"persistenceEnabled":true,"marketBaseRate":5.0,"eventId":"30897878","eventTypeId":"2","numberOfWinners":1,"bettingType":"ODDS","marketType":"MATCH_ODDS","marketTime":"2021-09-13T09:38:57.000Z","suspendTime":"2021-09-13T09:38:57.000Z","bspReconciled":false,"complete":true,"inPlay":true,"crossMatching":true,"runnersVoidable":false,"numberOfActiveRunners":2,"betDelay":5,"status":"SUSPENDED","runners":[{"status":"ACTIVE","sortPriority":1,"id":9626775,"name":"A Gamiz"},{"status":"ACTIVE","sortPriority":2,"id":22955132,"name":"K Bartone"}],"regulators":["MR_INT"],"countryCode":"GB","discountAllowed":true,"timezone":"GMT","openDate":"2021-09-13T09:38:57.000Z","version":4030587884,"name":"Match Odds","eventName":"A Gamiz v K Bartone"}}]}
{"op":"mcm","clk":"4230381653","pt":1631532321086,"mc":[{"id":"1.187595433","tv":0.0}]}
{"op":"mcm","clk":"4230381703","pt":1631532321682,"mc":[{"id":"1.187595433","marketDefinition":{"bspMarket":false,"turnInPlayEnabled":true,"persistenceEnabled":true,"marketBaseRate":5.0,"eventId":"30897878","eventTypeId":"2","numberOfWinners":1,"bettingType":"ODDS","marketType":"MATCH_ODDS","marketTime":"2021-09-13T09:38:57.000Z","suspendTime":"2021-09-13T09:38:57.000Z","bspReconciled":false,"complete":true,"inPlay":true,"crossMatching":false,"runnersVoidable":false,"numberOfActiveRunners":0,"betDelay":5,"status":"CLOSED","settledTime":"2021-09-13T11:25:19.000Z","runners":[{"status":"WINNER","sortPriority":1,"id":9626775,"name":"A Gamiz"},{"status":"LOSER","sortPriority":2,"id":22955132,"name":"K Bartone"}],"regulators":["MR_INT"],"countryCode":"GB","discountAllowed":true,"timezone":"GMT","openDate":"2021-09-13T09:38:57.000Z","version":4030587892,"name":"Match Odds","eventName":"A Gamiz v K Bartone"}}]}
