{"op":"mcm","clk":"4215250779","pt":1631536615663,"mc":[{"id":"1.187557985","rc":[{"batb":[[0,1.53,56.22],[1,1.47,152.84],[2,1.46,397]],"batl":[[1,1.58,272.71],[2,1.59,150.77]],"ltp":1.52,"tv":24946.65,"id":5300820}]}]}
{"op":"mcm","clk":"4215250807","pt":1631536616389,"mc":[{"id":"1.187557985","rc":[{"trd":[[1.53,1212.12]],"batb":[[0,1.53,51.22]],"ltp":1.53,"tv":24956.65,"id":5300820}],"tv":37809.25}]}
{"op":"mcm","clk":"4215250829","pt":1631536616860,"mc":[{"id":"1.187557985","rc":[{"batb":[[1,1.51,1.25],[2,1.47,152.84]],"ltp":1.53,"tv":24956.65,"id":5300820}]}]}
{"op":"mcm","clk":"4215250872","pt":1631536618059,"mc":[{"id":"1.187557985","rc":[{"batl":[[1,1.59,5],[2,1.6,6.51]],"ltp":1.53,"tv":24956.65,"id":5300820}]}]}
{"op":"mcm","clk":"4215250967","pt":1631536619576,"mc":[{"id":"1.187557985","rc":[{"batb":[[2,1.47,211.51]],"ltp":1.53,"tv":24956.65,"id":5300820},{"batl":[[0,3.15,5.9]],"ltp":2.92,"tv":12852.59,"id":9629022}]}]}
{"op":"mcm","clk":"4215251017","pt":1631536620472,"mc":[{"id":"1.187557985","rc":[{"trd":[[1.51,536.06],[1.53,1314.56]],"batb":[[0,1.47,152.84],[1,1.46,397],[2,1.45,5]],"batl":[[0,1.54,4174.03],[2,1.6,25.47]],"ltp":1.51,"tv":25061.59,"id":5300820},{"batl":[[0,3.15,2]],"ltp":2.92,"tv":12852.59,"id":9629022}],"tv":37914.19}]}
{"op":"mcm","clk":"4215251057","pt":1631536621094,"mc":[{"id":"1.187557985","rc":[{"batb":[[0,1.5,10.63],[1,1.48,5.38],[2,1.47,179.98]],"batl":[[0,1.51,359.81],[1,1.52,209.01],[2,1.53,1258.22]],"ltp":1.51,"tv":25061.59,"id":5300820},{"batl":[[1,3.25,323.65],[2,3.3,318.39]],"ltp":2.92,"tv":12852.59,"id":9629022}]}]}
{"op":"mcm","clk":"4215251120","pt":1631536622401,"mc":[{"id":"1.187557985","rc":[{"trd":[[2.98,16.88]],"batb":[[0,2.98,101.84],[1,2.84,21.52]],"batl":[[0,3.15,22.45]],"ltp":2.98,"tv":12866.48,"id":9629022}],"tv":37928.07}]}
{"op":"mcm","clk":"4215251188","pt":1631536622886,"mc":[{"id":"1.187557985","rc":[{"batb":[[2,1.47,223.73]],"batl":[[2,1.53,1329.18]],"ltp":1.51,"tv":25061.59,"id":5300820},{"batb":[[1,2.86,26.1],[2,2.84,21.52]],"batl":[[0,3.15,32.45]],"ltp":2.98,"tv":12866.48,"id":9629022}]}]}
{"op":"mcm","clk":"4215251661","pt":1631536626598,"mc":[{"id":"1.187557985","rc":[{"trd":[[1.51,638.28]],"batl":[[0,1.51,308.7]],"ltp":1.51,"tv":25163.81,"id":5300820},{"trd":[[2.98,83.03]],"batb":[[0,2.98,68.76]],"ltp":2.98,"tv":12932.62,"id":9629022}],"tv":38096.44}]}
{"op":"mcm","clk":"4215251876","pt":1631536629806,"mc":[{"id":"1.187557985","rc":[{"batb":[[0,1.5,296.63],[2,1.47,258.9]],"batl":[[0,1.51,325.64]],"ltp":1.51,"tv":25163.81,"id":5300820}]}]}
{"op":"mcm","clk":"4215251946","pt":1631536631502,"mc":[{"id":"1.187557985","rc":[{"trd":[[1.5,177.8]],"batb":[[0,1.5,291.69]],"ltp":1.5,"tv":25173.69,"id":5300820}],"tv":38106.32}]}
{"op":"mcm","clk":"4215251964","pt":1631536631808,"mc":[{"id":"1.187557985","rc":[{"batb":[[2,1.47,251.9]],"ltp":1.5,"tv":25173.69,"id":5300820}]}]}
{"op":"mcm","clk":"4215252085","pt":1631536634202,"mc":[{"id":"1.187557985","rc":[{"trd":[[1.5,182.45]],"batb":[[0,1.5,289.37]],"ltp":1.5,"tv":25178.34,"id":5300820}],"tv":38110.96}]}
{"op":"mcm","clk":"4215252205","pt":1631536636213,"mc":[{"id":"1.187557985","rc":[{"trd":[[1.51,638.47]],"batl":[[0,1.51,325.55]],"ltp":1.51,"tv":25178.52,"id":5300820}],"tv":38111.15}]}
{"op":"mcm","clk":"4215252299","pt":1631536638579,"mc":[{"id":"1.187557985","rc":[{"trd":[[1.51,1342.21]],"batl":[[0,1.52,209.01],[1,1.53,1329.18],[2,1.54,40.75]],"ltp":1.51,"tv":25882.27,"id":5300820},{"trd":[[2.98,109.69]],"batb":[[0,2.96,44.18]],"ltp":2.98,"tv":12959.28,"id":9629022}],"tv":38841.55}]}
{"op":"mcm","clk":"4215252344","pt":1631536639118,"mc":[{"id":"1.187557985","rc":[{"trd":[[1.5,761.24],[1.51,1342.86]],"batb":[[0,1.48,5.38],[1,1.47,251.9],[2,1.46,178.49]],"batl":[[0,1.5,126.78],[1,1.52,209.01],[2,1.53,1278.22]],"ltp":1.5,"tv":26461.71,"id":5300820}],"tv":39420.99}]}
{"op":"mcm","clk":"4215252394","pt":1631536640317,"mc":[{"id":"1.187557985","rc":[{"trd":[[1.5,784.73]],"batl":[[0,1.5,103.3]],"ltp":1.5,"tv":26485.19,"id":5300820},{"trd":[[3,61.74]],"ltp":3.0,"tv":12971.02,"id":9629022}],"tv":39456.21}]}
{"op":"mcm","clk":"4215252467","pt":1631536642001,"mc":[{"id":"1.187557985","rc":[{"batb":[[0,1.48,195.4],[1,1.47,284.5]],"batl":[[1,1.52,367.22],[2,1.53,1480.72]],"ltp":1.5,"tv":26485.19,"id":5300820}]}]}
{"op":"mcm","clk":"4215252583","pt":1631536644139,"mc":[{"id":"1.187557985","rc":[{"trd":[[1.48,42.57],[1.5,785.56]],"batb":[[0,1.48,185.41]],"batl":[[0,1.5,102.88]],"ltp":1.5,"tv":26506.02,"id":5300820}],"tv":39477.04}]}
{"op":"mcm","clk":"4215252704","pt":1631536646331,"mc":[{"id":"1.187557985","rc":[{"batb":[[1,1.47,461.57],[2,1.44,58.42]],"ltp":1.5,"tv":26506.02,"id":5300820}]}]}
{"op":"mcm","clk":"4215252736","pt":1631536647111,"mc":[{"id":"1.187557985","rc":[{"batb":[[0,1.48,380.41]],"ltp":1.5,"tv":26506.02,"id":5300820}]}]}
{"op":"mcm","clk":"4215252875","pt":1631536649838,"mc":[{"id":"1.187557985","rc":[{"trd":[[1.5,788.97]],"batl":[[0,1.5,101.18]],"ltp":1.5,"tv":26509.43,"id":5300820}],"tv":39480.45}]}
{"op":"mcm","clk":"4215252957","pt":1631536651140,"mc":[{"id":"1.187557985","rc":[{"trd":[[1.5,795.34]],"batl":[[0,1.5,96.92]],"ltp":1.5,"tv":26515.8,"id":5300820},{"trd":[[3,62.81]],"ltp":3.0,"tv":12972.09,"id":9629022}],"tv":39487.89}]}
{"op":"mcm","clk":"4215253232","pt":1631536655665,"mc":[{"id":"1.187557985","rc":[{"trd":[[1.5,804.52]],"batl":[[0,1.5,92.33]],"ltp":1.5,"tv":26524.98,"id":5300820}],"tv":39497.07}]}
{"op":"mcm","clk":"4215253387","pt":1631536658528,"mc":[{"id":"1.187557985","rc":[{"batb":[[0,1.48,185.41]],"ltp":1.5,"tv":26524.98,"id":5300820},{"batb":[[2,2.84,25.52]],"ltp":3.0,"tv":12972.09,"id":9629022}]}]}
{"op":"mcm","clk":"4215253515","pt":1631536660559,"mc":[{"id":"1.187557985","rc":[{"trd":[[1.5,824.05]],"batl":[[0,1.5,82.56]],"ltp":1.5,"tv":26544.5,"id":5300820}],"tv":39516.6}]}
{"op":"mcm","clk":"4215253595","pt":1631536661828,"mc":[{"id":"1.187557985","rc":[{"trd":[[1.5,824.18]],"batl":[[0,1.5,82.5]],"ltp":1.5,"tv":26544.64,"id":5300820}],"tv":39516.73}]}
{"op":"mcm","clk":"4215253716","pt":1631536663652,"mc":[{"id":"1.187557985","rc":[{"trd":[[1.48,42.61]],"batb":[[0,1.48,185.39]],"ltp":1.48,"tv":26544.68,"id":5300820}],"tv":39516.77}]}
{"op":"mcm","clk":"4215253777","pt":1631536664447,"mc":[{"id":"1.187557985","rc":[{"trd":[[1.5,854.42]],"batb":[[0,1.49,321.11],[1,1.48,185.39],[2,1.47,461.57]],"batl":[[0,1.5,52.26]],"ltp":1.5,"tv":26574.91,"id":5300820},{"trd":[[3,77.93]],"ltp":3.0,"tv":12987.21,"id":9629022}],"tv":39562.13}]}
{"op":"mcm","clk":"4215253852","pt":1631536665440,"mc":[{"id":"1.187557985","rc":[{"trd":[[1.5,859.07]],"batb":[[0,1.48,185.39],[1,1.47,461.57],[2,1.44,58.42]],"batl":[[0,1.5,49.93]],"ltp":1.5,"tv":26579.56,"id":5300820}],"tv":39566.78}]}
{"op":"mcm","clk":"4215253914","pt":1631536666375,"mc":[{"id":"1.187557985","rc":[{"batl":[[0,3.15,22.45]],"ltp":3.0,"tv":12987.21,"id":9629022}]}]}
{"op":"mcm","clk":"4215253993","pt":1631536667566,"mc":[{"id":"1.187557985","rc":[{"trd":[[1.48,114.94]],"batb":[[0,1.49,39.73]],"ltp":1.48,"tv":26651.89,"id":5300820}],"tv":39639.11}]}
{"op":"mcm","clk":"4215254006","pt":1631536667773,"mc":[{"id":"1.187557985","rc":[{"batl":[[0,3.15,20.45]],"ltp":3.0,"tv":12987.21,"id":9629022}]}]}
{"op":"mcm","clk":"4215254145","pt":1631536670449,"mc":[{"id":"1.187557985","rc":[{"batb":[[1,1.47,625.51],[2,1.46,249.48]],"batl":[[1,1.52,393.78]],"ltp":1.48,"tv":26651.89,"id":5300820}]}]}
{"op":"mcm","clk":"4215254576","pt":1631536676857,"mc":[{"id":"1.187557985","rc":[{"trd":[[1.5,859.1]],"batl":[[0,1.5,49.91]],"ltp":1.5,"tv":26651.93,"id":5300820}],"tv":39639.14}]}
{"op":"mcm","clk":"4215254690","pt":1631536679173,"mc":[{"id":"1.187557985","rc":[{"trd":[[1.5,944.28]],"batl":[[0,1.5,7.33]],"ltp":1.5,"tv":26737.11,"id":5300820}],"tv":39724.32}]}
{"op":"mcm","clk":"4215254991","pt":1631536684575,"mc":[{"id":"1.187557985","rc":[{"trd":[[1.5,958.93]],"batb":[[0,1.5,85.52],[1,1.49,39.73],[2,1.47,625.51]],"batl":[[0,1.52,393.78],[1,1.53,1480.72],[2,1.54,40.75]],"ltp":1.5,"tv":26751.76,"id":5300820}],"tv":39738.97}]}
{"op":"mcm","clk":"4215255012","pt":1631536684846,"mc":[{"id":"1.187557985","rc":[{"batb":[[0,1.5,110.52]],"ltp":1.5,"tv":26751.76,"id":5300820}]}]}
{"op":"mcm","clk":"4215255107","pt":1631536686375,"mc":[{"id":"1.187557985","rc":[{"batl":[[0,1.52,342.82]],"ltp":1.5,"tv":26751.76,"id":5300820},{"batb":[[1,2.84,25.52],[2,2.6,61.67]],"batl":[[0,3,2.32],[1,3.15,20.45],[2,3.25,323.65]],"ltp":3.0,"tv":12987.21,"id":9629022}]}]}
{"op":"mcm","clk":"4215255196","pt":1631536687649,"mc":[{"id":"1.187557985","rc":[{"trd":[[1.5,1056.12]],"batb":[[0,1.5,61.93]],"ltp":1.5,"tv":26848.95,"id":5300820}],"tv":39836.16}]}
{"op":"mcm","clk":"4215255303","pt":1631536689281,"mc":[{"id":"1.187557985","rc":[{"trd":[[1.5,1056.73]],"batb":[[0,1.5,61.62]],"batl":[[0,1.51,50.96],[1,1.52,342.82],[2,1.53,1480.72]],"ltp":1.5,"tv":26849.56,"id":5300820},{"batb":[[0,2.96,70.28],[1,2.86,4],[2,2.84,25.52]],"batl":[[0,3.15,20.45],[1,3.25,323.65],[2,3.3,318.39]],"ltp":3.0,"tv":12987.21,"id":9629022}],"tv":39836.77}]}
{"op":"mcm","clk":"4215255366","pt":1631536690657,"mc":[{"id":"1.187557985","rc":[{"trd":[[1.51,1444.79]],"batb":[[0,1.51,41.87],[1,1.5,61.62],[2,1.49,132.57]],"batl":[[0,1.52,342.82],[1,1.53,1480.72],[2,1.54,40.75]],"ltp":1.51,"tv":26951.49,"id":5300820},{"batb":[[0,2.96,44.18]],"ltp":3.0,"tv":12987.21,"id":9629022}],"tv":39938.7}]}
{"op":"mcm","clk":"4215255389","pt":1631536691080,"mc":[{"id":"1.187557985","rc":[{"batb":[[1,1.5,36.62]],"ltp":1.51,"tv":26951.49,"id":5300820}]}]}
{"op":"mcm","clk":"4215255525","pt":1631536693577,"mc":[{"id":"1.187557985","rc":[{"trd":[[1.51,1481.87]],"batb":[[0,1.51,23.33],[1,1.5,46.14]],"ltp":1.51,"tv":26988.58,"id":5300820},{"batl":[[0,3.15,36.16]],"ltp":3.0,"tv":12987.21,"id":9629022}],"tv":39975.79}]}
{"op":"mcm","clk":"4215255583","pt":1631536694594,"mc":[{"id":"1.187557985","rc":[{"trd":[[1.52,929.13]],"batl":[[0,1.52,358.65]],"ltp":1.52,"tv":27038.58,"id":5300820}],"tv":40025.79}]}
{"op":"mcm","clk":"4215255947","pt":1631536701479,"mc":[{"id":"1.187557985","rc":[{"batb":[[2,1.49,39.73]],"ltp":1.52,"tv":27038.58,"id":5300820}]}]}
{"op":"mcm","clk":"4215255966","pt":1631536702000,"mc":[{"id":"1.187557985","rc":[{"trd":[[1.52,929.2]],"batl":[[0,1.52,317.78]],"ltp":1.52,"tv":27038.65,"id":5300820},{"batb":[[2,2.84,21.52]],"batl":[[0,3.15,20.45]],"ltp":3.0,"tv":12987.21,"id":9629022}],"tv":40025.87}]}
{"op":"mcm","clk":"4215256110","pt":1631536704598,"mc":[{"id":"1.187557985","rc":[{"trd":[[1.52,1114.88]],"batb":[[0,1.51,141.52],[1,1.5,122.38],[2,1.48,272.78]],"batl":[[0,1.52,286.81],[1,1.53,1557.66]],"ltp":1.52,"tv":27224.33,"id":5300820},{"batb":[[0,2.96,61.95]],"ltp":3.0,"tv":12987.21,"id":9629022}],"tv":40211.54}]}
{"op":"mcm","clk":"4215256140","pt":1631536705070,"mc":[{"id":"1.187557985","rc":[{"trd":[[1.51,1563.54]],"batb":[[0,1.51,100.68]],"ltp":1.51,"tv":27305.99,"id":5300820},{"batb":[[0,2.96,44.18],[1,2.88,4],[2,2.86,4]],"ltp":3.0,"tv":12987.21,"id":9629022}],"tv":40293.21}]}
{"op":"mcm","clk":"4215256268","pt":1631536706978,"mc":[{"id":"1.187557985","rc":[{"trd":[[1.52,1119.52]],"batl":[[0,1.52,284.49]],"ltp":1.52,"tv":27310.64,"id":5300820}],"tv":40297.85}]}
{"op":"mcm","clk":"4215256360","pt":1631536708492,"mc":[{"id":"1.187557985","rc":[{"trd":[[1.52,1468.73]],"batb":[[0,1.5,46.14],[1,1.48,243.79],[2,1.47,625.51]],"batl":[[0,1.52,87.11],[1,1.53,1480.72]],"ltp":1.52,"tv":27659.84,"id":5300820}],"tv":40647.06}]}
{"op":"mcm","clk":"4215256384","pt":1631536708808,"mc":[{"id":"1.187557985","rc":[{"batl":[[0,1.53,1480.72],[1,1.54,40.75],[2,1.55,1251.22]],"ltp":1.52,"tv":27659.84,"id":5300820}]}]}
{"op":"mcm","clk":"4215256555","pt":1631536711629,"mc":[{"id":"1.187557985","rc":[{"trd":[[1.52,1554.73]],"batb":[[0,1.52,6.84],[1,1.5,46.14],[2,1.48,243.79]],"ltp":1.52,"tv":27745.85,"id":5300820},{"trd":[[2.96,261.44]],"batb":[[0,2.88,4],[1,2.86,4],[2,2.84,21.52]],"ltp":2.96,"tv":13031.39,"id":9629022}],"tv":40777.24}]}
{"op":"mcm","clk":"4215256579","pt":1631536711995,"mc":[{"id":"1.187557985","rc":[{"batb":[[2,1.48,365.42]],"batl":[[0,1.53,1625.56],[1,1.54,237.09]],"ltp":1.52,"tv":27745.85,"id":5300820},{"batb":[[0,2.86,4],[1,2.84,21.52],[2,2.6,61.67]],"batl":[[0,3.15,36.6]],"ltp":2.96,"tv":13031.39,"id":9629022}]}]}
{"op":"mcm","clk":"4215256626","pt":1631536712783,"mc":[{"id":"1.187557985","rc":[{"batb":[[0,1.52,14.03],[1,1.51,14.46],[2,1.5,46.14]],"ltp":1.52,"tv":27745.85,"id":5300820}]}]}
{"op":"mcm","clk":"4215256774","pt":1631536715038,"mc":[{"id":"1.187557985","rc":[{"trd":[[1.52,1566.52]],"batb":[[0,1.52,8.13]],"ltp":1.52,"tv":27757.63,"id":5300820}],"tv":40789.03}]}
{"op":"mcm","clk":"4215257004","pt":1631536718632,"mc":[{"id":"1.187557985","rc":[{"trd":[[1.52,1580.28],[1.53,1339.66]],"batb":[[0,1.52,1.26],[2,1.5,36.62]],"batl":[[0,1.53,1613.01]],"ltp":1.53,"tv":27796.5,"id":5300820},{"batb":[[0,2.88,20],[1,2.86,4],[2,2.84,21.52]],"ltp":2.96,"tv":13031.39,"id":9629022}],"tv":40827.89}]}
{"op":"mcm","clk":"4215257170","pt":1631536721251,"mc":[{"id":"1.187557985","rc":[{"batl":[[0,3.15,20.45]],"ltp":2.96,"tv":13031.39,"id":9629022}]}]}
{"op":"mcm","clk":"4215257220","pt":1631536722186,"mc":[{"id":"1.187557985","rc":[{"batb":[[2,1.48,365.42]],"ltp":1.53,"tv":27796.5,"id":5300820}]}]}
{"op":"mcm","clk":"4215257370","pt":1631536724486,"mc":[{"id":"1.187557985","rc":[{"batb":[[2,2.84,25.52]],"ltp":2.96,"tv":13031.39,"id":9629022}]}]}
{"op":"mcm","clk":"4215257446","pt":1631536725588,"mc":[{"id":"1.187557985","rc":[{"trd":[[1.52,1582.8]],"batb":[[0,1.51,14.46],[1,1.48,365.42],[2,1.47,625.51]],"batl":[[0,1.52,42.04],[1,1.53,1613.01],[2,1.54,237.09]],"ltp":1.52,"tv":27799.02,"id":5300820},{"batb":[[0,2.88,3]],"ltp":2.96,"tv":13031.39,"id":9629022}],"tv":40830.41}]}
{"op":"mcm","clk":"4215257624","pt":1631536728687,"mc":[{"id":"1.187557985","rc":[{"batb":[[0,2.9,20],[1,2.88,3],[2,2.86,4]],"ltp":2.96,"tv":13031.39,"id":9629022}]}]}
{"op":"mcm","clk":"4215258003","pt":1631536735500,"mc":[{"id":"1.187557985","rc":[{"trd":[[1.51,1575.44]],"batb":[[0,1.51,8.51],[1,1.49,4.26],[2,1.48,365.42]],"ltp":1.51,"tv":27810.92,"id":5300820}],"tv":40842.32}]}
{"op":"mcm","clk":"4215258074","pt":1631536736596,"mc":[{"id":"1.187557985","rc":[{"batb":[[1,1.5,4.26],[2,1.49,4.26]],"ltp":1.51,"tv":27810.92,"id":5300820},{"batb":[[2,2.84,21.52]],"ltp":2.96,"tv":13031.39,"id":9629022}]}]}
{"op":"mcm","clk":"4215258268","pt":1631536739780,"mc":[{"id":"1.187557985","rc":[{"batb":[[2,2.86,3]],"ltp":2.96,"tv":13031.39,"id":9629022}]}]}
{"op":"mcm","clk":"4215258403","pt":1631536741762,"mc":[{"id":"1.187557985","rc":[{"trd":[[1.52,1582.88]],"batl":[[0,1.52,42]],"ltp":1.52,"tv":27811.0,"id":5300820}],"tv":40842.39}]}
{"op":"mcm","clk":"4215258468","pt":1631536742913,"mc":[{"id":"1.187557985","rc":[{"batb":[[0,1.51,12.77]],"ltp":1.52,"tv":27811.0,"id":5300820}]}]}
{"op":"mcm","clk":"4215258806","pt":1631536748602,"mc":[{"id":"1.187557985","rc":[{"trd":[[1.52,1587.35]],"batl":[[0,1.52,456.61]],"ltp":1.52,"tv":27815.47,"id":5300820},{"trd":[[2.92,49.09]],"batb":[[0,2.92,218.14],[1,2.86,3],[2,2.84,21.52]],"ltp":2.92,"tv":13033.71,"id":9629022}],"tv":40849.19}]}
{"op":"mcm","clk":"4215258856","pt":1631536749486,"mc":[{"id":"1.187557985","rc":[{"batb":[[2,1.49,377.34]],"ltp":1.52,"tv":27815.47,"id":5300820},{"batl":[[0,3.05,182.26],[1,3.15,20.45],[2,3.25,323.65]],"ltp":2.92,"tv":13033.71,"id":9629022}]}]}
{"op":"mcm","clk":"4215258954","pt":1631536751209,"mc":[{"id":"1.187557985","rc":[{"batl":[[1,3.15,35.87]],"ltp":2.92,"tv":13033.71,"id":9629022}]}]}
{"op":"mcm","clk":"4215259201","pt":1631536755019,"mc":[{"id":"1.187557985","rc":[{"batb":[[0,2.94,20],[1,2.92,218.14],[2,2.86,3]],"ltp":2.92,"tv":13033.71,"id":9629022}]}]}
{"op":"mcm","clk":"4215259360","pt":1631536757205,"mc":[{"id":"1.187557985","rc":[{"trd":[[1.52,1605.51]],"batl":[[0,1.52,447.53]],"ltp":1.52,"tv":27833.63,"id":5300820}],"tv":40867.35}]}
{"op":"mcm","clk":"4215259394","pt":1631536757925,"mc":[{"id":"1.187557985","rc":[{"trd":[[1.52,2539.18],[1.53,1567.38]],"batl":[[0,1.53,1499.15],[1,1.54,237.09],[2,1.55,1251.22]],"ltp":1.53,"tv":28995.02,"id":5300820},{"trd":[[2.94,20]],"batb":[[0,2.92,218.14],[1,2.86,3],[2,2.84,21.52]],"ltp":2.94,"tv":13053.71,"id":9629022}],"tv":42048.74}]}
{"op":"mcm","clk":"4215259605","pt":1631536761120,"mc":[{"id":"1.187557985","rc":[{"batl":[[0,3.05,245.38]],"ltp":2.94,"tv":13053.71,"id":9629022}]}]}
{"op":"mcm","clk":"4215259684","pt":1631536762110,"mc":[{"id":"1.187557985","rc":[{"batl":[[0,1.52,33.56],[1,1.53,1499.15],[2,1.54,237.09]],"ltp":1.53,"tv":28995.02,"id":5300820},{"batb":[[0,2.92,236.17]],"ltp":2.94,"tv":13053.71,"id":9629022}]}]}
{"op":"mcm","clk":"4215259931","pt":1631536765252,"mc":[{"id":"1.187557985","rc":[{"trd":[[2.92,81.46]],"batb":[[0,2.92,219.99]],"ltp":2.92,"tv":13086.08,"id":9629022}],"tv":42081.1}]}
{"op":"mcm","clk":"4215260037","pt":1631536766720,"mc":[{"id":"1.187557985","rc":[{"batl":[[0,1.53,1499.15],[1,1.54,237.09],[2,1.55,1251.22]],"ltp":1.53,"tv":28995.02,"id":5300820}]}]}
{"op":"mcm","clk":"4215260230","pt":1631536769322,"mc":[{"id":"1.187557985","rc":[{"trd":[[1.53,1567.44]],"batl":[[0,1.53,1499.12]],"ltp":1.53,"tv":28995.08,"id":5300820}],"tv":42081.16}]}
{"op":"mcm","clk":"4215260271","pt":1631536769935,"mc":[{"id":"1.187557985","rc":[{"batl":[[0,1.53,1543.49]],"ltp":1.53,"tv":28995.08,"id":5300820}]}]}
{"op":"mcm","clk":"4215260384","pt":1631536771555,"mc":[{"id":"1.187557985","rc":[{"batb":[[0,1.52,70.59],[1,1.51,12.77],[2,1.5,4.26]],"ltp":1.53,"tv":28995.08,"id":5300820}]}]}
{"op":"mcm","clk":"4215260446","pt":1631536772442,"mc":[{"id":"1.187557985","rc":[{"trd":[[1.49,666.3],[1.5,1065.25],[1.51,1600.98],[1.52,2680.36]],"batb":[[0,1.49,324.96],[1,1.48,365.42],[2,1.47,625.51]],"ltp":1.49,"tv":29275.08,"id":5300820}],"tv":42361.17}]}
{"op":"mcm","clk":"4215260916","pt":1631536780051,"mc":[{"id":"1.187557985","rc":[{"batl":[[0,1.53,1499.12]],"ltp":1.49,"tv":29275.08,"id":5300820}]}]}
{"op":"mcm","clk":"4215261130","pt":1631536783131,"mc":[{"id":"1.187557985","rc":[{"batl":[[0,1.52,44.37],[1,1.53,1499.12],[2,1.54,237.09]],"ltp":1.49,"tv":29275.08,"id":5300820},{"batb":[[1,2.88,3],[2,2.86,3]],"ltp":2.92,"tv":13086.08,"id":9629022}]}]}
{"op":"mcm","clk":"4215261203","pt":1631536784166,"mc":[{"id":"1.187557985","rc":[{"trd":[[1.52,2685]],"batl":[[0,1.52,42.05]],"ltp":1.52,"tv":29279.73,"id":5300820}],"tv":42365.81}]}
{"op":"mcm","clk":"4215261268","pt":1631536784750,"mc":[{"id":"1.187557985","rc":[{"batl":[[0,1.52,424.5]],"ltp":1.52,"tv":29279.73,"id":5300820},{"batb":[[0,2.92,419.07]],"ltp":2.92,"tv":13086.08,"id":9629022}]}]}
{"op":"mcm","clk":"4215261374","pt":1631536786161,"mc":[{"id":"1.187557985","rc":[{"batb":[[0,2.92,219.99]],"ltp":2.92,"tv":13086.08,"id":9629022}]}]}
{"op":"mcm","clk":"4215261843","pt":1631536793069,"mc":[{"id":"1.187557985","rc":[{"trd":[[1.52,3533.95],[1.53,1918.56]],"batl":[[0,1.53,1323.56],[1,1.54,237.09],[2,1.55,1251.22]],"ltp":1.53,"tv":30479.79,"id":5300820},{"trd":[[2.92,130.27]],"batb":[[0,2.92,177.55]],"ltp":2.92,"tv":13134.89,"id":9629022}],"tv":43614.69}]}
{"op":"mcm","clk":"4215262125","pt":1631536797240,"mc":[{"id":"1.187557985","rc":[{"batl":[[0,1.53,1366.79]],"ltp":1.53,"tv":30479.79,"id":5300820},{"batb":[[2,2.84,21.52]],"ltp":2.92,"tv":13134.89,"id":9629022}]}]}
{"op":"mcm","clk":"4215262209","pt":1631536798547,"mc":[{"id":"1.187557985","rc":[{"batb":[[0,1.5,35.29],[1,1.49,324.96],[2,1.48,365.42]],"ltp":1.53,"tv":30479.79,"id":5300820}]}]}
{"op":"mcm","clk":"4215262321","pt":1631536800382,"mc":[{"id":"1.187557985","rc":[{"batb":[[2,2.86,3]],"ltp":2.92,"tv":13134.89,"id":9629022}]}]}
{"op":"mcm","clk":"4215262682","pt":1631536804793,"mc":[{"id":"1.187557985","rc":[{"batl":[[0,1.53,1451.79]],"ltp":1.53,"tv":30479.79,"id":5300820}]}]}
{"op":"mcm","clk":"4215263094","pt":1631536810861,"mc":[{"id":"1.187557985","rc":[{"batb":[[0,1.5,38.83]],"ltp":1.53,"tv":30479.79,"id":5300820}]}]}
{"op":"mcm","clk":"4215263654","pt":1631536819606,"mc":[{"id":"1.187557985","rc":[{"batb":[[2,2.84,21.52]],"ltp":2.92,"tv":13134.89,"id":9629022}]}]}
{"op":"mcm","clk":"4215263903","pt":1631536823580,"mc":[{"id":"1.187557985","rc":[{"trd":[[1.53,3124.2]],"batl":[[0,1.53,848.97]],"ltp":1.53,"tv":31685.43,"id":5300820},{"batb":[[2,2.86,3]],"ltp":2.92,"tv":13134.89,"id":9629022}],"tv":44820.33}]}
{"op":"mcm","clk":"4215263916","pt":1631536823777,"mc":[{"id":"1.187557985","rc":[{"trd":[[1.53,3268.86]],"batl":[[0,1.53,776.63]],"ltp":1.53,"tv":31830.09,"id":5300820}],"tv":44964.99}]}
{"op":"mcm","clk":"4215264122","pt":1631536827120,"mc":[{"id":"1.187557985","rc":[{"batb":[[1,2.86,3],[2,2.84,21.52]],"batl":[[0,3.05,308.5]],"ltp":2.92,"tv":13134.89,"id":9629022}]}]}
{"op":"mcm","clk":"4215264443","pt":1631536832088,"mc":[{"id":"1.187557985","rc":[{"batb":[[0,1.5,466.43]],"ltp":1.53,"tv":31830.09,"id":5300820},{"batl":[[0,3,213.8],[1,3.05,308.5],[2,3.15,35.87]],"ltp":2.92,"tv":13134.89,"id":9629022}]}]}
{"op":"mcm","clk":"4215264686","pt":1631536835811,"mc":[{"id":"1.187557985","rc":[{"batl":[[0,1.53,691.63]],"ltp":1.53,"tv":31830.09,"id":5300820}]}]}
{"op":"mcm","clk":"4215264842","pt":1631536838511,"mc":[{"id":"1.187557985","rc":[{"trd":[[2.92,132.37]],"batb":[[0,2.92,176.5]],"ltp":2.92,"tv":13136.99,"id":9629022}],"tv":44967.09}]}
{"op":"mcm","clk":"4215264900","pt":1631536839407,"mc":[{"id":"1.187557985","rc":[{"trd":[[1.5,1105.25],[1.53,3273.51]],"batb":[[0,1.5,446.43]],"batl":[[0,1.53,689.31]],"ltp":1.5,"tv":31874.74,"id":5300820}],"tv":45011.73}]}
{"op":"mcm","clk":"4215265082","pt":1631536842029,"mc":[{"id":"1.187557985","rc":[{"batl":[[0,1.52,85],[1,1.53,689.31],[2,1.54,237.09]],"ltp":1.5,"tv":31874.74,"id":5300820}]}]}
{"op":"mcm","clk":"4215265808","pt":1631536854428,"mc":[{"id":"1.187557985","rc":[{"trd":[[1.5,1106.03]],"batb":[[0,1.5,446.04]],"ltp":1.5,"tv":31875.51,"id":5300820}],"tv":45012.51}]}
{"op":"mcm","clk":"4215265831","pt":1631536855047,"mc":[{"id":"1.187557985","rc":[{"trd":[[1.5,1112.03]],"batb":[[0,1.5,443.04]],"ltp":1.5,"tv":31881.51,"id":5300820}],"tv":45018.51}]}
{"op":"mcm","clk":"4215265920","pt":1631536857019,"mc":[{"id":"1.187557985","rc":[{"batb":[[0,1.51,4.26],[1,1.5,443.49],[2,1.49,324.96]],"ltp":1.5,"tv":31881.51,"id":5300820}]}]}
{"op":"mcm","clk":"4215268021","pt":1631536879583,"mc":[{"id":"1.187557985","rc":[{"trd":[[1.5,1134.69],[1.51,1609.49]],"batb":[[0,1.5,432.16],[1,1.49,324.96],[2,1.48,365.42]],"ltp":1.5,"tv":31912.69,"id":5300820}],"tv":45049.68}]}
{"op":"mcm","clk":"4215268189","pt":1631536882509,"mc":[{"id":"1.187557985","rc":[{"batb":[[2,2.84,23.52]],"ltp":2.92,"tv":13136.99,"id":9629022}]}]}
{"op":"mcm","clk":"4215268267","pt":1631536883600,"mc":[{"id":"1.187557985","rc":[{"batl":[[0,1.53,689.31],[1,1.54,237.09],[2,1.55,1251.22]],"ltp":1.5,"tv":31912.69,"id":5300820}]}]}
{"op":"mcm","clk":"4215268695","pt":1631536890595,"mc":[{"id":"1.187557985","rc":[{"trd":[[2.92,135.45]],"batb":[[0,2.92,174.96]],"ltp":2.92,"tv":13140.07,"id":9629022}],"tv":45052.77}]}
{"op":"mcm","clk":"4215268726","pt":1631536891221,"mc":[{"id":"1.187557985","rc":[{"batl":[[0,1.51,85],[1,1.53,689.31],[2,1.54,237.09]],"ltp":1.5,"tv":31912.69,"id":5300820},{"trd":[[3,428.86]],"batb":[[1,2.84,23.52],[2,2.6,61.67]],"batl":[[0,3,38.33]],"ltp":3.0,"tv":13491.01,"id":9629022}],"tv":45403.7}]}
{"op":"mcm","clk":"4215268948","pt":1631536895237,"mc":[{"id":"1.187557985","rc":[{"trd":[[1.51,1620.74]],"batl":[[0,1.51,73.75]],"ltp":1.51,"tv":31923.94,"id":5300820},{"trd":[[2.96,267.18]],"ltp":2.96,"tv":13496.75,"id":9629022}],"tv":45420.69}]}
{"op":"mcm","clk":"4215269019","pt":1631536896699,"mc":[{"id":"1.187557985","rc":[{"trd":[[1.5,1136.09]],"batb":[[0,1.5,431.46]],"ltp":1.5,"tv":31925.33,"id":5300820}],"tv":45422.09}]}
{"op":"mcm","clk":"4215269593","pt":1631536907321,"mc":[{"id":"1.187557985","rc":[{"trd":[[1.51,1694.49]],"batl":[[0,1.53,646.08],[1,1.54,237.09],[2,1.55,1251.22]],"ltp":1.51,"tv":31999.08,"id":5300820},{"trd":[[2.96,304.82]],"batl":[[0,2.96,137.84],[1,3,38.33],[2,3.05,308.5]],"ltp":2.96,"tv":13534.38,"id":9629022}],"tv":45533.47}]}
{"op":"mcm","clk":"4215269755","pt":1631536909946,"mc":[{"id":"1.187557985","rc":[{"batb":[[0,2.84,21.52],[1,2.6,61.67],[2,2.56,184.11]],"ltp":2.96,"tv":13534.38,"id":9629022}]}]}
{"op":"mcm","clk":"4215269919","pt":1631536912917,"mc":[{"id":"1.187557985","rc":[{"batb":[[0,2.86,19.07],[1,2.84,21.52],[2,2.6,61.67]],"ltp":2.96,"tv":13534.38,"id":9629022}]}]}
{"op":"mcm","clk":"4215270084","pt":1631536915435,"mc":[{"id":"1.187557985","rc":[{"trd":[[1.51,1710.84]],"batl":[[1,1.54,632.14]],"ltp":1.51,"tv":32015.43,"id":5300820},{"trd":[[2.96,313.15]],"batb":[[0,2.88,211.24],[1,2.86,19.07],[2,2.84,21.52]],"batl":[[0,2.96,129.5]],"ltp":2.96,"tv":13542.72,"id":9629022}],"tv":45558.16}]}
{"op":"mcm","clk":"4215270311","pt":1631536919255,"mc":[{"id":"1.187557985","rc":[{"trd":[[1.51,1714.44]],"ltp":1.51,"tv":32019.03,"id":5300820},{"trd":[[2.96,314.99]],"batl":[[0,2.96,127.66]],"ltp":2.96,"tv":13544.56,"id":9629022}],"tv":45563.6}]}
{"op":"mcm","clk":"4215270401","pt":1631536921138,"mc":[{"id":"1.187557985","rc":[{"trd":[[2.88,4.45]],"batb":[[0,2.88,209.24]],"ltp":2.88,"tv":13548.56,"id":9629022}],"tv":45567.6}]}
{"op":"mcm","clk":"4215270509","pt":1631536923127,"mc":[{"id":"1.187557985","rc":[{"batl":[[0,3,38.33],[1,3.05,308.5],[2,3.15,35.87]],"ltp":2.88,"tv":13548.56,"id":9629022}]}]}
{"op":"mcm","clk":"4215270651","pt":1631536925327,"mc":[{"id":"1.187557985","rc":[{"trd":[[1.53,3279.37]],"batl":[[0,1.53,643.15]],"ltp":1.53,"tv":32024.89,"id":5300820}],"tv":45573.46}]}
{"op":"mcm","clk":"4215270706","pt":1631536926263,"mc":[{"id":"1.187557985","rc":[{"trd":[[2.88,259.77]],"batb":[[0,2.88,81.58]],"ltp":2.88,"tv":13803.88,"id":9629022}],"tv":45828.77}]}
{"op":"mcm","clk":"4215270963","pt":1631536930973,"mc":[{"id":"1.187557985","rc":[{"trd":[[1.5,1144.03]],"batb":[[0,1.5,427.49]],"ltp":1.5,"tv":32032.83,"id":5300820}],"tv":45836.71}]}
{"op":"mcm","clk":"4215271088","pt":1631536933349,"mc":[{"id":"1.187557985","rc":[{"batb":[[0,1.49,325.41],[1,1.48,365.42],[2,1.47,625.51]],"ltp":1.5,"tv":32032.83,"id":5300820}]}]}
{"op":"mcm","clk":"4215271119","pt":1631536933762,"mc":[{"id":"1.187557985","rc":[{"batl":[[0,1.51,10],[1,1.53,643.15],[2,1.54,632.14]],"ltp":1.5,"tv":32032.83,"id":5300820}]}]}
{"op":"mcm","clk":"4215271279","pt":1631536936485,"mc":[{"id":"1.187557985","rc":[{"batl":[[0,3.05,308.5],[1,3.15,35.87],[2,3.25,323.65]],"ltp":2.88,"tv":13803.88,"id":9629022}]}]}
{"op":"mcm","clk":"4215271411","pt":1631536938671,"mc":[{"id":"1.187557985","rc":[{"trd":[[1.5,1144.93]],"batb":[[0,1.49,324.96]],"batl":[[0,1.5,7.21],[1,1.51,10],[2,1.53,643.15]],"ltp":1.5,"tv":32033.73,"id":5300820}],"tv":45837.61}]}
{"op":"mcm","clk":"4215271574","pt":1631536941374,"mc":[{"id":"1.187557985","rc":[{"trd":[[1.48,1240.58],[1.49,1316.22]],"batb":[[0,1.47,625.51],[1,1.46,7],[2,1.44,58.42]],"ltp":1.48,"tv":33809.29,"id":5300820},{"trd":[[3.05,204.05]],"batl":[[0,3.05,116.95]],"ltp":3.05,"tv":13995.43,"id":9629022}],"tv":47804.72}]}
{"op":"mcm","clk":"4215271609","pt":1631536941979,"mc":[{"id":"1.187557985","rc":[{"trd":[[1.5,1159.35],[1.51,1724.2]],"batl":[[0,1.51,5.12],[1,1.53,295.81],[2,1.54,435.8]],"ltp":1.51,"tv":33833.47,"id":5300820}],"tv":47828.9}]}
{"op":"mcm","clk":"4215271758","pt":1631536944900,"mc":[{"id":"1.187557985","rc":[{"batb":[[0,1.48,40.19],[1,1.47,747.1],[2,1.46,256.56]],"batl":[[0,1.51,181.29],[1,1.52,209.09],[2,1.53,295.81]],"ltp":1.51,"tv":33833.47,"id":5300820}]}]}
{"op":"mcm","clk":"4215272283","pt":1631536954298,"mc":[{"id":"1.187557985","rc":[{"trd":[[1.51,1897.95]],"batb":[[1,1.47,625.59],[2,1.46,7]],"batl":[[0,1.52,209.09],[1,1.53,295.81],[2,1.54,435.8]],"ltp":1.51,"tv":34007.22,"id":5300820}],"tv":48002.65}]}
{"op":"mcm","clk":"4215272435","pt":1631536957217,"mc":[{"id":"1.187557985","rc":[{"trd":[[1.48,1256.34]],"batb":[[0,1.48,208.76]],"batl":[[0,1.52,329.82],[1,1.53,498.4]],"ltp":1.48,"tv":34022.98,"id":5300820},{"batb":[[1,2.84,24.52],[2,2.82,3]],"ltp":3.05,"tv":13995.43,"id":9629022}],"tv":48018.41}]}
{"op":"mcm","clk":"4215272582","pt":1631536960102,"mc":[{"id":"1.187557985","rc":[{"batb":[[0,2.88,100.65]],"ltp":3.05,"tv":13995.43,"id":9629022}]}]}
{"op":"mcm","clk":"4215272723","pt":1631536962605,"mc":[{"id":"1.187557985","rc":[{"batb":[[0,1.48,624.43]],"ltp":1.48,"tv":34022.98,"id":5300820},{"batl":[[1,3.1,198.45],[2,3.15,35.87]],"ltp":3.05,"tv":13995.43,"id":9629022}]}]}
{"op":"mcm","clk":"4215272811","pt":1631536964224,"mc":[{"id":"1.187557985","rc":[{"batl":[[0,1.52,743.79]],"ltp":1.48,"tv":34022.98,"id":5300820},{"batb":[[0,2.92,215.49],[1,2.88,100.65],[2,2.84,24.52]],"ltp":3.05,"tv":13995.43,"id":9629022}]}]}
{"op":"mcm","clk":"4215272994","pt":1631536967518,"mc":[{"id":"1.187557985","rc":[{"batb":[[0,1.49,5],[1,1.48,624.43],[2,1.47,625.59]],"ltp":1.48,"tv":34022.98,"id":5300820}]}]}
{"op":"mcm","clk":"4215273787","pt":1631536980348,"mc":[{"id":"1.187557985","rc":[{"batb":[[0,1.48,624.43],[1,1.47,625.59],[2,1.46,7]],"ltp":1.48,"tv":34022.98,"id":5300820}]}]}
{"op":"mcm","clk":"4215273988","pt":1631536983568,"mc":[{"id":"1.187557985","rc":[{"trd":[[1.52,3538.59]],"batl":[[0,1.52,741.47]],"ltp":1.52,"tv":34027.63,"id":5300820}],"tv":48023.06}]}
{"op":"mcm","clk":"4215274330","pt":1631536989642,"mc":[{"id":"1.187557985","rc":[{"trd":[[1.52,3547.55]],"batl":[[0,1.52,736.99]],"ltp":1.52,"tv":34036.59,"id":5300820}],"tv":48032.02}]}
{"op":"mcm","clk":"4215275125","pt":1631537004608,"mc":[{"id":"1.187557985","rc":[{"trd":[[1.48,1448.96]],"batb":[[0,1.48,415.67]],"ltp":1.48,"tv":34229.21,"id":5300820}],"tv":48224.64}]}
{"op":"mcm","clk":"4215275264","pt":1631537007507,"mc":[{"id":"1.187557985","rc":[{"batb":[[1,1.47,765.05],[2,1.46,256.58]],"batl":[[0,1.52,780.8]],"ltp":1.48,"tv":34229.21,"id":5300820}]}]}
{"op":"mcm","clk":"4215275321","pt":1631537008507,"mc":[{"id":"1.187557985","rc":[{"trd":[[1.52,3679.55]],"batb":[[0,1.48,448.59]],"batl":[[0,1.52,714.8]],"ltp":1.52,"tv":34361.21,"id":5300820}],"tv":48356.64}]}
{"op":"mcm","clk":"4215275342","pt":1631537008770,"mc":[{"id":"1.187557985","rc":[{"batb":[[1,1.47,625.61],[2,1.46,7]],"ltp":1.52,"tv":34361.21,"id":5300820}]}]}
{"op":"mcm","clk":"4215275410","pt":1631537010400,"mc":[{"id":"1.187557985","rc":[{"batb":[[0,1.48,32.92]],"batl":[[0,1.52,300.83],[2,1.54,40.75]],"ltp":1.52,"tv":34361.21,"id":5300820},{"batb":[[0,2.88,19.07],[1,2.84,24.52],[2,2.82,3]],"batl":[[1,3.15,35.87],[2,3.25,323.65]],"ltp":3.05,"tv":13995.43,"id":9629022}]}]}
{"op":"mcm","clk":"4215275426","pt":1631537010714,"mc":[{"id":"1.187557985","rc":[{"batb":[[0,2.84,24.52],[1,2.82,3],[2,2.6,61.67]],"ltp":3.05,"tv":13995.43,"id":9629022}]}]}
{"op":"mcm","clk":"4215275485","pt":1631537011683,"mc":[{"id":"1.187557985","rc":[{"batb":[[0,1.48,216.75]],"batl":[[0,1.52,322.72]],"ltp":1.52,"tv":34361.21,"id":5300820}]}]}
{"op":"mcm","clk":"4215275639","pt":1631537014386,"mc":[{"id":"1.187557985","rc":[{"batb":[[0,2.86,22.89],[1,2.84,24.52],[2,2.82,3]],"ltp":3.05,"tv":13995.43,"id":9629022}]}]}
{"op":"mcm","clk":"4215276251","pt":1631537025635,"mc":[{"id":"1.187557985","rc":[{"batb":[[0,1.47,43.75],[1,1.41,363.94],[2,1.4,409.06]],"batl":[[0,1.53,20],[1,1.55,30],[2,1.6,6.51]],"ltp":1.52,"tv":34361.21,"id":5300820},{"batb":[[0,2.84,16.3],[1,2.6,61.67],[2,2.56,184.11]],"batl":[[0,3.15,20.45],[1,3.4,160.43],[2,3.45,130.42]],"ltp":3.05,"tv":13995.43,"id":9629022}]}]}
{"op":"mcm","clk":"4215276315","pt":1631537026427,"mc":[{"id":"1.187557985","rc":[{"batb":[[0,1.41,363.94],[1,1.4,409.06],[2,1.39,781.47]],"batl":[[1,1.6,6.51],[2,1.64,289.86]],"ltp":1.52,"tv":34361.21,"id":5300820},{"batb":[[0,2.6,61.67],[1,2.56,184.11],[2,2.54,168.82]],"batl":[[0,3.4,160.43],[1,3.45,130.42],[2,3.5,188.15]],"ltp":3.05,"tv":13995.43,"id":9629022}]}]}
{"op":"mcm","clk":"4215276426","pt":1631537028524,"mc":[{"id":"1.187557985","rc":[{"batb":[[1,1.4,873.71],[2,1.39,1090.22]],"batl":[[2,1.64,446.16]],"ltp":1.52,"tv":34361.21,"id":5300820},{"batb":[[1,2.58,63.68],[2,2.56,184.11]],"ltp":3.05,"tv":13995.43,"id":9629022}]}]}
{"op":"mcm","clk":"4215276461","pt":1631537028903,"mc":[{"id":"1.187557985","rc":[{"batb":[[0,1.41,364.78],[2,1.39,869.97]],"ltp":1.52,"tv":34361.21,"id":5300820},{"batb":[[0,2.58,63.68],[1,2.56,184.11],[2,2.54,168.82]],"ltp":3.05,"tv":13995.43,"id":9629022}]}]}
{"op":"mcm","clk":"4215276672","pt":1631537032924,"mc":[{"id":"1.187557985","rc":[{"batb":[[1,1.4,625.54],[2,1.39,561.22]],"batl":[[2,1.64,289.86]],"ltp":1.52,"tv":34361.21,"id":5300820}]}]}
{"op":"mcm","clk":"4215276820","pt":1631537035616,"mc":[{"id":"1.187557985","rc":[{"batl":[[0,3.1,4],[1,3.4,160.43],[2,3.45,130.42]],"ltp":3.05,"tv":13995.43,"id":9629022}]}]}
{"op":"mcm","clk":"4215276841","pt":1631537036024,"mc":[{"id":"1.187557985","rc":[{"batb":[[0,1.52,137.13],[1,1.5,233.09],[2,1.49,228.04]],"batl":[[1,1.54,236.38],[2,1.55,193.22]],"ltp":1.52,"tv":34361.21,"id":5300820},{"batl":[[0,3.4,160.43],[1,3.45,130.42],[2,3.5,188.15]],"ltp":3.05,"tv":13995.43,"id":9629022}]}]}
{"op":"mcm","clk":"4215276908","pt":1631537037239,"mc":[{"id":"1.187557985","rc":[{"batb":[[0,2.6,66.82],[1,2.58,63.68],[2,2.56,184.11]],"batl":[[0,3.35,62.31],[1,3.4,160.43],[2,3.45,130.42]],"ltp":3.05,"tv":13995.43,"id":9629022}]}]}
{"op":"mcm","clk":"4215276991","pt":1631537038625,"mc":[{"id":"1.187557985","rc":[{"batb":[[1,1.42,8],[2,1.41,363.94]],"batl":[[1,1.6,6.51],[2,1.64,289.86]],"ltp":1.52,"tv":34361.21,"id":5300820},{"batb":[[0,2.58,63.68],[1,2.56,184.11],[2,2.54,168.82]],"batl":[[0,3.4,160.43],[1,3.45,130.42],[2,3.5,188.15]],"ltp":3.05,"tv":13995.43,"id":9629022}]}]}
{"op":"mcm","clk":"4215277039","pt":1631537039439,"mc":[{"id":"1.187557985","rc":[{"batb":[[0,1.52,136.29]],"ltp":1.52,"tv":34361.21,"id":5300820}]}]}
{"op":"mcm","clk":"4215277082","pt":1631537040129,"mc":[{"id":"1.187557985","rc":[{"batb":[[0,1.52,10.95]],"ltp":1.52,"tv":34361.21,"id":5300820}]}]}
{"op":"mcm","clk":"4215277152","pt":1631537041440,"mc":[{"id":"1.187557985","rc":[{"batl":[[2,1.64,446.16]],"ltp":1.52,"tv":34361.21,"id":5300820}]}]}
{"op":"mcm","clk":"4215277975","pt":1631537056037,"mc":[{"id":"1.187557985","rc":[{"trd":[[1.53,3319.37]],"batb":[[0,1.53,24],[1,1.52,10.95],[2,1.42,8]],"batl":[[0,1.6,6.51],[1,1.64,446.16],[2,1.65,398.68]],"ltp":1.53,"tv":34401.21,"id":5300820}],"tv":48396.64}]}
{"op":"mcm","clk":"4215278114","pt":1631537058033,"mc":[{"id":"1.187557985","rc":[{"batb":[[1,1.42,8],[2,1.41,363.94]],"batl":[[1,3.45,2.42],[2,1.65,0]],"ltp":1.53,"tv":34401.21,"id":5300820},{"batb":[[1,1.37,4],[2,1.3,10]],"ltp":3.05,"tv":13995.43,"id":9629022}]}]}
{"op":"mcm","clk":"4215278198","pt":1631537059452,"mc":[{"id":"1.187557985","rc":[{"trd":[[1.42,44.16],[1.53,3367.37]],"batb":[[0,1.41,363.94],[1,1.4,873.71],[2,1.39,869.97]],"ltp":1.42,"tv":34465.22,"id":5300820}],"tv":48460.65}]}
{"op":"mcm","clk":"4215278258","pt":1631537060646,"mc":[{"id":"1.187557985","rc":[{"batl":[[0,1.43,3.1],[1,1.45,2637.94],[2,1.46,2560.34]],"ltp":1.42,"tv":34465.22,"id":5300820}]}]}
{"op":"mcm","clk":"4215278317","pt":1631537061650,"mc":[{"id":"1.187557985","rc":[{"trd":[[1.43,14.42]],"batb":[[0,1.41,375.26],[2,1.39,875.7]],"batl":[[0,1.43,193.55],[1,1.44,260.12],[2,1.45,1318.96]],"ltp":1.43,"tv":34479.64,"id":5300820},{"trd":[[3.3,14.25]],"batb":[[0,3.25,86.27],[1,2.88,47.7],[2,2.58,63.68]],"batl":[[0,3.45,130.42],[1,3.5,188.15],[2,6,3]],"ltp":3.3,"tv":14001.68,"id":9629022}],"tv":48481.32}]}
{"op":"mcm","clk":"4215278380","pt":1631537062659,"mc":[{"id":"1.187557985","rc":[{"batb":[[2,1.39,923.73]],"ltp":1.43,"tv":34479.64,"id":5300820},{"batb":[[2,1.37,4]],"batl":[[1,3.5,207.12]],"ltp":3.3,"tv":14001.68,"id":9629022}]}]}
{"op":"mcm","clk":"4215278452","pt":1631537064067,"mc":[{"id":"1.187557985","rc":[{"batb":[[2,1.39,926.73]],"ltp":1.43,"tv":34479.64,"id":5300820},{"batb":[[2,2.68,3]],"ltp":3.3,"tv":14001.68,"id":9629022}]}]}
{"op":"mcm","clk":"4215278515","pt":1631537065573,"mc":[{"id":"1.187557985","rc":[{"trd":[[1.43,20.9]],"batb":[[0,1.41,452.08]],"batl":[[0,1.43,248.74],[1,1.44,340.92]],"ltp":1.43,"tv":34486.11,"id":5300820},{"trd":[[3.3,15.17]],"ltp":3.3,"tv":14002.6,"id":9629022}],"tv":48488.72}]}
{"op":"mcm","clk":"4215278569","pt":1631537066368,"mc":[{"id":"1.187557985","rc":[{"batb":[[1,1.4,935.14]],"ltp":1.43,"tv":34486.11,"id":5300820},{"batb":[[0,3.25,94.82],[1,3.1,14.28],[2,2.88,47.7]],"ltp":3.3,"tv":14002.6,"id":9629022}]}]}
{"op":"mcm","clk":"4215278619","pt":1631537067263,"mc":[{"id":"1.187557985","rc":[{"batb":[[1,3,5]],"batl":[[2,3.95,2.9]],"ltp":3.3,"tv":14002.6,"id":9629022}]}]}
{"op":"mcm","clk":"4215278657","pt":1631537067879,"mc":[{"id":"1.187557985","rc":[{"batl":[[2,3.8,144.75]],"ltp":3.3,"tv":14002.6,"id":9629022}]}]}
{"op":"mcm","clk":"4215278787","pt":1631537070451,"mc":[{"id":"1.187557985","rc":[{"trd":[[1.43,88.15]],"batl":[[0,1.43,59.5]],"ltp":1.43,"tv":34553.36,"id":5300820},{"batb":[[1,3.15,13.95],[2,3,5]],"ltp":3.3,"tv":14002.6,"id":9629022}],"tv":48555.97}]}
{"op":"mcm","clk":"4215278841","pt":1631537071262,"mc":[{"id":"1.187557985","rc":[{"batb":[[0,1.41,571.08]],"ltp":1.43,"tv":34553.36,"id":5300820}]}]}
{"op":"mcm","clk":"4215278888","pt":1631537071933,"mc":[{"id":"1.187557985","rc":[{"batb":[[1,1.4,873.71]],"batl":[[1,1.44,260.12]],"ltp":1.43,"tv":34553.36,"id":5300820}]}]}
{"op":"mcm","clk":"4215278963","pt":1631537073365,"mc":[{"id":"1.187557985","rc":[{"batb":[[1,1.4,907.38]],"batl":[[1,1.44,430.89],[2,1.45,1569.33]],"ltp":1.43,"tv":34553.36,"id":5300820}]}]}
{"op":"mcm","clk":"4215279024","pt":1631537074561,"mc":[{"id":"1.187557985","rc":[{"trd":[[1.41,27.13]],"batb":[[0,1.41,493.88]],"batl":[[0,1.44,430.89],[1,1.45,1569.33],[2,1.46,1310.16]],"ltp":1.41,"tv":34554.11,"id":5300820}],"tv":48556.72}]}
{"op":"mcm","clk":"4215279055","pt":1631537075283,"mc":[{"id":"1.187557985","rc":[{"trd":[[1.41,34.37]],"batb":[[0,1.41,490.26]],"ltp":1.41,"tv":34561.35,"id":5300820}],"tv":48563.95}]}
{"op":"mcm","clk":"4215279153","pt":1631537077581,"mc":[{"id":"1.187557985","rc":[{"batb":[[0,1.42,8.52],[1,1.41,490.26],[2,1.4,907.38]],"batl":[[1,1.45,250.37],[2,1.46,30]],"ltp":1.41,"tv":34561.35,"id":5300820}]}]}
{"op":"mcm","clk":"4215279205","pt":1631537078471,"mc":[{"id":"1.187557985","rc":[{"batb":[[1,1.41,119],[2,1.39,133.03]],"batl":[[0,1.46,30],[1,1.52,400],[2,1.54,276.97]],"ltp":1.41,"tv":34561.35,"id":5300820},{"batb":[[0,3.15,13.95],[1,2.88,47.53],[2,2.86,173.04]],"batl":[[0,3.5,18.97],[1,3.8,144.75],[2,3.85,165.88]],"ltp":3.3,"tv":14002.6,"id":9629022}]}]}
{"op":"mcm","clk":"4215279252","pt":1631537079363,"mc":[{"id":"1.187557985","rc":[{"batb":[[1,1.39,85],[2,1.36,360.62]],"batl":[[0,1.52,400],[1,1.54,276.97],[2,1.55,327.18]],"ltp":1.41,"tv":34561.35,"id":5300820},{"batb":[[0,2.88,47.53],[1,2.86,173.04],[2,2.84,156.5]],"batl":[[0,3.8,144.75],[1,3.85,165.88],[2,3.9,172.63]],"ltp":3.3,"tv":14002.6,"id":9629022}]}]}
{"op":"mcm","clk":"4215279310","pt":1631537080655,"mc":[{"id":"1.187557985","rc":[{"batl":[[0,1.51,47.5],[2,1.55,374.68]],"ltp":1.41,"tv":34561.35,"id":5300820},{"batb":[[0,2.96,4.63],[1,2.88,47.53],[2,2.86,173.04]],"ltp":3.3,"tv":14002.6,"id":9629022}]}]}
{"op":"mcm","clk":"4215279343","pt":1631537081306,"mc":[{"id":"1.187557985","rc":[{"batl":[[0,1.53,163.11],[1,1.54,475.24]],"ltp":1.41,"tv":34561.35,"id":5300820},{"batb":[[0,2.88,47.53],[1,2.86,173.04],[2,2.84,156.5]],"ltp":3.3,"tv":14002.6,"id":9629022}]}]}
{"op":"mcm","clk":"4215279483","pt":1631537084497,"mc":[{"id":"1.187557985","rc":[{"batl":[[0,1.5,57.61],[1,1.53,163.11],[2,1.54,475.24]],"ltp":1.41,"tv":34561.35,"id":5300820},{"batb":[[0,3,5],[1,2.88,47.53],[2,2.86,173.04]],"ltp":3.3,"tv":14002.6,"id":9629022}]}]}
{"op":"mcm","clk":"4215279504","pt":1631537084797,"mc":[{"id":"1.187557985","rc":[{"batl":[[0,1.53,163.11],[1,1.54,475.24],[2,1.55,374.68]],"ltp":1.41,"tv":34561.35,"id":5300820},{"batb":[[0,2.88,47.53],[1,2.86,173.04],[2,2.84,156.5]],"ltp":3.3,"tv":14002.6,"id":9629022}]}]}
{"op":"mcm","clk":"4215279575","pt":1631537086163,"mc":[{"id":"1.187557985","rc":[{"batb":[[0,1.39,85],[1,1.36,360.62],[2,1.35,372.44]],"ltp":1.41,"tv":34561.35,"id":5300820}]}]}
{"op":"mcm","clk":"4215279716","pt":1631537088777,"mc":[{"id":"1.187557985","rc":[{"batb":[[1,1.34,338.22],[2,1.3,77.18]],"ltp":1.41,"tv":34561.35,"id":5300820},{"batl":[[0,3.95,2.9],[1,4.4,2.09],[2,4.5,2.55]],"ltp":3.3,"tv":14002.6,"id":9629022}]}]}
{"op":"mcm","clk":"4215279800","pt":1631537090601,"mc":[{"id":"1.187557985","rc":[{"batb":[[0,1.49,13.12],[1,1.39,85],[2,1.34,338.22]],"ltp":1.41,"tv":34561.35,"id":5300820}]}]}
{"op":"mcm","clk":"4215279863","pt":1631537091596,"mc":[{"id":"1.187557985","rc":[{"batb":[[0,1.39,85],[1,1.34,338.22],[2,1.3,77.18]],"batl":[[0,1.5,45.87],[1,1.53,163.11],[2,1.54,475.24]],"ltp":1.41,"tv":34561.35,"id":5300820},{"trd":[[2.88,273.85]],"batb":[[0,3,5],[1,2.88,40.49],[2,2.86,173.04]],"batl":[[0,3.1,1233.88],[1,3.15,1197.58],[2,3.2,1197.58]],"ltp":2.88,"tv":14016.68,"id":9629022}],"tv":48578.04}]}
{"op":"mcm","clk":"4215279919","pt":1631537092586,"mc":[{"id":"1.187557985","rc":[{"trd":[[1.5,1180.49]],"batb":[[0,1.49,501.59],[1,1.48,234.86],[2,1.45,12.41]],"batl":[[0,1.53,163.11],[1,1.54,475.24],[2,1.55,374.68]],"ltp":1.5,"tv":34582.48,"id":5300820},{"batb":[[0,2.88,40.49],[1,2.86,173.04],[2,2.84,156.5]],"batl":[[0,3.1,616.94],[1,3.15,598.8],[2,3.2,598.8]],"ltp":2.88,"tv":14016.68,"id":9629022}],"tv":48599.17}]}
{"op":"mcm","clk":"4215279977","pt":1631537093595,"mc":[{"id":"1.187557985","rc":[{"batb":[[2,1.46,44.23]],"batl":[[2,1.55,404.68]],"ltp":1.5,"tv":34582.48,"id":5300820},{"batb":[[2,2.84,172.8]],"batl":[[2,3.2,619.02]],"ltp":2.88,"tv":14016.68,"id":9629022}]}]}
{"op":"mcm","clk":"4215279995","pt":1631537093999,"mc":[{"id":"1.187557985","rc":[{"batb":[[1,1.48,240.86],[2,1.47,6]],"ltp":1.5,"tv":34582.48,"id":5300820}]}]}
{"op":"mcm","clk":"4215280121","pt":1631537096664,"mc":[{"id":"1.187557985","rc":[{"trd":[[1.52,3685.58]],"batb":[[0,1.5,58.4],[1,1.49,726.5],[2,1.48,240.86]],"batl":[[0,1.52,58.99],[1,1.53,235.03],[2,1.54,475.24]],"ltp":1.52,"tv":34588.5,"id":5300820},{"trd":[[2.92,136.51]],"ltp":2.92,"tv":14017.74,"id":9629022}],"tv":48606.25}]}
{"op":"mcm","clk":"4215280143","pt":1631537097095,"mc":[{"id":"1.187557985","rc":[{"batl":[[0,3.05,21.39],[1,3.1,616.94],[2,3.15,598.8]],"ltp":2.92,"tv":14017.74,"id":9629022}]}]}
{"op":"mcm","clk":"4215280242","pt":1631537099198,"mc":[{"id":"1.187557985","rc":[{"batb":[[0,1.5,152.4]],"ltp":1.52,"tv":34588.5,"id":5300820}]}]}
{"op":"mcm","clk":"4215280298","pt":1631537100204,"mc":[{"id":"1.187557985","rc":[{"batl":[[2,3.15,619.25]],"ltp":2.92,"tv":14017.74,"id":9629022}]}]}
{"op":"mcm","clk":"4215280394","pt":1631537101594,"mc":[{"id":"1.187557985","rc":[{"batb":[[1,1.49,1102.99]],"ltp":1.52,"tv":34588.5,"id":5300820},{"batl":[[0,3.05,205.31]],"ltp":2.92,"tv":14017.74,"id":9629022}]}]}
{"op":"mcm","clk":"4215280469","pt":1631537102932,"mc":[{"id":"1.187557985","rc":[{"batb":[[0,1.51,63.59],[1,1.5,94],[2,1.49,1041.69]],"batl":[[1,1.53,163.11]],"ltp":1.52,"tv":34588.5,"id":5300820}]}]}
{"op":"mcm","clk":"4215280538","pt":1631537104093,"mc":[{"id":"1.187557985","rc":[{"trd":[[1.51,1913.95]],"batb":[[0,1.51,55.59]],"batl":[[1,1.53,562.6]],"ltp":1.51,"tv":34604.5,"id":5300820},{"batb":[[0,2.88,252.71]],"ltp":2.92,"tv":14017.74,"id":9629022}],"tv":48622.25}]}
{"op":"mcm","clk":"4215280581","pt":1631537104927,"mc":[{"id":"1.187557985","rc":[{"batb":[[0,1.5,94],[1,1.49,1041.69],[2,1.48,240.86]],"batl":[[0,1.53,562.6],[1,1.54,475.24],[2,1.55,404.68]],"ltp":1.51,"tv":34604.5,"id":5300820}]}]}
{"op":"mcm","clk":"4215280757","pt":1631537108389,"mc":[{"id":"1.187557985","rc":[{"trd":[[1.53,3367.53]],"batb":[[1,1.47,43.75],[2,1.4,214.39]],"batl":[[0,1.55,30],[1,1.6,6.51],[2,1.68,37.14]],"ltp":1.53,"tv":34604.66,"id":5300820},{"batb":[[0,2.84,16.3],[1,2.48,69.96],[2,2.46,6.38]],"batl":[[0,3.15,20.45],[1,3.65,3.5],[2,3.95,2.9]],"ltp":2.92,"tv":14017.74,"id":9629022}],"tv":48622.41}]}
{"op":"mcm","clk":"4215280806","pt":1631537109504,"mc":[{"id":"1.187557985","rc":[{"batb":[[0,1.4,214.39],[1,1.39,85],[2,1.38,75.46]],"batl":[[0,1.6,6.51],[1,1.68,37.14],[2,1.75,34.7]],"ltp":1.53,"tv":34604.66,"id":5300820},{"batb":[[0,2.48,69.96],[1,2.46,6.38],[2,2.32,6.89]],"batl":[[0,3.65,3.5],[1,3.95,2.9],[2,4.2,2.63]],"ltp":2.92,"tv":14017.74,"id":9629022}]}]}
{"op":"mcm","clk":"4215280893","pt":1631537111397,"mc":[{"id":"1.187557985","rc":[{"batb":[[0,1.4,513.75],[1,1.39,393.94]],"batl":[[2,1.69,236.66]],"ltp":1.53,"tv":34604.66,"id":5300820}]}]}
{"op":"mcm","clk":"4215280925","pt":1631537112325,"mc":[{"id":"1.187557985","rc":[{"batb":[[0,1.53,27.89],[1,1.4,513.75],[2,1.39,393.94]],"ltp":1.53,"tv":34604.66,"id":5300820}]}]}
{"op":"mcm","clk":"4215280952","pt":1631537112809,"mc":[{"id":"1.187557985","rc":[{"batb":[[1,1.4,214.39],[2,1.39,85]],"batl":[[2,1.75,34.7]],"ltp":1.53,"tv":34604.66,"id":5300820}]}]}
{"op":"mcm","clk":"4215281094","pt":1631537115640,"mc":[{"id":"1.187557985","rc":[{"batb":[[1,1.52,243.75],[2,1.51,215.86]],"batl":[[0,1.56,189.27],[1,1.57,184.13],[2,1.6,6.51]],"ltp":1.53,"tv":34604.66,"id":5300820}]}]}
{"op":"mcm","clk":"4215281127","pt":1631537116196,"mc":[{"id":"1.187557985","rc":[{"trd":[[1.55,1304.82]],"batb":[[0,1.55,79.2],[1,1.53,27.89],[2,1.52,243.75]],"ltp":1.55,"tv":34682.5,"id":5300820},{"trd":[[2.82,23.96]],"ltp":2.82,"tv":14037.71,"id":9629022}],"tv":48720.22}]}
{"op":"mcm","clk":"4215281166","pt":1631537117136,"mc":[{"id":"1.187557985","rc":[{"batl":[[2,1.59,32.55]],"ltp":1.55,"tv":34682.5,"id":5300820},{"batb":[[0,2.5,80.2],[1,2.48,69.96],[2,2.46,6.38]],"batl":[[0,3.3,17.5],[1,3.65,3.5],[2,3.95,2.9]],"ltp":2.82,"tv":14037.71,"id":9629022}]}]}
{"op":"mcm","clk":"4215281277","pt":1631537119457,"mc":[{"id":"1.187557985","rc":[{"trd":[[1.6,1309.72]],"batb":[[0,1.6,21.38],[1,1.55,79.2],[2,1.53,27.89]],"batl":[[0,1.68,37.14],[1,1.75,34.7],[2,1.76,29.52]],"ltp":1.6,"tv":34695.52,"id":5300820},{"batb":[[0,2.48,69.96],[1,2.46,6.38],[2,2.32,6.89]],"batl":[[0,3.65,3.5],[1,3.95,2.9],[2,4.2,2.63]],"ltp":2.82,"tv":14037.71,"id":9629022}],"tv":48733.23}]}
{"op":"mcm","clk":"4215281312","pt":1631537120027,"mc":[{"id":"1.187557985","rc":[{"batl":[[0,1.76,29.52],[1,3.45,2.42],[2,1.76,0]],"ltp":1.6,"tv":34695.52,"id":5300820},{"batb":[[1,2.3,5.58],[2,2,2]],"ltp":2.82,"tv":14037.71,"id":9629022}]}]}
{"op":"mcm","clk":"4215281425","pt":1631537122623,"mc":[{"id":"1.187557985","rc":[{"batl":[[0,1.67,5],[1,1.68,6],[2,1.69,236.62]],"ltp":1.6,"tv":34695.52,"id":5300820},{"batb":[[0,2.48,72.96],[1,2.46,3],[2,2.3,5.58]],"ltp":2.82,"tv":14037.71,"id":9629022}]}]}
{"op":"mcm","clk":"4215281455","pt":1631537123313,"mc":[{"id":"1.187557985","rc":[{"trd":[[1.6,1313.72]],"batb":[[0,1.6,19.38]],"batl":[[2,1.69,240.62]],"ltp":1.6,"tv":34699.52,"id":5300820}],"tv":48737.23}]}
{"op":"mcm","clk":"4215281523","pt":1631537124448,"mc":[{"id":"1.187557985","rc":[{"trd":[[1.55,1463.21],[1.6,1352.49]],"batb":[[0,1.53,27.89],[1,1.4,513.81],[2,1.39,393.94]],"batl":[[0,1.55,301.42],[1,1.67,5],[2,1.68,6]],"ltp":1.55,"tv":34896.68,"id":5300820}],"tv":48934.39}]}
{"op":"mcm","clk":"4215281570","pt":1631537125452,"mc":[{"id":"1.187557985","rc":[{"trd":[[1.55,1519]],"batb":[[1,1.4,214.39],[2,1.39,85]],"batl":[[0,1.55,273.52]],"ltp":1.55,"tv":34952.47,"id":5300820}],"tv":48990.18}]}
{"op":"mcm","clk":"4215281636","pt":1631537126639,"mc":[{"id":"1.187557985","rc":[{"trd":[[1.55,2066.09],[1.67,98.75],[1.68,236.39]],"batb":[[1,1.41,8],[2,1.4,214.39]],"batl":[[0,1.6,2],[1,1.68,35.39],[2,1.69,240.62]],"ltp":1.68,"tv":35521.56,"id":5300820},{"batb":[[1,2.46,8.88]],"ltp":2.82,"tv":14037.71,"id":9629022}],"tv":49559.28}]}
{"op":"mcm","clk":"4215281688","pt":1631537127625,"mc":[{"id":"1.187557985","rc":[{"trd":[[1.6,1356.49]],"batb":[[0,1.64,10.16],[1,1.53,27.89],[2,1.41,8]],"batl":[[0,1.69,236.62],[1,1.71,272.99],[2,1.76,29.52]],"ltp":1.6,"tv":35525.56,"id":5300820},{"batb":[[0,2.48,69.96],[1,2.3,5.58],[2,2,2]],"ltp":2.82,"tv":14037.71,"id":9629022}],"tv":49563.28}]}
{"op":"mcm","clk":"4215281731","pt":1631537128528,"mc":[{"id":"1.187557985","rc":[{"batb":[[0,1.64,170.79],[1,1.63,170.63],[2,1.61,4.95]],"ltp":1.6,"tv":35525.56,"id":5300820},{"trd":[[2.48,83.22]],"batb":[[0,2.48,61.89],[1,2.38,441.96],[2,2.36,428.97]],"batl":[[0,2.6,735.58],[1,2.62,713.94],[2,2.64,713.94]],"ltp":2.48,"tv":14053.84,"id":9629022}],"tv":49579.4}]}
{"op":"mcm","clk":"4215281788","pt":1631537129642,"mc":[{"id":"1.187557985","rc":[{"trd":[[1.64,484.81]],"batb":[[0,1.64,149.52],[2,1.62,120]],"ltp":1.64,"tv":35568.1,"id":5300820}],"tv":49621.94}]}
{"op":"mcm","clk":"4215281890","pt":1631537131563,"mc":[{"id":"1.187557985","rc":[{"trd":[[1.64,705.13],[1.68,264.28]],"batb":[[0,1.63,170.63],[1,1.62,120],[2,1.61,4.95]],"batl":[[0,1.76,29.52],[1,1.81,11.05],[2,1.85,8.62]],"ltp":1.68,"tv":35816.31,"id":5300820},{"trd":[[2.48,102.13]],"batb":[[0,2.48,42.98]],"ltp":2.48,"tv":14072.75,"id":9629022}],"tv":49889.06}]}
{"op":"mcm","clk":"4215281967","pt":1631537132662,"mc":[{"id":"1.187557985","rc":[{"batb":[[0,1.66,72.96],[1,1.65,69.66],[2,1.63,170.63]],"batl":[[0,1.67,203.4],[1,1.68,71.35],[2,1.76,29.52]],"ltp":1.68,"tv":35816.31,"id":5300820}]}]}
{"op":"mcm","clk":"4215282018","pt":1631537133462,"mc":[{"id":"1.187557985","rc":[{"trd":[[1.64,841.18],[1.65,155.77],[1.66,237.96]],"batb":[[0,1.63,170.63],[1,1.62,120],[2,1.61,4.95]],"batl":[[0,1.64,58.18],[1,1.67,203.4],[2,1.68,71.35]],"ltp":1.64,"tv":36237.59,"id":5300820},{"trd":[[2.48,106.53],[2.56,1.26]],"batb":[[0,2.48,40.78],[1,2.46,20.54],[2,2.38,441.96]],"batl":[[0,2.58,22.71],[1,2.6,735.58],[2,2.62,713.94]],"ltp":2.56,"tv":14078.41,"id":9629022}],"tv":50316.0}]}
{"op":"mcm","clk":"4215282078","pt":1631537134554,"mc":[{"id":"1.187557985","rc":[{"batb":[[0,1.63,392.27],[1,1.62,285.01]],"batl":[[2,1.68,252.64]],"ltp":1.64,"tv":36237.59,"id":5300820}]}]}
{"op":"mcm","clk":"4215282094","pt":1631537134864,"mc":[{"id":"1.187557985","rc":[{"batb":[[0,1.63,292.85]],"ltp":1.64,"tv":36237.59,"id":5300820}]}]}
{"op":"mcm","clk":"4215282207","pt":1631537136640,"mc":[{"id":"1.187557985","rc":[{"trd":[[1.64,908.37]],"batl":[[0,1.64,24.58],[2,1.68,282.64]],"ltp":1.64,"tv":36304.78,"id":5300820}],"tv":50383.19}]}
{"op":"mcm","clk":"4215282274","pt":1631537137444,"mc":[{"id":"1.187557985","rc":[{"batb":[[0,1.59,39.05],[1,1.53,27.89],[2,1.5,160.92]],"batl":[[2,1.68,101.35]],"ltp":1.64,"tv":36304.78,"id":5300820},{"batb":[[0,2.46,20.54],[1,2.16,7.78],[2,2.14,106.61]],"batl":[[0,2.7,23],[1,3.2,3.33],[2,3.65,3.5]],"ltp":2.56,"tv":14078.41,"id":9629022}]}]}
{"op":"mcm","clk":"4215282355","pt":1631537138444,"mc":[{"id":"1.187557985","rc":[{"batb":[[0,1.53,27.89],[1,1.5,160.92],[2,1.46,49.38]],"batl":[[2,1.68,71.35]],"ltp":1.64,"tv":36304.78,"id":5300820},{"batb":[[0,2.16,7.78],[1,2.14,106.61],[2,2.1,7.64]],"batl":[[0,3.2,3.33],[1,3.65,3.5],[2,3.8,3.37]],"ltp":2.56,"tv":14078.41,"id":9629022}]}]}
{"op":"mcm","clk":"4215282409","pt":1631537139423,"mc":[{"id":"1.187557985","rc":[{"trd":[[1.64,964.16]],"batb":[[0,1.63,55.41],[1,1.53,27.89],[2,1.5,160.92]],"batl":[[0,1.64,407.62],[1,1.86,29.75],[2,1.9,24.65]],"ltp":1.64,"tv":36360.57,"id":5300820}],"tv":50438.98}]}
{"op":"mcm","clk":"4215282477","pt":1631537140564,"mc":[{"id":"1.187557985","rc":[{"batb":[[2,1.5,483.63]],"batl":[[0,1.64,483.62],[2,1.9,228.36]],"ltp":1.64,"tv":36360.57,"id":5300820},{"batb":[[2,2.12,107.53]],"ltp":2.56,"tv":14078.41,"id":9629022}]}]}
{"op":"mcm","clk":"4215282515","pt":1631537141459,"mc":[{"id":"1.187557985","rc":[{"trd":[[1.64,971.65]],"batb":[[0,1.53,27.89],[1,1.5,482.46],[2,1.49,228.84]],"batl":[[0,1.64,76]],"ltp":1.64,"tv":36368.07,"id":5300820},{"trd":[[2.56,6.06]],"batb":[[1,2.12,107.53],[2,2.1,7.64]],"ltp":2.56,"tv":14083.21,"id":9629022}],"tv":50451.28}]}
{"op":"mcm","clk":"4215282695","pt":1631537145470,"mc":[{"id":"1.187557985","rc":[{"batl":[[0,1.86,29.75],[1,1.9,228.36],[2,1.92,188.09]],"ltp":1.64,"tv":36368.07,"id":5300820}]}]}
{"op":"mcm","clk":"4215282717","pt":1631537145880,"mc":[{"id":"1.187557985","rc":[{"batl":[[0,1.9,228.4],[1,1.92,188.09],[2,1.97,23.83]],"ltp":1.64,"tv":36368.07,"id":5300820},{"batb":[[0,2.12,107.53],[1,2.1,7.64],[2,2.02,7.24]],"ltp":2.56,"tv":14083.21,"id":9629022}]}]}
{"op":"mcm","clk":"4215282827","pt":1631537148562,"mc":[{"id":"1.187557985","rc":[{"batl":[[0,1.63,76.04],[1,1.9,228.36],[2,1.92,188.09]],"ltp":1.64,"tv":36368.07,"id":5300820}]}]}
{"op":"mcm","clk":"4215282865","pt":1631537149384,"mc":[{"id":"1.187557985","rc":[{"batb":[[1,1.5,159.75],[2,1.46,49.38]],"batl":[[1,1.86,5],[2,1.9,233.36]],"ltp":1.64,"tv":36368.07,"id":5300820},{"batb":[[0,2.12,111.53],[1,2.1,10.64]],"ltp":2.56,"tv":14083.21,"id":9629022}]}]}
{"op":"mcm","clk":"4215282939","pt":1631537150800,"mc":[{"id":"1.187557985","rc":[{"trd":[[1.63,228.73],[1.86,127.84]],"batl":[[0,1.9,228.36],[1,1.92,188.09],[2,1.97,23.83]],"ltp":1.86,"tv":36530.15,"id":5300820},{"batb":[[0,2.12,107.53],[1,2.1,7.64]],"ltp":2.56,"tv":14083.21,"id":9629022}],"tv":50613.37}]}
{"op":"mcm","clk":"4215283018","pt":1631537152496,"mc":[{"id":"1.187557985","rc":[{"batb":[[0,1.84,8.66],[1,1.83,216.69],[2,1.82,4.38]],"batl":[[2,1.93,545.02]],"ltp":1.86,"tv":36530.15,"id":5300820},{"batl":[[0,2.16,9.26],[1,2.28,4.09],[2,3.2,3.33]],"ltp":2.56,"tv":14083.21,"id":9629022}]}]}
{"op":"mcm","clk":"4215283066","pt":1631537153486,"mc":[{"id":"1.187557985","rc":[{"trd":[[1.83,160.81],[1.84,91.43]],"batb":[[0,1.83,207.37],[1,1.82,85.63],[2,1.81,222.99]],"ltp":1.83,"tv":36548.13,"id":5300820},{"trd":[[2.16,421.08],[2.2,146],[2.22,19.91]],"batl":[[0,2.28,4.09],[1,2.32,144.64],[2,2.42,16.65]],"ltp":2.22,"tv":14116.66,"id":9629022}],"tv":50664.8}]}
{"op":"mcm","clk":"4215283112","pt":1631537154167,"mc":[{"id":"1.187557985","rc":[{"batb":[[0,1.83,188.69]],"ltp":1.83,"tv":36548.13,"id":5300820},{"batb":[[2,2.06,4]],"batl":[[1,2.58,4],[2,2.88,3]],"ltp":2.22,"tv":14116.66,"id":9629022}]}]}
{"op":"mcm","clk":"4215283167","pt":1631537155581,"mc":[{"id":"1.187557985","rc":[{"batl":[[0,1.9,203.71]],"ltp":1.83,"tv":36548.13,"id":5300820},{"batb":[[1,2.06,4],[2,2.04,4]],"ltp":2.22,"tv":14116.66,"id":9629022}]}]}
{"op":"mcm","clk":"4215283210","pt":1631537156572,"mc":[{"id":"1.187557985","rc":[{"batb":[[0,1.86,58.9],[1,1.84,139.45],[2,1.83,188.69]],"batl":[[0,1.87,290.05],[1,1.88,78.73],[2,1.9,203.71]],"ltp":1.83,"tv":36548.13,"id":5300820}]}]}
{"op":"mcm","clk":"4215283253","pt":1631537157562,"mc":[{"id":"1.187557985","rc":[{"batb":[[1,1.85,55.6],[2,1.84,26.77]],"batl":[[2,1.89,56.34]],"ltp":1.83,"tv":36548.13,"id":5300820},{"batl":[[0,2.26,20.45],[1,2.28,4.09],[2,2.58,4]],"ltp":2.22,"tv":14116.66,"id":9629022}]}]}
{"op":"mcm","clk":"4215283294","pt":1631537158592,"mc":[{"id":"1.187557985","rc":[{"batb":[[2,1.84,94.16]],"ltp":1.83,"tv":36548.13,"id":5300820},{"batl":[[0,2.22,274.28]],"ltp":2.22,"tv":14116.66,"id":9629022}]}]}
{"op":"mcm","clk":"4215283316","pt":1631537159176,"mc":[{"id":"1.187557985","rc":[{"trd":[[1.85,116.36],[1.86,245.65]],"batb":[[0,1.85,42.87],[1,1.84,94.16],[2,1.83,188.69]],"ltp":1.85,"tv":36691.41,"id":5300820}],"tv":50808.07}]}
{"op":"mcm","clk":"4215283374","pt":1631537160487,"mc":[{"id":"1.187557985","rc":[{"batb":[[0,1.86,163],[1,1.85,42.87],[2,1.84,94.16]],"ltp":1.85,"tv":36691.41,"id":5300820},{"batb":[[1,2.1,27.27],[2,2.06,4]],"batl":[[2,2.3,26.31]],"ltp":2.22,"tv":14116.66,"id":9629022}]}]}
{"op":"mcm","clk":"4215283434","pt":1631537161576,"mc":[{"id":"1.187557985","rc":[{"trd":[[1.87,42.72]],"batb":[[2,1.84,447.37]],"batl":[[0,1.87,286.33]],"ltp":1.87,"tv":36695.13,"id":5300820},{"trd":[[2.14,3.25]],"batl":[[0,2.18,298.13],[1,2.22,274.28],[2,2.28,4.09]],"ltp":2.14,"tv":14119.91,"id":9629022}],"tv":50815.04}]}
{"op":"mcm","clk":"4215283482","pt":1631537162566,"mc":[{"id":"1.187557985","rc":[{"trd":[[1.86,245.83]],"batb":[[0,1.86,162.91],[2,1.84,734.42]],"ltp":1.86,"tv":36695.31,"id":5300820},{"trd":[[2.18,93.66]],"batl":[[0,2.18,265.12],[1,2.2,266.08],[2,2.22,274.28]],"ltp":2.18,"tv":14185.92,"id":9629022}],"tv":50881.23}]}
{"op":"mcm","clk":"4215283528","pt":1631537163498,"mc":[{"id":"1.187557985","rc":[{"batb":[[1,1.84,667.03],[2,1.83,188.69]],"batl":[[0,1.88,438.05],[1,1.89,135.21],[2,1.9,255.36]],"ltp":1.86,"tv":36695.31,"id":5300820}]}]}
{"op":"mcm","clk":"4215283583","pt":1631537164277,"mc":[{"id":"1.187557985","rc":[{"batb":[[1,1.68,106.19],[2,1.63,39.23]],"batl":[[2,1.9,30]],"ltp":1.86,"tv":36695.31,"id":5300820},{"batb":[[0,2.1,27.27],[1,1.91,97.61],[2,1.87,28.27]],"batl":[[0,2.3,26.31],[1,2.6,4.71],[2,2.88,3]],"ltp":2.18,"tv":14185.92,"id":9629022}]}]}
{"op":"mcm","clk":"4215283670","pt":1631537165591,"mc":[{"id":"1.187557985","rc":[{"batb":[[0,1.68,106.27],[1,1.63,39.23],[2,1.62,5]],"batl":[[0,2.02,2.22],[1,2.1,7.05],[2,2.16,8.22]],"ltp":1.86,"tv":36695.31,"id":5300820},{"batb":[[0,1.91,97.61],[1,1.87,28.27],[2,1.82,28.64]],"batl":[[0,2.6,4.71],[1,2.88,3],[2,2.94,4.75]],"ltp":2.18,"tv":14185.92,"id":9629022}]}]}
{"op":"mcm","clk":"4215283717","pt":1631537166610,"mc":[{"id":"1.187557985","rc":[{"batb":[[0,1.69,221.49],[1,1.68,106.19],[2,1.67,293.71]],"batl":[[1,2.12,168.41],[2,2.14,136.23]],"ltp":1.86,"tv":36695.31,"id":5300820},{"batb":[[0,1.91,74.22],[1,1.82,28.64],[2,1.37,4]],"ltp":2.18,"tv":14185.92,"id":9629022}]}]}
{"op":"mcm","clk":"4215283795","pt":1631537168177,"mc":[{"id":"1.187557985","rc":[{"batb":[[0,1.68,106.27],[1,1.62,5],[2,1.53,27.89]],"batl":[[1,2.22,6.75],[2,3.45,2.32]],"ltp":1.86,"tv":36695.31,"id":5300820},{"batl":[[0,2.88,3],[1,2.94,4.75],[2,2.94,0]],"ltp":2.18,"tv":14185.92,"id":9629022}]}]}
{"op":"mcm","clk":"4215283836","pt":1631537168999,"mc":[{"id":"1.187557985","rc":[{"batl":[[0,2.02,6.22],[1,2.1,7.95],[2,2.22,6.75]],"ltp":1.86,"tv":36695.31,"id":5300820},{"batb":[[0,1.98,4],[1,1.97,5],[2,1.91,102.61]],"ltp":2.18,"tv":14185.92,"id":9629022}]}]}
{"op":"mcm","clk":"4215283881","pt":1631537170302,"mc":[{"id":"1.187557985","rc":[{"batl":[[1,2.22,6.75],[2,3.45,2.32]],"ltp":1.86,"tv":36695.31,"id":5300820},{"batb":[[2,1.91,74.22]],"ltp":2.18,"tv":14185.92,"id":9629022}]}]}
{"op":"mcm","clk":"4215283947","pt":1631537171503,"mc":[{"id":"1.187557985","rc":[{"batb":[[0,1.83,188.77],[1,1.81,222.99],[2,1.68,106.19]],"batl":[[0,1.9,225.36],[1,1.92,188.1],[2,2.02,6.22]],"ltp":1.86,"tv":36695.31,"id":5300820},{"batb":[[2,1.93,623.8]],"ltp":2.18,"tv":14185.92,"id":9629022}]}]}
{"op":"mcm","clk":"4215284168","pt":1631537175505,"mc":[{"id":"1.187557985","rc":[{"batb":[[2,1.91,74.22]],"ltp":2.18,"tv":14185.92,"id":9629022}]}]}
{"op":"mcm","clk":"4215284186","pt":1631537175922,"mc":[{"id":"1.187557985","rc":[{"batb":[[0,1.68,106.27],[1,1.62,5],[2,1.53,27.89]],"batl":[[0,2.02,6.22],[1,2.22,6.75],[2,3.45,2.32]],"ltp":1.86,"tv":36695.31,"id":5300820}]}]}
{"op":"mcm","clk":"4215284227","pt":1631537176701,"mc":[{"id":"1.187557985","rc":[{"trd":[[1.87,42.88]],"batb":[[0,1.68,106.19]],"batl":[[0,2.02,6.79]],"ltp":1.87,"tv":36695.47,"id":5300820}],"tv":50881.39}]}
{"op":"mcm","clk":"4215284319","pt":1631537178618,"mc":[{"id":"1.187557985","rc":[{"trd":[[1.76,570.67]],"batb":[[0,1.9,1.43],[1,1.68,106.19],[2,1.62,5]],"batl":[[0,2.02,6.22]],"ltp":1.76,"tv":36696.61,"id":5300820},{"batb":[[0,1.99,604.8],[1,1.98,4],[2,1.97,5]],"ltp":2.18,"tv":14185.92,"id":9629022}],"tv":50882.53}]}
{"op":"mcm","clk":"4215284338","pt":1631537178921,"mc":[{"id":"1.187557985","rc":[{"batb":[[1,1.69,221.41],[2,1.68,106.19]],"batl":[[1,2.12,168.41],[2,2.14,136.23]],"ltp":1.76,"tv":36696.61,"id":5300820},{"batb":[[0,1.98,4],[1,1.97,5],[2,1.91,74.22]],"ltp":2.18,"tv":14185.92,"id":9629022}]}]}
{"op":"mcm","clk":"4215284424","pt":1631537181002,"mc":[{"id":"1.187557985","rc":[{"trd":[[1.9,236.78]],"batb":[[0,1.69,221.41],[1,1.68,106.19],[2,1.67,293.71]],"ltp":1.9,"tv":36699.47,"id":5300820},{"batb":[[1,1.91,74.22],[2,1.82,28.64]],"ltp":2.18,"tv":14185.92,"id":9629022}],"tv":50885.39}]}
{"op":"mcm","clk":"4215284578","pt":1631537184113,"mc":[{"id":"1.187557985","rc":[{"batb":[[1,1.97,5],[2,1.91,74.22]],"ltp":2.18,"tv":14185.92,"id":9629022}]}]}
{"op":"mcm","clk":"4215284881","pt":1631537190610,"mc":[{"id":"1.187557985","rc":[{"batl":[[1,2.22,6.75],[2,3.45,2.32]],"ltp":1.9,"tv":36699.47,"id":5300820}]}]}
{"op":"mcm","clk":"4215285018","pt":1631537193633,"mc":[{"id":"1.187557985","rc":[{"batl":[[0,1.75,252.69],[1,1.77,243.63],[2,1.78,1320.22]],"ltp":1.9,"tv":36699.47,"id":5300820}]}]}
{"op":"mcm","clk":"4215285073","pt":1631537194516,"mc":[{"id":"1.187557985","rc":[{"batb":[[0,1.7,9.38],[1,1.69,221.41],[2,1.68,110.94]],"batl":[[2,1.78,264.04]],"ltp":1.9,"tv":36699.47,"id":5300820},{"trd":[[2.36,135.47]],"batb":[[0,2.36,72.03],[1,2,663.09],[2,1.98,4]],"ltp":2.36,"tv":14202.86,"id":9629022}],"tv":50902.34}]}
{"op":"mcm","clk":"4215285120","pt":1631537195552,"mc":[{"id":"1.187557985","rc":[{"batb":[[0,1.7,38.49]],"ltp":1.9,"tv":36699.47,"id":5300820},{"batb":[[1,2.26,23.8],[2,2.08,20]],"batl":[[0,2.54,24.17],[1,2.7,15],[2,2.88,3]],"ltp":2.36,"tv":14202.86,"id":9629022}]}]}
{"op":"mcm","clk":"4215285172","pt":1631537196631,"mc":[{"id":"1.187557985","rc":[{"batl":[[1,2.88,3],[2,2.94,4.75]],"ltp":2.36,"tv":14202.86,"id":9629022}]}]}
{"op":"mcm","clk":"4215285306","pt":1631537198649,"mc":[{"id":"1.187557985","rc":[{"trd":[[1.73,271.18]],"batb":[[0,1.72,72],[1,1.71,63.25],[2,1.7,38.49]],"batl":[[0,1.73,382.41],[1,1.74,67.31],[2,1.75,331.74]],"ltp":1.73,"tv":36707.54,"id":5300820},{"trd":[[2.36,160.06]],"batb":[[0,2.36,59.73]],"ltp":2.36,"tv":14227.45,"id":9629022}],"tv":50935.0}]}
{"op":"mcm","clk":"4215285358","pt":1631537199639,"mc":[{"id":"1.187557985","rc":[{"batb":[[2,1.7,102.9]],"ltp":1.73,"tv":36707.54,"id":5300820},{"batb":[[1,2.08,20],[2,1.99,4]],"batl":[[0,2.52,43.97]],"ltp":2.36,"tv":14227.45,"id":9629022}]}]}
{"op":"mcm","clk":"4215285410","pt":1631537200616,"mc":[{"id":"1.187557985","rc":[{"batl":[[0,2.46,215.34]],"ltp":2.36,"tv":14227.45,"id":9629022}]}]}
{"op":"mcm","clk":"4215285450","pt":1631537201444,"mc":[{"id":"1.187557985","rc":[{"trd":[[1.72,106.32]],"batb":[[0,1.72,50.3]],"ltp":1.72,"tv":36750.94,"id":5300820}],"tv":50978.4}]}
{"op":"mcm","clk":"4215285497","pt":1631537202433,"mc":[{"id":"1.187557985","rc":[{"trd":[[1.73,322.39]],"batl":[[0,1.73,356.81]],"ltp":1.73,"tv":36802.15,"id":5300820},{"batb":[[1,2.28,23.43],[2,2.08,20]],"ltp":2.36,"tv":14227.45,"id":9629022}],"tv":51029.61}]}
{"op":"mcm","clk":"4215285552","pt":1631537203461,"mc":[{"id":"1.187557985","rc":[{"batl":[[1,2.52,24.33],[2,2.88,3]],"ltp":2.36,"tv":14227.45,"id":9629022}]}]}
{"op":"mcm","clk":"4215285631","pt":1631537204663,"mc":[{"id":"1.187557985","rc":[{"batb":[[0,1.71,63.25],[1,1.7,64.41],[2,1.66,36.92]],"batl":[[0,1.72,77.91],[1,1.73,541.06],[2,1.74,141.24]],"ltp":1.73,"tv":36802.15,"id":5300820},{"batb":[[0,2.28,23.43],[1,1.95,69.62],[2,1.82,28.64]],"batl":[[0,2.52,24.33],[1,2.52,0],[2,2.88,0]],"ltp":2.36,"tv":14227.45,"id":9629022}]}]}
{"op":"mcm","clk":"4215285699","pt":1631537205560,"mc":[{"id":"1.187557985","rc":[{"batb":[[0,1.71,382.45],[1,1.53,27.89],[2,1.51,156.23]],"batl":[[1,1.73,286.12],[2,1.74,67.31]],"ltp":1.73,"tv":36802.15,"id":5300820},{"batb":[[0,1.95,69.62],[1,1.82,28.64],[2,1.37,4]],"batl":[[0,2.42,270.24]],"ltp":2.36,"tv":14227.45,"id":9629022}]}]}
{"op":"mcm","clk":"4215285769","pt":1631537206548,"mc":[{"id":"1.187557985","rc":[{"trd":[[1.72,262.13]],"batb":[[0,1.53,27.89],[1,1.51,156.23],[2,1.41,8]],"batl":[[0,1.7,2.32],[1,1.74,67.31],[2,2.02,2.22]],"ltp":1.72,"tv":36957.97,"id":5300820},{"batl":[[0,2.44,43.97]],"ltp":2.36,"tv":14227.45,"id":9629022}],"tv":51185.42}]}
{"op":"mcm","clk":"4215285839","pt":1631537207538,"mc":[{"id":"1.187557985","rc":[{"trd":[[1.7,1286.27]],"batl":[[0,1.7,1.39],[1,2.02,2.22],[2,2.1,368.32]],"ltp":1.7,"tv":36959.83,"id":5300820}],"tv":51187.28}]}
{"op":"mcm","clk":"4215285858","pt":1631537207850,"mc":[{"id":"1.187557985","rc":[{"batb":[[0,1.53,28.82]],"batl":[[0,2.02,2.22],[1,2.1,368.32],[2,2.22,6.75]],"ltp":1.7,"tv":36959.83,"id":5300820}]}]}
{"op":"mcm","clk":"4215285919","pt":1631537208940,"mc":[{"id":"1.187557985","rc":[{"trd":[[1.73,324.25]],"batb":[[0,1.53,27.89]],"ltp":1.73,"tv":36961.69,"id":5300820}],"tv":51189.14}]}
{"op":"mcm","clk":"4215286017","pt":1631537210663,"mc":[{"id":"1.187557985","rc":[{"batb":[[0,1.74,257.56],[1,1.72,264.99],[2,1.53,27.89]],"batl":[[0,1.8,154.83],[1,1.82,222.76],[2,2.02,2.22]],"ltp":1.73,"tv":36961.69,"id":5300820}]}]}
{"op":"mcm","clk":"4215286028","pt":1631537210865,"mc":[{"id":"1.187557985","rc":[{"batb":[[0,1.77,136.29],[1,1.74,257.56],[2,1.72,264.99]],"ltp":1.73,"tv":36961.69,"id":5300820}]}]}
{"op":"mcm","clk":"4215286083","pt":1631537211753,"mc":[{"id":"1.187557985","rc":[{"batl":[[2,1.99,11.1]],"ltp":1.73,"tv":36961.69,"id":5300820},{"batb":[[0,2,118.37],[1,1.95,69.62],[2,1.82,28.64]],"batl":[[0,2.58,5]],"ltp":2.36,"tv":14227.45,"id":9629022}]}]}
{"op":"mcm","clk":"4215286257","pt":1631537214967,"mc":[{"id":"1.187557985","rc":[{"batb":[[0,1.77,11.33]],"ltp":1.73,"tv":36961.69,"id":5300820}]}]}
{"op":"mcm","clk":"4215286412","pt":1631537217568,"mc":[{"id":"1.187557985","rc":[{"batb":[[1,1.63,137.6],[2,1.53,27.89]],"batl":[[0,1.99,11.1],[1,2.02,2.22],[2,2.1,368.32]],"ltp":1.73,"tv":36961.69,"id":5300820}]}]}
{"op":"mcm","clk":"4215286475","pt":1631537218566,"mc":[{"id":"1.187557985","rc":[{"trd":[[1.77,22.66]],"batb":[[0,1.63,137.6],[1,1.53,27.89],[2,1.51,156.23]],"batl":[[0,2.02,2.22],[1,2.1,368.32],[2,2.22,6.75]],"ltp":1.77,"tv":36984.34,"id":5300820}],"tv":51211.8}]}
{"op":"mcm","clk":"4215286517","pt":1631537219127,"mc":[{"id":"1.187557985","rc":[{"batb":[[0,1.53,27.89],[1,1.51,156.23],[2,1.44,442.2]],"ltp":1.77,"tv":36984.34,"id":5300820},{"batb":[[0,1.95,69.62],[1,1.82,28.64],[2,1.37,4]],"ltp":2.36,"tv":14227.45,"id":9629022}]}]}
{"op":"mcm","clk":"4215286619","pt":1631537220549,"mc":[{"id":"1.187557985","rc":[{"batb":[[1,1.51,378.25],[2,1.5,222.17]],"batl":[[1,2.08,177.03],[2,2.1,512.19]],"ltp":1.77,"tv":36984.34,"id":5300820}]}]}
{"op":"mcm","clk":"4215286688","pt":1631537221701,"mc":[{"id":"1.187557985","rc":[{"batb":[[0,1.73,36.8],[1,1.53,27.89],[2,1.51,378.25]],"ltp":1.77,"tv":36984.34,"id":5300820}]}]}
{"op":"mcm","clk":"4215287066","pt":1631537227657,"mc":[{"id":"1.187557985","rc":[{"batb":[[2,1.51,156.23]],"batl":[[1,2.1,368.32],[2,2.22,6.75]],"ltp":1.77,"tv":36984.34,"id":5300820}]}]}
{"op":"mcm","clk":"4215287185","pt":1631537229563,"mc":[{"id":"1.187557985","rc":[{"batl":[[1,3.45,2.32],[2,2.22,0]],"ltp":1.77,"tv":36984.34,"id":5300820},{"batb":[[1,1.37,4],[2,1.3,10]],"ltp":2.36,"tv":14227.45,"id":9629022}]}]}
{"op":"mcm","clk":"4215287246","pt":1631537230659,"mc":[{"id":"1.187557985","rc":[{"trd":[[2,48.61],[2.02,13.06]],"batb":[[0,1.99,961.06],[1,1.98,932.8],[2,1.97,932.8]],"batl":[[0,3.45,2.32],[1,3.45,0]],"ltp":2.02,"tv":36986.57,"id":5300820},{"trd":[[1.95,23.58],[1.98,13.32],[2,37.83]],"batb":[[0,1.95,61.57],[1,1.93,153.37],[2,1.91,187.41]],"batl":[[0,1.97,8.1],[1,1.99,4.01],[2,2,168.1]],"ltp":1.95,"tv":14245.81,"id":9629022}],"tv":51232.39}]}
{"op":"mcm","clk":"4215287320","pt":1631537231597,"mc":[{"id":"1.187557985","rc":[{"trd":[[2.02,17.06]],"batb":[[1,1.98,1058.32]],"batl":[[0,2.26,8.85],[1,3.45,2.32]],"ltp":2.02,"tv":36990.57,"id":5300820},{"trd":[[1.97,12.1]],"batb":[[0,1.97,30.46],[1,1.95,61.57],[2,1.93,153.37]],"batl":[[0,1.99,4.01],[1,2,168.1],[2,2.02,161.04]],"ltp":1.97,"tv":14257.91,"id":9629022}],"tv":51248.48}]}
{"op":"mcm","clk":"4215287380","pt":1631537232491,"mc":[{"id":"1.187557985","rc":[{"batb":[[0,1.95,61.57],[1,1.93,153.37],[2,1.91,187.41]],"ltp":1.97,"tv":14257.91,"id":9629022}]}]}
{"op":"mcm","clk":"4215287464","pt":1631537233480,"mc":[{"id":"1.187557985","rc":[{"trd":[[2,52.86]],"batb":[[1,1.98,1063.32],[2,1.97,936.8]],"batl":[[1,2.5,278.33],[2,3.45,2.32]],"ltp":2.0,"tv":36994.82,"id":5300820},{"trd":[[1.99,4.01],[2,38.09]],"batl":[[0,2,167.84],[1,2.02,161.04],[2,2.36,2]],"ltp":2.0,"tv":14262.18,"id":9629022}],"tv":51257.0}]}
{"op":"mcm","clk":"4215287563","pt":1631537234581,"mc":[{"id":"1.187557985","rc":[{"batl":[[0,2.04,56.75],[1,2.26,8.85],[2,2.5,278.33]],"ltp":2.0,"tv":36994.82,"id":5300820},{"batb":[[0,1.97,335.51],[1,1.95,61.57],[2,1.93,153.37]],"batl":[[0,1.98,56.48],[1,2,167.84],[2,2.02,161.04]],"ltp":2.0,"tv":14262.18,"id":9629022}]}]}
{"op":"mcm","clk":"4215287675","pt":1631537235665,"mc":[{"id":"1.187557985","rc":[{"batb":[[0,2,33.33],[1,1.99,961.06],[2,1.98,1119.12]],"batl":[[1,2.24,273.38],[2,2.26,8.85]],"ltp":2.0,"tv":36994.82,"id":5300820},{"trd":[[1.97,21.28]],"batb":[[0,1.97,361.38]],"batl":[[1,1.99,20.05],[2,2,167.84]],"ltp":1.97,"tv":14271.36,"id":9629022}],"tv":51266.18}]}
{"op":"mcm","clk":"4215287757","pt":1631537236657,"mc":[{"id":"1.187557985","rc":[{"trd":[[2.02,46.76]],"batb":[[2,1.98,1118.87]],"batl":[[1,2.24,44.25]],"ltp":2.02,"tv":37024.52,"id":5300820},{"trd":[[1.98,75.43]],"batb":[[0,1.97,330.92]],"batl":[[0,1.98,10.27]],"ltp":1.98,"tv":14333.47,"id":9629022}],"tv":51357.99}]}
{"op":"mcm","clk":"4215287824","pt":1631537237491,"mc":[{"id":"1.187557985","rc":[{"batb":[[0,2,334.01]],"ltp":2.02,"tv":37024.52,"id":5300820},{"trd":[[1.98,95.97],[1.99,26.86]],"batl":[[0,1.99,8.62],[1,2,468.52],[2,2.02,161.04]],"ltp":1.99,"tv":14376.87,"id":9629022}],"tv":51401.39}]}
{"op":"mcm","clk":"4215287960","pt":1631537239598,"mc":[{"id":"1.187557985","rc":[{"batb":[[2,1.98,1063.07]],"batl":[[0,2.06,297.27],[1,2.08,28.86],[2,2.24,44.25]],"ltp":2.02,"tv":37024.52,"id":5300820},{"batb":[[0,1.98,268.48],[1,1.97,140.81],[2,1.95,61.57]],"batl":[[0,1.99,74.64]],"ltp":1.99,"tv":14376.87,"id":9629022}]}]}
{"op":"mcm","clk":"4215287993","pt":1631537240073,"mc":[{"id":"1.187557985","rc":[{"trd":[[2,62.86]],"batb":[[0,2,329.01]],"batl":[[0,2.04,264.05],[1,2.06,297.27],[2,2.08,28.86]],"ltp":2.0,"tv":37034.52,"id":5300820},{"trd":[[1.98,524.01]],"batb":[[0,1.98,54.45],[2,1.96,274.83]],"ltp":1.98,"tv":14804.91,"id":9629022}],"tv":51839.43}]}
{"op":"mcm","clk":"4215288112","pt":1631537242006,"mc":[{"id":"1.187557985","rc":[{"trd":[[2.04,139.11]],"batl":[[0,2.04,227.24]],"ltp":2.04,"tv":37108.13,"id":5300820},{"batb":[[0,1.98,229.91]],"ltp":1.98,"tv":14804.91,"id":9629022}],"tv":51913.04}]}
{"op":"mcm","clk":"4215288155","pt":1631537242680,"mc":[{"id":"1.187557985","rc":[{"batl":[[0,2.02,1.84],[1,2.04,227.24],[2,2.06,297.27]],"ltp":2.04,"tv":37108.13,"id":5300820}]}]}
{"op":"mcm","clk":"4215288310","pt":1631537245475,"mc":[{"id":"1.187557985","rc":[{"batb":[[2,1.98,1058.07]],"ltp":2.04,"tv":37108.13,"id":5300820},{"trd":[[1.98,524.24],[1.99,48.57]],"batb":[[0,1.98,175.35],[1,1.96,274.83],[2,1.95,61.57]],"batl":[[0,1.99,224]],"ltp":1.98,"tv":14826.84,"id":9629022}],"tv":51934.97}]}
{"op":"mcm","clk":"4215288466","pt":1631537247595,"mc":[{"id":"1.187557985","rc":[{"trd":[[1.98,527.96]],"batb":[[0,1.98,203.49]],"ltp":1.98,"tv":14830.56,"id":9629022}],"tv":51938.69}]}
{"op":"mcm","clk":"4215288516","pt":1631537248382,"mc":[{"id":"1.187557985","rc":[{"batb":[[0,1.98,30]],"ltp":1.98,"tv":14830.56,"id":9629022}]}]}
{"op":"mcm","clk":"4215288716","pt":1631537251489,"mc":[{"id":"1.187557985","rc":[{"batb":[[0,2,480.01]],"ltp":2.04,"tv":37108.13,"id":5300820},{"trd":[[1.99,395.52]],"batl":[[0,1.99,50.54]],"ltp":1.99,"tv":15177.51,"id":9629022}],"tv":52285.64}]}
{"op":"mcm","clk":"4215288759","pt":1631537252322,"mc":[{"id":"1.187557985","rc":[{"trd":[[2.02,50.44],[2.04,139.35]],"batl":[[0,2.04,227.12],[1,2.06,297.27],[2,2.08,28.86]],"ltp":2.04,"tv":37112.05,"id":5300820},{"trd":[[1.98,532.06]],"batb":[[0,1.98,27.95]],"ltp":1.98,"tv":15181.61,"id":9629022}],"tv":52293.67}]}
{"op":"mcm","clk":"4215288783","pt":1631537252686,"mc":[{"id":"1.187557985","rc":[{"batb":[[0,2,329.01]],"ltp":2.04,"tv":37112.05,"id":5300820}]}]}
{"op":"mcm","clk":"4215288887","pt":1631537254614,"mc":[{"id":"1.187557985","rc":[{"trd":[[1.99,395.91]],"batl":[[0,1.99,50.34]],"ltp":1.99,"tv":15182.01,"id":9629022}],"tv":52294.06}]}
{"op":"mcm","clk":"4215289010","pt":1631537256598,"mc":[{"id":"1.187557985","rc":[{"trd":[[2,150.12]],"batb":[[0,2,278.85]],"ltp":2.0,"tv":37199.3,"id":5300820},{"trd":[[1.99,496.57],[2,987.87]],"batl":[[0,2.02,161.04],[1,2.36,2],[2,2.02,0]],"ltp":2.0,"tv":16232.44,"id":9629022}],"tv":53431.75}]}
{"op":"mcm","clk":"4215289029","pt":1631537257009,"mc":[{"id":"1.187557985","rc":[{"batl":[[0,1.99,173.46],[1,2.02,161.04],[2,2.36,2]],"ltp":2.0,"tv":16232.44,"id":9629022}]}]}
{"op":"mcm","clk":"4215289166","pt":1631537259415,"mc":[{"id":"1.187557985","rc":[{"trd":[[2,160.19]],"batb":[[0,2,273.82]],"ltp":2.0,"tv":37209.37,"id":5300820},{"trd":[[1.98,545.78],[1.99,500.29]],"batb":[[0,1.98,21.09]],"batl":[[0,1.99,171.6]],"ltp":1.99,"tv":16249.88,"id":9629022}],"tv":53459.26}]}
{"op":"mcm","clk":"4215289217","pt":1631537260297,"mc":[{"id":"1.187557985","rc":[{"batl":[[1,2.02,248.94],[2,2.04,156.36]],"ltp":1.99,"tv":16249.88,"id":9629022}]}]}
{"op":"mcm","clk":"4215289314","pt":1631537262034,"mc":[{"id":"1.187557985","rc":[{"trd":[[1.99,510.05]],"batl":[[0,1.99,166.72]],"ltp":1.99,"tv":16259.64,"id":9629022}],"tv":53469.02}]}
{"op":"mcm","clk":"4215289411","pt":1631537263511,"mc":[{"id":"1.187557985","rc":[{"trd":[[2,210.2]],"batb":[[0,2,248.81]],"ltp":2.0,"tv":37259.38,"id":5300820}],"tv":53519.03}]}
{"op":"mcm","clk":"4215289471","pt":1631537264807,"mc":[{"id":"1.187557985","rc":[{"trd":[[1.98,547.06]],"batb":[[0,1.98,20.45]],"batl":[[1,2.02,216.25]],"ltp":1.98,"tv":16260.92,"id":9629022}],"tv":53520.31}]}
{"op":"mcm","clk":"4215289570","pt":1631537267238,"mc":[{"id":"1.187557985","rc":[{"trd":[[1.99,510.11]],"batl":[[0,1.99,166.69]],"ltp":1.99,"tv":16260.98,"id":9629022}],"tv":53520.37}]}
{"op":"mcm","clk":"4215289628","pt":1631537268125,"mc":[{"id":"1.187557985","rc":[{"trd":[[1.98,587.96]],"batb":[[0,1.96,274.83],[1,1.95,61.57],[2,1.94,315.66]],"batl":[[1,2.08,28.86],[2,2.36,2]],"ltp":1.98,"tv":16301.88,"id":9629022}],"tv":53561.27}]}
{"op":"mcm","clk":"4215289771","pt":1631537270650,"mc":[{"id":"1.187557985","rc":[{"batl":[[0,2.06,297.27],[1,2.08,28.86],[2,2.24,44.25]],"ltp":2.0,"tv":37259.38,"id":5300820},{"batl":[[2,2.26,124.26]],"ltp":1.98,"tv":16301.88,"id":9629022}]}]}
{"op":"mcm","clk":"4215289819","pt":1631537271401,"mc":[{"id":"1.187557985","rc":[{"batb":[[0,1.95,61.57],[1,1.94,315.66],[2,1.92,31.27]],"ltp":1.98,"tv":16301.88,"id":9629022}]}]}
{"op":"mcm","clk":"4215289835","pt":1631537271712,"mc":[{"id":"1.187557985","rc":[{"batl":[[0,2.08,28.86],[1,2.26,124.26],[2,2.28,114.41]],"ltp":1.98,"tv":16301.88,"id":9629022}]}]}
{"op":"mcm","clk":"4215290053","pt":1631537275227,"mc":[{"id":"1.187557985","rc":[{"batb":[[0,1.99,961.06],[1,1.98,1058.07],[2,1.97,936.8]],"ltp":2.0,"tv":37259.38,"id":5300820},{"batb":[[0,1.99,212.95],[1,1.95,61.57],[2,1.94,315.66]],"batl":[[0,2.06,51.01],[1,2.08,28.86],[2,2.26,124.26]],"ltp":1.98,"tv":16301.88,"id":9629022}]}]}
{"op":"mcm","clk":"4215290222","pt":1631537278414,"mc":[{"id":"1.187557985","rc":[{"batb":[[0,1.99,989.63],[1,1.98,932.8]],"ltp":2.0,"tv":37259.38,"id":5300820},{"batb":[[1,1.94,315.66],[2,1.92,31.27]],"ltp":1.98,"tv":16301.88,"id":9629022}]}]}
{"op":"mcm","clk":"4215290331","pt":1631537280927,"mc":[{"id":"1.187557985","rc":[{"batb":[[0,1.99,1198.63]],"ltp":2.0,"tv":37259.38,"id":5300820}]}]}
{"op":"mcm","clk":"4215290518","pt":1631537283636,"mc":[{"id":"1.187557985","rc":[{"trd":[[1.99,517.24]],"batb":[[0,1.99,209.38]],"ltp":1.99,"tv":16309.02,"id":9629022}],"tv":53568.41}]}
{"op":"mcm","clk":"4215290654","pt":1631537286049,"mc":[{"id":"1.187557985","rc":[{"trd":[[1.99,523.85]],"batb":[[0,1.99,206.08]],"ltp":1.99,"tv":16315.62,"id":9629022}],"tv":53575.01}]}
{"op":"mcm","clk":"4215290966","pt":1631537291632,"mc":[{"id":"1.187557985","rc":[{"batb":[[0,1.99,989.63]],"batl":[[2,2.2,6.73]],"ltp":2.0,"tv":37259.38,"id":5300820},{"batb":[[0,1.94,315.66],[1,1.92,31.27],[2,1.88,1017.3]],"ltp":1.99,"tv":16315.62,"id":9629022}]}]}
{"op":"mcm","clk":"4215291100","pt":1631537294530,"mc":[{"id":"1.187557985","rc":[{"trd":[[1.99,264.93]],"batb":[[0,1.99,780.48]],"ltp":1.99,"tv":37468.53,"id":5300820},{"trd":[[2.02,214.49]],"ltp":2.02,"tv":16521.71,"id":9629022}],"tv":53990.24}]}
{"op":"mcm","clk":"4215291196","pt":1631537296664,"mc":[{"id":"1.187557985","rc":[{"batb":[[0,1.99,28.57],[1,1.97,4],[2,1.96,4]],"ltp":1.99,"tv":37468.53,"id":5300820},{"batb":[[2,1.84,31.22]],"ltp":2.02,"tv":16521.71,"id":9629022}]}]}
{"op":"mcm","clk":"4215291242","pt":1631537297439,"mc":[{"id":"1.187557985","rc":[{"batb":[[0,1.93,31.1],[1,1.8,85.02],[2,1.72,33.09]],"batl":[[0,2.08,28.86],[1,2.32,6.11],[2,2.5,278.33]],"ltp":1.99,"tv":37468.53,"id":5300820},{"batb":[[0,1.95,98.08],[2,1.83,34.03]],"batl":[[0,2.08,28.86],[1,2.26,124.26],[2,2.28,114.41]],"ltp":2.02,"tv":16521.71,"id":9629022}]}]}
{"op":"mcm","clk":"4215291319","pt":1631537298640,"mc":[{"id":"1.187557985","rc":[{"batb":[[0,1.8,85.02],[1,1.72,33.09],[2,1.63,42.23]],"batl":[[0,2.32,6.11],[1,2.5,278.33],[2,3.45,2.32]],"ltp":1.99,"tv":37468.53,"id":5300820},{"batb":[[0,1.78,93.3],[1,1.76,291.06],[2,1.74,253]],"batl":[[0,2.26,124.26],[1,2.28,114.41],[2,2.36,2]],"ltp":2.02,"tv":16521.71,"id":9629022}]}]}
{"op":"mcm","clk":"4215291404","pt":1631537300655,"mc":[{"id":"1.187557985","rc":[{"batb":[[0,1.82,34.14],[1,1.78,93.3],[2,1.76,291.06]],"ltp":2.02,"tv":16521.71,"id":9629022}]}]}
{"op":"mcm","clk":"4215291421","pt":1631537300973,"mc":[{"id":"1.187557985","rc":[{"batb":[[0,1.78,93.3],[1,1.76,291.06],[2,1.74,253]],"ltp":2.02,"tv":16521.71,"id":9629022}]}]}
{"op":"mcm","clk":"4215291498","pt":1631537302061,"mc":[{"id":"1.187557985","rc":[{"batb":[[1,1.63,42.23],[2,1.58,422.21]],"batl":[[0,2.3,3],[1,2.32,6.11],[2,2.5,278.33]],"ltp":1.99,"tv":37468.53,"id":5300820},{"batb":[[0,1.81,5],[1,1.8,4],[2,1.78,97.3]],"batl":[[0,2.36,2],[1,2.28,0],[2,2.36,0]],"ltp":2.02,"tv":16521.71,"id":9629022}]}]}
{"op":"mcm","clk":"4215291574","pt":1631537303566,"mc":[{"id":"1.187557985","rc":[{"batb":[[2,1.53,27.89]],"batl":[[0,2.22,7.25],[1,2.3,3],[2,2.32,6.11]],"ltp":1.99,"tv":37468.53,"id":5300820},{"batl":[[0,1.86,3247.56],[1,2.36,2]],"ltp":2.02,"tv":16521.71,"id":9629022}]}]}
{"op":"mcm","clk":"4215291644","pt":1631537304658,"mc":[{"id":"1.187557985","rc":[{"batb":[[0,2.14,2196.26],[1,2.06,4.58],[2,1.8,85.02]],"batl":[[0,2.32,6.11],[1,2.5,278.33],[2,3.45,2.32]],"ltp":1.99,"tv":37468.53,"id":5300820},{"trd":[[1.82,27.61]],"batb":[[0,1.78,93.3],[1,1.76,291.06],[2,1.74,253]],"batl":[[0,1.83,236.58],[1,1.84,8.66],[2,1.85,209.51]],"ltp":1.82,"tv":16543.93,"id":9629022}],"tv":54012.46}]}
{"op":"mcm","clk":"4215291710","pt":1631537305552,"mc":[{"id":"1.187557985","rc":[{"batb":[[0,2.18,92.63],[1,2.14,1317.76],[2,2.06,4.58]],"batl":[[0,2.3,1021.74],[1,2.32,516.99],[2,2.34,510.88]],"ltp":1.99,"tv":37468.53,"id":5300820}]}]}
{"op":"mcm","clk":"4215291786","pt":1631537306639,"mc":[{"id":"1.187557985","rc":[{"batb":[[0,2.18,96.63],[1,2.16,3],[2,2.14,1317.76]],"batl":[[0,2.3,154.02],[1,2.32,69.97],[2,2.34,63.86]],"ltp":1.99,"tv":37468.53,"id":5300820},{"batb":[[1,1.77,34.18],[2,1.76,291.06]],"batl":[[2,1.85,214.51]],"ltp":1.82,"tv":16543.93,"id":9629022}]}]}
{"op":"mcm","clk":"4215291969","pt":1631537309647,"mc":[{"id":"1.187557985","rc":[{"trd":[[2.26,1.69]],"batb":[[0,2.2,29.98],[1,2.18,96.63],[2,2.16,3]],"ltp":2.26,"tv":37470.22,"id":5300820},{"trd":[[1.8,27.37]],"batb":[[0,1.8,178.36],[1,1.78,93.3],[2,1.77,34.18]],"batl":[[0,1.81,66.2],[1,1.82,97.41],[2,1.83,236.58]],"ltp":1.8,"tv":16559.74,"id":9629022}],"tv":54029.96}]}
{"op":"mcm","clk":"4215292028","pt":1631537310478,"mc":[{"id":"1.187557985","rc":[{"batb":[[0,2.2,287.66]],"ltp":2.26,"tv":37470.22,"id":5300820},{"batb":[[1,1.79,68.76],[2,1.78,93.3]],"batl":[[2,1.83,582.41]],"ltp":1.8,"tv":16559.74,"id":9629022}]}]}
{"op":"mcm","clk":"4215292084","pt":1631537311375,"mc":[{"id":"1.187557985","rc":[{"batl":[[0,2.3,420.81]],"ltp":2.26,"tv":37470.22,"id":5300820}]}]}
{"op":"mcm","clk":"4215292209","pt":1631537313546,"mc":[{"id":"1.187557985","rc":[{"batb":[[0,2.22,29.98],[1,2.2,287.66],[2,2.18,96.63]],"ltp":2.26,"tv":37470.22,"id":5300820},{"batb":[[1,1.79,148.02]],"batl":[[0,1.81,143.09]],"ltp":1.8,"tv":16559.74,"id":9629022}]}]}
{"op":"mcm","clk":"4215292259","pt":1631537314591,"mc":[{"id":"1.187557985","rc":[{"batb":[[0,2.18,92.63],[1,2.12,26.78],[2,1.98,125.69]],"batl":[[0,2.3,26.31],[1,2.46,6.75],[2,2.48,4.99]],"ltp":2.26,"tv":37470.22,"id":5300820},{"batb":[[1,1.79,68.76]],"batl":[[0,1.81,66.2],[1,1.84,8.66],[2,1.86,4.28]],"ltp":1.8,"tv":16559.74,"id":9629022}]}]}
{"op":"mcm","clk":"4215292305","pt":1631537315373,"mc":[{"id":"1.187557985","rc":[{"batb":[[0,1.98,125.69],[1,1.93,29.93],[2,1.82,27.64]],"batl":[[0,2.46,6.75],[1,2.48,4.99],[2,2.5,278.33]],"ltp":2.26,"tv":37470.22,"id":5300820},{"batb":[[2,1.69,33.21]],"batl":[[1,2.08,7.69],[2,2.22,7.75]],"ltp":1.8,"tv":16559.74,"id":9629022}]}]}
{"op":"mcm","clk":"4215292388","pt":1631537317240,"mc":[{"id":"1.187557985","rc":[{"batl":[[1,2.02,128.41],[2,2.04,156.43]],"ltp":1.8,"tv":16559.74,"id":9629022}]}]}
{"op":"mcm","clk":"4215292468","pt":1631537318586,"mc":[{"id":"1.187557985","rc":[{"batl":[[0,2.48,4.99],[1,2.5,278.33],[2,2.6,5.61]],"ltp":2.26,"tv":37470.22,"id":5300820},{"batb":[[2,1.68,35.86]],"batl":[[1,2.08,7.69],[2,2.22,7.75]],"ltp":1.8,"tv":16559.74,"id":9629022}]}]}
{"op":"mcm","clk":"4215292494","pt":1631537319153,"mc":[{"id":"1.187557985","rc":[{"batl":[[0,2.5,278.33],[1,2.6,5.61],[2,2.62,5.75]],"ltp":2.26,"tv":37470.22,"id":5300820},{"trd":[[1.81,0.19]],"batb":[[0,1.64,121.5],[1,1.63,38.23],[2,1.62,346.39]],"batl":[[0,1.81,66.11]],"ltp":1.81,"tv":16559.92,"id":9629022}],"tv":54030.15}]}
{"op":"mcm","clk":"4215292666","pt":1631537321651,"mc":[{"id":"1.187557985","rc":[{"batb":[[0,2,802.26],[1,1.98,125.69],[2,1.93,29.93]],"batl":[[0,2.6,5.61],[1,2.62,5.75],[2,3.45,2.32]],"ltp":2.26,"tv":37470.22,"id":5300820},{"batl":[[0,1.68,1406.03],[1,1.69,1116.73],[2,1.7,1379.87]],"ltp":1.81,"tv":16559.92,"id":9629022}]}]}
{"op":"mcm","clk":"4215292726","pt":1631537322589,"mc":[{"id":"1.187557985","rc":[{"batb":[[0,2.44,69.12],[1,2.2,90.88]],"batl":[[2,2.74,7.3]],"ltp":2.26,"tv":37470.22,"id":5300820},{"trd":[[1.68,303.28]],"batl":[[0,1.68,1401.99]],"ltp":1.68,"tv":16568.0,"id":9629022}],"tv":54038.23}]}
{"op":"mcm","clk":"4215292798","pt":1631537323577,"mc":[{"id":"1.187557985","rc":[{"batb":[[1,2.38,3],[2,2.36,3]],"batl":[[0,2.6,29.32]],"ltp":2.26,"tv":37470.22,"id":5300820},{"batb":[[1,1.63,76.02]],"ltp":1.68,"tv":16568.0,"id":9629022}]}]}
{"op":"mcm","clk":"4215292871","pt":1631537324557,"mc":[{"id":"1.187557985","rc":[{"trd":[[1.68,303.41]],"batl":[[0,1.68,1401.92]],"ltp":1.68,"tv":16568.14,"id":9629022}],"tv":54038.36}]}
{"op":"mcm","clk":"4215292998","pt":1631537326596,"mc":[{"id":"1.187557985","rc":[{"trd":[[2.52,1.64]],"batb":[[0,2.46,255.75],[1,2.44,69.12],[2,2.38,3]],"ltp":2.52,"tv":37471.74,"id":5300820},{"trd":[[1.66,50.15]],"batb":[[0,1.66,99.13],[1,1.65,78.13],[2,1.64,121.5]],"batl":[[0,1.67,58.35],[1,1.68,1917.05],[2,1.69,1116.73]],"ltp":1.66,"tv":16618.28,"id":9629022}],"tv":54090.02}]}
{"op":"mcm","clk":"4215293039","pt":1631537327372,"mc":[{"id":"1.187557985","rc":[{"batb":[[0,2.46,226.87]],"ltp":2.52,"tv":37471.74,"id":5300820},{"trd":[[1.67,37.29]],"batb":[[2,1.64,183.71]],"batl":[[0,1.67,52.39]],"ltp":1.67,"tv":16630.21,"id":9629022}],"tv":54101.95}]}
{"op":"mcm","clk":"4215293096","pt":1631537328570,"mc":[{"id":"1.187557985","rc":[{"batl":[[2,2.74,12.55]],"ltp":2.52,"tv":37471.74,"id":5300820}]}]}
{"op":"mcm","clk":"4215293158","pt":1631537329565,"mc":[{"id":"1.187557985","rc":[{"batb":[[1,2.44,73.12],[2,2.42,4]],"batl":[[2,2.7,4.45]],"ltp":2.52,"tv":37471.74,"id":5300820}]}]}
{"op":"mcm","clk":"4215293215","pt":1631537330604,"mc":[{"id":"1.187557985","rc":[{"batb":[[0,2.48,28.88],[1,2.46,226.87],[2,2.44,73.12]],"ltp":2.52,"tv":37471.74,"id":5300820},{"batb":[[1,1.65,135.43]],"batl":[[0,1.67,115.17]],"ltp":1.67,"tv":16630.21,"id":9629022}]}]}
{"op":"mcm","clk":"4215293228","pt":1631537330764,"mc":[{"id":"1.187557985","rc":[{"batb":[[1,1.65,78.13],[2,1.64,121.5]],"batl":[[0,1.67,52.39],[1,1.68,1858.72]],"ltp":1.67,"tv":16630.21,"id":9629022}]}]}
{"op":"mcm","clk":"4215293330","pt":1631537332481,"mc":[{"id":"1.187557985","rc":[{"batb":[[0,2.36,22.05],[1,2.2,90.88],[2,2.18,7.47]],"batl":[[0,2.6,23.71],[1,2.82,4.86],[2,2.86,5.25]],"ltp":2.52,"tv":37471.74,"id":5300820},{"batb":[[2,1.63,37.79]],"batl":[[1,1.73,30],[2,1.8,12.38]],"ltp":1.67,"tv":16630.21,"id":9629022}]}]}
{"op":"mcm","clk":"4215293377","pt":1631537333366,"mc":[{"id":"1.187557985","rc":[{"batb":[[0,2.2,90.88],[1,2.18,7.47],[2,2.08,7.56]],"batl":[[0,2.82,4.86],[1,2.86,5.25],[2,3,216.4]],"ltp":2.52,"tv":37471.74,"id":5300820},{"trd":[[1.67,47.32]],"batb":[[2,1.55,47.19]],"batl":[[0,1.67,47.37],[1,1.8,12.38],[2,1.84,29.78]],"ltp":1.67,"tv":16640.24,"id":9629022}],"tv":54111.98}]}
{"op":"mcm","clk":"4215293437","pt":1631537334558,"mc":[{"id":"1.187557985","rc":[{"trd":[[1.66,50.89]],"batb":[[0,1.66,98.76]],"ltp":1.66,"tv":16640.99,"id":9629022}],"tv":54112.73}]}
{"op":"mcm","clk":"4215293486","pt":1631537335601,"mc":[{"id":"1.187557985","rc":[{"trd":[[1.66,185.9]],"batb":[[0,1.66,31.25]],"batl":[[1,1.8,6.38],[2,1.81,185.99]],"ltp":1.66,"tv":16775.99,"id":9629022}],"tv":54247.74}]}
{"op":"mcm","clk":"4215293568","pt":1631537337039,"mc":[{"id":"1.187557985","rc":[{"batl":[[1,3,216.4],[2,3.45,2.32]],"ltp":2.52,"tv":37471.74,"id":5300820},{"batb":[[0,1.55,47.19],[1,1.54,151.88],[2,1.53,229.03]],"batl":[[0,1.8,6.38],[1,1.81,185.99],[2,1.83,216.92]],"ltp":1.66,"tv":16775.99,"id":9629022}]}]}
{"op":"mcm","clk":"4215293649","pt":1631537338612,"mc":[{"id":"1.187557985","rc":[{"batl":[[0,1.66,2.32],[1,1.8,5],[2,1.81,185.99]],"ltp":1.66,"tv":16775.99,"id":9629022}]}]}
{"op":"mcm","clk":"4215293703","pt":1631537339504,"mc":[{"id":"1.187557985","rc":[{"batb":[[1,2.08,7.56],[2,1.81,5]],"ltp":2.52,"tv":37471.74,"id":5300820},{"trd":[[1.66,185.92]],"batl":[[0,1.66,2.59],[2,2.24,3]],"ltp":1.66,"tv":16776.02,"id":9629022}],"tv":54247.76}]}
{"op":"mcm","clk":"4215293782","pt":1631537340601,"mc":[{"id":"1.187557985","rc":[{"trd":[[1.66,191.1],[1.67,50.89]],"batb":[[0,1.55,368.3]],"batl":[[0,1.8,5],[1,2.24,3],[2,2.24,0]],"ltp":1.67,"tv":16784.76,"id":9629022}],"tv":54256.5}]}
{"op":"mcm","clk":"4215293845","pt":1631537341596,"mc":[{"id":"1.187557985","rc":[{"batb":[[0,2.7,1416.66],[1,2.68,1375],[2,2.66,1375]],"batl":[[1,2.98,1283.56],[2,3,1462.2]],"ltp":2.52,"tv":37471.74,"id":5300820},{"batb":[[0,1.55,47.19]],"batl":[[0,1.61,12.42],[1,1.66,12],[2,1.8,5]],"ltp":1.67,"tv":16784.76,"id":9629022}]}]}
{"op":"mcm","clk":"4215293901","pt":1631537342571,"mc":[{"id":"1.187557985","rc":[{"batb":[[0,2.7,708.32],[1,2.68,740.72],[2,2.66,687.5]],"batl":[[1,2.98,359.69],[2,3,559]],"ltp":2.52,"tv":37471.74,"id":5300820},{"batl":[[0,1.57,174.57],[1,1.58,176.99],[2,1.61,12.42]],"ltp":1.67,"tv":16784.76,"id":9629022}]}]}
{"op":"mcm","clk":"4215293948","pt":1631537343608,"mc":[{"id":"1.187557985","rc":[{"batl":[[1,2.9,21.76],[2,2.98,359.69]],"ltp":2.52,"tv":37471.74,"id":5300820},{"batb":[[2,1.53,270.23]],"ltp":1.67,"tv":16784.76,"id":9629022}]}]}
{"op":"mcm","clk":"4215294056","pt":1631537345536,"mc":[{"id":"1.187557985","rc":[{"trd":[[2.74,17.52]],"batb":[[1,2.68,744.72],[2,2.66,691.5]],"ltp":2.74,"tv":37475.76,"id":5300820},{"trd":[[1.55,34.76],[1.57,13.05]],"batb":[[0,1.55,40.45]],"batl":[[0,1.57,167.54],[2,1.6,5]],"ltp":1.57,"tv":16805.29,"id":9629022}],"tv":54281.06}]}
{"op":"mcm","clk":"4215294113","pt":1631537346597,"mc":[{"id":"1.187557985","rc":[{"batb":[[0,2.74,242.56],[1,2.7,708.32],[2,2.68,744.72]],"ltp":2.74,"tv":37475.76,"id":5300820},{"trd":[[1.56,64.99]],"batb":[[0,1.56,12.52],[1,1.55,114.48],[2,1.54,227.6]],"batl":[[0,1.57,649.71],[1,1.58,234.71]],"ltp":1.56,"tv":16870.28,"id":9629022}],"tv":54346.04}]}
{"op":"mcm","clk":"4215294151","pt":1631537347529,"mc":[{"id":"1.187557985","rc":[{"trd":[[1.55,78.77],[1.56,90.03],[1.57,33.53]],"batb":[[0,1.55,92.47],[1,1.54,227.6],[2,1.53,270.23]],"batl":[[0,1.57,639.47]],"ltp":1.57,"tv":16959.81,"id":9629022}],"tv":54435.58}]}
{"op":"mcm","clk":"4215294197","pt":1631537348202,"mc":[{"id":"1.187557985","rc":[{"batl":[[1,2.86,198.13],[2,2.9,26.51]],"ltp":2.74,"tv":37475.76,"id":5300820},{"trd":[[1.57,42.21]],"batb":[[1,1.54,595.58],[2,1.53,317.56]],"batl":[[0,1.57,635.13]],"ltp":1.57,"tv":16968.49,"id":9629022}],"tv":54444.26}]}
{"op":"mcm","clk":"4215294269","pt":1631537349513,"mc":[{"id":"1.187557985","rc":[{"trd":[[2.74,25.52]],"batb":[[0,2.74,238.56]],"ltp":2.74,"tv":37483.77,"id":5300820},{"trd":[[1.57,103.64]],"batl":[[0,1.57,482.17]],"ltp":1.57,"tv":17029.93,"id":9629022}],"tv":54513.7}]}
{"op":"mcm","clk":"4215294334","pt":1631537350603,"mc":[{"id":"1.187557985","rc":[{"batb":[[0,2.74,257.59]],"ltp":2.74,"tv":37483.77,"id":5300820},{"batb":[[0,1.55,163.6]],"batl":[[0,1.57,691.79]],"ltp":1.57,"tv":17029.93,"id":9629022}]}]}
{"op":"mcm","clk":"4215294363","pt":1631537351016,"mc":[{"id":"1.187557985","rc":[{"batb":[[0,1.55,92.47],[1,1.54,519.85]],"batl":[[1,1.58,176.99]],"ltp":1.57,"tv":17029.93,"id":9629022}]}]}
{"op":"mcm","clk":"4215294456","pt":1631537352549,"mc":[{"id":"1.187557985","rc":[{"trd":[[1.57,104.03]],"batb":[[2,1.53,339.4]],"batl":[[0,1.57,691.59],[1,1.58,329.38],[2,1.59,172.04]],"ltp":1.57,"tv":17030.32,"id":9629022}],"tv":54514.09}]}
{"op":"mcm","clk":"4215294527","pt":1631537353635,"mc":[{"id":"1.187557985","rc":[{"batb":[[0,2.74,238.56],[1,2.68,57.22],[2,2.66,4]],"batl":[[0,2.86,198.13],[1,2.9,26.51],[2,2.98,141.03]],"ltp":2.74,"tv":37483.77,"id":5300820},{"trd":[[1.57,144.99]],"batb":[[0,1.55,74.03],[2,1.53,88.53]],"batl":[[0,1.57,671.11],[1,1.6,5],[2,1.62,39.84]],"ltp":1.57,"tv":17071.27,"id":9629022}],"tv":54555.04}]}
{"op":"mcm","clk":"4215294574","pt":1631537354314,"mc":[{"id":"1.187557985","rc":[{"batb":[[0,2.62,18.51],[1,2.58,193.93],[2,2.56,165.27]],"batl":[[0,2.9,21.76],[1,2.98,141.03],[2,3,364.2]],"ltp":2.74,"tv":37483.77,"id":5300820},{"trd":[[1.55,102.78],[1.57,145.02]],"batb":[[0,1.55,62.03],[1,1.53,41.2],[2,1.51,57.99]],"batl":[[0,1.57,247.76],[1,1.62,30],[2,1.64,220.43]],"ltp":1.57,"tv":17095.3,"id":9629022}],"tv":54579.07}]}
{"op":"mcm","clk":"4215294636","pt":1631537355417,"mc":[{"id":"1.187557985","rc":[{"batb":[[0,2.58,193.93],[1,2.56,165.27],[2,2.54,262.02]],"batl":[[0,2.98,141.03],[1,3,364.2],[2,3.05,229.8]],"ltp":2.74,"tv":37483.77,"id":5300820},{"batb":[[1,1.51,57.99],[2,1.5,261.89]],"batl":[[0,1.57,115.76],[1,1.64,220.43],[2,1.65,302.15]],"ltp":1.57,"tv":17095.3,"id":9629022}]}]}
{"op":"mcm","clk":"4215294687","pt":1631537356613,"mc":[{"id":"1.187557985","rc":[{"batb":[[2,1.5,255.89]],"batl":[[2,1.65,571.67]],"ltp":1.57,"tv":17095.3,"id":9629022}]}]}
{"op":"mcm","clk":"4215294754","pt":1631537357497,"mc":[{"id":"1.187557985","rc":[{"batl":[[0,2.9,4.45],[1,2.98,141.03],[2,3,364.2]],"ltp":2.74,"tv":37483.77,"id":5300820},{"trd":[[1.55,130.3]],"batb":[[0,1.53,42.33]],"batl":[[0,1.64,220.43],[1,1.65,571.67],[2,1.66,336.91]],"ltp":1.55,"tv":17122.82,"id":9629022}],"tv":54606.59}]}
{"op":"mcm","clk":"4215294790","pt":1631537358013,"mc":[{"id":"1.187557985","rc":[{"batl":[[0,2.98,141.03],[1,3,364.2],[2,3.05,229.8]],"ltp":2.74,"tv":37483.77,"id":5300820},{"batb":[[0,1.51,57.99],[1,1.5,255.89],[2,1.49,558.2]],"batl":[[0,1.64,220.53]],"ltp":1.55,"tv":17122.82,"id":9629022}]}]}
{"op":"mcm","clk":"4215294967","pt":1631537360637,"mc":[{"id":"1.187557985","rc":[{"batb":[[0,2.5,63.76],[1,2.48,17.77],[2,2.38,18.13]],"batl":[[0,2.98,144.03]],"ltp":2.74,"tv":37483.77,"id":5300820},{"trd":[[1.51,636.06]],"batb":[[0,1.5,261.89],[1,1.49,558.2],[2,1.48,542.89]],"batl":[[0,1.51,231.31],[1,1.67,43.09],[2,1.72,40.57]],"ltp":1.51,"tv":17238.79,"id":9629022}],"tv":54722.56}]}
{"op":"mcm","clk":"4215294998","pt":1631537361107,"mc":[{"id":"1.187557985","rc":[{"trd":[[2.96,13.52]],"ltp":2.96,"tv":37487.72,"id":5300820},{"trd":[[1.51,726.45]],"batl":[[0,1.51,182.25]],"ltp":1.51,"tv":17329.18,"id":9629022}],"tv":54816.9}]}
{"op":"mcm","clk":"4215295111","pt":1631537362514,"mc":[{"id":"1.187557985","rc":[{"batl":[[0,2.98,141.03],[1,3,147.8]],"ltp":2.96,"tv":37487.72,"id":5300820},{"batb":[[0,1.5,255.89]],"batl":[[1,1.53,184.84],[2,1.67,43.09]],"ltp":1.51,"tv":17329.18,"id":9629022}]}]}
{"op":"mcm","clk":"4215295189","pt":1631537363629,"mc":[{"id":"1.187557985","rc":[{"batb":[[0,2.9,1318.96],[1,2.88,1280.18],[2,2.86,1280.18]],"batl":[[0,2.98,4.75],[1,3.05,229.8],[2,3.2,1195.32]],"ltp":2.96,"tv":37487.72,"id":5300820},{"batb":[[0,1.49,563.2],[1,1.48,542.89],[2,1.47,236.32]],"batl":[[1,1.52,286.89],[2,1.53,383.38]],"ltp":1.51,"tv":17329.18,"id":9629022}]}]}
{"op":"mcm","clk":"4215295238","pt":1631537364313,"mc":[{"id":"1.187557985","rc":[{"batb":[[0,2.9,659.48],[1,2.88,684.43],[2,2.86,640.08]],"batl":[[2,3.1,6.45]],"ltp":2.96,"tv":37487.72,"id":5300820},{"trd":[[1.51,1015.78]],"batb":[[0,1.49,558.2]],"batl":[[0,1.51,37.6]],"ltp":1.51,"tv":17618.51,"id":9629022}],"tv":55106.23}]}
{"op":"mcm","clk":"4215295332","pt":1631537365608,"mc":[{"id":"1.187557985","rc":[{"trd":[[2.96,17.68]],"ltp":2.96,"tv":37491.87,"id":5300820},{"trd":[[1.51,1023.92]],"batb":[[2,1.47,280.07]],"batl":[[0,1.51,29.46]],"ltp":1.51,"tv":17626.65,"id":9629022}],"tv":55118.53}]}
{"op":"mcm","clk":"4215295400","pt":1631537366648,"mc":[{"id":"1.187557985","rc":[{"batb":[[2,2.86,644.08]],"ltp":2.96,"tv":37491.87,"id":5300820},{"batb":[[2,1.47,236.32]],"ltp":1.51,"tv":17626.65,"id":9629022}]}]}
{"op":"mcm","clk":"4215295472","pt":1631537367537,"mc":[{"id":"1.187557985","rc":[{"trd":[[2.98,3.35]],"batl":[[0,2.98,1.4]],"ltp":2.98,"tv":37495.22,"id":5300820},{"trd":[[1.5,476.99],[1.51,1024]],"batl":[[0,1.51,29.42],[2,1.53,198.54]],"ltp":1.5,"tv":17633.39,"id":9629022}],"tv":55128.62}]}
{"op":"mcm","clk":"4215295555","pt":1631537368636,"mc":[{"id":"1.187557985","rc":[{"trd":[[2.98,4.75]],"batb":[[0,2.92,19.9],[1,2.9,659.48],[2,2.88,684.43]],"batl":[[0,3.05,229.8],[1,3.1,6.45],[2,3.2,328.71]],"ltp":2.98,"tv":37496.62,"id":5300820},{"trd":[[1.49,63.36],[1.5,479.77]],"batb":[[0,1.49,208.02],[1,1.48,609.29]],"batl":[[0,1.5,2.16],[1,1.51,92.94],[2,1.52,358.99]],"ltp":1.49,"tv":17693.43,"id":9629022}],"tv":55190.06}]}
{"op":"mcm","clk":"4215295611","pt":1631537369520,"mc":[{"id":"1.187557985","rc":[{"trd":[[1.5,484.1],[1.51,1103.39]],"batl":[[0,1.51,53.25],[1,1.52,358.99],[2,1.53,198.54]],"ltp":1.51,"tv":17777.15,"id":9629022}],"tv":55273.78}]}
{"op":"mcm","clk":"4215295706","pt":1631537370622,"mc":[{"id":"1.187557985","rc":[{"trd":[[1.49,433.1]],"batb":[[0,1.49,23.12]],"batl":[[2,1.53,228.54]],"ltp":1.49,"tv":18146.89,"id":9629022}],"tv":55643.52}]}
{"op":"mcm","clk":"4215295771","pt":1631537371351,"mc":[{"id":"1.187557985","rc":[{"batl":[[2,3.2,348.93]],"ltp":2.98,"tv":37496.62,"id":5300820}]}]}
{"op":"mcm","clk":"4215295929","pt":1631537373542,"mc":[{"id":"1.187557985","rc":[{"trd":[[2.96,17.7],[3.05,21.02]],"batb":[[0,2.9,675.26],[1,2.88,684.43],[2,2.86,640.08]],"batl":[[0,3.05,228.69]],"ltp":3.05,"tv":37498.88,"id":5300820},{"trd":[[1.49,437.54],[1.51,1103.44]],"batb":[[0,1.5,75.2],[1,1.48,542.89]],"batl":[[0,1.51,131.24],[1,1.52,286.89]],"ltp":1.49,"tv":18151.39,"id":9629022}],"tv":55650.27}]}
{"op":"mcm","clk":"4215295996","pt":1631537374426,"mc":[{"id":"1.187557985","rc":[{"batb":[[0,2.92,228.35],[1,2.9,675.26],[2,2.88,684.43]],"ltp":3.05,"tv":37498.88,"id":5300820},{"trd":[[1.51,1216.6]],"batl":[[0,1.51,74.65],[1,1.52,725.56]],"ltp":1.51,"tv":18264.55,"id":9629022}],"tv":55763.43}]}
{"op":"mcm","clk":"4215296114","pt":1631537376145,"mc":[{"id":"1.187557985","rc":[{"batb":[[1,2.9,695.16]],"ltp":3.05,"tv":37498.88,"id":5300820},{"batb":[[0,1.48,542.89],[1,1.47,236.32],[2,1.46,6]],"batl":[[0,1.52,725.56],[1,1.53,228.54],[2,1.55,1.38]],"ltp":1.51,"tv":18264.55,"id":9629022}]}]}
{"op":"mcm","clk":"4215296219","pt":1631537377561,"mc":[{"id":"1.187557985","rc":[{"batl":[[0,3.05,442.57]],"ltp":3.05,"tv":37498.88,"id":5300820},{"batb":[[0,1.49,437.82],[1,1.48,542.89],[2,1.47,236.32]],"ltp":1.51,"tv":18264.55,"id":9629022}]}]}
{"op":"mcm","clk":"4215296332","pt":1631537379123,"mc":[{"id":"1.187557985","rc":[{"batb":[[0,1.49,438.19]],"batl":[[2,1.57,12.74]],"ltp":1.51,"tv":18264.55,"id":9629022}]}]}
{"op":"mcm","clk":"4215296556","pt":1631537382455,"mc":[{"id":"1.187557985","rc":[{"batb":[[1,2.9,679.38]],"batl":[[2,3.2,328.71]],"ltp":3.05,"tv":37498.88,"id":5300820},{"trd":[[1.49,506.41],[1.51,1217.34]],"batb":[[0,1.49,403.38]],"batl":[[0,1.52,784.56],[1,1.53,198.54]],"ltp":1.49,"tv":18334.15,"id":9629022}],"tv":55833.04}]}
{"op":"mcm","clk":"4215296692","pt":1631537384432,"mc":[{"id":"1.187557985","rc":[{"batb":[[0,2.88,44.35],[1,2.68,10.11],[2,2.6,216.94]],"batl":[[0,3.45,2.32],[1,3.5,158.13],[2,3.55,180.72]],"ltp":3.05,"tv":37498.88,"id":5300820},{"batb":[[0,1.41,11.31],[1,1.4,371.13],[2,1.39,607.4]],"batl":[[0,1.52,59],[1,1.58,10.09],[2,1.59,5.89]],"ltp":1.49,"tv":18334.15,"id":9629022}]}]}
{"op":"mcm","clk":"4215296761","pt":1631537385531,"mc":[{"id":"1.187557985","rc":[{"batb":[[0,2.94,15.46]],"ltp":3.05,"tv":37498.88,"id":5300820},{"batb":[[0,1.4,371.13],[1,1.39,601.66],[2,1.38,518.44]],"batl":[[0,1.51,30],[1,1.59,5.89],[2,1.62,224.92]],"ltp":1.49,"tv":18334.15,"id":9629022}]}]}
{"op":"mcm","clk":"4215296809","pt":1631537386463,"mc":[{"id":"1.187557985","rc":[{"batb":[[0,2.68,10.11],[1,2.6,216.94],[2,2.58,186.78]],"ltp":3.05,"tv":37498.88,"id":5300820},{"batb":[[0,1.5,52.93],[1,1.4,371.13],[2,1.39,601.66]],"batl":[[0,1.59,5.89],[1,1.62,224.92],[2,1.63,342.1]],"ltp":1.49,"tv":18334.15,"id":9629022}]}]}
{"op":"mcm","clk":"4215296876","pt":1631537387659,"mc":[{"id":"1.187557985","rc":[{"batb":[[1,2.64,55.98],[2,2.6,216.94]],"batl":[[0,3.3,19.78],[1,3.45,2.32],[2,3.5,158.13]],"ltp":3.05,"tv":37498.88,"id":5300820},{"batb":[[1,1.44,45.22],[2,1.4,371.13]],"batl":[[1,1.62,395.98],[2,1.63,500.27]],"ltp":1.49,"tv":18334.15,"id":9629022}]}]}
{"op":"mcm","clk":"4215296929","pt":1631537388640,"mc":[{"id":"1.187557985","rc":[{"batb":[[2,2.6,159.03]],"batl":[[0,3.45,2.32],[1,3.5,158.13],[2,3.55,180.72]],"ltp":3.05,"tv":37498.88,"id":5300820},{"batb":[[1,1.41,321.11],[2,1.4,377.13]],"batl":[[1,1.62,224.92],[2,1.63,342.1]],"ltp":1.49,"tv":18334.15,"id":9629022}]}]}
{"op":"mcm","clk":"4215297030","pt":1631537390556,"mc":[{"id":"1.187557985","rc":[{"trd":[[2.96,18.08]],"batb":[[0,2.64,55.98],[1,2.6,159.03],[2,2.58,186.78]],"ltp":2.96,"tv":37499.26,"id":5300820},{"trd":[[1.52,10.73]],"batb":[[0,1.52,1.59],[1,1.5,57.93],[2,1.41,321.11]],"batl":[[0,1.62,224.92],[1,1.63,342.1],[2,1.64,381.06]],"ltp":1.52,"tv":18334.88,"id":9629022}],"tv":55834.14}]}
{"op":"mcm","clk":"4215297085","pt":1631537391651,"mc":[{"id":"1.187557985","rc":[{"trd":[[2.92,40.45]],"ltp":2.92,"tv":37527.57,"id":5300820},{"trd":[[1.52,68.3]],"batb":[[0,1.51,5.37],[2,1.48,203.29]],"batl":[[0,1.52,230.91],[1,1.53,198.54],[2,1.62,224.92]],"ltp":1.52,"tv":18392.45,"id":9629022}],"tv":55920.02}]}
{"op":"mcm","clk":"4215297146","pt":1631537392649,"mc":[{"id":"1.187557985","rc":[{"batb":[[0,2.7,458.06],[1,2.64,55.98],[2,2.6,159.03]],"ltp":2.92,"tv":37527.57,"id":5300820},{"batb":[[2,1.41,321.11]],"batl":[[0,1.62,224.92],[1,1.63,342.1],[2,1.64,381.06]],"ltp":1.52,"tv":18392.45,"id":9629022}]}]}
{"op":"mcm","clk":"4215297155","pt":1631537392755,"mc":[{"id":"1.187557985","rc":[{"batb":[[0,2.64,55.98],[1,2.6,159.03],[2,2.58,186.78]],"ltp":2.92,"tv":37527.57,"id":5300820}]}]}
{"op":"mcm","clk":"4215297262","pt":1631537394568,"mc":[{"id":"1.187557985","rc":[{"batb":[[1,1.5,5]],"ltp":1.52,"tv":18392.45,"id":9629022}]}]}
{"op":"mcm","clk":"4215297316","pt":1631537395556,"mc":[{"id":"1.187557985","rc":[{"batl":[[1,1.63,613.66],[2,1.64,535]],"ltp":1.52,"tv":18392.45,"id":9629022}]}]}
{"op":"mcm","clk":"4215297408","pt":1631537397061,"mc":[{"id":"1.187557985","rc":[{"batl":[[1,4.2,150.07],[2,6,3]],"ltp":2.92,"tv":37527.57,"id":5300820}]}]}
{"op":"mcm","clk":"4215297597","pt":1631537399666,"mc":[{"id":"1.187557985","rc":[{"batl":[[0,2.72,863.96],[1,2.74,431.98],[2,2.76,431.98]],"ltp":2.92,"tv":37527.57,"id":5300820}]}]}
{"op":"mcm","clk":"4215297668","pt":1631537400655,"mc":[{"id":"1.187557985","rc":[{"batb":[[0,1.58,214.21],[1,1.57,182.13],[2,1.55,145.52]],"ltp":1.52,"tv":18392.45,"id":9629022}]}]}
{"op":"mcm","clk":"4215297724","pt":1631537401355,"mc":[{"id":"1.187557985","rc":[{"batb":[[0,2.64,74.27]],"ltp":2.92,"tv":37527.57,"id":5300820},{"batl":[[0,1.61,30],[1,1.62,224.92],[2,1.63,613.66]],"ltp":1.52,"tv":18392.45,"id":9629022}]}]}
{"op":"mcm","clk":"4215297933","pt":1631537404663,"mc":[{"id":"1.187557985","rc":[{"trd":[[2.64,5.04],[2.68,62.65]],"batb":[[0,2.64,71.75]],"batl":[[0,2.7,235.25],[1,2.72,863.96],[2,2.74,431.98]],"ltp":2.68,"tv":37533.78,"id":5300820},{"trd":[[1.6,49.43]],"batb":[[0,1.6,5.92],[1,1.59,461],[2,1.58,288.95]],"batl":[[0,1.61,192.33],[1,1.62,286.09]],"ltp":1.6,"tv":18431.14,"id":9629022}],"tv":55964.92}]}
{"op":"mcm","clk":"4215298301","pt":1631537410290,"mc":[{"id":"1.187557985","rc":[{"batb":[[2,1.58,214.21]],"batl":[[1,1.62,224.92]],"ltp":1.6,"tv":18431.14,"id":9629022}]}]}
{"op":"mcm","clk":"4215298429","pt":1631537412579,"mc":[{"id":"1.187557985","rc":[{"trd":[[1.61,2.31]],"batb":[[0,1.59,399.49],[1,1.58,214.21],[2,1.57,182.13]],"batl":[[0,1.61,125.63]],"ltp":1.61,"tv":18431.88,"id":9629022}],"tv":55965.67}]}
{"op":"mcm","clk":"4215298483","pt":1631537413498,"mc":[{"id":"1.187557985","rc":[{"batb":[[0,2.64,18.29],[1,2.42,70.71],[2,2.38,169.28]],"batl":[[0,2.96,3],[1,3,164.17],[2,3.05,177.8]],"ltp":2.68,"tv":37533.78,"id":5300820},{"batb":[[0,1.52,48.39],[1,1.51,6.27],[2,1.5,575.56]],"batl":[[1,1.72,34.41],[2,1.73,214]],"ltp":1.61,"tv":18431.88,"id":9629022}]}]}
{"op":"mcm","clk":"4215298532","pt":1631537414371,"mc":[{"id":"1.187557985","rc":[{"batb":[[0,2.42,70.71],[1,2.38,169.28],[2,2.36,204.11]],"batl":[[0,3,164.17],[1,3.05,177.8],[2,3.1,166.28]],"ltp":2.68,"tv":37533.78,"id":5300820},{"batb":[[0,1.52,43.39]],"batl":[[0,1.72,34.41],[1,1.73,214],[2,1.74,338.03]],"ltp":1.61,"tv":18431.88,"id":9629022}]}]}
{"op":"mcm","clk":"4215298592","pt":1631537415307,"mc":[{"id":"1.187557985","rc":[{"batb":[[1,1.51,59.2]],"ltp":1.61,"tv":18431.88,"id":9629022}]}]}
{"op":"mcm","clk":"4215298682","pt":1631537416579,"mc":[{"id":"1.187557985","rc":[{"batl":[[0,2.92,3],[1,3,164.17],[2,3.05,177.8]],"ltp":2.68,"tv":37533.78,"id":5300820},{"batb":[[0,1.55,5],[1,1.54,6],[2,1.53,6]],"batl":[[2,1.74,602.11]],"ltp":1.61,"tv":18431.88,"id":9629022}]}]}
{"op":"mcm","clk":"4215298690","pt":1631537416690,"mc":[{"id":"1.187557985","rc":[{"batl":[[0,3,164.17],[1,3.05,177.8],[2,3.1,166.28]],"ltp":2.68,"tv":37533.78,"id":5300820},{"batb":[[0,1.52,43.39],[1,1.51,59.2],[2,1.5,581.56]],"ltp":1.61,"tv":18431.88,"id":9629022}]}]}
{"op":"mcm","clk":"4215298945","pt":1631537421216,"mc":[{"id":"1.187557985","rc":[{"batl":[[0,3.45,2.32],[1,3.65,172.76],[2,6,3]],"ltp":2.68,"tv":37533.78,"id":5300820},{"batb":[[2,1.5,332.11]],"ltp":1.61,"tv":18431.88,"id":9629022}]}]}
{"op":"mcm","clk":"4215298992","pt":1631537421896,"mc":[{"id":"1.187557985","rc":[{"trd":[[1.52,78.3]],"batb":[[0,1.52,38.4]],"ltp":1.52,"tv":18441.88,"id":9629022}],"tv":55975.66}]}
{"op":"mcm","clk":"4215299051","pt":1631537422994,"mc":[{"id":"1.187557985","rc":[{"batl":[[1,6,3],[2,6.4,3]],"ltp":2.68,"tv":37533.78,"id":5300820}]}]}
{"op":"mcm","clk":"4215299161","pt":1631537424410,"mc":[{"id":"1.187557985","rc":[{"batl":[[0,2.62,7.63],[1,3.45,2.32],[2,6,3]],"ltp":2.68,"tv":37533.78,"id":5300820},{"batb":[[0,1.68,211.39],[1,1.66,1447.85],[2,1.65,1118.22]],"batl":[[1,1.73,223.22]],"ltp":1.52,"tv":18441.88,"id":9629022}]}]}
{"op":"mcm","clk":"4215299231","pt":1631537425396,"mc":[{"id":"1.187557985","rc":[{"batb":[[2,2.36,226.16]],"batl":[[0,2.62,31.2]],"ltp":2.68,"tv":37533.78,"id":5300820},{"batl":[[1,1.73,253.22],[2,1.74,613.6]],"ltp":1.52,"tv":18441.88,"id":9629022}]}]}
{"op":"mcm","clk":"4215299310","pt":1631537426594,"mc":[{"id":"1.187557985","rc":[{"batl":[[1,3.3,194.57],[2,3.45,2.32]],"ltp":2.68,"tv":37533.78,"id":5300820}]}]}
{"op":"mcm","clk":"4215299332","pt":1631537426910,"mc":[{"id":"1.187557985","rc":[{"trd":[[2.42,37.92]],"batb":[[0,2.42,70.6],[1,2.38,163.61]],"ltp":2.42,"tv":37534.01,"id":5300820},{"batl":[[0,1.73,253.22],[1,1.74,613.6],[2,1.75,283.52]],"ltp":1.52,"tv":18441.88,"id":9629022}],"tv":55975.89}]}
{"op":"mcm","clk":"4215299430","pt":1631537428498,"mc":[{"id":"1.187557985","rc":[{"batl":[[0,2.6,38.15],[1,2.62,31.2],[2,3.3,194.57]],"ltp":2.42,"tv":37534.01,"id":5300820},{"batb":[[0,1.7,5.57],[1,1.69,77.04],[2,1.68,211.39]],"batl":[[0,1.71,71.21],[1,1.72,75.9],[2,1.73,253.22]],"ltp":1.52,"tv":18441.88,"id":9629022}]}]}
{"op":"mcm","clk":"4215299473","pt":1631537429219,"mc":[{"id":"1.187557985","rc":[{"trd":[[2.44,24.33]],"batl":[[0,2.48,234.27],[1,2.6,38.15],[2,2.62,7.63]],"ltp":2.44,"tv":37535.36,"id":5300820},{"trd":[[1.7,112.41]],"batb":[[0,1.7,1.64],[2,1.68,625.2]],"ltp":1.7,"tv":18447.79,"id":9629022}],"tv":55983.16}]}
{"op":"mcm","clk":"4215299608","pt":1631537431426,"mc":[{"id":"1.187557985","rc":[{"trd":[[1.7,115.69]],"batb":[[0,1.69,77.04],[1,1.68,625.2],[2,1.66,1447.85]],"ltp":1.7,"tv":18451.07,"id":9629022}],"tv":55986.44}]}
{"op":"mcm","clk":"4215299673","pt":1631537432425,"mc":[{"id":"1.187557985","rc":[{"batl":[[1,2.58,23.86],[2,2.6,38.15]],"ltp":2.44,"tv":37535.36,"id":5300820}]}]}
{"op":"mcm","clk":"4215299742","pt":1631537433631,"mc":[{"id":"1.187557985","rc":[{"batb":[[2,1.66,295.73]],"batl":[[0,1.71,212.21]],"ltp":1.7,"tv":18451.07,"id":9629022}]}]}
{"op":"mcm","clk":"4215299796","pt":1631537434313,"mc":[{"id":"1.187557985","rc":[{"batb":[[0,2.36,22.05],[1,2.28,82.76],[2,2.24,179.13]],"batl":[[0,2.58,23.86],[1,2.66,150.21],[2,2.68,216.49]],"ltp":2.44,"tv":37535.36,"id":5300820},{"batb":[[1,1.6,250.24],[2,1.59,321.85]],"batl":[[2,1.73,30]],"ltp":1.7,"tv":18451.07,"id":9629022}]}]}
{"op":"mcm","clk":"4215299858","pt":1631537435509,"mc":[{"id":"1.187557985","rc":[{"batb":[[0,2.28,82.76],[1,2.24,179.13],[2,2.22,199.84]],"batl":[[0,2.66,150.21],[1,2.68,216.49],[2,2.7,218.28]],"ltp":2.44,"tv":37535.36,"id":5300820},{"batl":[[0,1.71,71.21],[2,1.79,10]],"ltp":1.7,"tv":18451.07,"id":9629022}]}]}
{"op":"mcm","clk":"4215299905","pt":1631537436410,"mc":[{"id":"1.187557985","rc":[{"batb":[[0,1.61,321.11]],"batl":[[0,1.7,2.32],[1,1.79,10],[2,1.8,255.17]],"ltp":1.7,"tv":18451.07,"id":9629022}]}]}
{"op":"mcm","clk":"4215299966","pt":1631537437608,"mc":[{"id":"1.187557985","rc":[{"batb":[[0,1.61,642.22]],"batl":[[0,1.7,2.52]],"ltp":1.7,"tv":18451.07,"id":9629022}]}]}
{"op":"mcm","clk":"4215299973","pt":1631537437711,"mc":[{"id":"1.187557985","rc":[{"batl":[[0,3.3,194.57],[1,3.45,2.32],[2,6,3]],"ltp":2.44,"tv":37535.36,"id":5300820},{"batb":[[1,1.55,144.18],[2,1.52,43.4]],"ltp":1.7,"tv":18451.07,"id":9629022}]}]}
{"op":"mcm","clk":"4215300102","pt":1631537439605,"mc":[{"id":"1.187557985","rc":[{"batb":[[0,2.28,85.76],[1,2.26,4],[2,2.24,179.13]],"batl":[[0,2.4,2527.62],[1,2.56,11.32],[2,3.3,194.57]],"ltp":2.44,"tv":37535.36,"id":5300820},{"trd":[[1.68,303.8],[1.7,120.33]],"batl":[[0,1.79,5],[1,1.8,255.17],[2,1.81,307.7]],"ltp":1.7,"tv":18456.11,"id":9629022}],"tv":55991.48}]}
{"op":"mcm","clk":"4215300170","pt":1631537440605,"mc":[{"id":"1.187557985","rc":[{"batb":[[0,2.28,82.76],[1,2.24,179.13],[2,2.22,199.84]],"batl":[[0,2.5,8],[1,3.3,194.57],[2,3.45,2.32]],"ltp":2.44,"tv":37535.36,"id":5300820},{"batb":[[0,1.77,144.78],[1,1.75,2432.34],[2,1.74,2121.44]],"ltp":1.7,"tv":18456.11,"id":9629022}]}]}
{"op":"mcm","clk":"4215300238","pt":1631537441637,"mc":[{"id":"1.187557985","rc":[{"batb":[[1,1.75,1339.48],[2,1.74,1060.72]],"batl":[[0,1.79,13.91],[1,1.8,266.28],[2,1.81,312.11]],"ltp":1.7,"tv":18456.11,"id":9629022}]}]}
{"op":"mcm","clk":"4215300290","pt":1631537442420,"mc":[{"id":"1.187557985","rc":[{"batl":[[0,2.42,25.17],[1,2.5,8],[2,2.62,4]],"ltp":2.44,"tv":37535.36,"id":5300820}]}]}
{"op":"mcm","clk":"4215300368","pt":1631537443628,"mc":[{"id":"1.187557985","rc":[{"batl":[[0,2.38,4],[1,2.42,25.17],[2,2.48,3]],"ltp":2.44,"tv":37535.36,"id":5300820},{"trd":[[1.77,407.64]],"batb":[[0,1.75,1092.86],[1,1.74,1060.72],[2,1.73,1060.72]],"ltp":1.77,"tv":18500.11,"id":9629022}],"tv":56035.48}]}
{"op":"mcm","clk":"4215300514","pt":1631537445623,"mc":[{"id":"1.187557985","rc":[{"trd":[[2.3,50.47]],"batl":[[0,2.32,252.66],[1,2.38,4],[2,2.48,89.8]],"ltp":2.3,"tv":37536.92,"id":5300820},{"trd":[[1.77,413.64]],"batb":[[0,1.77,52.71],[1,1.76,333.05],[2,1.75,1092.86]],"batl":[[0,1.79,94.76],[1,1.8,342.8]],"ltp":1.77,"tv":18506.1,"id":9629022}],"tv":56043.03}]}
{"op":"mcm","clk":"4215300552","pt":1631537446243,"mc":[{"id":"1.187557985","rc":[{"batl":[[0,2.3,268.76],[1,2.32,252.66],[2,2.38,4]],"ltp":2.3,"tv":37536.92,"id":5300820},{"batb":[[0,1.77,401.94],[1,1.76,653.93]],"ltp":1.77,"tv":18506.1,"id":9629022}]}]}
{"op":"mcm","clk":"4215300684","pt":1631537448650,"mc":[{"id":"1.187557985","rc":[{"trd":[[2.28,0.45]],"batb":[[0,2.28,82.57]],"batl":[[2,2.38,29.53]],"ltp":2.28,"tv":37537.31,"id":5300820},{"batb":[[2,1.74,251.87]],"batl":[[0,1.79,168.76],[1,1.8,331.69]],"ltp":1.77,"tv":18506.1,"id":9629022}],"tv":56043.42}]}
{"op":"mcm","clk":"4215300714","pt":1631537449224,"mc":[{"id":"1.187557985","rc":[{"batb":[[0,2.2,116.63],[1,2.16,213.43],[2,2.14,249.15]],"batl":[[0,2.38,25.53],[1,2.4,207.56],[2,2.42,228.48]],"ltp":2.28,"tv":37537.31,"id":5300820},{"batb":[[0,1.77,52.71],[1,1.76,68.39],[2,1.72,35.35]],"batl":[[0,1.79,159.85],[1,1.8,81.52],[2,1.83,30]],"ltp":1.77,"tv":18506.1,"id":9629022}]}]}
{"op":"mcm","clk":"4215300814","pt":1631537450642,"mc":[{"id":"1.187557985","rc":[{"batb":[[0,2.2,91.63]],"batl":[[0,2.28,5]],"ltp":2.28,"tv":37537.31,"id":5300820},{"batb":[[0,1.77,111.68],[2,1.71,258.1]],"batl":[[0,1.79,85.85],[1,1.8,5],[2,1.86,242.36]],"ltp":1.77,"tv":18506.1,"id":9629022}]}]}
{"op":"mcm","clk":"4215300822","pt":1631537450746,"mc":[{"id":"1.187557985","rc":[{"batb":[[0,1.77,52.71],[1,1.71,258.1],[2,1.7,280.51]],"ltp":1.77,"tv":18506.1,"id":9629022}]}]}
{"op":"mcm","clk":"4215300928","pt":1631537452621,"mc":[{"id":"1.187557985","rc":[{"batb":[[2,1.7,466.37]],"ltp":1.77,"tv":18506.1,"id":9629022}]}]}
{"op":"mcm","clk":"4215300953","pt":1631537452934,"mc":[{"id":"1.187557985","rc":[{"batb":[[0,1.71,258.1],[1,1.7,466.37],[2,1.69,396.49]],"batl":[[0,1.79,5]],"ltp":1.77,"tv":18506.1,"id":9629022}]}]}
{"op":"mcm","clk":"4215301060","pt":1631537454544,"mc":[{"id":"1.187557985","rc":[{"batl":[[1,2.48,3],[2,2.62,4]],"ltp":2.28,"tv":37537.31,"id":5300820},{"trd":[[1.79,10],[1.8,37.37]],"batb":[[0,1.65,117.24],[1,1.62,4],[2,1.51,52.93]],"batl":[[0,1.86,242.36],[1,1.87,246.24],[2,1.88,429.45]],"ltp":1.8,"tv":18526.1,"id":9629022}],"tv":56063.42}]}
{"op":"mcm","clk":"4215301105","pt":1631537455435,"mc":[{"id":"1.187557985","rc":[{"batl":[[2,3.3,194.57]],"ltp":2.28,"tv":37537.31,"id":5300820}]}]}
{"op":"mcm","clk":"4215301218","pt":1631537457622,"mc":[{"id":"1.187557985","rc":[{"batl":[[0,2.26,846.24],[1,2.28,826.34],[2,2.3,821.34]],"ltp":2.28,"tv":37537.31,"id":5300820},{"batb":[[0,1.82,181.17],[1,1.8,224.99],[2,1.79,2.97]],"batl":[[0,1.83,8.71],[1,1.85,4.31],[2,1.86,242.36]],"ltp":1.8,"tv":18526.1,"id":9629022}]}]}
{"op":"mcm","clk":"4215301273","pt":1631537458557,"mc":[{"id":"1.187557985","rc":[{"batl":[[0,2.26,871.24]],"ltp":2.28,"tv":37537.31,"id":5300820},{"batl":[[0,1.83,19.64]],"ltp":1.8,"tv":18526.1,"id":9629022}]}]}
{"op":"mcm","clk":"4215301319","pt":1631537459551,"mc":[{"id":"1.187557985","rc":[{"batl":[[1,2.28,821.34]],"ltp":2.28,"tv":37537.31,"id":5300820}]}]}
{"op":"mcm","clk":"4215301391","pt":1631537460921,"mc":[{"id":"1.187557985","rc":[{"batl":[[0,2.26,910.24]],"ltp":2.28,"tv":37537.31,"id":5300820}]}]}
{"op":"mcm","clk":"4215301487","pt":1631537462543,"mc":[{"id":"1.187557985","rc":[{"batl":[[1,2.28,847.85]],"ltp":2.28,"tv":37537.31,"id":5300820}]}]}
{"op":"mcm","clk":"4215301538","pt":1631537463165,"mc":[{"id":"1.187557985","rc":[{"batb":[[2,1.78,33.96]],"ltp":1.8,"tv":18526.1,"id":9629022}]}]}
{"op":"mcm","clk":"4215301626","pt":1631537464319,"mc":[{"id":"1.187557985","rc":[{"batl":[[0,2.22,264.66],[1,2.26,910.24],[2,2.28,847.85]],"ltp":2.28,"tv":37537.31,"id":5300820},{"batb":[[0,1.82,504]],"ltp":1.8,"tv":18526.1,"id":9629022}]}]}
{"op":"mcm","clk":"4215301703","pt":1631537465464,"mc":[{"id":"1.187557985","rc":[{"batl":[[1,2.24,234.01],[2,2.26,910.24]],"ltp":2.28,"tv":37537.31,"id":5300820},{"trd":[[1.83,15.28]],"batb":[[1,1.81,289.61],[2,1.8,224.99]],"batl":[[0,1.83,215.32]],"ltp":1.83,"tv":18530.75,"id":9629022}],"tv":56068.07}]}
{"op":"mcm","clk":"4215301840","pt":1631537467547,"mc":[{"id":"1.187557985","rc":[{"trd":[[2.22,1.08]],"batl":[[0,2.22,500.74]],"ltp":2.22,"tv":37538.39,"id":5300820},{"trd":[[1.83,445.96]],"batb":[[0,1.83,71.7],[1,1.82,504],[2,1.81,289.61]],"batl":[[0,1.85,4.31],[1,1.86,242.36],[2,1.87,246.24]],"ltp":1.83,"tv":18961.43,"id":9629022}],"tv":56499.82}]}
{"op":"mcm","clk":"4215301884","pt":1631537468128,"mc":[{"id":"1.187557985","rc":[{"trd":[[2.2,33.6]],"batb":[[0,2.2,86.63]],"ltp":2.2,"tv":37548.39,"id":5300820}],"tv":56509.82}]}
{"op":"mcm","clk":"4215301951","pt":1631537469164,"mc":[{"id":"1.187557985","rc":[{"batb":[[1,2.16,488.47]],"ltp":2.2,"tv":37548.39,"id":5300820},{"batl":[[0,1.85,325.44]],"ltp":1.83,"tv":18961.43,"id":9629022}]}]}
{"op":"mcm","clk":"4215302056","pt":1631537470634,"mc":[{"id":"1.187557985","rc":[{"trd":[[1.83,445.99]],"batb":[[0,1.83,71.68]],"ltp":1.83,"tv":18961.46,"id":9629022}],"tv":56509.85}]}
{"op":"mcm","clk":"4215302064","pt":1631537470738,"mc":[{"id":"1.187557985","rc":[{"trd":[[1.83,589.34]],"batb":[[0,1.82,504],[1,1.81,289.61],[2,1.8,224.99]],"batl":[[0,1.83,130.33],[1,1.85,325.44],[2,1.86,242.36]],"ltp":1.83,"tv":19104.81,"id":9629022}],"tv":56653.2}]}
{"op":"mcm","clk":"4215302154","pt":1631537472141,"mc":[{"id":"1.187557985","rc":[{"batl":[[2,2.26,871.24]],"ltp":2.2,"tv":37548.39,"id":5300820}]}]}
{"op":"mcm","clk":"4215302234","pt":1631537473650,"mc":[{"id":"1.187557985","rc":[{"trd":[[1.82,874.71]],"batb":[[0,1.82,80.43],[2,1.78,33.96]],"ltp":1.82,"tv":19951.91,"id":9629022}],"tv":57500.3}]}
{"op":"mcm","clk":"4215302288","pt":1631537474533,"mc":[{"id":"1.187557985","rc":[{"trd":[[1.82,874.93]],"batb":[[0,1.82,80.32]],"ltp":1.82,"tv":19952.13,"id":9629022}],"tv":57500.52}]}
{"op":"mcm","clk":"4215302346","pt":1631537475573,"mc":[{"id":"1.187557985","rc":[{"trd":[[1.82,875.06]],"batb":[[0,1.82,80.25]],"ltp":1.82,"tv":19952.26,"id":9629022}],"tv":57500.65}]}
{"op":"mcm","clk":"4215302423","pt":1631537476572,"mc":[{"id":"1.187557985","rc":[{"batl":[[0,2.22,236.62]],"ltp":2.2,"tv":37548.39,"id":5300820},{"batb":[[1,1.81,460.33],[2,1.79,229.44]],"ltp":1.82,"tv":19952.26,"id":9629022}]}]}
{"op":"mcm","clk":"4215302481","pt":1631537477666,"mc":[{"id":"1.187557985","rc":[{"batl":[[0,2.24,234.01],[1,2.26,871.24],[2,2.28,847.85]],"ltp":2.2,"tv":37548.39,"id":5300820},{"trd":[[1.82,875.08]],"batb":[[0,1.81,460.33],[1,1.79,229.44],[2,1.78,33.96]],"ltp":1.82,"tv":19952.28,"id":9629022}],"tv":57500.67}]}
{"op":"mcm","clk":"4215302624","pt":1631537480231,"mc":[{"id":"1.187557985","rc":[{"batl":[[0,1.82,3.72],[1,1.83,130.33],[2,1.85,325.44]],"ltp":1.82,"tv":19952.28,"id":9629022}]}]}
{"op":"mcm","clk":"4215302962","pt":1631537486360,"mc":[{"id":"1.187557985","rc":[{"trd":[[1.81,920.79]],"batb":[[0,1.78,33.96],[1,1.76,94.39],[2,1.66,222.68]],"batl":[[0,1.81,104.43],[1,1.82,3.72]],"ltp":1.81,"tv":20872.89,"id":9629022}],"tv":58421.28}]}
{"op":"mcm","clk":"4215303067","pt":1631537488384,"mc":[{"id":"1.187557985","rc":[{"batl":[[0,1.81,242.23],[1,1.85,325.44],[2,1.86,242.36]],"ltp":1.81,"tv":20872.89,"id":9629022}]}]}
{"op":"mcm","clk":"4215303132","pt":1631537489477,"mc":[{"id":"1.187557985","rc":[{"batl":[[0,2.26,871.24],[1,2.28,847.85],[2,2.3,821.34]],"ltp":2.2,"tv":37548.39,"id":5300820},{"batb":[[0,1.8,170.19],[1,1.79,133.93],[2,1.78,267.99]],"batl":[[0,1.81,830.23],[2,1.86,413.52]],"ltp":1.81,"tv":20872.89,"id":9629022}]}]}
{"op":"mcm","clk":"4215303167","pt":1631537489995,"mc":[{"id":"1.187557985","rc":[{"trd":[[2.22,6.11]],"ltp":2.22,"tv":37553.42,"id":5300820},{"trd":[[1.81,926.97]],"batl":[[0,1.81,824.05]],"ltp":1.81,"tv":20879.07,"id":9629022}],"tv":58432.5}]}
{"op":"mcm","clk":"4215303231","pt":1631537490990,"mc":[{"id":"1.187557985","rc":[{"batl":[[0,1.81,846.77]],"ltp":1.81,"tv":20879.07,"id":9629022}]}]}
{"op":"mcm","clk":"4215303361","pt":1631537493742,"mc":[{"id":"1.187557985","rc":[{"trd":[[1.81,927.04]],"batl":[[0,1.81,846.74]],"ltp":1.81,"tv":20879.13,"id":9629022}],"tv":58432.56}]}
{"op":"mcm","clk":"4215303449","pt":1631537495181,"mc":[{"id":"1.187557985","rc":[{"batb":[[0,1.8,143.7]],"batl":[[0,1.81,708.94]],"ltp":1.81,"tv":20879.13,"id":9629022}]}]}
{"op":"mcm","clk":"4215303576","pt":1631537497665,"mc":[{"id":"1.187557985","rc":[{"batl":[[2,1.86,439.23]],"ltp":1.81,"tv":20879.13,"id":9629022}]}]}
{"op":"mcm","clk":"4215303608","pt":1631537498390,"mc":[{"id":"1.187557985","rc":[{"trd":[[1.8,325.19]],"batb":[[0,1.79,133.93],[1,1.78,267.99],[2,1.76,94.39]],"batl":[[0,1.8,699.56],[1,1.81,708.94],[2,1.85,325.44]],"ltp":1.8,"tv":21166.95,"id":9629022}],"tv":58720.38}]}
{"op":"mcm","clk":"4215303629","pt":1631537498799,"mc":[{"id":"1.187557985","rc":[{"batb":[[0,1.79,32.3],[1,1.78,33.96]],"ltp":1.8,"tv":21166.95,"id":9629022}]}]}
{"op":"mcm","clk":"4215303778","pt":1631537501596,"mc":[{"id":"1.187557985","rc":[{"trd":[[2.24,16.17]],"batl":[[0,2.26,846.24]],"ltp":2.24,"tv":37560.33,"id":5300820},{"trd":[[1.8,354.15]],"batl":[[0,1.8,680.78],[1,1.81,689.94]],"ltp":1.8,"tv":21195.91,"id":9629022}],"tv":58756.25}]}
{"op":"mcm","clk":"4215303784","pt":1631537501704,"mc":[{"id":"1.187557985","rc":[{"batb":[[0,1.79,195.74],[2,1.77,238.79]],"batl":[[2,1.85,513.73]],"ltp":1.8,"tv":21195.91,"id":9629022}]}]}
{"op":"mcm","clk":"4215303894","pt":1631537503770,"mc":[{"id":"1.187557985","rc":[{"batl":[[0,1.8,684.72]],"ltp":1.8,"tv":21195.91,"id":9629022}]}]}
{"op":"mcm","clk":"4215304007","pt":1631537505480,"mc":[{"id":"1.187557985","rc":[{"trd":[[2.26,33.44]],"batl":[[0,2.26,814.49]],"ltp":2.26,"tv":37592.08,"id":5300820},{"trd":[[1.79,441.51]],"batb":[[0,1.78,33.96],[1,1.77,238.79],[2,1.76,94.39]],"ltp":1.79,"tv":21627.42,"id":9629022}],"tv":59219.51}]}
{"op":"mcm","clk":"4215304026","pt":1631537505791,"mc":[{"id":"1.187557985","rc":[{"batb":[[1,1.76,94.39],[2,1.66,222.68]],"batl":[[1,1.81,686.22],[2,1.85,325.44]],"ltp":1.79,"tv":21627.42,"id":9629022}]}]}
{"op":"mcm","clk":"4215304125","pt":1631537507396,"mc":[{"id":"1.187557985","rc":[{"trd":[[1.8,354.21]],"batl":[[0,1.8,684.69]],"ltp":1.8,"tv":21627.48,"id":9629022}],"tv":59219.57}]}
{"op":"mcm","clk":"4215304239","pt":1631537509665,"mc":[{"id":"1.187557985","rc":[{"trd":[[2.26,36.38]],"batl":[[0,2.26,811.55]],"ltp":2.26,"tv":37595.02,"id":5300820},{"trd":[[1.79,445.23]],"batb":[[0,1.78,237.89],[1,1.76,338.08]],"batl":[[2,1.84,190.58]],"ltp":1.79,"tv":21631.2,"id":9629022}],"tv":59226.23}]}
{"op":"mcm","clk":"4215304328","pt":1631537511270,"mc":[{"id":"1.187557985","rc":[{"trd":[[2.26,51.43]],"batl":[[0,2.26,796.5]],"ltp":2.26,"tv":37610.07,"id":5300820},{"trd":[[1.79,464.23]],"ltp":1.79,"tv":21650.2,"id":9629022}],"tv":59260.28}]}
{"op":"mcm","clk":"4215304462","pt":1631537513612,"mc":[{"id":"1.187557985","rc":[{"trd":[[2.26,51.5]],"batl":[[0,2.26,796.43]],"ltp":2.26,"tv":37610.14,"id":5300820},{"trd":[[1.79,464.32]],"ltp":1.79,"tv":21650.29,"id":9629022}],"tv":59260.44}]}
{"op":"mcm","clk":"4215304858","pt":1631537520208,"mc":[{"id":"1.187557985","rc":[{"trd":[[2.26,51.56]],"batl":[[0,2.26,796.37]],"ltp":2.26,"tv":37610.2,"id":5300820},{"trd":[[1.79,464.4]],"ltp":1.79,"tv":21650.37,"id":9629022}],"tv":59260.58}]}
{"op":"mcm","clk":"4215305093","pt":1631537523807,"mc":[{"id":"1.187557985","rc":[{"trd":[[1.8,357]],"batl":[[0,1.8,683.3]],"ltp":1.8,"tv":21653.16,"id":9629022}],"tv":59263.37}]}
{"op":"mcm","clk":"4215305494","pt":1631537529177,"mc":[{"id":"1.187557985","rc":[{"batl":[[0,1.8,3.94],[1,1.81,588]],"ltp":1.8,"tv":21653.16,"id":9629022}]}]}
{"op":"mcm","clk":"4215305774","pt":1631537533104,"mc":[{"id":"1.187557985","rc":[{"trd":[[2.26,51.78]],"batl":[[0,2.26,796.15]],"ltp":2.26,"tv":37610.42,"id":5300820},{"trd":[[1.79,464.68]],"ltp":1.79,"tv":21653.44,"id":9629022}],"tv":59263.87}]}
{"op":"mcm","clk":"4215305833","pt":1631537534198,"mc":[{"id":"1.187557985","rc":[{"trd":[[2.26,51.79]],"batl":[[0,2.26,796.14]],"ltp":2.26,"tv":37610.43,"id":5300820},{"trd":[[1.79,464.69],[1.8,357.18]],"batl":[[0,1.8,3.85]],"ltp":1.8,"tv":21653.63,"id":9629022}],"tv":59264.07}]}
{"op":"mcm","clk":"4215305976","pt":1631537536289,"mc":[{"id":"1.187557985","rc":[{"trd":[[2.26,73.97]],"batl":[[0,2.26,773.96]],"ltp":2.26,"tv":37632.61,"id":5300820},{"trd":[[1.79,492.69]],"ltp":1.79,"tv":21681.63,"id":9629022}],"tv":59314.25}]}
{"op":"mcm","clk":"4215306022","pt":1631537537226,"mc":[{"id":"1.187557985","rc":[{"trd":[[2.24,19.26]],"batl":[[0,2.24,262.69],[1,2.26,773.96],[2,2.28,847.85]],"ltp":2.24,"tv":37635.71,"id":5300820},{"trd":[[1.8,361.03]],"batl":[[0,1.81,588],[1,1.84,190.58],[2,1.85,325.44]],"ltp":1.8,"tv":21685.48,"id":9629022}],"tv":59321.2}]}
{"op":"mcm","clk":"4215306214","pt":1631537540413,"mc":[{"id":"1.187557985","rc":[{"trd":[[2.24,65.37]],"batl":[[0,2.24,216.59]],"ltp":2.24,"tv":37681.82,"id":5300820},{"trd":[[1.8,418.45]],"batb":[[0,1.79,64.83],[1,1.78,294.41],[2,1.76,338.08]],"batl":[[0,1.81,644.62]],"ltp":1.8,"tv":21742.9,"id":9629022}],"tv":59424.72}]}
{"op":"mcm","clk":"4215306444","pt":1631537544420,"mc":[{"id":"1.187557985","rc":[{"batb":[[0,1.78,237.89],[1,1.76,338.08],[2,1.66,222.68]],"batl":[[0,1.81,588],[2,1.85,321.12]],"ltp":1.8,"tv":21742.9,"id":9629022}]}]}
{"op":"mcm","clk":"4215306663","pt":1631537547643,"mc":[{"id":"1.187557985","rc":[{"trd":[[2.22,9.79]],"ltp":2.22,"tv":37685.5,"id":5300820},{"trd":[[1.81,931.55]],"batl":[[0,1.81,583.49]],"ltp":1.81,"tv":21747.41,"id":9629022}],"tv":59432.91}]}
{"op":"mcm","clk":"4215306752","pt":1631537549001,"mc":[{"id":"1.187557985","rc":[{"batb":[[0,1.8,19.14],[1,1.79,38.49],[2,1.78,237.89]],"ltp":1.81,"tv":21747.41,"id":9629022}]}]}
{"op":"mcm","clk":"4215306893","pt":1631537551303,"mc":[{"id":"1.187557985","rc":[{"trd":[[1.8,418.53]],"batb":[[0,1.8,19.11]],"ltp":1.8,"tv":21747.48,"id":9629022}],"tv":59432.98}]}
{"op":"mcm","clk":"4215306954","pt":1631537552703,"mc":[{"id":"1.187557985","rc":[{"trd":[[1.81,931.57]],"batl":[[0,1.81,583.48]],"ltp":1.81,"tv":21747.5,"id":9629022}],"tv":59433.01}]}
{"op":"mcm","clk":"4215307295","pt":1631537559246,"mc":[{"id":"1.187557985","rc":[{"batb":[[2,1.78,65.54]],"batl":[[1,1.85,321.12],[2,1.86,242.36]],"ltp":1.81,"tv":21747.5,"id":9629022}]}]}
{"op":"mcm","clk":"4215307350","pt":1631537560547,"mc":[{"id":"1.187557985","rc":[{"batb":[[2,1.78,33.96]],"ltp":1.81,"tv":21747.5,"id":9629022}]}]}
{"op":"mcm","clk":"4215307602","pt":1631537565150,"mc":[{"id":"1.187557985","rc":[{"batb":[[2,1.78,205.79]],"batl":[[1,1.84,191.09],[2,1.85,321.12]],"ltp":1.81,"tv":21747.5,"id":9629022}]}]}
{"op":"mcm","clk":"4215307716","pt":1631537567651,"mc":[{"id":"1.187557985","rc":[{"batb":[[1,2.1,31.27],[2,1.94,66.94]],"batl":[[1,2.28,26.51],[2,2.42,39]],"ltp":2.22,"tv":37685.5,"id":5300820},{"trd":[[1.81,931.68]],"batb":[[2,1.78,33.96]],"batl":[[0,1.81,583.42],[1,1.91,30],[2,2.08,7.69]],"ltp":1.81,"tv":21747.62,"id":9629022}],"tv":59433.12}]}
{"op":"mcm","clk":"4215307726","pt":1631537567858,"mc":[{"id":"1.187557985","rc":[{"batb":[[0,2.1,31.27],[1,1.94,66.94],[2,1.93,60.93]],"ltp":2.22,"tv":37685.5,"id":5300820}]}]}
{"op":"mcm","clk":"4215307825","pt":1631537569465,"mc":[{"id":"1.187557985","rc":[{"batb":[[0,1.94,66.94],[1,1.93,60.93],[2,1.92,188.42]],"batl":[[1,2.42,39],[2,2.5,145.71]],"ltp":2.22,"tv":37685.5,"id":5300820},{"batb":[[2,1.66,222.68]],"batl":[[0,2.08,7.69],[1,2.1,228.51],[2,2.12,215.72]],"ltp":1.81,"tv":21747.62,"id":9629022}]}]}
{"op":"mcm","clk":"4215307879","pt":1631537570346,"mc":[{"id":"1.187557985","rc":[{"batb":[[1,1.92,188.42],[2,1.91,283.84]],"ltp":2.22,"tv":37685.5,"id":5300820},{"batl":[[0,2.08,183.87],[1,2.1,372.52]],"ltp":1.81,"tv":21747.62,"id":9629022}]}]}
{"op":"mcm","clk":"4215308000","pt":1631537572622,"mc":[{"id":"1.187557985","rc":[{"batb":[[0,1.94,69.94],[1,1.93,5],[2,1.92,188.42]],"ltp":2.22,"tv":37685.5,"id":5300820},{"batl":[[0,2.02,4],[1,2.08,188.87],[2,2.1,372.52]],"ltp":1.81,"tv":21747.62,"id":9629022}]}]}
{"op":"mcm","clk":"4215308018","pt":1631537573039,"mc":[{"id":"1.187557985","rc":[{"batb":[[1,1.93,71.93]],"batl":[[0,2.22,10],[1,2.24,216.59],[2,2.42,39]],"ltp":2.22,"tv":37685.5,"id":5300820},{"batl":[[1,2.08,196.81]],"ltp":1.81,"tv":21747.62,"id":9629022}]}]}
{"op":"mcm","clk":"4215308122","pt":1631537575485,"mc":[{"id":"1.187557985","rc":[{"trd":[[2.22,13.87]],"batb":[[0,1.98,5],[1,1.97,4],[2,1.94,69.94]],"batl":[[0,2.22,5.92]],"ltp":2.22,"tv":37689.58,"id":5300820},{"trd":[[1.81,936.68]],"ltp":1.81,"tv":21752.62,"id":9629022}],"tv":59442.2}]}
{"op":"mcm","clk":"4215308206","pt":1631537577443,"mc":[{"id":"1.187557985","rc":[{"batb":[[0,1.81,4.39],[1,1.8,19.11],[2,1.79,38.49]],"ltp":1.81,"tv":21752.62,"id":9629022}]}]}
{"op":"mcm","clk":"4215308606","pt":1631537584255,"mc":[{"id":"1.187557985","rc":[{"batb":[[2,1.94,66.94]],"ltp":2.22,"tv":37689.58,"id":5300820},{"batl":[[1,2.1,228.51],[2,2.12,215.72]],"ltp":1.81,"tv":21752.62,"id":9629022}]}]}
{"op":"mcm","clk":"4215308758","pt":1631537586437,"mc":[{"id":"1.187557985","rc":[{"batb":[[0,1.94,66.94],[1,1.92,188.42],[2,1.91,283.84]],"ltp":2.22,"tv":37689.58,"id":5300820},{"batl":[[0,2.1,228.51],[1,2.12,215.72],[2,2.14,252.24]],"ltp":1.81,"tv":21752.62,"id":9629022}]}]}
{"op":"mcm","clk":"4215308824","pt":1631537587575,"mc":[{"id":"1.187557985","rc":[{"batb":[[1,1.93,160.68],[2,1.92,188.42]],"batl":[[0,2,162.76],[1,2.02,161.32],[2,2.18,9.17]],"ltp":2.22,"tv":37689.58,"id":5300820},{"batb":[[0,1.99,961.06],[1,1.98,932.8],[2,1.97,932.8]],"ltp":1.81,"tv":21752.62,"id":9629022}]}]}
{"op":"mcm","clk":"4215308884","pt":1631537588355,"mc":[{"id":"1.187557985","rc":[{"batb":[[2,1.92,219.69]],"batl":[[2,2.1,28.6]],"ltp":2.22,"tv":37689.58,"id":5300820},{"batb":[[2,1.97,998.32]],"batl":[[0,2.02,9.9],[1,2.08,28.86],[2,2.1,228.51]],"ltp":1.81,"tv":21752.62,"id":9629022}]}]}
{"op":"mcm","clk":"4215308995","pt":1631537590170,"mc":[{"id":"1.187557985","rc":[{"trd":[[2,210.32]],"batl":[[0,2,162.64]],"ltp":2.0,"tv":37689.7,"id":5300820},{"trd":[[2,987.99]],"batb":[[1,1.98,936.8],[2,1.97,1003.32]],"ltp":2.0,"tv":21752.74,"id":9629022}],"tv":59442.44}]}
{"op":"mcm","clk":"4215309096","pt":1631537591468,"mc":[{"id":"1.187557985","rc":[{"batl":[[0,2,418.18]],"ltp":2.0,"tv":37689.7,"id":5300820},{"batb":[[0,2,307.18],[1,1.99,1036.06],[2,1.98,936.8]],"batl":[[0,2.02,78.74],[1,2.04,73.77],[2,2.08,28.86]],"ltp":2.0,"tv":21752.74,"id":9629022}]}]}
{"op":"mcm","clk":"4215309179","pt":1631537592452,"mc":[{"id":"1.187557985","rc":[{"trd":[[2,218.07]],"batl":[[0,2,443.9],[2,2.18,9.17]],"ltp":2.0,"tv":37697.45,"id":5300820},{"trd":[[2,995.81]],"batb":[[0,2,328.83],[2,1.98,1008.82]],"ltp":2.0,"tv":21760.55,"id":9629022}],"tv":59458.01}]}
{"op":"mcm","clk":"4215309233","pt":1631537593282,"mc":[{"id":"1.187557985","rc":[{"batb":[[0,1.98,138],[1,1.94,66.94],[2,1.93,160.68]],"ltp":2.0,"tv":37697.45,"id":5300820}]}]}
{"op":"mcm","clk":"4215309377","pt":1631537595464,"mc":[{"id":"1.187557985","rc":[{"batl":[[2,2.06,29.13]],"ltp":2.0,"tv":37697.45,"id":5300820}]}]}
{"op":"mcm","clk":"4215309448","pt":1631537596448,"mc":[{"id":"1.187557985","rc":[{"batb":[[0,2,404.43],[1,1.99,961.06],[2,1.98,936.8]],"batl":[[1,2.08,28.86],[2,2.1,228.51]],"ltp":2.0,"tv":21760.55,"id":9629022}]}]}
{"op":"mcm","clk":"4215309523","pt":1631537597860,"mc":[{"id":"1.187557985","rc":[{"trd":[[1.98,2.8]],"batb":[[0,1.98,137.03]],"ltp":1.98,"tv":37699.39,"id":5300820}],"tv":59459.95}]}
{"op":"mcm","clk":"4215309578","pt":1631537598899,"mc":[{"id":"1.187557985","rc":[{"trd":[[2,995.84]],"batb":[[0,2,404.41]],"ltp":2.0,"tv":21760.59,"id":9629022}],"tv":59459.99}]}
{"op":"mcm","clk":"4215309739","pt":1631537601396,"mc":[{"id":"1.187557985","rc":[{"batb":[[1,1.92,31.27],[2,1.73,173.36]],"batl":[[0,2.06,29.13],[1,2.22,175.2],[2,2.24,397.82]],"ltp":1.98,"tv":37699.39,"id":5300820},{"trd":[[2,996.03]],"batb":[[0,2,123.22],[1,1.94,30.94],[2,1.82,277.39]],"batl":[[0,2.02,68.84],[2,2.38,6.25]],"ltp":2.0,"tv":21760.78,"id":9629022}],"tv":59460.17}]}
{"op":"mcm","clk":"4215309802","pt":1631537602499,"mc":[{"id":"1.187557985","rc":[{"batb":[[0,1.73,173.36],[1,1.71,272.93],[2,1.7,302.6]],"batl":[[0,2.22,175.2],[1,2.24,397.82],[2,2.26,223.07]],"ltp":1.98,"tv":37699.39,"id":5300820},{"batb":[[0,1.82,277.39],[1,1.81,230.86],[2,1.8,325.88]],"batl":[[0,2.38,6.25],[1,2.4,215.52],[2,2.42,168.3]],"ltp":2.0,"tv":21760.78,"id":9629022}]}]}
{"op":"mcm","clk":"4215309823","pt":1631537602863,"mc":[{"id":"1.187557985","rc":[{"batb":[[0,1.73,96.23]],"ltp":1.98,"tv":37699.39,"id":5300820},{"batl":[[0,2.4,215.52],[1,2.42,168.3],[2,2.44,206.97]],"ltp":2.0,"tv":21760.78,"id":9629022}]}]}
{"op":"mcm","clk":"4215309923","pt":1631537604571,"mc":[{"id":"1.187557985","rc":[{"batb":[[1,1.71,534.2]],"batl":[[2,2.26,357.78]],"ltp":1.98,"tv":37699.39,"id":5300820}]}]}
{"op":"mcm","clk":"4215309988","pt":1631537605660,"mc":[{"id":"1.187557985","rc":[{"batb":[[0,1.73,101.23],[1,1.72,6],[2,1.71,534.2]],"ltp":1.98,"tv":37699.39,"id":5300820},{"batl":[[0,2.38,4],[1,2.4,215.52],[2,2.42,168.3]],"ltp":2.0,"tv":21760.78,"id":9629022}]}]}
{"op":"mcm","clk":"4215310025","pt":1631537606389,"mc":[{"id":"1.187557985","rc":[{"batl":[[2,2.26,223.07]],"ltp":1.98,"tv":37699.39,"id":5300820}]}]}
{"op":"mcm","clk":"4215310044","pt":1631537606699,"mc":[{"id":"1.187557985","rc":[{"batl":[[0,2.24,216.59],[1,2.72,244.88],[2,3.4,22]],"ltp":1.98,"tv":37699.39,"id":5300820},{"batb":[[0,1.78,90.88],[1,1.62,4],[2,1.51,52.93]],"ltp":2.0,"tv":21760.78,"id":9629022}]}]}
{"op":"mcm","clk":"4215310144","pt":1631537608665,"mc":[{"id":"1.187557985","rc":[{"batb":[[0,1.73,96.23],[1,1.71,534.2],[2,1.7,302.6]],"batl":[[0,1.81,3342.36],[1,1.9,15.2],[2,2.24,216.59]],"ltp":1.98,"tv":37699.39,"id":5300820},{"batl":[[0,2.4,215.52],[1,2.42,168.3],[2,2.44,206.97]],"ltp":2.0,"tv":21760.78,"id":9629022}]}]}
{"op":"mcm","clk":"4215310192","pt":1631537609601,"mc":[{"id":"1.187557985","rc":[{"batl":[[0,1.77,188.87],[1,1.78,1074.44],[2,1.79,1277.76]],"ltp":1.98,"tv":37699.39,"id":5300820},{"batb":[[0,1.97,8.1],[1,1.95,4.09],[2,1.78,90.88]],"ltp":2.0,"tv":21760.78,"id":9629022}]}]}
{"op":"mcm","clk":"4215310256","pt":1631537610587,"mc":[{"id":"1.187557985","rc":[{"trd":[[1.77,33.96]],"batl":[[0,1.77,177.57]],"ltp":1.77,"tv":37710.69,"id":5300820},{"trd":[[2.28,77.76]],"batb":[[0,2.24,89.79],[1,2.02,653.37],[2,2,123.26]],"ltp":2.28,"tv":21769.55,"id":9629022}],"tv":59480.24}]}
{"op":"mcm","clk":"4215310333","pt":1631537611587,"mc":[{"id":"1.187557985","rc":[{"trd":[[1.77,102.32]],"batb":[[1,1.71,272.93]],"batl":[[0,1.77,143.39]],"ltp":1.77,"tv":37779.05,"id":5300820}],"tv":59548.6}]}
{"op":"mcm","clk":"4215310376","pt":1631537612467,"mc":[{"id":"1.187557985","rc":[{"trd":[[1.77,140.76]],"batl":[[0,1.77,124.17]],"ltp":1.77,"tv":37817.49,"id":5300820},{"batb":[[0,2.26,4],[1,2.24,92.79],[2,2.22,3]],"ltp":2.28,"tv":21769.55,"id":9629022}],"tv":59587.04}]}
{"op":"mcm","clk":"4215310482","pt":1631537614602,"mc":[{"id":"1.187557985","rc":[{"trd":[[1.75,1109.24]],"batb":[[0,1.74,80.17],[1,1.73,157.47],[2,1.72,156.04]],"batl":[[0,1.75,50.7],[1,1.76,60.51],[2,1.77,204.32]],"ltp":1.75,"tv":37823.08,"id":5300820},{"trd":[[2.32,83.03]],"batb":[[0,2.26,38.35]],"ltp":2.32,"tv":21770.96,"id":9629022}],"tv":59594.04}]}
{"op":"mcm","clk":"4215310561","pt":1631537615593,"mc":[{"id":"1.187557985","rc":[{"trd":[[1.75,1210.63],[1.76,691.68]],"batb":[[2,1.72,219.8]],"batl":[[0,1.77,204.32],[1,1.78,1148.92],[2,1.79,1277.76]],"ltp":1.76,"tv":38045.48,"id":5300820},{"batb":[[0,2.26,4]],"batl":[[0,2.38,25.53],[1,2.4,215.52],[2,2.42,168.3]],"ltp":2.32,"tv":21770.96,"id":9629022}],"tv":59816.44}]}
{"op":"mcm","clk":"4215310590","pt":1631537616010,"mc":[{"id":"1.187557985","rc":[{"batb":[[1,1.73,192.58]],"ltp":1.76,"tv":38045.48,"id":5300820}]}]}
{"op":"mcm","clk":"4215310763","pt":1631537618603,"mc":[{"id":"1.187557985","rc":[{"batb":[[1,1.73,131.34],[2,1.72,156.04]],"batl":[[0,1.76,61.47],[1,1.77,139.25],[2,1.78,1074.44]],"ltp":1.76,"tv":38045.48,"id":5300820},{"batb":[[0,2.28,34.35],[1,2.26,4],[2,2.24,92.79]],"ltp":2.32,"tv":21770.96,"id":9629022}]}]}
{"op":"mcm","clk":"4215310793","pt":1631537619123,"mc":[{"id":"1.187557985","rc":[{"trd":[[1.74,867.66]],"batb":[[0,1.74,60.63]],"batl":[[0,1.76,100.47]],"ltp":1.74,"tv":38084.56,"id":5300820}],"tv":59855.52}]}
{"op":"mcm","clk":"4215310866","pt":1631537620525,"mc":[{"id":"1.187557985","rc":[{"trd":[[1.76,691.73]],"batl":[[0,1.76,100.41]],"ltp":1.76,"tv":38084.61,"id":5300820},{"trd":[[2.3,0.04]],"ltp":2.3,"tv":21771.0,"id":9629022}],"tv":59855.61}]}
{"op":"mcm","clk":"4215310925","pt":1631537621412,"mc":[{"id":"1.187557985","rc":[{"trd":[[1.76,691.92]],"batb":[[0,1.74,127.63]],"batl":[[0,1.76,100.32]],"ltp":1.76,"tv":38084.8,"id":5300820},{"batb":[[0,2.24,92.79],[1,2.22,3],[2,2.18,25.42]],"ltp":2.3,"tv":21771.0,"id":9629022}],"tv":59855.8}]}
{"op":"mcm","clk":"4215311054","pt":1631537623595,"mc":[{"id":"1.187557985","rc":[{"batb":[[2,1.68,4]],"batl":[[1,1.8,4],[2,2.24,216.59]],"ltp":1.76,"tv":38084.8,"id":5300820},{"batb":[[1,2.18,25.42],[2,2,123.26]],"batl":[[1,2.74,5.48],[2,2.76,5.02]],"ltp":2.3,"tv":21771.0,"id":9629022}]}]}
{"op":"mcm","clk":"4215311135","pt":1631537624585,"mc":[{"id":"1.187557985","rc":[{"batb":[[1,1.73,35.11],[2,1.58,207.61]],"batl":[[1,2.24,216.59],[2,2.42,290.48]],"ltp":1.76,"tv":38084.8,"id":5300820},{"batb":[[0,2.26,34.35]],"ltp":2.3,"tv":21771.0,"id":9629022}]}]}
{"op":"mcm","clk":"4215311192","pt":1631537625519,"mc":[{"id":"1.187557985","rc":[{"trd":[[1.76,692.18]],"batb":[[0,1.58,132.55],[1,1.57,77.57],[2,1.55,426.3]],"batl":[[0,1.76,38.87]],"ltp":1.76,"tv":38085.06,"id":5300820},{"batb":[[0,2,123.26],[1,1.81,8.32],[2,1.8,4.14]],"batl":[[0,2.76,5.02],[1,2.98,5.25],[2,3,4.85]],"ltp":2.3,"tv":21771.0,"id":9629022}],"tv":59856.06}]}
{"op":"mcm","clk":"4215311257","pt":1631537626511,"mc":[{"id":"1.187557985","rc":[{"trd":[[1.76,692.35]],"batb":[[1,1.57,260.59],[2,1.56,189.8]],"batl":[[0,1.76,38.78],[1,1.95,146.08],[2,1.97,173.88]],"ltp":1.76,"tv":38085.24,"id":5300820}],"tv":59856.24}]}
{"op":"mcm","clk":"4215311308","pt":1631537627237,"mc":[{"id":"1.187557985","rc":[{"trd":[[1.76,731.13],[1.78,35.68]],"batl":[[0,1.95,146.08],[1,1.97,173.88],[2,2.24,216.59]],"ltp":1.78,"tv":38127.88,"id":5300820},{"trd":[[2.28,80.78],[2.3,29.72]],"batl":[[0,2.28,67.3],[1,2.76,5.02],[2,2.98,5.25]],"ltp":2.28,"tv":21803.7,"id":9629022}],"tv":59931.58}]}
{"op":"mcm","clk":"4215311409","pt":1631537628540,"mc":[{"id":"1.187557985","rc":[{"trd":[[1.78,60.53]],"batb":[[0,1.58,132.67]],"ltp":1.78,"tv":38152.73,"id":5300820},{"trd":[[2.28,100.18]],"batl":[[0,2.28,47.9]],"ltp":2.28,"tv":21823.1,"id":9629022}],"tv":59975.83}]}
{"op":"mcm","clk":"4215311445","pt":1631537629014,"mc":[{"id":"1.187557985","rc":[{"trd":[[1.78,62.86]],"batb":[[0,1.58,138.68],[1,1.57,265.59]],"ltp":1.78,"tv":38155.06,"id":5300820},{"trd":[[2.28,101.99]],"batl":[[0,2.28,46.09],[1,2.74,3],[2,2.76,5.02]],"ltp":2.28,"tv":21824.91,"id":9629022}],"tv":59979.97}]}
{"op":"mcm","clk":"4215311644","pt":1631537632115,"mc":[{"id":"1.187557985","rc":[{"trd":[[1.78,62.99]],"batb":[[0,1.58,138.76]],"ltp":1.78,"tv":38155.19,"id":5300820},{"trd":[[2.28,102.09]],"batl":[[0,2.28,45.99]],"ltp":2.28,"tv":21825.01,"id":9629022}],"tv":59980.2}]}
{"op":"mcm","clk":"4215311694","pt":1631537633000,"mc":[{"id":"1.187557985","rc":[{"batb":[[0,1.58,138.67]],"ltp":1.78,"tv":38155.19,"id":5300820}]}]}
{"op":"mcm","clk":"4215311889","pt":1631537636420,"mc":[{"id":"1.187557985","rc":[{"trd":[[1.77,140.83],[1.78,122.06]],"batb":[[0,1.58,138.55]],"batl":[[0,2.24,216.59],[1,2.42,290.48],[2,3.4,22]],"ltp":1.77,"tv":38214.33,"id":5300820},{"trd":[[2.28,148.08]],"batl":[[0,2.74,3],[1,2.76,5.02],[2,2.98,5.25]],"ltp":2.28,"tv":21871.0,"id":9629022}],"tv":60085.33}]}
{"op":"mcm","clk":"4215311973","pt":1631537637512,"mc":[{"id":"1.187557985","rc":[{"batb":[[0,1.58,132.55],[1,1.57,260.59]],"ltp":1.77,"tv":38214.33,"id":5300820},{"batl":[[0,2.76,5.02],[1,2.98,5.25],[2,3,4.85]],"ltp":2.28,"tv":21871.0,"id":9629022}]}]}
{"op":"mcm","clk":"4215312056","pt":1631537638652,"mc":[{"id":"1.187557985","rc":[{"batb":[[0,1.58,221.61]],"batl":[[0,1.63,2346.62],[1,1.64,2277.6],[2,1.65,2277.6]],"ltp":1.77,"tv":38214.33,"id":5300820},{"batl":[[0,2.74,5.25],[1,2.76,5.02],[2,2.84,1346.82]],"ltp":2.28,"tv":21871.0,"id":9629022}]}]}
{"op":"mcm","clk":"4215312127","pt":1631537639636,"mc":[{"id":"1.187557985","rc":[{"trd":[[1.61,93.75]],"batb":[[0,1.58,132.55]],"batl":[[0,1.61,158.36],[1,1.62,164.3],[2,1.63,1173.32]],"ltp":1.61,"tv":38227.14,"id":5300820},{"trd":[[2.62,123.75]],"batb":[[0,2.56,62.51],[1,2.36,78.24],[2,2.06,728.42]],"batl":[[0,2.76,5.02],[1,2.84,673.42],[2,2.86,359.48]],"ltp":2.62,"tv":21878.87,"id":9629022}],"tv":60106.01}]}
{"op":"mcm","clk":"4215312205","pt":1631537640627,"mc":[{"id":"1.187557985","rc":[{"trd":[[1.61,208.53]],"batl":[[0,1.61,81.68]],"ltp":1.61,"tv":38341.92,"id":5300820},{"trd":[[2.62,147.46]],"ltp":2.62,"tv":21902.58,"id":9629022}],"tv":60244.5}]}
{"op":"mcm","clk":"4215312270","pt":1631537641623,"mc":[{"id":"1.187557985","rc":[{"batl":[[0,1.62,164.3],[1,1.63,1173.32],[2,1.64,1143.8]],"ltp":1.61,"tv":38341.92,"id":5300820}]}]}
{"op":"mcm","clk":"4215312331","pt":1631537642368,"mc":[{"id":"1.187557985","rc":[{"trd":[[1.62,517.59]],"batl":[[0,1.62,128.84]],"ltp":1.62,"tv":38412.84,"id":5300820}],"tv":60315.42}]}
{"op":"mcm","clk":"4215312433","pt":1631537643657,"mc":[{"id":"1.187557985","rc":[{"batb":[[0,1.59,106.24],[1,1.58,132.55],[2,1.57,260.59]],"batl":[[0,1.6,73.26],[1,1.61,470.5],[2,1.62,128.84]],"ltp":1.62,"tv":38412.84,"id":5300820},{"batb":[[0,2.62,250.72],[1,2.56,62.51],[2,2.36,78.24]],"batl":[[1,2.8,22.36],[2,2.84,673.42]],"ltp":2.62,"tv":21902.58,"id":9629022}]}]}
{"op":"mcm","clk":"4215312508","pt":1631537644643,"mc":[{"id":"1.187557985","rc":[{"trd":[[1.6,1503.02],[1.61,222.66]],"batb":[[1,1.58,193.93],[2,1.57,321.99]],"batl":[[0,1.61,463.44],[1,1.62,375.65],[2,1.63,1333.41]],"ltp":1.61,"tv":38573.49,"id":5300820},{"batb":[[2,2.52,19.73]],"ltp":2.62,"tv":21902.58,"id":9629022}],"tv":60476.07}]}
{"op":"mcm","clk":"4215312571","pt":1631537645432,"mc":[{"id":"1.187557985","rc":[{"batb":[[2,1.57,346.48]],"ltp":1.61,"tv":38573.49,"id":5300820},{"batb":[[2,2.36,78.24]],"ltp":2.62,"tv":21902.58,"id":9629022}]}]}
{"op":"mcm","clk":"4215312713","pt":1631537647359,"mc":[{"id":"1.187557985","rc":[{"batb":[[0,2.62,269.63]],"ltp":2.62,"tv":21902.58,"id":9629022}]}]}
{"op":"mcm","clk":"4215312780","pt":1631537648141,"mc":[{"id":"1.187557985","rc":[{"batb":[[0,1.59,236.24],[1,1.58,132.55]],"batl":[[0,1.6,63.59],[1,1.61,400.95],[2,1.62,375.65]],"ltp":1.61,"tv":38573.49,"id":5300820},{"batb":[[1,2.56,81.74]],"ltp":2.62,"tv":21902.58,"id":9629022}]}]}
{"op":"mcm","clk":"4215312875","pt":1631537649645,"mc":[{"id":"1.187557985","rc":[{"trd":[[1.59,76.5]],"batb":[[0,1.59,236.15]],"ltp":1.59,"tv":38573.68,"id":5300820}],"tv":60476.26}]}
{"op":"mcm","clk":"4215312927","pt":1631537650475,"mc":[{"id":"1.187557985","rc":[{"trd":[[1.6,1503.17]],"batb":[[2,1.55,40.45]],"batl":[[0,1.6,63.52],[1,1.64,30],[2,1.99,5]],"ltp":1.6,"tv":38573.83,"id":5300820},{"batb":[[0,2.56,81.74],[1,2.36,78.24],[2,2.02,3]],"batl":[[0,2.8,22.36],[1,2.94,5.25],[2,2.98,5.25]],"ltp":2.62,"tv":21902.58,"id":9629022}],"tv":60476.41}]}
{"op":"mcm","clk":"4215312995","pt":1631537651364,"mc":[{"id":"1.187557985","rc":[{"trd":[[1.59,151.55],[1.6,1507.82]],"batb":[[0,1.59,198.65],[1,1.53,27.89],[2,1.52,417.6]],"batl":[[0,1.6,61.19],[1,1.99,5],[2,2,4]],"ltp":1.59,"tv":38653.53,"id":5300820},{"batb":[[0,2.36,78.24],[1,2.02,3],[2,2,3]],"batl":[[0,2.94,5.25],[1,2.98,5.25],[2,3,4.85]],"ltp":2.62,"tv":21902.58,"id":9629022}],"tv":60556.11}]}
{"op":"mcm","clk":"4215313078","pt":1631537652465,"mc":[{"id":"1.187557985","rc":[{"trd":[[1.59,288.82],[1.6,1555.39]],"batb":[[0,1.53,27.89],[1,1.52,417.6],[2,1.51,77.99]],"batl":[[0,1.55,654.6],[1,1.6,37.41],[2,1.99,5]],"ltp":1.59,"tv":38838.36,"id":5300820},{"batb":[[2,1.81,8.32]],"ltp":2.62,"tv":21902.58,"id":9629022}],"tv":60740.94}]}
{"op":"mcm","clk":"4215313155","pt":1631537653564,"mc":[{"id":"1.187557985","rc":[{"batl":[[1,1.59,138.63],[2,1.6,37.41]],"ltp":1.59,"tv":38838.36,"id":5300820}]}]}
{"op":"mcm","clk":"4215313191","pt":1631537654040,"mc":[{"id":"1.187557985","rc":[{"batl":[[2,1.99,5]],"ltp":1.59,"tv":38838.36,"id":5300820}]}]}
{"op":"mcm","clk":"4215313313","pt":1631537655656,"mc":[{"id":"1.187557985","rc":[{"trd":[[1.55,2380.51]],"batb":[[0,1.53,34.89],[1,1.52,424.6]],"batl":[[0,1.55,497.41]],"ltp":1.55,"tv":39152.78,"id":5300820},{"batl":[[0,2.9,3],[1,2.94,5.25],[2,2.98,5.25]],"ltp":2.62,"tv":21902.58,"id":9629022}],"tv":61055.36}]}
{"op":"mcm","clk":"4215313385","pt":1631537656649,"mc":[{"id":"1.187557985","rc":[{"trd":[[1.55,2388.16]],"batl":[[0,1.55,493.59],[1,1.59,6.6],[2,1.65,4]],"ltp":1.55,"tv":39160.43,"id":5300820}],"tv":61063.01}]}
{"op":"mcm","clk":"4215313459","pt":1631537657638,"mc":[{"id":"1.187557985","rc":[{"trd":[[1.54,1170.14],[1.55,3109.09]],"batb":[[0,1.54,100.75],[1,1.53,34.89],[2,1.52,424.6]],"batl":[[0,1.55,113.15],[1,1.99,5],[2,2.22,333.55]],"ltp":1.54,"tv":40153.91,"id":5300820},{"trd":[[2.8,551.58]],"batb":[[0,2.38,102.39],[1,2.36,78.24],[2,2.02,3]],"ltp":2.8,"tv":21924.74,"id":9629022}],"tv":62078.65}]}
{"op":"mcm","clk":"4215313486","pt":1631537658152,"mc":[{"id":"1.187557985","rc":[{"trd":[[1.55,3151.5]],"batl":[[0,1.55,91.94],[1,1.59,11.62],[2,1.99,5]],"ltp":1.55,"tv":40196.32,"id":5300820}],"tv":62121.06}]}
{"op":"mcm","clk":"4215313593","pt":1631537659359,"mc":[{"id":"1.187557985","rc":[{"trd":[[1.53,3528.34],[1.54,1371.66],[1.55,3249.69]],"batb":[[0,1.53,82.5],[1,1.52,424.6],[2,1.51,77.99]],"batl":[[0,1.55,42.84]],"ltp":1.55,"tv":40656.83,"id":5300820},{"trd":[[2.8,551.6]],"batb":[[0,2.36,78.24],[1,2.02,3],[2,1.81,8.32]],"ltp":2.8,"tv":21924.76,"id":9629022}],"tv":62581.59}]}
{"op":"mcm","clk":"4215313682","pt":1631537660459,"mc":[{"id":"1.187557985","rc":[{"batb":[[0,1.54,45.18],[1,1.53,82.5],[2,1.52,424.6]],"batl":[[1,1.58,182.66],[2,1.59,11.62]],"ltp":1.55,"tv":40656.83,"id":5300820}]}]}
{"op":"mcm","clk":"4215313721","pt":1631537660983,"mc":[{"id":"1.187557985","rc":[{"batb":[[0,1.52,424.6],[1,1.51,77.99],[2,1.5,80]],"batl":[[1,1.59,11.62],[2,1.99,5]],"ltp":1.55,"tv":40656.83,"id":5300820}]}]}
{"op":"mcm","clk":"4215313868","pt":1631537662650,"mc":[{"id":"1.187557985","rc":[{"trd":[[1.55,3290.58]],"batl":[[0,1.55,11.94]],"ltp":1.55,"tv":40697.73,"id":5300820},{"trd":[[2.8,563.17]],"ltp":2.8,"tv":21936.33,"id":9629022}],"tv":62634.06}]}
{"op":"mcm","clk":"4215313914","pt":1631537663376,"mc":[{"id":"1.187557985","rc":[{"trd":[[1.55,3292.48]],"batl":[[0,1.55,10.05],[2,1.69,279.89]],"ltp":1.55,"tv":40699.62,"id":5300820},{"trd":[[2.8,564.22]],"ltp":2.8,"tv":21937.37,"id":9629022}],"tv":62637.0}]}
{"op":"mcm","clk":"4215313971","pt":1631537664153,"mc":[{"id":"1.187557985","rc":[{"batb":[[1,1.51,83.99]],"ltp":1.55,"tv":40699.62,"id":5300820},{"batl":[[0,2.88,3],[1,2.9,3],[2,2.94,5.25]],"ltp":2.8,"tv":21937.37,"id":9629022}]}]}
{"op":"mcm","clk":"4215314053","pt":1631537665352,"mc":[{"id":"1.187557985","rc":[{"batl":[[0,1.59,11.62],[1,1.69,279.89],[2,1.71,274.7]],"ltp":1.55,"tv":40699.62,"id":5300820}]}]}
{"op":"mcm","clk":"4215314125","pt":1631537666391,"mc":[{"id":"1.187557985","rc":[{"batl":[[0,2.8,60],[1,2.88,3],[2,2.9,3]],"ltp":2.8,"tv":21937.37,"id":9629022}]}]}
{"op":"mcm","clk":"4215314222","pt":1631537667793,"mc":[{"id":"1.187557985","rc":[{"trd":[[1.55,3292.55]],"ltp":1.55,"tv":40699.7,"id":5300820},{"trd":[[2.8,564.26]],"batl":[[0,2.8,59.96]],"ltp":2.8,"tv":21937.41,"id":9629022}],"tv":62637.12}]}
{"op":"mcm","clk":"4215314335","pt":1631537669355,"mc":[{"id":"1.187557985","rc":[{"trd":[[1.55,3292.73]],"batl":[[1,1.99,5],[2,2.22,333.55]],"ltp":1.55,"tv":40699.88,"id":5300820},{"trd":[[2.8,564.36]],"batl":[[0,2.8,59.86]],"ltp":2.8,"tv":21937.51,"id":9629022}],"tv":62637.4}]}
{"op":"mcm","clk":"4215314450","pt":1631537670666,"mc":[{"id":"1.187557985","rc":[{"trd":[[1.55,3307.06]],"ltp":1.55,"tv":40714.21,"id":5300820},{"trd":[[2.8,569.3]],"batl":[[0,2.8,54.92]],"ltp":2.8,"tv":21942.45,"id":9629022}],"tv":62656.67}]}
{"op":"mcm","clk":"4215314513","pt":1631537671500,"mc":[{"id":"1.187557985","rc":[{"trd":[[1.55,3406.29]],"batb":[[0,1.49,164.6],[1,1.48,90.76],[2,1.47,388.41]],"batl":[[2,2.24,216.59]],"ltp":1.55,"tv":40813.43,"id":5300820},{"trd":[[2.8,624.22]],"batl":[[0,3.1,4.45],[1,2.88,0],[2,2.9,0]],"ltp":2.8,"tv":21997.37,"id":9629022}],"tv":62810.81}]}
{"op":"mcm","clk":"4215314607","pt":1631537672592,"mc":[{"id":"1.187557985","rc":[{"batl":[[0,1.52,363.79],[1,1.53,203.97],[2,1.59,11.62]],"ltp":1.55,"tv":40813.43,"id":5300820},{"batb":[[0,2.86,668.7],[1,2.84,649.04],[2,2.82,649.04]],"batl":[[1,3.2,328.71],[2,3.25,319.04]],"ltp":2.8,"tv":21997.37,"id":9629022}]}]}
{"op":"mcm","clk":"4215314665","pt":1631537673475,"mc":[{"id":"1.187557985","rc":[{"trd":[[1.52,3699.6]],"batb":[[0,1.51,42],[1,1.49,164.6],[2,1.48,90.76]],"batl":[[0,1.52,349.77],[2,1.59,41.62]],"ltp":1.52,"tv":40827.45,"id":5300820},{"trd":[[2.92,143.81]],"batb":[[2,2.82,697.32]],"ltp":2.92,"tv":22004.67,"id":9629022}],"tv":62832.13}]}
{"op":"mcm","clk":"4215314734","pt":1631537674572,"mc":[{"id":"1.187557985","rc":[{"trd":[[1.52,3711.6]],"batb":[[0,1.49,164.6],[1,1.48,90.76],[2,1.47,388.41]],"batl":[[0,1.52,343.77],[2,1.55,7]],"ltp":1.52,"tv":40839.45,"id":5300820}],"tv":62844.13}]}
{"op":"mcm","clk":"4215314874","pt":1631537676605,"mc":[{"id":"1.187557985","rc":[{"batb":[[0,1.5,251.7],[1,1.49,164.6],[2,1.48,90.76]],"batl":[[0,1.51,66.41],[1,1.52,778.18],[2,1.53,203.97]],"ltp":1.52,"tv":40839.45,"id":5300820},{"batb":[[0,2.92,226.12],[1,2.86,668.7],[2,2.84,649.04]],"ltp":2.92,"tv":22004.67,"id":9629022}]}]}
{"op":"mcm","clk":"4215314930","pt":1631537677284,"mc":[{"id":"1.187557985","rc":[{"batb":[[0,1.5,224.3],[1,1.49,239.27]],"batl":[[1,1.52,943.01]],"ltp":1.52,"tv":40839.45,"id":5300820}]}]}
{"op":"mcm","clk":"4215314976","pt":1631537677807,"mc":[{"id":"1.187557985","rc":[{"batl":[[0,3,21.21],[1,3.1,4.45],[2,3.2,328.71]],"ltp":2.92,"tv":22004.67,"id":9629022}]}]}
{"op":"mcm","clk":"4215315071","pt":1631537679372,"mc":[{"id":"1.187557985","rc":[{"batb":[[2,1.48,263.54]],"ltp":1.52,"tv":40839.45,"id":5300820},{"batl":[[2,3.15,219.42]],"ltp":2.92,"tv":22004.67,"id":9629022}]}]}
{"op":"mcm","clk":"4215315145","pt":1631537680470,"mc":[{"id":"1.187557985","rc":[{"trd":[[1.5,1193.69],[1.51,1931.82]],"batb":[[0,1.5,217.7]],"batl":[[0,1.51,57.47]],"ltp":1.5,"tv":40870.52,"id":5300820}],"tv":62875.2}]}
{"op":"mcm","clk":"4215315220","pt":1631537681509,"mc":[{"id":"1.187557985","rc":[{"batb":[[0,1.5,479.7],[2,1.48,90.76]],"batl":[[0,1.51,506.36],[1,1.52,713.14],[2,1.54,20]],"ltp":1.5,"tv":40870.52,"id":5300820},{"batb":[[0,2.96,228.99],[1,2.92,226.12],[2,2.86,668.7]],"ltp":2.92,"tv":22004.67,"id":9629022}]}]}
{"op":"mcm","clk":"4215315287","pt":1631537682497,"mc":[{"id":"1.187557985","rc":[{"trd":[[1.51,2183.01]],"batb":[[0,1.5,377.9],[1,1.49,164.6]],"batl":[[0,1.51,323.3],[1,1.52,717.99]],"ltp":1.51,"tv":41121.71,"id":5300820},{"trd":[[2.96,317.38]],"batb":[[0,2.96,227.8]],"ltp":2.96,"tv":22007.06,"id":9629022}],"tv":63128.77}]}
{"op":"mcm","clk":"4215315361","pt":1631537683590,"mc":[{"id":"1.187557985","rc":[{"trd":[[1.5,1949.55]],"batb":[[0,1.49,164.6],[1,1.48,90.76],[2,1.47,712.69]],"batl":[[0,1.5,304.65],[1,1.51,323.3],[2,1.52,717.99]],"ltp":1.5,"tv":41877.57,"id":5300820},{"trd":[[3,471.28]],"batl":[[0,3.1,4.45],[1,3.15,219.42],[2,3.2,328.71]],"ltp":3.0,"tv":22049.48,"id":9629022}],"tv":63927.05}]}
{"op":"mcm","clk":"4215315435","pt":1631537684588,"mc":[{"id":"1.187557985","rc":[{"trd":[[1.49,1509.59],[1.5,1949.57]],"batb":[[0,1.49,67.9],[2,1.47,831.76]],"batl":[[0,1.5,304.64],[1,1.51,505.81],[2,1.52,644.97]],"ltp":1.49,"tv":42070.95,"id":5300820}],"tv":64120.43}]}
{"op":"mcm","clk":"4215315471","pt":1631537685102,"mc":[{"id":"1.187557985","rc":[{"trd":[[1.49,1645.69]],"batb":[[0,1.48,90.76],[1,1.47,831.76],[2,1.46,693.03]],"batl":[[0,1.49,38.11],[1,1.5,304.64],[2,1.51,505.81]],"ltp":1.49,"tv":42207.05,"id":5300820},{"trd":[[3,471.48]],"ltp":3.0,"tv":22049.67,"id":9629022}],"tv":64256.73}]}
{"op":"mcm","clk":"4215315573","pt":1631537686615,"mc":[{"id":"1.187557985","rc":[{"trd":[[1.49,1646.06]],"batl":[[0,1.49,37.92]],"ltp":1.49,"tv":42207.43,"id":5300820}],"tv":64257.1}]}
{"op":"mcm","clk":"4215315618","pt":1631537687290,"mc":[{"id":"1.187557985","rc":[{"trd":[[1.49,1721.93],[1.5,2078.36]],"batb":[[2,1.46,737.26]],"batl":[[0,1.5,264.65],[1,1.51,505.81],[2,1.52,644.97]],"ltp":1.5,"tv":42412.09,"id":5300820},{"batl":[[1,3.15,239.87]],"ltp":3.0,"tv":22049.67,"id":9629022}],"tv":64461.76}]}
{"op":"mcm","clk":"4215315731","pt":1631537689008,"mc":[{"id":"1.187557985","rc":[{"trd":[[1.5,2078.54]],"batl":[[0,1.5,264.56]],"ltp":1.5,"tv":42412.27,"id":5300820}],"tv":64461.95}]}
{"op":"mcm","clk":"4215315838","pt":1631537690513,"mc":[{"id":"1.187557985","rc":[{"trd":[[1.5,2085.89]],"batl":[[0,1.5,257.21]],"ltp":1.5,"tv":42419.61,"id":5300820},{"trd":[[3,475.15]],"ltp":3.0,"tv":22053.34,"id":9629022}],"tv":64472.96}]}
{"op":"mcm","clk":"4215315907","pt":1631537691516,"mc":[{"id":"1.187557985","rc":[{"batb":[[0,1.48,294.76]],"batl":[[0,1.5,271.68]],"ltp":1.5,"tv":42419.61,"id":5300820}]}]}
{"op":"mcm","clk":"4215315983","pt":1631537692402,"mc":[{"id":"1.187557985","rc":[{"trd":[[1.48,1508.96]],"batb":[[0,1.48,264.76]],"ltp":1.48,"tv":42479.61,"id":5300820}],"tv":64532.96}]}
{"op":"mcm","clk":"4215316060","pt":1631537693594,"mc":[{"id":"1.187557985","rc":[{"trd":[[1.5,2086.33]],"batl":[[0,1.5,271.46]],"ltp":1.5,"tv":42480.06,"id":5300820}],"tv":64533.4}]}
{"op":"mcm","clk":"4215316124","pt":1631537694631,"mc":[{"id":"1.187557985","rc":[{"trd":[[1.48,1513.6],[1.5,2117.01]],"batb":[[0,1.48,262.44]],"batl":[[0,1.5,256.12]],"ltp":1.5,"tv":42515.38,"id":5300820}],"tv":64568.73}]}
{"op":"mcm","clk":"4215316133","pt":1631537694695,"mc":[{"id":"1.187557985","rc":[{"trd":[[1.5,2117.03]],"batl":[[0,1.5,256.1]],"ltp":1.5,"tv":42515.4,"id":5300820},{"trd":[[3,475.16]],"batb":[[2,2.88,15.95]],"ltp":3.0,"tv":22053.35,"id":9629022}],"tv":64568.76}]}
{"op":"mcm","clk":"4215316243","pt":1631537696607,"mc":[{"id":"1.187557985","rc":[{"trd":[[1.47,584.25],[1.48,2038.48]],"batb":[[0,1.47,764.2],[1,1.46,295.55],[2,1.43,642.22]],"ltp":1.47,"tv":43175.4,"id":5300820}],"tv":65228.76}]}
{"op":"mcm","clk":"4215316340","pt":1631537697702,"mc":[{"id":"1.187557985","rc":[{"batl":[[0,1.5,256.47]],"ltp":1.47,"tv":43175.4,"id":5300820}]}]}
{"op":"mcm","clk":"4215316466","pt":1631537699517,"mc":[{"id":"1.187557985","rc":[{"batl":[[0,1.5,242.01]],"ltp":1.47,"tv":43175.4,"id":5300820}]}]}
{"op":"mcm","clk":"4215316546","pt":1631537700615,"mc":[{"id":"1.187557985","rc":[{"batb":[[0,1.47,470.19],[1,1.46,44.23]],"batl":[[0,1.5,241.91],[1,1.51,323.3],[2,1.52,434.41]],"ltp":1.47,"tv":43175.4,"id":5300820},{"batl":[[0,3.15,239.87],[1,3.5,4.33],[2,3.65,3.9]],"ltp":3.0,"tv":22053.35,"id":9629022}]}]}
{"op":"mcm","clk":"4215316607","pt":1631537701408,"mc":[{"id":"1.187557985","rc":[{"batb":[[0,1.46,44.23],[1,1.43,642.22],[2,1.4,319.59]],"batl":[[0,1.5,24.68],[1,1.54,20],[2,2.24,216.59]],"ltp":1.47,"tv":43175.4,"id":5300820},{"batb":[[0,2.88,15.95],[1,2.42,72.55],[2,1.81,8.32]],"batl":[[0,3.5,4.33],[1,3.65,3.9],[2,3.75,4.18]],"ltp":3.0,"tv":22053.35,"id":9629022}]}]}
{"op":"mcm","clk":"4215316694","pt":1631537702611,"mc":[{"id":"1.187557985","rc":[{"batb":[[0,1.43,642.22],[1,1.4,319.59],[2,1.39,85]],"batl":[[0,1.5,24.4],[2,1.95,415.52]],"ltp":1.47,"tv":43175.4,"id":5300820},{"batb":[[0,2.42,72.55],[1,1.81,8.32],[2,1.8,4.14]],"ltp":3.0,"tv":22053.35,"id":9629022}]}]}
{"op":"mcm","clk":"4215316750","pt":1631537703595,"mc":[{"id":"1.187557985","rc":[{"batb":[[0,1.4,319.59],[1,1.39,85],[2,1.38,926.86]],"batl":[[2,1.66,157.29]],"ltp":1.47,"tv":43175.4,"id":5300820}]}]}
{"op":"mcm","clk":"4215316835","pt":1631537704635,"mc":[{"id":"1.187557985","rc":[{"batb":[[0,1.39,305.41],[1,1.38,926.86],[2,1.37,427.57]],"ltp":1.47,"tv":43175.4,"id":5300820},{"batb":[[0,2.48,70.38]],"batl":[[0,3.65,3.9],[1,3.75,4.18],[2,3.8,4.17]],"ltp":3.0,"tv":22053.35,"id":9629022}]}]}
{"op":"mcm","clk":"4215316958","pt":1631537706321,"mc":[{"id":"1.187557985","rc":[{"batb":[[0,1.41,642.22],[1,1.39,312.41],[2,1.38,926.86]],"batl":[[2,1.95,415.52]],"ltp":1.47,"tv":43175.4,"id":5300820},{"batl":[[0,3.5,3],[1,3.65,3.9],[2,3.75,4.18]],"ltp":3.0,"tv":22053.35,"id":9629022}]}]}
{"op":"mcm","clk":"4215317043","pt":1631537707524,"mc":[{"id":"1.187557985","rc":[{"batb":[[1,1.4,572.96],[2,1.39,305.41]],"batl":[[2,2.24,216.59]],"ltp":1.47,"tv":43175.4,"id":5300820},{"batl":[[0,3.5,3.39]],"ltp":3.0,"tv":22053.35,"id":9629022}]}]}
{"op":"mcm","clk":"4215317109","pt":1631537708623,"mc":[{"id":"1.187557985","rc":[{"batb":[[0,1.39,305.41],[1,1.38,480.23],[2,1.37,427.57]],"batl":[[2,1.58,12.66]],"ltp":1.47,"tv":43175.4,"id":5300820},{"batb":[[0,3.35,1141.78],[1,3.3,1108.2],[2,3.25,1108.2]],"batl":[[0,3.6,3]],"ltp":3.0,"tv":22053.35,"id":9629022}]}]}
{"op":"mcm","clk":"4215317192","pt":1631537709611,"mc":[{"id":"1.187557985","rc":[{"batb":[[0,1.41,6],[1,1.39,305.41],[2,1.38,480.23]],"batl":[[0,1.42,410.71],[1,1.43,268.39],[2,1.5,24.4]],"ltp":1.47,"tv":43175.4,"id":5300820},{"trd":[[3.35,13.14]],"batb":[[0,3.35,564.45],[1,3.3,638.37],[2,3.25,554.1]],"ltp":3.35,"tv":22066.25,"id":9629022}],"tv":65241.66}]}
{"op":"mcm","clk":"4215317249","pt":1631537710441,"mc":[{"id":"1.187557985","rc":[{"batb":[[0,1.39,305.41],[1,1.38,480.23],[2,1.37,427.57]],"batl":[[2,1.44,30]],"ltp":1.47,"tv":43175.4,"id":5300820},{"batb":[[2,3.25,567.43]],"batl":[[2,3.75,22.27]],"ltp":3.35,"tv":22066.25,"id":9629022}]}]}
{"op":"mcm","clk":"4215317309","pt":1631537711330,"mc":[{"id":"1.187557985","rc":[{"batb":[[0,1.39,342.49]],"ltp":1.47,"tv":43175.4,"id":5300820},{"batl":[[0,3.6,18]],"ltp":3.35,"tv":22066.25,"id":9629022}]}]}
{"op":"mcm","clk":"4215317390","pt":1631537712432,"mc":[{"id":"1.187557985","rc":[{"batl":[[2,1.45,63.91]],"ltp":1.47,"tv":43175.4,"id":5300820}]}]}
{"op":"mcm","clk":"4215317477","pt":1631537713634,"mc":[{"id":"1.187557985","rc":[{"trd":[[1.41,41.91]],"batb":[[0,1.4,75.21],[1,1.39,501.06],[2,1.38,480.23]],"batl":[[0,1.41,70.26],[1,1.42,470.87],[2,1.43,268.39]],"ltp":1.41,"tv":43182.95,"id":5300820},{"trd":[[3.4,1.05]],"ltp":3.4,"tv":22067.3,"id":9629022}],"tv":65250.25}]}
{"op":"mcm","clk":"4215317500","pt":1631537713947,"mc":[{"id":"1.187557985","rc":[{"trd":[[1.41,70.86]],"batl":[[0,1.41,41.31]],"ltp":1.41,"tv":43211.89,"id":5300820},{"trd":[[3.4,13.05]],"batb":[[2,3.25,554.1]],"ltp":3.4,"tv":22079.3,"id":9629022}],"tv":65291.2}]}
{"op":"mcm","clk":"4215317622","pt":1631537715632,"mc":[{"id":"1.187557985","rc":[{"batl":[[2,1.43,710.66]],"ltp":1.41,"tv":43211.89,"id":5300820},{"batb":[[1,3.3,817.01]],"ltp":3.4,"tv":22079.3,"id":9629022}]}]}
{"op":"mcm","clk":"4215317684","pt":1631537716523,"mc":[{"id":"1.187557985","rc":[{"trd":[[1.4,253.99]],"batb":[[0,1.4,52.06]],"ltp":1.4,"tv":43258.19,"id":5300820}],"tv":65337.49}]}
{"op":"mcm","clk":"4215317718","pt":1631537717149,"mc":[{"id":"1.187557985","rc":[{"batb":[[1,3.3,830.05]],"ltp":3.4,"tv":22079.3,"id":9629022}]}]}
{"op":"mcm","clk":"4215317822","pt":1631537718613,"mc":[{"id":"1.187557985","rc":[{"batb":[[0,1.4,72.11],[1,1.39,432.49]],"batl":[[0,1.41,86.75],[1,1.42,410.71]],"ltp":1.4,"tv":43258.19,"id":5300820}]}]}
{"op":"mcm","clk":"4215317914","pt":1631537720019,"mc":[{"id":"1.187557985","rc":[{"trd":[[1.4,274.64]],"batb":[[0,1.4,61.81]],"ltp":1.4,"tv":43278.83,"id":5300820}],"tv":65358.13}]}
{"op":"mcm","clk":"4215318006","pt":1631537721429,"mc":[{"id":"1.187557985","rc":[{"batb":[[0,1.39,175],[1,1.38,8],[2,1.36,1013.33]],"batl":[[0,1.43,30],[1,1.47,2.32],[2,1.49,7]],"ltp":1.4,"tv":43278.83,"id":5300820},{"batb":[[0,3.3,13.04],[1,3.05,4],[2,3,3]],"batl":[[0,3.6,3],[1,3.75,18.09],[2,3.95,2.9]],"ltp":3.4,"tv":22079.3,"id":9629022}]}]}
{"op":"mcm","clk":"4215318077","pt":1631537722424,"mc":[{"id":"1.187557985","rc":[{"batb":[[0,1.39,85],[1,1.37,512],[2,1.36,1475.33]],"batl":[[0,1.47,2.32],[1,1.54,20],[2,1.56,45.17]],"ltp":1.4,"tv":43278.83,"id":5300820},{"batb":[[0,2.84,49.29],[1,2.78,4.66],[2,2.5,4.82]],"batl":[[0,3.95,2.9],[1,4.3,2.15],[2,6,3]],"ltp":3.4,"tv":22079.3,"id":9629022}]}]}
{"op":"mcm","clk":"4215318128","pt":1631537723283,"mc":[{"id":"1.187557985","rc":[{"trd":[[1.39,44.8]],"batb":[[0,1.39,84.99],[2,1.36,512]],"ltp":1.39,"tv":43278.85,"id":5300820}],"tv":65358.16}]}
{"op":"mcm","clk":"4215318208","pt":1631537724335,"mc":[{"id":"1.187557985","rc":[{"batb":[[0,1.39,85.03]],"batl":[[1,1.53,246.15],[2,1.54,220.1]],"ltp":1.39,"tv":43278.85,"id":5300820}]}]}
{"op":"mcm","clk":"4215318309","pt":1631537725642,"mc":[{"id":"1.187557985","rc":[{"batb":[[0,2.84,52.29],[1,2.82,3],[2,2.78,4.66]],"ltp":3.4,"tv":22079.3,"id":9629022}]}]}
{"op":"mcm","clk":"4215318386","pt":1631537726634,"mc":[{"id":"1.187557985","rc":[{"trd":[[1.41,70.93]],"batb":[[0,1.39,84.99]],"batl":[[0,1.4,96.69],[1,1.47,2.32],[2,1.54,20]],"ltp":1.41,"tv":43278.93,"id":5300820}],"tv":65358.23}]}
{"op":"mcm","clk":"4215318467","pt":1631537727630,"mc":[{"id":"1.187557985","rc":[{"batl":[[0,1.4,106.09]],"ltp":1.41,"tv":43278.93,"id":5300820}]}]}
{"op":"mcm","clk":"4215318622","pt":1631537729453,"mc":[{"id":"1.187557985","rc":[{"trd":[[1.4,380.73]],"batb":[[0,1.41,136.29],[1,1.4,370.48],[2,1.39,397.67]],"batl":[[0,1.43,21.5],[1,1.44,357.89],[2,1.45,253.57]],"ltp":1.4,"tv":43385.02,"id":5300820},{"trd":[[3.5,42.45]],"batb":[[0,3.3,20.58],[1,2.84,52.29],[2,2.82,3]],"batl":[[0,3.6,19.46],[1,3.95,2.9],[2,4.3,2.15]],"ltp":3.5,"tv":22121.75,"id":9629022}],"tv":65506.78}]}
{"op":"mcm","clk":"4215318681","pt":1631537730339,"mc":[{"id":"1.187557985","rc":[{"batb":[[0,1.41,136.3]],"batl":[[0,1.44,357.89],[1,1.45,253.57],[2,1.47,2.32]],"ltp":1.4,"tv":43385.02,"id":5300820},{"batb":[[0,2.86,80.25]],"batl":[[0,3.9,14.5]],"ltp":3.5,"tv":22121.75,"id":9629022}]}]}
{"op":"mcm","clk":"4215318741","pt":1631537731236,"mc":[{"id":"1.187557985","rc":[{"batb":[[1,1.39,84.99],[2,1.37,512]],"batl":[[0,1.47,2.32],[1,1.54,20],[2,1.56,45.17]],"ltp":1.4,"tv":43385.02,"id":5300820},{"batb":[[0,2.84,52.29],[1,2.82,3],[2,2.78,4.66]],"batl":[[0,3.95,2.9],[1,4.3,2.15],[2,6,3]],"ltp":3.5,"tv":22121.75,"id":9629022}]}]}
{"op":"mcm","clk":"4215318848","pt":1631537732658,"mc":[{"id":"1.187557985","rc":[{"batb":[[0,1.41,136.34]],"batl":[[0,1.51,50.5]],"ltp":1.4,"tv":43385.02,"id":5300820},{"batb":[[0,2.96,4.38],[1,2.84,52.29],[2,2.82,3]],"ltp":3.5,"tv":22121.75,"id":9629022}]}]}
{"op":"mcm","clk":"4215318908","pt":1631537733440,"mc":[{"id":"1.187557985","rc":[{"batb":[[0,1.41,65.75]],"batl":[[0,1.54,20],[1,1.56,45.17],[2,1.82,475.58]],"ltp":1.4,"tv":43385.02,"id":5300820},{"batb":[[0,2.84,52.29],[1,2.82,3],[2,2.78,4.66]],"ltp":3.5,"tv":22121.75,"id":9629022}]}]}
{"op":"mcm","clk":"4215318951","pt":1631537734067,"mc":[{"id":"1.187557985","rc":[{"batb":[[0,1.41,12.8]],"batl":[[0,1.53,245.56],[1,1.54,220.1],[2,1.56,45.17]],"ltp":1.4,"tv":43385.02,"id":5300820}]}]}
{"op":"mcm","clk":"4215319079","pt":1631537735637,"mc":[{"id":"1.187557985","rc":[{"batb":[[0,1.41,12.76]],"ltp":1.4,"tv":43385.02,"id":5300820}]}]}
{"op":"mcm","clk":"4215319332","pt":1631537739465,"mc":[{"id":"1.187557985","rc":[{"trd":[[1.39,67.98],[1.4,385.73],[1.41,96.46]],"batb":[[0,1.39,73.4],[1,1.37,512],[2,1.36,512]],"batl":[[0,1.51,44.5],[1,1.53,245.56],[2,1.54,220.1]],"ltp":1.39,"tv":43438.72,"id":5300820},{"trd":[[3.5,44.45]],"batb":[[0,2.96,4.38],[1,2.84,52.29]],"ltp":3.5,"tv":22123.75,"id":9629022}],"tv":65562.48}]}
{"op":"mcm","clk":"4215319353","pt":1631537739775,"mc":[{"id":"1.187557985","rc":[{"batl":[[0,1.53,245.56],[1,1.54,220.1],[2,1.56,45.17]],"ltp":1.39,"tv":43438.72,"id":5300820},{"batb":[[0,2.84,52.29],[1,2.78,4.66],[2,2.5,4.82]],"ltp":3.5,"tv":22123.75,"id":9629022}]}]}
{"op":"mcm","clk":"4215319460","pt":1631537741044,"mc":[{"id":"1.187557985","rc":[{"batb":[[0,1.37,512],[1,1.36,512],[2,1.34,75.22]],"ltp":1.39,"tv":43438.72,"id":5300820}]}]}
{"op":"mcm","clk":"4215319572","pt":1631537742470,"mc":[{"id":"1.187557985","rc":[{"trd":[[1.53,3529.19]],"batl":[[0,1.53,244.71]],"ltp":1.53,"tv":43439.57,"id":5300820},{"trd":[[2.88,274.3]],"ltp":2.88,"tv":22124.2,"id":9629022}],"tv":65563.78}]}
{"op":"mcm","clk":"4215319641","pt":1631537743356,"mc":[{"id":"1.187557985","rc":[{"batb":[[0,1.36,512],[1,1.34,75.22],[2,1.33,277.82]],"ltp":1.53,"tv":43439.57,"id":5300820}]}]}
{"op":"mcm","clk":"4215319739","pt":1631537744869,"mc":[{"id":"1.187557985","rc":[{"trd":[[1.53,3529.57]],"batl":[[0,1.53,244.52]],"ltp":1.53,"tv":43439.95,"id":5300820}],"tv":65564.16}]}
{"op":"mcm","clk":"4215319842","pt":1631537746553,"mc":[{"id":"1.187557985","rc":[{"batl":[[0,1.51,49.5],[1,1.53,244.52],[2,1.54,220.1]],"ltp":1.53,"tv":43439.95,"id":5300820},{"batb":[[0,2.96,4.63],[1,2.84,52.29],[2,2.78,4.66]],"ltp":2.88,"tv":22124.2,"id":9629022}]}]}
{"op":"mcm","clk":"4215319875","pt":1631537747078,"mc":[{"id":"1.187557985","rc":[{"batb":[[1,1.34,587.22]],"batl":[[0,1.41,2.32],[1,1.5,5],[2,1.53,244.52]],"ltp":1.53,"tv":43439.95,"id":5300820},{"batb":[[0,2.84,52.29],[1,2.78,4.66],[2,2.5,4.82]],"ltp":2.88,"tv":22124.2,"id":9629022}]}]}
{"op":"mcm","clk":"4215319991","pt":1631537748657,"mc":[{"id":"1.187557985","rc":[{"trd":[[1.41,96.64]],"batl":[[0,1.41,2.23],[2,1.52,833.11]],"ltp":1.41,"tv":43440.14,"id":5300820}],"tv":65564.35}]}
{"op":"mcm","clk":"4215320083","pt":1631537750273,"mc":[{"id":"1.187557985","rc":[{"batb":[[0,1.34,587.22],[1,1.33,277.82],[2,1.31,1115.99]],"ltp":1.41,"tv":43440.14,"id":5300820}]}]}
{"op":"mcm","clk":"4215320298","pt":1631537753465,"mc":[{"id":"1.187557985","rc":[{"batb":[[0,1.34,589.22],[1,1.33,280.82]],"batl":[[2,1.51,51.5]],"ltp":1.41,"tv":43440.14,"id":5300820},{"batb":[[0,2.96,4.13],[1,2.84,52.29],[2,2.78,4.66]],"ltp":2.88,"tv":22124.2,"id":9629022}]}]}
{"op":"mcm","clk":"4215320412","pt":1631537754970,"mc":[{"id":"1.187557985","rc":[{"batl":[[2,1.52,833.11]],"ltp":1.41,"tv":43440.14,"id":5300820},{"batb":[[0,2.84,52.29],[1,2.78,4.66],[2,2.5,4.82]],"ltp":2.88,"tv":22124.2,"id":9629022}]}]}
{"op":"mcm","clk":"4215320504","pt":1631537756173,"mc":[{"id":"1.187557985","rc":[{"batb":[[0,1.33,277.82],[1,1.31,1115.99],[2,1.3,439.02]],"ltp":1.41,"tv":43440.14,"id":5300820},{"batl":[[0,4.3,2.15],[1,6,3],[2,6.4,3]],"ltp":2.88,"tv":22124.2,"id":9629022}]}]}
{"op":"mcm","clk":"4215320618","pt":1631537757578,"mc":[{"id":"1.187557985","rc":[{"batb":[[1,1.31,631.89]],"batl":[[1,1.5,18.33]],"ltp":1.41,"tv":43440.14,"id":5300820},{"batb":[[0,3.9,980.78],[1,3.85,951.92],[2,3.8,951.92]],"ltp":2.88,"tv":22124.2,"id":9629022}]}]}
{"op":"mcm","clk":"4215320707","pt":1631537758567,"mc":[{"id":"1.187557985","rc":[{"batl":[[0,1.34,201.09],[1,1.35,351.11],[2,1.41,2.23]],"ltp":1.41,"tv":43440.14,"id":5300820},{"trd":[[3.9,11.6]],"batb":[[0,3.9,484.6],[1,3.85,475.96],[2,3.8,475.96]],"ltp":3.9,"tv":22135.8,"id":9629022}],"tv":65575.95}]}
{"op":"mcm","clk":"4215320794","pt":1631537759666,"mc":[{"id":"1.187557985","rc":[{"batl":[[2,1.36,30]],"ltp":1.41,"tv":43440.14,"id":5300820},{"batb":[[2,3.8,486.67]],"batl":[[0,4.2,10.75],[1,4.3,2.15],[2,4.4,16.26]],"ltp":3.9,"tv":22135.8,"id":9629022}]}]}
{"op":"mcm","clk":"4215320945","pt":1631537761660,"mc":[{"id":"1.187557985","rc":[{"trd":[[3.9,16]],"batb":[[0,3.9,482.4]],"ltp":3.9,"tv":22140.2,"id":9629022}],"tv":65580.35}]}
{"op":"mcm","clk":"4215321017","pt":1631537762599,"mc":[{"id":"1.187557985","rc":[{"trd":[[1.34,273.38]],"batb":[[0,1.33,348.36],[1,1.32,60.88],[2,1.31,631.89]],"batl":[[0,1.34,304.19],[1,1.35,414.28]],"ltp":1.34,"tv":43445.78,"id":5300820},{"trd":[[3.9,17.88]],"batb":[[0,3.9,481.46]],"ltp":3.9,"tv":22142.08,"id":9629022}],"tv":65587.87}]}
{"op":"mcm","clk":"4215321043","pt":1631537762965,"mc":[{"id":"1.187557985","rc":[{"batb":[[0,1.33,608.36]],"batl":[[2,1.4,19.15]],"ltp":1.34,"tv":43445.78,"id":5300820},{"batb":[[2,3.8,475.96]],"ltp":3.9,"tv":22142.08,"id":9629022}]}]}
{"op":"mcm","clk":"4215321148","pt":1631537764267,"mc":[{"id":"1.187557985","rc":[{"trd":[[1.34,273.44]],"batb":[[1,1.32,555.77]],"batl":[[0,1.34,304.16],[2,1.39,71.5]],"ltp":1.34,"tv":43445.84,"id":5300820},{"batl":[[0,4.2,155.54]],"ltp":3.9,"tv":22142.08,"id":9629022}],"tv":65587.93}]}
{"op":"mcm","clk":"4215321197","pt":1631537764894,"mc":[{"id":"1.187557985","rc":[{"trd":[[1.34,278.44]],"batl":[[0,1.34,301.66]],"ltp":1.34,"tv":43450.84,"id":5300820}],"tv":65592.93}]}
{"op":"mcm","clk":"4215321294","pt":1631537766303,"mc":[{"id":"1.187557985","rc":[{"batl":[[1,1.35,935.76]],"ltp":1.34,"tv":43450.84,"id":5300820},{"batb":[[1,3.85,658.81]],"ltp":3.9,"tv":22142.08,"id":9629022}]}]}
{"op":"mcm","clk":"4215321384","pt":1631537767299,"mc":[{"id":"1.187557985","rc":[{"trd":[[1.33,10]],"batb":[[0,1.33,603.36]],"ltp":1.33,"tv":43460.84,"id":5300820},{"batl":[[0,4.1,11.87],[1,4.2,155.54],[2,4.3,2.15]],"ltp":3.9,"tv":22142.08,"id":9629022}],"tv":65602.93}]}
{"op":"mcm","clk":"4215321468","pt":1631537768398,"mc":[{"id":"1.187557985","rc":[{"trd":[[1.34,321.02]],"batb":[[0,1.33,1152.77],[1,1.32,494.89]],"batl":[[0,1.34,280.37],[1,1.35,872.59]],"ltp":1.34,"tv":43503.43,"id":5300820},{"batl":[[0,4.1,190.09]],"ltp":3.9,"tv":22142.08,"id":9629022}],"tv":65645.51}]}
{"op":"mcm","clk":"4215321494","pt":1631537768812,"mc":[{"id":"1.187557985","rc":[{"batl":[[0,1.34,105.92]],"ltp":1.34,"tv":43503.43,"id":5300820}]}]}
{"op":"mcm","clk":"4215321603","pt":1631537770379,"mc":[{"id":"1.187557985","rc":[{"trd":[[1.33,14.65],[1.34,321.09]],"batb":[[0,1.33,1079.89]],"batl":[[0,1.35,872.59],[1,1.39,71.5],[2,1.4,19.15]],"ltp":1.34,"tv":43508.15,"id":5300820}],"tv":65650.24}]}
{"op":"mcm","clk":"4215321701","pt":1631537771916,"mc":[{"id":"1.187557985","rc":[{"batl":[[0,1.35,1054.53],[1,1.36,334.21],[2,1.39,71.5]],"ltp":1.34,"tv":43508.15,"id":5300820}]}]}
{"op":"mcm","clk":"4215321803","pt":1631537773479,"mc":[{"id":"1.187557985","rc":[{"trd":[[1.33,19.3]],"batb":[[0,1.33,1077.57]],"ltp":1.33,"tv":43512.8,"id":5300820}],"tv":65654.89}]}
{"op":"mcm","clk":"4215321925","pt":1631537775597,"mc":[{"id":"1.187557985","rc":[{"batb":[[0,1.34,52.32],[1,1.33,1077.57],[2,1.32,494.89]],"batl":[[0,1.35,521.48],[1,1.39,71.5],[2,1.4,66.79]],"ltp":1.33,"tv":43512.8,"id":5300820},{"batb":[[0,3.85,182.85],[1,3.75,61.84],[2,3.65,3]],"batl":[[0,4.1,178.22]],"ltp":3.9,"tv":22142.08,"id":9629022}]}]}
{"op":"mcm","clk":"4215321961","pt":1631537776220,"mc":[{"id":"1.187557985","rc":[{"batb":[[1,1.33,260],[2,1.29,93.81]],"batl":[[0,1.35,30],[1,1.4,58.79],[2,1.42,417.45]],"ltp":1.33,"tv":43512.8,"id":5300820},{"batb":[[0,3.85,10.52],[1,3.5,4.08],[2,3.4,116.83]],"batl":[[0,4.4,16.26],[1,4.5,108.62],[2,4.6,146.52]],"ltp":3.9,"tv":22142.08,"id":9629022}]}]}
{"op":"mcm","clk":"4215322039","pt":1631537777522,"mc":[{"id":"1.187557985","rc":[{"batb":[[1,1.28,668.55],[2,1.27,530.14]],"batl":[[0,1.4,58.79],[1,1.42,417.45],[2,1.43,429.74]],"ltp":1.33,"tv":43512.8,"id":5300820},{"batb":[[0,3.5,4.08],[1,3.4,116.83],[2,3.35,190.29]],"batl":[[0,4.5,106.05],[1,4.6,146.52],[2,4.7,161.12]],"ltp":3.9,"tv":22142.08,"id":9629022}]}]}
{"op":"mcm","clk":"4215322109","pt":1631537778623,"mc":[{"id":"1.187557985","rc":[{"trd":[[1.34,325.74]],"batb":[[0,1.34,104.79],[2,1.27,998.43]],"batl":[[0,1.42,801.64],[1,1.43,698.15],[2,1.44,507.84]],"ltp":1.34,"tv":43517.44,"id":5300820},{"batb":[[0,3.4,116.83],[1,3.35,190.29],[2,3.3,205.98]],"ltp":3.9,"tv":22142.08,"id":9629022}],"tv":65659.53}]}
{"op":"mcm","clk":"4215322265","pt":1631537780502,"mc":[{"id":"1.187557985","rc":[{"batb":[[0,1.34,50.27],[1,1.29,82.81],[2,1.28,668.55]],"ltp":1.34,"tv":43517.44,"id":5300820},{"batl":[[0,4.5,108.76]],"ltp":3.9,"tv":22142.08,"id":9629022}]}]}
{"op":"mcm","clk":"4215322311","pt":1631537781126,"mc":[{"id":"1.187557985","rc":[{"batb":[[1,1.29,512],[2,1.28,1180.55]],"batl":[[0,1.42,809.64]],"ltp":1.34,"tv":43517.44,"id":5300820},{"batl":[[0,4.5,106.05]],"ltp":3.9,"tv":22142.08,"id":9629022}]}]}
{"op":"mcm","clk":"4215322416","pt":1631537782488,"mc":[{"id":"1.187557985","rc":[{"batl":[[0,1.41,512],[1,1.42,809.64],[2,1.43,698.15]],"ltp":1.34,"tv":43517.44,"id":5300820}]}]}
{"op":"mcm","clk":"4215322482","pt":1631537783320,"mc":[{"id":"1.187557985","rc":[{"batl":[[1,1.42,937.45],[2,1.43,429.74]],"ltp":1.34,"tv":43517.44,"id":5300820}]}]}
{"op":"mcm","clk":"4215322603","pt":1631537784628,"mc":[{"id":"1.187557985","rc":[{"batb":[[1,1.29,602.81]],"ltp":1.34,"tv":43517.44,"id":5300820},{"batl":[[0,4.5,108.18]],"ltp":3.9,"tv":22142.08,"id":9629022}]}]}
{"op":"mcm","clk":"4215322790","pt":1631537786520,"mc":[{"id":"1.187557985","rc":[{"trd":[[1.35,95.04]],"batb":[[0,1.35,117.39],[1,1.34,50.27],[2,1.33,270.78]],"batl":[[0,1.36,389.72],[1,1.37,324.84],[2,1.41,512]],"ltp":1.35,"tv":43555.24,"id":5300820}],"tv":65697.33}]}
{"op":"mcm","clk":"4215322865","pt":1631537787518,"mc":[{"id":"1.187557985","rc":[{"batl":[[2,1.4,92.7]],"ltp":1.35,"tv":43555.24,"id":5300820},{"batb":[[0,3.45,43.84],[1,3.4,116.83],[2,3.35,190.29]],"batl":[[0,4.4,39.41],[1,4.5,108.18],[2,4.6,146.52]],"ltp":3.9,"tv":22142.08,"id":9629022}]}]}
{"op":"mcm","clk":"4215322913","pt":1631537788143,"mc":[{"id":"1.187557985","rc":[{"batl":[[2,1.4,160.24]],"ltp":1.35,"tv":43555.24,"id":5300820},{"batb":[[0,3.5,4.08]],"ltp":3.9,"tv":22142.08,"id":9629022}]}]}
{"op":"mcm","clk":"4215323022","pt":1631537789546,"mc":[{"id":"1.187557985","rc":[{"batb":[[2,1.29,602.81]],"batl":[[0,1.4,67.54],[1,1.41,512],[2,1.42,937.45]],"ltp":1.35,"tv":43555.24,"id":5300820},{"batl":[[0,4.5,108.18],[1,4.6,146.52],[2,4.7,161.12]],"ltp":3.9,"tv":22142.08,"id":9629022}]}]}
{"op":"mcm","clk":"4215323097","pt":1631537790547,"mc":[{"id":"1.187557985","rc":[{"batb":[[0,1.35,11.48]],"batl":[[0,1.41,512],[1,1.42,937.45],[2,1.43,429.74]],"ltp":1.35,"tv":43555.24,"id":5300820},{"batb":[[0,3.4,116.83],[1,3.35,190.29],[2,3.3,205.98]],"ltp":3.9,"tv":22142.08,"id":9629022}]}]}
{"op":"mcm","clk":"4215323245","pt":1631537792327,"mc":[{"id":"1.187557985","rc":[{"trd":[[1.41,96.9]],"batl":[[0,1.41,511.87],[1,1.42,1322.69],[2,1.43,698.15]],"ltp":1.41,"tv":43555.5,"id":5300820}],"tv":65697.59}]}
{"op":"mcm","clk":"4215323336","pt":1631537793516,"mc":[{"id":"1.187557985","rc":[{"trd":[[1.41,97.88]],"batl":[[0,1.41,511.38]],"ltp":1.41,"tv":43556.48,"id":5300820}],"tv":65698.57}]}
{"op":"mcm","clk":"4215323350","pt":1631537793726,"mc":[{"id":"1.187557985","rc":[{"batb":[[0,1.36,54.51],[1,1.35,11.48],[2,1.34,50.27]],"ltp":1.41,"tv":43556.48,"id":5300820}]}]}
{"op":"mcm","clk":"4215323436","pt":1631537795334,"mc":[{"id":"1.187557985","rc":[{"batb":[[0,1.35,11.48],[1,1.34,50.27],[2,1.29,602.81]],"ltp":1.41,"tv":43556.48,"id":5300820}]}]}
{"op":"mcm","clk":"4215323605","pt":1631537798049,"mc":[{"id":"1.187557985","rc":[{"batb":[[1,1.34,47.95]],"ltp":1.41,"tv":43556.48,"id":5300820}]}]}
{"op":"mcm","clk":"4215323845","pt":1631537802630,"mc":[{"id":"1.187557985","rc":[{"batl":[[1,1.42,577.25],[2,1.43,53.5]],"ltp":1.41,"tv":43556.48,"id":5300820},{"batb":[[0,3.35,3.87],[1,3.3,3.58],[2,3.25,86.19]],"ltp":3.9,"tv":22142.08,"id":9629022}]}]}
{"op":"mcm","clk":"4215323853","pt":1631537802735,"mc":[{"id":"1.187557985","rc":[{"trd":[[1.29,531.28],[1.34,421.63],[1.35,118]],"batb":[[0,1.29,337.14],[1,1.28,1180.55],[2,1.27,997.19]],"ltp":1.29,"tv":44206.62,"id":5300820}],"tv":66348.7}]}
{"op":"mcm","clk":"4215323995","pt":1631537804459,"mc":[{"id":"1.187557985","rc":[{"trd":[[1.29,591.64]],"batb":[[0,1.28,668.55],[1,1.27,997.19],[2,1.26,1231.12]],"ltp":1.29,"tv":44266.98,"id":5300820},{"batl":[[0,4.5,106.05]],"ltp":3.9,"tv":22142.08,"id":9629022}],"tv":66409.06}]}
{"op":"mcm","clk":"4215324089","pt":1631537805643,"mc":[{"id":"1.187557985","rc":[{"batl":[[0,1.3,466.3],[1,1.31,1862.93],[2,1.32,1416.98]],"ltp":1.29,"tv":44266.98,"id":5300820},{"batl":[[0,4.6,146.52],[1,4.7,161.12],[2,4.9,2.05]],"ltp":3.9,"tv":22142.08,"id":9629022}]}]}
{"op":"mcm","clk":"4215324166","pt":1631537806459,"mc":[{"id":"1.187557985","rc":[{"trd":[[1.3,33.63]],"batb":[[2,1.26,1597.23]],"batl":[[0,1.3,440.67]],"ltp":1.3,"tv":44300.61,"id":5300820},{"trd":[[4.3,5.33]],"batb":[[0,4.1,97.74],[1,3.8,60.17],[2,3.45,3]],"ltp":4.3,"tv":22147.41,"id":9629022}],"tv":66448.02}]}
{"op":"mcm","clk":"4215324255","pt":1631537807608,"mc":[{"id":"1.187557985","rc":[{"trd":[[1.3,38.27]],"batb":[[0,1.28,707.53]],"batl":[[0,1.3,438.35],[1,1.31,1892.93]],"ltp":1.3,"tv":44305.25,"id":5300820},{"batb":[[0,4.3,9.09],[1,4.1,97.74],[2,3.8,60.17]],"ltp":4.3,"tv":22147.41,"id":9629022}],"tv":66452.67}]}
{"op":"mcm","clk":"4215324280","pt":1631537807821,"mc":[{"id":"1.187557985","rc":[{"batb":[[0,1.28,668.55]],"ltp":1.3,"tv":44305.25,"id":5300820}]}]}
{"op":"mcm","clk":"4215324385","pt":1631537809434,"mc":[{"id":"1.187557985","rc":[{"trd":[[1.28,37.11],[1.29,592.16]],"batb":[[0,1.28,649.99]],"batl":[[0,1.29,294.91],[1,1.3,438.35],[2,1.31,1892.93]],"ltp":1.29,"tv":44342.88,"id":5300820},{"batl":[[0,4.6,159.05]],"ltp":4.3,"tv":22147.41,"id":9629022}],"tv":66490.3}]}
{"op":"mcm","clk":"4215324474","pt":1631537810583,"mc":[{"id":"1.187557985","rc":[{"trd":[[1.29,601.22]],"batb":[[0,1.28,730.75]],"batl":[[0,1.29,349.1],[1,1.3,497.4],[2,1.31,2473.89]],"ltp":1.29,"tv":44351.94,"id":5300820},{"trd":[[4.4,0.9]],"batb":[[1,4.2,187.5],[2,4.1,97.74]],"ltp":4.4,"tv":22148.32,"id":9629022}],"tv":66500.27}]}
{"op":"mcm","clk":"4215324515","pt":1631537811308,"mc":[{"id":"1.187557985","rc":[{"trd":[[1.29,601.25]],"batb":[[1,1.27,1073.66]],"batl":[[0,1.29,349.09]],"ltp":1.29,"tv":44351.96,"id":5300820}],"tv":66500.29}]}
{"op":"mcm","clk":"4215324602","pt":1631537812410,"mc":[{"id":"1.187557985","rc":[{"batb":[[0,1.28,817.75],[1,1.27,1170.53]],"batl":[[2,1.31,2548.39]],"ltp":1.29,"tv":44351.96,"id":5300820},{"batb":[[1,4.2,190.07],[2,4.1,100.28]],"batl":[[2,4.8,2.27]],"ltp":4.4,"tv":22148.32,"id":9629022}]}]}
{"op":"mcm","clk":"4215324666","pt":1631537813088,"mc":[{"id":"1.187557985","rc":[{"batb":[[2,1.26,2050.63]],"batl":[[1,1.3,996.54]],"ltp":1.29,"tv":44351.96,"id":5300820},{"batb":[[0,4.3,159.99]],"batl":[[2,4.8,110.74]],"ltp":4.4,"tv":22148.32,"id":9629022}]}]}
{"op":"mcm","clk":"4215324770","pt":1631537814392,"mc":[{"id":"1.187557985","rc":[{"batb":[[1,1.27,1682.53],[2,1.26,2562.63]],"batl":[[1,1.3,1026.54]],"ltp":1.29,"tv":44351.96,"id":5300820}]}]}
{"op":"mcm","clk":"4215324853","pt":1631537815485,"mc":[{"id":"1.187557985","rc":[{"trd":[[1.29,602.02]],"batb":[[0,1.28,877.87]],"batl":[[0,1.29,410.29]],"ltp":1.29,"tv":44352.74,"id":5300820}],"tv":66501.06}]}
{"op":"mcm","clk":"4215324928","pt":1631537816577,"mc":[{"id":"1.187557985","rc":[{"trd":[[1.29,711.05]],"batb":[[0,1.28,817.75],[1,1.27,1606.06]],"batl":[[0,1.29,355.78],[1,1.3,967.5],[2,1.31,2473.21]],"ltp":1.29,"tv":44461.77,"id":5300820}],"tv":66610.09}]}
{"op":"mcm","clk":"4215325107","pt":1631537818516,"mc":[{"id":"1.187557985","rc":[{"trd":[[1.28,73.29]],"batb":[[0,1.28,718.9]],"batl":[[0,1.29,233.93]],"ltp":1.28,"tv":44497.94,"id":5300820}],"tv":66646.26}]}
{"op":"mcm","clk":"4215325285","pt":1631537820689,"mc":[{"id":"1.187557985","rc":[{"trd":[[1.29,711.07]],"batl":[[0,1.29,233.92]],"ltp":1.29,"tv":44497.96,"id":5300820}],"tv":66646.28}]}
{"op":"mcm","clk":"4215325442","pt":1631537822513,"mc":[{"id":"1.187557985","rc":[{"trd":[[1.29,712.37]],"batl":[[0,1.29,233.27]],"ltp":1.29,"tv":44499.26,"id":5300820}],"tv":66647.58}]}
{"op":"mcm","clk":"4215325582","pt":1631537824340,"mc":[{"id":"1.187557985","rc":[{"batl":[[1,1.3,1011.38]],"ltp":1.29,"tv":44499.26,"id":5300820}]}]}
{"op":"mcm","clk":"4215325666","pt":1631537825432,"mc":[{"id":"1.187557985","rc":[{"batb":[[0,1.28,87],[1,1.27,608.87],[2,1.26,1440.99]],"batl":[[1,1.3,30],[2,1.31,74.5]],"ltp":1.29,"tv":44499.26,"id":5300820},{"batb":[[0,4.3,9.09],[1,4.2,2.57],[2,4.1,2.54]],"batl":[[0,4.8,110.74],[1,4.9,126.79],[2,5,123.81]],"ltp":4.4,"tv":22148.32,"id":9629022}]}]}
{"op":"mcm","clk":"4215325746","pt":1631537826425,"mc":[{"id":"1.187557985","rc":[{"batb":[[0,1.27,608.87],[1,1.26,1440.99],[2,1.25,1050.08]],"batl":[[1,1.31,74.5],[2,1.32,80.36]],"ltp":1.29,"tv":44499.26,"id":5300820},{"batb":[[0,4.2,2.57],[1,4.1,2.54],[2,4,2.79]],"ltp":4.4,"tv":22148.32,"id":9629022}]}]}
{"op":"mcm","clk":"4215325902","pt":1631537828601,"mc":[{"id":"1.187557985","rc":[{"batb":[[2,1.25,1411.75]],"ltp":1.29,"tv":44499.26,"id":5300820},{"batl":[[0,4.8,112.74]],"ltp":4.4,"tv":22148.32,"id":9629022}]}]}
{"op":"mcm","clk":"4215325950","pt":1631537829327,"mc":[{"id":"1.187557985","rc":[{"trd":[[1.29,715.9]],"batb":[[0,1.27,618.87],[1,1.26,1449.99]],"batl":[[0,1.29,231.5]],"ltp":1.29,"tv":44502.8,"id":5300820}],"tv":66651.12}]}
{"op":"mcm","clk":"4215326120","pt":1631537831520,"mc":[{"id":"1.187557985","rc":[{"trd":[[1.29,741.82]],"batb":[[1,1.26,996.58],[2,1.25,512]],"batl":[[0,1.31,74.5],[1,1.32,80.36],[2,1.33,304.48]],"ltp":1.29,"tv":44528.72,"id":5300820},{"batl":[[0,4.8,4.27],[1,4.9,2.05],[2,6,3]],"ltp":4.4,"tv":22148.32,"id":9629022}],"tv":66677.04}]}
{"op":"mcm","clk":"4215326134","pt":1631537831832,"mc":[{"id":"1.187557985","rc":[{"batl":[[0,1.33,304.48],[1,1.34,363.42],[2,1.35,416.07]],"ltp":1.29,"tv":44528.72,"id":5300820},{"batb":[[0,4,2.79],[1,3.9,117.5],[2,3.85,144.02]],"ltp":4.4,"tv":22148.32,"id":9629022}]}]}
{"op":"mcm","clk":"4215326241","pt":1631537833650,"mc":[{"id":"1.187557985","rc":[{"trd":[[1.33,27.84]],"batb":[[0,1.3,59.58],[1,1.29,2965.12],[2,1.28,2877.92]],"batl":[[0,1.33,295.94]],"ltp":1.33,"tv":44537.26,"id":5300820},{"trd":[[4,8.42]],"batb":[[0,3.9,1098.28],[1,3.85,1095.94],[2,3.8,1213.06]],"batl":[[0,4.4,5.84],[1,4.8,4.27],[2,4.9,2.05]],"ltp":4.0,"tv":22156.74,"id":9629022}],"tv":66694.0}]}
{"op":"mcm","clk":"4215326316","pt":1631537834634,"mc":[{"id":"1.187557985","rc":[{"batb":[[0,1.32,284.51],[1,1.3,622.75],[2,1.29,1940.45]],"ltp":1.33,"tv":44537.26,"id":5300820},{"batb":[[0,3.9,387.22],[1,3.85,405.8],[2,3.8,522.92]],"batl":[[1,4.7,21.35],[2,4.8,4.27]],"ltp":4.0,"tv":22156.74,"id":9629022}]}]}
{"op":"mcm","clk":"4215326373","pt":1631537835412,"mc":[{"id":"1.187557985","rc":[{"batl":[[0,1.33,325.94]],"ltp":1.33,"tv":44537.26,"id":5300820},{"batb":[[0,4,10],[1,3.9,387.22],[2,3.85,405.8]],"batl":[[0,4.4,8.84],[1,4.7,18.59]],"ltp":4.0,"tv":22156.74,"id":9629022}]}]}
{"op":"mcm","clk":"4215326455","pt":1631537836623,"mc":[{"id":"1.187557985","rc":[{"trd":[[1.32,599.04]],"batb":[[0,1.32,232],[1,1.31,9],[2,1.3,632.75]],"ltp":1.32,"tv":44642.25,"id":5300820},{"batl":[[0,4.3,3],[1,4.4,8.84],[2,4.7,18.59]],"ltp":4.0,"tv":22156.74,"id":9629022}],"tv":66798.99}]}
{"op":"mcm","clk":"4215326605","pt":1631537838608,"mc":[{"id":"1.187557985","rc":[{"trd":[[1.33,33.47]],"batb":[[0,1.32,292],[1,1.31,83.63],[2,1.3,1188.12]],"batl":[[0,1.33,442.87],[1,1.34,427.75]],"ltp":1.33,"tv":44647.87,"id":5300820},{"trd":[[4,10.22]],"batb":[[0,4,9.1]],"batl":[[1,4.4,172.92]],"ltp":4.0,"tv":22158.54,"id":9629022}],"tv":66806.41}]}
{"op":"mcm","clk":"4215326621","pt":1631537838816,"mc":[{"id":"1.187557985","rc":[{"batl":[[2,4.7,3]],"ltp":4.0,"tv":22158.54,"id":9629022}]}]}
{"op":"mcm","clk":"4215326721","pt":1631537840421,"mc":[{"id":"1.187557985","rc":[{"batb":[[1,1.31,570.01]],"ltp":1.33,"tv":44647.87,"id":5300820},{"batl":[[0,4.3,151.17]],"ltp":4.0,"tv":22158.54,"id":9629022}]}]}
{"op":"mcm","clk":"4215326751","pt":1631537841143,"mc":[{"id":"1.187557985","rc":[{"batl":[[0,4.2,21.35],[1,4.3,151.17],[2,4.4,172.92]],"ltp":4.0,"tv":22158.54,"id":9629022}]}]}
{"op":"mcm","clk":"4215326799","pt":1631537842040,"mc":[{"id":"1.187557985","rc":[{"batb":[[0,1.32,490]],"batl":[[1,1.34,876.64]],"ltp":1.33,"tv":44647.87,"id":5300820},{"batb":[[1,3.9,541.46]],"ltp":4.0,"tv":22158.54,"id":9629022}]}]}
{"op":"mcm","clk":"4215326882","pt":1631537843538,"mc":[{"id":"1.187557985","rc":[{"batb":[[0,1.32,329.59],[1,1.31,74.63],[2,1.29,15]],"batl":[[0,1.33,214.97],[1,1.34,64.33],[2,1.38,62.75]],"ltp":1.33,"tv":44647.87,"id":5300820},{"batb":[[1,3.6,3.09],[2,3.55,3]],"batl":[[0,4.6,118.67],[1,4.7,127],[2,4.8,153.34]],"ltp":4.0,"tv":22158.54,"id":9629022}]}]}
{"op":"mcm","clk":"4215326942","pt":1631537844457,"mc":[{"id":"1.187557985","rc":[{"trd":[[1.33,33.84]],"batb":[[0,1.32,60],[1,1.29,15],[2,1.28,1307.72]],"batl":[[0,1.33,119.74],[1,1.38,62.75],[2,1.39,8]],"ltp":1.33,"tv":44648.25,"id":5300820},{"batb":[[0,3.6,3.09],[1,3.55,3],[2,3.45,137.4]],"batl":[[0,4.6,102.86]],"ltp":4.0,"tv":22158.54,"id":9629022}],"tv":66806.79}]}
{"op":"mcm","clk":"4215326968","pt":1631537844824,"mc":[{"id":"1.187557985","rc":[{"trd":[[1.33,69.92]],"batl":[[0,1.33,101.7]],"ltp":1.33,"tv":44684.33,"id":5300820}],"tv":66842.87}]}
{"op":"mcm","clk":"4215327064","pt":1631537846531,"mc":[{"id":"1.187557985","rc":[{"trd":[[1.33,155.1]],"batb":[[0,1.29,15],[1,1.28,967.81],[2,1.27,1386.22]],"batl":[[0,1.39,8],[1,1.4,260.82],[2,1.41,727.5]],"ltp":1.33,"tv":44769.51,"id":5300820},{"batb":[[0,3.55,3],[1,3.45,137.4],[2,3.4,145.2]],"ltp":4.0,"tv":22158.54,"id":9629022}],"tv":66928.05}]}
{"op":"mcm","clk":"4215327256","pt":1631537849636,"mc":[{"id":"1.187557985","rc":[{"batb":[[0,1.29,15.19]],"batl":[[0,1.38,70.25],[1,1.39,8],[2,1.41,55.5]],"ltp":1.33,"tv":44769.51,"id":5300820},{"batb":[[0,3.6,5.74],[1,3.55,3],[2,3.5,3]],"ltp":4.0,"tv":22158.54,"id":9629022}]}]}
{"op":"mcm","clk":"4215327292","pt":1631537850152,"mc":[{"id":"1.187557985","rc":[{"trd":[[1.33,155.48]],"batb":[[0,1.29,15],[1,1.28,455.81],[2,1.27,874.22]],"batl":[[0,1.38,6]],"ltp":1.33,"tv":44769.88,"id":5300820},{"batb":[[0,3.6,3]],"ltp":4.0,"tv":22158.54,"id":9629022}],"tv":66928.42}]}
{"op":"mcm","clk":"4215327405","pt":1631537851615,"mc":[{"id":"1.187557985","rc":[{"trd":[[1.29,771.82]],"batb":[[0,1.27,874.22],[1,1.26,1173.74],[2,1.25,579.53]],"batl":[[0,1.3,2942.3],[1,1.31,2855.76],[2,1.32,2855.76]],"ltp":1.29,"tv":44799.88,"id":5300820},{"batl":[[0,4.7,127],[1,4.8,153.34],[2,4.9,2.05]],"ltp":4.0,"tv":22158.54,"id":9629022}],"tv":66958.42}]}
{"op":"mcm","clk":"4215327468","pt":1631537852653,"mc":[{"id":"1.187557985","rc":[{"trd":[[1.29,789.32]],"batl":[[0,1.29,458.03],[1,1.3,1890.58],[2,1.31,1427.88]],"ltp":1.29,"tv":44817.38,"id":5300820},{"trd":[[4.4,6.03]],"batb":[[0,3.8,320.41],[1,3.6,3],[2,3.55,3]],"ltp":4.4,"tv":22163.67,"id":9629022}],"tv":66981.05}]}
{"op":"mcm","clk":"4215327523","pt":1631537853540,"mc":[{"id":"1.187557985","rc":[{"batl":[[0,1.29,676.57]],"ltp":1.29,"tv":44817.38,"id":5300820},{"batb":[[0,4.5,8.57],[1,4.2,93.55],[2,3.65,3]],"ltp":4.4,"tv":22163.67,"id":9629022}]}]}
{"op":"mcm","clk":"4215327605","pt":1631537854832,"mc":[{"id":"1.187557985","rc":[{"batb":[[0,1.27,913.32]],"ltp":1.29,"tv":44817.38,"id":5300820},{"batl":[[0,4.7,137.36]],"ltp":4.4,"tv":22163.67,"id":9629022}]}]}
{"op":"mcm","clk":"4215327720","pt":1631537856649,"mc":[{"id":"1.187557985","rc":[{"batl":[[0,1.29,706.57],[1,1.3,2467.24]],"ltp":1.29,"tv":44817.38,"id":5300820},{"batb":[[1,4.3,203.04],[2,4.2,93.55]],"ltp":4.4,"tv":22163.67,"id":9629022}]}]}
{"op":"mcm","clk":"4215327737","pt":1631537856972,"mc":[{"id":"1.187557985","rc":[{"batb":[[1,4.4,64.07],[2,4.3,203.04]],"ltp":4.4,"tv":22163.67,"id":9629022}]}]}
{"op":"mcm","clk":"4215327831","pt":1631537858933,"mc":[{"id":"1.187557985","rc":[{"batl":[[0,1.29,968.44]],"ltp":1.29,"tv":44817.38,"id":5300820},{"batb":[[1,4.4,204.91]],"ltp":4.4,"tv":22163.67,"id":9629022}]}]}
{"op":"mcm","clk":"4215327904","pt":1631537860141,"mc":[{"id":"1.187557985","rc":[{"batb":[[1,4.4,140.84]],"ltp":4.4,"tv":22163.67,"id":9629022}]}]}
{"op":"mcm","clk":"4215328035","pt":1631537862473,"mc":[{"id":"1.187557985","rc":[{"batl":[[0,1.28,220.25],[1,1.29,968.44],[2,1.3,2467.24]],"ltp":1.29,"tv":44817.38,"id":5300820}]}]}
{"op":"mcm","clk":"4215328068","pt":1631537862832,"mc":[{"id":"1.187557985","rc":[{"trd":[[1.28,163.1]],"batl":[[0,1.28,175.35],[1,1.29,1138.8]],"ltp":1.28,"tv":44907.19,"id":5300820},{"trd":[[4.5,4.64]],"batb":[[0,4.5,6.25]],"ltp":4.5,"tv":22168.31,"id":9629022}],"tv":67075.51}]}
{"op":"mcm","clk":"4215328124","pt":1631537863669,"mc":[{"id":"1.187557985","rc":[{"batb":[[0,1.27,1083.68]],"ltp":1.28,"tv":44907.19,"id":5300820}]}]}
{"op":"mcm","clk":"4215328243","pt":1631537865339,"mc":[{"id":"1.187557985","rc":[{"trd":[[1.28,338.45]],"batl":[[0,1.29,1138.8],[1,1.3,2467.24],[2,1.31,1427.88]],"ltp":1.28,"tv":45082.54,"id":5300820},{"trd":[[4.4,115.46],[4.5,67.02]],"batb":[[0,4.4,86.12],[1,4.3,203.04],[2,4.2,93.55]],"ltp":4.4,"tv":22340.12,"id":9629022}],"tv":67422.67}]}
{"op":"mcm","clk":"4215328288","pt":1631537865963,"mc":[{"id":"1.187557985","rc":[{"batb":[[0,4.5,2.32],[1,4.4,86.12],[2,4.3,203.04]],"ltp":4.4,"tv":22340.12,"id":9629022}]}]}
{"op":"mcm","clk":"4215328438","pt":1631537868464,"mc":[{"id":"1.187557985","rc":[{"trd":[[4.7,14.65]],"batl":[[0,4.7,130.04]],"ltp":4.7,"tv":22354.76,"id":9629022}],"tv":67437.31}]}
{"op":"mcm","clk":"4215328590","pt":1631537870351,"mc":[{"id":"1.187557985","rc":[{"trd":[[1.29,797.88]],"batb":[[2,1.25,550.53]],"batl":[[0,1.29,1134.52]],"ltp":1.29,"tv":45091.1,"id":5300820}],"tv":67445.87}]}
{"op":"mcm","clk":"4215328675","pt":1631537871556,"mc":[{"id":"1.187557985","rc":[{"batb":[[1,4.4,92.37]],"ltp":4.7,"tv":22354.76,"id":9629022}]}]}
{"op":"mcm","clk":"4215328710","pt":1631537872073,"mc":[{"id":"1.187557985","rc":[{"trd":[[1.27,9.15]],"batb":[[0,1.27,1079.11]],"ltp":1.27,"tv":45100.25,"id":5300820}],"tv":67455.02}]}
{"op":"mcm","clk":"4215328837","pt":1631537874177,"mc":[{"id":"1.187557985","rc":[{"trd":[[1.29,804.1]],"batl":[[0,1.29,1131.41]],"ltp":1.29,"tv":45106.46,"id":5300820},{"trd":[[4.5,68.85]],"batb":[[0,4.5,1.41]],"ltp":4.5,"tv":22356.59,"id":9629022}],"tv":67463.06}]}
{"op":"mcm","clk":"4215328901","pt":1631537875060,"mc":[{"id":"1.187557985","rc":[{"trd":[[1.29,810.06]],"batl":[[0,1.29,1128.43]],"ltp":1.29,"tv":45112.43,"id":5300820},{"trd":[[4.4,116.04],[4.5,71.67]],"batb":[[0,4.4,92.08],[1,4.3,203.04],[2,4.2,93.55]],"ltp":4.4,"tv":22359.99,"id":9629022}],"tv":67472.42}]}
{"op":"mcm","clk":"4215329000","pt":1631537876562,"mc":[{"id":"1.187557985","rc":[{"trd":[[1.29,1010.06]],"batb":[[0,1.28,40],[1,1.27,908.75],[2,1.26,1173.74]],"batl":[[0,1.29,858.07]],"ltp":1.29,"tv":45312.43,"id":5300820}],"tv":67672.42}]}
{"op":"mcm","clk":"4215329092","pt":1631537878095,"mc":[{"id":"1.187557985","rc":[{"trd":[[1.29,1014.7]],"batl":[[0,1.29,855.75]],"ltp":1.29,"tv":45317.07,"id":5300820},{"batb":[[0,4.4,94.65]],"ltp":4.4,"tv":22359.99,"id":9629022}],"tv":67677.07}]}
{"op":"mcm","clk":"4215329182","pt":1631537879566,"mc":[{"id":"1.187557985","rc":[{"trd":[[1.28,397.35]],"batb":[[0,1.28,10.55],[2,1.26,1259.03]],"batl":[[0,1.29,898.14]],"ltp":1.28,"tv":45375.97,"id":5300820}],"tv":67735.97}]}
{"op":"mcm","clk":"4215329232","pt":1631537880516,"mc":[{"id":"1.187557985","rc":[{"trd":[[1.29,1017.4]],"batb":[[0,1.28,95.73]],"batl":[[0,1.29,896.79]],"ltp":1.29,"tv":45378.67,"id":5300820}],"tv":67738.66}]}
{"op":"mcm","clk":"4215329299","pt":1631537881567,"mc":[{"id":"1.187557985","rc":[{"trd":[[1.28,401.35]],"batb":[[0,1.28,93.73]],"ltp":1.28,"tv":45382.67,"id":5300820},{"trd":[[4.4,180.84]],"batb":[[0,4.4,62.3]],"ltp":4.4,"tv":22424.79,"id":9629022}],"tv":67807.46}]}
{"op":"mcm","clk":"4215329369","pt":1631537882565,"mc":[{"id":"1.187557985","rc":[{"batb":[[1,1.27,917.75],[2,1.26,1267.03]],"batl":[[0,1.29,1067.15]],"ltp":1.28,"tv":45382.67,"id":5300820}]}]}
{"op":"mcm","clk":"4215329413","pt":1631537883250,"mc":[{"id":"1.187557985","rc":[{"batb":[[1,1.27,1088.11]],"ltp":1.28,"tv":45382.67,"id":5300820}]}]}
{"op":"mcm","clk":"4215329457","pt":1631537884044,"mc":[{"id":"1.187557985","rc":[{"trd":[[1.29,1017.42]],"batl":[[0,1.29,1067.14]],"ltp":1.29,"tv":45382.69,"id":5300820}],"tv":67807.48}]}
{"op":"mcm","clk":"4215329509","pt":1631537885052,"mc":[{"id":"1.187557985","rc":[{"trd":[[1.29,1017.53]],"batl":[[0,1.29,1067.08]],"ltp":1.29,"tv":45382.8,"id":5300820}],"tv":67807.6}]}
{"op":"mcm","clk":"4215329721","pt":1631537888476,"mc":[{"id":"1.187557985","rc":[{"trd":[[1.28,413.77]],"batb":[[0,1.28,87.52]],"ltp":1.28,"tv":45395.22,"id":5300820}],"tv":67820.02}]}
{"op":"mcm","clk":"4215329742","pt":1631537888734,"mc":[{"id":"1.187557985","rc":[{"trd":[[1.29,1017.59]],"batl":[[0,1.29,1067.05]],"ltp":1.29,"tv":45395.28,"id":5300820}],"tv":67820.07}]}
{"op":"mcm","clk":"4215329858","pt":1631537890631,"mc":[{"id":"1.187557985","rc":[{"trd":[[1.29,1020.19]],"batl":[[0,1.29,1065.75]],"ltp":1.29,"tv":45397.88,"id":5300820}],"tv":67822.68}]}
{"op":"mcm","clk":"4215329862","pt":1631537890734,"mc":[{"id":"1.187557985","rc":[{"trd":[[1.29,1020.27]],"batl":[[0,1.29,1065.71]],"ltp":1.29,"tv":45397.96,"id":5300820}],"tv":67822.75}]}
{"op":"mcm","clk":"4215329928","pt":1631537891841,"mc":[{"id":"1.187557985","rc":[{"trd":[[1.29,1063.66]],"batl":[[0,1.29,1044.01]],"ltp":1.29,"tv":45441.35,"id":5300820}],"tv":67866.14}]}
{"op":"mcm","clk":"4215330053","pt":1631537893838,"mc":[{"id":"1.187557985","rc":[{"trd":[[1.28,416.56]],"batb":[[0,1.28,86.13]],"ltp":1.28,"tv":45444.14,"id":5300820}],"tv":67868.93}]}
{"op":"mcm","clk":"4215330205","pt":1631537896251,"mc":[{"id":"1.187557985","rc":[{"batb":[[2,1.26,1259.03]],"ltp":1.28,"tv":45444.14,"id":5300820},{"batl":[[0,4.5,2.13],[1,4.7,130.04],[2,4.8,153.34]],"ltp":4.4,"tv":22424.79,"id":9629022}]}]}
{"op":"mcm","clk":"4215330342","pt":1631537898457,"mc":[{"id":"1.187557985","rc":[{"batb":[[0,1.28,88.4]],"ltp":1.28,"tv":45444.14,"id":5300820}]}]}
{"op":"mcm","clk":"4215330407","pt":1631537899451,"mc":[{"id":"1.187557985","rc":[{"batb":[[2,1.26,1270.03]],"ltp":1.28,"tv":45444.14,"id":5300820},{"trd":[[4.5,75.67]],"batl":[[0,4.7,130.16],[1,4.8,153.34],[2,4.9,2.05]],"ltp":4.5,"tv":22428.79,"id":9629022}],"tv":67872.93}]}
{"op":"mcm","clk":"4215330554","pt":1631537901343,"mc":[{"id":"1.187557985","rc":[{"trd":[[1.29,1067.53]],"batl":[[0,1.29,1042.08]],"ltp":1.29,"tv":45448.0,"id":5300820}],"tv":67876.8}]}
{"op":"mcm","clk":"4215330664","pt":1631537902554,"mc":[{"id":"1.187557985","rc":[{"trd":[[4.5,75.93]],"batl":[[0,4.7,130.04]],"ltp":4.5,"tv":22429.05,"id":9629022}],"tv":67877.05}]}
{"op":"mcm","clk":"4215331061","pt":1631537908352,"mc":[{"id":"1.187557985","rc":[{"trd":[[1.29,1067.58]],"batl":[[0,1.29,1042.05]],"ltp":1.29,"tv":45448.06,"id":5300820}],"tv":67877.11}]}
{"op":"mcm","clk":"4215331641","pt":1631537917476,"mc":[{"id":"1.187557985","rc":[{"trd":[[1.29,1067.6]],"batb":[[2,1.26,1259.03]],"batl":[[0,1.29,1042.04]],"ltp":1.29,"tv":45448.08,"id":5300820}],"tv":67877.13}]}
{"op":"mcm","clk":"4215331818","pt":1631537920514,"mc":[{"id":"1.187557985","rc":[{"batb":[[2,1.26,1268.03]],"ltp":1.29,"tv":45448.08,"id":5300820}]}]}
{"op":"mcm","clk":"4215331924","pt":1631537922406,"mc":[{"id":"1.187557985","rc":[{"trd":[[1.29,1068.12]],"batl":[[0,1.29,1041.78]],"ltp":1.29,"tv":45448.6,"id":5300820}],"tv":67877.65}]}
{"op":"mcm","clk":"4215332132","pt":1631537925809,"mc":[{"id":"1.187557985","rc":[{"batb":[[2,1.26,1287.95]],"ltp":1.29,"tv":45448.6,"id":5300820}]}]}
{"op":"mcm","clk":"4215332630","pt":1631537934525,"mc":[{"id":"1.187557985","rc":[{"batb":[[0,1.28,167.54]],"batl":[[0,1.29,1114.79],[1,1.3,2534.37]],"ltp":1.29,"tv":45448.6,"id":5300820}]}]}
{"op":"mcm","clk":"4215332650","pt":1631537934839,"mc":[{"id":"1.187557985","rc":[{"batb":[[1,1.27,1155.55],[2,1.26,1278.95]],"ltp":1.29,"tv":45448.6,"id":5300820},{"trd":[[4.4,206.84]],"batb":[[0,4.4,49.31]],"ltp":4.4,"tv":22455.05,"id":9629022}],"tv":67903.65}]}
{"op":"mcm","clk":"4215332839","pt":1631537937936,"mc":[{"id":"1.187557985","rc":[{"batb":[[2,1.26,1289.95]],"ltp":1.29,"tv":45448.6,"id":5300820}]}]}
{"op":"mcm","clk":"4215332924","pt":1631537939410,"mc":[{"id":"1.187557985","rc":[{"batb":[[0,1.28,86.13],[1,1.27,1088.11]],"batl":[[0,1.29,1041.78],[1,1.3,2467.24]],"ltp":1.29,"tv":45448.6,"id":5300820}]}]}
{"op":"mcm","clk":"4215333206","pt":1631537943517,"mc":[{"id":"1.187557985","rc":[{"batb":[[0,1.28,88.4]],"ltp":1.29,"tv":45448.6,"id":5300820}]}]}
{"op":"mcm","clk":"4215333439","pt":1631537947335,"mc":[{"id":"1.187557985","rc":[{"trd":[[1.29,1368.12]],"batb":[[2,1.26,1184.74]],"batl":[[0,1.29,891.78]],"ltp":1.29,"tv":45748.6,"id":5300820}],"tv":68203.65}]}
{"op":"mcm","clk":"4215333497","pt":1631537948225,"mc":[{"id":"1.187557985","rc":[{"batb":[[1,1.27,1049.01]],"ltp":1.29,"tv":45748.6,"id":5300820},{"batb":[[1,4.3,174.34]],"batl":[[0,4.7,119.68]],"ltp":4.4,"tv":22455.05,"id":9629022}]}]}
{"op":"mcm","clk":"4215333656","pt":1631537950439,"mc":[{"id":"1.187557985","rc":[{"batb":[[1,1.27,1265.66],[2,1.26,1173.74]],"batl":[[0,1.29,951.14]],"ltp":1.29,"tv":45748.6,"id":5300820}]}]}
{"op":"mcm","clk":"4215333833","pt":1631537953635,"mc":[{"id":"1.187557985","rc":[{"batb":[[2,1.26,1183.74]],"ltp":1.29,"tv":45748.6,"id":5300820}]}]}
{"op":"mcm","clk":"4215333951","pt":1631537955770,"mc":[{"id":"1.187557985","rc":[{"trd":[[1.28,493.28]],"batb":[[0,1.28,11.69]],"ltp":1.28,"tv":45825.32,"id":5300820},{"trd":[[4.6,21.34]],"ltp":4.6,"tv":22476.38,"id":9629022}],"tv":68301.71}]}
{"op":"mcm","clk":"4215334240","pt":1631537960042,"mc":[{"id":"1.187557985","rc":[{"batl":[[0,4.7,131.51]],"ltp":4.6,"tv":22476.38,"id":9629022}]}]}
{"op":"mcm","clk":"4215334627","pt":1631537966287,"mc":[{"id":"1.187557985","rc":[{"batb":[[2,1.26,1173.74]],"ltp":1.28,"tv":45825.32,"id":5300820}]}]}
{"op":"mcm","clk":"4215334707","pt":1631537967591,"mc":[{"id":"1.187557985","rc":[{"batb":[[1,1.27,170.36],[2,1.21,476.35]],"batl":[[0,1.29,200.36],[1,1.37,7],[2,1.39,327.3]],"ltp":1.28,"tv":45825.32,"id":5300820},{"batb":[[0,4.4,8.82],[1,3.65,3],[2,3.6,129.09]],"batl":[[0,5.1,14.81],[1,5.8,104.64],[2,5.9,112.48]],"ltp":4.6,"tv":22476.38,"id":9629022}]}]}
{"op":"mcm","clk":"4215334747","pt":1631537968472,"mc":[{"id":"1.187557985","rc":[{"batl":[[0,1.29,170.36]],"ltp":1.28,"tv":45825.32,"id":5300820},{"batb":[[0,3.65,3],[1,3.6,129.09],[2,3.55,251.78]],"batl":[[0,5.8,104.64],[1,5.9,112.48],[2,6,125.45]],"ltp":4.6,"tv":22476.38,"id":9629022}]}]}
{"op":"mcm","clk":"4215334802","pt":1631537969464,"mc":[{"id":"1.187557985","rc":[{"trd":[[1.29,1368.24]],"batl":[[0,1.29,170.3]],"ltp":1.29,"tv":45825.44,"id":5300820}],"tv":68301.83}]}
{"op":"mcm","clk":"4215334818","pt":1631537969878,"mc":[{"id":"1.187557985","rc":[{"batl":[[1,1.37,246.65],[2,1.38,312.86]],"ltp":1.29,"tv":45825.44,"id":5300820}]}]}
{"op":"mcm","clk":"4215334892","pt":1631537971130,"mc":[{"id":"1.187557985","rc":[{"trd":[[1.29,1380.82]],"batb":[[0,1.28,9.41]],"batl":[[0,1.29,160.04],[1,1.37,7],[2,1.39,327.3]],"ltp":1.29,"tv":45838.02,"id":5300820},{"trd":[[4.4,209.16]],"ltp":4.4,"tv":22478.71,"id":9629022}],"tv":68316.73}]}
{"op":"mcm","clk":"4215335076","pt":1631537974584,"mc":[{"id":"1.187557985","rc":[{"trd":[[1.28,512.1]],"batb":[[0,1.25,535.58],[1,1.24,571.34]],"batl":[[0,1.28,635.34],[1,1.29,592.54],[2,1.37,7]],"ltp":1.28,"tv":45856.84,"id":5300820}],"tv":68335.55}]}
{"op":"mcm","clk":"4215335125","pt":1631537975365,"mc":[{"id":"1.187557985","rc":[{"batl":[[1,1.29,645.95]],"ltp":1.28,"tv":45856.84,"id":5300820},{"batb":[[0,3.95,15],[1,3.65,3],[2,3.6,129.09]],"batl":[[0,5.7,39.53],[1,5.8,104.64],[2,5.9,112.48]],"ltp":4.4,"tv":22478.71,"id":9629022}]}]}
{"op":"mcm","clk":"4215335161","pt":1631537976555,"mc":[{"id":"1.187557985","rc":[{"trd":[[1.28,519.13]],"batl":[[0,1.28,628.31]],"ltp":1.28,"tv":45863.87,"id":5300820},{"trd":[[4.5,77.93]],"ltp":4.5,"tv":22480.71,"id":9629022}],"tv":68344.58}]}
{"op":"mcm","clk":"4215335244","pt":1631537978165,"mc":[{"id":"1.187557985","rc":[{"batb":[[0,1.25,598.72]],"batl":[[0,1.28,504.28]],"ltp":1.28,"tv":45863.87,"id":5300820}]}]}
{"op":"mcm","clk":"4215335302","pt":1631537979360,"mc":[{"id":"1.187557985","rc":[{"trd":[[1.28,539.91]],"batb":[[0,1.21,476.35],[1,1.2,1128.91],[2,1.19,838.32]],"batl":[[0,1.28,12.26],[1,1.29,160.04]],"ltp":1.28,"tv":45884.65,"id":5300820},{"batb":[[0,3.65,3],[1,3.6,129.09],[2,3.55,251.78]],"batl":[[0,5.8,104.64],[1,5.9,112.48],[2,6,128.45]],"ltp":4.5,"tv":22480.71,"id":9629022}],"tv":68365.36}]}
{"op":"mcm","clk":"4215335342","pt":1631537980195,"mc":[{"id":"1.187557985","rc":[{"trd":[[1.28,547.72]],"batb":[[1,1.2,1028.91]],"batl":[[0,1.28,8.35]],"ltp":1.28,"tv":45892.46,"id":5300820},{"batl":[[2,6,125.45]],"ltp":4.5,"tv":22480.71,"id":9629022}],"tv":68373.18}]}
{"op":"mcm","clk":"4215335454","pt":1631537982604,"mc":[{"id":"1.187557985","rc":[{"batb":[[1,1.2,1446.2],[2,1.19,1588.02]],"batl":[[2,1.37,236.38]],"ltp":1.28,"tv":45892.46,"id":5300820}]}]}
{"op":"mcm","clk":"4215335508","pt":1631537983600,"mc":[{"id":"1.187557985","rc":[{"trd":[[1.28,556.07],[1.29,1396.61]],"batl":[[0,1.29,144.25],[1,1.37,236.38],[2,1.38,312.84]],"ltp":1.29,"tv":45916.6,"id":5300820},{"trd":[[4.4,213.79],[4.5,80.3]],"ltp":4.4,"tv":22487.71,"id":9629022}],"tv":68404.32}]}
{"op":"mcm","clk":"4215335691","pt":1631537987258,"mc":[{"id":"1.187557985","rc":[{"batl":[[1,1.37,7],[2,1.4,5]],"ltp":1.29,"tv":45916.6,"id":5300820},{"batb":[[1,3.55,69.62],[2,3,2]],"ltp":4.4,"tv":22487.71,"id":9629022}]}]}
{"op":"mcm","clk":"4215335764","pt":1631537988463,"mc":[{"id":"1.187557985","rc":[{"batl":[[0,1.37,7],[1,1.4,5],[2,1.5,5]],"ltp":1.29,"tv":45916.6,"id":5300820}]}]}
{"op":"mcm","clk":"4215335842","pt":1631537989663,"mc":[{"id":"1.187557985","rc":[{"batb":[[0,1.2,1446.2],[1,1.19,1588.02],[2,1.18,138.86]],"ltp":1.29,"tv":45916.6,"id":5300820},{"batl":[[0,5.9,112.48],[1,6,125.45],[2,6.4,3]],"ltp":4.4,"tv":22487.71,"id":9629022}]}]}
{"op":"mcm","clk":"4215335919","pt":1631537990603,"mc":[{"id":"1.187557985","rc":[{"batl":[[0,1.22,418.35],[1,1.23,572.58],[2,1.26,483.11]],"ltp":1.29,"tv":45916.6,"id":5300820},{"batb":[[0,5.4,354.16],[1,5.3,343.74],[2,5.2,343.74]],"batl":[[2,6.4,167.36]],"ltp":4.4,"tv":22487.71,"id":9629022}]}]}
{"op":"mcm","clk":"4215335973","pt":1631537991494,"mc":[{"id":"1.187557985","rc":[{"trd":[[1.22,19.2]],"batb":[[1,1.19,1656.84]],"batl":[[0,1.22,399.15],[2,1.24,30]],"ltp":1.22,"tv":45935.8,"id":5300820},{"trd":[[5.5,4.26]],"batb":[[2,5.2,399.89]],"batl":[[2,6.2,13.15]],"ltp":5.5,"tv":22491.97,"id":9629022}],"tv":68427.78}]}
{"op":"mcm","clk":"4215336044","pt":1631537993058,"mc":[{"id":"1.187557985","rc":[{"batb":[[0,1.2,1502.32]],"ltp":1.22,"tv":45935.8,"id":5300820}]}]}
{"op":"mcm","clk":"4215336130","pt":1631537994578,"mc":[{"id":"1.187557985","rc":[{"trd":[[1.22,52.6]],"batb":[[0,1.21,15.37],[1,1.2,1578.61],[2,1.19,1656.84]],"batl":[[0,1.22,442.39]],"ltp":1.22,"tv":45969.21,"id":5300820},{"batb":[[0,5.4,369.16]],"ltp":5.5,"tv":22491.97,"id":9629022}],"tv":68461.18}]}
{"op":"mcm","clk":"4215336172","pt":1631537995307,"mc":[{"id":"1.187557985","rc":[{"trd":[[1.22,62.02]],"batb":[[2,1.19,1725.04]],"batl":[[0,1.22,436.14],[1,1.23,632.35]],"ltp":1.22,"tv":45978.62,"id":5300820},{"trd":[[5.5,4.95]],"ltp":5.5,"tv":22492.65,"id":9629022}],"tv":68471.28}]}
{"op":"mcm","clk":"4215336256","pt":1631537996569,"mc":[{"id":"1.187557985","rc":[{"trd":[[1.22,62.13]],"batb":[[1,1.2,1712.61]],"batl":[[0,1.22,436.08]],"ltp":1.22,"tv":45978.74,"id":5300820}],"tv":68471.4}]}
{"op":"mcm","clk":"4215336303","pt":1631537997666,"mc":[{"id":"1.187557985","rc":[{"batb":[[1,1.2,1914.83]],"ltp":1.22,"tv":45978.74,"id":5300820}]}]}
{"op":"mcm","clk":"4215336339","pt":1631537998496,"mc":[{"id":"1.187557985","rc":[{"batb":[[1,5.3,350.71]],"ltp":5.5,"tv":22492.65,"id":9629022}]}]}
{"op":"mcm","clk":"4215336407","pt":1631537999602,"mc":[{"id":"1.187557985","rc":[{"batb":[[2,1.19,1656.84]],"batl":[[1,1.23,572.58]],"ltp":1.22,"tv":45978.74,"id":5300820}]}]}
{"op":"mcm","clk":"4215336478","pt":1631538000610,"mc":[{"id":"1.187557985","rc":[{"trd":[[1.22,81.65]],"batl":[[0,1.22,426.32]],"ltp":1.22,"tv":45998.26,"id":5300820}],"tv":68490.92}]}
{"op":"mcm","clk":"4215336568","pt":1631538001591,"mc":[{"id":"1.187557985","rc":[{"batl":[[1,1.23,742.94]],"ltp":1.22,"tv":45998.26,"id":5300820}]}]}
{"op":"mcm","clk":"4215336588","pt":1631538001911,"mc":[{"id":"1.187557985","rc":[{"trd":[[1.22,98.69]],"batl":[[0,1.22,417.8]],"ltp":1.22,"tv":46015.3,"id":5300820}],"tv":68507.95}]}
