{"op":"mcm","clk":"4223820844","pt":1631450276579,"mc":[{"id":"1.187553973","marketDefinition":{"bspMarket":false,"turnInPlayEnabled":true,"persistenceEnabled":true,"marketBaseRate":5.0,"eventId":"30895619","eventTypeId":"2","numberOfWinners":1,"bettingType":"ODDS","marketType":"MATCH_ODDS","marketTime":"2021-09-12T14:00:00.000Z","suspendTime":"2021-09-12T14:00:00.000Z","bspReconciled":false,"complete":true,"inPlay":false,"crossMatching":false,"runnersVoidable":false,"numberOfActiveRunners":2,"betDelay":0,"status":"OPEN","runners":[{"status":"ACTIVE","sortPriority":1,"id":9631578,"name":"M Kobori"},{"status":"ACTIVE","sortPriority":2,"id":7429606,"name":"E Bogdan"}],"regulators":["MR_INT"],"countryCode":"GB","discountAllowed":false,"timezone":"GMT","openDate":"2021-09-12T15:00:00.000Z","version":4028154850,"name":"Match Odds","eventName":"M Kobori v E Bogdan"},"rc":[{"batb":[[0,1.01,25]],"ltp":0.0,"tv":0.0,"id":7429606},{"batb":[[0,1.01,25]],"ltp":0.0,"tv":0.0,"id":9631578}]}]}
{"op":"mcm","clk":"4223821190","pt":1631450278363,"mc":[{"id":"1.187553973","marketDefinition":{"bspMarket":false,"turnInPlayEnabled":true,"persistenceEnabled":true,"marketBaseRate":5.0,"eventId":"30895619","eventTypeId":"2","numberOfWinners":1,"bettingType":"ODDS","marketType":"MATCH_ODDS","marketTime":"2021-09-12T14:00:00.000Z","suspendTime":"2021-09-12T14:00:00.000Z","bspReconciled":false,"complete":true,"inPlay":false,"crossMatching":false,"runnersVoidable":false,"numberOfActiveRunners":2,"betDelay":0,"status":"OPEN","runners":[{"status":"ACTIVE","sortPriority":1,"id":9631578,"name":"M Kobori"},{"status":"ACTIVE","sortPriority":2,"id":7429606,"name":"E Bogdan"}],"regulators":["MR_INT"],"countryCode":"GB","discountAllowed":true,"timezone":"GMT","openDate":"2021-09-12T15:00:00.000Z","version":4028154850,"name":"Match Odds","eventName":"M Kobori v E Bogdan"}}]}
{"op":"mcm","clk":"4223907074","pt":1631450694004,"mc":[{"id":"1.187553973","rc":[{"batl":[[0,1.27,20.9]],"ltp":0.0,"tv":0.0,"id":9631578}]}]}
{"op":"mcm","clk":"4223908910","pt":1631450702803,"mc":[{"id":"1.187553973","rc":[{"batl":[[0,1.31,20.9]],"ltp":0.0,"tv":0.0,"id":9631578}]}]}
{"op":"mcm","clk":"4223909863","pt":1631450707225,"mc":[{"id":"1.187553973","rc":[{"batb":[[0,1.01,7]],"ltp":0.0,"tv":0.0,"id":7429606},{"batb":[[0,1.01,7]],"ltp":0.0,"tv":0.0,"id":9631578}]}]}
{"op":"mcm","clk":"4223927230","pt":1631450797898,"mc":[{"id":"1.187553973","rc":[{"batl":[[1,1.57,15.03]],"ltp":0.0,"tv":0.0,"id":9631578}]}]}
{"op":"mcm","clk":"4223929032","pt":1631450807023,"mc":[{"id":"1.187553973","rc":[{"batl":[[2,1.63,21.93]],"ltp":0.0,"tv":0.0,"id":9631578}]}]}
{"op":"mcm","clk":"4223929919","pt":1631450811625,"mc":[{"id":"1.187553973","rc":[{"batl":[[2,1.63,30.57]],"ltp":0.0,"tv":0.0,"id":9631578}]}]}
{"op":"mcm","clk":"4223931363","pt":1631450819639,"mc":[{"id":"1.187553973","rc":[{"batl":[[0,1.33,20.9]],"ltp":0.0,"tv":0.0,"id":9631578}]}]}
{"op":"mcm","clk":"4224532721","pt":1631453803359,"mc":[{"id":"1.187553973","rc":[{"batl":[[1,1.57,32.3],[2,1.63,65.11]],"ltp":0.0,"tv":0.0,"id":9631578}]}]}
{"op":"mcm","clk":"4225282557","pt":1631457649337,"mc":[{"id":"1.187553973","rc":[{"batl":[[0,1.57,32.3],[1,1.63,65.11],[2,1.63,0]],"ltp":0.0,"tv":0.0,"id":9631578}]}]}
{"op":"mcm","clk":"4225282580","pt":1631457649411,"mc":[{"id":"1.187553973","rc":[{"batl":[[0,1.27,20.9],[1,1.57,32.3],[2,1.63,65.11]],"ltp":0.0,"tv":0.0,"id":9631578}]}]}
{"op":"mcm","clk":"4225283917","pt":1631457656130,"mc":[{"id":"1.187553973","rc":[{"batl":[[0,1.27,36.44]],"ltp":0.0,"tv":0.0,"id":9631578}]}]}
{"op":"mcm","clk":"4225505200","pt":1631458877242,"mc":[{"id":"1.187553973","marketDefinition":{"bspMarket":false,"turnInPlayEnabled":true,"persistenceEnabled":true,"marketBaseRate":5.0,"eventId":"30895619","eventTypeId":"2","numberOfWinners":1,"bettingType":"ODDS","marketType":"MATCH_ODDS","marketTime":"2021-09-12T14:00:00.000Z","suspendTime":"2021-09-12T14:00:00.000Z","bspReconciled":false,"complete":true,"inPlay":true,"crossMatching":false,"runnersVoidable":false,"numberOfActiveRunners":2,"betDelay":5,"status":"OPEN","runners":[{"status":"ACTIVE","sortPriority":1,"id":9631578,"name":"M Kobori"},{"status":"ACTIVE","sortPriority":2,"id":7429606,"name":"E Bogdan"}],"regulators":["MR_INT"],"countryCode":"GB","discountAllowed":true,"timezone":"GMT","openDate":"2021-09-12T15:00:00.000Z","version":4028773083,"name":"Match Odds","eventName":"M Kobori v E Bogdan"}}]}
{"op":"mcm","clk":"4225530928","pt":1631459008756,"mc":[{"id":"1.187553973","rc":[{"batl":[[0,1.27,20.9]],"ltp":0.0,"tv":0.0,"id":9631578}]}]}
{"op":"mcm","clk":"4225531972","pt":1631459013826,"mc":[{"id":"1.187553973","rc":[{"batl":[[0,1.26,15.54],[1,1.27,20.9],[2,1.57,32.3]],"ltp":0.0,"tv":0.0,"id":9631578}]}]}
{"op":"mcm","clk":"4225535247","pt":1631459031147,"mc":[{"id":"1.187553973","rc":[{"batl":[[1,1.57,32.3],[2,1.63,65.11]],"ltp":0.0,"tv":0.0,"id":9631578}]}]}
{"op":"mcm","clk":"4225536234","pt":1631459036285,"mc":[{"id":"1.187553973","rc":[{"batl":[[0,1.26,36.44]],"ltp":0.0,"tv":0.0,"id":9631578}]}]}
{"op":"mcm","clk":"4226073797","pt":1631461878467,"mc":[{"id":"1.187553973","rc":[{"batl":[[0,1.14,70.98],[1,1.26,36.44],[2,1.57,32.3]],"ltp":0.0,"tv":0.0,"id":9631578}]}]}
{"op":"mcm","clk":"4226075287","pt":1631461887128,"mc":[{"id":"1.187553973","rc":[{"batl":[[2,1.57,15.03]],"ltp":0.0,"tv":0.0,"id":9631578}]}]}
{"op":"mcm","clk":"4226075889","pt":1631461890716,"mc":[{"id":"1.187553973","rc":[{"batl":[[2,1.57,0]],"ltp":0.0,"tv":0.0,"id":9631578}]}]}
{"op":"mcm","clk":"4226077912","pt":1631461903630,"mc":[{"id":"1.187553973","rc":[{"batl":[[2,1.37,61.48]],"ltp":0.0,"tv":0.0,"id":9631578}]}]}
{"op":"mcm","clk":"4226118776","pt":1631462149803,"mc":[{"id":"1.187553973","marketDefinition":{"bspMarket":false,"turnInPlayEnabled":true,"persistenceEnabled":true,"marketBaseRate":5.0,"eventId":"30895619","eventTypeId":"2","numberOfWinners":1,"bettingType":"ODDS","marketType":"MATCH_ODDS","marketTime":"2021-09-12T15:55:48.000Z","suspendTime":"2021-09-12T15:55:48.000Z","bspReconciled":false,"complete":true,"inPlay":true,"crossMatching":false,"runnersVoidable":false,"numberOfActiveRunners":2,"betDelay":5,"status":"OPEN","runners":[{"status":"ACTIVE","sortPriority":1,"id":9631578,"name":"M Kobori"},{"status":"ACTIVE","sortPriority":2,"id":7429606,"name":"E Bogdan"}],"regulators":["MR_INT"],"countryCode":"GB","discountAllowed":true,"timezone":"GMT","openDate":"2021-09-12T15:00:00.000Z","version":4028980903,"name":"Match Odds","eventName":"M Kobori v E Bogdan"}}]}
{"op":"mcm","clk":"4226122878","pt":1631462175189,"mc":[{"id":"1.187553973","marketDefinition":{"bspMarket":false,"turnInPlayEnabled":true,"persistenceEnabled":true,"marketBaseRate":5.0,"eventId":"30895619","eventTypeId":"2","numberOfWinners":1,"bettingType":"ODDS","marketType":"MATCH_ODDS","marketTime":"2021-09-12T15:55:48.000Z","suspendTime":"2021-09-12T15:55:48.000Z","bspReconciled":false,"complete":true,"inPlay":true,"crossMatching":false,"runnersVoidable":false,"numberOfActiveRunners":2,"betDelay":5,"status":"OPEN","runners":[{"status":"ACTIVE","sortPriority":1,"id":9631578,"name":"M Kobori"},{"status":"ACTIVE","sortPriority":2,"id":7429606,"name":"E Bogdan"}],"regulators":["MR_INT"],"countryCode":"GB","discountAllowed":true,"timezone":"GMT","openDate":"2021-09-12T15:55:48.000Z","version":4028980903,"name":"Match Odds","eventName":"M Kobori v E Bogdan"}}]}
{"op":"mcm","clk":"4226221519","pt":1631462734149,"mc":[{"id":"1.187553973","rc":[{"batl":[[0,1.26,36.44],[1,1.26,0],[2,1.37,0]],"ltp":0.0,"tv":0.0,"id":9631578}]}]}
{"op":"mcm","clk":"4226222429","pt":1631462739256,"mc":[{"id":"1.187553973","rc":[{"batl":[[0,1.15,70.98],[1,1.26,36.44],[2,1.33,61.48]],"ltp":0.0,"tv":0.0,"id":9631578}]}]}
{"op":"mcm","clk":"4226235020","pt":1631462808664,"mc":[{"id":"1.187553973","rc":[{"batl":[[0,1.26,36.44],[1,1.33,61.48],[2,1.33,0]],"ltp":0.0,"tv":0.0,"id":9631578}]}]}
{"op":"mcm","clk":"4226236544","pt":1631462813769,"mc":[{"id":"1.187553973","rc":[{"batl":[[0,1.14,70.98],[1,1.26,36.44],[2,1.33,61.48]],"ltp":0.0,"tv":0.0,"id":9631578}]}]}
{"op":"mcm","clk":"4226300180","pt":1631463130608,"mc":[{"id":"1.187553973","rc":[{"batl":[[0,1.26,36.44],[1,1.33,61.48],[2,1.33,0]],"ltp":0.0,"tv":0.0,"id":9631578}]}]}
{"op":"mcm","clk":"4226301224","pt":1631463135706,"mc":[{"id":"1.187553973","rc":[{"batl":[[0,1.08,70.98],[1,1.26,36.44],[2,1.33,61.48]],"ltp":0.0,"tv":0.0,"id":9631578}]}]}
{"op":"mcm","clk":"4226307642","pt":1631463168784,"mc":[{"id":"1.187553973","rc":[{"batl":[[1,1.33,61.48],[2,1.33,0]],"ltp":0.0,"tv":0.0,"id":9631578}]}]}
{"op":"mcm","clk":"4226308551","pt":1631463173876,"mc":[{"id":"1.187553973","rc":[{"batl":[[0,1.08,140.06],[2,1.61,15.54]],"ltp":0.0,"tv":0.0,"id":9631578}]}]}
{"op":"mcm","clk":"4226309732","pt":1631463180477,"mc":[{"id":"1.187553973","rc":[{"batl":[[1,1.61,15.54],[2,1.61,0]],"ltp":0.0,"tv":0.0,"id":9631578}]}]}
{"op":"mcm","clk":"4226310623","pt":1631463185271,"mc":[{"id":"1.187553973","rc":[{"batl":[[1,1.61,0]],"ltp":0.0,"tv":0.0,"id":9631578}]}]}
{"op":"mcm","clk":"4226310678","pt":1631463185585,"mc":[{"id":"1.187553973","rc":[{"batl":[[1,1.16,61.48]],"ltp":0.0,"tv":0.0,"id":9631578}]}]}
{"op":"mcm","clk":"4226313467","pt":1631463199855,"mc":[{"id":"1.187553973","rc":[{"batl":[[2,1.19,32.3]],"ltp":0.0,"tv":0.0,"id":9631578}]}]}
{"op":"mcm","clk":"4226367940","pt":1631463484561,"mc":[{"id":"1.187553973","rc":[{"batl":[[0,1.08,70.98]],"ltp":0.0,"tv":0.0,"id":9631578}]}]}
{"op":"mcm","clk":"4226370274","pt":1631463495558,"mc":[{"id":"1.187553973","rc":[{"batb":[[0,12,12.43],[1,1.01,7]],"ltp":0.0,"tv":0.0,"id":7429606}]}]}
{"op":"mcm","clk":"4226372256","pt":1631463506156,"mc":[{"id":"1.187553973","rc":[{"batb":[[1,4,13.47],[2,1.01,7]],"ltp":0.0,"tv":0.0,"id":7429606}]}]}
{"op":"mcm","clk":"4226373919","pt":1631463514953,"mc":[{"id":"1.187553973","rc":[{"batb":[[1,6,14.51],[2,4,13.47]],"ltp":0.0,"tv":0.0,"id":7429606}]}]}
{"op":"mcm","clk":"4226403180","pt":1631463670073,"mc":[{"id":"1.187553973","rc":[{"batl":[[0,1.16,61.48],[1,1.19,32.3],[2,1.19,0]],"ltp":0.0,"tv":0.0,"id":9631578}]}]}
{"op":"mcm","clk":"4226404071","pt":1631463675141,"mc":[{"id":"1.187553973","rc":[{"batl":[[0,1.06,70.98],[1,1.16,61.48],[2,1.19,32.3]],"ltp":0.0,"tv":0.0,"id":9631578}]}]}
{"op":"mcm","clk":"4226432353","pt":1631463853872,"mc":[{"id":"1.187553973","rc":[{"batl":[[1,1.5,1.38],[2,1.19,0]],"ltp":0.0,"tv":0.0,"id":9631578}]}]}
{"op":"mcm","clk":"4226433165","pt":1631463859017,"mc":[{"id":"1.187553973","rc":[{"batl":[[1,1.12,61.48],[2,1.14,32.3]],"ltp":0.0,"tv":0.0,"id":9631578}]}]}
{"op":"mcm","clk":"4226453679","pt":1631463993960,"mc":[{"id":"1.187553973","rc":[{"batl":[[0,1.06,122.79]],"ltp":0.0,"tv":0.0,"id":9631578}]}]}
{"op":"mcm","clk":"4226454743","pt":1631464001394,"mc":[{"id":"1.187553973","rc":[{"batl":[[0,1.12,61.48],[1,1.14,32.3],[2,1.5,1.38]],"ltp":0.0,"tv":0.0,"id":9631578}]}]}
{"op":"mcm","clk":"4226455470","pt":1631464006385,"mc":[{"id":"1.187553973","rc":[{"batl":[[0,1.05,122.79],[1,1.12,61.48],[2,1.14,32.3]],"ltp":0.0,"tv":0.0,"id":9631578}]}]}
{"op":"mcm","clk":"4226517106","pt":1631464434923,"mc":[{"id":"1.187553973","rc":[{"batl":[[0,1.12,61.48],[1,1.14,32.3],[2,1.5,1.38]],"ltp":0.0,"tv":0.0,"id":9631578}]}]}
{"op":"mcm","clk":"4226517936","pt":1631464440027,"mc":[{"id":"1.187553973","rc":[{"batl":[[0,1.06,122.79],[1,1.12,61.48],[2,1.14,32.3]],"ltp":0.0,"tv":0.0,"id":9631578}]}]}
{"op":"mcm","clk":"4226551950","pt":1631464661151,"mc":[{"id":"1.187553973","rc":[{"trd":[[12,14.23]],"batb":[[0,12,5.32]],"ltp":12.0,"tv":14.22,"id":7429606}],"tv":14.22}]}
{"op":"mcm","clk":"4226553008","pt":1631464668377,"mc":[{"id":"1.187553973","rc":[{"batl":[[0,1.12,61.48],[1,1.14,32.3],[2,1.5,1.38]],"ltp":0.0,"tv":0.0,"id":9631578}]}]}
{"op":"mcm","clk":"4226553810","pt":1631464673775,"mc":[{"id":"1.187553973","rc":[{"batb":[[0,6,14.51],[1,4,13.47],[2,1.01,7]],"ltp":12.0,"tv":14.22,"id":7429606}]}]}
{"op":"mcm","clk":"4226554868","pt":1631464680783,"mc":[{"id":"1.187553973","rc":[{"batl":[[0,1.14,32.3],[1,1.5,1.38],[2,1.5,0]],"ltp":0.0,"tv":0.0,"id":9631578}]}]}
{"op":"mcm","clk":"4226557743","pt":1631464699279,"mc":[{"id":"1.187553973","rc":[{"batb":[[0,4,13.47],[1,1.01,7],[2,1.01,0]],"ltp":12.0,"tv":14.22,"id":7429606}]}]}
{"op":"mcm","clk":"4226558562","pt":1631464704424,"mc":[{"id":"1.187553973","rc":[{"batb":[[0,7,14.51],[1,4,13.47],[2,1.01,7]],"ltp":12.0,"tv":14.22,"id":7429606}]}]}
{"op":"mcm","clk":"4226560829","pt":1631464720122,"mc":[{"id":"1.187553973","rc":[{"batl":[[1,1.27,43.52],[2,1.5,1.38]],"ltp":0.0,"tv":0.0,"id":9631578}]}]}
{"op":"mcm","clk":"4226562954","pt":1631464734028,"mc":[{"id":"1.187553973","rc":[{"batb":[[0,4,13.47],[1,1.01,7],[2,1.01,0]],"ltp":12.0,"tv":14.22,"id":7429606}]}]}
{"op":"mcm","clk":"4226563734","pt":1631464739105,"mc":[{"id":"1.187553973","rc":[{"batb":[[0,7.8,14.51],[1,4,13.47],[2,1.01,7]],"ltp":12.0,"tv":14.22,"id":7429606}]}]}
{"op":"mcm","clk":"4226565998","pt":1631464753725,"mc":[{"id":"1.187553973","rc":[{"batl":[[1,1.21,78.75],[2,1.27,43.52]],"ltp":0.0,"tv":0.0,"id":9631578}]}]}
{"op":"mcm","clk":"4226594668","pt":1631464949949,"mc":[{"id":"1.187553973","rc":[{"batb":[[0,4,13.47],[1,1.01,7],[2,1.01,0]],"ltp":12.0,"tv":14.22,"id":7429606}]}]}
{"op":"mcm","clk":"4226595432","pt":1631464955015,"mc":[{"id":"1.187553973","rc":[{"batb":[[0,6.8,14.51],[1,4,13.47],[2,1.01,7]],"ltp":12.0,"tv":14.22,"id":7429606}]}]}
{"op":"mcm","clk":"4226596199","pt":1631464961022,"mc":[{"id":"1.187553973","rc":[{"batb":[[0,6.8,7.08]],"ltp":12.0,"tv":14.22,"id":7429606}]}]}
{"op":"mcm","clk":"4226660866","pt":1631465401463,"mc":[{"id":"1.187553973","rc":[{"trd":[[6.8,8.54]],"batb":[[0,6.8,2.81]],"ltp":6.8,"tv":22.76,"id":7429606}],"tv":22.76}]}
{"op":"mcm","clk":"4226679257","pt":1631465536893,"mc":[{"id":"1.187553973","rc":[{"batb":[[0,4,13.47],[1,1.01,7],[2,1.01,0]],"ltp":6.8,"tv":22.76,"id":7429606},{"batl":[[0,1.21,78.75],[1,1.27,43.52],[2,1.5,1.38]],"ltp":0.0,"tv":0.0,"id":9631578}]}]}
{"op":"mcm","clk":"4226679887","pt":1631465542000,"mc":[{"id":"1.187553973","rc":[{"batb":[[0,5.8,2.81],[1,4,13.47],[2,1.01,7]],"ltp":6.8,"tv":22.76,"id":7429606},{"batl":[[0,1.17,32.3],[1,1.21,78.75],[2,1.27,43.52]],"ltp":0.0,"tv":0.0,"id":9631578}]}]}
{"op":"mcm","clk":"4226693465","pt":1631465648757,"mc":[{"id":"1.187553973","rc":[{"batb":[[2,1.25,11.57]],"ltp":6.8,"tv":22.76,"id":7429606}]}]}
{"op":"mcm","clk":"4226694888","pt":1631465659932,"mc":[{"id":"1.187553973","marketDefinition":{"bspMarket":false,"turnInPlayEnabled":true,"persistenceEnabled":true,"marketBaseRate":5.0,"eventId":"30895619","eventTypeId":"2","numberOfWinners":1,"bettingType":"ODDS","marketType":"MATCH_ODDS","marketTime":"2021-09-12T15:55:48.000Z","suspendTime":"2021-09-12T15:55:48.000Z","bspReconciled":false,"complete":true,"inPlay":true,"crossMatching":true,"runnersVoidable":false,"numberOfActiveRunners":2,"betDelay":5,"status":"OPEN","runners":[{"status":"ACTIVE","sortPriority":1,"id":9631578,"name":"M Kobori"},{"status":"ACTIVE","sortPriority":2,"id":7429606,"name":"E Bogdan"}],"regulators":["MR_INT"],"countryCode":"GB","discountAllowed":true,"timezone":"GMT","openDate":"2021-09-12T15:55:48.000Z","version":4028980903,"name":"Match Odds","eventName":"M Kobori v E Bogdan"}}]}
{"op":"mcm","clk":"4226701050","pt":1631465711894,"mc":[{"id":"1.187553973","rc":[{"trd":[[6.8,14.1]],"ltp":6.8,"tv":28.32,"id":7429606},{"trd":[[1.17,32.3]],"batl":[[0,1.21,78.75],[1,1.27,43.52],[2,1.5,1.38]],"ltp":1.17,"tv":32.29,"id":9631578}],"tv":60.62}]}
{"op":"mcm","clk":"4226701149","pt":1631465712686,"mc":[{"id":"1.187553973","rc":[{"batb":[[0,1.17,61.74],[1,1.01,7]],"ltp":1.17,"tv":32.29,"id":9631578}]}]}
{"op":"mcm","clk":"4226703517","pt":1631465731645,"mc":[{"id":"1.187553973","rc":[{"trd":[[1.21,32.52]],"batl":[[0,1.21,62.49]],"ltp":1.21,"tv":64.81,"id":9631578}],"tv":93.14}]}
{"op":"mcm","clk":"4226703896","pt":1631465734726,"mc":[{"id":"1.187553973","rc":[{"batl":[[0,1000,3.42]],"ltp":6.8,"tv":28.32,"id":7429606}]}]}
{"op":"mcm","clk":"4226704646","pt":1631465740816,"mc":[{"id":"1.187553973","rc":[{"trd":[[5.8,5.62]],"batb":[[0,4,13.47],[1,1.25,11.57],[2,1.01,7]],"ltp":5.8,"tv":33.94,"id":7429606}],"tv":98.76}]}
{"op":"mcm","clk":"4226707079","pt":1631465761776,"mc":[{"id":"1.187553973","rc":[{"batb":[[0,1.01,7],[1,1.01,0]],"ltp":1.21,"tv":64.81,"id":9631578}]}]}
{"op":"mcm","clk":"4226707702","pt":1631465766924,"mc":[{"id":"1.187553973","rc":[{"trd":[[1.21,156]],"batl":[[0,1.27,44.27],[1,1.5,1.38],[2,1.5,0]],"ltp":1.21,"tv":188.29,"id":9631578}],"tv":222.24}]}
{"op":"mcm","clk":"4226730114","pt":1631465958244,"mc":[{"id":"1.187553973","rc":[{"batl":[[0,1.27,43.52]],"ltp":1.21,"tv":188.29,"id":9631578}]}]}
{"op":"mcm","clk":"4226730797","pt":1631465963376,"mc":[{"id":"1.187553973","rc":[{"batl":[[0,1.27,20.9]],"ltp":1.21,"tv":188.29,"id":9631578}]}]}
{"op":"mcm","clk":"4226731911","pt":1631465972245,"mc":[{"id":"1.187553973","rc":[{"batb":[[0,1.25,11.57],[1,1.01,7],[2,1.01,0]],"ltp":5.8,"tv":33.94,"id":7429606}]}]}
{"op":"mcm","clk":"4226732586","pt":1631465977361,"mc":[{"id":"1.187553973","rc":[{"batb":[[0,3.85,13.47],[1,1.25,11.57],[2,1.01,7]],"ltp":5.8,"tv":33.94,"id":7429606}]}]}
{"op":"mcm","clk":"4226733323","pt":1631465983208,"mc":[{"id":"1.187553973","rc":[{"batb":[[0,1.25,11.57],[1,1.01,7],[2,1.01,0]],"ltp":5.8,"tv":33.94,"id":7429606}]}]}
{"op":"mcm","clk":"4226733986","pt":1631465988274,"mc":[{"id":"1.187553973","rc":[{"batb":[[0,3.65,13.47],[1,1.25,11.57],[2,1.01,7]],"ltp":5.8,"tv":33.94,"id":7429606}]}]}
{"op":"mcm","clk":"4226755055","pt":1631466134463,"mc":[{"id":"1.187553973","rc":[{"trd":[[1.27,25.69]],"batl":[[0,1.27,8.05]],"ltp":1.27,"tv":213.98,"id":9631578}],"tv":247.93}]}
{"op":"mcm","clk":"4226755628","pt":1631466138289,"mc":[{"id":"1.187553973","rc":[{"trd":[[1.27,41.8]],"batb":[[0,1.27,45.2],[1,1.01,7]],"batl":[[0,1.5,1.38],[1,1.5,0]],"ltp":1.27,"tv":230.09,"id":9631578}],"tv":264.04}]}
{"op":"mcm","clk":"4226755805","pt":1631466139295,"mc":[{"id":"1.187553973","rc":[{"batb":[[0,1.27,12.84]],"ltp":1.27,"tv":230.09,"id":9631578}]}]}
{"op":"mcm","clk":"4226755824","pt":1631466139400,"mc":[{"id":"1.187553973","rc":[{"batb":[[0,1.01,7],[1,1.01,0]],"ltp":1.27,"tv":230.09,"id":9631578}]}]}
{"op":"mcm","clk":"4226766132","pt":1631466207891,"mc":[{"id":"1.187553973","rc":[{"batb":[[0,1.25,11.57],[1,1.01,7],[2,1.01,0]],"ltp":5.8,"tv":33.94,"id":7429606}]}]}
{"op":"mcm","clk":"4226768283","pt":1631466223186,"mc":[{"id":"1.187553973","rc":[{"batl":[[1,1.88,13.99]],"ltp":1.27,"tv":230.09,"id":9631578}]}]}
{"op":"mcm","clk":"4226770475","pt":1631466238501,"mc":[{"id":"1.187553973","rc":[{"batl":[[2,5.9,14.16]],"ltp":1.27,"tv":230.09,"id":9631578}]}]}
{"op":"mcm","clk":"4226771443","pt":1631466245305,"mc":[{"id":"1.187553973","rc":[{"batl":[[2,5.9,0]],"ltp":1.27,"tv":230.09,"id":9631578}]}]}
{"op":"mcm","clk":"4226772246","pt":1631466250392,"mc":[{"id":"1.187553973","rc":[{"batl":[[2,4.7,14.16]],"ltp":1.27,"tv":230.09,"id":9631578}]}]}
{"op":"mcm","clk":"4226773513","pt":1631466258505,"mc":[{"id":"1.187553973","rc":[{"batl":[[2,4.7,31.43]],"ltp":1.27,"tv":230.09,"id":9631578}]}]}
{"op":"mcm","clk":"4226826611","pt":1631466591128,"mc":[{"id":"1.187553973","rc":[{"batl":[[1,4.7,31.43],[2,4.7,0]],"ltp":1.27,"tv":230.09,"id":9631578}]}]}
{"op":"mcm","clk":"4226827463","pt":1631466596215,"mc":[{"id":"1.187553973","rc":[{"batl":[[1,1.68,13.99],[2,4.7,31.43]],"ltp":1.27,"tv":230.09,"id":9631578}]}]}
{"op":"mcm","clk":"4226831946","pt":1631466622037,"mc":[{"id":"1.187553973","rc":[{"batb":[[0,1.01,7],[1,1.01,0]],"ltp":5.8,"tv":33.94,"id":7429606}]}]}
{"op":"mcm","clk":"4226832821","pt":1631466627134,"mc":[{"id":"1.187553973","rc":[{"batb":[[0,1.29,11.57],[1,1.01,7]],"ltp":5.8,"tv":33.94,"id":7429606}]}]}
{"op":"mcm","clk":"4226838307","pt":1631466662493,"mc":[{"id":"1.187553973","rc":[{"batl":[[1,1.68,0],[2,4.7,0]],"ltp":1.27,"tv":230.09,"id":9631578}]}]}
{"op":"mcm","clk":"4226839222","pt":1631466668609,"mc":[{"id":"1.187553973","rc":[{"batb":[[0,1.25,10.85],[1,1.01,7]],"ltp":1.27,"tv":230.09,"id":9631578}]}]}
{"op":"mcm","clk":"4226840429","pt":1631466675805,"mc":[{"id":"1.187553973","rc":[{"trd":[[1.25,16.26]],"batb":[[0,1.25,2.71]],"ltp":1.25,"tv":246.35,"id":9631578}],"tv":280.3}]}
{"op":"mcm","clk":"4226840899","pt":1631466678305,"mc":[{"id":"1.187553973","rc":[{"trd":[[1.25,21.68]],"batb":[[0,1.01,7],[1,1.01,0]],"batl":[[0,1.25,7.21],[1,1.5,1.38]],"ltp":1.25,"tv":251.77,"id":9631578}],"tv":285.72}]}
{"op":"mcm","clk":"4226840971","pt":1631466678673,"mc":[{"id":"1.187553973","rc":[{"batl":[[0,1.5,1.38],[1,1.5,0]],"ltp":1.25,"tv":251.77,"id":9631578}]}]}
{"op":"mcm","clk":"4226842673","pt":1631466688621,"mc":[{"id":"1.187553973","rc":[{"batb":[[0,1.15,18.08],[1,1.01,7]],"ltp":1.25,"tv":251.77,"id":9631578}]}]}
{"op":"mcm","clk":"4226844929","pt":1631466701905,"mc":[{"id":"1.187553973","rc":[{"batl":[[1,1.67,7.23]],"ltp":1.25,"tv":251.77,"id":9631578}]}]}
{"op":"mcm","clk":"4226847892","pt":1631466720221,"mc":[{"id":"1.187553973","rc":[{"batb":[[1,1.02,25.31],[2,1.01,7]],"ltp":1.25,"tv":251.77,"id":9631578}]}]}
{"op":"mcm","clk":"4226848663","pt":1631466724760,"mc":[{"id":"1.187553973","rc":[{"batl":[[1,1.67,0]],"ltp":1.25,"tv":251.77,"id":9631578}]}]}
{"op":"mcm","clk":"4226849532","pt":1631466729859,"mc":[{"id":"1.187553973","rc":[{"batl":[[1,1.59,7.23]],"ltp":1.25,"tv":251.77,"id":9631578}]}]}
{"op":"mcm","clk":"4226855029","pt":1631466762386,"mc":[{"id":"1.187553973","rc":[{"batb":[[0,1.15,13.74]],"ltp":1.25,"tv":251.77,"id":9631578}]}]}
{"op":"mcm","clk":"4226888492","pt":1631466958319,"mc":[{"id":"1.187553973","rc":[{"batb":[[0,1.02,25.31],[1,1.01,7],[2,1.01,0]],"ltp":1.25,"tv":251.77,"id":9631578}]}]}
{"op":"mcm","clk":"4226889145","pt":1631466962111,"mc":[{"id":"1.187553973","rc":[{"batb":[[0,1.02,18.08]],"ltp":1.25,"tv":251.77,"id":9631578}]}]}
{"op":"mcm","clk":"4226889952","pt":1631466966730,"mc":[{"id":"1.187553973","rc":[{"batb":[[0,1.01,7],[1,1.01,0]],"ltp":5.8,"tv":33.94,"id":7429606}]}]}
{"op":"mcm","clk":"4226890841","pt":1631466971824,"mc":[{"id":"1.187553973","rc":[{"batb":[[0,1.12,11.57],[1,1.01,7]],"ltp":5.8,"tv":33.94,"id":7429606}]}]}
{"op":"mcm","clk":"4226890984","pt":1631466972623,"mc":[{"id":"1.187553973","rc":[{"batl":[[0,1.59,7.23],[1,1.59,0]],"ltp":1.25,"tv":251.77,"id":9631578}]}]}
{"op":"mcm","clk":"4226900407","pt":1631467023096,"mc":[{"id":"1.187553973","rc":[{"batl":[[0,1.59,6.51]],"ltp":1.25,"tv":251.77,"id":9631578}]}]}
{"op":"mcm","clk":"4226907127","pt":1631467062151,"mc":[{"id":"1.187553973","rc":[{"trd":[[2.68,3.85]],"ltp":2.68,"tv":37.8,"id":7429606},{"trd":[[1.59,6.49]],"batl":[[0,1.59,0.01]],"ltp":1.59,"tv":258.27,"id":9631578}],"tv":296.07}]}
{"op":"mcm","clk":"4226920863","pt":1631467096086,"mc":[{"id":"1.187553973","rc":[{"batb":[[0,1.12,7.95]],"ltp":2.68,"tv":37.8,"id":7429606}]}]}
{"op":"mcm","clk":"4226931571","pt":1631467157250,"mc":[{"id":"1.187553973","rc":[{"batb":[[0,1.5,2.89],[1,1.12,7.95],[2,1.01,7]],"ltp":2.68,"tv":37.8,"id":7429606}]}]}
{"op":"mcm","clk":"4226941276","pt":1631467211919,"mc":[{"id":"1.187553973","rc":[{"batb":[[0,1.02,7.23]],"ltp":1.59,"tv":258.27,"id":9631578}]}]}
{"op":"mcm","clk":"4226970113","pt":1631467390560,"mc":[{"id":"1.187553973","rc":[{"batb":[[1,1.12,6.51]],"ltp":2.68,"tv":37.8,"id":7429606}]}]}
{"op":"mcm","clk":"4226972159","pt":1631467403978,"mc":[{"id":"1.187553973","rc":[{"batb":[[0,1.12,6.51],[1,1.01,7],[2,1.01,0]],"ltp":2.68,"tv":37.8,"id":7429606}]}]}
{"op":"mcm","clk":"4226972378","pt":1631467405388,"mc":[{"id":"1.187553973","rc":[{"batb":[[0,1.01,7],[1,1.01,0]],"ltp":2.68,"tv":37.8,"id":7429606}]}]}
{"op":"mcm","clk":"4226973934","pt":1631467415909,"mc":[{"id":"1.187553973","rc":[{"batb":[[0,1.15,10.85],[1,1.02,7.23],[2,1.01,7]],"ltp":1.59,"tv":258.27,"id":9631578}]}]}
{"op":"mcm","clk":"4226975785","pt":1631467428099,"mc":[{"id":"1.187553973","rc":[{"batb":[[0,1.05,2.89],[1,1.01,7]],"ltp":2.68,"tv":37.8,"id":7429606}]}]}
{"op":"mcm","clk":"4226975985","pt":1631467429541,"mc":[{"id":"1.187553973","rc":[{"batb":[[0,1.01,7],[1,1.01,0]],"ltp":2.68,"tv":37.8,"id":7429606}]}]}
{"op":"mcm","clk":"4226977573","pt":1631467439120,"mc":[{"id":"1.187553973","rc":[{"batb":[[0,2,13.01],[1,1.15,10.85],[2,1.02,7.23]],"ltp":1.59,"tv":258.27,"id":9631578}]}]}
{"op":"mcm","clk":"4226980706","pt":1631467459250,"mc":[{"id":"1.187553973","rc":[{"trd":[[1.01,14]],"batl":[[0,1.01,6634.9]],"ltp":1.01,"tv":51.8,"id":7429606}],"tv":310.07}]}
{"op":"mcm","clk":"4226981650","pt":1631467465098,"mc":[{"id":"1.187553973","marketDefinition":{"bspMarket":false,"turnInPlayEnabled":true,"persistenceEnabled":true,"marketBaseRate":5.0,"eventId":"30895619","eventTypeId":"2","numberOfWinners":1,"bettingType":"ODDS","marketType":"MATCH_ODDS","marketTime":"2021-09-12T15:55:48.000Z","suspendTime":"2021-09-12T15:55:48.000Z","bspReconciled":false,"complete":true,"inPlay":true,"crossMatching":true,"runnersVoidable":false,"numberOfActiveRunners":2,"betDelay":5,"status":"SUSPENDED","runners":[{"status":"ACTIVE","sortPriority":1,"id":9631578,"name":"M Kobori"},{"status":"ACTIVE","sortPriority":2,"id":7429606,"name":"E Bogdan"}],"regulators":["MR_INT"],"countryCode":"GB","discountAllowed":true,"timezone":"GMT","openDate":"2021-09-12T15:55:48.000Z","version":4029323558,"name":"Match Odds","eventName":"M Kobori v E Bogdan"}}]}
{"op":"mcm","clk":"4226982432","pt":1631467470309,"mc":[{"id":"1.187553973","tv":0.0}]}
{"op":"mcm","clk":"4226982582","pt":1631467471138,"mc":[{"id":"1.187553973","marketDefinition":{"bspMarket":false,"turnInPlayEnabled":true,"persistenceEnabled":true,"marketBaseRate":5.0,"eventId":"30895619","eventTypeId":"2","numberOfWinners":1,"bettingType":"ODDS","marketType":"MATCH_ODDS","marketTime":"2021-09-12T15:55:48.000Z","suspendTime":"2021-09-12T15:55:48.000Z","bspReconciled":false,"complete":true,"inPlay":true,"crossMatching":false,"runnersVoidable":false,"numberOfActiveRunners":0,"betDelay":5,"status":"CLOSED","settledTime":"2021-09-12T17:24:27.000Z","runners":[{"status":"LOSER","sortPriority":1,"id":9631578,"name":"M Kobori"},{"status":"WINNER","sortPriority":2,"id":7429606,"name":"E Bogdan"}],"regulators":["MR_INT"],"countryCode":"GB","discountAllowed":true,"timezone":"GMT","openDate":"2021-09-12T15:55:48.000Z","version":4029323690,"name":"Match Odds","eventName":"M Kobori v E Bogdan"}}]}
