{"op":"mcm","clk":"4229503647","pt":1631518765917,"mc":[{"id":"1.187595435","marketDefinition":{"bspMarket":false,"turnInPlayEnabled":true,"persistenceEnabled":true,"marketBaseRate":5.0,"eventId":"30897896","eventTypeId":"2","numberOfWinners":1,"bettingType":"ODDS","marketType":"MATCH_ODDS","marketTime":"2021-09-13T08:00:00.000Z","suspendTime":"2021-09-13T08:00:00.000Z","bspReconciled":false,"complete":true,"inPlay":false,"crossMatching":false,"runnersVoidable":false,"numberOfActiveRunners":2,"betDelay":0,"status":"OPEN","runners":[{"status":"ACTIVE","sortPriority":1,"id":9634224,"name":"M Gutierrez Carrasco"},{"status":"ACTIVE","sortPriority":2,"id":11252269,"name":"I Ghioroaie"}],"regulators":["MR_INT"],"countryCode":"GB","discountAllowed":false,"timezone":"GMT","openDate":"2021-09-13T11:00:00.000Z","version":4030167320,"name":"Match Odds","eventName":"M Gutierrez Carrasco v I Ghioroaie"},"rc":[{"batb":[[0,1.01,25]],"ltp":0.0,"tv":0.0,"id":9634224},{"batb":[[0,1.01,25]],"ltp":0.0,"tv":0.0,"id":11252269}]}]}
{"op":"mcm","clk":"4229503712","pt":1631518767640,"mc":[{"id":"1.187595435","marketDefinition":{"bspMarket":false,"turnInPlayEnabled":true,"persistenceEnabled":true,"marketBaseRate":5.0,"eventId":"30897896","eventTypeId":"2","numberOfWinners":1,"bettingType":"ODDS","marketType":"MATCH_ODDS","marketTime":"2021-09-13T08:00:00.000Z","suspendTime":"2021-09-13T08:00:00.000Z","bspReconciled":false,"complete":true,"inPlay":false,"crossMatching":false,"runnersVoidable":false,"numberOfActiveRunners":2,"betDelay":0,"status":"OPEN","runners":[{"status":"ACTIVE","sortPriority":1,"id":9634224,"name":"M Gutierrez Carrasco"},{"status":"ACTIVE","sortPriority":2,"id":11252269,"name":"I Ghioroaie"}],"regulators":["MR_INT"],"countryCode":"GB","discountAllowed":true,"timezone":"GMT","openDate":"2021-09-13T11:00:00.000Z","version":4030167320,"name":"Match Odds","eventName":"M Gutierrez Carrasco v I Ghioroaie"}}]}
{"op":"mcm","clk":"4229517281","pt":1631519123186,"mc":[{"id":"1.187595435","rc":[{"batb":[[0,1.01,7]],"ltp":0.0,"tv":0.0,"id":9634224},{"batb":[[0,1.01,7]],"ltp":0.0,"tv":0.0,"id":11252269}]}]}
{"op":"mcm","clk":"4229593837","pt":1631520828857,"mc":[{"id":"1.187595435","rc":[{"batl":[[0,2.84,106.47]],"ltp":0.0,"tv":0.0,"id":9634224}]}]}
{"op":"mcm","clk":"4229673318","pt":1631522324901,"mc":[{"id":"1.187595435","rc":[{"batl":[[0,2.3,2.66]],"ltp":0.0,"tv":0.0,"id":11252269}]}]}
{"op":"mcm","clk":"4229673588","pt":1631522330508,"mc":[{"id":"1.187595435","rc":[{"batb":[[0,1.2,13.31],[1,1.01,7]],"ltp":0.0,"tv":0.0,"id":11252269}]}]}
{"op":"mcm","clk":"4229713426","pt":1631523136649,"mc":[{"id":"1.187595435","rc":[{"batb":[[0,1.05,880.88],[1,1.01,7]],"ltp":0.0,"tv":0.0,"id":9634224},{"batb":[[0,1.22,195.55],[1,1.2,13.31],[2,1.01,7]],"ltp":0.0,"tv":0.0,"id":11252269}]}]}
{"op":"mcm","clk":"4229714204","pt":1631523151007,"mc":[{"id":"1.187595435","marketDefinition":{"bspMarket":false,"turnInPlayEnabled":true,"persistenceEnabled":true,"marketBaseRate":5.0,"eventId":"30897896","eventTypeId":"2","numberOfWinners":1,"bettingType":"ODDS","marketType":"MATCH_ODDS","marketTime":"2021-09-13T08:00:00.000Z","suspendTime":"2021-09-13T08:00:00.000Z","bspReconciled":false,"complete":true,"inPlay":false,"crossMatching":true,"runnersVoidable":false,"numberOfActiveRunners":2,"betDelay":0,"status":"OPEN","runners":[{"status":"ACTIVE","sortPriority":1,"id":9634224,"name":"M Gutierrez Carrasco"},{"status":"ACTIVE","sortPriority":2,"id":11252269,"name":"I Ghioroaie"}],"regulators":["MR_INT"],"countryCode":"GB","discountAllowed":true,"timezone":"GMT","openDate":"2021-09-13T11:00:00.000Z","version":4030167320,"name":"Match Odds","eventName":"M Gutierrez Carrasco v I Ghioroaie"}}]}
{"op":"mcm","clk":"4229743018","pt":1631523785914,"mc":[{"id":"1.187595435","rc":[{"batb":[[0,2.2,34.8],[1,1.05,880.36],[2,1.01,7]],"batl":[[0,2.84,106.55]],"ltp":0.0,"tv":0.0,"id":9634224},{"batb":[[0,1.57,73.27],[1,1.22,195.44],[2,1.2,13.32]],"batl":[[0,2.3,2.66]],"ltp":0.0,"tv":0.0,"id":11252269}]}]}
{"op":"mcm","clk":"4229802037","pt":1631524784402,"mc":[{"id":"1.187595435","rc":[{"batb":[[0,2.22,2.66],[1,2.2,34.8],[2,1.05,880.36]],"ltp":0.0,"tv":0.0,"id":9634224},{"batb":[[0,1.58,2.66],[1,1.57,73.27],[2,1.22,195.44]],"ltp":0.0,"tv":0.0,"id":11252269}]}]}
{"op":"mcm","clk":"4229824093","pt":1631525175535,"mc":[{"id":"1.187595435","marketDefinition":{"bspMarket":false,"turnInPlayEnabled":true,"persistenceEnabled":true,"marketBaseRate":5.0,"eventId":"30897896","eventTypeId":"2","numberOfWinners":1,"bettingType":"ODDS","marketType":"MATCH_ODDS","marketTime":"2021-09-13T10:55:00.000Z","suspendTime":"2021-09-13T10:55:00.000Z","bspReconciled":false,"complete":true,"inPlay":false,"crossMatching":true,"runnersVoidable":false,"numberOfActiveRunners":2,"betDelay":0,"status":"OPEN","runners":[{"status":"ACTIVE","sortPriority":1,"id":9634224,"name":"M Gutierrez Carrasco"},{"status":"ACTIVE","sortPriority":2,"id":11252269,"name":"I Ghioroaie"}],"regulators":["MR_INT"],"countryCode":"GB","discountAllowed":true,"timezone":"GMT","openDate":"2021-09-13T11:00:00.000Z","version":4030502540,"name":"Match Odds","eventName":"M Gutierrez Carrasco v I Ghioroaie"}}]}
{"op":"mcm","clk":"4229824246","pt":1631525178551,"mc":[{"id":"1.187595435","marketDefinition":{"bspMarket":false,"turnInPlayEnabled":true,"persistenceEnabled":true,"marketBaseRate":5.0,"eventId":"30897896","eventTypeId":"2","numberOfWinners":1,"bettingType":"ODDS","marketType":"MATCH_ODDS","marketTime":"2021-09-13T10:55:00.000Z","suspendTime":"2021-09-13T10:55:00.000Z","bspReconciled":false,"complete":true,"inPlay":false,"crossMatching":true,"runnersVoidable":false,"numberOfActiveRunners":2,"betDelay":0,"status":"OPEN","runners":[{"status":"ACTIVE","sortPriority":1,"id":9634224,"name":"M Gutierrez Carrasco"},{"status":"ACTIVE","sortPriority":2,"id":11252269,"name":"I Ghioroaie"}],"regulators":["MR_INT"],"countryCode":"GB","discountAllowed":true,"timezone":"GMT","openDate":"2021-09-13T10:55:00.000Z","version":4030502540,"name":"Match Odds","eventName":"M Gutierrez Carrasco v I Ghioroaie"}}]}
{"op":"mcm","clk":"4229824349","pt":1631525180410,"mc":[{"id":"1.187595435","rc":[{"batb":[[0,2.24,33.68],[1,2.22,2.66]],"ltp":0.0,"tv":0.0,"id":9634224}]}]}
{"op":"mcm","clk":"4229855940","pt":1631525707769,"mc":[{"id":"1.187595435","rc":[{"batb":[[2,1.01,7]],"ltp":0.0,"tv":0.0,"id":9634224},{"batb":[[2,1.2,13.32]],"ltp":0.0,"tv":0.0,"id":11252269}]}]}
{"op":"mcm","clk":"4229856700","pt":1631525719785,"mc":[{"id":"1.187595435","rc":[{"batb":[[2,1.28,158.46]],"batl":[[1,2.6,44.02]],"ltp":0.0,"tv":0.0,"id":11252269}]}]}
{"op":"mcm","clk":"4229877393","pt":1631526020574,"mc":[{"id":"1.187595435","rc":[{"batb":[[0,2.22,2.66],[1,2.2,34.8]],"ltp":0.0,"tv":0.0,"id":9634224}]}]}
{"op":"mcm","clk":"4229881532","pt":1631526086028,"mc":[{"id":"1.187595435","marketDefinition":{"bspMarket":false,"turnInPlayEnabled":true,"persistenceEnabled":true,"marketBaseRate":5.0,"eventId":"30897896","eventTypeId":"2","numberOfWinners":1,"bettingType":"ODDS","marketType":"MATCH_ODDS","marketTime":"2021-09-13T11:05:00.000Z","suspendTime":"2021-09-13T11:05:00.000Z","bspReconciled":false,"complete":true,"inPlay":false,"crossMatching":true,"runnersVoidable":false,"numberOfActiveRunners":2,"betDelay":0,"status":"OPEN","runners":[{"status":"ACTIVE","sortPriority":1,"id":9634224,"name":"M Gutierrez Carrasco"},{"status":"ACTIVE","sortPriority":2,"id":11252269,"name":"I Ghioroaie"}],"regulators":["MR_INT"],"countryCode":"GB","discountAllowed":true,"timezone":"GMT","openDate":"2021-09-13T10:55:00.000Z","version":4030511772,"name":"Match Odds","eventName":"M Gutierrez Carrasco v I Ghioroaie"}}]}
{"op":"mcm","clk":"4229881587","pt":1631526086794,"mc":[{"id":"1.187595435","rc":[{"batb":[[0,2.24,33.68],[1,2.22,2.66]],"ltp":0.0,"tv":0.0,"id":9634224}]}]}
{"op":"mcm","clk":"4229881988","pt":1631526089043,"mc":[{"id":"1.187595435","marketDefinition":{"bspMarket":false,"turnInPlayEnabled":true,"persistenceEnabled":true,"marketBaseRate":5.0,"eventId":"30897896","eventTypeId":"2","numberOfWinners":1,"bettingType":"ODDS","marketType":"MATCH_ODDS","marketTime":"2021-09-13T11:05:00.000Z","suspendTime":"2021-09-13T11:05:00.000Z","bspReconciled":false,"complete":true,"inPlay":false,"crossMatching":true,"runnersVoidable":false,"numberOfActiveRunners":2,"betDelay":0,"status":"OPEN","runners":[{"status":"ACTIVE","sortPriority":1,"id":9634224,"name":"M Gutierrez Carrasco"},{"status":"ACTIVE","sortPriority":2,"id":11252269,"name":"I Ghioroaie"}],"regulators":["MR_INT"],"countryCode":"GB","discountAllowed":true,"timezone":"GMT","openDate":"2021-09-13T11:05:00.000Z","version":4030511772,"name":"Match Odds","eventName":"M Gutierrez Carrasco v I Ghioroaie"}}]}
{"op":"mcm","clk":"4230155022","pt":1631529655704,"mc":[{"id":"1.187595435","rc":[{"batb":[[0,2.22,2.66],[1,2.2,34.8]],"ltp":0.0,"tv":0.0,"id":9634224}]}]}
{"op":"mcm","clk":"4230157291","pt":1631529683239,"mc":[{"id":"1.187595435","marketDefinition":{"bspMarket":false,"turnInPlayEnabled":true,"persistenceEnabled":true,"marketBaseRate":5.0,"eventId":"30897896","eventTypeId":"2","numberOfWinners":1,"bettingType":"ODDS","marketType":"MATCH_ODDS","marketTime":"2021-09-13T10:45:00.000Z","suspendTime":"2021-09-13T10:45:00.000Z","bspReconciled":false,"complete":true,"inPlay":false,"crossMatching":true,"runnersVoidable":false,"numberOfActiveRunners":2,"betDelay":0,"status":"OPEN","runners":[{"status":"ACTIVE","sortPriority":1,"id":9634224,"name":"M Gutierrez Carrasco"},{"status":"ACTIVE","sortPriority":2,"id":11252269,"name":"I Ghioroaie"}],"regulators":["MR_INT"],"countryCode":"GB","discountAllowed":true,"timezone":"GMT","openDate":"2021-09-13T11:05:00.000Z","version":4030551848,"name":"Match Odds","eventName":"M Gutierrez Carrasco v I Ghioroaie"}}]}
{"op":"mcm","clk":"4230157421","pt":1631529685245,"mc":[{"id":"1.187595435","marketDefinition":{"bspMarket":false,"turnInPlayEnabled":true,"persistenceEnabled":true,"marketBaseRate":5.0,"eventId":"30897896","eventTypeId":"2","numberOfWinners":1,"bettingType":"ODDS","marketType":"MATCH_ODDS","marketTime":"2021-09-13T10:45:00.000Z","suspendTime":"2021-09-13T10:45:00.000Z","bspReconciled":false,"complete":true,"inPlay":false,"crossMatching":true,"runnersVoidable":false,"numberOfActiveRunners":2,"betDelay":0,"status":"OPEN","runners":[{"status":"ACTIVE","sortPriority":1,"id":9634224,"name":"M Gutierrez Carrasco"},{"status":"ACTIVE","sortPriority":2,"id":11252269,"name":"I Ghioroaie"}],"regulators":["MR_INT"],"countryCode":"GB","discountAllowed":true,"timezone":"GMT","openDate":"2021-09-13T10:45:00.000Z","version":4030551848,"name":"Match Odds","eventName":"M Gutierrez Carrasco v I Ghioroaie"}}]}
{"op":"mcm","clk":"4230157515","pt":1631529686345,"mc":[{"id":"1.187595435","rc":[{"batb":[[0,2.24,33.68],[1,2.22,2.66]],"ltp":0.0,"tv":0.0,"id":9634224}]}]}
{"op":"mcm","clk":"4230182664","pt":1631529985401,"mc":[{"id":"1.187595435","marketDefinition":{"bspMarket":false,"turnInPlayEnabled":true,"persistenceEnabled":true,"marketBaseRate":5.0,"eventId":"30897896","eventTypeId":"2","numberOfWinners":1,"bettingType":"ODDS","marketType":"MATCH_ODDS","marketTime":"2021-09-13T10:45:00.000Z","suspendTime":"2021-09-13T10:45:00.000Z","bspReconciled":false,"complete":true,"inPlay":true,"crossMatching":true,"runnersVoidable":false,"numberOfActiveRunners":2,"betDelay":5,"status":"OPEN","runners":[{"status":"ACTIVE","sortPriority":1,"id":9634224,"name":"M Gutierrez Carrasco"},{"status":"ACTIVE","sortPriority":2,"id":11252269,"name":"I Ghioroaie"}],"regulators":["MR_INT"],"countryCode":"GB","discountAllowed":true,"timezone":"GMT","openDate":"2021-09-13T10:45:00.000Z","version":4030555980,"name":"Match Odds","eventName":"M Gutierrez Carrasco v I Ghioroaie"},"rc":[{"batb":[[0,1.01,7],[1,2.22,0],[2,1.01,0]],"ltp":0.0,"tv":0.0,"id":9634224},{"batb":[[0,1.01,7],[1,1.57,0],[2,1.28,0]],"ltp":0.0,"tv":0.0,"id":11252269}]}]}
{"op":"mcm","clk":"4230213357","pt":1631530347875,"mc":[{"id":"1.187595435","marketDefinition":{"bspMarket":false,"turnInPlayEnabled":true,"persistenceEnabled":true,"marketBaseRate":5.0,"eventId":"30897896","eventTypeId":"2","numberOfWinners":1,"bettingType":"ODDS","marketType":"MATCH_ODDS","marketTime":"2021-09-13T10:52:26.000Z","suspendTime":"2021-09-13T10:52:26.000Z","bspReconciled":false,"complete":true,"inPlay":true,"crossMatching":true,"runnersVoidable":false,"numberOfActiveRunners":2,"betDelay":5,"status":"OPEN","runners":[{"status":"ACTIVE","sortPriority":1,"id":9634224,"name":"M Gutierrez Carrasco"},{"status":"ACTIVE","sortPriority":2,"id":11252269,"name":"I Ghioroaie"}],"regulators":["MR_INT"],"countryCode":"GB","discountAllowed":true,"timezone":"GMT","openDate":"2021-09-13T10:45:00.000Z","version":4030561555,"name":"Match Odds","eventName":"M Gutierrez Carrasco v I Ghioroaie"}}]}
{"op":"mcm","clk":"4230213503","pt":1631530349885,"mc":[{"id":"1.187595435","marketDefinition":{"bspMarket":false,"turnInPlayEnabled":true,"persistenceEnabled":true,"marketBaseRate":5.0,"eventId":"30897896","eventTypeId":"2","numberOfWinners":1,"bettingType":"ODDS","marketType":"MATCH_ODDS","marketTime":"2021-09-13T10:52:26.000Z","suspendTime":"2021-09-13T10:52:26.000Z","bspReconciled":false,"complete":true,"inPlay":true,"crossMatching":true,"runnersVoidable":false,"numberOfActiveRunners":2,"betDelay":5,"status":"OPEN","runners":[{"status":"ACTIVE","sortPriority":1,"id":9634224,"name":"M Gutierrez Carrasco"},{"status":"ACTIVE","sortPriority":2,"id":11252269,"name":"I Ghioroaie"}],"regulators":["MR_INT"],"countryCode":"GB","discountAllowed":true,"timezone":"GMT","openDate":"2021-09-13T10:52:26.000Z","version":4030561555,"name":"Match Odds","eventName":"M Gutierrez Carrasco v I Ghioroaie"}}]}
{"op":"mcm","clk":"4230233864","pt":1631530630325,"mc":[{"id":"1.187595435","rc":[{"batb":[[0,1.82,407.57],[1,1.01,7]],"batl":[[1,3.15,203.58]],"ltp":0.0,"tv":0.0,"id":9634224}]}]}
{"op":"mcm","clk":"4230235958","pt":1631530658463,"mc":[{"id":"1.187595435","rc":[{"batb":[[0,1.01,7],[1,1.01,0]],"ltp":0.0,"tv":0.0,"id":9634224}]}]}
{"op":"mcm","clk":"4230236365","pt":1631530663946,"mc":[{"id":"1.187595435","rc":[{"batb":[[0,1.92,401.14],[1,1.01,7]],"ltp":0.0,"tv":0.0,"id":9634224}]}]}
{"op":"mcm","clk":"4230239347","pt":1631530702186,"mc":[{"id":"1.187595435","rc":[{"batl":[[1,3.15,0]],"ltp":0.0,"tv":0.0,"id":9634224}]}]}
{"op":"mcm","clk":"4230239778","pt":1631530708445,"mc":[{"id":"1.187595435","rc":[{"batl":[[1,3.65,173.1]],"ltp":0.0,"tv":0.0,"id":9634224}]}]}
{"op":"mcm","clk":"4230241381","pt":1631530729463,"mc":[{"id":"1.187595435","rc":[{"batb":[[0,1.01,7],[1,1.01,0]],"ltp":0.0,"tv":0.0,"id":9634224}]}]}
{"op":"mcm","clk":"4230241860","pt":1631530735685,"mc":[{"id":"1.187595435","rc":[{"batb":[[0,2.04,400.32],[1,1.01,7]],"ltp":0.0,"tv":0.0,"id":9634224}]}]}
{"op":"mcm","clk":"4230242601","pt":1631530745800,"mc":[{"id":"1.187595435","rc":[{"batl":[[1,3.65,0]],"ltp":0.0,"tv":0.0,"id":9634224}]}]}
{"op":"mcm","clk":"4230242986","pt":1631530751396,"mc":[{"id":"1.187595435","rc":[{"trd":[[2.84,8.66]],"batl":[[0,2.84,102.22]],"ltp":2.84,"tv":8.66,"id":9634224}],"tv":8.66}]}
{"op":"mcm","clk":"4230243034","pt":1631530752012,"mc":[{"id":"1.187595435","rc":[{"batl":[[1,4.2,150.36]],"ltp":2.84,"tv":8.66,"id":9634224}]}]}
{"op":"mcm","clk":"4230243527","pt":1631530759015,"mc":[{"id":"1.187595435","rc":[{"trd":[[2.84,98.82]],"batl":[[0,2.84,57.14]],"ltp":2.84,"tv":98.81,"id":9634224}],"tv":98.81}]}
{"op":"mcm","clk":"4230246235","pt":1631530797666,"mc":[{"id":"1.187595435","rc":[{"batl":[[1,4.2,0]],"ltp":2.84,"tv":98.81,"id":9634224}]}]}
{"op":"mcm","clk":"4230246736","pt":1631530803580,"mc":[{"id":"1.187595435","rc":[{"trd":[[2.84,98.62]],"batb":[[0,2.04,399.53]],"batl":[[0,2.84,57.02],[1,3.65,172.76]],"ltp":2.84,"tv":98.61,"id":9634224}],"tv":98.61}]}
{"op":"mcm","clk":"4230248908","pt":1631530829111,"mc":[{"id":"1.187595435","rc":[{"batl":[[1,3.65,0]],"ltp":2.84,"tv":98.61,"id":9634224}]}]}
{"op":"mcm","clk":"4230249358","pt":1631530834826,"mc":[{"id":"1.187595435","rc":[{"batl":[[1,3.45,182.89]],"ltp":2.84,"tv":98.61,"id":9634224}]}]}
{"op":"mcm","clk":"4230251881","pt":1631530866644,"mc":[{"id":"1.187595435","rc":[{"batb":[[0,1.01,7],[1,1.01,0]],"batl":[[1,3.45,0]],"ltp":2.84,"tv":98.61,"id":9634224}]}]}
{"op":"mcm","clk":"4230252351","pt":1631530871996,"mc":[{"id":"1.187595435","rc":[{"batb":[[0,1.82,406.77],[1,1.01,7]],"batl":[[1,3.15,203.19]],"ltp":2.84,"tv":98.61,"id":9634224}]}]}
{"op":"mcm","clk":"4230261452","pt":1631530986595,"mc":[{"id":"1.187595435","rc":[{"batl":[[1,3.15,0]],"ltp":2.84,"tv":98.61,"id":9634224}]}]}
{"op":"mcm","clk":"4230261920","pt":1631530992536,"mc":[{"id":"1.187595435","rc":[{"batl":[[1,3,216.4]],"ltp":2.84,"tv":98.61,"id":9634224}]}]}
{"op":"mcm","clk":"4230264562","pt":1631531025250,"mc":[{"id":"1.187595435","rc":[{"batb":[[0,1.01,7],[1,1.01,0]],"batl":[[1,3,0]],"ltp":2.84,"tv":98.61,"id":9634224}]}]}
{"op":"mcm","clk":"4230265067","pt":1631531030958,"mc":[{"id":"1.187595435","rc":[{"batb":[[0,1.97,400.31],[1,1.01,7]],"batl":[[1,3.65,172.76]],"ltp":2.84,"tv":98.61,"id":9634224}]}]}
{"op":"mcm","clk":"4230284912","pt":1631531254927,"mc":[{"id":"1.187595435","rc":[{"batb":[[0,1.01,7],[1,1.01,0]],"batl":[[1,3.65,0]],"ltp":2.84,"tv":98.61,"id":9634224}]}]}
{"op":"mcm","clk":"4230285392","pt":1631531260689,"mc":[{"id":"1.187595435","rc":[{"batb":[[0,2.22,389.82],[1,1.01,7]],"batl":[[1,4.6,137.93]],"ltp":2.84,"tv":98.61,"id":9634224}]}]}
{"op":"mcm","clk":"4230285871","pt":1631531266803,"mc":[{"id":"1.187595435","rc":[{"trd":[[2.84,113.86]],"batl":[[0,2.84,41.78]],"ltp":2.84,"tv":113.86,"id":9634224},{"trd":[[1.54,28.11]],"ltp":1.54,"tv":28.1,"id":11252269}],"tv":141.96}]}
{"op":"mcm","clk":"4230287904","pt":1631531292339,"mc":[{"id":"1.187595435","rc":[{"batb":[[0,1.01,7],[1,1.01,0]],"batl":[[1,4.6,0]],"ltp":2.84,"tv":113.86,"id":9634224}]}]}
{"op":"mcm","clk":"4230288393","pt":1631531298582,"mc":[{"id":"1.187595435","rc":[{"trd":[[2.84,124.61]],"batb":[[0,2.38,387.57],[1,1.01,7]],"batl":[[0,2.84,36.4],[1,5.3,120.43]],"ltp":2.84,"tv":124.6,"id":9634224}],"tv":152.71}]}
{"op":"mcm","clk":"4230288470","pt":1631531299551,"mc":[{"id":"1.187595435","rc":[{"trd":[[2.84,178.35]],"batl":[[0,2.84,9.53]],"ltp":2.84,"tv":178.35,"id":9634224}],"tv":206.46}]}
{"op":"mcm","clk":"4230288561","pt":1631531300574,"mc":[{"id":"1.187595435","rc":[{"trd":[[2.84,197.42]],"batb":[[0,2.84,76.19],[1,2.38,387.57],[2,1.01,7]],"batl":[[0,5.3,120.43],[1,5.3,0]],"ltp":2.84,"tv":197.41,"id":9634224}],"tv":225.52}]}
{"op":"mcm","clk":"4230288638","pt":1631531301570,"mc":[{"id":"1.187595435","rc":[{"batb":[[0,2.84,331.29]],"ltp":2.84,"tv":197.41,"id":9634224},{"batl":[[0,1.54,331.28]],"ltp":1.54,"tv":28.1,"id":11252269}]}]}
{"op":"mcm","clk":"4230288728","pt":1631531302555,"mc":[{"id":"1.187595435","rc":[{"batb":[[0,2.84,256.1]],"ltp":2.84,"tv":197.41,"id":9634224}]}]}
{"op":"mcm","clk":"4230288815","pt":1631531303586,"mc":[{"id":"1.187595435","rc":[{"batb":[[0,2.84,130]],"ltp":2.84,"tv":197.41,"id":9634224}]}]}
{"op":"mcm","clk":"4230288912","pt":1631531304580,"mc":[{"id":"1.187595435","rc":[{"batb":[[0,2.84,141.96]],"ltp":2.84,"tv":197.41,"id":9634224}]}]}
{"op":"mcm","clk":"4230288986","pt":1631531305366,"mc":[{"id":"1.187595435","rc":[{"batb":[[0,2.84,85.47]],"ltp":2.84,"tv":197.41,"id":9634224}]}]}
{"op":"mcm","clk":"4230289079","pt":1631531306501,"mc":[{"id":"1.187595435","rc":[{"batb":[[0,2.38,387.57],[1,1.01,7],[2,1.01,0]],"ltp":2.84,"tv":197.41,"id":9634224}]}]}
{"op":"mcm","clk":"4230291256","pt":1631531333208,"mc":[{"id":"1.187595435","rc":[{"batl":[[0,4.6,137.93]],"ltp":2.84,"tv":197.41,"id":9634224}]}]}
{"op":"mcm","clk":"4230294288","pt":1631531367557,"mc":[{"id":"1.187595435","rc":[{"batl":[[0,5.5,116.64]],"ltp":2.84,"tv":197.41,"id":9634224}]}]}
{"op":"mcm","clk":"4230297204","pt":1631531403839,"mc":[{"id":"1.187595435","rc":[{"batb":[[0,1.01,7],[1,1.01,0]],"ltp":2.84,"tv":197.41,"id":9634224}]}]}
{"op":"mcm","clk":"4230297743","pt":1631531410187,"mc":[{"id":"1.187595435","rc":[{"batb":[[0,2.52,386.72],[1,1.01,7]],"ltp":2.84,"tv":197.41,"id":9634224}]}]}
{"op":"mcm","clk":"4230300687","pt":1631531444436,"mc":[{"id":"1.187595435","rc":[{"batb":[[0,1.01,7],[1,1.01,0]],"ltp":2.84,"tv":197.41,"id":9634224}]}]}
{"op":"mcm","clk":"4230313655","pt":1631531591434,"mc":[{"id":"1.187595435","rc":[{"batb":[[0,2.52,386.72],[1,1.01,7]],"batl":[[0,6,107.64]],"ltp":2.84,"tv":197.41,"id":9634224}]}]}
{"op":"mcm","clk":"4230317143","pt":1631531631760,"mc":[{"id":"1.187595435","rc":[{"batl":[[0,5.3,120.43]],"ltp":2.84,"tv":197.41,"id":9634224}]}]}
{"op":"mcm","clk":"4230319512","pt":1631531662410,"mc":[{"id":"1.187595435","rc":[{"batb":[[0,1.01,7],[1,1.01,0]],"ltp":2.84,"tv":197.41,"id":9634224}]}]}
{"op":"mcm","clk":"4230319981","pt":1631531668138,"mc":[{"id":"1.187595435","rc":[{"batb":[[0,2.22,389.82],[1,1.01,7]],"batl":[[0,4.6,137.93]],"ltp":2.84,"tv":197.41,"id":9634224}]}]}
{"op":"mcm","clk":"4230323501","pt":1631531710079,"mc":[{"id":"1.187595435","rc":[{"batb":[[0,1.01,7],[1,1.01,0]],"ltp":2.84,"tv":197.41,"id":9634224}]}]}
{"op":"mcm","clk":"4230323978","pt":1631531715714,"mc":[{"id":"1.187595435","rc":[{"batb":[[0,2.38,387.57],[1,1.01,7]],"batl":[[0,5.3,120.43]],"ltp":2.84,"tv":197.41,"id":9634224}]}]}
{"op":"mcm","clk":"4230327316","pt":1631531758267,"mc":[{"id":"1.187595435","rc":[{"batl":[[0,4.6,137.93]],"ltp":2.84,"tv":197.41,"id":9634224}]}]}
{"op":"mcm","clk":"4230330544","pt":1631531799395,"mc":[{"id":"1.187595435","rc":[{"batb":[[0,1.01,7],[1,1.01,0]],"ltp":2.84,"tv":197.41,"id":9634224}]}]}
{"op":"mcm","clk":"4230331064","pt":1631531805629,"mc":[{"id":"1.187595435","rc":[{"batb":[[0,2.04,399.53],[1,1.01,7]],"batl":[[0,3.9,160.43]],"ltp":2.84,"tv":197.41,"id":9634224}]}]}
{"op":"mcm","clk":"4230346559","pt":1631531907948,"mc":[{"id":"1.187595435","rc":[{"batb":[[0,1.01,7],[1,1.01,0]],"ltp":2.84,"tv":197.41,"id":9634224}]}]}
{"op":"mcm","clk":"4230347086","pt":1631531914092,"mc":[{"id":"1.187595435","rc":[{"batb":[[0,2.22,389.82],[1,1.01,7]],"batl":[[0,4.6,137.93]],"ltp":2.84,"tv":197.41,"id":9634224}]}]}
{"op":"mcm","clk":"4230349851","pt":1631531945371,"mc":[{"id":"1.187595435","rc":[{"batl":[[0,3.9,160.43]],"ltp":2.84,"tv":197.41,"id":9634224}]}]}
{"op":"mcm","clk":"4230351856","pt":1631531969800,"mc":[{"id":"1.187595435","rc":[{"batl":[[0,4.6,137.93]],"ltp":2.84,"tv":197.41,"id":9634224}]}]}
{"op":"mcm","clk":"4230355199","pt":1631532009637,"mc":[{"id":"1.187595435","rc":[{"batb":[[0,1.01,7],[1,1.01,0]],"ltp":2.84,"tv":197.41,"id":9634224}]}]}
{"op":"mcm","clk":"4230355690","pt":1631532015142,"mc":[{"id":"1.187595435","rc":[{"batb":[[0,2.38,387.57],[1,1.01,7]],"batl":[[0,5.3,120.43]],"ltp":2.84,"tv":197.41,"id":9634224}]}]}
{"op":"mcm","clk":"4230358108","pt":1631532044197,"mc":[{"id":"1.187595435","rc":[{"batb":[[0,1.01,7],[1,1.01,0]],"ltp":2.84,"tv":197.41,"id":9634224}]}]}
{"op":"mcm","clk":"4230358628","pt":1631532050396,"mc":[{"id":"1.187595435","rc":[{"batb":[[0,2.52,386.72],[1,1.01,7]],"batl":[[0,6,107.64]],"ltp":2.84,"tv":197.41,"id":9634224}]}]}
{"op":"mcm","clk":"4230368947","pt":1631532165044,"mc":[{"id":"1.187595435","rc":[{"batl":[[0,5.3,120.43]],"ltp":2.84,"tv":197.41,"id":9634224}]}]}
{"op":"mcm","clk":"4230371803","pt":1631532199136,"mc":[{"id":"1.187595435","rc":[{"batl":[[0,6,107.64]],"ltp":2.84,"tv":197.41,"id":9634224}]}]}
{"op":"mcm","clk":"4230375425","pt":1631532241538,"mc":[{"id":"1.187595435","rc":[{"batb":[[0,1.01,7],[1,1.01,0]],"ltp":2.84,"tv":197.41,"id":9634224}]}]}
{"op":"mcm","clk":"4230375933","pt":1631532247440,"mc":[{"id":"1.187595435","rc":[{"batb":[[0,2.72,383.47],[1,1.01,7]],"batl":[[0,7.2,93.45]],"ltp":2.84,"tv":197.41,"id":9634224}]}]}
{"op":"mcm","clk":"4230381999","pt":1631532324922,"mc":[{"id":"1.187595435","rc":[{"batl":[[0,6,107.64]],"ltp":2.84,"tv":197.41,"id":9634224}]}]}
{"op":"mcm","clk":"4230383695","pt":1631532347237,"mc":[{"id":"1.187595435","rc":[{"batl":[[0,5.3,120.43]],"ltp":2.84,"tv":197.41,"id":9634224}]}]}
{"op":"mcm","clk":"4230386670","pt":1631532388397,"mc":[{"id":"1.187595435","rc":[{"batl":[[0,6,107.64]],"ltp":2.84,"tv":197.41,"id":9634224}]}]}
{"op":"mcm","clk":"4230392335","pt":1631532458419,"mc":[{"id":"1.187595435","rc":[{"batl":[[0,8.2,86.64]],"ltp":2.84,"tv":197.41,"id":9634224}]}]}
{"op":"mcm","clk":"4230396581","pt":1631532507158,"mc":[{"id":"1.187595435","rc":[{"batl":[[0,1.4,255.54]],"ltp":1.54,"tv":28.1,"id":11252269}]}]}
{"op":"mcm","clk":"4230403010","pt":1631532590818,"mc":[{"id":"1.187595435","rc":[{"batl":[[0,7.2,93.45]],"ltp":2.84,"tv":197.41,"id":9634224}]}]}
{"op":"mcm","clk":"4230405638","pt":1631532626480,"mc":[{"id":"1.187595435","rc":[{"batl":[[0,8.2,86.64]],"ltp":2.84,"tv":197.41,"id":9634224}]}]}
{"op":"mcm","clk":"4230408672","pt":1631532663050,"mc":[{"id":"1.187595435","rc":[{"batb":[[0,1.01,7],[1,1.01,0]],"ltp":2.84,"tv":197.41,"id":9634224}]}]}
{"op":"mcm","clk":"4230409217","pt":1631532669693,"mc":[{"id":"1.187595435","rc":[{"batb":[[0,2.98,379.45],[1,1.01,7]],"batl":[[0,9.4,79.11]],"ltp":2.84,"tv":197.41,"id":9634224}]}]}
{"op":"mcm","clk":"4230413350","pt":1631532719646,"mc":[{"id":"1.187595435","rc":[{"batl":[[0,10.5,73.32]],"ltp":2.84,"tv":197.41,"id":9634224}]}]}
{"op":"mcm","clk":"4230416592","pt":1631532759288,"mc":[{"id":"1.187595435","rc":[{"batl":[[0,12,68.71]],"ltp":2.84,"tv":197.41,"id":9634224}]}]}
{"op":"mcm","clk":"4230418079","pt":1631532773798,"mc":[{"id":"1.187595435","rc":[{"batl":[[0,1.11,5.06],[1,1.4,255.54]],"ltp":1.54,"tv":28.1,"id":11252269}]}]}
{"op":"mcm","clk":"4230419090","pt":1631532785548,"mc":[{"id":"1.187595435","rc":[{"trd":[[1.11,10.12]],"batb":[[0,1.11,250.48],[1,1.01,7]],"ltp":1.11,"tv":38.23,"id":11252269}],"tv":235.64}]}
{"op":"mcm","clk":"4230419398","pt":1631532788890,"mc":[{"id":"1.187595435","rc":[{"batl":[[0,1.22,255.54]],"ltp":1.11,"tv":38.23,"id":11252269}]}]}
{"op":"mcm","clk":"4230429835","pt":1631532912092,"mc":[{"id":"1.187595435","rc":[{"trd":[[1.22,3.41]],"batl":[[0,1.22,253.83]],"ltp":1.22,"tv":41.63,"id":11252269}],"tv":239.05}]}
{"op":"mcm","clk":"4230434078","pt":1631532958144,"mc":[{"id":"1.187595435","rc":[{"batb":[[0,1.01,7],[1,1.01,0]],"ltp":2.84,"tv":197.41,"id":9634224}]}]}
{"op":"mcm","clk":"4230434649","pt":1631532963851,"mc":[{"id":"1.187595435","rc":[{"batb":[[0,3.4,381.29],[1,1.01,7]],"batl":[[0,15.5,60.46]],"ltp":2.84,"tv":197.41,"id":9634224}]}]}
{"op":"mcm","clk":"4230436411","pt":1631532983244,"mc":[{"id":"1.187595435","rc":[{"batl":[[0,13.5,64.96]],"ltp":2.84,"tv":197.41,"id":9634224}]}]}
{"op":"mcm","clk":"4230437512","pt":1631532995255,"mc":[{"id":"1.187595435","rc":[{"batl":[[0,15.5,60.46]],"ltp":2.84,"tv":197.41,"id":9634224}]}]}
{"op":"mcm","clk":"4230441208","pt":1631533033818,"mc":[{"id":"1.187595435","rc":[{"batl":[[0,18,56.98]],"ltp":2.84,"tv":197.41,"id":9634224}]}]}
{"op":"mcm","clk":"4230444346","pt":1631533070681,"mc":[{"id":"1.187595435","rc":[{"batl":[[0,21,54.22]],"ltp":2.84,"tv":197.41,"id":9634224}]}]}
{"op":"mcm","clk":"4230445171","pt":1631533079986,"mc":[{"id":"1.187595435","rc":[{"batb":[[0,1.01,7],[1,1.01,0]],"ltp":1.22,"tv":41.63,"id":11252269}]}]}
{"op":"mcm","clk":"4230445639","pt":1631533085814,"mc":[{"id":"1.187595435","rc":[{"batl":[[0,1.06,3.34]],"ltp":1.22,"tv":41.63,"id":11252269}]}]}
{"op":"mcm","clk":"4230446019","pt":1631533090122,"mc":[{"id":"1.187595435","rc":[{"batl":[[1,1.16,255.54],[2,1.17,255.54]],"ltp":1.22,"tv":41.63,"id":11252269}]}]}
{"op":"mcm","clk":"4230448286","pt":1631533111248,"mc":[{"id":"1.187595435","rc":[{"batl":[[2,1.17,0]],"ltp":1.22,"tv":41.63,"id":11252269}]}]}
{"op":"mcm","clk":"4230451727","pt":1631533155313,"mc":[{"id":"1.187595435","rc":[{"trd":[[17.5,0.2]],"ltp":17.5,"tv":197.62,"id":9634224},{"trd":[[1.06,3.34]],"batl":[[0,1.16,255.54],[1,1.16,0]],"ltp":1.06,"tv":44.97,"id":11252269}],"tv":242.59}]}
{"op":"mcm","clk":"4230453618","pt":1631533174210,"mc":[{"id":"1.187595435","rc":[{"batl":[[0,18,56.78]],"ltp":17.5,"tv":197.62,"id":9634224}]}]}
{"op":"mcm","clk":"4230454658","pt":1631533187231,"mc":[{"id":"1.187595435","rc":[{"batl":[[0,21,54.04]],"ltp":17.5,"tv":197.62,"id":9634224}]}]}
{"op":"mcm","clk":"4230455575","pt":1631533199266,"mc":[{"id":"1.187595435","rc":[{"batb":[[0,1.01,7],[1,1.01,0]],"ltp":17.5,"tv":197.62,"id":9634224}]}]}
{"op":"mcm","clk":"4230468660","pt":1631533357914,"mc":[{"id":"1.187595435","rc":[{"batb":[[0,3.6,380.36],[1,1.01,7]],"batl":[[0,21,54.04]],"ltp":17.5,"tv":197.62,"id":9634224}]}]}
{"op":"mcm","clk":"4230471541","pt":1631533392338,"mc":[{"id":"1.187595435","rc":[{"batl":[[0,34,46.6]],"ltp":17.5,"tv":197.62,"id":9634224}]}]}
{"op":"mcm","clk":"4230474255","pt":1631533420078,"mc":[{"id":"1.187595435","rc":[{"batl":[[0,21,54.04]],"ltp":17.5,"tv":197.62,"id":9634224}]}]}
{"op":"mcm","clk":"4230477070","pt":1631533450669,"mc":[{"id":"1.187595435","rc":[{"batl":[[0,15.5,60.22]],"ltp":17.5,"tv":197.62,"id":9634224}]}]}
{"op":"mcm","clk":"4230479875","pt":1631533480077,"mc":[{"id":"1.187595435","rc":[{"batl":[[0,21,54.04]],"ltp":17.5,"tv":197.62,"id":9634224}]}]}
{"op":"mcm","clk":"4230483185","pt":1631533512675,"mc":[{"id":"1.187595435","rc":[{"batl":[[0,15.5,60.22]],"ltp":17.5,"tv":197.62,"id":9634224}]}]}
{"op":"mcm","clk":"4230485793","pt":1631533540297,"mc":[{"id":"1.187595435","rc":[{"batl":[[0,12,68.41]],"ltp":17.5,"tv":197.62,"id":9634224}]}]}
{"op":"mcm","clk":"4230494746","pt":1631533628891,"mc":[{"id":"1.187595435","rc":[{"batl":[[0,15.5,60.22]],"ltp":17.5,"tv":197.62,"id":9634224}]}]}
{"op":"mcm","clk":"4230496811","pt":1631533651406,"mc":[{"id":"1.187595435","rc":[{"batl":[[0,21,54.04]],"ltp":17.5,"tv":197.62,"id":9634224}]}]}
{"op":"mcm","clk":"4230498917","pt":1631533673829,"mc":[{"id":"1.187595435","rc":[{"batl":[[0,18,56.78]],"ltp":17.5,"tv":197.62,"id":9634224}]}]}
{"op":"mcm","clk":"4230500866","pt":1631533694155,"mc":[{"id":"1.187595435","rc":[{"batl":[[0,21,54.04]],"ltp":17.5,"tv":197.62,"id":9634224}]}]}
{"op":"mcm","clk":"4230511089","pt":1631533798256,"mc":[{"id":"1.187595435","rc":[{"batl":[[0,26,49.92]],"ltp":17.5,"tv":197.62,"id":9634224}]}]}
{"op":"mcm","clk":"4230513597","pt":1631533823689,"mc":[{"id":"1.187595435","rc":[{"batl":[[0,21,54.04]],"ltp":17.5,"tv":197.62,"id":9634224}]}]}
{"op":"mcm","clk":"4230515476","pt":1631533843476,"mc":[{"id":"1.187595435","rc":[{"batl":[[0,1.15,255.54]],"ltp":1.06,"tv":44.97,"id":11252269}]}]}
{"op":"mcm","clk":"4230516020","pt":1631533849211,"mc":[{"id":"1.187595435","rc":[{"batl":[[0,34,46.6]],"ltp":17.5,"tv":197.62,"id":9634224}]}]}
{"op":"mcm","clk":"4230519754","pt":1631533886068,"mc":[{"id":"1.187595435","rc":[{"batl":[[0,46,43.48]],"ltp":17.5,"tv":197.62,"id":9634224}]}]}
{"op":"mcm","clk":"4230524541","pt":1631533931930,"mc":[{"id":"1.187595435","rc":[{"batl":[[0,34,46.6]],"ltp":17.5,"tv":197.62,"id":9634224}]}]}
{"op":"mcm","clk":"4230528787","pt":1631533973516,"mc":[{"id":"1.187595435","rc":[{"batl":[[0,21,54.04]],"ltp":17.5,"tv":197.62,"id":9634224}]}]}
{"op":"mcm","clk":"4230532379","pt":1631534009852,"mc":[{"id":"1.187595435","rc":[{"trd":[[21,0.18]],"batl":[[0,21,53.86]],"ltp":21.0,"tv":197.8,"id":9634224},{"trd":[[1.05,3.62]],"ltp":1.05,"tv":48.59,"id":11252269}],"tv":246.39}]}
{"op":"mcm","clk":"4230533282","pt":1631534018875,"mc":[{"id":"1.187595435","rc":[{"batl":[[0,1.15,255.54]],"ltp":1.05,"tv":48.59,"id":11252269}]}]}
{"op":"mcm","clk":"4230533788","pt":1631534023581,"mc":[{"id":"1.187595435","rc":[{"batl":[[0,34,46.48]],"ltp":21.0,"tv":197.8,"id":9634224}]}]}
{"op":"mcm","clk":"4230537370","pt":1631534057915,"mc":[{"id":"1.187595435","rc":[{"batl":[[0,21,53.85]],"ltp":21.0,"tv":197.8,"id":9634224}]}]}
{"op":"mcm","clk":"4230540114","pt":1631534088163,"mc":[{"id":"1.187595435","rc":[{"batl":[[0,15.5,59.98]],"ltp":21.0,"tv":197.8,"id":9634224}]}]}
{"op":"mcm","clk":"4230542859","pt":1631534116174,"mc":[{"id":"1.187595435","rc":[{"batl":[[0,12,68.09]],"ltp":21.0,"tv":197.8,"id":9634224}]}]}
{"op":"mcm","clk":"4230547821","pt":1631534166020,"mc":[{"id":"1.187595435","rc":[{"batl":[[0,9.4,78.33]],"ltp":21.0,"tv":197.8,"id":9634224}]}]}
{"op":"mcm","clk":"4230552106","pt":1631534213989,"mc":[{"id":"1.187595435","rc":[{"batl":[[0,12,68.09]],"ltp":21.0,"tv":197.8,"id":9634224}]}]}
{"op":"mcm","clk":"4230555666","pt":1631534251517,"mc":[{"id":"1.187595435","rc":[{"batl":[[0,10.5,72.62]],"ltp":21.0,"tv":197.8,"id":9634224}]}]}
{"op":"mcm","clk":"4230557208","pt":1631534267817,"mc":[{"id":"1.187595435","rc":[{"batl":[[0,9.4,78.33]],"ltp":21.0,"tv":197.8,"id":9634224}]}]}
{"op":"mcm","clk":"4230560878","pt":1631534307985,"mc":[{"id":"1.187595435","rc":[{"batb":[[0,1.01,7],[1,1.01,0]],"ltp":21.0,"tv":197.8,"id":9634224}]}]}
{"op":"mcm","clk":"4230561402","pt":1631534313588,"mc":[{"id":"1.187595435","rc":[{"batb":[[0,2.72,386.13],[1,1.01,7]],"batl":[[0,7.2,92.44]],"ltp":21.0,"tv":197.8,"id":9634224}]}]}
{"op":"mcm","clk":"4230564162","pt":1631534346036,"mc":[{"id":"1.187595435","rc":[{"batl":[[0,8.2,85.73]],"ltp":21.0,"tv":197.8,"id":9634224}]}]}
{"op":"mcm","clk":"4230565239","pt":1631534357715,"mc":[{"id":"1.187595435","rc":[{"batb":[[0,1.16,255.54],[1,1.01,7]],"ltp":1.05,"tv":48.59,"id":11252269}]}]}
{"op":"mcm","clk":"4230567313","pt":1631534378130,"mc":[{"id":"1.187595435","rc":[{"batb":[[0,1.01,7],[1,1.01,0]],"ltp":1.05,"tv":48.59,"id":11252269}]}]}
{"op":"mcm","clk":"4230567683","pt":1631534381880,"mc":[{"id":"1.187595435","rc":[{"batl":[[0,6.6,99.21]],"ltp":21.0,"tv":197.8,"id":9634224}]}]}
{"op":"mcm","clk":"4230567980","pt":1631534384666,"mc":[{"id":"1.187595435","rc":[{"batb":[[0,1.2,255.54],[1,1.01,7]],"ltp":1.05,"tv":48.59,"id":11252269}]}]}
{"op":"mcm","clk":"4230569602","pt":1631534401312,"mc":[{"id":"1.187595435","rc":[{"trd":[[2.72,2.79]],"batb":[[0,2.72,384.74]],"ltp":2.72,"tv":200.59,"id":9634224}],"tv":249.18}]}
{"op":"mcm","clk":"4230570510","pt":1631534409814,"mc":[{"id":"1.187595435","rc":[{"batl":[[0,1.46,255.54]],"ltp":1.05,"tv":48.59,"id":11252269}]}]}
{"op":"mcm","clk":"4230570600","pt":1631534410719,"mc":[{"id":"1.187595435","rc":[{"batl":[[0,1.4,255.54],[1,1.46,255.54]],"ltp":1.05,"tv":48.59,"id":11252269}]}]}
{"op":"mcm","clk":"4230581134","pt":1631534517920,"mc":[{"id":"1.187595435","rc":[{"batl":[[0,1.46,255.54],[1,1.46,0]],"ltp":1.05,"tv":48.59,"id":11252269}]}]}
{"op":"mcm","clk":"4230581642","pt":1631534522190,"mc":[{"id":"1.187595435","rc":[{"batb":[[0,1.01,7],[1,1.01,0]],"ltp":2.72,"tv":200.59,"id":9634224}]}]}
{"op":"mcm","clk":"4230582284","pt":1631534528424,"mc":[{"id":"1.187595435","rc":[{"batb":[[0,2.98,380.61],[1,1.01,7]],"batl":[[0,9.4,78.75]],"ltp":2.72,"tv":200.59,"id":9634224}]}]}
{"op":"mcm","clk":"4230582567","pt":1631534531129,"mc":[{"id":"1.187595435","rc":[{"batb":[[0,1.01,7],[1,1.01,0]],"ltp":1.05,"tv":48.59,"id":11252269}]}]}
{"op":"mcm","clk":"4230586631","pt":1631534565960,"mc":[{"id":"1.187595435","rc":[{"batl":[[0,8.2,86.22]],"ltp":2.72,"tv":200.59,"id":9634224}]}]}
{"op":"mcm","clk":"4230589863","pt":1631534592424,"mc":[{"id":"1.187595435","rc":[{"batl":[[0,6.6,99.8]],"ltp":2.72,"tv":200.59,"id":9634224}]}]}
{"op":"mcm","clk":"4230589952","pt":1631534593108,"mc":[{"id":"1.187595435","rc":[{"batb":[[0,1.22,255.54],[1,1.01,7]],"ltp":1.05,"tv":48.59,"id":11252269}]}]}
{"op":"mcm","clk":"4230594213","pt":1631534632062,"mc":[{"id":"1.187595435","rc":[{"batl":[[0,8.2,86.22]],"ltp":2.72,"tv":200.59,"id":9634224}]}]}
{"op":"mcm","clk":"4230594762","pt":1631534636996,"mc":[{"id":"1.187595435","rc":[{"batb":[[0,1.01,7],[1,1.01,0]],"ltp":1.05,"tv":48.59,"id":11252269}]}]}
{"op":"mcm","clk":"4230595364","pt":1631534642673,"mc":[{"id":"1.187595435","rc":[{"batl":[[0,1.35,255.54]],"ltp":1.05,"tv":48.59,"id":11252269}]}]}
{"op":"mcm","clk":"4230598464","pt":1631534670822,"mc":[{"id":"1.187595435","rc":[{"batl":[[0,10.5,72.99]],"ltp":2.72,"tv":200.59,"id":9634224}]}]}
{"op":"mcm","clk":"4230602811","pt":1631534710890,"mc":[{"id":"1.187595435","rc":[{"batb":[[0,1.01,7],[1,1.01,0]],"ltp":2.72,"tv":200.59,"id":9634224}]}]}
{"op":"mcm","clk":"4230603395","pt":1631534716398,"mc":[{"id":"1.187595435","rc":[{"batb":[[0,3.3,379.13],[1,1.01,7]],"batl":[[0,13.5,64.69]],"ltp":2.72,"tv":200.59,"id":9634224}]}]}
{"op":"mcm","clk":"4230608047","pt":1631534757269,"mc":[{"id":"1.187595435","rc":[{"batl":[[0,10.5,72.99]],"ltp":2.72,"tv":200.59,"id":9634224}]}]}
{"op":"mcm","clk":"4230612784","pt":1631534798913,"mc":[{"id":"1.187595435","rc":[{"batl":[[0,13.5,64.69]],"ltp":2.72,"tv":200.59,"id":9634224}]}]}
{"op":"mcm","clk":"4230613064","pt":1631534801234,"mc":[{"id":"1.187595435","rc":[{"batl":[[0,1.25,255.54],[1,1.35,255.54]],"ltp":1.05,"tv":48.59,"id":11252269}]}]}
{"op":"mcm","clk":"4230613361","pt":1631534803706,"mc":[{"id":"1.187595435","rc":[{"batb":[[0,1.1,255.54],[1,1.01,7]],"ltp":1.05,"tv":48.59,"id":11252269}]}]}
{"op":"mcm","clk":"4230616336","pt":1631534827488,"mc":[{"id":"1.187595435","rc":[{"batl":[[1,1.35,0]],"ltp":1.05,"tv":48.59,"id":11252269}]}]}
{"op":"mcm","clk":"4230616826","pt":1631534831584,"mc":[{"id":"1.187595435","rc":[{"batl":[[0,1.2,255.54],[1,1.25,255.54]],"ltp":1.05,"tv":48.59,"id":11252269}]}]}
{"op":"mcm","clk":"4230617772","pt":1631534839998,"mc":[{"id":"1.187595435","rc":[{"batl":[[0,1.25,255.54],[1,1.25,0]],"ltp":1.05,"tv":48.59,"id":11252269}]}]}
{"op":"mcm","clk":"4230617844","pt":1631534840677,"mc":[{"id":"1.187595435","rc":[{"batl":[[0,10.5,72.99]],"ltp":2.72,"tv":200.59,"id":9634224}]}]}
{"op":"mcm","clk":"4230621049","pt":1631534869951,"mc":[{"id":"1.187595435","rc":[{"batb":[[0,1.01,7],[1,1.01,0]],"ltp":1.05,"tv":48.59,"id":11252269}]}]}
{"op":"mcm","clk":"4230621261","pt":1631534871985,"mc":[{"id":"1.187595435","rc":[{"batl":[[0,9.4,78.75]],"ltp":2.72,"tv":200.59,"id":9634224}]}]}
{"op":"mcm","clk":"4230621970","pt":1631534878548,"mc":[{"id":"1.187595435","rc":[{"batb":[[0,1.01,7],[1,1.01,0]],"ltp":2.72,"tv":200.59,"id":9634224}]}]}
{"op":"mcm","clk":"4230622535","pt":1631534884159,"mc":[{"id":"1.187595435","rc":[{"batb":[[0,2.72,384.74],[1,1.01,7]],"batl":[[0,7.2,92.97]],"ltp":2.72,"tv":200.59,"id":9634224}]}]}
{"op":"mcm","clk":"4230625514","pt":1631534913237,"mc":[{"id":"1.187595435","rc":[{"batb":[[0,1.01,7],[1,1.01,0]],"ltp":2.72,"tv":200.59,"id":9634224}]}]}
{"op":"mcm","clk":"4230626101","pt":1631534918837,"mc":[{"id":"1.187595435","rc":[{"batb":[[0,3.1,380.06],[1,1.01,7]],"batl":[[0,10.5,72.99]],"ltp":2.72,"tv":200.59,"id":9634224}]}]}
{"op":"mcm","clk":"4230628790","pt":1631534943952,"mc":[{"id":"1.187595435","rc":[{"batl":[[0,9.4,78.75]],"ltp":2.72,"tv":200.59,"id":9634224}]}]}
{"op":"mcm","clk":"4230629975","pt":1631534953970,"mc":[{"id":"1.187595435","rc":[{"batb":[[0,1.01,7],[1,1.01,0]],"ltp":2.72,"tv":200.59,"id":9634224}]}]}
{"op":"mcm","clk":"4230630685","pt":1631534959679,"mc":[{"id":"1.187595435","rc":[{"batl":[[0,1.11,2]],"ltp":1.05,"tv":48.59,"id":11252269}]}]}
{"op":"mcm","clk":"4230632925","pt":1631534981724,"mc":[{"id":"1.187595435","rc":[{"batb":[[0,1.08,255.54],[1,1.01,7]],"ltp":1.05,"tv":48.59,"id":11252269}]}]}
{"op":"mcm","clk":"4230636558","pt":1631535016946,"mc":[{"id":"1.187595435","rc":[{"trd":[[1.08,4]],"batb":[[0,1.08,253.53]],"ltp":1.08,"tv":52.59,"id":11252269}],"tv":253.18}]}
{"op":"mcm","clk":"4230637622","pt":1631535027095,"mc":[{"id":"1.187595435","rc":[{"batl":[[0,1.12,1.93]],"ltp":1.08,"tv":52.59,"id":11252269}]}]}
{"op":"mcm","clk":"4230637791","pt":1631535028515,"mc":[{"id":"1.187595435","rc":[{"batl":[[1,1.24,255.54]],"ltp":1.08,"tv":52.59,"id":11252269}]}]}
{"op":"mcm","clk":"4230637834","pt":1631535028937,"mc":[{"id":"1.187595435","rc":[{"batl":[[1,1.23,255.54],[2,1.24,255.54]],"ltp":1.08,"tv":52.59,"id":11252269}]}]}
{"op":"mcm","clk":"4230643016","pt":1631535083580,"mc":[{"id":"1.187595435","rc":[{"batl":[[1,1.23,0],[2,1.24,0]],"ltp":1.08,"tv":52.59,"id":11252269}]}]}
{"op":"mcm","clk":"4230643382","pt":1631535087302,"mc":[{"id":"1.187595435","rc":[{"batl":[[1,1.2,255.54]],"ltp":1.08,"tv":52.59,"id":11252269}]}]}
{"op":"mcm","clk":"4230646625","pt":1631535122517,"mc":[{"id":"1.187595435","rc":[{"batb":[[0,3.5,382.4],[1,1.01,7]],"batl":[[0,18,56.79]],"ltp":2.72,"tv":200.59,"id":9634224}]}]}
{"op":"mcm","clk":"4230650225","pt":1631535158044,"mc":[{"id":"1.187595435","rc":[{"batb":[[0,7.6,10],[1,3.5,382.4],[2,1.01,7]],"ltp":2.72,"tv":200.59,"id":9634224},{"batb":[[1,1.05,599.99],[2,1.01,7]],"ltp":1.08,"tv":52.59,"id":11252269}]}]}
{"op":"mcm","clk":"4230656701","pt":1631535227041,"mc":[{"id":"1.187595435","rc":[{"batl":[[0,21,54.05]],"ltp":2.72,"tv":200.59,"id":9634224}]}]}
{"op":"mcm","clk":"4230657310","pt":1631535233059,"mc":[{"id":"1.187595435","rc":[{"batb":[[0,3.5,382.4],[1,1.01,7],[2,1.01,0]],"ltp":2.72,"tv":200.59,"id":9634224},{"batb":[[1,1.01,7],[2,1.01,0]],"ltp":1.08,"tv":52.59,"id":11252269}]}]}
{"op":"mcm","clk":"4230657787","pt":1631535238046,"mc":[{"id":"1.187595435","rc":[{"batb":[[0,6,10],[1,3.5,382.4],[2,1.01,7]],"ltp":2.72,"tv":200.59,"id":9634224},{"batb":[[0,1.08,628.52]],"ltp":1.08,"tv":52.59,"id":11252269}]}]}
{"op":"mcm","clk":"4230658013","pt":1631535240526,"mc":[{"id":"1.187595435","rc":[{"batl":[[0,15.5,60.23]],"ltp":2.72,"tv":200.59,"id":9634224}]}]}
{"op":"mcm","clk":"4230659396","pt":1631535254468,"mc":[{"id":"1.187595435","rc":[{"batb":[[1,1.04,2.89],[2,1.01,7]],"ltp":1.08,"tv":52.59,"id":11252269}]}]}
{"op":"mcm","clk":"4230659520","pt":1631535256074,"mc":[{"id":"1.187595435","rc":[{"batb":[[1,1.01,7],[2,1.01,0]],"ltp":1.08,"tv":52.59,"id":11252269}]}]}
{"op":"mcm","clk":"4230659920","pt":1631535260089,"mc":[{"id":"1.187595435","rc":[{"batb":[[0,3.5,382.4],[1,1.01,7],[2,1.01,0]],"ltp":2.72,"tv":200.59,"id":9634224},{"batb":[[0,1.08,253.53]],"ltp":1.08,"tv":52.59,"id":11252269}]}]}
{"op":"mcm","clk":"4230660356","pt":1631535264607,"mc":[{"id":"1.187595435","rc":[{"batb":[[1,1.04,1446.45],[2,1.01,7]],"ltp":1.08,"tv":52.59,"id":11252269}]}]}
{"op":"mcm","clk":"4230660395","pt":1631535264989,"mc":[{"id":"1.187595435","rc":[{"batb":[[0,5.3,10],[1,3.5,382.4],[2,1.01,7]],"ltp":2.72,"tv":200.59,"id":9634224}]}]}
{"op":"mcm","clk":"4230660547","pt":1631535266872,"mc":[{"id":"1.187595435","rc":[{"batl":[[0,12,68.42]],"ltp":2.72,"tv":200.59,"id":9634224}]}]}
{"op":"mcm","clk":"4230661059","pt":1631535272781,"mc":[{"id":"1.187595435","rc":[{"batb":[[1,1.01,7],[2,1.01,0]],"ltp":1.08,"tv":52.59,"id":11252269}]}]}
{"op":"mcm","clk":"4230661792","pt":1631535280160,"mc":[{"id":"1.187595435","rc":[{"batb":[[0,1.1,1446.45],[1,1.08,253.53],[2,1.01,7]],"ltp":1.08,"tv":52.59,"id":11252269}]}]}
{"op":"mcm","clk":"4230662012","pt":1631535282466,"mc":[{"id":"1.187595435","rc":[{"trd":[[1.1,2891.69]],"batb":[[0,1.08,254.29],[1,1.01,7],[2,1.01,0]],"ltp":1.1,"tv":2944.28,"id":11252269}],"tv":3144.87}]}
{"op":"mcm","clk":"4230662759","pt":1631535290288,"mc":[{"id":"1.187595435","rc":[{"batb":[[0,1.08,253.53]],"ltp":1.1,"tv":2944.28,"id":11252269}]}]}
{"op":"mcm","clk":"4230662931","pt":1631535292163,"mc":[{"id":"1.187595435","rc":[{"batb":[[0,3.5,382.4],[1,1.01,7],[2,1.01,0]],"ltp":2.72,"tv":200.59,"id":9634224}]}]}
{"op":"mcm","clk":"4230663384","pt":1631535297083,"mc":[{"id":"1.187595435","rc":[{"batb":[[0,6,10],[1,3.5,382.4],[2,1.01,7]],"ltp":2.72,"tv":200.59,"id":9634224},{"batb":[[0,1.08,628.52]],"ltp":1.1,"tv":2944.28,"id":11252269}]}]}
{"op":"mcm","clk":"4230664336","pt":1631535306996,"mc":[{"id":"1.187595435","rc":[{"batl":[[1,1.19,1446.45],[2,1.2,255.54]],"ltp":1.1,"tv":2944.28,"id":11252269}]}]}
{"op":"mcm","clk":"4230664559","pt":1631535309412,"mc":[{"id":"1.187595435","rc":[{"trd":[[1.12,3.85],[1.19,2887.85]],"batl":[[0,1.19,2.68],[1,1.2,255.54],[2,1.2,0]],"ltp":1.19,"tv":5835.97,"id":11252269}],"tv":6036.56}]}
{"op":"mcm","clk":"4230665122","pt":1631535315216,"mc":[{"id":"1.187595435","rc":[{"batl":[[0,1.2,255.54],[1,1.2,0]],"ltp":1.19,"tv":5835.97,"id":11252269}]}]}
{"op":"mcm","clk":"4230665777","pt":1631535322613,"mc":[{"id":"1.187595435","rc":[{"batb":[[0,1.1,104.04],[1,1.08,374.99],[2,1.01,7]],"ltp":1.19,"tv":5835.97,"id":11252269}]}]}
{"op":"mcm","clk":"4230665845","pt":1631535323441,"mc":[{"id":"1.187595435","rc":[{"batb":[[0,1.1,312.12]],"ltp":1.19,"tv":5835.97,"id":11252269}]}]}
{"op":"mcm","clk":"4230665892","pt":1631535323925,"mc":[{"id":"1.187595435","rc":[{"batb":[[0,1.1,416.16]],"ltp":1.19,"tv":5835.97,"id":11252269}]}]}
{"op":"mcm","clk":"4230666062","pt":1631535325526,"mc":[{"id":"1.187595435","rc":[{"batl":[[0,15.5,60.23]],"ltp":2.72,"tv":200.59,"id":9634224}]}]}
{"op":"mcm","clk":"4230666844","pt":1631535333626,"mc":[{"id":"1.187595435","rc":[{"batl":[[0,1.36,1000]],"ltp":1.19,"tv":5835.97,"id":11252269}]}]}
{"op":"mcm","clk":"4230668999","pt":1631535356950,"mc":[{"id":"1.187595435","rc":[{"batl":[[0,13.5,64.69]],"ltp":2.72,"tv":200.59,"id":9634224}]}]}
{"op":"mcm","clk":"4230671100","pt":1631535379066,"mc":[{"id":"1.187595435","rc":[{"batb":[[1,1.09,3001.37],[2,1.08,374.99]],"ltp":1.19,"tv":5835.97,"id":11252269}]}]}
{"op":"mcm","clk":"4230671250","pt":1631535380585,"mc":[{"id":"1.187595435","rc":[{"batb":[[0,3.5,382.4],[1,1.01,7],[2,1.01,0]],"ltp":2.72,"tv":200.59,"id":9634224},{"batb":[[2,1.01,7]],"ltp":1.19,"tv":5835.97,"id":11252269}]}]}
{"op":"mcm","clk":"4230671488","pt":1631535382990,"mc":[{"id":"1.187595435","rc":[{"batb":[[1,1.01,7],[2,1.01,0]],"ltp":1.19,"tv":5835.97,"id":11252269}]}]}
{"op":"mcm","clk":"4230671765","pt":1631535385509,"mc":[{"id":"1.187595435","rc":[{"batb":[[0,5.3,10],[1,3.5,382.4],[2,1.01,7]],"ltp":2.72,"tv":200.59,"id":9634224},{"batb":[[0,1.12,249.99],[1,1.1,416.16],[2,1.01,7]],"ltp":1.19,"tv":5835.97,"id":11252269}]}]}
{"op":"mcm","clk":"4230672101","pt":1631535388721,"mc":[{"id":"1.187595435","rc":[{"batl":[[0,10.5,72.99]],"ltp":2.72,"tv":200.59,"id":9634224}]}]}
{"op":"mcm","clk":"4230672734","pt":1631535395184,"mc":[{"id":"1.187595435","rc":[{"batb":[[1,1.01,7],[2,1.01,0]],"ltp":1.19,"tv":5835.97,"id":11252269}]}]}
{"op":"mcm","clk":"4230673140","pt":1631535399364,"mc":[{"id":"1.187595435","rc":[{"trd":[[1.13,2891.69]],"batb":[[0,1.12,250.75]],"ltp":1.13,"tv":8727.66,"id":11252269}],"tv":8928.25}]}
{"op":"mcm","clk":"4230674207","pt":1631535410600,"mc":[{"id":"1.187595435","rc":[{"batb":[[0,1.12,249.99]],"ltp":1.13,"tv":8727.66,"id":11252269}]}]}
{"op":"mcm","clk":"4230674257","pt":1631535411180,"mc":[{"id":"1.187595435","rc":[{"trd":[[5.3,9.57]],"batb":[[0,3.5,382.4],[1,1.01,7],[2,1.01,0]],"ltp":5.3,"tv":210.16,"id":9634224}],"tv":8937.82}]}
{"op":"mcm","clk":"4230674739","pt":1631535416409,"mc":[{"id":"1.187595435","rc":[{"batb":[[0,1.01,7],[1,1.01,0]],"ltp":1.13,"tv":8727.66,"id":11252269}]}]}
{"op":"mcm","clk":"4230675184","pt":1631535421217,"mc":[{"id":"1.187595435","rc":[{"batb":[[0,4.8,10],[1,3.5,382.4],[2,1.01,7]],"ltp":5.3,"tv":210.16,"id":9634224},{"batb":[[0,1.15,200],[1,1.01,7]],"ltp":1.13,"tv":8727.66,"id":11252269}]}]}
{"op":"mcm","clk":"4230675258","pt":1631535422208,"mc":[{"id":"1.187595435","rc":[{"batl":[[0,9.4,78.75]],"ltp":5.3,"tv":210.16,"id":9634224}]}]}
{"op":"mcm","clk":"4230675400","pt":1631535423614,"mc":[{"id":"1.187595435","rc":[{"batb":[[1,1.14,260.1],[2,1.01,7]],"ltp":1.13,"tv":8727.66,"id":11252269}]}]}
{"op":"mcm","clk":"4230675445","pt":1631535424000,"mc":[{"id":"1.187595435","rc":[{"batb":[[1,1.14,364.14]],"ltp":1.13,"tv":8727.66,"id":11252269}]}]}
{"op":"mcm","clk":"4230676512","pt":1631535434941,"mc":[{"id":"1.187595435","rc":[{"batl":[[0,1.25,1446.45]],"ltp":1.13,"tv":8727.66,"id":11252269}]}]}
{"op":"mcm","clk":"4230676835","pt":1631535438804,"mc":[{"id":"1.187595435","rc":[{"trd":[[1.25,2891.69]],"batl":[[0,1.25,0.76]],"ltp":1.25,"tv":11619.34,"id":11252269}],"tv":11829.51}]}
{"op":"mcm","clk":"4230677094","pt":1631535441621,"mc":[{"id":"1.187595435","rc":[{"batb":[[1,1.01,7],[2,1.01,0]],"ltp":5.3,"tv":210.16,"id":9634224}]}]}
{"op":"mcm","clk":"4230678147","pt":1631535448562,"mc":[{"id":"1.187595435","rc":[{"batb":[[1,1.01,7],[2,1.01,0]],"ltp":1.25,"tv":11619.34,"id":11252269}]}]}
{"op":"mcm","clk":"4230679421","pt":1631535457953,"mc":[{"id":"1.187595435","rc":[{"batb":[[0,1.01,7],[1,1.01,0]],"ltp":5.3,"tv":210.16,"id":9634224},{"batb":[[0,1.01,7],[1,1.01,0]],"ltp":1.25,"tv":11619.34,"id":11252269}]}]}
{"op":"mcm","clk":"4230680122","pt":1631535462860,"mc":[{"id":"1.187595435","rc":[{"batb":[[0,3.95,10.16],[1,1.01,7]],"ltp":5.3,"tv":210.16,"id":9634224},{"batb":[[0,1.2,150],[1,1.01,7]],"ltp":1.25,"tv":11619.34,"id":11252269}]}]}
{"op":"mcm","clk":"4230682984","pt":1631535478590,"mc":[{"id":"1.187595435","rc":[{"batb":[[0,1.01,7],[1,1.01,0]],"ltp":5.3,"tv":210.16,"id":9634224}]}]}
{"op":"mcm","clk":"4230683802","pt":1631535483461,"mc":[{"id":"1.187595435","rc":[{"batb":[[0,3.7,11.11],[1,1.01,7]],"ltp":5.3,"tv":210.16,"id":9634224}]}]}
{"op":"mcm","clk":"4230684897","pt":1631535491083,"mc":[{"id":"1.187595435","rc":[{"batb":[[0,1.21,1446.45],[1,1.2,150],[2,1.01,7]],"ltp":1.25,"tv":11619.34,"id":11252269}]}]}
{"op":"mcm","clk":"4230685161","pt":1631535493176,"mc":[{"id":"1.187595435","rc":[{"trd":[[1.21,2891.69]],"batb":[[0,1.2,150.76],[1,1.01,7],[2,1.01,0]],"ltp":1.21,"tv":14511.03,"id":11252269}],"tv":14721.2}]}
{"op":"mcm","clk":"4230685259","pt":1631535493994,"mc":[{"id":"1.187595435","rc":[{"batb":[[0,1.01,7],[1,1.01,0]],"ltp":5.3,"tv":210.16,"id":9634224},{"batb":[[0,1.01,7.76],[1,1.01,0]],"ltp":1.21,"tv":14511.03,"id":11252269}]}]}
{"op":"mcm","clk":"4230685612","pt":1631535497499,"mc":[{"id":"1.187595435","rc":[{"batb":[[0,1.01,7]],"ltp":1.21,"tv":14511.03,"id":11252269}]}]}
{"op":"mcm","clk":"4230685749","pt":1631535498906,"mc":[{"id":"1.187595435","rc":[{"batb":[[0,3.15,13.95],[1,1.01,7]],"ltp":5.3,"tv":210.16,"id":9634224},{"batb":[[0,1.31,96.77],[1,1.01,7]],"ltp":1.21,"tv":14511.03,"id":11252269}]}]}
{"op":"mcm","clk":"4230686123","pt":1631535502234,"mc":[{"id":"1.187595435","rc":[{"batb":[[1,1.23,255.54],[2,1.01,7]],"ltp":1.21,"tv":14511.03,"id":11252269}]}]}
{"op":"mcm","clk":"4230686282","pt":1631535503629,"mc":[{"id":"1.187595435","rc":[{"batb":[[1,1.25,255.54],[2,1.23,255.54]],"batl":[[0,1.46,255.54]],"ltp":1.21,"tv":14511.03,"id":11252269}]}]}
{"op":"mcm","clk":"4230686334","pt":1631535504000,"mc":[{"id":"1.187595435","rc":[{"batl":[[0,1.45,255.54],[1,1.46,255.54]],"ltp":1.21,"tv":14511.03,"id":11252269}]}]}
{"op":"mcm","clk":"4230686515","pt":1631535505547,"mc":[{"id":"1.187595435","rc":[{"batl":[[0,1.4,52.02],[1,1.45,255.54],[2,1.46,255.54]],"ltp":1.21,"tv":14511.03,"id":11252269}]}]}
{"op":"mcm","clk":"4230686650","pt":1631535506633,"mc":[{"id":"1.187595435","rc":[{"batl":[[0,1.45,255.54],[1,1.46,255.54],[2,1.46,0]],"ltp":1.21,"tv":14511.03,"id":11252269}]}]}
{"op":"mcm","clk":"4230687324","pt":1631535512529,"mc":[{"id":"1.187595435","rc":[{"trd":[[1.31,104.04]],"batb":[[0,1.31,44.75]],"ltp":1.31,"tv":14615.07,"id":11252269}],"tv":14825.24}]}
{"op":"mcm","clk":"4230687352","pt":1631535512730,"mc":[{"id":"1.187595435","rc":[{"batb":[[0,1.25,255.54],[1,1.23,255.54],[2,1.01,7]],"ltp":1.31,"tv":14615.07,"id":11252269}]}]}
{"op":"mcm","clk":"4230687898","pt":1631535517740,"mc":[{"id":"1.187595435","rc":[{"batb":[[0,1.31,96.77],[1,1.25,255.54],[2,1.23,255.54]],"ltp":1.31,"tv":14615.07,"id":11252269}]}]}
{"op":"mcm","clk":"4230689065","pt":1631535529041,"mc":[{"id":"1.187595435","rc":[{"batl":[[0,1.43,1446.45],[1,1.45,255.54],[2,1.46,255.54]],"ltp":1.31,"tv":14615.07,"id":11252269}]}]}
{"op":"mcm","clk":"4230689298","pt":1631535531249,"mc":[{"id":"1.187595435","rc":[{"trd":[[1.43,2891.69]],"batl":[[0,1.45,256.3],[1,1.46,255.54],[2,1.46,0]],"ltp":1.43,"tv":17506.75,"id":11252269}],"tv":17716.92}]}
{"op":"mcm","clk":"4230689741","pt":1631535535746,"mc":[{"id":"1.187595435","rc":[{"batl":[[1,1.46,0]],"ltp":1.43,"tv":17506.75,"id":11252269}]}]}
{"op":"mcm","clk":"4230689934","pt":1631535537676,"mc":[{"id":"1.187595435","rc":[{"batl":[[0,1.45,255.54]],"ltp":1.43,"tv":17506.75,"id":11252269}]}]}
{"op":"mcm","clk":"4230690577","pt":1631535544291,"mc":[{"id":"1.187595435","rc":[{"batb":[[0,1.01,7],[1,1.01,0]],"ltp":5.3,"tv":210.16,"id":9634224},{"batb":[[0,1.25,255.54],[1,1.23,255.54],[2,1.01,7]],"ltp":1.43,"tv":17506.75,"id":11252269}]}]}
{"op":"mcm","clk":"4230691009","pt":1631535548633,"mc":[{"id":"1.187595435","rc":[{"batb":[[0,2.84,16.3],[1,1.01,7]],"ltp":5.3,"tv":210.16,"id":9634224},{"batb":[[0,1.38,78.94],[1,1.25,255.54],[2,1.23,255.54]],"ltp":1.43,"tv":17506.75,"id":11252269}]}]}
{"op":"mcm","clk":"4230691165","pt":1631535550519,"mc":[{"id":"1.187595435","rc":[{"batb":[[1,1.33,255.54],[2,1.25,255.54]],"ltp":1.43,"tv":17506.75,"id":11252269}]}]}
{"op":"mcm","clk":"4230691297","pt":1631535551827,"mc":[{"id":"1.187595435","rc":[{"batl":[[0,1.5,255.54]],"ltp":1.43,"tv":17506.75,"id":11252269}]}]}
{"op":"mcm","clk":"4230692372","pt":1631535562050,"mc":[{"id":"1.187595435","rc":[{"batb":[[0,1.39,1446.45],[1,1.38,78.94],[2,1.33,255.54]],"ltp":1.43,"tv":17506.75,"id":11252269}]}]}
{"op":"mcm","clk":"4230692596","pt":1631535564450,"mc":[{"id":"1.187595435","rc":[{"trd":[[1.39,2891.69]],"batb":[[0,1.38,79.7],[1,1.33,255.54],[2,1.25,255.54]],"ltp":1.39,"tv":20398.44,"id":11252269}],"tv":20608.61}]}
{"op":"mcm","clk":"4230693201","pt":1631535570359,"mc":[{"id":"1.187595435","rc":[{"batb":[[0,1.38,78.94]],"ltp":1.39,"tv":20398.44,"id":11252269}]}]}
{"op":"mcm","clk":"4230693951","pt":1631535578259,"mc":[{"id":"1.187595435","rc":[{"batb":[[0,1.01,7],[1,1.01,0]],"ltp":5.3,"tv":210.16,"id":9634224},{"batb":[[0,1.33,255.54],[1,1.25,255.54],[2,1.23,255.54]],"ltp":1.39,"tv":20398.44,"id":11252269}]}]}
{"op":"mcm","clk":"4230694426","pt":1631535583484,"mc":[{"id":"1.187595435","rc":[{"batb":[[0,3,15],[1,1.01,7]],"ltp":5.3,"tv":210.16,"id":9634224},{"batb":[[0,1.34,88.23]],"ltp":1.39,"tv":20398.44,"id":11252269}]}]}
{"op":"mcm","clk":"4230694902","pt":1631535588947,"mc":[{"id":"1.187595435","rc":[{"batb":[[1,1.29,255.54],[2,1.25,255.54]],"ltp":1.39,"tv":20398.44,"id":11252269}]}]}
{"op":"mcm","clk":"4230695096","pt":1631535591163,"mc":[{"id":"1.187595435","rc":[{"batb":[[0,3.65,5.32],[1,3,15],[2,1.01,7]],"ltp":5.3,"tv":210.16,"id":9634224}]}]}
{"op":"mcm","clk":"4230697714","pt":1631535620404,"mc":[{"id":"1.187595435","rc":[{"batb":[[0,1.35,506.26],[1,1.34,88.23],[2,1.29,255.54]],"ltp":1.39,"tv":20398.44,"id":11252269}]}]}
{"op":"mcm","clk":"4230697905","pt":1631535622709,"mc":[{"id":"1.187595435","rc":[{"trd":[[1.35,999.89]],"batb":[[0,1.35,6.36]],"ltp":1.35,"tv":21398.33,"id":11252269}],"tv":21608.5}]}
{"op":"mcm","clk":"4230698469","pt":1631535629121,"mc":[{"id":"1.187595435","rc":[{"batb":[[1,1.01,7],[2,1.01,0]],"ltp":5.3,"tv":210.16,"id":9634224},{"batb":[[1,1.29,255.54],[2,1.25,255.54]],"ltp":1.35,"tv":21398.33,"id":11252269}]}]}
{"op":"mcm","clk":"4230698567","pt":1631535630234,"mc":[{"id":"1.187595435","rc":[{"trd":[[1.35,1007.89]],"batb":[[0,1.35,2.36]],"ltp":1.35,"tv":21406.33,"id":11252269}],"tv":21616.5}]}
{"op":"mcm","clk":"4230698787","pt":1631535632748,"mc":[{"id":"1.187595435","rc":[{"trd":[[1.35,1012.63]],"batb":[[0,1.29,255.54],[1,1.25,255.54],[2,1.23,255.54]],"batl":[[0,1.35,1.63],[1,1.5,255.54]],"ltp":1.35,"tv":21411.07,"id":11252269}],"tv":21621.23}]}
{"op":"mcm","clk":"4230698941","pt":1631535634329,"mc":[{"id":"1.187595435","rc":[{"trd":[[3.65,5.32]],"batb":[[0,2.58,18.98]],"ltp":3.65,"tv":215.48,"id":9634224},{"trd":[[1.38,14.07]],"batl":[[0,1.5,255.54],[1,1.5,0]],"ltp":1.38,"tv":21425.14,"id":11252269}],"tv":21640.62}]}
{"op":"mcm","clk":"4230698996","pt":1631535635059,"mc":[{"id":"1.187595435","rc":[{"batb":[[1,2.22,391.36],[2,1.01,7]],"batl":[[0,4.6,137.18]],"ltp":3.65,"tv":215.48,"id":9634224}]}]}
{"op":"mcm","clk":"4230699356","pt":1631535639354,"mc":[{"id":"1.187595435","rc":[{"batb":[[0,1.45,66.66],[1,1.29,255.54],[2,1.25,255.54]],"ltp":1.38,"tv":21425.14,"id":11252269}]}]}
{"op":"mcm","clk":"4230699692","pt":1631535643037,"mc":[{"id":"1.187595435","rc":[{"batb":[[1,1.36,255.54],[2,1.29,255.54]],"ltp":1.38,"tv":21425.14,"id":11252269}]}]}
{"op":"mcm","clk":"4230699854","pt":1631535644668,"mc":[{"id":"1.187595435","rc":[{"batl":[[0,1.55,255.54]],"ltp":1.38,"tv":21425.14,"id":11252269}]}]}
{"op":"mcm","clk":"4230702129","pt":1631535667301,"mc":[{"id":"1.187595435","rc":[{"batl":[[0,1.54,1346.48],[1,1.55,255.54]],"ltp":1.38,"tv":21425.14,"id":11252269}]}]}
{"op":"mcm","clk":"4230702658","pt":1631535672701,"mc":[{"id":"1.187595435","rc":[{"trd":[[1.54,2718.6]],"batl":[[0,1.54,1.38]],"ltp":1.54,"tv":24115.63,"id":11252269}],"tv":24331.11}]}
{"op":"mcm","clk":"4230703361","pt":1631535679422,"mc":[{"id":"1.187595435","rc":[{"batb":[[0,2.22,391.36],[1,1.01,7],[2,1.01,0]],"ltp":3.65,"tv":215.48,"id":9634224},{"batb":[[0,1.36,255.54],[1,1.29,255.54],[2,1.25,255.54]],"ltp":1.54,"tv":24115.63,"id":11252269}]}]}
{"op":"mcm","clk":"4230703532","pt":1631535681233,"mc":[{"id":"1.187595435","rc":[{"batb":[[1,1.25,255.54],[2,1.23,255.54]],"ltp":1.54,"tv":24115.63,"id":11252269}]}]}
{"op":"mcm","clk":"4230703641","pt":1631535682430,"mc":[{"id":"1.187595435","rc":[{"batb":[[0,1.01,7],[1,1.01,0]],"ltp":3.65,"tv":215.48,"id":9634224},{"batb":[[1,1.23,255.54],[2,1.01,7]],"ltp":1.54,"tv":24115.63,"id":11252269}]}]}
{"op":"mcm","clk":"4230703688","pt":1631535683011,"mc":[{"id":"1.187595435","rc":[{"batb":[[1,1.01,7],[2,1.01,0]],"ltp":1.54,"tv":24115.63,"id":11252269}]}]}
{"op":"mcm","clk":"4230704964","pt":1631535696511,"mc":[{"id":"1.187595435","rc":[{"trd":[[1.54,2721.36]],"batb":[[0,1.54,2.62],[1,1.36,255.54],[2,1.01,7]],"batl":[[0,1.55,255.54],[1,1.55,0]],"ltp":1.54,"tv":24118.39,"id":11252269}],"tv":24333.87}]}
{"op":"mcm","clk":"4230705029","pt":1631535697449,"mc":[{"id":"1.187595435","rc":[{"batb":[[0,1.36,255.54],[1,1.01,7],[2,1.01,0]],"ltp":1.54,"tv":24118.39,"id":11252269}]}]}
{"op":"mcm","clk":"4230707596","pt":1631535728478,"mc":[{"id":"1.187595435","rc":[{"batb":[[0,2.58,18.98],[1,1.01,7]],"ltp":3.65,"tv":215.48,"id":9634224},{"batb":[[0,1.45,66.66],[1,1.36,255.54],[2,1.01,7]],"ltp":1.54,"tv":24118.39,"id":11252269}]}]}
{"op":"mcm","clk":"4230710748","pt":1631535760557,"mc":[{"id":"1.187595435","rc":[{"batb":[[0,1.01,7],[1,1.01,0]],"ltp":3.65,"tv":215.48,"id":9634224},{"batb":[[0,1.36,255.54],[1,1.01,7],[2,1.01,0]],"ltp":1.54,"tv":24118.39,"id":11252269}]}]}
{"op":"mcm","clk":"4230711313","pt":1631535765470,"mc":[{"id":"1.187595435","rc":[{"batb":[[0,2.42,21.12],[1,1.01,7]],"ltp":3.65,"tv":215.48,"id":9634224},{"batb":[[0,1.51,58.82],[1,1.36,255.54],[2,1.01,7]],"ltp":1.54,"tv":24118.39,"id":11252269}]}]}
{"op":"mcm","clk":"4230711450","pt":1631535766775,"mc":[{"id":"1.187595435","rc":[{"batb":[[1,2.04,401.22],[2,1.01,7]],"batl":[[0,3.9,159.57]],"ltp":3.65,"tv":215.48,"id":9634224}]}]}
{"op":"mcm","clk":"4230713321","pt":1631535783998,"mc":[{"id":"1.187595435","rc":[{"batb":[[1,1.45,255.54],[2,1.36,255.54]],"ltp":1.54,"tv":24118.39,"id":11252269}]}]}
{"op":"mcm","clk":"4230713670","pt":1631535786882,"mc":[{"id":"1.187595435","rc":[{"batl":[[0,1.66,255.54]],"ltp":1.54,"tv":24118.39,"id":11252269}]}]}
{"op":"mcm","clk":"4230715662","pt":1631535806338,"mc":[{"id":"1.187595435","rc":[{"batb":[[0,2.04,401.22],[1,1.01,7],[2,1.01,0]],"ltp":3.65,"tv":215.48,"id":9634224},{"batb":[[0,1.45,255.54],[1,1.36,255.54],[2,1.01,7]],"ltp":1.54,"tv":24118.39,"id":11252269}]}]}
{"op":"mcm","clk":"4230715866","pt":1631535808216,"mc":[{"id":"1.187595435","rc":[{"batb":[[0,1.01,7],[1,1.01,0]],"ltp":3.65,"tv":215.48,"id":9634224}]}]}
{"op":"mcm","clk":"4230716038","pt":1631535809842,"mc":[{"id":"1.187595435","rc":[{"batb":[[0,1.36,255.54],[1,1.01,7],[2,1.01,0]],"ltp":1.54,"tv":24118.39,"id":11252269}]}]}
{"op":"mcm","clk":"4230716181","pt":1631535811217,"mc":[{"id":"1.187595435","rc":[{"batb":[[0,2.58,18.98],[1,1.01,7]],"ltp":3.65,"tv":215.48,"id":9634224},{"batb":[[0,1.45,66.66],[1,1.36,255.54],[2,1.01,7]],"ltp":1.54,"tv":24118.39,"id":11252269}]}]}
{"op":"mcm","clk":"4230716521","pt":1631535814625,"mc":[{"id":"1.187595435","rc":[{"batb":[[1,2.22,391.36],[2,1.01,7]],"batl":[[0,4.6,137.18]],"ltp":3.65,"tv":215.48,"id":9634224}]}]}
{"op":"mcm","clk":"4230718277","pt":1631535832943,"mc":[{"id":"1.187595435","rc":[{"batb":[[0,2.22,391.36],[1,1.01,7],[2,1.01,0]],"ltp":3.65,"tv":215.48,"id":9634224},{"batb":[[0,1.36,255.54],[1,1.01,7],[2,1.01,0]],"ltp":1.54,"tv":24118.39,"id":11252269}]}]}
{"op":"mcm","clk":"4230718367","pt":1631535833677,"mc":[{"id":"1.187595435","rc":[{"batb":[[0,1.01,7],[1,1.01,0]],"ltp":3.65,"tv":215.48,"id":9634224}]}]}
{"op":"mcm","clk":"4230718838","pt":1631535837862,"mc":[{"id":"1.187595435","rc":[{"batb":[[0,3,15],[1,1.01,7]],"ltp":3.65,"tv":215.48,"id":9634224},{"batb":[[1,1.34,88.23],[2,1.01,7]],"ltp":1.54,"tv":24118.39,"id":11252269}]}]}
{"op":"mcm","clk":"4230719090","pt":1631535840177,"mc":[{"id":"1.187595435","rc":[{"batb":[[1,2.42,388.42],[2,1.01,7]],"batl":[[0,5.5,116.02]],"ltp":3.65,"tv":215.48,"id":9634224},{"batb":[[0,1.34,88.23],[1,1.01,7],[2,1.01,0]],"ltp":1.54,"tv":24118.39,"id":11252269}]}]}
{"op":"mcm","clk":"4230719795","pt":1631535846106,"mc":[{"id":"1.187595435","rc":[{"batb":[[1,1.28,255.54],[2,1.01,7]],"ltp":1.54,"tv":24118.39,"id":11252269}]}]}
{"op":"mcm","clk":"4230721482","pt":1631535863078,"mc":[{"id":"1.187595435","rc":[{"batb":[[0,2.42,388.42],[1,1.01,7],[2,1.01,0]],"ltp":3.65,"tv":215.48,"id":9634224},{"batb":[[0,1.28,255.54],[1,1.01,7],[2,1.01,0]],"ltp":1.54,"tv":24118.39,"id":11252269}]}]}
{"op":"mcm","clk":"4230721952","pt":1631535867957,"mc":[{"id":"1.187595435","rc":[{"batb":[[0,3.15,13.95],[1,2.42,388.42],[2,1.01,7]],"ltp":3.65,"tv":215.48,"id":9634224},{"batb":[[0,1.31,96.77],[1,1.28,255.54],[2,1.01,7]],"ltp":1.54,"tv":24118.39,"id":11252269}]}]}
{"op":"mcm","clk":"4230722794","pt":1631535877463,"mc":[{"id":"1.187595435","rc":[{"batb":[[0,1.01,7],[1,2.42,0],[2,1.01,0]],"ltp":3.65,"tv":215.48,"id":9634224},{"batb":[[0,1.28,255.54],[1,1.01,7],[2,1.01,0]],"ltp":1.54,"tv":24118.39,"id":11252269}]}]}
{"op":"mcm","clk":"4230723170","pt":1631535882165,"mc":[{"id":"1.187595435","rc":[{"batb":[[0,3.7,11.11],[1,1.01,7]],"ltp":3.65,"tv":215.48,"id":9634224},{"batb":[[0,1.23,130.43]],"ltp":1.54,"tv":24118.39,"id":11252269}]}]}
{"op":"mcm","clk":"4230723292","pt":1631535883671,"mc":[{"id":"1.187595435","rc":[{"batb":[[1,2.72,384.74],[2,1.01,7]],"batl":[[0,7.2,92.97]],"ltp":3.65,"tv":215.48,"id":9634224}]}]}
{"op":"mcm","clk":"4230723732","pt":1631535888610,"mc":[{"id":"1.187595435","rc":[{"batb":[[1,1.2,255.54],[2,1.01,7]],"ltp":1.54,"tv":24118.39,"id":11252269}]}]}
{"op":"mcm","clk":"4230723847","pt":1631535890069,"mc":[{"id":"1.187595435","rc":[{"batl":[[0,1.4,255.54],[1,1.66,255.54]],"ltp":1.54,"tv":24118.39,"id":11252269}]}]}
{"op":"mcm","clk":"4230724939","pt":1631535904629,"mc":[{"id":"1.187595435","rc":[{"batb":[[0,2.72,384.74],[1,1.01,7],[2,1.01,0]],"ltp":3.65,"tv":215.48,"id":9634224}]}]}
{"op":"mcm","clk":"4230725343","pt":1631535909527,"mc":[{"id":"1.187595435","rc":[{"batb":[[0,3.95,10.16],[1,2.72,384.74],[2,1.01,7]],"ltp":3.65,"tv":215.48,"id":9634224}]}]}
{"op":"mcm","clk":"4230726251","pt":1631535921844,"mc":[{"id":"1.187595435","rc":[{"batb":[[0,2.72,384.74],[1,1.01,7],[2,1.01,0]],"ltp":3.65,"tv":215.48,"id":9634224},{"batb":[[0,1.2,255.54],[1,1.01,7],[2,1.01,0]],"ltp":1.54,"tv":24118.39,"id":11252269}]}]}
{"op":"mcm","clk":"4230726375","pt":1631535923768,"mc":[{"id":"1.187595435","rc":[{"batb":[[0,1.01,7],[1,1.01,0]],"ltp":3.65,"tv":215.48,"id":9634224}]}]}
{"op":"mcm","clk":"4230726675","pt":1631535927584,"mc":[{"id":"1.187595435","rc":[{"batb":[[0,4.3,10],[1,1.01,7]],"ltp":3.65,"tv":215.48,"id":9634224},{"batb":[[0,1.18,166.66]],"ltp":1.54,"tv":24118.39,"id":11252269}]}]}
{"op":"mcm","clk":"4230726818","pt":1631535929546,"mc":[{"id":"1.187595435","rc":[{"batb":[[1,2.98,380.61],[2,1.01,7]],"batl":[[0,9.4,78.75]],"ltp":3.65,"tv":215.48,"id":9634224}]}]}
{"op":"mcm","clk":"4230726965","pt":1631535931472,"mc":[{"id":"1.187595435","rc":[{"batl":[[0,1.66,255.54],[1,1.66,0]],"ltp":1.54,"tv":24118.39,"id":11252269}]}]}
{"op":"mcm","clk":"4230727199","pt":1631535934477,"mc":[{"id":"1.187595435","rc":[{"batb":[[1,1.15,255.54],[2,1.01,7]],"ltp":1.54,"tv":24118.39,"id":11252269}]}]}
{"op":"mcm","clk":"4230727289","pt":1631535935662,"mc":[{"id":"1.187595435","rc":[{"batl":[[0,1.3,255.54],[1,1.66,255.54]],"ltp":1.54,"tv":24118.39,"id":11252269}]}]}
{"op":"mcm","clk":"4230729622","pt":1631535966229,"mc":[{"id":"1.187595435","rc":[{"batb":[[0,2.98,380.61],[1,1.01,7],[2,1.01,0]],"ltp":3.65,"tv":215.48,"id":9634224},{"batb":[[0,1.15,255.54],[1,1.01,7],[2,1.01,0]],"ltp":1.54,"tv":24118.39,"id":11252269}]}]}
{"op":"mcm","clk":"4230729877","pt":1631535969722,"mc":[{"id":"1.187595435","rc":[{"batb":[[0,1.01,7],[1,1.01,0]],"ltp":1.54,"tv":24118.39,"id":11252269}]}]}
{"op":"mcm","clk":"4230729977","pt":1631535971237,"mc":[{"id":"1.187595435","rc":[{"batb":[[0,5.8,10],[1,2.98,380.61],[2,1.01,7]],"ltp":3.65,"tv":215.48,"id":9634224},{"batb":[[0,1.11,272.72],[1,1.01,7]],"ltp":1.54,"tv":24118.39,"id":11252269}]}]}
{"op":"mcm","clk":"4230730136","pt":1631535973210,"mc":[{"id":"1.187595435","rc":[{"batl":[[0,12,68.42]],"ltp":3.65,"tv":215.48,"id":9634224}]}]}
{"op":"mcm","clk":"4230730172","pt":1631535973729,"mc":[{"id":"1.187595435","rc":[{"batl":[[0,1.2,255.54],[1,1.3,255.54]],"ltp":1.54,"tv":24118.39,"id":11252269}]}]}
{"op":"mcm","clk":"4230730308","pt":1631535975708,"mc":[{"id":"1.187595435","rc":[{"batb":[[1,1.09,255.54],[2,1.01,7]],"ltp":1.54,"tv":24118.39,"id":11252269}]}]}
{"op":"mcm","clk":"4230732821","pt":1631536008122,"mc":[{"id":"1.187595435","rc":[{"batb":[[0,2.98,380.61],[1,1.01,7],[2,1.01,0]],"ltp":3.65,"tv":215.48,"id":9634224},{"batb":[[0,1.09,255.54],[1,1.01,7],[2,1.01,0]],"ltp":1.54,"tv":24118.39,"id":11252269}]}]}
{"op":"mcm","clk":"4230733045","pt":1631536011052,"mc":[{"id":"1.187595435","rc":[{"batl":[[0,1.3,255.54],[1,1.3,0]],"ltp":1.54,"tv":24118.39,"id":11252269}]}]}
{"op":"mcm","clk":"4230733227","pt":1631536013046,"mc":[{"id":"1.187595435","rc":[{"batb":[[0,4.3,10],[1,2.98,380.61],[2,1.01,7]],"ltp":3.65,"tv":215.48,"id":9634224},{"batb":[[0,1.18,166.66],[1,1.09,255.54],[2,1.01,7]],"ltp":1.54,"tv":24118.39,"id":11252269}]}]}
{"op":"mcm","clk":"4230733388","pt":1631536014935,"mc":[{"id":"1.187595435","rc":[{"batl":[[0,9.4,78.75]],"ltp":3.65,"tv":215.48,"id":9634224}]}]}
{"op":"mcm","clk":"4230735520","pt":1631536041227,"mc":[{"id":"1.187595435","rc":[{"batl":[[0,8.2,86.22]],"ltp":3.65,"tv":215.48,"id":9634224}]}]}
{"op":"mcm","clk":"4230736198","pt":1631536049026,"mc":[{"id":"1.187595435","rc":[{"batb":[[0,2.98,380.61],[1,1.01,7],[2,1.01,0]],"ltp":3.65,"tv":215.48,"id":9634224},{"batb":[[0,1.09,255.54],[1,1.01,7],[2,1.01,0]],"ltp":1.54,"tv":24118.39,"id":11252269}]}]}
{"op":"mcm","clk":"4230736614","pt":1631536053909,"mc":[{"id":"1.187595435","rc":[{"batb":[[0,5.8,10],[1,2.98,380.61],[2,1.01,7]],"ltp":3.65,"tv":215.48,"id":9634224},{"batb":[[0,1.11,272.72],[1,1.09,255.54],[2,1.01,7]],"ltp":1.54,"tv":24118.39,"id":11252269}]}]}
{"op":"mcm","clk":"4230736853","pt":1631536056596,"mc":[{"id":"1.187595435","rc":[{"batl":[[0,12,68.42]],"ltp":3.65,"tv":215.48,"id":9634224}]}]}
{"op":"mcm","clk":"4230736924","pt":1631536057562,"mc":[{"id":"1.187595435","rc":[{"batl":[[0,1.2,255.54],[1,1.3,255.54]],"ltp":1.54,"tv":24118.39,"id":11252269}]}]}
{"op":"mcm","clk":"4230738626","pt":1631536077862,"mc":[{"id":"1.187595435","rc":[{"batb":[[0,1.09,255.54],[1,1.01,7],[2,1.01,0]],"ltp":1.54,"tv":24118.39,"id":11252269}]}]}
{"op":"mcm","clk":"4230739036","pt":1631536082759,"mc":[{"id":"1.187595435","rc":[{"batb":[[0,1.12,249.99],[1,1.09,255.54],[2,1.01,7]],"ltp":1.54,"tv":24118.39,"id":11252269}]}]}
{"op":"mcm","clk":"4230739314","pt":1631536086178,"mc":[{"id":"1.187595435","rc":[{"batl":[[0,10.5,72.99]],"ltp":3.65,"tv":215.48,"id":9634224}]}]}
{"op":"mcm","clk":"4230740074","pt":1631536095166,"mc":[{"id":"1.187595435","rc":[{"batb":[[0,2.98,380.61],[1,1.01,7],[2,1.01,0]],"ltp":3.65,"tv":215.48,"id":9634224},{"batb":[[0,1.09,255.54],[1,1.01,7],[2,1.01,0]],"ltp":1.54,"tv":24118.39,"id":11252269}]}]}
{"op":"mcm","clk":"4230740181","pt":1631536096281,"mc":[{"id":"1.187595435","rc":[{"batb":[[0,1.01,7],[1,1.01,0]],"ltp":3.65,"tv":215.48,"id":9634224}]}]}
{"op":"mcm","clk":"4230740445","pt":1631536099078,"mc":[{"id":"1.187595435","rc":[{"batb":[[0,1.01,7],[1,1.01,0]],"ltp":1.54,"tv":24118.39,"id":11252269}]}]}
{"op":"mcm","clk":"4230740551","pt":1631536100186,"mc":[{"id":"1.187595435","rc":[{"batb":[[0,6,10],[1,1.01,7]],"ltp":3.65,"tv":215.48,"id":9634224},{"batb":[[0,1.08,374.99],[1,1.01,7]],"ltp":1.54,"tv":24118.39,"id":11252269}]}]}
{"op":"mcm","clk":"4230740703","pt":1631536102163,"mc":[{"id":"1.187595435","rc":[{"batb":[[1,3.4,382.33],[2,1.01,7]],"batl":[[0,15.5,60.23]],"ltp":3.65,"tv":215.48,"id":9634224}]}]}
{"op":"mcm","clk":"4230740908","pt":1631536104573,"mc":[{"id":"1.187595435","rc":[{"batb":[[1,1.07,255.54],[2,1.01,7]],"ltp":1.54,"tv":24118.39,"id":11252269}]}]}
{"op":"mcm","clk":"4230740976","pt":1631536105573,"mc":[{"id":"1.187595435","rc":[{"batb":[[0,1.08,630.53],[2,1.06,255.54]],"batl":[[1,1.3,0]],"ltp":1.54,"tv":24118.39,"id":11252269}]}]}
{"op":"mcm","clk":"4230741238","pt":1631536108694,"mc":[{"id":"1.187595435","rc":[{"batl":[[0,1.16,255.54]],"ltp":1.54,"tv":24118.39,"id":11252269}]}]}
{"op":"mcm","clk":"4230741480","pt":1631536111380,"mc":[{"id":"1.187595435","rc":[{"batl":[[1,1.17,255.54]],"ltp":1.54,"tv":24118.39,"id":11252269}]}]}
{"op":"mcm","clk":"4230742451","pt":1631536122595,"mc":[{"id":"1.187595435","rc":[{"batb":[[0,3.4,382.33],[1,1.01,7],[2,1.01,0]],"ltp":3.65,"tv":215.48,"id":9634224},{"batb":[[0,1.08,255.54]],"ltp":1.54,"tv":24118.39,"id":11252269}]}]}
{"op":"mcm","clk":"4230742608","pt":1631536124518,"mc":[{"id":"1.187595435","rc":[{"batb":[[0,1.07,255.54],[1,1.06,255.54],[2,1.05,255.54]],"ltp":1.54,"tv":24118.39,"id":11252269}]}]}
{"op":"mcm","clk":"4230742637","pt":1631536124892,"mc":[{"id":"1.187595435","rc":[{"batb":[[0,1.06,255.54],[1,1.05,255.54],[2,1.04,511.07]],"ltp":1.54,"tv":24118.39,"id":11252269}]}]}
{"op":"mcm","clk":"4230742826","pt":1631536127617,"mc":[{"id":"1.187595435","rc":[{"batb":[[0,7.6,10],[1,3.4,382.33],[2,1.01,7]],"ltp":3.65,"tv":215.48,"id":9634224},{"batb":[[1,1.05,855.53]],"ltp":1.54,"tv":24118.39,"id":11252269}]}]}
{"op":"mcm","clk":"4230742983","pt":1631536129599,"mc":[{"id":"1.187595435","rc":[{"batl":[[0,21,54.05]],"ltp":3.65,"tv":215.48,"id":9634224}]}]}
{"op":"mcm","clk":"4230744289","pt":1631536146314,"mc":[{"id":"1.187595435","rc":[{"trd":[[7.6,9.57]],"batb":[[0,3.4,382.33],[1,1.01,7],[2,1.01,0]],"ltp":7.6,"tv":225.05,"id":9634224}],"tv":24343.44}]}
{"op":"mcm","clk":"4230744724","pt":1631536151365,"mc":[{"id":"1.187595435","rc":[{"batb":[[0,7.6,10],[1,3.4,382.33],[2,1.01,7]],"ltp":7.6,"tv":225.05,"id":9634224}]}]}
{"op":"mcm","clk":"4230750724","pt":1631536226330,"mc":[{"id":"1.187595435","rc":[{"batb":[[0,3.4,382.33],[1,1.01,7],[2,1.01,0]],"ltp":7.6,"tv":225.05,"id":9634224},{"batb":[[1,1.05,255.54]],"ltp":1.54,"tv":24118.39,"id":11252269}]}]}
{"op":"mcm","clk":"4230751155","pt":1631536231353,"mc":[{"id":"1.187595435","rc":[{"batb":[[0,6,10],[1,3.4,382.33],[2,1.01,7]],"ltp":7.6,"tv":225.05,"id":9634224},{"batb":[[0,1.08,374.99],[1,1.06,255.54],[2,1.05,255.54]],"ltp":1.54,"tv":24118.39,"id":11252269}]}]}
{"op":"mcm","clk":"4230751371","pt":1631536233655,"mc":[{"id":"1.187595435","rc":[{"batl":[[0,15.5,60.23]],"ltp":7.6,"tv":225.05,"id":9634224}]}]}
{"op":"mcm","clk":"4230751594","pt":1631536236212,"mc":[{"id":"1.187595435","rc":[{"batl":[[0,1.2,255.54]],"ltp":1.54,"tv":24118.39,"id":11252269}]}]}
{"op":"mcm","clk":"4230754520","pt":1631536269788,"mc":[{"id":"1.187595435","rc":[{"batb":[[0,3.4,382.33],[1,1.01,7],[2,1.01,0]],"ltp":7.6,"tv":225.05,"id":9634224},{"batb":[[0,1.06,255.54],[1,1.05,255.54],[2,1.04,511.07]],"ltp":1.54,"tv":24118.39,"id":11252269}]}]}
{"op":"mcm","clk":"4230754932","pt":1631536274702,"mc":[{"id":"1.187595435","rc":[{"batb":[[0,5.3,10],[1,3.4,382.33],[2,1.01,7]],"ltp":7.6,"tv":225.05,"id":9634224},{"batb":[[0,1.12,249.99],[1,1.06,255.54],[2,1.05,255.54]],"ltp":1.54,"tv":24118.39,"id":11252269}]}]}
{"op":"mcm","clk":"4230755251","pt":1631536278217,"mc":[{"id":"1.187595435","rc":[{"batl":[[0,10.5,72.99]],"ltp":7.6,"tv":225.05,"id":9634224},{"batl":[[0,1.24,255.54]],"ltp":1.54,"tv":24118.39,"id":11252269}]}]}
{"op":"mcm","clk":"4230755440","pt":1631536279898,"mc":[{"id":"1.187595435","rc":[{"batb":[[0,1.13,255.54],[1,1.12,249.99],[2,1.06,255.54]],"ltp":1.54,"tv":24118.39,"id":11252269}]}]}
{"op":"mcm","clk":"4230757241","pt":1631536301833,"mc":[{"id":"1.187595435","rc":[{"batl":[[0,12,68.42]],"ltp":7.6,"tv":225.05,"id":9634224}]}]}
{"op":"mcm","clk":"4230758315","pt":1631536313764,"mc":[{"id":"1.187595435","rc":[{"batb":[[0,3.4,382.33],[1,1.01,7],[2,1.01,0]],"ltp":7.6,"tv":225.05,"id":9634224},{"batb":[[1,1.06,255.54],[2,1.05,255.54]],"ltp":1.54,"tv":24118.39,"id":11252269}]}]}
{"op":"mcm","clk":"4230758566","pt":1631536316786,"mc":[{"id":"1.187595435","rc":[{"batb":[[0,1.06,255.54],[1,1.05,255.54],[2,1.04,511.07]],"ltp":1.54,"tv":24118.39,"id":11252269}]}]}
{"op":"mcm","clk":"4230758729","pt":1631536318777,"mc":[{"id":"1.187595435","rc":[{"batb":[[0,6,10],[1,3.4,382.33],[2,1.01,7]],"ltp":7.6,"tv":225.05,"id":9634224},{"batb":[[0,1.08,374.99],[1,1.06,255.54],[2,1.05,255.54]],"ltp":1.54,"tv":24118.39,"id":11252269}]}]}
{"op":"mcm","clk":"4230759098","pt":1631536322581,"mc":[{"id":"1.187595435","rc":[{"batb":[[0,1.11,255.54],[1,1.1,255.54],[2,1.08,374.99]],"ltp":1.54,"tv":24118.39,"id":11252269}]}]}
{"op":"mcm","clk":"4230761922","pt":1631536354483,"mc":[{"id":"1.187595435","rc":[{"batb":[[0,3.4,382.33],[1,1.01,7],[2,1.01,0]],"ltp":7.6,"tv":225.05,"id":9634224},{"batb":[[2,1.06,255.54]],"ltp":1.54,"tv":24118.39,"id":11252269}]}]}
{"op":"mcm","clk":"4230762173","pt":1631536357561,"mc":[{"id":"1.187595435","rc":[{"batb":[[0,1.06,255.54],[1,1.05,255.54],[2,1.04,511.07]],"ltp":1.54,"tv":24118.39,"id":11252269}]}]}
{"op":"mcm","clk":"4230762320","pt":1631536359395,"mc":[{"id":"1.187595435","rc":[{"batb":[[0,7.6,10],[1,3.4,382.33],[2,1.01,7]],"ltp":7.6,"tv":225.05,"id":9634224},{"batb":[[1,1.05,855.53]],"ltp":1.54,"tv":24118.39,"id":11252269}]}]}
{"op":"mcm","clk":"4230762533","pt":1631536361597,"mc":[{"id":"1.187595435","rc":[{"batl":[[0,21,54.05]],"ltp":7.6,"tv":225.05,"id":9634224}]}]}
{"op":"mcm","clk":"4230762756","pt":1631536363950,"mc":[{"id":"1.187595435","rc":[{"batl":[[0,1.12,255.54],[1,1.24,255.54]],"ltp":1.54,"tv":24118.39,"id":11252269}]}]}
{"op":"mcm","clk":"4230764703","pt":1631536383714,"mc":[{"id":"1.187595435","rc":[{"batb":[[1,1.01,7],[2,1.01,0]],"ltp":7.6,"tv":225.05,"id":9634224}]}]}
{"op":"mcm","clk":"4230764908","pt":1631536385912,"mc":[{"id":"1.187595435","rc":[{"trd":[[9.2,5.32]],"ltp":9.2,"tv":230.37,"id":9634224},{"trd":[[1.12,47.54]],"batl":[[0,1.12,211.84]],"ltp":1.12,"tv":24162.08,"id":11252269}],"tv":24392.46}]}
{"op":"mcm","clk":"4230765317","pt":1631536389884,"mc":[{"id":"1.187595435","rc":[{"batb":[[0,1.01,7],[1,1.01,0]],"ltp":9.2,"tv":230.37,"id":9634224},{"batb":[[1,1.05,255.54]],"ltp":1.12,"tv":24162.08,"id":11252269}]}]}
{"op":"mcm","clk":"4230765529","pt":1631536392179,"mc":[{"id":"1.187595435","rc":[{"batl":[[0,1.24,255.54],[1,1.24,0]],"ltp":1.12,"tv":24162.08,"id":11252269}]}]}
{"op":"mcm","clk":"4230765777","pt":1631536394780,"mc":[{"id":"1.187595435","rc":[{"batb":[[0,5.8,10],[1,1.01,7]],"ltp":9.2,"tv":230.37,"id":9634224},{"batb":[[0,1.11,272.72],[1,1.06,255.54],[2,1.05,255.54]],"ltp":1.12,"tv":24162.08,"id":11252269}]}]}
{"op":"mcm","clk":"4230765915","pt":1631536396314,"mc":[{"id":"1.187595435","rc":[{"batb":[[1,3.3,379.13],[2,1.01,7]],"batl":[[0,13.5,64.69]],"ltp":9.2,"tv":230.37,"id":9634224}]}]}
{"op":"mcm","clk":"4230766042","pt":1631536397515,"mc":[{"id":"1.187595435","rc":[{"batb":[[0,1.12,43.7],[1,1.11,272.72],[2,1.06,255.54]],"ltp":1.12,"tv":24162.08,"id":11252269}]}]}
{"op":"mcm","clk":"4230766226","pt":1631536399809,"mc":[{"id":"1.187595435","rc":[{"batl":[[0,1.21,255.54],[1,1.24,255.54]],"ltp":1.12,"tv":24162.08,"id":11252269}]}]}
{"op":"mcm","clk":"4230766401","pt":1631536401997,"mc":[{"id":"1.187595435","rc":[{"batb":[[0,1.17,41.82],[1,1.12,43.7],[2,1.11,272.72]],"ltp":1.12,"tv":24162.08,"id":11252269}]}]}
{"op":"mcm","clk":"4230767498","pt":1631536415206,"mc":[{"id":"1.187595435","rc":[{"batl":[[0,1.24,255.54],[1,1.24,0]],"ltp":1.12,"tv":24162.08,"id":11252269}]}]}
{"op":"mcm","clk":"4230767757","pt":1631536418222,"mc":[{"id":"1.187595435","rc":[{"batb":[[0,3.3,379.13],[1,1.01,7],[2,1.01,0]],"ltp":9.2,"tv":230.37,"id":9634224},{"batb":[[2,1.06,255.54]],"ltp":1.12,"tv":24162.08,"id":11252269}]}]}
{"op":"mcm","clk":"4230768207","pt":1631536423238,"mc":[{"id":"1.187595435","rc":[{"batb":[[0,4.3,10],[1,3.3,379.13],[2,1.01,7]],"ltp":9.2,"tv":230.37,"id":9634224},{"batb":[[0,1.18,166.66],[1,1.17,41.82],[2,1.12,43.7]],"ltp":1.12,"tv":24162.08,"id":11252269}]}]}
{"op":"mcm","clk":"4230768243","pt":1631536423753,"mc":[{"id":"1.187595435","rc":[{"batb":[[0,1.21,40.44],[1,1.18,166.66],[2,1.17,41.82]],"ltp":1.12,"tv":24162.08,"id":11252269}]}]}
{"op":"mcm","clk":"4230768375","pt":1631536425431,"mc":[{"id":"1.187595435","rc":[{"batl":[[0,8.2,86.22]],"ltp":9.2,"tv":230.37,"id":9634224}]}]}
{"op":"mcm","clk":"4230768394","pt":1631536425644,"mc":[{"id":"1.187595435","rc":[{"batl":[[0,1.32,255.54]],"ltp":1.12,"tv":24162.08,"id":11252269}]}]}
{"op":"mcm","clk":"4230768640","pt":1631536427947,"mc":[{"id":"1.187595435","rc":[{"batb":[[2,1.12,43.7]],"ltp":1.12,"tv":24162.08,"id":11252269}]}]}
{"op":"mcm","clk":"4230768723","pt":1631536428838,"mc":[{"id":"1.187595435","rc":[{"batb":[[2,1.06,255.54]],"ltp":1.12,"tv":24162.08,"id":11252269}]}]}
{"op":"mcm","clk":"4230769159","pt":1631536433854,"mc":[{"id":"1.187595435","rc":[{"batb":[[2,1.12,1.86]],"ltp":1.12,"tv":24162.08,"id":11252269}]}]}
{"op":"mcm","clk":"4230771875","pt":1631536463506,"mc":[{"id":"1.187595435","rc":[{"batb":[[0,3.3,379.13],[1,1.01,7],[2,1.01,0]],"ltp":9.2,"tv":230.37,"id":9634224},{"batb":[[1,1.12,1.86],[2,1.06,255.54]],"ltp":1.12,"tv":24162.08,"id":11252269}]}]}
{"op":"mcm","clk":"4230772193","pt":1631536466694,"mc":[{"id":"1.187595435","rc":[{"batb":[[0,1.12,1.86],[1,1.06,255.54],[2,1.05,255.54]],"ltp":1.12,"tv":24162.08,"id":11252269}]}]}
{"op":"mcm","clk":"4230772373","pt":1631536468510,"mc":[{"id":"1.187595435","rc":[{"batb":[[0,5.8,10],[1,3.3,379.13],[2,1.01,7]],"ltp":9.2,"tv":230.37,"id":9634224},{"batb":[[1,1.11,272.72],[2,1.06,255.54]],"ltp":1.12,"tv":24162.08,"id":11252269}]}]}
{"op":"mcm","clk":"4230772696","pt":1631536471993,"mc":[{"id":"1.187595435","rc":[{"batl":[[0,12,68.42]],"ltp":9.2,"tv":230.37,"id":9634224}]}]}
{"op":"mcm","clk":"4230772818","pt":1631536473399,"mc":[{"id":"1.187595435","rc":[{"batl":[[0,1.21,255.54],[1,1.32,255.54]],"ltp":1.12,"tv":24162.08,"id":11252269}]}]}
{"op":"mcm","clk":"4230773005","pt":1631536475518,"mc":[{"id":"1.187595435","rc":[{"batb":[[0,1.14,42.93],[1,1.12,1.86],[2,1.11,272.72]],"ltp":1.12,"tv":24162.08,"id":11252269}]}]}
{"op":"mcm","clk":"4230775913","pt":1631536507662,"mc":[{"id":"1.187595435","rc":[{"batb":[[0,3.3,379.13],[1,1.01,7],[2,1.01,0]],"ltp":9.2,"tv":230.37,"id":9634224},{"batb":[[2,1.06,255.54]],"ltp":1.12,"tv":24162.08,"id":11252269}]}]}
{"op":"mcm","clk":"4230776061","pt":1631536509250,"mc":[{"id":"1.187595435","rc":[{"batl":[[0,1.32,255.54],[1,1.32,0]],"ltp":1.12,"tv":24162.08,"id":11252269}]}]}
{"op":"mcm","clk":"4230776456","pt":1631536513376,"mc":[{"id":"1.187595435","rc":[{"batb":[[0,4.3,10],[1,3.3,379.13],[2,1.01,7]],"ltp":9.2,"tv":230.37,"id":9634224},{"batb":[[0,1.21,40.44],[1,1.18,166.66],[2,1.14,42.93]],"ltp":1.12,"tv":24162.08,"id":11252269}]}]}
{"op":"mcm","clk":"4230776586","pt":1631536514872,"mc":[{"id":"1.187595435","rc":[{"batl":[[0,8.2,86.22]],"ltp":9.2,"tv":230.37,"id":9634224}]}]}
{"op":"mcm","clk":"4230778717","pt":1631536537303,"mc":[{"id":"1.187595435","rc":[{"batb":[[0,3.3,379.13],[1,1.01,7],[2,1.01,0]],"ltp":9.2,"tv":230.37,"id":9634224},{"batb":[[1,1.14,42.93],[2,1.12,1.86]],"ltp":1.12,"tv":24162.08,"id":11252269}]}]}
{"op":"mcm","clk":"4230778758","pt":1631536537790,"mc":[{"id":"1.187595435","rc":[{"batb":[[0,1.01,7],[1,1.01,0]],"ltp":9.2,"tv":230.37,"id":9634224}]}]}
{"op":"mcm","clk":"4230779188","pt":1631536542190,"mc":[{"id":"1.187595435","rc":[{"batb":[[0,3.4,12.5],[1,1.01,7]],"ltp":9.2,"tv":230.37,"id":9634224},{"batb":[[0,1.27,111.11],[1,1.21,40.44],[2,1.14,42.93]],"ltp":1.12,"tv":24162.08,"id":11252269}]}]}
{"op":"mcm","clk":"4230779323","pt":1631536543502,"mc":[{"id":"1.187595435","rc":[{"batb":[[1,2.62,385.81],[2,1.01,7]],"batl":[[0,6.6,99.8]],"ltp":9.2,"tv":230.37,"id":9634224},{"batb":[[0,1.31,37.36],[1,1.27,111.11],[2,1.21,40.44]],"ltp":1.12,"tv":24162.08,"id":11252269}]}]}
{"op":"mcm","clk":"4230779388","pt":1631536544080,"mc":[{"id":"1.187595435","rc":[{"batb":[[0,1.32,37.07],[1,1.31,37.36],[2,1.27,111.11]],"ltp":1.12,"tv":24162.08,"id":11252269}]}]}
{"op":"mcm","clk":"4230779659","pt":1631536546815,"mc":[{"id":"1.187595435","rc":[{"batl":[[0,1.46,255.54]],"ltp":1.12,"tv":24162.08,"id":11252269}]}]}
{"op":"mcm","clk":"4230780360","pt":1631536554203,"mc":[{"id":"1.187595435","rc":[{"batb":[[1,1.27,111.11],[2,1.21,40.44]],"ltp":1.12,"tv":24162.08,"id":11252269}]}]}
{"op":"mcm","clk":"4230780586","pt":1631536556502,"mc":[{"id":"1.187595435","rc":[{"batb":[[2,1.12,1.86]],"ltp":1.12,"tv":24162.08,"id":11252269}]}]}
{"op":"mcm","clk":"4230781036","pt":1631536561223,"mc":[{"id":"1.187595435","rc":[{"batb":[[0,1.27,111.11],[1,1.12,1.86],[2,1.06,255.54]],"ltp":1.12,"tv":24162.08,"id":11252269}]}]}
{"op":"mcm","clk":"4230781440","pt":1631536565345,"mc":[{"id":"1.187595435","rc":[{"batb":[[0,1.4,34.96],[1,1.27,111.11],[2,1.12,1.86]],"ltp":1.12,"tv":24162.08,"id":11252269}]}]}
{"op":"mcm","clk":"4230782005","pt":1631536571516,"mc":[{"id":"1.187595435","rc":[{"trd":[[3.5,9.57]],"ltp":3.5,"tv":239.94,"id":9634224},{"trd":[[1.4,23.94]],"batb":[[0,1.4,11.02]],"ltp":1.4,"tv":24186.02,"id":11252269}],"tv":24425.96}]}
{"op":"mcm","clk":"4230782227","pt":1631536573720,"mc":[{"id":"1.187595435","rc":[{"batb":[[0,2.62,385.81],[1,1.01,7],[2,1.01,0]],"ltp":3.5,"tv":239.94,"id":9634224},{"batb":[[1,1.12,1.86],[2,1.06,255.54]],"ltp":1.4,"tv":24186.02,"id":11252269}]}]}
{"op":"mcm","clk":"4230782395","pt":1631536575445,"mc":[{"id":"1.187595435","rc":[{"trd":[[3.5,13.98]],"batb":[[0,3.5,16.03],[1,2.62,385.81],[2,1.01,7]],"ltp":3.5,"tv":244.35,"id":9634224},{"trd":[[1.4,34.96]],"batb":[[0,1.12,1.86],[1,1.06,255.54],[2,1.05,255.54]],"ltp":1.4,"tv":24197.04,"id":11252269}],"tv":24441.4}]}
{"op":"mcm","clk":"4230782490","pt":1631536576442,"mc":[{"id":"1.187595435","rc":[{"batb":[[0,3.5,70.55]],"ltp":3.5,"tv":244.35,"id":9634224}]}]}
{"op":"mcm","clk":"4230782617","pt":1631536577556,"mc":[{"id":"1.187595435","rc":[{"batb":[[0,3.5,70.87]],"ltp":3.5,"tv":244.35,"id":9634224}]}]}
{"op":"mcm","clk":"4230782715","pt":1631536578554,"mc":[{"id":"1.187595435","rc":[{"batb":[[0,3.5,36.6]],"ltp":3.5,"tv":244.35,"id":9634224}]}]}
{"op":"mcm","clk":"4230782814","pt":1631536579548,"mc":[{"id":"1.187595435","rc":[{"batb":[[0,3.5,21.99],[1,3.3,13.04],[2,2.62,385.81]],"ltp":3.5,"tv":244.35,"id":9634224},{"batb":[[0,1.28,107.14],[1,1.12,1.86],[2,1.06,255.54]],"ltp":1.4,"tv":24197.04,"id":11252269}]}]}
{"op":"mcm","clk":"4230782951","pt":1631536580627,"mc":[{"id":"1.187595435","rc":[{"batb":[[0,3.5,22]],"ltp":3.5,"tv":244.35,"id":9634224}]}]}
{"op":"mcm","clk":"4230783024","pt":1631536581256,"mc":[{"id":"1.187595435","rc":[{"batb":[[0,3.3,13.04],[1,2.62,385.81],[2,1.01,7]],"ltp":3.5,"tv":244.35,"id":9634224},{"batb":[[1,1.06,255.54],[2,1.05,255.54]],"batl":[[0,1.5,255.54]],"ltp":1.4,"tv":24197.04,"id":11252269}]}]}
{"op":"mcm","clk":"4230783107","pt":1631536582145,"mc":[{"id":"1.187595435","rc":[{"batl":[[0,6,107.07]],"ltp":3.5,"tv":244.35,"id":9634224},{"batb":[[0,1.31,255.54],[1,1.28,107.14],[2,1.06,255.54]],"ltp":1.4,"tv":24197.04,"id":11252269}]}]}
{"op":"mcm","clk":"4230783181","pt":1631536582832,"mc":[{"id":"1.187595435","rc":[{"batb":[[2,1.23,255.54]],"ltp":1.4,"tv":24197.04,"id":11252269}]}]}
{"op":"mcm","clk":"4230783904","pt":1631536590143,"mc":[{"id":"1.187595435","rc":[{"batb":[[0,2.62,385.81],[1,1.01,7],[2,1.01,0]],"ltp":3.5,"tv":244.35,"id":9634224},{"batb":[[1,1.23,255.54],[2,1.06,255.54]],"ltp":1.4,"tv":24197.04,"id":11252269}]}]}
{"op":"mcm","clk":"4230784382","pt":1631536595047,"mc":[{"id":"1.187595435","rc":[{"batb":[[0,2.84,16.3],[1,2.62,385.81],[2,1.01,7]],"ltp":3.5,"tv":244.35,"id":9634224},{"batb":[[0,1.38,78.94],[1,1.31,255.54],[2,1.23,255.54]],"ltp":1.4,"tv":24197.04,"id":11252269}]}]}
{"op":"mcm","clk":"4230784642","pt":1631536597962,"mc":[{"id":"1.187595435","rc":[{"batl":[[0,4.9,127.33]],"ltp":3.5,"tv":244.35,"id":9634224}]}]}
{"op":"mcm","clk":"4230784774","pt":1631536599295,"mc":[{"id":"1.187595435","rc":[{"batb":[[1,1.36,255.54],[2,1.31,255.54]],"ltp":1.4,"tv":24197.04,"id":11252269}]}]}
{"op":"mcm","clk":"4230787221","pt":1631536623426,"mc":[{"id":"1.187595435","rc":[{"batb":[[0,2.62,385.81],[1,1.01,7],[2,1.01,0]],"ltp":3.5,"tv":244.35,"id":9634224},{"batb":[[0,1.36,255.54],[1,1.31,255.54],[2,1.23,255.54]],"ltp":1.4,"tv":24197.04,"id":11252269}]}]}
{"op":"mcm","clk":"4230787985","pt":1631536628386,"mc":[{"id":"1.187595435","rc":[{"batb":[[0,2.66,18.07],[1,2.62,385.81],[2,1.01,7]],"ltp":3.5,"tv":244.35,"id":9634224},{"batb":[[0,1.42,71.42],[1,1.36,255.54],[2,1.31,255.54]],"ltp":1.4,"tv":24197.04,"id":11252269}]}]}
{"op":"mcm","clk":"4230789740","pt":1631536645593,"mc":[{"id":"1.187595435","rc":[{"batb":[[0,2.62,385.81],[1,1.01,7],[2,1.01,0]],"ltp":3.5,"tv":244.35,"id":9634224},{"batb":[[0,1.36,255.54],[1,1.31,255.54],[2,1.23,255.54]],"ltp":1.4,"tv":24197.04,"id":11252269}]}]}
{"op":"mcm","clk":"4230790003","pt":1631536648717,"mc":[{"id":"1.187595435","rc":[{"batb":[[0,1.31,255.54],[1,1.23,255.54],[2,1.06,255.54]],"ltp":1.4,"tv":24197.04,"id":11252269}]}]}
{"op":"mcm","clk":"4230790182","pt":1631536650514,"mc":[{"id":"1.187595435","rc":[{"batb":[[0,3.15,13.95],[1,2.62,385.81],[2,1.01,7]],"ltp":3.5,"tv":244.35,"id":9634224},{"batb":[[0,1.31,96.77]],"ltp":1.4,"tv":24197.04,"id":11252269}]}]}
{"op":"mcm","clk":"4230790463","pt":1631536653385,"mc":[{"id":"1.187595435","rc":[{"batl":[[0,6,107.07]],"ltp":3.5,"tv":244.35,"id":9634224}]}]}
{"op":"mcm","clk":"4230790657","pt":1631536655324,"mc":[{"id":"1.187595435","rc":[{"batb":[[1,1.26,255.54],[2,1.23,255.54]],"ltp":1.4,"tv":24197.04,"id":11252269}]}]}
{"op":"mcm","clk":"4230790854","pt":1631536657208,"mc":[{"id":"1.187595435","rc":[{"batl":[[0,1.44,255.54],[1,1.45,255.54]],"ltp":1.4,"tv":24197.04,"id":11252269}]}]}
{"op":"mcm","clk":"4230793555","pt":1631536683949,"mc":[{"id":"1.187595435","rc":[{"batl":[[1,1.45,0]],"ltp":1.4,"tv":24197.04,"id":11252269}]}]}
{"op":"mcm","clk":"4230795930","pt":1631536707969,"mc":[{"id":"1.187595435","rc":[{"batb":[[0,2.62,385.81],[1,1.01,7],[2,1.01,0]],"ltp":3.5,"tv":244.35,"id":9634224},{"batb":[[0,1.26,255.54],[1,1.23,255.54],[2,1.06,255.54]],"ltp":1.4,"tv":24197.04,"id":11252269}]}]}
{"op":"mcm","clk":"4230796140","pt":1631536710599,"mc":[{"id":"1.187595435","rc":[{"batb":[[0,1.06,255.54],[1,1.05,255.54],[2,1.04,511.07]],"ltp":1.4,"tv":24197.04,"id":11252269}]}]}
{"op":"mcm","clk":"4230796181","pt":1631536710648,"mc":[{"id":"1.187595435","rc":[{"batb":[[0,1.01,7],[1,1.01,0]],"ltp":3.5,"tv":244.35,"id":9634224}]}]}
{"op":"mcm","clk":"4230796404","pt":1631536712887,"mc":[{"id":"1.187595435","rc":[{"batb":[[0,4.3,10],[1,1.01,7]],"ltp":3.5,"tv":244.35,"id":9634224},{"batb":[[0,1.18,166.66],[1,1.06,255.54],[2,1.05,255.54]],"ltp":1.4,"tv":24197.04,"id":11252269}]}]}
{"op":"mcm","clk":"4230796518","pt":1631536713777,"mc":[{"id":"1.187595435","rc":[{"batl":[[0,1.3,255.54],[1,1.44,255.54]],"ltp":1.4,"tv":24197.04,"id":11252269}]}]}
{"op":"mcm","clk":"4230796795","pt":1631536716495,"mc":[{"id":"1.187595435","rc":[{"batb":[[1,2.84,381.81],[2,1.01,7]],"batl":[[0,8.2,86.22]],"ltp":3.5,"tv":244.35,"id":9634224}]}]}
{"op":"mcm","clk":"4230800500","pt":1631536756058,"mc":[{"id":"1.187595435","rc":[{"trd":[[1.18,53.17]],"batb":[[0,1.06,255.54],[1,1.05,255.54],[2,1.04,511.07]],"ltp":1.18,"tv":24250.21,"id":11252269}],"tv":24494.56}]}
{"op":"mcm","clk":"4230800939","pt":1631536760953,"mc":[{"id":"1.187595435","rc":[{"batb":[[0,1.18,166.66],[1,1.06,255.54],[2,1.05,255.54]],"ltp":1.18,"tv":24250.21,"id":11252269}]}]}
{"op":"mcm","clk":"4230801065","pt":1631536762367,"mc":[{"id":"1.187595435","rc":[{"batb":[[1,1.01,7],[2,1.01,0]],"ltp":3.5,"tv":244.35,"id":9634224}]}]}
{"op":"mcm","clk":"4230801799","pt":1631536769940,"mc":[{"id":"1.187595435","rc":[{"batb":[[1,2.98,380.61],[2,1.01,7]],"batl":[[0,9.4,78.75]],"ltp":3.5,"tv":244.35,"id":9634224}]}]}
{"op":"mcm","clk":"4230802422","pt":1631536776923,"mc":[{"id":"1.187595435","rc":[{"batb":[[0,2.98,380.61],[1,1.01,7],[2,1.01,0]],"ltp":3.5,"tv":244.35,"id":9634224},{"batb":[[0,1.06,255.54],[1,1.05,255.54],[2,1.04,511.07]],"ltp":1.18,"tv":24250.21,"id":11252269}]}]}
{"op":"mcm","clk":"4230802566","pt":1631536778549,"mc":[{"id":"1.187595435","rc":[{"batb":[[0,1.01,7],[1,1.01,0]],"ltp":3.5,"tv":244.35,"id":9634224}]}]}
{"op":"mcm","clk":"4230802902","pt":1631536781827,"mc":[{"id":"1.187595435","rc":[{"batb":[[0,6,10],[1,1.01,7]],"ltp":3.5,"tv":244.35,"id":9634224},{"batb":[[0,1.08,374.99],[1,1.06,255.54],[2,1.05,255.54]],"ltp":1.18,"tv":24250.21,"id":11252269}]}]}
{"op":"mcm","clk":"4230803058","pt":1631536783437,"mc":[{"id":"1.187595435","rc":[{"batl":[[0,1.16,255.54],[1,1.3,255.54],[2,1.44,255.54]],"ltp":1.18,"tv":24250.21,"id":11252269}]}]}
{"op":"mcm","clk":"4230803175","pt":1631536784532,"mc":[{"id":"1.187595435","rc":[{"batb":[[1,3.4,382.33],[2,1.01,7]],"batl":[[0,15.5,60.23]],"ltp":3.5,"tv":244.35,"id":9634224}]}]}
{"op":"mcm","clk":"4230805053","pt":1631536804946,"mc":[{"id":"1.187595435","rc":[{"batb":[[1,1.01,7],[2,1.01,0]],"ltp":3.5,"tv":244.35,"id":9634224}]}]}
{"op":"mcm","clk":"4230805415","pt":1631536809071,"mc":[{"id":"1.187595435","rc":[{"batl":[[0,1.3,255.54],[1,1.44,255.54],[2,1.44,0]],"ltp":1.18,"tv":24250.21,"id":11252269}]}]}
{"op":"mcm","clk":"4230805750","pt":1631536812184,"mc":[{"id":"1.187595435","rc":[{"batl":[[1,1.44,0]],"ltp":1.18,"tv":24250.21,"id":11252269}]}]}
{"op":"mcm","clk":"4230805966","pt":1631536814582,"mc":[{"id":"1.187595435","rc":[{"batb":[[1,3.3,379.13],[2,1.01,7]],"batl":[[0,13.5,64.69]],"ltp":3.5,"tv":244.35,"id":9634224},{"batl":[[0,1.2,255.54]],"ltp":1.18,"tv":24250.21,"id":11252269}]}]}
{"op":"mcm","clk":"4230806264","pt":1631536818183,"mc":[{"id":"1.187595435","rc":[{"batb":[[1,1.01,7],[2,1.01,0]],"ltp":3.5,"tv":244.35,"id":9634224}]}]}
{"op":"mcm","clk":"4230807971","pt":1631536836592,"mc":[{"id":"1.187595435","rc":[{"batl":[[0,1.09,2.89],[1,1.2,255.54]],"ltp":1.18,"tv":24250.21,"id":11252269}]}]}
{"op":"mcm","clk":"4230808371","pt":1631536841090,"mc":[{"id":"1.187595435","rc":[{"batb":[[0,1.01,7],[1,1.01,0]],"ltp":3.5,"tv":244.35,"id":9634224},{"batb":[[0,1.06,255.54],[1,1.05,255.54],[2,1.04,511.07]],"ltp":1.18,"tv":24250.21,"id":11252269}]}]}
{"op":"mcm","clk":"4230808564","pt":1631536843220,"mc":[{"id":"1.187595435","rc":[{"batl":[[1,1.2,0]],"ltp":1.18,"tv":24250.21,"id":11252269}]}]}
{"op":"mcm","clk":"4230808620","pt":1631536843800,"mc":[{"id":"1.187595435","rc":[{"batl":[[0,1.08,88.43],[1,1.09,2.89]],"ltp":1.18,"tv":24250.21,"id":11252269}]}]}
{"op":"mcm","clk":"4230808718","pt":1631536844891,"mc":[{"id":"1.187595435","rc":[{"batl":[[1,1.09,0]],"ltp":1.18,"tv":24250.21,"id":11252269}]}]}
{"op":"mcm","clk":"4230808831","pt":1631536845996,"mc":[{"id":"1.187595435","rc":[{"batb":[[0,4.3,10],[1,1.01,7]],"ltp":3.5,"tv":244.35,"id":9634224}]}]}
{"op":"mcm","clk":"4230808939","pt":1631536847397,"mc":[{"id":"1.187595435","rc":[{"batb":[[0,1.16,255.54],[1,1.06,255.54],[2,1.05,255.54]],"ltp":1.18,"tv":24250.21,"id":11252269}]}]}
{"op":"mcm","clk":"4230808984","pt":1631536847916,"mc":[{"id":"1.187595435","rc":[{"batb":[[1,2.84,381.81],[2,1.01,7]],"batl":[[0,8.2,86.22]],"ltp":3.5,"tv":244.35,"id":9634224}]}]}
{"op":"mcm","clk":"4230809112","pt":1631536849431,"mc":[{"id":"1.187595435","rc":[{"batl":[[1,13.5,85.8]],"ltp":3.5,"tv":244.35,"id":9634224},{"batb":[[0,1.17,255.54],[1,1.16,255.54],[2,1.06,255.54]],"ltp":1.18,"tv":24250.21,"id":11252269}]}]}
{"op":"mcm","clk":"4230809244","pt":1631536850629,"mc":[{"id":"1.187595435","rc":[{"batl":[[0,6,4.78],[1,8.2,86.22]],"ltp":3.5,"tv":244.35,"id":9634224},{"batb":[[2,1.08,221.47]],"batl":[[0,1.3,255.54]],"ltp":1.18,"tv":24250.21,"id":11252269}]}]}
{"op":"mcm","clk":"4230809317","pt":1631536851512,"mc":[{"id":"1.187595435","rc":[{"batb":[[2,1.08,138.42]],"ltp":1.18,"tv":24250.21,"id":11252269}]}]}
{"op":"mcm","clk":"4230809420","pt":1631536852506,"mc":[{"id":"1.187595435","rc":[{"batb":[[0,1.18,166.66],[1,1.17,255.54],[2,1.16,255.54]],"ltp":1.18,"tv":24250.21,"id":11252269}]}]}
{"op":"mcm","clk":"4230809612","pt":1631536854735,"mc":[{"id":"1.187595435","rc":[{"batl":[[0,8.2,86.22],[1,8.2,0]],"ltp":3.5,"tv":244.35,"id":9634224}]}]}
{"op":"mcm","clk":"4230810062","pt":1631536859822,"mc":[{"id":"1.187595435","rc":[{"batl":[[1,13.5,4.78]],"ltp":3.5,"tv":244.35,"id":9634224}]}]}
{"op":"mcm","clk":"4230811653","pt":1631536870145,"mc":[{"id":"1.187595435","rc":[{"trd":[[1.18,230.02]],"batb":[[0,1.17,255.54],[1,1.16,255.54],[2,1.07,255.54]],"ltp":1.18,"tv":24427.06,"id":11252269}],"tv":24671.42}]}
{"op":"mcm","clk":"4230811854","pt":1631536872124,"mc":[{"id":"1.187595435","rc":[{"batb":[[1,1.01,7],[2,1.01,0]],"batl":[[0,13.5,4.78],[1,13.5,0]],"ltp":3.5,"tv":244.35,"id":9634224},{"batb":[[0,1.28,2.17],[1,1.17,255.54],[2,1.16,255.54]],"ltp":1.18,"tv":24427.06,"id":11252269}]}]}
{"op":"mcm","clk":"4230811916","pt":1631536872750,"mc":[{"id":"1.187595435","rc":[{"batb":[[2,1.07,255.54]],"ltp":1.18,"tv":24427.06,"id":11252269}]}]}
{"op":"mcm","clk":"4230812126","pt":1631536875152,"mc":[{"id":"1.187595435","rc":[{"batb":[[2,1.11,272.72]],"ltp":1.18,"tv":24427.06,"id":11252269}]}]}
{"op":"mcm","clk":"4230812317","pt":1631536877348,"mc":[{"id":"1.187595435","rc":[{"batb":[[0,1.17,255.54],[1,1.11,272.72],[2,1.07,255.54]],"ltp":1.18,"tv":24427.06,"id":11252269}]}]}
{"op":"mcm","clk":"4230812505","pt":1631536879273,"mc":[{"id":"1.187595435","rc":[{"batb":[[0,1.01,7],[1,1.01,0]],"ltp":3.5,"tv":244.35,"id":9634224},{"batb":[[1,1.07,255.54],[2,1.06,255.54]],"ltp":1.18,"tv":24427.06,"id":11252269}]}]}
{"op":"mcm","clk":"4230813010","pt":1631536884280,"mc":[{"id":"1.187595435","rc":[{"batb":[[0,4,10],[1,1.01,7]],"ltp":3.5,"tv":244.35,"id":9634224},{"batb":[[0,1.2,150],[1,1.17,255.54],[2,1.07,255.54]],"ltp":1.18,"tv":24427.06,"id":11252269}]}]}
{"op":"mcm","clk":"4230813142","pt":1631536885594,"mc":[{"id":"1.187595435","rc":[{"batb":[[1,2.72,384.74],[2,1.01,7]],"batl":[[0,7.2,92.97],[1,13.5,4.78]],"ltp":3.5,"tv":244.35,"id":9634224}]}]}
{"op":"mcm","clk":"4230813196","pt":1631536886208,"mc":[{"id":"1.187595435","rc":[{"batb":[[1,1.01,7],[2,1.01,0]],"batl":[[0,13.5,4.78],[1,13.5,0]],"ltp":3.5,"tv":244.35,"id":9634224}]}]}
{"op":"mcm","clk":"4230813322","pt":1631536887511,"mc":[{"id":"1.187595435","rc":[{"batl":[[0,1.4,255.54]],"ltp":1.18,"tv":24427.06,"id":11252269}]}]}
{"op":"mcm","clk":"4230813396","pt":1631536888306,"mc":[{"id":"1.187595435","rc":[{"batb":[[0,1.23,255.54],[1,1.2,150],[2,1.17,255.54]],"ltp":1.18,"tv":24427.06,"id":11252269}]}]}
{"op":"mcm","clk":"4230813504","pt":1631536889395,"mc":[{"id":"1.187595435","rc":[{"batb":[[2,1.07,255.54]],"ltp":1.18,"tv":24427.06,"id":11252269}]}]}
{"op":"mcm","clk":"4230813792","pt":1631536892215,"mc":[{"id":"1.187595435","rc":[{"batb":[[0,1.01,7],[1,1.01,0]],"ltp":3.5,"tv":244.35,"id":9634224},{"batb":[[1,1.07,255.54],[2,1.06,255.54]],"ltp":1.18,"tv":24427.06,"id":11252269}]}]}
{"op":"mcm","clk":"4230814275","pt":1631536897129,"mc":[{"id":"1.187595435","rc":[{"batb":[[0,3,15],[1,1.01,7]],"ltp":3.5,"tv":244.35,"id":9634224},{"batb":[[0,1.34,88.23],[1,1.23,255.54],[2,1.07,255.54]],"ltp":1.18,"tv":24427.06,"id":11252269}]}]}
{"op":"mcm","clk":"4230814437","pt":1631536898935,"mc":[{"id":"1.187595435","rc":[{"batb":[[0,3.05,13.24],[1,3,15],[2,1.01,7]],"ltp":3.5,"tv":244.35,"id":9634224}]}]}
{"op":"mcm","clk":"4230814538","pt":1631536899926,"mc":[{"id":"1.187595435","rc":[{"batb":[[2,2.38,389.01]],"batl":[[0,5.3,119.78],[1,13.5,4.78]],"ltp":3.5,"tv":244.35,"id":9634224},{"batb":[[0,1.36,255.54],[1,1.34,88.23],[2,1.23,255.54]],"ltp":1.18,"tv":24427.06,"id":11252269}]}]}
{"op":"mcm","clk":"4230814644","pt":1631536901015,"mc":[{"id":"1.187595435","rc":[{"batl":[[0,1.53,255.54]],"ltp":1.18,"tv":24427.06,"id":11252269}]}]}
{"op":"mcm","clk":"4230814734","pt":1631536901898,"mc":[{"id":"1.187595435","rc":[{"batb":[[0,3,15],[1,2.38,389.01],[2,1.01,7]],"ltp":3.5,"tv":244.35,"id":9634224}]}]}
{"op":"mcm","clk":"4230817191","pt":1631536926739,"mc":[{"id":"1.187595435","rc":[{"batb":[[0,2.38,389.01],[1,1.01,7],[2,1.01,0]],"ltp":3.5,"tv":244.35,"id":9634224},{"batb":[[1,1.23,255.54],[2,1.07,255.54]],"ltp":1.18,"tv":24427.06,"id":11252269}]}]}
{"op":"mcm","clk":"4230817340","pt":1631536928461,"mc":[{"id":"1.187595435","rc":[{"batb":[[0,1.01,7],[1,1.01,0]],"batl":[[0,13.5,4.78],[1,13.5,0]],"ltp":3.5,"tv":244.35,"id":9634224}]}]}
{"op":"mcm","clk":"4230817580","pt":1631536930767,"mc":[{"id":"1.187595435","rc":[{"batb":[[0,2.4,19.42],[1,1.01,7]],"ltp":3.5,"tv":244.35,"id":9634224}]}]}
{"op":"mcm","clk":"4230817665","pt":1631536931660,"mc":[{"id":"1.187595435","rc":[{"batb":[[1,2.34,22.38],[2,1.01,7]],"ltp":3.5,"tv":244.35,"id":9634224}]}]}
{"op":"mcm","clk":"4230817953","pt":1631536934169,"mc":[{"id":"1.187595435","rc":[{"batb":[[0,2.34,22.38],[1,2.04,401.22]],"batl":[[0,3.9,159.57],[1,13.5,4.78]],"ltp":3.5,"tv":244.35,"id":9634224},{"batb":[[0,1.55,54.54],[1,1.43,255.54],[2,1.23,255.54]],"ltp":1.18,"tv":24427.06,"id":11252269}]}]}
{"op":"mcm","clk":"4230817998","pt":1631536934652,"mc":[{"id":"1.187595435","rc":[{"batb":[[1,1.46,255.54],[2,1.43,255.54]],"ltp":1.18,"tv":24427.06,"id":11252269}]}]}
{"op":"mcm","clk":"4230818118","pt":1631536935962,"mc":[{"id":"1.187595435","rc":[{"batl":[[0,1.7,255.54]],"ltp":1.18,"tv":24427.06,"id":11252269}]}]}
{"op":"mcm","clk":"4230818492","pt":1631536939864,"mc":[{"id":"1.187595435","rc":[{"batb":[[1,1.5,255.54],[2,1.46,255.54]],"ltp":1.18,"tv":24427.06,"id":11252269}]}]}
{"op":"mcm","clk":"4230820308","pt":1631536959208,"mc":[{"id":"1.187595435","rc":[{"batb":[[0,2.04,401.22],[1,1.01,7],[2,1.01,0]],"batl":[[1,13.5,0]],"ltp":3.5,"tv":244.35,"id":9634224},{"batb":[[0,1.5,255.54],[1,1.46,255.54],[2,1.43,255.54]],"ltp":1.18,"tv":24427.06,"id":11252269}]}]}
{"op":"mcm","clk":"4230820539","pt":1631536961508,"mc":[{"id":"1.187595435","rc":[{"batb":[[0,1.01,7],[1,1.01,0]],"ltp":3.5,"tv":244.35,"id":9634224},{"batb":[[0,1.46,255.54],[1,1.43,255.54],[2,1.23,255.54]],"ltp":1.18,"tv":24427.06,"id":11252269}]}]}
{"op":"mcm","clk":"4230820703","pt":1631536963188,"mc":[{"id":"1.187595435","rc":[{"batb":[[0,1.23,255.54],[1,1.07,255.54],[2,1.06,255.54]],"ltp":1.18,"tv":24427.06,"id":11252269}]}]}
{"op":"mcm","clk":"4230820779","pt":1631536964079,"mc":[{"id":"1.187595435","rc":[{"batb":[[0,2.84,16.3],[1,1.01,7]],"ltp":3.5,"tv":244.35,"id":9634224},{"batb":[[0,1.38,78.94],[1,1.23,255.54],[2,1.07,255.54]],"ltp":1.18,"tv":24427.06,"id":11252269}]}]}
{"op":"mcm","clk":"4230821099","pt":1631536967516,"mc":[{"id":"1.187595435","rc":[{"batb":[[1,2.3,391.9],[2,1.01,7]],"batl":[[0,4.9,127.33]],"ltp":3.5,"tv":244.35,"id":9634224}]}]}
{"op":"mcm","clk":"4230821266","pt":1631536969306,"mc":[{"id":"1.187595435","rc":[{"batl":[[0,1.53,255.54],[1,1.7,255.54]],"ltp":1.18,"tv":24427.06,"id":11252269}]}]}
{"op":"mcm","clk":"4230821361","pt":1631536970388,"mc":[{"id":"1.187595435","rc":[{"batb":[[1,1.35,255.54],[2,1.23,255.54]],"ltp":1.18,"tv":24427.06,"id":11252269}]}]}
{"op":"mcm","clk":"4230823147","pt":1631536990168,"mc":[{"id":"1.187595435","rc":[{"batl":[[1,1.7,0]],"ltp":1.18,"tv":24427.06,"id":11252269}]}]}
{"op":"mcm","clk":"4230823213","pt":1631536991006,"mc":[{"id":"1.187595435","rc":[{"batb":[[1,1.01,7],[2,1.01,0]],"ltp":3.5,"tv":244.35,"id":9634224}]}]}
{"op":"mcm","clk":"4230823661","pt":1631536996375,"mc":[{"id":"1.187595435","rc":[{"batb":[[0,1.01,7],[1,1.01,0]],"ltp":3.5,"tv":244.35,"id":9634224},{"batb":[[0,1.35,255.54],[1,1.23,255.54],[2,1.07,255.54]],"ltp":1.18,"tv":24427.06,"id":11252269}]}]}
{"op":"mcm","clk":"4230823790","pt":1631536997793,"mc":[{"id":"1.187595435","rc":[{"batb":[[0,1.23,255.54],[1,1.07,255.54],[2,1.06,255.54]],"ltp":1.18,"tv":24427.06,"id":11252269}]}]}
{"op":"mcm","clk":"4230824046","pt":1631537000473,"mc":[{"id":"1.187595435","rc":[{"batb":[[0,1.07,255.54],[1,1.06,255.54],[2,1.05,255.54]],"ltp":1.18,"tv":24427.06,"id":11252269}]}]}
{"op":"mcm","clk":"4230824121","pt":1631537001267,"mc":[{"id":"1.187595435","rc":[{"batb":[[0,4.1,10],[1,1.01,7]],"ltp":3.5,"tv":244.35,"id":9634224},{"batb":[[0,1.18,166.66],[1,1.07,255.54],[2,1.06,255.54]],"ltp":1.18,"tv":24427.06,"id":11252269}]}]}
{"op":"mcm","clk":"4230824334","pt":1631537003386,"mc":[{"id":"1.187595435","rc":[{"batb":[[1,2.84,381.81],[2,1.01,7]],"batl":[[0,8.2,86.22]],"ltp":3.5,"tv":244.35,"id":9634224},{"batl":[[0,1.35,255.54],[1,1.53,255.54]],"ltp":1.18,"tv":24427.06,"id":11252269}]}]}
{"op":"mcm","clk":"4230824418","pt":1631537004291,"mc":[{"id":"1.187595435","rc":[{"batl":[[0,1.3,255.54],[1,1.35,255.54]],"ltp":1.18,"tv":24427.06,"id":11252269}]}]}
{"op":"mcm","clk":"4230824568","pt":1631537005874,"mc":[{"id":"1.187595435","rc":[{"batb":[[1,1.17,255.54],[2,1.07,255.54]],"ltp":1.18,"tv":24427.06,"id":11252269}]}]}
{"op":"mcm","clk":"4230825294","pt":1631537014389,"mc":[{"id":"1.187595435","rc":[{"batb":[[1,1.01,7],[2,1.01,0]],"ltp":3.5,"tv":244.35,"id":9634224}]}]}
{"op":"mcm","clk":"4230825662","pt":1631537018896,"mc":[{"id":"1.187595435","rc":[{"batl":[[1,1.35,0]],"ltp":1.18,"tv":24427.06,"id":11252269}]}]}
{"op":"mcm","clk":"4230829724","pt":1631537064474,"mc":[{"id":"1.187595435","rc":[{"trd":[[1.3,26.59]],"batl":[[0,1.3,242.24]],"ltp":1.3,"tv":24453.65,"id":11252269}],"tv":24698.0}]}
{"op":"mcm","clk":"4230829854","pt":1631537065741,"mc":[{"id":"1.187595435","rc":[{"batb":[[0,1.01,7],[1,1.01,0]],"ltp":3.5,"tv":244.35,"id":9634224},{"batb":[[0,1.17,255.54],[1,1.07,255.54],[2,1.06,255.54]],"ltp":1.3,"tv":24453.65,"id":11252269}]}]}
{"op":"mcm","clk":"4230830198","pt":1631537069463,"mc":[{"id":"1.187595435","rc":[{"batb":[[0,1.07,255.54],[1,1.06,255.54],[2,1.05,255.54]],"ltp":1.3,"tv":24453.65,"id":11252269}]}]}
{"op":"mcm","clk":"4230830323","pt":1631537070678,"mc":[{"id":"1.187595435","rc":[{"batb":[[0,3.95,10.16],[1,1.01,7]],"ltp":3.5,"tv":244.35,"id":9634224},{"batb":[[0,1.2,150],[1,1.07,255.54],[2,1.06,255.54]],"ltp":1.3,"tv":24453.65,"id":11252269}]}]}
{"op":"mcm","clk":"4230830574","pt":1631537073153,"mc":[{"id":"1.187595435","rc":[{"batb":[[0,1.25,13.82],[1,1.2,150],[2,1.07,255.54]],"ltp":1.3,"tv":24453.65,"id":11252269}]}]}
{"op":"mcm","clk":"4230831220","pt":1631537080397,"mc":[{"id":"1.187595435","rc":[{"batb":[[0,1.01,7],[1,1.01,0]],"ltp":3.5,"tv":244.35,"id":9634224},{"batb":[[1,1.07,255.54],[2,1.06,255.54]],"ltp":1.3,"tv":24453.65,"id":11252269}]}]}
{"op":"mcm","clk":"4230831272","pt":1631537080977,"mc":[{"id":"1.187595435","rc":[{"batb":[[0,1.07,255.54],[1,1.06,255.54],[2,1.05,255.54]],"ltp":1.3,"tv":24453.65,"id":11252269}]}]}
{"op":"mcm","clk":"4230831567","pt":1631537084181,"mc":[{"id":"1.187595435","rc":[{"batb":[[0,1.06,255.54],[1,1.05,255.54],[2,1.03,255.54]],"ltp":1.3,"tv":24453.65,"id":11252269}]}]}
{"op":"mcm","clk":"4230831698","pt":1631537085589,"mc":[{"id":"1.187595435","rc":[{"batb":[[0,7.6,10],[1,1.01,7]],"ltp":3.5,"tv":244.35,"id":9634224},{"batb":[[1,1.05,855.53]],"batl":[[0,1.16,255.54],[1,1.2,255.54],[2,1.3,242.24]],"ltp":1.3,"tv":24453.65,"id":11252269}]}]}
{"op":"mcm","clk":"4230831822","pt":1631537087094,"mc":[{"id":"1.187595435","rc":[{"batb":[[1,1.05,599.99]],"ltp":1.3,"tv":24453.65,"id":11252269}]}]}
{"op":"mcm","clk":"4230831903","pt":1631537088091,"mc":[{"id":"1.187595435","rc":[{"batb":[[2,1.01,7]],"ltp":1.3,"tv":24453.65,"id":11252269}]}]}
{"op":"mcm","clk":"4230832157","pt":1631537091490,"mc":[{"id":"1.187595435","rc":[{"batl":[[2,1.3,0]],"ltp":1.3,"tv":24453.65,"id":11252269}]}]}
{"op":"mcm","clk":"4230832220","pt":1631537092273,"mc":[{"id":"1.187595435","rc":[{"batl":[[1,1.2,0]],"ltp":1.3,"tv":24453.65,"id":11252269}]}]}
{"op":"mcm","clk":"4230832717","pt":1631537098359,"mc":[{"id":"1.187595435","rc":[{"batl":[[0,1.14,255.54],[1,1.16,255.54]],"ltp":1.3,"tv":24453.65,"id":11252269}]}]}
{"op":"mcm","clk":"4230832899","pt":1631537100514,"mc":[{"id":"1.187595435","rc":[{"trd":[[1.06,514.37]],"batb":[[0,1.05,599.99],[1,1.01,7],[2,1.01,0]],"batl":[[0,1.06,244.51],[1,1.14,255.54],[2,1.16,255.54]],"ltp":1.06,"tv":24964.68,"id":11252269}],"tv":25209.03}]}
{"op":"mcm","clk":"4230833123","pt":1631537102711,"mc":[{"id":"1.187595435","rc":[{"trd":[[1.06,567.53]],"batl":[[0,1.06,217.92]],"ltp":1.06,"tv":25017.84,"id":11252269}],"tv":25262.2}]}
{"op":"mcm","clk":"4230833325","pt":1631537104614,"mc":[{"id":"1.187595435","rc":[{"batl":[[2,1.16,0]],"ltp":1.06,"tv":25017.84,"id":11252269}]}]}
{"op":"mcm","clk":"4230833383","pt":1631537105075,"mc":[{"id":"1.187595435","rc":[{"batl":[[1,1.07,2.89]],"ltp":1.06,"tv":25017.84,"id":11252269}]}]}
{"op":"mcm","clk":"4230833451","pt":1631537105721,"mc":[{"id":"1.187595435","rc":[{"trd":[[1.06,1003.37]],"batl":[[0,1.07,2.89],[1,1.07,0]],"ltp":1.06,"tv":25453.68,"id":11252269}],"tv":25698.04}]}
{"op":"mcm","clk":"4230833761","pt":1631537108718,"mc":[{"id":"1.187595435","rc":[{"batl":[[0,1.06,239.23]],"ltp":1.06,"tv":25453.68,"id":11252269}]}]}
{"op":"mcm","clk":"4230834040","pt":1631537111400,"mc":[{"id":"1.187595435","rc":[{"batb":[[0,1.01,7],[1,1.01,0]],"ltp":3.5,"tv":244.35,"id":9634224},{"batb":[[0,1.01,7],[1,1.01,0]],"ltp":1.06,"tv":25453.68,"id":11252269}]}]}
{"op":"mcm","clk":"4230834544","pt":1631537116406,"mc":[{"id":"1.187595435","rc":[{"batb":[[0,8,10],[1,1.01,7]],"ltp":3.5,"tv":244.35,"id":9634224},{"batb":[[0,1.04,749.99],[1,1.01,7]],"ltp":1.06,"tv":25453.68,"id":11252269}]}]}
{"op":"mcm","clk":"4230834864","pt":1631537119912,"mc":[{"id":"1.187595435","rc":[{"batl":[[0,17.5,2.66]],"ltp":3.5,"tv":244.35,"id":9634224}]}]}
{"op":"mcm","clk":"4230835183","pt":1631537123418,"mc":[{"id":"1.187595435","rc":[{"trd":[[17.5,2.86]],"ltp":17.5,"tv":247.01,"id":9634224},{"trd":[[1.04,399.81],[1.06,1047.28]],"batb":[[0,1.04,550.1]],"ltp":1.04,"tv":25897.41,"id":11252269}],"tv":26144.42}]}
{"op":"mcm","clk":"4230835204","pt":1631537123719,"mc":[{"id":"1.187595435","rc":[{"batb":[[0,1.01,7],[1,1.01,0]],"ltp":1.04,"tv":25897.41,"id":11252269}]}]}
{"op":"mcm","clk":"4230835692","pt":1631537128632,"mc":[{"id":"1.187595435","rc":[{"batb":[[0,1.04,749.99],[1,1.01,7]],"ltp":1.04,"tv":25897.41,"id":11252269}]}]}
{"op":"mcm","clk":"4230835884","pt":1631537130725,"mc":[{"id":"1.187595435","rc":[{"batb":[[0,1.01,7],[1,1.01,0]],"ltp":17.5,"tv":247.01,"id":9634224},{"batb":[[0,1.01,7],[1,1.01,0]],"ltp":1.04,"tv":25897.41,"id":11252269}]}]}
{"op":"mcm","clk":"4230836333","pt":1631537135658,"mc":[{"id":"1.187595435","rc":[{"batb":[[0,4.1,10],[1,1.01,7]],"ltp":17.5,"tv":247.01,"id":9634224},{"batb":[[0,1.18,166.66],[1,1.01,7]],"ltp":1.04,"tv":25897.41,"id":11252269}]}]}
{"op":"mcm","clk":"4230836484","pt":1631537137222,"mc":[{"id":"1.187595435","rc":[{"batb":[[1,1.11,425.89],[2,1.01,7]],"ltp":1.04,"tv":25897.41,"id":11252269}]}]}
{"op":"mcm","clk":"4230836674","pt":1631537139161,"mc":[{"id":"1.187595435","rc":[{"batb":[[1,1.16,425.89],[2,1.15,425.89]],"ltp":1.04,"tv":25897.41,"id":11252269}]}]}
{"op":"mcm","clk":"4230836909","pt":1631537141140,"mc":[{"id":"1.187595435","rc":[{"batl":[[0,1.3,425.89]],"ltp":1.04,"tv":25897.41,"id":11252269}]}]}
{"op":"mcm","clk":"4230837006","pt":1631537142136,"mc":[{"id":"1.187595435","rc":[{"trd":[[6.6,2]],"ltp":6.6,"tv":249.01,"id":9634224},{"trd":[[1.18,241.21]],"batb":[[0,1.16,425.89],[1,1.15,425.89],[2,1.11,425.89]],"ltp":1.18,"tv":25908.6,"id":11252269}],"tv":26157.61}]}
{"op":"mcm","clk":"4230837262","pt":1631537144579,"mc":[{"id":"1.187595435","rc":[{"batb":[[1,1.11,425.89],[2,1.01,7]],"ltp":1.18,"tv":25908.6,"id":11252269}]}]}
{"op":"mcm","clk":"4230837360","pt":1631537145469,"mc":[{"id":"1.187595435","rc":[{"batb":[[1,1.01,7],[2,1.01,0]],"ltp":1.18,"tv":25908.6,"id":11252269}]}]}
{"op":"mcm","clk":"4230837541","pt":1631537147057,"mc":[{"id":"1.187595435","rc":[{"batb":[[0,1.18,166.66],[1,1.16,425.89],[2,1.01,7]],"ltp":1.18,"tv":25908.6,"id":11252269}]}]}
{"op":"mcm","clk":"4230839661","pt":1631537170304,"mc":[{"id":"1.187595435","rc":[{"batb":[[0,1.01,7],[1,1.01,0]],"ltp":6.6,"tv":249.01,"id":9634224},{"batb":[[0,1.16,425.89],[1,1.01,7],[2,1.01,0]],"ltp":1.18,"tv":25908.6,"id":11252269}]}]}
{"op":"mcm","clk":"4230840137","pt":1631537175507,"mc":[{"id":"1.187595435","rc":[{"batb":[[0,2.84,16.3],[1,1.01,7]],"ltp":6.6,"tv":249.01,"id":9634224},{"batb":[[0,1.31,425.89],[1,1.16,425.89],[2,1.01,7]],"ltp":1.18,"tv":25908.6,"id":11252269}]}]}
{"op":"mcm","clk":"4230840234","pt":1631537176494,"mc":[{"id":"1.187595435","rc":[{"batb":[[1,2.3,391.9],[2,1.01,7]],"batl":[[0,4.9,127.33]],"ltp":6.6,"tv":249.01,"id":9634224},{"batb":[[0,1.38,78.94],[1,1.31,425.89],[2,1.16,425.89]],"ltp":1.18,"tv":25908.6,"id":11252269}]}]}
{"op":"mcm","clk":"4230840302","pt":1631537177321,"mc":[{"id":"1.187595435","rc":[{"batb":[[1,1.37,425.89],[2,1.31,425.89]],"ltp":1.18,"tv":25908.6,"id":11252269}]}]}
{"op":"mcm","clk":"4230840498","pt":1631537179499,"mc":[{"id":"1.187595435","rc":[{"batb":[[2,1.16,425.89]],"batl":[[0,1.56,425.89]],"ltp":1.18,"tv":25908.6,"id":11252269}]}]}
{"op":"mcm","clk":"4230842736","pt":1631537205248,"mc":[{"id":"1.187595435","rc":[{"trd":[[3.65,31.89]],"ltp":3.65,"tv":275.59,"id":9634224},{"trd":[[1.38,84.41]],"batb":[[0,1.38,8.6]],"ltp":1.38,"tv":25978.94,"id":11252269}],"tv":26254.53}]}
{"op":"mcm","clk":"4230842772","pt":1631537205666,"mc":[{"id":"1.187595435","rc":[{"batb":[[0,1.37,425.89],[1,1.16,425.89],[2,1.01,7]],"ltp":1.38,"tv":25978.94,"id":11252269}]}]}
{"op":"mcm","clk":"4230843246","pt":1631537210584,"mc":[{"id":"1.187595435","rc":[{"batb":[[1,1.31,96.77],[2,1.16,425.89]],"ltp":1.38,"tv":25978.94,"id":11252269}]}]}
{"op":"mcm","clk":"4230843326","pt":1631537211552,"mc":[{"id":"1.187595435","rc":[{"batb":[[0,2.3,391.9],[1,1.01,7],[2,1.01,0]],"ltp":3.65,"tv":275.59,"id":9634224},{"batb":[[1,1.16,425.89],[2,1.01,7]],"ltp":1.38,"tv":25978.94,"id":11252269}]}]}
{"op":"mcm","clk":"4230843411","pt":1631537212533,"mc":[{"id":"1.187595435","rc":[{"batb":[[0,1.01,7],[1,1.01,0]],"ltp":3.65,"tv":275.59,"id":9634224}]}]}
{"op":"mcm","clk":"4230843769","pt":1631537216474,"mc":[{"id":"1.187595435","rc":[{"batb":[[0,2,30],[1,1.01,7]],"ltp":3.65,"tv":275.59,"id":9634224}]}]}
{"op":"mcm","clk":"4230843802","pt":1631537216858,"mc":[{"id":"1.187595435","rc":[{"batb":[[0,1.5,425.89],[1,1.37,425.89],[2,1.16,425.89]],"ltp":1.38,"tv":25978.94,"id":11252269}]}]}
{"op":"mcm","clk":"4230843928","pt":1631537218153,"mc":[{"id":"1.187595435","rc":[{"batb":[[1,1.82,408.65],[2,1.01,7]],"batl":[[0,3.15,202.13]],"ltp":3.65,"tv":275.59,"id":9634224},{"batb":[[0,1.73,41.09],[1,1.5,425.89],[2,1.37,425.89]],"ltp":1.38,"tv":25978.94,"id":11252269}]}]}
{"op":"mcm","clk":"4230844306","pt":1631537222055,"mc":[{"id":"1.187595435","rc":[{"trd":[[2,5.78]],"batb":[[0,1.82,408.65],[1,1.01,7],[2,1.01,0]],"ltp":2.0,"tv":281.37,"id":9634224},{"batb":[[1,1.5,851.79]],"ltp":1.38,"tv":25978.94,"id":11252269}],"tv":26260.31}]}
{"op":"mcm","clk":"4230844738","pt":1631537226388,"mc":[{"id":"1.187595435","rc":[{"batl":[[0,1.93,425.89]],"ltp":1.38,"tv":25978.94,"id":11252269}]}]}
{"op":"mcm","clk":"4230844839","pt":1631537227490,"mc":[{"id":"1.187595435","rc":[{"batb":[[0,2,30],[1,1.82,408.65],[2,1.01,7]],"ltp":2.0,"tv":281.37,"id":9634224},{"batb":[[1,1.37,425.89],[2,1.16,425.89]],"ltp":1.38,"tv":25978.94,"id":11252269}]}]}
{"op":"mcm","clk":"4230845036","pt":1631537229470,"mc":[{"id":"1.187595435","rc":[{"batl":[[0,1.87,255.54],[1,1.93,425.89]],"ltp":1.38,"tv":25978.94,"id":11252269}]}]}
{"op":"mcm","clk":"4230845060","pt":1631537229682,"mc":[{"id":"1.187595435","rc":[{"batb":[[1,1.16,425.89],[2,1.01,7]],"ltp":1.38,"tv":25978.94,"id":11252269}]}]}
{"op":"mcm","clk":"4230845161","pt":1631537230867,"mc":[{"id":"1.187595435","rc":[{"batb":[[1,1.01,7],[2,1.01,0]],"ltp":1.38,"tv":25978.94,"id":11252269}]}]}
{"op":"mcm","clk":"4230845433","pt":1631537233376,"mc":[{"id":"1.187595435","rc":[{"trd":[[1.73,6.68]],"batb":[[0,1.73,37.75]],"ltp":1.73,"tv":25985.62,"id":11252269}],"tv":26266.99}]}
{"op":"mcm","clk":"4230845475","pt":1631537233692,"mc":[{"id":"1.187595435","rc":[{"batb":[[0,1.01,7],[1,1.01,0]],"ltp":1.73,"tv":25985.62,"id":11252269}]}]}
{"op":"mcm","clk":"4230846065","pt":1631537238709,"mc":[{"id":"1.187595435","rc":[{"batb":[[0,1.73,41.09],[1,1.01,7]],"ltp":1.73,"tv":25985.62,"id":11252269}]}]}
{"op":"mcm","clk":"4230846394","pt":1631537241696,"mc":[{"id":"1.187595435","rc":[{"batb":[[1,1.61,255.54],[2,1.01,7]],"ltp":1.73,"tv":25985.62,"id":11252269}]}]}
{"op":"mcm","clk":"4230857399","pt":1631537274573,"mc":[{"id":"1.187595435","rc":[{"batb":[[0,1.75,38.94],[1,1.73,41.09],[2,1.61,255.54]],"ltp":1.73,"tv":25985.62,"id":11252269}]}]}
{"op":"mcm","clk":"4230858737","pt":1631537287557,"mc":[{"id":"1.187595435","rc":[{"batb":[[0,1.73,41.09],[1,1.61,255.54],[2,1.01,7]],"ltp":1.73,"tv":25985.62,"id":11252269}]}]}
{"op":"mcm","clk":"4230859448","pt":1631537294889,"mc":[{"id":"1.187595435","rc":[{"trd":[[1.87,72.89]],"batl":[[0,1.87,219.09],[1,1.93,0]],"ltp":1.87,"tv":26058.51,"id":11252269}],"tv":26339.88}]}
{"op":"mcm","clk":"4230860264","pt":1631537303581,"mc":[{"id":"1.187595435","rc":[{"batb":[[0,1.8,38.36],[1,1.73,41.09],[2,1.61,255.54]],"ltp":1.87,"tv":26058.51,"id":11252269}]}]}
{"op":"mcm","clk":"4230860428","pt":1631537305188,"mc":[{"id":"1.187595435","rc":[{"batb":[[1,1.76,39.22],[2,1.73,41.09]],"ltp":1.87,"tv":26058.51,"id":11252269}]}]}
{"op":"mcm","clk":"4230860556","pt":1631537306387,"mc":[{"id":"1.187595435","rc":[{"batb":[[1,1.73,41.09],[2,1.01,7]],"ltp":1.87,"tv":26058.51,"id":11252269}]}]}
{"op":"mcm","clk":"4230860751","pt":1631537308501,"mc":[{"id":"1.187595435","rc":[{"batb":[[2,1.64,255.54]],"ltp":1.87,"tv":26058.51,"id":11252269}]}]}
{"op":"mcm","clk":"4230862533","pt":1631537327801,"mc":[{"id":"1.187595435","rc":[{"batl":[[0,1.97,255.54]],"ltp":1.87,"tv":26058.51,"id":11252269}]}]}
{"op":"mcm","clk":"4230871834","pt":1631537426230,"mc":[{"id":"1.187595435","rc":[{"batb":[[0,1.73,41.09],[1,1.64,255.54],[2,1.01,7]],"ltp":1.87,"tv":26058.51,"id":11252269}]}]}
{"op":"mcm","clk":"4230872206","pt":1631537430159,"mc":[{"id":"1.187595435","rc":[{"batb":[[0,1.84,37.52],[1,1.73,41.09],[2,1.64,255.54]],"ltp":1.87,"tv":26058.51,"id":11252269}]}]}
{"op":"mcm","clk":"4230885164","pt":1631537568065,"mc":[{"id":"1.187595435","rc":[{"batl":[[0,1.93,36.44],[1,1.97,255.54]],"ltp":1.87,"tv":26058.51,"id":11252269}]}]}
{"op":"mcm","clk":"4230885369","pt":1631537570658,"mc":[{"id":"1.187595435","rc":[{"batb":[[0,1.82,408.65],[1,1.01,7],[2,1.01,0]],"ltp":2.0,"tv":281.37,"id":9634224},{"batb":[[1,1.64,255.54],[2,1.01,7]],"ltp":1.87,"tv":26058.51,"id":11252269}]}]}
{"op":"mcm","clk":"4230885524","pt":1631537572571,"mc":[{"id":"1.187595435","rc":[{"batl":[[0,1.97,255.54],[1,1.97,0]],"ltp":1.87,"tv":26058.51,"id":11252269}]}]}
{"op":"mcm","clk":"4230885746","pt":1631537575576,"mc":[{"id":"1.187595435","rc":[{"batb":[[0,2.1,27.27],[1,1.82,408.65],[2,1.01,7]],"ltp":2.0,"tv":281.37,"id":9634224},{"batb":[[1,1.65,46.15],[2,1.64,255.54]],"ltp":1.87,"tv":26058.51,"id":11252269}]}]}
{"op":"mcm","clk":"4230886044","pt":1631537579362,"mc":[{"id":"1.187595435","rc":[{"batb":[[0,1.65,46.15],[1,1.64,255.54],[2,1.01,7]],"ltp":1.87,"tv":26058.51,"id":11252269}]}]}
{"op":"mcm","clk":"4230887482","pt":1631537597393,"mc":[{"id":"1.187595435","rc":[{"batb":[[0,1.82,408.65],[1,1.01,7],[2,1.01,0]],"ltp":2.0,"tv":281.37,"id":9634224},{"batb":[[0,1.64,255.54],[1,1.01,7],[2,1.01,0]],"ltp":1.87,"tv":26058.51,"id":11252269}]}]}
{"op":"mcm","clk":"4230887564","pt":1631537598486,"mc":[{"id":"1.187595435","rc":[{"batb":[[0,1.01,7],[1,1.01,0]],"ltp":2.0,"tv":281.37,"id":9634224},{"batb":[[0,1.01,7],[1,1.01,0]],"ltp":1.87,"tv":26058.51,"id":11252269}]}]}
{"op":"mcm","clk":"4230887866","pt":1631537602291,"mc":[{"id":"1.187595435","rc":[{"batb":[[0,2.58,18.98],[1,1.01,7]],"ltp":2.0,"tv":281.37,"id":9634224},{"batb":[[0,1.45,66.66],[1,1.01,7]],"ltp":1.87,"tv":26058.51,"id":11252269}]}]}
{"op":"mcm","clk":"4230887903","pt":1631537602810,"mc":[{"id":"1.187595435","rc":[{"batl":[[0,1.64,255.54],[1,1.97,255.54]],"ltp":1.87,"tv":26058.51,"id":11252269}]}]}
{"op":"mcm","clk":"4230888039","pt":1631537604310,"mc":[{"id":"1.187595435","rc":[{"batb":[[1,2.12,395.62],[2,1.01,7]],"batl":[[0,4.2,149.26]],"ltp":2.0,"tv":281.37,"id":9634224}]}]}
{"op":"mcm","clk":"4230888511","pt":1631537610381,"mc":[{"id":"1.187595435","rc":[{"batl":[[0,1.61,36.44],[1,1.64,255.54],[2,1.97,255.54]],"ltp":1.87,"tv":26058.51,"id":11252269}]}]}
{"op":"mcm","clk":"4230888783","pt":1631537613300,"mc":[{"id":"1.187595435","rc":[{"batb":[[0,1.46,72.88],[1,1.45,66.66],[2,1.01,7]],"ltp":1.87,"tv":26058.51,"id":11252269}]}]}
{"op":"mcm","clk":"4230889427","pt":1631537621204,"mc":[{"id":"1.187595435","rc":[{"batl":[[0,1.6,255.54],[1,1.61,36.44],[2,1.64,255.54]],"ltp":1.87,"tv":26058.51,"id":11252269}]}]}
{"op":"mcm","clk":"4230889539","pt":1631537622404,"mc":[{"id":"1.187595435","rc":[{"batb":[[0,1.52,45.42],[1,1.46,72.88],[2,1.45,66.66]],"ltp":1.87,"tv":26058.51,"id":11252269}]}]}
{"op":"mcm","clk":"4230889682","pt":1631537624120,"mc":[{"id":"1.187595435","rc":[{"batb":[[1,1.45,66.66],[2,1.01,7]],"batl":[[1,1.64,255.54],[2,1.97,255.54]],"ltp":1.87,"tv":26058.51,"id":11252269}]}]}
{"op":"mcm","clk":"4230891583","pt":1631537645119,"mc":[{"id":"1.187595435","rc":[{"batb":[[0,2.12,395.62],[1,1.01,7],[2,1.01,0]],"ltp":2.0,"tv":281.37,"id":9634224},{"batb":[[1,1.01,7],[2,1.01,0]],"ltp":1.87,"tv":26058.51,"id":11252269}]}]}
{"op":"mcm","clk":"4230891688","pt":1631537646158,"mc":[{"id":"1.187595435","rc":[{"batb":[[0,1.01,7],[1,1.01,0]],"ltp":2.0,"tv":281.37,"id":9634224},{"batb":[[0,1.01,7],[1,1.01,0]],"ltp":1.87,"tv":26058.51,"id":11252269}]}]}
{"op":"mcm","clk":"4230892045","pt":1631537650173,"mc":[{"id":"1.187595435","rc":[{"batb":[[0,3.3,13.04],[1,1.01,7]],"ltp":2.0,"tv":281.37,"id":9634224},{"batb":[[0,1.28,107.14],[1,1.01,7]],"ltp":1.87,"tv":26058.51,"id":11252269}]}]}
{"op":"mcm","clk":"4230892201","pt":1631537651737,"mc":[{"id":"1.187595435","rc":[{"batb":[[1,2.52,388.09],[2,1.01,7]],"batl":[[0,6,107.07]],"ltp":2.0,"tv":281.37,"id":9634224}]}]}
{"op":"mcm","clk":"4230893528","pt":1631537665976,"mc":[{"id":"1.187595435","rc":[{"batl":[[0,1.4,36.44],[1,1.6,255.54],[2,1.64,255.54]],"ltp":1.87,"tv":26058.51,"id":11252269}]}]}
{"op":"mcm","clk":"4230894856","pt":1631537680573,"mc":[{"id":"1.187595435","rc":[{"batb":[[0,1.01,7],[1,2.52,0],[2,1.01,0]],"ltp":2.0,"tv":281.37,"id":9634224},{"batb":[[0,1.01,7],[1,1.01,0]],"ltp":1.87,"tv":26058.51,"id":11252269}]}]}
{"op":"mcm","clk":"4230894917","pt":1631537681302,"mc":[{"id":"1.187595435","rc":[{"batl":[[0,1.6,255.54],[1,1.64,255.54],[2,1.97,255.54]],"ltp":1.87,"tv":26058.51,"id":11252269}]}]}
{"op":"mcm","clk":"4230895271","pt":1631537685308,"mc":[{"id":"1.187595435","rc":[{"batb":[[0,2.5,20],[1,1.01,7]],"ltp":2.0,"tv":281.37,"id":9634224},{"batl":[[0,1.64,255.54],[1,1.97,255.54],[2,1.97,0]],"ltp":1.87,"tv":26058.51,"id":11252269}]}]}
{"op":"mcm","clk":"4230895423","pt":1631537686614,"mc":[{"id":"1.187595435","rc":[{"batl":[[0,4.2,149.26]],"ltp":2.0,"tv":281.37,"id":9634224},{"batb":[[0,1.48,62.5],[1,1.01,7]],"batl":[[0,1.97,255.54],[1,1.97,0]],"ltp":1.87,"tv":26058.51,"id":11252269}]}]}
{"op":"mcm","clk":"4230895465","pt":1631537686979,"mc":[{"id":"1.187595435","rc":[{"batb":[[1,2.12,395.62],[2,1.01,7]],"ltp":2.0,"tv":281.37,"id":9634224}]}]}
{"op":"mcm","clk":"4230895705","pt":1631537689473,"mc":[{"id":"1.187595435","rc":[{"batb":[[1,1.47,46.96],[2,1.01,7]],"ltp":1.87,"tv":26058.51,"id":11252269}]}]}
{"op":"mcm","clk":"4230895887","pt":1631537691406,"mc":[{"id":"1.187595435","rc":[{"batl":[[0,1.59,36.44],[1,1.97,255.54]],"ltp":1.87,"tv":26058.51,"id":11252269}]}]}
{"op":"mcm","clk":"4230895989","pt":1631537692399,"mc":[{"id":"1.187595435","rc":[{"trd":[[1.59,72.89]],"batb":[[0,1.59,6.97],[1,1.48,62.5],[2,1.47,46.96]],"batl":[[0,1.97,255.54],[1,1.97,0]],"ltp":1.59,"tv":26131.4,"id":11252269}],"tv":26412.77}]}
{"op":"mcm","clk":"4230897874","pt":1631537711907,"mc":[{"id":"1.187595435","rc":[{"batb":[[0,1.01,7],[1,2.12,0],[2,1.01,0]],"ltp":2.0,"tv":281.37,"id":9634224},{"batb":[[1,1.47,46.96],[2,1.01,7]],"ltp":1.59,"tv":26131.4,"id":11252269}]}]}
{"op":"mcm","clk":"4230897971","pt":1631537712850,"mc":[{"id":"1.187595435","rc":[{"batb":[[1,1.01,7],[2,1.01,0]],"ltp":1.59,"tv":26131.4,"id":11252269}]}]}
{"op":"mcm","clk":"4230898154","pt":1631537714735,"mc":[{"id":"1.187595435","rc":[{"batb":[[0,1.01,7],[1,1.01,0]],"ltp":1.59,"tv":26131.4,"id":11252269}]}]}
{"op":"mcm","clk":"4230898440","pt":1631537717409,"mc":[{"id":"1.187595435","rc":[{"batb":[[0,3.3,13.04],[1,2.52,388.09],[2,1.01,7]],"batl":[[0,6,107.07]],"ltp":2.0,"tv":281.37,"id":9634224},{"batb":[[0,1.28,107.14],[1,1.01,7]],"ltp":1.59,"tv":26131.4,"id":11252269}]}]}
{"op":"mcm","clk":"4230898582","pt":1631537718816,"mc":[{"id":"1.187595435","rc":[{"batl":[[0,1.4,255.54]],"ltp":1.59,"tv":26131.4,"id":11252269}]}]}
{"op":"mcm","clk":"4230898745","pt":1631537720536,"mc":[{"id":"1.187595435","rc":[{"batb":[[1,2.7,50.99],[2,2.52,388.09]],"ltp":2.0,"tv":281.37,"id":9634224},{"batl":[[1,1.59,327.45]],"ltp":1.59,"tv":26131.4,"id":11252269}]}]}
{"op":"mcm","clk":"4230898815","pt":1631537721217,"mc":[{"id":"1.187595435","rc":[{"batb":[[1,2.52,388.09],[2,1.01,7]],"ltp":2.0,"tv":281.37,"id":9634224},{"batl":[[1,1.59,13.8]],"ltp":1.59,"tv":26131.4,"id":11252269}]}]}
{"op":"mcm","clk":"4230898887","pt":1631537721949,"mc":[{"id":"1.187595435","rc":[{"batl":[[1,1.59,0]],"ltp":1.59,"tv":26131.4,"id":11252269}]}]}
{"op":"mcm","clk":"4230899561","pt":1631537728930,"mc":[{"id":"1.187595435","rc":[{"batl":[[0,5,57.94],[1,6,107.07]],"ltp":2.0,"tv":281.37,"id":9634224}]}]}
{"op":"mcm","clk":"4230899936","pt":1631537732815,"mc":[{"id":"1.187595435","rc":[{"batb":[[1,1.25,255.54],[2,1.01,7]],"ltp":1.59,"tv":26131.4,"id":11252269}]}]}
{"op":"mcm","clk":"4230900116","pt":1631537734954,"mc":[{"id":"1.187595435","rc":[{"batl":[[0,1.46,255.54]],"ltp":1.59,"tv":26131.4,"id":11252269}]}]}
{"op":"mcm","clk":"4230900830","pt":1631537742260,"mc":[{"id":"1.187595435","rc":[{"batl":[[0,6,107.07],[1,6,0]],"ltp":2.0,"tv":281.37,"id":9634224}]}]}
{"op":"mcm","clk":"4230903884","pt":1631537775411,"mc":[{"id":"1.187595435","rc":[{"batb":[[0,1.01,7],[1,2.52,0],[2,1.01,0]],"batl":[[0,3.75,57.94]],"ltp":2.0,"tv":281.37,"id":9634224},{"batb":[[0,1.25,255.54],[1,1.01,7],[2,1.01,0]],"ltp":1.59,"tv":26131.4,"id":11252269}]}]}
{"op":"mcm","clk":"4230904351","pt":1631537780296,"mc":[{"id":"1.187595435","rc":[{"batb":[[0,2.66,18.07],[1,1.01,7]],"ltp":2.0,"tv":281.37,"id":9634224},{"batb":[[0,1.42,71.42],[1,1.25,255.54],[2,1.01,7]],"ltp":1.59,"tv":26131.4,"id":11252269}]}]}
{"op":"mcm","clk":"4230904442","pt":1631537781287,"mc":[{"id":"1.187595435","rc":[{"batb":[[1,2.22,391.36],[2,1.01,7]],"batl":[[1,4.6,137.18]],"ltp":2.0,"tv":281.37,"id":9634224}]}]}
{"op":"mcm","clk":"4230904573","pt":1631537782596,"mc":[{"id":"1.187595435","rc":[{"batb":[[1,1.37,255.54],[2,1.25,255.54]],"ltp":1.59,"tv":26131.4,"id":11252269}]}]}
{"op":"mcm","clk":"4230904679","pt":1631537783689,"mc":[{"id":"1.187595435","rc":[{"batl":[[0,1.59,255.54]],"ltp":1.59,"tv":26131.4,"id":11252269}]}]}
{"op":"mcm","clk":"4230906938","pt":1631537809329,"mc":[{"id":"1.187595435","rc":[{"batb":[[0,2.22,391.36],[1,1.01,7],[2,1.01,0]],"ltp":2.0,"tv":281.37,"id":9634224},{"batb":[[0,1.37,255.54],[1,1.25,255.54],[2,1.01,7]],"ltp":1.59,"tv":26131.4,"id":11252269}]}]}
{"op":"mcm","clk":"4230907048","pt":1631537810581,"mc":[{"id":"1.187595435","rc":[{"batb":[[0,1.01,7],[1,1.01,0]],"ltp":2.0,"tv":281.37,"id":9634224},{"batb":[[0,1.25,255.54],[1,1.01,7],[2,1.01,0]],"ltp":1.59,"tv":26131.4,"id":11252269}]}]}
{"op":"mcm","clk":"4230907362","pt":1631537814286,"mc":[{"id":"1.187595435","rc":[{"batb":[[0,3.4,12.5],[1,1.01,7]],"ltp":2.0,"tv":281.37,"id":9634224},{"batb":[[0,1.27,111.11],[1,1.25,255.54],[2,1.01,7]],"batl":[[0,1.4,255.54],[1,1.59,255.54]],"ltp":1.59,"tv":26131.4,"id":11252269}]}]}
{"op":"mcm","clk":"4230907598","pt":1631537816682,"mc":[{"id":"1.187595435","rc":[{"batb":[[1,2.62,385.81],[2,1.01,7]],"batl":[[0,6.6,99.8]],"ltp":2.0,"tv":281.37,"id":9634224}]}]}
{"op":"mcm","clk":"4230908002","pt":1631537820529,"mc":[{"id":"1.187595435","rc":[{"batl":[[0,5.5,57.94],[1,6.6,99.8]],"ltp":2.0,"tv":281.37,"id":9634224}]}]}
{"op":"mcm","clk":"4230908486","pt":1631537825511,"mc":[{"id":"1.187595435","rc":[{"trd":[[3.5,24.61]],"ltp":3.5,"tv":292.0,"id":9634224},{"trd":[[1.4,61.56]],"batl":[[0,1.4,228.94]],"ltp":1.4,"tv":26158.0,"id":11252269}],"tv":26450.0}]}
{"op":"mcm","clk":"4230909893","pt":1631537841245,"mc":[{"id":"1.187595435","rc":[{"batl":[[0,6.6,99.8],[1,6.6,0]],"ltp":3.5,"tv":292.0,"id":9634224}]}]}
{"op":"mcm","clk":"4230911873","pt":1631537864654,"mc":[{"id":"1.187595435","rc":[{"batb":[[1,1.01,7],[2,1.01,0]],"ltp":1.4,"tv":26158.0,"id":11252269}]}]}
{"op":"mcm","clk":"4230912217","pt":1631537868670,"mc":[{"id":"1.187595435","rc":[{"batb":[[0,1.34,36.06],[1,1.27,111.11],[2,1.01,7]],"ltp":1.4,"tv":26158.0,"id":11252269}]}]}
{"op":"mcm","clk":"4230913031","pt":1631537878475,"mc":[{"id":"1.187595435","rc":[{"batb":[[0,1.01,7],[1,2.62,0],[2,1.01,0]],"ltp":3.5,"tv":292.0,"id":9634224},{"batb":[[0,1.01,7],[1,1.27,0],[2,1.01,0]],"ltp":1.4,"tv":26158.0,"id":11252269}]}]}
{"op":"mcm","clk":"4230913243","pt":1631537881161,"mc":[{"id":"1.187595435","rc":[{"batl":[[1,1.59,0]],"ltp":1.4,"tv":26158.0,"id":11252269}]}]}
{"op":"mcm","clk":"4230913394","pt":1631537882783,"mc":[{"id":"1.187595435","rc":[{"batb":[[0,5.3,10],[1,1.01,7]],"ltp":3.5,"tv":292.0,"id":9634224},{"batb":[[0,1.12,249.99],[1,1.01,7]],"ltp":1.4,"tv":26158.0,"id":11252269}]}]}
{"op":"mcm","clk":"4230913544","pt":1631537884373,"mc":[{"id":"1.187595435","rc":[{"batb":[[1,3.1,380.06],[2,1.01,7]],"batl":[[0,10.5,72.99]],"ltp":3.5,"tv":292.0,"id":9634224},{"batl":[[0,1.27,255.54],[1,1.4,228.94]],"ltp":1.4,"tv":26158.0,"id":11252269}]}]}
{"op":"mcm","clk":"4230913737","pt":1631537886493,"mc":[{"id":"1.187595435","rc":[{"batl":[[1,1.4,0]],"ltp":1.4,"tv":26158.0,"id":11252269}]}]}
{"op":"mcm","clk":"4230914049","pt":1631537890167,"mc":[{"id":"1.187595435","rc":[{"batl":[[0,1.23,255.54]],"ltp":1.4,"tv":26158.0,"id":11252269}]}]}
{"op":"mcm","clk":"4230915239","pt":1631537902772,"mc":[{"id":"1.187595435","rc":[{"batb":[[0,1.13,255.54],[1,1.12,249.99],[2,1.01,7]],"ltp":1.4,"tv":26158.0,"id":11252269}]}]}
{"op":"mcm","clk":"4230915429","pt":1631537904814,"mc":[{"id":"1.187595435","rc":[{"batb":[[1,1.01,7],[2,1.01,0]],"ltp":3.5,"tv":292.0,"id":9634224}]}]}
{"op":"mcm","clk":"4230915960","pt":1631537910826,"mc":[{"id":"1.187595435","rc":[{"batb":[[0,1.01,7],[1,1.01,0]],"ltp":3.5,"tv":292.0,"id":9634224},{"batb":[[1,1.01,7],[2,1.01,0]],"ltp":1.4,"tv":26158.0,"id":11252269}]}]}
{"op":"mcm","clk":"4230916383","pt":1631537915712,"mc":[{"id":"1.187595435","rc":[{"batb":[[0,3.7,11.11],[1,1.01,7]],"ltp":3.5,"tv":292.0,"id":9634224}]}]}
{"op":"mcm","clk":"4230916490","pt":1631537917226,"mc":[{"id":"1.187595435","rc":[{"batb":[[1,2.62,385.81],[2,1.01,7]],"batl":[[0,6.6,99.8]],"ltp":3.5,"tv":292.0,"id":9634224},{"batb":[[0,1.23,130.43],[1,1.13,255.54],[2,1.01,7]],"ltp":1.4,"tv":26158.0,"id":11252269}]}]}
{"op":"mcm","clk":"4230916580","pt":1631537918127,"mc":[{"id":"1.187595435","rc":[{"batl":[[0,5.3,5.32],[1,6.6,99.8]],"ltp":3.5,"tv":292.0,"id":9634224},{"batb":[[0,1.23,169.71]],"ltp":1.4,"tv":26158.0,"id":11252269}]}]}
{"op":"mcm","clk":"4230916700","pt":1631537919322,"mc":[{"id":"1.187595435","rc":[{"trd":[[1.23,6]],"batb":[[0,1.23,39.28]],"batl":[[0,1.46,255.54]],"ltp":1.23,"tv":26164.0,"id":11252269}],"tv":26456.0}]}
{"op":"mcm","clk":"4230917134","pt":1631537924244,"mc":[{"id":"1.187595435","rc":[{"batl":[[1,5.5,57.94],[2,6.6,99.8]],"ltp":3.5,"tv":292.0,"id":9634224},{"batb":[[0,1.23,169.71]],"ltp":1.23,"tv":26164.0,"id":11252269}]}]}
{"op":"mcm","clk":"4230917989","pt":1631537934221,"mc":[{"id":"1.187595435","rc":[{"batb":[[1,1.01,7],[2,1.01,0]],"batl":[[2,6.6,0]],"ltp":3.5,"tv":292.0,"id":9634224}]}]}
{"op":"mcm","clk":"4230918092","pt":1631537935327,"mc":[{"id":"1.187595435","rc":[{"batl":[[1,5.5,0]],"ltp":3.5,"tv":292.0,"id":9634224}]}]}
{"op":"mcm","clk":"4230918561","pt":1631537941425,"mc":[{"id":"1.187595435","rc":[{"batb":[[0,1.23,130.43]],"ltp":1.23,"tv":26164.0,"id":11252269}]}]}
{"op":"mcm","clk":"4230918625","pt":1631537942162,"mc":[{"id":"1.187595435","rc":[{"batb":[[1,1.01,7],[2,1.01,0]],"ltp":1.23,"tv":26164.0,"id":11252269}]}]}
{"op":"mcm","clk":"4230918916","pt":1631537945560,"mc":[{"id":"1.187595435","rc":[{"batb":[[0,1.31,36.89],[1,1.23,130.43],[2,1.01,7]],"ltp":1.23,"tv":26164.0,"id":11252269}]}]}
{"op":"mcm","clk":"4230919304","pt":1631537950074,"mc":[{"id":"1.187595435","rc":[{"batb":[[0,1.01,7],[1,1.01,0]],"ltp":3.5,"tv":292.0,"id":9634224},{"batb":[[1,1.01,7],[2,1.01,0]],"ltp":1.23,"tv":26164.0,"id":11252269}]}]}
{"op":"mcm","clk":"4230919797","pt":1631537955156,"mc":[{"id":"1.187595435","rc":[{"batb":[[0,2.84,16.3],[1,1.01,7]],"ltp":3.5,"tv":292.0,"id":9634224},{"batb":[[0,1.43,33.79],[1,1.38,78.94],[2,1.31,36.89]],"ltp":1.23,"tv":26164.0,"id":11252269}]}]}
{"op":"mcm","clk":"4230919863","pt":1631537955887,"mc":[{"id":"1.187595435","rc":[{"batb":[[1,2.22,391.36],[2,1.01,7]],"batl":[[0,4.6,137.18],[1,5.3,5.32]],"ltp":3.5,"tv":292.0,"id":9634224}]}]}
{"op":"mcm","clk":"4230919970","pt":1631537957186,"mc":[{"id":"1.187595435","rc":[{"batl":[[0,3.7,57.94],[1,4.6,137.18],[2,5.3,5.32]],"ltp":3.5,"tv":292.0,"id":9634224}]}]}
{"op":"mcm","clk":"4230920224","pt":1631537959567,"mc":[{"id":"1.187595435","rc":[{"batb":[[2,1.01,7]],"ltp":1.23,"tv":26164.0,"id":11252269}]}]}
{"op":"mcm","clk":"4230920417","pt":1631537961560,"mc":[{"id":"1.187595435","rc":[{"batl":[[0,4.6,137.18],[1,5.3,5.32],[2,5.3,0]],"ltp":3.5,"tv":292.0,"id":9634224}]}]}
{"op":"mcm","clk":"4230920603","pt":1631537963567,"mc":[{"id":"1.187595435","rc":[{"batb":[[0,1.5,32.21],[1,1.43,33.79],[2,1.38,78.94]],"ltp":1.23,"tv":26164.0,"id":11252269}]}]}
{"op":"mcm","clk":"4230920776","pt":1631537965770,"mc":[{"id":"1.187595435","rc":[{"batb":[[1,1.38,78.94],[2,1.01,7]],"ltp":1.23,"tv":26164.0,"id":11252269}]}]}
{"op":"mcm","clk":"4230920898","pt":1631537967484,"mc":[{"id":"1.187595435","rc":[{"batl":[[0,1.6,255.54]],"ltp":1.23,"tv":26164.0,"id":11252269}]}]}
{"op":"mcm","clk":"4230922704","pt":1631537991508,"mc":[{"id":"1.187595435","rc":[{"batb":[[0,1.01,7],[1,2.22,0],[2,1.01,0]],"batl":[[0,5.3,5.32],[1,5.3,0]],"ltp":3.5,"tv":292.0,"id":9634224},{"batb":[[1,1.01,7],[2,1.01,0]],"ltp":1.23,"tv":26164.0,"id":11252269}]}]}
{"op":"mcm","clk":"4230922856","pt":1631537993329,"mc":[{"id":"1.187595435","rc":[{"trd":[[1.5,8.52]],"batb":[[0,1.5,27.96]],"ltp":1.5,"tv":26172.51,"id":11252269}],"tv":26464.52}]}
{"op":"mcm","clk":"4230923061","pt":1631537995729,"mc":[{"id":"1.187595435","rc":[{"batb":[[0,1.98,30.61],[1,1.01,7]],"ltp":3.5,"tv":292.0,"id":9634224}]}]}
{"op":"mcm","clk":"4230923225","pt":1631537997518,"mc":[{"id":"1.187595435","rc":[{"batb":[[1,1.77,409.74],[2,1.01,7]],"batl":[[0,3,215.29],[1,5.3,5.32]],"ltp":3.5,"tv":292.0,"id":9634224},{"batb":[[0,1.78,38.46],[1,1.64,29.46],[2,1.5,27.96]],"ltp":1.5,"tv":26172.51,"id":11252269}]}]}
{"op":"mcm","clk":"4230923277","pt":1631537998288,"mc":[{"id":"1.187595435","rc":[{"batb":[[1,1.71,255.54],[2,1.69,255.54]],"ltp":1.5,"tv":26172.51,"id":11252269}]}]}
{"op":"mcm","clk":"4230923479","pt":1631538000508,"mc":[{"id":"1.187595435","rc":[{"batb":[[2,1.5,27.96]],"ltp":1.5,"tv":26172.51,"id":11252269}]}]}
{"op":"mcm","clk":"4230923503","pt":1631538000722,"mc":[{"id":"1.187595435","rc":[{"batl":[[0,2.5,57.94],[1,3,215.29],[2,5.3,5.32]],"ltp":3.5,"tv":292.0,"id":9634224}]}]}
{"op":"mcm","clk":"4230923616","pt":1631538001759,"mc":[{"id":"1.187595435","rc":[{"batl":[[0,1.96,255.54]],"ltp":1.5,"tv":26172.51,"id":11252269}]}]}
{"op":"mcm","clk":"4230923728","pt":1631538002817,"mc":[{"id":"1.187595435","rc":[{"batb":[[2,1.01,7]],"ltp":1.5,"tv":26172.51,"id":11252269}]}]}
{"op":"mcm","clk":"4230924117","pt":1631538006335,"mc":[{"id":"1.187595435","rc":[{"trd":[[2,5.78],[2.72,2.79],[2.84,197.55],[3.5,24.64],[3.65,31.94],[5.3,9.58],[7.6,9.58],[9.2,5.32],[17.5,2.87]],"batb":[[1,1.77,409.67]],"batl":[[1,3,215.25],[2,5.3,5.32]],"ltp":3.5,"tv":292.22,"id":9634224},{"trd":[[1.04,399.78],[1.05,3.61],[1.06,1047.27],[1.1,2890.64],[1.11,10.12],[1.12,47.53],[1.13,2890.64],[1.18,241.23],[1.19,2886.81],[1.21,2890.64],[1.25,2890.64],[1.3,26.6],[1.35,1012.26],[1.39,2890.64],[1.4,61.55],[1.43,2890.64],[1.5,8.52],[1.54,2720.38],[1.59,72.88],[1.73,6.68],[1.87,72.88]],"batb":[[0,1.8,23.29],[1,1.78,38.46],[2,1.71,255.49]],"batl":[[0,1.96,255.49]],"ltp":1.5,"tv":26163.8,"id":11252269}],"tv":26456.03}]}
{"op":"mcm","clk":"4230924761","pt":1631538013470,"mc":[{"id":"1.187595435","rc":[{"batb":[[1,1.01,7],[2,1.01,0]],"batl":[[1,5.3,5.32],[2,5.3,0]],"ltp":3.5,"tv":292.22,"id":9634224}]}]}
{"op":"mcm","clk":"4230924961","pt":1631538015917,"mc":[{"id":"1.187595435","rc":[{"batb":[[0,1.01,7],[1,1.01,0]],"ltp":3.5,"tv":292.22,"id":9634224},{"batb":[[1,1.71,255.49],[2,1.01,7]],"ltp":1.5,"tv":26163.8,"id":11252269}]}]}
{"op":"mcm","clk":"4230925373","pt":1631538020892,"mc":[{"id":"1.187595435","rc":[{"batb":[[0,1.88,34.09],[1,1.01,7]],"ltp":3.5,"tv":292.22,"id":9634224},{"batb":[[0,1.85,35.29],[1,1.8,23.29],[2,1.71,255.49]],"ltp":1.5,"tv":26163.8,"id":11252269}]}]}
{"op":"mcm","clk":"4230925455","pt":1631538021827,"mc":[{"id":"1.187595435","rc":[{"batb":[[1,1.7,416.91],[2,1.01,7]],"batl":[[1,2.82,233.26],[2,5.3,5.32]],"ltp":3.5,"tv":292.22,"id":9634224}]}]}
{"op":"mcm","clk":"4230925555","pt":1631538023229,"mc":[{"id":"1.187595435","rc":[{"batl":[[0,2.82,233.26],[1,5.3,5.32],[2,5.3,0]],"ltp":3.5,"tv":292.22,"id":9634224}]}]}
{"op":"mcm","clk":"4230925610","pt":1631538024008,"mc":[{"id":"1.187595435","rc":[{"batl":[[0,2.18,255.49]],"ltp":1.5,"tv":26163.8,"id":11252269}]}]}
{"op":"mcm","clk":"4230925729","pt":1631538025596,"mc":[{"id":"1.187595435","rc":[{"batb":[[1,1.01,7],[2,1.01,0]],"batl":[[0,5.3,5.32],[1,5.3,0]],"ltp":3.5,"tv":292.22,"id":9634224},{"batb":[[0,1.87,255.49],[1,1.85,35.29],[2,1.01,7]],"ltp":1.5,"tv":26163.8,"id":11252269}]}]}
{"op":"mcm","clk":"4230926187","pt":1631538031836,"mc":[{"id":"1.187595435","rc":[{"batb":[[0,2.02,20.75],[1,1.87,255.49],[2,1.85,35.29]],"ltp":1.5,"tv":26163.8,"id":11252269}]}]}
{"op":"mcm","clk":"4230926839","pt":1631538040109,"mc":[{"id":"1.187595435","rc":[{"batb":[[0,1.01,7],[1,1.01,0]],"ltp":3.5,"tv":292.22,"id":9634224},{"batb":[[2,1.01,7]],"ltp":1.5,"tv":26163.8,"id":11252269}]}]}
{"op":"mcm","clk":"4230926918","pt":1631538040956,"mc":[{"id":"1.187595435","rc":[{"batb":[[1,1.01,7],[2,1.01,0]],"ltp":1.5,"tv":26163.8,"id":11252269}]}]}
{"op":"mcm","clk":"4230927015","pt":1631538041936,"mc":[{"id":"1.187595435","rc":[{"batb":[[0,1.01,7],[1,1.01,0]],"ltp":1.5,"tv":26163.8,"id":11252269}]}]}
{"op":"mcm","clk":"4230927285","pt":1631538045109,"mc":[{"id":"1.187595435","rc":[{"batb":[[0,2.66,18.07],[1,1.01,7]],"ltp":3.5,"tv":292.22,"id":9634224},{"batb":[[0,1.42,71.42],[1,1.01,7]],"ltp":1.5,"tv":26163.8,"id":11252269}]}]}
{"op":"mcm","clk":"4230927399","pt":1631538046260,"mc":[{"id":"1.187595435","rc":[{"batb":[[1,2.12,395.55],[2,1.01,7]],"batl":[[0,4.2,149.23],[1,5.3,5.32]],"ltp":3.5,"tv":292.22,"id":9634224}]}]}
{"op":"mcm","clk":"4230927525","pt":1631538047821,"mc":[{"id":"1.187595435","rc":[{"batl":[[0,1.85,255.49],[1,2.18,255.49]],"ltp":1.5,"tv":26163.8,"id":11252269}]}]}
{"op":"mcm","clk":"4230927713","pt":1631538050119,"mc":[{"id":"1.187595435","rc":[{"batl":[[1,2.18,0]],"ltp":1.5,"tv":26163.8,"id":11252269}]}]}
{"op":"mcm","clk":"4230927871","pt":1631538052150,"mc":[{"id":"1.187595435","rc":[{"batb":[[0,1.42,326.91]],"ltp":1.5,"tv":26163.8,"id":11252269}]}]}
{"op":"mcm","clk":"4230928193","pt":1631538056056,"mc":[{"id":"1.187595435","rc":[{"batl":[[0,1.7,255.49],[1,1.85,255.49]],"ltp":1.5,"tv":26163.8,"id":11252269}]}]}
{"op":"mcm","clk":"4230928257","pt":1631538056835,"mc":[{"id":"1.187595435","rc":[{"batl":[[0,1.7,510.99]],"ltp":1.5,"tv":26163.8,"id":11252269}]}]}
{"op":"mcm","clk":"4230928518","pt":1631538059968,"mc":[{"id":"1.187595435","rc":[{"batb":[[0,1.52,27.58],[1,1.42,326.91],[2,1.01,7]],"ltp":1.5,"tv":26163.8,"id":11252269}]}]}
{"op":"mcm","clk":"4230928932","pt":1631538064159,"mc":[{"id":"1.187595435","rc":[{"batl":[[0,3.35,36.44],[1,4.2,149.23],[2,5.3,5.32]],"ltp":3.5,"tv":292.22,"id":9634224}]}]}
{"op":"mcm","clk":"4230929895","pt":1631538075275,"mc":[{"id":"1.187595435","rc":[{"batl":[[1,1.85,0]],"ltp":1.5,"tv":26163.8,"id":11252269}]}]}
{"op":"mcm","clk":"4230930222","pt":1631538079288,"mc":[{"id":"1.187595435","rc":[{"batb":[[1,1.01,7],[2,1.01,0]],"batl":[[1,5.3,5.32],[2,5.3,0]],"ltp":3.5,"tv":292.22,"id":9634224}]}]}
{"op":"mcm","clk":"4230930326","pt":1631538080495,"mc":[{"id":"1.187595435","rc":[{"batl":[[0,5.3,5.32],[1,5.3,0]],"ltp":3.5,"tv":292.22,"id":9634224}]}]}
{"op":"mcm","clk":"4230931842","pt":1631538098790,"mc":[{"id":"1.187595435","rc":[{"batb":[[0,1.01,7],[1,1.01,0]],"ltp":3.5,"tv":292.22,"id":9634224},{"batb":[[1,1.42,255.49]],"ltp":1.5,"tv":26163.8,"id":11252269}]}]}
{"op":"mcm","clk":"4230931943","pt":1631538100231,"mc":[{"id":"1.187595435","rc":[{"batb":[[0,1.01,7],[1,1.42,0],[2,1.01,0]],"ltp":1.5,"tv":26163.8,"id":11252269}]}]}
{"op":"mcm","clk":"4230932273","pt":1631538103614,"mc":[{"id":"1.187595435","rc":[{"batl":[[0,1.4,255.49],[1,1.7,510.99]],"ltp":1.5,"tv":26163.8,"id":11252269}]}]}
{"op":"mcm","clk":"4230932361","pt":1631538104502,"mc":[{"id":"1.187595435","rc":[{"batb":[[0,4.3,10],[1,2.84,381.75],[2,1.01,7]],"batl":[[1,8.2,86.2]],"ltp":3.5,"tv":292.22,"id":9634224},{"batb":[[0,1.18,166.66],[1,1.01,7]],"ltp":1.5,"tv":26163.8,"id":11252269}]}]}
{"op":"mcm","clk":"4230932522","pt":1631538106326,"mc":[{"id":"1.187595435","rc":[{"batl":[[1,1.52,35.77],[2,1.7,510.99]],"ltp":1.5,"tv":26163.8,"id":11252269}]}]}
{"op":"mcm","clk":"4230932617","pt":1631538107423,"mc":[{"id":"1.187595435","rc":[{"batl":[[2,1.7,0]],"ltp":1.5,"tv":26163.8,"id":11252269}]}]}
{"op":"mcm","clk":"4230932792","pt":1631538109622,"mc":[{"id":"1.187595435","rc":[{"batb":[[1,1.16,255.49],[2,1.01,7]],"ltp":1.5,"tv":26163.8,"id":11252269}]}]}
{"op":"mcm","clk":"4230932840","pt":1631538110245,"mc":[{"id":"1.187595435","rc":[{"batb":[[0,1.18,422.15]],"ltp":1.5,"tv":26163.8,"id":11252269}]}]}
{"op":"mcm","clk":"4230933139","pt":1631538113645,"mc":[{"id":"1.187595435","rc":[{"batl":[[0,1.3,255.49],[1,1.4,255.49],[2,1.52,35.77]],"ltp":1.5,"tv":26163.8,"id":11252269}]}]}
{"op":"mcm","clk":"4230934293","pt":1631538125313,"mc":[{"id":"1.187595435","rc":[{"batb":[[1,1.01,7],[2,1.01,0]],"ltp":1.5,"tv":26163.8,"id":11252269}]}]}
{"op":"mcm","clk":"4230934547","pt":1631538127879,"mc":[{"id":"1.187595435","rc":[{"batl":[[2,1.52,0]],"ltp":1.5,"tv":26163.8,"id":11252269}]}]}
{"op":"mcm","clk":"4230935032","pt":1631538133203,"mc":[{"id":"1.187595435","rc":[{"trd":[[5.3,14.9]],"batl":[[0,8.2,86.2],[1,8.2,0]],"ltp":5.3,"tv":297.55,"id":9634224},{"trd":[[1.18,266.9],[1.23,28.93]],"batb":[[0,1.18,255.49]],"ltp":1.18,"tv":26212.4,"id":11252269}],"tv":26509.96}]}
{"op":"mcm","clk":"4230935111","pt":1631538134195,"mc":[{"id":"1.187595435","rc":[{"batl":[[1,1.4,0]],"ltp":1.18,"tv":26212.4,"id":11252269}]}]}
{"op":"mcm","clk":"4230935260","pt":1631538135822,"mc":[{"id":"1.187595435","rc":[{"batb":[[0,1.25,33.55],[1,1.18,255.49],[2,1.01,7]],"ltp":1.18,"tv":26212.4,"id":11252269}]}]}
{"op":"mcm","clk":"4230935462","pt":1631538138181,"mc":[{"id":"1.187595435","rc":[{"batb":[[1,1.18,422.15]],"ltp":1.18,"tv":26212.4,"id":11252269}]}]}
{"op":"mcm","clk":"4230937825","pt":1631538163554,"mc":[{"id":"1.187595435","rc":[{"batb":[[1,1.01,7],[2,1.01,0]],"ltp":5.3,"tv":297.55,"id":9634224}]}]}
{"op":"mcm","clk":"4230938979","pt":1631538177286,"mc":[{"id":"1.187595435","rc":[{"batb":[[0,1.01,7],[1,1.01,0]],"ltp":5.3,"tv":297.55,"id":9634224},{"batb":[[0,1.18,255.49],[1,1.01,7],[2,1.01,0]],"ltp":1.18,"tv":26212.4,"id":11252269}]}]}
{"op":"mcm","clk":"4230939020","pt":1631538177757,"mc":[{"id":"1.187595435","rc":[{"batb":[[0,1.01,7],[1,1.01,0]],"ltp":1.18,"tv":26212.4,"id":11252269}]}]}
{"op":"mcm","clk":"4230939315","pt":1631538181590,"mc":[{"id":"1.187595435","rc":[{"batl":[[0,1.13,255.49],[1,1.3,255.49]],"ltp":1.18,"tv":26212.4,"id":11252269}]}]}
{"op":"mcm","clk":"4230939380","pt":1631538182278,"mc":[{"id":"1.187595435","rc":[{"batb":[[0,8,10],[1,1.01,7]],"ltp":5.3,"tv":297.55,"id":9634224},{"batb":[[0,1.04,749.99],[1,1.01,7]],"ltp":1.18,"tv":26212.4,"id":11252269}]}]}
{"op":"mcm","clk":"4230939479","pt":1631538183279,"mc":[{"id":"1.187595435","rc":[{"batb":[[1,3.7,376.81],[2,1.01,7]],"batl":[[0,23,51.79]],"ltp":5.3,"tv":297.55,"id":9634224},{"batl":[[1,1.3,0]],"ltp":1.18,"tv":26212.4,"id":11252269}]}]}
{"op":"mcm","clk":"4230939709","pt":1631538185993,"mc":[{"id":"1.187595435","rc":[{"batl":[[0,1.13,510.99]],"ltp":1.18,"tv":26212.4,"id":11252269}]}]}
{"op":"mcm","clk":"4230940107","pt":1631538190528,"mc":[{"id":"1.187595435","rc":[{"batb":[[0,1.05,255.49],[1,1.04,1005.48],[2,1.03,255.49]],"ltp":1.18,"tv":26212.4,"id":11252269}]}]}
{"op":"mcm","clk":"4230940484","pt":1631538194482,"mc":[{"id":"1.187595435","rc":[{"batl":[[0,1.13,255.49]],"ltp":1.18,"tv":26212.4,"id":11252269}]}]}
{"op":"mcm","clk":"4230941058","pt":1631538200387,"mc":[{"id":"1.187595435","rc":[{"batb":[[0,1.06,109.32],[1,1.05,255.49],[2,1.04,1005.48]],"ltp":1.18,"tv":26212.4,"id":11252269}]}]}
{"op":"mcm","clk":"4230941503","pt":1631538205139,"mc":[{"id":"1.187595435","rc":[{"batb":[[1,1.01,7],[2,1.01,0]],"ltp":5.3,"tv":297.55,"id":9634224}]}]}
{"op":"mcm","clk":"4230941636","pt":1631538206597,"mc":[{"id":"1.187595435","rc":[{"trd":[[8.6,5.32]],"ltp":8.6,"tv":302.87,"id":9634224},{"trd":[[1.13,2931.15]],"batl":[[0,1.13,214.98]],"ltp":1.13,"tv":26252.92,"id":11252269}],"tv":26555.79}]}
{"op":"mcm","clk":"4230942695","pt":1631538217724,"mc":[{"id":"1.187595435","rc":[{"batb":[[0,1.01,7],[1,1.01,0]],"ltp":8.6,"tv":302.87,"id":9634224},{"batb":[[2,1.04,255.49]],"ltp":1.13,"tv":26252.92,"id":11252269}]}]}
{"op":"mcm","clk":"4230943139","pt":1631538222739,"mc":[{"id":"1.187595435","rc":[{"batb":[[0,5.3,10],[1,1.01,7]],"ltp":8.6,"tv":302.87,"id":9634224},{"batb":[[0,1.12,249.99],[1,1.06,109.32],[2,1.05,255.49]],"ltp":1.13,"tv":26252.92,"id":11252269}]}]}
{"op":"mcm","clk":"4230943267","pt":1631538224143,"mc":[{"id":"1.187595435","rc":[{"batb":[[0,1.15,72.88],[1,1.12,249.99],[2,1.06,109.32]],"ltp":1.13,"tv":26252.92,"id":11252269}]}]}
{"op":"mcm","clk":"4230943364","pt":1631538225132,"mc":[{"id":"1.187595435","rc":[{"batb":[[1,2.98,380.55],[2,1.01,7]],"batl":[[0,9.4,78.73]],"ltp":8.6,"tv":302.87,"id":9634224},{"batb":[[0,1.18,74.33],[1,1.15,109.32],[2,1.12,249.99]],"ltp":1.13,"tv":26252.92,"id":11252269}]}]}
{"op":"mcm","clk":"4230943592","pt":1631538227570,"mc":[{"id":"1.187595435","rc":[{"batb":[[0,1.2,73.09]],"batl":[[0,1.3,255.49]],"ltp":1.13,"tv":26252.92,"id":11252269}]}]}
{"op":"mcm","clk":"4230943895","pt":1631538230556,"mc":[{"id":"1.187595435","rc":[{"batb":[[1,1.15,364.81],[2,1.14,255.49]],"ltp":1.13,"tv":26252.92,"id":11252269}]}]}
{"op":"mcm","clk":"4230944039","pt":1631538231966,"mc":[{"id":"1.187595435","rc":[{"batb":[[2,1.14,328.37]],"ltp":1.13,"tv":26252.92,"id":11252269}]}]}
{"op":"mcm","clk":"4230944508","pt":1631538237345,"mc":[{"id":"1.187595435","rc":[{"batb":[[2,1.14,72.88]],"ltp":1.13,"tv":26252.92,"id":11252269}]}]}
{"op":"mcm","clk":"4230945157","pt":1631538244769,"mc":[{"id":"1.187595435","rc":[{"batb":[[1,1.01,7],[2,1.01,0]],"ltp":8.6,"tv":302.87,"id":9634224}]}]}
{"op":"mcm","clk":"4230945382","pt":1631538247298,"mc":[{"id":"1.187595435","rc":[{"batb":[[1,1.15,255.49],[2,1.12,249.99]],"ltp":1.13,"tv":26252.92,"id":11252269}]}]}
{"op":"mcm","clk":"4230945585","pt":1631538249678,"mc":[{"id":"1.187595435","rc":[{"batb":[[0,1.01,7],[1,1.01,0]],"ltp":8.6,"tv":302.87,"id":9634224},{"batb":[[2,1.05,255.49]],"ltp":1.13,"tv":26252.92,"id":11252269}]}]}
{"op":"mcm","clk":"4230946043","pt":1631538254790,"mc":[{"id":"1.187595435","rc":[{"batb":[[0,4.3,10],[1,2.84,381.75],[2,1.01,7]],"batl":[[0,8.2,86.2]],"ltp":8.6,"tv":302.87,"id":9634224},{"batb":[[1,1.18,166.66],[2,1.15,255.49]],"ltp":1.13,"tv":26252.92,"id":11252269}]}]}
{"op":"mcm","clk":"4230946132","pt":1631538255672,"mc":[{"id":"1.187595435","rc":[{"batb":[[0,1.23,71.31],[1,1.2,73.09],[2,1.18,166.66]],"ltp":1.13,"tv":26252.92,"id":11252269}]}]}
{"op":"mcm","clk":"4230946266","pt":1631538257295,"mc":[{"id":"1.187595435","rc":[{"batl":[[0,1.35,255.49]],"ltp":1.13,"tv":26252.92,"id":11252269}]}]}
{"op":"mcm","clk":"4230946401","pt":1631538258876,"mc":[{"id":"1.187595435","rc":[{"batb":[[1,1.01,7],[2,1.01,0]],"ltp":8.6,"tv":302.87,"id":9634224}]}]}
{"op":"mcm","clk":"4230947069","pt":1631538266692,"mc":[{"id":"1.187595435","rc":[{"batb":[[0,1.01,7],[1,1.01,0]],"ltp":8.6,"tv":302.87,"id":9634224},{"batb":[[2,1.15,255.49]],"ltp":1.13,"tv":26252.92,"id":11252269}]}]}
{"op":"mcm","clk":"4230947147","pt":1631538267683,"mc":[{"id":"1.187595435","rc":[{"batb":[[0,1.01,7],[1,1.2,0],[2,1.15,0]],"ltp":1.13,"tv":26252.92,"id":11252269}]}]}
{"op":"mcm","clk":"4230947530","pt":1631538272003,"mc":[{"id":"1.187595435","rc":[{"batb":[[0,12,10],[1,4,379.77],[2,1.01,7]],"batl":[[0,46,43.47]],"ltp":8.6,"tv":302.87,"id":9634224}]}]}
{"op":"mcm","clk":"4230947776","pt":1631538274294,"mc":[{"id":"1.187595435","rc":[{"batl":[[0,1.11,255.49]],"ltp":1.13,"tv":26252.92,"id":11252269}]}]}
{"op":"mcm","clk":"4230947901","pt":1631538275597,"mc":[{"id":"1.187595435","rc":[{"batl":[[0,1.1,255.49],[1,1.11,255.49]],"ltp":1.13,"tv":26252.92,"id":11252269}]}]}
{"op":"mcm","clk":"4230947974","pt":1631538276480,"mc":[{"id":"1.187595435","rc":[{"batb":[[0,1.03,200],[1,1.01,7]],"ltp":1.13,"tv":26252.92,"id":11252269}]}]}
{"op":"mcm","clk":"4230948078","pt":1631538277626,"mc":[{"id":"1.187595435","rc":[{"batb":[[0,1.03,455.49]],"batl":[[1,1.11,0]],"ltp":1.13,"tv":26252.92,"id":11252269}]}]}
{"op":"mcm","clk":"4230948621","pt":1631538283122,"mc":[{"id":"1.187595435","rc":[{"batb":[[0,1.03,655.49]],"ltp":1.13,"tv":26252.92,"id":11252269}]}]}
{"op":"mcm","clk":"4230949599","pt":1631538295619,"mc":[{"id":"1.187595435","rc":[{"batb":[[0,1.03,255.49]],"ltp":1.13,"tv":26252.92,"id":11252269}]}]}
{"op":"mcm","clk":"4230949827","pt":1631538298529,"mc":[{"id":"1.187595435","rc":[{"batb":[[1,1.01,7],[2,1.01,0]],"ltp":8.6,"tv":302.87,"id":9634224}]}]}
{"op":"mcm","clk":"4230950447","pt":1631538304551,"mc":[{"id":"1.187595435","rc":[{"batb":[[0,1.01,7],[1,1.01,0]],"ltp":8.6,"tv":302.87,"id":9634224}]}]}
{"op":"mcm","clk":"4230950973","pt":1631538309396,"mc":[{"id":"1.187595435","rc":[{"batb":[[0,7.6,10],[1,1.01,7]],"ltp":8.6,"tv":302.87,"id":9634224},{"batb":[[0,1.05,599.99],[1,1.03,255.49],[2,1.01,7]],"ltp":1.13,"tv":26252.92,"id":11252269}]}]}
{"op":"mcm","clk":"4230951017","pt":1631538309982,"mc":[{"id":"1.187595435","rc":[{"batb":[[0,1.1,79.73],[1,1.05,599.99],[2,1.03,255.49]],"ltp":1.13,"tv":26252.92,"id":11252269}]}]}
{"op":"mcm","clk":"4230951129","pt":1631538311079,"mc":[{"id":"1.187595435","rc":[{"batb":[[1,3.4,382.26],[2,1.01,7]],"batl":[[0,15.5,60.22]],"ltp":8.6,"tv":302.87,"id":9634224},{"batb":[[0,1.05,599.99],[1,1.03,255.49],[2,1.01,7]],"ltp":1.13,"tv":26252.92,"id":11252269}]}]}
{"op":"mcm","clk":"4230951232","pt":1631538312160,"mc":[{"id":"1.187595435","rc":[{"trd":[[7.6,19.58]],"batb":[[0,3.4,382.26],[1,1.01,7],[2,1.01,0]],"ltp":7.6,"tv":312.87,"id":9634224},{"trd":[[1.16,65.52]],"batb":[[0,1.16,10.09],[1,1.05,599.99],[2,1.03,255.49]],"ltp":1.16,"tv":26318.43,"id":11252269}],"tv":26631.31}]}
{"op":"mcm","clk":"4230951464","pt":1631538315051,"mc":[{"id":"1.187595435","rc":[{"batl":[[0,12,2.66],[1,15.5,60.22]],"ltp":7.6,"tv":312.87,"id":9634224}]}]}
{"op":"mcm","clk":"4230951655","pt":1631538317250,"mc":[{"id":"1.187595435","rc":[{"batb":[[2,1.01,7]],"ltp":1.16,"tv":26318.43,"id":11252269}]}]}
{"op":"mcm","clk":"4230951701","pt":1631538317865,"mc":[{"id":"1.187595435","rc":[{"batb":[[0,1.01,7],[1,1.01,0]],"batl":[[1,15.5,0]],"ltp":7.6,"tv":312.87,"id":9634224},{"batb":[[1,1.1,200],[2,1.05,599.99]],"ltp":1.16,"tv":26318.43,"id":11252269}]}]}
{"op":"mcm","clk":"4230951797","pt":1631538318969,"mc":[{"id":"1.187595435","rc":[{"batb":[[0,1.1,200],[1,1.05,599.99],[2,1.01,7]],"ltp":1.16,"tv":26318.43,"id":11252269}]}]}
{"op":"mcm","clk":"4230952540","pt":1631538328283,"mc":[{"id":"1.187595435","rc":[{"batb":[[1,1.01,7],[2,1.01,0]],"ltp":1.16,"tv":26318.43,"id":11252269}]}]}
{"op":"mcm","clk":"4230952690","pt":1631538329968,"mc":[{"id":"1.187595435","rc":[{"batb":[[0,1.01,7],[1,1.01,0]],"ltp":1.16,"tv":26318.43,"id":11252269}]}]}
{"op":"mcm","clk":"4230952993","pt":1631538333065,"mc":[{"id":"1.187595435","rc":[{"batb":[[0,4.1,10],[1,1.01,7]],"ltp":7.6,"tv":312.87,"id":9634224},{"batb":[[0,1.18,166.66],[1,1.01,7]],"ltp":1.16,"tv":26318.43,"id":11252269}]}]}
{"op":"mcm","clk":"4230953069","pt":1631538334066,"mc":[{"id":"1.187595435","rc":[{"batb":[[1,2.72,384.67],[2,1.01,7]],"batl":[[0,7.2,92.96],[1,12,2.66]],"ltp":7.6,"tv":312.87,"id":9634224}]}]}
{"op":"mcm","clk":"4230953512","pt":1631538339496,"mc":[{"id":"1.187595435","rc":[{"batb":[[0,1.2,200],[1,1.18,166.66],[2,1.01,7]],"ltp":1.16,"tv":26318.43,"id":11252269}]}]}
{"op":"mcm","clk":"4230953918","pt":1631538344306,"mc":[{"id":"1.187595435","rc":[{"batb":[[0,1.18,166.66],[1,1.01,7],[2,1.01,0]],"ltp":1.16,"tv":26318.43,"id":11252269}]}]}
{"op":"mcm","clk":"4230954629","pt":1631538353254,"mc":[{"id":"1.187595435","rc":[{"batb":[[0,1.2,100],[1,1.18,166.66],[2,1.01,7]],"ltp":1.16,"tv":26318.43,"id":11252269}]}]}
{"op":"mcm","clk":"4230955626","pt":1631538365609,"mc":[{"id":"1.187595435","rc":[{"batb":[[1,1.01,7],[2,1.01,0]],"batl":[[0,12,2.66],[1,12,0]],"ltp":7.6,"tv":312.87,"id":9634224}]}]}
{"op":"mcm","clk":"4230955718","pt":1631538366602,"mc":[{"id":"1.187595435","rc":[{"batb":[[0,1.18,166.66],[1,1.01,7],[2,1.01,0]],"ltp":1.16,"tv":26318.43,"id":11252269}]}]}
{"op":"mcm","clk":"4230957019","pt":1631538382146,"mc":[{"id":"1.187595435","rc":[{"batb":[[0,1.3,3],[1,1.18,166.66],[2,1.01,7]],"ltp":1.16,"tv":26318.43,"id":11252269}]}]}
{"op":"mcm","clk":"4230957441","pt":1631538386399,"mc":[{"id":"1.187595435","rc":[{"batb":[[0,1.01,7],[1,1.01,0]],"ltp":7.6,"tv":312.87,"id":9634224},{"batb":[[1,1.01,7],[2,1.01,0]],"ltp":1.16,"tv":26318.43,"id":11252269}]}]}
{"op":"mcm","clk":"4230958018","pt":1631538393313,"mc":[{"id":"1.187595435","rc":[{"batb":[[0,1.01,7],[1,1.01,0]],"ltp":1.16,"tv":26318.43,"id":11252269}]}]}
{"op":"mcm","clk":"4230958587","pt":1631538399746,"mc":[{"id":"1.187595435","rc":[{"trd":[[12,2.66]],"ltp":12.0,"tv":315.53,"id":9634224},{"trd":[[1.01,14],[1.09,29.31]],"batl":[[0,1.01,815.34]],"ltp":1.01,"tv":26361.74,"id":11252269}],"tv":26677.28}]}
{"op":"mcm","clk":"4230958975","pt":1631538404773,"mc":[{"id":"1.187595435","rc":[{"batl":[[1,1.17,3]],"ltp":1.01,"tv":26361.74,"id":11252269}]}]}
{"op":"mcm","clk":"4230959235","pt":1631538408171,"mc":[{"id":"1.187595435","marketDefinition":{"bspMarket":false,"turnInPlayEnabled":true,"persistenceEnabled":true,"marketBaseRate":5.0,"eventId":"30897896","eventTypeId":"2","numberOfWinners":1,"bettingType":"ODDS","marketType":"MATCH_ODDS","marketTime":"2021-09-13T10:52:26.000Z","suspendTime":"2021-09-13T10:52:26.000Z","bspReconciled":false,"complete":true,"inPlay":true,"crossMatching":true,"runnersVoidable":false,"numberOfActiveRunners":2,"betDelay":5,"status":"SUSPENDED","runners":[{"status":"ACTIVE","sortPriority":1,"id":9634224,"name":"M Gutierrez Carrasco"},{"status":"ACTIVE","sortPriority":2,"id":11252269,"name":"I Ghioroaie"}],"regulators":["MR_INT"],"countryCode":"GB","discountAllowed":true,"timezone":"GMT","openDate":"2021-09-13T10:52:26.000Z","version":4030686301,"name":"Match Odds","eventName":"M Gutierrez Carrasco v I Ghioroaie"}}]}
{"op":"mcm","clk":"4230959786","pt":1631538414581,"mc":[{"id":"1.187595435","tv":0.0}]}
{"op":"mcm","clk":"4230959937","pt":1631538416217,"mc":[{"id":"1.187595435","marketDefinition":{"bspMarket":false,"turnInPlayEnabled":true,"persistenceEnabled":true,"marketBaseRate":5.0,"eventId":"30897896","eventTypeId":"2","numberOfWinners":1,"bettingType":"ODDS","marketType":"MATCH_ODDS","marketTime":"2021-09-13T10:52:26.000Z","suspendTime":"2021-09-13T10:52:26.000Z","bspReconciled":false,"complete":true,"inPlay":true,"crossMatching":false,"runnersVoidable":false,"numberOfActiveRunners":0,"betDelay":5,"status":"CLOSED","settledTime":"2021-09-13T13:06:50.000Z","runners":[{"status":"LOSER","sortPriority":1,"id":9634224,"name":"M Gutierrez Carrasco"},{"status":"WINNER","sortPriority":2,"id":11252269,"name":"I Ghioroaie"}],"regulators":["MR_INT"],"countryCode":"GB","discountAllowed":true,"timezone":"GMT","openDate":"2021-09-13T10:52:26.000Z","version":4030686317,"name":"Match Odds","eventName":"M Gutierrez Carrasco v I Ghioroaie"}}]}
