{"op":"mcm","clk":"4212789890","pt":1631484721383,"mc":[{"id":"1.187566733","marketDefinition":{"bspMarket":false,"turnInPlayEnabled":true,"persistenceEnabled":true,"marketBaseRate":5.0,"eventId":"30896763","eventTypeId":"2","numberOfWinners":1,"bettingType":"ODDS","marketType":"MATCH_ODDS","marketTime":"2021-09-13T17:00:00.000Z","suspendTime":"2021-09-13T17:00:00.000Z","bspReconciled":false,"complete":true,"inPlay":false,"crossMatching":false,"runnersVoidable":false,"numberOfActiveRunners":2,"betDelay":0,"status":"OPEN","runners":[{"status":"ACTIVE","sortPriority":1,"id":9323645,"name":"Alexis Galarneau"},{"status":"ACTIVE","sortPriority":2,"id":8734382,"name":"Alexander Sarkissian"}],"regulators":["MR_INT"],"countryCode":"US","discountAllowed":false,"timezone":"UTC","openDate":"2021-09-13T17:00:00.000Z","version":4029866165,"name":"Match Odds","eventName":"Galarneau v Sarkissian"},"rc":[{"batb":[[0,1.02,3614.28],[1,1.01,3614.28]],"ltp":0.0,"tv":0.0,"id":8734382},{"batb":[[0,1.02,3614.28],[1,1.01,3614.28]],"ltp":0.0,"tv":0.0,"id":9323645}]}]}
{"op":"mcm","clk":"4212789998","pt":1631484723218,"mc":[{"id":"1.187566733","marketDefinition":{"bspMarket":false,"turnInPlayEnabled":true,"persistenceEnabled":true,"marketBaseRate":5.0,"eventId":"30896763","eventTypeId":"2","numberOfWinners":1,"bettingType":"ODDS","marketType":"MATCH_ODDS","marketTime":"2021-09-13T17:00:00.000Z","suspendTime":"2021-09-13T17:00:00.000Z","bspReconciled":false,"complete":true,"inPlay":false,"crossMatching":false,"runnersVoidable":false,"numberOfActiveRunners":2,"betDelay":0,"status":"OPEN","runners":[{"status":"ACTIVE","sortPriority":1,"id":9323645,"name":"Alexis Galarneau"},{"status":"ACTIVE","sortPriority":2,"id":8734382,"name":"Alexander Sarkissian"}],"regulators":["MR_INT"],"countryCode":"US","discountAllowed":true,"timezone":"UTC","openDate":"2021-09-13T17:00:00.000Z","version":4029866165,"name":"Match Odds","eventName":"Galarneau v Sarkissian"}}]}
{"op":"mcm","clk":"4212790103","pt":1631484724886,"mc":[{"id":"1.187566733","rc":[{"batb":[[1,1.01,3639.28]],"ltp":0.0,"tv":0.0,"id":8734382},{"batb":[[1,1.01,3639.28]],"ltp":0.0,"tv":0.0,"id":9323645}]}]}
{"op":"mcm","clk":"4212802551","pt":1631484910837,"mc":[{"id":"1.187566733","rc":[{"batb":[[1,1.01,3621.28]],"ltp":0.0,"tv":0.0,"id":8734382},{"batb":[[1,1.01,3621.28]],"ltp":0.0,"tv":0.0,"id":9323645}]}]}
{"op":"mcm","clk":"4212864194","pt":1631485810650,"mc":[{"id":"1.187566733","rc":[{"batb":[[1,1.01,3614.28]],"ltp":0.0,"tv":0.0,"id":8734382},{"batb":[[1,1.01,3614.28]],"ltp":0.0,"tv":0.0,"id":9323645}]}]}
{"op":"mcm","clk":"4212866403","pt":1631485845910,"mc":[{"id":"1.187566733","rc":[{"batb":[[1,1.01,3708.21]],"ltp":0.0,"tv":0.0,"id":8734382},{"batb":[[1,1.01,3708.21]],"ltp":0.0,"tv":0.0,"id":9323645}]}]}
{"op":"mcm","clk":"4212872258","pt":1631485952340,"mc":[{"id":"1.187566733","rc":[{"batb":[[0,1.4,768.51],[1,1.02,3614.28],[2,1.01,3708.21]],"ltp":0.0,"tv":0.0,"id":8734382},{"batb":[[0,1.1,768.51],[1,1.02,3614.28],[2,1.01,3708.21]],"ltp":0.0,"tv":0.0,"id":9323645}]}]}
{"op":"mcm","clk":"4212872853","pt":1631485962758,"mc":[{"id":"1.187566733","rc":[{"batb":[[0,1.41,23.91],[1,1.4,768.51],[2,1.02,3614.28]],"ltp":0.0,"tv":0.0,"id":8734382},{"batb":[[0,1.11,37.57],[1,1.1,768.51],[2,1.02,3614.28]],"ltp":0.0,"tv":0.0,"id":9323645}]}]}
{"op":"mcm","clk":"4212941042","pt":1631487162686,"mc":[{"id":"1.187566733","rc":[{"batb":[[0,1.41,29.81]],"ltp":0.0,"tv":0.0,"id":8734382},{"batb":[[0,1.11,43.8]],"ltp":0.0,"tv":0.0,"id":9323645}]}]}
{"op":"mcm","clk":"4212941310","pt":1631487169467,"mc":[{"id":"1.187566733","marketDefinition":{"bspMarket":false,"turnInPlayEnabled":true,"persistenceEnabled":true,"marketBaseRate":5.0,"eventId":"30896763","eventTypeId":"2","numberOfWinners":1,"bettingType":"ODDS","marketType":"MATCH_ODDS","marketTime":"2021-09-13T17:00:00.000Z","suspendTime":"2021-09-13T17:00:00.000Z","bspReconciled":false,"complete":true,"inPlay":false,"crossMatching":true,"runnersVoidable":false,"numberOfActiveRunners":2,"betDelay":0,"status":"OPEN","runners":[{"status":"ACTIVE","sortPriority":1,"id":9323645,"name":"Alexis Galarneau"},{"status":"ACTIVE","sortPriority":2,"id":8734382,"name":"Alexander Sarkissian"}],"regulators":["MR_INT"],"countryCode":"US","discountAllowed":true,"timezone":"UTC","openDate":"2021-09-13T17:00:00.000Z","version":4029866165,"name":"Match Odds","eventName":"Galarneau v Sarkissian"}}]}
{"op":"mcm","clk":"4212989918","pt":1631488338910,"mc":[{"id":"1.187566733","rc":[{"batb":[[0,1.41,29.81],[1,1.4,768.38],[2,1.02,3614.02]],"batl":[[0,990,2.2]],"ltp":0.0,"tv":0.0,"id":8734382},{"batb":[[0,1.11,43.79],[1,1.1,768.38],[2,1.02,3614.02]],"batl":[[0,990,2.2]],"ltp":0.0,"tv":0.0,"id":9323645}]}]}
{"op":"mcm","clk":"4213200056","pt":1631494504669,"mc":[{"id":"1.187566733","rc":[{"batb":[[0,2.6,1494.59],[1,1.41,29.81],[2,1.4,768.38]],"ltp":0.0,"tv":0.0,"id":8734382}]}]}
{"op":"mcm","clk":"4213202846","pt":1631494720236,"mc":[{"id":"1.187566733","rc":[{"batl":[[0,1.47,24.36],[1,990,2.2]],"ltp":0.0,"tv":0.0,"id":9323645}]}]}
{"op":"mcm","clk":"4213203021","pt":1631494736778,"mc":[{"id":"1.187566733","rc":[{"batl":[[0,1.51,24.36]],"ltp":0.0,"tv":0.0,"id":9323645}]}]}
{"op":"mcm","clk":"4213203517","pt":1631494769509,"mc":[{"id":"1.187566733","rc":[{"batl":[[1,1.59,21.43],[2,990,2.2]],"ltp":0.0,"tv":0.0,"id":9323645}]}]}
{"op":"mcm","clk":"4213203612","pt":1631494775623,"mc":[{"id":"1.187566733","rc":[{"batl":[[1,1.59,30.07]],"ltp":0.0,"tv":0.0,"id":9323645}]}]}
{"op":"mcm","clk":"4213203725","pt":1631494783565,"mc":[{"id":"1.187566733","rc":[{"batl":[[0,1.48,24.36]],"ltp":0.0,"tv":0.0,"id":9323645}]}]}
{"op":"mcm","clk":"4213203869","pt":1631494791882,"mc":[{"id":"1.187566733","rc":[{"batl":[[2,1.6,64.62]],"ltp":0.0,"tv":0.0,"id":9323645}]}]}
{"op":"mcm","clk":"4213204127","pt":1631494807193,"mc":[{"id":"1.187566733","rc":[{"batb":[[0,2.6,1494.63],[1,1.41,29.8],[2,1.4,767.98]],"ltp":0.0,"tv":0.0,"id":8734382},{"batb":[[0,1.11,43.77],[1,1.1,767.98],[2,1.02,3614.28]],"batl":[[2,1.6,65.31]],"ltp":0.0,"tv":0.0,"id":9323645}]}]}
{"op":"mcm","clk":"4213206080","pt":1631494903567,"mc":[{"id":"1.187566733","rc":[{"batb":[[0,2.62,5.91],[1,2.6,1494.63],[2,1.41,23.89]],"ltp":0.0,"tv":0.0,"id":8734382}]}]}
{"op":"mcm","clk":"4213382967","pt":1631501746384,"mc":[{"id":"1.187566733","rc":[{"batb":[[0,1.12,15.36],[1,1.11,43.77],[2,1.1,767.98]],"ltp":0.0,"tv":0.0,"id":9323645}]}]}
{"op":"mcm","clk":"4213482945","pt":1631504865087,"mc":[{"id":"1.187566733","rc":[{"batb":[[0,2.62,5.9],[1,2.6,1494.35],[2,1.41,23.89]],"ltp":0.0,"tv":0.0,"id":8734382},{"trd":[[1.48,48.66]],"batb":[[0,1.48,7.88],[1,1.12,15.36],[2,1.11,43.76]],"batl":[[0,1.59,30.02],[1,1.6,65.23],[2,990,2.2]],"ltp":1.48,"tv":48.66,"id":9323645}],"tv":48.66}]}
{"op":"mcm","clk":"4213482947","pt":1631504865292,"mc":[{"id":"1.187566733","rc":[{"trd":[[1.48,64.42]],"batb":[[0,1.12,15.36],[1,1.11,43.76],[2,1.1,767.79]],"ltp":1.48,"tv":64.41,"id":9323645}],"tv":64.41}]}
{"op":"mcm","clk":"4213483574","pt":1631504900932,"mc":[{"id":"1.187566733","rc":[{"batl":[[0,16,3.41],[1,990,2.2]],"ltp":0.0,"tv":0.0,"id":8734382}]}]}
{"op":"mcm","clk":"4213690077","pt":1631511638188,"mc":[{"id":"1.187566733","rc":[{"batb":[[0,2.62,5.91],[1,2.6,1495.7],[2,1.41,23.89]],"ltp":0.0,"tv":0.0,"id":8734382},{"trd":[[1.48,64.39]],"batb":[[0,1.12,15.36],[1,1.11,43.77],[2,1.1,767.85]],"ltp":1.48,"tv":64.38,"id":9323645}],"tv":64.38}]}
{"op":"mcm","clk":"4213761411","pt":1631513560724,"mc":[{"id":"1.187566733","rc":[{"batl":[[0,15.5,81.42],[1,16,3.41],[2,990,2.2]],"ltp":0.0,"tv":0.0,"id":8734382}]}]}
{"op":"mcm","clk":"4213762479","pt":1631513601931,"mc":[{"id":"1.187566733","rc":[{"batl":[[1,990,2.2],[2,990,0]],"ltp":0.0,"tv":0.0,"id":8734382}]}]}
{"op":"mcm","clk":"4213769496","pt":1631513861035,"mc":[{"id":"1.187566733","rc":[{"batl":[[0,730,3.88]],"ltp":0.0,"tv":0.0,"id":8734382}]}]}
{"op":"mcm","clk":"4213770454","pt":1631513890110,"mc":[{"id":"1.187566733","rc":[{"batl":[[0,16,3.41],[1,730,3.88],[2,990,2.2]],"ltp":0.0,"tv":0.0,"id":8734382}]}]}
{"op":"mcm","clk":"4213779570","pt":1631514160908,"mc":[{"id":"1.187566733","rc":[{"batl":[[0,15.5,182.63],[1,16,3.41]],"ltp":0.0,"tv":0.0,"id":8734382}]}]}
{"op":"mcm","clk":"4213779987","pt":1631514172417,"mc":[{"id":"1.187566733","rc":[{"batl":[[1,990,2.2],[2,990,0]],"ltp":0.0,"tv":0.0,"id":8734382}]}]}
{"op":"mcm","clk":"4213790266","pt":1631514404127,"mc":[{"id":"1.187566733","rc":[{"batl":[[0,990,2.2],[1,990,0]],"ltp":0.0,"tv":0.0,"id":8734382}]}]}
{"op":"mcm","clk":"4213792503","pt":1631514450993,"mc":[{"id":"1.187566733","rc":[{"batl":[[0,16,3.41],[1,990,2.2]],"ltp":0.0,"tv":0.0,"id":8734382}]}]}
{"op":"mcm","clk":"4213792885","pt":1631514460837,"mc":[{"id":"1.187566733","rc":[{"batl":[[0,15,5.07],[1,16,3.41],[2,990,2.2]],"ltp":0.0,"tv":0.0,"id":8734382}]}]}
{"op":"mcm","clk":"4213795214","pt":1631514522011,"mc":[{"id":"1.187566733","rc":[{"batl":[[1,990,2.2],[2,990,0]],"ltp":0.0,"tv":0.0,"id":8734382}]}]}
{"op":"mcm","clk":"4213933893","pt":1631517465632,"mc":[{"id":"1.187566733","rc":[{"batb":[[0,2.62,5.92],[1,2.6,1497.5],[2,1.41,23.89]],"ltp":0.0,"tv":0.0,"id":8734382},{"trd":[[1.48,64.45]],"batb":[[0,1.12,15.36],[1,1.11,43.78],[2,1.1,767.98]],"batl":[[0,1.59,30.03],[1,1.6,65.23]],"ltp":1.48,"tv":64.45,"id":9323645}],"tv":64.45}]}
{"op":"mcm","clk":"4214027878","pt":1631519261014,"mc":[{"id":"1.187566733","rc":[{"batl":[[0,990,2.2],[1,990,0]],"ltp":0.0,"tv":0.0,"id":8734382}]}]}
{"op":"mcm","clk":"4214027888","pt":1631519261221,"mc":[{"id":"1.187566733","rc":[{"batl":[[0,370,2.5],[1,990,2.2]],"ltp":0.0,"tv":0.0,"id":8734382}]}]}
{"op":"mcm","clk":"4214028522","pt":1631519273709,"mc":[{"id":"1.187566733","rc":[{"batl":[[0,16,3.41]],"ltp":0.0,"tv":0.0,"id":8734382}]}]}
{"op":"mcm","clk":"4214045346","pt":1631519561222,"mc":[{"id":"1.187566733","rc":[{"batl":[[0,14.5,5.24],[1,16,3.41],[2,990,2.2]],"ltp":0.0,"tv":0.0,"id":8734382}]}]}
{"op":"mcm","clk":"4214048017","pt":1631519609000,"mc":[{"id":"1.187566733","rc":[{"batl":[[1,990,2.2],[2,990,0]],"ltp":0.0,"tv":0.0,"id":8734382}]}]}
{"op":"mcm","clk":"4214145829","pt":1631521468797,"mc":[{"id":"1.187566733","rc":[{"batl":[[0,1.58,221.13],[1,1.59,30.03],[2,1.6,65.23]],"ltp":1.48,"tv":64.45,"id":9323645}]}]}
{"op":"mcm","clk":"4214181794","pt":1631522137012,"mc":[{"id":"1.187566733","rc":[{"batb":[[0,2.74,5.92]],"ltp":0.0,"tv":0.0,"id":8734382}]}]}
{"op":"mcm","clk":"4214390786","pt":1631525523027,"mc":[{"id":"1.187566733","rc":[{"trd":[[3,11.34]],"batb":[[0,2.74,5.91],[1,2.6,1496.6],[2,1.41,23.9]],"batl":[[0,3,19.33]],"ltp":3.0,"tv":11.34,"id":8734382},{"trd":[[1.48,64.48]],"batb":[[0,1.12,15.36],[1,1.11,43.78],[2,1.1,768.11]],"batl":[[0,1.58,221],[1,1.59,30.03],[2,1.6,65.23]],"ltp":1.48,"tv":64.47,"id":9323645}],"tv":75.81}]}
{"op":"mcm","clk":"4214401919","pt":1631525658872,"mc":[{"id":"1.187566733","rc":[{"trd":[[3,15.65]],"batl":[[0,3,15.02]],"ltp":3.0,"tv":15.65,"id":8734382},{"trd":[[1.5,8.63]],"batl":[[0,1.54,21.4],[1,1.58,221]],"ltp":1.5,"tv":73.1,"id":9323645}],"tv":88.75}]}
{"op":"mcm","clk":"4214403428","pt":1631525681204,"mc":[{"id":"1.187566733","rc":[{"trd":[[3,26.35]],"batl":[[0,3,4.32]],"ltp":3.0,"tv":26.35,"id":8734382},{"trd":[[1.5,30.03]],"batl":[[0,1.58,221],[1,1.6,65.23],[2,1.66,25]],"ltp":1.5,"tv":94.5,"id":9323645}],"tv":120.85}]}
{"op":"mcm","clk":"4214404018","pt":1631525690515,"mc":[{"id":"1.187566733","rc":[{"batl":[[0,1.58,221.69],[1,1.6,64.54]],"ltp":1.5,"tv":94.5,"id":9323645}]}]}
{"op":"mcm","clk":"4214487842","pt":1631526695684,"mc":[{"id":"1.187566733","rc":[{"batb":[[0,2.6,1496.6],[1,1.41,23.9],[2,1.4,768.11]],"ltp":3.0,"tv":26.35,"id":8734382},{"batb":[[1,1.11,37.55]],"ltp":1.5,"tv":94.5,"id":9323645}]}]}
{"op":"mcm","clk":"4214528376","pt":1631527221147,"mc":[{"id":"1.187566733","rc":[{"batb":[[0,2.72,3.68],[1,2.6,1496.6],[2,1.41,23.9]],"ltp":3.0,"tv":26.35,"id":8734382}]}]}
{"op":"mcm","clk":"4214845391","pt":1631531420858,"mc":[{"id":"1.187566733","rc":[{"batb":[[1,2.6,1495.17],[2,1.41,23.85]],"ltp":3.0,"tv":26.35,"id":8734382},{"trd":[[1.48,64.36],[1.5,29.97]],"batb":[[0,1.5,62.65],[1,1.12,15.33],[2,1.11,37.48]],"batl":[[0,1.58,221.48],[1,1.6,64.43]],"ltp":1.5,"tv":94.33,"id":9323645}],"tv":120.68}]}
{"op":"mcm","clk":"4214852177","pt":1631531513997,"mc":[{"id":"1.187566733","rc":[{"batb":[[1,1.11,37.48],[2,1.1,766.61]],"ltp":1.5,"tv":94.33,"id":9323645}]}]}
{"op":"mcm","clk":"4214869902","pt":1631531758837,"mc":[{"id":"1.187566733","rc":[{"trd":[[3,30.67]],"batb":[[0,2.76,21.01],[1,2.72,3.68],[2,2.6,1495.17]],"batl":[[0,990,2.2],[1,990,0]],"ltp":3.0,"tv":30.67,"id":8734382},{"trd":[[1.5,163.91]],"batb":[[0,1.11,37.48],[1,1.1,766.61],[2,1.04,271.21]],"batl":[[0,1.5,1074.19],[1,1.58,221.48],[2,1.6,64.43]],"ltp":1.5,"tv":228.27,"id":9323645}],"tv":258.94}]}
{"op":"mcm","clk":"4214870150","pt":1631531762065,"mc":[{"id":"1.187566733","rc":[{"batb":[[0,1.42,74.58],[1,1.11,37.48],[2,1.1,766.61]],"ltp":1.5,"tv":228.27,"id":9323645}]}]}
{"op":"mcm","clk":"4214870879","pt":1631531772144,"mc":[{"id":"1.187566733","rc":[{"batb":[[0,2.72,3.68],[1,2.6,1495.17],[2,1.41,23.85]],"ltp":3.0,"tv":30.67,"id":8734382},{"batl":[[0,1.49,1074.19]],"ltp":1.5,"tv":228.27,"id":9323645}]}]}
{"op":"mcm","clk":"4214895526","pt":1631532088112,"mc":[{"id":"1.187566733","rc":[{"batb":[[1,1.17,104.86],[2,1.11,37.48]],"ltp":1.5,"tv":228.27,"id":9323645}]}]}
{"op":"mcm","clk":"4214895531","pt":1631532088214,"mc":[{"id":"1.187566733","rc":[{"batb":[[2,1.8,24.51]],"ltp":3.0,"tv":30.67,"id":8734382}]}]}
{"op":"mcm","clk":"4214917938","pt":1631532374607,"mc":[{"id":"1.187566733","rc":[{"trd":[[1.49,39.12]],"batl":[[0,1.49,1054.63]],"ltp":1.49,"tv":267.39,"id":9323645}],"tv":298.06}]}
{"op":"mcm","clk":"4214924124","pt":1631532440583,"mc":[{"id":"1.187566733","rc":[{"batb":[[0,1.46,21.29],[1,1.42,74.58],[2,1.17,104.86]],"ltp":1.49,"tv":267.39,"id":9323645}]}]}
{"op":"mcm","clk":"4214925423","pt":1631532454502,"mc":[{"id":"1.187566733","rc":[{"batb":[[0,1.42,74.58],[1,1.17,104.86],[2,1.11,37.48]],"ltp":1.49,"tv":267.39,"id":9323645}]}]}
{"op":"mcm","clk":"4214932182","pt":1631532544847,"mc":[{"id":"1.187566733","rc":[{"trd":[[1.49,70.62]],"batl":[[0,1.49,1038.88]],"ltp":1.49,"tv":298.89,"id":9323645}],"tv":329.56}]}
{"op":"mcm","clk":"4214957333","pt":1631532960674,"mc":[{"id":"1.187566733","rc":[{"trd":[[1.49,90.56]],"batl":[[0,1.49,1028.9]],"ltp":1.49,"tv":318.83,"id":9323645}],"tv":349.5}]}
{"op":"mcm","clk":"4214975743","pt":1631533181752,"mc":[{"id":"1.187566733","rc":[{"batb":[[1,2.62,19.33],[2,2.6,1495.17]],"ltp":3.0,"tv":30.67,"id":8734382},{"batb":[[0,1.44,71.19]],"ltp":1.49,"tv":318.83,"id":9323645}]}]}
{"op":"mcm","clk":"4214982864","pt":1631533267977,"mc":[{"id":"1.187566733","rc":[{"batb":[[0,1.45,3.01],[1,1.44,71.19],[2,1.17,104.86]],"ltp":1.49,"tv":318.83,"id":9323645}]}]}
{"op":"mcm","clk":"4215003270","pt":1631533511484,"mc":[{"id":"1.187566733","rc":[{"batb":[[0,2.74,49.21],[1,2.72,3.68],[2,2.62,19.33]],"batl":[[0,14,9.82],[1,990,2.2]],"ltp":3.0,"tv":30.67,"id":8734382}]}]}
{"op":"mcm","clk":"4215014199","pt":1631533655071,"mc":[{"id":"1.187566733","rc":[{"batb":[[0,2.72,3.68],[1,2.62,19.33],[2,2.6,1495.17]],"batl":[[0,990,2.2],[1,990,0]],"ltp":3.0,"tv":30.67,"id":8734382},{"batl":[[0,1.48,1028.9]],"ltp":1.49,"tv":318.83,"id":9323645}]}]}
{"op":"mcm","clk":"4215014213","pt":1631533655267,"mc":[{"id":"1.187566733","rc":[{"batl":[[0,16,8.59],[1,990,2.2]],"ltp":3.0,"tv":30.67,"id":8734382}]}]}
{"op":"mcm","clk":"4215038735","pt":1631533895864,"mc":[{"id":"1.187566733","rc":[{"batb":[[0,2.74,57.4],[1,2.72,3.68],[2,2.62,19.33]],"ltp":3.0,"tv":30.67,"id":8734382}]}]}
{"op":"mcm","clk":"4215049292","pt":1631534049912,"mc":[{"id":"1.187566733","rc":[{"trd":[[1.48,85.34]],"batl":[[0,1.48,1018.41]],"ltp":1.48,"tv":339.81,"id":9323645}],"tv":370.48}]}
{"op":"mcm","clk":"4215056312","pt":1631534136082,"mc":[{"id":"1.187566733","rc":[{"trd":[[1.48,126.44]],"batl":[[0,1.48,997.86]],"ltp":1.48,"tv":380.91,"id":9323645}],"tv":411.58}]}
{"op":"mcm","clk":"4215061883","pt":1631534196172,"mc":[{"id":"1.187566733","rc":[{"batb":[[0,2.72,3.68],[1,2.62,19.33],[2,2.6,1495.17]],"batl":[[0,23,5.98]],"ltp":3.0,"tv":30.67,"id":8734382}]}]}
{"op":"mcm","clk":"4215061890","pt":1631534196268,"mc":[{"id":"1.187566733","rc":[{"batb":[[0,2.74,60.53],[1,2.72,3.68],[2,2.62,19.33]],"ltp":3.0,"tv":30.67,"id":8734382}]}]}
{"op":"mcm","clk":"4215072046","pt":1631534308878,"mc":[{"id":"1.187566733","rc":[{"trd":[[1.48,173.06]],"batl":[[0,1.48,974.55]],"ltp":1.48,"tv":427.53,"id":9323645}],"tv":458.2}]}
{"op":"mcm","clk":"4215087660","pt":1631534496537,"mc":[{"id":"1.187566733","rc":[{"batb":[[0,2.76,665.56]],"ltp":3.0,"tv":30.67,"id":8734382}]}]}
{"op":"mcm","clk":"4215087870","pt":1631534498827,"mc":[{"id":"1.187566733","rc":[{"batb":[[2,2.6,1495.17]],"ltp":3.0,"tv":30.67,"id":8734382}]}]}
{"op":"mcm","clk":"4215110064","pt":1631534784141,"mc":[{"id":"1.187566733","rc":[{"batb":[[0,2.72,3.68],[1,2.6,1495.17],[2,1.8,24.51]],"batl":[[0,4.1,2.34]],"ltp":3.0,"tv":30.67,"id":8734382}]}]}
{"op":"mcm","clk":"4215110081","pt":1631534784353,"mc":[{"id":"1.187566733","rc":[{"batb":[[0,2.74,63.68],[1,2.72,3.68],[2,2.6,1495.17]],"ltp":3.0,"tv":30.67,"id":8734382}]}]}
{"op":"mcm","clk":"4215110396","pt":1631534788378,"mc":[{"id":"1.187566733","rc":[{"batb":[[2,2.62,19.33]],"ltp":3.0,"tv":30.67,"id":8734382}]}]}
{"op":"mcm","clk":"4215133054","pt":1631535084570,"mc":[{"id":"1.187566733","rc":[{"batb":[[0,2.78,660.3]],"ltp":3.0,"tv":30.67,"id":8734382}]}]}
{"op":"mcm","clk":"4215133393","pt":1631535088362,"mc":[{"id":"1.187566733","rc":[{"batb":[[2,2.6,1495.17]],"ltp":3.0,"tv":30.67,"id":8734382}]}]}
{"op":"mcm","clk":"4215157417","pt":1631535384617,"mc":[{"id":"1.187566733","rc":[{"batb":[[0,2.8,655.65]],"ltp":3.0,"tv":30.67,"id":8734382}]}]}
{"op":"mcm","clk":"4215184393","pt":1631535684208,"mc":[{"id":"1.187566733","rc":[{"batb":[[0,2.72,3.68],[1,2.6,1495.17],[2,1.8,24.51]],"ltp":3.0,"tv":30.67,"id":8734382}]}]}
{"op":"mcm","clk":"4215184408","pt":1631535684416,"mc":[{"id":"1.187566733","rc":[{"batb":[[0,2.82,61.86],[1,2.72,3.68],[2,2.6,1495.17]],"ltp":3.0,"tv":30.67,"id":8734382}]}]}
{"op":"mcm","clk":"4215184700","pt":1631535687728,"mc":[{"id":"1.187566733","rc":[{"batb":[[2,2.62,19.33]],"ltp":3.0,"tv":30.67,"id":8734382}]}]}
{"op":"mcm","clk":"4215205612","pt":1631535937272,"mc":[{"id":"1.187566733","rc":[{"trd":[[1.48,296.35]],"batl":[[0,1.48,912.9]],"ltp":1.48,"tv":550.82,"id":9323645}],"tv":581.49}]}
{"op":"mcm","clk":"4215209293","pt":1631535984542,"mc":[{"id":"1.187566733","rc":[{"batb":[[0,2.74,670.22]],"ltp":3.0,"tv":30.67,"id":8734382}]}]}
{"op":"mcm","clk":"4215209569","pt":1631535988153,"mc":[{"id":"1.187566733","rc":[{"batb":[[2,2.6,1495.17]],"ltp":3.0,"tv":30.67,"id":8734382}]}]}
{"op":"mcm","clk":"4215214199","pt":1631536049949,"mc":[{"id":"1.187566733","rc":[{"trd":[[1.48,399.1]],"batl":[[0,1.48,861.53]],"ltp":1.48,"tv":653.57,"id":9323645}],"tv":684.24}]}
{"op":"mcm","clk":"4215222267","pt":1631536161962,"mc":[{"id":"1.187566733","rc":[{"trd":[[1.48,440.2]],"batl":[[0,1.48,840.97]],"ltp":1.48,"tv":694.67,"id":9323645}],"tv":725.34}]}
{"op":"mcm","clk":"4215230540","pt":1631536284546,"mc":[{"id":"1.187566733","rc":[{"batb":[[0,2.78,660.58]],"ltp":3.0,"tv":30.67,"id":8734382}]}]}
{"op":"mcm","clk":"4215232724","pt":1631536316735,"mc":[{"id":"1.187566733","rc":[{"batb":[[2,1.8,24.51]],"ltp":3.0,"tv":30.67,"id":8734382}]}]}
{"op":"mcm","clk":"4215249091","pt":1631536584396,"mc":[{"id":"1.187566733","rc":[{"batb":[[0,2.76,665.48]],"ltp":3.0,"tv":30.67,"id":8734382}]}]}
{"op":"mcm","clk":"4215266952","pt":1631536866525,"mc":[{"id":"1.187566733","rc":[{"batb":[[0,2.72,3.68],[1,1.8,24.51],[2,1.41,23.85]],"ltp":3.0,"tv":30.67,"id":8734382}]}]}
{"op":"mcm","clk":"4215267185","pt":1631536867605,"mc":[{"id":"1.187566733","rc":[{"batb":[[1,2.62,19.33],[2,1.8,24.51]],"ltp":3.0,"tv":30.67,"id":8734382}]}]}
{"op":"mcm","clk":"4215282521","pt":1631537141658,"mc":[{"id":"1.187566733","rc":[{"batb":[[0,2.76,63.21],[1,2.72,3.68],[2,2.62,19.33]],"ltp":3.0,"tv":30.67,"id":8734382}]}]}
{"op":"mcm","clk":"4215300246","pt":1631537441742,"mc":[{"id":"1.187566733","rc":[{"batb":[[0,2.74,584.89]],"ltp":3.0,"tv":30.67,"id":8734382}]}]}
{"op":"mcm","clk":"4215300590","pt":1631537446970,"mc":[{"id":"1.187566733","rc":[{"batb":[[2,1.8,24.51]],"ltp":3.0,"tv":30.67,"id":8734382}]}]}
{"op":"mcm","clk":"4215353091","pt":1631538224985,"mc":[{"id":"1.187566733","rc":[{"batb":[[0,2.82,61.82],[2,1.8,24.49]],"batl":[[0,4.1,2.33]],"ltp":3.0,"tv":30.67,"id":8734382},{"trd":[[1.48,440.21],[1.49,90.58],[1.5,163.89]],"batb":[[2,1.17,104.78]],"batl":[[0,1.48,840.84],[1,1.58,221.33],[2,1.6,64.4]],"ltp":1.48,"tv":694.67,"id":9323645}],"tv":725.34}]}
{"op":"mcm","clk":"4215353483","pt":1631538229610,"mc":[{"id":"1.187566733","rc":[{"batb":[[2,2.62,19.33]],"ltp":3.0,"tv":30.67,"id":8734382}]}]}
{"op":"mcm","clk":"4215361815","pt":1631538342018,"mc":[{"id":"1.187566733","rc":[{"batb":[[0,2.76,643.65]],"ltp":3.0,"tv":30.67,"id":8734382}]}]}
{"op":"mcm","clk":"4215362142","pt":1631538346517,"mc":[{"id":"1.187566733","rc":[{"batb":[[2,1.8,24.49]],"ltp":3.0,"tv":30.67,"id":8734382}]}]}
{"op":"mcm","clk":"4215365001","pt":1631538384202,"mc":[{"id":"1.187566733","rc":[{"batl":[[0,990,2.2],[1,990,0]],"ltp":3.0,"tv":30.67,"id":8734382}]}]}
{"op":"mcm","clk":"4215365049","pt":1631538384680,"mc":[{"id":"1.187566733","rc":[{"batl":[[0,4.1,2.33],[1,990,2.2]],"ltp":3.0,"tv":30.67,"id":8734382}]}]}
{"op":"mcm","clk":"4215385329","pt":1631538640826,"mc":[{"id":"1.187566733","rc":[{"batb":[[0,2.72,3.68],[1,1.8,24.49],[2,1.41,23.85]],"ltp":3.0,"tv":30.67,"id":8734382}]}]}
{"op":"mcm","clk":"4215385539","pt":1631538641895,"mc":[{"id":"1.187566733","rc":[{"batb":[[0,2.76,207.28],[1,2.72,3.68],[2,1.8,24.49]],"ltp":3.0,"tv":30.67,"id":8734382}]}]}
{"op":"mcm","clk":"4215385842","pt":1631538646203,"mc":[{"id":"1.187566733","rc":[{"batb":[[2,2.62,19.33]],"ltp":3.0,"tv":30.67,"id":8734382}]}]}
{"op":"mcm","clk":"4215390155","pt":1631538710588,"mc":[{"id":"1.187566733","rc":[{"batb":[[0,2.72,3.68],[1,2.62,19.33],[2,1.8,24.49]],"ltp":3.0,"tv":30.67,"id":8734382}]}]}
{"op":"mcm","clk":"4215407261","pt":1631538913167,"mc":[{"id":"1.187566733","rc":[{"batb":[[0,2.76,63.18],[1,2.72,3.68],[2,2.62,19.33]],"ltp":3.0,"tv":30.67,"id":8734382}]}]}
{"op":"mcm","clk":"4215441621","pt":1631539213380,"mc":[{"id":"1.187566733","rc":[{"batb":[[0,2.74,648.27]],"ltp":3.0,"tv":30.67,"id":8734382}]}]}
{"op":"mcm","clk":"4215441781","pt":1631539215785,"mc":[{"id":"1.187566733","rc":[{"batb":[[2,1.8,24.49]],"ltp":3.0,"tv":30.67,"id":8734382}]}]}
{"op":"mcm","clk":"4215528152","pt":1631540457424,"mc":[{"id":"1.187566733","rc":[{"batl":[[0,1.46,3.44],[1,1.48,840.84],[2,1.58,221.33]],"ltp":1.48,"tv":694.67,"id":9323645}]}]}
{"op":"mcm","clk":"4215528217","pt":1631540458726,"mc":[{"id":"1.187566733","rc":[{"batb":[[0,2.84,110.15]],"ltp":3.0,"tv":30.67,"id":8734382}]}]}
{"op":"mcm","clk":"4215528276","pt":1631540459926,"mc":[{"id":"1.187566733","rc":[{"batb":[[2,2.62,19.33]],"ltp":3.0,"tv":30.67,"id":8734382}]}]}
{"op":"mcm","clk":"4215533360","pt":1631540553281,"mc":[{"id":"1.187566733","rc":[{"trd":[[1.46,6.87],[1.48,452.74]],"batl":[[0,1.48,834.57],[1,1.58,221.33],[2,1.6,64.4]],"ltp":1.48,"tv":714.07,"id":9323645}],"tv":744.74}]}
{"op":"mcm","clk":"4215542419","pt":1631540713897,"mc":[{"id":"1.187566733","rc":[{"batb":[[0,2.76,496.31],[2,1.8,24.49]],"ltp":3.0,"tv":30.67,"id":8734382}]}]}
{"op":"mcm","clk":"4215582011","pt":1631541375711,"mc":[{"id":"1.187566733","rc":[{"trd":[[1.45,6.02]],"batb":[[0,1.44,71.19],[1,1.17,104.78],[2,1.15,15.97]],"ltp":1.45,"tv":720.09,"id":9323645}],"tv":750.76}]}
{"op":"mcm","clk":"4215583134","pt":1631541393654,"mc":[{"id":"1.187566733","rc":[{"batl":[[0,1.47,3.06],[1,1.48,834.57],[2,1.58,221.33]],"ltp":1.45,"tv":720.09,"id":9323645}]}]}
{"op":"mcm","clk":"4215605064","pt":1631541730957,"mc":[{"id":"1.187566733","rc":[{"batl":[[0,3.85,64.73],[1,4.1,2.33],[2,990,2.2]],"ltp":3.0,"tv":30.67,"id":8734382},{"trd":[[1.47,20.68]],"batl":[[0,1.48,834.57],[1,1.58,221.33],[2,1.6,64.4]],"ltp":1.47,"tv":740.77,"id":9323645}],"tv":771.44}]}
{"op":"mcm","clk":"4215606299","pt":1631541746186,"mc":[{"id":"1.187566733","rc":[{"batb":[[0,1.45,6.01],[1,1.44,71.19],[2,1.17,104.78]],"ltp":1.47,"tv":740.77,"id":9323645}]}]}
{"op":"mcm","clk":"4215611120","pt":1631541814153,"mc":[{"id":"1.187566733","rc":[{"trd":[[1.48,493.81]],"batl":[[0,1.48,814.05]],"ltp":1.48,"tv":781.85,"id":9323645}],"tv":812.52}]}
{"op":"mcm","clk":"4215617898","pt":1631541913346,"mc":[{"id":"1.187566733","rc":[{"batb":[[0,2.74,842.64]],"ltp":3.0,"tv":30.67,"id":8734382}]}]}
{"op":"mcm","clk":"4215673778","pt":1631542762942,"mc":[{"id":"1.187566733","rc":[{"batb":[[0,2.74,310.23]],"ltp":3.0,"tv":30.67,"id":8734382},{"batl":[[0,1.47,45],[1,1.48,814.05],[2,1.58,221.33]],"ltp":1.48,"tv":781.85,"id":9323645}]}]}
{"op":"mcm","clk":"4215673797","pt":1631542763260,"mc":[{"id":"1.187566733","rc":[{"batb":[[2,2.62,19.33]],"ltp":3.0,"tv":30.67,"id":8734382}]}]}
{"op":"mcm","clk":"4215676882","pt":1631542814052,"mc":[{"id":"1.187566733","rc":[{"batb":[[0,2.76,602.09],[2,1.8,24.49]],"ltp":3.0,"tv":30.67,"id":8734382}]}]}
{"op":"mcm","clk":"4215685265","pt":1631542962100,"mc":[{"id":"1.187566733","rc":[{"trd":[[1.47,335.89]],"batl":[[0,1.48,814.05],[1,1.58,221.33],[2,1.6,64.4]],"ltp":1.47,"tv":1097.05,"id":9323645}],"tv":1127.72}]}
{"op":"mcm","clk":"4215685291","pt":1631542962473,"mc":[{"id":"1.187566733","rc":[{"batb":[[0,2.82,408.8]],"ltp":3.0,"tv":30.67,"id":8734382}]}]}
{"op":"mcm","clk":"4215694176","pt":1631543101357,"mc":[{"id":"1.187566733","rc":[{"batl":[[1,1.53,2.09],[2,1.58,221.33]],"ltp":1.47,"tv":1097.05,"id":9323645}]}]}
{"op":"mcm","clk":"4215695052","pt":1631543113492,"mc":[{"id":"1.187566733","rc":[{"batb":[[0,2.78,821.95],[2,2.62,19.33]],"ltp":3.0,"tv":30.67,"id":8734382}]}]}
{"op":"mcm","clk":"4215695350","pt":1631543118625,"mc":[{"id":"1.187566733","rc":[{"batb":[[2,1.8,24.49]],"ltp":3.0,"tv":30.67,"id":8734382}]}]}
{"op":"mcm","clk":"4215714338","pt":1631543423691,"mc":[{"id":"1.187566733","rc":[{"batl":[[0,1.47,1485.75],[1,1.48,814.05],[2,1.53,2.09]],"ltp":1.47,"tv":1097.05,"id":9323645}]}]}
{"op":"mcm","clk":"4215781147","pt":1631544172763,"mc":[{"id":"1.187566733","rc":[{"batb":[[2,1.22,194.02]],"ltp":1.47,"tv":1097.05,"id":9323645}]}]}
{"op":"mcm","clk":"4215794062","pt":1631544339870,"mc":[{"id":"1.187566733","rc":[{"batl":[[0,1.46,814.05],[1,1.47,1485.75]],"ltp":1.47,"tv":1097.05,"id":9323645}]}]}
{"op":"mcm","clk":"4215795812","pt":1631544361508,"mc":[{"id":"1.187566733","rc":[{"trd":[[1.46,110.25]],"batl":[[0,1.46,762.39]],"ltp":1.46,"tv":1200.43,"id":9323645}],"tv":1231.1}]}
{"op":"mcm","clk":"4215817375","pt":1631544526557,"mc":[{"id":"1.187566733","rc":[{"trd":[[1.46,221.67]],"batl":[[0,1.46,706.71]],"ltp":1.46,"tv":1311.85,"id":9323645}],"tv":1342.52}]}
{"op":"mcm","clk":"4215820719","pt":1631544569915,"mc":[{"id":"1.187566733","rc":[{"trd":[[1.46,228.35]],"batl":[[0,1.46,703.37]],"ltp":1.46,"tv":1318.54,"id":9323645}],"tv":1349.21}]}
{"op":"mcm","clk":"4215820781","pt":1631544570599,"mc":[{"id":"1.187566733","rc":[{"batl":[[1,4,6.85],[2,4.1,2.33]],"ltp":3.0,"tv":30.67,"id":8734382},{"batb":[[2,1.35,14.07]],"batl":[[0,1.46,720.39]],"ltp":1.46,"tv":1318.54,"id":9323645}]}]}
{"op":"mcm","clk":"4215824367","pt":1631544613342,"mc":[{"id":"1.187566733","rc":[{"batb":[[0,2.76,1243.86]],"ltp":3.0,"tv":30.67,"id":8734382}]}]}
{"op":"mcm","clk":"4215833328","pt":1631544727921,"mc":[{"id":"1.187566733","rc":[{"batb":[[2,1.86,22.92]],"ltp":3.0,"tv":30.67,"id":8734382}]}]}
{"op":"mcm","clk":"4215853244","pt":1631545010971,"mc":[{"id":"1.187566733","marketDefinition":{"bspMarket":false,"turnInPlayEnabled":true,"persistenceEnabled":true,"marketBaseRate":5.0,"eventId":"30896763","eventTypeId":"2","numberOfWinners":1,"bettingType":"ODDS","marketType":"MATCH_ODDS","marketTime":"2021-09-13T16:55:00.000Z","suspendTime":"2021-09-13T16:55:00.000Z","bspReconciled":false,"complete":true,"inPlay":false,"crossMatching":true,"runnersVoidable":false,"numberOfActiveRunners":2,"betDelay":0,"status":"OPEN","runners":[{"status":"ACTIVE","sortPriority":1,"id":9323645,"name":"Alexis Galarneau"},{"status":"ACTIVE","sortPriority":2,"id":8734382,"name":"Alexander Sarkissian"}],"regulators":["MR_INT"],"countryCode":"US","discountAllowed":true,"timezone":"UTC","openDate":"2021-09-13T17:00:00.000Z","version":4030797656,"name":"Match Odds","eventName":"Galarneau v Sarkissian"}}]}
{"op":"mcm","clk":"4215855118","pt":1631545031107,"mc":[{"id":"1.187566733","marketDefinition":{"bspMarket":false,"turnInPlayEnabled":true,"persistenceEnabled":true,"marketBaseRate":5.0,"eventId":"30896763","eventTypeId":"2","numberOfWinners":1,"bettingType":"ODDS","marketType":"MATCH_ODDS","marketTime":"2021-09-13T16:55:00.000Z","suspendTime":"2021-09-13T16:55:00.000Z","bspReconciled":false,"complete":true,"inPlay":false,"crossMatching":true,"runnersVoidable":false,"numberOfActiveRunners":2,"betDelay":0,"status":"OPEN","runners":[{"status":"ACTIVE","sortPriority":1,"id":9323645,"name":"Alexis Galarneau"},{"status":"ACTIVE","sortPriority":2,"id":8734382,"name":"Alexander Sarkissian"}],"regulators":["MR_INT"],"countryCode":"US","discountAllowed":true,"timezone":"UTC","openDate":"2021-09-13T16:55:00.000Z","version":4030797656,"name":"Match Odds","eventName":"Galarneau v Sarkissian"}}]}
{"op":"mcm","clk":"4215855159","pt":1631545031395,"mc":[{"id":"1.187566733","rc":[{"batb":[[0,2.72,3.68],[1,1.86,22.92],[2,1.8,24.49]],"batl":[[0,4,6.85],[1,4.1,2.33],[2,990,2.2]],"ltp":3.0,"tv":30.67,"id":8734382}]}]}
{"op":"mcm","clk":"4215855627","pt":1631545036208,"mc":[{"id":"1.187566733","rc":[{"batb":[[1,2.62,19.33],[2,1.86,22.92]],"ltp":3.0,"tv":30.67,"id":8734382}]}]}
{"op":"mcm","clk":"4215855706","pt":1631545037123,"mc":[{"id":"1.187566733","rc":[{"batb":[[0,2.78,557.3],[1,2.72,3.68],[2,2.62,19.33]],"ltp":3.0,"tv":30.67,"id":8734382}]}]}
{"op":"mcm","clk":"4215856064","pt":1631545041305,"mc":[{"id":"1.187566733","rc":[{"batb":[[2,1.86,22.92]],"ltp":3.0,"tv":30.67,"id":8734382}]}]}
{"op":"mcm","clk":"4215856807","pt":1631545050736,"mc":[{"id":"1.187566733","rc":[{"batl":[[1,1.53,2.09],[2,1.58,221.33]],"ltp":1.46,"tv":1318.54,"id":9323645}]}]}
{"op":"mcm","clk":"4215858422","pt":1631545072135,"mc":[{"id":"1.187566733","rc":[{"batl":[[0,4,2.94]],"ltp":3.0,"tv":30.67,"id":8734382},{"batl":[[0,1.46,711.43]],"ltp":1.46,"tv":1318.54,"id":9323645}]}]}
{"op":"mcm","clk":"4215863415","pt":1631545137721,"mc":[{"id":"1.187566733","rc":[{"batb":[[2,2.62,10]],"ltp":3.0,"tv":30.67,"id":8734382},{"batb":[[1,1.44,94.92]],"ltp":1.46,"tv":1318.54,"id":9323645}]}]}
{"op":"mcm","clk":"4215865054","pt":1631545163852,"mc":[{"id":"1.187566733","rc":[{"trd":[[1.45,18.05]],"batb":[[0,1.44,94.92],[1,1.35,14.07],[2,1.23,85.68]],"batl":[[0,1.45,736.86],[1,1.46,711.43],[2,1.53,2.09]],"ltp":1.45,"tv":1330.56,"id":9323645}],"tv":1361.23}]}
{"op":"mcm","clk":"4215865245","pt":1631545166053,"mc":[{"id":"1.187566733","rc":[{"batb":[[0,3.2,5.12]],"batl":[[0,4.1,6.65],[1,990,2.2],[2,990,0]],"ltp":3.0,"tv":30.67,"id":8734382}]}]}
{"op":"mcm","clk":"4215865413","pt":1631545167966,"mc":[{"id":"1.187566733","rc":[{"batb":[[2,2.62,25.78]],"ltp":3.0,"tv":30.67,"id":8734382}]}]}
{"op":"mcm","clk":"4215866383","pt":1631545179373,"mc":[{"id":"1.187566733","rc":[{"batl":[[1,1.46,703.37]],"ltp":1.45,"tv":1330.56,"id":9323645}]}]}
{"op":"mcm","clk":"4215866685","pt":1631545183181,"mc":[{"id":"1.187566733","rc":[{"batb":[[0,2.72,3.68],[1,2.62,25.78],[2,1.86,22.92]],"ltp":3.0,"tv":30.67,"id":8734382}]}]}
{"op":"mcm","clk":"4215866702","pt":1631545183388,"mc":[{"id":"1.187566733","rc":[{"batb":[[0,2.82,532.08],[1,2.72,3.68],[2,2.62,25.78]],"ltp":3.0,"tv":30.67,"id":8734382}]}]}
{"op":"mcm","clk":"4215867111","pt":1631545188405,"mc":[{"id":"1.187566733","rc":[{"batb":[[2,2.62,14.81]],"ltp":3.0,"tv":30.67,"id":8734382}]}]}
{"op":"mcm","clk":"4215871086","pt":1631545235829,"mc":[{"id":"1.187566733","rc":[{"batl":[[0,4.1,6.64]],"ltp":3.0,"tv":30.67,"id":8734382},{"trd":[[1.45,129.52],[1.46,228.49],[1.47,336.16],[1.48,494.09],[1.49,90.63],[1.5,164]],"batb":[[2,1.23,85.6]],"batl":[[0,1.45,680.28],[1,1.46,704.24]],"ltp":1.45,"tv":1442.9,"id":9323645}],"tv":1473.57}]}
{"op":"mcm","clk":"4215875265","pt":1631545292112,"mc":[{"id":"1.187566733","rc":[{"batb":[[1,1.43,8.53],[2,1.35,14.08]],"ltp":1.45,"tv":1442.9,"id":9323645}]}]}
{"op":"mcm","clk":"4215877747","pt":1631545325394,"mc":[{"id":"1.187566733","rc":[{"trd":[[1.45,588.41]],"batl":[[0,1.45,450.84]],"ltp":1.45,"tv":1901.78,"id":9323645}],"tv":1932.45}]}
{"op":"mcm","clk":"4215880988","pt":1631545364143,"mc":[{"id":"1.187566733","rc":[{"batl":[[2,1000,0.01]],"ltp":3.0,"tv":30.67,"id":8734382}]}]}
{"op":"mcm","clk":"4215882330","pt":1631545381089,"mc":[{"id":"1.187566733","rc":[{"batb":[[2,1.23,85.6]],"ltp":1.45,"tv":1901.78,"id":9323645}]}]}
{"op":"mcm","clk":"4215883806","pt":1631545398773,"mc":[{"id":"1.187566733","rc":[{"batl":[[0,4.1,2.33]],"ltp":3.0,"tv":30.67,"id":8734382}]}]}
{"op":"mcm","clk":"4215884824","pt":1631545411804,"mc":[{"id":"1.187566733","rc":[{"batl":[[0,28,43.62]],"ltp":3.0,"tv":30.67,"id":8734382},{"batb":[[2,1.22,193.8]],"ltp":1.45,"tv":1901.78,"id":9323645}]}]}
{"op":"mcm","clk":"4215885995","pt":1631545426827,"mc":[{"id":"1.187566733","rc":[{"trd":[[1.45,1490.08]],"batb":[[0,1.45,423.14],[1,1.44,94.92],[2,1.43,8.53]],"batl":[[0,1.46,704.24],[1,1.53,2.09],[2,1.58,221.08]],"ltp":1.45,"tv":2803.46,"id":9323645}],"tv":2834.13}]}
{"op":"mcm","clk":"4215886100","pt":1631545428039,"mc":[{"id":"1.187566733","rc":[{"batl":[[0,3.95,117.78]],"ltp":3.0,"tv":30.67,"id":8734382}]}]}
{"op":"mcm","clk":"4215887816","pt":1631545451153,"mc":[{"id":"1.187566733","rc":[{"batb":[[1,1.44,99.18]],"ltp":1.45,"tv":2803.46,"id":9323645}]}]}
{"op":"mcm","clk":"4215890308","pt":1631545483528,"mc":[{"id":"1.187566733","rc":[{"batb":[[0,2.76,947.86]],"ltp":3.0,"tv":30.67,"id":8734382}]}]}
{"op":"mcm","clk":"4215890591","pt":1631545487224,"mc":[{"id":"1.187566733","rc":[{"batb":[[2,1.41,23.87]],"ltp":3.0,"tv":30.67,"id":8734382}]}]}
{"op":"mcm","clk":"4215891128","pt":1631545495011,"mc":[{"id":"1.187566733","rc":[{"trd":[[1.46,352.81]],"batl":[[0,1.46,642.08]],"ltp":1.46,"tv":2927.78,"id":9323645}],"tv":2958.45}]}
{"op":"mcm","clk":"4215904529","pt":1631545686414,"mc":[{"id":"1.187566733","rc":[{"batb":[[1,1.41,23.87],[2,1.4,767.39]],"ltp":3.0,"tv":30.67,"id":8734382}]}]}
{"op":"mcm","clk":"4215905026","pt":1631545693892,"mc":[{"id":"1.187566733","rc":[{"batb":[[0,3.15,3.18]],"ltp":3.0,"tv":30.67,"id":8734382}]}]}
{"op":"mcm","clk":"4215905101","pt":1631545694996,"mc":[{"id":"1.187566733","rc":[{"batb":[[1,2.62,25.78],[2,1.41,23.87]],"ltp":3.0,"tv":30.67,"id":8734382}]}]}
{"op":"mcm","clk":"4215906216","pt":1631545711943,"mc":[{"id":"1.187566733","rc":[{"batl":[[0,4.2,361.62]],"ltp":3.0,"tv":30.67,"id":8734382}]}]}
{"op":"mcm","clk":"4215939518","pt":1631546126913,"mc":[{"id":"1.187566733","rc":[{"batl":[[0,7.2,187.84]],"ltp":3.0,"tv":30.67,"id":8734382}]}]}
{"op":"mcm","clk":"4215946302","pt":1631546191965,"mc":[{"id":"1.187566733","rc":[{"trd":[[1.45,2336.36]],"batb":[[0,1.44,99.18],[1,1.43,8.53],[2,1.22,193.8]],"batl":[[0,1.45,723.57],[1,1.46,642.08],[2,1.53,2.09]],"ltp":1.45,"tv":3774.06,"id":9323645}],"tv":3804.73}]}
{"op":"mcm","clk":"4215946357","pt":1631546192590,"mc":[{"id":"1.187566733","rc":[{"batl":[[0,6.8,196.62]],"ltp":3.0,"tv":30.67,"id":8734382}]}]}
{"op":"mcm","clk":"4215946606","pt":1631546195096,"mc":[{"id":"1.187566733","rc":[{"batb":[[0,2.62,25.78],[1,1.41,23.87],[2,1.4,767.39]],"ltp":3.0,"tv":30.67,"id":8734382}]}]}
{"op":"mcm","clk":"4215946663","pt":1631546195672,"mc":[{"id":"1.187566733","rc":[{"batb":[[0,2.64,572.74],[1,2.62,25.78],[2,1.41,23.87]],"batl":[[0,4.1,10.3]],"ltp":3.0,"tv":30.67,"id":8734382},{"batb":[[2,1.35,28.03]],"ltp":1.45,"tv":3774.06,"id":9323645}]}]}
{"op":"mcm","clk":"4215947262","pt":1631546201495,"mc":[{"id":"1.187566733","rc":[{"batb":[[0,3.2,3.12]],"ltp":3.0,"tv":30.67,"id":8734382}]}]}
{"op":"mcm","clk":"4215948071","pt":1631546209205,"mc":[{"id":"1.187566733","rc":[{"batb":[[2,2.1,116.26]],"ltp":3.0,"tv":30.67,"id":8734382}]}]}
{"op":"mcm","clk":"4215956464","pt":1631546288991,"mc":[{"id":"1.187566733","rc":[{"batb":[[2,1.23,370.72]],"ltp":1.45,"tv":3774.06,"id":9323645}]}]}
{"op":"mcm","clk":"4215957776","pt":1631546301516,"mc":[{"id":"1.187566733","rc":[{"batl":[[0,15,91.12]],"ltp":3.0,"tv":30.67,"id":8734382}]}]}
{"op":"mcm","clk":"4215972985","pt":1631546458898,"mc":[{"id":"1.187566733","rc":[{"trd":[[1.45,2355.94]],"batl":[[0,1.45,713.78]],"ltp":1.45,"tv":3793.64,"id":9323645}],"tv":3824.31}]}
{"op":"mcm","clk":"4215987440","pt":1631546601586,"mc":[{"id":"1.187566733","rc":[{"batl":[[0,9,99.37]],"ltp":3.0,"tv":30.67,"id":8734382}]}]}
{"op":"mcm","clk":"4215991615","pt":1631546647973,"mc":[{"id":"1.187566733","rc":[{"batb":[[2,1.25,174.59]],"ltp":1.45,"tv":3793.64,"id":9323645}]}]}
{"op":"mcm","clk":"4216078953","pt":1631547801764,"mc":[{"id":"1.187566733","rc":[{"batl":[[0,7.4,165.16]],"ltp":3.0,"tv":30.67,"id":8734382}]}]}
{"op":"mcm","clk":"4216089498","pt":1631547923851,"mc":[{"id":"1.187566733","rc":[{"trd":[[1.45,2745.45]],"batl":[[0,1.45,519.03]],"ltp":1.45,"tv":4183.14,"id":9323645}],"tv":4213.81}]}
{"op":"mcm","clk":"4216106270","pt":1631548101638,"mc":[{"id":"1.187566733","rc":[{"batl":[[0,9.2,97.23]],"ltp":3.0,"tv":30.67,"id":8734382}]}]}
{"op":"mcm","clk":"4216110072","pt":1631548145301,"mc":[{"id":"1.187566733","rc":[{"trd":[[1.45,2925.51]],"batl":[[0,1.45,428.99]],"ltp":1.45,"tv":4363.21,"id":9323645}],"tv":4393.88}]}
{"op":"mcm","clk":"4216117821","pt":1631548226338,"mc":[{"id":"1.187566733","rc":[{"trd":[[1.44,198]],"batb":[[0,1.43,8.71],[1,1.25,174.59],[2,1.23,370.72]],"ltp":1.44,"tv":4561.21,"id":9323645}],"tv":4591.88}]}
{"op":"mcm","clk":"4216118142","pt":1631548229124,"mc":[{"id":"1.187566733","rc":[{"batb":[[1,1.36,116.02],[2,1.25,174.59]],"ltp":1.44,"tv":4561.21,"id":9323645}]}]}
{"op":"mcm","clk":"4216122427","pt":1631548274360,"mc":[{"id":"1.187566733","rc":[{"batl":[[0,1.45,458.98]],"ltp":1.44,"tv":4561.21,"id":9323645}]}]}
{"op":"mcm","clk":"4216122849","pt":1631548279572,"mc":[{"id":"1.187566733","rc":[{"batb":[[0,3.25,9.83],[1,3.2,3.12],[2,2.62,25.78]],"ltp":3.0,"tv":30.67,"id":8734382}]}]}
{"op":"mcm","clk":"4216123426","pt":1631548285570,"mc":[{"id":"1.187566733","rc":[{"batb":[[1,1.37,23.32],[2,1.36,116.02]],"ltp":1.44,"tv":4561.21,"id":9323645}]}]}
{"op":"mcm","clk":"4216123562","pt":1631548286784,"mc":[{"id":"1.187566733","rc":[{"batl":[[0,8.2,117.24]],"ltp":3.0,"tv":30.67,"id":8734382}]}]}
{"op":"mcm","clk":"4216124651","pt":1631548298918,"mc":[{"id":"1.187566733","rc":[{"batl":[[0,3.75,8.52]],"ltp":3.0,"tv":30.67,"id":8734382}]}]}
{"op":"mcm","clk":"4216125258","pt":1631548305420,"mc":[{"id":"1.187566733","rc":[{"batb":[[0,1.37,23.5],[1,1.36,116.02],[2,1.25,174.59]],"ltp":1.44,"tv":4561.21,"id":9323645}]}]}
{"op":"mcm","clk":"4216126348","pt":1631548318238,"mc":[{"id":"1.187566733","rc":[{"batb":[[0,1.38,4.44],[1,1.37,23.32],[2,1.36,116.02]],"ltp":1.44,"tv":4561.21,"id":9323645}]}]}
{"op":"mcm","clk":"4216135730","pt":1631548418453,"mc":[{"id":"1.187566733","rc":[{"batb":[[0,1.39,39.42],[1,1.38,4.26],[2,1.37,23.32]],"ltp":1.44,"tv":4561.21,"id":9323645}]}]}
{"op":"mcm","clk":"4216140674","pt":1631548472120,"mc":[{"id":"1.187566733","rc":[{"batb":[[2,1.36,116.02]],"ltp":1.44,"tv":4561.21,"id":9323645}]}]}
{"op":"mcm","clk":"4216140685","pt":1631548472219,"mc":[{"id":"1.187566733","rc":[{"batb":[[0,1.4,23.5],[1,1.39,39.24],[2,1.38,4.26]],"ltp":1.44,"tv":4561.21,"id":9323645}]}]}
{"op":"mcm","clk":"4216141018","pt":1631548476136,"mc":[{"id":"1.187566733","rc":[{"batl":[[0,990,2.2],[1,1000,0.01],[2,1000,0]],"ltp":3.0,"tv":30.67,"id":8734382}]}]}
{"op":"mcm","clk":"4216141082","pt":1631548476822,"mc":[{"id":"1.187566733","rc":[{"batl":[[0,6.6,144.16],[1,990,2.2],[2,1000,0.01]],"ltp":3.0,"tv":30.67,"id":8734382}]}]}
{"op":"mcm","clk":"4216141955","pt":1631548486146,"mc":[{"id":"1.187566733","rc":[{"batb":[[1,1.38,4.26],[2,1.36,116.02]],"ltp":1.44,"tv":4561.21,"id":9323645}]}]}
{"op":"mcm","clk":"4216142173","pt":1631548488140,"mc":[{"id":"1.187566733","rc":[{"batb":[[0,1.41,38.86],[1,1.4,23.32],[2,1.38,4.26]],"ltp":1.44,"tv":4561.21,"id":9323645}]}]}
{"op":"mcm","clk":"4216142269","pt":1631548489029,"mc":[{"id":"1.187566733","rc":[{"batl":[[0,14,68.07]],"ltp":3.0,"tv":30.67,"id":8734382}]}]}
{"op":"mcm","clk":"4216143358","pt":1631548500981,"mc":[{"id":"1.187566733","rc":[{"batb":[[2,3.15,5.95]],"ltp":3.0,"tv":30.67,"id":8734382},{"batb":[[2,1.38,37.92]],"ltp":1.44,"tv":4561.21,"id":9323645}]}]}
{"op":"mcm","clk":"4216143426","pt":1631548501556,"mc":[{"id":"1.187566733","rc":[{"batl":[[0,8.6,170.84]],"ltp":3.0,"tv":30.67,"id":8734382}]}]}
{"op":"mcm","clk":"4216146804","pt":1631548541004,"mc":[{"id":"1.187566733","rc":[{"batl":[[0,6.6,202.61]],"ltp":3.0,"tv":30.67,"id":8734382},{"batb":[[0,1.42,23.5],[1,1.41,38.68]],"ltp":1.44,"tv":4561.21,"id":9323645}]}]}
{"op":"mcm","clk":"4216152351","pt":1631548603102,"mc":[{"id":"1.187566733","rc":[{"trd":[[1.45,3129.59]],"batl":[[0,1.45,356.94]],"ltp":1.45,"tv":4765.29,"id":9323645}],"tv":4795.96}]}
{"op":"mcm","clk":"4216152431","pt":1631548604012,"mc":[{"id":"1.187566733","rc":[{"batl":[[0,8.8,54.63]],"ltp":3.0,"tv":30.67,"id":8734382},{"batb":[[0,1.42,61.89],[1,1.38,37.92],[2,1.36,116.02]],"batl":[[0,1.45,361.97]],"ltp":1.45,"tv":4765.29,"id":9323645}]}]}
{"op":"mcm","clk":"4216152461","pt":1631548604279,"mc":[{"id":"1.187566733","rc":[{"batl":[[0,8.2,220.48]],"ltp":3.0,"tv":30.67,"id":8734382}]}]}
{"op":"mcm","clk":"4216170624","pt":1631548808708,"mc":[{"id":"1.187566733","rc":[{"batb":[[1,1.4,48.01],[2,1.38,37.92]],"ltp":1.45,"tv":4765.29,"id":9323645}]}]}
{"op":"mcm","clk":"4216173237","pt":1631548835559,"mc":[{"id":"1.187566733","rc":[{"trd":[[1.45,3182.02]],"batl":[[0,1.45,335.76]],"ltp":1.45,"tv":4817.72,"id":9323645}],"tv":4848.39}]}
{"op":"mcm","clk":"4216187375","pt":1631548980680,"mc":[{"id":"1.187566733","rc":[{"batl":[[2,1.53,2.61]],"ltp":1.45,"tv":4817.72,"id":9323645}]}]}
{"op":"mcm","clk":"4216195477","pt":1631549076501,"mc":[{"id":"1.187566733","rc":[{"batl":[[0,6.6,19.83]],"ltp":3.0,"tv":30.67,"id":8734382}]}]}
{"op":"mcm","clk":"4216221661","pt":1631549342961,"mc":[{"id":"1.187566733","rc":[{"batb":[[1,1.4,50.11]],"batl":[[2,1.47,2]],"ltp":1.45,"tv":4817.72,"id":9323645}]}]}
{"op":"mcm","clk":"4216234012","pt":1631549480641,"mc":[{"id":"1.187566733","rc":[{"trd":[[1.45,3362.78]],"batl":[[0,1.45,245.37]],"ltp":1.45,"tv":4998.47,"id":9323645}],"tv":5029.14}]}
{"op":"mcm","clk":"4216267006","pt":1631549827661,"mc":[{"id":"1.187566733","rc":[{"trd":[[1.45,3453.06]],"batl":[[0,1.45,200.22]],"ltp":1.45,"tv":5088.76,"id":9323645}],"tv":5119.43}]}
{"op":"mcm","clk":"4216268055","pt":1631549837459,"mc":[{"id":"1.187566733","rc":[{"trd":[[1.44,198.36]],"batb":[[0,1.42,61.71]],"batl":[[0,1.44,5.03],[1,1.45,200.22],[2,1.46,642.08]],"ltp":1.44,"tv":5089.12,"id":9323645}],"tv":5119.79}]}
{"op":"mcm","clk":"4216268766","pt":1631549843692,"mc":[{"id":"1.187566733","rc":[{"batl":[[1,1.45,170.24]],"ltp":1.44,"tv":5089.12,"id":9323645}]}]}
{"op":"mcm","clk":"4216286157","pt":1631549935150,"mc":[{"id":"1.187566733","rc":[{"batl":[[0,5.6,353.89]],"ltp":3.0,"tv":30.67,"id":8734382},{"batb":[[0,1.43,7.68],[1,1.42,61.71],[2,1.4,50.11]],"ltp":1.44,"tv":5089.12,"id":9323645}]}]}
{"op":"mcm","clk":"4216286191","pt":1631549935462,"mc":[{"id":"1.187566733","rc":[{"batl":[[0,5,539.88]],"ltp":3.0,"tv":30.67,"id":8734382}]}]}
{"op":"mcm","clk":"4216287934","pt":1631549953193,"mc":[{"id":"1.187566733","rc":[{"batl":[[0,4.7,408.03]],"ltp":3.0,"tv":30.67,"id":8734382},{"trd":[[1.44,208.42]],"batb":[[0,1.44,2.65]],"batl":[[0,1.45,165.21],[1,1.46,644.69],[2,1.47,2]],"ltp":1.44,"tv":5099.18,"id":9323645}],"tv":5129.85}]}
{"op":"mcm","clk":"4216287941","pt":1631549953293,"mc":[{"id":"1.187566733","rc":[{"batl":[[1,1.46,642.08],[2,1.47,4.61]],"ltp":1.44,"tv":5099.18,"id":9323645}]}]}
{"op":"mcm","clk":"4216288749","pt":1631549961980,"mc":[{"id":"1.187566733","rc":[{"batb":[[0,1.43,2.65]],"ltp":1.44,"tv":5099.18,"id":9323645}]}]}
{"op":"mcm","clk":"4216290002","pt":1631549976519,"mc":[{"id":"1.187566733","rc":[{"batl":[[0,6,17.23]],"ltp":3.0,"tv":30.67,"id":8734382}]}]}
{"op":"mcm","clk":"4216303798","pt":1631550120190,"mc":[{"id":"1.187566733","rc":[{"batb":[[1,1.42,23.32]],"ltp":1.44,"tv":5099.18,"id":9323645}]}]}
{"op":"mcm","clk":"4216304454","pt":1631550127084,"mc":[{"id":"1.187566733","rc":[{"batl":[[0,8.8,218.44]],"ltp":3.0,"tv":30.67,"id":8734382},{"batb":[[1,1.41,23.32]],"ltp":1.44,"tv":5099.18,"id":9323645}]}]}
{"op":"mcm","clk":"4216307050","pt":1631550153653,"mc":[{"id":"1.187566733","rc":[{"batl":[[0,1.44,25.72],[1,1.45,167.39],[2,1.46,642.08]],"ltp":1.44,"tv":5099.18,"id":9323645}]}]}
{"op":"mcm","clk":"4216307498","pt":1631550158922,"mc":[{"id":"1.187566733","rc":[{"batb":[[1,3.15,5.95],[2,2.62,25.78]],"ltp":3.0,"tv":30.67,"id":8734382}]}]}
{"op":"mcm","clk":"4216308034","pt":1631550165263,"mc":[{"id":"1.187566733","rc":[{"batb":[[0,3.25,12.91]],"ltp":3.0,"tv":30.67,"id":8734382}]}]}
{"op":"mcm","clk":"4216312923","pt":1631550217835,"mc":[{"id":"1.187566733","rc":[{"trd":[[1.44,211.83]],"batl":[[0,1.44,24.02]],"ltp":1.44,"tv":5102.59,"id":9323645}],"tv":5133.26}]}
{"op":"mcm","clk":"4216314106","pt":1631550230953,"mc":[{"id":"1.187566733","rc":[{"batb":[[1,1.41,1.74]],"ltp":1.44,"tv":5102.59,"id":9323645}]}]}
{"op":"mcm","clk":"4216317144","pt":1631550265327,"mc":[{"id":"1.187566733","rc":[{"batl":[[0,1.44,22.18]],"ltp":1.44,"tv":5102.59,"id":9323645}]}]}
{"op":"mcm","clk":"4216317375","pt":1631550268041,"mc":[{"id":"1.187566733","rc":[{"batb":[[0,3.25,9.83]],"ltp":3.0,"tv":30.67,"id":8734382}]}]}
{"op":"mcm","clk":"4216317888","pt":1631550274224,"mc":[{"id":"1.187566733","rc":[{"batb":[[1,3.2,3.12],[2,3.15,5.95]],"ltp":3.0,"tv":30.67,"id":8734382}]}]}
{"op":"mcm","clk":"4216318151","pt":1631550276540,"mc":[{"id":"1.187566733","rc":[{"batl":[[0,6.6,6.11]],"ltp":3.0,"tv":30.67,"id":8734382}]}]}
{"op":"mcm","clk":"4216323047","pt":1631550331145,"mc":[{"id":"1.187566733","rc":[{"trd":[[1.44,256.18]],"batb":[[0,1.44,23.34],[1,1.43,2.65],[2,1.41,1.74]],"batl":[[0,1.45,165.21],[1,1.46,642.08],[2,1.47,4.61]],"ltp":1.44,"tv":5146.94,"id":9323645}],"tv":5177.61}]}
{"op":"mcm","clk":"4216323118","pt":1631550331725,"mc":[{"id":"1.187566733","rc":[{"batb":[[0,3.2,3.12],[1,3.15,5.95],[2,1.41,23.87]],"batl":[[0,6,82.63]],"ltp":3.0,"tv":30.67,"id":8734382}]}]}
{"op":"mcm","clk":"4216323661","pt":1631550336855,"mc":[{"id":"1.187566733","rc":[{"batb":[[2,2.62,25.78]],"batl":[[0,5.4,306.61]],"ltp":3.0,"tv":30.67,"id":8734382}]}]}
{"op":"mcm","clk":"4216324914","pt":1631550349543,"mc":[{"id":"1.187566733","rc":[{"batb":[[0,1.44,45.52],[2,1.4,50.11]],"ltp":1.44,"tv":5146.94,"id":9323645}]}]}
{"op":"mcm","clk":"4216325074","pt":1631550351166,"mc":[{"id":"1.187566733","rc":[{"batb":[[1,3.05,6.24]],"batl":[[0,5.1,529.35]],"ltp":3.0,"tv":30.67,"id":8734382},{"batb":[[2,1.4,82.09]],"ltp":1.44,"tv":5146.94,"id":9323645}]}]}
{"op":"mcm","clk":"4216325384","pt":1631550354258,"mc":[{"id":"1.187566733","rc":[{"batb":[[1,1.43,6.92]],"ltp":1.44,"tv":5146.94,"id":9323645}]}]}
{"op":"mcm","clk":"4216333351","pt":1631550430188,"mc":[{"id":"1.187566733","rc":[{"batl":[[0,5,294.92]],"ltp":3.0,"tv":30.67,"id":8734382},{"batb":[[0,1.44,22.18]],"ltp":1.44,"tv":5146.94,"id":9323645}]}]}
{"op":"mcm","clk":"4216333402","pt":1631550430707,"mc":[{"id":"1.187566733","rc":[{"batb":[[1,3.15,5.95],[2,3.05,6.24]],"ltp":3.0,"tv":30.67,"id":8734382},{"batb":[[0,1.43,9.2],[1,1.41,22.18],[2,1.4,50.11]],"ltp":1.44,"tv":5146.94,"id":9323645}]}]}
{"op":"mcm","clk":"4216333503","pt":1631550431707,"mc":[{"id":"1.187566733","rc":[{"batb":[[1,3.05,6.24],[2,2.62,25.78]],"ltp":3.0,"tv":30.67,"id":8734382}]}]}
{"op":"mcm","clk":"4216333919","pt":1631550435696,"mc":[{"id":"1.187566733","rc":[{"trd":[[1.45,3499.25]],"batl":[[0,1.45,142.12]],"ltp":1.45,"tv":5193.12,"id":9323645}],"tv":5223.79}]}
{"op":"mcm","clk":"4216334022","pt":1631550436698,"mc":[{"id":"1.187566733","rc":[{"batb":[[1,3.1,6.09],[2,3.05,6.24]],"ltp":3.0,"tv":30.67,"id":8734382}]}]}
{"op":"mcm","clk":"4216335247","pt":1631550447729,"mc":[{"id":"1.187566733","rc":[{"batb":[[2,2.62,25.78]],"ltp":3.0,"tv":30.67,"id":8734382},{"batb":[[1,1.42,22.18]],"ltp":1.45,"tv":5193.12,"id":9323645}]}]}
{"op":"mcm","clk":"4216336307","pt":1631550457849,"mc":[{"id":"1.187566733","rc":[{"batb":[[0,1.43,7.7],[1,1.42,24.11]],"ltp":1.45,"tv":5193.12,"id":9323645}]}]}
{"op":"mcm","clk":"4216336439","pt":1631550459158,"mc":[{"id":"1.187566733","rc":[{"batl":[[0,1.45,158.16]],"ltp":1.45,"tv":5193.12,"id":9323645}]}]}
{"op":"mcm","clk":"4216336791","pt":1631550462551,"mc":[{"id":"1.187566733","rc":[{"batb":[[0,3.25,7.13],[1,3.2,3.12],[2,3.1,6.09]],"ltp":3.0,"tv":30.67,"id":8734382}]}]}
{"op":"mcm","clk":"4216336925","pt":1631550463752,"mc":[{"id":"1.187566733","rc":[{"batb":[[2,3.15,5.95]],"ltp":3.0,"tv":30.67,"id":8734382}]}]}
{"op":"mcm","clk":"4216338999","pt":1631550484695,"mc":[{"id":"1.187566733","rc":[{"batb":[[0,1.44,1.31],[1,1.43,6.92],[2,1.42,24.11]],"ltp":1.45,"tv":5193.12,"id":9323645}]}]}
{"op":"mcm","clk":"4216347837","pt":1631550576456,"mc":[{"id":"1.187566733","rc":[{"batl":[[0,6.8,4.62]],"ltp":3.0,"tv":30.67,"id":8734382}]}]}
{"op":"mcm","clk":"4216348798","pt":1631550587066,"mc":[{"id":"1.187566733","rc":[{"batb":[[0,3.2,3.12],[1,3.15,5.95],[2,3.1,6.09]],"ltp":3.0,"tv":30.67,"id":8734382},{"batb":[[2,1.42,1.93]],"batl":[[0,1.45,142.12]],"ltp":1.45,"tv":5193.12,"id":9323645}]}]}
{"op":"mcm","clk":"4216348856","pt":1631550587653,"mc":[{"id":"1.187566733","rc":[{"batl":[[0,5.7,256.1]],"ltp":3.0,"tv":30.67,"id":8734382}]}]}
{"op":"mcm","clk":"4216353665","pt":1631550639344,"mc":[{"id":"1.187566733","rc":[{"batb":[[0,3.25,7.13],[1,3.2,3.12],[2,3.15,5.95]],"ltp":3.0,"tv":30.67,"id":8734382},{"batb":[[2,1.42,24.42]],"batl":[[0,1.45,158.16]],"ltp":1.45,"tv":5193.12,"id":9323645}]}]}
{"op":"mcm","clk":"4216357441","pt":1631550681820,"mc":[{"id":"1.187566733","rc":[{"batb":[[1,1.43,5.05]],"ltp":1.45,"tv":5193.12,"id":9323645}]}]}
{"op":"mcm","clk":"4216365582","pt":1631550793048,"mc":[{"id":"1.187566733","rc":[{"batb":[[0,1.44,3.01]],"batl":[[1,1.46,643.88]],"ltp":1.45,"tv":5193.12,"id":9323645}]}]}
{"op":"mcm","clk":"4216368166","pt":1631550827967,"mc":[{"id":"1.187566733","rc":[{"trd":[[1.43,1.38],[1.44,258.8]],"batb":[[0,1.43,6.06],[1,1.42,22.49],[2,1.4,50.11]],"ltp":1.43,"tv":5197.12,"id":9323645}],"tv":5227.79}]}
{"op":"mcm","clk":"4216369103","pt":1631550840004,"mc":[{"id":"1.187566733","rc":[{"batb":[[1,1.41,22.49]],"ltp":1.43,"tv":5197.12,"id":9323645}]}]}
{"op":"mcm","clk":"4216369685","pt":1631550846420,"mc":[{"id":"1.187566733","rc":[{"trd":[[1.43,13.51]],"batb":[[0,1.41,22.49],[1,1.4,50.11],[2,1.39,7.11]],"batl":[[0,1.43,1.61],[1,1.45,158.16],[2,1.46,643.88]],"ltp":1.43,"tv":5209.25,"id":9323645}],"tv":5239.92}]}
{"op":"mcm","clk":"4216369812","pt":1631550847780,"mc":[{"id":"1.187566733","rc":[{"batb":[[0,1.41,24.46],[1,1.4,52.08]],"batl":[[0,1.43,6.61]],"ltp":1.43,"tv":5209.25,"id":9323645}]}]}
{"op":"mcm","clk":"4216369975","pt":1631550849707,"mc":[{"id":"1.187566733","rc":[{"batb":[[2,1.39,9.09]],"batl":[[0,1.43,5]],"ltp":1.43,"tv":5209.25,"id":9323645}]}]}
{"op":"mcm","clk":"4216370181","pt":1631550852113,"mc":[{"id":"1.187566733","rc":[{"trd":[[1.43,23.5],[1.45,3501.35]],"batl":[[0,1.45,157.11],[1,1.46,643.88],[2,1.47,4.61]],"ltp":1.45,"tv":5221.34,"id":9323645}],"tv":5252.01}]}
{"op":"mcm","clk":"4216370347","pt":1631550854108,"mc":[{"id":"1.187566733","rc":[{"batl":[[0,1.45,141.07]],"ltp":1.45,"tv":5221.34,"id":9323645}]}]}
{"op":"mcm","clk":"4216370379","pt":1631550854416,"mc":[{"id":"1.187566733","rc":[{"batl":[[0,1.44,16.04],[1,1.45,143.04],[2,1.46,643.88]],"ltp":1.45,"tv":5221.34,"id":9323645}]}]}
{"op":"mcm","clk":"4216385020","pt":1631551033020,"mc":[{"id":"1.187566733","rc":[{"batb":[[0,1.42,4.26],[1,1.41,24.46],[2,1.4,52.08]],"ltp":1.45,"tv":5221.34,"id":9323645}]}]}
{"op":"mcm","clk":"4216393330","pt":1631551144030,"mc":[{"id":"1.187566733","rc":[{"batb":[[0,3.2,3.12],[1,3.15,5.95],[2,3.1,7.51]],"ltp":3.0,"tv":30.67,"id":8734382},{"batl":[[0,1.45,143.04],[1,1.46,643.88],[2,1.47,4.61]],"ltp":1.45,"tv":5221.34,"id":9323645}]}]}
{"op":"mcm","clk":"4216396213","pt":1631551176495,"mc":[{"id":"1.187566733","rc":[{"batl":[[0,4.9,7.1]],"ltp":3.0,"tv":30.67,"id":8734382}]}]}
{"op":"mcm","clk":"4216399725","pt":1631551224682,"mc":[{"id":"1.187566733","rc":[{"trd":[[3.2,5.14]],"batb":[[0,3.15,6.5],[1,3.1,7.51],[2,2.62,25.78]],"ltp":3.2,"tv":35.81,"id":8734382}],"tv":5257.15}]}
{"op":"mcm","clk":"4216407207","pt":1631551321642,"mc":[{"id":"1.187566733","rc":[{"batb":[[0,1.43,11.47],[1,1.42,6.1],[2,1.41,24.46]],"ltp":1.45,"tv":5221.34,"id":9323645}]}]}
{"op":"mcm","clk":"4216407316","pt":1631551323133,"mc":[{"id":"1.187566733","rc":[{"batb":[[0,3.1,8.06],[1,2.62,25.78],[2,1.41,23.87]],"batl":[[0,4.4,523.68]],"ltp":3.2,"tv":35.81,"id":8734382}]}]}
{"op":"mcm","clk":"4216408039","pt":1631551331960,"mc":[{"id":"1.187566733","rc":[{"batb":[[0,1.43,33.96],[2,1.41,1.97]],"ltp":1.45,"tv":5221.34,"id":9323645}]}]}
{"op":"mcm","clk":"4216408111","pt":1631551332750,"mc":[{"id":"1.187566733","rc":[{"batl":[[0,7,400.23]],"ltp":3.2,"tv":35.81,"id":8734382}]}]}
{"op":"mcm","clk":"4216419124","pt":1631551476518,"mc":[{"id":"1.187566733","rc":[{"batl":[[0,7,3.84]],"ltp":3.2,"tv":35.81,"id":8734382}]}]}
{"op":"mcm","clk":"4216421332","pt":1631551503449,"mc":[{"id":"1.187566733","rc":[{"batb":[[1,2.8,83.33],[2,2.62,25.78]],"ltp":3.2,"tv":35.81,"id":8734382}]}]}
{"op":"mcm","clk":"4216425273","pt":1631551557732,"mc":[{"id":"1.187566733","rc":[{"trd":[[1.45,3572.97]],"batl":[[0,1.45,107.23]],"ltp":1.45,"tv":5292.97,"id":9323645}],"tv":5328.78}]}
{"op":"mcm","clk":"4216428500","pt":1631551606092,"mc":[{"id":"1.187566733","marketDefinition":{"bspMarket":false,"turnInPlayEnabled":true,"persistenceEnabled":true,"marketBaseRate":5.0,"eventId":"30896763","eventTypeId":"2","numberOfWinners":1,"bettingType":"ODDS","marketType":"MATCH_ODDS","marketTime":"2021-09-13T16:50:00.000Z","suspendTime":"2021-09-13T16:50:00.000Z","bspReconciled":false,"complete":true,"inPlay":false,"crossMatching":true,"runnersVoidable":false,"numberOfActiveRunners":2,"betDelay":0,"status":"OPEN","runners":[{"status":"ACTIVE","sortPriority":1,"id":9323645,"name":"Alexis Galarneau"},{"status":"ACTIVE","sortPriority":2,"id":8734382,"name":"Alexander Sarkissian"}],"regulators":["MR_INT"],"countryCode":"US","discountAllowed":true,"timezone":"UTC","openDate":"2021-09-13T16:55:00.000Z","version":4030942181,"name":"Match Odds","eventName":"Galarneau v Sarkissian"}}]}
{"op":"mcm","clk":"4216428661","pt":1631551608105,"mc":[{"id":"1.187566733","marketDefinition":{"bspMarket":false,"turnInPlayEnabled":true,"persistenceEnabled":true,"marketBaseRate":5.0,"eventId":"30896763","eventTypeId":"2","numberOfWinners":1,"bettingType":"ODDS","marketType":"MATCH_ODDS","marketTime":"2021-09-13T16:50:00.000Z","suspendTime":"2021-09-13T16:50:00.000Z","bspReconciled":false,"complete":true,"inPlay":false,"crossMatching":true,"runnersVoidable":false,"numberOfActiveRunners":2,"betDelay":0,"status":"OPEN","runners":[{"status":"ACTIVE","sortPriority":1,"id":9323645,"name":"Alexis Galarneau"},{"status":"ACTIVE","sortPriority":2,"id":8734382,"name":"Alexander Sarkissian"}],"regulators":["MR_INT"],"countryCode":"US","discountAllowed":true,"timezone":"UTC","openDate":"2021-09-13T16:50:00.000Z","version":4030942181,"name":"Match Odds","eventName":"Galarneau v Sarkissian"}}]}
{"op":"mcm","clk":"4216428688","pt":1631551608297,"mc":[{"id":"1.187566733","rc":[{"batl":[[0,990,2.2],[1,1000,0.01],[2,1000,0]],"ltp":3.2,"tv":35.81,"id":8734382}]}]}
{"op":"mcm","clk":"4216428904","pt":1631551611082,"mc":[{"id":"1.187566733","rc":[{"batl":[[0,6.8,411.82],[1,990,2.2],[2,1000,0.01]],"ltp":3.2,"tv":35.81,"id":8734382}]}]}
{"op":"mcm","clk":"4216437744","pt":1631551740165,"mc":[{"id":"1.187566733","rc":[{"batb":[[0,1.43,36.63]],"ltp":1.45,"tv":5292.97,"id":9323645}]}]}
{"op":"mcm","clk":"4216437808","pt":1631551741061,"mc":[{"id":"1.187566733","rc":[{"batb":[[0,3.2,6.37],[1,3.1,136.66],[2,2.8,83.33]],"batl":[[0,5.8,251.74]],"ltp":3.2,"tv":35.81,"id":8734382},{"trd":[[1.43,96.75]],"batb":[[0,1.42,4.26],[1,1.4,50.11],[2,1.39,7.11]],"batl":[[0,1.43,536.74],[1,1.45,105.26],[2,1.46,642.08]],"ltp":1.43,"tv":5366.21,"id":9323645}],"tv":5402.02}]}
{"op":"mcm","clk":"4216437998","pt":1631551743890,"mc":[{"id":"1.187566733","rc":[{"batb":[[1,1.41,1.59],[2,1.4,50.11]],"ltp":1.43,"tv":5366.21,"id":9323645}]}]}
{"op":"mcm","clk":"4216441804","pt":1631551796153,"mc":[{"id":"1.187566733","rc":[{"batb":[[1,3.1,7.51]],"batl":[[0,3.5,2]],"ltp":3.2,"tv":35.81,"id":8734382},{"batl":[[0,1.43,538.74]],"ltp":1.43,"tv":5366.21,"id":9323645}]}]}
{"op":"mcm","clk":"4216442648","pt":1631551806368,"mc":[{"id":"1.187566733","rc":[{"trd":[[1.42,0.2]],"batb":[[0,1.42,4.16]],"ltp":1.42,"tv":5366.42,"id":9323645}],"tv":5402.23}]}
{"op":"mcm","clk":"4216443872","pt":1631551824478,"mc":[{"id":"1.187566733","rc":[{"trd":[[1.42,5.2]],"batb":[[0,1.42,1.66]],"ltp":1.42,"tv":5371.41,"id":9323645}],"tv":5407.22}]}
{"op":"mcm","clk":"4216449400","pt":1631551905920,"mc":[{"id":"1.187566733","marketDefinition":{"bspMarket":false,"turnInPlayEnabled":true,"persistenceEnabled":true,"marketBaseRate":5.0,"eventId":"30896763","eventTypeId":"2","numberOfWinners":1,"bettingType":"ODDS","marketType":"MATCH_ODDS","marketTime":"2021-09-13T17:05:00.000Z","suspendTime":"2021-09-13T17:05:00.000Z","bspReconciled":false,"complete":true,"inPlay":false,"crossMatching":true,"runnersVoidable":false,"numberOfActiveRunners":2,"betDelay":0,"status":"OPEN","runners":[{"status":"ACTIVE","sortPriority":1,"id":9323645,"name":"Alexis Galarneau"},{"status":"ACTIVE","sortPriority":2,"id":8734382,"name":"Alexander Sarkissian"}],"regulators":["MR_INT"],"countryCode":"US","discountAllowed":true,"timezone":"UTC","openDate":"2021-09-13T16:50:00.000Z","version":4030949816,"name":"Match Odds","eventName":"Galarneau v Sarkissian"},"rc":[{"batb":[[2,1.4,54.63]],"ltp":1.42,"tv":5371.41,"id":9323645}]}]}
{"op":"mcm","clk":"4216449572","pt":1631551908772,"mc":[{"id":"1.187566733","marketDefinition":{"bspMarket":false,"turnInPlayEnabled":true,"persistenceEnabled":true,"marketBaseRate":5.0,"eventId":"30896763","eventTypeId":"2","numberOfWinners":1,"bettingType":"ODDS","marketType":"MATCH_ODDS","marketTime":"2021-09-13T17:05:00.000Z","suspendTime":"2021-09-13T17:05:00.000Z","bspReconciled":false,"complete":true,"inPlay":false,"crossMatching":true,"runnersVoidable":false,"numberOfActiveRunners":2,"betDelay":0,"status":"OPEN","runners":[{"status":"ACTIVE","sortPriority":1,"id":9323645,"name":"Alexis Galarneau"},{"status":"ACTIVE","sortPriority":2,"id":8734382,"name":"Alexander Sarkissian"}],"regulators":["MR_INT"],"countryCode":"US","discountAllowed":true,"timezone":"UTC","openDate":"2021-09-13T17:05:00.000Z","version":4030949816,"name":"Match Odds","eventName":"Galarneau v Sarkissian"}}]}
{"op":"mcm","clk":"4216462178","pt":1631552082040,"mc":[{"id":"1.187566733","rc":[{"trd":[[1.43,100.16]],"batl":[[0,1.43,537.03]],"ltp":1.43,"tv":5374.82,"id":9323645}],"tv":5410.63}]}
{"op":"mcm","clk":"4216463907","pt":1631552106107,"mc":[{"id":"1.187566733","rc":[{"batb":[[0,1.42,214.83]],"ltp":1.43,"tv":5374.82,"id":9323645}]}]}
{"op":"mcm","clk":"4216464002","pt":1631552107205,"mc":[{"id":"1.187566733","rc":[{"batb":[[0,3.15,6.5]],"ltp":3.2,"tv":35.81,"id":8734382},{"batb":[[1,1.41,7.36]],"ltp":1.43,"tv":5374.82,"id":9323645}]}]}
{"op":"mcm","clk":"4216464156","pt":1631552108880,"mc":[{"id":"1.187566733","rc":[{"batb":[[2,1.4,159.04]],"ltp":1.43,"tv":5374.82,"id":9323645}]}]}
{"op":"mcm","clk":"4216464443","pt":1631552113212,"mc":[{"id":"1.187566733","rc":[{"batb":[[1,1.41,5.77]],"ltp":1.43,"tv":5374.82,"id":9323645}]}]}
{"op":"mcm","clk":"4216464689","pt":1631552116181,"mc":[{"id":"1.187566733","rc":[{"batb":[[1,3.1,1.42]],"ltp":3.2,"tv":35.81,"id":8734382},{"trd":[[1.43,526.5]],"batb":[[0,1.42,1.66]],"batl":[[0,1.43,323.86]],"ltp":1.43,"tv":5801.16,"id":9323645}],"tv":5836.97}]}
{"op":"mcm","clk":"4216464944","pt":1631552119199,"mc":[{"id":"1.187566733","rc":[{"batb":[[0,3.2,6.37],[1,3.15,5.95],[2,3.1,1.42]],"ltp":3.2,"tv":35.81,"id":8734382},{"batb":[[1,1.41,8.33]],"ltp":1.43,"tv":5801.16,"id":9323645}]}]}
{"op":"mcm","clk":"4216471692","pt":1631552206635,"mc":[{"id":"1.187566733","marketDefinition":{"bspMarket":false,"turnInPlayEnabled":true,"persistenceEnabled":true,"marketBaseRate":5.0,"eventId":"30896763","eventTypeId":"2","numberOfWinners":1,"bettingType":"ODDS","marketType":"MATCH_ODDS","marketTime":"2021-09-13T16:53:00.000Z","suspendTime":"2021-09-13T16:53:00.000Z","bspReconciled":false,"complete":true,"inPlay":false,"crossMatching":true,"runnersVoidable":false,"numberOfActiveRunners":2,"betDelay":0,"status":"OPEN","runners":[{"status":"ACTIVE","sortPriority":1,"id":9323645,"name":"Alexis Galarneau"},{"status":"ACTIVE","sortPriority":2,"id":8734382,"name":"Alexander Sarkissian"}],"regulators":["MR_INT"],"countryCode":"US","discountAllowed":true,"timezone":"UTC","openDate":"2021-09-13T17:05:00.000Z","version":4030954357,"name":"Match Odds","eventName":"Galarneau v Sarkissian"},"rc":[{"batb":[[1,1.41,2.56],[2,1.4,154.52]],"ltp":1.43,"tv":5801.16,"id":9323645}]}]}
{"op":"mcm","clk":"4216471920","pt":1631552210013,"mc":[{"id":"1.187566733","rc":[{"trd":[[1.41,2.68],[1.42,8.52]],"batb":[[0,1.41,1.22],[1,1.4,154.52],[2,1.39,7.11]],"ltp":1.41,"tv":5807.16,"id":9323645}],"tv":5842.97}]}
{"op":"mcm","clk":"4216474092","pt":1631552238468,"mc":[{"id":"1.187566733","rc":[{"trd":[[1.43,1148.95]],"batl":[[0,1.43,12.63]],"ltp":1.43,"tv":6429.61,"id":9323645}],"tv":6465.42}]}
{"op":"mcm","clk":"4216474154","pt":1631552239250,"mc":[{"id":"1.187566733","rc":[{"batb":[[0,3.15,6.5],[1,3.1,1.42],[2,3.05,33.89]],"ltp":3.2,"tv":35.81,"id":8734382}]}]}
{"op":"mcm","clk":"4216474923","pt":1631552249614,"mc":[{"id":"1.187566733","marketDefinition":{"bspMarket":false,"turnInPlayEnabled":true,"persistenceEnabled":true,"marketBaseRate":5.0,"eventId":"30896763","eventTypeId":"2","numberOfWinners":1,"bettingType":"ODDS","marketType":"MATCH_ODDS","marketTime":"2021-09-13T16:53:00.000Z","suspendTime":"2021-09-13T16:53:00.000Z","bspReconciled":false,"complete":true,"inPlay":false,"crossMatching":true,"runnersVoidable":false,"numberOfActiveRunners":2,"betDelay":0,"status":"OPEN","runners":[{"status":"ACTIVE","sortPriority":1,"id":9323645,"name":"Alexis Galarneau"},{"status":"ACTIVE","sortPriority":2,"id":8734382,"name":"Alexander Sarkissian"}],"regulators":["MR_INT"],"countryCode":"US","discountAllowed":true,"timezone":"UTC","openDate":"2021-09-13T16:53:00.000Z","version":4030954357,"name":"Match Odds","eventName":"Galarneau v Sarkissian"}}]}
{"op":"mcm","clk":"4216475570","pt":1631552258714,"mc":[{"id":"1.187566733","rc":[{"batl":[[0,1.43,585.99]],"ltp":1.43,"tv":6429.61,"id":9323645}]}]}
{"op":"mcm","clk":"4216475615","pt":1631552259289,"mc":[{"id":"1.187566733","rc":[{"batb":[[0,3.2,6.37],[1,3.15,5.95],[2,3.1,1.42]],"ltp":3.2,"tv":35.81,"id":8734382}]}]}
{"op":"mcm","clk":"4216478785","pt":1631552304136,"mc":[{"id":"1.187566733","rc":[{"trd":[[3.3,24]],"ltp":3.3,"tv":59.81,"id":8734382},{"trd":[[1.43,1204.31]],"batl":[[0,1.43,530.63]],"ltp":1.43,"tv":6484.97,"id":9323645}],"tv":6544.78}]}
{"op":"mcm","clk":"4216481115","pt":1631552338469,"mc":[{"id":"1.187566733","rc":[{"trd":[[1.43,1238.41]],"batl":[[0,1.43,513.57]],"ltp":1.43,"tv":6519.08,"id":9323645}],"tv":6578.89}]}
{"op":"mcm","clk":"4216483481","pt":1631552365721,"mc":[{"id":"1.187566733","rc":[{"trd":[[1.43,2127.38]],"batl":[[0,1.43,69.08]],"ltp":1.43,"tv":7408.04,"id":9323645}],"tv":7467.85}]}
{"op":"mcm","clk":"4216493729","pt":1631552473442,"mc":[{"id":"1.187566733","rc":[{"trd":[[3.2,5.14]],"batb":[[0,3.2,6.37],[1,3.15,5.96]],"ltp":3.3,"tv":59.81,"id":8734382},{"trd":[[1.41,2.68],[1.42,8.52],[1.43,2129.11],[1.44,258.84],[1.45,3576.1],[1.46,353],[1.47,336.36],[1.48,494.29],[1.49,90.67],[1.5,164.08]],"batb":[[0,1.41,1.22],[1,1.4,50.17]],"batl":[[0,1.43,69.14],[1,1.45,105.34],[2,1.46,642.59]],"ltp":1.43,"tv":7413.63,"id":9323645}],"tv":7473.45}]}
{"op":"mcm","clk":"4216494141","pt":1631552477962,"mc":[{"id":"1.187566733","marketDefinition":{"bspMarket":false,"turnInPlayEnabled":true,"persistenceEnabled":true,"marketBaseRate":5.0,"eventId":"30896763","eventTypeId":"2","numberOfWinners":1,"bettingType":"ODDS","marketType":"MATCH_ODDS","marketTime":"2021-09-13T16:53:00.000Z","suspendTime":"2021-09-13T16:53:00.000Z","bspReconciled":false,"complete":true,"inPlay":false,"crossMatching":true,"runnersVoidable":false,"numberOfActiveRunners":2,"betDelay":0,"status":"SUSPENDED","runners":[{"status":"ACTIVE","sortPriority":1,"id":9323645,"name":"Alexis Galarneau"},{"status":"ACTIVE","sortPriority":2,"id":8734382,"name":"Alexander Sarkissian"}],"regulators":["MR_INT"],"countryCode":"US","discountAllowed":true,"timezone":"UTC","openDate":"2021-09-13T16:53:00.000Z","version":4030973529,"name":"Match Odds","eventName":"Galarneau v Sarkissian"}}]}
{"op":"mcm","clk":"4216494181","pt":1631552478297,"mc":[{"id":"1.187566733","marketDefinition":{"bspMarket":false,"turnInPlayEnabled":true,"persistenceEnabled":true,"marketBaseRate":5.0,"eventId":"30896763","eventTypeId":"2","numberOfWinners":1,"bettingType":"ODDS","marketType":"MATCH_ODDS","marketTime":"2021-09-13T16:53:00.000Z","suspendTime":"2021-09-13T16:53:00.000Z","bspReconciled":false,"complete":true,"inPlay":true,"crossMatching":true,"runnersVoidable":false,"numberOfActiveRunners":2,"betDelay":3,"status":"OPEN","runners":[{"status":"ACTIVE","sortPriority":1,"id":9323645,"name":"Alexis Galarneau"},{"status":"ACTIVE","sortPriority":2,"id":8734382,"name":"Alexander Sarkissian"}],"regulators":["MR_INT"],"countryCode":"US","discountAllowed":true,"timezone":"UTC","openDate":"2021-09-13T16:53:00.000Z","version":4030973695,"name":"Match Odds","eventName":"Galarneau v Sarkissian"},"rc":[{"batb":[[0,1.01,98.87],[1,3.15,0],[2,3.1,0]],"ltp":3.3,"tv":59.81,"id":8734382},{"batb":[[1,1.4,2.1],[2,1.01,98.87]],"batl":[[0,1.47,2],[1,1.48,8.53],[2,1.5,10.79]],"ltp":1.43,"tv":7413.63,"id":9323645}]}]}
{"op":"mcm","clk":"4216495418","pt":1631552491168,"mc":[{"id":"1.187566733","rc":[{"trd":[[1.01,43.36],[1.4,4.2],[1.41,5.12]],"batb":[[0,1.01,77.2],[1,1.4,0],[2,1.01,0]],"ltp":1.01,"tv":7463.63,"id":9323645}],"tv":7523.44}]}
{"op":"mcm","clk":"4216495536","pt":1631552492435,"mc":[{"id":"1.187566733","rc":[{"batb":[[0,3,122.83],[1,1.01,98.87]],"ltp":3.3,"tv":59.81,"id":8734382},{"trd":[[1.45,3687.52],[1.46,377.88]],"batb":[[0,1.45,250.54],[1,1.01,77.2]],"batl":[[1,1.48,20.23],[2,1.5,256.45]],"ltp":1.45,"tv":7599.92,"id":9323645}],"tv":7659.74}]}
{"op":"mcm","clk":"4216495628","pt":1631552493553,"mc":[{"id":"1.187566733","rc":[{"trd":[[3.25,29.12]],"batb":[[1,2.98,36.25],[2,1.01,98.87]],"ltp":3.25,"tv":88.93,"id":8734382},{"trd":[[1.45,3752.79]],"batb":[[0,1.45,185.27],[1,1.33,99.02],[2,1.31,106.49]],"ltp":1.45,"tv":7665.19,"id":9323645}],"tv":7754.13}]}
{"op":"mcm","clk":"4216495998","pt":1631552497594,"mc":[{"id":"1.187566733","rc":[{"trd":[[1.45,3996.95]],"batb":[[0,1.45,63.19]],"ltp":1.45,"tv":7909.35,"id":9323645}],"tv":7998.29}]}
{"op":"mcm","clk":"4216496309","pt":1631552500566,"mc":[{"id":"1.187566733","rc":[{"batb":[[0,1.45,83.73]],"batl":[[0,1.47,22.26]],"ltp":1.45,"tv":7909.35,"id":9323645}]}]}
{"op":"mcm","clk":"4216496523","pt":1631552502673,"mc":[{"id":"1.187566733","rc":[{"batb":[[0,2.98,36.25],[1,1.01,98.87],[2,1.01,0]],"ltp":3.25,"tv":88.93,"id":8734382},{"batb":[[0,1.31,106.49],[1,1.01,77.2],[2,1.31,0]],"batl":[[0,1.47,2],[1,1.48,8.53],[2,1.5,10.79]],"ltp":1.45,"tv":7909.35,"id":9323645}]}]}
{"op":"mcm","clk":"4216496927","pt":1631552505879,"mc":[{"id":"1.187566733","rc":[{"batb":[[0,2.96,37.43]],"ltp":3.25,"tv":88.93,"id":8734382},{"batb":[[0,1.01,77.2],[1,1.01,0]],"ltp":1.45,"tv":7909.35,"id":9323645}]}]}
{"op":"mcm","clk":"4216497679","pt":1631552513318,"mc":[{"id":"1.187566733","rc":[{"batb":[[0,1.01,5]],"ltp":1.45,"tv":7909.35,"id":9323645}]}]}
{"op":"mcm","clk":"4216499145","pt":1631552525937,"mc":[{"id":"1.187566733","rc":[{"trd":[[1.01,53.36]],"batl":[[0,1.01,15.6],[1,1.47,2],[2,1.48,8.53]],"ltp":1.01,"tv":7919.35,"id":9323645}],"tv":8008.29}]}
{"op":"mcm","clk":"4216499198","pt":1631552526311,"mc":[{"id":"1.187566733","rc":[{"batb":[[1,1.6,768.05],[2,1.01,98.87]],"ltp":3.25,"tv":88.93,"id":8734382},{"trd":[[1.01,84.56]],"batb":[[0,1.05,752.45]],"batl":[[0,1.47,2],[1,1.48,8.53],[2,1.5,10.79]],"ltp":1.01,"tv":7950.55,"id":9323645}],"tv":8039.49}]}
{"op":"mcm","clk":"4216499874","pt":1631552532526,"mc":[{"id":"1.187566733","rc":[{"batb":[[0,3.1,433.38],[1,2.96,37.43],[2,1.6,768.05]],"batl":[[0,3.5,114.28]],"ltp":3.25,"tv":88.93,"id":8734382},{"batb":[[0,1.42,12.35],[1,1.4,285.71],[2,1.05,752.45]],"batl":[[0,1.44,14.95],[1,1.47,2],[2,1.48,8.53]],"ltp":1.01,"tv":7950.55,"id":9323645}]}]}
{"op":"mcm","clk":"4216499986","pt":1631552533619,"mc":[{"id":"1.187566733","rc":[{"batb":[[0,3.3,27.19],[1,3.1,465.44]],"ltp":3.25,"tv":88.93,"id":8734382},{"batb":[[2,1.33,103.98]],"ltp":1.01,"tv":7950.55,"id":9323645}]}]}
{"op":"mcm","clk":"4216500376","pt":1631552537547,"mc":[{"id":"1.187566733","rc":[{"trd":[[1.4,129.42],[1.42,33.22]],"batb":[[0,1.4,223.1],[1,1.33,103.98],[2,1.31,111.28]],"ltp":1.4,"tv":8100.47,"id":9323645}],"tv":8189.41}]}
{"op":"mcm","clk":"4216500671","pt":1631552540536,"mc":[{"id":"1.187566733","rc":[{"batb":[[0,1.4,244.4]],"batl":[[0,1.44,35.66]],"ltp":1.4,"tv":8100.47,"id":9323645}]}]}
{"op":"mcm","clk":"4216500784","pt":1631552541744,"mc":[{"id":"1.187566733","rc":[{"batl":[[0,1.42,1.71],[1,1.44,35.66],[2,1.47,2]],"ltp":1.4,"tv":8100.47,"id":9323645}]}]}
{"op":"mcm","clk":"4216500919","pt":1631552543126,"mc":[{"id":"1.187566733","rc":[{"batl":[[0,3.5,117.55]],"ltp":3.25,"tv":88.93,"id":8734382},{"batl":[[2,1.47,50.5]],"ltp":1.4,"tv":8100.47,"id":9323645}]}]}
{"op":"mcm","clk":"4216501081","pt":1631552544853,"mc":[{"id":"1.187566733","rc":[{"batl":[[1,1.43,25],[2,1.44,35.66]],"ltp":1.4,"tv":8100.47,"id":9323645}]}]}
{"op":"mcm","clk":"4216501204","pt":1631552546158,"mc":[{"id":"1.187566733","rc":[{"batl":[[1,3.6,3.36]],"ltp":3.25,"tv":88.93,"id":8734382},{"batb":[[1,1.39,60.91],[2,1.33,103.98]],"ltp":1.4,"tv":8100.47,"id":9323645}]}]}
{"op":"mcm","clk":"4216501246","pt":1631552546633,"mc":[{"id":"1.187566733","rc":[{"batb":[[1,1.33,103.98],[2,1.31,111.28]],"ltp":1.4,"tv":8100.47,"id":9323645}]}]}
{"op":"mcm","clk":"4216501348","pt":1631552547568,"mc":[{"id":"1.187566733","rc":[{"batl":[[2,1.44,20.71]],"ltp":1.4,"tv":8100.47,"id":9323645}]}]}
{"op":"mcm","clk":"4216501449","pt":1631552548663,"mc":[{"id":"1.187566733","rc":[{"batb":[[0,3.1,32.06],[1,1.6,768.05],[2,1.01,98.87]],"batl":[[0,3.6,3.36],[1,3.6,0]],"ltp":3.25,"tv":88.93,"id":8734382},{"batb":[[0,1.31,111.28],[1,1.05,752.45],[2,1.31,0]],"batl":[[1,1.47,2],[2,1.48,8.53]],"ltp":1.4,"tv":8100.47,"id":9323645}]}]}
{"op":"mcm","clk":"4216501589","pt":1631552550074,"mc":[{"id":"1.187566733","rc":[{"batb":[[1,3,5],[2,1.6,768.05]],"ltp":3.25,"tv":88.93,"id":8734382},{"batb":[[0,1.39,62.91],[1,1.31,111.28],[2,1.05,752.45]],"ltp":1.4,"tv":8100.47,"id":9323645}]}]}
{"op":"mcm","clk":"4216502088","pt":1631552555045,"mc":[{"id":"1.187566733","rc":[{"batb":[[0,3.35,21.87],[1,3.1,32.06],[2,3,5]],"batl":[[0,3.45,20.5],[1,3.6,3.36]],"ltp":3.25,"tv":88.93,"id":8734382},{"batl":[[0,1.42,21.46]],"ltp":1.4,"tv":8100.47,"id":9323645}]}]}
{"op":"mcm","clk":"4216502145","pt":1631552555673,"mc":[{"id":"1.187566733","rc":[{"batb":[[0,3.1,32.06],[1,3,5],[2,1.6,768.05]],"batl":[[0,3.6,3.36],[1,3.6,0]],"ltp":3.25,"tv":88.93,"id":8734382},{"batl":[[0,1.42,1.71]],"ltp":1.4,"tv":8100.47,"id":9323645}]}]}
{"op":"mcm","clk":"4216502881","pt":1631552563063,"mc":[{"id":"1.187566733","rc":[{"trd":[[1.42,36.64]],"batb":[[0,1.43,110.41],[1,1.42,116.84],[2,1.39,62.91]],"batl":[[0,1.47,2],[1,1.48,8.53],[2,1.49,52.5]],"ltp":1.42,"tv":8103.89,"id":9323645}],"tv":8192.83}]}
{"op":"mcm","clk":"4216503070","pt":1631552565061,"mc":[{"id":"1.187566733","rc":[{"batl":[[2,1.5,10.79]],"ltp":1.42,"tv":8103.89,"id":9323645}]}]}
{"op":"mcm","clk":"4216503388","pt":1631552568057,"mc":[{"id":"1.187566733","rc":[{"trd":[[1.39,14.82],[1.42,270.32],[1.43,2349.93]],"batb":[[0,1.39,67.21],[1,1.38,483.64],[2,1.31,111.28]],"batl":[[0,1.41,18.45],[1,1.43,471.4],[2,1.47,101.69]],"ltp":1.39,"tv":8573.21,"id":9323645}],"tv":8662.15}]}
{"op":"mcm","clk":"4216503487","pt":1631552568996,"mc":[{"id":"1.187566733","rc":[{"batb":[[0,3.45,24.84],[1,3.3,28.11],[2,3,5]],"batl":[[1,4.7,2.13]],"ltp":3.25,"tv":88.93,"id":8734382}]}]}
{"op":"mcm","clk":"4216503675","pt":1631552571201,"mc":[{"id":"1.187566733","rc":[{"trd":[[3.45,24.84]],"batb":[[0,3.3,28.11],[1,3,5],[2,1.6,768.05]],"ltp":3.45,"tv":113.77,"id":8734382},{"trd":[[1.41,102.8]],"batb":[[0,1.42,23.58],[1,1.41,121.68],[2,1.39,67.21]],"batl":[[0,1.43,471.4],[1,1.46,172.73]],"ltp":1.41,"tv":8670.89,"id":9323645}],"tv":8784.67}]}
{"op":"mcm","clk":"4216503775","pt":1631552572200,"mc":[{"id":"1.187566733","rc":[{"batb":[[0,1.41,121.68],[1,1.39,97.63],[2,1.38,483.64]],"batl":[[0,1.42,29.77],[1,1.43,471.4],[2,1.46,103.4]],"ltp":1.41,"tv":8670.89,"id":9323645}]}]}
{"op":"mcm","clk":"4216503854","pt":1631552572988,"mc":[{"id":"1.187566733","rc":[{"trd":[[1.41,295.34]],"batb":[[0,1.41,25.41]],"ltp":1.41,"tv":8863.43,"id":9323645}],"tv":8977.21}]}
{"op":"mcm","clk":"4216503898","pt":1631552573506,"mc":[{"id":"1.187566733","rc":[{"trd":[[1.41,346.16]],"batb":[[0,1.39,97.63],[1,1.38,483.64],[2,1.31,111.28]],"batl":[[0,1.41,106.59],[1,1.42,29.77],[2,1.43,471.4]],"ltp":1.41,"tv":8914.25,"id":9323645}],"tv":9028.03}]}
{"op":"mcm","clk":"4216504034","pt":1631552574786,"mc":[{"id":"1.187566733","rc":[{"batb":[[1,3.25,4.05],[2,3,5]],"batl":[[1,3.65,3.1],[2,4.7,2.13]],"ltp":3.45,"tv":113.77,"id":8734382},{"trd":[[1.41,465.78]],"batb":[[0,1.4,164.01],[1,1.39,97.63],[2,1.38,546.6]],"batl":[[0,1.41,46.78],[2,1.43,507.77]],"ltp":1.41,"tv":9033.87,"id":9323645}],"tv":9147.65}]}
{"op":"mcm","clk":"4216504185","pt":1631552576194,"mc":[{"id":"1.187566733","rc":[{"batb":[[2,3.2,3.47]],"batl":[[0,3.5,2.97],[1,3.6,3.36],[2,3.65,3.1]],"ltp":3.45,"tv":113.77,"id":8734382},{"trd":[[1.41,551.92]],"batb":[[0,1.4,227.17]],"batl":[[0,1.41,3.71]],"ltp":1.41,"tv":9120.01,"id":9323645}],"tv":9233.79}]}
{"op":"mcm","clk":"4216504300","pt":1631552577197,"mc":[{"id":"1.187566733","rc":[{"trd":[[1.41,574.66]],"batl":[[0,1.41,35.34]],"ltp":1.41,"tv":9142.75,"id":9323645}],"tv":9256.53}]}
{"op":"mcm","clk":"4216504411","pt":1631552578196,"mc":[{"id":"1.187566733","rc":[{"trd":[[1.41,628.18]],"batl":[[0,1.42,29.77],[1,1.43,507.77],[2,1.44,155.61]],"ltp":1.41,"tv":9196.27,"id":9323645}],"tv":9310.05}]}
{"op":"mcm","clk":"4216504541","pt":1631552579195,"mc":[{"id":"1.187566733","rc":[{"trd":[[1.41,725.9]],"batl":[[0,1.41,36.36],[1,1.42,29.77],[2,1.43,507.77]],"ltp":1.41,"tv":9293.99,"id":9323645}],"tv":9407.77}]}
{"op":"mcm","clk":"4216504668","pt":1631552580187,"mc":[{"id":"1.187566733","rc":[{"batb":[[2,1.6,768.05]],"batl":[[0,3.6,3.36],[1,3.6,0],[2,3.65,0]],"ltp":3.45,"tv":113.77,"id":8734382},{"batb":[[0,1.39,55.5],[1,1.3,116.82],[2,1.05,752.45]],"batl":[[1,1.44,52.33],[2,1.47,2]],"ltp":1.41,"tv":9293.99,"id":9323645}]}]}
{"op":"mcm","clk":"4216504717","pt":1631552580609,"mc":[{"id":"1.187566733","rc":[{"batl":[[0,1.44,52.33],[1,1.47,2],[2,1.48,8.53]],"ltp":1.41,"tv":9293.99,"id":9323645}]}]}
{"op":"mcm","clk":"4216505011","pt":1631552583114,"mc":[{"id":"1.187566733","rc":[{"batb":[[1,3.25,33]],"ltp":3.45,"tv":113.77,"id":8734382}]}]}
{"op":"mcm","clk":"4216505092","pt":1631552583902,"mc":[{"id":"1.187566733","rc":[{"batb":[[0,3.25,33],[1,1.6,768.05],[2,1.01,98.87]],"ltp":3.45,"tv":113.77,"id":8734382},{"batb":[[0,1.39,134.3],[1,1.38,136.06],[2,1.3,116.82]],"batl":[[1,1.47,107.24],[2,1.48,107.46]],"ltp":1.41,"tv":9293.99,"id":9323645}]}]}
{"op":"mcm","clk":"4216505118","pt":1631552584213,"mc":[{"id":"1.187566733","rc":[{"batl":[[1,1.47,2],[2,1.48,8.53]],"ltp":1.41,"tv":9293.99,"id":9323645}]}]}
{"op":"mcm","clk":"4216505423","pt":1631552587009,"mc":[{"id":"1.187566733","rc":[{"batb":[[0,3.45,8.7],[1,3.4,4.34],[2,3.35,6.34]],"batl":[[0,3.6,9.37],[1,3.75,210.16]],"ltp":3.45,"tv":113.77,"id":8734382},{"trd":[[1.39,29.86]],"batb":[[0,1.39,126.78]],"batl":[[0,1.41,22.51],[1,1.42,790.05],[2,1.43,114.12]],"ltp":1.39,"tv":9309.03,"id":9323645}],"tv":9422.81}]}
{"op":"mcm","clk":"4216505528","pt":1631552588112,"mc":[{"id":"1.187566733","rc":[{"batb":[[0,3.5,23.92],[1,3.45,8.7],[2,3.4,4.34]],"batl":[[2,4.8,2.08]],"ltp":3.45,"tv":113.77,"id":8734382},{"batb":[[2,1.31,114.38]],"ltp":1.39,"tv":9309.03,"id":9323645}]}]}
{"op":"mcm","clk":"4216505777","pt":1631552591030,"mc":[{"id":"1.187566733","rc":[{"batb":[[0,1.39,181.38]],"batl":[[0,1.41,76.33]],"ltp":1.39,"tv":9309.03,"id":9323645}]}]}
{"op":"mcm","clk":"4216505867","pt":1631552591926,"mc":[{"id":"1.187566733","rc":[{"trd":[[1.39,90.68]],"batb":[[0,1.39,150.97]],"ltp":1.39,"tv":9369.85,"id":9323645}],"tv":9483.63}]}
{"op":"mcm","clk":"4216506112","pt":1631552594304,"mc":[{"id":"1.187566733","rc":[{"batl":[[0,1.4,209],[1,1.41,76.33],[2,1.42,790.05]],"ltp":1.39,"tv":9369.85,"id":9323645}]}]}
{"op":"mcm","clk":"4216506449","pt":1631552597506,"mc":[{"id":"1.187566733","rc":[{"batb":[[1,1.38,194.12]],"batl":[[0,1.4,266.23]],"ltp":1.39,"tv":9369.85,"id":9323645}]}]}
{"op":"mcm","clk":"4216507275","pt":1631552605128,"mc":[{"id":"1.187566733","rc":[{"trd":[[1.38,98.06],[1.39,392.62]],"batb":[[0,1.38,145.09],[1,1.31,114.38],[2,1.26,136.29]],"ltp":1.38,"tv":9769.85,"id":9323645}],"tv":9883.63}]}
{"op":"mcm","clk":"4216507426","pt":1631552606637,"mc":[{"id":"1.187566733","rc":[{"batl":[[0,1.39,14.45],[1,1.4,266.23],[2,1.41,76.33]],"ltp":1.38,"tv":9769.85,"id":9323645}]}]}
{"op":"mcm","clk":"4216507615","pt":1631552608535,"mc":[{"id":"1.187566733","rc":[{"batb":[[0,1.38,203.39],[1,1.37,142.34],[2,1.31,114.38]],"batl":[[2,1.41,152.86]],"ltp":1.38,"tv":9769.85,"id":9323645}]}]}
{"op":"mcm","clk":"4216508060","pt":1631552612732,"mc":[{"id":"1.187566733","rc":[{"batl":[[0,1.4,266.23],[1,1.41,152.86],[2,1.42,790.05]],"ltp":1.38,"tv":9769.85,"id":9323645}]}]}
{"op":"mcm","clk":"4216508356","pt":1631552615834,"mc":[{"id":"1.187566733","rc":[{"trd":[[1.38,126.96]],"batb":[[0,1.38,188.94]],"ltp":1.38,"tv":9798.76,"id":9323645}],"tv":9912.53}]}
{"op":"mcm","clk":"4216509249","pt":1631552624546,"mc":[{"id":"1.187566733","rc":[{"batb":[[0,1.31,114.38],[1,1.26,136.29],[2,1.05,752.45]],"batl":[[1,1.41,76.33],[2,1.42,663.37]],"ltp":1.38,"tv":9798.76,"id":9323645}]}]}
{"op":"mcm","clk":"4216509610","pt":1631552627960,"mc":[{"id":"1.187566733","rc":[{"batb":[[0,1.33,103.59],[1,1.32,186.89],[2,1.31,114.38]],"batl":[[0,1.39,60.72],[1,1.4,266.23],[2,1.41,76.33]],"ltp":1.38,"tv":9798.76,"id":9323645}]}]}
{"op":"mcm","clk":"4216509936","pt":1631552631163,"mc":[{"id":"1.187566733","rc":[{"batb":[[0,1.34,16],[1,1.33,608.01],[2,1.32,186.89]],"ltp":1.38,"tv":9798.76,"id":9323645}]}]}
{"op":"mcm","clk":"4216510747","pt":1631552639183,"mc":[{"id":"1.187566733","rc":[{"trd":[[1.39,394.2]],"batb":[[1,1.33,103.59]],"batl":[[0,1.39,59.93]],"ltp":1.39,"tv":9800.33,"id":9323645}],"tv":9914.11}]}
{"op":"mcm","clk":"4216510985","pt":1631552641664,"mc":[{"id":"1.187566733","rc":[{"batb":[[0,3.3,28.03],[1,3.25,4.05],[2,1.6,768.05]],"ltp":3.45,"tv":113.77,"id":8734382},{"batb":[[0,1.33,103.59],[1,1.32,171.01],[2,1.26,136.29]],"batl":[[0,1.4,209],[1,1.44,52.33],[2,1.46,150.66]],"ltp":1.39,"tv":9800.33,"id":9323645}]}]}
{"op":"mcm","clk":"4216511095","pt":1631552642662,"mc":[{"id":"1.187566733","rc":[{"batb":[[1,1.6,768.05],[2,1.01,98.87]],"ltp":3.45,"tv":113.77,"id":8734382},{"batl":[[0,1.46,150.66],[1,1.47,104],[2,1.48,8.53]],"ltp":1.39,"tv":9800.33,"id":9323645}]}]}
{"op":"mcm","clk":"4216511327","pt":1631552644769,"mc":[{"id":"1.187566733","rc":[{"batb":[[1,3.15,3.63],[2,1.6,768.05]],"batl":[[0,4.2,2.78]],"ltp":3.45,"tv":113.77,"id":8734382},{"batb":[[0,1.32,92.14],[1,1.26,136.29],[2,1.05,752.45]],"batl":[[0,1.46,55.75],[1,1.47,2]],"ltp":1.39,"tv":9800.33,"id":9323645}]}]}
{"op":"mcm","clk":"4216511588","pt":1631552647191,"mc":[{"id":"1.187566733","rc":[{"batl":[[0,1.43,395.21],[1,1.46,55.75],[2,1.47,2]],"ltp":1.39,"tv":9800.33,"id":9323645}]}]}
{"op":"mcm","clk":"4216511687","pt":1631552648185,"mc":[{"id":"1.187566733","rc":[{"batl":[[0,3.95,2.9],[1,4.2,2.78]],"ltp":3.45,"tv":113.77,"id":8734382},{"batb":[[0,1.37,126.45],[1,1.36,147.35],[2,1.34,73.22]],"batl":[[0,1.4,106.33],[1,1.41,122.39],[2,1.46,55.75]],"ltp":1.39,"tv":9800.33,"id":9323645}]}]}
{"op":"mcm","clk":"4216511802","pt":1631552649290,"mc":[{"id":"1.187566733","rc":[{"batb":[[1,3.25,3.69],[2,3.15,3.63]],"ltp":3.45,"tv":113.77,"id":8734382},{"batl":[[2,1.44,63.58]],"ltp":1.39,"tv":9800.33,"id":9323645}]}]}
{"op":"mcm","clk":"4216512182","pt":1631552652814,"mc":[{"id":"1.187566733","rc":[{"batb":[[1,3.15,3.63],[2,1.6,768.05]],"batl":[[0,4.2,2.78],[1,4.2,0]],"ltp":3.45,"tv":113.77,"id":8734382},{"batb":[[0,1.32,92.14],[1,1.26,136.29],[2,1.05,752.45]],"batl":[[0,1.46,55.75],[1,1.47,2],[2,1.48,8.53]],"ltp":1.39,"tv":9800.33,"id":9323645}]}]}
{"op":"mcm","clk":"4216512542","pt":1631552656121,"mc":[{"id":"1.187566733","rc":[{"batb":[[1,3.25,3.93],[2,3.15,3.63]],"batl":[[0,3.95,2.9],[1,4.2,2.78]],"ltp":3.45,"tv":113.77,"id":8734382},{"batb":[[0,1.34,70.22],[1,1.33,103.59],[2,1.32,263.15]],"batl":[[0,1.44,54.58],[1,1.46,206.41],[2,1.47,104]],"ltp":1.39,"tv":9800.33,"id":9323645}]}]}
{"op":"mcm","clk":"4216512566","pt":1631552656381,"mc":[{"id":"1.187566733","rc":[{"batb":[[1,3.15,3.63],[2,1.6,768.05]],"batl":[[0,4.2,2.78],[1,4.2,0]],"ltp":3.45,"tv":113.77,"id":8734382},{"batb":[[0,1.33,103.59],[1,1.32,263.15],[2,1.26,136.29]],"batl":[[0,1.46,206.41],[1,1.47,104],[2,1.48,8.53]],"ltp":1.39,"tv":9800.33,"id":9323645}]}]}
{"op":"mcm","clk":"4216512806","pt":1631552659012,"mc":[{"id":"1.187566733","rc":[{"batl":[[0,1.47,2],[1,1.48,8.53],[2,1.5,10.79]],"ltp":1.39,"tv":9800.33,"id":9323645}]}]}
{"op":"mcm","clk":"4216513096","pt":1631552661915,"mc":[{"id":"1.187566733","rc":[{"batb":[[0,3.8,7.9],[1,3.75,57.28],[2,3.7,8.06]],"ltp":3.45,"tv":113.77,"id":8734382},{"trd":[[1.33,15.5]],"batb":[[0,1.33,112.65],[2,1.31,566.34]],"batl":[[0,1.35,19.89],[1,1.36,728.1],[2,1.37,172.25]],"ltp":1.33,"tv":9815.83,"id":9323645}],"tv":9929.61}]}
{"op":"mcm","clk":"4216513229","pt":1631552663017,"mc":[{"id":"1.187566733","rc":[{"batb":[[0,3.85,37.93],[1,3.8,7.9],[2,3.75,57.28]],"ltp":3.45,"tv":113.77,"id":8734382}]}]}
{"op":"mcm","clk":"4216513662","pt":1631552667006,"mc":[{"id":"1.187566733","rc":[{"trd":[[1.33,124.68]],"batb":[[0,1.33,16.81]],"ltp":1.33,"tv":9925.01,"id":9323645}],"tv":10038.79}]}
{"op":"mcm","clk":"4216513859","pt":1631552669005,"mc":[{"id":"1.187566733","rc":[{"batl":[[1,4.6,2.11],[2,4.9,2.45]],"ltp":3.45,"tv":113.77,"id":8734382}]}]}
{"op":"mcm","clk":"4216513965","pt":1631552669903,"mc":[{"id":"1.187566733","rc":[{"batb":[[1,1.32,375.89],[2,1.31,746.94]],"batl":[[0,1.35,193.89],[1,1.36,833.33]],"ltp":1.33,"tv":9925.01,"id":9323645}]}]}
{"op":"mcm","clk":"4216514423","pt":1631552674197,"mc":[{"id":"1.187566733","rc":[{"batb":[[1,3.7,4.12],[2,3.55,22.91]],"ltp":3.45,"tv":113.77,"id":8734382},{"batb":[[0,1.32,375.89],[1,1.31,180.6],[2,1.28,104.41]],"batl":[[0,1.35,174],[1,1.36,287.14]],"ltp":1.33,"tv":9925.01,"id":9323645}]}]}
{"op":"mcm","clk":"4216514524","pt":1631552675141,"mc":[{"id":"1.187566733","rc":[{"batb":[[0,3.55,22.91],[1,3.35,3.27],[2,1.6,768.05]],"batl":[[0,4.9,2.45],[1,4.6,0],[2,4.9,0]],"ltp":3.45,"tv":113.77,"id":8734382},{"trd":[[1.32,400]],"batb":[[0,1.32,12.7],[1,1.26,100.98],[2,1.22,168.34]],"batl":[[0,1.42,57.25],[1,1.47,2],[2,1.48,8.53]],"ltp":1.32,"tv":10325.01,"id":9323645}],"tv":10438.79}]}
{"op":"mcm","clk":"4216514917","pt":1631552679348,"mc":[{"id":"1.187566733","rc":[{"batb":[[1,1.27,91.43],[2,1.26,325.26]],"batl":[[0,1.39,106.71],[1,1.4,127.94],[2,1.42,57.25]],"ltp":1.32,"tv":10325.01,"id":9323645}]}]}
{"op":"mcm","clk":"4216515173","pt":1631552682023,"mc":[{"id":"1.187566733","rc":[{"batb":[[1,3.5,4.08],[2,3.35,3.27]],"ltp":3.45,"tv":113.77,"id":8734382},{"batl":[[1,1.4,192.08]],"ltp":1.32,"tv":10325.01,"id":9323645}]}]}
{"op":"mcm","clk":"4216515230","pt":1631552682601,"mc":[{"id":"1.187566733","rc":[{"batb":[[1,1.26,100.98],[2,1.22,168.34]],"ltp":1.32,"tv":10325.01,"id":9323645}]}]}
{"op":"mcm","clk":"4216515611","pt":1631552686197,"mc":[{"id":"1.187566733","rc":[{"batb":[[1,3.5,97.56],[2,3.35,30.29]],"batl":[[0,3.7,5.84],[1,3.85,168.1],[2,4,10]],"ltp":3.45,"tv":113.77,"id":8734382},{"batb":[[0,1.36,144.3],[1,1.35,154.84],[2,1.32,12.7]],"batl":[[0,1.39,122.28],[1,1.4,425.77]],"ltp":1.32,"tv":10325.01,"id":9323645}]}]}
{"op":"mcm","clk":"4216515642","pt":1631552686618,"mc":[{"id":"1.187566733","rc":[{"trd":[[3.7,2.81]],"batl":[[0,3.7,3.03]],"ltp":3.7,"tv":116.58,"id":8734382},{"trd":[[1.37,7.58]],"ltp":1.37,"tv":10332.59,"id":9323645}],"tv":10449.18}]}
{"op":"mcm","clk":"4216516088","pt":1631552690842,"mc":[{"id":"1.187566733","rc":[{"trd":[[3.7,5.84]],"batl":[[0,3.85,168.1],[1,4,10],[2,4.9,4.49]],"ltp":3.7,"tv":119.61,"id":8734382},{"trd":[[1.36,89.92],[1.37,15.76]],"batb":[[0,1.36,99.34]],"ltp":1.36,"tv":10430.69,"id":9323645}],"tv":10550.31}]}
{"op":"mcm","clk":"4216516166","pt":1631552691632,"mc":[{"id":"1.187566733","rc":[{"batb":[[0,1.36,136.37]],"batl":[[0,1.39,197.65]],"ltp":1.36,"tv":10430.69,"id":9323645}]}]}
{"op":"mcm","clk":"4216516284","pt":1631552692733,"mc":[{"id":"1.187566733","rc":[{"batl":[[2,4.2,2.78]],"ltp":3.7,"tv":119.61,"id":8734382},{"batb":[[2,1.32,90.59]],"ltp":1.36,"tv":10430.69,"id":9323645}]}]}
{"op":"mcm","clk":"4216516438","pt":1631552694202,"mc":[{"id":"1.187566733","rc":[{"trd":[[1.36,176.96]],"batb":[[0,1.36,112.97]],"batl":[[0,1.38,249],[1,1.39,221.94],[2,1.4,425.77]],"ltp":1.36,"tv":10517.73,"id":9323645}],"tv":10637.35}]}
{"op":"mcm","clk":"4216516548","pt":1631552695160,"mc":[{"id":"1.187566733","rc":[{"trd":[[3.85,168.1]],"batl":[[0,4,10],[1,4.2,2.78],[2,4.4,2.64]],"ltp":3.85,"tv":287.71,"id":8734382},{"trd":[[1.35,789.08],[1.36,402.9]],"batb":[[0,1.32,90.59],[1,1.3,204.57],[2,1.26,100.98]],"batl":[[0,1.35,1856.51],[1,1.36,87.03],[2,1.38,249]],"ltp":1.35,"tv":11532.75,"id":9323645}],"tv":11820.47}]}
{"op":"mcm","clk":"4216516737","pt":1631552696946,"mc":[{"id":"1.187566733","rc":[{"trd":[[1.35,860.64]],"batl":[[0,1.35,1820.73],[2,1.38,323.85]],"ltp":1.35,"tv":11604.31,"id":9323645}],"tv":11892.03}]}
{"op":"mcm","clk":"4216516866","pt":1631552698147,"mc":[{"id":"1.187566733","rc":[{"batl":[[2,4.3,2.55]],"ltp":3.85,"tv":287.71,"id":8734382},{"trd":[[1.35,1145.9]],"batb":[[0,1.34,162.64],[1,1.32,90.59],[2,1.31,75.79]],"batl":[[0,1.35,1678.1],[2,1.37,75.49]],"ltp":1.35,"tv":11889.57,"id":9323645}],"tv":12177.29}]}
{"op":"mcm","clk":"4216516955","pt":1631552699043,"mc":[{"id":"1.187566733","rc":[{"batb":[[1,3.5,4.08]],"batl":[[0,4.2,2.78],[1,4.3,2.55],[2,4.4,2.64]],"ltp":3.85,"tv":287.71,"id":8734382}]}]}
{"op":"mcm","clk":"4216517042","pt":1631552700043,"mc":[{"id":"1.187566733","rc":[{"trd":[[3.85,172.26]],"batb":[[0,3.35,30.29],[1,3.25,4.13],[2,3.2,4.32]],"batl":[[0,4.8,2.17],[1,4.3,0],[2,4.4,0]],"ltp":3.85,"tv":291.87,"id":8734382},{"trd":[[1.35,1157.76]],"batb":[[0,1.32,12.7],[1,1.27,97.87],[2,1.25,146.61]],"batl":[[0,1.35,1743.45],[1,1.42,57.25],[2,1.44,57.33]],"ltp":1.35,"tv":11901.43,"id":9323645}],"tv":12193.31}]}
{"op":"mcm","clk":"4216517169","pt":1631552701161,"mc":[{"id":"1.187566733","rc":[{"batb":[[0,3.6,20.35],[1,3.35,30.29],[2,3.25,4.13]],"ltp":3.85,"tv":291.87,"id":8734382},{"batl":[[0,1.35,1666.24],[1,1.36,90.09],[2,1.42,57.25]],"ltp":1.35,"tv":11901.43,"id":9323645}]}]}
{"op":"mcm","clk":"4216517238","pt":1631552701748,"mc":[{"id":"1.187566733","rc":[{"batb":[[0,3.35,30.29],[1,3.25,4.13],[2,3.2,4.32]],"ltp":3.85,"tv":291.87,"id":8734382},{"batl":[[1,1.42,57.25],[2,1.44,57.33]],"ltp":1.35,"tv":11901.43,"id":9323645}]}]}
{"op":"mcm","clk":"4216517375","pt":1631552702909,"mc":[{"id":"1.187566733","rc":[{"batl":[[0,4.5,2.43],[1,4.8,2.17]],"ltp":3.85,"tv":291.87,"id":8734382},{"batb":[[1,1.29,236.29],[2,1.28,209.96]],"batl":[[1,1.42,193.55],[2,1.43,118.43]],"ltp":1.35,"tv":11901.43,"id":9323645}]}]}
{"op":"mcm","clk":"4216517420","pt":1631552703228,"mc":[{"id":"1.187566733","rc":[{"batl":[[0,4.8,2.17],[1,4.8,0]],"ltp":3.85,"tv":291.87,"id":8734382},{"batb":[[1,1.29,148.48]],"ltp":1.35,"tv":11901.43,"id":9323645}]}]}
{"op":"mcm","clk":"4216518227","pt":1631552710136,"mc":[{"id":"1.187566733","rc":[{"batb":[[0,3.35,27.02]],"batl":[[0,4.5,2.45],[1,4.8,2.17]],"ltp":3.85,"tv":291.87,"id":8734382},{"batb":[[1,1.29,224.29]],"batl":[[0,1.42,136.3],[1,1.43,118.43],[2,1.44,57.33]],"ltp":1.35,"tv":11901.43,"id":9323645}]}]}
{"op":"mcm","clk":"4216518238","pt":1631552710239,"mc":[{"id":"1.187566733","rc":[{"batl":[[0,4.8,2.17],[1,4.8,0]],"ltp":3.85,"tv":291.87,"id":8734382},{"batb":[[1,1.29,148.48]],"ltp":1.35,"tv":11901.43,"id":9323645}]}]}
{"op":"mcm","clk":"4216518542","pt":1631552713036,"mc":[{"id":"1.187566733","rc":[{"batb":[[1,1.27,97.87],[2,1.25,146.61]],"ltp":1.35,"tv":11901.43,"id":9323645}]}]}
{"op":"mcm","clk":"4216518895","pt":1631552716152,"mc":[{"id":"1.187566733","rc":[{"batb":[[0,3.4,7.32],[1,3.35,27.02],[2,3.25,4.13]],"batl":[[0,3.55,7.57],[1,3.7,253.94],[2,3.75,36.26]],"ltp":3.85,"tv":291.87,"id":8734382},{"batb":[[0,1.39,82.98],[1,1.38,2403.54],[2,1.32,12.7]],"batl":[[1,1.43,631.29],[2,1.44,151.77]],"ltp":1.35,"tv":11901.43,"id":9323645}]}]}
{"op":"mcm","clk":"4216519007","pt":1631552717150,"mc":[{"id":"1.187566733","rc":[{"trd":[[1.39,408.9]],"batb":[[0,1.39,75.63],[1,1.38,324.6],[2,1.33,104.56]],"ltp":1.39,"tv":11916.13,"id":9323645}],"tv":12208.01}]}
{"op":"mcm","clk":"4216519302","pt":1631552719956,"mc":[{"id":"1.187566733","rc":[{"batl":[[0,1.42,223.8]],"ltp":1.39,"tv":11916.13,"id":9323645}]}]}
{"op":"mcm","clk":"4216519668","pt":1631552723186,"mc":[{"id":"1.187566733","rc":[{"batb":[[2,3.3,3.38]],"ltp":3.85,"tv":291.87,"id":8734382},{"batb":[[2,1.36,66.68]],"batl":[[0,1.41,247],[1,1.42,223.8],[2,1.43,689.79]],"ltp":1.39,"tv":11916.13,"id":9323645}]}]}
{"op":"mcm","clk":"4216519953","pt":1631552726077,"mc":[{"id":"1.187566733","rc":[{"trd":[[3.55,7.57]],"batl":[[0,3.7,253.94],[1,3.75,36.26],[2,3.8,38.57]],"ltp":3.55,"tv":299.44,"id":8734382},{"trd":[[1.39,579.49]],"batb":[[0,1.38,324.6],[1,1.36,66.68],[2,1.34,70.22]],"batl":[[0,1.39,276.46],[1,1.41,247],[2,1.42,223.8]],"ltp":1.39,"tv":12086.73,"id":9323645}],"tv":12386.17}]}
{"op":"mcm","clk":"4216519983","pt":1631552726390,"mc":[{"id":"1.187566733","rc":[{"trd":[[1.38,526.96]],"batb":[[0,1.38,124.6]],"batl":[[1,1.41,333.01]],"ltp":1.38,"tv":12486.73,"id":9323645}],"tv":12786.17}]}
{"op":"mcm","clk":"4216520219","pt":1631552728979,"mc":[{"id":"1.187566733","rc":[{"batb":[[0,1.38,162.03],[1,1.37,147.51],[2,1.36,66.68]],"batl":[[0,1.4,90.01],[2,1.42,268.61]],"ltp":1.38,"tv":12486.73,"id":9323645}]}]}
{"op":"mcm","clk":"4216520300","pt":1631552729707,"mc":[{"id":"1.187566733","rc":[{"batl":[[2,1.42,277.44]],"ltp":1.38,"tv":12486.73,"id":9323645}]}]}
{"op":"mcm","clk":"4216520658","pt":1631552733017,"mc":[{"id":"1.187566733","rc":[{"batb":[[0,3.3,3.38],[1,3.25,4.13],[2,3.2,4.32]],"batl":[[0,3.9,3.05],[1,3.95,3.1],[2,4.1,2.95]],"ltp":3.55,"tv":299.44,"id":8734382},{"batb":[[0,1.35,67.67],[1,1.34,70.22],[2,1.33,73.53]],"batl":[[0,1.41,247],[1,1.43,58.5],[2,1.44,57.33]],"ltp":1.38,"tv":12486.73,"id":9323645}]}]}
{"op":"mcm","clk":"4216520741","pt":1631552733814,"mc":[{"id":"1.187566733","rc":[{"batb":[[0,3.2,4.32],[1,3.15,31.3],[2,1.6,768.05]],"batl":[[0,4.1,2.95],[1,4.8,2.17],[2,4.1,0]],"ltp":3.55,"tv":299.44,"id":8734382},{"batb":[[0,1.33,73.53],[1,1.32,12.7],[2,1.29,123.03]],"batl":[[0,1.45,55.1],[1,1.47,2],[2,1.48,8.53]],"ltp":1.38,"tv":12486.73,"id":9323645}]}]}
{"op":"mcm","clk":"4216520947","pt":1631552735870,"mc":[{"id":"1.187566733","rc":[{"batb":[[0,1.33,234.96],[1,1.32,190.8]],"batl":[[1,1.46,157.42],[2,1.47,107.45]],"ltp":1.38,"tv":12486.73,"id":9323645}]}]}
{"op":"mcm","clk":"4216521065","pt":1631552737071,"mc":[{"id":"1.187566733","rc":[{"batb":[[0,3.3,3.38],[1,3.2,4.32],[2,3.15,31.3]],"ltp":3.55,"tv":299.44,"id":8734382},{"batl":[[0,1.43,64.5],[1,1.45,55.1],[2,1.46,157.42]],"ltp":1.38,"tv":12486.73,"id":9323645}]}]}
{"op":"mcm","clk":"4216521161","pt":1631552738090,"mc":[{"id":"1.187566733","rc":[{"batb":[[0,3.2,4.32],[1,3.15,31.3],[2,1.6,768.05]],"ltp":3.55,"tv":299.44,"id":8734382},{"batb":[[0,1.33,73.53],[1,1.32,12.7]],"batl":[[0,1.45,55.1],[1,1.46,157.42],[2,1.47,107.45]],"ltp":1.38,"tv":12486.73,"id":9323645}]}]}
{"op":"mcm","clk":"4216521480","pt":1631552741205,"mc":[{"id":"1.187566733","rc":[{"batb":[[1,3.15,224.96],[2,3.1,43.88]],"batl":[[0,3.45,39.42],[1,3.5,38.26],[2,3.55,38.26]],"ltp":3.55,"tv":299.44,"id":8734382},{"batb":[[0,1.42,2297.98],[1,1.41,128.5],[2,1.38,1500.67]],"batl":[[0,1.44,16.41],[1,1.45,55.1],[2,1.46,157.42]],"ltp":1.38,"tv":12486.73,"id":9323645}]}]}
{"op":"mcm","clk":"4216521556","pt":1631552742197,"mc":[{"id":"1.187566733","rc":[{"trd":[[1.42,284.7]],"batb":[[0,1.42,321.5]],"ltp":1.42,"tv":12501.11,"id":9323645}],"tv":12800.55}]}
{"op":"mcm","clk":"4216521858","pt":1631552745087,"mc":[{"id":"1.187566733","rc":[{"batl":[[0,1.44,98.51]],"ltp":1.42,"tv":12501.11,"id":9323645}]}]}
{"op":"mcm","clk":"4216522150","pt":1631552747888,"mc":[{"id":"1.187566733","rc":[{"batb":[[1,3.15,228.79]],"ltp":3.55,"tv":299.44,"id":8734382},{"batb":[[2,1.39,61.91]],"batl":[[2,1.46,217.67]],"ltp":1.42,"tv":12501.11,"id":9323645}]}]}
{"op":"mcm","clk":"4216522193","pt":1631552748411,"mc":[{"id":"1.187566733","rc":[{"batl":[[0,1.44,223.51]],"ltp":1.42,"tv":12501.11,"id":9323645}]}]}
{"op":"mcm","clk":"4216522343","pt":1631552749981,"mc":[{"id":"1.187566733","rc":[{"trd":[[1.42,684.7]],"batb":[[0,1.42,121.5]],"ltp":1.42,"tv":12901.11,"id":9323645}],"tv":13200.55}]}
{"op":"mcm","clk":"4216522647","pt":1631552753088,"mc":[{"id":"1.187566733","rc":[{"batb":[[1,3.15,3.83],[2,3,34.99]],"batl":[[0,3.75,2.94],[1,4.8,2.17],[2,3.55,0]],"ltp":3.55,"tv":299.44,"id":8734382},{"batb":[[0,1.37,69.77],[1,1.33,104.56],[2,1.32,12.7]],"batl":[[0,1.44,125],[2,1.46,60.25]],"ltp":1.42,"tv":12901.11,"id":9323645}]}]}
{"op":"mcm","clk":"4216522701","pt":1631552753615,"mc":[{"id":"1.187566733","rc":[{"batb":[[0,3.15,3.83],[1,3,34.99],[2,1.6,768.05]],"ltp":3.55,"tv":299.44,"id":8734382},{"batl":[[0,1.46,60.25],[1,1.47,2],[2,1.48,8.53]],"ltp":1.42,"tv":12901.11,"id":9323645}]}]}
{"op":"mcm","clk":"4216522812","pt":1631552754722,"mc":[{"id":"1.187566733","rc":[{"batl":[[0,1.42,371.43],[1,1.46,60.25],[2,1.47,2]],"ltp":1.42,"tv":12901.11,"id":9323645}]}]}
{"op":"mcm","clk":"4216522927","pt":1631552755734,"mc":[{"id":"1.187566733","rc":[{"batb":[[0,1.38,151.61],[1,1.37,217.22],[2,1.33,104.56]],"ltp":1.42,"tv":12901.11,"id":9323645}]}]}
{"op":"mcm","clk":"4216523056","pt":1631552756899,"mc":[{"id":"1.187566733","rc":[{"batb":[[0,3.2,3.67],[1,3.15,3.83],[2,3,34.99]],"ltp":3.55,"tv":299.44,"id":8734382},{"batl":[[1,1.45,60.5],[2,1.46,60.25]],"ltp":1.42,"tv":12901.11,"id":9323645}]}]}
{"op":"mcm","clk":"4216523250","pt":1631552758990,"mc":[{"id":"1.187566733","rc":[{"batb":[[0,3.15,3.83],[1,3,34.99],[2,1.6,768.05]],"ltp":3.55,"tv":299.44,"id":8734382},{"batl":[[0,1.46,60.25],[1,1.47,2],[2,1.48,8.53]],"ltp":1.42,"tv":12901.11,"id":9323645}]}]}
{"op":"mcm","clk":"4216523357","pt":1631552760199,"mc":[{"id":"1.187566733","rc":[{"batb":[[0,1.37,69.77],[1,1.33,104.56],[2,1.32,12.7]],"ltp":1.42,"tv":12901.11,"id":9323645}]}]}
{"op":"mcm","clk":"4216523669","pt":1631552763105,"mc":[{"id":"1.187566733","rc":[{"batb":[[0,3.2,5],[1,3.15,3.83],[2,3,176.06]],"batl":[[0,3.3,170.51],[1,3.75,2.94],[2,4,2.5]],"ltp":3.55,"tv":299.44,"id":8734382},{"batb":[[0,1.44,104.16],[1,1.43,195.44],[2,1.42,52.08]],"ltp":1.42,"tv":12901.11,"id":9323645}]}]}
{"op":"mcm","clk":"4216523777","pt":1631552764110,"mc":[{"id":"1.187566733","rc":[{"batb":[[2,3,226.06]],"batl":[[0,3.3,6.87]],"ltp":3.55,"tv":299.44,"id":8734382},{"trd":[[1.45,4011.13]],"batb":[[0,1.45,95.2],[1,1.44,137.48],[2,1.43,150.98]],"ltp":1.45,"tv":12915.29,"id":9323645}],"tv":13214.73}]}
{"op":"mcm","clk":"4216523796","pt":1631552764321,"mc":[{"id":"1.187566733","rc":[{"batb":[[2,3,186.06]],"ltp":3.55,"tv":299.44,"id":8734382}]}]}
{"op":"mcm","clk":"4216524204","pt":1631552768014,"mc":[{"id":"1.187566733","rc":[{"trd":[[1.45,4018.45]],"batb":[[0,1.45,91.54]],"batl":[[1,1.47,79.21]],"ltp":1.45,"tv":12922.61,"id":9323645}],"tv":13222.05}]}
{"op":"mcm","clk":"4216524413","pt":1631552769927,"mc":[{"id":"1.187566733","rc":[{"batl":[[1,3.5,3.55],[2,3.65,2.9]],"ltp":3.55,"tv":299.44,"id":8734382}]}]}
{"op":"mcm","clk":"4216524508","pt":1631552770827,"mc":[{"id":"1.187566733","rc":[{"batl":[[0,1.46,245.25]],"ltp":1.45,"tv":12922.61,"id":9323645}]}]}
{"op":"mcm","clk":"4216524844","pt":1631552774035,"mc":[{"id":"1.187566733","rc":[{"batl":[[0,1.46,315.32]],"ltp":1.45,"tv":12922.61,"id":9323645}]}]}
{"op":"mcm","clk":"4216524901","pt":1631552774665,"mc":[{"id":"1.187566733","rc":[{"trd":[[1.44,475.76],[1.45,4201.53]],"batb":[[0,1.44,29.02],[1,1.43,150.98],[2,1.42,10.42]],"ltp":1.44,"tv":13322.61,"id":9323645}],"tv":13622.05}]}
{"op":"mcm","clk":"4216525212","pt":1631552778134,"mc":[{"id":"1.187566733","rc":[{"batb":[[0,1.44,114.36],[1,1.43,272.1]],"batl":[[2,1.48,172.79]],"ltp":1.44,"tv":13322.61,"id":9323645}]}]}
{"op":"mcm","clk":"4216527230","pt":1631552798084,"mc":[{"id":"1.187566733","rc":[{"batb":[[0,2.92,4.19],[1,2.84,4.72],[2,2.8,4.33]],"batl":[[0,3.5,3.55],[1,3.65,2.9],[2,3.75,2.94]],"ltp":3.55,"tv":299.44,"id":8734382},{"batb":[[0,1.4,54.71],[1,1.38,62.96],[2,1.37,69.77]],"batl":[[0,1.46,185],[1,1.47,2],[2,1.48,8.53]],"ltp":1.44,"tv":13322.61,"id":9323645}]}]}
{"op":"mcm","clk":"4216527293","pt":1631552798673,"mc":[{"id":"1.187566733","rc":[{"batb":[[0,2.8,4.33],[1,2.76,17.87],[2,1.6,768.05]],"batl":[[0,3.65,2.9],[1,3.65,0],[2,3.75,0]],"ltp":3.55,"tv":299.44,"id":8734382},{"batb":[[0,1.38,62.96],[1,1.36,95.08],[2,1.32,12.7]],"batl":[[0,1.47,2],[1,1.48,8.53],[2,1.5,10.79]],"ltp":1.44,"tv":13322.61,"id":9323645}]}]}
{"op":"mcm","clk":"4216527796","pt":1631552803490,"mc":[{"id":"1.187566733","rc":[{"batb":[[0,1.45,164.46],[1,1.44,117.74],[2,1.38,62.96]],"batl":[[2,1.49,105.59]],"ltp":1.44,"tv":13322.61,"id":9323645}]}]}
{"op":"mcm","clk":"4216527953","pt":1631552804966,"mc":[{"id":"1.187566733","rc":[{"batl":[[0,3.5,3.31],[1,3.65,2.9]],"ltp":3.55,"tv":299.44,"id":8734382},{"batb":[[2,1.4,62.26]],"ltp":1.44,"tv":13322.61,"id":9323645}]}]}
{"op":"mcm","clk":"4216528000","pt":1631552805492,"mc":[{"id":"1.187566733","rc":[{"batb":[[0,2.92,4.69],[1,2.8,4.33],[2,2.76,17.87]],"ltp":3.55,"tv":299.44,"id":8734382}]}]}
{"op":"mcm","clk":"4216528271","pt":1631552808174,"mc":[{"id":"1.187566733","rc":[{"batb":[[0,1.4,62.26],[1,1.38,62.96],[2,1.36,95.08]],"batl":[[0,1.47,69.37],[2,1.5,10.79]],"ltp":1.44,"tv":13322.61,"id":9323645}]}]}
{"op":"mcm","clk":"4216528293","pt":1631552808383,"mc":[{"id":"1.187566733","rc":[{"batb":[[0,2.8,4.33],[1,2.76,17.87],[2,1.6,768.05]],"batl":[[0,3.65,2.9],[1,3.65,0]],"ltp":3.55,"tv":299.44,"id":8734382},{"batb":[[0,1.38,62.96],[1,1.36,95.08],[2,1.32,12.7]],"batl":[[0,1.47,2]],"ltp":1.44,"tv":13322.61,"id":9323645}]}]}
{"op":"mcm","clk":"4216528535","pt":1631552811099,"mc":[{"id":"1.187566733","rc":[{"batb":[[0,1.4,135.12],[1,1.39,138.21],[2,1.38,62.96]],"ltp":1.44,"tv":13322.61,"id":9323645}]}]}
{"op":"mcm","clk":"4216528740","pt":1631552812993,"mc":[{"id":"1.187566733","rc":[{"batl":[[0,1.45,5],[1,1.47,2],[2,1.48,8.53]],"ltp":1.44,"tv":13322.61,"id":9323645}]}]}
{"op":"mcm","clk":"4216528990","pt":1631552815089,"mc":[{"id":"1.187566733","rc":[{"batb":[[0,2.92,4.19],[1,2.8,4.33],[2,2.76,17.87]],"batl":[[0,3.5,3.27],[1,3.65,2.9]],"ltp":3.55,"tv":299.44,"id":8734382},{"batb":[[0,1.4,205.48]],"ltp":1.44,"tv":13322.61,"id":9323645}]}]}
{"op":"mcm","clk":"4216529006","pt":1631552815299,"mc":[{"id":"1.187566733","rc":[{"batb":[[0,2.8,4.33],[1,2.76,17.87],[2,1.6,768.05]],"batl":[[0,3.65,2.9],[1,3.65,0]],"ltp":3.55,"tv":299.44,"id":8734382},{"batb":[[0,1.4,135.12]],"ltp":1.44,"tv":13322.61,"id":9323645}]}]}
{"op":"mcm","clk":"4216529680","pt":1631552821944,"mc":[{"id":"1.187566733","rc":[{"batb":[[0,2.92,4.94],[1,2.8,4.33],[2,2.76,17.87]],"batl":[[0,3.5,3.79],[1,3.65,2.9]],"ltp":3.55,"tv":299.44,"id":8734382},{"batb":[[0,1.4,189.48]],"ltp":1.44,"tv":13322.61,"id":9323645}]}]}
{"op":"mcm","clk":"4216529778","pt":1631552822693,"mc":[{"id":"1.187566733","rc":[{"batb":[[0,3.3,4.58],[1,3.2,198.16],[2,2.8,4.33]],"batl":[[0,3.5,110.48]],"ltp":3.55,"tv":299.44,"id":8734382},{"trd":[[1.4,143.92]],"batb":[[0,1.4,388.84]],"batl":[[0,1.42,14.87],[1,1.43,133.27],[2,1.44,127.09]],"ltp":1.4,"tv":13337.11,"id":9323645}],"tv":13636.55}]}
{"op":"mcm","clk":"4216529907","pt":1631552823947,"mc":[{"id":"1.187566733","rc":[{"batb":[[2,3.15,30.71]],"batl":[[2,4.3,2.33]],"ltp":3.55,"tv":299.44,"id":8734382},{"batb":[[2,1.38,84.7]],"ltp":1.4,"tv":13337.11,"id":9323645}]}]}
{"op":"mcm","clk":"4216530312","pt":1631552826803,"mc":[{"id":"1.187566733","rc":[{"trd":[[1.4,556.62]],"batb":[[0,1.4,182.49]],"batl":[[0,1.42,82.84]],"ltp":1.4,"tv":13749.81,"id":9323645}],"tv":14049.25}]}
{"op":"mcm","clk":"4216530678","pt":1631552829815,"mc":[{"id":"1.187566733","rc":[{"batb":[[1,3.2,202.23]],"batl":[[2,3.75,2.86]],"ltp":3.55,"tv":299.44,"id":8734382},{"batb":[[1,1.39,199.19],[2,1.38,229]],"batl":[[1,1.43,206.2]],"ltp":1.4,"tv":13749.81,"id":9323645}]}]}
{"op":"mcm","clk":"4216530771","pt":1631552830650,"mc":[{"id":"1.187566733","rc":[{"trd":[[3.5,7]],"batl":[[0,3.5,103.48]],"ltp":3.5,"tv":306.44,"id":8734382},{"trd":[[1.4,939.11]],"batb":[[0,1.39,199.19],[1,1.38,229],[2,1.37,77.65]],"batl":[[0,1.42,198.84]],"ltp":1.4,"tv":14132.3,"id":9323645}],"tv":14438.74}]}
{"op":"mcm","clk":"4216531185","pt":1631552834133,"mc":[{"id":"1.187566733","rc":[{"batl":[[0,1.41,64.68],[1,1.42,82.84],[2,1.43,206.2]],"ltp":1.4,"tv":14132.3,"id":9323645}]}]}
{"op":"mcm","clk":"4216531301","pt":1631552835138,"mc":[{"id":"1.187566733","rc":[{"batb":[[0,3.2,4.07],[1,3.15,30.71],[2,3.1,4.24]],"batl":[[0,3.65,2.9],[1,3.75,2.86],[2,3.75,0]],"ltp":3.5,"tv":306.44,"id":8734382},{"batb":[[1,1.38,207.26],[2,1.37,66.77]],"batl":[[1,1.42,67.97],[2,1.43,152.72]],"ltp":1.4,"tv":14132.3,"id":9323645}]}]}
{"op":"mcm","clk":"4216531375","pt":1631552835819,"mc":[{"id":"1.187566733","rc":[{"batb":[[0,3.1,4.24],[1,2.92,38.44],[2,1.6,768.05]],"batl":[[0,3.75,2.86],[1,3.75,0]],"ltp":3.5,"tv":306.44,"id":8734382},{"batb":[[0,1.37,66.77],[1,1.34,102.72],[2,1.32,12.7]],"batl":[[0,1.45,5],[1,1.47,55.5],[2,1.48,8.53]],"ltp":1.4,"tv":14132.3,"id":9323645}]}]}
{"op":"mcm","clk":"4216531620","pt":1631552838134,"mc":[{"id":"1.187566733","rc":[{"batb":[[0,3.15,4.23],[1,3.1,4.24],[2,2.92,38.44]],"ltp":3.5,"tv":306.44,"id":8734382},{"batb":[[0,1.42,40],[1,1.37,66.77],[2,1.34,102.72]],"batl":[[1,1.46,61.75],[2,1.47,55.5]],"ltp":1.4,"tv":14132.3,"id":9323645}]}]}
{"op":"mcm","clk":"4216531710","pt":1631552839038,"mc":[{"id":"1.187566733","rc":[{"batb":[[0,3.2,3.52],[1,3.15,4.23],[2,3.1,4.24]],"batl":[[0,3.65,3.5],[1,3.75,2.86]],"ltp":3.5,"tv":306.44,"id":8734382},{"batb":[[1,1.38,67.96],[2,1.37,66.77]],"batl":[[0,1.45,64.1]],"ltp":1.4,"tv":14132.3,"id":9323645}]}]}
{"op":"mcm","clk":"4216531780","pt":1631552839740,"mc":[{"id":"1.187566733","rc":[{"batb":[[0,3.15,4.23],[1,3.1,4.24],[2,2.92,38.44]],"batl":[[0,3.75,2.86],[1,3.75,0]],"ltp":3.5,"tv":306.44,"id":8734382},{"batb":[[1,1.37,66.77],[2,1.36,222.63]],"batl":[[0,1.46,61.75],[1,1.47,55.5],[2,1.48,8.53]],"ltp":1.4,"tv":14132.3,"id":9323645}]}]}
{"op":"mcm","clk":"4216532046","pt":1631552842137,"mc":[{"id":"1.187566733","rc":[{"trd":[[1.42,694.7]],"batb":[[0,1.42,35]],"ltp":1.42,"tv":14142.3,"id":9323645}],"tv":14448.74}]}
{"op":"mcm","clk":"4216532145","pt":1631552842932,"mc":[{"id":"1.187566733","rc":[{"batb":[[0,3.2,4.12],[1,3.15,4.23],[2,3.1,4.24]],"batl":[[0,3.65,3.1],[1,3.75,2.86]],"ltp":3.5,"tv":306.44,"id":8734382},{"batb":[[1,1.38,69.96],[2,1.37,66.77]],"batl":[[0,1.45,174.65],[1,1.46,61.75],[2,1.47,55.5]],"ltp":1.42,"tv":14142.3,"id":9323645}]}]}
{"op":"mcm","clk":"4216532190","pt":1631552843244,"mc":[{"id":"1.187566733","rc":[{"batb":[[0,3.15,4.23],[1,3.1,4.24],[2,2.92,38.44]],"batl":[[0,3.75,2.86],[1,3.75,0]],"ltp":3.5,"tv":306.44,"id":8734382},{"batb":[[1,1.37,66.77],[2,1.36,222.63]],"batl":[[0,1.45,120.15]],"ltp":1.42,"tv":14142.3,"id":9323645}]}]}
{"op":"mcm","clk":"4216532457","pt":1631552845623,"mc":[{"id":"1.187566733","rc":[{"batl":[[0,1.44,57.7],[1,1.45,120.15],[2,1.46,61.75]],"ltp":1.42,"tv":14142.3,"id":9323645}]}]}
{"op":"mcm","clk":"4216532754","pt":1631552848068,"mc":[{"id":"1.187566733","rc":[{"batl":[[0,1.45,57],[1,1.46,61.75],[2,1.47,55.5]],"ltp":1.42,"tv":14142.3,"id":9323645}]}]}
{"op":"mcm","clk":"4216532921","pt":1631552848447,"mc":[{"id":"1.187566733","rc":[{"batl":[[0,1.46,61.75],[1,1.47,55.5],[2,1.48,8.53]],"ltp":1.42,"tv":14142.3,"id":9323645}]}]}
{"op":"mcm","clk":"4216533092","pt":1631552850174,"mc":[{"id":"1.187566733","rc":[{"batb":[[0,3.2,3.67],[1,3.15,4.23],[2,3.1,4.24]],"batl":[[0,3.65,2.9],[1,3.75,2.86]],"ltp":3.5,"tv":306.44,"id":8734382},{"batb":[[1,1.38,61.46],[2,1.37,66.77]],"batl":[[0,1.45,52.9],[1,1.46,61.75],[2,1.47,55.5]],"ltp":1.42,"tv":14142.3,"id":9323645}]}]}
{"op":"mcm","clk":"4216533116","pt":1631552850345,"mc":[{"id":"1.187566733","rc":[{"batb":[[0,3.15,4.23],[1,3.1,4.24],[2,2.92,38.44]],"batl":[[0,3.75,2.86],[1,3.75,0]],"ltp":3.5,"tv":306.44,"id":8734382},{"batb":[[1,1.37,66.77],[2,1.34,102.72]],"batl":[[0,1.46,61.75],[1,1.47,55.5],[2,1.48,8.53]],"ltp":1.42,"tv":14142.3,"id":9323645}]}]}
{"op":"mcm","clk":"4216533436","pt":1631552853663,"mc":[{"id":"1.187566733","rc":[{"batb":[[0,3.2,3.87],[1,3.15,4.23],[2,3.1,4.24]],"batl":[[0,3.65,3.5],[1,3.75,2.86]],"ltp":3.5,"tv":306.44,"id":8734382},{"trd":[[1.42,735.2]],"batb":[[0,1.42,14.75],[1,1.41,75.91],[2,1.4,133.76]],"batl":[[0,1.44,127.49],[1,1.45,169.05],[2,1.46,61.75]],"ltp":1.42,"tv":14182.8,"id":9323645}],"tv":14489.24}]}
{"op":"mcm","clk":"4216533767","pt":1631552857037,"mc":[{"id":"1.187566733","rc":[{"batb":[[1,1.38,61.46],[2,1.37,66.77]],"batl":[[0,1.45,55.7],[1,1.46,61.75],[2,1.47,55.5]],"ltp":1.42,"tv":14182.8,"id":9323645}]}]}
{"op":"mcm","clk":"4216533784","pt":1631552857250,"mc":[{"id":"1.187566733","rc":[{"batb":[[0,3.15,4.23],[1,3.1,4.24],[2,2.92,38.44]],"ltp":3.5,"tv":306.44,"id":8734382},{"batl":[[0,1.46,61.75],[1,1.47,55.5],[2,1.48,8.53]],"ltp":1.42,"tv":14182.8,"id":9323645}]}]}
{"op":"mcm","clk":"4216534491","pt":1631552864147,"mc":[{"id":"1.187566733","rc":[{"batb":[[0,3.2,3.62],[1,3.15,4.23],[2,3.1,4.24]],"ltp":3.5,"tv":306.44,"id":8734382},{"batl":[[0,1.45,61.9],[1,1.46,61.75],[2,1.47,55.5]],"ltp":1.42,"tv":14182.8,"id":9323645}]}]}
{"op":"mcm","clk":"4216534511","pt":1631552864364,"mc":[{"id":"1.187566733","rc":[{"batb":[[0,3.15,4.23],[1,3.1,4.24],[2,2.92,38.44]],"ltp":3.5,"tv":306.44,"id":8734382},{"batl":[[0,1.46,61.75],[1,1.47,55.5],[2,1.48,8.53]],"ltp":1.42,"tv":14182.8,"id":9323645}]}]}
{"op":"mcm","clk":"4216534671","pt":1631552866052,"mc":[{"id":"1.187566733","rc":[{"batb":[[0,3.55,4.39],[1,3.5,8.58],[2,3.45,4.28]],"batl":[[0,3.7,7.33],[1,3.75,214.77]],"ltp":3.5,"tv":306.44,"id":8734382},{"trd":[[1.38,541.66],[1.42,764.7]],"batb":[[0,1.37,66.77],[1,1.36,222.63],[2,1.35,161.1]],"batl":[[0,1.39,46.43],[1,1.4,180.35],[2,1.41,270.36]],"ltp":1.38,"tv":14227.0,"id":9323645}],"tv":14533.44}]}
{"op":"mcm","clk":"4216534758","pt":1631552867049,"mc":[{"id":"1.187566733","rc":[{"batl":[[2,3.9,7.7]],"ltp":3.5,"tv":306.44,"id":8734382}]}]}
{"op":"mcm","clk":"4216535067","pt":1631552870983,"mc":[{"id":"1.187566733","rc":[{"batl":[[0,1.39,101]],"ltp":1.38,"tv":14227.0,"id":9323645}]}]}
{"op":"mcm","clk":"4216535212","pt":1631552872675,"mc":[{"id":"1.187566733","rc":[{"batl":[[2,3.8,3.22]],"ltp":3.5,"tv":306.44,"id":8734382},{"batb":[[1,1.36,291.31]],"ltp":1.38,"tv":14227.0,"id":9323645}]}]}
{"op":"mcm","clk":"4216535276","pt":1631552873466,"mc":[{"id":"1.187566733","rc":[{"batl":[[0,1.39,238]],"ltp":1.38,"tv":14227.0,"id":9323645}]}]}
{"op":"mcm","clk":"4216535420","pt":1631552875192,"mc":[{"id":"1.187566733","rc":[{"trd":[[3.7,13.17]],"batl":[[0,3.75,214.77],[1,3.8,3.22],[2,3.9,7.7]],"ltp":3.7,"tv":313.77,"id":8734382},{"trd":[[1.36,629.76],[1.37,169.1]],"batb":[[0,1.36,177.88],[1,1.35,161.1],[2,1.34,102.72]],"ltp":1.36,"tv":14607.2,"id":9323645}],"tv":14920.97}]}
{"op":"mcm","clk":"4216535498","pt":1631552875883,"mc":[{"id":"1.187566733","rc":[{"batl":[[0,1.39,101],[1,1.4,133.27],[2,1.41,142.55]],"ltp":1.36,"tv":14607.2,"id":9323645}]}]}
{"op":"mcm","clk":"4216535791","pt":1631552879103,"mc":[{"id":"1.187566733","rc":[{"batl":[[2,3.9,10.75]],"ltp":3.7,"tv":313.77,"id":8734382},{"batb":[[0,1.37,68.77],[1,1.36,228.62],[2,1.35,226.37]],"batl":[[0,1.38,416.55],[1,1.39,209.63],[2,1.4,133.27]],"ltp":1.36,"tv":14607.2,"id":9323645}]}]}
{"op":"mcm","clk":"4216536063","pt":1631552882003,"mc":[{"id":"1.187566733","rc":[{"batb":[[0,3.35,3.67],[1,3.25,3.61],[2,3.15,4.23]],"batl":[[0,3.9,3.05],[1,3.8,0],[2,3.9,0]],"ltp":3.7,"tv":313.77,"id":8734382},{"batb":[[0,1.35,65.27],[1,1.32,123.31],[2,1.05,752.45]],"batl":[[0,1.38,361],[1,1.42,58.75],[2,1.44,53.08]],"ltp":1.36,"tv":14607.2,"id":9323645}]}]}
{"op":"mcm","clk":"4216536123","pt":1631552882692,"mc":[{"id":"1.187566733","rc":[{"batb":[[0,3.25,3.61],[1,3.1,32.48],[2,1.6,768.05]],"ltp":3.7,"tv":313.77,"id":8734382},{"batl":[[0,1.44,53.08],[1,1.47,2],[2,1.48,8.53]],"ltp":1.36,"tv":14607.2,"id":9323645}]}]}
{"op":"mcm","clk":"4216536346","pt":1631552885117,"mc":[{"id":"1.187566733","rc":[{"batl":[[0,3.8,2.87],[1,3.9,3.05]],"ltp":3.7,"tv":313.77,"id":8734382},{"trd":[[1.36,754.62]],"batb":[[1,1.34,159.28],[2,1.33,173.95]],"batl":[[0,1.36,137.57],[1,1.44,234.11],[2,1.45,113.43]],"ltp":1.36,"tv":14732.06,"id":9323645}],"tv":15045.83}]}
{"op":"mcm","clk":"4216536417","pt":1631552885913,"mc":[{"id":"1.187566733","rc":[{"batb":[[0,3.35,3.67],[1,3.25,3.61],[2,3.1,32.48]],"batl":[[0,3.9,3.05],[1,3.9,0]],"ltp":3.7,"tv":313.77,"id":8734382},{"batl":[[1,1.42,58.75],[2,1.44,234.11]],"ltp":1.36,"tv":14732.06,"id":9323645}]}]}
{"op":"mcm","clk":"4216536621","pt":1631552888177,"mc":[{"id":"1.187566733","rc":[{"batb":[[1,1.32,123.31],[2,1.05,752.45]],"ltp":1.36,"tv":14732.06,"id":9323645}]}]}
{"op":"mcm","clk":"4216536867","pt":1631552891184,"mc":[{"id":"1.187566733","rc":[{"batb":[[0,3.25,3.61],[1,3.1,32.48],[2,1.6,768.05]],"batl":[[0,3.5,6.61],[1,3.9,3.05],[2,4.2,2.38]],"ltp":3.7,"tv":313.77,"id":8734382},{"trd":[[1.36,1029.76]],"batb":[[0,1.4,2120.43],[1,1.39,237.4],[2,1.38,95.68]],"batl":[[0,1.42,13.99],[1,1.44,234.11],[2,1.45,113.43]],"ltp":1.36,"tv":15007.2,"id":9323645}],"tv":15320.97}]}
{"op":"mcm","clk":"4216536965","pt":1631552892186,"mc":[{"id":"1.187566733","rc":[{"batb":[[2,2.82,42.3]],"ltp":3.7,"tv":313.77,"id":8734382},{"trd":[[1.4,953.49]],"batb":[[0,1.4,314.75]],"ltp":1.4,"tv":15021.58,"id":9323645}],"tv":15335.35}]}
{"op":"mcm","clk":"4216537270","pt":1631552896131,"mc":[{"id":"1.187566733","rc":[{"batl":[[0,1.42,201.99]],"ltp":1.4,"tv":15021.58,"id":9323645}]}]}
{"op":"mcm","clk":"4216537502","pt":1631552898712,"mc":[{"id":"1.187566733","rc":[{"batb":[[1,3.15,4.63],[2,3.1,32.48]],"batl":[[1,3.65,3.1],[2,3.75,2.62]],"ltp":3.7,"tv":313.77,"id":8734382},{"batb":[[2,1.38,170.64]],"batl":[[0,1.42,259.23]],"ltp":1.4,"tv":15021.58,"id":9323645}]}]}
{"op":"mcm","clk":"4216537765","pt":1631552902124,"mc":[{"id":"1.187566733","rc":[{"batb":[[0,3.15,4.63],[1,3.05,4.69],[2,2.82,42.3]],"batl":[[0,3.65,3.1],[1,3.75,2.62],[2,3.9,3.05]],"ltp":3.7,"tv":313.77,"id":8734382},{"batb":[[0,1.38,74.96],[1,1.37,65.77],[2,1.35,165.55]],"batl":[[0,1.42,188],[1,1.46,85.25],[2,1.47,2]],"ltp":1.4,"tv":15021.58,"id":9323645}]}]}
{"op":"mcm","clk":"4216537828","pt":1631552902700,"mc":[{"id":"1.187566733","rc":[{"batb":[[0,3.05,4.69],[1,2.82,42.3],[2,1.6,768.05]],"batl":[[0,3.75,2.62],[1,3.75,0],[2,3.9,0]],"ltp":3.7,"tv":313.77,"id":8734382},{"batb":[[0,1.37,65.77],[1,1.35,100.28],[2,1.32,12.7]],"batl":[[0,1.47,2],[1,1.48,95.77],[2,1.5,10.79]],"ltp":1.4,"tv":15021.58,"id":9323645}]}]}
{"op":"mcm","clk":"4216537940","pt":1631552904018,"mc":[{"id":"1.187566733","rc":[{"batl":[[1,1.48,87.24]],"ltp":1.4,"tv":15021.58,"id":9323645}]}]}
{"op":"mcm","clk":"4216538030","pt":1631552905126,"mc":[{"id":"1.187566733","rc":[{"batb":[[0,1.37,164.59],[1,1.36,154.61],[2,1.35,100.28]],"ltp":1.4,"tv":15021.58,"id":9323645}]}]}
{"op":"mcm","clk":"4216538099","pt":1631552905918,"mc":[{"id":"1.187566733","rc":[{"batb":[[0,3.15,4.43],[1,3.05,4.69],[2,2.82,42.3]],"ltp":3.7,"tv":313.77,"id":8734382},{"batl":[[0,1.46,84.75],[1,1.47,2],[2,1.48,87.24]],"ltp":1.4,"tv":15021.58,"id":9323645}]}]}
{"op":"mcm","clk":"4216538126","pt":1631552906234,"mc":[{"id":"1.187566733","rc":[{"batb":[[0,3.05,4.69],[1,2.82,42.3],[2,1.6,768.05]],"ltp":3.7,"tv":313.77,"id":8734382},{"batl":[[0,1.47,2],[1,1.48,87.24],[2,1.5,10.79]],"ltp":1.4,"tv":15021.58,"id":9323645}]}]}
{"op":"mcm","clk":"4216538787","pt":1631552913038,"mc":[{"id":"1.187566733","rc":[{"batb":[[0,3.15,4.23],[1,3.05,4.69],[2,2.82,42.3]],"ltp":3.7,"tv":313.77,"id":8734382},{"batl":[[0,1.46,79.25],[1,1.47,2],[2,1.48,87.24]],"ltp":1.4,"tv":15021.58,"id":9323645}]}]}
{"op":"mcm","clk":"4216538801","pt":1631552913352,"mc":[{"id":"1.187566733","rc":[{"batb":[[0,3.05,4.69],[1,2.82,42.3],[2,1.6,768.05]],"ltp":3.7,"tv":313.77,"id":8734382},{"batl":[[0,1.47,2],[1,1.48,87.24],[2,1.5,10.79]],"ltp":1.4,"tv":15021.58,"id":9323645}]}]}
{"op":"mcm","clk":"4216539359","pt":1631552920054,"mc":[{"id":"1.187566733","rc":[{"batb":[[0,3.15,4.43],[1,3.05,4.69],[2,2.82,42.3]],"ltp":3.7,"tv":313.77,"id":8734382},{"batl":[[0,1.46,83.25],[1,1.47,2],[2,1.48,87.24]],"ltp":1.4,"tv":15021.58,"id":9323645}]}]}
{"op":"mcm","clk":"4216539378","pt":1631552920266,"mc":[{"id":"1.187566733","rc":[{"batb":[[0,3.05,4.69],[1,2.82,42.3],[2,1.6,768.05]],"ltp":3.7,"tv":313.77,"id":8734382},{"batl":[[0,1.47,2],[1,1.48,87.24],[2,1.5,10.79]],"ltp":1.4,"tv":15021.58,"id":9323645}]}]}
{"op":"mcm","clk":"4216539598","pt":1631552923167,"mc":[{"id":"1.187566733","rc":[{"batl":[[0,3.65,3.1],[1,3.75,2.62]],"ltp":3.7,"tv":313.77,"id":8734382},{"batb":[[0,1.38,68.96],[1,1.37,164.59],[2,1.36,154.61]],"ltp":1.4,"tv":15021.58,"id":9323645}]}]}
{"op":"mcm","clk":"4216539664","pt":1631552923751,"mc":[{"id":"1.187566733","rc":[{"batl":[[0,3.75,2.62],[1,3.75,0]],"ltp":3.7,"tv":313.77,"id":8734382},{"batb":[[0,1.37,164.59],[1,1.36,154.61],[2,1.35,100.28]],"ltp":1.4,"tv":15021.58,"id":9323645}]}]}
{"op":"mcm","clk":"4216539757","pt":1631552924752,"mc":[{"id":"1.187566733","rc":[{"batb":[[0,3.55,13.59],[1,3.5,25.72],[2,3.45,47.64]],"batl":[[0,3.7,239.45],[1,3.75,2.62]],"ltp":3.7,"tv":313.77,"id":8734382},{"trd":[[1.37,183.8]],"batb":[[0,1.37,157.24]],"batl":[[0,1.39,121.51],[1,1.4,153.16],[2,1.41,128.6]],"ltp":1.37,"tv":15036.28,"id":9323645}],"tv":15350.05}]}
{"op":"mcm","clk":"4216539873","pt":1631552925963,"mc":[{"id":"1.187566733","rc":[{"batb":[[1,3.5,8.58],[2,3.45,39.07]],"batl":[[2,4.5,2.22]],"ltp":3.7,"tv":313.77,"id":8734382},{"batb":[[2,1.35,122.5]],"ltp":1.37,"tv":15036.28,"id":9323645}]}]}
{"op":"mcm","clk":"4216540132","pt":1631552929175,"mc":[{"id":"1.187566733","rc":[{"trd":[[3.7,34.5]],"batl":[[0,3.7,218.12]],"ltp":3.7,"tv":335.1,"id":8734382},{"trd":[[1.37,555.87]],"batb":[[0,1.36,154.61],[1,1.35,122.5],[2,1.34,11.12]],"batl":[[0,1.39,183.74]],"ltp":1.37,"tv":15408.35,"id":9323645}],"tv":15743.45}]}
{"op":"mcm","clk":"4216540233","pt":1631552930481,"mc":[{"id":"1.187566733","rc":[{"batl":[[0,1.39,293.74]],"ltp":1.37,"tv":15408.35,"id":9323645}]}]}
{"op":"mcm","clk":"4216540348","pt":1631552931763,"mc":[{"id":"1.187566733","rc":[{"batl":[[2,3.8,2.67]],"ltp":3.7,"tv":335.1,"id":8734382},{"batb":[[0,1.36,270.91],[1,1.35,284.56]],"batl":[[1,1.4,206.46],[2,1.41,220.1]],"ltp":1.37,"tv":15408.35,"id":9323645}]}]}
{"op":"mcm","clk":"4216540531","pt":1631552933994,"mc":[{"id":"1.187566733","rc":[{"batl":[[0,1.38,63.61],[1,1.39,183.74],[2,1.4,206.46]],"ltp":1.37,"tv":15408.35,"id":9323645}]}]}
{"op":"mcm","clk":"4216540653","pt":1631552935483,"mc":[{"id":"1.187566733","rc":[{"trd":[[3.7,108.55]],"batl":[[0,3.7,144.07]],"ltp":3.7,"tv":409.15,"id":8734382},{"trd":[[1.37,755.87]],"ltp":1.37,"tv":15608.35,"id":9323645}],"tv":16017.5}]}
{"op":"mcm","clk":"4216540770","pt":1631552937100,"mc":[{"id":"1.187566733","rc":[{"batl":[[0,1.38,344.61]],"ltp":1.37,"tv":15608.35,"id":9323645}]}]}
{"op":"mcm","clk":"4216540808","pt":1631552937578,"mc":[{"id":"1.187566733","rc":[{"batb":[[1,1.35,353.23]],"ltp":1.37,"tv":15608.35,"id":9323645}]}]}
{"op":"mcm","clk":"4216541606","pt":1631552947105,"mc":[{"id":"1.187566733","rc":[{"trd":[[3.6,0.02]],"ltp":3.6,"tv":409.17,"id":8734382},{"trd":[[1.38,541.71]],"batl":[[0,1.38,344.56]],"ltp":1.38,"tv":15608.4,"id":9323645}],"tv":16017.57}]}
{"op":"mcm","clk":"4216541781","pt":1631552949206,"mc":[{"id":"1.187566733","rc":[{"batb":[[1,3.5,4.29],[2,3.45,7.94]],"batl":[[0,3.75,2.62],[1,3.8,2.67],[2,3.9,2.75]],"ltp":3.6,"tv":409.17,"id":8734382},{"batb":[[1,1.35,342.12],[2,1.34,5.56]],"batl":[[1,1.39,165.73]],"ltp":1.38,"tv":15608.4,"id":9323645}]}]}
{"op":"mcm","clk":"4216541835","pt":1631552949687,"mc":[{"id":"1.187566733","rc":[{"batb":[[0,3.3,5.58],[1,3.05,34.57],[2,1.6,768.05]],"batl":[[0,3.9,2.75],[1,3.8,0],[2,3.9,0]],"ltp":3.6,"tv":409.17,"id":8734382},{"batb":[[0,1.35,68.67],[1,1.33,105.99],[2,1.32,12.7]],"batl":[[0,1.43,117.5],[1,1.47,2],[2,1.5,10.79]],"ltp":1.38,"tv":15608.4,"id":9323645}]}]}
{"op":"mcm","clk":"4216542112","pt":1631552953206,"mc":[{"id":"1.187566733","rc":[{"batb":[[1,1.34,208.79],[2,1.33,281.24]],"batl":[[1,1.44,166.54],[2,1.45,113.92]],"ltp":1.38,"tv":15608.4,"id":9323645}]}]}
{"op":"mcm","clk":"4216542655","pt":1631552959983,"mc":[{"id":"1.187566733","rc":[{"batb":[[0,3.4,5.71],[1,3.3,5.58],[2,3.05,34.57]],"batl":[[0,3.8,3.12],[1,3.9,2.75]],"ltp":3.6,"tv":409.17,"id":8734382},{"batb":[[0,1.36,79.68],[1,1.35,68.67],[2,1.34,208.79]],"batl":[[0,1.41,117.5],[1,1.47,2],[2,1.5,10.79]],"ltp":1.38,"tv":15608.4,"id":9323645}]}]}
{"op":"mcm","clk":"4216542673","pt":1631552960294,"mc":[{"id":"1.187566733","rc":[{"batb":[[0,3.3,5.58],[1,3.05,34.57],[2,1.6,768.05]],"batl":[[0,3.9,2.75],[1,3.9,0]],"ltp":3.6,"tv":409.17,"id":8734382},{"batb":[[0,1.35,68.67],[1,1.34,208.79],[2,1.33,281.24]],"batl":[[0,1.47,2],[1,1.5,10.79],[2,1.51,0.52]],"ltp":1.38,"tv":15608.4,"id":9323645}]}]}
{"op":"mcm","clk":"4216542827","pt":1631552962180,"mc":[{"id":"1.187566733","rc":[{"batb":[[0,3.65,74.52],[1,3.6,72.32],[2,3.55,236.17]],"batl":[[0,3.85,162.52],[1,3.9,2.75]],"ltp":3.6,"tv":409.17,"id":8734382},{"trd":[[1.35,1172.58]],"batb":[[0,1.35,61.26]],"batl":[[0,1.37,17.37],[1,1.38,1773.3],[2,1.47,2]],"ltp":1.35,"tv":15623.22,"id":9323645}],"tv":16032.39}]}
{"op":"mcm","clk":"4216542902","pt":1631552963173,"mc":[{"id":"1.187566733","rc":[{"batb":[[0,3.65,37.26],[1,3.6,52.9],[2,3.55,200.01]],"batl":[[2,4.7,2.13]],"ltp":3.6,"tv":409.17,"id":8734382},{"batl":[[0,1.37,111.15],[1,1.38,419.24]],"ltp":1.35,"tv":15623.22,"id":9323645}]}]}
{"op":"mcm","clk":"4216543220","pt":1631552967126,"mc":[{"id":"1.187566733","rc":[{"batl":[[2,3.95,59.68]],"ltp":3.6,"tv":409.17,"id":8734382},{"batl":[[1,1.38,453.38]],"ltp":1.35,"tv":15623.22,"id":9323645}]}]}
{"op":"mcm","clk":"4216543240","pt":1631552967282,"mc":[{"id":"1.187566733","rc":[{"batl":[[2,4.7,2.13]],"ltp":3.6,"tv":409.17,"id":8734382},{"batl":[[1,1.38,419.24]],"ltp":1.35,"tv":15623.22,"id":9323645}]}]}
{"op":"mcm","clk":"4216543475","pt":1631552970321,"mc":[{"id":"1.187566733","rc":[{"batl":[[0,1.37,337.21]],"ltp":1.35,"tv":15623.22,"id":9323645}]}]}
{"op":"mcm","clk":"4216543652","pt":1631552972633,"mc":[{"id":"1.187566733","rc":[{"trd":[[3.85,220.91]],"batl":[[0,3.85,113.87]],"ltp":3.85,"tv":457.82,"id":8734382},{"trd":[[1.35,1433.84]],"batb":[[0,1.34,208.79],[1,1.33,281.24],[2,1.32,115.72]],"ltp":1.35,"tv":15884.48,"id":9323645}],"tv":16342.3}]}
{"op":"mcm","clk":"4216543784","pt":1631552974214,"mc":[{"id":"1.187566733","rc":[{"batl":[[1,1.38,276.21]],"ltp":1.35,"tv":15884.48,"id":9323645}]}]}
{"op":"mcm","clk":"4216543918","pt":1631552975789,"mc":[{"id":"1.187566733","rc":[{"batl":[[0,1.36,95.77],[1,1.37,337.21],[2,1.38,276.21]],"ltp":1.35,"tv":15884.48,"id":9323645}]}]}
{"op":"mcm","clk":"4216544438","pt":1631552982795,"mc":[{"id":"1.187566733","rc":[{"batl":[[1,1.37,319.84]],"ltp":1.35,"tv":15884.48,"id":9323645}]}]}
{"op":"mcm","clk":"4216544653","pt":1631552985834,"mc":[{"id":"1.187566733","rc":[{"trd":[[3.85,291.04]],"batl":[[0,3.85,43.74]],"ltp":3.85,"tv":527.95,"id":8734382},{"trd":[[1.35,1633.84]],"batb":[[0,1.34,229.96]],"batl":[[0,1.36,112.55],[1,1.37,187.84]],"ltp":1.35,"tv":16084.48,"id":9323645}],"tv":16612.43}]}
{"op":"mcm","clk":"4216544857","pt":1631552988929,"mc":[{"id":"1.187566733","rc":[{"batl":[[0,1.36,408.55]],"ltp":1.35,"tv":16084.48,"id":9323645}]}]}
{"op":"mcm","clk":"4216545570","pt":1631552997946,"mc":[{"id":"1.187566733","rc":[{"trd":[[3.85,334.78]],"batl":[[0,3.9,2.75],[1,4.7,2.13],[2,4.7,0]],"ltp":3.85,"tv":571.69,"id":8734382},{"trd":[[1.34,150.52],[1.35,1758.58]],"batb":[[0,1.34,154.7]],"ltp":1.34,"tv":16359.74,"id":9323645}],"tv":16931.43}]}
{"op":"mcm","clk":"4216545636","pt":1631552998834,"mc":[{"id":"1.187566733","rc":[{"trd":[[1.36,1038.78]],"batl":[[0,1.36,404.04]],"ltp":1.36,"tv":16368.76,"id":9323645}],"tv":16940.45}]}
{"op":"mcm","clk":"4216545812","pt":1631553001358,"mc":[{"id":"1.187566733","rc":[{"batb":[[0,1.34,188.25]],"batl":[[1,1.37,228.39]],"ltp":1.36,"tv":16368.76,"id":9323645}]}]}
{"op":"mcm","clk":"4216546028","pt":1631553003957,"mc":[{"id":"1.187566733","rc":[{"batb":[[0,1.34,410.25]],"ltp":1.36,"tv":16368.76,"id":9323645}]}]}
{"op":"mcm","clk":"4216546070","pt":1631553004635,"mc":[{"id":"1.187566733","rc":[{"batb":[[0,1.35,830.25],[1,1.34,410.25],[2,1.33,281.24]],"ltp":1.36,"tv":16368.76,"id":9323645}]}]}
{"op":"mcm","clk":"4216546387","pt":1631553008444,"mc":[{"id":"1.187566733","rc":[{"trd":[[1.35,2253.66]],"batb":[[0,1.35,582.71]],"ltp":1.35,"tv":16863.84,"id":9323645}],"tv":17435.53}]}
{"op":"mcm","clk":"4216546631","pt":1631553011648,"mc":[{"id":"1.187566733","rc":[{"batb":[[0,1.35,613.35]],"ltp":1.35,"tv":16863.84,"id":9323645}]}]}
{"op":"mcm","clk":"4216546797","pt":1631553013849,"mc":[{"id":"1.187566733","rc":[{"trd":[[1.35,3253.66]],"batb":[[0,1.35,113.35]],"ltp":1.35,"tv":17863.84,"id":9323645}],"tv":18435.53}]}
{"op":"mcm","clk":"4216547306","pt":1631553020340,"mc":[{"id":"1.187566733","rc":[{"trd":[[3.75,1.71]],"ltp":3.75,"tv":573.4,"id":8734382},{"trd":[[1.36,1043.49]],"batl":[[0,1.36,399.33]],"ltp":1.36,"tv":17868.55,"id":9323645}],"tv":18441.95}]}
{"op":"mcm","clk":"4216547672","pt":1631553024786,"mc":[{"id":"1.187566733","rc":[{"trd":[[1.34,923.82],[1.35,3480.36]],"batb":[[0,1.34,23.6],[1,1.33,281.24],[2,1.32,115.72]],"ltp":1.34,"tv":18868.55,"id":9323645}],"tv":19441.95}]}
{"op":"mcm","clk":"4216547885","pt":1631553028181,"mc":[{"id":"1.187566733","rc":[{"batb":[[1,1.33,356.6],[2,1.32,300.18]],"batl":[[1,1.37,318.4]],"ltp":1.34,"tv":18868.55,"id":9323645}]}]}
{"op":"mcm","clk":"4216548079","pt":1631553030868,"mc":[{"id":"1.187566733","rc":[{"batl":[[0,1.36,594.81]],"ltp":1.34,"tv":18868.55,"id":9323645}]}]}
{"op":"mcm","clk":"4216548427","pt":1631553034987,"mc":[{"id":"1.187566733","rc":[{"batl":[[0,1.36,578.03]],"ltp":1.34,"tv":18868.55,"id":9323645}]}]}
{"op":"mcm","clk":"4216548556","pt":1631553036682,"mc":[{"id":"1.187566733","rc":[{"batb":[[0,1.34,245.6]],"ltp":1.34,"tv":18868.55,"id":9323645}]}]}
{"op":"mcm","clk":"4216548633","pt":1631553037892,"mc":[{"id":"1.187566733","rc":[{"batl":[[1,4,4.51],[2,4.7,2.13]],"ltp":3.75,"tv":573.4,"id":8734382},{"batl":[[0,1.35,19.35],[1,1.36,578.03],[2,1.37,318.4]],"ltp":1.34,"tv":18868.55,"id":9323645}]}]}
{"op":"mcm","clk":"4216551335","pt":1631553073148,"mc":[{"id":"1.187566733","rc":[{"batl":[[2,4.7,0]],"ltp":3.75,"tv":573.4,"id":8734382}]}]}
{"op":"mcm","clk":"4216551382","pt":1631553073734,"mc":[{"id":"1.187566733","rc":[{"batb":[[0,3.5,8.06],[1,3.35,6.47],[2,3.15,30.55]],"ltp":3.75,"tv":573.4,"id":8734382},{"batb":[[1,1.32,12.7],[2,1.31,222]],"batl":[[0,1.36,491.48],[1,1.4,140.74],[2,1.42,149.75]],"ltp":1.34,"tv":18868.55,"id":9323645}]}]}
{"op":"mcm","clk":"4216551451","pt":1631553074525,"mc":[{"id":"1.187566733","rc":[{"batl":[[0,1.36,195.48]],"ltp":1.34,"tv":18868.55,"id":9323645}]}]}
{"op":"mcm","clk":"4216551626","pt":1631553076654,"mc":[{"id":"1.187566733","rc":[{"batl":[[1,1.4,225.41],[2,1.41,130.8]],"ltp":1.34,"tv":18868.55,"id":9323645}]}]}
{"op":"mcm","clk":"4216551722","pt":1631553077956,"mc":[{"id":"1.187566733","rc":[{"batb":[[0,1.32,12.7],[1,1.28,128.82],[2,1.05,752.45]],"batl":[[1,1.4,140.74],[2,1.42,149.75]],"ltp":1.34,"tv":18868.55,"id":9323645}]}]}
{"op":"mcm","clk":"4216551890","pt":1631553080121,"mc":[{"id":"1.187566733","rc":[{"batb":[[0,1.32,264.77],[1,1.31,192.26],[2,1.28,128.82]],"batl":[[0,1.35,91.35],[1,1.36,350.72],[2,1.4,140.74]],"ltp":1.34,"tv":18868.55,"id":9323645}]}]}
{"op":"mcm","clk":"4216552107","pt":1631553083035,"mc":[{"id":"1.187566733","rc":[{"batb":[[0,1.32,12.7],[1,1.28,128.82],[2,1.05,752.45]],"batl":[[0,1.36,195.48],[1,1.4,140.74],[2,1.42,149.75]],"ltp":1.34,"tv":18868.55,"id":9323645}]}]}
{"op":"mcm","clk":"4216552312","pt":1631553085941,"mc":[{"id":"1.187566733","rc":[{"batb":[[1,1.29,81.03],[2,1.28,345.29]],"batl":[[1,1.4,225.41],[2,1.41,130.8]],"ltp":1.34,"tv":18868.55,"id":9323645}]}]}
{"op":"mcm","clk":"4216552626","pt":1631553090137,"mc":[{"id":"1.187566733","rc":[{"batb":[[1,1.28,128.82],[2,1.05,752.45]],"ltp":1.34,"tv":18868.55,"id":9323645}]}]}
{"op":"mcm","clk":"4216552681","pt":1631553091168,"mc":[{"id":"1.187566733","rc":[{"batb":[[0,3.35,6.47],[1,3.15,30.55],[2,1.6,768.05]],"ltp":3.75,"tv":573.4,"id":8734382},{"batl":[[0,1.4,84.67],[1,1.41,130.8],[2,1.47,2]],"ltp":1.34,"tv":18868.55,"id":9323645}]}]}
{"op":"mcm","clk":"4216552818","pt":1631553093168,"mc":[{"id":"1.187566733","rc":[{"batb":[[0,3.6,6.88],[1,3.35,6.47],[2,3.15,30.55]],"batl":[[0,3.7,185.7],[1,3.75,84.25],[2,3.8,12]],"ltp":3.75,"tv":573.4,"id":8734382},{"batb":[[0,1.37,176.47],[1,1.36,157.22],[2,1.32,12.7]],"batl":[[2,1.42,463.46]],"ltp":1.34,"tv":18868.55,"id":9323645}]}]}
{"op":"mcm","clk":"4216552902","pt":1631553094172,"mc":[{"id":"1.187566733","rc":[{"batb":[[1,3.4,8.82],[2,3.35,10.89]],"batl":[[1,3.75,68.25],[2,3.8,4]],"ltp":3.75,"tv":573.4,"id":8734382},{"batb":[[1,1.36,252.64]],"batl":[[0,1.38,7.25],[1,1.4,84.67],[2,1.41,130.8]],"ltp":1.34,"tv":18868.55,"id":9323645}]}]}
{"op":"mcm","clk":"4216553019","pt":1631553095550,"mc":[{"id":"1.187566733","rc":[{"batl":[[1,1.4,274.57]],"ltp":1.34,"tv":18868.55,"id":9323645}]}]}
{"op":"mcm","clk":"4216553223","pt":1631553098173,"mc":[{"id":"1.187566733","rc":[{"trd":[[3.7,108.74]],"batl":[[0,3.7,185.51]],"ltp":3.7,"tv":573.59,"id":8734382},{"trd":[[1.37,1189.67]],"batb":[[0,1.36,252.64],[1,1.32,12.7],[2,1.31,111.86]],"batl":[[1,1.39,143.8],[2,1.4,274.57]],"ltp":1.37,"tv":19302.35,"id":9323645}],"tv":19875.94}]}
{"op":"mcm","clk":"4216553387","pt":1631553100072,"mc":[{"id":"1.187566733","rc":[{"batb":[[1,3.4,16.33]],"ltp":3.7,"tv":573.59,"id":8734382},{"batb":[[1,1.34,76.22],[2,1.32,86.59]],"batl":[[0,1.38,333.25]],"ltp":1.37,"tv":19302.35,"id":9323645}]}]}
{"op":"mcm","clk":"4216553454","pt":1631553100961,"mc":[{"id":"1.187566733","rc":[{"batb":[[0,1.37,78.95],[1,1.36,252.64],[2,1.34,76.22]],"batl":[[0,1.38,466.05],[2,1.4,369.66]],"ltp":1.37,"tv":19302.35,"id":9323645}]}]}
{"op":"mcm","clk":"4216553828","pt":1631553105158,"mc":[{"id":"1.187566733","rc":[{"trd":[[3.7,153.56]],"batl":[[0,3.7,140.69]],"ltp":3.7,"tv":618.41,"id":8734382},{"trd":[[1.37,1468.62]],"batb":[[0,1.36,252.64],[1,1.34,76.22],[2,1.32,86.59]],"ltp":1.37,"tv":19581.3,"id":9323645}],"tv":20199.71}]}
{"op":"mcm","clk":"4216553854","pt":1631553105505,"mc":[{"id":"1.187566733","rc":[{"batl":[[2,1.4,326.28]],"ltp":1.37,"tv":19581.3,"id":9323645}]}]}
{"op":"mcm","clk":"4216553960","pt":1631553106676,"mc":[{"id":"1.187566733","rc":[{"batb":[[0,1.36,255.07]],"ltp":1.37,"tv":19581.3,"id":9323645}]}]}
{"op":"mcm","clk":"4216554048","pt":1631553107795,"mc":[{"id":"1.187566733","rc":[{"batb":[[0,3.4,7.51],[1,3.3,7.58],[2,3,35.25]],"batl":[[0,4.2,2.78],[1,3.75,0],[2,3.8,0]],"ltp":3.7,"tv":618.41,"id":8734382},{"batb":[[0,1.36,2.43],[1,1.32,86.59],[2,1.31,111.86]],"batl":[[0,1.38,326],[1,1.4,189.9],[2,1.41,161.5]],"ltp":1.37,"tv":19581.3,"id":9323645}]}]}
{"op":"mcm","clk":"4216554123","pt":1631553108789,"mc":[{"id":"1.187566733","rc":[{"batl":[[0,1.4,189.9],[1,1.41,161.5],[2,1.43,149.5]],"ltp":1.37,"tv":19581.3,"id":9323645}]}]}
{"op":"mcm","clk":"4216554311","pt":1631553111099,"mc":[{"id":"1.187566733","rc":[{"batl":[[0,3.95,2.7],[1,4.2,2.78]],"ltp":3.7,"tv":618.41,"id":8734382},{"batb":[[1,1.34,67.72],[2,1.32,178.43]],"batl":[[2,1.43,289.58]],"ltp":1.37,"tv":19581.3,"id":9323645}]}]}
{"op":"mcm","clk":"4216554385","pt":1631553112105,"mc":[{"id":"1.187566733","rc":[{"batl":[[0,4.2,2.78],[1,4.2,0]],"ltp":3.7,"tv":618.41,"id":8734382},{"batb":[[1,1.32,86.59],[2,1.31,111.86]],"batl":[[2,1.43,149.5]],"ltp":1.37,"tv":19581.3,"id":9323645}]}]}
{"op":"mcm","clk":"4216554590","pt":1631553115089,"mc":[{"id":"1.187566733","rc":[{"batb":[[0,3.65,20.13],[1,3.4,7.51],[2,3.3,7.58]],"batl":[[0,3.75,19.62],[1,4.2,2.78]],"ltp":3.7,"tv":618.41,"id":8734382},{"batb":[[1,1.35,203.71],[2,1.34,171.31]],"batl":[[0,1.38,110.41],[1,1.39,141.02],[2,1.4,189.9]],"ltp":1.37,"tv":19581.3,"id":9323645}]}]}
{"op":"mcm","clk":"4216554617","pt":1631553115402,"mc":[{"id":"1.187566733","rc":[{"batb":[[0,3.4,7.51],[1,3.3,7.58],[2,3,35.25]],"batl":[[0,4.2,2.78],[1,4.2,0]],"ltp":3.7,"tv":618.41,"id":8734382},{"batl":[[0,1.38,91.16]],"ltp":1.37,"tv":19581.3,"id":9323645}]}]}
{"op":"mcm","clk":"4216554796","pt":1631553117570,"mc":[{"id":"1.187566733","rc":[{"batb":[[1,1.32,86.59],[2,1.31,111.86]],"batl":[[0,1.4,189.9],[1,1.41,161.5],[2,1.43,149.5]],"ltp":1.37,"tv":19581.3,"id":9323645}]}]}
{"op":"mcm","clk":"4216554984","pt":1631553120210,"mc":[{"id":"1.187566733","rc":[{"batb":[[0,1.36,224.43]],"ltp":1.37,"tv":19581.3,"id":9323645}]}]}
{"op":"mcm","clk":"4216554992","pt":1631553120415,"mc":[{"id":"1.187566733","rc":[{"batb":[[1,1.32,178.43],[2,1.31,303.81]],"batl":[[2,1.43,289.58]],"ltp":1.37,"tv":19581.3,"id":9323645}]}]}
{"op":"mcm","clk":"4216555079","pt":1631553121902,"mc":[{"id":"1.187566733","rc":[{"batl":[[0,3.95,2.9],[1,4.2,2.78]],"ltp":3.7,"tv":618.41,"id":8734382},{"batb":[[1,1.34,72.22],[2,1.32,178.43]],"ltp":1.37,"tv":19581.3,"id":9323645}]}]}
{"op":"mcm","clk":"4216555130","pt":1631553122693,"mc":[{"id":"1.187566733","rc":[{"batb":[[2,1.32,86.59]],"ltp":1.37,"tv":19581.3,"id":9323645}]}]}
{"op":"mcm","clk":"4216555232","pt":1631553123938,"mc":[{"id":"1.187566733","rc":[{"batb":[[0,3.3,7.58],[1,3,35.25],[2,1.6,768.05]],"ltp":3.7,"tv":618.41,"id":8734382},{"batl":[[0,1.43,289.58],[1,1.44,119.61],[2,1.47,2]],"ltp":1.37,"tv":19581.3,"id":9323645}]}]}
{"op":"mcm","clk":"4216555381","pt":1631553125703,"mc":[{"id":"1.187566733","rc":[{"batb":[[0,3.4,7.2],[1,3.3,7.58],[2,3,35.25]],"batl":[[0,3.5,86.39],[1,3.55,64.84],[2,3.95,2.9]],"ltp":3.7,"tv":618.41,"id":8734382},{"batb":[[0,1.4,299.17],[1,1.39,163.24],[2,1.38,10.8]],"batl":[[2,1.45,449.4]],"ltp":1.37,"tv":19581.3,"id":9323645}]}]}
{"op":"mcm","clk":"4216555510","pt":1631553127016,"mc":[{"id":"1.187566733","rc":[{"batb":[[1,1.39,248.92]],"batl":[[0,1.41,7.09],[1,1.43,289.58],[2,1.44,140.45]],"ltp":1.37,"tv":19581.3,"id":9323645}]}]}
{"op":"mcm","clk":"4216555570","pt":1631553127919,"mc":[{"id":"1.187566733","rc":[{"batb":[[2,1.38,232.8]],"ltp":1.37,"tv":19581.3,"id":9323645}]}]}
{"op":"mcm","clk":"4216555737","pt":1631553129788,"mc":[{"id":"1.187566733","rc":[{"batl":[[1,1.42,124.21],[2,1.43,289.58]],"ltp":1.37,"tv":19581.3,"id":9323645}]}]}
{"op":"mcm","clk":"4216555855","pt":1631553130992,"mc":[{"id":"1.187566733","rc":[{"batl":[[0,1.41,327.09],[1,1.42,346.21]],"ltp":1.37,"tv":19581.3,"id":9323645}]}]}
{"op":"mcm","clk":"4216556007","pt":1631553133000,"mc":[{"id":"1.187566733","rc":[{"batb":[[1,3.35,7.87],[2,3.3,7.58]],"batl":[[2,3.65,3.1]],"ltp":3.7,"tv":618.41,"id":8734382},{"trd":[[1.4,1353.49]],"batb":[[0,1.4,99.17],[2,1.38,304.76]],"batl":[[1,1.42,502.46]],"ltp":1.4,"tv":19981.3,"id":9323645}],"tv":20599.71}]}
{"op":"mcm","clk":"4216556057","pt":1631553133649,"mc":[{"id":"1.187566733","rc":[{"batl":[[0,1.41,444.82]],"ltp":1.4,"tv":19981.3,"id":9323645}]}]}
{"op":"mcm","clk":"4216556389","pt":1631553137843,"mc":[{"id":"1.187566733","rc":[{"batb":[[0,3.35,7.87],[1,3.3,7.58],[2,2.9,39.44]],"batl":[[0,3.65,3.1],[1,3.75,2.82],[2,3.95,2.9]],"ltp":3.7,"tv":618.41,"id":8734382},{"batb":[[0,1.38,293.96],[1,1.37,76.77],[2,1.36,224.43]],"batl":[[0,1.41,320],[1,1.42,378.25],[2,1.43,149.5]],"ltp":1.4,"tv":19981.3,"id":9323645}]}]}
{"op":"mcm","clk":"4216556443","pt":1631553138538,"mc":[{"id":"1.187566733","rc":[{"batl":[[0,1.42,378.25],[1,1.43,149.5],[2,1.44,222]],"ltp":1.4,"tv":19981.3,"id":9323645}]}]}
{"op":"mcm","clk":"4216556585","pt":1631553140435,"mc":[{"id":"1.187566733","rc":[{"batb":[[2,1.36,313.58]],"ltp":1.4,"tv":19981.3,"id":9323645}]}]}
{"op":"mcm","clk":"4216557506","pt":1631553152125,"mc":[{"id":"1.187566733","rc":[{"batl":[[0,3.75,2.82],[1,3.95,2.9],[2,4.2,2.78]],"ltp":3.7,"tv":618.41,"id":8734382},{"batb":[[0,1.37,76.77],[1,1.36,91.58],[2,1.35,261.82]],"ltp":1.4,"tv":19981.3,"id":9323645}]}]}
{"op":"mcm","clk":"4216557683","pt":1631553154149,"mc":[{"id":"1.187566733","rc":[{"batb":[[0,3.65,41.1],[1,3.6,20.56],[2,3.55,42.95]],"batl":[[1,3.85,206.04],[2,3.95,2.9]],"ltp":3.7,"tv":618.41,"id":8734382},{"trd":[[1.37,1483.22]],"batb":[[0,1.37,69.47]],"batl":[[0,1.38,26.03],[1,1.39,171.5],[2,1.4,237.27]],"ltp":1.37,"tv":19995.9,"id":9323645}],"tv":20614.31}]}
{"op":"mcm","clk":"4216557755","pt":1631553155148,"mc":[{"id":"1.187566733","rc":[{"batb":[[0,3.65,24.66],[1,3.6,12.34],[2,3.55,34.73]],"ltp":3.7,"tv":618.41,"id":8734382},{"batl":[[1,1.39,356.44],[2,1.4,372.81]],"ltp":1.37,"tv":19995.9,"id":9323645}]}]}
{"op":"mcm","clk":"4216557819","pt":1631553156046,"mc":[{"id":"1.187566733","rc":[{"batb":[[0,3.65,8.22],[1,3.6,4.12],[2,3.55,26.51]],"ltp":3.7,"tv":618.41,"id":8734382}]}]}
{"op":"mcm","clk":"4216557988","pt":1631553158046,"mc":[{"id":"1.187566733","rc":[{"batl":[[2,4,7.5]],"ltp":3.7,"tv":618.41,"id":8734382}]}]}
{"op":"mcm","clk":"4216558065","pt":1631553159149,"mc":[{"id":"1.187566733","rc":[{"batl":[[0,1.38,145.34]],"ltp":1.37,"tv":19995.9,"id":9323645}]}]}
{"op":"mcm","clk":"4216558173","pt":1631553160150,"mc":[{"id":"1.187566733","rc":[{"batl":[[0,1.38,337.99]],"ltp":1.37,"tv":19995.9,"id":9323645}]}]}
{"op":"mcm","clk":"4216558364","pt":1631553162468,"mc":[{"id":"1.187566733","rc":[{"batl":[[0,1.38,509.99]],"ltp":1.37,"tv":19995.9,"id":9323645}]}]}
{"op":"mcm","clk":"4216558959","pt":1631553168758,"mc":[{"id":"1.187566733","rc":[{"batb":[[0,3.4,7.51],[1,3.35,7.87],[2,3.3,7.58]],"ltp":3.7,"tv":618.41,"id":8734382},{"batb":[[0,1.36,2.43],[1,1.32,12.7],[2,1.3,118.83]],"batl":[[0,1.38,364.65],[1,1.41,163.5],[2,1.42,156.25]],"ltp":1.37,"tv":19995.9,"id":9323645}]}]}
{"op":"mcm","clk":"4216559026","pt":1631553169547,"mc":[{"id":"1.187566733","rc":[{"batl":[[0,1.38,192.65]],"ltp":1.37,"tv":19995.9,"id":9323645}]}]}
{"op":"mcm","clk":"4216559178","pt":1631553171749,"mc":[{"id":"1.187566733","rc":[{"batb":[[2,1.3,393.34]],"ltp":1.37,"tv":19995.9,"id":9323645}]}]}
{"op":"mcm","clk":"4216559238","pt":1631553172569,"mc":[{"id":"1.187566733","rc":[{"batb":[[2,1.3,118.83]],"ltp":1.37,"tv":19995.9,"id":9323645}]}]}
{"op":"mcm","clk":"4216559537","pt":1631553175656,"mc":[{"id":"1.187566733","rc":[{"batb":[[1,1.35,78.21],[2,1.34,170.02]],"batl":[[0,1.38,402.59],[1,1.39,139.97],[2,1.41,163.5]],"ltp":1.37,"tv":19995.9,"id":9323645}]}]}
{"op":"mcm","clk":"4216559809","pt":1631553178771,"mc":[{"id":"1.187566733","rc":[{"trd":[[3.8,0.87],[3.9,19.13]],"ltp":3.9,"tv":638.41,"id":8734382},{"trd":[[1.35,3535.62],[1.36,1045.92]],"batb":[[0,1.35,22.95],[1,1.34,170.02],[2,1.32,12.7]],"ltp":1.35,"tv":20053.59,"id":9323645}],"tv":20692.0}]}
{"op":"mcm","clk":"4216559893","pt":1631553179672,"mc":[{"id":"1.187566733","rc":[{"batb":[[0,1.32,12.7],[1,1.3,118.83],[2,1.06,284.46]],"batl":[[0,1.38,192.65],[1,1.41,163.5],[2,1.42,156.25]],"ltp":1.35,"tv":20053.59,"id":9323645}]}]}
{"op":"mcm","clk":"4216560126","pt":1631553182166,"mc":[{"id":"1.187566733","rc":[{"batb":[[2,1.1,299.23]],"batl":[[0,1.37,108.51],[1,1.38,192.65],[2,1.41,163.5]],"ltp":1.35,"tv":20053.59,"id":9323645}]}]}
{"op":"mcm","clk":"4216560157","pt":1631553182478,"mc":[{"id":"1.187566733","rc":[{"batl":[[0,1.38,192.65],[1,1.41,163.5],[2,1.42,156.25]],"ltp":1.35,"tv":20053.59,"id":9323645}]}]}
{"op":"mcm","clk":"4216560307","pt":1631553183654,"mc":[{"id":"1.187566733","rc":[{"batb":[[1,1.3,361.3],[2,1.29,211.83]],"batl":[[2,1.42,239.17]],"ltp":1.35,"tv":20053.59,"id":9323645}]}]}
{"op":"mcm","clk":"4216560625","pt":1631553186986,"mc":[{"id":"1.187566733","rc":[{"batb":[[1,1.3,118.83],[2,1.1,299.23]],"batl":[[0,1.41,163.5],[1,1.42,239.17],[2,1.43,273.52]],"ltp":1.35,"tv":20053.59,"id":9323645}]}]}
{"op":"mcm","clk":"4216560658","pt":1631553187255,"mc":[{"id":"1.187566733","rc":[{"batb":[[0,3.3,7.58],[1,3,34.83],[2,2,11.97]],"ltp":3.9,"tv":638.41,"id":8734382},{"batl":[[0,1.42,82.92],[1,1.43,273.52],[2,1.47,2]],"ltp":1.35,"tv":20053.59,"id":9323645}]}]}
{"op":"mcm","clk":"4216560842","pt":1631553189168,"mc":[{"id":"1.187566733","rc":[{"batl":[[0,3.55,4.52],[1,3.6,205.39],[2,4.1,2.44]],"ltp":3.9,"tv":638.41,"id":8734382},{"batb":[[0,1.39,156.15],[1,1.38,246.13],[2,1.37,95.64]],"batl":[[0,1.41,16.99],[1,1.42,82.92],[2,1.43,273.52]],"ltp":1.35,"tv":20053.59,"id":9323645}]}]}
{"op":"mcm","clk":"4216560913","pt":1631553189963,"mc":[{"id":"1.187566733","rc":[{"batb":[[2,2.94,38.1]],"ltp":3.9,"tv":638.41,"id":8734382},{"batb":[[0,1.39,242.5]],"batl":[[0,1.4,7.14],[1,1.41,16.99],[2,1.42,82.92]],"ltp":1.35,"tv":20053.59,"id":9323645}]}]}
{"op":"mcm","clk":"4216561289","pt":1631553194194,"mc":[{"id":"1.187566733","rc":[{"trd":[[3.5,9.86]],"ltp":3.5,"tv":641.27,"id":8734382},{"trd":[[1.4,1360.63]],"batl":[[0,1.41,16.99],[1,1.42,82.92],[2,1.43,459.43]],"ltp":1.4,"tv":20060.73,"id":9323645}],"tv":20702.0}]}
{"op":"mcm","clk":"4216561389","pt":1631553195085,"mc":[{"id":"1.187566733","rc":[{"batl":[[0,1.4,302],[1,1.41,122.42],[2,1.42,82.92]],"ltp":1.4,"tv":20060.73,"id":9323645}]}]}
{"op":"mcm","clk":"4216561464","pt":1631553195669,"mc":[{"id":"1.187566733","rc":[{"batb":[[0,3.4,7.86],[1,3.35,7.67],[2,3.3,7.58]],"batl":[[2,3.75,2.7]],"ltp":3.5,"tv":641.27,"id":8734382},{"batb":[[2,1.37,165.41]],"batl":[[1,1.41,284.92],[2,1.42,244.67]],"ltp":1.4,"tv":20060.73,"id":9323645}]}]}
{"op":"mcm","clk":"4216561713","pt":1631553198207,"mc":[{"id":"1.187566733","rc":[{"batl":[[2,3.65,3.1]],"ltp":3.5,"tv":641.27,"id":8734382},{"batb":[[1,1.38,313.59]],"batl":[[0,1.4,404.51]],"ltp":1.4,"tv":20060.73,"id":9323645}]}]}
{"op":"mcm","clk":"4216561977","pt":1631553201009,"mc":[{"id":"1.187566733","rc":[{"trd":[[1.39,979.49]],"batb":[[0,1.39,42.5]],"ltp":1.39,"tv":20460.73,"id":9323645}],"tv":21102.0}]}
{"op":"mcm","clk":"4216562272","pt":1631553204211,"mc":[{"id":"1.187566733","rc":[{"trd":[[1.4,1364.63]],"batb":[[1,1.38,384.1],[2,1.37,319.59]],"batl":[[0,1.4,402.51],[2,1.42,328.8]],"ltp":1.4,"tv":20464.73,"id":9323645}],"tv":21106.0}]}
{"op":"mcm","clk":"4216562847","pt":1631553210093,"mc":[{"id":"1.187566733","rc":[{"batl":[[0,3.8,3.02],[1,3.6,0],[2,3.65,0]],"ltp":3.5,"tv":641.27,"id":8734382},{"batb":[[0,1.36,66.93],[1,1.35,99.53],[2,1.32,12.7]],"batl":[[0,1.4,300],[1,1.41,162.5],[2,1.42,161.75]],"ltp":1.4,"tv":20464.73,"id":9323645}]}]}
{"op":"mcm","clk":"4216562912","pt":1631553210783,"mc":[{"id":"1.187566733","rc":[{"batb":[[0,3.35,7.67],[1,3.3,7.58],[2,2.94,38.1]],"ltp":3.5,"tv":641.27,"id":8734382},{"batl":[[0,1.38,500],[1,1.42,161.75],[2,1.43,335.41]],"ltp":1.4,"tv":20464.73,"id":9323645}]}]}
{"op":"mcm","clk":"4216563128","pt":1631553213098,"mc":[{"id":"1.187566733","rc":[{"batb":[[2,2.96,37.34]],"ltp":3.5,"tv":641.27,"id":8734382},{"batb":[[1,1.35,214.31],[2,1.34,272.64]],"ltp":1.4,"tv":20464.73,"id":9323645}]}]}
{"op":"mcm","clk":"4216563239","pt":1631553214203,"mc":[{"id":"1.187566733","rc":[{"batb":[[0,3.4,7.36],[1,3.35,7.67],[2,3.3,7.58]],"ltp":3.5,"tv":641.27,"id":8734382},{"batb":[[1,1.35,114.78]],"batl":[[0,1.41,168.5]],"ltp":1.4,"tv":20464.73,"id":9323645}]}]}
{"op":"mcm","clk":"4216563266","pt":1631553214412,"mc":[{"id":"1.187566733","rc":[{"batb":[[0,3.35,7.67],[1,3.3,7.58],[2,2.96,37.34]],"ltp":3.5,"tv":641.27,"id":8734382},{"batl":[[0,1.42,161.75],[1,1.43,335.41],[2,1.44,77.38]],"ltp":1.4,"tv":20464.73,"id":9323645}]}]}
{"op":"mcm","clk":"4216563538","pt":1631553217112,"mc":[{"id":"1.187566733","rc":[{"batl":[[0,1.38,101.35],[1,1.41,98.94],[2,1.42,161.75]],"ltp":1.4,"tv":20464.73,"id":9323645}]}]}
{"op":"mcm","clk":"4216563615","pt":1631553218009,"mc":[{"id":"1.187566733","rc":[{"batl":[[0,1.4,98.79]],"ltp":1.4,"tv":20464.73,"id":9323645}]}]}
{"op":"mcm","clk":"4216563850","pt":1631553220593,"mc":[{"id":"1.187566733","rc":[{"batl":[[0,1.41,98.94],[1,1.42,161.75],[2,1.43,335.41]],"ltp":1.4,"tv":20464.73,"id":9323645}]}]}
{"op":"mcm","clk":"4216563966","pt":1631553221714,"mc":[{"id":"1.187566733","rc":[{"batl":[[0,1.42,161.75],[1,1.43,335.41],[2,1.44,77.38]],"ltp":1.4,"tv":20464.73,"id":9323645}]}]}
{"op":"mcm","clk":"4216564802","pt":1631553229915,"mc":[{"id":"1.187566733","rc":[{"batb":[[1,1.34,101.04],[2,1.32,12.7]],"ltp":1.4,"tv":20464.73,"id":9323645}]}]}
{"op":"mcm","clk":"4216564924","pt":1631553231025,"mc":[{"id":"1.187566733","rc":[{"batl":[[0,3.75,3.26],[1,3.8,3.02]],"ltp":3.5,"tv":641.27,"id":8734382},{"batb":[[0,1.37,59.77],[1,1.36,66.93],[2,1.34,101.04]],"batl":[[1,1.43,149.5]],"ltp":1.4,"tv":20464.73,"id":9323645}]}]}
{"op":"mcm","clk":"4216564996","pt":1631553231717,"mc":[{"id":"1.187566733","rc":[{"batb":[[0,3.4,7.71],[1,3.35,7.67]],"batl":[[0,3.8,3.02],[1,3.8,0]],"ltp":3.5,"tv":641.27,"id":8734382},{"batb":[[0,1.36,66.93],[1,1.34,101.04],[2,1.32,12.7]],"batl":[[0,1.41,166.5],[1,1.42,161.75]],"ltp":1.4,"tv":20464.73,"id":9323645}]}]}
{"op":"mcm","clk":"4216565106","pt":1631553232924,"mc":[{"id":"1.187566733","rc":[{"batb":[[0,3.35,7.67],[1,3.3,7.03]],"batl":[[1,3.9,2.56]],"ltp":3.5,"tv":641.27,"id":8734382},{"batb":[[0,1.41,802.14],[1,1.4,159.6],[2,1.39,10.72]],"batl":[[0,1.42,161.75],[1,1.44,77.38],[2,1.45,117.19]],"ltp":1.4,"tv":20464.73,"id":9323645}]}]}
{"op":"mcm","clk":"4216565217","pt":1631553234026,"mc":[{"id":"1.187566733","rc":[{"batb":[[2,3.2,9.38]],"ltp":3.5,"tv":641.27,"id":8734382},{"batb":[[0,1.41,884.05]],"batl":[[1,1.43,6.99],[2,1.44,77.38]],"ltp":1.4,"tv":20464.73,"id":9323645}]}]}
{"op":"mcm","clk":"4216565374","pt":1631553235518,"mc":[{"id":"1.187566733","rc":[{"batb":[[2,1.39,232.72]],"ltp":1.4,"tv":20464.73,"id":9323645}]}]}
{"op":"mcm","clk":"4216565473","pt":1631553236438,"mc":[{"id":"1.187566733","rc":[{"trd":[[1.41,1264.1]],"batb":[[0,1.41,614.95]],"ltp":1.41,"tv":21002.93,"id":9323645}],"tv":21644.2}]}
{"op":"mcm","clk":"4216565632","pt":1631553238133,"mc":[{"id":"1.187566733","rc":[{"trd":[[3.35,76.27]],"batb":[[0,3.3,7.03],[1,3.2,9.38],[2,3.15,4.68]],"batl":[[0,3.7,2.89],[1,3.8,3.02],[2,3.9,2.56]],"ltp":3.35,"tv":717.54,"id":8734382},{"trd":[[1.42,908.44]],"batl":[[0,1.42,205.23],[1,1.43,93.4]],"ltp":1.42,"tv":21146.67,"id":9323645}],"tv":21864.21}]}
{"op":"mcm","clk":"4216566018","pt":1631553241929,"mc":[{"id":"1.187566733","rc":[{"batl":[[0,1.42,451.23]],"ltp":1.42,"tv":21146.67,"id":9323645}]}]}
{"op":"mcm","clk":"4216566672","pt":1631553248637,"mc":[{"id":"1.187566733","rc":[{"batb":[[2,1.39,10.72]],"ltp":1.42,"tv":21146.67,"id":9323645}]}]}
{"op":"mcm","clk":"4216566804","pt":1631553249844,"mc":[{"id":"1.187566733","rc":[{"batl":[[0,1.42,558.88]],"ltp":1.42,"tv":21146.67,"id":9323645}]}]}
{"op":"mcm","clk":"4216567024","pt":1631553252447,"mc":[{"id":"1.187566733","rc":[{"trd":[[1.41,1687.58]],"batb":[[0,1.41,403.21]],"ltp":1.41,"tv":21570.15,"id":9323645}],"tv":22287.69}]}
{"op":"mcm","clk":"4216567612","pt":1631553258261,"mc":[{"id":"1.187566733","rc":[{"trd":[[1.41,1691.92]],"batb":[[0,1.41,401.04]],"ltp":1.41,"tv":21574.49,"id":9323645}],"tv":22292.03}]}
{"op":"mcm","clk":"4216568198","pt":1631553264269,"mc":[{"id":"1.187566733","rc":[{"trd":[[3.35,114.48]],"ltp":3.35,"tv":755.75,"id":8734382},{"trd":[[1.42,998.59]],"batl":[[0,1.42,468.73]],"ltp":1.42,"tv":21664.64,"id":9323645}],"tv":22420.39}]}
{"op":"mcm","clk":"4216568551","pt":1631553267765,"mc":[{"id":"1.187566733","rc":[{"batb":[[0,2.92,7.69],[1,2.68,19.47],[2,2,11.97]],"batl":[[2,3.9,0]],"ltp":3.35,"tv":755.75,"id":8734382},{"batb":[[0,1.37,91.47],[1,1.32,12.7],[2,1.15,359.07]],"batl":[[0,1.42,361.08],[1,1.47,2],[2,1.49,129.5]],"ltp":1.42,"tv":21664.64,"id":9323645}]}]}
{"op":"mcm","clk":"4216568632","pt":1631553268557,"mc":[{"id":"1.187566733","rc":[{"batl":[[0,1.42,115.08]],"ltp":1.42,"tv":21664.64,"id":9323645}]}]}
{"op":"mcm","clk":"4216568873","pt":1631553271197,"mc":[{"id":"1.187566733","rc":[{"batb":[[0,1.37,269.98],[1,1.36,229.54],[2,1.32,12.7]],"ltp":1.42,"tv":21664.64,"id":9323645}]}]}
{"op":"mcm","clk":"4216568959","pt":1631553271975,"mc":[{"id":"1.187566733","rc":[{"batb":[[0,1.37,91.47],[1,1.36,69.93]],"ltp":1.42,"tv":21664.64,"id":9323645}]}]}
{"op":"mcm","clk":"4216569103","pt":1631553273555,"mc":[{"id":"1.187566733","rc":[{"batl":[[0,1.47,2],[1,1.5,10.79],[2,1.52,136.53]],"ltp":1.42,"tv":21664.64,"id":9323645}]}]}
{"op":"mcm","clk":"4216569250","pt":1631553275068,"mc":[{"id":"1.187566733","rc":[{"batb":[[0,1.42,195.64],[1,1.41,133.98],[2,1.37,91.47]],"batl":[[0,1.46,127.46],[1,1.47,112.15],[2,1.5,10.79]],"ltp":1.42,"tv":21664.64,"id":9323645}]}]}
{"op":"mcm","clk":"4216569456","pt":1631553277197,"mc":[{"id":"1.187566733","rc":[{"batl":[[0,1.44,113.48],[1,1.46,127.46],[2,1.47,112.15]],"ltp":1.42,"tv":21664.64,"id":9323645}]}]}
{"op":"mcm","clk":"4216569576","pt":1631553278178,"mc":[{"id":"1.187566733","rc":[{"batl":[[0,3.65,3.1],[1,3.7,2.89],[2,3.8,3.02]],"ltp":3.35,"tv":755.75,"id":8734382},{"batb":[[2,1.38,66.96]],"ltp":1.42,"tv":21664.64,"id":9323645}]}]}
{"op":"mcm","clk":"4216569645","pt":1631553278873,"mc":[{"id":"1.187566733","rc":[{"batl":[[0,3.7,2.89],[1,3.8,3.02],[2,3.8,0]],"ltp":3.35,"tv":755.75,"id":8734382},{"batb":[[0,1.37,91.47],[1,1.36,69.93],[2,1.32,12.7]],"batl":[[1,1.47,2],[2,1.49,59.5]],"ltp":1.42,"tv":21664.64,"id":9323645}]}]}
{"op":"mcm","clk":"4216569776","pt":1631553280157,"mc":[{"id":"1.187566733","rc":[{"batl":[[1,1.45,190],[2,1.47,2]],"ltp":1.42,"tv":21664.64,"id":9323645}]}]}
{"op":"mcm","clk":"4216569846","pt":1631553280855,"mc":[{"id":"1.187566733","rc":[{"batb":[[0,1.38,2.64],[1,1.37,91.47],[2,1.36,69.93]],"batl":[[1,1.47,2],[2,1.49,59.5]],"ltp":1.42,"tv":21664.64,"id":9323645}]}]}
{"op":"mcm","clk":"4216569965","pt":1631553282087,"mc":[{"id":"1.187566733","rc":[{"batl":[[0,3.65,3.5],[1,3.7,2.89],[2,3.8,3.02]],"ltp":3.35,"tv":755.75,"id":8734382},{"batb":[[0,1.38,64.1],[1,1.37,269.98],[2,1.36,229.54]],"ltp":1.42,"tv":21664.64,"id":9323645}]}]}
{"op":"mcm","clk":"4216569994","pt":1631553282362,"mc":[{"id":"1.187566733","rc":[{"batl":[[0,3.7,2.89],[1,3.8,3.02],[2,3.8,0]],"ltp":3.35,"tv":755.75,"id":8734382},{"batb":[[0,1.38,2.64]],"ltp":1.42,"tv":21664.64,"id":9323645}]}]}
{"op":"mcm","clk":"4216570524","pt":1631553287892,"mc":[{"id":"1.187566733","rc":[{"batl":[[2,1000,2]],"ltp":3.35,"tv":755.75,"id":8734382}]}]}
{"op":"mcm","clk":"4216570642","pt":1631553289104,"mc":[{"id":"1.187566733","rc":[{"batl":[[0,3.65,2.7],[1,3.7,2.89],[2,3.8,3.02]],"ltp":3.35,"tv":755.75,"id":8734382},{"batb":[[0,1.38,73.1]],"ltp":1.42,"tv":21664.64,"id":9323645}]}]}
{"op":"mcm","clk":"4216570671","pt":1631553289387,"mc":[{"id":"1.187566733","rc":[{"batl":[[0,3.7,2.89],[1,3.8,3.02],[2,1000,2]],"ltp":3.35,"tv":755.75,"id":8734382},{"batb":[[0,1.38,2.64]],"ltp":1.42,"tv":21664.64,"id":9323645}]}]}
{"op":"mcm","clk":"4216570835","pt":1631553291196,"mc":[{"id":"1.187566733","rc":[{"batb":[[0,3.5,23.06],[1,3.45,4.28],[2,3.4,245.2]],"batl":[[1,3.75,202.59],[2,3.8,3.02]],"ltp":3.35,"tv":755.75,"id":8734382},{"batb":[[0,1.38,16.23]],"batl":[[0,1.39,7.19],[1,1.4,177.6],[2,1.41,132.86]],"ltp":1.42,"tv":21664.64,"id":9323645}]}]}
{"op":"mcm","clk":"4216571125","pt":1631553294205,"mc":[{"id":"1.187566733","rc":[{"batl":[[0,1.39,124.76]],"ltp":1.42,"tv":21664.64,"id":9323645}]}]}
{"op":"mcm","clk":"4216571195","pt":1631553294789,"mc":[{"id":"1.187566733","rc":[{"trd":[[3.55,7.82]],"ltp":3.55,"tv":756.0,"id":8734382},{"trd":[[1.39,980.13]],"batl":[[0,1.39,124.12],[1,1.4,308.64]],"ltp":1.39,"tv":21665.28,"id":9323645}],"tv":22421.28}]}
{"op":"mcm","clk":"4216571280","pt":1631553295586,"mc":[{"id":"1.187566733","rc":[{"trd":[[3.55,52.37]],"ltp":3.55,"tv":800.55,"id":8734382},{"trd":[[1.39,1093.91]],"batl":[[0,1.39,10.34]],"ltp":1.39,"tv":21779.06,"id":9323645}],"tv":22579.61}]}
{"op":"mcm","clk":"4216571392","pt":1631553296488,"mc":[{"id":"1.187566733","rc":[{"batl":[[0,1.39,333.34]],"ltp":1.39,"tv":21779.06,"id":9323645}]}]}
{"op":"mcm","clk":"4216571503","pt":1631553297606,"mc":[{"id":"1.187566733","rc":[{"batl":[[0,1.39,455.98]],"ltp":1.39,"tv":21779.06,"id":9323645}]}]}
{"op":"mcm","clk":"4216572393","pt":1631553305137,"mc":[{"id":"1.187566733","rc":[{"batb":[[0,3.3,3.18],[1,3.2,4.32],[2,2.92,7.69]],"batl":[[1,3.8,3.02],[2,3.9,2.75]],"ltp":3.55,"tv":800.55,"id":8734382},{"batb":[[0,1.38,2.64],[1,1.36,69.93],[2,1.35,60.67]],"batl":[[1,1.4,131.04],[2,1.43,64.5]],"ltp":1.39,"tv":21779.06,"id":9323645}]}]}
{"op":"mcm","clk":"4216572473","pt":1631553305843,"mc":[{"id":"1.187566733","rc":[{"batb":[[0,3.2,4.32],[1,2.84,41.54],[2,2,11.97]],"batl":[[1,3.9,2.75],[2,3.9,0]],"ltp":3.55,"tv":800.55,"id":8734382},{"batb":[[1,1.35,60.67],[2,1.34,100.28]],"batl":[[0,1.39,10.34],[1,1.45,64.3],[2,1.47,2]],"ltp":1.39,"tv":21779.06,"id":9323645}]}]}
{"op":"mcm","clk":"4216572727","pt":1631553308129,"mc":[{"id":"1.187566733","rc":[{"batb":[[2,1.34,314.11]],"batl":[[2,1.47,169.63]],"ltp":1.39,"tv":21779.06,"id":9323645}]}]}
{"op":"mcm","clk":"4216572813","pt":1631553309030,"mc":[{"id":"1.187566733","rc":[{"batb":[[0,3.3,3.68],[1,3.2,4.32],[2,2.84,41.54]],"ltp":3.55,"tv":800.55,"id":8734382},{"batb":[[2,1.34,100.28]],"batl":[[1,1.43,70.5],[2,1.45,64.3]],"ltp":1.39,"tv":21779.06,"id":9323645}]}]}
{"op":"mcm","clk":"4216572847","pt":1631553309308,"mc":[{"id":"1.187566733","rc":[{"batb":[[0,3.2,4.32],[1,2.84,41.54],[2,2,11.97]],"ltp":3.55,"tv":800.55,"id":8734382},{"batl":[[1,1.45,64.3],[2,1.47,2]],"ltp":1.39,"tv":21779.06,"id":9323645}]}]}
{"op":"mcm","clk":"4216572993","pt":1631553310834,"mc":[{"id":"1.187566733","rc":[{"batb":[[0,1.38,194.65],[1,1.37,153.97],[2,1.35,60.67]],"batl":[[1,1.42,191.46],[2,1.43,123.89]],"ltp":1.39,"tv":21779.06,"id":9323645}]}]}
{"op":"mcm","clk":"4216573123","pt":1631553312147,"mc":[{"id":"1.187566733","rc":[{"batl":[[1,3.8,2.97],[2,3.9,2.75]],"ltp":3.55,"tv":800.55,"id":8734382},{"batb":[[2,1.36,69.68]],"ltp":1.39,"tv":21779.06,"id":9323645}]}]}
{"op":"mcm","clk":"4216573165","pt":1631553312520,"mc":[{"id":"1.187566733","rc":[{"batb":[[0,3.3,3.48],[1,3.2,4.32],[2,2.84,41.54]],"ltp":3.55,"tv":800.55,"id":8734382},{"batl":[[2,1.43,190.39]],"ltp":1.39,"tv":21779.06,"id":9323645}]}]}
{"op":"mcm","clk":"4216573285","pt":1631553313852,"mc":[{"id":"1.187566733","rc":[{"batb":[[0,3.2,4.32],[1,2.84,41.54],[2,2,11.97]],"batl":[[1,3.9,2.75],[2,3.9,0]],"ltp":3.55,"tv":800.55,"id":8734382},{"batb":[[0,1.38,2.64],[1,1.35,60.67],[2,1.34,100.28]],"batl":[[1,1.45,64.3],[2,1.47,2]],"ltp":1.39,"tv":21779.06,"id":9323645}]}]}
{"op":"mcm","clk":"4216573379","pt":1631553314713,"mc":[{"id":"1.187566733","rc":[{"trd":[[1.39,1114.59]],"batb":[[0,1.39,23.66],[1,1.38,2.64],[2,1.35,60.67]],"batl":[[0,1.45,64.3],[1,1.47,2],[2,1.5,10.79]],"ltp":1.39,"tv":21799.74,"id":9323645}],"tv":22600.29}]}
{"op":"mcm","clk":"4216573630","pt":1631553317036,"mc":[{"id":"1.187566733","rc":[{"batb":[[0,3.3,3.68],[1,3.2,4.32],[2,2.84,41.54]],"batl":[[1,3.8,3.12],[2,3.9,2.75]],"ltp":3.55,"tv":800.55,"id":8734382},{"batb":[[2,1.36,72.68]],"batl":[[0,1.43,67.5],[1,1.45,64.3],[2,1.47,169.63]],"ltp":1.39,"tv":21799.74,"id":9323645}]}]}
{"op":"mcm","clk":"4216573704","pt":1631553317837,"mc":[{"id":"1.187566733","rc":[{"batb":[[0,3.2,4.32],[1,2.84,41.54],[2,2,11.97]],"batl":[[1,3.9,2.75],[2,3.9,0]],"ltp":3.55,"tv":800.55,"id":8734382},{"trd":[[1.39,1118.63]],"batb":[[0,1.39,21.64],[2,1.35,60.67]],"batl":[[0,1.45,64.3],[1,1.47,169.63],[2,1.48,106.8]],"ltp":1.39,"tv":21803.78,"id":9323645}],"tv":22604.33}]}
{"op":"mcm","clk":"4216574192","pt":1631553323041,"mc":[{"id":"1.187566733","rc":[{"batb":[[0,3.2,10.58],[1,3.1,230.23],[2,3.05,44.58]],"batl":[[0,3.3,6.02],[1,3.4,40],[2,3.45,38.82]],"ltp":3.55,"tv":800.55,"id":8734382},{"batb":[[0,1.43,339.74],[1,1.42,129.28],[2,1.41,700.39]],"ltp":1.39,"tv":21803.78,"id":9323645}]}]}
{"op":"mcm","clk":"4216574294","pt":1631553323923,"mc":[{"id":"1.187566733","rc":[{"batb":[[0,1.43,415.1]],"batl":[[0,1.45,71.2]],"ltp":1.39,"tv":21803.78,"id":9323645}]}]}
{"op":"mcm","clk":"4216574933","pt":1631553330718,"mc":[{"id":"1.187566733","rc":[{"batl":[[0,1.45,378.27]],"ltp":1.39,"tv":21803.78,"id":9323645}]}]}
{"op":"mcm","clk":"4216575296","pt":1631553334472,"mc":[{"id":"1.187566733","rc":[{"batb":[[0,1.43,214.49]],"ltp":1.39,"tv":21803.78,"id":9323645}]}]}
{"op":"mcm","clk":"4216575485","pt":1631553336571,"mc":[{"id":"1.187566733","rc":[{"trd":[[1.43,2358.95]],"batb":[[0,1.43,209.98]],"ltp":1.43,"tv":21812.8,"id":9323645}],"tv":22613.35}]}
{"op":"mcm","clk":"4216576104","pt":1631553343201,"mc":[{"id":"1.187566733","rc":[{"batb":[[0,2.84,46.26],[1,2.74,4.29],[2,2.54,22.32]],"batl":[[0,3.65,5.1],[1,3.7,2.89],[2,3.8,4.97]],"ltp":3.55,"tv":800.55,"id":8734382},{"batb":[[2,1.39,108.33]],"batl":[[0,1.45,307.07]],"ltp":1.43,"tv":21812.8,"id":9323645}]}]}
{"op":"mcm","clk":"4216576165","pt":1631553343680,"mc":[{"id":"1.187566733","rc":[{"batb":[[0,2.74,4.29],[1,2.54,22.32],[2,2,11.97]],"ltp":3.55,"tv":800.55,"id":8734382},{"batb":[[0,1.39,108.33],[1,1.38,79.06],[2,1.36,70.86]],"batl":[[0,1.47,2],[1,1.5,10.79],[2,1.57,58.02]],"ltp":1.43,"tv":21812.8,"id":9323645}]}]}
{"op":"mcm","clk":"4216576269","pt":1631553344539,"mc":[{"id":"1.187566733","rc":[{"batb":[[0,1.45,1.8],[1,1.39,108.33],[2,1.38,79.06]],"ltp":1.43,"tv":21812.8,"id":9323645}]}]}
{"op":"mcm","clk":"4216576512","pt":1631553346962,"mc":[{"id":"1.187566733","rc":[{"batb":[[0,2.84,5.22],[1,2.74,4.29],[2,2.54,22.32]],"ltp":3.55,"tv":800.55,"id":8734382},{"batb":[[2,1.38,264.81]],"batl":[[2,1.54,58.77]],"ltp":1.43,"tv":21812.8,"id":9323645}]}]}
{"op":"mcm","clk":"4216576558","pt":1631553347375,"mc":[{"id":"1.187566733","rc":[{"batb":[[0,2.74,4.29],[1,2.54,22.32],[2,2,11.97]],"ltp":3.55,"tv":800.55,"id":8734382},{"batl":[[2,1.57,176.11]],"ltp":1.43,"tv":21812.8,"id":9323645}]}]}
{"op":"mcm","clk":"4216576903","pt":1631553351047,"mc":[{"id":"1.187566733","rc":[{"batb":[[0,1.39,108.33],[1,1.38,264.81],[2,1.37,153.93]],"ltp":1.43,"tv":21812.8,"id":9323645}]}]}
{"op":"mcm","clk":"4216577242","pt":1631553354164,"mc":[{"id":"1.187566733","rc":[{"batb":[[0,2.84,4.72],[1,2.74,4.29],[2,2.54,22.32]],"ltp":3.55,"tv":800.55,"id":8734382},{"batl":[[2,1.54,61.77]],"ltp":1.43,"tv":21812.8,"id":9323645}]}]}
{"op":"mcm","clk":"4216577267","pt":1631553354484,"mc":[{"id":"1.187566733","rc":[{"batb":[[0,2.74,4.29],[1,2.54,22.32],[2,2,11.97]],"ltp":3.55,"tv":800.55,"id":8734382},{"batl":[[2,1.57,176.11]],"ltp":1.43,"tv":21812.8,"id":9323645}]}]}
{"op":"mcm","clk":"4216577687","pt":1631553358408,"mc":[{"id":"1.187566733","rc":[{"batb":[[1,1.38,79.06],[2,1.36,70.86]],"ltp":1.43,"tv":21812.8,"id":9323645}]}]}
{"op":"mcm","clk":"4216577958","pt":1631553361160,"mc":[{"id":"1.187566733","rc":[{"trd":[[2.96,0.27],[3,36.06],[3.1,0.95]],"batl":[[0,2.92,9.78],[1,2.94,51.02],[2,2.96,92.81]],"ltp":2.96,"tv":807.16,"id":8734382},{"trd":[[1.47,338.36],[1.5,174.87],[1.51,0.52]],"batb":[[0,1.51,2.48],[1,1.5,254.38],[2,1.39,108.33]],"batl":[[0,1.56,22.99],[1,1.57,175.59],[2,1.58,561.91]],"ltp":1.51,"tv":21826.11,"id":9323645}],"tv":22633.28}]}
{"op":"mcm","clk":"4216578066","pt":1631553362181,"mc":[{"id":"1.187566733","rc":[{"batb":[[2,2.16,34.83]],"batl":[[1,2.94,30.61],[2,2.96,55.85]],"ltp":2.96,"tv":807.16,"id":8734382},{"trd":[[1.53,3.32]],"batb":[[0,1.53,141.4],[1,1.52,95.77],[2,1.51,2.48]],"batl":[[0,1.54,6.49],[1,1.56,22.99],[2,1.57,175.59]],"ltp":1.53,"tv":21829.43,"id":9323645}],"tv":22636.6}]}
{"op":"mcm","clk":"4216578480","pt":1631553366204,"mc":[{"id":"1.187566733","rc":[{"batl":[[0,2.88,45.29],[1,2.92,9.78],[2,2.94,30.61]],"ltp":2.96,"tv":807.16,"id":8734382},{"batl":[[1,1.55,94.91],[2,1.56,22.99]],"ltp":1.53,"tv":21829.43,"id":9323645}]}]}
{"op":"mcm","clk":"4216578580","pt":1631553367091,"mc":[{"id":"1.187566733","rc":[{"batl":[[0,2.92,9.78],[1,2.94,30.61],[2,2.96,55.85]],"ltp":2.96,"tv":807.16,"id":8734382},{"trd":[[1.53,63.02],[1.54,13.28]],"batb":[[0,1.53,111.55]],"batl":[[0,1.55,94.91],[1,1.56,22.99],[2,1.57,175.59]],"ltp":1.53,"tv":21902.41,"id":9323645}],"tv":22709.58}]}
{"op":"mcm","clk":"4216578675","pt":1631553368196,"mc":[{"id":"1.187566733","rc":[{"batb":[[2,2.4,5.26]],"ltp":2.96,"tv":807.16,"id":8734382},{"batb":[[0,1.53,58.74]],"batl":[[0,1.54,185],[1,1.55,94.91],[2,1.56,22.99]],"ltp":1.53,"tv":21902.41,"id":9323645}]}]}
{"op":"mcm","clk":"4216578927","pt":1631553370681,"mc":[{"id":"1.187566733","rc":[{"trd":[[1.54,26.24]],"batb":[[1,1.52,163.22],[2,1.51,101.23]],"batl":[[0,1.54,262.63]],"ltp":1.54,"tv":21915.37,"id":9323645}],"tv":22722.53}]}
{"op":"mcm","clk":"4216579153","pt":1631553372804,"mc":[{"id":"1.187566733","rc":[{"trd":[[1.52,282.52],[1.53,180.51]],"batb":[[0,1.52,21.96],[1,1.51,101.23],[2,1.5,254.38]],"ltp":1.52,"tv":22315.37,"id":9323645}],"tv":23122.54}]}
{"op":"mcm","clk":"4216579439","pt":1631553375197,"mc":[{"id":"1.187566733","rc":[{"batb":[[0,2.54,22.32],[1,2.4,5.26],[2,2.38,6.46]],"batl":[[0,2.98,2.08],[1,3.35,2],[2,3.6,2]],"ltp":2.96,"tv":807.16,"id":8734382},{"batb":[[2,1.46,70.16]],"batl":[[0,1.54,178.52],[1,1.57,84.47],[2,1.71,49.5]],"ltp":1.52,"tv":22315.37,"id":9323645}]}]}
{"op":"mcm","clk":"4216579533","pt":1631553376101,"mc":[{"id":"1.187566733","rc":[{"trd":[[2.84,2.17]],"batb":[[0,2.4,5.26],[1,2.38,6.46],[2,2.28,6.66]],"batl":[[1,3.7,2.89],[2,3.6,0]],"ltp":2.84,"tv":809.33,"id":8734382},{"trd":[[1.54,30.24]],"batb":[[0,1.51,2.48],[1,1.46,70.16],[2,1.38,24.28]],"batl":[[0,1.54,174.52],[1,1.71,49.5],[2,1.72,50.66]],"ltp":1.54,"tv":22319.37,"id":9323645}],"tv":23128.71}]}
{"op":"mcm","clk":"4216579587","pt":1631553376702,"mc":[{"id":"1.187566733","rc":[{"batb":[[0,2.28,6.66],[1,2.16,34.83],[2,1.8,11.97]],"ltp":2.84,"tv":809.33,"id":8734382},{"batl":[[0,1.77,52.5],[1,44,7.23],[2,1.72,0]],"ltp":1.54,"tv":22319.37,"id":9323645}]}]}
{"op":"mcm","clk":"4216579754","pt":1631553378188,"mc":[{"id":"1.187566733","rc":[{"batl":[[1,3.5,2],[2,3.7,2.89]],"ltp":2.84,"tv":809.33,"id":8734382},{"batb":[[2,1.4,3.11]],"ltp":1.54,"tv":22319.37,"id":9323645}]}]}
{"op":"mcm","clk":"4216579863","pt":1631553379144,"mc":[{"id":"1.187566733","rc":[{"batb":[[1,2.2,33.9]],"batl":[[1,3.35,2],[2,3.6,2]],"ltp":2.84,"tv":809.33,"id":8734382},{"batb":[[1,1.44,71.83],[2,1.43,3.22]],"ltp":1.54,"tv":22319.37,"id":9323645}]}]}
{"op":"mcm","clk":"4216579963","pt":1631553379995,"mc":[{"id":"1.187566733","rc":[{"batb":[[0,2.4,6.31],[1,2.28,6.66],[2,2.2,33.9]],"batl":[[1,3.7,2.89],[2,3.6,0]],"ltp":2.84,"tv":809.33,"id":8734382},{"batb":[[2,1.38,24.28]],"batl":[[0,1.71,49.5],[1,1.77,52.5],[2,44,7.23]],"ltp":1.54,"tv":22319.37,"id":9323645}]}]}
{"op":"mcm","clk":"4216580053","pt":1631553380789,"mc":[{"id":"1.187566733","rc":[{"batb":[[0,2.28,6.66],[1,2.2,33.9],[2,1.8,11.97]],"ltp":2.84,"tv":809.33,"id":8734382},{"batl":[[0,1.53,573.82]],"ltp":1.54,"tv":22319.37,"id":9323645}]}]}
{"op":"mcm","clk":"4216580182","pt":1631553382119,"mc":[{"id":"1.187566733","rc":[{"trd":[[2.88,19.25]],"batb":[[0,2.72,18.59],[1,2.28,6.66],[2,2.2,33.9]],"ltp":2.88,"tv":828.58,"id":8734382},{"trd":[[1.53,216.74]],"batl":[[0,1.53,537.58],[1,1.58,19.25],[2,1.77,52.5]],"ltp":1.53,"tv":22355.61,"id":9323645}],"tv":23184.19}]}
{"op":"mcm","clk":"4216580260","pt":1631553382927,"mc":[{"id":"1.187566733","rc":[{"batb":[[0,2.28,6.66],[1,2.2,33.9],[2,1.8,11.97]],"ltp":2.88,"tv":828.58,"id":8734382},{"trd":[[1.53,716.42]],"batl":[[0,1.53,287.74],[1,1.59,122.58],[2,1.6,78.52]],"ltp":1.53,"tv":22855.29,"id":9323645}],"tv":23683.87}]}
{"op":"mcm","clk":"4216580373","pt":1631553383937,"mc":[{"id":"1.187566733","rc":[{"batb":[[0,2.4,6.01],[1,2.28,6.66],[2,2.2,33.9]],"ltp":2.88,"tv":828.58,"id":8734382},{"batl":[[1,1.71,50.5],[2,1.77,52.5]],"ltp":1.53,"tv":22855.29,"id":9323645}]}]}
{"op":"mcm","clk":"4216580573","pt":1631553386017,"mc":[{"id":"1.187566733","rc":[{"batl":[[1,3.35,2],[2,3.6,2]],"ltp":2.88,"tv":828.58,"id":8734382},{"batb":[[2,1.43,3.22]],"ltp":1.53,"tv":22855.29,"id":9323645}]}]}
{"op":"mcm","clk":"4216580649","pt":1631553386919,"mc":[{"id":"1.187566733","rc":[{"batb":[[0,2.28,6.66],[1,2.2,33.9],[2,1.8,11.97]],"batl":[[1,3.7,2.89],[2,3.6,0]],"ltp":2.88,"tv":828.58,"id":8734382},{"trd":[[1.53,868.32]],"batb":[[0,1.53,37.11],[1,1.52,96.51],[2,1.51,2.48]],"batl":[[0,1.57,93.01],[1,1.58,82.84]],"ltp":1.53,"tv":23007.19,"id":9323645}],"tv":23835.77}]}
{"op":"mcm","clk":"4216580854","pt":1631553388943,"mc":[{"id":"1.187566733","rc":[{"batl":[[0,3.7,2.89],[1,3.7,0]],"ltp":2.88,"tv":828.58,"id":8734382},{"batb":[[0,1.44,71.83],[1,1.38,24.28],[2,1.32,12.7]],"batl":[[0,1.77,52.5],[1,44,7.23],[2,810,0.07]],"ltp":1.53,"tv":23007.19,"id":9323645}]}]}
{"op":"mcm","clk":"4216580986","pt":1631553390113,"mc":[{"id":"1.187566733","rc":[{"batb":[[0,2.4,6.66],[1,2.28,6.66],[2,2.2,33.9]],"ltp":2.88,"tv":828.58,"id":8734382},{"batl":[[0,1.56,66.95],[1,1.71,54.5],[2,1.77,52.5]],"ltp":1.53,"tv":23007.19,"id":9323645}]}]}
{"op":"mcm","clk":"4216581110","pt":1631553390931,"mc":[{"id":"1.187566733","rc":[{"batb":[[0,2.28,6.66],[1,2.2,33.9],[2,1.8,11.97]],"ltp":2.88,"tv":828.58,"id":8734382},{"batl":[[0,1.77,52.5],[1,44,7.23],[2,810,0.07]],"ltp":1.53,"tv":23007.19,"id":9323645}]}]}
{"op":"mcm","clk":"4216581230","pt":1631553391832,"mc":[{"id":"1.187566733","rc":[{"batb":[[1,1.43,90.4],[2,1.42,130.4]],"batl":[[0,1.7,113],[1,1.71,61.72],[2,1.77,52.5]],"ltp":1.53,"tv":23007.19,"id":9323645}]}]}
{"op":"mcm","clk":"4216581371","pt":1631553393211,"mc":[{"id":"1.187566733","rc":[{"batl":[[0,3.35,2],[1,3.6,2],[2,3.7,2.89]],"ltp":2.88,"tv":828.58,"id":8734382},{"batb":[[1,1.43,93.62]],"ltp":1.53,"tv":23007.19,"id":9323645}]}]}
{"op":"mcm","clk":"4216581472","pt":1631553393843,"mc":[{"id":"1.187566733","rc":[{"batb":[[0,2.4,6.11],[1,2.28,6.66],[2,2.2,33.9]],"batl":[[0,3.6,2],[1,3.7,2.89],[2,3.7,0]],"ltp":2.88,"tv":828.58,"id":8734382},{"batb":[[1,1.43,90.4]],"batl":[[1,1.71,114.22]],"ltp":1.53,"tv":23007.19,"id":9323645}]}]}
{"op":"mcm","clk":"4216582060","pt":1631553400035,"mc":[{"id":"1.187566733","rc":[{"batl":[[0,3.35,2],[1,3.6,2],[2,3.7,2.89]],"ltp":2.88,"tv":828.58,"id":8734382},{"batb":[[1,1.43,93.62]],"ltp":1.53,"tv":23007.19,"id":9323645}]}]}
{"op":"mcm","clk":"4216582087","pt":1631553400344,"mc":[{"id":"1.187566733","rc":[{"batl":[[0,3.6,2],[1,3.7,2.89],[2,3.7,0]],"ltp":2.88,"tv":828.58,"id":8734382},{"batb":[[1,1.43,90.4]],"ltp":1.53,"tv":23007.19,"id":9323645}]}]}
{"op":"mcm","clk":"4216582745","pt":1631553407042,"mc":[{"id":"1.187566733","rc":[{"batl":[[0,3.35,2],[1,3.6,2],[2,3.7,2.89]],"ltp":2.88,"tv":828.58,"id":8734382},{"batb":[[1,1.43,93.62]],"ltp":1.53,"tv":23007.19,"id":9323645}]}]}
{"op":"mcm","clk":"4216582801","pt":1631553407532,"mc":[{"id":"1.187566733","rc":[{"batl":[[0,3.6,2],[1,3.7,2.89],[2,3.7,0]],"ltp":2.88,"tv":828.58,"id":8734382},{"batb":[[1,1.43,90.4]],"ltp":1.53,"tv":23007.19,"id":9323645}]}]}
{"op":"mcm","clk":"4216583052","pt":1631553409742,"mc":[{"id":"1.187566733","rc":[{"batl":[[0,3.7,2.89],[1,3.7,0]],"ltp":2.88,"tv":828.58,"id":8734382},{"batb":[[1,1.38,24.28],[2,1.32,12.7]],"ltp":1.53,"tv":23007.19,"id":9323645}]}]}
{"op":"mcm","clk":"4216583165","pt":1631553410758,"mc":[{"id":"1.187566733","rc":[{"batl":[[0,3.35,2],[1,3.7,2.89]],"ltp":2.88,"tv":828.58,"id":8734382},{"batb":[[1,1.43,3.22],[2,1.38,24.28]],"batl":[[0,1.7,119.01]],"ltp":1.53,"tv":23007.19,"id":9323645}]}]}
{"op":"mcm","clk":"4216583316","pt":1631553412147,"mc":[{"id":"1.187566733","rc":[{"batb":[[1,2.32,389.8],[2,2.28,6.66]],"batl":[[0,2.48,82.66],[1,2.52,59.52],[2,2.54,29.76]],"ltp":2.88,"tv":828.58,"id":8734382},{"batb":[[1,1.38,24.28],[2,1.32,12.7]],"ltp":1.53,"tv":23007.19,"id":9323645}]}]}
{"op":"mcm","clk":"4216583438","pt":1631553413146,"mc":[{"id":"1.187566733","rc":[{"batb":[[0,2.4,17.21]],"batl":[[0,2.48,48.78],[1,2.52,35.71],[2,2.54,17.86]],"ltp":2.88,"tv":828.58,"id":8734382},{"trd":[[1.68,11.9]],"batb":[[0,1.68,3.91],[1,1.67,40.78],[2,1.65,77.52]],"batl":[[2,1.73,86.72]],"ltp":1.68,"tv":23019.09,"id":9323645}],"tv":23847.67}]}
{"op":"mcm","clk":"4216583476","pt":1631553413572,"mc":[{"id":"1.187566733","rc":[{"batl":[[1,2.52,11.9],[2,2.54,5.96]],"ltp":2.88,"tv":828.58,"id":8734382},{"batl":[[2,1.73,17.34]],"ltp":1.68,"tv":23019.09,"id":9323645}]}]}
{"op":"mcm","clk":"4216583882","pt":1631553417165,"mc":[{"id":"1.187566733","rc":[{"batl":[[0,2.48,108.6]],"ltp":2.88,"tv":828.58,"id":8734382},{"batl":[[2,1.72,58.57]],"ltp":1.68,"tv":23019.09,"id":9323645}]}]}
{"op":"mcm","clk":"4216583946","pt":1631553417644,"mc":[{"id":"1.187566733","rc":[{"batl":[[0,2.48,48.78]],"ltp":2.88,"tv":828.58,"id":8734382},{"trd":[[1.68,19.68]],"batb":[[0,1.67,40.8],[1,1.65,77.52],[2,1.64,71.3]],"ltp":1.68,"tv":23026.87,"id":9323645}],"tv":23855.45}]}
{"op":"mcm","clk":"4216584213","pt":1631553419969,"mc":[{"id":"1.187566733","rc":[{"batl":[[0,1.7,230.01],[1,1.71,173.13]],"ltp":1.68,"tv":23026.87,"id":9323645}]}]}
{"op":"mcm","clk":"4216584389","pt":1631553421869,"mc":[{"id":"1.187566733","rc":[{"trd":[[2.42,24.46]],"ltp":2.42,"tv":853.04,"id":8734382},{"trd":[[1.7,34.82]],"batl":[[0,1.7,195.19]],"ltp":1.7,"tv":23061.69,"id":9323645}],"tv":23914.73}]}
{"op":"mcm","clk":"4216584477","pt":1631553422867,"mc":[{"id":"1.187566733","rc":[{"trd":[[1.7,185.42]],"batb":[[1,1.65,69.66],[2,1.57,50.77]],"batl":[[0,1.7,117.01]],"ltp":1.7,"tv":23212.29,"id":9323645}],"tv":24065.33}]}
{"op":"mcm","clk":"4216584529","pt":1631553423354,"mc":[{"id":"1.187566733","rc":[{"batb":[[0,2.4,6.11]],"ltp":2.42,"tv":853.04,"id":8734382},{"batb":[[0,1.67,40.78]],"ltp":1.7,"tv":23212.29,"id":9323645}]}]}
{"op":"mcm","clk":"4216584742","pt":1631553425051,"mc":[{"id":"1.187566733","rc":[{"batl":[[0,1.7,172.16]],"ltp":1.7,"tv":23212.29,"id":9323645}]}]}
{"op":"mcm","clk":"4216584847","pt":1631553426061,"mc":[{"id":"1.187566733","rc":[{"batb":[[1,1.66,70.46],[2,1.65,69.66]],"batl":[[0,1.68,1.71],[1,1.7,172.16],[2,1.71,224.92]],"ltp":1.7,"tv":23212.29,"id":9323645}]}]}
{"op":"mcm","clk":"4216584882","pt":1631553426377,"mc":[{"id":"1.187566733","rc":[{"batl":[[1,2.5,7.01],[2,2.52,11.9]],"ltp":2.42,"tv":853.04,"id":8734382},{"batl":[[1,1.7,187.13]],"ltp":1.7,"tv":23212.29,"id":9323645}]}]}
{"op":"mcm","clk":"4216585058","pt":1631553427861,"mc":[{"id":"1.187566733","rc":[{"batl":[[1,2.52,11.9],[2,2.54,5.96]],"ltp":2.42,"tv":853.04,"id":8734382},{"batl":[[1,1.7,172.16]],"ltp":1.7,"tv":23212.29,"id":9323645}]}]}
{"op":"mcm","clk":"4216585352","pt":1631553430785,"mc":[{"id":"1.187566733","rc":[{"batl":[[1,2.5,7.01],[2,2.52,11.9]],"ltp":2.42,"tv":853.04,"id":8734382},{"batl":[[0,1.7,187.13],[1,1.71,224.92],[2,1.72,119]],"ltp":1.7,"tv":23212.29,"id":9323645}]}]}
{"op":"mcm","clk":"4216585944","pt":1631553436081,"mc":[{"id":"1.187566733","rc":[{"batb":[[0,2,23.98],[1,1.99,43.51],[2,1.9,52.37]],"batl":[[0,3.7,2.89],[1,2.5,0],[2,2.52,0]],"ltp":2.42,"tv":853.04,"id":8734382},{"batb":[[0,1.57,50.77],[1,1.38,21.64],[2,1.32,12.7]],"batl":[[0,1.7,117.01],[1,1.93,47.5],[2,2,24.18]],"ltp":1.7,"tv":23212.29,"id":9323645}]}]}
{"op":"mcm","clk":"4216585997","pt":1631553436459,"mc":[{"id":"1.187566733","rc":[{"batl":[[0,1.7,6.01]],"ltp":1.7,"tv":23212.29,"id":9323645}]}]}
{"op":"mcm","clk":"4216586313","pt":1631553439200,"mc":[{"id":"1.187566733","rc":[{"batb":[[0,1.99,43.51],[1,1.9,52.37],[2,1.7,17.1]],"ltp":2.42,"tv":853.04,"id":8734382},{"batb":[[1,1.56,109.99],[2,1.55,89.04]],"batl":[[2,44,7.23]],"ltp":1.7,"tv":23212.29,"id":9323645}]}]}
{"op":"mcm","clk":"4216586682","pt":1631553442119,"mc":[{"id":"1.187566733","rc":[{"batb":[[0,2.62,14.54],[1,2.6,11.54],[2,2.58,5.76]],"batl":[[0,2.78,13.46],[1,2.84,421.05],[2,3.7,2.89]],"ltp":2.42,"tv":853.04,"id":8734382},{"trd":[[1.7,287.42]],"batl":[[0,1.59,6.29],[1,1.6,13.23],[2,1.61,71.5]],"ltp":1.7,"tv":23314.29,"id":9323645}],"tv":24167.33}]}
{"op":"mcm","clk":"4216586814","pt":1631553443186,"mc":[{"id":"1.187566733","rc":[{"batl":[[1,2.8,10.72],[2,2.82,5.36]],"ltp":2.42,"tv":853.04,"id":8734382},{"batl":[[1,1.6,86.25],[2,1.61,148.58]],"ltp":1.7,"tv":23314.29,"id":9323645}]}]}
{"op":"mcm","clk":"4216587039","pt":1631553445198,"mc":[{"id":"1.187566733","rc":[{"trd":[[1.59,12.58]],"batl":[[0,1.6,86.25],[1,1.61,148.58],[2,1.64,430.99]],"ltp":1.59,"tv":23326.87,"id":9323645}],"tv":24179.91}]}
{"op":"mcm","clk":"4216587258","pt":1631553446988,"mc":[{"id":"1.187566733","rc":[{"batl":[[0,1.59,49.68],[1,1.6,86.25],[2,1.61,148.58]],"ltp":1.59,"tv":23326.87,"id":9323645}]}]}
{"op":"mcm","clk":"4216587389","pt":1631553448099,"mc":[{"id":"1.187566733","rc":[{"batl":[[1,1.6,134.64]],"ltp":1.59,"tv":23326.87,"id":9323645}]}]}
{"op":"mcm","clk":"4216587645","pt":1631553450485,"mc":[{"id":"1.187566733","rc":[{"batl":[[0,1.59,165.68]],"ltp":1.59,"tv":23326.87,"id":9323645}]}]}
{"op":"mcm","clk":"4216587957","pt":1631553453195,"mc":[{"id":"1.187566733","rc":[{"batb":[[0,2.38,26.52],[1,2.02,8.24],[2,1.92,50.27]],"batl":[[0,3.7,2.89],[1,2.8,0],[2,2.82,0]],"ltp":2.42,"tv":853.04,"id":8734382},{"batl":[[0,1.59,116],[1,1.6,73.02],[2,1.61,77.08]],"ltp":1.59,"tv":23326.87,"id":9323645}]}]}
{"op":"mcm","clk":"4216588031","pt":1631553453821,"mc":[{"id":"1.187566733","rc":[{"batb":[[0,1.92,50.27],[1,1.91,39.39],[2,1.8,11.97]],"ltp":2.42,"tv":853.04,"id":8734382},{"batb":[[0,1.45,68.56],[1,1.38,21.64],[2,1.32,12.7]],"batl":[[0,2.1,6.55],[1,810,0.07],[2,1.61,0]],"ltp":1.59,"tv":23326.87,"id":9323645}]}]}
{"op":"mcm","clk":"4216588281","pt":1631553456026,"mc":[{"id":"1.187566733","rc":[{"batb":[[0,1.59,53.33],[1,1.45,68.56],[2,1.38,21.64]],"ltp":1.59,"tv":23326.87,"id":9323645}]}]}
{"op":"mcm","clk":"4216588416","pt":1631553457133,"mc":[{"id":"1.187566733","rc":[{"batb":[[0,2.02,8.24],[1,1.92,50.27],[2,1.91,39.39]],"ltp":2.42,"tv":853.04,"id":8734382},{"batl":[[0,1.98,36.75],[1,2.1,6.55],[2,810,0.07]],"ltp":1.59,"tv":23326.87,"id":9323645}]}]}
{"op":"mcm","clk":"4216588457","pt":1631553457400,"mc":[{"id":"1.187566733","rc":[{"batb":[[0,1.92,50.27],[1,1.91,39.39],[2,1.8,11.97]],"ltp":2.42,"tv":853.04,"id":8734382},{"batl":[[0,2.1,6.55],[1,810,0.07],[2,810,0]],"ltp":1.59,"tv":23326.87,"id":9323645}]}]}
{"op":"mcm","clk":"4216588642","pt":1631553459201,"mc":[{"id":"1.187566733","rc":[{"batb":[[0,2.52,21.99],[1,1.92,50.27],[2,1.91,39.39]],"batl":[[0,2.7,19.45],[1,2.74,192.6],[2,3.7,2.89]],"ltp":2.42,"tv":853.04,"id":8734382},{"batl":[[0,1.65,20.9],[1,2.1,6.55],[2,810,0.07]],"ltp":1.59,"tv":23326.87,"id":9323645}]}]}
{"op":"mcm","clk":"4216588681","pt":1631553459516,"mc":[{"id":"1.187566733","rc":[{"batb":[[0,1.92,50.27],[1,1.91,39.39],[2,1.8,11.97]],"batl":[[0,3.7,2.89],[1,2.74,0],[2,3.7,0]],"ltp":2.42,"tv":853.04,"id":8734382},{"batb":[[0,1.61,67.1],[1,1.6,78.39],[2,1.59,53.33]],"batl":[[0,1.65,81.96],[1,1.66,68.72],[2,2.1,6.55]],"ltp":1.59,"tv":23326.87,"id":9323645}]}]}
{"op":"mcm","clk":"4216589031","pt":1631553462827,"mc":[{"id":"1.187566733","rc":[{"batb":[[0,1.59,53.33],[1,1.45,68.56],[2,1.38,21.64]],"batl":[[0,2.1,6.55],[1,810,0.07],[2,2.1,0]],"ltp":1.59,"tv":23326.87,"id":9323645}]}]}
{"op":"mcm","clk":"4216589199","pt":1631553464191,"mc":[{"id":"1.187566733","rc":[{"batb":[[0,2.02,8.74],[1,1.92,50.27],[2,1.91,39.39]],"ltp":2.42,"tv":853.04,"id":8734382},{"trd":[[1.59,16.92]],"batb":[[0,1.45,68.56],[1,1.38,21.64],[2,1.32,12.7]],"batl":[[0,1.98,40.75],[1,2.1,6.55],[2,810,0.07]],"ltp":1.59,"tv":23331.21,"id":9323645}],"tv":24184.25}]}
{"op":"mcm","clk":"4216589285","pt":1631553464936,"mc":[{"id":"1.187566733","rc":[{"batb":[[0,1.92,50.27],[1,1.91,39.39],[2,1.8,11.97]],"ltp":2.42,"tv":853.04,"id":8734382},{"batl":[[0,2.1,6.55],[1,810,0.07],[2,810,0]],"ltp":1.59,"tv":23331.21,"id":9323645}]}]}
{"op":"mcm","clk":"4216589370","pt":1631553465807,"mc":[{"id":"1.187566733","rc":[{"batb":[[1,1.44,170.52],[2,1.43,126.44]],"batl":[[0,1.89,83.01],[1,1.91,85.21],[2,2.1,6.55]],"ltp":1.59,"tv":23331.21,"id":9323645}]}]}
{"op":"mcm","clk":"4216589625","pt":1631553468132,"mc":[{"id":"1.187566733","rc":[{"batb":[[0,2.02,7.74],[1,1.92,50.27],[2,1.91,39.39]],"ltp":2.42,"tv":853.04,"id":8734382},{"batl":[[2,1.98,41.25]],"ltp":1.59,"tv":23331.21,"id":9323645}]}]}
{"op":"mcm","clk":"4216589661","pt":1631553468417,"mc":[{"id":"1.187566733","rc":[{"batb":[[0,1.92,50.27],[1,1.91,39.39],[2,1.8,11.97]],"ltp":2.42,"tv":853.04,"id":8734382},{"batl":[[2,2.1,6.55]],"ltp":1.59,"tv":23331.21,"id":9323645}]}]}
{"op":"mcm","clk":"4216589902","pt":1631553470730,"mc":[{"id":"1.187566733","rc":[{"batl":[[0,3.7,3.65]],"ltp":2.42,"tv":853.04,"id":8734382}]}]}
{"op":"mcm","clk":"4216590346","pt":1631553475133,"mc":[{"id":"1.187566733","rc":[{"batb":[[0,2.02,8.24],[1,1.92,50.27],[2,1.91,39.39]],"ltp":2.42,"tv":853.04,"id":8734382},{"batl":[[2,1.98,37.25]],"ltp":1.59,"tv":23331.21,"id":9323645}]}]}
{"op":"mcm","clk":"4216590380","pt":1631553475443,"mc":[{"id":"1.187566733","rc":[{"batb":[[0,1.92,50.27],[1,1.91,39.39],[2,1.8,11.97]],"ltp":2.42,"tv":853.04,"id":8734382},{"batb":[[1,1.38,21.64],[2,1.32,12.7]],"batl":[[2,810,0.07]],"ltp":1.59,"tv":23331.21,"id":9323645}]}]}
{"op":"mcm","clk":"4216590666","pt":1631553478031,"mc":[{"id":"1.187566733","rc":[{"batl":[[0,2.2,13.84],[1,2.22,1360.02],[2,2.28,556.75]],"ltp":2.42,"tv":853.04,"id":8734382},{"batb":[[0,1.81,82.88],[1,1.8,155.34],[2,1.79,41.44]],"batl":[[0,1.89,97.2],[2,1.98,526.23]],"ltp":1.59,"tv":23331.21,"id":9323645}]}]}
{"op":"mcm","clk":"4216590790","pt":1631553479133,"mc":[{"id":"1.187566733","rc":[{"batb":[[2,1.84,29.12]],"batl":[[1,2.28,556.75],[2,2.4,4.17]],"ltp":2.42,"tv":853.04,"id":8734382},{"trd":[[1.85,10.82]],"batb":[[0,1.88,22.7],[1,1.83,65.74],[2,1.81,148.95]],"batl":[[1,1.9,78.96],[2,1.91,124.69]],"ltp":1.85,"tv":23342.03,"id":9323645}],"tv":24195.07}]}
{"op":"mcm","clk":"4216590870","pt":1631553479724,"mc":[{"id":"1.187566733","rc":[{"batb":[[2,1.81,115.8]],"batl":[[1,1.9,15.8],[2,1.91,93.11]],"ltp":1.85,"tv":23342.03,"id":9323645}]}]}
{"op":"mcm","clk":"4216591233","pt":1631553483053,"mc":[{"id":"1.187566733","rc":[{"batl":[[0,2.18,72.62],[1,2.2,13.84],[2,2.28,556.75]],"ltp":2.42,"tv":853.04,"id":8734382},{"trd":[[1.88,45.41]],"batb":[[0,1.83,65.74],[1,1.81,115.8],[2,1.8,75.51]],"batl":[[0,1.88,61.35],[1,1.89,135.65],[2,1.9,15.8]],"ltp":1.88,"tv":23387.44,"id":9323645}],"tv":24240.48}]}
{"op":"mcm","clk":"4216591256","pt":1631553483263,"mc":[{"id":"1.187566733","rc":[{"batl":[[0,2.2,13.84],[1,2.28,556.75],[2,2.4,4.17]],"ltp":2.42,"tv":853.04,"id":8734382}]}]}
{"op":"mcm","clk":"4216591612","pt":1631553486227,"mc":[{"id":"1.187566733","rc":[{"batb":[[0,1.94,279.69],[1,1.92,50.27],[2,1.91,39.39]],"ltp":2.42,"tv":853.04,"id":8734382}]}]}
{"op":"mcm","clk":"4216591777","pt":1631553487655,"mc":[{"id":"1.187566733","rc":[{"batb":[[0,1.94,329.2],[1,1.91,39.39],[2,1.86,28.7]],"ltp":2.42,"tv":853.04,"id":8734382},{"batb":[[0,1.85,28.53],[1,1.83,65.74],[2,1.81,115.8]],"ltp":1.88,"tv":23387.44,"id":9323645}]}]}
{"op":"mcm","clk":"4216592180","pt":1631553491462,"mc":[{"id":"1.187566733","rc":[{"batl":[[0,1.88,171.35],[1,1.89,122.89]],"ltp":1.88,"tv":23387.44,"id":9323645}]}]}
{"op":"mcm","clk":"4216592354","pt":1631553492961,"mc":[{"id":"1.187566733","rc":[{"batl":[[0,1.88,173.06]],"ltp":1.88,"tv":23387.44,"id":9323645}]}]}
{"op":"mcm","clk":"4216592507","pt":1631553494240,"mc":[{"id":"1.187566733","rc":[{"batb":[[1,1.83,79.13]],"ltp":1.88,"tv":23387.44,"id":9323645}]}]}
{"op":"mcm","clk":"4216592774","pt":1631553496857,"mc":[{"id":"1.187566733","rc":[{"trd":[[2.12,263.02]],"batl":[[0,2.12,69.42],[1,2.2,13.84],[2,2.28,556.75]],"ltp":2.12,"tv":1116.06,"id":8734382},{"trd":[[1.88,218.47],[1.89,122.89]],"batl":[[0,1.9,15.8],[1,1.91,93.11],[2,1.92,7.9]],"ltp":1.89,"tv":23683.39,"id":9323645}],"tv":24799.45}]}
{"op":"mcm","clk":"4216592843","pt":1631553497480,"mc":[{"id":"1.187566733","rc":[{"batb":[[0,1.94,49.51]],"ltp":2.12,"tv":1116.06,"id":8734382},{"batb":[[1,1.81,16.58],[2,1.8,75.51]],"batl":[[1,1.91,7.9]],"ltp":1.89,"tv":23683.39,"id":9323645}]}]}
{"op":"mcm","clk":"4216593122","pt":1631553500065,"mc":[{"id":"1.187566733","rc":[{"trd":[[2.1,41.6],[2.12,263.34]],"batb":[[0,1.95,44.8],[1,1.94,49.51],[2,1.91,39.39]],"batl":[[0,2.12,69.1]],"ltp":2.12,"tv":1157.97,"id":8734382},{"trd":[[1.89,123.25],[1.9,45.97]],"batb":[[0,1.86,32.65],[1,1.85,28.53],[2,1.81,16.58]],"batl":[[0,1.91,7.9],[1,1.92,7.9],[2,1.98,526.23]],"ltp":1.89,"tv":23729.72,"id":9323645}],"tv":24887.7}]}
{"op":"mcm","clk":"4216593189","pt":1631553500639,"mc":[{"id":"1.187566733","rc":[{"batb":[[0,1.95,261.87]],"ltp":2.12,"tv":1157.97,"id":8734382},{"batb":[[2,1.84,70.87]],"batl":[[0,1.9,74.38],[1,1.91,7.9],[2,1.92,91.88]],"ltp":1.89,"tv":23729.72,"id":9323645}]}]}
{"op":"mcm","clk":"4216593270","pt":1631553501437,"mc":[{"id":"1.187566733","rc":[{"batb":[[0,1.95,44.8]],"ltp":2.12,"tv":1157.97,"id":8734382}]}]}
{"op":"mcm","clk":"4216593352","pt":1631553502444,"mc":[{"id":"1.187566733","rc":[{"trd":[[2.12,277.92]],"batl":[[0,2.12,61.81]],"ltp":2.12,"tv":1172.56,"id":8734382}],"tv":24902.28}]}
{"op":"mcm","clk":"4216593515","pt":1631553503867,"mc":[{"id":"1.187566733","rc":[{"trd":[[2.1,54.1]],"batb":[[0,1.96,42.01],[1,1.95,44.8],[2,1.94,49.51]],"ltp":2.1,"tv":1185.06,"id":8734382},{"trd":[[1.9,59.79]],"batl":[[0,1.9,60.56]],"ltp":1.9,"tv":23743.54,"id":9323645}],"tv":24928.6}]}
{"op":"mcm","clk":"4216593769","pt":1631553506079,"mc":[{"id":"1.187566733","rc":[{"trd":[[2.12,277.96]],"batb":[[0,1.95,44.8],[1,1.94,49.51],[2,1.91,39.39]],"batl":[[0,2.12,411.47]],"ltp":2.12,"tv":1185.09,"id":8734382},{"trd":[[1.89,123.29]],"ltp":1.89,"tv":23743.58,"id":9323645}],"tv":24928.67}]}
{"op":"mcm","clk":"4216593868","pt":1631553507073,"mc":[{"id":"1.187566733","rc":[{"batl":[[1,2.28,556.75],[2,2.4,4.17]],"ltp":2.12,"tv":1185.09,"id":8734382},{"batb":[[2,1.84,79.28]],"ltp":1.89,"tv":23743.58,"id":9323645}]}]}
{"op":"mcm","clk":"4216594076","pt":1631553509086,"mc":[{"id":"1.187566733","rc":[{"batb":[[0,1.97,38.44],[1,1.95,44.8],[2,1.94,49.51]],"ltp":2.12,"tv":1185.09,"id":8734382}]}]}
{"op":"mcm","clk":"4216594161","pt":1631553509977,"mc":[{"id":"1.187566733","rc":[{"batl":[[1,2.16,12.86],[2,2.28,556.75]],"ltp":2.12,"tv":1185.09,"id":8734382},{"batl":[[2,1.92,106.89]],"ltp":1.89,"tv":23743.58,"id":9323645}]}]}
{"op":"mcm","clk":"4216594508","pt":1631553513062,"mc":[{"id":"1.187566733","rc":[{"trd":[[2.1,72.52],[2.12,689.42]],"batb":[[0,1.98,343.09]],"batl":[[0,2.16,12.86],[1,2.28,556.75],[2,2.4,4.17]],"ltp":2.12,"tv":1614.98,"id":8734382},{"trd":[[1.89,584.83],[1.9,80.15]],"batl":[[0,1.89,112.28],[1,1.9,284.2],[2,1.91,7.9]],"ltp":1.89,"tv":24225.48,"id":9323645}],"tv":25840.46}]}
{"op":"mcm","clk":"4216594532","pt":1631553513266,"mc":[{"id":"1.187566733","rc":[{"batb":[[1,1.94,49.51],[2,1.91,39.39]],"ltp":2.12,"tv":1614.98,"id":8734382}]}]}
{"op":"mcm","clk":"4216594821","pt":1631553515755,"mc":[{"id":"1.187566733","rc":[{"batb":[[2,1.84,90.97]],"batl":[[1,1.9,299.03]],"ltp":1.89,"tv":24225.48,"id":9323645}]}]}
{"op":"mcm","clk":"4216594897","pt":1631553516488,"mc":[{"id":"1.187566733","rc":[{"batb":[[0,1.94,49.51],[1,1.91,39.39],[2,1.86,28.7]],"ltp":2.12,"tv":1614.98,"id":8734382}]}]}
{"op":"mcm","clk":"4216595211","pt":1631553519543,"mc":[{"id":"1.187566733","rc":[{"trd":[[2.12,696.65]],"batb":[[0,1.99,586.49],[1,1.94,49.51],[2,1.91,39.39]],"ltp":2.12,"tv":1622.21,"id":8734382},{"trd":[[1.89,592.94]],"batl":[[0,1.89,104.17]],"ltp":1.89,"tv":24233.58,"id":9323645}],"tv":25855.79}]}
{"op":"mcm","clk":"4216595397","pt":1631553521278,"mc":[{"id":"1.187566733","rc":[{"batl":[[1,1.9,244]],"ltp":1.89,"tv":24233.58,"id":9323645}]}]}
{"op":"mcm","clk":"4216595689","pt":1631553524176,"mc":[{"id":"1.187566733","rc":[{"batl":[[2,1.91,103.17]],"ltp":1.89,"tv":24233.58,"id":9323645}]}]}
{"op":"mcm","clk":"4216597262","pt":1631553538405,"mc":[{"id":"1.187566733","rc":[{"trd":[[1.86,7.44]],"batb":[[0,1.86,28.93]],"ltp":1.86,"tv":24241.02,"id":9323645}],"tv":25863.23}]}
{"op":"mcm","clk":"4216597626","pt":1631553541687,"mc":[{"id":"1.187566733","rc":[{"trd":[[1.89,801.27],[1.9,271.81]],"batb":[[1,1.85,60.09]],"batl":[[0,1.9,148.17],[1,1.91,103.17],[2,1.92,22.91]],"ltp":1.9,"tv":24641.02,"id":9323645}],"tv":26263.23}]}
{"op":"mcm","clk":"4216597697","pt":1631553542276,"mc":[{"id":"1.187566733","rc":[{"batb":[[0,1.94,49.51],[1,1.91,39.39],[2,1.86,28.7]],"ltp":2.12,"tv":1622.21,"id":8734382}]}]}
{"op":"mcm","clk":"4216597950","pt":1631553544811,"mc":[{"id":"1.187566733","rc":[{"batl":[[0,1.89,10.12],[1,1.9,148.17],[2,1.91,103.17]],"ltp":1.9,"tv":24641.02,"id":9323645}]}]}
{"op":"mcm","clk":"4216598785","pt":1631553551921,"mc":[{"id":"1.187566733","rc":[{"trd":[[1.86,17.44]],"batb":[[0,1.86,23.93]],"ltp":1.86,"tv":24651.02,"id":9323645}],"tv":26273.23}]}
{"op":"mcm","clk":"4216598854","pt":1631553552725,"mc":[{"id":"1.187566733","rc":[{"trd":[[2.16,7.16]],"batl":[[0,2.16,9.28]],"ltp":2.16,"tv":1629.36,"id":8734382}],"tv":26280.39}]}
{"op":"mcm","clk":"4216599577","pt":1631553559134,"mc":[{"id":"1.187566733","rc":[{"trd":[[1.89,809.27]],"batl":[[0,1.89,6.12]],"ltp":1.89,"tv":24659.02,"id":9323645}],"tv":26288.39}]}
{"op":"mcm","clk":"4216600015","pt":1631553563031,"mc":[{"id":"1.187566733","rc":[{"trd":[[2.16,8.42]],"batl":[[0,2.28,556.75],[1,2.4,4.17],[2,2.4,0]],"ltp":2.16,"tv":1630.62,"id":8734382}],"tv":26289.65}]}
{"op":"mcm","clk":"4216600327","pt":1631553565924,"mc":[{"id":"1.187566733","rc":[{"batb":[[0,1.96,381.08],[1,1.94,49.51],[2,1.91,39.39]],"batl":[[0,2.16,8.65],[1,2.28,556.75],[2,2.4,4.17]],"ltp":2.16,"tv":1630.62,"id":8734382}]}]}
{"op":"mcm","clk":"4216600492","pt":1631553567557,"mc":[{"id":"1.187566733","rc":[{"batl":[[0,1.88,7],[1,1.89,6.12],[2,1.9,148.17]],"ltp":1.89,"tv":24659.02,"id":9323645}]}]}
{"op":"mcm","clk":"4216600598","pt":1631553568516,"mc":[{"id":"1.187566733","rc":[{"batb":[[0,2.02,8.74],[1,1.96,381.08],[2,1.94,49.51]],"batl":[[2,2.4,9.61]],"ltp":2.16,"tv":1630.62,"id":8734382}]}]}
{"op":"mcm","clk":"4216601051","pt":1631553572826,"mc":[{"id":"1.187566733","rc":[{"batl":[[0,2.28,556.75],[1,2.4,9.61],[2,2.5,5.55]],"ltp":2.16,"tv":1630.62,"id":8734382},{"trd":[[1.86,53.57]],"batb":[[0,1.86,5.86]],"ltp":1.86,"tv":24695.15,"id":9323645}],"tv":26325.78}]}
{"op":"mcm","clk":"4216601420","pt":1631553576138,"mc":[{"id":"1.187566733","rc":[{"batb":[[1,1.94,49.51],[2,1.91,39.39]],"batl":[[0,2.16,8.65],[1,2.28,556.75],[2,2.4,9.61]],"ltp":2.16,"tv":1630.62,"id":8734382},{"batl":[[0,1.88,18.81]],"ltp":1.86,"tv":24695.15,"id":9323645}]}]}
{"op":"mcm","clk":"4216601750","pt":1631553579326,"mc":[{"id":"1.187566733","rc":[{"batb":[[0,2.02,333.62]],"ltp":2.16,"tv":1630.62,"id":8734382}]}]}
{"op":"mcm","clk":"4216602015","pt":1631553582052,"mc":[{"id":"1.187566733","rc":[{"trd":[[1.88,226.47]],"batl":[[0,1.88,14.81]],"ltp":1.88,"tv":24703.16,"id":9323645}],"tv":26333.79}]}
{"op":"mcm","clk":"4216602962","pt":1631553591658,"mc":[{"id":"1.187566733","rc":[{"trd":[[1.88,256.08]],"batb":[[0,1.88,13.06],[1,1.86,5.86],[2,1.85,60.09]],"batl":[[0,1.89,6.12],[1,1.9,148.17],[2,1.91,103.17]],"ltp":1.88,"tv":24732.77,"id":9323645}],"tv":26363.4}]}
{"op":"mcm","clk":"4216603290","pt":1631553594755,"mc":[{"id":"1.187566733","rc":[{"batb":[[1,1.87,26.64],[2,1.86,5.86]],"ltp":1.88,"tv":24732.77,"id":9323645}]}]}
{"op":"mcm","clk":"4216603392","pt":1631553595797,"mc":[{"id":"1.187566733","rc":[{"batb":[[1,2,23.62],[2,1.94,49.51]],"ltp":2.16,"tv":1630.62,"id":8734382}]}]}
{"op":"mcm","clk":"4216603507","pt":1631553596891,"mc":[{"id":"1.187566733","rc":[{"batb":[[0,1.88,40.93]],"ltp":1.88,"tv":24732.77,"id":9323645}]}]}
{"op":"mcm","clk":"4216603843","pt":1631553600094,"mc":[{"id":"1.187566733","rc":[{"batb":[[0,1.88,70.25]],"batl":[[1,1.9,154.5]],"ltp":1.88,"tv":24732.77,"id":9323645}]}]}
{"op":"mcm","clk":"4216604043","pt":1631553602190,"mc":[{"id":"1.187566733","rc":[{"trd":[[1.89,821.51]],"batb":[[0,1.89,21.75],[1,1.88,70.25],[2,1.87,26.64]],"batl":[[0,1.9,154.5],[1,1.91,103.17],[2,1.92,27.63]],"ltp":1.89,"tv":24745.01,"id":9323645}],"tv":26375.64}]}
{"op":"mcm","clk":"4216604651","pt":1631553607601,"mc":[{"id":"1.187566733","rc":[{"batb":[[0,1.89,49.62]],"ltp":1.89,"tv":24745.01,"id":9323645}]}]}
{"op":"mcm","clk":"4216604803","pt":1631553608808,"mc":[{"id":"1.187566733","rc":[{"batb":[[0,2.02,8.74],[2,1.86,28.7]],"batl":[[0,2.4,5.44],[1,2.52,5.26],[2,2.4,0]],"ltp":2.16,"tv":1630.62,"id":8734382},{"batb":[[1,1.88,40.93],[2,1.72,40.59]],"batl":[[0,1.9,148.17],[1,1.98,50.25],[2,2,27.27]],"ltp":1.89,"tv":24745.01,"id":9323645}]}]}
{"op":"mcm","clk":"4216604922","pt":1631553609806,"mc":[{"id":"1.187566733","rc":[{"batb":[[0,2,23.62],[1,1.86,28.7],[2,1.5,107.72]],"ltp":2.16,"tv":1630.62,"id":8734382},{"batl":[[0,2,27.27],[1,810,0.07],[2,2,0]],"ltp":1.89,"tv":24745.01,"id":9323645}]}]}
{"op":"mcm","clk":"4216605624","pt":1631553616081,"mc":[{"id":"1.187566733","rc":[{"trd":[[1.88,279.2],[1.89,920.75]],"batb":[[0,1.88,29.38],[1,1.72,40.59],[2,1.71,36.76]],"ltp":1.88,"tv":24867.37,"id":9323645}],"tv":26498.0}]}
{"op":"mcm","clk":"4216606119","pt":1631553620690,"mc":[{"id":"1.187566733","rc":[{"batl":[[0,2.52,5.26],[1,2.52,0]],"ltp":2.16,"tv":1630.62,"id":8734382},{"trd":[[1.88,337.95]],"batb":[[0,1.71,36.76],[1,1.66,38.78],[2,1.57,1.95]],"ltp":1.88,"tv":24926.11,"id":9323645}],"tv":26556.74}]}
{"op":"mcm","clk":"4216606288","pt":1631553622208,"mc":[{"id":"1.187566733","rc":[{"batb":[[0,1.71,135.43],[1,1.7,62.54],[2,1.66,38.78]],"batl":[[1,2.02,62.72],[2,2.04,69.4]],"ltp":1.88,"tv":24926.11,"id":9323645}]}]}
{"op":"mcm","clk":"4216606308","pt":1631553622415,"mc":[{"id":"1.187566733","rc":[{"batl":[[1,2.04,69.4],[2,810,0.07]],"ltp":1.88,"tv":24926.11,"id":9323645}]}]}
{"op":"mcm","clk":"4216606558","pt":1631553624620,"mc":[{"id":"1.187566733","rc":[{"trd":[[2,51.49]],"batb":[[0,1.86,28.7],[1,1.5,107.72],[2,1.4,149.61]],"ltp":2.0,"tv":1682.11,"id":8734382},{"trd":[[2,4.25]],"batb":[[0,1.71,153.61]],"batl":[[0,2,23.02],[1,2.04,116.63],[2,2.06,67.53]],"ltp":2.0,"tv":24930.36,"id":9323645}],"tv":26612.48}]}
{"op":"mcm","clk":"4216606923","pt":1631553627798,"mc":[{"id":"1.187566733","rc":[{"batb":[[0,2,22.05],[1,1.86,28.7],[2,1.5,107.72]],"ltp":2.0,"tv":1682.11,"id":8734382}]}]}
{"op":"mcm","clk":"4216607395","pt":1631553632005,"mc":[{"id":"1.187566733","rc":[{"batb":[[0,1.71,36.76],[1,1.66,38.78],[2,1.57,1.95]],"ltp":2.0,"tv":24930.36,"id":9323645}]}]}
{"op":"mcm","clk":"4216607519","pt":1631553633135,"mc":[{"id":"1.187566733","rc":[{"trd":[[2,118.61]],"batb":[[0,1.86,28.7],[1,1.5,107.72],[2,1.4,149.61]],"batl":[[0,2,84.93],[1,2.52,5.26]],"ltp":2.0,"tv":1749.23,"id":8734382},{"trd":[[2,27.27]],"batl":[[0,2.04,116.63],[1,2.06,67.53],[2,810,0.07]],"ltp":2.0,"tv":24953.38,"id":9323645}],"tv":26702.62}]}
{"op":"mcm","clk":"4216607745","pt":1631553635142,"mc":[{"id":"1.187566733","rc":[{"trd":[[2,131.42]],"batl":[[0,2,76.39],[1,2.02,99.5],[2,2.04,8.27]],"ltp":2.0,"tv":1762.04,"id":8734382},{"trd":[[2,31.54]],"batb":[[0,1.96,56.06],[1,1.95,15.38],[2,1.94,86.67]],"batl":[[0,2.04,409.46]],"ltp":2.0,"tv":24957.65,"id":9323645}],"tv":26719.7}]}
{"op":"mcm","clk":"4216607853","pt":1631553636133,"mc":[{"id":"1.187566733","rc":[{"trd":[[2,136.57]],"batb":[[1,1.79,32.64],[2,1.5,107.72]],"batl":[[0,2,71.24]],"ltp":2.0,"tv":1767.19,"id":8734382},{"trd":[[2,36.69]],"batb":[[2,1.94,135.93]],"batl":[[1,2.06,82.09],[2,2.08,7.28]],"ltp":2.0,"tv":24962.8,"id":9323645}],"tv":26730.0}]}
{"op":"mcm","clk":"4216607862","pt":1631553636225,"mc":[{"id":"1.187566733","rc":[{"trd":[[2,279.05]],"batl":[[0,2.02,99.5],[1,2.04,8.27],[2,2.26,4.42]],"ltp":2.0,"tv":1909.67,"id":8734382}],"tv":26872.48}]}
{"op":"mcm","clk":"4216608291","pt":1631553639934,"mc":[{"id":"1.187566733","rc":[{"batb":[[0,1.87,59.33],[1,1.86,28.7],[2,1.79,32.64]],"ltp":2.0,"tv":1909.67,"id":8734382},{"batb":[[0,1.97,32.23],[1,1.96,56.06],[2,1.95,15.38]],"ltp":2.0,"tv":24962.8,"id":9323645}]}]}
{"op":"mcm","clk":"4216608481","pt":1631553641716,"mc":[{"id":"1.187566733","rc":[{"batb":[[0,1.93,28.93],[1,1.91,30.39],[2,1.87,59.33]],"batl":[[2,2.18,8.25]],"ltp":2.0,"tv":1909.67,"id":8734382},{"batl":[[2,2.08,15.47]],"ltp":2.0,"tv":24962.8,"id":9323645}]}]}
{"op":"mcm","clk":"4216608831","pt":1631553644931,"mc":[{"id":"1.187566733","rc":[{"batb":[[0,1.94,49.84],[1,1.93,28.93],[2,1.91,30.39]],"batl":[[1,2.18,8.25],[2,2.24,7.48]],"ltp":2.0,"tv":1909.67,"id":8734382}]}]}
{"op":"mcm","clk":"4216609198","pt":1631553647956,"mc":[{"id":"1.187566733","rc":[{"batl":[[0,2.02,108]],"ltp":2.0,"tv":1909.67,"id":8734382},{"batl":[[0,2.02,8.49],[1,2.04,409.46],[2,2.06,82.09]],"ltp":2.0,"tv":24962.8,"id":9323645}]}]}
{"op":"mcm","clk":"4216609248","pt":1631553648366,"mc":[{"id":"1.187566733","rc":[{"trd":[[2.02,0.38]],"batl":[[0,2.02,107.62]],"ltp":2.02,"tv":1910.05,"id":8734382},{"trd":[[1.98,0.39]],"ltp":1.98,"tv":24963.19,"id":9323645}],"tv":26873.25}]}
{"op":"mcm","clk":"4216609643","pt":1631553651543,"mc":[{"id":"1.187566733","rc":[{"batb":[[0,1.94,77.26],[2,1.92,27.69]],"ltp":2.02,"tv":1910.05,"id":8734382}]}]}
{"op":"mcm","clk":"4216609825","pt":1631553653154,"mc":[{"id":"1.187566733","rc":[{"batl":[[0,2.18,8.25],[1,2.24,7.48],[2,2.52,5.26]],"ltp":2.02,"tv":1910.05,"id":8734382},{"batb":[[1,1.94,49.26],[2,1.85,33.77]],"batl":[[0,2.08,8.19],[1,2.1,7.95],[2,810,0.07]],"ltp":1.98,"tv":24963.19,"id":9323645}]}]}
{"op":"mcm","clk":"4216609895","pt":1631553653750,"mc":[{"id":"1.187566733","rc":[{"batb":[[0,1.92,27.69],[1,1.79,32.64],[2,1.5,107.72]],"batl":[[0,2.24,7.48],[1,2.24,0],[2,2.52,0]],"ltp":2.02,"tv":1910.05,"id":8734382},{"batb":[[0,1.81,57],[1,1.57,1.95],[2,1.4,149.61]],"batl":[[0,2.1,7.95],[1,810,0.07],[2,810,0]],"ltp":1.98,"tv":24963.19,"id":9323645}]}]}
{"op":"mcm","clk":"4216610158","pt":1631553656159,"mc":[{"id":"1.187566733","rc":[{"batb":[[0,1.82,74.61],[1,1.81,57],[2,1.8,101.43]],"batl":[[1,2.14,96.91],[2,2.16,58.48]],"ltp":1.98,"tv":24963.19,"id":9323645}]}]}
{"op":"mcm","clk":"4216610283","pt":1631553657062,"mc":[{"id":"1.187566733","rc":[{"batb":[[0,1.93,27.93],[1,1.92,27.69],[2,1.91,27.39]],"batl":[[0,2.18,7.75],[1,2.24,7.48]],"ltp":2.02,"tv":1910.05,"id":8734382},{"batb":[[0,1.85,28.77],[1,1.82,74.61],[2,1.81,57]],"batl":[[0,2.08,8.19],[1,2.1,7.95],[2,2.14,96.91]],"ltp":1.98,"tv":24963.19,"id":9323645}]}]}
{"op":"mcm","clk":"4216610316","pt":1631553657379,"mc":[{"id":"1.187566733","rc":[{"batb":[[0,1.92,27.69],[1,1.91,27.39],[2,1.79,32.64]],"batl":[[0,2.24,7.48],[1,2.24,0]],"ltp":2.02,"tv":1910.05,"id":8734382},{"batb":[[0,1.81,57],[1,1.57,1.95],[2,1.4,149.61]],"batl":[[0,2.1,7.95],[1,810,0.07],[2,2.14,0]],"ltp":1.98,"tv":24963.19,"id":9323645}]}]}
{"op":"mcm","clk":"4216610619","pt":1631553660179,"mc":[{"id":"1.187566733","rc":[{"batl":[[0,1.94,12.81],[1,1.95,76.92],[2,1.96,38.46]],"ltp":2.02,"tv":1910.05,"id":8734382},{"batb":[[0,2.04,100.49],[1,1.81,57],[2,1.57,1.95]],"batl":[[1,2.12,9.22],[2,2.16,433.13]],"ltp":1.98,"tv":24963.19,"id":9323645}]}]}
{"op":"mcm","clk":"4216610738","pt":1631553661164,"mc":[{"id":"1.187566733","rc":[{"trd":[[1.94,5.2]],"batb":[[1,1.88,98.01],[2,1.86,89.74]],"batl":[[0,1.94,7.61],[1,1.95,84.02],[2,1.96,7.7]],"ltp":1.94,"tv":1915.25,"id":8734382},{"trd":[[2.06,4.9]],"batb":[[0,2.04,98.53],[1,2.02,43.05],[2,1.91,51.69]],"ltp":2.06,"tv":24968.09,"id":9323645}],"tv":26883.35}]}
{"op":"mcm","clk":"4216611425","pt":1631553667353,"mc":[{"id":"1.187566733","rc":[{"batb":[[1,1.89,25.41],[2,1.88,98.01]],"ltp":1.94,"tv":1915.25,"id":8734382},{"batb":[[2,1.97,25.17]],"batl":[[2,2.14,7.25]],"ltp":2.06,"tv":24968.09,"id":9323645}]}]}
{"op":"mcm","clk":"4216611781","pt":1631553670438,"mc":[{"id":"1.187566733","rc":[{"batb":[[1,1.9,33.22],[2,1.89,25.41]],"ltp":1.94,"tv":1915.25,"id":8734382}]}]}
{"op":"mcm","clk":"4216611871","pt":1631553671288,"mc":[{"id":"1.187566733","rc":[{"batl":[[0,1.95,84.02],[1,1.96,7.7],[2,1.97,83.89]],"ltp":1.94,"tv":1915.25,"id":8734382},{"batl":[[1,2.14,7.25],[2,2.16,439.85]],"ltp":2.06,"tv":24968.09,"id":9323645}]}]}
{"op":"mcm","clk":"4216612254","pt":1631553674464,"mc":[{"id":"1.187566733","rc":[{"batb":[[1,1.91,31.04],[2,1.9,33.22]],"batl":[[0,1.94,7.61],[1,1.95,84.02],[2,1.96,7.7]],"ltp":1.94,"tv":1915.25,"id":8734382},{"batl":[[1,2.12,13.97],[2,2.14,7.25]],"ltp":2.06,"tv":24968.09,"id":9323645}]}]}
{"op":"mcm","clk":"4216612444","pt":1631553676054,"mc":[{"id":"1.187566733","rc":[{"batb":[[0,1.87,27.27],[1,1.74,35.92],[2,1.4,149.61]],"batl":[[0,2.08,8.94],[1,1.95,0],[2,1.96,0]],"ltp":1.94,"tv":1915.25,"id":8734382},{"batb":[[0,1.93,27.93],[1,1.91,51.69],[2,1.4,149.61]],"batl":[[0,810,0.07],[1,2.12,0],[2,2.14,0]],"ltp":2.06,"tv":24968.09,"id":9323645}]}]}
{"op":"mcm","clk":"4216612815","pt":1631553679178,"mc":[{"id":"1.187566733","rc":[{"batb":[[0,1.9,27.46],[1,1.88,27.71],[2,1.87,27.27]],"batl":[[0,2.04,8.88],[1,2.08,8.94]],"ltp":1.94,"tv":1915.25,"id":8734382},{"batb":[[0,1.97,27.17],[1,1.93,27.93],[2,1.91,51.69]],"batl":[[0,2.12,8.21],[1,2.14,7.75],[2,810,0.07]],"ltp":2.06,"tv":24968.09,"id":9323645}]}]}
{"op":"mcm","clk":"4216612840","pt":1631553679389,"mc":[{"id":"1.187566733","rc":[{"batb":[[0,1.88,27.71],[1,1.87,27.27],[2,1.74,35.92]],"batl":[[0,2.08,8.94],[1,2.08,0]],"ltp":1.94,"tv":1915.25,"id":8734382},{"batb":[[0,1.93,27.93],[1,1.91,51.69],[2,1.4,149.61]],"batl":[[0,2.14,7.75],[1,810,0.07],[2,810,0]],"ltp":2.06,"tv":24968.09,"id":9323645}]}]}
{"op":"mcm","clk":"4216613165","pt":1631553682182,"mc":[{"id":"1.187566733","rc":[{"batb":[[0,1.93,21.36],[1,1.91,60.84],[2,1.89,85.38]],"batl":[[0,1.96,19.62],[1,1.97,56.33],[2,1.99,74.09]],"ltp":1.94,"tv":1915.25,"id":8734382},{"batl":[[0,2.08,20.44],[1,2.14,7.75],[2,810,0.07]],"ltp":2.06,"tv":24968.09,"id":9323645}]}]}
{"op":"mcm","clk":"4216613283","pt":1631553683084,"mc":[{"id":"1.187566733","rc":[{"batb":[[0,1.91,60.84],[1,1.89,85.38],[2,1.88,27.71]],"batl":[[0,1.97,56.33],[1,1.99,74.09],[2,2.08,8.94]],"ltp":1.94,"tv":1915.25,"id":8734382},{"batl":[[0,2.14,7.75],[1,810,0.07],[2,810,0]],"ltp":2.06,"tv":24968.09,"id":9323645}]}]}
{"op":"mcm","clk":"4216613471","pt":1631553684664,"mc":[{"id":"1.187566733","rc":[{"batl":[[1,810,0]],"ltp":2.06,"tv":24968.09,"id":9323645}]}]}
{"op":"mcm","clk":"4216613647","pt":1631553686195,"mc":[{"id":"1.187566733","rc":[{"batb":[[0,1.88,27.71],[1,1.87,27.27],[2,1.74,35.92]],"batl":[[0,2.08,8.94],[1,1.99,0],[2,2.08,0]],"ltp":1.94,"tv":1915.25,"id":8734382}]}]}
{"op":"mcm","clk":"4216613971","pt":1631553688768,"mc":[{"id":"1.187566733","rc":[{"batb":[[2,1.82,92.38]],"batl":[[0,2.08,104.9],[1,2.1,63.7]],"ltp":1.94,"tv":1915.25,"id":8734382}]}]}
{"op":"mcm","clk":"4216614127","pt":1631553690190,"mc":[{"id":"1.187566733","rc":[{"batb":[[0,1.9,25.46],[1,1.88,27.71],[2,1.87,27.27]],"batl":[[0,2.04,8.63],[1,2.08,104.9],[2,2.1,63.7]],"ltp":1.94,"tv":1915.25,"id":8734382},{"batb":[[0,1.97,27.17],[1,1.93,27.93],[2,1.91,51.69]],"batl":[[0,2.12,8.46],[1,2.14,7.75]],"ltp":2.06,"tv":24968.09,"id":9323645}]}]}
{"op":"mcm","clk":"4216614201","pt":1631553690668,"mc":[{"id":"1.187566733","rc":[{"batb":[[0,1.88,27.71],[1,1.87,27.27],[2,1.82,92.38]],"batl":[[0,2.08,104.9],[1,2.1,63.7],[2,2.1,0]],"ltp":1.94,"tv":1915.25,"id":8734382},{"batb":[[0,1.93,27.93],[1,1.91,51.69],[2,1.4,149.61]],"batl":[[0,2.14,7.75],[1,2.14,0]],"ltp":2.06,"tv":24968.09,"id":9323645}]}]}
{"op":"mcm","clk":"4216614578","pt":1631553694091,"mc":[{"id":"1.187566733","rc":[{"batl":[[0,2.04,8.13],[1,2.08,8.94]],"ltp":1.94,"tv":1915.25,"id":8734382},{"batb":[[0,1.97,25.17],[1,1.93,27.93],[2,1.91,51.69]],"ltp":2.06,"tv":24968.09,"id":9323645}]}]}
{"op":"mcm","clk":"4216614602","pt":1631553694298,"mc":[{"id":"1.187566733","rc":[{"batl":[[0,2.08,8.94],[1,2.08,0]],"ltp":1.94,"tv":1915.25,"id":8734382},{"batb":[[0,1.93,27.93],[1,1.91,51.69],[2,1.4,149.61]],"ltp":2.06,"tv":24968.09,"id":9323645}]}]}
{"op":"mcm","clk":"4216614934","pt":1631553697193,"mc":[{"id":"1.187566733","rc":[{"trd":[[1.88,55.42]],"batb":[[0,1.87,27.27],[1,1.82,92.38],[2,1.8,99.19]],"batl":[[0,1.88,27.78],[1,1.89,120.29],[2,1.9,100.43]],"ltp":1.88,"tv":1970.67,"id":8734382},{"batl":[[1,2.2,13.73],[2,2.24,418.2]],"ltp":2.06,"tv":24968.09,"id":9323645}],"tv":26938.77}]}
{"op":"mcm","clk":"4216615038","pt":1631553698082,"mc":[{"id":"1.187566733","rc":[{"trd":[[1.89,5.34]],"batb":[[1,1.81,16.58],[2,1.8,8.28]],"batl":[[0,1.89,114.95],[1,1.9,15.8],[2,1.91,7.9]],"ltp":1.89,"tv":1976.01,"id":8734382},{"trd":[[2.12,4.76]],"batb":[[0,2.08,38.94],[1,2,44.48],[2,1.93,27.93]],"ltp":2.12,"tv":24972.85,"id":9323645}],"tv":26948.87}]}
{"op":"mcm","clk":"4216615385","pt":1631553700705,"mc":[{"id":"1.187566733","rc":[{"batb":[[1,1.83,59.82],[2,1.81,113.81]],"batl":[[0,1.89,197.75],[2,1.91,91.02]],"ltp":1.89,"tv":1976.01,"id":8734382}]}]}
{"op":"mcm","clk":"4216615655","pt":1631553703083,"mc":[{"id":"1.187566733","rc":[{"batb":[[1,1.86,28.5],[2,1.83,59.82]],"ltp":1.89,"tv":1976.01,"id":8734382}]}]}
{"op":"mcm","clk":"4216615722","pt":1631553703605,"mc":[{"id":"1.187566733","rc":[{"batb":[[1,1.86,55.18]],"ltp":1.89,"tv":1976.01,"id":8734382},{"batb":[[1,2.04,8.62],[2,2.02,8.24]],"batl":[[1,2.16,6.72],[2,2.18,7.75]],"ltp":2.12,"tv":24972.85,"id":9323645}]}]}
{"op":"mcm","clk":"4216616155","pt":1631553707503,"mc":[{"id":"1.187566733","rc":[{"batb":[[0,1.87,180.27]],"ltp":1.89,"tv":1976.01,"id":8734382}]}]}
{"op":"mcm","clk":"4216616324","pt":1631553708929,"mc":[{"id":"1.187566733","rc":[{"trd":[[1.87,41.56]],"batb":[[0,1.87,159.49]],"ltp":1.87,"tv":2017.57,"id":8734382}],"tv":26990.42}]}
{"op":"mcm","clk":"4216616587","pt":1631553711139,"mc":[{"id":"1.187566733","rc":[{"trd":[[1.86,121.41],[1.87,369.4]],"batb":[[0,1.83,59.82],[1,1.81,113.81],[2,1.8,8.28]],"batl":[[0,1.86,184.9],[1,1.89,197.75],[2,1.9,15.8]],"ltp":1.86,"tv":2466.83,"id":8734382},{"trd":[[2.14,7.75],[2.16,9.52]],"batl":[[0,2.2,13.73],[1,2.24,418.2],[2,2.18,0]],"ltp":2.16,"tv":24990.12,"id":9323645}],"tv":27456.95}]}
{"op":"mcm","clk":"4216616617","pt":1631553711305,"mc":[{"id":"1.187566733","rc":[{"batb":[[1,2,44.48],[2,1.93,27.93]],"ltp":2.16,"tv":24990.12,"id":9323645}]}]}
{"op":"mcm","clk":"4216616767","pt":1631553712931,"mc":[{"id":"1.187566733","rc":[{"batb":[[0,1.81,16.58],[1,1.8,8.28],[2,1.79,8.28]],"ltp":1.86,"tv":2466.83,"id":8734382}]}]}
{"op":"mcm","clk":"4216616896","pt":1631553714027,"mc":[{"id":"1.187566733","rc":[{"batb":[[0,1.83,39.21],[1,1.81,16.58],[2,1.8,8.28]],"ltp":1.86,"tv":2466.83,"id":8734382}]}]}
{"op":"mcm","clk":"4216616953","pt":1631553714505,"mc":[{"id":"1.187566733","rc":[{"batb":[[0,1.83,101.21]],"ltp":1.86,"tv":2466.83,"id":8734382}]}]}
{"op":"mcm","clk":"4216617129","pt":1631553716120,"mc":[{"id":"1.187566733","rc":[{"batb":[[1,1.82,142.41],[2,1.81,16.58]],"ltp":1.86,"tv":2466.83,"id":8734382}]}]}
{"op":"mcm","clk":"4216617347","pt":1631553717913,"mc":[{"id":"1.187566733","rc":[{"batb":[[0,1.69,39.27],[1,1.4,149.61],[2,1.3,199.49]],"batl":[[1,1.89,0],[2,1.9,0]],"ltp":1.86,"tv":2466.83,"id":8734382},{"batb":[[0,2.14,31],[2,1.5,107.72]],"ltp":2.16,"tv":24990.12,"id":9323645}]}]}
