{"op":"mcm","clk":"4206563107","pt":1631438902043,"mc":[{"id":"1.187552293","marketDefinition":{"bspMarket":false,"turnInPlayEnabled":true,"persistenceEnabled":true,"marketBaseRate":5.0,"eventId":"30895221","eventTypeId":"2","numberOfWinners":1,"bettingType":"ODDS","marketType":"MATCH_ODDS","marketTime":"2021-09-12T13:30:00.000Z","suspendTime":"2021-09-12T13:30:00.000Z","bspReconciled":false,"complete":true,"inPlay":false,"crossMatching":false,"runnersVoidable":false,"numberOfActiveRunners":2,"betDelay":0,"status":"OPEN","runners":[{"status":"ACTIVE","sortPriority":1,"id":20586366,"name":"S Milatova"},{"status":"ACTIVE","sortPriority":2,"id":9636890,"name":"R Ushijima"}],"regulators":["MR_INT"],"countryCode":"GB","discountAllowed":false,"timezone":"GMT","openDate":"2021-09-12T13:30:00.000Z","version":4027604618,"name":"Match Odds","eventName":"S Milatova v R Ushijima"},"rc":[{"batb":[[0,1.01,25]],"ltp":0.0,"tv":0.0,"id":9636890},{"batb":[[0,1.01,25]],"ltp":0.0,"tv":0.0,"id":20586366}]}]}
{"op":"mcm","clk":"4206563235","pt":1631438903730,"mc":[{"id":"1.187552293","marketDefinition":{"bspMarket":false,"turnInPlayEnabled":true,"persistenceEnabled":true,"marketBaseRate":5.0,"eventId":"30895221","eventTypeId":"2","numberOfWinners":1,"bettingType":"ODDS","marketType":"MATCH_ODDS","marketTime":"2021-09-12T13:30:00.000Z","suspendTime":"2021-09-12T13:30:00.000Z","bspReconciled":false,"complete":true,"inPlay":false,"crossMatching":false,"runnersVoidable":false,"numberOfActiveRunners":2,"betDelay":0,"status":"OPEN","runners":[{"status":"ACTIVE","sortPriority":1,"id":20586366,"name":"S Milatova"},{"status":"ACTIVE","sortPriority":2,"id":9636890,"name":"R Ushijima"}],"regulators":["MR_INT"],"countryCode":"GB","discountAllowed":true,"timezone":"GMT","openDate":"2021-09-12T13:30:00.000Z","version":4027604618,"name":"Match Odds","eventName":"S Milatova v R Ushijima"}}]}
{"op":"mcm","clk":"4206572148","pt":1631439019287,"mc":[{"id":"1.187552293","rc":[{"batb":[[0,1.01,7]],"ltp":0.0,"tv":0.0,"id":9636890},{"batb":[[0,1.01,7]],"ltp":0.0,"tv":0.0,"id":20586366}]}]}
{"op":"mcm","clk":"4206658695","pt":1631439871706,"mc":[{"id":"1.187552293","rc":[{"batl":[[0,490,6.16]],"ltp":0.0,"tv":0.0,"id":9636890},{"batl":[[0,490,6.16]],"ltp":0.0,"tv":0.0,"id":20586366}]}]}
{"op":"mcm","clk":"4206779579","pt":1631440928852,"mc":[{"id":"1.187552293","rc":[{"batb":[[0,1.67,50.47],[1,1.01,7]],"ltp":0.0,"tv":0.0,"id":9636890},{"batb":[[0,2.1,30.74],[1,1.01,7]],"ltp":0.0,"tv":0.0,"id":20586366}]}]}
{"op":"mcm","clk":"4206783107","pt":1631440957946,"mc":[{"id":"1.187552293","marketDefinition":{"bspMarket":false,"turnInPlayEnabled":true,"persistenceEnabled":true,"marketBaseRate":5.0,"eventId":"30895221","eventTypeId":"2","numberOfWinners":1,"bettingType":"ODDS","marketType":"MATCH_ODDS","marketTime":"2021-09-12T13:30:00.000Z","suspendTime":"2021-09-12T13:30:00.000Z","bspReconciled":false,"complete":true,"inPlay":false,"crossMatching":true,"runnersVoidable":false,"numberOfActiveRunners":2,"betDelay":0,"status":"OPEN","runners":[{"status":"ACTIVE","sortPriority":1,"id":20586366,"name":"S Milatova"},{"status":"ACTIVE","sortPriority":2,"id":9636890,"name":"R Ushijima"}],"regulators":["MR_INT"],"countryCode":"GB","discountAllowed":true,"timezone":"GMT","openDate":"2021-09-12T13:30:00.000Z","version":4027604618,"name":"Match Odds","eventName":"S Milatova v R Ushijima"}}]}
{"op":"mcm","clk":"4206864797","pt":1631441549621,"mc":[{"id":"1.187552293","rc":[{"batl":[[1,990,2.2]],"ltp":0.0,"tv":0.0,"id":9636890},{"batl":[[1,990,2.2]],"ltp":0.0,"tv":0.0,"id":20586366}]}]}
{"op":"mcm","clk":"4207258686","pt":1631444495190,"mc":[{"id":"1.187552293","rc":[{"batb":[[1,1.01,12]],"ltp":0.0,"tv":0.0,"id":9636890},{"batb":[[1,1.01,12]],"ltp":0.0,"tv":0.0,"id":20586366}]}]}
{"op":"mcm","clk":"4207472050","pt":1631445675691,"mc":[{"id":"1.187552293","rc":[{"batb":[[1,1.05,879.5],[2,1.01,12]],"ltp":0.0,"tv":0.0,"id":9636890},{"batb":[[1,1.05,879.5],[2,1.01,12]],"ltp":0.0,"tv":0.0,"id":20586366}]}]}
{"op":"mcm","clk":"4207497431","pt":1631445819705,"mc":[{"id":"1.187552293","rc":[{"batb":[[2,1.02,108.45]],"ltp":0.0,"tv":0.0,"id":9636890},{"batb":[[2,1.02,108.45]],"ltp":0.0,"tv":0.0,"id":20586366}]}]}
{"op":"mcm","clk":"4207568901","pt":1631446203785,"mc":[{"id":"1.187552293","rc":[{"batb":[[0,1.67,67.3]],"ltp":0.0,"tv":0.0,"id":9636890},{"batb":[[0,2.1,40.99]],"ltp":0.0,"tv":0.0,"id":20586366}]}]}
{"op":"mcm","clk":"4208233688","pt":1631449725872,"mc":[{"id":"1.187552293","rc":[{"batb":[[0,1.7,28.18],[1,1.67,67.3],[2,1.05,879.5]],"ltp":0.0,"tv":0.0,"id":9636890}]}]}
{"op":"mcm","clk":"4208247862","pt":1631449800608,"mc":[{"id":"1.187552293","rc":[{"batb":[[0,1.71,18.05],[1,1.7,28.18],[2,1.67,67.3]],"ltp":0.0,"tv":0.0,"id":9636890},{"batb":[[0,2.12,11.44],[1,2.1,40.99],[2,1.05,879.5]],"ltp":0.0,"tv":0.0,"id":20586366}]}]}
{"op":"mcm","clk":"4208329034","pt":1631450189183,"mc":[{"id":"1.187552293","rc":[{"batb":[[0,1.71,46.23],[1,1.67,67.3],[2,1.05,879.5]],"ltp":0.0,"tv":0.0,"id":9636890}]}]}
{"op":"mcm","clk":"4208569415","pt":1631451399964,"mc":[{"id":"1.187552293","rc":[{"batb":[[1,1.67,68.68]],"ltp":0.0,"tv":0.0,"id":9636890}]}]}
{"op":"mcm","clk":"4208691844","pt":1631452026576,"mc":[{"id":"1.187552293","rc":[{"batl":[[0,2.56,2.66],[1,490,6.16],[2,990,2.2]],"ltp":0.0,"tv":0.0,"id":9636890}]}]}
{"op":"mcm","clk":"4208692701","pt":1631452030939,"mc":[{"id":"1.187552293","rc":[{"batb":[[2,1.4,5.32]],"ltp":0.0,"tv":0.0,"id":9636890}]}]}
{"op":"mcm","clk":"4208844297","pt":1631452686270,"mc":[{"id":"1.187552293","rc":[{"batb":[[1,2,45.09]],"ltp":0.0,"tv":0.0,"id":20586366}]}]}
{"op":"mcm","clk":"4208844452","pt":1631452687193,"mc":[{"id":"1.187552293","rc":[{"batb":[[0,2.02,12.56]],"ltp":0.0,"tv":0.0,"id":20586366}]}]}
{"op":"mcm","clk":"4208861336","pt":1631452774334,"mc":[{"id":"1.187552293","rc":[{"batb":[[0,1.71,28.18]],"ltp":0.0,"tv":0.0,"id":9636890},{"batb":[[0,2,45.09],[1,1.05,879.5],[2,1.02,108.45]],"ltp":0.0,"tv":0.0,"id":20586366}]}]}
{"op":"mcm","clk":"4208861554","pt":1631452775292,"mc":[{"id":"1.187552293","rc":[{"batb":[[0,1.72,17.79],[1,1.71,28.18],[2,1.67,68.68]],"ltp":0.0,"tv":0.0,"id":9636890},{"batb":[[0,2.02,12.56],[1,2,45.09],[2,1.05,879.5]],"ltp":0.0,"tv":0.0,"id":20586366}]}]}
{"op":"mcm","clk":"4208874217","pt":1631452843338,"mc":[{"id":"1.187552293","rc":[{"batb":[[0,1.73,17.55]],"ltp":0.0,"tv":0.0,"id":9636890},{"batb":[[0,2.04,12.32]],"ltp":0.0,"tv":0.0,"id":20586366}]}]}
{"op":"mcm","clk":"4208874397","pt":1631452844318,"mc":[{"id":"1.187552293","rc":[{"batb":[[0,1.71,28.18],[1,1.67,68.68],[2,1.4,5.32]],"ltp":0.0,"tv":0.0,"id":9636890},{"batb":[[0,2,45.09],[1,1.05,879.5],[2,1.02,108.45]],"ltp":0.0,"tv":0.0,"id":20586366}]}]}
{"op":"mcm","clk":"4208874564","pt":1631452845333,"mc":[{"id":"1.187552293","rc":[{"batb":[[0,1.72,17.79],[1,1.71,28.18],[2,1.67,68.68]],"ltp":0.0,"tv":0.0,"id":9636890},{"batb":[[0,2.02,12.56],[1,2,45.09],[2,1.05,879.5]],"ltp":0.0,"tv":0.0,"id":20586366}]}]}
{"op":"mcm","clk":"4208977532","pt":1631453392827,"mc":[{"id":"1.187552293","rc":[{"batb":[[2,1.02,108.45]],"ltp":0.0,"tv":0.0,"id":20586366}]}]}
{"op":"mcm","clk":"4208979792","pt":1631453403934,"mc":[{"id":"1.187552293","rc":[{"batl":[[1,2.9,43.98],[2,490,6.16]],"ltp":0.0,"tv":0.0,"id":9636890}]}]}
{"op":"mcm","clk":"4209001818","pt":1631453517685,"mc":[{"id":"1.187552293","marketDefinition":{"bspMarket":false,"turnInPlayEnabled":true,"persistenceEnabled":true,"marketBaseRate":5.0,"eventId":"30895221","eventTypeId":"2","numberOfWinners":1,"bettingType":"ODDS","marketType":"MATCH_ODDS","marketTime":"2021-09-12T13:30:00.000Z","suspendTime":"2021-09-12T13:30:00.000Z","bspReconciled":false,"complete":true,"inPlay":true,"crossMatching":true,"runnersVoidable":false,"numberOfActiveRunners":2,"betDelay":5,"status":"OPEN","runners":[{"status":"ACTIVE","sortPriority":1,"id":20586366,"name":"S Milatova"},{"status":"ACTIVE","sortPriority":2,"id":9636890,"name":"R Ushijima"}],"regulators":["MR_INT"],"countryCode":"GB","discountAllowed":true,"timezone":"GMT","openDate":"2021-09-12T13:30:00.000Z","version":4028394468,"name":"Match Odds","eventName":"S Milatova v R Ushijima"},"rc":[{"batb":[[0,1.67,1.38],[1,1.01,12],[2,1.67,0]],"ltp":0.0,"tv":0.0,"id":9636890},{"batb":[[0,1.01,12],[1,2,0],[2,1.02,0]],"ltp":0.0,"tv":0.0,"id":20586366}]}]}
{"op":"mcm","clk":"4209622985","pt":1631456753208,"mc":[{"id":"1.187552293","marketDefinition":{"bspMarket":false,"turnInPlayEnabled":true,"persistenceEnabled":true,"marketBaseRate":5.0,"eventId":"30895221","eventTypeId":"2","numberOfWinners":1,"bettingType":"ODDS","marketType":"MATCH_ODDS","marketTime":"2021-09-12T14:25:52.000Z","suspendTime":"2021-09-12T14:25:52.000Z","bspReconciled":false,"complete":true,"inPlay":true,"crossMatching":true,"runnersVoidable":false,"numberOfActiveRunners":2,"betDelay":5,"status":"OPEN","runners":[{"status":"ACTIVE","sortPriority":1,"id":20586366,"name":"S Milatova"},{"status":"ACTIVE","sortPriority":2,"id":9636890,"name":"R Ushijima"}],"regulators":["MR_INT"],"countryCode":"GB","discountAllowed":true,"timezone":"GMT","openDate":"2021-09-12T13:30:00.000Z","version":4028607558,"name":"Match Odds","eventName":"S Milatova v R Ushijima"}}]}
{"op":"mcm","clk":"4209623429","pt":1631456755221,"mc":[{"id":"1.187552293","marketDefinition":{"bspMarket":false,"turnInPlayEnabled":true,"persistenceEnabled":true,"marketBaseRate":5.0,"eventId":"30895221","eventTypeId":"2","numberOfWinners":1,"bettingType":"ODDS","marketType":"MATCH_ODDS","marketTime":"2021-09-12T14:25:52.000Z","suspendTime":"2021-09-12T14:25:52.000Z","bspReconciled":false,"complete":true,"inPlay":true,"crossMatching":true,"runnersVoidable":false,"numberOfActiveRunners":2,"betDelay":5,"status":"OPEN","runners":[{"status":"ACTIVE","sortPriority":1,"id":20586366,"name":"S Milatova"},{"status":"ACTIVE","sortPriority":2,"id":9636890,"name":"R Ushijima"}],"regulators":["MR_INT"],"countryCode":"GB","discountAllowed":true,"timezone":"GMT","openDate":"2021-09-12T14:25:52.000Z","version":4028607558,"name":"Match Odds","eventName":"S Milatova v R Ushijima"}}]}
{"op":"mcm","clk":"4210347686","pt":1631460905849,"mc":[{"id":"1.187552293","rc":[{"trd":[[1.01,24]],"batl":[[0,1.01,10]],"ltp":1.01,"tv":24.0,"id":20586366}],"tv":24.0}]}
{"op":"mcm","clk":"4210350528","pt":1631460921597,"mc":[{"id":"1.187552293","rc":[{"trd":[[1.01,44]],"batb":[[0,1.01,0.85]],"ltp":1.01,"tv":43.99,"id":20586366}],"tv":43.99}]}
{"op":"mcm","clk":"4210352447","pt":1631460932878,"mc":[{"id":"1.187552293","rc":[{"batl":[[0,2.5,4.04]],"ltp":1.01,"tv":43.99,"id":20586366}]}]}
{"op":"mcm","clk":"4210367820","pt":1631461023472,"mc":[{"id":"1.187552293","rc":[{"batl":[[0,2.5,76.34]],"ltp":1.01,"tv":43.99,"id":20586366}]}]}
{"op":"mcm","clk":"4210368696","pt":1631461028706,"mc":[{"id":"1.187552293","rc":[{"batl":[[0,2.5,4.04]],"ltp":1.01,"tv":43.99,"id":20586366}]}]}
{"op":"mcm","clk":"4210369570","pt":1631461033808,"mc":[{"id":"1.187552293","rc":[{"batl":[[0,2.48,72.3],[1,2.5,4.04]],"ltp":1.01,"tv":43.99,"id":20586366}]}]}
{"op":"mcm","clk":"4210375097","pt":1631461066139,"mc":[{"id":"1.187552293","rc":[{"batb":[[0,1.01,890.03]],"ltp":1.01,"tv":43.99,"id":20586366}]}]}
{"op":"mcm","clk":"4210456191","pt":1631461530366,"mc":[{"id":"1.187552293","rc":[{"trd":[[1.01,505.18]],"batb":[[0,1.01,659.44]],"ltp":1.01,"tv":505.18,"id":20586366}],"tv":505.18}]}
{"op":"mcm","clk":"4210460470","pt":1631461555929,"mc":[{"id":"1.187552293","rc":[{"trd":[[1.01,649.78]],"batb":[[0,1.01,587.14]],"ltp":1.01,"tv":649.78,"id":20586366}],"tv":649.78}]}
{"op":"mcm","clk":"4210503830","pt":1631461831670,"mc":[{"id":"1.187552293","marketDefinition":{"bspMarket":false,"turnInPlayEnabled":true,"persistenceEnabled":true,"marketBaseRate":5.0,"eventId":"30895221","eventTypeId":"2","numberOfWinners":1,"bettingType":"ODDS","marketType":"MATCH_ODDS","marketTime":"2021-09-12T14:25:52.000Z","suspendTime":"2021-09-12T14:25:52.000Z","bspReconciled":false,"complete":true,"inPlay":true,"crossMatching":true,"runnersVoidable":false,"numberOfActiveRunners":2,"betDelay":5,"status":"SUSPENDED","runners":[{"status":"ACTIVE","sortPriority":1,"id":20586366,"name":"S Milatova"},{"status":"ACTIVE","sortPriority":2,"id":9636890,"name":"R Ushijima"}],"regulators":["MR_INT"],"countryCode":"GB","discountAllowed":true,"timezone":"GMT","openDate":"2021-09-12T14:25:52.000Z","version":4028962307,"name":"Match Odds","eventName":"S Milatova v R Ushijima"}}]}
{"op":"mcm","clk":"4210504807","pt":1631461838731,"mc":[{"id":"1.187552293","tv":0.0}]}
{"op":"mcm","clk":"4210504947","pt":1631461839753,"mc":[{"id":"1.187552293","marketDefinition":{"bspMarket":false,"turnInPlayEnabled":true,"persistenceEnabled":true,"marketBaseRate":5.0,"eventId":"30895221","eventTypeId":"2","numberOfWinners":1,"bettingType":"ODDS","marketType":"MATCH_ODDS","marketTime":"2021-09-12T14:25:52.000Z","suspendTime":"2021-09-12T14:25:52.000Z","bspReconciled":false,"complete":true,"inPlay":true,"crossMatching":false,"runnersVoidable":false,"numberOfActiveRunners":0,"betDelay":5,"status":"CLOSED","settledTime":"2021-09-12T15:50:36.000Z","runners":[{"status":"WINNER","sortPriority":1,"id":20586366,"name":"S Milatova"},{"status":"LOSER","sortPriority":2,"id":9636890,"name":"R Ushijima"}],"regulators":["MR_INT"],"countryCode":"GB","discountAllowed":true,"timezone":"GMT","openDate":"2021-09-12T14:25:52.000Z","version":4028962421,"name":"Match Odds","eventName":"S Milatova v R Ushijima"}}]}
