{"op":"mcm","clk":"4215025429","pt":1631533705536,"mc":[{"id":"1.187557985","rc":[{"batb":[[0,1.35,292.08],[1,1.34,315.05],[2,1.29,538.19]],"batl":[[0,1.38,216.67],[1,1.39,258.73],[2,1.45,5]],"ltp":1.35,"tv":13397.09,"id":5300820}]}]}
{"op":"mcm","clk":"4215025485","pt":1631533706524,"mc":[{"id":"1.187557985","rc":[{"batl":[[2,1.43,69.28]],"ltp":1.35,"tv":13397.09,"id":5300820},{"batb":[[0,3.3,14.16],[1,3.25,3],[2,3.2,157.89]],"ltp":3.85,"tv":4555.51,"id":9629022}]}]}
{"op":"mcm","clk":"4215025552","pt":1631533707613,"mc":[{"id":"1.187557985","rc":[{"batl":[[0,4.3,47.36],[1,4.4,132.72],[2,4.5,111.58]],"ltp":3.85,"tv":4555.51,"id":9629022}]}]}
{"op":"mcm","clk":"4215025613","pt":1631533708645,"mc":[{"id":"1.187557985","rc":[{"batb":[[0,1.29,538.19],[1,1.28,388.12],[2,1.27,1008.41]],"batl":[[0,1.36,218],[1,1.43,8],[2,1.44,6]],"ltp":1.35,"tv":13397.09,"id":5300820},{"batb":[[0,3.3,2]],"batl":[[0,4.4,132.72],[1,4.5,111.58],[2,4.6,155.11]],"ltp":3.85,"tv":4555.51,"id":9629022}]}]}
{"op":"mcm","clk":"4215025623","pt":1631533708850,"mc":[{"id":"1.187557985","rc":[{"batl":[[0,1.43,8],[1,1.44,6],[2,1.45,5]],"ltp":1.35,"tv":13397.09,"id":5300820}]}]}
{"op":"mcm","clk":"4215025716","pt":1631533710620,"mc":[{"id":"1.187557985","rc":[{"batb":[[0,3.35,53.68],[1,3.3,2],[2,3.25,3]],"ltp":3.85,"tv":4555.51,"id":9629022}]}]}
{"op":"mcm","clk":"4215025768","pt":1631533711521,"mc":[{"id":"1.187557985","rc":[{"batb":[[1,1.28,759.21],[2,1.27,1430.58]],"batl":[[0,1.43,66.35],[2,1.45,191.98]],"ltp":1.35,"tv":13397.09,"id":5300820},{"batb":[[0,3.3,13.76],[1,3.25,3],[2,3.2,157.89]],"ltp":3.85,"tv":4555.51,"id":9629022}]}]}
{"op":"mcm","clk":"4215025798","pt":1631533712163,"mc":[{"id":"1.187557985","rc":[{"batb":[[0,1.27,446.4],[1,1.26,101.98],[2,1.23,523.6]],"batl":[[0,1.43,8]],"ltp":1.35,"tv":13397.09,"id":5300820},{"batb":[[0,3.3,2]],"batl":[[0,4.9,2.35],[1,4.5,0],[2,4.6,0]],"ltp":3.85,"tv":4555.51,"id":9629022}]}]}
{"op":"mcm","clk":"4215025902","pt":1631533713660,"mc":[{"id":"1.187557985","rc":[{"batb":[[0,1.41,832.92],[1,1.27,446.4],[2,1.26,101.98]],"ltp":1.35,"tv":13397.09,"id":5300820}]}]}
{"op":"mcm","clk":"4215025959","pt":1631533714521,"mc":[{"id":"1.187557985","rc":[{"batb":[[0,1.4,2732.14],[1,1.39,2651.78],[2,1.38,2651.78]],"batl":[[0,1.45,186.98],[1,1.46,561.48],[2,1.47,2955.98]],"ltp":1.35,"tv":13397.09,"id":5300820},{"batb":[[0,3.2,155.89],[1,3.15,228.13],[2,3.1,243.37]],"batl":[[0,3.95,5.06],[1,4.9,2.35]],"ltp":3.85,"tv":4555.51,"id":9629022}]}]}
{"op":"mcm","clk":"4215026036","pt":1631533715561,"mc":[{"id":"1.187557985","rc":[{"trd":[[1.42,28.16]],"batb":[[0,1.42,148.09],[1,1.41,246.02],[2,1.4,1366.08]],"batl":[[2,1.47,1069.5]],"ltp":1.42,"tv":13425.25,"id":5300820}],"tv":17980.77}]}
{"op":"mcm","clk":"4215026119","pt":1631533716550,"mc":[{"id":"1.187557985","rc":[{"batb":[[1,1.41,457.31]],"batl":[[1,1.46,568.98]],"ltp":1.42,"tv":13425.25,"id":5300820},{"batb":[[0,3.2,169.52]],"batl":[[0,3.65,4.6],[1,3.8,11.75],[2,3.95,5.06]],"ltp":3.85,"tv":4555.51,"id":9629022}]}]}
{"op":"mcm","clk":"4215026143","pt":1631533716959,"mc":[{"id":"1.187557985","rc":[{"batb":[[0,1.42,156.09],[1,1.41,463.31]],"ltp":1.42,"tv":13425.25,"id":5300820},{"batl":[[0,3.4,3],[1,3.65,4.6]],"ltp":3.85,"tv":4555.51,"id":9629022}]}]}
{"op":"mcm","clk":"4215026222","pt":1631533717944,"mc":[{"id":"1.187557985","rc":[{"batb":[[2,1.4,1374.08]],"ltp":1.42,"tv":13425.25,"id":5300820},{"batl":[[1,3.45,3],[2,3.65,4.6]],"ltp":3.85,"tv":4555.51,"id":9629022}]}]}
{"op":"mcm","clk":"4215026300","pt":1631533719556,"mc":[{"id":"1.187557985","rc":[{"batl":[[1,1.46,674.77]],"ltp":1.42,"tv":13425.25,"id":5300820},{"batl":[[0,3.35,11.64],[1,3.4,3],[2,3.45,3]],"ltp":3.85,"tv":4555.51,"id":9629022}]}]}
{"op":"mcm","clk":"4215026343","pt":1631533720138,"mc":[{"id":"1.187557985","rc":[{"batl":[[1,1.46,568.98]],"ltp":1.42,"tv":13425.25,"id":5300820},{"batl":[[0,3.4,3],[1,3.45,3],[2,3.9,3]],"ltp":3.85,"tv":4555.51,"id":9629022}]}]}
{"op":"mcm","clk":"4215026486","pt":1631533722055,"mc":[{"id":"1.187557985","rc":[{"batl":[[2,3.9,114.84]],"ltp":3.85,"tv":4555.51,"id":9629022}]}]}
{"op":"mcm","clk":"4215026609","pt":1631533723249,"mc":[{"id":"1.187557985","rc":[{"batl":[[0,3.4,26],[2,3.55,4.69]],"ltp":3.85,"tv":4555.51,"id":9629022}]}]}
{"op":"mcm","clk":"4215027170","pt":1631533731590,"mc":[{"id":"1.187557985","rc":[{"batb":[[0,1.42,148.09],[1,1.41,457.31],[2,1.39,48.03]],"batl":[[1,1.46,216.57],[2,1.47,6.33]],"ltp":1.42,"tv":13425.25,"id":5300820},{"batb":[[0,3.2,13.63],[1,3.15,89.04],[2,3.1,9.44]],"batl":[[0,3.55,4.69],[1,3.9,111.84],[2,3.95,133.82]],"ltp":3.85,"tv":4555.51,"id":9629022}]}]}
{"op":"mcm","clk":"4215027226","pt":1631533732477,"mc":[{"id":"1.187557985","rc":[{"batb":[[0,1.34,359.05],[1,1.33,729.79],[2,1.32,554.45]],"batl":[[0,1.58,310.78],[1,1.59,302.57],[2,1.6,410.06]],"ltp":1.42,"tv":13425.25,"id":5300820},{"batb":[[0,2.74,51.3],[1,2.72,146.46],[2,2.7,180.55]],"batl":[[0,3.9,111.84],[1,3.95,133.82],[2,4,189.71]],"ltp":3.85,"tv":4555.51,"id":9629022}]}]}
{"op":"mcm","clk":"4215027452","pt":1631533735581,"mc":[{"id":"1.187557985","rc":[{"batl":[[0,1.57,40.5],[1,1.58,310.78],[2,1.59,302.57]],"ltp":1.42,"tv":13425.25,"id":5300820},{"batb":[[0,2.74,56.32]],"ltp":3.85,"tv":4555.51,"id":9629022}]}]}
{"op":"mcm","clk":"4215027550","pt":1631533736591,"mc":[{"id":"1.187557985","rc":[{"batl":[[0,1.58,316.78],[1,1.59,302.57],[2,1.6,410.06]],"ltp":1.42,"tv":13425.25,"id":5300820},{"batb":[[0,2.74,54.3],[1,2.72,149.46]],"ltp":3.85,"tv":4555.51,"id":9629022}]}]}
{"op":"mcm","clk":"4215027709","pt":1631533739257,"mc":[{"id":"1.187557985","rc":[{"batb":[[0,1.44,190.33],[1,1.43,231.35],[2,1.34,359.05]],"batl":[[0,1.48,323.68],[1,1.49,191.4],[2,1.57,44.5]],"ltp":1.42,"tv":13425.25,"id":5300820},{"batb":[[0,2.74,59.32]],"ltp":3.85,"tv":4555.51,"id":9629022}]}]}
{"op":"mcm","clk":"4215027791","pt":1631533740384,"mc":[{"id":"1.187557985","rc":[{"batb":[[0,1.34,359.05],[1,1.33,729.79],[2,1.32,554.45]],"batl":[[0,1.57,44.5],[1,1.58,316.78],[2,1.59,302.57]],"ltp":1.42,"tv":13425.25,"id":5300820}]}]}
{"op":"mcm","clk":"4215027851","pt":1631533741188,"mc":[{"id":"1.187557985","rc":[{"batl":[[0,1.57,5]],"ltp":1.42,"tv":13425.25,"id":5300820},{"batb":[[0,2.74,54.3]],"ltp":3.85,"tv":4555.51,"id":9629022}]}]}
{"op":"mcm","clk":"4215028025","pt":1631533743183,"mc":[{"id":"1.187557985","rc":[{"batb":[[0,1.34,637.17],[1,1.33,1056.96]],"batl":[[1,1.58,580.49],[2,1.59,451.94]],"ltp":1.42,"tv":13425.25,"id":5300820}]}]}
{"op":"mcm","clk":"4215028228","pt":1631533746507,"mc":[{"id":"1.187557985","rc":[{"batb":[[0,1.33,345.01],[1,1.28,585.76],[2,1.27,97.87]],"ltp":1.42,"tv":13425.25,"id":5300820},{"batl":[[0,4.1,2.55],[1,4.6,2.21],[2,4.9,2.35]],"ltp":3.85,"tv":4555.51,"id":9629022}]}]}
{"op":"mcm","clk":"4215028289","pt":1631533747507,"mc":[{"id":"1.187557985","rc":[{"batl":[[0,1.57,47.5]],"ltp":1.42,"tv":13425.25,"id":5300820},{"batb":[[0,2.74,58.82]],"ltp":3.85,"tv":4555.51,"id":9629022}]}]}
{"op":"mcm","clk":"4215028348","pt":1631533748297,"mc":[{"id":"1.187557985","rc":[{"batb":[[1,1.28,93.16]],"batl":[[0,1.58,574.49],[1,1.59,451.94],[2,1.6,410.06]],"ltp":1.42,"tv":13425.25,"id":5300820},{"batb":[[0,2.74,51.3],[1,2.72,146.46]],"ltp":3.85,"tv":4555.51,"id":9629022}]}]}
{"op":"mcm","clk":"4215028433","pt":1631533749488,"mc":[{"id":"1.187557985","rc":[{"batb":[[0,1.53,248.81],[1,1.52,179.47],[2,1.38,1043.71]],"batl":[[2,1.6,1067.49]],"ltp":1.42,"tv":13425.25,"id":5300820},{"batl":[[0,2.94,650.52],[1,2.96,631.38],[2,2.98,631.38]],"ltp":3.85,"tv":4555.51,"id":9629022}]}]}
{"op":"mcm","clk":"4215028488","pt":1631533750386,"mc":[{"id":"1.187557985","rc":[{"trd":[[1.53,1160]],"batb":[[0,1.53,235.56],[2,1.51,156.48]],"batl":[[0,1.54,7.5],[1,1.58,574.49],[2,1.59,451.94]],"ltp":1.53,"tv":13451.75,"id":5300820},{"batb":[[0,2.84,16.3],[1,2.74,51.3],[2,2.72,146.46]],"ltp":3.85,"tv":4555.51,"id":9629022}],"tv":18007.27}]}
{"op":"mcm","clk":"4215028530","pt":1631533751282,"mc":[{"id":"1.187557985","rc":[{"batl":[[0,2.88,3],[1,2.94,650.52],[2,2.96,631.38]],"ltp":3.85,"tv":4555.51,"id":9629022}]}]}
{"op":"mcm","clk":"4215028614","pt":1631533752380,"mc":[{"id":"1.187557985","rc":[{"batb":[[1,1.52,184.47],[2,1.51,162.48]],"batl":[[0,1.58,574.49],[1,1.59,451.94],[2,1.6,1067.49]],"ltp":1.53,"tv":13451.75,"id":5300820},{"batb":[[0,2.74,51.3],[1,2.72,146.46],[2,2.7,180.55]],"batl":[[1,2.92,3],[2,2.94,650.52]],"ltp":3.85,"tv":4555.51,"id":9629022}]}]}
{"op":"mcm","clk":"4215028796","pt":1631533754576,"mc":[{"id":"1.187557985","rc":[{"batl":[[0,1.58,464.39],[1,1.59,302.57]],"ltp":1.53,"tv":13451.75,"id":5300820}]}]}
{"op":"mcm","clk":"4215028875","pt":1631533755635,"mc":[{"id":"1.187557985","rc":[{"batl":[[0,1.56,7.5],[1,1.58,464.39],[2,1.59,302.57]],"ltp":1.53,"tv":13451.75,"id":5300820},{"batb":[[0,2.78,16.85],[1,2.74,51.3],[2,2.72,146.46]],"ltp":3.85,"tv":4555.51,"id":9629022}]}]}
{"op":"mcm","clk":"4215028950","pt":1631533756529,"mc":[{"id":"1.187557985","rc":[{"batl":[[2,1.59,342.07]],"ltp":1.53,"tv":13451.75,"id":5300820}]}]}
{"op":"mcm","clk":"4215029004","pt":1631533757417,"mc":[{"id":"1.187557985","rc":[{"batl":[[1,1.57,133.54],[2,1.58,464.39]],"ltp":1.53,"tv":13451.75,"id":5300820}]}]}
{"op":"mcm","clk":"4215029377","pt":1631533761824,"mc":[{"id":"1.187557985","rc":[{"trd":[[1.53,1187.44]],"batb":[[0,1.53,221.84]],"ltp":1.53,"tv":13479.19,"id":5300820}],"tv":18034.71}]}
{"op":"mcm","clk":"4215029519","pt":1631533763392,"mc":[{"id":"1.187557985","rc":[{"batb":[[0,1.54,35.87],[1,1.53,221.84],[2,1.52,184.47]],"ltp":1.53,"tv":13479.19,"id":5300820}]}]}
{"op":"mcm","clk":"4215029551","pt":1631533763705,"mc":[{"id":"1.187557985","rc":[{"batl":[[0,2.92,3],[1,2.94,650.52],[2,2.96,631.38]],"ltp":3.85,"tv":4555.51,"id":9629022}]}]}
{"op":"mcm","clk":"4215029642","pt":1631533765111,"mc":[{"id":"1.187557985","rc":[{"trd":[[2.84,462.78]],"ltp":2.84,"tv":4557.53,"id":9629022}],"tv":18036.73}]}
{"op":"mcm","clk":"4215029805","pt":1631533767512,"mc":[{"id":"1.187557985","rc":[{"trd":[[1.54,888.64]],"batb":[[0,1.54,35.75]],"ltp":1.54,"tv":13479.43,"id":5300820}],"tv":18036.97}]}
{"op":"mcm","clk":"4215029879","pt":1631533768295,"mc":[{"id":"1.187557985","rc":[{"batl":[[0,2.9,16.21],[1,2.92,3],[2,2.94,650.52]],"ltp":2.84,"tv":4557.53,"id":9629022}]}]}
{"op":"mcm","clk":"4215030494","pt":1631533776634,"mc":[{"id":"1.187557985","rc":[{"batb":[[0,1.44,190.96],[1,1.43,57.43],[2,1.38,65.96]],"batl":[[1,1.61,36.5],[2,1.62,39.75]],"ltp":1.54,"tv":13479.43,"id":5300820},{"batb":[[1,2.62,5.54],[2,2.6,8.54]],"batl":[[0,3.1,5.17],[1,3.35,3.9],[2,3.65,2.9]],"ltp":2.84,"tv":4557.53,"id":9629022}]}]}
{"op":"mcm","clk":"4215030555","pt":1631533777429,"mc":[{"id":"1.187557985","rc":[{"batl":[[0,1.64,36.18],[1,1.95,415.52],[2,44,7.23]],"ltp":1.54,"tv":13479.43,"id":5300820},{"batb":[[0,2.6,3],[1,2.58,3],[2,2.56,4.58]],"batl":[[0,3.35,3.9],[1,3.65,2.9],[2,3.75,2.98]],"ltp":2.84,"tv":4557.53,"id":9629022}]}]}
{"op":"mcm","clk":"4215030727","pt":1631533779620,"mc":[{"id":"1.187557985","rc":[{"batb":[[0,1.48,43.3],[1,1.45,292.52],[2,1.44,416.37]],"batl":[[1,1.66,230.05],[2,1.67,125.53]],"ltp":1.54,"tv":13479.43,"id":5300820},{"batb":[[1,2.56,4.58],[2,2.52,63.26]],"ltp":2.84,"tv":4557.53,"id":9629022}]}]}
{"op":"mcm","clk":"4215030808","pt":1631533780645,"mc":[{"id":"1.187557985","rc":[{"batb":[[0,1.44,190.96],[1,1.43,57.43],[2,1.38,65.96]],"batl":[[0,1.63,6],[1,1.64,36.18],[2,1.95,415.52]],"ltp":1.54,"tv":13479.43,"id":5300820},{"batl":[[0,3.3,3],[1,3.35,3.9],[2,3.65,2.9]],"ltp":2.84,"tv":4557.53,"id":9629022}]}]}
{"op":"mcm","clk":"4215031031","pt":1631533783429,"mc":[{"id":"1.187557985","rc":[{"batl":[[0,1.61,44.5],[1,1.62,5],[2,1.63,6]],"ltp":1.54,"tv":13479.43,"id":5300820},{"batb":[[0,2.62,8.04],[1,2.6,3],[2,2.58,4]],"ltp":2.84,"tv":4557.53,"id":9629022}]}]}
{"op":"mcm","clk":"4215031133","pt":1631533784625,"mc":[{"id":"1.187557985","rc":[{"batb":[[0,1.51,292.65],[1,1.5,189.77],[2,1.45,137.81]],"batl":[[0,1.56,260.16],[1,1.57,156.74],[2,1.61,6]],"ltp":1.54,"tv":13479.43,"id":5300820},{"batb":[[0,2.62,3]],"batl":[[0,3.25,15],[1,3.3,3],[2,3.35,3.9]],"ltp":2.84,"tv":4557.53,"id":9629022}]}]}
{"op":"mcm","clk":"4215031183","pt":1631533785347,"mc":[{"id":"1.187557985","rc":[{"batb":[[0,1.44,190.96],[1,1.43,57.43],[2,1.38,65.96]],"batl":[[0,1.61,6],[1,1.62,5],[2,1.63,6]],"ltp":1.54,"tv":13479.43,"id":5300820},{"batl":[[0,3.3,3],[1,3.35,3.9],[2,3.65,2.9]],"ltp":2.84,"tv":4557.53,"id":9629022}]}]}
{"op":"mcm","clk":"4215031406","pt":1631533788230,"mc":[{"id":"1.187557985","rc":[{"batb":[[0,1.45,292.52],[1,1.44,416.37],[2,1.43,57.43]],"ltp":1.54,"tv":13479.43,"id":5300820}]}]}
{"op":"mcm","clk":"4215031490","pt":1631533789322,"mc":[{"id":"1.187557985","rc":[{"batb":[[0,1.44,190.96],[1,1.43,57.43],[2,1.38,65.96]],"ltp":1.54,"tv":13479.43,"id":5300820}]}]}
{"op":"mcm","clk":"4215031543","pt":1631533790461,"mc":[{"id":"1.187557985","rc":[{"batl":[[0,1.61,51.5]],"ltp":1.54,"tv":13479.43,"id":5300820},{"batb":[[0,2.62,8.04]],"ltp":2.84,"tv":4557.53,"id":9629022}]}]}
{"op":"mcm","clk":"4215031622","pt":1631533791628,"mc":[{"id":"1.187557985","rc":[{"batl":[[0,1.61,6]],"ltp":1.54,"tv":13479.43,"id":5300820},{"batb":[[0,2.64,3],[1,2.62,3],[2,2.6,3]],"ltp":2.84,"tv":4557.53,"id":9629022}]}]}
{"op":"mcm","clk":"4215031707","pt":1631533792661,"mc":[{"id":"1.187557985","rc":[{"batb":[[0,1.61,157.5],[1,1.6,147],[2,1.44,190.96]],"batl":[[0,1.64,36.18],[1,1.66,230.05],[2,1.67,125.53]],"ltp":1.54,"tv":13479.43,"id":5300820},{"batb":[[0,2.56,4.58],[1,2.52,63.26],[2,2.46,777.44]],"batl":[[0,2.68,713.62],[1,2.7,692.64],[2,2.72,692.64]],"ltp":2.84,"tv":4557.53,"id":9629022}]}]}
{"op":"mcm","clk":"4215031756","pt":1631533793450,"mc":[{"id":"1.187557985","rc":[{"trd":[[1.61,71.64]],"batb":[[0,1.61,144.68],[2,1.58,131.13]],"batl":[[1,1.66,237.55]],"ltp":1.61,"tv":13505.07,"id":5300820},{"batb":[[1,2.52,82.99]],"ltp":2.84,"tv":4557.53,"id":9629022}],"tv":18062.61}]}
{"op":"mcm","clk":"4215031897","pt":1631533795371,"mc":[{"id":"1.187557985","rc":[{"batl":[[0,2.66,3],[1,2.68,713.62],[2,2.7,692.64]],"ltp":2.84,"tv":4557.53,"id":9629022}]}]}
{"op":"mcm","clk":"4215032179","pt":1631533799358,"mc":[{"id":"1.187557985","rc":[{"batb":[[2,2.46,783.45]],"ltp":2.84,"tv":4557.53,"id":9629022}]}]}
{"op":"mcm","clk":"4215032247","pt":1631533800571,"mc":[{"id":"1.187557985","rc":[{"trd":[[1.61,78.44]],"batb":[[0,1.61,141.28]],"ltp":1.61,"tv":13511.87,"id":5300820}],"tv":18069.41}]}
{"op":"mcm","clk":"4215032645","pt":1631533805653,"mc":[{"id":"1.187557985","rc":[{"batb":[[0,1.56,40.08],[1,1.54,286.65],[2,1.53,327.92]],"batl":[[0,1.66,7.5],[1,1.71,32.81],[2,1.73,274.37]],"ltp":1.61,"tv":13511.87,"id":5300820},{"batb":[[0,2.52,19.73],[1,2.4,9.41],[2,2.38,3]],"batl":[[0,2.76,5.65],[1,2.84,138.76],[2,2.86,189.62]],"ltp":2.84,"tv":4557.53,"id":9629022}]}]}
{"op":"mcm","clk":"4215032727","pt":1631533806636,"mc":[{"id":"1.187557985","rc":[{"batb":[[0,1.54,286.65],[1,1.53,327.92],[2,1.52,318.29]],"batl":[[0,1.71,32.81],[1,1.73,274.37],[2,1.74,256.81]],"ltp":1.61,"tv":13511.87,"id":5300820},{"batb":[[0,2.4,9.41],[1,2.36,167.89],[2,2.34,310.43]],"batl":[[0,2.84,138.76],[1,2.86,189.62],[2,2.88,224.66]],"ltp":2.84,"tv":4557.53,"id":9629022}]}]}
{"op":"mcm","clk":"4215032862","pt":1631533808365,"mc":[{"id":"1.187557985","rc":[{"batb":[[2,1.52,586.93]],"batl":[[2,1.74,403.13]],"ltp":1.61,"tv":13511.87,"id":5300820}]}]}
{"op":"mcm","clk":"4215032926","pt":1631533809164,"mc":[{"id":"1.187557985","rc":[{"batb":[[2,1.52,318.29]],"batl":[[2,1.74,256.81]],"ltp":1.61,"tv":13511.87,"id":5300820}]}]}
{"op":"mcm","clk":"4215032982","pt":1631533809888,"mc":[{"id":"1.187557985","rc":[{"batl":[[0,1.71,36.81]],"ltp":1.61,"tv":13511.87,"id":5300820},{"batb":[[1,2.38,4],[2,2.36,167.89]],"ltp":2.84,"tv":4557.53,"id":9629022}]}]}
{"op":"mcm","clk":"4215033162","pt":1631533812358,"mc":[{"id":"1.187557985","rc":[{"batb":[[0,1.59,188.06],[1,1.58,154.27],[2,1.54,286.65]],"batl":[[0,1.64,227.87],[1,1.65,130.98],[2,1.68,38.39]],"ltp":1.61,"tv":13511.87,"id":5300820},{"batb":[[0,2.46,8.88],[1,2.44,4],[2,2.4,9.41]],"ltp":2.84,"tv":4557.53,"id":9629022}]}]}
{"op":"mcm","clk":"4215033223","pt":1631533813352,"mc":[{"id":"1.187557985","rc":[{"batl":[[2,1.68,63.39]],"ltp":1.61,"tv":13511.87,"id":5300820},{"batb":[[2,2.42,3]],"ltp":2.84,"tv":4557.53,"id":9629022}]}]}
{"op":"mcm","clk":"4215033303","pt":1631533814489,"mc":[{"id":"1.187557985","rc":[{"batb":[[0,1.54,286.65],[1,1.53,327.92],[2,1.52,318.29]],"batl":[[0,1.68,38.39],[1,1.71,36.81],[2,1.73,274.37]],"ltp":1.61,"tv":13511.87,"id":5300820}]}]}
{"op":"mcm","clk":"4215033343","pt":1631533814867,"mc":[{"id":"1.187557985","rc":[{"batl":[[0,1.68,5]],"ltp":1.61,"tv":13511.87,"id":5300820},{"batb":[[0,2.46,3]],"ltp":2.84,"tv":4557.53,"id":9629022}]}]}
{"op":"mcm","clk":"4215033473","pt":1631533816569,"mc":[{"id":"1.187557985","rc":[{"batb":[[0,1.6,92.31],[1,1.54,286.65],[2,1.53,327.92]],"ltp":1.61,"tv":13511.87,"id":5300820}]}]}
{"op":"mcm","clk":"4215033531","pt":1631533817395,"mc":[{"id":"1.187557985","rc":[{"batb":[[0,1.54,286.65],[1,1.53,327.92],[2,1.52,586.93]],"ltp":1.61,"tv":13511.87,"id":5300820}]}]}
{"op":"mcm","clk":"4215033702","pt":1631533819598,"mc":[{"id":"1.187557985","rc":[{"batb":[[0,1.5,160.5],[1,1.45,56.61],[2,1.38,454.63]],"ltp":1.61,"tv":13511.87,"id":5300820},{"batl":[[0,3.25,6.66],[1,2.86,0],[2,2.88,0]],"ltp":2.84,"tv":4557.53,"id":9629022}]}]}
{"op":"mcm","clk":"4215033730","pt":1631533819968,"mc":[{"id":"1.187557985","rc":[{"batb":[[2,1.25,237.69]],"ltp":1.61,"tv":13511.87,"id":5300820}]}]}
{"op":"mcm","clk":"4215033925","pt":1631533822601,"mc":[{"id":"1.187557985","rc":[{"batb":[[0,1.69,151.59],[1,1.67,249.97],[2,1.66,1152.12]],"batl":[[0,1.71,32.81],[1,1.73,274.37],[2,1.74,403.13]],"ltp":1.61,"tv":13511.87,"id":5300820},{"batb":[[0,2.4,6.41],[1,2.36,167.89],[2,2.34,310.43]],"batl":[[0,2.96,6.76],[1,3.25,6.66]],"ltp":2.84,"tv":4557.53,"id":9629022}]}]}
{"op":"mcm","clk":"4215033998","pt":1631533823381,"mc":[{"id":"1.187557985","rc":[{"trd":[[1.69,65.96]],"batb":[[0,1.69,139.24],[2,1.66,1262.24]],"ltp":1.69,"tv":13536.57,"id":5300820},{"batl":[[0,2.54,6.04],[1,2.96,6.76],[2,3.25,6.66]],"ltp":2.84,"tv":4557.53,"id":9629022}],"tv":18094.11}]}
{"op":"mcm","clk":"4215034125","pt":1631533825304,"mc":[{"id":"1.187557985","rc":[{"batb":[[1,1.68,5],[2,1.67,253.97]],"ltp":1.69,"tv":13536.57,"id":5300820},{"batl":[[0,2.46,4],[1,2.5,4],[2,2.54,6.04]],"ltp":2.84,"tv":4557.53,"id":9629022}]}]}
{"op":"mcm","clk":"4215034201","pt":1631533826508,"mc":[{"id":"1.187557985","rc":[{"batl":[[2,2.96,6.76]],"ltp":2.84,"tv":4557.53,"id":9629022}]}]}
{"op":"mcm","clk":"4215034265","pt":1631533827607,"mc":[{"id":"1.187557985","rc":[{"batb":[[0,1.7,139.15],[1,1.69,139.24],[2,1.68,5]],"ltp":1.69,"tv":13536.57,"id":5300820}]}]}
{"op":"mcm","clk":"4215034332","pt":1631533828495,"mc":[{"id":"1.187557985","rc":[{"batb":[[0,1.7,32.24]],"ltp":1.69,"tv":13536.57,"id":5300820},{"batl":[[0,2.44,20],[1,2.46,4],[2,2.5,4]],"ltp":2.84,"tv":4557.53,"id":9629022}]}]}
{"op":"mcm","clk":"4215034391","pt":1631533829305,"mc":[{"id":"1.187557985","rc":[{"batl":[[2,1.74,441.38]],"ltp":1.69,"tv":13536.57,"id":5300820},{"batb":[[2,2.34,316.65]],"ltp":2.84,"tv":4557.53,"id":9629022}]}]}
{"op":"mcm","clk":"4215034571","pt":1631533831522,"mc":[{"id":"1.187557985","rc":[{"trd":[[1.7,55.07]],"batb":[[0,1.7,30.44]],"ltp":1.7,"tv":13540.17,"id":5300820},{"trd":[[2.44,5.44]],"batl":[[0,2.44,18.78]],"ltp":2.44,"tv":4559.98,"id":9629022}],"tv":18100.15}]}
{"op":"mcm","clk":"4215035008","pt":1631533838256,"mc":[{"id":"1.187557985","rc":[{"trd":[[1.7,62.81]],"batb":[[0,1.7,26.57]],"ltp":1.7,"tv":13547.9,"id":5300820},{"batl":[[2,2.52,6.08]],"ltp":2.44,"tv":4559.98,"id":9629022}],"tv":18107.89}]}
{"op":"mcm","clk":"4215035207","pt":1631533841609,"mc":[{"id":"1.187557985","rc":[{"batb":[[0,1.66,36.92],[1,1.63,237.61],[2,1.62,352.72]],"batl":[[0,1.76,37.02],[1,1.78,35.25],[2,1.8,275.26]],"ltp":1.7,"tv":13547.9,"id":5300820},{"batb":[[0,2.3,29.85],[1,2.28,7.66],[2,2.24,158.23]],"batl":[[0,2.52,6.08],[1,2.6,162.39],[2,2.62,177.73]],"ltp":2.44,"tv":4559.98,"id":9629022}]}]}
{"op":"mcm","clk":"4215035246","pt":1631533842436,"mc":[{"id":"1.187557985","rc":[{"batb":[[0,1.63,237.61],[1,1.62,352.72],[2,1.61,294.15]],"batl":[[0,1.78,35.25],[1,1.8,275.26],[2,1.81,244.97]],"ltp":1.7,"tv":13547.9,"id":5300820},{"batb":[[0,2.28,7.66],[1,2.24,158.23],[2,2.22,302.49]],"batl":[[0,2.6,162.39],[1,2.62,177.73],[2,2.64,187.23]],"ltp":2.44,"tv":4559.98,"id":9629022}]}]}
{"op":"mcm","clk":"4215035281","pt":1631533843222,"mc":[{"id":"1.187557985","rc":[{"batb":[[0,1.73,20.67],[1,1.63,237.61],[2,1.62,352.72]],"ltp":1.7,"tv":13547.9,"id":5300820}]}]}
{"op":"mcm","clk":"4215035350","pt":1631533844625,"mc":[{"id":"1.187557985","rc":[{"batl":[[0,1.75,5],[1,1.78,35.25],[2,1.8,275.26]],"ltp":1.7,"tv":13547.9,"id":5300820},{"batb":[[0,2.32,4],[1,2.3,3],[2,2.28,7.66]],"ltp":2.44,"tv":4559.98,"id":9629022}]}]}
{"op":"mcm","clk":"4215035412","pt":1631533845630,"mc":[{"id":"1.187557985","rc":[{"batl":[[1,1.76,5],[2,1.77,5]],"ltp":1.7,"tv":13547.9,"id":5300820},{"batb":[[2,2.28,11.66]],"ltp":2.44,"tv":4559.98,"id":9629022}]}]}
{"op":"mcm","clk":"4215035461","pt":1631533846516,"mc":[{"id":"1.187557985","rc":[{"trd":[[1.73,152.49]],"batb":[[0,1.73,18.86]],"ltp":1.73,"tv":13551.52,"id":5300820}],"tv":18111.5}]}
{"op":"mcm","clk":"4215035578","pt":1631533848433,"mc":[{"id":"1.187557985","rc":[{"trd":[[1.73,190.21]],"batb":[[0,1.67,192.61],[1,1.66,128.61],[2,1.63,237.61]],"batl":[[0,1.72,127.11],[1,1.74,220],[2,1.75,35.1]],"ltp":1.73,"tv":13589.24,"id":5300820},{"batb":[[0,2.32,11.14]],"ltp":2.44,"tv":4559.98,"id":9629022}],"tv":18149.23}]}
{"op":"mcm","clk":"4215035655","pt":1631533849638,"mc":[{"id":"1.187557985","rc":[{"batl":[[2,1.75,163.1]],"ltp":1.73,"tv":13589.24,"id":5300820}]}]}
{"op":"mcm","clk":"4215035725","pt":1631533850629,"mc":[{"id":"1.187557985","rc":[{"batb":[[0,1.63,237.61],[1,1.62,352.72],[2,1.61,294.15]],"batl":[[0,1.75,5],[1,1.76,5],[2,1.77,5]],"ltp":1.73,"tv":13589.24,"id":5300820},{"batb":[[0,2.32,4]],"ltp":2.44,"tv":4559.98,"id":9629022}]}]}
{"op":"mcm","clk":"4215035906","pt":1631533853444,"mc":[{"id":"1.187557985","rc":[{"batb":[[2,1.61,466.96]],"ltp":1.73,"tv":13589.24,"id":5300820}]}]}
{"op":"mcm","clk":"4215036030","pt":1631533855249,"mc":[{"id":"1.187557985","rc":[{"batb":[[0,1.58,131.29],[1,1.54,43.62],[2,1.53,45.33]],"ltp":1.73,"tv":13589.24,"id":5300820},{"batl":[[0,2.86,4.75],[1,2.9,4.55],[2,3.25,3.66]],"ltp":2.44,"tv":4559.98,"id":9629022}]}]}
{"op":"mcm","clk":"4215036164","pt":1631533857647,"mc":[{"id":"1.187557985","rc":[{"batb":[[0,1.74,2198.28],[1,1.73,2133.62],[2,1.72,2133.62]],"batl":[[0,1.75,31.14],[1,1.78,35.25],[2,1.8,275.26]],"ltp":1.73,"tv":13589.24,"id":5300820},{"batb":[[0,2.32,6.64],[1,2.28,7.66],[2,2.24,154.23]],"batl":[[0,2.82,7.09],[1,2.86,4.75],[2,2.9,4.55]],"ltp":2.44,"tv":4559.98,"id":9629022}]}]}
{"op":"mcm","clk":"4215036228","pt":1631533858652,"mc":[{"id":"1.187557985","rc":[{"trd":[[1.76,224.1]],"batb":[[0,1.76,157.02],[1,1.74,1315.88],[2,1.73,1162.8]],"batl":[[0,1.78,35.25],[1,1.8,275.26],[2,1.81,244.97]],"ltp":1.76,"tv":13613.34,"id":5300820},{"batb":[[0,2.28,7.66],[1,2.24,154.23],[2,2.22,299.49]],"ltp":2.44,"tv":4559.98,"id":9629022}],"tv":18173.33}]}
{"op":"mcm","clk":"4215036269","pt":1631533859425,"mc":[{"id":"1.187557985","rc":[{"batb":[[1,1.74,1350.75]],"ltp":1.76,"tv":13613.34,"id":5300820},{"batl":[[0,2.36,6.43],[1,2.54,23.75],[2,2.82,7.09]],"ltp":2.44,"tv":4559.98,"id":9629022}]}]}
{"op":"mcm","clk":"4215036324","pt":1631533860531,"mc":[{"id":"1.187557985","rc":[{"batb":[[1,1.75,5],[2,1.74,1355.75]],"ltp":1.76,"tv":13613.34,"id":5300820},{"batl":[[0,2.32,3],[1,2.36,6.43],[2,2.72,4]],"ltp":2.44,"tv":4559.98,"id":9629022}]}]}
{"op":"mcm","clk":"4215036350","pt":1631533860950,"mc":[{"id":"1.187557985","rc":[{"batl":[[1,2.34,3],[2,2.36,6.43]],"ltp":2.44,"tv":4559.98,"id":9629022}]}]}
{"op":"mcm","clk":"4215036463","pt":1631533862619,"mc":[{"id":"1.187557985","rc":[{"trd":[[1.76,227.64]],"batb":[[0,1.76,155.25]],"batl":[[0,1.78,101.24]],"ltp":1.76,"tv":13616.88,"id":5300820},{"trd":[[2.32,81.62]],"batl":[[0,2.32,1.68],[2,2.38,27.99]],"ltp":2.32,"tv":4562.62,"id":9629022}],"tv":18179.51}]}
{"op":"mcm","clk":"4215036531","pt":1631533863527,"mc":[{"id":"1.187557985","rc":[{"batb":[[0,1.77,34.98],[1,1.76,155.25],[2,1.75,5]],"batl":[[0,1.78,35.25]],"ltp":1.76,"tv":13616.88,"id":5300820},{"batl":[[2,2.72,4]],"ltp":2.32,"tv":4562.62,"id":9629022}]}]}
{"op":"mcm","clk":"4215036639","pt":1631533865139,"mc":[{"id":"1.187557985","rc":[{"batl":[[1,1.79,35.5],[2,1.8,307.78]],"ltp":1.76,"tv":13616.88,"id":5300820},{"trd":[[2.28,8]],"batb":[[0,2.28,3.66],[1,2.26,6.98],[2,2.24,161]],"batl":[[0,2.32,8.2],[2,2.42,169.22]],"ltp":2.28,"tv":4570.62,"id":9629022}],"tv":18187.51}]}
{"op":"mcm","clk":"4215036733","pt":1631533866549,"mc":[{"id":"1.187557985","rc":[{"batb":[[2,1.75,39.64]],"ltp":1.76,"tv":13616.88,"id":5300820},{"batl":[[0,2.3,32.15],[1,2.32,8.2],[2,2.34,3]],"ltp":2.28,"tv":4570.62,"id":9629022}]}]}
{"op":"mcm","clk":"4215036845","pt":1631533868364,"mc":[{"id":"1.187557985","rc":[{"batb":[[0,1.75,34.64],[1,1.71,239.28],[2,1.7,248.96]],"batl":[[0,1.82,142.54],[1,1.84,230.64],[2,1.85,264.11]],"ltp":1.76,"tv":13616.88,"id":5300820},{"batb":[[0,2.2,7.67],[1,2.18,175.56],[2,2.16,221.81]],"batl":[[0,2.32,6.52],[1,2.42,169.22],[2,2.44,219.34]],"ltp":2.28,"tv":4570.62,"id":9629022}]}]}
{"op":"mcm","clk":"4215036906","pt":1631533869459,"mc":[{"id":"1.187557985","rc":[{"batb":[[0,1.71,239.28],[1,1.7,248.96],[2,1.69,374.11]],"ltp":1.76,"tv":13616.88,"id":5300820},{"batl":[[0,2.42,169.22],[1,2.44,219.34],[2,2.46,216.51]],"ltp":2.28,"tv":4570.62,"id":9629022}]}]}
{"op":"mcm","clk":"4215036977","pt":1631533870446,"mc":[{"id":"1.187557985","rc":[{"batl":[[0,2.28,250.43],[1,2.42,169.22],[2,2.44,219.34]],"ltp":2.28,"tv":4570.62,"id":9629022}]}]}
{"op":"mcm","clk":"4215037042","pt":1631533871536,"mc":[{"id":"1.187557985","rc":[{"batb":[[1,1.7,417.5]],"batl":[[0,1.8,30.67],[1,1.81,5],[2,1.82,146.54]],"ltp":1.76,"tv":13616.88,"id":5300820},{"batb":[[0,2.24,7.02],[1,2.2,10.67],[2,2.18,179.56]],"ltp":2.28,"tv":4570.62,"id":9629022}]}]}
{"op":"mcm","clk":"4215037157","pt":1631533872369,"mc":[{"id":"1.187557985","rc":[{"batl":[[0,1.81,5],[1,1.82,146.54],[2,1.84,230.64]],"ltp":1.76,"tv":13616.88,"id":5300820},{"batb":[[0,2.2,10.67],[1,2.18,179.56],[2,2.16,221.81]],"ltp":2.28,"tv":4570.62,"id":9629022}]}]}
{"op":"mcm","clk":"4215037249","pt":1631533873261,"mc":[{"id":"1.187557985","rc":[{"batb":[[1,1.7,248.96]],"ltp":1.76,"tv":13616.88,"id":5300820}]}]}
{"op":"mcm","clk":"4215037386","pt":1631533875353,"mc":[{"id":"1.187557985","rc":[{"batb":[[0,2.22,3],[1,2.2,10.67],[2,2.18,179.56]],"ltp":2.28,"tv":4570.62,"id":9629022}]}]}
{"op":"mcm","clk":"4215037452","pt":1631533876175,"mc":[{"id":"1.187557985","rc":[{"batb":[[0,1.75,141.58],[1,1.73,221],[2,1.71,239.28]],"batl":[[0,1.81,203.87],[2,1.83,186.26]],"ltp":1.76,"tv":13616.88,"id":5300820},{"trd":[[2.28,45.82]],"batl":[[0,2.28,231.52]],"ltp":2.28,"tv":4608.44,"id":9629022}],"tv":18225.33}]}
{"op":"mcm","clk":"4215037578","pt":1631533878164,"mc":[{"id":"1.187557985","rc":[{"batb":[[0,1.71,239.28],[1,1.7,248.96],[2,1.69,374.11]],"batl":[[0,1.81,5],[2,1.84,230.64]],"ltp":1.76,"tv":13616.88,"id":5300820}]}]}
{"op":"mcm","clk":"4215037761","pt":1631533881169,"mc":[{"id":"1.187557985","rc":[{"batb":[[1,1.7,417.5]],"ltp":1.76,"tv":13616.88,"id":5300820}]}]}
{"op":"mcm","clk":"4215037844","pt":1631533882630,"mc":[{"id":"1.187557985","rc":[{"batb":[[0,1.67,108.53],[1,1.65,36.73],[2,1.59,6]],"batl":[[0,1.82,142.54],[1,1.84,230.64],[2,1.85,264.11]],"ltp":1.76,"tv":13616.88,"id":5300820},{"batb":[[0,2.2,7.67],[1,2.18,175.56],[2,2.16,221.81]],"batl":[[1,2.54,5.75],[2,2.72,4]],"ltp":2.28,"tv":4608.44,"id":9629022}]}]}
{"op":"mcm","clk":"4215038034","pt":1631533885546,"mc":[{"id":"1.187557985","rc":[{"batb":[[0,1.81,193.89],[1,1.79,197.06],[2,1.67,108.53]],"batl":[[0,1.82,29.25]],"ltp":1.76,"tv":13616.88,"id":5300820},{"batl":[[0,2.26,846.24],[1,2.28,1052.86],[2,2.3,821.34]],"ltp":2.28,"tv":4608.44,"id":9629022}]}]}
{"op":"mcm","clk":"4215038114","pt":1631533886642,"mc":[{"id":"1.187557985","rc":[{"trd":[[1.81,23.66]],"batb":[[0,1.81,182.06],[1,1.79,283.25],[2,1.69,104.6]],"ltp":1.81,"tv":13640.54,"id":5300820},{"batl":[[0,2.22,6.79],[1,2.26,846.24],[2,2.28,1052.86]],"ltp":2.28,"tv":4608.44,"id":9629022}],"tv":18248.99}]}
{"op":"mcm","clk":"4215038176","pt":1631533887630,"mc":[{"id":"1.187557985","rc":[{"batb":[[1,1.79,288.25],[2,1.78,4]],"ltp":1.81,"tv":13640.54,"id":5300820},{"batl":[[1,2.26,849.24]],"ltp":2.28,"tv":4608.44,"id":9629022}]}]}
{"op":"mcm","clk":"4215038251","pt":1631533888621,"mc":[{"id":"1.187557985","rc":[{"batb":[[1,1.8,5],[2,1.79,288.25]],"batl":[[1,1.83,113.29],[2,1.84,230.64]],"ltp":1.81,"tv":13640.54,"id":5300820},{"batl":[[1,2.24,3],[2,2.26,849.24]],"ltp":2.28,"tv":4608.44,"id":9629022}]}]}
{"op":"mcm","clk":"4215038340","pt":1631533889614,"mc":[{"id":"1.187557985","rc":[{"trd":[[1.82,58.18]],"batl":[[0,1.83,113.45],[1,1.84,230.64],[2,1.85,264.11]],"ltp":1.82,"tv":13698.72,"id":5300820}],"tv":18307.17}]}
{"op":"mcm","clk":"4215038387","pt":1631533890294,"mc":[{"id":"1.187557985","rc":[{"trd":[[1.82,142.08]],"batb":[[0,1.82,30.01],[1,1.81,182.06],[2,1.8,5]],"batl":[[0,1.83,113.29]],"ltp":1.82,"tv":13782.62,"id":5300820},{"trd":[[2.2,52.09]],"batb":[[0,2.18,175.56],[1,2.16,221.81],[2,2.14,383.09]],"batl":[[0,2.24,3],[1,2.26,849.24],[2,2.28,1052.86]],"ltp":2.2,"tv":4660.53,"id":9629022}],"tv":18443.16}]}
{"op":"mcm","clk":"4215038603","pt":1631533893424,"mc":[{"id":"1.187557985","rc":[{"batl":[[2,2.28,821.34]],"ltp":2.2,"tv":4660.53,"id":9629022}]}]}
{"op":"mcm","clk":"4215038780","pt":1631533896650,"mc":[{"id":"1.187557985","rc":[{"batb":[[1,1.81,215.39]],"batl":[[1,1.86,347.63],[2,1.88,180.47]],"ltp":1.82,"tv":13782.62,"id":5300820},{"batb":[[0,2.16,221.81],[1,2.14,383.09],[2,2.1,500.89]],"batl":[[0,2.22,231.52],[1,2.24,9.73],[2,2.26,849.24]],"ltp":2.2,"tv":4660.53,"id":9629022}]}]}
{"op":"mcm","clk":"4215038993","pt":1631533899623,"mc":[{"id":"1.187557985","rc":[{"trd":[[1.82,202.1]],"batb":[[0,1.81,215.39],[1,1.8,5],[2,1.79,288.25]],"batl":[[0,1.82,19.99],[1,1.83,113.29],[2,1.86,347.63]],"ltp":1.82,"tv":13842.64,"id":5300820}],"tv":18503.18}]}
{"op":"mcm","clk":"4215039044","pt":1631533900430,"mc":[{"id":"1.187557985","rc":[{"batb":[[2,1.79,283.25]],"ltp":1.82,"tv":13842.64,"id":5300820},{"batl":[[2,2.26,846.24]],"ltp":2.2,"tv":4660.53,"id":9629022}]}]}
{"op":"mcm","clk":"4215039081","pt":1631533901055,"mc":[{"id":"1.187557985","rc":[{"trd":[[2.22,5.09]],"batl":[[0,2.22,228.97]],"ltp":2.22,"tv":4665.62,"id":9629022}],"tv":18508.27}]}
{"op":"mcm","clk":"4215039292","pt":1631533904130,"mc":[{"id":"1.187557985","rc":[{"trd":[[1.82,242.08]],"batl":[[0,1.83,113.29],[1,1.86,347.63],[2,1.88,180.47]],"ltp":1.82,"tv":13882.62,"id":5300820}],"tv":18548.25}]}
{"op":"mcm","clk":"4215039385","pt":1631533905649,"mc":[{"id":"1.187557985","rc":[{"batb":[[0,1.81,182.06]],"ltp":1.82,"tv":13882.62,"id":5300820},{"batl":[[0,2.24,3],[1,2.26,846.24],[2,2.28,821.34]],"ltp":2.22,"tv":4665.62,"id":9629022}]}]}
{"op":"mcm","clk":"4215039488","pt":1631533907362,"mc":[{"id":"1.187557985","rc":[{"trd":[[1.81,27.66]],"batb":[[0,1.81,180.06]],"ltp":1.81,"tv":13886.63,"id":5300820},{"batb":[[1,2.14,382.75]],"ltp":2.22,"tv":4665.62,"id":9629022}],"tv":18552.26}]}
{"op":"mcm","clk":"4215039563","pt":1631533908356,"mc":[{"id":"1.187557985","rc":[{"trd":[[1.83,45.86]],"batb":[[0,1.81,211.94]],"batl":[[0,1.83,90.36]],"ltp":1.83,"tv":13932.49,"id":5300820}],"tv":18598.12}]}
{"op":"mcm","clk":"4215039612","pt":1631533909032,"mc":[{"id":"1.187557985","rc":[{"trd":[[1.83,136.22]],"batl":[[0,1.88,180.47],[1,1.9,165.48],[2,1.99,231.42]],"ltp":1.83,"tv":14022.85,"id":5300820},{"trd":[[2.2,127.25]],"batl":[[0,2.2,153.81],[1,2.24,3],[2,2.26,846.24]],"ltp":2.2,"tv":4740.79,"id":9629022}],"tv":18763.64}]}
{"op":"mcm","clk":"4215039690","pt":1631533910649,"mc":[{"id":"1.187557985","rc":[{"batl":[[1,2.24,18]],"ltp":2.2,"tv":4740.79,"id":9629022}]}]}
{"op":"mcm","clk":"4215039746","pt":1631533911584,"mc":[{"id":"1.187557985","rc":[{"trd":[[1.83,141.22]],"ltp":1.83,"tv":14027.85,"id":5300820},{"trd":[[2.2,131.41]],"batl":[[0,2.2,149.65]],"ltp":2.2,"tv":4744.94,"id":9629022}],"tv":18772.79}]}
{"op":"mcm","clk":"4215039784","pt":1631533911955,"mc":[{"id":"1.187557985","rc":[{"batl":[[2,1.93,7.5]],"ltp":1.83,"tv":14027.85,"id":5300820}]}]}
{"op":"mcm","clk":"4215040523","pt":1631533923291,"mc":[{"id":"1.187557985","rc":[{"trd":[[1.83,143.22]],"ltp":1.83,"tv":14029.85,"id":5300820},{"trd":[[2.2,133.07]],"batl":[[0,2.2,147.99]],"ltp":2.2,"tv":4746.6,"id":9629022}],"tv":18776.45}]}
{"op":"mcm","clk":"4215042154","pt":1631533946124,"mc":[{"id":"1.187557985","rc":[{"trd":[[1.83,143.49]],"ltp":1.83,"tv":14030.12,"id":5300820},{"trd":[[2.2,133.29]],"batl":[[0,2.2,147.77]],"ltp":2.2,"tv":4746.82,"id":9629022}],"tv":18776.95}]}
{"op":"mcm","clk":"4215043787","pt":1631533971168,"mc":[{"id":"1.187557985","rc":[{"batb":[[0,1.81,212.8]],"ltp":1.83,"tv":14030.12,"id":5300820}]}]}
{"op":"mcm","clk":"4215044092","pt":1631533975643,"mc":[{"id":"1.187557985","rc":[{"batl":[[0,2.24,18],[1,2.26,846.24],[2,2.28,821.34]],"ltp":2.2,"tv":4746.82,"id":9629022}]}]}
{"op":"mcm","clk":"4215044269","pt":1631533978757,"mc":[{"id":"1.187557985","rc":[{"trd":[[2.16,295.54]],"batb":[[0,2.16,74.05]],"ltp":2.16,"tv":5042.36,"id":9629022}],"tv":19072.48}]}
{"op":"mcm","clk":"4215044373","pt":1631533980576,"mc":[{"id":"1.187557985","rc":[{"trd":[[1.87,39]],"ltp":1.87,"tv":14069.12,"id":5300820},{"trd":[[2.16,329.3]],"batb":[[0,2.16,40.28]],"ltp":2.16,"tv":5076.13,"id":9629022}],"tv":19145.25}]}
{"op":"mcm","clk":"4215044476","pt":1631533981882,"mc":[{"id":"1.187557985","rc":[{"batb":[[0,1.81,180.92]],"ltp":1.87,"tv":14069.12,"id":5300820},{"batl":[[0,2.24,3]],"ltp":2.16,"tv":5076.13,"id":9629022}]}]}
{"op":"mcm","clk":"4215045324","pt":1631533995586,"mc":[{"id":"1.187557985","rc":[{"batl":[[0,1.86,3.84],[1,1.88,180.47],[2,1.9,165.48]],"ltp":1.87,"tv":14069.12,"id":5300820}]}]}
{"op":"mcm","clk":"4215045597","pt":1631534000086,"mc":[{"id":"1.187557985","rc":[{"batb":[[0,1.81,210.69]],"ltp":1.87,"tv":14069.12,"id":5300820},{"batl":[[0,2.24,18]],"ltp":2.16,"tv":5076.13,"id":9629022}]}]}
{"op":"mcm","clk":"4215046106","pt":1631534007516,"mc":[{"id":"1.187557985","rc":[{"batb":[[0,1.77,35.04],[1,1.72,263.33],[2,1.71,357.28]],"batl":[[1,1.93,7.5],[2,1.99,231.42]],"ltp":1.87,"tv":14069.12,"id":5300820},{"batb":[[0,2.08,27.77],[1,2,203.15],[2,1.99,259.62]],"batl":[[0,2.3,6.57],[1,2.4,173.35],[2,2.42,236.95]],"ltp":2.16,"tv":5076.13,"id":9629022}]}]}
{"op":"mcm","clk":"4215046176","pt":1631534008487,"mc":[{"id":"1.187557985","rc":[{"batb":[[0,1.72,264.19],[1,1.71,357.28],[2,1.7,385.32]],"batl":[[1,1.99,231.42],[2,2,232.66]],"ltp":1.87,"tv":14069.12,"id":5300820},{"batb":[[0,2,203.15],[1,1.99,259.62],[2,1.98,378.03]],"batl":[[0,2.4,173.35],[1,2.42,236.95],[2,2.44,187.86]],"ltp":2.16,"tv":5076.13,"id":9629022}]}]}
{"op":"mcm","clk":"4215046318","pt":1631534010426,"mc":[{"id":"1.187557985","rc":[{"batb":[[1,1.71,555.8]],"ltp":1.87,"tv":14069.12,"id":5300820}]}]}
{"op":"mcm","clk":"4215046421","pt":1631534012016,"mc":[{"id":"1.187557985","rc":[{"batl":[[0,1.86,4.8]],"ltp":1.87,"tv":14069.12,"id":5300820}]}]}
{"op":"mcm","clk":"4215046797","pt":1631534017043,"mc":[{"id":"1.187557985","rc":[{"batl":[[0,1.86,3.84]],"ltp":1.87,"tv":14069.12,"id":5300820}]}]}
{"op":"mcm","clk":"4215046971","pt":1631534019552,"mc":[{"id":"1.187557985","rc":[{"batb":[[0,1.71,35.05],[1,1.69,104.6],[2,1.64,40.07]],"ltp":1.87,"tv":14069.12,"id":5300820},{"batl":[[0,2.42,6.75],[1,2.58,5.25],[2,2.44,0]],"ltp":2.16,"tv":5076.13,"id":9629022}]}]}
{"op":"mcm","clk":"4215047018","pt":1631534020229,"mc":[{"id":"1.187557985","rc":[{"batb":[[0,1.69,104.6],[1,1.64,40.07],[2,1.3,198.07]],"ltp":1.87,"tv":14069.12,"id":5300820},{"batl":[[0,2.58,5.25],[1,2.58,0]],"ltp":2.16,"tv":5076.13,"id":9629022}]}]}
{"op":"mcm","clk":"4215047107","pt":1631534021334,"mc":[{"id":"1.187557985","rc":[{"trd":[[1.86,7.68]],"batl":[[0,2,232.66],[1,2.02,312.17],[2,2.04,184.34]],"ltp":1.86,"tv":14076.8,"id":5300820}],"tv":19152.93}]}
{"op":"mcm","clk":"4215047212","pt":1631534022642,"mc":[{"id":"1.187557985","rc":[{"batb":[[0,1.96,138.54],[1,1.94,152.05],[2,1.93,990.94]],"ltp":1.86,"tv":14076.8,"id":5300820},{"batl":[[0,2.54,7.87],[1,2.58,5.25]],"ltp":2.16,"tv":5076.13,"id":9629022}]}]}
{"op":"mcm","clk":"4215047295","pt":1631534023635,"mc":[{"id":"1.187557985","rc":[{"trd":[[1.96,22.48]],"batb":[[0,1.96,127.3]],"ltp":1.96,"tv":14099.28,"id":5300820},{"batl":[[0,2.14,7.02],[1,2.54,7.87],[2,2.58,5.25]],"ltp":2.16,"tv":5076.13,"id":9629022}],"tv":19175.41}]}
{"op":"mcm","clk":"4215047448","pt":1631534025565,"mc":[{"id":"1.187557985","rc":[{"batb":[[1,1.94,156.05],[2,1.93,994.94]],"ltp":1.96,"tv":14099.28,"id":5300820},{"batl":[[0,2.06,4],[1,2.14,7.02],[2,2.54,7.87]],"ltp":2.16,"tv":5076.13,"id":9629022}]}]}
{"op":"mcm","clk":"4215047535","pt":1631534026621,"mc":[{"id":"1.187557985","rc":[{"batl":[[0,2,207.47]],"ltp":1.96,"tv":14099.28,"id":5300820}]}]}
{"op":"mcm","clk":"4215047593","pt":1631534027457,"mc":[{"id":"1.187557985","rc":[{"trd":[[1.96,100.27]],"batb":[[0,1.96,88.41]],"ltp":1.96,"tv":14177.07,"id":5300820},{"trd":[[2.06,6.94]],"batl":[[0,2.14,7.55],[1,2.54,7.87],[2,2.58,5.25]],"ltp":2.06,"tv":5083.06,"id":9629022}],"tv":19260.13}]}
{"op":"mcm","clk":"4215047760","pt":1631534029449,"mc":[{"id":"1.187557985","rc":[{"batl":[[1,2.18,196.19],[2,2.2,236.38]],"ltp":2.06,"tv":5083.06,"id":9629022}]}]}
{"op":"mcm","clk":"4215047839","pt":1631534030649,"mc":[{"id":"1.187557985","rc":[{"batb":[[0,1.96,110]],"batl":[[2,2.04,211.77]],"ltp":1.96,"tv":14177.07,"id":5300820}]}]}
{"op":"mcm","clk":"4215048222","pt":1631534035560,"mc":[{"id":"1.187557985","rc":[{"batl":[[0,2.1,38.28],[1,2.14,7.02],[2,2.18,196.19]],"ltp":2.06,"tv":5083.06,"id":9629022}]}]}
{"op":"mcm","clk":"4215048238","pt":1631534035768,"mc":[{"id":"1.187557985","rc":[{"batl":[[0,2.14,7.55],[1,2.18,196.19],[2,2.2,236.38]],"ltp":2.06,"tv":5083.06,"id":9629022}]}]}
{"op":"mcm","clk":"4215048377","pt":1631534037649,"mc":[{"id":"1.187557985","rc":[{"batb":[[1,1.94,152.05],[2,1.92,69.04]],"batl":[[0,2.04,211.77],[1,2.06,129.63],[2,2.08,7.21]],"ltp":1.96,"tv":14177.07,"id":5300820},{"batb":[[0,1.98,127.19],[1,1.93,31.1],[2,1.85,31.77]],"batl":[[0,2.14,7.02]],"ltp":2.06,"tv":5083.06,"id":9629022}]}]}
{"op":"mcm","clk":"4215048449","pt":1631534038646,"mc":[{"id":"1.187557985","rc":[{"batb":[[0,1.84,281.35],[1,1.83,270.58],[2,1.82,343.07]],"batl":[[0,2.2,163.25],[1,2.22,265.63],[2,2.24,270.1]],"ltp":1.96,"tv":14177.07,"id":5300820},{"batb":[[0,1.83,300.89],[1,1.82,295.95],[2,1.81,368.11]],"batl":[[0,2.18,196.19],[1,2.2,236.38],[2,2.22,247.49]],"ltp":2.06,"tv":5083.06,"id":9629022}]}]}
{"op":"mcm","clk":"4215048576","pt":1631534040575,"mc":[{"id":"1.187557985","rc":[{"batb":[[2,1.82,547.3]],"batl":[[2,2.24,440.02]],"ltp":1.96,"tv":14177.07,"id":5300820}]}]}
{"op":"mcm","clk":"4215048695","pt":1631534042053,"mc":[{"id":"1.187557985","rc":[{"batb":[[2,1.82,343.07]],"batl":[[0,2.2,166.25],[2,2.24,270.1]],"ltp":1.96,"tv":14177.07,"id":5300820},{"batb":[[0,1.83,305.89],[1,1.82,300.95]],"ltp":2.06,"tv":5083.06,"id":9629022}]}]}
{"op":"mcm","clk":"4215048891","pt":1631534044570,"mc":[{"id":"1.187557985","rc":[{"batl":[[0,2.02,20.25],[1,2.2,166.25],[2,2.22,265.63]],"ltp":1.96,"tv":14177.07,"id":5300820},{"batb":[[0,1.98,19.76],[1,1.83,305.89],[2,1.82,300.95]],"batl":[[0,2.04,21.38],[1,2.18,196.19],[2,2.2,236.38]],"ltp":2.06,"tv":5083.06,"id":9629022}]}]}
{"op":"mcm","clk":"4215048959","pt":1631534045462,"mc":[{"id":"1.187557985","rc":[{"batl":[[0,2.18,6.25]],"ltp":1.96,"tv":14177.07,"id":5300820},{"batb":[[0,1.85,33.77]],"batl":[[0,2.18,196.19],[1,2.2,236.38],[2,2.22,247.49]],"ltp":2.06,"tv":5083.06,"id":9629022}]}]}
{"op":"mcm","clk":"4215049048","pt":1631534046563,"mc":[{"id":"1.187557985","rc":[{"batb":[[0,1.85,109.29],[1,1.84,281.35],[2,1.83,270.58]],"batl":[[0,2.18,57.55]],"ltp":1.96,"tv":14177.07,"id":5300820},{"batb":[[0,1.94,128.27],[1,1.92,157.01],[2,1.84,72.96]],"batl":[[0,2.02,208.4],[1,2.04,133.18],[2,2.18,196.19]],"ltp":2.06,"tv":5083.06,"id":9629022}]}]}
{"op":"mcm","clk":"4215049201","pt":1631534048654,"mc":[{"id":"1.187557985","rc":[{"batb":[[0,1.84,281.35],[1,1.83,270.58],[2,1.82,343.07]],"batl":[[0,2.2,166.25],[1,2.22,265.63],[2,2.24,270.1]],"ltp":1.96,"tv":14177.07,"id":5300820},{"batb":[[0,1.83,305.89],[1,1.82,300.95],[2,1.81,368.11]],"batl":[[0,2.18,196.19],[1,2.2,236.38],[2,2.22,247.49]],"ltp":2.06,"tv":5083.06,"id":9629022}]}]}
{"op":"mcm","clk":"4215049277","pt":1631534049641,"mc":[{"id":"1.187557985","rc":[{"batl":[[0,2.02,87.11],[1,2.18,196.19],[2,2.2,236.38]],"ltp":2.06,"tv":5083.06,"id":9629022}]}]}
{"op":"mcm","clk":"4215049288","pt":1631534049849,"mc":[{"id":"1.187557985","rc":[{"batl":[[0,2.18,196.19],[1,2.2,236.38],[2,2.22,247.49]],"ltp":2.06,"tv":5083.06,"id":9629022}]}]}
{"op":"mcm","clk":"4215049416","pt":1631534051576,"mc":[{"id":"1.187557985","rc":[{"batb":[[2,1.81,544.38]],"batl":[[2,2.22,417.46]],"ltp":2.06,"tv":5083.06,"id":9629022}]}]}
{"op":"mcm","clk":"4215049560","pt":1631534053359,"mc":[{"id":"1.187557985","rc":[{"batb":[[1,1.82,295.95]],"ltp":2.06,"tv":5083.06,"id":9629022}]}]}
{"op":"mcm","clk":"4215049801","pt":1631534056604,"mc":[{"id":"1.187557985","rc":[{"batl":[[0,2.18,4],[1,2.2,166.25],[2,2.22,265.63]],"ltp":1.96,"tv":14177.07,"id":5300820},{"batb":[[0,1.85,4],[1,1.84,5],[2,1.83,305.89]],"ltp":2.06,"tv":5083.06,"id":9629022}]}]}
{"op":"mcm","clk":"4215050150","pt":1631534061477,"mc":[{"id":"1.187557985","rc":[{"batl":[[1,2.2,3],[2,2.28,6.34]],"ltp":1.96,"tv":14177.07,"id":5300820},{"batb":[[2,1.83,86.5]],"batl":[[2,2.22,247.49]],"ltp":2.06,"tv":5083.06,"id":9629022}]}]}
{"op":"mcm","clk":"4215050390","pt":1631534064409,"mc":[{"id":"1.187557985","rc":[{"trd":[[1.84,23.52]],"batb":[[0,1.82,547.3],[1,1.8,278.57],[2,1.77,35.37]],"batl":[[0,1.89,163.37],[1,1.91,162.85],[2,1.94,2028.8]],"ltp":1.84,"tv":14200.59,"id":5300820},{"batb":[[0,2.12,2],[1,2.1,223.8],[2,2.08,111.9]],"batl":[[0,2.22,247.49],[1,2.3,7.05],[2,2.22,0]],"ltp":2.06,"tv":5083.06,"id":9629022}],"tv":19283.65}]}
{"op":"mcm","clk":"4215050487","pt":1631534065501,"mc":[{"id":"1.187557985","rc":[{"batb":[[1,1.81,162.29],[2,1.8,359.72]],"ltp":1.84,"tv":14200.59,"id":5300820},{"batb":[[0,2.12,104.43]],"batl":[[2,2.72,7.35]],"ltp":2.06,"tv":5083.06,"id":9629022}]}]}
{"op":"mcm","clk":"4215050646","pt":1631534067584,"mc":[{"id":"1.187557985","rc":[{"batb":[[0,1.82,579.95]],"ltp":1.84,"tv":14200.59,"id":5300820},{"batl":[[0,2.22,274.43],[1,2.3,13.62]],"ltp":2.06,"tv":5083.06,"id":9629022}]}]}
{"op":"mcm","clk":"4215050713","pt":1631534068468,"mc":[{"id":"1.187557985","rc":[{"batl":[[0,1.89,167.37]],"ltp":1.84,"tv":14200.59,"id":5300820},{"batb":[[0,2.12,107.43],[1,2.1,226.8]],"batl":[[0,2.22,277.43]],"ltp":2.06,"tv":5083.06,"id":9629022}]}]}
{"op":"mcm","clk":"4215050796","pt":1631534069606,"mc":[{"id":"1.187557985","rc":[{"trd":[[1.82,245.92]],"batb":[[0,1.82,578.03]],"ltp":1.82,"tv":14204.42,"id":5300820},{"trd":[[2.22,8.23]],"batl":[[0,2.22,275.86]],"ltp":2.22,"tv":5086.2,"id":9629022}],"tv":19290.62}]}
{"op":"mcm","clk":"4215050854","pt":1631534070599,"mc":[{"id":"1.187557985","rc":[{"batb":[[0,1.82,545.38]],"ltp":1.82,"tv":14204.42,"id":5300820}]}]}
{"op":"mcm","clk":"4215050862","pt":1631534070695,"mc":[{"id":"1.187557985","rc":[{"batl":[[2,2.42,5.75]],"ltp":2.22,"tv":5086.2,"id":9629022}]}]}
{"op":"mcm","clk":"4215050985","pt":1631534072610,"mc":[{"id":"1.187557985","rc":[{"batl":[[0,1.84,4],[1,1.89,167.37],[2,1.91,162.85]],"ltp":1.82,"tv":14204.42,"id":5300820},{"batb":[[2,2.08,139.67]],"ltp":2.22,"tv":5086.2,"id":9629022}]}]}
{"op":"mcm","clk":"4215051043","pt":1631534073405,"mc":[{"id":"1.187557985","rc":[{"batb":[[0,1.83,32.65],[1,1.82,545.38],[2,1.81,162.29]],"ltp":1.82,"tv":14204.42,"id":5300820},{"batl":[[2,2.34,7.25]],"ltp":2.22,"tv":5086.2,"id":9629022}]}]}
{"op":"mcm","clk":"4215051188","pt":1631534075415,"mc":[{"id":"1.187557985","rc":[{"batl":[[1,1.85,5],[2,1.89,167.37]],"ltp":1.82,"tv":14204.42,"id":5300820}]}]}
{"op":"mcm","clk":"4215051874","pt":1631534084925,"mc":[{"id":"1.187557985","rc":[{"batl":[[0,1.89,163.37],[1,1.91,162.85],[2,1.93,7.5]],"ltp":1.82,"tv":14204.42,"id":5300820},{"batb":[[0,2.12,104.43],[1,2.1,223.8]],"ltp":2.22,"tv":5086.2,"id":9629022}]}]}
{"op":"mcm","clk":"4215052458","pt":1631534092634,"mc":[{"id":"1.187557985","rc":[{"batb":[[0,1.82,204.23],[1,1.8,278.57],[2,1.77,34.18]],"batl":[[0,1.89,161.37]],"ltp":1.82,"tv":14204.42,"id":5300820},{"batb":[[0,2.12,102.43],[1,2.08,27.77],[2,1.97,26.17]],"batl":[[0,2.3,6.57],[1,2.34,7.25],[2,2.42,5.75]],"ltp":2.22,"tv":5086.2,"id":9629022}]}]}
{"op":"mcm","clk":"4215052484","pt":1631534093051,"mc":[{"id":"1.187557985","rc":[{"batb":[[0,1.77,34.18],[1,1.71,32.19],[2,1.69,104.27]],"batl":[[0,1.93,7.5],[1,2.04,7.88],[2,2.06,7.75]],"ltp":1.82,"tv":14204.42,"id":5300820},{"batb":[[0,2.08,27.77],[1,1.97,26.17],[2,1.95,29.31]],"batl":[[1,2.42,5.75],[2,2.42,0]],"ltp":2.22,"tv":5086.2,"id":9629022}]}]}
{"op":"mcm","clk":"4215052596","pt":1631534094514,"mc":[{"id":"1.187557985","rc":[{"batb":[[0,1.71,32.19],[1,1.69,104.27],[2,1.67,415.42]],"batl":[[0,2.04,7.88],[1,2.06,7.75],[2,2.14,7.25]],"ltp":1.82,"tv":14204.42,"id":5300820},{"batb":[[0,1.97,26.17],[1,1.95,29.31],[2,1.94,67.53]],"batl":[[0,2.42,5.75],[1,2.42,0]],"ltp":2.22,"tv":5086.2,"id":9629022}]}]}
{"op":"mcm","clk":"4215052613","pt":1631534094721,"mc":[{"id":"1.187557985","rc":[{"batl":[[0,2.14,7.25],[1,2.28,6.34],[2,2.5,278.33]],"ltp":1.82,"tv":14204.42,"id":5300820},{"batb":[[0,1.94,67.53],[1,1.88,24.96],[2,1.79,28.31]],"ltp":2.22,"tv":5086.2,"id":9629022}]}]}
{"op":"mcm","clk":"4215052754","pt":1631534096437,"mc":[{"id":"1.187557985","rc":[{"batb":[[0,1.71,192.64],[1,1.69,344.06]],"batl":[[0,2.08,187.26],[1,2.1,122.54],[2,2.14,7.25]],"ltp":1.82,"tv":14204.42,"id":5300820}]}]}
{"op":"mcm","clk":"4215052885","pt":1631534098151,"mc":[{"id":"1.187557985","rc":[{"batb":[[0,1.71,196.64],[1,1.7,4],[2,1.69,344.06]],"batl":[[0,2.04,3],[1,2.08,190.26],[2,2.1,122.54]],"ltp":1.82,"tv":14204.42,"id":5300820},{"batb":[[0,1.97,4],[1,1.96,4],[2,1.94,72.53]],"batl":[[0,2.42,8.75]],"ltp":2.22,"tv":5086.2,"id":9629022}]}]}
{"op":"mcm","clk":"4215053013","pt":1631534099654,"mc":[{"id":"1.187557985","rc":[{"batb":[[0,1.75,34.31],[1,1.71,36.19],[2,1.7,4]],"batl":[[1,2.08,3],[2,2.14,7.25]],"ltp":1.82,"tv":14204.42,"id":5300820},{"batl":[[0,2.34,6.75],[1,2.42,8.75]],"ltp":2.22,"tv":5086.2,"id":9629022}]}]}
{"op":"mcm","clk":"4215053027","pt":1631534099913,"mc":[{"id":"1.187557985","rc":[{"batb":[[0,1.71,36.19],[1,1.7,4],[2,1.69,104.27]],"ltp":1.82,"tv":14204.42,"id":5300820},{"batl":[[0,2.42,8.75],[1,2.42,0]],"ltp":2.22,"tv":5086.2,"id":9629022}]}]}
{"op":"mcm","clk":"4215053184","pt":1631534101640,"mc":[{"id":"1.187557985","rc":[{"batb":[[0,1.99,1922.1],[1,1.98,4391.08],[2,1.97,1865.58]],"batl":[[0,2.14,7.25],[1,2.28,6.34],[2,2.5,278.33]],"ltp":1.82,"tv":14204.42,"id":5300820},{"batb":[[0,1.94,67.53],[1,1.88,2059.54],[2,1.87,987.37]],"batl":[[1,2.48,8.06]],"ltp":2.22,"tv":5086.2,"id":9629022}]}]}
{"op":"mcm","clk":"4215053283","pt":1631534102632,"mc":[{"id":"1.187557985","rc":[{"trd":[[2,11.05]],"batb":[[0,1.99,961.06],[1,1.98,956.81],[2,1.97,932.8]],"ltp":2.0,"tv":14215.47,"id":5300820},{"trd":[[2,11.05]],"batb":[[1,1.93,169.93],[2,1.91,159.61]],"batl":[[0,2,96.15],[1,2.02,137.14],[2,2.42,8.75]],"ltp":2.0,"tv":5097.25,"id":9629022}],"tv":19312.72}]}
{"op":"mcm","clk":"4215053385","pt":1631534103634,"mc":[{"id":"1.187557985","rc":[{"batl":[[0,2.1,7.15],[1,2.14,7.25],[2,2.28,6.34]],"ltp":2.0,"tv":14215.47,"id":5300820},{"batb":[[2,1.91,191.05]],"batl":[[0,2.02,137.14],[1,2.12,7.08],[2,2.2,43.75]],"ltp":2.0,"tv":5097.25,"id":9629022}]}]}
{"op":"mcm","clk":"4215053462","pt":1631534104564,"mc":[{"id":"1.187557985","rc":[{"batl":[[2,2.4,3]],"ltp":2.0,"tv":5097.25,"id":9629022}]}]}
{"op":"mcm","clk":"4215053505","pt":1631534105038,"mc":[{"id":"1.187557985","rc":[{"batb":[[0,2,3],[1,1.99,965.06],[2,1.98,956.81]],"batl":[[1,2.12,30.32],[2,2.14,7.25]],"ltp":2.0,"tv":14215.47,"id":5300820},{"batl":[[0,2,5],[1,2.02,137.14],[2,2.12,7.08]],"ltp":2.0,"tv":5097.25,"id":9629022}]}]}
{"op":"mcm","clk":"4215053667","pt":1631534106665,"mc":[{"id":"1.187557985","rc":[{"trd":[[1.99,55.78],[2,22.05]],"batb":[[0,1.99,937.17],[1,1.98,956.81],[2,1.97,932.8]],"ltp":1.99,"tv":14282.25,"id":5300820},{"trd":[[2,16.05]],"batl":[[0,2.02,236.55],[1,2.04,133.16],[2,2.1,67.58]],"ltp":2.0,"tv":5102.25,"id":9629022}],"tv":19384.5}]}
{"op":"mcm","clk":"4215053736","pt":1631534107445,"mc":[{"id":"1.187557985","rc":[{"trd":[[2,25.51]],"ltp":2.0,"tv":14285.71,"id":5300820},{"trd":[[2,19.37]],"batl":[[2,2.4,3]],"ltp":2.0,"tv":5105.57,"id":9629022}],"tv":19391.28}]}
{"op":"mcm","clk":"4215053829","pt":1631534108544,"mc":[{"id":"1.187557985","rc":[{"batl":[[2,2.1,7.55]],"ltp":2.0,"tv":5105.57,"id":9629022}]}]}
{"op":"mcm","clk":"4215054001","pt":1631534110633,"mc":[{"id":"1.187557985","rc":[{"batl":[[0,2.02,278.64],[2,2.1,14.7]],"ltp":2.0,"tv":5105.57,"id":9629022}]}]}
{"op":"mcm","clk":"4215054129","pt":1631534112252,"mc":[{"id":"1.187557985","rc":[{"batb":[[0,1.99,966.55]],"ltp":2.0,"tv":14285.71,"id":5300820}]}]}
{"op":"mcm","clk":"4215054319","pt":1631534114448,"mc":[{"id":"1.187557985","rc":[{"batb":[[0,1.92,31.27],[1,1.85,29.77],[2,1.81,83.01]],"batl":[[1,2.32,7.11],[2,2.52,6.51]],"ltp":2.0,"tv":14285.71,"id":5300820},{"batb":[[0,1.91,31.44],[1,1.77,90.63],[2,1.76,34.23]],"batl":[[0,2.1,7.15],[1,2.18,7.25],[2,2.28,6.84]],"ltp":2.0,"tv":5105.57,"id":9629022}]}]}
{"op":"mcm","clk":"4215054401","pt":1631534115491,"mc":[{"id":"1.187557985","rc":[{"batb":[[0,1.85,29.77],[1,1.81,83.01],[2,1.79,29.31]],"batl":[[0,2.32,7.11],[1,2.52,6.51],[2,2.58,5.44]],"ltp":2.0,"tv":14285.71,"id":5300820},{"batb":[[0,1.77,90.63],[1,1.76,34.23],[2,1.66,35.28]],"batl":[[0,2.18,7.25],[1,2.28,6.84],[2,2.4,3]],"ltp":2.0,"tv":5105.57,"id":9629022}]}]}
{"op":"mcm","clk":"4215054425","pt":1631534115754,"mc":[{"id":"1.187557985","rc":[{"batl":[[0,2.52,6.51],[1,2.58,5.44],[2,2.82,234.47]],"ltp":2.0,"tv":14285.71,"id":5300820},{"batb":[[1,1.66,35.28],[2,1.64,35.82]],"ltp":2.0,"tv":5105.57,"id":9629022}]}]}
{"op":"mcm","clk":"4215054571","pt":1631534117583,"mc":[{"id":"1.187557985","rc":[{"batb":[[1,1.76,144.33],[2,1.74,215.24]],"batl":[[1,2.2,171.11],[2,2.22,104.89]],"ltp":2.0,"tv":5105.57,"id":9629022}]}]}
{"op":"mcm","clk":"4215054627","pt":1631534118164,"mc":[{"id":"1.187557985","rc":[{"batb":[[2,1.72,5]],"ltp":2.0,"tv":14285.71,"id":5300820},{"batb":[[1,1.66,35.28],[2,1.64,35.82]],"batl":[[1,2.4,3],[2,2.22,0]],"ltp":2.0,"tv":5105.57,"id":9629022}]}]}
{"op":"mcm","clk":"4215054731","pt":1631534119367,"mc":[{"id":"1.187557985","rc":[{"batl":[[0,2.18,11.25]],"ltp":2.0,"tv":5105.57,"id":9629022}]}]}
{"op":"mcm","clk":"4215054926","pt":1631534121664,"mc":[{"id":"1.187557985","rc":[{"batb":[[0,1.9,117.05],[1,1.88,167.58],[2,1.77,90.63]],"batl":[[0,1.97,178.5],[1,1.99,143.21],[2,2.18,11.25]],"ltp":2.0,"tv":5105.57,"id":9629022}]}]}
{"op":"mcm","clk":"4215055012","pt":1631534122560,"mc":[{"id":"1.187557985","rc":[{"batb":[[0,1.85,33.77],[1,1.84,4],[2,1.81,83.01]],"batl":[[0,2.3,4],[1,2.32,5.36],[2,2.52,6.51]],"ltp":2.0,"tv":14285.71,"id":5300820},{"batb":[[2,1.77,95.63]],"ltp":2.0,"tv":5105.57,"id":9629022}]}]}
{"op":"mcm","clk":"4215055089","pt":1631534123388,"mc":[{"id":"1.187557985","rc":[{"batl":[[1,2.52,6.51],[2,2.58,5.44]],"ltp":2.0,"tv":14285.71,"id":5300820},{"batb":[[0,1.77,95.63],[1,1.76,5],[2,1.66,35.28]],"batl":[[0,2.18,11.25],[1,2.4,3],[2,2.18,0]],"ltp":2.0,"tv":5105.57,"id":9629022}]}]}
{"op":"mcm","clk":"4215055371","pt":1631534126373,"mc":[{"id":"1.187557985","rc":[{"batl":[[1,2.32,6.61],[2,2.52,6.51]],"ltp":2.0,"tv":14285.71,"id":5300820},{"batb":[[1,1.76,183.06],[2,1.74,215.24]],"batl":[[1,2.2,171.11],[2,2.22,104.89]],"ltp":2.0,"tv":5105.57,"id":9629022}]}]}
{"op":"mcm","clk":"4215055390","pt":1631534126682,"mc":[{"id":"1.187557985","rc":[{"batl":[[1,2.52,6.51],[2,2.58,5.44]],"ltp":2.0,"tv":14285.71,"id":5300820},{"batb":[[1,1.76,149.33]],"ltp":2.0,"tv":5105.57,"id":9629022}]}]}
{"op":"mcm","clk":"4215055579","pt":1631534128665,"mc":[{"id":"1.187557985","rc":[{"batb":[[1,1.76,5],[2,1.66,35.28]],"batl":[[1,2.4,3],[2,2.22,0]],"ltp":2.0,"tv":5105.57,"id":9629022}]}]}
{"op":"mcm","clk":"4215055601","pt":1631534128873,"mc":[{"id":"1.187557985","rc":[{"batb":[[0,1.85,29.77]],"ltp":2.0,"tv":14285.71,"id":5300820},{"batl":[[0,2.18,7.25]],"ltp":2.0,"tv":5105.57,"id":9629022}]}]}
{"op":"mcm","clk":"4215055847","pt":1631534131360,"mc":[{"id":"1.187557985","rc":[{"trd":[[1.85,46.66]],"batb":[[0,1.85,18.07],[1,1.84,147.62],[2,1.82,186.48]],"batl":[[0,1.9,121.34],[1,1.92,1163.41],[2,1.93,966.8]],"ltp":1.85,"tv":14309.11,"id":5300820},{"batb":[[0,2.08,2.31],[1,1.77,95.63],[2,1.76,5]],"ltp":2.0,"tv":5105.57,"id":9629022}],"tv":19414.68}]}
{"op":"mcm","clk":"4215055940","pt":1631534132359,"mc":[{"id":"1.187557985","rc":[{"trd":[[1.9,150.8]],"batl":[[0,1.9,109.3]],"ltp":1.9,"tv":14321.15,"id":5300820},{"trd":[[2.1,581.71]],"batb":[[0,2.1,105.1],[1,2.08,2.31],[2,2.04,28.84]],"batl":[[2,2.7,7.41]],"ltp":2.1,"tv":5116.46,"id":9629022}],"tv":19437.61}]}
{"op":"mcm","clk":"4215056252","pt":1631534135402,"mc":[{"id":"1.187557985","rc":[{"trd":[[1.85,50.38]],"batb":[[0,1.85,16.21]],"ltp":1.85,"tv":14324.86,"id":5300820},{"trd":[[2.18,3.14]],"batl":[[0,2.18,5.68]],"ltp":2.18,"tv":5119.6,"id":9629022}],"tv":19444.47}]}
{"op":"mcm","clk":"4215056357","pt":1631534136399,"mc":[{"id":"1.187557985","rc":[{"trd":[[1.85,82.8],[1.9,167.72]],"batb":[[0,1.84,147.62],[1,1.82,186.48],[2,1.81,83.01]],"batl":[[0,1.9,100.84]],"ltp":1.9,"tv":14374.2,"id":5300820},{"batb":[[2,1.89,73.39]],"ltp":2.18,"tv":5119.6,"id":9629022}],"tv":19493.81}]}
{"op":"mcm","clk":"4215056492","pt":1631534137510,"mc":[{"id":"1.187557985","rc":[{"batl":[[1,2.28,6.59],[2,2.38,6.25]],"ltp":2.18,"tv":5119.6,"id":9629022}]}]}
{"op":"mcm","clk":"4215056536","pt":1631534137881,"mc":[{"id":"1.187557985","rc":[{"batl":[[1,1.91,6.34],[2,1.92,1163.41]],"ltp":1.9,"tv":14374.2,"id":5300820}]}]}
{"op":"mcm","clk":"4215056734","pt":1631534139605,"mc":[{"id":"1.187557985","rc":[{"batb":[[2,2.06,28.3]],"ltp":2.18,"tv":5119.6,"id":9629022}]}]}
{"op":"mcm","clk":"4215056955","pt":1631534142179,"mc":[{"id":"1.187557985","rc":[{"batb":[[0,1.84,178.87]],"ltp":1.9,"tv":14374.2,"id":5300820}]}]}
{"op":"mcm","clk":"4215057078","pt":1631534143491,"mc":[{"id":"1.187557985","rc":[{"trd":[[1.9,233.92]],"batb":[[0,1.9,16.66],[1,1.84,178.87],[2,1.82,186.48]],"batl":[[0,1.91,6.34],[1,1.92,1003.14],[2,1.93,974.3]],"ltp":1.9,"tv":14440.4,"id":5300820}],"tv":19560.01}]}
{"op":"mcm","clk":"4215057129","pt":1631534144111,"mc":[{"id":"1.187557985","rc":[{"batb":[[0,1.9,17.51]],"ltp":1.9,"tv":14440.4,"id":5300820}]}]}
{"op":"mcm","clk":"4215057266","pt":1631534145618,"mc":[{"id":"1.187557985","rc":[{"batb":[[0,1.84,178.87],[1,1.82,186.48],[2,1.81,83.01]],"ltp":1.9,"tv":14440.4,"id":5300820}]}]}
{"op":"mcm","clk":"4215057332","pt":1631534146307,"mc":[{"id":"1.187557985","rc":[{"batb":[[0,1.84,200.26]],"batl":[[0,1.91,187.49],[2,1.93,1131.96]],"ltp":1.9,"tv":14440.4,"id":5300820}]}]}
{"op":"mcm","clk":"4215057441","pt":1631534147311,"mc":[{"id":"1.187557985","rc":[{"trd":[[2.1,641.81]],"batb":[[0,2.1,75.05]],"batl":[[2,2.3,6.25]],"ltp":2.1,"tv":5179.7,"id":9629022}],"tv":19620.11}]}
{"op":"mcm","clk":"4215057775","pt":1631534150610,"mc":[{"id":"1.187557985","rc":[{"trd":[[1.91,34.82]],"batl":[[0,1.91,170.09]],"ltp":1.91,"tv":14475.22,"id":5300820}],"tv":19654.92}]}
{"op":"mcm","clk":"4215057866","pt":1631534151612,"mc":[{"id":"1.187557985","rc":[{"trd":[[1.91,68.74]],"batl":[[0,1.91,153.13]],"ltp":1.91,"tv":14509.15,"id":5300820}],"tv":19688.85}]}
{"op":"mcm","clk":"4215058045","pt":1631534153601,"mc":[{"id":"1.187557985","rc":[{"batb":[[0,1.84,215.86]],"ltp":1.91,"tv":14509.15,"id":5300820}]}]}
{"op":"mcm","clk":"4215058217","pt":1631534155637,"mc":[{"id":"1.187557985","rc":[{"batl":[[0,2.18,28.02]],"ltp":2.1,"tv":5179.7,"id":9629022}]}]}
{"op":"mcm","clk":"4215058239","pt":1631534155904,"mc":[{"id":"1.187557985","rc":[{"batl":[[0,2.18,5.68]],"ltp":2.1,"tv":5179.7,"id":9629022}]}]}
{"op":"mcm","clk":"4215058495","pt":1631534159124,"mc":[{"id":"1.187557985","rc":[{"batl":[[0,2.18,28.02]],"ltp":2.1,"tv":5179.7,"id":9629022}]}]}
{"op":"mcm","clk":"4215058773","pt":1631534162331,"mc":[{"id":"1.187557985","rc":[{"batb":[[0,1.78,33.96],[1,1.74,409.86],[2,1.73,39.13]],"batl":[[0,1.93,7.5],[1,2.28,3],[2,2.32,6.11]],"ltp":1.91,"tv":14509.15,"id":5300820},{"batb":[[0,2.06,28.3],[1,1.89,73.39],[2,1.78,4]],"batl":[[0,2.38,6.25],[1,2.4,9.14],[2,2.5,6.39]],"ltp":2.1,"tv":5179.7,"id":9629022}]}]}
{"op":"mcm","clk":"4215058881","pt":1631534163453,"mc":[{"id":"1.187557985","rc":[{"batb":[[0,1.74,409.86],[1,1.73,39.13],[2,1.72,34.34]],"batl":[[0,2.28,3],[1,2.32,6.11],[2,2.52,6.51]],"ltp":1.91,"tv":14509.15,"id":5300820},{"batb":[[0,1.89,73.39],[1,1.78,4],[2,1.76,33.48]],"ltp":2.1,"tv":5179.7,"id":9629022}]}]}
{"op":"mcm","clk":"4215059048","pt":1631534165539,"mc":[{"id":"1.187557985","rc":[{"batb":[[0,1.78,36.66],[1,1.74,409.86],[2,1.73,39.13]],"batl":[[0,2.16,202.42],[1,2.18,116.85],[2,2.28,3]],"ltp":1.91,"tv":14509.15,"id":5300820},{"batb":[[0,1.88,73.81],[1,1.85,29.57],[2,1.78,4]],"ltp":2.1,"tv":5179.7,"id":9629022}]}]}
{"op":"mcm","clk":"4215059148","pt":1631534166640,"mc":[{"id":"1.187557985","rc":[{"batb":[[0,1.74,414.86],[1,1.73,43.13],[2,1.72,34.34]],"batl":[[0,2.14,4],[1,2.16,202.42],[2,2.18,116.85]],"ltp":1.91,"tv":14509.15,"id":5300820},{"batb":[[0,1.89,3],[1,1.88,77.81],[2,1.85,29.57]],"batl":[[0,2.36,3],[1,2.38,6.25],[2,2.4,9.14]],"ltp":2.1,"tv":5179.7,"id":9629022}]}]}
{"op":"mcm","clk":"4215059170","pt":1631534166848,"mc":[{"id":"1.187557985","rc":[{"batb":[[0,1.88,77.81],[1,1.85,29.57],[2,1.78,4]],"ltp":2.1,"tv":5179.7,"id":9629022}]}]}
{"op":"mcm","clk":"4215059313","pt":1631534168435,"mc":[{"id":"1.187557985","rc":[{"batl":[[1,2.18,6.75],[2,2.28,3]],"ltp":1.91,"tv":14509.15,"id":5300820}]}]}
{"op":"mcm","clk":"4215059383","pt":1631534169326,"mc":[{"id":"1.187557985","rc":[{"batl":[[0,2.28,3],[1,2.32,6.11],[2,2.52,6.51]],"ltp":1.91,"tv":14509.15,"id":5300820},{"batb":[[0,1.88,73.81],[1,1.78,4],[2,1.76,33.48]],"ltp":2.1,"tv":5179.7,"id":9629022}]}]}
{"op":"mcm","clk":"4215059573","pt":1631534171455,"mc":[{"id":"1.187557985","rc":[{"batb":[[1,1.87,165.14],[2,1.85,176.41]],"batl":[[0,1.94,154.59],[1,1.96,1125.66],[2,1.97,947.06]],"ltp":2.1,"tv":5179.7,"id":9629022}]}]}
{"op":"mcm","clk":"4215059662","pt":1631534172551,"mc":[{"id":"1.187557985","rc":[{"trd":[[2.06,10.81]],"batb":[[0,2.02,118.83],[1,1.93,31.1],[2,1.89,25]],"batl":[[0,2.14,7.02],[1,2.26,15],[2,2.28,3]],"ltp":2.06,"tv":14519.96,"id":5300820},{"trd":[[1.94,11.48]],"batb":[[0,1.88,105.79]],"batl":[[0,1.94,143.11]],"ltp":1.94,"tv":5191.18,"id":9629022}],"tv":19711.14}]}
{"op":"mcm","clk":"4215059716","pt":1631534173134,"mc":[{"id":"1.187557985","rc":[{"batb":[[0,2.06,4],[1,2.04,4],[2,2.02,118.83]],"ltp":2.06,"tv":14519.96,"id":5300820}]}]}
{"op":"mcm","clk":"4215059837","pt":1631534174447,"mc":[{"id":"1.187557985","rc":[{"batl":[[1,1.95,4],[2,1.96,1125.66]],"ltp":1.94,"tv":5191.18,"id":9629022}]}]}
{"op":"mcm","clk":"4215059953","pt":1631534175644,"mc":[{"id":"1.187557985","rc":[{"batl":[[0,1.94,158.46]],"ltp":1.94,"tv":5191.18,"id":9629022}]}]}
{"op":"mcm","clk":"4215060040","pt":1631534176639,"mc":[{"id":"1.187557985","rc":[{"trd":[[2.06,40.4]],"batb":[[0,2.04,4],[1,2.02,118.83],[2,1.82,82.26]],"ltp":2.06,"tv":14549.54,"id":5300820},{"trd":[[1.94,37.91]],"batl":[[0,1.94,133.78]],"ltp":1.94,"tv":5217.61,"id":9629022}],"tv":19767.15}]}
{"op":"mcm","clk":"4215060137","pt":1631534177840,"mc":[{"id":"1.187557985","rc":[{"batb":[[2,1.91,29.39]],"ltp":2.06,"tv":14549.54,"id":5300820}]}]}
{"op":"mcm","clk":"4215060298","pt":1631534179557,"mc":[{"id":"1.187557985","rc":[{"batb":[[0,2.06,33.67],[1,2.04,4],[2,2.02,118.83]],"ltp":2.06,"tv":14549.54,"id":5300820},{"trd":[[1.88,48.25]],"batb":[[0,1.88,81.66]],"ltp":1.88,"tv":5265.86,"id":9629022}],"tv":19815.41}]}
{"op":"mcm","clk":"4215060496","pt":1631534181655,"mc":[{"id":"1.187557985","rc":[{"batb":[[0,2.04,4],[1,2.02,118.83],[2,1.95,30.77]],"batl":[[1,2.28,3],[2,2.32,6.11]],"ltp":2.06,"tv":14549.54,"id":5300820},{"batl":[[2,1.96,149.88]],"ltp":1.88,"tv":5265.86,"id":9629022}]}]}
{"op":"mcm","clk":"4215060592","pt":1631534182653,"mc":[{"id":"1.187557985","rc":[{"batb":[[1,1.95,30.77],[2,1.91,29.39]],"batl":[[2,2.62,5.25]],"ltp":2.06,"tv":14549.54,"id":5300820},{"batb":[[0,1.78,4],[1,1.67,108.28],[2,1.62,36.04]],"batl":[[0,1.95,4],[1,2.1,7.55],[2,2.2,6.88]],"ltp":1.88,"tv":5265.86,"id":9629022}]}]}
{"op":"mcm","clk":"4215060664","pt":1631534183444,"mc":[{"id":"1.187557985","rc":[{"batb":[[1,1.91,29.39],[2,1.84,28.47]],"batl":[[0,2.08,50]],"ltp":2.06,"tv":14549.54,"id":5300820}]}]}
{"op":"mcm","clk":"4215060838","pt":1631534185367,"mc":[{"id":"1.187557985","rc":[{"batb":[[0,1.84,28.47],[1,1.82,82.26],[2,1.79,5]],"batl":[[1,2.62,5.25],[2,2.82,234.47]],"ltp":2.06,"tv":14549.54,"id":5300820},{"batb":[[0,1.67,108.28],[1,1.66,167.45],[2,1.65,130.03]],"batl":[[0,2.18,139.28],[1,2.2,114.38],[2,2.38,6.25]],"ltp":1.88,"tv":5265.86,"id":9629022}]}]}
{"op":"mcm","clk":"4215061131","pt":1631534188565,"mc":[{"id":"1.187557985","rc":[{"batb":[[0,1.91,31.39],[1,1.84,33.47],[2,1.83,5]],"batl":[[1,2.6,5.76],[2,2.62,5.25]],"ltp":2.06,"tv":14549.54,"id":5300820},{"batl":[[0,2.1,7.25],[1,2.18,142.28],[2,2.2,114.38]],"ltp":1.88,"tv":5265.86,"id":9629022}]}]}
{"op":"mcm","clk":"4215061155","pt":1631534188764,"mc":[{"id":"1.187557985","rc":[{"batb":[[0,1.84,33.47],[1,1.83,5],[2,1.82,82.26]],"ltp":2.06,"tv":14549.54,"id":5300820},{"batl":[[0,2.18,142.28],[1,2.2,114.38],[2,2.38,6.25]],"ltp":1.88,"tv":5265.86,"id":9629022}]}]}
{"op":"mcm","clk":"4215061600","pt":1631534193173,"mc":[{"id":"1.187557985","rc":[{"batl":[[0,2.62,5.25],[1,2.82,234.47],[2,3.1,3.75]],"ltp":2.06,"tv":14549.54,"id":5300820}]}]}
{"op":"mcm","clk":"4215061697","pt":1631534194174,"mc":[{"id":"1.187557985","rc":[{"batl":[[0,2.18,3],[1,2.2,0],[2,2.38,0]],"ltp":1.88,"tv":5265.86,"id":9629022}]}]}
{"op":"mcm","clk":"4215061810","pt":1631534195379,"mc":[{"id":"1.187557985","rc":[{"batl":[[1,3.1,3.75],[2,100,0.96]],"ltp":2.06,"tv":14549.54,"id":5300820}]}]}
{"op":"mcm","clk":"4215061919","pt":1631534196579,"mc":[{"id":"1.187557985","rc":[{"trd":[[2.04,50]],"batl":[[1,100,0.96],[2,100,0]],"ltp":2.04,"tv":14599.54,"id":5300820},{"trd":[[1.96,52.04]],"batl":[[0,1.71,1505.15],[1,1.73,2210.98],[2,1.74,2145.96]],"ltp":1.96,"tv":5317.9,"id":9629022}],"tv":19917.45}]}
{"op":"mcm","clk":"4215062028","pt":1631534197648,"mc":[{"id":"1.187557985","rc":[{"trd":[[2.4,9.52]],"batb":[[0,2.34,78.74],[1,2.14,100.25],[2,1.84,33.47]],"ltp":2.4,"tv":14609.06,"id":5300820},{"trd":[[1.71,13.36]],"batl":[[0,1.71,154.34],[1,1.73,1327.11],[2,1.74,1072.98]],"ltp":1.71,"tv":5331.26,"id":9629022}],"tv":19940.33}]}
{"op":"mcm","clk":"4215062118","pt":1631534198653,"mc":[{"id":"1.187557985","rc":[{"trd":[[2.4,15.85]],"batb":[[2,1.85,5]],"batl":[[0,2.6,26.25],[1,2.62,5.25],[2,100,0.96]],"ltp":2.4,"tv":14615.39,"id":5300820},{"trd":[[1.71,92.94]],"batl":[[0,1.71,110.11]],"ltp":1.71,"tv":5410.84,"id":9629022}],"tv":20026.24}]}
{"op":"mcm","clk":"4215062199","pt":1631534199546,"mc":[{"id":"1.187557985","rc":[{"batb":[[2,2.04,4]],"batl":[[2,3.45,182.89]],"ltp":2.4,"tv":14615.39,"id":5300820},{"batl":[[0,1.73,1105.48],[1,1.74,1072.98],[2,1.75,1072.98]],"ltp":1.71,"tv":5410.84,"id":9629022}]}]}
{"op":"mcm","clk":"4215062376","pt":1631534201610,"mc":[{"id":"1.187557985","rc":[{"batb":[[0,2.36,33.62],[1,2.34,78.74],[2,2.14,100.25]],"batl":[[0,2.38,6.22],[1,2.6,26.25],[2,2.62,5.25]],"ltp":2.4,"tv":14615.39,"id":5300820}]}]}
{"op":"mcm","clk":"4215062466","pt":1631534202655,"mc":[{"id":"1.187557985","rc":[{"batb":[[0,2.38,3],[1,2.36,4],[2,2.34,78.74]],"batl":[[0,2.5,24.49]],"ltp":2.4,"tv":14615.39,"id":5300820},{"batb":[[0,1.67,144.93],[1,1.66,216.35]],"batl":[[0,1.72,260.47],[1,1.73,1105.48],[2,1.74,1289.81]],"ltp":1.71,"tv":5410.84,"id":9629022}]}]}
{"op":"mcm","clk":"4215062726","pt":1631534205647,"mc":[{"id":"1.187557985","rc":[{"batb":[[2,2.34,82.74]],"ltp":2.4,"tv":14615.39,"id":5300820}]}]}
{"op":"mcm","clk":"4215062995","pt":1631534208441,"mc":[{"id":"1.187557985","rc":[{"batb":[[0,2.4,15],[1,2.38,3],[2,2.36,4]],"ltp":2.4,"tv":14615.39,"id":5300820}]}]}
{"op":"mcm","clk":"4215063051","pt":1631534209228,"mc":[{"id":"1.187557985","rc":[{"trd":[[2.4,16.63]],"batb":[[0,2.4,14.61]],"ltp":2.4,"tv":14616.17,"id":5300820}],"tv":20027.01}]}
{"op":"mcm","clk":"4215063535","pt":1631534215467,"mc":[{"id":"1.187557985","rc":[{"batl":[[0,2.6,26.25],[1,2.62,5.25],[2,2.64,5.18]],"ltp":2.4,"tv":14616.17,"id":5300820}]}]}
{"op":"mcm","clk":"4215063563","pt":1631534215731,"mc":[{"id":"1.187557985","rc":[{"batb":[[2,2.34,82.74]],"ltp":2.4,"tv":14616.17,"id":5300820}]}]}
{"op":"mcm","clk":"4215063817","pt":1631534218543,"mc":[{"id":"1.187557985","rc":[{"batl":[[0,2.54,24.17],[1,2.6,26.25],[2,2.62,5.25]],"ltp":2.4,"tv":14616.17,"id":5300820}]}]}
{"op":"mcm","clk":"4215063841","pt":1631534218758,"mc":[{"id":"1.187557985","rc":[{"batb":[[2,2.34,78.74]],"ltp":2.4,"tv":14616.17,"id":5300820}]}]}
{"op":"mcm","clk":"4215064327","pt":1631534223567,"mc":[{"id":"1.187557985","rc":[{"batb":[[0,2.38,3],[1,2.34,78.74],[2,2.3,23.07]],"batl":[[1,2.64,5.18],[2,2.8,4.52]],"ltp":2.4,"tv":14616.17,"id":5300820},{"batl":[[0,1.72,224.65],[1,1.74,216.83],[2,1.77,7.5]],"ltp":1.71,"tv":5410.84,"id":9629022}]}]}
{"op":"mcm","clk":"4215064380","pt":1631534223988,"mc":[{"id":"1.187557985","rc":[{"batb":[[0,2.3,23.07],[1,2.18,7.36],[2,2.14,108.57]],"batl":[[1,2.8,4.52],[2,2.82,5.25]],"ltp":2.4,"tv":14616.17,"id":5300820},{"batb":[[0,1.67,36.65],[1,1.59,129.7],[2,1.56,49.08]],"batl":[[0,1.77,7.5],[1,1.84,33.28],[2,1.87,27.5]],"ltp":1.71,"tv":5410.84,"id":9629022}]}]}
{"op":"mcm","clk":"4215064533","pt":1631534225451,"mc":[{"id":"1.187557985","rc":[{"batb":[[0,2.14,100.25],[1,2.12,7.54],[2,1.92,400.36]],"batl":[[0,2.8,4.52],[1,2.82,5.25],[2,3.45,182.89]],"ltp":2.4,"tv":14616.17,"id":5300820},{"batb":[[0,1.69,1.06]],"batl":[[0,1.89,26.5],[1,1.84,0],[2,1.87,0]],"ltp":1.71,"tv":5410.84,"id":9629022}]}]}
{"op":"mcm","clk":"4215064646","pt":1631534226648,"mc":[{"id":"1.187557985","rc":[{"batb":[[2,1.58,242.72]],"batl":[[0,1.84,177.91],[1,1.86,175.43],[2,1.89,26.5]],"ltp":1.71,"tv":5410.84,"id":9629022}]}]}
{"op":"mcm","clk":"4215064720","pt":1631534227499,"mc":[{"id":"1.187557985","rc":[{"trd":[[1.69,2.11],[1.72,0.37]],"batb":[[0,1.59,129.7],[1,1.58,242.72],[2,1.57,156.03]],"batl":[[0,1.67,3.21],[1,1.84,177.91],[2,1.86,175.43]],"ltp":1.69,"tv":5413.32,"id":9629022}],"tv":20029.5}]}
{"op":"mcm","clk":"4215064821","pt":1631534228589,"mc":[{"id":"1.187557985","rc":[{"batb":[[0,2.18,6.36],[1,2.14,103.25],[2,2.12,11.54]],"batl":[[0,2.7,3],[1,2.8,4.52],[2,2.82,5.25]],"ltp":2.4,"tv":14616.17,"id":5300820},{"batl":[[1,1.84,208.19]],"ltp":1.69,"tv":5413.32,"id":9629022}]}]}
{"op":"mcm","clk":"4215064841","pt":1631534228800,"mc":[{"id":"1.187557985","rc":[{"batb":[[0,2.14,103.25],[1,2.12,11.54],[2,1.92,400.36]],"ltp":2.4,"tv":14616.17,"id":5300820},{"batl":[[1,1.85,5],[2,1.88,4]],"ltp":1.69,"tv":5413.32,"id":9629022}]}]}
{"op":"mcm","clk":"4215064987","pt":1631534230576,"mc":[{"id":"1.187557985","rc":[{"trd":[[1.67,6.42]],"batl":[[0,1.63,2233.12],[1,1.84,5],[2,1.85,5]],"ltp":1.67,"tv":5419.74,"id":9629022}],"tv":20035.92}]}
{"op":"mcm","clk":"4215065075","pt":1631534231568,"mc":[{"id":"1.187557985","rc":[{"batb":[[2,1.4,148.56]],"batl":[[0,2.8,4.52],[1,2.82,5.25],[2,100,0.96]],"ltp":2.4,"tv":14616.17,"id":5300820},{"batl":[[0,1.65,2318.18],[1,1.66,2250],[2,1.67,2250]],"ltp":1.67,"tv":5419.74,"id":9629022}]}]}
{"op":"mcm","clk":"4215065177","pt":1631534232567,"mc":[{"id":"1.187557985","rc":[{"trd":[[2.58,9.09]],"batb":[[0,2.52,64.1],[1,2.32,81.42],[2,2.14,103.25]],"ltp":2.58,"tv":14625.26,"id":5300820},{"trd":[[1.63,14.39]],"batl":[[0,1.63,165.04],[1,1.64,131.89],[2,1.65,1159.1]],"ltp":1.63,"tv":5434.13,"id":9629022}],"tv":20059.4}]}
{"op":"mcm","clk":"4215065279","pt":1631534233562,"mc":[{"id":"1.187557985","rc":[{"batb":[[2,2.14,3]],"ltp":2.58,"tv":14625.26,"id":5300820}]}]}
{"op":"mcm","clk":"4215065392","pt":1631534234663,"mc":[{"id":"1.187557985","rc":[{"batb":[[0,2.54,4],[1,2.52,67.1],[2,2.32,81.42]],"ltp":2.58,"tv":14625.26,"id":5300820},{"batl":[[1,1.64,136.89]],"ltp":1.63,"tv":5434.13,"id":9629022}]}]}
{"op":"mcm","clk":"4215065472","pt":1631534235407,"mc":[{"id":"1.187557985","rc":[{"batb":[[0,2.58,3],[1,2.56,3],[2,2.54,4]],"batl":[[0,2.78,21.85],[1,2.8,4.52],[2,2.82,5.25]],"ltp":2.58,"tv":14625.26,"id":5300820}]}]}
{"op":"mcm","clk":"4215065577","pt":1631534236504,"mc":[{"id":"1.187557985","rc":[{"trd":[[1.58,73.24],[1.59,259.41]],"batb":[[0,1.58,206.1],[1,1.57,156.03],[2,1.56,49.08]],"ltp":1.58,"tv":5766.79,"id":9629022}],"tv":20392.05}]}
{"op":"mcm","clk":"4215065689","pt":1631534237577,"mc":[{"id":"1.187557985","rc":[{"batl":[[0,2.78,22.48]],"ltp":2.58,"tv":14625.26,"id":5300820},{"batb":[[0,1.58,224.65],[2,1.56,89.16]],"batl":[[0,1.63,198.48]],"ltp":1.58,"tv":5766.79,"id":9629022}]}]}
{"op":"mcm","clk":"4215065753","pt":1631534238200,"mc":[{"id":"1.187557985","rc":[{"trd":[[2.58,25.95]],"batb":[[0,2.56,3],[1,2.54,4],[2,2.52,67.1]],"ltp":2.58,"tv":14642.12,"id":5300820},{"trd":[[1.63,31.58]],"batl":[[0,1.63,181.29]],"ltp":1.63,"tv":5783.98,"id":9629022}],"tv":20426.1}]}
{"op":"mcm","clk":"4215065989","pt":1631534240565,"mc":[{"id":"1.187557985","rc":[{"batb":[[0,2.58,15],[1,2.56,3],[2,2.54,4]],"batl":[[0,2.76,21.85],[1,2.78,22.48],[2,2.8,4.52]],"ltp":2.58,"tv":14642.12,"id":5300820},{"trd":[[1.63,103.58]],"batb":[[0,1.58,241.04]],"batl":[[0,1.63,161.35]],"ltp":1.63,"tv":5855.98,"id":9629022}],"tv":20498.1}]}
{"op":"mcm","clk":"4215066173","pt":1631534242596,"mc":[{"id":"1.187557985","rc":[{"trd":[[1.58,80.12]],"batb":[[0,1.58,237.6]],"ltp":1.58,"tv":5862.86,"id":9629022}],"tv":20504.99}]}
{"op":"mcm","clk":"4215066270","pt":1631534243590,"mc":[{"id":"1.187557985","rc":[{"batb":[[0,2.52,83.83],[1,2.46,5.38],[2,2.38,6.67]],"batl":[[0,2.78,22.48],[1,2.82,5.25],[2,2.94,4.25]],"ltp":2.58,"tv":14642.12,"id":5300820},{"batb":[[0,1.56,40.08],[1,1.55,49.59],[2,1.52,208.46]],"batl":[[0,1.66,7.5],[1,1.68,34.39],[2,1.72,39.66]],"ltp":1.58,"tv":5862.86,"id":9629022}]}]}
{"op":"mcm","clk":"4215066366","pt":1631534244486,"mc":[{"id":"1.187557985","rc":[{"batb":[[0,2.38,6.67],[1,2.32,81.42],[2,2.2,4]],"batl":[[0,2.94,4.25],[1,3.9,160.43],[2,100,0.96]],"ltp":2.58,"tv":14642.12,"id":5300820},{"batb":[[0,1.52,208.46],[1,1.48,52.01],[2,1.43,3.41]],"batl":[[0,1.72,39.66],[1,1.83,5],[2,1.84,5]],"ltp":1.58,"tv":5862.86,"id":9629022}]}]}
{"op":"mcm","clk":"4215066572","pt":1631534246486,"mc":[{"id":"1.187557985","rc":[{"batb":[[0,1.52,397.8],[1,1.51,180.92],[2,1.48,52.01]],"batl":[[1,1.74,228],[2,1.76,208.65]],"ltp":1.58,"tv":5862.86,"id":9629022}]}]}
{"op":"mcm","clk":"4215066679","pt":1631534247599,"mc":[{"id":"1.187557985","rc":[{"batb":[[0,2.46,5.88],[1,2.38,6.67],[2,2.36,79.33]],"ltp":2.58,"tv":14642.12,"id":5300820},{"batb":[[0,1.52,245.08],[1,1.51,337.07]],"batl":[[0,1.68,33.89],[1,1.72,39.66],[2,1.74,228]],"ltp":1.58,"tv":5862.86,"id":9629022}]}]}
{"op":"mcm","clk":"4215066703","pt":1631534247897,"mc":[{"id":"1.187557985","rc":[{"batb":[[0,2.38,6.67],[1,2.36,79.33],[2,2.2,4]],"batl":[[0,2.94,7.25]],"ltp":2.58,"tv":14642.12,"id":5300820},{"batb":[[0,1.52,252.08],[1,1.51,342.07]],"batl":[[0,1.72,39.66],[1,1.74,228],[2,1.76,208.65]],"ltp":1.58,"tv":5862.86,"id":9629022}]}]}
{"op":"mcm","clk":"4215066815","pt":1631534249206,"mc":[{"id":"1.187557985","rc":[{"batb":[[0,1.52,62.74],[1,1.51,161.15]],"ltp":1.58,"tv":5862.86,"id":9629022}]}]}
{"op":"mcm","clk":"4215066934","pt":1631534250621,"mc":[{"id":"1.187557985","rc":[{"batl":[[0,2.82,8.25],[1,2.94,7.25]],"ltp":2.58,"tv":14642.12,"id":5300820},{"batb":[[0,1.55,47.19],[1,1.52,62.74],[2,1.51,161.15]],"ltp":1.58,"tv":5862.86,"id":9629022}]}]}
{"op":"mcm","clk":"4215067011","pt":1631534251515,"mc":[{"id":"1.187557985","rc":[{"batl":[[0,2.82,3],[1,2.86,3],[2,2.94,7.25]],"ltp":2.58,"tv":14642.12,"id":5300820},{"trd":[[1.68,66.78]],"batb":[[0,1.55,6]],"ltp":1.68,"tv":5929.64,"id":9629022}],"tv":20571.77}]}
{"op":"mcm","clk":"4215067113","pt":1631534252615,"mc":[{"id":"1.187557985","rc":[{"trd":[[2.38,16.29]],"batb":[[0,2.36,79.33],[1,2.3,457.34],[2,2.28,443.88]],"batl":[[0,2.52,5.76],[1,2.58,50],[2,2.82,3]],"ltp":2.38,"tv":14658.41,"id":5300820},{"trd":[[1.72,4.45]],"batb":[[0,1.68,181.52],[1,1.66,1431.06],[2,1.65,1118.22]],"batl":[[0,1.72,35.58]],"ltp":1.72,"tv":5933.72,"id":9629022}],"tv":20592.14}]}
{"op":"mcm","clk":"4215067205","pt":1631534253604,"mc":[{"id":"1.187557985","rc":[{"batb":[[1,2.32,22.72],[2,2.3,457.34]],"batl":[[1,2.56,24.01],[2,2.58,50]],"ltp":2.38,"tv":14658.41,"id":5300820},{"batb":[[1,1.67,107.61],[2,1.66,1431.06]],"batl":[[2,1.76,216.15]],"ltp":1.72,"tv":5933.72,"id":9629022}]}]}
{"op":"mcm","clk":"4215067296","pt":1631534254603,"mc":[{"id":"1.187557985","rc":[{"batb":[[0,2.36,83.33],[1,2.34,3],[2,2.32,22.72]],"ltp":2.38,"tv":14658.41,"id":5300820}]}]}
{"op":"mcm","clk":"4215067381","pt":1631534255594,"mc":[{"id":"1.187557985","rc":[{"batb":[[0,2.36,108.31]],"ltp":2.38,"tv":14658.41,"id":5300820}]}]}
{"op":"mcm","clk":"4215067483","pt":1631534256582,"mc":[{"id":"1.187557985","rc":[{"batl":[[0,2.52,42.01]],"ltp":2.38,"tv":14658.41,"id":5300820},{"trd":[[1.68,286.78]],"batb":[[0,1.67,107.61],[1,1.66,1305.88],[2,1.65,1118.22]],"batl":[[1,1.76,7.5],[2,1.83,5]],"ltp":1.68,"tv":6153.72,"id":9629022}],"tv":20812.14}]}
{"op":"mcm","clk":"4215067560","pt":1631534257418,"mc":[{"id":"1.187557985","rc":[{"trd":[[2.38,20.7]],"batl":[[1,2.58,50],[2,2.8,4]],"ltp":2.38,"tv":14662.82,"id":5300820},{"trd":[[1.72,10.55]],"batl":[[0,1.72,29.48]],"ltp":1.72,"tv":6159.82,"id":9629022}],"tv":20822.65}]}
{"op":"mcm","clk":"4215067646","pt":1631534258406,"mc":[{"id":"1.187557985","rc":[{"batl":[[2,2.68,5.64]],"ltp":2.38,"tv":14662.82,"id":5300820},{"batl":[[2,1.8,29.52]],"ltp":1.72,"tv":6159.82,"id":9629022}]}]}
{"op":"mcm","clk":"4215067742","pt":1631534259503,"mc":[{"id":"1.187557985","rc":[{"batb":[[0,1.67,354.17],[2,1.65,1155.43]],"batl":[[1,1.73,179.12],[2,1.75,213.17]],"ltp":1.72,"tv":6159.82,"id":9629022}]}]}
{"op":"mcm","clk":"4215067839","pt":1631534260604,"mc":[{"id":"1.187557985","rc":[{"batl":[[0,2.52,66.34]],"ltp":2.38,"tv":14662.82,"id":5300820}]}]}
{"op":"mcm","clk":"4215068159","pt":1631534264514,"mc":[{"id":"1.187557985","rc":[{"trd":[[1.67,14.42]],"batb":[[0,1.67,350.17]],"ltp":1.67,"tv":6167.82,"id":9629022}],"tv":20830.65}]}
{"op":"mcm","clk":"4215068242","pt":1631534265403,"mc":[{"id":"1.187557985","rc":[{"batb":[[0,2.32,22.72],[1,2.24,5.77],[2,2.16,6.78]],"batl":[[0,2.52,24.33]],"ltp":2.38,"tv":14662.82,"id":5300820},{"batb":[[0,1.65,37.21],[1,1.6,52.19],[2,1.58,131.63]],"batl":[[0,1.76,7.5],[1,1.8,29.52],[2,1.86,28.25]],"ltp":1.67,"tv":6167.82,"id":9629022}]}]}
{"op":"mcm","clk":"4215068338","pt":1631534266445,"mc":[{"id":"1.187557985","rc":[{"batb":[[0,2.24,5.77],[1,2.16,6.78],[2,2.14,104.1]],"batl":[[0,2.58,50],[1,2.8,8.77],[2,2.94,4.25]],"ltp":2.38,"tv":14662.82,"id":5300820},{"batb":[[0,1.58,131.63],[1,1.56,58.08],[2,1.52,55.74]],"batl":[[0,1.8,29.52],[1,1.86,28.25],[2,1.89,26.5]],"ltp":1.67,"tv":6167.82,"id":9629022}]}]}
{"op":"mcm","clk":"4215068369","pt":1631534266710,"mc":[{"id":"1.187557985","rc":[{"batb":[[0,2.16,6.78],[1,2.14,104.1],[2,2.12,7.54]],"ltp":2.38,"tv":14662.82,"id":5300820},{"batl":[[0,1.86,28.25],[1,1.89,26.5],[2,1.89,0]],"ltp":1.67,"tv":6167.82,"id":9629022}]}]}
{"op":"mcm","clk":"4215068525","pt":1631534268323,"mc":[{"id":"1.187557985","rc":[{"batl":[[0,2.8,8.77],[1,2.94,4.25],[2,3.45,182.89]],"ltp":2.38,"tv":14662.82,"id":5300820},{"batb":[[0,1.58,376],[1,1.57,156.21],[2,1.56,58.08]],"batl":[[1,1.87,147.51],[2,1.89,193.62]],"ltp":1.67,"tv":6167.82,"id":9629022}]}]}
{"op":"mcm","clk":"4215068629","pt":1631534269623,"mc":[{"id":"1.187557985","rc":[{"batl":[[1,1.89,26.5],[2,1.89,0]],"ltp":1.67,"tv":6167.82,"id":9629022}]}]}
{"op":"mcm","clk":"4215068672","pt":1631534270202,"mc":[{"id":"1.187557985","rc":[{"batl":[[0,1.86,33.25]],"ltp":1.67,"tv":6167.82,"id":9629022}]}]}
{"op":"mcm","clk":"4215068739","pt":1631534271139,"mc":[{"id":"1.187557985","rc":[{"batl":[[0,2.74,4],[1,2.8,8.77],[2,2.94,4.25]],"ltp":2.38,"tv":14662.82,"id":5300820},{"batb":[[0,1.58,382],[1,1.57,161.21]],"ltp":1.67,"tv":6167.82,"id":9629022}]}]}
{"op":"mcm","clk":"4215068845","pt":1631534272551,"mc":[{"id":"1.187557985","rc":[{"batb":[[0,2.18,914.12],[1,2.16,6.78],[2,2.14,104.1]],"batl":[[0,2.8,4.77],[1,2.94,4.25],[2,100,0.96]],"ltp":2.38,"tv":14662.82,"id":5300820},{"batb":[[0,1.58,376],[1,1.57,156.21],[2,1.56,53.08]],"batl":[[0,1.63,2163.95],[1,1.64,132.04],[2,1.65,1159.1]],"ltp":1.67,"tv":6167.82,"id":9629022}]}]}
{"op":"mcm","clk":"4215068952","pt":1631534273646,"mc":[{"id":"1.187557985","rc":[{"trd":[[2.58,34.96]],"batb":[[0,2.58,62.93],[1,2.5,20],[2,2.34,81.42]],"batl":[[0,2.78,22.48],[1,2.8,4.77],[2,2.94,4.25]],"ltp":2.58,"tv":14671.83,"id":5300820},{"trd":[[1.63,117.84]],"batb":[[2,1.56,93.16]],"batl":[[0,1.63,183.26]],"ltp":1.63,"tv":6182.08,"id":9629022}],"tv":20853.92}]}
{"op":"mcm","clk":"4215069276","pt":1631534277459,"mc":[{"id":"1.187557985","rc":[{"trd":[[2.58,50.76]],"batb":[[0,2.58,55.03]],"ltp":2.58,"tv":14687.63,"id":5300820}],"tv":20869.72}]}
{"op":"mcm","clk":"4215069386","pt":1631534278615,"mc":[{"id":"1.187557985","rc":[{"batb":[[0,2.58,88.93],[1,2.46,5.88],[2,2.38,5.96]],"batl":[[2,2.9,4.05]],"ltp":2.58,"tv":14687.63,"id":5300820}]}]}
{"op":"mcm","clk":"4215069426","pt":1631534279031,"mc":[{"id":"1.187557985","rc":[{"batl":[[0,2.76,23.85],[1,2.78,22.48],[2,2.8,4.77]],"ltp":2.58,"tv":14687.63,"id":5300820}]}]}
{"op":"mcm","clk":"4215069550","pt":1631534280618,"mc":[{"id":"1.187557985","rc":[{"batl":[[2,1.65,1166.6]],"ltp":1.63,"tv":6182.08,"id":9629022}]}]}
{"op":"mcm","clk":"4215069660","pt":1631534281841,"mc":[{"id":"1.187557985","rc":[{"batb":[[1,2.54,19.48],[2,2.46,5.88]],"ltp":2.58,"tv":14687.63,"id":5300820}]}]}
{"op":"mcm","clk":"4215069865","pt":1631534284368,"mc":[{"id":"1.187557985","rc":[{"batl":[[0,1.63,178.64]],"ltp":1.63,"tv":6182.08,"id":9629022}]}]}
{"op":"mcm","clk":"4215070135","pt":1631534287544,"mc":[{"id":"1.187557985","rc":[{"batb":[[0,2.58,55.03]],"batl":[[0,2.78,22.48],[1,2.9,4.05],[2,2.94,4.25]],"ltp":2.58,"tv":14687.63,"id":5300820},{"batb":[[2,1.56,40.08]],"batl":[[2,1.65,7.5]],"ltp":1.63,"tv":6182.08,"id":9629022}]}]}
{"op":"mcm","clk":"4215070174","pt":1631534287978,"mc":[{"id":"1.187557985","rc":[{"batb":[[0,2.54,19.48],[1,2.38,5.96],[2,2.34,81.42]],"batl":[[1,3.05,4.1],[2,3.9,160.43]],"ltp":2.58,"tv":14687.63,"id":5300820},{"batb":[[0,1.56,40.08],[1,1.5,159.91],[2,1.49,52.01]],"batl":[[0,1.65,7.5],[1,1.72,39.16],[2,1.86,33.25]],"ltp":1.63,"tv":6182.08,"id":9629022}]}]}
{"op":"mcm","clk":"4215070297","pt":1631534289452,"mc":[{"id":"1.187557985","rc":[{"batb":[[0,2.38,5.96],[1,2.34,81.42],[2,2.16,6.78]],"batl":[[0,3.05,4.1],[1,3.9,160.43],[2,3.9,0]],"ltp":2.58,"tv":14687.63,"id":5300820},{"batb":[[0,1.5,159.91],[1,1.49,52.01],[2,1.48,52.01]],"batl":[[0,1.72,39.16],[1,1.86,33.25],[2,1.89,26.5]],"ltp":1.63,"tv":6182.08,"id":9629022}]}]}
{"op":"mcm","clk":"4215070458","pt":1631534291351,"mc":[{"id":"1.187557985","rc":[{"batb":[[0,1.51,193.86],[1,1.5,346.1],[2,1.49,52.01]],"batl":[[1,1.75,214.7],[2,1.77,205.24]],"ltp":1.63,"tv":6182.08,"id":9629022}]}]}
{"op":"mcm","clk":"4215070565","pt":1631534292662,"mc":[{"id":"1.187557985","rc":[{"batl":[[0,3,2.96],[1,3.05,4.1],[2,3.9,160.43]],"ltp":2.58,"tv":14687.63,"id":5300820},{"batb":[[1,1.5,353.1],[2,1.49,57.01]],"ltp":1.63,"tv":6182.08,"id":9629022}]}]}
{"op":"mcm","clk":"4215070715","pt":1631534294548,"mc":[{"id":"1.187557985","rc":[{"batb":[[0,2.46,5.51],[1,2.38,5.96],[2,2.34,81.42]],"batl":[[0,2.9,9.41],[1,2.98,3],[2,3,2]],"ltp":2.58,"tv":14687.63,"id":5300820},{"batb":[[0,1.53,59.33],[1,1.52,6],[2,1.51,199.86]],"batl":[[0,1.68,36.39],[1,1.72,39.16],[2,1.75,214.7]],"ltp":1.63,"tv":6182.08,"id":9629022}]}]}
{"op":"mcm","clk":"4215070736","pt":1631534294759,"mc":[{"id":"1.187557985","rc":[{"batb":[[0,2.38,5.96],[1,2.34,81.42],[2,2.16,6.78]],"batl":[[0,2.9,4.96]],"ltp":2.58,"tv":14687.63,"id":5300820},{"batb":[[0,1.53,6]],"batl":[[0,1.72,39.16],[1,1.75,214.7],[2,1.77,205.24]],"ltp":1.63,"tv":6182.08,"id":9629022}]}]}
{"op":"mcm","clk":"4215070945","pt":1631534297396,"mc":[{"id":"1.187557985","rc":[{"batb":[[2,2.04,399.53]],"ltp":2.58,"tv":14687.63,"id":5300820},{"batl":[[1,1.86,5],[2,1.77,0]],"ltp":1.63,"tv":6182.08,"id":9629022}]}]}
{"op":"mcm","clk":"4215071145","pt":1631534299453,"mc":[{"id":"1.187557985","rc":[{"trd":[[2.62,0.96]],"batl":[[0,2.9,4]],"ltp":2.62,"tv":14688.59,"id":5300820},{"trd":[[1.61,1.57]],"ltp":1.61,"tv":6183.65,"id":9629022}],"tv":20872.25}]}
{"op":"mcm","clk":"4215071243","pt":1631534300568,"mc":[{"id":"1.187557985","rc":[{"batb":[[0,2.48,852.04],[1,2.38,5.96],[2,2.34,81.42]],"batl":[[0,3.05,4.1],[1,3.9,160.43],[2,3,0]],"ltp":2.62,"tv":14688.59,"id":5300820},{"batb":[[0,1.51,193.86],[1,1.5,346.1],[2,1.49,52.01]],"batl":[[0,1.55,182.25],[1,1.56,1384.11],[2,1.57,1189.9]],"ltp":1.61,"tv":6183.65,"id":9629022}]}]}
{"op":"mcm","clk":"4215071328","pt":1631534301470,"mc":[{"id":"1.187557985","rc":[{"trd":[[2.8,8.47]],"batb":[[0,2.82,49.96],[1,2.6,61.34],[2,2.38,5.96]],"ltp":2.8,"tv":14697.06,"id":5300820},{"trd":[[1.55,15.3]],"batl":[[0,1.55,166.95],[2,1.57,1197.4]],"ltp":1.55,"tv":6198.95,"id":9629022}],"tv":20896.02}]}
{"op":"mcm","clk":"4215071428","pt":1631534302362,"mc":[{"id":"1.187557985","rc":[{"batb":[[1,2.78,16.85],[2,2.6,61.34]],"batl":[[1,3.1,20.7],[2,3.9,160.43]],"ltp":2.8,"tv":14697.06,"id":5300820}]}]}
{"op":"mcm","clk":"4215071511","pt":1631534303256,"mc":[{"id":"1.187557985","rc":[{"batb":[[1,2.8,3],[2,2.78,19.85]],"batl":[[0,3.05,24.6]],"ltp":2.8,"tv":14697.06,"id":5300820}]}]}
{"op":"mcm","clk":"4215071602","pt":1631534304201,"mc":[{"id":"1.187557985","rc":[{"batl":[[2,1.57,1189.9]],"ltp":1.55,"tv":6198.95,"id":9629022}]}]}
{"op":"mcm","clk":"4215071743","pt":1631534305478,"mc":[{"id":"1.187557985","rc":[{"batb":[[0,2.82,79.76]],"ltp":2.8,"tv":14697.06,"id":5300820},{"batl":[[0,1.55,313.57]],"ltp":1.55,"tv":6198.95,"id":9629022}]}]}
{"op":"mcm","clk":"4215071851","pt":1631534306469,"mc":[{"id":"1.187557985","rc":[{"batb":[[2,2.78,3]],"ltp":2.8,"tv":14697.06,"id":5300820},{"batl":[[0,1.55,200.55]],"ltp":1.55,"tv":6198.95,"id":9629022}]}]}
{"op":"mcm","clk":"4215071927","pt":1631534307361,"mc":[{"id":"1.187557985","rc":[{"batl":[[1,3.1,24.75],[2,3.25,4.06]],"ltp":2.8,"tv":14697.06,"id":5300820},{"batl":[[0,1.55,208.05],[2,1.57,1241.4]],"ltp":1.55,"tv":6198.95,"id":9629022}]}]}
{"op":"mcm","clk":"4215071989","pt":1631534308087,"mc":[{"id":"1.187557985","rc":[{"batb":[[0,1.52,5],[1,1.51,193.86],[2,1.5,346.1]],"ltp":1.55,"tv":6198.95,"id":9629022}]}]}
{"op":"mcm","clk":"4215072127","pt":1631534309825,"mc":[{"id":"1.187557985","rc":[{"batb":[[0,2.82,96.24]],"ltp":2.8,"tv":14697.06,"id":5300820}]}]}
{"op":"mcm","clk":"4215072307","pt":1631534312282,"mc":[{"id":"1.187557985","rc":[{"trd":[[1.5,402.28],[1.51,387.72],[1.52,10]],"batb":[[0,1.5,144.96],[1,1.49,52.01],[2,1.48,762.73]],"ltp":1.5,"tv":6998.96,"id":9629022}],"tv":21696.02}]}
{"op":"mcm","clk":"4215072385","pt":1631534313207,"mc":[{"id":"1.187557985","rc":[{"batl":[[1,1.56,1225.96]],"ltp":1.5,"tv":6998.96,"id":9629022}]}]}
{"op":"mcm","clk":"4215072586","pt":1631534315583,"mc":[{"id":"1.187557985","rc":[{"batb":[[0,2.82,66.44],[2,2.74,5.02]],"batl":[[0,3.05,4.1]],"ltp":2.8,"tv":14697.06,"id":5300820},{"batb":[[2,1.48,52.01]],"batl":[[0,1.55,174.45],[1,1.57,51.5],[2,1.59,44.5]],"ltp":1.5,"tv":6998.96,"id":9629022}]}]}
{"op":"mcm","clk":"4215072657","pt":1631534316416,"mc":[{"id":"1.187557985","rc":[{"batb":[[0,2.82,16.48],[1,2.74,5.02],[2,2.68,4.86]],"batl":[[0,3.1,24.75],[1,3.25,4.06],[2,3.9,160.43]],"ltp":2.8,"tv":14697.06,"id":5300820},{"batb":[[0,1.48,52.01],[1,1.47,43.75],[2,1.45,242.14]],"batl":[[0,1.55,7.5]],"ltp":1.5,"tv":6998.96,"id":9629022}]}]}
{"op":"mcm","clk":"4215072759","pt":1631534317436,"mc":[{"id":"1.187557985","rc":[{"batb":[[0,2.68,4.86],[1,2.6,61.34],[2,2.38,5.96]],"batl":[[0,3.25,4.06],[1,3.9,160.43],[2,3.9,0]],"ltp":2.8,"tv":14697.06,"id":5300820},{"batb":[[0,1.45,242.14],[1,1.43,3.41],[2,1.37,4]],"batl":[[0,1.59,44.5],[1,1.71,5],[2,1.72,39.16]],"ltp":1.5,"tv":6998.96,"id":9629022}]}]}
{"op":"mcm","clk":"4215072874","pt":1631534318608,"mc":[{"id":"1.187557985","rc":[{"batl":[[0,3,3],[1,3.25,4.06],[2,3.9,160.43]],"ltp":2.8,"tv":14697.06,"id":5300820},{"batb":[[0,1.5,6],[1,1.49,7],[2,1.45,242.14]],"ltp":1.5,"tv":6998.96,"id":9629022}]}]}
{"op":"mcm","clk":"4215072956","pt":1631534319601,"mc":[{"id":"1.187557985","rc":[{"batb":[[1,2.64,59.5]],"batl":[[0,3.1,3]],"ltp":2.8,"tv":14697.06,"id":5300820},{"batb":[[0,1.48,6],[1,1.47,6],[2,1.45,403.45]],"batl":[[1,1.62,257.39],[2,1.63,135.15]],"ltp":1.5,"tv":6998.96,"id":9629022}]}]}
{"op":"mcm","clk":"4215073044","pt":1631534320612,"mc":[{"id":"1.187557985","rc":[{"batl":[[0,3.15,3]],"ltp":2.8,"tv":14697.06,"id":5300820},{"batb":[[0,1.46,7],[1,1.45,408.45],[2,1.44,415.36]],"ltp":1.5,"tv":6998.96,"id":9629022}]}]}
{"op":"mcm","clk":"4215073052","pt":1631534320706,"mc":[{"id":"1.187557985","rc":[{"batl":[[1,3.25,7.06]],"ltp":2.8,"tv":14697.06,"id":5300820}]}]}
{"op":"mcm","clk":"4215073187","pt":1631534322492,"mc":[{"id":"1.187557985","rc":[{"batl":[[0,3.05,3],[1,3.15,3],[2,3.25,7.06]],"ltp":2.8,"tv":14697.06,"id":5300820},{"batb":[[1,1.45,63.21],[2,1.44,192.53]],"ltp":1.5,"tv":6998.96,"id":9629022}]}]}
{"op":"mcm","clk":"4215073273","pt":1631534323528,"mc":[{"id":"1.187557985","rc":[{"batb":[[0,2.74,5.02],[1,2.68,4.86],[2,2.64,59.5]],"batl":[[1,3.1,4.45],[2,3.15,3]],"ltp":2.8,"tv":14697.06,"id":5300820},{"batb":[[0,1.48,53.01],[1,1.46,7],[2,1.45,63.21]],"batl":[[0,1.57,45.5],[1,1.59,44.5],[2,1.62,257.39]],"ltp":1.5,"tv":6998.96,"id":9629022}]}]}
{"op":"mcm","clk":"4215073356","pt":1631534324435,"mc":[{"id":"1.187557985","rc":[{"batb":[[0,2.68,4.86],[1,2.64,59.5],[2,2.38,5.96]],"batl":[[1,3.15,3],[2,3.2,3]],"ltp":2.8,"tv":14697.06,"id":5300820},{"batb":[[0,1.46,7],[1,1.45,63.21],[2,1.44,192.53]],"batl":[[0,1.59,44.5],[1,1.62,257.39],[2,1.63,135.15]],"ltp":1.5,"tv":6998.96,"id":9629022}]}]}
{"op":"mcm","clk":"4215073468","pt":1631534325628,"mc":[{"id":"1.187557985","rc":[{"trd":[[2.68,13.71]],"batb":[[0,2.64,59.5],[1,2.38,5.96],[2,2.04,399.53]],"batl":[[0,2.8,683.04],[1,2.82,662.94],[2,2.84,662.94]],"ltp":2.68,"tv":14710.77,"id":5300820},{"trd":[[1.59,266.14]],"batb":[[0,1.57,179.53],[1,1.56,160.36],[2,1.54,57.12]],"batl":[[0,1.59,37.77]],"ltp":1.59,"tv":7005.69,"id":9629022}],"tv":21716.46}]}
{"op":"mcm","clk":"4215073538","pt":1631534326431,"mc":[{"id":"1.187557985","rc":[{"batb":[[1,2.58,18.98],[2,2.38,5.96]],"ltp":2.68,"tv":14710.77,"id":5300820},{"batb":[[1,1.56,298.68],[2,1.54,97.94]],"ltp":1.59,"tv":7005.69,"id":9629022}]}]}
{"op":"mcm","clk":"4215073729","pt":1631534328630,"mc":[{"id":"1.187557985","rc":[{"batb":[[1,2.6,4],[2,2.58,21.98]],"ltp":2.68,"tv":14710.77,"id":5300820}]}]}
{"op":"mcm","clk":"4215073895","pt":1631534330616,"mc":[{"id":"1.187557985","rc":[{"trd":[[2.68,14.84]],"ltp":2.68,"tv":14711.9,"id":5300820},{"trd":[[1.59,271.89]],"batb":[[0,1.57,257.53],[2,1.54,57.12]],"batl":[[0,1.59,33.95]],"ltp":1.59,"tv":7011.43,"id":9629022}],"tv":21723.33}]}
{"op":"mcm","clk":"4215073939","pt":1631534331238,"mc":[{"id":"1.187557985","rc":[{"batl":[[0,2.78,17.59],[1,2.8,683.04],[2,2.82,662.94]],"ltp":2.68,"tv":14711.9,"id":5300820}]}]}
{"op":"mcm","clk":"4215074152","pt":1631534333590,"mc":[{"id":"1.187557985","rc":[{"batl":[[2,2.82,685.17]],"ltp":2.68,"tv":14711.9,"id":5300820},{"batb":[[2,1.55,40.45]],"ltp":1.59,"tv":7011.43,"id":9629022}]}]}
{"op":"mcm","clk":"4215074190","pt":1631534334021,"mc":[{"id":"1.187557985","rc":[{"batb":[[1,2.58,21.98],[2,2.48,6.51]],"ltp":2.68,"tv":14711.9,"id":5300820}]}]}
{"op":"mcm","clk":"4215074780","pt":1631534341620,"mc":[{"id":"1.187557985","rc":[{"batb":[[0,2.58,18.98],[1,2.38,5.96],[2,2.36,188.45]],"batl":[[0,2.82,22.23],[1,3,175.15],[2,3.05,163.81]],"ltp":2.68,"tv":14711.9,"id":5300820},{"batb":[[0,1.55,40.45],[1,1.5,314.65],[2,1.49,344.88]],"batl":[[0,1.64,7.5],[1,1.71,5],[2,1.72,39.16]],"ltp":1.59,"tv":7011.43,"id":9629022}]}]}
{"op":"mcm","clk":"4215074831","pt":1631534342468,"mc":[{"id":"1.187557985","rc":[{"batb":[[0,2.38,5.96],[1,2.36,188.45],[2,2.34,311.99]],"batl":[[0,3,175.15],[1,3.05,163.81],[2,3.1,199.44]],"ltp":2.68,"tv":14711.9,"id":5300820},{"batb":[[0,1.5,314.65],[1,1.49,344.88],[2,1.48,488.25]],"batl":[[0,1.71,5],[1,1.72,39.16],[2,1.74,261.35]],"ltp":1.59,"tv":7011.43,"id":9629022}]}]}
{"op":"mcm","clk":"4215075008","pt":1631534344617,"mc":[{"id":"1.187557985","rc":[{"batb":[[2,1.48,747.1]],"ltp":1.59,"tv":7011.43,"id":9629022}]}]}
{"op":"mcm","clk":"4215075079","pt":1631534345608,"mc":[{"id":"1.187557985","rc":[{"batb":[[0,2.4,3],[1,2.38,9.96],[2,2.36,188.45]],"ltp":2.68,"tv":14711.9,"id":5300820},{"batb":[[0,1.5,320.65],[1,1.49,349.88]],"ltp":1.59,"tv":7011.43,"id":9629022}]}]}
{"op":"mcm","clk":"4215075088","pt":1631534345715,"mc":[{"id":"1.187557985","rc":[{"batl":[[0,3,178.15]],"ltp":2.68,"tv":14711.9,"id":5300820},{"batb":[[2,1.48,488.25]],"ltp":1.59,"tv":7011.43,"id":9629022}]}]}
{"op":"mcm","clk":"4215075332","pt":1631534348757,"mc":[{"id":"1.187557985","rc":[{"batb":[[0,1.59,230.37],[1,1.58,153.07],[2,1.5,320.65]],"batl":[[0,1.64,180.94],[1,1.65,129.8],[2,1.71,5]],"ltp":1.59,"tv":7011.43,"id":9629022}]}]}
{"op":"mcm","clk":"4215075463","pt":1631534350333,"mc":[{"id":"1.187557985","rc":[{"batb":[[0,2.42,15],[1,2.4,3],[2,2.38,9.96]],"batl":[[0,2.98,64.89],[1,3,178.15],[2,3.05,163.81]],"ltp":2.68,"tv":14711.9,"id":5300820},{"batb":[[2,1.51,121.9]],"batl":[[2,1.7,25]],"ltp":1.59,"tv":7011.43,"id":9629022}]}]}
{"op":"mcm","clk":"4215075590","pt":1631534352165,"mc":[{"id":"1.187557985","rc":[{"batb":[[0,2.48,6.26]],"ltp":2.68,"tv":14711.9,"id":5300820},{"batl":[[2,1.67,36.5]],"ltp":1.59,"tv":7011.43,"id":9629022}]}]}
{"op":"mcm","clk":"4215075752","pt":1631534354253,"mc":[{"id":"1.187557985","rc":[{"batb":[[0,2.4,3],[1,2.38,9.96],[2,2.36,188.45]],"batl":[[0,3,178.15],[1,3.05,163.81],[2,3.1,199.44]],"ltp":2.68,"tv":14711.9,"id":5300820},{"batb":[[0,1.5,320.65],[1,1.49,349.88],[2,1.48,488.25]],"batl":[[0,1.71,5],[1,1.72,39.16],[2,1.74,261.35]],"ltp":1.59,"tv":7011.43,"id":9629022}]}]}
{"op":"mcm","clk":"4215076006","pt":1631534357664,"mc":[{"id":"1.187557985","rc":[{"batb":[[0,2.48,6.01],[1,2.4,3],[2,2.38,5.96]],"batl":[[0,3,3],[1,3.1,4.45],[2,3.25,4.06]],"ltp":2.68,"tv":14711.9,"id":5300820},{"batb":[[0,1.5,6],[1,1.48,320.99],[2,1.47,378.07]],"batl":[[0,1.67,36.5],[1,1.71,5],[2,1.72,39.16]],"ltp":1.59,"tv":7011.43,"id":9629022}]}]}
{"op":"mcm","clk":"4215076028","pt":1631534357927,"mc":[{"id":"1.187557985","rc":[{"batb":[[0,2.4,3],[1,2.38,5.96],[2,2.36,188.45]],"batl":[[1,3.25,4.06],[2,3.35,3.7]],"ltp":2.68,"tv":14711.9,"id":5300820},{"batb":[[1,1.47,174.47],[2,1.45,58.21]],"batl":[[0,1.71,5],[1,1.72,39.16],[2,1.74,261.35]],"ltp":1.59,"tv":7011.43,"id":9629022}]}]}
{"op":"mcm","clk":"4215076169","pt":1631534359660,"mc":[{"id":"1.187557985","rc":[{"batb":[[0,2.38,5.96],[1,2.36,188.45],[2,2.34,311.99]],"ltp":2.68,"tv":14711.9,"id":5300820},{"batl":[[0,1.72,39.16],[1,1.74,261.35],[2,1.75,439.83]],"ltp":1.59,"tv":7011.43,"id":9629022}]}]}
{"op":"mcm","clk":"4215076249","pt":1631534360652,"mc":[{"id":"1.187557985","rc":[{"trd":[[2.38,36.28]],"batb":[[0,2.36,188.45],[1,2.34,311.99],[2,2.32,226.74]],"batl":[[0,2.48,771.18],[1,2.5,748.48],[2,2.52,748.48]],"ltp":2.38,"tv":14727.48,"id":5300820},{"trd":[[1.72,15.61]],"batb":[[0,1.62,65.04],[1,1.52,1076.79],[2,1.5,6]],"batl":[[0,1.72,34.1]],"ltp":1.72,"tv":7016.49,"id":9629022}],"tv":21743.97}]}
{"op":"mcm","clk":"4215076345","pt":1631534361654,"mc":[{"id":"1.187557985","rc":[{"batb":[[2,2.32,249.46]],"ltp":2.38,"tv":14727.48,"id":5300820},{"batb":[[0,1.69,335.48],[1,1.67,248.9],[2,1.64,37.5]],"ltp":1.72,"tv":7016.49,"id":9629022}]}]}
{"op":"mcm","clk":"4215076580","pt":1631534364425,"mc":[{"id":"1.187557985","rc":[{"batb":[[2,1.62,65.04]],"ltp":1.72,"tv":7016.49,"id":9629022}]}]}
{"op":"mcm","clk":"4215076664","pt":1631534365633,"mc":[{"id":"1.187557985","rc":[{"trd":[[2.38,42.3]],"ltp":2.38,"tv":14733.5,"id":5300820},{"trd":[[1.72,27.5]],"batb":[[0,1.69,408.48]],"batl":[[0,1.72,23.99]],"ltp":1.72,"tv":7028.38,"id":9629022}],"tv":21761.88}]}
{"op":"mcm","clk":"4215076725","pt":1631534366574,"mc":[{"id":"1.187557985","rc":[{"batl":[[0,2.46,20.96],[1,2.48,771.18],[2,2.5,748.48]],"ltp":2.38,"tv":14733.5,"id":5300820}]}]}
{"op":"mcm","clk":"4215076892","pt":1631534368634,"mc":[{"id":"1.187557985","rc":[{"batb":[[2,1.66,36.92]],"ltp":1.72,"tv":7028.38,"id":9629022}]}]}
{"op":"mcm","clk":"4215077506","pt":1631534376558,"mc":[{"id":"1.187557985","rc":[{"trd":[[2.38,42.49]],"ltp":2.38,"tv":14733.69,"id":5300820},{"trd":[[1.72,27.77]],"batl":[[0,1.72,23.72]],"ltp":1.72,"tv":7028.65,"id":9629022}],"tv":21762.34}]}
{"op":"mcm","clk":"4215077676","pt":1631534378761,"mc":[{"id":"1.187557985","rc":[{"trd":[[1.72,32.41]],"batl":[[0,1.72,21.4]],"ltp":1.72,"tv":7033.29,"id":9629022}],"tv":21766.99}]}
{"op":"mcm","clk":"4215078257","pt":1631534386579,"mc":[{"id":"1.187557985","rc":[{"batb":[[0,2.32,22.72],[1,2.1,185.82],[2,2.08,366.52]],"batl":[[0,2.52,24.33],[1,2.7,144.63],[2,2.72,175.51]],"ltp":2.38,"tv":14733.69,"id":5300820},{"batb":[[0,1.66,36.92],[1,1.59,286.66],[2,1.58,291.54]],"batl":[[0,1.76,7.5],[1,1.91,190.83],[2,1.92,258.58]],"ltp":1.72,"tv":7033.29,"id":9629022}]}]}
{"op":"mcm","clk":"4215078323","pt":1631534387416,"mc":[{"id":"1.187557985","rc":[{"batb":[[0,2.1,185.82],[1,2.08,366.52],[2,2.06,245.95]],"batl":[[0,2.38,10]],"ltp":2.38,"tv":14733.69,"id":5300820},{"batb":[[0,1.59,286.66],[1,1.58,291.54],[2,1.57,484.4]],"batl":[[0,1.91,190.83],[1,1.92,258.58],[2,1.93,324.73]],"ltp":1.72,"tv":7033.29,"id":9629022}]}]}
{"op":"mcm","clk":"4215078477","pt":1631534389488,"mc":[{"id":"1.187557985","rc":[{"batb":[[1,1.58,457.92],[2,1.57,640.88]],"batl":[[2,1.93,463.82]],"ltp":1.72,"tv":7033.29,"id":9629022}]}]}
{"op":"mcm","clk":"4215078565","pt":1631534390596,"mc":[{"id":"1.187557985","rc":[{"batb":[[0,2.1,189.82],[1,2.08,369.52]],"ltp":2.38,"tv":14733.69,"id":5300820},{"batl":[[0,1.91,194.83]],"ltp":1.72,"tv":7033.29,"id":9629022}]}]}
{"op":"mcm","clk":"4215079011","pt":1631534396537,"mc":[{"id":"1.187557985","rc":[{"batl":[[1,2.86,5.25],[2,2.98,2]],"ltp":2.38,"tv":14733.69,"id":5300820},{"batb":[[0,1.57,135.23],[1,1.54,71.12],[2,1.51,5]],"ltp":1.72,"tv":7033.29,"id":9629022}]}]}
{"op":"mcm","clk":"4215079180","pt":1631534398540,"mc":[{"id":"1.187557985","rc":[{"batb":[[0,2.1,185.82],[1,2.08,366.52]],"ltp":2.38,"tv":14733.69,"id":5300820},{"batl":[[0,1.91,190.83]],"ltp":1.72,"tv":7033.29,"id":9629022}]}]}
{"op":"mcm","clk":"4215079280","pt":1631534399658,"mc":[{"id":"1.187557985","rc":[{"trd":[[2.1,21.06]],"batb":[[0,2.1,175.29]],"batl":[[0,2.3,18.85],[1,2.38,10],[2,2.86,5.25]],"ltp":2.1,"tv":14754.75,"id":5300820},{"batb":[[0,1.86,190.31],[1,1.84,1219.17],[2,1.83,1008.82]],"ltp":1.72,"tv":7033.29,"id":9629022}],"tv":21788.05}]}
{"op":"mcm","clk":"4215079362","pt":1631534400559,"mc":[{"id":"1.187557985","rc":[{"batb":[[0,2.1,202.56]],"batl":[[0,2.3,45.16],[1,2.34,259.13],[2,2.38,10]],"ltp":2.1,"tv":14754.75,"id":5300820},{"batb":[[0,1.86,266.63]],"batl":[[0,1.9,7.5],[1,1.91,190.83],[2,1.92,258.58]],"ltp":1.72,"tv":7033.29,"id":9629022}]}]}
{"op":"mcm","clk":"4215079444","pt":1631534401533,"mc":[{"id":"1.187557985","rc":[{"batl":[[2,2.36,4]],"ltp":2.1,"tv":14754.75,"id":5300820}]}]}
{"op":"mcm","clk":"4215079715","pt":1631534404645,"mc":[{"id":"1.187557985","rc":[{"trd":[[2.1,37.19]],"batb":[[0,2.1,194.49]],"batl":[[0,2.28,62.89],[1,2.3,45.16],[2,2.34,259.13]],"ltp":2.1,"tv":14770.88,"id":5300820},{"trd":[[1.9,3.26]],"batl":[[0,1.9,5.87]],"ltp":1.9,"tv":7036.55,"id":9629022}],"tv":21807.44}]}
{"op":"mcm","clk":"4215079778","pt":1631534405540,"mc":[{"id":"1.187557985","rc":[{"batl":[[2,2.36,4]],"ltp":2.1,"tv":14770.88,"id":5300820}]}]}
{"op":"mcm","clk":"4215079950","pt":1631534407435,"mc":[{"id":"1.187557985","rc":[{"batl":[[1,1.91,214.96]],"ltp":1.9,"tv":7036.55,"id":9629022}]}]}
{"op":"mcm","clk":"4215080053","pt":1631534408544,"mc":[{"id":"1.187557985","rc":[{"trd":[[2.08,180.66],[2.1,429.1]],"batb":[[0,2.08,276.16],[1,2.06,245.95],[2,1.87,79.25]],"ltp":2.08,"tv":15343.45,"id":5300820},{"trd":[[1.9,11.73]],"batl":[[0,1.91,214.96],[1,1.92,258.58],[2,1.93,463.82]],"ltp":1.9,"tv":7045.03,"id":9629022}],"tv":22388.48}]}
{"op":"mcm","clk":"4215080144","pt":1631534409657,"mc":[{"id":"1.187557985","rc":[{"batl":[[1,2.3,18.85]],"ltp":2.08,"tv":15343.45,"id":5300820},{"batl":[[0,1.91,190.83]],"ltp":1.9,"tv":7045.03,"id":9629022}]}]}
{"op":"mcm","clk":"4215080173","pt":1631534410076,"mc":[{"id":"1.187557985","rc":[{"trd":[[1.86,6.82]],"batb":[[0,1.86,263.22]],"ltp":1.86,"tv":7051.84,"id":9629022}],"tv":22395.3}]}
{"op":"mcm","clk":"4215080383","pt":1631534412576,"mc":[{"id":"1.187557985","rc":[{"batb":[[2,2.02,29.41]],"batl":[[0,2.24,26.94]],"ltp":2.08,"tv":15343.45,"id":5300820}]}]}
{"op":"mcm","clk":"4215080459","pt":1631534413475,"mc":[{"id":"1.187557985","rc":[{"batl":[[0,2.1,100],[1,2.24,26.94],[2,2.3,18.85]],"ltp":2.08,"tv":15343.45,"id":5300820},{"batl":[[0,1.92,258.58],[1,1.93,463.82],[2,1.95,152.44]],"ltp":1.86,"tv":7051.84,"id":9629022}]}]}
{"op":"mcm","clk":"4215080519","pt":1631534414272,"mc":[{"id":"1.187557985","rc":[{"batb":[[0,2.02,29.41],[1,1.87,79.25],[2,1.86,404.12]],"batl":[[2,2.36,4]],"ltp":2.08,"tv":15343.45,"id":5300820},{"batb":[[0,1.82,33.12],[1,1.81,5],[2,1.71,224.5]],"batl":[[0,2.18,160.02],[1,2.2,189.72],[2,2.22,274.39]],"ltp":1.86,"tv":7051.84,"id":9629022}]}]}
{"op":"mcm","clk":"4215080619","pt":1631534415582,"mc":[{"id":"1.187557985","rc":[{"batb":[[0,1.87,79.25],[1,1.86,404.12],[2,1.85,248.83]],"batl":[[1,2.38,10],[2,2.42,196.9]],"ltp":2.08,"tv":15343.45,"id":5300820},{"batb":[[0,1.71,224.5],[1,1.7,340.02],[2,1.69,474.91]],"ltp":1.86,"tv":7051.84,"id":9629022}]}]}
{"op":"mcm","clk":"4215080789","pt":1631534417594,"mc":[{"id":"1.187557985","rc":[{"batb":[[0,1.86,485.13],[1,1.85,248.83],[2,1.84,213.97]],"batl":[[0,2.08,316]],"ltp":2.08,"tv":15343.45,"id":5300820},{"batb":[[1,1.7,441.35],[2,1.69,371.48]],"ltp":1.86,"tv":7051.84,"id":9629022}]}]}
{"op":"mcm","clk":"4215080879","pt":1631534418651,"mc":[{"id":"1.187557985","rc":[{"batb":[[0,1.91,2.32],[1,1.71,224.5],[2,1.7,441.35]],"ltp":1.86,"tv":7051.84,"id":9629022}]}]}
{"op":"mcm","clk":"4215080956","pt":1631534419590,"mc":[{"id":"1.187557985","rc":[{"batl":[[1,2.22,457.47],[2,2.38,10]],"ltp":2.08,"tv":15343.45,"id":5300820}]}]}
{"op":"mcm","clk":"4215081016","pt":1631534420175,"mc":[{"id":"1.187557985","rc":[{"batl":[[0,2.38,10],[1,2.42,196.9],[2,2.44,183.26]],"ltp":2.08,"tv":15343.45,"id":5300820},{"batb":[[0,1.91,116.49],[1,1.89,165.05],[2,1.71,224.5]],"batl":[[0,1.98,174.99],[1,2,141.34],[2,2.18,160.02]],"ltp":1.86,"tv":7051.84,"id":9629022}]}]}
{"op":"mcm","clk":"4215081123","pt":1631534421543,"mc":[{"id":"1.187557985","rc":[{"batb":[[0,1.86,489.13],[1,1.85,252.83]],"ltp":2.08,"tv":15343.45,"id":5300820},{"batl":[[2,2.18,163.02]],"ltp":1.86,"tv":7051.84,"id":9629022}]}]}
{"op":"mcm","clk":"4215081181","pt":1631534422382,"mc":[{"id":"1.187557985","rc":[{"batb":[[0,1.87,105.57],[1,1.86,489.13],[2,1.85,252.83]],"ltp":2.08,"tv":15343.45,"id":5300820},{"batl":[[2,2.16,95.63]],"ltp":1.86,"tv":7051.84,"id":9629022}]}]}
{"op":"mcm","clk":"4215081289","pt":1631534423590,"mc":[{"id":"1.187557985","rc":[{"batb":[[0,1.86,489.13],[1,1.85,252.83],[2,1.84,213.97]],"ltp":2.08,"tv":15343.45,"id":5300820},{"batb":[[0,1.91,2.32],[1,1.71,224.5],[2,1.7,441.35]],"batl":[[0,2.18,163.02],[1,2.2,189.72],[2,2.22,274.39]],"ltp":1.86,"tv":7051.84,"id":9629022}]}]}
{"op":"mcm","clk":"4215081494","pt":1631534426406,"mc":[{"id":"1.187557985","rc":[{"batb":[[2,1.7,664.75]],"batl":[[0,2.18,295.07],[1,2.2,297.25]],"ltp":1.86,"tv":7051.84,"id":9629022}]}]}
{"op":"mcm","clk":"4215081756","pt":1631534429524,"mc":[{"id":"1.187557985","rc":[{"batl":[[0,1.97,2.5],[1,2.18,295.07],[2,2.2,297.25]],"ltp":1.86,"tv":7051.84,"id":9629022}]}]}
{"op":"mcm","clk":"4215081794","pt":1631534429898,"mc":[{"id":"1.187557985","rc":[{"batl":[[0,2.18,295.07],[1,2.2,297.25],[2,2.22,274.39]],"ltp":1.86,"tv":7051.84,"id":9629022}]}]}
{"op":"mcm","clk":"4215082085","pt":1631534433402,"mc":[{"id":"1.187557985","rc":[{"batb":[[1,1.85,248.83]],"ltp":2.08,"tv":15343.45,"id":5300820}]}]}
{"op":"mcm","clk":"4215082262","pt":1631534435417,"mc":[{"id":"1.187557985","rc":[{"batb":[[1,1.5,106.96],[2,1.4,148.56]],"ltp":2.08,"tv":15343.45,"id":5300820},{"batl":[[0,2.18,135.05],[1,2.2,107.53],[2,2.22,0]],"ltp":1.86,"tv":7051.84,"id":9629022}]}]}
{"op":"mcm","clk":"4215082365","pt":1631534436632,"mc":[{"id":"1.187557985","rc":[{"batb":[[1,1.85,2],[2,1.5,106.96]],"ltp":2.08,"tv":15343.45,"id":5300820},{"batl":[[0,2.18,3],[1,2.2,0]],"ltp":1.86,"tv":7051.84,"id":9629022}]}]}
{"op":"mcm","clk":"4215082528","pt":1631534438622,"mc":[{"id":"1.187557985","rc":[{"batb":[[0,2.3,831.52],[1,2.28,807.06],[2,2.26,807.06]],"ltp":2.08,"tv":15343.45,"id":5300820},{"trd":[[1.91,4.64]],"batb":[[0,1.71,224.5],[1,1.7,664.75],[2,1.69,371.48]],"batl":[[0,2.12,9.43],[1,2.18,3]],"ltp":1.91,"tv":7056.49,"id":9629022}],"tv":22399.94}]}
{"op":"mcm","clk":"4215082588","pt":1631534439416,"mc":[{"id":"1.187557985","rc":[{"trd":[[2.3,19.24]],"batb":[[0,2.32,84.85],[1,2.3,821.9],[2,2.28,807.06]],"batl":[[2,2.44,208.26]],"ltp":2.3,"tv":15362.69,"id":5300820},{"batb":[[2,1.69,407.59]],"batl":[[0,1.76,168.78],[1,1.78,202.49],[2,2.12,9.43]],"ltp":1.91,"tv":7056.49,"id":9629022}],"tv":22419.18}]}
{"op":"mcm","clk":"4215082675","pt":1631534440406,"mc":[{"id":"1.187557985","rc":[{"trd":[[2.32,4]],"batb":[[0,2.32,82.85]],"ltp":2.32,"tv":15366.69,"id":5300820},{"batl":[[2,1.83,144.64]],"ltp":1.91,"tv":7056.49,"id":9629022}],"tv":22423.18}]}
{"op":"mcm","clk":"4215082761","pt":1631534441256,"mc":[{"id":"1.187557985","rc":[{"batl":[[2,1.94,15]],"ltp":1.91,"tv":7056.49,"id":9629022}]}]}
{"op":"mcm","clk":"4215083159","pt":1631534445412,"mc":[{"id":"1.187557985","rc":[{"batl":[[2,1.93,199.85]],"ltp":1.91,"tv":7056.49,"id":9629022}]}]}
{"op":"mcm","clk":"4215083794","pt":1631534453359,"mc":[{"id":"1.187557985","rc":[{"batb":[[0,2.08,181.53],[1,2.06,352.49],[2,2.04,310.61]],"batl":[[1,2.44,25],[2,2.66,197.73]],"ltp":2.32,"tv":15366.69,"id":5300820},{"batb":[[0,1.69,36.11],[1,1.63,3.71],[2,1.6,266.21]],"batl":[[0,1.93,199.85],[1,1.94,230.17],[2,1.95,276.39]],"ltp":1.91,"tv":7056.49,"id":9629022}]}]}
{"op":"mcm","clk":"4215083870","pt":1631534454448,"mc":[{"id":"1.187557985","rc":[{"batl":[[1,2.66,197.73],[2,2.68,226.65]],"ltp":2.32,"tv":15366.69,"id":5300820},{"batb":[[0,1.63,3.71],[1,1.6,266.21],[2,1.59,288.48]],"ltp":1.91,"tv":7056.49,"id":9629022}]}]}
{"op":"mcm","clk":"4215084351","pt":1631534460439,"mc":[{"id":"1.187557985","rc":[{"batb":[[0,1.74,124.7],[1,1.72,224.32],[2,1.63,3.71]],"batl":[[0,1.79,125.07],[1,1.81,192.06],[2,1.93,199.85]],"ltp":1.91,"tv":7056.49,"id":9629022}]}]}
{"op":"mcm","clk":"4215084424","pt":1631534461338,"mc":[{"id":"1.187557985","rc":[{"batb":[[0,2.1,75.63],[1,2.08,181.53],[2,2.06,352.49]],"batl":[[0,2.36,23.37],[1,2.38,10],[2,2.66,197.73]],"ltp":2.32,"tv":15366.69,"id":5300820},{"batb":[[2,1.64,18.55]],"batl":[[2,1.92,89.04]],"ltp":1.91,"tv":7056.49,"id":9629022}]}]}
{"op":"mcm","clk":"4215084508","pt":1631534462352,"mc":[{"id":"1.187557985","rc":[{"batb":[[0,2.08,181.53],[1,2.06,352.49],[2,2.04,310.61]],"batl":[[0,2.38,10],[1,2.66,197.73],[2,2.68,226.65]],"ltp":2.32,"tv":15366.69,"id":5300820},{"batb":[[0,1.63,3.71],[1,1.6,266.21],[2,1.59,288.48]],"batl":[[0,1.93,199.85],[1,1.94,230.17],[2,1.95,276.39]],"ltp":1.91,"tv":7056.49,"id":9629022}]}]}
{"op":"mcm","clk":"4215084826","pt":1631534465341,"mc":[{"id":"1.187557985","rc":[{"batl":[[1,1.94,352.79]],"ltp":1.91,"tv":7056.49,"id":9629022}]}]}
{"op":"mcm","clk":"4215084964","pt":1631534466773,"mc":[{"id":"1.187557985","rc":[{"batb":[[0,2.06,117.57],[1,1.87,5],[2,1.86,404.12]],"ltp":2.32,"tv":15366.69,"id":5300820},{"batl":[[0,2.16,3],[1,1.94,0],[2,1.95,0]],"ltp":1.91,"tv":7056.49,"id":9629022}]}]}
{"op":"mcm","clk":"4215085054","pt":1631534467871,"mc":[{"id":"1.187557985","rc":[{"batb":[[2,1.7,16.97]],"ltp":2.32,"tv":15366.69,"id":5300820}]}]}
{"op":"mcm","clk":"4215085239","pt":1631534469656,"mc":[{"id":"1.187557985","rc":[{"trd":[[2.38,52.49]],"batl":[[0,2.7,221.18],[1,2.76,4.77],[2,3.05,4.1]],"ltp":2.38,"tv":15376.69,"id":5300820},{"trd":[[1.63,125.26],[1.72,46.24]],"batb":[[0,1.59,288.48],[1,1.58,832.17],[2,1.57,225.59]],"batl":[[0,1.63,1850.32],[1,1.64,132.75],[2,1.65,2318.18]],"ltp":1.63,"tv":7077.74,"id":9629022}],"tv":22454.44}]}
{"op":"mcm","clk":"4215085345","pt":1631534470664,"mc":[{"id":"1.187557985","rc":[{"trd":[[2.58,59.69]],"batb":[[0,2.58,63.1],[1,2.28,87.7],[2,2.06,117.57]],"ltp":2.58,"tv":15385.62,"id":5300820},{"trd":[[1.63,139.39]],"batl":[[0,1.63,143.45],[2,1.65,1159.1]],"ltp":1.63,"tv":7091.87,"id":9629022}],"tv":22477.5}]}
{"op":"mcm","clk":"4215085430","pt":1631534471605,"mc":[{"id":"1.187557985","rc":[{"trd":[[2.58,84]],"batb":[[0,2.58,50.94],[1,2.38,4],[2,2.36,4]],"ltp":2.58,"tv":15409.93,"id":5300820},{"batb":[[1,1.58,700.8],[2,1.57,68.57]],"ltp":1.63,"tv":7091.87,"id":9629022}],"tv":22501.8}]}
{"op":"mcm","clk":"4215085548","pt":1631534472653,"mc":[{"id":"1.187557985","rc":[{"batl":[[1,2.74,22.74],[2,2.76,4.77]],"ltp":2.58,"tv":15409.93,"id":5300820}]}]}
{"op":"mcm","clk":"4215085608","pt":1631534473279,"mc":[{"id":"1.187557985","rc":[{"batb":[[1,2.52,3],[2,2.5,3]],"batl":[[0,2.7,239.98]],"ltp":2.58,"tv":15409.93,"id":5300820}]}]}
{"op":"mcm","clk":"4215085715","pt":1631534474484,"mc":[{"id":"1.187557985","rc":[{"trd":[[2.58,91]],"batb":[[0,2.58,47.44]],"ltp":2.58,"tv":15416.93,"id":5300820},{"batb":[[0,1.59,419.85]],"ltp":1.63,"tv":7091.87,"id":9629022}],"tv":22508.8}]}
{"op":"mcm","clk":"4215085738","pt":1631534474753,"mc":[{"id":"1.187557985","rc":[{"batb":[[2,1.57,108.3]],"ltp":1.63,"tv":7091.87,"id":9629022}]}]}
{"op":"mcm","clk":"4215086757","pt":1631534486287,"mc":[{"id":"1.187557985","rc":[{"batb":[[2,2.28,192.99]],"ltp":2.58,"tv":15416.93,"id":5300820},{"trd":[[1.59,903.94]],"batb":[[0,1.58,700.8],[1,1.57,108.3],[2,1.55,678.63]],"ltp":1.59,"tv":7723.93,"id":9629022}],"tv":23140.86}]}
{"op":"mcm","clk":"4215086960","pt":1631534488490,"mc":[{"id":"1.187557985","rc":[{"batb":[[0,2.28,87.7],[1,1.97,400.31],[2,1.7,16.97]],"batl":[[0,2.74,22.74],[1,3.1,4.35],[2,3.2,4.13]],"ltp":2.58,"tv":15416.93,"id":5300820},{"batb":[[0,1.57,39.73],[1,1.49,165.94],[2,1.48,67.26]],"batl":[[0,1.71,5.65],[1,1.64,0],[2,1.65,0]],"ltp":1.59,"tv":7723.93,"id":9629022}]}]}
{"op":"mcm","clk":"4215087055","pt":1631534489492,"mc":[{"id":"1.187557985","rc":[{"batl":[[0,3.1,4.35],[1,3.2,4.13],[2,3.65,172.76]],"ltp":2.58,"tv":15416.93,"id":5300820},{"batb":[[0,1.58,40.98]],"ltp":1.59,"tv":7723.93,"id":9629022}]}]}
{"op":"mcm","clk":"4215087131","pt":1631534490387,"mc":[{"id":"1.187557985","rc":[{"batb":[[0,1.49,165.94],[1,1.48,67.26],[2,1.46,81.88]],"ltp":1.59,"tv":7723.93,"id":9629022}]}]}
{"op":"mcm","clk":"4215087243","pt":1631534491598,"mc":[{"id":"1.187557985","rc":[{"batb":[[0,2.44,20.83],[1,2.28,87.7],[2,1.97,400.31]],"ltp":2.58,"tv":15416.93,"id":5300820},{"batb":[[0,1.49,468.19],[1,1.48,265.65]],"batl":[[1,1.77,158.9],[2,1.79,198.98]],"ltp":1.59,"tv":7723.93,"id":9629022}]}]}
{"op":"mcm","clk":"4215087265","pt":1631534491915,"mc":[{"id":"1.187557985","rc":[{"batb":[[0,2.28,87.7],[1,1.97,400.31],[2,1.7,16.97]],"ltp":2.58,"tv":15416.93,"id":5300820}]}]}
{"op":"mcm","clk":"4215087335","pt":1631534492910,"mc":[{"id":"1.187557985","rc":[{"batl":[[0,3.05,3],[1,3.1,4.35],[2,3.2,4.13]],"ltp":2.58,"tv":15416.93,"id":5300820},{"batb":[[0,1.49,473.19],[1,1.48,272.65]],"ltp":1.59,"tv":7723.93,"id":9629022}]}]}
{"op":"mcm","clk":"4215087556","pt":1631534495387,"mc":[{"id":"1.187557985","rc":[{"batl":[[0,2.98,3],[1,3.05,3],[2,3.1,4.35]],"ltp":2.58,"tv":15416.93,"id":5300820},{"batb":[[0,1.51,6],[1,1.5,5],[2,1.49,473.19]],"ltp":1.59,"tv":7723.93,"id":9629022}]}]}
{"op":"mcm","clk":"4215087601","pt":1631534495909,"mc":[{"id":"1.187557985","rc":[{"batl":[[1,1.77,0],[2,1.79,0]],"ltp":1.59,"tv":7723.93,"id":9629022}]}]}
{"op":"mcm","clk":"4215087850","pt":1631534498613,"mc":[{"id":"1.187557985","rc":[{"batb":[[0,2.86,1337.42],[1,2.84,1298.08],[2,2.82,1298.08]],"batl":[[0,3.1,4.35],[1,3.2,1199.45],[2,3.25,1160.16]],"ltp":2.58,"tv":15416.93,"id":5300820},{"batb":[[0,1.49,468.19],[1,1.48,265.65],[2,1.46,81.88]],"batl":[[1,1.83,10.93]],"ltp":1.59,"tv":7723.93,"id":9629022}]}]}
{"op":"mcm","clk":"4215087942","pt":1631534499602,"mc":[{"id":"1.187557985","rc":[{"trd":[[2.86,16.52]],"batb":[[0,2.88,47.78],[1,2.86,660.44],[2,2.84,649.04]],"batl":[[1,3.2,332.84],[2,3.25,319.04]],"ltp":2.86,"tv":15433.45,"id":5300820},{"batl":[[0,1.54,280.92],[1,1.55,162.27],[2,1.71,5.65]],"ltp":1.59,"tv":7723.93,"id":9629022}],"tv":23157.38}]}
{"op":"mcm","clk":"4215088024","pt":1631534500494,"mc":[{"id":"1.187557985","rc":[{"batl":[[0,3.1,25.05]],"ltp":2.86,"tv":15433.45,"id":5300820},{"batb":[[2,1.47,43.75]],"batl":[[2,1.58,30]],"ltp":1.59,"tv":7723.93,"id":9629022}]}]}
{"op":"mcm","clk":"4215088102","pt":1631534501593,"mc":[{"id":"1.187557985","rc":[{"trd":[[2.88,0.19]],"batb":[[0,2.88,47.69]],"ltp":2.88,"tv":15433.63,"id":5300820}],"tv":23157.56}]}
{"op":"mcm","clk":"4215088119","pt":1631534501800,"mc":[{"id":"1.187557985","rc":[{"batl":[[0,3.05,21.75],[1,3.1,25.05],[2,3.2,332.84]],"ltp":2.88,"tv":15433.63,"id":5300820},{"batb":[[0,1.49,511.26]],"ltp":1.59,"tv":7723.93,"id":9629022}]}]}
{"op":"mcm","clk":"4215088279","pt":1631534503621,"mc":[{"id":"1.187557985","rc":[{"trd":[[2.88,4.19]],"batb":[[0,2.88,45.69]],"ltp":2.88,"tv":15437.64,"id":5300820},{"batl":[[2,1.6,139.62]],"ltp":1.59,"tv":7723.93,"id":9629022}],"tv":23161.57}]}
{"op":"mcm","clk":"4215088356","pt":1631534504614,"mc":[{"id":"1.187557985","rc":[{"batb":[[0,1.49,511.09]],"batl":[[2,1.66,28.25]],"ltp":1.59,"tv":7723.93,"id":9629022}]}]}
{"op":"mcm","clk":"4215088599","pt":1631534507396,"mc":[{"id":"1.187557985","rc":[{"batl":[[2,1.57,30]],"ltp":1.59,"tv":7723.93,"id":9629022}]}]}
{"op":"mcm","clk":"4215088925","pt":1631534511502,"mc":[{"id":"1.187557985","rc":[{"batb":[[0,1.49,468.02]],"ltp":1.59,"tv":7723.93,"id":9629022}]}]}
{"op":"mcm","clk":"4215089191","pt":1631534514619,"mc":[{"id":"1.187557985","rc":[{"trd":[[1.5,404.67]],"batb":[[0,1.5,41.88],[1,1.49,468.02],[2,1.48,265.65]],"ltp":1.5,"tv":7726.31,"id":9629022}],"tv":23163.95}]}
{"op":"mcm","clk":"4215089207","pt":1631534514831,"mc":[{"id":"1.187557985","rc":[{"batb":[[0,1.49,468.02],[1,1.48,265.65],[2,1.47,43.75]],"ltp":1.5,"tv":7726.31,"id":9629022}]}]}
{"op":"mcm","clk":"4215089529","pt":1631534518652,"mc":[{"id":"1.187557985","rc":[{"trd":[[1.54,400]],"batl":[[0,1.54,80.92]],"ltp":1.54,"tv":8126.31,"id":9629022}],"tv":23563.95}]}
{"op":"mcm","clk":"4215089592","pt":1631534519346,"mc":[{"id":"1.187557985","rc":[{"batb":[[0,1.49,403.66],[1,1.48,67.26]],"ltp":1.54,"tv":8126.31,"id":9629022}]}]}
{"op":"mcm","clk":"4215089880","pt":1631534522555,"mc":[{"id":"1.187557985","rc":[{"batb":[[0,1.5,223.28],[1,1.49,403.66],[2,1.48,67.26]],"batl":[[0,1.54,170.4]],"ltp":1.54,"tv":8126.31,"id":9629022}]}]}
{"op":"mcm","clk":"4215089938","pt":1631534523238,"mc":[{"id":"1.187557985","rc":[{"trd":[[2.88,8.81]],"batb":[[0,2.88,43.38]],"ltp":2.88,"tv":15442.26,"id":5300820}],"tv":23568.57}]}
{"op":"mcm","clk":"4215090332","pt":1631534528221,"mc":[{"id":"1.187557985","rc":[{"batb":[[1,1.49,357.49]],"ltp":1.54,"tv":8126.31,"id":9629022}]}]}
{"op":"mcm","clk":"4215090405","pt":1631534529057,"mc":[{"id":"1.187557985","rc":[{"trd":[[1.54,404.64]],"batl":[[0,1.54,168.08]],"ltp":1.54,"tv":8130.95,"id":9629022}],"tv":23573.21}]}
{"op":"mcm","clk":"4215090569","pt":1631534531241,"mc":[{"id":"1.187557985","rc":[{"batb":[[0,1.5,269.45],[2,1.48,73.26]],"ltp":1.54,"tv":8130.95,"id":9629022}]}]}
{"op":"mcm","clk":"4215092075","pt":1631534549472,"mc":[{"id":"1.187557985","rc":[{"trd":[[2.88,11.7]],"batb":[[0,2.88,41.93]],"ltp":2.88,"tv":15445.15,"id":5300820},{"batb":[[0,1.5,223.28]],"ltp":1.54,"tv":8130.95,"id":9629022}],"tv":23576.11}]}
{"op":"mcm","clk":"4215092121","pt":1631534550057,"mc":[{"id":"1.187557985","rc":[{"trd":[[2.88,14.6]],"batb":[[0,2.88,40.48]],"ltp":2.88,"tv":15448.05,"id":5300820},{"batb":[[2,1.48,67.26]],"ltp":1.54,"tv":8130.95,"id":9629022}],"tv":23579.0}]}
{"op":"mcm","clk":"4215092685","pt":1631534557495,"mc":[{"id":"1.187557985","rc":[{"batb":[[1,1.49,357.24]],"ltp":1.54,"tv":8130.95,"id":9629022}]}]}
{"op":"mcm","clk":"4215093895","pt":1631534572594,"mc":[{"id":"1.187557985","rc":[{"trd":[[3,3.14]],"ltp":3.0,"tv":15451.19,"id":5300820},{"trd":[[1.5,410.95]],"batb":[[0,1.5,217]],"ltp":1.5,"tv":8137.23,"id":9629022}],"tv":23588.42}]}
{"op":"mcm","clk":"4215094027","pt":1631534573997,"mc":[{"id":"1.187557985","rc":[{"batb":[[0,1.5,261.54]],"ltp":1.5,"tv":8137.23,"id":9629022}]}]}
{"op":"mcm","clk":"4215095230","pt":1631534589015,"mc":[{"id":"1.187557985","rc":[{"batl":[[1,1.55,212.57]],"ltp":1.5,"tv":8137.23,"id":9629022}]}]}
{"op":"mcm","clk":"4215095818","pt":1631534595807,"mc":[{"id":"1.187557985","rc":[{"batl":[[0,3.1,25.05],[1,3.2,332.84],[2,3.25,319.04]],"ltp":3.0,"tv":15451.19,"id":5300820},{"batb":[[0,1.5,217]],"ltp":1.5,"tv":8137.23,"id":9629022}]}]}
{"op":"mcm","clk":"4215096626","pt":1631534605214,"mc":[{"id":"1.187557985","rc":[{"batl":[[0,3.05,29.87],[1,3.1,25.05],[2,3.2,332.84]],"ltp":3.0,"tv":15451.19,"id":5300820},{"batb":[[0,1.5,261.54]],"ltp":1.5,"tv":8137.23,"id":9629022}]}]}
{"op":"mcm","clk":"4215096888","pt":1631534608403,"mc":[{"id":"1.187557985","rc":[{"batb":[[0,1.5,217]],"ltp":1.5,"tv":8137.23,"id":9629022}]}]}
{"op":"mcm","clk":"4215097126","pt":1631534611185,"mc":[{"id":"1.187557985","rc":[{"batb":[[0,1.51,44.54],[1,1.5,217],[2,1.49,357.24]],"ltp":1.5,"tv":8137.23,"id":9629022}]}]}
{"op":"mcm","clk":"4215097431","pt":1631534615536,"mc":[{"id":"1.187557985","rc":[{"batb":[[1,2.8,4.38],[2,2.76,17.04]],"batl":[[0,3.1,25.05],[1,3.25,3.94],[2,3.65,172.76]],"ltp":3.0,"tv":15451.19,"id":5300820},{"batb":[[0,1.5,217],[1,1.49,357.24],[2,1.48,67.26]],"batl":[[2,1.57,74.5]],"ltp":1.5,"tv":8137.23,"id":9629022}]}]}
{"op":"mcm","clk":"4215097528","pt":1631534616415,"mc":[{"id":"1.187557985","rc":[{"batb":[[0,2.76,17.04],[1,2.74,8.02],[2,2.72,3]],"batl":[[0,3.1,20.7]],"ltp":3.0,"tv":15451.19,"id":5300820},{"batb":[[0,1.47,49.75],[1,1.45,85.61],[2,1.44,188.87]],"batl":[[0,1.57,74.5],[1,1.71,5.65],[2,1.57,0]],"ltp":1.5,"tv":8137.23,"id":9629022}]}]}
{"op":"mcm","clk":"4215097626","pt":1631534617405,"mc":[{"id":"1.187557985","rc":[{"batb":[[0,2.74,8.02],[1,2.72,3],[2,2.7,55.98]],"batl":[[0,3.25,3.94],[1,3.65,172.76],[2,3.65,0]],"ltp":3.0,"tv":15451.19,"id":5300820},{"batb":[[0,1.47,6]],"batl":[[0,1.57,44.5]],"ltp":1.5,"tv":8137.23,"id":9629022}]}]}
{"op":"mcm","clk":"4215097696","pt":1631534618508,"mc":[{"id":"1.187557985","rc":[{"batb":[[0,1.49,6],[1,1.48,7],[2,1.47,6]],"ltp":1.5,"tv":8137.23,"id":9629022}]}]}
{"op":"mcm","clk":"4215097770","pt":1631534619600,"mc":[{"id":"1.187557985","rc":[{"batl":[[0,3.1,3],[1,3.25,3.94],[2,3.65,172.76]],"ltp":3.0,"tv":15451.19,"id":5300820},{"batl":[[1,1.59,169.25],[2,1.6,144.39]],"ltp":1.5,"tv":8137.23,"id":9629022}]}]}
{"op":"mcm","clk":"4215097914","pt":1631534621584,"mc":[{"id":"1.187557985","rc":[{"batl":[[0,2.88,2183.34],[1,3.1,12.68],[2,3.15,3]],"ltp":3.0,"tv":15451.19,"id":5300820}]}]}
{"op":"mcm","clk":"4215097997","pt":1631534622600,"mc":[{"id":"1.187557985","rc":[{"batb":[[0,2.74,5.02],[1,2.7,55.98],[2,1.97,400.31]],"batl":[[0,3.05,3],[1,3.1,3]],"ltp":3.0,"tv":15451.19,"id":5300820}]}]}
{"op":"mcm","clk":"4215098066","pt":1631534623495,"mc":[{"id":"1.187557985","rc":[{"trd":[[2.74,13.49]],"batb":[[0,2.7,55.98],[1,2.64,398.44],[2,2.62,386.72]],"batl":[[0,2.9,673.93],[1,2.92,640.08],[2,2.94,640.08]],"ltp":2.74,"tv":15464.68,"id":5300820},{"trd":[[1.57,6.02]],"batb":[[0,1.55,150.9],[1,1.54,195.64],[2,1.53,82.33]],"batl":[[0,1.57,43.48]],"ltp":1.57,"tv":8143.25,"id":9629022}],"tv":23607.93}]}
{"op":"mcm","clk":"4215098175","pt":1631534624602,"mc":[{"id":"1.187557985","rc":[{"batl":[[1,2.92,661.73]],"ltp":2.74,"tv":15464.68,"id":5300820},{"batb":[[1,1.54,340.83]],"batl":[[0,1.57,38.48]],"ltp":1.57,"tv":8143.25,"id":9629022}]}]}
{"op":"mcm","clk":"4215098313","pt":1631534626120,"mc":[{"id":"1.187557985","rc":[{"batl":[[0,2.88,3],[1,2.9,673.93],[2,2.92,661.73]],"ltp":2.74,"tv":15464.68,"id":5300820}]}]}
{"op":"mcm","clk":"4215098372","pt":1631534626912,"mc":[{"id":"1.187557985","rc":[{"batl":[[2,2.92,640.08]],"ltp":2.74,"tv":15464.68,"id":5300820}]}]}
{"op":"mcm","clk":"4215098482","pt":1631534628230,"mc":[{"id":"1.187557985","rc":[{"batb":[[0,1.55,193.87]],"ltp":1.57,"tv":8143.25,"id":9629022}]}]}
{"op":"mcm","clk":"4215098691","pt":1631534630644,"mc":[{"id":"1.187557985","rc":[{"batb":[[0,2.6,4],[1,2.58,237.98],[2,2.56,213.09]],"batl":[[0,2.88,21.87],[1,2.94,143.81],[2,2.96,162.32]],"ltp":2.74,"tv":15464.68,"id":5300820},{"batb":[[0,1.52,289.74],[1,1.51,445.83],[2,1.5,400.43]],"batl":[[0,1.64,224.3],[1,1.65,296.79],[2,1.66,326.81]],"ltp":1.57,"tv":8143.25,"id":9629022}]}]}
{"op":"mcm","clk":"4215098778","pt":1631534631643,"mc":[{"id":"1.187557985","rc":[{"batb":[[1,2.58,219]],"batl":[[0,2.94,143.81],[1,2.96,162.32],[2,2.98,183.49]],"ltp":2.74,"tv":15464.68,"id":5300820},{"batb":[[0,1.55,116],[1,1.52,289.74],[2,1.51,445.83]],"ltp":1.57,"tv":8143.25,"id":9629022}]}]}
{"op":"mcm","clk":"4215098787","pt":1631534631747,"mc":[{"id":"1.187557985","rc":[{"batb":[[0,1.52,289.74],[1,1.51,445.83],[2,1.5,400.43]],"ltp":1.57,"tv":8143.25,"id":9629022}]}]}
{"op":"mcm","clk":"4215098914","pt":1631534633632,"mc":[{"id":"1.187557985","rc":[{"batl":[[0,1.63,30],[1,1.64,390.4],[2,1.65,426.28]],"ltp":1.57,"tv":8143.25,"id":9629022}]}]}
{"op":"mcm","clk":"4215098981","pt":1631534634423,"mc":[{"id":"1.187557985","rc":[{"batl":[[2,2.98,178.24]],"ltp":2.74,"tv":15464.68,"id":5300820},{"batb":[[1,1.51,353.84]],"batl":[[0,1.63,5],[1,1.64,224.3],[2,1.65,296.79]],"ltp":1.57,"tv":8143.25,"id":9629022}]}]}
{"op":"mcm","clk":"4215099234","pt":1631534637625,"mc":[{"id":"1.187557985","rc":[{"batb":[[0,2.62,3],[1,2.58,216]],"ltp":2.74,"tv":15464.68,"id":5300820},{"batb":[[0,1.55,151.33],[1,1.54,167.85],[2,1.52,289.74]],"batl":[[0,1.59,168.83],[1,1.6,144.39],[2,1.63,5]],"ltp":1.57,"tv":8143.25,"id":9629022}]}]}
{"op":"mcm","clk":"4215099406","pt":1631534639634,"mc":[{"id":"1.187557985","rc":[{"batb":[[0,1.52,289.74],[1,1.51,353.84],[2,1.5,400.43]],"batl":[[0,1.63,5],[1,1.64,224.3],[2,1.65,296.79]],"ltp":1.57,"tv":8143.25,"id":9629022}]}]}
{"op":"mcm","clk":"4215099476","pt":1631534640518,"mc":[{"id":"1.187557985","rc":[{"batb":[[1,2.6,3],[2,2.58,216]],"ltp":2.74,"tv":15464.68,"id":5300820},{"batl":[[0,1.62,5],[1,1.63,5],[2,1.64,224.3]],"ltp":1.57,"tv":8143.25,"id":9629022}]}]}
{"op":"mcm","clk":"4215099629","pt":1631534642525,"mc":[{"id":"1.187557985","rc":[{"batl":[[2,1.64,390.4]],"ltp":1.57,"tv":8143.25,"id":9629022}]}]}
{"op":"mcm","clk":"4215099703","pt":1631534643630,"mc":[{"id":"1.187557985","rc":[{"batl":[[2,1.64,224.3]],"ltp":1.57,"tv":8143.25,"id":9629022}]}]}
{"op":"mcm","clk":"4215099859","pt":1631534645652,"mc":[{"id":"1.187557985","rc":[{"batl":[[0,1.6,4],[1,1.62,5],[2,1.63,5]],"ltp":1.57,"tv":8143.25,"id":9629022}]}]}
{"op":"mcm","clk":"4215099892","pt":1631534646132,"mc":[{"id":"1.187557985","rc":[{"batl":[[0,1.62,5],[1,1.63,5],[2,1.64,224.3]],"ltp":1.57,"tv":8143.25,"id":9629022}]}]}
{"op":"mcm","clk":"4215099978","pt":1631534647289,"mc":[{"id":"1.187557985","rc":[{"batb":[[0,1.53,308.23],[1,1.52,467.35],[2,1.51,353.84]],"batl":[[0,1.58,197.19],[1,1.59,147.61],[2,1.62,5]],"ltp":1.57,"tv":8143.25,"id":9629022}]}]}
{"op":"mcm","clk":"4215100089","pt":1631534648446,"mc":[{"id":"1.187557985","rc":[{"batb":[[0,1.52,289.74],[1,1.51,353.84],[2,1.5,400.43]],"batl":[[0,1.62,5],[1,1.63,5],[2,1.64,224.3]],"ltp":1.57,"tv":8143.25,"id":9629022}]}]}
{"op":"mcm","clk":"4215100326","pt":1631534651657,"mc":[{"id":"1.187557985","rc":[{"batl":[[2,1.64,399.08]],"ltp":1.57,"tv":8143.25,"id":9629022}]}]}
{"op":"mcm","clk":"4215100374","pt":1631534652345,"mc":[{"id":"1.187557985","rc":[{"batb":[[1,2.58,216],[2,2.56,213.09]],"ltp":2.74,"tv":15464.68,"id":5300820},{"batl":[[1,1.64,399.08],[2,1.65,426.3]],"ltp":1.57,"tv":8143.25,"id":9629022}]}]}
{"op":"mcm","clk":"4215100627","pt":1631534655438,"mc":[{"id":"1.187557985","rc":[{"batb":[[1,2.6,3],[2,2.58,216]],"ltp":2.74,"tv":15464.68,"id":5300820}]}]}
{"op":"mcm","clk":"4215100811","pt":1631534657454,"mc":[{"id":"1.187557985","rc":[{"batb":[[2,2.58,63.76]],"ltp":2.74,"tv":15464.68,"id":5300820},{"batl":[[1,1.64,0],[2,1.65,0]],"ltp":1.57,"tv":8143.25,"id":9629022}]}]}
{"op":"mcm","clk":"4215101150","pt":1631534660661,"mc":[{"id":"1.187557985","rc":[{"batb":[[0,2.82,833.32],[1,2.8,416.66],[2,2.78,416.66]],"batl":[[0,2.98,178.24],[1,3.1,4.85],[2,3.2,328.71]],"ltp":2.74,"tv":15464.68,"id":5300820},{"batb":[[0,1.5,395.43],[1,1.49,483.13],[2,1.48,288.03]],"batl":[[0,1.54,264.61],[1,1.55,161.74],[2,1.62,5]],"ltp":1.57,"tv":8143.25,"id":9629022}]}]}
{"op":"mcm","clk":"4215101217","pt":1631534661395,"mc":[{"id":"1.187557985","rc":[{"trd":[[2.84,8.2]],"batb":[[0,2.88,47.36],[1,2.82,833.32],[2,2.8,416.66]],"ltp":2.84,"tv":15472.88,"id":5300820},{"trd":[[1.54,419.76]],"batl":[[0,1.54,249.49],[2,1.58,30]],"ltp":1.54,"tv":8158.37,"id":9629022}],"tv":23631.25}]}
{"op":"mcm","clk":"4215101357","pt":1631534663081,"mc":[{"id":"1.187557985","rc":[{"batl":[[0,2.98,196.54],[1,3.1,25.55]],"ltp":2.84,"tv":15472.88,"id":5300820},{"batb":[[0,1.5,438.42]],"ltp":1.54,"tv":8158.37,"id":9629022}]}]}
{"op":"mcm","clk":"4215101526","pt":1631534665488,"mc":[{"id":"1.187557985","rc":[{"batl":[[2,1.61,30]],"ltp":1.54,"tv":8158.37,"id":9629022}]}]}
{"op":"mcm","clk":"4215101749","pt":1631534668377,"mc":[{"id":"1.187557985","rc":[{"batl":[[2,1.57,30]],"ltp":1.54,"tv":8158.37,"id":9629022}]}]}
{"op":"mcm","clk":"4215102415","pt":1631534677211,"mc":[{"id":"1.187557985","rc":[{"batl":[[0,1.54,276.54]],"ltp":1.54,"tv":8158.37,"id":9629022}]}]}
{"op":"mcm","clk":"4215103099","pt":1631534687538,"mc":[{"id":"1.187557985","rc":[{"batb":[[0,2.76,17.04],[1,2.7,55.9],[2,2.34,2.89]],"batl":[[0,3.1,20.7],[1,3.65,172.76],[2,3.2,0]],"ltp":2.84,"tv":15472.88,"id":5300820},{"batb":[[0,1.47,43.75],[1,1.43,197.71],[2,1.37,4]],"batl":[[0,1.57,30],[1,1.61,5],[2,1.57,0]],"ltp":1.54,"tv":8158.37,"id":9629022}]}]}
{"op":"mcm","clk":"4215103168","pt":1631534688472,"mc":[{"id":"1.187557985","rc":[{"batb":[[0,2.7,55.9],[1,2.34,2.89],[2,1.97,400.31]],"batl":[[0,3.65,172.76],[1,3.65,0]],"ltp":2.84,"tv":15472.88,"id":5300820},{"batb":[[0,1.43,197.71],[1,1.37,4],[2,1.2,447.66]],"batl":[[0,1.61,5],[1,1.61,0]],"ltp":1.54,"tv":8158.37,"id":9629022}]}]}
{"op":"mcm","clk":"4215103300","pt":1631534690447,"mc":[{"id":"1.187557985","rc":[{"batb":[[0,1.44,252.24],[1,1.43,425.78],[2,1.37,4]],"batl":[[0,1.59,200.4],[1,1.6,144.41],[2,1.61,5]],"ltp":1.54,"tv":8158.37,"id":9629022}]}]}
{"op":"mcm","clk":"4215103356","pt":1631534691652,"mc":[{"id":"1.187557985","rc":[{"batb":[[0,2.7,59.9],[1,2.68,3],[2,2.34,2.89]],"batl":[[0,3.15,3],[1,3.35,3],[2,3.65,172.76]],"ltp":2.84,"tv":15472.88,"id":5300820},{"batb":[[0,1.45,5],[1,1.44,6],[2,1.43,204.71]],"batl":[[0,1.59,5],[1,1.61,5],[2,1.61,0]],"ltp":1.54,"tv":8158.37,"id":9629022}]}]}
{"op":"mcm","clk":"4215103501","pt":1631534693636,"mc":[{"id":"1.187557985","rc":[{"batl":[[1,3.3,3],[2,3.35,3]],"ltp":2.84,"tv":15472.88,"id":5300820},{"batl":[[0,1.56,681.53],[1,1.59,5],[2,1.61,5]],"ltp":1.54,"tv":8158.37,"id":9629022}]}]}
{"op":"mcm","clk":"4215103566","pt":1631534694472,"mc":[{"id":"1.187557985","rc":[{"batb":[[0,1.48,288.65],[1,1.47,203.25],[2,1.45,5]],"batl":[[0,1.52,141.65],[1,1.53,170.77],[2,1.59,5]],"ltp":1.54,"tv":8158.37,"id":9629022}]}]}
{"op":"mcm","clk":"4215103649","pt":1631534695368,"mc":[{"id":"1.187557985","rc":[{"batb":[[2,1.46,6]],"ltp":1.54,"tv":8158.37,"id":9629022}]}]}
{"op":"mcm","clk":"4215103749","pt":1631534696465,"mc":[{"id":"1.187557985","rc":[{"batb":[[0,2.72,40.28],[1,2.7,59.9],[2,2.68,3]],"batl":[[0,3.1,15],[1,3.15,3],[2,3.3,3]],"ltp":2.84,"tv":15472.88,"id":5300820},{"batl":[[2,1.58,25]],"ltp":1.54,"tv":8158.37,"id":9629022}]}]}
{"op":"mcm","clk":"4215103982","pt":1631534699656,"mc":[{"id":"1.187557985","rc":[{"batb":[[0,2.7,59.9],[1,2.68,3],[2,2.34,2.89]],"batl":[[0,3.15,3],[1,3.3,3],[2,3.35,3]],"ltp":2.84,"tv":15472.88,"id":5300820},{"batb":[[0,1.46,6],[1,1.45,5],[2,1.44,6]],"batl":[[0,1.59,5],[1,1.61,5],[2,1.58,0]],"ltp":1.54,"tv":8158.37,"id":9629022}]}]}
{"op":"mcm","clk":"4215104214","pt":1631534702688,"mc":[{"id":"1.187557985","rc":[{"batb":[[2,1.44,251.42]],"batl":[[0,1.59,212.45],[1,1.6,144.41],[2,1.61,5]],"ltp":1.54,"tv":8158.37,"id":9629022}]}]}
{"op":"mcm","clk":"4215105011","pt":1631534712664,"mc":[{"id":"1.187557985","rc":[{"trd":[[2.7,2.66]],"batb":[[0,2.7,58.57]],"ltp":2.7,"tv":15475.54,"id":5300820},{"batb":[[2,1.44,6]],"ltp":1.54,"tv":8158.37,"id":9629022}],"tv":23633.92}]}
{"op":"mcm","clk":"4215105055","pt":1631534713192,"mc":[{"id":"1.187557985","rc":[{"batb":[[1,2.34,2.89],[2,1.97,400.31]],"batl":[[1,3.65,172.76],[2,3.35,0]],"ltp":2.7,"tv":15475.54,"id":5300820},{"batb":[[1,1.43,197.71],[2,1.37,4]],"batl":[[2,1.61,0]],"ltp":1.54,"tv":8158.37,"id":9629022}]}]}
{"op":"mcm","clk":"4215105215","pt":1631534715607,"mc":[{"id":"1.187557985","rc":[{"trd":[[2.7,19.61]],"batb":[[0,2.7,46.09],[1,2.64,398.44],[2,2.62,386.72]],"batl":[[0,2.9,659.48],[1,2.92,640.08],[2,2.94,640.08]],"ltp":2.7,"tv":15492.48,"id":5300820},{"batb":[[0,1.54,280.41],[1,1.53,173.13],[2,1.46,6]],"batl":[[0,1.59,207.45]],"ltp":1.54,"tv":8158.37,"id":9629022}],"tv":23650.86}]}
{"op":"mcm","clk":"4215105272","pt":1631534716599,"mc":[{"id":"1.187557985","rc":[{"batl":[[1,2.92,661.73]],"ltp":2.7,"tv":15492.48,"id":5300820},{"batb":[[0,1.54,424.84],[2,1.52,41.6]],"batl":[[2,1.64,30]],"ltp":1.54,"tv":8158.37,"id":9629022}]}]}
{"op":"mcm","clk":"4215105440","pt":1631534718465,"mc":[{"id":"1.187557985","rc":[{"batl":[[0,2.88,3],[1,2.9,659.48],[2,2.92,661.73]],"ltp":2.7,"tv":15492.48,"id":5300820},{"batb":[[2,1.49,167.7]],"ltp":1.54,"tv":8158.37,"id":9629022}]}]}
{"op":"mcm","clk":"4215105521","pt":1631534719611,"mc":[{"id":"1.187557985","rc":[{"batb":[[0,1.55,42.97],[1,1.54,424.84],[2,1.53,173.13]],"ltp":1.54,"tv":8158.37,"id":9629022}]}]}
{"op":"mcm","clk":"4215105600","pt":1631534720618,"mc":[{"id":"1.187557985","rc":[{"batl":[[0,2.88,37.55],[2,2.92,640.08]],"ltp":2.7,"tv":15492.48,"id":5300820}]}]}
{"op":"mcm","clk":"4215105692","pt":1631534721609,"mc":[{"id":"1.187557985","rc":[{"batl":[[0,2.88,3]],"ltp":2.7,"tv":15492.48,"id":5300820},{"batb":[[2,1.53,214.33]],"ltp":1.54,"tv":8158.37,"id":9629022}]}]}
{"op":"mcm","clk":"4215105879","pt":1631534724175,"mc":[{"id":"1.187557985","rc":[{"batl":[[0,2.88,24.87]],"ltp":2.7,"tv":15492.48,"id":5300820}]}]}
{"op":"mcm","clk":"4215105981","pt":1631534725595,"mc":[{"id":"1.187557985","rc":[{"batb":[[0,1.56,18.08],[1,1.55,42.97],[2,1.54,424.84]],"ltp":1.54,"tv":8158.37,"id":9629022}]}]}
{"op":"mcm","clk":"4215106090","pt":1631534727390,"mc":[{"id":"1.187557985","rc":[{"batl":[[0,2.86,31.12],[1,2.88,24.87],[2,2.9,659.48]],"ltp":2.7,"tv":15492.48,"id":5300820}]}]}
{"op":"mcm","clk":"4215106350","pt":1631534731528,"mc":[{"id":"1.187557985","rc":[{"batb":[[0,2.56,84.25],[1,2.34,2.89],[2,1.97,400.31]],"batl":[[0,2.88,21.87],[1,3,4.86],[2,3.1,5.05]],"ltp":2.7,"tv":15492.48,"id":5300820},{"batb":[[1,1.53,41.2],[2,1.5,80.38]],"batl":[[0,1.64,30],[1,1.6,0],[2,1.64,0]],"ltp":1.54,"tv":8158.37,"id":9629022}]}]}
{"op":"mcm","clk":"4215106439","pt":1631534732624,"mc":[{"id":"1.187557985","rc":[{"batb":[[0,2.56,65.02]],"batl":[[0,3.1,5.05],[1,3.2,4.53],[2,3.65,172.76]],"ltp":2.7,"tv":15492.48,"id":5300820},{"batb":[[0,1.49,167.7],[1,1.48,88.01],[2,1.47,6]],"ltp":1.54,"tv":8158.37,"id":9629022}]}]}
{"op":"mcm","clk":"4215106554","pt":1631534734611,"mc":[{"id":"1.187557985","rc":[{"batb":[[1,2.54,65.19],[2,2.34,2.89]],"ltp":2.7,"tv":15492.48,"id":5300820},{"batb":[[0,1.49,378.23],[1,1.48,285.16]],"batl":[[0,1.64,149.65],[1,1.65,129.79]],"ltp":1.54,"tv":8158.37,"id":9629022}]}]}
{"op":"mcm","clk":"4215106628","pt":1631534735606,"mc":[{"id":"1.187557985","rc":[{"batb":[[0,2.56,4],[1,2.54,68.19]],"ltp":2.7,"tv":15492.48,"id":5300820},{"batb":[[0,1.49,377.81]],"batl":[[0,1.64,154.65],[1,1.65,134.79]],"ltp":1.54,"tv":8158.37,"id":9629022}]}]}
{"op":"mcm","clk":"4215106695","pt":1631534736596,"mc":[{"id":"1.187557985","rc":[{"batl":[[0,3.05,3],[1,3.1,5.05],[2,3.2,4.53]],"ltp":2.7,"tv":15492.48,"id":5300820},{"batb":[[0,1.51,18.08],[1,1.49,382.81],[2,1.48,291.16]],"ltp":1.54,"tv":8158.37,"id":9629022}]}]}
{"op":"mcm","clk":"4215106706","pt":1631534736702,"mc":[{"id":"1.187557985","rc":[{"batl":[[0,2.7,13.43],[1,3.05,3],[2,3.1,5.05]],"ltp":2.7,"tv":15492.48,"id":5300820}]}]}
{"op":"mcm","clk":"4215106784","pt":1631534737897,"mc":[{"id":"1.187557985","rc":[{"batb":[[0,1.5,18.08]],"ltp":1.54,"tv":8158.37,"id":9629022}]}]}
{"op":"mcm","clk":"4215106858","pt":1631534739624,"mc":[{"id":"1.187557985","rc":[{"batb":[[1,1.49,172.28],[2,1.48,94.01]],"ltp":1.54,"tv":8158.37,"id":9629022}]}]}
{"op":"mcm","clk":"4215106925","pt":1631534740615,"mc":[{"id":"1.187557985","rc":[{"batl":[[0,3.05,3],[1,3.1,5.05],[2,3.2,4.53]],"ltp":2.7,"tv":15492.48,"id":5300820},{"batb":[[0,1.59,2576.52],[1,1.5,18.08],[2,1.49,172.28]],"ltp":1.54,"tv":8158.37,"id":9629022}]}]}
{"op":"mcm","clk":"4215106939","pt":1631534740822,"mc":[{"id":"1.187557985","rc":[{"batb":[[0,1.5,18.08],[1,1.49,172.28],[2,1.48,94.01]],"ltp":1.54,"tv":8158.37,"id":9629022}]}]}
{"op":"mcm","clk":"4215107054","pt":1631534742443,"mc":[{"id":"1.187557985","rc":[{"trd":[[2.56,12.7]],"batb":[[0,2.54,68.19],[1,2.5,420.75],[2,2.48,408.37]],"batl":[[0,2.74,697.98],[1,2.76,677.46],[2,2.78,677.46]],"ltp":2.56,"tv":15505.18,"id":5300820},{"trd":[[1.64,7.34]],"batb":[[0,1.59,262.59],[1,1.58,153.07],[2,1.54,87.12]],"batl":[[0,1.64,147.31]],"ltp":1.64,"tv":8165.71,"id":9629022}],"tv":23670.9}]}
{"op":"mcm","clk":"4215107115","pt":1631534743442,"mc":[{"id":"1.187557985","rc":[{"batl":[[0,2.72,22.87],[1,2.74,697.98],[2,2.76,677.46]],"ltp":2.56,"tv":15505.18,"id":5300820},{"batb":[[0,1.6,127.86],[1,1.59,262.59],[2,1.58,192.46]],"batl":[[2,1.92,10.42]],"ltp":1.64,"tv":8165.71,"id":9629022}]}]}
{"op":"mcm","clk":"4215107283","pt":1631534746001,"mc":[{"id":"1.187557985","rc":[{"batb":[[0,2.58,2.89],[1,2.54,68.19],[2,2.5,420.75]],"ltp":2.56,"tv":15505.18,"id":5300820},{"batb":[[2,1.58,153.07]],"ltp":1.64,"tv":8165.71,"id":9629022}]}]}
{"op":"mcm","clk":"4215107401","pt":1631534747530,"mc":[{"id":"1.187557985","rc":[{"batb":[[1,2.54,65.19]],"batl":[[0,2.7,31.54],[1,2.72,22.87],[2,2.74,697.98]],"ltp":2.56,"tv":15505.18,"id":5300820},{"batb":[[0,1.61,40.99],[1,1.6,127.86],[2,1.59,262.59]],"batl":[[0,1.64,142.31],[1,1.65,129.79]],"ltp":1.64,"tv":8165.71,"id":9629022}]}]}
{"op":"mcm","clk":"4215107535","pt":1631534749528,"mc":[{"id":"1.187557985","rc":[{"batb":[[2,1.59,301.64]],"ltp":1.64,"tv":8165.71,"id":9629022}]}]}
{"op":"mcm","clk":"4215107724","pt":1631534752635,"mc":[{"id":"1.187557985","rc":[{"batb":[[2,2.44,72.22]],"batl":[[0,2.86,15.75],[1,3,4.59],[2,3.1,5.05]],"ltp":2.56,"tv":15505.18,"id":5300820},{"batb":[[0,1.6,127.86],[1,1.59,301.64],[2,1.58,153.07]],"batl":[[2,1.92,0]],"ltp":1.64,"tv":8165.71,"id":9629022}]}]}
{"op":"mcm","clk":"4215107760","pt":1631534753160,"mc":[{"id":"1.187557985","rc":[{"batb":[[1,2.44,72.22],[2,1.97,400.31]],"batl":[[0,3,4.59],[1,3.1,5.05],[2,3.2,4.53]],"ltp":2.56,"tv":15505.18,"id":5300820},{"batb":[[0,1.59,39.05],[1,1.55,143.76],[2,1.5,83.8]],"ltp":1.64,"tv":8165.71,"id":9629022}]}]}
{"op":"mcm","clk":"4215107826","pt":1631534754426,"mc":[{"id":"1.187557985","rc":[{"batb":[[0,1.55,143.76],[1,1.5,83.8],[2,1.48,88.01]],"ltp":1.64,"tv":8165.71,"id":9629022}]}]}
{"op":"mcm","clk":"4215107969","pt":1631534756529,"mc":[{"id":"1.187557985","rc":[{"batl":[[0,2.86,5.25],[1,3,4.59],[2,3.1,5.05]],"ltp":2.56,"tv":15505.18,"id":5300820},{"batb":[[1,1.54,82.12],[2,1.5,83.8]],"ltp":1.64,"tv":8165.71,"id":9629022}]}]}
{"op":"mcm","clk":"4215108090","pt":1631534758623,"mc":[{"id":"1.187557985","rc":[{"batb":[[0,2.44,72.22],[1,1.97,400.31],[2,1.8,11.88]],"ltp":2.56,"tv":15505.18,"id":5300820}]}]}
{"op":"mcm","clk":"4215108180","pt":1631534759622,"mc":[{"id":"1.187557985","rc":[{"batb":[[0,1.58,277.72],[1,1.57,156.81],[2,1.55,143.76]],"batl":[[0,1.63,148.99],[1,1.64,132.55]],"ltp":1.64,"tv":8165.71,"id":9629022}]}]}
{"op":"mcm","clk":"4215108256","pt":1631534760625,"mc":[{"id":"1.187557985","rc":[{"batl":[[0,2.84,26.25],[1,2.86,5.25],[2,3,4.59]],"ltp":2.56,"tv":15505.18,"id":5300820},{"batb":[[0,1.58,152.41],[1,1.55,143.76],[2,1.54,82.12]],"batl":[[2,1.79,5]],"ltp":1.64,"tv":8165.71,"id":9629022}]}]}
{"op":"mcm","clk":"4215108322","pt":1631534761261,"mc":[{"id":"1.187557985","rc":[{"batb":[[0,2.48,2.89],[1,2.44,72.22],[2,1.97,400.31]],"ltp":2.56,"tv":15505.18,"id":5300820}]}]}
{"op":"mcm","clk":"4215108467","pt":1631534763150,"mc":[{"id":"1.187557985","rc":[{"batb":[[0,1.59,131.74],[1,1.58,152.41],[2,1.55,143.76]],"ltp":1.64,"tv":8165.71,"id":9629022}]}]}
{"op":"mcm","clk":"4215108575","pt":1631534764563,"mc":[{"id":"1.187557985","rc":[{"batb":[[0,2.5,14.45],[1,2.48,2.89],[2,2.44,72.22]],"ltp":2.56,"tv":15505.18,"id":5300820},{"batb":[[0,1.59,205.34]],"ltp":1.64,"tv":8165.71,"id":9629022}]}]}
{"op":"mcm","clk":"4215108687","pt":1631534766136,"mc":[{"id":"1.187557985","rc":[{"batb":[[0,2.48,2.89],[1,2.44,72.22],[2,1.97,400.31]],"batl":[[0,2.86,5.25],[1,3,4.59],[2,3.1,5.05]],"ltp":2.56,"tv":15505.18,"id":5300820},{"batb":[[0,1.59,131.74]],"batl":[[2,1.79,0]],"ltp":1.64,"tv":8165.71,"id":9629022}]}]}
{"op":"mcm","clk":"4215108730","pt":1631534766763,"mc":[{"id":"1.187557985","rc":[{"batb":[[0,1.55,143.76],[1,1.54,82.12],[2,1.5,83.8]],"ltp":1.64,"tv":8165.71,"id":9629022}]}]}
{"op":"mcm","clk":"4215108921","pt":1631534769643,"mc":[{"id":"1.187557985","rc":[{"batb":[[0,1.55,325.74],[1,1.54,250.33]],"batl":[[0,1.69,207.42],[1,1.71,230.65]],"ltp":1.64,"tv":8165.71,"id":9629022}]}]}
{"op":"mcm","clk":"4215109704","pt":1631534779567,"mc":[{"id":"1.187557985","rc":[{"batb":[[0,2.64,724.44],[1,2.62,703.12],[2,2.6,703.12]],"batl":[[1,2.9,659.48],[2,2.92,352.04]],"ltp":2.56,"tv":15505.18,"id":5300820},{"batl":[[0,1.59,144.7],[1,1.6,144.7],[2,1.88,10.64]],"ltp":1.64,"tv":8165.71,"id":9629022}]}]}
{"op":"mcm","clk":"4215109778","pt":1631534780468,"mc":[{"id":"1.187557985","rc":[{"trd":[[2.68,31.78]],"batb":[[0,2.68,48.34],[1,2.64,724.44],[2,2.62,703.12]],"ltp":2.68,"tv":15522.13,"id":5300820}],"tv":23687.85}]}
{"op":"mcm","clk":"4215109847","pt":1631534781559,"mc":[{"id":"1.187557985","rc":[{"batl":[[0,2.86,27.24]],"ltp":2.68,"tv":15522.13,"id":5300820},{"batb":[[1,1.54,291.15]],"batl":[[2,1.66,30]],"ltp":1.64,"tv":8165.71,"id":9629022}]}]}
{"op":"mcm","clk":"4215109873","pt":1631534782085,"mc":[{"id":"1.187557985","rc":[{"batl":[[0,2.84,26.25],[1,2.86,27.24],[2,2.9,659.48]],"ltp":2.68,"tv":15522.13,"id":5300820},{"batb":[[0,1.56,33.27],[1,1.55,325.74],[2,1.54,291.15]],"ltp":1.64,"tv":8165.71,"id":9629022}]}]}
{"op":"mcm","clk":"4215110098","pt":1631534784462,"mc":[{"id":"1.187557985","rc":[{"batl":[[2,1.74,5]],"ltp":1.64,"tv":8165.71,"id":9629022}]}]}
{"op":"mcm","clk":"4215110593","pt":1631534790580,"mc":[{"id":"1.187557985","rc":[{"batb":[[1,2.58,2.89],[2,2.56,19.23]],"batl":[[0,2.86,21.99],[1,2.98,5.25],[2,3,4.59]],"ltp":2.68,"tv":15522.13,"id":5300820},{"batb":[[0,1.55,325.74],[1,1.54,209.03],[2,1.51,87.99]],"batl":[[0,1.59,140.24],[2,1.74,0]],"ltp":1.64,"tv":8165.71,"id":9629022}]}]}
{"op":"mcm","clk":"4215110652","pt":1631534791368,"mc":[{"id":"1.187557985","rc":[{"batb":[[0,2.58,2.89],[1,2.54,66.02],[2,1.97,400.31]],"batl":[[0,2.98,5.25],[1,3,4.59],[2,3.1,5.05]],"ltp":2.68,"tv":15522.13,"id":5300820},{"batb":[[0,1.51,87.99],[1,1.5,83.8],[2,1.49,166.69]],"ltp":1.64,"tv":8165.71,"id":9629022}]}]}
{"op":"mcm","clk":"4215110679","pt":1631534791684,"mc":[{"id":"1.187557985","rc":[{"batl":[[0,3.1,5.05],[1,3.2,4.53],[2,3.65,172.76]],"ltp":2.68,"tv":15522.13,"id":5300820},{"batb":[[0,1.49,166.69],[1,1.48,88.01],[2,1.46,79.88]],"ltp":1.64,"tv":8165.71,"id":9629022}]}]}
{"op":"mcm","clk":"4215110814","pt":1631534793495,"mc":[{"id":"1.187557985","rc":[{"batb":[[0,1.56,93],[1,1.49,166.69],[2,1.48,88.01]],"ltp":1.64,"tv":8165.71,"id":9629022}]}]}
{"op":"mcm","clk":"4215110870","pt":1631534794079,"mc":[{"id":"1.187557985","rc":[{"batb":[[1,2.52,66.19]],"ltp":2.68,"tv":15522.13,"id":5300820},{"batb":[[0,1.49,166.27],[1,1.48,88.01],[2,1.46,79.88]],"ltp":1.64,"tv":8165.71,"id":9629022}]}]}
{"op":"mcm","clk":"4215111056","pt":1631534796599,"mc":[{"id":"1.187557985","rc":[{"batl":[[0,2.76,18.52],[1,3.1,5.05],[2,3.2,4.53]],"ltp":2.68,"tv":15522.13,"id":5300820},{"batb":[[0,1.56,19.58],[1,1.54,139.29],[2,1.53,172.25]],"batl":[[0,1.58,193.82],[1,1.59,168.25]],"ltp":1.64,"tv":8165.71,"id":9629022}]}]}
{"op":"mcm","clk":"4215111065","pt":1631534796704,"mc":[{"id":"1.187557985","rc":[{"batl":[[0,3.1,5.05],[1,3.2,4.53],[2,3.65,172.76]],"ltp":2.68,"tv":15522.13,"id":5300820},{"batb":[[0,1.54,139.29],[1,1.53,172.25],[2,1.49,166.27]],"batl":[[1,1.59,147.75]],"ltp":1.64,"tv":8165.71,"id":9629022}]}]}
{"op":"mcm","clk":"4215111206","pt":1631534798594,"mc":[{"id":"1.187557985","rc":[{"batb":[[0,2.6,14.45],[1,2.58,2.89],[2,2.52,66.19]],"batl":[[0,2.98,4.75],[1,3.1,5.05],[2,3.2,4.53]],"ltp":2.68,"tv":15522.13,"id":5300820},{"batb":[[2,1.51,89.99]],"batl":[[2,1.73,5]],"ltp":1.64,"tv":8165.71,"id":9629022}]}]}
{"op":"mcm","clk":"4215111286","pt":1631534799597,"mc":[{"id":"1.187557985","rc":[{"batb":[[0,2.58,2.89],[1,2.52,66.19],[2,1.97,400.31]],"ltp":2.68,"tv":15522.13,"id":5300820},{"batb":[[0,1.51,89.99],[1,1.49,166.27],[2,1.48,88.01]],"ltp":1.64,"tv":8165.71,"id":9629022}]}]}
{"op":"mcm","clk":"4215111311","pt":1631534799911,"mc":[{"id":"1.187557985","rc":[{"batl":[[0,3.1,5.05],[1,3.2,4.53],[2,3.65,172.76]],"ltp":2.68,"tv":15522.13,"id":5300820},{"batb":[[0,1.49,166.27],[1,1.48,88.01],[2,1.46,79.88]],"ltp":1.64,"tv":8165.71,"id":9629022}]}]}
{"op":"mcm","clk":"4215111509","pt":1631534802640,"mc":[{"id":"1.187557985","rc":[{"batb":[[0,1.49,335.87],[1,1.48,284.82]],"batl":[[0,1.65,127.27],[1,1.66,127.14]],"ltp":1.64,"tv":8165.71,"id":9629022}]}]}
{"op":"mcm","clk":"4215111654","pt":1631534804380,"mc":[{"id":"1.187557985","rc":[{"batl":[[0,3.05,3],[1,3.1,5.05],[2,3.2,4.53]],"ltp":2.68,"tv":15522.13,"id":5300820},{"batl":[[0,1.64,4],[1,1.65,127.27],[2,1.66,127.14]],"ltp":1.64,"tv":8165.71,"id":9629022}]}]}
{"op":"mcm","clk":"4215111689","pt":1631534804900,"mc":[{"id":"1.187557985","rc":[{"batl":[[0,2.96,3],[1,3.05,3],[2,3.1,5.05]],"ltp":2.68,"tv":15522.13,"id":5300820},{"batb":[[0,1.51,5],[1,1.5,5],[2,1.49,340.87]],"ltp":1.64,"tv":8165.71,"id":9629022}]}]}
{"op":"mcm","clk":"4215111808","pt":1631534806482,"mc":[{"id":"1.187557985","rc":[{"batl":[[1,2.98,8.25],[2,3.05,3]],"ltp":2.68,"tv":15522.13,"id":5300820},{"batb":[[0,1.51,86.99]],"ltp":1.64,"tv":8165.71,"id":9629022}]}]}
{"op":"mcm","clk":"4215111825","pt":1631534806754,"mc":[{"id":"1.187557985","rc":[{"batl":[[1,2.98,3]],"ltp":2.68,"tv":15522.13,"id":5300820},{"batb":[[0,1.51,5]],"ltp":1.64,"tv":8165.71,"id":9629022}]}]}
{"op":"mcm","clk":"4215112038","pt":1631534809488,"mc":[{"id":"1.187557985","rc":[{"batl":[[1,1.65,0],[2,1.66,0]],"ltp":1.64,"tv":8165.71,"id":9629022}]}]}
{"op":"mcm","clk":"4215112163","pt":1631534811645,"mc":[{"id":"1.187557985","rc":[{"batl":[[0,3.1,5.05],[1,3.2,4.53],[2,3.65,172.76]],"ltp":2.68,"tv":15522.13,"id":5300820},{"batb":[[0,1.49,335.87],[1,1.48,284.82],[2,1.46,79.88]],"ltp":1.64,"tv":8165.71,"id":9629022}]}]}
{"op":"mcm","clk":"4215112232","pt":1631534812642,"mc":[{"id":"1.187557985","rc":[{"batb":[[0,2.86,668.7],[1,2.84,649.04],[2,2.82,649.04]],"batl":[[1,3.2,333.24],[2,3.25,319.04]],"ltp":2.68,"tv":15522.13,"id":5300820},{"batl":[[0,1.53,237.86],[1,1.54,166],[2,1.64,4]],"ltp":1.64,"tv":8165.71,"id":9629022}]}]}
{"op":"mcm","clk":"4215112302","pt":1631534813645,"mc":[{"id":"1.187557985","rc":[{"trd":[[2.88,22.73]],"batb":[[0,2.88,47.61],[1,2.86,668.7],[2,2.84,649.04]],"batl":[[0,3.1,25.75]],"ltp":2.88,"tv":15530.26,"id":5300820},{"trd":[[1.53,15.3]],"batb":[[2,1.47,43.75]],"batl":[[0,1.53,222.56],[2,1.58,30]],"ltp":1.53,"tv":8181.01,"id":9629022}],"tv":23711.28}]}
{"op":"mcm","clk":"4215112377","pt":1631534814850,"mc":[{"id":"1.187557985","rc":[{"batl":[[0,3.05,24.01],[1,3.1,25.75],[2,3.2,333.24]],"ltp":2.88,"tv":15530.26,"id":5300820},{"batb":[[0,1.49,382.04]],"ltp":1.53,"tv":8181.01,"id":9629022}]}]}
{"op":"mcm","clk":"4215112576","pt":1631534817648,"mc":[{"id":"1.187557985","rc":[{"batb":[[0,1.49,212.44],[1,1.48,88.01]],"batl":[[0,1.63,25],[1,1.64,4],[2,1.82,10.99]],"ltp":1.53,"tv":8181.01,"id":9629022}]}]}
{"op":"mcm","clk":"4215112655","pt":1631534818647,"mc":[{"id":"1.187557985","rc":[{"batl":[[0,1.63,5]],"ltp":1.53,"tv":8181.01,"id":9629022}]}]}
{"op":"mcm","clk":"4215112862","pt":1631534820659,"mc":[{"id":"1.187557985","rc":[{"batl":[[0,1.57,30],[1,1.63,5],[2,1.64,4]],"ltp":1.53,"tv":8181.01,"id":9629022}]}]}
{"op":"mcm","clk":"4215112960","pt":1631534821545,"mc":[{"id":"1.187557985","rc":[{"batl":[[0,1.63,5],[1,1.64,4],[2,1.82,10.99]],"ltp":1.53,"tv":8181.01,"id":9629022}]}]}
{"op":"mcm","clk":"4215113237","pt":1631534824647,"mc":[{"id":"1.187557985","rc":[{"batl":[[0,1.56,42.15],[1,1.63,5],[2,1.64,4]],"ltp":1.53,"tv":8181.01,"id":9629022}]}]}
{"op":"mcm","clk":"4215113324","pt":1631534825231,"mc":[{"id":"1.187557985","rc":[{"batb":[[0,1.49,391.08],[1,1.48,284.82]],"batl":[[0,1.53,229.06],[1,1.54,165.99],[2,1.58,30]],"ltp":1.53,"tv":8181.01,"id":9629022}]}]}
{"op":"mcm","clk":"4215113762","pt":1631534830581,"mc":[{"id":"1.187557985","rc":[{"batb":[[0,2.76,17.04],[1,2.66,57.4],[2,2.6,3]],"batl":[[0,3.1,20.7],[1,3.4,4.19],[2,3.65,172.76]],"ltp":2.88,"tv":15530.26,"id":5300820},{"batb":[[0,1.47,43.75],[1,1.43,3.41],[2,1.42,293.36]],"batl":[[0,1.63,5],[1,1.54,0],[2,1.58,0]],"ltp":1.53,"tv":8181.01,"id":9629022}]}]}
{"op":"mcm","clk":"4215113814","pt":1631534831469,"mc":[{"id":"1.187557985","rc":[{"batb":[[0,2.66,57.4],[1,2.6,3],[2,2.58,2.89]],"batl":[[0,3.4,4.19],[1,3.65,172.76],[2,3.65,0]],"ltp":2.88,"tv":15530.26,"id":5300820},{"batb":[[0,1.43,3.41],[1,1.42,293.36],[2,1.37,4]],"ltp":1.53,"tv":8181.01,"id":9629022}]}]}
{"op":"mcm","clk":"4215113983","pt":1631534833559,"mc":[{"id":"1.187557985","rc":[{"batl":[[0,3.1,3],[1,3.4,4.19],[2,3.65,172.76]],"ltp":2.88,"tv":15530.26,"id":5300820},{"batb":[[0,1.47,7],[1,1.46,7],[2,1.43,3.41]],"ltp":1.53,"tv":8181.01,"id":9629022}]}]}
{"op":"mcm","clk":"4215114046","pt":1631534834654,"mc":[{"id":"1.187557985","rc":[{"batb":[[0,2.66,61.4],[1,2.64,3],[2,2.6,3]],"batl":[[1,3.15,3],[2,3.4,7.19]],"ltp":2.88,"tv":15530.26,"id":5300820},{"batb":[[2,1.44,7]],"batl":[[0,1.61,3],[1,1.63,5]],"ltp":1.53,"tv":8181.01,"id":9629022}]}]}
{"op":"mcm","clk":"4215114222","pt":1631534836549,"mc":[{"id":"1.187557985","rc":[{"batb":[[0,2.68,3],[1,2.66,61.4],[2,2.64,3]],"ltp":2.88,"tv":15530.26,"id":5300820},{"batb":[[0,1.47,333.57],[1,1.46,216.37]],"batl":[[0,1.52,297.62],[1,1.53,169.69],[2,1.59,6]],"ltp":1.53,"tv":8181.01,"id":9629022}]}]}
{"op":"mcm","clk":"4215114261","pt":1631534837180,"mc":[{"id":"1.187557985","rc":[{"batl":[[2,3.25,4.14]],"ltp":2.88,"tv":15530.26,"id":5300820},{"batb":[[2,1.45,88.81]],"ltp":1.53,"tv":8181.01,"id":9629022}]}]}
{"op":"mcm","clk":"4215114343","pt":1631534838495,"mc":[{"id":"1.187557985","rc":[{"batl":[[2,3.4,7.19]],"ltp":2.88,"tv":15530.26,"id":5300820},{"batb":[[0,1.47,7],[1,1.46,7],[2,1.44,7]],"batl":[[0,1.59,6],[1,1.61,3],[2,1.63,5]],"ltp":1.53,"tv":8181.01,"id":9629022}]}]}
{"op":"mcm","clk":"4215114563","pt":1631534841452,"mc":[{"id":"1.187557985","rc":[{"batl":[[0,1.59,167.78],[1,1.6,144.55],[2,1.61,3]],"ltp":1.53,"tv":8181.01,"id":9629022}]}]}
{"op":"mcm","clk":"4215114850","pt":1631534845176,"mc":[{"id":"1.187557985","rc":[{"batb":[[1,1.44,7],[2,1.43,8.41]],"ltp":1.53,"tv":8181.01,"id":9629022}]}]}
{"op":"mcm","clk":"4215114933","pt":1631534846271,"mc":[{"id":"1.187557985","rc":[{"batb":[[1,2.66,57.4],[2,2.58,2.89]],"batl":[[1,3.4,4.19],[2,3.65,172.76]],"ltp":2.88,"tv":15530.26,"id":5300820},{"batb":[[1,1.43,3.41],[2,1.42,293.36]],"batl":[[2,1.61,0]],"ltp":1.53,"tv":8181.01,"id":9629022}]}]}
{"op":"mcm","clk":"4215115096","pt":1631534848359,"mc":[{"id":"1.187557985","rc":[{"batb":[[0,2.66,57.4],[1,2.58,2.89],[2,1.97,400.31]],"ltp":2.88,"tv":15530.26,"id":5300820},{"batb":[[1,1.46,5],[2,1.43,3.41]],"batl":[[0,1.59,161.78]],"ltp":1.53,"tv":8181.01,"id":9629022}]}]}
{"op":"mcm","clk":"4215115196","pt":1631534849465,"mc":[{"id":"1.187557985","rc":[{"trd":[[2.68,40.25]],"batb":[[0,2.66,60.4],[1,2.64,724.44],[2,2.62,386.72]],"batl":[[0,2.86,16.25],[1,2.9,659.48],[2,2.92,640.08]],"ltp":2.68,"tv":15538.73,"id":5300820},{"trd":[[1.59,918.22]],"batb":[[0,1.55,159.22],[1,1.54,259.16],[2,1.47,7]],"batl":[[0,1.59,147.5]],"ltp":1.59,"tv":8195.29,"id":9629022}],"tv":23734.03}]}
{"op":"mcm","clk":"4215115277","pt":1631534850461,"mc":[{"id":"1.187557985","rc":[{"batb":[[0,2.66,57.4]],"batl":[[1,2.9,681.24]],"ltp":2.68,"tv":15538.73,"id":5300820},{"batb":[[0,1.55,301.64],[2,1.52,41.6]],"batl":[[2,1.88,10.64]],"ltp":1.59,"tv":8195.29,"id":9629022}]}]}
{"op":"mcm","clk":"4215115443","pt":1631534852612,"mc":[{"id":"1.187557985","rc":[{"batl":[[1,2.88,3],[2,2.9,681.24]],"ltp":2.68,"tv":15538.73,"id":5300820},{"batb":[[2,1.53,5]],"ltp":1.59,"tv":8195.29,"id":9629022}]}]}
{"op":"mcm","clk":"4215115584","pt":1631534854403,"mc":[{"id":"1.187557985","rc":[{"batl":[[0,2.84,27.6],[1,2.86,16.25],[2,2.88,3]],"ltp":2.68,"tv":15538.73,"id":5300820},{"batb":[[0,1.55,344.61]],"ltp":1.59,"tv":8195.29,"id":9629022}]}]}
{"op":"mcm","clk":"4215115754","pt":1631534856494,"mc":[{"id":"1.187557985","rc":[{"batb":[[2,1.53,46.2]],"ltp":1.59,"tv":8195.29,"id":9629022}]}]}
{"op":"mcm","clk":"4215115839","pt":1631534857390,"mc":[{"id":"1.187557985","rc":[{"batl":[[1,2.86,38.24]],"ltp":2.68,"tv":15538.73,"id":5300820}]}]}
{"op":"mcm","clk":"4215115961","pt":1631534859376,"mc":[{"id":"1.187557985","rc":[{"trd":[[1.55,21.26]],"batb":[[0,1.55,341.63]],"ltp":1.55,"tv":8201.25,"id":9629022}],"tv":23739.99}]}
{"op":"mcm","clk":"4215116512","pt":1631534866480,"mc":[{"id":"1.187557985","rc":[{"batb":[[0,2.58,2.89],[1,2.56,19.23],[2,2.52,66.61]],"batl":[[0,2.86,21.99],[1,2.94,5.25],[2,3.05,4.5]],"ltp":2.68,"tv":15538.73,"id":5300820},{"batb":[[0,1.53,41.2],[1,1.52,90.24],[2,1.49,255.7]],"ltp":1.55,"tv":8201.25,"id":9629022}]}]}
{"op":"mcm","clk":"4215116615","pt":1631534867577,"mc":[{"id":"1.187557985","rc":[{"batb":[[1,2.52,66.61],[2,1.97,400.31]],"batl":[[0,3.05,4.5],[1,3.4,4.19],[2,3.65,172.76]],"ltp":2.68,"tv":15538.73,"id":5300820},{"batb":[[0,1.52,6],[1,1.49,255.7],[2,1.43,3.41]],"ltp":1.55,"tv":8201.25,"id":9629022}]}]}
{"op":"mcm","clk":"4215116758","pt":1631534869573,"mc":[{"id":"1.187557985","rc":[{"batb":[[1,1.49,407.82],[2,1.48,196.57]],"batl":[[0,1.64,30],[1,1.65,140.3],[2,1.66,127.03]],"ltp":1.55,"tv":8201.25,"id":9629022}]}]}
{"op":"mcm","clk":"4215116799","pt":1631534870207,"mc":[{"id":"1.187557985","rc":[{"batl":[[0,1.64,4]],"ltp":1.55,"tv":8201.25,"id":9629022}]}]}
{"op":"mcm","clk":"4215116857","pt":1631534870986,"mc":[{"id":"1.187557985","rc":[{"batl":[[0,2.9,3],[1,2.94,3],[2,3.05,4.5]],"ltp":2.68,"tv":15538.73,"id":5300820},{"batb":[[1,1.51,4],[2,1.49,255.7]],"batl":[[1,1.65,0],[2,1.66,0]],"ltp":1.55,"tv":8201.25,"id":9629022}]}]}
{"op":"mcm","clk":"4215117032","pt":1631534873389,"mc":[{"id":"1.187557985","rc":[{"batl":[[2,3.05,7.5]],"ltp":2.68,"tv":15538.73,"id":5300820}]}]}
{"op":"mcm","clk":"4215117096","pt":1631534874217,"mc":[{"id":"1.187557985","rc":[{"batl":[[1,2.94,8.25]],"ltp":2.68,"tv":15538.73,"id":5300820},{"batb":[[0,1.53,295.7],[1,1.52,276.82],[2,1.51,4]],"batl":[[0,1.58,209.19],[1,1.59,147.59],[2,1.64,4]],"ltp":1.55,"tv":8201.25,"id":9629022}]}]}
{"op":"mcm","clk":"4215117158","pt":1631534875106,"mc":[{"id":"1.187557985","rc":[{"batb":[[0,2.6,14.45],[1,2.58,2.89],[2,2.52,66.61]],"batl":[[0,2.88,15],[1,2.9,3],[2,2.94,8.25]],"ltp":2.68,"tv":15538.73,"id":5300820},{"batl":[[2,1.63,20]],"ltp":1.55,"tv":8201.25,"id":9629022}]}]}
{"op":"mcm","clk":"4215117345","pt":1631534877605,"mc":[{"id":"1.187557985","rc":[{"batb":[[0,2.58,2.89],[1,2.52,66.61],[2,1.97,400.31]],"batl":[[0,2.9,3],[1,2.94,8.25],[2,3.05,7.5]],"ltp":2.68,"tv":15538.73,"id":5300820},{"batb":[[0,1.52,99.24],[1,1.51,4],[2,1.49,255.7]],"batl":[[0,1.64,4],[1,1.59,0],[2,1.63,0]],"ltp":1.55,"tv":8201.25,"id":9629022}]}]}
{"op":"mcm","clk":"4215117414","pt":1631534878497,"mc":[{"id":"1.187557985","rc":[{"batl":[[1,2.94,3]],"ltp":2.68,"tv":15538.73,"id":5300820},{"batb":[[0,1.52,6]],"ltp":1.55,"tv":8201.25,"id":9629022}]}]}
{"op":"mcm","clk":"4215117608","pt":1631534881431,"mc":[{"id":"1.187557985","rc":[{"batl":[[0,3.05,4.5],[1,3.4,4.19],[2,3.65,172.76]],"ltp":2.68,"tv":15538.73,"id":5300820},{"batb":[[0,1.49,407.82],[1,1.48,196.57],[2,1.43,3.41]],"batl":[[0,1.65,140.3],[1,1.66,127.03]],"ltp":1.55,"tv":8201.25,"id":9629022}]}]}
{"op":"mcm","clk":"4215118044","pt":1631534887609,"mc":[{"id":"1.187557985","rc":[{"batl":[[0,1.53,1689.54]],"ltp":1.55,"tv":8201.25,"id":9629022}]}]}
{"op":"mcm","clk":"4215118111","pt":1631534888445,"mc":[{"id":"1.187557985","rc":[{"batb":[[0,2.86,1337.42],[1,2.84,1298.08],[2,2.82,1298.08]],"batl":[[1,3.2,1195.32],[2,3.25,1160.16]],"ltp":2.68,"tv":15538.73,"id":5300820},{"batl":[[0,1.81,11.05]],"ltp":1.55,"tv":8201.25,"id":9629022}]}]}
{"op":"mcm","clk":"4215118190","pt":1631534889447,"mc":[{"id":"1.187557985","rc":[{"trd":[[2.88,30.86]],"batb":[[0,2.86,668.7],[1,2.84,649.04],[2,2.82,649.04]],"batl":[[1,3.2,328.71],[2,3.25,319.04]],"ltp":2.88,"tv":15546.86,"id":5300820},{"trd":[[1.53,30.6]],"batl":[[0,1.53,238.74],[1,1.54,165.8],[2,1.81,11.05]],"ltp":1.53,"tv":8216.55,"id":9629022}],"tv":23763.42}]}
{"op":"mcm","clk":"4215118269","pt":1631534890642,"mc":[{"id":"1.187557985","rc":[{"batb":[[0,2.88,47.53],[1,2.86,668.7],[2,2.84,649.04]],"batl":[[1,3.15,20.45],[2,3.2,328.71]],"ltp":2.88,"tv":15546.86,"id":5300820},{"batb":[[2,1.47,43.75]],"ltp":1.53,"tv":8216.55,"id":9629022}]}]}
{"op":"mcm","clk":"4215118322","pt":1631534891526,"mc":[{"id":"1.187557985","rc":[{"batb":[[0,1.49,453.99]],"batl":[[2,1.66,5]],"ltp":1.53,"tv":8216.55,"id":9629022}]}]}
{"op":"mcm","clk":"4215118572","pt":1631534894556,"mc":[{"id":"1.187557985","rc":[{"batl":[[2,1.57,30]],"ltp":1.53,"tv":8216.55,"id":9629022}]}]}
{"op":"mcm","clk":"4215118851","pt":1631534898235,"mc":[{"id":"1.187557985","rc":[{"batl":[[0,3.05,28.51]],"ltp":2.88,"tv":15546.86,"id":5300820}]}]}
{"op":"mcm","clk":"4215119241","pt":1631534903648,"mc":[{"id":"1.187557985","rc":[{"batb":[[1,2.76,17.04],[2,2.66,57.49]],"batl":[[0,3.05,4.5],[2,3.25,4.62]],"ltp":2.88,"tv":15546.86,"id":5300820},{"batb":[[0,1.49,407.82]],"ltp":1.53,"tv":8216.55,"id":9629022}]}]}
{"op":"mcm","clk":"4215119281","pt":1631534904168,"mc":[{"id":"1.187557985","rc":[{"batb":[[0,2.76,17.04],[1,2.66,57.49],[2,2.58,2.89]],"batl":[[0,3.15,20.45],[1,3.4,4.19],[2,3.65,172.76]],"ltp":2.88,"tv":15546.86,"id":5300820},{"batb":[[0,1.47,43.75],[1,1.43,3.41],[2,1.42,292.02]],"batl":[[0,1.57,30],[1,1.54,0],[2,1.57,0]],"ltp":1.53,"tv":8216.55,"id":9629022}]}]}
{"op":"mcm","clk":"4215119373","pt":1631534905436,"mc":[{"id":"1.187557985","rc":[{"batb":[[0,2.66,57.49],[1,2.58,2.89],[2,1.97,400.31]],"batl":[[0,3.4,4.19],[1,3.65,172.76],[2,3.65,0]],"ltp":2.88,"tv":15546.86,"id":5300820},{"batb":[[0,1.43,3.41],[1,1.42,292.02],[2,1.37,4]],"ltp":1.53,"tv":8216.55,"id":9629022}]}]}
{"op":"mcm","clk":"4215119498","pt":1631534907365,"mc":[{"id":"1.187557985","rc":[{"batl":[[0,3.15,3],[1,3.25,4.54],[2,3.4,4.19]],"ltp":2.88,"tv":15546.86,"id":5300820},{"batb":[[0,1.47,7],[1,1.46,7],[2,1.45,86.81]],"batl":[[0,1.59,176.12],[1,1.6,144.4]],"ltp":1.53,"tv":8216.55,"id":9629022}]}]}
{"op":"mcm","clk":"4215119519","pt":1631534907728,"mc":[{"id":"1.187557985","rc":[{"batl":[[1,3.4,4.19],[2,3.65,172.76]],"ltp":2.88,"tv":15546.86,"id":5300820},{"batb":[[2,1.43,3.41]],"ltp":1.53,"tv":8216.55,"id":9629022}]}]}
{"op":"mcm","clk":"4215119614","pt":1631534909456,"mc":[{"id":"1.187557985","rc":[{"batb":[[0,2.66,60.49],[1,2.64,4],[2,2.58,2.89]],"batl":[[1,3.4,7.19]],"ltp":2.88,"tv":15546.86,"id":5300820},{"batb":[[2,1.45,7]],"batl":[[0,1.61,5],[1,1.6,0]],"ltp":1.53,"tv":8216.55,"id":9629022}]}]}
{"op":"mcm","clk":"4215119646","pt":1631534909939,"mc":[{"id":"1.187557985","rc":[{"batb":[[0,2.68,4],[1,2.66,60.49],[2,2.64,4]],"ltp":2.88,"tv":15546.86,"id":5300820},{"batl":[[0,1.59,3],[1,1.61,5]],"ltp":1.53,"tv":8216.55,"id":9629022}]}]}
{"op":"mcm","clk":"4215119764","pt":1631534911358,"mc":[{"id":"1.187557985","rc":[{"batl":[[0,3.4,7.19],[1,3.4,0],[2,3.65,0]],"ltp":2.88,"tv":15546.86,"id":5300820},{"batb":[[0,1.43,3.41],[1,1.42,649.15],[2,1.41,243.48]],"ltp":1.53,"tv":8216.55,"id":9629022}]}]}
{"op":"mcm","clk":"4215119864","pt":1631534912659,"mc":[{"id":"1.187557985","rc":[{"batl":[[0,1.46,2214.82],[1,1.47,1500.27],[2,1.48,1262.74]],"ltp":1.53,"tv":8216.55,"id":9629022}]}]}
{"op":"mcm","clk":"4215119923","pt":1631534913648,"mc":[{"id":"1.187557985","rc":[{"trd":[[3.15,7.63]],"batb":[[0,3.1,95.31],[1,2.96,15.3],[2,2.88,47.7]],"ltp":3.15,"tv":15554.49,"id":5300820},{"trd":[[1.46,16.46]],"batl":[[0,1.46,195.09]],"ltp":1.46,"tv":8233.01,"id":9629022}],"tv":23787.51}]}
{"op":"mcm","clk":"4215120001","pt":1631534914546,"mc":[{"id":"1.187557985","rc":[{"batl":[[0,3.35,21.74],[1,3.4,7.19]],"ltp":3.15,"tv":15554.49,"id":5300820},{"batb":[[0,1.43,20.46],[2,1.41,290.33]],"ltp":1.46,"tv":8233.01,"id":9629022}]}]}
{"op":"mcm","clk":"4215120073","pt":1631534915650,"mc":[{"id":"1.187557985","rc":[{"batb":[[1,3.05,3],[2,3,3]],"batl":[[2,4.6,137.93]],"ltp":3.15,"tv":15554.49,"id":5300820}]}]}
{"op":"mcm","clk":"4215120086","pt":1631534915964,"mc":[{"id":"1.187557985","rc":[{"batl":[[1,3.4,4.19]],"ltp":3.15,"tv":15554.49,"id":5300820}]}]}
{"op":"mcm","clk":"4215120187","pt":1631534917477,"mc":[{"id":"1.187557985","rc":[{"batl":[[1,3.4,23.55]],"ltp":3.15,"tv":15554.49,"id":5300820}]}]}
{"op":"mcm","clk":"4215120336","pt":1631534919307,"mc":[{"id":"1.187557985","rc":[{"batl":[[2,3.65,111.04]],"ltp":3.15,"tv":15554.49,"id":5300820},{"batb":[[0,1.43,88.46]],"ltp":1.46,"tv":8233.01,"id":9629022}]}]}
{"op":"mcm","clk":"4215120512","pt":1631534921604,"mc":[{"id":"1.187557985","rc":[{"batb":[[2,3,18]],"ltp":3.15,"tv":15554.49,"id":5300820},{"batb":[[0,1.43,20.46]],"ltp":1.46,"tv":8233.01,"id":9629022}]}]}
{"op":"mcm","clk":"4215120675","pt":1631534924315,"mc":[{"id":"1.187557985","rc":[{"batb":[[0,1.44,224],[1,1.43,20.46],[2,1.42,649.15]],"ltp":1.46,"tv":8233.01,"id":9629022}]}]}
{"op":"mcm","clk":"4215120759","pt":1631534925618,"mc":[{"id":"1.187557985","rc":[{"batb":[[1,3,15],[2,2.92,148.56]],"batl":[[0,3.4,23.55],[1,3.65,111.04],[2,3.7,152.7]],"ltp":3.15,"tv":15554.49,"id":5300820},{"batb":[[1,1.43,3.41]],"batl":[[1,1.47,199.25],[2,1.49,6.1]],"ltp":1.46,"tv":8233.01,"id":9629022}]}]}
{"op":"mcm","clk":"4215120836","pt":1631534926614,"mc":[{"id":"1.187557985","rc":[{"batb":[[0,3,15],[1,2.92,148.56],[2,2.9,164.22]],"batl":[[0,3.4,19.36]],"ltp":3.15,"tv":15554.49,"id":5300820},{"batb":[[0,1.43,3.41],[1,1.41,46.85],[2,1.38,87.46]],"batl":[[0,1.49,6.1],[1,1.5,30],[2,1.52,331.61]],"ltp":1.46,"tv":8233.01,"id":9629022}]}]}
{"op":"mcm","clk":"4215120894","pt":1631534927406,"mc":[{"id":"1.187557985","rc":[{"batb":[[0,2.92,152.75],[1,2.9,164.22],[2,2.88,241.02]],"batl":[[0,3.65,106.94],[1,3.7,152.7],[2,3.75,173.38]],"ltp":3.15,"tv":15554.49,"id":5300820},{"batb":[[1,1.37,322.45],[2,1.36,454.65]],"batl":[[1,1.52,375.62],[2,1.53,387.28]],"ltp":1.46,"tv":8233.01,"id":9629022}]}]}
{"op":"mcm","clk":"4215121023","pt":1631534929187,"mc":[{"id":"1.187557985","rc":[{"batb":[[2,1.36,763.76]],"batl":[[2,1.53,648.85]],"ltp":1.46,"tv":8233.01,"id":9629022}]}]}
{"op":"mcm","clk":"4215121321","pt":1631534933399,"mc":[{"id":"1.187557985","rc":[{"batl":[[0,3.65,4.3],[1,3.9,3.65],[2,3.95,3.7]],"ltp":3.15,"tv":15554.49,"id":5300820},{"batb":[[1,1.38,100.96],[2,1.37,4]],"ltp":1.46,"tv":8233.01,"id":9629022}]}]}
{"op":"mcm","clk":"4215121402","pt":1631534934605,"mc":[{"id":"1.187557985","rc":[{"batl":[[0,3.9,3.65],[1,3.95,3.7],[2,3.95,0]],"ltp":3.15,"tv":15554.49,"id":5300820},{"batb":[[1,1.37,4],[2,1.35,350.85]],"ltp":1.46,"tv":8233.01,"id":9629022}]}]}
{"op":"mcm","clk":"4215121505","pt":1631534936530,"mc":[{"id":"1.187557985","rc":[{"trd":[[2.92,10.06],[3,6.17]],"batb":[[0,2.92,147.72]],"batl":[[0,3.1,15.05],[1,3.15,616.94],[2,3.25,598.8]],"ltp":2.92,"tv":15567.58,"id":5300820},{"trd":[[1.49,6.1]],"batb":[[0,1.49,143.98],[1,1.48,291.22],[2,1.43,3.41]],"batl":[[0,1.52,375.62],[1,1.53,648.85],[2,1.54,609.44]],"ltp":1.49,"tv":8239.11,"id":9629022}],"tv":23806.7}]}
{"op":"mcm","clk":"4215121576","pt":1631534937524,"mc":[{"id":"1.187557985","rc":[{"batl":[[2,3.2,20.22]],"ltp":2.92,"tv":15567.58,"id":5300820},{"batb":[[0,1.49,310.09],[2,1.44,17.05]],"ltp":1.49,"tv":8239.11,"id":9629022}]}]}
{"op":"mcm","clk":"4215121631","pt":1631534938209,"mc":[{"id":"1.187557985","rc":[{"batl":[[2,3.25,598.8]],"ltp":2.92,"tv":15567.58,"id":5300820},{"batb":[[2,1.43,203.24]],"ltp":1.49,"tv":8239.11,"id":9629022}]}]}
{"op":"mcm","clk":"4215121702","pt":1631534939210,"mc":[{"id":"1.187557985","rc":[{"batb":[[2,1.47,6]],"ltp":1.49,"tv":8239.11,"id":9629022}]}]}
{"op":"mcm","clk":"4215121871","pt":1631534941539,"mc":[{"id":"1.187557985","rc":[{"batl":[[0,3.05,22.44],[1,3.1,15.05],[2,3.15,616.94]],"ltp":2.92,"tv":15567.58,"id":5300820},{"batb":[[0,1.49,353.04]],"ltp":1.49,"tv":8239.11,"id":9629022}]}]}
{"op":"mcm","clk":"4215122104","pt":1631534944635,"mc":[{"id":"1.187557985","rc":[{"batl":[[1,3.1,35.75]],"ltp":2.92,"tv":15567.58,"id":5300820},{"batb":[[0,1.5,224],[1,1.49,353.04],[2,1.48,291.22]],"ltp":1.49,"tv":8239.11,"id":9629022}]}]}
{"op":"mcm","clk":"4215122486","pt":1631534949631,"mc":[{"id":"1.187557985","rc":[{"batb":[[0,2.92,4.19],[1,2.88,47.7],[2,2.76,17.04]],"batl":[[0,3.1,35.75],[1,3.35,4.5],[2,3.6,4.16]],"ltp":2.92,"tv":15567.58,"id":5300820},{"batb":[[1,1.49,310.09]],"batl":[[0,1.52,44.01],[1,1.53,261.57],[2,1.54,165.7]],"ltp":1.49,"tv":8239.11,"id":9629022}]}]}
{"op":"mcm","clk":"4215122514","pt":1631534950045,"mc":[{"id":"1.187557985","rc":[{"batb":[[0,2.76,17.04],[1,2.7,3],[2,2.66,57.49]],"batl":[[0,3.1,20.7]],"ltp":2.92,"tv":15567.58,"id":5300820},{"batb":[[1,1.47,43.75],[2,1.44,6]],"batl":[[0,1.58,5],[1,1.53,0],[2,1.54,0]],"ltp":1.49,"tv":8239.11,"id":9629022}]}]}
{"op":"mcm","clk":"4215122598","pt":1631534951457,"mc":[{"id":"1.187557985","rc":[{"batb":[[0,2.7,3],[1,2.66,57.49],[2,2.58,2.89]],"batl":[[0,3.35,4.5],[1,3.6,4.16],[2,3.9,164.08]],"ltp":2.92,"tv":15567.58,"id":5300820},{"batb":[[0,1.44,6],[1,1.43,296.67],[2,1.39,95.91]],"ltp":1.49,"tv":8239.11,"id":9629022}]}]}
{"op":"mcm","clk":"4215122656","pt":1631534952138,"mc":[{"id":"1.187557985","rc":[{"batb":[[1,1.43,290.67]],"batl":[[0,1.58,5.25]],"ltp":1.49,"tv":8239.11,"id":9629022}]}]}
{"op":"mcm","clk":"4215122739","pt":1631534953441,"mc":[{"id":"1.187557985","rc":[{"batb":[[0,2.76,4],[1,2.74,3],[2,2.7,3]],"ltp":2.92,"tv":15567.58,"id":5300820},{"batb":[[2,1.42,339.33]],"batl":[[0,1.57,4.25],[1,1.58,5],[2,1.59,191.26]],"ltp":1.49,"tv":8239.11,"id":9629022}]}]}
{"op":"mcm","clk":"4215122818","pt":1631534954649,"mc":[{"id":"1.187557985","rc":[{"batb":[[2,2.72,3]],"batl":[[0,3.3,3],[1,3.35,4.5],[2,3.6,4.16]],"ltp":2.92,"tv":15567.58,"id":5300820}]}]}
{"op":"mcm","clk":"4215122881","pt":1631534955439,"mc":[{"id":"1.187557985","rc":[{"batb":[[1,1.43,295.67]],"batl":[[2,1.59,0]],"ltp":1.49,"tv":8239.11,"id":9629022}]}]}
{"op":"mcm","clk":"4215123105","pt":1631534958626,"mc":[{"id":"1.187557985","rc":[{"batb":[[0,2.78,657.72],[1,2.76,4],[2,2.74,3]],"batl":[[0,3.35,4.5],[1,3.6,4.16],[2,3.9,3.65]],"ltp":2.92,"tv":15567.58,"id":5300820},{"batb":[[0,1.43,290.67],[1,1.42,339.33],[2,1.41,243.31]],"batl":[[0,1.46,2326.43],[1,1.47,1500.13],[2,1.48,1262.74]],"ltp":1.49,"tv":8239.11,"id":9629022}]}]}
{"op":"mcm","clk":"4215123170","pt":1631534959571,"mc":[{"id":"1.187557985","rc":[{"trd":[[3.15,15.26]],"batb":[[0,3.1,95.73],[1,2.96,15.3],[2,2.84,48.79]],"batl":[[1,3.4,19.36],[2,3.6,4.16]],"ltp":3.15,"tv":15575.21,"id":5300820},{"trd":[[1.46,32.92]],"batb":[[2,1.41,290.16]],"batl":[[0,1.46,212.59]],"ltp":1.46,"tv":8255.57,"id":9629022}],"tv":23830.79}]}
{"op":"mcm","clk":"4215123332","pt":1631534961662,"mc":[{"id":"1.187557985","rc":[{"batl":[[0,3.35,24.8]],"ltp":3.15,"tv":15575.21,"id":5300820},{"batb":[[0,1.43,331.01]],"ltp":1.46,"tv":8255.57,"id":9629022}]}]}
{"op":"mcm","clk":"4215123403","pt":1631534962448,"mc":[{"id":"1.187557985","rc":[{"batb":[[1,3.05,3],[2,3,4]],"ltp":3.15,"tv":15575.21,"id":5300820}]}]}
{"op":"mcm","clk":"4215123501","pt":1631534963643,"mc":[{"id":"1.187557985","rc":[{"trd":[[3.15,23.92]],"ltp":3.15,"tv":15583.87,"id":5300820},{"trd":[[1.46,51.6]],"batb":[[0,1.44,179],[1,1.43,331.01],[2,1.42,339.33]],"batl":[[0,1.46,193.91]],"ltp":1.46,"tv":8274.25,"id":9629022}],"tv":23858.13}]}
{"op":"mcm","clk":"4215123805","pt":1631534967658,"mc":[{"id":"1.187557985","rc":[{"batb":[[2,3,19]],"ltp":3.15,"tv":15583.87,"id":5300820}]}]}
{"op":"mcm","clk":"4215124292","pt":1631534974590,"mc":[{"id":"1.187557985","rc":[{"batb":[[2,3,15]],"ltp":3.15,"tv":15583.87,"id":5300820},{"trd":[[1.44,0.54]],"batb":[[0,1.44,178.73]],"batl":[[1,1.47,199.11],[2,1.49,6.17]],"ltp":1.44,"tv":8274.79,"id":9629022}],"tv":23858.67}]}
{"op":"mcm","clk":"4215124339","pt":1631534975052,"mc":[{"id":"1.187557985","rc":[{"batb":[[0,3.05,3],[1,3,15],[2,2.92,178.07]],"batl":[[0,3.4,19.36],[1,3.65,120.34],[2,3.7,149.25]],"ltp":3.15,"tv":15583.87,"id":5300820},{"batb":[[1,1.43,3.41],[2,1.41,46.85]],"batl":[[0,1.49,6.17],[1,1.5,30],[2,1.52,269.23]],"ltp":1.44,"tv":8274.79,"id":9629022}]}]}
{"op":"mcm","clk":"4215124455","pt":1631534976455,"mc":[{"id":"1.187557985","rc":[{"batb":[[0,2.92,178.07],[1,2.9,182.42],[2,2.88,176.18]],"batl":[[0,3.65,116.44],[1,3.7,149.25],[2,3.75,186.89]],"ltp":3.15,"tv":15583.87,"id":5300820},{"batb":[[0,1.43,3.41],[1,1.37,413.06],[2,1.36,392.84]],"batl":[[1,1.52,269.23],[2,1.53,277.57]],"ltp":1.44,"tv":8274.79,"id":9629022}]}]}
{"op":"mcm","clk":"4215124548","pt":1631534977606,"mc":[{"id":"1.187557985","rc":[{"batb":[[0,3,3],[1,2.92,178.07],[2,2.9,182.42]],"ltp":3.15,"tv":15583.87,"id":5300820}]}]}
{"op":"mcm","clk":"4215124607","pt":1631534978184,"mc":[{"id":"1.187557985","rc":[{"batb":[[0,2.92,178.07],[1,2.9,182.42],[2,2.88,176.18]],"ltp":3.15,"tv":15583.87,"id":5300820}]}]}
{"op":"mcm","clk":"4215124713","pt":1631534979588,"mc":[{"id":"1.187557985","rc":[{"batb":[[0,2.92,180.07],[1,2.9,184.42]],"ltp":3.15,"tv":15583.87,"id":5300820}]}]}
{"op":"mcm","clk":"4215124760","pt":1631534980374,"mc":[{"id":"1.187557985","rc":[{"batl":[[0,3.3,18.35],[1,3.65,116.44],[2,3.7,149.25]],"ltp":3.15,"tv":15583.87,"id":5300820},{"batb":[[0,1.43,25.84],[1,1.41,289.62],[2,1.4,250.57]],"batl":[[0,1.45,281.87],[1,1.46,225.75],[2,1.49,6.17]],"ltp":1.44,"tv":8274.79,"id":9629022}]}]}
{"op":"mcm","clk":"4215124789","pt":1631534980681,"mc":[{"id":"1.187557985","rc":[{"batl":[[0,3.65,116.44],[1,3.7,149.25],[2,3.75,186.89]],"ltp":3.15,"tv":15583.87,"id":5300820},{"batb":[[0,1.43,3.41]],"batl":[[1,1.46,204]],"ltp":1.44,"tv":8274.79,"id":9629022}]}]}
{"op":"mcm","clk":"4215124944","pt":1631534982562,"mc":[{"id":"1.187557985","rc":[{"batb":[[0,2.94,54.1],[1,2.92,180.07],[2,2.9,184.42]],"batl":[[0,3.6,38.15],[1,3.65,120.34],[2,3.7,149.25]],"ltp":3.15,"tv":15583.87,"id":5300820},{"batl":[[2,1.48,30.85]],"ltp":1.44,"tv":8274.79,"id":9629022}]}]}
{"op":"mcm","clk":"4215125301","pt":1631534987466,"mc":[{"id":"1.187557985","rc":[{"batb":[[0,2.92,180.07],[1,2.9,184.42],[2,2.88,176.18]],"batl":[[0,3.65,120.34],[1,3.7,149.25],[2,3.75,186.89]],"ltp":3.15,"tv":15583.87,"id":5300820},{"batb":[[1,1.38,85.46],[2,1.37,413.06]],"batl":[[0,1.49,6.17],[1,1.52,269.23],[2,1.53,277.57]],"ltp":1.44,"tv":8274.79,"id":9629022}]}]}
{"op":"mcm","clk":"4215125345","pt":1631534987992,"mc":[{"id":"1.187557985","rc":[{"batl":[[0,3.65,116.44]],"ltp":3.15,"tv":15583.87,"id":5300820},{"batb":[[1,1.37,413.06],[2,1.36,392.84]],"ltp":1.44,"tv":8274.79,"id":9629022}]}]}
{"op":"mcm","clk":"4215125548","pt":1631534990492,"mc":[{"id":"1.187557985","rc":[{"batb":[[2,1.36,695.28]],"batl":[[2,1.53,543.94]],"ltp":1.44,"tv":8274.79,"id":9629022}]}]}
{"op":"mcm","clk":"4215125583","pt":1631534990914,"mc":[{"id":"1.187557985","rc":[{"batl":[[0,3.65,120.34]],"ltp":3.15,"tv":15583.87,"id":5300820},{"batb":[[1,1.38,94.46],[2,1.37,413.06]],"ltp":1.44,"tv":8274.79,"id":9629022}]}]}
{"op":"mcm","clk":"4215125703","pt":1631534992586,"mc":[{"id":"1.187557985","rc":[{"batl":[[0,3.65,116.44]],"ltp":3.15,"tv":15583.87,"id":5300820},{"batb":[[1,1.37,413.06],[2,1.36,695.28]],"ltp":1.44,"tv":8274.79,"id":9629022}]}]}
{"op":"mcm","clk":"4215125721","pt":1631534992893,"mc":[{"id":"1.187557985","rc":[{"batb":[[1,2.9,182.42]],"ltp":3.15,"tv":15583.87,"id":5300820}]}]}
{"op":"mcm","clk":"4215125920","pt":1631534995524,"mc":[{"id":"1.187557985","rc":[{"batb":[[0,2.92,2],[1,2.84,48.79],[2,2.58,2.89]],"ltp":3.15,"tv":15583.87,"id":5300820},{"batl":[[1,1.57,4],[2,1.53,0]],"ltp":1.44,"tv":8274.79,"id":9629022}]}]}
{"op":"mcm","clk":"4215126143","pt":1631534998630,"mc":[{"id":"1.187557985","rc":[{"batb":[[0,3.55,546.44],[1,3.45,530.36],[2,3.4,530.36]],"batl":[[0,3.7,149.25],[1,3.75,186.89],[2,3.95,3.7]],"ltp":3.15,"tv":15583.87,"id":5300820},{"trd":[[1.43,6.82]],"batb":[[0,1.38,11.56]],"batl":[[0,1.39,162.72],[1,1.4,245.19],[2,1.49,6.17]],"ltp":1.43,"tv":8281.61,"id":9629022}],"tv":23865.49}]}
{"op":"mcm","clk":"4215126216","pt":1631534999518,"mc":[{"id":"1.187557985","rc":[{"trd":[[3.55,14.08]],"batb":[[0,3.55,539.4],[1,3.5,70.63],[2,3.45,530.36]],"batl":[[0,3.75,186.89],[1,3.95,3.7],[2,3.95,0]],"ltp":3.55,"tv":15597.95,"id":5300820},{"batb":[[1,1.37,4]],"batl":[[0,1.4,245.19],[1,1.49,6.17],[2,1.51,10.56]],"ltp":1.43,"tv":8281.61,"id":9629022}],"tv":23879.57}]}
{"op":"mcm","clk":"4215126288","pt":1631535000616,"mc":[{"id":"1.187557985","rc":[{"batl":[[0,3.75,204.98]],"ltp":3.55,"tv":15597.95,"id":5300820},{"batb":[[2,1.36,745.28]],"batl":[[1,1.45,30],[2,1.48,30.85]],"ltp":1.43,"tv":8281.61,"id":9629022}]}]}
{"op":"mcm","clk":"4215126331","pt":1631535001115,"mc":[{"id":"1.187557985","rc":[{"batl":[[2,1.48,36.85]],"ltp":1.43,"tv":8281.61,"id":9629022}]}]}
{"op":"mcm","clk":"4215126461","pt":1631535002579,"mc":[{"id":"1.187557985","rc":[{"batl":[[0,3.75,221.81]],"ltp":3.55,"tv":15597.95,"id":5300820},{"batl":[[0,1.4,394.45],[1,1.41,234.85],[2,1.45,30]],"ltp":1.43,"tv":8281.61,"id":9629022}]}]}
{"op":"mcm","clk":"4215126558","pt":1631535003623,"mc":[{"id":"1.187557985","rc":[{"batl":[[2,1.48,36.85]],"ltp":1.43,"tv":8281.61,"id":9629022}]}]}
{"op":"mcm","clk":"4215126633","pt":1631535004617,"mc":[{"id":"1.187557985","rc":[{"batb":[[0,1.38,1765.56]],"ltp":1.43,"tv":8281.61,"id":9629022}]}]}
{"op":"mcm","clk":"4215126719","pt":1631535005610,"mc":[{"id":"1.187557985","rc":[{"batl":[[0,3.75,204.98],[2,4.1,103.34]],"ltp":3.55,"tv":15597.95,"id":5300820},{"batl":[[0,1.39,1.7],[1,1.4,394.45],[2,1.41,234.85]],"ltp":1.43,"tv":8281.61,"id":9629022}]}]}
{"op":"mcm","clk":"4215126795","pt":1631535006501,"mc":[{"id":"1.187557985","rc":[{"trd":[[1.39,0.04]],"batl":[[0,1.39,1.69]],"ltp":1.39,"tv":8281.64,"id":9629022}],"tv":23879.6}]}
{"op":"mcm","clk":"4215126873","pt":1631535007602,"mc":[{"id":"1.187557985","rc":[{"batb":[[0,3.55,608.85],[1,3.5,164.91]],"ltp":3.55,"tv":15597.95,"id":5300820},{"batl":[[1,1.4,806.72]],"ltp":1.39,"tv":8281.64,"id":9629022}]}]}
{"op":"mcm","clk":"4215126948","pt":1631535008589,"mc":[{"id":"1.187557985","rc":[{"batl":[[0,3.7,16.83],[1,3.75,204.98],[2,3.95,3.7]],"ltp":3.55,"tv":15597.95,"id":5300820},{"batl":[[0,1.4,806.72],[1,1.41,234.85],[2,1.46,350.62]],"ltp":1.39,"tv":8281.64,"id":9629022}]}]}
{"op":"mcm","clk":"4215127066","pt":1631535010223,"mc":[{"id":"1.187557985","rc":[{"trd":[[1.38,91.63]],"batb":[[0,1.38,1719.75]],"ltp":1.38,"tv":8373.27,"id":9629022}],"tv":23971.23}]}
{"op":"mcm","clk":"4215127202","pt":1631535011637,"mc":[{"id":"1.187557985","rc":[{"trd":[[1.4,50]],"batl":[[0,1.4,781.72]],"ltp":1.4,"tv":8423.27,"id":9629022}],"tv":24021.23}]}
{"op":"mcm","clk":"4215127371","pt":1631535013509,"mc":[{"id":"1.187557985","rc":[{"trd":[[1.38,137.05]],"batb":[[0,1.38,1697.04],[2,1.36,767.3]],"ltp":1.38,"tv":8468.69,"id":9629022}],"tv":24066.65}]}
{"op":"mcm","clk":"4215127507","pt":1631535015237,"mc":[{"id":"1.187557985","rc":[{"batb":[[2,1.36,786.64]],"ltp":1.38,"tv":8468.69,"id":9629022}]}]}
{"op":"mcm","clk":"4215127799","pt":1631535018928,"mc":[{"id":"1.187557985","rc":[{"trd":[[1.4,57.06]],"batl":[[0,1.4,778.19]],"ltp":1.4,"tv":8475.75,"id":9629022}],"tv":24073.71}]}
{"op":"mcm","clk":"4215127994","pt":1631535021401,"mc":[{"id":"1.187557985","rc":[{"batl":[[0,1.4,745.61]],"ltp":1.4,"tv":8475.75,"id":9629022}]}]}
{"op":"mcm","clk":"4215128181","pt":1631535023906,"mc":[{"id":"1.187557985","rc":[{"trd":[[1.4,61.7]],"batb":[[2,1.36,821.02]],"batl":[[0,1.4,743.29]],"ltp":1.4,"tv":8480.39,"id":9629022}],"tv":24078.35}]}
{"op":"mcm","clk":"4215128434","pt":1631535027408,"mc":[{"id":"1.187557985","rc":[{"trd":[[1.38,237.05]],"batb":[[0,1.38,1647.04]],"ltp":1.38,"tv":8580.39,"id":9629022}],"tv":24178.35}]}
{"op":"mcm","clk":"4215128498","pt":1631535028199,"mc":[{"id":"1.187557985","rc":[{"batb":[[0,1.38,1690.45]],"ltp":1.38,"tv":8580.39,"id":9629022}]}]}
{"op":"mcm","clk":"4215128556","pt":1631535029095,"mc":[{"id":"1.187557985","rc":[{"trd":[[1.4,101.7]],"batl":[[0,1.4,723.29]],"ltp":1.4,"tv":8620.39,"id":9629022}],"tv":24218.35}]}
{"op":"mcm","clk":"4215128652","pt":1631535030522,"mc":[{"id":"1.187557985","rc":[{"batl":[[0,3.75,204.98],[1,3.95,3.7],[2,4.1,103.34]],"ltp":3.55,"tv":15597.95,"id":5300820},{"batb":[[0,1.38,1647.04]],"ltp":1.4,"tv":8620.39,"id":9629022}]}]}
{"op":"mcm","clk":"4215128772","pt":1631535032209,"mc":[{"id":"1.187557985","rc":[{"trd":[[1.38,237.23]],"batb":[[0,1.38,1646.95]],"ltp":1.38,"tv":8620.58,"id":9629022}],"tv":24218.54}]}
{"op":"mcm","clk":"4215128865","pt":1631535033214,"mc":[{"id":"1.187557985","rc":[{"batb":[[2,1.36,839.6]],"ltp":1.38,"tv":8620.58,"id":9629022}]}]}
{"op":"mcm","clk":"4215129205","pt":1631535037634,"mc":[{"id":"1.187557985","rc":[{"trd":[[3.55,18.42]],"batb":[[0,3.55,606.68]],"ltp":3.55,"tv":15602.29,"id":5300820}],"tv":24222.88}]}
{"op":"mcm","clk":"4215129397","pt":1631535040255,"mc":[{"id":"1.187557985","rc":[{"batl":[[0,1.4,701.1]],"ltp":1.38,"tv":8620.58,"id":9629022}]}]}
{"op":"mcm","clk":"4215129639","pt":1631535043220,"mc":[{"id":"1.187557985","rc":[{"batb":[[2,1.36,866.82]],"batl":[[0,1.39,200],[1,1.4,701.1],[2,1.41,234.85]],"ltp":1.38,"tv":8620.58,"id":9629022}]}]}
{"op":"mcm","clk":"4215129717","pt":1631535044524,"mc":[{"id":"1.187557985","rc":[{"trd":[[1.39,0.95]],"batl":[[0,1.39,199.54]],"ltp":1.39,"tv":8621.49,"id":9629022}],"tv":24223.79}]}
{"op":"mcm","clk":"4215130248","pt":1631535051344,"mc":[{"id":"1.187557985","rc":[{"batl":[[0,3.7,24.32],[1,3.75,204.98],[2,3.95,3.7]],"ltp":3.55,"tv":15602.29,"id":5300820},{"batb":[[0,1.38,1693.97]],"ltp":1.39,"tv":8621.49,"id":9629022}]}]}
{"op":"mcm","clk":"4215130374","pt":1631535053127,"mc":[{"id":"1.187557985","rc":[{"trd":[[1.39,5.6]],"batl":[[0,1.39,197.22]],"ltp":1.39,"tv":8626.14,"id":9629022}],"tv":24228.43}]}
{"op":"mcm","clk":"4215130782","pt":1631535058663,"mc":[{"id":"1.187557985","rc":[{"batb":[[0,1.38,1646.95]],"ltp":1.39,"tv":8626.14,"id":9629022}]}]}
{"op":"mcm","clk":"4215131065","pt":1631535062158,"mc":[{"id":"1.187557985","rc":[{"trd":[[1.39,99.64]],"batl":[[0,1.39,150.2]],"ltp":1.39,"tv":8720.18,"id":9629022}],"tv":24322.47}]}
{"op":"mcm","clk":"4215131456","pt":1631535066278,"mc":[{"id":"1.187557985","rc":[{"batl":[[0,3.75,204.98],[1,3.95,3.7],[2,4.1,103.34]],"ltp":3.55,"tv":15602.29,"id":5300820},{"trd":[[1.39,109.64]],"batl":[[0,1.39,145.2]],"ltp":1.39,"tv":8730.18,"id":9629022}],"tv":24332.47}]}
{"op":"mcm","clk":"4215131549","pt":1631535067170,"mc":[{"id":"1.187557985","rc":[{"batb":[[2,1.36,442.84]],"batl":[[1,1.4,412.27],[2,1.46,350.62]],"ltp":1.39,"tv":8730.18,"id":9629022}]}]}
{"op":"mcm","clk":"4215132132","pt":1631535074481,"mc":[{"id":"1.187557985","rc":[{"trd":[[3.55,43.97]],"batb":[[0,3.55,593.91]],"ltp":3.55,"tv":15627.84,"id":5300820}],"tv":24358.02}]}
{"op":"mcm","clk":"4215132220","pt":1631535075268,"mc":[{"id":"1.187557985","rc":[{"trd":[[1.39,209.64]],"batb":[[2,1.36,865.62]],"batl":[[0,1.39,95.2],[1,1.4,702.28],[2,1.41,234.86]],"ltp":1.39,"tv":8830.18,"id":9629022}],"tv":24458.02}]}
{"op":"mcm","clk":"4215132488","pt":1631535077991,"mc":[{"id":"1.187557985","rc":[{"trd":[[3.55,45.41]],"batb":[[0,3.55,593.19]],"ltp":3.55,"tv":15629.28,"id":5300820}],"tv":24459.46}]}
{"op":"mcm","clk":"4215132603","pt":1631535079189,"mc":[{"id":"1.187557985","rc":[{"trd":[[1.39,219.64]],"batl":[[0,1.39,90.2]],"ltp":1.39,"tv":8840.18,"id":9629022}],"tv":24469.46}]}
{"op":"mcm","clk":"4215132747","pt":1631535080860,"mc":[{"id":"1.187557985","rc":[{"trd":[[3.55,46.85]],"batb":[[0,3.55,592.47]],"ltp":3.55,"tv":15630.73,"id":5300820}],"tv":24470.91}]}
{"op":"mcm","clk":"4215133572","pt":1631535090502,"mc":[{"id":"1.187557985","rc":[{"batl":[[0,3.75,379.56]],"ltp":3.55,"tv":15630.73,"id":5300820},{"batb":[[1,1.37,481.85]],"ltp":1.39,"tv":8840.18,"id":9629022}]}]}
{"op":"mcm","clk":"4215133795","pt":1631535093294,"mc":[{"id":"1.187557985","rc":[{"trd":[[3.55,232.58]],"batb":[[0,3.55,499.59]],"ltp":3.55,"tv":15816.46,"id":5300820},{"trd":[[1.39,395.64]],"batl":[[0,1.39,2.2]],"ltp":1.39,"tv":9016.18,"id":9629022}],"tv":24832.64}]}
{"op":"mcm","clk":"4215134054","pt":1631535096480,"mc":[{"id":"1.187557985","rc":[{"batb":[[1,1.37,623.45]],"ltp":1.39,"tv":9016.18,"id":9629022}]}]}
{"op":"mcm","clk":"4215134627","pt":1631535103412,"mc":[{"id":"1.187557985","rc":[{"batl":[[0,1.4,702.28],[1,1.41,234.86],[2,1.44,30]],"ltp":1.39,"tv":9016.18,"id":9629022}]}]}
{"op":"mcm","clk":"4215134687","pt":1631535104096,"mc":[{"id":"1.187557985","rc":[{"batb":[[2,1.36,442.84]],"batl":[[0,1.4,412.27],[1,1.44,30],[2,1.46,350.62]],"ltp":1.39,"tv":9016.18,"id":9629022}]}]}
{"op":"mcm","clk":"4215134897","pt":1631535106510,"mc":[{"id":"1.187557985","rc":[{"trd":[[1.38,285.13]],"batb":[[0,1.38,1623]],"ltp":1.38,"tv":9064.08,"id":9629022}],"tv":24880.54}]}
{"op":"mcm","clk":"4215135418","pt":1631535112217,"mc":[{"id":"1.187557985","rc":[{"trd":[[3.55,268.2]],"batb":[[0,3.55,481.78]],"batl":[[0,3.75,361.47]],"ltp":3.55,"tv":15852.08,"id":5300820},{"batb":[[0,1.39,2.32],[1,1.38,1623],[2,1.37,623.45]],"ltp":1.38,"tv":9064.08,"id":9629022}],"tv":24916.16}]}
{"op":"mcm","clk":"4215135696","pt":1631535115431,"mc":[{"id":"1.187557985","rc":[{"batl":[[1,3.8,17.92],[2,3.95,3.7]],"ltp":3.55,"tv":15852.08,"id":5300820},{"batl":[[0,1.4,702.28],[1,1.41,234.86],[2,1.44,30]],"ltp":1.38,"tv":9064.08,"id":9629022}]}]}
{"op":"mcm","clk":"4215136891","pt":1631535130127,"mc":[{"id":"1.187557985","rc":[{"trd":[[1.39,400.28]],"batb":[[0,1.38,1623],[1,1.37,623.45],[2,1.36,865.62]],"ltp":1.39,"tv":9068.72,"id":9629022}],"tv":24920.8}]}
{"op":"mcm","clk":"4215136954","pt":1631535130952,"mc":[{"id":"1.187557985","rc":[{"trd":[[3.55,268.22]],"batb":[[0,3.55,481.77]],"ltp":3.55,"tv":15852.1,"id":5300820}],"tv":24920.82}]}
{"op":"mcm","clk":"4215137601","pt":1631535138043,"mc":[{"id":"1.187557985","rc":[{"trd":[[1.4,118.74]],"batl":[[0,1.4,693.76]],"ltp":1.4,"tv":9085.76,"id":9629022}],"tv":24937.86}]}
{"op":"mcm","clk":"4215137733","pt":1631535139864,"mc":[{"id":"1.187557985","rc":[{"batl":[[0,3.7,27.86],[1,3.75,361.47],[2,3.8,17.92]],"ltp":3.55,"tv":15852.1,"id":5300820},{"batb":[[0,1.39,37.95],[1,1.38,1623],[2,1.37,623.45]],"ltp":1.4,"tv":9085.76,"id":9629022}]}]}
{"op":"mcm","clk":"4215138366","pt":1631535147654,"mc":[{"id":"1.187557985","rc":[{"batb":[[0,3.55,69.45],[2,3.15,250.73]],"ltp":3.55,"tv":15852.1,"id":5300820},{"trd":[[1.39,405.72]],"batb":[[0,1.39,35.23],[2,1.37,481.85]],"ltp":1.39,"tv":9091.19,"id":9629022}],"tv":24943.3}]}
{"op":"mcm","clk":"4215138456","pt":1631535148658,"mc":[{"id":"1.187557985","rc":[{"batb":[[0,3.15,250.73],[1,3.1,160.07],[2,3.05,212.46]],"batl":[[0,3.8,17.92],[1,4.1,103.34],[2,4.2,112.26]],"ltp":3.55,"tv":15852.1,"id":5300820},{"batb":[[0,1.37,4],[1,1.36,50],[2,1.32,439.68]],"batl":[[0,1.44,30],[1,1.46,350.62],[2,1.47,352.59]],"ltp":1.39,"tv":9091.19,"id":9629022}]}]}
{"op":"mcm","clk":"4215138529","pt":1631535149490,"mc":[{"id":"1.187557985","rc":[{"batl":[[0,4.1,103.34],[1,4.2,112.26],[2,4.3,124.22]],"ltp":3.55,"tv":15852.1,"id":5300820},{"batb":[[1,1.32,439.68],[2,1.31,727.64]],"batl":[[0,1.46,350.62],[1,1.47,352.59],[2,1.48,365.42]],"ltp":1.39,"tv":9091.19,"id":9629022}]}]}
{"op":"mcm","clk":"4215138697","pt":1631535151488,"mc":[{"id":"1.187557985","rc":[{"batb":[[1,1.32,607.32],[2,1.31,1069.24]],"batl":[[1,1.47,531.08],[2,1.48,558.32]],"ltp":1.39,"tv":9091.19,"id":9629022}]}]}
{"op":"mcm","clk":"4215138796","pt":1631535152658,"mc":[{"id":"1.187557985","rc":[{"batb":[[0,3.15,253.73],[1,3.1,163.07]],"ltp":3.55,"tv":15852.1,"id":5300820},{"batb":[[0,1.4,9.76],[1,1.37,4],[2,1.32,607.32]],"batl":[[0,1.46,354.62]],"ltp":1.39,"tv":9091.19,"id":9629022}]}]}
{"op":"mcm","clk":"4215138866","pt":1631535153571,"mc":[{"id":"1.187557985","rc":[{"trd":[[1.4,127.26]],"batb":[[0,1.4,5.5]],"ltp":1.4,"tv":9099.71,"id":9629022}],"tv":24951.81}]}
{"op":"mcm","clk":"4215139292","pt":1631535158409,"mc":[{"id":"1.187557985","rc":[{"batl":[[0,990,0.01],[1,4.2,0],[2,4.3,0]],"ltp":3.55,"tv":15852.1,"id":5300820},{"batb":[[2,1.31,294.72]],"ltp":1.4,"tv":9099.71,"id":9629022}]}]}
{"op":"mcm","clk":"4215139481","pt":1631535160419,"mc":[{"id":"1.187557985","rc":[{"batb":[[0,3.15,250.73],[1,3.1,160.07]],"ltp":3.55,"tv":15852.1,"id":5300820},{"batl":[[0,1.46,350.62]],"ltp":1.4,"tv":9099.71,"id":9629022}]}]}
{"op":"mcm","clk":"4215139604","pt":1631535161520,"mc":[{"id":"1.187557985","rc":[{"trd":[[3.15,39.08]],"batb":[[0,3.15,243.15],[2,3.05,557.34]],"batl":[[0,3.35,14.1],[1,3.4,562.5],[2,3.45,545.96]],"ltp":3.15,"tv":15867.26,"id":5300820},{"batb":[[0,1.43,457],[1,1.42,234.61],[2,1.41,5.66]],"ltp":1.4,"tv":9099.71,"id":9629022}],"tv":24966.98}]}
{"op":"mcm","clk":"4215139732","pt":1631535162627,"mc":[{"id":"1.187557985","rc":[{"batl":[[2,3.45,565.12]],"ltp":3.15,"tv":15867.26,"id":5300820},{"batb":[[2,1.41,1220.04]],"ltp":1.4,"tv":9099.71,"id":9629022}]}]}
{"op":"mcm","clk":"4215139830","pt":1631535163620,"mc":[{"id":"1.187557985","rc":[{"batl":[[0,3.3,3],[1,3.35,14.1],[2,3.4,562.5]],"ltp":3.15,"tv":15867.26,"id":5300820},{"batb":[[2,1.41,1228.04]],"ltp":1.4,"tv":9099.71,"id":9629022}]}]}
{"op":"mcm","clk":"4215139904","pt":1631535164520,"mc":[{"id":"1.187557985","rc":[{"batl":[[1,3.35,17.1]],"ltp":3.15,"tv":15867.26,"id":5300820},{"batb":[[0,1.44,7],[1,1.43,465],[2,1.42,240.61]],"ltp":1.4,"tv":9099.71,"id":9629022}]}]}
{"op":"mcm","clk":"4215140101","pt":1631535166596,"mc":[{"id":"1.187557985","rc":[{"trd":[[3.15,52.17]],"batb":[[0,3.15,236.61]],"batl":[[0,3.25,3],[1,3.3,3],[2,3.35,17.1]],"ltp":3.15,"tv":15880.34,"id":5300820},{"batb":[[0,1.44,81.55],[1,1.43,520],[2,1.42,286.9]],"ltp":1.4,"tv":9099.71,"id":9629022}],"tv":24980.06}]}
{"op":"mcm","clk":"4215140191","pt":1631535167640,"mc":[{"id":"1.187557985","rc":[{"batl":[[0,3.25,44.64]],"ltp":3.15,"tv":15880.34,"id":5300820},{"batb":[[0,1.44,7]],"ltp":1.4,"tv":9099.71,"id":9629022}]}]}
{"op":"mcm","clk":"4215140278","pt":1631535168432,"mc":[{"id":"1.187557985","rc":[{"batl":[[0,3.25,3]],"ltp":3.15,"tv":15880.34,"id":5300820},{"batb":[[0,1.45,7],[1,1.44,7],[2,1.43,520]],"ltp":1.4,"tv":9099.71,"id":9629022}]}]}
{"op":"mcm","clk":"4215140384","pt":1631535169536,"mc":[{"id":"1.187557985","rc":[{"batl":[[1,3.3,204.08]],"ltp":3.15,"tv":15880.34,"id":5300820},{"batb":[[1,1.44,467.82]],"ltp":1.4,"tv":9099.71,"id":9629022}]}]}
{"op":"mcm","clk":"4215140490","pt":1631535170637,"mc":[{"id":"1.187557985","rc":[{"batb":[[2,1.43,465]],"ltp":1.4,"tv":9099.71,"id":9629022}]}]}
{"op":"mcm","clk":"4215140549","pt":1631535171219,"mc":[{"id":"1.187557985","rc":[{"batl":[[0,3.2,15],[1,3.25,3],[2,3.3,204.08]],"ltp":3.15,"tv":15880.34,"id":5300820}]}]}
{"op":"mcm","clk":"4215140726","pt":1631535173151,"mc":[{"id":"1.187557985","rc":[{"trd":[[1.46,200.72]],"batb":[[0,1.45,270]],"batl":[[0,1.46,276.06]],"ltp":1.46,"tv":9248.83,"id":9629022}],"tv":25129.18}]}
{"op":"mcm","clk":"4215141133","pt":1631535177656,"mc":[{"id":"1.187557985","rc":[{"batb":[[0,3.15,75.66],[1,2.98,15.15],[2,2.92,46.02]],"batl":[[0,3.4,19.36],[1,3.6,139.76],[2,3.65,178.45]],"ltp":3.15,"tv":15880.34,"id":5300820},{"batb":[[0,1.45,263],[1,1.42,46.29],[2,1.41,209.95]],"batl":[[0,1.55,273.16],[1,1.56,266.8],[2,1.57,347.09]],"ltp":1.46,"tv":9248.83,"id":9629022}]}]}
{"op":"mcm","clk":"4215141208","pt":1631535178444,"mc":[{"id":"1.187557985","rc":[{"batb":[[0,2.92,46.02],[1,2.88,1.45],[2,2.82,145.68]],"batl":[[0,3.6,139.76],[1,3.65,178.45],[2,3.7,144.03]],"ltp":3.15,"tv":15880.34,"id":5300820},{"batb":[[1,1.4,5.5],[2,1.39,87.91]],"ltp":1.46,"tv":9248.83,"id":9629022}]}]}
{"op":"mcm","clk":"4215141250","pt":1631535178919,"mc":[{"id":"1.187557985","rc":[{"batl":[[0,3.6,135.6]],"ltp":3.15,"tv":15880.34,"id":5300820},{"batb":[[0,1.4,5.5],[1,1.38,331.98],[2,1.37,390.12]],"ltp":1.46,"tv":9248.83,"id":9629022}]}]}
{"op":"mcm","clk":"4215141389","pt":1631535180660,"mc":[{"id":"1.187557985","rc":[{"batb":[[2,1.37,769.96]],"batl":[[0,1.51,30],[1,1.55,273.16],[2,1.56,436.86]],"ltp":1.46,"tv":9248.83,"id":9629022}]}]}
{"op":"mcm","clk":"4215141457","pt":1631535181453,"mc":[{"id":"1.187557985","rc":[{"batb":[[0,2.9,46.28],[1,2.88,2.17]],"ltp":3.15,"tv":15880.34,"id":5300820},{"batb":[[0,1.46,4.39],[1,1.4,5.5],[2,1.38,331.98]],"batl":[[0,1.55,273.16],[1,1.56,436.86],[2,1.57,500.94]],"ltp":1.46,"tv":9248.83,"id":9629022}]}]}
{"op":"mcm","clk":"4215141786","pt":1631535185633,"mc":[{"id":"1.187557985","rc":[{"batl":[[0,3.6,139.91]],"ltp":3.15,"tv":15880.34,"id":5300820},{"batb":[[2,1.39,92.91]],"batl":[[1,1.56,266.8],[2,1.57,347.09]],"ltp":1.46,"tv":9248.83,"id":9629022}]}]}
{"op":"mcm","clk":"4215141813","pt":1631535185951,"mc":[{"id":"1.187557985","rc":[{"batl":[[0,3.6,135.6]],"ltp":3.15,"tv":15880.34,"id":5300820},{"batb":[[2,1.38,331.98]],"ltp":1.46,"tv":9248.83,"id":9629022}]}]}
{"op":"mcm","clk":"4215142049","pt":1631535188270,"mc":[{"id":"1.187557985","rc":[{"batb":[[1,1.45,250.51],[2,1.44,219.94]],"batl":[[0,1.49,227.61],[1,1.5,182.52],[2,1.55,273.16]],"ltp":1.46,"tv":9248.83,"id":9629022}]}]}
{"op":"mcm","clk":"4215142129","pt":1631535189322,"mc":[{"id":"1.187557985","rc":[{"batb":[[1,1.4,5.5],[2,1.38,331.98]],"batl":[[0,1.55,273.16],[1,1.56,266.8],[2,1.57,347.09]],"ltp":1.46,"tv":9248.83,"id":9629022}]}]}
{"op":"mcm","clk":"4215142225","pt":1631535190649,"mc":[{"id":"1.187557985","rc":[{"batl":[[0,3.55,3.98],[1,3.6,135.6],[2,3.65,178.45]],"ltp":3.15,"tv":15880.34,"id":5300820}]}]}
{"op":"mcm","clk":"4215142378","pt":1631535192541,"mc":[{"id":"1.187557985","rc":[{"batl":[[1,3.6,139.31]],"ltp":3.15,"tv":15880.34,"id":5300820},{"batb":[[2,1.39,90.91]],"batl":[[1,1.56,436.86],[2,1.57,500.94]],"ltp":1.46,"tv":9248.83,"id":9629022}]}]}
{"op":"mcm","clk":"4215142397","pt":1631535192753,"mc":[{"id":"1.187557985","rc":[{"batl":[[1,3.6,135.6]],"ltp":3.15,"tv":15880.34,"id":5300820},{"batb":[[2,1.38,331.98]],"ltp":1.46,"tv":9248.83,"id":9629022}]}]}
{"op":"mcm","clk":"4215142910","pt":1631535199390,"mc":[{"id":"1.187557985","rc":[{"batl":[[1,3.6,139.71]],"ltp":3.15,"tv":15880.34,"id":5300820},{"batb":[[2,1.39,85.91]],"ltp":1.46,"tv":9248.83,"id":9629022}]}]}
{"op":"mcm","clk":"4215142981","pt":1631535200393,"mc":[{"id":"1.187557985","rc":[{"batl":[[1,3.6,135.6]],"ltp":3.15,"tv":15880.34,"id":5300820},{"batb":[[0,1.4,5.5],[1,1.38,331.98],[2,1.37,769.96]],"ltp":1.46,"tv":9248.83,"id":9629022}]}]}
{"op":"mcm","clk":"4215143068","pt":1631535201496,"mc":[{"id":"1.187557985","rc":[{"batb":[[2,2.58,2.89]],"ltp":3.15,"tv":15880.34,"id":5300820},{"batl":[[0,44,7.23],[1,990,0.01],[2,1.57,0]],"ltp":1.46,"tv":9248.83,"id":9629022}]}]}
{"op":"mcm","clk":"4215143208","pt":1631535203589,"mc":[{"id":"1.187557985","rc":[{"batl":[[0,1.41,2040.66],[1,44,7.23],[2,990,0.01]],"ltp":1.46,"tv":9248.83,"id":9629022}]}]}
{"op":"mcm","clk":"4215143301","pt":1631535204618,"mc":[{"id":"1.187557985","rc":[{"batb":[[0,3.45,554.34],[1,3.4,538.04],[2,3.35,538.04]],"batl":[[1,3.65,178.45],[2,3.7,144.03]],"ltp":3.15,"tv":15880.34,"id":5300820},{"batb":[[1,1.38,343.53]],"batl":[[0,1.41,299.23],[1,1.42,227.68],[2,1.52,10.49]],"ltp":1.46,"tv":9248.83,"id":9629022}]}]}
{"op":"mcm","clk":"4215143365","pt":1631535205480,"mc":[{"id":"1.187557985","rc":[{"trd":[[3.45,14.18]],"batb":[[0,3.45,619.55]],"ltp":3.45,"tv":15894.52,"id":5300820}],"tv":25143.36}]}
{"op":"mcm","clk":"4215143455","pt":1631535206475,"mc":[{"id":"1.187557985","rc":[{"batl":[[0,3.55,22.94]],"ltp":3.45,"tv":15894.52,"id":5300820},{"batb":[[1,1.39,6],[2,1.38,351.53]],"batl":[[2,1.45,30]],"ltp":1.46,"tv":9248.83,"id":9629022}]}]}
{"op":"mcm","clk":"4215143687","pt":1631535209528,"mc":[{"id":"1.187557985","rc":[{"batl":[[2,1.52,16.49]],"ltp":1.46,"tv":9248.83,"id":9629022}]}]}
{"op":"mcm","clk":"4215143858","pt":1631535211588,"mc":[{"id":"1.187557985","rc":[{"batl":[[2,1.49,358.11]],"ltp":1.46,"tv":9248.83,"id":9629022}]}]}
{"op":"mcm","clk":"4215143888","pt":1631535212004,"mc":[{"id":"1.187557985","rc":[{"batl":[[2,1.44,30]],"ltp":1.46,"tv":9248.83,"id":9629022}]}]}
{"op":"mcm","clk":"4215143990","pt":1631535213423,"mc":[{"id":"1.187557985","rc":[{"batl":[[0,3.55,3.98]],"ltp":3.45,"tv":15894.52,"id":5300820}]}]}
{"op":"mcm","clk":"4215144243","pt":1631535216323,"mc":[{"id":"1.187557985","rc":[{"batl":[[0,3.5,18.96],[1,3.55,3.98],[2,3.65,178.45]],"ltp":3.45,"tv":15894.52,"id":5300820},{"batb":[[0,1.4,33]],"ltp":1.46,"tv":9248.83,"id":9629022}]}]}
{"op":"mcm","clk":"4215144306","pt":1631535217015,"mc":[{"id":"1.187557985","rc":[{"trd":[[1.41,107.39]],"batl":[[0,1.41,245.53]],"ltp":1.41,"tv":9356.21,"id":9629022}],"tv":25250.74}]}
{"op":"mcm","clk":"4215144466","pt":1631535218595,"mc":[{"id":"1.187557985","rc":[{"batb":[[0,3.45,72.3],[1,3.3,13.04],[2,3.05,243.61]],"ltp":3.45,"tv":15894.52,"id":5300820}]}]}
{"op":"mcm","clk":"4215144560","pt":1631535219592,"mc":[{"id":"1.187557985","rc":[{"batb":[[0,3.3,13.04],[1,3.05,243.61],[2,3,158.78]],"batl":[[0,3.55,3.98],[1,4,103.64],[2,4.1,148.11]],"ltp":3.45,"tv":15894.52,"id":5300820},{"batb":[[0,1.4,5.5],[1,1.37,4],[2,1.35,50.7]],"batl":[[0,1.44,30],[1,1.49,358.11],[2,1.5,340.17]],"ltp":1.41,"tv":9356.21,"id":9629022}]}]}
{"op":"mcm","clk":"4215144644","pt":1631535220590,"mc":[{"id":"1.187557985","rc":[{"batb":[[0,3.05,243.61],[1,3,158.78],[2,2.98,228.14]],"ltp":3.45,"tv":15894.52,"id":5300820},{"batb":[[2,1.33,413.03]],"batl":[[0,1.49,358.11],[1,1.5,340.17],[2,1.51,338.38]],"ltp":1.41,"tv":9356.21,"id":9629022}]}]}
{"op":"mcm","clk":"4215144786","pt":1631535222490,"mc":[{"id":"1.187557985","rc":[{"batl":[[0,3.35,1.7],[1,3.55,3.98],[2,4,103.64]],"ltp":3.45,"tv":15894.52,"id":5300820},{"batl":[[1,1.5,637.06],[2,1.51,515.44]],"ltp":1.41,"tv":9356.21,"id":9629022}]}]}
{"op":"mcm","clk":"4215144863","pt":1631535223602,"mc":[{"id":"1.187557985","rc":[{"batl":[[0,3.45,2.32]],"ltp":3.45,"tv":15894.52,"id":5300820}]}]}
{"op":"mcm","clk":"4215144876","pt":1631535223815,"mc":[{"id":"1.187557985","rc":[{"batb":[[0,3.05,245.61],[1,3,160.78]],"ltp":3.45,"tv":15894.52,"id":5300820},{"batl":[[0,1.49,364.11]],"ltp":1.41,"tv":9356.21,"id":9629022}]}]}
{"op":"mcm","clk":"4215145114","pt":1631535226516,"mc":[{"id":"1.187557985","rc":[{"batl":[[2,4.2,3.48]],"ltp":3.45,"tv":15894.52,"id":5300820},{"batb":[[2,1.32,104.64]],"ltp":1.41,"tv":9356.21,"id":9629022}]}]}
{"op":"mcm","clk":"4215145267","pt":1631535228627,"mc":[{"id":"1.187557985","rc":[{"batb":[[0,3.05,243.61],[1,3,158.78]],"ltp":3.45,"tv":15894.52,"id":5300820},{"batl":[[0,1.49,358.11]],"ltp":1.41,"tv":9356.21,"id":9629022}]}]}
{"op":"mcm","clk":"4215145352","pt":1631535229629,"mc":[{"id":"1.187557985","rc":[{"trd":[[3.05,15.38]],"batb":[[0,3.05,235.91]],"batl":[[0,3.25,588.46],[1,3.3,571.16],[2,3.35,571.16]],"ltp":3.05,"tv":15909.91,"id":5300820},{"batb":[[0,1.46,155.81],[1,1.45,223.46],[2,1.43,5.58]],"ltp":1.41,"tv":9356.21,"id":9629022}],"tv":25266.13}]}
{"op":"mcm","clk":"4215145431","pt":1631535230520,"mc":[{"id":"1.187557985","rc":[{"batb":[[2,1.43,202.98]],"batl":[[2,1.51,545.44]],"ltp":1.41,"tv":9356.21,"id":9629022}]}]}
{"op":"mcm","clk":"4215145529","pt":1631535231633,"mc":[{"id":"1.187557985","rc":[{"batl":[[0,3.2,3],[1,3.25,588.46],[2,3.3,571.16]],"ltp":3.05,"tv":15909.91,"id":5300820},{"batb":[[0,1.46,162.81],[1,1.45,229.46]],"ltp":1.41,"tv":9356.21,"id":9629022}]}]}
{"op":"mcm","clk":"4215145599","pt":1631535232420,"mc":[{"id":"1.187557985","rc":[{"batl":[[0,3.15,3],[1,3.2,3],[2,3.25,588.46]],"ltp":3.05,"tv":15909.91,"id":5300820},{"batb":[[0,1.47,6],[1,1.46,162.81],[2,1.45,229.46]],"ltp":1.41,"tv":9356.21,"id":9629022}]}]}
{"op":"mcm","clk":"4215145780","pt":1631535234631,"mc":[{"id":"1.187557985","rc":[{"batl":[[1,3.2,40.31]],"ltp":3.05,"tv":15909.91,"id":5300820},{"batb":[[0,1.47,65.22]],"ltp":1.41,"tv":9356.21,"id":9629022}]}]}
{"op":"mcm","clk":"4215145873","pt":1631535235627,"mc":[{"id":"1.187557985","rc":[{"batl":[[1,3.2,3]],"ltp":3.05,"tv":15909.91,"id":5300820},{"batb":[[0,1.47,6],[1,1.46,235.81]],"ltp":1.41,"tv":9356.21,"id":9629022}]}]}
{"op":"mcm","clk":"4215146122","pt":1631535238516,"mc":[{"id":"1.187557985","rc":[{"batb":[[0,3.05,89.54]],"ltp":3.05,"tv":15909.91,"id":5300820},{"batb":[[0,1.48,59.22],[1,1.47,6],[2,1.46,235.81]],"ltp":1.41,"tv":9356.21,"id":9629022}]}]}
{"op":"mcm","clk":"4215146364","pt":1631535241531,"mc":[{"id":"1.187557985","rc":[{"batl":[[0,3.1,15],[1,3.15,3],[2,3.2,3]],"ltp":3.05,"tv":15909.91,"id":5300820}]}]}
{"op":"mcm","clk":"4215146589","pt":1631535244634,"mc":[{"id":"1.187557985","rc":[{"trd":[[3.05,18.79]],"batb":[[0,2.96,15.3],[1,2.78,50.96],[2,2.3,390.4]],"batl":[[0,3.35,19.56],[1,3.45,2.32],[2,3.55,3.98]],"ltp":3.05,"tv":15913.32,"id":5300820},{"batb":[[0,1.42,46.29],[1,1.4,5.5],[2,1.37,4]],"batl":[[0,1.51,30],[1,44,7.23],[2,990,0.01]],"ltp":1.41,"tv":9356.21,"id":9629022}],"tv":25269.53}]}
{"op":"mcm","clk":"4215146680","pt":1631535245525,"mc":[{"id":"1.187557985","rc":[{"batb":[[0,2.78,50.96],[1,2.3,390.4],[2,1.2,62]],"batl":[[0,3.45,2.32],[1,3.55,3.98],[2,3.9,3.75]],"ltp":3.05,"tv":15913.32,"id":5300820},{"batb":[[0,1.4,5.5],[1,1.37,4],[2,1.36,242.34]],"batl":[[0,44,7.23],[1,990,0.01],[2,990,0]],"ltp":1.41,"tv":9356.21,"id":9629022}]}]}
{"op":"mcm","clk":"4215146870","pt":1631535247624,"mc":[{"id":"1.187557985","rc":[{"batl":[[2,3.6,4.01]],"ltp":3.05,"tv":15913.32,"id":5300820},{"batb":[[1,1.39,94.91],[2,1.38,378.97]],"batl":[[0,1.6,153.97],[1,1.61,140.31],[2,44,7.23]],"ltp":1.41,"tv":9356.21,"id":9629022}]}]}
{"op":"mcm","clk":"4215146919","pt":1631535248460,"mc":[{"id":"1.187557985","rc":[{"batl":[[2,3.9,3.75]],"ltp":3.05,"tv":15913.32,"id":5300820},{"batb":[[1,1.38,378.97],[2,1.37,521.79]],"ltp":1.41,"tv":9356.21,"id":9629022}]}]}
{"op":"mcm","clk":"4215146966","pt":1631535249038,"mc":[{"id":"1.187557985","rc":[{"batb":[[1,2.3,391.12]],"ltp":3.05,"tv":15913.32,"id":5300820}]}]}
{"op":"mcm","clk":"4215147073","pt":1631535250349,"mc":[{"id":"1.187557985","rc":[{"batb":[[1,2.58,2.17],[2,2.3,390.4]],"ltp":3.05,"tv":15913.32,"id":5300820}]}]}
{"op":"mcm","clk":"4215147158","pt":1631535251449,"mc":[{"id":"1.187557985","rc":[{"batb":[[1,2.58,2.89]],"ltp":3.05,"tv":15913.32,"id":5300820}]}]}
{"op":"mcm","clk":"4215147189","pt":1631535251868,"mc":[{"id":"1.187557985","rc":[{"batb":[[1,2.58,3.62]],"ltp":3.05,"tv":15913.32,"id":5300820}]}]}
{"op":"mcm","clk":"4215147400","pt":1631535254657,"mc":[{"id":"1.187557985","rc":[{"batl":[[2,3.6,4.16]],"ltp":3.05,"tv":15913.32,"id":5300820},{"batb":[[1,1.39,87.91],[2,1.38,378.97]],"ltp":1.41,"tv":9356.21,"id":9629022}]}]}
{"op":"mcm","clk":"4215147419","pt":1631535254924,"mc":[{"id":"1.187557985","rc":[{"batl":[[2,3.9,3.75]],"ltp":3.05,"tv":15913.32,"id":5300820},{"batb":[[1,1.38,378.97],[2,1.37,521.79]],"ltp":1.41,"tv":9356.21,"id":9629022}]}]}
{"op":"mcm","clk":"4215147577","pt":1631535257073,"mc":[{"id":"1.187557985","rc":[{"batb":[[1,2.58,4.34]],"ltp":3.05,"tv":15913.32,"id":5300820}]}]}
{"op":"mcm","clk":"4215147717","pt":1631535258859,"mc":[{"id":"1.187557985","rc":[{"batl":[[0,44,7.23],[1,990,0.01],[2,44,0]],"ltp":1.41,"tv":9356.21,"id":9629022}]}]}
{"op":"mcm","clk":"4215147944","pt":1631535261545,"mc":[{"id":"1.187557985","rc":[{"batb":[[0,3.35,1141.78],[1,3.3,1108.2],[2,3.25,1108.2]],"ltp":3.05,"tv":15913.32,"id":5300820},{"batb":[[1,1.39,90.91],[2,1.38,378.97]],"batl":[[0,1.66,12.05],[1,44,7.23],[2,990,0.01]],"ltp":1.41,"tv":9356.21,"id":9629022}]}]}
{"op":"mcm","clk":"4215148031","pt":1631535262551,"mc":[{"id":"1.187557985","rc":[{"trd":[[3.4,14.18]],"batb":[[0,3.4,67.55],[1,3.35,570.9],[2,3.3,554.1]],"ltp":3.4,"tv":15927.5,"id":5300820},{"batb":[[0,1.39,11.47],[1,1.38,378.97],[2,1.37,527.45]],"batl":[[0,1.42,269.67],[1,1.43,220.91],[2,1.52,10.49]],"ltp":1.41,"tv":9356.21,"id":9629022}],"tv":25283.72}]}
{"op":"mcm","clk":"4215148096","pt":1631535263346,"mc":[{"id":"1.187557985","rc":[{"batl":[[0,3.45,13.92]],"ltp":3.4,"tv":15927.5,"id":5300820},{"batl":[[2,1.45,30]],"ltp":1.41,"tv":9356.21,"id":9629022}]}]}
{"op":"mcm","clk":"4215148322","pt":1631535266441,"mc":[{"id":"1.187557985","rc":[{"batb":[[0,1.4,57.35],[1,1.39,11.47],[2,1.38,378.97]],"batl":[[2,1.46,156.78]],"ltp":1.41,"tv":9356.21,"id":9629022}]}]}
{"op":"mcm","clk":"4215148421","pt":1631535267643,"mc":[{"id":"1.187557985","rc":[{"batl":[[0,3.45,2.32]],"ltp":3.4,"tv":15927.5,"id":5300820},{"batl":[[2,1.52,10.49]],"ltp":1.41,"tv":9356.21,"id":9629022}]}]}
{"op":"mcm","clk":"4215148583","pt":1631535269578,"mc":[{"id":"1.187557985","rc":[{"batb":[[0,1.4,203.35]],"batl":[[2,1.44,30]],"ltp":1.41,"tv":9356.21,"id":9629022}]}]}
{"op":"mcm","clk":"4215148616","pt":1631535270155,"mc":[{"id":"1.187557985","rc":[{"batb":[[2,3.3,567.14]],"ltp":3.4,"tv":15927.5,"id":5300820},{"batb":[[0,1.4,146],[2,1.38,263.68]],"batl":[[0,1.42,222.34]],"ltp":1.41,"tv":9356.21,"id":9629022}]}]}
{"op":"mcm","clk":"4215148663","pt":1631535270787,"mc":[{"id":"1.187557985","rc":[{"trd":[[3.4,37.39]],"batb":[[0,3.4,55.94]],"ltp":3.4,"tv":15950.71,"id":5300820}],"tv":25306.93}]}
{"op":"mcm","clk":"4215148839","pt":1631535272990,"mc":[{"id":"1.187557985","rc":[{"batb":[[0,1.41,57.35],[1,1.4,146],[2,1.39,174.27]],"ltp":1.41,"tv":9356.21,"id":9629022}]}]}
{"op":"mcm","clk":"4215149009","pt":1631535275473,"mc":[{"id":"1.187557985","rc":[{"trd":[[1.42,11.72]],"batl":[[0,1.42,216.48]],"ltp":1.42,"tv":9367.93,"id":9629022}],"tv":25318.64}]}
{"op":"mcm","clk":"4215149423","pt":1631535281372,"mc":[{"id":"1.187557985","rc":[{"trd":[[1.42,21.48]],"batl":[[0,1.42,211.6]],"ltp":1.42,"tv":9377.69,"id":9629022}],"tv":25328.4}]}
{"op":"mcm","clk":"4215149591","pt":1631535283571,"mc":[{"id":"1.187557985","rc":[{"trd":[[3.4,54.43]],"batb":[[0,3.3,13.04],[1,2.96,105.69],[2,2.9,156.61]],"batl":[[2,3.95,3.9]],"ltp":3.4,"tv":15967.75,"id":5300820},{"batb":[[0,1.4,146],[1,1.37,4],[2,1.36,50]],"batl":[[0,1.44,30],[1,1.53,275.35],[2,1.54,333.23]],"ltp":1.42,"tv":9377.69,"id":9629022}],"tv":25345.44}]}
{"op":"mcm","clk":"4215149645","pt":1631535284365,"mc":[{"id":"1.187557985","rc":[{"batb":[[0,2.96,105.69],[1,2.9,156.61],[2,2.88,163.47]],"batl":[[2,4,134.96]],"ltp":3.4,"tv":15967.75,"id":5300820},{"batb":[[0,1.37,4],[1,1.33,413.1],[2,1.32,587.34]],"batl":[[0,1.53,275.35],[1,1.54,333.23],[2,1.55,383.35]],"ltp":1.42,"tv":9377.69,"id":9629022}]}]}
{"op":"mcm","clk":"4215149818","pt":1631535286566,"mc":[{"id":"1.187557985","rc":[{"batb":[[1,2.94,106.61],[2,2.9,156.61]],"ltp":3.4,"tv":15967.75,"id":5300820},{"batb":[[0,1.42,25],[1,1.37,4],[2,1.33,413.1]],"batl":[[0,1.51,7],[1,1.53,435.37],[2,1.54,497.88]],"ltp":1.42,"tv":9377.69,"id":9629022}]}]}
{"op":"mcm","clk":"4215149892","pt":1631535287561,"mc":[{"id":"1.187557985","rc":[{"batb":[[0,2.96,3],[1,2.94,108.61]],"ltp":3.4,"tv":15967.75,"id":5300820},{"batl":[[1,1.52,6],[2,1.53,435.37]],"ltp":1.42,"tv":9377.69,"id":9629022}]}]}
{"op":"mcm","clk":"4215150095","pt":1631535290605,"mc":[{"id":"1.187557985","rc":[{"batb":[[2,2.92,4]],"batl":[[2,3.95,3.5]],"ltp":3.4,"tv":15967.75,"id":5300820},{"batb":[[0,1.37,4],[1,1.34,96.72]],"ltp":1.42,"tv":9377.69,"id":9629022}]}]}
{"op":"mcm","clk":"4215150116","pt":1631535290873,"mc":[{"id":"1.187557985","rc":[{"batl":[[2,4,134.96]],"ltp":3.4,"tv":15967.75,"id":5300820},{"batb":[[1,1.33,413.1],[2,1.32,587.34]],"ltp":1.42,"tv":9377.69,"id":9629022}]}]}
{"op":"mcm","clk":"4215150418","pt":1631535295480,"mc":[{"id":"1.187557985","rc":[{"batl":[[2,4.4,3.44]],"ltp":3.4,"tv":15967.75,"id":5300820},{"batb":[[1,1.31,301.42],[2,1.3,95.48]],"ltp":1.42,"tv":9377.69,"id":9629022}]}]}
{"op":"mcm","clk":"4215150498","pt":1631535296609,"mc":[{"id":"1.187557985","rc":[{"batb":[[1,2.94,2]],"ltp":3.4,"tv":15967.75,"id":5300820}]}]}
{"op":"mcm","clk":"4215150650","pt":1631535298501,"mc":[{"id":"1.187557985","rc":[{"trd":[[2.94,2.74],[2.96,9.57]],"batb":[[0,2.9,156.61],[1,2.88,163.47],[2,2.86,239.16]],"batl":[[0,3.1,632.39],[1,3.15,598.8],[2,3.2,598.8]],"ltp":2.94,"tv":15980.06,"id":5300820},{"trd":[[1.51,394.72]],"batb":[[0,1.49,243.52],[1,1.48,292.28],[2,1.47,10.85]],"batl":[[0,1.53,435.37],[1,1.54,497.88],[2,1.55,383.35]],"ltp":1.51,"tv":9384.69,"id":9629022}],"tv":25364.75}]}
{"op":"mcm","clk":"4215150733","pt":1631535299569,"mc":[{"id":"1.187557985","rc":[{"batb":[[0,2.92,107.03],[1,2.9,172.39],[2,2.88,163.47]],"ltp":2.94,"tv":15980.06,"id":5300820},{"batl":[[0,1.53,465.37]],"ltp":1.51,"tv":9384.69,"id":9629022}]}]}
{"op":"mcm","clk":"4215150845","pt":1631535301268,"mc":[{"id":"1.187557985","rc":[{"batl":[[0,3,3],[1,3.05,3],[2,3.1,632.39]],"ltp":2.94,"tv":15980.06,"id":5300820},{"batb":[[0,1.5,7],[1,1.49,250.52],[2,1.48,298.28]],"ltp":1.51,"tv":9384.69,"id":9629022}]}]}
{"op":"mcm","clk":"4215151044","pt":1631535303605,"mc":[{"id":"1.187557985","rc":[{"trd":[[2.92,12.14]],"batb":[[0,2.92,105.99]],"ltp":2.92,"tv":15982.13,"id":5300820},{"batb":[[0,1.5,67.83]],"ltp":1.51,"tv":9384.69,"id":9629022}],"tv":25366.83}]}
{"op":"mcm","clk":"4215151118","pt":1631535304502,"mc":[{"id":"1.187557985","rc":[{"batl":[[0,2.98,3],[1,3,3],[2,3.05,3]],"ltp":2.92,"tv":15982.13,"id":5300820},{"batb":[[0,1.51,7.32],[1,1.5,7],[2,1.49,250.52]],"ltp":1.51,"tv":9384.69,"id":9629022}]}]}
{"op":"mcm","clk":"4215151582","pt":1631535310203,"mc":[{"id":"1.187557985","rc":[{"batl":[[0,2.96,15],[1,2.98,3],[2,3,3]],"ltp":2.92,"tv":15982.13,"id":5300820},{"trd":[[1.53,80.61]],"batb":[[0,1.52,60.83],[1,1.51,7.32],[2,1.5,7]],"batl":[[0,1.53,440.36]],"ltp":1.53,"tv":9434.7,"id":9629022}],"tv":25416.84}]}
{"op":"mcm","clk":"4215151788","pt":1631535313425,"mc":[{"id":"1.187557985","rc":[{"batb":[[1,2.9,156.61]],"batl":[[2,3.1,632.39]],"ltp":2.92,"tv":15982.13,"id":5300820},{"batb":[[2,1.49,243.52]],"ltp":1.53,"tv":9434.7,"id":9629022}]}]}
{"op":"mcm","clk":"4215151872","pt":1631535314528,"mc":[{"id":"1.187557985","rc":[{"batb":[[0,2.56,60.84],[1,2.48,145.86],[2,2.46,173.89]],"batl":[[0,3.45,140.69],[1,3.5,144.82],[2,3.55,150.79]],"ltp":2.92,"tv":15982.13,"id":5300820},{"batb":[[0,1.51,2.32],[1,1.4,358.6],[2,1.39,412.66]],"batl":[[0,1.53,30],[1,1.68,305.72],[2,1.69,241.2]],"ltp":1.53,"tv":9434.7,"id":9629022}]}]}
