{"op":"mcm","clk":"4230447626","pt":1631533103349,"mc":[{"id":"1.187557146","rc":[{"batb":[[1,1.82,34.64],[2,1.72,38.84]],"ltp":2.52,"tv":2236.78,"id":19931652},{"batl":[[2,2.22,7.25]],"ltp":1.62,"tv":19653.55,"id":8257797}]}]}
{"op":"mcm","clk":"4230447662","pt":1631533103649,"mc":[{"id":"1.187557146","rc":[{"batb":[[1,1.72,38.84],[2,1.47,1.54]],"ltp":2.52,"tv":2236.78,"id":19931652},{"batl":[[2,2.36,307.28]],"ltp":1.62,"tv":19653.55,"id":8257797}]}]}
{"op":"mcm","clk":"4230447952","pt":1631533107182,"mc":[{"id":"1.187557146","rc":[{"batb":[[1,1.82,33.14],[2,1.72,38.84]],"ltp":2.52,"tv":2236.78,"id":19931652},{"batl":[[2,2.22,6.25]],"ltp":1.62,"tv":19653.55,"id":8257797}]}]}
{"op":"mcm","clk":"4230447973","pt":1631533107495,"mc":[{"id":"1.187557146","rc":[{"batb":[[1,1.72,38.84],[2,1.47,1.54]],"ltp":2.52,"tv":2236.78,"id":19931652},{"batl":[[2,2.36,307.28]],"ltp":1.62,"tv":19653.55,"id":8257797}]}]}
{"op":"mcm","clk":"4230448238","pt":1631533110677,"mc":[{"id":"1.187557146","rc":[{"batb":[[1,1.82,34.64],[2,1.72,38.84]],"ltp":2.52,"tv":2236.78,"id":19931652},{"batl":[[2,2.22,6.75]],"ltp":1.62,"tv":19653.55,"id":8257797}]}]}
{"op":"mcm","clk":"4230448328","pt":1631533111774,"mc":[{"id":"1.187557146","rc":[{"batb":[[1,1.72,38.84],[2,1.47,1.54]],"ltp":2.52,"tv":2236.78,"id":19931652},{"batl":[[2,2.36,307.28]],"ltp":1.62,"tv":19653.55,"id":8257797}]}]}
{"op":"mcm","clk":"4230448504","pt":1631533113977,"mc":[{"id":"1.187557146","rc":[{"batl":[[1,990,0.01],[2,6.4,0]],"ltp":2.52,"tv":2236.78,"id":19931652}]}]}
{"op":"mcm","clk":"4230448608","pt":1631533115282,"mc":[{"id":"1.187557146","rc":[{"batb":[[1,1.39,80.75],[2,1.21,766.7]],"batl":[[2,990,0.01]],"ltp":1.62,"tv":19653.55,"id":8257797}]}]}
{"op":"mcm","clk":"4230448675","pt":1631533116068,"mc":[{"id":"1.187557146","rc":[{"trd":[[1.89,12.8],[1.92,1.9],[1.93,61],[1.98,321.61],[2,180.49],[2.1,24.48],[2.22,0.19]],"batb":[[0,1.72,38.84],[1,1.47,1.54],[2,1.25,20]],"batl":[[0,2,10],[1,2.12,143.54],[2,3,1.8]],"ltp":2.0,"tv":2357.32,"id":19931652},{"trd":[[1.82,0.24],[1.9,235.74],[2,423],[2.02,377.1],[2.08,61.59],[2.12,11.41]],"batb":[[0,1.89,1.93],[1,1.76,31.71],[2,1.74,16.04]],"batl":[[0,2.04,13.68],[1,2.16,182.85]],"ltp":2.0,"tv":19721.91,"id":8257797}],"tv":22079.23}]}
{"op":"mcm","clk":"4230448727","pt":1631533116797,"mc":[{"id":"1.187557146","rc":[{"batb":[[0,1.79,33.56],[1,1.72,38.84],[2,1.47,1.54]],"ltp":2.0,"tv":2357.32,"id":19931652},{"batb":[[0,1.89,28.46]],"ltp":2.0,"tv":19721.91,"id":8257797}]}]}
{"op":"mcm","clk":"4230448943","pt":1631533119304,"mc":[{"id":"1.187557146","rc":[{"batb":[[1,1.77,402.61],[2,1.76,31.71]],"batl":[[2,3,219.52]],"ltp":2.0,"tv":19721.91,"id":8257797}]}]}
{"op":"mcm","clk":"4230448998","pt":1631533119878,"mc":[{"id":"1.187557146","rc":[{"batb":[[0,1.89,26.53]],"ltp":2.0,"tv":19721.91,"id":8257797}]}]}
{"op":"mcm","clk":"4230449233","pt":1631533122579,"mc":[{"id":"1.187557146","rc":[{"batb":[[0,1.81,43.29],[1,1.79,33.56],[2,1.72,38.84]],"ltp":2.0,"tv":2357.32,"id":19931652},{"batl":[[2,2.24,6.73]],"ltp":2.0,"tv":19721.91,"id":8257797}]}]}
{"op":"mcm","clk":"4230449365","pt":1631533124298,"mc":[{"id":"1.187557146","rc":[{"batb":[[0,2,105],[1,1.89,26.53],[2,1.77,402.61]],"ltp":2.0,"tv":19721.91,"id":8257797}]}]}
{"op":"mcm","clk":"4230449505","pt":1631533126083,"mc":[{"id":"1.187557146","rc":[{"trd":[[1.96,89.09]],"ltp":1.96,"tv":2371.54,"id":19931652},{"trd":[[2.04,186.01]],"batb":[[0,1.89,26.53],[1,1.77,402.61],[2,1.76,31.71]],"batl":[[0,2.16,182.86],[1,2.24,6.73],[2,3,219.52]],"ltp":2.04,"tv":19735.58,"id":8257797}],"tv":22107.13}]}
{"op":"mcm","clk":"4230449935","pt":1631533132020,"mc":[{"id":"1.187557146","rc":[{"batl":[[0,1.98,12.16],[1,2,10],[2,2.12,143.54]],"ltp":1.96,"tv":2371.54,"id":19931652},{"batl":[[0,2.08,9.64],[1,2.16,182.85],[2,2.24,6.73]],"ltp":2.04,"tv":19735.58,"id":8257797}]}]}
{"op":"mcm","clk":"4230449978","pt":1631533132624,"mc":[{"id":"1.187557146","rc":[{"batb":[[1,1.79,81.87]],"ltp":1.96,"tv":2371.54,"id":19931652}]}]}
{"op":"mcm","clk":"4230450142","pt":1631533134718,"mc":[{"id":"1.187557146","rc":[{"trd":[[1.98,323.41]],"batl":[[0,1.98,10.36]],"ltp":1.98,"tv":2373.34,"id":19931652},{"trd":[[2.02,378.86]],"ltp":2.02,"tv":19737.34,"id":8257797}],"tv":22110.69}]}
{"op":"mcm","clk":"4230450245","pt":1631533136335,"mc":[{"id":"1.187557146","rc":[{"trd":[[1.98,344.13]],"batb":[[0,1.98,67.95],[1,1.81,43.29],[2,1.79,81.87]],"batl":[[0,2,10],[1,2.12,143.54],[2,3,1.8]],"ltp":1.98,"tv":2394.06,"id":19931652}],"tv":22131.41}]}
{"op":"mcm","clk":"4230450300","pt":1631533137222,"mc":[{"id":"1.187557146","rc":[{"trd":[[1.92,12.33],[1.96,89.1]],"batb":[[0,1.81,43.29],[1,1.79,81.87],[2,1.72,38.84]],"batl":[[0,1.92,2.64],[1,2,10],[2,2.12,143.54]],"ltp":1.92,"tv":2404.5,"id":19931652},{"trd":[[2.04,186.02],[2.08,71.22]],"batl":[[0,2.16,182.85],[1,2.24,6.73],[2,2.28,7.34]],"ltp":2.08,"tv":19746.98,"id":8257797}],"tv":22151.49}]}
{"op":"mcm","clk":"4230450567","pt":1631533140827,"mc":[{"id":"1.187557146","rc":[{"batb":[[1,1.8,45.13],[2,1.79,81.87]],"batl":[[0,1.92,404.64]],"ltp":1.92,"tv":2404.5,"id":19931652},{"batl":[[2,2.26,6.25]],"ltp":2.08,"tv":19746.98,"id":8257797}]}]}
{"op":"mcm","clk":"4230450729","pt":1631533142927,"mc":[{"id":"1.187557146","rc":[{"batl":[[0,1.92,2.64]],"ltp":1.92,"tv":2404.5,"id":19931652}]}]}
{"op":"mcm","clk":"4230450897","pt":1631533145338,"mc":[{"id":"1.187557146","rc":[{"trd":[[1.92,17.61]],"batb":[[0,1.92,68.47],[1,1.81,43.29],[2,1.8,45.13]],"batl":[[0,2,10],[1,2.12,143.54],[2,3,1.8]],"ltp":1.92,"tv":2409.78,"id":19931652},{"batl":[[0,2.16,183.3]],"ltp":2.08,"tv":19746.98,"id":8257797}],"tv":22156.77}]}
{"op":"mcm","clk":"4230451038","pt":1631533147214,"mc":[{"id":"1.187557146","rc":[{"batb":[[1,1.79,33.56],[2,1.74,44.52]],"batl":[[0,3,1.8],[1,990,0.01],[2,3,0]],"ltp":1.92,"tv":2409.78,"id":19931652},{"batb":[[0,1.77,402.61],[1,1.71,37.07],[2,1.58,2.09]],"batl":[[0,3,219.97],[1,990,0.01],[2,2.26,0]],"ltp":2.08,"tv":19746.98,"id":8257797}]}]}
{"op":"mcm","clk":"4230451096","pt":1631533148040,"mc":[{"id":"1.187557146","rc":[{"trd":[[1.98,344.59]],"ltp":1.98,"tv":2410.24,"id":19931652},{"trd":[[2.02,379.31]],"batl":[[0,3,219.52]],"ltp":2.02,"tv":19747.43,"id":8257797}],"tv":22157.68}]}
{"op":"mcm","clk":"4230451187","pt":1631533149238,"mc":[{"id":"1.187557146","rc":[{"trd":[[1.92,154.55]],"batb":[[0,1.79,33.56],[1,1.74,44.52],[2,1.47,1.54]],"batl":[[0,1.92,333.53],[1,3,1.8],[2,990,0.01]],"ltp":1.92,"tv":2547.18,"id":19931652}],"tv":22294.62}]}
{"op":"mcm","clk":"4230451287","pt":1631533150333,"mc":[{"id":"1.187557146","rc":[{"batb":[[0,1.79,77.87],[1,1.78,33.97],[2,1.75,43.99]],"ltp":1.92,"tv":2547.18,"id":19931652},{"batb":[[1,1.72,36.48],[2,1.71,37.07]],"batl":[[0,2.28,6.09],[1,2.34,6.75],[2,3,219.52]],"ltp":2.02,"tv":19747.43,"id":8257797}]}]}
{"op":"mcm","clk":"4230451304","pt":1631533150542,"mc":[{"id":"1.187557146","rc":[{"batb":[[0,1.78,33.97],[1,1.75,43.99],[2,1.74,44.52]],"ltp":1.92,"tv":2547.18,"id":19931652},{"batb":[[2,1.58,2.09]],"batl":[[0,2.34,6.75],[1,3,219.52],[2,990,0.01]],"ltp":2.02,"tv":19747.43,"id":8257797}]}]}
{"op":"mcm","clk":"4230451512","pt":1631533153146,"mc":[{"id":"1.187557146","rc":[{"batl":[[0,3,1.8],[1,990,0.01],[2,990,0]],"ltp":1.92,"tv":2547.18,"id":19931652},{"batb":[[0,1.72,36.48],[1,1.58,2.09],[2,1.21,766.7]],"ltp":2.02,"tv":19747.43,"id":8257797}]}]}
{"op":"mcm","clk":"4230451685","pt":1631533154835,"mc":[{"id":"1.187557146","rc":[{"batb":[[0,1.83,30.5],[1,1.81,15.42],[2,1.8,97.33]],"batl":[[0,1.86,18.26],[1,1.87,21.4],[2,1.92,111.19]],"ltp":1.92,"tv":2547.18,"id":19931652},{"batb":[[0,1.92,29.07],[1,1.9,14.69],[2,1.72,36.48]],"batl":[[0,2.24,7.3],[1,2.34,6.75],[2,3,219.52]],"ltp":2.02,"tv":19747.43,"id":8257797}]}]}
{"op":"mcm","clk":"4230451796","pt":1631533156256,"mc":[{"id":"1.187557146","rc":[{"batb":[[0,2.06,41],[1,1.92,29.07],[2,1.9,14.69]],"ltp":2.02,"tv":19747.43,"id":8257797}]}]}
{"op":"mcm","clk":"4230451875","pt":1631533157148,"mc":[{"id":"1.187557146","rc":[{"trd":[[1.78,67.94],[1.8,230.74],[1.81,30.84],[1.83,61]],"batb":[[0,1.76,4.51],[1,1.75,43.99],[2,1.74,44.52]],"ltp":1.78,"tv":2910.71,"id":19931652},{"trd":[[2.24,28.99]],"batl":[[0,2.34,6.75],[1,3,219.52],[2,990,0.01]],"ltp":2.24,"tv":19754.73,"id":8257797}],"tv":22665.44}]}
{"op":"mcm","clk":"4230451950","pt":1631533158035,"mc":[{"id":"1.187557146","rc":[{"batl":[[0,1.87,21.4],[1,1.92,111.19],[2,3,1.8]],"ltp":1.78,"tv":2910.71,"id":19931652}]}]}
{"op":"mcm","clk":"4230452128","pt":1631533160134,"mc":[{"id":"1.187557146","rc":[{"batl":[[0,1.83,402],[1,1.87,21.4],[2,1.92,111.19]],"ltp":1.78,"tv":2910.71,"id":19931652}]}]}
{"op":"mcm","clk":"4230452210","pt":1631533160930,"mc":[{"id":"1.187557146","rc":[{"batl":[[0,1.83,414.31]],"ltp":1.78,"tv":2910.71,"id":19931652},{"batb":[[1,2,22.12],[2,1.93,27.93]],"batl":[[0,2.28,10.95],[1,2.34,6.75],[2,2.44,6.33]],"ltp":2.24,"tv":19754.73,"id":8257797}]}]}
{"op":"mcm","clk":"4230452545","pt":1631533163843,"mc":[{"id":"1.187557146","rc":[{"batl":[[0,1.83,412.31]],"ltp":1.78,"tv":2910.71,"id":19931652}]}]}
{"op":"mcm","clk":"4230452692","pt":1631533165054,"mc":[{"id":"1.187557146","rc":[{"batb":[[0,1.76,4.7]],"ltp":1.78,"tv":2910.71,"id":19931652},{"batb":[[2,1.95,25.91]],"batl":[[2,2.4,5.74]],"ltp":2.24,"tv":19754.73,"id":8257797}]}]}
{"op":"mcm","clk":"4230452811","pt":1631533166065,"mc":[{"id":"1.187557146","rc":[{"batb":[[1,1.69,51.21],[2,1.68,41.67]],"batl":[[0,2.06,7.75],[1,3,1.8],[2,990,0.01]],"ltp":1.78,"tv":2910.71,"id":19931652},{"batb":[[0,1.87,27.53],[1,1.86,399.17],[2,1.58,2.09]],"batl":[[0,3,219.52],[1,990,0.01],[2,2.4,0]],"ltp":2.24,"tv":19754.73,"id":8257797}]}]}
{"op":"mcm","clk":"4230453140","pt":1631533169294,"mc":[{"id":"1.187557146","rc":[{"batb":[[1,1.72,46.84],[2,1.69,51.21]],"batl":[[0,2,23.18],[1,2.06,7.75],[2,3,1.8]],"ltp":1.78,"tv":2910.71,"id":19931652},{"batb":[[0,2,23.18],[1,1.95,25.31],[2,1.88,27.03]],"batl":[[0,2.4,6.89],[1,2.46,5.75],[2,3,219.52]],"ltp":2.24,"tv":19754.73,"id":8257797}]}]}
{"op":"mcm","clk":"4230453173","pt":1631533169454,"mc":[{"id":"1.187557146","rc":[{"batb":[[1,1.69,51.21],[2,1.67,42.34]],"batl":[[0,2.06,7.75],[1,3,1.8],[2,990,0.01]],"ltp":1.78,"tv":2910.71,"id":19931652},{"batb":[[0,1.95,25.31],[1,1.88,27.03],[2,1.86,399.17]],"batl":[[0,2.46,5.75],[1,3,219.52],[2,990,0.01]],"ltp":2.24,"tv":19754.73,"id":8257797}]}]}
{"op":"mcm","clk":"4230453383","pt":1631533171449,"mc":[{"id":"1.187557146","rc":[{"trd":[[1.76,29.56],[1.78,68.33]],"batb":[[0,1.69,51.21],[1,1.67,42.34],[2,1.47,1.54]],"batl":[[0,1.76,395.3],[1,2.06,7.75],[2,3,1.8]],"ltp":1.76,"tv":2920.11,"id":19931652}],"tv":22674.84}]}
{"op":"mcm","clk":"4230453530","pt":1631533173277,"mc":[{"id":"1.187557146","rc":[{"trd":[[1.76,33.9]],"batl":[[0,1.76,395.13],[1,2,25.16],[2,2.06,7.75]],"ltp":1.76,"tv":2924.45,"id":19931652},{"batb":[[0,2,25.42],[1,1.95,25.31],[2,1.88,27.03]],"ltp":2.24,"tv":19754.73,"id":8257797}],"tv":22679.18}]}
{"op":"mcm","clk":"4230453675","pt":1631533174987,"mc":[{"id":"1.187557146","rc":[{"batl":[[0,1.76,2],[1,2.06,7.75],[2,3,1.8]],"ltp":1.76,"tv":2924.45,"id":19931652},{"batb":[[0,1.95,25.31],[1,1.88,27.03],[2,1.86,399.17]],"ltp":2.24,"tv":19754.73,"id":8257797}]}]}
{"op":"mcm","clk":"4230453771","pt":1631533176290,"mc":[{"id":"1.187557146","rc":[{"batb":[[0,1.7,8.58],[1,1.69,51.21],[2,1.68,115.83]],"batl":[[0,1.75,114.28],[1,1.76,2],[2,1.83,269.03]],"ltp":1.76,"tv":2924.45,"id":19931652},{"batb":[[0,2.36,10.27],[1,1.95,25.31],[2,1.88,27.03]],"batl":[[1,990,0.01],[2,990,0]],"ltp":2.24,"tv":19754.73,"id":8257797}]}]}
{"op":"mcm","clk":"4230453858","pt":1631533177277,"mc":[{"id":"1.187557146","rc":[{"batb":[[0,1.7,41.41],[2,1.68,132.44]],"batl":[[0,1.75,22.86]],"ltp":1.76,"tv":2924.45,"id":19931652},{"batb":[[1,2.22,32.3],[2,2.06,40.75]],"batl":[[1,6,3],[2,6.4,3]],"ltp":2.24,"tv":19754.73,"id":8257797}]}]}
{"op":"mcm","clk":"4230454040","pt":1631533179358,"mc":[{"id":"1.187557146","rc":[{"batl":[[1,1.83,269.48],[2,1.93,28.92]],"ltp":1.76,"tv":2924.45,"id":19931652},{"batl":[[1,3.65,175.35],[2,6,3]],"ltp":2.24,"tv":19754.73,"id":8257797}]}]}
{"op":"mcm","clk":"4230454251","pt":1631533182172,"mc":[{"id":"1.187557146","rc":[{"trd":[[1.74,13.93],[1.75,45.72]],"batb":[[0,1.78,52.92],[1,1.7,41.41],[2,1.69,51.21]],"batl":[[0,1.83,269.03],[1,1.93,28.92],[2,1.95,14.32]],"ltp":1.75,"tv":2984.1,"id":19931652},{"trd":[[2.36,10.27]],"batb":[[0,2.22,32.3],[1,2.06,40.75],[2,1.97,395.66]],"ltp":2.36,"tv":19765.0,"id":8257797}],"tv":22749.1}]}
{"op":"mcm","clk":"4230454329","pt":1631533183110,"mc":[{"id":"1.187557146","rc":[{"batl":[[1,1.87,27.5],[2,1.93,28.92]],"ltp":1.75,"tv":2984.1,"id":19931652},{"batb":[[1,2.14,7.82],[2,2.06,40.75]],"batl":[[1,2.52,5.51],[2,2.58,4.75]],"ltp":2.36,"tv":19765.0,"id":8257797}]}]}
{"op":"mcm","clk":"4230454393","pt":1631533183888,"mc":[{"id":"1.187557146","rc":[{"trd":[[1.69,102.42],[1.7,82.82],[1.78,174.17]],"batb":[[0,1.68,132.44],[1,1.67,46.85],[2,1.66,55.32]],"ltp":1.69,"tv":3275.18,"id":19931652}],"tv":23040.18}]}
{"op":"mcm","clk":"4230454495","pt":1631533185290,"mc":[{"id":"1.187557146","rc":[{"batl":[[0,1.74,55],[1,1.83,269.03],[2,1.87,27.5]],"ltp":1.69,"tv":3275.18,"id":19931652}]}]}
{"op":"mcm","clk":"4230454586","pt":1631533186289,"mc":[{"id":"1.187557146","rc":[{"batb":[[0,1.68,16.61]],"batl":[[0,1.87,27.5],[1,1.88,28.29],[2,1.91,27.5]],"ltp":1.69,"tv":3275.18,"id":19931652},{"batb":[[2,2.12,7.04]],"batl":[[2,2.54,4.88]],"ltp":2.36,"tv":19765.0,"id":8257797}]}]}
{"op":"mcm","clk":"4230454643","pt":1631533187118,"mc":[{"id":"1.187557146","rc":[{"trd":[[1.69,106.42]],"batb":[[0,1.67,4.51],[1,1.62,38.58],[2,1.6,49.2]],"batl":[[0,1.68,394.82],[2,2.06,7.75]],"ltp":1.69,"tv":3279.18,"id":19931652},{"batb":[[0,2.06,40.75],[1,1.97,395.66],[2,1.95,25.31]],"batl":[[0,2.62,5.75],[1,3.65,175.35],[2,990,0.01]],"ltp":2.36,"tv":19765.0,"id":8257797}],"tv":23044.18}]}
{"op":"mcm","clk":"4230454672","pt":1631533187383,"mc":[{"id":"1.187557146","rc":[{"batl":[[0,1.88,28.29],[1,2.06,7.75],[2,3,1.8]],"ltp":1.69,"tv":3279.18,"id":19931652}]}]}
{"op":"mcm","clk":"4230454865","pt":1631533189983,"mc":[{"id":"1.187557146","rc":[{"batb":[[1,1.65,40.07],[2,1.62,38.04]],"batl":[[1,1.91,28.61],[2,2.06,7.75]],"ltp":1.69,"tv":3279.18,"id":19931652},{"batb":[[0,2.12,6.54],[1,2.08,7.06],[2,2.06,40.75]],"batl":[[0,2.54,5.75],[1,2.62,5.75],[2,3.65,175.35]],"ltp":2.36,"tv":19765.0,"id":8257797}]}]}
{"op":"mcm","clk":"4230454963","pt":1631533191126,"mc":[{"id":"1.187557146","rc":[{"trd":[[1.67,9.92]],"batb":[[0,1.65,40.07],[1,1.62,38.04],[2,1.6,49.2]],"batl":[[0,1.67,389.86],[1,1.88,28.29],[2,1.91,28.61]],"ltp":1.67,"tv":3289.1,"id":19931652}],"tv":23054.1}]}
{"op":"mcm","clk":"4230455127","pt":1631533193313,"mc":[{"id":"1.187557146","rc":[{"trd":[[1.67,100.88]],"batl":[[0,1.88,28.29],[1,1.91,28.61],[2,2.06,7.75]],"ltp":1.67,"tv":3380.06,"id":19931652},{"trd":[[2.48,5.75]],"ltp":2.48,"tv":19770.75,"id":8257797}],"tv":23150.81}]}
{"op":"mcm","clk":"4230455191","pt":1631533194201,"mc":[{"id":"1.187557146","rc":[{"batl":[[2,990,0.01]],"ltp":1.67,"tv":3380.06,"id":19931652}]}]}
{"op":"mcm","clk":"4230455349","pt":1631533196307,"mc":[{"id":"1.187557146","rc":[{"batl":[[0,1.68,11.14],[1,1.72,116.28],[2,1.73,1765.02]],"ltp":1.67,"tv":3380.06,"id":19931652},{"batb":[[0,2.4,82.69],[1,2.12,6.54],[2,2.08,7.06]],"batl":[[1,2.56,10.99],[2,2.6,82.66]],"ltp":2.48,"tv":19770.75,"id":8257797}]}]}
{"op":"mcm","clk":"4230455374","pt":1631533196621,"mc":[{"id":"1.187557146","rc":[{"batb":[[1,1.63,34.24],[2,1.62,38.04]],"batl":[[0,1.72,23.26],[1,1.85,30.17],[2,1.87,14.92]],"ltp":1.67,"tv":3380.06,"id":19931652},{"batl":[[1,2.6,82.66],[2,2.62,5.75]],"ltp":2.48,"tv":19770.75,"id":8257797}]}]}
{"op":"mcm","clk":"4230455454","pt":1631533197711,"mc":[{"id":"1.187557146","rc":[{"batb":[[1,2.36,27.28],[2,2.24,31.55]],"ltp":2.48,"tv":19770.75,"id":8257797}]}]}
{"op":"mcm","clk":"4230455607","pt":1631533199741,"mc":[{"id":"1.187557146","rc":[{"batb":[[0,1.65,40.3]],"batl":[[0,1.68,11.14],[1,1.72,23.26],[2,1.85,30.17]],"ltp":1.67,"tv":3380.06,"id":19931652},{"batl":[[1,2.56,10.99],[2,2.6,82.66]],"ltp":2.48,"tv":19770.75,"id":8257797}]}]}
{"op":"mcm","clk":"4230455723","pt":1631533201319,"mc":[{"id":"1.187557146","rc":[{"trd":[[1.65,79.06],[1.66,2.75],[1.67,101.34],[1.68,4.34]],"batb":[[0,1.63,34.24],[1,1.62,38.04],[2,1.61,17.33]],"batl":[[0,1.68,8.97]],"ltp":1.65,"tv":3465.0,"id":19931652}],"tv":23235.75}]}
{"op":"mcm","clk":"4230455999","pt":1631533204728,"mc":[{"id":"1.187557146","rc":[{"trd":[[1.64,26.07]],"batl":[[0,1.64,273.74],[1,1.68,8.97],[2,1.72,23.26]],"ltp":1.64,"tv":3491.07,"id":19931652},{"trd":[[2.54,5.75],[2.56,10.99]],"batl":[[0,2.6,82.66],[1,2.62,5.75],[2,990,0.01]],"ltp":2.56,"tv":19787.49,"id":8257797}],"tv":23278.56}]}
{"op":"mcm","clk":"4230456121","pt":1631533206243,"mc":[{"id":"1.187557146","rc":[{"trd":[[1.64,98.19]],"batl":[[0,1.64,237.68]],"ltp":1.64,"tv":3563.19,"id":19931652}],"tv":23350.68}]}
{"op":"mcm","clk":"4230456202","pt":1631533207137,"mc":[{"id":"1.187557146","rc":[{"batb":[[1,2.36,33.96]],"ltp":2.56,"tv":19787.49,"id":8257797}]}]}
{"op":"mcm","clk":"4230456291","pt":1631533208330,"mc":[{"id":"1.187557146","rc":[{"batl":[[0,1.68,8.97],[1,1.72,23.26],[2,1.85,30.17]],"ltp":1.64,"tv":3563.19,"id":19931652},{"batb":[[1,2.36,27.28]],"ltp":2.56,"tv":19787.49,"id":8257797}]}]}
{"op":"mcm","clk":"4230456333","pt":1631533208954,"mc":[{"id":"1.187557146","rc":[{"batb":[[2,2.34,6.72]],"ltp":2.56,"tv":19787.49,"id":8257797}]}]}
{"op":"mcm","clk":"4230456475","pt":1631533210629,"mc":[{"id":"1.187557146","rc":[{"batl":[[0,1.72,23.26],[1,1.85,30.17],[2,1.87,14.92]],"ltp":1.64,"tv":3563.19,"id":19931652}]}]}
{"op":"mcm","clk":"4230456594","pt":1631533212142,"mc":[{"id":"1.187557146","rc":[{"batl":[[1,1.74,32.75],[2,1.85,30.17]],"ltp":1.64,"tv":3563.19,"id":19931652}]}]}
{"op":"mcm","clk":"4230456625","pt":1631533212457,"mc":[{"id":"1.187557146","rc":[{"batl":[[1,1.85,30.17],[2,1.87,14.92]],"ltp":1.64,"tv":3563.19,"id":19931652}]}]}
{"op":"mcm","clk":"4230456769","pt":1631533214166,"mc":[{"id":"1.187557146","rc":[{"batb":[[0,1.62,38.04],[1,1.6,49.2],[2,1.57,4.51]],"batl":[[0,990,0.01],[1,1.85,0],[2,1.87,0]],"ltp":1.64,"tv":3563.19,"id":19931652},{"batb":[[0,2.36,27.28],[1,2.24,31.55],[2,1.58,2.09]],"batl":[[0,990,0.01],[1,2.62,0],[2,990,0]],"ltp":2.56,"tv":19787.49,"id":8257797}]}]}
{"op":"mcm","clk":"4230456835","pt":1631533214950,"mc":[{"id":"1.187557146","rc":[{"batb":[[1,1.57,4.51],[2,1.56,53.81]],"ltp":1.64,"tv":3563.19,"id":19931652},{"batb":[[0,2.24,31.55],[1,1.58,2.09],[2,1.21,766.7]],"batl":[[0,2.56,1.38],[1,990,0.01]],"ltp":2.56,"tv":19787.49,"id":8257797}]}]}
{"op":"mcm","clk":"4230456907","pt":1631533215880,"mc":[{"id":"1.187557146","rc":[{"trd":[[1.64,100.34]],"batl":[[0,1.63,235.53],[1,1.74,34.75],[2,990,0.01]],"ltp":1.64,"tv":3565.34,"id":19931652},{"trd":[[2.56,12.37]],"batl":[[0,990,0.01],[1,990,0]],"ltp":2.56,"tv":19788.87,"id":8257797}],"tv":23354.21}]}
{"op":"mcm","clk":"4230457037","pt":1631533217352,"mc":[{"id":"1.187557146","rc":[{"batl":[[1,1.73,32.5],[2,1.74,34.75]],"ltp":1.64,"tv":3565.34,"id":19931652},{"batb":[[0,2.36,6.43],[1,2.34,5.72],[2,2.24,31.55]],"ltp":2.56,"tv":19788.87,"id":8257797}]}]}
{"op":"mcm","clk":"4230457269","pt":1631533219851,"mc":[{"id":"1.187557146","rc":[{"batl":[[0,1.73,32.5],[1,1.74,34.75],[2,990,0.01]],"ltp":1.64,"tv":3565.34,"id":19931652}]}]}
{"op":"mcm","clk":"4230457451","pt":1631533222346,"mc":[{"id":"1.187557146","rc":[{"batl":[[0,1.64,16.1],[1,1.66,21.75],[2,1.68,100.81]],"ltp":1.64,"tv":3565.34,"id":19931652},{"batb":[[0,2.5,21.36],[1,2.36,6.43],[2,2.34,5.72]],"batl":[[0,2.66,90.86],[1,990,0.01]],"ltp":2.56,"tv":19788.87,"id":8257797}]}]}
{"op":"mcm","clk":"4230457501","pt":1631533223069,"mc":[{"id":"1.187557146","rc":[{"batb":[[1,1.61,34.67],[2,1.59,17.55]],"ltp":1.64,"tv":3565.34,"id":19931652},{"batb":[[1,2.46,24.6],[2,2.36,6.43]],"ltp":2.56,"tv":19788.87,"id":8257797}]}]}
{"op":"mcm","clk":"4230457829","pt":1631533227764,"mc":[{"id":"1.187557146","rc":[{"trd":[[1.62,76.08]],"batb":[[0,1.61,34.67],[1,1.59,17.55],[2,1.57,4.51]],"batl":[[0,1.62,197.49],[1,1.64,16.1],[2,1.66,21.75]],"ltp":1.62,"tv":3641.42,"id":19931652}],"tv":23430.29}]}
{"op":"mcm","clk":"4230458052","pt":1631533231096,"mc":[{"id":"1.187557146","rc":[{"batl":[[0,1.62,110]],"ltp":1.62,"tv":3641.42,"id":19931652}]}]}
{"op":"mcm","clk":"4230458536","pt":1631533237905,"mc":[{"id":"1.187557146","rc":[{"trd":[[1.61,69.65]],"batb":[[0,1.59,17.55],[1,1.57,4.51],[2,1.56,53.81]],"batl":[[0,1.61,162.51],[1,1.62,110],[2,1.64,16.1]],"ltp":1.61,"tv":3711.07,"id":19931652},{"trd":[[2.62,0.19]],"ltp":2.62,"tv":19789.06,"id":8257797}],"tv":23500.14}]}
{"op":"mcm","clk":"4230458860","pt":1631533241815,"mc":[{"id":"1.187557146","rc":[{"trd":[[1.61,74.36]],"batl":[[0,1.62,110],[1,1.64,16.1],[2,1.66,21.75]],"ltp":1.61,"tv":3715.78,"id":19931652},{"trd":[[2.62,3.09]],"ltp":2.62,"tv":19791.95,"id":8257797}],"tv":23507.74}]}
{"op":"mcm","clk":"4230458948","pt":1631533242905,"mc":[{"id":"1.187557146","rc":[{"trd":[[1.62,76.26]],"batl":[[0,1.62,109.91]],"ltp":1.62,"tv":3715.96,"id":19931652}],"tv":23507.92}]}
{"op":"mcm","clk":"4230459171","pt":1631533245337,"mc":[{"id":"1.187557146","rc":[{"trd":[[1.6,11.03]],"ltp":1.6,"tv":3726.99,"id":19931652},{"trd":[[2.66,6.63]],"batl":[[0,2.66,84.23]],"ltp":2.66,"tv":19798.58,"id":8257797}],"tv":23525.58}]}
{"op":"mcm","clk":"4230459400","pt":1631533248039,"mc":[{"id":"1.187557146","rc":[{"trd":[[1.6,12.41]],"ltp":1.6,"tv":3728.37,"id":19931652},{"trd":[[2.66,7.46]],"batl":[[0,2.66,83.4]],"ltp":2.66,"tv":19799.41,"id":8257797}],"tv":23527.79}]}
{"op":"mcm","clk":"4230459655","pt":1631533251113,"mc":[{"id":"1.187557146","rc":[{"batl":[[0,1.61,157.8],[1,1.62,109.91],[2,1.64,16.1]],"ltp":1.6,"tv":3728.37,"id":19931652}]}]}
{"op":"mcm","clk":"4230459915","pt":1631533254061,"mc":[{"id":"1.187557146","rc":[{"trd":[[1.6,18.41]],"ltp":1.6,"tv":3734.37,"id":19931652},{"trd":[[2.66,11.07]],"batl":[[0,2.66,79.79]],"ltp":2.66,"tv":19803.02,"id":8257797}],"tv":23537.4}]}
{"op":"mcm","clk":"4230460080","pt":1631533256136,"mc":[{"id":"1.187557146","rc":[{"batl":[[0,1.62,109.91],[1,1.66,21.75],[2,1.68,100.81]],"ltp":1.6,"tv":3734.37,"id":19931652}]}]}
{"op":"mcm","clk":"4230460562","pt":1631533262027,"mc":[{"id":"1.187557146","rc":[{"trd":[[1.6,151.06]],"batl":[[0,1.62,124.12]],"ltp":1.6,"tv":3867.02,"id":19931652},{"trd":[[2.66,90.86]],"batl":[[0,2.72,10.52]],"ltp":2.66,"tv":19882.81,"id":8257797}],"tv":23749.84}]}
{"op":"mcm","clk":"4230460756","pt":1631533264257,"mc":[{"id":"1.187557146","rc":[{"batl":[[0,1.62,109.91]],"ltp":1.6,"tv":3867.02,"id":19931652},{"batl":[[0,990,0.01],[1,990,0]],"ltp":2.66,"tv":19882.81,"id":8257797}]}]}
{"op":"mcm","clk":"4230460985","pt":1631533267198,"mc":[{"id":"1.187557146","rc":[{"batl":[[0,1.62,124.12]],"ltp":1.6,"tv":3867.02,"id":19931652},{"batl":[[0,2.72,10.52],[1,6,3],[2,6.4,3]],"ltp":2.66,"tv":19882.81,"id":8257797}]}]}
{"op":"mcm","clk":"4230461413","pt":1631533272489,"mc":[{"id":"1.187557146","rc":[{"trd":[[1.62,324.5]],"batb":[[0,1.62,55.61],[1,1.59,17.55],[2,1.57,4.51]],"batl":[[0,1.66,21.75],[1,1.68,100.81],[2,1.73,32.59]],"ltp":1.62,"tv":4115.26,"id":19931652}],"tv":23998.07}]}
{"op":"mcm","clk":"4230461768","pt":1631533276275,"mc":[{"id":"1.187557146","rc":[{"trd":[[1.62,344.5]],"batb":[[0,1.62,45.61]],"ltp":1.62,"tv":4135.26,"id":19931652}],"tv":24018.07}]}
{"op":"mcm","clk":"4230461915","pt":1631533277991,"mc":[{"id":"1.187557146","rc":[{"trd":[[1.62,394.8]],"batb":[[0,1.62,20.46]],"ltp":1.62,"tv":4185.56,"id":19931652}],"tv":24068.38}]}
{"op":"mcm","clk":"4230462353","pt":1631533282674,"mc":[{"id":"1.187557146","rc":[{"batl":[[0,6,3],[1,6.4,3],[2,6.6,3]],"ltp":2.66,"tv":19882.81,"id":8257797}]}]}
{"op":"mcm","clk":"4230462604","pt":1631533285587,"mc":[{"id":"1.187557146","rc":[{"batl":[[0,1.64,15.39],[1,1.66,21.75],[2,1.68,100.81]],"ltp":1.62,"tv":4185.56,"id":19931652},{"batl":[[0,2.66,8.67],[1,6,3],[2,6.4,3]],"ltp":2.66,"tv":19882.81,"id":8257797}]}]}
{"op":"mcm","clk":"4230463239","pt":1631533293390,"mc":[{"id":"1.187557146","rc":[{"batb":[[0,1.59,17.55],[1,1.57,4.51],[2,1.56,53.81]],"ltp":1.62,"tv":4185.56,"id":19931652}]}]}
{"op":"mcm","clk":"4230463546","pt":1631533297190,"mc":[{"id":"1.187557146","rc":[{"trd":[[1.64,109.36]],"batl":[[0,1.64,10.88]],"ltp":1.64,"tv":4194.58,"id":19931652}],"tv":24077.4}]}
{"op":"mcm","clk":"4230463816","pt":1631533301102,"mc":[{"id":"1.187557146","rc":[{"trd":[[1.64,110.26]],"batl":[[0,1.64,10.43]],"ltp":1.64,"tv":4195.48,"id":19931652}],"tv":24078.3}]}
{"op":"mcm","clk":"4230463988","pt":1631533303212,"mc":[{"id":"1.187557146","rc":[{"trd":[[1.64,131.12]],"batb":[[0,1.64,10.02],[1,1.59,17.55],[2,1.57,4.51]],"batl":[[0,1.66,21.75],[1,1.68,100.81],[2,1.73,32.59]],"ltp":1.64,"tv":4216.34,"id":19931652}],"tv":24099.15}]}
{"op":"mcm","clk":"4230464226","pt":1631533306335,"mc":[{"id":"1.187557146","rc":[{"trd":[[1.64,151.15]],"batb":[[0,1.59,17.55],[1,1.57,4.51],[2,1.56,53.81]],"ltp":1.64,"tv":4236.37,"id":19931652}],"tv":24119.19}]}
{"op":"mcm","clk":"4230464310","pt":1631533307325,"mc":[{"id":"1.187557146","rc":[{"batl":[[0,6,3],[1,6.4,3],[2,6.6,3]],"ltp":2.66,"tv":19882.81,"id":8257797}]}]}
{"op":"mcm","clk":"4230464562","pt":1631533310357,"mc":[{"id":"1.187557146","rc":[{"batb":[[0,1.57,4.51],[1,1.56,53.81],[2,1.47,1]],"batl":[[0,1.66,36.42]],"ltp":1.64,"tv":4236.37,"id":19931652},{"batl":[[0,2.6,7.26],[1,6,3],[2,6.4,3]],"ltp":2.66,"tv":19882.81,"id":8257797}]}]}
{"op":"mcm","clk":"4230464640","pt":1631533311349,"mc":[{"id":"1.187557146","rc":[{"batl":[[0,1.66,21.75]],"ltp":1.64,"tv":4236.37,"id":19931652},{"batl":[[0,6,3],[1,6.4,3],[2,6.6,3]],"ltp":2.66,"tv":19882.81,"id":8257797}]}]}
{"op":"mcm","clk":"4230464965","pt":1631533315151,"mc":[{"id":"1.187557146","rc":[{"batl":[[1,1.73,32.59],[2,1.74,34.75]],"ltp":1.64,"tv":4236.37,"id":19931652},{"batb":[[0,2.5,5.36]],"ltp":2.66,"tv":19882.81,"id":8257797}]}]}
{"op":"mcm","clk":"4230465011","pt":1631533315776,"mc":[{"id":"1.187557146","rc":[{"batb":[[1,1.47,1],[2,1.44,75.15]],"batl":[[0,1.78,33.84],[1,990,0.01],[2,1.74,0]],"ltp":1.64,"tv":4236.37,"id":19931652},{"batb":[[0,2.22,32.3],[1,2.16,2.62],[2,1.21,766.7]],"ltp":2.66,"tv":19882.81,"id":8257797}]}]}
{"op":"mcm","clk":"4230465291","pt":1631533318841,"mc":[{"id":"1.187557146","rc":[{"batb":[[0,2.28,6.16],[1,2.22,32.3],[2,2.16,2.62]],"ltp":2.66,"tv":19882.81,"id":8257797}]}]}
{"op":"mcm","clk":"4230465614","pt":1631533322193,"mc":[{"id":"1.187557146","rc":[{"batl":[[0,1.74,32.84],[1,1.78,33.75],[2,990,0.01]],"ltp":1.64,"tv":4236.37,"id":19931652},{"batb":[[0,2.34,6.22],[1,2.28,6.16],[2,2.22,32.3]],"ltp":2.66,"tv":19882.81,"id":8257797}]}]}
{"op":"mcm","clk":"4230465643","pt":1631533322456,"mc":[{"id":"1.187557146","rc":[{"batl":[[0,1.78,33.84],[1,990,0.01],[2,990,0]],"ltp":1.64,"tv":4236.37,"id":19931652},{"batb":[[0,2.28,6.16],[1,2.22,32.3],[2,2.16,2.62]],"ltp":2.66,"tv":19882.81,"id":8257797}]}]}
{"op":"mcm","clk":"4230466135","pt":1631533328287,"mc":[{"id":"1.187557146","rc":[{"trd":[[1.57,9.02]],"batb":[[0,1.47,1],[1,1.44,75.15],[2,1.42,2.07]],"batl":[[0,1.52,12.75],[1,1.53,50.5],[2,1.56,128.2]],"ltp":1.57,"tv":4245.39,"id":19931652},{"batb":[[0,2.88,96.52],[1,2.28,6.16],[2,2.22,32.3]],"batl":[[0,3.05,10.53],[1,3.25,83.22],[2,6,3]],"ltp":2.66,"tv":19882.81,"id":8257797}],"tv":24128.21}]}
{"op":"mcm","clk":"4230466203","pt":1631533329171,"mc":[{"id":"1.187557146","rc":[{"trd":[[1.52,4.34]],"batb":[[0,1.48,37.72],[1,1.47,1],[2,1.46,19.12]],"batl":[[0,1.52,10.58],[2,1.56,25.64]],"ltp":1.52,"tv":4249.73,"id":19931652},{"batb":[[1,2.84,41.42],[2,2.5,23.26]],"ltp":2.66,"tv":19882.81,"id":8257797}],"tv":24132.55}]}
{"op":"mcm","clk":"4230466709","pt":1631533335117,"mc":[{"id":"1.187557146","rc":[{"batb":[[2,2.58,5.56]],"ltp":2.66,"tv":19882.81,"id":8257797}]}]}
{"op":"mcm","clk":"4230467049","pt":1631533339083,"mc":[{"id":"1.187557146","rc":[{"batl":[[0,1.53,50.5],[1,1.56,25.64],[2,1.63,40.5]],"ltp":1.52,"tv":4249.73,"id":19931652},{"batl":[[0,3.25,83.22],[1,6,3],[2,6.4,3]],"ltp":2.66,"tv":19882.81,"id":8257797}]}]}
{"op":"mcm","clk":"4230467284","pt":1631533342005,"mc":[{"id":"1.187557146","rc":[{"batl":[[0,1.52,10.58],[1,1.53,50.5],[2,1.56,25.64]],"ltp":1.52,"tv":4249.73,"id":19931652},{"batl":[[0,3,5.13],[1,3.25,83.22],[2,6,3]],"ltp":2.66,"tv":19882.81,"id":8257797}]}]}
{"op":"mcm","clk":"4230467566","pt":1631533345245,"mc":[{"id":"1.187557146","rc":[{"batb":[[0,1.47,1],[1,1.42,2.07],[2,1.31,112.22]],"batl":[[0,1.67,40.5],[1,990,0.1],[2,1.56,0]],"ltp":1.52,"tv":4249.73,"id":19931652},{"batb":[[0,2.5,23.26],[1,2.48,5.51],[2,2.16,2.62]],"batl":[[0,6,3],[1,6.4,3],[2,6.6,3]],"ltp":2.66,"tv":19882.81,"id":8257797}]}]}
{"op":"mcm","clk":"4230467794","pt":1631533348300,"mc":[{"id":"1.187557146","rc":[{"batl":[[0,1.63,44.5],[1,1.67,40.5],[2,990,0.1]],"ltp":1.52,"tv":4249.73,"id":19931652},{"batb":[[0,2.58,5.56],[1,2.5,23.26],[2,2.48,5.51]],"ltp":2.66,"tv":19882.81,"id":8257797}]}]}
{"op":"mcm","clk":"4230467862","pt":1631533349238,"mc":[{"id":"1.187557146","rc":[{"batb":[[0,1.53,7.84],[1,1.47,1],[2,1.42,2.07]],"batl":[[0,1.67,40.5],[1,990,0.1],[2,990,0]],"ltp":1.52,"tv":4249.73,"id":19931652},{"batb":[[0,2.5,23.26],[1,2.48,5.51],[2,2.16,2.62]],"ltp":2.66,"tv":19882.81,"id":8257797}]}]}
{"op":"mcm","clk":"4230467947","pt":1631533350238,"mc":[{"id":"1.187557146","rc":[{"trd":[[1.53,15.68]],"batb":[[0,1.47,1],[1,1.42,2.07],[2,1.36,3.62]],"ltp":1.53,"tv":4265.41,"id":19931652}],"tv":24148.23}]}
{"op":"mcm","clk":"4230468121","pt":1631533352231,"mc":[{"id":"1.187557146","rc":[{"batl":[[0,1.63,38.5],[1,1.67,40.5],[2,990,0.1]],"ltp":1.53,"tv":4265.41,"id":19931652},{"batb":[[0,2.58,5.56],[1,2.5,23.26],[2,2.48,5.51]],"ltp":2.66,"tv":19882.81,"id":8257797}]}]}
{"op":"mcm","clk":"4230468209","pt":1631533353162,"mc":[{"id":"1.187557146","rc":[{"batb":[[2,1.31,112.22]],"batl":[[0,1.67,40.5],[1,990,0.1],[2,990,0]],"ltp":1.53,"tv":4265.41,"id":19931652},{"batb":[[0,2.5,23.26],[1,2.48,5.51],[2,2.16,2.62]],"ltp":2.66,"tv":19882.81,"id":8257797}]}]}
{"op":"mcm","clk":"4230468510","pt":1631533356252,"mc":[{"id":"1.187557146","rc":[{"batb":[[2,1.32,3.62]],"ltp":1.53,"tv":4265.41,"id":19931652}]}]}
{"op":"mcm","clk":"4230468522","pt":1631533356458,"mc":[{"id":"1.187557146","rc":[{"batb":[[0,1.66,2.17],[1,1.47,1],[2,1.42,2.07]],"ltp":1.53,"tv":4265.41,"id":19931652}]}]}
{"op":"mcm","clk":"4230468831","pt":1631533359869,"mc":[{"id":"1.187557146","rc":[{"trd":[[1.66,7.09]],"batb":[[0,1.47,1],[1,1.42,2.07],[2,1.32,3.62]],"ltp":1.66,"tv":4269.75,"id":19931652}],"tv":24152.57}]}
{"op":"mcm","clk":"4230469664","pt":1631533370077,"mc":[{"id":"1.187557146","rc":[{"batb":[[0,2.58,5.56],[1,2.5,23.26],[2,2.48,5.51]],"ltp":2.66,"tv":19882.81,"id":8257797}]}]}
{"op":"mcm","clk":"4230469697","pt":1631533370444,"mc":[{"id":"1.187557146","rc":[{"trd":[[1.31,8],[1.32,7.23],[1.42,4.14],[1.47,2]],"batb":[[0,1.31,108.22],[1,1.25,20],[2,1.2,100]],"ltp":1.31,"tv":4291.12,"id":19931652},{"batb":[[0,2.5,23.26],[1,2.48,5.51],[2,2.16,2.62]],"ltp":2.66,"tv":19882.81,"id":8257797}],"tv":24173.94}]}
{"op":"mcm","clk":"4230469929","pt":1631533372961,"mc":[{"id":"1.187557146","rc":[{"batb":[[0,1.59,35.11],[1,1.57,17.78],[2,1.31,108.22]],"batl":[[0,1.64,156.4],[1,1.67,40.5],[2,1.8,31.1]],"ltp":1.31,"tv":4291.12,"id":19931652},{"batl":[[0,2.66,7.76],[1,2.68,14.92],[2,3.05,83.22]],"ltp":2.66,"tv":19882.81,"id":8257797}]}]}
{"op":"mcm","clk":"4230469973","pt":1631533373579,"mc":[{"id":"1.187557146","rc":[{"batb":[[2,1.54,56.48]],"ltp":1.31,"tv":4291.12,"id":19931652},{"batb":[[2,2.22,32.3]],"ltp":2.66,"tv":19882.81,"id":8257797}]}]}
{"op":"mcm","clk":"4230470451","pt":1631533379207,"mc":[{"id":"1.187557146","rc":[{"batl":[[1,1.66,44],[2,1.67,40.5]],"ltp":1.31,"tv":4291.12,"id":19931652}]}]}
{"op":"mcm","clk":"4230470498","pt":1631533379785,"mc":[{"id":"1.187557146","rc":[{"batb":[[0,1.63,2.17],[1,1.59,35.11],[2,1.57,17.78]],"batl":[[1,1.66,46]],"ltp":1.31,"tv":4291.12,"id":19931652},{"batb":[[2,2.34,6.22]],"ltp":2.66,"tv":19882.81,"id":8257797}]}]}
{"op":"mcm","clk":"4230470662","pt":1631533381569,"mc":[{"id":"1.187557146","rc":[{"trd":[[1.63,2.17]],"batb":[[0,1.59,35.11],[1,1.57,17.78],[2,1.54,56.48]],"ltp":1.63,"tv":4293.29,"id":19931652},{"trd":[[2.6,1.36],[2.66,100.14]],"batl":[[0,2.66,3.12]],"ltp":2.66,"tv":19893.45,"id":8257797}],"tv":24186.75}]}
{"op":"mcm","clk":"4230471204","pt":1631533388012,"mc":[{"id":"1.187557146","rc":[{"batb":[[0,1.4,83.51],[1,1.3,3.62],[2,1.25,20]],"batl":[[0,1.66,46],[1,1.78,31.34],[2,990,0.01]],"ltp":1.63,"tv":4293.29,"id":19931652},{"batb":[[0,2.28,6.16],[1,2.22,32.3],[2,2.16,2.62]],"batl":[[0,3.9,162.84],[1,6,3],[2,6.4,3]],"ltp":2.66,"tv":19893.45,"id":8257797}]}]}
{"op":"mcm","clk":"4230471230","pt":1631533388380,"mc":[{"id":"1.187557146","rc":[{"batb":[[1,1.25,20],[2,1.2,100]],"ltp":1.63,"tv":4293.29,"id":19931652}]}]}
{"op":"mcm","clk":"4230471345","pt":1631533389989,"mc":[{"id":"1.187557146","rc":[{"batb":[[1,1.3,3.62],[2,1.25,20]],"ltp":1.63,"tv":4293.29,"id":19931652}]}]}
{"op":"mcm","clk":"4230471730","pt":1631533394215,"mc":[{"id":"1.187557146","rc":[{"batb":[[0,1.57,19.57],[1,1.4,83.51],[2,1.3,3.62]],"batl":[[0,1.63,19.5],[1,1.66,46],[2,1.78,31.34]],"ltp":1.63,"tv":4293.29,"id":19931652},{"batl":[[0,2.74,20.75],[1,3.9,162.84],[2,6,3]],"ltp":2.66,"tv":19893.45,"id":8257797}]}]}
{"op":"mcm","clk":"4230471841","pt":1631533395313,"mc":[{"id":"1.187557146","rc":[{"batb":[[0,1.4,83.51],[1,1.3,3.62],[2,1.27,3.62]],"batl":[[0,1.66,46],[1,1.78,31.34],[2,990,0.01]],"ltp":1.63,"tv":4293.29,"id":19931652},{"batl":[[0,3.9,162.84],[1,6,3],[2,6.4,3]],"ltp":2.66,"tv":19893.45,"id":8257797}]}]}
{"op":"mcm","clk":"4230471873","pt":1631533395621,"mc":[{"id":"1.187557146","rc":[{"batl":[[0,1.66,44]],"ltp":1.63,"tv":4293.29,"id":19931652}]}]}
{"op":"mcm","clk":"4230472054","pt":1631533397212,"mc":[{"id":"1.187557146","rc":[{"batl":[[0,1.66,4]],"ltp":1.63,"tv":4293.29,"id":19931652}]}]}
{"op":"mcm","clk":"4230472171","pt":1631533398301,"mc":[{"id":"1.187557146","rc":[{"trd":[[1.64,155.49]],"batl":[[0,1.6,3.34],[1,1.66,2],[2,1.78,31.34]],"ltp":1.64,"tv":4297.63,"id":19931652},{"batb":[[2,2.04,395.05]],"ltp":2.66,"tv":19893.45,"id":8257797}],"tv":24191.09}]}
{"op":"mcm","clk":"4230472283","pt":1631533399599,"mc":[{"id":"1.187557146","rc":[{"batl":[[1,1.78,31.34],[2,990,0.01]],"ltp":1.64,"tv":4297.63,"id":19931652}]}]}
{"op":"mcm","clk":"4230472547","pt":1631533402110,"mc":[{"id":"1.187557146","rc":[{"batl":[[0,1.78,31.34],[1,990,0.01],[2,990,0]],"ltp":1.64,"tv":4297.63,"id":19931652}]}]}
{"op":"mcm","clk":"4230472858","pt":1631533405137,"mc":[{"id":"1.187557146","rc":[{"batl":[[0,1.74,35.84],[1,1.78,31.25],[2,990,0.01]],"ltp":1.64,"tv":4297.63,"id":19931652},{"batb":[[0,2.34,7.22],[1,2.28,6.16],[2,2.22,32.3]],"ltp":2.66,"tv":19893.45,"id":8257797}]}]}
{"op":"mcm","clk":"4230472894","pt":1631533405443,"mc":[{"id":"1.187557146","rc":[{"batl":[[0,1.78,31.34],[1,990,0.01],[2,990,0]],"ltp":1.64,"tv":4297.63,"id":19931652},{"batb":[[0,2.28,6.16],[1,2.22,32.3],[2,2.04,395.05]],"ltp":2.66,"tv":19893.45,"id":8257797}]}]}
{"op":"mcm","clk":"4230473438","pt":1631533410951,"mc":[{"id":"1.187557146","rc":[{"batl":[[1,990,0.01],[2,6.4,0]],"ltp":2.66,"tv":19893.45,"id":8257797}]}]}
{"op":"mcm","clk":"4230473555","pt":1631533412131,"mc":[{"id":"1.187557146","rc":[{"batl":[[0,1.74,36.34],[1,1.78,31.25],[2,990,0.01]],"ltp":1.64,"tv":4297.63,"id":19931652},{"batb":[[0,2.34,6.22],[1,2.28,6.16],[2,2.22,32.3]],"batl":[[0,990,0.01],[1,990,0]],"ltp":2.66,"tv":19893.45,"id":8257797}]}]}
{"op":"mcm","clk":"4230473650","pt":1631533413118,"mc":[{"id":"1.187557146","rc":[{"trd":[[1.72,21.03]],"batb":[[0,1.72,32.36],[1,1.7,16.42],[2,1.66,24.1]],"batl":[[0,1.76,106.7],[2,1.97,28.33]],"ltp":1.72,"tv":4297.81,"id":19931652},{"batb":[[0,2.32,12.74]],"batl":[[0,2.4,7.02],[1,2.72,83.22],[2,990,0.01]],"ltp":2.66,"tv":19893.45,"id":8257797}],"tv":24191.27}]}
{"op":"mcm","clk":"4230473768","pt":1631533414324,"mc":[{"id":"1.187557146","rc":[{"batb":[[1,1.71,2.17],[2,1.7,16.42]],"ltp":1.72,"tv":4297.81,"id":19931652}]}]}
{"op":"mcm","clk":"4230473895","pt":1631533415925,"mc":[{"id":"1.187557146","rc":[{"batl":[[2,3.45,185.61]],"ltp":2.66,"tv":19893.45,"id":8257797}]}]}
{"op":"mcm","clk":"4230474185","pt":1631533419349,"mc":[{"id":"1.187557146","rc":[{"batl":[[2,1.84,31.28]],"ltp":1.72,"tv":4297.81,"id":19931652},{"batl":[[1,2.68,4.39],[2,2.72,83.22]],"ltp":2.66,"tv":19893.45,"id":8257797}]}]}
{"op":"mcm","clk":"4230474387","pt":1631533421535,"mc":[{"id":"1.187557146","rc":[{"batb":[[1,1.7,16.42],[2,1.67,42.43]],"ltp":1.72,"tv":4297.81,"id":19931652}]}]}
{"op":"mcm","clk":"4230474647","pt":1631533424143,"mc":[{"id":"1.187557146","rc":[{"batb":[[0,1.6,43.09],[1,1.55,48.19],[2,1.52,59.33]],"batl":[[0,1.88,34.29],[1,990,0.01],[2,1.84,0]],"ltp":1.72,"tv":4297.81,"id":19931652},{"batb":[[0,2.04,436.22],[1,1.21,766.7],[2,2.22,0]],"batl":[[0,2.68,4.39],[1,2.82,4.75],[2,3.45,185.61]],"ltp":2.66,"tv":19893.45,"id":8257797}]}]}
{"op":"mcm","clk":"4230474739","pt":1631533425073,"mc":[{"id":"1.187557146","rc":[{"batb":[[0,1.55,48.19],[1,1.52,59.33],[2,1.3,3.62]],"ltp":1.72,"tv":4297.81,"id":19931652},{"batb":[[0,2.4,4.2],[1,2.04,436.22],[2,1.21,766.7]],"batl":[[0,2.82,4.75],[1,3.45,185.61],[2,990,0.01]],"ltp":2.66,"tv":19893.45,"id":8257797}]}]}
{"op":"mcm","clk":"4230474830","pt":1631533426175,"mc":[{"id":"1.187557146","rc":[{"batl":[[0,1.72,5.49],[1,1.88,34.29],[2,990,0.01]],"ltp":1.72,"tv":4297.81,"id":19931652}]}]}
{"op":"mcm","clk":"4230474941","pt":1631533427270,"mc":[{"id":"1.187557146","rc":[{"batl":[[1,1.84,34.03],[2,1.88,34.29]],"ltp":1.72,"tv":4297.81,"id":19931652},{"batb":[[1,2.18,7.36],[2,2.12,7.29]],"ltp":2.66,"tv":19893.45,"id":8257797}]}]}
{"op":"mcm","clk":"4230475000","pt":1631533427951,"mc":[{"id":"1.187557146","rc":[{"batl":[[1,1.88,34.29],[2,990,0.01]],"ltp":1.72,"tv":4297.81,"id":19931652},{"batb":[[1,2.12,7.29],[2,2.04,436.22]],"ltp":2.66,"tv":19893.45,"id":8257797}]}]}
{"op":"mcm","clk":"4230475170","pt":1631533429975,"mc":[{"id":"1.187557146","rc":[{"batl":[[0,1.72,9.62]],"ltp":1.72,"tv":4297.81,"id":19931652}]}]}
{"op":"mcm","clk":"4230475279","pt":1631533431286,"mc":[{"id":"1.187557146","rc":[{"batb":[[0,1.6,45.04],[1,1.55,48.19],[2,1.52,59.33]],"batl":[[1,1.84,34.28],[2,1.88,34.29]],"ltp":1.72,"tv":4297.81,"id":19931652},{"batb":[[1,2.18,6.97],[2,2.12,7.29]],"batl":[[0,2.68,5.39],[1,2.82,4.75],[2,3.45,185.61]],"ltp":2.66,"tv":19893.45,"id":8257797}]}]}
{"op":"mcm","clk":"4230475362","pt":1631533432063,"mc":[{"id":"1.187557146","rc":[{"batb":[[0,1.55,48.19],[1,1.52,59.33],[2,1.3,3.62]],"batl":[[0,1.72,18.73],[1,1.88,34.29],[2,990,0.01]],"ltp":1.72,"tv":4297.81,"id":19931652},{"batb":[[1,2.12,7.29],[2,2.04,436.22]],"batl":[[0,2.82,4.75],[1,3.45,185.61],[2,990,0.01]],"ltp":2.66,"tv":19893.45,"id":8257797}]}]}
{"op":"mcm","clk":"4230475650","pt":1631533435195,"mc":[{"id":"1.187557146","rc":[{"batl":[[0,1.72,14.6]],"ltp":1.72,"tv":4297.81,"id":19931652}]}]}
{"op":"mcm","clk":"4230475753","pt":1631533436187,"mc":[{"id":"1.187557146","rc":[{"trd":[[1.72,35.63]],"batl":[[0,1.88,34.29],[1,990,0.01],[2,990,0]],"ltp":1.72,"tv":4312.41,"id":19931652},{"trd":[[2.38,10.55],[2.4,9.01]],"batb":[[0,2.12,7.29],[1,2.04,41.17],[2,1.21,766.7]],"batl":[[0,2.82,4.99],[1,990,0.01],[2,990,0]],"ltp":2.38,"tv":19912.4,"id":8257797}],"tv":24224.82}]}
{"op":"mcm","clk":"4230475856","pt":1631533437285,"mc":[{"id":"1.187557146","rc":[{"batb":[[0,1.81,110.5],[1,1.76,109.5],[2,1.55,48.19]],"batl":[[0,1.86,9.45],[1,1.88,34.29],[2,1.89,145.51]],"ltp":1.72,"tv":4312.41,"id":19931652},{"batl":[[0,2.24,14.65],[1,2.28,1330.86],[2,2.4,6.22]],"ltp":2.38,"tv":19912.4,"id":8257797}]}]}
{"op":"mcm","clk":"4230475948","pt":1631533438273,"mc":[{"id":"1.187557146","rc":[{"batb":[[0,1.84,30.34],[1,1.82,15.33],[2,1.81,22.1]],"ltp":1.72,"tv":4312.41,"id":19931652},{"batb":[[2,1.95,47.95]],"batl":[[1,2.82,4.99],[2,990,0.01]],"ltp":2.38,"tv":19912.4,"id":8257797}]}]}
{"op":"mcm","clk":"4230476037","pt":1631533439198,"mc":[{"id":"1.187557146","rc":[{"trd":[[1.84,2.39]],"batb":[[0,1.84,27.94]],"ltp":1.84,"tv":4314.8,"id":19931652},{"trd":[[2.2,2]],"ltp":2.2,"tv":19914.4,"id":8257797}],"tv":24229.21}]}
{"op":"mcm","clk":"4230476112","pt":1631533440192,"mc":[{"id":"1.187557146","rc":[{"batl":[[1,2.4,2.24],[2,2.82,4.75]],"ltp":2.2,"tv":19914.4,"id":8257797}]}]}
{"op":"mcm","clk":"4230476139","pt":1631533440460,"mc":[{"id":"1.187557146","rc":[{"batl":[[1,2.4,4.24]],"ltp":2.2,"tv":19914.4,"id":8257797}]}]}
{"op":"mcm","clk":"4230476447","pt":1631533444169,"mc":[{"id":"1.187557146","rc":[{"batb":[[1,2.1,7.44],[2,2.08,7.06]],"batl":[[1,2.34,5.99],[2,2.4,7.69]],"ltp":2.2,"tv":19914.4,"id":8257797}]}]}
{"op":"mcm","clk":"4230476649","pt":1631533446299,"mc":[{"id":"1.187557146","rc":[{"batb":[[0,2.14,23.84],[1,2.12,7.29],[2,2.1,7.44]],"batl":[[2,2.4,5.69]],"ltp":2.2,"tv":19914.4,"id":8257797}]}]}
{"op":"mcm","clk":"4230477013","pt":1631533449998,"mc":[{"id":"1.187557146","rc":[{"trd":[[1.84,4.75]],"batb":[[0,1.84,26.76]],"ltp":1.84,"tv":4317.16,"id":19931652},{"batb":[[0,2.12,7.29],[1,2.1,7.44],[2,2.08,7.06]],"ltp":2.2,"tv":19914.4,"id":8257797}],"tv":24231.57}]}
{"op":"mcm","clk":"4230477227","pt":1631533452185,"mc":[{"id":"1.187557146","rc":[{"trd":[[1.84,12]],"batb":[[0,1.75,33.99],[1,1.72,34.09],[2,1.68,41.67]],"batl":[[0,1.92,34.31],[1,990,0.01],[2,1.89,0]],"ltp":1.84,"tv":4324.41,"id":19931652},{"batb":[[0,2.08,7.06],[1,1.95,47.95],[2,1.82,401.7]],"batl":[[0,2.34,5.99],[1,2.4,5.69],[2,2.82,4.75]],"ltp":2.2,"tv":19914.4,"id":8257797}],"tv":24238.82}]}
{"op":"mcm","clk":"4230477246","pt":1631533452390,"mc":[{"id":"1.187557146","rc":[{"batb":[[0,1.72,34.09],[1,1.68,41.67],[2,1.25,20]],"ltp":1.84,"tv":4324.41,"id":19931652},{"batl":[[0,2.4,5.93],[1,3.15,206.16],[2,990,0.01]],"ltp":2.2,"tv":19914.4,"id":8257797}]}]}
{"op":"mcm","clk":"4230477393","pt":1631533454001,"mc":[{"id":"1.187557146","rc":[{"batl":[[0,1.84,4.13],[1,1.92,34.31],[2,990,0.01]],"ltp":1.84,"tv":4324.41,"id":19931652}]}]}
{"op":"mcm","clk":"4230477519","pt":1631533455308,"mc":[{"id":"1.187557146","rc":[{"batl":[[1,1.9,34.95],[2,1.92,34.31]],"ltp":1.84,"tv":4324.41,"id":19931652},{"batb":[[0,2.1,8.64],[1,2.08,7.06],[2,1.95,47.95]],"ltp":2.2,"tv":19914.4,"id":8257797}]}]}
{"op":"mcm","clk":"4230477595","pt":1631533456096,"mc":[{"id":"1.187557146","rc":[{"batb":[[2,1.54,5.03]],"batl":[[1,1.92,34.31],[2,990,0.01]],"ltp":1.84,"tv":4324.41,"id":19931652},{"batb":[[0,2.08,7.06],[1,1.95,47.95],[2,1.82,401.7]],"ltp":2.2,"tv":19914.4,"id":8257797}]}]}
{"op":"mcm","clk":"4230477718","pt":1631533457303,"mc":[{"id":"1.187557146","rc":[{"batl":[[0,1.89,270.53]],"ltp":1.84,"tv":4324.41,"id":19931652}]}]}
{"op":"mcm","clk":"4230477803","pt":1631533458130,"mc":[{"id":"1.187557146","rc":[{"batl":[[0,1.92,34.31],[1,990,0.01],[2,990,0]],"ltp":1.84,"tv":4324.41,"id":19931652}]}]}
{"op":"mcm","clk":"4230478243","pt":1631533462266,"mc":[{"id":"1.187557146","rc":[{"batb":[[2,1.67,9.29]],"batl":[[0,1.9,32.45],[1,1.92,34.31],[2,990,0.01]],"ltp":1.84,"tv":4324.41,"id":19931652},{"batb":[[0,2.1,7.44],[1,2.08,7.06],[2,1.95,47.95]],"ltp":2.2,"tv":19914.4,"id":8257797}]}]}
{"op":"mcm","clk":"4230478304","pt":1631533462939,"mc":[{"id":"1.187557146","rc":[{"batb":[[0,1.75,30.43],[1,1.72,34.09],[2,1.68,41.67]],"batl":[[0,1.92,34.31],[1,990,0.01],[2,990,0]],"ltp":1.84,"tv":4324.41,"id":19931652},{"batb":[[0,2.08,7.06],[1,1.95,47.95],[2,1.82,401.7]],"batl":[[0,2.34,6.99],[1,2.4,5.69],[2,3.15,206.16]],"ltp":2.2,"tv":19914.4,"id":8257797}]}]}
{"op":"mcm","clk":"4230478406","pt":1631533464038,"mc":[{"id":"1.187557146","rc":[{"batb":[[0,1.72,34.09],[1,1.68,41.67],[2,1.67,9.29]],"ltp":1.84,"tv":4324.41,"id":19931652},{"batl":[[0,2.4,5.93],[1,3.15,206.16],[2,990,0.01]],"ltp":2.2,"tv":19914.4,"id":8257797}]}]}
{"op":"mcm","clk":"4230479419","pt":1631533474936,"mc":[{"id":"1.187557146","rc":[{"trd":[[1.72,43.27],[1.75,46.04]],"batb":[[0,1.72,30.27]],"ltp":1.72,"tv":4332.37,"id":19931652},{"trd":[[2.32,0.24]],"batl":[[0,2.4,5.69]],"ltp":2.32,"tv":19914.64,"id":8257797}],"tv":24247.01}]}
{"op":"mcm","clk":"4230479608","pt":1631533477236,"mc":[{"id":"1.187557146","rc":[{"batl":[[0,1.9,31.85],[1,1.92,34.31],[2,990,0.01]],"ltp":1.72,"tv":4332.37,"id":19931652},{"batb":[[0,2.1,7.24],[1,2.08,7.06],[2,1.95,47.95]],"ltp":2.32,"tv":19914.64,"id":8257797}]}]}
{"op":"mcm","clk":"4230479694","pt":1631533478261,"mc":[{"id":"1.187557146","rc":[{"batl":[[0,1.92,34.31],[1,990,0.01],[2,990,0]],"ltp":1.72,"tv":4332.37,"id":19931652},{"batb":[[0,2.08,7.06],[1,1.95,47.95],[2,1.82,401.7]],"ltp":2.32,"tv":19914.64,"id":8257797}]}]}
{"op":"mcm","clk":"4230479848","pt":1631533479868,"mc":[{"id":"1.187557146","rc":[{"batb":[[0,1.74,32.08],[1,1.72,62.82],[2,1.68,146.19]],"batl":[[0,1.76,8.29],[1,1.78,169.3],[2,1.8,22.22]],"ltp":1.72,"tv":4332.37,"id":19931652},{"batb":[[0,2.28,10.66],[1,2.08,7.06],[2,1.95,47.95]],"ltp":2.32,"tv":19914.64,"id":8257797}]}]}
{"op":"mcm","clk":"4230479936","pt":1631533480853,"mc":[{"id":"1.187557146","rc":[{"batb":[[1,2.22,32.89],[2,2.08,7.06]],"ltp":2.32,"tv":19914.64,"id":8257797}]}]}
{"op":"mcm","clk":"4230480582","pt":1631533487171,"mc":[{"id":"1.187557146","rc":[{"batb":[[2,2.12,7.29]],"batl":[[1,2.7,5.15],[2,2.86,4.75]],"ltp":2.32,"tv":19914.64,"id":8257797}]}]}
{"op":"mcm","clk":"4230481178","pt":1631533492592,"mc":[{"id":"1.187557146","rc":[{"trd":[[1.76,42.42]],"batl":[[0,1.76,4.03]],"ltp":1.76,"tv":4340.89,"id":19931652}],"tv":24255.53}]}
{"op":"mcm","clk":"4230482244","pt":1631533503083,"mc":[{"id":"1.187557146","rc":[{"batb":[[1,1.72,16.22],[2,1.68,41.67]],"batl":[[0,1.94,31.25],[1,1.99,28.05],[2,2.02,13.82]],"ltp":1.76,"tv":4340.89,"id":19931652},{"batb":[[0,2.22,32.89],[1,2.06,7.58],[2,2,43.93]],"batl":[[0,2.86,4.75],[1,3.15,206.16],[2,990,0.01]],"ltp":2.32,"tv":19914.64,"id":8257797}]}]}
{"op":"mcm","clk":"4230482271","pt":1631533503395,"mc":[{"id":"1.187557146","rc":[{"batb":[[0,1.67,9.29],[1,1.54,52.65],[2,1.52,60.25]],"batl":[[1,990,0.01],[2,2.02,0]],"ltp":1.76,"tv":4340.89,"id":19931652},{"batb":[[0,2.06,7.58],[1,2,43.93],[2,1.92,395.58]],"ltp":2.32,"tv":19914.64,"id":8257797}]}]}
{"op":"mcm","clk":"4230482566","pt":1631533506284,"mc":[{"id":"1.187557146","rc":[{"batb":[[1,1.59,39.11],[2,1.54,52.65]],"batl":[[0,1.89,35.5],[1,1.94,31.25],[2,990,0.01]],"ltp":1.76,"tv":4340.89,"id":19931652},{"batb":[[0,2.12,7.29],[1,2.06,7.58],[2,2,43.93]],"batl":[[0,2.7,5.65],[1,2.86,4.75],[2,3.15,206.16]],"ltp":2.32,"tv":19914.64,"id":8257797}]}]}
{"op":"mcm","clk":"4230482585","pt":1631533506487,"mc":[{"id":"1.187557146","rc":[{"batb":[[1,1.54,52.65],[2,1.52,60.25]],"batl":[[0,1.94,31.25],[1,990,0.01],[2,990,0]],"ltp":1.76,"tv":4340.89,"id":19931652},{"batb":[[0,2.06,7.58],[1,2,43.93],[2,1.92,395.58]],"batl":[[0,2.86,4.75],[1,3.15,206.16],[2,6,3]],"ltp":2.32,"tv":19914.64,"id":8257797}]}]}
{"op":"mcm","clk":"4230483226","pt":1631533513208,"mc":[{"id":"1.187557146","rc":[{"batb":[[1,1.59,48.11],[2,1.54,52.65]],"batl":[[0,1.89,35.5],[1,1.94,31.25],[2,990,0.01]],"ltp":1.76,"tv":4340.89,"id":19931652},{"batb":[[0,2.12,6.79],[1,2.06,7.58],[2,2,43.93]],"batl":[[0,2.7,4.35],[1,2.86,4.75],[2,3.15,206.16]],"ltp":2.32,"tv":19914.64,"id":8257797}]}]}
{"op":"mcm","clk":"4230483296","pt":1631533514130,"mc":[{"id":"1.187557146","rc":[{"batb":[[1,1.54,52.65],[2,1.52,60.25]],"batl":[[0,1.94,31.25],[1,990,0.01],[2,990,0]],"ltp":1.76,"tv":4340.89,"id":19931652},{"batb":[[0,2.06,7.58],[1,2,43.93],[2,1.92,395.58]],"batl":[[0,2.86,4.75],[1,3.15,206.16],[2,990,0.01]],"ltp":2.32,"tv":19914.64,"id":8257797}]}]}
{"op":"mcm","clk":"4230483403","pt":1631533515324,"mc":[{"id":"1.187557146","rc":[{"batb":[[2,1.65,0.09]],"batl":[[1,990,0.01],[2,990,0]],"ltp":2.32,"tv":19914.64,"id":8257797}]}]}
{"op":"mcm","clk":"4230483487","pt":1631533516224,"mc":[{"id":"1.187557146","rc":[{"batb":[[0,1.89,29.53],[1,1.87,14.92],[2,1.72,115.58]],"batl":[[0,1.92,125.31],[1,1.94,31.25],[2,990,0.01]],"ltp":1.76,"tv":4340.89,"id":19931652},{"batb":[[2,1.84,30.34]],"batl":[[0,2.16,10.61],[1,2.26,17.7],[2,2.86,4.75]],"ltp":2.32,"tv":19914.64,"id":8257797}]}]}
{"op":"mcm","clk":"4230483571","pt":1631533517125,"mc":[{"id":"1.187557146","rc":[{"batb":[[2,1.82,31.88]],"batl":[[2,6,3]],"ltp":1.76,"tv":4340.89,"id":19931652}]}]}
{"op":"mcm","clk":"4230484128","pt":1631533522732,"mc":[{"id":"1.187557146","rc":[{"batl":[[2,2.2,6.58]],"ltp":1.76,"tv":4340.89,"id":19931652},{"batb":[[2,1.84,61.06]],"batl":[[2,2.32,6.61]],"ltp":2.32,"tv":19914.64,"id":8257797}]}]}
{"op":"mcm","clk":"4230484603","pt":1631533527949,"mc":[{"id":"1.187557146","rc":[{"trd":[[1.89,13.34]],"batb":[[0,1.89,29.26]],"ltp":1.89,"tv":4341.43,"id":19931652}],"tv":24256.07}]}
{"op":"mcm","clk":"4230485887","pt":1631533541345,"mc":[{"id":"1.187557146","rc":[{"batb":[[0,1.76,32.48],[1,1.71,34.19],[2,1.69,40.84]],"batl":[[0,2.2,6.58],[1,2.3,6.95],[2,6,3]],"ltp":1.89,"tv":4341.43,"id":19931652},{"batb":[[0,1.84,30.72],[1,1.78,31.97],[2,1.77,436.98]],"batl":[[0,2.32,6.61],[1,2.42,6.25],[2,2.86,4.75]],"ltp":2.32,"tv":19914.64,"id":8257797}]}]}
{"op":"mcm","clk":"4230485923","pt":1631533541651,"mc":[{"id":"1.187557146","rc":[{"batb":[[0,1.71,34.19],[1,1.69,40.84],[2,1.67,9.29]],"batl":[[0,2.3,6.95],[1,6,3],[2,6.4,3]],"ltp":1.89,"tv":4341.43,"id":19931652},{"batb":[[0,1.78,31.97],[1,1.77,436.98],[2,1.2,100.09]],"batl":[[0,2.42,6.25],[1,3,219.52],[2,990,0.01]],"ltp":2.32,"tv":19914.64,"id":8257797}]}]}
{"op":"mcm","clk":"4230486889","pt":1631533551292,"mc":[{"id":"1.187557146","rc":[{"batl":[[1,990,0.01],[2,6.4,0]],"ltp":1.89,"tv":4341.43,"id":19931652},{"batb":[[2,1.65,0.09]],"ltp":2.32,"tv":19914.64,"id":8257797}]}]}
{"op":"mcm","clk":"4230486994","pt":1631533552286,"mc":[{"id":"1.187557146","rc":[{"batb":[[1,1.77,34.37]],"batl":[[1,990,0.01],[2,990,0]],"ltp":2.32,"tv":19914.64,"id":8257797}]}]}
{"op":"mcm","clk":"4230487101","pt":1631533553274,"mc":[{"id":"1.187557146","rc":[{"batb":[[0,1.74,8.95],[1,1.71,34.19],[2,1.69,40.84]],"batl":[[0,1.78,128.18],[1,1.79,42.5],[2,2.3,6.95]],"ltp":1.89,"tv":4341.43,"id":19931652},{"batb":[[0,2.26,11.48],[1,2.18,91.74],[2,1.78,31.97]],"batl":[[1,2.5,83.22],[2,990,0.01]],"ltp":2.32,"tv":19914.64,"id":8257797}]}]}
{"op":"mcm","clk":"4230487206","pt":1631533554270,"mc":[{"id":"1.187557146","rc":[{"batb":[[0,1.75,31.89],[1,1.74,8.95],[2,1.73,16.13]],"batl":[[1,2,27.91],[2,2.04,13.68]],"ltp":1.89,"tv":4341.43,"id":19931652},{"batb":[[0,2.2,33.64],[1,2.18,18.34],[2,1.96,47.36]],"ltp":2.32,"tv":19914.64,"id":8257797}]}]}
{"op":"mcm","clk":"4230487440","pt":1631533556566,"mc":[{"id":"1.187557146","rc":[{"batl":[[2,3.45,185.61]],"ltp":2.32,"tv":19914.64,"id":8257797}]}]}
{"op":"mcm","clk":"4230487748","pt":1631533559176,"mc":[{"id":"1.187557146","rc":[{"trd":[[1.78,178.84]],"batl":[[0,1.78,123.51]],"ltp":1.78,"tv":4346.1,"id":19931652},{"trd":[[2.28,3.65]],"ltp":2.28,"tv":19918.29,"id":8257797}],"tv":24264.39}]}
{"op":"mcm","clk":"4230487877","pt":1631533560283,"mc":[{"id":"1.187557146","rc":[{"batl":[[1,1.92,35.56],[2,1.97,31.5]],"ltp":1.78,"tv":4346.1,"id":19931652},{"batb":[[2,2.08,8.31]],"batl":[[1,2.48,4.99],[2,2.5,83.22]],"ltp":2.28,"tv":19918.29,"id":8257797}]}]}
{"op":"mcm","clk":"4230487968","pt":1631533560977,"mc":[{"id":"1.187557146","rc":[{"batb":[[0,1.67,9.29],[1,1.65,36.93],[2,1.6,49.96]],"batl":[[0,1.97,31.5],[1,2.3,6.95],[2,990,0.01]],"ltp":1.78,"tv":4346.1,"id":19931652},{"batb":[[0,1.96,47.36],[1,1.92,395.58],[2,1.77,34.37]],"batl":[[0,2.54,6.38],[1,3.45,185.61],[2,990,0.01]],"ltp":2.28,"tv":19918.29,"id":8257797}]}]}
{"op":"mcm","clk":"4230488194","pt":1631533563283,"mc":[{"id":"1.187557146","rc":[{"batl":[[0,2.28,8.52],[1,2.54,6.38],[2,3.45,185.61]],"ltp":2.28,"tv":19918.29,"id":8257797}]}]}
{"op":"mcm","clk":"4230488298","pt":1631533564204,"mc":[{"id":"1.187557146","rc":[{"batb":[[0,1.68,36.61],[1,1.67,9.29],[2,1.65,36.93]],"batl":[[0,1.92,30.06],[1,1.97,31.5],[2,2.3,6.95]],"ltp":1.78,"tv":4346.1,"id":19931652},{"batb":[[0,2.08,7.81],[1,2.02,9.74],[2,1.96,47.36]],"batl":[[1,2.48,6.49],[2,2.54,6.38]],"ltp":2.28,"tv":19918.29,"id":8257797}]}]}
{"op":"mcm","clk":"4230488323","pt":1631533564413,"mc":[{"id":"1.187557146","rc":[{"batb":[[0,1.67,9.29],[1,1.65,36.93],[2,1.6,49.96]],"batl":[[0,1.97,31.5],[1,2.3,6.95],[2,990,0.01]],"ltp":1.78,"tv":4346.1,"id":19931652},{"batb":[[0,2.02,9.74],[1,1.96,47.36],[2,1.92,395.58]],"batl":[[1,2.54,6.38],[2,3.45,185.61]],"ltp":2.28,"tv":19918.29,"id":8257797}]}]}
{"op":"mcm","clk":"4230488864","pt":1631533569306,"mc":[{"id":"1.187557146","rc":[{"trd":[[1.78,189.75]],"batl":[[0,1.68,121.58],[1,1.7,106.73],[2,1.73,1769.28]],"ltp":1.78,"tv":4357.01,"id":19931652},{"trd":[[2.28,12.16]],"batl":[[0,2.54,6.38],[1,2.56,9.71],[2,2.72,86.86]],"ltp":2.28,"tv":19926.81,"id":8257797}],"tv":24283.82}]}
{"op":"mcm","clk":"4230488937","pt":1631533569803,"mc":[{"id":"1.187557146","rc":[{"batb":[[1,1.65,70.76],[2,1.63,17.12]],"batl":[[1,1.7,23.52],[2,1.88,29.69]],"ltp":1.78,"tv":4357.01,"id":19931652}]}]}
{"op":"mcm","clk":"4230489070","pt":1631533570804,"mc":[{"id":"1.187557146","rc":[{"batb":[[0,2.38,26.78],[1,2.16,34.73],[2,2.02,9.74]],"ltp":2.28,"tv":19926.81,"id":8257797}]}]}
{"op":"mcm","clk":"4230489682","pt":1631533576001,"mc":[{"id":"1.187557146","rc":[{"batb":[[2,1.63,53.35]],"batl":[[2,1.77,39.5]],"ltp":1.78,"tv":4357.01,"id":19931652},{"batb":[[1,2.28,7.41],[2,2.24,6.77]],"batl":[[2,2.6,5.31]],"ltp":2.28,"tv":19926.81,"id":8257797}]}]}
{"op":"mcm","clk":"4230490444","pt":1631533583104,"mc":[{"id":"1.187557146","rc":[{"batb":[[1,1.63,36.23],[2,1.61,44.09]],"batl":[[0,1.8,36.12],[1,2.3,6.95],[2,990,0.01]],"ltp":1.78,"tv":4357.01,"id":19931652},{"batb":[[0,2.24,6.77],[1,2.16,34.73],[2,1.92,395.58]],"batl":[[0,2.6,5.31],[1,2.64,5.18],[2,3.45,185.61]],"ltp":2.28,"tv":19926.81,"id":8257797}]}]}
{"op":"mcm","clk":"4230490760","pt":1631533586309,"mc":[{"id":"1.187557146","rc":[{"batl":[[0,1.77,36.5],[1,1.8,36.12],[2,2.3,6.95]],"ltp":1.78,"tv":4357.01,"id":19931652}]}]}
{"op":"mcm","clk":"4230490813","pt":1631533586817,"mc":[{"id":"1.187557146","rc":[{"trd":[[1.67,101.73]],"batb":[[0,1.67,9.1]],"batl":[[0,1.8,36.12],[1,2.3,6.95],[2,990,0.01]],"ltp":1.67,"tv":4357.39,"id":19931652}],"tv":24284.2}]}
{"op":"mcm","clk":"4230491368","pt":1631533593262,"mc":[{"id":"1.187557146","rc":[{"trd":[[1.67,119.93]],"batb":[[0,1.61,44.09],[1,1.54,62.61],[2,1.25,20]],"batl":[[0,1.67,59.8],[1,1.77,37.5],[2,1.8,36.12]],"ltp":1.67,"tv":4375.59,"id":19931652},{"batb":[[0,2.28,6.41],[1,2.24,6.77],[2,2.16,34.73]],"batl":[[0,2.64,5.18],[1,3.45,185.61],[2,6,3]],"ltp":2.28,"tv":19926.81,"id":8257797}],"tv":24302.4}]}
{"op":"mcm","clk":"4230491390","pt":1631533593524,"mc":[{"id":"1.187557146","rc":[{"batl":[[1,1.8,36.12],[2,2.3,6.95]],"ltp":1.67,"tv":4375.59,"id":19931652},{"batb":[[0,2.24,6.77],[1,2.16,34.73],[2,1.92,395.58]],"ltp":2.28,"tv":19926.81,"id":8257797}]}]}
{"op":"mcm","clk":"4230491474","pt":1631533594461,"mc":[{"id":"1.187557146","rc":[{"batl":[[0,1.8,36.12],[1,2.3,6.95],[2,990,0.01]],"ltp":1.67,"tv":4375.59,"id":19931652}]}]}
{"op":"mcm","clk":"4230492018","pt":1631533600255,"mc":[{"id":"1.187557146","rc":[{"batl":[[0,1.77,36.5],[1,1.8,36.12],[2,2.3,6.95]],"ltp":1.67,"tv":4375.59,"id":19931652},{"batb":[[0,2.28,6.16],[1,2.24,6.77],[2,2.16,34.73]],"ltp":2.28,"tv":19926.81,"id":8257797}]}]}
{"op":"mcm","clk":"4230492051","pt":1631533600670,"mc":[{"id":"1.187557146","rc":[{"batl":[[0,1.8,36.12],[1,2.3,6.95],[2,990,0.01]],"ltp":1.67,"tv":4375.59,"id":19931652},{"batb":[[0,2.24,6.77],[1,2.16,34.73],[2,1.92,395.58]],"ltp":2.28,"tv":19926.81,"id":8257797}]}]}
{"op":"mcm","clk":"4230492268","pt":1631533603167,"mc":[{"id":"1.187557146","rc":[{"batb":[[1,1.54,57.57]],"ltp":1.67,"tv":4375.59,"id":19931652}]}]}
{"op":"mcm","clk":"4230492647","pt":1631533607272,"mc":[{"id":"1.187557146","rc":[{"batl":[[2,990,0.01]],"ltp":2.28,"tv":19926.81,"id":8257797}]}]}
{"op":"mcm","clk":"4230492702","pt":1631533607780,"mc":[{"id":"1.187557146","rc":[{"batl":[[1,990,0.01],[2,990,0]],"ltp":2.28,"tv":19926.81,"id":8257797}]}]}
{"op":"mcm","clk":"4230492817","pt":1631533609086,"mc":[{"id":"1.187557146","rc":[{"batb":[[0,1.76,22.72],[1,1.75,31.89],[2,1.74,9.96]],"batl":[[0,1.78,122.58],[1,1.8,36.12],[2,2.3,6.95]],"ltp":1.67,"tv":4375.59,"id":19931652},{"batb":[[2,1.99,28.05]],"ltp":2.28,"tv":19926.81,"id":8257797}]}]}
{"op":"mcm","clk":"4230493042","pt":1631533611590,"mc":[{"id":"1.187557146","rc":[{"batl":[[1,3.3,197.44],[2,990,0.01]],"ltp":2.28,"tv":19926.81,"id":8257797}]}]}
{"op":"mcm","clk":"4230493424","pt":1631533615293,"mc":[{"id":"1.187557146","rc":[{"batl":[[2,1.96,32.62]],"ltp":1.67,"tv":4375.59,"id":19931652},{"batb":[[2,2.04,7.87]],"batl":[[0,2.52,6.26],[1,2.62,5.46],[2,2.64,5.18]],"ltp":2.28,"tv":19926.81,"id":8257797}]}]}
{"op":"mcm","clk":"4230494004","pt":1631533621282,"mc":[{"id":"1.187557146","rc":[{"batb":[[0,1.62,38.13],[1,1.59,50.54],[2,1.25,20]],"batl":[[0,2.02,8.25],[1,2.3,6.95],[2,990,0.01]],"ltp":1.67,"tv":4375.59,"id":19931652},{"batb":[[0,1.99,30.51],[1,1.92,395.58],[2,1.91,51.05]],"batl":[[0,2.62,5.46],[1,3.3,197.44],[2,990,0.01]],"ltp":2.28,"tv":19926.81,"id":8257797}]}]}
{"op":"mcm","clk":"4230494299","pt":1631533624312,"mc":[{"id":"1.187557146","rc":[{"batb":[[0,1.66,35.78],[1,1.62,38.13],[2,1.59,50.54]],"batl":[[0,1.96,32.12],[1,2.02,8.25],[2,2.3,6.95]],"ltp":1.67,"tv":4375.59,"id":19931652},{"batb":[[0,2.04,8.62],[1,1.99,30.51],[2,1.92,395.58]],"batl":[[0,2.52,5.01],[1,2.62,5.46],[2,3.3,197.44]],"ltp":2.28,"tv":19926.81,"id":8257797}]}]}
{"op":"mcm","clk":"4230494333","pt":1631533624584,"mc":[{"id":"1.187557146","rc":[{"batb":[[0,1.62,38.13],[1,1.59,50.54],[2,1.25,20]],"batl":[[0,2.02,8.25],[1,2.3,6.95],[2,990,0.01]],"ltp":1.67,"tv":4375.59,"id":19931652},{"batb":[[0,1.99,30.51],[1,1.92,395.58],[2,1.91,51.05]],"batl":[[0,2.62,5.46],[1,3.3,197.44],[2,990,0.01]],"ltp":2.28,"tv":19926.81,"id":8257797}]}]}
{"op":"mcm","clk":"4230494563","pt":1631533627223,"mc":[{"id":"1.187557146","rc":[{"batb":[[0,1.77,19.37],[1,1.62,38.13],[2,1.59,50.54]],"batl":[[0,1.82,18.75],[1,2.02,8.25],[2,2.3,6.95]],"ltp":1.67,"tv":4375.59,"id":19931652},{"batl":[[0,2.3,21.75],[1,2.62,5.46],[2,3.3,197.44]],"ltp":2.28,"tv":19926.81,"id":8257797}]}]}
{"op":"mcm","clk":"4230494653","pt":1631533628011,"mc":[{"id":"1.187557146","rc":[{"batb":[[0,1.62,38.13],[1,1.59,50.54],[2,1.25,20]],"batl":[[0,2.02,8.25],[1,2.3,6.95],[2,990,0.01]],"ltp":1.67,"tv":4375.59,"id":19931652},{"batl":[[0,2.62,5.46],[1,3.3,197.44],[2,990,0.01]],"ltp":2.28,"tv":19926.81,"id":8257797}]}]}
{"op":"mcm","clk":"4230494953","pt":1631533631196,"mc":[{"id":"1.187557146","rc":[{"batb":[[0,1.66,35.28],[1,1.62,38.13],[2,1.59,50.54]],"batl":[[0,1.96,32.12],[1,2.02,8.25],[2,2.3,6.95]],"ltp":1.67,"tv":4375.59,"id":19931652},{"batb":[[0,2.04,8.37],[1,1.99,30.51],[2,1.92,395.58]],"batl":[[0,2.52,5.51],[1,2.62,5.46],[2,3.3,197.44]],"ltp":2.28,"tv":19926.81,"id":8257797}]}]}
{"op":"mcm","clk":"4230494978","pt":1631533631507,"mc":[{"id":"1.187557146","rc":[{"batb":[[0,1.62,38.13],[1,1.59,50.54],[2,1.25,20]],"batl":[[0,2.02,8.25],[1,2.3,6.95],[2,990,0.01]],"ltp":1.67,"tv":4375.59,"id":19931652},{"batb":[[0,1.99,30.51],[1,1.92,395.58],[2,1.91,51.05]],"batl":[[0,2.62,5.46],[1,3.3,197.44],[2,990,0.01]],"ltp":2.28,"tv":19926.81,"id":8257797}]}]}
{"op":"mcm","clk":"4230495541","pt":1631533638330,"mc":[{"id":"1.187557146","rc":[{"batb":[[0,1.66,35.78],[1,1.62,38.13],[2,1.59,50.54]],"batl":[[0,1.96,33.37],[1,2.02,8.25],[2,2.3,6.95]],"ltp":1.67,"tv":4375.59,"id":19931652},{"batb":[[0,2.04,7.62],[1,1.99,30.51]],"batl":[[0,2.52,5.51],[1,2.62,5.46]],"ltp":2.28,"tv":19926.81,"id":8257797}]}]}
{"op":"mcm","clk":"4230495652","pt":1631533639325,"mc":[{"id":"1.187557146","rc":[{"batb":[[0,1.62,38.13],[1,1.59,50.54],[2,1.25,20]],"batl":[[0,1.66,9.53],[1,1.7,1803.48],[2,1.72,116.28]],"ltp":1.67,"tv":4375.59,"id":19931652},{"batb":[[0,2.5,73.46]],"batl":[[0,2.6,10.59],[2,2.72,71.15]],"ltp":2.28,"tv":19926.81,"id":8257797}]}]}
{"op":"mcm","clk":"4230495737","pt":1631533640313,"mc":[{"id":"1.187557146","rc":[{"batb":[[0,1.64,34.12],[1,1.62,55.27],[2,1.59,50.54]],"batl":[[1,1.68,44.64],[2,1.72,23.26]],"ltp":1.67,"tv":4375.59,"id":19931652},{"batb":[[1,2.46,10.38],[2,2.38,26.44]],"ltp":2.28,"tv":19926.81,"id":8257797}]}]}
{"op":"mcm","clk":"4230496294","pt":1631533646409,"mc":[{"id":"1.187557146","rc":[{"batb":[[2,1.61,36.09]],"ltp":1.67,"tv":4375.59,"id":19931652},{"batl":[[2,2.64,5.68]],"ltp":2.28,"tv":19926.81,"id":8257797}]}]}
{"op":"mcm","clk":"4230496608","pt":1631533649325,"mc":[{"id":"1.187557146","rc":[{"trd":[[1.64,221.64]],"batb":[[0,1.64,1.05]],"ltp":1.64,"tv":4441.74,"id":19931652}],"tv":24368.55}]}
{"op":"mcm","clk":"4230496971","pt":1631533653028,"mc":[{"id":"1.187557146","rc":[{"batb":[[0,1.59,40.11],[1,1.54,57.49],[2,1.25,20]],"batl":[[0,1.77,36.5],[1,2.02,8.25],[2,990,0.01]],"ltp":1.64,"tv":4441.74,"id":19931652},{"batb":[[0,2.18,34.14],[1,2.04,395.05],[2,1.99,30.51]],"batl":[[0,3.9,162.84],[1,6,3],[2,6.4,3]],"ltp":2.28,"tv":19926.81,"id":8257797}]}]}
{"op":"mcm","clk":"4230497253","pt":1631533656349,"mc":[{"id":"1.187557146","rc":[{"batl":[[1,990,0.01],[2,990,0]],"ltp":1.64,"tv":4441.74,"id":19931652},{"batb":[[0,2.28,6.66],[1,2.18,34.14],[2,2.04,395.05]],"batl":[[0,2.7,4.55],[1,3.9,162.84],[2,6,3]],"ltp":2.28,"tv":19926.81,"id":8257797}]}]}
{"op":"mcm","clk":"4230497504","pt":1631533659259,"mc":[{"id":"1.187557146","rc":[{"batb":[[1,1.54,177.46]],"batl":[[0,1.62,177],[1,1.63,44.5],[2,1.77,36.5]],"ltp":1.64,"tv":4441.74,"id":19931652},{"batb":[[0,2.58,9.56],[1,2.54,78.74],[2,2.28,6.66]],"batl":[[1,2.72,7.37],[2,3.9,162.84]],"ltp":2.28,"tv":19926.81,"id":8257797}]}]}
{"op":"mcm","clk":"4230497603","pt":1631533660357,"mc":[{"id":"1.187557146","rc":[{"batb":[[1,1.57,35.55],[2,1.55,18]],"batl":[[1,1.77,36.5],[2,1.78,31.36]],"ltp":1.64,"tv":4441.74,"id":19931652},{"batb":[[0,2.54,15.74],[1,2.52,22.68],[2,2.28,37.04]],"ltp":2.28,"tv":19926.81,"id":8257797}]}]}
{"op":"mcm","clk":"4230499441","pt":1631533679783,"mc":[{"id":"1.187557146","rc":[{"trd":[[1.59,0.3]],"batb":[[0,1.59,39.96]],"ltp":1.59,"tv":4442.04,"id":19931652}],"tv":24368.85}]}
{"op":"mcm","clk":"4230499704","pt":1631533682593,"mc":[{"id":"1.187557146","rc":[{"trd":[[1.62,401.76]],"batl":[[0,1.62,170.04]],"ltp":1.62,"tv":4449.0,"id":19931652},{"trd":[[2.6,5.7]],"ltp":2.6,"tv":19931.14,"id":8257797}],"tv":24380.15}]}
{"op":"mcm","clk":"4230502012","pt":1631533706051,"mc":[{"id":"1.187557146","rc":[{"trd":[[1.62,401.91]],"batl":[[0,1.62,169.89]],"ltp":1.62,"tv":4449.15,"id":19931652},{"trd":[[2.6,5.79]],"ltp":2.6,"tv":19931.24,"id":8257797}],"tv":24380.39}]}
{"op":"mcm","clk":"4230502417","pt":1631533710623,"mc":[{"id":"1.187557146","rc":[{"trd":[[1.62,406.95]],"batl":[[0,1.62,167.37]],"ltp":1.62,"tv":4454.19,"id":19931652}],"tv":24385.43}]}
{"op":"mcm","clk":"4230504159","pt":1631533728679,"mc":[{"id":"1.187557146","rc":[{"trd":[[1.62,413.77]],"batl":[[0,1.62,163.96]],"ltp":1.62,"tv":4461.0,"id":19931652}],"tv":24392.25}]}
{"op":"mcm","clk":"4230505115","pt":1631533737589,"mc":[{"id":"1.187557146","rc":[{"trd":[[1.62,431.83]],"batl":[[0,1.62,145.9]],"ltp":1.62,"tv":4479.06,"id":19931652},{"trd":[[2.6,17.04]],"ltp":2.6,"tv":19942.49,"id":8257797}],"tv":24421.56}]}
{"op":"mcm","clk":"4230506025","pt":1631533746508,"mc":[{"id":"1.187557146","rc":[{"batb":[[1,1.54,177.46],[2,1.4,83.35]],"batl":[[2,990,0.01]],"ltp":1.62,"tv":4479.06,"id":19931652}]}]}
{"op":"mcm","clk":"4230506332","pt":1631533749330,"mc":[{"id":"1.187557146","rc":[{"batb":[[1,1.54,57.49]],"batl":[[0,1.77,36.5],[1,990,0.01],[2,990,0]],"ltp":1.62,"tv":4479.06,"id":19931652},{"batb":[[0,2.52,22.68],[1,2.28,37.04],[2,2.04,395.05]],"batl":[[1,3.9,162.84],[2,6,3]],"ltp":2.6,"tv":19942.49,"id":8257797}]}]}
{"op":"mcm","clk":"4230506417","pt":1631533750224,"mc":[{"id":"1.187557146","rc":[{"batb":[[0,1.4,83.35],[1,1.39,64.91],[2,1.25,20]],"batl":[[0,1.76,35.52]],"ltp":1.62,"tv":4479.06,"id":19931652},{"batb":[[0,2.3,5.78],[1,2.28,30.38]],"batl":[[0,3.6,3.26]],"ltp":2.6,"tv":19942.49,"id":8257797}]}]}
{"op":"mcm","clk":"4230506682","pt":1631533753218,"mc":[{"id":"1.187557146","rc":[{"batl":[[0,1.72,35.16],[1,1.76,35.52],[2,990,0.01]],"ltp":1.62,"tv":4479.06,"id":19931652},{"batb":[[0,2.38,6.46],[1,2.3,5.78],[2,2.28,30.38]],"ltp":2.6,"tv":19942.49,"id":8257797}]}]}
{"op":"mcm","clk":"4230506721","pt":1631533753632,"mc":[{"id":"1.187557146","rc":[{"batl":[[0,1.76,35.52],[1,990,0.01],[2,990,0]],"ltp":1.62,"tv":4479.06,"id":19931652},{"batb":[[0,2.3,5.78],[1,2.28,30.38],[2,2.04,395.05]],"ltp":2.6,"tv":19942.49,"id":8257797}]}]}
{"op":"mcm","clk":"4230506848","pt":1631533755310,"mc":[{"id":"1.187557146","rc":[{"batl":[[1,6,3],[2,6.4,3]],"ltp":2.6,"tv":19942.49,"id":8257797}]}]}
{"op":"mcm","clk":"4230506881","pt":1631533755730,"mc":[{"id":"1.187557146","rc":[{"batl":[[0,3.6,3.38]],"ltp":2.6,"tv":19942.49,"id":8257797}]}]}
{"op":"mcm","clk":"4230506995","pt":1631533756944,"mc":[{"id":"1.187557146","rc":[{"batb":[[0,1.69,33.03],[1,1.67,16.71],[2,1.65,24.24]],"batl":[[1,1.92,29.07],[2,1.94,14.38]],"ltp":1.62,"tv":4479.06,"id":19931652},{"batb":[[0,2.4,7.96],[1,2.36,102.45],[2,2.3,5.78]],"batl":[[0,2.46,5.72],[1,2.6,98.3],[2,3.6,3.26]],"ltp":2.6,"tv":19942.49,"id":8257797}]}]}
{"op":"mcm","clk":"4230507120","pt":1631533758259,"mc":[{"id":"1.187557146","rc":[{"batb":[[2,1.65,68.93]],"ltp":1.62,"tv":4479.06,"id":19931652},{"batl":[[1,2.6,98.18]],"ltp":2.6,"tv":19942.49,"id":8257797}]}]}
{"op":"mcm","clk":"4230507201","pt":1631533759039,"mc":[{"id":"1.187557146","rc":[{"batl":[[1,2.6,102.18]],"ltp":2.6,"tv":19942.49,"id":8257797}]}]}
{"op":"mcm","clk":"4230507247","pt":1631533759513,"mc":[{"id":"1.187557146","rc":[{"batl":[[2,3.45,185.61]],"ltp":2.6,"tv":19942.49,"id":8257797}]}]}
{"op":"mcm","clk":"4230507593","pt":1631533763337,"mc":[{"id":"1.187557146","rc":[{"batb":[[0,1.51,61.25],[1,1.39,64.91],[2,1.25,20]],"batl":[[0,990,0.01],[1,1.92,0],[2,1.94,0]],"ltp":1.62,"tv":4479.06,"id":19931652},{"batb":[[0,2.1,38.41],[1,2.04,395.05],[2,1.65,0.09]],"batl":[[0,2.6,2],[1,3.45,185.61],[2,3.6,3.26]],"ltp":2.6,"tv":19942.49,"id":8257797}]}]}
{"op":"mcm","clk":"4230507676","pt":1631533764236,"mc":[{"id":"1.187557146","rc":[{"batb":[[0,1.58,43.56],[1,1.54,44.62],[2,1.51,61.25]],"batl":[[0,1.8,38.17],[1,1.84,31.03],[2,990,0.01]],"ltp":1.62,"tv":4479.06,"id":19931652},{"batb":[[0,2.24,6.02],[1,2.18,6.86],[2,2.1,38.41]],"batl":[[1,2.74,4.48],[2,2.86,4.75]],"ltp":2.6,"tv":19942.49,"id":8257797}]}]}
{"op":"mcm","clk":"4230507711","pt":1631533764638,"mc":[{"id":"1.187557146","rc":[{"batb":[[0,1.54,44.62],[1,1.51,61.25],[2,1.39,64.91]],"batl":[[0,1.84,31.03],[1,990,0.01],[2,990,0]],"ltp":1.62,"tv":4479.06,"id":19931652},{"batb":[[0,2.18,6.86],[1,2.1,38.41],[2,2.04,395.05]],"batl":[[0,2.86,4.75],[1,3.45,185.61],[2,3.6,3.26]],"ltp":2.6,"tv":19942.49,"id":8257797}]}]}
{"op":"mcm","clk":"4230507864","pt":1631533766256,"mc":[{"id":"1.187557146","rc":[{"batl":[[0,2.86,4.87]],"ltp":2.6,"tv":19942.49,"id":8257797}]}]}
{"op":"mcm","clk":"4230508104","pt":1631533768653,"mc":[{"id":"1.187557146","rc":[{"batl":[[0,2.86,4.75]],"ltp":2.6,"tv":19942.49,"id":8257797}]}]}
{"op":"mcm","clk":"4230508498","pt":1631533772344,"mc":[{"id":"1.187557146","rc":[{"batb":[[0,1.77,113],[1,1.76,16.29],[2,1.72,102.89]],"batl":[[0,1.83,134.44],[1,1.84,31.03],[2,990,0.01]],"ltp":1.62,"tv":4479.06,"id":19931652},{"batb":[[0,2.24,8.03],[1,2.18,6.86],[2,2.1,38.41]],"batl":[[0,2.34,1294.2],[1,2.86,4.75]],"ltp":2.6,"tv":19942.49,"id":8257797}]}]}
{"op":"mcm","clk":"4230508604","pt":1631533773239,"mc":[{"id":"1.187557146","rc":[{"batb":[[0,1.79,31.18],[1,1.77,38.37],[2,1.76,16.29]],"ltp":1.62,"tv":4479.06,"id":19931652},{"batl":[[0,2.86,4.75],[1,3.6,3.26],[2,990,0.01]],"ltp":2.6,"tv":19942.49,"id":8257797}]}]}
{"op":"mcm","clk":"4230508816","pt":1631533775269,"mc":[{"id":"1.187557146","rc":[{"batl":[[0,2.4,2],[1,2.86,4.75],[2,3.6,3.26]],"ltp":2.6,"tv":19942.49,"id":8257797}]}]}
{"op":"mcm","clk":"4230508896","pt":1631533776055,"mc":[{"id":"1.187557146","rc":[{"batl":[[0,2.4,4],[2,3.15,206.16]],"ltp":2.6,"tv":19942.49,"id":8257797}]}]}
{"op":"mcm","clk":"4230508997","pt":1631533777253,"mc":[{"id":"1.187557146","rc":[{"batl":[[2,2.06,152.91]],"ltp":1.62,"tv":4479.06,"id":19931652}]}]}
{"op":"mcm","clk":"4230509079","pt":1631533778148,"mc":[{"id":"1.187557146","rc":[{"batl":[[2,990,0.01]],"ltp":1.62,"tv":4479.06,"id":19931652},{"batl":[[0,2.4,2]],"ltp":2.6,"tv":19942.49,"id":8257797}]}]}
{"op":"mcm","clk":"4230509136","pt":1631533778877,"mc":[{"id":"1.187557146","rc":[{"batl":[[0,2.86,4.75],[1,3.15,206.16],[2,3.6,3.26]],"ltp":2.6,"tv":19942.49,"id":8257797}]}]}
{"op":"mcm","clk":"4230509255","pt":1631533780048,"mc":[{"id":"1.187557146","rc":[{"batb":[[0,1.71,34.19],[1,1.68,33.11],[2,1.63,45.77]],"batl":[[0,1.88,33.79],[1,990,0.01],[2,990,0]],"ltp":1.62,"tv":4479.06,"id":19931652},{"batb":[[0,2.12,7.29],[1,2,44.85],[2,1.82,401.7]],"batl":[[0,2.42,6.25],[1,2.48,5.99],[2,2.86,4.75]],"ltp":2.6,"tv":19942.49,"id":8257797}]}]}
{"op":"mcm","clk":"4230509359","pt":1631533781164,"mc":[{"id":"1.187557146","rc":[{"batb":[[0,1.68,33.11],[1,1.63,45.77],[2,1.39,64.91]],"ltp":1.62,"tv":4479.06,"id":19931652},{"batl":[[0,2.48,5.99],[1,3.15,206.16],[2,3.6,3.26]],"ltp":2.6,"tv":19942.49,"id":8257797}]}]}
{"op":"mcm","clk":"4230509547","pt":1631533783055,"mc":[{"id":"1.187557146","rc":[{"batl":[[0,1.86,33.25],[1,1.88,33.79],[2,990,0.01]],"ltp":1.62,"tv":4479.06,"id":19931652},{"batb":[[0,2.16,7.28],[1,2.12,7.29],[2,2,44.85]],"ltp":2.6,"tv":19942.49,"id":8257797}]}]}
{"op":"mcm","clk":"4230509580","pt":1631533783371,"mc":[{"id":"1.187557146","rc":[{"batl":[[0,1.88,33.79],[1,990,0.01],[2,990,0]],"ltp":1.62,"tv":4479.06,"id":19931652},{"batb":[[0,2.12,7.29],[1,2,44.85],[2,1.82,401.7]],"ltp":2.6,"tv":19942.49,"id":8257797}]}]}
{"op":"mcm","clk":"4230510845","pt":1631533796100,"mc":[{"id":"1.187557146","rc":[{"batb":[[0,1.71,36.19],[1,1.68,33.11],[2,1.63,45.77]],"ltp":1.62,"tv":4479.06,"id":19931652},{"batl":[[0,2.42,6.25],[1,2.48,5.99],[2,3.15,206.16]],"ltp":2.6,"tv":19942.49,"id":8257797}]}]}
{"op":"mcm","clk":"4230510954","pt":1631533797097,"mc":[{"id":"1.187557146","rc":[{"batb":[[0,1.68,33.11],[1,1.63,45.77],[2,1.39,64.91]],"batl":[[0,1.86,33.25],[1,1.88,33.79],[2,990,0.01]],"ltp":1.62,"tv":4479.06,"id":19931652},{"batb":[[0,2.16,7.78],[1,2.12,7.29],[2,2,44.85]],"batl":[[0,2.48,5.99],[1,3.15,206.16],[2,3.6,3.26]],"ltp":2.6,"tv":19942.49,"id":8257797}]}]}
{"op":"mcm","clk":"4230510982","pt":1631533797408,"mc":[{"id":"1.187557146","rc":[{"batl":[[0,1.88,33.79],[1,990,0.01],[2,990,0]],"ltp":1.62,"tv":4479.06,"id":19931652},{"batb":[[0,2.12,7.29],[1,2,44.85],[2,1.82,401.7]],"ltp":2.6,"tv":19942.49,"id":8257797}]}]}
{"op":"mcm","clk":"4230511216","pt":1631533799298,"mc":[{"id":"1.187557146","rc":[{"batb":[[0,1.76,113.64],[1,1.68,33.11],[2,1.63,45.77]],"batl":[[1,1.89,132.12],[2,990,0.01]],"ltp":1.62,"tv":4479.06,"id":19931652},{"batl":[[0,2.2,8.42],[1,2.26,1342.44],[2,2.28,79.57]],"ltp":2.6,"tv":19942.49,"id":8257797}]}]}
{"op":"mcm","clk":"4230511321","pt":1631533800306,"mc":[{"id":"1.187557146","rc":[{"batb":[[0,1.87,29.85],[1,1.85,15.09],[2,1.83,31.21]],"ltp":1.62,"tv":4479.06,"id":19931652},{"batb":[[2,1.93,49.37]],"batl":[[1,2.28,79.57],[2,2.48,5.99]],"ltp":2.6,"tv":19942.49,"id":8257797}]}]}
{"op":"mcm","clk":"4230511342","pt":1631533800518,"mc":[{"id":"1.187557146","rc":[{"batl":[[2,6,3]],"ltp":1.62,"tv":4479.06,"id":19931652}]}]}
{"op":"mcm","clk":"4230511756","pt":1631533804293,"mc":[{"id":"1.187557146","rc":[{"batl":[[2,2.14,156.73]],"ltp":1.62,"tv":4479.06,"id":19931652}]}]}
{"op":"mcm","clk":"4230511772","pt":1631533804488,"mc":[{"id":"1.187557146","rc":[{"batl":[[2,6,3]],"ltp":1.62,"tv":4479.06,"id":19931652}]}]}
{"op":"mcm","clk":"4230512013","pt":1631533807209,"mc":[{"id":"1.187557146","rc":[{"trd":[[1.87,55.12]],"batb":[[0,1.87,2.29]],"batl":[[0,6,3],[1,6.4,3],[2,6.6,3]],"ltp":1.87,"tv":4534.19,"id":19931652},{"batb":[[0,2,44.85],[1,1.93,49.37],[2,1.86,30.01]],"batl":[[0,2.48,5.99],[1,3,219.52],[2,3.6,3.26]],"ltp":2.6,"tv":19942.49,"id":8257797}],"tv":24476.68}]}
{"op":"mcm","clk":"4230512069","pt":1631533807790,"mc":[{"id":"1.187557146","rc":[{"batb":[[0,1.79,29.31],[1,1.75,36.07],[2,1.39,64.91]],"batl":[[0,1.91,33.5],[1,6,3],[2,6.4,3]],"ltp":1.87,"tv":4534.19,"id":19931652},{"batb":[[0,2.08,8.56],[2,1.82,401.7]],"batl":[[0,2.28,7.34]],"ltp":2.6,"tv":19942.49,"id":8257797}]}]}
{"op":"mcm","clk":"4230512278","pt":1631533810195,"mc":[{"id":"1.187557146","rc":[{"batl":[[1,2.42,16],[2,3,219.52]],"ltp":2.6,"tv":19942.49,"id":8257797}]}]}
{"op":"mcm","clk":"4230512299","pt":1631533810404,"mc":[{"id":"1.187557146","rc":[{"batl":[[1,3,219.52],[2,3.6,3.26]],"ltp":2.6,"tv":19942.49,"id":8257797}]}]}
{"op":"mcm","clk":"4230512458","pt":1631533812109,"mc":[{"id":"1.187557146","rc":[{"batb":[[0,1.81,30.29],[1,1.79,29.31],[2,1.75,36.07]],"batl":[[0,1.9,33.45],[1,1.91,33.5],[2,6,3]],"ltp":1.87,"tv":4534.19,"id":19931652},{"batb":[[0,2.1,6.54],[1,2.08,8.56],[2,1.93,49.37]],"batl":[[0,2.24,6.48],[1,2.28,7.34],[2,3,219.52]],"ltp":2.6,"tv":19942.49,"id":8257797}]}]}
{"op":"mcm","clk":"4230512487","pt":1631533812407,"mc":[{"id":"1.187557146","rc":[{"batb":[[0,1.79,29.31],[1,1.75,36.07],[2,1.39,64.91]],"batl":[[0,1.91,33.5],[1,6,3],[2,6.4,3]],"ltp":1.87,"tv":4534.19,"id":19931652},{"batb":[[0,2.08,8.56],[1,1.93,49.37],[2,1.82,401.7]],"batl":[[0,2.28,7.34],[1,3,219.52],[2,3.6,3.26]],"ltp":2.6,"tv":19942.49,"id":8257797}]}]}
{"op":"mcm","clk":"4230512744","pt":1631533815325,"mc":[{"id":"1.187557146","rc":[{"batb":[[0,1.86,21.68],[1,1.79,29.31],[2,1.75,36.07]],"batl":[[0,1.88,19.54],[1,1.91,33.5],[2,6,3]],"ltp":1.87,"tv":4534.19,"id":19931652},{"batl":[[0,2.16,18.97],[1,2.28,7.34],[2,3,219.52]],"ltp":2.6,"tv":19942.49,"id":8257797}]}]}
{"op":"mcm","clk":"4230512811","pt":1631533815935,"mc":[{"id":"1.187557146","rc":[{"batb":[[0,1.79,29.31],[1,1.75,36.07],[2,1.39,64.91]],"batl":[[0,1.91,33.5],[1,990,0.01],[2,6,0]],"ltp":1.87,"tv":4534.19,"id":19931652},{"batl":[[0,2.28,7.34],[1,3,219.52],[2,3.6,3.26]],"ltp":2.6,"tv":19942.49,"id":8257797}]}]}
{"op":"mcm","clk":"4230513130","pt":1631533819121,"mc":[{"id":"1.187557146","rc":[{"batb":[[0,1.81,31.29],[1,1.79,29.31],[2,1.75,36.07]],"batl":[[0,1.9,34.25],[1,1.91,33.5],[2,990,0.01]],"ltp":1.87,"tv":4534.19,"id":19931652},{"batb":[[0,2.1,8.04],[1,2.08,8.56],[2,1.93,49.37]],"batl":[[0,2.24,6.98],[1,2.28,7.34],[2,3,219.52]],"ltp":2.6,"tv":19942.49,"id":8257797}]}]}
{"op":"mcm","clk":"4230513159","pt":1631533819435,"mc":[{"id":"1.187557146","rc":[{"batb":[[0,1.79,29.31],[1,1.75,36.07],[2,1.39,64.91]],"batl":[[0,1.91,33.5],[1,990,0.01],[2,990,0]],"ltp":1.87,"tv":4534.19,"id":19931652},{"batb":[[0,2.08,8.56],[1,1.93,49.37],[2,1.82,401.7]],"batl":[[0,2.28,7.34],[1,3,219.52],[2,3.6,3.26]],"ltp":2.6,"tv":19942.49,"id":8257797}]}]}
{"op":"mcm","clk":"4230513851","pt":1631533826138,"mc":[{"id":"1.187557146","rc":[{"trd":[[1.75,93.54],[1.79,29.31],[1.83,85.04]],"batb":[[0,1.8,19.57],[1,1.78,15.68]],"batl":[[0,1.83,103.94],[1,1.91,33.5],[2,990,0.01]],"ltp":1.83,"tv":4635.04,"id":19931652},{"trd":[[2.2,22],[2.28,49.85],[2.34,50.92]],"batb":[[1,1.93,78.29],[2,1.91,14.61]],"batl":[[0,2.36,68.96]],"ltp":2.2,"tv":20051.1,"id":8257797}],"tv":24686.14}]}
{"op":"mcm","clk":"4230513916","pt":1631533826718,"mc":[{"id":"1.187557146","rc":[{"batb":[[2,1.64,44.94]],"ltp":1.83,"tv":4635.04,"id":19931652},{"batb":[[0,2.1,38.49],[1,2.08,8.56],[2,1.99,45.02]],"ltp":2.2,"tv":20051.1,"id":8257797}]}]}
{"op":"mcm","clk":"4230514410","pt":1631533832242,"mc":[{"id":"1.187557146","rc":[{"batb":[[2,1.73,37.13]],"batl":[[1,1.88,54.79],[2,1.91,33.5]],"ltp":1.83,"tv":4635.04,"id":19931652},{"batb":[[0,2.12,7.79],[1,2.1,38.49],[2,2.08,8.56]],"batl":[[1,2.38,6.25],[2,2.44,5.83]],"ltp":2.2,"tv":20051.1,"id":8257797}]}]}
{"op":"mcm","clk":"4230514803","pt":1631533836326,"mc":[{"id":"1.187557146","rc":[{"batb":[[2,1.7,33.92]],"batl":[[0,1.91,33.5],[1,990,0.01],[2,1.91,0]],"ltp":1.83,"tv":4635.04,"id":19931652},{"batb":[[0,1.99,45.02],[1,1.93,28.92],[2,1.91,14.61]],"batl":[[0,3,219.52],[1,3.6,3.26],[2,990,0.01]],"ltp":2.2,"tv":20051.1,"id":8257797}]}]}
{"op":"mcm","clk":"4230514815","pt":1631533836430,"mc":[{"id":"1.187557146","rc":[{"batb":[[0,1.7,33.92],[1,1.64,44.94],[2,1.39,64.91]],"ltp":1.83,"tv":4635.04,"id":19931652},{"batb":[[1,1.82,401.7],[2,1.65,0.09]],"ltp":2.2,"tv":20051.1,"id":8257797}]}]}
{"op":"mcm","clk":"4230515079","pt":1631533839352,"mc":[{"id":"1.187557146","rc":[{"batb":[[0,2,44.18],[1,1.99,45.02],[2,1.82,401.7]],"ltp":2.2,"tv":20051.1,"id":8257797}]}]}
{"op":"mcm","clk":"4230515111","pt":1631533839666,"mc":[{"id":"1.187557146","rc":[{"batb":[[0,2.08,8.31],[1,2,44.18]],"batl":[[0,2.44,5.83],[1,3,219.52],[2,3.6,3.26]],"ltp":2.2,"tv":20051.1,"id":8257797}]}]}
{"op":"mcm","clk":"4230515924","pt":1631533848172,"mc":[{"id":"1.187557146","rc":[{"batl":[[0,1.89,95.59],[1,1.91,33.5],[2,990,0.01]],"ltp":1.83,"tv":4635.04,"id":19931652},{"batb":[[2,1.87,29.85]],"batl":[[0,2.2,16.84],[1,2.24,17.86],[2,2.28,103.59]],"ltp":2.2,"tv":20051.1,"id":8257797}]}]}
{"op":"mcm","clk":"4230515992","pt":1631533848956,"mc":[{"id":"1.187557146","rc":[{"batb":[[0,1.82,31.71],[1,1.7,33.92],[2,1.68,41.59]],"batl":[[2,6,3]],"ltp":1.83,"tv":4635.04,"id":19931652}]}]}
{"op":"mcm","clk":"4230516617","pt":1631533855087,"mc":[{"id":"1.187557146","rc":[{"batl":[[2,2.26,7.25]],"ltp":1.83,"tv":4635.04,"id":19931652}]}]}
{"op":"mcm","clk":"4230517810","pt":1631533867376,"mc":[{"id":"1.187557146","rc":[{"trd":[[1.83,105.29]],"batl":[[0,1.83,34.24],[1,1.89,95.59],[2,1.91,33.5]],"ltp":1.83,"tv":4655.28,"id":19931652},{"trd":[[2.2,38.84]],"batl":[[0,2.24,17.86],[1,2.28,103.59],[2,2.44,5.83]],"ltp":2.2,"tv":20067.94,"id":8257797}],"tv":24723.22}]}
{"op":"mcm","clk":"4230518699","pt":1631533875293,"mc":[{"id":"1.187557146","rc":[{"batb":[[0,1.68,41.59],[1,1.25,20],[2,1.01,105.7]],"batl":[[1,2.26,7.25],[2,2.38,6.75]],"ltp":1.83,"tv":4655.28,"id":19931652},{"batb":[[0,1.82,401.7],[1,1.8,52.18],[2,1.75,33.97]],"batl":[[0,3,219.52],[1,990,0.01],[2,2.44,0]],"ltp":2.2,"tv":20067.94,"id":8257797}]}]}
{"op":"mcm","clk":"4230519230","pt":1631533881218,"mc":[{"id":"1.187557146","rc":[{"trd":[[1.82,0.11],[1.83,139.52]],"batl":[[0,2.26,7.25],[1,2.38,6.75],[2,2.4,5.49]],"ltp":1.83,"tv":4689.63,"id":19931652},{"trd":[[2.2,67.41]],"ltp":2.2,"tv":20096.51,"id":8257797}],"tv":24786.14}]}
{"op":"mcm","clk":"4230519859","pt":1631533887114,"mc":[{"id":"1.187557146","rc":[{"batl":[[0,2.2,4],[1,3,219.52],[2,990,0.01]],"ltp":2.2,"tv":20096.51,"id":8257797}]}]}
{"op":"mcm","clk":"4230520544","pt":1631533893945,"mc":[{"id":"1.187557146","rc":[{"batl":[[0,2.2,2]],"ltp":2.2,"tv":20096.51,"id":8257797}]}]}
{"op":"mcm","clk":"4230520724","pt":1631533895816,"mc":[{"id":"1.187557146","rc":[{"batl":[[0,3,219.52],[1,990,0.01],[2,990,0]],"ltp":2.2,"tv":20096.51,"id":8257797}]}]}
{"op":"mcm","clk":"4230521362","pt":1631533901731,"mc":[{"id":"1.187557146","rc":[{"batl":[[0,2.2,2],[1,3,219.52],[2,990,0.01]],"ltp":2.2,"tv":20096.51,"id":8257797}]}]}
{"op":"mcm","clk":"4230521586","pt":1631533903713,"mc":[{"id":"1.187557146","rc":[{"trd":[[1.83,141.92]],"batl":[[0,1.75,63.22],[1,1.8,22.22],[2,1.86,430.38]],"ltp":1.83,"tv":4692.03,"id":19931652},{"trd":[[2.2,69.41]],"batb":[[0,2.4,8.21],[1,2.32,15.89],[2,1.82,401.7]],"batl":[[0,2.46,5.49],[1,2.56,112.52],[2,3,219.52]],"ltp":2.2,"tv":20098.51,"id":8257797}],"tv":24790.54}]}
{"op":"mcm","clk":"4230521702","pt":1631533904859,"mc":[{"id":"1.187557146","rc":[{"batb":[[1,1.59,50.63],[2,1.25,20]],"ltp":1.83,"tv":4692.03,"id":19931652},{"batb":[[2,2.2,32.97]],"ltp":2.2,"tv":20098.51,"id":8257797}]}]}
{"op":"mcm","clk":"4230521881","pt":1631533906422,"mc":[{"id":"1.187557146","rc":[{"trd":[[2.4,13.01]],"batb":[[0,2.4,6.21]],"ltp":2.4,"tv":20102.51,"id":8257797}],"tv":24794.54}]}
{"op":"mcm","clk":"4230522639","pt":1631533914135,"mc":[{"id":"1.187557146","rc":[{"trd":[[2.4,17.01]],"batb":[[0,2.4,4.21]],"ltp":2.4,"tv":20106.51,"id":8257797}],"tv":24798.54}]}
{"op":"mcm","clk":"4230522847","pt":1631533916183,"mc":[{"id":"1.187557146","rc":[{"batl":[[1,1.91,50.5],[2,1.96,28.48]],"ltp":1.83,"tv":4692.03,"id":19931652},{"batb":[[0,2.32,15.89],[1,2.2,32.97],[2,2.08,7.56]],"batl":[[0,3,219.52],[1,6,3],[2,6.4,3]],"ltp":2.4,"tv":20106.51,"id":8257797}]}]}
{"op":"mcm","clk":"4230522919","pt":1631533916858,"mc":[{"id":"1.187557146","rc":[{"batb":[[0,1.59,50.63],[1,1.25,20],[2,1.2,100]],"batl":[[0,1.98,45.75],[1,2.26,7.25],[2,2.38,6.75]],"ltp":1.83,"tv":4692.03,"id":19931652},{"batb":[[0,1.95,48.53],[1,1.82,401.7],[2,1.8,52.18]],"ltp":2.4,"tv":20106.51,"id":8257797}]}]}
{"op":"mcm","clk":"4230523296","pt":1631533920351,"mc":[{"id":"1.187557146","rc":[{"batb":[[0,2.02,8.74],[1,1.95,48.53],[2,1.82,401.7]],"ltp":2.4,"tv":20106.51,"id":8257797}]}]}
{"op":"mcm","clk":"4230524028","pt":1631533927274,"mc":[{"id":"1.187557146","rc":[{"batl":[[0,1.66,220.08],[1,1.83,30.5],[2,1.85,15.09]],"ltp":1.83,"tv":4692.03,"id":19931652},{"batb":[[0,2.5,94.72],[1,2.08,8.31],[2,2.02,8.74]],"batl":[[0,2.78,87.96]],"ltp":2.4,"tv":20106.51,"id":8257797}]}]}
{"op":"mcm","clk":"4230524116","pt":1631533928166,"mc":[{"id":"1.187557146","rc":[{"batb":[[1,1.53,58.58],[2,1.25,20]],"batl":[[0,1.66,154.33]],"ltp":1.83,"tv":4692.03,"id":19931652},{"batb":[[0,2.5,16],[1,2.38,26.36],[2,2.18,34.48]],"ltp":2.4,"tv":20106.51,"id":8257797}]}]}
{"op":"mcm","clk":"4230524339","pt":1631533930207,"mc":[{"id":"1.187557146","rc":[{"batb":[[0,1.6,8.64],[1,1.59,50.63],[2,1.53,58.58]],"ltp":1.83,"tv":4692.03,"id":19931652},{"batb":[[0,2.6,7.2],[1,2.5,16],[2,2.38,26.36]],"ltp":2.4,"tv":20106.51,"id":8257797}]}]}
{"op":"mcm","clk":"4230524447","pt":1631533931093,"mc":[{"id":"1.187557146","rc":[{"batl":[[1,3.65,175.35],[2,6,3]],"ltp":2.4,"tv":20106.51,"id":8257797}]}]}
{"op":"mcm","clk":"4230524752","pt":1631533933860,"mc":[{"id":"1.187557146","rc":[{"batb":[[2,1.57,42.57]],"batl":[[1,1.73,58.5],[2,1.77,52.5]],"ltp":1.83,"tv":4692.03,"id":19931652},{"batl":[[0,2.76,4.52],[1,2.78,87.96],[2,2.82,4.36]],"ltp":2.4,"tv":20106.51,"id":8257797}]}]}
{"op":"mcm","clk":"4230525078","pt":1631533937304,"mc":[{"id":"1.187557146","rc":[{"batb":[[0,1.59,50.63],[1,1.55,45.79],[2,1.53,58.58]],"batl":[[0,1.77,52.5],[1,2.26,7.25],[2,2.38,6.75]],"ltp":1.83,"tv":4692.03,"id":19931652},{"batb":[[0,2.38,26.36],[1,2.18,34.48],[2,1.97,395.66]],"batl":[[0,2.82,4.36],[1,3.65,175.35],[2,6,3]],"ltp":2.4,"tv":20106.51,"id":8257797}]}]}
{"op":"mcm","clk":"4230525105","pt":1631533937617,"mc":[{"id":"1.187557146","rc":[{"batb":[[0,1.55,45.79],[1,1.53,58.58],[2,1.25,20]],"ltp":1.83,"tv":4692.03,"id":19931652},{"batb":[[0,2.18,34.48],[1,1.97,395.66],[2,1.8,52.18]],"ltp":2.4,"tv":20106.51,"id":8257797}]}]}
{"op":"mcm","clk":"4230525400","pt":1631533940392,"mc":[{"id":"1.187557146","rc":[{"batb":[[0,1.57,40.57],[1,1.55,45.79],[2,1.53,58.58]],"batl":[[0,1.73,52.5],[1,1.77,52.5],[2,2.26,7.25]],"ltp":1.83,"tv":4692.03,"id":19931652},{"batb":[[0,2.36,6.18],[1,2.28,6.16],[2,2.18,34.48]],"batl":[[0,2.76,4.77],[1,2.82,4.36],[2,3.65,175.35]],"ltp":2.4,"tv":20106.51,"id":8257797}]}]}
{"op":"mcm","clk":"4230525500","pt":1631533941382,"mc":[{"id":"1.187557146","rc":[{"batb":[[0,1.55,45.79],[1,1.53,58.58],[2,1.25,20]],"batl":[[0,1.77,52.5],[1,2.26,7.25],[2,2.38,6.75]],"ltp":1.83,"tv":4692.03,"id":19931652},{"batb":[[0,2.28,6.16],[1,2.18,34.48],[2,1.97,395.66]],"batl":[[0,2.82,4.36],[1,3.65,175.35],[2,6,3]],"ltp":2.4,"tv":20106.51,"id":8257797}]}]}
{"op":"mcm","clk":"4230526014","pt":1631533947005,"mc":[{"id":"1.187557146","rc":[{"batl":[[0,1.57,2.17],[1,1.77,52.5],[2,2.26,7.25]],"ltp":1.83,"tv":4692.03,"id":19931652}]}]}
{"op":"mcm","clk":"4230526233","pt":1631533949209,"mc":[{"id":"1.187557146","rc":[{"trd":[[1.57,13.36]],"batl":[[0,1.77,52.5],[1,2.26,7.25],[2,2.38,6.75]],"ltp":1.57,"tv":4696.37,"id":19931652},{"batl":[[2,990,0.01]],"ltp":2.4,"tv":20106.51,"id":8257797}],"tv":24802.88}]}
{"op":"mcm","clk":"4230526433","pt":1631533951298,"mc":[{"id":"1.187557146","rc":[{"batl":[[0,1.72,8.71],[1,1.77,52.5],[2,1.97,28.33]],"ltp":1.57,"tv":4696.37,"id":19931652},{"batb":[[0,2.32,93.37],[1,2.28,6.16],[2,2.18,34.48]],"batl":[[0,2.4,16.66],[1,2.46,9.98],[2,2.56,112.52]],"ltp":2.4,"tv":20106.51,"id":8257797}]}]}
{"op":"mcm","clk":"4230526522","pt":1631533952121,"mc":[{"id":"1.187557146","rc":[{"batb":[[0,1.7,39.92],[1,1.58,51.3],[2,1.55,45.79]],"ltp":1.57,"tv":4696.37,"id":19931652}]}]}
{"op":"mcm","clk":"4230527116","pt":1631533958033,"mc":[{"id":"1.187557146","rc":[{"batl":[[2,1.92,47.56]],"ltp":1.57,"tv":4696.37,"id":19931652}]}]}
{"op":"mcm","clk":"4230527718","pt":1631533963236,"mc":[{"id":"1.187557146","rc":[{"batl":[[0,1.77,52.5],[1,1.92,47.56],[2,1.97,28.33]],"ltp":1.57,"tv":4696.37,"id":19931652},{"batb":[[0,2.28,6.16],[1,2.18,34.48],[2,2.08,8.81]],"batl":[[0,2.82,4.36],[1,3.3,197.44],[2,990,0.01]],"ltp":2.4,"tv":20106.51,"id":8257797}]}]}
{"op":"mcm","clk":"4230527789","pt":1631533963859,"mc":[{"id":"1.187557146","rc":[{"batb":[[0,1.58,51.3],[1,1.25,20],[2,1.01,105.7]],"batl":[[0,1.99,47.5],[1,2.26,7.25],[2,2.38,6.75]],"ltp":1.57,"tv":4696.37,"id":19931652},{"batb":[[0,1.97,395.66],[1,1.89,26.69],[2,1.8,52.18]],"batl":[[0,3.3,197.44],[1,990,0.01],[2,990,0]],"ltp":2.4,"tv":20106.51,"id":8257797}]}]}
{"op":"mcm","clk":"4230528155","pt":1631533967229,"mc":[{"id":"1.187557146","rc":[{"batb":[[0,2,24.72],[1,1.97,395.66],[2,1.89,26.69]],"ltp":2.4,"tv":20106.51,"id":8257797}]}]}
{"op":"mcm","clk":"4230528499","pt":1631533970747,"mc":[{"id":"1.187557146","rc":[{"trd":[[1.92,157.93]],"ltp":1.92,"tv":4699.75,"id":19931652}],"tv":24806.26}]}
{"op":"mcm","clk":"4230529103","pt":1631533977146,"mc":[{"id":"1.187557146","rc":[{"batb":[[1,1.89,26.69],[2,1.8,52.18]],"batl":[[0,990,0.01],[1,990,0]],"ltp":2.4,"tv":20106.51,"id":8257797}]}]}
{"op":"mcm","clk":"4230529229","pt":1631533978348,"mc":[{"id":"1.187557146","rc":[{"batl":[[0,1.94,8.98],[1,1.99,47.5],[2,2,59.09]],"ltp":1.92,"tv":4699.75,"id":19931652},{"batb":[[0,2,83.81]],"batl":[[0,2.12,105.03],[1,2.2,112.52],[2,990,0.01]],"ltp":2.4,"tv":20106.51,"id":8257797}]}]}
{"op":"mcm","clk":"4230529329","pt":1631533979235,"mc":[{"id":"1.187557146","rc":[{"batb":[[0,1.93,26.28],[1,1.69,41],[2,1.25,20]],"ltp":1.92,"tv":4699.75,"id":19931652},{"batl":[[0,2.12,29.55]],"ltp":2.4,"tv":20106.51,"id":8257797}]}]}
{"op":"mcm","clk":"4230529349","pt":1631533979440,"mc":[{"id":"1.187557146","rc":[{"trd":[[1.93,65.34]],"batb":[[0,1.93,24.11]],"ltp":1.93,"tv":4704.09,"id":19931652}],"tv":24810.6}]}
{"op":"mcm","clk":"4230529504","pt":1631533980958,"mc":[{"id":"1.187557146","rc":[{"batl":[[2,2.82,211.06]],"ltp":2.4,"tv":20106.51,"id":8257797}]}]}
{"op":"mcm","clk":"4230529737","pt":1631533983267,"mc":[{"id":"1.187557146","rc":[{"trd":[[1.94,293.23]],"batl":[[0,1.99,47.5],[1,2,59.09],[2,2.26,7.25]],"ltp":1.94,"tv":4722.05,"id":19931652}],"tv":24828.56}]}
{"op":"mcm","clk":"4230529930","pt":1631533984863,"mc":[{"id":"1.187557146","rc":[{"batb":[[2,1.67,2.05]],"ltp":1.94,"tv":4722.05,"id":19931652},{"batl":[[2,2.5,2.51]],"ltp":2.4,"tv":20106.51,"id":8257797}]}]}
{"op":"mcm","clk":"4230530076","pt":1631533986267,"mc":[{"id":"1.187557146","rc":[{"batb":[[0,1.93,24.19]],"ltp":1.94,"tv":4722.05,"id":19931652},{"batl":[[0,2.02,137.8],[1,2.12,29.55],[2,2.2,112.52]],"ltp":2.4,"tv":20106.51,"id":8257797}]}]}
{"op":"mcm","clk":"4230530115","pt":1631533986643,"mc":[{"id":"1.187557146","rc":[{"trd":[[1.99,104.02],[2,382.48]],"batb":[[0,2,181.28],[1,1.93,24.11],[2,1.69,41]],"batl":[[0,2.26,7.25],[1,2.38,6.75],[2,2.4,5.49]],"ltp":2.0,"tv":5019.04,"id":19931652},{"trd":[[2,506.81]],"batb":[[0,1.89,26.69],[1,1.8,52.18],[2,1.79,31.18]],"ltp":2.0,"tv":20190.32,"id":8257797}],"tv":25209.36}]}
{"op":"mcm","clk":"4230530349","pt":1631533989082,"mc":[{"id":"1.187557146","rc":[{"batl":[[0,2.12,29.55],[1,2.2,112.52],[2,2.5,2.51]],"ltp":2.0,"tv":20190.32,"id":8257797}]}]}
{"op":"mcm","clk":"4230530454","pt":1631533990070,"mc":[{"id":"1.187557146","rc":[{"batb":[[0,1.93,24.19],[1,1.69,41],[2,1.68,2.11]],"ltp":2.0,"tv":5019.04,"id":19931652},{"batl":[[2,2.48,2.74]],"ltp":2.0,"tv":20190.32,"id":8257797}]}]}
{"op":"mcm","clk":"4230530662","pt":1631533992153,"mc":[{"id":"1.187557146","rc":[{"batl":[[0,2,137.8],[1,2.12,29.55],[2,2.2,112.52]],"ltp":2.0,"tv":20190.32,"id":8257797}]}]}
{"op":"mcm","clk":"4230530747","pt":1631533993082,"mc":[{"id":"1.187557146","rc":[{"batl":[[1,2.12,18.86]],"ltp":2.0,"tv":20190.32,"id":8257797}]}]}
{"op":"mcm","clk":"4230530841","pt":1631533993971,"mc":[{"id":"1.187557146","rc":[{"batb":[[0,1.93,24.11]],"ltp":2.0,"tv":5019.04,"id":19931652},{"batl":[[0,2.12,18.86],[1,2.2,112.52],[2,2.48,2.74]],"ltp":2.0,"tv":20190.32,"id":8257797}]}]}
{"op":"mcm","clk":"4230531023","pt":1631533996066,"mc":[{"id":"1.187557146","rc":[{"batb":[[1,1.92,8.73],[2,1.69,41]],"batl":[[0,1.96,8.36],[1,2.26,7.25],[2,2.38,6.75]],"ltp":2.0,"tv":5019.04,"id":19931652},{"batb":[[2,1.73,45.13]],"ltp":2.0,"tv":20190.32,"id":8257797}]}]}
{"op":"mcm","clk":"4230531063","pt":1631533996474,"mc":[{"id":"1.187557146","rc":[{"trd":[[1.96,89.26]],"batl":[[0,1.96,8.28]],"ltp":1.96,"tv":5019.2,"id":19931652}],"tv":25209.52}]}
{"op":"mcm","clk":"4230531424","pt":1631534000284,"mc":[{"id":"1.187557146","rc":[{"batb":[[0,1.96,58.62],[1,1.69,41],[2,1.58,40.06]],"batl":[[0,3,3.64],[1,3.05,4.5],[2,990,0.01]],"ltp":1.96,"tv":5019.2,"id":19931652},{"batb":[[0,1.7,453.94],[1,1.54,53.23],[2,1.5,49.02]],"batl":[[0,2.74,4.48],[1,2.82,211.06],[2,990,0.01]],"ltp":2.0,"tv":20190.32,"id":8257797}]}]}
{"op":"mcm","clk":"4230531445","pt":1631534000493,"mc":[{"id":"1.187557146","rc":[{"batb":[[0,1.69,41],[1,1.58,40.06],[2,1.25,20]],"ltp":1.96,"tv":5019.2,"id":19931652}]}]}
{"op":"mcm","clk":"4230531716","pt":1631534003279,"mc":[{"id":"1.187557146","rc":[{"batb":[[1,1.67,41.76],[2,1.62,42.04]],"batl":[[0,2.86,4.25],[1,3,3.64],[2,3.05,4.5]],"ltp":1.96,"tv":5019.2,"id":19931652},{"batb":[[1,1.54,96.35]],"batl":[[0,2.5,7.96],[1,2.62,5.46],[2,2.74,4.48]],"ltp":2.0,"tv":20190.32,"id":8257797}]}]}
{"op":"mcm","clk":"4230531727","pt":1631534003383,"mc":[{"id":"1.187557146","rc":[{"batb":[[1,1.62,42.04],[2,1.58,40.06]],"ltp":1.96,"tv":5019.2,"id":19931652},{"batl":[[0,2.62,5.46],[1,2.74,4.48],[2,2.82,211.06]],"ltp":2.0,"tv":20190.32,"id":8257797}]}]}
{"op":"mcm","clk":"4230532002","pt":1631534006293,"mc":[{"id":"1.187557146","rc":[{"batb":[[1,1.62,44.16]],"batl":[[0,3.05,4.5],[1,3.65,3.1],[2,990,0.01]],"ltp":1.96,"tv":5019.2,"id":19931652},{"batb":[[0,1.54,53.23],[1,1.49,49.01],[2,1.38,70.96]],"batl":[[0,2.62,8.21],[2,990,0.01]],"ltp":2.0,"tv":20190.32,"id":8257797}]}]}
{"op":"mcm","clk":"4230532106","pt":1631534007231,"mc":[{"id":"1.187557146","rc":[{"batb":[[1,1.62,42.04]],"batl":[[0,1.71,22.5],[1,1.78,22.48],[2,1.93,28.92]],"ltp":1.96,"tv":5019.2,"id":19931652},{"batb":[[0,2.4,5.21],[1,2.28,103.18],[2,1.54,53.23]],"batl":[[0,2.56,124.62],[1,2.62,5.46],[2,2.74,4.48]],"ltp":2.0,"tv":20190.32,"id":8257797}]}]}
{"op":"mcm","clk":"4230532204","pt":1631534008222,"mc":[{"id":"1.187557146","rc":[{"batb":[[2,2.2,33.47]],"ltp":2.0,"tv":20190.32,"id":8257797}]}]}
{"op":"mcm","clk":"4230532384","pt":1631534009905,"mc":[{"id":"1.187557146","rc":[{"batb":[[0,2.4,13.53]],"batl":[[0,2.46,5.38],[1,2.56,124.62],[2,2.62,5.46]],"ltp":2.0,"tv":20190.32,"id":8257797}]}]}
{"op":"mcm","clk":"4230532728","pt":1631534013324,"mc":[{"id":"1.187557146","rc":[{"batl":[[2,1.93,70.92]],"ltp":1.96,"tv":5019.2,"id":19931652}]}]}
{"op":"mcm","clk":"4230532824","pt":1631534014213,"mc":[{"id":"1.187557146","rc":[{"batl":[[2,1.93,74.92]],"ltp":1.96,"tv":5019.2,"id":19931652}]}]}
{"op":"mcm","clk":"4230532943","pt":1631534015523,"mc":[{"id":"1.187557146","rc":[{"trd":[[2.4,20.63]],"batb":[[0,2.4,11.72]],"ltp":2.4,"tv":20193.94,"id":8257797}],"tv":25213.14}]}
{"op":"mcm","clk":"4230533079","pt":1631534016920,"mc":[{"id":"1.187557146","rc":[{"trd":[[1.69,175.32]],"batb":[[0,1.69,6.55]],"ltp":1.69,"tv":5088.1,"id":19931652}],"tv":25282.04}]}
{"op":"mcm","clk":"4230533215","pt":1631534018199,"mc":[{"id":"1.187557146","rc":[{"batb":[[0,1.57,45.57],[1,1.56,54.64],[2,1.53,50.33]],"batl":[[0,2.02,7.75],[1,3.05,4.5],[2,3.65,3.1]],"ltp":1.69,"tv":5088.1,"id":19931652},{"batb":[[0,1.99,27.51],[1,1.92,430.26],[2,1.87,27.45]],"batl":[[0,2.76,4.77],[1,2.9,4.75],[2,3.45,166.24]],"ltp":2.4,"tv":20193.94,"id":8257797}]}]}
{"op":"mcm","clk":"4230533232","pt":1631534018405,"mc":[{"id":"1.187557146","rc":[{"batb":[[0,1.56,54.64],[1,1.53,50.33],[2,1.25,20]],"ltp":1.69,"tv":5088.1,"id":19931652},{"batl":[[0,2.9,4.75],[1,3.45,166.24],[2,6,3]],"ltp":2.4,"tv":20193.94,"id":8257797}]}]}
{"op":"mcm","clk":"4230533547","pt":1631534021331,"mc":[{"id":"1.187557146","rc":[{"batb":[[1,1.55,55.56],[2,1.53,50.33]],"batl":[[0,1.94,26.75],[1,2.02,7.75],[2,3.05,4.5]],"ltp":1.69,"tv":5088.1,"id":19931652},{"batb":[[0,2.06,7.08],[1,1.99,27.51],[2,1.92,430.26]],"ltp":2.4,"tv":20193.94,"id":8257797}]}]}
{"op":"mcm","clk":"4230533649","pt":1631534022226,"mc":[{"id":"1.187557146","rc":[{"batb":[[0,1.55,55.56],[1,1.53,50.33],[2,1.25,20]],"batl":[[0,2.02,7.75],[1,3.05,4.5],[2,3.65,3.1]],"ltp":1.69,"tv":5088.1,"id":19931652},{"batb":[[0,1.99,27.51],[1,1.92,430.26],[2,1.88,26.95]],"batl":[[1,6,3],[2,6.4,3]],"ltp":2.4,"tv":20193.94,"id":8257797}]}]}
{"op":"mcm","clk":"4230533848","pt":1631534024104,"mc":[{"id":"1.187557146","rc":[{"batb":[[0,1.55,56.55]],"ltp":1.69,"tv":5088.1,"id":19931652}]}]}
{"op":"mcm","clk":"4230534075","pt":1631534026215,"mc":[{"id":"1.187557146","rc":[{"batb":[[0,1.57,45.56],[1,1.55,55.56],[2,1.53,50.33]],"ltp":1.69,"tv":5088.1,"id":19931652},{"batl":[[0,2.76,4.77],[1,2.9,4.75],[2,6,3]],"ltp":2.4,"tv":20193.94,"id":8257797}]}]}
{"op":"mcm","clk":"4230534128","pt":1631534026620,"mc":[{"id":"1.187557146","rc":[{"batb":[[0,1.55,56.55],[1,1.53,50.33],[2,1.25,20]],"ltp":1.69,"tv":5088.1,"id":19931652},{"batl":[[0,2.9,4.75],[1,3.3,176.5]],"ltp":2.4,"tv":20193.94,"id":8257797}]}]}
{"op":"mcm","clk":"4230534267","pt":1631534028139,"mc":[{"id":"1.187557146","rc":[{"batb":[[0,1.55,55.56]],"batl":[[0,1.94,29.25],[1,2.02,7.75],[2,3.05,4.5]],"ltp":1.69,"tv":5088.1,"id":19931652},{"batb":[[0,2.06,8.58],[1,1.99,27.51],[2,1.92,430.26]],"ltp":2.4,"tv":20193.94,"id":8257797}]}]}
{"op":"mcm","clk":"4230534296","pt":1631534028411,"mc":[{"id":"1.187557146","rc":[{"batl":[[0,2.02,7.75],[1,3.05,4.5],[2,3.65,3.1]],"ltp":1.69,"tv":5088.1,"id":19931652},{"batb":[[0,1.99,27.51],[1,1.92,430.26],[2,1.88,26.95]],"ltp":2.4,"tv":20193.94,"id":8257797}]}]}
{"op":"mcm","clk":"4230535464","pt":1631534039167,"mc":[{"id":"1.187557146","rc":[{"batl":[[0,1.56,2.17],[1,2.02,7.75],[2,3.05,4.5]],"ltp":1.69,"tv":5088.1,"id":19931652}]}]}
{"op":"mcm","clk":"4230535592","pt":1631534040323,"mc":[{"id":"1.187557146","rc":[{"trd":[[1.56,4.34]],"batl":[[0,2.02,7.75],[1,3.05,4.5],[2,3.65,3.1]],"ltp":1.56,"tv":5092.44,"id":19931652}],"tv":25286.38}]}
{"op":"mcm","clk":"4230535974","pt":1631534043836,"mc":[{"id":"1.187557146","rc":[{"batl":[[2,990,0.01]],"ltp":2.4,"tv":20193.94,"id":8257797}]}]}
{"op":"mcm","clk":"4230536155","pt":1631534045356,"mc":[{"id":"1.187557146","rc":[{"batl":[[0,1.98,13.29],[1,2.02,7.75],[2,3.05,4.5]],"ltp":1.56,"tv":5092.44,"id":19931652},{"batb":[[1,1.94,120.7]],"batl":[[0,2.06,97.08],[1,2.08,8.6],[2,2.1,1432.38]],"ltp":2.4,"tv":20193.94,"id":8257797}]}]}
{"op":"mcm","clk":"4230536253","pt":1631534046353,"mc":[{"id":"1.187557146","rc":[{"trd":[[1.94,319.48]],"batb":[[0,1.94,52.13],[1,1.7,40.08],[2,1.55,55.56]],"ltp":1.94,"tv":5118.69,"id":19931652},{"trd":[[2.06,514.38]],"batl":[[0,2.06,9.71],[2,2.16,168.46]],"ltp":2.06,"tv":20235.82,"id":8257797}],"tv":25354.51}]}
{"op":"mcm","clk":"4230536277","pt":1631534046562,"mc":[{"id":"1.187557146","rc":[{"batb":[[2,1.53,50.33]],"ltp":1.94,"tv":5118.69,"id":19931652}]}]}
{"op":"mcm","clk":"4230536833","pt":1631534052369,"mc":[{"id":"1.187557146","rc":[{"batb":[[2,1.69,38.21]],"batl":[[2,2.8,4.22]],"ltp":1.94,"tv":5118.69,"id":19931652}]}]}
{"op":"mcm","clk":"4230537274","pt":1631534056769,"mc":[{"id":"1.187557146","rc":[{"trd":[[1.98,357.88],[2,391.5]],"batl":[[0,2.02,7.75],[1,2.8,4.22],[2,3.05,4.5]],"ltp":2.0,"tv":5141.0,"id":19931652},{"trd":[[1.99,64.09],[2.02,392.33]],"batb":[[0,1.94,120.7],[1,1.88,26.95],[2,1.78,31.36]],"batl":[[0,1.99,157.1],[1,2.06,9.71],[2,2.08,8.6]],"ltp":1.99,"tv":20312.93,"id":8257797}],"tv":25453.93}]}
{"op":"mcm","clk":"4230537553","pt":1631534059859,"mc":[{"id":"1.187557146","rc":[{"batl":[[2,2.82,5.25]],"ltp":2.0,"tv":5141.0,"id":19931652}]}]}
{"op":"mcm","clk":"4230537648","pt":1631534060959,"mc":[{"id":"1.187557146","rc":[{"batl":[[0,2.06,9.71],[1,2.08,8.6],[2,2.16,168.46]],"ltp":1.99,"tv":20312.93,"id":8257797}]}]}
{"op":"mcm","clk":"4230537820","pt":1631534062685,"mc":[{"id":"1.187557146","rc":[{"batb":[[2,1.7,453.94]],"ltp":1.99,"tv":20312.93,"id":8257797}]}]}
{"op":"mcm","clk":"4230537950","pt":1631534064054,"mc":[{"id":"1.187557146","rc":[{"trd":[[2.02,7.75]],"batl":[[0,2.8,4.22],[1,2.82,5.25],[2,3,4.37]],"ltp":2.02,"tv":5148.75,"id":19931652},{"trd":[[1.98,7.91]],"batl":[[0,1.97,149.19],[1,2.06,9.71],[2,2.08,8.6]],"ltp":1.98,"tv":20320.83,"id":8257797}],"tv":25469.59}]}
{"op":"mcm","clk":"4230538114","pt":1631534065933,"mc":[{"id":"1.187557146","rc":[{"batb":[[0,1.7,40.08],[1,1.69,38.21],[2,1.62,45.04]],"batl":[[0,3.9,2.55],[1,990,0.01],[2,3,0]],"ltp":2.02,"tv":5148.75,"id":19931652},{"batb":[[0,1.7,453.94],[1,1.54,53.81],[2,1.33,0.09]],"batl":[[1,2.46,5.75],[2,2.62,5.25]],"ltp":1.98,"tv":20320.83,"id":8257797}]}]}
{"op":"mcm","clk":"4230538228","pt":1631534067271,"mc":[{"id":"1.187557146","rc":[{"batl":[[0,2.62,10.88],[1,3.9,2.55],[2,990,0.01]],"ltp":2.02,"tv":5148.75,"id":19931652}]}]}
{"op":"mcm","clk":"4230538235","pt":1631534067376,"mc":[{"id":"1.187557146","rc":[{"batl":[[0,3.9,2.55],[1,990,0.01],[2,990,0]],"ltp":2.02,"tv":5148.75,"id":19931652}]}]}
{"op":"mcm","clk":"4230538403","pt":1631534069294,"mc":[{"id":"1.187557146","rc":[{"batb":[[0,1.69,78.71],[1,1.62,45.04],[2,1.6,38.39]],"batl":[[1,6,3],[2,6.4,3]],"ltp":2.02,"tv":5148.75,"id":19931652},{"batb":[[2,1.2,100.09]],"ltp":1.98,"tv":20320.83,"id":8257797}]}]}
{"op":"mcm","clk":"4230538438","pt":1631534069668,"mc":[{"id":"1.187557146","rc":[{"batb":[[0,1.69,40.5],[2,1.53,50.33]],"ltp":2.02,"tv":5148.75,"id":19931652},{"batl":[[0,2.62,5.25],[1,2.82,211.06],[2,2.9,4.75]],"ltp":1.98,"tv":20320.83,"id":8257797}]}]}
{"op":"mcm","clk":"4230538601","pt":1631534071887,"mc":[{"id":"1.187557146","rc":[{"trd":[[1.7,3.97]],"batb":[[0,1.7,451.96]],"ltp":1.7,"tv":20324.81,"id":8257797}],"tv":25473.56}]}
{"op":"mcm","clk":"4230538856","pt":1631534074797,"mc":[{"id":"1.187557146","rc":[{"batb":[[2,1.25,20]],"ltp":2.02,"tv":5148.75,"id":19931652},{"batb":[[0,1.54,53.81],[1,1.2,100.09],[2,1.19,103]],"batl":[[0,990,0.01],[1,2.82,0],[2,2.9,0]],"ltp":1.7,"tv":20324.81,"id":8257797}]}]}
{"op":"mcm","clk":"4230539003","pt":1631534076299,"mc":[{"id":"1.187557146","rc":[{"trd":[[2.6,13.18]],"batb":[[0,2.52,24.52],[1,1.95,51.21],[2,1.69,40.5]],"batl":[[0,2.78,136.55],[1,3.9,2.55],[2,6,3]],"ltp":2.6,"tv":5161.93,"id":19931652},{"trd":[[1.62,70.6]],"batb":[[1,1.49,37.46],[2,1.47,18.99]],"batl":[[0,1.61,32.34],[1,1.66,14.65],[2,1.72,23.26]],"ltp":1.62,"tv":20324.97,"id":8257797}],"tv":25486.9}]}
{"op":"mcm","clk":"4230539024","pt":1631534076505,"mc":[{"id":"1.187557146","rc":[{"batb":[[2,1.62,45.04]],"ltp":2.6,"tv":5161.93,"id":19931652}]}]}
{"op":"mcm","clk":"4230539624","pt":1631534083111,"mc":[{"id":"1.187557146","rc":[{"batb":[[1,1.97,26.17],[2,1.95,51.21]],"ltp":2.6,"tv":5161.93,"id":19931652}]}]}
{"op":"mcm","clk":"4230539725","pt":1631534084308,"mc":[{"id":"1.187557146","rc":[{"trd":[[2.78,9.28]],"batl":[[0,2.78,127.27]],"ltp":2.78,"tv":5171.21,"id":19931652},{"trd":[[1.56,16.53]],"ltp":1.56,"tv":20341.5,"id":8257797}],"tv":25512.71}]}
{"op":"mcm","clk":"4230539906","pt":1631534086291,"mc":[{"id":"1.187557146","rc":[{"trd":[[2.62,4.51]],"batb":[[1,1.95,51.21],[2,1.85,30.77]],"batl":[[0,6,3],[1,6.4,3],[2,6.6,3]],"ltp":2.62,"tv":5175.72,"id":19931652},{"trd":[[1.61,7.52]],"batb":[[1,1.46,495.36],[2,1.22,160.68]],"batl":[[0,2.22,298.44],[1,990,0.01],[2,1.72,0]],"ltp":1.61,"tv":20349.02,"id":8257797}],"tv":25524.74}]}
{"op":"mcm","clk":"4230539942","pt":1631534086599,"mc":[{"id":"1.187557146","rc":[{"batb":[[0,1.95,51.21],[1,1.85,30.77],[2,1.25,20]],"ltp":2.62,"tv":5175.72,"id":19931652},{"batb":[[0,1.46,495.36],[1,1.22,160.68],[2,1.2,100]],"ltp":1.61,"tv":20349.02,"id":8257797}]}]}
{"op":"mcm","clk":"4230540087","pt":1631534087897,"mc":[{"id":"1.187557146","rc":[{"trd":[[1.56,17.3]],"batb":[[0,1.22,160.68],[1,1.2,100],[2,1.19,103]],"batl":[[0,1.56,206.31]],"ltp":1.56,"tv":20349.8,"id":8257797}],"tv":25525.52}]}
{"op":"mcm","clk":"4230540188","pt":1631534088896,"mc":[{"id":"1.187557146","rc":[{"trd":[[2.78,19.97]],"ltp":2.78,"tv":5186.41,"id":19931652},{"trd":[[1.56,36.35]],"batl":[[0,1.56,187.26]],"ltp":1.56,"tv":20368.84,"id":8257797}],"tv":25555.26}]}
{"op":"mcm","clk":"4230540248","pt":1631534089513,"mc":[{"id":"1.187557146","rc":[{"batb":[[0,1.97,23.17],[1,1.95,51.21],[2,1.85,30.77]],"ltp":2.78,"tv":5186.41,"id":19931652},{"batl":[[1,2.04,7.13],[2,2.18,7.75]],"ltp":1.56,"tv":20368.84,"id":8257797}]}]}
{"op":"mcm","clk":"4230540483","pt":1631534092214,"mc":[{"id":"1.187557146","rc":[{"trd":[[2.78,20.51]],"batl":[[0,990,0.01],[1,6.4,0],[2,6.6,0]],"ltp":2.78,"tv":5186.95,"id":19931652},{"trd":[[1.56,37.32]],"batb":[[1,1.2,0],[2,1.19,0]],"batl":[[0,1.56,186.3]],"ltp":1.56,"tv":20369.81,"id":8257797}],"tv":25556.76}]}
{"op":"mcm","clk":"4230540578","pt":1631534093108,"mc":[{"id":"1.187557146","rc":[{"batb":[[0,1.95,51.21],[1,1.85,30.77],[2,1.25,20]],"ltp":2.78,"tv":5186.95,"id":19931652},{"batl":[[0,2.18,7.75],[1,990,0.01],[2,2.18,0]],"ltp":1.56,"tv":20369.81,"id":8257797}]}]}
{"op":"mcm","clk":"4230540683","pt":1631534094211,"mc":[{"id":"1.187557146","rc":[{"batl":[[0,2.08,30.1],[1,2.12,169.17],[2,990,0.01]],"ltp":2.78,"tv":5186.95,"id":19931652},{"batb":[[0,1.78,31.36],[1,1.76,15.86],[2,1.22,160.68]],"batl":[[0,1.98,11.17],[1,2.16,172.21],[2,2.18,7.75]],"ltp":1.56,"tv":20369.81,"id":8257797}]}]}
{"op":"mcm","clk":"4230540758","pt":1631534095137,"mc":[{"id":"1.187557146","rc":[{"trd":[[2.08,1.85]],"batb":[[2,1.71,39.5]],"batl":[[0,2.08,28.25]],"ltp":2.08,"tv":5188.8,"id":19931652},{"trd":[[1.92,2]],"batb":[[0,1.87,27.45],[1,1.78,31.36],[2,1.76,15.86]],"ltp":1.92,"tv":20371.81,"id":8257797}],"tv":25560.61}]}
{"op":"mcm","clk":"4230541139","pt":1631534099033,"mc":[{"id":"1.187557146","rc":[{"batl":[[0,2.08,17.39],[2,2.62,2]],"ltp":2.08,"tv":5188.8,"id":19931652},{"batl":[[0,2.16,172.21],[1,2.18,7.75],[2,2.82,212.27]],"ltp":1.92,"tv":20371.81,"id":8257797}]}]}
{"op":"mcm","clk":"4230541173","pt":1631534099447,"mc":[{"id":"1.187557146","rc":[{"batl":[[2,2.62,4]],"ltp":2.08,"tv":5188.8,"id":19931652}]}]}
{"op":"mcm","clk":"4230541353","pt":1631534101223,"mc":[{"id":"1.187557146","rc":[{"batb":[[2,1.74,31.52]],"ltp":2.08,"tv":5188.8,"id":19931652},{"batl":[[2,2.36,6.32]],"ltp":1.92,"tv":20371.81,"id":8257797}]}]}
{"op":"mcm","clk":"4230541433","pt":1631534101949,"mc":[{"id":"1.187557146","rc":[{"batl":[[0,2.08,28.25]],"ltp":2.08,"tv":5188.8,"id":19931652},{"batl":[[0,1.98,11.17],[1,2.16,172.21],[2,2.18,7.75]],"ltp":1.92,"tv":20371.81,"id":8257797}]}]}
{"op":"mcm","clk":"4230541567","pt":1631534103212,"mc":[{"id":"1.187557146","rc":[{"batl":[[0,2.62,4],[1,3.05,3.7],[2,3.9,3.15]],"ltp":2.08,"tv":5188.8,"id":19931652},{"batl":[[0,2.18,7.75],[1,2.36,6.32],[2,2.5,5.47]],"ltp":1.92,"tv":20371.81,"id":8257797}]}]}
{"op":"mcm","clk":"4230541630","pt":1631534103837,"mc":[{"id":"1.187557146","rc":[{"batb":[[0,1.71,39.5],[1,1.67,32.47],[2,1.25,20]],"ltp":2.08,"tv":5188.8,"id":19931652},{"batb":[[0,1.7,451.87],[1,1.53,54.98],[2,1.49,51.01]],"batl":[[0,2.82,212.27],[1,990,0.01],[2,2.5,0]],"ltp":1.92,"tv":20371.81,"id":8257797}]}]}
{"op":"mcm","clk":"4230541811","pt":1631534105832,"mc":[{"id":"1.187557146","rc":[{"batl":[[0,2.02,13.53],[1,2.62,4],[2,3.05,3.7]],"ltp":2.08,"tv":5188.8,"id":19931652}]}]}
{"op":"mcm","clk":"4230541927","pt":1631534106927,"mc":[{"id":"1.187557146","rc":[{"trd":[[2.02,21.28]],"batl":[[0,2.62,4],[1,3.05,3.7],[2,3.9,3.15]],"ltp":2.02,"tv":5202.33,"id":19931652},{"trd":[[1.98,21.71]],"batl":[[0,1.92,13.76],[1,2.5,5.95],[2,2.82,212.27]],"ltp":1.98,"tv":20385.61,"id":8257797}],"tv":25587.94}]}
{"op":"mcm","clk":"4230542056","pt":1631534108124,"mc":[{"id":"1.187557146","rc":[{"batl":[[0,3.05,3.7],[1,3.9,3.15],[2,990,0.01]],"ltp":2.02,"tv":5202.33,"id":19931652},{"batl":[[0,2.5,5.95],[1,2.82,212.27],[2,990,0.01]],"ltp":1.98,"tv":20385.61,"id":8257797}]}]}
{"op":"mcm","clk":"4230542090","pt":1631534108544,"mc":[{"id":"1.187557146","rc":[{"trd":[[1.71,13.82]],"batb":[[0,1.71,32.59]],"ltp":1.71,"tv":5216.14,"id":19931652}],"tv":25601.76}]}
{"op":"mcm","clk":"4230542261","pt":1631534110265,"mc":[{"id":"1.187557146","rc":[{"batb":[[0,1.74,33.02],[1,1.71,32.59],[2,1.67,32.47]],"ltp":1.71,"tv":5216.14,"id":19931652},{"batl":[[0,2.36,6.07],[1,2.5,5.95],[2,2.82,212.27]],"ltp":1.98,"tv":20385.61,"id":8257797}]}]}
{"op":"mcm","clk":"4230542324","pt":1631534110842,"mc":[{"id":"1.187557146","rc":[{"batb":[[0,1.71,32.59],[1,1.67,32.47],[2,1.25,20]],"ltp":1.71,"tv":5216.14,"id":19931652},{"batl":[[0,1.92,9]],"ltp":1.98,"tv":20385.61,"id":8257797}]}]}
{"op":"mcm","clk":"4230542987","pt":1631534117848,"mc":[{"id":"1.187557146","rc":[{"batl":[[0,3.9,3.15],[1,990,0.01],[2,990,0]],"ltp":1.71,"tv":5216.14,"id":19931652},{"batb":[[0,1.53,54.98],[1,1.35,74.67],[2,1.33,0.09]],"batl":[[2,990,0.01]],"ltp":1.98,"tv":20385.61,"id":8257797}]}]}
{"op":"mcm","clk":"4230543098","pt":1631534118952,"mc":[{"id":"1.187557146","rc":[{"batl":[[0,2.72,7.58],[1,2.78,115.01],[2,3.9,3.15]],"ltp":1.71,"tv":5216.14,"id":19931652},{"batb":[[1,1.48,37.72],[2,1.46,19.12]],"batl":[[0,1.59,25.16],[1,1.62,18.07],[2,1.72,178]],"ltp":1.98,"tv":20385.61,"id":8257797}]}]}
{"op":"mcm","clk":"4230543178","pt":1631534119729,"mc":[{"id":"1.187557146","rc":[{"batb":[[0,2.54,24.02],[1,1.97,49.87],[2,1.67,32.47]],"ltp":1.71,"tv":5216.14,"id":19931652},{"batb":[[0,1.53,54.81]],"ltp":1.98,"tv":20385.61,"id":8257797}]}]}
{"op":"mcm","clk":"4230543334","pt":1631534121249,"mc":[{"id":"1.187557146","rc":[{"batb":[[2,1.46,514.47]],"batl":[[2,1.7,42]],"ltp":1.98,"tv":20385.61,"id":8257797}]}]}
{"op":"mcm","clk":"4230543430","pt":1631534122038,"mc":[{"id":"1.187557146","rc":[{"trd":[[2.68,14.93]],"ltp":2.68,"tv":5231.07,"id":19931652},{"trd":[[1.59,25.16]],"batl":[[0,1.62,18.07],[1,1.7,44],[2,1.72,178]],"ltp":1.59,"tv":20410.77,"id":8257797}],"tv":25641.85}]}
{"op":"mcm","clk":"4230543764","pt":1631534125066,"mc":[{"id":"1.187557146","rc":[{"batb":[[1,2.02,7.74],[2,1.97,49.87]],"ltp":2.68,"tv":5231.07,"id":19931652},{"batl":[[1,1.7,4]],"ltp":1.59,"tv":20410.77,"id":8257797}]}]}
{"op":"mcm","clk":"4230543881","pt":1631534126064,"mc":[{"id":"1.187557146","rc":[{"batl":[[1,1.7,47.08]],"ltp":1.59,"tv":20410.77,"id":8257797}]}]}
{"op":"mcm","clk":"4230543997","pt":1631534127152,"mc":[{"id":"1.187557146","rc":[{"trd":[[2.72,7.58],[2.78,90.51]],"batl":[[0,2.78,45.01],[1,3.9,3.15],[2,990,0.01]],"ltp":2.78,"tv":5308.65,"id":19931652},{"trd":[[1.56,162.07],[1.58,93.88]],"ltp":1.56,"tv":20548.57,"id":8257797}],"tv":25857.23}]}
{"op":"mcm","clk":"4230544293","pt":1631534130252,"mc":[{"id":"1.187557146","rc":[{"trd":[[2.78,95.56]],"batl":[[0,2.78,39.96]],"ltp":2.78,"tv":5313.7,"id":19931652},{"trd":[[1.56,171.07],[1.62,80.67]],"batl":[[0,1.62,13.04]],"ltp":1.56,"tv":20567.63,"id":8257797}],"tv":25881.34}]}
{"op":"mcm","clk":"4230544319","pt":1631534130565,"mc":[{"id":"1.187557146","rc":[{"batl":[[1,1.7,45.08]],"ltp":1.56,"tv":20567.63,"id":8257797}]}]}
{"op":"mcm","clk":"4230544427","pt":1631534131673,"mc":[{"id":"1.187557146","rc":[{"trd":[[2.6,13.63]],"ltp":2.6,"tv":5314.15,"id":19931652},{"trd":[[1.62,81.39]],"batl":[[0,1.62,12.32]],"ltp":1.62,"tv":20568.35,"id":8257797}],"tv":25882.51}]}
{"op":"mcm","clk":"4230544569","pt":1631534132995,"mc":[{"id":"1.187557146","rc":[{"batb":[[0,1.97,49.87],[1,1.91,30.39],[2,1.67,32.47]],"batl":[[0,990,0.01],[1,3.9,0],[2,990,0]],"ltp":2.6,"tv":5314.15,"id":19931652},{"batb":[[0,1.46,495.36],[1,1.22,162.52],[2,1.46,0]],"batl":[[0,1.7,45.08],[1,2.22,298.44],[2,2.5,5.95]],"ltp":1.62,"tv":20568.35,"id":8257797}]}]}
{"op":"mcm","clk":"4230544785","pt":1631534135095,"mc":[{"id":"1.187557146","rc":[{"batb":[[0,1.22,162.52],[1,1.22,0]],"batl":[[1,2.5,5.95],[2,990,0.01]],"ltp":1.62,"tv":20568.35,"id":8257797}]}]}
{"op":"mcm","clk":"4230544895","pt":1631534136189,"mc":[{"id":"1.187557146","rc":[{"batb":[[2,1.25,20]],"batl":[[0,6,3],[1,6.4,3],[2,6.6,3]],"ltp":2.6,"tv":5314.15,"id":19931652},{"batb":[[1,1.2,100],[2,1.19,103]],"batl":[[1,2.1,7.95]],"ltp":1.62,"tv":20568.35,"id":8257797}]}]}
{"op":"mcm","clk":"4230545018","pt":1631534137509,"mc":[{"id":"1.187557146","rc":[{"batl":[[0,1.56,2],[1,1.7,45.08],[2,2.1,7.95]],"ltp":1.62,"tv":20568.35,"id":8257797}]}]}
{"op":"mcm","clk":"4230545135","pt":1631534138611,"mc":[{"id":"1.187557146","rc":[{"batl":[[0,990,0.01],[1,6.4,0],[2,6.6,0]],"ltp":2.6,"tv":5314.15,"id":19931652},{"batb":[[1,1.2,0],[2,1.19,0]],"ltp":1.62,"tv":20568.35,"id":8257797}]}]}
{"op":"mcm","clk":"4230545316","pt":1631534140301,"mc":[{"id":"1.187557146","rc":[{"trd":[[2.42,31.67],[2.78,96.68]],"batl":[[0,2.08,338.63],[1,2.12,16.11],[2,990,0.01]],"ltp":2.42,"tv":5346.94,"id":19931652},{"trd":[[1.56,173.07],[1.7,49.05]],"batb":[[0,1.86,155.29],[1,1.22,162.52]],"batl":[[0,1.96,11.8],[1,2.08,138.58]],"ltp":1.7,"tv":20615.43,"id":8257797}],"tv":25962.38}]}
{"op":"mcm","clk":"4230545409","pt":1631534141291,"mc":[{"id":"1.187557146","rc":[{"batb":[[2,1.71,38.83]],"batl":[[0,2.08,19.24],[1,990,0.01],[2,990,0]],"ltp":2.42,"tv":5346.94,"id":19931652},{"batb":[[0,1.86,183.49],[1,1.77,31.53],[2,1.75,15.95]],"batl":[[0,2.08,138.58],[1,2.1,7.95],[2,990,0.01]],"ltp":1.7,"tv":20615.43,"id":8257797}]}]}
{"op":"mcm","clk":"4230545582","pt":1631534143278,"mc":[{"id":"1.187557146","rc":[{"batl":[[1,2.12,16.11],[2,990,0.01]],"ltp":2.42,"tv":5346.94,"id":19931652},{"batl":[[0,1.96,11.8],[1,2.08,138.58],[2,2.1,7.95]],"ltp":1.7,"tv":20615.43,"id":8257797}]}]}
{"op":"mcm","clk":"4230545601","pt":1631534143490,"mc":[{"id":"1.187557146","rc":[{"batl":[[1,990,0.01],[2,990,0]],"ltp":2.42,"tv":5346.94,"id":19931652},{"batl":[[0,2.08,138.58],[1,2.1,7.95],[2,2.72,222.44]],"ltp":1.7,"tv":20615.43,"id":8257797}]}]}
{"op":"mcm","clk":"4230545963","pt":1631534147207,"mc":[{"id":"1.187557146","rc":[{"batb":[[2,1.79,32.31]],"batl":[[1,2.12,16.11],[2,2.42,4]],"ltp":2.42,"tv":5346.94,"id":19931652},{"batl":[[0,1.96,11.8],[1,2.08,138.58],[2,2.1,7.95]],"ltp":1.7,"tv":20615.43,"id":8257797}]}]}
{"op":"mcm","clk":"4230546250","pt":1631534150345,"mc":[{"id":"1.187557146","rc":[{"batb":[[0,1.93,102],[1,1.86,183.49],[2,1.77,31.53]],"ltp":1.7,"tv":20615.43,"id":8257797}]}]}
{"op":"mcm","clk":"4230546768","pt":1631534155015,"mc":[{"id":"1.187557146","rc":[{"trd":[[1.93,5.52]],"batb":[[0,1.93,99.24]],"ltp":1.93,"tv":20620.95,"id":8257797}],"tv":25967.9}]}
{"op":"mcm","clk":"4230546815","pt":1631534155431,"mc":[{"id":"1.187557146","rc":[{"batl":[[2,2.42,2]],"ltp":2.42,"tv":5346.94,"id":19931652}]}]}
{"op":"mcm","clk":"4230546975","pt":1631534157145,"mc":[{"id":"1.187557146","rc":[{"batl":[[2,3.1,3.45]],"ltp":2.42,"tv":5346.94,"id":19931652}]}]}
{"op":"mcm","clk":"4230547018","pt":1631534157615,"mc":[{"id":"1.187557146","rc":[{"batb":[[2,1.67,452.07]],"ltp":1.93,"tv":20620.95,"id":8257797}]}]}
{"op":"mcm","clk":"4230547388","pt":1631534161326,"mc":[{"id":"1.187557146","rc":[{"batb":[[0,1.72,32.34],[1,1.71,38.83],[2,1.25,20]],"batl":[[0,3.1,3.45],[1,3.95,2.9],[2,990,0.01]],"ltp":2.42,"tv":5346.94,"id":19931652},{"batb":[[0,1.67,452.07],[1,1.56,21.43],[2,1.52,55.98]],"batl":[[0,2.4,6.14],[1,2.72,222.44],[2,990,0.01]],"ltp":1.93,"tv":20620.95,"id":8257797}]}]}
{"op":"mcm","clk":"4230547663","pt":1631534164237,"mc":[{"id":"1.187557146","rc":[{"batb":[[0,1.79,31.31],[1,1.72,32.34],[2,1.71,38.83]],"ltp":2.42,"tv":5346.94,"id":19931652},{"batl":[[0,2.28,6.32],[1,2.4,6.14],[2,2.72,222.44]],"ltp":1.93,"tv":20620.95,"id":8257797}]}]}
{"op":"mcm","clk":"4230547710","pt":1631534164754,"mc":[{"id":"1.187557146","rc":[{"batb":[[0,1.72,32.34],[1,1.71,38.83],[2,1.25,20]],"ltp":2.42,"tv":5346.94,"id":19931652},{"batl":[[0,2.4,6.37],[1,2.72,222.44],[2,990,0.01]],"ltp":1.93,"tv":20620.95,"id":8257797}]}]}
{"op":"mcm","clk":"4230547823","pt":1631534166062,"mc":[{"id":"1.187557146","rc":[{"batl":[[0,2.4,6.14]],"ltp":1.93,"tv":20620.95,"id":8257797}]}]}
{"op":"mcm","clk":"4230547851","pt":1631534166378,"mc":[{"id":"1.187557146","rc":[{"batb":[[1,1.52,55.98],[2,1.48,48.26]],"ltp":1.93,"tv":20620.95,"id":8257797}]}]}
{"op":"mcm","clk":"4230548156","pt":1631534170051,"mc":[{"id":"1.187557146","rc":[{"batl":[[0,3.95,2.9],[1,990,0.01],[2,990,0]],"ltp":2.42,"tv":5346.94,"id":19931652},{"batb":[[0,1.52,55.98],[1,1.34,76.72],[2,1.33,0.09]],"batl":[[1,990,0.01],[2,990,0]],"ltp":1.93,"tv":20620.95,"id":8257797}]}]}
{"op":"mcm","clk":"4230548263","pt":1631534171356,"mc":[{"id":"1.187557146","rc":[{"trd":[[1.71,116.37],[1.72,107.95]],"batb":[[0,1.7,145.53],[1,1.57,52.3]],"batl":[[0,1.71,11.7],[1,1.83,19.37],[2,1.86,185.46]],"ltp":1.71,"tv":5514.18,"id":19931652},{"trd":[[2.4,26.77]],"batb":[[0,2.16,35.56],[1,1.83,29.29],[2,1.52,55.98]],"batl":[[0,990,0.01],[1,990,0]],"ltp":2.4,"tv":20627.09,"id":8257797}],"tv":26141.28}]}
{"op":"mcm","clk":"4230548285","pt":1631534171667,"mc":[{"id":"1.187557146","rc":[{"batb":[[2,1.34,76.72]],"batl":[[0,6,3],[1,6.4,3],[2,6.6,3]],"ltp":2.4,"tv":20627.09,"id":8257797}]}]}
{"op":"mcm","clk":"4230548508","pt":1631534174067,"mc":[{"id":"1.187557146","rc":[{"batb":[[1,1.86,432.2],[2,1.83,29.29]],"batl":[[0,3.3,178.59],[1,6,3],[2,6.4,3]],"ltp":2.4,"tv":20627.09,"id":8257797}]}]}
{"op":"mcm","clk":"4230548744","pt":1631534176992,"mc":[{"id":"1.187557146","rc":[{"batb":[[1,1.58,43.56],[2,1.57,52.3]],"ltp":1.71,"tv":5514.18,"id":19931652},{"batb":[[1,1.95,25.71],[2,1.86,432.2]],"batl":[[0,2.74,4.75],[1,2.86,4.75],[2,3.3,178.59]],"ltp":2.4,"tv":20627.09,"id":8257797}]}]}
{"op":"mcm","clk":"4230548828","pt":1631534177985,"mc":[{"id":"1.187557146","rc":[{"trd":[[1.71,123.61]],"batl":[[0,1.71,8.08]],"ltp":1.71,"tv":5521.42,"id":19931652}],"tv":26148.51}]}
{"op":"mcm","clk":"4230549087","pt":1631534181287,"mc":[{"id":"1.187557146","rc":[{"trd":[[1.71,124.23]],"batl":[[0,1.71,7.77],[1,1.86,185.46],[2,1.95,28.63]],"ltp":1.71,"tv":5522.04,"id":19931652}],"tv":26149.13}]}
{"op":"mcm","clk":"4230549208","pt":1631534182801,"mc":[{"id":"1.187557146","rc":[{"batl":[[1,1.86,190.44]],"ltp":1.71,"tv":5522.04,"id":19931652}]}]}
{"op":"mcm","clk":"4230549311","pt":1631534183799,"mc":[{"id":"1.187557146","rc":[{"trd":[[1.71,139.77]],"batb":[[0,1.76,4.26],[1,1.7,145.53],[2,1.58,43.56]],"batl":[[0,1.8,11.17]],"ltp":1.71,"tv":5537.58,"id":19931652}],"tv":26164.67}]}
{"op":"mcm","clk":"4230549519","pt":1631534185787,"mc":[{"id":"1.187557146","rc":[{"batl":[[0,2.4,4.51],[1,2.74,4.75],[2,2.86,4.75]],"ltp":2.4,"tv":20627.09,"id":8257797}]}]}
{"op":"mcm","clk":"4230549632","pt":1631534187299,"mc":[{"id":"1.187557146","rc":[{"batb":[[0,1.64,34.07],[1,1.59,42.11]],"batl":[[0,1.86,9.97],[1,1.95,28.63],[2,1.97,14.17]],"ltp":1.71,"tv":5537.58,"id":19931652},{"batb":[[2,1.87,30.27]],"batl":[[1,2.58,5.25],[2,2.7,4.95]],"ltp":2.4,"tv":20627.09,"id":8257797}]}]}
{"op":"mcm","clk":"4230549658","pt":1631534187666,"mc":[{"id":"1.187557146","rc":[{"batb":[[0,1.59,42.11],[1,1.57,52.3],[2,1.25,20]],"batl":[[1,2.16,7.72],[2,2.18,8.25]],"ltp":1.71,"tv":5537.58,"id":19931652},{"batb":[[0,1.87,30.27],[1,1.86,432.2],[2,1.85,28.77]],"batl":[[0,2.4,5.14],[1,2.7,4.95],[2,3.3,178.59]],"ltp":2.4,"tv":20627.09,"id":8257797}]}]}
{"op":"mcm","clk":"4230549890","pt":1631534190232,"mc":[{"id":"1.187557146","rc":[{"batl":[[0,2.7,5.58],[1,3.3,178.59],[2,6,3]],"ltp":2.4,"tv":20627.09,"id":8257797}]}]}
{"op":"mcm","clk":"4230550269","pt":1631534194284,"mc":[{"id":"1.187557146","rc":[{"batb":[[0,1.64,35.82],[1,1.59,42.11],[2,1.57,52.3]],"batl":[[1,2.06,8.25],[2,2.16,7.72]],"ltp":1.71,"tv":5537.58,"id":19931652},{"batb":[[0,1.95,25.11],[1,1.87,30.27],[2,1.86,432.2]],"batl":[[0,2.58,6.38],[1,2.7,4.95],[2,3.3,178.59]],"ltp":2.4,"tv":20627.09,"id":8257797}]}]}
{"op":"mcm","clk":"4230550369","pt":1631534195283,"mc":[{"id":"1.187557146","rc":[{"batb":[[0,1.59,42.11],[1,1.57,52.3],[2,1.25,20]],"batl":[[1,2.16,7.72],[2,2.18,8.25]],"ltp":1.71,"tv":5537.58,"id":19931652},{"batb":[[0,1.87,30.27],[1,1.86,432.2],[2,1.85,28.77]],"batl":[[0,2.7,4.95],[1,3.3,178.59],[2,990,0.01]],"ltp":2.4,"tv":20627.09,"id":8257797}]}]}
{"op":"mcm","clk":"4230550895","pt":1631534201340,"mc":[{"id":"1.187557146","rc":[{"batb":[[0,1.64,44.07],[1,1.59,42.11],[2,1.57,52.3]],"batl":[[1,2.06,7.92],[2,2.16,7.72]],"ltp":1.71,"tv":5537.58,"id":19931652},{"batb":[[0,1.95,25.71],[1,1.87,30.27],[2,1.86,432.2]],"batl":[[0,2.58,5.25],[1,2.7,4.95],[2,3.3,178.59]],"ltp":2.4,"tv":20627.09,"id":8257797}]}]}
{"op":"mcm","clk":"4230550918","pt":1631534201608,"mc":[{"id":"1.187557146","rc":[{"batb":[[0,1.59,42.11],[1,1.57,52.3],[2,1.25,20]],"batl":[[1,2.16,7.72],[2,2.18,8.25]],"ltp":1.71,"tv":5537.58,"id":19931652},{"batb":[[0,1.87,30.27],[1,1.86,432.2],[2,1.85,28.77]],"batl":[[0,2.7,4.95],[1,3.3,178.59],[2,990,0.01]],"ltp":2.4,"tv":20627.09,"id":8257797}]}]}
{"op":"mcm","clk":"4230551071","pt":1631534203232,"mc":[{"id":"1.187557146","rc":[{"batl":[[1,990,0.01],[2,2.18,0]],"ltp":1.71,"tv":5537.58,"id":19931652},{"batb":[[2,1.84,28.7]],"ltp":2.4,"tv":20627.09,"id":8257797}]}]}
{"op":"mcm","clk":"4230551389","pt":1631534206329,"mc":[{"id":"1.187557146","rc":[{"batb":[[1,1.58,128.1],[2,1.57,52.3]],"batl":[[0,1.64,11.72],[1,1.68,144.02],[2,1.69,23.66]],"ltp":1.71,"tv":5537.58,"id":19931652},{"batb":[[1,1.84,28.7],[2,1.84,0]],"batl":[[0,2.66,11.11],[1,2.7,4.95]],"ltp":2.4,"tv":20627.09,"id":8257797}]}]}
{"op":"mcm","clk":"4230551470","pt":1631534207121,"mc":[{"id":"1.187557146","rc":[{"batb":[[0,2.44,24.85],[1,2.18,33.89],[2,1.87,30.27]],"batl":[[2,6,3]],"ltp":2.4,"tv":20627.09,"id":8257797}]}]}
{"op":"mcm","clk":"4230551717","pt":1631534209752,"mc":[{"id":"1.187557146","rc":[{"batb":[[2,2.04,347.91]],"batl":[[2,3.9,139.88]],"ltp":2.4,"tv":20627.09,"id":8257797}]}]}
{"op":"mcm","clk":"4230552466","pt":1631534218071,"mc":[{"id":"1.187557146","rc":[{"trd":[[1.64,233.36],[1.68,52.27]],"batl":[[0,1.68,96.09],[1,1.69,23.66],[2,1.76,31.71]],"ltp":1.68,"tv":5597.23,"id":19931652},{"trd":[[2.46,32.74],[2.56,19.88]],"ltp":2.46,"tv":20667.34,"id":8257797}],"tv":26264.57}]}
{"op":"mcm","clk":"4230552642","pt":1631534219865,"mc":[{"id":"1.187557146","rc":[{"batb":[[0,1.64,7.55],[1,1.59,42.11],[2,1.58,128.1]],"ltp":1.68,"tv":5597.23,"id":19931652}]}]}
{"op":"mcm","clk":"4230552944","pt":1631534223089,"mc":[{"id":"1.187557146","rc":[{"batl":[[0,2.66,11.74]],"ltp":2.46,"tv":20667.34,"id":8257797}]}]}
{"op":"mcm","clk":"4230553333","pt":1631534227279,"mc":[{"id":"1.187557146","rc":[{"trd":[[1.64,249.45]],"batb":[[0,1.59,42.11],[1,1.58,128.1],[2,1.57,52.3]],"batl":[[0,1.62,267.06],[1,1.68,96.09],[2,1.69,23.66]],"ltp":1.64,"tv":5613.32,"id":19931652},{"trd":[[2.56,20.51],[2.66,100.18]],"batl":[[0,2.66,11.09]],"ltp":2.66,"tv":20668.01,"id":8257797}],"tv":26281.33}]}
{"op":"mcm","clk":"4230553433","pt":1631534228278,"mc":[{"id":"1.187557146","rc":[{"batl":[[0,2.7,4.95],[1,3.9,139.88],[2,6,3]],"ltp":2.66,"tv":20668.01,"id":8257797}]}]}
{"op":"mcm","clk":"4230553598","pt":1631534230000,"mc":[{"id":"1.187557146","rc":[{"trd":[[1.62,512.07]],"batl":[[0,1.62,186.82]],"ltp":1.62,"tv":5693.56,"id":19931652},{"trd":[[2.6,67.04]],"ltp":2.6,"tv":20718.01,"id":8257797}],"tv":26411.57}]}
{"op":"mcm","clk":"4230553722","pt":1631534231196,"mc":[{"id":"1.187557146","rc":[{"trd":[[1.62,536.56]],"batl":[[0,1.62,162.33],[1,1.66,14.82],[2,1.68,96.09]],"ltp":1.62,"tv":5718.05,"id":19931652},{"trd":[[2.6,82.3]],"ltp":2.6,"tv":20733.26,"id":8257797}],"tv":26451.31}]}
{"op":"mcm","clk":"4230553879","pt":1631534232671,"mc":[{"id":"1.187557146","rc":[{"trd":[[1.59,42.41]],"batb":[[0,1.58,128.1],[1,1.57,52.3],[2,1.4,82.26]],"batl":[[0,1.61,113],[1,1.62,162.33],[2,1.66,14.82]],"ltp":1.59,"tv":5760.16,"id":19931652},{"trd":[[2.7,34.69]],"batb":[[0,2.7,145.72],[1,2.44,24.85],[2,2.18,33.89]],"batl":[[0,3.9,139.88],[1,6,3],[2,6.4,3]],"ltp":2.7,"tv":20767.96,"id":8257797}],"tv":26528.12}]}
{"op":"mcm","clk":"4230554184","pt":1631534235876,"mc":[{"id":"1.187557146","rc":[{"batl":[[0,3.15,11.48],[1,3.9,139.88],[2,6,3]],"ltp":2.7,"tv":20767.96,"id":8257797}]}]}
{"op":"mcm","clk":"4230554430","pt":1631534238206,"mc":[{"id":"1.187557146","rc":[{"batl":[[2,1.68,96.09]],"ltp":1.59,"tv":5760.16,"id":19931652},{"trd":[[2.7,35]],"batb":[[0,2.7,145.57]],"ltp":2.7,"tv":20768.26,"id":8257797}],"tv":26528.43}]}
{"op":"mcm","clk":"4230554726","pt":1631534241295,"mc":[{"id":"1.187557146","rc":[{"trd":[[2.7,57.37]],"batb":[[0,2.7,134.39]],"ltp":2.7,"tv":20790.63,"id":8257797}],"tv":26550.79}]}
{"op":"mcm","clk":"4230554995","pt":1631534244324,"mc":[{"id":"1.187557146","rc":[{"batl":[[1,1.62,176.94]],"ltp":1.59,"tv":5760.16,"id":19931652},{"batl":[[0,2.72,10.48],[1,3.15,11.48],[2,3.9,139.88]],"ltp":2.7,"tv":20790.63,"id":8257797}]}]}
{"op":"mcm","clk":"4230555060","pt":1631534245007,"mc":[{"id":"1.187557146","rc":[{"batl":[[1,1.62,14.61]],"ltp":1.59,"tv":5760.16,"id":19931652},{"batl":[[1,3.9,139.88],[2,6,3]],"ltp":2.7,"tv":20790.63,"id":8257797}]}]}
{"op":"mcm","clk":"4230555355","pt":1631534248118,"mc":[{"id":"1.187557146","rc":[{"trd":[[1.58,274.24]],"batb":[[0,1.57,52.3],[1,1.4,82.26],[2,1.25,20]],"batl":[[0,1.58,16.19],[1,1.61,113],[2,1.62,14.61]],"ltp":1.58,"tv":6034.4,"id":19931652},{"trd":[[2.72,10.48]],"batl":[[0,3.9,139.88],[1,6,3],[2,6.4,3]],"ltp":2.72,"tv":20801.11,"id":8257797}],"tv":26835.51}]}
{"op":"mcm","clk":"4230555402","pt":1631534248736,"mc":[{"id":"1.187557146","rc":[{"trd":[[1.58,275.33]],"batl":[[0,1.58,15.11],[1,1.62,14.61],[2,1.68,96.09]],"ltp":1.58,"tv":6035.48,"id":19931652},{"trd":[[2.72,11.11]],"ltp":2.72,"tv":20801.74,"id":8257797}],"tv":26837.23}]}
{"op":"mcm","clk":"4230555652","pt":1631534251317,"mc":[{"id":"1.187557146","rc":[{"trd":[[1.58,282.16]],"batl":[[0,1.58,8.27],[1,1.68,96.09],[2,1.69,23.66]],"ltp":1.58,"tv":6042.32,"id":19931652},{"trd":[[2.72,15.08]],"batl":[[0,3.8,9.59],[1,3.9,139.88],[2,6,3]],"ltp":2.72,"tv":20805.71,"id":8257797}],"tv":26848.03}]}
{"op":"mcm","clk":"4230555686","pt":1631534251642,"mc":[{"id":"1.187557146","rc":[{"batl":[[0,1.58,282.27]],"ltp":1.58,"tv":6042.32,"id":19931652},{"batl":[[0,3.9,139.88],[1,6,3],[2,6.4,3]],"ltp":2.72,"tv":20805.71,"id":8257797}]}]}
{"op":"mcm","clk":"4230555887","pt":1631534253606,"mc":[{"id":"1.187557146","rc":[{"batl":[[1,1.6,16.02],[2,1.68,96.09]],"ltp":1.58,"tv":6042.32,"id":19931652},{"batl":[[0,2.78,10.12],[1,3.9,139.88],[2,6,3]],"ltp":2.72,"tv":20805.71,"id":8257797}]}]}
{"op":"mcm","clk":"4230556315","pt":1631534258253,"mc":[{"id":"1.187557146","rc":[{"batl":[[0,1.58,274],[1,1.68,96.09],[2,1.69,23.66]],"ltp":1.58,"tv":6042.32,"id":19931652},{"batl":[[0,3.9,139.88],[1,6,3],[2,6.4,3]],"ltp":2.72,"tv":20805.71,"id":8257797}]}]}
{"op":"mcm","clk":"4230556598","pt":1631534261245,"mc":[{"id":"1.187557146","rc":[{"batl":[[1,1.6,16.02],[2,1.68,96.09]],"ltp":1.58,"tv":6042.32,"id":19931652},{"batl":[[0,2.78,10.12],[1,3.9,139.88],[2,6,3]],"ltp":2.72,"tv":20805.71,"id":8257797}]}]}
{"op":"mcm","clk":"4230557098","pt":1631534266668,"mc":[{"id":"1.187557146","rc":[{"trd":[[1.57,117.96]],"batb":[[0,1.4,82.26],[1,1.25,20],[2,1.2,100]],"batl":[[0,1.57,16.6],[1,1.58,274],[2,1.6,16.02]],"ltp":1.57,"tv":6146.92,"id":19931652}],"tv":26952.63}]}
{"op":"mcm","clk":"4230557334","pt":1631534269258,"mc":[{"id":"1.187557146","rc":[{"trd":[[1.57,134.56],[1.58,556.16]],"batl":[[0,1.6,16.02],[1,1.68,96.09],[2,1.69,23.66]],"ltp":1.58,"tv":6437.52,"id":19931652},{"trd":[[2.7,114.06],[2.72,174.25],[2.74,9.51]],"batb":[[0,2.7,106.04]],"ltp":2.7,"tv":21031.08,"id":8257797}],"tv":27468.61}]}
{"op":"mcm","clk":"4230558570","pt":1631534283174,"mc":[{"id":"1.187557146","rc":[{"trd":[[1.56,17.71]],"batl":[[0,1.59,132],[1,1.6,16.02],[2,1.68,96.09]],"ltp":1.56,"tv":6450.88,"id":19931652},{"trd":[[2.78,7.5]],"batl":[[0,2.78,2.62]],"ltp":2.78,"tv":21038.58,"id":8257797}],"tv":27489.47}]}
{"op":"mcm","clk":"4230559491","pt":1631534293295,"mc":[{"id":"1.187557146","rc":[{"batl":[[0,1.68,96.09],[1,1.69,23.66],[2,1.86,12.53]],"ltp":1.56,"tv":6450.88,"id":19931652},{"batl":[[0,3.9,139.88],[1,6,3],[2,6.4,3]],"ltp":2.78,"tv":21038.58,"id":8257797}]}]}
{"op":"mcm","clk":"4230559787","pt":1631534296298,"mc":[{"id":"1.187557146","rc":[{"batl":[[0,1.58,11.93],[1,1.68,96.09],[2,1.69,23.66]],"ltp":1.56,"tv":6450.88,"id":19931652},{"batl":[[0,2.84,12.23],[1,3.9,139.88],[2,6,3]],"ltp":2.78,"tv":21038.58,"id":8257797}]}]}
{"op":"mcm","clk":"4230559853","pt":1631534297095,"mc":[{"id":"1.187557146","rc":[{"batl":[[0,1.86,12.53],[1,990,0.01],[2,1.69,0]],"ltp":1.56,"tv":6450.88,"id":19931652},{"batb":[[1,2.18,33.89],[2,2.04,347.91]],"batl":[[0,3.9,139.88],[1,6,3],[2,6.4,3]],"ltp":2.78,"tv":21038.58,"id":8257797}]}]}
{"op":"mcm","clk":"4230560119","pt":1631534300308,"mc":[{"id":"1.187557146","rc":[{"batb":[[0,1.39,84.02]],"ltp":1.56,"tv":6450.88,"id":19931652},{"batb":[[1,2.2,33.05]],"ltp":2.78,"tv":21038.58,"id":8257797}]}]}
{"op":"mcm","clk":"4230560441","pt":1631534303831,"mc":[{"id":"1.187557146","rc":[{"batb":[[2,2.04,0]],"batl":[[0,6,3],[1,6.4,3],[2,6.6,3]],"ltp":2.78,"tv":21038.58,"id":8257797}]}]}
{"op":"mcm","clk":"4230560588","pt":1631534305314,"mc":[{"id":"1.187557146","rc":[{"batb":[[0,1.41,215.11],[1,1.39,84.02],[2,1.25,20]],"batl":[[0,1.43,12.58],[1,1.5,93.62],[2,1.86,12.53]],"ltp":1.56,"tv":6450.88,"id":19931652},{"batb":[[0,3.05,65.58],[1,3,46.81],[2,2.7,106.04]],"ltp":2.78,"tv":21038.58,"id":8257797}]}]}
{"op":"mcm","clk":"4230560708","pt":1631534306324,"mc":[{"id":"1.187557146","rc":[{"batl":[[2,1.57,35.55]],"ltp":1.56,"tv":6450.88,"id":19931652},{"batb":[[0,3.05,13.12],[1,3,82.71]],"ltp":2.78,"tv":21038.58,"id":8257797}]}]}
{"op":"mcm","clk":"4230560841","pt":1631534307619,"mc":[{"id":"1.187557146","rc":[{"batl":[[0,4.9,133.75],[1,6,3],[2,6.4,3]],"ltp":2.78,"tv":21038.58,"id":8257797}]}]}
{"op":"mcm","clk":"4230561532","pt":1631534314943,"mc":[{"id":"1.187557146","rc":[{"batb":[[0,1.25,20],[1,1.24,147.53],[2,1.2,100]],"batl":[[0,1.61,39.5],[1,1.67,35.5],[2,1.86,12.53]],"ltp":1.56,"tv":6450.88,"id":19931652},{"batb":[[0,2.7,106.04],[1,2.62,5.04],[2,2.54,22.26]],"ltp":2.78,"tv":21038.58,"id":8257797}]}]}
{"op":"mcm","clk":"4230561597","pt":1631534315738,"mc":[{"id":"1.187557146","rc":[{"batl":[[0,3.3,3.61],[1,4.9,133.75],[2,6,3]],"ltp":2.78,"tv":21038.58,"id":8257797}]}]}
{"op":"mcm","clk":"4230561783","pt":1631534317840,"mc":[{"id":"1.187557146","rc":[{"trd":[[1.43,8.33]],"ltp":1.43,"tv":6459.21,"id":19931652},{"trd":[[3.3,3.61]],"batl":[[0,4.9,133.75],[1,6,3],[2,6.4,3]],"ltp":3.3,"tv":21042.19,"id":8257797}],"tv":27501.41}]}
{"op":"mcm","clk":"4230562227","pt":1631534323425,"mc":[{"id":"1.187557146","rc":[{"batb":[[0,1.26,3.62],[1,1.25,20],[2,1.24,147.53]],"ltp":1.43,"tv":6459.21,"id":19931652}]}]}
{"op":"mcm","clk":"4230562544","pt":1631534327474,"mc":[{"id":"1.187557146","rc":[{"batl":[[0,6,3],[1,6.4,3],[2,6.6,3]],"ltp":3.3,"tv":21042.19,"id":8257797}]}]}
{"op":"mcm","clk":"4230562653","pt":1631534329355,"mc":[{"id":"1.187557146","rc":[{"trd":[[1.56,36.9]],"batl":[[1,1.64,177.98],[2,1.67,35.5]],"ltp":1.56,"tv":6478.4,"id":19931652},{"trd":[[2.76,10.85]],"batl":[[0,2.76,14.5],[1,2.88,86.63],[2,2.92,10.2]],"ltp":2.76,"tv":21053.04,"id":8257797}],"tv":27531.45}]}
{"op":"mcm","clk":"4230562740","pt":1631534330344,"mc":[{"id":"1.187557146","rc":[{"batb":[[0,1.53,58.49],[1,1.34,99.33],[2,1.26,3.62]],"ltp":1.56,"tv":6478.4,"id":19931652}]}]}
{"op":"mcm","clk":"4230563122","pt":1631534334269,"mc":[{"id":"1.187557146","rc":[{"trd":[[1.56,38.44]],"batb":[[2,1.25,20]],"ltp":1.56,"tv":6479.95,"id":19931652},{"trd":[[2.76,11.72]],"batl":[[0,2.76,13.63]],"ltp":2.76,"tv":21053.91,"id":8257797}],"tv":27533.87}]}
{"op":"mcm","clk":"4230563272","pt":1631534335891,"mc":[{"id":"1.187557146","rc":[{"trd":[[1.56,47.44]],"ltp":1.56,"tv":6488.95,"id":19931652},{"trd":[[2.76,16.81]],"batl":[[0,2.76,8.54]],"ltp":2.76,"tv":21059.0,"id":8257797}],"tv":27547.96}]}
{"op":"mcm","clk":"4230563397","pt":1631534337251,"mc":[{"id":"1.187557146","rc":[{"batb":[[2,1.26,7.03]],"batl":[[0,1.59,61],[1,1.61,39.5],[2,1.64,177.98]],"ltp":1.56,"tv":6488.95,"id":19931652}]}]}
{"op":"mcm","clk":"4230563547","pt":1631534339288,"mc":[{"id":"1.187557146","rc":[{"batl":[[2,3.9,167.24]],"ltp":2.76,"tv":21059.0,"id":8257797}]}]}
{"op":"mcm","clk":"4230563651","pt":1631534340289,"mc":[{"id":"1.187557146","rc":[{"batl":[[0,1.61,39.5],[1,1.67,35.5],[2,1.72,33.91]],"ltp":1.56,"tv":6488.95,"id":19931652},{"batl":[[0,3.9,167.24],[1,6,3],[2,6.4,3]],"ltp":2.76,"tv":21059.0,"id":8257797}]}]}
{"op":"mcm","clk":"4230563696","pt":1631534340769,"mc":[{"id":"1.187557146","rc":[{"batb":[[0,1.34,99.33],[1,1.26,7.03],[2,1.25,20]],"batl":[[0,1.72,33.91],[1,1.77,29.63],[2,1.86,2.56]],"ltp":1.56,"tv":6488.95,"id":19931652},{"batb":[[1,2.38,5.96],[2,2.22,32.8]],"ltp":2.76,"tv":21059.0,"id":8257797}]}]}
{"op":"mcm","clk":"4230563813","pt":1631534342192,"mc":[{"id":"1.187557146","rc":[{"batl":[[0,1.58,18.05],[1,1.72,33.91],[2,1.77,29.63]],"ltp":1.56,"tv":6488.95,"id":19931652},{"batl":[[0,2.84,8.65],[1,3.9,167.24],[2,6,3]],"ltp":2.76,"tv":21059.0,"id":8257797}]}]}
{"op":"mcm","clk":"4230563900","pt":1631534342984,"mc":[{"id":"1.187557146","rc":[{"batl":[[0,1.72,33.91],[1,1.77,29.63],[2,1.86,2.56]],"ltp":1.56,"tv":6488.95,"id":19931652},{"batl":[[0,3.9,167.24],[1,6,3],[2,6.4,3]],"ltp":2.76,"tv":21059.0,"id":8257797}]}]}
{"op":"mcm","clk":"4230563959","pt":1631534343677,"mc":[{"id":"1.187557146","rc":[{"batb":[[2,2.28,6.91]],"ltp":2.76,"tv":21059.0,"id":8257797}]}]}
{"op":"mcm","clk":"4230564700","pt":1631534351587,"mc":[{"id":"1.187557146","rc":[{"batl":[[1,990,0.01],[2,6.4,0]],"ltp":2.76,"tv":21059.0,"id":8257797}]}]}
{"op":"mcm","clk":"4230564848","pt":1631534353314,"mc":[{"id":"1.187557146","rc":[{"batl":[[0,1.72,45.11],[2,1.8,154.75]],"ltp":1.56,"tv":6488.95,"id":19931652},{"trd":[[2.7,326.15]],"batb":[[0,2.38,5.96],[1,2.28,6.91],[2,2.22,32.8]],"batl":[[0,2.46,8.57],[1,2.5,76.82],[2,990,0.01]],"ltp":2.7,"tv":21271.09,"id":8257797}],"tv":27760.05}]}
{"op":"mcm","clk":"4230564940","pt":1631534354303,"mc":[{"id":"1.187557146","rc":[{"batb":[[0,1.68,41.76],[1,1.49,63.35],[2,1.34,99.33]],"batl":[[0,1.72,11.2]],"ltp":1.56,"tv":6488.95,"id":19931652},{"batb":[[0,2.28,6.91],[1,2.22,32.8],[2,2,43.6]],"ltp":2.7,"tv":21271.09,"id":8257797}]}]}
{"op":"mcm","clk":"4230564962","pt":1631534354509,"mc":[{"id":"1.187557146","rc":[{"batb":[[2,1.26,7.03]],"ltp":1.56,"tv":6488.95,"id":19931652}]}]}
{"op":"mcm","clk":"4230565179","pt":1631534357088,"mc":[{"id":"1.187557146","rc":[{"batl":[[2,3.3,202.14]],"ltp":2.7,"tv":21271.09,"id":8257797}]}]}
{"op":"mcm","clk":"4230565530","pt":1631534360184,"mc":[{"id":"1.187557146","rc":[{"batb":[[1,1.54,45.12],[2,1.49,115.36]],"ltp":1.56,"tv":6488.95,"id":19931652},{"batb":[[2,2.2,7.27]],"batl":[[2,2.7,9.02]],"ltp":2.7,"tv":21271.09,"id":8257797}]}]}
{"op":"mcm","clk":"4230565592","pt":1631534361016,"mc":[{"id":"1.187557146","rc":[{"batl":[[2,2.7,11.02]],"ltp":2.7,"tv":21271.09,"id":8257797}]}]}
{"op":"mcm","clk":"4230566059","pt":1631534365312,"mc":[{"id":"1.187557146","rc":[{"batl":[[2,2.7,2]],"ltp":2.7,"tv":21271.09,"id":8257797}]}]}
{"op":"mcm","clk":"4230566096","pt":1631534365733,"mc":[{"id":"1.187557146","rc":[{"trd":[[1.72,108.19]],"batl":[[0,1.72,11.08]],"ltp":1.72,"tv":6489.2,"id":19931652}],"tv":27760.29}]}
{"op":"mcm","clk":"4230566180","pt":1631534366626,"mc":[{"id":"1.187557146","rc":[{"batl":[[2,2.86,4.75]],"ltp":2.7,"tv":21271.09,"id":8257797}]}]}
{"op":"mcm","clk":"4230567044","pt":1631534375330,"mc":[{"id":"1.187557146","rc":[{"batl":[[0,1.87,29.5],[1,1.92,29.07],[2,1.94,14.38]],"ltp":1.72,"tv":6489.2,"id":19931652},{"batb":[[0,2.22,32.8],[1,2,43.6],[2,1.86,390.87]],"batl":[[0,2.86,4.75],[1,3.05,4.1],[2,3.3,202.14]],"ltp":2.7,"tv":21271.09,"id":8257797}]}]}
{"op":"mcm","clk":"4230567132","pt":1631534376123,"mc":[{"id":"1.187557146","rc":[{"batb":[[0,1.49,115.36],[1,1.26,7.03],[2,1.25,20]],"batl":[[1,990,0.01],[2,1.94,0]],"ltp":1.72,"tv":6489.2,"id":19931652},{"batb":[[0,2,43.6],[1,1.86,390.87],[2,1.86,0]],"batl":[[0,3.05,4.1],[1,3.3,202.14],[2,990,0.01]],"ltp":2.7,"tv":21271.09,"id":8257797}]}]}
{"op":"mcm","clk":"4230567368","pt":1631534378867,"mc":[{"id":"1.187557146","rc":[{"batb":[[0,2.14,6.82],[1,2,43.6],[2,1.86,390.87]],"ltp":2.7,"tv":21271.09,"id":8257797}]}]}
{"op":"mcm","clk":"4230568474","pt":1631534389159,"mc":[{"id":"1.187557146","rc":[{"batl":[[0,1.83,32.5],[1,1.87,29.5],[2,990,0.01]],"ltp":1.72,"tv":6489.2,"id":19931652},{"batb":[[0,2.2,6.67],[1,2.14,6.82],[2,2,43.6]],"ltp":2.7,"tv":21271.09,"id":8257797}]}]}
{"op":"mcm","clk":"4230568564","pt":1631534390162,"mc":[{"id":"1.187557146","rc":[{"batl":[[0,1.87,29.5],[1,990,0.01],[2,990,0]],"ltp":1.72,"tv":6489.2,"id":19931652},{"batb":[[0,2.14,6.82],[1,2,43.6],[2,1.86,390.87]],"ltp":2.7,"tv":21271.09,"id":8257797}]}]}
{"op":"mcm","clk":"4230568812","pt":1631534393270,"mc":[{"id":"1.187557146","rc":[{"batb":[[0,1.77,113],[1,1.68,456.72],[2,1.49,115.36]],"batl":[[0,1.86,12.47],[1,1.87,29.5],[2,1.92,114.83]],"ltp":1.72,"tv":6489.2,"id":19931652},{"batl":[[0,2.24,12.65],[1,3.05,4.1]],"ltp":2.7,"tv":21271.09,"id":8257797}]}]}
{"op":"mcm","clk":"4230568913","pt":1631534394273,"mc":[{"id":"1.187557146","rc":[{"batb":[[0,1.82,32.05],[1,1.77,22.6],[2,1.69,40.92]],"ltp":1.72,"tv":6489.2,"id":19931652},{"batb":[[2,1.91,51.3]],"batl":[[1,2.86,4.75],[2,3.05,4.1]],"ltp":2.7,"tv":21271.09,"id":8257797}]}]}
{"op":"mcm","clk":"4230569169","pt":1631534396963,"mc":[{"id":"1.187557146","rc":[{"batl":[[2,2.92,232.38]],"ltp":2.7,"tv":21271.09,"id":8257797}]}]}
{"op":"mcm","clk":"4230569460","pt":1631534400077,"mc":[{"id":"1.187557146","rc":[{"batb":[[2,1.72,33.84]],"batl":[[2,1.91,26.61]],"ltp":1.72,"tv":6489.2,"id":19931652},{"batb":[[1,2.08,7.56],[2,2.06,8.08]],"batl":[[1,2.4,5.64],[2,2.48,5.74]],"ltp":2.7,"tv":21271.09,"id":8257797}]}]}
{"op":"mcm","clk":"4230569595","pt":1631534401310,"mc":[{"id":"1.187557146","rc":[{"batb":[[1,1.72,33.84],[2,1.69,40.92]],"ltp":1.72,"tv":6489.2,"id":19931652}]}]}
{"op":"mcm","clk":"4230569669","pt":1631534402011,"mc":[{"id":"1.187557146","rc":[{"batb":[[0,1.69,40.92],[1,1.68,39.86],[2,1.49,52.01]],"batl":[[0,1.94,27.25],[1,990,0.1],[2,1.91,0]],"ltp":1.72,"tv":6489.2,"id":19931652},{"batb":[[0,1.91,51.3],[1,1.86,390.87],[2,2.06,0]],"batl":[[0,2.92,232.38],[1,3.05,4.1],[2,990,0.01]],"ltp":2.7,"tv":21271.09,"id":8257797}]}]}
{"op":"mcm","clk":"4230570012","pt":1631534405113,"mc":[{"id":"1.187557146","rc":[{"batl":[[0,1.94,27.48]],"ltp":1.72,"tv":6489.2,"id":19931652},{"batb":[[0,2.06,7.08],[1,1.91,51.3],[2,1.86,390.87]],"batl":[[0,2.48,5.24],[1,2.92,232.38],[2,3.05,4.1]],"ltp":2.7,"tv":21271.09,"id":8257797}]}]}
{"op":"mcm","clk":"4230570057","pt":1631534405484,"mc":[{"id":"1.187557146","rc":[{"batl":[[1,990,0.01]],"ltp":1.72,"tv":6489.2,"id":19931652}]}]}
{"op":"mcm","clk":"4230570495","pt":1631534409708,"mc":[{"id":"1.187557146","rc":[{"batb":[[2,1.59,1.7]],"ltp":1.72,"tv":6489.2,"id":19931652},{"batb":[[2,1.86,0]],"ltp":2.7,"tv":21271.09,"id":8257797}]}]}
{"op":"mcm","clk":"4230570645","pt":1631534411194,"mc":[{"id":"1.187557146","rc":[{"trd":[[1.82,0.57]],"batb":[[0,1.88,21.28],[1,1.69,40.92],[2,1.68,39.86]],"batl":[[0,1.94,27.25],[1,1.98,75.33],[2,990,0.01]],"ltp":1.82,"tv":6489.66,"id":19931652},{"batb":[[0,2.08,6.78],[1,2.06,7.08],[2,1.91,51.3]],"batl":[[0,2.12,7.03],[1,2.16,111.01],[2,2.48,5.24]],"ltp":2.7,"tv":21271.09,"id":8257797}],"tv":27760.76}]}
{"op":"mcm","clk":"4230570723","pt":1631534412110,"mc":[{"id":"1.187557146","rc":[{"batb":[[0,1.91,27.45],[1,1.88,21.28],[2,1.73,37.49]],"batl":[[2,6,3]],"ltp":1.82,"tv":6489.66,"id":19931652}]}]}
{"op":"mcm","clk":"4230571276","pt":1631534417540,"mc":[{"id":"1.187557146","rc":[{"batl":[[2,2.38,6.75]],"ltp":1.82,"tv":6489.66,"id":19931652}]}]}
{"op":"mcm","clk":"4230571673","pt":1631534422013,"mc":[{"id":"1.187557146","rc":[{"trd":[[1.91,36.09]],"batb":[[0,1.91,9.4]],"ltp":1.91,"tv":6525.75,"id":19931652}],"tv":27796.85}]}
{"op":"mcm","clk":"4230572309","pt":1631534428155,"mc":[{"id":"1.187557146","rc":[{"batl":[[0,1.94,27.34]],"ltp":1.91,"tv":6525.75,"id":19931652}]}]}
{"op":"mcm","clk":"4230572525","pt":1631534430261,"mc":[{"id":"1.187557146","rc":[{"trd":[[1.86,46.84],[1.88,42.56],[1.89,21.23],[1.91,54.88]],"batb":[[0,1.73,37.49],[1,1.68,39.86],[2,1.59,1.7]],"batl":[[0,1.94,27.25]],"ltp":1.86,"tv":6626.32,"id":19931652},{"trd":[[2.12,18.44],[2.16,40.01]],"batl":[[0,2.16,84.03],[1,2.48,5.24],[2,2.92,232.38]],"ltp":2.16,"tv":21305.1,"id":8257797}],"tv":27931.42}]}
{"op":"mcm","clk":"4230572855","pt":1631534434249,"mc":[{"id":"1.187557146","rc":[{"batb":[[1,1.59,1.7],[2,1.26,7.03]],"batl":[[0,1.91,1.53],[1,2.38,6.75],[2,2.52,4.76]],"ltp":1.86,"tv":6626.32,"id":19931652},{"batb":[[0,1.91,51.3],[1,1.82,30.67],[2,1.8,15.5]],"batl":[[0,2.92,232.38],[1,990,0.01],[2,2.92,0]],"ltp":2.16,"tv":21305.1,"id":8257797}]}]}
{"op":"mcm","clk":"4230572886","pt":1631534434558,"mc":[{"id":"1.187557146","rc":[{"batb":[[0,1.73,33.13],[1,1.7,394.89],[2,1.66,33.28]],"ltp":2.16,"tv":21305.1,"id":8257797}]}]}
{"op":"mcm","clk":"4230573144","pt":1631534437157,"mc":[{"id":"1.187557146","rc":[{"trd":[[1.91,56.04]],"batl":[[0,2.38,7.7],[1,2.52,4.76],[2,2.54,6.25]],"ltp":1.91,"tv":6627.48,"id":19931652}],"tv":27932.58}]}
{"op":"mcm","clk":"4230573216","pt":1631534437880,"mc":[{"id":"1.187557146","rc":[{"batb":[[0,1.72,37.99]],"batl":[[0,2.52,5.71],[1,2.54,6.25],[2,6,3]],"ltp":1.91,"tv":6627.48,"id":19931652},{"batb":[[0,1.7,394.89],[1,1.66,33.28],[2,1.65,79.2]],"ltp":2.16,"tv":21305.1,"id":8257797}]}]}
{"op":"mcm","clk":"4230573360","pt":1631534439260,"mc":[{"id":"1.187557146","rc":[{"trd":[[1.91,56.99]],"batl":[[0,2.52,4.76]],"ltp":1.91,"tv":6628.43,"id":19931652},{"trd":[[2.08,72.1]],"batl":[[0,2,343.62],[1,2.92,232.38],[2,990,0.01]],"ltp":2.08,"tv":21305.98,"id":8257797}],"tv":27934.41}]}
{"op":"mcm","clk":"4230573484","pt":1631534440352,"mc":[{"id":"1.187557146","rc":[{"batb":[[0,1.72,35.09],[1,1.7,394.89],[2,1.66,33.28]],"ltp":2.08,"tv":21305.98,"id":8257797}]}]}
{"op":"mcm","clk":"4230573583","pt":1631534441357,"mc":[{"id":"1.187557146","rc":[{"batb":[[0,1.7,394.89],[1,1.66,33.28],[2,1.65,79.2]],"batl":[[0,990,0.01],[1,2.92,0],[2,990,0]],"ltp":2.08,"tv":21305.98,"id":8257797}]}]}
{"op":"mcm","clk":"4230573674","pt":1631534442253,"mc":[{"id":"1.187557146","rc":[{"batb":[[0,1.9,37.86],[1,1.72,37.99],[2,1.59,1.7]],"batl":[[0,1.98,42.75],[1,2.52,4.76],[2,2.54,6.25]],"ltp":1.91,"tv":6628.43,"id":19931652},{"batl":[[0,2.12,41.21],[1,2.14,234.13],[2,990,0.01]],"ltp":2.08,"tv":21305.98,"id":8257797}]}]}
{"op":"mcm","clk":"4230573694","pt":1631534442464,"mc":[{"id":"1.187557146","rc":[{"batb":[[0,1.72,37.99],[1,1.59,1.7],[2,1.26,7.03]],"batl":[[0,2.52,4.76],[1,2.54,6.25],[2,6,3]],"ltp":1.91,"tv":6628.43,"id":19931652},{"batl":[[0,990,0.01],[1,2.14,0],[2,990,0]],"ltp":2.08,"tv":21305.98,"id":8257797}]}]}
{"op":"mcm","clk":"4230573854","pt":1631534444168,"mc":[{"id":"1.187557146","rc":[{"batl":[[0,2.4,5.34],[1,2.52,4.76],[2,2.54,6.25]],"ltp":1.91,"tv":6628.43,"id":19931652},{"trd":[[1.72,0.02]],"ltp":1.72,"tv":21306.0,"id":8257797}],"tv":27934.43}]}
{"op":"mcm","clk":"4230573890","pt":1631534444675,"mc":[{"id":"1.187557146","rc":[{"batl":[[0,2.52,4.76],[1,2.54,6.25],[2,6,3]],"ltp":1.91,"tv":6628.43,"id":19931652},{"batl":[[0,2.72,241.76],[1,990,0.01]],"ltp":1.72,"tv":21306.0,"id":8257797}]}]}
{"op":"mcm","clk":"4230574130","pt":1631534447066,"mc":[{"id":"1.187557146","rc":[{"batl":[[0,2.38,6.75],[1,2.52,4.76],[2,2.54,6.25]],"ltp":1.91,"tv":6628.43,"id":19931652}]}]}
{"op":"mcm","clk":"4230574247","pt":1631534448179,"mc":[{"id":"1.187557146","rc":[{"batl":[[0,2.52,4.76],[1,2.54,6.25],[2,6,3]],"ltp":1.91,"tv":6628.43,"id":19931652}]}]}
{"op":"mcm","clk":"4230575261","pt":1631534460191,"mc":[{"id":"1.187557146","rc":[{"batl":[[0,2.54,6.25],[1,6,3],[2,6.4,3]],"ltp":1.91,"tv":6628.43,"id":19931652},{"batb":[[0,1.65,79.2],[1,1.2,100],[2,1.19,103]],"batl":[[0,990,0.01],[1,990,0]],"ltp":1.72,"tv":21306.0,"id":8257797}]}]}
{"op":"mcm","clk":"4230575367","pt":1631534461289,"mc":[{"id":"1.187557146","rc":[{"batl":[[0,2.28,10.11],[1,2.42,122.3],[2,2.54,6.25]],"ltp":1.91,"tv":6628.43,"id":19931652},{"batl":[[0,1.83,13.34],[1,1.87,106.96],[2,2.2,283.59]],"ltp":1.72,"tv":21306.0,"id":8257797}]}]}
{"op":"mcm","clk":"4230575472","pt":1631534462301,"mc":[{"id":"1.187557146","rc":[{"batb":[[0,2.26,32.89],[1,1.94,51.21],[2,1.59,1.7]],"ltp":1.91,"tv":6628.43,"id":19931652},{"batb":[[1,1.58,35.33],[2,1.56,17.89]],"batl":[[1,1.87,21.4]],"ltp":1.72,"tv":21306.0,"id":8257797}]}]}
{"op":"mcm","clk":"4230576174","pt":1631534469023,"mc":[{"id":"1.187557146","rc":[{"trd":[[2.28,29.88]],"batl":[[0,2.42,122.3],[1,2.54,6.25],[2,3.45,3.3]],"ltp":2.28,"tv":6638.54,"id":19931652},{"trd":[[1.78,89.11]],"batl":[[0,1.76,538.21],[1,1.83,13.34],[2,1.87,21.4]],"ltp":1.78,"tv":21318.99,"id":8257797}],"tv":27957.53}]}
{"op":"mcm","clk":"4230576239","pt":1631534469614,"mc":[{"id":"1.187557146","rc":[{"trd":[[1.76,69.35]],"batl":[[0,1.76,538.12]],"ltp":1.76,"tv":21319.18,"id":8257797}],"tv":27957.72}]}
{"op":"mcm","clk":"4230576375","pt":1631534471026,"mc":[{"id":"1.187557146","rc":[{"batb":[[0,1.94,51.21],[1,1.59,1.7],[2,1.26,7.03]],"batl":[[0,3.45,3.3],[1,4.5,2.23],[2,6,3]],"ltp":2.28,"tv":6638.54,"id":19931652},{"batb":[[0,1.55,404.3],[1,1.41,61.89],[2,1.4,79.91]],"batl":[[1,2.42,286.96],[2,990,0.01]],"ltp":1.76,"tv":21319.18,"id":8257797}]}]}
{"op":"mcm","clk":"4230576460","pt":1631534471920,"mc":[{"id":"1.187557146","rc":[{"trd":[[2.3,0.09]],"ltp":2.3,"tv":6638.63,"id":19931652},{"trd":[[1.76,69.47]],"batl":[[0,1.76,537.99]],"ltp":1.76,"tv":21319.3,"id":8257797}],"tv":27957.93}]}
{"op":"mcm","clk":"4230576619","pt":1631534473331,"mc":[{"id":"1.187557146","rc":[{"batl":[[1,1.78,2.41],[2,2.42,286.96]],"ltp":1.76,"tv":21319.3,"id":8257797}]}]}
{"op":"mcm","clk":"4230576804","pt":1631534475337,"mc":[{"id":"1.187557146","rc":[{"batl":[[0,2.42,286.96],[1,990,0.01],[2,2.42,0]],"ltp":1.76,"tv":21319.3,"id":8257797}]}]}
{"op":"mcm","clk":"4230576887","pt":1631534476229,"mc":[{"id":"1.187557146","rc":[{"batl":[[0,2.26,30.38],[1,3.45,3.3],[2,4.5,2.23]],"ltp":2.3,"tv":6638.63,"id":19931652}]}]}
{"op":"mcm","clk":"4230577104","pt":1631534478543,"mc":[{"id":"1.187557146","rc":[{"batb":[[2,1.25,20]],"ltp":2.3,"tv":6638.63,"id":19931652}]}]}
{"op":"mcm","clk":"4230577445","pt":1631534481949,"mc":[{"id":"1.187557146","rc":[{"batb":[[0,1.95,4.54],[1,1.94,51.21],[2,1.59,1.7]],"ltp":2.3,"tv":6638.63,"id":19931652}]}]}
{"op":"mcm","clk":"4230578094","pt":1631534487964,"mc":[{"id":"1.187557146","rc":[{"batl":[[0,2.26,29.21]],"ltp":2.3,"tv":6638.63,"id":19931652}]}]}
{"op":"mcm","clk":"4230578416","pt":1631534491282,"mc":[{"id":"1.187557146","rc":[{"trd":[[2.26,42.84]],"batb":[[0,2.96,7.64],[1,2.92,68.5],[2,1.95,4.54]],"batl":[[0,4.5,2.23],[1,6,3],[2,6.4,3]],"ltp":2.26,"tv":6667.84,"id":19931652},{"trd":[[1.79,86.46]],"batb":[[0,1.48,16.58],[1,1.44,210.1]],"batl":[[0,1.83,283.59]],"ltp":1.79,"tv":21356.07,"id":8257797}],"tv":28023.91}]}
{"op":"mcm","clk":"4230578493","pt":1631534492176,"mc":[{"id":"1.187557146","rc":[{"batb":[[0,3,38.07],[1,2.96,7.64],[2,2.92,13.7]],"ltp":2.26,"tv":6667.84,"id":19931652}]}]}
{"op":"mcm","clk":"4230578700","pt":1631534494175,"mc":[{"id":"1.187557146","rc":[{"batl":[[1,1.95,422.03],[2,990,0.01]],"ltp":1.79,"tv":21356.07,"id":8257797}]}]}
{"op":"mcm","clk":"4230578860","pt":1631534495280,"mc":[{"id":"1.187557146","rc":[{"batl":[[0,1.79,2],[1,1.83,283.59],[2,1.95,422.03]],"ltp":1.79,"tv":21356.07,"id":8257797}]}]}
{"op":"mcm","clk":"4230578972","pt":1631534496275,"mc":[{"id":"1.187557146","rc":[{"trd":[[3,24.74]],"batb":[[0,3,33.57]],"batl":[[0,3.55,86.18],[1,4.5,2.23],[2,6,3]],"ltp":3.0,"tv":6676.84,"id":19931652},{"batl":[[0,1.83,283.59],[1,1.95,422.03],[2,990,0.01]],"ltp":1.79,"tv":21356.07,"id":8257797}],"tv":28032.92}]}
{"op":"mcm","clk":"4230579072","pt":1631534497163,"mc":[{"id":"1.187557146","rc":[{"batl":[[0,4.5,2.23],[1,6,3],[2,6.4,3]],"ltp":3.0,"tv":6676.84,"id":19931652},{"batl":[[2,1000,2.74]],"ltp":1.79,"tv":21356.07,"id":8257797}]}]}
{"op":"mcm","clk":"4230579143","pt":1631534498008,"mc":[{"id":"1.187557146","rc":[{"batl":[[1,6,5]],"ltp":3.0,"tv":6676.84,"id":19931652},{"batl":[[2,990,0.01]],"ltp":1.79,"tv":21356.07,"id":8257797}]}]}
{"op":"mcm","clk":"4230579383","pt":1631534500173,"mc":[{"id":"1.187557146","rc":[{"trd":[[1.48,33.21]],"batb":[[0,1.44,210.1],[1,1.4,79.91],[2,1.36,41.04]],"batl":[[0,1.45,672.37],[1,1.83,283.59],[2,1.95,422.03]],"ltp":1.48,"tv":21389.28,"id":8257797}],"tv":28066.13}]}
{"op":"mcm","clk":"4230579558","pt":1631534501795,"mc":[{"id":"1.187557146","rc":[{"batl":[[1,1.48,2.41],[2,1.83,283.59]],"ltp":1.48,"tv":21389.28,"id":8257797}]}]}
{"op":"mcm","clk":"4230579815","pt":1631534504298,"mc":[{"id":"1.187557146","rc":[{"batl":[[0,1.45,672.45],[1,1.49,5.94]],"ltp":1.48,"tv":21389.28,"id":8257797}]}]}
{"op":"mcm","clk":"4230579884","pt":1631534504975,"mc":[{"id":"1.187557146","rc":[{"batl":[[0,1.83,283.67],[1,1.95,422.03],[2,990,0.01]],"ltp":1.48,"tv":21389.28,"id":8257797}]}]}
{"op":"mcm","clk":"4230579919","pt":1631534505393,"mc":[{"id":"1.187557146","rc":[{"trd":[[3,26.96]],"batb":[[0,3,31.36]],"ltp":3.0,"tv":6679.06,"id":19931652},{"trd":[[1.45,4.5],[1.5,38.84]],"batl":[[0,1.83,283.59]],"ltp":1.5,"tv":21393.87,"id":8257797}],"tv":28072.93}]}
{"op":"mcm","clk":"4230580108","pt":1631534507289,"mc":[{"id":"1.187557146","rc":[{"trd":[[1.44,5.95]],"batb":[[0,1.44,207.24]],"ltp":1.44,"tv":21399.59,"id":8257797}],"tv":28078.66}]}
{"op":"mcm","clk":"4230580198","pt":1631534508294,"mc":[{"id":"1.187557146","rc":[{"trd":[[1.44,421.07]],"batb":[[0,1.4,79.91],[1,1.36,41.04],[2,1.34,482.91]],"batl":[[0,1.44,464.49],[1,1.83,283.59],[2,1.95,422.03]],"ltp":1.44,"tv":21814.71,"id":8257797}],"tv":28493.78}]}
{"op":"mcm","clk":"4230580285","pt":1631534509285,"mc":[{"id":"1.187557146","rc":[{"trd":[[3.25,72.78]],"batb":[[1,2.46,26.11],[2,1.59,1.7]],"ltp":3.25,"tv":6679.96,"id":19931652},{"trd":[[1.44,423.11]],"batb":[[1,1.34,462.08],[2,1.29,91.81]],"batl":[[0,1.44,462.45],[1,1.86,5.03]],"ltp":1.44,"tv":21816.75,"id":8257797}],"tv":28496.71}]}
{"op":"mcm","clk":"4230580320","pt":1631534509602,"mc":[{"id":"1.187557146","rc":[{"batb":[[0,2.46,26.11],[1,1.59,1.7],[2,1.25,20]],"batl":[[0,6,3],[1,6.4,3],[2,6.6,3]],"ltp":3.25,"tv":6679.96,"id":19931652},{"batb":[[0,1.34,462.08],[1,1.2,272.63],[2,1.19,103]],"ltp":1.44,"tv":21816.75,"id":8257797}]}]}
{"op":"mcm","clk":"4230580464","pt":1631534511128,"mc":[{"id":"1.187557146","rc":[{"trd":[[1.44,486.07]],"batl":[[0,1.44,430.92]],"ltp":1.44,"tv":21879.7,"id":8257797}],"tv":28559.67}]}
{"op":"mcm","clk":"4230580610","pt":1631534512818,"mc":[{"id":"1.187557146","rc":[{"batb":[[0,2.44,26.28]],"batl":[[2,6.6,5]],"ltp":3.25,"tv":6679.96,"id":19931652},{"batb":[[1,1.2,271.8]],"batl":[[0,1.44,433.34]],"ltp":1.44,"tv":21879.7,"id":8257797}]}]}
{"op":"mcm","clk":"4230580720","pt":1631534513819,"mc":[{"id":"1.187557146","rc":[{"trd":[[1.44,495.1]],"batl":[[0,1.44,428.81]],"ltp":1.44,"tv":21888.74,"id":8257797}],"tv":28568.7}]}
{"op":"mcm","clk":"4230580860","pt":1631534515090,"mc":[{"id":"1.187557146","rc":[{"batl":[[1,1.68,5.27],[2,1.86,5.03]],"ltp":1.44,"tv":21888.74,"id":8257797}]}]}
{"op":"mcm","clk":"4230580889","pt":1631534515402,"mc":[{"id":"1.187557146","rc":[{"batl":[[0,1.44,426.4]],"ltp":1.44,"tv":21888.74,"id":8257797}]}]}
{"op":"mcm","clk":"4230581045","pt":1631534517135,"mc":[{"id":"1.187557146","rc":[{"batl":[[1,1.86,5.03],[2,1.95,422.03]],"ltp":1.44,"tv":21888.74,"id":8257797}]}]}
{"op":"mcm","clk":"4230581159","pt":1631534518127,"mc":[{"id":"1.187557146","rc":[{"batb":[[0,1.2,271.8],[1,1.19,103],[2,1.18,256.86]],"batl":[[0,1.86,5.03],[1,990,0.01],[2,1.95,0]],"ltp":1.44,"tv":21888.74,"id":8257797}]}]}
{"op":"mcm","clk":"4230581308","pt":1631534519297,"mc":[{"id":"1.187557146","rc":[{"batb":[[0,2.96,251.88],[1,2.44,26.28],[2,1.59,1.7]],"batl":[[0,5.5,71.82],[1,6,3],[2,6.4,3]],"ltp":3.25,"tv":6679.96,"id":19931652},{"trd":[[1.26,378.23]],"batl":[[0,1.28,26.24],[1,1.32,151.52],[2,1.86,5.03]],"ltp":1.26,"tv":21925.5,"id":8257797}],"tv":28605.46}]}
{"op":"mcm","clk":"4230581418","pt":1631534520344,"mc":[{"id":"1.187557146","rc":[{"batb":[[0,4.5,26.86],[1,3.65,23.01],[2,2.96,251.88]],"ltp":3.25,"tv":6679.96,"id":19931652},{"batb":[[0,1.2,318.31],[2,1.18,280.51]],"batl":[[1,1.32,30.3]],"ltp":1.26,"tv":21925.5,"id":8257797}]}]}
{"op":"mcm","clk":"4230581538","pt":1631534521296,"mc":[{"id":"1.187557146","rc":[{"batl":[[2,1.4,400]],"ltp":1.26,"tv":21925.5,"id":8257797}]}]}
{"op":"mcm","clk":"4230581574","pt":1631534521617,"mc":[{"id":"1.187557146","rc":[{"batl":[[2,1.4,402]],"ltp":1.26,"tv":21925.5,"id":8257797}]}]}
{"op":"mcm","clk":"4230581715","pt":1631534522920,"mc":[{"id":"1.187557146","rc":[{"batb":[[2,1.18,826.75]],"batl":[[2,1.4,44]],"ltp":1.26,"tv":21925.5,"id":8257797}]}]}
{"op":"mcm","clk":"4230581867","pt":1631534524447,"mc":[{"id":"1.187557146","rc":[{"batl":[[2,1.4,42]],"ltp":1.26,"tv":21925.5,"id":8257797}]}]}
{"op":"mcm","clk":"4230582163","pt":1631534527330,"mc":[{"id":"1.187557146","rc":[{"trd":[[5.5,9.22]],"batl":[[0,5.5,71.28]],"ltp":5.5,"tv":6680.5,"id":19931652},{"trd":[[1.22,176.56]],"batl":[[2,1.34,18.04]],"ltp":1.22,"tv":21927.91,"id":8257797}],"tv":28608.42}]}
{"op":"mcm","clk":"4230582196","pt":1631534527640,"mc":[{"id":"1.187557146","rc":[{"batb":[[1,3.75,2.91],[2,3.65,23.01]],"ltp":5.5,"tv":6680.5,"id":19931652},{"trd":[[1.28,180.66]],"batl":[[0,1.28,23.69]],"ltp":1.28,"tv":21933.02,"id":8257797}],"tv":28613.52}]}
{"op":"mcm","clk":"4230582377","pt":1631534529324,"mc":[{"id":"1.187557146","rc":[{"trd":[[1.28,180.85]],"batl":[[0,1.32,30.3],[1,1.34,18.04],[2,1.36,76.07]],"ltp":1.28,"tv":21933.2,"id":8257797}],"tv":28613.71}]}
{"op":"mcm","clk":"4230582446","pt":1631534529955,"mc":[{"id":"1.187557146","rc":[{"trd":[[5.5,21.19]],"batl":[[0,5.5,59.31]],"ltp":5.5,"tv":6692.47,"id":19931652},{"trd":[[1.22,230.68]],"ltp":1.22,"tv":21987.31,"id":8257797}],"tv":28679.79}]}
{"op":"mcm","clk":"4230582571","pt":1631534531134,"mc":[{"id":"1.187557146","rc":[{"batl":[[0,1.27,6.98],[1,1.32,30.3],[2,1.34,18.04]],"ltp":1.22,"tv":21987.31,"id":8257797}]}]}
{"op":"mcm","clk":"4230582692","pt":1631534532249,"mc":[{"id":"1.187557146","rc":[{"trd":[[5.5,83.93]],"batl":[[0,6,3],[1,6.4,3],[2,6.6,5]],"ltp":5.5,"tv":6755.21,"id":19931652},{"trd":[[1.22,542.58]],"batl":[[0,1.22,19.11],[1,1.27,27.42],[2,1.32,30.3]],"ltp":1.22,"tv":22299.21,"id":8257797}],"tv":29054.43}]}
{"op":"mcm","clk":"4230582944","pt":1631534534245,"mc":[{"id":"1.187557146","rc":[{"batl":[[0,1.27,27.42],[1,1.32,30.3],[2,1.34,18.04]],"ltp":1.22,"tv":22299.21,"id":8257797}]}]}
{"op":"mcm","clk":"4230583101","pt":1631534535349,"mc":[{"id":"1.187557146","rc":[{"batb":[[0,3.65,23.01],[1,3.4,3.31],[2,1.59,1.7]],"batl":[[2,6.6,3]],"ltp":5.5,"tv":6755.21,"id":19931652},{"batb":[[0,1.2,100],[2,1.18,652.24]],"batl":[[0,1.27,6.98],[1,1.62,630.72],[2,1.86,5.03]],"ltp":1.22,"tv":22299.21,"id":8257797}]}]}
{"op":"mcm","clk":"4230583479","pt":1631534538353,"mc":[{"id":"1.187557146","rc":[{"batb":[[0,3.75,2.99],[1,3.65,23.01],[2,3.4,3.31]],"ltp":5.5,"tv":6755.21,"id":19931652},{"batl":[[1,1.36,76.07],[2,1.41,64.5]],"ltp":1.22,"tv":22299.21,"id":8257797}]}]}
{"op":"mcm","clk":"4230583497","pt":1631534538563,"mc":[{"id":"1.187557146","rc":[{"batb":[[0,3.65,23.01],[1,3.4,3.31],[2,1.59,1.7]],"ltp":5.5,"tv":6755.21,"id":19931652},{"batl":[[1,1.41,64.5],[2,1.62,630.72]],"ltp":1.22,"tv":22299.21,"id":8257797}]}]}
{"op":"mcm","clk":"4230583606","pt":1631534539558,"mc":[{"id":"1.187557146","rc":[{"batb":[[0,1.2,100.09]],"ltp":1.22,"tv":22299.21,"id":8257797}]}]}
{"op":"mcm","clk":"4230583800","pt":1631534541259,"mc":[{"id":"1.187557146","rc":[{"trd":[[1.27,592.62]],"batl":[[0,1.27,2.47]],"ltp":1.27,"tv":22308.23,"id":8257797}],"tv":29063.44}]}
{"op":"mcm","clk":"4230584193","pt":1631534544892,"mc":[{"id":"1.187557146","rc":[{"batl":[[0,1.41,64.5],[1,1.62,630.72],[2,1.86,5.03]],"ltp":1.27,"tv":22308.23,"id":8257797}]}]}
{"op":"mcm","clk":"4230584327","pt":1631534546051,"mc":[{"id":"1.187557146","rc":[{"batb":[[0,1.2,100.7]],"ltp":1.27,"tv":22308.23,"id":8257797}]}]}
{"op":"mcm","clk":"4230584407","pt":1631534546788,"mc":[{"id":"1.187557146","rc":[{"batb":[[0,1.2,100.79]],"ltp":1.27,"tv":22308.23,"id":8257797}]}]}
{"op":"mcm","clk":"4230584525","pt":1631534547787,"mc":[{"id":"1.187557146","rc":[{"batb":[[2,1.18,106]],"batl":[[1,1.86,5.03],[2,990,0.01]],"ltp":1.27,"tv":22308.23,"id":8257797}]}]}
{"op":"mcm","clk":"4230584667","pt":1631534548995,"mc":[{"id":"1.187557146","rc":[{"trd":[[6,3],[6.4,3.41],[6.6,3],[7,3],[7.4,8.4],[7.8,3],[8.2,3],[8.8,3]],"batb":[[0,8,15],[1,7.2,54.38],[2,3.65,23.01]],"batl":[[0,9.4,3],[1,10,72.97],[2,10.5,3]],"ltp":8.8,"tv":6779.21,"id":19931652},{"trd":[[1.12,375.07],[1.13,655.27],[1.14,262.53],[1.15,321.82],[1.16,1156.99],[1.17,263.68],[1.18,234.61],[1.19,208.17],[1.2,242.94],[1.27,594.2]],"batb":[[0,1.11,191.28],[1,1.1,490.33],[2,1.09,465.21]],"batl":[[0,1.15,27.03],[1,1.41,64.5],[2,1.86,5.03]],"ltp":1.12,"tv":24561.85,"id":8257797}],"tv":31341.06}]}
{"op":"mcm","clk":"4230584772","pt":1631534549788,"mc":[{"id":"1.187557146","rc":[{"batb":[[0,8,5],[2,6.8,18.66]],"ltp":8.8,"tv":6779.21,"id":19931652}]}]}
{"op":"mcm","clk":"4230584901","pt":1631534551059,"mc":[{"id":"1.187557146","rc":[{"batl":[[1,1.2,40],[2,1.41,64.5]],"ltp":1.12,"tv":24561.85,"id":8257797}]}]}
{"op":"mcm","clk":"4230585010","pt":1631534551967,"mc":[{"id":"1.187557146","rc":[{"trd":[[8,5.78]],"batb":[[0,8,2.11]],"ltp":8.0,"tv":6784.99,"id":19931652},{"batb":[[2,1.09,1241.8]],"batl":[[1,1.2,42]],"ltp":1.12,"tv":24561.85,"id":8257797}],"tv":31346.85}]}
{"op":"mcm","clk":"4230585235","pt":1631534554198,"mc":[{"id":"1.187557146","rc":[{"batl":[[1,1.2,40]],"ltp":1.12,"tv":24561.85,"id":8257797}]}]}
{"op":"mcm","clk":"4230585396","pt":1631534555468,"mc":[{"id":"1.187557146","rc":[{"batl":[[1,1.41,64.5],[2,1.47,822.95]],"ltp":1.12,"tv":24561.85,"id":8257797}]}]}
{"op":"mcm","clk":"4230585776","pt":1631534558807,"mc":[{"id":"1.187557146","rc":[{"batl":[[0,1.41,64.5],[1,1.47,822.95],[2,1.86,5.03]],"ltp":1.12,"tv":24561.85,"id":8257797}]}]}
{"op":"mcm","clk":"4230586045","pt":1631534561083,"mc":[{"id":"1.187557146","rc":[{"trd":[[8,7.89]],"batb":[[0,7.2,54.38],[1,6.8,18.66],[2,4.4,28.54]],"ltp":8.0,"tv":6787.1,"id":19931652},{"trd":[[1.15,336.5]],"batb":[[0,1.15,75.57],[1,1.11,191.28],[2,1.1,490.33]],"ltp":1.15,"tv":24576.53,"id":8257797}],"tv":31363.64}]}
{"op":"mcm","clk":"4230586142","pt":1631534561813,"mc":[{"id":"1.187557146","rc":[{"batl":[[0,8.6,6.03],[1,9.4,3],[2,10,72.97]],"ltp":8.0,"tv":6787.1,"id":19931652},{"trd":[[1.15,432.14]],"batb":[[0,1.15,37.75]],"ltp":1.15,"tv":24672.17,"id":8257797}],"tv":31459.28}]}
{"op":"mcm","clk":"4230586266","pt":1631534563014,"mc":[{"id":"1.187557146","rc":[{"batb":[[2,6,5]],"ltp":8.0,"tv":6787.1,"id":19931652}]}]}
{"op":"mcm","clk":"4230586408","pt":1631534564217,"mc":[{"id":"1.187557146","rc":[{"batb":[[0,1.15,155.75]],"ltp":1.15,"tv":24672.17,"id":8257797}]}]}
{"op":"mcm","clk":"4230586496","pt":1631534565010,"mc":[{"id":"1.187557146","rc":[{"trd":[[6,9],[6.8,26.8],[7.2,70.42]],"batb":[[0,6,2],[1,4.4,28.54],[2,3.4,3.31]],"batl":[[0,6.4,1.81],[1,7,3],[2,7.4,3]],"ltp":6.0,"tv":6870.34,"id":19931652},{"trd":[[1.17,598.36],[1.18,317.93]],"batb":[[0,1.16,113],[1,1.15,272.75],[2,1.14,121]],"batl":[[2,1.6,384]],"ltp":1.18,"tv":25090.17,"id":8257797}],"tv":31960.51}]}
{"op":"mcm","clk":"4230586668","pt":1631534566328,"mc":[{"id":"1.187557146","rc":[{"batb":[[1,1.15,287.93]],"ltp":1.18,"tv":25090.17,"id":8257797}]}]}
{"op":"mcm","clk":"4230586729","pt":1631534566843,"mc":[{"id":"1.187557146","rc":[{"batb":[[1,1.15,287.84]],"ltp":1.18,"tv":25090.17,"id":8257797}]}]}
{"op":"mcm","clk":"4230586988","pt":1631534569115,"mc":[{"id":"1.187557146","rc":[{"trd":[[6.4,7.03],[7,9]],"batb":[[0,6.8,17.77],[1,6,2],[2,4.3,29.87]],"batl":[[0,7.4,3],[1,7.8,3],[2,8.2,3]],"ltp":7.0,"tv":6879.96,"id":19931652}],"tv":31970.13}]}
{"op":"mcm","clk":"4230587199","pt":1631534570845,"mc":[{"id":"1.187557146","rc":[{"batb":[[0,1.17,10],[1,1.16,113],[2,1.15,287.84]],"ltp":1.18,"tv":25090.17,"id":8257797}]}]}
{"op":"mcm","clk":"4230587343","pt":1631534572012,"mc":[{"id":"1.187557146","rc":[{"trd":[[6.8,62.33]],"batb":[[0,6,2],[1,4.3,29.87],[2,3.4,3.31]],"ltp":6.8,"tv":6915.49,"id":19931652}],"tv":32005.66}]}
{"op":"mcm","clk":"4230587515","pt":1631534573212,"mc":[{"id":"1.187557146","rc":[{"batb":[[0,4.3,29.87],[1,3.4,3.31],[2,1.25,20]],"ltp":6.8,"tv":6915.49,"id":19931652},{"trd":[[1.15,736.11],[1.16,1383.34],[1.17,618.39]],"batb":[[0,1.15,136.09],[1,1.14,121],[2,1.13,127]],"ltp":1.15,"tv":25640.52,"id":8257797}],"tv":32556.01}]}
{"op":"mcm","clk":"4230587628","pt":1631534574212,"mc":[{"id":"1.187557146","rc":[{"batb":[[0,1.15,136.18]],"ltp":1.15,"tv":25640.52,"id":8257797}]}]}
{"op":"mcm","clk":"4230587724","pt":1631534574931,"mc":[{"id":"1.187557146","rc":[{"batl":[[2,8,4.82]],"ltp":6.8,"tv":6915.49,"id":19931652},{"trd":[[1.2,243.12]],"batb":[[0,1.15,110.91]],"batl":[[0,1.16,42.08],[1,1.41,64.5],[2,1.47,822.95]],"ltp":1.2,"tv":25640.7,"id":8257797}],"tv":32556.19}]}
{"op":"mcm","clk":"4230587989","pt":1631534577029,"mc":[{"id":"1.187557146","rc":[{"batb":[[0,6.6,20.59],[1,4.2,31.3],[2,3.4,3.31]],"ltp":6.8,"tv":6915.49,"id":19931652}]}]}
{"op":"mcm","clk":"4230588120","pt":1631534578020,"mc":[{"id":"1.187557146","rc":[{"trd":[[1.16,1467.5]],"batb":[[0,1.15,131.05]],"batl":[[0,1.41,64.5],[1,1.47,822.95],[2,1.86,5.03]],"ltp":1.16,"tv":25724.86,"id":8257797}],"tv":32640.35}]}
{"op":"mcm","clk":"4230588367","pt":1631534580142,"mc":[{"id":"1.187557146","rc":[{"trd":[[6.6,3.33]],"batb":[[0,6.6,20.25]],"ltp":6.6,"tv":6915.82,"id":19931652},{"trd":[[1.18,319.79]],"batb":[[0,1.15,251.05]],"batl":[[0,1.18,2.07],[1,1.41,64.5],[2,1.47,822.95]],"ltp":1.18,"tv":25726.72,"id":8257797}],"tv":32642.54}]}
{"op":"mcm","clk":"4230588491","pt":1631534581258,"mc":[{"id":"1.187557146","rc":[{"trd":[[6.6,23.59]],"batb":[[0,4.2,31.3],[1,3.4,3.31],[2,1.25,20]],"batl":[[0,6,3],[1,6.4,3],[2,6.6,3]],"ltp":6.6,"tv":6936.07,"id":19931652},{"trd":[[1.18,437.13]],"batb":[[0,1.2,100],[1,1.19,93.73],[2,1.17,109]],"batl":[[0,1.41,64.5],[1,1.47,822.95],[2,1.61,579]],"ltp":1.18,"tv":25844.06,"id":8257797}],"tv":32780.13}]}
{"op":"mcm","clk":"4230588999","pt":1631534585129,"mc":[{"id":"1.187557146","rc":[{"trd":[[6,33.59]],"batb":[[0,4,32.8]],"batl":[[0,6.4,3],[1,6.6,3],[2,7,3]],"ltp":6.0,"tv":6960.66,"id":19931652},{"trd":[[1.2,346]],"batb":[[0,1.2,2.12]],"ltp":1.2,"tv":25946.94,"id":8257797}],"tv":32907.6}]}
{"op":"mcm","clk":"4230589094","pt":1631534585852,"mc":[{"id":"1.187557146","rc":[{"trd":[[1.19,221.97],[1.2,350.24]],"batb":[[0,1.19,86.83],[1,1.17,109],[2,1.16,113]],"ltp":1.19,"tv":25964.98,"id":8257797}],"tv":32925.64}]}
{"op":"mcm","clk":"4230589250","pt":1631534587165,"mc":[{"id":"1.187557146","rc":[{"batl":[[0,1.2,2],[1,1.41,64.5],[2,1.47,822.95]],"ltp":1.19,"tv":25964.98,"id":8257797}]}]}
{"op":"mcm","clk":"4230589370","pt":1631534588268,"mc":[{"id":"1.187557146","rc":[{"trd":[[1.19,296.97]],"batb":[[0,1.19,49.33]],"batl":[[0,1.41,64.5],[1,1.47,822.95],[2,1.61,579]],"ltp":1.19,"tv":26039.98,"id":8257797}],"tv":33000.64}]}
{"op":"mcm","clk":"4230589461","pt":1631534589056,"mc":[{"id":"1.187557146","rc":[{"trd":[[4,17.87]],"batb":[[0,4,23.87]],"ltp":4.0,"tv":6978.53,"id":19931652}],"tv":33018.51}]}
{"op":"mcm","clk":"4230589516","pt":1631534589461,"mc":[{"id":"1.187557146","rc":[{"batl":[[0,1.2,689],[1,1.41,64.5],[2,1.47,822.95]],"ltp":1.19,"tv":26039.98,"id":8257797}]}]}
{"op":"mcm","clk":"4230589728","pt":1631534591266,"mc":[{"id":"1.187557146","rc":[{"trd":[[1.19,363.15]],"batb":[[0,1.19,16.24]],"batl":[[0,1.2,690.38]],"ltp":1.19,"tv":26106.16,"id":8257797}],"tv":33084.69}]}
{"op":"mcm","clk":"4230589956","pt":1631534593163,"mc":[{"id":"1.187557146","rc":[{"batb":[[0,6.2,22.93],[1,3.95,34.73],[2,3.4,3.31]],"ltp":4.0,"tv":6978.53,"id":19931652}]}]}
{"op":"mcm","clk":"4230590551","pt":1631534598142,"mc":[{"id":"1.187557146","rc":[{"trd":[[1.2,390.59]],"batl":[[0,1.2,670.17]],"ltp":1.2,"tv":26146.51,"id":8257797}],"tv":33125.04}]}
{"op":"mcm","clk":"4230590703","pt":1631534599549,"mc":[{"id":"1.187557146","rc":[{"trd":[[6.4,7.65]],"batl":[[0,6.4,2.38]],"ltp":6.4,"tv":6979.15,"id":19931652},{"trd":[[1.18,440.5],[1.19,395.63],[1.2,391.49]],"batb":[[0,1.17,109],[1,1.16,113],[2,1.15,110.91]],"batl":[[0,1.2,669.72]],"ltp":1.18,"tv":26183.25,"id":8257797}],"tv":33162.41}]}
{"op":"mcm","clk":"4230590875","pt":1631534601170,"mc":[{"id":"1.187557146","rc":[{"batl":[[2,6.8,4.4]],"ltp":6.4,"tv":6979.15,"id":19931652}]}]}
{"op":"mcm","clk":"4230590966","pt":1631534602059,"mc":[{"id":"1.187557146","rc":[{"batl":[[2,7,3]],"ltp":6.4,"tv":6979.15,"id":19931652}]}]}
{"op":"mcm","clk":"4230591054","pt":1631534602952,"mc":[{"id":"1.187557146","rc":[{"trd":[[6.2,8.1]],"batb":[[0,6.2,22.03]],"ltp":6.2,"tv":6980.95,"id":19931652}],"tv":33164.21}]}
{"op":"mcm","clk":"4230591134","pt":1631534603690,"mc":[{"id":"1.187557146","rc":[{"trd":[[1.2,400.53]],"batl":[[0,1.2,665.19]],"ltp":1.2,"tv":26192.29,"id":8257797}],"tv":33173.24}]}
{"op":"mcm","clk":"4230591275","pt":1631534605058,"mc":[{"id":"1.187557146","rc":[{"trd":[[6.2,14.1]],"batb":[[0,6.2,19.03]],"batl":[[2,6.8,4.4]],"ltp":6.2,"tv":6986.95,"id":19931652},{"trd":[[1.2,600.84]],"batb":[[0,1.19,103],[1,1.18,106],[2,1.17,109]],"batl":[[0,1.2,564.88]],"ltp":1.2,"tv":26392.6,"id":8257797}],"tv":33379.55}]}
{"op":"mcm","clk":"4230591689","pt":1631534609183,"mc":[{"id":"1.187557146","rc":[{"batl":[[0,1.2,1.38],[1,1.41,64.59]],"ltp":1.2,"tv":26392.6,"id":8257797}]}]}
{"op":"mcm","clk":"4230591747","pt":1631534609808,"mc":[{"id":"1.187557146","rc":[{"trd":[[6.2,14.15]],"batb":[[0,6.2,19]],"ltp":6.2,"tv":6986.99,"id":19931652}],"tv":33379.59}]}
{"op":"mcm","clk":"4230592347","pt":1631534615308,"mc":[{"id":"1.187557146","rc":[{"trd":[[6.2,14.33]],"batb":[[0,6.2,18.91]],"ltp":6.2,"tv":6987.18,"id":19931652}],"tv":33379.78}]}
{"op":"mcm","clk":"4230592529","pt":1631534616988,"mc":[{"id":"1.187557146","rc":[{"trd":[[6.2,14.52]],"batb":[[0,6.2,18.82]],"ltp":6.2,"tv":6987.36,"id":19931652},{"trd":[[1.19,601.18]],"batb":[[0,1.18,106.38],[1,1.17,109],[2,1.16,113]],"ltp":1.19,"tv":26598.15,"id":8257797}],"tv":33585.52}]}
{"op":"mcm","clk":"4230592769","pt":1631534619079,"mc":[{"id":"1.187557146","rc":[{"trd":[[6.2,15.13]],"batb":[[0,6.2,18.21]],"ltp":6.2,"tv":6987.97,"id":19931652},{"trd":[[1.2,606.72]],"batl":[[0,1.41,64.59],[1,1.47,822.95],[2,1.86,5.03]],"ltp":1.2,"tv":26604.04,"id":8257797}],"tv":33592.02}]}
{"op":"mcm","clk":"4230592848","pt":1631534620115,"mc":[{"id":"1.187557146","rc":[{"trd":[[6.2,15.21]],"batb":[[0,6.2,18.12]],"ltp":6.2,"tv":6988.06,"id":19931652},{"trd":[[1.2,607.17]],"ltp":1.2,"tv":26604.49,"id":8257797}],"tv":33592.56}]}
{"op":"mcm","clk":"4230592927","pt":1631534620596,"mc":[{"id":"1.187557146","rc":[{"trd":[[6.2,33.34]],"batb":[[0,3.95,34.73],[1,3.4,3.31],[2,1.25,20]],"batl":[[0,6,3],[1,6.4,2.38],[2,6.6,3]],"ltp":6.2,"tv":7006.18,"id":19931652},{"trd":[[1.2,700.75]],"batb":[[0,1.2,6.42],[1,1.18,106.38],[2,1.17,109]],"batl":[[2,1.61,761]],"ltp":1.2,"tv":26698.07,"id":8257797}],"tv":33704.26}]}
{"op":"mcm","clk":"4230593207","pt":1631534623228,"mc":[{"id":"1.187557146","rc":[{"batl":[[0,6.8,4.4],[1,7,3],[2,8.8,3]],"ltp":6.2,"tv":7006.18,"id":19931652},{"batb":[[0,1.17,109],[1,1.13,127],[2,1.12,133]],"batl":[[2,1.86,5.03]],"ltp":1.2,"tv":26698.07,"id":8257797}]}]}
{"op":"mcm","clk":"4230593303","pt":1631534624018,"mc":[{"id":"1.187557146","rc":[{"trd":[[1.17,621.8]],"batb":[[0,1.17,107.3]],"ltp":1.17,"tv":26701.48,"id":8257797}],"tv":33707.66}]}
{"op":"mcm","clk":"4230593575","pt":1631534626329,"mc":[{"id":"1.187557146","rc":[{"batb":[[0,3.9,36.48]],"ltp":6.2,"tv":7006.18,"id":19931652},{"batl":[[0,1.2,40],[1,1.41,969.59],[2,1.47,822.95]],"ltp":1.17,"tv":26701.48,"id":8257797}]}]}
{"op":"mcm","clk":"4230593657","pt":1631534627120,"mc":[{"id":"1.187557146","rc":[{"batl":[[0,1.18,110.24],[1,1.2,42],[2,1.41,969.59]],"ltp":1.17,"tv":26701.48,"id":8257797}]}]}
{"op":"mcm","clk":"4230594048","pt":1631534630434,"mc":[{"id":"1.187557146","rc":[{"batl":[[1,1.2,40]],"ltp":1.17,"tv":26701.48,"id":8257797}]}]}
{"op":"mcm","clk":"4230594334","pt":1631534633217,"mc":[{"id":"1.187557146","rc":[{"batl":[[1,1.41,969.59],[2,1.47,822.95]],"ltp":1.17,"tv":26701.48,"id":8257797}]}]}
{"op":"mcm","clk":"4230594365","pt":1631534633534,"mc":[{"id":"1.187557146","rc":[{"batl":[[0,1.41,969.59],[1,1.47,822.95],[2,1.86,5.03]],"ltp":1.17,"tv":26701.48,"id":8257797}]}]}
{"op":"mcm","clk":"4230594725","pt":1631534636628,"mc":[{"id":"1.187557146","rc":[{"trd":[[6.8,62.78]],"batl":[[0,6.8,3.95]],"ltp":6.8,"tv":7006.63,"id":19931652},{"trd":[[1.17,839.34]],"batb":[[0,1.13,127],[1,1.12,133],[2,1.11,150.38]],"ltp":1.17,"tv":26919.01,"id":8257797}],"tv":33925.65}]}
{"op":"mcm","clk":"4230594930","pt":1631534638627,"mc":[{"id":"1.187557146","rc":[{"batl":[[0,1.18,10],[1,1.41,969.59],[2,1.47,822.95]],"ltp":1.17,"tv":26919.01,"id":8257797}]}]}
{"op":"mcm","clk":"4230595799","pt":1631534646869,"mc":[{"id":"1.187557146","rc":[{"batl":[[0,7,3],[1,8.8,3],[2,9.4,3]],"ltp":6.8,"tv":7006.63,"id":19931652}]}]}
{"op":"mcm","clk":"4230595870","pt":1631534647561,"mc":[{"id":"1.187557146","rc":[{"batl":[[0,1.41,969.59],[1,1.47,822.95],[2,1.86,5.03]],"ltp":1.17,"tv":26919.01,"id":8257797}]}]}
{"op":"mcm","clk":"4230596185","pt":1631534650350,"mc":[{"id":"1.187557146","rc":[{"batb":[[0,6.4,3.42],[1,3.9,36.48],[2,3.4,3.31]],"batl":[[0,6.8,3.95],[1,7,3],[2,8.8,3]],"ltp":6.8,"tv":7006.63,"id":19931652}]}]}
{"op":"mcm","clk":"4230596227","pt":1631534650669,"mc":[{"id":"1.187557146","rc":[{"trd":[[6.8,64.5]],"batl":[[0,6.8,2.23]],"ltp":6.8,"tv":7008.35,"id":19931652},{"trd":[[1.17,849.34]],"ltp":1.17,"tv":26929.01,"id":8257797}],"tv":33937.37}]}
{"op":"mcm","clk":"4230596558","pt":1631534653557,"mc":[{"id":"1.187557146","rc":[{"trd":[[6.4,8.05]],"batb":[[0,6.4,3.02]],"ltp":6.4,"tv":7008.75,"id":19931652},{"trd":[[1.19,603.35]],"ltp":1.19,"tv":26931.18,"id":8257797}],"tv":33939.94}]}
{"op":"mcm","clk":"4230596669","pt":1631534654487,"mc":[{"id":"1.187557146","rc":[{"batl":[[1,8.8,3],[2,9.4,3]],"ltp":6.4,"tv":7008.75,"id":19931652},{"batl":[[0,1.41,64.59]],"ltp":1.19,"tv":26931.18,"id":8257797}]}]}
{"op":"mcm","clk":"4230597116","pt":1631534658088,"mc":[{"id":"1.187557146","rc":[{"trd":[[6.6,26.35]],"batl":[[0,6.8,2.47]],"ltp":6.6,"tv":7011.51,"id":19931652},{"trd":[[1.17,864.96],[1.18,652.83]],"batl":[[0,1.38,966.09],[1,1.41,64.5],[2,1.47,822.95]],"ltp":1.17,"tv":27159.14,"id":8257797}],"tv":34170.66}]}
{"op":"mcm","clk":"4230597234","pt":1631534659194,"mc":[{"id":"1.187557146","rc":[{"trd":[[6.6,26.59],[6.8,66.73]],"batl":[[0,8.8,3],[1,9.4,3],[2,10,72.97]],"ltp":6.8,"tv":7013.98,"id":19931652},{"trd":[[1.17,879.29]],"batl":[[0,1.17,138.84],[1,1.38,966.09],[2,1.41,64.5]],"ltp":1.17,"tv":27173.46,"id":8257797}],"tv":34187.45}]}
{"op":"mcm","clk":"4230597415","pt":1631534660878,"mc":[{"id":"1.187557146","rc":[{"batb":[[0,3.9,36.48],[1,3.4,3.31],[2,1.25,20]],"ltp":6.8,"tv":7013.98,"id":19931652}]}]}
{"op":"mcm","clk":"4230597582","pt":1631534662499,"mc":[{"id":"1.187557146","rc":[{"trd":[[6.8,75.24]],"ltp":6.8,"tv":7022.5,"id":19931652},{"trd":[[1.17,928.77]],"batl":[[0,1.17,89.35]],"ltp":1.17,"tv":27222.95,"id":8257797}],"tv":34245.45}]}
{"op":"mcm","clk":"4230597733","pt":1631534664014,"mc":[{"id":"1.187557146","rc":[{"batl":[[0,9.4,3],[1,10,72.97],[2,10.5,3]],"ltp":6.8,"tv":7022.5,"id":19931652},{"batb":[[0,1.12,133],[1,1.11,150.38],[2,1.1,150]],"ltp":1.17,"tv":27222.95,"id":8257797}]}]}
{"op":"mcm","clk":"4230597815","pt":1631534664802,"mc":[{"id":"1.187557146","rc":[{"batl":[[0,1.38,966.09],[1,1.41,64.5],[2,1.47,822.95]],"ltp":1.17,"tv":27222.95,"id":8257797}]}]}
{"op":"mcm","clk":"4230598046","pt":1631534667003,"mc":[{"id":"1.187557146","rc":[{"batl":[[0,7.2,7.01],[1,7.4,3],[2,9.4,3]],"ltp":6.8,"tv":7022.5,"id":19931652},{"batb":[[0,1.16,113],[1,1.12,133],[2,1.11,150.38]],"batl":[[0,1.18,23.01],[1,1.38,966.09],[2,1.41,64.5]],"ltp":1.17,"tv":27222.95,"id":8257797}]}]}
{"op":"mcm","clk":"4230598287","pt":1631534669207,"mc":[{"id":"1.187557146","rc":[{"batl":[[0,7.4,3],[1,9.4,3],[2,10,72.97]],"ltp":6.8,"tv":7022.5,"id":19931652},{"batb":[[0,1.16,113.45]],"batl":[[0,1.38,966.09],[1,1.41,64.5],[2,1.47,822.95]],"ltp":1.17,"tv":27222.95,"id":8257797}]}]}
{"op":"mcm","clk":"4230598374","pt":1631534669934,"mc":[{"id":"1.187557146","rc":[{"batl":[[0,9.4,3],[1,10,72.97],[2,10.5,3]],"ltp":6.8,"tv":7022.5,"id":19931652},{"trd":[[1.19,604.25]],"batb":[[0,1.12,133],[1,1.11,150.38],[2,1.1,150]],"batl":[[0,1.32,1.08],[1,1.38,966],[2,1.41,64.5]],"ltp":1.19,"tv":27223.85,"id":8257797}],"tv":34246.35}]}
{"op":"mcm","clk":"4230598563","pt":1631534671817,"mc":[{"id":"1.187557146","rc":[{"trd":[[8.6,0.13]],"ltp":8.6,"tv":7022.63,"id":19931652},{"trd":[[1.13,656.26]],"batl":[[0,1.38,966.09],[1,1.41,64.5],[2,1.47,822.95]],"ltp":1.13,"tv":27224.83,"id":8257797}],"tv":34247.47}]}
{"op":"mcm","clk":"4230598659","pt":1631534672810,"mc":[{"id":"1.187557146","rc":[{"batl":[[0,7,3],[1,9.4,3],[2,10,72.97]],"ltp":8.6,"tv":7022.63,"id":19931652},{"batb":[[0,1.17,109],[1,1.12,133],[2,1.11,150.38]],"ltp":1.13,"tv":27224.83,"id":8257797}]}]}
{"op":"mcm","clk":"4230598889","pt":1631534675120,"mc":[{"id":"1.187557146","rc":[{"batl":[[1,7.2,6.85],[2,9.4,3]],"ltp":8.6,"tv":7022.63,"id":19931652},{"trd":[[1.17,1073.43]],"batb":[[0,1.17,36.66]],"batl":[[0,1.18,23.97],[1,1.38,966.09],[2,1.41,64.5]],"ltp":1.17,"tv":27369.5,"id":8257797}],"tv":34392.13}]}
{"op":"mcm","clk":"4230599207","pt":1631534678410,"mc":[{"id":"1.187557146","rc":[{"batb":[[0,4.1,26.26],[1,3.9,36.48],[2,3.4,3.31]],"ltp":8.6,"tv":7022.63,"id":19931652}]}]}
{"op":"mcm","clk":"4230599469","pt":1631534681124,"mc":[{"id":"1.187557146","rc":[{"trd":[[1.18,657.17]],"batl":[[0,1.18,21.8]],"ltp":1.18,"tv":27373.84,"id":8257797}],"tv":34396.47}]}
{"op":"mcm","clk":"4230599563","pt":1631534681853,"mc":[{"id":"1.187557146","rc":[{"batl":[[1,9.4,3],[2,10,72.97]],"ltp":8.6,"tv":7022.63,"id":19931652},{"batl":[[0,1.38,966.09],[1,1.41,64.5],[2,1.47,822.95]],"ltp":1.18,"tv":27373.84,"id":8257797}]}]}
{"op":"mcm","clk":"4230599766","pt":1631534683835,"mc":[{"id":"1.187557146","rc":[{"batb":[[0,3.9,36.48],[1,3.4,3.31],[2,1.25,20]],"ltp":8.6,"tv":7022.63,"id":19931652}]}]}
{"op":"mcm","clk":"4230599862","pt":1631534684716,"mc":[{"id":"1.187557146","rc":[{"batl":[[1,7.2,7.2],[2,9.4,3]],"ltp":8.6,"tv":7022.63,"id":19931652},{"batl":[[0,1.18,21.8],[1,1.38,966.09],[2,1.41,64.5]],"ltp":1.18,"tv":27373.84,"id":8257797}]}]}
{"op":"mcm","clk":"4230600037","pt":1631534686436,"mc":[{"id":"1.187557146","rc":[{"trd":[[1.17,1146.76]],"batb":[[0,1.12,133],[1,1.11,150.38],[2,1.1,150]],"batl":[[0,1.17,48.51],[1,1.18,21.8],[2,1.38,966.09]],"ltp":1.17,"tv":27447.17,"id":8257797}],"tv":34469.8}]}
{"op":"mcm","clk":"4230600339","pt":1631534689254,"mc":[{"id":"1.187557146","rc":[{"batl":[[0,9.4,3],[1,10.5,3],[2,11,3]],"ltp":8.6,"tv":7022.63,"id":19931652},{"batl":[[1,1.41,64.59],[2,1.47,822.95]],"ltp":1.17,"tv":27447.17,"id":8257797}]}]}
{"op":"mcm","clk":"4230600371","pt":1631534689573,"mc":[{"id":"1.187557146","rc":[{"batb":[[1,1.25,20],[2,1.01,105.7]],"ltp":8.6,"tv":7022.63,"id":19931652},{"batl":[[1,1.47,823.04],[2,3.8,27.65]],"ltp":1.17,"tv":27447.17,"id":8257797}]}]}
{"op":"mcm","clk":"4230600536","pt":1631534691281,"mc":[{"id":"1.187557146","rc":[{"batb":[[0,1.16,113],[1,1.12,133],[2,1.11,150.38]],"batl":[[0,1.17,88.54],[1,1.37,1063.09],[2,1.47,822.95]],"ltp":1.17,"tv":27447.17,"id":8257797}]}]}
{"op":"mcm","clk":"4230600559","pt":1631534691450,"mc":[{"id":"1.187557146","rc":[{"batl":[[2,3.8,27.65]],"ltp":1.17,"tv":27447.17,"id":8257797}]}]}
{"op":"mcm","clk":"4230600855","pt":1631534694486,"mc":[{"id":"1.187557146","rc":[{"batl":[[0,1.17,48.51]],"ltp":1.17,"tv":27447.17,"id":8257797}]}]}
{"op":"mcm","clk":"4230601036","pt":1631534696046,"mc":[{"id":"1.187557146","rc":[{"trd":[[6.8,75.34]],"ltp":6.8,"tv":7022.72,"id":19931652},{"trd":[[1.16,1551.5],[1.17,1147.3]],"batb":[[0,1.16,71]],"batl":[[0,1.17,47.97]],"ltp":1.16,"tv":27531.7,"id":8257797}],"tv":34554.43}]}
{"op":"mcm","clk":"4230601384","pt":1631534698972,"mc":[{"id":"1.187557146","rc":[{"batl":[[0,1.37,1063.09],[1,3.8,27.65],[2,8.8,7.23]],"ltp":1.16,"tv":27531.7,"id":8257797}]}]}
{"op":"mcm","clk":"4230601702","pt":1631534702057,"mc":[{"id":"1.187557146","rc":[{"trd":[[1.16,1647.43]],"batb":[[0,1.16,23.04]],"ltp":1.16,"tv":27627.63,"id":8257797}],"tv":34650.36}]}
{"op":"mcm","clk":"4230601797","pt":1631534702808,"mc":[{"id":"1.187557146","rc":[{"trd":[[1.16,1693.51]],"batb":[[0,1.12,133],[1,1.11,150.38],[2,1.1,150]],"batl":[[0,1.16,16.96],[1,1.37,1063.09],[2,3.8,27.65]],"ltp":1.16,"tv":27673.71,"id":8257797}],"tv":34696.44}]}
{"op":"mcm","clk":"4230601960","pt":1631534703902,"mc":[{"id":"1.187557146","rc":[{"trd":[[1.16,1695.07]],"batl":[[0,1.16,56.21]],"ltp":1.16,"tv":27675.27,"id":8257797}],"tv":34698.0}]}
{"op":"mcm","clk":"4230602146","pt":1631534705189,"mc":[{"id":"1.187557146","rc":[{"batl":[[0,1.16,40.03]],"ltp":1.16,"tv":27675.27,"id":8257797}]}]}
{"op":"mcm","clk":"4230602309","pt":1631534706305,"mc":[{"id":"1.187557146","rc":[{"trd":[[1.16,1700.96]],"batl":[[0,1.16,39.09]],"ltp":1.16,"tv":27681.17,"id":8257797}],"tv":34703.89}]}
{"op":"mcm","clk":"4230602544","pt":1631534708316,"mc":[{"id":"1.187557146","rc":[{"batl":[[0,1.37,1063.09],[1,3.8,27.65],[2,8.8,7.23]],"ltp":1.16,"tv":27681.17,"id":8257797}]}]}
{"op":"mcm","clk":"4230603791","pt":1631534719935,"mc":[{"id":"1.187557146","rc":[{"batl":[[1,18,2],[2,21,2]],"ltp":6.8,"tv":7022.72,"id":19931652},{"batb":[[1,1.11,9.38],[2,1.06,794.48]],"batl":[[0,3.8,27.74],[1,8.8,7.23],[2,44,7.23]],"ltp":1.16,"tv":27681.17,"id":8257797}]}]}
{"op":"mcm","clk":"4230604062","pt":1631534722246,"mc":[{"id":"1.187557146","rc":[{"trd":[[9.4,3]],"batb":[[0,11,21.55],[1,3.9,36.48],[2,1.25,20]],"batl":[[0,17.5,62.1]],"ltp":9.4,"tv":7025.72,"id":19931652},{"trd":[[1.11,1015.01],[1.12,641.07]],"batb":[[0,1.06,794.48],[1,1.05,303.16],[2,1.04,300]],"batl":[[0,1.1,230.74],[1,1.11,36.04],[2,3.8,27.74]],"ltp":1.11,"tv":27991.34,"id":8257797}],"tv":35017.06}]}
{"op":"mcm","clk":"4230604140","pt":1631534722926,"mc":[{"id":"1.187557146","rc":[{"batb":[[1,9.4,19.83],[2,5.5,30.13]],"ltp":9.4,"tv":7025.72,"id":19931652},{"batl":[[2,1.25,1212]],"ltp":1.11,"tv":27991.34,"id":8257797}]}]}
{"op":"mcm","clk":"4230604325","pt":1631534724653,"mc":[{"id":"1.187557146","rc":[{"batb":[[2,1.04,1566.18]],"ltp":1.11,"tv":27991.34,"id":8257797}]}]}
{"op":"mcm","clk":"4230604470","pt":1631534725753,"mc":[{"id":"1.187557146","rc":[{"trd":[[1.1,438.46]],"batl":[[0,1.1,185.66]],"ltp":1.1,"tv":28081.5,"id":8257797}],"tv":35107.22}]}
{"op":"mcm","clk":"4230604611","pt":1631534726929,"mc":[{"id":"1.187557146","rc":[{"batl":[[2,1.13,36.16]],"ltp":1.1,"tv":28081.5,"id":8257797}]}]}
{"op":"mcm","clk":"4230604862","pt":1631534728960,"mc":[{"id":"1.187557146","rc":[{"batb":[[2,6.8,2]],"ltp":9.4,"tv":7025.72,"id":19931652},{"batl":[[2,1.17,153.5]],"ltp":1.1,"tv":28081.5,"id":8257797}]}]}
{"op":"mcm","clk":"4230604957","pt":1631534729747,"mc":[{"id":"1.187557146","rc":[{"trd":[[1.06,1094.04]],"batb":[[0,1.06,787.25]],"ltp":1.06,"tv":28095.95,"id":8257797}],"tv":35121.68}]}
{"op":"mcm","clk":"4230605158","pt":1631534731337,"mc":[{"id":"1.187557146","rc":[{"trd":[[1.1,583.12]],"batl":[[0,1.1,113.32],[1,1.17,153.5],[2,1.19,126.5]],"ltp":1.1,"tv":28240.61,"id":8257797}],"tv":35266.34}]}
{"op":"mcm","clk":"4230605241","pt":1631534732153,"mc":[{"id":"1.187557146","rc":[{"batb":[[0,6.8,2],[1,5.7,2.02],[2,5.5,30.13]],"batl":[[0,55,2],[1,990,0.01],[2,21,0]],"ltp":9.4,"tv":7025.72,"id":19931652},{"trd":[[1.06,1252.86]],"batb":[[0,1.04,1266.18],[1,1.02,1314.71],[2,1.01,2583.49]],"batl":[[0,1.17,153.5],[1,1.19,126.5],[2,1.21,139.5]],"ltp":1.06,"tv":28399.43,"id":8257797}],"tv":35425.16}]}
{"op":"mcm","clk":"4230605301","pt":1631534732641,"mc":[{"id":"1.187557146","rc":[{"batb":[[0,5.7,2.02],[1,5.5,30.13],[2,1.25,20]],"ltp":9.4,"tv":7025.72,"id":19931652},{"batl":[[0,1.11,50.26],[1,1.21,139.5],[2,1.37,1033.99]],"ltp":1.06,"tv":28399.43,"id":8257797}]}]}
{"op":"mcm","clk":"4230605487","pt":1631534734352,"mc":[{"id":"1.187557146","rc":[{"batl":[[0,990,0.01],[1,990,0]],"ltp":9.4,"tv":7025.72,"id":19931652},{"batb":[[0,1.07,160],[1,1.02,0],[2,1.01,0]],"batl":[[2,3.8,27.74]],"ltp":1.06,"tv":28399.43,"id":8257797}]}]}
{"op":"mcm","clk":"4230605738","pt":1631534736557,"mc":[{"id":"1.187557146","rc":[{"batl":[[0,990,0.91]],"ltp":9.4,"tv":7025.72,"id":19931652}]}]}
{"op":"mcm","clk":"4230606118","pt":1631534740256,"mc":[{"id":"1.187557146","rc":[{"batb":[[0,1.02,7.35],[1,1.01,7.23]],"ltp":1.06,"tv":28399.43,"id":8257797}]}]}
{"op":"mcm","clk":"4230606223","pt":1631534741296,"mc":[{"id":"1.187557146","rc":[{"batl":[[0,990,0.01]],"ltp":9.4,"tv":7025.72,"id":19931652}]}]}
{"op":"mcm","clk":"4230606273","pt":1631534741767,"mc":[{"id":"1.187557146","rc":[{"trd":[[1.1,583.36]],"batb":[[0,1.02,7.23]],"ltp":1.1,"tv":28399.67,"id":8257797}],"tv":35425.4}]}
{"op":"mcm","clk":"4230606436","pt":1631534743175,"mc":[{"id":"1.187557146","rc":[{"batb":[[0,1.06,955.59],[1,1.02,7.23],[2,1.01,7.23]],"batl":[[0,1.21,139.5],[1,1.4,949.63],[2,3.8,27.65]],"ltp":1.1,"tv":28399.67,"id":8257797}]}]}
{"op":"mcm","clk":"4230606519","pt":1631534743875,"mc":[{"id":"1.187557146","rc":[{"batb":[[0,1.02,7.23],[1,1.01,7.23],[2,1.01,0]],"batl":[[1,3.8,27.74],[2,8.8,7.23]],"ltp":1.1,"tv":28399.67,"id":8257797}]}]}
{"op":"mcm","clk":"4230606669","pt":1631534745279,"mc":[{"id":"1.187557146","rc":[{"batb":[[0,1.03,7.23],[1,1.02,7.23],[2,1.01,7.23]],"ltp":1.1,"tv":28399.67,"id":8257797}]}]}
{"op":"mcm","clk":"4230606700","pt":1631534745585,"mc":[{"id":"1.187557146","rc":[{"batl":[[0,1.1,50.26],[1,1.21,139.5],[2,3.8,27.74]],"ltp":1.1,"tv":28399.67,"id":8257797}]}]}
{"op":"mcm","clk":"4230606924","pt":1631534747269,"mc":[{"id":"1.187557146","rc":[{"batb":[[0,7,2],[1,6.6,2],[2,5.7,2.02]],"batl":[[0,60,2],[1,65,2],[2,990,0.01]],"ltp":9.4,"tv":7025.72,"id":19931652},{"batl":[[0,1.1,95.34]],"ltp":1.1,"tv":28399.67,"id":8257797}]}]}
{"op":"mcm","clk":"4230607043","pt":1631534748176,"mc":[{"id":"1.187557146","rc":[{"batb":[[0,5.7,2.02],[1,5.5,30.13],[2,1.25,20]],"batl":[[0,990,0.01],[1,65,0],[2,990,0]],"ltp":9.4,"tv":7025.72,"id":19931652}]}]}
{"op":"mcm","clk":"4230607189","pt":1631534749374,"mc":[{"id":"1.187557146","rc":[{"batb":[[0,1.04,7.23],[1,1.03,7.23],[2,1.02,7.23]],"ltp":1.1,"tv":28399.67,"id":8257797}]}]}
{"op":"mcm","clk":"4230607722","pt":1631534754214,"mc":[{"id":"1.187557146","rc":[{"batb":[[0,7,2],[1,6.6,2],[2,5.7,2.02]],"batl":[[0,60,2],[1,65,2],[2,990,0.01]],"ltp":9.4,"tv":7025.72,"id":19931652}]}]}
{"op":"mcm","clk":"4230607818","pt":1631534755108,"mc":[{"id":"1.187557146","rc":[{"batb":[[0,5.7,2.02],[1,5.5,30.13],[2,1.25,20]],"batl":[[0,990,0.01],[1,65,0],[2,990,0]],"ltp":9.4,"tv":7025.72,"id":19931652},{"batl":[[0,1.06,115.72]],"ltp":1.1,"tv":28399.67,"id":8257797}]}]}
{"op":"mcm","clk":"4230608102","pt":1631534757885,"mc":[{"id":"1.187557146","rc":[{"batb":[[0,6.8,2],[1,6.6,2],[2,5.7,2.02]],"batl":[[0,60,2],[1,65,2],[2,990,0.01]],"ltp":9.4,"tv":7025.72,"id":19931652},{"trd":[[1.06,1278.06]],"batl":[[0,1.06,103.12],[1,1.17,132.5],[2,1.19,132.5]],"ltp":1.06,"tv":28424.87,"id":8257797}],"tv":35450.59}]}
{"op":"mcm","clk":"4230608194","pt":1631534758810,"mc":[{"id":"1.187557146","rc":[{"batl":[[0,55,2],[1,60,2],[2,65,2]],"ltp":9.4,"tv":7025.72,"id":19931652},{"batb":[[0,1.03,7.23],[1,1.02,1076.28],[2,1.01,2827.36]],"ltp":1.06,"tv":28424.87,"id":8257797}]}]}
{"op":"mcm","clk":"4230608351","pt":1631534760207,"mc":[{"id":"1.187557146","rc":[{"trd":[[6.6,30.59],[6.8,102.14],[17.5,41.79]],"batb":[[0,6,29.48],[1,5.7,2.02],[2,5.5,30.13]],"batl":[[0,6.4,2.35],[1,8,62.89],[2,8.6,4.66]],"ltp":6.6,"tv":7062.77,"id":19931652},{"trd":[[1.06,1381.18],[1.17,1279.8]],"batb":[[0,1.13,99.12],[1,1.11,25.14],[2,1.06,7.23]],"batl":[[0,1.2,158.26],[1,1.21,139.5],[2,3.8,27.74]],"ltp":1.17,"tv":28660.48,"id":8257797}],"tv":35723.26}]}
{"op":"mcm","clk":"4230608435","pt":1631534760893,"mc":[{"id":"1.187557146","rc":[{"batb":[[0,1.15,253.05],[1,1.13,99.12],[2,1.11,25.14]],"ltp":1.17,"tv":28660.48,"id":8257797}]}]}
{"op":"mcm","clk":"4230608721","pt":1631534763306,"mc":[{"id":"1.187557146","rc":[{"trd":[[6.4,12.75]],"batl":[[0,8,62.89],[1,8.6,4.66],[2,8.8,2.12]],"ltp":6.4,"tv":7067.47,"id":19931652},{"batb":[[2,1.11,706.71]],"batl":[[2,1.49,780.77]],"ltp":1.17,"tv":28660.48,"id":8257797}],"tv":35727.96}]}
{"op":"mcm","clk":"4230608949","pt":1631534765301,"mc":[{"id":"1.187557146","rc":[{"trd":[[1.15,950.05]],"batb":[[0,1.15,146.04]],"ltp":1.15,"tv":28874.43,"id":8257797}],"tv":35941.91}]}
{"op":"mcm","clk":"4230609486","pt":1631534769905,"mc":[{"id":"1.187557146","rc":[{"batl":[[0,1.2,147.38]],"ltp":1.15,"tv":28874.43,"id":8257797}]}]}
{"op":"mcm","clk":"4230609861","pt":1631534773113,"mc":[{"id":"1.187557146","rc":[{"trd":[[1.15,1005.95],[1.18,691.45]],"batb":[[0,1.15,118.09]],"ltp":1.15,"tv":28964.61,"id":8257797}],"tv":36032.09}]}
{"op":"mcm","clk":"4230609963","pt":1631534774008,"mc":[{"id":"1.187557146","rc":[{"trd":[[1.15,1045.96]],"batb":[[0,1.15,98.07]],"ltp":1.15,"tv":29004.62,"id":8257797}],"tv":36072.1}]}
{"op":"mcm","clk":"4230610187","pt":1631534776119,"mc":[{"id":"1.187557146","rc":[{"trd":[[1.18,711.99]],"batb":[[0,1.18,6.87],[1,1.15,98.07],[2,1.13,99.12]],"batl":[[0,1.19,15.76],[1,1.2,147.38],[2,1.21,139.5]],"ltp":1.18,"tv":29025.16,"id":8257797}],"tv":36092.64}]}
{"op":"mcm","clk":"4230610615","pt":1631534779928,"mc":[{"id":"1.187557146","rc":[{"trd":[[1.15,1050.27],[1.18,725.73]],"batb":[[0,1.18,144.64],[1,1.15,95.92]],"ltp":1.15,"tv":29043.2,"id":8257797}],"tv":36110.68}]}
{"op":"mcm","clk":"4230610916","pt":1631534782346,"mc":[{"id":"1.187557146","rc":[{"batb":[[0,5.5,30.13],[1,3.4,25.36],[2,1.25,20]],"batl":[[0,990,0.01],[1,8.6,0],[2,8.8,0]],"ltp":6.4,"tv":7067.47,"id":19931652},{"batb":[[2,1.13,49.39]],"batl":[[0,1.49,780.77],[1,3.8,27.65],[2,8.8,7.23]],"ltp":1.15,"tv":29043.2,"id":8257797}]}]}
{"op":"mcm","clk":"4230610958","pt":1631534782728,"mc":[{"id":"1.187557146","rc":[{"batb":[[0,3.4,25.36],[1,1.25,20],[2,1.01,105.7]],"ltp":6.4,"tv":7067.47,"id":19931652},{"batb":[[1,1.11,681.57],[2,1.06,584.96]],"ltp":1.15,"tv":29043.2,"id":8257797}]}]}
{"op":"mcm","clk":"4230611112","pt":1631534783932,"mc":[{"id":"1.187557146","rc":[{"batb":[[0,1.11,681.57],[1,1.06,584.96],[2,1.04,7.23]],"ltp":1.15,"tv":29043.2,"id":8257797}]}]}
{"op":"mcm","clk":"4230611199","pt":1631534784666,"mc":[{"id":"1.187557146","rc":[{"batb":[[0,1.06,584.96],[1,1.04,7.23],[2,1.03,7.23]],"batl":[[0,3.8,27.74],[1,8.8,7.23],[2,44,7.23]],"ltp":1.15,"tv":29043.2,"id":8257797}]}]}
{"op":"mcm","clk":"4230611356","pt":1631534786131,"mc":[{"id":"1.187557146","rc":[{"batb":[[0,3.5,23.77]],"ltp":6.4,"tv":7067.47,"id":19931652},{"batb":[[0,1.06,7.23],[1,1.05,603.84],[2,1.04,7.23]],"ltp":1.15,"tv":29043.2,"id":8257797}]}]}
{"op":"mcm","clk":"4230611468","pt":1631534787278,"mc":[{"id":"1.187557146","rc":[{"batl":[[0,1.18,18.18],[1,3.8,27.74],[2,8.8,7.23]],"ltp":1.15,"tv":29043.2,"id":8257797}]}]}
{"op":"mcm","clk":"4230611743","pt":1631534789947,"mc":[{"id":"1.187557146","rc":[{"batl":[[0,1.18,16.18]],"ltp":1.15,"tv":29043.2,"id":8257797}]}]}
{"op":"mcm","clk":"4230611850","pt":1631534790942,"mc":[{"id":"1.187557146","rc":[{"trd":[[6.4,15.73]],"ltp":6.4,"tv":7070.45,"id":19931652},{"trd":[[1.18,741.91]],"batl":[[0,3.8,27.74],[1,8.8,7.23],[2,44,7.23]],"ltp":1.18,"tv":29059.38,"id":8257797}],"tv":36129.84}]}
{"op":"mcm","clk":"4230612083","pt":1631534793074,"mc":[{"id":"1.187557146","rc":[{"batb":[[0,1.13,626.87],[1,1.06,7.23],[2,1.05,603.84]],"batl":[[0,1.53,732.35],[1,3.8,27.65],[2,8.8,7.23]],"ltp":1.18,"tv":29059.38,"id":8257797}]}]}
{"op":"mcm","clk":"4230612324","pt":1631534794970,"mc":[{"id":"1.187557146","rc":[{"batb":[[0,1.06,7.23],[1,1.05,603.84],[2,1.04,7.23]],"batl":[[0,3.8,27.74],[1,8.8,7.23],[2,44,7.23]],"ltp":1.18,"tv":29059.38,"id":8257797}]}]}
{"op":"mcm","clk":"4230612788","pt":1631534798959,"mc":[{"id":"1.187557146","rc":[{"batb":[[0,1.07,45.08],[1,1.06,7.23],[2,1.05,611.07]],"ltp":1.18,"tv":29059.38,"id":8257797}]}]}
{"op":"mcm","clk":"4230613199","pt":1631534802272,"mc":[{"id":"1.187557146","rc":[{"batb":[[0,10,20],[1,3.5,23.77],[2,1.25,20]],"batl":[[0,13.5,3.53],[1,17.5,60.41],[2,990,0.01]],"ltp":6.4,"tv":7070.45,"id":19931652},{"trd":[[1.07,1067.39]],"batb":[[0,1.07,8.91]],"batl":[[0,1.09,36.61],[1,1.1,3750],[2,1.11,386.2]],"ltp":1.07,"tv":29131.71,"id":8257797}],"tv":36202.17}]}
{"op":"mcm","clk":"4230613301","pt":1631534803276,"mc":[{"id":"1.187557146","rc":[{"batb":[[0,10,4],[1,9.6,18.33],[2,5.2,34.64]],"ltp":6.4,"tv":7070.45,"id":19931652},{"batb":[[2,1.05,664.23]],"batl":[[1,1.11,362.3],[2,3.8,27.74]],"ltp":1.07,"tv":29131.71,"id":8257797}]}]}
{"op":"mcm","clk":"4230613430","pt":1631534804269,"mc":[{"id":"1.187557146","rc":[{"batl":[[0,10.5,3],[1,13.5,3.53],[2,17.5,60.41]],"ltp":6.4,"tv":7070.45,"id":19931652},{"trd":[[1.09,461.84],[1.11,1228.13]],"batl":[[0,1.11,255.74],[1,1.21,1352],[2,1.37,1033.99]],"ltp":1.11,"tv":29418.05,"id":8257797}],"tv":36488.51}]}
{"op":"mcm","clk":"4230613450","pt":1631534804480,"mc":[{"id":"1.187557146","rc":[{"batb":[[0,1.07,16.14]],"ltp":1.11,"tv":29418.05,"id":8257797}]}]}
{"op":"mcm","clk":"4230613757","pt":1631534807271,"mc":[{"id":"1.187557146","rc":[{"trd":[[10.5,3],[13.5,18.89]],"batl":[[0,17.5,60.41],[1,21,18.87],[2,990,0.01]],"ltp":13.5,"tv":7076.98,"id":19931652},{"trd":[[1.07,1099.67],[1.08,722.27],[1.1,611.98]],"batb":[[0,1.06,7.23],[1,1.05,664.23],[2,1.04,1273.42]],"batl":[[0,1.07,266.02],[1,1.11,255.74],[2,1.21,1352]],"ltp":1.07,"tv":29523.08,"id":8257797}],"tv":36600.07}]}
{"op":"mcm","clk":"4230613770","pt":1631534807376,"mc":[{"id":"1.187557146","rc":[{"batl":[[1,990,0.01],[2,990,0]],"ltp":13.5,"tv":7076.98,"id":19931652},{"batl":[[0,1.11,255.74],[1,1.21,1352],[2,1.37,1033.99]],"ltp":1.07,"tv":29523.08,"id":8257797}]}]}
{"op":"mcm","clk":"4230614018","pt":1631534809588,"mc":[{"id":"1.187557146","rc":[{"batl":[[1,55,2],[2,990,0.01]],"ltp":13.5,"tv":7076.98,"id":19931652}]}]}
{"op":"mcm","clk":"4230614568","pt":1631534814273,"mc":[{"id":"1.187557146","rc":[{"trd":[[10,11.58]],"batb":[[0,9.6,18.46],[1,5.2,34.64],[2,1.25,20]],"ltp":10.0,"tv":7084.72,"id":19931652},{"batb":[[0,1.05,664.23],[1,1.04,1273.42],[2,1.03,34.33]],"ltp":1.07,"tv":29523.08,"id":8257797}],"tv":36607.81}]}
{"op":"mcm","clk":"4230614593","pt":1631534814484,"mc":[{"id":"1.187557146","rc":[{"trd":[[10,12.34]],"batb":[[0,9.6,18.33]],"ltp":10.0,"tv":7085.48,"id":19931652},{"trd":[[1.11,1232.63]],"batl":[[0,1.11,251.24]],"ltp":1.11,"tv":29527.58,"id":8257797}],"tv":36613.07}]}
{"op":"mcm","clk":"4230614736","pt":1631534815481,"mc":[{"id":"1.187557146","rc":[{"batl":[[0,1.09,50.26],[1,1.11,251.24],[2,1.21,1352]],"ltp":1.11,"tv":29527.58,"id":8257797}]}]}
{"op":"mcm","clk":"4230615221","pt":1631534819276,"mc":[{"id":"1.187557146","rc":[{"batl":[[0,55,2],[1,990,0.01],[2,990,0]],"ltp":10.0,"tv":7085.48,"id":19931652},{"batb":[[0,1.08,124.02],[1,1.05,657],[2,1.04,1273.42]],"batl":[[1,1.21,1352],[2,1.37,1033.99]],"ltp":1.11,"tv":29527.58,"id":8257797}]}]}
{"op":"mcm","clk":"4230615310","pt":1631534820010,"mc":[{"id":"1.187557146","rc":[{"batb":[[0,5.2,34.64],[1,1.25,20],[2,1.01,105.7]],"ltp":10.0,"tv":7085.48,"id":19931652},{"batb":[[1,1.04,1273.43],[2,1.03,7.23]],"batl":[[1,1.37,1033.99],[2,3.8,27.65]],"ltp":1.11,"tv":29527.58,"id":8257797}]}]}
{"op":"mcm","clk":"4230615399","pt":1631534820589,"mc":[{"id":"1.187557146","rc":[{"batb":[[1,1.04,1266.2]],"ltp":1.11,"tv":29527.58,"id":8257797}]}]}
{"op":"mcm","clk":"4230615514","pt":1631534821490,"mc":[{"id":"1.187557146","rc":[{"batb":[[1,1.03,7.25],[2,1.02,1128.22]],"batl":[[1,3.8,27.74],[2,8.8,7.23]],"ltp":1.11,"tv":29527.58,"id":8257797}]}]}
{"op":"mcm","clk":"4230615674","pt":1631534822700,"mc":[{"id":"1.187557146","rc":[{"batl":[[0,990,0.01],[1,990,0]],"ltp":10.0,"tv":7085.48,"id":19931652},{"batb":[[0,1.03,7.25],[1,1.02,7.23],[2,1.01,7.23]],"ltp":1.11,"tv":29527.58,"id":8257797}]}]}
{"op":"mcm","clk":"4230615995","pt":1631534825124,"mc":[{"id":"1.187557146","rc":[{"batb":[[0,1.03,8.02]],"batl":[[0,3.8,27.74],[1,8.8,7.23],[2,44,7.23]],"ltp":1.11,"tv":29527.58,"id":8257797}]}]}
{"op":"mcm","clk":"4230616187","pt":1631534826330,"mc":[{"id":"1.187557146","rc":[{"batb":[[2,1.01,2312.62]],"batl":[[0,1.11,21.5],[1,3.8,27.74],[2,8.8,7.23]],"ltp":1.11,"tv":29527.58,"id":8257797}]}]}
{"op":"mcm","clk":"4230616233","pt":1631534826593,"mc":[{"id":"1.187557146","rc":[{"batb":[[2,1.01,7.23]],"batl":[[0,3.8,27.74],[1,8.8,7.23],[2,44,7.23]],"ltp":1.11,"tv":29527.58,"id":8257797}]}]}
{"op":"mcm","clk":"4230616414","pt":1631534828119,"mc":[{"id":"1.187557146","rc":[{"trd":[[1.08,731.3],[1.09,463.39]],"batb":[[0,1.06,955.59],[1,1.03,7.25],[2,1.02,7.23]],"batl":[[0,1.08,44.97],[1,1.4,949.63],[2,3.8,27.65]],"ltp":1.08,"tv":29538.16,"id":8257797}],"tv":36623.64}]}
{"op":"mcm","clk":"4230616529","pt":1631534829011,"mc":[{"id":"1.187557146","rc":[{"batb":[[0,1.03,7.25],[1,1.02,221.64],[2,1.01,7.23]],"batl":[[1,3.8,27.74],[2,8.8,7.23]],"ltp":1.08,"tv":29538.16,"id":8257797}]}]}
{"op":"mcm","clk":"4230616617","pt":1631534829795,"mc":[{"id":"1.187557146","rc":[{"batl":[[0,55,2],[1,60,2],[2,65,2]],"ltp":10.0,"tv":7085.48,"id":19931652},{"batb":[[1,1.02,1562.25],[2,1.01,2430.14]],"batl":[[0,3.8,27.74],[1,8.8,7.23],[2,44,7.23]],"ltp":1.08,"tv":29538.16,"id":8257797}]}]}
{"op":"mcm","clk":"4230616777","pt":1631534831103,"mc":[{"id":"1.187557146","rc":[{"batb":[[0,1.09,19.3],[1,1.03,7.25],[2,1.02,1562.25]],"ltp":1.08,"tv":29538.16,"id":8257797}]}]}
{"op":"mcm","clk":"4230617096","pt":1631534833922,"mc":[{"id":"1.187557146","rc":[{"batl":[[0,1.23,45.08],[1,3.8,27.74],[2,8.8,7.23]],"ltp":1.08,"tv":29538.16,"id":8257797}]}]}
{"op":"mcm","clk":"4230617161","pt":1631534834496,"mc":[{"id":"1.187557146","rc":[{"batb":[[0,1.19,180.81],[1,1.09,19.3],[2,1.03,7.25]],"ltp":1.08,"tv":29538.16,"id":8257797}]}]}
{"op":"mcm","clk":"4230617310","pt":1631534835705,"mc":[{"id":"1.187557146","rc":[{"trd":[[1.23,304.78]],"batl":[[0,1.23,8.91]],"ltp":1.23,"tv":29610.49,"id":8257797}],"tv":36695.98}]}
{"op":"mcm","clk":"4230617713","pt":1631534839444,"mc":[{"id":"1.187557146","rc":[{"batb":[[0,1.09,19.3],[1,1.03,7.25],[2,1.02,1562.25]],"ltp":1.23,"tv":29610.49,"id":8257797}]}]}
{"op":"mcm","clk":"4230617923","pt":1631534841449,"mc":[{"id":"1.187557146","rc":[{"batl":[[0,1.19,2],[1,1.23,8.91],[2,3.8,27.74]],"ltp":1.23,"tv":29610.49,"id":8257797}]}]}
{"op":"mcm","clk":"4230618112","pt":1631534843338,"mc":[{"id":"1.187557146","rc":[{"trd":[[1.19,608.25],[1.23,318.14]],"batl":[[0,1.23,2.23],[1,3.8,27.74],[2,8.8,7.23]],"ltp":1.23,"tv":29627.85,"id":8257797}],"tv":36713.33}]}
{"op":"mcm","clk":"4230618458","pt":1631534846321,"mc":[{"id":"1.187557146","rc":[{"batb":[[0,26,6.56],[1,5.2,34.64],[2,1.25,20]],"ltp":10.0,"tv":7085.48,"id":19931652},{"trd":[[1.03,2508.96],[1.04,524.46],[1.09,501.99]],"batb":[[0,1.02,1562.25],[1,1.01,2430.14],[2,1.02,0]],"batl":[[0,1.03,111.26],[1,1.04,125.62],[2,1.23,2.23]],"ltp":1.03,"tv":29701.32,"id":8257797}],"tv":36786.81}]}
{"op":"mcm","clk":"4230618532","pt":1631534847257,"mc":[{"id":"1.187557146","rc":[{"trd":[[26,7.97]],"batb":[[0,26,2.04],[1,20,7.45],[2,12,53]],"ltp":26.0,"tv":7092.0,"id":19931652},{"trd":[[1.03,2731.48],[1.04,838.82]],"batl":[[0,1.09,1578],[1,1.1,842],[2,1.17,1578]],"ltp":1.04,"tv":30238.2,"id":8257797}],"tv":37330.21}]}
{"op":"mcm","clk":"4230619068","pt":1631534852031,"mc":[{"id":"1.187557146","rc":[{"trd":[[20,0.23],[26,12.05]],"batb":[[0,20,7.33],[1,12,53],[2,11,69.38]],"ltp":20.0,"tv":7096.31,"id":19931652}],"tv":37334.52}]}
{"op":"mcm","clk":"4230619218","pt":1631534853342,"mc":[{"id":"1.187557146","rc":[{"batb":[[0,1.02,1555.02],[1,1.01,2422.91]],"ltp":1.04,"tv":30238.2,"id":8257797}]}]}
{"op":"mcm","clk":"4230619451","pt":1631534855342,"mc":[{"id":"1.187557146","rc":[{"trd":[[20,1.05]],"batb":[[0,20,6.92]],"ltp":20.0,"tv":7097.13,"id":19931652}],"tv":37335.34}]}
{"op":"mcm","clk":"4230619648","pt":1631534857174,"mc":[{"id":"1.187557146","rc":[{"batb":[[0,1.04,5],[1,1.02,1555.02],[2,1.01,2422.91]],"ltp":1.04,"tv":30238.2,"id":8257797}]}]}
{"op":"mcm","clk":"4230619766","pt":1631534858377,"mc":[{"id":"1.187557146","rc":[{"trd":[[20,1.2]],"batb":[[0,20,6.77]],"ltp":20.0,"tv":7097.29,"id":19931652},{"trd":[[1.06,1384.07]],"ltp":1.06,"tv":30241.09,"id":8257797}],"tv":37338.38}]}
{"op":"mcm","clk":"4230619916","pt":1631534859691,"mc":[{"id":"1.187557146","rc":[{"trd":[[1.04,848.82]],"batb":[[0,1.02,1555.02],[1,1.01,2422.91],[2,1.01,0]],"ltp":1.04,"tv":30251.09,"id":8257797}],"tv":37348.38}]}
{"op":"mcm","clk":"4230620043","pt":1631534860893,"mc":[{"id":"1.187557146","rc":[{"batb":[[0,1.04,3.34],[1,1.02,1555.02],[2,1.01,2422.91]],"batl":[[0,1.06,242],[1,1.09,1578],[2,1.1,842]],"ltp":1.04,"tv":30251.09,"id":8257797}]}]}
{"op":"mcm","clk":"4230620099","pt":1631534861360,"mc":[{"id":"1.187557146","rc":[{"batb":[[0,1.02,1555.02],[1,1.01,2422.91],[2,1.01,0]],"batl":[[0,1.03,14.7],[1,1.06,242],[2,1.09,1578]],"ltp":1.04,"tv":30251.09,"id":8257797}]}]}
{"op":"mcm","clk":"4230620233","pt":1631534862697,"mc":[{"id":"1.187557146","rc":[{"batl":[[0,50,5.8],[1,55,2],[2,60,2]],"ltp":20.0,"tv":7097.29,"id":19931652},{"batl":[[1,1.04,75.63],[2,1.06,242]],"ltp":1.04,"tv":30251.09,"id":8257797}]}]}
{"op":"mcm","clk":"4230620424","pt":1631534864286,"mc":[{"id":"1.187557146","rc":[{"batl":[[0,55,2],[1,60,2],[2,65,2]],"ltp":20.0,"tv":7097.29,"id":19931652},{"batl":[[1,1.06,242],[2,1.08,7.23]],"ltp":1.04,"tv":30251.09,"id":8257797}]}]}
{"op":"mcm","clk":"4230620493","pt":1631534864861,"mc":[{"id":"1.187557146","rc":[{"batb":[[0,11,12.38],[1,6.8,93],[2,1.25,20]],"batl":[[0,520,35.96],[1,990,0.01],[2,65,0]],"ltp":20.0,"tv":7097.29,"id":19931652},{"batb":[[0,1.02,214.41],[1,1.01,0]],"ltp":1.04,"tv":30251.09,"id":8257797}]}]}
{"op":"mcm","clk":"4230620640","pt":1631534866269,"mc":[{"id":"1.187557146","rc":[{"batl":[[0,990,0.01],[1,990,0]],"ltp":20.0,"tv":7097.29,"id":19931652},{"trd":[[1.03,2736.52]],"batl":[[0,1.03,12.18],[1,1.08,7.23],[2,1.17,1578.02]],"ltp":1.03,"tv":30256.13,"id":8257797}],"tv":37353.42}]}
{"op":"mcm","clk":"4230620809","pt":1631534867993,"mc":[{"id":"1.187557146","rc":[{"batb":[[2,6.4,107]],"ltp":20.0,"tv":7097.29,"id":19931652},{"trd":[[1.03,2736.8]],"batl":[[0,1.03,12.04]],"ltp":1.03,"tv":30256.41,"id":8257797}],"tv":37353.7}]}
{"op":"mcm","clk":"4230621398","pt":1631534873349,"mc":[{"id":"1.187557146","rc":[{"batb":[[0,6.8,93],[1,6.4,107],[2,6.2,110]],"ltp":20.0,"tv":7097.29,"id":19931652}]}]}
{"op":"mcm","clk":"4230621498","pt":1631534874348,"mc":[{"id":"1.187557146","marketDefinition":{"bspMarket":false,"turnInPlayEnabled":true,"persistenceEnabled":true,"marketBaseRate":5.0,"eventId":"30895970","eventTypeId":"2","numberOfWinners":1,"bettingType":"ODDS","marketType":"MATCH_ODDS","marketTime":"2021-09-13T09:57:00.000Z","suspendTime":"2021-09-13T09:57:00.000Z","bspReconciled":false,"complete":true,"inPlay":true,"crossMatching":true,"runnersVoidable":false,"numberOfActiveRunners":2,"betDelay":3,"status":"SUSPENDED","runners":[{"status":"ACTIVE","sortPriority":1,"id":8257797,"name":"Alessandro Bega"},{"status":"ACTIVE","sortPriority":2,"id":19931652,"name":"Titouan Droguet"}],"regulators":["MR_INT"],"countryCode":"FR","discountAllowed":true,"timezone":"UTC","openDate":"2021-09-13T09:57:00.000Z","version":4030624268,"name":"Match Odds","eventName":"Bega v Ti Droguet"},"rc":[{"batb":[[0,1.01,214.41]],"ltp":1.03,"tv":30256.41,"id":8257797}]}]}
{"op":"mcm","clk":"4230621898","pt":1631534877939,"mc":[{"id":"1.187557146","rc":[{"batb":[[0,1.01,105.7],[1,6.4,0],[2,6.2,0]],"ltp":20.0,"tv":7097.29,"id":19931652},{"batl":[[0,1.72,0.16],[1,1.08,0],[2,1.17,0]],"ltp":1.03,"tv":30256.41,"id":8257797}]}]}
{"op":"mcm","clk":"4230626115","pt":1631534919004,"mc":[{"id":"1.187557146","tv":0.0}]}
{"op":"mcm","clk":"4230626294","pt":1631534920596,"mc":[{"id":"1.187557146","marketDefinition":{"bspMarket":false,"turnInPlayEnabled":true,"persistenceEnabled":true,"marketBaseRate":5.0,"eventId":"30895970","eventTypeId":"2","numberOfWinners":1,"bettingType":"ODDS","marketType":"MATCH_ODDS","marketTime":"2021-09-13T09:57:00.000Z","suspendTime":"2021-09-13T09:57:00.000Z","bspReconciled":false,"complete":true,"inPlay":true,"crossMatching":false,"runnersVoidable":false,"numberOfActiveRunners":0,"betDelay":3,"status":"CLOSED","settledTime":"2021-09-13T12:08:28.000Z","runners":[{"status":"WINNER","sortPriority":1,"id":8257797,"name":"Alessandro Bega"},{"status":"LOSER","sortPriority":2,"id":19931652,"name":"Titouan Droguet"}],"regulators":["MR_INT"],"countryCode":"FR","discountAllowed":true,"timezone":"UTC","openDate":"2021-09-13T09:57:00.000Z","version":4030624930,"name":"Match Odds","eventName":"Bega v Ti Droguet"}}]}
