{"op":"mcm","clk":"4216617668","pt":1631553720705,"mc":[{"id":"1.187566733","rc":[{"batb":[[0,1.78,106.89],[1,1.76,106.57],[2,1.69,39.27]],"batl":[[1,1.96,56.18],[2,1.98,75.11]],"ltp":1.86,"tv":2466.83,"id":8734382}]}]}
{"op":"mcm","clk":"4216617895","pt":1631553722615,"mc":[{"id":"1.187566733","rc":[{"batl":[[0,1.83,46.14],[1,1.86,184.9],[2,1.96,56.18]],"ltp":1.86,"tv":2466.83,"id":8734382}]}]}
{"op":"mcm","clk":"4216618133","pt":1631553724730,"mc":[{"id":"1.187566733","rc":[{"trd":[[1.83,1.05]],"batl":[[0,1.83,45.09]],"ltp":1.83,"tv":2467.88,"id":8734382},{"trd":[[2.2,0.87]],"ltp":2.2,"tv":24990.99,"id":9323645}],"tv":27458.87}]}
{"op":"mcm","clk":"4216618284","pt":1631553726175,"mc":[{"id":"1.187566733","rc":[{"batl":[[2,1.96,0]],"ltp":1.83,"tv":2467.88,"id":8734382}]}]}
{"op":"mcm","clk":"4216618600","pt":1631553729060,"mc":[{"id":"1.187566733","rc":[{"batl":[[1,1.84,138.9],[2,1.85,40.76]],"ltp":1.83,"tv":2467.88,"id":8734382},{"batb":[[0,2.16,94.91],[1,2.14,31],[2,2,44.48]],"batl":[[0,2.24,9],[1,2.28,328.79]],"ltp":2.2,"tv":24990.99,"id":9323645}]}]}
{"op":"mcm","clk":"4216618705","pt":1631553730158,"mc":[{"id":"1.187566733","rc":[{"trd":[[1.83,6.62]],"batb":[[2,1.75,85.72]],"batl":[[0,1.83,39.53]],"ltp":1.83,"tv":2473.44,"id":8734382},{"trd":[[2.2,5.5]],"batb":[[0,2.16,54.31],[2,2.08,39.53]],"ltp":2.2,"tv":24995.62,"id":9323645}],"tv":27469.07}]}
{"op":"mcm","clk":"4216618725","pt":1631553730329,"mc":[{"id":"1.187566733","rc":[{"batb":[[2,1.75,17.14]],"batl":[[1,1.84,106.29],[2,1.85,24.46]],"ltp":1.83,"tv":2473.44,"id":8734382}]}]}
{"op":"mcm","clk":"4216618971","pt":1631553732629,"mc":[{"id":"1.187566733","rc":[{"trd":[[1.83,9.18]],"batl":[[0,1.83,38.25]],"ltp":1.83,"tv":2476.0,"id":8734382}],"tv":27471.63}]}
{"op":"mcm","clk":"4216619145","pt":1631553733945,"mc":[{"id":"1.187566733","rc":[{"batb":[[0,1.78,150.95]],"ltp":1.83,"tv":2476.0,"id":8734382}]}]}
{"op":"mcm","clk":"4216619327","pt":1631553735728,"mc":[{"id":"1.187566733","rc":[{"batb":[[0,1.79,43.06],[1,1.78,150.95],[2,1.76,106.57]],"ltp":1.83,"tv":2476.0,"id":8734382}]}]}
{"op":"mcm","clk":"4216619790","pt":1631553740264,"mc":[{"id":"1.187566733","rc":[{"batl":[[1,1.84,48.91]],"ltp":1.83,"tv":2476.0,"id":8734382}]}]}
{"op":"mcm","clk":"4216620124","pt":1631553743154,"mc":[{"id":"1.187566733","rc":[{"trd":[[1.8,11.2]],"batb":[[0,1.78,150.95],[1,1.76,106.57],[2,1.75,17.14]],"batl":[[0,1.8,173.7],[1,1.83,38.25],[2,1.84,48.91]],"ltp":1.8,"tv":2487.2,"id":8734382},{"trd":[[2.24,9]],"batb":[[0,2.16,54.92]],"batl":[[0,2.28,328.79],[1,2.28,0]],"ltp":2.24,"tv":25004.62,"id":9323645}],"tv":27491.83}]}
{"op":"mcm","clk":"4216620230","pt":1631553744056,"mc":[{"id":"1.187566733","rc":[{"trd":[[1.8,32.42]],"batl":[[0,1.8,152.48]],"ltp":1.8,"tv":2508.42,"id":8734382},{"trd":[[2.24,27.26]],"batb":[[0,2.16,54.31]],"ltp":2.24,"tv":25022.89,"id":9323645}],"tv":27531.31}]}
{"op":"mcm","clk":"4216620451","pt":1631553746053,"mc":[{"id":"1.187566733","rc":[{"trd":[[1.8,37.2]],"batb":[[1,1.77,42.4],[2,1.76,106.57]],"batl":[[0,1.8,147.7]],"ltp":1.8,"tv":2513.21,"id":8734382},{"trd":[[2.24,31.11]],"ltp":2.24,"tv":25026.73,"id":9323645}],"tv":27539.94}]}
{"op":"mcm","clk":"4216620566","pt":1631553747056,"mc":[{"id":"1.187566733","rc":[{"batl":[[1,1.84,48.91],[2,1.85,125.72]],"ltp":1.8,"tv":2513.21,"id":8734382}]}]}
{"op":"mcm","clk":"4216620635","pt":1631553747744,"mc":[{"id":"1.187566733","rc":[{"trd":[[1.8,88.91]],"batl":[[0,1.8,95.99]],"ltp":1.8,"tv":2564.91,"id":8734382},{"trd":[[2.24,72.66]],"ltp":2.24,"tv":25068.28,"id":9323645}],"tv":27633.2}]}
{"op":"mcm","clk":"4216620754","pt":1631553748848,"mc":[{"id":"1.187566733","rc":[{"batb":[[0,1.78,248.95]],"ltp":1.8,"tv":2564.91,"id":8734382}]}]}
{"op":"mcm","clk":"4216620870","pt":1631553749844,"mc":[{"id":"1.187566733","rc":[{"trd":[[1.78,76.5]],"batb":[[0,1.78,210.7]],"ltp":1.78,"tv":2641.41,"id":8734382}],"tv":27709.7}]}
{"op":"mcm","clk":"4216620938","pt":1631553750685,"mc":[{"id":"1.187566733","rc":[{"batl":[[0,1.84,48.91],[1,1.85,24.46],[2,1.86,43.25]],"ltp":1.78,"tv":2641.41,"id":8734382}]}]}
{"op":"mcm","clk":"4216621044","pt":1631553751847,"mc":[{"id":"1.187566733","rc":[{"batb":[[0,1.78,112.7]],"ltp":1.78,"tv":2641.41,"id":8734382},{"batb":[[0,2.18,42.69],[1,2.16,54.31],[2,2.14,31]],"batl":[[0,2.2,8.53],[1,2.28,328.79]],"ltp":2.24,"tv":25068.28,"id":9323645}]}]}
{"op":"mcm","clk":"4216621094","pt":1631553752370,"mc":[{"id":"1.187566733","rc":[{"trd":[[1.83,9.57]],"ltp":1.83,"tv":2641.81,"id":8734382},{"trd":[[2.2,5.83]],"batb":[[0,2.16,54.31],[1,2.14,31],[2,2.08,39.53]],"batl":[[0,2.2,8.21]],"ltp":2.2,"tv":25068.61,"id":9323645}],"tv":27710.42}]}
{"op":"mcm","clk":"4216621285","pt":1631553754189,"mc":[{"id":"1.187566733","rc":[{"trd":[[1.78,248.74],[1.83,19.44]],"batb":[[0,1.79,44.58],[1,1.78,26.58],[2,1.77,42.4]],"batl":[[2,1.86,24.46]],"ltp":1.78,"tv":2823.92,"id":8734382},{"trd":[[2.2,14.04]],"batl":[[0,2.28,328.79],[1,2.28,0]],"ltp":2.2,"tv":25076.81,"id":9323645}],"tv":27900.74}]}
{"op":"mcm","clk":"4216621314","pt":1631553754467,"mc":[{"id":"1.187566733","rc":[{"batb":[[1,1.75,17.14],[2,1.74,8.58]],"ltp":1.78,"tv":2823.92,"id":8734382}]}]}
{"op":"mcm","clk":"4216621608","pt":1631553757082,"mc":[{"id":"1.187566733","rc":[{"batb":[[0,1.77,94.43],[1,1.75,125.94]],"batl":[[0,1.83,110.48],[1,1.84,48.91],[2,1.85,116.27]],"ltp":1.78,"tv":2823.92,"id":8734382},{"batl":[[0,2.28,340.8]],"ltp":2.2,"tv":25076.81,"id":9323645}]}]}
{"op":"mcm","clk":"4216621643","pt":1631553757361,"mc":[{"id":"1.187566733","rc":[{"batb":[[1,1.76,43.89],[2,1.75,125.94]],"ltp":1.78,"tv":2823.92,"id":8734382}]}]}
{"op":"mcm","clk":"4216621749","pt":1631553758460,"mc":[{"id":"1.187566733","rc":[{"batb":[[0,1.8,1.8],[1,1.77,94.43],[2,1.76,43.89]],"ltp":1.78,"tv":2823.92,"id":8734382}]}]}
{"op":"mcm","clk":"4216621875","pt":1631553759576,"mc":[{"id":"1.187566733","rc":[{"batl":[[0,1.82,17.21],[1,1.83,110.48],[2,1.84,48.91]],"ltp":1.78,"tv":2823.92,"id":8734382}]}]}
{"op":"mcm","clk":"4216621950","pt":1631553760258,"mc":[{"id":"1.187566733","rc":[{"batb":[[1,1.78,40.27],[2,1.77,94.43]],"ltp":1.78,"tv":2823.92,"id":8734382}]}]}
{"op":"mcm","clk":"4216622076","pt":1631553761575,"mc":[{"id":"1.187566733","rc":[{"batb":[[1,1.79,39.02],[2,1.78,40.27]],"ltp":1.78,"tv":2823.92,"id":8734382}]}]}
{"op":"mcm","clk":"4216622213","pt":1631553762781,"mc":[{"id":"1.187566733","rc":[{"trd":[[1.82,2.18]],"batb":[[0,1.79,39.02],[1,1.78,40.27],[2,1.77,94.43]],"batl":[[0,1.82,15.03]],"ltp":1.82,"tv":2826.1,"id":8734382},{"trd":[[2.2,15.84]],"ltp":2.2,"tv":25078.61,"id":9323645}],"tv":27904.72}]}
{"op":"mcm","clk":"4216622421","pt":1631553764767,"mc":[{"id":"1.187566733","rc":[{"trd":[[1.78,254.34],[1.79,78.04]],"batb":[[0,1.78,37.47],[1,1.77,94.43],[2,1.76,43.89]],"ltp":1.78,"tv":2909.74,"id":8734382}],"tv":27988.35}]}
{"op":"mcm","clk":"4216622579","pt":1631553766201,"mc":[{"id":"1.187566733","rc":[{"batb":[[1,1.76,43.89],[2,1.75,17.14]],"batl":[[1,1.83,35.83]],"ltp":1.78,"tv":2909.74,"id":8734382}]}]}
{"op":"mcm","clk":"4216622600","pt":1631553766404,"mc":[{"id":"1.187566733","rc":[{"batb":[[0,1.76,43.89],[1,1.75,17.14],[2,1.74,8.58]],"ltp":1.78,"tv":2909.74,"id":8734382}]}]}
{"op":"mcm","clk":"4216622860","pt":1631553769187,"mc":[{"id":"1.187566733","rc":[{"batb":[[0,1.78,164.11],[1,1.76,43.89],[2,1.75,17.14]],"ltp":1.78,"tv":2909.74,"id":8734382}]}]}
{"op":"mcm","clk":"4216622979","pt":1631553770192,"mc":[{"id":"1.187566733","rc":[{"batb":[[0,1.79,162.02],[1,1.78,164.11],[2,1.76,43.89]],"batl":[[1,1.83,22.31]],"ltp":1.78,"tv":2909.74,"id":8734382}]}]}
{"op":"mcm","clk":"4216623036","pt":1631553770612,"mc":[{"id":"1.187566733","rc":[{"batb":[[2,1.77,83.12]],"batl":[[0,1.89,75.06],[1,1.91,83.52],[2,1.95,29.7]],"ltp":1.78,"tv":2909.74,"id":8734382},{"batb":[[0,2.14,31],[1,2.08,39.53],[2,1.5,107.72]],"ltp":2.2,"tv":25078.61,"id":9323645}]}]}
{"op":"mcm","clk":"4216623207","pt":1631553772079,"mc":[{"id":"1.187566733","rc":[{"batb":[[0,1.79,195.05]],"ltp":1.78,"tv":2909.74,"id":8734382}]}]}
{"op":"mcm","clk":"4216623285","pt":1631553772812,"mc":[{"id":"1.187566733","rc":[{"trd":[[1.79,182.92]],"batb":[[0,1.79,109.58]],"ltp":1.79,"tv":3014.61,"id":8734382}],"tv":28093.23}]}
{"op":"mcm","clk":"4216623375","pt":1631553773596,"mc":[{"id":"1.187566733","rc":[{"batb":[[2,2.04,7.87]],"ltp":2.2,"tv":25078.61,"id":9323645}]}]}
{"op":"mcm","clk":"4216623449","pt":1631553774283,"mc":[{"id":"1.187566733","rc":[{"batb":[[2,1.69,83.2]],"ltp":1.79,"tv":3014.61,"id":8734382}]}]}
{"op":"mcm","clk":"4216623874","pt":1631553777808,"mc":[{"id":"1.187566733","rc":[{"batl":[[0,2.2,2.62]],"ltp":2.2,"tv":25078.61,"id":9323645}]}]}
{"op":"mcm","clk":"4216623956","pt":1631553778500,"mc":[{"id":"1.187566733","rc":[{"batl":[[0,1.88,49.93],[1,1.89,75.06],[2,1.91,83.52]],"ltp":1.79,"tv":3014.61,"id":8734382}]}]}
{"op":"mcm","clk":"4216624086","pt":1631553779716,"mc":[{"id":"1.187566733","rc":[{"batb":[[0,1.78,164.11],[1,1.69,83.2],[2,1.68,62.42]],"ltp":1.79,"tv":3014.61,"id":8734382}]}]}
{"op":"mcm","clk":"4216625155","pt":1631553789018,"mc":[{"id":"1.187566733","rc":[{"batl":[[1,1.95,29.7],[2,1.91,0]],"ltp":1.79,"tv":3014.61,"id":8734382}]}]}
{"op":"mcm","clk":"4216625231","pt":1631553789813,"mc":[{"id":"1.187566733","rc":[{"batl":[[1,1.95,0]],"ltp":1.79,"tv":3014.61,"id":8734382}]}]}
{"op":"mcm","clk":"4216625335","pt":1631553790905,"mc":[{"id":"1.187566733","rc":[{"batb":[[0,1.69,83.2],[1,1.68,62.42],[2,1.63,44.73]],"ltp":1.79,"tv":3014.61,"id":8734382}]}]}
{"op":"mcm","clk":"4216625480","pt":1631553792193,"mc":[{"id":"1.187566733","rc":[{"batl":[[0,1.74,70.57],[1,1.75,51.43],[2,1.76,132.7]],"ltp":1.79,"tv":3014.61,"id":8734382},{"batb":[[0,2.32,14.53],[1,2.2,8.92],[2,2.14,31]],"batl":[[0,2.4,6.95],[1,2.42,287.42]],"ltp":2.2,"tv":25078.61,"id":9323645}]}]}
{"op":"mcm","clk":"4216625587","pt":1631553793141,"mc":[{"id":"1.187566733","rc":[{"trd":[[1.74,9.43]],"batb":[[2,1.67,89.82]],"batl":[[0,1.74,61.14]],"ltp":1.74,"tv":3024.04,"id":8734382},{"trd":[[2.34,7.01]],"batb":[[1,2.26,30.63],[2,2.2,8.92]],"ltp":2.34,"tv":25085.63,"id":9323645}],"tv":28109.67}]}
{"op":"mcm","clk":"4216625600","pt":1631553793240,"mc":[{"id":"1.187566733","rc":[{"batb":[[2,1.67,17.96]],"ltp":1.74,"tv":3024.04,"id":8734382}]}]}
{"op":"mcm","clk":"4216626019","pt":1631553797037,"mc":[{"id":"1.187566733","rc":[{"trd":[[1.73,22.22]],"batb":[[0,1.7,34.7],[1,1.69,83.2],[2,1.68,62.42]],"batl":[[0,1.73,11.88],[1,1.74,61.14],[2,1.75,51.43]],"ltp":1.73,"tv":3046.26,"id":8734382},{"trd":[[2.36,16.29]],"ltp":2.36,"tv":25101.92,"id":9323645}],"tv":28148.18}]}
{"op":"mcm","clk":"4216626063","pt":1631553797449,"mc":[{"id":"1.187566733","rc":[{"batb":[[0,1.71,79],[1,1.7,34.7],[2,1.69,83.2]],"ltp":1.73,"tv":3046.26,"id":8734382}]}]}
{"op":"mcm","clk":"4216626380","pt":1631553800657,"mc":[{"id":"1.187566733","rc":[{"batb":[[0,1.71,112.95]],"batl":[[1,1.74,86.94]],"ltp":1.73,"tv":3046.26,"id":8734382}]}]}
{"op":"mcm","clk":"4216626720","pt":1631553803918,"mc":[{"id":"1.187566733","rc":[{"trd":[[1.71,44.18]],"batb":[[0,1.71,90.86]],"ltp":1.71,"tv":3090.45,"id":8734382}],"tv":28192.37}]}
{"op":"mcm","clk":"4216627038","pt":1631553807030,"mc":[{"id":"1.187566733","rc":[{"trd":[[1.71,45.34]],"batb":[[0,1.71,90.28]],"ltp":1.71,"tv":3091.61,"id":8734382}],"tv":28193.53}]}
{"op":"mcm","clk":"4216627240","pt":1631553808927,"mc":[{"id":"1.187566733","rc":[{"batb":[[0,1.71,56.33],[1,1.55,53.96],[2,1.3,199.49]],"batl":[[0,1.88,75.97],[1,1.74,0],[2,1.75,0]],"ltp":1.71,"tv":3091.61,"id":8734382},{"batb":[[0,2.18,34.16],[1,2.14,31],[2,1.5,107.72]],"ltp":2.36,"tv":25101.92,"id":9323645}]}]}
{"op":"mcm","clk":"4216627305","pt":1631553809557,"mc":[{"id":"1.187566733","rc":[{"batb":[[0,1.55,53.96],[1,1.3,199.49],[2,1.25,167.57]],"ltp":1.71,"tv":3091.61,"id":8734382}]}]}
{"op":"mcm","clk":"4216627577","pt":1631553812155,"mc":[{"id":"1.187566733","rc":[{"batb":[[0,1.73,1.8],[1,1.6,103.36],[2,1.59,75.54]],"batl":[[0,1.81,81.62],[1,1.83,94.78],[2,1.84,31.53]],"ltp":1.71,"tv":3091.61,"id":8734382},{"batb":[[0,2.18,41.52],[2,2.12,8.04]],"ltp":2.36,"tv":25101.92,"id":9323645}]}]}
{"op":"mcm","clk":"4216627597","pt":1631553812366,"mc":[{"id":"1.187566733","rc":[{"batl":[[2,1.88,75.97]],"ltp":1.71,"tv":3091.61,"id":8734382},{"batb":[[0,2.18,34.16]],"ltp":2.36,"tv":25101.92,"id":9323645}]}]}
{"op":"mcm","clk":"4216627725","pt":1631553813530,"mc":[{"id":"1.187566733","rc":[{"batb":[[1,1.55,53.96],[2,1.3,199.49]],"batl":[[2,1.88,49.93]],"ltp":1.71,"tv":3091.61,"id":8734382}]}]}
{"op":"mcm","clk":"4216628002","pt":1631553816169,"mc":[{"id":"1.187566733","rc":[{"trd":[[1.81,5.58]],"batb":[[0,1.76,397.25],[1,1.74,86.2],[2,1.73,44.9]],"batl":[[0,1.8,10.34],[1,1.81,76.04],[2,1.83,94.78]],"ltp":1.81,"tv":3097.19,"id":8734382},{"trd":[[2.22,4.55]],"batl":[[0,2.3,219.86]],"ltp":2.22,"tv":25106.47,"id":9323645}],"tv":28203.66}]}
{"op":"mcm","clk":"4216628133","pt":1631553817174,"mc":[{"id":"1.187566733","rc":[{"batb":[[1,1.75,96.36],[2,1.74,51.72]],"batl":[[2,1.83,176.74]],"ltp":1.81,"tv":3097.19,"id":8734382},{"batb":[[2,2.12,45.38]],"ltp":2.22,"tv":25106.47,"id":9323645}]}]}
{"op":"mcm","clk":"4216628157","pt":1631553817340,"mc":[{"id":"1.187566733","rc":[{"batb":[[2,1.74,17.24]],"batl":[[2,1.83,111.18]],"ltp":1.81,"tv":3097.19,"id":8734382}]}]}
{"op":"mcm","clk":"4216628574","pt":1631553821187,"mc":[{"id":"1.187566733","rc":[{"batb":[[0,1.77,166.24],[1,1.76,427.95],[2,1.75,96.36]],"batl":[[0,1.8,32.18]],"ltp":1.81,"tv":3097.19,"id":8734382},{"batl":[[0,2.26,18.36]],"ltp":2.22,"tv":25106.47,"id":9323645}]}]}
{"op":"mcm","clk":"4216628848","pt":1631553823155,"mc":[{"id":"1.187566733","rc":[{"batb":[[0,2.18,40.52],[1,2.16,8.28],[2,2.14,31]],"ltp":2.22,"tv":25106.47,"id":9323645}]}]}
{"op":"mcm","clk":"4216628949","pt":1631553824054,"mc":[{"id":"1.187566733","rc":[{"batb":[[0,1.77,198.56]],"ltp":1.81,"tv":3097.19,"id":8734382}]}]}
{"op":"mcm","clk":"4216629041","pt":1631553824841,"mc":[{"id":"1.187566733","rc":[{"batb":[[0,1.77,166.24],[1,1.74,17.24],[2,1.73,8.62]],"batl":[[0,1.83,16.4],[1,1.84,8.2],[2,1.85,8.2]],"ltp":1.81,"tv":3097.19,"id":8734382},{"batb":[[0,2.16,8.28],[1,2.14,31],[2,2.12,37.34]],"ltp":2.22,"tv":25106.47,"id":9323645}]}]}
{"op":"mcm","clk":"4216629138","pt":1631553825680,"mc":[{"id":"1.187566733","rc":[{"batl":[[0,1.82,51.58],[1,1.83,16.4],[2,1.84,8.2]],"ltp":1.81,"tv":3097.19,"id":8734382}]}]}
{"op":"mcm","clk":"4216629433","pt":1631553828157,"mc":[{"id":"1.187566733","rc":[{"batl":[[2,1.84,39.48]],"ltp":1.81,"tv":3097.19,"id":8734382},{"batb":[[0,2.18,6.97],[1,2.16,8.28],[2,2.14,31]],"ltp":2.22,"tv":25106.47,"id":9323645}]}]}
{"op":"mcm","clk":"4216629477","pt":1631553828472,"mc":[{"id":"1.187566733","rc":[{"batl":[[2,1.84,8.2]],"ltp":1.81,"tv":3097.19,"id":8734382},{"batb":[[0,2.16,8.28],[1,2.14,31],[2,2.12,37.34]],"ltp":2.22,"tv":25106.47,"id":9323645}]}]}
{"op":"mcm","clk":"4216629992","pt":1631553832987,"mc":[{"id":"1.187566733","rc":[{"batl":[[0,2.24,1.39]],"ltp":2.22,"tv":25106.47,"id":9323645}]}]}
{"op":"mcm","clk":"4216630265","pt":1631553835202,"mc":[{"id":"1.187566733","rc":[{"batl":[[2,1.84,38.23]],"ltp":1.81,"tv":3097.19,"id":8734382},{"batb":[[0,2.18,7.36],[1,2.16,8.28],[2,2.14,31]],"ltp":2.22,"tv":25106.47,"id":9323645}]}]}
{"op":"mcm","clk":"4216630303","pt":1631553835502,"mc":[{"id":"1.187566733","rc":[{"batl":[[2,1.84,8.2]],"ltp":1.81,"tv":3097.19,"id":8734382},{"batb":[[0,2.16,8.28],[1,2.14,31],[2,2.12,37.34]],"ltp":2.22,"tv":25106.47,"id":9323645}]}]}
{"op":"mcm","clk":"4216631143","pt":1631553842174,"mc":[{"id":"1.187566733","rc":[{"trd":[[1.77,81.89],[1.8,90.63]],"batb":[[0,1.77,125.29]],"batl":[[2,1.84,39.48]],"ltp":1.77,"tv":3180.8,"id":8734382},{"trd":[[2.24,74.04]],"batb":[[0,2.18,6.86],[1,2.16,8.28],[2,2.14,31]],"ltp":2.24,"tv":25107.85,"id":9323645}],"tv":28288.66}]}
{"op":"mcm","clk":"4216631171","pt":1631553842395,"mc":[{"id":"1.187566733","rc":[{"batl":[[2,1.84,8.2]],"ltp":1.77,"tv":3180.8,"id":8734382},{"batb":[[0,2.16,8.28],[1,2.14,31],[2,2.12,37.34]],"ltp":2.24,"tv":25107.85,"id":9323645}]}]}
{"op":"mcm","clk":"4216631353","pt":1631553843980,"mc":[{"id":"1.187566733","rc":[{"trd":[[1.77,96.35]],"batb":[[0,1.77,118.07]],"ltp":1.77,"tv":3195.26,"id":8734382}],"tv":28303.11}]}
{"op":"mcm","clk":"4216631412","pt":1631553844376,"mc":[{"id":"1.187566733","rc":[{"batb":[[0,1.74,17.24],[1,1.73,8.62],[2,1.72,8.62]],"ltp":1.77,"tv":3195.26,"id":8734382}]}]}
{"op":"mcm","clk":"4216631683","pt":1631553846694,"mc":[{"id":"1.187566733","rc":[{"trd":[[1.71,186.82],[1.72,8.62],[1.73,39.46],[1.74,43.91]],"batb":[[0,1.66,98.01],[1,1.65,66.36],[2,1.6,47.92]],"batl":[[0,1.73,112.88],[1,1.74,35.75],[2,1.78,517.27]],"ltp":1.71,"tv":3397.08,"id":8734382},{"trd":[[2.4,6.18]],"batb":[[0,2.4,2.36],[1,2.34,9.22],[2,2.16,8.28]],"batl":[[0,2.46,6.26],[1,2.5,347.47]],"ltp":2.4,"tv":25114.03,"id":9323645}],"tv":28511.11}]}
{"op":"mcm","clk":"4216631817","pt":1631553847907,"mc":[{"id":"1.187566733","rc":[{"batb":[[0,1.66,64.73],[1,1.6,47.92],[2,1.51,59.58]],"batl":[[0,1.74,35.75],[1,1.78,517.27],[2,1.82,51.58]],"ltp":1.71,"tv":3397.08,"id":8734382},{"batb":[[1,2.34,37.5],[2,2.22,32.31]],"ltp":2.4,"tv":25114.03,"id":9323645}]}]}
{"op":"mcm","clk":"4216632089","pt":1631553850220,"mc":[{"id":"1.187566733","rc":[{"batb":[[0,1.67,73.25],[1,1.66,64.71],[2,1.6,47.92]],"batl":[[0,1.72,88.5],[1,1.74,146.08],[2,1.78,517.27]],"ltp":1.71,"tv":3397.08,"id":8734382}]}]}
{"op":"mcm","clk":"4216632231","pt":1631553851598,"mc":[{"id":"1.187566733","rc":[{"trd":[[2.4,10.9]],"batb":[[0,2.34,37.5],[1,2.22,32.31],[2,2.16,8.28]],"ltp":2.4,"tv":25118.75,"id":9323645}],"tv":28515.83}]}
{"op":"mcm","clk":"4216632428","pt":1631553853120,"mc":[{"id":"1.187566733","rc":[{"batl":[[2,1.77,101.2]],"ltp":1.71,"tv":3397.08,"id":8734382}]}]}
{"op":"mcm","clk":"4216632474","pt":1631553853491,"mc":[{"id":"1.187566733","rc":[{"trd":[[1.71,186.86]],"batb":[[0,1.68,36.59],[1,1.67,73.23],[2,1.66,64.71]],"batl":[[0,1.71,29.01],[1,1.72,88.5],[2,1.74,146.08]],"ltp":1.71,"tv":3397.12,"id":8734382},{"batb":[[1,2.28,7.16],[2,2.22,39.15]],"ltp":2.4,"tv":25118.75,"id":9323645}],"tv":28515.87}]}
{"op":"mcm","clk":"4216632680","pt":1631553855315,"mc":[{"id":"1.187566733","rc":[{"batb":[[2,2.24,6.77]],"ltp":2.4,"tv":25118.75,"id":9323645}]}]}
{"op":"mcm","clk":"4216632821","pt":1631553856633,"mc":[{"id":"1.187566733","rc":[{"batb":[[0,1.68,101.59]],"ltp":1.71,"tv":3397.12,"id":8734382},{"batl":[[0,2.5,347.47],[1,2.5,0]],"ltp":2.4,"tv":25118.75,"id":9323645}]}]}
{"op":"mcm","clk":"4216633176","pt":1631553859512,"mc":[{"id":"1.187566733","rc":[{"batb":[[0,1.7,10.13],[1,1.68,101.59],[2,1.67,73.23]],"ltp":1.71,"tv":3397.12,"id":8734382},{"batb":[[0,2.36,10.44],[1,2.34,37.5],[2,2.28,7.16]],"ltp":2.4,"tv":25118.75,"id":9323645}]}]}
{"op":"mcm","clk":"4216633427","pt":1631553861625,"mc":[{"id":"1.187566733","rc":[{"batb":[[0,1.68,101.59],[1,1.67,73.23],[2,1.66,64.71]],"ltp":1.71,"tv":3397.12,"id":8734382},{"batb":[[0,2.34,37.5],[1,2.28,7.16],[2,2.24,6.77]],"ltp":2.4,"tv":25118.75,"id":9323645}]}]}
{"op":"mcm","clk":"4216633578","pt":1631553862726,"mc":[{"id":"1.187566733","rc":[{"batb":[[0,1.69,35.99],[1,1.68,101.59],[2,1.67,73.23]],"batl":[[1,1.72,116.81]],"ltp":1.71,"tv":3397.12,"id":8734382}]}]}
{"op":"mcm","clk":"4216633790","pt":1631553864717,"mc":[{"id":"1.187566733","rc":[{"batb":[[0,1.7,10.13],[1,1.69,35.99],[2,1.68,36.59]],"ltp":1.71,"tv":3397.12,"id":8734382},{"batb":[[0,2.36,10.44],[1,2.34,37.5],[2,2.28,7.16]],"ltp":2.4,"tv":25118.75,"id":9323645}]}]}
{"op":"mcm","clk":"4216634147","pt":1631553868087,"mc":[{"id":"1.187566733","rc":[{"batb":[[0,1.7,175.13]],"batl":[[0,1.72,116.81],[1,1.74,146.08],[2,1.77,101.2]],"ltp":1.71,"tv":3397.12,"id":8734382}]}]}
{"op":"mcm","clk":"4216634474","pt":1631553871162,"mc":[{"id":"1.187566733","rc":[{"batb":[[0,1.7,203.11]],"ltp":1.71,"tv":3397.12,"id":8734382},{"batb":[[0,2.34,37.5],[1,2.28,7.16],[2,2.24,6.77]],"ltp":2.4,"tv":25118.75,"id":9323645}]}]}
{"op":"mcm","clk":"4216634531","pt":1631553871633,"mc":[{"id":"1.187566733","rc":[{"batb":[[0,1.51,59.58],[1,1.3,199.49],[2,1.25,167.57]],"batl":[[0,1.77,101.2],[1,1.78,35.75],[2,1.8,33.67]],"ltp":1.71,"tv":3397.12,"id":8734382},{"batb":[[0,2.28,7.16],[1,2.24,6.77],[2,2.22,39.15]],"ltp":2.4,"tv":25118.75,"id":9323645}]}]}
{"op":"mcm","clk":"4216634830","pt":1631553874300,"mc":[{"id":"1.187566733","rc":[{"batb":[[0,1.57,70.81],[1,1.56,80.38],[2,1.51,59.58]],"batl":[[2,1.8,131.48]],"ltp":1.71,"tv":3397.12,"id":8734382}]}]}
{"op":"mcm","clk":"4216635561","pt":1631553881234,"mc":[{"id":"1.187566733","rc":[{"batb":[[0,1.51,59.58],[1,1.3,199.49],[2,1.25,167.57]],"ltp":1.71,"tv":3397.12,"id":8734382}]}]}
{"op":"mcm","clk":"4216635751","pt":1631553883131,"mc":[{"id":"1.187566733","rc":[{"batl":[[0,1.57,14.4],[1,1.8,97.81],[2,1.81,32.5]],"ltp":1.71,"tv":3397.12,"id":8734382},{"batb":[[0,2.22,39.15],[1,2.14,31],[2,1.5,107.72]],"ltp":2.4,"tv":25118.75,"id":9323645}]}]}
{"op":"mcm","clk":"4216635856","pt":1631553884131,"mc":[{"id":"1.187566733","rc":[{"trd":[[1.57,14.4],[1.8,96.18]],"batb":[[0,1.76,11.1],[1,1.74,335.53],[2,1.51,59.58]],"batl":[[0,1.8,105.76],[1,1.81,32.5],[2,1.82,95.97]],"ltp":1.8,"tv":3417.07,"id":8734382},{"trd":[[2.24,78.5],[2.74,8.25]],"batl":[[0,2.44,84.01]],"ltp":2.24,"tv":25131.46,"id":9323645}],"tv":28548.53}]}
{"op":"mcm","clk":"4216635967","pt":1631553885167,"mc":[{"id":"1.187566733","rc":[{"batb":[[1,1.74,418.82],[2,1.72,114.59]],"ltp":1.8,"tv":3417.07,"id":8734382},{"batb":[[2,2.12,36.84]],"batl":[[0,2.44,16.81]],"ltp":2.24,"tv":25131.46,"id":9323645}]}]}
{"op":"mcm","clk":"4216636274","pt":1631553888163,"mc":[{"id":"1.187566733","rc":[{"batl":[[0,1.79,100.08],[1,1.8,105.76],[2,1.81,32.5]],"ltp":1.8,"tv":3417.07,"id":8734382}]}]}
{"op":"mcm","clk":"4216636377","pt":1631553889162,"mc":[{"id":"1.187566733","rc":[{"batb":[[0,1.77,36.76],[1,1.76,11.1],[2,1.74,418.82]],"batl":[[0,1.79,130.58]],"ltp":1.8,"tv":3417.07,"id":8734382}]}]}
{"op":"mcm","clk":"4216636562","pt":1631553890957,"mc":[{"id":"1.187566733","rc":[{"batb":[[1,1.76,49.35]],"ltp":1.8,"tv":3417.07,"id":8734382}]}]}
{"op":"mcm","clk":"4216636610","pt":1631553891437,"mc":[{"id":"1.187566733","rc":[{"batb":[[1,1.76,145.35]],"ltp":1.8,"tv":3417.07,"id":8734382},{"batb":[[1,2.2,6.87],[2,2.16,7.53]],"ltp":2.24,"tv":25131.46,"id":9323645}]}]}
{"op":"mcm","clk":"4216636735","pt":1631553892855,"mc":[{"id":"1.187566733","rc":[{"batb":[[2,2.18,6.36]],"ltp":2.24,"tv":25131.46,"id":9323645}]}]}
{"op":"mcm","clk":"4216636914","pt":1631553894566,"mc":[{"id":"1.187566733","rc":[{"trd":[[1.77,102.85]],"batb":[[0,1.77,30.26]],"ltp":1.77,"tv":3423.57,"id":8734382},{"trd":[[2.3,5]],"batl":[[0,2.42,198.4],[1,2.44,16.81]],"ltp":2.3,"tv":25136.46,"id":9323645}],"tv":28560.03}]}
{"op":"mcm","clk":"4216637068","pt":1631553896135,"mc":[{"id":"1.187566733","rc":[{"batb":[[1,1.76,134.25],[2,1.65,42.55]],"batl":[[1,1.83,31.5],[2,1.84,32.53]],"ltp":1.77,"tv":3423.57,"id":8734382},{"batb":[[0,2.22,32.31]],"ltp":2.3,"tv":25136.46,"id":9323645}]}]}
{"op":"mcm","clk":"4216637104","pt":1631553896571,"mc":[{"id":"1.187566733","rc":[{"batb":[[0,1.55,52.95],[1,1.3,199.49],[2,1.25,167.57]],"batl":[[0,1.79,100.08]],"ltp":1.77,"tv":3423.57,"id":8734382},{"batb":[[0,2.2,6.87],[1,2.18,6.36],[2,2.16,7.53]],"ltp":2.3,"tv":25136.46,"id":9323645}]}]}
{"op":"mcm","clk":"4216637363","pt":1631553899156,"mc":[{"id":"1.187566733","rc":[{"batb":[[0,1.63,94.79],[1,1.62,70.44],[2,1.55,52.95]],"ltp":1.77,"tv":3423.57,"id":8734382}]}]}
{"op":"mcm","clk":"4216637439","pt":1631553899958,"mc":[{"id":"1.187566733","rc":[{"trd":[[1.79,282.99]],"batb":[[0,1.55,52.95],[1,1.3,199.49],[2,1.25,167.57]],"batl":[[0,1.83,31.5],[1,1.84,32.53],[2,1.85,29.5]],"ltp":1.79,"tv":3523.64,"id":8734382},{"trd":[[2.26,79.26]],"batl":[[0,2.26,6.96]],"ltp":2.26,"tv":25215.73,"id":9323645}],"tv":28739.37}]}
{"op":"mcm","clk":"4216637477","pt":1631553900266,"mc":[{"id":"1.187566733","rc":[{"batl":[[0,1.85,29.5],[1,1.84,0],[2,1.85,0]],"ltp":1.79,"tv":3523.64,"id":8734382},{"batb":[[0,2.16,7.53],[1,2.14,31],[2,2.12,36.84]],"ltp":2.26,"tv":25215.73,"id":9323645}]}]}
{"op":"mcm","clk":"4216637649","pt":1631553902063,"mc":[{"id":"1.187566733","rc":[{"trd":[[1.79,291.78]],"batb":[[0,1.72,70.46],[1,1.7,118.92],[2,1.55,52.95]],"batl":[[0,1.77,59.91],[1,1.79,101.15],[2,1.85,29.5]],"ltp":1.79,"tv":3532.43,"id":8734382},{"trd":[[2.26,86.22]],"ltp":2.26,"tv":25222.68,"id":9323645}],"tv":28755.12}]}
{"op":"mcm","clk":"4216637826","pt":1631553903763,"mc":[{"id":"1.187566733","rc":[{"batl":[[2,1.83,30.5]],"ltp":1.79,"tv":3532.43,"id":8734382},{"batb":[[0,2.2,7.72],[1,2.16,7.53],[2,2.14,31]],"ltp":2.26,"tv":25222.68,"id":9323645}]}]}
{"op":"mcm","clk":"4216637965","pt":1631553905084,"mc":[{"id":"1.187566733","rc":[{"batb":[[0,1.55,52.95],[1,1.3,199.49],[2,1.25,167.57]],"batl":[[0,1.85,29.5],[1,1.79,0],[2,1.83,0]],"ltp":1.79,"tv":3532.43,"id":8734382},{"batb":[[0,2.16,7.53],[1,2.14,31],[2,2.12,36.84]],"ltp":2.26,"tv":25222.68,"id":9323645}]}]}
{"op":"mcm","clk":"4216638019","pt":1631553905558,"mc":[{"id":"1.187566733","rc":[{"batl":[[0,1.78,82.05],[1,1.79,81.01],[2,1.85,29.5]],"ltp":1.79,"tv":3532.43,"id":8734382}]}]}
{"op":"mcm","clk":"4216638188","pt":1631553906996,"mc":[{"id":"1.187566733","rc":[{"batl":[[0,1.77,83.12],[1,1.78,82.05],[2,1.79,81.01]],"ltp":1.79,"tv":3532.43,"id":8734382}]}]}
{"op":"mcm","clk":"4216638268","pt":1631553907676,"mc":[{"id":"1.187566733","rc":[{"batb":[[0,1.63,100.06],[1,1.62,70.44],[2,1.55,52.95]],"batl":[[2,1.85,29.5]],"ltp":1.79,"tv":3532.43,"id":8734382}]}]}
{"op":"mcm","clk":"4216638842","pt":1631553912997,"mc":[{"id":"1.187566733","rc":[{"batb":[[0,1.64,200],[1,1.63,100.06],[2,1.62,70.44]],"ltp":1.79,"tv":3532.43,"id":8734382},{"batl":[[0,810,0.07]],"ltp":2.26,"tv":25222.68,"id":9323645}]}]}
{"op":"mcm","clk":"4216639100","pt":1631553915577,"mc":[{"id":"1.187566733","rc":[{"batl":[[0,1.78,82.05],[1,1.85,29.5],[2,1.88,73.76]],"ltp":1.79,"tv":3532.43,"id":8734382}]}]}
{"op":"mcm","clk":"4216639549","pt":1631553919687,"mc":[{"id":"1.187566733","rc":[{"batl":[[0,1.78,164.11]],"ltp":1.79,"tv":3532.43,"id":8734382}]}]}
{"op":"mcm","clk":"4216639836","pt":1631553922342,"mc":[{"id":"1.187566733","rc":[{"batl":[[1,1.83,33.5],[2,1.85,29.5]],"ltp":1.79,"tv":3532.43,"id":8734382},{"batb":[[0,2.2,7.57],[1,2.16,7.53],[2,2.14,31]],"ltp":2.26,"tv":25222.68,"id":9323645}]}]}
{"op":"mcm","clk":"4216640500","pt":1631553928689,"mc":[{"id":"1.187566733","rc":[{"batb":[[1,1.55,52.95],[2,1.3,199.49]],"ltp":1.79,"tv":3532.43,"id":8734382}]}]}
{"op":"mcm","clk":"4216640598","pt":1631553929696,"mc":[{"id":"1.187566733","rc":[{"batl":[[0,1.85,29.5],[1,1.88,73.76],[2,1.9,84.51]],"ltp":1.79,"tv":3532.43,"id":8734382},{"batb":[[0,2.16,7.53],[1,2.14,31],[2,2.12,36.84]],"ltp":2.26,"tv":25222.68,"id":9323645}]}]}
{"op":"mcm","clk":"4216640856","pt":1631553932110,"mc":[{"id":"1.187566733","rc":[{"batb":[[0,1.83,8.24],[1,1.82,73.34],[2,1.8,99.06]],"batl":[[1,1.86,8.27],[2,1.88,73.76]],"ltp":1.79,"tv":3532.43,"id":8734382},{"trd":[[2.16,18.86]],"batb":[[0,2.16,2.86]],"batl":[[0,2.24,253.06],[1,2.26,95.64],[2,2.28,6.7]],"ltp":2.16,"tv":25232.02,"id":9323645}],"tv":28764.46}]}
{"op":"mcm","clk":"4216641598","pt":1631553938797,"mc":[{"id":"1.187566733","rc":[{"batl":[[2,1.87,29.5]],"ltp":1.79,"tv":3532.43,"id":8734382},{"batb":[[1,2.14,37.82],[2,2.12,44.38]],"ltp":2.16,"tv":25232.02,"id":9323645}]}]}
{"op":"mcm","clk":"4216641686","pt":1631553939701,"mc":[{"id":"1.187566733","rc":[{"batb":[[0,1.83,47.41]],"batl":[[0,1.85,68.25]],"ltp":1.79,"tv":3532.43,"id":8734382}]}]}
{"op":"mcm","clk":"4216643966","pt":1631553962039,"mc":[{"id":"1.187566733","rc":[{"batb":[[0,1.72,33.09],[1,1.63,44.06],[2,1.3,199.49]],"batl":[[0,1.88,30.04],[1,1.86,0],[2,1.87,0]],"ltp":1.79,"tv":3532.43,"id":8734382},{"batb":[[0,2.14,31],[1,2.06,40.11],[2,1.5,107.72]],"batl":[[0,2.4,6.34],[1,810,0.07],[2,2.28,0]],"ltp":2.16,"tv":25232.02,"id":9323645}]}]}
{"op":"mcm","clk":"4216644284","pt":1631553965056,"mc":[{"id":"1.187566733","rc":[{"batl":[[0,1.87,29.5],[1,1.88,30.04]],"ltp":1.79,"tv":3532.43,"id":8734382},{"batb":[[0,2.14,37.82],[1,2.12,7.79],[2,2.06,40.11]],"ltp":2.16,"tv":25232.02,"id":9323645}]}]}
{"op":"mcm","clk":"4216644349","pt":1631553965543,"mc":[{"id":"1.187566733","rc":[{"batl":[[0,1.88,30.04],[1,1.88,0]],"ltp":1.79,"tv":3532.43,"id":8734382},{"batb":[[0,2.14,31]],"ltp":2.16,"tv":25232.02,"id":9323645}]}]}
{"op":"mcm","clk":"4216644529","pt":1631553967161,"mc":[{"id":"1.187566733","rc":[{"batl":[[1,1.89,270.68]],"ltp":1.79,"tv":3532.43,"id":8734382}]}]}
{"op":"mcm","clk":"4216644627","pt":1631553968161,"mc":[{"id":"1.187566733","rc":[{"batb":[[0,1.8,80.9],[1,1.78,102.63],[2,1.72,33.09]],"batl":[[0,1.86,74.15],[1,1.88,117.23]],"ltp":1.79,"tv":3532.43,"id":8734382}]}]}
{"op":"mcm","clk":"4216644706","pt":1631553968840,"mc":[{"id":"1.187566733","rc":[{"batb":[[2,1.75,34.03]],"ltp":1.79,"tv":3532.43,"id":8734382},{"batl":[[0,2.34,6.25],[1,2.4,6.34],[2,810,0.07]],"ltp":2.16,"tv":25232.02,"id":9323645}]}]}
{"op":"mcm","clk":"4216644947","pt":1631553970954,"mc":[{"id":"1.187566733","rc":[{"trd":[[1.86,129.82]],"batl":[[0,1.86,65.74]],"ltp":1.86,"tv":3540.84,"id":8734382},{"trd":[[2.16,26.1]],"ltp":2.16,"tv":25239.27,"id":9323645}],"tv":28780.12}]}
{"op":"mcm","clk":"4216645070","pt":1631553972055,"mc":[{"id":"1.187566733","rc":[{"batb":[[0,1.72,33.09],[1,1.63,44.06],[2,1.3,199.49]],"batl":[[0,1.87,28.5],[1,1.88,30.04]],"ltp":1.86,"tv":3540.84,"id":8734382},{"batb":[[0,2.14,38.32]],"batl":[[0,2.4,6.34],[1,810,0.07],[2,810,0]],"ltp":2.16,"tv":25239.27,"id":9323645}]}]}
{"op":"mcm","clk":"4216645103","pt":1631553972368,"mc":[{"id":"1.187566733","rc":[{"batl":[[0,1.88,30.04],[1,1.88,0]],"ltp":1.86,"tv":3540.84,"id":8734382},{"batb":[[0,2.14,31]],"ltp":2.16,"tv":25239.27,"id":9323645}]}]}
{"op":"mcm","clk":"4216645406","pt":1631553974970,"mc":[{"id":"1.187566733","rc":[{"batb":[[0,1.73,81.75],[1,1.72,33.09],[2,1.71,116.68]],"batl":[[1,1.95,92.17],[2,1.97,76.1]],"ltp":1.86,"tv":3540.84,"id":8734382}]}]}
{"op":"mcm","clk":"4216645677","pt":1631553977772,"mc":[{"id":"1.187566733","rc":[{"batl":[[1,1.95,0],[2,1.97,0]],"ltp":1.86,"tv":3540.84,"id":8734382}]}]}
{"op":"mcm","clk":"4216645803","pt":1631553979083,"mc":[{"id":"1.187566733","rc":[{"batl":[[0,1.87,28.73],[1,1.88,30.04]],"ltp":1.86,"tv":3540.84,"id":8734382},{"batb":[[0,2.14,38.32]],"ltp":2.16,"tv":25239.27,"id":9323645}]}]}
{"op":"mcm","clk":"4216645829","pt":1631553979360,"mc":[{"id":"1.187566733","rc":[{"batl":[[0,1.88,30.04],[1,1.88,0]],"ltp":1.86,"tv":3540.84,"id":8734382},{"batb":[[0,2.14,31]],"ltp":2.16,"tv":25239.27,"id":9323645}]}]}
{"op":"mcm","clk":"4216645959","pt":1631553980774,"mc":[{"id":"1.187566733","rc":[{"batb":[[0,1.74,13.81],[1,1.73,81.75],[2,1.72,415.2]],"batl":[[0,1.78,79.75],[1,1.79,103.77],[2,1.8,31.27]],"ltp":1.86,"tv":3540.84,"id":8734382},{"batb":[[0,2.28,39.48],[1,2.26,19.74],[2,2.24,28.26]],"ltp":2.16,"tv":25239.27,"id":9323645}]}]}
{"op":"mcm","clk":"4216646057","pt":1631553981764,"mc":[{"id":"1.187566733","rc":[{"trd":[[2.28,8.84]],"batb":[[0,2.28,8.74],[1,2.26,37.71],[2,2.24,15.1]],"batl":[[1,2.42,12.4],[2,2.44,6.2]],"ltp":2.28,"tv":25248.11,"id":9323645}],"tv":28788.96}]}
{"op":"mcm","clk":"4216646385","pt":1631553984878,"mc":[{"id":"1.187566733","rc":[{"batb":[[0,1.75,30.67],[1,1.74,81.81],[2,1.73,81.75]],"batl":[[0,1.77,28.4],[1,1.78,79.75],[2,1.79,103.77]],"ltp":1.86,"tv":3540.84,"id":8734382}]}]}
{"op":"mcm","clk":"4216647981","pt":1631554000102,"mc":[{"id":"1.187566733","rc":[{"batb":[[0,1.74,68],[1,1.62,37.54],[2,1.54,54.21]],"batl":[[0,1.84,29.03],[1,1.78,0],[2,1.79,0]],"ltp":1.86,"tv":3540.84,"id":8734382},{"batb":[[0,2.18,6.36],[1,2.16,35.41],[2,2.14,31]],"batl":[[0,2.62,4.75],[1,810,0.07],[2,2.44,0]],"ltp":2.28,"tv":25248.11,"id":9323645}]}]}
{"op":"mcm","clk":"4216648024","pt":1631554000522,"mc":[{"id":"1.187566733","rc":[{"batb":[[0,1.62,37.54],[1,1.54,54.21],[2,1.3,199.49]],"ltp":1.86,"tv":3540.84,"id":8734382}]}]}
{"op":"mcm","clk":"4216648331","pt":1631554003195,"mc":[{"id":"1.187566733","rc":[{"batb":[[0,1.62,136.06],[1,1.61,71.95],[2,1.54,54.21]],"batl":[[1,1.87,86.22],[2,1.89,85.74]],"ltp":1.86,"tv":3540.84,"id":8734382}]}]}
{"op":"mcm","clk":"4216648385","pt":1631554003714,"mc":[{"id":"1.187566733","rc":[{"batb":[[0,1.62,38.21],[1,1.54,54.21],[2,1.3,199.49]],"batl":[[1,1.87,0],[2,1.89,0]],"ltp":1.86,"tv":3540.84,"id":8734382}]}]}
{"op":"mcm","clk":"4216648604","pt":1631554006137,"mc":[{"id":"1.187566733","rc":[{"trd":[[1.77,104.19]],"batb":[[0,1.73,20.13],[1,1.62,37.54],[2,1.54,54.21]],"batl":[[0,1.76,19.85],[1,1.84,29.03]],"ltp":1.77,"tv":3542.18,"id":8734382},{"batl":[[0,2.36,20.82],[1,2.62,4.75],[2,810,0.07]],"ltp":2.28,"tv":25248.11,"id":9323645}],"tv":28790.3}]}
{"op":"mcm","clk":"4216648707","pt":1631554007026,"mc":[{"id":"1.187566733","rc":[{"batb":[[0,1.62,37.54],[1,1.54,54.21],[2,1.3,199.49]],"batl":[[0,1.84,29.03],[1,1.84,0]],"ltp":1.77,"tv":3542.18,"id":8734382},{"batl":[[0,2.62,4.75],[1,810,0.07],[2,810,0]],"ltp":2.28,"tv":25248.11,"id":9323645}]}]}
{"op":"mcm","clk":"4216648832","pt":1631554008346,"mc":[{"id":"1.187566733","rc":[{"batl":[[0,2.28,6.09],[1,2.62,4.75],[2,810,0.07]],"ltp":2.28,"tv":25248.11,"id":9323645}]}]}
{"op":"mcm","clk":"4216649000","pt":1631554010026,"mc":[{"id":"1.187566733","rc":[{"batb":[[0,2.2,6.92],[1,2.18,6.36],[2,2.16,35.41]],"ltp":2.28,"tv":25248.11,"id":9323645}]}]}
{"op":"mcm","clk":"4216649054","pt":1631554010609,"mc":[{"id":"1.187566733","rc":[{"batb":[[0,1.62,136.06],[1,1.61,71.95],[2,1.54,54.21]],"batl":[[1,1.87,86.22],[2,1.89,85.74]],"ltp":1.77,"tv":3542.18,"id":8734382},{"batb":[[0,2.18,6.36],[1,2.16,35.41],[2,2.14,31]],"ltp":2.28,"tv":25248.11,"id":9323645}]}]}
{"op":"mcm","clk":"4216649380","pt":1631554013915,"mc":[{"id":"1.187566733","rc":[{"batb":[[0,1.66,40.78],[1,1.62,136.06],[2,1.61,71.95]],"batl":[[0,1.82,27.75],[1,1.84,29.03],[2,1.87,86.22]],"ltp":1.77,"tv":3542.18,"id":8734382},{"batl":[[1,2.52,5.51],[2,2.62,4.75]],"ltp":2.28,"tv":25248.11,"id":9323645}]}]}
{"op":"mcm","clk":"4216649512","pt":1631554015121,"mc":[{"id":"1.187566733","rc":[{"batb":[[0,1.62,136.06],[1,1.61,71.95],[2,1.54,54.21]],"batl":[[0,1.84,29.03],[1,1.87,86.22],[2,1.89,85.74]],"ltp":1.77,"tv":3542.18,"id":8734382},{"trd":[[2.18,0.16]],"batb":[[0,2.18,6.28]],"batl":[[1,2.62,4.75],[2,810,0.07]],"ltp":2.18,"tv":25248.26,"id":9323645}],"tv":28790.45}]}
{"op":"mcm","clk":"4216649720","pt":1631554017021,"mc":[{"id":"1.187566733","rc":[{"batb":[[0,2.2,6.92],[1,2.18,6.28],[2,2.16,35.41]],"ltp":2.18,"tv":25248.26,"id":9323645}]}]}
{"op":"mcm","clk":"4216649829","pt":1631554018123,"mc":[{"id":"1.187566733","rc":[{"trd":[[1.78,262.14]],"batl":[[0,1.76,0.5]],"ltp":1.78,"tv":3549.98,"id":8734382},{"trd":[[2.28,14.93]],"batb":[[0,2.18,6.28],[1,2.16,35.41],[2,2.14,31]],"batl":[[0,2.62,4.75],[1,810,0.07],[2,810,0]],"ltp":2.28,"tv":25254.36,"id":9323645}],"tv":28804.35}]}
{"op":"mcm","clk":"4216649944","pt":1631554019156,"mc":[{"id":"1.187566733","rc":[{"batb":[[0,1.62,587.32]],"batl":[[0,1.67,90.66],[1,1.68,14.6],[2,1.69,155.48]],"ltp":1.78,"tv":3549.98,"id":8734382},{"batb":[[0,2.5,80.4],[1,2.46,12.2],[2,2.44,14.02]],"batl":[[0,2.56,9.99],[1,2.62,4.75],[2,810,0.07]],"ltp":2.28,"tv":25254.36,"id":9323645}]}]}
{"op":"mcm","clk":"4216649996","pt":1631554019624,"mc":[{"id":"1.187566733","rc":[{"batb":[[1,1.61,90.59],[2,1.6,9.32]],"ltp":1.78,"tv":3549.98,"id":8734382},{"trd":[[2.5,8.2]],"batb":[[0,2.5,76.3],[1,2.46,36.7]],"ltp":2.5,"tv":25262.56,"id":9323645}],"tv":28812.55}]}
{"op":"mcm","clk":"4216650405","pt":1631554023021,"mc":[{"id":"1.187566733","rc":[{"batb":[[0,1.64,79],[1,1.63,34.93],[2,1.62,587.32]],"batl":[[0,1.66,33.01],[1,1.67,90.66],[2,1.68,14.6]],"ltp":1.78,"tv":3549.98,"id":8734382}]}]}
{"op":"mcm","clk":"4216650456","pt":1631554023542,"mc":[{"id":"1.187566733","rc":[{"trd":[[2.5,31.1]],"batb":[[0,2.5,64.85]],"ltp":2.5,"tv":25285.46,"id":9323645}],"tv":28835.45}]}
{"op":"mcm","clk":"4216650586","pt":1631554024922,"mc":[{"id":"1.187566733","rc":[{"batl":[[2,3,3.53]],"ltp":2.5,"tv":25285.46,"id":9323645}]}]}
{"op":"mcm","clk":"4216650667","pt":1631554025756,"mc":[{"id":"1.187566733","rc":[{"batb":[[0,1.64,118.31]],"batl":[[1,1.67,129.26]],"ltp":1.78,"tv":3549.98,"id":8734382}]}]}
{"op":"mcm","clk":"4216651035","pt":1631554029525,"mc":[{"id":"1.187566733","rc":[{"trd":[[1.64,6.92]],"batb":[[0,1.64,114.85]],"ltp":1.64,"tv":3556.91,"id":8734382}],"tv":28842.37}]}
{"op":"mcm","clk":"4216651401","pt":1631554033161,"mc":[{"id":"1.187566733","rc":[{"trd":[[1.66,1.34]],"batl":[[0,1.66,32.34]],"ltp":1.66,"tv":3558.25,"id":8734382}],"tv":28843.71}]}
{"op":"mcm","clk":"4216652393","pt":1631554043465,"mc":[{"id":"1.187566733","rc":[{"trd":[[1.66,2.24]],"batl":[[0,1.66,31.89]],"ltp":1.66,"tv":3559.15,"id":8734382}],"tv":28844.61}]}
{"op":"mcm","clk":"4216652538","pt":1631554045048,"mc":[{"id":"1.187566733","rc":[{"batb":[[0,1.64,75.54],[1,1.5,54.96],[2,1.45,55.41]],"batl":[[0,1.81,28.71],[1,1.67,0],[2,1.68,0]],"ltp":1.66,"tv":3559.15,"id":8734382},{"batb":[[0,2.28,30.21],[1,2.22,7.34],[2,2.14,31]],"batl":[[0,3,3.53],[1,3.25,3.98],[2,810,0.07]],"ltp":2.5,"tv":25285.46,"id":9323645}]}]}
{"op":"mcm","clk":"4216652573","pt":1631554045468,"mc":[{"id":"1.187566733","rc":[{"batb":[[0,1.45,55.41],[1,1.42,74.69],[2,1.3,199.49]],"ltp":1.66,"tv":3559.15,"id":8734382},{"batl":[[0,3.25,3.98],[1,810,0.07],[2,810,0]],"ltp":2.5,"tv":25285.46,"id":9323645}]}]}
{"op":"mcm","clk":"4216652816","pt":1631554047989,"mc":[{"id":"1.187566733","rc":[{"batb":[[0,1.49,112.5],[1,1.48,97.96],[2,1.45,55.41]],"batl":[[0,1.77,62.65],[1,1.79,101.13],[2,1.81,28.71]],"ltp":1.66,"tv":3559.15,"id":8734382}]}]}
{"op":"mcm","clk":"4216653019","pt":1631554050198,"mc":[{"id":"1.187566733","rc":[{"batb":[[0,1.45,55.41],[1,1.42,74.69],[2,1.3,199.49]],"batl":[[0,1.81,28.71],[1,1.79,0],[2,1.81,0]],"ltp":1.66,"tv":3559.15,"id":8734382},{"batl":[[1,1000,2.24]],"ltp":2.5,"tv":25285.46,"id":9323645}]}]}
{"op":"mcm","clk":"4216653063","pt":1631554050678,"mc":[{"id":"1.187566733","rc":[{"batl":[[1,810,0.07]],"ltp":2.5,"tv":25285.46,"id":9323645}]}]}
{"op":"mcm","clk":"4216653194","pt":1631554052059,"mc":[{"id":"1.187566733","rc":[{"batb":[[0,1.5,46.8],[1,1.45,55.41],[2,1.42,74.69]],"ltp":1.66,"tv":3559.15,"id":8734382},{"batl":[[0,3,4.84],[1,3.25,3.98],[2,810,0.07]],"ltp":2.5,"tv":25285.46,"id":9323645}]}]}
{"op":"mcm","clk":"4216653315","pt":1631554053171,"mc":[{"id":"1.187566733","rc":[{"batb":[[0,1.45,55.41],[1,1.42,74.69],[2,1.3,199.49]],"ltp":1.66,"tv":3559.15,"id":8734382},{"batl":[[0,3.25,3.98],[1,810,0.07],[2,810,0]],"ltp":2.5,"tv":25285.46,"id":9323645}]}]}
{"op":"mcm","clk":"4216653368","pt":1631554053801,"mc":[{"id":"1.187566733","rc":[{"batl":[[1,820,0.14]],"ltp":2.5,"tv":25285.46,"id":9323645}]}]}
{"op":"mcm","clk":"4216653482","pt":1631554055179,"mc":[{"id":"1.187566733","rc":[{"batl":[[0,1.77,30.5],[1,1.81,28.71]],"ltp":1.66,"tv":3559.15,"id":8734382}]}]}
{"op":"mcm","clk":"4216653531","pt":1631554055762,"mc":[{"id":"1.187566733","rc":[{"trd":[[1.45,7.89]],"batb":[[0,1.45,47.52]],"batl":[[0,1.81,28.71],[1,1.81,0]],"ltp":1.45,"tv":3567.04,"id":8734382},{"trd":[[3.25,11.48]],"batl":[[0,820,0.14],[1,820,0]],"ltp":3.25,"tv":25296.94,"id":9323645}],"tv":28863.98}]}
{"op":"mcm","clk":"4216653615","pt":1631554056803,"mc":[{"id":"1.187566733","rc":[{"batb":[[0,1.49,112.5],[1,1.48,97.96],[2,1.45,47.52]],"batl":[[0,1.77,62.65],[1,1.79,101.13],[2,1.81,28.71]],"ltp":1.45,"tv":3567.04,"id":8734382}]}]}
{"op":"mcm","clk":"4216653772","pt":1631554058176,"mc":[{"id":"1.187566733","rc":[{"batb":[[0,2.28,37.62]],"ltp":3.25,"tv":25296.94,"id":9323645}]}]}
{"op":"mcm","clk":"4216653909","pt":1631554059016,"mc":[{"id":"1.187566733","rc":[{"batb":[[0,1.5,48.56],[1,1.49,112.5],[2,1.48,97.96]],"ltp":1.45,"tv":3567.04,"id":8734382},{"batb":[[0,2.28,30.21]],"batl":[[0,3,4.21],[1,3.25,3.42],[2,820,0.14]],"ltp":3.25,"tv":25296.94,"id":9323645}]}]}
{"op":"mcm","clk":"4216653936","pt":1631554059282,"mc":[{"id":"1.187566733","rc":[{"batb":[[0,1.49,112.5],[1,1.48,97.96],[2,1.45,47.52]],"ltp":1.45,"tv":3567.04,"id":8734382},{"batl":[[0,3.25,3.42],[1,820,0.14],[2,820,0]],"ltp":3.25,"tv":25296.94,"id":9323645}]}]}
{"op":"mcm","clk":"4216654095","pt":1631554061186,"mc":[{"id":"1.187566733","rc":[{"batb":[[0,1.5,232.37],[1,1.49,112.5],[2,1.48,97.96]],"batl":[[0,1.53,91.44],[1,1.54,82.71],[2,1.56,24.24]],"ltp":1.45,"tv":3567.04,"id":8734382},{"batb":[[0,2.9,41.38],[1,2.84,31.69],[2,2.82,15.85]],"batl":[[0,2.92,7.88],[1,3,116.19],[2,3.25,3.42]],"ltp":3.25,"tv":25296.94,"id":9323645}]}]}
{"op":"mcm","clk":"4216654171","pt":1631554062130,"mc":[{"id":"1.187566733","rc":[{"batb":[[2,1.48,118.24]],"ltp":1.45,"tv":3567.04,"id":8734382},{"trd":[[2.9,7.14]],"batb":[[0,2.9,37.81],[1,2.84,10.56],[2,2.82,47.24]],"ltp":2.9,"tv":25304.08,"id":9323645}],"tv":28871.12}]}
{"op":"mcm","clk":"4216654449","pt":1631554064872,"mc":[{"id":"1.187566733","rc":[{"batb":[[0,1.5,281.26]],"batl":[[0,1.53,139.37]],"ltp":1.45,"tv":3567.04,"id":8734382}]}]}
{"op":"mcm","clk":"4216654544","pt":1631554065980,"mc":[{"id":"1.187566733","rc":[{"trd":[[1.52,60.41]],"batb":[[0,1.52,138.8],[1,1.5,281.26],[2,1.49,112.5]],"ltp":1.52,"tv":3627.45,"id":8734382}],"tv":28931.53}]}
{"op":"mcm","clk":"4216654625","pt":1631554067192,"mc":[{"id":"1.187566733","rc":[{"trd":[[1.52,130.16]],"batb":[[0,1.52,103.93]],"ltp":1.52,"tv":3697.2,"id":8734382}],"tv":29001.28}]}
{"op":"mcm","clk":"4216654701","pt":1631554068095,"mc":[{"id":"1.187566733","rc":[{"trd":[[1.52,160.36]],"batb":[[0,1.52,88.83]],"ltp":1.52,"tv":3727.4,"id":8734382}],"tv":29031.48}]}
{"op":"mcm","clk":"4216654805","pt":1631554069208,"mc":[{"id":"1.187566733","rc":[{"trd":[[1.51,53.02],[1.52,353.19]],"batb":[[0,1.51,26.01]],"batl":[[0,1.52,121.22],[1,1.53,139.37],[2,1.54,134.3]],"ltp":1.51,"tv":3973.25,"id":8734382},{"trd":[[2.92,7.88]],"batl":[[0,3,116.19],[1,3.25,3.42],[2,810,0.07]],"ltp":2.92,"tv":25311.96,"id":9323645}],"tv":29285.21}]}
{"op":"mcm","clk":"4216654888","pt":1631554070205,"mc":[{"id":"1.187566733","rc":[{"batl":[[0,1.52,217.21]],"ltp":1.51,"tv":3973.25,"id":8734382},{"batb":[[0,2.92,7.87],[1,2.9,37.81],[2,2.84,10.56]],"ltp":2.92,"tv":25311.96,"id":9323645}]}]}
{"op":"mcm","clk":"4216654989","pt":1631554071103,"mc":[{"id":"1.187566733","rc":[{"batl":[[0,1.52,56.6]],"ltp":1.51,"tv":3973.25,"id":8734382}]}]}
{"op":"mcm","clk":"4216655096","pt":1631554072210,"mc":[{"id":"1.187566733","rc":[{"trd":[[1.52,593.57]],"batl":[[0,1.52,105.51]],"ltp":1.52,"tv":4213.63,"id":8734382},{"batb":[[0,2.92,47.27]],"ltp":2.92,"tv":25311.96,"id":9323645}],"tv":29525.59}]}
{"op":"mcm","clk":"4216655176","pt":1631554073207,"mc":[{"id":"1.187566733","rc":[{"trd":[[1.51,105.04]],"batb":[[0,1.5,281.26],[1,1.49,112.5],[2,1.48,118.24]],"batl":[[0,1.51,207.99],[1,1.52,79.81],[2,1.53,139.37]],"ltp":1.51,"tv":4265.65,"id":8734382}],"tv":29577.61}]}
{"op":"mcm","clk":"4216655269","pt":1631554074206,"mc":[{"id":"1.187566733","rc":[{"batl":[[0,1.51,103.6],[1,1.52,15.51]],"ltp":1.51,"tv":4265.65,"id":8734382},{"batb":[[0,2.98,16.25],[1,2.92,47.27],[2,2.9,37.81]],"ltp":2.92,"tv":25311.96,"id":9323645}]}]}
{"op":"mcm","clk":"4216655363","pt":1631554075107,"mc":[{"id":"1.187566733","rc":[{"batl":[[0,1.51,205.89]],"ltp":1.51,"tv":4265.65,"id":8734382},{"batb":[[0,2.98,42.11]],"ltp":2.92,"tv":25311.96,"id":9323645}]}]}
{"op":"mcm","clk":"4216655455","pt":1631554076100,"mc":[{"id":"1.187566733","rc":[{"batl":[[0,1.51,290.89]],"ltp":1.51,"tv":4265.65,"id":8734382},{"batb":[[0,2.98,56.24],[1,2.94,11.92],[2,2.92,47.27]],"ltp":2.92,"tv":25311.96,"id":9323645}]}]}
{"op":"mcm","clk":"4216655537","pt":1631554076999,"mc":[{"id":"1.187566733","rc":[{"trd":[[1.51,189.17]],"batb":[[0,1.5,421.26]],"batl":[[0,1.52,15.51],[1,1.53,139.37],[2,1.54,134.3]],"ltp":1.51,"tv":4349.78,"id":8734382},{"trd":[[2.96,42.91],[2.98,86.62]],"batb":[[0,2.9,37.81],[1,2.84,10.56],[2,2.82,47.24]],"ltp":2.96,"tv":25441.49,"id":9323645}],"tv":29791.27}]}
{"op":"mcm","clk":"4216655633","pt":1631554077892,"mc":[{"id":"1.187566733","rc":[{"trd":[[1.5,180]],"batb":[[0,1.5,331.26]],"ltp":1.5,"tv":4529.78,"id":8734382}],"tv":29971.27}]}
{"op":"mcm","clk":"4216655731","pt":1631554079096,"mc":[{"id":"1.187566733","rc":[{"trd":[[1.5,780]],"batb":[[0,1.5,31.26],[1,1.49,171.13]],"batl":[[0,1.51,58.15],[1,1.52,15.51],[2,1.53,139.37]],"ltp":1.5,"tv":5129.78,"id":8734382}],"tv":30571.27}]}
{"op":"mcm","clk":"4216655805","pt":1631554080053,"mc":[{"id":"1.187566733","rc":[{"trd":[[1.5,901]],"batb":[[0,1.49,171.13],[1,1.48,118.24],[2,1.47,10.14]],"ltp":1.5,"tv":5250.77,"id":8734382},{"trd":[[3,79.34]],"batl":[[0,3,61.9]],"ltp":3.0,"tv":25520.82,"id":9323645}],"tv":30771.6}]}
{"op":"mcm","clk":"4216655919","pt":1631554081113,"mc":[{"id":"1.187566733","rc":[{"trd":[[1.5,999.21]],"batl":[[0,1.5,55.4],[1,1.51,58.15],[2,1.52,15.51]],"ltp":1.5,"tv":5348.98,"id":8734382},{"trd":[[3,154.04]],"batb":[[0,3,12.8],[1,2.9,37.81],[2,2.84,10.56]],"batl":[[0,3.25,3.42],[1,810,0.07],[2,810,0]],"ltp":3.0,"tv":25595.53,"id":9323645}],"tv":30944.51}]}
{"op":"mcm","clk":"4216656017","pt":1631554082112,"mc":[{"id":"1.187566733","rc":[{"trd":[[1.5,1047.25]],"batl":[[0,1.5,95.38]],"ltp":1.5,"tv":5397.02,"id":8734382},{"trd":[[3,165.92]],"batb":[[0,3,6.86]],"ltp":3.0,"tv":25607.4,"id":9323645}],"tv":31004.43}]}
{"op":"mcm","clk":"4216656054","pt":1631554082532,"mc":[{"id":"1.187566733","rc":[{"trd":[[1.5,1175.25]],"batb":[[0,1.5,44.74],[1,1.49,112.5],[2,1.48,118.24]],"batl":[[0,1.51,58.15],[1,1.52,15.51],[2,1.53,139.37]],"ltp":1.5,"tv":5525.03,"id":8734382},{"batb":[[0,2.9,37.81],[1,2.84,10.56],[2,2.82,47.24]],"ltp":3.0,"tv":25607.4,"id":9323645}],"tv":31132.44}]}
{"op":"mcm","clk":"4216656208","pt":1631554084118,"mc":[{"id":"1.187566733","rc":[{"trd":[[1.5,1264.73]],"batb":[[0,1.49,112.5],[1,1.48,118.24],[2,1.47,10.14]],"batl":[[0,1.5,698.12],[1,1.51,58.15],[2,1.52,15.51]],"ltp":1.5,"tv":5614.51,"id":8734382},{"batl":[[0,3.2,274.74],[1,3.25,3.42],[2,810,0.07]],"ltp":3.0,"tv":25607.4,"id":9323645}],"tv":31221.92}]}
{"op":"mcm","clk":"4216656268","pt":1631554084746,"mc":[{"id":"1.187566733","rc":[{"trd":[[1.5,1276.61]],"batl":[[0,1.5,686.23]],"ltp":1.5,"tv":5626.39,"id":8734382},{"trd":[[3,171.86]],"batb":[[1,2.88,6.19],[2,2.84,10.56]],"batl":[[0,3.25,3.42],[1,810,0.07],[2,810,0]],"ltp":3.0,"tv":25613.34,"id":9323645}],"tv":31239.74}]}
{"op":"mcm","clk":"4216656443","pt":1631554086806,"mc":[{"id":"1.187566733","rc":[{"trd":[[1.49,28.12]],"batb":[[0,1.49,84.38]],"batl":[[0,1.5,745.79]],"ltp":1.49,"tv":5654.51,"id":8734382},{"trd":[[3.05,13.74]],"ltp":3.05,"tv":25627.08,"id":9323645}],"tv":31281.6}]}
{"op":"mcm","clk":"4216656544","pt":1631554087857,"mc":[{"id":"1.187566733","rc":[{"trd":[[1.49,87.86],[1.5,1674.29]],"batb":[[0,1.49,54.51]],"batl":[[0,1.5,546.95]],"ltp":1.49,"tv":6111.93,"id":8734382}],"tv":31739.02}]}
{"op":"mcm","clk":"4216656663","pt":1631554089140,"mc":[{"id":"1.187566733","rc":[{"batb":[[0,1.49,291.51]],"batl":[[0,1.5,547.34]],"ltp":1.49,"tv":6111.93,"id":8734382}]}]}
{"op":"mcm","clk":"4216656764","pt":1631554089918,"mc":[{"id":"1.187566733","rc":[{"batb":[[0,1.49,304.47]],"ltp":1.49,"tv":6111.93,"id":8734382}]}]}
{"op":"mcm","clk":"4216656836","pt":1631554090617,"mc":[{"id":"1.187566733","rc":[{"batb":[[1,1.48,133.32]],"ltp":1.49,"tv":6111.93,"id":8734382},{"batl":[[0,3.25,46.37]],"ltp":3.05,"tv":25627.08,"id":9323645}]}]}
{"op":"mcm","clk":"4216656965","pt":1631554091909,"mc":[{"id":"1.187566733","rc":[{"trd":[[1.49,130.47]],"batb":[[0,1.49,237]],"ltp":1.49,"tv":6154.54,"id":8734382},{"trd":[[3.05,34.55]],"batb":[[1,2.84,10.56],[2,2.82,47.24]],"ltp":3.05,"tv":25647.9,"id":9323645}],"tv":31802.44}]}
{"op":"mcm","clk":"4216657064","pt":1631554092816,"mc":[{"id":"1.187566733","rc":[{"trd":[[1.49,175.29]],"batb":[[0,1.49,214.59]],"ltp":1.49,"tv":6199.36,"id":8734382}],"tv":31847.26}]}
{"op":"mcm","clk":"4216657183","pt":1631554094052,"mc":[{"id":"1.187566733","rc":[{"trd":[[1.49,239.96]],"batb":[[0,1.49,182.26]],"ltp":1.49,"tv":6264.02,"id":8734382}],"tv":31911.93}]}
{"op":"mcm","clk":"4216657288","pt":1631554095049,"mc":[{"id":"1.187566733","rc":[{"batb":[[1,1.48,191.28],[2,1.47,112.07]],"ltp":1.49,"tv":6264.02,"id":8734382},{"batl":[[0,3.25,3.42]],"ltp":3.05,"tv":25647.9,"id":9323645}]}]}
{"op":"mcm","clk":"4216657359","pt":1631554095735,"mc":[{"id":"1.187566733","rc":[{"trd":[[1.49,248.19]],"batb":[[0,1.49,178.14]],"ltp":1.49,"tv":6272.26,"id":8734382}],"tv":31920.16}]}
{"op":"mcm","clk":"4216657545","pt":1631554097936,"mc":[{"id":"1.187566733","rc":[{"trd":[[1.49,363.29]],"batb":[[0,1.49,120.59]],"ltp":1.49,"tv":6387.36,"id":8734382},{"batb":[[0,2.96,6.11],[1,2.9,37.81],[2,2.84,10.56]],"batl":[[0,3.05,6.76],[1,3.25,3.42],[2,810,0.07]],"ltp":3.05,"tv":25647.9,"id":9323645}],"tv":32035.27}]}
{"op":"mcm","clk":"4216657721","pt":1631554099642,"mc":[{"id":"1.187566733","rc":[{"trd":[[1.49,465.7]],"batb":[[0,1.49,69.39]],"ltp":1.49,"tv":6489.77,"id":8734382}],"tv":32137.67}]}
{"op":"mcm","clk":"4216657870","pt":1631554101069,"mc":[{"id":"1.187566733","rc":[{"trd":[[1.49,604.48]],"batb":[[0,1.48,191.28],[1,1.47,112.07],[2,1.46,10.14]],"batl":[[0,1.49,116.92],[1,1.5,547.34],[2,1.51,58.15]],"ltp":1.49,"tv":6628.55,"id":8734382}],"tv":32276.45}]}
{"op":"mcm","clk":"4216658114","pt":1631554103447,"mc":[{"id":"1.187566733","rc":[{"trd":[[1.49,890.56]],"batl":[[0,1.49,3.75]],"ltp":1.49,"tv":6914.63,"id":8734382}],"tv":32562.53}]}
{"op":"mcm","clk":"4216658235","pt":1631554104648,"mc":[{"id":"1.187566733","rc":[{"batb":[[0,1.48,585.28]],"batl":[[0,1.5,547.34],[1,1.51,58.15],[2,1.52,15.51]],"ltp":1.49,"tv":6914.63,"id":8734382}]}]}
{"op":"mcm","clk":"4216658902","pt":1631554111849,"mc":[{"id":"1.187566733","rc":[{"batl":[[0,1.5,546.95]],"ltp":1.49,"tv":6914.63,"id":8734382}]}]}
{"op":"mcm","clk":"4216659212","pt":1631554115046,"mc":[{"id":"1.187566733","rc":[{"trd":[[1.48,0.78]],"batb":[[0,1.48,584.89]],"ltp":1.48,"tv":6915.41,"id":8734382}],"tv":32563.31}]}
{"op":"mcm","clk":"4216660055","pt":1631554124201,"mc":[{"id":"1.187566733","rc":[{"trd":[[1.48,2.17]],"batb":[[0,1.48,584.19]],"ltp":1.48,"tv":6916.8,"id":8734382}],"tv":32564.71}]}
{"op":"mcm","clk":"4216660429","pt":1631554128180,"mc":[{"id":"1.187566733","rc":[{"trd":[[1.5,2674.3]],"batl":[[0,1.5,46.95]],"ltp":1.5,"tv":7916.81,"id":8734382}],"tv":33564.71}]}
{"op":"mcm","clk":"4216660450","pt":1631554128391,"mc":[{"id":"1.187566733","rc":[{"batl":[[0,1.51,58.15],[1,1.52,15.51],[2,1.53,193.82]],"ltp":1.5,"tv":7916.81,"id":8734382}]}]}
{"op":"mcm","clk":"4216660720","pt":1631554131282,"mc":[{"id":"1.187566733","rc":[{"batb":[[0,1.49,143.05],[1,1.48,584.19],[2,1.47,112.07]],"ltp":1.5,"tv":7916.81,"id":8734382}]}]}
{"op":"mcm","clk":"4216662717","pt":1631554151506,"mc":[{"id":"1.187566733","rc":[{"batb":[[1,1.48,630.7],[2,1.47,167.74]],"ltp":1.5,"tv":7916.81,"id":8734382},{"batl":[[1,3.1,3.35],[2,3.15,3.9]],"ltp":3.05,"tv":25647.9,"id":9323645}]}]}
{"op":"mcm","clk":"4216664997","pt":1631554176176,"mc":[{"id":"1.187566733","rc":[{"batb":[[0,1.48,440.51],[1,1.47,55.67],[2,1.42,74.69]],"batl":[[0,1.6,41.26],[1,1.64,34.68],[2,1.53,0]],"ltp":1.5,"tv":7916.81,"id":8734382},{"batb":[[0,2.82,41.96],[1,2.66,25.17],[2,2.56,5.33]],"batl":[[0,3.1,3.35],[1,3.15,3.9],[2,810,0.07]],"ltp":3.05,"tv":25647.9,"id":9323645}]}]}
{"op":"mcm","clk":"4216665056","pt":1631554176872,"mc":[{"id":"1.187566733","rc":[{"batb":[[0,1.47,55.67],[1,1.39,81.65],[2,1.25,167.57]],"batl":[[0,1.64,34.68],[1,1.64,0]],"ltp":1.5,"tv":7916.81,"id":8734382},{"batb":[[0,2.66,19.89],[1,2.56,5.33],[2,2.14,31]],"batl":[[0,3.15,3.9],[1,810,0.07],[2,810,0]],"ltp":3.05,"tv":25647.9,"id":9323645}]}]}
{"op":"mcm","clk":"4216665235","pt":1631554179080,"mc":[{"id":"1.187566733","rc":[{"batb":[[1,1.46,78.68],[2,1.45,106.85]],"batl":[[0,1.58,90.51],[1,1.59,74.32],[2,1.64,34.68]],"ltp":1.5,"tv":7916.81,"id":8734382}]}]}
{"op":"mcm","clk":"4216665339","pt":1631554180185,"mc":[{"id":"1.187566733","rc":[{"batb":[[0,1.48,47.26],[1,1.47,55.67],[2,1.39,81.65]],"batl":[[0,1.64,34.68],[1,1.59,0],[2,1.64,0]],"ltp":1.5,"tv":7916.81,"id":8734382},{"batl":[[0,3.1,4.45],[1,3.15,3.9],[2,810,0.07]],"ltp":3.05,"tv":25647.9,"id":9323645}]}]}
{"op":"mcm","clk":"4216665367","pt":1631554180444,"mc":[{"id":"1.187566733","rc":[{"batb":[[0,1.47,55.67],[1,1.39,81.65],[2,1.25,167.57]],"ltp":1.5,"tv":7916.81,"id":8734382},{"batl":[[0,3.15,3.9],[1,810,0.07],[2,810,0]],"ltp":3.05,"tv":25647.9,"id":9323645}]}]}
{"op":"mcm","clk":"4216665486","pt":1631554181980,"mc":[{"id":"1.187566733","rc":[{"batb":[[0,1.49,154.89],[1,1.48,99.24],[2,1.47,55.67]],"batl":[[0,1.54,137.01],[1,1.55,80.91],[2,1.64,34.68]],"ltp":1.5,"tv":7916.81,"id":8734382}]}]}
{"op":"mcm","clk":"4216665650","pt":1631554183773,"mc":[{"id":"1.187566733","rc":[{"batb":[[1,1.48,157.5]],"batl":[[2,1.6,40.96]],"ltp":1.5,"tv":7916.81,"id":8734382},{"batb":[[0,2.66,24.67]],"batl":[[0,3.1,3.75],[1,3.15,3.9],[2,810,0.07]],"ltp":3.05,"tv":25647.9,"id":9323645}]}]}
{"op":"mcm","clk":"4216665789","pt":1631554185458,"mc":[{"id":"1.187566733","rc":[{"batb":[[0,1.47,55.67],[1,1.39,81.65],[2,1.25,167.57]],"batl":[[0,1.64,34.68],[1,1.55,0],[2,1.6,0]],"ltp":1.5,"tv":7916.81,"id":8734382},{"batb":[[0,2.66,19.89]],"batl":[[0,3.15,3.9],[1,810,0.07],[2,810,0]],"ltp":3.05,"tv":25647.9,"id":9323645}]}]}
{"op":"mcm","clk":"4216666058","pt":1631554188990,"mc":[{"id":"1.187566733","rc":[{"batl":[[0,1.58,90.51],[1,1.59,74.32]],"ltp":1.5,"tv":7916.81,"id":8734382}]}]}
{"op":"mcm","clk":"4216666174","pt":1631554190100,"mc":[{"id":"1.187566733","rc":[{"batl":[[0,1.49,50],[1,1.58,90.51],[2,1.59,74.32]],"ltp":1.5,"tv":7916.81,"id":8734382}]}]}
{"op":"mcm","clk":"4216666341","pt":1631554192165,"mc":[{"id":"1.187566733","rc":[{"trd":[[1.49,940.56],[1.58,6.47]],"batb":[[0,1.54,79.55],[1,1.53,184.86],[2,1.52,49.02]],"batl":[[0,1.56,13.24],[1,1.58,84.04],[2,1.59,121.49]],"ltp":1.58,"tv":7973.28,"id":8734382},{"trd":[[2.72,3.76],[3,196.69]],"batl":[[0,2.88,238.63],[1,2.92,13.7],[2,3.15,3.9]],"ltp":2.72,"tv":25676.49,"id":9323645}],"tv":33649.77}]}
{"op":"mcm","clk":"4216666384","pt":1631554192692,"mc":[{"id":"1.187566733","rc":[{"batb":[[1,1.53,106.42],[2,1.52,9.8]],"batl":[[2,1.59,93.18]],"ltp":1.58,"tv":7973.28,"id":8734382},{"batb":[[2,2.48,23.83]],"ltp":2.72,"tv":25676.49,"id":9323645}]}]}
{"op":"mcm","clk":"4216666728","pt":1631554196211,"mc":[{"id":"1.187566733","rc":[{"trd":[[1.56,8.45]],"batb":[[0,1.54,204.29]],"batl":[[0,1.56,65.53]],"ltp":1.56,"tv":7981.73,"id":8734382},{"trd":[[2.78,4.74]],"ltp":2.78,"tv":25681.23,"id":9323645}],"tv":33662.96}]}
{"op":"mcm","clk":"4216666893","pt":1631554198116,"mc":[{"id":"1.187566733","rc":[{"batb":[[2,1.52,59.54]],"ltp":1.56,"tv":7981.73,"id":8734382},{"batb":[[0,2.66,25.67],[1,2.6,4.49],[2,2.56,5.33]],"batl":[[2,2.94,4.25]],"ltp":2.78,"tv":25681.23,"id":9323645}]}]}
{"op":"mcm","clk":"4216666920","pt":1631554198389,"mc":[{"id":"1.187566733","rc":[{"batb":[[2,1.52,9.8]],"ltp":1.56,"tv":7981.73,"id":8734382}]}]}
{"op":"mcm","clk":"4216667033","pt":1631554199393,"mc":[{"id":"1.187566733","rc":[{"batl":[[1,1.57,37.9],[2,1.58,84.04]],"ltp":1.56,"tv":7981.73,"id":8734382}]}]}
{"op":"mcm","clk":"4216667323","pt":1631554201917,"mc":[{"id":"1.187566733","rc":[{"trd":[[1.54,11.14]],"batb":[[0,1.54,316.15]],"ltp":1.54,"tv":7992.87,"id":8734382},{"trd":[[2.86,6]],"ltp":2.86,"tv":25687.23,"id":9323645}],"tv":33680.1}]}
{"op":"mcm","clk":"4216667471","pt":1631554203206,"mc":[{"id":"1.187566733","rc":[{"batb":[[1,1.53,86.82],[2,1.47,120.37]],"batl":[[0,1.57,37.9],[1,1.58,84.04],[2,1.59,74.32]],"ltp":1.54,"tv":7992.87,"id":8734382},{"batl":[[0,2.94,4.25],[1,3.15,3.9],[2,810,0.07]],"ltp":2.86,"tv":25687.23,"id":9323645}]}]}
{"op":"mcm","clk":"4216667554","pt":1631554203999,"mc":[{"id":"1.187566733","rc":[{"batb":[[0,1.54,123],[1,1.47,55.67],[2,1.44,71.58]],"batl":[[0,1.62,37.25],[1,1.58,0],[2,1.59,0]],"ltp":1.54,"tv":7992.87,"id":8734382},{"batb":[[0,2.48,23.83],[1,2.14,31],[2,1.8,11.97]],"batl":[[0,3.15,3.9],[1,810,0.07],[2,810,0]],"ltp":2.86,"tv":25687.23,"id":9323645}]}]}
{"op":"mcm","clk":"4216667636","pt":1631554204798,"mc":[{"id":"1.187566733","rc":[{"batb":[[0,1.44,71.58],[1,1.25,167.57],[2,1.2,448.84]],"ltp":1.54,"tv":7992.87,"id":8734382},{"batl":[[0,810,0.07],[1,810,0]],"ltp":2.86,"tv":25687.23,"id":9323645}]}]}
{"op":"mcm","clk":"4216667711","pt":1631554205538,"mc":[{"id":"1.187566733","rc":[{"batb":[[0,1.52,49.24],[1,1.44,71.58],[2,1.25,167.57]],"ltp":1.54,"tv":7992.87,"id":8734382}]}]}
{"op":"mcm","clk":"4216667860","pt":1631554206815,"mc":[{"id":"1.187566733","rc":[{"batb":[[1,1.5,121.83],[2,1.49,96.37]],"batl":[[1,1.65,87.54],[2,1.66,64.29]],"ltp":1.54,"tv":7992.87,"id":8734382},{"batb":[[0,2.6,5.29],[1,2.48,23.83],[2,2.14,31]],"batl":[[0,2.94,5.25],[1,810,0.07]],"ltp":2.86,"tv":25687.23,"id":9323645}]}]}
{"op":"mcm","clk":"4216668223","pt":1631554210028,"mc":[{"id":"1.187566733","rc":[{"batl":[[0,1.6,43.81],[1,1.62,37.25],[2,1.65,87.54]],"ltp":1.54,"tv":7992.87,"id":8734382},{"batb":[[0,2.66,4.81],[1,2.6,5.29],[2,2.48,23.83]],"ltp":2.86,"tv":25687.23,"id":9323645}]}]}
{"op":"mcm","clk":"4216668285","pt":1631554210409,"mc":[{"id":"1.187566733","rc":[{"batl":[[0,1.62,37.25],[1,1.65,87.54],[2,1.66,64.29]],"ltp":1.54,"tv":7992.87,"id":8734382},{"batb":[[0,2.6,5.29],[1,2.48,23.83],[2,2.14,31]],"ltp":2.86,"tv":25687.23,"id":9323645}]}]}
{"op":"mcm","clk":"4216668551","pt":1631554213046,"mc":[{"id":"1.187566733","rc":[{"batb":[[1,1.44,71.58],[2,1.25,167.57]],"batl":[[1,1.65,0],[2,1.66,0]],"ltp":1.54,"tv":7992.87,"id":8734382}]}]}
{"op":"mcm","clk":"4216668646","pt":1631554213944,"mc":[{"id":"1.187566733","rc":[{"batl":[[1,810,0]],"ltp":2.86,"tv":25687.23,"id":9323645}]}]}
{"op":"mcm","clk":"4216668838","pt":1631554216050,"mc":[{"id":"1.187566733","rc":[{"batb":[[1,1.5,366.2],[2,1.49,96.37]],"batl":[[0,1.54,76.88],[1,1.55,124.69],[2,1.58,659.57]],"ltp":1.54,"tv":7992.87,"id":8734382},{"batb":[[0,2.88,5.13],[1,2.86,52.44],[2,2.84,26.22]],"batl":[[1,2.96,7.1],[2,3,121.91]],"ltp":2.86,"tv":25687.23,"id":9323645}]}]}
{"op":"mcm","clk":"4216668940","pt":1631554217055,"mc":[{"id":"1.187566733","rc":[{"trd":[[2.88,7.24]],"batb":[[0,2.88,1.51],[1,2.86,10.48],[2,2.84,5.24]],"ltp":2.88,"tv":25694.47,"id":9323645}],"tv":33687.34}]}
{"op":"mcm","clk":"4216669300","pt":1631554220838,"mc":[{"id":"1.187566733","rc":[{"batb":[[0,1.52,140.43]],"ltp":1.54,"tv":7992.87,"id":8734382}]}]}
{"op":"mcm","clk":"4216669538","pt":1631554222935,"mc":[{"id":"1.187566733","rc":[{"batb":[[1,1.51,54.99],[2,1.5,420.06]],"batl":[[2,1.57,39.5]],"ltp":1.54,"tv":7992.87,"id":8734382},{"batl":[[2,2.98,4.75]],"ltp":2.88,"tv":25694.47,"id":9323645}]}]}
{"op":"mcm","clk":"4216669598","pt":1631554223563,"mc":[{"id":"1.187566733","rc":[{"trd":[[1.52,839.74]],"batb":[[0,1.52,121.35]],"ltp":1.52,"tv":8239.03,"id":8734382}],"tv":33933.5}]}
{"op":"mcm","clk":"4216669782","pt":1631554225878,"mc":[{"id":"1.187566733","rc":[{"trd":[[1.52,1082.44]],"batb":[[0,1.51,54.99],[1,1.5,420.06],[2,1.49,96.37]],"batl":[[0,1.52,1.73],[1,1.54,76.88],[2,1.55,124.69]],"ltp":1.52,"tv":8481.73,"id":8734382}],"tv":34176.21}]}
{"op":"mcm","clk":"4216669901","pt":1631554226942,"mc":[{"id":"1.187566733","rc":[{"batb":[[0,1.51,131.94]],"batl":[[0,1.54,142.83],[1,1.55,124.69],[2,1.57,39.5]],"ltp":1.52,"tv":8481.73,"id":8734382},{"batb":[[0,2.86,10.48],[1,2.84,5.24],[2,2.82,5.24]],"batl":[[1,2.98,4.75],[2,3,126.64]],"ltp":2.88,"tv":25694.47,"id":9323645}]}]}
{"op":"mcm","clk":"4216670031","pt":1631554228051,"mc":[{"id":"1.187566733","rc":[{"batb":[[0,1.5,53.86],[1,1.41,77.88],[2,1.25,167.57]],"batl":[[0,1.52,100],[1,1.57,39.5],[2,1.59,44.5]],"ltp":1.52,"tv":8481.73,"id":8734382},{"batb":[[0,2.74,4.79],[1,2.68,5.36],[2,2.6,5.29]],"batl":[[0,3,4.73],[1,2.98,0],[2,3,0]],"ltp":2.88,"tv":25694.47,"id":9323645}]}]}
{"op":"mcm","clk":"4216670112","pt":1631554229044,"mc":[{"id":"1.187566733","rc":[{"trd":[[1.52,1282.44],[1.55,143.52]],"batb":[[0,1.55,28.24],[1,1.52,73.95],[2,1.5,53.86]],"batl":[[0,1.57,39.5],[1,1.59,44.5],[2,1.62,37.25]],"ltp":1.55,"tv":8825.25,"id":8734382}],"tv":34519.73}]}
{"op":"mcm","clk":"4216670210","pt":1631554230042,"mc":[{"id":"1.187566733","rc":[{"trd":[[1.55,165.86]],"batb":[[0,1.55,17.07],[1,1.5,53.86],[2,1.41,77.88]],"batl":[[0,1.59,44.5],[1,1.59,0],[2,1.62,0]],"ltp":1.55,"tv":8847.59,"id":8734382},{"batb":[[0,2.68,5.36],[1,2.58,21.4],[2,2.14,31]],"ltp":2.88,"tv":25694.47,"id":9323645}],"tv":34542.07}]}
{"op":"mcm","clk":"4216670285","pt":1631554230975,"mc":[{"id":"1.187566733","rc":[{"batb":[[2,1.47,105.16]],"batl":[[1,1.61,117.03],[2,1.62,69.53]],"ltp":1.55,"tv":8847.59,"id":8734382}]}]}
{"op":"mcm","clk":"4216670374","pt":1631554232176,"mc":[{"id":"1.187566733","rc":[{"trd":[[1.55,200]],"batb":[[0,1.5,53.86],[1,1.47,105.16],[2,1.46,104.22]],"ltp":1.55,"tv":8881.73,"id":8734382}],"tv":34576.21}]}
{"op":"mcm","clk":"4216670628","pt":1631554234973,"mc":[{"id":"1.187566733","rc":[{"batb":[[0,1.51,53.99],[1,1.5,53.86],[2,1.47,105.16]],"ltp":1.55,"tv":8881.73,"id":8734382},{"batl":[[0,2.98,4.75],[1,3,4.73]],"ltp":2.88,"tv":25694.47,"id":9323645}]}]}
{"op":"mcm","clk":"4216670721","pt":1631554236077,"mc":[{"id":"1.187566733","rc":[{"batb":[[0,1.5,53.86],[1,1.47,105.16],[2,1.46,104.22]],"batl":[[0,1.57,63.5],[1,1.59,44.5],[2,1.61,117.03]],"ltp":1.55,"tv":8881.73,"id":8734382},{"batb":[[0,2.74,5.29],[1,2.68,5.36],[2,2.58,21.4]],"batl":[[0,3,4.73],[1,3,0]],"ltp":2.88,"tv":25694.47,"id":9323645}]}]}
{"op":"mcm","clk":"4216670759","pt":1631554236453,"mc":[{"id":"1.187566733","rc":[{"batl":[[0,1.59,44.5],[1,1.61,117.03],[2,1.62,69.53]],"ltp":1.55,"tv":8881.73,"id":8734382},{"batb":[[0,2.68,5.36],[1,2.58,21.4],[2,2.14,31]],"ltp":2.88,"tv":25694.47,"id":9323645}]}]}
{"op":"mcm","clk":"4216670844","pt":1631554237554,"mc":[{"id":"1.187566733","rc":[{"batl":[[0,2.86,2.17],[1,3,4.73]],"ltp":2.88,"tv":25694.47,"id":9323645}]}]}
{"op":"mcm","clk":"4216671049","pt":1631554239979,"mc":[{"id":"1.187566733","rc":[{"batl":[[0,3,4.73],[1,3,0]],"ltp":2.88,"tv":25694.47,"id":9323645}]}]}
{"op":"mcm","clk":"4216671113","pt":1631554240667,"mc":[{"id":"1.187566733","rc":[{"batb":[[1,1.41,77.88],[2,1.25,167.57]],"ltp":1.55,"tv":8881.73,"id":8734382}]}]}
{"op":"mcm","clk":"4216671237","pt":1631554242177,"mc":[{"id":"1.187566733","rc":[{"batb":[[0,1.51,47.99],[1,1.5,53.86],[2,1.41,77.88]],"ltp":1.55,"tv":8881.73,"id":8734382},{"batl":[[0,2.98,4.75],[1,3,4.73]],"ltp":2.88,"tv":25694.47,"id":9323645}]}]}
{"op":"mcm","clk":"4216671330","pt":1631554243154,"mc":[{"id":"1.187566733","rc":[{"batb":[[0,1.5,53.86],[1,1.41,77.88],[2,1.25,167.57]],"batl":[[0,1.57,60.5],[1,1.59,44.5],[2,1.61,117.03]],"ltp":1.55,"tv":8881.73,"id":8734382},{"batb":[[0,2.74,5.29],[1,2.68,5.36],[2,2.58,21.4]],"batl":[[0,3,4.73],[1,3,0]],"ltp":2.88,"tv":25694.47,"id":9323645}]}]}
{"op":"mcm","clk":"4216671377","pt":1631554243677,"mc":[{"id":"1.187566733","rc":[{"trd":[[1.57,25.19]],"batb":[[0,1.56,113.59],[1,1.55,83.02],[2,1.5,53.86]],"batl":[[0,1.59,44.5],[1,1.61,117.03],[2,1.62,90.44]],"ltp":1.57,"tv":8892.52,"id":8734382},{"trd":[[2.74,25.01]],"batb":[[0,2.68,5.36],[1,2.6,233.41]],"batl":[[0,2.78,10.8],[1,2.8,5.4],[2,2.82,5.4]],"ltp":2.74,"tv":25711.23,"id":9323645}],"tv":34603.76}]}
{"op":"mcm","clk":"4216671492","pt":1631554244895,"mc":[{"id":"1.187566733","rc":[{"batb":[[2,1.5,114.7]],"ltp":1.57,"tv":8892.52,"id":8734382},{"trd":[[2.78,13.74]],"batb":[[1,2.6,244.95],[2,2.58,27.16]],"batl":[[0,2.78,6.3]],"ltp":2.78,"tv":25720.23,"id":9323645}],"tv":34612.76}]}
{"op":"mcm","clk":"4216671755","pt":1631554247954,"mc":[{"id":"1.187566733","rc":[{"batb":[[0,1.56,182.48]],"ltp":1.57,"tv":8892.52,"id":8734382}]}]}
{"op":"mcm","clk":"4216672022","pt":1631554250893,"mc":[{"id":"1.187566733","rc":[{"batb":[[2,1.52,45.49]],"ltp":1.57,"tv":8892.52,"id":8734382},{"batb":[[2,2.58,33.22]],"ltp":2.78,"tv":25720.23,"id":9323645}]}]}
{"op":"mcm","clk":"4216672312","pt":1631554253711,"mc":[{"id":"1.187566733","rc":[{"batl":[[2,1.62,69.53]],"ltp":1.57,"tv":8892.52,"id":8734382}]}]}
{"op":"mcm","clk":"4216672484","pt":1631554255570,"mc":[{"id":"1.187566733","rc":[{"batl":[[0,2.74,2.17],[1,2.78,6.3],[2,2.8,5.4]],"ltp":2.78,"tv":25720.23,"id":9323645}]}]}
{"op":"mcm","clk":"4216672577","pt":1631554256573,"mc":[{"id":"1.187566733","rc":[{"batl":[[1,1.6,16.93],[2,1.61,117.03]],"ltp":1.57,"tv":8892.52,"id":8734382},{"batl":[[1,2.78,16.88]],"ltp":2.78,"tv":25720.23,"id":9323645}]}]}
{"op":"mcm","clk":"4216672696","pt":1631554257683,"mc":[{"id":"1.187566733","rc":[{"trd":[[2.68,3.6]],"batb":[[0,2.68,3.56]],"batl":[[0,2.78,16.88],[1,2.8,5.4],[2,2.82,5.4]],"ltp":2.68,"tv":25723.83,"id":9323645}],"tv":34616.36}]}
{"op":"mcm","clk":"4216672937","pt":1631554260089,"mc":[{"id":"1.187566733","rc":[{"batb":[[0,1.5,53.86],[1,1.46,67.89],[2,1.25,167.57]],"batl":[[0,1.65,51.5],[1,1.6,0],[2,1.61,0]],"ltp":1.57,"tv":8892.52,"id":8734382},{"batb":[[0,2.52,5.49],[1,2.4,26.18],[2,2.14,31]],"batl":[[0,3,4.73],[1,2.8,0],[2,2.82,0]],"ltp":2.68,"tv":25723.83,"id":9323645}]}]}
{"op":"mcm","clk":"4216673047","pt":1631554261317,"mc":[{"id":"1.187566733","rc":[{"batl":[[0,1.56,13.85],[1,1.65,51.5]],"ltp":1.57,"tv":8892.52,"id":8734382}]}]}
{"op":"mcm","clk":"4216673191","pt":1631554262594,"mc":[{"id":"1.187566733","rc":[{"batb":[[0,1.52,97.74],[1,1.51,91.35],[2,1.5,53.86]],"batl":[[2,1.69,93.07]],"ltp":1.57,"tv":8892.52,"id":8734382}]}]}
{"op":"mcm","clk":"4216673314","pt":1631554263701,"mc":[{"id":"1.187566733","rc":[{"batl":[[2,1.69,0]],"ltp":1.57,"tv":8892.52,"id":8734382}]}]}
{"op":"mcm","clk":"4216673579","pt":1631554266209,"mc":[{"id":"1.187566733","rc":[{"batl":[[0,1.56,126.59],[1,1.57,48.08],[2,1.58,48.08]],"ltp":1.57,"tv":8892.52,"id":8734382},{"batb":[[0,2.68,74.62],[1,2.52,5.49],[2,2.4,26.18]],"batl":[[0,2.88,6.31],[1,2.92,186.4],[2,3,4.73]],"ltp":2.68,"tv":25723.83,"id":9323645}]}]}
{"op":"mcm","clk":"4216673618","pt":1631554266633,"mc":[{"id":"1.187566733","rc":[{"batl":[[0,1.56,230.96],[1,1.57,106.54],[2,1.58,28.85]],"ltp":1.57,"tv":8892.52,"id":8734382},{"batb":[[0,2.78,10.66],[1,2.68,44.77],[2,2.52,5.49]],"ltp":2.68,"tv":25723.83,"id":9323645}]}]}
{"op":"mcm","clk":"4216673733","pt":1631554267638,"mc":[{"id":"1.187566733","rc":[{"batb":[[2,1.5,73.86]],"batl":[[0,1.56,192.5],[1,1.57,87.31],[2,1.58,9.62]],"ltp":1.57,"tv":8892.52,"id":8734382},{"trd":[[2.78,21.1]],"batb":[[0,2.78,6.98],[1,2.72,18.71],[2,2.68,44.77]],"ltp":2.78,"tv":25731.19,"id":9323645}],"tv":34623.72}]}
{"op":"mcm","clk":"4216673795","pt":1631554268425,"mc":[{"id":"1.187566733","rc":[{"batl":[[0,1.56,178.65]],"ltp":1.57,"tv":8892.52,"id":8734382}]}]}
{"op":"mcm","clk":"4216674001","pt":1631554270420,"mc":[{"id":"1.187566733","rc":[{"batb":[[0,1.53,54.37],[1,1.52,97.74],[2,1.51,91.35]],"ltp":1.57,"tv":8892.52,"id":8734382}]}]}
{"op":"mcm","clk":"4216674322","pt":1631554273630,"mc":[{"id":"1.187566733","rc":[{"batb":[[2,2.68,49.88]],"ltp":2.78,"tv":25731.19,"id":9323645}]}]}
{"op":"mcm","clk":"4216674392","pt":1631554274531,"mc":[{"id":"1.187566733","rc":[{"batb":[[0,1.53,128.37]],"ltp":1.57,"tv":8892.52,"id":8734382}]}]}
{"op":"mcm","clk":"4216674509","pt":1631554275746,"mc":[{"id":"1.187566733","rc":[{"trd":[[1.53,100]],"batb":[[0,1.53,78.37]],"ltp":1.53,"tv":8992.52,"id":8734382}],"tv":34723.72}]}
{"op":"mcm","clk":"4216674805","pt":1631554278912,"mc":[{"id":"1.187566733","rc":[{"batl":[[0,1.56,208.99]],"ltp":1.53,"tv":8992.52,"id":8734382}]}]}
{"op":"mcm","clk":"4216675013","pt":1631554281143,"mc":[{"id":"1.187566733","rc":[{"batb":[[0,1.53,74],[1,1.48,59.76],[2,1.46,67.89]],"batl":[[0,1.59,49.5],[1,1.61,45.5],[2,1.65,51.5]],"ltp":1.53,"tv":8992.52,"id":8734382},{"batb":[[0,2.72,18.71],[1,2.68,5.11],[2,2.62,5.54]],"ltp":2.78,"tv":25731.19,"id":9323645}]}]}
{"op":"mcm","clk":"4216675057","pt":1631554281625,"mc":[{"id":"1.187566733","rc":[{"batb":[[0,1.48,59.76],[1,1.42,75.61],[2,1.25,167.57]],"batl":[[0,1.61,45.5],[1,1.61,0],[2,1.65,0]],"ltp":1.53,"tv":8992.52,"id":8734382},{"batb":[[0,2.62,5.54],[1,2.5,23.5],[2,2.14,31]],"ltp":2.78,"tv":25731.19,"id":9323645}]}]}
{"op":"mcm","clk":"4216675262","pt":1631554284079,"mc":[{"id":"1.187566733","rc":[{"batb":[[0,1.48,165.49],[1,1.47,101.41],[2,1.42,75.61]],"batl":[[1,1.64,94.66],[2,1.65,65.52]],"ltp":1.53,"tv":8992.52,"id":8734382}]}]}
{"op":"mcm","clk":"4216675345","pt":1631554284944,"mc":[{"id":"1.187566733","rc":[{"batl":[[0,3.1,3.85]],"ltp":2.78,"tv":25731.19,"id":9323645}]}]}
{"op":"mcm","clk":"4216675436","pt":1631554285952,"mc":[{"id":"1.187566733","rc":[{"batl":[[1,1.64,0],[2,1.65,0]],"ltp":1.53,"tv":8992.52,"id":8734382}]}]}
{"op":"mcm","clk":"4216675648","pt":1631554288123,"mc":[{"id":"1.187566733","rc":[{"batb":[[0,1.56,4.51],[1,1.5,43.66],[2,1.48,165.49]],"batl":[[0,1.59,49.5],[1,1.61,45.5]],"ltp":1.53,"tv":8992.52,"id":8734382},{"batb":[[0,2.68,5.36],[1,2.62,5.54],[2,2.5,23.5]],"batl":[[0,3,4.71],[1,3.1,3.85]],"ltp":2.78,"tv":25731.19,"id":9323645}]}]}
{"op":"mcm","clk":"4216675731","pt":1631554288852,"mc":[{"id":"1.187566733","rc":[{"trd":[[1.56,12.96]],"batb":[[0,1.48,700.89],[1,1.47,101.41],[2,1.42,75.61]],"batl":[[0,1.52,121.02],[1,1.53,143.83],[2,1.54,29.41]],"ltp":1.56,"tv":8997.03,"id":8734382},{"trd":[[2.8,2.51]],"batb":[[0,2.84,236.09]],"batl":[[0,3.05,11.48]],"ltp":2.8,"tv":25733.7,"id":9323645}],"tv":34730.74}]}
{"op":"mcm","clk":"4216675832","pt":1631554289866,"mc":[{"id":"1.187566733","rc":[{"trd":[[1.52,1289.16]],"batb":[[1,1.47,121.81],[2,1.46,10.2]],"batl":[[0,1.52,114.3]],"ltp":1.52,"tv":9003.75,"id":8734382},{"trd":[[2.92,11.38]],"batb":[[0,2.84,277.46],[1,2.64,19.97],[2,2.62,5.54]],"ltp":2.92,"tv":25737.2,"id":9323645}],"tv":34740.96}]}
{"op":"mcm","clk":"4216676170","pt":1631554293060,"mc":[{"id":"1.187566733","rc":[{"batb":[[0,1.49,54.8],[1,1.48,700.89],[2,1.47,121.81]],"batl":[[0,1.51,29.95],[1,1.52,114.3],[2,1.53,143.83]],"ltp":1.52,"tv":9003.75,"id":8734382}]}]}
{"op":"mcm","clk":"4216676390","pt":1631554295454,"mc":[{"id":"1.187566733","rc":[{"batb":[[2,1.47,175.48]],"ltp":1.52,"tv":9003.75,"id":8734382},{"batb":[[0,2.84,282.18],[1,2.78,4.66],[2,2.64,19.97]],"batl":[[2,3.15,4.1]],"ltp":2.92,"tv":25737.2,"id":9323645}]}]}
{"op":"mcm","clk":"4216676702","pt":1631554298741,"mc":[{"id":"1.187566733","rc":[{"batb":[[0,1.49,205.8]],"ltp":1.52,"tv":9003.75,"id":8734382}]}]}
{"op":"mcm","clk":"4216676785","pt":1631554299743,"mc":[{"id":"1.187566733","rc":[{"batl":[[1,1.52,108]],"ltp":1.52,"tv":9003.75,"id":8734382},{"batl":[[0,3.1,3.85],[1,3.15,4.1],[2,3.15,0]],"ltp":2.92,"tv":25737.2,"id":9323645}]}]}
{"op":"mcm","clk":"4216676946","pt":1631554301857,"mc":[{"id":"1.187566733","rc":[{"batl":[[1,1.52,171.74]],"ltp":1.52,"tv":9003.75,"id":8734382}]}]}
{"op":"mcm","clk":"4216677009","pt":1631554302654,"mc":[{"id":"1.187566733","rc":[{"batb":[[0,1.5,7.97],[1,1.49,205.8],[2,1.48,700.89]],"ltp":1.52,"tv":9003.75,"id":8734382},{"batb":[[0,2.88,9.97],[1,2.84,282.18],[2,2.78,4.66]],"batl":[[0,3,3.98],[1,3.1,3.85],[2,3.15,4.1]],"ltp":2.92,"tv":25737.2,"id":9323645}]}]}
{"op":"mcm","clk":"4216677230","pt":1631554304981,"mc":[{"id":"1.187566733","rc":[{"batb":[[0,1.49,205.8],[1,1.48,165.49],[2,1.47,155.08]],"batl":[[2,1.53,85.01]],"ltp":1.52,"tv":9003.75,"id":8734382},{"batb":[[0,2.84,46.09],[1,2.78,4.66],[2,2.64,19.97]],"batl":[[0,3.1,3.85],[1,3.15,4.1],[2,3.15,0]],"ltp":2.92,"tv":25737.2,"id":9323645}]}]}
{"op":"mcm","clk":"4216677331","pt":1631554306166,"mc":[{"id":"1.187566733","rc":[{"batb":[[0,1.49,151],[1,1.48,59.76],[2,1.47,53.67]],"batl":[[0,1.56,51.42],[1,1.52,0],[2,1.53,0]],"ltp":1.52,"tv":9003.75,"id":8734382},{"batb":[[0,2.78,4.66],[1,2.64,19.97],[2,2.14,31]],"ltp":2.92,"tv":25737.2,"id":9323645}]}]}
{"op":"mcm","clk":"4216677356","pt":1631554306477,"mc":[{"id":"1.187566733","rc":[{"batb":[[0,1.48,59.76],[1,1.47,53.67],[2,1.39,83.5]],"ltp":1.52,"tv":9003.75,"id":8734382}]}]}
{"op":"mcm","clk":"4216677487","pt":1631554308060,"mc":[{"id":"1.187566733","rc":[{"batb":[[0,1.49,53.01],[1,1.48,59.76],[2,1.47,53.67]],"ltp":1.52,"tv":9003.75,"id":8734382},{"batl":[[0,3.05,4.7],[1,3.1,3.85],[2,3.15,4.1]],"ltp":2.92,"tv":25737.2,"id":9323645}]}]}
{"op":"mcm","clk":"4216677575","pt":1631554308959,"mc":[{"id":"1.187566733","rc":[{"batb":[[0,1.48,59.76],[1,1.47,53.67],[2,1.45,88.43]],"batl":[[0,1.54,52.25],[1,1.56,51.42],[2,1.58,102.71]],"ltp":1.52,"tv":9003.75,"id":8734382},{"batb":[[0,2.84,4.22],[1,2.78,4.66],[2,2.64,19.97]],"batl":[[0,3.1,3.85],[1,3.15,4.1],[2,3.15,0]],"ltp":2.92,"tv":25737.2,"id":9323645}]}]}
{"op":"mcm","clk":"4216677595","pt":1631554309278,"mc":[{"id":"1.187566733","rc":[{"batl":[[0,1.56,51.42],[1,1.58,102.71],[2,1.59,74.2]],"ltp":1.52,"tv":9003.75,"id":8734382},{"batb":[[0,2.78,4.66],[1,2.64,19.97],[2,2.14,31]],"ltp":2.92,"tv":25737.2,"id":9323645}]}]}
{"op":"mcm","clk":"4216678113","pt":1631554315187,"mc":[{"id":"1.187566733","rc":[{"batb":[[2,1.39,83.5]],"ltp":1.52,"tv":9003.75,"id":8734382}]}]}
{"op":"mcm","clk":"4216678204","pt":1631554316188,"mc":[{"id":"1.187566733","rc":[{"batl":[[0,1.54,52.75],[1,1.56,51.42],[2,1.58,102.71]],"ltp":1.52,"tv":9003.75,"id":8734382},{"batb":[[0,2.84,4.72],[1,2.78,4.66],[2,2.64,19.97]],"ltp":2.92,"tv":25737.2,"id":9323645}]}]}
{"op":"mcm","clk":"4216678226","pt":1631554316494,"mc":[{"id":"1.187566733","rc":[{"batl":[[0,1.56,51.42],[1,1.58,102.71],[2,1.59,74.2]],"ltp":1.52,"tv":9003.75,"id":8734382},{"batb":[[0,2.78,4.66],[1,2.64,19.97],[2,2.14,31]],"ltp":2.92,"tv":25737.2,"id":9323645}]}]}
{"op":"mcm","clk":"4216678414","pt":1631554318086,"mc":[{"id":"1.187566733","rc":[{"batb":[[0,1.53,153.32],[1,1.52,89.54],[2,1.5,551.44]],"batl":[[1,1.58,118.19]],"ltp":1.52,"tv":9003.75,"id":8734382},{"trd":[[2.78,28.5]],"batb":[[0,2.64,20.93],[1,2.14,31],[2,1.8,11.97]],"batl":[[0,2.84,53.22],[1,2.88,31.25],[2,2.9,15.62]],"ltp":2.78,"tv":25744.6,"id":9323645}],"tv":34748.36}]}
{"op":"mcm","clk":"4216678518","pt":1631554319092,"mc":[{"id":"1.187566733","rc":[{"batb":[[1,2.46,24.59],[2,2.14,31]],"batl":[[1,2.88,10.42],[2,2.9,5.2]],"ltp":2.78,"tv":25744.6,"id":9323645}]}]}
{"op":"mcm","clk":"4216678884","pt":1631554323087,"mc":[{"id":"1.187566733","rc":[{"trd":[[1.54,16.68]],"ltp":1.54,"tv":9009.29,"id":8734382},{"trd":[[2.84,3]],"batl":[[0,2.84,50.22]],"ltp":2.84,"tv":25747.6,"id":9323645}],"tv":34756.9}]}
{"op":"mcm","clk":"4216679110","pt":1631554325980,"mc":[{"id":"1.187566733","rc":[{"batb":[[0,1.53,224.59],[2,1.51,51.99]],"batl":[[0,1.56,104.8]],"ltp":1.54,"tv":9009.29,"id":8734382},{"batb":[[0,2.66,5.74],[1,2.64,19.97],[2,2.6,5.09]],"ltp":2.84,"tv":25747.6,"id":9323645}]}]}
{"op":"mcm","clk":"4216679133","pt":1631554326299,"mc":[{"id":"1.187566733","rc":[{"batb":[[0,2.66,92.69]],"ltp":2.84,"tv":25747.6,"id":9323645}]}]}
{"op":"mcm","clk":"4216679369","pt":1631554329101,"mc":[{"id":"1.187566733","rc":[{"batb":[[0,1.54,91],[1,1.53,224.59],[2,1.52,89.54]],"ltp":1.54,"tv":9009.29,"id":8734382}]}]}
{"op":"mcm","clk":"4216679642","pt":1631554332305,"mc":[{"id":"1.187566733","rc":[{"batb":[[0,1.54,153.88]],"ltp":1.54,"tv":9009.29,"id":8734382}]}]}
{"op":"mcm","clk":"4216680583","pt":1631554344108,"mc":[{"id":"1.187566733","rc":[{"batb":[[0,1.54,91],[1,1.51,51.99],[2,1.49,58.01]],"batl":[[0,1.6,43.96],[1,1.62,45.25],[2,1.59,0]],"ltp":1.54,"tv":9009.29,"id":8734382},{"batb":[[0,2.66,4.78],[1,2.6,5.09],[2,2.46,24.59]],"batl":[[0,2.98,3.75],[1,3.05,4.3],[2,3.1,3.85]],"ltp":2.84,"tv":25747.6,"id":9323645}]}]}
{"op":"mcm","clk":"4216680622","pt":1631554344528,"mc":[{"id":"1.187566733","rc":[{"batb":[[0,1.49,58.01],[1,1.44,72.09],[2,1.25,167.57]],"batl":[[0,1.62,45.25],[1,1.62,0]],"ltp":1.54,"tv":9009.29,"id":8734382},{"batb":[[0,2.6,5.09],[1,2.46,24.59],[2,2.14,31]],"batl":[[0,3.05,4.3],[1,3.05,0],[2,3.1,0]],"ltp":2.84,"tv":25747.6,"id":9323645}]}]}
{"op":"mcm","clk":"4216680830","pt":1631554347025,"mc":[{"id":"1.187566733","rc":[{"batb":[[0,1.49,206.64],[1,1.48,99.14],[2,1.44,72.09]],"batl":[[1,1.66,93.82],[2,1.67,62.98]],"ltp":1.54,"tv":9009.29,"id":8734382}]}]}
{"op":"mcm","clk":"4216681192","pt":1631554351108,"mc":[{"id":"1.187566733","rc":[{"batb":[[0,1.51,43.99],[1,1.49,206.64],[2,1.48,99.14]],"batl":[[0,1.6,44.21],[1,1.62,45.25],[2,1.66,93.82]],"ltp":1.54,"tv":9009.29,"id":8734382},{"batb":[[0,2.66,5.78],[1,2.6,5.09],[2,2.46,24.59]],"batl":[[0,2.98,4.75],[1,3.05,4.3]],"ltp":2.84,"tv":25747.6,"id":9323645}]}]}
{"op":"mcm","clk":"4216681284","pt":1631554352011,"mc":[{"id":"1.187566733","rc":[{"batb":[[0,1.49,206.64],[1,1.48,99.14],[2,1.44,72.09]],"batl":[[0,1.62,45.25],[1,1.62,0],[2,1.66,0]],"ltp":1.54,"tv":9009.29,"id":8734382},{"batb":[[0,2.6,5.09],[1,2.46,24.59],[2,2.14,31]],"batl":[[0,3.05,4.3],[1,3.05,0]],"ltp":2.84,"tv":25747.6,"id":9323645}]}]}
{"op":"mcm","clk":"4216681592","pt":1631554355147,"mc":[{"id":"1.187566733","rc":[{"trd":[[1.52,1293.33]],"batl":[[0,1.52,22.81],[1,1.53,51.5],[2,1.54,156.13]],"ltp":1.52,"tv":9013.46,"id":8734382},{"trd":[[2.92,13.55]],"batb":[[0,2.88,9.21],[1,2.86,52.44],[2,2.84,26.22]],"batl":[[0,2.96,9.33],[1,3.05,312.16]],"ltp":2.92,"tv":25749.77,"id":9323645}],"tv":34763.23}]}
{"op":"mcm","clk":"4216681689","pt":1631554356108,"mc":[{"id":"1.187566733","rc":[{"trd":[[1.52,1300.15]],"batl":[[0,1.52,15.99]],"ltp":1.52,"tv":9020.28,"id":8734382},{"trd":[[2.92,17.1]],"batb":[[1,2.86,31.46],[2,2.84,15.73]],"batl":[[2,3.1,9.68]],"ltp":2.92,"tv":25753.32,"id":9323645}],"tv":34773.6}]}
{"op":"mcm","clk":"4216682068","pt":1631554360020,"mc":[{"id":"1.187566733","rc":[{"batb":[[0,1.51,122],[1,1.49,206.64],[2,1.48,99.14]],"ltp":1.52,"tv":9020.28,"id":8734382}]}]}
{"op":"mcm","clk":"4216682338","pt":1631554362718,"mc":[{"id":"1.187566733","rc":[{"batb":[[0,1.51,173.99],[1,1.5,46.12],[2,1.49,206.64]],"batl":[[1,1.53,78.21]],"ltp":1.52,"tv":9020.28,"id":8734382},{"batl":[[1,3,4.14],[2,3.05,312.16]],"ltp":2.92,"tv":25753.32,"id":9323645}]}]}
{"op":"mcm","clk":"4216682931","pt":1631554368138,"mc":[{"id":"1.187566733","rc":[{"batb":[[0,1.51,122],[2,1.49,58.01]],"batl":[[0,1.55,48.9],[1,1.57,47.5],[2,1.62,45.25]],"ltp":1.52,"tv":9020.28,"id":8734382},{"batb":[[0,2.8,4.83],[1,2.74,5.02],[2,2.6,26.15]],"batl":[[0,3,4.14],[1,3.05,4.3],[2,3.05,0]],"ltp":2.92,"tv":25753.32,"id":9323645}]}]}
{"op":"mcm","clk":"4216683008","pt":1631554368826,"mc":[{"id":"1.187566733","rc":[{"batb":[[0,1.49,58.01],[1,1.4,79.64],[2,1.25,167.57]],"batl":[[0,1.57,47.5],[1,1.57,0],[2,1.62,0]],"ltp":1.52,"tv":9020.28,"id":8734382},{"batb":[[0,2.74,5.02],[1,2.6,21.06],[2,2.14,31]],"batl":[[0,3.05,4.3],[1,3.05,0]],"ltp":2.92,"tv":25753.32,"id":9323645}]}]}
{"op":"mcm","clk":"4216683220","pt":1631554371055,"mc":[{"id":"1.187566733","rc":[{"batb":[[1,1.46,119.71],[2,1.45,107.62]],"batl":[[1,1.6,118.79],[2,1.61,70.96]],"ltp":1.52,"tv":9020.28,"id":8734382}]}]}
{"op":"mcm","clk":"4216683324","pt":1631554372064,"mc":[{"id":"1.187566733","rc":[{"batb":[[0,1.5,50.3],[1,1.49,58.01],[2,1.46,119.71]],"ltp":1.52,"tv":9020.28,"id":8734382},{"batl":[[0,3,4.55],[1,3.05,4.3]],"ltp":2.92,"tv":25753.32,"id":9323645}]}]}
{"op":"mcm","clk":"4216683357","pt":1631554372339,"mc":[{"id":"1.187566733","rc":[{"batb":[[0,1.49,58.01],[1,1.46,119.71],[2,1.45,107.62]],"ltp":1.52,"tv":9020.28,"id":8734382},{"batl":[[0,3.05,4.3],[1,3.05,0]],"ltp":2.92,"tv":25753.32,"id":9323645}]}]}
{"op":"mcm","clk":"4216683458","pt":1631554373351,"mc":[{"id":"1.187566733","rc":[{"batb":[[1,1.4,79.64],[2,1.25,167.57]],"batl":[[1,1.6,0],[2,1.61,0]],"ltp":1.52,"tv":9020.28,"id":8734382}]}]}
{"op":"mcm","clk":"4216683667","pt":1631554375141,"mc":[{"id":"1.187566733","rc":[{"batl":[[0,1.55,45.5],[1,1.57,47.5]],"ltp":1.52,"tv":9020.28,"id":8734382},{"batb":[[0,2.8,4.83],[1,2.74,5.02],[2,2.6,21.06]],"batl":[[0,2.92,2],[1,3.05,4.3]],"ltp":2.92,"tv":25753.32,"id":9323645}]}]}
{"op":"mcm","clk":"4216683770","pt":1631554376037,"mc":[{"id":"1.187566733","rc":[{"batl":[[0,1.57,47.5],[1,1.57,0]],"ltp":1.52,"tv":9020.28,"id":8734382},{"batb":[[0,2.74,5.02],[1,2.6,21.06],[2,2.14,31]],"batl":[[2,3.1,175.37]],"ltp":2.92,"tv":25753.32,"id":9323645}]}]}
{"op":"mcm","clk":"4216683842","pt":1631554376827,"mc":[{"id":"1.187566733","rc":[{"batb":[[0,1.5,157.78],[1,1.49,154.66],[2,1.4,79.64]],"batl":[[0,1.55,124.64],[1,1.56,79.13],[2,1.57,47.5]],"ltp":1.52,"tv":9020.28,"id":8734382},{"batl":[[2,3.1,0]],"ltp":2.92,"tv":25753.32,"id":9323645}]}]}
{"op":"mcm","clk":"4216684063","pt":1631554379163,"mc":[{"id":"1.187566733","rc":[{"batb":[[0,1.5,200.8]],"ltp":1.52,"tv":9020.28,"id":8734382},{"batl":[[1,3,4.19],[2,3.05,4.3]],"ltp":2.92,"tv":25753.32,"id":9323645}]}]}
{"op":"mcm","clk":"4216684097","pt":1631554379435,"mc":[{"id":"1.187566733","rc":[{"batb":[[0,1.5,157.78]],"ltp":1.52,"tv":9020.28,"id":8734382},{"batl":[[1,3.05,4.3],[2,3.05,0]],"ltp":2.92,"tv":25753.32,"id":9323645}]}]}
{"op":"mcm","clk":"4216684176","pt":1631554380273,"mc":[{"id":"1.187566733","rc":[{"batb":[[0,1.49,58.01],[1,1.4,79.64],[2,1.25,167.57]],"batl":[[0,1.57,47.5],[1,1.56,0],[2,1.57,0]],"ltp":1.52,"tv":9020.28,"id":8734382}]}]}
{"op":"mcm","clk":"4216684386","pt":1631554382056,"mc":[{"id":"1.187566733","rc":[{"batb":[[0,1.52,114],[1,1.49,58.01],[2,1.4,79.64]],"batl":[[0,1.55,46.5],[1,1.57,47.5]],"ltp":1.52,"tv":9020.28,"id":8734382},{"batb":[[0,2.8,4.38],[1,2.74,5.02],[2,2.6,21.06]],"ltp":2.92,"tv":25753.32,"id":9323645}]}]}
{"op":"mcm","clk":"4216684413","pt":1631554382276,"mc":[{"id":"1.187566733","rc":[{"batb":[[0,1.49,58.01],[1,1.4,79.64],[2,1.25,167.57]],"batl":[[0,1.57,47.5],[1,1.57,0]],"ltp":1.52,"tv":9020.28,"id":8734382},{"batb":[[0,2.74,5.02],[1,2.6,21.06],[2,2.14,31]],"ltp":2.92,"tv":25753.32,"id":9323645}]}]}
{"op":"mcm","clk":"4216684565","pt":1631554383646,"mc":[{"id":"1.187566733","rc":[{"trd":[[1.5,2785.02],[1.52,1303.99]],"batb":[[1,1.46,119.71],[2,1.45,107.62]],"batl":[[0,1.5,53.47],[1,1.57,47.5],[2,1.6,119.19]],"ltp":1.5,"tv":9134.85,"id":8734382},{"trd":[[2.92,19.1],[3,200.43]],"batl":[[0,3.05,4.3],[1,3.05,0]],"ltp":3.0,"tv":25759.06,"id":9323645}],"tv":34893.91}]}
{"op":"mcm","clk":"4216684924","pt":1631554387185,"mc":[{"id":"1.187566733","rc":[{"trd":[[1.5,2877.11]],"batl":[[0,1.57,47.5],[1,1.6,119.19],[2,1.61,70.96]],"ltp":1.5,"tv":9226.94,"id":8734382},{"trd":[[3,207.85]],"ltp":3.0,"tv":25766.48,"id":9323645}],"tv":34993.42}]}
{"op":"mcm","clk":"4216685132","pt":1631554389142,"mc":[{"id":"1.187566733","rc":[{"batl":[[0,1.55,74.7],[1,1.57,47.5],[2,1.6,119.19]],"ltp":1.5,"tv":9226.94,"id":8734382},{"batb":[[0,2.8,4.38],[1,2.74,5.02],[2,2.6,21.06]],"ltp":3.0,"tv":25766.48,"id":9323645}]}]}
{"op":"mcm","clk":"4216685163","pt":1631554389460,"mc":[{"id":"1.187566733","rc":[{"batl":[[0,1.57,47.5],[1,1.6,119.19],[2,1.61,70.96]],"ltp":1.5,"tv":9226.94,"id":8734382},{"batb":[[0,2.74,5.02],[1,2.6,21.06],[2,2.14,31]],"ltp":3.0,"tv":25766.48,"id":9323645}]}]}
{"op":"mcm","clk":"4216685905","pt":1631554396164,"mc":[{"id":"1.187566733","rc":[{"batl":[[0,1.55,88.7],[1,1.57,47.5],[2,1.6,119.19]],"ltp":1.5,"tv":9226.94,"id":8734382},{"batb":[[0,2.8,5.13],[1,2.74,5.02],[2,2.6,21.06]],"ltp":3.0,"tv":25766.48,"id":9323645}]}]}
{"op":"mcm","clk":"4216685938","pt":1631554396493,"mc":[{"id":"1.187566733","rc":[{"batl":[[0,1.57,47.5],[1,1.6,119.19],[2,1.61,70.96]],"ltp":1.5,"tv":9226.94,"id":8734382},{"batb":[[0,2.74,5.02],[1,2.6,21.06],[2,2.14,31]],"ltp":3.0,"tv":25766.48,"id":9323645}]}]}
{"op":"mcm","clk":"4216686103","pt":1631554397957,"mc":[{"id":"1.187566733","rc":[{"batb":[[1,1.4,79.64],[2,1.25,167.57]],"ltp":1.5,"tv":9226.94,"id":8734382}]}]}
{"op":"mcm","clk":"4216686412","pt":1631554401171,"mc":[{"id":"1.187566733","rc":[{"batb":[[0,1.55,118.96],[1,1.54,85.01],[2,1.49,58.01]],"batl":[[1,1.6,139.03]],"ltp":1.5,"tv":9226.94,"id":8734382},{"trd":[[2.74,32.47]],"batb":[[0,2.74,1.29]],"batl":[[0,2.78,8.78],[1,2.82,42.55],[2,2.84,258.22]],"ltp":2.74,"tv":25773.94,"id":9323645}],"tv":35000.88}]}
{"op":"mcm","clk":"4216686514","pt":1631554402166,"mc":[{"id":"1.187566733","rc":[{"batb":[[2,1.49,119.52]],"ltp":1.5,"tv":9226.94,"id":8734382},{"batb":[[1,2.64,11.36],[2,2.62,5.68]],"batl":[[2,2.84,237.09]],"ltp":2.74,"tv":25773.94,"id":9323645}]}]}
{"op":"mcm","clk":"4216686792","pt":1631554404971,"mc":[{"id":"1.187566733","rc":[{"batb":[[0,1.55,167.06]],"batl":[[0,1.57,70.03]],"ltp":1.5,"tv":9226.94,"id":8734382}]}]}
{"op":"mcm","clk":"4216687129","pt":1631554407988,"mc":[{"id":"1.187566733","rc":[{"batb":[[2,1.51,51.99]],"ltp":1.5,"tv":9226.94,"id":8734382}]}]}
{"op":"mcm","clk":"4216688003","pt":1631554416699,"mc":[{"id":"1.187566733","rc":[{"trd":[[1.55,242.12],[1.56,28.61]],"batb":[[0,1.55,146]],"ltp":1.55,"tv":9284.71,"id":8734382},{"trd":[[2.78,37.28]],"batl":[[0,2.82,42.55],[1,2.84,237.09],[2,2.86,5.28]],"ltp":2.78,"tv":25782.72,"id":9323645}],"tv":35067.43}]}
{"op":"mcm","clk":"4216688327","pt":1631554419971,"mc":[{"id":"1.187566733","rc":[{"batb":[[0,1.55,155.42]],"batl":[[1,1.6,150.38]],"ltp":1.55,"tv":9284.71,"id":8734382}]}]}
{"op":"mcm","clk":"4216688471","pt":1631554421395,"mc":[{"id":"1.187566733","rc":[{"batl":[[2,1.61,146.46]],"ltp":1.55,"tv":9284.71,"id":8734382},{"batb":[[2,2.62,11.22]],"ltp":2.78,"tv":25782.72,"id":9323645}]}]}
{"op":"mcm","clk":"4216689008","pt":1631554426919,"mc":[{"id":"1.187566733","rc":[{"batl":[[1,1.6,130.54]],"ltp":1.55,"tv":9284.71,"id":8734382}]}]}
{"op":"mcm","clk":"4216689284","pt":1631554429795,"mc":[{"id":"1.187566733","rc":[{"batb":[[0,1.56,97],[1,1.55,155.42],[2,1.54,85.01]],"batl":[[1,1.58,17.32],[2,1.6,130.54]],"ltp":1.55,"tv":9284.71,"id":8734382},{"batl":[[1,2.84,247.2]],"ltp":2.78,"tv":25782.72,"id":9323645}]}]}
{"op":"mcm","clk":"4216689524","pt":1631554432115,"mc":[{"id":"1.187566733","rc":[{"batb":[[1,1.51,51.99],[2,1.49,58.01]],"batl":[[0,1.62,75.75],[1,1.63,79.5],[2,1.64,73.93]],"ltp":1.55,"tv":9284.71,"id":8734382},{"batb":[[0,2.6,5.44],[1,2.58,5.56],[2,2.56,5.58]],"batl":[[0,2.98,4.25],[1,3.05,4.3],[2,2.86,0]],"ltp":2.78,"tv":25782.72,"id":9323645}]}]}
{"op":"mcm","clk":"4216689636","pt":1631554433117,"mc":[{"id":"1.187566733","rc":[{"batb":[[0,1.49,58.01],[1,1.45,69.49],[2,1.25,167.57]],"batl":[[0,1.63,79.5],[1,1.64,73.93],[2,1.64,0]],"ltp":1.55,"tv":9284.71,"id":8734382},{"batb":[[0,2.58,5.56],[1,2.56,5.58],[2,2.4,26.43]],"batl":[[0,3.05,4.32],[1,3.05,0]],"ltp":2.78,"tv":25782.72,"id":9323645}]}]}
{"op":"mcm","clk":"4216689814","pt":1631554435013,"mc":[{"id":"1.187566733","rc":[{"batb":[[0,1.51,82.09],[1,1.5,93.61],[2,1.49,58.01]],"batl":[[2,1.68,105.4]],"ltp":1.55,"tv":9284.71,"id":8734382}]}]}
{"op":"mcm","clk":"4216689890","pt":1631554435804,"mc":[{"id":"1.187566733","rc":[{"batb":[[0,1.49,58.01],[1,1.45,69.49],[2,1.25,167.57]],"batl":[[2,1.68,0]],"ltp":1.55,"tv":9284.71,"id":8734382}]}]}
{"op":"mcm","clk":"4216690009","pt":1631554437011,"mc":[{"id":"1.187566733","rc":[{"batl":[[0,3.05,4.3]],"ltp":2.78,"tv":25782.72,"id":9323645}]}]}
{"op":"mcm","clk":"4216690122","pt":1631554438112,"mc":[{"id":"1.187566733","rc":[{"batl":[[0,2.92,182.51],[1,3.05,4.3]],"ltp":2.78,"tv":25782.72,"id":9323645}]}]}
{"op":"mcm","clk":"4216690211","pt":1631554438907,"mc":[{"id":"1.187566733","rc":[{"batl":[[0,1.61,85.5],[1,1.63,79.5],[2,1.64,73.93]],"ltp":1.55,"tv":9284.71,"id":8734382},{"batb":[[0,2.62,6.04],[1,2.58,5.56],[2,2.56,5.58]],"batl":[[0,3.05,4.3],[1,3.05,0]],"ltp":2.78,"tv":25782.72,"id":9323645}]}]}
{"op":"mcm","clk":"4216690292","pt":1631554439970,"mc":[{"id":"1.187566733","rc":[{"batb":[[0,1.56,145.52],[1,1.55,83.3],[2,1.49,58.01]],"batl":[[0,1.61,87.19],[1,1.62,69.77],[2,1.63,79.5]],"ltp":1.55,"tv":9284.71,"id":8734382},{"batb":[[0,2.58,5.56],[1,2.56,5.58],[2,2.4,26.43]],"ltp":2.78,"tv":25782.72,"id":9323645}]}]}
{"op":"mcm","clk":"4216690423","pt":1631554441140,"mc":[{"id":"1.187566733","rc":[{"batb":[[0,1.49,58.01],[1,1.45,69.49],[2,1.25,167.57]],"batl":[[0,1.63,79.5],[1,1.64,73.93],[2,1.63,0]],"ltp":1.55,"tv":9284.71,"id":8734382}]}]}
{"op":"mcm","clk":"4216690645","pt":1631554443112,"mc":[{"id":"1.187566733","rc":[{"batb":[[0,1.57,39.45],[1,1.49,58.01],[2,1.45,69.49]],"batl":[[0,1.6,11.15],[1,1.63,79.5],[2,1.64,73.93]],"ltp":1.55,"tv":9284.71,"id":8734382}]}]}
{"op":"mcm","clk":"4216690708","pt":1631554443699,"mc":[{"id":"1.187566733","rc":[{"batb":[[0,1.51,82.09],[1,1.5,93.61],[2,1.49,58.01]],"batl":[[0,1.63,79.5],[1,1.64,73.93],[2,1.68,105.4]],"ltp":1.55,"tv":9284.71,"id":8734382}]}]}
{"op":"mcm","clk":"4216690937","pt":1631554446032,"mc":[{"id":"1.187566733","rc":[{"batl":[[0,1.61,80.5],[1,1.63,79.5],[2,1.64,73.93]],"ltp":1.55,"tv":9284.71,"id":8734382},{"batb":[[0,2.62,5.54],[1,2.58,5.56],[2,2.56,5.58]],"ltp":2.78,"tv":25782.72,"id":9323645}]}]}
{"op":"mcm","clk":"4216690976","pt":1631554446415,"mc":[{"id":"1.187566733","rc":[{"batl":[[0,1.63,79.5],[1,1.64,73.93],[2,1.68,105.4]],"ltp":1.55,"tv":9284.71,"id":8734382},{"batb":[[0,2.58,5.56],[1,2.56,5.58],[2,2.4,26.43]],"ltp":2.78,"tv":25782.72,"id":9323645}]}]}
{"op":"mcm","clk":"4216691145","pt":1631554448001,"mc":[{"id":"1.187566733","rc":[{"batb":[[0,1.51,130.08]],"ltp":1.55,"tv":9284.71,"id":8734382},{"batl":[[0,2.98,4.75],[1,3.05,4.3]],"ltp":2.78,"tv":25782.72,"id":9323645}]}]}
{"op":"mcm","clk":"4216691172","pt":1631554448320,"mc":[{"id":"1.187566733","rc":[{"batb":[[0,1.51,82.09]],"ltp":1.55,"tv":9284.71,"id":8734382},{"batl":[[0,3.05,4.3],[1,3.05,0]],"ltp":2.78,"tv":25782.72,"id":9323645}]}]}
{"op":"mcm","clk":"4216691420","pt":1631554450836,"mc":[{"id":"1.187566733","rc":[{"batb":[[0,1.49,58.01],[1,1.45,69.49],[2,1.25,167.57]],"ltp":1.55,"tv":9284.71,"id":8734382}]}]}
{"op":"mcm","clk":"4216691656","pt":1631554453129,"mc":[{"id":"1.187566733","rc":[{"batl":[[0,1.61,79.5],[1,1.63,79.5],[2,1.64,73.93]],"ltp":1.55,"tv":9284.71,"id":8734382},{"batb":[[0,2.62,6.04],[1,2.58,5.56],[2,2.56,5.58]],"ltp":2.78,"tv":25782.72,"id":9323645}]}]}
{"op":"mcm","clk":"4216691757","pt":1631554454027,"mc":[{"id":"1.187566733","rc":[{"trd":[[1.63,157.96]],"batb":[[0,1.62,194.89],[1,1.61,18.64],[2,1.6,9.32]],"batl":[[0,1.64,83.75],[1,1.68,105.4],[2,1.7,651.98]],"ltp":1.63,"tv":9442.67,"id":8734382},{"trd":[[2.58,8]],"batb":[[0,2.58,1.56],[1,2.56,5.58],[2,2.4,26.43]],"batl":[[0,2.66,14.01],[1,2.84,916.6],[2,3.05,4.3]],"ltp":2.58,"tv":25790.72,"id":9323645}],"tv":35233.39}]}
{"op":"mcm","clk":"4216691865","pt":1631554455036,"mc":[{"id":"1.187566733","rc":[{"batl":[[1,1.68,79.94],[2,1.69,8.92]],"ltp":1.63,"tv":9442.67,"id":8734382}]}]}
{"op":"mcm","clk":"4216692088","pt":1631554457113,"mc":[{"id":"1.187566733","rc":[{"batb":[[0,1.62,230.41],[1,1.61,91.4]],"batl":[[1,1.67,86.32],[2,1.68,79.94]],"ltp":1.63,"tv":9442.67,"id":8734382}]}]}
{"op":"mcm","clk":"4216692181","pt":1631554457913,"mc":[{"id":"1.187566733","rc":[{"batb":[[0,1.62,268.52]],"batl":[[0,1.64,94.47]],"ltp":1.63,"tv":9442.67,"id":8734382}]}]}
{"op":"mcm","clk":"4216692501","pt":1631554461044,"mc":[{"id":"1.187566733","rc":[{"batl":[[2,2.86,4.25]],"ltp":2.58,"tv":25790.72,"id":9323645}]}]}
{"op":"mcm","clk":"4216693068","pt":1631554466538,"mc":[{"id":"1.187566733","rc":[{"trd":[[1.62,137.63]],"batb":[[0,1.62,199.71]],"ltp":1.62,"tv":9580.3,"id":8734382}],"tv":35371.02}]}
{"op":"mcm","clk":"4216693303","pt":1631554469116,"mc":[{"id":"1.187566733","rc":[{"batb":[[0,1.57,50.86],[1,1.54,49.12],[2,1.51,110.32]],"batl":[[0,1.72,35.91],[1,1.75,37.34],[2,1.68,0]],"ltp":1.62,"tv":9580.3,"id":8734382},{"batb":[[0,2.4,26.43],[1,2.38,5.96],[2,2.32,6.64]],"batl":[[0,2.86,4.25],[1,2.98,4.25],[2,3.05,4.3]],"ltp":2.58,"tv":25790.72,"id":9323645}]}]}
{"op":"mcm","clk":"4216693322","pt":1631554469326,"mc":[{"id":"1.187566733","rc":[{"batb":[[0,1.51,110.32],[1,1.25,167.57],[2,1.2,448.84]],"batl":[[0,1.75,37.34],[1,1.75,0]],"ltp":1.62,"tv":9580.3,"id":8734382},{"batb":[[0,2.32,6.64],[1,2.18,34.07],[2,2.14,31]],"batl":[[0,2.98,4.25],[1,2.98,0],[2,3.05,0]],"ltp":2.58,"tv":25790.72,"id":9323645}]}]}
{"op":"mcm","clk":"4216693571","pt":1631554471950,"mc":[{"id":"1.187566733","rc":[{"batb":[[0,1.56,103.42],[1,1.55,83.28],[2,1.51,110.32]],"batl":[[1,1.79,104.7],[2,1.81,98.54]],"ltp":1.62,"tv":9580.3,"id":8734382}]}]}
{"op":"mcm","clk":"4216693667","pt":1631554472952,"mc":[{"id":"1.187566733","rc":[{"batb":[[2,1.54,42.12]],"ltp":1.62,"tv":9580.3,"id":8734382},{"batl":[[0,2.86,4.25],[1,2.98,4.25]],"ltp":2.58,"tv":25790.72,"id":9323645}]}]}
{"op":"mcm","clk":"4216693764","pt":1631554473955,"mc":[{"id":"1.187566733","rc":[{"batl":[[0,2.58,20],[1,2.86,4.25],[2,2.98,4.25]],"ltp":2.58,"tv":25790.72,"id":9323645}]}]}
{"op":"mcm","clk":"4216693973","pt":1631554476159,"mc":[{"id":"1.187566733","rc":[{"trd":[[1.56,129.64],[1.63,189.62]],"batb":[[0,1.56,51.29]],"batl":[[0,1.58,25.95],[1,1.6,116.67],[2,1.61,118.61]],"ltp":1.56,"tv":9712.99,"id":8734382},{"trd":[[2.58,28],[2.78,51.64],[2.8,4.31]],"batl":[[0,2.84,368.49]],"ltp":2.8,"tv":25826.88,"id":9323645}],"tv":35539.87}]}
{"op":"mcm","clk":"4216694055","pt":1631554476952,"mc":[{"id":"1.187566733","rc":[{"trd":[[1.58,12.99]],"batl":[[0,1.58,19.43],[1,1.6,79.17],[2,1.61,99.86]],"ltp":1.58,"tv":9719.51,"id":8734382},{"trd":[[2.72,7.55]],"batb":[[0,2.56,22.07],[1,2.36,27.53],[2,2.32,6.64]],"batl":[[2,2.88,10.42]],"ltp":2.72,"tv":25830.67,"id":9323645}],"tv":35550.18}]}
{"op":"mcm","clk":"4216694336","pt":1631554479958,"mc":[{"id":"1.187566733","rc":[{"batb":[[0,1.56,121.54]],"batl":[[0,1.58,40.63],[1,1.6,164.13]],"ltp":1.58,"tv":9719.51,"id":8734382}]}]}
{"op":"mcm","clk":"4216694569","pt":1631554482456,"mc":[{"id":"1.187566733","rc":[{"batb":[[0,2.6,5.44],[1,2.56,27.65],[2,2.36,27.53]],"ltp":2.72,"tv":25830.67,"id":9323645}]}]}
{"op":"mcm","clk":"4216694943","pt":1631554485948,"mc":[{"id":"1.187566733","rc":[{"batb":[[0,1.56,243.54]],"batl":[[1,1.6,141.22]],"ltp":1.58,"tv":9719.51,"id":8734382}]}]}
{"op":"mcm","clk":"4216695234","pt":1631554489062,"mc":[{"id":"1.187566733","rc":[{"batb":[[0,1.56,122],[1,1.53,48.33],[2,1.51,50.99]],"batl":[[0,1.64,35.43],[1,1.6,0],[2,1.61,0]],"ltp":1.58,"tv":9719.51,"id":8734382},{"batb":[[0,2.56,5.58],[1,2.36,27.53],[2,2.14,31]],"batl":[[0,2.9,4.65],[1,2.98,4.25],[2,2.88,0]],"ltp":2.72,"tv":25830.67,"id":9323645}]}]}
{"op":"mcm","clk":"4216695317","pt":1631554489963,"mc":[{"id":"1.187566733","rc":[{"trd":[[1.56,148.13]],"batb":[[0,1.51,50.99],[1,1.46,66.55],[2,1.25,167.57]],"ltp":1.56,"tv":9738.0,"id":8734382},{"trd":[[2.8,14.61]],"batl":[[0,2.98,4.25],[1,2.98,0]],"ltp":2.8,"tv":25840.97,"id":9323645}],"tv":35578.97}]}
{"op":"mcm","clk":"4216695532","pt":1631554492072,"mc":[{"id":"1.187566733","rc":[{"batb":[[0,1.51,179.63],[1,1.5,94.62],[2,1.46,66.55]],"batl":[[1,1.68,62.32],[2,1.7,120.58]],"ltp":1.56,"tv":9738.0,"id":8734382}]}]}
{"op":"mcm","clk":"4216695640","pt":1631554493185,"mc":[{"id":"1.187566733","rc":[{"batb":[[0,1.53,47.33],[1,1.51,50.99]],"batl":[[1,1.68,0],[2,1.7,0]],"ltp":1.56,"tv":9738.0,"id":8734382},{"batl":[[0,2.9,4.45],[1,2.98,4.25]],"ltp":2.8,"tv":25840.97,"id":9323645}]}]}
{"op":"mcm","clk":"4216695671","pt":1631554493455,"mc":[{"id":"1.187566733","rc":[{"batb":[[0,1.51,50.99],[1,1.46,66.55],[2,1.25,167.57]],"ltp":1.56,"tv":9738.0,"id":8734382},{"batl":[[0,2.98,4.25],[1,2.98,0]],"ltp":2.8,"tv":25840.97,"id":9323645}]}]}
{"op":"mcm","clk":"4216695842","pt":1631554495146,"mc":[{"id":"1.187566733","rc":[{"batb":[[0,1.57,114.05],[1,1.56,81.63],[2,1.51,50.99]],"batl":[[0,1.62,111.94],[1,1.63,68.62],[2,1.64,35.43]],"ltp":1.56,"tv":9738.0,"id":8734382}]}]}
{"op":"mcm","clk":"4216695994","pt":1631554496677,"mc":[{"id":"1.187566733","rc":[{"batb":[[2,1.53,46.33]],"ltp":1.56,"tv":9738.0,"id":8734382},{"batl":[[0,2.9,4.25],[1,2.98,4.25]],"ltp":2.8,"tv":25840.97,"id":9323645}]}]}
{"op":"mcm","clk":"4216696231","pt":1631554498846,"mc":[{"id":"1.187566733","rc":[{"batl":[[0,1.62,149.69]],"ltp":1.56,"tv":9738.0,"id":8734382},{"batb":[[0,2.6,5.44],[1,2.56,5.58],[2,2.36,27.53]],"ltp":2.8,"tv":25840.97,"id":9323645}]}]}
{"op":"mcm","clk":"4216696314","pt":1631554499857,"mc":[{"id":"1.187566733","rc":[{"batb":[[0,1.58,46.55],[1,1.57,114.05],[2,1.56,81.63]],"batl":[[0,1.61,21.11],[1,1.62,111.94],[2,1.63,68.62]],"ltp":1.56,"tv":9738.0,"id":8734382},{"batb":[[0,2.56,5.58],[1,2.36,27.53],[2,2.14,31]],"ltp":2.8,"tv":25840.97,"id":9323645}]}]}
{"op":"mcm","clk":"4216696563","pt":1631554502159,"mc":[{"id":"1.187566733","rc":[{"batb":[[0,1.51,50.99],[1,1.46,66.55],[2,1.25,167.57]],"batl":[[0,1.64,35.43],[1,1.62,0],[2,1.63,0]],"ltp":1.56,"tv":9738.0,"id":8734382},{"batl":[[0,2.98,4.25],[1,2.98,0]],"ltp":2.8,"tv":25840.97,"id":9323645}]}]}
{"op":"mcm","clk":"4216696824","pt":1631554504892,"mc":[{"id":"1.187566733","rc":[{"batb":[[0,1.51,179.63],[1,1.5,94.62],[2,1.46,66.55]],"batl":[[1,1.68,62.32],[2,1.7,120.58]],"ltp":1.56,"tv":9738.0,"id":8734382}]}]}
{"op":"mcm","clk":"4216697237","pt":1631554508976,"mc":[{"id":"1.187566733","rc":[{"batb":[[0,1.53,46.33],[1,1.51,179.63],[2,1.5,94.62]],"ltp":1.56,"tv":9738.0,"id":8734382},{"batl":[[0,2.9,4.25],[1,2.98,4.25]],"ltp":2.8,"tv":25840.97,"id":9323645}]}]}
{"op":"mcm","clk":"4216697297","pt":1631554509689,"mc":[{"id":"1.187566733","rc":[{"batb":[[0,1.51,179.63],[1,1.5,94.62],[2,1.46,66.55]],"ltp":1.56,"tv":9738.0,"id":8734382},{"batl":[[0,2.98,4.25],[1,2.98,0]],"ltp":2.8,"tv":25840.97,"id":9323645}]}]}
{"op":"mcm","clk":"4216697376","pt":1631554510583,"mc":[{"id":"1.187566733","rc":[{"trd":[[2.56,0.38]],"batb":[[0,2.56,5.39]],"ltp":2.56,"tv":25841.34,"id":9323645}],"tv":35579.34}]}
{"op":"mcm","clk":"4216697507","pt":1631554512008,"mc":[{"id":"1.187566733","rc":[{"batb":[[0,1.51,50.99],[1,1.46,66.55],[2,1.25,167.57]],"ltp":1.56,"tv":9738.0,"id":8734382}]}]}
{"op":"mcm","clk":"4216697791","pt":1631554514859,"mc":[{"id":"1.187566733","rc":[{"batb":[[0,1.63,126.31],[1,1.62,71.48],[2,1.61,55.9]],"batl":[[0,1.64,44.84]],"ltp":1.56,"tv":9738.0,"id":8734382},{"trd":[[2.56,8.44]],"batb":[[0,2.56,1.36],[1,2.42,255.41],[2,2.36,27.53]],"batl":[[0,2.6,46.15],[1,2.66,14.08],[2,2.84,1062.34]],"ltp":2.56,"tv":25849.4,"id":9323645}],"tv":35587.4}]}
{"op":"mcm","clk":"4216697915","pt":1631554515974,"mc":[{"id":"1.187566733","rc":[{"batb":[[2,1.61,18.64]],"ltp":1.56,"tv":9738.0,"id":8734382},{"batb":[[1,2.46,12.2],[2,2.44,6.1]],"ltp":2.56,"tv":25849.4,"id":9323645}]}]}
{"op":"mcm","clk":"4216698239","pt":1631554519087,"mc":[{"id":"1.187566733","rc":[{"batb":[[1,1.62,116.74]],"batl":[[1,1.65,20.39],[2,1.68,62.32]],"ltp":1.56,"tv":9738.0,"id":8734382}]}]}
{"op":"mcm","clk":"4216698565","pt":1631554522300,"mc":[{"id":"1.187566733","rc":[{"batl":[[2,2.8,4.32]],"ltp":2.56,"tv":25849.4,"id":9323645}]}]}
{"op":"mcm","clk":"4216698897","pt":1631554525513,"mc":[{"id":"1.187566733","rc":[{"batb":[[0,1.63,169.61]],"ltp":1.56,"tv":9738.0,"id":8734382}]}]}
{"op":"mcm","clk":"4216699018","pt":1631554526900,"mc":[{"id":"1.187566733","rc":[{"trd":[[2.6,21]],"batl":[[0,2.6,35.65]],"ltp":2.6,"tv":25870.4,"id":9323645}],"tv":35608.4}]}
{"op":"mcm","clk":"4216699400","pt":1631554530919,"mc":[{"id":"1.187566733","rc":[{"trd":[[1.63,190.96]],"batb":[[0,1.63,168.94]],"ltp":1.63,"tv":9739.34,"id":8734382}],"tv":35609.74}]}
{"op":"mcm","clk":"4216699786","pt":1631554535000,"mc":[{"id":"1.187566733","rc":[{"batb":[[0,1.53,50.33],[1,1.52,57.15],[2,1.51,50.99]],"batl":[[0,1.75,34.5],[1,1.65,0],[2,1.68,0]],"ltp":1.63,"tv":9739.34,"id":8734382},{"batb":[[0,2.32,6.64],[1,2.14,67],[2,1.8,11.97]],"batl":[[0,2.9,5.05],[1,2.98,4.25],[2,2.8,0]],"ltp":2.6,"tv":25870.4,"id":9323645}]}]}
{"op":"mcm","clk":"4216699828","pt":1631554535426,"mc":[{"id":"1.187566733","rc":[{"batb":[[2,1.25,167.57]],"ltp":1.63,"tv":9739.34,"id":8734382},{"batl":[[1,2.98,0]],"ltp":2.6,"tv":25870.4,"id":9323645}]}]}
{"op":"mcm","clk":"4216700055","pt":1631554537708,"mc":[{"id":"1.187566733","rc":[{"batb":[[0,1.57,112.88],[1,1.56,81.62],[2,1.53,50.33]],"batl":[[1,1.8,78.69],[2,1.82,97.28]],"ltp":1.63,"tv":9739.34,"id":8734382}]}]}
{"op":"mcm","clk":"4216700147","pt":1631554538602,"mc":[{"id":"1.187566733","rc":[{"batb":[[1,1.56,132.45]],"ltp":1.63,"tv":9739.34,"id":8734382},{"batl":[[0,2.8,4.37],[1,2.9,5.05]],"ltp":2.6,"tv":25870.4,"id":9323645}]}]}
{"op":"mcm","clk":"4216700818","pt":1631554544746,"mc":[{"id":"1.187566733","rc":[{"batb":[[0,1.53,50.33],[1,1.52,57.15],[2,1.25,167.57]],"batl":[[0,1.8,78.69],[1,1.82,97.28],[2,1.82,0]],"ltp":1.63,"tv":9739.34,"id":8734382},{"batl":[[0,2.9,5.05],[1,2.9,0]],"ltp":2.6,"tv":25870.4,"id":9323645}]}]}
{"op":"mcm","clk":"4216701075","pt":1631554547201,"mc":[{"id":"1.187566733","rc":[{"batb":[[0,1.7,208.82],[1,1.69,44.12],[2,1.68,44.12]],"batl":[[2,1.83,477.71]],"ltp":1.63,"tv":9739.34,"id":8734382},{"trd":[[2.32,8.7]],"batb":[[0,2.32,17.01]],"batl":[[0,2.4,319.73],[1,2.9,5.05]],"ltp":2.32,"tv":25879.1,"id":9323645}],"tv":35618.44}]}
{"op":"mcm","clk":"4216701167","pt":1631554548146,"mc":[{"id":"1.187566733","rc":[{"batb":[[0,1.74,106.91],[1,1.72,116.21],[2,1.7,150.95]],"batl":[[0,1.78,84.28],[1,1.79,42.14],[2,1.8,120.83]],"ltp":1.63,"tv":9739.34,"id":8734382},{"batb":[[2,2.08,39.19]],"ltp":2.32,"tv":25879.1,"id":9323645}]}]}
{"op":"mcm","clk":"4216701196","pt":1631554548320,"mc":[{"id":"1.187566733","rc":[{"batb":[[2,1.7,80.35]],"batl":[[0,1.78,16.86],[1,1.79,8.42],[2,1.8,87.11]],"ltp":1.63,"tv":9739.34,"id":8734382}]}]}
{"op":"mcm","clk":"4216701309","pt":1631554549513,"mc":[{"id":"1.187566733","rc":[{"trd":[[2.32,42.72]],"batb":[[0,2.14,67],[1,2.08,39.19],[2,1.5,107.72]],"batl":[[0,2.32,2.99],[1,2.4,319.73],[2,2.9,5.05]],"ltp":2.32,"tv":25913.12,"id":9323645}],"tv":35652.46}]}
{"op":"mcm","clk":"4216701578","pt":1631554552124,"mc":[{"id":"1.187566733","rc":[{"batb":[[0,1.75,37.76],[1,1.74,106.91],[2,1.72,116.21]],"batl":[[0,1.77,13.33],[1,1.78,16.86],[2,1.79,8.42]],"ltp":1.63,"tv":9739.34,"id":8734382}]}]}
{"op":"mcm","clk":"4216701651","pt":1631554552814,"mc":[{"id":"1.187566733","rc":[{"batl":[[0,2.4,319.73],[1,2.9,5.05],[2,2.9,0]],"ltp":2.32,"tv":25913.12,"id":9323645}]}]}
{"op":"mcm","clk":"4216701843","pt":1631554554835,"mc":[{"id":"1.187566733","rc":[{"trd":[[1.75,17.04]],"batb":[[0,1.75,29.24]],"batl":[[2,1.79,36.92]],"ltp":1.75,"tv":9756.38,"id":8734382},{"batb":[[0,2.26,6.98],[1,2.24,7.77],[2,2.14,67]],"batl":[[1,2.58,5.94],[2,2.68,4.64]],"ltp":2.32,"tv":25913.12,"id":9323645}],"tv":35669.5}]}
{"op":"mcm","clk":"4216701956","pt":1631554556145,"mc":[{"id":"1.187566733","rc":[{"trd":[[1.75,22.46]],"batb":[[0,1.75,26.53]],"ltp":1.75,"tv":9761.8,"id":8734382},{"batb":[[2,2.18,291.65]],"ltp":2.32,"tv":25913.12,"id":9323645}],"tv":35674.92}]}
{"op":"mcm","clk":"4216702036","pt":1631554556941,"mc":[{"id":"1.187566733","rc":[{"batl":[[1,1.78,47.61]],"ltp":1.75,"tv":9761.8,"id":8734382},{"batb":[[0,2.28,6.41],[1,2.26,6.98],[2,2.24,7.77]],"ltp":2.32,"tv":25913.12,"id":9323645}]}]}
{"op":"mcm","clk":"4216702292","pt":1631554559839,"mc":[{"id":"1.187566733","rc":[{"batl":[[0,2.4,312.56]],"ltp":2.32,"tv":25913.12,"id":9323645}]}]}
{"op":"mcm","clk":"4216702490","pt":1631554562167,"mc":[{"id":"1.187566733","rc":[{"trd":[[2.28,14.99]],"batb":[[0,2.28,6.38]],"ltp":2.28,"tv":25913.18,"id":9323645}],"tv":35674.98}]}
{"op":"mcm","clk":"4216702548","pt":1631554562756,"mc":[{"id":"1.187566733","rc":[{"batb":[[1,1.74,118.64]],"batl":[[1,1.78,61.81]],"ltp":1.75,"tv":9761.8,"id":8734382}]}]}
{"op":"mcm","clk":"4216702853","pt":1631554565663,"mc":[{"id":"1.187566733","rc":[{"trd":[[1.77,115.26]],"batl":[[0,1.77,7.79]],"ltp":1.77,"tv":9772.87,"id":8734382}],"tv":35686.06}]}
{"op":"mcm","clk":"4216703079","pt":1631554567633,"mc":[{"id":"1.187566733","rc":[{"trd":[[1.75,75.52]],"batb":[[0,1.74,118.64],[1,1.72,116.21],[2,1.7,80.35]],"batl":[[0,1.75,111.42],[1,1.77,7.79],[2,1.78,61.81]],"ltp":1.75,"tv":9825.93,"id":8734382}],"tv":35739.12}]}
{"op":"mcm","clk":"4216703434","pt":1631554570856,"mc":[{"id":"1.187566733","rc":[{"batb":[[0,1.74,159.01]],"batl":[[1,1.76,39.91],[2,1.77,7.79]],"ltp":1.75,"tv":9825.93,"id":8734382}]}]}
{"op":"mcm","clk":"4216703512","pt":1631554571550,"mc":[{"id":"1.187566733","rc":[{"trd":[[1.75,79.52]],"batl":[[0,1.75,109.42],[2,1.77,39.29]],"ltp":1.75,"tv":9829.93,"id":8734382}],"tv":35743.12}]}
{"op":"mcm","clk":"4216703687","pt":1631554573144,"mc":[{"id":"1.187566733","rc":[{"batb":[[1,1.73,40.6],[2,1.72,116.21]],"ltp":1.75,"tv":9829.93,"id":8734382}]}]}
{"op":"mcm","clk":"4216704008","pt":1631554575771,"mc":[{"id":"1.187566733","rc":[{"trd":[[1.75,90.13]],"batl":[[0,1.75,98.82]],"ltp":1.75,"tv":9840.54,"id":8734382},{"trd":[[2.32,50.72]],"ltp":2.32,"tv":25921.18,"id":9323645}],"tv":35761.73}]}
{"op":"mcm","clk":"4216704086","pt":1631554576666,"mc":[{"id":"1.187566733","rc":[{"batl":[[0,1.76,39.91],[1,1.77,39.29],[2,1.78,61.81]],"ltp":1.75,"tv":9840.54,"id":8734382}]}]}
{"op":"mcm","clk":"4216704453","pt":1631554580155,"mc":[{"id":"1.187566733","rc":[{"trd":[[1.74,241.55]],"batb":[[0,1.74,52.1],[2,1.7,80.35]],"ltp":1.74,"tv":10038.18,"id":8734382}],"tv":35959.37}]}
{"op":"mcm","clk":"4216704806","pt":1631554583150,"mc":[{"id":"1.187566733","rc":[{"batb":[[0,1.73,112.32],[1,1.71,118.89],[2,1.7,38.6]],"batl":[[1,1.77,7.79],[2,1.78,30.75]],"ltp":1.74,"tv":10038.18,"id":8734382},{"batb":[[0,2.22,31],[1,2.14,36],[2,2.08,39.19]],"batl":[[0,2.58,5.94],[1,2.68,4.64],[2,2.9,5.05]],"ltp":2.32,"tv":25921.18,"id":9323645}]}]}
{"op":"mcm","clk":"4216704844","pt":1631554583473,"mc":[{"id":"1.187566733","rc":[{"batb":[[0,1.62,45.4],[1,1.6,36.09],[2,1.3,199.49]],"batl":[[0,1.78,30.75],[1,1.77,0],[2,1.78,0]],"ltp":1.74,"tv":10038.18,"id":8734382},{"batb":[[1,2.08,39.19],[2,1.5,107.72]],"batl":[[0,2.68,4.64],[1,2.68,0],[2,2.9,0]],"ltp":2.32,"tv":25921.18,"id":9323645}]}]}
{"op":"mcm","clk":"4216705119","pt":1631554586144,"mc":[{"id":"1.187566733","rc":[{"batb":[[0,1.71,36.8],[1,1.65,125.8],[2,1.64,69.05]],"batl":[[1,1.85,72.33],[2,1.87,89.88]],"ltp":1.74,"tv":10038.18,"id":8734382}]}]}
{"op":"mcm","clk":"4216705203","pt":1631554586976,"mc":[{"id":"1.187566733","rc":[{"batb":[[0,1.62,45.4],[1,1.6,36.09],[2,1.3,199.49]],"batl":[[1,1.85,0],[2,1.87,0]],"ltp":1.74,"tv":10038.18,"id":8734382},{"batb":[[0,2.28,6.16],[1,2.22,31],[2,2.08,39.19]],"ltp":2.32,"tv":25921.18,"id":9323645}]}]}
{"op":"mcm","clk":"4216705426","pt":1631554589180,"mc":[{"id":"1.187566733","rc":[{"batb":[[0,1.73,38.13],[1,1.72,76.05],[2,1.7,121.01]],"batl":[[0,1.76,40.52],[1,1.77,67.48],[2,1.78,30.75]],"ltp":1.74,"tv":10038.18,"id":8734382},{"batl":[[0,2.36,40.57],[1,2.68,4.64]],"ltp":2.32,"tv":25921.18,"id":9323645}]}]}
{"op":"mcm","clk":"4216705532","pt":1631554590180,"mc":[{"id":"1.187566733","rc":[{"batb":[[0,1.62,45.4],[1,1.6,36.09],[2,1.3,199.49]],"batl":[[0,1.78,30.75],[1,1.77,0],[2,1.78,0]],"ltp":1.74,"tv":10038.18,"id":8734382},{"batl":[[0,2.68,4.64],[1,2.68,0]],"ltp":2.32,"tv":25921.18,"id":9323645}]}]}
{"op":"mcm","clk":"4216705865","pt":1631554593168,"mc":[{"id":"1.187566733","rc":[{"batb":[[0,1.65,125.8],[1,1.64,69.05],[2,1.62,45.4]],"batl":[[1,1.85,72.33],[2,1.87,89.88]],"ltp":1.74,"tv":10038.18,"id":8734382}]}]}
{"op":"mcm","clk":"4216705947","pt":1631554593851,"mc":[{"id":"1.187566733","rc":[{"batb":[[1,1.64,106.62]],"ltp":1.74,"tv":10038.18,"id":8734382},{"batl":[[0,2.58,5.94],[1,2.68,4.64]],"ltp":2.32,"tv":25921.18,"id":9323645}]}]}
{"op":"mcm","clk":"4216706258","pt":1631554596987,"mc":[{"id":"1.187566733","rc":[{"batl":[[0,1.77,29.5],[1,1.78,30.75],[2,1.85,72.33]],"ltp":1.74,"tv":10038.18,"id":8734382}]}]}
{"op":"mcm","clk":"4216706287","pt":1631554597255,"mc":[{"id":"1.187566733","rc":[{"batl":[[0,1.78,30.75],[1,1.85,72.33],[2,1.87,89.88]],"ltp":1.74,"tv":10038.18,"id":8734382}]}]}
{"op":"mcm","clk":"4216706650","pt":1631554600753,"mc":[{"id":"1.187566733","rc":[{"batb":[[0,1.65,126.19]],"ltp":1.74,"tv":10038.18,"id":8734382}]}]}
{"op":"mcm","clk":"4216706993","pt":1631554604079,"mc":[{"id":"1.187566733","rc":[{"batl":[[0,1.77,30.5],[1,1.78,30.75],[2,1.85,72.33]],"ltp":1.74,"tv":10038.18,"id":8734382}]}]}
{"op":"mcm","clk":"4216707048","pt":1631554604603,"mc":[{"id":"1.187566733","rc":[{"batl":[[0,1.78,30.75],[1,1.85,72.33],[2,1.87,89.88]],"ltp":1.74,"tv":10038.18,"id":8734382}]}]}
{"op":"mcm","clk":"4216707133","pt":1631554605296,"mc":[{"id":"1.187566733","rc":[{"trd":[[1.78,288.48]],"batl":[[0,1.78,4.41]],"ltp":1.78,"tv":10064.52,"id":8734382},{"trd":[[2.28,47.87]],"batb":[[0,2.22,31],[1,2.08,39.19],[2,1.5,107.72]],"ltp":2.28,"tv":25954.06,"id":9323645}],"tv":36018.59}]}
{"op":"mcm","clk":"4216707501","pt":1631554608468,"mc":[{"id":"1.187566733","rc":[{"batb":[[0,2.28,6.66],[1,2.22,31],[2,2.08,39.19]],"ltp":2.28,"tv":25954.06,"id":9323645}]}]}
{"op":"mcm","clk":"4216707644","pt":1631554609688,"mc":[{"id":"1.187566733","rc":[{"batl":[[1,1.85,0],[2,1.87,0]],"ltp":1.78,"tv":10064.52,"id":8734382}]}]}
{"op":"mcm","clk":"4216707898","pt":1631554611865,"mc":[{"id":"1.187566733","rc":[{"trd":[[1.78,288.5]],"batl":[[0,1.78,4.4]],"ltp":1.78,"tv":10064.54,"id":8734382}],"tv":36018.61}]}
{"op":"mcm","clk":"4216707972","pt":1631554612710,"mc":[{"id":"1.187566733","rc":[{"batb":[[0,1.68,9.39],[1,1.66,374.53],[2,1.65,125.8]],"batl":[[0,1.71,130.86],[1,1.72,8.78],[2,1.73,123.28]],"ltp":1.78,"tv":10064.54,"id":8734382},{"batb":[[0,2.42,6.27],[1,2.36,85.16],[2,2.28,6.66]],"ltp":2.28,"tv":25954.06,"id":9323645}]}]}
{"op":"mcm","clk":"4216708099","pt":1631554613895,"mc":[{"id":"1.187566733","rc":[{"trd":[[2.42,8.26]],"batb":[[0,2.42,2.14],[2,2.28,36.7]],"batl":[[0,2.58,17.56],[1,2.6,5.82],[2,2.62,5.82]],"ltp":2.42,"tv":25962.32,"id":9323645}],"tv":36026.87}]}
{"op":"mcm","clk":"4216708500","pt":1631554617682,"mc":[{"id":"1.187566733","rc":[{"batb":[[0,1.68,97.39]],"ltp":1.78,"tv":10064.54,"id":8734382}]}]}
{"op":"mcm","clk":"4216708746","pt":1631554620017,"mc":[{"id":"1.187566733","rc":[{"batl":[[1,1.72,41.19],[2,1.73,153.78]],"ltp":1.78,"tv":10064.54,"id":8734382},{"batb":[[1,2.38,5.96],[2,2.36,91.59]],"batl":[[2,2.62,10.28]],"ltp":2.42,"tv":25962.32,"id":9323645}]}]}
{"op":"mcm","clk":"4216708824","pt":1631554620606,"mc":[{"id":"1.187566733","rc":[{"batb":[[0,1.68,134.61]],"batl":[[0,1.71,167.42]],"ltp":1.78,"tv":10064.54,"id":8734382}]}]}
{"op":"mcm","clk":"4216709004","pt":1631554622278,"mc":[{"id":"1.187566733","rc":[{"batb":[[0,1.68,134.22]],"ltp":1.78,"tv":10064.54,"id":8734382}]}]}
{"op":"mcm","clk":"4216709133","pt":1631554623692,"mc":[{"id":"1.187566733","rc":[{"batb":[[0,1.68,125.22]],"ltp":1.78,"tv":10064.54,"id":8734382},{"batb":[[0,2.38,5.96],[1,2.36,91.59],[2,2.28,36.7]],"ltp":2.42,"tv":25962.32,"id":9323645}]}]}
{"op":"mcm","clk":"4216709339","pt":1631554625480,"mc":[{"id":"1.187566733","rc":[{"trd":[[1.71,187.64]],"batl":[[0,1.71,167.03]],"ltp":1.71,"tv":10065.32,"id":8734382}],"tv":36027.64}]}
{"op":"mcm","clk":"4216709463","pt":1631554626618,"mc":[{"id":"1.187566733","rc":[{"batb":[[0,2.4,7.25],[1,2.38,5.96],[2,2.36,91.59]],"batl":[[0,2.46,7.66],[1,2.58,17.56],[2,2.6,5.82]],"ltp":2.42,"tv":25962.32,"id":9323645}]}]}
{"op":"mcm","clk":"4216709789","pt":1631554629895,"mc":[{"id":"1.187566733","rc":[{"trd":[[1.68,2.78]],"batb":[[0,1.68,123.83]],"ltp":1.68,"tv":10068.09,"id":8734382}],"tv":36030.42}]}
{"op":"mcm","clk":"4216709903","pt":1631554631001,"mc":[{"id":"1.187566733","rc":[{"trd":[[1.68,7.9]],"batb":[[0,1.68,121.27]],"ltp":1.68,"tv":10073.21,"id":8734382}],"tv":36035.54}]}
{"op":"mcm","clk":"4216710566","pt":1631554638095,"mc":[{"id":"1.187566733","rc":[{"batb":[[0,1.68,84.05],[1,1.59,43.11],[2,1.55,53.46]],"batl":[[0,1.74,39.25],[1,1.72,0],[2,1.73,0]],"ltp":1.68,"tv":10073.21,"id":8734382},{"batb":[[0,2.34,6.22],[1,2.22,31],[2,2.18,34.16]],"batl":[[0,2.44,4.8],[1,2.7,5.05],[2,2.6,0]],"ltp":2.42,"tv":25962.32,"id":9323645}]}]}
{"op":"mcm","clk":"4216710603","pt":1631554638513,"mc":[{"id":"1.187566733","rc":[{"batb":[[0,1.59,43.11],[1,1.55,53.46],[2,1.3,199.49]],"ltp":1.68,"tv":10073.21,"id":8734382}]}]}
{"op":"mcm","clk":"4216710830","pt":1631554641001,"mc":[{"id":"1.187566733","rc":[{"trd":[[1.69,5.16]],"ltp":1.69,"tv":10078.37,"id":8734382},{"trd":[[2.44,3.57]],"batl":[[0,2.44,1.23]],"ltp":2.44,"tv":25965.89,"id":9323645}],"tv":36044.26}]}
{"op":"mcm","clk":"4216711253","pt":1631554644906,"mc":[{"id":"1.187566733","rc":[{"trd":[[1.69,6.94]],"batb":[[0,1.64,78.75],[1,1.63,70.34],[2,1.59,43.11]],"batl":[[0,1.69,102.91],[1,1.71,119.02],[2,1.73,34.5]],"ltp":1.69,"tv":10080.15,"id":8734382},{"trd":[[2.44,4.8]],"batb":[[0,2.36,6.43],[1,2.34,6.22],[2,2.22,31]],"batl":[[0,2.7,5.05],[1,2.7,0]],"ltp":2.44,"tv":25967.12,"id":9323645}],"tv":36047.27}]}
{"op":"mcm","clk":"4216711350","pt":1631554646011,"mc":[{"id":"1.187566733","rc":[{"batb":[[0,1.59,43.11],[1,1.55,53.46],[2,1.3,199.49]],"batl":[[0,1.73,34.5],[1,1.74,39.25],[2,1.73,0]],"ltp":1.69,"tv":10080.15,"id":8734382}]}]}
{"op":"mcm","clk":"4216711384","pt":1631554646332,"mc":[{"id":"1.187566733","rc":[{"batl":[[0,1.74,39.25],[1,1.74,0]],"ltp":1.69,"tv":10080.15,"id":8734382},{"batb":[[0,2.34,6.22],[1,2.22,31],[2,2.18,34.16]],"ltp":2.44,"tv":25967.12,"id":9323645}]}]}
{"op":"mcm","clk":"4216711577","pt":1631554648123,"mc":[{"id":"1.187566733","rc":[{"batb":[[0,1.62,37.54],[1,1.59,43.11],[2,1.55,53.46]],"batl":[[0,1.69,1.39],[1,1.74,39.25]],"ltp":1.69,"tv":10080.15,"id":8734382},{"batl":[[0,2.62,5.96],[1,2.7,5.05]],"ltp":2.44,"tv":25967.12,"id":9323645}]}]}
{"op":"mcm","clk":"4216711662","pt":1631554648913,"mc":[{"id":"1.187566733","rc":[{"batb":[[0,1.59,43.11],[1,1.57,118.57],[2,1.56,82.74]],"batl":[[2,1.77,75.55]],"ltp":1.69,"tv":10080.15,"id":8734382},{"batl":[[0,2.7,5.05],[1,2.7,0]],"ltp":2.44,"tv":25967.12,"id":9323645}]}]}
{"op":"mcm","clk":"4216712418","pt":1631554656065,"mc":[{"id":"1.187566733","rc":[{"batb":[[1,1.55,53.46],[2,1.3,199.49]],"ltp":1.69,"tv":10080.15,"id":8734382}]}]}
{"op":"mcm","clk":"4216712736","pt":1631554659054,"mc":[{"id":"1.187566733","rc":[{"trd":[[1.69,8.32]],"batb":[[0,1.72,86.09],[1,1.7,120.91],[2,1.69,16.21]],"batl":[[0,1.74,39.25],[1,1.76,8.52]],"ltp":1.69,"tv":10081.53,"id":8734382},{"trd":[[2.34,15.55],[2.44,5.76]],"batb":[[0,2.34,1.95]],"batl":[[0,2.4,12.5],[1,2.42,6.24],[2,2.44,6.24]],"ltp":2.34,"tv":25976.62,"id":9323645}],"tv":36058.16}]}
{"op":"mcm","clk":"4216712842","pt":1631554660058,"mc":[{"id":"1.187566733","rc":[{"trd":[[1.74,265.82]],"batl":[[0,1.74,14.98]],"ltp":1.74,"tv":10105.8,"id":8734382},{"trd":[[2.34,37.5]],"batb":[[0,2.26,13.28],[1,2.24,6.64],[2,2.22,37.64]],"ltp":2.34,"tv":25998.57,"id":9323645}],"tv":36104.38}]}
{"op":"mcm","clk":"4216713041","pt":1631554661825,"mc":[{"id":"1.187566733","rc":[{"trd":[[1.72,45.68]],"batb":[[0,1.72,67.56]],"ltp":1.72,"tv":10142.86,"id":8734382}],"tv":36141.44}]}
{"op":"mcm","clk":"4216713191","pt":1631554663033,"mc":[{"id":"1.187566733","rc":[{"batb":[[0,1.72,114.45]],"batl":[[1,1.75,46.08],[2,1.76,8.52]],"ltp":1.72,"tv":10142.86,"id":8734382}]}]}
{"op":"mcm","clk":"4216713411","pt":1631554664924,"mc":[{"id":"1.187566733","rc":[{"batl":[[0,1.74,59.11]],"ltp":1.72,"tv":10142.86,"id":8734382}]}]}
{"op":"mcm","clk":"4216713720","pt":1631554668029,"mc":[{"id":"1.187566733","rc":[{"trd":[[1.72,160.13]],"batb":[[0,1.7,120.91],[1,1.69,16.21],[2,1.67,40.53]],"ltp":1.72,"tv":10257.31,"id":8734382},{"trd":[[2.4,117.91]],"batb":[[0,2.4,284.39],[1,2.26,13.28],[2,2.24,6.64]],"batl":[[0,2.42,6.24],[1,2.44,6.24],[2,2.46,469.3]],"ltp":2.4,"tv":26105.59,"id":9323645}],"tv":36362.9}]}
{"op":"mcm","clk":"4216713767","pt":1631554668451,"mc":[{"id":"1.187566733","rc":[{"batb":[[0,1.69,16.21],[1,1.67,40.53],[2,1.66,157.36]],"ltp":1.72,"tv":10257.31,"id":8734382}]}]}
{"op":"mcm","clk":"4216714062","pt":1631554671158,"mc":[{"id":"1.187566733","rc":[{"batb":[[0,1.71,39.95],[1,1.69,16.21],[2,1.67,40.53]],"ltp":1.72,"tv":10257.31,"id":8734382}]}]}
{"op":"mcm","clk":"4216714162","pt":1631554672035,"mc":[{"id":"1.187566733","rc":[{"batb":[[0,1.71,129.93],[1,1.7,125.48],[2,1.69,139.99]],"batl":[[0,1.73,38.86],[1,1.74,59.11],[2,1.75,46.08]],"ltp":1.72,"tv":10257.31,"id":8734382}]}]}
{"op":"mcm","clk":"4216714457","pt":1631554674946,"mc":[{"id":"1.187566733","rc":[{"batb":[[1,2.36,7.75],[2,2.26,13.28]],"batl":[[0,2.42,14.23]],"ltp":2.4,"tv":26105.59,"id":9323645}]}]}
{"op":"mcm","clk":"4216714700","pt":1631554677168,"mc":[{"id":"1.187566733","rc":[{"batb":[[0,1.7,111],[1,1.65,40.33],[2,1.63,34.23]],"ltp":1.72,"tv":10257.31,"id":8734382},{"batb":[[1,2.22,31],[2,2.1,38.18]],"batl":[[0,2.54,5.25],[1,2.6,5.51],[2,2.62,5.25]],"ltp":2.4,"tv":26105.59,"id":9323645}]}]}
{"op":"mcm","clk":"4216714758","pt":1631554677849,"mc":[{"id":"1.187566733","rc":[{"batb":[[0,1.63,34.23],[1,1.6,47.5],[2,1.3,199.49]],"ltp":1.72,"tv":10257.31,"id":8734382},{"batl":[[0,2.6,5.51],[1,2.6,0],[2,2.62,0]],"ltp":2.4,"tv":26105.59,"id":9323645}]}]}
{"op":"mcm","clk":"4216714980","pt":1631554680064,"mc":[{"id":"1.187566733","rc":[{"batb":[[1,1.62,123.52],[2,1.61,73.9]],"batl":[[0,1.83,71.05],[1,1.85,93.04]],"ltp":1.72,"tv":10257.31,"id":8734382}]}]}
{"op":"mcm","clk":"4216715095","pt":1631554681068,"mc":[{"id":"1.187566733","rc":[{"batb":[[0,1.65,39.33],[1,1.63,34.23],[2,1.6,47.5]],"ltp":1.72,"tv":10257.31,"id":8734382},{"batl":[[0,2.54,5.75],[1,2.6,5.51]],"ltp":2.4,"tv":26105.59,"id":9323645}]}]}
{"op":"mcm","clk":"4216715128","pt":1631554681339,"mc":[{"id":"1.187566733","rc":[{"batb":[[0,1.63,34.23],[1,1.6,47.5],[2,1.3,199.49]],"ltp":1.72,"tv":10257.31,"id":8734382},{"batl":[[0,2.6,5.51],[1,2.6,0]],"ltp":2.4,"tv":26105.59,"id":9323645}]}]}
{"op":"mcm","clk":"4216715387","pt":1631554684072,"mc":[{"id":"1.187566733","rc":[{"batb":[[0,1.69,104.82],[1,1.68,63.57],[2,1.63,34.23]],"batl":[[0,1.75,109.15],[1,1.77,106.64]],"ltp":1.72,"tv":10257.31,"id":8734382}]}]}
{"op":"mcm","clk":"4216715448","pt":1631554684660,"mc":[{"id":"1.187566733","rc":[{"batb":[[2,1.65,31.93]],"ltp":1.72,"tv":10257.31,"id":8734382},{"batl":[[0,2.54,5.38],[1,2.6,5.51]],"ltp":2.4,"tv":26105.59,"id":9323645}]}]}
{"op":"mcm","clk":"4216715774","pt":1631554687986,"mc":[{"id":"1.187566733","rc":[{"batb":[[0,1.63,34.23],[1,1.6,47.5],[2,1.3,199.49]],"ltp":1.72,"tv":10257.31,"id":8734382},{"batl":[[0,2.6,5.51],[1,2.6,0]],"ltp":2.4,"tv":26105.59,"id":9323645}]}]}
{"op":"mcm","clk":"4216716072","pt":1631554691180,"mc":[{"id":"1.187566733","rc":[{"batb":[[0,1.65,39.53],[1,1.63,34.23],[2,1.62,123.52]],"batl":[[0,1.83,71.05],[1,1.85,93.04]],"ltp":1.72,"tv":10257.31,"id":8734382},{"batl":[[0,2.54,5.75],[1,2.6,5.51]],"ltp":2.4,"tv":26105.59,"id":9323645}]}]}
{"op":"mcm","clk":"4216716175","pt":1631554692192,"mc":[{"id":"1.187566733","rc":[{"batb":[[0,1.63,34.23],[1,1.62,123.52],[2,1.61,73.9]],"ltp":1.72,"tv":10257.31,"id":8734382},{"batl":[[0,2.6,5.51],[1,2.6,0]],"ltp":2.4,"tv":26105.59,"id":9323645}]}]}
{"op":"mcm","clk":"4216716486","pt":1631554695207,"mc":[{"id":"1.187566733","rc":[{"batl":[[0,1.67,74.69],[1,1.68,63.07],[2,1.74,659.73]],"ltp":1.72,"tv":10257.31,"id":8734382},{"batb":[[0,2.5,68.77],[1,2.48,30],[2,2.46,30]],"batl":[[0,2.6,364.72]],"ltp":2.4,"tv":26105.59,"id":9323645}]}]}
{"op":"mcm","clk":"4216716586","pt":1631554696175,"mc":[{"id":"1.187566733","rc":[{"trd":[[2.5,39.16]],"batb":[[0,2.5,16.74],[1,2.48,6],[2,2.46,6]],"batl":[[1,2.68,11.2],[2,2.7,16.79]],"ltp":2.5,"tv":26113.65,"id":9323645}],"tv":36370.96}]}
{"op":"mcm","clk":"4216716619","pt":1631554696480,"mc":[{"id":"1.187566733","rc":[{"batl":[[2,2.7,5.6]],"ltp":2.5,"tv":26113.65,"id":9323645}]}]}
{"op":"mcm","clk":"4216717910","pt":1631554708991,"mc":[{"id":"1.187566733","rc":[{"trd":[[1.63,199.5]],"batb":[[0,1.63,29.96]],"ltp":1.63,"tv":10265.85,"id":8734382}],"tv":36379.5}]}
{"op":"mcm","clk":"4216718218","pt":1631554712201,"mc":[{"id":"1.187566733","rc":[{"batl":[[2,1.69,32.11]],"ltp":1.63,"tv":10265.85,"id":8734382}]}]}
{"op":"mcm","clk":"4216719086","pt":1631554720726,"mc":[{"id":"1.187566733","rc":[{"trd":[[1.63,204.62]],"batb":[[0,1.63,27.4]],"ltp":1.63,"tv":10270.97,"id":8734382}],"tv":36384.62}]}
{"op":"mcm","clk":"4216719247","pt":1631554722109,"mc":[{"id":"1.187566733","rc":[{"batb":[[0,1.55,44.99],[1,1.52,57.9],[2,1.3,199.49]],"batl":[[0,1.72,35.66],[1,1.75,37.98],[2,1.69,0]],"ltp":1.63,"tv":10270.97,"id":8734382},{"batb":[[0,2.4,284.39],[1,2.38,5.46],[2,2.32,5.64]],"batl":[[0,2.82,4.75],[1,2.68,0],[2,2.7,0]],"ltp":2.5,"tv":26113.65,"id":9323645}]}]}
{"op":"mcm","clk":"4216719461","pt":1631554724111,"mc":[{"id":"1.187566733","rc":[{"batb":[[0,1.63,80],[1,1.55,44.99],[2,1.52,57.9]],"ltp":1.63,"tv":10270.97,"id":8734382}]}]}
{"op":"mcm","clk":"4216719562","pt":1631554725008,"mc":[{"id":"1.187566733","rc":[{"batb":[[0,1.55,44.99],[1,1.53,129.21],[2,1.52,149.6]],"batl":[[0,1.71,30.03],[1,1.72,35.66],[2,1.75,143.14]],"ltp":1.63,"tv":10270.97,"id":8734382}]}]}
{"op":"mcm","clk":"4216719634","pt":1631554725626,"mc":[{"id":"1.187566733","rc":[{"batb":[[1,1.52,57.9],[2,1.3,199.49]],"batl":[[0,1.72,35.66],[1,1.75,37.98],[2,1.75,0]],"ltp":1.63,"tv":10270.97,"id":8734382}]}]}
{"op":"mcm","clk":"4216719887","pt":1631554728118,"mc":[{"id":"1.187566733","rc":[{"trd":[[1.66,17.3]],"ltp":1.66,"tv":10286.03,"id":8734382},{"trd":[[2.5,49.16]],"ltp":2.5,"tv":26123.65,"id":9323645}],"tv":36409.68}]}
{"op":"mcm","clk":"4216719957","pt":1631554728801,"mc":[{"id":"1.187566733","rc":[{"batb":[[0,1.6,135.06],[1,1.59,77.39],[2,1.58,45.06]],"batl":[[0,1.65,76.61],[1,1.66,65.67],[2,1.72,35.66]],"ltp":1.66,"tv":10286.03,"id":8734382},{"batl":[[0,2.74,5.25],[1,2.82,4.75]],"ltp":2.5,"tv":26123.65,"id":9323645}]}]}
{"op":"mcm","clk":"4216720098","pt":1631554730112,"mc":[{"id":"1.187566733","rc":[{"batb":[[0,1.55,44.99],[1,1.52,57.9],[2,1.3,199.49]],"batl":[[0,1.72,35.66],[1,1.75,37.98],[2,1.72,0]],"ltp":1.66,"tv":10286.03,"id":8734382},{"batl":[[0,2.82,4.75],[1,2.82,0]],"ltp":2.5,"tv":26123.65,"id":9323645}]}]}
{"op":"mcm","clk":"4216720378","pt":1631554732910,"mc":[{"id":"1.187566733","rc":[{"batb":[[1,1.53,129.21],[2,1.52,149.6]],"batl":[[1,1.75,143.14],[2,1.77,106.64]],"ltp":1.66,"tv":10286.03,"id":8734382}]}]}
{"op":"mcm","clk":"4216720620","pt":1631554735425,"mc":[{"id":"1.187566733","rc":[{"batl":[[0,1.75,143.14],[1,1.77,106.64],[2,1.77,0]],"ltp":1.66,"tv":10286.03,"id":8734382},{"batb":[[1,2.32,5.64],[2,2.22,64.06]],"ltp":2.5,"tv":26123.65,"id":9323645}]}]}
{"op":"mcm","clk":"4216720769","pt":1631554737027,"mc":[{"id":"1.187566733","rc":[{"batb":[[0,1.58,43.56],[1,1.55,44.99],[2,1.53,129.21]],"ltp":1.66,"tv":10286.03,"id":8734382},{"batl":[[0,2.74,4.98],[1,2.82,4.75]],"ltp":2.5,"tv":26123.65,"id":9323645}]}]}
{"op":"mcm","clk":"4216720791","pt":1631554737225,"mc":[{"id":"1.187566733","rc":[{"batb":[[0,1.55,44.99],[1,1.53,129.21],[2,1.52,149.6]],"ltp":1.66,"tv":10286.03,"id":8734382},{"batl":[[0,2.82,4.75],[1,2.82,0]],"ltp":2.5,"tv":26123.65,"id":9323645}]}]}
{"op":"mcm","clk":"4216720925","pt":1631554738617,"mc":[{"id":"1.187566733","rc":[{"batl":[[0,1.72,34.91],[1,1.75,143.14],[2,1.77,106.64]],"ltp":1.66,"tv":10286.03,"id":8734382},{"batb":[[1,2.38,5.96],[2,2.32,5.64]],"ltp":2.5,"tv":26123.65,"id":9323645}]}]}
{"op":"mcm","clk":"4216721498","pt":1631554744032,"mc":[{"id":"1.187566733","rc":[{"batb":[[0,1.58,46.56],[1,1.55,44.99],[2,1.53,129.21]],"ltp":1.66,"tv":10286.03,"id":8734382},{"batl":[[0,2.74,5.25],[1,2.82,4.75]],"ltp":2.5,"tv":26123.65,"id":9323645}]}]}
{"op":"mcm","clk":"4216721522","pt":1631554744240,"mc":[{"id":"1.187566733","rc":[{"batb":[[0,1.55,44.99],[1,1.53,129.21],[2,1.52,149.6]],"ltp":1.66,"tv":10286.03,"id":8734382},{"batl":[[0,2.82,4.75],[1,2.82,0]],"ltp":2.5,"tv":26123.65,"id":9323645}]}]}
{"op":"mcm","clk":"4216722284","pt":1631554750959,"mc":[{"id":"1.187566733","rc":[{"batb":[[0,1.58,42.06],[1,1.55,44.99],[2,1.53,129.21]],"ltp":1.66,"tv":10286.03,"id":8734382},{"batl":[[0,2.74,4.98],[1,2.82,4.75]],"ltp":2.5,"tv":26123.65,"id":9323645}]}]}
{"op":"mcm","clk":"4216722320","pt":1631554751262,"mc":[{"id":"1.187566733","rc":[{"batb":[[0,1.55,44.99],[1,1.53,129.21],[2,1.52,149.6]],"ltp":1.66,"tv":10286.03,"id":8734382},{"batl":[[0,2.82,4.75],[1,2.82,0]],"ltp":2.5,"tv":26123.65,"id":9323645}]}]}
{"op":"mcm","clk":"4216722590","pt":1631554753571,"mc":[{"id":"1.187566733","rc":[{"batb":[[1,2.32,5.64],[2,2.22,64.06]],"ltp":2.5,"tv":26123.65,"id":9323645}]}]}
{"op":"mcm","clk":"4216722897","pt":1631554756159,"mc":[{"id":"1.187566733","rc":[{"trd":[[1.55,244.94]],"batb":[[0,1.56,384.14],[1,1.55,42.17],[2,1.53,129.21]],"batl":[[0,1.59,94.34],[1,1.6,71.29],[2,1.61,1983.5]],"ltp":1.55,"tv":10288.85,"id":8734382},{"trd":[[2.82,11.05]],"batb":[[0,2.76,72.46],[1,2.4,284.39],[2,2.32,5.64]],"batl":[[0,2.78,6.56]],"ltp":2.82,"tv":26134.7,"id":9323645}],"tv":36423.55}]}
{"op":"mcm","clk":"4216723002","pt":1631554757154,"mc":[{"id":"1.187566733","rc":[{"batb":[[2,1.53,227.25]],"batl":[[0,1.58,135.85],[1,1.59,132.62],[2,1.6,52.42]],"ltp":1.55,"tv":10288.85,"id":8734382},{"trd":[[2.76,7.52]],"batb":[[0,2.76,39.72],[1,2.52,22.66],[2,2.4,284.39]],"ltp":2.76,"tv":26142.22,"id":9323645}],"tv":36431.07}]}
{"op":"mcm","clk":"4216723041","pt":1631554757468,"mc":[{"id":"1.187566733","rc":[{"batb":[[2,1.53,148.81]],"batl":[[1,1.59,94.88],[2,1.6,33.55]],"ltp":1.55,"tv":10288.85,"id":8734382}]}]}
{"op":"mcm","clk":"4216723453","pt":1631554761162,"mc":[{"id":"1.187566733","rc":[{"batl":[[2,1.6,65.46]],"ltp":1.55,"tv":10288.85,"id":8734382},{"trd":[[2.76,12.1]],"batb":[[0,2.76,37.43]],"ltp":2.76,"tv":26146.8,"id":9323645}],"tv":36435.65}]}
{"op":"mcm","clk":"4216723716","pt":1631554763866,"mc":[{"id":"1.187566733","rc":[{"batb":[[0,1.56,523.14]],"ltp":1.55,"tv":10288.85,"id":8734382},{"batb":[[2,2.5,5.8]],"batl":[[1,3,3.95],[2,3.1,4.05]],"ltp":2.76,"tv":26146.8,"id":9323645}]}]}
{"op":"mcm","clk":"4216723773","pt":1631554764351,"mc":[{"id":"1.187566733","rc":[{"batl":[[1,1.59,126.99]],"ltp":1.55,"tv":10288.85,"id":8734382}]}]}
{"op":"mcm","clk":"4216724042","pt":1631554767075,"mc":[{"id":"1.187566733","rc":[{"batb":[[1,1.55,74.52]],"ltp":1.55,"tv":10288.85,"id":8734382}]}]}
{"op":"mcm","clk":"4216724384","pt":1631554770280,"mc":[{"id":"1.187566733","rc":[{"trd":[[2.78,55.64]],"batl":[[0,2.78,4.56]],"ltp":2.78,"tv":26150.8,"id":9323645}],"tv":36439.65}]}
{"op":"mcm","clk":"4216724731","pt":1631554773662,"mc":[{"id":"1.187566733","rc":[{"trd":[[1.56,153.25]],"batb":[[0,1.56,520.58]],"ltp":1.56,"tv":10293.97,"id":8734382}],"tv":36444.77}]}
{"op":"mcm","clk":"4216725390","pt":1631554780101,"mc":[{"id":"1.187566733","rc":[{"trd":[[1.57,90.99]],"batb":[[0,1.57,9.05],[1,1.56,520.58],[2,1.55,74.52]],"ltp":1.57,"tv":10359.77,"id":8734382},{"trd":[[2.76,49.53]],"batb":[[0,2.52,22.66],[1,2.5,5.8],[2,2.44,6.17]],"ltp":2.76,"tv":26188.23,"id":9323645}],"tv":36548.0}]}
{"op":"mcm","clk":"4216725501","pt":1631554781066,"mc":[{"id":"1.187566733","rc":[{"batb":[[1,1.56,139],[2,1.5,45.86]],"batl":[[0,1.69,36.5],[1,1.59,0],[2,1.6,0]],"ltp":1.57,"tv":10359.77,"id":8734382},{"batb":[[0,2.44,6.17],[1,2.4,284.39],[2,2.38,26.6]],"batl":[[0,3,3.95],[1,3.1,4.05],[2,3.1,0]],"ltp":2.76,"tv":26188.23,"id":9323645}]}]}
{"op":"mcm","clk":"4216725627","pt":1631554782171,"mc":[{"id":"1.187566733","rc":[{"batb":[[0,1.58,73.56],[1,1.57,9.05],[2,1.48,47.51]],"ltp":1.57,"tv":10359.77,"id":8734382},{"batl":[[0,3.1,4.05],[1,3.1,0]],"ltp":2.76,"tv":26188.23,"id":9323645}]}]}
{"op":"mcm","clk":"4216725683","pt":1631554782691,"mc":[{"id":"1.187566733","rc":[{"batb":[[0,1.48,47.51],[1,1.44,71.5],[2,1.3,199.49]],"ltp":1.57,"tv":10359.77,"id":8734382}]}]}
{"op":"mcm","clk":"4216725834","pt":1631554784201,"mc":[{"id":"1.187566733","rc":[{"batl":[[0,1.66,40.25],[1,1.69,36.5]],"ltp":1.57,"tv":10359.77,"id":8734382},{"batb":[[0,2.5,5.86],[1,2.44,6.17],[2,2.4,284.39]],"ltp":2.76,"tv":26188.23,"id":9323645}]}]}
{"op":"mcm","clk":"4216725947","pt":1631554785172,"mc":[{"id":"1.187566733","rc":[{"batb":[[1,1.45,165.95],[2,1.44,184.55]],"batl":[[0,1.64,102.64],[1,1.65,66.93],[2,1.69,36.5]],"ltp":1.57,"tv":10359.77,"id":8734382},{"batb":[[0,2.44,6.17],[1,2.4,284.39],[2,2.38,26.6]],"ltp":2.76,"tv":26188.23,"id":9323645}]}]}
{"op":"mcm","clk":"4216726001","pt":1631554785687,"mc":[{"id":"1.187566733","rc":[{"batb":[[1,1.44,71.5],[2,1.3,199.49]],"ltp":1.57,"tv":10359.77,"id":8734382}]}]}
{"op":"mcm","clk":"4216726255","pt":1631554787990,"mc":[{"id":"1.187566733","rc":[{"trd":[[1.64,13.07]],"batb":[[0,1.59,26.11],[1,1.57,128.02],[2,1.48,47.51]],"batl":[[0,1.64,116.58],[2,1.66,39.25]],"ltp":1.64,"tv":10365.92,"id":8734382},{"trd":[[2.56,12.38]],"batb":[[0,2.5,5.75],[1,2.44,6.17],[2,2.4,284.39]],"batl":[[0,2.66,7.37],[1,2.68,11.2],[2,2.7,10.65]],"ltp":2.56,"tv":26192.17,"id":9323645}],"tv":36558.09}]}
{"op":"mcm","clk":"4216726391","pt":1631554789111,"mc":[{"id":"1.187566733","rc":[{"batb":[[0,1.59,140.98],[1,1.58,79.12],[2,1.57,178.62]],"ltp":1.64,"tv":10365.92,"id":8734382},{"batb":[[0,2.5,17.75],[1,2.48,6],[2,2.46,6]],"ltp":2.56,"tv":26192.17,"id":9323645}]}]}
{"op":"mcm","clk":"4216726770","pt":1631554792198,"mc":[{"id":"1.187566733","rc":[{"batb":[[0,1.6,55.41],[1,1.59,140.98],[2,1.58,79.12]],"batl":[[0,1.63,69.53],[1,1.64,116.58],[2,1.65,66.93]],"ltp":1.64,"tv":10365.92,"id":8734382}]}]}
{"op":"mcm","clk":"4216727022","pt":1631554794592,"mc":[{"id":"1.187566733","rc":[{"batb":[[0,1.6,133.41]],"ltp":1.64,"tv":10365.92,"id":8734382}]}]}
{"op":"mcm","clk":"4216727381","pt":1631554797686,"mc":[{"id":"1.187566733","rc":[{"batl":[[1,1.64,179.99]],"ltp":1.64,"tv":10365.92,"id":8734382}]}]}
{"op":"mcm","clk":"4216727537","pt":1631554799210,"mc":[{"id":"1.187566733","rc":[{"batb":[[0,1.6,78],[1,1.57,50.6],[2,1.5,42.44]],"batl":[[0,1.73,33.5],[1,1.64,0],[2,1.65,0]],"ltp":1.64,"tv":10365.92,"id":8734382},{"batb":[[0,2.4,284.39],[1,2.38,26.6],[2,2.36,6.68]],"batl":[[0,3,4.08],[1,3.1,4.05],[2,3.15,3.7]],"ltp":2.56,"tv":26192.17,"id":9323645}]}]}
{"op":"mcm","clk":"4216727620","pt":1631554800017,"mc":[{"id":"1.187566733","rc":[{"batb":[[0,1.46,120.68],[1,1.3,199.49],[2,1.25,167.57]],"batl":[[0,1.73,33.89]],"ltp":1.64,"tv":10365.92,"id":8734382},{"batb":[[1,2.36,6.68],[2,2.22,63.64]],"batl":[[0,3.2,3.53],[1,3.1,0],[2,3.15,0]],"ltp":2.56,"tv":26192.17,"id":9323645}]}]}
{"op":"mcm","clk":"4216727885","pt":1631554802094,"mc":[{"id":"1.187566733","rc":[{"batb":[[0,1.47,155.4],[1,1.46,227.37],[2,1.3,199.49]],"batl":[[1,1.74,105.98],[2,1.76,108.52]],"ltp":1.64,"tv":10365.92,"id":8734382}]}]}
{"op":"mcm","clk":"4216728008","pt":1631554803206,"mc":[{"id":"1.187566733","rc":[{"batb":[[0,1.5,47.9],[1,1.47,155.4],[2,1.46,227.37]],"ltp":1.64,"tv":10365.92,"id":8734382},{"batl":[[0,3,4.53],[1,3.2,3.53]],"ltp":2.56,"tv":26192.17,"id":9323645}]}]}
{"op":"mcm","clk":"4216728087","pt":1631554803901,"mc":[{"id":"1.187566733","rc":[{"batb":[[0,1.46,120.68],[1,1.3,199.49],[2,1.25,167.57]],"ltp":1.64,"tv":10365.92,"id":8734382},{"batl":[[0,3.2,3.53],[1,3.2,0]],"ltp":2.56,"tv":26192.17,"id":9323645}]}]}
{"op":"mcm","clk":"4216728508","pt":1631554807104,"mc":[{"id":"1.187566733","rc":[{"trd":[[1.6,0.78]],"batb":[[0,1.68,247.35],[1,1.67,64.87],[2,1.66,25.88]],"batl":[[0,1.7,11.72],[1,1.73,33.5],[2,1.74,105.98]],"ltp":1.6,"tv":10366.7,"id":8734382},{"trd":[[2.4,126.26]],"batb":[[0,2.4,280.22],[2,2.32,246.36]],"batl":[[0,2.5,319.87],[1,2.52,5.51],[2,3,3.91]],"ltp":2.4,"tv":26200.51,"id":9323645}],"tv":36567.22}]}
{"op":"mcm","clk":"4216729008","pt":1631554811724,"mc":[{"id":"1.187566733","rc":[{"batb":[[0,1.68,345.35]],"ltp":1.6,"tv":10366.7,"id":8734382}]}]}
{"op":"mcm","clk":"4216729191","pt":1631554813612,"mc":[{"id":"1.187566733","rc":[{"batb":[[2,2.32,252.25]],"batl":[[2,2.68,5.14]],"ltp":2.4,"tv":26200.51,"id":9323645}]}]}
{"op":"mcm","clk":"4216729315","pt":1631554814716,"mc":[{"id":"1.187566733","rc":[{"batb":[[1,1.67,104.33]],"batl":[[1,1.71,56.69],[2,1.73,33.5]],"ltp":1.6,"tv":10366.7,"id":8734382}]}]}
{"op":"mcm","clk":"4216729533","pt":1631554816836,"mc":[{"id":"1.187566733","rc":[{"batb":[[0,1.68,384.58]],"ltp":1.6,"tv":10366.7,"id":8734382}]}]}
{"op":"mcm","clk":"4216729728","pt":1631554818636,"mc":[{"id":"1.187566733","rc":[{"batb":[[0,1.68,251.31]],"ltp":1.6,"tv":10366.7,"id":8734382}]}]}
{"op":"mcm","clk":"4216730051","pt":1631554821713,"mc":[{"id":"1.187566733","rc":[{"batb":[[0,2.36,6.68],[1,2.32,252.25],[2,2.3,59.12]],"ltp":2.4,"tv":26200.51,"id":9323645}]}]}
{"op":"mcm","clk":"4216730294","pt":1631554824150,"mc":[{"id":"1.187566733","rc":[{"batb":[[0,1.68,98],[1,1.6,40.24],[2,1.57,96.68]],"batl":[[0,1.73,33.5],[1,1.75,36.38],[2,1.73,0]],"ltp":1.6,"tv":10366.7,"id":8734382},{"batb":[[1,2.32,5.89],[2,2.22,31]],"batl":[[0,2.68,5.14],[1,2.76,4.77],[2,3,3.91]],"ltp":2.4,"tv":26200.51,"id":9323645}]}]}
{"op":"mcm","clk":"4216730375","pt":1631554824835,"mc":[{"id":"1.187566733","rc":[{"batb":[[0,1.57,96.68],[1,1.3,199.49],[2,1.25,167.57]],"batl":[[0,1.75,36.38],[1,1.75,0]],"ltp":1.6,"tv":10366.7,"id":8734382},{"batb":[[0,2.48,280.22]],"batl":[[0,2.76,4.77],[1,2.76,0],[2,3,0]],"ltp":2.4,"tv":26200.51,"id":9323645}]}]}
{"op":"mcm","clk":"4216730513","pt":1631554826162,"mc":[{"id":"1.187566733","rc":[{"batb":[[0,2.32,5.89],[1,2.22,31],[2,2.12,37.18]],"ltp":2.4,"tv":26200.51,"id":9323645}]}]}
{"op":"mcm","clk":"4216730590","pt":1631554826846,"mc":[{"id":"1.187566733","rc":[{"batb":[[0,1.58,123.73],[1,1.57,177.67],[2,1.3,199.49]],"batl":[[1,1.82,95.2],[2,1.84,94.37]],"ltp":1.6,"tv":10366.7,"id":8734382}]}]}
{"op":"mcm","clk":"4216731089","pt":1631554831183,"mc":[{"id":"1.187566733","rc":[{"batb":[[0,1.6,46.14],[1,1.58,123.73],[2,1.57,177.67]],"batl":[[0,1.73,32.5],[1,1.75,36.38],[2,1.82,95.2]],"ltp":1.6,"tv":10366.7,"id":8734382},{"batb":[[0,2.36,5.93],[1,2.32,5.89],[2,2.22,31]],"batl":[[0,2.68,5.39],[1,2.76,4.77]],"ltp":2.4,"tv":26200.51,"id":9323645}]}]}
{"op":"mcm","clk":"4216731109","pt":1631554831351,"mc":[{"id":"1.187566733","rc":[{"batb":[[0,1.58,123.73],[1,1.57,177.67],[2,1.3,199.49]],"batl":[[0,1.75,36.38],[1,1.82,95.2],[2,1.84,94.37]],"ltp":1.6,"tv":10366.7,"id":8734382},{"batb":[[0,2.32,5.89],[1,2.22,31],[2,2.12,37.18]],"batl":[[0,2.76,4.77],[1,2.76,0]],"ltp":2.4,"tv":26200.51,"id":9323645}]}]}
{"op":"mcm","clk":"4216731373","pt":1631554833739,"mc":[{"id":"1.187566733","rc":[{"batb":[[0,1.57,96.68],[1,1.3,199.49],[2,1.25,167.57]],"ltp":1.6,"tv":10366.7,"id":8734382}]}]}
{"op":"mcm","clk":"4216731730","pt":1631554837070,"mc":[{"id":"1.187566733","rc":[{"trd":[[1.75,162.89],[1.76,15.51]],"batb":[[0,1.72,584.35],[1,1.71,17.54],[2,1.7,8.78]],"batl":[[0,1.83,492.73],[1,1.82,0],[2,1.84,0]],"ltp":1.76,"tv":10454.97,"id":8734382},{"trd":[[2.32,71.19]],"batb":[[0,2.22,31],[1,2.12,37.18],[2,1.5,107.72]],"ltp":2.32,"tv":26220.98,"id":9323645}],"tv":36675.96}]}
{"op":"mcm","clk":"4216731826","pt":1631554837861,"mc":[{"id":"1.187566733","rc":[{"batb":[[1,1.71,54.97]],"batl":[[0,1.79,16.76],[1,1.8,8.38],[2,1.81,8.38]],"ltp":1.76,"tv":10454.97,"id":8734382},{"batb":[[2,2.06,40.7]],"ltp":2.32,"tv":26220.98,"id":9323645}]}]}
{"op":"mcm","clk":"4216732041","pt":1631554839959,"mc":[{"id":"1.187566733","rc":[{"batb":[[0,1.75,106.49],[1,1.73,114.57],[2,1.72,584.35]],"batl":[[2,1.81,84.3]],"ltp":1.76,"tv":10454.97,"id":8734382}]}]}
{"op":"mcm","clk":"4216732380","pt":1631554843154,"mc":[{"id":"1.187566733","rc":[{"batb":[[0,1.75,137.97]],"batl":[[0,1.76,32.27],[1,1.79,66.57],[2,1.8,8.38]],"ltp":1.76,"tv":10454.97,"id":8734382},{"batb":[[0,2.3,6.78],[1,2.22,31],[2,2.12,37.18]],"batl":[[0,2.5,5.75],[1,2.54,5.38],[2,2.76,4.77]],"ltp":2.32,"tv":26220.98,"id":9323645}]}]}
{"op":"mcm","clk":"4216732439","pt":1631554843680,"mc":[{"id":"1.187566733","rc":[{"batl":[[2,1.8,44]],"ltp":1.76,"tv":10454.97,"id":8734382},{"batb":[[1,2.24,7.27],[2,2.22,37.84]],"batl":[[2,2.58,5.25]],"ltp":2.32,"tv":26220.98,"id":9323645}]}]}
{"op":"mcm","clk":"4216732585","pt":1631554845163,"mc":[{"id":"1.187566733","rc":[{"batl":[[1,1.78,49.44],[2,1.79,97.07]],"ltp":1.76,"tv":10454.97,"id":8734382},{"batb":[[1,2.26,6.98],[2,2.24,7.27]],"ltp":2.32,"tv":26220.98,"id":9323645}]}]}
{"op":"mcm","clk":"4216732801","pt":1631554847174,"mc":[{"id":"1.187566733","rc":[{"trd":[[1.73,154.03],[1.74,294.54],[1.75,300.86]],"batb":[[0,1.72,572.32],[1,1.71,54.97],[2,1.7,8.78]],"batl":[[1,1.78,83.69]],"ltp":1.73,"tv":10736.23,"id":8734382},{"trd":[[2.34,140.68],[2.36,37.46],[2.38,83.28]],"batb":[[0,2.38,72.27],[1,2.3,6.78],[2,2.28,6.66]],"ltp":2.38,"tv":26428.62,"id":9323645}],"tv":37164.85}]}
{"op":"mcm","clk":"4216732831","pt":1631554847493,"mc":[{"id":"1.187566733","rc":[{"trd":[[1.73,159.49]],"ltp":1.73,"tv":10741.69,"id":8734382},{"trd":[[2.38,92.09]],"batb":[[0,2.38,65.88]],"ltp":2.38,"tv":26437.43,"id":9323645}],"tv":37179.13}]}
{"op":"mcm","clk":"4216732920","pt":1631554848387,"mc":[{"id":"1.187566733","rc":[{"batl":[[1,1.77,46.81],[2,1.78,83.69]],"ltp":1.73,"tv":10741.69,"id":8734382}]}]}
{"op":"mcm","clk":"4216733085","pt":1631554850079,"mc":[{"id":"1.187566733","rc":[{"trd":[[1.73,250.13]],"batb":[[0,1.73,20.58],[1,1.72,572.32],[2,1.71,174.81]],"batl":[[0,1.76,80.06],[2,1.78,97.92]],"ltp":1.73,"tv":10832.33,"id":8734382},{"trd":[[2.38,157.98]],"batb":[[0,2.3,6.78],[1,2.28,6.66],[2,2.26,6.98]],"ltp":2.38,"tv":26503.31,"id":9323645}],"tv":37335.65}]}
{"op":"mcm","clk":"4216733129","pt":1631554850503,"mc":[{"id":"1.187566733","rc":[{"batb":[[0,1.72,572.32],[1,1.71,54.97],[2,1.7,8.78]],"ltp":1.73,"tv":10832.33,"id":8734382}]}]}
{"op":"mcm","clk":"4216733367","pt":1631554852463,"mc":[{"id":"1.187566733","rc":[{"batb":[[0,1.72,669.32]],"ltp":1.73,"tv":10832.33,"id":8734382}]}]}
{"op":"mcm","clk":"4216733502","pt":1631554853681,"mc":[{"id":"1.187566733","rc":[{"batb":[[0,1.72,784.54],[2,1.7,131.4]],"batl":[[1,1.77,81.31],[2,1.78,183.61]],"ltp":1.73,"tv":10832.33,"id":8734382}]}]}
{"op":"mcm","clk":"4216733581","pt":1631554854577,"mc":[{"id":"1.187566733","rc":[{"batb":[[0,1.72,687.54]],"ltp":1.73,"tv":10832.33,"id":8734382}]}]}
{"op":"mcm","clk":"4216733748","pt":1631554856164,"mc":[{"id":"1.187566733","rc":[{"batb":[[0,1.72,58.14],[1,1.71,8.77],[2,1.7,4.39]],"batl":[[0,1.78,34.25],[1,1.79,8.38],[2,1.8,4.19]],"ltp":1.73,"tv":10832.33,"id":8734382},{"batb":[[0,2.22,31],[1,2.06,40.7],[2,1.5,107.72]],"batl":[[0,2.58,5.25],[1,2.54,0],[2,2.58,0]],"ltp":2.38,"tv":26503.31,"id":9323645}]}]}
{"op":"mcm","clk":"4216734019","pt":1631554859073,"mc":[{"id":"1.187566733","rc":[{"batb":[[0,1.64,194.98],[1,1.63,71.36],[2,1.3,199.49]],"batl":[[0,1.77,34.5],[1,1.78,34.25],[2,1.84,62.48]],"ltp":1.73,"tv":10832.33,"id":8734382},{"batb":[[0,2.28,6.66],[1,2.22,31],[2,2.06,40.7]],"ltp":2.38,"tv":26503.31,"id":9323645}]}]}
{"op":"mcm","clk":"4216734098","pt":1631554859870,"mc":[{"id":"1.187566733","rc":[{"batl":[[0,1.78,34.25],[1,1.84,62.48],[2,1.86,92.93]],"ltp":1.73,"tv":10832.33,"id":8734382}]}]}
{"op":"mcm","clk":"4216734179","pt":1631554860611,"mc":[{"id":"1.187566733","rc":[{"batb":[[0,1.64,89.95],[1,1.3,199.49],[2,1.25,167.57]],"batl":[[1,1.84,0],[2,1.86,0]],"ltp":1.73,"tv":10832.33,"id":8734382}]}]}
{"op":"mcm","clk":"4216734495","pt":1631554863111,"mc":[{"id":"1.187566733","rc":[{"batl":[[0,1.72,2],[1,1.78,34.25]],"ltp":1.73,"tv":10832.33,"id":8734382}]}]}
{"op":"mcm","clk":"4216734576","pt":1631554863807,"mc":[{"id":"1.187566733","rc":[{"trd":[[1.72,164.13]],"batb":[[0,1.71,73.32],[1,1.7,61.52],[2,1.64,89.95]],"batl":[[0,1.76,77.79],[1,1.78,140.25]],"ltp":1.72,"tv":10836.33,"id":8734382}],"tv":37339.65}]}
{"op":"mcm","clk":"4216734729","pt":1631554865080,"mc":[{"id":"1.187566733","rc":[{"trd":[[1.76,41.65]],"batb":[[0,1.64,89.95],[1,1.3,199.49],[2,1.25,167.57]],"batl":[[0,1.78,34.25],[1,1.78,0]],"ltp":1.76,"tv":10862.47,"id":8734382},{"trd":[[2.3,25]],"ltp":2.3,"tv":26523.31,"id":9323645}],"tv":37385.79}]}
{"op":"mcm","clk":"4216734944","pt":1631554866978,"mc":[{"id":"1.187566733","rc":[{"batb":[[0,1.67,45.47],[1,1.64,89.95],[2,1.3,199.49]],"ltp":1.76,"tv":10862.47,"id":8734382},{"batl":[[0,2.5,5.45],[1,2.58,5.25]],"ltp":2.3,"tv":26523.31,"id":9323645}]}]}
{"op":"mcm","clk":"4216735076","pt":1631554868079,"mc":[{"id":"1.187566733","rc":[{"batb":[[0,1.64,194.98],[1,1.63,71.36]],"batl":[[1,1.84,62.48],[2,1.86,92.93]],"ltp":1.76,"tv":10862.47,"id":8734382},{"batl":[[0,2.58,5.25],[1,2.58,0]],"ltp":2.3,"tv":26523.31,"id":9323645}]}]}
{"op":"mcm","clk":"4216735120","pt":1631554868504,"mc":[{"id":"1.187566733","rc":[{"batb":[[0,1.64,210.39]],"batl":[[1,1.85,95.28],[2,1.87,91.22]],"ltp":1.76,"tv":10862.47,"id":8734382}]}]}
{"op":"mcm","clk":"4216735694","pt":1631554874012,"mc":[{"id":"1.187566733","rc":[{"batb":[[0,1.67,41.47],[1,1.64,210.39],[2,1.63,71.36]],"ltp":1.76,"tv":10862.47,"id":8734382},{"batl":[[0,2.5,5.01],[1,2.58,5.25]],"ltp":2.3,"tv":26523.31,"id":9323645}]}]}
{"op":"mcm","clk":"4216735721","pt":1631554874278,"mc":[{"id":"1.187566733","rc":[{"batb":[[0,1.64,210.39],[1,1.63,71.36],[2,1.3,199.49]],"ltp":1.76,"tv":10862.47,"id":8734382},{"batl":[[0,2.58,5.25],[1,2.58,0]],"ltp":2.3,"tv":26523.31,"id":9323645}]}]}
{"op":"mcm","clk":"4216736396","pt":1631554881013,"mc":[{"id":"1.187566733","rc":[{"batb":[[0,1.67,42.47],[1,1.64,210.39],[2,1.63,71.36]],"ltp":1.76,"tv":10862.47,"id":8734382},{"batl":[[0,2.5,5.31],[1,2.58,5.25]],"ltp":2.3,"tv":26523.31,"id":9323645}]}]}
{"op":"mcm","clk":"4216736453","pt":1631554881543,"mc":[{"id":"1.187566733","rc":[{"batb":[[0,1.64,89.95],[1,1.3,199.49],[2,1.25,167.57]],"ltp":1.76,"tv":10862.47,"id":8734382},{"batl":[[0,2.58,5.25],[1,2.58,0]],"ltp":2.3,"tv":26523.31,"id":9323645}]}]}
{"op":"mcm","clk":"4216736729","pt":1631554884113,"mc":[{"id":"1.187566733","rc":[{"batl":[[0,2.48,3.4],[1,2.58,5.25]],"ltp":2.3,"tv":26523.31,"id":9323645}]}]}
{"op":"mcm","clk":"4216736799","pt":1631554884747,"mc":[{"id":"1.187566733","rc":[{"trd":[[1.78,357],[1.79,294.58]],"batb":[[0,1.76,489.96],[1,1.75,17.14],[2,1.74,8.58]],"batl":[[0,1.8,10.92],[1,1.86,315.78],[2,1.87,0]],"ltp":1.79,"tv":10933.77,"id":8734382},{"trd":[[2.28,58.99]],"batb":[[0,2.22,31],[1,2.06,40.7],[2,1.5,107.72]],"batl":[[0,2.34,85.91],[1,2.38,11.25],[2,2.58,5.25]],"ltp":2.28,"tv":26534.43,"id":9323645}],"tv":37468.21}]}
{"op":"mcm","clk":"4216736909","pt":1631554885810,"mc":[{"id":"1.187566733","rc":[{"batb":[[0,1.76,524.45]],"batl":[[2,1.96,5.1]],"ltp":1.79,"tv":10933.77,"id":8734382},{"batb":[[1,2.2,13.64],[2,2.18,6.82]],"ltp":2.28,"tv":26534.43,"id":9323645}]}]}
{"op":"mcm","clk":"4216737088","pt":1631554887746,"mc":[{"id":"1.187566733","rc":[{"batb":[[0,1.78,103.6],[1,1.76,633.57],[2,1.75,17.14]],"batl":[[1,1.84,68.1],[2,1.86,408.15]],"ltp":1.79,"tv":10933.77,"id":8734382}]}]}
{"op":"mcm","clk":"4216737173","pt":1631554888641,"mc":[{"id":"1.187566733","rc":[{"batl":[[0,1.8,72.16]],"ltp":1.79,"tv":10933.77,"id":8734382}]}]}
{"op":"mcm","clk":"4216737574","pt":1631554892625,"mc":[{"id":"1.187566733","rc":[{"batl":[[1,1.81,60.64],[2,1.84,68.1]],"ltp":1.79,"tv":10933.77,"id":8734382}]}]}
{"op":"mcm","clk":"4216738135","pt":1631554898335,"mc":[{"id":"1.187566733","rc":[{"trd":[[1.78,357.54]],"batb":[[0,1.78,103.33]],"ltp":1.78,"tv":10934.31,"id":8734382}],"tv":37468.75}]}
{"op":"mcm","clk":"4216738701","pt":1631554904041,"mc":[{"id":"1.187566733","rc":[{"trd":[[1.78,358.06]],"batb":[[0,1.78,103.07]],"ltp":1.78,"tv":10934.83,"id":8734382}],"tv":37469.27}]}
{"op":"mcm","clk":"4216738908","pt":1631554905852,"mc":[{"id":"1.187566733","rc":[{"trd":[[1.78,378.29]],"batb":[[0,1.78,92.95]],"ltp":1.78,"tv":10955.07,"id":8734382},{"batb":[[0,2.2,13.64],[1,2.18,6.82],[2,2.16,6.82]],"ltp":2.28,"tv":26534.43,"id":9323645}],"tv":37489.51}]}
{"op":"mcm","clk":"4216739064","pt":1631554907155,"mc":[{"id":"1.187566733","rc":[{"trd":[[1.8,98.67]],"batl":[[0,1.8,69.67]],"ltp":1.8,"tv":10957.56,"id":8734382},{"trd":[[2.24,80.5]],"ltp":2.24,"tv":26536.43,"id":9323645}],"tv":37494.0}]}
{"op":"mcm","clk":"4216739095","pt":1631554907443,"mc":[{"id":"1.187566733","rc":[{"trd":[[1.78,382.85]],"batb":[[0,1.78,90.67]],"ltp":1.78,"tv":10962.12,"id":8734382}],"tv":37498.55}]}
{"op":"mcm","clk":"4216739247","pt":1631554908857,"mc":[{"id":"1.187566733","rc":[{"batb":[[0,2.26,31],[1,2.2,13.64],[2,2.18,6.82]],"ltp":2.24,"tv":26536.43,"id":9323645}]}]}
{"op":"mcm","clk":"4216739320","pt":1631554909661,"mc":[{"id":"1.187566733","rc":[{"trd":[[1.78,390.07]],"batb":[[0,1.78,87.06]],"ltp":1.78,"tv":10969.34,"id":8734382}],"tv":37505.77}]}
{"op":"mcm","clk":"4216739454","pt":1631554910963,"mc":[{"id":"1.187566733","rc":[{"batl":[[2,1.84,75.04]],"ltp":1.78,"tv":10969.34,"id":8734382}]}]}
{"op":"mcm","clk":"4216739675","pt":1631554913078,"mc":[{"id":"1.187566733","rc":[{"batb":[[0,1.78,223.46]],"ltp":1.78,"tv":10969.34,"id":8734382}]}]}
{"op":"mcm","clk":"4216740144","pt":1631554917563,"mc":[{"id":"1.187566733","rc":[{"batb":[[1,1.76,619.24]],"batl":[[0,1.84,75.04],[1,1.86,408.15],[2,1.96,5.1]],"ltp":1.78,"tv":10969.34,"id":8734382}]}]}
{"op":"mcm","clk":"4216740459","pt":1631554920559,"mc":[{"id":"1.187566733","rc":[{"batb":[[1,1.76,636.11]],"batl":[[0,1.8,8.43],[1,1.83,64.92],[2,1.84,75.04]],"ltp":1.78,"tv":10969.34,"id":8734382}]}]}
{"op":"mcm","clk":"4216740779","pt":1631554923567,"mc":[{"id":"1.187566733","rc":[{"trd":[[1.8,99.45]],"batl":[[0,1.8,8.04],[1,1.81,67.13],[2,1.83,64.92]],"ltp":1.8,"tv":10970.12,"id":8734382}],"tv":37506.55}]}
{"op":"mcm","clk":"4216741084","pt":1631554926474,"mc":[{"id":"1.187566733","rc":[{"batl":[[0,1.8,75.68]],"ltp":1.8,"tv":10970.12,"id":8734382}]}]}
{"op":"mcm","clk":"4216741872","pt":1631554934010,"mc":[{"id":"1.187566733","rc":[{"batb":[[1,1.76,619.24]],"batl":[[0,1.83,64.92],[1,1.84,75.04],[2,1.86,408.15]],"ltp":1.8,"tv":10970.12,"id":8734382}]}]}
{"op":"mcm","clk":"4216742193","pt":1631554936989,"mc":[{"id":"1.187566733","rc":[{"batb":[[0,1.79,19.79],[1,1.78,223.46],[2,1.76,636.51]],"batl":[[0,1.8,8.04],[1,1.83,64.92],[2,1.84,75.04]],"ltp":1.8,"tv":10970.12,"id":8734382}]}]}
{"op":"mcm","clk":"4216742484","pt":1631554939899,"mc":[{"id":"1.187566733","rc":[{"batb":[[1,1.78,242.36]],"batl":[[1,1.81,82.52],[2,1.83,64.92]],"ltp":1.8,"tv":10970.12,"id":8734382}]}]}
{"op":"mcm","clk":"4216742834","pt":1631554943085,"mc":[{"id":"1.187566733","rc":[{"batl":[[0,1.8,91.02]],"ltp":1.8,"tv":10970.12,"id":8734382}]}]}
{"op":"mcm","clk":"4216743278","pt":1631554947193,"mc":[{"id":"1.187566733","rc":[{"trd":[[2.26,120.35]],"batb":[[0,2.26,13.94]],"ltp":2.26,"tv":26570.56,"id":9323645}],"tv":37540.68}]}
{"op":"mcm","clk":"4216743433","pt":1631554948726,"mc":[{"id":"1.187566733","rc":[{"trd":[[1.79,295.09]],"batb":[[0,1.79,19.54]],"ltp":1.79,"tv":10970.62,"id":8734382}],"tv":37541.18}]}
{"op":"mcm","clk":"4216743780","pt":1631554952113,"mc":[{"id":"1.187566733","rc":[{"trd":[[1.79,299.86]],"batb":[[0,1.79,17.15]],"ltp":1.79,"tv":10975.4,"id":8734382}],"tv":37545.96}]}
{"op":"mcm","clk":"4216743922","pt":1631554953598,"mc":[{"id":"1.187566733","rc":[{"batb":[[1,1.78,147.9],[2,1.76,527.39]],"ltp":1.79,"tv":10975.4,"id":8734382}]}]}
{"op":"mcm","clk":"4216744155","pt":1631554955809,"mc":[{"id":"1.187566733","rc":[{"trd":[[2.26,137.41]],"batb":[[0,2.26,5.41]],"ltp":2.26,"tv":26587.62,"id":9323645}],"tv":37563.02}]}
{"op":"mcm","clk":"4216744229","pt":1631554956503,"mc":[{"id":"1.187566733","rc":[{"batb":[[0,1.79,86.82],[2,1.77,106.9]],"ltp":1.79,"tv":10975.4,"id":8734382}]}]}
{"op":"mcm","clk":"4216745746","pt":1631554971059,"mc":[{"id":"1.187566733","rc":[{"trd":[[1.8,280.13]],"batl":[[0,1.81,82.52],[1,1.83,64.92],[2,1.85,96.03]],"ltp":1.8,"tv":11156.07,"id":8734382}],"tv":37743.7}]}
{"op":"mcm","clk":"4216745766","pt":1631554971262,"mc":[{"id":"1.187566733","rc":[{"batl":[[0,1.85,96.03],[1,1.86,315.78],[2,1.87,90.69]],"ltp":1.8,"tv":11156.07,"id":8734382}]}]}
{"op":"mcm","clk":"4216746039","pt":1631554973945,"mc":[{"id":"1.187566733","rc":[{"trd":[[1.8,286.92]],"batb":[[0,1.8,53.8],[1,1.79,86.82],[2,1.78,147.9]],"ltp":1.8,"tv":11162.86,"id":8734382},{"trd":[[2.26,142.82]],"batb":[[0,2.2,13.64],[1,2.18,6.82],[2,2.16,6.82]],"ltp":2.26,"tv":26593.03,"id":9323645}],"tv":37755.9}]}
{"op":"mcm","clk":"4216746102","pt":1631554974523,"mc":[{"id":"1.187566733","rc":[{"batl":[[0,1.84,46.87],[1,1.85,96.03],[2,1.86,315.78]],"ltp":1.8,"tv":11162.86,"id":8734382},{"batl":[[2,2.54,6.25]],"ltp":2.26,"tv":26593.03,"id":9323645}]}]}
{"op":"mcm","clk":"4216746372","pt":1631554977124,"mc":[{"id":"1.187566733","rc":[{"trd":[[1.8,306.92]],"batb":[[0,1.81,42.64],[1,1.8,43.8],[2,1.79,86.82]],"ltp":1.8,"tv":11182.86,"id":8734382}],"tv":37775.9}]}
{"op":"mcm","clk":"4216747059","pt":1631554984167,"mc":[{"id":"1.187566733","rc":[{"batb":[[0,1.8,43.8],[1,1.79,86.82],[2,1.78,147.9]],"batl":[[0,1.83,17.51],[1,1.84,46.87],[2,1.85,96.03]],"ltp":1.8,"tv":11182.86,"id":8734382},{"batl":[[0,2.28,9.08],[1,2.34,85.91],[2,2.38,11.25]],"ltp":2.26,"tv":26593.03,"id":9323645}]}]}
{"op":"mcm","clk":"4216747393","pt":1631554987077,"mc":[{"id":"1.187566733","rc":[{"batl":[[0,1.82,40.75],[1,1.83,17.51],[2,1.84,46.87]],"ltp":1.8,"tv":11182.86,"id":8734382}]}]}
{"op":"mcm","clk":"4216748019","pt":1631554993057,"mc":[{"id":"1.187566733","rc":[{"batb":[[0,1.78,129],[1,1.76,34.49],[2,1.65,66.53]],"ltp":1.8,"tv":11182.86,"id":8734382},{"batb":[[0,2.06,40.7],[1,1.85,28.45],[2,1.5,107.72]],"batl":[[0,2.54,6.25],[1,2.68,4.39],[2,2.38,0]],"ltp":2.26,"tv":26593.03,"id":9323645}]}]}
{"op":"mcm","clk":"4216748101","pt":1631554993761,"mc":[{"id":"1.187566733","rc":[{"batb":[[0,1.64,43.13],[1,1.6,70.59],[2,1.3,199.49]],"ltp":1.8,"tv":11182.86,"id":8734382},{"batb":[[0,1.85,28.45],[1,1.5,107.72],[2,1.4,149.61]],"batl":[[0,2.68,4.39],[1,2.68,0]],"ltp":2.26,"tv":26593.03,"id":9323645}]}]}
{"op":"mcm","clk":"4216748348","pt":1631554996049,"mc":[{"id":"1.187566733","rc":[{"batb":[[0,1.67,62.32],[1,1.66,66.42],[2,1.64,43.13]],"batl":[[0,2.08,93.35],[1,2.1,64.87]],"ltp":1.8,"tv":11182.86,"id":8734382}]}]}
{"op":"mcm","clk":"4216748439","pt":1631554996950,"mc":[{"id":"1.187566733","rc":[{"batb":[[2,1.65,65.13]],"ltp":1.8,"tv":11182.86,"id":8734382},{"batl":[[0,2.2,8.53],[1,2.54,5.25],[2,2.68,4.39]],"ltp":2.26,"tv":26593.03,"id":9323645}]}]}
{"op":"mcm","clk":"4216748479","pt":1631554997268,"mc":[{"id":"1.187566733","rc":[{"batb":[[2,1.64,43.13]],"ltp":1.8,"tv":11182.86,"id":8734382},{"batl":[[1,2.68,4.39],[2,2.68,0]],"ltp":2.26,"tv":26593.03,"id":9323645}]}]}
{"op":"mcm","clk":"4216748609","pt":1631554998690,"mc":[{"id":"1.187566733","rc":[{"batl":[[0,2.68,4.39],[1,2.68,0]],"ltp":2.26,"tv":26593.03,"id":9323645}]}]}
{"op":"mcm","clk":"4216749127","pt":1631555004099,"mc":[{"id":"1.187566733","rc":[{"batb":[[2,1.65,65.13]],"ltp":1.8,"tv":11182.86,"id":8734382},{"batl":[[0,2.54,5.75],[1,2.68,4.39]],"ltp":2.26,"tv":26593.03,"id":9323645}]}]}
{"op":"mcm","clk":"4216749173","pt":1631555004469,"mc":[{"id":"1.187566733","rc":[{"batb":[[2,1.64,43.13]],"ltp":1.8,"tv":11182.86,"id":8734382},{"batl":[[0,2.68,4.39],[1,2.68,0]],"ltp":2.26,"tv":26593.03,"id":9323645}]}]}
{"op":"mcm","clk":"4216749417","pt":1631555007076,"mc":[{"id":"1.187566733","rc":[{"batb":[[0,1.68,10.15],[1,1.67,62.32],[2,1.66,472.81]],"batl":[[0,1.84,5.43]],"ltp":1.8,"tv":11182.86,"id":8734382},{"batb":[[0,2.4,10.66],[1,2.36,63.56],[2,2.34,31.78]],"ltp":2.26,"tv":26593.03,"id":9323645}]}]}
{"op":"mcm","clk":"4216749522","pt":1631555008081,"mc":[{"id":"1.187566733","rc":[{"batb":[[2,1.66,563.17]],"batl":[[0,1.72,107.38],[1,1.74,113.35],[2,1.84,5.43]],"ltp":1.8,"tv":11182.86,"id":8734382},{"batb":[[1,2.36,12.72],[2,2.34,6.36]],"batl":[[0,2.42,4.13],[1,2.68,4.39]],"ltp":2.26,"tv":26593.03,"id":9323645}]}]}
{"op":"mcm","clk":"4216749558","pt":1631555008502,"mc":[{"id":"1.187566733","rc":[{"batb":[[2,1.66,490.89]],"ltp":1.8,"tv":11182.86,"id":8734382}]}]}
{"op":"mcm","clk":"4216749976","pt":1631555012113,"mc":[{"id":"1.187566733","rc":[{"batb":[[0,1.69,24.89],[1,1.68,10.15],[2,1.67,62.32]],"batl":[[0,1.71,43.24],[1,1.72,224.15],[2,1.74,113.35]],"ltp":1.8,"tv":11182.86,"id":8734382}]}]}
{"op":"mcm","clk":"4216750004","pt":1631555012338,"mc":[{"id":"1.187566733","rc":[{"batl":[[1,1.72,107.38]],"ltp":1.8,"tv":11182.86,"id":8734382}]}]}
{"op":"mcm","clk":"4216750173","pt":1631555014017,"mc":[{"id":"1.187566733","rc":[{"trd":[[2.4,143.32]],"batb":[[0,2.4,2.13]],"batl":[[1,2.64,5.18],[2,2.68,4.39]],"ltp":2.4,"tv":26610.09,"id":9323645}],"tv":37792.96}]}
{"op":"mcm","clk":"4216750279","pt":1631555015318,"mc":[{"id":"1.187566733","rc":[{"batb":[[1,1.68,36.59]],"ltp":1.8,"tv":11182.86,"id":8734382}]}]}
{"op":"mcm","clk":"4216750468","pt":1631555017182,"mc":[{"id":"1.187566733","rc":[{"batb":[[0,1.7,151],[1,1.69,24.89],[2,1.68,36.59]],"ltp":1.8,"tv":11182.86,"id":8734382}]}]}
{"op":"mcm","clk":"4216750537","pt":1631555017923,"mc":[{"id":"1.187566733","rc":[{"trd":[[1.71,188.69]],"batl":[[0,1.72,107.38],[1,1.74,113.35],[2,1.84,5.43]],"ltp":1.71,"tv":11183.91,"id":8734382}],"tv":37794.01}]}
{"op":"mcm","clk":"4216750753","pt":1631555020308,"mc":[{"id":"1.187566733","rc":[{"batb":[[0,1.7,178.75]],"batl":[[0,1.72,152.5]],"ltp":1.71,"tv":11183.91,"id":8734382}]}]}
{"op":"mcm","clk":"4216750919","pt":1631555022108,"mc":[{"id":"1.187566733","rc":[{"batb":[[2,1.68,26.44]],"batl":[[2,1.84,0]],"ltp":1.71,"tv":11183.91,"id":8734382},{"batb":[[0,2.24,31.81],[1,2.02,43.3],[2,1.85,28.45]],"batl":[[0,2.64,5.18],[1,2.68,4.39],[2,2.74,4.48]],"ltp":2.4,"tv":26610.09,"id":9323645}]}]}
{"op":"mcm","clk":"4216750982","pt":1631555022689,"mc":[{"id":"1.187566733","rc":[{"batb":[[0,1.58,71.06],[1,1.57,51.27],[2,1.3,199.49]],"ltp":1.71,"tv":11183.91,"id":8734382},{"batb":[[0,2.02,43.3],[1,1.5,107.72],[2,1.4,149.61]],"batl":[[0,2.74,4.48],[1,2.68,0],[2,2.74,0]],"ltp":2.4,"tv":26610.09,"id":9323645}]}]}
{"op":"mcm","clk":"4216751221","pt":1631555025129,"mc":[{"id":"1.187566733","rc":[{"batb":[[1,1.57,190.82],[2,1.56,83.31]],"batl":[[0,1.88,58.46],[1,1.9,86.62]],"ltp":1.71,"tv":11183.91,"id":8734382}]}]}
{"op":"mcm","clk":"4216751338","pt":1631555026208,"mc":[{"id":"1.187566733","rc":[{"batb":[[0,1.61,71.09],[1,1.58,71.06],[2,1.57,190.82]],"ltp":1.71,"tv":11183.91,"id":8734382},{"batl":[[0,2.64,5.93],[1,2.74,4.48]],"ltp":2.4,"tv":26610.09,"id":9323645}]}]}
{"op":"mcm","clk":"4216751369","pt":1631555026519,"mc":[{"id":"1.187566733","rc":[{"batb":[[0,1.58,71.06],[1,1.57,190.82],[2,1.56,83.31]],"ltp":1.71,"tv":11183.91,"id":8734382},{"batl":[[0,2.74,4.48],[1,2.74,0]],"ltp":2.4,"tv":26610.09,"id":9323645}]}]}
{"op":"mcm","clk":"4216751589","pt":1631555028905,"mc":[{"id":"1.187566733","rc":[{"batl":[[0,1.75,5.71]],"ltp":1.71,"tv":11183.91,"id":8734382},{"batb":[[0,2.56,5.9],[1,2.52,138.88],[2,2.5,29.76]],"batl":[[0,2.66,14.47],[1,2.72,301.43],[2,2.74,4.48]],"ltp":2.4,"tv":26610.09,"id":9323645}]}]}
{"op":"mcm","clk":"4216751713","pt":1631555030014,"mc":[{"id":"1.187566733","rc":[{"trd":[[1.62,143.81]],"batb":[[0,1.59,94.34],[1,1.58,118.24],[2,1.57,238]],"batl":[[0,1.62,89.43],[1,1.63,70.08],[2,1.75,5.71]],"ltp":1.62,"tv":11190.09,"id":8734382},{"trd":[[2.6,24.85]],"batb":[[1,2.52,91.26],[2,2.5,5.96]],"ltp":2.6,"tv":26613.94,"id":9323645}],"tv":37804.04}]}
{"op":"mcm","clk":"4216751746","pt":1631555030324,"mc":[{"id":"1.187566733","rc":[{"batb":[[0,1.59,18.86],[1,1.58,80.5],[2,1.57,200.26]],"ltp":1.62,"tv":11190.09,"id":8734382}]}]}
{"op":"mcm","clk":"4216751899","pt":1631555032123,"mc":[{"id":"1.187566733","rc":[{"trd":[[1.62,157.51]],"batb":[[2,1.57,141.59]],"batl":[[0,1.62,75.73]],"ltp":1.62,"tv":11203.79,"id":8734382},{"trd":[[2.6,33.38]],"ltp":2.6,"tv":26622.48,"id":9323645}],"tv":37826.27}]}
{"op":"mcm","clk":"4216751987","pt":1631555033122,"mc":[{"id":"1.187566733","rc":[{"trd":[[1.62,229.17]],"batl":[[0,1.62,39.9],[2,1.68,48.42]],"ltp":1.62,"tv":11275.45,"id":8734382}],"tv":37897.93}]}
{"op":"mcm","clk":"4216752169","pt":1631555035025,"mc":[{"id":"1.187566733","rc":[{"batb":[[1,1.58,150.07]],"batl":[[0,1.62,48.8]],"ltp":1.62,"tv":11275.45,"id":8734382}]}]}
{"op":"mcm","clk":"4216752252","pt":1631555035918,"mc":[{"id":"1.187566733","rc":[{"batb":[[2,1.57,209.16]],"ltp":1.62,"tv":11275.45,"id":8734382}]}]}
{"op":"mcm","clk":"4216752357","pt":1631555037139,"mc":[{"id":"1.187566733","rc":[{"batb":[[1,1.58,170.31]],"batl":[[0,1.62,64.83],[2,1.65,45.45]],"ltp":1.62,"tv":11275.45,"id":8734382}]}]}
{"op":"mcm","clk":"4216752952","pt":1631555043119,"mc":[{"id":"1.187566733","rc":[{"batb":[[0,1.56,28.48],[1,1.55,71.59],[2,1.54,34.58]],"batl":[[0,1.65,45.45],[1,1.68,48.42],[2,1.7,35.35]],"ltp":1.62,"tv":11275.45,"id":8734382},{"batb":[[0,2.42,6.44],[1,2.36,6.18],[2,2.22,32.9]],"batl":[[0,2.82,5.25],[1,2.72,0],[2,2.74,0]],"ltp":2.6,"tv":26622.48,"id":9323645}]}]}
{"op":"mcm","clk":"4216752986","pt":1631555043435,"mc":[{"id":"1.187566733","rc":[{"batb":[[0,1.55,71.59],[1,1.51,58.66],[2,1.3,199.49]],"batl":[[0,1.73,33.5],[1,1.68,0],[2,1.7,0]],"ltp":1.62,"tv":11275.45,"id":8734382},{"batb":[[0,2.36,6.18],[1,2.22,32.9],[2,1.8,12]],"ltp":2.6,"tv":26622.48,"id":9323645}]}]}
{"op":"mcm","clk":"4216753250","pt":1631555046048,"mc":[{"id":"1.187566733","rc":[{"batb":[[0,1.58,22.75],[1,1.55,71.59],[2,1.52,96]],"batl":[[0,1.6,4.27],[1,1.63,42.26],[2,1.73,103.39]],"ltp":1.62,"tv":11275.45,"id":8734382}]}]}
{"op":"mcm","clk":"4216753344","pt":1631555046954,"mc":[{"id":"1.187566733","rc":[{"batb":[[0,1.55,71.59],[1,1.52,96],[2,1.51,152.36]],"batl":[[1,1.73,103.39],[2,1.75,111.33]],"ltp":1.62,"tv":11275.45,"id":8734382}]}]}
{"op":"mcm","clk":"4216753454","pt":1631555048016,"mc":[{"id":"1.187566733","rc":[{"batb":[[1,1.51,58.66],[2,1.3,199.49]],"batl":[[1,1.73,33.5],[2,1.75,0]],"ltp":1.62,"tv":11275.45,"id":8734382}]}]}
{"op":"mcm","clk":"4216753649","pt":1631555050138,"mc":[{"id":"1.187566733","rc":[{"batl":[[1,1.7,40.85],[2,1.73,33.5]],"ltp":1.62,"tv":11275.45,"id":8734382},{"batb":[[0,2.42,6.94],[1,2.36,6.18],[2,2.22,32.9]],"ltp":2.6,"tv":26622.48,"id":9323645}]}]}
{"op":"mcm","clk":"4216753735","pt":1631555050938,"mc":[{"id":"1.187566733","rc":[{"trd":[[1.6,5.04]],"batb":[[0,1.61,21.09],[1,1.6,84.36],[2,1.59,77.22]],"batl":[[0,1.63,18.5],[1,1.65,126.18],[2,1.66,65.56]],"ltp":1.6,"tv":11279.71,"id":8734382},{"trd":[[2.66,2.57]],"batb":[[0,2.36,6.18],[1,2.22,32.9],[2,1.8,12]],"batl":[[0,2.64,16.36],[1,2.82,5.25]],"ltp":2.66,"tv":26625.05,"id":9323645}],"tv":37904.77}]}
{"op":"mcm","clk":"4216753761","pt":1631555051251,"mc":[{"id":"1.187566733","rc":[{"batb":[[0,1.6,84.36],[1,1.59,77.22],[2,1.55,71.59]],"batl":[[0,1.65,126.18],[1,1.66,65.56],[2,1.73,33.5]],"ltp":1.6,"tv":11279.71,"id":8734382},{"batl":[[0,2.82,5.25],[1,2.82,0]],"ltp":2.66,"tv":26625.05,"id":9323645}]}]}
{"op":"mcm","clk":"4216754008","pt":1631555053740,"mc":[{"id":"1.187566733","rc":[{"batl":[[2,1.7,34.85]],"ltp":1.6,"tv":11279.71,"id":8734382},{"batb":[[0,2.42,6.13],[1,2.36,6.18],[2,2.22,32.9]],"ltp":2.66,"tv":26625.05,"id":9323645}]}]}
{"op":"mcm","clk":"4216754237","pt":1631555056141,"mc":[{"id":"1.187566733","rc":[{"batb":[[0,1.55,71.59],[1,1.51,58.66],[2,1.3,199.49]],"batl":[[0,1.73,33.5],[1,1.66,0],[2,1.7,0]],"ltp":1.6,"tv":11279.71,"id":8734382},{"batb":[[0,2.36,6.18],[1,2.22,32.9],[2,1.8,12]],"ltp":2.66,"tv":26625.05,"id":9323645}]}]}
{"op":"mcm","clk":"4216754498","pt":1631555058568,"mc":[{"id":"1.187566733","rc":[{"batb":[[1,1.52,96],[2,1.51,152.36]],"batl":[[0,1.73,103.39],[1,1.75,111.33]],"ltp":1.6,"tv":11279.71,"id":8734382}]}]}
{"op":"mcm","clk":"4216754941","pt":1631555062933,"mc":[{"id":"1.187566733","rc":[{"batl":[[0,1.7,37.65],[1,1.73,103.39],[2,1.75,111.33]],"ltp":1.6,"tv":11279.71,"id":8734382},{"batb":[[0,2.42,5.44],[1,2.36,6.18],[2,2.22,32.9]],"ltp":2.66,"tv":26625.05,"id":9323645}]}]}
{"op":"mcm","clk":"4216755062","pt":1631555064034,"mc":[{"id":"1.187566733","rc":[{"batb":[[0,1.57,70.57],[1,1.55,71.59],[2,1.52,96]],"batl":[[0,1.73,103.39],[1,1.75,111.33],[2,1.75,0]],"ltp":1.6,"tv":11279.71,"id":8734382},{"batb":[[0,2.36,6.18],[1,2.22,32.9],[2,1.8,12]],"batl":[[0,2.76,5.02],[1,2.82,5.25]],"ltp":2.66,"tv":26625.05,"id":9323645}]}]}
{"op":"mcm","clk":"4216755081","pt":1631555064242,"mc":[{"id":"1.187566733","rc":[{"batb":[[0,1.55,71.59],[1,1.52,96],[2,1.51,152.36]],"ltp":1.6,"tv":11279.71,"id":8734382},{"batl":[[0,2.82,5.25],[1,2.82,0]],"ltp":2.66,"tv":26625.05,"id":9323645}]}]}
{"op":"mcm","clk":"4216755781","pt":1631555071048,"mc":[{"id":"1.187566733","rc":[{"batb":[[0,1.57,69.57],[1,1.55,71.59],[2,1.52,96]],"batl":[[0,1.73,33.5],[1,1.75,0]],"ltp":1.6,"tv":11279.71,"id":8734382},{"batl":[[0,2.76,4.77],[1,2.82,5.25]],"ltp":2.66,"tv":26625.05,"id":9323645}]}]}
{"op":"mcm","clk":"4216755817","pt":1631555071398,"mc":[{"id":"1.187566733","rc":[{"batb":[[0,1.55,71.59],[1,1.52,96],[2,1.51,152.36]],"ltp":1.6,"tv":11279.71,"id":8734382},{"batl":[[0,2.82,5.25],[1,2.82,0]],"ltp":2.66,"tv":26625.05,"id":9323645}]}]}
{"op":"mcm","clk":"4216756158","pt":1631555074173,"mc":[{"id":"1.187566733","rc":[{"trd":[[1.56,168.9]],"batl":[[0,1.56,81.44],[1,1.57,79.73],[2,1.6,19.95]],"ltp":1.56,"tv":11295.36,"id":8734382},{"trd":[[2.78,64.42]],"batb":[[0,2.7,77.79],[1,2.68,16.67],[2,2.66,16.67]],"batl":[[1,2.84,190.71]],"ltp":2.78,"tv":26633.83,"id":9323645}],"tv":37929.2}]}
{"op":"mcm","clk":"4216756204","pt":1631555074548,"mc":[{"id":"1.187566733","rc":[{"trd":[[1.56,175.4]],"batl":[[0,1.56,74.94]],"ltp":1.56,"tv":11301.86,"id":8734382},{"trd":[[2.78,68.07]],"batl":[[2,2.92,10.28]],"ltp":2.78,"tv":26637.48,"id":9323645}],"tv":37939.35}]}
{"op":"mcm","clk":"4216756440","pt":1631555076873,"mc":[{"id":"1.187566733","rc":[{"batb":[[1,1.52,104.85]],"batl":[[2,1.59,6.93]],"ltp":1.56,"tv":11301.86,"id":8734382}]}]}
{"op":"mcm","clk":"4216756547","pt":1631555077881,"mc":[{"id":"1.187566733","rc":[{"batb":[[1,1.53,23.06],[2,1.52,104.85]],"batl":[[0,1.56,84.85],[2,1.58,43.29]],"ltp":1.56,"tv":11301.86,"id":8734382}]}]}
{"op":"mcm","clk":"4216756641","pt":1631555078782,"mc":[{"id":"1.187566733","rc":[{"batl":[[0,1.56,91.78]],"ltp":1.56,"tv":11301.86,"id":8734382}]}]}
{"op":"mcm","clk":"4216756744","pt":1631555079859,"mc":[{"id":"1.187566733","rc":[{"batb":[[0,1.55,202.59],[1,1.54,68.62],[2,1.53,93.39]],"batl":[[0,1.56,98.7]],"ltp":1.56,"tv":11301.86,"id":8734382},{"batl":[[2,2.86,4.75]],"ltp":2.78,"tv":26637.48,"id":9323645}]}]}
{"op":"mcm","clk":"4216756924","pt":1631555081680,"mc":[{"id":"1.187566733","rc":[{"batl":[[0,1.56,91.78]],"ltp":1.56,"tv":11301.86,"id":8734382}]}]}
{"op":"mcm","clk":"4216757081","pt":1631555083178,"mc":[{"id":"1.187566733","rc":[{"trd":[[1.56,176.89]],"batb":[[1,1.54,90.46]],"batl":[[0,1.56,90.29]],"ltp":1.56,"tv":11303.35,"id":8734382},{"trd":[[2.78,68.91]],"ltp":2.78,"tv":26638.32,"id":9323645}],"tv":37941.67}]}
{"op":"mcm","clk":"4216757341","pt":1631555085895,"mc":[{"id":"1.187566733","rc":[{"trd":[[1.56,329.27]],"batl":[[0,1.56,14.1]],"ltp":1.56,"tv":11455.73,"id":8734382}],"tv":38094.05}]}
{"op":"mcm","clk":"4216757406","pt":1631555086546,"mc":[{"id":"1.187566733","rc":[{"trd":[[1.55,258.79]],"batb":[[0,1.55,195.66]],"batl":[[0,1.56,6.93],[2,1.58,60.67]],"ltp":1.55,"tv":11469.59,"id":8734382},{"batl":[[1,2.84,200.85]],"ltp":2.78,"tv":26638.32,"id":9323645}],"tv":38107.91}]}
{"op":"mcm","clk":"4216757654","pt":1631555089479,"mc":[{"id":"1.187566733","rc":[{"batb":[[0,1.55,220.32]],"batl":[[1,1.57,121.44],[2,1.58,138.09]],"ltp":1.55,"tv":11469.59,"id":8734382}]}]}
{"op":"mcm","clk":"4216758359","pt":1631555097197,"mc":[{"id":"1.187566733","rc":[{"batb":[[0,1.55,195.66],[1,1.54,68.62],[2,1.53,70.33]],"batl":[[2,1.58,77.42]],"ltp":1.55,"tv":11469.59,"id":8734382},{"batb":[[0,2.7,42.6],[1,2.68,2.78],[2,2.66,2.78]],"batl":[[1,2.86,4.75],[2,2.9,4.35]],"ltp":2.78,"tv":26638.32,"id":9323645}]}]}
{"op":"mcm","clk":"4216758448","pt":1631555098097,"mc":[{"id":"1.187566733","rc":[{"batb":[[0,1.55,131],[1,1.53,70.33],[2,1.48,64.2]],"batl":[[1,1.64,37.68],[2,1.78,2.61]],"ltp":1.55,"tv":11469.59,"id":8734382},{"batb":[[0,2.56,5.58],[1,2.4,25.85],[2,1.8,12]],"batl":[[0,2.9,4.35],[1,2.86,0],[2,2.9,0]],"ltp":2.78,"tv":26638.32,"id":9323645}]}]}
{"op":"mcm","clk":"4216758515","pt":1631555098799,"mc":[{"id":"1.187566733","rc":[{"batb":[[0,1.53,70.33],[1,1.48,64.2],[2,1.25,167.57]],"batl":[[0,1.55,26.02]],"ltp":1.55,"tv":11469.59,"id":8734382}]}]}
{"op":"mcm","clk":"4216758675","pt":1631555100203,"mc":[{"id":"1.187566733","rc":[{"batb":[[1,1.49,108.77],[2,1.48,165.18]],"batl":[[1,1.63,111.11],[2,1.64,105.75]],"ltp":1.55,"tv":11469.59,"id":8734382}]}]}
{"op":"mcm","clk":"4216758788","pt":1631555101119,"mc":[{"id":"1.187566733","rc":[{"batb":[[1,1.48,64.2],[2,1.25,167.57]],"batl":[[1,1.64,37.68],[2,1.78,2.61]],"ltp":1.55,"tv":11469.59,"id":8734382}]}]}
{"op":"mcm","clk":"4216758846","pt":1631555101608,"mc":[{"id":"1.187566733","rc":[{"batl":[[1,1.61,6.93],[2,1.64,37.68]],"ltp":1.55,"tv":11469.59,"id":8734382}]}]}
{"op":"mcm","clk":"4216759143","pt":1631555104202,"mc":[{"id":"1.187566733","rc":[{"trd":[[1.55,301.58]],"batb":[[0,1.54,70.31],[1,1.53,158.84],[2,1.48,64.2]],"batl":[[0,1.55,4.63],[1,1.58,106.3],[2,1.59,75.81]],"ltp":1.55,"tv":11512.37,"id":8734382}],"tv":38150.69}]}
{"op":"mcm","clk":"4216759193","pt":1631555104616,"mc":[{"id":"1.187566733","rc":[{"batb":[[2,1.5,7.16]],"ltp":1.55,"tv":11512.37,"id":8734382},{"batb":[[0,2.6,5.49],[1,2.56,5.58],[2,2.4,25.85]],"ltp":2.78,"tv":26638.32,"id":9323645}]}]}
{"op":"mcm","clk":"4216759467","pt":1631555107032,"mc":[{"id":"1.187566733","rc":[{"trd":[[1.55,304.55]],"batb":[[0,1.53,70.33],[1,1.5,7.16],[2,1.48,64.2]],"batl":[[0,1.55,3.14],[1,1.61,6.93],[2,1.62,39.25]],"ltp":1.55,"tv":11515.35,"id":8734382}],"tv":38153.67}]}
{"op":"mcm","clk":"4216759557","pt":1631555107907,"mc":[{"id":"1.187566733","rc":[{"batb":[[0,1.54,73.12],[1,1.53,70.33],[2,1.5,7.16]],"batl":[[2,1.64,37.68]],"ltp":1.55,"tv":11515.35,"id":8734382},{"batb":[[0,2.56,5.58],[1,2.4,25.85],[2,1.8,12]],"batl":[[0,2.86,4.75],[1,2.9,4.35]],"ltp":2.78,"tv":26638.32,"id":9323645}]}]}
{"op":"mcm","clk":"4216759665","pt":1631555108709,"mc":[{"id":"1.187566733","rc":[{"batb":[[0,1.53,70.33],[1,1.5,7.16],[2,1.48,64.2]],"batl":[[1,1.57,6.93],[2,1.61,6.93]],"ltp":1.55,"tv":11515.35,"id":8734382},{"batl":[[0,2.9,4.35],[1,2.9,0]],"ltp":2.78,"tv":26638.32,"id":9323645}]}]}
{"op":"mcm","clk":"4216759809","pt":1631555110023,"mc":[{"id":"1.187566733","rc":[{"trd":[[1.55,307.69]],"batb":[[2,1.49,108.77]],"batl":[[0,1.57,6.93],[1,1.61,6.93],[2,1.63,111.11]],"ltp":1.55,"tv":11518.48,"id":8734382},{"trd":[[2.8,16.34]],"batl":[[0,2.8,1.88],[1,2.9,4.35]],"ltp":2.8,"tv":26640.05,"id":9323645}],"tv":38158.54}]}
{"op":"mcm","clk":"4216760350","pt":1631555115105,"mc":[{"id":"1.187566733","rc":[{"batb":[[0,1.54,66.12],[1,1.53,70.33],[2,1.5,7.16]],"ltp":1.55,"tv":11518.48,"id":8734382},{"batl":[[1,2.86,5.25],[2,2.9,4.35]],"ltp":2.8,"tv":26640.05,"id":9323645}]}]}
{"op":"mcm","clk":"4216760389","pt":1631555115621,"mc":[{"id":"1.187566733","rc":[{"batb":[[0,1.53,70.33],[1,1.5,7.16],[2,1.49,108.77]],"ltp":1.55,"tv":11518.48,"id":8734382},{"batl":[[1,2.9,4.35],[2,2.9,0]],"ltp":2.8,"tv":26640.05,"id":9323645}]}]}
{"op":"mcm","clk":"4216760509","pt":1631555116728,"mc":[{"id":"1.187566733","rc":[{"trd":[[1.55,310.22]],"ltp":1.55,"tv":11521.02,"id":8734382},{"trd":[[2.8,17.75]],"batl":[[0,2.9,4.83],[1,2.9,0]],"ltp":2.8,"tv":26641.45,"id":9323645}],"tv":38162.47}]}
{"op":"mcm","clk":"4216761033","pt":1631555121922,"mc":[{"id":"1.187566733","rc":[{"batb":[[1,1.48,64.2],[2,1.25,167.57]],"batl":[[0,1.63,111.11],[1,1.64,105.75],[2,1.78,2.61]],"ltp":1.55,"tv":11521.02,"id":8734382}]}]}
{"op":"mcm","clk":"4216761366","pt":1631555125211,"mc":[{"id":"1.187566733","rc":[{"batb":[[0,1.6,10.72],[1,1.58,112.91],[2,1.57,153.25]],"ltp":1.55,"tv":11521.02,"id":8734382},{"batb":[[0,2.6,7.01],[1,2.56,5.58],[2,2.5,271.01]],"batl":[[0,2.62,3.82],[1,2.72,11.04],[2,2.74,5.52]],"ltp":2.8,"tv":26641.45,"id":9323645}]}]}
{"op":"mcm","clk":"4216761427","pt":1631555125921,"mc":[{"id":"1.187566733","rc":[{"batl":[[2,1.74,5.75]],"ltp":1.55,"tv":11521.02,"id":8734382},{"batb":[[2,2.54,11.82]],"ltp":2.8,"tv":26641.45,"id":9323645}]}]}
{"op":"mcm","clk":"4216761535","pt":1631555127026,"mc":[{"id":"1.187566733","rc":[{"batl":[[0,1.62,6.93],[1,1.63,111.11],[2,1.64,105.75]],"ltp":1.55,"tv":11521.02,"id":8734382}]}]}
{"op":"mcm","clk":"4216761768","pt":1631555129037,"mc":[{"id":"1.187566733","rc":[{"batb":[[0,1.6,34.3]],"batl":[[1,1.63,154.15]],"ltp":1.55,"tv":11521.02,"id":8734382}]}]}
{"op":"mcm","clk":"4216761877","pt":1631555130116,"mc":[{"id":"1.187566733","rc":[{"batb":[[1,1.59,21.61],[2,1.58,112.91]],"ltp":1.55,"tv":11521.02,"id":8734382}]}]}
{"op":"mcm","clk":"4216761977","pt":1631555131121,"mc":[{"id":"1.187566733","rc":[{"batb":[[0,1.61,112],[1,1.6,34.3],[2,1.59,21.61]],"ltp":1.55,"tv":11521.02,"id":8734382}]}]}
{"op":"mcm","clk":"4216762238","pt":1631555133751,"mc":[{"id":"1.187566733","rc":[{"batl":[[2,1.64,143.72]],"ltp":1.55,"tv":11521.02,"id":8734382}]}]}
{"op":"mcm","clk":"4216762780","pt":1631555139633,"mc":[{"id":"1.187566733","rc":[{"trd":[[1.62,230.21]],"batl":[[0,1.62,6.4]],"ltp":1.62,"tv":11522.06,"id":8734382}],"tv":38163.52}]}
{"op":"mcm","clk":"4216763112","pt":1631555143063,"mc":[{"id":"1.187566733","rc":[{"trd":[[1.61,10.1]],"batb":[[0,1.61,117.98]],"ltp":1.61,"tv":11532.16,"id":8734382}],"tv":38173.62}]}
{"op":"mcm","clk":"4216764147","pt":1631555154186,"mc":[{"id":"1.187566733","rc":[{"batb":[[0,1.61,106.95],[1,1.58,112.91],[2,1.57,80.68]],"batl":[[1,1.63,111.11],[2,1.64,68.07]],"ltp":1.61,"tv":11532.16,"id":8734382},{"batb":[[0,2.46,6.51],[1,2.42,6.13],[2,2.4,25.85]],"batl":[[0,2.82,5.73],[1,2.9,4.35],[2,2.74,0]],"ltp":2.8,"tv":26641.45,"id":9323645}]}]}
{"op":"mcm","clk":"4216764224","pt":1631555154981,"mc":[{"id":"1.187566733","rc":[{"batb":[[0,1.55,73.99],[1,1.52,128.61],[2,1.51,58.91]],"batl":[[1,1.7,36.95],[2,1.78,2.61]],"ltp":1.61,"tv":11532.16,"id":8734382},{"batb":[[0,2.42,6.13],[1,2.22,32.64],[2,1.8,12]],"batl":[[1,2.9,0]],"ltp":2.8,"tv":26641.45,"id":9323645}]}]}
{"op":"mcm","clk":"4216764341","pt":1631555156188,"mc":[{"id":"1.187566733","rc":[{"batl":[[0,1.7,36.95],[1,1.78,2.61],[2,1.78,0]],"ltp":1.61,"tv":11532.16,"id":8734382}]}]}
{"op":"mcm","clk":"4216764444","pt":1631555157192,"mc":[{"id":"1.187566733","rc":[{"batb":[[1,1.52,238.97],[2,1.51,152.27]],"batl":[[1,1.73,66.54],[2,1.75,110.86]],"ltp":1.61,"tv":11532.16,"id":8734382}]}]}
{"op":"mcm","clk":"4216764555","pt":1631555158198,"mc":[{"id":"1.187566733","rc":[{"batl":[[0,1.68,34.14],[1,1.7,36.95],[2,1.73,66.54]],"ltp":1.61,"tv":11532.16,"id":8734382},{"batb":[[0,2.46,5.88],[1,2.42,6.13],[2,2.22,32.64]],"ltp":2.8,"tv":26641.45,"id":9323645}]}]}
{"op":"mcm","clk":"4216764653","pt":1631555159163,"mc":[{"id":"1.187566733","rc":[{"batb":[[1,1.52,128.61],[2,1.51,58.91]],"batl":[[0,1.68,6.93],[2,1.78,2.61]],"ltp":1.61,"tv":11532.16,"id":8734382},{"batb":[[0,2.42,6.13],[1,2.22,32.64],[2,1.8,12]],"ltp":2.8,"tv":26641.45,"id":9323645}]}]}
{"op":"mcm","clk":"4216764829","pt":1631555161067,"mc":[{"id":"1.187566733","rc":[{"batb":[[0,1.57,65.57],[1,1.55,73.99],[2,1.52,128.61]],"ltp":1.61,"tv":11532.16,"id":8734382},{"batl":[[0,2.76,4.27],[1,2.82,5.73]],"ltp":2.8,"tv":26641.45,"id":9323645}]}]}
{"op":"mcm","clk":"4216764942","pt":1631555162075,"mc":[{"id":"1.187566733","rc":[{"batb":[[0,1.62,20.04],[1,1.6,102.98],[2,1.59,77]],"batl":[[0,1.64,20.93],[1,1.65,106.98],[2,1.66,65.35]],"ltp":1.61,"tv":11532.16,"id":8734382},{"batl":[[0,2.62,21.75]],"ltp":2.8,"tv":26641.45,"id":9323645}]}]}
{"op":"mcm","clk":"4216765001","pt":1631555162556,"mc":[{"id":"1.187566733","rc":[{"batb":[[0,1.6,102.98],[1,1.59,77],[2,1.55,73.99]],"batl":[[0,1.65,106.98],[1,1.66,65.35],[2,1.68,6.93]],"ltp":1.61,"tv":11532.16,"id":8734382},{"batl":[[0,2.82,5.73],[1,2.82,0]],"ltp":2.8,"tv":26641.45,"id":9323645}]}]}
{"op":"mcm","clk":"4216765245","pt":1631555164866,"mc":[{"id":"1.187566733","rc":[{"batb":[[0,1.55,73.99],[1,1.52,128.61],[2,1.51,58.91]],"batl":[[0,1.68,6.93],[1,1.69,256.02],[2,1.7,36.95]],"ltp":1.61,"tv":11532.16,"id":8734382}]}]}
{"op":"mcm","clk":"4216765330","pt":1631555165775,"mc":[{"id":"1.187566733","rc":[{"batl":[[0,1.57,45],[1,1.68,6.93],[2,1.69,256.02]],"ltp":1.61,"tv":11532.16,"id":8734382}]}]}
{"op":"mcm","clk":"4216765457","pt":1631555167058,"mc":[{"id":"1.187566733","rc":[{"batl":[[1,1.69,256.02],[2,1.7,36.95]],"ltp":1.61,"tv":11532.16,"id":8734382}]}]}
{"op":"mcm","clk":"4216765547","pt":1631555168060,"mc":[{"id":"1.187566733","rc":[{"trd":[[1.57,180.99]],"batb":[[0,1.57,27.57],[1,1.55,73.99],[2,1.52,238.97]],"batl":[[0,1.69,256.02],[1,1.7,36.95],[2,1.73,66.54]],"ltp":1.57,"tv":11622.16,"id":8734382},{"batl":[[0,2.76,4.52],[1,2.82,5.73]],"ltp":2.8,"tv":26641.45,"id":9323645}],"tv":38263.62}]}
{"op":"mcm","clk":"4216765639","pt":1631555169046,"mc":[{"id":"1.187566733","rc":[{"batb":[[0,1.55,73.99],[1,1.52,238.97],[2,1.51,152.27]],"batl":[[0,1.68,41.64],[1,1.69,256.02],[2,1.7,36.95]],"ltp":1.57,"tv":11622.16,"id":8734382},{"batb":[[0,2.46,5.88],[1,2.42,6.13],[2,2.22,32.64]],"batl":[[0,2.82,5.73],[1,2.82,0]],"ltp":2.8,"tv":26641.45,"id":9323645}]}]}
{"op":"mcm","clk":"4216765765","pt":1631555170175,"mc":[{"id":"1.187566733","rc":[{"trd":[[1.57,184.93]],"batb":[[0,1.57,5.41],[1,1.55,73.99],[2,1.52,238.97]],"batl":[[0,1.69,256.02],[1,1.7,36.95],[2,1.73,66.54]],"ltp":1.57,"tv":11626.1,"id":8734382},{"batb":[[0,2.42,6.13],[1,2.22,32.64],[2,1.8,12]],"ltp":2.8,"tv":26641.45,"id":9323645}],"tv":38267.55}]}
{"op":"mcm","clk":"4216765948","pt":1631555171977,"mc":[{"id":"1.187566733","rc":[{"batb":[[0,1.57,12.79]],"ltp":1.57,"tv":11626.1,"id":8734382}]}]}
{"op":"mcm","clk":"4216766275","pt":1631555175179,"mc":[{"id":"1.187566733","rc":[{"batl":[[0,2.76,4.27],[1,2.82,5.73]],"ltp":2.8,"tv":26641.45,"id":9323645}]}]}
{"op":"mcm","clk":"4216766366","pt":1631555176076,"mc":[{"id":"1.187566733","rc":[{"trd":[[1.69,8.35]],"batl":[[0,1.68,35.14],[1,1.69,256],[2,1.7,36.95]],"ltp":1.69,"tv":11626.13,"id":8734382},{"batb":[[0,2.46,5.51],[1,2.42,6.13],[2,2.22,32.64]],"batl":[[0,2.82,5.73],[1,2.82,0]],"ltp":2.8,"tv":26641.45,"id":9323645}],"tv":38267.58}]}
{"op":"mcm","clk":"4216766408","pt":1631555176496,"mc":[{"id":"1.187566733","rc":[{"batl":[[0,1.69,256],[1,1.7,36.95],[2,1.73,66.54]],"ltp":1.69,"tv":11626.13,"id":8734382},{"batb":[[0,2.42,6.13],[1,2.22,32.64],[2,1.8,12]],"ltp":2.8,"tv":26641.45,"id":9323645}]}]}
{"op":"mcm","clk":"4216766655","pt":1631555179157,"mc":[{"id":"1.187566733","rc":[{"batb":[[2,1.52,128.61]],"batl":[[0,1.7,36.95],[1,1.73,66.54],[2,1.75,110.86]],"ltp":1.69,"tv":11626.13,"id":8734382},{"batl":[[0,2.76,5.27],[1,2.82,5.73]],"ltp":2.8,"tv":26641.45,"id":9323645}]}]}
{"op":"mcm","clk":"4216766736","pt":1631555179964,"mc":[{"id":"1.187566733","rc":[{"trd":[[1.7,73.9],[1.71,194.4]],"batb":[[2,1.53,42.67]],"batl":[[0,1.73,66.54],[1,1.75,110.86],[2,1.78,2.61]],"ltp":1.71,"tv":11705.75,"id":8734382},{"trd":[[2.42,12.3]],"batb":[[0,2.42,2.09]],"batl":[[0,2.82,5.73],[1,2.82,0]],"ltp":2.42,"tv":26645.49,"id":9323645}],"tv":38351.24}]}
{"op":"mcm","clk":"4216766890","pt":1631555181700,"mc":[{"id":"1.187566733","rc":[{"batb":[[0,1.68,97.82],[1,1.67,64.82],[2,1.66,47.28]],"ltp":1.71,"tv":11705.75,"id":8734382},{"batb":[[1,2.4,9.04],[2,2.32,256.89]],"batl":[[0,2.44,4.1],[1,2.46,87.73],[2,2.48,12.1]],"ltp":2.42,"tv":26645.49,"id":9323645}]}]}
{"op":"mcm","clk":"4216766988","pt":1631555182763,"mc":[{"id":"1.187566733","rc":[{"batb":[[2,2.32,269.83]],"ltp":2.42,"tv":26645.49,"id":9323645}]}]}
{"op":"mcm","clk":"4216767087","pt":1631555183975,"mc":[{"id":"1.187566733","rc":[{"batb":[[1,1.67,71.75]],"ltp":1.71,"tv":11705.75,"id":8734382}]}]}
{"op":"mcm","clk":"4216767159","pt":1631555184664,"mc":[{"id":"1.187566733","rc":[{"batb":[[1,1.67,64.82]],"ltp":1.71,"tv":11705.75,"id":8734382}]}]}
{"op":"mcm","clk":"4216767247","pt":1631555185667,"mc":[{"id":"1.187566733","rc":[{"batb":[[0,1.69,8.84],[1,1.68,97.82],[2,1.67,64.82]],"batl":[[0,1.72,31.26],[1,1.73,66.54],[2,1.75,110.86]],"ltp":1.71,"tv":11705.75,"id":8734382}]}]}
{"op":"mcm","clk":"4216767411","pt":1631555187402,"mc":[{"id":"1.187566733","rc":[{"trd":[[1.69,15.58]],"batb":[[0,1.69,5.23]],"ltp":1.69,"tv":11712.97,"id":8734382}],"tv":38358.47}]}
{"op":"mcm","clk":"4216767591","pt":1631555189414,"mc":[{"id":"1.187566733","rc":[{"batb":[[1,1.68,106.74]],"batl":[[0,1.71,31.46],[1,1.72,31.26],[2,1.73,66.54]],"ltp":1.69,"tv":11712.97,"id":8734382}]}]}
{"op":"mcm","clk":"4216767784","pt":1631555191204,"mc":[{"id":"1.187566733","rc":[{"trd":[[1.69,31.96]],"batb":[[0,1.68,106.74],[1,1.67,64.82],[2,1.66,47.28]],"batl":[[0,1.69,31.75],[1,1.71,31.46],[2,1.72,31.26]],"ltp":1.69,"tv":11729.35,"id":8734382},{"trd":[[2.44,9.86]],"batl":[[0,2.46,87.73],[1,2.48,12.1],[2,2.5,279.66]],"ltp":2.44,"tv":26649.59,"id":9323645}],"tv":38378.95}]}
{"op":"mcm","clk":"4216768586","pt":1631555199095,"mc":[{"id":"1.187566733","rc":[{"trd":[[1.68,178.57]],"batb":[[0,1.67,64.82],[1,1.66,47.28],[2,1.65,42.21]],"ltp":1.68,"tv":11900.03,"id":8734382}],"tv":38549.63}]}
{"op":"mcm","clk":"4216768661","pt":1631555199890,"mc":[{"id":"1.187566733","rc":[{"trd":[[1.69,38.31]],"batl":[[0,1.69,28.58]],"ltp":1.69,"tv":11906.38,"id":8734382}],"tv":38555.98}]}
{"op":"mcm","clk":"4216768699","pt":1631555200308,"mc":[{"id":"1.187566733","rc":[{"batl":[[1,1.7,31.27],[2,1.71,31.46]],"ltp":1.69,"tv":11906.38,"id":8734382}]}]}
{"op":"mcm","clk":"4216768867","pt":1631555202110,"mc":[{"id":"1.187566733","rc":[{"batb":[[0,1.67,115.76],[1,1.66,113.72]],"ltp":1.69,"tv":11906.38,"id":8734382}]}]}
{"op":"mcm","clk":"4216768961","pt":1631555203118,"mc":[{"id":"1.187566733","rc":[{"batl":[[0,1.69,54.95]],"ltp":1.69,"tv":11906.38,"id":8734382}]}]}
{"op":"mcm","clk":"4216769886","pt":1631555212129,"mc":[{"id":"1.187566733","rc":[{"batb":[[0,1.65,42.21],[1,1.58,23.88],[2,1.57,256.02]],"batl":[[0,1.69,28.58],[1,1.78,2.61],[2,1.71,0]],"ltp":1.69,"tv":11906.38,"id":8734382},{"batb":[[0,2.22,32.64],[1,1.95,48.42],[2,1.4,149.61]],"batl":[[0,2.82,5.73],[1,2.9,4.55],[2,880,0.01]],"ltp":2.44,"tv":26649.59,"id":9323645}]}]}
{"op":"mcm","clk":"4216769926","pt":1631555212510,"mc":[{"id":"1.187566733","rc":[{"batb":[[0,1.58,23.88],[1,1.57,256.02],[2,1.55,73.99]],"ltp":1.69,"tv":11906.38,"id":8734382},{"batb":[[0,1.95,48.42],[1,1.4,149.61],[2,1.32,12.7]],"ltp":2.44,"tv":26649.59,"id":9323645}]}]}
{"op":"mcm","clk":"4216770210","pt":1631555215142,"mc":[{"id":"1.187566733","rc":[{"batb":[[1,1.57,326.59],[2,1.55,145.28]],"batl":[[2,1.96,68.43]],"ltp":1.69,"tv":11906.38,"id":8734382}]}]}
{"op":"mcm","clk":"4216770266","pt":1631555215640,"mc":[{"id":"1.187566733","rc":[{"batl":[[0,2.76,4.77],[1,2.82,5.73],[2,2.9,4.55]],"ltp":2.44,"tv":26649.59,"id":9323645}]}]}
{"op":"mcm","clk":"4216771011","pt":1631555223144,"mc":[{"id":"1.187566733","rc":[{"batb":[[2,1.55,73.99]],"batl":[[0,1.78,2.61],[1,1.96,68.43],[2,1.98,76.45]],"ltp":1.69,"tv":11906.38,"id":8734382}]}]}
{"op":"mcm","clk":"4216771390","pt":1631555226137,"mc":[{"id":"1.187566733","rc":[{"trd":[[1.78,392.68]],"batb":[[0,1.9,55.96],[1,1.88,88.19],[2,1.8,67.08]],"batl":[[0,1.92,17.64],[2,1.98,466.07]],"ltp":1.78,"tv":11908.99,"id":8734382},{"trd":[[2.28,61.03]],"batl":[[0,2.14,4.67],[1,2.16,29.69],[2,2.2,443.85]],"ltp":2.28,"tv":26651.63,"id":9323645}],"tv":38560.63}]}
{"op":"mcm","clk":"4216771428","pt":1631555226554,"mc":[{"id":"1.187566733","rc":[{"batb":[[2,1.85,29.12]],"ltp":1.78,"tv":11908.99,"id":8734382},{"batb":[[0,2.08,72.12],[1,2.06,36.06],[2,2.04,36.06]],"ltp":2.28,"tv":26651.63,"id":9323645}]}]}
{"op":"mcm","clk":"4216771567","pt":1631555227964,"mc":[{"id":"1.187566733","rc":[{"batb":[[0,2.08,14.42],[1,2.06,7.22],[2,2.04,7.22]],"batl":[[2,2.2,389.31]],"ltp":2.28,"tv":26651.63,"id":9323645}]}]}
{"op":"mcm","clk":"4216771899","pt":1631555231171,"mc":[{"id":"1.187566733","rc":[{"trd":[[1.9,111.92]],"batb":[[0,1.89,7.78],[1,1.85,29.12],[2,1.8,67.08]],"batl":[[1,1.93,18],[2,1.98,389.62]],"ltp":1.9,"tv":12020.91,"id":8734382}],"tv":38672.55}]}
{"op":"mcm","clk":"4216771934","pt":1631555231445,"mc":[{"id":"1.187566733","rc":[{"batb":[[0,1.91,7.61],[1,1.89,7.78],[2,1.85,29.12]],"ltp":1.9,"tv":12020.91,"id":8734382}]}]}
{"op":"mcm","clk":"4216772083","pt":1631555232840,"mc":[{"id":"1.187566733","rc":[{"trd":[[1.92,2.87]],"batl":[[0,1.92,14.77]],"ltp":1.92,"tv":12023.78,"id":8734382},{"trd":[[2.08,31.49]],"batb":[[0,2.06,7.22],[1,2.04,7.22],[2,1.95,48.42]],"ltp":2.08,"tv":26683.12,"id":9323645}],"tv":38706.91}]}
{"op":"mcm","clk":"4216772221","pt":1631555234065,"mc":[{"id":"1.187566733","rc":[{"trd":[[1.91,15.22]],"batb":[[0,1.89,76.54],[1,1.87,89.79]],"batl":[[0,1.9,25.41],[1,1.91,11.28],[2,1.92,33.59]],"ltp":1.91,"tv":12039.0,"id":8734382}],"tv":38722.13}]}
{"op":"mcm","clk":"4216772379","pt":1631555235549,"mc":[{"id":"1.187566733","rc":[{"batb":[[0,1.89,68.76]],"ltp":1.91,"tv":12039.0,"id":8734382}]}]}
{"op":"mcm","clk":"4216772732","pt":1631555238754,"mc":[{"id":"1.187566733","rc":[{"trd":[[1.89,101.2]],"batb":[[0,1.89,20.83]],"ltp":1.89,"tv":12134.87,"id":8734382}],"tv":38817.99}]}
{"op":"mcm","clk":"4216772883","pt":1631555240174,"mc":[{"id":"1.187566733","rc":[{"trd":[[1.9,112.41]],"batb":[[0,1.85,29.12],[1,1.84,8.24],[2,1.8,67.08]],"batl":[[0,1.91,11.28],[1,1.92,33.59],[2,1.93,18]],"ltp":1.9,"tv":12135.36,"id":8734382},{"trd":[[2.1,0.45]],"ltp":2.1,"tv":26683.57,"id":9323645}],"tv":38818.94}]}
{"op":"mcm","clk":"4216772974","pt":1631555240967,"mc":[{"id":"1.187566733","rc":[{"batl":[[0,1.91,97.49]],"ltp":1.9,"tv":12135.36,"id":8734382},{"batl":[[0,2.1,10],[1,2.14,4.67],[2,2.16,29.69]],"ltp":2.1,"tv":26683.57,"id":9323645}]}]}
{"op":"mcm","clk":"4216773031","pt":1631555241475,"mc":[{"id":"1.187566733","rc":[{"trd":[[1.9,112.81]],"ltp":1.9,"tv":12135.76,"id":8734382},{"trd":[[2.1,0.81]],"batl":[[0,2.1,9.64]],"ltp":2.1,"tv":26683.93,"id":9323645}],"tv":38819.7}]}
{"op":"mcm","clk":"4216773199","pt":1631555243055,"mc":[{"id":"1.187566733","rc":[{"trd":[[1.9,123.46]],"batb":[[0,1.88,86.86],[1,1.86,91.43],[2,1.85,29.12]],"batl":[[0,1.89,6.83],[1,1.91,97.49],[2,1.92,18.82]],"ltp":1.9,"tv":12146.41,"id":8734382},{"trd":[[2.1,10.45]],"batl":[[0,2.14,4.67],[1,2.16,18.98],[2,2.2,389.31]],"ltp":2.1,"tv":26693.57,"id":9323645}],"tv":38839.99}]}
{"op":"mcm","clk":"4216773272","pt":1631555243568,"mc":[{"id":"1.187566733","rc":[{"batl":[[0,1.9,17.18]],"ltp":1.9,"tv":12146.41,"id":8734382}]}]}
{"op":"mcm","clk":"4216773456","pt":1631555245159,"mc":[{"id":"1.187566733","rc":[{"batl":[[0,1.89,25.06],[1,1.9,17.18],[2,1.91,97.49]],"ltp":1.9,"tv":12146.41,"id":8734382}]}]}
{"op":"mcm","clk":"4216773549","pt":1631555246168,"mc":[{"id":"1.187566733","rc":[{"trd":[[1.89,101.61]],"batb":[[0,1.88,91.85]],"batl":[[0,1.89,24.65]],"ltp":1.89,"tv":12146.81,"id":8734382},{"trd":[[2.12,5.12]],"batl":[[1,2.16,32.24]],"ltp":2.12,"tv":26693.93,"id":9323645}],"tv":38840.75}]}
{"op":"mcm","clk":"4216773729","pt":1631555248168,"mc":[{"id":"1.187566733","rc":[{"batb":[[0,1.8,256.02],[1,1.71,9.75],[2,1.67,41.2]],"batl":[[1,1.91,86.21],[2,2,20]],"ltp":1.89,"tv":12146.81,"id":8734382},{"batb":[[0,1.67,40.03],[1,1.4,149.61],[2,1.32,12.7]],"batl":[[0,2.52,5.51],[1,2.7,5.15],[2,2.74,5.25]],"ltp":2.12,"tv":26693.93,"id":9323645}]}]}
{"op":"mcm","clk":"4216774063","pt":1631555251158,"mc":[{"id":"1.187566733","rc":[{"trd":[[1.89,102.01]],"batb":[[2,1.68,84.1]],"batl":[[0,1.89,24.25],[1,2,20],[2,2.36,89.29]],"ltp":1.89,"tv":12147.21,"id":8734382},{"trd":[[2.12,5.48]],"ltp":2.12,"tv":26694.29,"id":9323645}],"tv":38841.51}]}
{"op":"mcm","clk":"4216774618","pt":1631555255801,"mc":[{"id":"1.187566733","rc":[{"trd":[[1.89,110.54]],"batl":[[0,1.89,19.99]],"ltp":1.89,"tv":12155.75,"id":8734382}],"tv":38850.05}]}
{"op":"mcm","clk":"4216775153","pt":1631555261006,"mc":[{"id":"1.187566733","rc":[{"batb":[[2,1.67,41.2]],"batl":[[2,2.36,0]],"ltp":1.89,"tv":12155.75,"id":8734382}]}]}
{"op":"mcm","clk":"4216775231","pt":1631555261892,"mc":[{"id":"1.187566733","rc":[{"batl":[[0,2,20],[1,2,0]],"ltp":1.89,"tv":12155.75,"id":8734382},{"batb":[[1,1.32,12.7],[2,1.03,498.71]],"ltp":2.12,"tv":26694.29,"id":9323645}]}]}
{"op":"mcm","clk":"4216775292","pt":1631555262682,"mc":[{"id":"1.187566733","rc":[{"batb":[[1,1.67,41.2],[2,1.66,54.78]],"ltp":1.89,"tv":12155.75,"id":8734382}]}]}
{"op":"mcm","clk":"4216775426","pt":1631555264101,"mc":[{"id":"1.187566733","rc":[{"trd":[[2,299.05]],"batb":[[0,2.18,20.36],[1,1.8,256.02],[2,1.67,41.2]],"batl":[[0,2.28,13.91]],"ltp":2.0,"tv":12175.75,"id":8734382},{"trd":[[2,56.69]],"batb":[[0,1.74,93.47],[1,1.72,727.65],[2,1.67,40.03]],"batl":[[0,1.8,104.02],[1,1.82,101.18],[2,1.83,17.46]],"ltp":2.0,"tv":26714.29,"id":9323645}],"tv":38890.05}]}
{"op":"mcm","clk":"4216775525","pt":1631555265107,"mc":[{"id":"1.187566733","rc":[{"batb":[[0,2.2,34.57],[1,2.18,20.36],[2,1.87,28.36]],"batl":[[1,2.42,4.13]],"ltp":2.0,"tv":12175.75,"id":8734382},{"batb":[[0,1.77,16.96],[1,1.76,8.48],[2,1.75,8.48]],"ltp":2.0,"tv":26714.29,"id":9323645}]}]}
{"op":"mcm","clk":"4216783867","pt":1631555265871,"mc":[{"id":"1.187566733","rc":[{"batb":[[2,2.04,6.66]],"ltp":2.0,"tv":12175.75,"id":8734382}]}]}
{"op":"mcm","clk":"4216783969","pt":1631555266905,"mc":[{"id":"1.187566733","rc":[{"trd":[[2.28,10.34]],"batl":[[0,2.28,8.74]],"ltp":2.28,"tv":12186.09,"id":8734382}],"tv":38900.38}]}
{"op":"mcm","clk":"4216784135","pt":1631555268900,"mc":[{"id":"1.187566733","rc":[{"trd":[[2.24,69.56]],"ltp":2.24,"tv":12255.65,"id":8734382},{"trd":[[1.8,86.56]],"batb":[[0,1.77,25.46]],"batl":[[0,1.8,17.46]],"ltp":1.8,"tv":26800.85,"id":9323645}],"tv":39056.5}]}
{"op":"mcm","clk":"4216784169","pt":1631555269281,"mc":[{"id":"1.187566733","rc":[{"batl":[[0,1.83,17.46],[1,1.84,71.28],[2,1.87,80.75]],"ltp":1.8,"tv":26800.85,"id":9323645}]}]}
{"op":"mcm","clk":"4216784389","pt":1631555271181,"mc":[{"id":"1.187566733","rc":[{"batb":[[2,1.87,28.36]],"batl":[[0,2.24,16.86],[1,2.28,8.74],[2,2.42,4.13]],"ltp":2.24,"tv":12255.65,"id":8734382}]}]}
{"op":"mcm","clk":"4216784502","pt":1631555272418,"mc":[{"id":"1.187566733","rc":[{"batb":[[0,1.78,9.08],[1,1.77,25.46],[2,1.76,8.48]],"batl":[[0,1.81,107.06],[1,1.83,116.8],[2,1.84,71.28]],"ltp":1.8,"tv":26800.85,"id":9323645}]}]}
{"op":"mcm","clk":"4216784631","pt":1631555273882,"mc":[{"id":"1.187566733","rc":[{"trd":[[1.81,17.06]],"batl":[[0,1.81,98.53]],"ltp":1.81,"tv":26817.92,"id":9323645}],"tv":39073.57}]}
{"op":"mcm","clk":"4216784732","pt":1631555274895,"mc":[{"id":"1.187566733","rc":[{"trd":[[2.24,86.42],[2.28,19.08]],"batb":[[1,2.18,26.23]],"batl":[[0,2.42,4.13],[1,2.28,0],[2,2.42,0]],"ltp":2.28,"tv":12281.25,"id":8734382},{"trd":[[1.76,16.96],[1.77,50.93],[1.78,29.36],[1.8,107.54],[1.81,34.13]],"batb":[[0,1.75,93.07],[1,1.73,117.67],[2,1.72,607.51]],"batl":[[0,1.76,157.77],[1,1.81,90],[2,1.83,116.8]],"ltp":1.76,"tv":26953.21,"id":9323645}],"tv":39234.46}]}
{"op":"mcm","clk":"4216784955","pt":1631555277105,"mc":[{"id":"1.187566733","rc":[{"trd":[[2.3,7.82]],"ltp":2.3,"tv":12289.07,"id":8734382},{"trd":[[1.76,27.18]],"batl":[[0,1.76,147.55],[2,1.83,104.8]],"ltp":1.76,"tv":26963.42,"id":9323645}],"tv":39252.49}]}
{"op":"mcm","clk":"4216785029","pt":1631555277789,"mc":[{"id":"1.187566733","rc":[{"trd":[[1.76,104.21]],"batb":[[0,1.75,116.43]],"batl":[[0,1.76,109.04],[1,1.81,97.64]],"ltp":1.76,"tv":27040.45,"id":9323645}],"tv":39329.52}]}
{"op":"mcm","clk":"4216785141","pt":1631555278996,"mc":[{"id":"1.187566733","rc":[{"batb":[[1,2.18,20.36]],"ltp":2.3,"tv":12289.07,"id":8734382},{"trd":[[1.76,109.21]],"batl":[[0,1.76,270.54]],"ltp":1.76,"tv":27045.45,"id":9323645}],"tv":39334.52}]}
{"op":"mcm","clk":"4216785230","pt":1631555280098,"mc":[{"id":"1.187566733","rc":[{"trd":[[1.76,137.08]],"batl":[[0,1.76,256.6],[1,1.8,11.7],[2,1.81,97.64]],"ltp":1.76,"tv":27073.33,"id":9323645}],"tv":39362.4}]}
{"op":"mcm","clk":"4216785301","pt":1631555280830,"mc":[{"id":"1.187566733","rc":[{"batb":[[1,1.74,18.35],[2,1.73,117.67]],"batl":[[1,1.77,18.47],[2,1.8,11.7]],"ltp":1.76,"tv":27073.33,"id":9323645}]}]}
{"op":"mcm","clk":"4216785387","pt":1631555281719,"mc":[{"id":"1.187566733","rc":[{"batb":[[0,2.24,5.58],[1,2.2,34.57],[2,2.18,20.36]],"ltp":2.3,"tv":12289.07,"id":8734382},{"batl":[[2,1.78,22.09]],"ltp":1.76,"tv":27073.33,"id":9323645}]}]}
{"op":"mcm","clk":"4216785485","pt":1631555282821,"mc":[{"id":"1.187566733","rc":[{"trd":[[1.76,137.62]],"batl":[[0,1.76,256.33]],"ltp":1.76,"tv":27073.87,"id":9323645}],"tv":39362.94}]}
{"op":"mcm","clk":"4216785600","pt":1631555284089,"mc":[{"id":"1.187566733","rc":[{"trd":[[1.75,11.84],[1.76,249.9]],"batb":[[0,1.75,110.51]],"batl":[[0,1.76,200.19]],"ltp":1.75,"tv":27197.99,"id":9323645}],"tv":39487.06}]}
{"op":"mcm","clk":"4216785676","pt":1631555285030,"mc":[{"id":"1.187566733","rc":[{"batl":[[2,1.81,97.64]],"ltp":1.75,"tv":27197.99,"id":9323645}]}]}
{"op":"mcm","clk":"4216785791","pt":1631555286210,"mc":[{"id":"1.187566733","rc":[{"batb":[[0,1.75,107.95]],"batl":[[0,1.76,164]],"ltp":1.75,"tv":27197.99,"id":9323645}]}]}
{"op":"mcm","clk":"4216785843","pt":1631555286822,"mc":[{"id":"1.187566733","rc":[{"batb":[[1,1.87,28.36],[2,1.84,45.72]],"ltp":2.3,"tv":12289.07,"id":8734382},{"batb":[[0,1.6,256.02],[1,1.4,78.8],[2,1.32,12.7]],"batl":[[1,2.2,7.83],[2,2.32,5.61]],"ltp":1.75,"tv":27197.99,"id":9323645}]}]}
{"op":"mcm","clk":"4216785926","pt":1631555288025,"mc":[{"id":"1.187566733","rc":[{"batb":[[2,1.76,50.73]],"ltp":2.3,"tv":12289.07,"id":8734382},{"batl":[[0,2.32,5.61],[1,2.34,6.25],[2,2.52,5.51]],"ltp":1.75,"tv":27197.99,"id":9323645}]}]}
{"op":"mcm","clk":"4216785964","pt":1631555288501,"mc":[{"id":"1.187566733","rc":[{"batb":[[0,1.87,28.36],[1,1.76,50.73],[2,1.75,47.07]],"ltp":2.3,"tv":12289.07,"id":8734382},{"batl":[[0,1.89,256.02],[1,2.32,5.61],[2,2.34,6.25]],"ltp":1.75,"tv":27197.99,"id":9323645}]}]}
{"op":"mcm","clk":"4216786032","pt":1631555289538,"mc":[{"id":"1.187566733","rc":[{"batb":[[1,1.47,145.29],[2,1.46,114.53]],"batl":[[1,2.12,53.14],[2,2.14,61.19]],"ltp":1.75,"tv":27197.99,"id":9323645}]}]}
{"op":"mcm","clk":"4216786153","pt":1631555291110,"mc":[{"id":"1.187566733","rc":[{"batb":[[1,1.84,46.47],[2,1.76,50.73]],"ltp":2.3,"tv":12289.07,"id":8734382}]}]}
{"op":"mcm","clk":"4216786410","pt":1631555294250,"mc":[{"id":"1.187566733","rc":[{"batb":[[0,1.9,7.7],[1,1.87,28.36],[2,1.84,46.47]],"ltp":2.3,"tv":12289.07,"id":8734382}]}]}
{"op":"mcm","clk":"4216786915","pt":1631555299852,"mc":[{"id":"1.187566733","rc":[{"trd":[[2.12,705.65]],"ltp":2.12,"tv":12298.07,"id":8734382},{"trd":[[1.89,930.85]],"batl":[[0,1.89,245.92]],"ltp":1.89,"tv":27208.08,"id":9323645}],"tv":39506.15}]}
{"op":"mcm","clk":"4216787117","pt":1631555302222,"mc":[{"id":"1.187566733","rc":[{"trd":[[2.12,733.08]],"ltp":2.12,"tv":12325.5,"id":8734382},{"trd":[[1.89,961.62]],"batl":[[0,1.89,215.16]],"ltp":1.89,"tv":27238.85,"id":9323645}],"tv":39564.35}]}
{"op":"mcm","clk":"4216787448","pt":1631555306138,"mc":[{"id":"1.187566733","rc":[{"batb":[[2,1.76,50.73]],"ltp":2.12,"tv":12325.5,"id":8734382},{"batl":[[0,2.12,53.14],[1,2.14,61.19],[2,2.32,5.61]],"ltp":1.89,"tv":27238.85,"id":9323645}]}]}
{"op":"mcm","clk":"4216787540","pt":1631555307364,"mc":[{"id":"1.187566733","rc":[{"batb":[[0,1.87,28.36],[1,1.76,50.73],[2,1.75,47.07]],"ltp":2.12,"tv":12325.5,"id":8734382}]}]}
{"op":"mcm","clk":"4216787679","pt":1631555309039,"mc":[{"id":"1.187566733","rc":[{"batb":[[0,1.47,145.29],[1,1.46,114.53],[2,1.4,78.8]],"ltp":1.89,"tv":27238.85,"id":9323645}]}]}
{"op":"mcm","clk":"4216788493","pt":1631555317849,"mc":[{"id":"1.187566733","rc":[{"batb":[[0,1.9,20],[1,1.87,28.36],[2,1.76,50.73]],"ltp":2.12,"tv":12325.5,"id":8734382},{"batb":[[0,1.48,2.88],[1,1.47,145.29],[2,1.46,114.53]],"ltp":1.89,"tv":27238.85,"id":9323645}]}]}
{"op":"mcm","clk":"4216788613","pt":1631555319160,"mc":[{"id":"1.187566733","rc":[{"batb":[[1,1.4,78.8],[2,1.32,12.7]],"batl":[[0,2.32,5.61],[1,2.34,6.25],[2,2.52,5.51]],"ltp":1.89,"tv":27238.85,"id":9323645}]}]}
{"op":"mcm","clk":"4216788803","pt":1631555321054,"mc":[{"id":"1.187566733","rc":[{"trd":[[1.9,174.61]],"batb":[[0,1.87,28.36],[1,1.76,50.73],[2,1.75,47.07]],"batl":[[0,1.9,76.74],[1,1.92,1569],[2,2,7.58]],"ltp":1.9,"tv":12376.65,"id":8734382},{"trd":[[2.1,20.54]],"batb":[[0,2,7.58],[1,1.48,2.88],[2,1.4,78.8]],"batl":[[0,2.2,471.17],[1,2.32,5.61],[2,2.34,6.25]],"ltp":2.1,"tv":27248.94,"id":9323645}],"tv":39625.59}]}
{"op":"mcm","clk":"4216788916","pt":1631555322164,"mc":[{"id":"1.187566733","rc":[{"batb":[[0,1.89,72.14],[1,1.88,79.8],[2,1.87,158.22]],"batl":[[0,1.9,74.64],[1,1.95,56.75],[2,1.97,77.87]],"ltp":1.9,"tv":12376.65,"id":8734382},{"batb":[[1,1.93,49.76],[2,1.66,41.12]],"batl":[[0,2.12,4.72],[1,2.2,471.17],[2,2.32,5.61]],"ltp":2.1,"tv":27248.94,"id":9323645}]}]}
{"op":"mcm","clk":"4216788945","pt":1631555322482,"mc":[{"id":"1.187566733","rc":[{"batb":[[1,1.88,15.96],[2,1.87,126.3]],"ltp":1.9,"tv":12376.65,"id":8734382}]}]}
{"op":"mcm","clk":"4216789289","pt":1631555326177,"mc":[{"id":"1.187566733","rc":[{"trd":[[1.89,193.14]],"batb":[[0,1.88,15.96],[1,1.87,36.34],[2,1.86,7.98]],"ltp":1.89,"tv":12459.24,"id":8734382}],"tv":39708.18}]}
{"op":"mcm","clk":"4216789335","pt":1631555326654,"mc":[{"id":"1.187566733","rc":[{"trd":[[1.9,190.01]],"batl":[[0,1.9,66.94]],"ltp":1.9,"tv":12474.64,"id":8734382}],"tv":39723.58}]}
{"op":"mcm","clk":"4216789433","pt":1631555327864,"mc":[{"id":"1.187566733","rc":[{"trd":[[1.9,205.41]],"batl":[[0,1.9,59.24]],"ltp":1.9,"tv":12490.03,"id":8734382}],"tv":39738.97}]}
{"op":"mcm","clk":"4216789554","pt":1631555329077,"mc":[{"id":"1.187566733","rc":[{"trd":[[1.9,210.94]],"batb":[[0,1.88,109.99],[2,1.86,99.58]],"batl":[[0,1.9,53.71],[1,1.93,14.48],[2,1.95,78.95]],"ltp":1.9,"tv":12495.56,"id":8734382},{"trd":[[2.1,25.54]],"ltp":2.1,"tv":27253.94,"id":9323645}],"tv":39749.5}]}
{"op":"mcm","clk":"4216789655","pt":1631555330175,"mc":[{"id":"1.187566733","rc":[{"trd":[[1.9,229.8]],"batl":[[0,1.9,34.85],[1,1.92,14.8],[2,1.93,14.48]],"ltp":1.9,"tv":12514.42,"id":8734382},{"trd":[[2.1,42.61]],"ltp":2.1,"tv":27271.0,"id":9323645}],"tv":39785.43}]}
{"op":"mcm","clk":"4216789740","pt":1631555331171,"mc":[{"id":"1.187566733","rc":[{"batl":[[1,1.91,14.99],[2,1.92,14.8]],"ltp":1.9,"tv":12514.42,"id":8734382},{"batb":[[0,2.02,116.85],[1,2,7.58],[2,1.93,49.76]],"ltp":2.1,"tv":27271.0,"id":9323645}]}]}
{"op":"mcm","clk":"4216789821","pt":1631555332167,"mc":[{"id":"1.187566733","rc":[{"batl":[[2,1.92,29.95]],"ltp":1.9,"tv":12514.42,"id":8734382},{"batb":[[1,1.93,49.76],[2,1.66,41.12]],"ltp":2.1,"tv":27271.0,"id":9323645}]}]}
{"op":"mcm","clk":"4216789910","pt":1631555333058,"mc":[{"id":"1.187566733","rc":[{"trd":[[1.9,229.91]],"batl":[[0,1.9,34.79]],"ltp":1.9,"tv":12514.54,"id":8734382}],"tv":39785.54}]}
{"op":"mcm","clk":"4216790086","pt":1631555335190,"mc":[{"id":"1.187566733","rc":[{"trd":[[1.9,260.52]],"batl":[[0,1.9,4.18]],"ltp":1.9,"tv":12545.15,"id":8734382},{"trd":[[2.1,70.3]],"ltp":2.1,"tv":27298.69,"id":9323645}],"tv":39843.84}]}
{"op":"mcm","clk":"4216790178","pt":1631555336146,"mc":[{"id":"1.187566733","rc":[{"trd":[[1.9,264.7],[1.91,30.21],[1.92,22.69]],"batb":[[0,1.88,114.38],[1,1.87,40.23]],"batl":[[0,1.92,10.13],[1,1.93,14.48],[2,1.95,78.95]],"ltp":1.92,"tv":12584.14,"id":8734382},{"trd":[[2.08,63.55],[2.1,74.08]],"ltp":2.08,"tv":27334.54,"id":9323645}],"tv":39918.68}]}
{"op":"mcm","clk":"4216790251","pt":1631555337084,"mc":[{"id":"1.187566733","rc":[{"batl":[[1,1.95,78.95],[2,1.96,8.05]],"ltp":1.92,"tv":12584.14,"id":8734382},{"batb":[[0,1.93,49.76],[1,1.66,41.12],[2,1.32,12.7]],"batl":[[0,2.1,57.89],[1,2.12,4.72],[2,2.2,471.17]],"ltp":2.08,"tv":27334.54,"id":9323645}]}]}
{"op":"mcm","clk":"4216790334","pt":1631555338081,"mc":[{"id":"1.187566733","rc":[{"batb":[[0,1.88,114.65]],"ltp":1.92,"tv":12584.14,"id":8734382}]}]}
{"op":"mcm","clk":"4216790413","pt":1631555339180,"mc":[{"id":"1.187566733","rc":[{"trd":[[1.9,272.23]],"batb":[[0,1.89,19.28],[1,1.88,114.38],[2,1.87,40.23]],"ltp":1.9,"tv":12591.67,"id":8734382},{"trd":[[2.1,80.4]],"batl":[[0,2.1,51.57]],"ltp":2.1,"tv":27340.86,"id":9323645}],"tv":39932.53}]}
{"op":"mcm","clk":"4216790491","pt":1631555340071,"mc":[{"id":"1.187566733","rc":[{"trd":[[1.92,32.82]],"batl":[[0,1.93,17.47],[1,1.94,17.26],[2,1.95,78.95]],"ltp":1.92,"tv":12601.79,"id":8734382},{"trd":[[2.08,72.9]],"batb":[[0,1.94,72.65],[1,1.93,49.76],[2,1.66,41.12]],"batl":[[0,2.08,57.72],[1,2.1,118.69],[2,2.12,4.72]],"ltp":2.08,"tv":27350.21,"id":9323645}],"tv":39952.01}]}
{"op":"mcm","clk":"4216790577","pt":1631555341189,"mc":[{"id":"1.187566733","rc":[{"trd":[[1.92,51.16]],"ltp":1.92,"tv":12620.13,"id":8734382},{"trd":[[2.08,89.83]],"batl":[[0,2.08,40.79]],"ltp":2.08,"tv":27367.14,"id":9323645}],"tv":39987.28}]}
{"op":"mcm","clk":"4216790738","pt":1631555343172,"mc":[{"id":"1.187566733","rc":[{"trd":[[1.94,22.46]],"batl":[[0,1.95,78.95],[1,1.96,8.05],[2,1.97,77.87]],"ltp":1.94,"tv":12637.39,"id":8734382},{"trd":[[2.06,21.15]],"batb":[[0,1.95,65.32],[1,1.94,72.65],[2,1.93,49.76]],"batl":[[0,2.06,45.21],[1,2.08,40.79],[2,2.1,118.69]],"ltp":2.06,"tv":27383.39,"id":9323645}],"tv":40020.79}]}
{"op":"mcm","clk":"4216790797","pt":1631555343963,"mc":[{"id":"1.187566733","rc":[{"batb":[[0,1.95,1600.04]],"batl":[[1,2.1,67.12],[2,2.12,4.72]],"ltp":2.06,"tv":27383.39,"id":9323645}]}]}
{"op":"mcm","clk":"4216790884","pt":1631555345012,"mc":[{"id":"1.187566733","rc":[{"batb":[[0,1.92,46.37],[1,1.89,19.28],[2,1.88,114.38]],"batl":[[1,1.97,77.87],[2,2.02,522.31]],"ltp":1.94,"tv":12637.39,"id":8734382}]}]}
{"op":"mcm","clk":"4216791082","pt":1631555347004,"mc":[{"id":"1.187566733","rc":[{"trd":[[1.95,40.87]],"batb":[[2,1.88,20.35]],"batl":[[0,1.95,38.15]],"ltp":1.95,"tv":12678.26,"id":8734382},{"trd":[[2.04,38.93]],"batb":[[0,1.96,58.83],[1,1.95,1600.04],[2,1.94,72.65]],"batl":[[0,2.06,2.42]],"ltp":2.04,"tv":27422.32,"id":9323645}],"tv":40100.59}]}
{"op":"mcm","clk":"4216791201","pt":1631555348211,"mc":[{"id":"1.187566733","rc":[{"batb":[[1,1.91,24.21],[2,1.89,19.28]],"ltp":1.95,"tv":12678.26,"id":8734382},{"trd":[[2.06,25.99]],"batb":[[0,2.06,5.65],[1,1.96,58.83],[2,1.95,65.32]],"batl":[[0,2.12,19.75],[1,2.2,471.17],[2,2.32,5.61]],"ltp":2.06,"tv":27427.16,"id":9323645}],"tv":40105.43}]}
{"op":"mcm","clk":"4216791351","pt":1631555350206,"mc":[{"id":"1.187566733","rc":[{"trd":[[1.95,52.82]],"batb":[[0,1.94,287],[1,1.92,70.5],[2,1.91,24.21]],"batl":[[0,1.95,43.23]],"ltp":1.95,"tv":12690.21,"id":8734382},{"trd":[[2.04,50.35],[2.06,37.29]],"batb":[[0,1.93,49.76],[1,1.8,20],[2,1.66,41.12]],"ltp":2.04,"tv":27449.88,"id":9323645}],"tv":40140.1}]}
{"op":"mcm","clk":"4216791418","pt":1631555350895,"mc":[{"id":"1.187566733","rc":[{"batb":[[1,1.92,46.37],[2,1.77,256.02]],"batl":[[0,2.06,256.02],[1,1.97,0],[2,2.02,0]],"ltp":1.95,"tv":12690.21,"id":8734382},{"batb":[[0,1.8,20],[1,1.66,41.12],[2,1.32,12.7]],"batl":[[0,2.4,6.19],[1,2.52,5.51],[2,2.54,5.75]],"ltp":2.04,"tv":27449.88,"id":9323645}]}]}
{"op":"mcm","clk":"4216791531","pt":1631555352205,"mc":[{"id":"1.187566733","rc":[{"batb":[[0,1.77,256.02],[1,1.72,55.84],[2,1.68,40.28]],"ltp":1.95,"tv":12690.21,"id":8734382}]}]}
{"op":"mcm","clk":"4216791626","pt":1631555353204,"mc":[{"id":"1.187566733","rc":[{"batb":[[0,1.95,63.93],[1,1.94,28.92],[2,1.77,256.02]],"ltp":1.95,"tv":12690.21,"id":8734382},{"batb":[[0,1.96,1473.31],[1,1.94,54.29],[2,1.8,20]],"ltp":2.04,"tv":27449.88,"id":9323645}]}]}
{"op":"mcm","clk":"4216791678","pt":1631555353816,"mc":[{"id":"1.187566733","rc":[{"batb":[[0,1.77,256.02],[1,1.72,55.84],[2,1.68,159.49]],"batl":[[1,2.36,59.04],[2,2.38,46.21]],"ltp":1.95,"tv":12690.21,"id":8734382},{"batb":[[0,1.8,20],[1,1.66,41.12],[2,1.32,12.7]],"ltp":2.04,"tv":27449.88,"id":9323645}]}]}
{"op":"mcm","clk":"4216791770","pt":1631555354716,"mc":[{"id":"1.187566733","rc":[{"batb":[[0,1.95,44.91],[1,1.77,256.02],[2,1.72,55.84]],"ltp":1.95,"tv":12690.21,"id":8734382}]}]}
{"op":"mcm","clk":"4216792002","pt":1631555357119,"mc":[{"id":"1.187566733","rc":[{"batb":[[0,1.77,256.02],[1,1.72,55.84],[2,1.68,159.49]],"ltp":1.95,"tv":12690.21,"id":8734382}]}]}
{"op":"mcm","clk":"4216792102","pt":1631555358023,"mc":[{"id":"1.187566733","rc":[{"batb":[[1,1.73,55.13],[2,1.72,55.84]],"ltp":1.95,"tv":12690.21,"id":8734382},{"batl":[[0,2.38,6.75],[1,2.4,6.19],[2,2.52,5.51]],"ltp":2.04,"tv":27449.88,"id":9323645}]}]}
{"op":"mcm","clk":"4216792218","pt":1631555359119,"mc":[{"id":"1.187566733","rc":[{"batb":[[1,1.72,55.84],[2,1.68,159.49]],"batl":[[0,1.94,39],[1,2.06,256.02],[2,2.36,59.04]],"ltp":1.95,"tv":12690.21,"id":8734382},{"batl":[[0,2.4,6.19],[1,2.52,5.51],[2,2.54,5.75]],"ltp":2.04,"tv":27449.88,"id":9323645}]}]}
{"op":"mcm","clk":"4216792445","pt":1631555361231,"mc":[{"id":"1.187566733","rc":[{"batb":[[2,1.68,40.28]],"batl":[[2,2.36,0]],"ltp":1.95,"tv":12690.21,"id":8734382}]}]}
{"op":"mcm","clk":"4216792847","pt":1631555365017,"mc":[{"id":"1.187566733","rc":[{"trd":[[1.94,100.46]],"batl":[[0,2.04,70.42]],"ltp":1.94,"tv":12768.21,"id":8734382}],"tv":40218.1}]}
{"op":"mcm","clk":"4216792989","pt":1631555366529,"mc":[{"id":"1.187566733","rc":[{"batb":[[0,1.82,8.45],[1,1.8,8.66],[2,1.77,256.02]],"ltp":1.94,"tv":12768.21,"id":8734382}]}]}
{"op":"mcm","clk":"4216793127","pt":1631555368041,"mc":[{"id":"1.187566733","rc":[{"batb":[[0,1.95,80.44],[1,1.93,81.77],[2,1.82,8.45]],"batl":[[0,2.02,66.91],[1,2.04,70.42],[2,2.06,256.02]],"ltp":1.94,"tv":12768.21,"id":8734382},{"batl":[[0,2.06,3.61],[1,2.4,6.19],[2,2.52,5.51]],"ltp":2.04,"tv":27449.88,"id":9323645}]}]}
{"op":"mcm","clk":"4216793316","pt":1631555370447,"mc":[{"id":"1.187566733","rc":[{"batb":[[0,1.82,8.45],[1,1.8,8.66],[2,1.77,256.02]],"batl":[[0,2.06,256.02],[1,2.04,0],[2,2.06,0]],"ltp":1.94,"tv":12768.21,"id":8734382}]}]}
