{"op":"mcm","clk":"4230614278","pt":1631534811656,"mc":[{"id":"1.187557995","rc":[{"batl":[[1,1.35,244.46],[2,1.49,2.99]],"ltp":1.3,"tv":67668.05,"id":9342449},{"batb":[[0,3.55,100],[1,3.5,71.46],[2,2.2,42.67]],"ltp":4.1,"tv":8247.95,"id":9633869}]}]}
{"op":"mcm","clk":"4230614373","pt":1631534812649,"mc":[{"id":"1.187557995","rc":[{"trd":[[1.29,415.82]],"batb":[[2,1.26,699.89]],"batl":[[0,1.29,3254.21],[1,1.3,45.57],[2,1.31,90.44]],"ltp":1.29,"tv":68076.96,"id":9342449}],"tv":76324.92}]}
{"op":"mcm","clk":"4230614487","pt":1631534813656,"mc":[{"id":"1.187557995","rc":[{"batb":[[0,1.28,614.8],[1,1.27,552.57],[2,1.26,146.48]],"batl":[[1,1.35,244.46],[2,1.49,2.99]],"ltp":1.29,"tv":68076.96,"id":9342449},{"batl":[[0,4.6,6.36]],"ltp":4.1,"tv":8247.95,"id":9633869}]}]}
{"op":"mcm","clk":"4230614733","pt":1631534815442,"mc":[{"id":"1.187557995","rc":[{"batb":[[0,1.28,812.42]],"batl":[[2,1.37,59.5]],"ltp":1.29,"tv":68076.96,"id":9342449},{"batb":[[0,3.7,3.12],[1,3.55,100],[2,3.5,75.54]],"batl":[[0,4.5,2.37],[1,4.6,6.36],[2,4.9,4.15]],"ltp":4.1,"tv":8247.95,"id":9633869}]}]}
{"op":"mcm","clk":"4230614872","pt":1631534816648,"mc":[{"id":"1.187557995","rc":[{"trd":[[1.29,2945.92]],"batl":[[0,1.29,1949.03],[1,1.33,254.02],[2,1.34,325.02]],"ltp":1.29,"tv":70607.07,"id":9342449},{"trd":[[4.4,40.93]],"batl":[[0,4.6,6.36],[1,4.9,4.15],[2,4.9,0]],"ltp":4.4,"tv":8271.5,"id":9633869}],"tv":78878.57}]}
{"op":"mcm","clk":"4230615014","pt":1631534817662,"mc":[{"id":"1.187557995","rc":[{"trd":[[1.29,3066.78]],"batl":[[0,1.29,1888.6],[2,1.37,59.5]],"ltp":1.29,"tv":70727.93,"id":9342449},{"batl":[[0,4.5,20.38],[1,4.6,6.36],[2,4.9,4.15]],"ltp":4.4,"tv":8271.5,"id":9633869}],"tv":78999.43}]}
{"op":"mcm","clk":"4230615229","pt":1631534819339,"mc":[{"id":"1.187557995","rc":[{"trd":[[1.29,3161.61]],"batl":[[0,1.33,254.02],[1,1.37,59.5],[2,1.4,58.64]],"ltp":1.29,"tv":70822.76,"id":9342449},{"batl":[[0,4.6,6.36],[1,4.9,4.15],[2,4.9,0]],"ltp":4.4,"tv":8271.5,"id":9633869}],"tv":79094.26}]}
{"op":"mcm","clk":"4230615407","pt":1631534820663,"mc":[{"id":"1.187557995","rc":[{"trd":[[1.29,3659.21]],"batl":[[0,1.37,59.5],[1,1.4,58.64],[2,1.49,2.99]],"ltp":1.29,"tv":71320.36,"id":9342449}],"tv":79591.86}]}
{"op":"mcm","clk":"4230615538","pt":1631534821660,"mc":[{"id":"1.187557995","rc":[{"trd":[[1.29,3664.32]],"batb":[[0,1.29,14.87],[1,1.28,812.42],[2,1.27,552.57]],"batl":[[0,1.4,58.64],[1,1.49,2.99],[2,1.77,511.35]],"ltp":1.29,"tv":71325.46,"id":9342449},{"batb":[[0,3.55,100],[1,3.5,75.54],[2,2.2,42.67]],"ltp":4.4,"tv":8271.5,"id":9633869}],"tv":79596.96}]}
{"op":"mcm","clk":"4230615667","pt":1631534822664,"mc":[{"id":"1.187557995","rc":[{"batl":[[0,1.33,40.43],[1,1.4,58.64],[2,1.49,2.99]],"ltp":1.29,"tv":71325.46,"id":9342449},{"batl":[[0,4.4,20.38],[1,4.5,2.37],[2,4.6,6.36]],"ltp":4.4,"tv":8271.5,"id":9633869}]}]}
{"op":"mcm","clk":"4230615811","pt":1631534823658,"mc":[{"id":"1.187557995","rc":[{"batb":[[0,1.29,222.29]],"batl":[[0,1.4,58.64],[1,1.49,2.99],[2,1.77,511.35]],"ltp":1.29,"tv":71325.46,"id":9342449},{"batl":[[0,4.6,6.36],[1,4.9,4.15],[2,4.6,0]],"ltp":4.4,"tv":8271.5,"id":9633869}]}]}
{"op":"mcm","clk":"4230615933","pt":1631534824664,"mc":[{"id":"1.187557995","rc":[{"batb":[[0,1.29,24.87]],"batl":[[0,1.35,292.99],[1,1.36,308.44],[2,1.4,64.64]],"ltp":1.29,"tv":71325.46,"id":9342449},{"batb":[[0,3.55,103],[1,3.5,77.54]],"ltp":4.4,"tv":8271.5,"id":9633869}]}]}
{"op":"mcm","clk":"4230616226","pt":1631534826553,"mc":[{"id":"1.187557995","rc":[{"batb":[[1,1.28,803.42],[2,1.27,544.57]],"ltp":1.29,"tv":71325.46,"id":9342449},{"batl":[[0,4.5,2],[1,4.6,6.36],[2,4.9,4.15]],"ltp":4.4,"tv":8271.5,"id":9633869}]}]}
{"op":"mcm","clk":"4230616434","pt":1631534828179,"mc":[{"id":"1.187557995","rc":[{"batl":[[2,1.37,60.5]],"ltp":1.29,"tv":71325.46,"id":9342449},{"batb":[[0,3.7,3.12],[1,3.55,103],[2,3.5,77.54]],"ltp":4.4,"tv":8271.5,"id":9633869}]}]}
{"op":"mcm","clk":"4230616603","pt":1631534829689,"mc":[{"id":"1.187557995","rc":[{"batb":[[1,1.28,812.42]],"ltp":1.29,"tv":71325.46,"id":9342449},{"batb":[[1,3.55,100],[2,3.5,75.54]],"batl":[[0,4.5,4.29]],"ltp":4.4,"tv":8271.5,"id":9633869}]}]}
{"op":"mcm","clk":"4230616707","pt":1631534830586,"mc":[{"id":"1.187557995","rc":[{"batl":[[0,4.5,2]],"ltp":4.4,"tv":8271.5,"id":9633869}]}]}
{"op":"mcm","clk":"4230616806","pt":1631534831370,"mc":[{"id":"1.187557995","rc":[{"trd":[[1.35,1532.03]],"batb":[[0,1.33,1437.96],[1,1.32,1848.79],[2,1.31,1777.47]],"batl":[[0,1.35,276.45]],"ltp":1.35,"tv":71342.0,"id":9342449},{"trd":[[3.85,104.95]],"batb":[[1,3.55,396.3],[2,3.5,363.13]],"batl":[[0,4.2,7.23],[1,4.5,2],[2,4.6,6.36]],"ltp":3.85,"tv":8277.3,"id":9633869}],"tv":79619.3}]}
{"op":"mcm","clk":"4230616952","pt":1631534832679,"mc":[{"id":"1.187557995","rc":[{"trd":[[1.35,2030.95]],"batb":[[1,1.32,1827.18],[2,1.31,1503.44]],"batl":[[0,1.36,308.44],[1,1.37,60.5],[2,1.38,15]],"ltp":1.35,"tv":71840.92,"id":9342449},{"batl":[[0,4.2,15.61]],"ltp":3.85,"tv":8277.3,"id":9633869}],"tv":80118.22}]}
{"op":"mcm","clk":"4230617070","pt":1631534833675,"mc":[{"id":"1.187557995","rc":[{"batb":[[0,1.35,8],[1,1.34,7],[2,1.33,1437.96]],"ltp":1.35,"tv":71840.92,"id":9342449},{"batl":[[0,3.9,3],[1,4.2,15.61],[2,4.4,3]],"ltp":3.85,"tv":8277.3,"id":9633869}]}]}
{"op":"mcm","clk":"4230617181","pt":1631534834661,"mc":[{"id":"1.187557995","rc":[{"trd":[[1.34,7511.98],[1.35,2046.95]],"batb":[[0,1.33,1437.96],[1,1.32,1827.18],[2,1.31,1503.44]],"batl":[[0,1.34,166.13],[1,1.36,308.44],[2,1.37,60.5]],"ltp":1.34,"tv":71879.65,"id":9342449},{"trd":[[3.9,74.83]],"batl":[[0,4.2,15.61],[1,4.6,4.36],[2,4.9,4.15]],"ltp":3.9,"tv":8280.3,"id":9633869}],"tv":80159.95}]}
{"op":"mcm","clk":"4230617306","pt":1631534835699,"mc":[{"id":"1.187557995","rc":[{"batb":[[0,1.33,4967.61],[1,1.32,1899.86],[2,1.31,1395.68]],"batl":[[0,1.34,559.88],[1,1.35,314.14],[2,1.36,712.59]],"ltp":1.34,"tv":71879.65,"id":9342449},{"batb":[[0,3.75,13.17],[1,3.7,3.12],[2,3.55,396.3]],"batl":[[0,4.1,16.07],[1,4.2,15.61],[2,4.6,4.36]],"ltp":3.9,"tv":8280.3,"id":9633869}]}]}
{"op":"mcm","clk":"4230617424","pt":1631534836701,"mc":[{"id":"1.187557995","rc":[{"trd":[[1.34,7859.23]],"batl":[[0,1.34,386.24]],"ltp":1.34,"tv":72226.91,"id":9342449},{"batb":[[2,3.6,23.07]],"batl":[[1,4.2,7.23]],"ltp":3.9,"tv":8280.3,"id":9633869}],"tv":80507.21}]}
{"op":"mcm","clk":"4230617537","pt":1631534837700,"mc":[{"id":"1.187557995","rc":[{"batl":[[0,1.34,653.24]],"ltp":1.34,"tv":72226.91,"id":9342449},{"batl":[[2,4.5,2.55]],"ltp":3.9,"tv":8280.3,"id":9633869}]}]}
{"op":"mcm","clk":"4230617640","pt":1631534838699,"mc":[{"id":"1.187557995","rc":[{"batb":[[0,1.33,5006.37]],"ltp":1.34,"tv":72226.91,"id":9342449}]}]}
{"op":"mcm","clk":"4230617727","pt":1631534839633,"mc":[{"id":"1.187557995","rc":[{"batb":[[1,1.32,2005.92]],"ltp":1.34,"tv":72226.91,"id":9342449},{"batl":[[0,4.1,24.58]],"ltp":3.9,"tv":8280.3,"id":9633869}]}]}
{"op":"mcm","clk":"4230617872","pt":1631534840988,"mc":[{"id":"1.187557995","rc":[{"batb":[[0,1.33,4986.08],[1,1.32,1933.24]],"batl":[[2,1.36,653.61]],"ltp":1.34,"tv":72226.91,"id":9342449}]}]}
{"op":"mcm","clk":"4230618014","pt":1631534842298,"mc":[{"id":"1.187557995","rc":[{"batl":[[0,1.34,723.19],[1,1.35,246.74]],"ltp":1.34,"tv":72226.91,"id":9342449}]}]}
{"op":"mcm","clk":"4230618129","pt":1631534843512,"mc":[{"id":"1.187557995","rc":[{"batb":[[0,1.33,65.13],[1,1.32,106.06],[2,1.3,189.1]],"batl":[[1,1.38,15],[2,1.44,54.58]],"ltp":1.34,"tv":72226.91,"id":9342449},{"batb":[[0,3.6,23.07],[1,3.55,100],[2,3.45,3]],"batl":[[0,4.1,8.51],[1,4.5,2.55],[2,4.6,4.36]],"ltp":3.9,"tv":8280.3,"id":9633869}]}]}
{"op":"mcm","clk":"4230618234","pt":1631534844562,"mc":[{"id":"1.187557995","rc":[{"batb":[[0,1.3,189.1],[1,1.29,412.7],[2,1.28,133.91]],"batl":[[0,1.44,54.58],[1,1.49,50.49],[2,1.77,511.35]],"ltp":1.34,"tv":72226.91,"id":9342449},{"batb":[[0,3.45,3],[1,3.4,3],[2,3.25,3.57]],"batl":[[0,4.5,2.55],[1,4.6,4.36],[2,4.9,4.15]],"ltp":3.9,"tv":8280.3,"id":9633869}]}]}
{"op":"mcm","clk":"4230618302","pt":1631534844974,"mc":[{"id":"1.187557995","rc":[{"batl":[[0,1.49,50.49],[1,1.77,511.35],[2,1.82,2.89]],"ltp":1.34,"tv":72226.91,"id":9342449},{"batb":[[0,3,5],[1,2.96,44.43],[2,2.2,42.67]],"ltp":3.9,"tv":8280.3,"id":9633869}]}]}
{"op":"mcm","clk":"4230618492","pt":1631534846695,"mc":[{"id":"1.187557995","rc":[{"batb":[[1,1.29,175.36],[2,1.28,470.06]],"batl":[[0,1.45,292.06],[1,1.46,221.04],[2,1.49,50.49]],"ltp":1.34,"tv":72226.91,"id":9342449},{"batb":[[0,3,109.01],[1,2.2,42.67],[2,2,11.88]],"ltp":3.9,"tv":8280.3,"id":9633869}]}]}
{"op":"mcm","clk":"4230618673","pt":1631534848511,"mc":[{"id":"1.187557995","rc":[{"batl":[[2,1.49,56.49]],"ltp":1.34,"tv":72226.91,"id":9342449},{"batb":[[0,3,113.01],[1,2.98,3],[2,2.2,42.67]],"ltp":3.9,"tv":8280.3,"id":9633869}]}]}
{"op":"mcm","clk":"4230619013","pt":1631534851617,"mc":[{"id":"1.187557995","rc":[{"batl":[[0,1.44,235.95],[1,1.45,292.06],[2,1.46,221.04]],"ltp":1.34,"tv":72226.91,"id":9342449},{"batb":[[0,3.05,100],[1,3,113.01],[2,2.98,3]],"ltp":3.9,"tv":8280.3,"id":9633869}]}]}
{"op":"mcm","clk":"4230619027","pt":1631534851722,"mc":[{"id":"1.187557995","rc":[{"batl":[[0,1.44,293.28]],"ltp":1.34,"tv":72226.91,"id":9342449},{"batb":[[0,3.25,4.09],[1,3.05,100],[2,3,113.01]],"ltp":3.9,"tv":8280.3,"id":9633869}]}]}
{"op":"mcm","clk":"4230619761","pt":1631534858324,"mc":[{"id":"1.187557995","rc":[{"batl":[[0,1.44,235.95],[1,1.49,8.99],[2,1.77,511.35]],"ltp":1.34,"tv":72226.91,"id":9342449},{"batb":[[0,3.05,100],[1,3,113.01],[2,2.98,3]],"ltp":3.9,"tv":8280.3,"id":9633869}]}]}
{"op":"mcm","clk":"4230619849","pt":1631534859221,"mc":[{"id":"1.187557995","rc":[{"batb":[[0,1.28,470.06],[1,1.27,419.8],[2,1.26,619.68]],"batl":[[0,1.49,8.99],[1,1.77,511.35],[2,1.82,2.89]],"ltp":1.34,"tv":72226.91,"id":9342449},{"batl":[[0,4.6,4.36],[1,4.9,4.15],[2,4.9,0]],"ltp":3.9,"tv":8280.3,"id":9633869}]}]}
{"op":"mcm","clk":"4230620014","pt":1631534860629,"mc":[{"id":"1.187557995","rc":[{"batl":[[0,1.29,3237.69],[1,1.31,2919.84],[2,1.32,2833.96]],"ltp":1.34,"tv":72226.91,"id":9342449},{"batl":[[2,5,765]],"ltp":3.9,"tv":8280.3,"id":9633869}]}]}
{"op":"mcm","clk":"4230620123","pt":1631534861630,"mc":[{"id":"1.187557995","rc":[{"trd":[[1.29,3681.82]],"batl":[[0,1.29,252.37],[1,1.3,388.62],[2,1.31,1459.92]],"ltp":1.29,"tv":72244.41,"id":9342449},{"trd":[[4.4,46.06]],"batb":[[0,3.5,413.46],[1,3.05,100],[2,3,113.01]],"batl":[[2,5,210.37]],"ltp":4.4,"tv":8285.43,"id":9633869}],"tv":80529.84}]}
{"op":"mcm","clk":"4230620216","pt":1631534862434,"mc":[{"id":"1.187557995","rc":[{"batb":[[2,1.26,737.34]],"ltp":1.29,"tv":72244.41,"id":9342449},{"batb":[[0,4.1,115.33],[1,3.9,55.56],[2,3.1,3]],"batl":[[1,4.9,11.74]],"ltp":4.4,"tv":8285.43,"id":9633869}]}]}
{"op":"mcm","clk":"4230620292","pt":1631534863128,"mc":[{"id":"1.187557995","rc":[{"batb":[[2,1.26,619.68]],"ltp":1.29,"tv":72244.41,"id":9342449},{"batb":[[0,4.1,95.98]],"batl":[[1,4.9,4.15]],"ltp":4.4,"tv":8285.43,"id":9633869}]}]}
{"op":"mcm","clk":"4230620572","pt":1631534865642,"mc":[{"id":"1.187557995","rc":[{"batb":[[0,1.28,880.28],[1,1.27,491.55]],"batl":[[0,1.29,1216.3],[1,1.3,464.08]],"ltp":1.29,"tv":72244.41,"id":9342449}]}]}
{"op":"mcm","clk":"4230620664","pt":1631534866537,"mc":[{"id":"1.187557995","rc":[{"batb":[[1,1.27,3015.37]],"ltp":1.29,"tv":72244.41,"id":9342449},{"batb":[[0,4.2,25.84],[1,4.1,115.33],[2,3.9,55.56]],"batl":[[1,4.9,11.74]],"ltp":4.4,"tv":8285.43,"id":9633869}]}]}
{"op":"mcm","clk":"4230620716","pt":1631534867117,"mc":[{"id":"1.187557995","rc":[{"batb":[[0,4.1,115.33],[1,3.9,55.56],[2,3.1,3]],"ltp":4.4,"tv":8285.43,"id":9633869}]}]}
{"op":"mcm","clk":"4230620884","pt":1631534868641,"mc":[{"id":"1.187557995","rc":[{"batl":[[0,1.29,1427.3]],"ltp":1.29,"tv":72244.41,"id":9342449},{"batb":[[1,3.9,58.42]],"ltp":4.4,"tv":8285.43,"id":9633869}]}]}
{"op":"mcm","clk":"4230620993","pt":1631534869426,"mc":[{"id":"1.187557995","rc":[{"trd":[[1.29,3871.16]],"batl":[[0,1.29,1237.96],[2,1.31,1474.92]],"ltp":1.29,"tv":72433.75,"id":9342449},{"trd":[[4.4,101.56]],"ltp":4.4,"tv":8340.93,"id":9633869}],"tv":80774.68}]}
{"op":"mcm","clk":"4230621094","pt":1631534870325,"mc":[{"id":"1.187557995","rc":[{"batl":[[0,1.29,1174.93]],"ltp":1.29,"tv":72433.75,"id":9342449}]}]}
{"op":"mcm","clk":"4230621157","pt":1631534871035,"mc":[{"id":"1.187557995","rc":[{"batb":[[1,1.27,2943.62]],"batl":[[1,1.3,388.62]],"ltp":1.29,"tv":72433.75,"id":9342449}]}]}
{"op":"mcm","clk":"4230621328","pt":1631534872655,"mc":[{"id":"1.187557995","rc":[{"batb":[[0,1.28,955.09]],"batl":[[0,1.29,1250.28]],"ltp":1.29,"tv":72433.75,"id":9342449}]}]}
{"op":"mcm","clk":"4230621387","pt":1631534873232,"mc":[{"id":"1.187557995","rc":[{"batb":[[0,1.28,880.28],[1,1.27,3057.29]],"batl":[[0,1.29,1174.93],[1,1.3,540.54],[2,1.31,1841.93]],"ltp":1.29,"tv":72433.75,"id":9342449},{"batb":[[0,4.2,25.84],[1,4.1,115.33],[2,3.9,58.42]],"ltp":4.4,"tv":8340.93,"id":9633869}]}]}
{"op":"mcm","clk":"4230621617","pt":1631534875372,"mc":[{"id":"1.187557995","rc":[{"batb":[[0,1.28,801.38]],"batl":[[0,1.29,696.75]],"ltp":1.29,"tv":72433.75,"id":9342449},{"batb":[[1,4.1,95.98]],"ltp":4.4,"tv":8340.93,"id":9633869}]}]}
{"op":"mcm","clk":"4230621978","pt":1631534878652,"mc":[{"id":"1.187557995","rc":[{"trd":[[1.28,126.89]],"batb":[[0,1.28,773.07]],"batl":[[1,1.3,968.03]],"ltp":1.28,"tv":72490.37,"id":9342449},{"batb":[[0,4.2,18.75],[2,4,2]],"ltp":4.4,"tv":8340.93,"id":9633869}],"tv":80831.3}]}
{"op":"mcm","clk":"4230622185","pt":1631534880698,"mc":[{"id":"1.187557995","rc":[{"trd":[[1.28,1538.86]],"batb":[[0,1.27,2719.69],[1,1.26,146.48],[2,1.25,120]],"batl":[[1,1.3,427.49],[2,1.31,1474.92]],"ltp":1.28,"tv":73902.33,"id":9342449}],"tv":82243.26}]}
{"op":"mcm","clk":"4230622381","pt":1631534882684,"mc":[{"id":"1.187557995","rc":[{"trd":[[1.27,25.3]],"batb":[[0,1.27,2711.17]],"ltp":1.27,"tv":73919.37,"id":9342449},{"batb":[[0,4.3,25.84],[1,4.2,18.75],[2,4.1,95.98]],"ltp":4.4,"tv":8340.93,"id":9633869}],"tv":82260.3}]}
{"op":"mcm","clk":"4230622410","pt":1631534882946,"mc":[{"id":"1.187557995","rc":[{"batb":[[0,4.2,18.75],[1,4.1,95.98],[2,4,2]],"ltp":4.4,"tv":8340.93,"id":9633869}]}]}
{"op":"mcm","clk":"4230622516","pt":1631534883952,"mc":[{"id":"1.187557995","rc":[{"batb":[[2,1.25,213.73]],"ltp":1.27,"tv":73919.37,"id":9342449},{"batl":[[2,5,212.58]],"ltp":4.4,"tv":8340.93,"id":9633869}]}]}
{"op":"mcm","clk":"4230622756","pt":1631534886569,"mc":[{"id":"1.187557995","rc":[{"batb":[[0,1.27,187.35]],"ltp":1.27,"tv":73919.37,"id":9342449}]}]}
{"op":"mcm","clk":"4230622787","pt":1631534886884,"mc":[{"id":"1.187557995","rc":[{"batb":[[2,3.9,58.42]],"ltp":4.4,"tv":8340.93,"id":9633869}]}]}
{"op":"mcm","clk":"4230622882","pt":1631534887880,"mc":[{"id":"1.187557995","rc":[{"batb":[[0,1.27,524.95],[1,1.26,619.75]],"batl":[[1,1.3,968.03],[2,1.31,1841.93]],"ltp":1.27,"tv":73919.37,"id":9342449}]}]}
{"op":"mcm","clk":"4230623081","pt":1631534889653,"mc":[{"id":"1.187557995","rc":[{"batb":[[0,1.27,187.35],[1,1.25,213.73],[2,1.24,484.56]],"batl":[[0,1.29,211],[1,1.31,15],[2,1.34,64.25]],"ltp":1.27,"tv":73919.37,"id":9342449},{"batb":[[0,4.3,16.08],[1,4.2,18.75]],"batl":[[0,4.9,7.59],[1,5,2.21],[2,5.2,2.03]],"ltp":4.4,"tv":8340.93,"id":9633869}]}]}
{"op":"mcm","clk":"4230623182","pt":1631534890589,"mc":[{"id":"1.187557995","rc":[{"batb":[[1,1.25,93.73]],"batl":[[0,1.34,64.25],[1,1.49,2.99],[2,1.77,511.35]],"ltp":1.27,"tv":73919.37,"id":9342449},{"batb":[[0,3.9,58.42],[1,2.2,42.67],[2,2,11.88]],"batl":[[0,5,2.21],[1,5.2,2.03],[2,5.4,2.04]],"ltp":4.4,"tv":8340.93,"id":9633869}]}]}
{"op":"mcm","clk":"4230623334","pt":1631534892302,"mc":[{"id":"1.187557995","rc":[{"batb":[[2,1.24,730.55]],"batl":[[0,1.33,407.68],[1,1.34,391.94],[2,1.49,2.99]],"ltp":1.27,"tv":73919.37,"id":9342449}]}]}
{"op":"mcm","clk":"4230623465","pt":1631534893706,"mc":[{"id":"1.187557995","rc":[{"batb":[[2,1.24,339.26]],"batl":[[1,1.34,400.94]],"ltp":1.27,"tv":73919.37,"id":9342449},{"batb":[[0,4,104.27],[1,3.9,5.86],[2,3.85,3]],"ltp":4.4,"tv":8340.93,"id":9633869}]}]}
{"op":"mcm","clk":"4230623532","pt":1631534894502,"mc":[{"id":"1.187557995","rc":[{"batb":[[2,1.24,93.27]],"ltp":1.27,"tv":73919.37,"id":9342449}]}]}
{"op":"mcm","clk":"4230623602","pt":1631534895083,"mc":[{"id":"1.187557995","rc":[{"batl":[[0,1.32,198.47],[1,1.33,407.68],[2,1.34,336.69]],"ltp":1.27,"tv":73919.37,"id":9342449}]}]}
{"op":"mcm","clk":"4230623710","pt":1631534896182,"mc":[{"id":"1.187557995","rc":[{"batl":[[0,1.33,407.68],[1,1.34,327.69],[2,1.49,2.99]],"ltp":1.27,"tv":73919.37,"id":9342449},{"batb":[[1,3.9,2.86],[2,2.2,42.67]],"ltp":4.4,"tv":8340.93,"id":9633869}]}]}
{"op":"mcm","clk":"4230623862","pt":1631534897711,"mc":[{"id":"1.187557995","rc":[{"batb":[[0,1.3,381.13],[1,1.29,1897.41],[2,1.28,1438.96]],"ltp":1.27,"tv":73919.37,"id":9342449},{"trd":[[4,58.33]],"batb":[[0,4,98.85],[1,3.9,272.58],[2,3.85,475.96]],"batl":[[0,4.5,2],[1,5,2.21],[2,5.2,2.03]],"ltp":4.0,"tv":8351.75,"id":9633869}],"tv":82271.13}]}
{"op":"mcm","clk":"4230623943","pt":1631534898501,"mc":[{"id":"1.187557995","rc":[{"batb":[[1,1.29,2214.73],[2,1.28,2929.04]],"batl":[[2,1.35,15]],"ltp":1.27,"tv":73919.37,"id":9342449},{"batb":[[1,3.95,100],[2,3.9,293.26]],"batl":[[0,4.5,10.01]],"ltp":4.0,"tv":8351.75,"id":9633869}]}]}
{"op":"mcm","clk":"4230624045","pt":1631534899604,"mc":[{"id":"1.187557995","rc":[{"batb":[[0,4,113.09]],"ltp":4.0,"tv":8351.75,"id":9633869}]}]}
{"op":"mcm","clk":"4230624125","pt":1631534900396,"mc":[{"id":"1.187557995","rc":[{"batb":[[2,1.28,3165.84]],"batl":[[0,1.33,377.94]],"ltp":1.27,"tv":73919.37,"id":9342449}]}]}
{"op":"mcm","clk":"4230624244","pt":1631534901500,"mc":[{"id":"1.187557995","rc":[{"batb":[[0,1.31,61.12],[1,1.3,381.13],[2,1.29,2214.73]],"batl":[[0,1.32,824.73],[1,1.33,519.94],[2,1.34,327.69]],"ltp":1.27,"tv":73919.37,"id":9342449}]}]}
{"op":"mcm","clk":"4230624368","pt":1631534902714,"mc":[{"id":"1.187557995","rc":[{"batb":[[1,1.3,465.97]],"ltp":1.27,"tv":73919.37,"id":9342449}]}]}
{"op":"mcm","clk":"4230624448","pt":1631534903501,"mc":[{"id":"1.187557995","rc":[{"batb":[[1,1.3,2768.01]],"ltp":1.27,"tv":73919.37,"id":9342449},{"batl":[[0,4.4,14.83],[1,4.5,10.01],[2,5,2.21]],"ltp":4.0,"tv":8351.75,"id":9633869}]}]}
{"op":"mcm","clk":"4230624521","pt":1631534904173,"mc":[{"id":"1.187557995","rc":[{"batl":[[1,1.33,595.44],[2,1.34,394.94]],"ltp":1.27,"tv":73919.37,"id":9342449},{"batb":[[0,4,116.27]],"batl":[[2,4.8,2.22]],"ltp":4.0,"tv":8351.75,"id":9633869}]}]}
{"op":"mcm","clk":"4230624656","pt":1631534905585,"mc":[{"id":"1.187557995","rc":[{"batb":[[2,1.29,2326.14]],"ltp":1.27,"tv":73919.37,"id":9342449}]}]}
{"op":"mcm","clk":"4230625106","pt":1631534909404,"mc":[{"id":"1.187557995","rc":[{"trd":[[1.32,427.6]],"batb":[[0,1.3,2776.95],[1,1.29,2326.14],[2,1.28,1912.55]],"batl":[[0,1.31,333.96],[1,1.32,885.82],[2,1.33,595.44]],"ltp":1.32,"tv":73926.61,"id":9342449}],"tv":82278.36}]}
{"op":"mcm","clk":"4230625143","pt":1631534909823,"mc":[{"id":"1.187557995","rc":[{"batb":[[0,1.3,2728.08]],"batl":[[1,1.32,429.02]],"ltp":1.32,"tv":73926.61,"id":9342449}]}]}
{"op":"mcm","clk":"4230625330","pt":1631534911516,"mc":[{"id":"1.187557995","rc":[{"batb":[[0,1.3,2671.39]],"batl":[[0,1.32,361.19],[1,1.33,595.44],[2,1.34,394.94]],"ltp":1.32,"tv":73926.61,"id":9342449}]}]}
{"op":"mcm","clk":"4230625538","pt":1631534913398,"mc":[{"id":"1.187557995","rc":[{"batb":[[0,1.3,399.95],[2,1.28,2008.71]],"ltp":1.32,"tv":73926.61,"id":9342449},{"batl":[[2,4.6,2.21]],"ltp":4.0,"tv":8351.75,"id":9633869}]}]}
{"op":"mcm","clk":"4230625765","pt":1631534915600,"mc":[{"id":"1.187557995","rc":[{"batb":[[0,1.29,111.41],[1,1.28,569.75],[2,1.27,275.22]],"batl":[[0,1.33,497.63],[1,1.34,67.25],[2,1.35,78.5]],"ltp":1.32,"tv":73926.61,"id":9342449},{"batb":[[0,3.95,100],[1,3.9,23.54],[2,3.85,2.97]],"batl":[[0,4.5,8.01],[1,4.6,2.21],[2,4.8,2.22]],"ltp":4.0,"tv":8351.75,"id":9633869}]}]}
{"op":"mcm","clk":"4230625875","pt":1631534916603,"mc":[{"id":"1.187557995","rc":[{"batb":[[0,1.28,569.75],[1,1.27,275.22],[2,1.26,359.41]],"batl":[[0,1.34,67.25],[1,1.35,63.5],[2,1.49,2.99]],"ltp":1.32,"tv":73926.61,"id":9342449},{"batb":[[1,3.9,2.86]],"batl":[[0,4.6,2.21],[1,4.8,2.22],[2,5,2.21]],"ltp":4.0,"tv":8351.75,"id":9633869}]}]}
{"op":"mcm","clk":"4230626076","pt":1631534918632,"mc":[{"id":"1.187557995","rc":[{"batl":[[0,1.33,76.5],[1,1.34,67.25],[2,1.35,63.5]],"ltp":1.32,"tv":73926.61,"id":9342449},{"batb":[[0,4,2.93],[1,3.95,100],[2,3.9,2.86]],"ltp":4.0,"tv":8351.75,"id":9633869}]}]}
{"op":"mcm","clk":"4230626154","pt":1631534919319,"mc":[{"id":"1.187557995","rc":[{"batl":[[0,1.34,67.25],[1,1.35,63.5],[2,1.36,260.1]],"ltp":1.32,"tv":73926.61,"id":9342449},{"batb":[[0,3.95,100],[1,3.9,2.86],[2,3.85,2.97]],"ltp":4.0,"tv":8351.75,"id":9633869}]}]}
{"op":"mcm","clk":"4230626397","pt":1631534921612,"mc":[{"id":"1.187557995","rc":[{"trd":[[1.33,1710.61]],"batb":[[0,1.33,2941.37],[1,1.32,718.33],[2,1.31,181.1]],"ltp":1.33,"tv":74360.98,"id":9342449},{"trd":[[3.95,28.68]],"batb":[[0,3.95,94.29]],"batl":[[0,4.3,2],[1,4.6,2.21],[2,4.8,2.22]],"ltp":3.95,"tv":8363.17,"id":9633869}],"tv":82724.16}]}
{"op":"mcm","clk":"4230626493","pt":1631534922656,"mc":[{"id":"1.187557995","rc":[{"batb":[[1,1.32,1108.07]],"ltp":1.33,"tv":74360.98,"id":9342449},{"batl":[[0,4.2,8.38],[1,4.3,2],[2,4.5,11.05]],"ltp":3.95,"tv":8363.17,"id":9633869}]}]}
{"op":"mcm","clk":"4230626542","pt":1631534923023,"mc":[{"id":"1.187557995","rc":[{"batl":[[2,4.6,2.21]],"ltp":3.95,"tv":8363.17,"id":9633869}]}]}
{"op":"mcm","clk":"4230626798","pt":1631534925621,"mc":[{"id":"1.187557995","rc":[{"trd":[[1.34,8290.52]],"batb":[[0,1.33,2996.96]],"batl":[[0,1.34,313.93],[1,1.35,486.89]],"ltp":1.34,"tv":74792.27,"id":9342449},{"trd":[[3.95,216.88]],"batb":[[0,3.9,3.05],[1,3.85,2.97],[2,3.8,59.83]],"ltp":3.95,"tv":8551.37,"id":9633869}],"tv":83343.65}]}
{"op":"mcm","clk":"4230626896","pt":1631534926518,"mc":[{"id":"1.187557995","rc":[{"batb":[[0,1.33,3032.86],[1,1.32,1173.9],[2,1.31,378.71]],"ltp":1.34,"tv":74792.27,"id":9342449},{"batl":[[0,4.1,16.85],[1,4.2,8.38],[2,4.3,2]],"ltp":3.95,"tv":8551.37,"id":9633869}]}]}
{"op":"mcm","clk":"4230626955","pt":1631534927149,"mc":[{"id":"1.187557995","rc":[{"batb":[[2,1.31,576.33]],"ltp":1.34,"tv":74792.27,"id":9342449}]}]}
{"op":"mcm","clk":"4230627084","pt":1631534928347,"mc":[{"id":"1.187557995","rc":[{"batl":[[0,1.34,628.93],[2,1.36,331.17]],"ltp":1.34,"tv":74792.27,"id":9342449}]}]}
{"op":"mcm","clk":"4230627174","pt":1631534929343,"mc":[{"id":"1.187557995","rc":[{"trd":[[1.34,8918.01]],"batb":[[0,1.33,6130.27]],"batl":[[0,1.34,315.15]],"ltp":1.34,"tv":75419.76,"id":9342449}],"tv":83971.14}]}
{"op":"mcm","clk":"4230627414","pt":1631534931513,"mc":[{"id":"1.187557995","rc":[{"batb":[[1,1.32,1108.07]],"ltp":1.34,"tv":75419.76,"id":9342449},{"batl":[[1,4.3,2],[2,4.5,2.21]],"ltp":3.95,"tv":8551.37,"id":9633869}]}]}
{"op":"mcm","clk":"4230627523","pt":1631534932560,"mc":[{"id":"1.187557995","rc":[{"trd":[[1.34,9548.28]],"batb":[[0,1.33,6094.37]],"batl":[[0,1.35,486.91],[1,1.36,331.17],[2,1.37,294.52]],"ltp":1.34,"tv":76050.03,"id":9342449},{"batl":[[0,4.3,2],[1,4.5,2.21],[2,4.6,2.21]],"ltp":3.95,"tv":8551.37,"id":9633869}],"tv":84601.4}]}
{"op":"mcm","clk":"4230627628","pt":1631534933448,"mc":[{"id":"1.187557995","rc":[{"batb":[[0,1.33,6240.6]],"batl":[[0,1.34,55.77],[1,1.35,408.09],[2,1.36,331.17]],"ltp":1.34,"tv":76050.03,"id":9342449}]}]}
{"op":"mcm","clk":"4230627835","pt":1631534935338,"mc":[{"id":"1.187557995","rc":[{"batb":[[0,1.33,6038.78]],"batl":[[0,1.35,408.11],[1,1.36,331.17],[2,1.37,294.52]],"ltp":1.34,"tv":76050.03,"id":9342449},{"batl":[[0,4.1,8.51],[1,4.3,2],[2,4.5,2.21]],"ltp":3.95,"tv":8551.37,"id":9633869}]}]}
{"op":"mcm","clk":"4230627990","pt":1631534936637,"mc":[{"id":"1.187557995","rc":[{"batb":[[0,1.33,6173.33]],"ltp":1.34,"tv":76050.03,"id":9342449}]}]}
{"op":"mcm","clk":"4230628062","pt":1631534937261,"mc":[{"id":"1.187557995","rc":[{"batb":[[0,1.33,3075.92]],"batl":[[0,1.35,408.09]],"ltp":1.34,"tv":76050.03,"id":9342449}]}]}
{"op":"mcm","clk":"4230628398","pt":1631534940363,"mc":[{"id":"1.187557995","rc":[{"batb":[[0,1.32,106.06],[1,1.31,395.23],[2,1.29,404.05]],"batl":[[0,1.35,127],[1,1.36,71.07],[2,1.39,15]],"ltp":1.34,"tv":76050.03,"id":9342449},{"batb":[[0,3.75,2.9],[1,3.65,66.28],[2,3.6,23.07]],"batl":[[1,4.5,2.21],[2,4.6,2.21]],"ltp":3.95,"tv":8551.37,"id":9633869}]}]}
{"op":"mcm","clk":"4230628539","pt":1631534941650,"mc":[{"id":"1.187557995","rc":[{"batb":[[0,1.31,395.23],[1,1.29,404.05],[2,1.28,96.16]],"batl":[[0,1.36,318.09],[1,1.49,2.99],[2,1.77,511.35]],"ltp":1.34,"tv":76050.03,"id":9342449},{"batb":[[2,3.45,2]],"batl":[[0,4.2,16.85]],"ltp":3.95,"tv":8551.37,"id":9633869}]}]}
{"op":"mcm","clk":"4230628569","pt":1631534941857,"mc":[{"id":"1.187557995","rc":[{"batl":[[0,4.5,2.21],[1,4.6,2.21],[2,4.8,2.22]],"ltp":3.95,"tv":8551.37,"id":9633869}]}]}
{"op":"mcm","clk":"4230628749","pt":1631534943641,"mc":[{"id":"1.187557995","rc":[{"batb":[[0,1.31,487.02],[1,1.3,424.15],[2,1.29,816.46]],"batl":[[0,1.35,73.7],[1,1.36,318.09],[2,1.39,302.3]],"ltp":1.34,"tv":76050.03,"id":9342449},{"batb":[[0,3.85,3.16],[1,3.75,2.71],[2,3.65,66.28]],"batl":[[0,4.3,2.75],[1,4.5,2.21],[2,4.6,2.21]],"ltp":3.95,"tv":8551.37,"id":9633869}]}]}
{"op":"mcm","clk":"4230628846","pt":1631534944473,"mc":[{"id":"1.187557995","rc":[{"batl":[[0,1.36,326.09],[1,1.39,302.3],[2,1.4,265.28]],"ltp":1.34,"tv":76050.03,"id":9342449},{"batb":[[0,3.75,5.9],[1,3.7,3]],"ltp":3.95,"tv":8551.37,"id":9633869}]}]}
{"op":"mcm","clk":"4230629174","pt":1631534947357,"mc":[{"id":"1.187557995","rc":[{"batl":[[0,1.36,79.07]],"ltp":1.34,"tv":76050.03,"id":9342449}]}]}
{"op":"mcm","clk":"4230629588","pt":1631534950673,"mc":[{"id":"1.187557995","rc":[{"batb":[[0,1.31,91.79]],"batl":[[1,1.49,2.99],[2,1.77,511.35]],"ltp":1.34,"tv":76050.03,"id":9342449}]}]}
{"op":"mcm","clk":"4230629639","pt":1631534951039,"mc":[{"id":"1.187557995","rc":[{"batb":[[0,1.3,424.15],[1,1.29,816.46],[2,1.28,96.16]],"ltp":1.34,"tv":76050.03,"id":9342449},{"batl":[[0,4.5,2.21],[1,4.6,2.21],[2,4.8,2.22]],"ltp":3.95,"tv":8551.37,"id":9633869}]}]}
{"op":"mcm","clk":"4230629812","pt":1631534952665,"mc":[{"id":"1.187557995","rc":[{"batb":[[2,1.28,917.94]],"batl":[[0,1.33,321.1],[1,1.34,328.19],[2,1.36,71.07]],"ltp":1.34,"tv":76050.03,"id":9342449},{"batb":[[0,3.9,490.59],[1,3.85,475.96],[2,3.8,475.96]],"ltp":3.95,"tv":8551.37,"id":9633869}]}]}
{"op":"mcm","clk":"4230629920","pt":1631534953549,"mc":[{"id":"1.187557995","rc":[{"trd":[[1.33,1727.09]],"batl":[[0,1.33,304.62]],"ltp":1.33,"tv":76066.51,"id":9342449},{"trd":[[4,63.81]],"batb":[[0,4,103.76],[1,3.9,490.59],[2,3.85,475.96]],"ltp":4.0,"tv":8556.85,"id":9633869}],"tv":84623.36}]}
{"op":"mcm","clk":"4230630045","pt":1631534954384,"mc":[{"id":"1.187557995","rc":[{"batb":[[1,1.29,927.87]],"batl":[[2,1.35,15]],"ltp":1.33,"tv":76066.51,"id":9342449},{"batb":[[1,3.9,511.27]],"batl":[[0,4.5,10.22]],"ltp":4.0,"tv":8556.85,"id":9633869}]}]}
{"op":"mcm","clk":"4230630162","pt":1631534955271,"mc":[{"id":"1.187557995","rc":[{"batl":[[1,1.34,574.36],[2,1.35,93.53]],"ltp":1.33,"tv":76066.51,"id":9342449},{"batl":[[0,4.4,11.05],[1,4.5,10.22],[2,4.6,2.21]],"ltp":4.0,"tv":8556.85,"id":9633869}]}]}
{"op":"mcm","clk":"4230630318","pt":1631534956686,"mc":[{"id":"1.187557995","rc":[{"batb":[[0,1.31,138.92],[1,1.3,424.15],[2,1.29,927.87]],"batl":[[0,1.32,70.12],[1,1.33,304.62],[2,1.34,574.36]],"ltp":1.33,"tv":76066.51,"id":9342449}]}]}
{"op":"mcm","clk":"4230630429","pt":1631534957683,"mc":[{"id":"1.187557995","rc":[{"batb":[[0,1.31,265.07],[1,1.3,499.7]],"batl":[[0,1.32,585.6],[1,1.33,375.28]],"ltp":1.33,"tv":76066.51,"id":9342449}]}]}
{"op":"mcm","clk":"4230630556","pt":1631534958676,"mc":[{"id":"1.187557995","rc":[{"batb":[[0,4,133.26]],"ltp":4.0,"tv":8556.85,"id":9633869}]}]}
{"op":"mcm","clk":"4230630642","pt":1631534959268,"mc":[{"id":"1.187557995","rc":[{"batb":[[1,1.3,2771.14]],"ltp":1.33,"tv":76066.51,"id":9342449}]}]}
{"op":"mcm","clk":"4230630773","pt":1631534960574,"mc":[{"id":"1.187557995","rc":[{"batl":[[1,1.33,453.81],[2,1.34,653.61]],"ltp":1.33,"tv":76066.51,"id":9342449},{"batb":[[1,3.9,513.73]],"batl":[[1,4.5,2.21]],"ltp":4.0,"tv":8556.85,"id":9633869}]}]}
{"op":"mcm","clk":"4230630936","pt":1631534962181,"mc":[{"id":"1.187557995","rc":[{"batl":[[0,1.32,851.6]],"ltp":1.33,"tv":76066.51,"id":9342449},{"batl":[[0,4.3,91.69],[1,4.4,11.05],[2,4.5,2.21]],"ltp":4.0,"tv":8556.85,"id":9633869}]}]}
{"op":"mcm","clk":"4230631025","pt":1631534963278,"mc":[{"id":"1.187557995","rc":[{"batl":[[1,1.33,383.15]],"ltp":1.33,"tv":76066.51,"id":9342449},{"batl":[[1,4.4,19.18]],"ltp":4.0,"tv":8556.85,"id":9633869}]}]}
{"op":"mcm","clk":"4230631164","pt":1631534964694,"mc":[{"id":"1.187557995","rc":[{"batb":[[0,1.31,138.92],[1,1.3,2695.59]],"ltp":1.33,"tv":76066.51,"id":9342449},{"batb":[[1,3.9,513.54]],"ltp":4.0,"tv":8556.85,"id":9633869}]}]}
{"op":"mcm","clk":"4230631305","pt":1631534965995,"mc":[{"id":"1.187557995","rc":[{"batb":[[1,1.3,424.15]],"ltp":1.33,"tv":76066.51,"id":9342449}]}]}
{"op":"mcm","clk":"4230631388","pt":1631534966775,"mc":[{"id":"1.187557995","rc":[{"batb":[[0,1.3,424.15],[1,1.29,927.87],[2,1.28,1154.74]],"batl":[[0,1.32,781.48]],"ltp":1.33,"tv":76066.51,"id":9342449}]}]}
{"op":"mcm","clk":"4230631793","pt":1631534970679,"mc":[{"id":"1.187557995","rc":[{"batb":[[0,1.29,111.41],[1,1.28,332.96],[2,1.27,748.81]],"batl":[[0,1.34,325.42],[1,1.35,15],[2,1.36,71.07]],"ltp":1.33,"tv":76066.51,"id":9342449},{"batb":[[0,3.9,23.14],[1,3.8,58.99],[2,3.75,2.71]],"batl":[[1,4.4,8.13],[2,4.6,2.21]],"ltp":4.0,"tv":8556.85,"id":9633869}]}]}
{"op":"mcm","clk":"4230631863","pt":1631534971502,"mc":[{"id":"1.187557995","rc":[{"batb":[[0,1.28,332.96],[1,1.27,748.81],[2,1.26,97.48]],"batl":[[0,1.31,3529.41],[1,1.34,325.42]],"ltp":1.33,"tv":76066.51,"id":9342449},{"batb":[[0,3.9,2.46]],"batl":[[1,4.6,2.21],[2,4.8,2.22]],"ltp":4.0,"tv":8556.85,"id":9633869}]}]}
{"op":"mcm","clk":"4230632100","pt":1631534973696,"mc":[{"id":"1.187557995","rc":[{"batb":[[2,1.26,724.36]],"batl":[[0,1.34,325.42],[1,1.36,71.07],[2,1.37,382.14]],"ltp":1.33,"tv":76066.51,"id":9342449}]}]}
{"op":"mcm","clk":"4230632165","pt":1631534974276,"mc":[{"id":"1.187557995","rc":[{"batb":[[2,1.26,97.48]],"ltp":1.33,"tv":76066.51,"id":9342449}]}]}
{"op":"mcm","clk":"4230632241","pt":1631534975098,"mc":[{"id":"1.187557995","rc":[{"batb":[[0,1.28,96.16]],"ltp":1.33,"tv":76066.51,"id":9342449}]}]}
{"op":"mcm","clk":"4230632393","pt":1631534976710,"mc":[{"id":"1.187557995","rc":[{"batb":[[1,1.27,275.22],[2,1.26,300.21]],"batl":[[0,1.34,79.25],[1,1.37,382.14],[2,1.38,283.06]],"ltp":1.33,"tv":76066.51,"id":9342449},{"batb":[[2,2.2,42.67]],"ltp":4.0,"tv":8556.85,"id":9633869}]}]}
{"op":"mcm","clk":"4230632514","pt":1631534977710,"mc":[{"id":"1.187557995","rc":[{"trd":[[1.34,9697.32]],"batb":[[0,1.34,136.13],[1,1.33,1783.91],[2,1.32,1395.68]],"batl":[[0,1.37,382.14],[1,1.38,283.06],[2,1.49,2.99]],"ltp":1.34,"tv":76215.55,"id":9342449},{"trd":[[3.9,83]],"batb":[[0,3.8,58.99],[1,3.55,296.3],[2,3.5,287.59]],"batl":[[0,4.3,95.54]],"ltp":3.9,"tv":8565.02,"id":9633869}],"tv":84780.57}]}
{"op":"mcm","clk":"4230632599","pt":1631534978397,"mc":[{"id":"1.187557995","rc":[{"batb":[[2,1.32,1789.02]],"batl":[[2,1.49,16.41]],"ltp":1.34,"tv":76215.55,"id":9342449},{"batb":[[1,3.65,66.36],[2,3.55,319.82]],"batl":[[0,4.1,8.51],[1,4.3,95.54],[2,4.6,2.21]],"ltp":3.9,"tv":8565.02,"id":9633869}]}]}
{"op":"mcm","clk":"4230632815","pt":1631534980588,"mc":[{"id":"1.187557995","rc":[{"batb":[[0,1.34,2171.56]],"batl":[[0,1.37,458.46],[2,1.39,15]],"ltp":1.34,"tv":76215.55,"id":9342449}]}]}
{"op":"mcm","clk":"4230632913","pt":1631534981618,"mc":[{"id":"1.187557995","rc":[{"batb":[[0,1.35,75.52],[1,1.34,2171.56],[2,1.33,1783.91]],"batl":[[0,1.36,406.65],[1,1.37,458.46],[2,1.38,283.06]],"ltp":1.34,"tv":76215.55,"id":9342449}]}]}
{"op":"mcm","clk":"4230633023","pt":1631534982515,"mc":[{"id":"1.187557995","rc":[{"batl":[[0,4,25.69],[1,4.1,8.51],[2,4.3,95.54]],"ltp":3.9,"tv":8565.02,"id":9633869}]}]}
{"op":"mcm","clk":"4230633089","pt":1631534983101,"mc":[{"id":"1.187557995","rc":[{"batl":[[0,4,11.99]],"ltp":3.9,"tv":8565.02,"id":9633869}]}]}
{"op":"mcm","clk":"4230633253","pt":1631534984711,"mc":[{"id":"1.187557995","rc":[{"batl":[[0,1.36,478.22],[1,1.37,846.79]],"ltp":1.34,"tv":76215.55,"id":9342449},{"batb":[[1,3.75,2.87],[2,3.7,3.32]],"batl":[[0,4.3,3.85],[1,4.5,2.33],[2,4.6,2.21]],"ltp":3.9,"tv":8565.02,"id":9633869}]}]}
{"op":"mcm","clk":"4230633304","pt":1631534985217,"mc":[{"id":"1.187557995","rc":[{"batb":[[2,1.33,1888.35]],"batl":[[0,1.36,775.22],[2,1.38,347.31]],"ltp":1.34,"tv":76215.55,"id":9342449}]}]}
{"op":"mcm","clk":"4230633537","pt":1631534987625,"mc":[{"id":"1.187557995","rc":[{"batl":[[0,4,8.66],[1,4.3,3.85],[2,4.5,2.33]],"ltp":3.9,"tv":8565.02,"id":9633869}]}]}
{"op":"mcm","clk":"4230633579","pt":1631534988004,"mc":[{"id":"1.187557995","rc":[{"batl":[[1,4.2,19.25],[2,4.3,3.85]],"ltp":3.9,"tv":8565.02,"id":9633869}]}]}
{"op":"mcm","clk":"4230633733","pt":1631534989620,"mc":[{"id":"1.187557995","rc":[{"batb":[[1,1.34,2081.7],[2,1.33,104.44]],"batl":[[0,1.36,368.35],[1,1.37,66.5],[2,1.38,64.25]],"ltp":1.34,"tv":76215.55,"id":9342449},{"batb":[[0,3.7,3.32],[1,3.65,66.36],[2,3.6,3.29]],"batl":[[1,4.5,2.33],[2,4.6,2.21]],"ltp":3.9,"tv":8565.02,"id":9633869}]}]}
{"op":"mcm","clk":"4230633821","pt":1631534990510,"mc":[{"id":"1.187557995","rc":[{"trd":[[1.34,13860.35],[1.35,2197.98]],"batb":[[0,1.31,405.45],[1,1.3,650.77],[2,1.29,401.89]],"batl":[[0,1.34,1372.56],[1,1.36,71.35],[2,1.37,66.5]],"ltp":1.34,"tv":80529.61,"id":9342449},{"batl":[[0,4.5,2.33],[1,4.6,2.21],[2,4.8,2.22]],"ltp":3.9,"tv":8565.02,"id":9633869}],"tv":89094.64}]}
{"op":"mcm","clk":"4230633870","pt":1631534991017,"mc":[{"id":"1.187557995","rc":[{"batl":[[1,1.37,66.5],[2,1.38,64.25]],"ltp":1.34,"tv":80529.61,"id":9342449}]}]}
{"op":"mcm","clk":"4230634010","pt":1631534992699,"mc":[{"id":"1.187557995","rc":[{"batb":[[0,1.31,701.9],[1,1.3,1043],[2,1.29,398.04]],"ltp":1.34,"tv":80529.61,"id":9342449},{"batb":[[1,3.6,70.9],[2,2.2,42.67]],"batl":[[0,4.3,2.75],[1,4.5,2.33],[2,4.6,2.21]],"ltp":3.9,"tv":8565.02,"id":9633869}]}]}
{"op":"mcm","clk":"4230634067","pt":1631534993325,"mc":[{"id":"1.187557995","rc":[{"batb":[[0,1.31,487.24],[1,1.3,650.77]],"ltp":1.34,"tv":80529.61,"id":9342449}]}]}
{"op":"mcm","clk":"4230634307","pt":1631534995626,"mc":[{"id":"1.187557995","rc":[{"trd":[[1.34,14154.57]],"batl":[[0,1.35,14.87],[1,1.38,906.82],[2,1.49,2.99]],"ltp":1.34,"tv":80823.83,"id":9342449},{"trd":[[3.9,184.09]],"batb":[[0,3.6,70.9],[1,2.2,42.67],[2,2,11.88]],"ltp":3.9,"tv":8666.11,"id":9633869}],"tv":89489.95}]}
{"op":"mcm","clk":"4230634381","pt":1631534996237,"mc":[{"id":"1.187557995","rc":[{"trd":[[1.33,2075.46],[1.35,2253.01]],"batb":[[0,1.33,137.16],[1,1.32,361.88],[2,1.31,487.24]],"batl":[[0,1.34,54],[1,1.36,316.35],[2,1.37,294.23]],"ltp":1.33,"tv":81227.24,"id":9342449},{"trd":[[3.85,124.25]],"ltp":3.85,"tv":8685.41,"id":9633869}],"tv":89912.65}]}
{"op":"mcm","clk":"4230634500","pt":1631534997498,"mc":[{"id":"1.187557995","rc":[{"batb":[[1,1.32,412.63]],"ltp":1.33,"tv":81227.24,"id":9342449},{"batb":[[0,3.75,14.97],[1,3.6,70.9],[2,2.2,42.67]],"batl":[[0,4.2,13.75],[1,4.3,2.75],[2,4.5,2.33]],"ltp":3.85,"tv":8685.41,"id":9633869}]}]}
{"op":"mcm","clk":"4230634583","pt":1631534998537,"mc":[{"id":"1.187557995","rc":[{"batl":[[2,1.37,347.85]],"ltp":1.33,"tv":81227.24,"id":9342449},{"batb":[[0,3.6,70.9],[1,2.2,42.67],[2,2,11.88]],"batl":[[0,4.3,2.75],[1,4.5,2.33],[2,4.6,2.21]],"ltp":3.85,"tv":8685.41,"id":9633869}]}]}
{"op":"mcm","clk":"4230634606","pt":1631534998843,"mc":[{"id":"1.187557995","rc":[{"batl":[[2,1.37,365.73]],"ltp":1.33,"tv":81227.24,"id":9342449},{"batb":[[0,3.7,3.12],[1,3.6,70.9],[2,2.2,42.67]],"ltp":3.85,"tv":8685.41,"id":9633869}]}]}
{"op":"mcm","clk":"4230634786","pt":1631535000631,"mc":[{"id":"1.187557995","rc":[{"batb":[[0,1.33,261.56],[1,1.32,361.88]],"batl":[[1,1.36,410.13]],"ltp":1.33,"tv":81227.24,"id":9342449}]}]}
{"op":"mcm","clk":"4230634870","pt":1631535001342,"mc":[{"id":"1.187557995","rc":[{"batb":[[0,1.33,46.48],[1,1.31,487.24],[2,1.3,650.77]],"batl":[[0,1.38,64.25],[1,1.49,2.99],[2,1.82,2.89]],"ltp":1.33,"tv":81227.24,"id":9342449},{"batb":[[0,3.6,70.9],[1,2.2,42.67],[2,2,11.88]],"ltp":3.85,"tv":8685.41,"id":9633869}]}]}
{"op":"mcm","clk":"4230634990","pt":1631535002436,"mc":[{"id":"1.187557995","rc":[{"batb":[[0,1.31,487.24],[1,1.3,650.77],[2,1.29,398.04]],"ltp":1.33,"tv":81227.24,"id":9342449},{"batl":[[0,4.2,13.75],[1,4.3,2.75],[2,4.5,2.33]],"ltp":3.85,"tv":8685.41,"id":9633869}]}]}
{"op":"mcm","clk":"4230635023","pt":1631535002749,"mc":[{"id":"1.187557995","rc":[{"batl":[[0,4.3,2.75],[1,4.5,2.33],[2,4.6,2.21]],"ltp":3.85,"tv":8685.41,"id":9633869}]}]}
{"op":"mcm","clk":"4230635235","pt":1631535004629,"mc":[{"id":"1.187557995","rc":[{"batb":[[0,1.31,81.79],[1,1.29,398.04],[2,1.28,96.16]],"batl":[[0,1.37,74.5],[1,1.38,71.25],[2,1.49,2.99]],"ltp":1.33,"tv":81227.24,"id":9342449},{"batb":[[0,3.7,2.92],[1,3.6,73.9],[2,3.55,2]],"ltp":3.85,"tv":8685.41,"id":9633869}]}]}
{"op":"mcm","clk":"4230635343","pt":1631535005622,"mc":[{"id":"1.187557995","rc":[{"batb":[[0,1.3,509.92],[1,1.29,3778.52],[2,1.28,2974.08]],"batl":[[0,1.38,71.25],[1,1.47,13.61]],"ltp":1.33,"tv":81227.24,"id":9342449},{"batb":[[0,3.9,980.78],[1,3.85,951.92],[2,3.8,951.92]],"batl":[[0,4.5,2.33],[1,4.6,2.21],[2,4.8,2.22]],"ltp":3.85,"tv":8685.41,"id":9633869}]}]}
{"op":"mcm","clk":"4230635449","pt":1631535006609,"mc":[{"id":"1.187557995","rc":[{"batb":[[1,1.29,2295.96],[2,1.28,887.59]],"batl":[[0,1.33,245.57],[1,1.34,330.6],[2,1.38,71.25]],"ltp":1.33,"tv":81227.24,"id":9342449},{"trd":[[4,74.78]],"batb":[[0,4,98.78],[1,3.9,490.4],[2,3.85,475.96]],"ltp":4.0,"tv":8696.37,"id":9633869}],"tv":89923.62}]}
{"op":"mcm","clk":"4230635571","pt":1631535007615,"mc":[{"id":"1.187557995","rc":[{"batb":[[0,1.3,619.46]],"batl":[[2,1.35,15]],"ltp":1.33,"tv":81227.24,"id":9342449},{"batl":[[0,4.4,8.13],[1,4.5,2.33],[2,4.6,2.21]],"ltp":4.0,"tv":8696.37,"id":9633869}]}]}
{"op":"mcm","clk":"4230635663","pt":1631535008538,"mc":[{"id":"1.187557995","rc":[{"batl":[[0,4.4,19.78]],"ltp":4.0,"tv":8696.37,"id":9633869}]}]}
{"op":"mcm","clk":"4230635873","pt":1631535010643,"mc":[{"id":"1.187557995","rc":[{"trd":[[1.32,441.82]],"batb":[[0,1.31,217.2],[1,1.3,619.46],[2,1.29,2295.96]],"batl":[[0,1.32,335.86],[1,1.33,313.28],[2,1.34,330.6]],"ltp":1.32,"tv":81241.46,"id":9342449}],"tv":89937.84}]}
{"op":"mcm","clk":"4230635993","pt":1631535011638,"mc":[{"id":"1.187557995","rc":[{"batb":[[1,1.3,697.97]],"batl":[[1,1.33,440.32]],"ltp":1.32,"tv":81241.46,"id":9342449},{"batb":[[0,4,115.57]],"ltp":4.0,"tv":8696.37,"id":9633869}]}]}
{"op":"mcm","clk":"4230636117","pt":1631535012631,"mc":[{"id":"1.187557995","rc":[{"batb":[[2,3.85,479.53]],"ltp":4.0,"tv":8696.37,"id":9633869}]}]}
{"op":"mcm","clk":"4230636185","pt":1631535013250,"mc":[{"id":"1.187557995","rc":[{"batl":[[0,1.32,661.86],[1,1.33,695.18]],"ltp":1.32,"tv":81241.46,"id":9342449}]}]}
{"op":"mcm","clk":"4230636272","pt":1631535014137,"mc":[{"id":"1.187557995","rc":[{"batb":[[2,3.85,500.58]],"ltp":4.0,"tv":8696.37,"id":9633869}]}]}
{"op":"mcm","clk":"4230636440","pt":1631535015762,"mc":[{"id":"1.187557995","rc":[{"batb":[[1,1.3,2969.41]],"ltp":1.32,"tv":81241.46,"id":9342449}]}]}
{"op":"mcm","clk":"4230636593","pt":1631535017219,"mc":[{"id":"1.187557995","rc":[{"batl":[[1,1.33,627.47]],"ltp":1.32,"tv":81241.46,"id":9342449}]}]}
{"op":"mcm","clk":"4230636744","pt":1631535018625,"mc":[{"id":"1.187557995","rc":[{"batb":[[2,1.29,813.4]],"batl":[[1,1.33,500.43]],"ltp":1.32,"tv":81241.46,"id":9342449},{"batb":[[0,4,98.78],[1,3.85,24.62],[2,3.75,60.58]],"batl":[[0,4.4,8.13]],"ltp":4.0,"tv":8696.37,"id":9633869}]}]}
{"op":"mcm","clk":"4230636812","pt":1631535019245,"mc":[{"id":"1.187557995","rc":[{"batb":[[1,1.3,2459.49],[2,1.29,80.81]],"batl":[[0,1.32,58.83],[1,1.35,94.3],[2,1.37,75.5]],"ltp":1.32,"tv":81241.46,"id":9342449},{"batb":[[0,3.85,24.62],[1,3.75,60.58],[2,3.7,3.52]],"ltp":4.0,"tv":8696.37,"id":9633869}]}]}
{"op":"mcm","clk":"4230636950","pt":1631535020615,"mc":[{"id":"1.187557995","rc":[{"batb":[[0,1.29,80.81],[1,1.28,199.23],[2,1.27,670.45]],"batl":[[0,1.37,75.5],[1,1.38,71.48],[2,1.49,2.99]],"ltp":1.32,"tv":81241.46,"id":9342449},{"batb":[[0,3.75,60.58],[1,3.7,3.52],[2,3.65,3]],"batl":[[0,4.5,2.33],[1,4.6,2.21],[2,4.8,2.22]],"ltp":4.0,"tv":8696.37,"id":9633869}]}]}
{"op":"mcm","clk":"4230637070","pt":1631535021619,"mc":[{"id":"1.187557995","rc":[{"batb":[[0,1.28,103.07],[1,1.27,670.45],[2,1.26,532.01]],"batl":[[1,1.38,499.64],[2,1.39,274.33]],"ltp":1.32,"tv":81241.46,"id":9342449},{"batl":[[0,4.8,2.22],[1,4.9,2.15],[2,5,2.21]],"ltp":4.0,"tv":8696.37,"id":9633869}]}]}
{"op":"mcm","clk":"4230637279","pt":1631535023699,"mc":[{"id":"1.187557995","rc":[{"batl":[[0,1.35,75.3],[1,1.37,83.5],[2,1.38,499.64]],"ltp":1.32,"tv":81241.46,"id":9342449},{"batb":[[0,3.85,3.37],[1,3.75,63.58],[2,3.7,5.52]],"ltp":4.0,"tv":8696.37,"id":9633869}]}]}
{"op":"mcm","clk":"4230637317","pt":1631535024116,"mc":[{"id":"1.187557995","rc":[{"batb":[[0,1.29,83.81],[1,1.28,103.07],[2,1.27,670.45]],"batl":[[0,1.37,83.5],[1,1.38,499.64],[2,1.39,274.33]],"ltp":1.32,"tv":81241.46,"id":9342449},{"batb":[[0,3.75,63.58],[1,3.7,5.52],[2,3.65,3]],"batl":[[0,4.5,2.75],[1,4.8,2.22],[2,4.9,2.15]],"ltp":4.0,"tv":8696.37,"id":9633869}]}]}
{"op":"mcm","clk":"4230637425","pt":1631535025110,"mc":[{"id":"1.187557995","rc":[{"batb":[[0,1.28,103.07],[1,1.27,670.45],[2,1.25,379.16]],"batl":[[0,1.35,246.17],[1,1.37,83.5],[2,1.38,435.39]],"ltp":1.32,"tv":81241.46,"id":9342449},{"batl":[[0,4.8,2.22],[1,4.8,0],[2,4.9,0]],"ltp":4.0,"tv":8696.37,"id":9633869}]}]}
{"op":"mcm","clk":"4230637576","pt":1631535026624,"mc":[{"id":"1.187557995","rc":[{"batb":[[0,1.34,5910.94],[1,1.27,275.22]],"batl":[[0,1.37,83.5],[1,1.38,435.39],[2,1.39,274.33]],"ltp":1.32,"tv":81241.46,"id":9342449}]}]}
{"op":"mcm","clk":"4230637669","pt":1631535027520,"mc":[{"id":"1.187557995","rc":[{"batb":[[0,1.27,275.22],[1,1.25,379.16],[2,1.2,2]],"batl":[[0,1.36,8],[1,1.37,83.5],[2,1.38,435.39]],"ltp":1.32,"tv":81241.46,"id":9342449}]}]}
{"op":"mcm","clk":"4230637800","pt":1631535028622,"mc":[{"id":"1.187557995","rc":[{"batb":[[0,1.34,1891.02],[1,1.33,1818.1],[2,1.32,1666.51]],"batl":[[0,1.37,75.5],[1,1.38,428.39],[2,1.39,274.33]],"ltp":1.32,"tv":81241.46,"id":9342449},{"trd":[[3.75,46.05]],"batb":[[0,3.75,54.7],[1,3.7,3.52],[2,3.5,546.44]],"batl":[[0,4.1,8.85],[1,4.8,2.22]],"ltp":3.75,"tv":8708.14,"id":9633869}],"tv":89949.6}]}
{"op":"mcm","clk":"4230637886","pt":1631535029420,"mc":[{"id":"1.187557995","rc":[{"batb":[[1,1.33,1922.54]],"ltp":1.32,"tv":81241.46,"id":9342449},{"batl":[[0,4,8.66],[1,4.1,8.85],[2,4.6,11.1]],"ltp":3.75,"tv":8708.14,"id":9633869}]}]}
{"op":"mcm","clk":"4230638007","pt":1631535030620,"mc":[{"id":"1.187557995","rc":[{"batb":[[1,1.33,1818.1]],"ltp":1.32,"tv":81241.46,"id":9342449},{"batl":[[0,4.1,8.85],[1,4.8,2.22],[2,4.6,0]],"ltp":3.75,"tv":8708.14,"id":9633869}]}]}
{"op":"mcm","clk":"4230638236","pt":1631535032642,"mc":[{"id":"1.187557995","rc":[{"batb":[[0,1.34,1427.24],[1,1.33,1467.79]],"batl":[[0,1.37,318.55],[1,1.49,3.22],[2,1.5,13.33]],"ltp":1.32,"tv":81241.46,"id":9342449}]}]}
{"op":"mcm","clk":"4230638334","pt":1631535033508,"mc":[{"id":"1.187557995","rc":[{"batb":[[0,1.34,4433.55]],"batl":[[1,1.4,15.23],[2,1.49,2.99]],"ltp":1.32,"tv":81241.46,"id":9342449},{"batl":[[0,4,23.07],[1,4.1,8.85],[2,4.8,2.22]],"ltp":3.75,"tv":8708.14,"id":9633869}]}]}
{"op":"mcm","clk":"4230638503","pt":1631535035339,"mc":[{"id":"1.187557995","rc":[{"batl":[[0,1.37,461.55]],"ltp":1.32,"tv":81241.46,"id":9342449}]}]}
{"op":"mcm","clk":"4230638700","pt":1631535037532,"mc":[{"id":"1.187557995","rc":[{"batb":[[0,1.34,4536.44],[1,1.33,1744.19],[2,1.32,1385.26]],"batl":[[0,1.37,318.55]],"ltp":1.32,"tv":81241.46,"id":9342449}]}]}
{"op":"mcm","clk":"4230638737","pt":1631535037949,"mc":[{"id":"1.187557995","rc":[{"batb":[[0,1.34,5000.22],[1,1.33,2094.5]],"batl":[[1,1.38,428.39],[2,1.39,274.33]],"ltp":1.32,"tv":81241.46,"id":9342449}]}]}
{"op":"mcm","clk":"4230638988","pt":1631535040638,"mc":[{"id":"1.187557995","rc":[{"batl":[[0,1.36,593],[1,1.37,318.55],[2,1.38,428.39]],"ltp":1.32,"tv":81241.46,"id":9342449}]}]}
{"op":"mcm","clk":"4230639276","pt":1631535043951,"mc":[{"id":"1.187557995","rc":[{"batl":[[0,1.36,1059.41]],"ltp":1.32,"tv":81241.46,"id":9342449}]}]}
{"op":"mcm","clk":"4230639794","pt":1631535049248,"mc":[{"id":"1.187557995","rc":[{"trd":[[1.36,11224.56]],"batl":[[0,1.36,1009.41]],"ltp":1.36,"tv":81341.46,"id":9342449}],"tv":90049.6}]}
{"op":"mcm","clk":"4230639896","pt":1631535050353,"mc":[{"id":"1.187557995","rc":[{"batb":[[1,1.33,2337.35]],"ltp":1.36,"tv":81341.46,"id":9342449},{"batl":[[0,3.95,81.77],[1,4,23.07],[2,4.1,8.85]],"ltp":3.75,"tv":8708.14,"id":9633869}]}]}
{"op":"mcm","clk":"4230640094","pt":1631535052341,"mc":[{"id":"1.187557995","rc":[{"batb":[[0,1.34,5342.24]],"ltp":1.36,"tv":81341.46,"id":9342449}]}]}
{"op":"mcm","clk":"4230640169","pt":1631535053129,"mc":[{"id":"1.187557995","rc":[{"batb":[[0,1.34,5585]],"ltp":1.36,"tv":81341.46,"id":9342449},{"batl":[[0,3.95,164.12]],"ltp":3.75,"tv":8708.14,"id":9633869}]}]}
{"op":"mcm","clk":"4230640399","pt":1631535055634,"mc":[{"id":"1.187557995","rc":[{"batb":[[1,1.33,2254.82]],"ltp":1.36,"tv":81341.46,"id":9342449},{"batl":[[1,4,14.41]],"ltp":3.75,"tv":8708.14,"id":9633869}]}]}
{"op":"mcm","clk":"4230640590","pt":1631535057884,"mc":[{"id":"1.187557995","rc":[{"batb":[[0,1.35,25.8],[1,1.34,5585],[2,1.33,2462.32]],"ltp":1.36,"tv":81341.46,"id":9342449},{"batl":[[1,4,83.4]],"ltp":3.75,"tv":8708.14,"id":9633869}]}]}
{"op":"mcm","clk":"4230640685","pt":1631535058873,"mc":[{"id":"1.187557995","rc":[{"batl":[[0,3.95,172.85]],"ltp":3.75,"tv":8708.14,"id":9633869}]}]}
{"op":"mcm","clk":"4230640798","pt":1631535060172,"mc":[{"id":"1.187557995","rc":[{"trd":[[1.35,2254.09]],"batb":[[0,1.35,25.26]],"ltp":1.35,"tv":81342.54,"id":9342449}],"tv":90050.69}]}
{"op":"mcm","clk":"4230640927","pt":1631535061478,"mc":[{"id":"1.187557995","rc":[{"batl":[[2,1.38,616.64]],"ltp":1.35,"tv":81342.54,"id":9342449},{"batb":[[2,3.6,72.16]],"ltp":3.75,"tv":8708.14,"id":9633869}]}]}
{"op":"mcm","clk":"4230641237","pt":1631535064673,"mc":[{"id":"1.187557995","rc":[{"batl":[[1,4,68.99]],"ltp":3.75,"tv":8708.14,"id":9633869}]}]}
{"op":"mcm","clk":"4230641448","pt":1631535067171,"mc":[{"id":"1.187557995","rc":[{"batb":[[1,1.34,2578.69]],"ltp":1.35,"tv":81342.54,"id":9342449}]}]}
{"op":"mcm","clk":"4230641964","pt":1631535072762,"mc":[{"id":"1.187557995","rc":[{"batb":[[0,1.34,2578.69],[1,1.33,2462.32],[2,1.32,1385.26]],"ltp":1.35,"tv":81342.54,"id":9342449}]}]}
{"op":"mcm","clk":"4230642184","pt":1631535075108,"mc":[{"id":"1.187557995","rc":[{"trd":[[1.35,2373.11]],"batb":[[0,1.35,82.3],[1,1.34,2578.69],[2,1.33,2462.32]],"ltp":1.35,"tv":81461.56,"id":9342449}],"tv":90169.71}]}
{"op":"mcm","clk":"4230642640","pt":1631535079870,"mc":[{"id":"1.187557995","rc":[{"batl":[[2,1.38,616.41]],"ltp":1.35,"tv":81461.56,"id":9342449}]}]}
{"op":"mcm","clk":"4230642811","pt":1631535081490,"mc":[{"id":"1.187557995","rc":[{"trd":[[1.35,2373.58]],"batb":[[0,1.35,82.07]],"ltp":1.35,"tv":81462.03,"id":9342449}],"tv":90170.17}]}
{"op":"mcm","clk":"4230643068","pt":1631535084103,"mc":[{"id":"1.187557995","rc":[{"trd":[[1.36,11272.26]],"batl":[[0,1.36,985.56]],"ltp":1.36,"tv":81509.73,"id":9342449}],"tv":90217.87}]}
{"op":"mcm","clk":"4230643148","pt":1631535084793,"mc":[{"id":"1.187557995","rc":[{"trd":[[1.35,2374.27]],"batb":[[0,1.35,81.72]],"ltp":1.35,"tv":81510.42,"id":9342449}],"tv":90218.56}]}
{"op":"mcm","clk":"4230643635","pt":1631535089925,"mc":[{"id":"1.187557995","rc":[{"batb":[[1,1.34,5585]],"ltp":1.35,"tv":81510.42,"id":9342449}]}]}
{"op":"mcm","clk":"4230644622","pt":1631535100944,"mc":[{"id":"1.187557995","rc":[{"trd":[[1.36,11323.4]],"batl":[[0,1.36,959.99]],"ltp":1.36,"tv":81561.56,"id":9342449}],"tv":90269.7}]}
{"op":"mcm","clk":"4230644951","pt":1631535104413,"mc":[{"id":"1.187557995","rc":[{"batb":[[1,1.34,5121.22],[2,1.33,2112.01]],"batl":[[2,1.38,188.25]],"ltp":1.36,"tv":81561.56,"id":9342449}]}]}
{"op":"mcm","clk":"4230645255","pt":1631535107942,"mc":[{"id":"1.187557995","rc":[{"batb":[[1,1.34,5585],[2,1.33,2462.32]],"batl":[[2,1.38,616.41]],"ltp":1.36,"tv":81561.56,"id":9342449}]}]}
{"op":"mcm","clk":"4230645586","pt":1631535111483,"mc":[{"id":"1.187557995","rc":[{"batb":[[1,1.34,5651.12]],"batl":[[0,1.36,1040.88],[1,1.37,391.54]],"ltp":1.36,"tv":81561.56,"id":9342449}]}]}
{"op":"mcm","clk":"4230645615","pt":1631535111796,"mc":[{"id":"1.187557995","rc":[{"batb":[[2,1.33,2518.73]],"ltp":1.36,"tv":81561.56,"id":9342449}]}]}
{"op":"mcm","clk":"4230645769","pt":1631535113685,"mc":[{"id":"1.187557995","rc":[{"trd":[[1.35,2381.36]],"batb":[[0,1.35,78.18]],"ltp":1.35,"tv":81568.65,"id":9342449}],"tv":90276.79}]}
{"op":"mcm","clk":"4230645947","pt":1631535115479,"mc":[{"id":"1.187557995","rc":[{"batb":[[0,1.34,5242.98],[1,1.33,2462.32],[2,1.32,1385.26]],"batl":[[0,1.36,959.99],[1,1.37,318.55]],"ltp":1.35,"tv":81568.65,"id":9342449}]}]}
{"op":"mcm","clk":"4230646142","pt":1631535117492,"mc":[{"id":"1.187557995","rc":[{"trd":[[1.36,13215.92]],"batl":[[0,1.36,13.81]],"ltp":1.36,"tv":83461.16,"id":9342449}],"tv":92169.3}]}
{"op":"mcm","clk":"4230646443","pt":1631535120675,"mc":[{"id":"1.187557995","rc":[{"batb":[[0,1.35,503.38],[1,1.34,5242.98],[2,1.33,2462.32]],"batl":[[0,1.37,318.55],[1,1.38,616.41],[2,1.39,274.33]],"ltp":1.36,"tv":83461.16,"id":9342449}]}]}
{"op":"mcm","clk":"4230646589","pt":1631535122202,"mc":[{"id":"1.187557995","rc":[{"batl":[[0,1.36,680],[1,1.37,318.55],[2,1.38,616.41]],"ltp":1.36,"tv":83461.16,"id":9342449}]}]}
{"op":"mcm","clk":"4230646931","pt":1631535125393,"mc":[{"id":"1.187557995","rc":[{"batl":[[0,1.36,1063.36]],"ltp":1.36,"tv":83461.16,"id":9342449}]}]}
{"op":"mcm","clk":"4230647252","pt":1631535128506,"mc":[{"id":"1.187557995","rc":[{"batb":[[1,1.34,5616.67]],"ltp":1.36,"tv":83461.16,"id":9342449}]}]}
{"op":"mcm","clk":"4230648537","pt":1631535140917,"mc":[{"id":"1.187557995","rc":[{"trd":[[1.36,13407.92]],"batl":[[0,1.36,967.36]],"ltp":1.36,"tv":83653.16,"id":9342449}],"tv":92361.3}]}
{"op":"mcm","clk":"4230649141","pt":1631535147034,"mc":[{"id":"1.187557995","rc":[{"batb":[[1,1.34,2610.36]],"ltp":1.36,"tv":83653.16,"id":9342449}]}]}
{"op":"mcm","clk":"4230649308","pt":1631535148925,"mc":[{"id":"1.187557995","rc":[{"batb":[[1,1.34,2146.58],[2,1.33,2112.01]],"batl":[[2,1.38,188.25]],"ltp":1.36,"tv":83653.16,"id":9342449}]}]}
{"op":"mcm","clk":"4230649573","pt":1631535151562,"mc":[{"id":"1.187557995","rc":[{"batb":[[0,1.35,78.18],[1,1.34,102.89],[2,1.31,83.79]],"batl":[[0,1.36,584],[1,1.4,15],[2,1.49,2.99]],"ltp":1.36,"tv":83653.16,"id":9342449},{"batb":[[0,3.05,99.5],[1,2.2,42.67],[2,2,11.88]],"batl":[[0,3.95,8.73],[1,4.3,2.65],[2,4.6,2.31]],"ltp":3.75,"tv":8708.14,"id":9633869}]}]}
{"op":"mcm","clk":"4230649674","pt":1631535152644,"mc":[{"id":"1.187557995","rc":[{"batb":[[1,1.28,91.41],[2,1.27,541.9]],"batl":[[0,1.49,2.99],[1,1.82,2.89],[2,2.08,1]],"ltp":1.36,"tv":83653.16,"id":9342449},{"batl":[[0,4.6,2.31],[1,4.3,0],[2,4.6,0]],"ltp":3.75,"tv":8708.14,"id":9633869}]}]}
{"op":"mcm","clk":"4230649843","pt":1631535154266,"mc":[{"id":"1.187557995","rc":[{"batb":[[1,1.28,624.35],[2,1.27,997.75]],"batl":[[0,1.47,282.95],[1,1.48,208.15],[2,1.49,2.99]],"ltp":1.36,"tv":83653.16,"id":9342449}]}]}
{"op":"mcm","clk":"4230650049","pt":1631535156245,"mc":[{"id":"1.187557995","rc":[{"batb":[[1,1.31,225.72],[2,1.28,624.35]],"ltp":1.36,"tv":83653.16,"id":9342449}]}]}
{"op":"mcm","clk":"4230650155","pt":1631535157346,"mc":[{"id":"1.187557995","rc":[{"batb":[[1,1.28,624.35],[2,1.27,997.75]],"ltp":1.36,"tv":83653.16,"id":9342449}]}]}
{"op":"mcm","clk":"4230650372","pt":1631535159529,"mc":[{"id":"1.187557995","rc":[{"batb":[[1,1.31,84.79],[2,1.29,197.61]],"ltp":1.36,"tv":83653.16,"id":9342449},{"batl":[[0,4.3,2.75],[1,4.6,2.31]],"ltp":3.75,"tv":8708.14,"id":9633869}]}]}
{"op":"mcm","clk":"4230650397","pt":1631535159840,"mc":[{"id":"1.187557995","rc":[{"batb":[[1,1.29,197.61],[2,1.28,624.35]],"ltp":1.36,"tv":83653.16,"id":9342449},{"batl":[[0,4.6,2.31],[1,4.6,0]],"ltp":3.75,"tv":8708.14,"id":9633869}]}]}
{"op":"mcm","clk":"4230650570","pt":1631535161576,"mc":[{"id":"1.187557995","rc":[{"batb":[[0,1.29,197.61],[1,1.28,624.35],[2,1.27,997.75]],"batl":[[0,1.46,189.1],[1,1.49,2.99],[2,1.82,2.89]],"ltp":1.36,"tv":83653.16,"id":9342449}]}]}
{"op":"mcm","clk":"4230650742","pt":1631535163362,"mc":[{"id":"1.187557995","rc":[{"batb":[[0,1.28,624.35],[1,1.27,997.75],[2,1.2,2]],"batl":[[0,1.49,2.99],[1,1.82,2.89],[2,2.08,1]],"ltp":1.36,"tv":83653.16,"id":9342449}]}]}
{"op":"mcm","clk":"4230650883","pt":1631535164681,"mc":[{"id":"1.187557995","rc":[{"batl":[[0,1.31,313.97],[1,1.32,1805.66],[2,1.33,1406.26]],"ltp":1.36,"tv":83653.16,"id":9342449},{"batl":[[1,4.8,398.44],[2,4.9,212.7]],"ltp":3.75,"tv":8708.14,"id":9633869}]}]}
{"op":"mcm","clk":"4230650988","pt":1631535165676,"mc":[{"id":"1.187557995","rc":[{"batb":[[0,1.28,737.73],[2,1.22,445.77]],"ltp":1.36,"tv":83653.16,"id":9342449},{"trd":[[4.3,10.38]],"batb":[[0,4.3,83.76],[1,3.95,20.33],[2,3.75,62.26]],"batl":[[0,4.6,10.21]],"ltp":4.3,"tv":8718.52,"id":9633869}],"tv":92371.69}]}
{"op":"mcm","clk":"4230651073","pt":1631535166552,"mc":[{"id":"1.187557995","rc":[{"batb":[[2,1.22,970.57]],"ltp":1.36,"tv":83653.16,"id":9342449}]}]}
{"op":"mcm","clk":"4230651271","pt":1631535168553,"mc":[{"id":"1.187557995","rc":[{"batb":[[0,1.29,400.49],[1,1.28,737.73],[2,1.27,997.75]],"batl":[[0,1.3,71.64],[1,1.31,590.5],[2,1.32,1805.66]],"ltp":1.36,"tv":83653.16,"id":9342449}]}]}
{"op":"mcm","clk":"4230651377","pt":1631535169648,"mc":[{"id":"1.187557995","rc":[{"batl":[[1,1.31,772.98]],"ltp":1.36,"tv":83653.16,"id":9342449}]}]}
{"op":"mcm","clk":"4230651453","pt":1631535170541,"mc":[{"id":"1.187557995","rc":[{"batb":[[1,3.75,62.26],[2,3.55,69.29]],"ltp":4.3,"tv":8718.52,"id":9633869}]}]}
{"op":"mcm","clk":"4230651496","pt":1631535171057,"mc":[{"id":"1.187557995","rc":[{"batb":[[2,3.7,3.22]],"batl":[[2,4.9,215.05]],"ltp":4.3,"tv":8718.52,"id":9633869}]}]}
{"op":"mcm","clk":"4230651670","pt":1631535172583,"mc":[{"id":"1.187557995","rc":[{"batl":[[0,1.3,359.64]],"ltp":1.36,"tv":83653.16,"id":9342449}]}]}
{"op":"mcm","clk":"4230651767","pt":1631535173577,"mc":[{"id":"1.187557995","rc":[{"batb":[[1,4,20],[2,3.75,62.26]],"ltp":4.3,"tv":8718.52,"id":9633869}]}]}
{"op":"mcm","clk":"4230651816","pt":1631535174159,"mc":[{"id":"1.187557995","rc":[{"batl":[[0,1.3,409.64]],"ltp":1.36,"tv":83653.16,"id":9342449}]}]}
{"op":"mcm","clk":"4230651951","pt":1631535175570,"mc":[{"id":"1.187557995","rc":[{"batb":[[0,1.29,458.51],[1,1.28,943.85]],"batl":[[0,1.3,719.38]],"ltp":1.36,"tv":83653.16,"id":9342449}]}]}
{"op":"mcm","clk":"4230652038","pt":1631535176564,"mc":[{"id":"1.187557995","rc":[{"batb":[[0,1.29,137.79],[1,1.28,113.38],[2,1.27,541.9]],"batl":[[0,1.3,359.64],[1,1.33,15],[2,1.37,59.5]],"ltp":1.36,"tv":83653.16,"id":9342449},{"batb":[[2,3.7,3.22]],"batl":[[0,4.6,7.9],[1,4.9,2.35],[2,5.2,2.18]],"ltp":4.3,"tv":8718.52,"id":9633869}]}]}
{"op":"mcm","clk":"4230652119","pt":1631535177449,"mc":[{"id":"1.187557995","rc":[{"batb":[[0,1.27,187.35],[1,1.26,95.98],[2,1.25,492.33]],"batl":[[0,1.37,59.5],[1,1.41,59.5],[2,1.48,5]],"ltp":1.36,"tv":83653.16,"id":9342449},{"batb":[[0,3.7,3.22],[1,3.55,69.29],[2,3.4,3.26]],"batl":[[0,4.9,2.35],[1,5.2,2.18],[2,5.2,0]],"ltp":4.3,"tv":8718.52,"id":9633869}]}]}
{"op":"mcm","clk":"4230652204","pt":1631535178398,"mc":[{"id":"1.187557995","rc":[{"batl":[[0,1.41,59.5],[1,1.48,5],[2,1.49,2.99]],"ltp":1.36,"tv":83653.16,"id":9342449},{"batb":[[0,3.55,69.29],[1,3.4,3.26],[2,3.1,3]],"ltp":4.3,"tv":8718.52,"id":9633869}]}]}
{"op":"mcm","clk":"4230652329","pt":1631535179677,"mc":[{"id":"1.187557995","rc":[{"batl":[[0,1.29,50],[1,1.38,158.02],[2,1.39,276.75]],"ltp":1.36,"tv":83653.16,"id":9342449}]}]}
{"op":"mcm","clk":"4230652472","pt":1631535181293,"mc":[{"id":"1.187557995","rc":[{"batl":[[1,1.38,164.02]],"ltp":1.36,"tv":83653.16,"id":9342449},{"batb":[[0,3.55,72.29],[1,3.5,3],[2,3.4,3.26]],"ltp":4.3,"tv":8718.52,"id":9633869}]}]}
{"op":"mcm","clk":"4230652580","pt":1631535182675,"mc":[{"id":"1.187557995","rc":[{"batb":[[0,3.6,2],[1,3.55,72.29],[2,3.5,3]],"ltp":4.3,"tv":8718.52,"id":9633869}]}]}
{"op":"mcm","clk":"4230652654","pt":1631535183575,"mc":[{"id":"1.187557995","rc":[{"batl":[[1,1.37,227.43],[2,1.38,164.02]],"ltp":1.36,"tv":83653.16,"id":9342449}]}]}
{"op":"mcm","clk":"4230652743","pt":1631535184587,"mc":[{"id":"1.187557995","rc":[{"batl":[[1,1.37,304.93]],"ltp":1.36,"tv":83653.16,"id":9342449},{"batb":[[0,3.7,2.92],[1,3.6,2],[2,3.55,72.29]],"ltp":4.3,"tv":8718.52,"id":9633869}]}]}
{"op":"mcm","clk":"4230652958","pt":1631535186698,"mc":[{"id":"1.187557995","rc":[{"trd":[[1.29,3971.16]],"batb":[[2,1.24,112.52]],"batl":[[0,1.37,77.5],[1,1.38,164.02],[2,1.39,276.75]],"ltp":1.29,"tv":83753.16,"id":9342449}],"tv":92471.69}]}
{"op":"mcm","clk":"4230653047","pt":1631535187498,"mc":[{"id":"1.187557995","rc":[{"batl":[[0,1.38,164.02],[1,1.39,276.75],[2,1.4,7]],"ltp":1.29,"tv":83753.16,"id":9342449},{"batb":[[0,3.6,2],[1,3.55,72.29],[2,3.5,3]],"ltp":4.3,"tv":8718.52,"id":9633869}]}]}
{"op":"mcm","clk":"4230653157","pt":1631535188691,"mc":[{"id":"1.187557995","rc":[{"trd":[[1.38,712.68]],"batb":[[0,1.35,414.85],[1,1.34,1847.2],[2,1.33,1385.26]],"batl":[[0,1.39,276.75],[1,1.41,59.5],[2,1.48,5]],"ltp":1.38,"tv":83768.5,"id":9342449},{"trd":[[3.6,98.09]],"batb":[[0,3.55,69.29],[1,3.5,546.44],[2,3.45,291.7]],"batl":[[0,3.95,9.5],[1,4.9,2.35],[2,5.2,2.18]],"ltp":3.6,"tv":8724.4,"id":9633869}],"tv":92492.91}]}
{"op":"mcm","clk":"4230653239","pt":1631535189605,"mc":[{"id":"1.187557995","rc":[{"batb":[[0,1.35,669.57]],"batl":[[1,1.41,74.5]],"ltp":1.38,"tv":83768.5,"id":9342449},{"batb":[[1,3.5,570.44]],"batl":[[1,4,8.66],[2,4.9,2.35]],"ltp":3.6,"tv":8724.4,"id":9633869}]}]}
{"op":"mcm","clk":"4230653343","pt":1631535190696,"mc":[{"id":"1.187557995","rc":[{"batb":[[0,3.6,10],[1,3.55,69.29],[2,3.5,570.44]],"ltp":3.6,"tv":8724.4,"id":9633869}]}]}
{"op":"mcm","clk":"4230653430","pt":1631535191699,"mc":[{"id":"1.187557995","rc":[{"batl":[[0,1.39,425.05],[1,1.4,265.22],[2,1.41,74.5]],"ltp":1.38,"tv":83768.5,"id":9342449}]}]}
{"op":"mcm","clk":"4230653531","pt":1631535192597,"mc":[{"id":"1.187557995","rc":[{"batb":[[0,1.37,77.04],[1,1.36,71.14],[2,1.35,850.79]],"batl":[[0,1.38,60.49],[1,1.39,746.56],[2,1.4,265.22]],"ltp":1.38,"tv":83768.5,"id":9342449}]}]}
{"op":"mcm","clk":"4230653638","pt":1631535193502,"mc":[{"id":"1.187557995","rc":[{"batb":[[2,1.35,3848.27]],"ltp":1.38,"tv":83768.5,"id":9342449},{"batl":[[1,4.9,2.35],[2,5.2,2.18]],"ltp":3.6,"tv":8724.4,"id":9633869}]}]}
{"op":"mcm","clk":"4230653711","pt":1631535194183,"mc":[{"id":"1.187557995","rc":[{"batb":[[1,1.36,251.72]],"ltp":1.38,"tv":83768.5,"id":9342449},{"batl":[[0,3.9,13.17],[1,3.95,9.5],[2,4.9,2.35]],"ltp":3.6,"tv":8724.4,"id":9633869}]}]}
{"op":"mcm","clk":"4230653770","pt":1631535195004,"mc":[{"id":"1.187557995","rc":[{"batl":[[2,4.3,2.95]],"ltp":3.6,"tv":8724.4,"id":9633869}]}]}
{"op":"mcm","clk":"4230653919","pt":1631535196703,"mc":[{"id":"1.187557995","rc":[{"batl":[[0,3.9,21.97]],"ltp":3.6,"tv":8724.4,"id":9633869}]}]}
{"op":"mcm","clk":"4230654001","pt":1631535197608,"mc":[{"id":"1.187557995","rc":[{"batb":[[1,1.36,71.14],[2,1.35,2997.48]],"batl":[[1,1.39,62.97],[2,1.41,15]],"ltp":1.38,"tv":83768.5,"id":9342449},{"batb":[[0,3.5,24],[1,2.9,46.69],[2,2.2,42.67]],"batl":[[0,3.9,8.8],[1,4.3,2.95],[2,4.6,2.46]],"ltp":3.6,"tv":8724.4,"id":9633869}]}]}
{"op":"mcm","clk":"4230654062","pt":1631535198403,"mc":[{"id":"1.187557995","rc":[{"batb":[[2,1.35,77.06]],"batl":[[2,1.49,2.99]],"ltp":1.38,"tv":83768.5,"id":9342449},{"batb":[[0,2.9,46.69],[1,2.2,42.67],[2,2,11.88]],"batl":[[0,4.3,2.95],[1,4.6,2.46],[2,4.9,2.35]],"ltp":3.6,"tv":8724.4,"id":9633869}]}]}
{"op":"mcm","clk":"4230654183","pt":1631535199600,"mc":[{"id":"1.187557995","rc":[{"batb":[[0,1.37,145.99],[1,1.3,444.63],[2,1.28,90.41]],"batl":[[1,1.49,2.99],[2,1.71,553.3]],"ltp":1.38,"tv":83768.5,"id":9342449},{"batl":[[0,4.6,2.46],[1,4.9,2.35],[2,5.2,2.18]],"ltp":3.6,"tv":8724.4,"id":9633869}]}]}
{"op":"mcm","clk":"4230654244","pt":1631535200301,"mc":[{"id":"1.187557995","rc":[{"batb":[[2,1.28,540.48]],"batl":[[2,1.5,298.03]],"ltp":1.38,"tv":83768.5,"id":9342449}]}]}
{"op":"mcm","clk":"4230654358","pt":1631535201410,"mc":[{"id":"1.187557995","rc":[{"batb":[[0,1.3,444.63],[1,1.28,540.48],[2,1.27,988.78]],"batl":[[0,1.49,2.99],[1,1.5,298.03],[2,1.51,191.32]],"ltp":1.38,"tv":83768.5,"id":9342449}]}]}
{"op":"mcm","clk":"4230654553","pt":1631535203602,"mc":[{"id":"1.187557995","rc":[{"batl":[[0,1.37,8],[1,1.49,2.99],[2,1.5,298.03]],"ltp":1.38,"tv":83768.5,"id":9342449}]}]}
{"op":"mcm","clk":"4230654626","pt":1631535204433,"mc":[{"id":"1.187557995","rc":[{"batb":[[1,1.28,90.41],[2,1.27,534.37]],"batl":[[2,1.71,553.3]],"ltp":1.38,"tv":83768.5,"id":9342449}]}]}
{"op":"mcm","clk":"4230654730","pt":1631535205585,"mc":[{"id":"1.187557995","rc":[{"batb":[[0,1.31,92.79],[1,1.3,444.63],[2,1.28,90.41]],"batl":[[1,1.49,201.46]],"ltp":1.38,"tv":83768.5,"id":9342449},{"batl":[[0,4.3,2.55],[1,4.6,2.46],[2,4.9,2.35]],"ltp":3.6,"tv":8724.4,"id":9633869}]}]}
{"op":"mcm","clk":"4230654748","pt":1631535205806,"mc":[{"id":"1.187557995","rc":[{"batb":[[0,1.3,444.63],[1,1.28,90.41],[2,1.27,534.37]],"ltp":1.38,"tv":83768.5,"id":9342449},{"batl":[[0,4.6,2.46],[1,4.9,2.35],[2,5.2,2.18]],"ltp":3.6,"tv":8724.4,"id":9633869}]}]}
{"op":"mcm","clk":"4230654885","pt":1631535207529,"mc":[{"id":"1.187557995","rc":[{"trd":[[1.37,6063.88]],"batb":[[0,1.38,204.76],[1,1.37,388.57],[2,1.36,311.26]],"batl":[[0,1.41,384.17],[1,1.42,248.79],[2,1.49,201.46]],"ltp":1.37,"tv":83784.5,"id":9342449}],"tv":92508.91}]}
{"op":"mcm","clk":"4230655046","pt":1631535209228,"mc":[{"id":"1.187557995","rc":[{"batb":[[0,3.05,79.95],[1,2.9,46.69],[2,2.2,42.67]],"batl":[[0,4.3,2.55],[1,4.6,2.46],[2,4.9,2.35]],"ltp":3.6,"tv":8724.4,"id":9633869}]}]}
{"op":"mcm","clk":"4230655134","pt":1631535210235,"mc":[{"id":"1.187557995","rc":[{"trd":[[1.38,944.7]],"batb":[[0,1.38,88.74]],"ltp":1.38,"tv":84016.52,"id":9342449}],"tv":92740.93}]}
{"op":"mcm","clk":"4230655260","pt":1631535211527,"mc":[{"id":"1.187557995","rc":[{"batb":[[0,1.38,9.47],[1,1.29,245.32],[2,1.28,577.66]],"batl":[[0,1.49,201.46],[1,1.71,553.3],[2,1.82,2.89]],"ltp":1.38,"tv":84016.52,"id":9342449},{"batb":[[0,2.9,46.69],[1,2.2,42.67],[2,2,11.88]],"batl":[[0,4.6,2.46],[1,4.9,2.35],[2,5.2,2.18]],"ltp":3.6,"tv":8724.4,"id":9633869}]}]}
{"op":"mcm","clk":"4230655360","pt":1631535212640,"mc":[{"id":"1.187557995","rc":[{"batb":[[1,1.29,490.63]],"ltp":1.38,"tv":84016.52,"id":9342449}]}]}
{"op":"mcm","clk":"4230655480","pt":1631535214119,"mc":[{"id":"1.187557995","rc":[{"batb":[[2,1.28,1027.73]],"batl":[[1,1.5,298.03],[2,1.51,191.32]],"ltp":1.38,"tv":84016.52,"id":9342449}]}]}
{"op":"mcm","clk":"4230656089","pt":1631535220746,"mc":[{"id":"1.187557995","rc":[{"batb":[[2,1.28,577.66]],"ltp":1.38,"tv":84016.52,"id":9342449}]}]}
{"op":"mcm","clk":"4230656216","pt":1631535222129,"mc":[{"id":"1.187557995","rc":[{"batb":[[1,1.28,90.41],[2,1.27,534.37]],"batl":[[0,1.49,2.99]],"ltp":1.38,"tv":84016.52,"id":9342449}]}]}
{"op":"mcm","clk":"4230656383","pt":1631535223718,"mc":[{"id":"1.187557995","rc":[{"trd":[[1.49,4469.81],[1.5,2096.46]],"batb":[[0,1.46,297.72],[1,1.45,228.69],[2,1.38,9.47]],"batl":[[0,1.5,287.13],[1,1.51,191.32],[2,1.52,2516.44]],"ltp":1.5,"tv":84030.41,"id":9342449},{"trd":[[3,137.9]],"batb":[[1,2,11.88],[2,1.97,1.05]],"batl":[[0,3.2,11.93],[1,3.25,1176.92],[2,3.3,1142.3]],"ltp":3.0,"tv":8731.34,"id":9633869}],"tv":92761.76}]}
{"op":"mcm","clk":"4230656475","pt":1631535224618,"mc":[{"id":"1.187557995","rc":[{"batb":[[0,1.48,169.12],[1,1.46,297.72],[2,1.45,228.69]],"batl":[[2,1.52,692.02]],"ltp":1.5,"tv":84030.41,"id":9342449},{"batb":[[1,2.36,81.09],[2,2,11.88]],"batl":[[1,3.25,588.46],[2,3.3,571.16]],"ltp":3.0,"tv":8731.34,"id":9633869}]}]}
{"op":"mcm","clk":"4230656541","pt":1631535225457,"mc":[{"id":"1.187557995","rc":[{"batl":[[1,1.51,206.32]],"ltp":1.5,"tv":84030.41,"id":9342449},{"batb":[[0,2.92,61.85],[1,2.9,46.69],[2,2.36,81.09]],"ltp":3.0,"tv":8731.34,"id":9633869}]}]}
{"op":"mcm","clk":"4230656635","pt":1631535226355,"mc":[{"id":"1.187557995","rc":[{"batb":[[0,2.92,31.25]],"ltp":3.0,"tv":8731.34,"id":9633869}]}]}
{"op":"mcm","clk":"4230656721","pt":1631535227313,"mc":[{"id":"1.187557995","rc":[{"batl":[[0,1.5,319.5]],"ltp":1.5,"tv":84030.41,"id":9342449}]}]}
{"op":"mcm","clk":"4230656851","pt":1631535228629,"mc":[{"id":"1.187557995","rc":[{"batb":[[0,1.48,237.51],[1,1.47,198.95],[2,1.46,297.72]],"batl":[[0,1.49,43.99],[1,1.5,383],[2,1.51,432.82]],"ltp":1.5,"tv":84030.41,"id":9342449}]}]}
{"op":"mcm","clk":"4230656942","pt":1631535229526,"mc":[{"id":"1.187557995","rc":[{"batb":[[0,2.9,46.69],[1,2.36,81.09],[2,2,11.88]],"ltp":3.0,"tv":8731.34,"id":9633869}]}]}
{"op":"mcm","clk":"4230657060","pt":1631535230630,"mc":[{"id":"1.187557995","rc":[{"trd":[[1.48,6566.86]],"batb":[[0,1.48,216.2]],"ltp":1.48,"tv":84073.01,"id":9342449}],"tv":92804.36}]}
{"op":"mcm","clk":"4230657156","pt":1631535231637,"mc":[{"id":"1.187557995","rc":[{"trd":[[1.48,6600.94]],"batb":[[0,1.48,199.16]],"batl":[[1,1.5,539.84]],"ltp":1.48,"tv":84107.09,"id":9342449}],"tv":92838.44}]}
{"op":"mcm","clk":"4230657256","pt":1631535232632,"mc":[{"id":"1.187557995","rc":[{"trd":[[1.48,6643.54]],"batb":[[0,1.48,177.85]],"ltp":1.48,"tv":84149.69,"id":9342449},{"batb":[[0,2.96,30.61],[1,2.92,30.6],[2,2.9,46.69]],"batl":[[2,3.3,581.05]],"ltp":3.0,"tv":8731.34,"id":9633869}],"tv":92881.04}]}
{"op":"mcm","clk":"4230657342","pt":1631535233318,"mc":[{"id":"1.187557995","rc":[{"trd":[[1.48,6672.06]],"batb":[[0,1.48,163.59]],"batl":[[0,1.49,263.99],[2,1.51,370.36]],"ltp":1.48,"tv":84178.22,"id":9342449},{"batb":[[1,2.9,46.69],[2,2.36,81.09]],"ltp":3.0,"tv":8731.34,"id":9633869}],"tv":92909.56}]}
{"op":"mcm","clk":"4230657477","pt":1631535234636,"mc":[{"id":"1.187557995","rc":[{"batb":[[0,1.48,236.1]],"batl":[[1,1.5,614.75]],"ltp":1.48,"tv":84178.22,"id":9342449}]}]}
{"op":"mcm","clk":"4230657561","pt":1631535235523,"mc":[{"id":"1.187557995","rc":[{"batb":[[0,1.48,163.59],[1,1.47,122.3]],"batl":[[1,1.5,539.84]],"ltp":1.48,"tv":84178.22,"id":9342449}]}]}
{"op":"mcm","clk":"4230657629","pt":1631535236367,"mc":[{"id":"1.187557995","rc":[{"batb":[[0,1.48,68.39],[1,1.39,522.06],[2,1.37,238.41]],"batl":[[1,1.5,63.5],[2,1.51,15]],"ltp":1.48,"tv":84178.22,"id":9342449},{"batb":[[1,2.36,80],[2,1.97,1.05]],"batl":[[0,3.3,9.89],[1,3.6,3.31],[2,3.95,2.9]],"ltp":3.0,"tv":8731.34,"id":9633869}]}]}
{"op":"mcm","clk":"4230657727","pt":1631535237471,"mc":[{"id":"1.187557995","rc":[{"batb":[[0,1.39,522.06],[1,1.37,238.41],[2,1.34,541.27]],"batl":[[0,1.82,2.89],[1,1.95,419.09],[2,2.08,1]],"ltp":1.48,"tv":84178.22,"id":9342449},{"batb":[[0,2.36,80],[1,1.97,1.05],[2,1.67,1.38]],"batl":[[0,3.6,3.31],[1,3.95,2.9],[2,4.6,2.46]],"ltp":3.0,"tv":8731.34,"id":9633869}]}]}
{"op":"mcm","clk":"4230657922","pt":1631535239519,"mc":[{"id":"1.187557995","rc":[{"batb":[[2,1.36,365.36]],"batl":[[0,1.65,194.64],[1,1.66,132.92],[2,1.82,2.89]],"ltp":1.48,"tv":84178.22,"id":9342449}]}]}
{"op":"mcm","clk":"4230658030","pt":1631535240745,"mc":[{"id":"1.187557995","rc":[{"batl":[[2,1.74,5]],"ltp":1.48,"tv":84178.22,"id":9342449},{"batb":[[0,2.36,84],[1,2.34,4],[2,1.97,1.05]],"ltp":3.0,"tv":8731.34,"id":9633869}]}]}
{"op":"mcm","clk":"4230658226","pt":1631535242540,"mc":[{"id":"1.187557995","rc":[{"batl":[[0,1.74,5],[1,1.82,2.89],[2,2.08,1]],"ltp":1.48,"tv":84178.22,"id":9342449}]}]}
{"op":"mcm","clk":"4230658329","pt":1631535243638,"mc":[{"id":"1.187557995","rc":[{"batb":[[0,1.37,238.41],[1,1.36,365.36],[2,1.35,322.93]],"ltp":1.48,"tv":84178.22,"id":9342449},{"batl":[[0,3.95,2.9],[1,4.6,2.46],[2,4.9,2.35]],"ltp":3.0,"tv":8731.34,"id":9633869}]}]}
{"op":"mcm","clk":"4230658421","pt":1631535244653,"mc":[{"id":"1.187557995","rc":[{"batl":[[0,1.52,13.16],[1,1.74,5],[2,1.82,2.89]],"ltp":1.48,"tv":84178.22,"id":9342449},{"batb":[[0,3.5,1092.86],[1,3.45,1060.72],[2,3.4,1060.72]],"ltp":3.0,"tv":8731.34,"id":9633869}]}]}
{"op":"mcm","clk":"4230658511","pt":1631535245651,"mc":[{"id":"1.187557995","rc":[{"trd":[[1.39,207.48]],"batl":[[0,1.39,160.23],[1,1.4,267.29],[2,1.52,13.16]],"ltp":1.39,"tv":84193.47,"id":9342449},{"trd":[[3.55,27.54]],"batb":[[0,3.5,546.44],[1,3.45,605.25],[2,3.4,530.36]],"ltp":3.55,"tv":8737.31,"id":9633869}],"tv":92930.78}]}
{"op":"mcm","clk":"4230658616","pt":1631535246647,"mc":[{"id":"1.187557995","rc":[{"batl":[[2,1.43,15]],"ltp":1.39,"tv":84193.47,"id":9342449},{"batl":[[0,3.85,8.88],[1,3.95,2.9],[2,4.6,2.46]],"ltp":3.55,"tv":8737.31,"id":9633869}]}]}
{"op":"mcm","clk":"4230658643","pt":1631535247060,"mc":[{"id":"1.187557995","rc":[{"batb":[[2,1.35,424.34]],"ltp":1.39,"tv":84193.47,"id":9342449}]}]}
{"op":"mcm","clk":"4230658788","pt":1631535248682,"mc":[{"id":"1.187557995","rc":[{"batl":[[2,1.47,25]],"ltp":1.39,"tv":84193.47,"id":9342449}]}]}
{"op":"mcm","clk":"4230658901","pt":1631535249690,"mc":[{"id":"1.187557995","rc":[{"batb":[[0,1.37,381.63],[1,1.36,436.98]],"batl":[[0,1.38,47.49],[1,1.39,492.47],[2,1.4,341.2]],"ltp":1.39,"tv":84193.47,"id":9342449}]}]}
{"op":"mcm","clk":"4230659115","pt":1631535251675,"mc":[{"id":"1.187557995","rc":[{"trd":[[1.38,978.77]],"batb":[[1,1.36,3276.27]],"batl":[[0,1.38,30.45]],"ltp":1.38,"tv":84227.54,"id":9342449},{"batl":[[2,4.4,2.64]],"ltp":3.55,"tv":8737.31,"id":9633869}],"tv":92964.86}]}
{"op":"mcm","clk":"4230659212","pt":1631535252675,"mc":[{"id":"1.187557995","rc":[{"trd":[[1.38,1021.36]],"batl":[[0,1.38,9.16]],"ltp":1.38,"tv":84270.13,"id":9342449}],"tv":93007.45}]}
{"op":"mcm","clk":"4230659296","pt":1631535253601,"mc":[{"id":"1.187557995","rc":[{"trd":[[1.38,1034.53]],"batl":[[0,1.38,2.57]],"ltp":1.38,"tv":84283.3,"id":9342449},{"batb":[[2,3.4,555.36]],"batl":[[1,3.9,14.5],[2,3.95,2.9]],"ltp":3.55,"tv":8737.31,"id":9633869}],"tv":93020.61}]}
{"op":"mcm","clk":"4230659365","pt":1631535254304,"mc":[{"id":"1.187557995","rc":[{"trd":[[1.37,6832]],"batb":[[0,1.36,3276.27],[1,1.35,424.34],[2,1.34,859.7]],"batl":[[0,1.37,393.02],[1,1.38,2.57],[2,1.39,492.47]],"ltp":1.37,"tv":85051.41,"id":9342449},{"batl":[[1,3.95,2.9],[2,4.4,2.64]],"ltp":3.55,"tv":8737.31,"id":9633869}],"tv":93788.73}]}
{"op":"mcm","clk":"4230659533","pt":1631535256203,"mc":[{"id":"1.187557995","rc":[{"trd":[[1.37,6981.21]],"batb":[[0,1.36,3204.65]],"batl":[[0,1.37,318.42]],"ltp":1.37,"tv":85200.63,"id":9342449},{"batb":[[0,3.55,14.61],[1,3.5,546.44],[2,3.45,605.25]],"ltp":3.55,"tv":8737.31,"id":9633869}],"tv":93937.94}]}
{"op":"mcm","clk":"4230659660","pt":1631535257563,"mc":[{"id":"1.187557995","rc":[{"trd":[[1.37,7054.27]],"batb":[[0,1.36,365.36]],"batl":[[0,1.37,281.89]],"ltp":1.37,"tv":85273.69,"id":9342449}],"tv":94011.0}]}
{"op":"mcm","clk":"4230659743","pt":1631535258598,"mc":[{"id":"1.187557995","rc":[{"batb":[[2,1.34,74.72]],"batl":[[1,1.39,423.2],[2,1.4,267.29]],"ltp":1.37,"tv":85273.69,"id":9342449},{"batb":[[0,3.45,74.89],[1,3.4,25],[2,2.68,57.4]],"ltp":3.55,"tv":8737.31,"id":9633869}]}]}
{"op":"mcm","clk":"4230659841","pt":1631535259298,"mc":[{"id":"1.187557995","rc":[{"batb":[[0,1.35,101.41],[1,1.3,198.47],[2,1.28,577.75]],"batl":[[1,1.39,117],[2,1.42,15]],"ltp":1.37,"tv":85273.69,"id":9342449},{"batb":[[0,3.4,25],[1,2.68,57.4],[2,2.38,4]],"batl":[[1,4.6,2.46],[2,4.9,2.35]],"ltp":3.55,"tv":8737.31,"id":9633869}]}]}
{"op":"mcm","clk":"4230659993","pt":1631535260675,"mc":[{"id":"1.187557995","rc":[{"batb":[[0,1.3,198.47],[1,1.28,577.75],[2,1.26,456.48]],"batl":[[1,1.82,482.09],[2,2.08,1]],"ltp":1.37,"tv":85273.69,"id":9342449},{"batb":[[0,2.68,57.4],[1,2.38,4],[2,1.97,1.05]],"batl":[[0,4.6,2.46],[1,4.9,2.35],[2,5,2.23]],"ltp":3.55,"tv":8737.31,"id":9633869}]}]}
{"op":"mcm","clk":"4230660167","pt":1631535262605,"mc":[{"id":"1.187557995","rc":[{"batb":[[2,1.27,387.34]],"batl":[[1,1.54,151.76],[2,1.55,172.62]],"ltp":1.37,"tv":85273.69,"id":9342449},{"batb":[[0,2.72,55.06]],"ltp":3.55,"tv":8737.31,"id":9633869}]}]}
{"op":"mcm","clk":"4230660277","pt":1631535263781,"mc":[{"id":"1.187557995","rc":[{"batl":[[0,1.54,151.76],[1,1.55,172.62],[2,1.82,482.09]],"ltp":1.37,"tv":85273.69,"id":9342449}]}]}
{"op":"mcm","clk":"4230660553","pt":1631535266973,"mc":[{"id":"1.187557995","rc":[{"batb":[[0,2.84,3],[1,2.82,3],[2,2.72,55.06]],"ltp":3.55,"tv":8737.31,"id":9633869}]}]}
{"op":"mcm","clk":"4230660702","pt":1631535268594,"mc":[{"id":"1.187557995","rc":[{"batl":[[0,1.53,225.72],[1,1.54,151.76],[2,1.55,172.62]],"ltp":1.37,"tv":85273.69,"id":9342449}]}]}
{"op":"mcm","clk":"4230660905","pt":1631535271051,"mc":[{"id":"1.187557995","rc":[{"batb":[[0,1.28,577.75],[1,1.27,387.34],[2,1.26,932.04]],"ltp":1.37,"tv":85273.69,"id":9342449}]}]}
{"op":"mcm","clk":"4230661321","pt":1631535275578,"mc":[{"id":"1.187557995","rc":[{"batb":[[0,1.29,179.73],[1,1.28,577.75],[2,1.27,387.34]],"ltp":1.37,"tv":85273.69,"id":9342449}]}]}
{"op":"mcm","clk":"4230661408","pt":1631535276570,"mc":[{"id":"1.187557995","rc":[{"batl":[[1,1.82,482.09],[2,2.08,1]],"ltp":1.37,"tv":85273.69,"id":9342449}]}]}
{"op":"mcm","clk":"4230661466","pt":1631535277146,"mc":[{"id":"1.187557995","rc":[{"batb":[[0,1.28,577.75],[1,1.27,387.34],[2,1.26,932.04]],"batl":[[0,1.82,482.09],[1,2.08,1],[2,8.8,7.23]],"ltp":1.37,"tv":85273.69,"id":9342449}]}]}
{"op":"mcm","clk":"4230661619","pt":1631535278674,"mc":[{"id":"1.187557995","rc":[{"batb":[[0,1.27,387.34],[1,1.26,932.04],[2,1.25,109.01]],"batl":[[0,1.3,2050.08],[1,1.82,2.89],[2,2.08,1]],"ltp":1.37,"tv":85273.69,"id":9342449},{"batb":[[1,2.72,55.06],[2,1.97,1.05]],"batl":[[0,4.9,2.35],[1,5,2.23],[2,5.2,2.18]],"ltp":3.55,"tv":8737.31,"id":9633869}]}]}
{"op":"mcm","clk":"4230661721","pt":1631535279578,"mc":[{"id":"1.187557995","rc":[{"batl":[[0,1.3,498.18],[1,1.31,1828.73],[2,1.32,1416.98]],"ltp":1.37,"tv":85273.69,"id":9342449},{"batl":[[1,5,212.6],[2,5.1,204.19]],"ltp":3.55,"tv":8737.31,"id":9633869}]}]}
{"op":"mcm","clk":"4230661849","pt":1631535280691,"mc":[{"id":"1.187557995","rc":[{"batb":[[1,1.26,1049.7]],"ltp":1.37,"tv":85273.69,"id":9342449},{"trd":[[4.4,111.56]],"batb":[[0,4.4,77.67],[1,4,20],[2,3.9,15]],"batl":[[0,4.8,7.69],[1,4.9,2.35],[2,5,212.6]],"ltp":4.4,"tv":8747.31,"id":9633869}],"tv":94021.01}]}
{"op":"mcm","clk":"4230661945","pt":1631535281684,"mc":[{"id":"1.187557995","rc":[{"batb":[[2,3.4,76.74]],"batl":[[1,4.9,14.1]],"ltp":4.4,"tv":8747.31,"id":9633869}]}]}
{"op":"mcm","clk":"4230662119","pt":1631535283676,"mc":[{"id":"1.187557995","rc":[{"batb":[[0,1.28,56.19],[1,1.27,387.34],[2,1.26,1049.7]],"batl":[[0,1.29,409.1],[1,1.3,573.83],[2,1.31,1828.73]],"ltp":1.37,"tv":85273.69,"id":9342449}]}]}
{"op":"mcm","clk":"4230662198","pt":1631535284362,"mc":[{"id":"1.187557995","rc":[{"batb":[[1,1.27,461.52]],"batl":[[0,1.29,454.08],[1,1.3,640.83]],"ltp":1.37,"tv":85273.69,"id":9342449},{"batb":[[0,4.4,94.05]],"ltp":4.4,"tv":8747.31,"id":9633869}]}]}
{"op":"mcm","clk":"4230662301","pt":1631535285470,"mc":[{"id":"1.187557995","rc":[{"batb":[[1,3.4,76.74],[2,2.86,3]],"ltp":4.4,"tv":8747.31,"id":9633869}]}]}
{"op":"mcm","clk":"4230662333","pt":1631535285782,"mc":[{"id":"1.187557995","rc":[{"batb":[[2,1.26,3670.58]],"ltp":1.37,"tv":85273.69,"id":9342449}]}]}
{"op":"mcm","clk":"4230662614","pt":1631535288663,"mc":[{"id":"1.187557995","rc":[{"batb":[[1,4.1,19.35],[2,3.4,76.74]],"ltp":4.4,"tv":8747.31,"id":9633869}]}]}
{"op":"mcm","clk":"4230662684","pt":1631535289452,"mc":[{"id":"1.187557995","rc":[{"trd":[[1.28,1544.22],[1.29,3996.71]],"batb":[[0,1.28,53.51]],"batl":[[0,1.29,441.3]],"ltp":1.29,"tv":85304.61,"id":9342449}],"tv":94051.93}]}
{"op":"mcm","clk":"4230662784","pt":1631535290555,"mc":[{"id":"1.187557995","rc":[{"trd":[[1.28,1634.82],[1.29,4130.98]],"batb":[[0,1.27,461.52],[1,1.26,3670.58],[2,1.25,109.01]],"batl":[[0,1.29,172.56],[1,1.3,565.18]],"ltp":1.29,"tv":85529.47,"id":9342449},{"trd":[[4.4,334],[4.5,31.08]],"batb":[[0,4.1,19.35],[1,3.4,76.74],[2,2.86,3]],"ltp":4.4,"tv":8995.52,"id":9633869}],"tv":94524.99}]}
{"op":"mcm","clk":"4230662966","pt":1631535292687,"mc":[{"id":"1.187557995","rc":[{"batb":[[0,1.27,387.34]],"batl":[[0,1.29,103.15]],"ltp":1.29,"tv":85529.47,"id":9342449},{"batb":[[0,4.1,22.35],[1,4,3],[2,3.4,76.74]],"ltp":4.4,"tv":8995.52,"id":9633869}]}]}
{"op":"mcm","clk":"4230663051","pt":1631535293688,"mc":[{"id":"1.187557995","rc":[{"batb":[[0,1.28,120.99],[1,1.27,500.37],[2,1.26,3574.6]],"batl":[[0,1.29,58.17],[1,1.3,735.77],[2,1.31,368.81]],"ltp":1.29,"tv":85529.47,"id":9342449},{"batl":[[1,5.8,2.07],[2,880,0.01]],"ltp":4.4,"tv":8995.52,"id":9633869}]}]}
{"op":"mcm","clk":"4230663153","pt":1631535294577,"mc":[{"id":"1.187557995","rc":[{"batb":[[0,1.26,117.66],[1,1.24,473.59],[2,1.23,109.63]],"batl":[[0,1.3,67],[1,1.32,15],[2,1.36,227.43]],"ltp":1.29,"tv":85529.47,"id":9342449},{"batb":[[0,4.2,30.43],[1,4.1,19.35]],"batl":[[1,5.4,2.14],[2,5.8,2.07]],"ltp":4.4,"tv":8995.52,"id":9633869}]}]}
{"op":"mcm","clk":"4230663252","pt":1631535295582,"mc":[{"id":"1.187557995","rc":[{"batb":[[0,1.24,473.59],[1,1.23,109.63],[2,1.22,524.94]],"batl":[[0,1.36,227.43],[1,1.54,5],[2,1.71,553.2]],"ltp":1.29,"tv":85529.47,"id":9342449},{"batb":[[0,3.4,76.74],[1,1.97,1.05],[2,1.67,1.38]],"batl":[[0,5.4,2.14],[1,5.8,2.07],[2,6,2.01]],"ltp":4.4,"tv":8995.52,"id":9633869}]}]}
{"op":"mcm","clk":"4230663423","pt":1631535297602,"mc":[{"id":"1.187557995","rc":[{"batb":[[0,1.24,572.11]],"batl":[[1,1.4,291.35],[2,1.41,257.6]],"ltp":1.29,"tv":85529.47,"id":9342449},{"batb":[[0,3.35,80.5]],"batl":[[0,5.2,2.23],[1,5.4,2.14],[2,5.8,2.07]],"ltp":4.4,"tv":8995.52,"id":9633869}]}]}
{"op":"mcm","clk":"4230663601","pt":1631535299307,"mc":[{"id":"1.187557995","rc":[{"batl":[[0,1.4,291.35],[1,1.41,257.6],[2,1.54,5]],"ltp":1.29,"tv":85529.47,"id":9342449}]}]}
{"op":"mcm","clk":"4230663835","pt":1631535301690,"mc":[{"id":"1.187557995","rc":[{"batb":[[2,1.21,121.69]],"batl":[[0,1.39,218.06],[1,1.4,291.35],[2,1.41,257.6]],"ltp":1.29,"tv":85529.47,"id":9342449}]}]}
{"op":"mcm","clk":"4230663924","pt":1631535302591,"mc":[{"id":"1.187557995","rc":[{"batl":[[1,1.4,8],[2,1.54,5]],"ltp":1.29,"tv":85529.47,"id":9342449},{"batb":[[0,3.5,3],[1,3.45,3],[2,3.35,80.5]],"ltp":4.4,"tv":8995.52,"id":9633869}]}]}
{"op":"mcm","clk":"4230664109","pt":1631535304608,"mc":[{"id":"1.187557995","rc":[{"batl":[[0,1.39,227.06]],"ltp":1.29,"tv":85529.47,"id":9342449},{"batb":[[0,3.55,3],[1,3.5,3],[2,3.45,3]],"ltp":4.4,"tv":8995.52,"id":9633869}]}]}
{"op":"mcm","clk":"4230664215","pt":1631535305715,"mc":[{"id":"1.187557995","rc":[{"batb":[[0,1.28,136.29],[1,1.24,572.11],[2,1.23,109.63]],"batl":[[0,1.31,19.5],[1,1.39,227.06],[2,1.4,8]],"ltp":1.29,"tv":85529.47,"id":9342449},{"batb":[[0,4.2,19.02],[1,3.55,3],[2,3.5,3]],"batl":[[0,4.6,19.41],[1,5.2,2.23],[2,5.4,2.14]],"ltp":4.4,"tv":8995.52,"id":9633869}]}]}
{"op":"mcm","clk":"4230664238","pt":1631535305877,"mc":[{"id":"1.187557995","rc":[{"batl":[[0,1.39,227.06],[1,1.4,8],[2,1.54,5]],"ltp":1.29,"tv":85529.47,"id":9342449},{"batb":[[0,3.55,3],[1,3.5,3],[2,3.45,3]],"batl":[[0,5.2,2.23],[1,5.4,2.14],[2,5.8,2.07]],"ltp":4.4,"tv":8995.52,"id":9633869}]}]}
{"op":"mcm","clk":"4230664410","pt":1631535307923,"mc":[{"id":"1.187557995","rc":[{"batl":[[1,1.4,299.35],[2,1.41,257.6]],"ltp":1.29,"tv":85529.47,"id":9342449}]}]}
{"op":"mcm","clk":"4230664590","pt":1631535309627,"mc":[{"id":"1.187557995","rc":[{"batb":[[0,1.28,10.68]],"ltp":1.29,"tv":85529.47,"id":9342449}]}]}
{"op":"mcm","clk":"4230664776","pt":1631535311396,"mc":[{"id":"1.187557995","rc":[{"batb":[[1,1.21,121.69],[2,1.2,139.22]],"batl":[[0,1.39,9]],"ltp":1.29,"tv":85529.47,"id":9342449},{"batl":[[0,5.8,2.07],[1,6,2.01],[2,880,0.01]],"ltp":4.4,"tv":8995.52,"id":9633869}]}]}
{"op":"mcm","clk":"4230664885","pt":1631535312605,"mc":[{"id":"1.187557995","rc":[{"trd":[[1.39,215.3]],"batb":[[0,1.37,214.42],[1,1.36,378.78],[2,1.35,1490.53]],"batl":[[0,1.4,291.35],[1,1.41,257.6],[2,1.54,5]],"ltp":1.39,"tv":85537.29,"id":9342449},{"trd":[[3.55,36.6]],"batb":[[0,3.35,394.49],[1,3.3,304.76],[2,3.25,304.76]],"batl":[[0,3.9,9.75],[1,5.8,2.07],[2,6,2.01]],"ltp":3.55,"tv":9004.58,"id":9633869}],"tv":94541.87}]}
{"op":"mcm","clk":"4230664983","pt":1631535313699,"mc":[{"id":"1.187557995","rc":[{"batb":[[0,1.38,228.2],[1,1.37,214.42],[2,1.36,378.78]],"batl":[[2,1.42,15]],"ltp":1.39,"tv":85537.29,"id":9342449},{"batb":[[0,3.4,25],[1,3.35,394.49],[2,3.3,304.76]],"batl":[[0,3.85,8.88],[1,3.9,9.75],[2,5.8,2.07]],"ltp":3.55,"tv":9004.58,"id":9633869}]}]}
{"op":"mcm","clk":"4230665159","pt":1631535315640,"mc":[{"id":"1.187557995","rc":[{"batl":[[0,1.4,327.76]],"ltp":1.39,"tv":85537.29,"id":9342449},{"batl":[[0,3.7,3],[1,3.75,3],[2,3.85,8.88]],"ltp":3.55,"tv":9004.58,"id":9633869}]}]}
{"op":"mcm","clk":"4230665250","pt":1631535316628,"mc":[{"id":"1.187557995","rc":[{"batb":[[0,1.38,423.72],[1,1.37,223.42]],"batl":[[0,1.39,51.75],[1,1.4,562.3],[2,1.41,257.6]],"ltp":1.39,"tv":85537.29,"id":9342449}]}]}
{"op":"mcm","clk":"4230665323","pt":1631535317537,"mc":[{"id":"1.187557995","rc":[{"batb":[[1,1.37,295.42]],"batl":[[2,1.41,329.36]],"ltp":1.39,"tv":85537.29,"id":9342449},{"batl":[[2,3.8,15.52]],"ltp":3.55,"tv":9004.58,"id":9633869}]}]}
{"op":"mcm","clk":"4230665439","pt":1631535318632,"mc":[{"id":"1.187557995","rc":[{"batl":[[1,1.4,673.3]],"ltp":1.39,"tv":85537.29,"id":9342449},{"batb":[[0,3.5,14.57],[1,3.4,25],[2,3.35,394.49]],"ltp":3.55,"tv":9004.58,"id":9633869}]}]}
{"op":"mcm","clk":"4230665465","pt":1631535318934,"mc":[{"id":"1.187557995","rc":[{"batb":[[0,3.4,25],[1,3.35,394.49],[2,3.3,304.76]],"ltp":3.55,"tv":9004.58,"id":9633869}]}]}
{"op":"mcm","clk":"4230665611","pt":1631535320633,"mc":[{"id":"1.187557995","rc":[{"trd":[[1.39,226.38]],"batl":[[0,1.39,43.17]],"ltp":1.39,"tv":85548.37,"id":9342449},{"trd":[[3.55,38.98]],"batl":[[2,3.8,24.48]],"ltp":3.55,"tv":9006.95,"id":9633869}],"tv":94555.33}]}
{"op":"mcm","clk":"4230665735","pt":1631535322138,"mc":[{"id":"1.187557995","rc":[{"batb":[[0,3.45,20.63],[1,3.4,25],[2,3.35,394.49]],"ltp":3.55,"tv":9006.95,"id":9633869}]}]}
{"op":"mcm","clk":"4230665842","pt":1631535323441,"mc":[{"id":"1.187557995","rc":[{"batb":[[0,1.38,503.14],[1,1.37,223.42]],"batl":[[1,1.4,753.14],[2,1.41,257.6]],"ltp":1.39,"tv":85548.37,"id":9342449}]}]}
{"op":"mcm","clk":"4230665909","pt":1631535324133,"mc":[{"id":"1.187557995","rc":[{"batb":[[2,1.36,309.56]],"ltp":1.39,"tv":85548.37,"id":9342449}]}]}
{"op":"mcm","clk":"4230666071","pt":1631535325628,"mc":[{"id":"1.187557995","rc":[{"batb":[[0,1.38,235.2]],"batl":[[0,1.4,402.35],[1,1.41,257.6],[2,1.42,15]],"ltp":1.39,"tv":85548.37,"id":9342449},{"batb":[[0,3.4,25],[1,3.35,80.5],[2,3.25,2]],"batl":[[2,3.8,8.96]],"ltp":3.55,"tv":9006.95,"id":9633869}]}]}
{"op":"mcm","clk":"4230666163","pt":1631535326617,"mc":[{"id":"1.187557995","rc":[{"batb":[[0,1.35,101.41],[1,1.3,296.64],[2,1.29,9]],"batl":[[0,1.42,15],[1,1.62,618.19],[2,1.82,2.89]],"ltp":1.39,"tv":85548.37,"id":9342449},{"batb":[[1,2.62,60.58],[2,1.97,1.05]],"batl":[[0,3.8,8.96],[1,4.4,2.34],[2,4.9,2.25]],"ltp":3.55,"tv":9006.95,"id":9633869}]}]}
{"op":"mcm","clk":"4230666225","pt":1631535327444,"mc":[{"id":"1.187557995","rc":[{"batb":[[0,1.3,296.64],[1,1.29,9],[2,1.27,347.19]],"batl":[[0,1.62,618.19],[1,1.82,2.89],[2,2.08,1]],"ltp":1.39,"tv":85548.37,"id":9342449},{"batb":[[0,2.62,60.58],[1,1.97,1.05],[2,1.67,1.38]],"batl":[[0,4.4,2.34],[1,4.9,2.25],[2,5,2.07]],"ltp":3.55,"tv":9006.95,"id":9633869}]}]}
{"op":"mcm","clk":"4230666338","pt":1631535328647,"mc":[{"id":"1.187557995","rc":[{"batb":[[2,1.27,890.33]],"batl":[[0,1.55,204.98],[1,1.56,168.11],[2,1.62,618.19]],"ltp":1.39,"tv":85548.37,"id":9342449}]}]}
{"op":"mcm","clk":"4230666552","pt":1631535330651,"mc":[{"id":"1.187557995","rc":[{"batl":[[0,1.55,205.07],[2,1.62,622.19]],"ltp":1.39,"tv":85548.37,"id":9342449},{"batb":[[0,2.62,63.58],[1,2.6,4],[2,1.97,1.05]],"batl":[[0,4.4,5.34]],"ltp":3.55,"tv":9006.95,"id":9633869}]}]}
{"op":"mcm","clk":"4230666737","pt":1631535332632,"mc":[{"id":"1.187557995","rc":[{"batl":[[0,1.54,219],[1,1.62,622.19],[2,1.82,2.89]],"ltp":1.39,"tv":85548.37,"id":9342449},{"batb":[[0,2.8,4],[1,2.78,4],[2,2.62,63.58]],"ltp":3.55,"tv":9006.95,"id":9633869}]}]}
{"op":"mcm","clk":"4230666820","pt":1631535333453,"mc":[{"id":"1.187557995","rc":[{"batb":[[0,1.3,78.58]],"batl":[[0,1.62,622.28],[1,1.82,2.89],[2,2.08,1]],"ltp":1.39,"tv":85548.37,"id":9342449}]}]}
{"op":"mcm","clk":"4230666916","pt":1631535334551,"mc":[{"id":"1.187557995","rc":[{"batb":[[0,1.27,890.33],[1,1.26,563.79],[2,1.25,105.13]],"ltp":1.39,"tv":85548.37,"id":9342449},{"batl":[[0,4.9,2.25],[1,5,2.07],[2,5.8,2.07]],"ltp":3.55,"tv":9006.95,"id":9633869}]}]}
{"op":"mcm","clk":"4230667020","pt":1631535335651,"mc":[{"id":"1.187557995","rc":[{"batl":[[0,1.3,353.89],[1,1.31,1830.85],[2,1.32,1416.98]],"ltp":1.39,"tv":85548.37,"id":9342449},{"batl":[[1,5,212.44],[2,5.1,204.19]],"ltp":3.55,"tv":9006.95,"id":9633869}]}]}
{"op":"mcm","clk":"4230667123","pt":1631535336554,"mc":[{"id":"1.187557995","rc":[{"trd":[[1.3,762.74]],"batl":[[0,1.3,337.35]],"ltp":1.3,"tv":85564.91,"id":9342449},{"trd":[[4.3,15.38]],"batb":[[0,4.2,91.63],[1,4,20],[2,3.3,83.85]],"batl":[[0,4.7,7.79],[1,4.9,2.25],[2,5,212.44]],"ltp":4.3,"tv":9011.95,"id":9633869}],"tv":94576.87}]}
{"op":"mcm","clk":"4230667214","pt":1631535337353,"mc":[{"id":"1.187557995","rc":[{"batb":[[0,1.28,9],[1,1.27,1011.8],[2,1.26,563.79]],"ltp":1.3,"tv":85564.91,"id":9342449},{"batl":[[0,4.7,10.79],[1,4.8,11.25],[2,4.9,2.25]],"ltp":4.3,"tv":9011.95,"id":9633869}]}]}
{"op":"mcm","clk":"4230667300","pt":1631535338390,"mc":[{"id":"1.187557995","rc":[{"batb":[[1,3.3,83.85],[2,2.82,3]],"ltp":4.3,"tv":9011.95,"id":9633869}]}]}
{"op":"mcm","clk":"4230667394","pt":1631535339495,"mc":[{"id":"1.187557995","rc":[{"batb":[[0,1.28,67.73]],"batl":[[0,1.29,115.25],[1,1.3,414.42],[2,1.31,1830.85]],"ltp":1.3,"tv":85564.91,"id":9342449}]}]}
{"op":"mcm","clk":"4230667501","pt":1631535340467,"mc":[{"id":"1.187557995","rc":[{"batb":[[0,1.28,175.68],[1,1.27,1088.01]],"batl":[[0,1.29,277.84],[1,1.3,865.5]],"ltp":1.3,"tv":85564.91,"id":9342449},{"batb":[[0,4.3,20],[1,4.2,91.63],[2,3.3,83.85]],"batl":[[0,4.6,3],[1,4.7,10.79],[2,4.8,11.25]],"ltp":4.3,"tv":9011.95,"id":9633869}]}]}
{"op":"mcm","clk":"4230667601","pt":1631535341569,"mc":[{"id":"1.187557995","rc":[{"batb":[[2,4.1,19.35]],"ltp":4.3,"tv":9011.95,"id":9633869}]}]}
{"op":"mcm","clk":"4230667798","pt":1631535343627,"mc":[{"id":"1.187557995","rc":[{"trd":[[1.28,1640.24],[1.29,4135.34]],"batb":[[0,1.28,172.97]],"batl":[[0,1.29,275.66]],"ltp":1.29,"tv":85574.69,"id":9342449}],"tv":94586.65}]}
{"op":"mcm","clk":"4230668047","pt":1631535346355,"mc":[{"id":"1.187557995","rc":[{"batb":[[1,1.27,1011.8]],"batl":[[1,1.3,788.43]],"ltp":1.29,"tv":85574.69,"id":9342449}]}]}
{"op":"mcm","clk":"4230668160","pt":1631535347678,"mc":[{"id":"1.187557995","rc":[{"batb":[[0,1.28,166.68],[1,1.27,115.47],[2,1.23,115.63]],"batl":[[1,1.3,277.58],[2,1.32,15]],"ltp":1.29,"tv":85574.69,"id":9342449},{"batb":[[0,4.1,19.35],[1,3.3,83.85],[2,2.82,3]],"batl":[[0,4.7,7.79],[1,5.4,2.19],[2,5.8,2.07]],"ltp":4.3,"tv":9011.95,"id":9633869}]}]}
{"op":"mcm","clk":"4230668243","pt":1631535348669,"mc":[{"id":"1.187557995","rc":[{"batb":[[0,1.23,115.63],[1,1.22,455.71],[2,1.21,121.69]],"batl":[[0,1.42,189.1],[1,1.55,6],[2,1.62,618.19]],"ltp":1.29,"tv":85574.69,"id":9342449},{"batb":[[0,3.3,83.85],[1,2.82,3],[2,1.97,1.05]],"batl":[[0,5.4,2.19],[1,5.8,2.07],[2,6,2.01]],"ltp":4.3,"tv":9011.95,"id":9633869}]}]}
{"op":"mcm","clk":"4230668253","pt":1631535348770,"mc":[{"id":"1.187557995","rc":[{"batb":[[0,1.22,455.71],[1,1.21,121.69],[2,1.2,627.25]],"ltp":1.29,"tv":85574.69,"id":9342449},{"batl":[[0,5.8,2.07],[1,6,2.01],[2,880,0.01]],"ltp":4.3,"tv":9011.95,"id":9633869}]}]}
{"op":"mcm","clk":"4230668399","pt":1631535350339,"mc":[{"id":"1.187557995","rc":[{"batb":[[1,1.21,338.19],[2,1.2,1280.63]],"batl":[[0,1.41,403.7],[1,1.42,437.6],[2,1.55,6]],"ltp":1.29,"tv":85574.69,"id":9342449}]}]}
{"op":"mcm","clk":"4230668519","pt":1631535351649,"mc":[{"id":"1.187557995","rc":[{"batb":[[0,1.23,11],[1,1.22,468.71],[2,1.21,121.69]],"batl":[[0,1.42,196.1],[1,1.55,6],[2,1.62,618.19]],"ltp":1.29,"tv":85574.69,"id":9342449},{"batb":[[0,3.35,3],[1,3.3,86.85],[2,2.82,3]],"batl":[[0,5.4,2],[1,5.8,2.07],[2,6,2.01]],"ltp":4.3,"tv":9011.95,"id":9633869}]}]}
{"op":"mcm","clk":"4230668586","pt":1631535352369,"mc":[{"id":"1.187557995","rc":[{"batb":[[2,1.21,135.69]],"ltp":1.29,"tv":85574.69,"id":9342449},{"batl":[[1,5.6,2],[2,5.8,2.07]],"ltp":4.3,"tv":9011.95,"id":9633869}]}]}
{"op":"mcm","clk":"4230668697","pt":1631535353449,"mc":[{"id":"1.187557995","rc":[{"batl":[[0,1.41,7.1],[1,1.42,196.1],[2,1.55,6]],"ltp":1.29,"tv":85574.69,"id":9342449},{"batb":[[0,3.4,3],[1,3.35,3],[2,3.3,86.85]],"ltp":4.3,"tv":9011.95,"id":9633869}]}]}
{"op":"mcm","clk":"4230668803","pt":1631535354656,"mc":[{"id":"1.187557995","rc":[{"trd":[[1.28,1640.44]],"batb":[[0,1.29,583.59],[1,1.28,433.4],[2,1.24,18.08]],"batl":[[0,1.31,19.5],[1,1.32,346.36],[2,1.33,342.17]],"ltp":1.28,"tv":85574.89,"id":9342449},{"batb":[[0,4.2,20.07],[1,3.4,3],[2,3.35,3]],"batl":[[0,4.6,20.61],[1,5.4,2],[2,5.6,2]],"ltp":4.3,"tv":9011.95,"id":9633869}],"tv":94586.85}]}
{"op":"mcm","clk":"4230668879","pt":1631535355543,"mc":[{"id":"1.187557995","rc":[{"batl":[[0,1.32,346.36],[1,1.33,342.17],[2,1.41,227.61]],"ltp":1.28,"tv":85574.89,"id":9342449},{"batb":[[0,3.4,3],[1,3.35,3],[2,3.3,86.85]],"batl":[[0,5.4,4.24],[1,5.6,2],[2,5.8,2.07]],"ltp":4.3,"tv":9011.95,"id":9633869}]}]}
{"op":"mcm","clk":"4230668955","pt":1631535356544,"mc":[{"id":"1.187557995","rc":[{"batb":[[2,1.24,73.08]],"batl":[[2,1.38,179.45]],"ltp":1.28,"tv":85574.89,"id":9342449},{"batb":[[0,3.65,15],[1,3.4,3],[2,3.35,3]],"batl":[[0,5.2,10],[1,5.4,4.24],[2,5.6,2]],"ltp":4.3,"tv":9011.95,"id":9633869}]}]}
{"op":"mcm","clk":"4230669064","pt":1631535357685,"mc":[{"id":"1.187557995","rc":[{"batb":[[0,1.29,136.29],[1,1.24,25.08],[2,1.23,127.71]],"batl":[[0,1.41,227.61],[1,1.42,7],[2,1.55,6]],"ltp":1.28,"tv":85574.89,"id":9342449},{"batb":[[0,3.4,3],[1,3.35,3],[2,3.3,86.85]],"batl":[[0,5.2,2]],"ltp":4.3,"tv":9011.95,"id":9633869}]}]}
{"op":"mcm","clk":"4230669165","pt":1631535358668,"mc":[{"id":"1.187557995","rc":[{"batb":[[0,1.3,91.69],[1,1.29,11.21],[2,1.24,25.08]],"batl":[[0,1.31,149.68],[1,1.41,227.61],[2,1.42,7]],"ltp":1.28,"tv":85574.89,"id":9342449}]}]}
{"op":"mcm","clk":"4230669238","pt":1631535359465,"mc":[{"id":"1.187557995","rc":[{"batb":[[0,1.29,11.21],[1,1.24,25.08],[2,1.23,29.08]],"batl":[[0,1.41,227.61],[1,1.42,7],[2,1.55,6]],"ltp":1.28,"tv":85574.89,"id":9342449},{"batl":[[1,5.4,2]],"ltp":4.3,"tv":9011.95,"id":9633869}]}]}
{"op":"mcm","clk":"4230669343","pt":1631535360664,"mc":[{"id":"1.187557995","rc":[{"batb":[[0,1.3,18.08],[1,1.29,11.21],[2,1.24,25.08]],"batl":[[0,1.41,631.36],[1,1.42,255.5]],"ltp":1.28,"tv":85574.89,"id":9342449}]}]}
{"op":"mcm","clk":"4230669373","pt":1631535360984,"mc":[{"id":"1.187557995","rc":[{"batb":[[0,1.29,11.21],[1,1.24,25.08],[2,1.23,29.08]],"ltp":1.28,"tv":85574.89,"id":9342449}]}]}
{"op":"mcm","clk":"4230669862","pt":1631535365998,"mc":[{"id":"1.187557995","rc":[{"batb":[[2,1.23,18.08]],"batl":[[1,1.42,248.5],[2,1.62,618.19]],"ltp":1.28,"tv":85574.89,"id":9342449},{"batb":[[1,3.3,83.85],[2,1.97,1.05]],"batl":[[1,5.8,2.07],[2,6,2.01]],"ltp":4.3,"tv":9011.95,"id":9633869}]}]}
{"op":"mcm","clk":"4230670070","pt":1631535368296,"mc":[{"id":"1.187557995","rc":[{"batl":[[0,1.41,403.75]],"ltp":1.28,"tv":85574.89,"id":9342449},{"batb":[[0,3.3,83.85],[1,1.97,1.05],[2,1.67,1.38]],"batl":[[1,6,2.01],[2,880,0.01]],"ltp":4.3,"tv":9011.95,"id":9633869}]}]}
{"op":"mcm","clk":"4230670189","pt":1631535369707,"mc":[{"id":"1.187557995","rc":[{"trd":[[1.41,839.86]],"batb":[[0,1.37,366.98],[1,1.36,310.89],[2,1.35,84.27]],"batl":[[0,1.41,389.14]],"ltp":1.41,"tv":85589.5,"id":9342449},{"trd":[[3.4,21.3]],"batb":[[0,3.35,1141.78],[1,3.3,1192.05],[2,3.25,1108.2]],"batl":[[0,3.8,1020],[1,3.9,999.75],[2,3.95,990]],"ltp":3.4,"tv":9018.01,"id":9633869}],"tv":94607.52}]}
{"op":"mcm","clk":"4230670289","pt":1631535370691,"mc":[{"id":"1.187557995","rc":[{"batb":[[0,1.39,221.34],[1,1.37,366.98],[2,1.36,310.89]],"batl":[[2,1.53,13.07]],"ltp":1.41,"tv":85589.5,"id":9342449},{"batb":[[0,3.35,313.99],[1,3.3,388.61],[2,3.25,304.76]],"batl":[[0,3.8,510],[1,3.9,504.75],[2,3.95,495]],"ltp":3.4,"tv":9018.01,"id":9633869}]}]}
{"op":"mcm","clk":"4230670388","pt":1631535371688,"mc":[{"id":"1.187557995","rc":[{"batl":[[0,1.41,432.16],[2,1.43,15]],"ltp":1.41,"tv":85589.5,"id":9342449},{"batb":[[0,3.35,339.52]],"batl":[[1,3.85,8.88],[2,3.9,504.75]],"ltp":3.4,"tv":9018.01,"id":9633869}]}]}
{"op":"mcm","clk":"4230670486","pt":1631535372679,"mc":[{"id":"1.187557995","rc":[{"batb":[[2,1.36,317.89]],"ltp":1.41,"tv":85589.5,"id":9342449},{"batl":[[0,3.7,3],[1,3.75,3],[2,3.8,510]],"ltp":3.4,"tv":9018.01,"id":9633869}]}]}
{"op":"mcm","clk":"4230670523","pt":1631535373085,"mc":[{"id":"1.187557995","rc":[{"batb":[[1,1.38,6],[2,1.37,375.98]],"ltp":1.41,"tv":85589.5,"id":9342449}]}]}
{"op":"mcm","clk":"4230670671","pt":1631535374708,"mc":[{"id":"1.187557995","rc":[{"batb":[[0,1.39,366.48],[1,1.38,80.87]],"batl":[[0,1.4,40.85],[1,1.41,743.04],[2,1.42,314.85]],"ltp":1.41,"tv":85589.5,"id":9342449},{"batb":[[0,3.4,22.6],[1,3.35,339.52],[2,3.3,388.61]],"batl":[[1,3.75,17.97]],"ltp":3.4,"tv":9018.01,"id":9633869}]}]}
{"op":"mcm","clk":"4230671026","pt":1631535378190,"mc":[{"id":"1.187557995","rc":[{"trd":[[1.4,1137.24]],"batl":[[0,1.4,38.35]],"ltp":1.4,"tv":85594.51,"id":9342449},{"batl":[[1,3.75,27.01]],"ltp":3.4,"tv":9018.01,"id":9633869}],"tv":94612.52}]}
{"op":"mcm","clk":"4230671096","pt":1631535379066,"mc":[{"id":"1.187557995","rc":[{"batl":[[2,1.42,248.5]],"ltp":1.4,"tv":85594.51,"id":9342449}]}]}
{"op":"mcm","clk":"4230671253","pt":1631535380701,"mc":[{"id":"1.187557995","rc":[{"batb":[[0,1.39,422.35]],"batl":[[1,1.41,806.7]],"ltp":1.4,"tv":85594.51,"id":9342449}]}]}
{"op":"mcm","clk":"4230671274","pt":1631535380908,"mc":[{"id":"1.187557995","rc":[{"batb":[[0,1.39,366.48],[1,1.38,6]],"batl":[[1,1.41,743.04]],"ltp":1.4,"tv":85594.51,"id":9342449}]}]}
{"op":"mcm","clk":"4230671508","pt":1631535383201,"mc":[{"id":"1.187557995","rc":[{"trd":[[1.39,822.69]],"batb":[[0,1.38,6],[1,1.37,375.98],[2,1.36,417.89]],"batl":[[0,1.39,407.79],[1,1.41,663.93]],"ltp":1.39,"tv":86190.82,"id":9342449},{"batl":[[0,3.75,27.01],[1,3.8,510],[2,3.9,504.75]],"ltp":3.4,"tv":9018.01,"id":9633869}],"tv":95208.84}]}
{"op":"mcm","clk":"4230671842","pt":1631535386190,"mc":[{"id":"1.187557995","rc":[{"batb":[[1,1.37,430.23],[2,1.36,410.89]],"batl":[[0,1.39,124.21]],"ltp":1.39,"tv":86190.82,"id":9342449},{"batl":[[0,3.6,3],[1,3.75,27.01],[2,3.8,510]],"ltp":3.4,"tv":9018.01,"id":9633869}]}]}
{"op":"mcm","clk":"4230672055","pt":1631535388392,"mc":[{"id":"1.187557995","rc":[{"batb":[[0,1.36,100],[1,1.3,265.22],[2,1.28,335.98]],"batl":[[0,1.41,99],[1,1.43,15],[2,1.62,618.19]],"ltp":1.39,"tv":86190.82,"id":9342449},{"batb":[[0,3.35,25.53],[1,2.58,63.18],[2,1.97,1.05]],"batl":[[0,3.75,9.04],[1,4.4,2.44],[2,4.9,2.35]],"ltp":3.4,"tv":9018.01,"id":9633869}]}]}
{"op":"mcm","clk":"4230672197","pt":1631535389701,"mc":[{"id":"1.187557995","rc":[{"batb":[[0,1.3,184.84],[1,1.28,335.98],[2,1.26,95.98]],"batl":[[0,1.62,618.19],[1,1.82,2.89],[2,2.08,1]],"ltp":1.39,"tv":86190.82,"id":9342449},{"batb":[[0,2.58,63.18],[1,1.97,1.05],[2,1.67,1.38]],"batl":[[0,4.9,2.35],[1,5,2.17],[2,5.4,2.29]],"ltp":3.4,"tv":9018.01,"id":9633869}]}]}
{"op":"mcm","clk":"4230672384","pt":1631535391692,"mc":[{"id":"1.187557995","rc":[{"batb":[[1,1.28,258.91],[2,1.27,797.01]],"batl":[[0,1.56,244.25],[1,1.57,163.78],[2,1.62,618.19]],"ltp":1.39,"tv":86190.82,"id":9342449},{"batb":[[0,2.62,60.75]],"ltp":3.4,"tv":9018.01,"id":9633869}]}]}
{"op":"mcm","clk":"4230672576","pt":1631535393467,"mc":[{"id":"1.187557995","rc":[{"batb":[[0,1.3,194.84],[1,1.29,8],[2,1.27,346.1]],"batl":[[0,1.62,623.19],[1,1.82,2.89],[2,2.08,1]],"ltp":1.39,"tv":86190.82,"id":9342449},{"batb":[[1,2.6,4],[2,2.58,4]],"batl":[[0,4.4,3],[1,4.6,3],[2,4.9,2.35]],"ltp":3.4,"tv":9018.01,"id":9633869}]}]}
{"op":"mcm","clk":"4230672783","pt":1631535395642,"mc":[{"id":"1.187557995","rc":[{"batl":[[0,1.55,215.5],[1,1.62,623.19],[2,1.82,2.89]],"ltp":1.39,"tv":86190.82,"id":9342449}]}]}
{"op":"mcm","clk":"4230672894","pt":1631535396645,"mc":[{"id":"1.187557995","rc":[{"batb":[[0,1.4,381.54],[1,1.39,278.14],[2,1.3,273.12]],"batl":[[0,1.43,189.18],[1,1.44,234.79],[2,1.55,215.5]],"ltp":1.39,"tv":86190.82,"id":9342449},{"batb":[[0,2.62,64.75]],"batl":[[0,4.4,5.44]],"ltp":3.4,"tv":9018.01,"id":9633869}]}]}
{"op":"mcm","clk":"4230673046","pt":1631535398365,"mc":[{"id":"1.187557995","rc":[{"batb":[[2,1.33,157.07]],"batl":[[2,1.52,153.79]],"ltp":1.39,"tv":86190.82,"id":9342449},{"batb":[[0,2.92,80.64],[1,2.62,64.75],[2,2.6,4]],"batl":[[0,4.1,15],[1,4.4,5.44],[2,4.6,3]],"ltp":3.4,"tv":9018.01,"id":9633869}]}]}
{"op":"mcm","clk":"4230673241","pt":1631535400454,"mc":[{"id":"1.187557995","rc":[{"batb":[[0,1.4,10.7],[1,1.3,273.12],[2,1.29,8]],"batl":[[0,1.55,215.5],[1,1.62,623.19],[2,1.82,2.89]],"ltp":1.39,"tv":86190.82,"id":9342449},{"batb":[[0,2.62,64.75],[1,2.6,4],[2,2.58,4]],"batl":[[0,4.4,5.44],[1,4.6,3],[2,4.9,2.35]],"ltp":3.4,"tv":9018.01,"id":9633869}]}]}
{"op":"mcm","clk":"4230673341","pt":1631535401555,"mc":[{"id":"1.187557995","rc":[{"batb":[[1,1.3,194.84]],"batl":[[0,1.43,121.07],[1,1.55,215.5],[2,1.62,623.19]],"ltp":1.39,"tv":86190.82,"id":9342449},{"batl":[[0,4.4,3]],"ltp":3.4,"tv":9018.01,"id":9633869}]}]}
{"op":"mcm","clk":"4230673373","pt":1631535401863,"mc":[{"id":"1.187557995","rc":[{"batl":[[0,1.55,215.5],[1,1.62,623.19],[2,1.82,2.89]],"ltp":1.39,"tv":86190.82,"id":9342449}]}]}
{"op":"mcm","clk":"4230673534","pt":1631535403281,"mc":[{"id":"1.187557995","rc":[{"batl":[[1,1.56,244.25],[2,1.57,163.78]],"ltp":1.39,"tv":86190.82,"id":9342449}]}]}
{"op":"mcm","clk":"4230673607","pt":1631535404275,"mc":[{"id":"1.187557995","rc":[{"batb":[[2,1.28,258.91]],"ltp":1.39,"tv":86190.82,"id":9342449},{"batb":[[1,1.97,1.05],[2,1.67,1.38]],"batl":[[1,4.9,2.35],[2,5,2.17]],"ltp":3.4,"tv":9018.01,"id":9633869}]}]}
{"op":"mcm","clk":"4230673689","pt":1631535405370,"mc":[{"id":"1.187557995","rc":[{"batb":[[0,1.3,194.84],[1,1.29,200]],"batl":[[1,1.62,623.19],[2,1.82,2.89]],"ltp":1.39,"tv":86190.82,"id":9342449}]}]}
{"op":"mcm","clk":"4230673777","pt":1631535406269,"mc":[{"id":"1.187557995","rc":[{"batb":[[0,1.29,200],[1,1.28,258.91],[2,1.27,797.01]],"batl":[[0,1.62,623.19],[1,1.82,2.89],[2,2.08,1]],"ltp":1.39,"tv":86190.82,"id":9342449},{"batl":[[0,4.9,2.35],[1,5,2.17],[2,5.4,2.29]],"ltp":3.4,"tv":9018.01,"id":9633869}]}]}
{"op":"mcm","clk":"4230673896","pt":1631535407578,"mc":[{"id":"1.187557995","rc":[{"batb":[[0,1.3,79.88],[1,1.29,200],[2,1.28,258.91]],"batl":[[0,1.31,2570.58],[1,1.32,2897.72],[2,1.33,2812.5]],"ltp":1.39,"tv":86190.82,"id":9342449},{"batl":[[0,4.4,2.49],[1,4.8,796.88],[2,4.9,775.79]],"ltp":3.4,"tv":9018.01,"id":9633869}]}]}
{"op":"mcm","clk":"4230673990","pt":1631535408569,"mc":[{"id":"1.187557995","rc":[{"trd":[[1.3,779.28]],"batb":[[0,1.29,200],[1,1.28,258.91],[2,1.27,797.01]],"batl":[[0,1.3,179.77],[1,1.31,393.37],[2,1.32,1448.86]],"ltp":1.3,"tv":86207.36,"id":9342449},{"trd":[[4.3,20.38]],"batb":[[0,4.2,92.05],[1,3.3,84.18],[2,2.84,584.45]],"batl":[[0,4.8,219.14],[1,4.9,215.05],[2,5,214.87]],"ltp":4.3,"tv":9023.01,"id":9633869}],"tv":95230.38}]}
{"op":"mcm","clk":"4230674076","pt":1631535409510,"mc":[{"id":"1.187557995","rc":[{"batb":[[2,1.27,912.48]],"ltp":1.3,"tv":86207.36,"id":9342449},{"batb":[[1,4,20],[2,3.8,63.39]],"batl":[[0,4.7,7.79],[1,4.8,230.89],[2,4.9,215.05]],"ltp":4.3,"tv":9023.01,"id":9633869}]}]}
{"op":"mcm","clk":"4230674111","pt":1631535409869,"mc":[{"id":"1.187557995","rc":[{"batb":[[2,3.3,84.18]],"ltp":4.3,"tv":9023.01,"id":9633869}]}]}
{"op":"mcm","clk":"4230674391","pt":1631535412593,"mc":[{"id":"1.187557995","rc":[{"batb":[[0,1.29,265.03],[1,1.28,330.35]],"batl":[[0,1.3,299.57],[1,1.31,600.32]],"ltp":1.3,"tv":86207.36,"id":9342449}]}]}
{"op":"mcm","clk":"4230674491","pt":1631535413586,"mc":[{"id":"1.187557995","rc":[{"batl":[[0,1.3,347.54]],"ltp":1.3,"tv":86207.36,"id":9342449},{"batb":[[0,4.3,16.03],[1,4.2,92.05],[2,4,20]],"ltp":4.3,"tv":9023.01,"id":9633869}]}]}
{"op":"mcm","clk":"4230674546","pt":1631535414209,"mc":[{"id":"1.187557995","rc":[{"batb":[[0,1.29,283.11]],"batl":[[0,1.3,588.54]],"ltp":1.3,"tv":86207.36,"id":9342449}]}]}
{"op":"mcm","clk":"4230674671","pt":1631535415717,"mc":[{"id":"1.187557995","rc":[{"batb":[[1,1.28,348.43]],"ltp":1.3,"tv":86207.36,"id":9342449}]}]}
{"op":"mcm","clk":"4230674751","pt":1631535416615,"mc":[{"id":"1.187557995","rc":[{"batb":[[0,1.29,83.11]],"ltp":1.3,"tv":86207.36,"id":9342449}]}]}
{"op":"mcm","clk":"4230674799","pt":1631535417084,"mc":[{"id":"1.187557995","rc":[{"batb":[[1,1.28,330.35]],"batl":[[1,1.31,525.16]],"ltp":1.3,"tv":86207.36,"id":9342449}]}]}
{"op":"mcm","clk":"4230674942","pt":1631535418709,"mc":[{"id":"1.187557995","rc":[{"trd":[[1.29,4435.45]],"batb":[[0,1.28,330.35],[1,1.27,912.48],[2,1.26,95.98]],"batl":[[0,1.29,555.84],[1,1.3,791.34],[2,1.31,525.16]],"ltp":1.29,"tv":86507.47,"id":9342449}],"tv":95530.49}]}
{"op":"mcm","clk":"4230675039","pt":1631535419696,"mc":[{"id":"1.187557995","rc":[{"trd":[[1.27,107.51],[1.28,2158.26],[1.29,4835.45]],"batb":[[0,1.27,871.37],[1,1.26,95.98],[2,1.25,93.45]],"batl":[[0,1.29,355.84],[1,1.3,603.13],[2,1.31,504.76]],"ltp":1.29,"tv":87507.49,"id":9342449}],"tv":96530.51}]}
{"op":"mcm","clk":"4230675135","pt":1631535420694,"mc":[{"id":"1.187557995","rc":[{"batb":[[0,1.27,420.46]],"batl":[[1,1.3,420.67],[2,1.31,131.79]],"ltp":1.29,"tv":87507.49,"id":9342449}]}]}
{"op":"mcm","clk":"4230675275","pt":1631535422417,"mc":[{"id":"1.187557995","rc":[{"batb":[[0,1.28,8],[1,1.27,431.46],[2,1.26,95.98]],"batl":[[0,1.29,505.98]],"ltp":1.29,"tv":87507.49,"id":9342449},{"batl":[[0,4.6,2],[1,4.7,7.79],[2,4.8,230.89]],"ltp":4.3,"tv":9023.01,"id":9633869}]}]}
{"op":"mcm","clk":"4230675388","pt":1631535423524,"mc":[{"id":"1.187557995","rc":[{"batb":[[0,1.27,115.47],[1,1.24,390.97],[2,1.23,110.63]],"batl":[[0,1.29,358.55],[1,1.33,15],[2,1.41,246.17]],"ltp":1.29,"tv":87507.49,"id":9342449},{"batb":[[0,4,20],[1,3.3,83.85],[2,2.82,3]],"batl":[[0,4.7,7.79],[1,5.4,2.29],[2,5.8,2.07]],"ltp":4.3,"tv":9023.01,"id":9633869}]}]}
{"op":"mcm","clk":"4230675509","pt":1631535424597,"mc":[{"id":"1.187557995","rc":[{"batb":[[0,1.24,390.97],[1,1.23,110.63],[2,1.21,132.69]],"batl":[[0,1.29,355.84],[1,1.41,246.17],[2,1.54,6]],"ltp":1.29,"tv":87507.49,"id":9342449},{"batb":[[0,3.3,83.85],[1,2.82,3],[2,1.97,1.05]],"batl":[[0,5.4,2.29],[1,5.8,2.07],[2,6,2.01]],"ltp":4.3,"tv":9023.01,"id":9633869}]}]}
{"op":"mcm","clk":"4230675677","pt":1631535426520,"mc":[{"id":"1.187557995","rc":[{"batb":[[2,1.21,349.06]],"batl":[[1,1.41,631.31],[2,1.42,249.72]],"ltp":1.29,"tv":87507.49,"id":9342449}]}]}
{"op":"mcm","clk":"4230675797","pt":1631535427723,"mc":[{"id":"1.187557995","rc":[{"batb":[[0,1.24,402.97],[1,1.23,119.63]],"ltp":1.29,"tv":87507.49,"id":9342449},{"batl":[[0,5.2,3],[1,5.4,2.29],[2,5.8,2.07]],"ltp":4.3,"tv":9023.01,"id":9633869}]}]}
{"op":"mcm","clk":"4230676223","pt":1631535432026,"mc":[{"id":"1.187557995","rc":[{"batl":[[1,1.4,16.66],[2,1.41,631.31]],"ltp":1.29,"tv":87507.49,"id":9342449}]}]}
{"op":"mcm","clk":"4230676316","pt":1631535432924,"mc":[{"id":"1.187557995","rc":[{"batl":[[1,1.41,631.31],[2,1.42,249.72]],"ltp":1.29,"tv":87507.49,"id":9342449}]}]}
{"op":"mcm","clk":"4230676729","pt":1631535437397,"mc":[{"id":"1.187557995","rc":[{"batb":[[0,1.24,390.97],[1,1.23,9],[2,1.21,216.37]],"batl":[[1,1.4,7.23],[2,1.41,246.17]],"ltp":1.29,"tv":87507.49,"id":9342449},{"batl":[[0,6,2.01],[1,880,0.01],[2,5.8,0]],"ltp":4.3,"tv":9023.01,"id":9633869}]}]}
{"op":"mcm","clk":"4230676799","pt":1631535438262,"mc":[{"id":"1.187557995","rc":[{"batb":[[0,1.21,216.37],[1,1.2,1812.57],[2,1.1,297.11]],"batl":[[2,1.54,6]],"ltp":1.29,"tv":87507.49,"id":9342449}]}]}
{"op":"mcm","clk":"4230676919","pt":1631535439695,"mc":[{"id":"1.187557995","rc":[{"batb":[[2,1.06,2.07]],"batl":[[1,1.33,15.04],[2,1.4,7.23]],"ltp":1.29,"tv":87507.49,"id":9342449},{"batb":[[0,5.3,735.58],[1,5.1,713.94],[2,5,713.94]],"batl":[[1,6.2,616.94],[2,6.4,598.8]],"ltp":4.3,"tv":9023.01,"id":9633869}]}]}
{"op":"mcm","clk":"4230676999","pt":1631535440639,"mc":[{"id":"1.187557995","rc":[{"batb":[[2,1.17,596.39]],"batl":[[0,1.23,549.43],[1,1.24,510.5],[2,1.29,355.84]],"ltp":1.29,"tv":87507.49,"id":9342449},{"trd":[[5.3,8.34]],"batb":[[0,5.3,363.61],[1,5.2,55.65],[2,5.1,356.96]],"batl":[[0,6,5.01],[1,6.2,308.46],[2,6.4,299.4]],"ltp":5.3,"tv":9031.35,"id":9633869}],"tv":96538.85}]}
{"op":"mcm","clk":"4230677083","pt":1631535441521,"mc":[{"id":"1.187557995","rc":[{"batb":[[0,1.21,361.3],[1,1.2,1292.78]],"batl":[[2,1.26,15]],"ltp":1.29,"tv":87507.49,"id":9342449},{"batl":[[0,5.8,6.84],[1,6,5.01],[2,6.2,308.46]],"ltp":5.3,"tv":9031.35,"id":9633869}]}]}
{"op":"mcm","clk":"4230677376","pt":1631535444649,"mc":[{"id":"1.187557995","rc":[{"batb":[[0,1.21,435.51],[1,1.2,1363.18]],"batl":[[0,1.22,228.52],[1,1.23,784.36],[2,1.24,571.65]],"ltp":1.29,"tv":87507.49,"id":9342449},{"batb":[[0,5.4,16.21],[1,5.3,363.61],[2,5.2,55.65]],"ltp":5.3,"tv":9031.35,"id":9633869}]}]}
{"op":"mcm","clk":"4230677766","pt":1631535446713,"mc":[{"id":"1.187557995","rc":[{"batl":[[0,1.22,233.09]],"ltp":1.29,"tv":87507.49,"id":9342449}]}]}
{"op":"mcm","clk":"4230677930","pt":1631535447655,"mc":[{"id":"1.187557995","rc":[{"trd":[[1.21,4]],"batb":[[0,1.21,433.51]],"batl":[[0,1.22,680.17]],"ltp":1.21,"tv":87511.49,"id":9342449}],"tv":96542.85}]}
{"op":"mcm","clk":"4230678236","pt":1631535449162,"mc":[{"id":"1.187557995","rc":[{"trd":[[1.21,91.92],[1.22,0.5]],"batb":[[0,1.21,389.55]],"batl":[[0,1.22,679.93]],"ltp":1.21,"tv":87599.91,"id":9342449}],"tv":96631.27}]}
{"op":"mcm","clk":"4230678572","pt":1631535450633,"mc":[{"id":"1.187557995","rc":[{"trd":[[1.21,97.7]],"batb":[[0,1.21,386.66]],"batl":[[0,1.22,675.35]],"ltp":1.21,"tv":87605.69,"id":9342449}],"tv":96637.05}]}
{"op":"mcm","clk":"4230678614","pt":1631535450941,"mc":[{"id":"1.187557995","rc":[{"trd":[[1.22,395.98]],"batl":[[0,1.22,279.87],[2,1.24,510.5]],"ltp":1.22,"tv":88001.17,"id":9342449},{"trd":[[5.5,87.73]],"ltp":5.5,"tv":9119.09,"id":9633869}],"tv":97120.27}]}
{"op":"mcm","clk":"4230678859","pt":1631535452316,"mc":[{"id":"1.187557995","rc":[{"trd":[[1.22,400.62]],"batb":[[0,1.21,445.62],[1,1.2,1279.78]],"batl":[[0,1.22,344.84],[1,1.23,730.56]],"ltp":1.22,"tv":88005.82,"id":9342449}],"tv":97124.91}]}
{"op":"mcm","clk":"4230679023","pt":1631535453627,"mc":[{"id":"1.187557995","rc":[{"trd":[[1.22,409.9]],"batl":[[0,1.22,336.01]],"ltp":1.22,"tv":88015.1,"id":9342449},{"trd":[[5.5,89.59]],"ltp":5.5,"tv":9120.95,"id":9633869}],"tv":97136.05}]}
{"op":"mcm","clk":"4230679073","pt":1631535454042,"mc":[{"id":"1.187557995","rc":[{"trd":[[1.22,528.91]],"batb":[[0,1.21,371.41]],"batl":[[0,1.22,209.21]],"ltp":1.22,"tv":88134.11,"id":9342449}],"tv":97255.06}]}
{"op":"mcm","clk":"4230679157","pt":1631535454925,"mc":[{"id":"1.187557995","rc":[{"batl":[[0,1.22,449.67]],"ltp":1.22,"tv":88134.11,"id":9342449}]}]}
{"op":"mcm","clk":"4230679391","pt":1631535457635,"mc":[{"id":"1.187557995","rc":[{"trd":[[1.21,455.09]],"batb":[[0,1.21,192.69]],"ltp":1.21,"tv":88491.5,"id":9342449}],"tv":97612.45}]}
{"op":"mcm","clk":"4230679468","pt":1631535458422,"mc":[{"id":"1.187557995","rc":[{"batb":[[0,1.21,168.87]],"batl":[[0,1.22,687.54],[2,1.24,453.92]],"ltp":1.21,"tv":88491.5,"id":9342449},{"batl":[[1,6,2.01]],"ltp":5.5,"tv":9120.95,"id":9633869}]}]}
{"op":"mcm","clk":"4230679896","pt":1631535461532,"mc":[{"id":"1.187557995","rc":[{"batb":[[0,1.21,186.95],[1,1.2,1428.28],[2,1.19,399.19]],"batl":[[1,1.23,822.91]],"ltp":1.21,"tv":88491.5,"id":9342449}]}]}
{"op":"mcm","clk":"4230680066","pt":1631535462537,"mc":[{"id":"1.187557995","rc":[{"batl":[[0,1.22,706.65]],"ltp":1.21,"tv":88491.5,"id":9342449}]}]}
{"op":"mcm","clk":"4230680388","pt":1631535464669,"mc":[{"id":"1.187557995","rc":[{"trd":[[1.21,497.68]],"batb":[[0,1.21,165.66]],"ltp":1.21,"tv":88534.08,"id":9342449}],"tv":97655.04}]}
{"op":"mcm","clk":"4230680907","pt":1631535467572,"mc":[{"id":"1.187557995","rc":[{"batb":[[1,1.2,1449.57]],"ltp":1.21,"tv":88534.08,"id":9342449}]}]}
{"op":"mcm","clk":"4230681039","pt":1631535468319,"mc":[{"id":"1.187557995","rc":[{"batl":[[0,1.22,666.19]],"ltp":1.21,"tv":88534.08,"id":9342449},{"batb":[[0,5.3,363.61],[1,5.2,55.65],[2,5.1,356.96]],"ltp":5.5,"tv":9120.95,"id":9633869}]}]}
{"op":"mcm","clk":"4230681424","pt":1631535470447,"mc":[{"id":"1.187557995","rc":[{"batb":[[1,1.2,693.03],[2,1.17,596.39]],"batl":[[1,1.23,156.22],[2,1.33,15.04]],"ltp":1.21,"tv":88534.08,"id":9342449}]}]}
{"op":"mcm","clk":"4230683244","pt":1631535480160,"mc":[{"id":"1.187557995","rc":[{"trd":[[1.22,535.97]],"batl":[[0,1.22,662.66]],"ltp":1.22,"tv":88541.14,"id":9342449}],"tv":97662.1}]}
{"op":"mcm","clk":"4230683618","pt":1631535482502,"mc":[{"id":"1.187557995","rc":[{"trd":[[1.21,829]],"batb":[[0,1.2,693.03],[1,1.17,596.39],[2,1.06,2.07]],"batl":[[0,1.21,84.34],[1,1.22,662.66],[2,1.23,156.22]],"ltp":1.21,"tv":88872.47,"id":9342449}],"tv":97993.42}]}
{"op":"mcm","clk":"4230684153","pt":1631535485677,"mc":[{"id":"1.187557995","rc":[{"trd":[[1.21,830.38]],"batb":[[0,1.2,1070.8]],"batl":[[0,1.21,83.65]],"ltp":1.21,"tv":88873.84,"id":9342449},{"batb":[[2,5.1,371.59]],"batl":[[1,6,54.99]],"ltp":5.5,"tv":9120.95,"id":9633869}],"tv":97994.79}]}
{"op":"mcm","clk":"4230684272","pt":1631535486410,"mc":[{"id":"1.187557995","rc":[{"batb":[[1,1.18,327.94],[2,1.17,596.39]],"batl":[[1,1.22,643.55]],"ltp":1.21,"tv":88873.84,"id":9342449}]}]}
{"op":"mcm","clk":"4230684387","pt":1631535487212,"mc":[{"id":"1.187557995","rc":[{"batb":[[1,1.19,317.72],[2,1.18,327.94]],"ltp":1.21,"tv":88873.84,"id":9342449}]}]}
{"op":"mcm","clk":"4230684513","pt":1631535488098,"mc":[{"id":"1.187557995","rc":[{"batb":[[0,1.2,1827.34],[1,1.19,716.91]],"batl":[[2,1.23,822.91]],"ltp":1.21,"tv":88873.84,"id":9342449}]}]}
{"op":"mcm","clk":"4230684905","pt":1631535491181,"mc":[{"id":"1.187557995","rc":[{"batl":[[1,1.22,680.6]],"ltp":1.21,"tv":88873.84,"id":9342449},{"batb":[[2,5.1,430.41]],"ltp":5.5,"tv":9120.95,"id":9633869}]}]}
{"op":"mcm","clk":"4230685713","pt":1631535498596,"mc":[{"id":"1.187557995","rc":[{"trd":[[1.21,837.21]],"batl":[[0,1.21,80.23]],"ltp":1.21,"tv":88880.68,"id":9342449}],"tv":98001.63}]}
{"op":"mcm","clk":"4230685954","pt":1631535500927,"mc":[{"id":"1.187557995","rc":[{"trd":[[1.21,837.76]],"batl":[[0,1.21,79.68]],"ltp":1.21,"tv":88881.23,"id":9342449},{"trd":[[5.7,0.12]],"ltp":5.7,"tv":9121.06,"id":9633869}],"tv":98002.29}]}
{"op":"mcm","clk":"4230687334","pt":1631535512626,"mc":[{"id":"1.187557995","rc":[{"trd":[[1.21,845]],"batl":[[0,1.21,76.06]],"ltp":1.21,"tv":88888.46,"id":9342449}],"tv":98009.53}]}
{"op":"mcm","clk":"4230687488","pt":1631535513898,"mc":[{"id":"1.187557995","rc":[{"batb":[[0,5.4,15.95],[1,5.3,363.61],[2,5.2,55.65]],"ltp":5.7,"tv":9121.06,"id":9633869}]}]}
{"op":"mcm","clk":"4230687682","pt":1631535515653,"mc":[{"id":"1.187557995","rc":[{"batb":[[0,1.2,1823.83]],"ltp":1.21,"tv":88888.46,"id":9342449}]}]}
{"op":"mcm","clk":"4230687700","pt":1631535515851,"mc":[{"id":"1.187557995","rc":[{"trd":[[1.21,846.43]],"batl":[[0,1.21,75.34]],"ltp":1.21,"tv":88889.9,"id":9342449}],"tv":98010.97}]}
{"op":"mcm","clk":"4230688296","pt":1631535521577,"mc":[{"id":"1.187557995","rc":[{"batl":[[1,1.22,480.6]],"ltp":1.21,"tv":88889.9,"id":9342449}]}]}
{"op":"mcm","clk":"4230688607","pt":1631535524653,"mc":[{"id":"1.187557995","rc":[{"batl":[[0,1.21,275.34]],"ltp":1.21,"tv":88889.9,"id":9342449}]}]}
{"op":"mcm","clk":"4230688811","pt":1631535526687,"mc":[{"id":"1.187557995","rc":[{"batb":[[0,1.2,1866.88]],"ltp":1.21,"tv":88889.9,"id":9342449}]}]}
{"op":"mcm","clk":"4230688848","pt":1631535527041,"mc":[{"id":"1.187557995","rc":[{"batb":[[1,5.3,419.17],[2,5.1,430.41]],"ltp":5.7,"tv":9121.06,"id":9633869}]}]}
{"op":"mcm","clk":"4230689310","pt":1631535531357,"mc":[{"id":"1.187557995","rc":[{"batl":[[1,1.22,443.55]],"ltp":1.21,"tv":88889.9,"id":9342449}]}]}
{"op":"mcm","clk":"4230689546","pt":1631535533863,"mc":[{"id":"1.187557995","rc":[{"batl":[[0,1.21,312.69]],"ltp":1.21,"tv":88889.9,"id":9342449}]}]}
{"op":"mcm","clk":"4230689680","pt":1631535535168,"mc":[{"id":"1.187557995","rc":[{"batb":[[0,1.2,5274.03]],"ltp":1.21,"tv":88889.9,"id":9342449}]}]}
{"op":"mcm","clk":"4230689787","pt":1631535536264,"mc":[{"id":"1.187557995","rc":[{"batb":[[0,1.2,5230.98]],"ltp":1.21,"tv":88889.9,"id":9342449},{"batb":[[0,5.3,419.17],[1,5.1,430.41],[2,5,356.96]],"ltp":5.7,"tv":9121.06,"id":9633869}]}]}
{"op":"mcm","clk":"4230692050","pt":1631535559472,"mc":[{"id":"1.187557995","rc":[{"trd":[[1.21,867.69]],"batl":[[0,1.21,291.43]],"ltp":1.21,"tv":88911.16,"id":9342449},{"trd":[[5.7,4.63]],"ltp":5.7,"tv":9125.58,"id":9633869}],"tv":98036.74}]}
{"op":"mcm","clk":"4230692542","pt":1631535563883,"mc":[{"id":"1.187557995","rc":[{"trd":[[1.2,14]],"batb":[[0,1.2,5223.98]],"ltp":1.2,"tv":88925.15,"id":9342449}],"tv":98050.74}]}
{"op":"mcm","clk":"4230693103","pt":1631535569665,"mc":[{"id":"1.187557995","rc":[{"batl":[[0,1.21,91.43]],"ltp":1.2,"tv":88925.15,"id":9342449}]}]}
{"op":"mcm","clk":"4230693457","pt":1631535573070,"mc":[{"id":"1.187557995","rc":[{"trd":[[1.2,470.84]],"batb":[[0,1.2,4995.53]],"ltp":1.2,"tv":89381.99,"id":9342449},{"batl":[[1,6,52.98]],"ltp":5.7,"tv":9125.58,"id":9633869}],"tv":98507.58}]}
{"op":"mcm","clk":"4230694885","pt":1631535588794,"mc":[{"id":"1.187557995","rc":[{"batb":[[1,1.19,693.23]],"batl":[[2,1.23,800.17]],"ltp":1.2,"tv":89381.99,"id":9342449}]}]}
{"op":"mcm","clk":"4230695126","pt":1631535591692,"mc":[{"id":"1.187557995","rc":[{"batb":[[0,1.2,5019.02]],"ltp":1.2,"tv":89381.99,"id":9342449}]}]}
{"op":"mcm","clk":"4230695168","pt":1631535592060,"mc":[{"id":"1.187557995","rc":[{"trd":[[1.21,887.69]],"batl":[[0,1.21,81.43]],"ltp":1.21,"tv":89401.99,"id":9342449}],"tv":98527.58}]}
{"op":"mcm","clk":"4230695404","pt":1631535595206,"mc":[{"id":"1.187557995","rc":[{"batb":[[0,1.2,1611.87]],"ltp":1.21,"tv":89401.99,"id":9342449}]}]}
{"op":"mcm","clk":"4230695473","pt":1631535595998,"mc":[{"id":"1.187557995","rc":[{"batb":[[0,1.2,1658.02]],"ltp":1.21,"tv":89401.99,"id":9342449},{"batb":[[0,5.4,12.63],[1,5.3,419.17],[2,5.1,430.41]],"ltp":5.7,"tv":9125.58,"id":9633869}]}]}
{"op":"mcm","clk":"4230695820","pt":1631535599672,"mc":[{"id":"1.187557995","rc":[{"trd":[[1.21,1050.53]],"batb":[[0,1.21,24.91],[1,1.2,134.16],[2,1.17,588.86]],"batl":[[0,1.22,277.47],[1,1.25,15],[2,1.82,2.89]],"ltp":1.21,"tv":89564.83,"id":9342449},{"batb":[[0,5.1,14.63],[1,4.8,66.86],[2,1.97,1.05]],"batl":[[1,990,0.01],[2,6.2,0]],"ltp":5.7,"tv":9125.58,"id":9633869}],"tv":98690.41}]}
{"op":"mcm","clk":"4230695902","pt":1631535600512,"mc":[{"id":"1.187557995","rc":[{"batb":[[1,1.17,588.86],[2,1.06,2.07]],"batl":[[0,1.82,2.89],[1,2.08,1],[2,8.8,7.23]],"ltp":1.21,"tv":89564.83,"id":9342449},{"batb":[[0,4.8,66.86],[1,1.97,1.05],[2,1.67,1.38]],"batl":[[0,990,0.01],[1,990,0]],"ltp":5.7,"tv":9125.58,"id":9633869}]}]}
{"op":"mcm","clk":"4230696122","pt":1631535602691,"mc":[{"id":"1.187557995","rc":[{"trd":[[1.21,1100.34]],"batb":[[0,1.17,588.88],[1,1.06,2.07],[2,1.03,2.13]],"ltp":1.21,"tv":89614.64,"id":9342449}],"tv":98740.22}]}
{"op":"mcm","clk":"4230696397","pt":1631535605709,"mc":[{"id":"1.187557995","rc":[{"batb":[[0,1.21,7.02],[1,1.2,361.79],[2,1.19,707.44]],"batl":[[0,1.22,481.5],[1,1.23,541.73],[2,1.82,2.89]],"ltp":1.21,"tv":89614.64,"id":9342449}]}]}
{"op":"mcm","clk":"4230696413","pt":1631535605869,"mc":[{"id":"1.187557995","rc":[{"batl":[[2,1.82,6.89]],"ltp":1.21,"tv":89614.64,"id":9342449}]}]}
{"op":"mcm","clk":"4230696514","pt":1631535607072,"mc":[{"id":"1.187557995","rc":[{"batb":[[0,1.2,361.81],[1,1.19,707.44],[2,1.18,102.02]],"ltp":1.21,"tv":89614.64,"id":9342449},{"batb":[[0,4.9,47.11],[1,4.8,66.86],[2,1.97,1.05]],"ltp":5.7,"tv":9125.58,"id":9633869}]}]}
{"op":"mcm","clk":"4230696681","pt":1631535609217,"mc":[{"id":"1.187557995","rc":[{"batl":[[0,1.22,624.5]],"ltp":1.21,"tv":89614.64,"id":9342449}]}]}
{"op":"mcm","clk":"4230696801","pt":1631535610421,"mc":[{"id":"1.187557995","rc":[{"batb":[[0,1.17,588.88],[1,1.06,2.07],[2,1.03,2.13]],"batl":[[0,1.22,143],[1,1.82,6.89],[2,2.08,1]],"ltp":1.21,"tv":89614.64,"id":9342449},{"batb":[[0,4.8,66.86],[1,1.97,1.05],[2,1.67,1.38]],"ltp":5.7,"tv":9125.58,"id":9633869}]}]}
{"op":"mcm","clk":"4230696872","pt":1631535611312,"mc":[{"id":"1.187557995","rc":[{"batl":[[0,1.82,6.89],[1,2.08,1],[2,8.8,7.23]],"ltp":1.21,"tv":89614.64,"id":9342449}]}]}
{"op":"mcm","clk":"4230697057","pt":1631535613101,"mc":[{"id":"1.187557995","rc":[{"batb":[[0,1.17,1404.78],[1,1.16,369.22],[2,1.06,2.07]],"batl":[[0,1.26,496.19],[1,1.27,443.99],[2,1.82,6.89]],"ltp":1.21,"tv":89614.64,"id":9342449}]}]}
{"op":"mcm","clk":"4230697179","pt":1631535614626,"mc":[{"id":"1.187557995","rc":[{"batl":[[0,1.82,6.89],[1,2.08,1],[2,8.8,7.23]],"ltp":1.21,"tv":89614.64,"id":9342449}]}]}
{"op":"mcm","clk":"4230697271","pt":1631535615626,"mc":[{"id":"1.187557995","rc":[{"batb":[[0,1.18,189.11],[1,1.17,1404.76],[2,1.16,369.22]],"ltp":1.21,"tv":89614.64,"id":9342449}]}]}
{"op":"mcm","clk":"4230697323","pt":1631535616107,"mc":[{"id":"1.187557995","rc":[{"batb":[[0,1.17,1404.78],[1,1.16,369.22],[2,1.06,2.07]],"ltp":1.21,"tv":89614.64,"id":9342449}]}]}
{"op":"mcm","clk":"4230697451","pt":1631535617519,"mc":[{"id":"1.187557995","rc":[{"trd":[[1.21,1100.37]],"batb":[[0,1.17,1404.76]],"batl":[[0,1.19,297.86],[1,1.2,647.27],[2,1.3,15.38]],"ltp":1.21,"tv":89614.67,"id":9342449},{"batb":[[0,6,637.5],[1,5.9,618.76],[2,5.8,618.76]],"batl":[[0,7.6,503.28],[1,7.8,488.48],[2,8,488.48]],"ltp":5.7,"tv":9125.58,"id":9633869}],"tv":98740.26}]}
{"op":"mcm","clk":"4230697559","pt":1631535618618,"mc":[{"id":"1.187557995","rc":[{"trd":[[1.19,19.28]],"batb":[[2,1.13,773.63]],"batl":[[0,1.19,278.58]],"ltp":1.19,"tv":89633.95,"id":9342449},{"trd":[[6.2,3.7]],"batb":[[0,6,399.83],[1,5.9,309.38],[2,5.8,309.38]],"batl":[[0,7.6,138.4],[1,7.8,244.24],[2,8,244.24]],"ltp":6.2,"tv":9129.28,"id":9633869}],"tv":98763.24}]}
{"op":"mcm","clk":"4230697636","pt":1631535619404,"mc":[{"id":"1.187557995","rc":[{"batb":[[0,1.17,1595.44]],"batl":[[2,1.21,15]],"ltp":1.19,"tv":89633.95,"id":9342449},{"batl":[[0,6.8,6.22],[1,7.6,138.4],[2,7.8,244.24]],"ltp":6.2,"tv":9129.28,"id":9633869}]}]}
{"op":"mcm","clk":"4230697723","pt":1631535620613,"mc":[{"id":"1.187557995","rc":[{"batl":[[1,7.4,17.35],[2,7.6,138.4]],"ltp":6.2,"tv":9129.28,"id":9633869}]}]}
{"op":"mcm","clk":"4230697806","pt":1631535621612,"mc":[{"id":"1.187557995","rc":[{"batb":[[0,1.17,2025.62]],"batl":[[0,1.19,768.2]],"ltp":1.19,"tv":89633.95,"id":9342449}]}]}
{"op":"mcm","clk":"4230697900","pt":1631535622709,"mc":[{"id":"1.187557995","rc":[{"batb":[[0,1.17,2102.55],[1,1.16,433.41]],"batl":[[0,1.19,886.56],[1,1.2,705.54]],"ltp":1.19,"tv":89633.95,"id":9342449},{"batb":[[0,6.2,45.12],[1,6,399.83],[2,5.9,309.38]],"ltp":6.2,"tv":9129.28,"id":9633869}]}]}
{"op":"mcm","clk":"4230697970","pt":1631535623498,"mc":[{"id":"1.187557995","rc":[{"batb":[[0,6.2,10.65]],"ltp":6.2,"tv":9129.28,"id":9633869}]}]}
{"op":"mcm","clk":"4230698055","pt":1631535624500,"mc":[{"id":"1.187557995","rc":[{"batl":[[0,1.18,9.37],[1,1.19,886.56],[2,1.2,705.54]],"ltp":1.19,"tv":89633.95,"id":9342449}]}]}
{"op":"mcm","clk":"4230698188","pt":1631535625708,"mc":[{"id":"1.187557995","rc":[{"batb":[[2,1.14,509.37]],"batl":[[1,1.19,1069.56]],"ltp":1.19,"tv":89633.95,"id":9342449}]}]}
{"op":"mcm","clk":"4230698293","pt":1631535626710,"mc":[{"id":"1.187557995","rc":[{"batb":[[2,1.15,254.68]],"ltp":1.19,"tv":89633.95,"id":9342449}]}]}
{"op":"mcm","clk":"4230698370","pt":1631535627709,"mc":[{"id":"1.187557995","rc":[{"trd":[[1.18,18.74]],"batb":[[0,1.18,245.65],[1,1.17,2102.55],[2,1.16,369.22]],"batl":[[0,1.19,1069.56],[1,1.2,647.27],[2,1.21,15]],"ltp":1.18,"tv":89652.69,"id":9342449}],"tv":98781.97}]}
{"op":"mcm","clk":"4230698518","pt":1631535629701,"mc":[{"id":"1.187557995","rc":[{"trd":[[1.18,132.89]],"batb":[[0,1.18,188.58]],"batl":[[0,1.19,996.54]],"ltp":1.18,"tv":89766.84,"id":9342449}],"tv":98896.12}]}
{"op":"mcm","clk":"4230698696","pt":1631535631638,"mc":[{"id":"1.187557995","rc":[{"batb":[[0,1.17,222.45],[1,1.15,254.68],[2,1.14,509.37]],"batl":[[0,1.19,183],[1,1.21,15],[2,1.22,236.8]],"ltp":1.18,"tv":89766.84,"id":9342449},{"batb":[[0,5.7,12.76],[1,5.4,51.46],[2,4.9,2]],"batl":[[1,990,0.01],[2,7.6,0]],"ltp":6.2,"tv":9129.28,"id":9633869}]}]}
{"op":"mcm","clk":"4230698761","pt":1631535632438,"mc":[{"id":"1.187557995","rc":[{"batb":[[0,1.15,254.68],[1,1.14,509.37],[2,1.13,773.63]],"batl":[[0,1.22,236.8],[1,1.26,11],[2,1.39,17.83]],"ltp":1.18,"tv":89766.84,"id":9342449},{"batb":[[0,5.4,51.46],[1,4.9,2],[2,1.97,1.05]],"batl":[[0,990,0.01],[1,990,0]],"ltp":6.2,"tv":9129.28,"id":9633869}]}]}
{"op":"mcm","clk":"4230698949","pt":1631535634536,"mc":[{"id":"1.187557995","rc":[{"batb":[[1,1.14,1511.28],[2,1.13,986.65]],"batl":[[0,1.22,446.76],[1,1.23,548.02],[2,1.26,11]],"ltp":1.18,"tv":89766.84,"id":9342449}]}]}
{"op":"mcm","clk":"4230699638","pt":1631535642563,"mc":[{"id":"1.187557995","rc":[{"batb":[[1,1.14,509.37],[2,1.13,773.63]],"ltp":1.18,"tv":89766.84,"id":9342449}]}]}
{"op":"mcm","clk":"4230699799","pt":1631535644248,"mc":[{"id":"1.187557995","rc":[{"batl":[[0,1.22,209.96]],"ltp":1.18,"tv":89766.84,"id":9342449}]}]}
{"op":"mcm","clk":"4230699944","pt":1631535645677,"mc":[{"id":"1.187557995","rc":[{"trd":[[1.22,554.36]],"batb":[[0,1.2,674.64],[1,1.19,502.98]],"batl":[[0,1.22,191.57]],"ltp":1.22,"tv":89785.23,"id":9342449},{"trd":[[5.5,93.67]],"batb":[[1,5.3,721.7],[2,5.2,700.48]],"batl":[[0,6,2],[1,6.2,616.94],[2,6.4,598.8]],"ltp":5.5,"tv":9133.36,"id":9633869}],"tv":98918.59}]}
{"op":"mcm","clk":"4230700054","pt":1631535646684,"mc":[{"id":"1.187557995","rc":[{"batb":[[1,1.19,1014.94],[2,1.16,2846.59]],"ltp":1.22,"tv":89785.23,"id":9342449},{"batb":[[1,5.3,360.84],[2,5.2,192.63]],"batl":[[1,6.2,308.46],[2,6.4,299.4]],"ltp":5.5,"tv":9133.36,"id":9633869}]}]}
{"op":"mcm","clk":"4230700150","pt":1631535647586,"mc":[{"id":"1.187557995","rc":[{"batb":[[1,1.19,1152.58],[2,1.16,3050.6]],"batl":[[0,1.22,231.34],[2,1.25,15]],"ltp":1.22,"tv":89785.23,"id":9342449},{"batb":[[0,5.5,10.64],[1,5.4,51.46],[2,5.3,360.84]],"batl":[[1,6.2,315.03]],"ltp":5.5,"tv":9133.36,"id":9633869}]}]}
{"op":"mcm","clk":"4230700259","pt":1631535648590,"mc":[{"id":"1.187557995","rc":[{"batl":[[1,6.2,327.86]],"ltp":5.5,"tv":9133.36,"id":9633869}]}]}
{"op":"mcm","clk":"4230700331","pt":1631535649396,"mc":[{"id":"1.187557995","rc":[{"batb":[[1,1.19,1014.94]],"ltp":1.22,"tv":89785.23,"id":9342449}]}]}
{"op":"mcm","clk":"4230700465","pt":1631535650701,"mc":[{"id":"1.187557995","rc":[{"batb":[[0,1.21,55.66],[1,1.2,1014.45],[2,1.19,1093.27]],"batl":[[0,1.22,718.79],[1,1.23,625.17]],"ltp":1.22,"tv":89785.23,"id":9342449},{"batl":[[1,6.2,321.29]],"ltp":5.5,"tv":9133.36,"id":9633869}]}]}
{"op":"mcm","clk":"4230700667","pt":1631535652683,"mc":[{"id":"1.187557995","rc":[{"batb":[[1,1.2,1148.61]],"batl":[[2,1.25,124.86]],"ltp":1.22,"tv":89785.23,"id":9342449}]}]}
{"op":"mcm","clk":"4230700746","pt":1631535653459,"mc":[{"id":"1.187557995","rc":[{"batl":[[2,1.24,229.13]],"ltp":1.22,"tv":89785.23,"id":9342449}]}]}
{"op":"mcm","clk":"4230700810","pt":1631535654191,"mc":[{"id":"1.187557995","rc":[{"batl":[[0,1.22,906.79]],"ltp":1.22,"tv":89785.23,"id":9342449},{"batl":[[0,6,8.7]],"ltp":5.5,"tv":9133.36,"id":9633869}]}]}
{"op":"mcm","clk":"4230700971","pt":1631535655662,"mc":[{"id":"1.187557995","rc":[{"batb":[[2,1.19,1014.94]],"batl":[[1,1.23,548.02]],"ltp":1.22,"tv":89785.23,"id":9342449}]}]}
{"op":"mcm","clk":"4230701147","pt":1631535657478,"mc":[{"id":"1.187557995","rc":[{"batb":[[1,1.2,280.51],[2,1.17,567.35]],"batl":[[0,1.22,338.86],[1,1.24,229.13],[2,1.25,124.86]],"ltp":1.22,"tv":89785.23,"id":9342449},{"batb":[[0,5.1,14.63],[1,5,2.04],[2,4.9,67.44]],"batl":[[0,6,6.7],[1,7,2],[2,7.4,2]],"ltp":5.5,"tv":9133.36,"id":9633869}]}]}
{"op":"mcm","clk":"4230701277","pt":1631535658689,"mc":[{"id":"1.187557995","rc":[{"trd":[[1.22,654.37]],"batb":[[1,1.2,75.24]],"batl":[[0,1.22,23.26],[2,1.25,109.86]],"ltp":1.22,"tv":89885.24,"id":9342449},{"batb":[[0,5,2.04],[1,4.9,67.44],[2,4.7,2.52]],"batl":[[0,7,2],[1,7.4,2],[2,8.2,2]],"ltp":5.5,"tv":9133.36,"id":9633869}],"tv":99018.6}]}
{"op":"mcm","clk":"4230701460","pt":1631535660506,"mc":[{"id":"1.187557995","rc":[{"batb":[[0,1.17,901.48],[1,1.16,1641.08],[2,1.14,152.32]],"batl":[[0,1.24,229.13],[1,1.25,109.86],[2,1.26,379.88]],"ltp":1.22,"tv":89885.24,"id":9342449}]}]}
{"op":"mcm","clk":"4230701546","pt":1631535661301,"mc":[{"id":"1.187557995","rc":[{"batl":[[2,1.26,11]],"ltp":1.22,"tv":89885.24,"id":9342449}]}]}
{"op":"mcm","clk":"4230701662","pt":1631535662569,"mc":[{"id":"1.187557995","rc":[{"batb":[[0,1.17,484.1]],"batl":[[0,1.25,109.86],[1,1.26,11],[2,1.49,772.18]],"ltp":1.22,"tv":89885.24,"id":9342449}]}]}
{"op":"mcm","clk":"4230701700","pt":1631535662887,"mc":[{"id":"1.187557995","rc":[{"batl":[[0,1.26,11],[1,1.49,772.18],[2,1.82,2.89]],"ltp":1.22,"tv":89885.24,"id":9342449},{"batb":[[0,4.9,67.44],[1,4.7,2.52],[2,1.97,1.05]],"ltp":5.5,"tv":9133.36,"id":9633869}]}]}
{"op":"mcm","clk":"4230701896","pt":1631535664682,"mc":[{"id":"1.187557995","rc":[{"batl":[[0,1.19,785.51],[1,1.2,421.93],[2,1.26,11]],"ltp":1.22,"tv":89885.24,"id":9342449},{"batb":[[0,6.2,73.14],[1,6,318.74],[2,5.9,309.38]],"batl":[[2,7.6,138.4]],"ltp":5.5,"tv":9133.36,"id":9633869}]}]}
{"op":"mcm","clk":"4230701991","pt":1631535665676,"mc":[{"id":"1.187557995","rc":[{"batb":[[1,1.16,1791.08]],"batl":[[2,1.22,15]],"ltp":1.22,"tv":89885.24,"id":9342449},{"trd":[[6.2,10.98]],"batb":[[0,6.2,69.49]],"batl":[[0,7,8.12]],"ltp":6.2,"tv":9140.64,"id":9633869}],"tv":99025.88}]}
{"op":"mcm","clk":"4230702157","pt":1631535667620,"mc":[{"id":"1.187557995","rc":[{"batb":[[2,5.9,311.38]],"ltp":6.2,"tv":9140.64,"id":9633869}]}]}
{"op":"mcm","clk":"4230702262","pt":1631535668611,"mc":[{"id":"1.187557995","rc":[{"batb":[[0,1.18,108.78],[1,1.17,675.9],[2,1.16,1850.57]],"batl":[[0,1.19,1186.91],[1,1.2,483.98],[2,1.22,222.84]],"ltp":1.22,"tv":89885.24,"id":9342449}]}]}
{"op":"mcm","clk":"4230702342","pt":1631535669503,"mc":[{"id":"1.187557995","rc":[{"batl":[[0,1.19,1415.67],[2,1.22,207.84]],"ltp":1.22,"tv":89885.24,"id":9342449},{"batb":[[0,6.4,10.2],[1,6.2,69.49],[2,6,318.74]],"ltp":6.2,"tv":9140.64,"id":9633869}]}]}
{"op":"mcm","clk":"4230702400","pt":1631535669983,"mc":[{"id":"1.187557995","rc":[{"batl":[[2,1.22,314.59]],"ltp":1.22,"tv":89885.24,"id":9342449}]}]}
{"op":"mcm","clk":"4230702618","pt":1631535672281,"mc":[{"id":"1.187557995","rc":[{"batl":[[2,1.21,15]],"ltp":1.22,"tv":89885.24,"id":9342449}]}]}
{"op":"mcm","clk":"4230702942","pt":1631535675317,"mc":[{"id":"1.187557995","rc":[{"batb":[[2,1.16,1791.08]],"batl":[[1,1.2,421.93]],"ltp":1.22,"tv":89885.24,"id":9342449}]}]}
{"op":"mcm","clk":"4230703026","pt":1631535676219,"mc":[{"id":"1.187557995","rc":[{"batl":[[0,1.19,1366.78]],"ltp":1.22,"tv":89885.24,"id":9342449}]}]}
{"op":"mcm","clk":"4230703272","pt":1631535678621,"mc":[{"id":"1.187557995","rc":[{"batb":[[0,1.16,794.42],[1,1.15,236.8],[2,1.14,473.59]],"batl":[[0,1.19,154],[1,1.21,15],[2,1.22,314.59]],"ltp":1.22,"tv":89885.24,"id":9342449},{"batb":[[0,6.2,69.49],[1,5.9,12.24],[2,5.5,51.41]],"batl":[[0,7,6.12],[1,9.4,2],[2,12.5,2]],"ltp":6.2,"tv":9140.64,"id":9633869}]}]}
{"op":"mcm","clk":"4230703357","pt":1631535679422,"mc":[{"id":"1.187557995","rc":[{"batb":[[0,1.15,236.8],[1,1.14,473.59],[2,1.12,1048.39]],"batl":[[0,1.18,2.32],[1,1.22,314.59],[2,1.23,125.5]],"ltp":1.22,"tv":89885.24,"id":9342449},{"batb":[[0,5.5,51.41],[1,5.1,2.04],[2,1.97,1.05]],"batl":[[0,9.4,2],[1,12.5,2],[2,990,0.01]],"ltp":6.2,"tv":9140.64,"id":9633869}]}]}
{"op":"mcm","clk":"4230703450","pt":1631535680349,"mc":[{"id":"1.187557995","rc":[{"batb":[[0,1.14,473.59],[1,1.12,1048.39],[2,1.11,250]],"ltp":1.22,"tv":89885.24,"id":9342449}]}]}
{"op":"mcm","clk":"4230703566","pt":1631535681609,"mc":[{"id":"1.187557995","rc":[{"batb":[[1,1.13,1065.88],[2,1.12,1048.39]],"batl":[[1,1.22,641.6],[2,1.23,670.34]],"ltp":1.22,"tv":89885.24,"id":9342449}]}]}
{"op":"mcm","clk":"4230703624","pt":1631535682226,"mc":[{"id":"1.187557995","rc":[{"batb":[[1,1.12,1048.39],[2,1.11,250]],"batl":[[1,1.22,314.59],[2,1.23,125.5]],"ltp":1.22,"tv":89885.24,"id":9342449}]}]}
{"op":"mcm","clk":"4230703899","pt":1631535685209,"mc":[{"id":"1.187557995","rc":[{"batb":[[0,1.16,608.83],[1,1.15,588.39],[2,1.14,473.59]],"batl":[[0,1.18,584.66],[1,1.19,584.65],[2,1.22,314.59]],"ltp":1.22,"tv":89885.24,"id":9342449}]}]}
{"op":"mcm","clk":"4230704437","pt":1631535691130,"mc":[{"id":"1.187557995","rc":[{"batl":[[0,1.18,652.3]],"ltp":1.22,"tv":89885.24,"id":9342449},{"batb":[[0,5.8,40.68],[1,5.5,51.41],[2,5.1,2.04]],"batl":[[0,8.6,10],[1,9.4,2],[2,12.5,2]],"ltp":6.2,"tv":9140.64,"id":9633869}]}]}
{"op":"mcm","clk":"4230704559","pt":1631535692331,"mc":[{"id":"1.187557995","rc":[{"batb":[[0,1.14,473.59],[1,1.12,1048.39],[2,1.11,250]],"batl":[[0,1.18,13.92],[1,1.22,314.59],[2,1.23,125.5]],"ltp":1.22,"tv":89885.24,"id":9342449}]}]}
{"op":"mcm","clk":"4230704618","pt":1631535693021,"mc":[{"id":"1.187557995","rc":[{"batl":[[0,1.18,2.32]],"ltp":1.22,"tv":89885.24,"id":9342449},{"batb":[[0,5.5,51.41],[1,5.1,2.04],[2,1.97,1.05]],"batl":[[0,9.4,2],[1,12.5,2],[2,990,0.01]],"ltp":6.2,"tv":9140.64,"id":9633869}]}]}
{"op":"mcm","clk":"4230704782","pt":1631535694638,"mc":[{"id":"1.187557995","rc":[{"trd":[[1.18,133.66]],"batl":[[0,1.18,1.94]],"ltp":1.18,"tv":89886.01,"id":9342449}],"tv":99026.66}]}
{"op":"mcm","clk":"4230704869","pt":1631535695520,"mc":[{"id":"1.187557995","rc":[{"batb":[[1,1.13,1065.88],[2,1.12,1048.39]],"batl":[[1,1.22,641.6],[2,1.23,670.34]],"ltp":1.18,"tv":89886.01,"id":9342449}]}]}
{"op":"mcm","clk":"4230705625","pt":1631535704472,"mc":[{"id":"1.187557995","rc":[{"batl":[[0,1.22,641.6],[1,1.23,670.34],[2,1.24,104.73]],"ltp":1.18,"tv":89886.01,"id":9342449}]}]}
{"op":"mcm","clk":"4230706350","pt":1631535713637,"mc":[{"id":"1.187557995","rc":[{"batb":[[0,1.2,6736.34],[1,1.14,473.59]],"ltp":1.18,"tv":89886.01,"id":9342449}]}]}
{"op":"mcm","clk":"4230706415","pt":1631535714527,"mc":[{"id":"1.187557995","rc":[{"batb":[[0,1.14,473.59],[1,1.12,1048.39],[2,1.11,250]],"batl":[[0,1.22,433.76],[1,1.23,660.34]],"ltp":1.18,"tv":89886.01,"id":9342449}]}]}
{"op":"mcm","clk":"4230706481","pt":1631535715659,"mc":[{"id":"1.187557995","rc":[{"batb":[[0,1.18,3066.27],[1,1.14,473.59],[2,1.12,1048.39]],"ltp":1.18,"tv":89886.01,"id":9342449},{"trd":[[5.5,101.84]],"batb":[[0,5.5,47.33]],"batl":[[0,6,391.68],[1,6.2,195.84],[2,6.4,195.84]],"ltp":5.5,"tv":9148.8,"id":9633869}],"tv":99034.82}]}
{"op":"mcm","clk":"4230706570","pt":1631535716654,"mc":[{"id":"1.187557995","rc":[{"batb":[[0,1.2,526.73],[1,1.19,651.85],[2,1.18,1841.03]],"batl":[[0,1.22,478.91]],"ltp":1.18,"tv":89886.01,"id":9342449},{"batb":[[0,5.5,59.18],[1,5.3,443.4],[2,5.2,221.7]],"batl":[[0,6,235.01],[1,6.2,117.5],[2,6.4,119.5]],"ltp":5.5,"tv":9148.8,"id":9633869}]}]}
{"op":"mcm","clk":"4230706663","pt":1631535717531,"mc":[{"id":"1.187557995","rc":[{"batb":[[1,1.19,1315.17]],"batl":[[2,1.24,119.73]],"ltp":1.18,"tv":89886.01,"id":9342449},{"batb":[[1,5.3,55.43],[2,5.2,41.99]],"batl":[[1,6.2,124.07]],"ltp":5.5,"tv":9148.8,"id":9633869}]}]}
{"op":"mcm","clk":"4230706794","pt":1631535719254,"mc":[{"id":"1.187557995","rc":[{"batl":[[0,1.22,372.16]],"ltp":1.18,"tv":89886.01,"id":9342449},{"batb":[[0,5.5,57.06]],"ltp":5.5,"tv":9148.8,"id":9633869}]}]}
{"op":"mcm","clk":"4230706917","pt":1631535720661,"mc":[{"id":"1.187557995","rc":[{"batb":[[0,1.21,106.09],[1,1.2,693.84],[2,1.19,1315.17]],"batl":[[0,1.22,718.56],[1,1.23,740.17]],"ltp":1.18,"tv":89886.01,"id":9342449}]}]}
{"op":"mcm","clk":"4230706963","pt":1631535721144,"mc":[{"id":"1.187557995","rc":[{"batb":[[2,1.19,1381.35]],"ltp":1.18,"tv":89886.01,"id":9342449}]}]}
{"op":"mcm","clk":"4230707141","pt":1631535723378,"mc":[{"id":"1.187557995","rc":[{"batl":[[0,1.22,985.56]],"ltp":1.18,"tv":89886.01,"id":9342449}]}]}
{"op":"mcm","clk":"4230707445","pt":1631535726964,"mc":[{"id":"1.187557995","rc":[{"batb":[[2,1.19,1315.17]],"batl":[[1,1.23,660.34]],"ltp":1.18,"tv":89886.01,"id":9342449}]}]}
{"op":"mcm","clk":"4230707574","pt":1631535728172,"mc":[{"id":"1.187557995","rc":[{"trd":[[1.21,1101.27]],"batb":[[0,1.21,105.64]],"batl":[[0,1.22,1061.35]],"ltp":1.21,"tv":89886.91,"id":9342449}],"tv":99035.72}]}
{"op":"mcm","clk":"4230707801","pt":1631535730582,"mc":[{"id":"1.187557995","rc":[{"batb":[[0,1.2,612.94],[1,1.19,1315.17],[2,1.18,1841.03]],"batl":[[0,1.22,927.03]],"ltp":1.21,"tv":89886.91,"id":9342449}]}]}
{"op":"mcm","clk":"4230707905","pt":1631535731682,"mc":[{"id":"1.187557995","rc":[{"batb":[[0,1.19,663.32],[1,1.17,435.26],[2,1.14,893.68]],"batl":[[0,1.22,267],[1,1.24,15],[2,1.25,105.3]],"ltp":1.21,"tv":89886.91,"id":9342449},{"batb":[[0,5.5,45.21],[1,5.2,14.28],[2,5.1,2]],"batl":[[0,6.2,6.57],[1,8.2,2],[2,9.4,2]],"ltp":5.5,"tv":9148.8,"id":9633869}]}]}
{"op":"mcm","clk":"4230707980","pt":1631535732573,"mc":[{"id":"1.187557995","rc":[{"batb":[[0,1.19,137.64],[2,1.14,892.18]],"batl":[[0,1.24,15],[1,1.25,105.3],[2,1.27,93.5]],"ltp":1.21,"tv":89886.91,"id":9342449},{"batb":[[0,5.2,14.28],[1,4.9,65.94],[2,4.7,2.32]],"ltp":5.5,"tv":9148.8,"id":9633869}]}]}
{"op":"mcm","clk":"4230708075","pt":1631535733562,"mc":[{"id":"1.187557995","rc":[{"batb":[[0,1.14,892.18],[1,1.13,638.66],[2,1.12,180.79]],"batl":[[0,1.27,93.5],[1,1.53,723.95],[2,1.82,2.89]],"ltp":1.21,"tv":89886.91,"id":9342449},{"batb":[[0,4.9,65.94],[1,4.7,2.32],[2,1.97,1.05]],"batl":[[0,8.2,2],[1,9.4,2],[2,11,2]],"ltp":5.5,"tv":9148.8,"id":9633869}]}]}
{"op":"mcm","clk":"4230708159","pt":1631535734466,"mc":[{"id":"1.187557995","rc":[{"batb":[[0,1.16,316.89],[1,1.15,882.87],[2,1.14,892.18]],"batl":[[0,1.27,581.08],[1,1.28,423.81],[2,1.53,723.95]],"ltp":1.21,"tv":89886.91,"id":9342449}]}]}
{"op":"mcm","clk":"4230708240","pt":1631535735358,"mc":[{"id":"1.187557995","rc":[{"batb":[[0,1.22,200],[1,1.16,316.89],[2,1.15,882.87]],"ltp":1.21,"tv":89886.91,"id":9342449}]}]}
{"op":"mcm","clk":"4230708327","pt":1631535736396,"mc":[{"id":"1.187557995","rc":[{"batb":[[1,1.14,892.18],[2,1.13,638.66]],"ltp":1.21,"tv":89886.91,"id":9342449}]}]}
{"op":"mcm","clk":"4230708429","pt":1631535737285,"mc":[{"id":"1.187557995","rc":[{"batb":[[1,1.15,227.43],[2,1.14,892.18]],"batl":[[0,1.26,95.75],[1,1.27,581.08],[2,1.28,423.81]],"ltp":1.21,"tv":89886.91,"id":9342449}]}]}
{"op":"mcm","clk":"4230708641","pt":1631535739587,"mc":[{"id":"1.187557995","rc":[{"batb":[[0,1.24,672.57],[1,1.23,2073.71],[2,1.22,3416.5]],"ltp":1.21,"tv":89886.91,"id":9342449},{"trd":[[4.9,9.3]],"batb":[[0,4.9,61.29],[2,4.5,233.75]],"batl":[[0,5.6,2],[1,8.2,2],[2,9.4,2]],"ltp":4.9,"tv":9158.1,"id":9633869}],"tv":99045.02}]}
{"op":"mcm","clk":"4230708725","pt":1631535740474,"mc":[{"id":"1.187557995","rc":[{"batb":[[1,1.23,2198.81],[2,1.22,3849.97]],"ltp":1.21,"tv":89886.91,"id":9342449},{"batb":[[2,4.5,250.89]],"batl":[[0,5.3,7.23],[1,5.6,2],[2,8.2,2]],"ltp":4.9,"tv":9158.1,"id":9633869}]}]}
{"op":"mcm","clk":"4230708900","pt":1631535742466,"mc":[{"id":"1.187557995","rc":[{"batb":[[1,1.23,2073.71]],"batl":[[0,1.27,581.08],[1,1.28,423.81],[2,1.29,15]],"ltp":1.21,"tv":89886.91,"id":9342449}]}]}
{"op":"mcm","clk":"4230709006","pt":1631535743705,"mc":[{"id":"1.187557995","rc":[{"batb":[[0,1.25,102.25],[1,1.24,817.25],[2,1.23,2073.71]],"batl":[[0,1.26,368.98],[1,1.27,581.08],[2,1.28,423.81]],"ltp":1.21,"tv":89886.91,"id":9342449}]}]}
{"op":"mcm","clk":"4230709071","pt":1631535744282,"mc":[{"id":"1.187557995","rc":[{"batb":[[2,1.23,2137.78]],"batl":[[0,1.26,305.67]],"ltp":1.21,"tv":89886.91,"id":9342449}]}]}
{"op":"mcm","clk":"4230709214","pt":1631535745708,"mc":[{"id":"1.187557995","rc":[{"batb":[[0,1.25,155.92],[1,1.24,939.72]],"batl":[[1,1.27,632.62],[2,1.28,518.4]],"ltp":1.21,"tv":89886.91,"id":9342449},{"batb":[[2,4.5,252.99]],"batl":[[2,6,2]],"ltp":4.9,"tv":9158.1,"id":9633869}]}]}
{"op":"mcm","clk":"4230709260","pt":1631535746222,"mc":[{"id":"1.187557995","rc":[{"batl":[[0,1.26,493.67]],"ltp":1.21,"tv":89886.91,"id":9342449}]}]}
{"op":"mcm","clk":"4230709414","pt":1631535747481,"mc":[{"id":"1.187557995","rc":[{"batl":[[0,5.2,10.83],[1,5.3,7.23],[2,5.6,2]],"ltp":4.9,"tv":9158.1,"id":9633869}]}]}
{"op":"mcm","clk":"4230709510","pt":1631535748209,"mc":[{"id":"1.187557995","rc":[{"batb":[[0,1.25,355.92]],"batl":[[1,1.27,880.27]],"ltp":1.21,"tv":89886.91,"id":9342449}]}]}
{"op":"mcm","clk":"4230709611","pt":1631535749102,"mc":[{"id":"1.187557995","rc":[{"batb":[[2,1.23,2073.71]],"ltp":1.21,"tv":89886.91,"id":9342449}]}]}
{"op":"mcm","clk":"4230709853","pt":1631535751516,"mc":[{"id":"1.187557995","rc":[{"batb":[[0,1.25,433.38],[1,1.24,794.76]],"batl":[[0,1.26,567.08]],"ltp":1.21,"tv":89886.91,"id":9342449}]}]}
{"op":"mcm","clk":"4230709974","pt":1631535752512,"mc":[{"id":"1.187557995","rc":[{"batl":[[0,5.6,2],[1,6,2],[2,7,2]],"ltp":4.9,"tv":9158.1,"id":9633869}]}]}
{"op":"mcm","clk":"4230710070","pt":1631535753402,"mc":[{"id":"1.187557995","rc":[{"batb":[[0,1.25,200],[1,1.24,122.47],[2,1.2,528.5]],"batl":[[0,1.26,188],[1,1.29,346.3],[2,1.3,80.75]],"ltp":1.21,"tv":89886.91,"id":9342449},{"batb":[[0,4.5,17.14],[1,4.4,85.32],[2,4.3,2.68]],"batl":[[0,6,2],[1,7,2],[2,8.2,2]],"ltp":4.9,"tv":9158.1,"id":9633869}]}]}
{"op":"mcm","clk":"4230710172","pt":1631535754501,"mc":[{"id":"1.187557995","rc":[{"batb":[[1,1.2,528.5],[2,1.18,538.74]],"batl":[[0,1.29,331.3],[1,1.3,80.75],[2,1.31,76.5]],"ltp":1.21,"tv":89886.91,"id":9342449},{"batb":[[0,4.4,85.32],[1,4.3,2.68],[2,4.2,2.92]],"ltp":4.9,"tv":9158.1,"id":9633869}]}]}
{"op":"mcm","clk":"4230710284","pt":1631535755708,"mc":[{"id":"1.187557995","rc":[{"batl":[[0,5.5,10.83],[1,6,2],[2,7,2]],"ltp":4.9,"tv":9158.1,"id":9633869}]}]}
{"op":"mcm","clk":"4230710392","pt":1631535756692,"mc":[{"id":"1.187557995","rc":[{"batb":[[1,1.2,999.62],[2,1.19,687.01]],"batl":[[2,1.31,347.99]],"ltp":1.21,"tv":89886.91,"id":9342449},{"batl":[[0,6,2],[1,7,2],[2,8.2,2]],"ltp":4.9,"tv":9158.1,"id":9633869}]}]}
{"op":"mcm","clk":"4230710682","pt":1631535759820,"mc":[{"id":"1.187557995","rc":[{"batb":[[0,1.26,5.96],[1,1.25,200],[2,1.2,999.62]],"ltp":1.21,"tv":89886.91,"id":9342449}]}]}
{"op":"mcm","clk":"4230711109","pt":1631535763653,"mc":[{"id":"1.187557995","rc":[{"trd":[[1.26,1.86]],"batb":[[0,1.26,5.03]],"ltp":1.26,"tv":89888.77,"id":9342449}],"tv":99046.88}]}
{"op":"mcm","clk":"4230711310","pt":1631535765470,"mc":[{"id":"1.187557995","rc":[{"batb":[[2,1.2,528.5]],"batl":[[1,1.31,347.99],[2,1.32,360.62]],"ltp":1.26,"tv":89888.77,"id":9342449},{"batb":[[1,4.2,2.92],[2,1.97,1.05]],"batl":[[2,11,2]],"ltp":4.9,"tv":9158.1,"id":9633869}]}]}
{"op":"mcm","clk":"4230711494","pt":1631535767194,"mc":[{"id":"1.187557995","rc":[{"batl":[[0,1.29,94.5]],"ltp":1.26,"tv":89888.77,"id":9342449}]}]}
{"op":"mcm","clk":"4230711637","pt":1631535768655,"mc":[{"id":"1.187557995","rc":[{"batb":[[0,1.28,588.9],[1,1.27,460.64],[2,1.26,5.03]],"batl":[[0,1.29,5]],"ltp":1.26,"tv":89888.77,"id":9342449},{"trd":[[4.4,344.12]],"batb":[[0,4.4,80.7],[1,4.3,2],[2,4.2,2.92]],"batl":[[0,4.7,406.92],[1,4.8,394.96],[2,4.9,394.96]],"ltp":4.4,"tv":9168.23,"id":9633869}],"tv":99057.0}]}
{"op":"mcm","clk":"4230711716","pt":1631535769587,"mc":[{"id":"1.187557995","rc":[{"batb":[[1,1.27,576.11],[2,1.26,376.24]],"batl":[[0,1.31,347.99],[1,1.32,360.62],[2,1.33,790.88]],"ltp":1.26,"tv":89888.77,"id":9342449},{"batb":[[0,4.4,77.7],[1,4.2,2.92],[2,3.95,54.98]],"batl":[[0,4.7,414.71]],"ltp":4.4,"tv":9168.23,"id":9633869}]}]}
{"op":"mcm","clk":"4230711901","pt":1631535771690,"mc":[{"id":"1.187557995","rc":[{"batb":[[1,1.27,460.64]],"batl":[[0,1.31,384.57]],"ltp":1.26,"tv":89888.77,"id":9342449},{"batl":[[0,4.7,406.92]],"ltp":4.4,"tv":9168.23,"id":9633869}]}]}
{"op":"mcm","clk":"4230712038","pt":1631535772703,"mc":[{"id":"1.187557995","rc":[{"batb":[[0,1.28,628.44]],"batl":[[0,1.31,594.75]],"ltp":1.26,"tv":89888.77,"id":9342449},{"batl":[[0,4.6,12.63],[1,4.7,406.92],[2,4.8,394.96]],"ltp":4.4,"tv":9168.23,"id":9633869}]}]}
{"op":"mcm","clk":"4230712112","pt":1631535773389,"mc":[{"id":"1.187557995","rc":[{"batb":[[0,1.29,99.08],[1,1.28,628.44],[2,1.27,460.64]],"batl":[[0,1.3,78.83],[1,1.31,594.75],[2,1.32,360.62]],"ltp":1.26,"tv":89888.77,"id":9342449}]}]}
{"op":"mcm","clk":"4230712249","pt":1631535774624,"mc":[{"id":"1.187557995","rc":[{"batb":[[2,4.1,19.35]],"ltp":4.4,"tv":9168.23,"id":9633869}]}]}
{"op":"mcm","clk":"4230712307","pt":1631535775182,"mc":[{"id":"1.187557995","rc":[{"batl":[[2,1.32,375.62]],"ltp":1.26,"tv":89888.77,"id":9342449}]}]}
{"op":"mcm","clk":"4230712675","pt":1631535778387,"mc":[{"id":"1.187557995","rc":[{"batl":[[2,4.8,402.65]],"ltp":4.4,"tv":9168.23,"id":9633869}]}]}
{"op":"mcm","clk":"4230712851","pt":1631535779700,"mc":[{"id":"1.187557995","rc":[{"batl":[[0,1.3,147.9]],"ltp":1.26,"tv":89888.77,"id":9342449}]}]}
{"op":"mcm","clk":"4230712903","pt":1631535780165,"mc":[{"id":"1.187557995","rc":[{"batb":[[0,1.29,164.06]],"batl":[[0,1.3,289.06]],"ltp":1.26,"tv":89888.77,"id":9342449}]}]}
{"op":"mcm","clk":"4230713027","pt":1631535781477,"mc":[{"id":"1.187557995","rc":[{"trd":[[1.3,783.93]],"batl":[[0,1.3,286.74]],"ltp":1.3,"tv":89893.42,"id":9342449},{"trd":[[4.4,347.94]],"batb":[[0,4.4,75.79]],"ltp":4.4,"tv":9172.04,"id":9633869}],"tv":99065.47}]}
{"op":"mcm","clk":"4230713139","pt":1631535782475,"mc":[{"id":"1.187557995","rc":[{"trd":[[1.3,1183.93]],"batb":[[0,1.28,628.44],[1,1.27,460.64],[2,1.26,489.8]],"batl":[[0,1.3,10.23]],"ltp":1.3,"tv":90293.42,"id":9342449}],"tv":99465.47}]}
{"op":"mcm","clk":"4230713367","pt":1631535784474,"mc":[{"id":"1.187557995","rc":[{"trd":[[1.28,3158.26]],"batb":[[0,1.28,128.44]],"ltp":1.28,"tv":91293.42,"id":9342449}],"tv":100465.47}]}
{"op":"mcm","clk":"4230713511","pt":1631535785579,"mc":[{"id":"1.187557995","rc":[{"batl":[[2,1.32,15]],"ltp":1.28,"tv":91293.42,"id":9342449}]}]}
{"op":"mcm","clk":"4230713527","pt":1631535785736,"mc":[{"id":"1.187557995","rc":[{"batb":[[0,1.29,147.71],[1,1.28,128.44],[2,1.27,460.64]],"ltp":1.28,"tv":91293.42,"id":9342449}]}]}
{"op":"mcm","clk":"4230713734","pt":1631535787611,"mc":[{"id":"1.187557995","rc":[{"trd":[[1.3,1244.16]],"batb":[[1,1.28,270.59]],"batl":[[0,1.31,594.75],[1,1.32,15],[2,1.33,790.88]],"ltp":1.3,"tv":91353.65,"id":9342449},{"trd":[[4.4,359.69]],"batb":[[0,4.4,64.03]],"ltp":4.4,"tv":9183.8,"id":9633869}],"tv":100537.46}]}
{"op":"mcm","clk":"4230713760","pt":1631535787817,"mc":[{"id":"1.187557995","rc":[{"batb":[[1,1.28,494.29]],"batl":[[0,1.3,160.53],[1,1.31,704.4],[2,1.32,15]],"ltp":1.3,"tv":91353.65,"id":9342449}]}]}
{"op":"mcm","clk":"4230714138","pt":1631535791086,"mc":[{"id":"1.187557995","rc":[{"trd":[[1.29,4842.22]],"batb":[[0,1.28,494.29],[1,1.27,460.64],[2,1.26,489.8]],"batl":[[0,1.3,329.02]],"ltp":1.29,"tv":91360.43,"id":9342449}],"tv":100544.23}]}
{"op":"mcm","clk":"4230714427","pt":1631535793893,"mc":[{"id":"1.187557995","rc":[{"trd":[[4.4,370.33]],"batb":[[0,4.4,58.71]],"ltp":4.4,"tv":9194.44,"id":9633869}],"tv":100554.87}]}
{"op":"mcm","clk":"4230714745","pt":1631535797232,"mc":[{"id":"1.187557995","rc":[{"batb":[[0,1.28,454.75]],"ltp":1.29,"tv":91360.43,"id":9342449}]}]}
{"op":"mcm","clk":"4230715055","pt":1631535800530,"mc":[{"id":"1.187557995","rc":[{"trd":[[1.3,2100.87],[1.31,1365.3]],"batl":[[0,1.31,96.76],[1,1.32,15],[2,1.33,790.88]],"ltp":1.31,"tv":93432.52,"id":9342449},{"trd":[[4.4,429.04]],"batb":[[0,4.2,2.92],[1,4.1,19.35],[2,3.9,58.73]],"ltp":4.4,"tv":9253.15,"id":9633869}],"tv":102685.67}]}
{"op":"mcm","clk":"4230715351","pt":1631535803401,"mc":[{"id":"1.187557995","rc":[{"batb":[[0,1.29,155.98],[1,1.28,746.94],[2,1.27,460.64]],"batl":[[0,1.31,295.16],[1,1.32,375.78]],"ltp":1.31,"tv":93432.52,"id":9342449},{"batb":[[0,4.2,16.24]],"ltp":4.4,"tv":9253.15,"id":9633869}]}]}
{"op":"mcm","clk":"4230715586","pt":1631535805653,"mc":[{"id":"1.187557995","rc":[{"batb":[[1,1.28,181.91],[2,1.26,489.8]],"batl":[[0,1.32,15],[1,1.33,790.88],[2,1.34,1395.68]],"ltp":1.31,"tv":93432.52,"id":9342449}]}]}
{"op":"mcm","clk":"4230715659","pt":1631535806338,"mc":[{"id":"1.187557995","rc":[{"batl":[[0,1.31,559],[1,1.32,15],[2,1.33,790.88]],"ltp":1.31,"tv":93432.52,"id":9342449}]}]}
{"op":"mcm","clk":"4230716006","pt":1631535809534,"mc":[{"id":"1.187557995","rc":[{"batl":[[1,1.32,75.47]],"ltp":1.31,"tv":93432.52,"id":9342449}]}]}
{"op":"mcm","clk":"4230717912","pt":1631535829629,"mc":[{"id":"1.187557995","rc":[{"batb":[[0,1.26,489.8],[1,1.25,733.29],[2,1.24,533.61]],"batl":[[1,1.32,15],[2,1.35,74.1]],"ltp":1.31,"tv":93432.52,"id":9342449},{"batb":[[0,4.1,19.35],[1,3.9,55.73],[2,3.85,3.17]],"batl":[[0,4.8,7.69],[1,5.6,2.01],[2,990,0.01]],"ltp":4.4,"tv":9253.15,"id":9633869}]}]}
{"op":"mcm","clk":"4230718012","pt":1631535830629,"mc":[{"id":"1.187557995","rc":[{"batb":[[0,1.26,5.03]],"batl":[[0,1.36,306.58],[1,1.37,298.47],[2,1.38,66.75]],"ltp":1.31,"tv":93432.52,"id":9342449},{"batb":[[0,3.9,55.73],[1,3.6,2.94],[2,1.97,1.05]],"batl":[[0,5.6,2.01],[1,990,0.01],[2,990,0]],"ltp":4.4,"tv":9253.15,"id":9633869}]}]}
{"op":"mcm","clk":"4230718225","pt":1631535832678,"mc":[{"id":"1.187557995","rc":[{"batb":[[0,1.27,190.72],[1,1.26,5.03],[2,1.25,840.22]],"ltp":1.31,"tv":93432.52,"id":9342449},{"batb":[[1,3.85,57.57],[2,3.6,2.94]],"batl":[[0,5,2.23],[1,5.6,2.01],[2,990,0.01]],"ltp":4.4,"tv":9253.15,"id":9633869}]}]}
{"op":"mcm","clk":"4230718303","pt":1631535833153,"mc":[{"id":"1.187557995","rc":[{"batb":[[0,1.26,5.03],[1,1.25,840.22],[2,1.24,933.77]],"ltp":1.31,"tv":93432.52,"id":9342449},{"batb":[[0,3.85,57.57],[1,3.6,2.94],[2,1.97,1.05]],"ltp":4.4,"tv":9253.15,"id":9633869}]}]}
{"op":"mcm","clk":"4230718442","pt":1631535834351,"mc":[{"id":"1.187557995","rc":[{"batl":[[0,1.35,4],[1,1.36,311.58],[2,1.37,298.47]],"ltp":1.31,"tv":93432.52,"id":9342449},{"batl":[[0,4.4,5],[1,5,2.23],[2,5.6,2.01]],"ltp":4.4,"tv":9253.15,"id":9633869}]}]}
{"op":"mcm","clk":"4230718520","pt":1631535835087,"mc":[{"id":"1.187557995","rc":[{"trd":[[1.29,4842.32]],"batl":[[0,1.34,227.43],[1,1.35,4],[2,1.36,311.58]],"ltp":1.29,"tv":93432.61,"id":9342449},{"trd":[[4.4,429.07]],"batl":[[0,4.4,4.97]],"ltp":4.4,"tv":9253.18,"id":9633869}],"tv":102685.8}]}
{"op":"mcm","clk":"4230718788","pt":1631535837452,"mc":[{"id":"1.187557995","rc":[{"batl":[[1,1.35,75.3]],"ltp":1.29,"tv":93432.61,"id":9342449},{"batb":[[0,3.85,60.34]],"ltp":4.4,"tv":9253.18,"id":9633869}]}]}
{"op":"mcm","clk":"4230719331","pt":1631535842143,"mc":[{"id":"1.187557995","rc":[{"batl":[[2,1.36,5]],"ltp":1.29,"tv":93432.61,"id":9342449}]}]}
{"op":"mcm","clk":"4230719529","pt":1631535843877,"mc":[{"id":"1.187557995","rc":[{"batb":[[1,1.25,604.27]],"ltp":1.29,"tv":93432.61,"id":9342449}]}]}
{"op":"mcm","clk":"4230719735","pt":1631535845673,"mc":[{"id":"1.187557995","rc":[{"trd":[[1.29,4859.27]],"batl":[[0,1.28,520.79],[1,1.29,405.48],[2,1.3,3008.67]],"ltp":1.29,"tv":93449.56,"id":9342449},{"trd":[[4.4,434.04]],"batb":[[0,4.6,102.18],[1,4.5,51.08],[2,4.4,55.94]],"batl":[[0,5,2.23],[1,5.6,2.01],[2,990,0.01]],"ltp":4.4,"tv":9258.15,"id":9633869}],"tv":102707.72}]}
{"op":"mcm","clk":"4230719831","pt":1631535846377,"mc":[{"id":"1.187557995","rc":[{"batb":[[2,1.24,1170.67]],"batl":[[1,1.29,420.48]],"ltp":1.29,"tv":93449.56,"id":9342449},{"trd":[[4.6,9.3]],"batb":[[0,4.6,172.09],[2,4.4,51.08]],"batl":[[1,5.3,7.23],[2,5.6,2.01]],"ltp":4.6,"tv":9267.45,"id":9633869}],"tv":102717.02}]}
{"op":"mcm","clk":"4230720026","pt":1631535848304,"mc":[{"id":"1.187557995","rc":[{"batb":[[1,4.5,68.22]],"batl":[[0,5,11.84]],"ltp":4.6,"tv":9267.45,"id":9633869}]}]}
{"op":"mcm","clk":"4230720176","pt":1631535849679,"mc":[{"id":"1.187557995","rc":[{"batb":[[0,1.26,301.11]],"batl":[[0,1.27,63.9],[1,1.28,660.79],[2,1.29,420.48]],"ltp":1.29,"tv":93449.56,"id":9342449}]}]}
{"op":"mcm","clk":"4230720255","pt":1631535850503,"mc":[{"id":"1.187557995","rc":[{"batb":[[0,1.26,362.39]],"batl":[[1,1.28,837.51],[2,1.29,405.48]],"ltp":1.29,"tv":93449.56,"id":9342449},{"batb":[[0,4.6,183.89],[1,4.5,51.08]],"ltp":4.6,"tv":9267.45,"id":9633869}]}]}
{"op":"mcm","clk":"4230720446","pt":1631535852573,"mc":[{"id":"1.187557995","rc":[{"batb":[[2,1.24,1608.19]],"ltp":1.29,"tv":93449.56,"id":9342449},{"batl":[[1,5.2,7.38],[2,5.3,7.23]],"ltp":4.6,"tv":9267.45,"id":9633869}]}]}
{"op":"mcm","clk":"4230720543","pt":1631535853459,"mc":[{"id":"1.187557995","rc":[{"batl":[[1,1.28,852.51]],"ltp":1.29,"tv":93449.56,"id":9342449},{"batb":[[0,4.6,200.55]],"ltp":4.6,"tv":9267.45,"id":9633869}]}]}
{"op":"mcm","clk":"4230720845","pt":1631535856677,"mc":[{"id":"1.187557995","rc":[{"batb":[[0,1.27,39.11],[1,1.26,418.95],[2,1.25,604.27]],"batl":[[0,1.28,932.92],[1,1.29,405.48],[2,1.3,3330.92]],"ltp":1.29,"tv":93449.56,"id":9342449}]}]}
{"op":"mcm","clk":"4230720876","pt":1631535856943,"mc":[{"id":"1.187557995","rc":[{"batb":[[1,1.26,258.56]],"batl":[[0,1.28,804.84]],"ltp":1.29,"tv":93449.56,"id":9342449}]}]}
{"op":"mcm","clk":"4230721059","pt":1631535858663,"mc":[{"id":"1.187557995","rc":[{"batb":[[0,1.26,197.27],[1,1.24,837.68],[2,1.23,542.48]],"batl":[[0,1.28,155],[1,1.31,253.83],[2,1.32,281.36]],"ltp":1.29,"tv":93449.56,"id":9342449},{"batb":[[0,4.6,91.22],[1,4.2,95.06],[2,4.1,9.54]],"batl":[[0,5.2,7.38],[1,5.3,7.23],[2,5.6,2.01]],"ltp":4.6,"tv":9267.45,"id":9633869}]}]}
{"op":"mcm","clk":"4230721128","pt":1631535859454,"mc":[{"id":"1.187557995","rc":[{"batb":[[0,1.26,5.03],[1,1.23,417.38],[2,1.22,570.21]],"batl":[[0,1.31,253.83],[1,1.32,281.36],[2,1.35,75.3]],"ltp":1.29,"tv":93449.56,"id":9342449},{"batb":[[0,4.2,95.06],[1,4.1,9.54],[2,3.95,3]],"batl":[[0,5.6,2.01],[1,990,0.01],[2,5.6,0]],"ltp":4.6,"tv":9267.45,"id":9633869}]}]}
{"op":"mcm","clk":"4230721212","pt":1631535860448,"mc":[{"id":"1.187557995","rc":[{"batl":[[2,1.33,329.5]],"ltp":1.29,"tv":93449.56,"id":9342449},{"batb":[[2,4,11.91]],"ltp":4.6,"tv":9267.45,"id":9633869}]}]}
{"op":"mcm","clk":"4230721332","pt":1631535861670,"mc":[{"id":"1.187557995","rc":[{"batb":[[2,1.22,1295.42]],"batl":[[0,1.3,312.55],[1,1.31,253.83],[2,1.32,705.43]],"ltp":1.29,"tv":93449.56,"id":9342449},{"batb":[[0,4.3,9.88],[1,4.2,95.06],[2,4.1,9.54]],"ltp":4.6,"tv":9267.45,"id":9633869}]}]}
{"op":"mcm","clk":"4230721431","pt":1631535862554,"mc":[{"id":"1.187557995","rc":[{"batl":[[0,1.31,253.83],[1,1.32,705.43],[2,1.33,674.58]],"ltp":1.29,"tv":93449.56,"id":9342449},{"batb":[[0,4.2,95.06],[1,4.1,9.54],[2,4,11.91]],"ltp":4.6,"tv":9267.45,"id":9633869}]}]}
{"op":"mcm","clk":"4230721689","pt":1631535865282,"mc":[{"id":"1.187557995","rc":[{"trd":[[1.26,11.92]],"batb":[[0,1.23,417.38],[1,1.22,1295.42],[2,1.21,411.68]],"batl":[[0,1.25,4840.63],[1,1.3,352.15],[2,1.31,253.83]],"ltp":1.26,"tv":93459.63,"id":9342449},{"batb":[[0,4.3,9.18],[1,4.2,95.06],[2,4.1,9.54]],"ltp":4.6,"tv":9267.45,"id":9633869}],"tv":102727.08}]}
{"op":"mcm","clk":"4230722310","pt":1631535871669,"mc":[{"id":"1.187557995","rc":[{"batb":[[1,1.22,570.21],[2,1.16,584.08]],"batl":[[0,1.31,253.83],[1,1.32,281.36],[2,1.33,329.5]],"ltp":1.26,"tv":93459.63,"id":9342449},{"batb":[[0,4.2,95.06],[1,4.1,9.54],[2,4,11.91]],"ltp":4.6,"tv":9267.45,"id":9633869}]}]}
{"op":"mcm","clk":"4230722481","pt":1631535873542,"mc":[{"id":"1.187557995","rc":[{"batb":[[2,1.11,250]],"ltp":1.26,"tv":93459.63,"id":9342449}]}]}
{"op":"mcm","clk":"4230722557","pt":1631535874580,"mc":[{"id":"1.187557995","rc":[{"batb":[[0,1.26,359.42],[1,1.25,598.87],[2,1.23,417.38]],"batl":[[0,1.28,202.43],[1,1.29,411.02],[2,1.31,253.83]],"ltp":1.26,"tv":93459.63,"id":9342449},{"batb":[[0,4.5,18.6],[1,4.2,95.06],[2,4.1,9.54]],"batl":[[0,4.9,21.35],[1,5.6,2.01],[2,990,0.01]],"ltp":4.6,"tv":9267.45,"id":9633869}]}]}
{"op":"mcm","clk":"4230722623","pt":1631535875469,"mc":[{"id":"1.187557995","rc":[{"batb":[[1,1.25,504.32],[2,1.24,91.25]],"batl":[[0,1.28,180.34],[2,1.3,78.61]],"ltp":1.26,"tv":93459.63,"id":9342449},{"batb":[[0,4.3,26.17]],"batl":[[0,5.5,10.05]],"ltp":4.6,"tv":9267.45,"id":9633869}]}]}
{"op":"mcm","clk":"4230722693","pt":1631535876360,"mc":[{"id":"1.187557995","rc":[{"batl":[[2,1.3,429.86]],"ltp":1.26,"tv":93459.63,"id":9342449},{"batb":[[0,4.3,9.28]],"ltp":4.6,"tv":9267.45,"id":9633869}]}]}
{"op":"mcm","clk":"4230722791","pt":1631535877463,"mc":[{"id":"1.187557995","rc":[{"batb":[[2,1.24,501.77]],"ltp":1.26,"tv":93459.63,"id":9342449},{"batl":[[0,5.2,7.93]],"ltp":4.6,"tv":9267.45,"id":9633869}]}]}
{"op":"mcm","clk":"4230722874","pt":1631535878664,"mc":[{"id":"1.187557995","rc":[{"batb":[[0,1.26,174.4],[1,1.24,410.52],[2,1.23,606.47]],"batl":[[0,1.3,351.25],[1,1.31,253.83],[2,1.32,281.36]],"ltp":1.26,"tv":93459.63,"id":9342449}]}]}
{"op":"mcm","clk":"4230722958","pt":1631535879663,"mc":[{"id":"1.187557995","rc":[{"batb":[[0,1.23,606.47],[1,1.22,570.21],[2,1.18,557.31]],"batl":[[0,1.31,253.83],[1,1.32,281.36],[2,1.33,329.5]],"ltp":1.26,"tv":93459.63,"id":9342449},{"batb":[[0,4.2,95.06],[1,4.1,9.54],[2,4,11.91]],"batl":[[0,5.6,2.01],[1,990,0.01],[2,990,0]],"ltp":4.6,"tv":9267.45,"id":9633869}]}]}
{"op":"mcm","clk":"4230723108","pt":1631535881481,"mc":[{"id":"1.187557995","rc":[{"batb":[[1,1.22,1295.42],[2,1.21,411.68]],"batl":[[1,1.32,705.43],[2,1.33,674.58]],"ltp":1.26,"tv":93459.63,"id":9342449}]}]}
{"op":"mcm","clk":"4230723165","pt":1631535882165,"mc":[{"id":"1.187557995","rc":[{"batb":[[1,1.22,570.21],[2,1.18,557.31]],"ltp":1.26,"tv":93459.63,"id":9342449}]}]}
{"op":"mcm","clk":"4230723389","pt":1631535884708,"mc":[{"id":"1.187557995","rc":[{"batb":[[0,1.29,7173.75],[1,1.28,2988.28],[2,1.27,2900.38]],"batl":[[0,1.32,705.43],[1,1.33,674.58],[2,1.35,71.3]],"ltp":1.26,"tv":93459.63,"id":9342449},{"trd":[[4.2,10.26]],"batb":[[0,4.2,89.93],[2,4,968.17]],"ltp":4.2,"tv":9277.71,"id":9633869}],"tv":102737.34}]}
{"op":"mcm","clk":"4230723486","pt":1631535885700,"mc":[{"id":"1.187557995","rc":[{"batb":[[0,1.29,444.66],[1,1.28,2328.73],[2,1.27,1450.18]],"ltp":1.26,"tv":93459.63,"id":9342449},{"batb":[[2,4,274.89]],"batl":[[0,4.6,5.56],[1,5.6,2.01],[2,990,0.01]],"ltp":4.2,"tv":9277.71,"id":9633869}]}]}
{"op":"mcm","clk":"4230723567","pt":1631535886690,"mc":[{"id":"1.187557995","rc":[{"batl":[[0,1.32,720.43]],"ltp":1.26,"tv":93459.63,"id":9342449},{"batb":[[1,4.1,28.89]],"batl":[[1,4.8,7.69],[2,5.2,10.05]],"ltp":4.2,"tv":9277.71,"id":9633869}]}]}
{"op":"mcm","clk":"4230723650","pt":1631535887675,"mc":[{"id":"1.187557995","rc":[{"batl":[[0,1.32,759.84]],"ltp":1.26,"tv":93459.63,"id":9342449},{"batl":[[2,5.6,2.01]],"ltp":4.2,"tv":9277.71,"id":9633869}]}]}
{"op":"mcm","clk":"4230723811","pt":1631535889697,"mc":[{"id":"1.187557995","rc":[{"batb":[[0,1.3,179.83],[1,1.29,683.38],[2,1.28,2328.73]],"batl":[[0,1.31,71.7],[1,1.32,818.83],[2,1.33,674.58]],"ltp":1.26,"tv":93459.63,"id":9342449}]}]}
{"op":"mcm","clk":"4230723853","pt":1631535890176,"mc":[{"id":"1.187557995","rc":[{"batl":[[0,4.5,12.87],[1,4.6,5.56]],"ltp":4.2,"tv":9277.71,"id":9633869}]}]}
{"op":"mcm","clk":"4230724025","pt":1631535892324,"mc":[{"id":"1.187557995","rc":[{"batb":[[0,1.3,352.02]],"ltp":1.26,"tv":93459.63,"id":9342449},{"batl":[[2,4.9,9.35]],"ltp":4.2,"tv":9277.71,"id":9633869}]}]}
{"op":"mcm","clk":"4230724141","pt":1631535893674,"mc":[{"id":"1.187557995","rc":[{"batl":[[2,4.7,7.79]],"ltp":4.2,"tv":9277.71,"id":9633869}]}]}
{"op":"mcm","clk":"4230724311","pt":1631535896113,"mc":[{"id":"1.187557995","rc":[{"batb":[[0,1.31,28.17],[1,1.3,251.38],[2,1.29,615.23]],"batl":[[0,1.32,896.64],[1,1.33,674.58],[2,1.35,71.3]],"ltp":1.26,"tv":93459.63,"id":9342449}]}]}
{"op":"mcm","clk":"4230724384","pt":1631535897206,"mc":[{"id":"1.187557995","rc":[{"batb":[[2,1.29,547.02]],"ltp":1.26,"tv":93459.63,"id":9342449}]}]}
{"op":"mcm","clk":"4230724456","pt":1631535898086,"mc":[{"id":"1.187557995","rc":[{"batb":[[0,1.3,172.19],[1,1.29,547.02],[2,1.28,2328.73]],"batl":[[0,1.32,759.84]],"ltp":1.26,"tv":93459.63,"id":9342449}]}]}
{"op":"mcm","clk":"4230724577","pt":1631535899586,"mc":[{"id":"1.187557995","rc":[{"batl":[[0,1.32,1026.84]],"ltp":1.26,"tv":93459.63,"id":9342449}]}]}
{"op":"mcm","clk":"4230724652","pt":1631535900578,"mc":[{"id":"1.187557995","rc":[{"batb":[[0,1.26,772.21],[1,1.25,783.68],[2,1.23,424.63]],"batl":[[0,1.32,282],[1,1.36,246.17],[2,1.38,66.75]],"ltp":1.26,"tv":93459.63,"id":9342449},{"batb":[[0,4.1,19.35],[1,3.7,63.35],[2,3.6,2.94]],"batl":[[0,4.7,7.79],[1,4.9,9.35],[2,5.4,8.34]],"ltp":4.2,"tv":9277.71,"id":9633869}]}]}
{"op":"mcm","clk":"4230724720","pt":1631535901521,"mc":[{"id":"1.187557995","rc":[{"batb":[[0,1.26,395.23],[1,1.25,991.51]],"batl":[[0,1.36,246.17],[1,1.38,66.75],[2,1.4,263.49]],"ltp":1.26,"tv":93459.63,"id":9342449},{"batb":[[0,3.7,63.35],[1,3.6,2.94],[2,3.5,13.1]],"batl":[[0,5.4,8.34],[1,5.6,2.01],[2,990,0.01]],"ltp":4.2,"tv":9277.71,"id":9633869}]}]}
{"op":"mcm","clk":"4230724874","pt":1631535903694,"mc":[{"id":"1.187557995","rc":[{"batb":[[1,1.25,1515.6],[2,1.24,534.16]],"batl":[[1,1.37,166.45],[2,1.38,356.19]],"ltp":1.26,"tv":93459.63,"id":9342449}]}]}
{"op":"mcm","clk":"4230724985","pt":1631535905199,"mc":[{"id":"1.187557995","rc":[{"batl":[[0,1.3,2.32],[1,1.36,246.17],[2,1.37,166.45]],"ltp":1.26,"tv":93459.63,"id":9342449}]}]}
{"op":"mcm","clk":"4230725271","pt":1631535908693,"mc":[{"id":"1.187557995","rc":[{"batl":[[0,1.36,246.17],[1,1.37,166.45],[2,1.38,356.19]],"ltp":1.26,"tv":93459.63,"id":9342449}]}]}
{"op":"mcm","clk":"4230725290","pt":1631535908904,"mc":[{"id":"1.187557995","rc":[{"batl":[[1,1.38,66.75],[2,1.4,263.49]],"ltp":1.26,"tv":93459.63,"id":9342449}]}]}
{"op":"mcm","clk":"4230725413","pt":1631535910624,"mc":[{"id":"1.187557995","rc":[{"batb":[[0,1.25,912.54],[1,1.24,534.16],[2,1.23,424.63]],"batl":[[0,1.38,66.75],[1,1.4,263.49],[2,1.41,243.5]],"ltp":1.26,"tv":93459.63,"id":9342449}]}]}
{"op":"mcm","clk":"4230725507","pt":1631535911712,"mc":[{"id":"1.187557995","rc":[{"batl":[[0,1.28,2881.2]],"ltp":1.26,"tv":93459.63,"id":9342449},{"batb":[[1,3.5,13.1],[2,3.4,13.31]],"ltp":4.2,"tv":9277.71,"id":9633869}]}]}
{"op":"mcm","clk":"4230725591","pt":1631535912542,"mc":[{"id":"1.187557995","rc":[{"batl":[[0,1.28,496.2],[1,1.29,405.88],[2,1.38,14.49]],"ltp":1.26,"tv":93459.63,"id":9342449},{"batb":[[0,4.5,425],[1,4.4,412.5],[2,4.3,412.5]],"batl":[[0,5.3,198.46],[1,5.4,358.58],[2,5.5,350.24]],"ltp":4.2,"tv":9277.71,"id":9633869}]}]}
{"op":"mcm","clk":"4230725661","pt":1631535913525,"mc":[{"id":"1.187557995","rc":[{"batl":[[1,1.29,420.88]],"ltp":1.26,"tv":93459.63,"id":9342449},{"trd":[[4.5,40.38]],"batb":[[0,4.5,498.17],[1,4.4,430.14]],"batl":[[0,5.3,205.69]],"ltp":4.5,"tv":9287.01,"id":9633869}],"tv":102746.64}]}
{"op":"mcm","clk":"4230725724","pt":1631535914250,"mc":[{"id":"1.187557995","rc":[{"batb":[[0,1.25,953.68],[2,1.23,549.73]],"batl":[[2,1.37,7]],"ltp":1.26,"tv":93459.63,"id":9342449}]}]}
{"op":"mcm","clk":"4230725817","pt":1631535915449,"mc":[{"id":"1.187557995","rc":[{"batl":[[2,1.37,191.22]],"ltp":1.26,"tv":93459.63,"id":9342449}]}]}
{"op":"mcm","clk":"4230725891","pt":1631535916550,"mc":[{"id":"1.187557995","rc":[{"batb":[[0,1.26,383.28],[1,1.25,953.68],[2,1.24,534.16]],"batl":[[0,1.27,68.99],[1,1.28,496.2],[2,1.29,420.88]],"ltp":1.26,"tv":93459.63,"id":9342449}]}]}
{"op":"mcm","clk":"4230725944","pt":1631535917325,"mc":[{"id":"1.187557995","rc":[{"batl":[[1,1.28,669.94],[2,1.29,405.88]],"ltp":1.26,"tv":93459.63,"id":9342449},{"batb":[[0,4.6,60.53],[1,4.5,498.17],[2,4.4,412.5]],"batl":[[0,5.2,22.24],[1,5.3,205.69],[2,5.4,358.58]],"ltp":4.5,"tv":9287.01,"id":9633869}]}]}
{"op":"mcm","clk":"4230726023","pt":1631535918458,"mc":[{"id":"1.187557995","rc":[{"batb":[[2,1.24,941.18]],"ltp":1.26,"tv":93459.63,"id":9342449},{"batb":[[0,4.6,11.02]],"batl":[[0,5.2,29.82]],"ltp":4.5,"tv":9287.01,"id":9633869}]}]}
{"op":"mcm","clk":"4230726088","pt":1631535919353,"mc":[{"id":"1.187557995","rc":[{"batl":[[0,5.2,7.58]],"ltp":4.5,"tv":9287.01,"id":9633869}]}]}
{"op":"mcm","clk":"4230726159","pt":1631535920451,"mc":[{"id":"1.187557995","rc":[{"batl":[[1,1.28,684.94]],"ltp":1.26,"tv":93459.63,"id":9342449},{"batb":[[1,4.5,515.31]],"ltp":4.5,"tv":9287.01,"id":9633869}]}]}
{"op":"mcm","clk":"4230726248","pt":1631535921843,"mc":[{"id":"1.187557995","rc":[{"batl":[[0,5.1,22.24],[1,5.2,7.58],[2,5.3,205.69]],"ltp":4.5,"tv":9287.01,"id":9633869}]}]}
{"op":"mcm","clk":"4230726348","pt":1631535923451,"mc":[{"id":"1.187557995","rc":[{"batb":[[0,1.27,34.03],[1,1.26,279.45],[2,1.25,953.68]],"batl":[[0,1.28,634.76],[1,1.29,405.88],[2,1.3,359.95]],"ltp":1.26,"tv":93459.63,"id":9342449}]}]}
{"op":"mcm","clk":"4230726494","pt":1631535925573,"mc":[{"id":"1.187557995","rc":[{"batb":[[0,1.26,205.47],[1,1.25,953.68],[2,1.24,941.18]],"batl":[[0,1.28,557.02]],"ltp":1.26,"tv":93459.63,"id":9342449}]}]}
{"op":"mcm","clk":"4230727063","pt":1631535932696,"mc":[{"id":"1.187557995","rc":[{"batb":[[1,1.25,388.45],[2,1.24,407.02]],"batl":[[0,1.28,15],[1,1.31,290.5],[2,1.32,520.7]],"ltp":1.26,"tv":93459.63,"id":9342449},{"batb":[[0,4.5,94.96],[1,4.2,10.42],[2,4.1,12.24]],"batl":[[0,5.2,7.58],[1,5.3,7.23],[2,5.4,8.34]],"ltp":4.5,"tv":9287.01,"id":9633869}]}]}
{"op":"mcm","clk":"4230727135","pt":1631535933693,"mc":[{"id":"1.187557995","rc":[{"batb":[[0,1.23,352.53],[1,1.22,1018.37],[2,1.2,538.19]],"batl":[[1,1.32,207.84],[2,1.33,319.5]],"ltp":1.26,"tv":93459.63,"id":9342449},{"batb":[[0,4.5,17.14],[1,4,115.4],[2,3.8,3]],"batl":[[0,5.3,7.23],[1,5.6,2.01],[2,990,0.01]],"ltp":4.5,"tv":9287.01,"id":9633869}]}]}
{"op":"mcm","clk":"4230727185","pt":1631535934374,"mc":[{"id":"1.187557995","rc":[{"batb":[[0,1.23,227.43]],"batl":[[0,1.32,207.84],[1,1.33,319.5],[2,1.37,7]],"ltp":1.26,"tv":93459.63,"id":9342449},{"batb":[[0,4,115.4],[1,3.8,3],[2,3.5,13.1]],"batl":[[0,5.6,2.01],[1,990,0.01],[2,990,0]],"ltp":4.5,"tv":9287.01,"id":9633869}]}]}
{"op":"mcm","clk":"4230727281","pt":1631535935568,"mc":[{"id":"1.187557995","rc":[{"batb":[[0,1.25,199.62],[1,1.23,227.43],[2,1.22,1557.95]],"batl":[[0,1.32,405.81],[1,1.33,667.42]],"ltp":1.26,"tv":93459.63,"id":9342449}]}]}
{"op":"mcm","clk":"4230727369","pt":1631535936558,"mc":[{"id":"1.187557995","rc":[{"batb":[[0,1.24,399.27]],"batl":[[0,1.31,347.5],[1,1.32,405.81],[2,1.33,667.42]],"ltp":1.26,"tv":93459.63,"id":9342449},{"batb":[[0,4.2,11.02],[1,4,115.4],[2,3.8,3]],"batl":[[0,5.2,8.43],[1,5.6,2.01],[2,990,0.01]],"ltp":4.5,"tv":9287.01,"id":9633869}]}]}
{"op":"mcm","clk":"4230727398","pt":1631535936871,"mc":[{"id":"1.187557995","rc":[{"batb":[[0,1.23,227.43],[1,1.22,1018.37],[2,1.2,538.19]],"batl":[[0,1.32,207.84],[1,1.33,319.5],[2,1.37,7]],"ltp":1.26,"tv":93459.63,"id":9342449},{"batb":[[0,4,115.4],[1,3.8,3],[2,3.5,13.1]],"batl":[[0,5.6,2.01],[1,990,0.01],[2,990,0]],"ltp":4.5,"tv":9287.01,"id":9633869}]}]}
{"op":"mcm","clk":"4230727578","pt":1631535939475,"mc":[{"id":"1.187557995","rc":[{"batl":[[0,5.1,246.06],[1,5.6,2.01],[2,990,0.01]],"ltp":4.5,"tv":9287.01,"id":9633869}]}]}
{"op":"mcm","clk":"4230727641","pt":1631535940262,"mc":[{"id":"1.187557995","rc":[{"batb":[[0,1.26,434.37],[1,1.25,505.7],[2,1.24,425.52]],"batl":[[0,1.29,520.45],[1,1.3,388.41],[2,1.31,333.5]],"ltp":1.26,"tv":93459.63,"id":9342449},{"batb":[[0,4.2,9.47],[1,4,115.4],[2,3.8,3]],"batl":[[0,5.2,7.23]],"ltp":4.5,"tv":9287.01,"id":9633869}]}]}
{"op":"mcm","clk":"4230727771","pt":1631535942082,"mc":[{"id":"1.187557995","rc":[{"batb":[[2,1.24,520.24]],"ltp":1.26,"tv":93459.63,"id":9342449}]}]}
{"op":"mcm","clk":"4230727932","pt":1631535944201,"mc":[{"id":"1.187557995","rc":[{"batl":[[0,1.28,267],[1,1.29,520.45],[2,1.3,388.41]],"ltp":1.26,"tv":93459.63,"id":9342449}]}]}
{"op":"mcm","clk":"4230728047","pt":1631535945579,"mc":[{"id":"1.187557995","rc":[{"batb":[[0,1.26,231.05],[1,1.24,425.52],[2,1.23,227.43]],"batl":[[1,1.31,333.5],[2,1.32,207.84]],"ltp":1.26,"tv":93459.63,"id":9342449}]}]}
{"op":"mcm","clk":"4230728123","pt":1631535946606,"mc":[{"id":"1.187557995","rc":[{"batb":[[0,1.23,227.43],[1,1.22,1018.37],[2,1.2,538.19]],"batl":[[0,1.32,207.84],[1,1.33,319.5],[2,1.37,7]],"ltp":1.26,"tv":93459.63,"id":9342449},{"batb":[[0,4,115.4],[1,3.8,3],[2,3.5,13.1]],"batl":[[0,5.6,2.01],[1,990,0.01],[2,990,0]],"ltp":4.5,"tv":9287.01,"id":9633869}]}]}
{"op":"mcm","clk":"4230728258","pt":1631535948492,"mc":[{"id":"1.187557995","rc":[{"batb":[[1,1.22,1557.95],[2,1.21,598.84]],"batl":[[0,1.32,405.81],[1,1.33,667.42]],"ltp":1.26,"tv":93459.63,"id":9342449}]}]}
{"op":"mcm","clk":"4230728326","pt":1631535949577,"mc":[{"id":"1.187557995","rc":[{"batb":[[0,1.24,481.27],[1,1.23,227.43],[2,1.22,1557.95]],"ltp":1.26,"tv":93459.63,"id":9342449},{"batl":[[0,5.2,8.18],[1,5.6,2.01],[2,990,0.01]],"ltp":4.5,"tv":9287.01,"id":9633869}]}]}
{"op":"mcm","clk":"4230728380","pt":1631535950213,"mc":[{"id":"1.187557995","rc":[{"batb":[[0,1.23,227.43],[1,1.22,1557.95],[2,1.21,598.84]],"ltp":1.26,"tv":93459.63,"id":9342449},{"batl":[[0,5.6,2.01],[1,990,0.01],[2,990,0]],"ltp":4.5,"tv":9287.01,"id":9633869}]}]}
{"op":"mcm","clk":"4230728846","pt":1631535956387,"mc":[{"id":"1.187557995","rc":[{"batb":[[1,1.22,1018.37],[2,1.2,538.19]],"ltp":1.26,"tv":93459.63,"id":9342449}]}]}
{"op":"mcm","clk":"4230728948","pt":1631535957792,"mc":[{"id":"1.187557995","rc":[{"batl":[[0,1.32,197.97]],"ltp":1.26,"tv":93459.63,"id":9342449}]}]}
{"op":"mcm","clk":"4230729110","pt":1631535959618,"mc":[{"id":"1.187557995","rc":[{"trd":[[1.32,457.94]],"batb":[[0,1.3,201.71],[1,1.29,543.23],[2,1.28,1494.14]],"batl":[[0,1.32,181.85]],"ltp":1.32,"tv":93475.75,"id":9342449},{"trd":[[4.1,20.22]],"batb":[[0,4,378.38],[1,3.95,255.23],[2,3.9,255.23]],"batl":[[0,4.5,5.67],[1,5.6,2.01],[2,990,0.01]],"ltp":4.1,"tv":9292.2,"id":9633869}],"tv":102767.95}]}
{"op":"mcm","clk":"4230729194","pt":1631535960625,"mc":[{"id":"1.187557995","rc":[{"batb":[[1,1.29,861.72]],"batl":[[1,1.33,682.42]],"ltp":1.32,"tv":93475.75,"id":9342449},{"batb":[[0,4,417.33]],"batl":[[1,4.7,7.79],[2,5.1,42.18]],"ltp":4.1,"tv":9292.2,"id":9633869}]}]}
{"op":"mcm","clk":"4230729210","pt":1631535960806,"mc":[{"id":"1.187557995","rc":[{"batl":[[2,5.6,2.01]],"ltp":4.1,"tv":9292.2,"id":9633869}]}]}
{"op":"mcm","clk":"4230729352","pt":1631535962503,"mc":[{"id":"1.187557995","rc":[{"batl":[[1,5.6,2.01],[2,990,0.01]],"ltp":4.1,"tv":9292.2,"id":9633869}]}]}
{"op":"mcm","clk":"4230729438","pt":1631535963617,"mc":[{"id":"1.187557995","rc":[{"batb":[[0,1.31,99.87],[1,1.3,257.59],[2,1.29,861.72]],"batl":[[0,1.32,261.78]],"ltp":1.32,"tv":93475.75,"id":9342449}]}]}
{"op":"mcm","clk":"4230729501","pt":1631535964512,"mc":[{"id":"1.187557995","rc":[{"batb":[[1,1.3,473.73],[2,1.29,932.85]],"batl":[[1,1.33,738.96]],"ltp":1.32,"tv":93475.75,"id":9342449}]}]}
{"op":"mcm","clk":"4230729574","pt":1631535965695,"mc":[{"id":"1.187557995","rc":[{"batl":[[1,4.6,7.9],[2,5.6,2.01]],"ltp":4.1,"tv":9292.2,"id":9633869}]}]}
{"op":"mcm","clk":"4230729629","pt":1631535966333,"mc":[{"id":"1.187557995","rc":[{"batl":[[2,4.8,8.42]],"ltp":4.1,"tv":9292.2,"id":9633869}]}]}
{"op":"mcm","clk":"4230729782","pt":1631535968422,"mc":[{"id":"1.187557995","rc":[{"trd":[[1.32,567.27]],"batl":[[0,1.32,79.93]],"ltp":1.32,"tv":93585.08,"id":9342449},{"trd":[[4.1,55.42]],"ltp":4.1,"tv":9327.4,"id":9633869}],"tv":102912.48}]}
{"op":"mcm","clk":"4230729938","pt":1631535970705,"mc":[{"id":"1.187557995","rc":[{"trd":[[1.31,1382.96]],"batb":[[0,1.31,91.04],[1,1.3,549.04],[2,1.29,861.72]],"batl":[[1,1.33,682.42]],"ltp":1.31,"tv":93602.74,"id":9342449}],"tv":102930.15}]}
{"op":"mcm","clk":"4230729975","pt":1631535971236,"mc":[{"id":"1.187557995","rc":[{"batb":[[0,1.31,274.82],[1,1.3,621.25],[2,1.29,793.42]],"batl":[[1,1.33,808.43],[2,1.34,330.52]],"ltp":1.31,"tv":93602.74,"id":9342449},{"batl":[[0,4.5,22.13]],"ltp":4.1,"tv":9327.4,"id":9633869}]}]}
{"op":"mcm","clk":"4230730064","pt":1631535972339,"mc":[{"id":"1.187557995","rc":[{"batb":[[0,1.31,183.78],[1,1.3,490.06]],"batl":[[0,1.33,808.43],[1,1.34,330.52],[2,1.37,7]],"ltp":1.31,"tv":93602.74,"id":9342449},{"batl":[[0,4.5,5.67]],"ltp":4.1,"tv":9327.4,"id":9633869}]}]}
{"op":"mcm","clk":"4230730289","pt":1631535975499,"mc":[{"id":"1.187557995","rc":[{"batl":[[0,1.33,855.2]],"ltp":1.31,"tv":93602.74,"id":9342449},{"batl":[[0,4.4,16.46],[1,4.5,5.67],[2,4.6,7.9]],"ltp":4.1,"tv":9327.4,"id":9633869}]}]}
{"op":"mcm","clk":"4230730359","pt":1631535976248,"mc":[{"id":"1.187557995","rc":[{"batl":[[0,1.33,1006.2]],"ltp":1.31,"tv":93602.74,"id":9342449}]}]}
{"op":"mcm","clk":"4230730448","pt":1631535977637,"mc":[{"id":"1.187557995","rc":[{"batb":[[2,1.29,733.61]],"batl":[[0,1.33,639.93]],"ltp":1.31,"tv":93602.74,"id":9342449},{"trd":[[4,79.68]],"batb":[[0,4,121.23],[1,3.5,59.73],[2,3.45,146.75]],"batl":[[0,4.6,7.9],[1,4.8,8.42],[2,4.9,48.52]],"ltp":4.0,"tv":9332.3,"id":9633869}],"tv":102935.05}]}
{"op":"mcm","clk":"4230730514","pt":1631535978525,"mc":[{"id":"1.187557995","rc":[{"batb":[[0,1.27,115.47],[1,1.26,599.97],[2,1.25,995.44]],"batl":[[0,1.33,15],[1,1.39,235.95],[2,1.4,190.02]],"ltp":1.31,"tv":93602.74,"id":9342449},{"batb":[[0,4,20]],"batl":[[1,4.9,48.52],[2,5,67.37]],"ltp":4.0,"tv":9332.3,"id":9633869}]}]}
{"op":"mcm","clk":"4230730585","pt":1631535979530,"mc":[{"id":"1.187557995","rc":[{"batb":[[0,1.26,599.97],[1,1.25,995.44],[2,1.24,701.38]],"batl":[[0,1.39,235.95],[1,1.4,190.02],[2,1.41,394.72]],"ltp":1.31,"tv":93602.74,"id":9342449},{"batb":[[0,3.5,59.73],[1,3.45,146.75],[2,3.4,110.24]],"batl":[[0,4.9,48.52],[1,5,67.37],[2,5.1,60.45]],"ltp":4.0,"tv":9332.3,"id":9633869}]}]}
{"op":"mcm","clk":"4230730660","pt":1631535980620,"mc":[{"id":"1.187557995","rc":[{"batb":[[1,1.25,1387.02],[2,1.24,1231.44]],"batl":[[1,1.4,490.26],[2,1.41,654.57]],"ltp":1.31,"tv":93602.74,"id":9342449}]}]}
{"op":"mcm","clk":"4230730737","pt":1631535981607,"mc":[{"id":"1.187557995","rc":[{"batb":[[0,1.27,345.87],[1,1.26,599.97],[2,1.25,1387.02]],"ltp":1.31,"tv":93602.74,"id":9342449},{"batb":[[0,3.5,62.73],[1,3.45,148.75]],"batl":[[0,4.8,9.22],[1,4.9,48.52],[2,5,67.37]],"ltp":4.0,"tv":9332.3,"id":9633869}]}]}
{"op":"mcm","clk":"4230730763","pt":1631535981926,"mc":[{"id":"1.187557995","rc":[{"batb":[[0,1.26,599.97],[1,1.25,1387.02],[2,1.24,1231.44]],"ltp":1.31,"tv":93602.74,"id":9342449},{"batl":[[0,4.9,48.52],[1,5,67.37],[2,5.1,60.45]],"ltp":4.0,"tv":9332.3,"id":9633869}]}]}
{"op":"mcm","clk":"4230731280","pt":1631535988715,"mc":[{"id":"1.187557995","rc":[{"batb":[[0,1.27,347.87],[1,1.26,599.97],[2,1.25,1387.02]],"ltp":1.31,"tv":93602.74,"id":9342449},{"batl":[[0,4.8,8.67],[1,4.9,48.52],[2,5,67.37]],"ltp":4.0,"tv":9332.3,"id":9633869}]}]}
{"op":"mcm","clk":"4230731297","pt":1631535988927,"mc":[{"id":"1.187557995","rc":[{"batb":[[0,1.26,599.97],[1,1.25,1387.02],[2,1.24,1231.44]],"ltp":1.31,"tv":93602.74,"id":9342449},{"batl":[[0,4.9,48.52],[1,5,67.37],[2,5.1,60.45]],"ltp":4.0,"tv":9332.3,"id":9633869}]}]}
{"op":"mcm","clk":"4230731776","pt":1631535995532,"mc":[{"id":"1.187557995","rc":[{"batb":[[0,1.27,349.87],[1,1.26,599.97],[2,1.25,1387.02]],"batl":[[1,1.41,243.5],[2,1.44,237.58]],"ltp":1.31,"tv":93602.74,"id":9342449},{"batb":[[0,3.5,3],[1,3.45,74.06],[2,3.4,13.31]],"batl":[[0,4.8,8.62],[1,4.9,48.52],[2,5,67.37]],"ltp":4.0,"tv":9332.3,"id":9633869}]}]}
{"op":"mcm","clk":"4230731839","pt":1631535996262,"mc":[{"id":"1.187557995","rc":[{"batb":[[0,1.26,192.82],[1,1.25,1387.02],[2,1.24,1231.44]],"batl":[[0,1.46,245.75],[1,1.53,723.95],[2,1.82,2.89]],"ltp":1.31,"tv":93602.74,"id":9342449},{"batb":[[2,3.15,15.43]],"batl":[[0,4.9,48.52],[1,5,67.37],[2,5.1,60.45]],"ltp":4.0,"tv":9332.3,"id":9633869}]}]}
{"op":"mcm","clk":"4230731954","pt":1631535997626,"mc":[{"id":"1.187557995","rc":[{"batl":[[0,1.28,3539.74],[1,1.46,245.75],[2,1.53,723.95]],"ltp":1.31,"tv":93602.74,"id":9342449}]}]}
{"op":"mcm","clk":"4230732046","pt":1631535998622,"mc":[{"id":"1.187557995","rc":[{"batb":[[0,1.25,1387.02],[1,1.24,1231.44],[2,1.22,568.03]],"batl":[[0,1.27,187.7],[1,1.28,428.38],[2,1.38,14.49]],"ltp":1.31,"tv":93602.74,"id":9342449},{"batb":[[0,4.5,503.74],[1,4.4,412.5],[2,4.3,412.5]],"ltp":4.0,"tv":9332.3,"id":9633869}]}]}
{"op":"mcm","clk":"4230732102","pt":1631535999457,"mc":[{"id":"1.187557995","rc":[{"trd":[[1.27,124.72]],"batb":[[0,1.25,1386.69]],"batl":[[0,1.27,170.49],[2,1.29,15]],"ltp":1.27,"tv":93619.95,"id":9342449},{"trd":[[4.7,4.65]],"batb":[[0,4.5,520.88]],"ltp":4.7,"tv":9336.95,"id":9633869}],"tv":102956.91}]}
{"op":"mcm","clk":"4230732232","pt":1631536001193,"mc":[{"id":"1.187557995","rc":[{"batb":[[2,1.23,125.1]],"ltp":1.27,"tv":93619.95,"id":9342449}]}]}
{"op":"mcm","clk":"4230732355","pt":1631536002563,"mc":[{"id":"1.187557995","rc":[{"batb":[[0,1.26,94.66],[1,1.25,1654.91],[2,1.24,1296.84]],"batl":[[0,1.27,239.99],[1,1.28,509.21]],"ltp":1.27,"tv":93619.95,"id":9342449},{"batb":[[0,4.6,15],[1,4.5,520.88],[2,4.4,412.5]],"ltp":4.7,"tv":9336.95,"id":9633869}]}]}
{"op":"mcm","clk":"4230732453","pt":1631536003568,"mc":[{"id":"1.187557995","rc":[{"trd":[[1.27,134.45]],"batl":[[0,1.27,230.26],[2,1.33,186.65]],"ltp":1.27,"tv":93629.68,"id":9342449},{"trd":[[4.7,7.28]],"batb":[[1,4.5,503.74]],"ltp":4.7,"tv":9339.58,"id":9633869}],"tv":102969.27}]}
{"op":"mcm","clk":"4230732517","pt":1631536004248,"mc":[{"id":"1.187557995","rc":[{"batl":[[2,1.32,201.87]],"ltp":1.27,"tv":93629.68,"id":9342449}]}]}
{"op":"mcm","clk":"4230732582","pt":1631536005030,"mc":[{"id":"1.187557995","rc":[{"batl":[[2,1.31,302.5]],"ltp":1.27,"tv":93629.68,"id":9342449}]}]}
{"op":"mcm","clk":"4230732679","pt":1631536006457,"mc":[{"id":"1.187557995","rc":[{"batl":[[1,1.28,524.21]],"ltp":1.27,"tv":93629.68,"id":9342449},{"batb":[[0,4.6,31.66]],"ltp":4.7,"tv":9339.58,"id":9633869}]}]}
{"op":"mcm","clk":"4230732779","pt":1631536007654,"mc":[{"id":"1.187557995","rc":[{"batb":[[2,1.24,1513.19]],"ltp":1.27,"tv":93629.68,"id":9342449}]}]}
{"op":"mcm","clk":"4230732894","pt":1631536009164,"mc":[{"id":"1.187557995","rc":[{"batb":[[2,1.24,1447.79]],"batl":[[1,1.28,443.38]],"ltp":1.27,"tv":93629.68,"id":9342449}]}]}
{"op":"mcm","clk":"4230733348","pt":1631536014567,"mc":[{"id":"1.187557995","rc":[{"batb":[[0,1.25,1586.09],[1,1.24,1447.79],[2,1.23,963.44]],"batl":[[0,1.27,160.76]],"ltp":1.27,"tv":93629.68,"id":9342449}]}]}
{"op":"mcm","clk":"4230733767","pt":1631536019691,"mc":[{"id":"1.187557995","rc":[{"batb":[[0,1.25,1386.69]],"ltp":1.27,"tv":93629.68,"id":9342449},{"batb":[[1,4.5,78.74],[2,4.2,10.32]],"ltp":4.7,"tv":9339.58,"id":9633869}]}]}
{"op":"mcm","clk":"4230733816","pt":1631536020164,"mc":[{"id":"1.187557995","rc":[{"batb":[[0,1.24,216.35],[1,1.23,963.44],[2,1.22,826.43]],"batl":[[0,1.28,15],[1,1.31,302.5],[2,1.32,201.87]],"ltp":1.27,"tv":93629.68,"id":9342449},{"batb":[[0,4.6,16.66],[1,4.2,10.32],[2,4,106.94]],"batl":[[0,5.4,55.75],[1,5.5,56.11],[2,5.6,58.36]],"ltp":4.7,"tv":9339.58,"id":9633869}]}]}
{"op":"mcm","clk":"4230733938","pt":1631536021686,"mc":[{"id":"1.187557995","rc":[{"batb":[[1,1.23,838.34]],"batl":[[0,1.32,201.87],[1,1.34,438.65],[2,1.35,213.64]],"ltp":1.27,"tv":93629.68,"id":9342449},{"batb":[[0,4,106.94],[1,3.95,54.97],[2,3.9,75.08]],"ltp":4.7,"tv":9339.58,"id":9633869}]}]}
{"op":"mcm","clk":"4230734015","pt":1631536022683,"mc":[{"id":"1.187557995","rc":[{"batl":[[1,1.33,330.18],[2,1.34,770.7]],"ltp":1.27,"tv":93629.68,"id":9342449}]}]}
{"op":"mcm","clk":"4230734116","pt":1631536023885,"mc":[{"id":"1.187557995","rc":[{"batl":[[1,1.34,438.65],[2,1.35,213.64]],"ltp":1.27,"tv":93629.68,"id":9342449}]}]}
{"op":"mcm","clk":"4230734221","pt":1631536025194,"mc":[{"id":"1.187557995","rc":[{"batb":[[0,4.1,3],[1,4,108.94],[2,3.95,54.97]],"ltp":4.7,"tv":9339.58,"id":9633869}]}]}
{"op":"mcm","clk":"4230734397","pt":1631536027188,"mc":[{"id":"1.187557995","rc":[{"batb":[[0,1.26,393.5],[1,1.25,503.33],[2,1.24,216.35]],"batl":[[0,1.29,553.98],[1,1.3,386.55],[2,1.32,201.87]],"ltp":1.27,"tv":93629.68,"id":9342449}]}]}
{"op":"mcm","clk":"4230734496","pt":1631536028396,"mc":[{"id":"1.187557995","rc":[{"batb":[[1,1.25,562.24]],"batl":[[2,1.31,280.5]],"ltp":1.27,"tv":93629.68,"id":9342449},{"batb":[[0,4.2,10.12],[1,4.1,3],[2,4,108.94]],"batl":[[0,5.3,26.27],[1,5.4,55.75],[2,5.5,56.11]],"ltp":4.7,"tv":9339.58,"id":9633869}]}]}
{"op":"mcm","clk":"4230734758","pt":1631536031471,"mc":[{"id":"1.187557995","rc":[{"batb":[[0,1.27,223.1],[1,1.26,393.5],[2,1.25,562.24]],"batl":[[0,1.29,659.8]],"ltp":1.27,"tv":93629.68,"id":9342449}]}]}
{"op":"mcm","clk":"4230734815","pt":1631536032199,"mc":[{"id":"1.187557995","rc":[{"batb":[[0,1.24,216.35],[1,1.23,838.34],[2,1.22,826.43]],"batl":[[0,1.32,201.87],[1,1.34,438.65],[2,1.35,213.64]],"ltp":1.27,"tv":93629.68,"id":9342449},{"batb":[[0,4.1,3],[1,4,108.94],[2,3.95,54.97]],"batl":[[0,5.4,55.75],[1,5.5,56.11],[2,5.6,58.36]],"ltp":4.7,"tv":9339.58,"id":9633869}]}]}
{"op":"mcm","clk":"4230734994","pt":1631536034600,"mc":[{"id":"1.187557995","rc":[{"batb":[[0,4.3,44.07],[1,4.1,3],[2,4,108.94]],"ltp":4.7,"tv":9339.58,"id":9633869}]}]}
{"op":"mcm","clk":"4230735075","pt":1631536035492,"mc":[{"id":"1.187557995","rc":[{"batl":[[1,1.33,331.4],[2,1.34,770.71]],"ltp":1.27,"tv":93629.68,"id":9342449},{"batb":[[0,4.1,3],[1,4,108.94],[2,3.95,54.97]],"ltp":4.7,"tv":9339.58,"id":9633869}]}]}
{"op":"mcm","clk":"4230735315","pt":1631536038680,"mc":[{"id":"1.187557995","rc":[{"batl":[[0,1.31,369.5],[1,1.32,201.87],[2,1.33,331.4]],"ltp":1.27,"tv":93629.68,"id":9342449},{"batb":[[0,4.2,10.92],[1,4.1,3],[2,4,108.94]],"ltp":4.7,"tv":9339.58,"id":9633869}]}]}
{"op":"mcm","clk":"4230735348","pt":1631536039092,"mc":[{"id":"1.187557995","rc":[{"batl":[[0,1.32,201.87],[1,1.33,331.4],[2,1.34,770.71]],"ltp":1.27,"tv":93629.68,"id":9342449},{"batb":[[0,4.1,3],[1,4,106.94],[2,3.95,54.97]],"ltp":4.7,"tv":9339.58,"id":9633869}]}]}
{"op":"mcm","clk":"4230735636","pt":1631536042700,"mc":[{"id":"1.187557995","rc":[{"batl":[[1,1.53,723.95],[2,1.82,2.89]],"ltp":1.27,"tv":93629.68,"id":9342449},{"batb":[[1,4,109.94],[2,3.9,12.06]],"ltp":4.7,"tv":9339.58,"id":9633869}]}]}
{"op":"mcm","clk":"4230735717","pt":1631536043683,"mc":[{"id":"1.187557995","rc":[{"batb":[[0,1.23,838.34],[1,1.22,826.43],[2,1.21,1403.95]],"ltp":1.27,"tv":93629.68,"id":9342449}]}]}
{"op":"mcm","clk":"4230735787","pt":1631536044424,"mc":[{"id":"1.187557995","rc":[{"batb":[[0,1.22,826.43],[1,1.21,1403.95],[2,1.2,799.3]],"ltp":1.27,"tv":93629.68,"id":9342449},{"batl":[[0,5.4,48.41]],"ltp":4.7,"tv":9339.58,"id":9633869}]}]}
{"op":"mcm","clk":"4230735907","pt":1631536045677,"mc":[{"id":"1.187557995","rc":[{"batl":[[0,1.24,642.99],[1,1.25,468.47],[2,1.31,378.2]],"ltp":1.27,"tv":93629.68,"id":9342449},{"batb":[[0,5.2,367.78],[1,5.1,356.96],[2,5,420.06]],"batl":[[0,5.6,58.36],[1,5.8,7.37],[2,6.2,169.65]],"ltp":4.7,"tv":9339.58,"id":9633869}]}]}
{"op":"mcm","clk":"4230735971","pt":1631536046522,"mc":[{"id":"1.187557995","rc":[{"batl":[[2,1.28,190.16]],"ltp":1.27,"tv":93629.68,"id":9342449},{"trd":[[5.2,8.34]],"batb":[[0,5.2,363.61],[2,5,435.06]],"ltp":5.2,"tv":9347.92,"id":9633869}],"tv":102977.61}]}
{"op":"mcm","clk":"4230736041","pt":1631536047308,"mc":[{"id":"1.187557995","rc":[{"batl":[[2,1.31,385.2]],"ltp":1.27,"tv":93629.68,"id":9342449},{"batb":[[2,5,420.06]],"ltp":5.2,"tv":9347.92,"id":9633869}]}]}
{"op":"mcm","clk":"4230736168","pt":1631536048716,"mc":[{"id":"1.187557995","rc":[{"batl":[[0,1.24,762.99],[2,1.31,7]],"ltp":1.27,"tv":93629.68,"id":9342449}]}]}
{"op":"mcm","clk":"4230736241","pt":1631536049589,"mc":[{"id":"1.187557995","rc":[{"batb":[[0,1.23,96.97],[1,1.22,1122.01],[2,1.21,1403.95]],"batl":[[0,1.24,828.93],[1,1.25,483.47]],"ltp":1.27,"tv":93629.68,"id":9342449}]}]}
{"op":"mcm","clk":"4230736300","pt":1631536050418,"mc":[{"id":"1.187557995","rc":[{"batl":[[0,1.24,1082.89],[1,1.25,468.47]],"ltp":1.27,"tv":93629.68,"id":9342449},{"batb":[[0,5.2,378.61]],"ltp":5.2,"tv":9347.92,"id":9633869}]}]}
{"op":"mcm","clk":"4230736383","pt":1631536051522,"mc":[{"id":"1.187557995","rc":[{"batl":[[2,1.26,360.25]],"ltp":1.27,"tv":93629.68,"id":9342449}]}]}
{"op":"mcm","clk":"4230736440","pt":1631536052162,"mc":[{"id":"1.187557995","rc":[{"batl":[[2,5.9,6.77]],"ltp":5.2,"tv":9347.92,"id":9633869}]}]}
{"op":"mcm","clk":"4230736587","pt":1631536053596,"mc":[{"id":"1.187557995","rc":[{"batl":[[1,1.25,483.47]],"ltp":1.27,"tv":93629.68,"id":9342449},{"batb":[[2,5,435.06]],"ltp":5.2,"tv":9347.92,"id":9633869}]}]}
{"op":"mcm","clk":"4230736693","pt":1631536054597,"mc":[{"id":"1.187557995","rc":[{"trd":[[1.24,4.64]],"batl":[[0,1.24,1080.57]],"ltp":1.24,"tv":93634.33,"id":9342449}],"tv":102982.25}]}
{"op":"mcm","clk":"4230737048","pt":1631536059217,"mc":[{"id":"1.187557995","rc":[{"batb":[[0,1.22,1056.09],[1,1.21,1403.95],[2,1.2,1369.58]],"batl":[[0,1.24,1014.63]],"ltp":1.24,"tv":93634.33,"id":9342449}]}]}
{"op":"mcm","clk":"4230737217","pt":1631536061434,"mc":[{"id":"1.187557995","rc":[{"trd":[[1.22,884.77]],"batb":[[0,1.22,940.89]],"ltp":1.22,"tv":93864.73,"id":9342449}],"tv":103212.65}]}
{"op":"mcm","clk":"4230737272","pt":1631536062325,"mc":[{"id":"1.187557995","rc":[{"batl":[[0,1.24,1075.64]],"ltp":1.22,"tv":93864.73,"id":9342449}]}]}
{"op":"mcm","clk":"4230737464","pt":1631536064532,"mc":[{"id":"1.187557995","rc":[{"trd":[[1.24,22.5]],"batb":[[2,1.2,1344.73]],"batl":[[0,1.24,1066.71]],"ltp":1.24,"tv":93882.58,"id":9342449}],"tv":103230.51}]}
{"op":"mcm","clk":"4230737747","pt":1631536067708,"mc":[{"id":"1.187557995","rc":[{"trd":[[1.22,991.34]],"batb":[[0,1.22,887.59],[1,1.21,1428.59]],"ltp":1.22,"tv":93989.15,"id":9342449}],"tv":103337.08}]}
{"op":"mcm","clk":"4230737874","pt":1631536069019,"mc":[{"id":"1.187557995","rc":[{"trd":[[1.24,32.5]],"batl":[[0,1.24,1061.71]],"ltp":1.24,"tv":93999.15,"id":9342449}],"tv":103347.08}]}
{"op":"mcm","clk":"4230737956","pt":1631536070021,"mc":[{"id":"1.187557995","rc":[{"trd":[[5.2,8.72]],"batb":[[0,5.2,378.42]],"ltp":5.2,"tv":9348.31,"id":9633869}],"tv":103347.46}]}
{"op":"mcm","clk":"4230738081","pt":1631536071746,"mc":[{"id":"1.187557995","rc":[{"trd":[[5.2,36.4]],"batb":[[0,5.2,364.58]],"ltp":5.2,"tv":9375.99,"id":9633869}],"tv":103375.14}]}
{"op":"mcm","clk":"4230738398","pt":1631536075334,"mc":[{"id":"1.187557995","rc":[{"trd":[[5.2,40.4]],"batb":[[0,5.2,362.58]],"ltp":5.2,"tv":9379.99,"id":9633869}],"tv":103379.14}]}
{"op":"mcm","clk":"4230738980","pt":1631536082175,"mc":[{"id":"1.187557995","rc":[{"batb":[[1,1.21,729.75],[2,1.2,896.99]],"batl":[[0,1.24,434.97],[1,1.25,15]],"ltp":1.24,"tv":93999.15,"id":9342449}]}]}
{"op":"mcm","clk":"4230739450","pt":1631536087970,"mc":[{"id":"1.187557995","rc":[{"batb":[[2,1.2,460.87]],"ltp":1.24,"tv":93999.15,"id":9342449}]}]}
{"op":"mcm","clk":"4230739663","pt":1631536090470,"mc":[{"id":"1.187557995","rc":[{"trd":[[5.2,40.79]],"batb":[[0,5.2,362.39]],"ltp":5.2,"tv":9380.37,"id":9633869}],"tv":103379.52}]}
{"op":"mcm","clk":"4230739763","pt":1631536091477,"mc":[{"id":"1.187557995","rc":[{"batb":[[0,1.2,134.16],[1,1.19,247.11],[2,1.18,1333.6]],"batl":[[0,1.24,310]],"ltp":1.24,"tv":93999.15,"id":9342449},{"batb":[[0,5,15],[1,4.8,9.28],[2,4.5,147.69]],"batl":[[0,5.9,6.77],[1,6.4,40.6],[2,6.6,46]],"ltp":5.2,"tv":9380.37,"id":9633869}]}]}
{"op":"mcm","clk":"4230739848","pt":1631536092483,"mc":[{"id":"1.187557995","rc":[{"batb":[[0,1.19,247.11],[1,1.18,1333.6],[2,1.17,1576.75]],"batl":[[0,1.24,120],[1,1.27,339.81],[2,1.28,989.47]],"ltp":1.24,"tv":93999.15,"id":9342449},{"batb":[[0,4.5,147.69],[1,4.4,75.73],[2,4.3,82.44]],"batl":[[0,6.4,40.6],[1,6.6,46],[2,6.8,52.64]],"ltp":5.2,"tv":9380.37,"id":9633869}]}]}
{"op":"mcm","clk":"4230740022","pt":1631536094536,"mc":[{"id":"1.187557995","rc":[{"batb":[[1,1.18,885.29],[2,1.17,846.93]],"batl":[[1,1.28,564.58],[2,1.29,231.84]],"ltp":1.24,"tv":93999.15,"id":9342449},{"batb":[[0,4.6,75.9],[1,4.5,69.2],[2,4.4,75.73]],"ltp":5.2,"tv":9380.37,"id":9633869}]}]}
{"op":"mcm","clk":"4230740117","pt":1631536095655,"mc":[{"id":"1.187557995","rc":[{"batl":[[1,1.26,415.75],[2,1.28,564.58]],"ltp":1.24,"tv":93999.15,"id":9342449},{"batb":[[0,4.8,8.88],[1,4.6,75.9],[2,4.5,69.2]],"ltp":5.2,"tv":9380.37,"id":9633869}]}]}
{"op":"mcm","clk":"4230740149","pt":1631536095967,"mc":[{"id":"1.187557995","rc":[{"batl":[[1,1.28,564.58],[2,1.29,231.84]],"ltp":1.24,"tv":93999.15,"id":9342449},{"batb":[[0,4.6,75.9],[1,4.5,69.2],[2,4.4,75.73]],"ltp":5.2,"tv":9380.37,"id":9633869}]}]}
{"op":"mcm","clk":"4230740302","pt":1631536097664,"mc":[{"id":"1.187557995","rc":[{"batb":[[0,1.21,261.16],[1,1.2,658.84],[2,1.19,247.11]],"batl":[[0,1.23,507.09],[1,1.24,671.46],[2,1.28,564.58]],"ltp":1.24,"tv":93999.15,"id":9342449},{"batb":[[0,5.3,36.88],[1,4.6,75.9],[2,4.5,69.2]],"batl":[[0,5.6,40.96],[1,6.4,40.6],[2,6.6,46]],"ltp":5.2,"tv":9380.37,"id":9633869}]}]}
{"op":"mcm","clk":"4230740372","pt":1631536098350,"mc":[{"id":"1.187557995","rc":[{"batb":[[2,1.19,714.82]],"batl":[[1,1.24,630.98]],"ltp":1.24,"tv":93999.15,"id":9342449},{"batb":[[0,4.6,75.9],[1,4.5,69.2],[2,4.4,75.73]],"batl":[[0,6.4,46.09],[1,6.6,46],[2,6.8,52.64]],"ltp":5.2,"tv":9380.37,"id":9633869}]}]}
{"op":"mcm","clk":"4230740478","pt":1631536099351,"mc":[{"id":"1.187557995","rc":[{"batb":[[1,1.2,713.41]],"batl":[[0,1.23,563.7],[2,1.26,339.25]],"ltp":1.24,"tv":93999.15,"id":9342449},{"batb":[[0,4.8,7.88],[1,4.7,51.26],[2,4.6,75.9]],"batl":[[0,6.2,16.33],[1,6.4,46.09],[2,6.6,46]],"ltp":5.2,"tv":9380.37,"id":9633869}]}]}
{"op":"mcm","clk":"4230740516","pt":1631536099772,"mc":[{"id":"1.187557995","rc":[{"batb":[[1,4.6,75.9],[2,4.5,69.2]],"ltp":5.2,"tv":9380.37,"id":9633869}]}]}
{"op":"mcm","clk":"4230740732","pt":1631536102581,"mc":[{"id":"1.187557995","rc":[{"batb":[[0,1.19,247.11],[1,1.18,885.29],[2,1.17,846.93]],"batl":[[0,1.24,120],[1,1.28,564.58],[2,1.29,231.84]],"ltp":1.24,"tv":93999.15,"id":9342449},{"batb":[[0,4.6,75.9],[1,4.5,69.2],[2,4.4,75.73]],"batl":[[0,6.4,40.6],[1,6.6,46],[2,6.8,52.64]],"ltp":5.2,"tv":9380.37,"id":9633869}]}]}
{"op":"mcm","clk":"4230740975","pt":1631536105573,"mc":[{"id":"1.187557995","rc":[{"batb":[[0,1.19,846.82],[1,1.18,1333.6],[2,1.17,1576.75]],"batl":[[1,1.26,383.25],[2,1.27,339.81]],"ltp":1.24,"tv":93999.15,"id":9342449},{"batb":[[0,4.8,9.13],[1,4.6,75.9],[2,4.5,69.2]],"batl":[[0,6.4,46.59]],"ltp":5.2,"tv":9380.37,"id":9633869}]}]}
{"op":"mcm","clk":"4230741001","pt":1631536105991,"mc":[{"id":"1.187557995","rc":[{"batb":[[0,1.19,247.11]],"batl":[[1,1.27,339.81],[2,1.28,989.47]],"ltp":1.24,"tv":93999.15,"id":9342449},{"batb":[[0,4.6,75.9],[1,4.5,69.2],[2,4.4,75.73]],"batl":[[0,6.4,40.6]],"ltp":5.2,"tv":9380.37,"id":9633869}]}]}
{"op":"mcm","clk":"4230741101","pt":1631536107087,"mc":[{"id":"1.187557995","rc":[{"batb":[[0,1.2,197.61],[1,1.18,555.56],[2,1.17,556.97]],"ltp":1.24,"tv":93999.15,"id":9342449},{"batl":[[0,7,6.42],[1,7.4,5.24],[2,990,0.01]],"ltp":5.2,"tv":9380.37,"id":9633869}]}]}
{"op":"mcm","clk":"4230741310","pt":1631536109691,"mc":[{"id":"1.187557995","rc":[{"trd":[[1.24,152.5],[1.27,151.29]],"batb":[[0,1.25,2],[1,1.24,1895.16],[2,1.23,947.58]],"batl":[[0,1.27,322.97],[1,1.28,989.47],[2,1.29,231.84]],"ltp":1.27,"tv":94135.99,"id":9342449},{"trd":[[4.7,11.83],[5.1,29.18]],"batl":[[0,5,1463.88],[1,5.3,763.11],[2,7,6.42]],"ltp":4.7,"tv":9414.1,"id":9633869}],"tv":103550.09}]}
{"op":"mcm","clk":"4230741382","pt":1631536110596,"mc":[{"id":"1.187557995","rc":[{"batb":[[0,1.25,230.62],[1,1.24,2057.97],[2,1.23,568.55]],"batl":[[1,1.28,2825.41],[2,1.29,1149.82]],"ltp":1.27,"tv":94135.99,"id":9342449},{"batl":[[0,5,2],[1,5.3,460.61]],"ltp":4.7,"tv":9414.1,"id":9633869}]}]}
{"op":"mcm","clk":"4230741515","pt":1631536111688,"mc":[{"id":"1.187557995","rc":[{"batb":[[1,1.24,1299.91],[2,1.23,189.52]],"batl":[[1,1.28,1218.96],[2,1.29,346.59]],"ltp":1.27,"tv":94135.99,"id":9342449},{"batb":[[0,4.7,11.57],[1,4.6,92.56],[2,4.5,69.2]],"batl":[[2,5.4,7.15]],"ltp":4.7,"tv":9414.1,"id":9633869}]}]}
{"op":"mcm","clk":"4230741641","pt":1631536113195,"mc":[{"id":"1.187557995","rc":[{"batl":[[0,1.27,474.98],[2,1.29,361.59]],"ltp":1.27,"tv":94135.99,"id":9342449}]}]}
{"op":"mcm","clk":"4230741755","pt":1631536114583,"mc":[{"id":"1.187557995","rc":[{"batb":[[0,1.26,94.66],[1,1.25,513.88],[2,1.24,1299.91]],"batl":[[0,1.27,537.72]],"ltp":1.27,"tv":94135.99,"id":9342449}]}]}
{"op":"mcm","clk":"4230741805","pt":1631536115097,"mc":[{"id":"1.187557995","rc":[{"batl":[[2,5.9,32.1]],"ltp":4.7,"tv":9414.1,"id":9633869}]}]}
{"op":"mcm","clk":"4230742031","pt":1631536117607,"mc":[{"id":"1.187557995","rc":[{"batl":[[2,1.29,764.09]],"ltp":1.27,"tv":94135.99,"id":9342449},{"batl":[[2,5.4,7.49]],"ltp":4.7,"tv":9414.1,"id":9633869}]}]}
{"op":"mcm","clk":"4230742091","pt":1631536118290,"mc":[{"id":"1.187557995","rc":[{"batl":[[1,5.2,7.31],[2,5.3,460.61]],"ltp":4.7,"tv":9414.1,"id":9633869}]}]}
{"op":"mcm","clk":"4230742622","pt":1631536124688,"mc":[{"id":"1.187557995","rc":[{"batb":[[0,1.23,502.73],[1,1.22,248.13],[2,1.21,1177.37]],"batl":[[0,1.27,110],[1,1.29,15],[2,1.3,227.43]],"ltp":1.27,"tv":94135.99,"id":9342449},{"batb":[[0,4.6,16.66],[1,4.3,90.12],[2,4.2,12.57]],"batl":[[0,5.2,7.31],[1,5.4,7.49],[2,5.5,49.47]],"ltp":4.7,"tv":9414.1,"id":9633869}]}]}
{"op":"mcm","clk":"4230742662","pt":1631536125419,"mc":[{"id":"1.187557995","rc":[{"batb":[[0,1.22,248.13],[1,1.21,1177.37],[2,1.2,831.7]],"batl":[[0,1.3,227.43],[1,1.31,359.5],[2,1.32,170.62]],"ltp":1.27,"tv":94135.99,"id":9342449},{"batb":[[0,4.3,90.12],[1,4.2,12.57],[2,4.1,68.71]],"batl":[[0,5.5,49.47],[1,5.6,48.63],[2,5.7,63.72]],"ltp":4.7,"tv":9414.1,"id":9633869}]}]}
{"op":"mcm","clk":"4230742829","pt":1631536127718,"mc":[{"id":"1.187557995","rc":[{"batb":[[1,1.21,1696.91],[2,1.2,1460.24]],"batl":[[0,1.29,351.5],[1,1.3,227.43],[2,1.31,861.83]],"ltp":1.27,"tv":94135.99,"id":9342449}]}]}
{"op":"mcm","clk":"4230742894","pt":1631536128707,"mc":[{"id":"1.187557995","rc":[{"batb":[[0,1.28,108.48],[1,1.22,248.13],[2,1.21,1696.91]],"batl":[[0,1.3,237.43],[1,1.31,861.83],[2,1.32,526.75]],"ltp":1.27,"tv":94135.99,"id":9342449},{"batb":[[0,4.3,92.12]],"ltp":4.7,"tv":9414.1,"id":9633869}]}]}
{"op":"mcm","clk":"4230742931","pt":1631536129112,"mc":[{"id":"1.187557995","rc":[{"batb":[[2,1.21,1177.37]],"batl":[[1,1.31,359.5],[2,1.32,170.62]],"ltp":1.27,"tv":94135.99,"id":9342449}]}]}
{"op":"mcm","clk":"4230743024","pt":1631536130225,"mc":[{"id":"1.187557995","rc":[{"batb":[[1,1.23,216.35],[2,1.22,248.13]],"ltp":1.27,"tv":94135.99,"id":9342449}]}]}
{"op":"mcm","clk":"4230743121","pt":1631536131692,"mc":[{"id":"1.187557995","rc":[{"batb":[[1,1.23,650.98]],"batl":[[0,1.29,975.64],[1,1.3,237.43],[2,1.31,359.5]],"ltp":1.27,"tv":94135.99,"id":9342449},{"batb":[[0,4.4,9.96],[1,4.3,92.12],[2,4.2,12.57]],"batl":[[0,5.4,7.39],[1,5.5,49.47],[2,5.6,48.63]],"ltp":4.7,"tv":9414.1,"id":9633869}]}]}
{"op":"mcm","clk":"4230743175","pt":1631536132332,"mc":[{"id":"1.187557995","rc":[{"trd":[[1.28,3302.22]],"batb":[[0,1.24,383.13],[1,1.23,773.83]],"batl":[[0,1.26,222.87],[1,1.27,446.46],[2,1.3,237.43]],"ltp":1.28,"tv":94279.95,"id":9342449},{"trd":[[4.6,29.62]],"batb":[[0,4.3,92.12],[1,4.2,12.57],[2,4.1,68.71]],"batl":[[0,5.5,49.47],[1,5.6,48.63],[2,5.7,63.72]],"ltp":4.6,"tv":9434.42,"id":9633869}],"tv":103714.38}]}
{"op":"mcm","clk":"4230743293","pt":1631536133896,"mc":[{"id":"1.187557995","rc":[{"batl":[[2,1.29,123.51]],"ltp":1.28,"tv":94279.95,"id":9342449},{"batb":[[0,4.4,39.62],[1,4.3,92.12],[2,4.2,12.57]],"batl":[[0,5.4,15.14],[1,5.5,49.47],[2,5.6,48.63]],"ltp":4.6,"tv":9434.42,"id":9633869}]}]}
{"op":"mcm","clk":"4230743439","pt":1631536135647,"mc":[{"id":"1.187557995","rc":[{"batb":[[0,1.23,621.98],[1,1.22,248.13],[2,1.21,1177.37]],"batl":[[0,1.29,340.5],[1,1.3,237.43],[2,1.31,359.5]],"ltp":1.28,"tv":94279.95,"id":9342449},{"batb":[[0,4.4,8.51]],"batl":[[0,5.4,7.19]],"ltp":4.6,"tv":9434.42,"id":9633869}]}]}
{"op":"mcm","clk":"4230743460","pt":1631536135926,"mc":[{"id":"1.187557995","rc":[{"batb":[[0,1.23,216.35]],"batl":[[0,1.3,237.43],[1,1.31,359.5],[2,1.32,170.62]],"ltp":1.28,"tv":94279.95,"id":9342449},{"batb":[[0,4.3,92.12],[1,4.2,12.57],[2,4.1,68.71]],"batl":[[0,5.5,49.47],[1,5.6,48.63],[2,5.7,63.72]],"ltp":4.6,"tv":9434.42,"id":9633869}]}]}
{"op":"mcm","clk":"4230743759","pt":1631536139717,"mc":[{"id":"1.187557995","rc":[{"batb":[[2,1.21,1716.47]],"batl":[[1,1.31,845.31],[2,1.32,526.73]],"ltp":1.28,"tv":94279.95,"id":9342449}]}]}
{"op":"mcm","clk":"4230743875","pt":1631536141135,"mc":[{"id":"1.187557995","rc":[{"batl":[[1,1.53,723.95],[2,1.82,2.89]],"ltp":1.28,"tv":94279.95,"id":9342449},{"batb":[[1,4.2,9.57],[2,1.97,1.05]],"ltp":4.6,"tv":9434.42,"id":9633869}]}]}
{"op":"mcm","clk":"4230743985","pt":1631536142509,"mc":[{"id":"1.187557995","rc":[{"batb":[[0,1.22,248.13],[1,1.21,1299.95],[2,1.2,1440.51]],"batl":[[0,1.3,10]],"ltp":1.28,"tv":94279.95,"id":9342449}]}]}
{"op":"mcm","clk":"4230744071","pt":1631536143705,"mc":[{"id":"1.187557995","rc":[{"batb":[[0,1.21,1299.95],[1,1.2,1440.51],[2,1.17,556.97]],"batl":[[0,1.23,246.75],[1,1.24,516.3],[2,1.3,10]],"ltp":1.28,"tv":94279.95,"id":9342449},{"batb":[[0,5.2,735.58],[1,5.1,713.94],[2,5,713.94]],"batl":[[0,5.6,48.63],[1,5.7,63.72],[2,5.8,8.02]],"ltp":4.6,"tv":9434.42,"id":9633869}]}]}
{"op":"mcm","clk":"4230744144","pt":1631536144645,"mc":[{"id":"1.187557995","rc":[{"trd":[[1.23,17.58]],"batl":[[0,1.23,229.17]],"ltp":1.23,"tv":94297.53,"id":9342449},{"trd":[[5.3,12.42]],"batb":[[0,5.2,424.01],[1,5.1,356.96],[2,5,356.96]],"ltp":5.3,"tv":9438.5,"id":9633869}],"tv":103736.04}]}
{"op":"mcm","clk":"4230744212","pt":1631536145428,"mc":[{"id":"1.187557995","rc":[{"batl":[[2,1.26,15]],"ltp":1.23,"tv":94297.53,"id":9342449}]}]}
{"op":"mcm","clk":"4230744273","pt":1631536146221,"mc":[{"id":"1.187557995","rc":[{"batb":[[1,1.2,1574.67]],"ltp":1.23,"tv":94297.53,"id":9342449}]}]}
{"op":"mcm","clk":"4230744473","pt":1631536148636,"mc":[{"id":"1.187557995","rc":[{"batb":[[0,1.22,97.76],[1,1.21,1572.38],[2,1.2,1635.66]],"batl":[[0,1.23,495.23],[1,1.24,596.31],[2,1.27,103.92]],"ltp":1.23,"tv":94297.53,"id":9342449},{"batb":[[0,5.3,54.35],[1,5.2,424.01],[2,5.1,356.96]],"ltp":5.3,"tv":9438.5,"id":9633869}]}]}
{"op":"mcm","clk":"4230744506","pt":1631536148949,"mc":[{"id":"1.187557995","rc":[{"batl":[[0,1.23,341.43]],"ltp":1.23,"tv":94297.53,"id":9342449},{"batb":[[0,5.3,11.72]],"ltp":5.3,"tv":9438.5,"id":9633869}]}]}
{"op":"mcm","clk":"4230744728","pt":1631536151460,"mc":[{"id":"1.187557995","rc":[{"batl":[[2,1.25,15]],"ltp":1.23,"tv":94297.53,"id":9342449}]}]}
{"op":"mcm","clk":"4230744806","pt":1631536152241,"mc":[{"id":"1.187557995","rc":[{"batl":[[0,1.23,544.43]],"ltp":1.23,"tv":94297.53,"id":9342449}]}]}
{"op":"mcm","clk":"4230744901","pt":1631536153451,"mc":[{"id":"1.187557995","rc":[{"batb":[[2,1.2,1574.67]],"batl":[[1,1.24,516.3]],"ltp":1.23,"tv":94297.53,"id":9342449}]}]}
{"op":"mcm","clk":"4230745046","pt":1631536155502,"mc":[{"id":"1.187557995","rc":[{"batb":[[1,1.21,1645.48]],"batl":[[0,1.23,604.4]],"ltp":1.23,"tv":94297.53,"id":9342449}]}]}
{"op":"mcm","clk":"4230745073","pt":1631536155834,"mc":[{"id":"1.187557995","rc":[{"batl":[[0,1.23,544.43]],"ltp":1.23,"tv":94297.53,"id":9342449}]}]}
{"op":"mcm","clk":"4230745226","pt":1631536157415,"mc":[{"id":"1.187557995","rc":[{"trd":[[1.23,19.58]],"batl":[[0,1.23,543.43]],"ltp":1.23,"tv":94299.53,"id":9342449}],"tv":103738.04}]}
{"op":"mcm","clk":"4230745265","pt":1631536157835,"mc":[{"id":"1.187557995","rc":[{"batb":[[0,1.21,1515.61],[1,1.2,1574.67],[2,1.19,398.64]],"batl":[[0,1.23,472.68]],"ltp":1.23,"tv":94299.53,"id":9342449}]}]}
{"op":"mcm","clk":"4230745567","pt":1631536161446,"mc":[{"id":"1.187557995","rc":[{"batb":[[0,1.2,134.16],[1,1.19,398.64],[2,1.17,556.97]],"batl":[[0,1.23,203],[1,1.25,15],[2,1.26,379.25]],"ltp":1.23,"tv":94299.53,"id":9342449},{"batb":[[0,5,15],[1,4.8,8.88],[2,4.6,73.56]],"batl":[[0,5.9,6.77],[1,7,6.42],[2,7.4,5.24]],"ltp":5.3,"tv":9438.5,"id":9633869}]}]}
{"op":"mcm","clk":"4230745667","pt":1631536162652,"mc":[{"id":"1.187557995","rc":[{"trd":[[1.23,24.22]],"batb":[[0,1.19,398.64],[1,1.17,556.97],[2,1.16,1287.78]],"batl":[[0,1.27,103.92],[1,1.28,362.59],[2,1.53,723.95]],"ltp":1.23,"tv":94304.18,"id":9342449},{"batb":[[0,4.6,73.56],[1,4.5,9.3],[2,4.4,3]],"batl":[[0,7,6.42],[1,7.4,5.24],[2,8.2,4.23]],"ltp":5.3,"tv":9438.5,"id":9633869}],"tv":103742.68}]}
{"op":"mcm","clk":"4230745797","pt":1631536164514,"mc":[{"id":"1.187557995","rc":[{"batb":[[1,1.17,1246.26],[2,1.16,1784.7]],"batl":[[0,1.27,330.33],[1,1.28,788.74]],"ltp":1.23,"tv":94304.18,"id":9342449}]}]}
{"op":"mcm","clk":"4230745925","pt":1631536166144,"mc":[{"id":"1.187557995","rc":[{"batl":[[0,1.27,341.33]],"ltp":1.23,"tv":94304.18,"id":9342449},{"batb":[[0,4.7,2],[1,4.6,76.56],[2,4.5,9.3]],"ltp":5.3,"tv":9438.5,"id":9633869}]}]}
{"op":"mcm","clk":"4230746096","pt":1631536168733,"mc":[{"id":"1.187557995","rc":[{"batb":[[1,1.18,236.8],[2,1.17,1246.26]],"ltp":1.23,"tv":94304.18,"id":9342449}]}]}
{"op":"mcm","clk":"4230746197","pt":1631536170249,"mc":[{"id":"1.187557995","rc":[{"batl":[[0,1.26,373.75],[1,1.27,341.33],[2,1.28,788.74]],"ltp":1.23,"tv":94304.18,"id":9342449}]}]}
{"op":"mcm","clk":"4230746243","pt":1631536170872,"mc":[{"id":"1.187557995","rc":[{"batb":[[0,1.18,236.8],[1,1.17,1246.26],[2,1.16,1784.7]],"batl":[[0,1.27,341.33],[1,1.28,788.74],[2,1.53,723.95]],"ltp":1.23,"tv":94304.18,"id":9342449}]}]}
{"op":"mcm","clk":"4230746381","pt":1631536172664,"mc":[{"id":"1.187557995","rc":[{"batb":[[0,1.18,416.52]],"ltp":1.23,"tv":94304.18,"id":9342449}]}]}
{"op":"mcm","clk":"4230746442","pt":1631536173448,"mc":[{"id":"1.187557995","rc":[{"batb":[[0,4.8,7.63],[1,4.7,2],[2,4.6,76.56]],"ltp":5.3,"tv":9438.5,"id":9633869}]}]}
{"op":"mcm","clk":"4230746528","pt":1631536174443,"mc":[{"id":"1.187557995","rc":[{"batb":[[0,4.7,2],[1,4.6,76.56],[2,4.5,9.3]],"ltp":5.3,"tv":9438.5,"id":9633869}]}]}
{"op":"mcm","clk":"4230746759","pt":1631536177638,"mc":[{"id":"1.187557995","rc":[{"batl":[[0,1.26,378.25],[1,1.27,341.33],[2,1.28,788.74]],"ltp":1.23,"tv":94304.18,"id":9342449},{"batb":[[0,4.8,8.08],[1,4.7,2],[2,4.6,76.56]],"ltp":5.3,"tv":9438.5,"id":9633869}]}]}
{"op":"mcm","clk":"4230746804","pt":1631536178265,"mc":[{"id":"1.187557995","rc":[{"batl":[[0,1.27,114.92],[1,1.28,353.59],[2,1.53,723.95]],"ltp":1.23,"tv":94304.18,"id":9342449},{"batb":[[0,4.7,2],[1,4.6,73.56],[2,4.5,9.3]],"ltp":5.3,"tv":9438.5,"id":9633869}]}]}
{"op":"mcm","clk":"4230746973","pt":1631536180269,"mc":[{"id":"1.187557995","rc":[{"batb":[[0,1.17,1246.26],[1,1.16,1784.7],[2,1.14,689.82]],"batl":[[0,1.27,11]],"ltp":1.23,"tv":94304.18,"id":9342449}]}]}
{"op":"mcm","clk":"4230747064","pt":1631536181266,"mc":[{"id":"1.187557995","rc":[{"batl":[[0,1.19,403.74],[1,1.2,639.42],[2,1.27,11]],"ltp":1.23,"tv":94304.18,"id":9342449},{"batb":[[0,6,318.74],[1,5.9,309.38],[2,5.8,309.38]],"batl":[[2,7.6,138.4]],"ltp":5.3,"tv":9438.5,"id":9633869}]}]}
{"op":"mcm","clk":"4230747197","pt":1631536182642,"mc":[{"id":"1.187557995","rc":[{"batb":[[1,1.16,1934.7]],"batl":[[2,1.22,15]],"ltp":1.23,"tv":94304.18,"id":9342449},{"trd":[[6.2,18.12]],"batb":[[0,6.2,73.58],[1,6,318.74],[2,5.9,309.38]],"batl":[[0,7,12.54]],"ltp":6.2,"tv":9445.64,"id":9633869}],"tv":103749.82}]}
{"op":"mcm","clk":"4230747348","pt":1631536184559,"mc":[{"id":"1.187557995","rc":[{"batl":[[2,1.26,10]],"ltp":1.23,"tv":94304.18,"id":9342449}]}]}
{"op":"mcm","clk":"4230747434","pt":1631536185666,"mc":[{"id":"1.187557995","rc":[{"batb":[[0,1.18,101.07],[1,1.17,1556.51],[2,1.16,1934.7]],"batl":[[0,1.19,681.5],[1,1.2,705.95]],"ltp":1.23,"tv":94304.18,"id":9342449},{"batb":[[0,6.2,86.11]],"batl":[[0,7,21.24]],"ltp":6.2,"tv":9445.64,"id":9633869}]}]}
{"op":"mcm","clk":"4230747505","pt":1631536186473,"mc":[{"id":"1.187557995","rc":[{"batb":[[2,1.16,2012.53]],"batl":[[0,1.19,632.24]],"ltp":1.23,"tv":94304.18,"id":9342449}]}]}
{"op":"mcm","clk":"4230747615","pt":1631536187676,"mc":[{"id":"1.187557995","rc":[{"batl":[[2,1.22,179.73]],"ltp":1.23,"tv":94304.18,"id":9342449}]}]}
{"op":"mcm","clk":"4230747660","pt":1631536188251,"mc":[{"id":"1.187557995","rc":[{"batl":[[2,1.21,15]],"ltp":1.23,"tv":94304.18,"id":9342449}]}]}
{"op":"mcm","clk":"4230747854","pt":1631536190955,"mc":[{"id":"1.187557995","rc":[{"batb":[[2,1.16,1934.7]],"batl":[[1,1.2,639.42]],"ltp":1.23,"tv":94304.18,"id":9342449}]}]}
{"op":"mcm","clk":"4230747958","pt":1631536192176,"mc":[{"id":"1.187557995","rc":[{"trd":[[6.2,26.44]],"batb":[[0,6.2,81.95]],"ltp":6.2,"tv":9453.96,"id":9633869}],"tv":103758.14}]}
{"op":"mcm","clk":"4230748138","pt":1631536194490,"mc":[{"id":"1.187557995","rc":[{"trd":[[1.19,59.28]],"batl":[[0,1.19,612.24]],"ltp":1.19,"tv":94344.18,"id":9342449}],"tv":103798.14}]}
