{"op":"mcm","clk":"4233467748","pt":1631535192808,"mc":[{"id":"1.187557653","rc":[{"trd":[[1.83,65.85]],"ltp":1.83,"tv":1600.47,"id":9632596},{"trd":[[2.2,37.71]],"batl":[[0,2.2,6.29]],"ltp":2.2,"tv":1932.21,"id":9433864}],"tv":3532.69}]}
{"op":"mcm","clk":"4233468663","pt":1631535202916,"mc":[{"id":"1.187557653","rc":[{"batl":[[0,1.9,28.53],[1,2.18,4.59],[2,990,0.01]],"ltp":1.83,"tv":1600.47,"id":9632596},{"batl":[[0,2.72,264.63],[1,990,0.01],[2,990,0]],"ltp":2.2,"tv":1932.21,"id":9433864}]}]}
{"op":"mcm","clk":"4233468841","pt":1631535205015,"mc":[{"id":"1.187557653","rc":[{"batl":[[0,2.18,4.59],[1,990,0.01],[2,990,0]],"ltp":1.83,"tv":1600.47,"id":9632596}]}]}
{"op":"mcm","clk":"4233468931","pt":1631535206121,"mc":[{"id":"1.187557653","rc":[{"batb":[[0,2.16,6.84],[1,2.1,14.28],[2,2.08,87.02]],"batl":[[0,2.2,6.29],[1,2.46,32.18],[2,2.72,264.63]],"ltp":2.2,"tv":1932.21,"id":9433864}]}]}
{"op":"mcm","clk":"4233468945","pt":1631535206328,"mc":[{"id":"1.187557653","rc":[{"batl":[[1,2.72,264.63],[2,990,0.01]],"ltp":2.2,"tv":1932.21,"id":9433864}]}]}
{"op":"mcm","clk":"4233469132","pt":1631535208231,"mc":[{"id":"1.187557653","rc":[{"batl":[[0,2.14,859],[1,2.18,4.59],[2,990,0.01]],"ltp":1.83,"tv":1600.47,"id":9632596}]}]}
{"op":"mcm","clk":"4233469598","pt":1631535213120,"mc":[{"id":"1.187557653","rc":[{"batb":[[0,1.79,33.39],[1,1.71,39.33],[2,1.01,113.7]],"batl":[[0,990,0.01],[1,2.18,0],[2,990,0]],"ltp":1.83,"tv":1600.47,"id":9632596},{"batb":[[0,2.04,41.84],[1,1.97,47.03],[2,1.74,379.61]],"batl":[[0,2.72,264.63],[1,990,0.01],[2,990,0]],"ltp":2.2,"tv":1932.21,"id":9433864}]}]}
{"op":"mcm","clk":"4233469622","pt":1631535213344,"mc":[{"id":"1.187557653","rc":[{"batb":[[0,1.71,39.33],[1,1.01,113.7],[2,1.01,0]],"ltp":1.83,"tv":1600.47,"id":9632596},{"batb":[[0,1.97,47.03],[1,1.74,379.61],[2,1.19,1]],"ltp":2.2,"tv":1932.21,"id":9433864}]}]}
{"op":"mcm","clk":"4233470165","pt":1631535218863,"mc":[{"id":"1.187557653","rc":[{"batb":[[0,1.86,48.4],[1,1.85,24.19],[2,1.84,24.19]],"batl":[[0,1.92,8.05],[1,1.96,27.66],[2,1.98,73.8]],"ltp":1.83,"tv":1600.47,"id":9632596},{"trd":[[1.97,10.16]],"batb":[[0,1.97,41.95]],"batl":[[0,2.16,73.86],[1,2.24,277.98],[2,2.72,264.63]],"ltp":1.97,"tv":1942.37,"id":9433864}],"tv":3542.85}]}
{"op":"mcm","clk":"4233470278","pt":1631535219857,"mc":[{"id":"1.187557653","rc":[{"batb":[[0,1.86,46.01],[1,1.85,8.06],[2,1.84,8.06]],"batl":[[1,1.96,42.96],[2,1.97,7.66]],"ltp":1.83,"tv":1600.47,"id":9632596},{"batb":[[1,1.84,29.04],[2,1.74,379.61]],"ltp":1.97,"tv":1942.37,"id":9433864}]}]}
{"op":"mcm","clk":"4233471083","pt":1631535227849,"mc":[{"id":"1.187557653","rc":[{"batb":[[0,1.96,47.11]],"ltp":1.97,"tv":1942.37,"id":9433864}]}]}
{"op":"mcm","clk":"4233472283","pt":1631535239995,"mc":[{"id":"1.187557653","rc":[{"trd":[[1.92,12.51]],"batl":[[0,1.92,1.6]],"ltp":1.92,"tv":1606.92,"id":9632596},{"trd":[[2.08,21.44]],"ltp":2.08,"tv":1948.32,"id":9433864}],"tv":3555.25}]}
{"op":"mcm","clk":"4233473387","pt":1631535250300,"mc":[{"id":"1.187557653","rc":[{"batl":[[0,1.96,42.96],[1,1.97,7.66],[2,1.98,81.46]],"ltp":1.92,"tv":1606.92,"id":9632596},{"batl":[[0,2.16,55.56]],"ltp":2.08,"tv":1948.32,"id":9433864}]}]}
{"op":"mcm","clk":"4233473700","pt":1631535253195,"mc":[{"id":"1.187557653","rc":[{"batl":[[0,1.94,10.93],[1,1.96,42.96],[2,1.97,7.66]],"ltp":1.92,"tv":1606.92,"id":9632596},{"batl":[[0,2.12,10.48],[1,2.16,55.56],[2,2.24,277.98]],"ltp":2.08,"tv":1948.32,"id":9433864}]}]}
{"op":"mcm","clk":"4233477441","pt":1631535290079,"mc":[{"id":"1.187557653","rc":[{"trd":[[1.94,235.6]],"batl":[[0,1.94,9.12]],"ltp":1.94,"tv":1608.73,"id":9632596},{"trd":[[2.06,48.47]],"ltp":2.06,"tv":1950.03,"id":9433864}],"tv":3558.76}]}
{"op":"mcm","clk":"4233478462","pt":1631535300306,"mc":[{"id":"1.187557653","rc":[{"batl":[[0,1.96,42.96],[1,1.97,7.66],[2,1.98,81.46]],"ltp":1.94,"tv":1608.73,"id":9632596},{"batl":[[0,2.16,55.56],[1,2.24,277.98],[2,2.72,264.63]],"ltp":2.06,"tv":1950.03,"id":9433864}]}]}
{"op":"mcm","clk":"4233478772","pt":1631535303173,"mc":[{"id":"1.187557653","rc":[{"batl":[[0,1.94,9.12],[1,1.96,42.96],[2,1.97,7.66]],"ltp":1.94,"tv":1608.73,"id":9632596},{"batl":[[0,2.12,12.13],[1,2.16,55.56],[2,2.24,277.98]],"ltp":2.06,"tv":1950.03,"id":9433864}]}]}
{"op":"mcm","clk":"4233479066","pt":1631535305820,"mc":[{"id":"1.187557653","rc":[{"batl":[[1,1.96,15.3]],"ltp":1.94,"tv":1608.73,"id":9632596}]}]}
{"op":"mcm","clk":"4233480458","pt":1631535318935,"mc":[{"id":"1.187557653","rc":[{"batb":[[0,1.76,35.48],[1,1.01,113.7],[2,1.84,0]],"batl":[[0,990,0.01],[1,1.96,0],[2,1.97,0]],"ltp":1.94,"tv":1608.73,"id":9632596},{"batb":[[0,1.84,29.04],[1,1.74,379.61],[2,1.19,1]],"batl":[[0,2.72,264.63],[1,990,0.01],[2,2.24,0]],"ltp":2.06,"tv":1950.03,"id":9433864}]}]}
{"op":"mcm","clk":"4233480946","pt":1631535324237,"mc":[{"id":"1.187557653","rc":[{"batb":[[1,1.19,1],[2,1.01,113.7]],"batl":[[0,990,0.01],[1,990,0]],"ltp":2.06,"tv":1950.03,"id":9433864}]}]}
{"op":"mcm","clk":"4233481162","pt":1631535326046,"mc":[{"id":"1.187557653","rc":[{"trd":[[2.16,4.63]],"batb":[[0,2,66.05],[1,1.85,29.31],[2,1.76,35.48]],"batl":[[0,2.12,18.03],[1,2.16,88.23],[2,990,0.01]],"ltp":2.16,"tv":1613.36,"id":9632596},{"trd":[[1.85,23.86]],"batb":[[0,1.91,28.39],[1,1.84,29.04],[2,1.19,1]],"batl":[[0,1.96,113.85],[1,1.99,15.08],[2,2,73.59]],"ltp":1.85,"tv":1955.44,"id":9433864}],"tv":3568.8}]}
{"op":"mcm","clk":"4233481272","pt":1631535327141,"mc":[{"id":"1.187557653","rc":[{"batb":[[1,1.99,48.2],[2,1.87,29.04]],"batl":[[0,2.12,32.19],[1,2.14,7.08],[2,2.16,95.31]],"ltp":2.16,"tv":1613.36,"id":9632596},{"batb":[[2,1.72,36.4]],"ltp":1.85,"tv":1955.44,"id":9433864}]}]}
{"op":"mcm","clk":"4233481640","pt":1631535331054,"mc":[{"id":"1.187557653","rc":[{"trd":[[2.04,28.29]],"ltp":2.04,"tv":1622.32,"id":9632596},{"trd":[[1.96,14.82]],"batl":[[0,1.96,104.52]],"ltp":1.96,"tv":1964.77,"id":9433864}],"tv":3587.09}]}
{"op":"mcm","clk":"4233482217","pt":1631535336769,"mc":[{"id":"1.187557653","rc":[{"batb":[[0,1.87,29.04],[1,1.01,113.7],[2,1.87,0]],"batl":[[0,990,0.01],[1,2.14,0],[2,2.16,0]],"ltp":2.04,"tv":1622.32,"id":9632596},{"batb":[[0,1.72,36.4],[1,1.58,388.69],[2,1.19,1]],"batl":[[0,2.5,299.95],[1,990,0.01],[2,2,0]],"ltp":1.96,"tv":1964.77,"id":9433864}]}]}
{"op":"mcm","clk":"4233485552","pt":1631535374223,"mc":[{"id":"1.187557653","rc":[{"batb":[[1,1.19,1],[2,1.01,113.7]],"ltp":1.96,"tv":1964.77,"id":9433864}]}]}
{"op":"mcm","clk":"4233485799","pt":1631535376241,"mc":[{"id":"1.187557653","rc":[{"batb":[[0,1.92,9.26],[1,1.87,29.04],[2,1.76,35.31]],"batl":[[0,1.96,9.26],[1,1.97,27.52],[2,2.02,102.69]],"ltp":2.04,"tv":1622.32,"id":9632596},{"batb":[[0,2,15],[1,1.99,7.5],[2,1.98,7.5]],"batl":[[0,2.12,92.08],[1,2.5,299.95],[2,990,0.01]],"ltp":1.96,"tv":1964.77,"id":9433864}]}]}
{"op":"mcm","clk":"4233485843","pt":1631535376611,"mc":[{"id":"1.187557653","rc":[{"trd":[[1.96,5.34]],"batl":[[0,1.96,3.92]],"ltp":1.96,"tv":1627.66,"id":9632596},{"trd":[[2.04,66.1]],"batl":[[0,2.12,106.24],[1,2.14,7.08],[2,2.16,7.08]],"ltp":2.04,"tv":1969.9,"id":9433864}],"tv":3597.56}]}
{"op":"mcm","clk":"4233486191","pt":1631535380528,"mc":[{"id":"1.187557653","rc":[{"trd":[[1.92,29.41]],"batb":[[0,1.87,29.85],[1,1.76,35.31],[2,1.75,30.99]],"ltp":1.92,"tv":1644.56,"id":9632596}],"tv":3614.46}]}
{"op":"mcm","clk":"4233486788","pt":1631535386550,"mc":[{"id":"1.187557653","rc":[{"batb":[[0,1.87,29.04]],"batl":[[0,1.97,27.52],[1,2.02,102.69],[2,2.24,4.46]],"ltp":1.92,"tv":1644.56,"id":9632596}]}]}
{"op":"mcm","clk":"4233487054","pt":1631535389432,"mc":[{"id":"1.187557653","rc":[{"batl":[[0,1.96,12.21],[1,1.97,27.52],[2,2.02,102.69]],"ltp":1.92,"tv":1644.56,"id":9632596},{"batl":[[0,2.12,123.85]],"ltp":2.04,"tv":1969.9,"id":9433864}]}]}
{"op":"mcm","clk":"4233487160","pt":1631535390531,"mc":[{"id":"1.187557653","rc":[{"batl":[[0,1.97,27.52],[1,2.02,102.69],[2,2.24,4.46]],"ltp":1.92,"tv":1644.56,"id":9632596},{"batl":[[0,2.12,106.24]],"ltp":2.04,"tv":1969.9,"id":9433864}]}]}
{"op":"mcm","clk":"4233487442","pt":1631535393456,"mc":[{"id":"1.187557653","rc":[{"batl":[[0,1.96,12.21],[1,1.97,27.52],[2,2.02,102.69]],"ltp":1.92,"tv":1644.56,"id":9632596},{"batl":[[0,2.12,123.85]],"ltp":2.04,"tv":1969.9,"id":9433864}]}]}
{"op":"mcm","clk":"4233488973","pt":1631535410075,"mc":[{"id":"1.187557653","rc":[{"batb":[[0,1.76,35.31],[1,1.01,113.7],[2,1.75,0]],"batl":[[0,990,0.01],[1,1.97,0],[2,2.02,0]],"ltp":1.92,"tv":1644.56,"id":9632596},{"batb":[[0,1.8,30.96],[1,1.62,388.38],[2,1.19,1]],"batl":[[0,2.5,299.95],[1,990,0.01],[2,2.16,0]],"ltp":2.04,"tv":1969.9,"id":9433864}]}]}
{"op":"mcm","clk":"4233490747","pt":1631535428345,"mc":[{"id":"1.187557653","rc":[{"batb":[[1,1.19,1],[2,1.01,113.7]],"batl":[[0,990,0.01],[1,990,0]],"ltp":2.04,"tv":1969.9,"id":9433864}]}]}
{"op":"mcm","clk":"4233490938","pt":1631535430151,"mc":[{"id":"1.187557653","rc":[{"batb":[[0,1.8,9.22],[1,1.76,35.31],[2,1.67,32.47]],"batl":[[0,1.83,7.89],[1,1.86,45.29],[2,1.87,8.06]],"ltp":1.92,"tv":1644.56,"id":9632596},{"batb":[[0,2.14,93.46],[1,1.8,30.96],[2,1.19,1]],"batl":[[0,2.28,82.78],[1,990,0.01]],"ltp":2.04,"tv":1969.9,"id":9433864}]}]}
{"op":"mcm","clk":"4233491035","pt":1631535431141,"mc":[{"id":"1.187557653","rc":[{"trd":[[1.83,71.63]],"batb":[[1,1.77,16.96],[2,1.76,43.79]],"batl":[[0,1.83,2.11]],"ltp":1.83,"tv":1650.34,"id":9632596},{"trd":[[2.2,42.52]],"batb":[[1,2.08,39.41],[2,1.92,50.21]],"ltp":2.2,"tv":1974.71,"id":9433864}],"tv":3625.05}]}
{"op":"mcm","clk":"4233491193","pt":1631535432756,"mc":[{"id":"1.187557653","rc":[{"batl":[[1,2.82,253.59],[2,990,0.01]],"ltp":2.2,"tv":1974.71,"id":9433864}]}]}
{"op":"mcm","clk":"4233491431","pt":1631535435045,"mc":[{"id":"1.187557653","rc":[{"trd":[[1.8,97.91]],"batb":[[0,1.77,16.96],[1,1.76,43.79],[2,1.75,8.48]],"ltp":1.8,"tv":1668.78,"id":9632596}],"tv":3643.49}]}
{"op":"mcm","clk":"4233492013","pt":1631535441054,"mc":[{"id":"1.187557653","rc":[{"batl":[[0,1.86,45.29],[1,1.87,8.06],[2,1.88,8.06]],"ltp":1.8,"tv":1668.78,"id":9632596}]}]}
{"op":"mcm","clk":"4233492084","pt":1631535441675,"mc":[{"id":"1.187557653","rc":[{"batl":[[1,990,0.01],[2,990,0]],"ltp":2.2,"tv":1974.71,"id":9433864}]}]}
{"op":"mcm","clk":"4233492308","pt":1631535443970,"mc":[{"id":"1.187557653","rc":[{"batl":[[0,1.83,11.18],[1,1.86,45.29],[2,1.87,8.06]],"ltp":1.8,"tv":1668.78,"id":9632596},{"batl":[[0,2.28,96.21]],"ltp":2.2,"tv":1974.71,"id":9433864}]}]}
{"op":"mcm","clk":"4233492422","pt":1631535445075,"mc":[{"id":"1.187557653","rc":[{"batl":[[0,1.86,45.29],[1,1.87,8.06],[2,1.88,8.06]],"ltp":1.8,"tv":1668.78,"id":9632596},{"batl":[[0,2.28,82.78]],"ltp":2.2,"tv":1974.71,"id":9433864}]}]}
{"op":"mcm","clk":"4233493109","pt":1631535448054,"mc":[{"id":"1.187557653","rc":[{"batl":[[0,1.83,11.18],[1,1.86,45.29],[2,1.87,8.06]],"ltp":1.8,"tv":1668.78,"id":9632596},{"batl":[[0,2.28,96.21]],"ltp":2.2,"tv":1974.71,"id":9433864}]}]}
{"op":"mcm","clk":"4233493710","pt":1631535450248,"mc":[{"id":"1.187557653","rc":[{"batb":[[0,1.76,35.31],[1,1.68,42.01],[2,1.67,32.47]],"batl":[[0,1.86,29.15],[1,990,0.01],[2,1.87,0]],"ltp":1.8,"tv":1668.78,"id":9632596},{"batb":[[0,2.08,39.41],[1,1.92,50.21],[2,1.19,1]],"batl":[[0,990,0.01],[1,990,0]],"ltp":2.2,"tv":1974.71,"id":9433864}]}]}
{"op":"mcm","clk":"4233493787","pt":1631535450631,"mc":[{"id":"1.187557653","rc":[{"batb":[[0,1.68,42.01],[1,1.01,113.7],[2,1.67,0]],"batl":[[0,990,0.01],[1,990,0]],"ltp":1.8,"tv":1668.78,"id":9632596},{"batb":[[0,1.92,50.21],[1,1.19,1],[2,1.01,113.7]],"ltp":2.2,"tv":1974.71,"id":9433864}]}]}
{"op":"mcm","clk":"4233504907","pt":1631535467140,"mc":[{"id":"1.187557653","rc":[{"trd":[[2.06,22.64]],"batb":[[0,1.89,79.36],[1,1.88,39.68],[2,1.87,39.68]],"batl":[[0,2.04,88.87],[1,990,0.01]],"ltp":2.06,"tv":1673.63,"id":9632596},{"trd":[[1.94,35.47]],"batb":[[0,2.04,6.76],[1,1.92,50.21],[2,1.19,1]],"batl":[[0,2.08,8.71],[1,2.1,1199.25],[2,2.12,136.92]],"ltp":1.94,"tv":1979.86,"id":9433864}],"tv":3653.49}]}
{"op":"mcm","clk":"4233505124","pt":1631535468259,"mc":[{"id":"1.187557653","rc":[{"batb":[[0,1.9,27.95],[1,1.89,15.88],[2,1.88,7.94]],"batl":[[0,1.99,102.63],[1,2,37.68],[2,2.02,37.68]],"ltp":2.06,"tv":1673.63,"id":9632596},{"batb":[[2,1.75,33.89]],"batl":[[1,2.12,136.92],[2,2.16,92.6]],"ltp":1.94,"tv":1979.86,"id":9433864}]}]}
{"op":"mcm","clk":"4233505147","pt":1631535468372,"mc":[{"id":"1.187557653","rc":[{"batl":[[0,1.99,42.33],[1,2,7.54],[2,2.02,7.54]],"ltp":2.06,"tv":1673.63,"id":9632596}]}]}
{"op":"mcm","clk":"4233508606","pt":1631535486678,"mc":[{"id":"1.187557653","rc":[{"trd":[[1.92,32.03]],"ltp":1.92,"tv":1676.25,"id":9632596},{"trd":[[2.08,23.86]],"batl":[[0,2.08,6.29]],"ltp":2.08,"tv":1982.28,"id":9433864}],"tv":3658.54}]}
{"op":"mcm","clk":"4233509011","pt":1631535489875,"mc":[{"id":"1.187557653","rc":[{"batb":[[0,1.76,35.56],[1,1.01,113.7],[2,1.88,0]],"batl":[[0,990,0.01],[1,2,0],[2,2.02,0]],"ltp":1.92,"tv":1676.25,"id":9632596},{"batb":[[0,1.75,33.89],[1,1.19,1],[2,1.01,113.7]],"batl":[[0,990,0.01],[1,2.12,0],[2,2.16,0]],"ltp":2.08,"tv":1982.28,"id":9433864}]}]}
{"op":"mcm","clk":"4233511255","pt":1631535510209,"mc":[{"id":"1.187557653","rc":[{"batb":[[0,1.78,7.99],[1,1.76,175.91],[2,1.65,32.86]],"batl":[[0,1.85,29.31],[1,1.89,105.82],[2,1.98,366.71]],"ltp":1.92,"tv":1676.25,"id":9632596},{"batb":[[0,2.24,6.22],[1,2.18,13.76],[2,2.16,6.88]],"ltp":2.08,"tv":1982.28,"id":9433864}]}]}
{"op":"mcm","clk":"4233511364","pt":1631535511224,"mc":[{"id":"1.187557653","rc":[{"batb":[[1,1.76,227.05],[2,1.75,25.57]],"ltp":1.92,"tv":1676.25,"id":9632596},{"trd":[[2.24,39.06]],"batb":[[0,2.24,1.46]],"ltp":2.24,"tv":1991.8,"id":9433864}],"tv":3668.06}]}
{"op":"mcm","clk":"4233511394","pt":1631535511430,"mc":[{"id":"1.187557653","rc":[{"batb":[[1,1.76,192.95],[2,1.75,8.52]],"ltp":1.92,"tv":1676.25,"id":9632596}]}]}
{"op":"mcm","clk":"4233512550","pt":1631535521066,"mc":[{"id":"1.187557653","rc":[{"batb":[[0,1.76,192.95],[1,1.75,8.52],[2,1.74,8.52]],"ltp":1.92,"tv":1676.25,"id":9632596},{"batb":[[0,2.18,13.76],[1,2.16,6.88],[2,2.14,6.88]],"ltp":2.24,"tv":1991.8,"id":9433864}]}]}
{"op":"mcm","clk":"4233512913","pt":1631535524231,"mc":[{"id":"1.187557653","rc":[{"batl":[[0,1.83,15.01],[1,1.85,29.31],[2,1.89,105.82]],"ltp":1.92,"tv":1676.25,"id":9632596},{"batl":[[0,2.28,10.32],[1,2.94,107.06],[2,990,0.01]],"ltp":2.24,"tv":1991.8,"id":9433864}]}]}
{"op":"mcm","clk":"4233512932","pt":1631535524494,"mc":[{"id":"1.187557653","rc":[{"batl":[[1,990,0.01],[2,990,0]],"ltp":2.24,"tv":1991.8,"id":9433864}]}]}
{"op":"mcm","clk":"4233513811","pt":1631535531196,"mc":[{"id":"1.187557653","rc":[{"batb":[[0,1.65,44.52],[1,1.01,113.7],[2,1.74,0]],"batl":[[0,990,0.01],[1,1.85,0],[2,1.89,0]],"ltp":1.92,"tv":1676.25,"id":9632596},{"batb":[[0,1.9,52.05],[1,1.19,1],[2,1.01,113.7]],"batl":[[0,990,0.01],[1,990,0]],"ltp":2.24,"tv":1991.8,"id":9433864}]}]}
{"op":"mcm","clk":"4233515899","pt":1631535549206,"mc":[{"id":"1.187557653","rc":[{"trd":[[2.06,27.49]],"batb":[[0,1.91,47.11],[1,1.9,23.56],[2,1.89,23.56]],"batl":[[0,1.98,7.9],[1,2,27.11],[2,2.06,100.08]],"ltp":2.06,"tv":1681.1,"id":9632596},{"trd":[[1.93,5.18]],"batl":[[0,2.06,66.27],[1,990,0.01]],"ltp":1.93,"tv":1996.98,"id":9433864}],"tv":3678.09}]}
{"op":"mcm","clk":"4233515994","pt":1631535550203,"mc":[{"id":"1.187557653","rc":[{"batb":[[0,1.91,15.7],[1,1.9,7.86],[2,1.89,7.86]],"ltp":2.06,"tv":1681.1,"id":9632596},{"batb":[[0,1.99,15.08],[1,1.98,7.54],[2,1.97,7.54]],"ltp":1.93,"tv":1996.98,"id":9433864}]}]}
{"op":"mcm","clk":"4233516043","pt":1631535550623,"mc":[{"id":"1.187557653","rc":[{"batb":[[0,1.92,27.03],[1,1.91,15.7],[2,1.9,7.86]],"ltp":2.06,"tv":1681.1,"id":9632596}]}]}
{"op":"mcm","clk":"4233516398","pt":1631535554121,"mc":[{"id":"1.187557653","rc":[{"trd":[[1.94,240.4]],"ltp":1.94,"tv":1685.9,"id":9632596},{"trd":[[2.06,52.99]],"batl":[[0,2.06,61.75]],"ltp":2.06,"tv":2001.5,"id":9433864}],"tv":3687.41}]}
{"op":"mcm","clk":"4233518513","pt":1631535573650,"mc":[{"id":"1.187557653","rc":[{"trd":[[1.98,3.69]],"batl":[[0,1.98,4.21]],"ltp":1.98,"tv":1689.59,"id":9632596},{"trd":[[2.02,13.92]],"ltp":2.02,"tv":2005.11,"id":9433864}],"tv":3694.71}]}
{"op":"mcm","clk":"4233518704","pt":1631535575222,"mc":[{"id":"1.187557653","rc":[{"batb":[[1,1.77,34.64],[2,1.01,113.7]],"batl":[[0,990,0.01],[1,2,0],[2,2.06,0]],"ltp":1.98,"tv":1689.59,"id":9632596},{"batb":[[0,1.9,52.05],[1,1.74,34.64],[2,1.19,1]],"batl":[[0,990,0.01],[1,990,0]],"ltp":2.02,"tv":2005.11,"id":9433864}]}]}
{"op":"mcm","clk":"4233518744","pt":1631535575534,"mc":[{"id":"1.187557653","rc":[{"batb":[[0,1.77,34.64],[1,1.01,113.7],[2,1.01,0]],"ltp":1.98,"tv":1689.59,"id":9632596},{"batb":[[0,1.74,34.64],[1,1.19,1],[2,1.01,113.7]],"ltp":2.02,"tv":2005.11,"id":9433864}]}]}
{"op":"mcm","clk":"4233522782","pt":1631535613201,"mc":[{"id":"1.187557653","rc":[{"trd":[[2.28,15.18]],"batb":[[0,2.12,40.25],[1,1.94,27.95],[2,1.93,26.53]],"batl":[[0,2.24,5.42],[1,990,0.01]],"ltp":2.28,"tv":1693.98,"id":9632596},{"trd":[[1.77,5.65]],"batb":[[0,1.83,29.63],[1,1.74,213.33],[2,1.59,47.87]],"batl":[[0,1.86,17.48],[1,1.89,111.11],[2,1.9,23.81]],"ltp":1.77,"tv":2010.76,"id":9433864}],"tv":3704.75}]}
{"op":"mcm","clk":"4233522825","pt":1631535613627,"mc":[{"id":"1.187557653","rc":[{"batl":[[1,2.56,3.91],[2,990,0.01]],"ltp":2.28,"tv":1693.98,"id":9632596},{"batb":[[1,1.8,16.66],[2,1.79,8.34]],"batl":[[1,1.89,79.37],[2,1.9,7.94]],"ltp":1.77,"tv":2010.76,"id":9433864}]}]}
{"op":"mcm","clk":"4233523753","pt":1631535622500,"mc":[{"id":"1.187557653","rc":[{"batl":[[0,2.56,3.91],[1,990,0.01],[2,990,0]],"ltp":2.28,"tv":1693.98,"id":9632596},{"batl":[[0,1.89,79.37],[1,1.9,7.94],[2,1.91,7.94]],"ltp":1.77,"tv":2010.76,"id":9433864}]}]}
{"op":"mcm","clk":"4233524075","pt":1631535625443,"mc":[{"id":"1.187557653","rc":[{"batb":[[0,2.2,7.21],[1,2.12,40.25],[2,1.94,27.95]],"ltp":2.28,"tv":1693.98,"id":9632596},{"batb":[[1,1.8,27.1]],"ltp":1.77,"tv":2010.76,"id":9433864}]}]}
{"op":"mcm","clk":"4233524617","pt":1631535630653,"mc":[{"id":"1.187557653","rc":[{"trd":[[2.2,2.9]],"batb":[[0,2.2,5.76]],"ltp":2.2,"tv":1696.89,"id":9632596}],"tv":3707.66}]}
{"op":"mcm","clk":"4233524979","pt":1631535634164,"mc":[{"id":"1.187557653","rc":[{"batb":[[0,1.93,26.53],[1,1.01,113.7],[2,1.94,0]],"batl":[[0,990,0.01],[1,990,0]],"ltp":2.2,"tv":1696.89,"id":9632596},{"batb":[[0,1.59,47.87],[1,1.19,1],[2,1.01,113.7]],"batl":[[0,990,0.01],[1,1.9,0],[2,1.91,0]],"ltp":1.77,"tv":2010.76,"id":9433864}]}]}
{"op":"mcm","clk":"4233528693","pt":1631535669238,"mc":[{"id":"1.187557653","rc":[{"trd":[[2.66,3.76]],"batb":[[0,2.48,60.48],[1,2.46,30.24],[2,2.44,30.24]],"batl":[[0,2.66,7.91],[1,2.78,108.02],[2,990,0.01]],"ltp":2.66,"tv":1700.65,"id":9632596},{"trd":[[1.6,6.25]],"batl":[[0,1.64,12.6],[1,1.68,166.87],[2,1.69,118.34]],"ltp":1.6,"tv":2017.01,"id":9433864}],"tv":3717.67}]}
{"op":"mcm","clk":"4233528790","pt":1631535670238,"mc":[{"id":"1.187557653","rc":[{"batl":[[0,2.66,56.4],[1,2.68,28.2],[2,2.7,28.2]],"ltp":2.66,"tv":1700.65,"id":9632596},{"batb":[[0,1.65,32.86],[1,1.59,47.87],[2,1.53,54.48]],"batl":[[0,1.69,23.66],[1,1.84,29.47],[2,990,0.01]],"ltp":1.6,"tv":2017.01,"id":9433864}]}]}
{"op":"mcm","clk":"4233528832","pt":1631535670617,"mc":[{"id":"1.187557653","rc":[{"batb":[[0,2.48,36.29],[1,2.46,18.14],[2,2.44,18.14]],"batl":[[0,2.66,11.28],[1,2.68,5.64],[2,2.7,5.64]],"ltp":2.66,"tv":1700.65,"id":9632596}]}]}
{"op":"mcm","clk":"4233529196","pt":1631535674122,"mc":[{"id":"1.187557653","rc":[{"batl":[[1,1.76,112.53],[2,1.84,29.47]],"ltp":1.6,"tv":2017.01,"id":9433864}]}]}
{"op":"mcm","clk":"4233529216","pt":1631535674337,"mc":[{"id":"1.187557653","rc":[{"batl":[[1,1.84,29.47],[2,2.16,372.43]],"ltp":1.6,"tv":2017.01,"id":9433864}]}]}
{"op":"mcm","clk":"4233530025","pt":1631535682341,"mc":[{"id":"1.187557653","rc":[{"batl":[[0,2.66,19.19]],"ltp":2.66,"tv":1700.65,"id":9632596},{"trd":[[1.65,37.39]],"batb":[[0,1.65,14.17]],"ltp":1.65,"tv":2054.4,"id":9433864}],"tv":3755.06}]}
{"op":"mcm","clk":"4233530359","pt":1631535686199,"mc":[{"id":"1.187557653","rc":[{"batl":[[0,2.66,11.28]],"ltp":2.66,"tv":1700.65,"id":9632596},{"batb":[[0,1.53,54.48],[1,1.44,405.13],[2,1.19,1]],"batl":[[1,2.16,372.43],[2,990,0.01]],"ltp":1.65,"tv":2054.4,"id":9433864}]}]}
{"op":"mcm","clk":"4233531715","pt":1631535699658,"mc":[{"id":"1.187557653","rc":[{"batl":[[0,1.65,8.52],[1,1.69,23.66],[2,2.16,372.43]],"ltp":1.65,"tv":2054.4,"id":9433864}]}]}
{"op":"mcm","clk":"4233531943","pt":1631535701990,"mc":[{"id":"1.187557653","rc":[{"batb":[[0,2.22,34.81],[1,1.01,113.7],[2,2.44,0]],"batl":[[0,990,0.01],[1,2.68,0],[2,2.7,0]],"ltp":2.66,"tv":1700.65,"id":9632596},{"batl":[[1,2.16,372.43],[2,990,0.01]],"ltp":1.65,"tv":2054.4,"id":9433864}]}]}
{"op":"mcm","clk":"4233532717","pt":1631535709515,"mc":[{"id":"1.187557653","rc":[{"batb":[[1,1.19,1],[2,1.01,113.7]],"batl":[[1,990,0.01],[2,990,0]],"ltp":1.65,"tv":2054.4,"id":9433864}]}]}
{"op":"mcm","clk":"4233533069","pt":1631535712797,"mc":[{"id":"1.187557653","rc":[{"trd":[[2.52,5.58]],"batb":[[0,2.32,96.49],[1,2.22,34.81],[2,1.01,113.7]],"batl":[[0,2.48,48.38],[1,2.78,3.6],[2,990,0.01]],"ltp":2.52,"tv":1706.23,"id":9632596},{"trd":[[1.65,45.91]],"batb":[[0,1.73,31.34],[1,1.72,9.12],[2,1.71,15.85]],"batl":[[0,1.94,27.95],[1,1.96,13.83],[2,990,0.01]],"ltp":1.65,"tv":2062.92,"id":9433864}],"tv":3769.15}]}
{"op":"mcm","clk":"4233533160","pt":1631535713792,"mc":[{"id":"1.187557653","rc":[{"batb":[[0,2.32,109.43],[1,2.3,6.46],[2,2.28,6.46]],"ltp":2.52,"tv":1706.23,"id":9632596},{"trd":[[1.73,11.98]],"batb":[[0,1.73,25.36]],"ltp":1.73,"tv":2074.9,"id":9433864}],"tv":3781.13}]}
{"op":"mcm","clk":"4233533604","pt":1631535717995,"mc":[{"id":"1.187557653","rc":[{"trd":[[1.73,26.37]],"batb":[[0,1.73,18.16]],"batl":[[2,2.22,357.84]],"ltp":1.73,"tv":2089.3,"id":9433864}],"tv":3795.53}]}
{"op":"mcm","clk":"4233533840","pt":1631535720713,"mc":[{"id":"1.187557653","rc":[{"batl":[[0,1.84,34.25],[1,1.94,27.95],[2,1.96,13.83]],"ltp":1.73,"tv":2089.3,"id":9433864}]}]}
{"op":"mcm","clk":"4233534793","pt":1631535729856,"mc":[{"id":"1.187557653","rc":[{"trd":[[2.32,0.8]],"batb":[[0,2.32,108.63]],"ltp":2.32,"tv":1707.03,"id":9632596},{"trd":[[1.76,24.68]],"batb":[[0,1.72,9.12],[1,1.68,53.57],[2,1.67,66.36]],"batl":[[1,2.22,357.84],[2,990,0.01]],"ltp":1.76,"tv":2090.35,"id":9433864}],"tv":3797.38}]}
{"op":"mcm","clk":"4233535431","pt":1631535736044,"mc":[{"id":"1.187557653","rc":[{"batb":[[0,2.04,43.85],[1,1.01,113.7],[2,2.28,0]],"batl":[[0,990,0.01],[1,2.78,0],[2,990,0]],"ltp":2.32,"tv":1707.03,"id":9632596},{"batb":[[0,1.61,46.02],[1,1.46,404.98],[2,1.19,1]],"batl":[[0,2.22,357.84],[1,990,0.01],[2,990,0]],"ltp":1.76,"tv":2090.35,"id":9433864}]}]}
{"op":"mcm","clk":"4233536349","pt":1631535745171,"mc":[{"id":"1.187557653","rc":[{"batb":[[1,1.19,1],[2,1.01,113.7]],"ltp":1.76,"tv":2090.35,"id":9433864}]}]}
{"op":"mcm","clk":"4233536431","pt":1631535745962,"mc":[{"id":"1.187557653","rc":[{"batb":[[1,1.92,28.24],[2,1.9,14.27]],"batl":[[0,2.2,12.1],[1,2.54,3.94],[2,990,0.01]],"ltp":2.32,"tv":1707.03,"id":9632596},{"batb":[[0,1.84,29.47],[1,1.82,141.27],[2,1.81,8.24]],"batl":[[0,1.89,118.66],[1,2.22,357.84],[2,990,0.01]],"ltp":1.76,"tv":2090.35,"id":9433864}]}]}
{"op":"mcm","clk":"4233536516","pt":1631535746867,"mc":[{"id":"1.187557653","rc":[{"batb":[[2,1.91,27.36]],"ltp":2.32,"tv":1707.03,"id":9632596},{"trd":[[1.84,23.08]],"batb":[[0,1.84,23.85]],"batl":[[1,1.92,15.62],[2,1.93,7.82]],"ltp":1.84,"tv":2101.59,"id":9433864}],"tv":3808.62}]}
{"op":"mcm","clk":"4233537957","pt":1631535762972,"mc":[{"id":"1.187557653","rc":[{"batb":[[1,1.91,27.36],[2,1.01,113.7]],"ltp":2.32,"tv":1707.03,"id":9632596},{"batb":[[0,1.82,126.38],[1,1.81,8.24],[2,1.8,8.24]],"ltp":1.84,"tv":2101.59,"id":9433864}]}]}
{"op":"mcm","clk":"4233538350","pt":1631535767196,"mc":[{"id":"1.187557653","rc":[{"batl":[[0,990,0.01],[1,2.54,0],[2,990,0]],"ltp":2.32,"tv":1707.03,"id":9632596},{"trd":[[1.89,84.72]],"batb":[[0,1.79,31.88],[1,1.7,37.41],[2,1.55,392.04]],"batl":[[0,2.22,357.84],[1,990,0.01],[2,1.93,0]],"ltp":1.89,"tv":2141.59,"id":9433864}],"tv":3848.62}]}
{"op":"mcm","clk":"4233538376","pt":1631535767506,"mc":[{"id":"1.187557653","rc":[{"batb":[[0,1.91,27.36],[1,1.01,113.7],[2,1.01,0]],"ltp":2.32,"tv":1707.03,"id":9632596},{"batb":[[0,1.7,37.41],[1,1.55,392.04],[2,1.19,1]],"ltp":1.89,"tv":2141.59,"id":9433864}]}]}
{"op":"mcm","clk":"4233539391","pt":1631535777280,"mc":[{"id":"1.187557653","rc":[{"batb":[[0,2.22,67.56],[1,2.2,33.78],[2,2.18,33.78]],"batl":[[0,2.42,78.46],[1,990,0.01]],"ltp":2.32,"tv":1707.03,"id":9632596},{"trd":[[1.71,24.44]],"batb":[[0,1.76,30.8],[1,1.74,28.64],[2,1.7,37.41]],"batl":[[0,1.8,130.55],[1,1.87,106.96],[2,1.98,27.39]],"ltp":1.71,"tv":2153.29,"id":9433864}],"tv":3860.32}]}
{"op":"mcm","clk":"4233539514","pt":1631535778285,"mc":[{"id":"1.187557653","rc":[{"batb":[[0,2.22,13.52],[1,2.2,6.76],[2,2.18,43.83]],"batl":[[1,2.7,3.7],[2,990,0.01]],"ltp":2.32,"tv":1707.03,"id":9632596},{"batb":[[2,1.73,17.34]],"ltp":1.71,"tv":2153.29,"id":9433864}]}]}
{"op":"mcm","clk":"4233539959","pt":1631535782111,"mc":[{"id":"1.187557653","rc":[{"trd":[[2.24,11.17]],"ltp":2.24,"tv":1713.42,"id":9632596},{"trd":[[1.8,26.4]],"batl":[[0,1.8,122.6],[2,1.89,101.17]],"ltp":1.8,"tv":2161.24,"id":9433864}],"tv":3874.66}]}
{"op":"mcm","clk":"4233539983","pt":1631535782317,"mc":[{"id":"1.187557653","rc":[{"batl":[[2,1.98,27.39]],"ltp":1.8,"tv":2161.24,"id":9433864}]}]}
{"op":"mcm","clk":"4233540578","pt":1631535787216,"mc":[{"id":"1.187557653","rc":[{"batb":[[1,1.74,15.58]],"batl":[[0,1.8,104.1]],"ltp":1.8,"tv":2161.24,"id":9433864}]}]}
{"op":"mcm","clk":"4233540928","pt":1631535790188,"mc":[{"id":"1.187557653","rc":[{"batb":[[1,1.74,28.65]],"batl":[[0,1.78,12.32],[1,1.8,104.1],[2,1.87,106.96]],"ltp":1.8,"tv":2161.24,"id":9433864}]}]}
{"op":"mcm","clk":"4233541068","pt":1631535791730,"mc":[{"id":"1.187557653","rc":[{"trd":[[1.76,30.4]],"batb":[[0,1.76,27.94]],"ltp":1.76,"tv":2166.96,"id":9433864}],"tv":3880.38}]}
{"op":"mcm","clk":"4233541280","pt":1631535794430,"mc":[{"id":"1.187557653","rc":[{"batb":[[0,1.74,13.07],[1,1.73,17.34],[2,1.72,8.68]],"ltp":1.76,"tv":2166.96,"id":9433864}]}]}
{"op":"mcm","clk":"4233546087","pt":1631535849227,"mc":[{"id":"1.187557653","rc":[{"batb":[[0,1.98,48.95],[1,1.01,113.7],[2,2.18,0]],"batl":[[0,990,0.01],[1,2.7,0],[2,990,0]],"ltp":2.24,"tv":1713.42,"id":9632596},{"batb":[[0,1.62,44.52],[1,1.55,392.04],[2,1.19,1]],"batl":[[0,2.22,357.84],[1,990,0.01],[2,1.87,0]],"ltp":1.76,"tv":2166.96,"id":9433864}]}]}
{"op":"mcm","clk":"4233547038","pt":1631535859243,"mc":[{"id":"1.187557653","rc":[{"batl":[[0,990,0.01],[1,990,0]],"ltp":1.76,"tv":2166.96,"id":9433864}]}]}
{"op":"mcm","clk":"4233547105","pt":1631535860028,"mc":[{"id":"1.187557653","rc":[{"batb":[[1,1.86,29.15],[2,1.84,14.73]],"batl":[[0,2.12,11.53],[1,2.2,127.9],[2,2.42,4.13]],"ltp":2.24,"tv":1713.42,"id":9632596},{"batb":[[0,1.9,28.53],[1,1.88,14.42],[2,1.87,48.12]],"batl":[[0,1.94,9.83],[1,1.98,111.97],[2,990,0.01]],"ltp":1.76,"tv":2166.96,"id":9433864}]}]}
{"op":"mcm","clk":"4233547207","pt":1631535861075,"mc":[{"id":"1.187557653","rc":[{"batb":[[2,1.84,45.44]],"ltp":2.24,"tv":1713.42,"id":9632596},{"trd":[[1.9,119.06]],"batb":[[0,1.9,23.11],[2,1.87,16.04]],"batl":[[1,1.97,15.22],[2,1.98,119.59]],"ltp":1.9,"tv":2177.82,"id":9433864}],"tv":3891.24}]}
{"op":"mcm","clk":"4233548045","pt":1631535870251,"mc":[{"id":"1.187557653","rc":[{"trd":[[1.94,43]],"batl":[[0,1.94,6.06]],"ltp":1.94,"tv":2185.36,"id":9433864}],"tv":3898.78}]}
{"op":"mcm","clk":"4233548623","pt":1631535877043,"mc":[{"id":"1.187557653","rc":[{"batb":[[1,1.84,30.71],[2,1.01,113.7]],"ltp":2.24,"tv":1713.42,"id":9632596},{"batb":[[0,1.87,16.04],[1,1.86,8.02],[2,1.85,72.88]],"ltp":1.94,"tv":2185.36,"id":9433864}]}]}
{"op":"mcm","clk":"4233548898","pt":1631535880492,"mc":[{"id":"1.187557653","rc":[{"batl":[[0,2.2,127.9],[1,2.42,4.13],[2,990,0.01]],"ltp":2.24,"tv":1713.42,"id":9632596},{"batl":[[0,1.97,15.22],[1,1.98,119.59],[2,1.99,7.62]],"ltp":1.94,"tv":2185.36,"id":9433864}]}]}
{"op":"mcm","clk":"4233549032","pt":1631535882056,"mc":[{"id":"1.187557653","rc":[{"batb":[[0,1.84,30.71],[1,1.01,113.7],[2,1.01,0]],"batl":[[0,990,0.01],[1,2.42,0],[2,990,0]],"ltp":2.24,"tv":1713.42,"id":9632596},{"batb":[[0,1.75,34.23],[1,1.55,392.04],[2,1.19,1]],"batl":[[0,2.5,299.95],[1,990,0.01],[2,1.99,0]],"ltp":1.94,"tv":2185.36,"id":9433864}]}]}
{"op":"mcm","clk":"4233549386","pt":1631535886895,"mc":[{"id":"1.187557653","rc":[{"batl":[[0,990,0.01],[1,990,0]],"ltp":1.94,"tv":2185.36,"id":9433864}]}]}
{"op":"mcm","clk":"4233549471","pt":1631535888088,"mc":[{"id":"1.187557653","rc":[{"trd":[[2.3,63.32]],"batb":[[0,2.08,96.16],[1,1.96,27.66],[2,1.94,13.98]],"batl":[[0,2.24,2.51],[1,2.32,76.91],[2,990,0.01]],"ltp":2.3,"tv":1717.77,"id":9632596},{"trd":[[1.76,36.08]],"batb":[[0,1.81,29.95],[1,1.79,15.14],[2,1.75,34.23]],"batl":[[0,1.86,37.12],[1,1.87,8.06],[2,1.88,8.06]],"ltp":1.76,"tv":2191.04,"id":9433864}],"tv":3908.81}]}
{"op":"mcm","clk":"4233549522","pt":1631535888766,"mc":[{"id":"1.187557653","rc":[{"batb":[[0,2.1,40.75],[1,2.08,96.16],[2,1.96,27.66]],"batl":[[2,2.58,3.88]],"ltp":2.3,"tv":1717.77,"id":9632596},{"batb":[[2,1.77,16.96]],"ltp":1.76,"tv":2191.04,"id":9433864}]}]}
{"op":"mcm","clk":"4233549780","pt":1631535892480,"mc":[{"id":"1.187557653","rc":[{"trd":[[2.16,7.17]],"ltp":2.16,"tv":1720.31,"id":9632596},{"trd":[[1.86,2.95]],"batl":[[0,1.86,34.17]],"ltp":1.86,"tv":2193.99,"id":9433864}],"tv":3914.3}]}
{"op":"mcm","clk":"4233550170","pt":1631535897616,"mc":[{"id":"1.187557653","rc":[{"batl":[[0,2.32,76.91],[1,2.58,3.88],[2,990,0.01]],"ltp":2.16,"tv":1720.31,"id":9632596},{"batl":[[0,1.86,13.19]],"ltp":1.86,"tv":2193.99,"id":9433864}]}]}
{"op":"mcm","clk":"4233550356","pt":1631535900521,"mc":[{"id":"1.187557653","rc":[{"batl":[[0,2.28,14.2],[1,2.32,76.91],[2,2.58,3.88]],"ltp":2.16,"tv":1720.31,"id":9632596},{"batl":[[0,1.83,10.39],[1,1.86,13.19],[2,1.87,8.06]],"ltp":1.86,"tv":2193.99,"id":9433864}]}]}
{"op":"mcm","clk":"4233550664","pt":1631535904680,"mc":[{"id":"1.187557653","rc":[{"batb":[[2,1.88,28.62]],"ltp":2.16,"tv":1720.31,"id":9632596},{"batb":[[0,1.77,16.96],[1,1.76,8.48],[2,1.75,42.71]],"ltp":1.86,"tv":2193.99,"id":9433864}]}]}
{"op":"mcm","clk":"4233550750","pt":1631535905930,"mc":[{"id":"1.187557653","rc":[{"batb":[[0,1.88,28.62],[1,1.01,113.7],[2,1.88,0]],"batl":[[0,990,0.01],[1,2.32,0],[2,2.58,0]],"ltp":2.16,"tv":1720.31,"id":9632596},{"batb":[[0,1.63,43.35],[1,1.55,392.04],[2,1.19,1]],"batl":[[0,2.36,326.18],[1,990,0.01],[2,1.87,0]],"ltp":1.86,"tv":2193.99,"id":9433864}]}]}
{"op":"mcm","clk":"4233551237","pt":1631535913422,"mc":[{"id":"1.187557653","rc":[{"batb":[[1,1.19,1],[2,1.01,113.7]],"batl":[[0,990,0.01],[1,990,0]],"ltp":1.86,"tv":2193.99,"id":9433864}]}]}
{"op":"mcm","clk":"4233551329","pt":1631535914721,"mc":[{"id":"1.187557653","rc":[{"batb":[[0,2.46,6.28],[1,2.4,62.5],[2,2.38,31.24]],"ltp":2.16,"tv":1720.31,"id":9632596},{"trd":[[1.64,18.82]],"batb":[[0,1.68,32.27],[1,1.66,20.01],[2,1.63,43.35]],"batl":[[0,1.72,154.23],[1,1.89,28.69],[2,1.91,14.19]],"ltp":1.64,"tv":2206.19,"id":9433864}],"tv":3926.5}]}
{"op":"mcm","clk":"4233551407","pt":1631535915922,"mc":[{"id":"1.187557653","rc":[{"batb":[[1,2.4,37.5],[2,2.38,18.74]],"batl":[[0,2.56,11.72],[1,2.58,5.86],[2,2.6,5.86]],"ltp":2.16,"tv":1720.31,"id":9632596}]}]}
{"op":"mcm","clk":"4233551921","pt":1631535924534,"mc":[{"id":"1.187557653","rc":[{"batb":[[0,2.4,37.5],[1,2.38,18.74],[2,2.36,18.74]],"ltp":2.16,"tv":1720.31,"id":9632596},{"batb":[[1,1.66,16.34]],"ltp":1.64,"tv":2206.19,"id":9433864}]}]}
{"op":"mcm","clk":"4233552142","pt":1631535927464,"mc":[{"id":"1.187557653","rc":[{"batl":[[0,2.56,23.87]],"ltp":2.16,"tv":1720.31,"id":9632596},{"trd":[[1.68,22.97]],"batb":[[0,1.68,20.79]],"ltp":1.68,"tv":2229.16,"id":9433864}],"tv":3949.47}]}
{"op":"mcm","clk":"4233552450","pt":1631535931578,"mc":[{"id":"1.187557653","rc":[{"batb":[[0,1.63,43.35],[1,1.62,132.65],[2,1.55,52.89]],"batl":[[1,2.22,357.84],[2,990,0.01]],"ltp":1.68,"tv":2229.16,"id":9433864}]}]}
{"op":"mcm","clk":"4233552941","pt":1631535937698,"mc":[{"id":"1.187557653","rc":[{"batl":[[0,2.56,11.72]],"ltp":2.16,"tv":1720.31,"id":9632596}]}]}
{"op":"mcm","clk":"4233553170","pt":1631535940927,"mc":[{"id":"1.187557653","rc":[{"batb":[[0,2.3,31.55],[1,2.08,41.92],[2,1.01,113.7]],"batl":[[0,990,0.01],[1,2.58,0],[2,2.6,0]],"ltp":2.16,"tv":1720.31,"id":9632596},{"batb":[[1,1.55,52.89],[2,1.46,404.98]],"batl":[[0,2.22,357.84],[1,990,0.01],[2,990,0]],"ltp":1.68,"tv":2229.16,"id":9433864}]}]}
{"op":"mcm","clk":"4233553228","pt":1631535941504,"mc":[{"id":"1.187557653","rc":[{"batb":[[0,2.08,41.92],[1,1.01,113.7],[2,1.01,0]],"ltp":2.16,"tv":1720.31,"id":9632596},{"batb":[[0,1.55,52.89],[1,1.46,404.98],[2,1.19,1]],"ltp":1.68,"tv":2229.16,"id":9433864}]}]}
{"op":"mcm","clk":"4233553405","pt":1631535944112,"mc":[{"id":"1.187557653","rc":[{"batl":[[0,3.95,73.3],[1,990,0.01]],"ltp":2.16,"tv":1720.31,"id":9632596},{"batl":[[0,2.2,1007.9],[1,2.22,357.84],[2,990,0.01]],"ltp":1.68,"tv":2229.16,"id":9433864}]}]}
{"op":"mcm","clk":"4233553424","pt":1631535944305,"mc":[{"id":"1.187557653","rc":[{"batl":[[0,990,0.01],[1,990,0]],"ltp":2.16,"tv":1720.31,"id":9632596},{"batl":[[0,2.22,357.84],[1,990,0.01],[2,990,0]],"ltp":1.68,"tv":2229.16,"id":9433864}]}]}
{"op":"mcm","clk":"4233554177","pt":1631535953335,"mc":[{"id":"1.187557653","rc":[{"batb":[[1,1.19,1],[2,1.01,113.7]],"ltp":1.68,"tv":2229.16,"id":9433864}]}]}
{"op":"mcm","clk":"4233554340","pt":1631535955227,"mc":[{"id":"1.187557653","rc":[{"batb":[[1,1.94,27.95],[2,1.92,14.12]],"batl":[[0,2.24,11.21],[1,2.26,88.5],[2,2.28,13.16]],"ltp":2.16,"tv":1720.31,"id":9632596},{"batb":[[0,1.82,29.79],[1,1.8,15.06],[2,1.55,52.89]],"batl":[[0,1.86,15.76],[1,1.89,148.62],[2,2.22,357.84]],"ltp":1.68,"tv":2229.16,"id":9433864}]}]}
{"op":"mcm","clk":"4233554443","pt":1631535956233,"mc":[{"id":"1.187557653","rc":[{"batb":[[0,2.14,42.05],[1,2.12,7],[2,2.1,7]],"ltp":2.16,"tv":1720.31,"id":9632596},{"trd":[[1.82,33.9]],"batb":[[0,1.82,24.14],[2,1.76,33.3]],"ltp":1.82,"tv":2240.45,"id":9433864}],"tv":3960.77}]}
{"op":"mcm","clk":"4233554532","pt":1631535957120,"mc":[{"id":"1.187557653","rc":[{"batb":[[0,2.14,14.02]],"ltp":2.16,"tv":1720.31,"id":9632596}]}]}
{"op":"mcm","clk":"4233555705","pt":1631535972269,"mc":[{"id":"1.187557653","rc":[{"trd":[[1.82,42.92]],"batb":[[0,1.76,33.3],[1,1.65,42.18],[2,1.52,396.29]],"ltp":1.82,"tv":2249.47,"id":9433864}],"tv":3969.78}]}
{"op":"mcm","clk":"4233556459","pt":1631535982178,"mc":[{"id":"1.187557653","rc":[{"batb":[[0,2.08,41.92],[1,1.86,29.54],[2,1.01,113.7]],"batl":[[0,990,0.01],[1,2.26,0],[2,2.28,0]],"ltp":2.16,"tv":1720.31,"id":9632596},{"batl":[[0,2.22,357.84],[1,990,0.01],[2,2.22,0]],"ltp":1.82,"tv":2249.47,"id":9433864}]}]}
{"op":"mcm","clk":"4233556493","pt":1631535982492,"mc":[{"id":"1.187557653","rc":[{"batb":[[0,1.86,29.54],[1,1.01,113.7],[2,1.01,0]],"ltp":2.16,"tv":1720.31,"id":9632596},{"batb":[[0,1.65,42.18],[1,1.52,396.29],[2,1.19,1]],"batl":[[1,990,0]],"ltp":1.82,"tv":2249.47,"id":9433864}]}]}
{"op":"mcm","clk":"4233558944","pt":1631536012155,"mc":[{"id":"1.187557653","rc":[{"batb":[[0,2.36,113.35],[1,1.86,29.54],[2,1.01,113.7]],"batl":[[0,2.5,11.06],[1,2.6,91.82]],"ltp":2.16,"tv":1720.31,"id":9632596},{"trd":[[1.65,58.03]],"batb":[[0,1.69,32.09],[1,1.67,16.23],[2,1.65,36.11]],"batl":[[0,1.7,125.79],[1,1.74,17.24],[2,1.75,8.62]],"ltp":1.65,"tv":2261.6,"id":9433864}],"tv":3981.91}]}
{"op":"mcm","clk":"4233559043","pt":1631536013252,"mc":[{"id":"1.187557653","rc":[{"batb":[[1,2.28,32.47],[2,2.06,43.35]],"batl":[[2,2.84,3.52]],"ltp":2.16,"tv":1720.31,"id":9632596},{"batb":[[2,1.66,18.08]],"ltp":1.65,"tv":2261.6,"id":9433864}]}]}
{"op":"mcm","clk":"4233560397","pt":1631536029277,"mc":[{"id":"1.187557653","rc":[{"batb":[[0,1.66,18.08],[1,1.65,45.15],[2,1.64,9.04]],"ltp":1.65,"tv":2261.6,"id":9433864}]}]}
{"op":"mcm","clk":"4233561465","pt":1631536041815,"mc":[{"id":"1.187557653","rc":[{"batb":[[0,2.06,43.18],[1,1.01,113.7],[2,2.06,0]],"ltp":2.16,"tv":1720.31,"id":9632596},{"batb":[[0,1.56,51.3],[1,1.52,396.29],[2,1.19,1]],"batl":[[0,2.22,357.84],[1,1.74,0],[2,1.75,0]],"ltp":1.65,"tv":2261.6,"id":9433864}]}]}
{"op":"mcm","clk":"4233561805","pt":1631536046110,"mc":[{"id":"1.187557653","rc":[{"batl":[[0,2.5,207.23]],"ltp":2.16,"tv":1720.31,"id":9632596}]}]}
{"op":"mcm","clk":"4233563313","pt":1631536064265,"mc":[{"id":"1.187557653","rc":[{"batl":[[0,2.22,90.1],[1,2.24,1369.17],[2,2.28,65.8]],"ltp":2.16,"tv":1720.31,"id":9632596},{"batb":[[0,1.76,144.79],[1,1.56,51.3],[2,1.52,396.29]],"batl":[[0,1.86,10.26],[1,1.89,116.49],[2,2.22,357.84]],"ltp":1.65,"tv":2261.6,"id":9433864}]}]}
{"op":"mcm","clk":"4233563413","pt":1631536065261,"mc":[{"id":"1.187557653","rc":[{"batb":[[0,2.14,70.08],[1,2.12,35.04],[2,2.1,35.04]],"batl":[[1,2.24,15.81],[2,2.28,13.16]],"ltp":2.16,"tv":1720.31,"id":9632596},{"trd":[[1.83,40.73]],"batb":[[0,1.83,23.98],[1,1.81,14.98],[2,1.78,32.38]],"ltp":1.83,"tv":2272.89,"id":9433864}],"tv":3993.2}]}
{"op":"mcm","clk":"4233563451","pt":1631536065652,"mc":[{"id":"1.187557653","rc":[{"batb":[[0,2.14,14.02],[1,2.12,7],[2,2.1,7]],"ltp":2.16,"tv":1720.31,"id":9632596}]}]}
{"op":"mcm","clk":"4233563763","pt":1631536069279,"mc":[{"id":"1.187557653","rc":[{"batl":[[2,1.97,103.17]],"ltp":1.83,"tv":2272.89,"id":9433864}]}]}
{"op":"mcm","clk":"4233563780","pt":1631536069452,"mc":[{"id":"1.187557653","rc":[{"batl":[[2,2.22,357.84]],"ltp":1.83,"tv":2272.89,"id":9433864}]}]}
{"op":"mcm","clk":"4233564841","pt":1631536081699,"mc":[{"id":"1.187557653","rc":[{"batb":[[0,1.78,32.38],[1,1.76,144.79],[2,1.65,41.67]],"ltp":1.83,"tv":2272.89,"id":9433864}]}]}
{"op":"mcm","clk":"4233565049","pt":1631536084291,"mc":[{"id":"1.187557653","rc":[{"trd":[[2.22,12.86]],"batl":[[0,2.22,83.67]],"ltp":2.22,"tv":1733.17,"id":9632596}],"tv":4006.06}]}
{"op":"mcm","clk":"4233565962","pt":1631536094906,"mc":[{"id":"1.187557653","rc":[{"batb":[[0,2.06,43.18],[1,1.85,30.21],[2,1.01,113.7]],"ltp":2.22,"tv":1733.17,"id":9632596},{"batb":[[1,1.65,41.67],[2,1.52,396.29]],"batl":[[0,2.22,357.84],[1,1.89,0],[2,2.22,0]],"ltp":1.83,"tv":2272.89,"id":9433864}]}]}
{"op":"mcm","clk":"4233565993","pt":1631536095340,"mc":[{"id":"1.187557653","rc":[{"batb":[[0,1.85,30.21],[1,1.01,113.7],[2,1.01,0]],"ltp":2.22,"tv":1733.17,"id":9632596},{"batb":[[0,1.65,41.67],[1,1.52,396.29],[2,1.19,1]],"ltp":1.83,"tv":2272.89,"id":9433864}]}]}
{"op":"mcm","clk":"4233567020","pt":1631536108218,"mc":[{"id":"1.187557653","rc":[{"batl":[[0,1.94,103.1],[1,1.95,1542.78],[2,1.96,76.52]],"ltp":2.22,"tv":1733.17,"id":9632596},{"batb":[[0,2.08,7.06],[1,1.65,41.67]],"batl":[[0,2.12,7.54],[1,2.2,158.17]],"ltp":1.83,"tv":2272.89,"id":9433864}]}]}
{"op":"mcm","clk":"4233567125","pt":1631536109216,"mc":[{"id":"1.187557653","rc":[{"batb":[[1,1.74,36.99],[2,1.73,31.34]],"batl":[[0,1.94,61.86],[1,1.95,27.81],[2,1.96,45.91]],"ltp":2.22,"tv":1733.17,"id":9632596},{"trd":[[2.08,33.76]],"batb":[[0,2.08,2.11],[1,1.97,46.44],[2,1.83,29.2]],"batl":[[1,2.16,69.44],[2,2.18,34.72]],"ltp":2.08,"tv":2282.79,"id":9433864}],"tv":4015.96}]}
{"op":"mcm","clk":"4233567150","pt":1631536109530,"mc":[{"id":"1.187557653","rc":[{"batl":[[2,1.96,15.3]],"ltp":2.22,"tv":1733.17,"id":9632596},{"batl":[[1,2.16,13.88],[2,2.18,6.94]],"ltp":2.08,"tv":2282.79,"id":9433864}]}]}
{"op":"mcm","clk":"4233568006","pt":1631536119482,"mc":[{"id":"1.187557653","rc":[{"batb":[[0,1.97,46.44],[1,1.83,29.2],[2,1.67,383.76]],"batl":[[0,2.16,13.88],[1,2.18,6.94],[2,2.2,165.11]],"ltp":2.08,"tv":2282.79,"id":9433864}]}]}
{"op":"mcm","clk":"4233568238","pt":1631536122368,"mc":[{"id":"1.187557653","rc":[{"batl":[[0,1.94,70.67]],"ltp":2.22,"tv":1733.17,"id":9632596},{"batl":[[0,2.12,12.39],[1,2.16,13.88],[2,2.18,6.94]],"ltp":2.08,"tv":2282.79,"id":9433864}]}]}
{"op":"mcm","clk":"4233573818","pt":1631536192903,"mc":[{"id":"1.187557653","rc":[{"trd":[[1.89,514.92]],"ltp":1.89,"tv":1736.8,"id":9632596},{"trd":[[2.12,28.31]],"batl":[[0,2.12,9.15]],"ltp":2.12,"tv":2286.03,"id":9433864}],"tv":4022.83}]}
{"op":"mcm","clk":"4233573996","pt":1631536195630,"mc":[{"id":"1.187557653","rc":[{"batb":[[2,1.01,113.7]],"batl":[[1,1.96,15.3],[2,1.97,7.66]],"ltp":1.89,"tv":1736.8,"id":9632596}]}]}
{"op":"mcm","clk":"4233574051","pt":1631536196416,"mc":[{"id":"1.187557653","rc":[{"trd":[[1.89,518.55]],"ltp":1.89,"tv":1740.43,"id":9632596},{"trd":[[2.12,31.55]],"batl":[[0,2.12,5.91]],"ltp":2.12,"tv":2289.27,"id":9433864}],"tv":4029.7}]}
{"op":"mcm","clk":"4233574372","pt":1631536200222,"mc":[{"id":"1.187557653","rc":[{"trd":[[1.89,521.34]],"ltp":1.89,"tv":1743.22,"id":9632596},{"trd":[[2.12,34.04]],"batl":[[0,2.12,3.42]],"ltp":2.12,"tv":2291.76,"id":9433864}],"tv":4034.98}]}
{"op":"mcm","clk":"4233574691","pt":1631536203128,"mc":[{"id":"1.187557653","rc":[{"batl":[[0,1.94,61.86]],"ltp":1.89,"tv":1743.22,"id":9632596},{"batl":[[0,2.16,13.88],[1,2.18,6.94],[2,2.2,165.11]],"ltp":2.12,"tv":2291.76,"id":9433864}]}]}
{"op":"mcm","clk":"4233574762","pt":1631536203814,"mc":[{"id":"1.187557653","rc":[{"trd":[[1.86,25.76]],"ltp":1.86,"tv":1745.22,"id":9632596},{"trd":[[2.16,41.51]],"batl":[[0,2.16,12.16]],"ltp":2.16,"tv":2293.48,"id":9433864}],"tv":4038.7}]}
{"op":"mcm","clk":"4233574960","pt":1631536206010,"mc":[{"id":"1.187557653","rc":[{"batl":[[0,1.92,9.38],[1,1.94,61.86],[2,1.96,15.3]],"ltp":1.86,"tv":1745.22,"id":9632596},{"batl":[[0,2.16,29.26]],"ltp":2.16,"tv":2293.48,"id":9433864}]}]}
{"op":"mcm","clk":"4233575004","pt":1631536206640,"mc":[{"id":"1.187557653","rc":[{"batl":[[0,1.94,61.86],[1,1.96,15.3],[2,1.97,7.66]],"ltp":1.86,"tv":1745.22,"id":9632596},{"batl":[[0,2.16,12.16]],"ltp":2.16,"tv":2293.48,"id":9433864}]}]}
{"op":"mcm","clk":"4233575221","pt":1631536209536,"mc":[{"id":"1.187557653","rc":[{"batl":[[0,1.92,9.38],[1,1.94,61.86],[2,1.96,15.3]],"ltp":1.86,"tv":1745.22,"id":9632596},{"batl":[[0,2.16,29.26]],"ltp":2.16,"tv":2293.48,"id":9433864}]}]}
{"op":"mcm","clk":"4233575294","pt":1631536210429,"mc":[{"id":"1.187557653","rc":[{"batl":[[0,1.94,61.86],[1,1.96,15.3],[2,1.97,7.66]],"ltp":1.86,"tv":1745.22,"id":9632596},{"batl":[[0,2.16,12.16]],"ltp":2.16,"tv":2293.48,"id":9433864}]}]}
{"op":"mcm","clk":"4233575540","pt":1631536213353,"mc":[{"id":"1.187557653","rc":[{"batl":[[0,1.92,9.38],[1,1.94,61.86],[2,1.96,15.3]],"ltp":1.86,"tv":1745.22,"id":9632596},{"batl":[[0,2.16,29.26]],"ltp":2.16,"tv":2293.48,"id":9433864}]}]}
{"op":"mcm","clk":"4233575773","pt":1631536216239,"mc":[{"id":"1.187557653","rc":[{"batl":[[0,2.72,264.63],[1,2.18,0],[2,2.2,0]],"ltp":2.16,"tv":2293.48,"id":9433864}]}]}
{"op":"mcm","clk":"4233575802","pt":1631536216656,"mc":[{"id":"1.187557653","rc":[{"batb":[[0,1.74,36.99],[1,1.01,113.7],[2,1.01,0]],"ltp":1.86,"tv":1745.22,"id":9632596},{"batb":[[0,1.83,29.2],[1,1.67,383.76],[2,1.19,1]],"ltp":2.16,"tv":2293.48,"id":9433864}]}]}
{"op":"mcm","clk":"4233576707","pt":1631536226862,"mc":[{"id":"1.187557653","rc":[{"batb":[[0,1.76,142.17],[1,1.74,36.99],[2,1.65,32.86]],"batl":[[0,1.83,49.18],[1,1.84,89.81],[2,1.85,53.9]],"ltp":1.86,"tv":1745.22,"id":9632596},{"batb":[[0,2.24,7.09],[1,1.83,29.2]],"ltp":2.16,"tv":2293.48,"id":9433864}]}]}
{"op":"mcm","clk":"4233576809","pt":1631536227868,"mc":[{"id":"1.187557653","rc":[{"batl":[[0,1.83,16.4],[1,1.84,73.42],[2,1.85,37.51]],"ltp":1.86,"tv":1745.22,"id":9632596},{"trd":[[2.24,48.4]],"batb":[[0,2.24,2.42],[1,2.12,37.41],[2,1.96,47.53]],"batl":[[0,2.34,12.82],[1,2.36,6.4],[2,2.38,6.4]],"ltp":2.24,"tv":2302.82,"id":9433864}],"tv":4048.04}]}
{"op":"mcm","clk":"4233577714","pt":1631536237785,"mc":[{"id":"1.187557653","rc":[{"batb":[[0,1.76,122.74]],"ltp":1.86,"tv":1745.22,"id":9632596},{"batb":[[0,2.12,37.41],[1,1.96,47.53],[2,1.74,379.61]],"ltp":2.24,"tv":2302.82,"id":9433864}]}]}
{"op":"mcm","clk":"4233577965","pt":1631536240804,"mc":[{"id":"1.187557653","rc":[{"batl":[[0,1.83,32.56]],"ltp":1.86,"tv":1745.22,"id":9632596},{"batl":[[0,2.28,9.36],[1,2.34,12.82],[2,2.36,6.4]],"ltp":2.24,"tv":2302.82,"id":9433864}]}]}
{"op":"mcm","clk":"4233578621","pt":1631536248187,"mc":[{"id":"1.187557653","rc":[{"batb":[[0,1.74,36.99],[1,1.65,32.86],[2,1.64,44.94]],"batl":[[0,1.85,29.31],[1,1.87,14.5],[2,1.85,0]],"ltp":1.86,"tv":1745.22,"id":9632596},{"batl":[[0,2.72,264.63],[1,2.34,0],[2,2.36,0]],"ltp":2.24,"tv":2302.82,"id":9433864}]}]}
{"op":"mcm","clk":"4233578638","pt":1631536248401,"mc":[{"id":"1.187557653","rc":[{"batb":[[0,1.64,44.94],[1,1.01,113.7],[2,1.64,0]],"ltp":1.86,"tv":1745.22,"id":9632596},{"batb":[[0,1.96,47.53],[1,1.74,379.61],[2,1.19,1]],"ltp":2.24,"tv":2302.82,"id":9433864}]}]}
{"op":"mcm","clk":"4233579237","pt":1631536256099,"mc":[{"id":"1.187557653","rc":[{"trd":[[2,17.24]],"batb":[[0,1.88,47.88],[1,1.87,23.94],[2,1.86,88.45]],"batl":[[0,1.96,36.6],[1,1.98,13.69],[2,2.02,120.54]],"ltp":2.0,"tv":1750.22,"id":9632596},{"trd":[[1.99,33.05]],"batl":[[0,2.12,15.96],[1,2.72,264.63]],"ltp":1.99,"tv":2307.85,"id":9433864}],"tv":4058.07}]}
{"op":"mcm","clk":"4233579311","pt":1631536257207,"mc":[{"id":"1.187557653","rc":[{"batb":[[0,1.88,15.96],[1,1.87,7.98],[2,1.86,102.03]],"batl":[[1,1.98,28.85],[2,1.99,7.58]],"ltp":2.0,"tv":1750.22,"id":9632596},{"batb":[[1,1.81,30.71],[2,1.74,379.61]],"ltp":1.99,"tv":2307.85,"id":9433864}]}]}
{"op":"mcm","clk":"4233579816","pt":1631536263443,"mc":[{"id":"1.187557653","rc":[{"trd":[[1.89,526.08]],"ltp":1.89,"tv":1754.96,"id":9632596},{"trd":[[2.12,38.27]],"batl":[[0,2.12,11.73]],"ltp":2.12,"tv":2312.08,"id":9433864}],"tv":4067.04}]}
{"op":"mcm","clk":"4233580042","pt":1631536266043,"mc":[{"id":"1.187557653","rc":[{"batl":[[0,1.96,27.66]],"ltp":1.89,"tv":1754.96,"id":9632596},{"batl":[[0,2.72,264.63],[1,2.72,0]],"ltp":2.12,"tv":2312.08,"id":9433864}]}]}
{"op":"mcm","clk":"4233580154","pt":1631536267444,"mc":[{"id":"1.187557653","rc":[{"trd":[[1.88,9.48]],"batb":[[0,1.88,11.22]],"ltp":1.88,"tv":1764.44,"id":9632596}],"tv":4076.52}]}
{"op":"mcm","clk":"4233580315","pt":1631536269221,"mc":[{"id":"1.187557653","rc":[{"batl":[[0,1.96,41.08]],"ltp":1.88,"tv":1764.44,"id":9632596},{"batl":[[0,2.12,16.45],[1,2.7,173.09],[2,2.72,264.63]],"ltp":2.12,"tv":2312.08,"id":9433864}]}]}
{"op":"mcm","clk":"4233580332","pt":1631536269427,"mc":[{"id":"1.187557653","rc":[{"batl":[[1,2.72,264.63],[2,2.72,0]],"ltp":2.12,"tv":2312.08,"id":9433864}]}]}
{"op":"mcm","clk":"4233580434","pt":1631536270941,"mc":[{"id":"1.187557653","rc":[{"trd":[[1.89,529.71]],"ltp":1.89,"tv":1768.07,"id":9632596},{"trd":[[2.12,41.51]],"batl":[[0,2.12,13.21]],"ltp":2.12,"tv":2315.32,"id":9433864}],"tv":4083.39}]}
{"op":"mcm","clk":"4233580647","pt":1631536273656,"mc":[{"id":"1.187557653","rc":[{"batl":[[0,1.96,27.66]],"ltp":1.89,"tv":1768.07,"id":9632596},{"batl":[[0,2.72,264.63],[1,2.72,0]],"ltp":2.12,"tv":2315.32,"id":9433864}]}]}
{"op":"mcm","clk":"4233580972","pt":1631536277059,"mc":[{"id":"1.187557653","rc":[{"batl":[[0,1.94,7.96],[1,1.96,27.66],[2,1.98,28.85]],"ltp":1.89,"tv":1768.07,"id":9632596},{"batl":[[0,2.12,13.21],[1,2.72,264.63]],"ltp":2.12,"tv":2315.32,"id":9433864}]}]}
{"op":"mcm","clk":"4233581315","pt":1631536281149,"mc":[{"id":"1.187557653","rc":[{"batl":[[0,1.96,27.66],[1,1.98,28.85],[2,1.99,7.58]],"ltp":1.89,"tv":1768.07,"id":9632596},{"batl":[[0,2.72,264.63],[1,2.72,0]],"ltp":2.12,"tv":2315.32,"id":9433864}]}]}
{"op":"mcm","clk":"4233581542","pt":1631536284075,"mc":[{"id":"1.187557653","rc":[{"batl":[[0,1.94,7.96],[1,1.96,27.66],[2,1.98,28.85]],"ltp":1.89,"tv":1768.07,"id":9632596},{"batl":[[0,2.12,13.21],[1,2.72,264.63]],"ltp":2.12,"tv":2315.32,"id":9433864}]}]}
{"op":"mcm","clk":"4233582135","pt":1631536291167,"mc":[{"id":"1.187557653","rc":[{"batb":[[0,1.73,37.32],[1,1.01,113.7],[2,1.86,0]],"ltp":1.89,"tv":1768.07,"id":9632596},{"batb":[[0,1.81,30.71],[1,1.74,379.61],[2,1.19,1]],"batl":[[0,2.72,264.63],[1,2.72,0]],"ltp":2.12,"tv":2315.32,"id":9433864}]}]}
{"op":"mcm","clk":"4233582364","pt":1631536293673,"mc":[{"id":"1.187557653","rc":[{"batb":[[1,1.19,1],[2,1.01,113.7]],"ltp":2.12,"tv":2315.32,"id":9433864}]}]}
{"op":"mcm","clk":"4233582725","pt":1631536297803,"mc":[{"id":"1.187557653","rc":[{"batb":[[1,1.62,388.38],[2,1.19,1]],"batl":[[0,2.6,281.81]],"ltp":2.12,"tv":2315.32,"id":9433864}]}]}
{"op":"mcm","clk":"4233584099","pt":1631536313228,"mc":[{"id":"1.187557653","rc":[{"trd":[[2.18,4.58]],"batb":[[0,2.06,99.58],[1,1.73,37.32],[2,1.01,113.7]],"batl":[[0,2.16,11.95],[1,2.24,122.42]],"ltp":2.18,"tv":1772.65,"id":9632596},{"trd":[[1.84,28.51]],"batl":[[0,1.92,114.24],[1,1.96,76.52],[2,1.97,38.26]],"ltp":1.84,"tv":2320.75,"id":9433864}],"tv":4093.4}]}
{"op":"mcm","clk":"4233584191","pt":1631536314116,"mc":[{"id":"1.187557653","rc":[{"batb":[[1,2.02,45.61],[2,1.88,28.84]],"batl":[[0,2.16,81.39],[1,2.18,34.72],[2,2.2,34.72]],"ltp":2.18,"tv":1772.65,"id":9632596},{"batb":[[0,1.88,28.84],[1,1.86,14.58],[2,1.81,30.71]],"batl":[[1,1.96,15.3],[2,1.97,7.66]],"ltp":1.84,"tv":2320.75,"id":9433864}]}]}
{"op":"mcm","clk":"4233584254","pt":1631536314950,"mc":[{"id":"1.187557653","rc":[{"batl":[[0,2.16,25.83],[1,2.18,6.94],[2,2.2,6.94]],"ltp":2.18,"tv":1772.65,"id":9632596}]}]}
{"op":"mcm","clk":"4233585009","pt":1631536323352,"mc":[{"id":"1.187557653","rc":[{"batl":[[0,2.16,13.88]],"ltp":2.18,"tv":1772.65,"id":9632596},{"batl":[[0,1.92,104.16]],"ltp":1.84,"tv":2320.75,"id":9433864}]}]}
{"op":"mcm","clk":"4233585293","pt":1631536326135,"mc":[{"id":"1.187557653","rc":[{"batl":[[0,2.16,25.79]],"ltp":2.18,"tv":1772.65,"id":9632596},{"batl":[[0,1.92,119.44]],"ltp":1.84,"tv":2320.75,"id":9433864}]}]}
{"op":"mcm","clk":"4233585476","pt":1631536328276,"mc":[{"id":"1.187557653","rc":[{"batb":[[0,2.02,45.61],[1,1.88,28.84],[2,1.87,29.29]],"batl":[[0,2.16,11.91],[1,2.18,0],[2,2.2,0]],"ltp":2.18,"tv":1772.65,"id":9632596},{"batl":[[0,1.92,15.28],[1,2.5,299.95],[2,1.97,0]],"ltp":1.84,"tv":2320.75,"id":9433864}]}]}
{"op":"mcm","clk":"4233585532","pt":1631536328851,"mc":[{"id":"1.187557653","rc":[{"batb":[[0,1.87,29.29],[1,1.01,113.7],[2,1.87,0]],"ltp":2.18,"tv":1772.65,"id":9632596},{"batb":[[0,1.66,40.5],[1,1.62,388.38],[2,1.19,1]],"batl":[[0,2.5,299.95],[1,2.5,0]],"ltp":1.84,"tv":2320.75,"id":9433864}]}]}
{"op":"mcm","clk":"4233586490","pt":1631536339768,"mc":[{"id":"1.187557653","rc":[{"batb":[[1,1.19,1],[2,1.01,113.7]],"ltp":1.84,"tv":2320.75,"id":9433864}]}]}
{"op":"mcm","clk":"4233586617","pt":1631536341081,"mc":[{"id":"1.187557653","rc":[{"trd":[[2.42,4.13]],"batb":[[0,2.36,7.59],[1,2.34,17.1],[2,1.87,29.29]],"batl":[[0,2.42,3.62]],"ltp":2.42,"tv":1776.78,"id":9632596},{"trd":[[1.7,31.2]],"batb":[[0,1.72,31.52],[1,1.7,15.95],[2,1.66,168.88]],"batl":[[0,1.78,84.28],[1,1.79,42.14],[2,1.8,42.14]],"ltp":1.7,"tv":2326.63,"id":9433864}],"tv":4103.41}]}
{"op":"mcm","clk":"4233586717","pt":1631536342175,"mc":[{"id":"1.187557653","rc":[{"batb":[[2,2.24,33.97]],"batl":[[1,2.44,12.3],[2,2.46,6.14]],"ltp":2.42,"tv":1776.78,"id":9632596},{"batl":[[0,1.78,16.86],[1,1.79,8.42],[2,1.8,8.42]],"ltp":1.7,"tv":2326.63,"id":9433864}]}]}
{"op":"mcm","clk":"4233587491","pt":1631536351009,"mc":[{"id":"1.187557653","rc":[{"batb":[[0,2.34,17.1],[1,2.24,33.97],[2,2.08,42.51]],"batl":[[0,2.44,12.3],[1,2.46,6.14],[2,2.48,6.14]],"ltp":2.42,"tv":1776.78,"id":9632596},{"trd":[[1.72,7.23]],"batb":[[0,1.72,27.91]],"ltp":1.72,"tv":2333.86,"id":9433864}],"tv":4110.64}]}
{"op":"mcm","clk":"4233587760","pt":1631536353921,"mc":[{"id":"1.187557653","rc":[{"batb":[[0,2.36,11.83],[1,2.34,17.1],[2,2.24,33.97]],"ltp":2.42,"tv":1776.78,"id":9632596},{"batb":[[1,1.7,24.12]],"ltp":1.72,"tv":2333.86,"id":9433864}]}]}
{"op":"mcm","clk":"4233588114","pt":1631536358204,"mc":[{"id":"1.187557653","rc":[{"batb":[[0,2.24,33.97],[1,2.08,42.51],[2,1.01,113.7]],"ltp":2.42,"tv":1776.78,"id":9632596},{"batb":[[0,1.66,40.5],[1,1.57,49.87],[2,1.5,397.3]],"batl":[[0,2.3,337.41],[1,1.79,0],[2,1.8,0]],"ltp":1.72,"tv":2333.86,"id":9433864}]}]}
{"op":"mcm","clk":"4233588132","pt":1631536358415,"mc":[{"id":"1.187557653","rc":[{"batb":[[0,2.08,42.51],[1,1.01,113.7],[2,1.01,0]],"ltp":2.42,"tv":1776.78,"id":9632596},{"batb":[[0,1.57,49.87],[1,1.5,397.3],[2,1.19,1]],"ltp":1.72,"tv":2333.86,"id":9433864}]}]}
{"op":"mcm","clk":"4233588657","pt":1631536364942,"mc":[{"id":"1.187557653","rc":[{"batb":[[0,1.59,3.62],[1,1.57,49.87],[2,1.5,397.3]],"ltp":1.72,"tv":2333.86,"id":9433864}]}]}
{"op":"mcm","clk":"4233589075","pt":1631536369243,"mc":[{"id":"1.187557653","rc":[{"batl":[[0,1.72,8.55],[1,2.3,337.41]],"ltp":1.72,"tv":2333.86,"id":9433864}]}]}
{"op":"mcm","clk":"4233589169","pt":1631536370237,"mc":[{"id":"1.187557653","rc":[{"batb":[[0,2.6,76.92],[1,2.54,11.82],[2,2.52,5.9]],"batl":[[0,2.72,7.38],[1,2.84,108.1]],"ltp":2.42,"tv":1776.78,"id":9632596},{"trd":[[1.59,12.57],[1.62,42.83]],"batb":[[0,1.62,9.39],[1,1.6,16.95],[2,1.57,49.87]],"batl":[[0,1.81,29.95],[1,1.83,14.82],[2,2.3,337.41]],"ltp":1.62,"tv":2389.26,"id":9433864}],"tv":4166.05}]}
{"op":"mcm","clk":"4233589216","pt":1631536370656,"mc":[{"id":"1.187557653","rc":[{"batl":[[1,2.74,10.94],[2,2.76,5.48]],"ltp":2.42,"tv":1776.78,"id":9632596}]}]}
{"op":"mcm","clk":"4233589328","pt":1631536371651,"mc":[{"id":"1.187557653","rc":[{"batl":[[2,2.3,0]],"ltp":1.62,"tv":2389.26,"id":9433864}]}]}
{"op":"mcm","clk":"4233589722","pt":1631536375260,"mc":[{"id":"1.187557653","rc":[{"batl":[[2,2.1,394.06]],"ltp":1.62,"tv":2389.26,"id":9433864}]}]}
{"op":"mcm","clk":"4233589975","pt":1631536378068,"mc":[{"id":"1.187557653","rc":[{"batl":[[0,1.73,851.31],[1,1.81,29.95],[2,1.83,14.82]],"ltp":1.62,"tv":2389.26,"id":9433864}]}]}
{"op":"mcm","clk":"4233590124","pt":1631536379852,"mc":[{"id":"1.187557653","rc":[{"batl":[[0,2.74,10.94],[1,2.76,5.48],[2,2.78,5.48]],"ltp":2.42,"tv":1776.78,"id":9632596}]}]}
{"op":"mcm","clk":"4233590411","pt":1631536383048,"mc":[{"id":"1.187557653","rc":[{"batl":[[0,2.66,9.19],[1,2.74,10.94],[2,2.76,5.48]],"ltp":2.42,"tv":1776.78,"id":9632596},{"batl":[[0,1.64,16.32]],"ltp":1.62,"tv":2389.26,"id":9433864}]}]}
{"op":"mcm","clk":"4233591801","pt":1631536399664,"mc":[{"id":"1.187557653","rc":[{"trd":[[1.62,56.28]],"batb":[[0,1.62,2.67]],"ltp":1.62,"tv":2402.72,"id":9433864}],"tv":4179.5}]}
{"op":"mcm","clk":"4233592009","pt":1631536401890,"mc":[{"id":"1.187557653","rc":[{"trd":[[2.6,10.8]],"batb":[[0,2.6,71.52]],"ltp":2.6,"tv":1787.58,"id":9632596}],"tv":4190.3}]}
{"op":"mcm","clk":"4233592412","pt":1631536406577,"mc":[{"id":"1.187557653","rc":[{"batb":[[0,1.57,49.87],[1,1.51,57.99],[2,1.4,418.5]],"batl":[[1,2.1,394.06],[2,1.83,0]],"ltp":1.62,"tv":2402.72,"id":9433864}]}]}
{"op":"mcm","clk":"4233593128","pt":1631536415204,"mc":[{"id":"1.187557653","rc":[{"batb":[[0,2.26,33.3],[1,1.01,113.7],[2,2.52,0]],"ltp":2.6,"tv":1787.58,"id":9632596},{"batb":[[0,1.51,57.99],[1,1.4,418.5],[2,1.19,1]],"batl":[[0,2.1,394.06],[1,2.1,0]],"ltp":1.62,"tv":2402.72,"id":9433864}]}]}
{"op":"mcm","clk":"4233593966","pt":1631536424014,"mc":[{"id":"1.187557653","rc":[{"batb":[[0,1.64,15],[1,1.51,57.99],[2,1.4,418.5]],"ltp":1.62,"tv":2402.72,"id":9433864}]}]}
{"op":"mcm","clk":"4233594182","pt":1631536426113,"mc":[{"id":"1.187557653","rc":[{"batb":[[0,2.74,73],[1,2.7,55.56],[2,2.68,27.78]],"batl":[[0,2.84,9.6],[1,3,42.59]],"ltp":2.6,"tv":1787.58,"id":9632596},{"trd":[[1.64,48.82]],"batb":[[0,1.51,57.99],[1,1.5,85.18]],"batl":[[0,1.55,6.45],[1,1.58,17.6],[2,1.61,1930.14]],"ltp":1.64,"tv":2432.72,"id":9433864}],"tv":4220.3}]}
{"op":"mcm","clk":"4233594285","pt":1631536427214,"mc":[{"id":"1.187557653","rc":[{"batb":[[0,2.74,43.8],[1,2.7,33.34],[2,2.68,16.67]],"batl":[[1,2.9,51.72],[2,2.92,25.86]],"ltp":2.6,"tv":1787.58,"id":9632596},{"trd":[[1.55,12.9]],"batb":[[0,1.56,28.31],[1,1.54,17.61],[2,1.51,57.99]],"batl":[[0,1.58,17.6],[1,1.64,450.05],[2,1.74,31.16]],"ltp":1.55,"tv":2445.61,"id":9433864}],"tv":4233.2}]}
{"op":"mcm","clk":"4233594297","pt":1631536427318,"mc":[{"id":"1.187557653","rc":[{"batb":[[1,2.7,11.12],[2,2.68,5.56]],"batl":[[1,2.9,10.34],[2,2.92,5.18]],"ltp":2.6,"tv":1787.58,"id":9632596}]}]}
{"op":"mcm","clk":"4233594669","pt":1631536431139,"mc":[{"id":"1.187557653","rc":[{"batl":[[2,1.67,123.11]],"ltp":1.55,"tv":2445.61,"id":9433864}]}]}
{"op":"mcm","clk":"4233594684","pt":1631536431350,"mc":[{"id":"1.187557653","rc":[{"batl":[[2,1.74,31.16]],"ltp":1.55,"tv":2445.61,"id":9433864}]}]}
{"op":"mcm","clk":"4233595599","pt":1631536441458,"mc":[{"id":"1.187557653","rc":[{"trd":[[1.58,16.8]],"batl":[[0,1.58,12.6]],"ltp":1.58,"tv":2455.61,"id":9433864}],"tv":4243.2}]}
{"op":"mcm","clk":"4233595807","pt":1631536443441,"mc":[{"id":"1.187557653","rc":[{"batb":[[0,1.51,57.99],[1,1.5,85.18],[2,1.46,66.28]],"batl":[[2,2.1,394.06]],"ltp":1.58,"tv":2455.61,"id":9433864}]}]}
{"op":"mcm","clk":"4233595969","pt":1631536445258,"mc":[{"id":"1.187557653","rc":[{"batb":[[0,2.6,22.51],[1,2.42,27.61],[2,1.01,113.7]],"ltp":2.6,"tv":1787.58,"id":9632596},{"batb":[[1,1.46,66.28],[2,1.4,418.5]],"batl":[[0,2.1,394.06],[1,1.64,0],[2,2.1,0]],"ltp":1.58,"tv":2455.61,"id":9433864}]}]}
{"op":"mcm","clk":"4233595997","pt":1631536445575,"mc":[{"id":"1.187557653","rc":[{"batb":[[0,2.42,27.61],[1,1.01,113.7],[2,1.01,0]],"ltp":2.6,"tv":1787.58,"id":9632596},{"batb":[[0,1.46,66.28],[1,1.4,418.5],[2,1.19,1]],"ltp":1.58,"tv":2455.61,"id":9433864}]}]}
{"op":"mcm","clk":"4233596765","pt":1631536454151,"mc":[{"id":"1.187557653","rc":[{"batb":[[1,1.19,1],[2,1.01,113.7]],"ltp":1.58,"tv":2455.61,"id":9433864}]}]}
{"op":"mcm","clk":"4233596904","pt":1631536455565,"mc":[{"id":"1.187557653","rc":[{"trd":[[2.96,3.38]],"batb":[[0,2.88,6.7],[1,2.84,10.56],[2,2.82,76.2]],"batl":[[0,2.96,1.99],[1,3.15,60.63]],"ltp":2.96,"tv":1790.96,"id":9632596},{"trd":[[1.51,6.62]],"batb":[[0,1.51,35.91],[1,1.49,18.2],[2,1.46,66.28]],"batl":[[0,1.58,430.14],[1,1.68,32.27],[2,1.7,15.95]],"ltp":1.51,"tv":2462.23,"id":9433864}],"tv":4253.2}]}
{"op":"mcm","clk":"4233597011","pt":1631536456761,"mc":[{"id":"1.187557653","rc":[{"batl":[[2,3.4,2.94]],"ltp":2.96,"tv":1790.96,"id":9632596},{"batb":[[2,1.48,20.28]],"ltp":1.51,"tv":2462.23,"id":9433864}]}]}
{"op":"mcm","clk":"4233597378","pt":1631536460269,"mc":[{"id":"1.187557653","rc":[{"batl":[[1,1.63,138.88],[2,1.68,32.27]],"ltp":1.51,"tv":2462.23,"id":9433864}]}]}
{"op":"mcm","clk":"4233597396","pt":1631536460482,"mc":[{"id":"1.187557653","rc":[{"batl":[[1,1.68,32.27],[2,1.7,15.95]],"ltp":1.51,"tv":2462.23,"id":9433864}]}]}
{"op":"mcm","clk":"4233597863","pt":1631536465598,"mc":[{"id":"1.187557653","rc":[{"batb":[[0,2.84,10.56],[1,2.82,76.2],[2,2.8,5.28]],"batl":[[0,3.15,60.63],[1,3.4,2.94],[2,3.4,0]],"ltp":2.96,"tv":1790.96,"id":9632596}]}]}
{"op":"mcm","clk":"4233598202","pt":1631536468873,"mc":[{"id":"1.187557653","rc":[{"batb":[[0,2.88,10.17],[1,2.84,10.56],[2,2.82,76.2]],"batl":[[0,3,3.85],[1,3.15,60.63],[2,3.4,2.94]],"ltp":2.96,"tv":1790.96,"id":9632596},{"batb":[[1,1.5,7.71],[2,1.49,18.2]],"ltp":1.51,"tv":2462.23,"id":9433864}]}]}
{"op":"mcm","clk":"4233598572","pt":1631536472611,"mc":[{"id":"1.187557653","rc":[{"batb":[[0,1.5,7.71],[1,1.48,20.28],[2,1.47,10.14]],"batl":[[1,1.95,443.02],[2,1.7,0]],"ltp":1.51,"tv":2462.23,"id":9433864}]}]}
{"op":"mcm","clk":"4233599136","pt":1631536479097,"mc":[{"id":"1.187557653","rc":[{"batb":[[0,2.6,22.68],[1,1.01,113.7],[2,2.82,0]],"ltp":2.96,"tv":1790.96,"id":9632596},{"batb":[[0,1.42,73.89],[1,1.34,431.32],[2,1.19,1]],"batl":[[0,1.95,443.02],[1,1.95,0]],"ltp":1.51,"tv":2462.23,"id":9433864}]}]}
{"op":"mcm","clk":"4233599824","pt":1631536487120,"mc":[{"id":"1.187557653","rc":[{"batb":[[0,3,5.04],[1,2.96,10.14],[2,2.94,5.06]],"ltp":2.96,"tv":1790.96,"id":9632596},{"batb":[[0,1.48,36.64],[1,1.47,15.12],[2,1.46,18.57]],"batl":[[0,1.49,6.71],[1,1.5,10.07],[2,1.64,33.06]],"ltp":1.51,"tv":2462.23,"id":9433864}]}]}
{"op":"mcm","clk":"4233599901","pt":1631536488089,"mc":[{"id":"1.187557653","rc":[{"batl":[[0,3.2,9.38],[1,3.25,4.68],[2,3.3,4.68]],"ltp":2.96,"tv":1790.96,"id":9632596}]}]}
{"op":"mcm","clk":"4233601064","pt":1631536501078,"mc":[{"id":"1.187557653","rc":[{"batb":[[0,2.9,42.34],[1,2.76,19.08],[2,1.01,113.7]],"ltp":2.96,"tv":1790.96,"id":9632596},{"batb":[[0,1.42,73.89],[1,1.39,80.58],[2,1.34,431.32]],"batl":[[0,1.95,443.02],[1,1.5,0],[2,1.64,0]],"ltp":1.51,"tv":2462.23,"id":9433864}]}]}
{"op":"mcm","clk":"4233601110","pt":1631536501472,"mc":[{"id":"1.187557653","rc":[{"batb":[[0,2.76,19.08],[1,1.01,113.7],[2,1.01,0]],"ltp":2.96,"tv":1790.96,"id":9632596},{"batb":[[0,1.39,80.58],[1,1.34,431.32],[2,1.19,1]],"ltp":1.51,"tv":2462.23,"id":9433864}]}]}
{"op":"mcm","clk":"4233601366","pt":1631536504151,"mc":[{"id":"1.187557653","rc":[{"batl":[[0,4.2,674.24]],"ltp":2.96,"tv":1790.96,"id":9632596}]}]}
{"op":"mcm","clk":"4233601949","pt":1631536509888,"mc":[{"id":"1.187557653","rc":[{"batl":[[0,3,0.01]],"ltp":2.96,"tv":1790.96,"id":9632596}]}]}
{"op":"mcm","clk":"4233602775","pt":1631536518288,"mc":[{"id":"1.187557653","rc":[{"trd":[[3,26.27]],"batb":[[0,3.1,6.44],[1,3,104.56],[2,2.86,43.35]],"batl":[[0,3.2,6.1],[1,3.3,45.44],[2,3.35,69.22]],"ltp":3.0,"tv":1790.98,"id":9632596},{"batb":[[0,1.46,37.14],[1,1.44,18.82],[2,1.39,80.58]],"batl":[[0,1.47,100.25],[1,1.48,6.76],[2,1.49,20.14]],"ltp":1.51,"tv":2462.23,"id":9433864}],"tv":4253.22}]}
{"op":"mcm","clk":"4233602809","pt":1631536518705,"mc":[{"id":"1.187557653","rc":[{"batl":[[1,3.3,9.08],[2,3.35,51.04]],"ltp":3.0,"tv":1790.98,"id":9632596}]}]}
{"op":"mcm","clk":"4233603818","pt":1631536529812,"mc":[{"id":"1.187557653","rc":[{"trd":[[1.46,6.9]],"batb":[[0,1.46,33.69]],"ltp":1.46,"tv":2469.13,"id":9433864}],"tv":4260.12}]}
{"op":"mcm","clk":"4233606473","pt":1631536557380,"mc":[{"id":"1.187557653","rc":[{"trd":[[1.46,74.28]],"batb":[[0,1.44,18.82],[1,1.39,80.58],[2,1.36,90.54]],"batl":[[0,1.46,110.95],[1,1.47,100.25],[2,1.48,6.76]],"ltp":1.46,"tv":2536.52,"id":9433864}],"tv":4327.5}]}
{"op":"mcm","clk":"4233610782","pt":1631536604715,"mc":[{"id":"1.187557653","rc":[{"batb":[[0,1.39,80.58],[1,1.36,90.54],[2,1.34,431.32]],"ltp":1.46,"tv":2536.52,"id":9433864}]}]}
{"op":"mcm","clk":"4233611185","pt":1631536609242,"mc":[{"id":"1.187557653","rc":[{"batb":[[0,2.86,43.35],[1,1.01,113.7],[2,2.86,0]],"ltp":3.0,"tv":1790.98,"id":9632596},{"batb":[[0,1.36,90.54],[1,1.34,431.32],[2,1.19,1]],"batl":[[1,1.95,443.02],[2,1.48,0]],"ltp":1.46,"tv":2536.52,"id":9433864}]}]}
{"op":"mcm","clk":"4233611350","pt":1631536611160,"mc":[{"id":"1.187557653","rc":[{"batb":[[0,1.4,191.29],[1,1.36,90.54],[2,1.34,431.32]],"ltp":1.46,"tv":2536.52,"id":9433864}]}]}
{"op":"mcm","clk":"4233611369","pt":1631536611321,"mc":[{"id":"1.187557653","rc":[{"batb":[[0,1.36,90.54],[1,1.34,431.32],[2,1.19,1]],"ltp":1.46,"tv":2536.52,"id":9433864}]}]}
{"op":"mcm","clk":"4233612946","pt":1631536625777,"mc":[{"id":"1.187557653","rc":[{"batb":[[0,3,26.08],[1,2.96,9.72],[2,2.86,43.35]],"batl":[[0,3.45,2.9]],"ltp":3.0,"tv":1790.98,"id":9632596},{"trd":[[1.46,296.21]],"batb":[[0,1.49,36.39],[1,1.48,7.38],[2,1.47,18.45]],"batl":[[0,1.5,52.15],[1,1.65,32.86],[2,1.67,16.23]],"ltp":1.46,"tv":2758.44,"id":9433864}],"tv":4549.43}]}
{"op":"mcm","clk":"4233613157","pt":1631536626894,"mc":[{"id":"1.187557653","rc":[{"batb":[[2,2.94,10.2]],"ltp":3.0,"tv":1790.98,"id":9632596},{"batl":[[0,1.5,58.82]],"ltp":1.46,"tv":2758.44,"id":9433864}]}]}
{"op":"mcm","clk":"4233613295","pt":1631536628596,"mc":[{"id":"1.187557653","rc":[{"trd":[[1.49,4]],"batb":[[0,1.49,34.39]],"ltp":1.49,"tv":2762.44,"id":9433864}],"tv":4553.43}]}
{"op":"mcm","clk":"4233613514","pt":1631536631770,"mc":[{"id":"1.187557653","rc":[{"batl":[[0,3.4,362.08],[1,3.45,2.9]],"ltp":3.0,"tv":1790.98,"id":9632596}]}]}
{"op":"mcm","clk":"4233613820","pt":1631536635713,"mc":[{"id":"1.187557653","rc":[{"batb":[[1,2.94,10.2],[2,2.92,5.1]],"ltp":3.0,"tv":1790.98,"id":9632596},{"batb":[[1,1.47,18.45],[2,1.45,148.84]],"ltp":1.49,"tv":2762.44,"id":9433864}]}]}
{"op":"mcm","clk":"4233614084","pt":1631536639218,"mc":[{"id":"1.187557653","rc":[{"batb":[[0,2.86,43.35],[1,2.74,19.66],[2,1.01,113.7]],"ltp":3.0,"tv":1790.98,"id":9632596},{"batb":[[0,1.43,72.47],[1,1.39,80.92],[2,1.36,90.54]],"batl":[[0,1.95,443.02],[1,1.65,0],[2,1.67,0]],"ltp":1.49,"tv":2762.44,"id":9433864}]}]}
{"op":"mcm","clk":"4233614114","pt":1631536639593,"mc":[{"id":"1.187557653","rc":[{"batb":[[0,2.74,19.66],[1,1.01,113.7],[2,1.01,0]],"ltp":3.0,"tv":1790.98,"id":9632596},{"batb":[[0,1.39,80.92],[1,1.34,431.32],[2,1.19,1]],"ltp":1.49,"tv":2762.44,"id":9433864}]}]}
{"op":"mcm","clk":"4233614319","pt":1631536642209,"mc":[{"id":"1.187557653","rc":[{"batl":[[0,1.61,2009.74],[1,1.95,443.02]],"ltp":1.49,"tv":2762.44,"id":9433864}]}]}
{"op":"mcm","clk":"4233614335","pt":1631536642414,"mc":[{"id":"1.187557653","rc":[{"batl":[[0,1.95,443.02],[1,1.95,0]],"ltp":1.49,"tv":2762.44,"id":9433864}]}]}
{"op":"mcm","clk":"4233614597","pt":1631536646011,"mc":[{"id":"1.187557653","rc":[{"batb":[[0,2.88,78.1],[1,2.74,19.66],[2,1.01,113.7]],"batl":[[0,3,3.8],[1,3.05,65.58],[2,3.35,2.99]],"ltp":3.0,"tv":1790.98,"id":9632596},{"trd":[[1.49,4.44]],"batb":[[0,1.51,35.91],[1,1.5,7.59],[2,1.49,38.34]],"batl":[[0,1.68,32.27],[1,1.7,15.96],[2,1.95,443.02]],"ltp":1.49,"tv":2762.89,"id":9433864}],"tv":4553.87}]}
{"op":"mcm","clk":"4233614671","pt":1631536647004,"mc":[{"id":"1.187557653","rc":[{"batb":[[1,2.8,10.72],[2,2.78,5.36]],"ltp":3.0,"tv":1790.98,"id":9632596},{"batl":[[0,1.52,6.58],[1,1.68,32.27],[2,1.7,15.96]],"ltp":1.49,"tv":2762.89,"id":9433864}]}]}
{"op":"mcm","clk":"4233616623","pt":1631536671272,"mc":[{"id":"1.187557653","rc":[{"batb":[[0,2.74,19.66],[1,2.62,21.92],[2,1.01,113.7]],"ltp":3.0,"tv":1790.98,"id":9632596},{"batb":[[1,1.49,18.2],[2,1.47,64.77]],"batl":[[0,1.68,32.27],[1,1.7,15.96],[2,1.95,443.02]],"ltp":1.49,"tv":2762.89,"id":9433864}]}]}
{"op":"mcm","clk":"4233616664","pt":1631536671658,"mc":[{"id":"1.187557653","rc":[{"batb":[[0,2.62,21.92],[1,1.01,113.7],[2,1.01,0]],"ltp":3.0,"tv":1790.98,"id":9632596},{"batb":[[0,1.43,71.8],[1,1.34,431.32],[2,1.19,1]],"batl":[[0,1.95,443.02],[1,1.7,0],[2,1.95,0]],"ltp":1.49,"tv":2762.89,"id":9433864}]}]}
{"op":"mcm","clk":"4233616868","pt":1631536674266,"mc":[{"id":"1.187557653","rc":[{"batl":[[0,1.67,396.46],[1,1.95,443.02]],"ltp":1.49,"tv":2762.89,"id":9433864}]}]}
{"op":"mcm","clk":"4233616890","pt":1631536674494,"mc":[{"id":"1.187557653","rc":[{"batl":[[0,1.95,443.02],[1,1.95,0]],"ltp":1.49,"tv":2762.89,"id":9433864}]}]}
{"op":"mcm","clk":"4233617120","pt":1631536676078,"mc":[{"id":"1.187557653","rc":[{"batb":[[0,1.43,71.88]],"ltp":1.49,"tv":2762.89,"id":9433864}]}]}
{"op":"mcm","clk":"4233618028","pt":1631536686213,"mc":[{"id":"1.187557653","rc":[{"batb":[[1,1.19,1],[2,1.01,113.7]],"ltp":1.49,"tv":2762.89,"id":9433864}]}]}
{"op":"mcm","clk":"4233618166","pt":1631536687861,"mc":[{"id":"1.187557653","rc":[{"batl":[[0,2.92,9.37],[1,2.96,77.7],[2,2.98,5.06]],"ltp":3.0,"tv":1790.98,"id":9632596},{"batb":[[0,1.54,35.21],[1,1.52,17.91],[2,1.43,71.8]],"batl":[[0,1.56,166.46],[1,1.71,31.72],[2,1.73,15.67]],"ltp":1.49,"tv":2762.89,"id":9433864}]}]}
{"op":"mcm","clk":"4233618254","pt":1631536688822,"mc":[{"id":"1.187557653","rc":[{"batb":[[0,2.74,10.94],[1,2.72,5.48],[2,2.7,5.48]],"ltp":3.0,"tv":1790.98,"id":9632596},{"trd":[[1.54,13.08]],"batb":[[0,1.54,28.67],[1,1.52,17.83],[2,1.5,59.25]],"ltp":1.54,"tv":2775.96,"id":9433864}],"tv":4566.95}]}
{"op":"mcm","clk":"4233618506","pt":1631536691518,"mc":[{"id":"1.187557653","rc":[{"batb":[[0,1.54,28.75]],"ltp":1.54,"tv":2775.96,"id":9433864}]}]}
{"op":"mcm","clk":"4233619282","pt":1631536700006,"mc":[{"id":"1.187557653","rc":[{"batb":[[0,2.62,21.92],[1,2.52,24.43],[2,1.01,113.7]],"ltp":3.0,"tv":1790.98,"id":9632596},{"batl":[[0,1.71,31.72],[1,1.73,15.67],[2,1.95,443.02]],"ltp":1.54,"tv":2775.96,"id":9433864}]}]}
{"op":"mcm","clk":"4233619328","pt":1631536700492,"mc":[{"id":"1.187557653","rc":[{"batb":[[0,2.52,24.43],[1,1.01,113.7],[2,1.01,0]],"ltp":3.0,"tv":1790.98,"id":9632596},{"batb":[[0,1.47,64.76],[1,1.38,415.85],[2,1.19,1]],"batl":[[0,1.95,443.02],[1,1.73,0],[2,1.95,0]],"ltp":1.54,"tv":2775.96,"id":9433864}]}]}
{"op":"mcm","clk":"4233620923","pt":1631536717746,"mc":[{"id":"1.187557653","rc":[{"batb":[[0,2.88,80.1],[1,2.78,71.94],[2,2.52,24.43]],"batl":[[0,3,3.73],[1,3.1,49.63]],"ltp":3.0,"tv":1790.98,"id":9632596},{"trd":[[1.54,13.24]],"batb":[[0,1.51,35.91],[1,1.5,7.46],[2,1.49,18.2]],"batl":[[0,1.52,6.5],[1,1.55,19.36],[2,1.56,9.68]],"ltp":1.54,"tv":2776.12,"id":9433864}],"tv":4567.11}]}
{"op":"mcm","clk":"4233621020","pt":1631536718736,"mc":[{"id":"1.187557653","rc":[{"batb":[[2,2.72,19.75]],"batl":[[2,3.35,2.99]],"ltp":3.0,"tv":1790.98,"id":9632596},{"batb":[[2,1.49,38.34]],"ltp":1.54,"tv":2776.12,"id":9433864}]}]}
{"op":"mcm","clk":"4233621174","pt":1631536720515,"mc":[{"id":"1.187557653","rc":[{"trd":[[1.52,13]],"batl":[[0,1.55,19.36],[1,1.56,9.68],[2,1.57,9.68]],"ltp":1.52,"tv":2789.12,"id":9433864}],"tv":4580.11}]}
{"op":"mcm","clk":"4233622214","pt":1631536732178,"mc":[{"id":"1.187557653","rc":[{"batb":[[1,2.72,19.75],[2,2.62,22.09]],"batl":[[2,3.35,0]],"ltp":3.0,"tv":1790.98,"id":9632596},{"batb":[[2,1.49,18.2]],"batl":[[0,1.68,32.27],[1,1.7,15.96],[2,1.95,443.02]],"ltp":1.52,"tv":2789.12,"id":9433864}]}]}
{"op":"mcm","clk":"4233622270","pt":1631536732765,"mc":[{"id":"1.187557653","rc":[{"batb":[[0,2.62,22.09],[1,1.01,113.7],[2,2.62,0]],"ltp":3.0,"tv":1790.98,"id":9632596},{"batb":[[0,1.43,71.88],[1,1.38,415.85],[2,1.19,1]],"batl":[[0,1.95,443.02],[1,1.7,0],[2,1.95,0]],"ltp":1.52,"tv":2789.12,"id":9433864}]}]}
{"op":"mcm","clk":"4233623245","pt":1631536743279,"mc":[{"id":"1.187557653","rc":[{"batb":[[1,2.38,28.54],[2,1.01,113.7]],"batl":[[0,2.92,8.9],[1,2.94,10.2],[2,2.96,5.1]],"ltp":3.0,"tv":1790.98,"id":9632596},{"batb":[[0,1.53,35.44],[1,1.51,17.95],[2,1.5,58.91]],"batl":[[0,1.56,172.79],[1,1.71,31.72],[2,1.73,15.67]],"ltp":1.52,"tv":2789.12,"id":9433864}]}]}
{"op":"mcm","clk":"4233623307","pt":1631536743903,"mc":[{"id":"1.187557653","rc":[{"trd":[[1.53,13.08]],"batb":[[0,1.53,28.9]],"batl":[[1,1.58,18.98],[2,1.59,9.5]],"ltp":1.53,"tv":2802.2,"id":9433864}],"tv":4593.18}]}
{"op":"mcm","clk":"4233623515","pt":1631536745790,"mc":[{"id":"1.187557653","rc":[{"trd":[[1.53,17.08]],"batb":[[0,1.53,26.9]],"ltp":1.53,"tv":2806.2,"id":9433864}],"tv":4597.18}]}
{"op":"mcm","clk":"4233625096","pt":1631536764415,"mc":[{"id":"1.187557653","rc":[{"trd":[[2.78,0.01]],"ltp":2.78,"tv":1790.99,"id":9632596},{"trd":[[1.56,0.02]],"batl":[[0,1.56,172.77]],"ltp":1.56,"tv":2806.22,"id":9433864}],"tv":4597.21}]}
{"op":"mcm","clk":"4233626414","pt":1631536777873,"mc":[{"id":"1.187557653","rc":[{"batb":[[0,2.38,28.54],[1,1.01,113.7],[2,1.01,0]],"ltp":2.78,"tv":1790.99,"id":9632596},{"batb":[[0,1.45,68.2],[1,1.38,415.85],[2,1.23,2]],"batl":[[0,1.95,443.02],[1,1.58,0],[2,1.59,0]],"ltp":1.56,"tv":2806.22,"id":9433864}]}]}
{"op":"mcm","clk":"4233626614","pt":1631536779866,"mc":[{"id":"1.187557653","rc":[{"batb":[[0,1.45,68.9]],"ltp":1.56,"tv":2806.22,"id":9433864}]}]}
{"op":"mcm","clk":"4233626692","pt":1631536781048,"mc":[{"id":"1.187557653","rc":[{"batb":[[0,2.36,28.95]],"ltp":2.78,"tv":1790.99,"id":9632596},{"batb":[[0,1.45,68.56]],"ltp":1.56,"tv":2806.22,"id":9433864}]}]}
{"op":"mcm","clk":"4233626760","pt":1631536781984,"mc":[{"id":"1.187557653","rc":[{"trd":[[1.56,1.41]],"batb":[[0,1.45,67.86]],"batl":[[0,1.53,12.42],[1,1.95,443.02]],"ltp":1.56,"tv":2807.62,"id":9433864}],"tv":4598.61}]}
{"op":"mcm","clk":"4233627304","pt":1631536788688,"mc":[{"id":"1.187557653","rc":[{"batl":[[0,1.95,443.02],[1,1.95,0]],"ltp":1.56,"tv":2807.62,"id":9433864}]}]}
{"op":"mcm","clk":"4233627955","pt":1631536797916,"mc":[{"id":"1.187557653","rc":[{"batb":[[0,3,37.84],[1,2.92,30.82],[2,2.9,15.41]],"ltp":2.78,"tv":1790.99,"id":9632596},{"batb":[[0,1.48,36.64],[1,1.47,12.92],[2,1.46,18.57]],"batl":[[0,1.49,6.71],[1,1.5,75.7],[2,1.65,32.86]],"ltp":1.56,"tv":2807.62,"id":9433864}]}]}
{"op":"mcm","clk":"4233628043","pt":1631536798913,"mc":[{"id":"1.187557653","rc":[{"batb":[[1,2.92,10.28],[2,2.9,5.14]],"batl":[[0,3.15,9.52],[1,3.2,4.76],[2,3.25,4.76]],"ltp":2.78,"tv":1790.99,"id":9632596}]}]}
{"op":"mcm","clk":"4233629003","pt":1631536809912,"mc":[{"id":"1.187557653","rc":[{"batb":[[0,2.56,23.6],[1,1.01,113.7],[2,2.9,0]],"ltp":2.78,"tv":1790.99,"id":9632596},{"batb":[[0,1.41,77.57],[1,1.38,415.85],[2,1.23,2]],"batl":[[0,1.95,443.02],[1,1.5,0],[2,1.65,0]],"ltp":1.56,"tv":2807.62,"id":9433864}]}]}
{"op":"mcm","clk":"4233630788","pt":1631536831246,"mc":[{"id":"1.187557653","rc":[{"batb":[[0,2.78,5.44],[1,2.56,23.6],[2,1.01,113.7]],"batl":[[0,2.88,69.44],[1,2.92,51.36],[2,2.94,25.68]],"ltp":2.78,"tv":1790.99,"id":9632596},{"batb":[[0,1.55,34.98],[1,1.54,12.07],[2,1.53,17.72]],"batl":[[0,1.58,148.78],[1,1.73,31.35],[2,1.75,15.49]],"ltp":1.56,"tv":2807.62,"id":9433864}]}]}
{"op":"mcm","clk":"4233630864","pt":1631536832138,"mc":[{"id":"1.187557653","rc":[{"batb":[[1,2.7,55.56],[2,2.68,27.78]],"batl":[[1,2.92,10.28],[2,2.94,5.14]],"ltp":2.78,"tv":1790.99,"id":9632596},{"trd":[[1.55,25.8]],"batb":[[0,1.55,28.53],[2,1.53,73.45]],"ltp":1.55,"tv":2820.51,"id":9433864}],"tv":4611.51}]}
{"op":"mcm","clk":"4233630928","pt":1631536833037,"mc":[{"id":"1.187557653","rc":[{"batb":[[1,2.7,11.12],[2,2.68,5.56]],"ltp":2.78,"tv":1790.99,"id":9632596}]}]}
{"op":"mcm","clk":"4233632037","pt":1631536848280,"mc":[{"id":"1.187557653","rc":[{"batb":[[0,1.54,12.07],[1,1.53,55.73],[2,1.5,79.93]],"batl":[[1,1.95,443.02],[2,1.75,0]],"ltp":1.55,"tv":2820.51,"id":9433864}]}]}
{"op":"mcm","clk":"4233632242","pt":1631536850890,"mc":[{"id":"1.187557653","rc":[{"trd":[[2.78,0.71]],"batb":[[0,2.78,4.74]],"ltp":2.78,"tv":1791.69,"id":9632596},{"trd":[[1.57,11.24]],"ltp":1.57,"tv":2821.75,"id":9433864}],"tv":4613.45}]}
{"op":"mcm","clk":"4233632271","pt":1631536851302,"mc":[{"id":"1.187557653","rc":[{"batl":[[0,1.55,2.32],[1,1.58,148.78],[2,1.95,443.02]],"ltp":1.57,"tv":2821.75,"id":9433864}]}]}
{"op":"mcm","clk":"4233632463","pt":1631536853904,"mc":[{"id":"1.187557653","rc":[{"batb":[[0,2.56,23.6],[1,2.3,31.55],[2,1.01,113.7]],"ltp":2.78,"tv":1791.69,"id":9632596},{"batb":[[0,1.53,55.73],[1,1.46,66.36],[2,1.38,415.85]],"batl":[[1,1.95,443.02],[2,1.95,0]],"ltp":1.57,"tv":2821.75,"id":9433864}]}]}
{"op":"mcm","clk":"4233632510","pt":1631536854374,"mc":[{"id":"1.187557653","rc":[{"batb":[[0,2.3,31.55],[1,1.01,113.7],[2,1.01,0]],"ltp":2.78,"tv":1791.69,"id":9632596},{"batb":[[0,1.46,66.36],[1,1.38,415.85],[2,1.23,2]],"ltp":1.57,"tv":2821.75,"id":9433864}]}]}
{"op":"mcm","clk":"4233635552","pt":1631536882827,"mc":[{"id":"1.187557653","rc":[{"trd":[[1.55,27.2]],"batl":[[0,1.55,1.62]],"ltp":1.55,"tv":2823.15,"id":9433864}],"tv":4614.85}]}
{"op":"mcm","clk":"4233635664","pt":1631536884238,"mc":[{"id":"1.187557653","rc":[{"batb":[[0,3,4.23],[1,2.94,51.02],[2,2.92,25.52]],"batl":[[0,3.1,5.2]],"ltp":2.78,"tv":1791.69,"id":9632596},{"batb":[[1,1.44,156.14],[2,1.38,415.85]],"batl":[[0,1.5,15.13],[1,1.52,2113.14],[2,1.55,1.62]],"ltp":1.55,"tv":2823.15,"id":9433864}]}]}
{"op":"mcm","clk":"4233635764","pt":1631536885270,"mc":[{"id":"1.187557653","rc":[{"batb":[[1,2.94,10.2],[2,2.92,5.1]],"batl":[[1,3.2,46.88],[2,3.25,23.44]],"ltp":2.78,"tv":1791.69,"id":9632596},{"batb":[[0,1.49,36.39],[1,1.47,18.45],[2,1.46,66.36]],"batl":[[1,1.55,1.62],[2,1.58,557.91]],"ltp":1.55,"tv":2823.15,"id":9433864}]}]}
{"op":"mcm","clk":"4233635785","pt":1631536885530,"mc":[{"id":"1.187557653","rc":[{"batl":[[1,3.2,9.38],[2,3.25,4.68]],"ltp":2.78,"tv":1791.69,"id":9632596}]}]}
{"op":"mcm","clk":"4233637005","pt":1631536901687,"mc":[{"id":"1.187557653","rc":[{"batb":[[0,1.46,66.36],[1,1.44,156.14],[2,1.41,77.4]],"ltp":1.55,"tv":2823.15,"id":9433864}]}]}
{"op":"mcm","clk":"4233637858","pt":1631536912080,"mc":[{"id":"1.187557653","rc":[{"batb":[[0,2.5,24.85],[1,1.01,113.7],[2,2.92,0]],"ltp":2.78,"tv":1791.69,"id":9632596},{"batb":[[0,1.41,77.4],[1,1.38,415.85],[2,1.23,2]],"batl":[[0,1.55,1.62],[1,1.95,443.02],[2,1.58,0]],"ltp":1.55,"tv":2823.15,"id":9433864}]}]}
{"op":"mcm","clk":"4233638307","pt":1631536917279,"mc":[{"id":"1.187557653","rc":[{"batb":[[0,3.25,5.8],[1,3.2,71.55],[2,3.15,63.5]],"batl":[[0,3.35,5.44],[1,3.55,72.93]],"ltp":2.78,"tv":1791.69,"id":9632596},{"batb":[[1,1.23,2],[2,1.19,1]],"batl":[[0,1.46,6.85],[1,1.47,20.4],[2,1.48,10.2]],"ltp":1.55,"tv":2823.15,"id":9433864}]}]}
{"op":"mcm","clk":"4233638366","pt":1631536918106,"mc":[{"id":"1.187557653","rc":[{"batl":[[1,3.4,44.12],[2,3.45,22.06]],"ltp":2.78,"tv":1791.69,"id":9632596},{"batb":[[0,1.44,37.65],[1,1.42,19.09],[2,1.41,77.4]],"ltp":1.55,"tv":2823.15,"id":9433864}]}]}
{"op":"mcm","clk":"4233638384","pt":1631536918318,"mc":[{"id":"1.187557653","rc":[{"batl":[[1,3.4,8.82],[2,3.45,4.42]],"ltp":2.78,"tv":1791.69,"id":9632596}]}]}
{"op":"mcm","clk":"4233639797","pt":1631536934531,"mc":[{"id":"1.187557653","rc":[{"batb":[[0,1.41,77.4],[1,1.37,87.45],[2,1.31,442.37]],"ltp":1.55,"tv":2823.15,"id":9433864}]}]}
{"op":"mcm","clk":"4233640123","pt":1631536938241,"mc":[{"id":"1.187557653","rc":[{"batb":[[0,2.76,19.16],[1,1.01,113.7],[2,3.15,0]],"ltp":2.78,"tv":1791.69,"id":9632596},{"batb":[[0,1.37,87.45],[1,1.31,442.37],[2,1.23,2]],"batl":[[0,1.55,1.62],[1,1.95,443.02],[2,1.48,0]],"ltp":1.55,"tv":2823.15,"id":9433864}]}]}
{"op":"mcm","clk":"4233641068","pt":1631536949230,"mc":[{"id":"1.187557653","rc":[{"batl":[[1,1.7,0.01]],"ltp":1.55,"tv":2823.15,"id":9433864}]}]}
{"op":"mcm","clk":"4233641147","pt":1631536950062,"mc":[{"id":"1.187557653","rc":[{"batb":[[0,3.4,5.77],[1,3.3,45.44],[2,3.25,22.72]],"batl":[[0,3.5,4.34],[1,3.7,63.2]],"ltp":2.78,"tv":1791.69,"id":9632596},{"batl":[[0,1.42,125.18],[1,1.44,6.94],[2,1.55,1.62]],"ltp":1.55,"tv":2823.15,"id":9433864}]}]}
{"op":"mcm","clk":"4233641242","pt":1631536951155,"mc":[{"id":"1.187557653","rc":[{"batb":[[1,3.3,9.08],[2,3.25,4.54]],"batl":[[1,3.6,41.68],[2,3.65,20.84]],"ltp":2.78,"tv":1791.69,"id":9632596},{"batb":[[0,1.41,38.45],[1,1.39,19.5],[2,1.37,87.45]],"ltp":1.55,"tv":2823.15,"id":9433864}]}]}
{"op":"mcm","clk":"4233641270","pt":1631536951470,"mc":[{"id":"1.187557653","rc":[{"batl":[[1,3.6,8.34],[2,3.65,4.16]],"ltp":2.78,"tv":1791.69,"id":9632596}]}]}
{"op":"mcm","clk":"4233641979","pt":1631536959156,"mc":[{"id":"1.187557653","rc":[{"trd":[[3.4,10]],"batb":[[0,3.3,9.85],[1,3.25,4.54],[2,3.2,67.04]],"ltp":3.4,"tv":1801.68,"id":9632596}],"tv":4624.84}]}
{"op":"mcm","clk":"4233642395","pt":1631536964589,"mc":[{"id":"1.187557653","rc":[{"trd":[[1.42,0.44]],"batl":[[0,1.42,124.96]],"ltp":1.42,"tv":2823.6,"id":9433864}],"tv":4625.29}]}
{"op":"mcm","clk":"4233642722","pt":1631536969403,"mc":[{"id":"1.187557653","rc":[{"batb":[[0,3.3,9.08]],"batl":[[0,3.6,8.34],[1,3.65,4.16],[2,3.7,67.36]],"ltp":3.4,"tv":1801.68,"id":9632596}]}]}
{"op":"mcm","clk":"4233642933","pt":1631536972301,"mc":[{"id":"1.187557653","rc":[{"batb":[[0,3.35,6.08],[1,3.3,9.08],[2,3.25,4.54]],"batl":[[0,3.5,4.6],[1,3.6,8.34],[2,3.65,4.16]],"ltp":3.4,"tv":1801.68,"id":9632596},{"batb":[[1,1.4,11.5],[2,1.39,19.5]],"ltp":1.42,"tv":2823.6,"id":9433864}]}]}
{"op":"mcm","clk":"4233644927","pt":1631536998649,"mc":[{"id":"1.187557653","rc":[{"trd":[[1.42,12.4]],"batl":[[0,1.42,118.98]],"ltp":1.42,"tv":2835.55,"id":9433864}],"tv":4637.24}]}
{"op":"mcm","clk":"4233645299","pt":1631537003555,"mc":[{"id":"1.187557653","rc":[{"trd":[[3.35,19.21]],"batb":[[0,3.3,9.08],[1,3.25,4.54],[2,3.2,67.04]],"ltp":3.35,"tv":1820.89,"id":9632596},{"trd":[[1.42,29.03]],"batl":[[0,1.42,102.35]],"ltp":1.42,"tv":2852.18,"id":9433864}],"tv":4673.08}]}
{"op":"mcm","clk":"4233645569","pt":1631537007069,"mc":[{"id":"1.187557653","rc":[{"trd":[[1.41,41.47]],"batb":[[0,1.41,28.46]],"ltp":1.41,"tv":2872.18,"id":9433864}],"tv":4693.08}]}
{"op":"mcm","clk":"4233645887","pt":1631537010983,"mc":[{"id":"1.187557653","rc":[{"batl":[[2,1.57,34.54]],"ltp":1.41,"tv":2872.18,"id":9433864}]}]}
{"op":"mcm","clk":"4233646102","pt":1631537013752,"mc":[{"id":"1.187557653","rc":[{"batl":[[0,3.6,8.34],[1,3.65,4.16],[2,3.7,67.36]],"ltp":3.35,"tv":1820.89,"id":9632596},{"batb":[[1,1.39,19.5],[2,1.37,87.45]],"ltp":1.41,"tv":2872.18,"id":9433864}]}]}
{"op":"mcm","clk":"4233646202","pt":1631537014950,"mc":[{"id":"1.187557653","rc":[{"trd":[[1.42,38.05]],"batl":[[0,1.42,97.84]],"ltp":1.42,"tv":2881.2,"id":9433864}],"tv":4702.1}]}
{"op":"mcm","clk":"4233646353","pt":1631537016676,"mc":[{"id":"1.187557653","rc":[{"batb":[[0,3.3,14.52]],"batl":[[0,3.4,5.22],[1,3.6,8.34],[2,3.65,4.16]],"ltp":3.35,"tv":1820.89,"id":9632596}]}]}
{"op":"mcm","clk":"4233652288","pt":1631537092114,"mc":[{"id":"1.187557653","rc":[{"batb":[[0,3.15,34.06],[1,2.82,18.08],[2,1.01,113.7]],"ltp":3.35,"tv":1820.89,"id":9632596},{"batl":[[0,1.57,34.54],[1,1.59,17.05],[2,1.7,0.01]],"ltp":1.42,"tv":2881.2,"id":9433864}]}]}
{"op":"mcm","clk":"4233652315","pt":1631537092533,"mc":[{"id":"1.187557653","rc":[{"batb":[[0,2.82,18.08],[1,1.01,113.7],[2,1.01,0]],"ltp":3.35,"tv":1820.89,"id":9632596},{"batb":[[0,1.29,114.89],[1,1.23,2],[2,1.19,1]],"batl":[[0,1.7,0.01],[1,1.59,0],[2,1.7,0]],"ltp":1.42,"tv":2881.2,"id":9433864}]}]}
{"op":"mcm","clk":"4233653497","pt":1631537106127,"mc":[{"id":"1.187557653","rc":[{"batb":[[0,2.96,94.8],[1,2.82,18.08],[2,1.01,113.7]],"batl":[[0,3.05,7.14],[1,3.2,62.5],[2,3.3,74.53]],"ltp":3.35,"tv":1820.89,"id":9632596},{"batb":[[0,1.49,36.39],[1,1.47,18.45],[2,1.46,102.74]],"batl":[[0,1.65,32.86],[1,1.67,16.23],[2,1.7,0.01]],"ltp":1.42,"tv":2881.2,"id":9433864}]}]}
{"op":"mcm","clk":"4233653585","pt":1631537107133,"mc":[{"id":"1.187557653","rc":[{"batb":[[2,2.56,23.26]],"batl":[[1,3.2,37.5]],"ltp":3.35,"tv":1820.89,"id":9632596},{"batb":[[2,1.46,61.64]],"batl":[[0,1.5,6.67],[1,1.52,98.68],[2,1.53,49.34]],"ltp":1.42,"tv":2881.2,"id":9433864}]}]}
{"op":"mcm","clk":"4233653602","pt":1631537107341,"mc":[{"id":"1.187557653","rc":[{"batb":[[2,1.46,20.54]],"batl":[[1,1.52,19.74],[2,1.53,9.86]],"ltp":1.42,"tv":2881.2,"id":9433864}]}]}
{"op":"mcm","clk":"4233654190","pt":1631537114256,"mc":[{"id":"1.187557653","rc":[{"batl":[[1,3.3,74.53],[2,3.3,0]],"ltp":3.35,"tv":1820.89,"id":9632596},{"batb":[[2,1.44,69.37]],"batl":[[0,1.65,32.86],[1,1.67,16.23],[2,1.7,0.01]],"ltp":1.42,"tv":2881.2,"id":9433864}]}]}
{"op":"mcm","clk":"4233654244","pt":1631537114951,"mc":[{"id":"1.187557653","rc":[{"batb":[[0,2.56,23.26],[1,1.01,113.7],[2,2.56,0]],"ltp":3.35,"tv":1820.89,"id":9632596},{"batb":[[0,1.36,89.29],[1,1.23,2],[2,1.19,1]],"batl":[[0,1.7,0.01],[1,1.67,0],[2,1.7,0]],"ltp":1.42,"tv":2881.2,"id":9433864}]}]}
{"op":"mcm","clk":"4233656995","pt":1631537148190,"mc":[{"id":"1.187557653","rc":[{"batb":[[0,3.35,82.11],[1,2.56,23.26],[2,1.01,113.7]],"batl":[[0,3.5,5.03]],"ltp":3.35,"tv":1820.89,"id":9632596},{"batb":[[0,1.4,51.3],[1,1.38,19.64],[2,1.36,283.75]],"batl":[[0,1.43,90.91],[1,1.44,62.5],[2,1.45,31.25]],"ltp":1.42,"tv":2881.2,"id":9433864}]}]}
{"op":"mcm","clk":"4233657074","pt":1631537149186,"mc":[{"id":"1.187557653","rc":[{"batb":[[1,3.15,33.14],[2,2.8,18.41]],"batl":[[1,3.9,2.56]],"ltp":3.35,"tv":1820.89,"id":9632596},{"batb":[[1,1.39,21.58],[2,1.38,30.44]],"batl":[[1,1.44,20.84],[2,1.45,10.42]],"ltp":1.42,"tv":2881.2,"id":9433864}]}]}
{"op":"mcm","clk":"4233657253","pt":1631537151516,"mc":[{"id":"1.187557653","rc":[{"trd":[[3.35,95.81]],"batb":[[0,3.35,43.81]],"ltp":3.35,"tv":1897.49,"id":9632596}],"tv":4778.7}]}
{"op":"mcm","clk":"4233657677","pt":1631537156925,"mc":[{"id":"1.187557653","rc":[{"batb":[[0,1.4,51.31]],"ltp":1.42,"tv":2881.2,"id":9433864}]}]}
{"op":"mcm","clk":"4233658298","pt":1631537165622,"mc":[{"id":"1.187557653","rc":[{"trd":[[3.35,109.61]],"batb":[[0,3.35,36.91]],"ltp":3.35,"tv":1911.29,"id":9632596}],"tv":4792.5}]}
{"op":"mcm","clk":"4233658490","pt":1631537168216,"mc":[{"id":"1.187557653","rc":[{"batb":[[0,2.8,18.41],[1,1.01,113.7],[2,2.8,0]],"ltp":3.35,"tv":1911.29,"id":9632596},{"batb":[[0,1.28,121.85],[1,1.23,2],[2,1.19,1]],"batl":[[0,1.7,0.01],[1,1.44,0],[2,1.45,0]],"ltp":1.42,"tv":2881.2,"id":9433864}]}]}
{"op":"mcm","clk":"4233659405","pt":1631537182288,"mc":[{"id":"1.187557653","rc":[{"batb":[[0,2.88,91.99],[1,2.8,18.41],[2,1.01,113.7]],"batl":[[0,3.05,9.62],[1,3.15,47.62],[2,3.2,23.8]],"ltp":3.35,"tv":1911.29,"id":9632596},{"batb":[[0,1.49,36.39],[1,1.47,18.45],[2,1.45,175.4]],"batl":[[0,1.52,15.99],[1,1.66,32.67],[2,1.68,16.14]],"ltp":1.42,"tv":2881.2,"id":9433864}]}]}
{"op":"mcm","clk":"4233659476","pt":1631537183172,"mc":[{"id":"1.187557653","rc":[{"batb":[[0,2.9,10.34],[1,2.88,97.17],[2,2.86,5.18]],"batl":[[1,3.15,9.52],[2,3.2,4.76]],"ltp":3.35,"tv":1911.29,"id":9632596},{"batb":[[2,1.45,243.93]],"batl":[[0,1.51,6.62],[1,1.52,15.99],[2,1.66,32.67]],"ltp":1.42,"tv":2881.2,"id":9433864}]}]}
{"op":"mcm","clk":"4233660598","pt":1631537198702,"mc":[{"id":"1.187557653","rc":[{"trd":[[2.96,4.91]],"ltp":2.96,"tv":1912.82,"id":9632596},{"trd":[[1.51,9.62]],"batl":[[0,1.51,3.62]],"ltp":1.51,"tv":2884.2,"id":9433864}],"tv":4797.03}]}
{"op":"mcm","clk":"4233660770","pt":1631537201184,"mc":[{"id":"1.187557653","rc":[{"batb":[[0,2.52,24.6],[1,1.01,113.7],[2,2.86,0]],"ltp":2.96,"tv":1912.82,"id":9632596},{"batb":[[0,1.36,90.47],[1,1.34,431.32],[2,1.23,2]],"batl":[[0,1.95,443.02],[1,1.52,0],[2,1.66,0]],"ltp":1.51,"tv":2884.2,"id":9433864}]}]}
{"op":"mcm","clk":"4233660982","pt":1631537204187,"mc":[{"id":"1.187557653","rc":[{"batl":[[0,1.95,443.02]],"ltp":1.51,"tv":2884.2,"id":9433864}]}]}
{"op":"mcm","clk":"4233661225","pt":1631537207109,"mc":[{"id":"1.187557653","rc":[{"batb":[[0,1.36,90.46]],"ltp":1.51,"tv":2884.2,"id":9433864}]}]}
{"op":"mcm","clk":"4233661293","pt":1631537207995,"mc":[{"id":"1.187557653","rc":[{"batb":[[1,1.23,2],[2,1.19,1]],"ltp":1.51,"tv":2884.2,"id":9433864}]}]}
{"op":"mcm","clk":"4233661420","pt":1631537209928,"mc":[{"id":"1.187557653","rc":[{"batb":[[0,3.4,4.37],[1,3.3,9.08],[2,3.25,66.08]],"batl":[[0,3.5,5.54],[1,3.75,68.19]],"ltp":2.96,"tv":1912.82,"id":9632596},{"batb":[[0,1.4,38.73],[1,1.38,19.64],[2,1.36,90.46]],"batl":[[0,1.42,7.04],[1,1.43,167.21],[2,1.54,35.21]],"ltp":1.51,"tv":2884.2,"id":9433864}]}]}
{"op":"mcm","clk":"4233661510","pt":1631537211121,"mc":[{"id":"1.187557653","rc":[{"batl":[[2,3.95,2.53]],"ltp":2.96,"tv":1912.82,"id":9632596},{"batb":[[1,1.38,41.38],[2,1.37,10.88]],"ltp":1.51,"tv":2884.2,"id":9433864}]}]}
{"op":"mcm","clk":"4233661700","pt":1631537213823,"mc":[{"id":"1.187557653","rc":[{"trd":[[3.4,18.48]],"batb":[[0,3.3,9.21],[1,3.25,66.08],[2,3.2,37.09]],"ltp":3.4,"tv":1921.3,"id":9632596}],"tv":4805.51}]}
{"op":"mcm","clk":"4233661979","pt":1631537217198,"mc":[{"id":"1.187557653","rc":[{"trd":[[1.42,51.93]],"batl":[[0,1.43,167.31],[1,1.54,35.21],[2,1.56,17.38]],"ltp":1.42,"tv":2898.08,"id":9433864}],"tv":4819.39}]}
{"op":"mcm","clk":"4233662622","pt":1631537224034,"mc":[{"id":"1.187557653","rc":[{"batb":[[0,3.3,9.08]],"batl":[[0,3.75,68.19],[1,3.95,2.53],[2,3.95,0]],"ltp":3.4,"tv":1921.3,"id":9632596}]}]}
{"op":"mcm","clk":"4233662814","pt":1631537226019,"mc":[{"id":"1.187557653","rc":[{"batb":[[0,2.74,19.41],[1,1.01,113.7],[2,3.2,0]],"ltp":3.4,"tv":1921.3,"id":9632596},{"batb":[[0,1.28,450.13],[1,1.25,135.48],[2,1.23,2]],"batl":[[0,1.82,505.01],[1,1.54,0],[2,1.56,0]],"ltp":1.42,"tv":2898.08,"id":9433864}]}]}
{"op":"mcm","clk":"4233663701","pt":1631537236445,"mc":[{"id":"1.187557653","rc":[{"batb":[[0,1.25,135.48],[1,1.23,2],[2,1.19,1]],"ltp":1.42,"tv":2898.08,"id":9433864}]}]}
{"op":"mcm","clk":"4233663826","pt":1631537237857,"mc":[{"id":"1.187557653","rc":[{"batb":[[0,2.84,5.74],[1,2.74,19.41],[2,1.01,113.7]],"batl":[[0,2.92,6.57],[1,3.35,2.99],[2,3.5,149.67]],"ltp":3.4,"tv":1921.3,"id":9632596},{"batb":[[0,1.51,35.91],[1,1.49,38.34],[2,1.48,10.06]],"batl":[[0,1.56,204.47],[1,1.68,32.27],[2,1.7,15.95]],"ltp":1.42,"tv":2898.08,"id":9433864}]}]}
{"op":"mcm","clk":"4233663897","pt":1631537238645,"mc":[{"id":"1.187557653","rc":[{"trd":[[2.92,3.43]],"batb":[[1,2.8,10.72],[2,2.78,5.36]],"batl":[[0,2.92,3.14]],"ltp":2.92,"tv":1924.73,"id":9632596},{"trd":[[1.52,19.58]],"ltp":1.52,"tv":2904.66,"id":9433864}],"tv":4829.4}]}
{"op":"mcm","clk":"4233664654","pt":1631537249210,"mc":[{"id":"1.187557653","rc":[{"batb":[[0,2.4,27.61],[1,1.01,113.7],[2,2.78,0]],"ltp":2.92,"tv":1924.73,"id":9632596},{"batb":[[0,1.35,92.3],[1,1.34,431.32],[2,1.23,2]],"batl":[[0,1.82,505.01],[1,1.68,0],[2,1.7,0]],"ltp":1.52,"tv":2904.66,"id":9433864}]}]}
{"op":"mcm","clk":"4233665605","pt":1631537261836,"mc":[{"id":"1.187557653","rc":[{"batb":[[1,1.23,2],[2,1.19,1]],"ltp":1.52,"tv":2904.66,"id":9433864}]}]}
{"op":"mcm","clk":"4233665670","pt":1631537262719,"mc":[{"id":"1.187557653","rc":[{"batb":[[0,2.5,98.75],[1,2.4,27.61],[2,1.01,113.7]],"batl":[[0,2.6,7.09],[1,2.66,78.95],[2,2.68,16.92]],"ltp":2.92,"tv":1924.73,"id":9632596},{"batb":[[0,1.61,33.68],[1,1.59,17.05],[2,1.5,300.51]],"batl":[[0,1.66,16.33],[1,1.81,29.95],[2,1.83,14.82]],"ltp":1.52,"tv":2904.66,"id":9433864}]}]}
{"op":"mcm","clk":"4233665744","pt":1631537263614,"mc":[{"id":"1.187557653","rc":[{"trd":[[2.6,14.64]],"batb":[[1,2.48,12.1],[2,2.46,6.04]],"batl":[[0,2.6,3.25],[1,2.66,56.39],[2,2.68,5.64]],"ltp":2.6,"tv":1928.57,"id":9632596},{"trd":[[1.62,62.45]],"batb":[[2,1.58,48.62]],"ltp":1.62,"tv":2910.83,"id":9433864}],"tv":4839.41}]}
{"op":"mcm","clk":"4233666430","pt":1631537273742,"mc":[{"id":"1.187557653","rc":[{"batl":[[0,2.66,56.39],[1,2.68,5.64],[2,2.7,5.64]],"ltp":2.6,"tv":1928.57,"id":9632596},{"batl":[[0,1.81,29.96],[1,1.83,14.82],[2,2.16,372.43]],"ltp":1.62,"tv":2910.83,"id":9433864}]}]}
{"op":"mcm","clk":"4233666641","pt":1631537277021,"mc":[{"id":"1.187557653","rc":[{"trd":[[1.62,62.47]],"batb":[[0,1.62,9.37],[1,1.61,33.68],[2,1.59,17.05]],"batl":[[0,1.66,22.34],[1,1.81,29.95],[2,1.83,14.82]],"ltp":1.62,"tv":2910.85,"id":9433864}],"tv":4839.43}]}
{"op":"mcm","clk":"4233667089","pt":1631537283364,"mc":[{"id":"1.187557653","rc":[{"batl":[[0,1.64,8.37],[1,1.66,22.34],[2,1.81,29.95]],"ltp":1.62,"tv":2910.85,"id":9433864}]}]}
{"op":"mcm","clk":"4233667297","pt":1631537286667,"mc":[{"id":"1.187557653","rc":[{"batb":[[0,1.61,33.68],[1,1.59,17.05],[2,1.58,48.62]],"batl":[[1,1.81,29.95],[2,1.83,14.82]],"ltp":1.62,"tv":2910.85,"id":9433864}]}]}
{"op":"mcm","clk":"4233667489","pt":1631537289545,"mc":[{"id":"1.187557653","rc":[{"batb":[[0,1.62,9.37],[1,1.61,33.68],[2,1.59,17.05]],"batl":[[1,1.66,22.35],[2,1.81,29.95]],"ltp":1.62,"tv":2910.85,"id":9433864}]}]}
{"op":"mcm","clk":"4233668217","pt":1631537299679,"mc":[{"id":"1.187557653","rc":[{"batb":[[1,1.58,48.62],[2,1.5,300.51]],"batl":[[2,2.16,372.43]],"ltp":1.62,"tv":2910.85,"id":9433864}]}]}
{"op":"mcm","clk":"4233669059","pt":1631537311624,"mc":[{"id":"1.187557653","rc":[{"trd":[[2.5,24.06],[2.56,5.12]],"batb":[[0,2.5,86.72]],"ltp":2.5,"tv":1953.51,"id":9632596},{"trd":[[1.64,64.18]],"batl":[[0,1.66,22.35],[1,2.16,372.43],[2,2.16,0]],"ltp":1.64,"tv":2926.2,"id":9433864}],"tv":4879.72}]}
{"op":"mcm","clk":"4233670767","pt":1631537337049,"mc":[{"id":"1.187557653","rc":[{"trd":[[1.62,65.57]],"batb":[[0,1.62,7.82]],"ltp":1.62,"tv":2929.3,"id":9433864}],"tv":4882.82}]}
{"op":"mcm","clk":"4233671243","pt":1631537344185,"mc":[{"id":"1.187557653","rc":[{"batb":[[0,2.14,39.08],[1,1.01,113.7],[2,2.46,0]],"ltp":2.5,"tv":1953.51,"id":9632596},{"batb":[[0,1.49,60.33],[1,1.44,405.13],[2,1.23,2]],"batl":[[0,2.16,372.43],[1,2.16,0]],"ltp":1.62,"tv":2929.3,"id":9433864}]}]}
{"op":"mcm","clk":"4233671518","pt":1631537348153,"mc":[{"id":"1.187557653","rc":[{"batb":[[0,2.12,39.25]],"ltp":2.5,"tv":1953.51,"id":9632596},{"batb":[[0,1.5,60.17]],"ltp":1.62,"tv":2929.3,"id":9433864}]}]}
{"op":"mcm","clk":"4233672873","pt":1631537365401,"mc":[{"id":"1.187557653","rc":[{"batb":[[1,1.23,2],[2,1.19,1]],"ltp":1.62,"tv":2929.3,"id":9433864}]}]}
{"op":"mcm","clk":"4233672991","pt":1631537367278,"mc":[{"id":"1.187557653","rc":[{"batl":[[0,2.34,216.89],[1,2.42,103.52],[2,2.58,3.88]],"ltp":2.5,"tv":1953.51,"id":9632596},{"batb":[[0,1.76,125.22],[1,1.75,85.72],[2,1.74,42.86]],"batl":[[0,1.8,12.57],[1,1.83,132.15],[2,2.16,372.43]],"ltp":1.62,"tv":2929.3,"id":9433864}]}]}
{"op":"mcm","clk":"4233673046","pt":1631537368215,"mc":[{"id":"1.187557653","rc":[{"batb":[[1,1.88,28.95],[2,1.01,113.7]],"batl":[[0,2.42,103.52],[1,2.58,3.88],[2,2.58,0]],"ltp":2.5,"tv":1953.51,"id":9632596},{"trd":[[1.76,47.5]],"batb":[[0,1.76,104.85],[1,1.75,51.43],[2,1.74,41.3]],"batl":[[2,1.84,81.52]],"ltp":1.76,"tv":2940.72,"id":9433864}],"tv":4894.24}]}
{"op":"mcm","clk":"4233673105","pt":1631537369001,"mc":[{"id":"1.187557653","rc":[{"batb":[[1,1.75,17.14],[2,1.74,24.16]],"batl":[[2,1.84,16.3]],"ltp":1.76,"tv":2940.72,"id":9433864}]}]}
{"op":"mcm","clk":"4233673388","pt":1631537372811,"mc":[{"id":"1.187557653","rc":[{"trd":[[1.76,51.5]],"batb":[[0,1.76,102.85]],"ltp":1.76,"tv":2944.72,"id":9433864}],"tv":4898.24}]}
{"op":"mcm","clk":"4233673555","pt":1631537374998,"mc":[{"id":"1.187557653","rc":[{"batb":[[2,1.01,115.4]],"ltp":2.5,"tv":1953.51,"id":9632596}]}]}
{"op":"mcm","clk":"4233674236","pt":1631537384537,"mc":[{"id":"1.187557653","rc":[{"batb":[[0,1.76,72.05],[2,1.74,8.58]],"ltp":1.76,"tv":2944.72,"id":9433864}]}]}
{"op":"mcm","clk":"4233674721","pt":1631537391027,"mc":[{"id":"1.187557653","rc":[{"batb":[[0,1.73,35.4],[1,1.61,45.69],[2,1.52,396.29]],"batl":[[0,2.16,372.43],[1,1.83,0],[2,1.84,0]],"ltp":1.76,"tv":2944.72,"id":9433864}]}]}
{"op":"mcm","clk":"4233674820","pt":1631537392123,"mc":[{"id":"1.187557653","rc":[{"batb":[[0,1.88,28.95],[1,1.01,115.4],[2,1.01,0]],"ltp":2.5,"tv":1953.51,"id":9632596},{"batb":[[0,1.61,45.69],[1,1.52,396.29],[2,1.46,2]],"batl":[[0,2.16,373.21]],"ltp":1.76,"tv":2944.72,"id":9433864}]}]}
{"op":"mcm","clk":"4233675105","pt":1631537395820,"mc":[{"id":"1.187557653","rc":[{"batl":[[0,1.76,22.08],[1,2.16,372.43]],"ltp":1.76,"tv":2944.72,"id":9433864}]}]}
{"op":"mcm","clk":"4233675973","pt":1631537407470,"mc":[{"id":"1.187557653","rc":[{"batl":[[0,1.76,22.07]],"ltp":1.76,"tv":2944.72,"id":9433864}]}]}
{"op":"mcm","clk":"4233676357","pt":1631537412856,"mc":[{"id":"1.187557653","rc":[{"batb":[[1,1.46,2],[2,1.23,2]],"batl":[[1,2.16,0]],"ltp":1.76,"tv":2944.72,"id":9433864}]}]}
{"op":"mcm","clk":"4233676464","pt":1631537414269,"mc":[{"id":"1.187557653","rc":[{"trd":[[2.3,80.21]],"batl":[[0,1.99,100.5],[1,2.02,13.06],[2,2.04,246.96]],"ltp":2.3,"tv":1970.4,"id":9632596},{"trd":[[1.76,73.57]],"batb":[[0,1.97,76.14],[1,1.96,38.08],[2,1.95,38.08]],"batl":[[0,2.04,11.3],[1,2.08,110.29]],"ltp":1.76,"tv":2966.79,"id":9433864}],"tv":4937.2}]}
{"op":"mcm","clk":"4233676531","pt":1631537415267,"mc":[{"id":"1.187557653","rc":[{"trd":[[1.99,5.08]],"batb":[[0,1.93,77.72],[1,1.92,38.86],[2,1.91,38.86]],"batl":[[0,1.99,95.42],[2,2.12,166.35]],"ltp":1.99,"tv":1975.48,"id":9632596},{"trd":[[2,15.97]],"batb":[[0,1.98,27.39],[1,1.97,15.22],[2,1.96,21.45]],"ltp":2.0,"tv":2971.84,"id":9433864}],"tv":4947.33}]}
{"op":"mcm","clk":"4233676554","pt":1631537415578,"mc":[{"id":"1.187557653","rc":[{"batb":[[0,1.93,15.54],[1,1.92,7.78],[2,1.91,7.78]],"ltp":1.99,"tv":1975.48,"id":9632596}]}]}
{"op":"mcm","clk":"4233676618","pt":1631537416575,"mc":[{"id":"1.187557653","rc":[{"batl":[[2,2.6,281.81]],"ltp":2.0,"tv":2971.84,"id":9433864}]}]}
{"op":"mcm","clk":"4233676789","pt":1631537419194,"mc":[{"id":"1.187557653","rc":[{"batl":[[2,2.2,94.08]],"ltp":2.0,"tv":2971.84,"id":9433864}]}]}
{"op":"mcm","clk":"4233676805","pt":1631537419391,"mc":[{"id":"1.187557653","rc":[{"batl":[[2,2.6,281.81]],"ltp":2.0,"tv":2971.84,"id":9433864}]}]}
{"op":"mcm","clk":"4233677071","pt":1631537422991,"mc":[{"id":"1.187557653","rc":[{"trd":[[1.99,5.09]],"batl":[[0,1.99,95.41]],"ltp":1.99,"tv":1975.49,"id":9632596},{"trd":[[2,15.98]],"ltp":2.0,"tv":2971.85,"id":9433864}],"tv":4947.35}]}
{"op":"mcm","clk":"4233677668","pt":1631537431491,"mc":[{"id":"1.187557653","rc":[{"batb":[[0,1.97,15.22],[1,1.96,7.62],[2,1.95,56.07]],"ltp":2.0,"tv":2971.85,"id":9433864}]}]}
{"op":"mcm","clk":"4233678088","pt":1631537436710,"mc":[{"id":"1.187557653","rc":[{"batb":[[0,1.67,42.59],[1,1.01,115.4],[2,1.91,0]],"ltp":1.99,"tv":1975.49,"id":9632596},{"batb":[[0,1.79,31.63],[1,1.62,388.38],[2,1.46,2]],"batl":[[0,2.6,281.81],[1,2.08,0],[2,2.6,0]],"ltp":2.0,"tv":2971.85,"id":9433864}]}]}
{"op":"mcm","clk":"4233679494","pt":1631537455542,"mc":[{"id":"1.187557653","rc":[{"batb":[[1,1.46,2],[2,1.23,2]],"ltp":2.0,"tv":2971.85,"id":9433864}]}]}
{"op":"mcm","clk":"4233679796","pt":1631537459934,"mc":[{"id":"1.187557653","rc":[{"batb":[[1,1.67,383.76],[2,1.46,2]],"ltp":2.0,"tv":2971.85,"id":9433864}]}]}
{"op":"mcm","clk":"4233680775","pt":1631537472867,"mc":[{"id":"1.187557653","rc":[{"batb":[[1,1.46,2],[2,1.23,2]],"ltp":2.0,"tv":2971.85,"id":9433864}]}]}
{"op":"mcm","clk":"4233680848","pt":1631537473969,"mc":[{"id":"1.187557653","rc":[{"batb":[[0,1.93,28.09],[1,1.91,14.19],[2,1.67,42.59]],"ltp":1.99,"tv":1975.49,"id":9632596},{"trd":[[1.82,53.9]],"batb":[[0,1.83,2.19],[1,1.82,29.79],[2,1.8,15.06]],"batl":[[0,1.86,8.47],[1,1.89,105.99],[2,1.9,47.38]],"ltp":1.82,"tv":2982.83,"id":9433864}],"tv":4958.33}]}
{"op":"mcm","clk":"4233680911","pt":1631537474949,"mc":[{"id":"1.187557653","rc":[{"batb":[[0,2.04,44.18],[1,1.93,28.09],[2,1.91,14.19]],"batl":[[0,2.46,4.07]],"ltp":1.99,"tv":1975.49,"id":9632596},{"batb":[[2,1.81,16.58]],"batl":[[2,1.9,15.8]],"ltp":1.82,"tv":2982.83,"id":9433864}]}]}
{"op":"mcm","clk":"4233681477","pt":1631537483972,"mc":[{"id":"1.187557653","rc":[{"batb":[[0,1.82,29.79],[1,1.81,16.58],[2,1.8,23.34]],"batl":[[0,1.89,105.99],[1,1.9,15.8],[2,1.91,7.9]],"ltp":1.82,"tv":2982.83,"id":9433864}]}]}
{"op":"mcm","clk":"4233681675","pt":1631537486773,"mc":[{"id":"1.187557653","rc":[{"batl":[[0,2.24,12.59],[1,2.46,4.07]],"ltp":1.99,"tv":1975.49,"id":9632596},{"batl":[[0,1.86,13.84],[1,1.89,105.99],[2,1.9,15.8]],"ltp":1.82,"tv":2982.83,"id":9433864}]}]}
{"op":"mcm","clk":"4233681928","pt":1631537490996,"mc":[{"id":"1.187557653","rc":[{"batb":[[1,1.77,35.15],[2,1.01,115.4]],"ltp":1.99,"tv":1975.49,"id":9632596},{"batb":[[0,1.81,16.58],[1,1.8,8.28],[2,1.79,39.91]],"ltp":1.82,"tv":2982.83,"id":9433864}]}]}
{"op":"mcm","clk":"4233682117","pt":1631537494199,"mc":[{"id":"1.187557653","rc":[{"batb":[[0,2.04,454.5]],"ltp":1.99,"tv":1975.49,"id":9632596}]}]}
{"op":"mcm","clk":"4233682343","pt":1631537498085,"mc":[{"id":"1.187557653","rc":[{"batb":[[0,1.79,31.63],[1,1.63,43.26],[2,1.55,392.04]],"batl":[[0,2.42,312.73],[1,1.89,0],[2,1.9,0]],"ltp":1.82,"tv":2982.83,"id":9433864}]}]}
{"op":"mcm","clk":"4233682394","pt":1631537498699,"mc":[{"id":"1.187557653","rc":[{"batb":[[0,1.77,35.15],[1,1.01,115.4],[2,1.01,0]],"ltp":1.99,"tv":1975.49,"id":9632596},{"batb":[[0,1.63,43.26],[1,1.55,392.04],[2,1.46,2]],"ltp":1.82,"tv":2982.83,"id":9433864}]}]}
{"op":"mcm","clk":"4233685193","pt":1631537539679,"mc":[{"id":"1.187557653","rc":[{"batb":[[1,1.46,2],[2,1.23,2]],"ltp":1.82,"tv":2982.83,"id":9433864}]}]}
{"op":"mcm","clk":"4233685290","pt":1631537541151,"mc":[{"id":"1.187557653","rc":[{"batb":[[1,1.68,32.27],[2,1.66,16.34]],"batl":[[0,1.88,63.83],[1,1.89,40.95],[2,1.91,14.19]],"ltp":1.99,"tv":1975.49,"id":9632596},{"batb":[[0,2.1,42.86],[1,2.08,21.43],[2,2.06,21.43]],"batl":[[0,2.2,14.51],[1,2.28,144.96]],"ltp":1.82,"tv":2982.83,"id":9433864}]}]}
{"op":"mcm","clk":"4233685348","pt":1631537542182,"mc":[{"id":"1.187557653","rc":[{"batb":[[0,1.81,16.58],[1,1.8,8.28],[2,1.79,8.28]],"ltp":1.99,"tv":1975.49,"id":9632596},{"batb":[[0,2.1,14.28],[1,2.08,46.8],[2,2.06,7.14]],"batl":[[0,2.14,4.67],[1,2.2,14.51],[2,2.28,144.96]],"ltp":1.82,"tv":2982.83,"id":9433864}]}]}
{"op":"mcm","clk":"4233686409","pt":1631537558205,"mc":[{"id":"1.187557653","rc":[{"batl":[[1,1.89,12.26],[2,2.04,4.9]],"ltp":1.99,"tv":1975.49,"id":9632596}]}]}
{"op":"mcm","clk":"4233686607","pt":1631537561917,"mc":[{"id":"1.187557653","rc":[{"trd":[[1.87,4.78]],"ltp":1.87,"tv":1980.27,"id":9632596},{"trd":[[2.14,4.18]],"batl":[[0,2.2,15],[1,2.28,144.96],[2,2.82,253.59]],"ltp":2.14,"tv":2987.01,"id":9433864}],"tv":4967.29}]}
{"op":"mcm","clk":"4233687548","pt":1631537577023,"mc":[{"id":"1.187557653","rc":[{"batb":[[0,1.77,35.15],[1,1.57,52.38],[2,1.01,115.4]],"ltp":1.87,"tv":1980.27,"id":9632596},{"batb":[[0,2.08,39.66],[1,1.88,26.78],[2,1.7,383.83]],"batl":[[0,2.82,253.59],[1,2.28,0],[2,2.82,0]],"ltp":2.14,"tv":2987.01,"id":9433864}]}]}
{"op":"mcm","clk":"4233687573","pt":1631537577442,"mc":[{"id":"1.187557653","rc":[{"batb":[[0,1.57,52.38],[1,1.01,115.4],[2,1.01,0]],"ltp":1.87,"tv":1980.27,"id":9632596},{"batb":[[0,1.88,26.78],[1,1.7,383.83],[2,1.46,2]],"ltp":2.14,"tv":2987.01,"id":9433864}]}]}
{"op":"mcm","clk":"4233688708","pt":1631537599157,"mc":[{"id":"1.187557653","rc":[{"batb":[[0,1.62,9.37],[1,1.57,52.38],[2,1.49,36.39]],"batl":[[0,1.66,54.9],[1,1.68,16.14],[2,1.7,161.64]],"ltp":1.87,"tv":1980.27,"id":9632596},{"batb":[[0,2.6,76.92],[1,2.54,11.82],[2,2.52,5.9]],"batl":[[0,2.78,144.89]],"ltp":2.14,"tv":2987.01,"id":9433864}]}]}
{"op":"mcm","clk":"4233688770","pt":1631537600250,"mc":[{"id":"1.187557653","rc":[{"batb":[[1,1.58,18.98],[2,1.57,61.88]],"ltp":1.87,"tv":1980.27,"id":9632596},{"batl":[[0,2.62,3.82],[1,2.78,144.89]],"ltp":2.14,"tv":2987.01,"id":9433864}]}]}
{"op":"mcm","clk":"4233688858","pt":1631537602084,"mc":[{"id":"1.187557653","rc":[{"batl":[[2,3.45,198.52]],"ltp":2.14,"tv":2987.01,"id":9433864}]}]}
{"op":"mcm","clk":"4233688976","pt":1631537604053,"mc":[{"id":"1.187557653","rc":[{"trd":[[1.61,2.8],[1.62,18.74]],"batb":[[0,1.58,18.98],[1,1.57,61.88],[2,1.56,9.5]],"ltp":1.61,"tv":2001.81,"id":9632596},{"trd":[[2.62,1.72]],"batl":[[0,2.62,2.1]],"ltp":2.62,"tv":2988.73,"id":9433864}],"tv":4990.55}]}
{"op":"mcm","clk":"4233689384","pt":1631537611059,"mc":[{"id":"1.187557653","rc":[{"batl":[[0,1.66,54.93]],"ltp":1.61,"tv":2001.81,"id":9632596},{"trd":[[2.62,5.92]],"batb":[[0,2.62,3.89],[1,2.6,76.92],[2,2.54,11.82]],"batl":[[0,2.78,144.89],[1,3.45,198.52],[2,3.45,0]],"ltp":2.62,"tv":2992.93,"id":9433864}],"tv":4994.75}]}
{"op":"mcm","clk":"4233689489","pt":1631537612777,"mc":[{"id":"1.187557653","rc":[{"batb":[[0,2.6,76.92],[1,2.54,11.82],[2,2.52,5.9]],"ltp":2.62,"tv":2992.93,"id":9433864}]}]}
{"op":"mcm","clk":"4233689575","pt":1631537614108,"mc":[{"id":"1.187557653","rc":[{"batl":[[0,1.66,32.7]],"ltp":1.61,"tv":2001.81,"id":9632596},{"batl":[[0,2.78,225.11]],"ltp":2.62,"tv":2992.93,"id":9433864}]}]}
{"op":"mcm","clk":"4233689590","pt":1631537614289,"mc":[{"id":"1.187557653","rc":[{"batl":[[0,2.78,144.89]],"ltp":2.62,"tv":2992.93,"id":9433864}]}]}
{"op":"mcm","clk":"4233689727","pt":1631537616996,"mc":[{"id":"1.187557653","rc":[{"trd":[[1.58,12.92]],"batb":[[0,1.58,12.52]],"batl":[[0,1.64,16.22],[1,1.66,32.67],[2,1.68,16.14]],"ltp":1.58,"tv":2014.73,"id":9632596},{"batl":[[0,2.66,9.11],[1,2.78,144.89],[2,3.45,198.52]],"ltp":2.62,"tv":2992.93,"id":9433864}],"tv":5007.67}]}
{"op":"mcm","clk":"4233689818","pt":1631537618705,"mc":[{"id":"1.187557653","rc":[{"batl":[[0,1.64,16.18]],"ltp":1.58,"tv":2014.73,"id":9632596}]}]}
{"op":"mcm","clk":"4233689994","pt":1631537621933,"mc":[{"id":"1.187557653","rc":[{"batl":[[0,1.64,16.22]],"ltp":1.58,"tv":2014.73,"id":9632596}]}]}
{"op":"mcm","clk":"4233690271","pt":1631537625992,"mc":[{"id":"1.187557653","rc":[{"trd":[[1.56,54.83],[1.57,123.73],[1.58,37.96],[1.6,15.14]],"batb":[[0,1.49,36.39],[1,1.47,18.45],[2,1.46,69.62]],"batl":[[0,1.64,16.88]],"ltp":1.56,"tv":2233.48,"id":9632596},{"trd":[[2.66,9.11],[2.78,20.11]],"batl":[[0,2.78,124.78],[1,3.45,198.52],[2,3.45,0]],"ltp":2.78,"tv":3022.15,"id":9433864}],"tv":5255.63}]}
{"op":"mcm","clk":"4233690406","pt":1631537628230,"mc":[{"id":"1.187557653","rc":[{"batb":[[0,1.46,69.62],[1,1.01,115.4],[2,1.46,0]],"batl":[[0,1.6,0.7],[1,1.66,0],[2,1.68,0]],"ltp":1.56,"tv":2233.48,"id":9632596},{"batb":[[0,2.42,25.36],[1,2.14,36.4],[2,1.92,373.16]],"batl":[[0,3.45,198.52],[1,3.45,0]],"ltp":2.78,"tv":3022.15,"id":9433864}]}]}
{"op":"mcm","clk":"4233690464","pt":1631537628909,"mc":[{"id":"1.187557653","rc":[{"batb":[[0,2.14,36.4],[1,1.92,373.16],[2,1.46,2]],"ltp":2.78,"tv":3022.15,"id":9433864}]}]}
{"op":"mcm","clk":"4233690617","pt":1631537631910,"mc":[{"id":"1.187557653","rc":[{"batb":[[0,1.45,71.13]],"ltp":1.56,"tv":2233.48,"id":9632596},{"batb":[[0,2.16,35.56]],"ltp":2.78,"tv":3022.15,"id":9433864}]}]}
{"op":"mcm","clk":"4233690732","pt":1631537634036,"mc":[{"id":"1.187557653","rc":[{"batl":[[0,3.05,2.13],[1,3.45,198.52]],"ltp":2.78,"tv":3022.15,"id":9433864}]}]}
{"op":"mcm","clk":"4233691008","pt":1631537638137,"mc":[{"id":"1.187557653","rc":[{"batb":[[1,1.01,113.7]],"ltp":1.56,"tv":2233.48,"id":9632596}]}]}
{"op":"mcm","clk":"4233691033","pt":1631537638550,"mc":[{"id":"1.187557653","rc":[{"trd":[[1.6,15.64]],"batl":[[0,1.6,0.21]],"ltp":1.6,"tv":2233.97,"id":9632596},{"trd":[[2.66,9.41]],"ltp":2.66,"tv":3022.45,"id":9433864}],"tv":5256.42}]}
{"op":"mcm","clk":"4233691551","pt":1631537647151,"mc":[{"id":"1.187557653","rc":[{"batb":[[1,1.46,2],[2,1.23,2]],"batl":[[1,3.45,0]],"ltp":2.66,"tv":3022.45,"id":9433864}]}]}
{"op":"mcm","clk":"4233691606","pt":1631537648142,"mc":[{"id":"1.187557653","rc":[{"batb":[[0,1.48,13.5],[1,1.47,179.05],[2,1.45,71.13]],"batl":[[0,1.5,4.86],[1,1.52,98.68],[2,1.53,49.34]],"ltp":1.6,"tv":2233.97,"id":9632596}]}]}
{"op":"mcm","clk":"4233691695","pt":1631537649281,"mc":[{"id":"1.187557653","rc":[{"trd":[[1.5,4.86]],"batb":[[2,1.46,102.74]],"batl":[[0,1.52,19.74],[1,1.53,9.86],[2,1.54,139.74]],"ltp":1.5,"tv":2238.83,"id":9632596},{"trd":[[3,2.43]],"batb":[[0,2.76,17.74],[1,2.42,25.61],[2,1.46,2]],"batl":[[0,3.05,3.1]],"ltp":3.0,"tv":3024.88,"id":9433864}],"tv":5263.71}]}
{"op":"mcm","clk":"4233691708","pt":1631537649489,"mc":[{"id":"1.187557653","rc":[{"batb":[[2,1.46,20.54]],"ltp":1.5,"tv":2238.83,"id":9632596}]}]}
{"op":"mcm","clk":"4233691788","pt":1631537650848,"mc":[{"id":"1.187557653","rc":[{"batb":[[2,2.04,373.96]],"batl":[[1,3.9,174.3]],"ltp":3.0,"tv":3024.88,"id":9433864}]}]}
{"op":"mcm","clk":"4233691933","pt":1631537653148,"mc":[{"id":"1.187557653","rc":[{"trd":[[1.48,31.39],[1.51,1.89]],"batb":[[0,1.47,179.05],[1,1.46,20.54],[2,1.45,81.41]],"batl":[[0,1.48,17.51],[1,1.52,19.74],[2,1.53,9.86]],"ltp":1.48,"tv":2272.11,"id":9632596},{"trd":[[2.94,0.97],[3.05,2.13]],"batl":[[0,3.3,59.32]],"ltp":3.05,"tv":3027.98,"id":9433864}],"tv":5300.09}]}
{"op":"mcm","clk":"4233691947","pt":1631537653358,"mc":[{"id":"1.187557653","rc":[{"batl":[[0,1.52,19.74],[1,1.53,9.86],[2,1.54,139.74]],"ltp":1.48,"tv":2272.11,"id":9632596},{"batl":[[0,3.9,174.3],[1,3.9,0]],"ltp":3.05,"tv":3027.98,"id":9433864}]}]}
{"op":"mcm","clk":"4233692027","pt":1631537654669,"mc":[{"id":"1.187557653","rc":[{"batb":[[0,2.78,39.73],[1,2.76,17.74],[2,2.42,25.61]],"ltp":3.05,"tv":3027.98,"id":9433864}]}]}
{"op":"mcm","clk":"4233692137","pt":1631537656283,"mc":[{"id":"1.187557653","rc":[{"batl":[[0,3.3,195.35],[1,3.9,174.3]],"ltp":3.05,"tv":3027.98,"id":9433864}]}]}
{"op":"mcm","clk":"4233692149","pt":1631537656491,"mc":[{"id":"1.187557653","rc":[{"batl":[[0,3.9,174.3],[1,3.9,0]],"ltp":3.05,"tv":3027.98,"id":9433864}]}]}
{"op":"mcm","clk":"4233692268","pt":1631537658365,"mc":[{"id":"1.187557653","rc":[{"batl":[[0,1.52,19.78]],"ltp":1.48,"tv":2272.11,"id":9632596}]}]}
{"op":"mcm","clk":"4233692389","pt":1631537659674,"mc":[{"id":"1.187557653","rc":[{"batl":[[0,3.8,131.25],[1,3.9,174.3]],"ltp":3.05,"tv":3027.98,"id":9433864}]}]}
{"op":"mcm","clk":"4233692613","pt":1631537662288,"mc":[{"id":"1.187557653","rc":[{"batb":[[0,1.47,196.27]],"batl":[[0,1.5,9.09],[1,1.52,19.78],[2,1.53,9.86]],"ltp":1.48,"tv":2272.11,"id":9632596},{"batb":[[0,3,4.54],[1,2.78,39.73],[2,2.76,17.74]],"ltp":3.05,"tv":3027.98,"id":9433864}]}]}
{"op":"mcm","clk":"4233692652","pt":1631537663008,"mc":[{"id":"1.187557653","rc":[{"trd":[[1.47,392.49],[1.5,32.12],[1.51,1.97],[1.52,13.58]],"batb":[[0,1.46,20.54],[1,1.45,81.41],[2,1.44,10.28]],"batl":[[0,1.47,175.39],[1,1.52,12.95]],"ltp":1.47,"tv":2705.52,"id":9632596},{"trd":[[3,6.97]],"batb":[[0,2.76,17.74],[1,2.42,25.61],[2,2.04,373.96]],"ltp":3.0,"tv":3032.52,"id":9433864}],"tv":5738.04}]}
{"op":"mcm","clk":"4233692681","pt":1631537663479,"mc":[{"id":"1.187557653","rc":[{"batl":[[0,3.9,174.3],[1,3.9,0]],"ltp":3.0,"tv":3032.52,"id":9433864}]}]}
{"op":"mcm","clk":"4233692799","pt":1631537665607,"mc":[{"id":"1.187557653","rc":[{"batb":[[0,2.78,39.73],[1,2.76,17.74],[2,2.42,25.61]],"ltp":3.0,"tv":3032.52,"id":9433864}]}]}
{"op":"mcm","clk":"4233692849","pt":1631537666598,"mc":[{"id":"1.187557653","rc":[{"trd":[[1.47,403.41]],"batl":[[0,1.47,164.47],[1,1.5,8.44],[2,1.52,12.95]],"ltp":1.47,"tv":2716.44,"id":9632596},{"trd":[[3.1,5.18]],"batb":[[0,3,4.22]],"batl":[[0,3.6,52.95],[1,3.9,174.3]],"ltp":3.1,"tv":3037.7,"id":9433864}],"tv":5754.14}]}
{"op":"mcm","clk":"4233693232","pt":1631537672604,"mc":[{"id":"1.187557653","rc":[{"batl":[[1,1.52,12.95],[2,1.53,9.86]],"ltp":1.47,"tv":2716.44,"id":9632596},{"batb":[[0,2.76,17.74],[1,2.42,25.61],[2,2.04,373.96]],"ltp":3.1,"tv":3037.7,"id":9433864}]}]}
{"op":"mcm","clk":"4233693465","pt":1631537676090,"mc":[{"id":"1.187557653","rc":[{"batl":[[0,3.9,174.3],[1,3.9,0]],"ltp":3.1,"tv":3037.7,"id":9433864}]}]}
{"op":"mcm","clk":"4233693562","pt":1631537677816,"mc":[{"id":"1.187557653","rc":[{"batb":[[0,1.45,71.13],[1,1.37,92.89],[2,1.01,113.7]],"batl":[[1,1.6,0.21],[2,1.53,0]],"ltp":1.47,"tv":2716.44,"id":9632596}]}]}
{"op":"mcm","clk":"4233693670","pt":1631537679223,"mc":[{"id":"1.187557653","rc":[{"batb":[[0,1.37,92.89],[1,1.01,113.7],[2,1.01,0]],"ltp":1.47,"tv":2716.44,"id":9632596},{"batb":[[0,2.42,25.61],[1,2.04,373.96],[2,1.46,2]],"ltp":3.1,"tv":3037.7,"id":9433864}]}]}
{"op":"mcm","clk":"4233693729","pt":1631537680001,"mc":[{"id":"1.187557653","rc":[{"batb":[[2,2.02,2.13]],"ltp":3.1,"tv":3037.7,"id":9433864}]}]}
{"op":"mcm","clk":"4233694895","pt":1631537698845,"mc":[{"id":"1.187557653","rc":[{"batb":[[1,2.02,2.13],[2,1.46,2]],"ltp":3.1,"tv":3037.7,"id":9433864}]}]}
{"op":"mcm","clk":"4233694977","pt":1631537700142,"mc":[{"id":"1.187557653","rc":[{"batl":[[0,1.4,6.24],[1,1.41,141.84],[2,1.47,164.47]],"ltp":1.47,"tv":2716.44,"id":9632596},{"batb":[[0,3.35,44.78],[1,3.3,98.51],[2,3.25,22.4]],"batl":[[0,3.6,4.48],[1,3.7,60.18]],"ltp":3.1,"tv":3037.7,"id":9433864}]}]}
{"op":"mcm","clk":"4233695059","pt":1631537701148,"mc":[{"id":"1.187557653","rc":[{"trd":[[1.4,6.24],[1.41,1.28]],"batb":[[1,1.33,40.77],[2,1.31,20.69]],"batl":[[0,1.41,83.82],[1,1.47,201.35],[2,1.49,18.2]],"ltp":1.41,"tv":2723.96,"id":9632596},{"trd":[[3.4,0.53],[3.5,2.5]],"batb":[[0,3.35,26.87],[1,3.3,89.55],[2,3.25,13.44]],"batl":[[2,3.75,40]],"ltp":3.4,"tv":3040.73,"id":9433864}],"tv":5764.69}]}
{"op":"mcm","clk":"4233695127","pt":1631537702149,"mc":[{"id":"1.187557653","rc":[{"batl":[[2,3.75,8]],"ltp":3.4,"tv":3040.73,"id":9433864}]}]}
{"op":"mcm","clk":"4233695298","pt":1631537705170,"mc":[{"id":"1.187557653","rc":[{"batl":[[0,1.4,17.48],[1,1.41,83.82],[2,1.47,201.35]],"ltp":1.41,"tv":2723.96,"id":9632596},{"batl":[[1,3.7,105.62]],"ltp":3.4,"tv":3040.73,"id":9433864}]}]}
{"op":"mcm","clk":"4233695308","pt":1631537705371,"mc":[{"id":"1.187557653","rc":[{"batl":[[0,1.41,83.82],[1,1.47,201.35],[2,1.49,18.2]],"ltp":1.41,"tv":2723.96,"id":9632596},{"batl":[[1,3.7,60.18]],"ltp":3.4,"tv":3040.73,"id":9433864}]}]}
{"op":"mcm","clk":"4233695502","pt":1631537707886,"mc":[{"id":"1.187557653","rc":[{"batl":[[1,1.47,250.85]],"ltp":1.41,"tv":2723.96,"id":9632596}]}]}
{"op":"mcm","clk":"4233695588","pt":1631537708880,"mc":[{"id":"1.187557653","rc":[{"trd":[[1.41,1.98]],"batb":[[2,1.32,81.14]],"batl":[[0,1.41,83.47],[1,1.47,86.39]],"ltp":1.41,"tv":2724.66,"id":9632596}],"tv":5765.39}]}
{"op":"mcm","clk":"4233695610","pt":1631537709296,"mc":[{"id":"1.187557653","rc":[{"batb":[[2,1.31,20.69]],"ltp":1.41,"tv":2724.66,"id":9632596}]}]}
{"op":"mcm","clk":"4233695729","pt":1631537711287,"mc":[{"id":"1.187557653","rc":[{"batb":[[1,1.33,109.3]],"ltp":1.41,"tv":2724.66,"id":9632596},{"batl":[[0,3.7,60.18],[1,3.75,8],[2,3.8,4]],"ltp":3.4,"tv":3040.73,"id":9433864}]}]}
{"op":"mcm","clk":"4233695741","pt":1631537711483,"mc":[{"id":"1.187557653","rc":[{"batb":[[1,1.33,40.77]],"ltp":1.41,"tv":2724.66,"id":9632596}]}]}
{"op":"mcm","clk":"4233695845","pt":1631537713178,"mc":[{"id":"1.187557653","rc":[{"batb":[[1,1.3,116.4],[2,1.01,113.7]],"batl":[[0,1.47,49.5],[1,1.5,53.29],[2,1.6,0.21]],"ltp":1.41,"tv":2724.66,"id":9632596},{"batb":[[0,3.15,31.46],[1,2.78,43.6],[2,2.22,366.63]],"batl":[[0,4.6,149.87],[1,3.75,0],[2,3.8,0]],"ltp":3.4,"tv":3040.73,"id":9433864}]}]}
{"op":"mcm","clk":"4233695855","pt":1631537713383,"mc":[{"id":"1.187557653","rc":[{"batb":[[0,1.3,116.4],[1,1.01,113.7],[2,1.01,0]],"batl":[[0,1.5,53.29],[1,1.6,0.21],[2,1.6,0]],"ltp":1.41,"tv":2724.66,"id":9632596},{"batb":[[0,2.78,43.6],[1,2.22,366.63],[2,2.02,2.13]],"ltp":3.4,"tv":3040.73,"id":9433864}]}]}
{"op":"mcm","clk":"4233695977","pt":1631537714996,"mc":[{"id":"1.187557653","rc":[{"batb":[[0,1.33,70.53],[1,1.3,116.4],[2,1.01,113.7]],"ltp":1.41,"tv":2724.66,"id":9632596},{"batb":[[0,3,5],[1,2.78,43.6],[2,2.22,366.63]],"ltp":3.4,"tv":3040.73,"id":9433864}]}]}
{"op":"mcm","clk":"4233696065","pt":1631537716203,"mc":[{"id":"1.187557653","rc":[{"batb":[[1,1.32,75.39],[2,1.3,116.4]],"ltp":1.41,"tv":2724.66,"id":9632596},{"batl":[[0,4.1,68.78],[1,4.6,149.87]],"ltp":3.4,"tv":3040.73,"id":9433864}]}]}
{"op":"mcm","clk":"4233696129","pt":1631537717199,"mc":[{"id":"1.187557653","rc":[{"batl":[[0,3.6,153.38],[1,4.1,3.15],[2,4.6,149.87]],"ltp":3.4,"tv":3040.73,"id":9433864}]}]}
{"op":"mcm","clk":"4233696195","pt":1631537718192,"mc":[{"id":"1.187557653","rc":[{"batb":[[0,3.1,4.14],[1,3,5],[2,2.78,43.6]],"batl":[[0,4.1,3.15],[1,4.6,149.87],[2,4.6,0]],"ltp":3.4,"tv":3040.73,"id":9433864}]}]}
{"op":"mcm","clk":"4233696207","pt":1631537718399,"mc":[{"id":"1.187557653","rc":[{"batb":[[0,3,5],[1,2.78,43.6],[2,2.22,366.63]],"ltp":3.4,"tv":3040.73,"id":9433864}]}]}
{"op":"mcm","clk":"4233696294","pt":1631537720118,"mc":[{"id":"1.187557653","rc":[{"batl":[[0,1.47,57.5],[1,1.5,53.29],[2,1.6,0.21]],"ltp":1.41,"tv":2724.66,"id":9632596}]}]}
{"op":"mcm","clk":"4233696310","pt":1631537720483,"mc":[{"id":"1.187557653","rc":[{"batl":[[0,1.5,53.29],[1,1.6,0.21],[2,1.6,0]],"ltp":1.41,"tv":2724.66,"id":9632596}]}]}
{"op":"mcm","clk":"4233696588","pt":1631537725116,"mc":[{"id":"1.187557653","rc":[{"batb":[[0,3.1,3.74],[1,3,5],[2,2.78,43.6]],"ltp":3.4,"tv":3040.73,"id":9433864}]}]}
{"op":"mcm","clk":"4233696611","pt":1631537725490,"mc":[{"id":"1.187557653","rc":[{"batb":[[0,3,5],[1,2.78,43.6],[2,2.22,366.63]],"ltp":3.4,"tv":3040.73,"id":9433864}]}]}
{"op":"mcm","clk":"4233696733","pt":1631537727208,"mc":[{"id":"1.187557653","rc":[{"trd":[[1.33,141.07]],"batb":[[0,1.32,75.39],[1,1.3,116.4],[2,1.01,113.7]],"batl":[[0,1.33,170.63],[1,1.47,52.5],[2,1.5,53.29]],"ltp":1.33,"tv":2865.73,"id":9632596}],"tv":5906.46}]}
{"op":"mcm","clk":"4233696815","pt":1631537728721,"mc":[{"id":"1.187557653","rc":[{"batb":[[0,3.1,4.14],[1,3,5],[2,2.78,43.6]],"batl":[[1,4.6,0]],"ltp":3.4,"tv":3040.73,"id":9433864}]}]}
{"op":"mcm","clk":"4233696877","pt":1631537729814,"mc":[{"id":"1.187557653","rc":[{"trd":[[1.33,482.32]],"batb":[[0,1.33,47.16],[1,1.32,75.39],[2,1.3,116.4]],"batl":[[0,1.35,18.53],[1,1.36,59.63],[2,1.37,11.02]],"ltp":1.33,"tv":3206.98,"id":9632596},{"batb":[[0,3.75,57.85]],"batl":[[0,4,4.14],[1,4.1,3.15],[2,4.2,77.98]],"ltp":3.4,"tv":3040.73,"id":9433864}],"tv":6247.71}]}
{"op":"mcm","clk":"4233696952","pt":1631537731023,"mc":[{"id":"1.187557653","rc":[{"trd":[[1.35,7.81]],"batl":[[0,1.35,10.72]],"ltp":1.35,"tv":3214.79,"id":9632596},{"trd":[[3.85,2.74]],"batb":[[1,3.55,23.18],[2,3.2,29.29]],"batl":[[2,4.2,85.12]],"ltp":3.85,"tv":3043.47,"id":9433864}],"tv":6258.26}]}
{"op":"mcm","clk":"4233697274","pt":1631537736419,"mc":[{"id":"1.187557653","rc":[{"batb":[[0,1.33,141.16]],"ltp":1.35,"tv":3214.79,"id":9632596}]}]}
{"op":"mcm","clk":"4233697338","pt":1631537737466,"mc":[{"id":"1.187557653","rc":[{"batb":[[2,1.31,81.79]],"ltp":1.35,"tv":3214.79,"id":9632596},{"batb":[[1,3.6,3.04],[2,3.55,23.18]],"batl":[[2,4.2,87.8]],"ltp":3.85,"tv":3043.47,"id":9433864}]}]}
{"op":"mcm","clk":"4233697539","pt":1631537740724,"mc":[{"id":"1.187557653","rc":[{"batl":[[0,1.36,59.63],[1,1.37,11.02],[2,1.38,77.77]],"ltp":1.35,"tv":3214.79,"id":9632596},{"batl":[[0,4.1,3.15],[1,4.2,87.8],[2,4.3,6.13]],"ltp":3.85,"tv":3043.47,"id":9433864}]}]}
{"op":"mcm","clk":"4233697734","pt":1631537743719,"mc":[{"id":"1.187557653","rc":[{"batb":[[0,3.85,4.3],[1,3.75,57.85],[2,3.6,3.04]],"batl":[[0,4,6.78],[1,4.1,3.15],[2,4.2,87.8]],"ltp":3.85,"tv":3043.47,"id":9433864}]}]}
{"op":"mcm","clk":"4233698048","pt":1631537749230,"mc":[{"id":"1.187557653","rc":[{"batb":[[0,1.33,94],[1,1.31,81.79],[2,1.27,133.47]],"batl":[[0,1.4,59.34],[1,1.6,0.21],[2,1.38,0]],"ltp":1.35,"tv":3214.79,"id":9632596},{"batb":[[0,3.2,29.29],[1,2.38,366.06],[2,2.02,2.13]],"batl":[[0,4.3,2.55],[1,5.3,130.72],[2,4.2,0]],"ltp":3.85,"tv":3043.47,"id":9433864}]}]}
{"op":"mcm","clk":"4233698085","pt":1631537749855,"mc":[{"id":"1.187557653","rc":[{"batb":[[0,1.31,81.79],[1,1.27,133.47],[2,1.01,113.7]],"ltp":1.35,"tv":3214.79,"id":9632596}]}]}
{"op":"mcm","clk":"4233698230","pt":1631537752159,"mc":[{"id":"1.187557653","rc":[{"batb":[[0,1.32,73.89],[1,1.31,81.79],[2,1.27,133.47]],"batl":[[0,1.38,66.25],[1,1.4,59.34],[2,1.6,0.21]],"ltp":1.35,"tv":3214.79,"id":9632596},{"batb":[[0,3.6,3.59],[1,3.5,3.28],[2,3.2,29.29]],"batl":[[0,4.2,2.38],[1,4.3,2.55],[2,5.3,130.72]],"ltp":3.85,"tv":3043.47,"id":9433864}]}]}
{"op":"mcm","clk":"4233698241","pt":1631537752369,"mc":[{"id":"1.187557653","rc":[{"batb":[[0,1.31,81.79],[1,1.27,133.47],[2,1.01,113.7]],"batl":[[0,1.4,59.34],[1,1.6,0.21],[2,1.6,0]],"ltp":1.35,"tv":3214.79,"id":9632596},{"batb":[[0,3.5,3.28],[1,3.2,29.29],[2,2.38,366.06]],"batl":[[0,4.3,2.55],[1,5.3,130.72],[2,5.3,0]],"ltp":3.85,"tv":3043.47,"id":9433864}]}]}
{"op":"mcm","clk":"4233699107","pt":1631537765990,"mc":[{"id":"1.187557653","rc":[{"batb":[[0,1.32,87.89],[1,1.31,81.79],[2,1.27,133.47]],"batl":[[0,1.38,64.75],[1,1.4,59.34],[2,1.6,0.21]],"ltp":1.35,"tv":3214.79,"id":9632596},{"batb":[[0,3.6,3.09],[1,3.5,3.28],[2,3.2,29.29]],"batl":[[0,4.2,2.78],[1,4.3,2.55],[2,5.3,130.72]],"ltp":3.85,"tv":3043.47,"id":9433864}]}]}
{"op":"mcm","clk":"4233699132","pt":1631537766304,"mc":[{"id":"1.187557653","rc":[{"batb":[[0,1.31,81.79],[1,1.27,133.47],[2,1.01,113.7]],"batl":[[0,1.4,59.34],[1,1.6,0.21],[2,1.6,0]],"ltp":1.35,"tv":3214.79,"id":9632596},{"batb":[[0,3.5,3.28],[1,3.2,29.29],[2,2.38,366.06]],"batl":[[0,4.3,2.55],[1,5.3,130.72],[2,5.3,0]],"ltp":3.85,"tv":3043.47,"id":9433864}]}]}
{"op":"mcm","clk":"4233699318","pt":1631537769594,"mc":[{"id":"1.187557653","rc":[{"batb":[[0,1.32,85.89],[1,1.31,81.79],[2,1.27,133.47]],"batl":[[0,1.38,66.25],[1,1.4,59.34],[2,1.6,0.21]],"ltp":1.35,"tv":3214.79,"id":9632596},{"batb":[[0,3.6,2.94],[1,3.5,3.28],[2,3.2,29.29]],"batl":[[0,4.2,2.83],[1,4.3,2.55],[2,5.3,130.72]],"ltp":3.85,"tv":3043.47,"id":9433864}]}]}
{"op":"mcm","clk":"4233699393","pt":1631537770973,"mc":[{"id":"1.187557653","rc":[{"batl":[[2,5.3,0]],"ltp":3.85,"tv":3043.47,"id":9433864}]}]}
{"op":"mcm","clk":"4233699704","pt":1631537776217,"mc":[{"id":"1.187557653","rc":[{"batb":[[0,1.31,81.79],[1,1.27,133.47],[2,1.01,113.7]],"batl":[[0,1.4,59.34],[1,1.6,0.21],[2,1.6,0]],"ltp":1.35,"tv":3214.79,"id":9632596},{"batb":[[0,3.2,29.29],[1,2.02,2.13],[2,1.46,2]],"batl":[[0,4.3,2.55],[1,4.3,0]],"ltp":3.85,"tv":3043.47,"id":9433864}]}]}
{"op":"mcm","clk":"4233699891","pt":1631537779093,"mc":[{"id":"1.187557653","rc":[{"batb":[[0,1.34,21.22],[1,1.31,81.79],[2,1.27,133.47]],"batl":[[0,1.35,19.7],[1,1.4,59.34],[2,1.6,0.21]],"ltp":1.35,"tv":3214.79,"id":9632596},{"batl":[[0,3.95,19.7],[1,4.3,2.55]],"ltp":3.85,"tv":3043.47,"id":9433864}]}]}
{"op":"mcm","clk":"4233699920","pt":1631537779615,"mc":[{"id":"1.187557653","rc":[{"batb":[[0,1.31,81.79],[1,1.27,133.47],[2,1.01,113.7]],"batl":[[0,1.4,59.34],[1,1.6,0.21],[2,1.6,0]],"ltp":1.35,"tv":3214.79,"id":9632596},{"batb":[[0,3.5,3.24],[1,3.2,29.29],[2,2.02,2.13]],"batl":[[0,4.3,2.55],[1,4.3,0]],"ltp":3.85,"tv":3043.47,"id":9433864}]}]}
{"op":"mcm","clk":"4233700153","pt":1631537783897,"mc":[{"id":"1.187557653","rc":[{"trd":[[1.31,40]],"batb":[[0,1.32,41.07],[1,1.31,61.79],[2,1.3,20.85]],"batl":[[0,1.39,13.07],[1,1.4,59.34],[2,1.41,170.03]],"ltp":1.31,"tv":3254.79,"id":9632596},{"trd":[[3.5,8.3]],"batb":[[0,3.2,29.63],[1,2.02,2.13],[2,1.46,2]],"batl":[[0,3.7,6.96],[1,3.85,23.38],[2,3.9,11.69]],"ltp":3.5,"tv":3049.27,"id":9433864}],"tv":6304.06}]}
{"op":"mcm","clk":"4233700228","pt":1631537785201,"mc":[{"id":"1.187557653","rc":[{"batb":[[0,1.35,98.07],[1,1.32,41.07],[2,1.31,61.79]],"ltp":1.31,"tv":3254.79,"id":9632596},{"batb":[[0,3.45,43.82],[1,3.4,13.04],[2,3.35,13.04]],"batl":[[1,3.85,7.8],[2,3.9,3.9]],"ltp":3.5,"tv":3049.27,"id":9433864}]}]}
{"op":"mcm","clk":"4233700267","pt":1631537785832,"mc":[{"id":"1.187557653","rc":[{"batb":[[0,3.45,26.43]],"ltp":3.5,"tv":3049.27,"id":9433864}]}]}
{"op":"mcm","clk":"4233700405","pt":1631537787724,"mc":[{"id":"1.187557653","rc":[{"trd":[[3.7,13.92],[3.85,18.34]],"batb":[[0,3.45,9.28],[1,3.4,4.34],[2,3.35,4.34]],"batl":[[0,3.9,3.9],[1,3.95,34.28],[2,4,139.98]],"ltp":3.85,"tv":3078.79,"id":9433864}],"tv":6333.58}]}
{"op":"mcm","clk":"4233700484","pt":1631537788714,"mc":[{"id":"1.187557653","rc":[{"trd":[[3.85,18.82]],"batb":[[0,3.45,9.04]],"ltp":3.85,"tv":3079.27,"id":9433864}],"tv":6334.06}]}
{"op":"mcm","clk":"4233700609","pt":1631537790906,"mc":[{"id":"1.187557653","rc":[{"batb":[[1,1.33,82.53],[2,1.32,41.07]],"ltp":1.31,"tv":3254.79,"id":9632596}]}]}
{"op":"mcm","clk":"4233700662","pt":1631537791693,"mc":[{"id":"1.187557653","rc":[{"batb":[[0,1.36,136],[1,1.35,98.07],[2,1.33,82.53]],"ltp":1.31,"tv":3254.79,"id":9632596}]}]}
{"op":"mcm","clk":"4233701001","pt":1631537796644,"mc":[{"id":"1.187557653","rc":[{"batl":[[0,1.39,14]],"ltp":1.31,"tv":3254.79,"id":9632596}]}]}
{"op":"mcm","clk":"4233701087","pt":1631537798051,"mc":[{"id":"1.187557653","rc":[{"batb":[[1,1.33,82.53],[2,1.31,61.79]],"batl":[[0,1.45,64.23],[1,1.6,0.21],[2,1.41,0]],"ltp":1.31,"tv":3254.79,"id":9632596},{"batb":[[0,3.2,3.97],[1,2.84,41.17],[2,2.3,368.04]],"batl":[[0,4.1,2.65],[1,4.3,2.55],[2,4.9,139.05]],"ltp":3.85,"tv":3079.27,"id":9433864}]}]}
{"op":"mcm","clk":"4233701151","pt":1631537799143,"mc":[{"id":"1.187557653","rc":[{"batb":[[0,1.31,61.79],[1,1.29,122.01],[2,1.01,113.7]],"ltp":1.31,"tv":3254.79,"id":9632596},{"batl":[[0,4.3,2.55],[1,4.9,139.05],[2,4.9,0]],"ltp":3.85,"tv":3079.27,"id":9433864}]}]}
{"op":"mcm","clk":"4233701263","pt":1631537801125,"mc":[{"id":"1.187557653","rc":[{"batl":[[0,1.43,63.43],[1,1.45,63.3],[2,1.6,0.21]],"ltp":1.31,"tv":3254.79,"id":9632596},{"batb":[[0,3.3,4.28],[1,3.2,3.97],[2,2.84,41.17]],"ltp":3.85,"tv":3079.27,"id":9433864}]}]}
{"op":"mcm","clk":"4233701280","pt":1631537801437,"mc":[{"id":"1.187557653","rc":[{"batl":[[0,1.45,64.23],[1,1.6,0.21],[2,1.6,0]],"ltp":1.31,"tv":3254.79,"id":9632596},{"batb":[[0,3.2,3.97],[1,2.84,41.17],[2,2.3,368.04]],"ltp":3.85,"tv":3079.27,"id":9433864}]}]}
{"op":"mcm","clk":"4233701663","pt":1631537808285,"mc":[{"id":"1.187557653","rc":[{"batl":[[0,1.43,61.43],[1,1.45,63.3],[2,1.6,0.21]],"ltp":1.31,"tv":3254.79,"id":9632596},{"batb":[[0,3.3,3.78],[1,3.2,3.97],[2,2.84,41.17]],"ltp":3.85,"tv":3079.27,"id":9433864}]}]}
{"op":"mcm","clk":"4233701680","pt":1631537808450,"mc":[{"id":"1.187557653","rc":[{"batl":[[0,1.45,64.23],[1,1.6,0.21],[2,1.6,0]],"ltp":1.31,"tv":3254.79,"id":9632596},{"batb":[[0,3.2,3.97],[1,2.84,41.17],[2,2.3,368.04]],"batl":[[1,4.9,0]],"ltp":3.85,"tv":3079.27,"id":9433864}]}]}
{"op":"mcm","clk":"4233701785","pt":1631537809957,"mc":[{"id":"1.187557653","rc":[{"trd":[[1.37,0.93]],"batb":[[0,1.43,14.88],[1,1.38,39.29],[2,1.36,19.93]],"batl":[[0,1.45,75.56],[1,1.52,35.67],[2,1.54,17.61]],"ltp":1.37,"tv":3255.72,"id":9632596},{"trd":[[3.2,6.46],[3.7,14.26]],"batb":[[0,3.05,71.14]],"batl":[[0,3.3,60.6],[1,3.4,8.82],[2,3.45,4.42]],"ltp":3.2,"tv":3086.07,"id":9433864}],"tv":6341.79}]}
{"op":"mcm","clk":"4233701847","pt":1631537810945,"mc":[{"id":"1.187557653","rc":[{"batb":[[0,1.43,90.36]],"batl":[[1,1.47,20.4],[2,1.48,10.2]],"ltp":1.37,"tv":3255.72,"id":9632596},{"batb":[[2,2.36,27.36]],"ltp":3.2,"tv":3086.07,"id":9433864}]}]}
{"op":"mcm","clk":"4233701952","pt":1631537812776,"mc":[{"id":"1.187557653","rc":[{"trd":[[1.43,29.76]],"batb":[[0,1.43,75.48]],"ltp":1.43,"tv":3285.48,"id":9632596}],"tv":6371.55}]}
{"op":"mcm","clk":"4233702005","pt":1631537813768,"mc":[{"id":"1.187557653","rc":[{"batb":[[0,1.43,158.48]],"ltp":1.43,"tv":3285.48,"id":9632596}]}]}
{"op":"mcm","clk":"4233702161","pt":1631537816679,"mc":[{"id":"1.187557653","rc":[{"batb":[[2,2.68,4.61]],"ltp":3.2,"tv":3086.07,"id":9433864}]}]}
{"op":"mcm","clk":"4233702605","pt":1631537822983,"mc":[{"id":"1.187557653","rc":[{"batl":[[0,1.45,63.3]],"ltp":1.43,"tv":3285.48,"id":9632596}]}]}
{"op":"mcm","clk":"4233702762","pt":1631537825898,"mc":[{"id":"1.187557653","rc":[{"batb":[[1,1.42,14.43],[2,1.38,39.29]],"batl":[[0,1.44,13.77],[1,1.45,63.3],[2,1.47,20.4]],"ltp":1.43,"tv":3285.48,"id":9632596}]}]}
{"op":"mcm","clk":"4233702821","pt":1631537827091,"mc":[{"id":"1.187557653","rc":[{"batb":[[2,1.31,174.42]],"ltp":1.43,"tv":3285.48,"id":9632596}]}]}
{"op":"mcm","clk":"4233702949","pt":1631537829383,"mc":[{"id":"1.187557653","rc":[{"batb":[[2,2.72,4.84]],"ltp":3.2,"tv":3086.07,"id":9433864}]}]}
{"op":"mcm","clk":"4233703110","pt":1631537832296,"mc":[{"id":"1.187557653","rc":[{"batb":[[0,3.05,146.7]],"ltp":3.2,"tv":3086.07,"id":9433864}]}]}
{"op":"mcm","clk":"4233703341","pt":1631537836197,"mc":[{"id":"1.187557653","rc":[{"batb":[[1,1.31,174.42],[2,1.01,113.7]],"batl":[[0,1.45,63.3],[1,1.58,38.25],[2,1.59,44.5]],"ltp":1.43,"tv":3285.48,"id":9632596},{"batb":[[0,3.05,76.3]],"batl":[[0,4.2,163.07],[1,4.3,2.55],[2,3.45,0]],"ltp":3.2,"tv":3086.07,"id":9433864}]}]}
{"op":"mcm","clk":"4233703378","pt":1631537836820,"mc":[{"id":"1.187557653","rc":[{"batb":[[0,1.31,112.63],[1,1.01,113.7],[2,1.01,0]],"batl":[[0,1.64,39.64],[1,1.58,0],[2,1.59,0]],"ltp":1.43,"tv":3285.48,"id":9632596},{"batb":[[0,2.56,4.83],[1,2.36,27.36],[2,2.3,368.04]],"batl":[[1,4.3,0]],"ltp":3.2,"tv":3086.07,"id":9433864}]}]}
{"op":"mcm","clk":"4233703402","pt":1631537837311,"mc":[{"id":"1.187557653","rc":[{"batb":[[0,1.44,25],[1,1.31,112.63],[2,1.01,113.7]],"ltp":1.43,"tv":3285.48,"id":9632596}]}]}
{"op":"mcm","clk":"4233704539","pt":1631537857224,"mc":[{"id":"1.187557653","rc":[{"batl":[[0,1.59,45.5],[1,1.64,39.64]],"ltp":1.43,"tv":3285.48,"id":9632596},{"batb":[[0,2.68,5.36],[1,2.56,4.83],[2,2.36,27.36]],"ltp":3.2,"tv":3086.07,"id":9433864}]}]}
{"op":"mcm","clk":"4233704568","pt":1631537857638,"mc":[{"id":"1.187557653","rc":[{"batb":[[0,1.31,112.63],[1,1.01,113.7],[2,1.01,0]],"batl":[[0,1.64,39.64],[1,1.64,0]],"ltp":1.43,"tv":3285.48,"id":9632596},{"batb":[[0,2.56,4.83],[1,2.36,27.36],[2,2.3,368.04]],"ltp":3.2,"tv":3086.07,"id":9433864}]}]}
{"op":"mcm","clk":"4233705097","pt":1631537866958,"mc":[{"id":"1.187557653","rc":[{"batl":[[0,1.6,0.21]],"ltp":1.43,"tv":3285.48,"id":9632596}]}]}
{"op":"mcm","clk":"4233705259","pt":1631537869891,"mc":[{"id":"1.187557653","rc":[{"batb":[[1,1.28,42.36],[2,1.26,21.52]],"batl":[[0,1.33,17.56],[1,1.35,59.5],[2,1.41,38.45]],"ltp":1.43,"tv":3285.48,"id":9632596},{"batb":[[0,3.85,6.97],[1,3.8,23.69],[2,3.75,11.84]],"batl":[[0,4.2,5.74],[1,4.3,82.32]],"ltp":3.2,"tv":3086.07,"id":9433864}]}]}
{"op":"mcm","clk":"4233705317","pt":1631537870881,"mc":[{"id":"1.187557653","rc":[{"trd":[[1.33,490.44]],"batl":[[0,1.33,9.44]],"ltp":1.33,"tv":3293.6,"id":9632596},{"trd":[[4,2.7]],"batb":[[1,3.8,7.9],[2,3.75,3.94]],"batl":[[0,4.2,12.88],[1,4.3,85.9],[2,4.4,3.58]],"ltp":4.0,"tv":3088.77,"id":9433864}],"tv":6382.37}]}
{"op":"mcm","clk":"4233705972","pt":1631537880684,"mc":[{"id":"1.187557653","rc":[{"batl":[[0,1.35,59.5],[1,1.41,38.45],[2,1.43,18.96]],"ltp":1.33,"tv":3293.6,"id":9632596},{"batl":[[0,4.2,7.14]],"ltp":4.0,"tv":3088.77,"id":9433864}]}]}
{"op":"mcm","clk":"4233706147","pt":1631537883618,"mc":[{"id":"1.187557653","rc":[{"batb":[[0,4,5.29],[1,3.85,6.97],[2,3.8,7.9]],"batl":[[0,4.2,15.45]],"ltp":4.0,"tv":3088.77,"id":9433864}]}]}
{"op":"mcm","clk":"4233706298","pt":1631537885790,"mc":[{"id":"1.187557653","rc":[{"batb":[[0,1.33,35],[1,1.31,112.63],[2,1.28,42.36]],"ltp":1.33,"tv":3293.6,"id":9632596}]}]}
{"op":"mcm","clk":"4233706884","pt":1631537894732,"mc":[{"id":"1.187557653","rc":[{"trd":[[4,13.28]],"batb":[[0,3.85,6.97],[1,3.8,7.9],[2,3.75,3.94]],"batl":[[0,4,11.75],[1,4.2,15.45],[2,4.3,85.9]],"ltp":4.0,"tv":3099.35,"id":9433864}],"tv":6392.95}]}
{"op":"mcm","clk":"4233707027","pt":1631537897245,"mc":[{"id":"1.187557653","rc":[{"batl":[[0,4.2,15.45],[1,4.3,85.9],[2,4.4,3.58]],"ltp":4.0,"tv":3099.35,"id":9433864}]}]}
{"op":"mcm","clk":"4233707471","pt":1631537903545,"mc":[{"id":"1.187557653","rc":[{"batb":[[0,1.31,112.63],[1,1.28,42.36],[2,1.26,21.52]],"ltp":1.33,"tv":3293.6,"id":9632596}]}]}
{"op":"mcm","clk":"4233707553","pt":1631537905061,"mc":[{"id":"1.187557653","rc":[{"batl":[[0,4.2,7.14]],"ltp":4.0,"tv":3099.35,"id":9433864}]}]}
{"op":"mcm","clk":"4233707640","pt":1631537906837,"mc":[{"id":"1.187557653","rc":[{"trd":[[1.33,497.33],[1.35,14.93]],"batl":[[0,1.41,38.45],[1,1.43,18.96],[2,1.45,808.1]],"ltp":1.35,"tv":3307.61,"id":9632596},{"trd":[[3.85,35.25],[4,15.56]],"batb":[[0,3.8,7.9],[1,3.75,3.94],[2,3.7,3.94]],"ltp":3.85,"tv":3118.06,"id":9433864}],"tv":6425.68}]}
{"op":"mcm","clk":"4233707706","pt":1631537907936,"mc":[{"id":"1.187557653","rc":[{"batl":[[0,1.34,12.58],[1,1.41,38.45],[2,1.43,18.96]],"ltp":1.35,"tv":3307.61,"id":9632596},{"batl":[[0,4.1,6.89],[1,4.2,7.14],[2,4.3,85.9]],"ltp":3.85,"tv":3118.06,"id":9433864}]}]}
{"op":"mcm","clk":"4233707859","pt":1631537910352,"mc":[{"id":"1.187557653","rc":[{"trd":[[1.34,0.08]],"batl":[[0,1.34,12.54]],"ltp":1.34,"tv":3307.69,"id":9632596}],"tv":6425.75}]}
{"op":"mcm","clk":"4233708215","pt":1631537916532,"mc":[{"id":"1.187557653","rc":[{"trd":[[1.31,167.58],[1.32,21.41]],"batb":[[0,1.31,48.83]],"ltp":1.31,"tv":3456.67,"id":9632596},{"trd":[[4.1,6.89]],"batl":[[0,4.2,7.14],[1,4.3,85.9],[2,4.4,3.58]],"ltp":4.1,"tv":3124.95,"id":9433864}],"tv":6581.63}]}
{"op":"mcm","clk":"4233708331","pt":1631537918537,"mc":[{"id":"1.187557653","rc":[{"trd":[[1.34,25.16]],"batb":[[0,1.34,12.46],[1,1.31,48.83],[2,1.28,42.36]],"batl":[[0,1.41,38.45],[1,1.43,18.96],[2,1.45,808.1]],"ltp":1.34,"tv":3481.75,"id":9632596}],"tv":6606.71}]}
{"op":"mcm","clk":"4233708437","pt":1631537920251,"mc":[{"id":"1.187557653","rc":[{"batb":[[1,1.31,114.94]],"ltp":1.34,"tv":3481.75,"id":9632596}]}]}
{"op":"mcm","clk":"4233708516","pt":1631537921669,"mc":[{"id":"1.187557653","rc":[{"batl":[[0,1.41,1210.43]],"ltp":1.34,"tv":3481.75,"id":9632596}]}]}
{"op":"mcm","clk":"4233708634","pt":1631537923672,"mc":[{"id":"1.187557653","rc":[{"trd":[[1.34,50.08]],"batb":[[0,1.31,114.94],[1,1.28,42.36],[2,1.26,21.52]],"batl":[[0,1.34,8.62],[1,1.41,38.45],[2,1.43,18.96]],"ltp":1.34,"tv":3506.67,"id":9632596},{"batl":[[0,4.1,4.12],[1,4.2,7.14],[2,4.3,85.9]],"ltp":4.1,"tv":3124.95,"id":9433864}],"tv":6631.63}]}
{"op":"mcm","clk":"4233708831","pt":1631537926971,"mc":[{"id":"1.187557653","rc":[{"batl":[[0,1.41,38.45],[1,1.43,18.96],[2,1.45,808.1]],"ltp":1.34,"tv":3506.67,"id":9632596},{"batl":[[0,4.2,7.14],[1,4.3,85.9],[2,4.4,3.58]],"ltp":4.1,"tv":3124.95,"id":9433864}]}]}
{"op":"mcm","clk":"4233709168","pt":1631537932897,"mc":[{"id":"1.187557653","rc":[{"batb":[[0,3.9,6.01],[1,3.8,7.9],[2,3.75,3.94]],"batl":[[0,4.1,8.19],[1,4.2,7.14],[2,4.3,85.9]],"ltp":4.1,"tv":3124.95,"id":9433864}]}]}
{"op":"mcm","clk":"4233709222","pt":1631537933690,"mc":[{"id":"1.187557653","rc":[{"batb":[[0,3.8,7.9],[1,3.75,3.94],[2,3.7,3.94]],"batl":[[0,4.2,7.14],[1,4.3,85.9],[2,4.4,3.58]],"ltp":4.1,"tv":3124.95,"id":9433864}]}]}
{"op":"mcm","clk":"4233709461","pt":1631537936577,"mc":[{"id":"1.187557653","rc":[{"batb":[[0,3.9,6.01],[1,3.8,7.9],[2,3.75,3.94]],"batl":[[0,4.1,8.19],[1,4.2,7.14],[2,4.3,85.9]],"ltp":4.1,"tv":3124.95,"id":9433864}]}]}
{"op":"mcm","clk":"4233710465","pt":1631537952744,"mc":[{"id":"1.187557653","rc":[{"trd":[[1.32,46.84]],"batl":[[0,1.32,58.82],[1,1.41,38.45],[2,1.43,18.96]],"ltp":1.32,"tv":3532.1,"id":9632596},{"trd":[[4.1,15.08]],"batl":[[0,4.2,7.14],[1,4.3,85.9],[2,4.4,3.58]],"ltp":4.1,"tv":3133.14,"id":9433864}],"tv":6665.25}]}
{"op":"mcm","clk":"4233710701","pt":1631537956711,"mc":[{"id":"1.187557653","rc":[{"batb":[[1,1.24,151.21],[2,1.01,113.7]],"batl":[[0,1.45,808.1],[1,1.46,6.85],[2,1.6,0.21]],"ltp":1.32,"tv":3532.1,"id":9632596}]}]}
{"op":"mcm","clk":"4233710916","pt":1631537959198,"mc":[{"id":"1.187557653","rc":[{"batl":[[0,4.2,40.14]],"ltp":4.1,"tv":3133.14,"id":9433864}]}]}
{"op":"mcm","clk":"4233710978","pt":1631537960143,"mc":[{"id":"1.187557653","rc":[{"trd":[[1.31,285.26]],"batb":[[0,1.31,56.07],[1,1.24,265.73],[2,1.21,109.69]],"batl":[[0,1.38,58.75],[1,1.4,64.04],[2,1.45,808.1]],"ltp":1.31,"tv":3649.78,"id":9632596},{"batl":[[0,4.2,7.14]],"ltp":4.1,"tv":3133.14,"id":9433864}],"tv":6782.93}]}
{"op":"mcm","clk":"4233710989","pt":1631537960301,"mc":[{"id":"1.187557653","rc":[{"batb":[[1,1.25,98.09],[2,1.24,265.73]],"ltp":1.31,"tv":3649.78,"id":9632596}]}]}
{"op":"mcm","clk":"4233711238","pt":1631537963255,"mc":[{"id":"1.187557653","rc":[{"batl":[[0,1.38,109.3]],"ltp":1.31,"tv":3649.78,"id":9632596},{"batb":[[0,3.8,7.9],[1,3.75,3.94],[2,3.7,3.94]],"ltp":4.1,"tv":3133.14,"id":9433864}]}]}
{"op":"mcm","clk":"4233711249","pt":1631537963411,"mc":[{"id":"1.187557653","rc":[{"batl":[[0,1.38,58.75]],"ltp":1.31,"tv":3649.78,"id":9632596}]}]}
{"op":"mcm","clk":"4233711366","pt":1631537965813,"mc":[{"id":"1.187557653","rc":[{"batl":[[0,1.33,14.77],[1,1.38,58.75],[2,1.4,64.04]],"ltp":1.31,"tv":3649.78,"id":9632596},{"batl":[[0,4.2,13.77]],"ltp":4.1,"tv":3133.14,"id":9433864}]}]}
{"op":"mcm","clk":"4233712658","pt":1631537988046,"mc":[{"id":"1.187557653","rc":[{"batb":[[0,1.24,151.21],[1,1.21,109.69],[2,1.01,113.7]],"batl":[[0,1.4,64.04],[1,1.6,0.21],[2,1.4,0]],"ltp":1.31,"tv":3649.78,"id":9632596},{"batb":[[0,3.15,31.38],[1,2.3,368.04],[2,2.02,2.13]],"batl":[[0,5.3,130.72],[1,5.8,2],[2,4.4,0]],"ltp":4.1,"tv":3133.14,"id":9433864}]}]}
{"op":"mcm","clk":"4233712867","pt":1631537991281,"mc":[{"id":"1.187557653","rc":[{"batb":[[0,1.24,99.27],[1,1.23,157.07],[2,1.21,109.69]],"ltp":1.31,"tv":3649.78,"id":9632596},{"batb":[[0,3.5,3.04],[1,3.15,30.54],[2,2.3,368.04]],"batl":[[0,5.2,2.18],[1,5.3,130.72],[2,5.8,2]],"ltp":4.1,"tv":3133.14,"id":9433864}]}]}
{"op":"mcm","clk":"4233712882","pt":1631537991491,"mc":[{"id":"1.187557653","rc":[{"batb":[[0,1.23,157.07],[1,1.21,109.69],[2,1.01,113.7]],"ltp":1.31,"tv":3649.78,"id":9632596},{"batl":[[0,5.3,130.72],[1,5.8,2],[2,5.8,0]],"ltp":4.1,"tv":3133.14,"id":9433864}]}]}
{"op":"mcm","clk":"4233713014","pt":1631537994158,"mc":[{"id":"1.187557653","rc":[{"batb":[[0,3.6,3.54],[1,3.5,3.04],[2,3.15,30.54]],"ltp":4.1,"tv":3133.14,"id":9433864}]}]}
{"op":"mcm","clk":"4233713058","pt":1631537994889,"mc":[{"id":"1.187557653","rc":[{"batb":[[0,3.5,3.04],[1,3.15,30.54],[2,2.3,368.04]],"ltp":4.1,"tv":3133.14,"id":9433864}]}]}
{"op":"mcm","clk":"4233713129","pt":1631537996199,"mc":[{"id":"1.187557653","rc":[{"batl":[[0,5.8,2],[1,5.8,0]],"ltp":4.1,"tv":3133.14,"id":9433864}]}]}
{"op":"mcm","clk":"4233713225","pt":1631537997976,"mc":[{"id":"1.187557653","rc":[{"batb":[[0,1.33,40.77],[1,1.31,20.69],[2,1.23,157.07]],"batl":[[1,1.46,37.14],[2,1.48,18.32]],"ltp":1.31,"tv":3649.78,"id":9632596},{"trd":[[3.6,5.88]],"batb":[[0,3.6,5.74],[1,3.5,3.04],[2,3.35,70.73]],"batl":[[0,3.75,77.2],[1,3.9,53.85],[2,3.95,11.54]],"ltp":3.6,"tv":3139.02,"id":9433864}],"tv":6788.81}]}
{"op":"mcm","clk":"4233713281","pt":1631537998972,"mc":[{"id":"1.187557653","rc":[{"batb":[[0,1.36,94.98],[1,1.33,40.77],[2,1.31,20.69]],"ltp":1.31,"tv":3649.78,"id":9632596},{"batb":[[1,3.5,11.62],[2,3.45,4.28]],"batl":[[1,3.9,38.47],[2,3.95,3.84]],"ltp":3.6,"tv":3139.02,"id":9433864}]}]}
{"op":"mcm","clk":"4233713844","pt":1631538005807,"mc":[{"id":"1.187557653","rc":[{"trd":[[1.31,285.18],[1.32,46.82],[1.33,497.26],[1.47,403.27],[1.56,54.8],[1.57,123.67],[1.58,37.95],[1.6,15.63],[1.67,9.11],[1.68,16.17],[1.7,17.53],[1.74,41.04],[1.83,71.63],[1.86,25.76],[1.87,4.78],[1.89,529.66],[1.92,32.03],[2,17.24],[2.2,2.91],[2.3,80.21],[3.4,18.47],[3.5,9.57],[3.55,8.33]],"batb":[[0,1.36,94.95],[1,1.33,40.82],[2,1.32,73.39]],"batl":[[1,1.42,53.75],[2,1.44,60.83]],"ltp":1.31,"tv":3649.29,"id":9632596},{"trd":[[1.2,61.74],[1.23,33.18],[1.24,32.92],[1.25,4.05],[1.28,32.24],[1.29,28.23],[1.32,23.46],[1.33,234.3],[1.34,15.5],[1.4,236.11],[1.41,41.49],[1.42,51.93],[1.46,296.15],[1.49,4.44],[1.53,17.09],[1.54,13.25],[1.55,27.21],[1.59,12.58],[1.62,65.61],[1.64,64.17],[1.65,58.05],[1.68,22.99],[1.71,24.44],[1.72,7.23],[1.73,26.39],[1.75,12.12],[1.76,73.56],[1.81,11.24],[1.82,53.91],[1.83,40.73],[1.84,28.52],[1.85,23.85],[1.87,11.3],[1.89,84.72],[1.9,119.04],[1.91,10.7],[1.94,43],[1.97,10.16],[1.98,18.02],[1.99,33.05],[2.02,13.91],[2.04,66.09],[2.06,52.99],[2.16,41.5],[2.18,9.7],[3.85,35.25],[4,15.56]],"ltp":3.6,"tv":3138.99,"id":9433864}],"tv":6788.29}]}
{"op":"mcm","clk":"4233714545","pt":1631538016232,"mc":[{"id":"1.187557653","rc":[{"batb":[[1,3.5,3.04],[2,3.35,74]],"batl":[[1,4.2,2.23],[2,4.4,2.79]],"ltp":3.6,"tv":3138.99,"id":9433864}]}]}
{"op":"mcm","clk":"4233714603","pt":1631538017027,"mc":[{"id":"1.187557653","rc":[{"batb":[[0,1.3,83.58],[1,1.29,121.81],[2,1.21,109.69]],"batl":[[0,1.44,60.83],[1,1.6,0.21],[2,1.44,0]],"ltp":1.31,"tv":3649.29,"id":9632596},{"batb":[[0,3.25,3.85],[1,2.92,38.23],[2,2.3,367.98]],"batl":[[0,4.4,2.79],[1,4.6,149.85],[2,5.8,2]],"ltp":3.6,"tv":3138.99,"id":9433864}]}]}
{"op":"mcm","clk":"4233714775","pt":1631538020227,"mc":[{"id":"1.187557653","rc":[{"batb":[[0,1.32,72.89],[1,1.3,83.58],[2,1.29,121.81]],"ltp":1.31,"tv":3649.29,"id":9632596},{"batl":[[0,4.2,2.73],[1,4.4,2.79],[2,4.6,149.85]],"ltp":3.6,"tv":3138.99,"id":9433864}]}]}
{"op":"mcm","clk":"4233714794","pt":1631538020536,"mc":[{"id":"1.187557653","rc":[{"batb":[[0,1.3,83.58],[1,1.29,121.81],[2,1.21,109.69]],"ltp":1.31,"tv":3649.29,"id":9632596},{"batl":[[0,4.4,2.79],[1,4.6,149.85],[2,5.8,2]],"ltp":3.6,"tv":3138.99,"id":9433864}]}]}
{"op":"mcm","clk":"4233714950","pt":1631538023241,"mc":[{"id":"1.187557653","rc":[{"batl":[[0,1.42,65.25],[1,1.44,60.83],[2,1.6,0.21]],"ltp":1.31,"tv":3649.29,"id":9632596},{"batb":[[0,3.35,3.27],[1,3.25,3.85],[2,2.92,38.23]],"ltp":3.6,"tv":3138.99,"id":9433864}]}]}
{"op":"mcm","clk":"4233715005","pt":1631538024009,"mc":[{"id":"1.187557653","rc":[{"batl":[[0,1.44,60.83],[1,1.6,0.21],[2,1.6,0]],"ltp":1.31,"tv":3649.29,"id":9632596},{"batb":[[0,3.25,3.85],[1,2.92,38.23],[2,2.3,367.98]],"ltp":3.6,"tv":3138.99,"id":9433864}]}]}
{"op":"mcm","clk":"4233715190","pt":1631538027258,"mc":[{"id":"1.187557653","rc":[{"batb":[[0,1.32,69.89],[1,1.3,83.58],[2,1.29,121.81]],"ltp":1.31,"tv":3649.29,"id":9632596},{"batl":[[0,4.2,2.38],[1,4.4,2.79],[2,4.6,149.85]],"ltp":3.6,"tv":3138.99,"id":9433864}]}]}
{"op":"mcm","clk":"4233715200","pt":1631538027458,"mc":[{"id":"1.187557653","rc":[{"batb":[[0,1.3,83.58],[1,1.29,121.81],[2,1.21,109.69]],"ltp":1.31,"tv":3649.29,"id":9632596},{"batl":[[0,4.4,2.79],[1,4.6,149.85],[2,5.8,2]],"ltp":3.6,"tv":3138.99,"id":9433864}]}]}
{"op":"mcm","clk":"4233715678","pt":1631538034274,"mc":[{"id":"1.187557653","rc":[{"batb":[[0,1.32,68.14],[1,1.3,83.58],[2,1.29,121.81]],"ltp":1.31,"tv":3649.29,"id":9632596},{"batl":[[0,4.2,2.53],[1,4.4,2.79],[2,4.6,149.85]],"ltp":3.6,"tv":3138.99,"id":9433864}]}]}
{"op":"mcm","clk":"4233715697","pt":1631538034592,"mc":[{"id":"1.187557653","rc":[{"batb":[[0,1.3,83.58],[1,1.29,121.81],[2,1.21,109.69]],"ltp":1.31,"tv":3649.29,"id":9632596},{"batl":[[0,4.4,2.79],[1,4.6,149.85],[2,5.8,2]],"ltp":3.6,"tv":3138.99,"id":9433864}]}]}
{"op":"mcm","clk":"4233716222","pt":1631538041278,"mc":[{"id":"1.187557653","rc":[{"batb":[[0,1.32,79.64],[1,1.3,83.58],[2,1.29,121.81]],"ltp":1.31,"tv":3649.29,"id":9632596},{"batl":[[0,4.2,2.53],[1,4.4,2.79],[2,4.6,149.85]],"ltp":3.6,"tv":3138.99,"id":9433864}]}]}
{"op":"mcm","clk":"4233716244","pt":1631538041584,"mc":[{"id":"1.187557653","rc":[{"batb":[[0,1.3,83.58],[1,1.29,121.81],[2,1.21,109.69]],"ltp":1.31,"tv":3649.29,"id":9632596},{"batl":[[0,4.4,2.79],[1,4.6,149.85],[2,5.8,2]],"ltp":3.6,"tv":3138.99,"id":9433864}]}]}
{"op":"mcm","clk":"4233716666","pt":1631538048202,"mc":[{"id":"1.187557653","rc":[{"batb":[[0,1.32,84.89],[1,1.3,83.58],[2,1.29,121.81]],"ltp":1.31,"tv":3649.29,"id":9632596},{"batl":[[0,4.2,2.58],[1,4.4,2.79],[2,4.6,149.85]],"ltp":3.6,"tv":3138.99,"id":9433864}]}]}
{"op":"mcm","clk":"4233716684","pt":1631538048500,"mc":[{"id":"1.187557653","rc":[{"batb":[[0,1.3,83.58],[1,1.29,121.81],[2,1.21,109.69]],"ltp":1.31,"tv":3649.29,"id":9632596},{"batl":[[0,4.4,2.79],[1,4.6,149.85],[2,5.8,2]],"ltp":3.6,"tv":3138.99,"id":9433864}]}]}
{"op":"mcm","clk":"4233717622","pt":1631538062110,"mc":[{"id":"1.187557653","rc":[{"trd":[[1.3,1.4]],"batb":[[0,1.3,82.88]],"ltp":1.3,"tv":3650.69,"id":9632596}],"tv":6789.68}]}
{"op":"mcm","clk":"4233718187","pt":1631538069116,"mc":[{"id":"1.187557653","rc":[{"batl":[[0,1.42,63.75],[1,1.44,60.83],[2,1.6,0.21]],"ltp":1.3,"tv":3650.69,"id":9632596},{"batb":[[0,3.35,3.67],[1,3.25,3.85],[2,2.92,38.23]],"ltp":3.6,"tv":3138.99,"id":9433864}]}]}
{"op":"mcm","clk":"4233718238","pt":1631538069702,"mc":[{"id":"1.187557653","rc":[{"batl":[[0,1.44,60.83],[1,1.6,0.21],[2,1.6,0]],"ltp":1.3,"tv":3650.69,"id":9632596},{"batb":[[0,3.25,3.85],[1,2.92,38.23],[2,2.3,367.98]],"ltp":3.6,"tv":3138.99,"id":9433864}]}]}
{"op":"mcm","clk":"4233718743","pt":1631538076219,"mc":[{"id":"1.187557653","rc":[{"batl":[[0,1.42,53.75],[1,1.44,60.83],[2,1.6,0.21]],"ltp":1.3,"tv":3650.69,"id":9632596},{"batb":[[0,3.35,3.87],[1,3.25,3.85],[2,2.92,38.23]],"ltp":3.6,"tv":3138.99,"id":9433864}]}]}
{"op":"mcm","clk":"4233718773","pt":1631538076842,"mc":[{"id":"1.187557653","rc":[{"batl":[[0,1.44,60.83],[1,1.6,0.21],[2,1.6,0]],"ltp":1.3,"tv":3650.69,"id":9632596},{"batb":[[0,3.25,3.85],[1,2.92,38.23],[2,2.3,367.98]],"ltp":3.6,"tv":3138.99,"id":9433864}]}]}
{"op":"mcm","clk":"4233719023","pt":1631538080233,"mc":[{"id":"1.187557653","rc":[{"batb":[[0,1.41,20.08],[1,1.4,142.86],[2,1.39,107.92]],"ltp":1.3,"tv":3650.69,"id":9632596},{"trd":[[3.25,6.24]],"batb":[[0,3.3,6.84],[1,3.1,69.04],[2,2.92,38.23]],"batl":[[0,3.4,57.13],[1,3.6,926.52],[2,3.9,4.07]],"ltp":3.25,"tv":3145.23,"id":9433864}],"tv":6795.92}]}
{"op":"mcm","clk":"4233719081","pt":1631538081125,"mc":[{"id":"1.187557653","rc":[{"batb":[[0,1.41,100.14],[1,1.4,85.72],[2,1.39,64.75]],"batl":[[0,1.44,164.99],[1,1.45,52.08],[2,1.46,52.08]],"ltp":1.3,"tv":3650.69,"id":9632596},{"batl":[[1,4.4,2.79],[2,5.8,2]],"ltp":3.25,"tv":3145.23,"id":9433864}]}]}
{"op":"mcm","clk":"4233719099","pt":1631538081440,"mc":[{"id":"1.187557653","rc":[{"batb":[[2,1.39,21.58]],"batl":[[0,1.44,81.67],[1,1.45,10.42],[2,1.46,10.42]],"ltp":1.3,"tv":3650.69,"id":9632596}]}]}
{"op":"mcm","clk":"4233719254","pt":1631538083525,"mc":[{"id":"1.187557653","rc":[{"batl":[[1,4.2,163.05],[2,4.4,2.79]],"ltp":3.25,"tv":3145.23,"id":9433864}]}]}
{"op":"mcm","clk":"4233719545","pt":1631538087476,"mc":[{"id":"1.187557653","rc":[{"trd":[[1.41,8.57]],"batb":[[0,1.41,96.84]],"ltp":1.41,"tv":3657.28,"id":9632596}],"tv":6802.52}]}
{"op":"mcm","clk":"4233719625","pt":1631538088369,"mc":[{"id":"1.187557653","rc":[{"batl":[[1,1.45,66.52],[2,1.46,65.67]],"ltp":1.41,"tv":3657.28,"id":9632596},{"batb":[[1,3.2,4.45],[2,3.15,3.43]],"batl":[[1,3.65,3.3],[2,3.8,2.72]],"ltp":3.25,"tv":3145.23,"id":9433864}]}]}
{"op":"mcm","clk":"4233720288","pt":1631538096475,"mc":[{"id":"1.187557653","rc":[{"batb":[[0,1.41,157.84]],"ltp":1.41,"tv":3657.28,"id":9632596}]}]}
{"op":"mcm","clk":"4233720413","pt":1631538097671,"mc":[{"id":"1.187557653","rc":[{"batb":[[0,1.41,141.06]],"ltp":1.41,"tv":3657.28,"id":9632596},{"batb":[[0,3.2,4.45],[1,3.15,3.43],[2,3.1,68.31]],"ltp":3.25,"tv":3145.23,"id":9433864}]}]}
{"op":"mcm","clk":"4233720627","pt":1631538100634,"mc":[{"id":"1.187557653","rc":[{"batb":[[0,1.41,157.84]],"batl":[[0,1.43,12.39],[1,1.44,81.67],[2,1.45,66.52]],"ltp":1.41,"tv":3657.28,"id":9632596}]}]}
{"op":"mcm","clk":"4233720704","pt":1631538101477,"mc":[{"id":"1.187557653","rc":[{"batb":[[2,3.1,72.35]],"ltp":3.25,"tv":3145.23,"id":9433864}]}]}
{"op":"mcm","clk":"4233720980","pt":1631538105077,"mc":[{"id":"1.187557653","rc":[{"batb":[[0,1.41,61],[1,1.38,71.46],[2,1.36,72.43]],"batl":[[0,1.46,55.25],[1,1.6,0.21],[2,1.45,0]],"ltp":1.41,"tv":3657.28,"id":9632596},{"batb":[[0,2.76,17.74],[1,2.3,367.98],[2,2.02,2.13]],"batl":[[0,3.65,3.3],[1,3.8,2.72],[2,4.2,163.05]],"ltp":3.25,"tv":3145.23,"id":9433864}]}]}
{"op":"mcm","clk":"4233721037","pt":1631538105909,"mc":[{"id":"1.187557653","rc":[{"batb":[[0,1.36,72.43],[1,1.35,96.54],[2,1.3,82.88]],"ltp":1.41,"tv":3657.28,"id":9632596},{"batl":[[0,3.8,2.72],[1,4.2,163.05],[2,4.4,2.79]],"ltp":3.25,"tv":3145.23,"id":9433864}]}]}
{"op":"mcm","clk":"4233721262","pt":1631538108205,"mc":[{"id":"1.187557653","rc":[{"batb":[[0,3.15,3.83],[1,2.76,17.74],[2,2.3,367.98]],"ltp":3.25,"tv":3145.23,"id":9433864}]}]}
{"op":"mcm","clk":"4233721609","pt":1631538112124,"mc":[{"id":"1.187557653","rc":[{"batb":[[0,1.38,68.46],[1,1.36,72.43],[2,1.35,96.54]],"ltp":1.41,"tv":3657.28,"id":9632596},{"batl":[[0,3.65,3.5],[1,3.8,2.72],[2,4.2,163.05]],"ltp":3.25,"tv":3145.23,"id":9433864}]}]}
{"op":"mcm","clk":"4233721649","pt":1631538112498,"mc":[{"id":"1.187557653","rc":[{"batb":[[0,1.36,72.43],[1,1.35,96.54],[2,1.3,82.88]],"ltp":1.41,"tv":3657.28,"id":9632596},{"batl":[[0,3.8,2.72],[1,4.2,163.05],[2,4.4,2.79]],"ltp":3.25,"tv":3145.23,"id":9433864}]}]}
{"op":"mcm","clk":"4233722045","pt":1631538116824,"mc":[{"id":"1.187557653","rc":[{"trd":[[1.46,55.25]],"batl":[[0,1.6,0.21],[1,1.6,0]],"ltp":1.46,"tv":3712.53,"id":9632596},{"trd":[[3.15,33.27]],"batb":[[0,2.76,17.74],[1,2.3,367.98],[2,2.02,2.13]],"batl":[[0,3.15,108.32],[1,3.8,2.72],[2,4.2,163.05]],"ltp":3.15,"tv":3178.5,"id":9433864}],"tv":6891.04}]}
{"op":"mcm","clk":"4233722275","pt":1631538119117,"mc":[{"id":"1.187557653","rc":[{"trd":[[1.46,104.55]],"batb":[[0,1.38,65.46],[1,1.36,72.43],[2,1.35,96.54]],"ltp":1.46,"tv":3761.83,"id":9632596},{"trd":[[3.15,62.96]],"batl":[[0,3.15,82.05],[1,3.65,3.5],[2,3.8,2.72]],"ltp":3.15,"tv":3208.19,"id":9433864}],"tv":6970.03}]}
{"op":"mcm","clk":"4233722420","pt":1631538120113,"mc":[{"id":"1.187557653","rc":[{"trd":[[1.46,153.3]],"ltp":1.46,"tv":3810.58,"id":9632596},{"trd":[[3.15,93.61]],"batl":[[0,3.15,55.42]],"ltp":3.15,"tv":3238.84,"id":9433864}],"tv":7049.43}]}
{"op":"mcm","clk":"4233722887","pt":1631538124630,"mc":[{"id":"1.187557653","rc":[{"batb":[[0,1.36,72.43],[1,1.35,96.54],[2,1.3,82.88]],"ltp":1.46,"tv":3810.58,"id":9632596},{"batl":[[0,3.8,2.72],[1,4.2,163.05],[2,4.4,2.79]],"ltp":3.15,"tv":3238.84,"id":9433864}]}]}
{"op":"mcm","clk":"4233723727","pt":1631538134248,"mc":[{"id":"1.187557653","rc":[{"batb":[[2,1.33,40.82]],"batl":[[0,1.38,11.77],[1,1.42,28.16],[2,1.46,37.19]],"ltp":1.46,"tv":3810.58,"id":9632596},{"batb":[[0,3.45,43.48],[1,3.4,21.74],[2,3.35,21.74]],"batl":[[0,3.75,76.4],[1,3.8,2.72],[2,4.2,163.05]],"ltp":3.15,"tv":3238.84,"id":9433864}]}]}
{"op":"mcm","clk":"4233723764","pt":1631538134667,"mc":[{"id":"1.187557653","rc":[{"trd":[[1.38,7.67]],"batl":[[0,1.38,4.1]],"ltp":1.38,"tv":3818.25,"id":9632596},{"trd":[[3.6,8.82]],"batb":[[0,3.45,8.7],[1,3.4,4.34],[2,3.35,4.34]],"batl":[[2,3.85,7.8]],"ltp":3.6,"tv":3241.78,"id":9433864}],"tv":7060.04}]}
{"op":"mcm","clk":"4233724639","pt":1631538144531,"mc":[{"id":"1.187557653","rc":[{"batl":[[0,1.42,28.16],[1,1.46,37.19],[2,1.48,18.34]],"ltp":1.38,"tv":3818.25,"id":9632596},{"batl":[[0,3.75,70.51]],"ltp":3.6,"tv":3241.78,"id":9433864}]}]}
{"op":"mcm","clk":"4233724746","pt":1631538145943,"mc":[{"id":"1.187557653","rc":[{"batb":[[0,1.36,73.36]],"ltp":1.38,"tv":3818.25,"id":9632596}]}]}
{"op":"mcm","clk":"4233724877","pt":1631538147471,"mc":[{"id":"1.187557653","rc":[{"batb":[[0,3.6,4.46],[1,3.45,8.7],[2,3.4,4.34]],"batl":[[0,3.7,4.49],[1,3.75,70.51],[2,3.8,2.72]],"ltp":3.6,"tv":3241.78,"id":9433864}]}]}
{"op":"mcm","clk":"4233725037","pt":1631538149195,"mc":[{"id":"1.187557653","rc":[{"batb":[[0,1.35,97.47],[1,1.3,82.88],[2,1.27,215.49]],"batl":[[0,1.6,0.21],[1,1.46,0],[2,1.48,0]],"ltp":1.38,"tv":3818.25,"id":9632596},{"batb":[[0,3.2,29.87],[1,2.9,38.99],[2,2.3,367.98]],"batl":[[0,4.2,163.05],[1,4.4,2.79],[2,4.8,2.47]],"ltp":3.6,"tv":3241.78,"id":9433864}]}]}
{"op":"mcm","clk":"4233725079","pt":1631538149565,"mc":[{"id":"1.187557653","rc":[{"batb":[[0,1.3,83.81],[1,1.27,215.49],[2,1.21,109.69]],"ltp":1.38,"tv":3818.25,"id":9632596},{"batb":[[0,2.9,38.99],[1,2.3,367.98],[2,2.02,2.13]],"ltp":3.6,"tv":3241.78,"id":9433864}]}]}
{"op":"mcm","clk":"4233725318","pt":1631538152288,"mc":[{"id":"1.187557653","rc":[{"batb":[[0,1.31,83.72],[1,1.3,82.88],[2,1.28,86.36]],"ltp":1.38,"tv":3818.25,"id":9632596},{"batl":[[1,4.3,2.35],[2,4.4,2.79]],"ltp":3.6,"tv":3241.78,"id":9433864}]}]}
{"op":"mcm","clk":"4233725373","pt":1631538152871,"mc":[{"id":"1.187557653","rc":[{"batb":[[0,1.3,83.81],[1,1.28,86.36],[2,1.27,128.92]],"ltp":1.38,"tv":3818.25,"id":9632596},{"batl":[[0,4.4,2.79],[1,4.6,2.26],[2,5.8,2]],"ltp":3.6,"tv":3241.78,"id":9433864}]}]}
{"op":"mcm","clk":"4233725582","pt":1631538155269,"mc":[{"id":"1.187557653","rc":[{"batb":[[0,1.36,22.11],[1,1.3,82.88],[2,1.28,86.36]],"batl":[[0,1.4,18.59],[1,1.6,0.21]],"ltp":1.38,"tv":3818.25,"id":9632596},{"batl":[[0,3.75,21.42],[1,4.4,2.79],[2,4.6,2.26]],"ltp":3.6,"tv":3241.78,"id":9433864}]}]}
{"op":"mcm","clk":"4233725657","pt":1631538156106,"mc":[{"id":"1.187557653","rc":[{"batb":[[0,1.3,83.81],[1,1.28,86.36],[2,1.27,128.92]],"batl":[[0,1.6,0.21],[1,1.6,0]],"ltp":1.38,"tv":3818.25,"id":9632596},{"batl":[[0,4.2,2.43]],"ltp":3.6,"tv":3241.78,"id":9433864}]}]}
{"op":"mcm","clk":"4233725702","pt":1631538156578,"mc":[{"id":"1.187557653","rc":[{"batl":[[0,4.4,2.79],[1,4.6,2.26],[2,4.9,139.02]],"ltp":3.6,"tv":3241.78,"id":9433864}]}]}
{"op":"mcm","clk":"4233725795","pt":1631538157683,"mc":[{"id":"1.187557653","rc":[{"batb":[[0,1.3,82.88]],"ltp":1.38,"tv":3818.25,"id":9632596}]}]}
{"op":"mcm","clk":"4233726823","pt":1631538169923,"mc":[{"id":"1.187557653","rc":[{"batb":[[0,1.32,81.39],[1,1.3,82.88],[2,1.28,86.36]],"ltp":1.38,"tv":3818.25,"id":9632596}]}]}
{"op":"mcm","clk":"4233726898","pt":1631538170611,"mc":[{"id":"1.187557653","rc":[{"batb":[[0,1.3,82.88],[1,1.28,86.36],[2,1.27,128.92]],"ltp":1.38,"tv":3818.25,"id":9632596}]}]}
{"op":"mcm","clk":"4233728071","pt":1631538184267,"mc":[{"id":"1.187557653","rc":[{"batb":[[0,1.32,89.64],[1,1.3,82.88],[2,1.28,86.36]],"ltp":1.38,"tv":3818.25,"id":9632596},{"batl":[[2,5.8,2]],"ltp":3.6,"tv":3241.78,"id":9433864}]}]}
{"op":"mcm","clk":"4233728162","pt":1631538185258,"mc":[{"id":"1.187557653","rc":[{"batb":[[0,1.42,66.44],[1,1.4,107.14],[2,1.39,53.58]],"batl":[[0,1.52,35.72],[1,1.54,17.63],[2,1.6,0.21]],"ltp":1.38,"tv":3818.25,"id":9632596},{"trd":[[3.15,99.95]],"batb":[[0,3.25,3],[1,3.05,76.37],[2,2.9,38.99]],"batl":[[0,3.35,65.01],[1,3.4,9.19],[2,3.75,269.68]],"ltp":3.15,"tv":3248.12,"id":9433864}],"tv":7066.38}]}
{"op":"mcm","clk":"4233728238","pt":1631538186252,"mc":[{"id":"1.187557653","rc":[{"batb":[[0,1.42,145.25],[1,1.4,64.28],[2,1.39,32.15]],"batl":[[2,1.56,6.41]],"ltp":1.38,"tv":3818.25,"id":9632596},{"batb":[[1,3.2,46.88],[2,3.15,23.44]],"batl":[[0,3.35,41.13]],"ltp":3.15,"tv":3248.12,"id":9433864}]}]}
{"op":"mcm","clk":"4233728274","pt":1631538186635,"mc":[{"id":"1.187557653","rc":[{"batb":[[1,1.4,21.42],[2,1.39,10.72]],"ltp":1.38,"tv":3818.25,"id":9632596},{"batb":[[1,3.2,9.38],[2,3.15,4.68]],"ltp":3.15,"tv":3248.12,"id":9433864}]}]}
{"op":"mcm","clk":"4233728708","pt":1631538192154,"mc":[{"id":"1.187557653","rc":[{"batb":[[2,1.39,79.63]],"ltp":1.38,"tv":3818.25,"id":9632596},{"batl":[[2,3.6,3.71]],"ltp":3.15,"tv":3248.12,"id":9433864}]}]}
{"op":"mcm","clk":"4233728976","pt":1631538195176,"mc":[{"id":"1.187557653","rc":[{"batb":[[0,3.2,9.38],[1,3.15,4.68],[2,3.1,4.68]],"batl":[[0,3.35,35.82]],"ltp":3.15,"tv":3248.12,"id":9433864}]}]}
{"op":"mcm","clk":"4233729250","pt":1631538198097,"mc":[{"id":"1.187557653","rc":[{"batb":[[0,1.43,13.08],[1,1.42,145.25],[2,1.4,21.42]],"batl":[[0,1.45,14.03],[1,1.52,35.72],[2,1.54,17.63]],"ltp":1.38,"tv":3818.25,"id":9632596}]}]}
{"op":"mcm","clk":"4233729822","pt":1631538205292,"mc":[{"id":"1.187557653","rc":[{"trd":[[1.45,14.03]],"batl":[[0,1.52,35.72],[1,1.54,17.63],[2,1.56,6.41]],"ltp":1.45,"tv":3832.28,"id":9632596},{"trd":[[3.2,31.58]],"batb":[[0,3.15,4.68],[1,3.1,4.68],[2,3.05,76.37]],"batl":[[0,3.2,53.14],[1,3.35,35.82],[2,3.4,9.19]],"ltp":3.2,"tv":3273.24,"id":9433864}],"tv":7105.53}]}
{"op":"mcm","clk":"4233730382","pt":1631538211915,"mc":[{"id":"1.187557653","rc":[{"batl":[[0,1.51,26.88],[1,1.52,35.72],[2,1.54,17.63]],"ltp":1.45,"tv":3832.28,"id":9632596}]}]}
{"op":"mcm","clk":"4233730472","pt":1631538213013,"mc":[{"id":"1.187557653","rc":[{"batb":[[0,1.42,78.81],[1,1.39,68.91],[2,1.37,101.4]],"batl":[[0,1.52,35.72],[1,1.54,17.63],[2,1.6,0.21]],"ltp":1.45,"tv":3832.28,"id":9632596},{"batb":[[0,2.9,38.99],[1,2.76,17.99],[2,2.3,367.98]],"batl":[[1,3.6,3.71],[2,3.75,3.02]],"ltp":3.2,"tv":3273.24,"id":9433864}]}]}
{"op":"mcm","clk":"4233730494","pt":1631538213324,"mc":[{"id":"1.187557653","rc":[{"batb":[[0,1.39,68.91],[1,1.37,61.77],[2,1.36,154.38]],"batl":[[0,1.6,0.21],[1,1.54,0],[2,1.6,0]],"ltp":1.45,"tv":3832.28,"id":9632596},{"batb":[[0,2.76,17.99],[1,2.3,367.98],[2,2.02,2.13]],"ltp":3.2,"tv":3273.24,"id":9433864}]}]}
{"op":"mcm","clk":"4233730705","pt":1631538216146,"mc":[{"id":"1.187557653","rc":[{"batl":[[0,3.6,3.71],[1,3.75,3.02],[2,3.8,2.97]],"ltp":3.2,"tv":3273.24,"id":9433864}]}]}
{"op":"mcm","clk":"4233730825","pt":1631538217089,"mc":[{"id":"1.187557653","rc":[{"batb":[[0,1.36,154.38],[1,1.3,82.88],[2,1.28,86.36]],"batl":[[0,1.47,378.16],[1,1.6,0.21]],"ltp":1.45,"tv":3832.28,"id":9632596},{"batl":[[0,3.8,2.97],[1,4.2,163.05],[2,4.4,2.79]],"ltp":3.2,"tv":3273.24,"id":9433864}]}]}
{"op":"mcm","clk":"4233730938","pt":1631538218136,"mc":[{"id":"1.187557653","rc":[{"batb":[[0,1.44,20.92],[1,1.36,154.38],[2,1.3,82.88]],"batl":[[0,1.47,20.5]],"ltp":1.45,"tv":3832.28,"id":9632596},{"batl":[[0,3.25,19.14],[1,3.8,2.97],[2,4.2,163.05]],"ltp":3.2,"tv":3273.24,"id":9433864}]}]}
{"op":"mcm","clk":"4233730978","pt":1631538218498,"mc":[{"id":"1.187557653","rc":[{"batb":[[0,1.36,154.38],[1,1.3,82.88],[2,1.28,86.36]],"batl":[[0,1.6,0.21],[1,1.6,0]],"ltp":1.45,"tv":3832.28,"id":9632596},{"batl":[[0,3.8,2.97],[1,4.2,163.05],[2,4.4,2.79]],"ltp":3.2,"tv":3273.24,"id":9433864}]}]}
{"op":"mcm","clk":"4233731433","pt":1631538223150,"mc":[{"id":"1.187557653","rc":[{"batb":[[0,1.39,65.91],[1,1.36,154.38],[2,1.3,82.88]],"ltp":1.45,"tv":3832.28,"id":9632596},{"batl":[[0,3.6,3.06],[1,3.8,2.97],[2,4.2,163.05]],"ltp":3.2,"tv":3273.24,"id":9433864}]}]}
{"op":"mcm","clk":"4233731456","pt":1631538223409,"mc":[{"id":"1.187557653","rc":[{"batb":[[0,1.36,154.38],[1,1.3,82.88],[2,1.28,86.36]],"ltp":1.45,"tv":3832.28,"id":9632596},{"batl":[[0,3.8,2.97],[1,4.2,163.05],[2,4.4,2.79]],"ltp":3.2,"tv":3273.24,"id":9433864}]}]}
{"op":"mcm","clk":"4233731734","pt":1631538227023,"mc":[{"id":"1.187557653","rc":[{"batb":[[0,1.39,58.91],[1,1.36,154.38],[2,1.3,82.88]],"ltp":1.45,"tv":3832.28,"id":9632596},{"batl":[[0,3.6,3.16],[1,3.8,2.97],[2,4.2,163.05]],"ltp":3.2,"tv":3273.24,"id":9433864}]}]}
{"op":"mcm","clk":"4233731767","pt":1631538227344,"mc":[{"id":"1.187557653","rc":[{"batb":[[0,1.36,154.38],[1,1.3,82.88],[2,1.28,86.36]],"ltp":1.45,"tv":3832.28,"id":9632596},{"batl":[[0,3.8,2.97],[1,4.2,163.05],[2,4.4,2.79]],"ltp":3.2,"tv":3273.24,"id":9433864}]}]}
{"op":"mcm","clk":"4233732085","pt":1631538230239,"mc":[{"id":"1.187557653","rc":[{"batb":[[0,1.46,124.34],[1,1.45,62.81],[2,1.42,21.12]],"batl":[[0,1.5,8.79],[1,1.52,136.98],[2,1.55,35.03]],"ltp":1.45,"tv":3832.28,"id":9632596},{"batb":[[0,3,4.39],[1,2.76,17.99]],"batl":[[0,3.05,3.28],[1,3.1,4.86],[2,3.15,63.5]],"ltp":3.2,"tv":3273.24,"id":9433864}]}]}
{"op":"mcm","clk":"4233732187","pt":1631538231232,"mc":[{"id":"1.187557653","rc":[{"batb":[[0,1.46,194.11]],"batl":[[1,1.52,156.72],[2,1.53,9.86]],"ltp":1.45,"tv":3832.28,"id":9632596},{"batb":[[2,2.34,27.69]],"ltp":3.2,"tv":3273.24,"id":9433864}]}]}
{"op":"mcm","clk":"4233732549","pt":1631538235155,"mc":[{"id":"1.187557653","rc":[{"trd":[[1.47,413.52],[1.48,38.15]],"ltp":1.47,"tv":3849.29,"id":9632596},{"trd":[[3.05,5.41],[3.1,10.04]],"batl":[[0,3.15,63.5],[1,3.25,9.3],[2,3.8,2.97]],"ltp":3.1,"tv":3281.38,"id":9433864}],"tv":7130.68}]}
{"op":"mcm","clk":"4233732659","pt":1631538236559,"mc":[{"id":"1.187557653","rc":[{"batl":[[2,3.65,2.9]],"ltp":3.1,"tv":3281.38,"id":9433864}]}]}
{"op":"mcm","clk":"4233733047","pt":1631538240525,"mc":[{"id":"1.187557653","rc":[{"trd":[[1.5,33.98]],"batl":[[0,1.5,7.86]],"ltp":1.5,"tv":3851.15,"id":9632596}],"tv":7132.54}]}
{"op":"mcm","clk":"4233733488","pt":1631538245132,"mc":[{"id":"1.187557653","rc":[{"batl":[[0,1.52,156.72],[1,1.53,9.86],[2,1.54,9.86]],"ltp":1.5,"tv":3851.15,"id":9632596},{"batb":[[0,2.76,17.99],[1,2.34,27.69],[2,2.04,373.9]],"ltp":3.1,"tv":3281.38,"id":9433864}]}]}
{"op":"mcm","clk":"4233733555","pt":1631538245765,"mc":[{"id":"1.187557653","rc":[{"batb":[[0,1.5,34.84],[1,1.46,194.11],[2,1.45,62.81]],"ltp":1.5,"tv":3851.15,"id":9632596}]}]}
{"op":"mcm","clk":"4233733764","pt":1631538248081,"mc":[{"id":"1.187557653","rc":[{"trd":[[1.5,46.75]],"batb":[[0,1.5,22.07]],"ltp":1.5,"tv":3863.92,"id":9632596},{"trd":[[3,13.35]],"batl":[[0,3.15,70.37]],"ltp":3.0,"tv":3287.76,"id":9433864}],"tv":7151.69}]}
{"op":"mcm","clk":"4233734005","pt":1631538250765,"mc":[{"id":"1.187557653","rc":[{"batl":[[0,3.15,63.5]],"ltp":3.0,"tv":3287.76,"id":9433864}]}]}
{"op":"mcm","clk":"4233734289","pt":1631538254261,"mc":[{"id":"1.187557653","rc":[{"trd":[[1.5,67.63]],"batb":[[0,1.5,8.15]],"ltp":1.5,"tv":3884.8,"id":9632596},{"trd":[[3,16.83]],"batb":[[0,2.78,54.72],[1,2.76,17.99],[2,2.34,27.69]],"batl":[[0,3.1,6.63],[1,3.15,63.5],[2,3.25,9.3]],"ltp":3.0,"tv":3291.24,"id":9433864}],"tv":7176.05}]}
{"op":"mcm","clk":"4233734534","pt":1631538256974,"mc":[{"id":"1.187557653","rc":[{"trd":[[1.52,79.74]],"batl":[[0,1.52,90.56]],"ltp":1.52,"tv":3950.96,"id":9632596},{"trd":[[2.92,34.44]],"ltp":2.92,"tv":3325.68,"id":9433864}],"tv":7276.64}]}
{"op":"mcm","clk":"4233734571","pt":1631538257501,"mc":[{"id":"1.187557653","rc":[{"trd":[[1.5,71.95]],"batb":[[0,1.5,3.82]],"ltp":1.5,"tv":3955.28,"id":9632596},{"trd":[[3,18.99]],"ltp":3.0,"tv":3327.85,"id":9433864}],"tv":7283.13}]}
{"op":"mcm","clk":"4233734672","pt":1631538258304,"mc":[{"id":"1.187557653","rc":[{"batl":[[0,3.15,63.5],[1,3.25,9.3],[2,3.65,2.9]],"ltp":3.0,"tv":3327.85,"id":9433864}]}]}
{"op":"mcm","clk":"4233734910","pt":1631538261181,"mc":[{"id":"1.187557653","rc":[{"batb":[[0,1.46,194.11],[1,1.45,62.81],[2,1.42,21.12]],"ltp":1.5,"tv":3955.28,"id":9632596},{"batb":[[0,2.96,5.74],[1,2.78,54.72],[2,2.76,17.99]],"batl":[[0,3.05,6.85],[1,3.15,63.5],[2,3.25,9.3]],"ltp":3.0,"tv":3327.85,"id":9433864}]}]}
{"op":"mcm","clk":"4233734956","pt":1631538261701,"mc":[{"id":"1.187557653","rc":[{"trd":[[1.52,84.78]],"batl":[[0,1.52,88.04]],"ltp":1.52,"tv":3960.32,"id":9632596},{"batb":[[1,2.76,17.99],[2,2.34,27.69]],"ltp":3.0,"tv":3327.85,"id":9433864}],"tv":7288.17}]}
{"op":"mcm","clk":"4233735172","pt":1631538263889,"mc":[{"id":"1.187557653","rc":[{"batb":[[0,2.76,17.99],[1,2.34,27.69],[2,2.04,373.9]],"batl":[[0,3.15,63.5],[1,3.25,9.3],[2,3.65,2.9]],"ltp":3.0,"tv":3327.85,"id":9433864}]}]}
{"op":"mcm","clk":"4233735206","pt":1631538264308,"mc":[{"id":"1.187557653","rc":[{"trd":[[1.52,92.43]],"batl":[[0,1.52,84.21]],"ltp":1.52,"tv":3967.98,"id":9632596}],"tv":7295.83}]}
{"op":"mcm","clk":"4233735446","pt":1631538267215,"mc":[{"id":"1.187557653","rc":[{"batb":[[0,1.46,69.77],[1,1.4,38.78],[2,1.38,81.13]],"batl":[[0,1.55,35.03],[1,1.57,17.29],[2,1.6,0.21]],"ltp":1.52,"tv":3967.98,"id":9632596},{"batl":[[0,3.65,2.9],[1,3.75,2.9],[2,3.8,2.97]],"ltp":3.0,"tv":3327.85,"id":9433864}]}]}
{"op":"mcm","clk":"4233735483","pt":1631538267597,"mc":[{"id":"1.187557653","rc":[{"batb":[[0,1.38,61.46],[1,1.37,63.77],[2,1.36,59.68]],"batl":[[0,1.6,0.21],[1,1.57,0],[2,1.6,0]],"ltp":1.52,"tv":3967.98,"id":9632596},{"batb":[[0,2.34,27.69],[1,2.04,373.9],[2,1.46,2]],"ltp":3.0,"tv":3327.85,"id":9433864}]}]}
{"op":"mcm","clk":"4233735682","pt":1631538269927,"mc":[{"id":"1.187557653","rc":[{"batb":[[0,1.35,95.54],[1,1.34,73.72],[2,1.3,82.88]],"ltp":1.52,"tv":3967.98,"id":9632596},{"batl":[[0,3.9,174.27],[1,3.95,2.7],[2,4.4,2.79]],"ltp":3.0,"tv":3327.85,"id":9433864}]}]}
{"op":"mcm","clk":"4233735933","pt":1631538273085,"mc":[{"id":"1.187557653","rc":[{"batb":[[0,1.38,62.96],[1,1.35,95.54],[2,1.34,73.72]],"ltp":1.52,"tv":3967.98,"id":9632596},{"batl":[[0,3.65,3.5],[1,3.9,174.27],[2,3.95,2.7]],"ltp":3.0,"tv":3327.85,"id":9433864}]}]}
{"op":"mcm","clk":"4233735965","pt":1631538273416,"mc":[{"id":"1.187557653","rc":[{"batb":[[0,1.35,95.54],[1,1.34,73.72],[2,1.3,82.88]],"ltp":1.52,"tv":3967.98,"id":9632596},{"batl":[[0,3.9,174.27],[1,3.95,2.7],[2,4.4,2.79]],"ltp":3.0,"tv":3327.85,"id":9433864}]}]}
{"op":"mcm","clk":"4233736748","pt":1631538281255,"mc":[{"id":"1.187557653","rc":[{"batb":[[1,1.46,2],[2,1.23,2]],"batl":[[0,3.95,2.7],[1,4.4,2.79],[2,4.6,2.26]],"ltp":3.0,"tv":3327.85,"id":9433864}]}]}
{"op":"mcm","clk":"4233736906","pt":1631538282834,"mc":[{"id":"1.187557653","rc":[{"trd":[[1.6,16.05]],"batb":[[0,1.63,61.23],[1,1.61,124.01],[2,1.59,18.86]],"batl":[[0,1.7,31.94],[1,1.72,15.78]],"ltp":1.6,"tv":3968.4,"id":9632596},{"batb":[[0,2.5,8.29],[1,2.42,94.42],[2,2.34,27.69]],"batl":[[0,2.56,3.91],[1,2.6,25.74],[2,2.72,134.42]],"ltp":3.0,"tv":3327.85,"id":9433864}],"tv":7296.25}]}
{"op":"mcm","clk":"4233737015","pt":1631538283750,"mc":[{"id":"1.187557653","rc":[{"batb":[[1,1.61,172.53]],"batl":[[0,1.68,17.86],[1,1.69,8.92],[2,1.7,40.86]],"ltp":1.6,"tv":3968.4,"id":9632596}]}]}
{"op":"mcm","clk":"4233738385","pt":1631538299061,"mc":[{"id":"1.187557653","rc":[{"trd":[[2.5,5.25]],"batb":[[0,2.5,8.19]],"ltp":2.5,"tv":3328.05,"id":9433864}],"tv":7296.45}]}
{"op":"mcm","clk":"4233738445","pt":1631538299776,"mc":[{"id":"1.187557653","rc":[{"batl":[[2,1.7,8.92]],"ltp":1.6,"tv":3968.4,"id":9632596}]}]}
{"op":"mcm","clk":"4233738641","pt":1631538302054,"mc":[{"id":"1.187557653","rc":[{"batb":[[0,1.49,57.01],[1,1.47,67.76],[2,1.44,57.67]],"ltp":1.6,"tv":3968.4,"id":9632596},{"batb":[[0,2.02,42.42],[1,1.86,375.87],[2,1.46,2]],"batl":[[0,3.05,3.7],[1,3.3,214.76],[2,3.95,2.7]],"ltp":2.5,"tv":3328.05,"id":9433864}]}]}
{"op":"mcm","clk":"4233738693","pt":1631538302573,"mc":[{"id":"1.187557653","rc":[{"batb":[[0,1.47,67.76],[1,1.44,57.67],[2,1.34,73.72]],"ltp":1.6,"tv":3968.4,"id":9632596},{"batl":[[0,3.3,214.76],[1,3.95,2.7],[2,4.4,2.79]],"ltp":2.5,"tv":3328.05,"id":9433864}]}]}
{"op":"mcm","clk":"4233739461","pt":1631538309184,"mc":[{"id":"1.187557653","rc":[{"batb":[[0,1.49,60.01],[1,1.47,67.76],[2,1.44,57.67]],"ltp":1.6,"tv":3968.4,"id":9632596},{"batl":[[0,3.05,3.7],[1,3.3,214.76],[2,3.95,2.7]],"ltp":2.5,"tv":3328.05,"id":9433864}]}]}
{"op":"mcm","clk":"4233739573","pt":1631538310493,"mc":[{"id":"1.187557653","rc":[{"batb":[[0,1.47,67.76],[1,1.44,57.67],[2,1.34,73.72]],"ltp":1.6,"tv":3968.4,"id":9632596},{"batl":[[0,3.3,214.76],[1,3.95,2.7],[2,4.4,2.79]],"ltp":2.5,"tv":3328.05,"id":9433864}]}]}
{"op":"mcm","clk":"4233740502","pt":1631538320992,"mc":[{"id":"1.187557653","rc":[{"batb":[[0,1.49,54.01],[1,1.47,67.76],[2,1.44,57.67]],"ltp":1.6,"tv":3968.4,"id":9632596},{"batl":[[0,3.05,4.7],[1,3.3,214.76],[2,3.95,2.7]],"ltp":2.5,"tv":3328.05,"id":9433864}]}]}
{"op":"mcm","clk":"4233740523","pt":1631538321307,"mc":[{"id":"1.187557653","rc":[{"batb":[[0,1.47,67.76],[1,1.44,57.67],[2,1.34,73.72]],"ltp":1.6,"tv":3968.4,"id":9632596},{"batl":[[0,3.3,214.76],[1,3.95,2.7],[2,4.4,2.79]],"ltp":2.5,"tv":3328.05,"id":9433864}]}]}
{"op":"mcm","clk":"4233741036","pt":1631538327237,"mc":[{"id":"1.187557653","rc":[{"batb":[[2,1.3,82.88]],"ltp":1.6,"tv":3968.4,"id":9632596},{"batb":[[1,1.46,2],[2,1.23,2]],"batl":[[0,3.3,3.75],[1,4.4,2.79],[2,4.6,2.26]],"ltp":2.5,"tv":3328.05,"id":9433864}]}]}
{"op":"mcm","clk":"4233741110","pt":1631538328023,"mc":[{"id":"1.187557653","rc":[{"batb":[[0,1.84,55.47],[1,1.82,104.4],[2,1.81,41.22]],"batl":[[0,1.89,18.23],[1,1.91,28.43],[2,1.93,14.07]],"ltp":1.6,"tv":3968.4,"id":9632596},{"batb":[[0,2.08,111.91],[1,2.02,42.42],[2,1.46,2]],"batl":[[0,2.18,4.59],[1,2.2,24.94],[2,2.6,538.89]],"ltp":2.5,"tv":3328.05,"id":9433864}]}]}
{"op":"mcm","clk":"4233741218","pt":1631538329117,"mc":[{"id":"1.187557653","rc":[{"batb":[[1,1.82,71.43],[2,1.81,24.73]],"batl":[[2,1.92,15.62]],"ltp":1.6,"tv":3968.4,"id":9632596},{"batb":[[2,1.82,29.95]],"ltp":2.5,"tv":3328.05,"id":9433864}]}]}
{"op":"mcm","clk":"4233741813","pt":1631538335826,"mc":[{"id":"1.187557653","rc":[{"batl":[[2,2.5,5.87]],"ltp":2.5,"tv":3328.05,"id":9433864}]}]}
{"op":"mcm","clk":"4233742641","pt":1631538344936,"mc":[{"id":"1.187557653","rc":[{"batl":[[1,1.92,15.62],[2,1.93,7.82]],"ltp":1.6,"tv":3968.4,"id":9632596}]}]}
{"op":"mcm","clk":"4233742949","pt":1631538348040,"mc":[{"id":"1.187557653","rc":[{"batb":[[0,1.67,48.47],[1,1.65,44.67],[2,1.61,45.09]],"ltp":1.6,"tv":3968.4,"id":9632596},{"batb":[[0,1.82,29.95],[1,1.7,383.77],[2,1.46,2]],"batl":[[0,2.5,5.87],[1,2.64,4.93],[2,2.82,253.55]],"ltp":2.5,"tv":3328.05,"id":9433864}]}]}
{"op":"mcm","clk":"4233742981","pt":1631538348356,"mc":[{"id":"1.187557653","rc":[{"batb":[[0,1.65,44.67],[1,1.61,45.09],[2,1.44,57.67]],"ltp":1.6,"tv":3968.4,"id":9632596},{"batl":[[0,2.64,4.93],[1,2.82,253.55],[2,3.3,3.75]],"ltp":2.5,"tv":3328.05,"id":9433864}]}]}
{"op":"mcm","clk":"4233743280","pt":1631538351743,"mc":[{"id":"1.187557653","rc":[{"batb":[[0,1.82,30.85]],"ltp":2.5,"tv":3328.05,"id":9433864}]}]}
{"op":"mcm","clk":"4233743903","pt":1631538358078,"mc":[{"id":"1.187557653","rc":[{"batb":[[0,1.82,29.95]],"ltp":2.5,"tv":3328.05,"id":9433864}]}]}
{"op":"mcm","clk":"4233743934","pt":1631538358389,"mc":[{"id":"1.187557653","rc":[{"batb":[[0,1.67,47.47],[1,1.65,44.67],[2,1.61,45.09]],"ltp":1.6,"tv":3968.4,"id":9632596},{"batl":[[0,2.5,5.67],[1,2.64,4.93],[2,2.82,253.55]],"ltp":2.5,"tv":3328.05,"id":9433864}]}]}
{"op":"mcm","clk":"4233744251","pt":1631538361686,"mc":[{"id":"1.187557653","rc":[{"batb":[[0,1.65,44.67],[1,1.61,45.09],[2,1.44,57.67]],"ltp":1.6,"tv":3968.4,"id":9632596},{"batl":[[0,2.64,4.93],[1,2.82,253.55],[2,3.3,3.75]],"ltp":2.5,"tv":3328.05,"id":9433864}]}]}
{"op":"mcm","clk":"4233744560","pt":1631538364983,"mc":[{"id":"1.187557653","rc":[{"batb":[[0,1.67,51.47],[1,1.65,44.67],[2,1.61,45.09]],"ltp":1.6,"tv":3968.4,"id":9632596},{"batl":[[0,2.5,5.75],[1,2.64,4.93],[2,2.82,253.55]],"ltp":2.5,"tv":3328.05,"id":9433864}]}]}
{"op":"mcm","clk":"4233747024","pt":1631538392529,"mc":[{"id":"1.187557653","rc":[{"batb":[[0,1.65,44.67],[1,1.61,45.09],[2,1.44,57.67]],"ltp":1.6,"tv":3968.4,"id":9632596},{"batl":[[0,2.64,4.93],[1,2.82,253.55],[2,3.3,3.75]],"ltp":2.5,"tv":3328.05,"id":9433864}]}]}
{"op":"mcm","clk":"4233747208","pt":1631538394158,"mc":[{"id":"1.187557653","rc":[{"batb":[[1,1.46,2],[2,1.23,2]],"batl":[[1,3.3,3.75],[2,4.4,2.79]],"ltp":2.5,"tv":3328.05,"id":9433864}]}]}
{"op":"mcm","clk":"4233747320","pt":1631538395263,"mc":[{"id":"1.187557653","rc":[{"batb":[[0,1.68,10.84],[1,1.65,44.67],[2,1.61,45.09]],"batl":[[0,1.74,17.24],[1,1.75,39.65],[2,1.76,8.62]],"ltp":1.6,"tv":3968.4,"id":9632596},{"batb":[[0,2.4,9.67],[1,2.32,123.14],[2,1.82,29.95]],"batl":[[0,2.56,87.4],[1,2.64,4.93],[2,3.3,3.75]],"ltp":2.5,"tv":3328.05,"id":9433864}]}]}
{"op":"mcm","clk":"4233747399","pt":1631538396038,"mc":[{"id":"1.187557653","rc":[{"batb":[[1,1.66,90.36],[2,1.65,89.85]],"ltp":1.6,"tv":3968.4,"id":9632596},{"batb":[[2,2.28,30.37]],"batl":[[0,2.46,4.07],[1,2.56,87.4],[2,2.64,4.93]],"ltp":2.5,"tv":3328.05,"id":9433864}]}]}
{"op":"mcm","clk":"4233747429","pt":1631538396355,"mc":[{"id":"1.187557653","rc":[{"batb":[[1,1.66,18.08],[2,1.65,53.71]],"ltp":1.6,"tv":3968.4,"id":9632596}]}]}
{"op":"mcm","clk":"4233747683","pt":1631538399169,"mc":[{"id":"1.187557653","rc":[{"trd":[[1.68,37.45]],"batb":[[0,1.66,18.28],[1,1.65,53.71],[2,1.64,9.04]],"ltp":1.68,"tv":3989.68,"id":9632596}],"tv":7317.73}]}
{"op":"mcm","clk":"4233747776","pt":1631538400166,"mc":[{"id":"1.187557653","rc":[{"trd":[[1.68,42.16]],"batb":[[0,1.66,18.08]],"ltp":1.68,"tv":3994.39,"id":9632596},{"trd":[[2.46,23.31]],"batl":[[0,2.46,1.13]],"ltp":2.46,"tv":3330.99,"id":9433864}],"tv":7325.38}]}
{"op":"mcm","clk":"4233748466","pt":1631538407791,"mc":[{"id":"1.187557653","rc":[{"trd":[[2.4,17.34]],"batb":[[0,2.4,9.57]],"ltp":2.4,"tv":3331.19,"id":9433864}],"tv":7325.58}]}
{"op":"mcm","clk":"4233748579","pt":1631538409053,"mc":[{"id":"1.187557653","rc":[{"batb":[[0,2.32,123.14],[1,2.28,30.37],[2,1.93,50.03]],"ltp":2.4,"tv":3331.19,"id":9433864}]}]}
{"op":"mcm","clk":"4233748620","pt":1631538409581,"mc":[{"id":"1.187557653","rc":[{"batb":[[0,1.72,5.73],[1,1.66,18.08],[2,1.65,53.71]],"ltp":1.68,"tv":3994.39,"id":9632596}]}]}
{"op":"mcm","clk":"4233748854","pt":1631538412261,"mc":[{"id":"1.187557653","rc":[{"trd":[[1.72,22.68]],"batb":[[0,1.66,18.08],[1,1.65,53.71],[2,1.64,9.04]],"batl":[[1,1.75,8.62]],"ltp":1.72,"tv":4005.84,"id":9632596}],"tv":7337.03}]}
{"op":"mcm","clk":"4233748959","pt":1631538413265,"mc":[{"id":"1.187557653","rc":[{"batb":[[0,1.48,116.35],[1,1.47,54.67],[2,1.44,57.67]],"ltp":1.72,"tv":4005.84,"id":9632596},{"batb":[[0,1.93,50.03],[1,1.82,377.82],[2,1.46,2]],"batl":[[0,3.1,4.35],[1,3.15,224.34],[2,3.3,3.75]],"ltp":2.4,"tv":3331.19,"id":9433864}]}]}
{"op":"mcm","clk":"4233749018","pt":1631538413995,"mc":[{"id":"1.187557653","rc":[{"batb":[[1,1.44,57.67],[2,1.3,82.88]],"ltp":1.72,"tv":4005.84,"id":9632596},{"batl":[[0,2.4,1.17],[1,3.1,4.35],[2,3.15,220.24]],"ltp":2.4,"tv":3331.19,"id":9433864}]}]}
{"op":"mcm","clk":"4233749113","pt":1631538415100,"mc":[{"id":"1.187557653","rc":[{"trd":[[1.71,1.64]],"batl":[[0,1.7,12.6]],"ltp":1.71,"tv":4007.48,"id":9632596},{"trd":[[2.4,18.51]],"batl":[[0,2.5,6.81]],"ltp":2.4,"tv":3332.36,"id":9433864}],"tv":7339.84}]}
{"op":"mcm","clk":"4233749209","pt":1631538416199,"mc":[{"id":"1.187557653","rc":[{"batl":[[0,2.4,1.8]],"ltp":2.4,"tv":3332.36,"id":9433864}]}]}
{"op":"mcm","clk":"4233750678","pt":1631538433232,"mc":[{"id":"1.187557653","rc":[{"batb":[[0,1.95,99.26],[1,1.94,23.08],[2,1.93,23.08]],"batl":[[0,1.98,11.73],[1,2.06,150.22]],"ltp":1.71,"tv":4007.48,"id":9632596},{"batb":[[0,1.97,27.56],[1,1.95,13.93],[2,1.93,50.03]],"batl":[[0,2.04,63.72],[1,2.06,16.75],[2,2.08,11.83]],"ltp":2.4,"tv":3332.36,"id":9433864}]}]}
{"op":"mcm","clk":"4233750771","pt":1631538434135,"mc":[{"id":"1.187557653","rc":[{"batb":[[0,1.95,68.49],[1,1.94,7.7],[2,1.93,7.7]],"batl":[[1,2.06,164.78],[2,2.08,7.28]],"ltp":1.71,"tv":4007.48,"id":9632596}]}]}
{"op":"mcm","clk":"4233751507","pt":1631538442535,"mc":[{"id":"1.187557653","rc":[{"trd":[[1.98,7.38]],"batl":[[0,1.98,8.04]],"ltp":1.98,"tv":4011.17,"id":9632596},{"trd":[[2.02,17.53]],"ltp":2.02,"tv":3335.97,"id":9433864}],"tv":7347.15}]}
{"op":"mcm","clk":"4233751689","pt":1631538444521,"mc":[{"id":"1.187557653","rc":[{"trd":[[1.98,14.54]],"batl":[[0,1.98,4.46]],"ltp":1.98,"tv":4018.34,"id":9632596}],"tv":7354.31}]}
{"op":"mcm","clk":"4233752217","pt":1631538450247,"mc":[{"id":"1.187557653","rc":[{"trd":[[1.96,5.35]],"ltp":1.96,"tv":4018.35,"id":9632596},{"trd":[[2.04,66.1]],"batb":[[0,1.93,50.03],[1,1.74,34.97],[2,1.67,383.7]],"batl":[[0,2.04,63.71]],"ltp":2.04,"tv":3335.98,"id":9433864}],"tv":7354.33}]}
{"op":"mcm","clk":"4233752452","pt":1631538453061,"mc":[{"id":"1.187557653","rc":[{"batl":[[0,2.06,164.78],[1,2.08,7.28],[2,2.1,7.28]],"ltp":1.96,"tv":4018.35,"id":9632596},{"batl":[[2,2.16,144.41]],"ltp":2.04,"tv":3335.98,"id":9433864}]}]}
{"op":"mcm","clk":"4233752516","pt":1631538453636,"mc":[{"id":"1.187557653","rc":[{"trd":[[1.97,12.86]],"batl":[[0,1.97,14.58],[1,2.02,3.5],[2,2.04,63.71]],"ltp":1.97,"tv":3338.68,"id":9433864}],"tv":7357.03}]}
{"op":"mcm","clk":"4233752762","pt":1631538456234,"mc":[{"id":"1.187557653","rc":[{"trd":[[2.02,27.06]],"batb":[[0,1.73,50.13],[1,1.71,38.82],[2,1.48,50.26]],"ltp":2.02,"tv":4024.81,"id":9632596},{"trd":[[1.97,32.6]],"batb":[[0,1.74,34.97],[1,1.67,383.7],[2,1.46,2]],"batl":[[0,1.97,1.4],[2,2.38,6.25]],"ltp":1.97,"tv":3358.42,"id":9433864}],"tv":7383.23}]}
{"op":"mcm","clk":"4233753037","pt":1631538459043,"mc":[{"id":"1.187557653","rc":[{"batb":[[0,1.74,43.52],[1,1.73,50.13],[2,1.71,38.82]],"ltp":2.02,"tv":4024.81,"id":9632596},{"batl":[[2,2.36,7.32]],"ltp":1.97,"tv":3358.42,"id":9433864}]}]}
{"op":"mcm","clk":"4233753082","pt":1631538459461,"mc":[{"id":"1.187557653","rc":[{"batb":[[0,1.79,45.31],[1,1.74,43.52],[2,1.73,50.13]],"ltp":2.02,"tv":4024.81,"id":9632596},{"batl":[[2,2.28,5.84]],"ltp":1.97,"tv":3358.42,"id":9433864}]}]}
{"op":"mcm","clk":"4233753332","pt":1631538461952,"mc":[{"id":"1.187557653","rc":[{"batb":[[0,1.74,43.52],[1,1.73,50.13],[2,1.71,38.82]],"ltp":2.02,"tv":4024.81,"id":9632596},{"batl":[[2,2.36,7.32]],"ltp":1.97,"tv":3358.42,"id":9433864}]}]}
{"op":"mcm","clk":"4233753450","pt":1631538463149,"mc":[{"id":"1.187557653","rc":[{"batb":[[1,1.46,2],[2,1.23,2]],"ltp":1.97,"tv":3358.42,"id":9433864}]}]}
{"op":"mcm","clk":"4233753671","pt":1631538465275,"mc":[{"id":"1.187557653","rc":[{"trd":[[1.98,18.11],[2.02,28.43]],"batl":[[0,1.83,11.99],[1,1.84,29.51],[2,1.86,14.6]],"ltp":1.98,"tv":4029.75,"id":9632596},{"trd":[[1.97,34],[2.02,21.03]],"batb":[[0,2.2,95.76],[1,1.74,34.97],[2,1.46,2]],"batl":[[0,2.28,12.72],[1,2.36,7.32],[2,2.38,6.25]],"ltp":2.02,"tv":3363.32,"id":9433864}],"tv":7393.07}]}
{"op":"mcm","clk":"4233753749","pt":1631538466183,"mc":[{"id":"1.187557653","rc":[{"batb":[[0,1.77,16.96],[1,1.76,8.48],[2,1.75,8.48]],"batl":[[0,1.84,29.51],[1,1.86,14.6],[2,1.87,106.96]],"ltp":1.98,"tv":4029.75,"id":9632596},{"batb":[[1,2.16,35.47],[2,1.77,32.79]],"batl":[[0,2.28,4.39]],"ltp":2.02,"tv":3363.32,"id":9433864}]}]}
{"op":"mcm","clk":"4233753793","pt":1631538466755,"mc":[{"id":"1.187557653","rc":[{"batb":[[2,1.77,392.45]],"ltp":2.02,"tv":3363.32,"id":9433864}]}]}
{"op":"mcm","clk":"4233753976","pt":1631538468783,"mc":[{"id":"1.187557653","rc":[{"batl":[[0,1.83,11.99],[1,1.84,29.51],[2,1.86,14.6]],"ltp":1.98,"tv":4029.75,"id":9632596},{"batl":[[0,2.28,17.11]],"ltp":2.02,"tv":3363.32,"id":9433864}]}]}
{"op":"mcm","clk":"4233754645","pt":1631538476382,"mc":[{"id":"1.187557653","rc":[{"trd":[[1.83,84.97]],"batl":[[0,1.83,5.32]],"ltp":1.83,"tv":4043.09,"id":9632596}],"tv":7406.41}]}
{"op":"mcm","clk":"4233754748","pt":1631538477680,"mc":[{"id":"1.187557653","rc":[{"trd":[[2.2,143.02]],"batb":[[0,2.2,45.51]],"ltp":2.2,"tv":3463.82,"id":9433864}],"tv":7506.91}]}
{"op":"mcm","clk":"4233754957","pt":1631538480027,"mc":[{"id":"1.187557653","rc":[{"batb":[[0,1.71,38.82],[1,1.63,33.31],[2,1.61,16.86]],"batl":[[0,1.84,29.51],[1,1.86,14.6],[2,1.86,0]],"ltp":1.83,"tv":4043.09,"id":9632596},{"batb":[[0,2.16,35.47],[1,1.77,392.45],[2,1.46,2]],"batl":[[0,2.4,1.8],[1,2.72,264.59],[2,2.82,5.25]],"ltp":2.2,"tv":3463.82,"id":9433864}]}]}
{"op":"mcm","clk":"4233754989","pt":1631538480344,"mc":[{"id":"1.187557653","rc":[{"batb":[[0,1.55,49.19],[1,1.48,115.68],[2,1.47,54.67]],"ltp":1.83,"tv":4043.09,"id":9632596},{"batb":[[0,1.77,392.45],[1,1.46,2],[2,1.23,2]],"ltp":2.2,"tv":3463.82,"id":9433864}]}]}
{"op":"mcm","clk":"4233755397","pt":1631538484387,"mc":[{"id":"1.187557653","rc":[{"batb":[[0,1.77,32.79]],"batl":[[1,2.82,5.25],[2,3.1,4.35]],"ltp":2.2,"tv":3463.82,"id":9433864}]}]}
{"op":"mcm","clk":"4233755517","pt":1631538485690,"mc":[{"id":"1.187557653","rc":[{"trd":[[1.71,4.17]],"batb":[[0,1.48,314.02],[1,1.47,54.67],[2,1.44,57.67]],"batl":[[0,1.58,57.82],[1,1.59,75.47],[2,1.6,16.97]],"ltp":1.71,"tv":4045.62,"id":9632596},{"trd":[[2.4,20.31]],"batb":[[0,2.74,32.84],[1,2.72,16.43],[2,2.7,16.43]],"batl":[[0,2.84,6.02],[1,3.1,4.35],[2,3.15,3.9]],"ltp":2.4,"tv":3465.62,"id":9433864}],"tv":7511.24}]}
{"op":"mcm","clk":"4233755623","pt":1631538486795,"mc":[{"id":"1.187557653","rc":[{"batl":[[0,1.58,34.37]],"ltp":1.71,"tv":4045.62,"id":9632596},{"batb":[[0,2.74,10.94],[1,2.72,5.48],[2,2.7,5.48]],"batl":[[0,2.92,3.42],[1,2.96,10.14],[2,2.98,5.06]],"ltp":2.4,"tv":3465.62,"id":9433864}]}]}
{"op":"mcm","clk":"4233755836","pt":1631538489607,"mc":[{"id":"1.187557653","rc":[{"batl":[[0,1.58,57.82]],"ltp":1.71,"tv":4045.62,"id":9632596},{"batl":[[0,2.84,6.02],[1,2.92,3.42],[2,2.96,10.14]],"ltp":2.4,"tv":3465.62,"id":9433864}]}]}
{"op":"mcm","clk":"4233756395","pt":1631538496394,"mc":[{"id":"1.187557653","rc":[{"batb":[[0,1.48,2639.76]],"ltp":1.71,"tv":4045.62,"id":9632596}]}]}
{"op":"mcm","clk":"4233756923","pt":1631538502776,"mc":[{"id":"1.187557653","rc":[{"batl":[[0,1.58,23.45],[2,1.62,6.17]],"ltp":1.71,"tv":4045.62,"id":9632596}]}]}
{"op":"mcm","clk":"4233757487","pt":1631538508946,"mc":[{"id":"1.187557653","rc":[{"trd":[[1.58,103.82]],"batb":[[0,1.58,44.68],[1,1.48,314.02],[2,1.47,54.67]],"batl":[[0,1.59,75.47],[1,1.62,6.17],[2,1.86,988.81]],"ltp":1.58,"tv":4111.49,"id":9632596},{"trd":[[2.74,10.94]],"batb":[[0,2.72,5.48],[1,2.7,5.48],[2,2.68,19.41]],"ltp":2.74,"tv":3476.56,"id":9433864}],"tv":7588.05}]}
{"op":"mcm","clk":"4233757778","pt":1631538512181,"mc":[{"id":"1.187557653","rc":[{"trd":[[1.58,193.18]],"batb":[[0,1.48,314.02],[1,1.47,54.67],[2,1.44,57.67]],"ltp":1.58,"tv":4200.84,"id":9632596}],"tv":7677.41}]}
{"op":"mcm","clk":"4233758066","pt":1631538515066,"mc":[{"id":"1.187557653","rc":[{"batb":[[0,1.48,2707.49]],"ltp":1.58,"tv":4200.84,"id":9632596}]}]}
{"op":"mcm","clk":"4233758422","pt":1631538518880,"mc":[{"id":"1.187557653","rc":[{"batl":[[0,2.74,16.97]],"ltp":2.74,"tv":3476.56,"id":9433864}]}]}
{"op":"mcm","clk":"4233758652","pt":1631538521796,"mc":[{"id":"1.187557653","rc":[{"batl":[[1,1.6,17.4],[2,1.62,6.17]],"ltp":1.58,"tv":4200.84,"id":9632596},{"batl":[[1,2.78,9.5],[2,2.92,3.42]],"ltp":2.74,"tv":3476.56,"id":9433864}]}]}
{"op":"mcm","clk":"4233759026","pt":1631538526289,"mc":[{"id":"1.187557653","rc":[{"trd":[[2.72,2.34]],"batb":[[0,2.72,4.31]],"ltp":2.72,"tv":3478.9,"id":9433864}],"tv":7679.75}]}
{"op":"mcm","clk":"4233759603","pt":1631538532805,"mc":[{"id":"1.187557653","rc":[{"batl":[[0,2.78,9.5],[1,2.92,3.42],[2,2.96,10.14]],"ltp":2.72,"tv":3478.9,"id":9433864}]}]}
{"op":"mcm","clk":"4233760439","pt":1631538542200,"mc":[{"id":"1.187557653","rc":[{"batb":[[0,1.4,61.61],[1,1.39,54.91],[2,1.34,75.72]],"ltp":1.58,"tv":4200.84,"id":9632596},{"batb":[[0,2.14,36.31],[1,2.04,353.71],[2,1.46,2]],"batl":[[0,3.5,3.13],[1,3.6,3.31],[2,3.9,184.87]],"ltp":2.72,"tv":3478.9,"id":9433864}]}]}
{"op":"mcm","clk":"4233760469","pt":1631538542511,"mc":[{"id":"1.187557653","rc":[{"batb":[[0,1.34,75.72],[1,1.33,185.36],[2,1.01,113.68]],"ltp":1.58,"tv":4200.84,"id":9632596},{"batl":[[0,3.9,184.87],[1,3.95,2.9],[2,4.1,2.65]],"ltp":2.72,"tv":3478.9,"id":9433864}]}]}
{"op":"mcm","clk":"4233761073","pt":1631538549101,"mc":[{"id":"1.187557653","rc":[{"batb":[[0,1.4,66.21],[1,1.34,75.72],[2,1.33,185.36]],"ltp":1.58,"tv":4200.84,"id":9632596},{"batl":[[0,3.5,2.87],[1,3.9,184.87],[2,3.95,2.9]],"ltp":2.72,"tv":3478.9,"id":9433864}]}]}
{"op":"mcm","clk":"4233761099","pt":1631538549412,"mc":[{"id":"1.187557653","rc":[{"batb":[[0,1.34,75.72],[1,1.33,185.36],[2,1.01,113.68]],"ltp":1.58,"tv":4200.84,"id":9632596},{"batl":[[0,3.9,184.87],[1,3.95,2.9],[2,4.1,2.65]],"ltp":2.72,"tv":3478.9,"id":9433864}]}]}
{"op":"mcm","clk":"4233761215","pt":1631538550618,"mc":[{"id":"1.187557653","rc":[{"batb":[[0,2.16,3.59],[1,2.14,36.31],[2,2.04,353.71]],"ltp":2.72,"tv":3478.9,"id":9433864}]}]}
{"op":"mcm","clk":"4233761604","pt":1631538554644,"mc":[{"id":"1.187557653","rc":[{"trd":[[2.14,50.43],[2.16,48.69]],"batb":[[0,2.14,13.19],[1,2.04,353.71],[2,1.46,2]],"ltp":2.14,"tv":3532.33,"id":9433864}],"tv":7733.17}]}
{"op":"mcm","clk":"4233761760","pt":1631538556112,"mc":[{"id":"1.187557653","rc":[{"batb":[[0,1.4,64.51],[1,1.34,75.72],[2,1.33,185.36]],"ltp":1.58,"tv":4200.84,"id":9632596},{"batl":[[0,3.5,3.91],[1,3.9,184.87],[2,3.95,2.9]],"ltp":2.14,"tv":3532.33,"id":9433864}]}]}
{"op":"mcm","clk":"4233761789","pt":1631538556423,"mc":[{"id":"1.187557653","rc":[{"batb":[[0,1.34,75.72],[1,1.33,185.36],[2,1.01,113.68]],"ltp":1.58,"tv":4200.84,"id":9632596},{"batl":[[0,3.9,184.87],[1,3.95,2.9],[2,4.1,2.65]],"ltp":2.14,"tv":3532.33,"id":9433864}]}]}
{"op":"mcm","clk":"4233762463","pt":1631538563261,"mc":[{"id":"1.187557653","rc":[{"batb":[[0,1.4,70.76],[1,1.34,75.72],[2,1.33,185.36]],"ltp":1.58,"tv":4200.84,"id":9632596},{"batl":[[0,3.5,3.29],[1,3.9,184.87],[2,3.95,2.9]],"ltp":2.14,"tv":3532.33,"id":9433864}]}]}
{"op":"mcm","clk":"4233762525","pt":1631538564047,"mc":[{"id":"1.187557653","rc":[{"batb":[[0,1.34,75.72],[1,1.33,185.36],[2,1.01,113.68]],"ltp":1.58,"tv":4200.84,"id":9632596},{"batb":[[0,2.04,353.71],[1,1.46,2],[2,1.23,2]],"batl":[[0,3.9,184.87],[1,3.95,2.9],[2,4.1,2.65]],"ltp":2.14,"tv":3532.33,"id":9433864}]}]}
{"op":"mcm","clk":"4233762609","pt":1631538565138,"mc":[{"id":"1.187557653","rc":[{"batb":[[1,1.33,104.83]],"ltp":1.58,"tv":4200.84,"id":9632596},{"batb":[[0,1.46,2],[1,1.23,2],[2,1.19,1]],"batl":[[0,3.95,2.9],[1,3.95,0],[2,4.1,0]],"ltp":2.14,"tv":3532.33,"id":9433864}]}]}
{"op":"mcm","clk":"4233762692","pt":1631538566123,"mc":[{"id":"1.187557653","rc":[{"batb":[[0,1.77,84.76],[1,1.76,42.38],[2,1.75,42.38]],"batl":[[0,1.89,193.9]],"ltp":1.58,"tv":4200.84,"id":9632596},{"batl":[[0,2.2,12.54],[1,2.26,1426.5],[2,2.28,4.39]],"ltp":2.14,"tv":3532.33,"id":9433864}]}]}
{"op":"mcm","clk":"4233762778","pt":1631538567268,"mc":[{"id":"1.187557653","rc":[{"batb":[[0,1.83,59.03],[1,1.77,50.86],[2,1.76,25.43]],"batl":[[0,1.84,29.51],[1,1.86,14.6],[2,1.89,193.9]],"ltp":1.58,"tv":4200.84,"id":9632596},{"batb":[[0,2.12,36.89],[1,1.75,33.8],[2,1.46,2]],"batl":[[1,2.22,16.25],[2,2.26,53.1]],"ltp":2.14,"tv":3532.33,"id":9433864}]}]}
{"op":"mcm","clk":"4233762808","pt":1631538567530,"mc":[{"id":"1.187557653","rc":[{"batb":[[1,1.77,16.96],[2,1.76,8.48]],"ltp":1.58,"tv":4200.84,"id":9632596}]}]}
{"op":"mcm","clk":"4233762912","pt":1631538568725,"mc":[{"id":"1.187557653","rc":[{"batb":[[2,1.74,360.53]],"ltp":2.14,"tv":3532.33,"id":9433864}]}]}
{"op":"mcm","clk":"4233764041","pt":1631538581967,"mc":[{"id":"1.187557653","rc":[{"trd":[[1.84,102.9]],"batl":[[0,1.84,19.5]],"ltp":1.84,"tv":4220.84,"id":9632596},{"trd":[[2.2,145.9]],"batl":[[0,2.2,11.1]],"ltp":2.2,"tv":3535.21,"id":9433864}],"tv":7756.06}]}
{"op":"mcm","clk":"4233764176","pt":1631538583580,"mc":[{"id":"1.187557653","rc":[{"batl":[[0,1.89,193.9],[1,1.9,15.8],[2,1.91,7.9]],"ltp":1.84,"tv":4220.84,"id":9632596}]}]}
{"op":"mcm","clk":"4233764504","pt":1631538587187,"mc":[{"id":"1.187557653","rc":[{"batb":[[1,1.73,37.56],[2,1.56,48.33]],"batl":[[0,1.89,14.38],[1,1.9,0],[2,1.91,0]],"ltp":1.84,"tv":4220.84,"id":9632596},{"batl":[[2,2.8,5.02]],"ltp":2.2,"tv":3535.21,"id":9433864}]}]}
{"op":"mcm","clk":"4233764600","pt":1631538588082,"mc":[{"id":"1.187557653","rc":[{"batb":[[0,1.5,63.08],[1,1.47,48.67],[2,1.46,59.88]],"ltp":1.84,"tv":4220.84,"id":9632596},{"batb":[[0,1.75,33.8],[1,1.74,360.53],[2,1.46,2]],"batl":[[0,2.92,254.12],[1,3.15,4.5],[2,3.2,3.33]],"ltp":2.2,"tv":3535.21,"id":9433864}]}]}
{"op":"mcm","clk":"4233764841","pt":1631538590695,"mc":[{"id":"1.187557653","rc":[{"batl":[[0,1.83,0.46]],"ltp":1.84,"tv":4220.84,"id":9632596}]}]}
{"op":"mcm","clk":"4233764981","pt":1631538592102,"mc":[{"id":"1.187557653","rc":[{"trd":[[1.83,85.43]],"ltp":1.83,"tv":4221.31,"id":9632596},{"trd":[[2.2,146.29]],"ltp":2.2,"tv":3535.6,"id":9433864}],"tv":7756.91}]}
{"op":"mcm","clk":"4233765251","pt":1631538594997,"mc":[{"id":"1.187557653","rc":[{"batb":[[0,1.57,47.57],[1,1.5,63.08],[2,1.47,48.67]],"ltp":1.83,"tv":4221.31,"id":9632596},{"batl":[[0,2.78,4.75],[1,2.92,254.12],[2,3.15,4.5]],"ltp":2.2,"tv":3535.6,"id":9433864}]}]}
{"op":"mcm","clk":"4233765284","pt":1631538595305,"mc":[{"id":"1.187557653","rc":[{"batb":[[0,1.5,63.08],[1,1.47,48.67],[2,1.46,59.88]],"ltp":1.83,"tv":4221.31,"id":9632596},{"batl":[[0,2.92,254.12],[1,3.15,4.5],[2,3.2,3.33]],"ltp":2.2,"tv":3535.6,"id":9433864}]}]}
{"op":"mcm","clk":"4233765528","pt":1631538598193,"mc":[{"id":"1.187557653","rc":[{"batb":[[0,1.56,47.58],[1,1.5,63.08],[2,1.47,48.67]],"ltp":1.83,"tv":4221.31,"id":9632596},{"batl":[[0,2.8,4.72],[1,2.92,254.12],[2,3.15,4.5]],"ltp":2.2,"tv":3535.6,"id":9433864}]}]}
{"op":"mcm","clk":"4233765547","pt":1631538598505,"mc":[{"id":"1.187557653","rc":[{"batb":[[0,1.5,63.08],[1,1.47,48.67],[2,1.46,59.88]],"ltp":1.83,"tv":4221.31,"id":9632596},{"batl":[[0,2.92,254.12],[1,3.15,4.5],[2,3.2,3.33]],"ltp":2.2,"tv":3535.6,"id":9433864}]}]}
{"op":"mcm","clk":"4233766357","pt":1631538607240,"mc":[{"id":"1.187557653","rc":[{"batb":[[1,1.48,214.03]],"batl":[[0,1.58,34.37],[1,1.59,125.78],[2,1.6,34.04]],"ltp":1.83,"tv":4221.31,"id":9632596},{"batb":[[0,2.62,11.44],[1,2.6,5.72],[2,2.58,5.72]],"batl":[[0,2.78,9.71],[1,3.2,3.33],[2,3.2,0]],"ltp":2.2,"tv":3535.6,"id":9433864}]}]}
{"op":"mcm","clk":"4233766463","pt":1631538608027,"mc":[{"id":"1.187557653","rc":[{"batb":[[0,2.62,31.77]],"batl":[[1,2.84,52.82],[2,2.86,26.42]],"ltp":2.2,"tv":3535.6,"id":9433864}]}]}
{"op":"mcm","clk":"4233766537","pt":1631538608606,"mc":[{"id":"1.187557653","rc":[{"batl":[[1,2.84,10.56],[2,2.86,5.28]],"ltp":2.2,"tv":3535.6,"id":9433864}]}]}
{"op":"mcm","clk":"4233766883","pt":1631538612159,"mc":[{"id":"1.187557653","rc":[{"trd":[[1.54,7.68],[1.56,72.1]],"ltp":1.54,"tv":4246.29,"id":9632596},{"trd":[[2.78,29.82],[2.84,4.16]],"batl":[[0,2.84,6.4],[1,2.86,5.28],[2,2.88,5.28]],"ltp":2.84,"tv":3549.47,"id":9433864}],"tv":7795.76}]}
{"op":"mcm","clk":"4233767201","pt":1631538614830,"mc":[{"id":"1.187557653","rc":[{"trd":[[1.58,200.4]],"batl":[[0,1.58,30.75]],"ltp":1.58,"tv":4253.52,"id":9632596}],"tv":7802.99}]}
{"op":"mcm","clk":"4233767848","pt":1631538622151,"mc":[{"id":"1.187557653","rc":[{"batl":[[2,1.6,16.97]],"ltp":1.58,"tv":4253.52,"id":9632596}]}]}
{"op":"mcm","clk":"4233768116","pt":1631538625234,"mc":[{"id":"1.187557653","rc":[{"trd":[[1.58,202.72]],"batl":[[0,1.58,14.42],[2,1.63,6.13]],"ltp":1.58,"tv":4255.84,"id":9632596},{"trd":[[2.72,3.69]],"batl":[[0,2.84,16.18]],"ltp":2.72,"tv":3550.82,"id":9433864}],"tv":7806.66}]}
{"op":"mcm","clk":"4233768927","pt":1631538634260,"mc":[{"id":"1.187557653","rc":[{"batb":[[1,1.34,169.7],[2,1.33,74.53]],"ltp":1.58,"tv":4255.84,"id":9632596},{"batb":[[0,2.62,20.33],[1,2.1,37.73],[2,2.04,354.13]],"batl":[[0,3.9,184.64],[1,3.95,2.9],[2,4.1,2.95]],"ltp":2.72,"tv":3550.82,"id":9433864}]}]}
{"op":"mcm","clk":"4233768978","pt":1631538634933,"mc":[{"id":"1.187557653","rc":[{"batb":[[0,1.34,169.7],[1,1.33,74.53],[2,1.01,113.68]],"ltp":1.58,"tv":4255.84,"id":9632596},{"batb":[[0,2.1,37.73],[1,2.04,354.13],[2,1.46,2]],"ltp":2.72,"tv":3550.82,"id":9433864}]}]}
{"op":"mcm","clk":"4233769081","pt":1631538636133,"mc":[{"id":"1.187557653","rc":[{"batb":[[0,1.34,170.16]],"ltp":1.58,"tv":4255.84,"id":9632596}]}]}
{"op":"mcm","clk":"4233769169","pt":1631538637274,"mc":[{"id":"1.187557653","rc":[{"batb":[[0,1.34,101.94]],"ltp":1.58,"tv":4255.84,"id":9632596},{"batl":[[1,4.1,2.95],[2,4.1,0]],"ltp":2.72,"tv":3550.82,"id":9433864}]}]}
{"op":"mcm","clk":"4233769887","pt":1631538641035,"mc":[{"id":"1.187557653","rc":[{"batb":[[0,1.39,69.37],[1,1.34,101.48],[2,1.33,74.53]],"ltp":1.58,"tv":4255.84,"id":9632596},{"batl":[[0,3.6,3.11],[1,3.9,184.64],[2,4.1,2.95]],"ltp":2.72,"tv":3550.82,"id":9433864}]}]}
{"op":"mcm","clk":"4233769972","pt":1631538641415,"mc":[{"id":"1.187557653","rc":[{"batb":[[0,1.34,101.94],[1,1.33,74.53],[2,1.01,113.68]],"ltp":1.58,"tv":4255.84,"id":9632596},{"batl":[[0,3.9,184.64],[1,4.1,2.95],[2,4.1,0]],"ltp":2.72,"tv":3550.82,"id":9433864}]}]}
{"op":"mcm","clk":"4233770649","pt":1631538647971,"mc":[{"id":"1.187557653","rc":[{"batb":[[0,1.39,70.37],[1,1.34,101.48],[2,1.33,74.53]],"ltp":1.58,"tv":4255.84,"id":9632596},{"batl":[[0,3.6,3.46],[1,3.9,184.64],[2,4.1,2.95]],"ltp":2.72,"tv":3550.82,"id":9433864}]}]}
{"op":"mcm","clk":"4233770785","pt":1631538649377,"mc":[{"id":"1.187557653","rc":[{"batb":[[0,1.34,101.94],[1,1.33,74.53],[2,1.01,113.68]],"ltp":1.58,"tv":4255.84,"id":9632596},{"batl":[[0,3.9,184.64],[1,4.1,2.95],[2,4.1,0]],"ltp":2.72,"tv":3550.82,"id":9433864}]}]}
{"op":"mcm","clk":"4233771030","pt":1631538652192,"mc":[{"id":"1.187557653","rc":[{"batb":[[0,1.82,59.14],[1,1.64,33.11],[2,1.62,16.76]],"batl":[[0,1.85,29.35],[1,1.86,11.85],[2,1.87,14.52]],"ltp":1.58,"tv":4255.84,"id":9632596},{"batb":[[1,1.46,2],[2,1.23,2]],"batl":[[0,2.18,55.04],[1,2.22,16.25],[2,2.24,14.21]],"ltp":2.72,"tv":3550.82,"id":9433864}]}]}
{"op":"mcm","clk":"4233771116","pt":1631538653180,"mc":[{"id":"1.187557653","rc":[{"batb":[[1,1.74,36.73],[2,1.64,33.11]],"ltp":1.58,"tv":4255.84,"id":9632596},{"batb":[[1,1.75,34.38],[2,1.46,2]],"ltp":2.72,"tv":3550.82,"id":9433864}]}]}
{"op":"mcm","clk":"4233771273","pt":1631538654908,"mc":[{"id":"1.187557653","rc":[{"batb":[[2,1.74,360.53]],"ltp":2.72,"tv":3550.82,"id":9433864}]}]}
{"op":"mcm","clk":"4233772752","pt":1631538669224,"mc":[{"id":"1.187557653","rc":[{"batb":[[2,1.57,49.57]],"batl":[[0,1.86,11.85],[1,1.89,184.88],[2,1.9,7.94]],"ltp":1.58,"tv":4255.84,"id":9632596},{"trd":[[2.18,13.3]],"batl":[[0,2.18,53.24]],"ltp":2.18,"tv":3554.42,"id":9433864}],"tv":7810.26}]}
{"op":"mcm","clk":"4233772884","pt":1631538670230,"mc":[{"id":"1.187557653","rc":[{"batl":[[1,1.89,169],[2,1.9,0]],"ltp":1.58,"tv":4255.84,"id":9632596},{"batl":[[0,2.22,16.25],[1,2.24,14.21],[2,2.4,130.07]],"ltp":2.18,"tv":3554.42,"id":9433864}]}]}
{"op":"mcm","clk":"4233772963","pt":1631538671121,"mc":[{"id":"1.187557653","rc":[{"batb":[[0,1.51,62.08],[1,1.48,55.26],[2,1.33,74.53]],"ltp":1.58,"tv":4255.84,"id":9632596},{"batb":[[0,1.75,34.38],[1,1.74,360.53],[2,1.46,2]],"batl":[[0,2.92,254.12],[1,3.1,4.15],[2,4.1,2.95]],"ltp":2.18,"tv":3554.42,"id":9433864}]}]}
{"op":"mcm","clk":"4233773229","pt":1631538674625,"mc":[{"id":"1.187557653","rc":[{"batb":[[1,1.46,2],[2,1.23,2]],"batl":[[0,3.1,4.15],[1,4.1,2.95],[2,4.1,0]],"ltp":2.18,"tv":3554.42,"id":9433864}]}]}
{"op":"mcm","clk":"4233773354","pt":1631538675931,"mc":[{"id":"1.187557653","rc":[{"batb":[[1,1.48,284.74],[2,1.43,37.97]],"batl":[[0,1.58,138.7],[1,1.59,34.15],[2,1.6,182.06]],"ltp":1.58,"tv":4255.84,"id":9632596},{"batb":[[0,2.64,11.36],[1,2.62,5.68],[2,2.6,5.68]],"batl":[[0,2.84,12.38],[1,3.1,4.15]],"ltp":2.18,"tv":3554.42,"id":9433864}]}]}
{"op":"mcm","clk":"4233773444","pt":1631538676819,"mc":[{"id":"1.187557653","rc":[{"batb":[[2,2.6,26.43]],"batl":[[0,2.84,22.94],[1,2.86,5.28],[2,2.88,5.28]],"ltp":2.18,"tv":3554.42,"id":9433864}]}]}
{"op":"mcm","clk":"4233773790","pt":1631538680747,"mc":[{"id":"1.187557653","rc":[{"trd":[[1.54,19.78]],"ltp":1.54,"tv":4267.94,"id":9632596},{"trd":[[2.84,10.72]],"batl":[[0,2.84,16.38]],"ltp":2.84,"tv":3560.98,"id":9433864}],"tv":7828.92}]}
{"op":"mcm","clk":"4233774681","pt":1631538690754,"mc":[{"id":"1.187557653","rc":[{"batl":[[0,1.58,126.58]],"ltp":1.54,"tv":4267.94,"id":9632596},{"batl":[[0,2.84,10.56]],"ltp":2.84,"tv":3560.98,"id":9433864}]}]}
{"op":"mcm","clk":"4233774910","pt":1631538693287,"mc":[{"id":"1.187557653","rc":[{"batb":[[1,1.48,55.26],[2,1.39,62.91]],"batl":[[0,1.84,0.77],[1,1.59,0],[2,1.6,0]],"ltp":1.54,"tv":4267.94,"id":9632596},{"batb":[[0,2.6,20.75],[1,2.1,38.4],[2,2.04,354.13]],"batl":[[0,3.1,4.15],[1,3.6,3.06],[2,3.9,184.64]],"ltp":2.84,"tv":3560.98,"id":9433864}]}]}
{"op":"mcm","clk":"4233774970","pt":1631538693866,"mc":[{"id":"1.187557653","rc":[{"batb":[[0,1.39,62.91],[1,1.34,100.56],[2,1.33,76.53]],"ltp":1.54,"tv":4267.94,"id":9632596},{"batb":[[0,2.1,38.4],[1,2.04,354.13],[2,1.46,2]],"batl":[[0,3.6,3.06],[1,3.9,184.64],[2,4.1,2.95]],"ltp":2.84,"tv":3560.98,"id":9433864}]}]}
{"op":"mcm","clk":"4233774995","pt":1631538694442,"mc":[{"id":"1.187557653","rc":[{"batb":[[0,1.34,100.56],[1,1.33,76.53],[2,1.01,113.68]],"ltp":1.54,"tv":4267.94,"id":9632596},{"batl":[[0,3.9,184.64],[1,4.1,2.95],[2,4.1,0]],"ltp":2.84,"tv":3560.98,"id":9433864}]}]}
{"op":"mcm","clk":"4233775144","pt":1631538696092,"mc":[{"id":"1.187557653","rc":[{"batl":[[0,2.72,1.8]],"ltp":2.84,"tv":3560.98,"id":9433864}]}]}
{"op":"mcm","clk":"4233775318","pt":1631538698181,"mc":[{"id":"1.187557653","rc":[{"batb":[[0,1.55,21.79],[1,1.34,100.56],[2,1.33,76.53]],"batl":[[0,1.62,20.75],[1,1.84,0.77]],"ltp":1.54,"tv":4267.94,"id":9632596},{"batl":[[1,2.82,21.75],[2,4.1,2.95]],"ltp":2.84,"tv":3560.98,"id":9433864}]}]}
{"op":"mcm","clk":"4233775351","pt":1631538698493,"mc":[{"id":"1.187557653","rc":[{"batb":[[0,1.34,100.56],[1,1.33,76.53],[2,1.01,113.68]],"batl":[[0,1.84,0.77],[1,1.84,0]],"ltp":1.54,"tv":4267.94,"id":9632596},{"batl":[[1,4.1,2.95],[2,4.1,0]],"ltp":2.84,"tv":3560.98,"id":9433864}]}]}
{"op":"mcm","clk":"4233775439","pt":1631538699482,"mc":[{"id":"1.187557653","rc":[{"batl":[[1,3.65,198.3],[2,4.1,2.95]],"ltp":2.84,"tv":3560.98,"id":9433864}]}]}
{"op":"mcm","clk":"4233775543","pt":1631538700776,"mc":[{"id":"1.187557653","rc":[{"batb":[[0,1.39,72.91],[1,1.34,100.56],[2,1.33,76.53]],"ltp":1.54,"tv":4267.94,"id":9632596},{"batl":[[1,3.6,3.31],[2,3.65,198.3]],"ltp":2.84,"tv":3560.98,"id":9433864}]}]}
{"op":"mcm","clk":"4233776316","pt":1631538710320,"mc":[{"id":"1.187557653","rc":[{"batb":[[1,1.46,2],[2,1.23,2]],"batl":[[2,4.1,2.95]],"ltp":2.84,"tv":3560.98,"id":9433864}]}]}
{"op":"mcm","clk":"4233776457","pt":1631538711785,"mc":[{"id":"1.187557653","rc":[{"trd":[[1.84,103.68]],"batb":[[0,1.82,59.14],[1,1.65,32.91],[2,1.63,16.66]],"batl":[[0,1.85,29.35],[1,1.86,20.19],[2,1.87,14.52]],"ltp":1.84,"tv":4268.71,"id":9632596},{"trd":[[2.18,13.95]],"batl":[[0,2.18,54.39],[1,2.22,16.25],[2,2.24,7.36]],"ltp":2.18,"tv":3561.63,"id":9433864}],"tv":7830.34}]}
{"op":"mcm","clk":"4233776580","pt":1631538713097,"mc":[{"id":"1.187557653","rc":[{"batb":[[1,1.75,36.14],[2,1.65,32.91]],"ltp":1.84,"tv":4268.71,"id":9632596},{"batb":[[1,1.74,34.89],[2,1.46,2]],"ltp":2.18,"tv":3561.63,"id":9433864}]}]}
{"op":"mcm","clk":"4233776716","pt":1631538714414,"mc":[{"id":"1.187557653","rc":[{"batb":[[1,1.74,395.41]],"ltp":2.18,"tv":3561.63,"id":9433864}]}]}
{"op":"mcm","clk":"4233778697","pt":1631538725764,"mc":[{"id":"1.187557653","rc":[{"trd":[[2.18,19.37]],"batl":[[0,2.18,51.68]],"ltp":2.18,"tv":3567.05,"id":9433864}],"tv":7835.76}]}
{"op":"mcm","clk":"4233779248","pt":1631538728732,"mc":[{"id":"1.187557653","rc":[{"batb":[[2,1.57,48.57]],"batl":[[0,1.86,20.19],[1,1.89,174.54],[2,1.9,7.94]],"ltp":1.84,"tv":4268.71,"id":9632596}]}]}
{"op":"mcm","clk":"4233779671","pt":1631538730876,"mc":[{"id":"1.187557653","rc":[{"batb":[[0,1.85,25],[1,1.82,59.14],[2,1.75,36.14]],"ltp":1.84,"tv":4268.71,"id":9632596}]}]}
{"op":"mcm","clk":"4233780465","pt":1631538735263,"mc":[{"id":"1.187557653","rc":[{"batl":[[1,1.89,158.66],[2,1.9,0]],"ltp":1.84,"tv":4268.71,"id":9632596},{"batl":[[0,2.22,16.25],[1,2.24,7.36],[2,2.76,4.52]],"ltp":2.18,"tv":3567.05,"id":9433864}]}]}
{"op":"mcm","clk":"4233780612","pt":1631538735871,"mc":[{"id":"1.187557653","rc":[{"batb":[[1,1.51,60.99],[2,1.48,52.01]],"ltp":1.84,"tv":4268.71,"id":9632596},{"batb":[[0,1.74,395.41],[1,1.46,2],[2,1.23,2]],"batl":[[0,2.92,254.12],[1,3.1,4.05],[2,3.6,3.31]],"ltp":2.18,"tv":3567.05,"id":9433864}]}]}
{"op":"mcm","clk":"4233782927","pt":1631538746561,"mc":[{"id":"1.187557653","rc":[{"batl":[[1,3.1,0],[2,3.6,0]],"ltp":2.18,"tv":3567.05,"id":9433864}]}]}
{"op":"mcm","clk":"4233783596","pt":1631538749161,"mc":[{"id":"1.187557653","rc":[{"batb":[[0,2.3,65.22],[1,2.28,32.6],[2,2.26,32.6]],"batl":[[0,2.4,142.52]],"ltp":1.84,"tv":4268.71,"id":9632596},{"batb":[[0,1.76,14.08],[1,1.74,34.89],[2,1.46,2]],"batl":[[0,1.77,1722.78],[1,1.78,117.98],[2,1.8,10.34]],"ltp":2.18,"tv":3567.05,"id":9433864}]}]}
{"op":"mcm","clk":"4233783752","pt":1631538750258,"mc":[{"id":"1.187557653","rc":[{"batb":[[0,2.3,39.13],[1,2.28,19.56],[2,2.26,19.56]],"batl":[[1,2.54,3.94]],"ltp":1.84,"tv":4268.71,"id":9632596},{"batb":[[1,1.75,31.03],[2,1.74,34.89]],"batl":[[0,1.78,73.04],[1,1.8,10.34],[2,1.92,215.66]],"ltp":2.18,"tv":3567.05,"id":9433864}]}]}
{"op":"mcm","clk":"4233783783","pt":1631538750569,"mc":[{"id":"1.187557653","rc":[{"batb":[[0,2.3,13.04],[1,2.28,6.52],[2,2.26,6.52]],"ltp":1.84,"tv":4268.71,"id":9632596}]}]}
{"op":"mcm","clk":"4233784165","pt":1631538754170,"mc":[{"id":"1.187557653","rc":[{"batl":[[2,1.92,332.21]],"ltp":2.18,"tv":3567.05,"id":9433864}]}]}
{"op":"mcm","clk":"4233784190","pt":1631538754381,"mc":[{"id":"1.187557653","rc":[{"batl":[[2,1.92,215.66]],"ltp":2.18,"tv":3567.05,"id":9433864}]}]}
{"op":"mcm","clk":"4233785229","pt":1631538764994,"mc":[{"id":"1.187557653","rc":[{"trd":[[2.4,142.52]],"batl":[[0,2.54,3.94],[1,2.54,0]],"ltp":2.4,"tv":4411.23,"id":9632596},{"trd":[[1.71,224.47],[1.73,57.77],[1.74,90.66],[1.75,74.17],[1.76,101.72]],"batb":[[0,1.69,17.76],[1,1.68,8.88],[2,1.67,8.88]],"batl":[[0,1.7,932.88],[1,1.78,73.04],[2,1.8,10.34]],"ltp":1.71,"tv":3958.44,"id":9433864}],"tv":8369.68}]}
{"op":"mcm","clk":"4233785390","pt":1631538767014,"mc":[{"id":"1.187557653","rc":[{"batl":[[1,1.76,1.16],[2,1.78,73.04]],"ltp":1.71,"tv":3958.44,"id":9433864}]}]}
{"op":"mcm","clk":"4233785507","pt":1631538768215,"mc":[{"id":"1.187557653","rc":[{"trd":[[1.7,615.01]],"batl":[[0,1.7,640.98]],"ltp":1.7,"tv":4542.25,"id":9433864}],"tv":8953.49}]}
{"op":"mcm","clk":"4233785593","pt":1631538769110,"mc":[{"id":"1.187557653","rc":[{"trd":[[1.7,685.95]],"batl":[[0,1.7,605.51],[1,1.76,15.62]],"ltp":1.7,"tv":4613.19,"id":9433864}],"tv":9024.43}]}
{"op":"mcm","clk":"4233785646","pt":1631538769585,"mc":[{"id":"1.187557653","rc":[{"trd":[[1.7,745.95]],"batl":[[0,1.7,575.51]],"ltp":1.7,"tv":4673.19,"id":9433864}],"tv":9084.43}]}
{"op":"mcm","clk":"4233785826","pt":1631538771813,"mc":[{"id":"1.187557653","rc":[{"batb":[[0,1.69,334.76]],"ltp":1.7,"tv":4673.19,"id":9433864}]}]}
{"op":"mcm","clk":"4233786224","pt":1631538776908,"mc":[{"id":"1.187557653","rc":[{"trd":[[1.7,818.23]],"batl":[[0,1.7,539.37]],"ltp":1.7,"tv":4745.47,"id":9433864}],"tv":9156.71}]}
{"op":"mcm","clk":"4233786346","pt":1631538778108,"mc":[{"id":"1.187557653","rc":[{"trd":[[1.7,844.88]],"batl":[[0,1.7,526.05],[2,1.78,85.4]],"ltp":1.7,"tv":4772.12,"id":9433864}],"tv":9183.36}]}
{"op":"mcm","clk":"4233786963","pt":1631538784930,"mc":[{"id":"1.187557653","rc":[{"trd":[[1.7,918.33]],"batl":[[0,1.7,489.32]],"ltp":1.7,"tv":4845.58,"id":9433864}],"tv":9256.81}]}
{"op":"mcm","clk":"4233787285","pt":1631538788614,"mc":[{"id":"1.187557653","rc":[{"trd":[[1.69,35.78]],"batb":[[0,1.69,316.87]],"batl":[[2,1.78,73.04]],"ltp":1.69,"tv":4881.35,"id":9433864}],"tv":9292.59}]}
{"op":"mcm","clk":"4233787516","pt":1631538791359,"mc":[{"id":"1.187557653","rc":[{"batb":[[0,2.32,8.58],[1,2.3,13.04],[2,2.28,6.52]],"ltp":2.4,"tv":4411.23,"id":9632596},{"trd":[[1.7,945.9]],"batl":[[0,1.7,475.54]],"ltp":1.7,"tv":4908.92,"id":9433864}],"tv":9320.15}]}
{"op":"mcm","clk":"4233787685","pt":1631538793036,"mc":[{"id":"1.187557653","rc":[{"trd":[[1.7,1020.68]],"batl":[[0,1.7,438.14]],"ltp":1.7,"tv":4983.7,"id":9433864}],"tv":9394.94}]}
{"op":"mcm","clk":"4233788257","pt":1631538799180,"mc":[{"id":"1.187557653","rc":[{"trd":[[1.7,1020.84]],"batl":[[0,1.7,438.06]],"ltp":1.7,"tv":4983.86,"id":9433864}],"tv":9395.1}]}
{"op":"mcm","clk":"4233788435","pt":1631538801058,"mc":[{"id":"1.187557653","rc":[{"batb":[[0,1.69,354.94]],"ltp":1.7,"tv":4983.86,"id":9433864}]}]}
{"op":"mcm","clk":"4233788476","pt":1631538801576,"mc":[{"id":"1.187557653","rc":[{"batb":[[0,2.3,13.04],[1,2.28,6.52],[2,2.26,6.52]],"ltp":2.4,"tv":4411.23,"id":9632596}]}]}
{"op":"mcm","clk":"4233788800","pt":1631538805065,"mc":[{"id":"1.187557653","rc":[{"trd":[[2.42,11.98]],"batb":[[0,2.36,7.59],[1,2.3,13.04],[2,2.28,6.52]],"ltp":2.42,"tv":4419.08,"id":9632596},{"trd":[[1.7,1032.02]],"batl":[[0,1.7,426.89],[1,1.76,1.16]],"ltp":1.7,"tv":4995.04,"id":9433864}],"tv":9414.12}]}
{"op":"mcm","clk":"4233788905","pt":1631538806288,"mc":[{"id":"1.187557653","rc":[{"trd":[[1.7,1032.18]],"batl":[[0,1.7,426.81]],"ltp":1.7,"tv":4995.2,"id":9433864}],"tv":9414.28}]}
{"op":"mcm","clk":"4233789064","pt":1631538808198,"mc":[{"id":"1.187557653","rc":[{"trd":[[1.69,64.68]],"batb":[[0,1.69,340.49]],"ltp":1.69,"tv":5024.1,"id":9433864}],"tv":9443.19}]}
{"op":"mcm","clk":"4233789500","pt":1631538812990,"mc":[{"id":"1.187557653","rc":[{"trd":[[1.69,745.65]],"batb":[[0,1.68,8.88],[1,1.67,8.88],[2,1.57,49.36]],"batl":[[0,1.69,42.28],[1,1.7,426.81],[2,1.76,1.16]],"ltp":1.69,"tv":5705.07,"id":9433864}],"tv":10124.16}]}
{"op":"mcm","clk":"4233789658","pt":1631538814699,"mc":[{"id":"1.187557653","rc":[{"batb":[[0,2.3,13.04],[1,2.28,6.52],[2,2.26,6.52]],"ltp":2.42,"tv":4419.08,"id":9632596}]}]}
