{"op":"mcm","clk":"4228627361","pt":1631462832250,"mc":[{"id":"1.187557759","marketDefinition":{"bspMarket":false,"turnInPlayEnabled":true,"persistenceEnabled":true,"marketBaseRate":5.0,"eventId":"30896122","eventTypeId":"2","numberOfWinners":1,"bettingType":"ODDS","marketType":"MATCH_ODDS","marketTime":"2021-09-13T11:00:00.000Z","suspendTime":"2021-09-13T11:00:00.000Z","bspReconciled":false,"complete":true,"inPlay":false,"crossMatching":false,"runnersVoidable":false,"numberOfActiveRunners":2,"betDelay":0,"status":"OPEN","runners":[{"status":"ACTIVE","sortPriority":1,"id":9634485,"name":"Nicola Kuhn"},{"status":"ACTIVE","sortPriority":2,"id":9712888,"name":"Matteo Martineau"}],"regulators":["MR_INT"],"countryCode":"PL","discountAllowed":false,"timezone":"UTC","openDate":"2021-09-13T11:00:00.000Z","version":4029036632,"name":"Match Odds","eventName":"Kuhn v Martineau"},"rc":[{"batb":[[0,1.01,25]],"ltp":0.0,"tv":0.0,"id":9634485},{"batb":[[0,1.01,25]],"ltp":0.0,"tv":0.0,"id":9712888}]}]}
{"op":"mcm","clk":"4228627983","pt":1631462833871,"mc":[{"id":"1.187557759","marketDefinition":{"bspMarket":false,"turnInPlayEnabled":true,"persistenceEnabled":true,"marketBaseRate":5.0,"eventId":"30896122","eventTypeId":"2","numberOfWinners":1,"bettingType":"ODDS","marketType":"MATCH_ODDS","marketTime":"2021-09-13T11:00:00.000Z","suspendTime":"2021-09-13T11:00:00.000Z","bspReconciled":false,"complete":true,"inPlay":false,"crossMatching":false,"runnersVoidable":false,"numberOfActiveRunners":2,"betDelay":0,"status":"OPEN","runners":[{"status":"ACTIVE","sortPriority":1,"id":9634485,"name":"Nicola Kuhn"},{"status":"ACTIVE","sortPriority":2,"id":9712888,"name":"Matteo Martineau"}],"regulators":["MR_INT"],"countryCode":"PL","discountAllowed":true,"timezone":"UTC","openDate":"2021-09-13T11:00:00.000Z","version":4029036632,"name":"Match Odds","eventName":"Kuhn v Martineau"}}]}
{"op":"mcm","clk":"4228685849","pt":1631463136848,"mc":[{"id":"1.187557759","rc":[{"batl":[[0,990,2.2]],"ltp":0.0,"tv":0.0,"id":9634485},{"batl":[[0,990,2.2]],"ltp":0.0,"tv":0.0,"id":9712888}]}]}
{"op":"mcm","clk":"4228718141","pt":1631463307591,"mc":[{"id":"1.187557759","rc":[{"batb":[[0,1.01,15]],"ltp":0.0,"tv":0.0,"id":9634485},{"batb":[[0,1.01,15]],"ltp":0.0,"tv":0.0,"id":9712888}]}]}
{"op":"mcm","clk":"4228885145","pt":1631464244305,"mc":[{"id":"1.187557759","rc":[{"batb":[[0,1.01,108.94]],"ltp":0.0,"tv":0.0,"id":9634485},{"batb":[[0,1.01,108.94]],"ltp":0.0,"tv":0.0,"id":9712888}]}]}
{"op":"mcm","clk":"4230083715","pt":1631471739034,"mc":[{"id":"1.187557759","rc":[{"batb":[[0,1.83,27.16],[1,1.01,108.94]],"ltp":0.0,"tv":0.0,"id":9634485},{"batb":[[0,1.83,27.16],[1,1.01,108.94]],"ltp":0.0,"tv":0.0,"id":9712888}]}]}
{"op":"mcm","clk":"4230085033","pt":1631471749920,"mc":[{"id":"1.187557759","marketDefinition":{"bspMarket":false,"turnInPlayEnabled":true,"persistenceEnabled":true,"marketBaseRate":5.0,"eventId":"30896122","eventTypeId":"2","numberOfWinners":1,"bettingType":"ODDS","marketType":"MATCH_ODDS","marketTime":"2021-09-13T11:00:00.000Z","suspendTime":"2021-09-13T11:00:00.000Z","bspReconciled":false,"complete":true,"inPlay":false,"crossMatching":true,"runnersVoidable":false,"numberOfActiveRunners":2,"betDelay":0,"status":"OPEN","runners":[{"status":"ACTIVE","sortPriority":1,"id":9634485,"name":"Nicola Kuhn"},{"status":"ACTIVE","sortPriority":2,"id":9712888,"name":"Matteo Martineau"}],"regulators":["MR_INT"],"countryCode":"PL","discountAllowed":true,"timezone":"UTC","openDate":"2021-09-13T11:00:00.000Z","version":4029036632,"name":"Match Odds","eventName":"Kuhn v Martineau"}}]}
{"op":"mcm","clk":"4230165222","pt":1631472415576,"mc":[{"id":"1.187557759","rc":[{"batl":[[0,12,3.42],[1,990,2.2]],"ltp":0.0,"tv":0.0,"id":9712888}]}]}
{"op":"mcm","clk":"4230165264","pt":1631472415894,"mc":[{"id":"1.187557759","rc":[{"batl":[[0,12,3.42],[1,990,2.2]],"ltp":0.0,"tv":0.0,"id":9634485}]}]}
{"op":"mcm","clk":"4230219082","pt":1631472852695,"mc":[{"id":"1.187557759","rc":[{"batb":[[1,1.01,581.8]],"ltp":0.0,"tv":0.0,"id":9634485}]}]}
{"op":"mcm","clk":"4230219109","pt":1631472853012,"mc":[{"id":"1.187557759","rc":[{"batb":[[1,1.01,581.8]],"ltp":0.0,"tv":0.0,"id":9712888}]}]}
{"op":"mcm","clk":"4230362116","pt":1631474227998,"mc":[{"id":"1.187557759","rc":[{"batb":[[1,1.25,14.46],[2,1.01,581.8]],"ltp":0.0,"tv":0.0,"id":9634485},{"batb":[[1,1.25,14.46],[2,1.01,581.8]],"ltp":0.0,"tv":0.0,"id":9712888}]}]}
{"op":"mcm","clk":"4230594982","pt":1631477172205,"mc":[{"id":"1.187557759","rc":[{"batb":[[2,1.01,586.76]],"batl":[[0,12,3.42]],"ltp":0.0,"tv":0.0,"id":9634485},{"batb":[[2,1.01,586.76]],"batl":[[0,12,3.42]],"ltp":0.0,"tv":0.0,"id":9712888}]}]}
{"op":"mcm","clk":"4230734628","pt":1631479434850,"mc":[{"id":"1.187557759","rc":[{"batb":[[0,1.8,28.18]],"ltp":0.0,"tv":0.0,"id":9634485},{"batb":[[0,1.87,25.91]],"ltp":0.0,"tv":0.0,"id":9712888}]}]}
{"op":"mcm","clk":"4230743722","pt":1631479647342,"mc":[{"id":"1.187557759","rc":[{"batb":[[0,1.73,30.88]],"ltp":0.0,"tv":0.0,"id":9634485},{"batb":[[0,1.95,23.73]],"ltp":0.0,"tv":0.0,"id":9712888}]}]}
{"op":"mcm","clk":"4230772839","pt":1631480396294,"mc":[{"id":"1.187557759","rc":[{"batb":[[0,1.7,32.2]],"ltp":0.0,"tv":0.0,"id":9634485},{"batb":[[0,2,22.54]],"ltp":0.0,"tv":0.0,"id":9712888}]}]}
{"op":"mcm","clk":"4230793166","pt":1631480877013,"mc":[{"id":"1.187557759","rc":[{"batb":[[0,1.67,33.65]],"ltp":0.0,"tv":0.0,"id":9634485}]}]}
{"op":"mcm","clk":"4230964579","pt":1631484954710,"mc":[{"id":"1.187557759","rc":[{"batb":[[0,1.67,39.65],[1,1.25,14.46],[2,1.01,586.68]],"ltp":0.0,"tv":0.0,"id":9634485},{"batb":[[1,1.25,14.46],[2,1.01,586.68]],"ltp":0.0,"tv":0.0,"id":9712888}]}]}
{"op":"mcm","clk":"4231000040","pt":1631485765765,"mc":[{"id":"1.187557759","rc":[{"batb":[[1,1.3,768.51],[2,1.25,14.46]],"ltp":0.0,"tv":0.0,"id":9634485},{"batb":[[1,1.4,768.51],[2,1.25,14.46]],"ltp":0.0,"tv":0.0,"id":9712888}]}]}
{"op":"mcm","clk":"4231000353","pt":1631485773385,"mc":[{"id":"1.187557759","rc":[{"batb":[[1,1.31,29.03],[2,1.3,768.51]],"ltp":0.0,"tv":0.0,"id":9634485},{"batb":[[1,1.41,23.91],[2,1.4,768.51]],"ltp":0.0,"tv":0.0,"id":9712888}]}]}
{"op":"mcm","clk":"4231003766","pt":1631485855480,"mc":[{"id":"1.187557759","rc":[{"batb":[[1,1.31,35.78]],"ltp":0.0,"tv":0.0,"id":9634485}]}]}
{"op":"mcm","clk":"4231089297","pt":1631487789933,"mc":[{"id":"1.187557759","rc":[{"batb":[[1,1.31,35.77],[2,1.3,768.38]],"batl":[[0,1.9,25],[1,12,3.42],[2,990,2.2]],"ltp":0.0,"tv":0.0,"id":9634485},{"batb":[[1,1.41,23.91],[2,1.4,768.38]],"batl":[[0,2.5,25],[1,12,3.42],[2,990,2.2]],"ltp":0.0,"tv":0.0,"id":9712888}]}]}
{"op":"mcm","clk":"4231090819","pt":1631487826685,"mc":[{"id":"1.187557759","rc":[{"batl":[[1,990,2.2],[2,990,0]],"ltp":0.0,"tv":0.0,"id":9634485},{"batl":[[1,990,2.2],[2,990,0]],"ltp":0.0,"tv":0.0,"id":9712888}]}]}
{"op":"mcm","clk":"4231090940","pt":1631487829516,"mc":[{"id":"1.187557759","rc":[{"batb":[[1,1.31,29.03]],"ltp":0.0,"tv":0.0,"id":9634485}]}]}
{"op":"mcm","clk":"4231255219","pt":1631491231580,"mc":[{"id":"1.187557759","rc":[{"batb":[[0,2.04,21.67]],"ltp":0.0,"tv":0.0,"id":9712888}]}]}
{"op":"mcm","clk":"4231459653","pt":1631494642519,"mc":[{"id":"1.187557759","rc":[{"batl":[[0,2.46,3.63],[1,2.5,25],[2,990,2.2]],"ltp":0.0,"tv":0.0,"id":9712888}]}]}
{"op":"mcm","clk":"4231460735","pt":1631494668661,"mc":[{"id":"1.187557759","rc":[{"batl":[[0,2.46,2.94]],"ltp":0.0,"tv":0.0,"id":9712888}]}]}
{"op":"mcm","clk":"4231481215","pt":1631495087165,"mc":[{"id":"1.187557759","rc":[{"trd":[[1.67,18.94],[1.68,4.3]],"batb":[[0,1.67,30.18],[1,1.31,29.01],[2,1.3,767.98]],"ltp":1.67,"tv":23.24,"id":9634485},{"trd":[[2.46,2.94]],"batb":[[1,1.41,23.89],[2,1.4,767.98]],"batl":[[0,2.5,25],[1,990,2.2],[2,990,0]],"ltp":2.46,"tv":2.93,"id":9712888}],"tv":26.17}]}
{"op":"mcm","clk":"4231481440","pt":1631495091409,"mc":[{"id":"1.187557759","rc":[{"batb":[[0,1.67,39.65]],"ltp":1.67,"tv":23.24,"id":9634485}]}]}
{"op":"mcm","clk":"4231710108","pt":1631501873395,"mc":[{"id":"1.187557759","rc":[{"batb":[[0,1.67,41.03]],"ltp":1.67,"tv":23.24,"id":9634485}]}]}
{"op":"mcm","clk":"4231713229","pt":1631502011889,"mc":[{"id":"1.187557759","rc":[{"batb":[[1,1.31,29.01],[2,1.3,767.79]],"ltp":1.67,"tv":23.23,"id":9634485},{"trd":[[2.46,2.93]],"batb":[[0,2.1,20.49],[1,1.41,23.89],[2,1.4,767.79]],"ltp":2.46,"tv":2.93,"id":9712888}],"tv":26.17}]}
{"op":"mcm","clk":"4231804469","pt":1631504968726,"mc":[{"id":"1.187557759","rc":[{"trd":[[1.9,25]],"batl":[[0,2.2,47.98]],"ltp":1.9,"tv":48.23,"id":9634485},{"trd":[[2.1,130.26]],"batb":[[0,1.62,74.07]],"batl":[[0,2.1,174.53],[1,2.5,25],[2,990,2.2]],"ltp":2.1,"tv":133.19,"id":9712888}],"tv":181.43}]}
{"op":"mcm","clk":"4231804506","pt":1631504969748,"mc":[{"id":"1.187557759","rc":[{"batb":[[0,1.74,9.31],[1,1.67,41.03],[2,1.31,29.01]],"batl":[[0,3.85,56.23]],"ltp":1.9,"tv":48.23,"id":9634485},{"batb":[[0,1.42,135.64]],"ltp":2.1,"tv":133.19,"id":9712888}]}]}
{"op":"mcm","clk":"4231804538","pt":1631504970520,"mc":[{"id":"1.187557759","rc":[{"batl":[[0,3.8,27.32]],"ltp":1.9,"tv":48.23,"id":9634485},{"batb":[[0,1.41,23.89],[1,1.4,767.79],[2,1.33,21.9]],"ltp":2.1,"tv":133.19,"id":9712888}]}]}
{"op":"mcm","clk":"4231804597","pt":1631504972361,"mc":[{"id":"1.187557759","rc":[{"batb":[[0,1.97,23.24],[1,1.41,23.89],[2,1.4,767.79]],"ltp":2.1,"tv":133.19,"id":9712888}]}]}
{"op":"mcm","clk":"4231815354","pt":1631505269422,"mc":[{"id":"1.187557759","rc":[{"batl":[[0,2.6,107.83]],"ltp":1.9,"tv":48.23,"id":9634485}]}]}
{"op":"mcm","clk":"4231821968","pt":1631505480039,"mc":[{"id":"1.187557759","rc":[{"batl":[[0,2.52,40.52]],"ltp":1.9,"tv":48.23,"id":9634485}]}]}
{"op":"mcm","clk":"4231837497","pt":1631505923776,"mc":[{"id":"1.187557759","rc":[{"batb":[[0,1.67,41.03],[1,1.31,29.01],[2,1.3,767.79]],"batl":[[0,990,2.2],[1,990,0]],"ltp":1.9,"tv":48.23,"id":9634485},{"trd":[[1.97,46.49]],"batb":[[0,1.89,25.33]],"ltp":1.97,"tv":179.67,"id":9712888}],"tv":227.91}]}
{"op":"mcm","clk":"4231837507","pt":1631505924083,"mc":[{"id":"1.187557759","rc":[{"batb":[[0,1.77,23.8],[1,1.67,41.03],[2,1.31,29.01]],"batl":[[0,3.75,59.8],[1,990,2.2]],"ltp":1.9,"tv":48.23,"id":9634485}]}]}
{"op":"mcm","clk":"4231853020","pt":1631506398959,"mc":[{"id":"1.187557759","rc":[{"trd":[[2.1,159.29]],"batl":[[0,2.1,160.02]],"ltp":2.1,"tv":208.7,"id":9712888}],"tv":256.94}]}
{"op":"mcm","clk":"4231883243","pt":1631507224277,"mc":[{"id":"1.187557759","rc":[{"trd":[[1.9,52.84]],"ltp":1.9,"tv":76.07,"id":9634485},{"trd":[[2.1,184.45]],"batl":[[0,2.1,134.86]],"ltp":2.1,"tv":233.87,"id":9712888}],"tv":309.94}]}
{"op":"mcm","clk":"4231890924","pt":1631507484619,"mc":[{"id":"1.187557759","rc":[{"trd":[[1.9,192.01]],"ltp":1.9,"tv":215.25,"id":9634485},{"trd":[[2.1,310.27]],"batl":[[0,2.1,9.04]],"ltp":2.1,"tv":359.69,"id":9712888}],"tv":574.94}]}
{"op":"mcm","clk":"4231890956","pt":1631507485438,"mc":[{"id":"1.187557759","rc":[{"batb":[[0,1.67,41.03],[1,1.31,29.01],[2,1.3,767.79]],"ltp":1.9,"tv":215.25,"id":9634485}]}]}
{"op":"mcm","clk":"4231916216","pt":1631508385342,"mc":[{"id":"1.187557759","rc":[{"batb":[[0,1.7,10.6],[1,1.67,41.03],[2,1.31,29.01]],"ltp":1.9,"tv":215.25,"id":9634485}]}]}
{"op":"mcm","clk":"4231916225","pt":1631508385957,"mc":[{"id":"1.187557759","rc":[{"batb":[[0,1.67,41.03],[1,1.31,29.01],[2,1.3,767.79]],"ltp":1.9,"tv":215.25,"id":9634485}]}]}
{"op":"mcm","clk":"4231931196","pt":1631508685376,"mc":[{"id":"1.187557759","rc":[{"batb":[[0,1.71,10.53],[1,1.67,41.03],[2,1.31,29.01]],"ltp":1.9,"tv":215.25,"id":9634485}]}]}
{"op":"mcm","clk":"4231931214","pt":1631508685888,"mc":[{"id":"1.187557759","rc":[{"batb":[[0,1.67,41.03],[1,1.31,29.01],[2,1.3,767.79]],"ltp":1.9,"tv":215.25,"id":9634485}]}]}
{"op":"mcm","clk":"4231944372","pt":1631509202665,"mc":[{"id":"1.187557759","rc":[{"batb":[[0,1.67,57.85]],"ltp":1.9,"tv":215.25,"id":9634485},{"batb":[[0,1.89,37.99]],"ltp":2.1,"tv":359.69,"id":9712888}]}]}
{"op":"mcm","clk":"4231947169","pt":1631509285445,"mc":[{"id":"1.187557759","rc":[{"trd":[[1.67,18.95],[1.68,4.31],[1.9,191.84]],"batb":[[0,1.7,10.6],[1,1.67,57.85],[2,1.31,29.01]],"ltp":1.9,"tv":215.08,"id":9634485},{"trd":[[1.97,46.49],[2.1,310.24]],"batb":[[1,1.41,23.89],[2,1.4,767.85]],"ltp":2.1,"tv":359.66,"id":9712888}],"tv":574.75}]}
{"op":"mcm","clk":"4231947188","pt":1631509285854,"mc":[{"id":"1.187557759","rc":[{"batb":[[0,1.67,57.85],[1,1.31,29.01],[2,1.3,767.85]],"ltp":1.9,"tv":215.08,"id":9634485}]}]}
{"op":"mcm","clk":"4231961578","pt":1631509585568,"mc":[{"id":"1.187557759","rc":[{"batb":[[0,1.7,10.6],[1,1.67,57.85],[2,1.31,29.01]],"ltp":1.9,"tv":215.08,"id":9634485}]}]}
{"op":"mcm","clk":"4231961618","pt":1631509586338,"mc":[{"id":"1.187557759","rc":[{"batb":[[0,1.68,26.14]],"batl":[[0,3.25,77.01]],"ltp":1.9,"tv":215.08,"id":9634485}]}]}
{"op":"mcm","clk":"4231975370","pt":1631509824348,"mc":[{"id":"1.187557759","rc":[{"batl":[[0,2.52,132.54]],"ltp":1.9,"tv":215.08,"id":9634485}]}]}
{"op":"mcm","clk":"4232013081","pt":1631510664766,"mc":[{"id":"1.187557759","rc":[{"batb":[[2,1.36,49.21]],"ltp":1.9,"tv":215.08,"id":9634485}]}]}
{"op":"mcm","clk":"4232032003","pt":1631511241834,"mc":[{"id":"1.187557759","rc":[{"batb":[[0,1.67,57.85],[1,1.36,49.21],[2,1.31,29.01]],"batl":[[0,2,3]],"ltp":1.9,"tv":215.08,"id":9634485}]}]}
{"op":"mcm","clk":"4232032010","pt":1631511241937,"mc":[{"id":"1.187557759","rc":[{"batb":[[0,1.68,26.14],[1,1.67,57.85],[2,1.36,49.21]],"ltp":1.9,"tv":215.08,"id":9634485}]}]}
{"op":"mcm","clk":"4232037105","pt":1631511394054,"mc":[{"id":"1.187557759","rc":[{"batl":[[0,2,3.1]],"ltp":1.9,"tv":215.08,"id":9634485}]}]}
{"op":"mcm","clk":"4232037412","pt":1631511402368,"mc":[{"id":"1.187557759","rc":[{"trd":[[1.9,191.94]],"batl":[[0,2,3]],"ltp":1.9,"tv":215.18,"id":9634485},{"trd":[[2.1,310.33]],"batl":[[0,2.1,8.95]],"ltp":2.1,"tv":359.75,"id":9712888}],"tv":574.94}]}
{"op":"mcm","clk":"4232039522","pt":1631511456672,"mc":[{"id":"1.187557759","rc":[{"batl":[[1,46,29.03],[2,990,2.2]],"ltp":1.9,"tv":215.18,"id":9634485},{"batl":[[2,46,29.03]],"ltp":2.1,"tv":359.75,"id":9712888}]}]}
{"op":"mcm","clk":"4232060627","pt":1631512006467,"mc":[{"id":"1.187557759","rc":[{"batl":[[1,2.34,2.66],[2,46,29.03]],"ltp":1.9,"tv":215.18,"id":9634485}]}]}
{"op":"mcm","clk":"4232078888","pt":1631512496119,"mc":[{"id":"1.187557759","rc":[{"trd":[[2,3]],"batl":[[0,2.3,66.11]],"ltp":2.0,"tv":218.18,"id":9634485},{"trd":[[2,3]],"batl":[[0,2,4.23],[1,2.1,8.95],[2,2.5,25]],"ltp":2.0,"tv":362.75,"id":9712888}],"tv":580.94}]}
{"op":"mcm","clk":"4232083326","pt":1631512613541,"mc":[{"id":"1.187557759","rc":[{"trd":[[2,6]],"ltp":2.0,"tv":221.18,"id":9634485},{"trd":[[2,8.46]],"batl":[[0,2.1,8.95],[1,2.5,25],[2,46,29.03]],"ltp":2.0,"tv":368.21,"id":9712888}],"tv":589.4}]}
{"op":"mcm","clk":"4232088537","pt":1631512796204,"mc":[{"id":"1.187557759","rc":[{"batl":[[0,2.34,2.66],[1,46,29.03],[2,990,2.2]],"ltp":2.0,"tv":221.18,"id":9634485}]}]}
{"op":"mcm","clk":"4232106312","pt":1631513311168,"mc":[{"id":"1.187557759","rc":[{"trd":[[2.1,319.31]],"batl":[[0,2.1,4.46]],"ltp":2.1,"tv":377.19,"id":9712888}],"tv":598.38}]}
{"op":"mcm","clk":"4232116117","pt":1631513503353,"mc":[{"id":"1.187557759","rc":[{"batb":[[0,1.67,57.85],[1,1.36,49.21],[2,1.31,29.01]],"ltp":2.0,"tv":221.18,"id":9634485}]}]}
{"op":"mcm","clk":"4232124109","pt":1631513642306,"mc":[{"id":"1.187557759","rc":[{"batb":[[0,1.69,10.66],[1,1.67,57.85],[2,1.36,49.21]],"batl":[[0,2.3,4.74],[1,2.34,2.66],[2,46,29.03]],"ltp":2.0,"tv":221.18,"id":9634485}]}]}
{"op":"mcm","clk":"4232172083","pt":1631514445554,"mc":[{"id":"1.187557759","rc":[{"batb":[[0,1.67,57.85],[1,1.36,49.21],[2,1.31,29.01]],"ltp":2.0,"tv":221.18,"id":9634485}]}]}
{"op":"mcm","clk":"4232175077","pt":1631514542479,"mc":[{"id":"1.187557759","rc":[{"batb":[[0,1.69,10.66],[1,1.67,57.85],[2,1.36,49.21]],"batl":[[0,2.32,198.39]],"ltp":2.0,"tv":221.18,"id":9634485}]}]}
{"op":"mcm","clk":"4232179867","pt":1631514675717,"mc":[{"id":"1.187557759","rc":[{"batb":[[0,1.67,57.85],[1,1.36,49.21],[2,1.31,29.01]],"ltp":2.0,"tv":221.18,"id":9634485}]}]}
{"op":"mcm","clk":"4232184114","pt":1631514793633,"mc":[{"id":"1.187557759","rc":[{"batb":[[1,1.42,97.66],[2,1.36,49.21]],"ltp":2.0,"tv":221.18,"id":9634485},{"batb":[[1,1.5,87.98],[2,1.41,23.89]],"ltp":2.1,"tv":377.19,"id":9712888}]}]}
{"op":"mcm","clk":"4232194563","pt":1631515074778,"mc":[{"id":"1.187557759","rc":[{"trd":[[1.89,8.8]],"batb":[[0,1.89,33.59]],"ltp":1.89,"tv":385.99,"id":9712888}],"tv":607.18}]}
{"op":"mcm","clk":"4232194648","pt":1631515078306,"mc":[{"id":"1.187557759","rc":[{"batb":[[0,1.89,37.99]],"ltp":1.89,"tv":385.99,"id":9712888}]}]}
{"op":"mcm","clk":"4232226372","pt":1631516036711,"mc":[{"id":"1.187557759","rc":[{"batb":[[0,1.67,7.38],[1,1.62,54.54],[2,1.42,97.66]],"batl":[[0,2.34,2.66],[1,46,29.03],[2,990,2.2]],"ltp":2.0,"tv":221.18,"id":9634485},{"batb":[[0,1.51,171.39]],"ltp":1.89,"tv":385.99,"id":9712888}]}]}
{"op":"mcm","clk":"4232226383","pt":1631516036916,"mc":[{"id":"1.187557759","rc":[{"batb":[[0,1.5,87.98],[1,1.41,23.89],[2,1.4,767.85]],"ltp":1.89,"tv":385.99,"id":9712888}]}]}
{"op":"mcm","clk":"4232226603","pt":1631516042207,"mc":[{"id":"1.187557759","rc":[{"batb":[[0,1.68,5.31],[1,1.67,7.38],[2,1.62,54.54]],"ltp":2.0,"tv":221.18,"id":9634485}]}]}
{"op":"mcm","clk":"4232228316","pt":1631516085499,"mc":[{"id":"1.187557759","rc":[{"batb":[[0,1.51,15.36],[1,1.5,87.98],[2,1.41,23.89]],"ltp":1.89,"tv":385.99,"id":9712888}]}]}
{"op":"mcm","clk":"4232236051","pt":1631516276997,"mc":[{"id":"1.187557759","rc":[{"batb":[[0,1.67,7.38],[1,1.62,54.54],[2,1.42,97.66]],"ltp":2.0,"tv":221.18,"id":9634485}]}]}
{"op":"mcm","clk":"4232254442","pt":1631516642283,"mc":[{"id":"1.187557759","rc":[{"trd":[[1.67,18.97],[1.68,4.31],[1.9,192.27]],"batb":[[0,1.68,5.31],[1,1.67,7.38],[2,1.62,54.54]],"batl":[[0,2.34,2.66],[1,46,29.07]],"ltp":2.0,"tv":221.54,"id":9634485},{"trd":[[1.89,8.8],[1.97,46.49],[2,8.47],[2.1,319.43]],"batb":[[0,1.51,15.36],[1,1.5,88.09],[2,1.41,23.89]],"batl":[[0,2.1,4.46],[2,46,29.07]],"ltp":1.89,"tv":386.13,"id":9712888}],"tv":607.67}]}
{"op":"mcm","clk":"4232261192","pt":1631516757974,"mc":[{"id":"1.187557759","rc":[{"batb":[[0,1.67,7.38],[1,1.62,54.54],[2,1.42,97.78]],"ltp":2.0,"tv":221.54,"id":9634485}]}]}
{"op":"mcm","clk":"4232267097","pt":1631516846648,"mc":[{"id":"1.187557759","rc":[{"batb":[[2,1.41,31.11]],"ltp":1.89,"tv":386.13,"id":9712888}]}]}
{"op":"mcm","clk":"4232275833","pt":1631516995949,"mc":[{"id":"1.187557759","rc":[{"batb":[[0,1.9,28.16],[1,1.67,7.38],[2,1.62,54.54]],"ltp":2.0,"tv":221.54,"id":9634485}]}]}
{"op":"mcm","clk":"4232301969","pt":1631517472090,"mc":[{"id":"1.187557759","rc":[{"batb":[[0,1.51,21.72]],"ltp":1.89,"tv":386.13,"id":9712888}]}]}
{"op":"mcm","clk":"4232397822","pt":1631519148722,"mc":[{"id":"1.187557759","rc":[{"batb":[[1,1.41,31.11],[2,1.4,767.98]],"ltp":1.89,"tv":386.13,"id":9712888}]}]}
{"op":"mcm","clk":"4232420843","pt":1631519460885,"mc":[{"id":"1.187557759","rc":[{"batl":[[0,1.76,2.17],[1,2.1,4.46],[2,2.5,25]],"ltp":1.89,"tv":386.13,"id":9712888}]}]}
{"op":"mcm","clk":"4232421442","pt":1631519474609,"mc":[{"id":"1.187557759","rc":[{"batl":[[0,2.1,4.46],[1,2.5,25],[2,46,29.07]],"ltp":1.89,"tv":386.13,"id":9712888}]}]}
{"op":"mcm","clk":"4232421817","pt":1631519482424,"mc":[{"id":"1.187557759","rc":[{"batb":[[0,1.91,3.04],[1,1.9,28.16],[2,1.67,7.38]],"batl":[[1,2.7,4.26],[2,46,29.07]],"ltp":2.0,"tv":221.54,"id":9634485},{"batb":[[0,1.51,15.36]],"batl":[[0,1.76,7.24],[1,1.94,7.71],[2,2.1,4.46]],"ltp":1.89,"tv":386.13,"id":9712888}]}]}
{"op":"mcm","clk":"4232423099","pt":1631519509568,"mc":[{"id":"1.187557759","rc":[{"trd":[[2.3,5.55]],"batl":[[0,2.3,2.99],[1,2.34,2.66],[2,2.7,4.26]],"ltp":2.3,"tv":227.09,"id":9634485},{"trd":[[1.76,7.24]],"batl":[[0,1.94,7.71],[1,2.1,4.46],[2,2.5,25]],"ltp":1.76,"tv":393.37,"id":9712888}],"tv":620.46}]}
{"op":"mcm","clk":"4232423123","pt":1631519509980,"mc":[{"id":"1.187557759","rc":[{"batb":[[0,1.9,28.16],[1,1.67,7.38],[2,1.62,54.54]],"ltp":2.3,"tv":227.09,"id":9634485},{"batb":[[0,1.51,21.32]],"ltp":1.76,"tv":393.37,"id":9712888}]}]}
{"op":"mcm","clk":"4232423344","pt":1631519515465,"mc":[{"id":"1.187557759","rc":[{"trd":[[2.06,7.26]],"batl":[[0,2.06,78.07],[1,2.3,2.99],[2,2.34,2.66]],"ltp":2.06,"tv":234.35,"id":9634485},{"trd":[[1.94,7.71]],"batb":[[0,1.54,493.95],[1,1.51,15.36],[2,1.41,31.11]],"batl":[[0,2.1,4.46],[1,2.5,25],[2,46,29.07]],"ltp":1.94,"tv":401.08,"id":9712888}],"tv":635.43}]}
{"op":"mcm","clk":"4232423617","pt":1631519521590,"mc":[{"id":"1.187557759","rc":[{"trd":[[1.9,194.03]],"batb":[[0,1.9,26.39]],"ltp":1.9,"tv":236.11,"id":9634485},{"trd":[[2.1,328.35],[2.12,1.59]],"batl":[[0,2.34,26.77]],"ltp":2.12,"tv":411.59,"id":9712888}],"tv":647.71}]}
{"op":"mcm","clk":"4232423859","pt":1631519526776,"mc":[{"id":"1.187557759","rc":[{"trd":[[1.9,220.42]],"batb":[[0,1.67,7.38],[1,1.62,54.54],[2,1.36,49.28]],"ltp":1.9,"tv":262.51,"id":9634485},{"trd":[[2.12,25.24],[2.2,9.06]],"batb":[[0,1.63,268.69],[1,1.41,31.11],[2,1.4,767.98]],"batl":[[0,2.5,25],[1,46,29.07],[2,990,2.2]],"ltp":2.2,"tv":444.3,"id":9712888}],"tv":706.81}]}
{"op":"mcm","clk":"4232424054","pt":1631519531595,"mc":[{"id":"1.187557759","rc":[{"batl":[[0,2.06,83.61]],"ltp":1.9,"tv":262.51,"id":9634485},{"batb":[[0,2.04,32.51]],"ltp":2.2,"tv":444.3,"id":9712888}]}]}
{"op":"mcm","clk":"4232424134","pt":1631519533600,"mc":[{"id":"1.187557759","rc":[{"batl":[[0,2,72.43],[1,2.06,83.61],[2,2.3,2.99]],"ltp":1.9,"tv":262.51,"id":9634485}]}]}
{"op":"mcm","clk":"4232424919","pt":1631519552743,"mc":[{"id":"1.187557759","rc":[{"trd":[[1.7,7.24]],"batl":[[0,2.06,172.98],[1,2.3,2.99],[2,2.34,2.66]],"ltp":1.7,"tv":269.75,"id":9634485}],"tv":714.05}]}
{"op":"mcm","clk":"4232424938","pt":1631519553052,"mc":[{"id":"1.187557759","rc":[{"batl":[[0,2.06,83.61]],"ltp":1.7,"tv":269.75,"id":9634485}]}]}
{"op":"mcm","clk":"4232425298","pt":1631519561222,"mc":[{"id":"1.187557759","rc":[{"batl":[[0,2.48,72.43],[1,2.5,25],[2,46,29.07]],"ltp":2.2,"tv":444.3,"id":9712888}]}]}
{"op":"mcm","clk":"4232425531","pt":1631519565330,"mc":[{"id":"1.187557759","rc":[{"batb":[[0,1.71,3.8],[1,1.67,7.38],[2,1.62,54.54]],"ltp":1.7,"tv":269.75,"id":9634485},{"batl":[[0,2.2,12.63],[1,2.48,72.43],[2,2.5,25]],"ltp":2.2,"tv":444.3,"id":9712888}]}]}
{"op":"mcm","clk":"4232426033","pt":1631519576773,"mc":[{"id":"1.187557759","rc":[{"trd":[[2.04,6.02]],"batb":[[0,2.04,29.5]],"ltp":2.04,"tv":450.31,"id":9712888}],"tv":720.07}]}
{"op":"mcm","clk":"4232426201","pt":1631519581700,"mc":[{"id":"1.187557759","rc":[{"batb":[[0,2.04,32.51]],"ltp":2.04,"tv":450.31,"id":9712888}]}]}
{"op":"mcm","clk":"4232482470","pt":1631520387962,"mc":[{"id":"1.187557759","rc":[{"batb":[[2,1.62,50.52]],"ltp":1.7,"tv":269.75,"id":9634485},{"batb":[[0,2.04,30.12]],"ltp":2.04,"tv":450.31,"id":9712888}]}]}
{"op":"mcm","clk":"4232520712","pt":1631520965610,"mc":[{"id":"1.187557759","rc":[{"batb":[[1,1.41,23.89]],"ltp":2.04,"tv":450.31,"id":9712888}]}]}
{"op":"mcm","clk":"4232521101","pt":1631520971726,"mc":[{"id":"1.187557759","rc":[{"batb":[[0,1.67,7.38],[1,1.62,50.52],[2,1.36,49.28]],"ltp":1.7,"tv":269.75,"id":9634485}]}]}
{"op":"mcm","clk":"4232562676","pt":1631521566550,"mc":[{"id":"1.187557759","rc":[{"trd":[[2.2,30]],"batl":[[0,2.2,2.16]],"ltp":2.2,"tv":471.25,"id":9712888}],"tv":741.01}]}
{"op":"mcm","clk":"4232569590","pt":1631521679836,"mc":[{"id":"1.187557759","rc":[{"batl":[[1,2.5,25],[2,46,29.07]],"ltp":2.2,"tv":471.25,"id":9712888}]}]}
{"op":"mcm","clk":"4232571617","pt":1631521722870,"mc":[{"id":"1.187557759","rc":[{"batl":[[0,2.06,5.54],[1,2.34,2.66],[2,46,29.07]],"ltp":1.7,"tv":269.75,"id":9634485}]}]}
{"op":"mcm","clk":"4232580250","pt":1631521894699,"mc":[{"id":"1.187557759","rc":[{"batb":[[0,1.83,34.13],[1,1.67,7.38],[2,1.62,50.52]],"batl":[[0,2.34,2.66],[1,46,29.07],[2,990,2.2]],"ltp":1.7,"tv":269.75,"id":9634485}]}]}
{"op":"mcm","clk":"4232580270","pt":1631521895009,"mc":[{"id":"1.187557759","rc":[{"batl":[[0,2.2,215.1],[1,2.34,2.66],[2,46,29.07]],"ltp":1.7,"tv":269.75,"id":9634485}]}]}
{"op":"mcm","clk":"4232585423","pt":1631521988689,"mc":[{"id":"1.187557759","rc":[{"batl":[[0,2.34,75.21],[1,46,29.07],[2,990,2.2]],"ltp":1.7,"tv":269.75,"id":9634485},{"trd":[[2.04,66.26]],"batb":[[0,1.67,206.42]],"ltp":2.04,"tv":531.49,"id":9712888}],"tv":801.25}]}
{"op":"mcm","clk":"4232585474","pt":1631521989411,"mc":[{"id":"1.187557759","rc":[{"batl":[[0,2.34,2.66]],"ltp":1.7,"tv":269.75,"id":9634485},{"batb":[[0,1.46,508.28]],"ltp":2.04,"tv":531.49,"id":9712888}]}]}
{"op":"mcm","clk":"4232585545","pt":1631521990801,"mc":[{"id":"1.187557759","rc":[{"batl":[[0,2.32,116.18],[1,2.34,2.66],[2,46,29.07]],"ltp":1.7,"tv":269.75,"id":9634485},{"batb":[[0,1.94,33.32]],"ltp":2.04,"tv":531.49,"id":9712888}]}]}
{"op":"mcm","clk":"4232600345","pt":1631522290829,"mc":[{"id":"1.187557759","rc":[{"batl":[[0,2.34,2.66],[1,46,29.07],[2,990,2.2]],"ltp":1.7,"tv":269.75,"id":9634485}]}]}
{"op":"mcm","clk":"4232600361","pt":1631522291341,"mc":[{"id":"1.187557759","rc":[{"batl":[[0,2.26,119.21],[1,2.34,2.66],[2,46,29.07]],"ltp":1.7,"tv":269.75,"id":9634485}]}]}
{"op":"mcm","clk":"4232602040","pt":1631522326296,"mc":[{"id":"1.187557759","rc":[{"batb":[[0,2,26.62],[1,1.94,33.32],[2,1.41,23.89]],"ltp":2.04,"tv":531.49,"id":9712888}]}]}
{"op":"mcm","clk":"4232602067","pt":1631522326965,"mc":[{"id":"1.187557759","rc":[{"batl":[[0,2.22,296.27]],"ltp":1.7,"tv":269.75,"id":9634485}]}]}
{"op":"mcm","clk":"4232602619","pt":1631522338803,"mc":[{"id":"1.187557759","rc":[{"batb":[[0,2.04,26.62]],"ltp":2.04,"tv":531.49,"id":9712888}]}]}
{"op":"mcm","clk":"4232602639","pt":1631522339214,"mc":[{"id":"1.187557759","rc":[{"batl":[[0,2.2,121.45]],"ltp":1.7,"tv":269.75,"id":9634485}]}]}
{"op":"mcm","clk":"4232603101","pt":1631522348637,"mc":[{"id":"1.187557759","rc":[{"batl":[[0,2.2,184.93]],"ltp":1.7,"tv":269.75,"id":9634485},{"trd":[[2.06,39.74]],"batb":[[0,2.06,6.76]],"ltp":2.06,"tv":571.23,"id":9712888}],"tv":840.99}]}
{"op":"mcm","clk":"4232603135","pt":1631522349153,"mc":[{"id":"1.187557759","rc":[{"batl":[[0,2.2,74.09]],"ltp":1.7,"tv":269.75,"id":9634485}]}]}
{"op":"mcm","clk":"4232603746","pt":1631522360137,"mc":[{"id":"1.187557759","rc":[{"batb":[[0,2.08,6.76]],"ltp":2.06,"tv":571.23,"id":9712888}]}]}
{"op":"mcm","clk":"4232605178","pt":1631522386076,"mc":[{"id":"1.187557759","rc":[{"batb":[[1,1.67,54.13],[2,1.36,49.28]],"ltp":1.7,"tv":269.75,"id":9634485},{"batb":[[0,2.1,28.47],[1,2.08,6.76]],"ltp":2.06,"tv":571.23,"id":9712888}]}]}
{"op":"mcm","clk":"4232605513","pt":1631522392198,"mc":[{"id":"1.187557759","rc":[{"batb":[[0,2.1,35.23],[1,1.41,23.89],[2,1.4,767.98]],"ltp":2.06,"tv":571.23,"id":9712888}]}]}
{"op":"mcm","clk":"4232606479","pt":1631522408217,"mc":[{"id":"1.187557759","rc":[{"batb":[[0,2.12,6.76],[1,2.1,28.47],[2,1.41,23.89]],"ltp":2.06,"tv":571.23,"id":9712888}]}]}
{"op":"mcm","clk":"4232607005","pt":1631522416825,"mc":[{"id":"1.187557759","rc":[{"batb":[[0,2.14,6.76]],"ltp":2.06,"tv":571.23,"id":9712888}]}]}
{"op":"mcm","clk":"4232607576","pt":1631522426768,"mc":[{"id":"1.187557759","rc":[{"batl":[[0,2.5,25],[1,46,29.07],[2,990,2.2]],"ltp":2.06,"tv":571.23,"id":9712888}]}]}
{"op":"mcm","clk":"4232607584","pt":1631522426973,"mc":[{"id":"1.187557759","rc":[{"batl":[[0,2.46,5.26],[1,2.5,25],[2,46,29.07]],"ltp":2.06,"tv":571.23,"id":9712888}]}]}
{"op":"mcm","clk":"4232607731","pt":1631522429754,"mc":[{"id":"1.187557759","rc":[{"trd":[[1.88,2.49]],"ltp":1.88,"tv":272.24,"id":9634485},{"trd":[[2.14,2.19]],"batb":[[0,2.14,4.57]],"ltp":2.14,"tv":573.42,"id":9712888}],"tv":845.67}]}
{"op":"mcm","clk":"4232616631","pt":1631522591193,"mc":[{"id":"1.187557759","rc":[{"batl":[[0,2.08,39.83]],"ltp":1.88,"tv":272.24,"id":9634485}]}]}
{"op":"mcm","clk":"4232625995","pt":1631522754782,"mc":[{"id":"1.187557759","rc":[{"batb":[[2,1.42,97.78]],"batl":[[2,2.8,44.04]],"ltp":1.88,"tv":272.24,"id":9634485}]}]}
{"op":"mcm","clk":"4232626476","pt":1631522763787,"mc":[{"id":"1.187557759","rc":[{"batb":[[2,1.36,49.28]],"batl":[[2,46,29.07]],"ltp":1.88,"tv":272.24,"id":9634485}]}]}
{"op":"mcm","clk":"4232642621","pt":1631523092829,"mc":[{"id":"1.187557759","rc":[{"batb":[[2,1.42,46.62]],"ltp":1.88,"tv":272.24,"id":9634485},{"batb":[[2,1.57,34.35]],"ltp":2.14,"tv":573.42,"id":9712888}]}]}
{"op":"mcm","clk":"4232642631","pt":1631523093036,"mc":[{"id":"1.187557759","rc":[{"batl":[[0,2.06,6.83],[1,2.08,39.83],[2,2.34,2.66]],"ltp":1.88,"tv":272.24,"id":9634485},{"batl":[[2,2.54,4.7]],"ltp":2.14,"tv":573.42,"id":9712888}]}]}
{"op":"mcm","clk":"4232647257","pt":1631523191199,"mc":[{"id":"1.187557759","rc":[{"batl":[[0,2.04,40.61],[1,2.06,6.83]],"ltp":1.88,"tv":272.24,"id":9634485}]}]}
{"op":"mcm","clk":"4232657332","pt":1631523418405,"mc":[{"id":"1.187557759","marketDefinition":{"bspMarket":false,"turnInPlayEnabled":true,"persistenceEnabled":true,"marketBaseRate":5.0,"eventId":"30896122","eventTypeId":"2","numberOfWinners":1,"bettingType":"ODDS","marketType":"MATCH_ODDS","marketTime":"2021-09-13T10:54:00.000Z","suspendTime":"2021-09-13T10:54:00.000Z","bspReconciled":false,"complete":true,"inPlay":false,"crossMatching":true,"runnersVoidable":false,"numberOfActiveRunners":2,"betDelay":0,"status":"OPEN","runners":[{"status":"ACTIVE","sortPriority":1,"id":9634485,"name":"Nicola Kuhn"},{"status":"ACTIVE","sortPriority":2,"id":9712888,"name":"Matteo Martineau"}],"regulators":["MR_INT"],"countryCode":"PL","discountAllowed":true,"timezone":"UTC","openDate":"2021-09-13T11:00:00.000Z","version":4030477202,"name":"Match Odds","eventName":"Kuhn v Martineau"}}]}
{"op":"mcm","clk":"4232657579","pt":1631523421630,"mc":[{"id":"1.187557759","marketDefinition":{"bspMarket":false,"turnInPlayEnabled":true,"persistenceEnabled":true,"marketBaseRate":5.0,"eventId":"30896122","eventTypeId":"2","numberOfWinners":1,"bettingType":"ODDS","marketType":"MATCH_ODDS","marketTime":"2021-09-13T10:54:00.000Z","suspendTime":"2021-09-13T10:54:00.000Z","bspReconciled":false,"complete":true,"inPlay":false,"crossMatching":true,"runnersVoidable":false,"numberOfActiveRunners":2,"betDelay":0,"status":"OPEN","runners":[{"status":"ACTIVE","sortPriority":1,"id":9634485,"name":"Nicola Kuhn"},{"status":"ACTIVE","sortPriority":2,"id":9712888,"name":"Matteo Martineau"}],"regulators":["MR_INT"],"countryCode":"PL","discountAllowed":true,"timezone":"UTC","openDate":"2021-09-13T10:54:00.000Z","version":4030477202,"name":"Match Odds","eventName":"Kuhn v Martineau"},"rc":[{"batl":[[0,2.06,6.83],[1,2.34,2.66],[2,46,29.07]],"ltp":1.88,"tv":272.24,"id":9634485},{"batl":[[0,2.5,25],[1,2.54,4.7],[2,46,29.07]],"ltp":2.14,"tv":573.42,"id":9712888}]}]}
{"op":"mcm","clk":"4232657954","pt":1631523431657,"mc":[{"id":"1.187557759","rc":[{"batl":[[0,2.04,39.02],[1,2.06,6.83],[2,2.34,2.66]],"ltp":1.88,"tv":272.24,"id":9634485},{"batl":[[0,2.42,5.35],[1,2.5,25],[2,2.54,4.7]],"ltp":2.14,"tv":573.42,"id":9712888}]}]}
{"op":"mcm","clk":"4232661700","pt":1631523542446,"mc":[{"id":"1.187557759","rc":[{"batb":[[1,1.67,69.71]],"ltp":1.88,"tv":272.24,"id":9634485},{"batb":[[1,2.1,37.97]],"ltp":2.14,"tv":573.42,"id":9712888}]}]}
{"op":"mcm","clk":"4232665527","pt":1631523635346,"mc":[{"id":"1.187557759","rc":[{"trd":[[1.67,18.96],[1.68,4.31],[1.7,7.24],[1.9,220.56],[2.06,7.26]],"batb":[[0,1.83,34.14],[1,1.67,69.71],[2,1.42,46.59]],"batl":[[1,2.06,6.83],[2,2.34,2.66]],"ltp":1.88,"tv":272.37,"id":9634485},{"trd":[[1.76,7.24],[1.89,8.8],[1.94,7.7],[1.97,46.5],[2,8.47],[2.04,66.25],[2.06,39.76],[2.1,328.55],[2.12,25.24],[2.14,2.19],[2.2,30]],"batb":[[0,2.14,4.57],[2,1.57,34.33]],"batl":[[2,2.54,4.7]],"ltp":2.14,"tv":573.62,"id":9712888}],"tv":846.0}]}
{"op":"mcm","clk":"4232681867","pt":1631523955523,"mc":[{"id":"1.187557759","rc":[{"batl":[[0,2.04,39.87]],"ltp":1.88,"tv":272.37,"id":9634485}]}]}
{"op":"mcm","clk":"4232705836","pt":1631524369849,"mc":[{"id":"1.187557759","rc":[{"batb":[[2,1.42,144.31]],"ltp":1.88,"tv":272.37,"id":9634485}]}]}
{"op":"mcm","clk":"4232710424","pt":1631524450171,"mc":[{"id":"1.187557759","rc":[{"batb":[[2,1.42,97.72]],"batl":[[1,2.34,2.66],[2,2.8,44.02]],"ltp":1.88,"tv":272.37,"id":9634485},{"batb":[[2,1.41,23.9]],"batl":[[2,46,29.05]],"ltp":2.14,"tv":573.62,"id":9712888}]}]}
{"op":"mcm","clk":"4232715810","pt":1631524549654,"mc":[{"id":"1.187557759","rc":[{"batl":[[0,1.87,10.85]],"ltp":1.88,"tv":272.37,"id":9634485}]}]}
{"op":"mcm","clk":"4232721710","pt":1631524656152,"mc":[{"id":"1.187557759","rc":[{"batl":[[0,1.87,14.3]],"ltp":1.88,"tv":272.37,"id":9634485}]}]}
{"op":"mcm","clk":"4232805236","pt":1631526065733,"mc":[{"id":"1.187557759","rc":[{"batb":[[0,1.7,34.14]],"ltp":1.88,"tv":272.37,"id":9634485},{"batl":[[0,2.5,25],[1,46,29.05],[2,990,2.2]],"ltp":2.14,"tv":573.62,"id":9712888}]}]}
{"op":"mcm","clk":"4232806084","pt":1631526082658,"mc":[{"id":"1.187557759","rc":[{"batb":[[0,1.7,82.79]],"ltp":1.88,"tv":272.37,"id":9634485}]}]}
{"op":"mcm","clk":"4232815816","pt":1631526195412,"mc":[{"id":"1.187557759","rc":[{"trd":[[1.87,10]],"batl":[[0,1.87,9.29]],"ltp":1.87,"tv":282.37,"id":9634485}],"tv":856.0}]}
{"op":"mcm","clk":"4232855579","pt":1631526840679,"mc":[{"id":"1.187557759","rc":[{"batb":[[0,1.71,18.03],[1,1.7,82.79],[2,1.67,69.71]],"ltp":1.87,"tv":282.37,"id":9634485},{"batb":[[0,2.16,11.04],[1,2.14,4.57],[2,2.1,37.97]],"ltp":2.14,"tv":573.62,"id":9712888}]}]}
{"op":"mcm","clk":"4232861258","pt":1631526950614,"mc":[{"id":"1.187557759","rc":[{"batb":[[0,1.71,100.82],[1,1.67,69.71],[2,1.42,97.72]],"ltp":1.87,"tv":282.37,"id":9634485}]}]}
{"op":"mcm","clk":"4232866713","pt":1631527048602,"mc":[{"id":"1.187557759","rc":[{"trd":[[1.71,5.79]],"batb":[[0,1.71,97.93]],"ltp":1.71,"tv":288.16,"id":9634485}],"tv":861.79}]}
{"op":"mcm","clk":"4232869219","pt":1631527091979,"mc":[{"id":"1.187557759","rc":[{"batb":[[0,2.18,2.66],[1,2.16,11.04],[2,2.14,4.57]],"ltp":2.14,"tv":573.62,"id":9712888}]}]}
{"op":"mcm","clk":"4232917988","pt":1631528010174,"mc":[{"id":"1.187557759","rc":[{"trd":[[1.71,57]],"batb":[[0,1.71,72.32]],"ltp":1.71,"tv":339.37,"id":9634485}],"tv":912.99}]}
{"op":"mcm","clk":"4232918069","pt":1631528010955,"mc":[{"id":"1.187557759","rc":[{"batb":[[0,1.72,17.78],[1,1.71,72.32],[2,1.67,69.71]],"ltp":1.71,"tv":339.37,"id":9634485}]}]}
{"op":"mcm","clk":"4232935515","pt":1631528153733,"mc":[{"id":"1.187557759","rc":[{"batb":[[0,1.72,90.1],[1,1.67,69.71],[2,1.42,97.72]],"ltp":1.71,"tv":339.37,"id":9634485}]}]}
{"op":"mcm","clk":"4232958916","pt":1631528549473,"mc":[{"id":"1.187557759","rc":[{"batb":[[1,1.68,2.66],[2,1.67,69.71]],"ltp":1.71,"tv":339.37,"id":9634485}]}]}
{"op":"mcm","clk":"4233018515","pt":1631529441949,"mc":[{"id":"1.187557759","rc":[{"batl":[[1,1.9,2],[2,2.34,2.66]],"ltp":1.71,"tv":339.37,"id":9634485}]}]}
{"op":"mcm","clk":"4233030517","pt":1631529656795,"mc":[{"id":"1.187557759","rc":[{"batl":[[0,1.86,11.48],[1,1.87,9.29],[2,1.9,2]],"ltp":1.71,"tv":339.37,"id":9634485}]}]}
{"op":"mcm","clk":"4233030524","pt":1631529657002,"mc":[{"id":"1.187557759","rc":[{"batb":[[2,1.67,81.19]],"ltp":1.71,"tv":339.37,"id":9634485}]}]}
{"op":"mcm","clk":"4233081371","pt":1631530317013,"mc":[{"id":"1.187557759","rc":[{"batl":[[1,1.87,5.85]],"ltp":1.71,"tv":339.37,"id":9634485}]}]}
{"op":"mcm","clk":"4233081991","pt":1631530324810,"mc":[{"id":"1.187557759","rc":[{"batl":[[0,1.74,3.44],[1,1.86,11.48],[2,1.87,5.85]],"ltp":1.71,"tv":339.37,"id":9634485}]}]}
{"op":"mcm","clk":"4233082001","pt":1631530324915,"mc":[{"id":"1.187557759","rc":[{"trd":[[1.74,6.88]],"batl":[[0,1.86,11.48],[1,1.87,5.85],[2,1.9,2]],"ltp":1.74,"tv":346.25,"id":9634485}],"tv":919.88}]}
{"op":"mcm","clk":"4233102849","pt":1631530618421,"mc":[{"id":"1.187557759","marketDefinition":{"bspMarket":false,"turnInPlayEnabled":true,"persistenceEnabled":true,"marketBaseRate":5.0,"eventId":"30896122","eventTypeId":"2","numberOfWinners":1,"bettingType":"ODDS","marketType":"MATCH_ODDS","marketTime":"2021-09-13T11:09:00.000Z","suspendTime":"2021-09-13T11:09:00.000Z","bspReconciled":false,"complete":true,"inPlay":false,"crossMatching":true,"runnersVoidable":false,"numberOfActiveRunners":2,"betDelay":0,"status":"OPEN","runners":[{"status":"ACTIVE","sortPriority":1,"id":9634485,"name":"Nicola Kuhn"},{"status":"ACTIVE","sortPriority":2,"id":9712888,"name":"Matteo Martineau"}],"regulators":["MR_INT"],"countryCode":"PL","discountAllowed":true,"timezone":"UTC","openDate":"2021-09-13T10:54:00.000Z","version":4030566723,"name":"Match Odds","eventName":"Kuhn v Martineau"}}]}
{"op":"mcm","clk":"4233106033","pt":1631530662649,"mc":[{"id":"1.187557759","marketDefinition":{"bspMarket":false,"turnInPlayEnabled":true,"persistenceEnabled":true,"marketBaseRate":5.0,"eventId":"30896122","eventTypeId":"2","numberOfWinners":1,"bettingType":"ODDS","marketType":"MATCH_ODDS","marketTime":"2021-09-13T11:09:00.000Z","suspendTime":"2021-09-13T11:09:00.000Z","bspReconciled":false,"complete":true,"inPlay":false,"crossMatching":true,"runnersVoidable":false,"numberOfActiveRunners":2,"betDelay":0,"status":"OPEN","runners":[{"status":"ACTIVE","sortPriority":1,"id":9634485,"name":"Nicola Kuhn"},{"status":"ACTIVE","sortPriority":2,"id":9712888,"name":"Matteo Martineau"}],"regulators":["MR_INT"],"countryCode":"PL","discountAllowed":true,"timezone":"UTC","openDate":"2021-09-13T11:09:00.000Z","version":4030566723,"name":"Match Odds","eventName":"Kuhn v Martineau"}}]}
{"op":"mcm","clk":"4233112164","pt":1631530754292,"mc":[{"id":"1.187557759","rc":[{"trd":[[1.72,27.31]],"batb":[[0,1.72,76.44]],"ltp":1.72,"tv":373.56,"id":9634485}],"tv":947.19}]}
{"op":"mcm","clk":"4233114625","pt":1631530793609,"mc":[{"id":"1.187557759","rc":[{"trd":[[1.72,28.71]],"batb":[[0,1.72,75.74]],"ltp":1.72,"tv":374.96,"id":9634485}],"tv":948.59}]}
{"op":"mcm","clk":"4233124203","pt":1631530918289,"mc":[{"id":"1.187557759","rc":[{"trd":[[1.67,18.95],[1.68,4.3],[1.7,7.24],[1.71,56.89],[1.72,28.65],[1.74,6.88],[1.87,10],[1.88,2.49],[1.9,220.13],[2.06,7.25],[2.3,5.54]],"batb":[[0,1.72,75.6],[1,1.7,70.7],[2,1.68,2.66]],"batl":[[0,1.86,11.45]],"ltp":1.72,"tv":374.31,"id":9634485},{"trd":[[1.76,7.23],[1.89,8.8],[1.94,7.7],[1.97,46.45],[2,8.46],[2.04,66.25],[2.06,39.71],[2.1,328.32],[2.12,25.23],[2.14,2.18],[2.2,29.98],[2.46,2.93]],"batb":[[0,2.18,2.66],[1,2.16,11.01],[2,2.14,4.56]],"batl":[[1,46,29.02]],"ltp":2.14,"tv":573.24,"id":9712888}],"tv":947.56}]}
{"op":"mcm","clk":"4233150913","pt":1631531219826,"mc":[{"id":"1.187557759","rc":[{"trd":[[1.85,0.15]],"ltp":1.85,"tv":374.46,"id":9634485},{"trd":[[2.18,0.13]],"batb":[[0,2.18,2.53]],"ltp":2.18,"tv":573.37,"id":9712888}],"tv":947.84}]}
{"op":"mcm","clk":"4233174824","pt":1631531516249,"mc":[{"id":"1.187557759","marketDefinition":{"bspMarket":false,"turnInPlayEnabled":true,"persistenceEnabled":true,"marketBaseRate":5.0,"eventId":"30896122","eventTypeId":"2","numberOfWinners":1,"bettingType":"ODDS","marketType":"MATCH_ODDS","marketTime":"2021-09-13T11:24:00.000Z","suspendTime":"2021-09-13T11:24:00.000Z","bspReconciled":false,"complete":true,"inPlay":false,"crossMatching":true,"runnersVoidable":false,"numberOfActiveRunners":2,"betDelay":0,"status":"OPEN","runners":[{"status":"ACTIVE","sortPriority":1,"id":9634485,"name":"Nicola Kuhn"},{"status":"ACTIVE","sortPriority":2,"id":9712888,"name":"Matteo Martineau"}],"regulators":["MR_INT"],"countryCode":"PL","discountAllowed":true,"timezone":"UTC","openDate":"2021-09-13T11:09:00.000Z","version":4030580104,"name":"Match Odds","eventName":"Kuhn v Martineau"}}]}
{"op":"mcm","clk":"4233175038","pt":1631531519289,"mc":[{"id":"1.187557759","marketDefinition":{"bspMarket":false,"turnInPlayEnabled":true,"persistenceEnabled":true,"marketBaseRate":5.0,"eventId":"30896122","eventTypeId":"2","numberOfWinners":1,"bettingType":"ODDS","marketType":"MATCH_ODDS","marketTime":"2021-09-13T11:24:00.000Z","suspendTime":"2021-09-13T11:24:00.000Z","bspReconciled":false,"complete":true,"inPlay":false,"crossMatching":true,"runnersVoidable":false,"numberOfActiveRunners":2,"betDelay":0,"status":"OPEN","runners":[{"status":"ACTIVE","sortPriority":1,"id":9634485,"name":"Nicola Kuhn"},{"status":"ACTIVE","sortPriority":2,"id":9712888,"name":"Matteo Martineau"}],"regulators":["MR_INT"],"countryCode":"PL","discountAllowed":true,"timezone":"UTC","openDate":"2021-09-13T11:24:00.000Z","version":4030580104,"name":"Match Odds","eventName":"Kuhn v Martineau"}}]}
{"op":"mcm","clk":"4233232069","pt":1631532290461,"mc":[{"id":"1.187557759","rc":[{"trd":[[1.7,148.48],[1.72,261.25]],"batb":[[0,1.68,2.73],[1,1.67,81.16],[2,1.63,238.1]],"batl":[[0,1.72,415.28],[1,1.86,11.45],[2,1.87,5.85]],"ltp":1.7,"tv":748.3,"id":9634485},{"batb":[[0,2.2,1157.74],[1,2.18,2.53],[2,2.16,11.01]],"ltp":2.18,"tv":573.37,"id":9712888}],"tv":1321.68}]}
{"op":"mcm","clk":"4233232098","pt":1631532291066,"mc":[{"id":"1.187557759","rc":[{"batl":[[0,1.72,417.28]],"ltp":1.7,"tv":748.3,"id":9634485},{"batb":[[0,2.34,9.53]],"batl":[[0,2.5,27]],"ltp":2.18,"tv":573.37,"id":9712888}]}]}
{"op":"mcm","clk":"4233239218","pt":1631532403609,"mc":[{"id":"1.187557759","rc":[{"batb":[[0,1.68,87.91]],"ltp":1.7,"tv":748.3,"id":9634485}]}]}
{"op":"mcm","clk":"4233239255","pt":1631532404023,"mc":[{"id":"1.187557759","rc":[{"batb":[[0,2.32,9.68]],"ltp":2.18,"tv":573.37,"id":9712888}]}]}
{"op":"mcm","clk":"4233240071","pt":1631532416302,"mc":[{"id":"1.187557759","marketDefinition":{"bspMarket":false,"turnInPlayEnabled":true,"persistenceEnabled":true,"marketBaseRate":5.0,"eventId":"30896122","eventTypeId":"2","numberOfWinners":1,"bettingType":"ODDS","marketType":"MATCH_ODDS","marketTime":"2021-09-13T11:39:00.000Z","suspendTime":"2021-09-13T11:39:00.000Z","bspReconciled":false,"complete":true,"inPlay":false,"crossMatching":true,"runnersVoidable":false,"numberOfActiveRunners":2,"betDelay":0,"status":"OPEN","runners":[{"status":"ACTIVE","sortPriority":1,"id":9634485,"name":"Nicola Kuhn"},{"status":"ACTIVE","sortPriority":2,"id":9712888,"name":"Matteo Martineau"}],"regulators":["MR_INT"],"countryCode":"PL","discountAllowed":true,"timezone":"UTC","openDate":"2021-09-13T11:24:00.000Z","version":4030588878,"name":"Match Odds","eventName":"Kuhn v Martineau"}}]}
{"op":"mcm","clk":"4233240292","pt":1631532419326,"mc":[{"id":"1.187557759","marketDefinition":{"bspMarket":false,"turnInPlayEnabled":true,"persistenceEnabled":true,"marketBaseRate":5.0,"eventId":"30896122","eventTypeId":"2","numberOfWinners":1,"bettingType":"ODDS","marketType":"MATCH_ODDS","marketTime":"2021-09-13T11:39:00.000Z","suspendTime":"2021-09-13T11:39:00.000Z","bspReconciled":false,"complete":true,"inPlay":false,"crossMatching":true,"runnersVoidable":false,"numberOfActiveRunners":2,"betDelay":0,"status":"OPEN","runners":[{"status":"ACTIVE","sortPriority":1,"id":9634485,"name":"Nicola Kuhn"},{"status":"ACTIVE","sortPriority":2,"id":9712888,"name":"Matteo Martineau"}],"regulators":["MR_INT"],"countryCode":"PL","discountAllowed":true,"timezone":"UTC","openDate":"2021-09-13T11:39:00.000Z","version":4030588878,"name":"Match Odds","eventName":"Kuhn v Martineau"}}]}
{"op":"mcm","clk":"4233242082","pt":1631532445646,"mc":[{"id":"1.187557759","rc":[{"batl":[[0,1.72,2]],"ltp":1.7,"tv":748.3,"id":9634485}]}]}
{"op":"mcm","clk":"4233242125","pt":1631532446074,"mc":[{"id":"1.187557759","rc":[{"batb":[[0,2.18,2.53],[1,2.16,11.01],[2,2.14,4.56]],"ltp":2.18,"tv":573.37,"id":9712888}]}]}
{"op":"mcm","clk":"4233244584","pt":1631532481205,"mc":[{"id":"1.187557759","rc":[{"trd":[[1.68,92.14],[1.7,148.56]],"batb":[[0,1.67,81.16],[1,1.63,238.1],[2,1.43,99.05]],"ltp":1.68,"tv":836.21,"id":9634485},{"trd":[[2.44,0.05],[2.48,73.21]],"batb":[[0,2.48,266.9],[1,2.18,2.53],[2,2.16,11.01]],"ltp":2.48,"tv":646.63,"id":9712888}],"tv":1482.85}]}
{"op":"mcm","clk":"4233244648","pt":1631532482039,"mc":[{"id":"1.187557759","rc":[{"batb":[[1,2.4,9.12],[2,2.18,2.53]],"ltp":2.48,"tv":646.63,"id":9712888}]}]}
{"op":"mcm","clk":"4233244839","pt":1631532484428,"mc":[{"id":"1.187557759","rc":[{"batb":[[0,1.67,18.83]],"ltp":1.68,"tv":836.21,"id":9634485}]}]}
{"op":"mcm","clk":"4233255409","pt":1631532625418,"mc":[{"id":"1.187557759","rc":[{"trd":[[2.48,78.02]],"batb":[[0,2.48,264.5]],"ltp":2.48,"tv":651.45,"id":9712888}],"tv":1487.67}]}
{"op":"mcm","clk":"4233255756","pt":1631532629712,"mc":[{"id":"1.187557759","rc":[{"trd":[[1.68,95.65]],"ltp":1.68,"tv":839.72,"id":9634485},{"trd":[[2.48,80.4]],"batb":[[0,2.48,262.12]],"ltp":2.48,"tv":653.83,"id":9712888}],"tv":1493.55}]}
{"op":"mcm","clk":"4233257638","pt":1631532654040,"mc":[{"id":"1.187557759","rc":[{"trd":[[1.68,99.16]],"ltp":1.68,"tv":843.23,"id":9634485},{"trd":[[2.48,82.78]],"batb":[[0,2.48,259.74]],"ltp":2.48,"tv":656.2,"id":9712888}],"tv":1499.44}]}
{"op":"mcm","clk":"4233263713","pt":1631532729890,"mc":[{"id":"1.187557759","rc":[{"batb":[[1,1.66,283.65],[2,1.63,238.1]],"ltp":1.68,"tv":843.23,"id":9634485}]}]}
{"op":"mcm","clk":"4233267830","pt":1631532776760,"mc":[{"id":"1.187557759","rc":[{"trd":[[1.68,102.68]],"ltp":1.68,"tv":846.75,"id":9634485},{"trd":[[2.48,85.16]],"batb":[[0,2.48,257.36]],"ltp":2.48,"tv":658.59,"id":9712888}],"tv":1505.35}]}
{"op":"mcm","clk":"4233268455","pt":1631532784187,"mc":[{"id":"1.187557759","rc":[{"trd":[[1.68,138.46]],"ltp":1.68,"tv":882.53,"id":9634485},{"trd":[[2.48,109.4]],"batb":[[0,2.48,233.12]],"ltp":2.48,"tv":682.82,"id":9712888}],"tv":1565.36}]}
{"op":"mcm","clk":"4233269037","pt":1631532791104,"mc":[{"id":"1.187557759","rc":[{"trd":[[1.68,422.1]],"batb":[[1,1.63,238.1],[2,1.43,99.05]],"ltp":1.68,"tv":1166.17,"id":9634485},{"trd":[[2.48,301.55]],"batb":[[0,2.48,40.97]],"ltp":2.48,"tv":874.97,"id":9712888}],"tv":2041.15}]}
{"op":"mcm","clk":"4233270122","pt":1631532803105,"mc":[{"id":"1.187557759","rc":[{"trd":[[1.68,482.59]],"batb":[[0,1.68,67.28],[1,1.67,18.83],[2,1.63,238.1]],"ltp":1.68,"tv":1226.66,"id":9634485},{"trd":[[2.48,342.52]],"batb":[[0,2.4,9.12],[1,2.18,2.53],[2,2.16,11.01]],"ltp":2.48,"tv":915.95,"id":9712888}],"tv":2142.61}]}
{"op":"mcm","clk":"4233270270","pt":1631532804810,"mc":[{"id":"1.187557759","rc":[{"batb":[[1,1.67,81.16]],"ltp":1.68,"tv":1226.66,"id":9634485},{"batb":[[0,2.18,2.53],[1,2.16,11.01],[2,2.14,4.56]],"ltp":2.48,"tv":915.95,"id":9712888}]}]}
{"op":"mcm","clk":"4233270276","pt":1631532804915,"mc":[{"id":"1.187557759","rc":[{"batb":[[0,2.18,348.97]],"ltp":2.48,"tv":915.95,"id":9712888}]}]}
{"op":"mcm","clk":"4233271674","pt":1631532820328,"mc":[{"id":"1.187557759","rc":[{"batb":[[1,1.67,18.83]],"ltp":1.68,"tv":1226.66,"id":9634485},{"batb":[[0,2.22,10.48],[1,2.2,34.8],[2,2.18,348.97]],"ltp":2.48,"tv":915.95,"id":9712888}]}]}
{"op":"mcm","clk":"4233271951","pt":1631532823228,"mc":[{"id":"1.187557759","rc":[{"batb":[[2,1.66,255.54]],"ltp":1.68,"tv":1226.66,"id":9634485}]}]}
{"op":"mcm","clk":"4233280020","pt":1631532914754,"mc":[{"id":"1.187557759","rc":[{"batb":[[0,2.2,34.8],[1,2.18,2.53],[2,2.14,4.56]],"ltp":2.48,"tv":915.95,"id":9712888}]}]}
{"op":"mcm","clk":"4233280091","pt":1631532915378,"mc":[{"id":"1.187557759","rc":[{"batb":[[0,2.22,10.48],[1,2.2,34.8],[2,2.18,2.53]],"ltp":2.48,"tv":915.95,"id":9712888}]}]}
{"op":"mcm","clk":"4233286620","pt":1631532985591,"mc":[{"id":"1.187557759","rc":[{"batb":[[0,1.69,67.28],[1,1.67,20.94],[2,1.66,257.65]],"ltp":1.68,"tv":1226.66,"id":9634485}]}]}
{"op":"mcm","clk":"4233295123","pt":1631533080288,"mc":[{"id":"1.187557759","rc":[{"batb":[[1,1.67,18.83],[2,1.66,255.54]],"ltp":1.68,"tv":1226.66,"id":9634485}]}]}
{"op":"mcm","clk":"4233312316","pt":1631533317146,"mc":[{"id":"1.187557759","marketDefinition":{"bspMarket":false,"turnInPlayEnabled":true,"persistenceEnabled":true,"marketBaseRate":5.0,"eventId":"30896122","eventTypeId":"2","numberOfWinners":1,"bettingType":"ODDS","marketType":"MATCH_ODDS","marketTime":"2021-09-13T11:54:00.000Z","suspendTime":"2021-09-13T11:54:00.000Z","bspReconciled":false,"complete":true,"inPlay":false,"crossMatching":true,"runnersVoidable":false,"numberOfActiveRunners":2,"betDelay":0,"status":"OPEN","runners":[{"status":"ACTIVE","sortPriority":1,"id":9634485,"name":"Nicola Kuhn"},{"status":"ACTIVE","sortPriority":2,"id":9712888,"name":"Matteo Martineau"}],"regulators":["MR_INT"],"countryCode":"PL","discountAllowed":true,"timezone":"UTC","openDate":"2021-09-13T11:39:00.000Z","version":4030603735,"name":"Match Odds","eventName":"Kuhn v Martineau"}}]}
{"op":"mcm","clk":"4233312519","pt":1631533320164,"mc":[{"id":"1.187557759","marketDefinition":{"bspMarket":false,"turnInPlayEnabled":true,"persistenceEnabled":true,"marketBaseRate":5.0,"eventId":"30896122","eventTypeId":"2","numberOfWinners":1,"bettingType":"ODDS","marketType":"MATCH_ODDS","marketTime":"2021-09-13T11:54:00.000Z","suspendTime":"2021-09-13T11:54:00.000Z","bspReconciled":false,"complete":true,"inPlay":false,"crossMatching":true,"runnersVoidable":false,"numberOfActiveRunners":2,"betDelay":0,"status":"OPEN","runners":[{"status":"ACTIVE","sortPriority":1,"id":9634485,"name":"Nicola Kuhn"},{"status":"ACTIVE","sortPriority":2,"id":9712888,"name":"Matteo Martineau"}],"regulators":["MR_INT"],"countryCode":"PL","discountAllowed":true,"timezone":"UTC","openDate":"2021-09-13T11:54:00.000Z","version":4030603735,"name":"Match Odds","eventName":"Kuhn v Martineau"}}]}
{"op":"mcm","clk":"4233367779","pt":1631534044829,"mc":[{"id":"1.187557759","rc":[{"batl":[[0,2.46,10.63],[1,2.5,27],[2,46,29.02]],"ltp":2.48,"tv":915.95,"id":9712888}]}]}
{"op":"mcm","clk":"4233379170","pt":1631534217944,"mc":[{"id":"1.187557759","marketDefinition":{"bspMarket":false,"turnInPlayEnabled":true,"persistenceEnabled":true,"marketBaseRate":5.0,"eventId":"30896122","eventTypeId":"2","numberOfWinners":1,"bettingType":"ODDS","marketType":"MATCH_ODDS","marketTime":"2021-09-13T12:09:00.000Z","suspendTime":"2021-09-13T12:09:00.000Z","bspReconciled":false,"complete":true,"inPlay":false,"crossMatching":true,"runnersVoidable":false,"numberOfActiveRunners":2,"betDelay":0,"status":"OPEN","runners":[{"status":"ACTIVE","sortPriority":1,"id":9634485,"name":"Nicola Kuhn"},{"status":"ACTIVE","sortPriority":2,"id":9712888,"name":"Matteo Martineau"}],"regulators":["MR_INT"],"countryCode":"PL","discountAllowed":true,"timezone":"UTC","openDate":"2021-09-13T11:54:00.000Z","version":4030614197,"name":"Match Odds","eventName":"Kuhn v Martineau"}}]}
{"op":"mcm","clk":"4233381799","pt":1631534256138,"mc":[{"id":"1.187557759","marketDefinition":{"bspMarket":false,"turnInPlayEnabled":true,"persistenceEnabled":true,"marketBaseRate":5.0,"eventId":"30896122","eventTypeId":"2","numberOfWinners":1,"bettingType":"ODDS","marketType":"MATCH_ODDS","marketTime":"2021-09-13T12:09:00.000Z","suspendTime":"2021-09-13T12:09:00.000Z","bspReconciled":false,"complete":true,"inPlay":false,"crossMatching":true,"runnersVoidable":false,"numberOfActiveRunners":2,"betDelay":0,"status":"OPEN","runners":[{"status":"ACTIVE","sortPriority":1,"id":9634485,"name":"Nicola Kuhn"},{"status":"ACTIVE","sortPriority":2,"id":9712888,"name":"Matteo Martineau"}],"regulators":["MR_INT"],"countryCode":"PL","discountAllowed":true,"timezone":"UTC","openDate":"2021-09-13T12:09:00.000Z","version":4030614197,"name":"Match Odds","eventName":"Kuhn v Martineau"}}]}
{"op":"mcm","clk":"4233397063","pt":1631534464294,"mc":[{"id":"1.187557759","rc":[{"trd":[[1.69,2.7]],"batb":[[0,1.69,65.93]],"ltp":1.69,"tv":1229.36,"id":9634485}],"tv":2145.31}]}
{"op":"mcm","clk":"4233410012","pt":1631534606994,"mc":[{"id":"1.187557759","rc":[{"trd":[[1.69,44.19]],"batb":[[0,1.69,45.18]],"ltp":1.69,"tv":1270.84,"id":9634485}],"tv":2186.79}]}
{"op":"mcm","clk":"4233420698","pt":1631534709511,"mc":[{"id":"1.187557759","rc":[{"trd":[[2.46,3.07]],"batl":[[0,2.46,10.56]],"ltp":2.46,"tv":916.08,"id":9712888}],"tv":2186.93}]}
{"op":"mcm","clk":"4233431763","pt":1631534813128,"mc":[{"id":"1.187557759","rc":[{"batl":[[2,1.89,338.16]],"ltp":1.69,"tv":1270.84,"id":9634485}]}]}
{"op":"mcm","clk":"4233432130","pt":1631534817058,"mc":[{"id":"1.187557759","marketDefinition":{"bspMarket":false,"turnInPlayEnabled":true,"persistenceEnabled":true,"marketBaseRate":5.0,"eventId":"30896122","eventTypeId":"2","numberOfWinners":1,"bettingType":"ODDS","marketType":"MATCH_ODDS","marketTime":"2021-09-13T12:06:00.000Z","suspendTime":"2021-09-13T12:06:00.000Z","bspReconciled":false,"complete":true,"inPlay":false,"crossMatching":true,"runnersVoidable":false,"numberOfActiveRunners":2,"betDelay":0,"status":"OPEN","runners":[{"status":"ACTIVE","sortPriority":1,"id":9634485,"name":"Nicola Kuhn"},{"status":"ACTIVE","sortPriority":2,"id":9712888,"name":"Matteo Martineau"}],"regulators":["MR_INT"],"countryCode":"PL","discountAllowed":true,"timezone":"UTC","openDate":"2021-09-13T12:09:00.000Z","version":4030622672,"name":"Match Odds","eventName":"Kuhn v Martineau"}}]}
{"op":"mcm","clk":"4233432347","pt":1631534819053,"mc":[{"id":"1.187557759","marketDefinition":{"bspMarket":false,"turnInPlayEnabled":true,"persistenceEnabled":true,"marketBaseRate":5.0,"eventId":"30896122","eventTypeId":"2","numberOfWinners":1,"bettingType":"ODDS","marketType":"MATCH_ODDS","marketTime":"2021-09-13T12:06:00.000Z","suspendTime":"2021-09-13T12:06:00.000Z","bspReconciled":false,"complete":true,"inPlay":false,"crossMatching":true,"runnersVoidable":false,"numberOfActiveRunners":2,"betDelay":0,"status":"OPEN","runners":[{"status":"ACTIVE","sortPriority":1,"id":9634485,"name":"Nicola Kuhn"},{"status":"ACTIVE","sortPriority":2,"id":9712888,"name":"Matteo Martineau"}],"regulators":["MR_INT"],"countryCode":"PL","discountAllowed":true,"timezone":"UTC","openDate":"2021-09-13T12:06:00.000Z","version":4030622672,"name":"Match Odds","eventName":"Kuhn v Martineau"}}]}
{"op":"mcm","clk":"4233440562","pt":1631534900771,"mc":[{"id":"1.187557759","rc":[{"batb":[[0,2.26,31.05],[1,2.24,10.31],[2,2.22,10.48]],"ltp":2.46,"tv":916.08,"id":9712888}]}]}
{"op":"mcm","clk":"4233444423","pt":1631534940844,"mc":[{"id":"1.187557759","rc":[{"batb":[[1,2.2,34.8],[2,2.18,2.53]],"ltp":2.46,"tv":916.08,"id":9712888}]}]}
{"op":"mcm","clk":"4233468179","pt":1631535197402,"mc":[{"id":"1.187557759","rc":[{"trd":[[1.69,49.3]],"batb":[[0,1.69,42.62]],"ltp":1.69,"tv":1275.95,"id":9634485}],"tv":2192.04}]}
{"op":"mcm","clk":"4233477770","pt":1631535293475,"mc":[{"id":"1.187557759","rc":[{"batb":[[2,1.63,282.03]],"ltp":1.69,"tv":1275.95,"id":9634485}]}]}
{"op":"mcm","clk":"4233489749","pt":1631535418711,"mc":[{"id":"1.187557759","rc":[{"batb":[[2,1.63,238.1]],"ltp":1.69,"tv":1275.95,"id":9634485},{"batb":[[0,2.2,34.8],[1,2.18,2.53],[2,2.14,4.56]],"ltp":2.46,"tv":916.08,"id":9712888}]}]}
{"op":"mcm","clk":"4233489841","pt":1631535419336,"mc":[{"id":"1.187557759","marketDefinition":{"bspMarket":false,"turnInPlayEnabled":true,"persistenceEnabled":true,"marketBaseRate":5.0,"eventId":"30896122","eventTypeId":"2","numberOfWinners":1,"bettingType":"ODDS","marketType":"MATCH_ODDS","marketTime":"2021-09-13T12:06:00.000Z","suspendTime":"2021-09-13T12:06:00.000Z","bspReconciled":false,"complete":true,"inPlay":true,"crossMatching":true,"runnersVoidable":false,"numberOfActiveRunners":2,"betDelay":3,"status":"OPEN","runners":[{"status":"ACTIVE","sortPriority":1,"id":9634485,"name":"Nicola Kuhn"},{"status":"ACTIVE","sortPriority":2,"id":9712888,"name":"Matteo Martineau"}],"regulators":["MR_INT"],"countryCode":"PL","discountAllowed":true,"timezone":"UTC","openDate":"2021-09-13T12:06:00.000Z","version":4030631804,"name":"Match Odds","eventName":"Kuhn v Martineau"},"rc":[{"batb":[[0,1.67,1.38],[1,1.01,115.4],[2,1.63,0]],"batl":[[0,1.9,2],[1,1.86,0],[2,1.89,0]],"ltp":1.69,"tv":1275.95,"id":9634485},{"batb":[[0,2.14,4.56],[1,1.01,115.4],[2,2.14,0]],"ltp":2.46,"tv":916.08,"id":9712888}]}]}
{"op":"mcm","clk":"4233490593","pt":1631535426627,"mc":[{"id":"1.187557759","rc":[{"batb":[[0,2.4,7.48],[1,2.36,241.71],[2,2.14,4.56]],"batl":[[0,2.46,6.92],[1,2.5,208.32]],"ltp":2.46,"tv":916.08,"id":9712888}]}]}
{"op":"mcm","clk":"4233490681","pt":1631535427624,"mc":[{"id":"1.187557759","rc":[{"batb":[[1,1.57,49.71],[2,1.53,55.31]],"ltp":1.69,"tv":1275.95,"id":9634485},{"batb":[[1,2.38,26.95],[2,2.36,241.71]],"ltp":2.46,"tv":916.08,"id":9712888}]}]}
{"op":"mcm","clk":"4233491074","pt":1631535431555,"mc":[{"id":"1.187557759","rc":[{"trd":[[1.68,492.72]],"ltp":1.68,"tv":1286.08,"id":9634485},{"trd":[[2.46,9.99]],"batl":[[0,2.5,208.32],[1,2.5,0]],"ltp":2.46,"tv":923.0,"id":9712888}],"tv":2209.09}]}
{"op":"mcm","clk":"4233491158","pt":1631535432348,"mc":[{"id":"1.187557759","rc":[{"batb":[[1,1.65,127.18],[2,1.64,66.05]],"batl":[[0,1.71,96.9],[1,1.73,109.88],[2,1.9,2]],"ltp":1.68,"tv":1286.08,"id":9634485}]}]}
{"op":"mcm","clk":"4233492066","pt":1631535441572,"mc":[{"id":"1.187557759","rc":[{"batb":[[0,2.38,26.95],[1,2.36,241.71],[2,2.22,32.22]],"ltp":2.46,"tv":923.0,"id":9712888}]}]}
{"op":"mcm","clk":"4233492181","pt":1631535442565,"mc":[{"id":"1.187557759","rc":[{"batb":[[1,2.22,32.22],[2,2.14,4.56]],"ltp":2.46,"tv":923.0,"id":9712888}]}]}
{"op":"mcm","clk":"4233492240","pt":1631535443186,"mc":[{"id":"1.187557759","rc":[{"batb":[[1,1.53,55.31],[2,1.05,475.37]],"batl":[[0,1.9,2],[1,1.73,0],[2,1.9,0]],"ltp":1.68,"tv":1286.08,"id":9634485},{"batb":[[0,2.22,32.22],[1,2.14,4.56],[2,1.05,475.37]],"ltp":2.46,"tv":923.0,"id":9712888}]}]}
{"op":"mcm","clk":"4233492648","pt":1631535445793,"mc":[{"id":"1.187557759","rc":[{"batb":[[1,1.61,90.88],[2,1.6,72.15]],"batl":[[0,1.8,91.61],[1,1.82,93.16],[2,1.9,2]],"ltp":1.68,"tv":1286.08,"id":9634485},{"batb":[[2,1.09,260.53]],"ltp":2.46,"tv":923.0,"id":9712888}]}]}
{"op":"mcm","clk":"4233493035","pt":1631535447717,"mc":[{"id":"1.187557759","rc":[{"batb":[[2,1.11,270.09]],"ltp":2.46,"tv":923.0,"id":9712888}]}]}
{"op":"mcm","clk":"4233493535","pt":1631535449650,"mc":[{"id":"1.187557759","rc":[{"batl":[[0,1.9,2],[1,1.82,0],[2,1.9,0]],"ltp":1.68,"tv":1286.08,"id":9634485}]}]}
{"op":"mcm","clk":"4233493826","pt":1631535450938,"mc":[{"id":"1.187557759","rc":[{"batb":[[2,1.2,445.66]],"ltp":2.46,"tv":923.0,"id":9712888}]}]}
{"op":"mcm","clk":"4233494161","pt":1631535452631,"mc":[{"id":"1.187557759","rc":[{"trd":[[1.61,9.76],[1.67,21.69]],"batb":[[0,1.62,9.16],[1,1.61,86]],"batl":[[0,1.66,120.66],[1,1.68,121.35],[2,1.9,2]],"ltp":1.61,"tv":1298.59,"id":9634485},{"batb":[[0,2.42,454.21],[1,2.22,32.22],[2,2.14,4.56]],"batl":[[0,2.66,276.36]],"ltp":2.46,"tv":923.0,"id":9712888}],"tv":2221.6}]}
{"op":"mcm","clk":"4233494313","pt":1631535453727,"mc":[{"id":"1.187557759","rc":[{"batb":[[0,2.48,23.77],[1,2.42,454.21],[2,2.34,27.7]],"batl":[[1,3,3.33]],"ltp":2.46,"tv":923.0,"id":9712888}]}]}
{"op":"mcm","clk":"4233504958","pt":1631535467459,"mc":[{"id":"1.187557759","rc":[{"batb":[[0,1.5,59.66],[1,1.3,198.07],[2,1.25,237.69]],"batl":[[0,1.9,2],[1,1.68,0],[2,1.9,0]],"ltp":1.61,"tv":1298.59,"id":9634485},{"batb":[[0,2.34,27.7],[1,2.14,4.56],[2,1.8,11.88]],"ltp":2.46,"tv":923.0,"id":9712888}]}]}
{"op":"mcm","clk":"4233506117","pt":1631535472637,"mc":[{"id":"1.187557759","rc":[{"batb":[[0,1.62,97.36],[1,1.61,70.55],[2,1.5,59.66]],"batl":[[0,1.67,85.89],[1,1.69,119],[2,1.9,2]],"ltp":1.61,"tv":1298.59,"id":9634485}]}]}
{"op":"mcm","clk":"4233507235","pt":1631535478588,"mc":[{"id":"1.187557759","rc":[{"batb":[[0,1.66,34.07],[1,1.5,59.66],[2,1.3,198.07]],"batl":[[0,1.9,2],[1,1.69,0],[2,1.9,0]],"ltp":1.61,"tv":1298.59,"id":9634485},{"batb":[[2,1.7,16.97]],"ltp":2.46,"tv":923.0,"id":9712888}]}]}
{"op":"mcm","clk":"4233507716","pt":1631535481301,"mc":[{"id":"1.187557759","rc":[{"batb":[[1,1.58,70.48],[2,1.57,77.38]],"batl":[[0,1.72,77.33],[1,1.74,107.91],[2,1.9,2]],"ltp":1.61,"tv":1298.59,"id":9634485}]}]}
{"op":"mcm","clk":"4233509827","pt":1631535496818,"mc":[{"id":"1.187557759","rc":[{"batb":[[1,1.5,59.66],[2,1.3,198.07]],"ltp":1.61,"tv":1298.59,"id":9634485}]}]}
{"op":"mcm","clk":"4233510111","pt":1631535499695,"mc":[{"id":"1.187557759","rc":[{"batb":[[0,1.67,77.49],[1,1.66,97.18],[2,1.5,59.66]],"ltp":1.61,"tv":1298.59,"id":9634485},{"batb":[[0,2.4,6.74],[1,2.34,27.7],[2,2.32,238.65]],"batl":[[0,2.46,7.7],[1,2.5,304.31],[2,2.84,14.08]],"ltp":2.46,"tv":923.0,"id":9712888}]}]}
{"op":"mcm","clk":"4233510237","pt":1631535500809,"mc":[{"id":"1.187557759","rc":[{"trd":[[1.68,498.78]],"batb":[[2,1.58,48.53]],"ltp":1.68,"tv":1304.65,"id":9634485},{"trd":[[2.46,14.13]],"batl":[[0,2.46,3.56]],"ltp":2.46,"tv":927.14,"id":9712888}],"tv":2231.8}]}
{"op":"mcm","clk":"4233511305","pt":1631535510732,"mc":[{"id":"1.187557759","rc":[{"batb":[[0,2.34,27.7],[1,2.32,238.65],[2,2.3,13.04]],"batl":[[0,2.5,304.31],[1,2.84,14.08],[2,2.86,5.28]],"ltp":2.46,"tv":927.14,"id":9712888}]}]}
{"op":"mcm","clk":"4233511696","pt":1631535513744,"mc":[{"id":"1.187557759","rc":[{"batb":[[0,1.68,8.83],[1,1.67,77.49],[2,1.66,97.18]],"ltp":1.68,"tv":1304.65,"id":9634485},{"batb":[[0,2.42,6],[1,2.34,27.7],[2,2.32,238.65]],"ltp":2.46,"tv":927.14,"id":9712888}]}]}
{"op":"mcm","clk":"4233513270","pt":1631535527061,"mc":[{"id":"1.187557759","rc":[{"trd":[[1.71,65.38],[1.72,269.81]],"batl":[[0,1.72,73.05]],"ltp":1.72,"tv":1321.71,"id":9634485},{"trd":[[2.42,6]],"batb":[[0,2.34,27.7],[1,2.32,238.65],[2,2.3,13.04]],"ltp":2.42,"tv":933.14,"id":9712888}],"tv":2254.86}]}
{"op":"mcm","clk":"4233513558","pt":1631535529367,"mc":[{"id":"1.187557759","rc":[{"batb":[[0,1.66,34.07],[1,1.54,54.06],[2,1.3,198.07]],"batl":[[0,1.9,2],[1,1.74,0],[2,1.9,0]],"ltp":1.72,"tv":1321.71,"id":9634485},{"batb":[[0,2.18,34.48],[1,2.14,4.56],[2,1.7,16.97]],"ltp":2.42,"tv":933.14,"id":9712888}]}]}
{"op":"mcm","clk":"4233514119","pt":1631535533774,"mc":[{"id":"1.187557759","rc":[{"batb":[[0,1.69,69.6],[1,1.67,122.77],[2,1.66,34.07]],"batl":[[0,1.74,75.15],[1,1.76,103.9],[2,1.9,2]],"ltp":1.72,"tv":1321.71,"id":9634485}]}]}
{"op":"mcm","clk":"4233514645","pt":1631535538469,"mc":[{"id":"1.187557759","rc":[{"batb":[[0,1.66,34.07],[1,1.54,54.06],[2,1.3,198.07]],"batl":[[0,1.9,2],[1,1.76,0],[2,1.9,0]],"ltp":1.72,"tv":1321.71,"id":9634485}]}]}
{"op":"mcm","clk":"4233515029","pt":1631535541476,"mc":[{"id":"1.187557759","rc":[{"batb":[[1,1.61,127.91],[2,1.6,72.3]],"batl":[[0,1.83,98.29],[1,1.85,88.45],[2,1.9,2]],"ltp":1.72,"tv":1321.71,"id":9634485}]}]}
{"op":"mcm","clk":"4233515580","pt":1631535546386,"mc":[{"id":"1.187557759","rc":[{"batb":[[1,1.54,54.06],[2,1.3,198.07]],"ltp":1.72,"tv":1321.71,"id":9634485}]}]}
{"op":"mcm","clk":"4233515948","pt":1631535549785,"mc":[{"id":"1.187557759","rc":[{"batb":[[0,1.77,84.76],[1,1.76,648.6],[2,1.75,42.38]],"batl":[[0,1.83,109.16],[2,1.89,450.52]],"ltp":1.72,"tv":1321.71,"id":9634485},{"batb":[[2,1.6,99.04]],"batl":[[0,2.28,31.01],[1,2.62,3.82],[2,3.95,83.6]],"ltp":2.42,"tv":933.14,"id":9712888}]}]}
{"op":"mcm","clk":"4233516032","pt":1631535550516,"mc":[{"id":"1.187557759","rc":[{"trd":[[1.78,5.75]],"batb":[[0,1.77,16.96],[1,1.76,614.7],[2,1.75,8.48]],"ltp":1.78,"tv":1327.46,"id":9634485},{"trd":[[2.28,4.49]],"batb":[[1,2.16,13.88],[2,2.14,11.5]],"batl":[[0,2.28,26.52],[2,3.95,0]],"ltp":2.28,"tv":937.63,"id":9712888}],"tv":2265.1}]}
{"op":"mcm","clk":"4233516410","pt":1631535554176,"mc":[{"id":"1.187557759","rc":[{"trd":[[1.78,39.72]],"ltp":1.78,"tv":1361.43,"id":9634485},{"trd":[[2.28,31.01]],"batl":[[0,2.62,3.82],[1,2.62,0]],"ltp":2.28,"tv":964.15,"id":9712888}],"tv":2325.59}]}
{"op":"mcm","clk":"4233516733","pt":1631535557428,"mc":[{"id":"1.187557759","rc":[{"batl":[[0,2.6,459.04],[1,2.62,3.82]],"ltp":2.28,"tv":964.15,"id":9712888}]}]}
{"op":"mcm","clk":"4233517541","pt":1631535564183,"mc":[{"id":"1.187557759","rc":[{"batl":[[0,1.83,98.29]],"ltp":1.78,"tv":1361.43,"id":9634485}]}]}
{"op":"mcm","clk":"4233517830","pt":1631535567104,"mc":[{"id":"1.187557759","rc":[{"batb":[[1,1.76,627.87]],"batl":[[0,1.8,11.03],[1,1.83,98.29],[2,1.85,88.45]],"ltp":1.78,"tv":1361.43,"id":9634485}]}]}
{"op":"mcm","clk":"4233518161","pt":1631535570293,"mc":[{"id":"1.187557759","rc":[{"batb":[[0,1.77,100.96]],"ltp":1.78,"tv":1361.43,"id":9634485}]}]}
{"op":"mcm","clk":"4233518623","pt":1631535574539,"mc":[{"id":"1.187557759","rc":[{"batb":[[0,1.59,47.78],[1,1.3,198.07],[2,1.25,237.69]],"batl":[[0,1.9,2],[1,1.83,0],[2,1.85,0]],"ltp":1.78,"tv":1361.43,"id":9634485},{"batb":[[0,2.14,4.56],[1,1.98,45.86],[2,1.6,99.04]],"ltp":2.28,"tv":964.15,"id":9712888}]}]}
{"op":"mcm","clk":"4233518694","pt":1631535575121,"mc":[{"id":"1.187557759","rc":[{"batl":[[0,1.77,8.43],[1,1.9,2]],"ltp":1.78,"tv":1361.43,"id":9634485}]}]}
{"op":"mcm","clk":"4233518992","pt":1631535577840,"mc":[{"id":"1.187557759","rc":[{"batl":[[0,1.9,2],[1,1.9,0]],"ltp":1.78,"tv":1361.43,"id":9634485}]}]}
{"op":"mcm","clk":"4233519163","pt":1631535579514,"mc":[{"id":"1.187557759","rc":[{"batb":[[0,1.8,68.29],[1,1.78,98.77],[2,1.59,47.78]],"batl":[[0,1.86,76.24],[1,1.88,84.16],[2,1.9,2]],"ltp":1.78,"tv":1361.43,"id":9634485}]}]}
{"op":"mcm","clk":"4233519853","pt":1631535586435,"mc":[{"id":"1.187557759","rc":[{"batb":[[0,1.59,47.78],[1,1.3,198.07],[2,1.25,237.69]],"batl":[[0,1.9,2],[1,1.88,0],[2,1.9,0]],"ltp":1.78,"tv":1361.43,"id":9634485}]}]}
{"op":"mcm","clk":"4233520161","pt":1631535589468,"mc":[{"id":"1.187557759","rc":[{"batb":[[0,1.67,96.19],[1,1.66,63.15],[2,1.59,47.78]],"batl":[[1,2.02,96.7],[2,2.04,65.77]],"ltp":1.78,"tv":1361.43,"id":9634485}]}]}
{"op":"mcm","clk":"4233521278","pt":1631535599353,"mc":[{"id":"1.187557759","rc":[{"batb":[[0,1.59,47.78],[1,1.3,198.07],[2,1.25,237.69]],"ltp":1.78,"tv":1361.43,"id":9634485}]}]}
{"op":"mcm","clk":"4233521655","pt":1631535602788,"mc":[{"id":"1.187557759","rc":[{"trd":[[1.9,222.13]],"batb":[[0,1.94,69.13],[1,1.92,77.49],[2,1.91,120.42]],"batl":[[0,1.98,11.98]],"ltp":1.9,"tv":1363.43,"id":9634485},{"trd":[[2.1,330.13],[2.14,11.31]],"batb":[[0,1.98,45.86],[1,1.5,106.96],[2,1.4,148.56]],"batl":[[0,2.08,11.42],[1,2.36,4.24]],"ltp":2.1,"tv":975.08,"id":9712888}],"tv":2338.52}]}
{"op":"mcm","clk":"4233521745","pt":1631535603605,"mc":[{"id":"1.187557759","rc":[{"trd":[[1.94,10.64]],"batb":[[0,1.94,63.81]],"batl":[[1,2.02,111.56],[2,2.04,73.19]],"ltp":1.94,"tv":1374.07,"id":9634485},{"batb":[[1,1.76,33.3],[2,1.5,106.96]],"ltp":2.1,"tv":975.08,"id":9712888}],"tv":2349.16}]}
{"op":"mcm","clk":"4233522186","pt":1631535607595,"mc":[{"id":"1.187557759","rc":[{"trd":[[1.94,75.68]],"batb":[[0,1.91,120.42],[1,1.9,7.86],[2,1.89,7.86]],"ltp":1.94,"tv":1439.11,"id":9634485}],"tv":2414.2}]}
{"op":"mcm","clk":"4233522503","pt":1631535610578,"mc":[{"id":"1.187557759","rc":[{"batb":[[0,1.93,86.8],[1,1.91,199.19],[2,1.9,7.86]],"batl":[[1,2.02,131.67]],"ltp":1.94,"tv":1439.11,"id":9634485}]}]}
{"op":"mcm","clk":"4233522869","pt":1631535613995,"mc":[{"id":"1.187557759","rc":[{"batl":[[0,1.94,2.56],[1,1.98,11.98],[2,2.02,131.67]],"ltp":1.94,"tv":1439.11,"id":9634485}]}]}
{"op":"mcm","clk":"4233523806","pt":1631535623022,"mc":[{"id":"1.187557759","rc":[{"batl":[[0,1.98,11.98],[1,2.02,131.67],[2,2.04,73.19]],"ltp":1.94,"tv":1439.11,"id":9634485}]}]}
{"op":"mcm","clk":"4233524001","pt":1631535624714,"mc":[{"id":"1.187557759","rc":[{"batb":[[0,1.68,39.25],[1,1.53,2.53],[2,1.4,148.56]],"ltp":1.94,"tv":1439.11,"id":9634485},{"batb":[[0,1.76,33.3],[1,1.5,106.96],[2,1.4,148.56]],"ltp":2.1,"tv":975.08,"id":9712888}]}]}
{"op":"mcm","clk":"4233524129","pt":1631535626130,"mc":[{"id":"1.187557759","rc":[{"batl":[[0,1.93,2.56]],"ltp":1.94,"tv":1439.11,"id":9634485}]}]}
{"op":"mcm","clk":"4233524486","pt":1631535629331,"mc":[{"id":"1.187557759","rc":[{"trd":[[1.93,2.56]],"ltp":1.93,"tv":1441.66,"id":9634485},{"trd":[[2.06,42.1]],"batb":[[0,1.94,68.77],[1,1.92,77.49],[2,1.76,33.3]],"batl":[[0,2.02,94.66],[1,2.04,65.77]],"ltp":2.06,"tv":977.47,"id":9712888}],"tv":2419.14}]}
{"op":"mcm","clk":"4233525134","pt":1631535635772,"mc":[{"id":"1.187557759","rc":[{"batb":[[0,1.76,33.3],[1,1.5,106.96],[2,1.4,148.56]],"ltp":2.06,"tv":977.47,"id":9712888}]}]}
{"op":"mcm","clk":"4233525442","pt":1631535638671,"mc":[{"id":"1.187557759","rc":[{"batb":[[1,1.75,63.81],[2,1.73,108.62]],"batl":[[0,2.3,82.56],[1,2.32,45.77]],"ltp":2.06,"tv":977.47,"id":9712888}]}]}
{"op":"mcm","clk":"4233525525","pt":1631535639353,"mc":[{"id":"1.187557759","rc":[{"batl":[[0,1.98,0.12]],"ltp":1.93,"tv":1441.66,"id":9634485}]}]}
{"op":"mcm","clk":"4233525889","pt":1631535643143,"mc":[{"id":"1.187557759","rc":[{"batb":[[1,1.5,106.96],[2,1.4,148.56]],"ltp":2.06,"tv":977.47,"id":9712888}]}]}
{"op":"mcm","clk":"4233526217","pt":1631535646262,"mc":[{"id":"1.187557759","rc":[{"trd":[[1.75,5.71]],"batb":[[0,1.77,103.36],[1,1.75,104.68],[2,1.68,39.25]],"batl":[[0,1.8,66.67],[1,1.83,17.55],[2,1.84,99.82]],"ltp":1.75,"tv":1447.37,"id":9634485},{"trd":[[2.32,4.31]],"batb":[[0,2.18,41.28],[1,2.16,20.64],[2,2.14,20.64]],"batl":[[0,2.28,325.18]],"ltp":2.32,"tv":981.78,"id":9712888}],"tv":2429.16}]}
{"op":"mcm","clk":"4233526320","pt":1631535647271,"mc":[{"id":"1.187557759","rc":[{"batb":[[1,1.76,17.04],[2,1.75,113.2]],"ltp":1.75,"tv":1447.37,"id":9634485},{"batb":[[1,2.16,55.79]],"batl":[[1,2.6,3.85]],"ltp":2.32,"tv":981.78,"id":9712888}]}]}
{"op":"mcm","clk":"4233528912","pt":1631535671337,"mc":[{"id":"1.187557759","rc":[{"batb":[[0,1.6,46.61],[1,1.53,2.53],[2,1.4,148.56]],"ltp":1.75,"tv":1447.37,"id":9634485},{"batb":[[0,1.96,47.2],[1,1.6,99.04],[2,1.5,106.96]],"ltp":2.32,"tv":981.78,"id":9712888}]}]}
{"op":"mcm","clk":"4233529204","pt":1631535674234,"mc":[{"id":"1.187557759","rc":[{"batb":[[0,1.68,77.96],[1,1.66,125.52],[2,1.6,46.61]],"batl":[[0,1.77,8.43],[1,2.02,59.51],[2,2.04,65.78]],"ltp":1.75,"tv":1447.37,"id":9634485}]}]}
{"op":"mcm","clk":"4233529329","pt":1631535675332,"mc":[{"id":"1.187557759","rc":[{"batb":[[0,1.6,46.61],[1,1.53,2.53],[2,1.4,148.56]],"batl":[[1,2.02,0],[2,2.04,0]],"ltp":1.75,"tv":1447.37,"id":9634485}]}]}
{"op":"mcm","clk":"4233529614","pt":1631535678250,"mc":[{"id":"1.187557759","rc":[{"trd":[[1.77,16.86]],"batb":[[0,1.81,55.24],[1,1.79,96.98],[2,1.6,46.61]],"batl":[[0,1.87,76.84],[1,1.89,82.81]],"ltp":1.77,"tv":1464.24,"id":9634485}],"tv":2446.03}]}
{"op":"mcm","clk":"4233529741","pt":1631535679425,"mc":[{"id":"1.187557759","rc":[{"batl":[[2,2.42,290.48]],"ltp":1.77,"tv":1464.24,"id":9634485}]}]}
{"op":"mcm","clk":"4233530079","pt":1631535682952,"mc":[{"id":"1.187557759","rc":[{"batb":[[0,1.6,46.61],[1,1.55,426.3],[2,1.53,2.53]],"batl":[[0,2.42,290.48],[1,1.89,0],[2,2.42,0]],"ltp":1.77,"tv":1464.24,"id":9634485}]}]}
{"op":"mcm","clk":"4233530357","pt":1631535686199,"mc":[{"id":"1.187557759","rc":[{"batb":[[0,1.68,73.04],[1,1.66,125.51],[2,1.6,46.61]],"batl":[[0,2.02,63.6],[1,2.04,65.79],[2,2.42,290.48]],"ltp":1.77,"tv":1464.24,"id":9634485}]}]}
{"op":"mcm","clk":"4233530734","pt":1631535689874,"mc":[{"id":"1.187557759","rc":[{"batb":[[0,1.6,46.61],[1,1.55,426.3],[2,1.53,2.53]],"ltp":1.77,"tv":1464.24,"id":9634485}]}]}
{"op":"mcm","clk":"4233531018","pt":1631535692756,"mc":[{"id":"1.187557759","rc":[{"batb":[[0,1.95,65.61],[1,1.93,76.25],[2,1.92,46.87]],"batl":[[0,2,5.76],[1,2.02,63.6],[2,2.04,65.79]],"ltp":1.77,"tv":1464.24,"id":9634485},{"batb":[[0,2,5.76],[1,1.96,47.2]],"batl":[[0,2.06,516.5],[1,2.34,4.27]],"ltp":2.32,"tv":981.78,"id":9712888}]}]}
{"op":"mcm","clk":"4233531141","pt":1631535693761,"mc":[{"id":"1.187557759","rc":[{"trd":[[1.95,10.58]],"batb":[[0,1.95,60.32],[2,1.92,15.62]],"batl":[[1,2.02,78.46],[2,2.04,73.21]],"ltp":1.95,"tv":1474.82,"id":9634485},{"batb":[[2,1.75,34.06]],"ltp":2.32,"tv":981.78,"id":9712888}],"tv":2456.61}]}
{"op":"mcm","clk":"4233532715","pt":1631535709515,"mc":[{"id":"1.187557759","rc":[{"trd":[[1.95,10.82]],"batb":[[0,1.95,60.2]],"ltp":1.95,"tv":1475.05,"id":9634485}],"tv":2456.84}]}
{"op":"mcm","clk":"4233533351","pt":1631535715616,"mc":[{"id":"1.187557759","rc":[{"batb":[[0,1.69,38.41],[1,1.53,2.53],[2,1.4,148.56]],"ltp":1.95,"tv":1475.05,"id":9634485},{"batb":[[0,1.75,34.06],[1,1.5,106.96],[2,1.4,148.56]],"ltp":2.32,"tv":981.78,"id":9712888}]}]}
{"op":"mcm","clk":"4233533644","pt":1631535718515,"mc":[{"id":"1.187557759","rc":[{"batb":[[0,1.79,61.3],[1,1.77,100.67],[2,1.69,38.41]],"batl":[[0,2.36,68.58],[1,2.4,84.1]],"ltp":1.95,"tv":1475.05,"id":9634485}]}]}
{"op":"mcm","clk":"4233534043","pt":1631535722711,"mc":[{"id":"1.187557759","rc":[{"trd":[[1.79,11.36]],"batb":[[0,1.8,388.42],[1,1.79,55.62],[2,1.77,100.67]],"batl":[[0,1.81,66.3],[1,1.83,7.82],[2,1.85,87.17]],"ltp":1.79,"tv":1486.41,"id":9634485},{"batb":[[0,2.16,41.66],[1,2.14,20.83],[2,2.12,20.83]],"ltp":2.32,"tv":981.78,"id":9712888}],"tv":2468.2}]}
{"op":"mcm","clk":"4233534156","pt":1631535723511,"mc":[{"id":"1.187557759","rc":[{"batb":[[2,1.77,117.63]],"ltp":1.79,"tv":1486.41,"id":9634485},{"batb":[[0,2.16,13.88],[1,2.14,42.92],[2,2.12,6.94]],"batl":[[0,2.58,3.88]],"ltp":2.32,"tv":981.78,"id":9712888}]}]}
{"op":"mcm","clk":"4233534555","pt":1631535727431,"mc":[{"id":"1.187557759","rc":[{"trd":[[1.8,65.42]],"batb":[[0,1.8,355.71]],"ltp":1.8,"tv":1551.83,"id":9634485}],"tv":2533.62}]}
{"op":"mcm","clk":"4233535013","pt":1631535731841,"mc":[{"id":"1.187557759","rc":[{"batl":[[0,2.56,225.78],[1,2.58,3.88]],"ltp":2.32,"tv":981.78,"id":9712888}]}]}
{"op":"mcm","clk":"4233535563","pt":1631535737347,"mc":[{"id":"1.187557759","rc":[{"batl":[[1,1.85,87.17],[2,1.87,85.59]],"ltp":1.8,"tv":1551.83,"id":9634485}]}]}
{"op":"mcm","clk":"4233535671","pt":1631535738339,"mc":[{"id":"1.187557759","rc":[{"trd":[[1.8,85.42]],"batb":[[0,1.8,345.71]],"ltp":1.8,"tv":1571.83,"id":9634485}],"tv":2553.62}]}
{"op":"mcm","clk":"4233535897","pt":1631535740542,"mc":[{"id":"1.187557759","rc":[{"batb":[[0,1.8,472.71]],"batl":[[1,1.83,16.86],[2,1.85,87.17]],"ltp":1.8,"tv":1571.83,"id":9634485},{"batl":[[0,2.28,8.75]],"ltp":2.32,"tv":981.78,"id":9712888}]}]}
{"op":"mcm","clk":"4233537140","pt":1631535753674,"mc":[{"id":"1.187557759","rc":[{"batb":[[0,1.69,38.41],[1,1.6,46.28],[2,1.55,426.3]],"batl":[[0,2.42,290.48],[1,810,0.07],[2,1.85,0]],"ltp":1.8,"tv":1571.83,"id":9634485},{"batb":[[0,2.14,35.98],[1,1.95,48.2],[2,1.6,99.04]],"ltp":2.32,"tv":981.78,"id":9712888}]}]}
{"op":"mcm","clk":"4233537156","pt":1631535753892,"mc":[{"id":"1.187557759","rc":[{"batb":[[0,1.6,46.28],[1,1.55,426.3],[2,1.53,2.53]],"ltp":1.8,"tv":1571.83,"id":9634485},{"batb":[[0,1.95,48.2],[1,1.6,99.04],[2,1.5,106.96]],"ltp":2.32,"tv":981.78,"id":9712888}]}]}
{"op":"mcm","clk":"4233537382","pt":1631535756586,"mc":[{"id":"1.187557759","rc":[{"batb":[[0,1.69,72.64],[1,1.67,122.89],[2,1.6,46.28]],"batl":[[0,2.04,78.21],[1,2.06,63.94],[2,2.42,290.48]],"ltp":1.8,"tv":1571.83,"id":9634485}]}]}
{"op":"mcm","clk":"4233537475","pt":1631535757681,"mc":[{"id":"1.187557759","rc":[{"batb":[[0,1.6,46.28],[1,1.55,426.3],[2,1.53,2.53]],"batl":[[0,2.42,290.48],[1,1000,2.24],[2,2.42,0]],"ltp":1.8,"tv":1571.83,"id":9634485}]}]}
{"op":"mcm","clk":"4233537535","pt":1631535758373,"mc":[{"id":"1.187557759","rc":[{"batl":[[1,810,0.07]],"ltp":1.8,"tv":1571.83,"id":9634485}]}]}
{"op":"mcm","clk":"4233537726","pt":1631535760557,"mc":[{"id":"1.187557759","rc":[{"batb":[[0,1.82,70.49],[1,1.8,95.26],[2,1.6,46.28]],"batl":[[0,1.88,66.51],[1,1.9,81.51],[2,2.42,290.48]],"ltp":1.8,"tv":1571.83,"id":9634485}]}]}
{"op":"mcm","clk":"4233538155","pt":1631535765159,"mc":[{"id":"1.187557759","rc":[{"batb":[[0,1.6,46.28],[1,1.55,426.3],[2,1.53,2.53]],"batl":[[0,2.42,290.48],[1,820,0.14],[2,2.42,0]],"ltp":1.8,"tv":1571.83,"id":9634485}]}]}
{"op":"mcm","clk":"4233538441","pt":1631535768084,"mc":[{"id":"1.187557759","rc":[{"batb":[[0,1.69,72.64],[1,1.67,122.89],[2,1.6,46.28]],"batl":[[0,2.04,78.21],[1,2.06,63.94],[2,2.42,290.48]],"ltp":1.8,"tv":1571.83,"id":9634485}]}]}
{"op":"mcm","clk":"4233541693","pt":1631535799271,"mc":[{"id":"1.187557759","rc":[{"batl":[[0,2.42,290.48],[1,820,0.14],[2,2.42,0]],"ltp":1.8,"tv":1571.83,"id":9634485}]}]}
{"op":"mcm","clk":"4233541860","pt":1631535801171,"mc":[{"id":"1.187557759","rc":[{"batl":[[0,820,0.14],[1,820,0]],"ltp":1.8,"tv":1571.83,"id":9634485}]}]}
{"op":"mcm","clk":"4233542031","pt":1631535802844,"mc":[{"id":"1.187557759","rc":[{"trd":[[1.69,61.2]],"batb":[[0,1.69,66.69],[2,1.66,45.18]],"batl":[[0,1.74,89.74],[1,1.75,8.62],[2,1.76,112.64]],"ltp":1.69,"tv":1583.73,"id":9634485},{"batb":[[0,2.4,6.62],[1,2.36,84.74],[2,1.95,48.2]],"batl":[[0,2.42,247.95],[1,2.46,7.9],[2,2.78,3.6]],"ltp":2.32,"tv":981.78,"id":9712888}],"tv":2565.52}]}
{"op":"mcm","clk":"4233542075","pt":1631535803359,"mc":[{"id":"1.187557759","rc":[{"batb":[[2,1.66,18.08]],"ltp":1.69,"tv":1583.73,"id":9634485},{"batb":[[2,2.3,29.29]],"ltp":2.32,"tv":981.78,"id":9712888}]}]}
{"op":"mcm","clk":"4233542686","pt":1631535810170,"mc":[{"id":"1.187557759","rc":[{"batb":[[0,1.7,127],[1,1.69,66.69],[2,1.67,122.89]],"ltp":1.69,"tv":1583.73,"id":9634485}]}]}
{"op":"mcm","clk":"4233542917","pt":1631535812677,"mc":[{"id":"1.187557759","rc":[{"trd":[[1.72,278.33]],"ltp":1.72,"tv":1592.25,"id":9634485},{"trd":[[2.4,6.1]],"batb":[[0,2.36,85.26],[1,2.3,29.29],[2,2.12,36.82]],"ltp":2.4,"tv":987.88,"id":9712888}],"tv":2580.14}]}
{"op":"mcm","clk":"4233542945","pt":1631535812967,"mc":[{"id":"1.187557759","rc":[{"batb":[[0,1.69,66.69],[1,1.67,122.89],[2,1.66,18.08]],"ltp":1.72,"tv":1592.25,"id":9634485}]}]}
{"op":"mcm","clk":"4233543209","pt":1631535816051,"mc":[{"id":"1.187557759","rc":[{"batb":[[0,1.71,138],[1,1.69,66.69],[2,1.67,122.89]],"ltp":1.72,"tv":1592.25,"id":9634485}]}]}
{"op":"mcm","clk":"4233543761","pt":1631535822875,"mc":[{"id":"1.187557759","rc":[{"batb":[[0,2.36,84.74]],"batl":[[1,2.78,3.6],[2,2.78,0]],"ltp":2.4,"tv":987.88,"id":9712888}]}]}
{"op":"mcm","clk":"4233544031","pt":1631535825797,"mc":[{"id":"1.187557759","rc":[{"batb":[[1,1.7,9.25],[2,1.69,66.69]],"ltp":1.72,"tv":1592.25,"id":9634485},{"trd":[[2.36,0.72]],"batb":[[0,2.36,95.2]],"ltp":2.36,"tv":988.6,"id":9712888}],"tv":2580.86}]}
{"op":"mcm","clk":"4233544665","pt":1631535832788,"mc":[{"id":"1.187557759","rc":[{"trd":[[1.71,67.24]],"batb":[[0,1.71,137.07],[1,1.55,478.77],[2,1.53,2.53]],"batl":[[0,2.3,314.02],[1,810,0.07],[2,1.76,0]],"ltp":1.71,"tv":1594.11,"id":9634485},{"batb":[[0,2.12,36.82],[1,1.7,16.97],[2,1.6,99.04]],"ltp":2.36,"tv":988.6,"id":9712888}],"tv":2582.72}]}
{"op":"mcm","clk":"4233544716","pt":1631535833301,"mc":[{"id":"1.187557759","rc":[{"batb":[[0,1.55,478.77],[1,1.53,2.53],[2,1.3,198.07]],"ltp":1.71,"tv":1594.11,"id":9634485}]}]}
{"op":"mcm","clk":"4233544944","pt":1631535835717,"mc":[{"id":"1.187557759","rc":[{"batb":[[0,1.62,115.45],[1,1.61,70.7],[2,1.55,478.77]],"batl":[[0,1.86,69.22],[1,1.88,84.24],[2,2.3,314.02]],"ltp":1.71,"tv":1594.11,"id":9634485}]}]}
{"op":"mcm","clk":"4233544967","pt":1631535835924,"mc":[{"id":"1.187557759","rc":[{"batb":[[0,1.55,478.77],[1,1.53,2.53],[2,1.3,198.07]],"batl":[[0,2.3,314.02],[1,810,0.07],[2,2.3,0]],"ltp":1.71,"tv":1594.11,"id":9634485}]}]}
{"op":"mcm","clk":"4233545165","pt":1631535837911,"mc":[{"id":"1.187557759","rc":[{"batb":[[0,1.71,75.75],[1,1.69,117.91],[2,1.55,478.77]],"batl":[[0,1.76,60.43],[1,1.78,100.3],[2,2.3,314.02]],"ltp":1.71,"tv":1594.11,"id":9634485}]}]}
{"op":"mcm","clk":"4233545706","pt":1631535844035,"mc":[{"id":"1.187557759","rc":[{"batb":[[0,1.55,478.77],[1,1.53,2.53],[2,1.3,198.07]],"batl":[[0,2.3,314.02],[1,810,0.07],[2,2.3,0]],"ltp":1.71,"tv":1594.11,"id":9634485}]}]}
{"op":"mcm","clk":"4233545914","pt":1631535846937,"mc":[{"id":"1.187557759","rc":[{"batb":[[0,1.62,115.45],[1,1.61,70.7],[2,1.55,478.77]],"batl":[[0,1.86,69.22],[1,1.88,84.24],[2,2.3,314.02]],"ltp":1.71,"tv":1594.11,"id":9634485}]}]}
{"op":"mcm","clk":"4233546603","pt":1631535854809,"mc":[{"id":"1.187557759","rc":[{"batl":[[0,2.3,314.02],[1,810,0.07],[2,2.3,0]],"ltp":1.71,"tv":1594.11,"id":9634485}]}]}
{"op":"mcm","clk":"4233546738","pt":1631535856215,"mc":[{"id":"1.187557759","rc":[{"batb":[[2,1.55,52.47]],"batl":[[0,810,0.07],[1,810,0]],"ltp":1.71,"tv":1594.11,"id":9634485}]}]}
{"op":"mcm","clk":"4233546899","pt":1631535857830,"mc":[{"id":"1.187557759","rc":[{"trd":[[1.62,12.34],[1.66,22.24],[1.67,42.03]],"batb":[[0,1.62,109.28]],"batl":[[0,1.67,58.86],[1,1.68,53.57],[2,1.69,146.04]],"ltp":1.67,"tv":1649.04,"id":9634485},{"batb":[[0,2.44,49.18],[1,2.36,392.43],[2,2.12,36.82]],"batl":[[0,2.56,214.66],[1,2.6,10.54]],"ltp":2.36,"tv":988.6,"id":9712888}],"tv":2637.64}]}
{"op":"mcm","clk":"4233546993","pt":1631535858825,"mc":[{"id":"1.187557759","rc":[{"batb":[[1,1.61,126.6],[2,1.6,9.32]],"batl":[[1,1.68,17.86],[2,1.69,128.18]],"ltp":1.67,"tv":1649.04,"id":9634485},{"batb":[[1,2.42,25.27],[2,2.36,392.43]],"batl":[[2,2.94,3.4]],"ltp":2.36,"tv":988.6,"id":9712888}]}]}
{"op":"mcm","clk":"4233547003","pt":1631535858929,"mc":[{"id":"1.187557759","rc":[{"batb":[[1,1.61,89.34]],"ltp":1.67,"tv":1649.04,"id":9634485}]}]}
{"op":"mcm","clk":"4233547224","pt":1631535861131,"mc":[{"id":"1.187557759","rc":[{"batb":[[0,1.62,117.84]],"batl":[[0,1.67,66.72]],"ltp":1.67,"tv":1649.04,"id":9634485}]}]}
{"op":"mcm","clk":"4233547823","pt":1631535867746,"mc":[{"id":"1.187557759","rc":[{"batl":[[1,2.94,3.4],[2,2.94,0]],"ltp":2.36,"tv":988.6,"id":9712888}]}]}
{"op":"mcm","clk":"4233548080","pt":1631535870669,"mc":[{"id":"1.187557759","rc":[{"batl":[[1,1.68,32.69]],"ltp":1.67,"tv":1649.04,"id":9634485},{"batl":[[0,2.56,224.23]],"ltp":2.36,"tv":988.6,"id":9712888}]}]}
{"op":"mcm","clk":"4233548451","pt":1631535874948,"mc":[{"id":"1.187557759","rc":[{"trd":[[1.67,42.32]],"batl":[[0,1.67,66.43]],"ltp":1.67,"tv":1649.33,"id":9634485},{"trd":[[2.48,342.71]],"ltp":2.48,"tv":988.79,"id":9712888}],"tv":2638.12}]}
{"op":"mcm","clk":"4233549109","pt":1631535883097,"mc":[{"id":"1.187557759","rc":[{"trd":[[1.67,42.46]],"batl":[[0,1.67,66.29]],"ltp":1.67,"tv":1649.47,"id":9634485},{"trd":[[2.48,342.81]],"ltp":2.48,"tv":988.89,"id":9712888}],"tv":2638.36}]}
{"op":"mcm","clk":"4233549995","pt":1631535894974,"mc":[{"id":"1.187557759","rc":[{"batb":[[0,1.61,18.64],[1,1.6,9.32],[2,1.59,9.32]],"batl":[[0,1.68,32.69],[1,1.69,8.92],[2,1.7,8.92]],"ltp":1.67,"tv":1649.47,"id":9634485}]}]}
{"op":"mcm","clk":"4233550060","pt":1631535896111,"mc":[{"id":"1.187557759","rc":[{"batb":[[0,1.64,65],[1,1.61,18.64],[2,1.6,9.32]],"ltp":1.67,"tv":1649.47,"id":9634485}]}]}
{"op":"mcm","clk":"4233553135","pt":1631535940509,"mc":[{"id":"1.187557759","rc":[{"trd":[[1.68,563.25]],"batb":[[0,1.61,18.64],[1,1.6,9.32],[2,1.59,9.32]],"batl":[[0,1.69,9.38],[1,1.7,8.92],[2,1.74,94.3]],"ltp":1.68,"tv":1713.94,"id":9634485}],"tv":2702.83}]}
{"op":"mcm","clk":"4233553578","pt":1631535946205,"mc":[{"id":"1.187557759","rc":[{"trd":[[1.68,564.17],[1.69,79.04],[1.7,226.51]],"batl":[[0,1.74,94.3],[1,1.76,103.93],[2,2.16,347.55]],"ltp":1.7,"tv":1810.65,"id":9634485},{"trd":[[2.44,41.92]],"batb":[[0,2.44,7.31]],"ltp":2.44,"tv":1030.76,"id":9712888}],"tv":2841.41}]}
{"op":"mcm","clk":"4233553907","pt":1631535950415,"mc":[{"id":"1.187557759","rc":[{"batl":[[0,2.56,214.66]],"ltp":2.44,"tv":1030.76,"id":9712888}]}]}
{"op":"mcm","clk":"4233554127","pt":1631535952817,"mc":[{"id":"1.187557759","rc":[{"batb":[[0,1.61,9.32],[1,1.6,4.66],[2,1.59,4.66]],"ltp":1.7,"tv":1810.65,"id":9634485},{"batb":[[0,2.42,25.27],[1,2.3,29.54],[2,1.8,11.88]],"ltp":2.44,"tv":1030.76,"id":9712888}]}]}
{"op":"mcm","clk":"4233554199","pt":1631535953544,"mc":[{"id":"1.187557759","rc":[{"trd":[[1.7,254.8]],"batb":[[0,1.54,119.87],[1,1.53,88.37],[2,1.48,62.59]],"ltp":1.7,"tv":1838.95,"id":9634485},{"batb":[[0,2.3,29.54],[1,1.8,11.88],[2,1.7,16.97]],"ltp":2.44,"tv":1030.76,"id":9712888}],"tv":2869.71}]}
{"op":"mcm","clk":"4233554262","pt":1631535954323,"mc":[{"id":"1.187557759","rc":[{"batb":[[1,1.7,16.97],[2,1.6,99.04]],"ltp":2.44,"tv":1030.76,"id":9712888}]}]}
{"op":"mcm","clk":"4233554866","pt":1631535961328,"mc":[{"id":"1.187557759","rc":[{"batb":[[0,1.53,2.53],[1,1.48,62.59],[2,1.44,442.2]],"ltp":1.7,"tv":1838.95,"id":9634485}]}]}
{"op":"mcm","clk":"4233554992","pt":1631535962556,"mc":[{"id":"1.187557759","rc":[{"batb":[[2,1.3,198.07]],"ltp":1.7,"tv":1838.95,"id":9634485}]}]}
{"op":"mcm","clk":"4233555163","pt":1631535964445,"mc":[{"id":"1.187557759","rc":[{"trd":[[1.74,22.28]],"batb":[[0,1.68,110.74],[1,1.66,125.74],[2,1.53,2.53]],"batl":[[0,1.74,86.6],[2,1.8,388.45]],"ltp":1.74,"tv":1854.35,"id":9634485},{"batl":[[0,2.42,271.48],[1,2.44,6.2],[2,2.46,6.2]],"ltp":2.44,"tv":1030.76,"id":9712888}],"tv":2885.11}]}
{"op":"mcm","clk":"4233555249","pt":1631535965538,"mc":[{"id":"1.187557759","rc":[{"trd":[[1.7,260.79]],"batb":[[2,1.61,45.86]],"batl":[[2,1.79,16.76]],"ltp":1.7,"tv":1860.34,"id":9634485},{"trd":[[2.42,10.21]],"batb":[[1,2.2,32.97],[2,1.7,16.97]],"batl":[[0,2.42,267.27]],"ltp":2.42,"tv":1034.97,"id":9712888}],"tv":2895.31}]}
{"op":"mcm","clk":"4233555407","pt":1631535967644,"mc":[{"id":"1.187557759","rc":[{"trd":[[1.74,37.68]],"batl":[[0,1.74,78.9]],"ltp":1.74,"tv":1875.74,"id":9634485}],"tv":2910.71}]}
{"op":"mcm","clk":"4233555594","pt":1631535970648,"mc":[{"id":"1.187557759","rc":[{"batb":[[0,1.68,119.57]],"ltp":1.74,"tv":1875.74,"id":9634485}]}]}
{"op":"mcm","clk":"4233555691","pt":1631535972060,"mc":[{"id":"1.187557759","rc":[{"trd":[[1.7,260.89]],"ltp":1.7,"tv":1875.83,"id":9634485},{"trd":[[2.42,10.28]],"batl":[[0,2.42,267.2]],"ltp":2.42,"tv":1035.04,"id":9712888}],"tv":2910.87}]}
{"op":"mcm","clk":"4233556308","pt":1631535980258,"mc":[{"id":"1.187557759","rc":[{"batl":[[2,1.78,19.63]],"ltp":1.7,"tv":1875.83,"id":9634485},{"batl":[[0,2.36,5.97],[1,2.42,267.2],[2,2.44,6.2]],"ltp":2.42,"tv":1035.04,"id":9712888}]}]}
{"op":"mcm","clk":"4233556483","pt":1631535982388,"mc":[{"id":"1.187557759","rc":[{"batb":[[0,1.54,54.23],[1,1.53,2.53],[2,1.5,432.79]],"batl":[[0,2.16,347.55],[1,810,0.07],[2,1.78,0]],"ltp":1.7,"tv":1875.83,"id":9634485},{"batb":[[0,2.2,32.97],[1,1.7,16.97],[2,1.6,99.04]],"ltp":2.42,"tv":1035.04,"id":9712888}]}]}
{"op":"mcm","clk":"4233556727","pt":1631535985207,"mc":[{"id":"1.187557759","rc":[{"batb":[[0,1.61,72.12],[1,1.6,72.14],[2,1.54,54.23]],"batl":[[0,1.8,82.36],[1,1.82,93.24],[2,2.16,347.55]],"ltp":1.7,"tv":1875.83,"id":9634485}]}]}
{"op":"mcm","clk":"4233557498","pt":1631535994288,"mc":[{"id":"1.187557759","rc":[{"batl":[[0,2.16,347.55],[1,810,0.07],[2,2.16,0]],"ltp":1.7,"tv":1875.83,"id":9634485}]}]}
{"op":"mcm","clk":"4233557749","pt":1631535997729,"mc":[{"id":"1.187557759","rc":[{"trd":[[1.64,6.21]],"batl":[[0,1.66,116.35],[1,1.67,53.89],[2,1.68,165.1]],"ltp":1.64,"tv":1882.04,"id":9634485},{"trd":[[2.56,3.98]],"batb":[[0,2.42,49.58],[1,2.2,32.97],[2,1.7,16.97]],"batl":[[0,2.56,4.16],[1,2.66,390.09]],"ltp":2.56,"tv":1039.02,"id":9712888}],"tv":2921.06}]}
{"op":"mcm","clk":"4233557820","pt":1631535998724,"mc":[{"id":"1.187557759","rc":[{"batl":[[1,1.67,17.96],[2,1.68,147.14]],"ltp":1.64,"tv":1882.04,"id":9634485},{"batb":[[0,2.46,24.35],[1,2.42,49.58],[2,2.32,28.54]],"batl":[[1,2.66,401.37],[2,2.68,5.64]],"ltp":2.56,"tv":1039.02,"id":9712888}]}]}
{"op":"mcm","clk":"4233557954","pt":1631536000296,"mc":[{"id":"1.187557759","rc":[{"trd":[[1.66,65.73]],"batl":[[0,1.66,94.61]],"ltp":1.66,"tv":1925.53,"id":9634485}],"tv":2964.55}]}
{"op":"mcm","clk":"4233558111","pt":1631536002144,"mc":[{"id":"1.187557759","rc":[{"trd":[[1.64,12.7]],"ltp":1.64,"tv":1932.02,"id":9634485},{"trd":[[2.56,8.14]],"batl":[[0,2.66,401.37],[1,2.68,5.64],[2,2.7,5.64]],"ltp":2.56,"tv":1043.18,"id":9712888}],"tv":2975.2}]}
{"op":"mcm","clk":"4233558288","pt":1631536003830,"mc":[{"id":"1.187557759","rc":[{"batb":[[0,1.61,84.52]],"batl":[[0,1.66,104.33]],"ltp":1.64,"tv":1932.02,"id":9634485}]}]}
{"op":"mcm","clk":"4233558464","pt":1631536006023,"mc":[{"id":"1.187557759","rc":[{"trd":[[1.66,71.57]],"batl":[[0,1.66,98.49]],"ltp":1.66,"tv":1937.86,"id":9634485},{"trd":[[2.5,3.87]],"ltp":2.5,"tv":1047.05,"id":9712888}],"tv":2984.91}]}
{"op":"mcm","clk":"4233558567","pt":1631536007237,"mc":[{"id":"1.187557759","rc":[{"batl":[[2,1.68,130.33]],"ltp":1.66,"tv":1937.86,"id":9634485}]}]}
{"op":"mcm","clk":"4233558824","pt":1631536010840,"mc":[{"id":"1.187557759","rc":[{"trd":[[1.66,262.53]],"batb":[[0,1.61,72.12],[1,1.54,54.23],[2,1.53,2.53]],"batl":[[0,1.66,14.65],[2,1.68,8.98]],"ltp":1.66,"tv":2128.82,"id":9634485},{"batl":[[0,2.6,8.18],[1,2.66,401.37],[2,2.68,5.64]],"ltp":2.5,"tv":1047.05,"id":9712888}],"tv":3175.87}]}
{"op":"mcm","clk":"4233558908","pt":1631536011839,"mc":[{"id":"1.187557759","rc":[{"batl":[[0,2.16,347.55],[1,810,0.07],[2,1.68,0]],"ltp":1.66,"tv":2128.82,"id":9634485},{"batb":[[1,2.32,28.54],[2,1.8,11.88]],"ltp":2.5,"tv":1047.05,"id":9712888}]}]}
{"op":"mcm","clk":"4233558957","pt":1631536012262,"mc":[{"id":"1.187557759","rc":[{"batb":[[0,1.53,2.53],[1,1.5,432.79],[2,1.45,67.36]],"ltp":1.66,"tv":2128.82,"id":9634485},{"batb":[[0,2.32,28.54],[1,1.8,11.88],[2,1.7,16.97]],"ltp":2.5,"tv":1047.05,"id":9712888}]}]}
{"op":"mcm","clk":"4233559080","pt":1631536013728,"mc":[{"id":"1.187557759","rc":[{"batb":[[0,1.62,71.56],[1,1.53,2.53],[2,1.5,432.79]],"batl":[[0,1.67,109.65],[1,1.69,118.52],[2,2.16,347.55]],"ltp":1.66,"tv":2128.82,"id":9634485}]}]}
{"op":"mcm","clk":"4233559096","pt":1631536013940,"mc":[{"id":"1.187557759","rc":[{"batb":[[0,1.53,2.53],[1,1.5,432.79],[2,1.45,67.36]],"batl":[[0,2.16,347.55],[1,810,0.07],[2,2.16,0]],"ltp":1.66,"tv":2128.82,"id":9634485}]}]}
{"op":"mcm","clk":"4233559189","pt":1631536014935,"mc":[{"id":"1.187557759","rc":[{"batb":[[1,1.52,142.63],[2,1.51,90.19]],"batl":[[0,1.74,75.95],[1,1.76,103.65],[2,2.16,347.55]],"ltp":1.66,"tv":2128.82,"id":9634485}]}]}
{"op":"mcm","clk":"4233560205","pt":1631536026978,"mc":[{"id":"1.187557759","rc":[{"batb":[[1,1.5,432.79],[2,1.45,67.36]],"ltp":1.66,"tv":2128.82,"id":9634485}]}]}
{"op":"mcm","clk":"4233560358","pt":1631536028760,"mc":[{"id":"1.187557759","rc":[{"trd":[[1.53,1.18]],"batb":[[0,1.53,1.94]],"ltp":1.53,"tv":2130.0,"id":9634485}],"tv":3177.05}]}
{"op":"mcm","clk":"4233560442","pt":1631536029752,"mc":[{"id":"1.187557759","rc":[{"batb":[[0,1.69,121.34],[1,1.68,26.63],[2,1.67,149.11]],"batl":[[2,1.78,316.61]],"ltp":1.53,"tv":2130.0,"id":9634485},{"batb":[[0,2.36,9.27],[1,2.32,28.54]],"batl":[[0,2.42,5.86],[1,2.46,313.61],[2,2.56,46.87]],"ltp":2.5,"tv":1047.05,"id":9712888}]}]}
{"op":"mcm","clk":"4233560491","pt":1631536030376,"mc":[{"id":"1.187557759","rc":[{"trd":[[1.68,667.11],[1.69,321.72],[1.7,269.23]],"batb":[[0,1.67,8.88],[1,1.59,47.28],[2,1.53,1.94]],"ltp":1.68,"tv":2483.96,"id":9634485},{"trd":[[2.42,16.14],[2.46,48.06]],"batb":[[2,2.3,13.04]],"batl":[[0,2.46,279.68],[1,2.56,46.87],[2,2.8,3.57]],"ltp":2.46,"tv":1086.84,"id":9712888}],"tv":3570.8}]}
{"op":"mcm","clk":"4233560772","pt":1631536033401,"mc":[{"id":"1.187557759","rc":[{"batb":[[0,1.68,90.99],[1,1.67,8.88],[2,1.66,125.41]],"batl":[[0,1.74,112.52]],"ltp":1.68,"tv":2483.96,"id":9634485}]}]}
{"op":"mcm","clk":"4233561340","pt":1631536040192,"mc":[{"id":"1.187557759","rc":[{"batb":[[0,2.32,28.54],[1,2.3,13.04],[2,2.28,6.52]],"ltp":2.46,"tv":1086.84,"id":9712888}]}]}
{"op":"mcm","clk":"4233561581","pt":1631536043121,"mc":[{"id":"1.187557759","rc":[{"batl":[[0,1.72,10.78],[1,1.74,112.52],[2,1.76,103.65]],"ltp":1.68,"tv":2483.96,"id":9634485},{"batl":[[0,2.46,289.17]],"ltp":2.46,"tv":1086.84,"id":9712888}]}]}
{"op":"mcm","clk":"4233562295","pt":1631536052640,"mc":[{"id":"1.187557759","rc":[{"batb":[[0,1.53,1.94],[1,1.52,56.57],[2,1.5,432.79]],"batl":[[0,2.16,347.55],[1,1.74,0],[2,1.76,0]],"ltp":1.68,"tv":2483.96,"id":9634485},{"batb":[[0,2.2,33.14],[1,1.7,16.97],[2,1.6,99.04]],"ltp":2.46,"tv":1086.84,"id":9712888}]}]}
{"op":"mcm","clk":"4233562754","pt":1631536057770,"mc":[{"id":"1.187557759","rc":[{"batb":[[0,1.66,104.66],[1,1.65,64.51],[2,1.53,1.94]],"batl":[[0,1.72,111.64],[1,1.74,107.65],[2,2.16,347.55]],"ltp":1.68,"tv":2483.96,"id":9634485}]}]}
{"op":"mcm","clk":"4233563323","pt":1631536064374,"mc":[{"id":"1.187557759","rc":[{"batb":[[0,1.53,1.94],[1,1.52,56.57],[2,1.5,432.79]],"batl":[[0,2.16,347.55],[1,1.74,0],[2,2.16,0]],"ltp":1.68,"tv":2483.96,"id":9634485}]}]}
{"op":"mcm","clk":"4233563585","pt":1631536067347,"mc":[{"id":"1.187557759","rc":[{"batb":[[0,1.59,122.82],[1,1.58,75.7],[2,1.53,1.94]],"batl":[[0,1.8,67.78],[1,1.82,93.16],[2,2.16,347.55]],"ltp":1.68,"tv":2483.96,"id":9634485}]}]}
{"op":"mcm","clk":"4233564430","pt":1631536076868,"mc":[{"id":"1.187557759","rc":[{"batl":[[2,1.89,255.54]],"ltp":1.68,"tv":2483.96,"id":9634485}]}]}
{"op":"mcm","clk":"4233564881","pt":1631536082290,"mc":[{"id":"1.187557759","rc":[{"batl":[[0,1.89,255.54],[1,2.16,347.55],[2,1.89,0]],"ltp":1.68,"tv":2483.96,"id":9634485}]}]}
{"op":"mcm","clk":"4233565194","pt":1631536085717,"mc":[{"id":"1.187557759","rc":[{"trd":[[1.59,12.58]],"batb":[[0,1.6,9.81],[1,1.59,116.53],[2,1.58,75.7]],"batl":[[0,1.64,80.54],[1,1.65,64.22],[2,1.68,71.42]],"ltp":1.59,"tv":2496.54,"id":9634485},{"batb":[[0,2.6,7.14],[1,2.58,34.88],[2,2.56,17.45]],"batl":[[0,2.72,375.12]],"ltp":2.46,"tv":1086.84,"id":9712888}],"tv":3583.38}]}
{"op":"mcm","clk":"4233565284","pt":1631536086509,"mc":[{"id":"1.187557759","rc":[{"batb":[[1,2.58,11.62],[2,2.56,5.82]],"batl":[[1,2.76,10.88],[2,2.78,5.44]],"ltp":2.46,"tv":1086.84,"id":9712888}]}]}
{"op":"mcm","clk":"4233566250","pt":1631536098514,"mc":[{"id":"1.187557759","rc":[{"trd":[[1.64,63.83]],"batl":[[0,1.64,29.41]],"ltp":1.64,"tv":2547.67,"id":9634485},{"trd":[[2.56,52.55],[2.58,23.24],[2.6,14.28]],"batb":[[0,2.54,5.82],[1,2.5,23.18],[2,2.36,830.54]],"ltp":2.56,"tv":1168.76,"id":9712888}],"tv":3716.43}]}
{"op":"mcm","clk":"4233566302","pt":1631536099130,"mc":[{"id":"1.187557759","rc":[{"batb":[[1,1.59,73.64],[2,1.53,1.94]],"batl":[[0,1.65,64.22],[1,1.68,71.42],[2,1.89,255.54]],"ltp":1.64,"tv":2547.67,"id":9634485}]}]}
{"op":"mcm","clk":"4233566519","pt":1631536102042,"mc":[{"id":"1.187557759","rc":[{"batb":[[0,1.6,84.19]],"batl":[[0,1.65,119.57],[1,1.66,62.66],[2,1.68,71.42]],"ltp":1.64,"tv":2547.67,"id":9634485}]}]}
{"op":"mcm","clk":"4233567063","pt":1631536108640,"mc":[{"id":"1.187557759","rc":[{"batb":[[0,1.6,74.38]],"ltp":1.64,"tv":2547.67,"id":9634485}]}]}
{"op":"mcm","clk":"4233567362","pt":1631536111620,"mc":[{"id":"1.187557759","rc":[{"batl":[[0,1.64,12.05],[1,1.65,119.57],[2,1.66,62.66]],"ltp":1.64,"tv":2547.67,"id":9634485},{"batl":[[0,2.66,11.62],[1,2.72,375.12],[2,2.76,10.88]],"ltp":2.56,"tv":1168.76,"id":9712888}]}]}
{"op":"mcm","clk":"4233567749","pt":1631536116386,"mc":[{"id":"1.187557759","rc":[{"batl":[[0,1.65,119.57],[1,1.66,62.66],[2,1.89,255.54]],"ltp":1.64,"tv":2547.67,"id":9634485},{"batb":[[0,2.32,28.54],[1,1.8,11.88],[2,1.7,16.97]],"ltp":2.56,"tv":1168.76,"id":9712888}]}]}
{"op":"mcm","clk":"4233567797","pt":1631536116860,"mc":[{"id":"1.187557759","rc":[{"batb":[[0,1.53,1.94],[1,1.5,432.79],[2,1.43,73.05]],"batl":[[0,1.89,255.54],[1,2.16,347.55],[2,1.89,0]],"ltp":1.64,"tv":2547.67,"id":9634485}]}]}
{"op":"mcm","clk":"4233568037","pt":1631536119846,"mc":[{"id":"1.187557759","rc":[{"batb":[[1,1.43,73.05],[2,1.3,198.07]],"ltp":1.64,"tv":2547.67,"id":9634485}]}]}
{"op":"mcm","clk":"4233568123","pt":1631536120946,"mc":[{"id":"1.187557759","rc":[{"batb":[[0,1.57,125.44],[1,1.56,79.36],[2,1.53,1.94]],"batl":[[0,1.62,91.63],[1,1.63,66.91],[2,1.89,255.54]],"ltp":1.64,"tv":2547.67,"id":9634485}]}]}
{"op":"mcm","clk":"4233568725","pt":1631536128177,"mc":[{"id":"1.187557759","rc":[{"batb":[[0,1.53,1.94],[1,1.43,73.05],[2,1.4,457.22]],"batl":[[0,1.89,255.54],[1,2.16,347.55],[2,1.89,0]],"ltp":1.64,"tv":2547.67,"id":9634485}]}]}
{"op":"mcm","clk":"4233568955","pt":1631536131101,"mc":[{"id":"1.187557759","rc":[{"batb":[[1,1.48,165.83],[2,1.47,100.88]],"batl":[[0,1.74,89.96],[1,1.76,103.64],[2,1.89,255.54]],"ltp":1.64,"tv":2547.67,"id":9634485}]}]}
{"op":"mcm","clk":"4233569754","pt":1631536140604,"mc":[{"id":"1.187557759","rc":[{"batl":[[0,1.89,255.54],[1,2.16,347.55],[2,1.89,0]],"ltp":1.64,"tv":2547.67,"id":9634485}]}]}
{"op":"mcm","clk":"4233569830","pt":1631536141497,"mc":[{"id":"1.187557759","rc":[{"batl":[[1,2.16,0]],"ltp":1.64,"tv":2547.67,"id":9634485}]}]}
{"op":"mcm","clk":"4233570022","pt":1631536143799,"mc":[{"id":"1.187557759","rc":[{"trd":[[1.5,6.67],[1.53,3.12]],"batb":[[0,1.48,688.7],[1,1.47,100.88],[2,1.43,73.05]],"batl":[[0,1.52,9.34],[1,1.53,132.99],[2,1.54,82.19]],"ltp":1.5,"tv":2556.28,"id":9634485},{"trd":[[2.9,1.02],[3,3.34]],"batb":[[0,2.9,40.36],[1,2.88,31.25],[2,2.86,15.62]],"batl":[[0,3,2.88]],"ltp":3.0,"tv":1173.12,"id":9712888}],"tv":3729.4}]}
{"op":"mcm","clk":"4233570096","pt":1631536144787,"mc":[{"id":"1.187557759","rc":[{"batb":[[1,2.88,10.42],[2,2.86,5.2]],"batl":[[1,3.1,9.68],[2,3.15,4.84]],"ltp":3.0,"tv":1173.12,"id":9712888}]}]}
{"op":"mcm","clk":"4233570556","pt":1631536151510,"mc":[{"id":"1.187557759","rc":[{"batb":[[0,1.5,124],[1,1.48,688.7],[2,1.47,100.88]],"ltp":1.5,"tv":2556.28,"id":9634485}]}]}
{"op":"mcm","clk":"4233570681","pt":1631536153488,"mc":[{"id":"1.187557759","rc":[{"trd":[[1.52,2.64]],"batl":[[0,1.53,132.99],[1,1.54,82.19],[2,1.66,2024.71]],"ltp":1.52,"tv":2558.92,"id":9634485},{"trd":[[2.92,1.38]],"batl":[[0,3.1,9.68],[1,3.15,4.84],[2,3.2,4.84]],"ltp":2.92,"tv":1174.5,"id":9712888}],"tv":3733.42}]}
{"op":"mcm","clk":"4233570724","pt":1631536154337,"mc":[{"id":"1.187557759","rc":[{"trd":[[1.5,13.91]],"batb":[[0,1.5,120.38]],"ltp":1.5,"tv":2566.15,"id":9634485}],"tv":3740.66}]}
{"op":"mcm","clk":"4233570895","pt":1631536156396,"mc":[{"id":"1.187557759","rc":[{"batl":[[0,1.52,13.29],[1,1.53,132.99],[2,1.54,82.19]],"ltp":1.5,"tv":2566.15,"id":9634485},{"batl":[[0,3.05,11],[1,3.1,9.68],[2,3.15,4.84]],"ltp":2.92,"tv":1174.5,"id":9712888}]}]}
{"op":"mcm","clk":"4233570935","pt":1631536156929,"mc":[{"id":"1.187557759","rc":[{"batb":[[1,1.48,620.27],[2,1.43,73.05]],"ltp":1.5,"tv":2566.15,"id":9634485}]}]}
{"op":"mcm","clk":"4233571136","pt":1631536159826,"mc":[{"id":"1.187557759","rc":[{"batb":[[1,1.49,70.38],[2,1.48,620.27]],"ltp":1.5,"tv":2566.15,"id":9634485}]}]}
{"op":"mcm","clk":"4233571198","pt":1631536160656,"mc":[{"id":"1.187557759","rc":[{"batb":[[2,1.48,97.4]],"batl":[[0,1.53,132.99],[1,1.54,82.19],[2,1.89,255.54]],"ltp":1.5,"tv":2566.15,"id":9634485},{"batb":[[0,2.9,6.9],[1,2.88,5.21],[2,2.86,2.6]],"batl":[[0,3.1,4.84],[1,3.15,2.42],[2,3.2,2.42]],"ltp":2.92,"tv":1174.5,"id":9712888}]}]}
{"op":"mcm","clk":"4233571244","pt":1631536161239,"mc":[{"id":"1.187557759","rc":[{"batb":[[0,1.34,471.85],[1,1.32,103.6],[2,1.25,237.69]],"batl":[[0,1.89,255.54],[1,1.95,415.52],[2,1.89,0]],"ltp":1.5,"tv":2566.15,"id":9634485},{"batb":[[0,2.52,22.68],[1,1.8,11.88],[2,1.7,16.97]],"ltp":2.92,"tv":1174.5,"id":9712888}]}]}
{"op":"mcm","clk":"4233571438","pt":1631536163849,"mc":[{"id":"1.187557759","rc":[{"batb":[[0,1.36,167.84],[1,1.35,148.1],[2,1.34,471.85]],"batl":[[0,1.64,117.98],[1,1.65,63.99],[2,1.89,255.54]],"ltp":1.5,"tv":2566.15,"id":9634485}]}]}
{"op":"mcm","clk":"4233571521","pt":1631536164838,"mc":[{"id":"1.187557759","rc":[{"batb":[[0,1.34,471.85],[1,1.32,103.6],[2,1.25,237.69]],"batl":[[0,1.54,349.86],[1,1.89,255.54],[2,1.95,415.52]],"ltp":1.5,"tv":2566.15,"id":9634485}]}]}
{"op":"mcm","clk":"4233571550","pt":1631536165258,"mc":[{"id":"1.187557759","rc":[{"batb":[[0,1.46,109.28],[1,1.45,106.42],[2,1.34,471.85]],"batl":[[0,1.5,119.92],[1,1.51,88.74],[2,1.89,255.54]],"ltp":1.5,"tv":2566.15,"id":9634485}]}]}
{"op":"mcm","clk":"4233571861","pt":1631536169367,"mc":[{"id":"1.187557759","rc":[{"batb":[[0,1.34,471.85],[1,1.32,103.6],[2,1.25,237.69]],"batl":[[0,1.89,255.54],[1,1.95,415.52],[2,1.89,0]],"ltp":1.5,"tv":2566.15,"id":9634485}]}]}
{"op":"mcm","clk":"4233572131","pt":1631536172567,"mc":[{"id":"1.187557759","rc":[{"batb":[[0,1.36,167.84],[1,1.35,148.1],[2,1.34,471.85]],"ltp":1.5,"tv":2566.15,"id":9634485}]}]}
{"op":"mcm","clk":"4233572241","pt":1631536173765,"mc":[{"id":"1.187557759","rc":[{"batb":[[0,1.36,831.55],[2,1.32,103.6]],"batl":[[0,1.39,7.19],[1,1.4,10.42],[2,1.41,2382.24]],"ltp":1.5,"tv":2566.15,"id":9634485},{"batb":[[0,3.5,4.17],[1,3.45,57.98],[2,3.4,44.12]],"batl":[[0,3.7,9.62]],"ltp":2.92,"tv":1174.5,"id":9712888}]}]}
{"op":"mcm","clk":"4233572321","pt":1631536174759,"mc":[{"id":"1.187557759","rc":[{"batl":[[1,1.4,197.55],[2,1.41,117.13]],"ltp":1.5,"tv":2566.15,"id":9634485},{"batb":[[1,3.45,34.79],[2,3.4,26.47]],"batl":[[1,3.75,40],[2,3.8,20]],"ltp":2.92,"tv":1174.5,"id":9712888}]}]}
{"op":"mcm","clk":"4233572417","pt":1631536175785,"mc":[{"id":"1.187557759","rc":[{"batl":[[1,3.75,8],[2,3.8,4]],"ltp":2.92,"tv":1174.5,"id":9712888}]}]}
{"op":"mcm","clk":"4233572683","pt":1631536178779,"mc":[{"id":"1.187557759","rc":[{"batl":[[0,1.39,77.3]],"ltp":1.5,"tv":2566.15,"id":9634485},{"batl":[[2,3.8,36.85]],"ltp":2.92,"tv":1174.5,"id":9712888}]}]}
{"op":"mcm","clk":"4233572702","pt":1631536179089,"mc":[{"id":"1.187557759","rc":[{"batl":[[0,1.39,7.19]],"ltp":1.5,"tv":2566.15,"id":9634485},{"batl":[[2,3.8,4]],"ltp":2.92,"tv":1174.5,"id":9712888}]}]}
{"op":"mcm","clk":"4233572925","pt":1631536182073,"mc":[{"id":"1.187557759","rc":[{"batb":[[0,1.37,247],[1,1.36,831.55],[2,1.35,148.1]],"ltp":1.5,"tv":2566.15,"id":9634485}]}]}
{"op":"mcm","clk":"4233573284","pt":1631536186091,"mc":[{"id":"1.187557759","rc":[{"trd":[[1.39,14.38]],"batb":[[0,1.39,14.65],[1,1.37,247],[2,1.36,831.55]],"batl":[[0,1.4,197.55],[1,1.41,117.13],[2,1.82,475.58]],"ltp":1.39,"tv":2580.53,"id":9634485}],"tv":3755.04}]}
{"op":"mcm","clk":"4233573943","pt":1631536194702,"mc":[{"id":"1.187557759","rc":[{"batl":[[0,3.7,9.67]],"ltp":2.92,"tv":1174.5,"id":9712888}]}]}
{"op":"mcm","clk":"4233574406","pt":1631536200530,"mc":[{"id":"1.187557759","rc":[{"trd":[[1.4,3.56]],"batl":[[0,1.4,195.77]],"ltp":1.4,"tv":2584.09,"id":9634485}],"tv":3758.59}]}
{"op":"mcm","clk":"4233575152","pt":1631536208750,"mc":[{"id":"1.187557759","rc":[{"batb":[[0,1.37,247],[1,1.36,831.55],[2,1.35,148.1]],"ltp":1.4,"tv":2584.09,"id":9634485}]}]}
{"op":"mcm","clk":"4233575319","pt":1631536210746,"mc":[{"id":"1.187557759","rc":[{"batl":[[0,1.4,187.13]],"ltp":1.4,"tv":2584.09,"id":9634485},{"batb":[[0,3.45,34.79],[1,3.4,26.47],[2,3.35,13.24]],"batl":[[0,3.75,8.05],[1,3.8,4],[2,3.85,4]],"ltp":2.92,"tv":1174.5,"id":9712888}]}]}
{"op":"mcm","clk":"4233575415","pt":1631536211843,"mc":[{"id":"1.187557759","rc":[{"batb":[[0,1.4,14.65],[1,1.37,247],[2,1.36,663.71]],"batl":[[0,1.82,475.58],[1,1.89,255.54],[2,1.82,0]],"ltp":1.4,"tv":2584.09,"id":9634485}]}]}
{"op":"mcm","clk":"4233575584","pt":1631536213716,"mc":[{"id":"1.187557759","rc":[{"trd":[[1.4,27.74],[1.41,10]],"batb":[[0,1.38,11.76]],"ltp":1.4,"tv":2618.27,"id":9634485},{"trd":[[3.45,4.09],[3.5,2.05]],"batb":[[0,3.5,1.76],[1,3.45,30.7],[2,3.4,26.47]],"ltp":3.5,"tv":1180.64,"id":9712888}],"tv":3798.92}]}
{"op":"mcm","clk":"4233575669","pt":1631536214826,"mc":[{"id":"1.187557759","rc":[{"batl":[[0,1.46,160.06],[1,1.47,98.46],[2,1.82,475.58]],"ltp":1.4,"tv":2618.27,"id":9634485}]}]}
{"op":"mcm","clk":"4233575700","pt":1631536215239,"mc":[{"id":"1.187557759","rc":[{"trd":[[1.4,29.74]],"ltp":1.4,"tv":2620.27,"id":9634485},{"trd":[[3.5,2.85]],"batb":[[0,3.45,31.66],[1,3.4,26.47],[2,3.35,13.24]],"ltp":3.5,"tv":1181.44,"id":9712888}],"tv":3801.72}]}
{"op":"mcm","clk":"4233575857","pt":1631536217341,"mc":[{"id":"1.187557759","rc":[{"batl":[[0,3.75,8]],"ltp":3.5,"tv":1181.44,"id":9712888}]}]}
{"op":"mcm","clk":"4233576474","pt":1631536223928,"mc":[{"id":"1.187557759","rc":[{"batb":[[0,1.37,247],[1,1.36,663.71],[2,1.33,158.87]],"ltp":1.4,"tv":2620.27,"id":9634485},{"batb":[[0,3.45,30.7]],"ltp":3.5,"tv":1181.44,"id":9712888}]}]}
{"op":"mcm","clk":"4233576672","pt":1631536226475,"mc":[{"id":"1.187557759","rc":[{"batb":[[1,1.33,158.87],[2,1.32,165.71]],"ltp":1.4,"tv":2620.27,"id":9634485},{"batb":[[0,3,34.64],[1,2,11.88],[2,1.8,11.88]],"ltp":3.5,"tv":1181.44,"id":9712888}]}]}
{"op":"mcm","clk":"4233576763","pt":1631536227376,"mc":[{"id":"1.187557759","rc":[{"batb":[[0,1.33,158.87],[1,1.32,165.71],[2,1.29,116.15]],"ltp":1.4,"tv":2620.27,"id":9634485}]}]}
{"op":"mcm","clk":"4233577267","pt":1631536232674,"mc":[{"id":"1.187557759","rc":[{"batb":[[0,1.29,116.15],[1,1.28,492.6],[2,1.2,386.24]],"ltp":1.4,"tv":2620.27,"id":9634485}]}]}
{"op":"mcm","clk":"4233577337","pt":1631536233464,"mc":[{"id":"1.187557759","rc":[{"batb":[[1,1.2,386.24],[2,1.17,314.59]],"ltp":1.4,"tv":2620.27,"id":9634485},{"batl":[[0,3.5,0.05]],"ltp":3.5,"tv":1181.44,"id":9712888}]}]}
{"op":"mcm","clk":"4233577524","pt":1631536235658,"mc":[{"id":"1.187557759","rc":[{"batb":[[0,1.45,13.8],[1,1.43,20.98],[2,1.42,121.03]],"batl":[[1,1.47,109.39],[2,1.5,332.31]],"ltp":1.4,"tv":2620.27,"id":9634485},{"batb":[[0,3,200.79]],"batl":[[0,3.35,219.06],[1,3.8,2.68]],"ltp":3.5,"tv":1181.44,"id":9712888}]}]}
{"op":"mcm","clk":"4233577630","pt":1631536236793,"mc":[{"id":"1.187557759","rc":[{"trd":[[1.45,13.88]],"batb":[[0,1.45,6.86]],"ltp":1.45,"tv":2634.15,"id":9634485},{"batb":[[0,3.05,9.84],[1,3,205.71],[2,2.98,4.92]],"ltp":3.5,"tv":1181.44,"id":9712888}],"tv":3815.6}]}
{"op":"mcm","clk":"4233577942","pt":1631536240490,"mc":[{"id":"1.187557759","rc":[{"trd":[[1.45,27.6]],"batb":[[0,1.43,20.98],[1,1.42,121.03],[2,1.41,272.59]],"ltp":1.45,"tv":2647.87,"id":9634485}],"tv":3829.31}]}
{"op":"mcm","clk":"4233578200","pt":1631536243200,"mc":[{"id":"1.187557759","rc":[{"batb":[[0,1.45,149],[1,1.43,20.98],[2,1.42,121.03]],"ltp":1.45,"tv":2647.87,"id":9634485}]}]}
{"op":"mcm","clk":"4233578469","pt":1631536246496,"mc":[{"id":"1.187557759","rc":[{"batl":[[1,1.47,98.46]],"ltp":1.45,"tv":2647.87,"id":9634485}]}]}
{"op":"mcm","clk":"4233578721","pt":1631536249385,"mc":[{"id":"1.187557759","rc":[{"batb":[[1,1.44,13.11],[2,1.43,20.98]],"batl":[[0,1.46,172.6]],"ltp":1.45,"tv":2647.87,"id":9634485}]}]}
{"op":"mcm","clk":"4233578771","pt":1631536250104,"mc":[{"id":"1.187557759","rc":[{"batb":[[1,1.43,20.98],[2,1.42,121.03]],"batl":[[0,1.46,160.06]],"ltp":1.45,"tv":2647.87,"id":9634485}]}]}
{"op":"mcm","clk":"4233579236","pt":1631536256099,"mc":[{"id":"1.187557759","rc":[{"batb":[[1,1.44,13.11],[2,1.43,20.98]],"batl":[[0,1.46,172.6]],"ltp":1.45,"tv":2647.87,"id":9634485}]}]}
{"op":"mcm","clk":"4233579527","pt":1631536259821,"mc":[{"id":"1.187557759","rc":[{"batb":[[1,1.42,110.53],[2,1.41,120.25]],"batl":[[0,1.46,160.06],[2,1.82,475.58]],"ltp":1.45,"tv":2647.87,"id":9634485},{"batb":[[0,3,34.64],[1,2.76,17.74],[2,2,11.88]],"batl":[[0,3.5,0.05],[1,3.8,0]],"ltp":3.5,"tv":1181.44,"id":9712888}]}]}
{"op":"mcm","clk":"4233579562","pt":1631536260330,"mc":[{"id":"1.187557759","rc":[{"batb":[[0,1.33,99.16],[1,1.31,484.1],[2,1.2,386.24]],"batl":[[0,1.82,475.58],[1,1.89,255.54],[2,1.82,0]],"ltp":1.45,"tv":2647.87,"id":9634485},{"batb":[[0,2.76,17.74],[1,2,11.88],[2,1.8,11.88]],"ltp":3.5,"tv":1181.44,"id":9712888}]}]}
{"op":"mcm","clk":"4233579832","pt":1631536263605,"mc":[{"id":"1.187557759","rc":[{"batl":[[2,1000,2.17]],"ltp":1.45,"tv":2647.87,"id":9634485}]}]}
{"op":"mcm","clk":"4233579951","pt":1631536264808,"mc":[{"id":"1.187557759","rc":[{"batb":[[0,1.43,163.83],[1,1.42,117.02],[2,1.33,99.16]],"batl":[[0,1.47,98.84],[1,1.48,96.28],[2,1.82,475.58]],"ltp":1.45,"tv":2647.87,"id":9634485}]}]}
{"op":"mcm","clk":"4233580248","pt":1631536268439,"mc":[{"id":"1.187557759","rc":[{"batb":[[2,1.34,471.85]],"ltp":1.45,"tv":2647.87,"id":9634485}]}]}
{"op":"mcm","clk":"4233580488","pt":1631536271541,"mc":[{"id":"1.187557759","rc":[{"batb":[[0,1.44,106],[1,1.43,163.83],[2,1.42,117.02]],"ltp":1.45,"tv":2647.87,"id":9634485}]}]}
{"op":"mcm","clk":"4233580587","pt":1631536272825,"mc":[{"id":"1.187557759","rc":[{"batb":[[0,1.34,471.85],[1,1.33,99.16],[2,1.2,386.24]],"batl":[[0,1.82,475.58],[1,1.89,255.54],[2,810,0.07]],"ltp":1.45,"tv":2647.87,"id":9634485}]}]}
{"op":"mcm","clk":"4233580813","pt":1631536275342,"mc":[{"id":"1.187557759","rc":[{"batb":[[0,1.37,208.7],[1,1.36,143.39],[2,1.33,99.16]],"ltp":1.45,"tv":2647.87,"id":9634485}]}]}
{"op":"mcm","clk":"4233580950","pt":1631536276846,"mc":[{"id":"1.187557759","rc":[{"batb":[[0,1.38,546.28],[1,1.37,208.7],[2,1.36,143.39]],"batl":[[0,1.4,7.14],[1,1.41,12.33],[2,1.42,2351.88]],"ltp":1.45,"tv":2647.87,"id":9634485},{"batb":[[0,3.3,182.85],[1,2.76,17.74],[2,2,11.88]],"batl":[[0,3.55,5.6]],"ltp":3.5,"tv":1181.44,"id":9712888}]}]}
{"op":"mcm","clk":"4233581056","pt":1631536277843,"mc":[{"id":"1.187557759","rc":[{"batb":[[0,1.38,654.98],[1,1.37,263.06],[2,1.36,197.75]],"batl":[[1,1.41,146.16],[2,1.42,114.13]],"ltp":1.45,"tv":2647.87,"id":9634485},{"batl":[[1,4.1,2.44]],"ltp":3.5,"tv":1181.44,"id":9712888}]}]}
{"op":"mcm","clk":"4233581114","pt":1631536278535,"mc":[{"id":"1.187557759","rc":[{"batb":[[0,1.38,568.02],[1,1.37,219.58],[2,1.36,154.27]],"ltp":1.45,"tv":2647.87,"id":9634485},{"batb":[[1,3.25,28.87],[2,2.94,37.57]],"ltp":3.5,"tv":1181.44,"id":9712888}]}]}
{"op":"mcm","clk":"4233581619","pt":1631536285067,"mc":[{"id":"1.187557759","rc":[{"batb":[[0,1.39,171],[1,1.38,568.02],[2,1.37,219.58]],"ltp":1.45,"tv":2647.87,"id":9634485}]}]}
{"op":"mcm","clk":"4233581747","pt":1631536286887,"mc":[{"id":"1.187557759","rc":[{"trd":[[1.4,29.86]],"batl":[[0,1.4,7.02]],"ltp":1.4,"tv":2647.99,"id":9634485},{"trd":[[3.5,2.9]],"ltp":3.5,"tv":1181.49,"id":9712888}],"tv":3829.48}]}
{"op":"mcm","clk":"4233582527","pt":1631536295298,"mc":[{"id":"1.187557759","rc":[{"batb":[[0,1.29,114.73],[1,1.28,492.6],[2,1.2,386.24]],"batl":[[0,1.82,475.58],[1,1.89,255.54],[2,44,7.23]],"ltp":1.4,"tv":2647.99,"id":9634485},{"batb":[[0,2.94,37.57],[1,2,11.88],[2,1.8,11.88]],"ltp":3.5,"tv":1181.49,"id":9712888}]}]}
{"op":"mcm","clk":"4233582950","pt":1631536300410,"mc":[{"id":"1.187557759","rc":[{"batb":[[0,1.39,111.68],[1,1.38,132.68],[2,1.29,114.73]],"batl":[[0,1.42,85.22],[1,1.43,111.22],[2,1.82,475.58]],"ltp":1.4,"tv":2647.99,"id":9634485}]}]}
{"op":"mcm","clk":"4233583585","pt":1631536307440,"mc":[{"id":"1.187557759","rc":[{"batb":[[0,1.29,114.73],[1,1.28,492.6],[2,1.2,386.24]],"batl":[[0,1.82,475.58],[1,1.89,255.54],[2,44,7.23]],"ltp":1.4,"tv":2647.99,"id":9634485}]}]}
{"op":"mcm","clk":"4233583843","pt":1631536310402,"mc":[{"id":"1.187557759","rc":[{"batb":[[0,1.34,104.63],[1,1.33,158.63],[2,1.29,114.73]],"batl":[[0,1.48,89.65],[1,1.49,93.78],[2,1.82,475.58]],"ltp":1.4,"tv":2647.99,"id":9634485}]}]}
{"op":"mcm","clk":"4233584768","pt":1631536320726,"mc":[{"id":"1.187557759","rc":[{"batl":[[0,1.82,475.58],[1,1.89,255.54],[2,44,7.23]],"ltp":1.4,"tv":2647.99,"id":9634485}]}]}
{"op":"mcm","clk":"4233585051","pt":1631536323722,"mc":[{"id":"1.187557759","rc":[{"batb":[[0,1.34,631.44]],"batl":[[0,1.37,177.06],[1,1.38,129.42],[2,1.39,631.18]],"ltp":1.4,"tv":2647.99,"id":9634485},{"batb":[[0,3.65,8.22],[1,3.6,4.12],[2,3.55,4.12]],"batl":[[0,3.85,4.64]],"ltp":3.5,"tv":1181.49,"id":9712888}]}]}
{"op":"mcm","clk":"4233585155","pt":1631536324825,"mc":[{"id":"1.187557759","rc":[{"batl":[[1,4.1,7.32],[2,4.2,3.66]],"ltp":3.5,"tv":1181.49,"id":9712888}]}]}
{"op":"mcm","clk":"4233585566","pt":1631536329265,"mc":[{"id":"1.187557759","rc":[{"batb":[[0,1.35,120],[1,1.34,631.44],[2,1.33,158.63]],"ltp":1.4,"tv":2647.99,"id":9634485}]}]}
{"op":"mcm","clk":"4233586107","pt":1631536335299,"mc":[{"id":"1.187557759","rc":[{"batb":[[0,1.34,631.44],[1,1.33,158.63],[2,1.29,114.73]],"ltp":1.4,"tv":2647.99,"id":9634485}]}]}
{"op":"mcm","clk":"4233586363","pt":1631536338504,"mc":[{"id":"1.187557759","rc":[{"batb":[[0,1.36,380],[1,1.34,631.44],[2,1.33,158.63]],"ltp":1.4,"tv":2647.99,"id":9634485}]}]}
{"op":"mcm","clk":"4233587288","pt":1631536348709,"mc":[{"id":"1.187557759","rc":[{"trd":[[1.36,5.11]],"batb":[[0,1.36,377.45],[1,1.29,114.73],[2,1.28,492.6]],"batl":[[0,1.82,475.58],[1,1.89,255.54],[2,44,7.23]],"ltp":1.36,"tv":2653.09,"id":9634485},{"batb":[[0,3.5,23.68],[1,3.2,30.21],[2,2,11.88]],"ltp":3.5,"tv":1181.49,"id":9712888}],"tv":3834.59}]}
{"op":"mcm","clk":"4233587345","pt":1631536349293,"mc":[{"id":"1.187557759","rc":[{"batb":[[0,1.28,492.6],[1,1.27,127.86],[2,1.17,314.59]],"ltp":1.36,"tv":2653.09,"id":9634485},{"batb":[[0,3.2,30.21],[1,2,11.88],[2,1.8,11.88]],"ltp":3.5,"tv":1181.49,"id":9712888}]}]}
{"op":"mcm","clk":"4233587555","pt":1631536351720,"mc":[{"id":"1.187557759","rc":[{"batb":[[0,1.31,132.19],[1,1.3,179.15],[2,1.28,492.6]],"batl":[[0,1.43,182.13],[1,1.44,107.05],[2,1.82,475.58]],"ltp":1.36,"tv":2653.09,"id":9634485}]}]}
{"op":"mcm","clk":"4233587860","pt":1631536355109,"mc":[{"id":"1.187557759","rc":[{"batl":[[0,1.43,182.18]],"ltp":1.36,"tv":2653.09,"id":9634485}]}]}
{"op":"mcm","clk":"4233588733","pt":1631536365734,"mc":[{"id":"1.187557759","rc":[{"trd":[[1.35,0.05]],"batl":[[0,1.43,182.13]],"ltp":1.35,"tv":2653.14,"id":9634485},{"trd":[[3.85,0.02]],"ltp":3.85,"tv":1181.51,"id":9712888}],"tv":3834.65}]}
{"op":"mcm","clk":"4233589016","pt":1631536369033,"mc":[{"id":"1.187557759","rc":[{"batb":[[0,1.28,492.6],[1,1.27,127.86],[2,1.17,314.59]],"batl":[[0,1.82,475.58],[1,1.89,255.54],[2,44,7.23]],"ltp":1.35,"tv":2653.14,"id":9634485}]}]}
{"op":"mcm","clk":"4233589326","pt":1631536371651,"mc":[{"id":"1.187557759","rc":[{"batb":[[0,1.4,10.74],[1,1.39,1964.57],[2,1.38,197.1]],"batl":[[0,1.45,187.58],[1,1.46,182.06],[2,1.47,182.06]],"ltp":1.35,"tv":2653.14,"id":9634485},{"batb":[[0,3.35,6.51],[1,3.2,272.8],[2,2,11.88]],"batl":[[0,3.5,4.3],[1,3.55,203.68],[2,4,2.5]],"ltp":3.85,"tv":1181.51,"id":9712888}]}]}
{"op":"mcm","clk":"4233589435","pt":1631536372646,"mc":[{"id":"1.187557759","rc":[{"batb":[[1,1.39,285.19],[2,1.38,231.4]],"batl":[[0,1.41,7.09],[1,1.43,182.13],[2,1.44,107.05]],"ltp":1.35,"tv":2653.14,"id":9634485},{"batb":[[2,2.8,42.76]],"ltp":3.85,"tv":1181.51,"id":9712888}]}]}
{"op":"mcm","clk":"4233589835","pt":1631536376660,"mc":[{"id":"1.187557759","rc":[{"batl":[[1,1.42,96.54],[2,1.43,182.13]],"ltp":1.35,"tv":2653.14,"id":9634485},{"batl":[[2,3.65,36.12]],"ltp":3.85,"tv":1181.51,"id":9712888}]}]}
{"op":"mcm","clk":"4233589863","pt":1631536376928,"mc":[{"id":"1.187557759","rc":[{"batl":[[1,1.43,182.13],[2,1.44,107.05]],"ltp":1.35,"tv":2653.14,"id":9634485},{"batl":[[2,4,2.5]],"ltp":3.85,"tv":1181.51,"id":9712888}]}]}
{"op":"mcm","clk":"4233590123","pt":1631536379852,"mc":[{"id":"1.187557759","rc":[{"batb":[[0,1.4,168.74]],"ltp":1.35,"tv":2653.14,"id":9634485}]}]}
{"op":"mcm","clk":"4233590462","pt":1631536383766,"mc":[{"id":"1.187557759","rc":[{"batb":[[1,1.39,126.41]],"ltp":1.35,"tv":2653.14,"id":9634485}]}]}
{"op":"mcm","clk":"4233591889","pt":1631536400595,"mc":[{"id":"1.187557759","rc":[{"batb":[[0,1.4,158],[1,1.31,484.1],[2,1.3,113.39]],"batl":[[0,1.82,475.58],[1,1.89,255.54],[2,44,7.23]],"ltp":1.35,"tv":2653.14,"id":9634485},{"batb":[[0,2.8,42.76],[1,2,11.88],[2,1.8,11.88]],"ltp":3.85,"tv":1181.51,"id":9712888}]}]}
{"op":"mcm","clk":"4233591952","pt":1631536401326,"mc":[{"id":"1.187557759","rc":[{"batb":[[0,1.31,484.1],[1,1.3,113.39],[2,1.17,314.59]],"ltp":1.35,"tv":2653.14,"id":9634485}]}]}
{"op":"mcm","clk":"4233592151","pt":1631536403504,"mc":[{"id":"1.187557759","rc":[{"batb":[[0,1.34,139.63],[1,1.33,159.15],[2,1.31,484.1]],"batl":[[0,1.52,92.51],[1,1.53,84.51],[2,1.82,475.58]],"ltp":1.35,"tv":2653.14,"id":9634485}]}]}
{"op":"mcm","clk":"4233592529","pt":1631536408296,"mc":[{"id":"1.187557759","rc":[{"batb":[[0,1.31,484.1],[1,1.3,113.39],[2,1.17,314.59]],"ltp":1.35,"tv":2653.14,"id":9634485}]}]}
{"op":"mcm","clk":"4233592683","pt":1631536410319,"mc":[{"id":"1.187557759","rc":[{"batb":[[0,1.3,113.39],[1,1.17,314.59],[2,1.15,356.53]],"ltp":1.35,"tv":2653.14,"id":9634485}]}]}
{"op":"mcm","clk":"4233592768","pt":1631536411313,"mc":[{"id":"1.187557759","rc":[{"batb":[[0,1.49,134.22],[1,1.48,119.33],[2,1.47,120.93]],"batl":[[0,1.52,107.79],[2,1.56,564.91]],"ltp":1.35,"tv":2653.14,"id":9634485},{"batl":[[0,3.05,9.93],[1,3.1,238.61],[2,3.5,2.86]],"ltp":3.85,"tv":1181.51,"id":9712888}]}]}
{"op":"mcm","clk":"4233592870","pt":1631536412302,"mc":[{"id":"1.187557759","rc":[{"trd":[[1.49,13.42]],"batb":[[0,1.49,127.51]],"ltp":1.49,"tv":2666.56,"id":9634485},{"batb":[[0,2.9,10.34],[1,2.88,5.18],[2,2.86,5.18]],"ltp":3.85,"tv":1181.51,"id":9712888}],"tv":3848.07}]}
{"op":"mcm","clk":"4233593201","pt":1631536416077,"mc":[{"id":"1.187557759","rc":[{"trd":[[1.49,54.35]],"batb":[[0,1.49,107.05]],"ltp":1.49,"tv":2707.49,"id":9634485}],"tv":3889.0}]}
{"op":"mcm","clk":"4233594520","pt":1631536429621,"mc":[{"id":"1.187557759","rc":[{"trd":[[1.49,268.47]],"batb":[[0,1.48,119.33],[1,1.47,120.93],[2,1.46,10.2]],"batl":[[0,1.49,106.73],[1,1.52,107.79],[2,1.53,84.51]],"ltp":1.49,"tv":2921.61,"id":9634485}],"tv":4103.12}]}
{"op":"mcm","clk":"4233594792","pt":1631536432754,"mc":[{"id":"1.187557759","rc":[{"trd":[[1.49,311.26]],"batb":[[0,1.35,93.14],[1,1.34,471.85],[2,1.17,314.59]],"batl":[[0,1.49,85.33],[1,1.82,475.58],[2,1.89,255.54]],"ltp":1.49,"tv":2964.4,"id":9634485},{"batb":[[0,2.42,25.27],[1,2,11.88],[2,1.8,11.88]],"ltp":3.85,"tv":1181.51,"id":9712888}],"tv":4145.91}]}
{"op":"mcm","clk":"4233595010","pt":1631536435359,"mc":[{"id":"1.187557759","rc":[{"batb":[[0,1.4,106.24],[1,1.39,128.26],[2,1.35,93.14]],"batl":[[1,1.69,116.33],[2,1.71,113.9]],"ltp":1.49,"tv":2964.4,"id":9634485}]}]}
{"op":"mcm","clk":"4233595155","pt":1631536436721,"mc":[{"id":"1.187557759","rc":[{"batb":[[0,1.35,93.14],[1,1.34,471.85],[2,1.17,314.59]],"ltp":1.49,"tv":2964.4,"id":9634485}]}]}
{"op":"mcm","clk":"4233595242","pt":1631536437756,"mc":[{"id":"1.187557759","rc":[{"batb":[[1,1.17,314.59],[2,1.15,356.53]],"ltp":1.49,"tv":2964.4,"id":9634485}]}]}
{"op":"mcm","clk":"4233595434","pt":1631536439734,"mc":[{"id":"1.187557759","rc":[{"trd":[[1.49,481.91]],"batb":[[0,1.64,1394.41],[1,1.63,120.09],[2,1.62,68.89]],"batl":[[0,1.66,9.19]],"ltp":1.49,"tv":3135.05,"id":9634485},{"batb":[[1,2.4,312.46],[2,2.38,57.14]],"batl":[[0,2.6,63.96],[1,2.62,50.76],[2,2.64,50.76]],"ltp":3.85,"tv":1181.51,"id":9712888}],"tv":4316.56}]}
{"op":"mcm","clk":"4233595532","pt":1631536440723,"mc":[{"id":"1.187557759","rc":[{"trd":[[1.64,76.17]],"batb":[[0,1.64,111.08]],"ltp":1.64,"tv":3147.39,"id":9634485}],"tv":4328.9}]}
{"op":"mcm","clk":"4233595899","pt":1631536444529,"mc":[{"id":"1.187557759","rc":[{"batb":[[0,1.64,208.08]],"ltp":1.64,"tv":3147.39,"id":9634485}]}]}
{"op":"mcm","clk":"4233596545","pt":1631536451488,"mc":[{"id":"1.187557759","rc":[{"batb":[[0,1.64,97]],"ltp":1.64,"tv":3147.39,"id":9634485}]}]}
{"op":"mcm","clk":"4233596885","pt":1631536455396,"mc":[{"id":"1.187557759","rc":[{"trd":[[1.64,79.21]],"batb":[[0,1.64,95.48]],"ltp":1.64,"tv":3150.43,"id":9634485}],"tv":4331.94}]}
{"op":"mcm","clk":"4233598031","pt":1631536467263,"mc":[{"id":"1.187557759","rc":[{"batl":[[2,1.71,113.95]],"ltp":1.64,"tv":3150.43,"id":9634485}]}]}
{"op":"mcm","clk":"4233602468","pt":1631536515185,"mc":[{"id":"1.187557759","rc":[{"trd":[[1.64,79.47]],"batb":[[0,1.64,95.35]],"ltp":1.64,"tv":3150.69,"id":9634485}],"tv":4332.2}]}
{"op":"mcm","clk":"4233604232","pt":1631536534227,"mc":[{"id":"1.187557759","rc":[{"batb":[[0,1.47,63.76],[1,1.44,442.2],[2,1.43,1.7]],"batl":[[0,1.89,255.58],[1,2.16,347.55],[2,44,7.23]],"ltp":1.64,"tv":3150.69,"id":9634485},{"batb":[[0,2.28,29.87],[1,1.8,11.88],[2,1.7,16.97]],"ltp":3.85,"tv":1181.51,"id":9712888}]}]}
{"op":"mcm","clk":"4233604527","pt":1631536537249,"mc":[{"id":"1.187557759","rc":[{"batb":[[0,1.55,67.41],[1,1.54,83.11],[2,1.47,63.76]],"batl":[[0,1.76,88.21],[1,1.78,99.87],[2,1.89,255.54]],"ltp":1.64,"tv":3150.69,"id":9634485}]}]}
{"op":"mcm","clk":"4233606048","pt":1631536553353,"mc":[{"id":"1.187557759","rc":[{"batl":[[0,1.89,255.58],[1,2.16,347.55],[2,44,7.23]],"ltp":1.64,"tv":3150.69,"id":9634485}]}]}
{"op":"mcm","clk":"4233606246","pt":1631536555079,"mc":[{"id":"1.187557759","rc":[{"batl":[[1,44,7.23],[2,810,0.07]],"ltp":1.64,"tv":3150.69,"id":9634485}]}]}
{"op":"mcm","clk":"4233606407","pt":1631536556750,"mc":[{"id":"1.187557759","rc":[{"trd":[[1.55,12.98]],"batb":[[0,1.54,83.11],[1,1.47,63.76],[2,1.43,1.7]],"batl":[[0,1.58,20.42],[1,1.59,90.67],[2,1.6,71.52]],"ltp":1.55,"tv":3163.67,"id":9634485},{"batb":[[0,2.7,11.12],[1,2.68,5.56],[2,2.66,5.56]],"batl":[[0,2.84,7.74],[1,2.92,325.54]],"ltp":3.85,"tv":1181.51,"id":9712888}],"tv":4345.18}]}
{"op":"mcm","clk":"4233606460","pt":1631536557273,"mc":[{"id":"1.187557759","rc":[{"batl":[[1,2.92,335.82],[2,2.94,5.14]],"ltp":3.85,"tv":1181.51,"id":9712888}]}]}
{"op":"mcm","clk":"4233606649","pt":1631536559275,"mc":[{"id":"1.187557759","rc":[{"batb":[[0,1.54,147.35],[1,1.53,85.69],[2,1.47,63.76]],"ltp":1.55,"tv":3163.67,"id":9634485}]}]}
{"op":"mcm","clk":"4233606785","pt":1631536560842,"mc":[{"id":"1.187557759","rc":[{"batl":[[0,1.57,58.4],[1,1.58,20.42],[2,1.59,90.67]],"ltp":1.55,"tv":3163.67,"id":9634485},{"batl":[[1,2.92,381.52]],"ltp":3.85,"tv":1181.51,"id":9712888}]}]}
{"op":"mcm","clk":"4233606816","pt":1631536561155,"mc":[{"id":"1.187557759","rc":[{"batl":[[0,1.58,20.42],[1,1.59,90.67],[2,1.6,71.52]],"ltp":1.55,"tv":3163.67,"id":9634485},{"batl":[[1,2.92,335.82]],"ltp":3.85,"tv":1181.51,"id":9712888}]}]}
{"op":"mcm","clk":"4233608272","pt":1631536576807,"mc":[{"id":"1.187557759","rc":[{"batl":[[0,1.59,90.67],[1,1.6,71.52],[2,1.89,255.54]],"ltp":1.55,"tv":3163.67,"id":9634485},{"batb":[[0,2.64,20.08],[1,2.46,24.6],[2,1.8,11.88]],"ltp":3.85,"tv":1181.51,"id":9712888}]}]}
{"op":"mcm","clk":"4233608302","pt":1631536577072,"mc":[{"id":"1.187557759","rc":[{"batb":[[0,1.43,1.7],[1,1.4,79.16],[2,1.38,454.63]],"batl":[[0,1.89,255.54],[1,2.04,388.3],[2,44,7.23]],"ltp":1.55,"tv":3163.67,"id":9634485},{"batb":[[0,2.46,24.6],[1,1.8,11.88],[2,1.7,16.97]],"ltp":3.85,"tv":1181.51,"id":9712888}]}]}
{"op":"mcm","clk":"4233608719","pt":1631536581621,"mc":[{"id":"1.187557759","rc":[{"batb":[[0,1.53,77.44],[1,1.52,87.54],[2,1.43,1.7]],"batl":[[0,1.57,94.23],[1,1.58,74.88],[2,1.89,255.54]],"ltp":1.55,"tv":3163.67,"id":9634485}]}]}
{"op":"mcm","clk":"4233609002","pt":1631536584811,"mc":[{"id":"1.187557759","rc":[{"batb":[[0,1.43,1.7],[1,1.4,79.16],[2,1.38,454.63]],"batl":[[0,1.89,255.54],[1,2.04,388.3],[2,44,7.23]],"ltp":1.55,"tv":3163.67,"id":9634485}]}]}
{"op":"mcm","clk":"4233609261","pt":1631536587702,"mc":[{"id":"1.187557759","rc":[{"batb":[[0,1.46,84.63],[1,1.45,106.25],[2,1.43,1.7]],"batl":[[0,1.67,107.51],[1,1.69,118.62],[2,1.89,255.54]],"ltp":1.55,"tv":3163.67,"id":9634485}]}]}
{"op":"mcm","clk":"4233609349","pt":1631536588826,"mc":[{"id":"1.187557759","rc":[{"batb":[[0,1.43,1.7],[1,1.4,79.16],[2,1.38,454.63]],"batl":[[0,1.89,255.54],[1,2.04,388.3],[2,44,7.23]],"ltp":1.55,"tv":3163.67,"id":9634485}]}]}
{"op":"mcm","clk":"4233609506","pt":1631536590708,"mc":[{"id":"1.187557759","rc":[{"batb":[[2,1.37,2.63]],"batl":[[1,44,7.23],[2,44,0]],"ltp":1.55,"tv":3163.67,"id":9634485}]}]}
{"op":"mcm","clk":"4233609608","pt":1631536591804,"mc":[{"id":"1.187557759","rc":[{"batb":[[0,1.46,96.71],[1,1.45,106.25],[2,1.43,1.7]],"batl":[[0,1.47,6.8],[1,1.48,12.13],[2,1.5,143.34]],"ltp":1.55,"tv":3163.67,"id":9634485},{"batb":[[0,3,70],[1,2.98,15],[2,2.96,15]],"batl":[[0,3.25,210.95]],"ltp":3.85,"tv":1181.51,"id":9712888}]}]}
{"op":"mcm","clk":"4233609690","pt":1631536592696,"mc":[{"id":"1.187557759","rc":[{"batb":[[2,1.44,20.84]],"ltp":1.55,"tv":3163.67,"id":9634485},{"batb":[[0,3,50],[1,2.98,5],[2,2.96,5]],"batl":[[1,3.6,2.78]],"ltp":3.85,"tv":1181.51,"id":9712888}]}]}
{"op":"mcm","clk":"4233610061","pt":1631536596607,"mc":[{"id":"1.187557759","rc":[{"batb":[[0,1.46,212.71]],"ltp":1.55,"tv":3163.67,"id":9634485}]}]}
{"op":"mcm","clk":"4233611412","pt":1631536611843,"mc":[{"id":"1.187557759","rc":[{"batb":[[0,1.46,200.63],[2,1.4,79.16]],"batl":[[0,1.5,143.34],[1,1.51,88.62],[2,1.89,696.82]],"ltp":1.55,"tv":3163.67,"id":9634485},{"batb":[[0,2.9,38.83],[1,2.7,19],[2,1.8,11.88]],"ltp":3.85,"tv":1181.51,"id":9712888}]}]}
{"op":"mcm","clk":"4233611457","pt":1631536612263,"mc":[{"id":"1.187557759","rc":[{"batb":[[0,1.37,2.63],[1,1.33,98.83],[2,1.31,484.1]],"batl":[[0,1.89,696.82],[1,44,7.23],[2,1.89,0]],"ltp":1.55,"tv":3163.67,"id":9634485},{"batb":[[0,2.7,19],[1,1.8,11.88],[2,1.7,16.97]],"ltp":3.85,"tv":1181.51,"id":9712888}]}]}
{"op":"mcm","clk":"4233611717","pt":1631536614826,"mc":[{"id":"1.187557759","rc":[{"batb":[[0,1.38,156.62],[1,1.37,140.5],[2,1.33,98.83]],"batl":[[0,1.56,76.18],[1,1.57,76.76],[2,1.89,696.82]],"ltp":1.55,"tv":3163.67,"id":9634485}]}]}
{"op":"mcm","clk":"4233613219","pt":1631536627465,"mc":[{"id":"1.187557759","rc":[{"batb":[[0,1.37,2.63],[1,1.33,98.83],[2,1.31,484.1]],"ltp":1.55,"tv":3163.67,"id":9634485}]}]}
{"op":"mcm","clk":"4233613269","pt":1631536628294,"mc":[{"id":"1.187557759","rc":[{"batb":[[2,1.25,237.69]],"ltp":1.55,"tv":3163.67,"id":9634485}]}]}
{"op":"mcm","clk":"4233613370","pt":1631536629697,"mc":[{"id":"1.187557759","rc":[{"batb":[[0,1.5,528.92],[1,1.49,50],[2,1.48,50]],"batl":[[2,1.58,446.16]],"ltp":1.55,"tv":3163.67,"id":9634485},{"batb":[[0,2.84,6],[1,2.7,19],[2,1.8,11.88]],"batl":[[0,2.92,6.35],[1,3,147.79],[2,3.35,2.99]],"ltp":3.85,"tv":1181.51,"id":9712888}]}]}
{"op":"mcm","clk":"4233613444","pt":1631536630688,"mc":[{"id":"1.187557759","rc":[{"trd":[[1.52,15.8]],"batb":[[0,1.52,97.11],[1,1.51,90.03],[2,1.5,448.92]],"ltp":1.52,"tv":3176.83,"id":9634485},{"batb":[[1,2.78,53.96],[2,2.76,26.98]],"ltp":3.85,"tv":1181.51,"id":9712888}],"tv":4358.34}]}
{"op":"mcm","clk":"4233613479","pt":1631536631338,"mc":[{"id":"1.187557759","rc":[{"batb":[[1,2.78,10.8],[2,2.76,5.4]],"ltp":3.85,"tv":1181.51,"id":9712888}]}]}
{"op":"mcm","clk":"4233613742","pt":1631536634668,"mc":[{"id":"1.187557759","rc":[{"batl":[[0,1.54,49.84],[1,1.56,76.18],[2,1.57,76.76]],"ltp":1.52,"tv":3176.83,"id":9634485},{"batl":[[1,3,186.2]],"ltp":3.85,"tv":1181.51,"id":9712888}]}]}
{"op":"mcm","clk":"4233613759","pt":1631536634871,"mc":[{"id":"1.187557759","rc":[{"batl":[[0,1.56,76.18],[1,1.57,76.76],[2,1.58,446.16]],"ltp":1.52,"tv":3176.83,"id":9634485},{"batl":[[1,3,147.79]],"ltp":3.85,"tv":1181.51,"id":9712888}]}]}
{"op":"mcm","clk":"4233614856","pt":1631536649499,"mc":[{"id":"1.187557759","rc":[{"batb":[[0,1.52,59],[1,1.38,454.63],[2,1.37,89.91]],"batl":[[0,1.89,696.82],[1,44,7.23],[2,1.58,0]],"ltp":1.52,"tv":3176.83,"id":9634485},{"batb":[[0,2.48,24.02],[1,1.8,11.88],[2,1.7,16.97]],"ltp":3.85,"tv":1181.51,"id":9712888}]}]}
{"op":"mcm","clk":"4233614917","pt":1631536650305,"mc":[{"id":"1.187557759","rc":[{"batb":[[0,1.38,454.63],[1,1.37,89.91],[2,1.25,237.69]],"ltp":1.52,"tv":3176.83,"id":9634485}]}]}
{"op":"mcm","clk":"4233615197","pt":1631536653644,"mc":[{"id":"1.187557759","rc":[{"batb":[[0,1.5,94.65],[1,1.49,94.97],[2,1.38,454.63]],"batl":[[0,1.54,99.81],[1,1.55,80.43],[2,1.89,696.82]],"ltp":1.52,"tv":3176.83,"id":9634485}]}]}
{"op":"mcm","clk":"4233615613","pt":1631536658621,"mc":[{"id":"1.187557759","rc":[{"batb":[[0,1.38,454.63],[1,1.37,87.28],[2,1.25,237.69]],"batl":[[0,1.89,696.82],[1,44,7.23],[2,1.89,0]],"ltp":1.52,"tv":3176.83,"id":9634485}]}]}
{"op":"mcm","clk":"4233615827","pt":1631536661552,"mc":[{"id":"1.187557759","rc":[{"batb":[[0,1.42,128.28],[1,1.41,120.49],[2,1.38,454.63]],"batl":[[0,1.65,87.22],[1,1.66,62.8],[2,1.89,696.82]],"ltp":1.52,"tv":3176.83,"id":9634485}]}]}
{"op":"mcm","clk":"4233615884","pt":1631536662336,"mc":[{"id":"1.187557759","rc":[{"batb":[[0,1.38,454.63],[1,1.37,87.28],[2,1.25,237.69]],"batl":[[0,1.89,696.82],[1,44,7.23],[2,1.89,0]],"ltp":1.52,"tv":3176.83,"id":9634485}]}]}
{"op":"mcm","clk":"4233615929","pt":1631536662914,"mc":[{"id":"1.187557759","rc":[{"batb":[[0,1.37,87.28],[1,1.25,237.69],[2,1.2,386.24]],"ltp":1.52,"tv":3176.83,"id":9634485}]}]}
{"op":"mcm","clk":"4233616119","pt":1631536665542,"mc":[{"id":"1.187557759","rc":[{"batb":[[0,1.42,128.28],[1,1.41,120.49],[2,1.4,406.6]],"batl":[[0,1.44,6.94],[1,1.46,205.28],[2,1.47,129.49]],"ltp":1.52,"tv":3176.83,"id":9634485},{"batb":[[0,3.25,5.33],[1,2.48,24.02],[2,1.8,11.88]],"batl":[[0,3.35,5.7],[1,3.5,162.64]],"ltp":3.85,"tv":1181.51,"id":9712888}]}]}
{"op":"mcm","clk":"4233616233","pt":1631536666848,"mc":[{"id":"1.187557759","rc":[{"batb":[[1,1.41,141.77],[2,1.4,417.24]],"batl":[[1,1.46,164.18],[2,1.47,108.95]],"ltp":1.52,"tv":3176.83,"id":9634485},{"batb":[[1,3.05,34.14],[2,2.78,17.49]],"batl":[[2,3.8,2.63]],"ltp":3.85,"tv":1181.51,"id":9712888}]}]}
{"op":"mcm","clk":"4233616799","pt":1631536673381,"mc":[{"id":"1.187557759","rc":[{"batb":[[0,1.42,200.28]],"ltp":1.52,"tv":3176.83,"id":9634485}]}]}
{"op":"mcm","clk":"4233617715","pt":1631536682473,"mc":[{"id":"1.187557759","rc":[{"batb":[[1,1.41,120.49],[2,1.37,87.28]],"batl":[[0,1.46,143.64],[1,1.47,98.67],[2,1.89,696.82]],"ltp":1.52,"tv":3176.83,"id":9634485},{"batb":[[0,3.05,34.14],[1,2.78,17.49],[2,2,11.88]],"ltp":3.85,"tv":1181.51,"id":9712888}]}]}
{"op":"mcm","clk":"4233617799","pt":1631536683386,"mc":[{"id":"1.187557759","rc":[{"batb":[[0,1.31,484.1],[1,1.3,110.12],[2,1.2,386.24]],"batl":[[0,1.89,696.82],[1,44,7.23],[2,1.89,0]],"ltp":1.52,"tv":3176.83,"id":9634485},{"batb":[[0,2.78,17.49],[1,2,11.88],[2,1.8,11.88]],"ltp":3.85,"tv":1181.51,"id":9712888}]}]}
{"op":"mcm","clk":"4233617984","pt":1631536685802,"mc":[{"id":"1.187557759","rc":[{"batb":[[0,1.34,223.77],[1,1.33,160.46],[2,1.31,484.1]],"batl":[[0,1.53,150.92],[1,1.54,82.12],[2,1.89,696.82]],"ltp":1.52,"tv":3176.83,"id":9634485}]}]}
{"op":"mcm","clk":"4233619558","pt":1631536703219,"mc":[{"id":"1.187557759","rc":[{"batl":[[0,1.89,696.82],[1,44,7.23],[2,1.89,0]],"ltp":1.52,"tv":3176.83,"id":9634485}]}]}
{"op":"mcm","clk":"4233619849","pt":1631536706616,"mc":[{"id":"1.187557759","rc":[{"batb":[[0,1.34,152.43],[1,1.3,110.12],[2,1.17,314.59]],"batl":[[0,1.37,23.45],[1,1.38,153.41],[2,1.39,135.97]],"ltp":1.52,"tv":3176.83,"id":9634485},{"batb":[[0,3.65,54.8],[1,3.5,129.25],[2,2.78,17.49]],"batl":[[0,3.85,5.8],[1,4,257.04]],"ltp":3.85,"tv":1181.51,"id":9712888}]}]}
{"op":"mcm","clk":"4233619942","pt":1631536707508,"mc":[{"id":"1.187557759","rc":[{"batb":[[2,1.27,125.86]],"ltp":1.52,"tv":3176.83,"id":9634485},{"batb":[[2,3.45,25.02]],"batl":[[1,4,264.54],[2,4.1,3.76]],"ltp":3.85,"tv":1181.51,"id":9712888}]}]}
{"op":"mcm","clk":"4233620130","pt":1631536709541,"mc":[{"id":"1.187557759","rc":[{"batb":[[0,1.35,109.42],[1,1.34,152.43],[2,1.3,110.12]],"ltp":1.52,"tv":3176.83,"id":9634485}]}]}
{"op":"mcm","clk":"4233620395","pt":1631536712737,"mc":[{"id":"1.187557759","rc":[{"batb":[[0,1.35,180.42]],"ltp":1.52,"tv":3176.83,"id":9634485}]}]}
{"op":"mcm","clk":"4233621542","pt":1631536724641,"mc":[{"id":"1.187557759","rc":[{"trd":[[1.35,77.54]],"batb":[[0,1.35,141.67]],"ltp":1.35,"tv":3254.32,"id":9634485}],"tv":4435.83}]}
{"op":"mcm","clk":"4233621809","pt":1631536727937,"mc":[{"id":"1.187557759","rc":[{"batb":[[0,1.35,158.79]],"batl":[[1,1.38,174.59]],"ltp":1.35,"tv":3254.32,"id":9634485}]}]}
{"op":"mcm","clk":"4233622358","pt":1631536733812,"mc":[{"id":"1.187557759","rc":[{"trd":[[1.37,3.94]],"batl":[[0,1.37,21.48]],"ltp":1.37,"tv":3258.26,"id":9634485}],"tv":4439.77}]}
{"op":"mcm","clk":"4233622614","pt":1631536736696,"mc":[{"id":"1.187557759","rc":[{"trd":[[1.37,4.14]],"batl":[[0,1.37,21.28]],"ltp":1.37,"tv":3258.46,"id":9634485},{"trd":[[3.7,0.07]],"ltp":3.7,"tv":1181.58,"id":9712888}],"tv":4440.04}]}
{"op":"mcm","clk":"4233622891","pt":1631536739674,"mc":[{"id":"1.187557759","rc":[{"batl":[[0,1.38,152.85],[1,1.39,125.09],[2,1.77,507.52]],"ltp":1.37,"tv":3258.46,"id":9634485},{"batb":[[0,3.45,25.02],[1,3.1,32.05],[2,2,11.88]],"ltp":3.7,"tv":1181.58,"id":9712888}]}]}
{"op":"mcm","clk":"4233622951","pt":1631536740295,"mc":[{"id":"1.187557759","rc":[{"batb":[[0,1.27,125.86],[1,1.25,512.06],[2,1.17,314.59]],"batl":[[0,1.77,507.52],[1,1.89,255.54],[2,44,7.23]],"ltp":1.37,"tv":3258.46,"id":9634485},{"batb":[[0,3.1,32.05],[1,2,11.88],[2,1.8,11.88]],"ltp":3.7,"tv":1181.58,"id":9712888}]}]}
{"op":"mcm","clk":"4233623201","pt":1631536742806,"mc":[{"id":"1.187557759","rc":[{"batb":[[0,1.31,189.88],[1,1.3,180.12],[2,1.27,125.86]],"batl":[[0,1.44,110.64],[1,1.45,104.45],[2,1.77,507.52]],"ltp":1.37,"tv":3258.46,"id":9634485}]}]}
{"op":"mcm","clk":"4233623224","pt":1631536743069,"mc":[{"id":"1.187557759","rc":[{"batb":[[0,1.27,125.86],[1,1.25,512.06],[2,1.17,314.59]],"batl":[[0,1.77,507.52],[1,1.89,255.54],[2,44,7.23]],"ltp":1.37,"tv":3258.46,"id":9634485}]}]}
{"op":"mcm","clk":"4233623485","pt":1631536745480,"mc":[{"id":"1.187557759","rc":[{"batb":[[0,1.36,105.28],[1,1.35,147.14],[2,1.27,125.86]],"batl":[[0,1.39,123.94],[1,1.4,121.46],[2,1.77,507.52]],"ltp":1.37,"tv":3258.46,"id":9634485}]}]}
{"op":"mcm","clk":"4233624105","pt":1631536752519,"mc":[{"id":"1.187557759","rc":[{"batb":[[0,1.27,125.86],[1,1.25,512.06],[2,1.17,314.59]],"batl":[[0,1.77,507.52],[1,1.89,255.54],[2,44,7.23]],"ltp":1.37,"tv":3258.46,"id":9634485}]}]}
{"op":"mcm","clk":"4233624366","pt":1631536755436,"mc":[{"id":"1.187557759","rc":[{"batb":[[0,1.31,189.88],[1,1.3,180.12],[2,1.27,125.86]],"batl":[[0,1.44,110.64],[1,1.45,104.45],[2,1.77,507.52]],"ltp":1.37,"tv":3258.46,"id":9634485}]}]}
{"op":"mcm","clk":"4233625056","pt":1631536764240,"mc":[{"id":"1.187557759","rc":[{"batl":[[0,1.77,507.52],[1,1.89,255.54],[2,44,7.23]],"ltp":1.37,"tv":3258.46,"id":9634485}]}]}
{"op":"mcm","clk":"4233625320","pt":1631536766832,"mc":[{"id":"1.187557759","rc":[{"batb":[[2,1.29,210.86]],"batl":[[0,1.34,1364.65],[1,1.77,507.52],[2,1.89,255.54]],"ltp":1.37,"tv":3258.46,"id":9634485},{"batb":[[0,3.9,69.74],[1,3.85,67.68],[2,3.8,67.68]],"ltp":3.7,"tv":1181.58,"id":9712888}]}]}
{"op":"mcm","clk":"4233625447","pt":1631536767822,"mc":[{"id":"1.187557759","rc":[{"batb":[[2,1.29,105.42]],"batl":[[0,1.33,13.63],[1,1.34,232.73],[2,1.35,596.54]],"ltp":1.37,"tv":3258.46,"id":9634485},{"batb":[[0,3.9,34.88],[1,3.85,33.84],[2,3.8,33.84]],"batl":[[0,4.2,6.59],[1,4.3,206.76],[2,4.7,2.13]],"ltp":3.7,"tv":1181.58,"id":9712888}]}]}
{"op":"mcm","clk":"4233625824","pt":1631536771829,"mc":[{"id":"1.187557759","rc":[{"batl":[[1,1.34,344.75]],"ltp":1.37,"tv":3258.46,"id":9634485},{"batl":[[1,4.3,239]],"ltp":3.7,"tv":1181.58,"id":9712888}]}]}
{"op":"mcm","clk":"4233625841","pt":1631536772037,"mc":[{"id":"1.187557759","rc":[{"batl":[[1,1.34,232.73]],"ltp":1.37,"tv":3258.46,"id":9634485},{"batl":[[1,4.3,206.76]],"ltp":3.7,"tv":1181.58,"id":9712888}]}]}
{"op":"mcm","clk":"4233626136","pt":1631536775058,"mc":[{"id":"1.187557759","rc":[{"batb":[[0,1.31,284.88]],"ltp":1.37,"tv":3258.46,"id":9634485}]}]}
{"op":"mcm","clk":"4233626554","pt":1631536779278,"mc":[{"id":"1.187557759","rc":[{"batb":[[0,1.31,189.88]],"batl":[[1,1.34,123.04]],"ltp":1.37,"tv":3258.46,"id":9634485}]}]}
{"op":"mcm","clk":"4233626789","pt":1631536782360,"mc":[{"id":"1.187557759","rc":[{"batb":[[0,1.32,381],[1,1.31,189.88],[2,1.3,180.12]],"ltp":1.37,"tv":3258.46,"id":9634485}]}]}
{"op":"mcm","clk":"4233627245","pt":1631536787778,"mc":[{"id":"1.187557759","rc":[{"trd":[[1.32,0.16]],"batb":[[0,1.32,380.92]],"ltp":1.32,"tv":3258.62,"id":9634485}],"tv":4440.2}]}
{"op":"mcm","clk":"4233627797","pt":1631536795684,"mc":[{"id":"1.187557759","rc":[{"batl":[[0,1.34,115.58],[1,1.35,143.98],[2,1.77,507.52]],"ltp":1.32,"tv":3258.62,"id":9634485},{"batb":[[0,3.65,42.18],[1,3.35,26.44],[2,2.2,42.67]],"ltp":3.7,"tv":1181.58,"id":9712888}]}]}
{"op":"mcm","clk":"4233627849","pt":1631536796310,"mc":[{"id":"1.187557759","rc":[{"batb":[[0,1.24,143.68],[1,1.22,365.72],[2,1.17,314.59]],"batl":[[0,1.77,507.52],[1,1.89,255.54],[2,44,7.23]],"ltp":1.32,"tv":3258.62,"id":9634485},{"batb":[[0,3.35,26.44],[1,2.2,42.67],[2,2,11.88]],"ltp":3.7,"tv":1181.58,"id":9712888}]}]}
{"op":"mcm","clk":"4233628029","pt":1631536798805,"mc":[{"id":"1.187557759","rc":[{"batb":[[0,1.28,262.35],[1,1.27,206.71],[2,1.24,143.68]],"batl":[[0,1.39,105.5],[1,1.4,121.68],[2,1.77,507.52]],"ltp":1.32,"tv":3258.62,"id":9634485}]}]}
{"op":"mcm","clk":"4233629767","pt":1631536818824,"mc":[{"id":"1.187557759","rc":[{"batb":[[0,1.24,143.68],[1,1.22,365.72],[2,1.17,314.59]],"ltp":1.32,"tv":3258.62,"id":9634485}]}]}
{"op":"mcm","clk":"4233629913","pt":1631536820851,"mc":[{"id":"1.187557759","rc":[{"batl":[[0,1.28,4.13],[1,1.39,105.5],[2,1.4,121.68]],"ltp":1.32,"tv":3258.62,"id":9634485}]}]}
{"op":"mcm","clk":"4233630006","pt":1631536821843,"mc":[{"id":"1.187557759","rc":[{"trd":[[1.28,8.26]],"batb":[[0,1.36,3084.62],[1,1.35,248.14],[2,1.34,97.78]],"batl":[[0,1.38,14.42]],"ltp":1.28,"tv":3266.88,"id":9634485},{"batb":[[0,3.45,39.42],[1,3.4,57.39],[2,3.35,83.83]],"batl":[[0,3.75,4.51],[1,3.85,190.05],[2,4.3,2.33]],"ltp":3.7,"tv":1181.58,"id":9712888}],"tv":4448.46}]}
{"op":"mcm","clk":"4233630075","pt":1631536822734,"mc":[{"id":"1.187557759","rc":[{"batb":[[0,1.36,364.09]],"batl":[[0,1.38,21.67]],"ltp":1.28,"tv":3266.88,"id":9634485},{"batb":[[1,3.4,38.26],[2,3.35,64.7]],"ltp":3.7,"tv":1181.58,"id":9712888}]}]}
{"op":"mcm","clk":"4233630658","pt":1631536829724,"mc":[{"id":"1.187557759","rc":[{"batb":[[0,1.36,436.09]],"ltp":1.28,"tv":3266.88,"id":9634485}]}]}
{"op":"mcm","clk":"4233630808","pt":1631536831455,"mc":[{"id":"1.187557759","rc":[{"batb":[[0,1.36,72],[1,1.27,125.19],[2,1.25,349.29]],"batl":[[0,1.37,3.85],[1,1.77,507.52],[2,1.89,255.54]],"ltp":1.28,"tv":3266.88,"id":9634485},{"batb":[[0,3,35.06],[1,2.2,42.67],[2,2,11.88]],"ltp":3.7,"tv":1181.58,"id":9712888}]}]}
{"op":"mcm","clk":"4233630879","pt":1631536832348,"mc":[{"id":"1.187557759","rc":[{"batb":[[0,1.27,125.19],[1,1.25,349.29],[2,1.17,314.59]],"ltp":1.28,"tv":3266.88,"id":9634485}]}]}
{"op":"mcm","clk":"4233631061","pt":1631536834342,"mc":[{"id":"1.187557759","rc":[{"batb":[[0,1.32,115.08],[1,1.31,171.7],[2,1.27,125.19]],"batl":[[1,1.47,145.49],[2,1.48,95.72]],"ltp":1.28,"tv":3266.88,"id":9634485}]}]}
{"op":"mcm","clk":"4233631501","pt":1631536840556,"mc":[{"id":"1.187557759","rc":[{"batl":[[1,1.77,507.52],[2,1.89,255.54]],"ltp":1.28,"tv":3266.88,"id":9634485}]}]}
{"op":"mcm","clk":"4233631697","pt":1631536843588,"mc":[{"id":"1.187557759","rc":[{"batb":[[0,1.32,129.96],[1,1.31,724.25]],"batl":[[0,1.34,30.58],[1,1.35,236.14],[2,1.36,774.01]],"ltp":1.28,"tv":3266.88,"id":9634485},{"batb":[[0,3.9,30.77],[1,3,35.06],[2,2.2,42.67]],"ltp":3.7,"tv":1181.58,"id":9712888}]}]}
{"op":"mcm","clk":"4233631785","pt":1631536844678,"mc":[{"id":"1.187557759","rc":[{"batb":[[1,3.65,42.51],[2,3.3,27.53]],"batl":[[0,4.3,6.98],[1,4.4,3.48],[2,4.5,3.48]],"ltp":3.7,"tv":1181.58,"id":9712888}]}]}
{"op":"mcm","clk":"4233631966","pt":1631536847290,"mc":[{"id":"1.187557759","rc":[{"batb":[[0,1.33,284],[1,1.32,129.96],[2,1.31,724.25]],"ltp":1.28,"tv":3266.88,"id":9634485}]}]}
{"op":"mcm","clk":"4233632157","pt":1631536849902,"mc":[{"id":"1.187557759","rc":[{"batl":[[1,1.35,262.63]],"ltp":1.28,"tv":3266.88,"id":9634485}]}]}
{"op":"mcm","clk":"4233632355","pt":1631536852503,"mc":[{"id":"1.187557759","rc":[{"batl":[[1,1.35,236.14]],"ltp":1.28,"tv":3266.88,"id":9634485}]}]}
{"op":"mcm","clk":"4233632595","pt":1631536855618,"mc":[{"id":"1.187557759","rc":[{"trd":[[1.33,52.98]],"batb":[[0,1.33,257.51]],"ltp":1.33,"tv":3319.86,"id":9634485}],"tv":4501.44}]}
{"op":"mcm","clk":"4233634511","pt":1631536870608,"mc":[{"id":"1.187557759","rc":[{"trd":[[1.33,60.92]],"batb":[[0,1.33,253.54]],"ltp":1.33,"tv":3327.8,"id":9634485}],"tv":4509.38}]}
{"op":"mcm","clk":"4233634729","pt":1631536873113,"mc":[{"id":"1.187557759","rc":[{"trd":[[3.9,0.18]],"batb":[[0,3.9,30.68]],"ltp":3.9,"tv":1181.76,"id":9712888}],"tv":4509.56}]}
{"op":"mcm","clk":"4233635101","pt":1631536877448,"mc":[{"id":"1.187557759","rc":[{"batb":[[1,1.25,349.29],[2,1.24,143.34]],"batl":[[0,1.77,507.52],[1,1.89,255.54],[2,8.8,7.23]],"ltp":1.33,"tv":3327.8,"id":9634485},{"batb":[[0,3.3,27.53],[1,2.2,42.67],[2,2,11.88]],"ltp":3.9,"tv":1181.76,"id":9712888}]}]}
{"op":"mcm","clk":"4233635176","pt":1631536878337,"mc":[{"id":"1.187557759","rc":[{"batb":[[0,1.25,349.29],[1,1.24,143.34],[2,1.17,314.59]],"ltp":1.33,"tv":3327.8,"id":9634485}]}]}
{"op":"mcm","clk":"4233635333","pt":1631536880259,"mc":[{"id":"1.187557759","rc":[{"batb":[[0,1.29,92.86],[1,1.28,194.46],[2,1.25,349.29]],"batl":[[0,1.41,175.15],[1,1.42,113.58],[2,1.77,507.52]],"ltp":1.33,"tv":3327.8,"id":9634485}]}]}
{"op":"mcm","clk":"4233636090","pt":1631536889435,"mc":[{"id":"1.187557759","rc":[{"batb":[[0,1.25,349.29],[1,1.24,143.34],[2,1.17,314.59]],"batl":[[0,1.77,507.52],[1,1.89,255.54],[2,8.8,7.23]],"ltp":1.33,"tv":3327.8,"id":9634485}]}]}
{"op":"mcm","clk":"4233636331","pt":1631536892580,"mc":[{"id":"1.187557759","rc":[{"batb":[[0,1.37,163.62],[1,1.36,705.02],[2,1.25,349.29]],"batl":[[0,1.39,12.74],[1,1.41,175.15],[2,1.42,113.58]],"ltp":1.33,"tv":3327.8,"id":9634485},{"batb":[[0,3.4,200.89],[1,3.3,27.53],[2,2.2,42.67]],"batl":[[0,3.7,15.02],[1,3.75,4.06],[2,3.8,4.06]],"ltp":3.9,"tv":1181.76,"id":9712888}]}]}
{"op":"mcm","clk":"4233636399","pt":1631536893565,"mc":[{"id":"1.187557759","rc":[{"batb":[[2,1.32,102.68]],"batl":[[0,1.39,19.93],[2,1.42,134.7]],"ltp":1.33,"tv":3327.8,"id":9634485},{"batb":[[2,2.9,39]],"ltp":3.9,"tv":1181.76,"id":9712888}]}]}
{"op":"mcm","clk":"4233636913","pt":1631536900389,"mc":[{"id":"1.187557759","rc":[{"batb":[[0,1.37,254.62]],"ltp":1.33,"tv":3327.8,"id":9634485}]}]}
{"op":"mcm","clk":"4233637816","pt":1631536911668,"mc":[{"id":"1.187557759","rc":[{"batb":[[0,1.37,163.62]],"ltp":1.33,"tv":3327.8,"id":9634485}]}]}
{"op":"mcm","clk":"4233638072","pt":1631536914800,"mc":[{"id":"1.187557759","rc":[{"batb":[[0,1.38,381],[1,1.37,163.62],[2,1.36,705.02]],"ltp":1.33,"tv":3327.8,"id":9634485}]}]}
{"op":"mcm","clk":"4233638218","pt":1631536916482,"mc":[{"id":"1.187557759","rc":[{"batb":[[1,1.27,125.6],[2,1.25,349.29]],"batl":[[0,1.77,507.52],[1,1.89,255.54],[2,8.8,7.23]],"ltp":1.33,"tv":3327.8,"id":9634485},{"batb":[[0,2.9,39],[1,2.2,42.67],[2,2,11.88]],"ltp":3.9,"tv":1181.76,"id":9712888}]}]}
{"op":"mcm","clk":"4233638306","pt":1631536917279,"mc":[{"id":"1.187557759","rc":[{"batb":[[0,1.27,125.6],[1,1.25,349.29],[2,1.17,314.59]],"ltp":1.33,"tv":3327.8,"id":9634485}]}]}
{"op":"mcm","clk":"4233638481","pt":1631536919410,"mc":[{"id":"1.187557759","rc":[{"batb":[[0,1.32,122.19],[1,1.31,171.86],[2,1.27,125.6]],"batl":[[0,1.51,156.08],[1,1.52,86.04],[2,1.77,507.52]],"ltp":1.33,"tv":3327.8,"id":9634485}]}]}
{"op":"mcm","clk":"4233638851","pt":1631536924011,"mc":[{"id":"1.187557759","rc":[{"batl":[[0,1.77,507.52],[1,1.89,255.54],[2,8.8,7.23]],"ltp":1.33,"tv":3327.8,"id":9634485}]}]}
{"op":"mcm","clk":"4233639082","pt":1631536926796,"mc":[{"id":"1.187557759","rc":[{"batb":[[0,1.32,136.03]],"batl":[[0,1.34,441.42],[1,1.35,111.12],[2,1.36,794.57]],"ltp":1.33,"tv":3327.8,"id":9634485},{"batb":[[0,4,3.99],[1,2.9,39],[2,2.2,42.67]],"batl":[[0,4.3,242.67]],"ltp":3.9,"tv":1181.76,"id":9712888}]}]}
{"op":"mcm","clk":"4233639178","pt":1631536927830,"mc":[{"id":"1.187557759","rc":[{"batl":[[0,1.34,7.46],[1,1.35,185.11],[2,1.36,888.5]],"ltp":1.33,"tv":3327.8,"id":9634485},{"batb":[[1,3.65,42.34],[2,3.25,28.28]],"batl":[[0,4.3,277.55],[1,4.4,17.44],[2,4.5,17.44]],"ltp":3.9,"tv":1181.76,"id":9712888}]}]}
{"op":"mcm","clk":"4233639201","pt":1631536928102,"mc":[{"id":"1.187557759","rc":[{"batl":[[0,4.3,249.65],[1,4.4,3.48],[2,4.5,3.48]],"ltp":3.9,"tv":1181.76,"id":9712888}]}]}
{"op":"mcm","clk":"4233639796","pt":1631536934531,"mc":[{"id":"1.187557759","rc":[{"batb":[[0,1.33,274],[1,1.32,136.03],[2,1.31,171.86]],"ltp":1.33,"tv":3327.8,"id":9634485}]}]}
{"op":"mcm","clk":"4233640214","pt":1631536939231,"mc":[{"id":"1.187557759","rc":[{"trd":[[1.33,126.92]],"batb":[[0,1.33,241]],"ltp":1.33,"tv":3393.8,"id":9634485}],"tv":4575.56}]}
{"op":"mcm","clk":"4233641550","pt":1631536954452,"mc":[{"id":"1.187557759","rc":[{"trd":[[4,0.02]],"batb":[[0,4,3.98]],"ltp":4.0,"tv":1181.78,"id":9712888}],"tv":4575.58}]}
{"op":"mcm","clk":"4233642034","pt":1631536959794,"mc":[{"id":"1.187557759","rc":[{"batb":[[1,1.32,122.19]],"batl":[[0,1.35,174],[1,1.36,217.46],[2,1.37,5.56]],"ltp":1.33,"tv":3393.8,"id":9634485},{"batb":[[0,3.65,42.34],[1,3.25,28.28],[2,2.2,42.67]],"batl":[[0,4.3,3.49],[1,4.4,1.74],[2,4.5,1.74]],"ltp":4.0,"tv":1181.78,"id":9712888}]}]}
{"op":"mcm","clk":"4233642056","pt":1631536960151,"mc":[{"id":"1.187557759","rc":[{"batb":[[1,1.25,349.29],[2,1.24,146.36]],"batl":[[0,1.77,507.52],[1,1.89,255.54],[2,8.8,7.23]],"ltp":1.33,"tv":3393.8,"id":9634485},{"batb":[[0,3.25,28.28],[1,2.2,42.67],[2,2,11.88]],"ltp":4.0,"tv":1181.78,"id":9712888}]}]}
{"op":"mcm","clk":"4233642136","pt":1631536961353,"mc":[{"id":"1.187557759","rc":[{"batb":[[0,1.25,349.29],[1,1.24,146.36],[2,1.17,314.59]],"ltp":1.33,"tv":3393.8,"id":9634485}]}]}
{"op":"mcm","clk":"4233642451","pt":1631536965381,"mc":[{"id":"1.187557759","rc":[{"batb":[[0,1.33,150.92],[1,1.32,165.56],[2,1.25,349.29]],"batl":[[0,1.36,120.94],[1,1.37,134.21],[2,1.77,507.52]],"ltp":1.33,"tv":3393.8,"id":9634485}]}]}
{"op":"mcm","clk":"4233642955","pt":1631536972508,"mc":[{"id":"1.187557759","rc":[{"batb":[[0,1.25,349.29],[1,1.24,146.36],[2,1.17,314.59]],"batl":[[0,1.77,507.52],[1,1.89,255.54],[2,8.8,7.23]],"ltp":1.33,"tv":3393.8,"id":9634485}]}]}
{"op":"mcm","clk":"4233643151","pt":1631536975525,"mc":[{"id":"1.187557759","rc":[{"batb":[[0,1.28,187.25],[1,1.27,205.32],[2,1.25,349.29]],"batl":[[0,1.42,184.05],[1,1.43,110.11],[2,1.77,507.52]],"ltp":1.33,"tv":3393.8,"id":9634485}]}]}
{"op":"mcm","clk":"4233643742","pt":1631536983209,"mc":[{"id":"1.187557759","rc":[{"batb":[[0,1.25,349.29],[1,1.24,146.36],[2,1.17,314.59]],"ltp":1.33,"tv":3393.8,"id":9634485}]}]}
{"op":"mcm","clk":"4233643849","pt":1631536984838,"mc":[{"id":"1.187557759","rc":[{"batb":[[0,1.24,146.36],[1,1.17,314.59],[2,1.15,356.53]],"ltp":1.33,"tv":3393.8,"id":9634485}]}]}
{"op":"mcm","clk":"4233643991","pt":1631536986638,"mc":[{"id":"1.187557759","rc":[{"batb":[[0,1.38,352.22],[1,1.37,137.46],[2,1.24,146.36]],"batl":[[0,1.4,8.64],[1,1.42,184.05],[2,1.43,110.11]],"ltp":1.33,"tv":3393.8,"id":9634485},{"batb":[[0,3.5,3.46],[1,3.35,214.82],[2,3.25,28.28]],"batl":[[0,3.75,36.26],[1,3.8,35.2],[2,3.85,35.2]],"ltp":4.0,"tv":1181.78,"id":9712888}]}]}
{"op":"mcm","clk":"4233644062","pt":1631536987533,"mc":[{"id":"1.187557759","rc":[{"batb":[[2,1.33,100.58]],"batl":[[0,1.39,7.19],[1,1.4,8.64],[2,1.42,184.05]],"ltp":1.33,"tv":3393.8,"id":9634485},{"batb":[[1,3.35,219.3],[2,3.3,2.24]],"ltp":4.0,"tv":1181.78,"id":9712888}]}]}
{"op":"mcm","clk":"4233644530","pt":1631536993746,"mc":[{"id":"1.187557759","rc":[{"trd":[[1.38,349.14]],"batb":[[0,1.37,137.46],[1,1.33,100.58],[2,1.28,459.41]],"batl":[[2,1.42,114.69]],"ltp":1.38,"tv":3742.94,"id":9634485},{"trd":[[3.65,132.03]],"ltp":3.65,"tv":1313.81,"id":9712888}],"tv":5056.75}]}
{"op":"mcm","clk":"4233644583","pt":1631536994335,"mc":[{"id":"1.187557759","rc":[{"batb":[[0,1.38,114],[1,1.37,137.46],[2,1.33,100.58]],"ltp":1.38,"tv":3742.94,"id":9634485}]}]}
{"op":"mcm","clk":"4233644780","pt":1631536996745,"mc":[{"id":"1.187557759","rc":[{"batb":[[1,1.37,201.6],[2,1.36,144.05]],"batl":[[2,1.41,143.12]],"ltp":1.38,"tv":3742.94,"id":9634485}]}]}
{"op":"mcm","clk":"4233645215","pt":1631537002341,"mc":[{"id":"1.187557759","rc":[{"trd":[[1.38,389.14]],"batb":[[0,1.38,94]],"ltp":1.38,"tv":3782.94,"id":9634485}],"tv":5096.75}]}
{"op":"mcm","clk":"4233645306","pt":1631537003661,"mc":[{"id":"1.187557759","rc":[{"batl":[[1,1.41,143.12],[2,1.42,114.69]],"ltp":1.38,"tv":3782.94,"id":9634485},{"batb":[[0,3.35,219.3],[1,3.3,2.24],[2,3.25,30.52]],"ltp":3.65,"tv":1313.81,"id":9712888}]}]}
{"op":"mcm","clk":"4233645530","pt":1631537006569,"mc":[{"id":"1.187557759","rc":[{"batl":[[0,1.39,22.89]],"ltp":1.38,"tv":3782.94,"id":9634485},{"batl":[[0,3.7,5.9],[1,3.75,36.26],[2,3.8,35.2]],"ltp":3.65,"tv":1313.81,"id":9712888}]}]}
{"op":"mcm","clk":"4233645847","pt":1631537010573,"mc":[{"id":"1.187557759","rc":[{"batb":[[1,1.33,100.58],[2,1.28,459.41]],"batl":[[0,1.77,507.52],[1,1.89,255.54],[2,8.8,7.23]],"ltp":1.38,"tv":3782.94,"id":9634485},{"batb":[[0,3.25,28.28],[1,2.88,40.08],[2,2.2,42.67]],"ltp":3.65,"tv":1313.81,"id":9712888}]}]}
{"op":"mcm","clk":"4233645922","pt":1631537011370,"mc":[{"id":"1.187557759","rc":[{"batb":[[0,1.28,459.41],[1,1.17,314.59],[2,1.15,356.53]],"ltp":1.38,"tv":3782.94,"id":9634485},{"batb":[[0,2.88,40.08],[1,2.2,42.67],[2,2,11.88]],"ltp":3.65,"tv":1313.81,"id":9712888}]}]}
{"op":"mcm","clk":"4233646150","pt":1631537014384,"mc":[{"id":"1.187557759","rc":[{"batb":[[0,1.28,123.6]],"batl":[[0,1.89,255.54],[1,8.8,7.23],[2,44,7.23]],"ltp":1.38,"tv":3782.94,"id":9634485}]}]}
{"op":"mcm","clk":"4233646264","pt":1631537015680,"mc":[{"id":"1.187557759","rc":[{"batb":[[0,1.39,161.69],[1,1.38,133.89],[2,1.28,123.6]],"batl":[[0,1.43,151.54],[1,1.44,107.9],[2,1.89,255.54]],"ltp":1.38,"tv":3782.94,"id":9634485}]}]}
{"op":"mcm","clk":"4233646336","pt":1631537016468,"mc":[{"id":"1.187557759","rc":[{"batb":[[0,1.39,135.61]],"ltp":1.38,"tv":3782.94,"id":9634485}]}]}
{"op":"mcm","clk":"4233646571","pt":1631537019468,"mc":[{"id":"1.187557759","rc":[{"batb":[[0,1.4,133],[1,1.39,135.61],[2,1.38,133.89]],"batl":[[0,1.43,176.95]],"ltp":1.38,"tv":3782.94,"id":9634485}]}]}
{"op":"mcm","clk":"4233646799","pt":1631537022497,"mc":[{"id":"1.187557759","rc":[{"batb":[[1,1.28,123.6],[2,1.17,314.59]],"batl":[[0,1.89,255.54],[1,8.8,7.23],[2,44,7.23]],"ltp":1.38,"tv":3782.94,"id":9634485}]}]}
{"op":"mcm","clk":"4233646836","pt":1631537022871,"mc":[{"id":"1.187557759","rc":[{"batb":[[0,1.28,123.6],[1,1.17,314.59],[2,1.15,356.53]],"ltp":1.38,"tv":3782.94,"id":9634485}]}]}
{"op":"mcm","clk":"4233647038","pt":1631537025369,"mc":[{"id":"1.187557759","rc":[{"batb":[[0,1.32,133.88],[1,1.31,173.45],[2,1.28,123.6]],"batl":[[0,1.51,156.9],[1,1.52,86.82],[2,1.89,255.54]],"ltp":1.38,"tv":3782.94,"id":9634485}]}]}
{"op":"mcm","clk":"4233648058","pt":1631537038250,"mc":[{"id":"1.187557759","rc":[{"trd":[[1.32,3.56]],"batb":[[0,1.32,132.18]],"ltp":1.32,"tv":3786.34,"id":9634485}],"tv":5100.15}]}
{"op":"mcm","clk":"4233648181","pt":1631537039501,"mc":[{"id":"1.187557759","rc":[{"batb":[[0,1.28,123.6],[1,1.17,314.59],[2,1.15,356.53]],"ltp":1.32,"tv":3786.34,"id":9634485}]}]}
{"op":"mcm","clk":"4233648495","pt":1631537042717,"mc":[{"id":"1.187557759","rc":[{"batb":[[0,1.46,166.29],[1,1.45,107.53],[2,1.28,123.6]],"ltp":1.32,"tv":3786.34,"id":9634485},{"batb":[[0,3.1,5.44],[1,2.88,379.68]],"batl":[[0,3.15,38.1],[1,3.2,7],[2,3.25,27.7]],"ltp":3.65,"tv":1313.81,"id":9712888}]}]}
{"op":"mcm","clk":"4233648593","pt":1631537043811,"mc":[{"id":"1.187557759","rc":[{"batb":[[2,1.41,77.15]],"batl":[[0,1.47,6.8],[1,1.51,156.9],[2,1.52,86.82]],"ltp":1.32,"tv":3786.34,"id":9634485},{"batb":[[1,3,10],[2,2.98,5]],"ltp":3.65,"tv":1313.81,"id":9712888}]}]}
{"op":"mcm","clk":"4233650511","pt":1631537068363,"mc":[{"id":"1.187557759","rc":[{"batb":[[0,1.33,99.58],[1,1.17,314.59],[2,1.15,356.53]],"batl":[[0,1.89,255.54],[1,8.8,7.23],[2,44,7.23]],"ltp":1.32,"tv":3786.34,"id":9634485},{"batb":[[0,2.46,24.27],[1,2,11.88],[2,1.8,11.88]],"ltp":3.65,"tv":1313.81,"id":9712888}]}]}
{"op":"mcm","clk":"4233650751","pt":1631537071301,"mc":[{"id":"1.187557759","rc":[{"batb":[[0,1.38,137.43],[1,1.37,138.62],[2,1.33,99.58]],"batl":[[0,1.66,91.34],[1,1.68,121.71],[2,1.89,255.54]],"ltp":1.32,"tv":3786.34,"id":9634485}]}]}
{"op":"mcm","clk":"4233651051","pt":1631537074777,"mc":[{"id":"1.187557759","rc":[{"batb":[[0,1.33,99.58],[1,1.17,314.59],[2,1.15,356.53]],"batl":[[0,1.89,255.54],[1,8.8,7.23],[2,44,7.23]],"ltp":1.32,"tv":3786.34,"id":9634485}]}]}
{"op":"mcm","clk":"4233651257","pt":1631537077691,"mc":[{"id":"1.187557759","rc":[{"batb":[[0,1.49,129.94],[1,1.48,98.39],[2,1.33,99.58]],"batl":[[0,1.5,19.83],[1,1.53,76.21],[2,1.54,83.04]],"ltp":1.32,"tv":3786.34,"id":9634485},{"batb":[[0,3,20],[1,2.46,24.27],[2,2,11.88]],"batl":[[0,3.2,19.08]],"ltp":3.65,"tv":1313.81,"id":9712888}]}]}
{"op":"mcm","clk":"4233651277","pt":1631537077893,"mc":[{"id":"1.187557759","rc":[{"batl":[[0,1.53,76.21],[1,1.54,83.04],[2,1.89,255.54]],"ltp":1.32,"tv":3786.34,"id":9634485},{"batb":[[0,2.46,24.27],[1,2,11.88],[2,1.8,11.88]],"ltp":3.65,"tv":1313.81,"id":9712888}]}]}
{"op":"mcm","clk":"4233651800","pt":1631537084900,"mc":[{"id":"1.187557759","rc":[{"batb":[[0,1.33,99.58],[1,1.17,314.59],[2,1.15,356.53]],"batl":[[0,1.89,255.54],[1,8.8,7.23],[2,44,7.23]],"ltp":1.32,"tv":3786.34,"id":9634485}]}]}
{"op":"mcm","clk":"4233651991","pt":1631537087823,"mc":[{"id":"1.187557759","rc":[{"batb":[[0,1.38,137.43],[1,1.37,138.62],[2,1.33,99.58]],"batl":[[0,1.66,91.34],[1,1.68,121.71],[2,1.89,255.54]],"ltp":1.32,"tv":3786.34,"id":9634485}]}]}
{"op":"mcm","clk":"4233652444","pt":1631537094223,"mc":[{"id":"1.187557759","rc":[{"batb":[[0,1.33,99.58],[1,1.17,314.59],[2,1.15,356.53]],"ltp":1.32,"tv":3786.34,"id":9634485}]}]}
{"op":"mcm","clk":"4233652654","pt":1631537096823,"mc":[{"id":"1.187557759","rc":[{"batl":[[0,2.86,4.91]],"ltp":3.65,"tv":1313.81,"id":9712888}]}]}
{"op":"mcm","clk":"4233652691","pt":1631537097318,"mc":[{"id":"1.187557759","rc":[{"batb":[[0,1.61,98.91],[1,1.6,72.38],[2,1.56,19.24]],"batl":[[0,1.62,18.94],[1,1.66,91.34],[2,1.68,661.37]],"ltp":1.32,"tv":3786.34,"id":9634485},{"batb":[[1,1.8,11.88],[2,1.7,16.97]],"batl":[[0,2.72,8.58],[1,2.78,391.06],[2,3.05,3.28]],"ltp":3.65,"tv":1313.81,"id":9712888}]}]}
{"op":"mcm","clk":"4233652764","pt":1631537098217,"mc":[{"id":"1.187557759","rc":[{"trd":[[1.61,22.26]],"batb":[[0,1.61,92.66]],"ltp":1.61,"tv":3798.84,"id":9634485},{"batb":[[0,2.6,11.54],[1,2.58,5.76],[2,2.56,5.76]],"ltp":3.65,"tv":1313.81,"id":9712888}],"tv":5112.65}]}
{"op":"mcm","clk":"4233653381","pt":1631537104722,"mc":[{"id":"1.187557759","rc":[{"trd":[[1.61,22.6]],"batb":[[0,1.61,92.49]],"ltp":1.61,"tv":3799.18,"id":9634485}],"tv":5112.99}]}
{"op":"mcm","clk":"4233654019","pt":1631537112231,"mc":[{"id":"1.187557759","rc":[{"trd":[[1.61,25.96]],"batb":[[0,1.61,90.81]],"ltp":1.61,"tv":3802.53,"id":9634485}],"tv":5116.35}]}
{"op":"mcm","clk":"4233655808","pt":1631537133867,"mc":[{"id":"1.187557759","rc":[{"trd":[[1.62,16.6]],"batl":[[0,1.62,16.81]],"ltp":1.62,"tv":3806.79,"id":9634485}],"tv":5120.61}]}
{"op":"mcm","clk":"4233656677","pt":1631537144103,"mc":[{"id":"1.187557759","rc":[{"batl":[[0,1.66,91.34],[1,1.68,661.37],[2,1.89,255.54]],"ltp":1.62,"tv":3806.79,"id":9634485},{"batl":[[0,2.78,391.06],[1,3.05,3.28],[2,3.05,0]],"ltp":3.65,"tv":1313.81,"id":9712888}]}]}
{"op":"mcm","clk":"4233656955","pt":1631537147618,"mc":[{"id":"1.187557759","rc":[{"batl":[[0,1.62,16.81],[1,1.66,91.34],[2,1.68,661.37]],"ltp":1.62,"tv":3806.79,"id":9634485},{"batl":[[0,2.72,9.85],[1,2.78,391.06],[2,3.05,3.28]],"ltp":3.65,"tv":1313.81,"id":9712888}]}]}
{"op":"mcm","clk":"4233657193","pt":1631537150689,"mc":[{"id":"1.187557759","rc":[{"trd":[[1.61,31.06]],"batb":[[0,1.61,88.26]],"ltp":1.61,"tv":3811.9,"id":9634485}],"tv":5125.71}]}
{"op":"mcm","clk":"4233657894","pt":1631537160002,"mc":[{"id":"1.187557759","rc":[{"trd":[[1.61,31.22]],"batb":[[0,1.61,88.18]],"ltp":1.61,"tv":3812.06,"id":9634485}],"tv":5125.87}]}
{"op":"mcm","clk":"4233659222","pt":1631537179437,"mc":[{"id":"1.187557759","rc":[{"trd":[[1.61,51.22]],"batb":[[0,1.61,78.18]],"ltp":1.61,"tv":3832.06,"id":9634485},{"trd":[[2.6,31.31]],"batb":[[0,2.6,3.03]],"ltp":2.6,"tv":1330.84,"id":9712888}],"tv":5162.9}]}
{"op":"mcm","clk":"4233659446","pt":1631537182861,"mc":[{"id":"1.187557759","rc":[{"batb":[[0,1.61,87.45]],"batl":[[1,1.66,102.47]],"ltp":1.61,"tv":3832.06,"id":9634485}]}]}
{"op":"mcm","clk":"4233659791","pt":1631537187683,"mc":[{"id":"1.187557759","rc":[{"batl":[[2,1.67,40.5]],"ltp":1.61,"tv":3832.06,"id":9634485}]}]}
{"op":"mcm","clk":"4233661474","pt":1631537210706,"mc":[{"id":"1.187557759","rc":[{"batb":[[0,1.54,54.31],[1,1.45,67.7],[2,1.25,237.69]],"batl":[[0,1.67,40.5],[1,1.69,32.5],[2,1.89,255.54]],"ltp":1.61,"tv":3832.06,"id":9634485},{"batb":[[0,2.46,24.27],[1,2.3,29.29],[2,1.8,11.88]],"batl":[[0,3.15,4.5],[1,4,0.02],[2,3.05,0]],"ltp":2.6,"tv":1330.84,"id":9712888}]}]}
{"op":"mcm","clk":"4233661501","pt":1631537211018,"mc":[{"id":"1.187557759","rc":[{"batb":[[0,1.45,67.7],[1,1.25,237.69],[2,1.2,386.24]],"batl":[[0,1.69,32.5],[1,1.89,255.54],[2,8.8,7.23]],"ltp":1.61,"tv":3832.06,"id":9634485},{"batb":[[0,2.3,29.29],[1,1.8,11.88],[2,1.7,16.97]],"ltp":2.6,"tv":1330.84,"id":9712888}]}]}
{"op":"mcm","clk":"4233661599","pt":1631537212421,"mc":[{"id":"1.187557759","rc":[{"batb":[[0,1.47,50.67],[1,1.45,67.7],[2,1.25,237.69]],"ltp":1.61,"tv":3832.06,"id":9634485},{"batb":[[0,2.44,5.92],[1,2.3,29.29],[2,1.8,11.88]],"ltp":2.6,"tv":1330.84,"id":9712888}]}]}
{"op":"mcm","clk":"4233661684","pt":1631537213614,"mc":[{"id":"1.187557759","rc":[{"batb":[[0,1.52,83.98],[1,1.51,90.46],[2,1.47,50.67]],"batl":[[1,1.74,84.52],[2,1.76,104.14]],"ltp":1.61,"tv":3832.06,"id":9634485}]}]}
{"op":"mcm","clk":"4233661841","pt":1631537215744,"mc":[{"id":"1.187557759","rc":[{"batb":[[0,2.48,6.01],[1,2.44,5.92],[2,2.3,29.29]],"ltp":2.6,"tv":1330.84,"id":9712888}]}]}
{"op":"mcm","clk":"4233661862","pt":1631537216002,"mc":[{"id":"1.187557759","rc":[{"batb":[[0,2.44,5.92],[1,2.3,29.29],[2,1.8,11.88]],"ltp":2.6,"tv":1330.84,"id":9712888}]}]}
{"op":"mcm","clk":"4233662025","pt":1631537217719,"mc":[{"id":"1.187557759","rc":[{"batl":[[0,1.67,34.5],[1,1.69,32.5],[2,1.74,84.52]],"ltp":1.61,"tv":3832.06,"id":9634485}]}]}
{"op":"mcm","clk":"4233662065","pt":1631537218032,"mc":[{"id":"1.187557759","rc":[{"batl":[[0,1.69,32.5],[1,1.74,84.52],[2,1.76,104.14]],"ltp":1.61,"tv":3832.06,"id":9634485}]}]}
{"op":"mcm","clk":"4233662233","pt":1631537219445,"mc":[{"id":"1.187557759","rc":[{"batb":[[0,1.47,50.67],[1,1.45,67.7],[2,1.25,237.69]],"ltp":1.61,"tv":3832.06,"id":9634485}]}]}
{"op":"mcm","clk":"4233662460","pt":1631537222257,"mc":[{"id":"1.187557759","rc":[{"batb":[[0,1.68,121.56],[1,1.66,150.62],[2,1.65,9.04]],"batl":[[1,1.7,17.25],[2,1.74,84.52]],"ltp":1.61,"tv":3832.06,"id":9634485},{"batb":[[1,2.32,386.68],[2,2.3,29.29]],"batl":[[0,2.72,996.79],[1,2.82,3.55],[2,3.15,4.5]],"ltp":2.6,"tv":1330.84,"id":9712888}]}]}
{"op":"mcm","clk":"4233662576","pt":1631537223514,"mc":[{"id":"1.187557759","rc":[{"trd":[[1.68,679.15]],"batb":[[0,1.68,115.54]],"batl":[[2,1.74,101.76]],"ltp":1.68,"tv":3844.1,"id":9634485}],"tv":5174.94}]}
{"op":"mcm","clk":"4233663028","pt":1631537228626,"mc":[{"id":"1.187557759","rc":[{"batl":[[2,1.74,137.51]],"ltp":1.68,"tv":3844.1,"id":9634485},{"batb":[[1,2.34,6.72],[2,2.32,386.68]],"batl":[[0,2.7,5.25],[1,2.72,996.79],[2,2.8,4.22]],"ltp":2.6,"tv":1330.84,"id":9712888}]}]}
{"op":"mcm","clk":"4233663142","pt":1631537230134,"mc":[{"id":"1.187557759","rc":[{"batb":[[0,1.68,216.54]],"ltp":1.68,"tv":3844.1,"id":9634485}]}]}
{"op":"mcm","clk":"4233663235","pt":1631537231326,"mc":[{"id":"1.187557759","rc":[{"trd":[[1.68,679.31]],"batb":[[0,1.68,216.46]],"ltp":1.68,"tv":3844.26,"id":9634485}],"tv":5175.1}]}
{"op":"mcm","clk":"4233663708","pt":1631537236548,"mc":[{"id":"1.187557759","rc":[{"batl":[[0,2.7,41.23]],"ltp":2.6,"tv":1330.84,"id":9712888}]}]}
{"op":"mcm","clk":"4233664064","pt":1631537240585,"mc":[{"id":"1.187557759","rc":[{"trd":[[2.44,42.11]],"batb":[[0,2.44,5.83]],"ltp":2.44,"tv":1331.02,"id":9712888}],"tv":5175.28}]}
{"op":"mcm","clk":"4233664501","pt":1631537246657,"mc":[{"id":"1.187557759","rc":[{"batb":[[0,1.56,46.83],[1,1.52,56.07],[2,1.46,291.71]],"batl":[[0,1.76,37.77],[1,1.89,255.54],[2,2.22,431.6]],"ltp":1.68,"tv":3844.26,"id":9634485},{"batb":[[0,2.3,6.48],[1,2.18,34.56],[2,1.7,16.97]],"batl":[[0,2.8,4.22],[1,2.72,0],[2,2.8,0]],"ltp":2.44,"tv":1331.02,"id":9712888}]}]}
{"op":"mcm","clk":"4233664847","pt":1631537251584,"mc":[{"id":"1.187557759","rc":[{"batb":[[0,1.67,62.75],[1,1.66,63.24],[2,1.56,46.83]],"batl":[[0,1.72,92.25],[1,1.74,108.15],[2,1.76,37.77]],"ltp":1.68,"tv":3844.26,"id":9634485}]}]}
{"op":"mcm","clk":"4233664947","pt":1631537252793,"mc":[{"id":"1.187557759","rc":[{"batb":[[0,2.34,6.22],[1,2.3,6.48],[2,2.18,34.56]],"ltp":2.44,"tv":1331.02,"id":9712888}]}]}
{"op":"mcm","clk":"4233665000","pt":1631537253616,"mc":[{"id":"1.187557759","rc":[{"batb":[[0,2.3,6.48],[1,2.18,34.56],[2,1.7,16.97]],"ltp":2.44,"tv":1331.02,"id":9712888}]}]}
{"op":"mcm","clk":"4233665099","pt":1631537255023,"mc":[{"id":"1.187557759","rc":[{"batb":[[0,1.56,46.83],[1,1.52,56.07],[2,1.46,291.71]],"batl":[[0,1.76,37.77],[1,1.89,255.54],[2,2.22,431.6]],"ltp":1.68,"tv":3844.26,"id":9634485}]}]}
{"op":"mcm","clk":"4233665267","pt":1631537256806,"mc":[{"id":"1.187557759","rc":[{"batb":[[0,1.59,41.11],[1,1.56,46.83],[2,1.52,56.07]],"ltp":1.68,"tv":3844.26,"id":9634485},{"batl":[[0,2.7,4.95],[1,2.8,4.22]],"ltp":2.44,"tv":1331.02,"id":9712888}]}]}
{"op":"mcm","clk":"4233665291","pt":1631537257115,"mc":[{"id":"1.187557759","rc":[{"batb":[[0,1.56,46.83],[1,1.52,56.07],[2,1.46,291.71]],"ltp":1.68,"tv":3844.26,"id":9634485},{"batl":[[0,2.8,4.22],[1,2.8,0]],"ltp":2.44,"tv":1331.02,"id":9712888}]}]}
{"op":"mcm","clk":"4233665398","pt":1631537258790,"mc":[{"id":"1.187557759","rc":[{"batb":[[2,1.3,198.07]],"batl":[[1,1.82,83.89],[2,1.84,90.21]],"ltp":1.68,"tv":3844.26,"id":9634485}]}]}
{"op":"mcm","clk":"4233665536","pt":1631537260793,"mc":[{"id":"1.187557759","rc":[{"trd":[[1.76,75.54]],"batb":[[0,1.73,17.34],[1,1.72,514.01],[2,1.71,125.64]],"batl":[[0,1.78,17.91],[1,1.83,375.85],[2,1.89,255.54]],"ltp":1.76,"tv":3919.8,"id":9634485},{"batb":[[2,1.6,99.04]],"batl":[[0,2.36,7.44],[1,2.66,3.76],[2,2.8,4.22]],"ltp":2.44,"tv":1331.02,"id":9712888}],"tv":5250.82}]}
{"op":"mcm","clk":"4233665589","pt":1631537261629,"mc":[{"id":"1.187557759","rc":[{"trd":[[1.73,11.62]],"batb":[[0,1.73,11.53]],"ltp":1.73,"tv":3931.42,"id":9634485},{"batb":[[1,2.22,13.52],[2,2.2,6.76]],"ltp":2.44,"tv":1331.02,"id":9712888}],"tv":5262.44}]}
{"op":"mcm","clk":"4233665762","pt":1631537263822,"mc":[{"id":"1.187557759","rc":[{"batb":[[0,1.75,110.88],[1,1.73,120.65],[2,1.72,514.01]],"batl":[[1,1.81,57.88],[2,1.83,467.77]],"ltp":1.73,"tv":3931.42,"id":9634485}]}]}
{"op":"mcm","clk":"4233665895","pt":1631537265846,"mc":[{"id":"1.187557759","rc":[{"trd":[[1.75,47.57]],"batb":[[0,1.75,89.95]],"ltp":1.75,"tv":3973.28,"id":9634485}],"tv":5304.3}]}
{"op":"mcm","clk":"4233665964","pt":1631537266932,"mc":[{"id":"1.187557759","rc":[{"batl":[[1,1.79,31.69],[2,1.81,89.38]],"ltp":1.75,"tv":3973.28,"id":9634485},{"batb":[[1,2.26,6.98],[2,2.22,19.86]],"batl":[[1,2.52,5.76],[2,2.6,4.96]],"ltp":2.44,"tv":1331.02,"id":9712888}]}]}
{"op":"mcm","clk":"4233666095","pt":1631537268634,"mc":[{"id":"1.187557759","rc":[{"batb":[[0,1.75,99.32]],"batl":[[2,1.8,30.67]],"ltp":1.75,"tv":3973.28,"id":9634485},{"batb":[[2,2.24,6.27]],"ltp":2.44,"tv":1331.02,"id":9712888}]}]}
{"op":"mcm","clk":"4233666208","pt":1631537270207,"mc":[{"id":"1.187557759","rc":[{"trd":[[1.75,47.79]],"batb":[[0,1.75,99.21]],"ltp":1.75,"tv":3973.5,"id":9634485}],"tv":5304.52}]}
{"op":"mcm","clk":"4233666528","pt":1631537275348,"mc":[{"id":"1.187557759","rc":[{"trd":[[1.75,48.27]],"batb":[[0,1.75,98.73]],"ltp":1.75,"tv":3973.98,"id":9634485},{"trd":[[2.34,0.36]],"ltp":2.34,"tv":1331.38,"id":9712888}],"tv":5305.36}]}
{"op":"mcm","clk":"4233667107","pt":1631537283637,"mc":[{"id":"1.187557759","rc":[{"batb":[[0,1.63,36.23],[1,1.6,46.36],[2,1.5,287.3]],"batl":[[0,1.89,255.54],[1,2.22,431.6],[2,1.8,0]],"ltp":1.75,"tv":3973.98,"id":9634485},{"batb":[[0,2.2,7.87],[1,2.08,39.58],[2,1.6,99.04]],"batl":[[0,2.6,4.96],[1,2.52,0],[2,2.6,0]],"ltp":2.34,"tv":1331.38,"id":9712888}]}]}
{"op":"mcm","clk":"4233667307","pt":1631537286830,"mc":[{"id":"1.187557759","rc":[{"batb":[[0,1.66,35.28],[1,1.63,36.23],[2,1.6,46.36]],"batl":[[0,1.82,34.27],[1,1.88,81.52],[2,1.89,255.54]],"ltp":1.75,"tv":3973.98,"id":9634485},{"batl":[[0,2.52,6.01],[1,2.6,4.96]],"ltp":2.34,"tv":1331.38,"id":9712888}]}]}
{"op":"mcm","clk":"4233667329","pt":1631537287144,"mc":[{"id":"1.187557759","rc":[{"batb":[[0,1.63,36.23],[1,1.6,46.36],[2,1.3,198.07]],"ltp":1.75,"tv":3973.98,"id":9634485},{"batl":[[0,2.6,4.96],[1,2.6,0]],"ltp":2.34,"tv":1331.38,"id":9712888}]}]}
{"op":"mcm","clk":"4233667429","pt":1631537288760,"mc":[{"id":"1.187557759","rc":[{"trd":[[1.75,48.31]],"batb":[[0,1.81,102.89],[1,1.8,8.72],[2,1.79,97.29]],"batl":[[0,1.82,34.25],[1,1.83,8.28],[2,1.88,81.52]],"ltp":1.75,"tv":3974.02,"id":9634485},{"batl":[[0,2.26,39.82],[1,2.28,418.35],[2,2.3,19.91]],"ltp":2.34,"tv":1331.38,"id":9712888}],"tv":5305.4}]}
{"op":"mcm","clk":"4233667503","pt":1631537289757,"mc":[{"id":"1.187557759","rc":[{"trd":[[1.81,11.3]],"batb":[[0,1.81,97.24]],"ltp":1.81,"tv":3985.32,"id":9634485},{"batb":[[2,2.02,43.51]],"batl":[[0,2.26,13.28],[1,2.28,405.08],[2,2.3,6.64]],"ltp":2.34,"tv":1331.38,"id":9712888}],"tv":5316.7}]}
{"op":"mcm","clk":"4233667628","pt":1631537291467,"mc":[{"id":"1.187557759","rc":[{"trd":[[1.81,28.74]],"batb":[[0,1.81,88.52]],"ltp":1.81,"tv":4002.76,"id":9634485}],"tv":5334.14}]}
{"op":"mcm","clk":"4233667774","pt":1631537293589,"mc":[{"id":"1.187557759","rc":[{"trd":[[1.81,61.34]],"batb":[[0,1.81,72.22]],"ltp":1.81,"tv":4035.36,"id":9634485}],"tv":5366.74}]}
{"op":"mcm","clk":"4233667861","pt":1631537294785,"mc":[{"id":"1.187557759","rc":[{"batl":[[2,1.88,7.64]],"ltp":1.81,"tv":4035.36,"id":9634485}]}]}
{"op":"mcm","clk":"4233667944","pt":1631537295789,"mc":[{"id":"1.187557759","rc":[{"batl":[[1,1.83,40.78],[2,1.84,31.03]],"ltp":1.81,"tv":4035.36,"id":9634485},{"batb":[[1,2.18,7.86],[2,2.08,39.58]],"ltp":2.34,"tv":1331.38,"id":9712888}]}]}
{"op":"mcm","clk":"4233668013","pt":1631537296874,"mc":[{"id":"1.187557759","rc":[{"batb":[[0,1.81,85.94]],"ltp":1.81,"tv":4035.36,"id":9634485}]}]}
{"op":"mcm","clk":"4233668463","pt":1631537303308,"mc":[{"id":"1.187557759","rc":[{"batb":[[0,1.7,37.92],[1,1.68,39.33],[2,1.55,285.97]],"batl":[[0,1.89,255.54],[1,2.22,431.6],[2,1.84,0]],"ltp":1.81,"tv":4035.36,"id":9634485},{"batb":[[0,2.18,7.86],[1,2.02,43.51],[2,1.6,99.04]],"batl":[[0,2.44,5.58],[1,2.28,0],[2,2.3,0]],"ltp":2.34,"tv":1331.38,"id":9712888}]}]}
{"op":"mcm","clk":"4233668702","pt":1631537306795,"mc":[{"id":"1.187557759","rc":[{"batb":[[0,1.75,97.47],[1,1.73,109.15],[2,1.7,37.92]],"batl":[[0,1.84,31.78],[1,1.89,255.54],[2,1.92,59.89]],"ltp":1.81,"tv":4035.36,"id":9634485}]}]}
{"op":"mcm","clk":"4233668937","pt":1631537309802,"mc":[{"id":"1.187557759","rc":[{"batl":[[0,1.83,28.5],[1,1.84,31.78],[2,1.89,255.54]],"ltp":1.81,"tv":4035.36,"id":9634485},{"trd":[[2.18,4.97]],"batb":[[0,2.2,7.42],[1,2.18,5.44],[2,2.02,43.51]],"ltp":2.18,"tv":1336.22,"id":9712888}],"tv":5371.58}]}
{"op":"mcm","clk":"4233668975","pt":1631537310321,"mc":[{"id":"1.187557759","rc":[{"batl":[[0,1.84,31.78],[1,1.89,255.54],[2,1.92,59.89]],"ltp":1.81,"tv":4035.36,"id":9634485},{"batb":[[0,2.18,5.44],[1,2.02,43.51],[2,1.6,99.04]],"ltp":2.18,"tv":1336.22,"id":9712888}]}]}
{"op":"mcm","clk":"4233669185","pt":1631537313498,"mc":[{"id":"1.187557759","rc":[{"batb":[[1,1.73,149.28]],"ltp":1.81,"tv":4035.36,"id":9634485},{"batl":[[0,2.38,6.75],[1,2.44,5.58]],"ltp":2.18,"tv":1336.22,"id":9712888}]}]}
{"op":"mcm","clk":"4233669211","pt":1631537313912,"mc":[{"id":"1.187557759","rc":[{"batb":[[1,1.73,109.15]],"ltp":1.81,"tv":4035.36,"id":9634485},{"batl":[[0,2.44,5.58],[1,2.44,0]],"ltp":2.18,"tv":1336.22,"id":9712888}]}]}
{"op":"mcm","clk":"4233669407","pt":1631537316828,"mc":[{"id":"1.187557759","rc":[{"batl":[[0,1.83,33.5],[1,1.84,31.78],[2,1.89,255.54]],"ltp":1.81,"tv":4035.36,"id":9634485},{"batb":[[0,2.2,6.62],[1,2.18,5.44],[2,2.02,43.51]],"ltp":2.18,"tv":1336.22,"id":9712888}]}]}
{"op":"mcm","clk":"4233669459","pt":1631537317503,"mc":[{"id":"1.187557759","rc":[{"batb":[[0,1.7,37.92],[1,1.68,39.33],[2,1.55,285.97]],"batl":[[0,1.84,31.78],[1,1.89,255.54],[2,1.92,59.89]],"ltp":1.81,"tv":4035.36,"id":9634485},{"batb":[[0,2.18,5.44],[1,2.02,43.51],[2,1.6,99.04]],"ltp":2.18,"tv":1336.22,"id":9712888}]}]}
{"op":"mcm","clk":"4233669646","pt":1631537320508,"mc":[{"id":"1.187557759","rc":[{"trd":[[1.84,63.56],[1.85,6.4]],"batb":[[0,1.86,25.04],[1,1.84,88.87],[2,1.82,65.94]],"batl":[[0,1.89,270.6],[1,1.92,59.89],[2,1.94,367.96]],"ltp":1.85,"tv":4105.17,"id":9634485},{"trd":[[2.18,10.55]],"batb":[[0,2.02,43.51],[1,1.6,99.04],[2,1.5,106.96]],"batl":[[0,2.2,401.69],[1,2.22,20.46],[2,2.24,20.46]],"ltp":2.18,"tv":1341.8,"id":9712888}],"tv":5446.97}]}
{"op":"mcm","clk":"4233669708","pt":1631537321607,"mc":[{"id":"1.187557759","rc":[{"trd":[[1.83,5.56]],"batb":[[0,1.82,65.94],[1,1.78,32.13],[2,1.77,20.37]],"ltp":1.83,"tv":4110.73,"id":9634485},{"trd":[[2.2,34.6]],"batb":[[0,2.08,14.42],[1,2.06,7.22],[2,2.04,7.22]],"batl":[[0,2.2,397.07]],"ltp":2.2,"tv":1346.42,"id":9712888}],"tv":5457.15}]}
{"op":"mcm","clk":"4233669846","pt":1631537323833,"mc":[{"id":"1.187557759","rc":[{"batb":[[0,1.85,86.42],[1,1.83,90.51],[2,1.82,65.94]],"batl":[[1,1.92,80.04]],"ltp":1.83,"tv":4110.73,"id":9634485}]}]}
{"op":"mcm","clk":"4233669958","pt":1631537325363,"mc":[{"id":"1.187557759","rc":[{"trd":[[1.85,24.6]],"batb":[[0,1.85,77.32]],"ltp":1.85,"tv":4128.93,"id":9634485}],"tv":5475.35}]}
{"op":"mcm","clk":"4233670416","pt":1631537331957,"mc":[{"id":"1.187557759","rc":[{"batb":[[0,1.86,191.41],[1,1.85,77.32],[2,1.83,90.51]],"ltp":1.85,"tv":4128.93,"id":9634485}]}]}
{"op":"mcm","clk":"4233670555","pt":1631537334245,"mc":[{"id":"1.187557759","rc":[{"trd":[[1.86,18.28]],"batb":[[0,1.86,182.27]],"ltp":1.86,"tv":4147.21,"id":9634485}],"tv":5493.63}]}
{"op":"mcm","clk":"4233670706","pt":1631537336370,"mc":[{"id":"1.187557759","rc":[{"batb":[[0,1.86,236.27]],"ltp":1.86,"tv":4147.21,"id":9634485}]}]}
{"op":"mcm","clk":"4233671418","pt":1631537346847,"mc":[{"id":"1.187557759","rc":[{"batb":[[0,1.86,237.11]],"ltp":1.86,"tv":4147.21,"id":9634485}]}]}
{"op":"mcm","clk":"4233671556","pt":1631537348668,"mc":[{"id":"1.187557759","rc":[{"trd":[[1.89,0.1]],"batl":[[0,1.89,270.55]],"ltp":1.89,"tv":4147.31,"id":9634485}],"tv":5493.73}]}
{"op":"mcm","clk":"4233671590","pt":1631537349185,"mc":[{"id":"1.187557759","rc":[{"batl":[[0,1.89,15.06]],"ltp":1.89,"tv":4147.31,"id":9634485}]}]}
{"op":"mcm","clk":"4233671796","pt":1631537352277,"mc":[{"id":"1.187557759","rc":[{"trd":[[1.86,490.84],[1.88,4.15]],"batb":[[0,1.85,77.32],[1,1.83,90.51],[2,1.82,65.94]],"batl":[[0,1.86,18.36],[1,1.89,15.06],[2,1.92,80.04]],"ltp":1.86,"tv":4621.53,"id":9634485}],"tv":5967.96}]}
{"op":"mcm","clk":"4233671978","pt":1631537354786,"mc":[{"id":"1.187557759","rc":[{"batb":[[2,1.78,32.13]],"batl":[[0,1.92,80.04],[1,1.94,76.65],[2,2.22,431.74]],"ltp":1.86,"tv":4621.53,"id":9634485},{"batb":[[0,2.02,43.51],[1,1.86,27.78],[2,1.6,99.04]],"batl":[[0,2.5,4.73],[1,2.22,0],[2,2.24,0]],"ltp":2.2,"tv":1346.42,"id":9712888}]}]}
{"op":"mcm","clk":"4233671993","pt":1631537354998,"mc":[{"id":"1.187557759","rc":[{"batb":[[0,1.68,38.91],[1,1.55,285.97],[2,1.3,198.07]],"batl":[[0,2.22,431.74],[1,1.94,0],[2,2.22,0]],"ltp":1.86,"tv":4621.53,"id":9634485},{"batb":[[0,1.86,27.78],[1,1.6,99.04],[2,1.5,106.96]],"ltp":2.2,"tv":1346.42,"id":9712888}]}]}
{"op":"mcm","clk":"4233672128","pt":1631537356450,"mc":[{"id":"1.187557759","rc":[{"batl":[[0,2.08,8.09],[1,2.22,431.6]],"ltp":1.86,"tv":4621.53,"id":9634485},{"batb":[[0,1.93,27.93],[1,1.86,27.78],[2,1.6,99.04]],"ltp":2.2,"tv":1346.42,"id":9712888}]}]}
{"op":"mcm","clk":"4233672249","pt":1631537357804,"mc":[{"id":"1.187557759","rc":[{"batb":[[0,1.75,88.2],[1,1.73,109.2],[2,1.68,38.91]],"batl":[[1,2.1,85.54],[2,2.12,58.94]],"ltp":1.86,"tv":4621.53,"id":9634485}]}]}
{"op":"mcm","clk":"4233672327","pt":1631537358497,"mc":[{"id":"1.187557759","rc":[{"batb":[[2,1.72,41.59]],"batl":[[2,2.12,67.4]],"ltp":1.86,"tv":4621.53,"id":9634485},{"batb":[[1,1.9,30.96],[2,1.86,27.78]],"batl":[[0,2.4,5.84],[1,2.5,4.73]],"ltp":2.2,"tv":1346.42,"id":9712888}]}]}
{"op":"mcm","clk":"4233672612","pt":1631537361672,"mc":[{"id":"1.187557759","rc":[{"batl":[[0,2.06,8.4],[1,2.08,7.94],[2,2.1,85.54]],"ltp":1.86,"tv":4621.53,"id":9634485},{"batb":[[0,1.95,27.71],[1,1.93,27.93],[2,1.9,30.96]],"ltp":2.2,"tv":1346.42,"id":9712888}]}]}
{"op":"mcm","clk":"4233672634","pt":1631537361981,"mc":[{"id":"1.187557759","rc":[{"batl":[[0,2.08,8.09],[1,2.1,85.54],[2,2.12,67.4]],"ltp":1.86,"tv":4621.53,"id":9634485},{"batb":[[0,1.93,27.93],[1,1.9,30.96],[2,1.86,27.78]],"ltp":2.2,"tv":1346.42,"id":9712888}]}]}
{"op":"mcm","clk":"4233672741","pt":1631537363368,"mc":[{"id":"1.187557759","rc":[{"trd":[[1.75,73.61]],"batb":[[0,1.75,75.55]],"batl":[[1,2.12,8.46],[2,2.22,431.6]],"ltp":1.75,"tv":4646.83,"id":9634485}],"tv":5993.26}]}
{"op":"mcm","clk":"4233672930","pt":1631537366390,"mc":[{"id":"1.187557759","rc":[{"trd":[[1.75,85.23]],"batb":[[0,1.75,69.74],[1,1.74,366.42],[2,1.73,109.2]],"batl":[[0,1.78,11.51],[1,1.81,80.05],[2,1.83,92]],"ltp":1.75,"tv":4658.45,"id":9634485},{"batb":[[0,2.26,39.82],[1,2.24,19.91],[2,2.22,19.91]],"ltp":2.2,"tv":1346.42,"id":9712888}],"tv":6004.88}]}
{"op":"mcm","clk":"4233673005","pt":1631537367486,"mc":[{"id":"1.187557759","rc":[{"batb":[[0,2.26,13.28],[1,2.24,6.64],[2,2.22,6.64]],"batl":[[2,2.66,3.76]],"ltp":2.2,"tv":1346.42,"id":9712888}]}]}
{"op":"mcm","clk":"4233673162","pt":1631537369781,"mc":[{"id":"1.187557759","rc":[{"batb":[[0,1.75,78]],"batl":[[1,1.81,89.91]],"ltp":1.75,"tv":4658.45,"id":9634485}]}]}
{"op":"mcm","clk":"4233673292","pt":1631537371611,"mc":[{"id":"1.187557759","rc":[{"trd":[[1.75,119.85]],"batb":[[0,1.75,60.69]],"ltp":1.75,"tv":4693.07,"id":9634485}],"tv":6039.5}]}
{"op":"mcm","clk":"4233673423","pt":1631537373283,"mc":[{"id":"1.187557759","rc":[{"batl":[[1,2.46,6.25],[2,2.5,4.73]],"ltp":2.2,"tv":1346.42,"id":9712888}]}]}
{"op":"mcm","clk":"4233673504","pt":1631537374529,"mc":[{"id":"1.187557759","rc":[{"batb":[[0,1.75,68.43]],"batl":[[1,1.81,99.15]],"ltp":1.75,"tv":4693.07,"id":9634485}]}]}
{"op":"mcm","clk":"4233674628","pt":1631537389832,"mc":[{"id":"1.187557759","rc":[{"batb":[[1,1.73,109.2],[2,1.72,41.59]],"batl":[[0,1.81,99.15],[1,1.83,92],[2,1.86,28.26]],"ltp":1.75,"tv":4693.07,"id":9634485},{"batb":[[0,2.16,42.76],[1,2.12,6.54],[2,2,44.85]],"ltp":2.2,"tv":1346.42,"id":9712888}]}]}
{"op":"mcm","clk":"4233674664","pt":1631537390349,"mc":[{"id":"1.187557759","rc":[{"batb":[[0,1.66,39.28],[1,1.61,45.86],[2,1.55,285.97]],"batl":[[0,1.89,24.51],[1,2.22,431.74],[2,1.86,0]],"ltp":1.75,"tv":4693.07,"id":9634485},{"batb":[[0,2.12,6.54],[1,2,44.85],[2,1.6,99.04]],"batl":[[0,2.52,6.01],[1,2.46,0],[2,2.5,0]],"ltp":2.2,"tv":1346.42,"id":9712888}]}]}
{"op":"mcm","clk":"4233674868","pt":1631537392811,"mc":[{"id":"1.187557759","rc":[{"batb":[[0,1.67,94.39],[1,1.66,102.81],[2,1.61,45.86]],"batl":[[1,1.94,71.12],[2,1.96,74.34]],"ltp":1.75,"tv":4693.07,"id":9634485}]}]}
{"op":"mcm","clk":"4233675242","pt":1631537397638,"mc":[{"id":"1.187557759","rc":[{"trd":[[1.86,490.85]],"batl":[[0,1.89,24.5]],"ltp":1.86,"tv":4693.08,"id":9634485},{"trd":[[2.12,28.62],[2.16,0.01]],"batb":[[0,2.12,4.85]],"ltp":2.12,"tv":1349.81,"id":9712888}],"tv":6042.9}]}
{"op":"mcm","clk":"4233675484","pt":1631537400761,"mc":[{"id":"1.187557759","rc":[{"batb":[[0,1.66,39.28],[1,1.61,45.86],[2,1.55,285.97]],"ltp":1.86,"tv":4693.08,"id":9634485}]}]}
{"op":"mcm","clk":"4233675707","pt":1631537403660,"mc":[{"id":"1.187557759","rc":[{"batb":[[0,1.87,87.49],[1,1.85,136.06],[2,1.84,24.32]],"batl":[[1,1.92,17.01],[2,1.94,71.12]],"ltp":1.86,"tv":4693.08,"id":9634485},{"batl":[[0,2.16,10.08],[1,2.2,504.33],[2,2.22,11.75]],"ltp":2.12,"tv":1349.81,"id":9712888}]}]}
{"op":"mcm","clk":"4233675776","pt":1631537404755,"mc":[{"id":"1.187557759","rc":[{"trd":[[1.87,20.98]],"batb":[[0,1.87,82],[1,1.85,103.63],[2,1.84,8.1]],"ltp":1.87,"tv":4704.06,"id":9634485},{"batb":[[1,2.06,14.56],[2,2.04,7.28]],"ltp":2.12,"tv":1349.81,"id":9712888}],"tv":6053.88}]}
{"op":"mcm","clk":"4233675945","pt":1631537407060,"mc":[{"id":"1.187557759","rc":[{"trd":[[2.16,20.07]],"batl":[[0,2.2,504.38],[1,2.22,11.75],[2,2.44,4.1]],"ltp":2.16,"tv":1369.87,"id":9712888}],"tv":6073.94}]}
{"op":"mcm","clk":"4233676076","pt":1631537408774,"mc":[{"id":"1.187557759","rc":[{"trd":[[1.87,43.04]],"batb":[[0,1.87,70.97]],"ltp":1.87,"tv":4726.12,"id":9634485}],"tv":6096.0}]}
{"op":"mcm","clk":"4233676156","pt":1631537409982,"mc":[{"id":"1.187557759","rc":[{"batl":[[2,2.34,6.75]],"ltp":2.16,"tv":1369.87,"id":9712888}]}]}
{"op":"mcm","clk":"4233676272","pt":1631537411660,"mc":[{"id":"1.187557759","rc":[{"batb":[[0,1.87,78.37]],"batl":[[2,1.94,79.91]],"ltp":1.87,"tv":4726.12,"id":9634485}]}]}
{"op":"mcm","clk":"4233676344","pt":1631537412748,"mc":[{"id":"1.187557759","rc":[{"trd":[[1.89,9.25]],"batl":[[0,1.89,15.35]],"ltp":1.89,"tv":4735.27,"id":9634485},{"trd":[[2.12,46.48]],"batb":[[0,2.06,14.56],[1,2.04,7.28],[2,2.02,7.28]],"ltp":2.12,"tv":1387.73,"id":9712888}],"tv":6123.01}]}
{"op":"mcm","clk":"4233676674","pt":1631537417299,"mc":[{"id":"1.187557759","rc":[{"batl":[[1,1.94,79.91],[2,1.96,74.34]],"ltp":1.89,"tv":4735.27,"id":9634485},{"batl":[[0,2.2,504.33]],"ltp":2.12,"tv":1387.73,"id":9712888}]}]}
{"op":"mcm","clk":"4233676856","pt":1631537420182,"mc":[{"id":"1.187557759","rc":[{"batl":[[0,1.89,29.42]],"ltp":1.89,"tv":4735.27,"id":9634485},{"batl":[[0,2.2,517.32]],"ltp":2.12,"tv":1387.73,"id":9712888}]}]}
{"op":"mcm","clk":"4233677617","pt":1631537430808,"mc":[{"id":"1.187557759","rc":[{"batb":[[0,1.8,31.21],[1,1.75,40.11],[2,1.71,38.19]],"batl":[[0,2.5,368.89],[1,1.94,0],[2,1.96,0]],"ltp":1.89,"tv":4735.27,"id":9634485},{"batb":[[0,2,44.85],[1,1.88,28.96],[2,1.82,29.87]],"batl":[[0,2.34,6.75],[1,2.42,5.75],[2,2.52,6.01]],"ltp":2.12,"tv":1387.73,"id":9712888}]}]}
{"op":"mcm","clk":"4233677637","pt":1631537431108,"mc":[{"id":"1.187557759","rc":[{"batb":[[0,1.71,38.19],[1,1.68,39.08],[2,1.55,285.97]],"ltp":1.89,"tv":4735.27,"id":9634485},{"batb":[[0,1.88,28.96],[1,1.82,29.87],[2,1.5,106.96]],"batl":[[0,2.42,5.75],[1,2.42,0],[2,2.52,0]],"ltp":2.12,"tv":1387.73,"id":9712888}]}]}
{"op":"mcm","clk":"4233677845","pt":1631537433587,"mc":[{"id":"1.187557759","rc":[{"batb":[[0,1.75,93.05],[1,1.73,109.29],[2,1.71,38.19]],"batl":[[0,2.16,87.87],[1,2.18,54.43],[2,2.5,368.76]],"ltp":1.89,"tv":4735.27,"id":9634485}]}]}
{"op":"mcm","clk":"4233677925","pt":1631537434587,"mc":[{"id":"1.187557759","rc":[{"batl":[[0,2.14,7.89],[1,2.16,87.73],[2,2.18,54.43]],"ltp":1.89,"tv":4735.27,"id":9634485}]}]}
{"op":"mcm","clk":"4233678048","pt":1631537436203,"mc":[{"id":"1.187557759","rc":[{"batl":[[1,2.5,368.76],[2,2.18,0]],"ltp":1.89,"tv":4735.27,"id":9634485}]}]}
{"op":"mcm","clk":"4233678185","pt":1631537437815,"mc":[{"id":"1.187557759","rc":[{"batb":[[0,1.75,142.12]],"batl":[[1,2.5,0]],"ltp":1.89,"tv":4735.27,"id":9634485},{"batl":[[0,2.34,6.75],[1,2.42,5.75]],"ltp":2.12,"tv":1387.73,"id":9712888}]}]}
{"op":"mcm","clk":"4233678266","pt":1631537438808,"mc":[{"id":"1.187557759","rc":[{"trd":[[1.75,131.41]],"batb":[[0,1.75,87.27]],"batl":[[0,1.8,1774.06],[1,1.81,41.66],[2,1.82,41.66]],"ltp":1.75,"tv":4746.83,"id":9634485},{"batl":[[0,2.42,5.75],[1,2.42,0]],"ltp":2.12,"tv":1387.73,"id":9712888}],"tv":6134.57}]}
{"op":"mcm","clk":"4233678341","pt":1631537439809,"mc":[{"id":"1.187557759","rc":[{"batb":[[1,1.74,423.31],[2,1.73,109.29]],"batl":[[0,1.78,19.53],[1,1.8,16.66],[2,1.81,83.95]],"ltp":1.75,"tv":4746.83,"id":9634485},{"batl":[[0,2.36,6.25],[1,2.42,5.75],[2,2.64,3.79]],"ltp":2.12,"tv":1387.73,"id":9712888}]}]}
{"op":"mcm","clk":"4233678419","pt":1631537440714,"mc":[{"id":"1.187557759","rc":[{"batb":[[0,2.16,35.31],[1,1.97,46.53],[2,1.88,29.12]],"ltp":2.12,"tv":1387.73,"id":9712888}]}]}
{"op":"mcm","clk":"4233678658","pt":1631537443832,"mc":[{"id":"1.187557759","rc":[{"batl":[[0,1.76,17.92],[1,1.78,19.53],[2,1.8,16.66]],"ltp":1.75,"tv":4746.83,"id":9634485},{"batl":[[1,2.42,71.41]],"ltp":2.12,"tv":1387.73,"id":9712888}]}]}
{"op":"mcm","clk":"4233678679","pt":1631537444106,"mc":[{"id":"1.187557759","rc":[{"batl":[[0,1.78,19.53],[1,1.8,16.66],[2,1.81,83.95]],"ltp":1.75,"tv":4746.83,"id":9634485},{"batl":[[1,2.42,5.75]],"ltp":2.12,"tv":1387.73,"id":9712888}]}]}
{"op":"mcm","clk":"4233678832","pt":1631537446510,"mc":[{"id":"1.187557759","rc":[{"batb":[[1,2.12,6.54],[2,2.08,8.56]],"batl":[[2,2.46,6.25]],"ltp":2.12,"tv":1387.73,"id":9712888}]}]}
{"op":"mcm","clk":"4233679055","pt":1631537449739,"mc":[{"id":"1.187557759","rc":[{"batb":[[0,2.16,105.67]],"ltp":2.12,"tv":1387.73,"id":9712888}]}]}
{"op":"mcm","clk":"4233679077","pt":1631537450054,"mc":[{"id":"1.187557759","rc":[{"batb":[[0,2.16,35.31]],"ltp":2.12,"tv":1387.73,"id":9712888}]}]}
{"op":"mcm","clk":"4233679776","pt":1631537459760,"mc":[{"id":"1.187557759","rc":[{"batb":[[0,2.16,105.67]],"ltp":2.12,"tv":1387.73,"id":9712888}]}]}
{"op":"mcm","clk":"4233679957","pt":1631537461767,"mc":[{"id":"1.187557759","rc":[{"batb":[[1,1.73,109.29],[2,1.72,8.72]],"batl":[[0,1.8,8.33],[1,1.81,79.78],[2,1.82,4.17]],"ltp":1.75,"tv":4746.83,"id":9634485},{"batl":[[0,2.42,5.75],[1,2.46,6.25],[2,2.52,6.26]],"ltp":2.12,"tv":1387.73,"id":9712888}]}]}
{"op":"mcm","clk":"4233680004","pt":1631537462333,"mc":[{"id":"1.187557759","rc":[{"batb":[[0,1.66,48.78],[1,1.6,46.36],[2,1.55,285.97]],"batl":[[0,1.92,25.31],[1,2.36,396.03],[2,1.82,0]],"ltp":1.75,"tv":4746.83,"id":9634485},{"batb":[[0,2.08,8.56],[1,1.97,46.53],[2,1.6,99.04]],"batl":[[0,2.52,6.26],[1,2.46,0],[2,2.52,0]],"ltp":2.12,"tv":1387.73,"id":9712888}]}]}
{"op":"mcm","clk":"4233680266","pt":1631537465736,"mc":[{"id":"1.187557759","rc":[{"batb":[[0,1.69,53.21],[1,1.66,163.06],[2,1.65,65]],"batl":[[0,1.88,28.79],[1,1.92,25.31],[2,1.97,86.69]],"ltp":1.75,"tv":4746.83,"id":9634485},{"batl":[[0,2.46,6.25],[1,2.52,6.26]],"ltp":2.12,"tv":1387.73,"id":9712888}]}]}
{"op":"mcm","clk":"4233680339","pt":1631537466769,"mc":[{"id":"1.187557759","rc":[{"batb":[[0,1.66,163.06],[1,1.65,65],[2,1.6,46.36]],"batl":[[0,1.92,25.31],[1,2,0.14],[2,1.97,0]],"ltp":1.75,"tv":4746.83,"id":9634485},{"batl":[[0,2.52,6.26],[1,2.52,0]],"ltp":2.12,"tv":1387.73,"id":9712888}]}]}
{"op":"mcm","clk":"4233680493","pt":1631537468754,"mc":[{"id":"1.187557759","rc":[{"trd":[[1.66,274.57]],"batb":[[0,1.66,547.4]],"batl":[[0,1.68,12.75],[1,1.71,52.63],[2,1.72,131.4]],"ltp":1.66,"tv":4758.87,"id":9634485},{"batb":[[0,2.32,338.85],[1,2.08,8.56],[2,1.97,46.53]],"batl":[[1,2.56,11.06]],"ltp":2.12,"tv":1387.73,"id":9712888}],"tv":6146.61}]}
{"op":"mcm","clk":"4233680576","pt":1631537469851,"mc":[{"id":"1.187557759","rc":[{"batl":[[1,1.71,17.54],[2,1.72,113.86]],"ltp":1.66,"tv":4758.87,"id":9634485},{"batl":[[2,2.58,34.88]],"ltp":2.12,"tv":1387.73,"id":9712888}]}]}
{"op":"mcm","clk":"4233680631","pt":1631537470738,"mc":[{"id":"1.187557759","rc":[{"batb":[[1,2.3,29.2],[2,2.16,34.89]],"batl":[[2,2.58,11.62]],"ltp":2.12,"tv":1387.73,"id":9712888}]}]}
{"op":"mcm","clk":"4233681047","pt":1631537476780,"mc":[{"id":"1.187557759","rc":[{"batb":[[2,1.64,51.07]],"ltp":1.66,"tv":4758.87,"id":9634485},{"batb":[[1,2.3,35.78],[2,2.26,6.98]],"batl":[[2,2.58,16.87]],"ltp":2.12,"tv":1387.73,"id":9712888}]}]}
{"op":"mcm","clk":"4233681323","pt":1631537481591,"mc":[{"id":"1.187557759","rc":[{"batb":[[0,1.64,51.07],[1,1.63,48.23],[2,1.55,52.13]],"batl":[[0,1.76,32.27],[1,1.79,28.5],[2,1.92,25.31]],"ltp":1.66,"tv":4758.87,"id":9634485},{"batb":[[0,2.3,6.58],[1,2.26,6.98],[2,2.16,34.89]],"batl":[[0,2.58,5.25],[1,2.6,5.86],[2,2.58,0]],"ltp":2.12,"tv":1387.73,"id":9712888}]}]}
{"op":"mcm","clk":"4233681399","pt":1631537482779,"mc":[{"id":"1.187557759","rc":[{"batb":[[0,1.63,48.23],[1,1.55,52.13],[2,1.46,294.69]],"batl":[[0,1.66,8.52],[2,2.22,429.8]],"ltp":1.66,"tv":4758.87,"id":9634485},{"batb":[[0,2.26,6.98],[1,2.16,34.89],[2,1.6,99.04]],"batl":[[0,2.6,5.86],[1,2.6,0]],"ltp":2.12,"tv":1387.73,"id":9712888}]}]}
{"op":"mcm","clk":"4233681640","pt":1631537486195,"mc":[{"id":"1.187557759","rc":[{"trd":[[1.66,283.09]],"batb":[[0,1.68,83.13],[1,1.67,62.18],[2,1.63,48.23]],"batl":[[0,1.73,68.75],[1,1.75,106.61],[2,1.79,28.5]],"ltp":1.66,"tv":4767.39,"id":9634485},{"trd":[[2.5,9.52]],"ltp":2.5,"tv":1393.38,"id":9712888}],"tv":6160.78}]}
{"op":"mcm","clk":"4233681778","pt":1631537488695,"mc":[{"id":"1.187557759","rc":[{"batb":[[2,1.64,46.82]],"batl":[[2,1.76,32.77]],"ltp":1.66,"tv":4767.39,"id":9634485},{"batb":[[0,2.3,6.98],[1,2.26,6.98],[2,2.16,34.89]],"batl":[[0,2.58,6.25],[1,2.6,5.86]],"ltp":2.5,"tv":1393.38,"id":9712888}]}]}
{"op":"mcm","clk":"4233681800","pt":1631537488994,"mc":[{"id":"1.187557759","rc":[{"batb":[[2,1.63,48.23]],"ltp":1.66,"tv":4767.39,"id":9634485},{"batl":[[0,2.6,5.86],[1,2.6,0]],"ltp":2.5,"tv":1393.38,"id":9712888}]}]}
{"op":"mcm","clk":"4233682066","pt":1631537493306,"mc":[{"id":"1.187557759","rc":[{"batb":[[0,1.63,48.23],[1,1.55,52.13],[2,1.46,294.69]],"batl":[[0,1.79,28.5],[1,2.22,429.8],[2,1.76,0]],"ltp":1.66,"tv":4767.39,"id":9634485},{"batb":[[0,2.26,6.98],[1,2.16,34.89],[2,1.6,99.04]],"ltp":2.5,"tv":1393.38,"id":9712888}]}]}
{"op":"mcm","clk":"4233682213","pt":1631537495593,"mc":[{"id":"1.187557759","rc":[{"batb":[[0,1.64,47.57],[1,1.63,48.23],[2,1.55,52.13]],"ltp":1.66,"tv":4767.39,"id":9634485},{"batl":[[0,2.58,5.25],[1,2.6,5.86]],"ltp":2.5,"tv":1393.38,"id":9712888}]}]}
{"op":"mcm","clk":"4233682265","pt":1631537496791,"mc":[{"id":"1.187557759","rc":[{"batb":[[0,1.63,48.23],[1,1.61,115.51],[2,1.6,72.78]],"batl":[[1,1.8,71.04],[2,1.82,93.75]],"ltp":1.66,"tv":4767.39,"id":9634485},{"batl":[[0,2.6,5.86],[1,2.6,0]],"ltp":2.5,"tv":1393.38,"id":9712888}]}]}
{"op":"mcm","clk":"4233682440","pt":1631537499416,"mc":[{"id":"1.187557759","rc":[{"batb":[[1,1.55,52.13],[2,1.46,294.69]],"ltp":1.66,"tv":4767.39,"id":9634485}]}]}
{"op":"mcm","clk":"4233682556","pt":1631537501189,"mc":[{"id":"1.187557759","rc":[{"batb":[[2,1.3,198.07]],"ltp":1.66,"tv":4767.39,"id":9634485}]}]}
{"op":"mcm","clk":"4233682634","pt":1631537502219,"mc":[{"id":"1.187557759","rc":[{"batb":[[0,1.75,22.86],[1,1.74,463.68],[2,1.72,213.26]],"ltp":1.66,"tv":4767.39,"id":9634485},{"batb":[[0,2.32,7.67],[1,2.26,6.98],[2,2.16,34.89]],"batl":[[0,2.42,11.75],[1,2.6,5.86],[2,2.66,3.76]],"ltp":2.5,"tv":1393.38,"id":9712888}]}]}
{"op":"mcm","clk":"4233682715","pt":1631537503609,"mc":[{"id":"1.187557759","rc":[{"trd":[[1.75,143.03]],"batb":[[0,1.75,17.05],[2,1.72,143.5]],"batl":[[1,1.8,87.7],[2,1.81,8.34]],"ltp":1.75,"tv":4779.01,"id":9634485}],"tv":6172.4}]}
{"op":"mcm","clk":"4233682932","pt":1631537507126,"mc":[{"id":"1.187557759","rc":[{"trd":[[1.75,177.13]],"batb":[[0,1.74,463.68],[1,1.72,143.5],[2,1.71,58.91]],"ltp":1.75,"tv":4813.11,"id":9634485}],"tv":6206.5}]}
{"op":"mcm","clk":"4233683073","pt":1631537509310,"mc":[{"id":"1.187557759","rc":[{"batl":[[1,2.52,5.76],[2,2.6,5.86]],"ltp":2.5,"tv":1393.38,"id":9712888}]}]}
{"op":"mcm","clk":"4233684073","pt":1631537523818,"mc":[{"id":"1.187557759","rc":[{"batb":[[0,1.63,48.23],[1,1.58,48.45],[2,1.52,290.46]],"batl":[[0,1.92,25.81],[1,2.22,429.66],[2,1.81,0]],"ltp":1.75,"tv":4813.11,"id":9634485},{"batb":[[0,2.08,8.31],[1,1.97,46.86],[2,1.7,16.97]],"batl":[[0,2.6,5.86],[1,2.52,0],[2,2.6,0]],"ltp":2.5,"tv":1393.38,"id":9712888}]}]}
{"op":"mcm","clk":"4233684354","pt":1631537527827,"mc":[{"id":"1.187557759","rc":[{"batb":[[0,1.77,104.49],[1,1.75,105.21],[2,1.63,48.23]],"batl":[[0,1.78,21.75],[1,1.84,100.18],[2,1.86,87.41]],"ltp":1.75,"tv":4813.11,"id":9634485},{"batb":[[0,2.28,20.91],[1,2.08,8.31],[2,1.97,46.86]],"batl":[[0,2.36,19.82],[1,2.6,5.86]],"ltp":2.5,"tv":1393.38,"id":9712888}]}]}
{"op":"mcm","clk":"4233684377","pt":1631537528146,"mc":[{"id":"1.187557759","rc":[{"batl":[[0,1.84,100.18],[1,1.86,87.41],[2,1.92,25.81]],"ltp":1.75,"tv":4813.11,"id":9634485},{"batb":[[0,2.08,8.31],[1,1.97,46.86],[2,1.6,99.04]],"batl":[[0,2.6,5.86],[1,2.6,0]],"ltp":2.5,"tv":1393.38,"id":9712888}]}]}
{"op":"mcm","clk":"4233684484","pt":1631537529654,"mc":[{"id":"1.187557759","rc":[{"batb":[[1,1.75,105.13]],"ltp":1.75,"tv":4813.11,"id":9634485}]}]}
{"op":"mcm","clk":"4233684529","pt":1631537530430,"mc":[{"id":"1.187557759","rc":[{"batb":[[2,1.66,48.78]],"batl":[[2,1.88,28.29]],"ltp":1.75,"tv":4813.11,"id":9634485},{"batl":[[0,2.52,5.26],[1,2.6,5.86]],"ltp":2.5,"tv":1393.38,"id":9712888}]}]}
{"op":"mcm","clk":"4233684669","pt":1631537532476,"mc":[{"id":"1.187557759","rc":[{"batb":[[0,1.77,104.57]],"ltp":1.75,"tv":4813.11,"id":9634485}]}]}
{"op":"mcm","clk":"4233684892","pt":1631537535253,"mc":[{"id":"1.187557759","rc":[{"batb":[[0,1.63,48.31],[1,1.58,48.45],[2,1.52,290.46]],"batl":[[0,1.92,25.81],[1,2.22,429.66],[2,1.88,0]],"ltp":1.75,"tv":4813.11,"id":9634485},{"batl":[[0,2.6,5.86],[1,2.6,0]],"ltp":2.5,"tv":1393.38,"id":9712888}]}]}
{"op":"mcm","clk":"4233685128","pt":1631537538751,"mc":[{"id":"1.187557759","rc":[{"batb":[[0,1.64,108.72],[1,1.63,116.17],[2,1.58,48.45]],"batl":[[1,1.98,67.5],[2,2,69.96]],"ltp":1.75,"tv":4813.11,"id":9634485}]}]}
{"op":"mcm","clk":"4233685209","pt":1631537539848,"mc":[{"id":"1.187557759","rc":[{"batl":[[1,2.22,429.66],[2,2,0]],"ltp":1.75,"tv":4813.11,"id":9634485}]}]}
{"op":"mcm","clk":"4233685215","pt":1631537539949,"mc":[{"id":"1.187557759","rc":[{"batl":[[0,2.22,429.66],[1,2.22,0]],"ltp":1.75,"tv":4813.11,"id":9634485}]}]}
{"op":"mcm","clk":"4233685322","pt":1631537541661,"mc":[{"id":"1.187557759","rc":[{"batb":[[0,2.12,7.04],[1,2.08,8.31],[2,1.97,46.86]],"ltp":2.5,"tv":1393.38,"id":9712888}]}]}
{"op":"mcm","clk":"4233685387","pt":1631537542759,"mc":[{"id":"1.187557759","rc":[{"trd":[[1.64,91.67],[1.77,17.02]],"batb":[[0,1.64,102.54]],"batl":[[0,1.66,11.79],[1,1.68,89.28],[2,1.69,348.81]],"ltp":1.64,"tv":4825.47,"id":9634485},{"batb":[[0,2.36,306.52],[1,2.34,85.48],[2,2.08,8.31]],"batl":[[0,2.56,253.05],[1,2.6,16.01]],"ltp":2.5,"tv":1393.38,"id":9712888}],"tv":6218.86}]}
{"op":"mcm","clk":"4233685449","pt":1631537543750,"mc":[{"id":"1.187557759","rc":[{"batb":[[2,1.61,18.64]],"batl":[[1,1.68,17.86],[2,1.69,74.54]],"ltp":1.64,"tv":4825.47,"id":9634485},{"batb":[[1,2.34,113.26],[2,2.18,34.39]],"batl":[[2,2.88,3.47]],"ltp":2.5,"tv":1393.38,"id":9712888}]}]}
{"op":"mcm","clk":"4233685717","pt":1631537547590,"mc":[{"id":"1.187557759","rc":[{"batl":[[0,1.66,17.14]],"ltp":1.64,"tv":4825.47,"id":9634485},{"batl":[[2,2.62,60.48]],"ltp":2.5,"tv":1393.38,"id":9712888}]}]}
{"op":"mcm","clk":"4233685733","pt":1631537547856,"mc":[{"id":"1.187557759","rc":[{"batl":[[0,1.66,11.79]],"ltp":1.64,"tv":4825.47,"id":9634485},{"batl":[[2,2.88,3.47]],"ltp":2.5,"tv":1393.38,"id":9712888}]}]}
{"op":"mcm","clk":"4233685989","pt":1631537551881,"mc":[{"id":"1.187557759","rc":[{"trd":[[1.66,283.12]],"batl":[[0,1.66,11.76]],"ltp":1.66,"tv":4825.5,"id":9634485},{"trd":[[2.5,9.54]],"ltp":2.5,"tv":1393.4,"id":9712888}],"tv":6218.91}]}
{"op":"mcm","clk":"4233686421","pt":1631537558413,"mc":[{"id":"1.187557759","rc":[{"trd":[[1.64,93.57]],"batb":[[0,1.64,101.59]],"ltp":1.64,"tv":4827.4,"id":9634485}],"tv":6220.81}]}
{"op":"mcm","clk":"4233686619","pt":1631537562081,"mc":[{"id":"1.187557759","rc":[{"batl":[[0,1.68,17.86],[1,1.69,74.54],[2,1.7,8.92]],"ltp":1.64,"tv":4827.4,"id":9634485},{"batl":[[1,2.6,5.86]],"ltp":2.5,"tv":1393.4,"id":9712888}]}]}
{"op":"mcm","clk":"4233686737","pt":1631537563899,"mc":[{"id":"1.187557759","rc":[{"batb":[[0,1.64,101.8]],"ltp":1.64,"tv":4827.4,"id":9634485}]}]}
{"op":"mcm","clk":"4233686802","pt":1631537564992,"mc":[{"id":"1.187557759","rc":[{"batl":[[0,1.66,11.76],[1,1.68,17.86],[2,1.69,74.54]],"ltp":1.64,"tv":4827.4,"id":9634485},{"batl":[[1,2.6,16.02]],"ltp":2.5,"tv":1393.4,"id":9712888}]}]}
{"op":"mcm","clk":"4233687173","pt":1631537570809,"mc":[{"id":"1.187557759","rc":[{"trd":[[1.66,291.62]],"batl":[[0,1.66,3.26]],"ltp":1.66,"tv":4835.9,"id":9634485},{"trd":[[2.5,15.19]],"ltp":2.5,"tv":1399.05,"id":9712888}],"tv":6234.96}]}
{"op":"mcm","clk":"4233687554","pt":1631537577127,"mc":[{"id":"1.187557759","rc":[{"batb":[[0,2.36,1495.4]],"ltp":2.5,"tv":1399.05,"id":9712888}]}]}
{"op":"mcm","clk":"4233687808","pt":1631537581442,"mc":[{"id":"1.187557759","rc":[{"batl":[[0,1.68,17.86],[1,1.69,74.54],[2,1.7,8.92]],"ltp":1.66,"tv":4835.9,"id":9634485},{"batb":[[0,2.36,306.52]],"batl":[[1,2.6,5.86]],"ltp":2.5,"tv":1399.05,"id":9712888}]}]}
{"op":"mcm","clk":"4233687914","pt":1631537583939,"mc":[{"id":"1.187557759","rc":[{"batb":[[0,2.5,5.53],[1,2.36,306.52],[2,2.34,113.26]],"batl":[[0,2.56,260.52]],"ltp":2.5,"tv":1399.05,"id":9712888}]}]}
{"op":"mcm","clk":"4233689200","pt":1631537607885,"mc":[{"id":"1.187557759","rc":[{"trd":[[2.5,16.99]],"batb":[[0,2.5,4.63]],"ltp":2.5,"tv":1400.85,"id":9712888}],"tv":6236.76}]}
{"op":"mcm","clk":"4233689361","pt":1631537610799,"mc":[{"id":"1.187557759","rc":[{"trd":[[1.67,42.93]],"ltp":1.67,"tv":4836.37,"id":9634485},{"trd":[[2.5,17.3]],"batb":[[0,2.5,4.32]],"ltp":2.5,"tv":1401.16,"id":9712888}],"tv":6237.53}]}
{"op":"mcm","clk":"4233689779","pt":1631537618085,"mc":[{"id":"1.187557759","rc":[{"batb":[[0,2.36,306.52],[1,2.34,113.26],[2,2.18,34.39]],"batl":[[0,2.56,253.05]],"ltp":2.5,"tv":1401.16,"id":9712888}]}]}
{"op":"mcm","clk":"4233689862","pt":1631537619485,"mc":[{"id":"1.187557759","rc":[{"trd":[[1.64,96.19],[1.65,0.42]],"batb":[[0,1.64,100.28]],"ltp":1.64,"tv":4839.41,"id":9634485}],"tv":6240.58}]}
{"op":"mcm","clk":"4233690177","pt":1631537624585,"mc":[{"id":"1.187557759","rc":[{"trd":[[1.68,679.33]],"batl":[[0,1.68,34.13]],"ltp":1.68,"tv":4839.43,"id":9634485},{"batl":[[0,2.56,261.7]],"ltp":2.5,"tv":1401.16,"id":9712888}],"tv":6240.59}]}
{"op":"mcm","clk":"4233690697","pt":1631537633516,"mc":[{"id":"1.187557759","rc":[{"batb":[[1,2.34,119.98],[2,2.28,6.91]],"batl":[[2,2.82,5.25]],"ltp":2.5,"tv":1401.16,"id":9712888}]}]}
{"op":"mcm","clk":"4233691224","pt":1631537641467,"mc":[{"id":"1.187557759","rc":[{"trd":[[1.64,97.09]],"batb":[[0,1.64,99.83]],"ltp":1.64,"tv":4840.33,"id":9634485}],"tv":6241.49}]}
{"op":"mcm","clk":"4233691297","pt":1631537642666,"mc":[{"id":"1.187557759","rc":[{"batb":[[0,1.52,290.46],[1,1.51,52.99],[2,1.48,62.34]],"batl":[[0,1.77,29.63],[1,2.22,429.66],[2,2.56,0.14]],"ltp":1.64,"tv":4840.33,"id":9634485},{"batb":[[0,2.28,6.91],[1,2.18,34.39],[2,1.7,16.97]],"batl":[[0,2.98,4.25],[1,2.6,0],[2,2.82,0]],"ltp":2.5,"tv":1401.16,"id":9712888}]}]}
{"op":"mcm","clk":"4233691468","pt":1631537645638,"mc":[{"id":"1.187557759","rc":[{"batb":[[0,1.55,50.79],[1,1.53,137.74],[2,1.52,379.35]],"batl":[[0,1.74,35.75],[1,1.77,29.63],[2,1.79,106.8]],"ltp":1.64,"tv":4840.33,"id":9634485},{"batb":[[0,2.34,6.72],[1,2.28,6.91],[2,2.18,34.39]],"batl":[[0,2.82,4.75],[1,2.98,4.25]],"ltp":2.5,"tv":1401.16,"id":9712888}]}]}
{"op":"mcm","clk":"4233691480","pt":1631537645951,"mc":[{"id":"1.187557759","rc":[{"batb":[[0,1.53,137.74],[1,1.52,379.35],[2,1.51,52.99]],"batl":[[0,1.77,29.63],[1,1.79,106.8],[2,1.81,95.35]],"ltp":1.64,"tv":4840.33,"id":9634485},{"batb":[[0,2.28,6.91],[1,2.18,34.39],[2,1.7,16.97]],"batl":[[0,2.98,4.25],[1,2.98,0]],"ltp":2.5,"tv":1401.16,"id":9712888}]}]}
{"op":"mcm","clk":"4233691643","pt":1631537648661,"mc":[{"id":"1.187557759","rc":[{"batb":[[0,1.52,290.46],[1,1.51,52.99],[2,1.48,62.34]],"batl":[[1,2.22,429.66],[2,2.56,0.14]],"ltp":1.64,"tv":4840.33,"id":9634485}]}]}
{"op":"mcm","clk":"4233691751","pt":1631537650175,"mc":[{"id":"1.187557759","rc":[{"batb":[[0,1.51,52.99],[1,1.48,62.34],[2,1.3,198.07]],"ltp":1.64,"tv":4840.33,"id":9634485}]}]}
{"op":"mcm","clk":"4233691833","pt":1631537651674,"mc":[{"id":"1.187557759","rc":[{"batb":[[0,1.62,86.75],[1,1.61,71.04],[2,1.51,52.99]],"batl":[[0,1.67,98.47],[1,1.69,119.89],[2,1.77,29.63]],"ltp":1.64,"tv":4840.33,"id":9634485}]}]}
{"op":"mcm","clk":"4233691905","pt":1631537652782,"mc":[{"id":"1.187557759","rc":[{"batb":[[2,1.55,48.59]],"batl":[[2,1.74,35.75]],"ltp":1.64,"tv":4840.33,"id":9634485},{"batb":[[0,2.34,6.22],[1,2.28,6.91],[2,2.18,34.39]],"batl":[[0,2.82,4.75],[1,2.98,4.25]],"ltp":2.5,"tv":1401.16,"id":9712888}]}]}
{"op":"mcm","clk":"4233691968","pt":1631537653670,"mc":[{"id":"1.187557759","rc":[{"batb":[[2,1.51,52.99]],"ltp":1.64,"tv":4840.33,"id":9634485},{"batl":[[0,2.98,4.25],[1,2.98,0]],"ltp":2.5,"tv":1401.16,"id":9712888}]}]}
{"op":"mcm","clk":"4233692016","pt":1631537654457,"mc":[{"id":"1.187557759","rc":[{"batb":[[0,1.51,52.99],[1,1.48,62.34],[2,1.44,298]],"batl":[[0,1.77,29.63],[1,2.22,429.66],[2,2.56,0.14]],"ltp":1.64,"tv":4840.33,"id":9634485},{"batb":[[0,2.28,6.91],[1,2.18,34.39],[2,1.7,16.97]],"ltp":2.5,"tv":1401.16,"id":9712888}]}]}
{"op":"mcm","clk":"4233692184","pt":1631537656960,"mc":[{"id":"1.187557759","rc":[{"batb":[[0,1.53,137.74],[1,1.52,88.89],[2,1.51,52.99]],"batl":[[1,1.79,106.8],[2,1.81,95.35]],"ltp":1.64,"tv":4840.33,"id":9634485}]}]}
{"op":"mcm","clk":"4233692695","pt":1631537663790,"mc":[{"id":"1.187557759","rc":[{"batb":[[0,1.55,53.19],[1,1.53,137.74],[2,1.52,88.89]],"ltp":1.64,"tv":4840.33,"id":9634485},{"batl":[[0,2.82,4.75],[1,2.98,4.25]],"ltp":2.5,"tv":1401.16,"id":9712888}]}]}
{"op":"mcm","clk":"4233692706","pt":1631537663996,"mc":[{"id":"1.187557759","rc":[{"batb":[[0,1.53,137.74],[1,1.52,88.89],[2,1.51,52.99]],"ltp":1.64,"tv":4840.33,"id":9634485},{"batl":[[0,2.98,4.25],[1,2.98,0]],"ltp":2.5,"tv":1401.16,"id":9712888}]}]}
{"op":"mcm","clk":"4233693028","pt":1631537669401,"mc":[{"id":"1.187557759","rc":[{"batb":[[0,1.51,52.99],[1,1.48,62.34],[2,1.44,298]],"ltp":1.64,"tv":4840.33,"id":9634485}]}]}
{"op":"mcm","clk":"4233693117","pt":1631537670714,"mc":[{"id":"1.187557759","rc":[{"batb":[[0,1.55,51.39],[1,1.51,52.99],[2,1.48,62.34]],"ltp":1.64,"tv":4840.33,"id":9634485},{"batl":[[0,2.82,5.25],[1,2.98,4.25]],"ltp":2.5,"tv":1401.16,"id":9712888}]}]}
{"op":"mcm","clk":"4233693161","pt":1631537671501,"mc":[{"id":"1.187557759","rc":[{"batb":[[0,1.51,52.99],[1,1.48,62.34],[2,1.3,198.07]],"ltp":1.64,"tv":4840.33,"id":9634485},{"batl":[[0,2.98,4.25],[1,2.98,0]],"ltp":2.5,"tv":1401.16,"id":9712888}]}]}
{"op":"mcm","clk":"4233693231","pt":1631537672604,"mc":[{"id":"1.187557759","rc":[{"batb":[[0,1.73,70.82],[1,1.72,536.52],[2,1.71,113.72]],"ltp":1.64,"tv":4840.33,"id":9634485},{"batb":[[0,2.32,5.95],[1,2.28,6.91],[2,2.18,34.39]],"batl":[[0,2.4,74.39],[1,2.42,31.24],[2,2.44,31.24]],"ltp":2.5,"tv":1401.16,"id":9712888}]}]}
{"op":"mcm","clk":"4233693310","pt":1631537673801,"mc":[{"id":"1.187557759","rc":[{"trd":[[1.73,23.32]],"batb":[[0,1.73,64.97]],"batl":[[2,1.8,16.66]],"ltp":1.73,"tv":4852.03,"id":9634485},{"batl":[[0,2.4,24.39],[1,2.42,6.24],[2,2.44,6.24]],"ltp":2.5,"tv":1401.16,"id":9712888}],"tv":6253.19}]}
{"op":"mcm","clk":"4233693327","pt":1631537674007,"mc":[{"id":"1.187557759","rc":[{"batl":[[1,1.8,16.66],[2,1.81,8.34]],"ltp":1.73,"tv":4852.03,"id":9634485}]}]}
{"op":"mcm","clk":"4233693535","pt":1631537677403,"mc":[{"id":"1.187557759","rc":[{"batl":[[1,1.78,61.04],[2,1.8,113.88]],"ltp":1.73,"tv":4852.03,"id":9634485}]}]}
{"op":"mcm","clk":"4233693681","pt":1631537679327,"mc":[{"id":"1.187557759","rc":[{"batb":[[2,2.22,7.43]],"ltp":2.5,"tv":1401.16,"id":9712888}]}]}
{"op":"mcm","clk":"4233693807","pt":1631537681047,"mc":[{"id":"1.187557759","rc":[{"batl":[[2,1.8,148.3]],"ltp":1.73,"tv":4852.03,"id":9634485},{"batb":[[2,2.24,6.77]],"ltp":2.5,"tv":1401.16,"id":9712888}]}]}
{"op":"mcm","clk":"4233694517","pt":1631537692757,"mc":[{"id":"1.187557759","rc":[{"batb":[[1,1.72,50.09]],"batl":[[2,1.8,131.64]],"ltp":1.73,"tv":4852.03,"id":9634485},{"batb":[[0,2.28,6.91],[1,2.24,6.77],[2,2.22,7.43]],"batl":[[0,2.4,11.89],[1,2.54,5.75],[2,2.62,5.75]],"ltp":2.5,"tv":1401.16,"id":9712888}]}]}
{"op":"mcm","clk":"4233694540","pt":1631537693136,"mc":[{"id":"1.187557759","rc":[{"batb":[[0,1.62,45.04],[1,1.56,50.71],[2,1.5,288.58]],"batl":[[0,1.83,27.5],[1,2.22,429.66],[2,1.8,0]],"ltp":1.73,"tv":4852.03,"id":9634485},{"batb":[[0,2.2,7.17],[1,2.06,40.5],[2,1.7,16.97]],"batl":[[0,2.62,5.75],[1,2.54,0],[2,2.62,0]],"ltp":2.5,"tv":1401.16,"id":9712888}]}]}
{"op":"mcm","clk":"4233694654","pt":1631537694846,"mc":[{"id":"1.187557759","rc":[{"batl":[[0,1.83,27.7]],"ltp":1.73,"tv":4852.03,"id":9634485}]}]}
{"op":"mcm","clk":"4233694716","pt":1631537695843,"mc":[{"id":"1.187557759","rc":[{"batb":[[0,1.62,140.39],[1,1.61,71.08],[2,1.56,50.71]],"batl":[[1,1.87,68.68],[2,1.89,83.2]],"ltp":1.73,"tv":4852.03,"id":9634485}]}]}
{"op":"mcm","clk":"4233694768","pt":1631537696657,"mc":[{"id":"1.187557759","rc":[{"batl":[[0,1.83,27.5]],"ltp":1.73,"tv":4852.03,"id":9634485}]}]}
{"op":"mcm","clk":"4233694826","pt":1631537697550,"mc":[{"id":"1.187557759","rc":[{"batl":[[1,2.22,429.66],[2,1.89,0]],"ltp":1.73,"tv":4852.03,"id":9634485}]}]}
{"op":"mcm","clk":"4233694949","pt":1631537699770,"mc":[{"id":"1.187557759","rc":[{"batl":[[0,1.81,30.5],[1,1.83,27.5],[2,2.22,429.66]],"ltp":1.73,"tv":4852.03,"id":9634485},{"batb":[[0,2.22,6.84],[1,2.2,7.17],[2,2.06,40.5]],"ltp":2.5,"tv":1401.16,"id":9712888}]}]}
{"op":"mcm","clk":"4233695002","pt":1631537700462,"mc":[{"id":"1.187557759","rc":[{"trd":[[1.62,28.94]],"batb":[[0,1.62,553.97]],"batl":[[0,1.66,16.66],[1,1.67,90.3],[2,1.69,119.95]],"ltp":1.62,"tv":4864.37,"id":9634485},{"batb":[[0,2.5,12],[1,2.48,6],[2,2.46,6]],"batl":[[0,2.6,6.93],[1,2.62,5.75]],"ltp":2.5,"tv":1401.16,"id":9712888}],"tv":6265.53}]}
{"op":"mcm","clk":"4233695102","pt":1631537701770,"mc":[{"id":"1.187557759","rc":[{"batl":[[2,2.68,11.2]],"ltp":2.5,"tv":1401.16,"id":9712888}]}]}
{"op":"mcm","clk":"4233695961","pt":1631537714783,"mc":[{"id":"1.187557759","rc":[{"batb":[[0,1.5,288.58],[1,1.47,59.67],[2,1.45,67.7]],"batl":[[0,1.78,34.25],[1,2.22,429.66],[2,1.69,0]],"ltp":1.62,"tv":4864.37,"id":9634485},{"batb":[[0,2.28,6.66],[1,2.2,33.56],[2,1.8,11.88]],"batl":[[0,3.15,3.7],[1,2.62,0],[2,2.68,0]],"ltp":2.5,"tv":1401.16,"id":9712888}]}]}
{"op":"mcm","clk":"4233696168","pt":1631537717775,"mc":[{"id":"1.187557759","rc":[{"batb":[[0,1.51,55.99],[1,1.5,395.02],[2,1.49,96.22]],"batl":[[0,1.78,140.05],[1,1.8,97.09],[2,2.22,429.66]],"ltp":1.62,"tv":4864.37,"id":9634485},{"batl":[[0,2.98,3.75],[1,3.15,3.7]],"ltp":2.5,"tv":1401.16,"id":9712888}]}]}
{"op":"mcm","clk":"4233696194","pt":1631537718192,"mc":[{"id":"1.187557759","rc":[{"batb":[[0,1.5,395.02],[1,1.49,96.22],[2,1.47,59.67]],"ltp":1.62,"tv":4864.37,"id":9634485},{"batl":[[0,3.15,3.7],[1,3.15,0]],"ltp":2.5,"tv":1401.16,"id":9712888}]}]}
