{"op":"mcm","clk":"4222579854","pt":1631443439549,"mc":[{"id":"1.187553166","marketDefinition":{"bspMarket":false,"turnInPlayEnabled":true,"persistenceEnabled":true,"marketBaseRate":5.0,"eventId":"30895352","eventTypeId":"2","numberOfWinners":1,"bettingType":"ODDS","marketType":"MATCH_ODDS","marketTime":"2021-09-12T16:30:00.000Z","suspendTime":"2021-09-12T16:30:00.000Z","bspReconciled":false,"complete":true,"inPlay":false,"crossMatching":false,"runnersVoidable":false,"numberOfActiveRunners":2,"betDelay":0,"status":"OPEN","runners":[{"status":"ACTIVE","sortPriority":1,"id":17982600,"name":"N Ugrelidze"},{"status":"ACTIVE","sortPriority":2,"id":13689566,"name":"E Shalimova"}],"regulators":["MR_INT"],"countryCode":"GB","discountAllowed":false,"timezone":"GMT","openDate":"2021-09-12T16:30:00.000Z","version":4027795450,"name":"Match Odds","eventName":"N Ugrelidze v E Shalimova"},"rc":[{"batb":[[0,1.01,25]],"ltp":0.0,"tv":0.0,"id":17982600},{"batb":[[0,1.01,25]],"ltp":0.0,"tv":0.0,"id":13689566}]}]}
{"op":"mcm","clk":"4222580148","pt":1631443441310,"mc":[{"id":"1.187553166","marketDefinition":{"bspMarket":false,"turnInPlayEnabled":true,"persistenceEnabled":true,"marketBaseRate":5.0,"eventId":"30895352","eventTypeId":"2","numberOfWinners":1,"bettingType":"ODDS","marketType":"MATCH_ODDS","marketTime":"2021-09-12T16:30:00.000Z","suspendTime":"2021-09-12T16:30:00.000Z","bspReconciled":false,"complete":true,"inPlay":false,"crossMatching":false,"runnersVoidable":false,"numberOfActiveRunners":2,"betDelay":0,"status":"OPEN","runners":[{"status":"ACTIVE","sortPriority":1,"id":17982600,"name":"N Ugrelidze"},{"status":"ACTIVE","sortPriority":2,"id":13689566,"name":"E Shalimova"}],"regulators":["MR_INT"],"countryCode":"GB","discountAllowed":true,"timezone":"GMT","openDate":"2021-09-12T16:30:00.000Z","version":4027795450,"name":"Match Odds","eventName":"N Ugrelidze v E Shalimova"}}]}
{"op":"mcm","clk":"4222727778","pt":1631444411648,"mc":[{"id":"1.187553166","rc":[{"batb":[[0,1.01,7]],"ltp":0.0,"tv":0.0,"id":17982600},{"batb":[[0,1.01,7]],"ltp":0.0,"tv":0.0,"id":13689566}]}]}
{"op":"mcm","clk":"4222743003","pt":1631444493861,"mc":[{"id":"1.187553166","rc":[{"batb":[[0,1.01,12]],"ltp":0.0,"tv":0.0,"id":17982600},{"batb":[[0,1.01,12]],"ltp":0.0,"tv":0.0,"id":13689566}]}]}
{"op":"mcm","clk":"4222860986","pt":1631445139654,"mc":[{"id":"1.187553166","rc":[{"batl":[[0,990,2.2]],"ltp":0.0,"tv":0.0,"id":17982600},{"batl":[[0,990,2.2]],"ltp":0.0,"tv":0.0,"id":13689566}]}]}
{"op":"mcm","clk":"4222999607","pt":1631445819860,"mc":[{"id":"1.187553166","rc":[{"batb":[[0,1.02,108.45],[1,1.01,12]],"ltp":0.0,"tv":0.0,"id":17982600},{"batb":[[0,1.02,108.45],[1,1.01,12]],"ltp":0.0,"tv":0.0,"id":13689566}]}]}
{"op":"mcm","clk":"4223004595","pt":1631445846859,"mc":[{"id":"1.187553166","marketDefinition":{"bspMarket":false,"turnInPlayEnabled":true,"persistenceEnabled":true,"marketBaseRate":5.0,"eventId":"30895352","eventTypeId":"2","numberOfWinners":1,"bettingType":"ODDS","marketType":"MATCH_ODDS","marketTime":"2021-09-12T16:30:00.000Z","suspendTime":"2021-09-12T16:30:00.000Z","bspReconciled":false,"complete":true,"inPlay":false,"crossMatching":true,"runnersVoidable":false,"numberOfActiveRunners":2,"betDelay":0,"status":"OPEN","runners":[{"status":"ACTIVE","sortPriority":1,"id":17982600,"name":"N Ugrelidze"},{"status":"ACTIVE","sortPriority":2,"id":13689566,"name":"E Shalimova"}],"regulators":["MR_INT"],"countryCode":"GB","discountAllowed":true,"timezone":"GMT","openDate":"2021-09-12T16:30:00.000Z","version":4027795450,"name":"Match Odds","eventName":"N Ugrelidze v E Shalimova"}}]}
{"op":"mcm","clk":"4223337640","pt":1631447563300,"mc":[{"id":"1.187553166","rc":[{"batl":[[0,2,40],[1,990,2.2]],"ltp":0.0,"tv":0.0,"id":13689566}]}]}
{"op":"mcm","clk":"4223641536","pt":1631449245862,"mc":[{"id":"1.187553166","rc":[{"batb":[[0,1.02,2307.21]],"batl":[[0,1.98,43.98],[1,2,40],[2,990,2.2]],"ltp":0.0,"tv":0.0,"id":13689566}]}]}
{"op":"mcm","clk":"4224168734","pt":1631452062049,"mc":[{"id":"1.187553166","rc":[{"batl":[[0,1.72,2.66],[1,1.98,43.98],[2,2,40]],"ltp":0.0,"tv":0.0,"id":13689566}]}]}
{"op":"mcm","clk":"4224475772","pt":1631453516860,"mc":[{"id":"1.187553166","rc":[{"batl":[[0,1.7,43.98],[1,1.72,2.66]],"ltp":0.0,"tv":0.0,"id":13689566}]}]}
{"op":"mcm","clk":"4224496340","pt":1631453617869,"mc":[{"id":"1.187553166","rc":[{"batl":[[0,1.41,2],[1,1.7,43.98],[2,1.72,2.66]],"ltp":0.0,"tv":0.0,"id":13689566}]}]}
{"op":"mcm","clk":"4224516725","pt":1631453720200,"mc":[{"id":"1.187553166","rc":[{"batb":[[1,1.01,1720.09]],"ltp":0.0,"tv":0.0,"id":13689566}]}]}
{"op":"mcm","clk":"4224518642","pt":1631453729911,"mc":[{"id":"1.187553166","rc":[{"batb":[[1,1.01,3428.18]],"ltp":0.0,"tv":0.0,"id":13689566}]}]}
{"op":"mcm","clk":"4224578287","pt":1631454041565,"mc":[{"id":"1.187553166","rc":[{"batb":[[1,1.01,12]],"ltp":0.0,"tv":0.0,"id":13689566}]}]}
{"op":"mcm","clk":"4224839699","pt":1631455500661,"mc":[{"id":"1.187553166","rc":[{"batl":[[0,1.4,40],[1,1.41,2],[2,1.7,43.98]],"ltp":0.0,"tv":0.0,"id":13689566}]}]}
{"op":"mcm","clk":"4225121861","pt":1631456847564,"mc":[{"id":"1.187553166","rc":[{"batb":[[1,1.01,4282.22]],"ltp":0.0,"tv":0.0,"id":13689566}]}]}
{"op":"mcm","clk":"4225141637","pt":1631456956924,"mc":[{"id":"1.187553166","rc":[{"batl":[[0,1.38,43.98],[1,1.4,40],[2,1.41,2]],"ltp":0.0,"tv":0.0,"id":13689566}]}]}
{"op":"mcm","clk":"4225942686","pt":1631461195088,"mc":[{"id":"1.187553166","rc":[{"batl":[[0,1.06,124.52],[1,1.38,43.98],[2,1.4,40]],"ltp":0.0,"tv":0.0,"id":13689566}]}]}
{"op":"mcm","clk":"4225945911","pt":1631461211626,"mc":[{"id":"1.187553166","rc":[{"batl":[[1,1.13,81.69],[2,1.38,43.98]],"ltp":0.0,"tv":0.0,"id":13689566}]}]}
{"op":"mcm","clk":"4226024761","pt":1631461646334,"mc":[{"id":"1.187553166","rc":[{"batb":[[1,1.01,4285.11]],"ltp":0.0,"tv":0.0,"id":13689566}]}]}
{"op":"mcm","clk":"4226028002","pt":1631461665485,"mc":[{"id":"1.187553166","rc":[{"batb":[[1,1.01,4285.83]],"ltp":0.0,"tv":0.0,"id":13689566}]}]}
{"op":"mcm","clk":"4226038450","pt":1631461675921,"mc":[{"id":"1.187553166","rc":[{"batb":[[0,1.02,2307.93],[1,1.01,4282.22]],"ltp":0.0,"tv":0.0,"id":13689566}]}]}
{"op":"mcm","clk":"4226135555","pt":1631462253288,"mc":[{"id":"1.187553166","rc":[{"batb":[[1,1.01,4367.62]],"batl":[[0,1.08,124.52]],"ltp":0.0,"tv":0.0,"id":13689566}]}]}
{"op":"mcm","clk":"4226136040","pt":1631462256396,"mc":[{"id":"1.187553166","rc":[{"batl":[[0,1.08,38.17]],"ltp":0.0,"tv":0.0,"id":13689566}]}]}
{"op":"mcm","clk":"4226136751","pt":1631462261294,"mc":[{"id":"1.187553166","rc":[{"batb":[[1,1.01,4282.22]],"batl":[[0,1.09,38.17]],"ltp":0.0,"tv":0.0,"id":13689566}]}]}
{"op":"mcm","clk":"4226205199","pt":1631462642795,"mc":[{"id":"1.187553166","rc":[{"batb":[[0,9.4,10],[1,1.02,108.45],[2,1.01,12]],"ltp":0.0,"tv":0.0,"id":17982600},{"batb":[[0,1.05,2.89],[1,1.04,500],[2,1.02,2307.93]],"ltp":0.0,"tv":0.0,"id":13689566}]}]}
{"op":"mcm","clk":"4226205323","pt":1631462643493,"mc":[{"id":"1.187553166","rc":[{"batb":[[2,1.03,86.12]],"ltp":0.0,"tv":0.0,"id":13689566}]}]}
{"op":"mcm","clk":"4226208690","pt":1631462663125,"mc":[{"id":"1.187553166","marketDefinition":{"bspMarket":false,"turnInPlayEnabled":true,"persistenceEnabled":true,"marketBaseRate":5.0,"eventId":"30895352","eventTypeId":"2","numberOfWinners":1,"bettingType":"ODDS","marketType":"MATCH_ODDS","marketTime":"2021-09-12T16:30:00.000Z","suspendTime":"2021-09-12T16:30:00.000Z","bspReconciled":false,"complete":true,"inPlay":true,"crossMatching":true,"runnersVoidable":false,"numberOfActiveRunners":2,"betDelay":5,"status":"OPEN","runners":[{"status":"ACTIVE","sortPriority":1,"id":17982600,"name":"N Ugrelidze"},{"status":"ACTIVE","sortPriority":2,"id":13689566,"name":"E Shalimova"}],"regulators":["MR_INT"],"countryCode":"GB","discountAllowed":true,"timezone":"GMT","openDate":"2021-09-12T16:30:00.000Z","version":4029032998,"name":"Match Odds","eventName":"N Ugrelidze v E Shalimova"},"rc":[{"batb":[[0,1.01,12],[1,1.02,0],[2,1.01,0]],"ltp":0.0,"tv":0.0,"id":17982600},{"batb":[[0,1.01,12.72],[1,1.04,0],[2,1.03,0]],"batl":[[2,1.4,40]],"ltp":0.0,"tv":0.0,"id":13689566}]}]}
{"op":"mcm","clk":"4226217893","pt":1631462714495,"mc":[{"id":"1.187553166","rc":[{"batb":[[0,1.01,12]],"ltp":0.0,"tv":0.0,"id":13689566}]}]}
{"op":"mcm","clk":"4226218805","pt":1631462719630,"mc":[{"id":"1.187553166","rc":[{"batb":[[0,1.01,12.72]],"ltp":0.0,"tv":0.0,"id":13689566}]}]}
{"op":"mcm","clk":"4226245286","pt":1631462844650,"mc":[{"id":"1.187553166","rc":[{"batb":[[0,1.01,12]],"ltp":0.0,"tv":0.0,"id":13689566}]}]}
{"op":"mcm","clk":"4226246252","pt":1631462849715,"mc":[{"id":"1.187553166","rc":[{"batb":[[0,1.01,12.72]],"ltp":0.0,"tv":0.0,"id":13689566}]}]}
{"op":"mcm","clk":"4226252214","pt":1631462884512,"mc":[{"id":"1.187553166","rc":[{"batb":[[0,1.01,12]],"ltp":0.0,"tv":0.0,"id":13689566}]}]}
{"op":"mcm","clk":"4226253111","pt":1631462889223,"mc":[{"id":"1.187553166","marketDefinition":{"bspMarket":false,"turnInPlayEnabled":true,"persistenceEnabled":true,"marketBaseRate":5.0,"eventId":"30895352","eventTypeId":"2","numberOfWinners":1,"bettingType":"ODDS","marketType":"MATCH_ODDS","marketTime":"2021-09-12T16:08:08.000Z","suspendTime":"2021-09-12T16:08:08.000Z","bspReconciled":false,"complete":true,"inPlay":true,"crossMatching":true,"runnersVoidable":false,"numberOfActiveRunners":2,"betDelay":5,"status":"OPEN","runners":[{"status":"ACTIVE","sortPriority":1,"id":17982600,"name":"N Ugrelidze"},{"status":"ACTIVE","sortPriority":2,"id":13689566,"name":"E Shalimova"}],"regulators":["MR_INT"],"countryCode":"GB","discountAllowed":true,"timezone":"GMT","openDate":"2021-09-12T16:30:00.000Z","version":4029039828,"name":"Match Odds","eventName":"N Ugrelidze v E Shalimova"}}]}
{"op":"mcm","clk":"4226253177","pt":1631462889562,"mc":[{"id":"1.187553166","rc":[{"batb":[[0,1.01,12.72]],"ltp":0.0,"tv":0.0,"id":13689566}]}]}
{"op":"mcm","clk":"4226253615","pt":1631462892241,"mc":[{"id":"1.187553166","marketDefinition":{"bspMarket":false,"turnInPlayEnabled":true,"persistenceEnabled":true,"marketBaseRate":5.0,"eventId":"30895352","eventTypeId":"2","numberOfWinners":1,"bettingType":"ODDS","marketType":"MATCH_ODDS","marketTime":"2021-09-12T16:08:08.000Z","suspendTime":"2021-09-12T16:08:08.000Z","bspReconciled":false,"complete":true,"inPlay":true,"crossMatching":true,"runnersVoidable":false,"numberOfActiveRunners":2,"betDelay":5,"status":"OPEN","runners":[{"status":"ACTIVE","sortPriority":1,"id":17982600,"name":"N Ugrelidze"},{"status":"ACTIVE","sortPriority":2,"id":13689566,"name":"E Shalimova"}],"regulators":["MR_INT"],"countryCode":"GB","discountAllowed":true,"timezone":"GMT","openDate":"2021-09-12T16:08:08.000Z","version":4029039828,"name":"Match Odds","eventName":"N Ugrelidze v E Shalimova"}}]}
{"op":"mcm","clk":"4226267496","pt":1631462960565,"mc":[{"id":"1.187553166","rc":[{"batb":[[0,1.01,12]],"ltp":0.0,"tv":0.0,"id":13689566}]}]}
{"op":"mcm","clk":"4226268433","pt":1631462965681,"mc":[{"id":"1.187553166","rc":[{"batb":[[0,1.01,12.72]],"ltp":0.0,"tv":0.0,"id":13689566}]}]}
{"op":"mcm","clk":"4226290157","pt":1631463077204,"mc":[{"id":"1.187553166","rc":[{"batb":[[0,1.01,12]],"ltp":0.0,"tv":0.0,"id":13689566}]}]}
{"op":"mcm","clk":"4226306182","pt":1631463160763,"mc":[{"id":"1.187553166","rc":[{"batb":[[0,4.2,377.06],[1,1.01,12]],"batl":[[0,85,39.77]],"ltp":0.0,"tv":0.0,"id":17982600}]}]}
{"op":"mcm","clk":"4226310905","pt":1631463186785,"mc":[{"id":"1.187553166","rc":[{"batl":[[0,170,37.59]],"ltp":0.0,"tv":0.0,"id":17982600}]}]}
{"op":"mcm","clk":"4226316902","pt":1631463217965,"mc":[{"id":"1.187553166","rc":[{"batl":[[0,340,36.48]],"ltp":0.0,"tv":0.0,"id":17982600}]}]}
{"op":"mcm","clk":"4226318660","pt":1631463227459,"mc":[{"id":"1.187553166","rc":[{"batl":[[0,1.13,81.69],[1,1.4,40],[2,11.5,8.68]],"ltp":0.0,"tv":0.0,"id":13689566}]}]}
{"op":"mcm","clk":"4226319667","pt":1631463232581,"mc":[{"id":"1.187553166","rc":[{"batl":[[0,1.07,38.17],[1,1.13,81.69],[2,1.4,40]],"ltp":0.0,"tv":0.0,"id":13689566}]}]}
{"op":"mcm","clk":"4226323089","pt":1631463250007,"mc":[{"id":"1.187553166","rc":[{"batl":[[0,170,37.59]],"ltp":0.0,"tv":0.0,"id":17982600}]}]}
{"op":"mcm","clk":"4226328519","pt":1631463279118,"mc":[{"id":"1.187553166","rc":[{"batl":[[0,340,36.48]],"ltp":0.0,"tv":0.0,"id":17982600}]}]}
{"op":"mcm","clk":"4226351380","pt":1631463396340,"mc":[{"id":"1.187553166","rc":[{"batl":[[0,170,37.59]],"ltp":0.0,"tv":0.0,"id":17982600}]}]}
{"op":"mcm","clk":"4226359236","pt":1631463437469,"mc":[{"id":"1.187553166","rc":[{"batl":[[0,340,36.48]],"ltp":0.0,"tv":0.0,"id":17982600}]}]}
{"op":"mcm","clk":"4226543235","pt":1631464604203,"mc":[{"id":"1.187553166","rc":[{"batb":[[0,1.01,12],[1,1.01,0]],"ltp":0.0,"tv":0.0,"id":17982600}]}]}
{"op":"mcm","clk":"4226546454","pt":1631464625157,"mc":[{"id":"1.187553166","rc":[{"trd":[[1.01,24]],"batl":[[0,1.01,5.08],[1,1.07,38.17],[2,1.13,81.69]],"ltp":1.01,"tv":23.99,"id":13689566}],"tv":23.99}]}
{"op":"mcm","clk":"4226707039","pt":1631465761453,"mc":[{"id":"1.187553166","rc":[{"batb":[[0,4.5,380.19],[1,1.01,12]],"ltp":0.0,"tv":0.0,"id":17982600}]}]}
{"op":"mcm","clk":"4226756896","pt":1631466146109,"mc":[{"id":"1.187553166","rc":[{"batb":[[0,1.01,12],[1,1.01,0]],"ltp":0.0,"tv":0.0,"id":17982600}]}]}
{"op":"mcm","clk":"4226761261","pt":1631466174934,"mc":[{"id":"1.187553166","rc":[{"batb":[[0,4.7,377.71],[1,1.01,12]],"ltp":0.0,"tv":0.0,"id":17982600}]}]}
{"op":"mcm","clk":"4226764534","pt":1631466196367,"mc":[{"id":"1.187553166","rc":[{"batb":[[0,1.01,12],[1,1.01,0]],"ltp":0.0,"tv":0.0,"id":17982600}]}]}
{"op":"mcm","clk":"4226770561","pt":1631466239148,"mc":[{"id":"1.187553166","rc":[{"batb":[[0,4.6,380.58],[1,1.01,12]],"ltp":0.0,"tv":0.0,"id":17982600}]}]}
{"op":"mcm","clk":"4226785932","pt":1631466339984,"mc":[{"id":"1.187553166","rc":[{"batb":[[0,1.01,12],[1,1.01,0]],"ltp":0.0,"tv":0.0,"id":17982600}]}]}
{"op":"mcm","clk":"4226789815","pt":1631466363700,"mc":[{"id":"1.187553166","rc":[{"batb":[[0,4.8,372.81],[1,1.01,12]],"ltp":0.0,"tv":0.0,"id":17982600}]}]}
{"op":"mcm","clk":"4226791553","pt":1631466374121,"mc":[{"id":"1.187553166","rc":[{"batb":[[0,1.01,12],[1,1.01,0]],"ltp":0.0,"tv":0.0,"id":17982600}]}]}
{"op":"mcm","clk":"4226857667","pt":1631466778436,"mc":[{"id":"1.187553166","rc":[{"batb":[[0,1.03,6.96],[1,1.01,12]],"ltp":0.0,"tv":0.0,"id":17982600}]}]}
{"op":"mcm","clk":"4226858310","pt":1631466782452,"mc":[{"id":"1.187553166","rc":[{"batb":[[0,1.01,12],[1,1.01,0]],"ltp":0.0,"tv":0.0,"id":17982600}]}]}
{"op":"mcm","clk":"4226928791","pt":1631467141015,"mc":[{"id":"1.187553166","marketDefinition":{"bspMarket":false,"turnInPlayEnabled":true,"persistenceEnabled":true,"marketBaseRate":5.0,"eventId":"30895352","eventTypeId":"2","numberOfWinners":1,"bettingType":"ODDS","marketType":"MATCH_ODDS","marketTime":"2021-09-12T16:08:08.000Z","suspendTime":"2021-09-12T16:08:08.000Z","bspReconciled":false,"complete":true,"inPlay":true,"crossMatching":true,"runnersVoidable":false,"numberOfActiveRunners":2,"betDelay":5,"status":"SUSPENDED","runners":[{"status":"ACTIVE","sortPriority":1,"id":17982600,"name":"N Ugrelidze"},{"status":"ACTIVE","sortPriority":2,"id":13689566,"name":"E Shalimova"}],"regulators":["MR_INT"],"countryCode":"GB","discountAllowed":true,"timezone":"GMT","openDate":"2021-09-12T16:08:08.000Z","version":4029299813,"name":"Match Odds","eventName":"N Ugrelidze v E Shalimova"}}]}
{"op":"mcm","clk":"4226929415","pt":1631467144650,"mc":[{"id":"1.187553166","tv":0.0}]}
{"op":"mcm","clk":"4226929658","pt":1631467146055,"mc":[{"id":"1.187553166","marketDefinition":{"bspMarket":false,"turnInPlayEnabled":true,"persistenceEnabled":true,"marketBaseRate":5.0,"eventId":"30895352","eventTypeId":"2","numberOfWinners":1,"bettingType":"ODDS","marketType":"MATCH_ODDS","marketTime":"2021-09-12T16:08:08.000Z","suspendTime":"2021-09-12T16:08:08.000Z","bspReconciled":false,"complete":true,"inPlay":true,"crossMatching":false,"runnersVoidable":false,"numberOfActiveRunners":0,"betDelay":5,"status":"CLOSED","settledTime":"2021-09-12T17:19:03.000Z","runners":[{"status":"LOSER","sortPriority":1,"id":17982600,"name":"N Ugrelidze"},{"status":"WINNER","sortPriority":2,"id":13689566,"name":"E Shalimova"}],"regulators":["MR_INT"],"countryCode":"GB","discountAllowed":true,"timezone":"GMT","openDate":"2021-09-12T16:08:08.000Z","version":4029300423,"name":"Match Odds","eventName":"N Ugrelidze v E Shalimova"}}]}
