{"op":"mcm","clk":"4226331039","pt":1631448529060,"mc":[{"id":"1.187552454","rc":[{"trd":[[1.45,4884.47]],"batb":[[0,1.45,5279.33]],"batl":[[1,1.49,269.95]],"ltp":1.45,"tv":12741.34,"id":9028621}],"tv":14110.86}]}
{"op":"mcm","clk":"4226331430","pt":1631448531384,"mc":[{"id":"1.187552454","rc":[{"batb":[[1,3,3],[2,2.96,2.38]],"ltp":3.9,"tv":1369.51,"id":9345630}]}]}
{"op":"mcm","clk":"4226331586","pt":1631448532190,"mc":[{"id":"1.187552454","rc":[{"batl":[[0,1.46,3.42],[1,1.48,6],[2,1.49,269.95]],"ltp":1.45,"tv":12741.34,"id":9028621}]}]}
{"op":"mcm","clk":"4226331767","pt":1631448533155,"mc":[{"id":"1.187552454","rc":[{"trd":[[1.46,6.83],[1.48,96.71]],"batl":[[0,1.48,2.34],[1,1.49,269.95],[2,1.5,279.18]],"ltp":1.48,"tv":12755.49,"id":9028621}],"tv":14125.01}]}
{"op":"mcm","clk":"4226332036","pt":1631448534885,"mc":[{"id":"1.187552454","rc":[{"batl":[[0,1.47,416.77],[1,1.48,2.34],[2,1.49,269.95]],"ltp":1.48,"tv":12755.49,"id":9028621}]}]}
{"op":"mcm","clk":"4226332450","pt":1631448537187,"mc":[{"id":"1.187552454","rc":[{"batb":[[1,1.34,36.72],[2,1.33,656.59]],"ltp":1.48,"tv":12755.49,"id":9028621}]}]}
{"op":"mcm","clk":"4226332606","pt":1631448538090,"mc":[{"id":"1.187552454","rc":[{"batb":[[0,3.1,3],[1,3.05,5.09],[2,3,3]],"ltp":3.9,"tv":1369.51,"id":9345630},{"batb":[[2,1.32,39.89]],"batl":[[0,1.47,421.77],[1,1.48,26.83]],"ltp":1.48,"tv":12755.49,"id":9028621}]}]}
{"op":"mcm","clk":"4226332839","pt":1631448539376,"mc":[{"id":"1.187552454","rc":[{"trd":[[1.47,640.63]],"batl":[[0,1.47,101.46]],"ltp":1.47,"tv":13396.12,"id":9028621}],"tv":14765.64}]}
{"op":"mcm","clk":"4226333199","pt":1631448541598,"mc":[{"id":"1.187552454","rc":[{"trd":[[1.45,5825.29]],"batb":[[0,1.44,336.19]],"batl":[[0,1.45,4568.45],[1,1.47,101.46],[2,1.48,26.83]],"ltp":1.45,"tv":14336.94,"id":9028621}],"tv":15706.46}]}
{"op":"mcm","clk":"4226333372","pt":1631448542423,"mc":[{"id":"1.187552454","rc":[{"batl":[[0,3.55,3],[1,3.95,2],[2,4.2,2]],"ltp":3.9,"tv":1369.51,"id":9345630},{"batb":[[1,1.4,7],[2,1.34,36.72]],"ltp":1.45,"tv":14336.94,"id":9028621}]}]}
{"op":"mcm","clk":"4226333618","pt":1631448543825,"mc":[{"id":"1.187552454","rc":[{"batb":[[1,3.05,2.09],[2,2.96,2.38]],"ltp":3.9,"tv":1369.51,"id":9345630}]}]}
{"op":"mcm","clk":"4226333892","pt":1631448545587,"mc":[{"id":"1.187552454","rc":[{"batb":[[0,3.2,3],[1,3.15,3],[2,3.1,3]],"batl":[[0,3.3,3],[1,3.55,71.64],[2,3.95,2]],"ltp":3.9,"tv":1369.51,"id":9345630},{"trd":[[1.45,6359.66]],"batl":[[0,1.45,4307.26]],"ltp":1.45,"tv":14871.31,"id":9028621}],"tv":16240.83}]}
{"op":"mcm","clk":"4226334064","pt":1631448546511,"mc":[{"id":"1.187552454","rc":[{"batl":[[1,3.95,2],[2,4.2,2]],"ltp":3.9,"tv":1369.51,"id":9345630},{"batb":[[1,1.34,36.72],[2,1.33,16.16]],"ltp":1.45,"tv":14871.31,"id":9028621}]}]}
{"op":"mcm","clk":"4226334252","pt":1631448547578,"mc":[{"id":"1.187552454","rc":[{"batb":[[0,2.48,12.51],[1,2.34,13.22],[2,2.32,15.14]],"ltp":3.9,"tv":1369.51,"id":9345630},{"batb":[[0,1.33,16.16],[1,1.17,314.09],[2,1.1,296.65]],"batl":[[0,1.45,4301.26],[1,1.47,96.46],[2,1.64,33.04]],"ltp":1.45,"tv":14871.31,"id":9028621}]}]}
{"op":"mcm","clk":"4226334306","pt":1631448547908,"mc":[{"id":"1.187552454","rc":[{"batb":[[0,2.84,2.47],[1,2.68,2.36],[2,2.48,12.51]],"batl":[[0,3.9,2]],"ltp":3.9,"tv":1369.51,"id":9345630},{"batb":[[0,1.35,32.07],[1,1.33,16.16],[2,1.17,314.09]],"batl":[[2,1.54,21.75]],"ltp":1.45,"tv":14871.31,"id":9028621}]}]}
{"op":"mcm","clk":"4226334746","pt":1631448550420,"mc":[{"id":"1.187552454","rc":[{"batl":[[0,1.47,96.46],[1,1.54,21.75],[2,1.59,23.5]],"ltp":1.45,"tv":14871.31,"id":9028621}]}]}
{"op":"mcm","clk":"4226334913","pt":1631448551399,"mc":[{"id":"1.187552454","rc":[{"batb":[[0,2.68,2.36],[1,2.48,12.51],[2,2.34,13.22]],"batl":[[0,3.9,4]],"ltp":3.9,"tv":1369.51,"id":9345630},{"batb":[[0,1.37,7],[1,1.36,7],[2,1.35,40.07]],"batl":[[1,1.59,23.5],[2,1.64,33.04]],"ltp":1.45,"tv":14871.31,"id":9028621}]}]}
{"op":"mcm","clk":"4226335085","pt":1631448552415,"mc":[{"id":"1.187552454","rc":[{"batb":[[0,1.45,8.54],[1,1.37,7],[2,1.36,7]],"ltp":1.45,"tv":14871.31,"id":9028621}]}]}
{"op":"mcm","clk":"4226335207","pt":1631448553009,"mc":[{"id":"1.187552454","rc":[{"batb":[[1,1.38,505.98],[2,1.37,432.37]],"batl":[[1,1.58,263.57],[2,1.59,248.71]],"ltp":1.45,"tv":14871.31,"id":9028621}]}]}
{"op":"mcm","clk":"4226335491","pt":1631448554620,"mc":[{"id":"1.187552454","rc":[{"batl":[[0,3.65,2],[1,3.75,3],[2,3.9,4]],"ltp":3.9,"tv":1369.51,"id":9345630},{"batb":[[1,1.38,539.44]],"ltp":1.45,"tv":14871.31,"id":9028621}]}]}
{"op":"mcm","clk":"4226335700","pt":1631448555718,"mc":[{"id":"1.187552454","rc":[{"batb":[[1,1.38,557.57]],"ltp":1.45,"tv":14871.31,"id":9028621}]}]}
{"op":"mcm","clk":"4226336126","pt":1631448558141,"mc":[{"id":"1.187552454","rc":[{"batl":[[0,1.58,263.57],[1,1.59,248.71],[2,1.64,33.04]],"ltp":1.45,"tv":14871.31,"id":9028621}]}]}
{"op":"mcm","clk":"4226336536","pt":1631448560434,"mc":[{"id":"1.187552454","rc":[{"batb":[[1,1.38,539.44]],"ltp":1.45,"tv":14871.31,"id":9028621}]}]}
{"op":"mcm","clk":"4226336719","pt":1631448561405,"mc":[{"id":"1.187552454","rc":[{"batb":[[0,2.72,3],[1,2.7,4],[2,2.68,2.36]],"ltp":3.9,"tv":1369.51,"id":9345630},{"batl":[[0,1.52,96.46],[1,1.58,269.57],[2,1.59,248.71]],"ltp":1.45,"tv":14871.31,"id":9028621}]}]}
{"op":"mcm","clk":"4226336887","pt":1631448562324,"mc":[{"id":"1.187552454","rc":[{"batb":[[0,1.38,539.44],[1,1.37,432.37],[2,1.35,40.07]],"batl":[[0,1.58,269.57],[1,1.59,248.71],[2,1.64,33.04]],"ltp":1.45,"tv":14871.31,"id":9028621}]}]}
{"op":"mcm","clk":"4226337062","pt":1631448563527,"mc":[{"id":"1.187552454","rc":[{"batl":[[0,1.42,731.06],[1,1.43,508.16],[2,1.58,269.57]],"ltp":1.45,"tv":14871.31,"id":9028621}]}]}
{"op":"mcm","clk":"4226337084","pt":1631448563643,"mc":[{"id":"1.187552454","rc":[{"batb":[[2,1.35,32.07]],"ltp":1.45,"tv":14871.31,"id":9028621}]}]}
{"op":"mcm","clk":"4226337369","pt":1631448565212,"mc":[{"id":"1.187552454","rc":[{"trd":[[3.3,220.2],[3.35,338.1]],"ltp":3.3,"tv":1899.59,"id":9345630},{"trd":[[1.42,927.23],[1.43,511.57]],"batb":[[0,1.47,8.54],[1,1.38,539.44],[2,1.37,432.37]],"batl":[[0,1.58,269.57],[1,1.59,248.71],[2,1.64,33.04]],"ltp":1.43,"tv":16110.53,"id":9028621}],"tv":18010.13}]}
{"op":"mcm","clk":"4226337534","pt":1631448566320,"mc":[{"id":"1.187552454","rc":[{"batl":[[2,3.9,2]],"ltp":3.3,"tv":1899.59,"id":9345630},{"trd":[[1.47,657.71]],"batb":[[0,1.38,539.44],[1,1.37,432.37],[2,1.35,32.07]],"ltp":1.47,"tv":16127.61,"id":9028621}],"tv":18027.21}]}
{"op":"mcm","clk":"4226337986","pt":1631448569039,"mc":[{"id":"1.187552454","rc":[{"batl":[[2,1.64,30.15]],"ltp":1.47,"tv":16127.61,"id":9028621}]}]}
{"op":"mcm","clk":"4226338157","pt":1631448570158,"mc":[{"id":"1.187552454","rc":[{"batl":[[0,3.75,3],[1,3.9,2],[2,3.9,0]],"ltp":3.3,"tv":1899.59,"id":9345630},{"batb":[[0,1.37,7],[1,1.35,32.07],[2,1.33,16.16]],"batl":[[0,1.58,6],[1,1.59,23.5],[2,1.64,11.51]],"ltp":1.47,"tv":16127.61,"id":9028621}]}]}
{"op":"mcm","clk":"4226338763","pt":1631448573549,"mc":[{"id":"1.187552454","rc":[{"batb":[[0,2.68,2.36],[1,2.48,12.51],[2,2.34,13.22]],"batl":[[0,3.65,2]],"ltp":3.3,"tv":1899.59,"id":9345630},{"batb":[[0,1.38,30.96]],"batl":[[0,1.59,23.5],[1,1.64,11.51],[2,1.67,7.5]],"ltp":1.47,"tv":16127.61,"id":9028621}]}]}
{"op":"mcm","clk":"4226338900","pt":1631448574514,"mc":[{"id":"1.187552454","rc":[{"batl":[[0,3.9,2],[1,3.9,0]],"ltp":3.3,"tv":1899.59,"id":9345630},{"batb":[[0,1.35,32.07],[1,1.33,16.16],[2,1.2,385.63]],"batl":[[0,1.57,6.89],[1,1.59,23.5],[2,1.64,5.86]],"ltp":1.47,"tv":16127.61,"id":9028621}]}]}
{"op":"mcm","clk":"4226339061","pt":1631448575536,"mc":[{"id":"1.187552454","rc":[{"batb":[[0,2.84,2.72],[1,2.68,2.36],[2,2.48,12.51]],"ltp":3.3,"tv":1899.59,"id":9345630},{"batb":[[0,1.4,473.99],[1,1.35,32.07],[2,1.33,16.16]],"batl":[[0,1.54,24.25],[1,1.57,6.89],[2,1.59,23.5]],"ltp":1.47,"tv":16127.61,"id":9028621}]}]}
{"op":"mcm","clk":"4226339070","pt":1631448575631,"mc":[{"id":"1.187552454","rc":[{"batb":[[0,2.68,2.36],[1,2.48,12.51],[2,2.34,13.22]],"ltp":3.3,"tv":1899.59,"id":9345630},{"batl":[[0,1.57,6.89],[1,1.59,23.5],[2,1.64,5.86]],"ltp":1.47,"tv":16127.61,"id":9028621}]}]}
{"op":"mcm","clk":"4226339287","pt":1631448576863,"mc":[{"id":"1.187552454","rc":[{"batl":[[0,3.65,2],[1,3.9,2]],"ltp":3.3,"tv":1899.59,"id":9345630},{"batb":[[1,1.38,32.96],[2,1.35,32.07]],"ltp":1.47,"tv":16127.61,"id":9028621}]}]}
{"op":"mcm","clk":"4226339739","pt":1631448579522,"mc":[{"id":"1.187552454","rc":[{"batb":[[1,1.38,538.94],[2,1.37,425.37]],"batl":[[1,1.58,263.57],[2,1.59,248.71]],"ltp":1.47,"tv":16127.61,"id":9028621}]}]}
{"op":"mcm","clk":"4226340076","pt":1631448581450,"mc":[{"id":"1.187552454","rc":[{"batl":[[0,1.52,6.89],[1,1.53,6.89],[2,1.57,6.89]],"ltp":1.47,"tv":16127.61,"id":9028621}]}]}
{"op":"mcm","clk":"4226340254","pt":1631448582552,"mc":[{"id":"1.187552454","rc":[{"batb":[[0,2.84,2.47],[1,2.68,2.36],[2,2.48,12.51]],"ltp":3.3,"tv":1899.59,"id":9345630},{"batl":[[0,1.51,6.89],[1,1.52,6.89],[2,1.53,6.89]],"ltp":1.47,"tv":16127.61,"id":9028621}]}]}
{"op":"mcm","clk":"4226340269","pt":1631448582656,"mc":[{"id":"1.187552454","rc":[{"batb":[[0,2.68,2.36],[1,2.48,12.51],[2,2.34,13.22]],"ltp":3.3,"tv":1899.59,"id":9345630}]}]}
{"op":"mcm","clk":"4226341075","pt":1631448587435,"mc":[{"id":"1.187552454","rc":[{"trd":[[3.5,2]],"ltp":3.5,"tv":1901.59,"id":9345630},{"trd":[[1.4,33.92]],"batb":[[0,1.4,460.26]],"batl":[[0,1.42,503.68],[1,1.43,340.88],[2,1.51,6.89]],"ltp":1.4,"tv":16150.09,"id":9028621}],"tv":18051.68}]}
{"op":"mcm","clk":"4226341243","pt":1631448588458,"mc":[{"id":"1.187552454","rc":[{"trd":[[3.5,8]],"batb":[[0,2.9,985.23],[1,2.68,2.36],[2,2.48,12.51]],"ltp":3.5,"tv":1907.59,"id":9345630},{"trd":[[1.4,48.91]],"batb":[[0,1.4,445.26]],"batl":[[0,1.41,7],[1,1.42,503.68],[2,1.43,340.88]],"ltp":1.4,"tv":16165.08,"id":9028621}],"tv":18072.68}]}
{"op":"mcm","clk":"4226341369","pt":1631448589249,"mc":[{"id":"1.187552454","rc":[{"batb":[[0,2.98,11.8],[1,2.9,985.23],[2,2.68,2.36]],"ltp":3.5,"tv":1907.59,"id":9345630},{"trd":[[1.4,51.47]],"batb":[[0,1.4,443.98]],"ltp":1.4,"tv":16167.64,"id":9028621}],"tv":18075.24}]}
{"op":"mcm","clk":"4226341541","pt":1631448590371,"mc":[{"id":"1.187552454","rc":[{"batb":[[0,2.98,4],[1,2.96,3],[2,2.9,985.23]],"ltp":3.5,"tv":1907.59,"id":9345630}]}]}
{"op":"mcm","clk":"4226341748","pt":1631448591559,"mc":[{"id":"1.187552454","rc":[{"trd":[[1.41,482.97]],"batl":[[0,1.41,6.6]],"ltp":1.41,"tv":16168.44,"id":9028621}],"tv":18076.04}]}
{"op":"mcm","clk":"4226341911","pt":1631448592571,"mc":[{"id":"1.187552454","rc":[{"trd":[[1.4,96.93]],"batb":[[0,1.4,421.26]],"ltp":1.4,"tv":16213.9,"id":9028621}],"tv":18121.49}]}
{"op":"mcm","clk":"4226342085","pt":1631448593545,"mc":[{"id":"1.187552454","rc":[{"batb":[[0,3,20],[1,2.98,4],[2,2.96,3]],"ltp":3.5,"tv":1907.59,"id":9345630}]}]}
{"op":"mcm","clk":"4226342245","pt":1631448594454,"mc":[{"id":"1.187552454","rc":[{"batb":[[0,2.98,4],[1,2.96,3],[2,2.68,2.36]],"ltp":3.5,"tv":1907.59,"id":9345630}]}]}
{"op":"mcm","clk":"4226342422","pt":1631448595479,"mc":[{"id":"1.187552454","rc":[{"batb":[[1,2.96,5.13],[2,2.78,2.66]],"batl":[[2,4.2,2]],"ltp":3.5,"tv":1907.59,"id":9345630}]}]}
{"op":"mcm","clk":"4226342554","pt":1631448596369,"mc":[{"id":"1.187552454","rc":[{"batl":[[0,3.65,12]],"ltp":3.5,"tv":1907.59,"id":9345630},{"batb":[[0,1.4,341.62]],"ltp":1.4,"tv":16213.9,"id":9028621}]}]}
{"op":"mcm","clk":"4226342784","pt":1631448597562,"mc":[{"id":"1.187552454","rc":[{"batl":[[0,4.2,2],[1,4.6,2],[2,4.2,0]],"ltp":3.5,"tv":1907.59,"id":9345630},{"batb":[[0,1.4,1005.21],[1,1.38,505.98]],"ltp":1.4,"tv":16213.9,"id":9028621}]}]}
{"op":"mcm","clk":"4226342912","pt":1631448598174,"mc":[{"id":"1.187552454","rc":[{"batb":[[1,2.96,3]],"ltp":3.5,"tv":1907.59,"id":9345630},{"batb":[[1,1.32,40.14],[2,1.28,41.16]],"batl":[[0,1.5,6],[1,1.56,20.67],[2,1.59,23.5]],"ltp":1.4,"tv":16213.9,"id":9028621}]}]}
{"op":"mcm","clk":"4226343146","pt":1631448599556,"mc":[{"id":"1.187552454","rc":[{"batb":[[0,1.42,20.5],[1,1.4,1005.21],[2,1.32,40.14]],"ltp":1.4,"tv":16213.9,"id":9028621}]}]}
{"op":"mcm","clk":"4226343430","pt":1631448601469,"mc":[{"id":"1.187552454","rc":[{"batb":[[0,3,3],[1,2.98,4],[2,2.96,2.38]],"ltp":3.5,"tv":1907.59,"id":9345630},{"batb":[[1,1.41,1.04],[2,1.32,651.07]],"batl":[[1,1.51,24.5],[2,1.52,452.66]],"ltp":1.4,"tv":16213.9,"id":9028621}]}]}
{"op":"mcm","clk":"4226343528","pt":1631448601963,"mc":[{"id":"1.187552454","rc":[{"batb":[[2,2.78,2.66]],"ltp":3.5,"tv":1907.59,"id":9345630},{"batl":[[1,1.56,20.67],[2,1.67,7.5]],"ltp":1.4,"tv":16213.9,"id":9028621}]}]}
{"op":"mcm","clk":"4226343750","pt":1631448603282,"mc":[{"id":"1.187552454","rc":[{"trd":[[1.41,485.05],[1.42,968.23]],"batb":[[0,1.32,651.07],[1,1.31,534.51],[2,1.28,41.16]],"batl":[[0,1.36,709.52],[1,1.5,6],[2,1.56,20.67]],"ltp":1.41,"tv":16256.97,"id":9028621}],"tv":18164.57}]}
{"op":"mcm","clk":"4226343967","pt":1631448604517,"mc":[{"id":"1.187552454","rc":[{"batb":[[0,3.8,6],[1,3.75,2],[2,3,3]],"ltp":3.5,"tv":1907.59,"id":9345630},{"batl":[[0,1.35,4492.3],[1,1.36,711.52],[2,1.37,14]],"ltp":1.41,"tv":16256.97,"id":9028621}]}]}
{"op":"mcm","clk":"4226344144","pt":1631448605482,"mc":[{"id":"1.187552454","rc":[{"batb":[[0,3.8,3]],"ltp":3.5,"tv":1907.59,"id":9345630},{"batl":[[0,1.35,336.3],[1,1.36,432.49],[2,1.37,7]],"ltp":1.41,"tv":16256.97,"id":9028621}]}]}
{"op":"mcm","clk":"4226344299","pt":1631448606294,"mc":[{"id":"1.187552454","rc":[{"batb":[[2,3.4,2]],"ltp":3.5,"tv":1907.59,"id":9345630}]}]}
{"op":"mcm","clk":"4226344552","pt":1631448607582,"mc":[{"id":"1.187552454","rc":[{"batl":[[0,4.1,10],[1,4.2,2],[2,4.6,2]],"ltp":3.5,"tv":1907.59,"id":9345630},{"batb":[[0,1.32,695.11]],"batl":[[1,1.36,476.4]],"ltp":1.41,"tv":16256.97,"id":9028621}]}]}
{"op":"mcm","clk":"4226344860","pt":1631448609386,"mc":[{"id":"1.187552454","rc":[{"trd":[[1.32,51.57]],"batb":[[0,1.32,680.43]],"ltp":1.32,"tv":16286.33,"id":9028621}],"tv":18193.93}]}
{"op":"mcm","clk":"4226345098","pt":1631448610721,"mc":[{"id":"1.187552454","rc":[{"batb":[[0,3.8,18]],"ltp":3.5,"tv":1907.59,"id":9345630}]}]}
{"op":"mcm","clk":"4226345373","pt":1631448612384,"mc":[{"id":"1.187552454","rc":[{"batb":[[2,3.55,2.08]],"ltp":3.5,"tv":1907.59,"id":9345630}]}]}
{"op":"mcm","clk":"4226345566","pt":1631448613497,"mc":[{"id":"1.187552454","rc":[{"trd":[[1.35,677.42]],"batb":[[0,1.35,32.65],[1,1.32,680.43],[2,1.31,534.51]],"batl":[[0,1.36,476.4],[1,1.37,7],[2,1.39,36.5]],"ltp":1.35,"tv":16958.93,"id":9028621}],"tv":18866.53}]}
{"op":"mcm","clk":"4226346090","pt":1631448616493,"mc":[{"id":"1.187552454","rc":[{"trd":[[3.8,9.93]],"batb":[[0,3.8,8.07]],"ltp":3.8,"tv":1917.52,"id":9345630},{"trd":[[1.35,742.72],[1.36,1323.49]],"batb":[[0,1.32,806.93],[1,1.31,534.51],[2,1.28,41.16]],"batl":[[0,1.37,417.31],[1,1.39,36.5],[2,1.41,29.5]],"ltp":1.36,"tv":18342.45,"id":9028621}],"tv":20259.98}]}
{"op":"mcm","clk":"4226346265","pt":1631448617535,"mc":[{"id":"1.187552454","rc":[{"batb":[[0,3.75,2],[1,3.55,2.08],[2,3.4,4.01]],"ltp":3.8,"tv":1917.52,"id":9345630},{"batb":[[0,1.32,575.82],[1,1.28,41.16],[2,1.25,50.09]],"ltp":1.36,"tv":18342.45,"id":9028621}]}]}
{"op":"mcm","clk":"4226346683","pt":1631448620251,"mc":[{"id":"1.187552454","rc":[{"batb":[[2,3.5,2.04]],"ltp":3.8,"tv":1917.52,"id":9345630},{"batb":[[0,1.35,6.18],[1,1.33,487.65],[2,1.32,575.64]],"batl":[[0,1.36,347.17],[1,1.37,417.31],[2,1.39,36.5]],"ltp":1.36,"tv":18342.45,"id":9028621}]}]}
{"op":"mcm","clk":"4226346888","pt":1631448621546,"mc":[{"id":"1.187552454","rc":[{"batl":[[0,1.36,384.75]],"ltp":1.36,"tv":18342.45,"id":9028621}]}]}
{"op":"mcm","clk":"4226347070","pt":1631448622441,"mc":[{"id":"1.187552454","rc":[{"batb":[[0,3.4,2],[1,3.3,2.08],[2,3.25,2]],"batl":[[0,5,2],[1,5.2,2],[2,4.6,0]],"ltp":3.8,"tv":1917.52,"id":9345630},{"batb":[[1,1.25,50.09],[2,1.24,59.27]],"batl":[[0,1.37,7],[1,1.43,30.5],[2,1.44,27.58]],"ltp":1.36,"tv":18342.45,"id":9028621}]}]}
{"op":"mcm","clk":"4226347211","pt":1631448623139,"mc":[{"id":"1.187552454","rc":[{"batb":[[0,3.3,2.08],[1,3.25,2],[2,2.78,2.66]],"ltp":3.8,"tv":1917.52,"id":9345630},{"batl":[[0,1.43,30.5],[1,1.44,27.58],[2,1.5,6]],"ltp":1.36,"tv":18342.45,"id":9028621}]}]}
{"op":"mcm","clk":"4226347475","pt":1631448624536,"mc":[{"id":"1.187552454","rc":[{"batb":[[0,3.75,10],[1,3.3,2.08],[2,3.25,2]],"ltp":3.8,"tv":1917.52,"id":9345630}]}]}
{"op":"mcm","clk":"4226347684","pt":1631448625423,"mc":[{"id":"1.187552454","rc":[{"batb":[[0,3.3,2.08],[1,3.25,2],[2,2.78,2.66]],"ltp":3.8,"tv":1917.52,"id":9345630},{"batb":[[0,1.33,18.12],[1,1.29,313.94],[2,1.28,594.37]],"batl":[[0,1.43,298.83],[1,1.44,357.05]],"ltp":1.36,"tv":18342.45,"id":9028621}]}]}
{"op":"mcm","clk":"4226347725","pt":1631448625631,"mc":[{"id":"1.187552454","rc":[{"batl":[[0,4.6,2],[1,5,2],[2,5.2,2]],"ltp":3.8,"tv":1917.52,"id":9345630},{"batb":[[2,1.28,640.28]],"ltp":1.36,"tv":18342.45,"id":9028621}]}]}
{"op":"mcm","clk":"4226348262","pt":1631448628537,"mc":[{"id":"1.187552454","rc":[{"batb":[[0,3.5,2.04],[1,3.3,2.08],[2,3.25,2]],"batl":[[1,5,4]],"ltp":3.8,"tv":1917.52,"id":9345630},{"batb":[[0,1.37,6],[1,1.33,18.12],[2,1.29,313.94]],"batl":[[0,1.4,30.69],[1,1.42,382.3],[2,1.43,298.83]],"ltp":1.36,"tv":18342.45,"id":9028621}]}]}
{"op":"mcm","clk":"4226348316","pt":1631448628868,"mc":[{"id":"1.187552454","rc":[{"batb":[[0,3.3,2.08],[1,3.25,2],[2,2.78,2.66]],"ltp":3.8,"tv":1917.52,"id":9345630},{"batl":[[0,1.42,382.3],[1,1.43,298.83],[2,1.44,357.05]],"ltp":1.36,"tv":18342.45,"id":9028621}]}]}
{"op":"mcm","clk":"4226348750","pt":1631448631242,"mc":[{"id":"1.187552454","rc":[{"batb":[[1,1.33,17.93]],"ltp":1.36,"tv":18342.45,"id":9028621}]}]}
{"op":"mcm","clk":"4226348945","pt":1631448632473,"mc":[{"id":"1.187552454","rc":[{"batb":[[0,3.5,2],[1,3.3,2.08],[2,3.25,2]],"ltp":3.8,"tv":1917.52,"id":9345630},{"batl":[[0,1.4,28.19],[1,1.42,382.3],[2,1.43,298.83]],"ltp":1.36,"tv":18342.45,"id":9028621}]}]}
{"op":"mcm","clk":"4226349004","pt":1631448632742,"mc":[{"id":"1.187552454","rc":[{"batb":[[0,3.3,2.08],[1,3.25,2],[2,2.78,2.66]],"ltp":3.8,"tv":1917.52,"id":9345630},{"batl":[[0,1.42,382.3],[1,1.43,298.83],[2,1.44,357.05]],"ltp":1.36,"tv":18342.45,"id":9028621}]}]}
{"op":"mcm","clk":"4226349902","pt":1631448637425,"mc":[{"id":"1.187552454","rc":[{"batl":[[0,5,4],[1,5.2,2],[2,5.2,0]],"ltp":3.8,"tv":1917.52,"id":9345630},{"batb":[[0,1.33,17.93],[1,1.25,59.09],[2,1.24,70.27]],"ltp":1.36,"tv":18342.45,"id":9028621}]}]}
{"op":"mcm","clk":"4226350093","pt":1631448638549,"mc":[{"id":"1.187552454","rc":[{"batb":[[0,1.38,731.06],[1,1.37,508.16],[2,1.33,17.93]],"ltp":1.36,"tv":18342.45,"id":9028621}]}]}
{"op":"mcm","clk":"4226350265","pt":1631448639572,"mc":[{"id":"1.187552454","rc":[{"batb":[[0,3.5,2.04],[1,3.3,2.08],[2,3.25,2]],"ltp":3.8,"tv":1917.52,"id":9345630},{"batl":[[0,1.4,34.99],[1,1.42,382.3],[2,1.43,298.83]],"ltp":1.36,"tv":18342.45,"id":9028621}]}]}
{"op":"mcm","clk":"4226350473","pt":1631448640553,"mc":[{"id":"1.187552454","rc":[{"batb":[[0,3.35,3],[1,3.3,5.08]],"ltp":3.8,"tv":1917.52,"id":9345630},{"trd":[[1.4,108.93]],"batb":[[0,1.4,302.8],[1,1.39,391.2],[2,1.38,731.06]],"batl":[[0,1.42,390.3],[1,1.43,298.83],[2,1.44,357.05]],"ltp":1.4,"tv":18354.45,"id":9028621}],"tv":20271.98}]}
{"op":"mcm","clk":"4226350635","pt":1631448641467,"mc":[{"id":"1.187552454","rc":[{"batb":[[0,3.3,2.08],[1,3.25,2],[2,2.78,2.66]],"batl":[[0,3.85,3],[1,4.1,20],[2,5,4]],"ltp":3.8,"tv":1917.52,"id":9345630},{"batb":[[1,1.39,435.66],[2,1.37,508.16]],"batl":[[0,1.42,382.3]],"ltp":1.4,"tv":18354.45,"id":9028621}]}]}
{"op":"mcm","clk":"4226350787","pt":1631448642342,"mc":[{"id":"1.187552454","rc":[{"batl":[[0,3.6,3],[1,3.85,3]],"ltp":3.8,"tv":1917.52,"id":9345630},{"batb":[[0,1.41,16.8],[1,1.4,302.8],[2,1.39,435.66]],"ltp":1.4,"tv":18354.45,"id":9028621}]}]}
{"op":"mcm","clk":"4226350947","pt":1631448643255,"mc":[{"id":"1.187552454","rc":[{"batb":[[0,1.4,302.8],[1,1.39,435.66],[2,1.34,13]],"ltp":1.4,"tv":18354.45,"id":9028621}]}]}
{"op":"mcm","clk":"4226351313","pt":1631448645251,"mc":[{"id":"1.187552454","rc":[{"trd":[[1.4,113.41]],"batb":[[0,1.4,300.56]],"ltp":1.4,"tv":18358.93,"id":9028621}],"tv":20276.46}]}
{"op":"mcm","clk":"4226351551","pt":1631448646554,"mc":[{"id":"1.187552454","rc":[{"batb":[[2,2.92,12.38]],"batl":[[2,4.2,2]],"ltp":3.8,"tv":1917.52,"id":9345630}]}]}
{"op":"mcm","clk":"4226351858","pt":1631448648372,"mc":[{"id":"1.187552454","rc":[{"batl":[[0,3.55,20],[1,3.6,3],[2,3.85,3]],"ltp":3.8,"tv":1917.52,"id":9345630}]}]}
{"op":"mcm","clk":"4226352181","pt":1631448650270,"mc":[{"id":"1.187552454","rc":[{"batb":[[0,1.41,17.93],[1,1.4,300.56],[2,1.39,435.66]],"ltp":1.4,"tv":18358.93,"id":9028621}]}]}
{"op":"mcm","clk":"4226352557","pt":1631448652367,"mc":[{"id":"1.187552454","rc":[{"trd":[[1.41,497.05]],"batb":[[0,1.41,11.93]],"ltp":1.41,"tv":18370.94,"id":9028621}],"tv":20288.47}]}
{"op":"mcm","clk":"4226352735","pt":1631448653408,"mc":[{"id":"1.187552454","rc":[{"trd":[[3.35,340.35]],"ltp":3.35,"tv":1919.77,"id":9345630},{"trd":[[1.42,973.54]],"batl":[[0,1.42,376.99]],"ltp":1.42,"tv":18376.25,"id":9028621}],"tv":20296.03}]}
{"op":"mcm","clk":"4226354736","pt":1631448664475,"mc":[{"id":"1.187552454","rc":[{"batl":[[0,3.6,3],[1,4.2,2],[2,4.8,2]],"ltp":3.35,"tv":1919.77,"id":9345630},{"batb":[[2,1.39,391.2]],"batl":[[0,1.43,298.83],[1,1.44,357.05],[2,1.5,6]],"ltp":1.42,"tv":18376.25,"id":9028621}]}]}
{"op":"mcm","clk":"4226354833","pt":1631448665068,"mc":[{"id":"1.187552454","rc":[{"batb":[[0,2.74,2.52],[1,2.2,42.66],[2,2,11.86]],"batl":[[0,4.8,2],[1,4.2,0],[2,4.8,0]],"ltp":3.35,"tv":1919.77,"id":9345630},{"batb":[[1,1.28,24.6],[2,1.27,62.46]],"batl":[[0,1.5,6],[1,1.57,23.5],[2,1.8,826.8]],"ltp":1.42,"tv":18376.25,"id":9028621}]}]}
{"op":"mcm","clk":"4226355021","pt":1631448666105,"mc":[{"id":"1.187552454","rc":[{"trd":[[1.41,520.92]],"batb":[[0,1.28,24.6],[1,1.27,62.46],[2,1.17,314.09]],"ltp":1.41,"tv":18400.11,"id":9028621}],"tv":20319.89}]}
{"op":"mcm","clk":"4226355256","pt":1631448667376,"mc":[{"id":"1.187552454","rc":[{"batb":[[0,3.5,3],[1,2.74,2.52],[2,2.2,42.66]],"ltp":3.35,"tv":1919.77,"id":9345630}]}]}
{"op":"mcm","clk":"4226355418","pt":1631448668282,"mc":[{"id":"1.187552454","rc":[{"batb":[[1,2.92,12.63],[2,2.74,13.04]],"batl":[[0,4.2,2],[1,4.8,2]],"ltp":3.35,"tv":1919.77,"id":9345630},{"batb":[[0,1.33,718.51],[1,1.32,550.78],[2,1.28,24.6]],"batl":[[1,1.52,30.02],[2,1.54,432.93]],"ltp":1.41,"tv":18400.11,"id":9028621}]}]}
{"op":"mcm","clk":"4226355581","pt":1631448668993,"mc":[{"id":"1.187552454","rc":[{"batb":[[1,2.74,13.04],[2,2.2,42.66]],"batl":[[1,4.6,2],[2,4.8,2]],"ltp":3.35,"tv":1919.77,"id":9345630},{"batb":[[2,1.28,32.6]],"batl":[[1,1.54,432.93],[2,1.55,244.43]],"ltp":1.41,"tv":18400.11,"id":9028621}]}]}
{"op":"mcm","clk":"4226355804","pt":1631448670384,"mc":[{"id":"1.187552454","rc":[{"batb":[[1,2.74,2.52]],"batl":[[0,4.6,2],[1,4.8,2],[2,4.8,0]],"ltp":3.35,"tv":1919.77,"id":9345630},{"batb":[[0,1.28,32.6],[1,1.27,73.46],[2,1.17,314.09]],"batl":[[1,1.57,23.5],[2,1.8,826.8]],"ltp":1.41,"tv":18400.11,"id":9028621}]}]}
{"op":"mcm","clk":"4226355857","pt":1631448670707,"mc":[{"id":"1.187552454","rc":[{"batb":[[0,1.29,23.75],[1,1.28,32.6],[2,1.27,73.46]],"ltp":1.41,"tv":18400.11,"id":9028621}]}]}
{"op":"mcm","clk":"4226356192","pt":1631448672408,"mc":[{"id":"1.187552454","rc":[{"trd":[[3.5,14]],"batb":[[0,2.74,2.52],[1,2.2,42.66],[2,2,11.86]],"ltp":3.5,"tv":1925.77,"id":9345630}],"tv":20325.89}]}
{"op":"mcm","clk":"4226356412","pt":1631448673580,"mc":[{"id":"1.187552454","rc":[{"batb":[[0,2.74,13.04]],"batl":[[0,3.9,10],[1,4.2,2],[2,4.6,2]],"ltp":3.5,"tv":1925.77,"id":9345630},{"batb":[[0,1.42,229.37],[1,1.41,365.9],[2,1.34,194.25]],"batl":[[0,1.45,282.8],[1,1.46,310.82],[2,1.49,30]],"ltp":1.41,"tv":18400.11,"id":9028621}]}]}
{"op":"mcm","clk":"4226356466","pt":1631448673904,"mc":[{"id":"1.187552454","rc":[{"batl":[[2,4.5,3]],"ltp":3.5,"tv":1925.77,"id":9345630}]}]}
{"op":"mcm","clk":"4226356775","pt":1631448675506,"mc":[{"id":"1.187552454","rc":[{"batb":[[0,2.92,11.88],[1,2.74,13.04],[2,2.2,42.66]],"ltp":3.5,"tv":1925.77,"id":9345630}]}]}
{"op":"mcm","clk":"4226356849","pt":1631448675929,"mc":[{"id":"1.187552454","rc":[{"batl":[[0,1.44,360.07],[1,1.45,282.8],[2,1.46,310.82]],"ltp":1.41,"tv":18400.11,"id":9028621}]}]}
{"op":"mcm","clk":"4226357063","pt":1631448677123,"mc":[{"id":"1.187552454","rc":[{"batb":[[2,1.34,173.99]],"ltp":1.41,"tv":18400.11,"id":9028621}]}]}
{"op":"mcm","clk":"4226357442","pt":1631448679094,"mc":[{"id":"1.187552454","rc":[{"batb":[[0,2.94,59.4],[1,2.92,11.88],[2,2.74,13.04]],"ltp":3.5,"tv":1925.77,"id":9345630},{"trd":[[1.42,1400.56]],"batb":[[0,1.42,15.86]],"batl":[[0,1.45,282.8],[1,1.46,310.82],[2,1.49,30]],"ltp":1.42,"tv":18827.13,"id":9028621}],"tv":20752.91}]}
{"op":"mcm","clk":"4226357655","pt":1631448680333,"mc":[{"id":"1.187552454","rc":[{"batb":[[0,2.92,11.88],[1,2.74,13.04],[2,2.2,42.66]],"batl":[[0,4.2,2],[1,4.5,3],[2,4.6,2]],"ltp":3.5,"tv":1925.77,"id":9345630},{"batb":[[0,1.32,53.64],[1,1.31,8],[2,1.3,8]],"batl":[[0,1.5,6],[1,1.52,30.02],[2,1.57,30]],"ltp":1.42,"tv":18827.13,"id":9028621}]}]}
{"op":"mcm","clk":"4226357732","pt":1631448680702,"mc":[{"id":"1.187552454","rc":[{"batb":[[0,2.74,2.52],[1,2.2,42.66],[2,2,11.86]],"batl":[[0,4.5,3],[1,4.6,2],[2,4.8,2]],"ltp":3.5,"tv":1925.77,"id":9345630},{"batb":[[0,1.32,8]],"batl":[[1,1.57,23.5],[2,1.8,826.8]],"ltp":1.42,"tv":18827.13,"id":9028621}]}]}
{"op":"mcm","clk":"4226358207","pt":1631448683221,"mc":[{"id":"1.187552454","rc":[{"batb":[[0,1.33,622.31],[1,1.32,517.5],[2,1.31,8]],"batl":[[1,1.53,265.58],[2,1.54,252.07]],"ltp":1.42,"tv":18827.13,"id":9028621}]}]}
{"op":"mcm","clk":"4226358389","pt":1631448684136,"mc":[{"id":"1.187552454","rc":[{"batb":[[0,2.74,13.04]],"batl":[[0,4.2,5],[1,4.3,2],[2,4.5,3]],"ltp":3.5,"tv":1925.77,"id":9345630},{"batb":[[1,1.32,555.39]],"ltp":1.42,"tv":18827.13,"id":9028621}]}]}
{"op":"mcm","clk":"4226358586","pt":1631448685212,"mc":[{"id":"1.187552454","rc":[{"batl":[[2,4.8,2]],"ltp":3.5,"tv":1925.77,"id":9345630},{"batb":[[0,1.33,643.19],[2,1.27,62.46]],"ltp":1.42,"tv":18827.13,"id":9028621}]}]}
{"op":"mcm","clk":"4226358981","pt":1631448687304,"mc":[{"id":"1.187552454","rc":[{"batb":[[0,2.92,12.38],[1,2.74,13.04],[2,2.2,42.66]],"ltp":3.5,"tv":1925.77,"id":9345630},{"batl":[[0,1.48,145.49],[1,1.5,6],[2,1.52,31.27]],"ltp":1.42,"tv":18827.13,"id":9028621}]}]}
{"op":"mcm","clk":"4226359685","pt":1631448691111,"mc":[{"id":"1.187552454","rc":[{"batb":[[0,1.33,622.31],[2,1.27,45.87]],"batl":[[0,1.37,508.16],[1,1.38,731.06],[2,1.48,145.49]],"ltp":1.42,"tv":18827.13,"id":9028621}]}]}
{"op":"mcm","clk":"4226359916","pt":1631448692413,"mc":[{"id":"1.187552454","rc":[{"batb":[[0,3.7,8.32],[1,2.92,12.38],[2,2.74,13.04]],"ltp":3.5,"tv":1925.77,"id":9345630},{"batl":[[0,1.37,518.54]],"ltp":1.42,"tv":18827.13,"id":9028621}]}]}
{"op":"mcm","clk":"4226360138","pt":1631448693540,"mc":[{"id":"1.187552454","rc":[{"batb":[[0,3.8,3],[1,3.7,8.32],[2,2.98,711.39]],"ltp":3.5,"tv":1925.77,"id":9345630},{"batl":[[0,1.36,7],[1,1.37,1154.53],[2,1.38,1125.3]],"ltp":1.42,"tv":18827.13,"id":9028621}]}]}
{"op":"mcm","clk":"4226360247","pt":1631448694129,"mc":[{"id":"1.187552454","rc":[{"batb":[[2,3.25,61.9]],"batl":[[0,4.1,18.52],[1,4.2,5],[2,4.3,2]],"ltp":3.5,"tv":1925.77,"id":9345630},{"batb":[[0,1.33,662.76]],"batl":[[1,1.37,1199.29]],"ltp":1.42,"tv":18827.13,"id":9028621}]}]}
{"op":"mcm","clk":"4226360540","pt":1631448695839,"mc":[{"id":"1.187552454","rc":[{"batl":[[2,4.8,2]],"ltp":3.5,"tv":1925.77,"id":9345630},{"batl":[[1,1.37,691.13],[2,1.38,394.24]],"ltp":1.42,"tv":18827.13,"id":9028621}]}]}
{"op":"mcm","clk":"4226361127","pt":1631448699065,"mc":[{"id":"1.187552454","rc":[{"batb":[[2,3.5,10.06]],"batl":[[2,4.6,2]],"ltp":3.5,"tv":1925.77,"id":9345630},{"batb":[[2,1.28,45.66]],"batl":[[0,1.35,159.5],[1,1.36,7],[2,1.37,691.13]],"ltp":1.42,"tv":18827.13,"id":9028621}]}]}
{"op":"mcm","clk":"4226361408","pt":1631448700560,"mc":[{"id":"1.187552454","rc":[{"trd":[[1.33,147.9]],"batb":[[0,1.33,657.76]],"ltp":1.33,"tv":18837.13,"id":9028621}],"tv":20762.91}]}
{"op":"mcm","clk":"4226362768","pt":1631448708378,"mc":[{"id":"1.187552454","rc":[{"trd":[[1.35,744.89]],"batl":[[0,1.35,158.42]],"ltp":1.35,"tv":18839.31,"id":9028621}],"tv":20765.08}]}
{"op":"mcm","clk":"4226363609","pt":1631448713469,"mc":[{"id":"1.187552454","rc":[{"trd":[[1.33,167.9]],"batb":[[0,1.33,647.76]],"ltp":1.33,"tv":18859.31,"id":9028621}],"tv":20785.08}]}
{"op":"mcm","clk":"4226363803","pt":1631448714483,"mc":[{"id":"1.187552454","rc":[{"trd":[[3.85,6.89]],"ltp":3.85,"tv":1932.66,"id":9345630},{"trd":[[1.35,764.53]],"batl":[[0,1.35,138.77]],"ltp":1.35,"tv":18878.95,"id":9028621}],"tv":20811.62}]}
{"op":"mcm","clk":"4226364307","pt":1631448717485,"mc":[{"id":"1.187552454","rc":[{"trd":[[1.35,864.9]],"batl":[[0,1.35,88.59]],"ltp":1.35,"tv":18979.31,"id":9028621}],"tv":20911.98}]}
{"op":"mcm","clk":"4226364481","pt":1631448718488,"mc":[{"id":"1.187552454","rc":[{"batl":[[0,4.2,2],[1,4.6,2],[2,4.8,2]],"ltp":3.85,"tv":1932.66,"id":9345630},{"batb":[[0,1.33,607.31],[1,1.32,547.39]],"batl":[[2,1.37,646.37]],"ltp":1.35,"tv":18979.31,"id":9028621}]}]}
{"op":"mcm","clk":"4226364694","pt":1631448719595,"mc":[{"id":"1.187552454","rc":[{"batb":[[0,3.3,2.01],[1,3.1,3],[2,2.92,12.38]],"batl":[[0,5,2],[1,4.6,0],[2,4.8,0]],"ltp":3.85,"tv":1932.66,"id":9345630},{"batb":[[0,1.25,47.13],[1,1.23,33.79],[2,1.2,68.89]],"batl":[[1,1.43,31.5],[2,1.5,6]],"ltp":1.35,"tv":18979.31,"id":9028621}]}]}
{"op":"mcm","clk":"4226364828","pt":1631448720371,"mc":[{"id":"1.187552454","rc":[{"trd":[[1.35,964.9]],"batb":[[1,1.2,68.89],[2,1.17,314.09]],"batl":[[0,1.35,38.59]],"ltp":1.35,"tv":19079.32,"id":9028621}],"tv":21011.98}]}
{"op":"mcm","clk":"4226365010","pt":1631448721562,"mc":[{"id":"1.187552454","rc":[{"trd":[[3.85,6.99]],"ltp":3.85,"tv":1932.76,"id":9345630},{"trd":[[1.35,965.18]],"batb":[[0,1.29,426.26],[1,1.28,598.3],[2,1.25,47.13]],"batl":[[0,1.35,38.3],[2,1.44,484.98]],"ltp":1.35,"tv":19079.6,"id":9028621}],"tv":21012.36}]}
{"op":"mcm","clk":"4226365146","pt":1631448722375,"mc":[{"id":"1.187552454","rc":[{"batb":[[0,3.5,13.06],[1,3.45,2],[2,3.3,9.89]],"batl":[[0,4.6,5],[1,5,4]],"ltp":3.85,"tv":1932.76,"id":9345630},{"batb":[[1,1.28,644.96],[2,1.27,8]],"batl":[[1,1.4,35.48],[2,1.43,37.14]],"ltp":1.35,"tv":19079.6,"id":9028621}]}]}
{"op":"mcm","clk":"4226365194","pt":1631448722691,"mc":[{"id":"1.187552454","rc":[{"batb":[[0,3.5,3],[2,3.3,2.01]],"ltp":3.85,"tv":1932.76,"id":9345630},{"batl":[[1,1.43,31.5],[2,1.44,484.98]],"ltp":1.35,"tv":19079.6,"id":9028621}]}]}
{"op":"mcm","clk":"4226365795","pt":1631448726308,"mc":[{"id":"1.187552454","rc":[{"trd":[[1.35,968.28]],"batl":[[0,1.35,36.76]],"ltp":1.35,"tv":19082.69,"id":9028621}],"tv":21015.46}]}
{"op":"mcm","clk":"4226366346","pt":1631448729513,"mc":[{"id":"1.187552454","rc":[{"batb":[[0,3.5,13.1],[2,3.3,10.19]],"ltp":3.85,"tv":1932.76,"id":9345630},{"batl":[[1,1.4,39.98],[2,1.43,38]],"ltp":1.35,"tv":19082.69,"id":9028621}]}]}
{"op":"mcm","clk":"4226366441","pt":1631448730114,"mc":[{"id":"1.187552454","rc":[{"batb":[[0,3.5,3],[2,3.3,2.01]],"ltp":3.85,"tv":1932.76,"id":9345630},{"batl":[[1,1.43,31.5],[2,1.44,484.98]],"ltp":1.35,"tv":19082.69,"id":9028621}]}]}
{"op":"mcm","clk":"4226366665","pt":1631448731400,"mc":[{"id":"1.187552454","rc":[{"batl":[[0,1.33,508.16],[1,1.34,731.06],[2,1.35,36.76]],"ltp":1.35,"tv":19082.69,"id":9028621}]}]}
{"op":"mcm","clk":"4226367080","pt":1631448733595,"mc":[{"id":"1.187552454","rc":[{"batb":[[0,4.2,2],[1,3.5,13.06],[2,3.3,10.29]],"ltp":3.85,"tv":1932.76,"id":9345630},{"batl":[[0,1.31,4.92],[1,1.33,508.16],[2,1.34,731.06]],"ltp":1.35,"tv":19082.69,"id":9028621}]}]}
{"op":"mcm","clk":"4226367226","pt":1631448734504,"mc":[{"id":"1.187552454","rc":[{"batl":[[1,1.32,612.28],[2,1.33,978.99]],"ltp":1.35,"tv":19082.69,"id":9028621}]}]}
{"op":"mcm","clk":"4226367388","pt":1631448735531,"mc":[{"id":"1.187552454","rc":[{"batb":[[1,3.9,3],[2,3.5,13.06]],"batl":[[1,5,2]],"ltp":3.85,"tv":1932.76,"id":9345630},{"batb":[[2,1.25,47.13]],"batl":[[2,1.33,986.99]],"ltp":1.35,"tv":19082.69,"id":9028621}]}]}
{"op":"mcm","clk":"4226367499","pt":1631448736128,"mc":[{"id":"1.187552454","rc":[{"trd":[[1.29,22]],"batb":[[0,1.29,424.26]],"ltp":1.29,"tv":19086.69,"id":9028621}],"tv":21019.46}]}
{"op":"mcm","clk":"4226367617","pt":1631448736832,"mc":[{"id":"1.187552454","rc":[{"batl":[[2,1.33,478.83]],"ltp":1.29,"tv":19086.69,"id":9028621}]}]}
{"op":"mcm","clk":"4226367876","pt":1631448738383,"mc":[{"id":"1.187552454","rc":[{"batl":[[0,4.5,10.79],[1,4.6,5],[2,5,50.5]],"ltp":3.85,"tv":1932.76,"id":9345630},{"trd":[[1.29,81.92]],"batb":[[0,1.29,394.3],[2,1.27,5]],"ltp":1.29,"tv":19146.61,"id":9028621}],"tv":21079.38}]}
{"op":"mcm","clk":"4226367989","pt":1631448738923,"mc":[{"id":"1.187552454","rc":[{"batl":[[2,5,2]],"ltp":3.85,"tv":1932.76,"id":9345630},{"trd":[[1.31,23.58]],"batl":[[0,1.32,612.41],[1,1.33,478.83],[2,1.4,37.43]],"ltp":1.31,"tv":19156.19,"id":9028621}],"tv":21088.96}]}
{"op":"mcm","clk":"4226368475","pt":1631448741244,"mc":[{"id":"1.187552454","rc":[{"trd":[[1.29,670.62]],"batb":[[0,1.29,99.95]],"ltp":1.29,"tv":19744.89,"id":9028621}],"tv":21677.65}]}
{"op":"mcm","clk":"4226368660","pt":1631448742206,"mc":[{"id":"1.187552454","rc":[{"trd":[[1.31,23.84]],"batb":[[0,1.29,100.32]],"batl":[[0,1.32,547.28],[1,1.33,8]],"ltp":1.31,"tv":19745.15,"id":9028621}],"tv":21677.91}]}
{"op":"mcm","clk":"4226369131","pt":1631448744812,"mc":[{"id":"1.187552454","rc":[{"trd":[[1.31,24.58]],"batb":[[0,1.29,288.97]],"batl":[[0,1.31,250.64],[1,1.32,547.28],[2,1.33,8]],"ltp":1.31,"tv":19745.89,"id":9028621}],"tv":21678.65}]}
{"op":"mcm","clk":"4226369446","pt":1631448746528,"mc":[{"id":"1.187552454","rc":[{"batl":[[0,1.3,49.63],[1,1.31,250.64],[2,1.32,547.28]],"ltp":1.31,"tv":19745.89,"id":9028621}]}]}
{"op":"mcm","clk":"4226369618","pt":1631448747518,"mc":[{"id":"1.187552454","rc":[{"batl":[[0,4.6,5],[1,5,2],[2,5,0]],"ltp":3.85,"tv":1932.76,"id":9345630}]}]}
{"op":"mcm","clk":"4226369968","pt":1631448749536,"mc":[{"id":"1.187552454","rc":[{"batb":[[0,4.3,6.17],[1,4.2,2],[2,3.9,3]],"ltp":3.85,"tv":1932.76,"id":9345630}]}]}
{"op":"mcm","clk":"4226370308","pt":1631448751344,"mc":[{"id":"1.187552454","rc":[{"batb":[[2,1.25,47.13]],"ltp":1.31,"tv":19745.89,"id":9028621}]}]}
{"op":"mcm","clk":"4226370408","pt":1631448751838,"mc":[{"id":"1.187552454","rc":[{"trd":[[1.29,677.56],[1.3,36.74]],"batb":[[0,1.29,285.5]],"batl":[[0,1.3,46.02]],"ltp":1.3,"tv":19760.06,"id":9028621}],"tv":21692.82}]}
{"op":"mcm","clk":"4226370871","pt":1631448754361,"mc":[{"id":"1.187552454","rc":[{"batb":[[2,1.27,10]],"ltp":1.3,"tv":19760.06,"id":9028621}]}]}
{"op":"mcm","clk":"4226371071","pt":1631448755448,"mc":[{"id":"1.187552454","rc":[{"trd":[[4.3,2.4]],"batb":[[0,4.3,5.97]],"ltp":4.3,"tv":1933.16,"id":9345630}],"tv":21693.22}]}
{"op":"mcm","clk":"4226371438","pt":1631448757439,"mc":[{"id":"1.187552454","rc":[{"batl":[[0,4.6,21.23]],"ltp":4.3,"tv":1933.16,"id":9345630}]}]}
{"op":"mcm","clk":"4226371492","pt":1631448757754,"mc":[{"id":"1.187552454","rc":[{"batl":[[0,4.6,5]],"ltp":4.3,"tv":1933.16,"id":9345630}]}]}
{"op":"mcm","clk":"4226372651","pt":1631448764333,"mc":[{"id":"1.187552454","rc":[{"trd":[[4.2,8.87],[4.3,28.25]],"batb":[[0,3.9,3],[1,3.5,13.06],[2,3.3,2.01]],"batl":[[0,4.5,16.23],[1,4.6,5],[2,5,2]],"ltp":4.2,"tv":1967.88,"id":9345630},{"trd":[[1.3,82.75],[1.31,40.19]],"batl":[[0,1.32,547.28],[1,1.33,8],[2,1.4,37.43]],"ltp":1.31,"tv":19821.68,"id":9028621}],"tv":21789.57}]}
{"op":"mcm","clk":"4226373204","pt":1631448767356,"mc":[{"id":"1.187552454","rc":[{"batb":[[0,3.95,15],[1,3.9,3],[2,3.5,13.06]],"ltp":4.2,"tv":1967.88,"id":9345630},{"batb":[[2,1.25,47.13]],"batl":[[0,1.32,784.94],[1,1.33,478.91]],"ltp":1.31,"tv":19821.68,"id":9028621}]}]}
{"op":"mcm","clk":"4226373279","pt":1631448767736,"mc":[{"id":"1.187552454","rc":[{"batb":[[0,1.3,2.3],[1,1.29,285.5],[2,1.28,644.96]],"ltp":1.31,"tv":19821.68,"id":9028621}]}]}
{"op":"mcm","clk":"4226374093","pt":1631448772662,"mc":[{"id":"1.187552454","rc":[{"trd":[[1.32,68.65]],"batl":[[0,1.32,776.4]],"ltp":1.32,"tv":19838.76,"id":9028621}],"tv":21806.65}]}
{"op":"mcm","clk":"4226374366","pt":1631448774165,"mc":[{"id":"1.187552454","rc":[{"batb":[[0,1.29,285.5],[1,1.28,644.96],[2,1.25,47.13]],"ltp":1.32,"tv":19838.76,"id":9028621}]}]}
{"op":"mcm","clk":"4226375398","pt":1631448780570,"mc":[{"id":"1.187552454","rc":[{"batl":[[0,1.3,20],[1,1.32,776.4],[2,1.33,478.91]],"ltp":1.32,"tv":19838.76,"id":9028621}]}]}
{"op":"mcm","clk":"4226376212","pt":1631448785452,"mc":[{"id":"1.187552454","rc":[{"batl":[[0,1.3,123]],"ltp":1.32,"tv":19838.76,"id":9028621}]}]}
{"op":"mcm","clk":"4226376348","pt":1631448786459,"mc":[{"id":"1.187552454","rc":[{"trd":[[1.3,162.21]],"batl":[[0,1.3,83.27]],"ltp":1.3,"tv":19918.22,"id":9028621}],"tv":21886.1}]}
{"op":"mcm","clk":"4226376514","pt":1631448787469,"mc":[{"id":"1.187552454","rc":[{"trd":[[1.3,231.18]],"batl":[[0,1.3,48.79]],"ltp":1.3,"tv":19987.19,"id":9028621}],"tv":21955.07}]}
{"op":"mcm","clk":"4226376727","pt":1631448788867,"mc":[{"id":"1.187552454","rc":[{"trd":[[1.3,235.78]],"batl":[[0,1.3,46.49]],"ltp":1.3,"tv":19991.79,"id":9028621}],"tv":21959.67}]}
{"op":"mcm","clk":"4226377069","pt":1631448791168,"mc":[{"id":"1.187552454","rc":[{"trd":[[4.3,33.25]],"ltp":4.3,"tv":1972.88,"id":9345630},{"trd":[[1.3,252.32]],"batl":[[0,1.32,776.4],[1,1.33,478.91],[2,1.4,37.43]],"ltp":1.3,"tv":20008.33,"id":9028621}],"tv":21981.21}]}
{"op":"mcm","clk":"4226377400","pt":1631448793566,"mc":[{"id":"1.187552454","rc":[{"trd":[[1.29,717.56]],"batb":[[0,1.29,265.5]],"batl":[[0,1.32,547.3],[1,1.33,8]],"ltp":1.29,"tv":20048.33,"id":9028621}],"tv":22021.21}]}
{"op":"mcm","clk":"4226377847","pt":1631448796590,"mc":[{"id":"1.187552454","rc":[{"batl":[[0,1.31,247.37],[1,1.32,547.3],[2,1.33,8]],"ltp":1.29,"tv":20048.33,"id":9028621}]}]}
{"op":"mcm","clk":"4226378838","pt":1631448802393,"mc":[{"id":"1.187552454","rc":[{"trd":[[1.31,40.39]],"batb":[[0,1.3,1.55],[1,1.29,265.5],[2,1.28,644.96]],"batl":[[0,1.31,247.27]],"ltp":1.31,"tv":20048.53,"id":9028621}],"tv":22021.41}]}
{"op":"mcm","clk":"4226379488","pt":1631448806306,"mc":[{"id":"1.187552454","rc":[{"trd":[[4.2,53.81]],"ltp":4.2,"tv":2017.82,"id":9345630},{"trd":[[1.31,184.47]],"batl":[[0,1.32,547.3],[1,1.33,8],[2,1.4,37.43]],"ltp":1.31,"tv":20192.61,"id":9028621}],"tv":22210.43}]}
{"op":"mcm","clk":"4226379969","pt":1631448809273,"mc":[{"id":"1.187552454","rc":[{"batb":[[1,1.29,355]],"batl":[[0,1.32,731.99],[1,1.33,478.9]],"ltp":1.31,"tv":20192.61,"id":9028621}]}]}
{"op":"mcm","clk":"4226380950","pt":1631448815595,"mc":[{"id":"1.187552454","rc":[{"trd":[[4.1,5.6]],"ltp":4.1,"tv":2021.42,"id":9345630},{"trd":[[1.32,79.84]],"batb":[[0,1.3,57.55]],"batl":[[0,1.32,720.8]],"ltp":1.32,"tv":20203.8,"id":9028621}],"tv":22225.22}]}
{"op":"mcm","clk":"4226381341","pt":1631448818423,"mc":[{"id":"1.187552454","rc":[{"trd":[[1.29,1427.56],[1.3,367.41]],"batb":[[0,1.28,644.96],[1,1.25,47.13],[2,1.2,34.44]],"batl":[[0,1.29,99.88],[1,1.32,547.35],[2,1.33,8]],"ltp":1.29,"tv":21028.89,"id":9028621}],"tv":23050.31}]}
{"op":"mcm","clk":"4226381807","pt":1631448821304,"mc":[{"id":"1.187552454","rc":[{"batb":[[0,1.28,913.07],[1,1.27,637.67],[2,1.25,47.13]],"batl":[[1,1.31,328.51],[2,1.32,547.35]],"ltp":1.29,"tv":21028.89,"id":9028621}]}]}
{"op":"mcm","clk":"4226382249","pt":1631448824016,"mc":[{"id":"1.187552454","rc":[{"batl":[[2,4.9,2]],"ltp":4.1,"tv":2021.42,"id":9345630},{"batb":[[2,1.26,46.98]],"ltp":1.29,"tv":21028.89,"id":9028621}]}]}
{"op":"mcm","clk":"4226384664","pt":1631448839532,"mc":[{"id":"1.187552454","rc":[{"trd":[[4.4,1.4]],"batb":[[0,3.9,3],[1,3.5,13.06],[2,2.2,42.66]],"batl":[[0,4.9,2],[1,5.2,2],[2,4.9,0]],"ltp":4.4,"tv":2022.82,"id":9345630},{"trd":[[1.29,1432.32]],"batb":[[0,1.26,46.98],[1,1.24,52.02],[2,1.2,34.44]],"batl":[[0,1.29,95.11],[1,1.33,8],[2,1.4,37.43]],"ltp":1.29,"tv":21033.65,"id":9028621}],"tv":23056.47}]}
{"op":"mcm","clk":"4226384754","pt":1631448840027,"mc":[{"id":"1.187552454","rc":[{"batb":[[0,3.5,3],[1,2.2,42.66],[2,2,11.86]],"batl":[[0,5.2,2],[1,5.2,0]],"ltp":4.4,"tv":2022.82,"id":9345630},{"batb":[[0,1.24,52.02],[1,1.2,34.44],[2,1.17,314.09]],"batl":[[1,1.5,6],[2,1.94,8.68]],"ltp":1.29,"tv":21033.65,"id":9028621}]}]}
{"op":"mcm","clk":"4226384889","pt":1631448840975,"mc":[{"id":"1.187552454","rc":[{"trd":[[1.29,1622.55]],"batb":[[0,1.29,3.89],[1,1.24,52.02],[2,1.2,34.44]],"batl":[[0,1.5,6],[1,1.94,8.68],[2,8.8,7.23]],"ltp":1.29,"tv":21223.88,"id":9028621}],"tv":23246.7}]}
{"op":"mcm","clk":"4226385156","pt":1631448842472,"mc":[{"id":"1.187552454","rc":[{"batb":[[0,4.2,2],[1,3.5,3],[2,2.2,42.66]],"ltp":4.4,"tv":2022.82,"id":9345630},{"batb":[[1,1.26,599.56],[2,1.25,695.98]],"batl":[[0,1.34,678.57],[1,1.35,439.88],[2,1.5,6]],"ltp":1.29,"tv":21223.88,"id":9028621}]}]}
{"op":"mcm","clk":"4226385257","pt":1631448842952,"mc":[{"id":"1.187552454","rc":[{"batl":[[0,4.8,3],[1,4.9,5],[2,5.2,5]],"ltp":4.4,"tv":2022.82,"id":9345630},{"batb":[[1,1.26,656.54],[2,1.25,707.98]],"ltp":1.29,"tv":21223.88,"id":9028621}]}]}
{"op":"mcm","clk":"4226385432","pt":1631448844188,"mc":[{"id":"1.187552454","rc":[{"batb":[[2,3.45,3]],"ltp":4.4,"tv":2022.82,"id":9345630},{"trd":[[1.29,1630.33]],"batb":[[0,1.26,656.54],[1,1.25,707.98],[2,1.24,61.02]],"batl":[[0,1.34,682.57],[2,1.4,4]],"ltp":1.29,"tv":21231.66,"id":9028621}],"tv":23254.48}]}
{"op":"mcm","clk":"4226385652","pt":1631448845581,"mc":[{"id":"1.187552454","rc":[{"batl":[[0,1.31,34.5],[1,1.32,4],[2,1.34,682.57]],"ltp":1.29,"tv":21231.66,"id":9028621}]}]}
{"op":"mcm","clk":"4226385690","pt":1631448845795,"mc":[{"id":"1.187552454","rc":[{"batl":[[0,1.32,4],[1,1.34,682.57],[2,1.35,439.88]],"ltp":1.29,"tv":21231.66,"id":9028621}]}]}
{"op":"mcm","clk":"4226386384","pt":1631448850393,"mc":[{"id":"1.187552454","rc":[{"batb":[[0,1.26,56.98],[1,1.25,12]],"ltp":1.29,"tv":21231.66,"id":9028621}]}]}
{"op":"mcm","clk":"4226386416","pt":1631448850717,"mc":[{"id":"1.187552454","rc":[{"batl":[[1,4.9,3]],"ltp":4.4,"tv":2022.82,"id":9345630},{"batb":[[0,1.26,10]],"ltp":1.29,"tv":21231.66,"id":9028621}]}]}
{"op":"mcm","clk":"4226386711","pt":1631448852582,"mc":[{"id":"1.187552454","rc":[{"batl":[[0,1.31,37.5],[1,1.34,678.57]],"ltp":1.29,"tv":21231.66,"id":9028621}]}]}
{"op":"mcm","clk":"4226386909","pt":1631448853588,"mc":[{"id":"1.187552454","rc":[{"batl":[[0,4.5,2],[1,4.8,3],[2,4.9,3]],"ltp":4.4,"tv":2022.82,"id":9345630},{"trd":[[1.31,259.47]],"batb":[[0,1.31,212.22],[1,1.3,550.07],[2,1.29,2]],"batl":[[0,1.34,678.57],[1,1.35,439.88],[2,1.4,4]],"ltp":1.31,"tv":21306.66,"id":9028621}],"tv":23329.48}]}
{"op":"mcm","clk":"4226387076","pt":1631448854437,"mc":[{"id":"1.187552454","rc":[{"batl":[[1,4.7,2],[2,4.8,3]],"ltp":4.4,"tv":2022.82,"id":9345630},{"batb":[[0,1.3,550.07],[1,1.29,2],[2,1.26,18]],"ltp":1.31,"tv":21306.66,"id":9028621}]}]}
{"op":"mcm","clk":"4226387267","pt":1631448855469,"mc":[{"id":"1.187552454","rc":[{"batl":[[1,4.7,4]],"ltp":4.4,"tv":2022.82,"id":9345630},{"batb":[[2,1.27,33.51]],"ltp":1.31,"tv":21306.66,"id":9028621}]}]}
{"op":"mcm","clk":"4226387449","pt":1631448856502,"mc":[{"id":"1.187552454","rc":[{"batb":[[2,2.2,42.66]],"batl":[[0,4.4,3],[1,4.5,2],[2,4.7,4]],"ltp":4.4,"tv":2022.82,"id":9345630},{"batb":[[0,1.3,557.07],[1,1.29,11]],"batl":[[0,1.34,716.49]],"ltp":1.31,"tv":21306.66,"id":9028621}]}]}
{"op":"mcm","clk":"4226387610","pt":1631448857505,"mc":[{"id":"1.187552454","rc":[{"trd":[[4.2,55.81]],"batb":[[0,3.5,3],[1,2.2,42.66],[2,2,11.86]],"ltp":4.2,"tv":2024.82,"id":9345630},{"trd":[[1.32,86.21]],"batb":[[0,1.32,15.16],[1,1.3,792.94],[2,1.29,594.49]],"ltp":1.32,"tv":21313.02,"id":9028621}],"tv":23337.84}]}
{"op":"mcm","clk":"4226387740","pt":1631448858360,"mc":[{"id":"1.187552454","rc":[{"trd":[[1.3,379.31],[1.32,116.53]],"batb":[[0,1.3,844.04],[1,1.29,594.49],[2,1.27,33.51]],"ltp":1.3,"tv":21355.25,"id":9028621}],"tv":23380.07}]}
{"op":"mcm","clk":"4226387858","pt":1631448859176,"mc":[{"id":"1.187552454","rc":[{"trd":[[1.3,399.31]],"batb":[[0,1.31,22.22],[1,1.3,834.04],[2,1.29,594.49]],"ltp":1.3,"tv":21375.25,"id":9028621}],"tv":23400.07}]}
{"op":"mcm","clk":"4226388037","pt":1631448860302,"mc":[{"id":"1.187552454","rc":[{"batb":[[0,4.1,2],[1,4,2],[2,3.5,3]],"batl":[[2,4.6,2]],"ltp":4.2,"tv":2024.82,"id":9345630},{"batl":[[0,1.32,42.11],[1,1.33,38.5],[2,1.34,500.89]],"ltp":1.3,"tv":21375.25,"id":9028621}]}]}
{"op":"mcm","clk":"4226388225","pt":1631448861484,"mc":[{"id":"1.187552454","rc":[{"batb":[[2,3.9,2]],"batl":[[0,4.3,15],[1,4.4,3],[2,4.5,2]],"ltp":4.2,"tv":2024.82,"id":9345630},{"batl":[[2,1.34,538.64]],"ltp":1.3,"tv":21375.25,"id":9028621}]}]}
{"op":"mcm","clk":"4226388354","pt":1631448862503,"mc":[{"id":"1.187552454","rc":[{"batl":[[1,1.33,277.78]],"ltp":1.3,"tv":21375.25,"id":9028621}]}]}
{"op":"mcm","clk":"4226388809","pt":1631448865483,"mc":[{"id":"1.187552454","rc":[{"batb":[[0,1.3,834.04],[1,1.29,594.49],[2,1.28,44.41]],"ltp":1.3,"tv":21375.25,"id":9028621}]}]}
{"op":"mcm","clk":"4226389649","pt":1631448870506,"mc":[{"id":"1.187552454","rc":[{"batb":[[2,1.28,69.01]],"ltp":1.3,"tv":21375.25,"id":9028621}]}]}
{"op":"mcm","clk":"4226389678","pt":1631448870716,"mc":[{"id":"1.187552454","rc":[{"batb":[[1,1.29,585.49]],"ltp":1.3,"tv":21375.25,"id":9028621}]}]}
{"op":"mcm","clk":"4226390114","pt":1631448873320,"mc":[{"id":"1.187552454","rc":[{"batb":[[0,4,2],[1,3.9,2],[2,3.85,2]],"batl":[[0,4.6,2],[1,4.9,2],[2,5,2]],"ltp":4.2,"tv":2024.82,"id":9345630},{"batb":[[0,1.28,69.01],[1,1.26,55.48],[2,1.25,52.09]],"batl":[[0,1.33,38.5],[1,1.34,37.75],[2,1.35,38.5]],"ltp":1.3,"tv":21375.25,"id":9028621}]}]}
{"op":"mcm","clk":"4226390161","pt":1631448873627,"mc":[{"id":"1.187552454","rc":[{"batb":[[1,3.5,3],[2,2.2,42.66]],"batl":[[0,4.9,2],[1,4.9,0],[2,5,0]],"ltp":4.2,"tv":2024.82,"id":9345630},{"batb":[[0,1.28,24.6],[2,1.17,314.09]],"batl":[[1,1.36,20.89],[2,1.4,4]],"ltp":1.3,"tv":21375.25,"id":9028621}]}]}
{"op":"mcm","clk":"4226390606","pt":1631448876552,"mc":[{"id":"1.187552454","rc":[{"batb":[[0,4.1,2],[1,4,5],[2,3.95,3]],"batl":[[0,4.6,3],[1,4.9,2]],"ltp":4.2,"tv":2024.82,"id":9345630},{"batl":[[0,1.32,38.61],[1,1.33,45.5],[2,1.36,20.89]],"ltp":1.3,"tv":21375.25,"id":9028621}]}]}
{"op":"mcm","clk":"4226390719","pt":1631448877233,"mc":[{"id":"1.187552454","rc":[{"batb":[[0,4,5],[1,3.95,3],[2,3.5,3]],"batl":[[1,4.9,4]],"ltp":4.2,"tv":2024.82,"id":9345630},{"batl":[[0,1.33,45.5],[1,1.36,20.89],[2,1.4,4]],"ltp":1.3,"tv":21375.25,"id":9028621}]}]}
{"op":"mcm","clk":"4226390997","pt":1631448879213,"mc":[{"id":"1.187552454","rc":[{"batb":[[0,1.3,515.22],[1,1.29,578.83],[2,1.28,24.6]],"batl":[[0,1.33,530.84],[1,1.34,459.31],[2,1.36,20.89]],"ltp":1.3,"tv":21375.25,"id":9028621}]}]}
{"op":"mcm","clk":"4226391182","pt":1631448880508,"mc":[{"id":"1.187552454","rc":[{"batl":[[0,4.5,15],[1,4.6,5],[2,4.9,4]],"ltp":4.2,"tv":2024.82,"id":9345630},{"trd":[[1.32,117.33]],"batb":[[0,1.3,514.82],[1,1.29,649.73],[2,1.28,69.76]],"ltp":1.32,"tv":21376.04,"id":9028621}],"tv":23400.86}]}
{"op":"mcm","clk":"4226391243","pt":1631448880852,"mc":[{"id":"1.187552454","rc":[{"batb":[[1,1.29,578.83]],"ltp":1.32,"tv":21376.04,"id":9028621}]}]}
{"op":"mcm","clk":"4226391602","pt":1631448883447,"mc":[{"id":"1.187552454","rc":[{"batb":[[0,4.1,2],[1,4,5],[2,3.95,3]],"ltp":4.2,"tv":2024.82,"id":9345630}]}]}
{"op":"mcm","clk":"4226391785","pt":1631448884445,"mc":[{"id":"1.187552454","rc":[{"batb":[[0,4,5],[1,3.95,3],[2,3.5,3]],"batl":[[0,4.6,5],[1,4.9,4],[2,4.9,0]],"ltp":4.2,"tv":2024.82,"id":9345630},{"batb":[[0,1.28,69.76],[1,1.26,55.48],[2,1.17,314.09]],"batl":[[0,1.33,45.5],[1,1.36,20.89],[2,1.4,4]],"ltp":1.32,"tv":21376.04,"id":9028621}]}]}
{"op":"mcm","clk":"4226391824","pt":1631448884746,"mc":[{"id":"1.187552454","rc":[{"batl":[[0,4.6,3]],"ltp":4.2,"tv":2024.82,"id":9345630},{"batb":[[0,1.28,24.6]],"ltp":1.32,"tv":21376.04,"id":9028621}]}]}
{"op":"mcm","clk":"4226392251","pt":1631448887459,"mc":[{"id":"1.187552454","rc":[{"batb":[[0,1.28,607.34],[1,1.27,634.07],[2,1.26,55.48]],"batl":[[1,1.36,629.81],[2,1.37,411.47]],"ltp":1.32,"tv":21376.04,"id":9028621}]}]}
{"op":"mcm","clk":"4226392377","pt":1631448888460,"mc":[{"id":"1.187552454","rc":[{"batb":[[1,2.2,42.66],[2,2,11.86]],"batl":[[0,4.6,5],[1,4.9,2]],"ltp":4.2,"tv":2024.82,"id":9345630},{"batb":[[0,1.28,648.5]],"batl":[[0,1.33,7],[1,1.36,20.89],[2,1.94,8.68]],"ltp":1.32,"tv":21376.04,"id":9028621}]}]}
{"op":"mcm","clk":"4226392681","pt":1631448890563,"mc":[{"id":"1.187552454","rc":[{"batb":[[0,4.1,2],[1,4,5],[2,2.2,42.66]],"ltp":4.2,"tv":2024.82,"id":9345630},{"batb":[[1,1.27,642.07],[2,1.26,66.48]],"batl":[[1,1.94,8.68],[2,8.8,7.23]],"ltp":1.32,"tv":21376.04,"id":9028621}]}]}
{"op":"mcm","clk":"4226392750","pt":1631448891049,"mc":[{"id":"1.187552454","rc":[{"batb":[[0,4,5],[1,2.2,42.66],[2,2,11.86]],"ltp":4.2,"tv":2024.82,"id":9345630},{"batb":[[1,1.27,667.58]],"ltp":1.32,"tv":21376.04,"id":9028621}]}]}
{"op":"mcm","clk":"4226392960","pt":1631448892562,"mc":[{"id":"1.187552454","rc":[{"batb":[[0,4.1,19.33],[1,4,5],[2,3.95,3]],"batl":[[0,4.6,20.5]],"ltp":4.2,"tv":2024.82,"id":9345630},{"batb":[[0,1.28,698.16]],"batl":[[0,1.31,517.57],[1,1.32,529.69],[2,1.33,7]],"ltp":1.32,"tv":21376.04,"id":9028621}]}]}
{"op":"mcm","clk":"4226393080","pt":1631448893315,"mc":[{"id":"1.187552454","rc":[{"batl":[[0,4.6,5]],"ltp":4.2,"tv":2024.82,"id":9345630},{"batl":[[1,1.32,551.22]],"ltp":1.32,"tv":21376.04,"id":9028621}]}]}
{"op":"mcm","clk":"4226393584","pt":1631448896493,"mc":[{"id":"1.187552454","rc":[{"trd":[[1.28,57.86]],"batb":[[0,1.28,669.23]],"ltp":1.28,"tv":21433.9,"id":9028621}],"tv":23458.72}]}
{"op":"mcm","clk":"4226393809","pt":1631448898075,"mc":[{"id":"1.187552454","rc":[{"batb":[[0,4.2,2],[1,4.1,21.33],[2,4,5]],"batl":[[2,5,2]],"ltp":4.2,"tv":2024.82,"id":9345630},{"batl":[[0,1.31,553.07]],"ltp":1.28,"tv":21433.9,"id":9028621}]}]}
{"op":"mcm","clk":"4226394087","pt":1631448899964,"mc":[{"id":"1.187552454","rc":[{"batb":[[1,1.27,642.07]],"batl":[[1,1.32,529.69]],"ltp":1.28,"tv":21433.9,"id":9028621}]}]}
{"op":"mcm","clk":"4226394326","pt":1631448901591,"mc":[{"id":"1.187552454","rc":[{"batb":[[0,1.28,669.54]],"ltp":1.28,"tv":21433.9,"id":9028621}]}]}
{"op":"mcm","clk":"4226394582","pt":1631448902966,"mc":[{"id":"1.187552454","rc":[{"batb":[[2,1.26,55.48]],"ltp":1.28,"tv":21433.9,"id":9028621}]}]}
{"op":"mcm","clk":"4226394934","pt":1631448905270,"mc":[{"id":"1.187552454","rc":[{"batl":[[1,1.32,551.22]],"ltp":1.28,"tv":21433.9,"id":9028621}]}]}
{"op":"mcm","clk":"4226395148","pt":1631448906546,"mc":[{"id":"1.187552454","rc":[{"batb":[[1,4.1,2]],"ltp":4.2,"tv":2024.82,"id":9345630},{"batb":[[0,1.28,619.88],[2,1.26,81.97]],"batl":[[1,1.32,516.22]],"ltp":1.28,"tv":21433.9,"id":9028621}]}]}
{"op":"mcm","clk":"4226395274","pt":1631448907377,"mc":[{"id":"1.187552454","rc":[{"batb":[[0,4.1,2],[1,4,3],[2,2.2,42.66]],"batl":[[0,5.6,2],[1,4.9,0],[2,5,0]],"ltp":4.2,"tv":2024.82,"id":9345630},{"batb":[[0,1.26,26.8],[1,1.22,53.84],[2,1.17,314.09]],"batl":[[0,1.32,21.53],[1,1.33,7],[2,1.94,8.68]],"ltp":1.28,"tv":21433.9,"id":9028621}]}]}
{"op":"mcm","clk":"4226395771","pt":1631448910388,"mc":[{"id":"1.187552454","rc":[{"batb":[[0,4.2,2],[1,4.1,4],[2,4,3]],"batl":[[0,5,2],[1,5.6,2]],"ltp":4.2,"tv":2024.82,"id":9345630},{"batb":[[1,1.25,946.1],[2,1.24,738.99]],"batl":[[0,1.31,39.5],[1,1.32,70.64],[2,1.33,293.43]],"ltp":1.28,"tv":21433.9,"id":9028621}]}]}
{"op":"mcm","clk":"4226395823","pt":1631448910667,"mc":[{"id":"1.187552454","rc":[{"batb":[[0,4.1,4],[1,4,3],[2,2.2,42.66]],"ltp":4.2,"tv":2024.82,"id":9345630},{"batl":[[0,1.32,70.64],[1,1.33,293.43],[2,1.34,462.45]],"ltp":1.28,"tv":21433.9,"id":9028621}]}]}
{"op":"mcm","clk":"4226396567","pt":1631448915798,"mc":[{"id":"1.187552454","rc":[{"batl":[[1,1.33,7],[2,1.94,8.68]],"ltp":1.28,"tv":21433.9,"id":9028621}]}]}
{"op":"mcm","clk":"4226396811","pt":1631448917479,"mc":[{"id":"1.187552454","rc":[{"batb":[[0,1.29,1482.87],[1,1.28,1438.96],[2,1.27,1438.96]],"batl":[[0,1.32,49.11]],"ltp":1.28,"tv":21433.9,"id":9028621}]}]}
{"op":"mcm","clk":"4226396961","pt":1631448918506,"mc":[{"id":"1.187552454","rc":[{"batl":[[1,5.3,360.85],[2,5.4,350.24]],"ltp":4.2,"tv":2024.82,"id":9345630},{"trd":[[1.29,1644.69],[1.3,399.93]],"batb":[[0,1.29,66.95],[1,1.28,71.95],[2,1.27,71.95]],"ltp":1.29,"tv":21448.88,"id":9028621}],"tv":23473.7}]}
{"op":"mcm","clk":"4226397099","pt":1631448919410,"mc":[{"id":"1.187552454","rc":[{"batb":[[0,4.1,6]],"batl":[[1,5.3,18.04],[2,5.4,17.51]],"ltp":4.2,"tv":2024.82,"id":9345630},{"trd":[[1.28,201.76],[1.29,1778.59]],"batb":[[0,1.27,71.95],[1,1.25,746.89],[2,1.22,53.84]],"batl":[[0,1.28,336.52],[1,1.29,559.32],[2,1.31,8]],"ltp":1.28,"tv":21726.68,"id":9028621}],"tv":23751.5}]}
{"op":"mcm","clk":"4226397282","pt":1631448920596,"mc":[{"id":"1.187552454","rc":[{"batb":[[0,4.2,607.55],[1,4.1,6],[2,4,3]],"batl":[[0,5,4]],"ltp":4.2,"tv":2024.82,"id":9345630},{"batb":[[1,1.25,754.89],[2,1.24,8]],"ltp":1.28,"tv":21726.68,"id":9028621}]}]}
{"op":"mcm","clk":"4226397460","pt":1631448921583,"mc":[{"id":"1.187552454","rc":[{"batb":[[0,4.2,20],[2,2.2,42.66]],"batl":[[0,4.9,10],[1,5,4],[2,5.3,18.04]],"ltp":4.2,"tv":2024.82,"id":9345630},{"batl":[[2,1.31,119.55]],"ltp":1.28,"tv":21726.68,"id":9028621}]}]}
{"op":"mcm","clk":"4226397553","pt":1631448922214,"mc":[{"id":"1.187552454","rc":[{"batb":[[2,2.6,3.71]],"batl":[[0,4.9,23.62]],"ltp":4.2,"tv":2024.82,"id":9345630},{"batl":[[2,1.31,141.24]],"ltp":1.28,"tv":21726.68,"id":9028621}]}]}
{"op":"mcm","clk":"4226397743","pt":1631448923480,"mc":[{"id":"1.187552454","rc":[{"trd":[[1.27,106.96]],"batb":[[0,1.27,18.47],[1,1.26,257.18],[2,1.25,754.89]],"batl":[[0,1.28,416.76]],"ltp":1.27,"tv":21833.64,"id":9028621}],"tv":23858.46}]}
{"op":"mcm","clk":"4226397851","pt":1631448924306,"mc":[{"id":"1.187552454","rc":[{"batb":[[1,4.1,646.15]],"ltp":4.2,"tv":2024.82,"id":9345630},{"trd":[[1.27,143.9]],"batb":[[0,1.26,257.18],[1,1.25,754.89],[2,1.24,8]],"batl":[[0,1.27,3.91],[1,1.28,416.76],[2,1.29,559.32]],"ltp":1.27,"tv":21870.58,"id":9028621}],"tv":23895.4}]}
{"op":"mcm","clk":"4226398089","pt":1631448925812,"mc":[{"id":"1.187552454","rc":[{"batb":[[0,4.4,2],[1,4.3,2],[2,4.1,6]],"ltp":4.2,"tv":2024.82,"id":9345630},{"batl":[[2,1.29,601.82]],"ltp":1.27,"tv":21870.58,"id":9028621}]}]}
{"op":"mcm","clk":"4226398367","pt":1631448927609,"mc":[{"id":"1.187552454","rc":[{"batb":[[0,4.5,2],[1,4.4,2],[2,4.3,2]],"ltp":4.2,"tv":2024.82,"id":9345630},{"batl":[[1,1.28,462.1]],"ltp":1.27,"tv":21870.58,"id":9028621}]}]}
{"op":"mcm","clk":"4226398545","pt":1631448928904,"mc":[{"id":"1.187552454","rc":[{"batb":[[0,4.5,22]],"ltp":4.2,"tv":2024.82,"id":9345630}]}]}
{"op":"mcm","clk":"4226399282","pt":1631448933510,"mc":[{"id":"1.187552454","rc":[{"batb":[[0,4.5,2]],"batl":[[0,5,4],[1,5.4,2],[2,5.6,2]],"ltp":4.2,"tv":2024.82,"id":9345630},{"batb":[[2,1.23,50.63]],"ltp":1.27,"tv":21870.58,"id":9028621}]}]}
{"op":"mcm","clk":"4226399369","pt":1631448934137,"mc":[{"id":"1.187552454","rc":[{"batb":[[0,4.4,2],[1,4.1,2],[2,2.6,3.71]],"batl":[[0,5.8,2],[1,5.4,0],[2,5.6,0]],"ltp":4.2,"tv":2024.82,"id":9345630},{"batb":[[0,1.21,60.69],[1,1.19,66.2],[2,1.1,296.65]],"batl":[[1,1.29,42.5],[2,1.32,9]],"ltp":1.27,"tv":21870.58,"id":9028621}]}]}
{"op":"mcm","clk":"4226399502","pt":1631448935009,"mc":[{"id":"1.187552454","rc":[{"batb":[[1,1.1,296.65],[2,1.05,474.54]],"ltp":1.27,"tv":21870.58,"id":9028621}]}]}
{"op":"mcm","clk":"4226399889","pt":1631448937449,"mc":[{"id":"1.187552454","rc":[{"batb":[[0,4.5,2],[1,4.4,2],[2,4.1,2]],"batl":[[0,5.4,4],[1,5.5,3],[2,5.8,4]],"ltp":4.2,"tv":2024.82,"id":9345630},{"batb":[[0,1.23,67.63],[1,1.22,3],[2,1.21,64.69]],"batl":[[1,1.28,46.09],[2,1.29,42.5]],"ltp":1.27,"tv":21870.58,"id":9028621}]}]}
{"op":"mcm","clk":"4226399945","pt":1631448937721,"mc":[{"id":"1.187552454","rc":[{"batb":[[0,4.4,2],[1,4.1,2],[2,2.6,3.71]],"batl":[[0,5.4,2]],"ltp":4.2,"tv":2024.82,"id":9345630},{"batb":[[0,1.23,4]],"batl":[[1,1.29,42.5],[2,1.32,9]],"ltp":1.27,"tv":21870.58,"id":9028621}]}]}
{"op":"mcm","clk":"4226400180","pt":1631448939226,"mc":[{"id":"1.187552454","rc":[{"batb":[[2,1.21,97.49]],"ltp":1.27,"tv":21870.58,"id":9028621}]}]}
{"op":"mcm","clk":"4226400478","pt":1631448941210,"mc":[{"id":"1.187552454","rc":[{"batb":[[0,1.25,572.23],[1,1.24,729.97],[2,1.23,4]],"batl":[[1,1.28,759.39],[2,1.29,595.01]],"ltp":1.27,"tv":21870.58,"id":9028621}]}]}
{"op":"mcm","clk":"4226400970","pt":1631448944439,"mc":[{"id":"1.187552454","rc":[{"batb":[[0,4.5,2],[1,4.4,2],[2,4.1,2]],"batl":[[0,5.4,4]],"ltp":4.2,"tv":2024.82,"id":9345630},{"batb":[[0,1.23,57.63],[1,1.22,3],[2,1.21,97.49]],"batl":[[1,1.28,41.09],[2,1.29,42.5]],"ltp":1.27,"tv":21870.58,"id":9028621}]}]}
{"op":"mcm","clk":"4226401024","pt":1631448944807,"mc":[{"id":"1.187552454","rc":[{"batb":[[0,4.4,2],[1,4.1,2],[2,2.6,3.71]],"batl":[[0,5.4,2]],"ltp":4.2,"tv":2024.82,"id":9345630},{"batb":[[0,1.23,4]],"batl":[[1,1.29,42.5],[2,1.32,9]],"ltp":1.27,"tv":21870.58,"id":9028621}]}]}
{"op":"mcm","clk":"4226401339","pt":1631448947032,"mc":[{"id":"1.187552454","rc":[{"batb":[[0,1.23,485.63],[1,1.22,810.94]],"batl":[[2,1.31,607.68]],"ltp":1.27,"tv":21870.58,"id":9028621}]}]}
{"op":"mcm","clk":"4226401522","pt":1631448948438,"mc":[{"id":"1.187552454","rc":[{"batl":[[0,5.4,4]],"ltp":4.2,"tv":2024.82,"id":9345630},{"batb":[[0,1.23,550.26],[1,1.22,807.94]],"ltp":1.27,"tv":21870.58,"id":9028621}]}]}
{"op":"mcm","clk":"4226401691","pt":1631448949535,"mc":[{"id":"1.187552454","rc":[{"batl":[[0,5.4,2],[1,5.8,2],[2,5.8,0]],"ltp":4.2,"tv":2024.82,"id":9345630},{"batb":[[0,1.23,4],[1,1.21,93.49],[2,1.1,296.65]],"ltp":1.27,"tv":21870.58,"id":9028621}]}]}
{"op":"mcm","clk":"4226401837","pt":1631448950547,"mc":[{"id":"1.187552454","rc":[{"trd":[[4.7,1.06]],"batl":[[0,4.7,20.35],[1,4.8,19.75],[2,4.9,19.75]],"ltp":4.7,"tv":2025.88,"id":9345630},{"trd":[[1.27,147.81]],"batb":[[1,1.21,60.69]],"batl":[[0,1.29,42.5],[1,1.31,607.68],[2,1.32,501.33]],"ltp":1.27,"tv":21874.49,"id":9028621}],"tv":23900.37}]}
{"op":"mcm","clk":"4226401962","pt":1631448951442,"mc":[{"id":"1.187552454","rc":[{"batl":[[0,4.7,223.81],[1,4.8,217.23],[2,4.9,219.38]],"ltp":4.7,"tv":2025.88,"id":9345630},{"batb":[[0,1.26,24.98],[1,1.23,4],[2,1.21,60.69]],"ltp":1.27,"tv":21874.49,"id":9028621}]}]}
{"op":"mcm","clk":"4226402108","pt":1631448952535,"mc":[{"id":"1.187552454","rc":[{"batb":[[0,1.28,506.99],[1,1.27,631.05],[2,1.26,24.98]],"batl":[[2,1.32,492.33]],"ltp":1.27,"tv":21874.49,"id":9028621}]}]}
{"op":"mcm","clk":"4226402244","pt":1631448953455,"mc":[{"id":"1.187552454","rc":[{"trd":[[1.28,253.36]],"batb":[[0,1.28,481.19]],"ltp":1.28,"tv":21926.09,"id":9028621}],"tv":23951.97}]}
{"op":"mcm","clk":"4226402415","pt":1631448954539,"mc":[{"id":"1.187552454","rc":[{"batl":[[0,4.6,13.76],[1,4.7,223.81],[2,4.8,217.23]],"ltp":4.7,"tv":2025.88,"id":9345630}]}]}
{"op":"mcm","clk":"4226402568","pt":1631448955461,"mc":[{"id":"1.187552454","rc":[{"batb":[[2,4,2]],"ltp":4.7,"tv":2025.88,"id":9345630}]}]}
{"op":"mcm","clk":"4226402714","pt":1631448956342,"mc":[{"id":"1.187552454","rc":[{"trd":[[1.28,293.76]],"batb":[[0,1.28,460.99]],"ltp":1.28,"tv":21966.49,"id":9028621}],"tv":23992.37}]}
{"op":"mcm","clk":"4226402959","pt":1631448957829,"mc":[{"id":"1.187552454","rc":[{"batb":[[1,4.2,2],[2,4.1,2]],"ltp":4.7,"tv":2025.88,"id":9345630},{"batb":[[0,1.28,504.37]],"batl":[[1,1.31,647.18]],"ltp":1.28,"tv":21966.49,"id":9028621}]}]}
{"op":"mcm","clk":"4226403225","pt":1631448959641,"mc":[{"id":"1.187552454","rc":[{"trd":[[1.28,355.32]],"batb":[[0,1.28,473.59]],"ltp":1.28,"tv":22028.05,"id":9028621}],"tv":24053.93}]}
{"op":"mcm","clk":"4226403828","pt":1631448963183,"mc":[{"id":"1.187552454","rc":[{"batb":[[0,1.28,518.07]],"ltp":1.28,"tv":22028.05,"id":9028621}]}]}
{"op":"mcm","clk":"4226404687","pt":1631448968492,"mc":[{"id":"1.187552454","rc":[{"batl":[[1,4.7,225.81]],"ltp":4.7,"tv":2025.88,"id":9345630},{"batb":[[2,1.26,32.98]],"ltp":1.28,"tv":22028.05,"id":9028621}]}]}
{"op":"mcm","clk":"4226405318","pt":1631448972377,"mc":[{"id":"1.187552454","rc":[{"batb":[[0,4.1,2],[1,4,4],[2,2.6,3.71]],"batl":[[0,4.7,2],[1,5.4,2],[2,5.8,2]],"ltp":4.7,"tv":2025.88,"id":9345630},{"batb":[[0,1.26,8],[1,1.24,28.7],[2,1.23,4]],"batl":[[0,1.28,605.94],[1,1.33,37.5],[2,1.94,8.68]],"ltp":1.28,"tv":22028.05,"id":9028621}]}]}
{"op":"mcm","clk":"4226405374","pt":1631448972714,"mc":[{"id":"1.187552454","rc":[{"batl":[[0,5.4,2],[1,5.8,2],[2,5.8,0]],"ltp":4.7,"tv":2025.88,"id":9345630},{"batb":[[0,1.24,28.7],[1,1.23,4],[2,1.21,60.69]],"ltp":1.28,"tv":22028.05,"id":9028621}]}]}
{"op":"mcm","clk":"4226405827","pt":1631448975403,"mc":[{"id":"1.187552454","rc":[{"batb":[[0,4.2,2],[1,4.1,2],[2,4,4]],"batl":[[0,5.2,2],[1,5.4,2],[2,5.8,2]],"ltp":4.7,"tv":2025.88,"id":9345630},{"batb":[[0,1.24,74.47]],"batl":[[1,1.31,38.5],[2,1.33,37.5]],"ltp":1.28,"tv":22028.05,"id":9028621}]}]}
{"op":"mcm","clk":"4226406028","pt":1631448976537,"mc":[{"id":"1.187552454","rc":[{"batl":[[0,5.2,3]],"ltp":4.7,"tv":2025.88,"id":9345630},{"batb":[[0,1.24,9]],"ltp":1.28,"tv":22028.05,"id":9028621}]}]}
{"op":"mcm","clk":"4226406512","pt":1631448979290,"mc":[{"id":"1.187552454","rc":[{"batb":[[0,1.27,707.12],[1,1.26,665.83],[2,1.24,9]],"batl":[[1,1.3,490.3],[2,1.31,553.1]],"ltp":1.28,"tv":22028.05,"id":9028621}]}]}
{"op":"mcm","clk":"4226406801","pt":1631448981274,"mc":[{"id":"1.187552454","rc":[{"batb":[[0,4.2,12]],"batl":[[0,5.1,15],[1,5.2,3],[2,5.4,2]],"ltp":4.7,"tv":2025.88,"id":9345630}]}]}
{"op":"mcm","clk":"4226407013","pt":1631448982517,"mc":[{"id":"1.187552454","rc":[{"batl":[[1,5.2,5]],"ltp":4.7,"tv":2025.88,"id":9345630},{"batb":[[2,1.24,67.02]],"ltp":1.28,"tv":22028.05,"id":9028621}]}]}
{"op":"mcm","clk":"4226407186","pt":1631448983527,"mc":[{"id":"1.187552454","rc":[{"batb":[[0,4.2,2],[2,4,2]],"batl":[[0,5.2,5],[1,5.4,2],[2,5.8,2]],"ltp":4.7,"tv":2025.88,"id":9345630},{"batl":[[0,1.3,490.3],[1,1.31,553.1],[2,1.33,37.5]],"ltp":1.28,"tv":22028.05,"id":9028621}]}]}
{"op":"mcm","clk":"4226407324","pt":1631448984412,"mc":[{"id":"1.187552454","rc":[{"batb":[[0,4.1,2],[1,4,2],[2,2.6,3.71]],"batl":[[0,5.2,3]],"ltp":4.7,"tv":2025.88,"id":9345630},{"batb":[[0,1.27,52.63],[1,1.24,9],[2,1.23,4]],"batl":[[0,1.33,37.5],[1,1.94,8.68],[2,8.8,7.23]],"ltp":1.28,"tv":22028.05,"id":9028621}]}]}
{"op":"mcm","clk":"4226407377","pt":1631448984722,"mc":[{"id":"1.187552454","rc":[{"batb":[[0,1.24,9],[1,1.23,4],[2,1.22,31.31]],"ltp":1.28,"tv":22028.05,"id":9028621}]}]}
{"op":"mcm","clk":"4226407654","pt":1631448986428,"mc":[{"id":"1.187552454","rc":[{"batl":[[0,1.27,605.94],[1,1.33,37.5],[2,1.94,8.68]],"ltp":1.28,"tv":22028.05,"id":9028621}]}]}
{"op":"mcm","clk":"4226407850","pt":1631448987517,"mc":[{"id":"1.187552454","rc":[{"batb":[[0,4.2,3],[1,4.1,2],[2,4,4]],"batl":[[1,5.8,2],[2,5.8,0]],"ltp":4.7,"tv":2025.88,"id":9345630},{"batb":[[0,1.25,393.67],[1,1.24,735.45]],"batl":[[1,1.31,8],[2,1.32,7]],"ltp":1.28,"tv":22028.05,"id":9028621}]}]}
{"op":"mcm","clk":"4226407870","pt":1631448987615,"mc":[{"id":"1.187552454","rc":[{"batb":[[0,4.2,5]],"batl":[[0,5.2,5]],"ltp":4.7,"tv":2025.88,"id":9345630},{"batb":[[1,1.24,796.22]],"batl":[[1,1.31,51.5]],"ltp":1.28,"tv":22028.05,"id":9028621}]}]}
{"op":"mcm","clk":"4226408297","pt":1631448990408,"mc":[{"id":"1.187552454","rc":[{"batl":[[0,5.2,3]],"ltp":4.7,"tv":2025.88,"id":9345630},{"batb":[[0,1.24,9],[1,1.22,31.31],[2,1.21,60.69]],"ltp":1.28,"tv":22028.05,"id":9028621}]}]}
{"op":"mcm","clk":"4226408655","pt":1631448992517,"mc":[{"id":"1.187552454","rc":[{"batb":[[0,4.2,2],[1,4,2],[2,2.6,3.71]],"ltp":4.7,"tv":2025.88,"id":9345630},{"trd":[[1.27,1359.69]],"batb":[[0,1.3,1493.55],[1,1.29,944.94],[2,1.28,1427.88]],"batl":[[0,1.31,43.5],[1,1.32,60.55],[2,1.33,37.5]],"ltp":1.27,"tv":23239.93,"id":9028621}],"tv":25265.81}]}
{"op":"mcm","clk":"4226408875","pt":1631448993534,"mc":[{"id":"1.187552454","rc":[{"batb":[[0,4,2],[1,3.8,503.28],[2,3.75,488.48]],"batl":[[0,4.6,2.26],[1,5.2,3],[2,5.8,2]],"ltp":4.7,"tv":2025.88,"id":9345630},{"batb":[[0,1.31,322.34],[1,1.3,1360.47],[2,1.29,785.33]],"batl":[[0,1.32,60.55],[1,1.33,37.5],[2,1.34,610.91]],"ltp":1.27,"tv":23239.93,"id":9028621}]}]}
{"op":"mcm","clk":"4226408959","pt":1631448994020,"mc":[{"id":"1.187552454","rc":[{"batl":[[1,4.7,2],[2,5.2,3]],"ltp":4.7,"tv":2025.88,"id":9345630}]}]}
{"op":"mcm","clk":"4226409150","pt":1631448995318,"mc":[{"id":"1.187552454","rc":[{"batl":[[1,4.7,5]],"ltp":4.7,"tv":2025.88,"id":9345630},{"batb":[[0,1.31,344.56],[2,1.29,809.08]],"ltp":1.27,"tv":23239.93,"id":9028621}]}]}
{"op":"mcm","clk":"4226409287","pt":1631448996232,"mc":[{"id":"1.187552454","rc":[{"batb":[[0,1.31,322.34],[2,1.29,785.33]],"ltp":1.27,"tv":23239.93,"id":9028621}]}]}
{"op":"mcm","clk":"4226409624","pt":1631448998135,"mc":[{"id":"1.187552454","rc":[{"batl":[[0,4.5,15],[1,4.6,2.26],[2,4.7,5]],"ltp":4.7,"tv":2025.88,"id":9345630}]}]}
{"op":"mcm","clk":"4226409912","pt":1631449000056,"mc":[{"id":"1.187552454","rc":[{"batb":[[1,3.9,2],[2,3.8,503.28]],"ltp":4.7,"tv":2025.88,"id":9345630},{"batl":[[2,1.34,652.16]],"ltp":1.27,"tv":23239.93,"id":9028621}]}]}
{"op":"mcm","clk":"4226410502","pt":1631449004305,"mc":[{"id":"1.187552454","rc":[{"trd":[[1.32,238.42]],"batb":[[0,1.32,6.45],[1,1.31,322.34],[2,1.3,1360.47]],"batl":[[0,1.33,37.5],[1,1.34,652.16],[2,1.35,440.88]],"ltp":1.32,"tv":23361.03,"id":9028621}],"tv":25386.91}]}
{"op":"mcm","clk":"4226410921","pt":1631449007260,"mc":[{"id":"1.187552454","rc":[{"batl":[[1,1.34,609.37]],"ltp":1.32,"tv":23361.03,"id":9028621}]}]}
{"op":"mcm","clk":"4226411056","pt":1631449008271,"mc":[{"id":"1.187552454","rc":[{"batb":[[2,3.85,2.04]],"ltp":4.7,"tv":2025.88,"id":9345630},{"trd":[[1.32,238.78]],"batb":[[0,1.32,6.27]],"batl":[[2,1.35,472.98]],"ltp":1.32,"tv":23361.39,"id":9028621}],"tv":25387.27}]}
{"op":"mcm","clk":"4226411320","pt":1631449010360,"mc":[{"id":"1.187552454","rc":[{"batb":[[1,1.31,366.18]],"ltp":1.32,"tv":23361.39,"id":9028621}]}]}
{"op":"mcm","clk":"4226411519","pt":1631449011897,"mc":[{"id":"1.187552454","rc":[{"batb":[[0,1.31,366.18],[1,1.3,1360.47],[2,1.29,785.33]],"ltp":1.32,"tv":23361.39,"id":9028621}]}]}
{"op":"mcm","clk":"4226411864","pt":1631449014564,"mc":[{"id":"1.187552454","rc":[{"batl":[[1,1.34,571.28]],"ltp":1.32,"tv":23361.39,"id":9028621}]}]}
{"op":"mcm","clk":"4226411915","pt":1631449015004,"mc":[{"id":"1.187552454","rc":[{"trd":[[1.31,737.85]],"batb":[[0,1.31,126.99]],"ltp":1.31,"tv":23839.77,"id":9028621}],"tv":25865.65}]}
{"op":"mcm","clk":"4226412110","pt":1631449016386,"mc":[{"id":"1.187552454","rc":[{"batb":[[0,3.9,2],[1,3.85,2.04],[2,2.2,42.66]],"batl":[[0,4.7,3],[1,4.8,2],[2,5.2,2]],"ltp":4.7,"tv":2025.88,"id":9345630},{"batb":[[1,1.3,551.34],[2,1.27,59.87]],"batl":[[0,1.34,571.28],[1,1.35,472.98],[2,1.72,877.31]],"ltp":1.31,"tv":23839.77,"id":9028621}]}]}
{"op":"mcm","clk":"4226412280","pt":1631449017500,"mc":[{"id":"1.187552454","rc":[{"batb":[[0,3.85,2.04],[1,2.2,42.66],[2,2,11.86]],"batl":[[0,5.2,2],[1,4.8,0],[2,5.2,0]],"ltp":4.7,"tv":2025.88,"id":9345630},{"batb":[[0,1.26,26.49],[1,1.24,51.77],[2,1.23,46.5]],"batl":[[0,1.35,32.1],[1,1.72,877.31],[2,1.94,8.68]],"ltp":1.31,"tv":23839.77,"id":9028621}]}]}
{"op":"mcm","clk":"4226412654","pt":1631449020072,"mc":[{"id":"1.187552454","rc":[{"batb":[[0,3.9,2],[1,3.85,5.04],[2,2.2,42.66]],"ltp":4.7,"tv":2025.88,"id":9345630},{"batb":[[0,1.33,3.9],[1,1.28,383.88],[2,1.27,629.7]],"batl":[[0,1.34,8],[1,1.35,32.1],[2,1.36,324]],"ltp":1.31,"tv":23839.77,"id":9028621}]}]}
{"op":"mcm","clk":"4226412798","pt":1631449021106,"mc":[{"id":"1.187552454","rc":[{"batb":[[2,3.8,2]],"batl":[[0,4.8,2],[1,5.2,2]],"ltp":4.7,"tv":2025.88,"id":9345630},{"batb":[[2,1.27,676.57]],"batl":[[1,1.35,40.1]],"ltp":1.31,"tv":23839.77,"id":9028621}]}]}
{"op":"mcm","clk":"4226413120","pt":1631449023514,"mc":[{"id":"1.187552454","rc":[{"batb":[[1,1.27,46.87],[2,1.25,27.55]],"ltp":1.31,"tv":23839.77,"id":9028621}]}]}
{"op":"mcm","clk":"4226413314","pt":1631449024592,"mc":[{"id":"1.187552454","rc":[{"batb":[[0,3.85,2.04],[1,2.2,42.66],[2,2,11.86]],"batl":[[0,5.2,2],[1,5.2,0]],"ltp":4.7,"tv":2025.88,"id":9345630},{"batb":[[1,1.32,72.44],[2,1.31,70.31]],"batl":[[0,1.35,32.1],[1,1.36,324],[2,1.37,415.1]],"ltp":1.31,"tv":23839.77,"id":9028621}]}]}
{"op":"mcm","clk":"4226413429","pt":1631449025289,"mc":[{"id":"1.187552454","rc":[{"batb":[[0,1.32,72.44],[1,1.31,70.31],[2,1.3,70.31]],"ltp":1.31,"tv":23839.77,"id":9028621}]}]}
{"op":"mcm","clk":"4226413636","pt":1631449026576,"mc":[{"id":"1.187552454","rc":[{"batb":[[1,3.65,288.18],[2,3.6,279.71]],"batl":[[0,4.4,2.34],[1,5.2,2]],"ltp":4.7,"tv":2025.88,"id":9345630},{"batb":[[0,1.33,527.35],[1,1.32,1308.8],[2,1.31,773.44]],"ltp":1.31,"tv":23839.77,"id":9028621}]}]}
{"op":"mcm","clk":"4226413796","pt":1631449027597,"mc":[{"id":"1.187552454","rc":[{"batl":[[0,4.1,2],[1,4.4,2.34],[2,4.5,2]],"ltp":4.7,"tv":2025.88,"id":9345630},{"batb":[[0,1.33,546.85]],"ltp":1.31,"tv":23839.77,"id":9028621}]}]}
{"op":"mcm","clk":"4226414082","pt":1631449029378,"mc":[{"id":"1.187552454","rc":[{"batb":[[0,1.33,567.73]],"ltp":1.31,"tv":23839.77,"id":9028621}]}]}
{"op":"mcm","clk":"4226414351","pt":1631449031218,"mc":[{"id":"1.187552454","rc":[{"batl":[[0,4,10],[1,4.1,2],[2,4.4,2.34]],"ltp":4.7,"tv":2025.88,"id":9345630}]}]}
{"op":"mcm","clk":"4226415229","pt":1631449037199,"mc":[{"id":"1.187552454","rc":[{"trd":[[3.85,14.03]],"batb":[[0,3.65,288.18],[1,3.6,279.71],[2,3.55,279.71]],"ltp":3.85,"tv":2032.92,"id":9345630},{"trd":[[1.35,976.72]],"batl":[[0,1.35,23.66]],"ltp":1.35,"tv":23848.21,"id":9028621}],"tv":25881.13}]}
{"op":"mcm","clk":"4226415691","pt":1631449040409,"mc":[{"id":"1.187552454","rc":[{"batb":[[0,3.7,14.52],[1,3.65,288.18],[2,3.6,279.71]],"ltp":3.85,"tv":2032.92,"id":9345630},{"trd":[[1.35,984.52]],"batl":[[0,1.35,19.76]],"ltp":1.35,"tv":23856.01,"id":9028621}],"tv":25888.93}]}
{"op":"mcm","clk":"4226416350","pt":1631449044712,"mc":[{"id":"1.187552454","rc":[{"trd":[[1.33,343.8]],"batb":[[0,1.33,479.78]],"ltp":1.33,"tv":24031.91,"id":9028621}],"tv":26064.83}]}
{"op":"mcm","clk":"4226416792","pt":1631449047555,"mc":[{"id":"1.187552454","rc":[{"batb":[[0,1.33,458.9]],"ltp":1.33,"tv":24031.91,"id":9028621}]}]}
{"op":"mcm","clk":"4226416928","pt":1631449048454,"mc":[{"id":"1.187552454","rc":[{"trd":[[3.85,19.15]],"ltp":3.85,"tv":2038.04,"id":9345630},{"trd":[[1.35,999.13]],"batb":[[0,1.33,509.84]],"batl":[[0,1.35,5.15]],"ltp":1.35,"tv":24046.52,"id":9028621}],"tv":26084.56}]}
{"op":"mcm","clk":"4226417318","pt":1631449051140,"mc":[{"id":"1.187552454","rc":[{"batl":[[1,1.36,364.26]],"ltp":1.35,"tv":24046.52,"id":9028621}]}]}
{"op":"mcm","clk":"4226417818","pt":1631449054547,"mc":[{"id":"1.187552454","rc":[{"batb":[[0,3.4,2.01],[1,3.2,2.02],[2,2.2,42.66]],"batl":[[0,5,2],[1,4.1,0],[2,4.4,0]],"ltp":3.85,"tv":2038.04,"id":9345630},{"batb":[[0,1.26,26.49],[1,1.25,51.49],[2,1.24,37.49]],"batl":[[0,1.41,30.5],[1,1.45,26.7],[2,1.72,877.31]],"ltp":1.35,"tv":24046.52,"id":9028621}]}]}
{"op":"mcm","clk":"4226417839","pt":1631449054661,"mc":[{"id":"1.187552454","rc":[{"batb":[[0,3.2,2.02],[1,2.2,42.66],[2,2,11.86]],"ltp":3.85,"tv":2038.04,"id":9345630},{"batl":[[0,1.45,26.7],[1,1.72,877.31],[2,1.94,8.68]],"ltp":1.35,"tv":24046.52,"id":9028621}]}]}
{"op":"mcm","clk":"4226418277","pt":1631449057528,"mc":[{"id":"1.187552454","rc":[{"batb":[[0,3.5,2],[1,3.45,3],[2,3.4,3]],"ltp":3.85,"tv":2038.04,"id":9345630},{"batb":[[0,1.29,550.73],[1,1.28,606.18],[2,1.26,26.49]],"batl":[[0,1.41,8],[1,1.43,523.79],[2,1.44,331.14]],"ltp":1.35,"tv":24046.52,"id":9028621}]}]}
{"op":"mcm","clk":"4226418384","pt":1631449058233,"mc":[{"id":"1.187552454","rc":[{"batl":[[0,4.6,2],[1,4.9,3],[2,5,2]],"ltp":3.85,"tv":2038.04,"id":9345630},{"batb":[[1,1.28,650.09],[2,1.27,9]],"batl":[[1,1.42,8],[2,1.43,523.79]],"ltp":1.35,"tv":24046.52,"id":9028621}]}]}
{"op":"mcm","clk":"4226418549","pt":1631449059349,"mc":[{"id":"1.187552454","rc":[{"batl":[[0,1.33,68.89],[1,1.41,8],[2,1.42,8]],"ltp":1.35,"tv":24046.52,"id":9028621}]}]}
{"op":"mcm","clk":"4226418662","pt":1631449060158,"mc":[{"id":"1.187552454","rc":[{"batl":[[1,1.4,7],[2,1.41,8]],"ltp":1.35,"tv":24046.52,"id":9028621}]}]}
{"op":"mcm","clk":"4226418826","pt":1631449061430,"mc":[{"id":"1.187552454","rc":[{"batb":[[2,3.4,5.01]],"ltp":3.85,"tv":2038.04,"id":9345630},{"batl":[[2,1.41,40.5]],"ltp":1.35,"tv":24046.52,"id":9028621}]}]}
{"op":"mcm","clk":"4226418860","pt":1631449061657,"mc":[{"id":"1.187552454","rc":[{"batb":[[2,3.4,3]],"ltp":3.85,"tv":2038.04,"id":9345630},{"batl":[[2,1.41,8]],"ltp":1.35,"tv":24046.52,"id":9028621}]}]}
{"op":"mcm","clk":"4226419051","pt":1631449063072,"mc":[{"id":"1.187552454","rc":[{"batl":[[0,1.4,7],[1,1.41,8],[2,1.42,8]],"ltp":1.35,"tv":24046.52,"id":9028621}]}]}
{"op":"mcm","clk":"4226419240","pt":1631449064449,"mc":[{"id":"1.187552454","rc":[{"batl":[[0,1.32,5403.18],[1,1.33,1437.97],[2,1.34,1395.68]],"ltp":1.35,"tv":24046.52,"id":9028621}]}]}
{"op":"mcm","clk":"4226419338","pt":1631449065039,"mc":[{"id":"1.187552454","rc":[{"batl":[[0,1.33,71.9],[1,1.34,69.78],[2,1.35,69.78]],"ltp":1.35,"tv":24046.52,"id":9028621}]}]}
{"op":"mcm","clk":"4226430030","pt":1631449066474,"mc":[{"id":"1.187552454","rc":[{"batl":[[1,4.7,813.84],[2,4.8,789.9]],"ltp":3.85,"tv":2038.04,"id":9345630},{"batl":[[0,1.33,1509.87],[1,1.34,1465.46],[2,1.35,1465.46]],"ltp":1.35,"tv":24046.52,"id":9028621}]}]}
{"op":"mcm","clk":"4226430161","pt":1631449067441,"mc":[{"id":"1.187552454","rc":[{"batb":[[0,4,2],[1,3.5,2],[2,3.45,3]],"batl":[[1,4.7,223.81],[2,4.8,394.96]],"ltp":3.85,"tv":2038.04,"id":9345630},{"batl":[[0,1.32,511.44],[1,1.33,1267.98],[2,1.34,774.62]],"ltp":1.35,"tv":24046.52,"id":9028621}]}]}
{"op":"mcm","clk":"4226430276","pt":1631449068244,"mc":[{"id":"1.187552454","rc":[{"batb":[[1,3.55,650.59],[2,3.5,2]],"ltp":3.85,"tv":2038.04,"id":9345630}]}]}
{"op":"mcm","clk":"4226430482","pt":1631449069570,"mc":[{"id":"1.187552454","rc":[{"batb":[[1,3.55,660.59]],"batl":[[0,4.5,10],[1,4.6,2],[2,4.7,223.81]],"ltp":3.85,"tv":2038.04,"id":9345630},{"batb":[[0,1.29,599.89]],"batl":[[1,1.33,1317.97]],"ltp":1.35,"tv":24046.52,"id":9028621}]}]}
{"op":"mcm","clk":"4226430628","pt":1631449070578,"mc":[{"id":"1.187552454","rc":[{"batb":[[1,3.55,650.59]],"ltp":3.85,"tv":2038.04,"id":9345630}]}]}
{"op":"mcm","clk":"4226431121","pt":1631449074086,"mc":[{"id":"1.187552454","rc":[{"batb":[[1,3.85,2],[2,3.6,2.04]],"ltp":3.85,"tv":2038.04,"id":9345630}]}]}
{"op":"mcm","clk":"4226431362","pt":1631449075494,"mc":[{"id":"1.187552454","rc":[{"trd":[[4.5,10.4]],"batl":[[0,4.5,4.8]],"ltp":4.5,"tv":2048.44,"id":9345630}],"tv":26094.96}]}
{"op":"mcm","clk":"4226431485","pt":1631449076257,"mc":[{"id":"1.187552454","rc":[{"batb":[[0,4,21.24]],"ltp":4.5,"tv":2048.44,"id":9345630}]}]}
{"op":"mcm","clk":"4226432604","pt":1631449083160,"mc":[{"id":"1.187552454","rc":[{"trd":[[1.29,1782.59]],"batb":[[0,1.29,597.89]],"ltp":1.29,"tv":24050.52,"id":9028621}],"tv":26098.96}]}
{"op":"mcm","clk":"4226432842","pt":1631449084488,"mc":[{"id":"1.187552454","rc":[{"batb":[[0,3.85,2],[1,3.6,2.04],[2,3.5,2]],"batl":[[0,4.9,3],[1,5,2],[2,5.6,2]],"ltp":4.5,"tv":2048.44,"id":9345630},{"batb":[[0,1.27,9],[1,1.25,51.49],[2,1.22,65.34]],"batl":[[0,1.29,137.77],[1,1.35,37.1],[2,1.38,29.75]],"ltp":1.29,"tv":24050.52,"id":9028621}]}]}
{"op":"mcm","clk":"4226432921","pt":1631449084876,"mc":[{"id":"1.187552454","rc":[{"batb":[[0,3.6,2.04],[1,3.5,2],[2,2.2,42.66]],"batl":[[0,5.6,2],[1,5,0],[2,5.6,0]],"ltp":4.5,"tv":2048.44,"id":9345630},{"batb":[[0,1.22,65.34],[1,1.1,296.65],[2,1.05,474.54]],"batl":[[1,1.38,29.75],[2,1.4,7]],"ltp":1.29,"tv":24050.52,"id":9028621}]}]}
{"op":"mcm","clk":"4226433053","pt":1631449085689,"mc":[{"id":"1.187552454","rc":[{"batb":[[0,1.23,29.95],[1,1.22,65.34],[2,1.1,296.65]],"ltp":1.29,"tv":24050.52,"id":9028621}]}]}
{"op":"mcm","clk":"4226433348","pt":1631449087591,"mc":[{"id":"1.187552454","rc":[{"batb":[[0,3.85,3],[1,3.8,3],[2,3.6,2.04]],"ltp":4.5,"tv":2048.44,"id":9345630},{"batb":[[0,1.26,505.62],[1,1.25,695.39],[2,1.23,29.95]],"batl":[[0,1.34,8],[1,1.35,7],[2,1.37,346.13]],"ltp":1.29,"tv":24050.52,"id":9028621}]}]}
{"op":"mcm","clk":"4226433462","pt":1631449088180,"mc":[{"id":"1.187552454","rc":[{"batl":[[0,5,2],[1,5.6,4]],"ltp":4.5,"tv":2048.44,"id":9345630},{"batb":[[1,1.25,750.72]],"ltp":1.29,"tv":24050.52,"id":9028621}]}]}
{"op":"mcm","clk":"4226433645","pt":1631449089399,"mc":[{"id":"1.187552454","rc":[{"batl":[[0,5.4,3]],"ltp":4.5,"tv":2048.44,"id":9345630},{"batb":[[0,1.23,41.95],[1,1.22,78.34],[2,1.21,10]],"batl":[[0,1.34,8.99],[2,1.38,29.75]],"ltp":1.29,"tv":24050.52,"id":9028621}]}]}
{"op":"mcm","clk":"4226433735","pt":1631449089981,"mc":[{"id":"1.187552454","rc":[{"batl":[[0,1.29,12.02],[1,1.34,8],[2,1.35,7]],"ltp":1.29,"tv":24050.52,"id":9028621}]}]}
{"op":"mcm","clk":"4226433969","pt":1631449091481,"mc":[{"id":"1.187552454","rc":[{"trd":[[4.4,4.92]],"batb":[[0,3.9,3],[1,3.85,5],[2,3.8,3]],"ltp":4.4,"tv":2051.96,"id":9345630},{"trd":[[1.29,1794.6]],"batl":[[0,1.34,8],[1,1.35,42.1],[2,1.38,29.75]],"ltp":1.29,"tv":24062.54,"id":9028621}],"tv":26114.5}]}
{"op":"mcm","clk":"4226434155","pt":1631449092592,"mc":[{"id":"1.187552454","rc":[{"batb":[[1,3.85,3]],"batl":[[0,5,2],[1,5.4,3],[2,5.6,4]],"ltp":4.4,"tv":2051.96,"id":9345630},{"batb":[[0,1.3,522.98],[1,1.29,579.62],[2,1.25,54.17]],"batl":[[0,1.33,479.46],[1,1.34,507.95],[2,1.35,7]],"ltp":1.29,"tv":24062.54,"id":9028621}]}]}
{"op":"mcm","clk":"4226434288","pt":1631449093484,"mc":[{"id":"1.187552454","rc":[{"batb":[[2,1.26,26.49]],"ltp":1.29,"tv":24062.54,"id":9028621}]}]}
{"op":"mcm","clk":"4226434519","pt":1631449094911,"mc":[{"id":"1.187552454","rc":[{"batb":[[1,3.85,5.04]],"ltp":4.4,"tv":2051.96,"id":9345630},{"batl":[[2,1.35,41.3]],"ltp":1.29,"tv":24062.54,"id":9028621}]}]}
{"op":"mcm","clk":"4226434709","pt":1631449095991,"mc":[{"id":"1.187552454","rc":[{"batb":[[0,3.95,15],[1,3.9,3],[2,3.85,5.04]],"ltp":4.4,"tv":2051.96,"id":9345630},{"batb":[[0,1.3,567.93]],"ltp":1.29,"tv":24062.54,"id":9028621}]}]}
{"op":"mcm","clk":"4226435284","pt":1631449099326,"mc":[{"id":"1.187552454","rc":[{"batb":[[0,3.9,3],[1,3.6,2.04],[2,2.2,42.66]],"batl":[[0,5.4,3],[1,5.6,4],[2,5.6,0]],"ltp":4.4,"tv":2051.96,"id":9345630},{"batb":[[0,1.26,26.49],[1,1.25,27.55],[2,1.23,41.95]],"batl":[[0,1.34,8],[1,1.38,29.75],[2,1.94,8.68]],"ltp":1.29,"tv":24062.54,"id":9028621}]}]}
{"op":"mcm","clk":"4226435653","pt":1631449101519,"mc":[{"id":"1.187552454","rc":[{"batl":[[1,5.6,2]],"ltp":4.4,"tv":2051.96,"id":9345630},{"batb":[[0,1.23,12],[1,1.22,65.34],[2,1.1,296.65]],"ltp":1.29,"tv":24062.54,"id":9028621}]}]}
{"op":"mcm","clk":"4226435834","pt":1631449102538,"mc":[{"id":"1.187552454","rc":[{"batb":[[1,3.85,3],[2,3.6,2.04]],"batl":[[0,5,2],[1,5.4,3],[2,5.6,2]],"ltp":4.4,"tv":2051.96,"id":9345630},{"batb":[[0,1.26,505.62],[1,1.25,740.4],[2,1.23,12]],"batl":[[1,1.37,346.13],[2,1.38,431.15]],"ltp":1.29,"tv":24062.54,"id":9028621}]}]}
{"op":"mcm","clk":"4226436343","pt":1631449105543,"mc":[{"id":"1.187552454","rc":[{"batb":[[1,3.85,5]],"ltp":4.4,"tv":2051.96,"id":9345630},{"batb":[[2,1.23,41.95]],"batl":[[1,1.35,31.3],[2,1.37,346.13]],"ltp":1.29,"tv":24062.54,"id":9028621}]}]}
{"op":"mcm","clk":"4226436458","pt":1631449106246,"mc":[{"id":"1.187552454","rc":[{"batb":[[1,3.85,3]],"ltp":4.4,"tv":2051.96,"id":9345630},{"batl":[[0,1.27,593.14],[1,1.34,8]],"ltp":1.29,"tv":24062.54,"id":9028621}]}]}
{"op":"mcm","clk":"4226436639","pt":1631449107321,"mc":[{"id":"1.187552454","rc":[{"trd":[[1.26,100]],"batb":[[0,1.26,455.62]],"ltp":1.26,"tv":24162.54,"id":9028621}],"tv":26214.5}]}
{"op":"mcm","clk":"4226436815","pt":1631449108547,"mc":[{"id":"1.187552454","rc":[{"trd":[[1.27,1480.78]],"batl":[[0,1.27,610.59]],"ltp":1.27,"tv":24283.63,"id":9028621}],"tv":26335.6}]}
{"op":"mcm","clk":"4226436982","pt":1631449109520,"mc":[{"id":"1.187552454","rc":[{"batb":[[1,3.85,5]],"ltp":4.4,"tv":2051.96,"id":9345630},{"batl":[[2,1.35,39.1]],"ltp":1.27,"tv":24283.63,"id":9028621}]}]}
{"op":"mcm","clk":"4226437555","pt":1631449112939,"mc":[{"id":"1.187552454","rc":[{"batl":[[0,1.27,532.59]],"ltp":1.27,"tv":24283.63,"id":9028621}]}]}
{"op":"mcm","clk":"4226437821","pt":1631449114436,"mc":[{"id":"1.187552454","rc":[{"trd":[[1.27,2505.64]],"batl":[[0,1.27,20.16]],"ltp":1.27,"tv":25308.49,"id":9028621}],"tv":27360.45}]}
{"op":"mcm","clk":"4226437885","pt":1631449114820,"mc":[{"id":"1.187552454","rc":[{"batb":[[1,3.6,2.04],[2,2.6,3.71]],"ltp":4.4,"tv":2051.96,"id":9345630},{"batl":[[2,1.37,346.13]],"ltp":1.27,"tv":25308.49,"id":9028621}]}]}
{"op":"mcm","clk":"4226438094","pt":1631449116137,"mc":[{"id":"1.187552454","rc":[{"batb":[[2,2.2,42.66]],"ltp":4.4,"tv":2051.96,"id":9345630},{"trd":[[1.27,2545.96],[1.34,98.05]],"batb":[[0,1.34,7538.2],[1,1.33,71.9],[2,1.32,69.78]],"batl":[[0,1.37,346.13],[1,1.38,431.15],[2,1.94,8.68]],"ltp":1.34,"tv":25364.81,"id":9028621}],"tv":27416.77}]}
{"op":"mcm","clk":"4226438512","pt":1631449118838,"mc":[{"id":"1.187552454","rc":[{"batb":[[1,3.85,2],[2,3.6,2.04]],"ltp":4.4,"tv":2051.96,"id":9345630},{"batl":[[0,1.35,8],[1,1.37,346.13],[2,1.38,431.15]],"ltp":1.34,"tv":25364.81,"id":9028621}]}]}
{"op":"mcm","clk":"4226438928","pt":1631449121520,"mc":[{"id":"1.187552454","rc":[{"batb":[[1,3.85,4]],"ltp":4.4,"tv":2051.96,"id":9345630},{"batl":[[0,1.35,40.9],[1,1.36,9],[2,1.37,346.13]],"ltp":1.34,"tv":25364.81,"id":9028621}]}]}
{"op":"mcm","clk":"4226439010","pt":1631449122031,"mc":[{"id":"1.187552454","rc":[{"trd":[[3.9,10.16]],"batb":[[0,3.85,2],[1,3.6,2.04],[2,2.2,42.66]],"ltp":3.9,"tv":2057.5,"id":9345630},{"batl":[[0,1.35,8]],"ltp":1.34,"tv":25364.81,"id":9028621}],"tv":27422.31}]}
{"op":"mcm","clk":"4226439557","pt":1631449125278,"mc":[{"id":"1.187552454","rc":[{"batb":[[1,3.8,3],[2,3.6,2.04]],"ltp":3.9,"tv":2057.5,"id":9345630}]}]}
{"op":"mcm","clk":"4226440086","pt":1631449128480,"mc":[{"id":"1.187552454","rc":[{"batb":[[0,3.85,4]],"ltp":3.9,"tv":2057.5,"id":9345630},{"batl":[[0,1.35,42.1]],"ltp":1.34,"tv":25364.81,"id":9028621}]}]}
{"op":"mcm","clk":"4226440193","pt":1631449129217,"mc":[{"id":"1.187552454","rc":[{"batb":[[0,3.85,2]],"ltp":3.9,"tv":2057.5,"id":9345630},{"trd":[[1.34,169.55]],"batb":[[0,1.34,7502.45]],"batl":[[0,1.35,8]],"ltp":1.34,"tv":25436.31,"id":9028621}],"tv":27493.82}]}
{"op":"mcm","clk":"4226440746","pt":1631449132613,"mc":[{"id":"1.187552454","rc":[{"trd":[[1.34,211.19]],"batb":[[0,1.34,7481.63]],"ltp":1.34,"tv":25477.95,"id":9028621}],"tv":27535.46}]}
{"op":"mcm","clk":"4226441133","pt":1631449135321,"mc":[{"id":"1.187552454","rc":[{"batb":[[0,3.85,4]],"ltp":3.9,"tv":2057.5,"id":9345630},{"batl":[[0,1.35,44.9]],"ltp":1.34,"tv":25477.95,"id":9028621}]}]}
{"op":"mcm","clk":"4226441172","pt":1631449135600,"mc":[{"id":"1.187552454","rc":[{"batb":[[0,3.85,2]],"ltp":3.9,"tv":2057.5,"id":9345630},{"batl":[[0,1.35,8],[1,1.37,346.13],[2,1.38,431.15]],"ltp":1.34,"tv":25477.95,"id":9028621}]}]}
{"op":"mcm","clk":"4226441730","pt":1631449139101,"mc":[{"id":"1.187552454","rc":[{"batb":[[1,3.6,2.04],[2,2.2,42.66]],"ltp":3.9,"tv":2057.5,"id":9345630}]}]}
{"op":"mcm","clk":"4226441956","pt":1631449140531,"mc":[{"id":"1.187552454","rc":[{"trd":[[1.34,2260.9]],"batb":[[0,1.34,6456.78]],"ltp":1.34,"tv":27527.66,"id":9028621}],"tv":29585.16}]}
{"op":"mcm","clk":"4226442266","pt":1631449142300,"mc":[{"id":"1.187552454","rc":[{"batb":[[0,3.85,4],[1,3.8,2],[2,3.6,2.04]],"ltp":3.9,"tv":2057.5,"id":9345630},{"batb":[[1,1.26,455.62],[2,1.25,740.4]],"batl":[[0,1.35,41.5]],"ltp":1.34,"tv":27527.66,"id":9028621}]}]}
{"op":"mcm","clk":"4226442401","pt":1631449143102,"mc":[{"id":"1.187552454","rc":[{"batb":[[0,3.85,2]],"ltp":3.9,"tv":2057.5,"id":9345630},{"trd":[[1.34,2264.87]],"batb":[[0,1.34,6454.79]],"batl":[[0,1.35,8]],"ltp":1.34,"tv":27531.63,"id":9028621}],"tv":29589.14}]}
{"op":"mcm","clk":"4226442587","pt":1631449144218,"mc":[{"id":"1.187552454","rc":[{"trd":[[1.34,2298.77]],"batb":[[0,1.34,6437.84]],"ltp":1.34,"tv":27565.53,"id":9028621}],"tv":29623.03}]}
{"op":"mcm","clk":"4226442743","pt":1631449145295,"mc":[{"id":"1.187552454","rc":[{"trd":[[1.34,2328.69]],"batb":[[0,1.34,6422.88]],"ltp":1.34,"tv":27595.45,"id":9028621}],"tv":29652.95}]}
{"op":"mcm","clk":"4226443420","pt":1631449149602,"mc":[{"id":"1.187552454","rc":[{"batl":[[1,1.38,29.75],[2,1.94,8.96]],"ltp":1.34,"tv":27595.45,"id":9028621}]}]}
{"op":"mcm","clk":"4226443861","pt":1631449152536,"mc":[{"id":"1.187552454","rc":[{"batl":[[1,5.1,206.25],[2,5.2,363.96]],"ltp":3.9,"tv":2057.5,"id":9345630},{"trd":[[1.34,14492.31]],"batb":[[0,1.34,341.07]],"ltp":1.34,"tv":39759.07,"id":9028621}],"tv":41816.57}]}
{"op":"mcm","clk":"4226444018","pt":1631449153505,"mc":[{"id":"1.187552454","rc":[{"batb":[[0,4.4,2],[1,3.9,647.07],[2,3.85,2]],"ltp":3.9,"tv":2057.5,"id":9345630},{"batb":[[0,1.26,455.62],[1,1.25,45.01],[2,1.23,12]],"batl":[[0,1.3,8],[1,1.35,8],[2,1.38,29.75]],"ltp":1.34,"tv":39759.07,"id":9028621}]}]}
{"op":"mcm","clk":"4226444156","pt":1631449154521,"mc":[{"id":"1.187552454","rc":[{"batl":[[0,4.9,10],[1,5,2],[2,5.1,206.25]],"ltp":3.9,"tv":2057.5,"id":9345630},{"batl":[[1,1.34,355.13],[2,1.35,8]],"ltp":1.34,"tv":39759.07,"id":9028621}]}]}
{"op":"mcm","clk":"4226444301","pt":1631449155421,"mc":[{"id":"1.187552454","rc":[{"batl":[[0,4.7,81.38],[1,4.9,10],[2,5,2]],"ltp":3.9,"tv":2057.5,"id":9345630},{"batl":[[1,1.34,1363.51]],"ltp":1.34,"tv":39759.07,"id":9028621}]}]}
{"op":"mcm","clk":"4226444475","pt":1631449156537,"mc":[{"id":"1.187552454","rc":[{"batb":[[1,3.95,3],[2,3.9,3]],"batl":[[0,4.9,10],[1,5,2],[2,5.4,3]],"ltp":3.9,"tv":2057.5,"id":9345630},{"batb":[[0,1.26,496.47]],"batl":[[1,1.34,1370.51]],"ltp":1.34,"tv":39759.07,"id":9028621}]}]}
{"op":"mcm","clk":"4226444604","pt":1631449157329,"mc":[{"id":"1.187552454","rc":[{"batb":[[0,3.9,3],[1,3.85,2],[2,3.6,2.04]],"batl":[[0,5.4,3],[1,5.6,2],[2,5.4,0]],"ltp":3.9,"tv":2057.5,"id":9345630},{"trd":[[1.27,2565.92]],"batb":[[0,1.23,12],[1,1.22,65.34],[2,1.1,296.65]],"batl":[[0,1.34,151.66],[1,1.35,8],[2,1.38,29.75]],"ltp":1.27,"tv":39779.03,"id":9028621}],"tv":41836.53}]}
{"op":"mcm","clk":"4226444820","pt":1631449158504,"mc":[{"id":"1.187552454","rc":[{"batl":[[0,1.34,144.77]],"ltp":1.27,"tv":39779.03,"id":9028621}]}]}
{"op":"mcm","clk":"4226444937","pt":1631449159302,"mc":[{"id":"1.187552454","rc":[{"batb":[[0,4,2],[1,3.9,3],[2,3.85,2]],"ltp":3.9,"tv":2057.5,"id":9345630},{"batl":[[0,1.33,34.5],[1,1.34,209.77],[2,1.35,8]],"ltp":1.27,"tv":39779.03,"id":9028621}]}]}
{"op":"mcm","clk":"4226445083","pt":1631449160108,"mc":[{"id":"1.187552454","rc":[{"batl":[[2,5.8,2]],"ltp":3.9,"tv":2057.5,"id":9345630},{"batb":[[0,1.25,256.62],[1,1.24,712.22],[2,1.23,12]],"batl":[[0,1.33,358.98],[1,1.34,664.2]],"ltp":1.27,"tv":39779.03,"id":9028621}]}]}
{"op":"mcm","clk":"4226445299","pt":1631449161505,"mc":[{"id":"1.187552454","rc":[{"batb":[[1,1.24,719.66]],"batl":[[0,1.33,34.5],[1,1.34,144.77]],"ltp":1.27,"tv":39779.03,"id":9028621}]}]}
{"op":"mcm","clk":"4226445450","pt":1631449162515,"mc":[{"id":"1.187552454","rc":[{"batb":[[0,4.2,2],[1,4,2],[2,3.9,3]],"batl":[[0,5.2,4],[1,5.4,3],[2,5.6,2]],"ltp":3.9,"tv":2057.5,"id":9345630},{"batb":[[1,1.24,771.68]],"batl":[[0,1.27,1464.86],[1,1.31,37.5],[2,1.33,34.5]],"ltp":1.27,"tv":39779.03,"id":9028621}]}]}
{"op":"mcm","clk":"4226445613","pt":1631449163535,"mc":[{"id":"1.187552454","rc":[{"batb":[[0,4.5,154.12],[1,4.4,149.59],[2,4.3,149.59]],"batl":[[1,5.3,360.84],[2,5.4,353.24]],"ltp":3.9,"tv":2057.5,"id":9345630},{"batb":[[1,1.24,764.24]],"batl":[[0,1.27,4980.4],[1,1.33,34.5],[2,1.34,7]],"ltp":1.27,"tv":39779.03,"id":9028621}]}]}
{"op":"mcm","clk":"4226445744","pt":1631449164446,"mc":[{"id":"1.187552454","rc":[{"batb":[[2,4.3,151.59]],"ltp":3.9,"tv":2057.5,"id":9345630},{"batl":[[0,1.27,567.37],[1,1.28,574.29],[2,1.29,8]],"ltp":1.27,"tv":39779.03,"id":9028621}]}]}
{"op":"mcm","clk":"4226445913","pt":1631449165565,"mc":[{"id":"1.187552454","rc":[{"batb":[[0,4.5,158.4]],"ltp":3.9,"tv":2057.5,"id":9345630},{"batl":[[1,1.28,589.29]],"ltp":1.27,"tv":39779.03,"id":9028621}]}]}
{"op":"mcm","clk":"4226446037","pt":1631449166325,"mc":[{"id":"1.187552454","rc":[{"batl":[[0,5.2,14.6]],"ltp":3.9,"tv":2057.5,"id":9345630},{"batb":[[0,1.24,764.24],[1,1.23,12],[2,1.22,76.34]],"batl":[[0,1.27,615.03]],"ltp":1.27,"tv":39779.03,"id":9028621}]}]}
{"op":"mcm","clk":"4226446374","pt":1631449168449,"mc":[{"id":"1.187552454","rc":[{"trd":[[1.24,512.41]],"batb":[[0,1.24,727.06]],"ltp":1.24,"tv":39853.39,"id":9028621}],"tv":41910.89}]}
{"op":"mcm","clk":"4226446539","pt":1631449169464,"mc":[{"id":"1.187552454","rc":[{"batb":[[0,4.6,21.35],[1,4.5,158.4],[2,4.4,149.59]],"ltp":3.9,"tv":2057.5,"id":9345630},{"batb":[[0,1.24,1010.3],[1,1.23,756.28]],"batl":[[0,1.25,80],[1,1.27,615.03],[2,1.28,589.29]],"ltp":1.24,"tv":39853.39,"id":9028621}]}]}
{"op":"mcm","clk":"4226446641","pt":1631449170156,"mc":[{"id":"1.187552454","rc":[{"batb":[[0,4.7,2],[1,4.5,160.4]],"batl":[[2,5.4,355.24]],"ltp":3.9,"tv":2057.5,"id":9345630},{"batb":[[1,1.23,809.91]],"batl":[[1,1.26,6.89],[2,1.27,663.53]],"ltp":1.24,"tv":39853.39,"id":9028621}]}]}
{"op":"mcm","clk":"4226446853","pt":1631449171441,"mc":[{"id":"1.187552454","rc":[{"batl":[[0,1.25,580]],"ltp":1.24,"tv":39853.39,"id":9028621}]}]}
{"op":"mcm","clk":"4226447062","pt":1631449172558,"mc":[{"id":"1.187552454","rc":[{"batb":[[2,1.22,65.34]],"ltp":1.24,"tv":39853.39,"id":9028621}]}]}
{"op":"mcm","clk":"4226447211","pt":1631449173438,"mc":[{"id":"1.187552454","rc":[{"batl":[[0,1.25,500]],"ltp":1.24,"tv":39853.39,"id":9028621}]}]}
{"op":"mcm","clk":"4226447406","pt":1631449174556,"mc":[{"id":"1.187552454","rc":[{"batb":[[1,4.5,156.12]],"ltp":3.9,"tv":2057.5,"id":9345630}]}]}
{"op":"mcm","clk":"4226447528","pt":1631449175352,"mc":[{"id":"1.187552454","rc":[{"batl":[[0,1.26,6.89],[1,1.27,624.58],[2,1.28,633.38]],"ltp":1.24,"tv":39853.39,"id":9028621}]}]}
{"op":"mcm","clk":"4226447737","pt":1631449176576,"mc":[{"id":"1.187552454","rc":[{"batb":[[1,4.6,21.35],[2,4.5,156.12]],"ltp":3.9,"tv":2057.5,"id":9345630}]}]}
{"op":"mcm","clk":"4226447781","pt":1631449176755,"mc":[{"id":"1.187552454","rc":[{"batb":[[1,4.5,156.12],[2,4.4,149.59]],"ltp":3.9,"tv":2057.5,"id":9345630}]}]}
{"op":"mcm","clk":"4226448049","pt":1631449178461,"mc":[{"id":"1.187552454","rc":[{"batb":[[1,4.6,4.16],[2,4.5,156.12]],"ltp":3.9,"tv":2057.5,"id":9345630},{"trd":[[1.24,1512.41],[1.26,100.39]],"batb":[[0,1.24,510.3]],"batl":[[0,1.26,6.69]],"ltp":1.24,"tv":40853.78,"id":9028621}],"tv":42911.29}]}
{"op":"mcm","clk":"4226448160","pt":1631449179258,"mc":[{"id":"1.187552454","rc":[{"batl":[[0,1.25,137.77],[1,1.26,6.69],[2,1.27,624.58]],"ltp":1.24,"tv":40853.78,"id":9028621}]}]}
{"op":"mcm","clk":"4226448287","pt":1631449180144,"mc":[{"id":"1.187552454","rc":[{"batb":[[0,4.7,12]],"ltp":3.9,"tv":2057.5,"id":9345630}]}]}
{"op":"mcm","clk":"4226448502","pt":1631449181541,"mc":[{"id":"1.187552454","rc":[{"batb":[[0,4.7,2],[2,4.5,2]],"batl":[[0,5.4,2],[1,5.6,8.99],[2,5.8,2]],"ltp":3.9,"tv":2057.5,"id":9345630},{"trd":[[1.24,1688.41]],"batb":[[0,1.23,489.28],[1,1.22,65.34],[2,1.21,63.69]],"batl":[[2,1.27,48.5]],"ltp":1.24,"tv":41029.78,"id":9028621}],"tv":43087.29}]}
{"op":"mcm","clk":"4226448663","pt":1631449182465,"mc":[{"id":"1.187552454","rc":[{"batb":[[1,4.5,2],[2,4.1,2]],"batl":[[1,5.6,2]],"ltp":3.9,"tv":2057.5,"id":9345630}]}]}
{"op":"mcm","clk":"4226449005","pt":1631449184584,"mc":[{"id":"1.187552454","rc":[{"batb":[[1,4.1,2],[2,4,2]],"batl":[[0,5.2,2],[1,5.4,2],[2,5.6,2]],"ltp":3.9,"tv":2057.5,"id":9345630},{"batb":[[0,1.24,52.27],[1,1.23,489.28],[2,1.22,866.66]],"batl":[[0,1.26,6.69],[1,1.27,48.5],[2,1.29,596.84]],"ltp":1.24,"tv":41029.78,"id":9028621}]}]}
{"op":"mcm","clk":"4226449072","pt":1631449184955,"mc":[{"id":"1.187552454","rc":[{"batl":[[0,5.4,2],[1,5.6,2],[2,5.8,2]],"ltp":3.9,"tv":2057.5,"id":9345630},{"batb":[[0,1.23,489.28],[1,1.22,866.66],[2,1.21,63.69]],"ltp":1.24,"tv":41029.78,"id":9028621}]}]}
{"op":"mcm","clk":"4226449300","pt":1631449186371,"mc":[{"id":"1.187552454","rc":[{"batb":[[2,3,5.94]],"batl":[[2,5.8,0]],"ltp":3.9,"tv":2057.5,"id":9345630},{"batb":[[2,1.05,474.54]],"batl":[[2,1.32,7]],"ltp":1.24,"tv":41029.78,"id":9028621}]}]}
{"op":"mcm","clk":"4226449427","pt":1631449187276,"mc":[{"id":"1.187552454","rc":[{"batb":[[0,4.9,21.76],[1,4.7,5],[2,4.6,3]],"ltp":3.9,"tv":2057.5,"id":9345630},{"trd":[[1.26,103.17]],"batl":[[0,1.24,137.77],[1,1.26,16.3],[2,1.27,48.5]],"ltp":1.26,"tv":41032.57,"id":9028621}],"tv":43090.07}]}
{"op":"mcm","clk":"4226449569","pt":1631449188140,"mc":[{"id":"1.187552454","rc":[{"trd":[[1.24,1787.45]],"batl":[[0,1.24,88.25]],"ltp":1.24,"tv":41131.61,"id":9028621}],"tv":43189.11}]}
{"op":"mcm","clk":"4226449764","pt":1631449189368,"mc":[{"id":"1.187552454","rc":[{"batb":[[0,4.9,110.82]],"ltp":3.9,"tv":2057.5,"id":9345630},{"trd":[[1.24,1807.45]],"batb":[[2,1.18,13.52]],"batl":[[0,1.24,78.25],[1,1.25,447.06],[2,1.26,639.83]],"ltp":1.24,"tv":41151.61,"id":9028621}],"tv":43209.11}]}
{"op":"mcm","clk":"4226449928","pt":1631449190477,"mc":[{"id":"1.187552454","rc":[{"batb":[[1,4.8,3.94],[2,4.7,5]],"batl":[[2,6,6.7]],"ltp":3.9,"tv":2057.5,"id":9345630},{"batl":[[1,1.25,462.06],[2,1.26,673.28]],"ltp":1.24,"tv":41151.61,"id":9028621}]}]}
{"op":"mcm","clk":"4226450112","pt":1631449191597,"mc":[{"id":"1.187552454","rc":[{"batb":[[1,4.7,5],[2,4.6,3]],"batl":[[2,6,0]],"ltp":3.9,"tv":2057.5,"id":9345630},{"batb":[[0,1.23,434.9]],"batl":[[1,1.25,447.06]],"ltp":1.24,"tv":41151.61,"id":9028621}]}]}
{"op":"mcm","clk":"4226450462","pt":1631449193471,"mc":[{"id":"1.187552454","rc":[{"batb":[[0,4.9,125.97]],"ltp":3.9,"tv":2057.5,"id":9345630}]}]}
{"op":"mcm","clk":"4226450610","pt":1631449194285,"mc":[{"id":"1.187552454","rc":[{"batl":[[2,6,6.7]],"ltp":3.9,"tv":2057.5,"id":9345630},{"batl":[[2,1.26,688.28]],"ltp":1.24,"tv":41151.61,"id":9028621}]}]}
{"op":"mcm","clk":"4226450940","pt":1631449196186,"mc":[{"id":"1.187552454","rc":[{"batl":[[0,1.25,447.06],[1,1.26,682.98],[2,1.27,48.5]],"ltp":1.24,"tv":41151.61,"id":9028621}]}]}
{"op":"mcm","clk":"4226451149","pt":1631449197474,"mc":[{"id":"1.187552454","rc":[{"batb":[[0,4.9,129.81]],"ltp":3.9,"tv":2057.5,"id":9345630},{"trd":[[1.23,6.84]],"batb":[[0,1.23,431.48]],"ltp":1.23,"tv":41158.44,"id":9028621}],"tv":43215.94}]}
{"op":"mcm","clk":"4226451318","pt":1631449198492,"mc":[{"id":"1.187552454","rc":[{"trd":[[5,60]],"ltp":5.0,"tv":2117.5,"id":9345630},{"trd":[[1.25,240]],"batl":[[0,1.25,207.06]],"ltp":1.25,"tv":41398.44,"id":9028621}],"tv":43515.94}]}
{"op":"mcm","clk":"4226451476","pt":1631449199465,"mc":[{"id":"1.187552454","rc":[{"batb":[[2,4.5,2]],"ltp":5.0,"tv":2117.5,"id":9345630},{"batb":[[0,1.24,12.96],[1,1.23,431.48],[2,1.22,866.66]],"ltp":1.25,"tv":41398.44,"id":9028621}]}]}
{"op":"mcm","clk":"4226451706","pt":1631449200588,"mc":[{"id":"1.187552454","rc":[{"batb":[[0,1.24,59.93]],"ltp":1.25,"tv":41398.44,"id":9028621}]}]}
{"op":"mcm","clk":"4226452041","pt":1631449202580,"mc":[{"id":"1.187552454","rc":[{"batb":[[1,1.23,536.15]],"batl":[[0,1.25,364.68]],"ltp":1.25,"tv":41398.44,"id":9028621}]}]}
{"op":"mcm","clk":"4226452360","pt":1631449204586,"mc":[{"id":"1.187552454","rc":[{"batb":[[0,1.24,60.19]],"ltp":1.25,"tv":41398.44,"id":9028621}]}]}
{"op":"mcm","clk":"4226453613","pt":1631449212567,"mc":[{"id":"1.187552454","rc":[{"batl":[[0,5.4,2.69]],"ltp":5.0,"tv":2117.5,"id":9345630},{"batb":[[0,1.24,56.29]],"ltp":1.25,"tv":41398.44,"id":9028621}]}]}
{"op":"mcm","clk":"4226453656","pt":1631449212880,"mc":[{"id":"1.187552454","rc":[{"batl":[[0,5.4,2]],"ltp":5.0,"tv":2117.5,"id":9345630}]}]}
{"op":"mcm","clk":"4226453898","pt":1631449214494,"mc":[{"id":"1.187552454","rc":[{"batl":[[0,5.4,11.03]],"ltp":5.0,"tv":2117.5,"id":9345630}]}]}
{"op":"mcm","clk":"4226453989","pt":1631449215006,"mc":[{"id":"1.187552454","rc":[{"trd":[[4.9,61.44],[5,151.17]],"batb":[[0,4.9,99.09]],"batl":[[0,5.4,2]],"ltp":4.9,"tv":2270.11,"id":9345630},{"trd":[[1.25,604.68]],"batl":[[0,1.26,682.98],[1,1.27,48.5],[2,1.28,12.47]],"ltp":1.25,"tv":41763.12,"id":9028621}],"tv":44033.23}]}
{"op":"mcm","clk":"4226454376","pt":1631449217395,"mc":[{"id":"1.187552454","rc":[{"batb":[[0,1.24,56.54]],"ltp":1.25,"tv":41763.12,"id":9028621}]}]}
{"op":"mcm","clk":"4226454441","pt":1631449217899,"mc":[{"id":"1.187552454","rc":[{"batl":[[0,5.4,11.03]],"ltp":4.9,"tv":2270.11,"id":9345630},{"batb":[[1,1.23,692.18]],"batl":[[0,1.26,892.67],[1,1.27,640.8]],"ltp":1.25,"tv":41763.12,"id":9028621}]}]}
{"op":"mcm","clk":"4226454639","pt":1631449219125,"mc":[{"id":"1.187552454","rc":[{"batb":[[0,1.25,13.01],[1,1.24,56.29],[2,1.23,692.18]],"ltp":1.25,"tv":41763.12,"id":9028621}]}]}
{"op":"mcm","clk":"4226454743","pt":1631449219790,"mc":[{"id":"1.187552454","rc":[{"batb":[[0,1.25,16.91]],"ltp":1.25,"tv":41763.12,"id":9028621}]}]}
{"op":"mcm","clk":"4226454875","pt":1631449220724,"mc":[{"id":"1.187552454","rc":[{"batl":[[0,5,12],[1,5.4,11.03],[2,5.6,2]],"ltp":4.9,"tv":2270.11,"id":9345630}]}]}
{"op":"mcm","clk":"4226455074","pt":1631449221896,"mc":[{"id":"1.187552454","rc":[{"batb":[[1,4.8,2],[2,4.7,5]],"ltp":4.9,"tv":2270.11,"id":9345630}]}]}
{"op":"mcm","clk":"4226455398","pt":1631449223807,"mc":[{"id":"1.187552454","rc":[{"trd":[[1.26,103.55]],"batl":[[0,1.26,892.48]],"ltp":1.26,"tv":41763.5,"id":9028621}],"tv":44033.61}]}
{"op":"mcm","clk":"4226456206","pt":1631449229416,"mc":[{"id":"1.187552454","rc":[{"batb":[[1,1.24,56.03]],"ltp":1.26,"tv":41763.5,"id":9028621}]}]}
{"op":"mcm","clk":"4226456445","pt":1631449230818,"mc":[{"id":"1.187552454","rc":[{"trd":[[4.9,62.1]],"batb":[[0,4.9,98.76]],"ltp":4.9,"tv":2270.77,"id":9345630}],"tv":44034.28}]}
{"op":"mcm","clk":"4226456714","pt":1631449232421,"mc":[{"id":"1.187552454","rc":[{"trd":[[1.25,606.86]],"batb":[[0,1.25,15.83]],"ltp":1.25,"tv":41765.68,"id":9028621}],"tv":44036.45}]}
{"op":"mcm","clk":"4226457339","pt":1631449236219,"mc":[{"id":"1.187552454","rc":[{"batb":[[2,4.7,2]],"ltp":4.9,"tv":2270.77,"id":9345630},{"trd":[[1.26,103.91]],"batl":[[0,1.26,892.3]],"ltp":1.26,"tv":41766.03,"id":9028621}],"tv":44036.81}]}
{"op":"mcm","clk":"4226457432","pt":1631449236806,"mc":[{"id":"1.187552454","rc":[{"batb":[[0,1.25,62.8],[1,1.24,9.06]],"ltp":1.26,"tv":41766.03,"id":9028621}]}]}
{"op":"mcm","clk":"4226457896","pt":1631449239413,"mc":[{"id":"1.187552454","rc":[{"batb":[[2,4.7,5]],"ltp":4.9,"tv":2270.77,"id":9345630}]}]}
{"op":"mcm","clk":"4226458051","pt":1631449240314,"mc":[{"id":"1.187552454","rc":[{"trd":[[4.9,92.4]],"batb":[[0,4.9,83.61]],"ltp":4.9,"tv":2301.07,"id":9345630}],"tv":44067.11}]}
{"op":"mcm","clk":"4226458928","pt":1631449246076,"mc":[{"id":"1.187552454","rc":[{"trd":[[4.9,92.6]],"batb":[[0,4.9,83.51]],"ltp":4.9,"tv":2301.27,"id":9345630}],"tv":44067.31}]}
{"op":"mcm","clk":"4226459348","pt":1631449248749,"mc":[{"id":"1.187552454","rc":[{"batb":[[0,1.25,50.87]],"ltp":1.26,"tv":41766.03,"id":9028621}]}]}
{"op":"mcm","clk":"4226459839","pt":1631449251959,"mc":[{"id":"1.187552454","rc":[{"trd":[[4.9,140.34]],"batb":[[0,4.9,59.64],[2,4.7,2]],"ltp":4.9,"tv":2349.01,"id":9345630}],"tv":44115.05}]}
{"op":"mcm","clk":"4226459947","pt":1631449252758,"mc":[{"id":"1.187552454","rc":[{"batb":[[0,1.25,46.97]],"ltp":1.26,"tv":41766.03,"id":9028621}]}]}
{"op":"mcm","clk":"4226460329","pt":1631449255181,"mc":[{"id":"1.187552454","rc":[{"batb":[[2,4.7,5]],"ltp":4.9,"tv":2349.01,"id":9345630}]}]}
{"op":"mcm","clk":"4226460830","pt":1631449258048,"mc":[{"id":"1.187552454","rc":[{"batl":[[0,5.4,11.03],[1,5.6,2],[2,6,6.7]],"ltp":4.9,"tv":2349.01,"id":9345630},{"batb":[[0,1.25,52.82]],"ltp":1.26,"tv":41766.03,"id":9028621}]}]}
{"op":"mcm","clk":"4226461241","pt":1631449260458,"mc":[{"id":"1.187552454","rc":[{"trd":[[4.9,146.14]],"batb":[[0,4.9,56.74]],"ltp":4.9,"tv":2354.81,"id":9345630}],"tv":44120.85}]}
{"op":"mcm","clk":"4226461330","pt":1631449260980,"mc":[{"id":"1.187552454","rc":[{"trd":[[4.9,170.14]],"batb":[[0,4.9,44.74]],"ltp":4.9,"tv":2378.81,"id":9345630}],"tv":44144.85}]}
{"op":"mcm","clk":"4226461507","pt":1631449261944,"mc":[{"id":"1.187552454","rc":[{"trd":[[1.26,119.91]],"batl":[[0,1.26,884.3]],"ltp":1.26,"tv":41782.03,"id":9028621}],"tv":44160.85}]}
{"op":"mcm","clk":"4226462895","pt":1631449270080,"mc":[{"id":"1.187552454","rc":[{"batb":[[2,4.7,2]],"ltp":4.9,"tv":2378.81,"id":9345630},{"trd":[[1.26,122.53]],"batl":[[0,1.26,882.99]],"ltp":1.26,"tv":41784.65,"id":9028621}],"tv":44163.47}]}
{"op":"mcm","clk":"4226463421","pt":1631449273250,"mc":[{"id":"1.187552454","rc":[{"batb":[[2,4.7,5]],"ltp":4.9,"tv":2378.81,"id":9345630}]}]}
{"op":"mcm","clk":"4226463476","pt":1631449273684,"mc":[{"id":"1.187552454","rc":[{"trd":[[1.26,146.39]],"batl":[[0,1.26,871.06]],"ltp":1.26,"tv":41808.51,"id":9028621}],"tv":44187.32}]}
{"op":"mcm","clk":"4226464682","pt":1631449281227,"mc":[{"id":"1.187552454","rc":[{"trd":[[1.26,150.28]],"batl":[[0,1.26,869.11]],"ltp":1.26,"tv":41812.41,"id":9028621}],"tv":44191.22}]}
{"op":"mcm","clk":"4226466423","pt":1631449291845,"mc":[{"id":"1.187552454","rc":[{"batb":[[2,4.7,2]],"ltp":4.9,"tv":2378.81,"id":9345630},{"trd":[[1.26,152.04]],"batl":[[0,1.26,868.23]],"ltp":1.26,"tv":41814.17,"id":9028621}],"tv":44192.98}]}
{"op":"mcm","clk":"4226466652","pt":1631449293438,"mc":[{"id":"1.187552454","rc":[{"batb":[[0,1.25,46.97]],"ltp":1.26,"tv":41814.17,"id":9028621}]}]}
{"op":"mcm","clk":"4226466890","pt":1631449295046,"mc":[{"id":"1.187552454","rc":[{"batb":[[2,4.7,5]],"ltp":4.9,"tv":2378.81,"id":9345630}]}]}
{"op":"mcm","clk":"4226467143","pt":1631449296428,"mc":[{"id":"1.187552454","rc":[{"trd":[[4.9,170.49]],"batb":[[0,4.9,44.57]],"ltp":4.9,"tv":2379.16,"id":9345630}],"tv":44193.33}]}
{"op":"mcm","clk":"4226467924","pt":1631449301546,"mc":[{"id":"1.187552454","rc":[{"trd":[[1.26,296.64]],"batl":[[0,1.26,795.93]],"ltp":1.26,"tv":41958.77,"id":9028621}],"tv":44337.93}]}
{"op":"mcm","clk":"4226468034","pt":1631449302329,"mc":[{"id":"1.187552454","rc":[{"trd":[[1.26,313.73]],"batl":[[0,1.26,787.39]],"ltp":1.26,"tv":41975.85,"id":9028621}],"tv":44355.01}]}
{"op":"mcm","clk":"4226468104","pt":1631449302754,"mc":[{"id":"1.187552454","rc":[{"trd":[[1.26,315.39]],"batl":[[0,1.26,786.56]],"ltp":1.26,"tv":41977.51,"id":9028621}],"tv":44356.67}]}
{"op":"mcm","clk":"4226468442","pt":1631449304937,"mc":[{"id":"1.187552454","rc":[{"batb":[[2,1.23,733.92]],"batl":[[0,1.26,842.6]],"ltp":1.26,"tv":41977.51,"id":9028621}]}]}
{"op":"mcm","clk":"4226469243","pt":1631449309986,"mc":[{"id":"1.187552454","rc":[{"batb":[[2,4.7,2]],"ltp":4.9,"tv":2379.16,"id":9345630},{"trd":[[1.26,319.29]],"batl":[[0,1.26,840.65]],"ltp":1.26,"tv":41981.41,"id":9028621}],"tv":44360.57}]}
{"op":"mcm","clk":"4226469745","pt":1631449313172,"mc":[{"id":"1.187552454","rc":[{"batb":[[2,4.7,4]],"ltp":4.9,"tv":2379.16,"id":9345630}]}]}
{"op":"mcm","clk":"4226470067","pt":1631449314904,"mc":[{"id":"1.187552454","rc":[{"batb":[[1,1.24,14.91]],"ltp":1.26,"tv":41981.41,"id":9028621}]}]}
{"op":"mcm","clk":"4226470253","pt":1631449316011,"mc":[{"id":"1.187552454","rc":[{"trd":[[1.24,1837.27],[1.25,700.8]],"batb":[[0,1.23,733.92],[1,1.22,866.66],[2,1.18,13.52]],"batl":[[0,1.24,10.42],[1,1.26,840.65],[2,1.27,640.8]],"ltp":1.24,"tv":42105.17,"id":9028621}],"tv":44484.33}]}
{"op":"mcm","clk":"4226470752","pt":1631449319823,"mc":[{"id":"1.187552454","rc":[{"batl":[[0,1.26,840.65],[1,1.27,640.8],[2,1.28,12.47]],"ltp":1.24,"tv":42105.17,"id":9028621}]}]}
{"op":"mcm","clk":"4226471780","pt":1631449326528,"mc":[{"id":"1.187552454","rc":[{"trd":[[4.9,238.81]],"batb":[[0,4.9,10.41]],"ltp":4.9,"tv":2447.48,"id":9345630}],"tv":44552.65}]}
{"op":"mcm","clk":"4226471794","pt":1631449326635,"mc":[{"id":"1.187552454","rc":[{"batb":[[2,4.7,2]],"ltp":4.9,"tv":2447.48,"id":9345630}]}]}
{"op":"mcm","clk":"4226472303","pt":1631449330147,"mc":[{"id":"1.187552454","rc":[{"batb":[[1,4.7,4],[2,4.5,2]],"ltp":4.9,"tv":2447.48,"id":9345630}]}]}
{"op":"mcm","clk":"4226472467","pt":1631449331321,"mc":[{"id":"1.187552454","rc":[{"trd":[[1.23,10.25]],"batb":[[0,1.23,771.93]],"ltp":1.23,"tv":42108.59,"id":9028621}],"tv":44556.07}]}
{"op":"mcm","clk":"4226472721","pt":1631449332949,"mc":[{"id":"1.187552454","rc":[{"batl":[[1,1.27,646.65]],"ltp":1.23,"tv":42108.59,"id":9028621}]}]}
{"op":"mcm","clk":"4226473207","pt":1631449336250,"mc":[{"id":"1.187552454","rc":[{"batb":[[2,1.01,30]],"batl":[[2,1.29,8]],"ltp":1.23,"tv":42108.59,"id":9028621}]}]}
{"op":"mcm","clk":"4226473391","pt":1631449337747,"mc":[{"id":"1.187552454","rc":[{"batl":[[0,1.25,2.56],[1,1.26,840.65],[2,1.27,646.65]],"ltp":1.23,"tv":42108.59,"id":9028621}]}]}
{"op":"mcm","clk":"4226474862","pt":1631449347457,"mc":[{"id":"1.187552454","rc":[{"trd":[[1.25,705.93]],"batb":[[0,1.25,1.34],[1,1.23,771.93],[2,1.22,866.66]],"batl":[[0,1.26,840.65],[1,1.27,646.65],[2,1.29,8]],"ltp":1.25,"tv":42113.71,"id":9028621}],"tv":44561.2}]}
{"op":"mcm","clk":"4226475568","pt":1631449351565,"mc":[{"id":"1.187552454","rc":[{"trd":[[1.24,1974.25],[1.25,708.6]],"batb":[[0,1.23,771.93],[1,1.22,866.66],[2,1.01,30]],"batl":[[0,1.24,9.51],[1,1.26,840.65],[2,1.27,646.65]],"ltp":1.24,"tv":42253.38,"id":9028621}],"tv":44700.86}]}
{"op":"mcm","clk":"4226477414","pt":1631449363404,"mc":[{"id":"1.187552454","rc":[{"trd":[[1.24,1984.85]],"batl":[[0,1.24,4.21]],"ltp":1.24,"tv":42263.98,"id":9028621}],"tv":44711.46}]}
{"op":"mcm","clk":"4226479107","pt":1631449374355,"mc":[{"id":"1.187552454","rc":[{"trd":[[4.9,259.63],[5.1,1.02]],"batb":[[0,4.7,4],[1,4.5,2],[2,1.01,30]],"batl":[[0,4.9,8.57],[1,5.4,11.03],[2,5.6,2]],"ltp":4.9,"tv":2469.32,"id":9345630},{"trd":[[1.24,1989.06]],"batl":[[0,1.26,840.65],[1,1.27,646.65],[2,1.29,8]],"ltp":1.24,"tv":42268.19,"id":9028621}],"tv":44737.51}]}
{"op":"mcm","clk":"4226479315","pt":1631449375646,"mc":[{"id":"1.187552454","rc":[{"trd":[[4.9,261.2]],"batl":[[0,4.9,7]],"ltp":4.9,"tv":2470.89,"id":9345630},{"trd":[[1.25,714.76]],"ltp":1.25,"tv":42274.35,"id":9028621}],"tv":44745.24}]}
{"op":"mcm","clk":"4226479642","pt":1631449377556,"mc":[{"id":"1.187552454","rc":[{"trd":[[4.9,275.2]],"batb":[[0,4.9,8.38],[1,4.7,4],[2,4.5,2]],"batl":[[0,5.4,11.03],[1,5.6,2],[2,990,0.01]],"ltp":4.9,"tv":2484.89,"id":9345630},{"batb":[[0,1.24,3.18],[1,1.23,771.93],[2,1.22,866.66]],"ltp":1.25,"tv":42274.35,"id":9028621}],"tv":44759.24}]}
{"op":"mcm","clk":"4226479808","pt":1631449378555,"mc":[{"id":"1.187552454","rc":[{"batb":[[1,4.8,17.51],[2,4.7,4]],"ltp":4.9,"tv":2484.89,"id":9345630}]}]}
{"op":"mcm","clk":"4226479858","pt":1631449378871,"mc":[{"id":"1.187552454","rc":[{"batb":[[1,4.7,4],[2,4.5,2]],"ltp":4.9,"tv":2484.89,"id":9345630}]}]}
{"op":"mcm","clk":"4226480174","pt":1631449380735,"mc":[{"id":"1.187552454","rc":[{"batb":[[1,4.8,7],[2,4.7,4]],"batl":[[2,5.8,6.84]],"ltp":4.9,"tv":2484.89,"id":9345630}]}]}
{"op":"mcm","clk":"4226480375","pt":1631449381929,"mc":[{"id":"1.187552454","rc":[{"batb":[[0,4.9,25.89]],"ltp":4.9,"tv":2484.89,"id":9345630}]}]}
{"op":"mcm","clk":"4226480718","pt":1631449383959,"mc":[{"id":"1.187552454","rc":[{"batb":[[0,1.23,771.93],[1,1.22,866.66],[2,1.21,32.73]],"ltp":1.25,"tv":42274.35,"id":9028621}]}]}
{"op":"mcm","clk":"4226481143","pt":1631449386763,"mc":[{"id":"1.187552454","rc":[{"trd":[[1.26,319.69]],"batl":[[0,1.26,840.45]],"ltp":1.26,"tv":42274.74,"id":9028621}],"tv":44759.64}]}
{"op":"mcm","clk":"4226481878","pt":1631449391771,"mc":[{"id":"1.187552454","rc":[{"trd":[[1.26,324.99]],"batl":[[0,1.26,837.8]],"ltp":1.26,"tv":42280.05,"id":9028621}],"tv":44764.94}]}
{"op":"mcm","clk":"4226482051","pt":1631449392754,"mc":[{"id":"1.187552454","rc":[{"trd":[[1.23,11.5]],"batb":[[0,1.23,771.31]],"ltp":1.23,"tv":42281.29,"id":9028621}],"tv":44766.18}]}
{"op":"mcm","clk":"4226484763","pt":1631449410412,"mc":[{"id":"1.187552454","rc":[{"trd":[[1.23,11.92]],"batb":[[0,1.23,771.1]],"ltp":1.23,"tv":42281.71,"id":9028621}],"tv":44766.6}]}
{"op":"mcm","clk":"4226486772","pt":1631449422883,"mc":[{"id":"1.187552454","rc":[{"batb":[[0,1.24,23],[1,1.23,771.1],[2,1.22,866.66]],"ltp":1.23,"tv":42281.71,"id":9028621}]}]}
{"op":"mcm","clk":"4226489848","pt":1631449443754,"mc":[{"id":"1.187552454","rc":[{"trd":[[4.9,277]],"batb":[[0,4.9,24.99]],"ltp":4.9,"tv":2486.69,"id":9345630}],"tv":44768.4}]}
{"op":"mcm","clk":"4226490505","pt":1631449448253,"mc":[{"id":"1.187552454","rc":[{"trd":[[1.24,1996.58]],"batb":[[0,1.24,19.24]],"ltp":1.24,"tv":42289.23,"id":9028621}],"tv":44775.92}]}
{"op":"mcm","clk":"4226491026","pt":1631449451966,"mc":[{"id":"1.187552454","rc":[{"trd":[[1.26,325.38]],"batl":[[0,1.26,837.6]],"ltp":1.26,"tv":42289.63,"id":9028621}],"tv":44776.32}]}
{"op":"mcm","clk":"4226491160","pt":1631449452855,"mc":[{"id":"1.187552454","rc":[{"trd":[[1.26,333.89]],"batl":[[0,1.26,833.35]],"ltp":1.26,"tv":42298.13,"id":9028621}],"tv":44784.82}]}
{"op":"mcm","clk":"4226494834","pt":1631449477727,"mc":[{"id":"1.187552454","rc":[{"trd":[[1.26,335.84]],"batl":[[0,1.26,832.37]],"ltp":1.26,"tv":42300.09,"id":9028621}],"tv":44786.78}]}
{"op":"mcm","clk":"4226498710","pt":1631449503766,"mc":[{"id":"1.187552454","rc":[{"batl":[[0,5,82.26],[1,5.4,11.03],[2,5.6,2]],"ltp":4.9,"tv":2486.69,"id":9345630}]}]}
{"op":"mcm","clk":"4226500271","pt":1631449514476,"mc":[{"id":"1.187552454","rc":[{"trd":[[5,163.09]],"batl":[[0,5,70.34]],"ltp":5.0,"tv":2498.61,"id":9345630},{"trd":[[1.25,762.44]],"ltp":1.25,"tv":42347.76,"id":9028621}],"tv":44846.37}]}
{"op":"mcm","clk":"4226502020","pt":1631449525988,"mc":[{"id":"1.187552454","rc":[{"trd":[[5,168.29]],"batl":[[0,5,65.14]],"ltp":5.0,"tv":2503.81,"id":9345630},{"trd":[[1.25,783.26]],"ltp":1.25,"tv":42368.58,"id":9028621}],"tv":44872.4}]}
{"op":"mcm","clk":"4226502252","pt":1631449527498,"mc":[{"id":"1.187552454","rc":[{"batb":[[0,4.9,7.48],[2,1.01,30]],"batl":[[1,990,0.01],[2,5.6,0]],"ltp":5.0,"tv":2503.81,"id":9345630},{"batb":[[1,1.21,32.73],[2,1.01,30]],"batl":[[0,1.26,15],[1,1.27,5.85],[2,1.32,7]],"ltp":1.25,"tv":42368.58,"id":9028621}]}]}
{"op":"mcm","clk":"4226502404","pt":1631449528464,"mc":[{"id":"1.187552454","rc":[{"batb":[[0,1.01,30],[1,4.8,0],[2,1.01,0]],"ltp":5.0,"tv":2503.81,"id":9345630},{"batb":[[1,1.01,30],[2,1.01,0]],"batl":[[0,1.27,5.85],[1,1.32,7],[2,1.34,13.01]],"ltp":1.25,"tv":42368.58,"id":9028621}]}]}
{"op":"mcm","clk":"4226502699","pt":1631449530388,"mc":[{"id":"1.187552454","rc":[{"trd":[[5,184.98]],"batl":[[0,5,56.79]],"ltp":5.0,"tv":2520.49,"id":9345630},{"batb":[[1,1.19,1190.88],[2,1.18,579.63]],"batl":[[1,1.29,551.5],[2,1.3,526.34]],"ltp":1.25,"tv":42368.58,"id":9028621}],"tv":44889.08}]}
{"op":"mcm","clk":"4226502740","pt":1631449530740,"mc":[{"id":"1.187552454","rc":[{"batb":[[1,1.01,30],[2,1.18,0]],"batl":[[1,1.32,7],[2,1.34,13.01]],"ltp":1.25,"tv":42368.58,"id":9028621}]}]}
{"op":"mcm","clk":"4226502889","pt":1631449531682,"mc":[{"id":"1.187552454","rc":[{"batb":[[0,4.4,2],[1,4.3,2],[2,1.01,30]],"ltp":5.0,"tv":2520.49,"id":9345630}]}]}
{"op":"mcm","clk":"4226503165","pt":1631449533579,"mc":[{"id":"1.187552454","rc":[{"trd":[[5,186.72]],"batl":[[0,5,55.92]],"ltp":5.0,"tv":2522.24,"id":9345630}],"tv":44890.83}]}
{"op":"mcm","clk":"4226503295","pt":1631449534491,"mc":[{"id":"1.187552454","rc":[{"trd":[[5,242.65]],"batl":[[0,990,0.01],[1,990,0]],"ltp":5.0,"tv":2578.16,"id":9345630},{"trd":[[1.25,1006.95]],"batb":[[1,1.22,920.99],[2,1.21,710.51]],"batl":[[0,1.25,457.72],[1,1.26,622.37],[2,1.27,5.85]],"ltp":1.25,"tv":42592.27,"id":9028621}],"tv":45170.44}]}
{"op":"mcm","clk":"4226503420","pt":1631449535290,"mc":[{"id":"1.187552454","rc":[{"batb":[[0,4.5,10],[1,4.4,2],[2,4.3,2]],"ltp":5.0,"tv":2578.16,"id":9345630}]}]}
{"op":"mcm","clk":"4226503575","pt":1631449536401,"mc":[{"id":"1.187552454","rc":[{"trd":[[1.25,1108.17]],"batl":[[0,1.25,407.11]],"ltp":1.25,"tv":42693.49,"id":9028621}],"tv":45271.66}]}
{"op":"mcm","clk":"4226503719","pt":1631449537389,"mc":[{"id":"1.187552454","rc":[{"batb":[[1,1.22,1017.54]],"batl":[[0,1.25,536.69]],"ltp":1.25,"tv":42693.49,"id":9028621}]}]}
{"op":"mcm","clk":"4226503855","pt":1631449538485,"mc":[{"id":"1.187552454","rc":[{"batl":[[0,1.25,587.57]],"ltp":1.25,"tv":42693.49,"id":9028621}]}]}
{"op":"mcm","clk":"4226503896","pt":1631449538706,"mc":[{"id":"1.187552454","rc":[{"batb":[[0,4.4,2],[1,4.3,2],[2,1.01,30]],"ltp":5.0,"tv":2578.16,"id":9345630},{"batb":[[1,1.01,30],[2,1.21,0]],"batl":[[0,1.27,5.85],[1,1.32,7],[2,1.34,13.01]],"ltp":1.25,"tv":42693.49,"id":9028621}]}]}
{"op":"mcm","clk":"4226504166","pt":1631449540806,"mc":[{"id":"1.187552454","rc":[{"batb":[[1,1.2,2],[2,1.01,30]],"ltp":1.25,"tv":42693.49,"id":9028621}]}]}
{"op":"mcm","clk":"4226504294","pt":1631449541612,"mc":[{"id":"1.187552454","rc":[{"batb":[[1,1.2,372.53],[2,1.19,938.64]],"batl":[[1,1.29,439.51],[2,1.3,526.26]],"ltp":1.25,"tv":42693.49,"id":9028621}]}]}
{"op":"mcm","clk":"4226504525","pt":1631449543219,"mc":[{"id":"1.187552454","rc":[{"batb":[[1,1.01,30],[2,1.01,0]],"ltp":5.0,"tv":2578.16,"id":9345630},{"trd":[[1.24,2035.06]],"batb":[[0,1.2,372.53],[1,1.19,938.64],[2,1.01,30]],"batl":[[0,1.24,81.76],[1,1.27,5.85],[2,1.29,439.51]],"ltp":1.24,"tv":42731.97,"id":9028621}],"tv":45310.14}]}
{"op":"mcm","clk":"4226504680","pt":1631449544201,"mc":[{"id":"1.187552454","rc":[{"trd":[[1.24,2107.36]],"batl":[[0,1.24,45.61]],"ltp":1.24,"tv":42804.27,"id":9028621}],"tv":45382.44}]}
{"op":"mcm","clk":"4226504831","pt":1631449545316,"mc":[{"id":"1.187552454","rc":[{"batb":[[0,1.2,370.53]],"ltp":1.24,"tv":42804.27,"id":9028621}]}]}
{"op":"mcm","clk":"4226506006","pt":1631449552814,"mc":[{"id":"1.187552454","rc":[{"trd":[[1.24,2198.58],[1.27,2577.62]],"batb":[[0,1.27,20.84],[1,1.2,370.53],[2,1.19,938.64]],"batl":[[0,1.29,439.51],[1,1.3,526.26],[2,1.32,7]],"ltp":1.27,"tv":42907.19,"id":9028621}],"tv":45485.36}]}
{"op":"mcm","clk":"4226506380","pt":1631449555417,"mc":[{"id":"1.187552454","rc":[{"trd":[[4.4,22.26]],"batb":[[0,1.01,30],[1,1.01,0]],"ltp":4.4,"tv":2595.5,"id":9345630},{"trd":[[1.29,1840.1]],"batl":[[0,1.29,394.01]],"ltp":1.29,"tv":42952.69,"id":9028621}],"tv":45548.2}]}
{"op":"mcm","clk":"4226506521","pt":1631449556315,"mc":[{"id":"1.187552454","rc":[{"batb":[[0,4.3,3],[1,1.01,30]],"ltp":4.4,"tv":2595.5,"id":9345630},{"batb":[[0,1.2,370.53],[1,1.19,938.64],[2,1.01,30]],"batl":[[0,1.29,404.01]],"ltp":1.29,"tv":42952.69,"id":9028621}]}]}
{"op":"mcm","clk":"4226506848","pt":1631449558583,"mc":[{"id":"1.187552454","rc":[{"batb":[[1,4.2,3],[2,1.01,30]],"ltp":4.4,"tv":2595.5,"id":9345630},{"batl":[[0,1.29,10],[1,1.32,7],[2,1.34,13.01]],"ltp":1.29,"tv":42952.69,"id":9028621}]}]}
{"op":"mcm","clk":"4226506960","pt":1631449559436,"mc":[{"id":"1.187552454","rc":[{"batb":[[0,5.5,347.73],[1,5.4,337.5],[2,5.3,337.5]],"ltp":4.4,"tv":2595.5,"id":9345630}]}]}
{"op":"mcm","clk":"4226507035","pt":1631449559821,"mc":[{"id":"1.187552454","rc":[{"batb":[[0,5.5,17.39],[1,5.4,16.88],[2,5.3,16.88]],"ltp":4.4,"tv":2595.5,"id":9345630}]}]}
{"op":"mcm","clk":"4226507249","pt":1631449561203,"mc":[{"id":"1.187552454","rc":[{"batb":[[0,5.5,124.14],[1,5.4,120.49],[2,5.3,120.49]],"batl":[[0,6.8,154.69],[1,7,150.14],[2,7.2,150.14]],"ltp":4.4,"tv":2595.5,"id":9345630},{"batb":[[2,1.15,13.87]],"batl":[[0,1.22,650.17],[1,1.23,716.64],[2,1.24,12.86]],"ltp":1.29,"tv":42952.69,"id":9028621}]}]}
{"op":"mcm","clk":"4226507438","pt":1631449562413,"mc":[{"id":"1.187552454","rc":[{"batb":[[2,5.3,134.44]],"batl":[[0,6.8,160.91]],"ltp":4.4,"tv":2595.5,"id":9345630},{"batb":[[2,1.18,35.35]],"batl":[[2,1.24,27.86]],"ltp":1.29,"tv":42952.69,"id":9028621}]}]}
{"op":"mcm","clk":"4226507668","pt":1631449564042,"mc":[{"id":"1.187552454","rc":[{"batl":[[0,6.6,21.19],[1,6.8,160.91],[2,7,150.14]],"ltp":4.4,"tv":2595.5,"id":9345630}]}]}
{"op":"mcm","clk":"4226507881","pt":1631449565417,"mc":[{"id":"1.187552454","rc":[{"batb":[[0,5.6,10],[1,5.5,124.14],[2,5.4,120.49]],"ltp":4.4,"tv":2595.5,"id":9345630},{"batl":[[0,1.22,703.65]],"ltp":1.29,"tv":42952.69,"id":9028621}]}]}
{"op":"mcm","clk":"4226507979","pt":1631449566097,"mc":[{"id":"1.187552454","rc":[{"batl":[[1,6.8,154.69]],"ltp":4.4,"tv":2595.5,"id":9345630},{"trd":[[1.2,160.28]],"batb":[[0,1.2,292.39],[2,1.15,13.87]],"batl":[[2,1.24,12.86]],"ltp":1.2,"tv":43108.97,"id":9028621}],"tv":45704.48}]}
{"op":"mcm","clk":"4226508188","pt":1631449567433,"mc":[{"id":"1.187552454","rc":[{"batb":[[2,1.16,83.03]],"batl":[[2,1.24,60.84]],"ltp":1.2,"tv":43108.97,"id":9028621}]}]}
{"op":"mcm","clk":"4226508502","pt":1631449569344,"mc":[{"id":"1.187552454","rc":[{"batb":[[0,1.2,362.73]],"batl":[[1,1.23,731.64]],"ltp":1.2,"tv":43108.97,"id":9028621}]}]}
{"op":"mcm","clk":"4226508837","pt":1631449571546,"mc":[{"id":"1.187552454","rc":[{"batb":[[1,5.5,137.47]],"ltp":4.4,"tv":2595.5,"id":9345630}]}]}
{"op":"mcm","clk":"4226508985","pt":1631449572541,"mc":[{"id":"1.187552454","rc":[{"batl":[[0,6.6,27.52]],"ltp":4.4,"tv":2595.5,"id":9345630}]}]}
{"op":"mcm","clk":"4226509033","pt":1631449572829,"mc":[{"id":"1.187552454","rc":[{"batl":[[0,6.6,6.33]],"ltp":4.4,"tv":2595.5,"id":9345630}]}]}
{"op":"mcm","clk":"4226509407","pt":1631449575328,"mc":[{"id":"1.187552454","rc":[{"trd":[[1.2,470.22]],"batb":[[0,1.2,207.76]],"ltp":1.2,"tv":43418.91,"id":9028621}],"tv":46014.42}]}
{"op":"mcm","clk":"4226509502","pt":1631449575970,"mc":[{"id":"1.187552454","rc":[{"batl":[[0,6.4,21.19],[1,6.6,6.33],[2,6.8,154.69]],"ltp":4.4,"tv":2595.5,"id":9345630}]}]}
{"op":"mcm","clk":"4226510042","pt":1631449579457,"mc":[{"id":"1.187552454","rc":[{"trd":[[1.21,1450.92]],"batb":[[0,1.2,297.52]],"batl":[[0,1.21,63.41],[1,1.22,795.82],[2,1.23,731.64]],"ltp":1.21,"tv":43538.09,"id":9028621}],"tv":46133.6}]}
{"op":"mcm","clk":"4226510067","pt":1631449579616,"mc":[{"id":"1.187552454","rc":[{"trd":[[1.2,470.62],[1.21,1492.56]],"batb":[[0,1.2,297.32]],"batl":[[0,1.21,42.59]],"ltp":1.2,"tv":43580.13,"id":9028621}],"tv":46175.63}]}
{"op":"mcm","clk":"4226510474","pt":1631449582739,"mc":[{"id":"1.187552454","rc":[{"trd":[[1.21,1493]],"batl":[[0,1.21,42.37],[2,1.23,790.14]],"ltp":1.21,"tv":43580.57,"id":9028621}],"tv":46176.08}]}
{"op":"mcm","clk":"4226510880","pt":1631449585541,"mc":[{"id":"1.187552454","rc":[{"batb":[[0,5.5,13.33],[1,5.1,2],[2,5,2]],"batl":[[0,6.6,6.33],[1,7.4,2],[2,8.8,2]],"ltp":4.4,"tv":2595.5,"id":9345630},{"batb":[[0,1.16,83.03],[1,1.13,635.71],[2,1.01,30]],"batl":[[0,1.23,15],[1,1.24,47.98],[2,1.25,56.18]],"ltp":1.21,"tv":43580.57,"id":9028621}]}]}
{"op":"mcm","clk":"4226511020","pt":1631449586496,"mc":[{"id":"1.187552454","rc":[{"batb":[[0,5,2],[1,4.8,2],[2,4.4,2.78]],"batl":[[0,8.8,2],[1,990,0.01],[2,8.8,0]],"ltp":4.4,"tv":2595.5,"id":9345630},{"batb":[[0,1.13,635.71],[1,1.01,30],[2,1.01,0]],"batl":[[0,1.25,56.18],[1,1.26,49.75],[2,1.28,10]],"ltp":1.21,"tv":43580.57,"id":9028621}]}]}
{"op":"mcm","clk":"4226511237","pt":1631449588262,"mc":[{"id":"1.187552454","rc":[{"batb":[[0,1.16,748.34],[1,1.15,1072.2],[2,1.13,635.71]],"batl":[[0,1.25,439.34],[1,1.26,678.25]],"ltp":1.21,"tv":43580.57,"id":9028621}]}]}
{"op":"mcm","clk":"4226511409","pt":1631449589372,"mc":[{"id":"1.187552454","rc":[{"batl":[[0,7.4,2],[1,8.8,2],[2,990,0.01]],"ltp":4.4,"tv":2595.5,"id":9345630},{"batb":[[0,1.16,825.62],[1,1.15,1155.23]],"ltp":1.21,"tv":43580.57,"id":9028621}]}]}
{"op":"mcm","clk":"4226511481","pt":1631449589789,"mc":[{"id":"1.187552454","rc":[{"batb":[[0,5,4],[1,4.9,3],[2,4.8,2]],"batl":[[1,7.8,2],[2,8.8,4]],"ltp":4.4,"tv":2595.5,"id":9345630},{"batb":[[2,1.13,654.71]],"batl":[[0,1.25,448.34]],"ltp":1.21,"tv":43580.57,"id":9028621}]}]}
{"op":"mcm","clk":"4226511747","pt":1631449591571,"mc":[{"id":"1.187552454","rc":[{"batl":[[0,7.4,4]],"ltp":4.4,"tv":2595.5,"id":9345630},{"batb":[[0,1.16,842.62],[1,1.15,1170.23]],"ltp":1.21,"tv":43580.57,"id":9028621}]}]}
{"op":"mcm","clk":"4226511906","pt":1631449592574,"mc":[{"id":"1.187552454","rc":[{"batb":[[0,5.1,3],[1,5,4],[2,4.9,3]],"ltp":4.4,"tv":2595.5,"id":9345630},{"batl":[[0,1.24,62.98],[1,1.25,448.34],[2,1.26,678.25]],"ltp":1.21,"tv":43580.57,"id":9028621}]}]}
{"op":"mcm","clk":"4226511928","pt":1631449592766,"mc":[{"id":"1.187552454","rc":[{"batl":[[0,1.24,12]],"ltp":1.21,"tv":43580.57,"id":9028621}]}]}
{"op":"mcm","clk":"4226512563","pt":1631449596974,"mc":[{"id":"1.187552454","rc":[{"batb":[[0,6.4,14.94],[1,6.2,14.5],[2,6,14.5]],"ltp":4.4,"tv":2595.5,"id":9345630}]}]}
{"op":"mcm","clk":"4226512679","pt":1631449597778,"mc":[{"id":"1.187552454","rc":[{"batl":[[1,1.25,65.18],[2,1.26,49.75]],"ltp":1.21,"tv":43580.57,"id":9028621}]}]}
{"op":"mcm","clk":"4226512952","pt":1631449599594,"mc":[{"id":"1.187552454","rc":[{"batb":[[0,1.16,825.62],[2,1.13,119.73]],"batl":[[0,1.23,58.5],[1,1.24,62.48],[2,1.25,65.18]],"ltp":1.21,"tv":43580.57,"id":9028621}]}]}
{"op":"mcm","clk":"4226513084","pt":1631449600587,"mc":[{"id":"1.187552454","rc":[{"trd":[[6.4,21.36]],"batb":[[0,6.4,182.18],[1,6.2,187.19],[2,6,187.19]],"batl":[[2,8,478.12]],"ltp":6.4,"tv":2616.86,"id":9345630}],"tv":46197.43}]}
{"op":"mcm","clk":"4226513211","pt":1631449601284,"mc":[{"id":"1.187552454","rc":[{"batb":[[0,6.4,93.22],[1,6.2,100.85],[2,6,100.85]],"batl":[[1,8,239.06],[2,8.2,127.61]],"ltp":6.4,"tv":2616.86,"id":9345630},{"batb":[[2,1.13,100.73]],"batl":[[0,1.18,746],[1,1.19,894.49],[2,1.21,13.18]],"ltp":1.21,"tv":43580.57,"id":9028621}]}]}
{"op":"mcm","clk":"4226513390","pt":1631449602496,"mc":[{"id":"1.187552454","rc":[{"batb":[[2,6,112.85]],"batl":[[1,7.8,5.75],[2,8,239.06]],"ltp":6.4,"tv":2616.86,"id":9345630},{"batb":[[1,1.15,1208.95]],"batl":[[2,1.2,15]],"ltp":1.21,"tv":43580.57,"id":9028621}]}]}
{"op":"mcm","clk":"4226513535","pt":1631449603350,"mc":[{"id":"1.187552454","rc":[{"batb":[[0,6.6,8.92],[1,6.4,93.22],[2,6.2,100.85]],"batl":[[0,7,2.73],[1,7.4,14.16],[2,7.8,5.75]],"ltp":6.4,"tv":2616.86,"id":9345630},{"batb":[[0,1.16,870.73]],"ltp":1.21,"tv":43580.57,"id":9028621}]}]}
{"op":"mcm","clk":"4226513862","pt":1631449605545,"mc":[{"id":"1.187552454","rc":[{"batl":[[0,1.17,90.02],[1,1.18,746],[2,1.19,894.49]],"ltp":1.21,"tv":43580.57,"id":9028621}]}]}
{"op":"mcm","clk":"4226514002","pt":1631449606316,"mc":[{"id":"1.187552454","rc":[{"batl":[[0,1.18,803],[1,1.19,894.49],[2,1.21,13.18]],"ltp":1.21,"tv":43580.57,"id":9028621}]}]}
{"op":"mcm","clk":"4226514192","pt":1631449607477,"mc":[{"id":"1.187552454","rc":[{"trd":[[1.16,200]],"batb":[[0,1.16,770.73]],"batl":[[2,1.21,70.68]],"ltp":1.16,"tv":43780.57,"id":9028621}],"tv":46397.43}]}
{"op":"mcm","clk":"4226514370","pt":1631449608594,"mc":[{"id":"1.187552454","rc":[{"batb":[[2,6.2,112.38]],"ltp":6.4,"tv":2616.86,"id":9345630},{"trd":[[1.16,208.5]],"batb":[[0,1.16,766.48]],"ltp":1.16,"tv":43789.07,"id":9028621}],"tv":46405.94}]}
{"op":"mcm","clk":"4226514500","pt":1631449609383,"mc":[{"id":"1.187552454","rc":[{"batb":[[2,6.2,114.38]],"ltp":6.4,"tv":2616.86,"id":9345630},{"batl":[[1,1.19,987.99],[2,1.2,71.13]],"ltp":1.16,"tv":43789.07,"id":9028621}]}]}
{"op":"mcm","clk":"4226514751","pt":1631449610902,"mc":[{"id":"1.187552454","rc":[{"trd":[[7,5.46]],"batb":[[0,7,2.21],[1,6.6,8.92],[2,6.4,93.22]],"batl":[[0,7.4,14.16],[1,7.8,5.75],[2,8,239.06]],"ltp":7.0,"tv":2622.32,"id":9345630},{"batb":[[0,1.16,824.41]],"ltp":1.16,"tv":43789.07,"id":9028621}],"tv":46411.4}]}
{"op":"mcm","clk":"4226515008","pt":1631449612491,"mc":[{"id":"1.187552454","rc":[{"batb":[[1,6.2,11.53],[2,5.7,2]],"batl":[[0,7.8,5.75],[1,11,2],[2,12.5,2]],"ltp":7.0,"tv":2622.32,"id":9345630},{"batb":[[0,1.15,38.72],[1,1.1,126.64],[2,1.09,810.12]],"batl":[[0,1.19,15],[1,1.21,57.5],[2,1.24,12]],"ltp":1.16,"tv":43789.07,"id":9028621}]}]}
{"op":"mcm","clk":"4226515161","pt":1631449613611,"mc":[{"id":"1.187552454","rc":[{"batb":[[1,5.7,2],[2,5.1,3]],"batl":[[0,11,2],[1,12.5,2],[2,990,0.01]],"ltp":7.0,"tv":2622.32,"id":9345630},{"batb":[[0,1.1,126.64],[1,1.09,810.12],[2,1.01,30]],"batl":[[0,1.21,57.5],[1,1.24,12],[2,1.34,13.01]],"ltp":1.16,"tv":43789.07,"id":9028621}]}]}
{"op":"mcm","clk":"4226515451","pt":1631449615580,"mc":[{"id":"1.187552454","rc":[{"batb":[[0,1.13,746.49],[1,1.12,1122.84],[2,1.1,126.64]],"batl":[[0,1.16,10],[1,1.21,801.91],[2,1.22,756.26]],"ltp":1.16,"tv":43789.07,"id":9028621}]}]}
{"op":"mcm","clk":"4226515536","pt":1631449616177,"mc":[{"id":"1.187552454","rc":[{"batl":[[0,9.4,2],[1,11,2],[2,12.5,2]],"ltp":7.0,"tv":2622.32,"id":9345630},{"batb":[[1,1.12,1225.63],[2,1.11,117.59]],"ltp":1.16,"tv":43789.07,"id":9028621}]}]}
{"op":"mcm","clk":"4226515627","pt":1631449616875,"mc":[{"id":"1.187552454","rc":[{"batl":[[1,10.5,2],[2,11,4]],"ltp":7.0,"tv":2622.32,"id":9345630}]}]}
{"op":"mcm","clk":"4226515864","pt":1631449618471,"mc":[{"id":"1.187552454","rc":[{"batl":[[0,8.8,2],[1,9.4,2],[2,10.5,2]],"ltp":7.0,"tv":2622.32,"id":9345630},{"batl":[[0,1.16,26.62]],"ltp":1.16,"tv":43789.07,"id":9028621}]}]}
{"op":"mcm","clk":"4226516001","pt":1631449619384,"mc":[{"id":"1.187552454","rc":[{"batb":[[1,6.2,2],[2,5.7,2]],"ltp":7.0,"tv":2622.32,"id":9345630},{"batl":[[1,1.19,75.5],[2,1.2,64.68]],"ltp":1.16,"tv":43789.07,"id":9028621}]}]}
{"op":"mcm","clk":"4226516094","pt":1631449619979,"mc":[{"id":"1.187552454","rc":[{"batb":[[0,5.7,2.78],[1,5.1,3],[2,1.01,30]],"ltp":7.0,"tv":2622.32,"id":9345630},{"batl":[[0,1.16,16.62],[1,1.21,801.91],[2,1.22,756.26]],"ltp":1.16,"tv":43789.07,"id":9028621}]}]}
{"op":"mcm","clk":"4226516319","pt":1631449621407,"mc":[{"id":"1.187552454","rc":[{"trd":[[7,6.24]],"batb":[[0,5.7,2]],"batl":[[1,10.5,2],[2,11,4]],"ltp":7.0,"tv":2623.1,"id":9345630},{"trd":[[1.16,241.75],[1.17,4.65]],"batb":[[0,1.19,37.38],[1,1.18,1620.76],[2,1.17,1551.82]],"batl":[[0,1.21,801.91],[1,1.22,756.26],[2,1.24,12]],"ltp":1.17,"tv":43826.97,"id":9028621}],"tv":46450.07}]}
{"op":"mcm","clk":"4226516369","pt":1631449621692,"mc":[{"id":"1.187552454","rc":[{"batb":[[0,1.18,81.04],[1,1.17,78.65],[2,1.16,78.65]],"ltp":1.17,"tv":43826.97,"id":9028621}]}]}
{"op":"mcm","clk":"4226516691","pt":1631449623580,"mc":[{"id":"1.187552454","rc":[{"batb":[[1,5.4,572.52],[2,5.3,555.68]],"batl":[[0,6.6,2],[1,8.8,2],[2,10.5,2]],"ltp":7.0,"tv":2623.1,"id":9345630},{"trd":[[1.18,27.36]],"batb":[[0,1.18,1707.48],[1,1.17,1651.74],[2,1.16,1651.74]],"ltp":1.18,"tv":43854.33,"id":9028621}],"tv":46477.43}]}
{"op":"mcm","clk":"4226516848","pt":1631449624598,"mc":[{"id":"1.187552454","rc":[{"batb":[[0,5.7,4],[1,5.6,2],[2,5.4,126.89]],"batl":[[0,5.9,2],[1,6.6,2],[2,8.8,2]],"ltp":7.0,"tv":2623.1,"id":9345630},{"batb":[[0,1.2,8],[1,1.19,393.13],[2,1.18,1901.84]],"batl":[[0,1.21,811.91],[2,1.24,24.86]],"ltp":1.18,"tv":43854.33,"id":9028621}]}]}
{"op":"mcm","clk":"4226516963","pt":1631449625415,"mc":[{"id":"1.187552454","rc":[{"batb":[[0,5.7,2],[1,5.6,15.04]],"batl":[[2,7,6.12]],"ltp":7.0,"tv":2623.1,"id":9345630},{"batl":[[0,1.21,801.91],[1,1.22,771.26]],"ltp":1.18,"tv":43854.33,"id":9028621}]}]}
{"op":"mcm","clk":"4226517001","pt":1631449625684,"mc":[{"id":"1.187552454","rc":[{"batb":[[0,5.8,9.92],[1,5.7,2],[2,5.6,15.04]],"ltp":7.0,"tv":2623.1,"id":9345630},{"batb":[[2,1.18,1976.81]],"batl":[[0,1.21,856.37]],"ltp":1.18,"tv":43854.33,"id":9028621}]}]}
{"op":"mcm","clk":"4226517181","pt":1631449627018,"mc":[{"id":"1.187552454","rc":[{"batl":[[2,7.4,10]],"ltp":7.0,"tv":2623.1,"id":9345630}]}]}
{"op":"mcm","clk":"4226517384","pt":1631449628518,"mc":[{"id":"1.187552454","rc":[{"trd":[[5.9,2]],"batl":[[0,6.6,2],[1,7.2,50.96]],"ltp":5.9,"tv":2625.1,"id":9345630},{"trd":[[1.19,26.64],[1.2,496.45]],"batb":[[0,1.19,379.81],[1,1.18,1976.81],[2,1.17,901.58]],"ltp":1.19,"tv":43906.8,"id":9028621}],"tv":46531.9}]}
{"op":"mcm","clk":"4226517442","pt":1631449628906,"mc":[{"id":"1.187552454","rc":[{"batl":[[1,8.8,2],[2,11,2]],"ltp":5.9,"tv":2625.1,"id":9345630}]}]}
{"op":"mcm","clk":"4226517706","pt":1631449630495,"mc":[{"id":"1.187552454","rc":[{"trd":[[1.19,101.02]],"batb":[[0,1.19,342.62]],"ltp":1.19,"tv":43981.18,"id":9028621}],"tv":46606.28}]}
{"op":"mcm","clk":"4226517738","pt":1631449630713,"mc":[{"id":"1.187552454","rc":[{"batl":[[1,8.8,4]],"ltp":5.9,"tv":2625.1,"id":9345630},{"batl":[[2,1.24,83.59]],"ltp":1.19,"tv":43981.18,"id":9028621}]}]}
{"op":"mcm","clk":"4226517945","pt":1631449631927,"mc":[{"id":"1.187552454","rc":[{"batl":[[0,6.4,10],[1,6.6,2],[2,8.8,4]],"ltp":5.9,"tv":2625.1,"id":9345630}]}]}
{"op":"mcm","clk":"4226518145","pt":1631449633121,"mc":[{"id":"1.187552454","rc":[{"batl":[[0,1.2,9.75],[1,1.21,856.37],[2,1.22,816.26]],"ltp":1.19,"tv":43981.18,"id":9028621}]}]}
{"op":"mcm","clk":"4226518228","pt":1631449633708,"mc":[{"id":"1.187552454","rc":[{"batl":[[1,6.6,8.33]],"ltp":5.9,"tv":2625.1,"id":9345630}]}]}
{"op":"mcm","clk":"4226518830","pt":1631449637836,"mc":[{"id":"1.187552454","rc":[{"batl":[[0,1.21,856.37],[1,1.22,816.26],[2,1.23,54.5]],"ltp":1.19,"tv":43981.18,"id":9028621}]}]}
{"op":"mcm","clk":"4226519307","pt":1631449641444,"mc":[{"id":"1.187552454","rc":[{"batb":[[0,5.6,13.04],[1,5.1,2],[2,5,2]],"batl":[[0,6.6,6.33],[1,8.8,4],[2,11,2]],"ltp":5.9,"tv":2625.1,"id":9345630},{"batb":[[0,1.17,36.38],[1,1.13,106.73],[2,1.11,694.99]],"batl":[[0,1.22,60],[1,1.24,70.73],[2,1.25,54.58]],"ltp":1.19,"tv":43981.18,"id":9028621}]}]}
{"op":"mcm","clk":"4226519459","pt":1631449642476,"mc":[{"id":"1.187552454","rc":[{"batb":[[0,4.8,2],[1,1.01,30],[2,5,0]],"batl":[[0,6,2.54],[1,8.8,2]],"ltp":5.9,"tv":2625.1,"id":9345630},{"batb":[[0,1.11,694.99],[1,1.1,140.64],[2,1.09,136.61]],"batl":[[0,1.24,12],[1,1.26,50.75],[2,1.34,13.01]],"ltp":1.19,"tv":43981.18,"id":9028621}]}]}
{"op":"mcm","clk":"4226519754","pt":1631449644382,"mc":[{"id":"1.187552454","rc":[{"batb":[[0,1.14,1559.97],[1,1.13,285.61],[2,1.11,694.99]],"batl":[[1,1.25,679.75],[2,1.26,673.8]],"ltp":1.19,"tv":43981.18,"id":9028621}]}]}
{"op":"mcm","clk":"4226519923","pt":1631449645445,"mc":[{"id":"1.187552454","rc":[{"batb":[[0,5.1,2],[1,4.8,2],[2,1.01,30]],"batl":[[1,8.8,4]],"ltp":5.9,"tv":2625.1,"id":9345630},{"batb":[[1,1.13,384.34]],"batl":[[0,1.24,65.48],[1,1.25,731.69]],"ltp":1.19,"tv":43981.18,"id":9028621}]}]}
{"op":"mcm","clk":"4226519957","pt":1631449645665,"mc":[{"id":"1.187552454","rc":[{"batb":[[1,5,3],[2,4.8,2]],"ltp":5.9,"tv":2625.1,"id":9345630},{"batb":[[2,1.12,11]],"batl":[[0,1.24,12]],"ltp":1.19,"tv":43981.18,"id":9028621}]}]}
{"op":"mcm","clk":"4226520177","pt":1631449647470,"mc":[{"id":"1.187552454","rc":[{"batl":[[1,1.26,50.75],[2,1.34,13.01]],"ltp":1.19,"tv":43981.18,"id":9028621}]}]}
{"op":"mcm","clk":"4226520322","pt":1631449648583,"mc":[{"id":"1.187552454","rc":[{"batb":[[0,5.4,3],[1,5.3,2],[2,5.1,2]],"ltp":5.9,"tv":2625.1,"id":9345630},{"batl":[[0,1.23,71.59],[1,1.24,12],[2,1.26,50.75]],"ltp":1.19,"tv":43981.18,"id":9028621}]}]}
{"op":"mcm","clk":"4226520396","pt":1631449649060,"mc":[{"id":"1.187552454","rc":[{"batb":[[2,5.2,2]],"ltp":5.9,"tv":2625.1,"id":9345630},{"batl":[[0,1.23,92.41]],"ltp":1.19,"tv":43981.18,"id":9028621}]}]}
{"op":"mcm","clk":"4226520596","pt":1631449650576,"mc":[{"id":"1.187552454","rc":[{"trd":[[5.4,6.97],[5.5,714.94],[5.6,460.74],[5.7,78.28]],"batb":[[0,5.4,2.57]],"batl":[[2,9,116.87]],"ltp":5.4,"tv":3861.55,"id":9345630},{"trd":[[1.21,2829.81],[1.22,188.69],[1.23,227.33]],"batb":[[0,1.14,1006.19],[1,1.13,98.73]],"batl":[[0,1.24,12],[1,1.25,16]],"ltp":1.23,"tv":45607.24,"id":9028621}],"tv":49468.8}]}
{"op":"mcm","clk":"4226520762","pt":1631449651586,"mc":[{"id":"1.187552454","rc":[{"trd":[[5.2,2],[5.3,2],[5.4,7.54],[6,5.04]],"batb":[[0,5.1,2],[1,5,3],[2,4.8,2]],"batl":[[0,7.8,5.75]],"ltp":5.2,"tv":3871.15,"id":9345630},{"trd":[[1.19,220.66],[1.2,496.63],[1.23,229.83],[1.24,2528.72]],"batb":[[0,1.24,618.18],[1,1.14,1046.27],[2,1.13,98.73]],"batl":[[0,1.25,8],[1,1.26,50.75],[2,1.34,13.01]],"ltp":1.24,"tv":46059.71,"id":9028621}],"tv":49930.87}]}
{"op":"mcm","clk":"4226520882","pt":1631449652274,"mc":[{"id":"1.187552454","rc":[{"trd":[[5.2,17]],"batl":[[0,8.8,4],[1,9,116.87],[2,9.2,113.44]],"ltp":5.2,"tv":3886.15,"id":9345630},{"trd":[[1.24,3008.28]],"batb":[[0,1.24,346.96],[1,1.14,1046.6]],"ltp":1.24,"tv":46539.27,"id":9028621}],"tv":50425.42}]}
{"op":"mcm","clk":"4226521033","pt":1631449653379,"mc":[{"id":"1.187552454","rc":[{"trd":[[5.2,27]],"batb":[[0,6,278.89],[1,5.1,2],[2,5,3]],"batl":[[0,8,88.87],[1,8.8,4],[2,9,116.87]],"ltp":5.2,"tv":3896.15,"id":9345630},{"trd":[[1.21,2830.47],[1.24,3660.26]],"batb":[[0,1.15,829.62],[1,1.14,1046.27]],"batl":[[0,1.17,473.17],[1,1.18,930.36],[2,1.25,8]],"ltp":1.21,"tv":47191.9,"id":9028621}],"tv":51088.06}]}
{"op":"mcm","clk":"4226521166","pt":1631449654598,"mc":[{"id":"1.187552454","rc":[{"batb":[[0,6,281.43]],"ltp":5.2,"tv":3896.15,"id":9345630},{"batb":[[1,1.14,911.37]],"batl":[[1,1.18,945.36]],"ltp":1.21,"tv":47191.9,"id":9028621}]}]}
{"op":"mcm","clk":"4226521295","pt":1631449655504,"mc":[{"id":"1.187552454","rc":[{"batb":[[0,6.4,3],[1,6.2,2],[2,6,278.89]],"batl":[[0,7.6,5.83],[1,8,88.87],[2,8.8,4]],"ltp":5.2,"tv":3896.15,"id":9345630},{"batb":[[1,1.14,871.29]],"batl":[[2,1.24,8]],"ltp":1.21,"tv":47191.9,"id":9028621}]}]}
{"op":"mcm","clk":"4226521478","pt":1631449656580,"mc":[{"id":"1.187552454","rc":[{"batb":[[2,5.1,2]],"batl":[[1,7.8,9.86],[2,8,88.87]],"ltp":5.2,"tv":3896.15,"id":9345630},{"batb":[[0,1.15,1013.28]],"batl":[[0,1.17,636.9]],"ltp":1.21,"tv":47191.9,"id":9028621}]}]}
{"op":"mcm","clk":"4226521610","pt":1631449657376,"mc":[{"id":"1.187552454","rc":[{"batb":[[2,4.8,2]],"ltp":5.2,"tv":3896.15,"id":9345630},{"trd":[[1.17,5.31]],"batl":[[0,1.17,636.57]],"ltp":1.17,"tv":47192.56,"id":9028621}],"tv":51088.72}]}
{"op":"mcm","clk":"4226521756","pt":1631449658389,"mc":[{"id":"1.187552454","rc":[{"batb":[[1,6.2,500.74]],"ltp":5.2,"tv":3896.15,"id":9345630},{"batl":[[2,1.19,60]],"ltp":1.17,"tv":47192.56,"id":9028621}]}]}
{"op":"mcm","clk":"4226521805","pt":1631449658682,"mc":[{"id":"1.187552454","rc":[{"batb":[[1,6.2,489.21]],"ltp":5.2,"tv":3896.15,"id":9345630},{"batb":[[0,1.15,1052]],"ltp":1.17,"tv":47192.56,"id":9028621}]}]}
{"op":"mcm","clk":"4226521995","pt":1631449660110,"mc":[{"id":"1.187552454","rc":[{"batb":[[1,6.2,2]],"ltp":5.2,"tv":3896.15,"id":9345630},{"trd":[[1.17,1269.29]],"batb":[[1,1.14,598.15]],"batl":[[0,1.17,4.58]],"ltp":1.17,"tv":48456.54,"id":9028621}],"tv":52352.7}]}
{"op":"mcm","clk":"4226522325","pt":1631449662488,"mc":[{"id":"1.187552454","rc":[{"batb":[[0,6.4,14.11]],"batl":[[1,8,88.87],[2,8.8,4]],"ltp":5.2,"tv":3896.15,"id":9345630},{"trd":[[1.15,5.12]],"batb":[[0,1.15,1049.44]],"ltp":1.15,"tv":48461.67,"id":9028621}],"tv":52357.83}]}
{"op":"mcm","clk":"4226522473","pt":1631449663493,"mc":[{"id":"1.187552454","rc":[{"batb":[[0,6.6,2],[1,6.4,486.05],[2,6.2,2]],"ltp":5.2,"tv":3896.15,"id":9345630},{"batb":[[0,1.15,1320.21]],"batl":[[0,1.17,370.85]],"ltp":1.15,"tv":48461.67,"id":9028621}]}]}
{"op":"mcm","clk":"4226522597","pt":1631449664400,"mc":[{"id":"1.187552454","rc":[{"trd":[[7.6,2.82]],"batl":[[0,7.6,4.42]],"ltp":7.6,"tv":3898.98,"id":9345630},{"trd":[[1.17,1270.15]],"batl":[[0,1.17,370.42]],"ltp":1.17,"tv":48462.52,"id":9028621}],"tv":52361.5}]}
{"op":"mcm","clk":"4226522883","pt":1631449666579,"mc":[{"id":"1.187552454","rc":[{"batb":[[0,6.4,11.11],[1,1.01,30],[2,6.2,0]],"batl":[[0,7.6,5.2],[1,990,0.01],[2,8.8,0]],"ltp":7.6,"tv":3898.98,"id":9345630},{"batb":[[0,1.15,38.72],[1,1.08,719.06],[2,1.01,30]],"batl":[[0,1.19,60],[1,1.34,13.01],[2,1.47,896.39]],"ltp":1.17,"tv":48462.52,"id":9028621}]}]}
{"op":"mcm","clk":"4226523005","pt":1631449667588,"mc":[{"id":"1.187552454","rc":[{"batb":[[0,1.01,30],[1,1.01,0]],"batl":[[0,990,0.78],[1,990,0]],"ltp":7.6,"tv":3898.98,"id":9345630},{"batb":[[0,1.08,719.06],[1,1.01,30],[2,1.01,0]],"batl":[[0,1.34,13.01],[1,1.39,17.8]],"ltp":1.17,"tv":48462.52,"id":9028621}]}]}
{"op":"mcm","clk":"4226523242","pt":1631449669519,"mc":[{"id":"1.187552454","rc":[{"batb":[[0,1.12,981.95],[1,1.11,902.11],[2,1.08,719.06]],"batl":[[0,1.21,999.55],[1,1.22,719.31],[2,1.34,13.01]],"ltp":1.17,"tv":48462.52,"id":9028621}]}]}
{"op":"mcm","clk":"4226523538","pt":1631449671520,"mc":[{"id":"1.187552454","rc":[{"batb":[[0,3.9,2],[1,3.85,3],[2,1.01,30]],"batl":[[0,13.5,2],[1,990,0.01]],"ltp":7.6,"tv":3898.98,"id":9345630},{"batl":[[2,1.34,17.01]],"ltp":1.17,"tv":48462.52,"id":9028621}]}]}
{"op":"mcm","clk":"4226523782","pt":1631449673224,"mc":[{"id":"1.187552454","rc":[{"batb":[[0,1.08,719.06],[1,1.01,30],[2,1.08,0]],"batl":[[0,1.2,9.75],[1,1.21,999.55],[2,1.22,719.31]],"ltp":1.17,"tv":48462.52,"id":9028621}]}]}
{"op":"mcm","clk":"4226523951","pt":1631449674511,"mc":[{"id":"1.187552454","rc":[{"batb":[[0,1.01,30.12],[1,1.01,0]],"ltp":1.17,"tv":48462.52,"id":9028621}]}]}
{"op":"mcm","clk":"4226524074","pt":1631449675509,"mc":[{"id":"1.187552454","rc":[{"batb":[[0,1.18,81.04],[1,1.17,78.77],[2,1.16,78.65]],"ltp":1.17,"tv":48462.52,"id":9028621}]}]}
{"op":"mcm","clk":"4226524192","pt":1631449676512,"mc":[{"id":"1.187552454","rc":[{"batb":[[0,5.4,44.5],[1,5.3,43.2],[2,5.2,43.2]],"ltp":7.6,"tv":3898.98,"id":9345630},{"batb":[[0,1.18,1896.89],[1,1.17,1647.08],[2,1.16,865.2]],"ltp":1.17,"tv":48462.52,"id":9028621}]}]}
{"op":"mcm","clk":"4226524302","pt":1631449677424,"mc":[{"id":"1.187552454","rc":[{"trd":[[6,6.99]],"batb":[[0,5.7,12.76],[1,5.4,44.5],[2,5.3,43.2]],"batl":[[0,7,24.54],[1,13.5,2],[2,990,0.01]],"ltp":6.0,"tv":3900.93,"id":9345630},{"trd":[[1.2,506.38]],"batb":[[0,1.18,1904.89],[1,1.17,1683.46]],"batl":[[0,1.21,999.55],[1,1.22,779.31],[2,1.24,12.86]],"ltp":1.2,"tv":48472.27,"id":9028621}],"tv":52373.2}]}
{"op":"mcm","clk":"4226524437","pt":1631449678631,"mc":[{"id":"1.187552454","rc":[{"trd":[[5.8,0.1]],"batb":[[0,5.8,1.95],[1,5.7,14.76],[2,5.4,44.5]],"batl":[[0,7,24.49]],"ltp":5.8,"tv":3901.03,"id":9345630}],"tv":52373.3}]}
{"op":"mcm","clk":"4226524655","pt":1631449680431,"mc":[{"id":"1.187552454","rc":[{"batb":[[0,5.8,3.98]],"ltp":5.8,"tv":3901.03,"id":9345630}]}]}
{"op":"mcm","clk":"4226524798","pt":1631449681447,"mc":[{"id":"1.187552454","rc":[{"batb":[[0,5.8,1.95]],"batl":[[0,6.8,16.66],[1,7,24.49],[2,13.5,2]],"ltp":5.8,"tv":3901.03,"id":9345630},{"trd":[[1.18,117.6]],"batb":[[0,1.18,2009.77]],"batl":[[0,1.21,1072.65]],"ltp":1.18,"tv":48562.51,"id":9028621}],"tv":52463.54}]}
{"op":"mcm","clk":"4226524932","pt":1631449682427,"mc":[{"id":"1.187552454","rc":[{"batl":[[1,13.5,2],[2,990,0.01]],"ltp":5.8,"tv":3901.03,"id":9345630},{"batb":[[0,1.18,914.9],[1,1.17,901.58]],"batl":[[0,1.21,73.1],[1,1.22,60]],"ltp":1.18,"tv":48562.51,"id":9028621}]}]}
{"op":"mcm","clk":"4226525037","pt":1631449683128,"mc":[{"id":"1.187552454","rc":[{"batl":[[0,11,2],[2,18,2]],"ltp":5.8,"tv":3901.03,"id":9345630},{"batl":[[2,1.23,53.5]],"ltp":1.18,"tv":48562.51,"id":9028621}]}]}
{"op":"mcm","clk":"4226525228","pt":1631449684556,"mc":[{"id":"1.187552454","rc":[{"batb":[[0,5.9,16.99],[1,5.8,1.95],[2,5.7,14.76]],"ltp":5.8,"tv":3901.03,"id":9345630}]}]}
{"op":"mcm","clk":"4226525396","pt":1631449685572,"mc":[{"id":"1.187552454","rc":[{"batl":[[0,6.8,24.91],[1,11,2],[2,13.5,2]],"ltp":5.8,"tv":3901.03,"id":9345630}]}]}
{"op":"mcm","clk":"4226525770","pt":1631449688233,"mc":[{"id":"1.187552454","rc":[{"trd":[[1.21,2834.47]],"batl":[[0,1.21,71.1]],"ltp":1.21,"tv":48566.51,"id":9028621}],"tv":52467.54}]}
{"op":"mcm","clk":"4226525918","pt":1631449689456,"mc":[{"id":"1.187552454","rc":[{"batl":[[0,6.6,16.66],[1,6.8,24.91],[2,11,2]],"ltp":5.8,"tv":3901.03,"id":9345630},{"batb":[[0,1.18,1920.37],[1,1.17,1683.34]],"batl":[[0,1.21,1070.65],[1,1.22,779.31]],"ltp":1.21,"tv":48566.51,"id":9028621}]}]}
{"op":"mcm","clk":"4226526102","pt":1631449690838,"mc":[{"id":"1.187552454","rc":[{"batb":[[2,5.7,12.76]],"ltp":5.8,"tv":3901.03,"id":9345630}]}]}
{"op":"mcm","clk":"4226526689","pt":1631449695464,"mc":[{"id":"1.187552454","rc":[{"batb":[[0,5.7,12.76],[1,4.8,2],[2,1.01,30]],"batl":[[0,6.8,24.91],[1,11,2],[2,13.5,2]],"ltp":5.8,"tv":3901.03,"id":9345630},{"batb":[[0,1.17,36.38],[1,1.13,7.04],[2,1.11,586.4]],"batl":[[0,1.22,60],[1,1.26,46.25],[2,1.34,17.01]],"ltp":1.21,"tv":48566.51,"id":9028621}]}]}
{"op":"mcm","clk":"4226526823","pt":1631449696471,"mc":[{"id":"1.187552454","rc":[{"batb":[[0,4.8,2],[1,1.01,30],[2,1.01,0]],"batl":[[0,11,2],[1,13.5,2],[2,18,2]],"ltp":5.8,"tv":3901.03,"id":9345630},{"batb":[[0,1.13,7.04],[1,1.11,586.4],[2,1.1,104.74]],"batl":[[0,1.26,46.25],[1,1.34,17.01],[2,1.39,17.8]],"ltp":1.21,"tv":48566.51,"id":9028621}]}]}
{"op":"mcm","clk":"4226526970","pt":1631449697550,"mc":[{"id":"1.187552454","rc":[{"batl":[[0,1.18,8],[1,1.26,46.25],[2,1.34,17.01]],"ltp":1.21,"tv":48566.51,"id":9028621}]}]}
{"op":"mcm","clk":"4226527083","pt":1631449698456,"mc":[{"id":"1.187552454","rc":[{"trd":[[1.18,117.8]],"batb":[[1,1.12,1679.56],[2,1.11,586.4]],"batl":[[0,1.18,7.9],[1,1.26,459.59],[2,1.27,579.51]],"ltp":1.18,"tv":48566.71,"id":9028621}],"tv":52467.74}]}
{"op":"mcm","clk":"4226527240","pt":1631449699776,"mc":[{"id":"1.187552454","rc":[{"batb":[[0,4.8,4],[1,4.7,2],[2,1.01,30]],"batl":[[0,10.5,2],[1,11,2],[2,13.5,2]],"ltp":5.8,"tv":3901.03,"id":9345630},{"batl":[[1,1.26,465.59]],"ltp":1.18,"tv":48566.71,"id":9028621}]}]}
{"op":"mcm","clk":"4226527434","pt":1631449701475,"mc":[{"id":"1.187552454","rc":[{"batl":[[0,9.4,2],[1,10.5,2],[2,11,2]],"ltp":5.8,"tv":3901.03,"id":9345630}]}]}
{"op":"mcm","clk":"4226527550","pt":1631449702381,"mc":[{"id":"1.187552454","rc":[{"batb":[[0,5.1,2],[1,5,3],[2,4.8,4]],"ltp":5.8,"tv":3901.03,"id":9345630}]}]}
{"op":"mcm","clk":"4226527935","pt":1631449705566,"mc":[{"id":"1.187552454","rc":[{"batb":[[0,5.3,2],[1,5.1,2],[2,5,3]],"ltp":5.8,"tv":3901.03,"id":9345630},{"batl":[[1,1.23,51.5],[2,1.24,59.98]],"ltp":1.18,"tv":48566.71,"id":9028621}]}]}
{"op":"mcm","clk":"4226527966","pt":1631449705892,"mc":[{"id":"1.187552454","rc":[{"batb":[[0,5.1,2],[1,5,3],[2,4.8,4]],"ltp":5.8,"tv":3901.03,"id":9345630},{"batl":[[1,1.26,465.59],[2,1.27,579.51]],"ltp":1.18,"tv":48566.71,"id":9028621}]}]}
{"op":"mcm","clk":"4226528196","pt":1631449707585,"mc":[{"id":"1.187552454","rc":[{"batb":[[0,1.14,11.7],[1,1.13,7.04],[2,1.12,1679.56]],"ltp":1.18,"tv":48566.71,"id":9028621}]}]}
{"op":"mcm","clk":"4226528288","pt":1631449708188,"mc":[{"id":"1.187552454","rc":[{"trd":[[1.14,23.4]],"batb":[[0,1.13,7.04],[1,1.12,1679.56],[2,1.11,586.4]],"batl":[[0,1.14,9.99]],"ltp":1.14,"tv":48590.11,"id":9028621}],"tv":52491.14}]}
{"op":"mcm","clk":"4226528546","pt":1631449710308,"mc":[{"id":"1.187552454","rc":[{"batl":[[0,1.26,465.59],[1,1.27,579.51],[2,1.34,17.01]],"ltp":1.14,"tv":48590.11,"id":9028621}]}]}
{"op":"mcm","clk":"4226528676","pt":1631449711327,"mc":[{"id":"1.187552454","rc":[{"batb":[[2,4.8,2]],"batl":[[1,11,2],[2,18,2]],"ltp":5.8,"tv":3901.03,"id":9345630},{"batb":[[0,1.18,1.95],[1,1.13,7.04],[2,1.12,1679.56]],"batl":[[2,1.34,13.01]],"ltp":1.14,"tv":48590.11,"id":9028621}]}]}
{"op":"mcm","clk":"4226528980","pt":1631449713461,"mc":[{"id":"1.187552454","rc":[{"batb":[[0,4.8,2],[1,1.01,30],[2,4.8,0]],"ltp":5.8,"tv":3901.03,"id":9345630},{"trd":[[1.13,0.1],[1.18,121.7]],"batb":[[0,1.13,6.99],[1,1.11,586.4],[2,1.1,104.74]],"batl":[[0,1.25,7],[1,1.26,465.59],[2,1.27,579.51]],"ltp":1.13,"tv":48594.11,"id":9028621}],"tv":52495.14}]}
{"op":"mcm","clk":"4226529083","pt":1631449714355,"mc":[{"id":"1.187552454","rc":[{"batl":[[0,5.6,20.98],[1,9.4,2],[2,11,2]],"ltp":5.8,"tv":3901.03,"id":9345630},{"trd":[[1.15,47.82]],"batl":[[0,1.26,459.59],[1,1.27,579.51],[2,1.34,13.01]],"ltp":1.15,"tv":48636.81,"id":9028621}],"tv":52537.84}]}
{"op":"mcm","clk":"4226529221","pt":1631449715577,"mc":[{"id":"1.187552454","rc":[{"batl":[[0,5.6,440.62],[1,6,2],[2,9.4,2]],"ltp":5.8,"tv":3901.03,"id":9345630},{"batb":[[0,1.2,19.02],[1,1.13,6.99]],"ltp":1.15,"tv":48636.81,"id":9028621}]}]}
{"op":"mcm","clk":"4226529333","pt":1631449716396,"mc":[{"id":"1.187552454","rc":[{"batb":[[0,4.8,4],[1,4.7,2],[2,1.01,30]],"batl":[[0,5.2,2],[1,5.6,104.91],[2,6,2]],"ltp":5.8,"tv":3901.03,"id":9345630},{"batb":[[0,1.24,307.47],[1,1.23,733.59],[2,1.2,19.02]],"batl":[[2,1.29,12.37]],"ltp":1.15,"tv":48636.81,"id":9028621}]}]}
{"op":"mcm","clk":"4226529478","pt":1631449717512,"mc":[{"id":"1.187552454","rc":[{"batb":[[0,4.8,29.78]],"batl":[[1,5.5,3],[2,5.6,104.91]],"ltp":5.8,"tv":3901.03,"id":9345630},{"batb":[[2,1.22,9]],"batl":[[0,1.26,519.59]],"ltp":1.15,"tv":48636.81,"id":9028621}]}]}
{"op":"mcm","clk":"4226530169","pt":1631449722586,"mc":[{"id":"1.187552454","rc":[{"batb":[[2,4.4,2]],"batl":[[2,5.6,132.88]],"ltp":5.8,"tv":3901.03,"id":9345630},{"batl":[[2,1.29,59.87]],"ltp":1.15,"tv":48636.81,"id":9028621}]}]}
{"op":"mcm","clk":"4226530222","pt":1631449723000,"mc":[{"id":"1.187552454","rc":[{"trd":[[1.24,3685.66]],"batb":[[0,1.24,294.77]],"ltp":1.24,"tv":48662.21,"id":9028621}],"tv":52563.24}]}
{"op":"mcm","clk":"4226530387","pt":1631449724168,"mc":[{"id":"1.187552454","rc":[{"trd":[[1.24,3686.65]],"batb":[[0,1.24,315.96]],"ltp":1.24,"tv":48663.21,"id":9028621}],"tv":52564.24}]}
{"op":"mcm","clk":"4226530536","pt":1631449725510,"mc":[{"id":"1.187552454","rc":[{"trd":[[1.26,355.34]],"batl":[[0,1.26,509.84]],"ltp":1.26,"tv":48682.71,"id":9028621}],"tv":52583.74}]}
{"op":"mcm","clk":"4226530628","pt":1631449726085,"mc":[{"id":"1.187552454","rc":[{"batb":[[0,1.24,294.27]],"ltp":1.26,"tv":48682.71,"id":9028621}]}]}
{"op":"mcm","clk":"4226530831","pt":1631449727613,"mc":[{"id":"1.187552454","rc":[{"trd":[[1.24,3687.05]],"batb":[[0,1.24,294.07]],"ltp":1.24,"tv":48683.11,"id":9028621}],"tv":52584.14}]}
{"op":"mcm","clk":"4226531344","pt":1631449731923,"mc":[{"id":"1.187552454","rc":[{"batb":[[1,4.4,2],[2,4.2,2]],"ltp":5.8,"tv":3901.03,"id":9345630},{"trd":[[1.26,356.86]],"batl":[[0,1.26,509.08]],"ltp":1.26,"tv":48684.63,"id":9028621}],"tv":52585.66}]}
{"op":"mcm","clk":"4226531458","pt":1631449732722,"mc":[{"id":"1.187552454","rc":[{"trd":[[4.8,5.55]],"batb":[[0,4.8,27.01]],"ltp":4.8,"tv":3906.57,"id":9345630}],"tv":52591.2}]}
{"op":"mcm","clk":"4226531662","pt":1631449734321,"mc":[{"id":"1.187552454","rc":[{"trd":[[4.8,6.21]],"batb":[[0,4.8,26.68]],"ltp":4.8,"tv":3907.24,"id":9345630},{"trd":[[1.24,3744.47]],"batb":[[0,1.24,265.36]],"ltp":1.24,"tv":48742.05,"id":9028621}],"tv":52649.29}]}
{"op":"mcm","clk":"4226531772","pt":1631449735204,"mc":[{"id":"1.187552454","rc":[{"trd":[[1.24,3756.47],[1.26,359.2]],"batb":[[0,1.24,259.36]],"batl":[[0,1.26,507.91]],"ltp":1.24,"tv":48756.39,"id":9028621}],"tv":52663.63}]}
{"op":"mcm","clk":"4226532191","pt":1631449738530,"mc":[{"id":"1.187552454","rc":[{"batl":[[2,5.6,27.97]],"ltp":4.8,"tv":3907.24,"id":9345630}]}]}
{"op":"mcm","clk":"4226532312","pt":1631449739406,"mc":[{"id":"1.187552454","rc":[{"batb":[[0,4.8,15.78],[1,4.2,2],[2,1.01,30]],"batl":[[0,5.6,27.97],[1,7.8,2],[2,11,2]],"ltp":4.8,"tv":3907.24,"id":9345630},{"batb":[[0,1.21,32.73],[1,1.15,588.42],[2,1.13,6.99]],"batl":[[0,1.26,60],[1,1.31,44.5],[2,1.34,13.01]],"ltp":1.24,"tv":48756.39,"id":9028621}]}]}
{"op":"mcm","clk":"4226532437","pt":1631449740413,"mc":[{"id":"1.187552454","rc":[{"batb":[[0,4.2,2],[1,1.01,30],[2,1.01,0]],"batl":[[0,7.8,2],[1,11,2],[2,18,2]],"ltp":4.8,"tv":3907.24,"id":9345630},{"batb":[[0,1.15,588.42],[1,1.13,6.99],[2,1.12,28.7]],"batl":[[0,1.31,44.5],[1,1.34,13.01],[2,1.47,896.39]],"ltp":1.24,"tv":48756.39,"id":9028621}]}]}
{"op":"mcm","clk":"4226532722","pt":1631449742320,"mc":[{"id":"1.187552454","rc":[{"batb":[[0,4.4,2],[1,4.2,2],[2,1.01,30]],"ltp":4.8,"tv":3907.24,"id":9345630},{"batb":[[0,1.18,916.76],[1,1.17,871.63],[2,1.15,588.42]],"batl":[[0,1.29,43.5],[1,1.31,371.56],[2,1.32,474]],"ltp":1.24,"tv":48756.39,"id":9028621}]}]}
{"op":"mcm","clk":"4226532785","pt":1631449742713,"mc":[{"id":"1.187552454","rc":[{"batb":[[0,4.2,2],[1,1.01,30],[2,1.01,0]],"ltp":4.8,"tv":3907.24,"id":9345630},{"batl":[[0,1.31,371.56],[1,1.32,474],[2,1.34,13.01]],"ltp":1.24,"tv":48756.39,"id":9028621}]}]}
{"op":"mcm","clk":"4226533008","pt":1631449744230,"mc":[{"id":"1.187552454","rc":[{"batb":[[0,4.7,3],[1,4.6,2],[2,4.2,4]],"batl":[[0,7.8,4]],"ltp":4.8,"tv":3907.24,"id":9345630},{"batb":[[2,1.15,604.42]],"batl":[[0,1.27,10],[1,1.31,380.56],[2,1.32,474]],"ltp":1.24,"tv":48756.39,"id":9028621}]}]}
{"op":"mcm","clk":"4226533190","pt":1631449745526,"mc":[{"id":"1.187552454","rc":[{"batb":[[2,4.4,2]],"ltp":4.8,"tv":3907.24,"id":9345630},{"batl":[[1,1.29,8],[2,1.31,380.56]],"ltp":1.24,"tv":48756.39,"id":9028621}]}]}
{"op":"mcm","clk":"4226533294","pt":1631449746248,"mc":[{"id":"1.187552454","rc":[{"batl":[[2,1.3,8]],"ltp":1.24,"tv":48756.39,"id":9028621}]}]}
{"op":"mcm","clk":"4226533692","pt":1631449749414,"mc":[{"id":"1.187552454","rc":[{"batb":[[2,4.4,4]],"ltp":4.8,"tv":3907.24,"id":9345630},{"batb":[[0,1.18,916.36]],"batl":[[1,1.29,51.5]],"ltp":1.24,"tv":48756.39,"id":9028621}]}]}
{"op":"mcm","clk":"4226533729","pt":1631449749735,"mc":[{"id":"1.187552454","rc":[{"batb":[[2,4.4,2]],"ltp":4.8,"tv":3907.24,"id":9345630},{"batl":[[0,1.19,111],[1,1.27,10],[2,1.29,8]],"ltp":1.24,"tv":48756.39,"id":9028621}]}]}
{"op":"mcm","clk":"4226533934","pt":1631449751411,"mc":[{"id":"1.187552454","rc":[{"trd":[[1.19,341.76]],"batl":[[0,1.19,50.45]],"ltp":1.19,"tv":48877.48,"id":9028621}],"tv":52784.73}]}
{"op":"mcm","clk":"4226534679","pt":1631449757214,"mc":[{"id":"1.187552454","rc":[{"batb":[[1,4.2,2],[2,1.01,30]],"ltp":4.8,"tv":3907.24,"id":9345630},{"batl":[[1,1.29,8],[2,1.31,371.56]],"ltp":1.19,"tv":48877.48,"id":9028621}]}]}
{"op":"mcm","clk":"4226535293","pt":1631449761358,"mc":[{"id":"1.187552454","rc":[{"trd":[[1.19,343.34]],"batl":[[0,1.19,49.66]],"ltp":1.19,"tv":48879.07,"id":9028621}],"tv":52786.31}]}
{"op":"mcm","clk":"4226535546","pt":1631449763235,"mc":[{"id":"1.187552454","rc":[{"trd":[[1.19,343.54]],"batl":[[0,1.19,49.56]],"ltp":1.19,"tv":48879.27,"id":9028621}],"tv":52786.51}]}
{"op":"mcm","clk":"4226535634","pt":1631449763965,"mc":[{"id":"1.187552454","rc":[{"trd":[[1.18,125.7],[1.19,351.12]],"batb":[[0,1.18,914.36]],"batl":[[0,1.19,45.77],[2,1.31,44.5]],"ltp":1.18,"tv":48890.84,"id":9028621}],"tv":52798.08}]}
{"op":"mcm","clk":"4226535832","pt":1631449765555,"mc":[{"id":"1.187552454","rc":[{"trd":[[4.7,4.06]],"batb":[[0,4.2,2],[1,1.01,30],[2,1.01,0]],"batl":[[0,4.7,20.35],[1,4.8,19.75],[2,4.9,19.75]],"ltp":4.7,"tv":3910.24,"id":9345630},{"trd":[[1.19,442.66],[1.28,366.34]],"batl":[[0,1.29,8],[1,1.31,44.5],[2,1.34,13.01]],"ltp":1.28,"tv":48993.4,"id":9028621}],"tv":52903.64}]}
{"op":"mcm","clk":"4226535919","pt":1631449766240,"mc":[{"id":"1.187552454","rc":[{"batb":[[0,1.19,49.65],[1,1.18,914.36],[2,1.17,871.63]],"ltp":1.28,"tv":48993.4,"id":9028621}]}]}
{"op":"mcm","clk":"4226536125","pt":1631449767574,"mc":[{"id":"1.187552454","rc":[{"trd":[[4.7,42.6],[4.8,45.71],[4.9,316.5]],"batb":[[0,5.9,24.06],[1,5.7,23.35],[2,5.2,4]],"batl":[[0,7.2,146.24],[1,7.4,141.79],[2,7.6,141.79]],"ltp":4.9,"tv":4027.78,"id":9345630},{"trd":[[1.27,2585.63]],"batb":[[0,1.18,914.64],[1,1.17,871.63],[2,1.15,95.4]],"batl":[[0,1.2,299.09],[1,1.21,782.85],[2,1.23,12.97]],"ltp":1.27,"tv":49001.41,"id":9028621}],"tv":53029.19}]}
{"op":"mcm","clk":"4226536260","pt":1631449768468,"mc":[{"id":"1.187552454","rc":[{"batb":[[2,5.5,13.33]],"batl":[[0,7,24.64],[1,7.2,146.09],[2,7.4,141.79]],"ltp":4.9,"tv":4027.78,"id":9345630},{"batb":[[0,1.19,5.32],[1,1.18,914.36],[2,1.17,908.01]],"batl":[[2,1.22,60]],"ltp":1.27,"tv":49001.41,"id":9028621}]}]}
{"op":"mcm","clk":"4226536404","pt":1631449769486,"mc":[{"id":"1.187552454","rc":[{"batb":[[2,5.2,2]],"batl":[[0,7.2,146.24],[1,7.4,141.79],[2,7.6,141.79]],"ltp":4.9,"tv":4027.78,"id":9345630},{"batb":[[1,1.18,971.35],[2,1.17,871.63]],"ltp":1.27,"tv":49001.41,"id":9028621}]}]}
{"op":"mcm","clk":"4226536487","pt":1631449770071,"mc":[{"id":"1.187552454","rc":[{"batl":[[0,6.4,3.9],[1,7,20.18],[2,7.2,146.09]],"ltp":4.9,"tv":4027.78,"id":9345630}]}]}
{"op":"mcm","clk":"4226536780","pt":1631449772368,"mc":[{"id":"1.187552454","rc":[{"trd":[[6.2,0.15]],"batb":[[0,5.9,34.6]],"batl":[[0,6.4,3.75]],"ltp":6.2,"tv":4027.92,"id":9345630},{"trd":[[1.18,196.64],[1.19,454.04]],"batb":[[0,1.18,935.88],[1,1.17,871.63],[2,1.15,95.4]],"ltp":1.18,"tv":49083.74,"id":9028621}],"tv":53111.67}]}
{"op":"mcm","clk":"4226536908","pt":1631449773270,"mc":[{"id":"1.187552454","rc":[{"trd":[[1.18,254.06]],"batb":[[0,1.18,907.17],[1,1.17,908.01]],"ltp":1.18,"tv":49141.16,"id":9028621}],"tv":53169.09}]}
{"op":"mcm","clk":"4226536961","pt":1631449773640,"mc":[{"id":"1.187552454","rc":[{"batb":[[2,1.15,95.23]],"ltp":1.18,"tv":49141.16,"id":9028621}]}]}
{"op":"mcm","clk":"4226537148","pt":1631449775352,"mc":[{"id":"1.187552454","rc":[{"batb":[[1,5.7,36.11]],"batl":[[1,6.8,24.91],[2,7,20.18]],"ltp":6.2,"tv":4027.92,"id":9345630}]}]}
{"op":"mcm","clk":"4226537989","pt":1631449782382,"mc":[{"id":"1.187552454","rc":[{"trd":[[1.2,516.36]],"batl":[[0,1.2,294.1]],"ltp":1.2,"tv":49151.15,"id":9028621}],"tv":53179.07}]}
{"op":"mcm","clk":"4226538716","pt":1631449788162,"mc":[{"id":"1.187552454","rc":[{"trd":[[1.2,520.26]],"batl":[[0,1.2,292.15]],"ltp":1.2,"tv":49155.04,"id":9028621}],"tv":53182.97}]}
{"op":"mcm","clk":"4226538863","pt":1631449789383,"mc":[{"id":"1.187552454","rc":[{"trd":[[1.2,520.59]],"batl":[[0,1.2,291.98]],"ltp":1.2,"tv":49155.38,"id":9028621}],"tv":53183.31}]}
{"op":"mcm","clk":"4226538978","pt":1631449790455,"mc":[{"id":"1.187552454","rc":[{"trd":[[1.2,521.48]],"batl":[[0,1.2,291.53]],"ltp":1.2,"tv":49156.27,"id":9028621}],"tv":53184.2}]}
{"op":"mcm","clk":"4226539220","pt":1631449792385,"mc":[{"id":"1.187552454","rc":[{"batb":[[0,5.7,12.76],[1,5,2],[2,4.7,2]],"batl":[[0,6.8,24.91],[1,11,2],[2,18,2]],"ltp":6.2,"tv":4027.92,"id":9345630},{"batb":[[0,1.17,36.38],[1,1.13,6.99],[2,1.11,594.32]],"batl":[[0,1.22,60],[1,1.25,46.38],[2,1.26,43.25]],"ltp":1.2,"tv":49156.27,"id":9028621}]}]}
{"op":"mcm","clk":"4226539351","pt":1631449793489,"mc":[{"id":"1.187552454","rc":[{"batb":[[0,4.7,2],[1,4.5,2],[2,1.01,30]],"batl":[[0,11,2],[1,18,2],[2,21,2]],"ltp":6.2,"tv":4027.92,"id":9345630},{"batb":[[0,1.13,6.99],[1,1.11,594.32],[2,1.1,104.74]],"batl":[[0,1.18,4.25],[1,1.27,10],[2,1.28,45.09]],"ltp":1.2,"tv":49156.27,"id":9028621}]}]}
{"op":"mcm","clk":"4226539396","pt":1631449793878,"mc":[{"id":"1.187552454","rc":[{"batl":[[1,1.26,9.75],[2,1.27,10]],"ltp":1.2,"tv":49156.27,"id":9028621}]}]}
{"op":"mcm","clk":"4226539757","pt":1631449797095,"mc":[{"id":"1.187552454","rc":[{"batb":[[0,4.8,3],[1,4.7,2],[2,4.6,2]],"batl":[[0,10.5,2],[1,11,2],[2,18,2]],"ltp":6.2,"tv":4027.92,"id":9345630}]}]}
{"op":"mcm","clk":"4226539936","pt":1631449798493,"mc":[{"id":"1.187552454","rc":[{"batb":[[0,1.17,741.4],[1,1.16,1063.51],[2,1.13,6.99]],"batl":[[1,1.19,566.22],[2,1.2,819.67]],"ltp":1.2,"tv":49156.27,"id":9028621}]}]}
{"op":"mcm","clk":"4226540044","pt":1631449799387,"mc":[{"id":"1.187552454","rc":[{"batb":[[0,5,2],[1,4.9,2],[2,4.8,3]],"ltp":6.2,"tv":4027.92,"id":9345630}]}]}
{"op":"mcm","clk":"4226540125","pt":1631449800007,"mc":[{"id":"1.187552454","rc":[{"batb":[[0,5.4,10],[1,5,4],[2,4.9,2]],"batl":[[0,8,10],[1,10.5,2],[2,11,2]],"ltp":6.2,"tv":4027.92,"id":9345630}]}]}
{"op":"mcm","clk":"4226540301","pt":1631449801119,"mc":[{"id":"1.187552454","rc":[{"batb":[[2,1.13,25.51]],"batl":[[0,1.18,224.13]],"ltp":1.2,"tv":49156.27,"id":9028621}]}]}
{"op":"mcm","clk":"4226540518","pt":1631449802503,"mc":[{"id":"1.187552454","rc":[{"batb":[[0,5,4],[1,4.9,2],[2,4.8,3]],"batl":[[0,10.5,2],[1,11,2],[2,18,2]],"ltp":6.2,"tv":4027.92,"id":9345630},{"trd":[[1.17,1342.45],[1.18,500.07]],"batb":[[0,1.17,705.25]],"batl":[[0,1.18,101.13]],"ltp":1.17,"tv":49474.58,"id":9028621}],"tv":53502.5}]}
{"op":"mcm","clk":"4226540656","pt":1631449803415,"mc":[{"id":"1.187552454","rc":[{"trd":[[6.4,21.55]],"ltp":6.4,"tv":4028.11,"id":9345630},{"trd":[[1.18,501.1]],"batb":[[0,1.13,25.51],[1,1.11,594.32],[2,1.1,104.74]],"batl":[[0,1.18,100.09],[1,1.2,39.73],[2,1.25,51.74]],"ltp":1.18,"tv":49475.61,"id":9028621}],"tv":53503.73}]}
{"op":"mcm","clk":"4226540761","pt":1631449804015,"mc":[{"id":"1.187552454","rc":[{"batl":[[1,1.2,60.55]],"ltp":1.18,"tv":49475.61,"id":9028621}]}]}
{"op":"mcm","clk":"4226541045","pt":1631449805796,"mc":[{"id":"1.187552454","rc":[{"batb":[[1,1.12,1567.32],[2,1.11,905.77]],"batl":[[1,1.2,20.82]],"ltp":1.18,"tv":49475.61,"id":9028621}]}]}
{"op":"mcm","clk":"4226541636","pt":1631449810023,"mc":[{"id":"1.187552454","rc":[{"batb":[[0,5,2],[2,4.5,2]],"ltp":6.4,"tv":4028.11,"id":9345630},{"batl":[[0,1.26,568.43],[1,1.27,588.26],[2,1.28,45.09]],"ltp":1.18,"tv":49475.61,"id":9028621}]}]}
{"op":"mcm","clk":"4226541836","pt":1631449811310,"mc":[{"id":"1.187552454","rc":[{"batb":[[1,4.5,2],[2,1.01,30]],"ltp":6.4,"tv":4028.11,"id":9345630},{"trd":[[1.13,31.91]],"batb":[[0,1.13,9.6]],"ltp":1.13,"tv":49507.43,"id":9028621}],"tv":53535.54}]}
{"op":"mcm","clk":"4226542106","pt":1631449813299,"mc":[{"id":"1.187552454","rc":[{"batb":[[0,5,4]],"ltp":6.4,"tv":4028.11,"id":9345630},{"batl":[[0,1.25,62.34],[1,1.26,576.43],[2,1.27,588.26]],"ltp":1.13,"tv":49507.43,"id":9028621}]}]}
{"op":"mcm","clk":"4226542265","pt":1631449814519,"mc":[{"id":"1.187552454","rc":[{"batb":[[0,5,2],[1,4.9,2],[2,4.5,2]],"ltp":6.4,"tv":4028.11,"id":9345630},{"batl":[[0,1.25,11]],"ltp":1.13,"tv":49507.43,"id":9028621}]}]}
{"op":"mcm","clk":"4226542415","pt":1631449815595,"mc":[{"id":"1.187552454","rc":[{"batb":[[0,1.13,10.38]],"ltp":1.13,"tv":49507.43,"id":9028621}]}]}
{"op":"mcm","clk":"4226542440","pt":1631449815808,"mc":[{"id":"1.187552454","rc":[{"batb":[[0,1.12,1568.09],[1,1.11,905.77],[2,1.1,104.74]],"ltp":1.13,"tv":49507.43,"id":9028621}]}]}
{"op":"mcm","clk":"4226542585","pt":1631449816923,"mc":[{"id":"1.187552454","rc":[{"batb":[[0,5,4]],"ltp":6.4,"tv":4028.11,"id":9345630},{"batl":[[0,1.25,56.18]],"ltp":1.13,"tv":49507.43,"id":9028621}]}]}
{"op":"mcm","clk":"4226542727","pt":1631449817845,"mc":[{"id":"1.187552454","rc":[{"batb":[[0,5,2]],"ltp":6.4,"tv":4028.11,"id":9345630},{"batl":[[0,1.25,11]],"ltp":1.13,"tv":49507.43,"id":9028621}]}]}
{"op":"mcm","clk":"4226542833","pt":1631449818669,"mc":[{"id":"1.187552454","rc":[{"trd":[[1.18,502.64]],"batb":[[0,1.11,594.32],[1,1.1,104.74],[2,1.08,167.31]],"batl":[[0,1.13,99.23],[1,1.25,11],[2,1.26,576.43]],"ltp":1.18,"tv":49508.97,"id":9028621}],"tv":53537.09}]}
{"op":"mcm","clk":"4226543062","pt":1631449820521,"mc":[{"id":"1.187552454","rc":[{"trd":[[8.6,8.54]],"batb":[[0,7.8,12.26],[1,7.6,11.9],[2,7.4,11.9]],"ltp":8.6,"tv":4036.65,"id":9345630},{"trd":[[1.13,96.91]],"batb":[[0,1.11,7.92]],"batl":[[0,1.13,34.23],[1,1.26,568.43],[2,1.27,588.26]],"ltp":1.13,"tv":49573.97,"id":9028621}],"tv":53610.63}]}
{"op":"mcm","clk":"4226543199","pt":1631449821508,"mc":[{"id":"1.187552454","rc":[{"trd":[[7.4,11.9],[7.6,14.72],[7.8,12.26]],"batb":[[0,5,2],[1,4.5,473.06],[2,4.4,457.21]],"batl":[[0,5.8,2.02],[1,10.5,2],[2,11,2]],"ltp":7.4,"tv":4072.71,"id":9345630},{"trd":[[1.13,165.37],[1.15,130.97],[1.16,395.63]],"batb":[[0,1.23,1554.88],[1,1.22,1256.68],[2,1.21,1538.84]],"batl":[[0,1.25,46.74]],"ltp":1.16,"tv":49879.46,"id":9028621}],"tv":53952.18}]}
{"op":"mcm","clk":"4226543301","pt":1631449822341,"mc":[{"id":"1.187552454","rc":[{"batb":[[0,4.5,46.28],[1,4.4,228.6],[2,4.3,228.6]],"batl":[[0,5.3,2]],"ltp":7.4,"tv":4072.71,"id":9345630},{"batb":[[0,1.23,1692.16],[1,1.22,1538.42],[2,1.21,762.57]],"batl":[[0,1.26,568.43],[1,1.27,588.26],[2,1.28,57.56]],"ltp":1.16,"tv":49879.46,"id":9028621}]}]}
{"op":"mcm","clk":"4226543433","pt":1631449823533,"mc":[{"id":"1.187552454","rc":[{"batb":[[0,4.9,15.38],[1,4.5,46.28],[2,4.4,228.6]],"batl":[[1,6,26.83],[2,8.6,2]],"ltp":7.4,"tv":4072.71,"id":9345630}]}]}
{"op":"mcm","clk":"4226543496","pt":1631449824047,"mc":[{"id":"1.187552454","rc":[{"batb":[[0,4.5,46.28],[1,4.4,228.6],[2,4.3,228.6]],"batl":[[1,8.6,2],[2,10.5,2]],"ltp":7.4,"tv":4072.71,"id":9345630},{"batl":[[0,1.26,558.68]],"ltp":1.16,"tv":49879.46,"id":9028621}]}]}
{"op":"mcm","clk":"4226543635","pt":1631449825124,"mc":[{"id":"1.187552454","rc":[{"batb":[[0,4.6,26.78],[1,4.5,46.28],[2,4.4,228.6]],"ltp":7.4,"tv":4072.71,"id":9345630},{"batb":[[0,1.23,1752.05]],"batl":[[0,1.26,613.96]],"ltp":1.16,"tv":49879.46,"id":9028621}]}]}
{"op":"mcm","clk":"4226543919","pt":1631449827240,"mc":[{"id":"1.187552454","rc":[{"batb":[[0,4.8,15.78]],"ltp":7.4,"tv":4072.71,"id":9345630},{"batb":[[2,1.21,795.3]],"ltp":1.16,"tv":49879.46,"id":9028621}]}]}
{"op":"mcm","clk":"4226544056","pt":1631449828235,"mc":[{"id":"1.187552454","rc":[{"batb":[[1,4.6,610.06],[2,4.5,46.28]],"batl":[[0,5.3,12],[1,7.4,2],[2,8.6,2]],"ltp":7.4,"tv":4072.71,"id":9345630}]}]}
{"op":"mcm","clk":"4226544121","pt":1631449828718,"mc":[{"id":"1.187552454","rc":[{"batb":[[0,1.24,97.62],[1,1.23,1752.05],[2,1.22,1538.42]],"ltp":1.16,"tv":49879.46,"id":9028621}]}]}
{"op":"mcm","clk":"4226544324","pt":1631449830428,"mc":[{"id":"1.187552454","rc":[{"batb":[[0,4.8,42.56]],"batl":[[1,5.7,27.67],[2,7.4,2]],"ltp":7.4,"tv":4072.71,"id":9345630}]}]}
{"op":"mcm","clk":"4226544642","pt":1631449832447,"mc":[{"id":"1.187552454","rc":[{"batb":[[1,4.5,46.28],[2,4.4,230.6]],"ltp":7.4,"tv":4072.71,"id":9345630}]}]}
{"op":"mcm","clk":"4226544667","pt":1631449832657,"mc":[{"id":"1.187552454","rc":[{"trd":[[1.24,3756.96]],"batb":[[0,1.24,97.38]],"ltp":1.24,"tv":49879.95,"id":9028621}],"tv":53952.67}]}
{"op":"mcm","clk":"4226545114","pt":1631449835839,"mc":[{"id":"1.187552454","rc":[{"trd":[[5.2,41.13]],"ltp":5.2,"tv":4086.84,"id":9345630},{"trd":[[1.24,3816.2]],"batb":[[0,1.24,38.14]],"ltp":1.24,"tv":49939.19,"id":9028621}],"tv":54026.03}]}
{"op":"mcm","clk":"4226545452","pt":1631449838547,"mc":[{"id":"1.187552454","rc":[{"trd":[[1.26,367.71]],"batl":[[0,1.25,39.73],[1,1.26,609.71],[2,1.27,588.26]],"ltp":1.26,"tv":49947.69,"id":9028621}],"tv":54034.54}]}
{"op":"mcm","clk":"4226545540","pt":1631449839131,"mc":[{"id":"1.187552454","rc":[{"trd":[[1.25,1229.26]],"batb":[[0,1.25,62.45],[1,1.24,38.14],[2,1.23,1752.05]],"batl":[[0,1.26,609.71],[1,1.27,588.26],[2,1.28,57.56]],"ltp":1.25,"tv":50068.79,"id":9028621}],"tv":54155.63}]}
{"op":"mcm","clk":"4226545701","pt":1631449840246,"mc":[{"id":"1.187552454","rc":[{"trd":[[1.25,1230.26]],"batb":[[0,1.25,61.95]],"ltp":1.25,"tv":50069.79,"id":9028621}],"tv":54156.63}]}
{"op":"mcm","clk":"4226546227","pt":1631449844147,"mc":[{"id":"1.187552454","rc":[{"trd":[[1.25,1231.85]],"batb":[[0,1.25,61.16]],"ltp":1.25,"tv":50071.37,"id":9028621}],"tv":54158.22}]}
{"op":"mcm","clk":"4226546480","pt":1631449846097,"mc":[{"id":"1.187552454","rc":[{"batb":[[0,1.24,38.14],[1,1.23,1752.05],[2,1.22,1538.42]],"ltp":1.25,"tv":50071.37,"id":9028621}]}]}
{"op":"mcm","clk":"4226546952","pt":1631449849903,"mc":[{"id":"1.187552454","rc":[{"batb":[[0,4.8,28.58]],"ltp":5.2,"tv":4086.84,"id":9345630},{"batl":[[0,1.26,568.68]],"ltp":1.25,"tv":50071.37,"id":9028621}]}]}
{"op":"mcm","clk":"4226547147","pt":1631449851425,"mc":[{"id":"1.187552454","rc":[{"batb":[[0,4.8,15.78],[1,4.4,2],[2,4.3,2]],"batl":[[0,5.3,2]],"ltp":5.2,"tv":4086.84,"id":9345630},{"batb":[[1,1.21,40.73],[2,1.18,13.52]],"batl":[[0,1.26,60],[1,1.27,10],[2,1.28,12.47]],"ltp":1.25,"tv":50071.37,"id":9028621}]}]}
{"op":"mcm","clk":"4226547298","pt":1631449852596,"mc":[{"id":"1.187552454","rc":[{"batb":[[0,4.2,2],[1,1.01,30],[2,4.3,0]],"batl":[[0,7.4,2],[1,9.4,2],[2,10.5,2]],"ltp":5.2,"tv":4086.84,"id":9345630},{"batb":[[1,1.16,80.78],[2,1.15,509.02]],"batl":[[0,1.27,10],[1,1.31,42.5],[2,1.34,13.01]],"ltp":1.25,"tv":50071.37,"id":9028621}]}]}
{"op":"mcm","clk":"4226547576","pt":1631449854407,"mc":[{"id":"1.187552454","rc":[{"batb":[[1,1.18,813.21],[2,1.17,975.66]],"batl":[[1,1.31,454],[2,1.32,473.22]],"ltp":1.25,"tv":50071.37,"id":9028621}]}]}
{"op":"mcm","clk":"4226547749","pt":1631449855682,"mc":[{"id":"1.187552454","rc":[{"batb":[[0,4.7,2],[1,4.6,3],[2,4.2,2]],"ltp":5.2,"tv":4086.84,"id":9345630},{"batb":[[0,1.18,813.21],[1,1.17,975.66],[2,1.16,80.78]],"ltp":1.25,"tv":50071.37,"id":9028621}]}]}
{"op":"mcm","clk":"4226548092","pt":1631449858528,"mc":[{"id":"1.187552454","rc":[{"batb":[[2,4.4,2]],"ltp":5.2,"tv":4086.84,"id":9345630},{"batl":[[1,1.29,47.5],[2,1.31,454]],"ltp":1.25,"tv":50071.37,"id":9028621}]}]}
{"op":"mcm","clk":"4226548146","pt":1631449858914,"mc":[{"id":"1.187552454","rc":[{"batb":[[2,4.2,2]],"ltp":5.2,"tv":4086.84,"id":9345630},{"batl":[[1,1.31,454],[2,1.32,473.22]],"ltp":1.25,"tv":50071.37,"id":9028621}]}]}
{"op":"mcm","clk":"4226548479","pt":1631449861498,"mc":[{"id":"1.187552454","rc":[{"trd":[[4.6,3],[4.7,44.6]],"batb":[[0,4.2,2],[1,1.01,30],[2,4.2,0]],"ltp":4.6,"tv":4091.84,"id":9345630},{"trd":[[1.27,2621.23],[1.28,384.47]],"batb":[[0,1.28,21.91],[1,1.26,1.99],[2,1.18,813.21]],"batl":[[0,1.31,454],[1,1.32,473.22],[2,1.34,13.01]],"ltp":1.28,"tv":50125.1,"id":9028621}],"tv":54216.94}]}
{"op":"mcm","clk":"4226548727","pt":1631449863252,"mc":[{"id":"1.187552454","rc":[{"batb":[[0,1.26,1.99],[1,1.18,813.21],[2,1.17,975.66]],"ltp":1.28,"tv":50125.1,"id":9028621}]}]}
{"op":"mcm","clk":"4226549019","pt":1631449865316,"mc":[{"id":"1.187552454","rc":[{"batb":[[0,4.5,3],[1,4.4,2],[2,4.3,3]],"ltp":4.6,"tv":4091.84,"id":9345630},{"batl":[[0,1.29,8],[1,1.3,9],[2,1.31,463]],"ltp":1.28,"tv":50125.1,"id":9028621}]}]}
{"op":"mcm","clk":"4226549567","pt":1631449869200,"mc":[{"id":"1.187552454","rc":[{"batb":[[1,4.4,4]],"ltp":4.6,"tv":4091.84,"id":9345630},{"batl":[[0,1.29,51.5]],"ltp":1.28,"tv":50125.1,"id":9028621}]}]}
{"op":"mcm","clk":"4226549741","pt":1631449870343,"mc":[{"id":"1.187552454","rc":[{"batb":[[1,4.4,2]],"ltp":4.6,"tv":4091.84,"id":9345630},{"batl":[[0,1.29,8]],"ltp":1.28,"tv":50125.1,"id":9028621}]}]}
{"op":"mcm","clk":"4226550195","pt":1631449873348,"mc":[{"id":"1.187552454","rc":[{"batl":[[0,4.7,20.35],[1,4.8,19.75],[2,4.9,19.75]],"ltp":4.6,"tv":4091.84,"id":9345630},{"batb":[[1,1.15,509.02],[2,1.12,112.45]],"ltp":1.28,"tv":50125.1,"id":9028621}]}]}
{"op":"mcm","clk":"4226550322","pt":1631449874255,"mc":[{"id":"1.187552454","rc":[{"trd":[[4.5,16.4]],"batb":[[0,4.2,2],[1,4.1,3],[2,1.01,30]],"batl":[[0,4.5,5.54],[1,4.7,20.35],[2,4.8,19.75]],"ltp":4.5,"tv":4097.84,"id":9345630},{"batl":[[0,1.31,454],[1,1.32,473.22],[2,1.34,13.01]],"ltp":1.28,"tv":50125.1,"id":9028621}],"tv":54222.94}]}
{"op":"mcm","clk":"4226550513","pt":1631449875554,"mc":[{"id":"1.187552454","rc":[{"batl":[[1,4.7,427.27],[2,4.8,414.7]],"ltp":4.5,"tv":4097.84,"id":9345630},{"batb":[[0,1.28,11269.86],[1,1.26,1.99],[2,1.25,27.81]],"batl":[[2,1.33,1685.03]],"ltp":1.28,"tv":50125.1,"id":9028621}]}]}
{"op":"mcm","clk":"4226550665","pt":1631449876350,"mc":[{"id":"1.187552454","rc":[{"batl":[[1,4.7,223.81],[2,4.8,217.23]],"ltp":4.5,"tv":4097.84,"id":9345630},{"batb":[[0,1.28,731.97],[1,1.27,607.16],[2,1.26,1.99]],"batl":[[1,1.32,485.31],[2,1.33,842.51]],"ltp":1.28,"tv":50125.1,"id":9028621}]}]}
{"op":"mcm","clk":"4226550839","pt":1631449877435,"mc":[{"id":"1.187552454","rc":[{"trd":[[4.4,26.26],[4.5,23.47]],"batb":[[0,4.2,20.75]],"batl":[[0,4.5,2.01]],"ltp":4.5,"tv":4108.91,"id":9345630},{"batb":[[1,1.27,625.11]],"batl":[[0,1.31,514]],"ltp":1.28,"tv":50125.1,"id":9028621}],"tv":54234.02}]}
{"op":"mcm","clk":"4226550890","pt":1631449877752,"mc":[{"id":"1.187552454","rc":[{"batb":[[1,1.27,615.16]],"ltp":1.28,"tv":50125.1,"id":9028621}]}]}
{"op":"mcm","clk":"4226551406","pt":1631449881089,"mc":[{"id":"1.187552454","rc":[{"batb":[[0,1.28,781.33]],"ltp":1.28,"tv":50125.1,"id":9028621}]}]}
{"op":"mcm","clk":"4226551551","pt":1631449881953,"mc":[{"id":"1.187552454","rc":[{"batb":[[2,4,2]],"ltp":4.5,"tv":4108.91,"id":9345630},{"batl":[[2,1.33,879.01]],"ltp":1.28,"tv":50125.1,"id":9028621}]}]}
{"op":"mcm","clk":"4226551684","pt":1631449882759,"mc":[{"id":"1.187552454","rc":[{"batl":[[0,4.5,2.21]],"ltp":4.5,"tv":4108.91,"id":9345630},{"batl":[[0,1.3,2198.76],[1,1.31,514],[2,1.32,485.31]],"ltp":1.28,"tv":50125.1,"id":9028621}]}]}
{"op":"mcm","clk":"4226551940","pt":1631449884359,"mc":[{"id":"1.187552454","rc":[{"batl":[[0,4.7,224.01],[1,4.8,217.23],[2,4.9,247.61]],"ltp":4.5,"tv":4108.91,"id":9345630},{"trd":[[1.28,602.19]],"batb":[[0,1.28,672.47],[2,1.26,31.4]],"ltp":1.28,"tv":50342.82,"id":9028621}],"tv":54451.74}]}
{"op":"mcm","clk":"4226552214","pt":1631449886072,"mc":[{"id":"1.187552454","rc":[{"trd":[[1.28,604.14]],"batb":[[0,1.28,671.49]],"ltp":1.28,"tv":50344.78,"id":9028621}],"tv":54453.69}]}
{"op":"mcm","clk":"4226552818","pt":1631449890362,"mc":[{"id":"1.187552454","rc":[{"trd":[[4.5,23.87],[4.6,9.19]],"batl":[[0,4.6,15.45],[1,4.7,223.81],[2,4.8,217.23]],"ltp":4.6,"tv":4115.5,"id":9345630},{"trd":[[1.28,626.39]],"batb":[[0,1.28,649.24],[2,1.26,29.41]],"ltp":1.28,"tv":50367.03,"id":9028621}],"tv":54482.53}]}
{"op":"mcm","clk":"4226552916","pt":1631449891065,"mc":[{"id":"1.187552454","rc":[{"trd":[[1.3,400.72]],"batl":[[0,1.3,2198.36]],"ltp":1.3,"tv":50367.82,"id":9028621}],"tv":54483.32}]}
{"op":"mcm","clk":"4226553001","pt":1631449891664,"mc":[{"id":"1.187552454","rc":[{"batb":[[0,1.29,43.98],[1,1.28,649.24],[2,1.27,615.16]],"ltp":1.3,"tv":50367.82,"id":9028621}]}]}
{"op":"mcm","clk":"4226553673","pt":1631449896785,"mc":[{"id":"1.187552454","rc":[{"batl":[[0,1.31,514],[1,1.32,485.31],[2,1.33,879.01]],"ltp":1.3,"tv":50367.82,"id":9028621}]}]}
{"op":"mcm","clk":"4226553892","pt":1631449898596,"mc":[{"id":"1.187552454","rc":[{"batb":[[0,4.2,18.75],[2,3.85,2]],"batl":[[0,4.9,30.38],[1,5.6,2],[2,6.6,2]],"ltp":4.6,"tv":4115.5,"id":9345630},{"batb":[[0,1.29,44.17],[1,1.27,8],[2,1.26,29.41]],"batl":[[0,1.31,60],[1,1.32,12.09],[2,1.34,18.97]],"ltp":1.3,"tv":50367.82,"id":9028621}]}]}
{"op":"mcm","clk":"4226554015","pt":1631449899460,"mc":[{"id":"1.187552454","rc":[{"batb":[[0,3.85,2],[1,1.01,30],[2,3.85,0]],"batl":[[0,5.6,2],[1,6.6,2],[2,10.5,2]],"ltp":4.6,"tv":4115.5,"id":9345630},{"batb":[[1,1.22,50.34],[2,1.2,1.71]],"batl":[[0,1.34,13.01],[1,1.35,34.5],[2,1.47,896.39]],"ltp":1.3,"tv":50367.82,"id":9028621}]}]}
{"op":"mcm","clk":"4226554167","pt":1631449900471,"mc":[{"id":"1.187552454","rc":[{"batb":[[0,3.9,2],[1,3.85,2],[2,3.75,2]],"ltp":4.6,"tv":4115.5,"id":9345630},{"batl":[[0,1.34,49.76],[2,1.36,36.57]],"ltp":1.3,"tv":50367.82,"id":9028621}]}]}
{"op":"mcm","clk":"4226554305","pt":1631449901484,"mc":[{"id":"1.187552454","rc":[{"batb":[[0,4,2]],"ltp":4.6,"tv":4115.5,"id":9345630},{"batb":[[0,1.3,2.19],[1,1.29,43.98],[2,1.23,808.58]],"batl":[[0,1.33,40.5],[1,1.34,13.01],[2,1.35,34.5]],"ltp":1.3,"tv":50367.82,"id":9028621}]}]}
{"op":"mcm","clk":"4226554346","pt":1631449901865,"mc":[{"id":"1.187552454","rc":[{"batb":[[0,3.85,2],[1,3.75,2],[2,1.01,30]],"ltp":4.6,"tv":4115.5,"id":9345630},{"batl":[[0,1.34,13.01],[1,1.35,34.5],[2,1.36,618.52]],"ltp":1.3,"tv":50367.82,"id":9028621}]}]}
{"op":"mcm","clk":"4226554548","pt":1631449902777,"mc":[{"id":"1.187552454","rc":[{"batb":[[0,3.9,2],[1,3.85,5],[2,3.75,2]],"ltp":4.6,"tv":4115.5,"id":9345630},{"batl":[[0,1.34,21.01]],"ltp":1.3,"tv":50367.82,"id":9028621}]}]}
{"op":"mcm","clk":"4226554721","pt":1631449903987,"mc":[{"id":"1.187552454","rc":[{"batb":[[2,3.8,3]],"batl":[[2,11,2]],"ltp":4.6,"tv":4115.5,"id":9345630},{"batb":[[1,1.22,50.34],[2,1.2,1.71]],"ltp":1.3,"tv":50367.82,"id":9028621}]}]}
{"op":"mcm","clk":"4226555105","pt":1631449906597,"mc":[{"id":"1.187552454","rc":[{"trd":[[3.9,20.7]],"batb":[[0,3.85,2],[1,3.75,2],[2,3.65,617.2]],"batl":[[0,4.5,2.55],[1,5.6,2],[2,6.6,2]],"ltp":3.9,"tv":4126.04,"id":9345630},{"trd":[[1.34,14511.35]],"batb":[[0,1.32,1521.3],[1,1.31,1476.56],[2,1.3,1478.75]],"batl":[[0,1.35,34.5],[1,1.36,618.52],[2,1.37,393.6]],"ltp":1.34,"tv":50386.86,"id":9028621}],"tv":54512.91}]}
{"op":"mcm","clk":"4226555239","pt":1631449907485,"mc":[{"id":"1.187552454","rc":[{"batb":[[2,3.65,72.81]],"ltp":3.9,"tv":4126.04,"id":9345630},{"trd":[[1.32,243.78]],"batb":[[0,1.32,1473.08],[1,1.31,1286.86],[2,1.3,775.63]],"batl":[[1,1.36,630.25]],"ltp":1.32,"tv":50391.86,"id":9028621}],"tv":54517.91}]}
{"op":"mcm","clk":"4226555374","pt":1631449908459,"mc":[{"id":"1.187552454","rc":[{"trd":[[3.85,27.15]],"batb":[[0,3.75,23.81],[1,3.65,72.81],[2,3.6,299.53]],"batl":[[0,4.3,33.02],[1,4.5,2.55],[2,5.6,2]],"ltp":3.85,"tv":4134.04,"id":9345630},{"trd":[[1.35,1038.54]],"batb":[[2,1.3,803.01]],"batl":[[0,1.35,9.09],[2,1.37,453.6]],"ltp":1.35,"tv":50431.27,"id":9028621}],"tv":54565.32}]}
{"op":"mcm","clk":"4226555788","pt":1631449911482,"mc":[{"id":"1.187552454","rc":[{"batb":[[0,3.75,33.81]],"batl":[[2,4.7,73.22]],"ltp":3.85,"tv":4134.04,"id":9345630},{"batb":[[0,1.32,1524.73],[2,1.3,775.63]],"ltp":1.35,"tv":50431.27,"id":9028621}]}]}
{"op":"mcm","clk":"4226555857","pt":1631449911973,"mc":[{"id":"1.187552454","rc":[{"batl":[[2,5.6,2]],"ltp":3.85,"tv":4134.04,"id":9345630},{"trd":[[1.32,301.63]],"batb":[[0,1.32,1495.81]],"ltp":1.32,"tv":50489.11,"id":9028621}],"tv":54623.16}]}
{"op":"mcm","clk":"4226556087","pt":1631449913471,"mc":[{"id":"1.187552454","rc":[{"batb":[[0,1.32,1496.64],[2,1.3,773.64]],"ltp":1.32,"tv":50489.11,"id":9028621}]}]}
{"op":"mcm","clk":"4226556190","pt":1631449914200,"mc":[{"id":"1.187552454","rc":[{"batl":[[0,4.2,21.79],[1,4.3,33.02],[2,4.5,2.55]],"ltp":3.85,"tv":4134.04,"id":9345630},{"batb":[[1,1.31,1313.8]],"ltp":1.32,"tv":50489.11,"id":9028621}]}]}
{"op":"mcm","clk":"4226556341","pt":1631449915190,"mc":[{"id":"1.187552454","rc":[{"batb":[[0,3.85,4.97],[1,3.75,33.81],[2,3.65,72.81]],"ltp":3.85,"tv":4134.04,"id":9345630}]}]}
{"op":"mcm","clk":"4226556424","pt":1631449915708,"mc":[{"id":"1.187552454","rc":[{"batb":[[0,1.34,250.83],[1,1.32,1495.81],[2,1.31,1313.8]],"ltp":1.32,"tv":50489.11,"id":9028621}]}]}
{"op":"mcm","clk":"4226556683","pt":1631449917311,"mc":[{"id":"1.187552454","rc":[{"batb":[[0,1.34,250]],"ltp":1.32,"tv":50489.11,"id":9028621}]}]}
{"op":"mcm","clk":"4226557010","pt":1631449919406,"mc":[{"id":"1.187552454","rc":[{"batb":[[1,1.33,48.81],[2,1.32,1495.81]],"ltp":1.32,"tv":50489.11,"id":9028621}]}]}
{"op":"mcm","clk":"4226557133","pt":1631449920207,"mc":[{"id":"1.187552454","rc":[{"trd":[[3.85,46.16]],"batb":[[0,3.75,33.81],[1,3.65,72.81],[2,3.6,299.53]],"ltp":3.85,"tv":4153.04,"id":9345630},{"trd":[[1.35,1064.39]],"batl":[[0,1.35,2181.99]],"ltp":1.35,"tv":50514.97,"id":9028621}],"tv":54668.02}]}
{"op":"mcm","clk":"4226557347","pt":1631449921543,"mc":[{"id":"1.187552454","rc":[{"trd":[[1.35,1068.37]],"batl":[[0,1.35,2180.01]],"ltp":1.35,"tv":50518.94,"id":9028621}],"tv":54671.99}]}
{"op":"mcm","clk":"4226557405","pt":1631449921931,"mc":[{"id":"1.187552454","rc":[{"trd":[[3.85,46.25]],"ltp":3.85,"tv":4153.14,"id":9345630},{"trd":[[1.35,1068.65]],"batl":[[0,1.35,2179.72]],"ltp":1.35,"tv":50519.23,"id":9028621}],"tv":54672.38}]}
{"op":"mcm","clk":"4226557825","pt":1631449924560,"mc":[{"id":"1.187552454","rc":[{"batb":[[0,3.9,3],[1,3.75,33.81],[2,3.65,72.81]],"ltp":3.85,"tv":4153.14,"id":9345630}]}]}
{"op":"mcm","clk":"4226557868","pt":1631449924851,"mc":[{"id":"1.187552454","rc":[{"trd":[[1.35,1080.05]],"batl":[[0,1.35,2174.02]],"ltp":1.35,"tv":50530.63,"id":9028621}],"tv":54683.77}]}
{"op":"mcm","clk":"4226558008","pt":1631449925648,"mc":[{"id":"1.187552454","rc":[{"trd":[[1.34,14527.26]],"batb":[[0,1.34,242.05]],"ltp":1.34,"tv":50546.53,"id":9028621}],"tv":54699.68}]}
{"op":"mcm","clk":"4226558357","pt":1631449928058,"mc":[{"id":"1.187552454","rc":[{"trd":[[1.34,14548.36],[1.35,1080.44]],"batb":[[0,1.34,231.5]],"batl":[[0,1.35,2173.83]],"ltp":1.35,"tv":50568.02,"id":9028621}],"tv":54721.17}]}
{"op":"mcm","clk":"4226558708","pt":1631449930434,"mc":[{"id":"1.187552454","rc":[{"trd":[[3.85,307.11],[3.9,26.7],[3.95,29.62]],"batb":[[0,3.75,33.81],[1,3.65,72.81],[2,3.6,299.53]],"ltp":3.95,"tv":4428.43,"id":9345630},{"trd":[[1.34,14590.73],[1.35,1824.35]],"batb":[[0,1.34,197.88]],"batl":[[0,1.35,1429.92]],"ltp":1.34,"tv":51354.3,"id":9028621}],"tv":55782.74}]}
{"op":"mcm","clk":"4226558868","pt":1631449931572,"mc":[{"id":"1.187552454","rc":[{"trd":[[1.34,14598.99],[1.35,1826.02]],"batb":[[0,1.34,193.75]],"batl":[[0,1.35,1429.09]],"ltp":1.34,"tv":51364.23,"id":9028621}],"tv":55792.67}]}
{"op":"mcm","clk":"4226558913","pt":1631449931848,"mc":[{"id":"1.187552454","rc":[{"trd":[[3.85,341.49]],"ltp":3.85,"tv":4462.82,"id":9345630},{"trd":[[1.35,1924.08]],"batl":[[0,1.35,1331.02]],"ltp":1.35,"tv":51462.29,"id":9028621}],"tv":55925.12}]}
{"op":"mcm","clk":"4226559178","pt":1631449933864,"mc":[{"id":"1.187552454","rc":[{"trd":[[1.34,14986.49]],"batb":[[0,1.33,48.81],[1,1.32,1495.81],[2,1.31,1313.8]],"batl":[[0,1.34,48.25],[1,1.35,1331.02],[2,1.36,630.25]],"ltp":1.34,"tv":51849.79,"id":9028621}],"tv":56312.62}]}
{"op":"mcm","clk":"4226559718","pt":1631449937945,"mc":[{"id":"1.187552454","rc":[{"trd":[[1.34,14989.83]],"batl":[[0,1.34,46.58]],"ltp":1.34,"tv":51853.13,"id":9028621}],"tv":56315.95}]}
{"op":"mcm","clk":"4226559837","pt":1631449938757,"mc":[{"id":"1.187552454","rc":[{"batl":[[0,1.35,1331.02],[1,1.36,630.25],[2,1.37,453.6]],"ltp":1.34,"tv":51853.13,"id":9028621}]}]}
{"op":"mcm","clk":"4226560125","pt":1631449940721,"mc":[{"id":"1.187552454","rc":[{"trd":[[1.35,1929.38]],"batl":[[0,1.35,1328.37]],"ltp":1.35,"tv":51858.43,"id":9028621}],"tv":56321.25}]}
{"op":"mcm","clk":"4226560600","pt":1631449943896,"mc":[{"id":"1.187552454","rc":[{"batb":[[1,1.32,817.1],[2,1.31,800.38]],"batl":[[1,1.36,36.57],[2,1.37,60]],"ltp":1.35,"tv":51858.43,"id":9028621}]}]}
{"op":"mcm","clk":"4226561052","pt":1631449947380,"mc":[{"id":"1.187552454","rc":[{"batl":[[0,1.34,219.88],[1,1.35,1328.37],[2,1.36,36.57]],"ltp":1.35,"tv":51858.43,"id":9028621}]}]}
{"op":"mcm","clk":"4226562229","pt":1631449955587,"mc":[{"id":"1.187552454","rc":[{"trd":[[1.34,15002.67]],"batl":[[0,1.34,213.46]],"ltp":1.34,"tv":51871.27,"id":9028621}],"tv":56334.09}]}
{"op":"mcm","clk":"4226562789","pt":1631449959182,"mc":[{"id":"1.187552454","rc":[{"trd":[[1.34,15022.31]],"batl":[[0,1.34,203.63]],"ltp":1.34,"tv":51890.92,"id":9028621}],"tv":56353.74}]}
{"op":"mcm","clk":"4226563258","pt":1631449962293,"mc":[{"id":"1.187552454","rc":[{"trd":[[1.33,351.21]],"batb":[[0,1.33,45.11]],"ltp":1.33,"tv":51898.33,"id":9028621}],"tv":56361.15}]}
{"op":"mcm","clk":"4226563791","pt":1631449965716,"mc":[{"id":"1.187552454","rc":[{"trd":[[1.34,15027.89]],"batl":[[0,1.34,200.85]],"ltp":1.34,"tv":51903.9,"id":9028621}],"tv":56366.73}]}
{"op":"mcm","clk":"4226564343","pt":1631449969401,"mc":[{"id":"1.187552454","rc":[{"trd":[[1.33,441.42]],"batb":[[0,1.32,817.1],[1,1.31,800.38],[2,1.3,773.64]],"batl":[[0,1.33,36.73],[1,1.34,200.85]],"ltp":1.33,"tv":51994.12,"id":9028621}],"tv":56456.94}]}
{"op":"mcm","clk":"4226564855","pt":1631449972887,"mc":[{"id":"1.187552454","rc":[{"batb":[[2,3.6,301.53]],"ltp":3.85,"tv":4462.82,"id":9345630}]}]}
{"op":"mcm","clk":"4226565461","pt":1631449977096,"mc":[{"id":"1.187552454","rc":[{"trd":[[4,0.1]],"ltp":4.0,"tv":4462.92,"id":9345630},{"trd":[[1.33,441.72]],"batl":[[0,1.33,36.43]],"ltp":1.33,"tv":51994.42,"id":9028621}],"tv":56457.34}]}
{"op":"mcm","clk":"4226565925","pt":1631449980516,"mc":[{"id":"1.187552454","rc":[{"batb":[[0,3.75,21.81],[1,3.6,2],[2,3.4,2]],"batl":[[0,4.3,33.02],[1,4.8,2],[2,990,0.01]],"ltp":4.0,"tv":4462.92,"id":9345630},{"batb":[[0,1.31,26.94],[1,1.29,539.04],[2,1.28,579.24]],"batl":[[0,1.32,5.12],[1,1.33,36.43],[2,1.37,60]],"ltp":1.33,"tv":51994.42,"id":9028621}]}]}
{"op":"mcm","clk":"4226566089","pt":1631449981509,"mc":[{"id":"1.187552454","rc":[{"batb":[[0,3.6,2],[1,3.4,2],[2,1.01,30]],"batl":[[0,4.8,2],[1,990,0.01],[2,990,0]],"ltp":4.0,"tv":4462.92,"id":9345630},{"batb":[[0,1.29,539.04],[1,1.28,579.24],[2,1.27,48.87]],"batl":[[1,1.38,33.25],[2,1.41,301.1]],"ltp":1.33,"tv":51994.42,"id":9028621}]}]}
{"op":"mcm","clk":"4226566133","pt":1631449981724,"mc":[{"id":"1.187552454","rc":[{"batb":[[0,3.4,2],[1,1.01,30],[2,1.01,0]],"ltp":4.0,"tv":4462.92,"id":9345630},{"batl":[[1,1.41,301.1],[2,1.42,339.11]],"ltp":1.33,"tv":51994.42,"id":9028621}]}]}
{"op":"mcm","clk":"4226566425","pt":1631449983558,"mc":[{"id":"1.187552454","rc":[{"batb":[[0,3.5,3],[1,3.45,3],[2,3.4,2]],"ltp":4.0,"tv":4462.92,"id":9345630},{"trd":[[1.32,302.14]],"batl":[[0,1.32,4.87]],"ltp":1.32,"tv":51994.93,"id":9028621}],"tv":56457.85}]}
{"op":"mcm","clk":"4226566552","pt":1631449984384,"mc":[{"id":"1.187552454","rc":[{"batl":[[0,4.5,2],[1,4.8,2],[2,990,0.01]],"ltp":4.0,"tv":4462.92,"id":9345630},{"batb":[[0,1.29,582.85]],"batl":[[0,1.32,41.3]],"ltp":1.32,"tv":51994.93,"id":9028621}]}]}
{"op":"mcm","clk":"4226567152","pt":1631449988441,"mc":[{"id":"1.187552454","rc":[{"batb":[[0,3.6,2.04],[1,3.5,3],[2,3.45,3]],"ltp":4.0,"tv":4462.92,"id":9345630},{"batl":[[1,1.38,30.25],[2,1.41,301.1]],"ltp":1.32,"tv":51994.93,"id":9028621}]}]}
{"op":"mcm","clk":"4226567194","pt":1631449988717,"mc":[{"id":"1.187552454","rc":[{"batb":[[0,3.5,3],[1,3.45,3],[2,3.4,2]],"ltp":4.0,"tv":4462.92,"id":9345630},{"batl":[[1,1.41,301.1],[2,1.42,339.11]],"ltp":1.32,"tv":51994.93,"id":9028621}]}]}
{"op":"mcm","clk":"4226568165","pt":1631449995428,"mc":[{"id":"1.187552454","rc":[{"batb":[[0,3.6,2],[1,3.5,3],[2,3.45,3]],"ltp":4.0,"tv":4462.92,"id":9345630},{"batl":[[1,1.38,35.25],[2,1.41,301.1]],"ltp":1.32,"tv":51994.93,"id":9028621}]}]}
{"op":"mcm","clk":"4226568219","pt":1631449995756,"mc":[{"id":"1.187552454","rc":[{"batb":[[0,3.5,3],[1,3.4,2],[2,1.01,30]],"ltp":4.0,"tv":4462.92,"id":9345630},{"batl":[[1,1.41,301.1],[2,1.42,339.11]],"ltp":1.32,"tv":51994.93,"id":9028621}]}]}
{"op":"mcm","clk":"4226568706","pt":1631449999172,"mc":[{"id":"1.187552454","rc":[{"batb":[[1,3.45,3],[2,3.4,2]],"ltp":4.0,"tv":4462.92,"id":9345630},{"batl":[[0,1.32,4.87]],"ltp":1.32,"tv":51994.93,"id":9028621}]}]}
{"op":"mcm","clk":"4226569008","pt":1631450001358,"mc":[{"id":"1.187552454","rc":[{"trd":[[1.32,304.99]],"batl":[[0,1.32,3.44]],"ltp":1.32,"tv":51997.78,"id":9028621}],"tv":56460.7}]}
{"op":"mcm","clk":"4226569179","pt":1631450002488,"mc":[{"id":"1.187552454","rc":[{"batb":[[0,3.6,2],[1,3.5,3],[2,3.45,3]],"batl":[[0,4.8,2],[1,990,0.01],[2,990,0]],"ltp":4.0,"tv":4462.92,"id":9345630},{"batb":[[0,1.27,49.07],[1,1.21,440.98],[2,1.2,1.71]],"batl":[[1,1.38,33.75],[2,1.41,32.5]],"ltp":1.32,"tv":51997.78,"id":9028621}]}]}
{"op":"mcm","clk":"4226569221","pt":1631450002783,"mc":[{"id":"1.187552454","rc":[{"batb":[[0,3.5,3],[1,3.45,3],[2,3.4,2]],"ltp":4.0,"tv":4462.92,"id":9345630},{"batl":[[1,1.41,32.5],[2,1.68,635.46]],"ltp":1.32,"tv":51997.78,"id":9028621}]}]}
{"op":"mcm","clk":"4226569484","pt":1631450004550,"mc":[{"id":"1.187552454","rc":[{"batl":[[0,4.3,548.63],[1,4.8,2],[2,990,0.01]],"ltp":4.0,"tv":4462.92,"id":9345630}]}]}
{"op":"mcm","clk":"4226569641","pt":1631450005569,"mc":[{"id":"1.187552454","rc":[{"batl":[[0,4.5,2]],"ltp":4.0,"tv":4462.92,"id":9345630},{"trd":[[1.32,311.87],[1.33,485.1]],"batb":[[0,1.33,653.32],[1,1.32,493.53],[2,1.29,50.01]],"batl":[[0,1.37,524.91],[1,1.38,381.49],[2,1.41,32.5]],"ltp":1.33,"tv":52048.04,"id":9028621}],"tv":56510.96}]}
{"op":"mcm","clk":"4226569803","pt":1631450006577,"mc":[{"id":"1.187552454","rc":[{"batb":[[0,3.6,2],[1,3.5,3],[2,3.45,3]],"ltp":4.0,"tv":4462.92,"id":9345630},{"batb":[[2,1.3,9.95]],"batl":[[1,1.38,414.74]],"ltp":1.33,"tv":52048.04,"id":9028621}]}]}
{"op":"mcm","clk":"4226570226","pt":1631450009587,"mc":[{"id":"1.187552454","rc":[{"batb":[[0,3.65,15]],"batl":[[0,4.8,2],[1,990,0.01],[2,990,0]],"ltp":4.0,"tv":4462.92,"id":9345630},{"batb":[[0,1.33,175.53],[1,1.3,10.15],[2,1.27,48.87]],"batl":[[0,1.41,32.5],[1,1.68,635.46],[2,3.8,27.47]],"ltp":1.33,"tv":52048.04,"id":9028621}]}]}
{"op":"mcm","clk":"4226570276","pt":1631450009864,"mc":[{"id":"1.187552454","rc":[{"batb":[[0,3.5,3],[1,3.45,3],[2,3.4,2]],"ltp":4.0,"tv":4462.92,"id":9345630},{"batb":[[0,1.3,10.15],[1,1.27,48.87],[2,1.21,440.98]],"ltp":1.33,"tv":52048.04,"id":9028621}]}]}
{"op":"mcm","clk":"4226570660","pt":1631450012404,"mc":[{"id":"1.187552454","rc":[{"batb":[[1,3.4,2],[2,1.01,30]],"ltp":4.0,"tv":4462.92,"id":9345630},{"batb":[[1,1.29,527.95],[2,1.28,579.23]],"batl":[[0,1.41,311.11],[1,1.42,339.11],[2,1.68,635.46]],"ltp":1.33,"tv":52048.04,"id":9028621}]}]}
{"op":"mcm","clk":"4226570753","pt":1631450012992,"mc":[{"id":"1.187552454","rc":[{"batl":[[0,4.5,2],[1,4.8,2],[2,990,0.01]],"ltp":4.0,"tv":4462.92,"id":9345630},{"batb":[[1,1.29,578.76]],"batl":[[0,1.4,6],[1,1.41,311.11],[2,1.42,339.11]],"ltp":1.33,"tv":52048.04,"id":9028621}]}]}
{"op":"mcm","clk":"4226571124","pt":1631450015586,"mc":[{"id":"1.187552454","rc":[{"batb":[[1,3.45,3],[2,3.4,2]],"ltp":4.0,"tv":4462.92,"id":9345630}]}]}
{"op":"mcm","clk":"4226571885","pt":1631450020934,"mc":[{"id":"1.187552454","rc":[{"trd":[[1.3,420.63],[1.32,312.27]],"batb":[[0,1.29,578.76],[1,1.28,579.23],[2,1.27,48.87]],"batl":[[0,1.3,4.3],[1,1.4,6],[2,1.41,311.11]],"ltp":1.3,"tv":52068.35,"id":9028621}],"tv":56531.27}]}
{"op":"mcm","clk":"4226572248","pt":1631450023400,"mc":[{"id":"1.187552454","rc":[{"batb":[[0,3.6,2],[1,3.5,3],[2,3.45,3]],"ltp":4.0,"tv":4462.92,"id":9345630},{"batl":[[1,1.38,30.75],[2,1.4,6]],"ltp":1.3,"tv":52068.35,"id":9028621}]}]}
{"op":"mcm","clk":"4226572335","pt":1631450024107,"mc":[{"id":"1.187552454","rc":[{"batb":[[0,3.5,3],[1,3.45,3],[2,3.4,2]],"ltp":4.0,"tv":4462.92,"id":9345630},{"trd":[[1.3,429.23]],"batl":[[0,1.4,6],[1,1.41,311.11],[2,1.42,339.11]],"ltp":1.3,"tv":52076.95,"id":9028621}],"tv":56539.87}]}
{"op":"mcm","clk":"4226572517","pt":1631450025337,"mc":[{"id":"1.187552454","rc":[{"batb":[[0,1.29,50.81],[1,1.27,48.87],[2,1.21,440.98]],"ltp":1.3,"tv":52076.95,"id":9028621}]}]}
{"op":"mcm","clk":"4226572569","pt":1631450025734,"mc":[{"id":"1.187552454","rc":[{"batl":[[0,4.8,2],[1,990,0.01],[2,990,0]],"ltp":4.0,"tv":4462.92,"id":9345630},{"batb":[[0,1.27,48.87],[1,1.21,440.98],[2,1.2,1.71]],"ltp":1.3,"tv":52076.95,"id":9028621}]}]}
{"op":"mcm","clk":"4226572842","pt":1631450027506,"mc":[{"id":"1.187552454","rc":[{"trd":[[3.6,10.91]],"batl":[[0,3.7,29.38],[1,4.8,2],[2,990,0.01]],"ltp":3.6,"tv":4473.5,"id":9345630},{"trd":[[1.38,23.09]],"batb":[[1,1.2,1.71],[2,1.12,6.16]],"ltp":1.38,"tv":52093.9,"id":9028621}],"tv":56567.4}]}
{"op":"mcm","clk":"4226572985","pt":1631450028581,"mc":[{"id":"1.187552454","rc":[{"trd":[[3.5,18.56]],"batb":[[0,3.4,2],[1,1.01,30],[2,3.4,0]],"batl":[[0,3.5,1.44],[1,3.7,143.93],[2,3.8,5.62]],"ltp":3.5,"tv":4478.06,"id":9345630},{"trd":[[1.4,124.81],[1.41,548.92]],"batb":[[0,1.38,321.77],[1,1.37,406.68],[2,1.36,47.18]],"batl":[[0,1.41,297.11],[1,1.42,344.73],[2,1.68,635.46]],"ltp":1.41,"tv":52133.3,"id":9028621}],"tv":56611.36}]}
{"op":"mcm","clk":"4226573141","pt":1631450029534,"mc":[{"id":"1.187552454","rc":[{"batb":[[0,3.4,27]],"batl":[[0,3.7,143.93],[1,3.8,5.62],[2,3.85,35.54]],"ltp":3.5,"tv":4478.06,"id":9345630},{"batl":[[1,1.42,404.73]],"ltp":1.41,"tv":52133.3,"id":9028621}]}]}
{"op":"mcm","clk":"4226573568","pt":1631450032438,"mc":[{"id":"1.187552454","rc":[{"batl":[[2,4.8,2]],"ltp":3.5,"tv":4478.06,"id":9345630}]}]}
{"op":"mcm","clk":"4226573726","pt":1631450033442,"mc":[{"id":"1.187552454","rc":[{"batl":[[0,3.65,16.01],[1,3.7,143.93],[2,3.8,5.62]],"ltp":3.5,"tv":4478.06,"id":9345630},{"batb":[[0,1.38,359.07]],"ltp":1.41,"tv":52133.3,"id":9028621}]}]}
{"op":"mcm","clk":"4226574054","pt":1631450035650,"mc":[{"id":"1.187552454","rc":[{"batl":[[2,3.8,41.47]],"ltp":3.5,"tv":4478.06,"id":9345630}]}]}
{"op":"mcm","clk":"4226574234","pt":1631450036833,"mc":[{"id":"1.187552454","rc":[{"batl":[[0,1.4,1539.13],[1,1.41,297.11],[2,1.42,404.73]],"ltp":1.41,"tv":52133.3,"id":9028621}]}]}
{"op":"mcm","clk":"4226574481","pt":1631450038537,"mc":[{"id":"1.187552454","rc":[{"batb":[[0,1.39,28.92],[1,1.38,359.07],[2,1.37,406.68]],"ltp":1.41,"tv":52133.3,"id":9028621}]}]}
{"op":"mcm","clk":"4226574553","pt":1631450039031,"mc":[{"id":"1.187552454","rc":[{"trd":[[1.39,210.68]],"batb":[[0,1.39,27.03]],"ltp":1.39,"tv":52137.08,"id":9028621}],"tv":56615.15}]}
{"op":"mcm","clk":"4226574714","pt":1631450040062,"mc":[{"id":"1.187552454","rc":[{"trd":[[1.39,210.99]],"batb":[[0,1.39,26.87]],"ltp":1.39,"tv":52137.4,"id":9028621}],"tv":56615.46}]}
{"op":"mcm","clk":"4226574874","pt":1631450040946,"mc":[{"id":"1.187552454","rc":[{"batb":[[0,1.38,359.07],[1,1.37,406.68],[2,1.36,47.18]],"batl":[[0,1.4,1319.26]],"ltp":1.39,"tv":52137.4,"id":9028621}]}]}
{"op":"mcm","clk":"4226575126","pt":1631450042476,"mc":[{"id":"1.187552454","rc":[{"batl":[[0,1.39,9.75],[1,1.4,1319.26],[2,1.41,297.11]],"ltp":1.39,"tv":52137.4,"id":9028621}]}]}
{"op":"mcm","clk":"4226575374","pt":1631450043878,"mc":[{"id":"1.187552454","rc":[{"batl":[[0,1.39,229.63]],"ltp":1.39,"tv":52137.4,"id":9028621}]}]}
{"op":"mcm","clk":"4226575648","pt":1631450045695,"mc":[{"id":"1.187552454","rc":[{"batl":[[0,1.39,228.46]],"ltp":1.39,"tv":52137.4,"id":9028621}]}]}
{"op":"mcm","clk":"4226576292","pt":1631450049461,"mc":[{"id":"1.187552454","rc":[{"trd":[[3.65,39.84]],"batl":[[0,3.65,7.59]],"ltp":3.65,"tv":4494.9,"id":9345630},{"batb":[[0,1.38,321.77]],"ltp":1.39,"tv":52137.4,"id":9028621}],"tv":56632.3}]}
{"op":"mcm","clk":"4226576458","pt":1631450050598,"mc":[{"id":"1.187552454","rc":[{"batl":[[0,3.8,41.47],[1,4.2,2.03],[2,4.5,2.01]],"ltp":3.65,"tv":4494.9,"id":9345630}]}]}
{"op":"mcm","clk":"4226576492","pt":1631450050755,"mc":[{"id":"1.187552454","rc":[{"batb":[[0,3.4,25]],"batl":[[0,3.8,35.85]],"ltp":3.65,"tv":4494.9,"id":9345630},{"batb":[[0,1.35,25.35],[1,1.32,64.64],[2,1.29,57.81]],"batl":[[2,1.42,60]],"ltp":1.39,"tv":52137.4,"id":9028621}]}]}
{"op":"mcm","clk":"4226576795","pt":1631450052593,"mc":[{"id":"1.187552454","rc":[{"batb":[[0,1.01,30],[1,1.01,0]],"batl":[[0,4.5,2.01],[1,4.6,2.01],[2,4.8,2]],"ltp":3.65,"tv":4494.9,"id":9345630},{"batb":[[0,1.29,57.81],[1,1.28,77.16],[2,1.27,48.87]],"batl":[[2,1.68,635.46]],"ltp":1.39,"tv":52137.4,"id":9028621}]}]}
{"op":"mcm","clk":"4226576846","pt":1631450052905,"mc":[{"id":"1.187552454","rc":[{"batl":[[1,990,0.01],[2,4.8,0]],"ltp":3.65,"tv":4494.9,"id":9345630},{"batb":[[1,1.28,11],[2,1.24,426.73]],"ltp":1.39,"tv":52137.4,"id":9028621}]}]}
{"op":"mcm","clk":"4226577055","pt":1631450054096,"mc":[{"id":"1.187552454","rc":[{"batb":[[0,1.33,622.37],[1,1.32,492.82],[2,1.29,57.81]],"batl":[[1,1.49,412.97],[2,1.5,269.73]],"ltp":1.39,"tv":52137.4,"id":9028621}]}]}
{"op":"mcm","clk":"4226577284","pt":1631450055387,"mc":[{"id":"1.187552454","rc":[{"trd":[[1.39,254.38]],"batl":[[0,1.39,206.77]],"ltp":1.39,"tv":52180.78,"id":9028621}],"tv":56675.69}]}
{"op":"mcm","clk":"4226577449","pt":1631450056317,"mc":[{"id":"1.187552454","rc":[{"batl":[[0,4.2,2.13],[1,4.5,4.01],[2,990,0.01]],"ltp":3.65,"tv":4494.9,"id":9345630},{"trd":[[1.39,271.48]],"batb":[[1,1.32,550.46],[2,1.29,64.81]],"batl":[[0,1.39,198.21]],"ltp":1.39,"tv":52197.89,"id":9028621}],"tv":56692.79}]}
{"op":"mcm","clk":"4226577544","pt":1631450056807,"mc":[{"id":"1.187552454","rc":[{"batl":[[0,1.49,412.97],[1,1.5,269.73],[2,1.68,635.46]],"ltp":1.39,"tv":52197.89,"id":9028621}]}]}
{"op":"mcm","clk":"4226577857","pt":1631450058592,"mc":[{"id":"1.187552454","rc":[{"batl":[[0,4.5,4.01],[1,990,0.01],[2,990,0]],"ltp":3.65,"tv":4494.9,"id":9345630},{"batb":[[0,1.29,64.81],[1,1.28,11],[2,1.24,426.73]],"batl":[[0,1.68,635.46],[1,3.8,27.47],[2,8.8,7.23]],"ltp":1.39,"tv":52197.89,"id":9028621}]}]}
{"op":"mcm","clk":"4226578074","pt":1631450059976,"mc":[{"id":"1.187552454","rc":[{"batb":[[0,2.46,3],[1,2.44,4],[2,1.01,30]],"ltp":3.65,"tv":4494.9,"id":9345630},{"batl":[[0,1.49,5],[1,1.68,635.46],[2,3.8,27.47]],"ltp":1.39,"tv":52197.89,"id":9028621}]}]}
{"op":"mcm","clk":"4226578338","pt":1631450061488,"mc":[{"id":"1.187552454","rc":[{"batb":[[0,1.39,445.44],[1,1.38,394.57],[2,1.29,64.81]],"batl":[[0,1.43,460.7],[1,1.44,317.73],[2,1.49,5]],"ltp":1.39,"tv":52197.89,"id":9028621}]}]}
{"op":"mcm","clk":"4226578531","pt":1631450062595,"mc":[{"id":"1.187552454","rc":[{"batb":[[0,2.92,15],[1,2.46,3],[2,2.44,4]],"batl":[[0,4.1,20.05],[1,4.2,2.23],[2,4.5,4.01]],"ltp":3.65,"tv":4494.9,"id":9345630},{"batb":[[2,1.32,63.64]],"ltp":1.39,"tv":52197.89,"id":9028621}]}]}
{"op":"mcm","clk":"4226578564","pt":1631450062816,"mc":[{"id":"1.187552454","rc":[{"batb":[[0,2.46,3],[1,2.44,4],[2,1.01,30]],"ltp":3.65,"tv":4494.9,"id":9345630}]}]}
{"op":"mcm","clk":"4226579158","pt":1631450066318,"mc":[{"id":"1.187552454","rc":[{"batb":[[0,1.39,485.95]],"ltp":1.39,"tv":52197.89,"id":9028621}]}]}
{"op":"mcm","clk":"4226579318","pt":1631450067304,"mc":[{"id":"1.187552454","rc":[{"batl":[[0,4.2,2.23],[1,4.5,4.01],[2,990,0.01]],"ltp":3.65,"tv":4494.9,"id":9345630},{"batb":[[0,1.32,63.64],[1,1.29,64.81],[2,1.24,426.73]],"batl":[[0,1.49,5],[1,1.68,640.46],[2,3.8,27.47]],"ltp":1.39,"tv":52197.89,"id":9028621}]}]}
{"op":"mcm","clk":"4226579472","pt":1631450068222,"mc":[{"id":"1.187552454","rc":[{"batl":[[0,4.5,4.01],[1,990,0.01],[2,990,0]],"ltp":3.65,"tv":4494.9,"id":9345630},{"batb":[[0,1.33,296.69]],"ltp":1.39,"tv":52197.89,"id":9028621}]}]}
{"op":"mcm","clk":"4226579675","pt":1631450069399,"mc":[{"id":"1.187552454","rc":[{"batb":[[0,2.92,75],[1,2.46,3],[2,2.44,4]],"ltp":3.65,"tv":4494.9,"id":9345630}]}]}
{"op":"mcm","clk":"4226579844","pt":1631450070375,"mc":[{"id":"1.187552454","rc":[{"batb":[[0,3,3],[1,2.98,3],[2,2.46,3]],"ltp":3.65,"tv":4494.9,"id":9345630},{"batb":[[0,1.33,919.06],[1,1.32,492.82],[2,1.29,64.81]],"batl":[[0,1.49,417.97],[1,1.5,269.73],[2,1.68,640.46]],"ltp":1.39,"tv":52197.89,"id":9028621}]}]}
{"op":"mcm","clk":"4226580014","pt":1631450071432,"mc":[{"id":"1.187552454","rc":[{"batb":[[2,1.01,30]],"batl":[[0,4.2,2.23],[1,4.5,4.01],[2,990,0.01]],"ltp":3.65,"tv":4494.9,"id":9345630},{"batb":[[1,1.32,550.46]],"ltp":1.39,"tv":52197.89,"id":9028621}]}]}
{"op":"mcm","clk":"4226581168","pt":1631450078228,"mc":[{"id":"1.187552454","rc":[{"batl":[[0,1.49,5],[1,1.68,635.46],[2,3.8,27.47]],"ltp":1.39,"tv":52197.89,"id":9028621}]}]}
{"op":"mcm","clk":"4226581532","pt":1631450080521,"mc":[{"id":"1.187552454","rc":[{"trd":[[1.33,502.19]],"batb":[[0,1.33,910.52]],"batl":[[0,1.37,69.8],[1,1.38,67.75],[2,1.39,67.75]],"ltp":1.33,"tv":52214.97,"id":9028621}],"tv":56709.88}]}
{"op":"mcm","clk":"4226581710","pt":1631450081491,"mc":[{"id":"1.187552454","rc":[{"batb":[[0,3.3,6],[1,3,3],[2,2.98,3]],"batl":[[0,4.2,457.59],[1,4.3,441.96],[2,4.4,441.96]],"ltp":3.65,"tv":4494.9,"id":9345630},{"batl":[[0,1.37,781.94],[1,1.38,568.6],[2,1.39,193.39]],"ltp":1.33,"tv":52214.97,"id":9028621}]}]}
{"op":"mcm","clk":"4226581873","pt":1631450082420,"mc":[{"id":"1.187552454","rc":[{"trd":[[3.7,35.36]],"batb":[[0,3.65,22.64],[1,3.3,3],[2,3,3]],"batl":[[0,4.1,11.15],[1,4.2,491.13],[2,4.3,441.96]],"ltp":3.7,"tv":4530.26,"id":9345630},{"trd":[[1.37,666.19]],"batb":[[0,1.33,957.4],[2,1.31,26.94]],"batl":[[0,1.37,686.44],[1,1.38,628.6]],"ltp":1.37,"tv":52310.47,"id":9028621}],"tv":56840.74}]}
{"op":"mcm","clk":"4226582046","pt":1631450083503,"mc":[{"id":"1.187552454","rc":[{"batb":[[2,3.05,4]],"ltp":3.7,"tv":4530.26,"id":9345630}]}]}
{"op":"mcm","clk":"4226582354","pt":1631450085501,"mc":[{"id":"1.187552454","rc":[{"batb":[[1,3.35,728.97],[2,3.3,3]],"batl":[[0,3.95,13.41],[1,4.1,11.15],[2,4.2,491.13]],"ltp":3.7,"tv":4530.26,"id":9345630},{"batl":[[1,1.38,568.6]],"ltp":1.37,"tv":52310.47,"id":9028621}]}]}
{"op":"mcm","clk":"4226582491","pt":1631450086418,"mc":[{"id":"1.187552454","rc":[{"batb":[[1,3.35,713.97]],"ltp":3.7,"tv":4530.26,"id":9345630},{"batl":[[0,1.37,726.11]],"ltp":1.37,"tv":52310.47,"id":9028621}]}]}
{"op":"mcm","clk":"4226582976","pt":1631450089405,"mc":[{"id":"1.187552454","rc":[{"batb":[[0,3.7,15],[1,3.65,22.64]],"ltp":3.7,"tv":4530.26,"id":9345630},{"batl":[[0,1.37,786.11]],"ltp":1.37,"tv":52310.47,"id":9028621}]}]}
{"op":"mcm","clk":"4226583016","pt":1631450089726,"mc":[{"id":"1.187552454","rc":[{"batl":[[0,1.36,219.88],[1,1.37,786.11],[2,1.38,568.6]],"ltp":1.37,"tv":52310.47,"id":9028621}]}]}
{"op":"mcm","clk":"4226583294","pt":1631450091729,"mc":[{"id":"1.187552454","rc":[{"batl":[[0,1.36,1539.13]],"ltp":1.37,"tv":52310.47,"id":9028621}]}]}
{"op":"mcm","clk":"4226583708","pt":1631450094418,"mc":[{"id":"1.187552454","rc":[{"trd":[[3.75,0.82]],"batb":[[0,3.3,3],[1,3.05,4],[2,1.01,30]],"ltp":3.75,"tv":4531.08,"id":9345630},{"trd":[[1.36,1325.74]],"batl":[[0,1.36,1536.88]],"ltp":1.36,"tv":52312.73,"id":9028621}],"tv":56843.81}]}
{"op":"mcm","clk":"4226584202","pt":1631450097521,"mc":[{"id":"1.187552454","rc":[{"batb":[[0,3.7,22.22],[1,3.35,780.08],[2,3.3,3]],"ltp":3.75,"tv":4531.08,"id":9345630}]}]}
{"op":"mcm","clk":"4226584260","pt":1631450097937,"mc":[{"id":"1.187552454","rc":[{"batb":[[1,3.35,765.08]],"ltp":3.75,"tv":4531.08,"id":9345630},{"batl":[[1,1.37,774.46]],"ltp":1.36,"tv":52312.73,"id":9028621}]}]}
{"op":"mcm","clk":"4226584400","pt":1631450098852,"mc":[{"id":"1.187552454","rc":[{"trd":[[1.33,507.48]],"batb":[[0,1.33,954.76]],"ltp":1.33,"tv":52318.03,"id":9028621}],"tv":56849.11}]}
{"op":"mcm","clk":"4226584860","pt":1631450101532,"mc":[{"id":"1.187552454","rc":[{"batb":[[1,3.05,4],[2,1.01,30]],"batl":[[0,4.2,34.32],[1,4.4,2.04],[2,4.5,2.01]],"ltp":3.75,"tv":4531.08,"id":9345630},{"batb":[[0,1.33,285.51],[1,1.31,26.94],[2,1.3,63.88]],"batl":[[1,1.37,60],[2,1.48,6]],"ltp":1.33,"tv":52318.03,"id":9028621}]}]}
{"op":"mcm","clk":"4226585008","pt":1631450102476,"mc":[{"id":"1.187552454","rc":[{"batb":[[0,3.05,4],[1,1.01,30],[2,1.01,0]],"batl":[[0,4.4,2.82],[1,4.5,2.01],[2,4.8,2.02]],"ltp":3.75,"tv":4531.08,"id":9345630},{"batb":[[1,1.3,63.88],[2,1.29,57.81]],"batl":[[1,1.48,6],[2,1.68,635.46]],"ltp":1.33,"tv":52318.03,"id":9028621}]}]}
{"op":"mcm","clk":"4226585152","pt":1631450103346,"mc":[{"id":"1.187552454","rc":[{"trd":[[1.36,1342.45]],"batl":[[0,1.36,1528.52]],"ltp":1.36,"tv":52334.73,"id":9028621}],"tv":56865.81}]}
{"op":"mcm","clk":"4226585330","pt":1631450104302,"mc":[{"id":"1.187552454","rc":[{"batb":[[2,1.29,741]],"batl":[[1,1.43,228.72],[2,1.44,320.03]],"ltp":1.36,"tv":52334.73,"id":9028621}]}]}
{"op":"mcm","clk":"4226585416","pt":1631450104784,"mc":[{"id":"1.187552454","rc":[{"trd":[[3.9,27.43]],"batl":[[0,4.4,2.09]],"ltp":3.9,"tv":4531.81,"id":9345630},{"trd":[[1.34,15030.02]],"batl":[[0,1.36,209.27]],"ltp":1.34,"tv":52336.86,"id":9028621}],"tv":56868.67}]}
{"op":"mcm","clk":"4226585606","pt":1631450105858,"mc":[{"id":"1.187552454","rc":[{"trd":[[1.36,1353.85]],"batl":[[0,1.43,228.72],[1,1.44,320.03],[2,1.48,6]],"ltp":1.36,"tv":52348.27,"id":9028621}],"tv":56880.08}]}
{"op":"mcm","clk":"4226586178","pt":1631450109342,"mc":[{"id":"1.187552454","rc":[{"batb":[[0,3.3,3],[1,3.25,3],[2,3.05,4]],"ltp":3.9,"tv":4531.81,"id":9345630},{"batb":[[0,1.33,285.69]],"batl":[[0,1.43,235.72]],"ltp":1.36,"tv":52348.27,"id":9028621}]}]}
{"op":"mcm","clk":"4226586760","pt":1631450112846,"mc":[{"id":"1.187552454","rc":[{"batb":[[0,1.33,285.93]],"ltp":1.36,"tv":52348.27,"id":9028621}]}]}
{"op":"mcm","clk":"4226587068","pt":1631450114771,"mc":[{"id":"1.187552454","rc":[{"batb":[[0,1.33,285.6]],"ltp":1.36,"tv":52348.27,"id":9028621}]}]}
{"op":"mcm","clk":"4226587436","pt":1631450117274,"mc":[{"id":"1.187552454","rc":[{"batb":[[0,1.33,285.51]],"ltp":1.36,"tv":52348.27,"id":9028621}]}]}
{"op":"mcm","clk":"4226588416","pt":1631450123578,"mc":[{"id":"1.187552454","rc":[{"batb":[[1,1.01,30],[2,3.05,0]],"batl":[[0,4.5,2.06],[1,4.8,2.02],[2,990,0.01]],"ltp":3.9,"tv":4531.81,"id":9345630},{"batb":[[0,1.29,741],[1,1.28,582.3],[2,1.27,73.03]],"batl":[[2,1.68,635.46]],"ltp":1.36,"tv":52348.27,"id":9028621}]}]}
{"op":"mcm","clk":"4226588746","pt":1631450125580,"mc":[{"id":"1.187552454","rc":[{"batb":[[0,1.29,57.81],[1,1.27,73.03],[2,1.21,440.98]],"ltp":1.36,"tv":52348.27,"id":9028621}]}]}
{"op":"mcm","clk":"4226588876","pt":1631450126361,"mc":[{"id":"1.187552454","rc":[{"trd":[[3.3,231.74]],"batb":[[0,1.01,30],[1,1.01,0]],"batl":[[0,4.8,2.07],[1,990,0.01],[2,990,0]],"ltp":3.3,"tv":4543.35,"id":9345630},{"trd":[[1.43,524.36]],"batb":[[0,1.27,73.03],[1,1.21,440.98],[2,1.12,6.16]],"batl":[[0,1.43,222.93]],"ltp":1.43,"tv":52361.06,"id":9028621}],"tv":56904.41}]}
{"op":"mcm","clk":"4226589054","pt":1631450127499,"mc":[{"id":"1.187552454","rc":[{"batb":[[0,3.25,2],[1,1.01,30]],"ltp":3.3,"tv":4543.35,"id":9345630},{"batb":[[0,1.38,69.29],[1,1.37,67.26],[2,1.36,67.26]],"ltp":1.43,"tv":52361.06,"id":9028621}]}]}
{"op":"mcm","clk":"4226589204","pt":1631450128578,"mc":[{"id":"1.187552454","rc":[{"batl":[[0,3.6,8.36],[1,4.8,2.07],[2,990,0.01]],"ltp":3.3,"tv":4543.35,"id":9345630},{"batb":[[0,1.4,311.89],[1,1.39,446.07],[2,1.38,762.23]],"batl":[[0,1.42,11.24],[1,1.43,222.93],[2,1.44,325.57]],"ltp":1.43,"tv":52361.06,"id":9028621}]}]}
{"op":"mcm","clk":"4226589344","pt":1631450129568,"mc":[{"id":"1.187552454","rc":[{"batb":[[0,3.2,3]],"batl":[[0,3.4,3],[1,3.6,8.36],[2,4.8,2.07]],"ltp":3.3,"tv":4543.35,"id":9345630},{"batb":[[0,1.41,7],[1,1.4,311.89],[2,1.39,446.07]],"batl":[[1,1.43,215.93]],"ltp":1.43,"tv":52361.06,"id":9028621}]}]}
{"op":"mcm","clk":"4226589472","pt":1631450130467,"mc":[{"id":"1.187552454","rc":[{"batb":[[0,3.3,26.08],[1,3.2,3],[2,1.01,30]],"batl":[[2,3.8,35.85]],"ltp":3.3,"tv":4543.35,"id":9345630},{"batl":[[1,1.43,275.93]],"ltp":1.43,"tv":52361.06,"id":9028621}]}]}
{"op":"mcm","clk":"4226589644","pt":1631450131549,"mc":[{"id":"1.187552454","rc":[{"batb":[[2,1.39,511.72]],"ltp":1.43,"tv":52361.06,"id":9028621}]}]}
{"op":"mcm","clk":"4226589786","pt":1631450132451,"mc":[{"id":"1.187552454","rc":[{"batb":[[2,2.86,85.4]],"ltp":3.3,"tv":4543.35,"id":9345630},{"trd":[[1.41,552.92]],"batb":[[0,1.41,5]],"ltp":1.41,"tv":52365.06,"id":9028621}],"tv":56908.41}]}
