{"op":"mcm","clk":"4232350266","pt":1631518387108,"mc":[{"id":"1.187594320","marketDefinition":{"bspMarket":false,"turnInPlayEnabled":true,"persistenceEnabled":true,"marketBaseRate":5.0,"eventId":"30897898","eventTypeId":"2","numberOfWinners":1,"bettingType":"ODDS","marketType":"MATCH_ODDS","marketTime":"2021-09-13T09:00:00.000Z","suspendTime":"2021-09-13T09:00:00.000Z","bspReconciled":false,"complete":true,"inPlay":false,"crossMatching":false,"runnersVoidable":false,"numberOfActiveRunners":2,"betDelay":0,"status":"OPEN","runners":[{"status":"ACTIVE","sortPriority":1,"id":9637111,"name":"R Serban"},{"status":"ACTIVE","sortPriority":2,"id":20586366,"name":"S Milatova"}],"regulators":["MR_INT"],"countryCode":"GB","discountAllowed":false,"timezone":"GMT","openDate":"2021-09-13T12:00:00.000Z","version":4030164794,"name":"Match Odds","eventName":"R Serban v S Milatova"},"rc":[{"batb":[[0,1.01,25]],"ltp":0.0,"tv":0.0,"id":9637111},{"batb":[[0,1.01,25]],"ltp":0.0,"tv":0.0,"id":20586366}]}]}
{"op":"mcm","clk":"4232350343","pt":1631518388646,"mc":[{"id":"1.187594320","marketDefinition":{"bspMarket":false,"turnInPlayEnabled":true,"persistenceEnabled":true,"marketBaseRate":5.0,"eventId":"30897898","eventTypeId":"2","numberOfWinners":1,"bettingType":"ODDS","marketType":"MATCH_ODDS","marketTime":"2021-09-13T09:00:00.000Z","suspendTime":"2021-09-13T09:00:00.000Z","bspReconciled":false,"complete":true,"inPlay":false,"crossMatching":false,"runnersVoidable":false,"numberOfActiveRunners":2,"betDelay":0,"status":"OPEN","runners":[{"status":"ACTIVE","sortPriority":1,"id":9637111,"name":"R Serban"},{"status":"ACTIVE","sortPriority":2,"id":20586366,"name":"S Milatova"}],"regulators":["MR_INT"],"countryCode":"GB","discountAllowed":true,"timezone":"GMT","openDate":"2021-09-13T12:00:00.000Z","version":4030164794,"name":"Match Odds","eventName":"R Serban v S Milatova"}}]}
{"op":"mcm","clk":"4232396353","pt":1631519122469,"mc":[{"id":"1.187594320","rc":[{"batb":[[0,1.01,7]],"ltp":0.0,"tv":0.0,"id":9637111},{"batb":[[0,1.01,7]],"ltp":0.0,"tv":0.0,"id":20586366}]}]}
{"op":"mcm","clk":"4232418368","pt":1631519402729,"mc":[{"id":"1.187594320","rc":[{"batb":[[0,1.02,2202.2],[1,1.01,7]],"ltp":0.0,"tv":0.0,"id":9637111},{"batb":[[0,1.05,880.88],[1,1.01,7]],"ltp":0.0,"tv":0.0,"id":20586366}]}]}
{"op":"mcm","clk":"4232610528","pt":1631522483140,"mc":[{"id":"1.187594320","rc":[{"batl":[[0,1.82,2.66]],"ltp":0.0,"tv":0.0,"id":9637111}]}]}
{"op":"mcm","clk":"4232610881","pt":1631522488974,"mc":[{"id":"1.187594320","rc":[{"batb":[[0,1.03,53.23],[1,1.02,2202.2],[2,1.01,7]],"ltp":0.0,"tv":0.0,"id":9637111}]}]}
{"op":"mcm","clk":"4232622114","pt":1631522684860,"mc":[{"id":"1.187594320","rc":[{"batb":[[0,1.05,880.88],[1,1.03,53.23]],"ltp":0.0,"tv":0.0,"id":9637111}]}]}
{"op":"mcm","clk":"4232626384","pt":1631522762130,"mc":[{"id":"1.187594320","marketDefinition":{"bspMarket":false,"turnInPlayEnabled":true,"persistenceEnabled":true,"marketBaseRate":5.0,"eventId":"30897898","eventTypeId":"2","numberOfWinners":1,"bettingType":"ODDS","marketType":"MATCH_ODDS","marketTime":"2021-09-13T14:00:00.000Z","suspendTime":"2021-09-13T14:00:00.000Z","bspReconciled":false,"complete":true,"inPlay":false,"crossMatching":false,"runnersVoidable":false,"numberOfActiveRunners":2,"betDelay":0,"status":"OPEN","runners":[{"status":"ACTIVE","sortPriority":1,"id":9637111,"name":"R Serban"},{"status":"ACTIVE","sortPriority":2,"id":20586366,"name":"S Milatova"}],"regulators":["MR_INT"],"countryCode":"GB","discountAllowed":true,"timezone":"GMT","openDate":"2021-09-13T12:00:00.000Z","version":4030340774,"name":"Match Odds","eventName":"R Serban v S Milatova"}}]}
{"op":"mcm","clk":"4232626493","pt":1631522764139,"mc":[{"id":"1.187594320","marketDefinition":{"bspMarket":false,"turnInPlayEnabled":true,"persistenceEnabled":true,"marketBaseRate":5.0,"eventId":"30897898","eventTypeId":"2","numberOfWinners":1,"bettingType":"ODDS","marketType":"MATCH_ODDS","marketTime":"2021-09-13T14:00:00.000Z","suspendTime":"2021-09-13T14:00:00.000Z","bspReconciled":false,"complete":true,"inPlay":false,"crossMatching":false,"runnersVoidable":false,"numberOfActiveRunners":2,"betDelay":0,"status":"OPEN","runners":[{"status":"ACTIVE","sortPriority":1,"id":9637111,"name":"R Serban"},{"status":"ACTIVE","sortPriority":2,"id":20586366,"name":"S Milatova"}],"regulators":["MR_INT"],"countryCode":"GB","discountAllowed":true,"timezone":"GMT","openDate":"2021-09-13T14:00:00.000Z","version":4030340774,"name":"Match Odds","eventName":"R Serban v S Milatova"}}]}
{"op":"mcm","clk":"4232666944","pt":1631523664110,"mc":[{"id":"1.187594320","rc":[{"batb":[[0,1.14,223.75],[1,1.05,880.36],[2,1.03,53.28]],"batl":[[0,1.82,2.66]],"ltp":0.0,"tv":0.0,"id":9637111},{"batb":[[0,5,10],[1,1.05,880.36],[2,1.01,7]],"ltp":0.0,"tv":0.0,"id":20586366}]}]}
{"op":"mcm","clk":"4232667183","pt":1631523670683,"mc":[{"id":"1.187594320","marketDefinition":{"bspMarket":false,"turnInPlayEnabled":true,"persistenceEnabled":true,"marketBaseRate":5.0,"eventId":"30897898","eventTypeId":"2","numberOfWinners":1,"bettingType":"ODDS","marketType":"MATCH_ODDS","marketTime":"2021-09-13T14:00:00.000Z","suspendTime":"2021-09-13T14:00:00.000Z","bspReconciled":false,"complete":true,"inPlay":false,"crossMatching":true,"runnersVoidable":false,"numberOfActiveRunners":2,"betDelay":0,"status":"OPEN","runners":[{"status":"ACTIVE","sortPriority":1,"id":9637111,"name":"R Serban"},{"status":"ACTIVE","sortPriority":2,"id":20586366,"name":"S Milatova"}],"regulators":["MR_INT"],"countryCode":"GB","discountAllowed":true,"timezone":"GMT","openDate":"2021-09-13T14:00:00.000Z","version":4030340774,"name":"Match Odds","eventName":"R Serban v S Milatova"}}]}
{"op":"mcm","clk":"4232704757","pt":1631524352498,"mc":[{"id":"1.187594320","rc":[{"batl":[[1,990,2.2]],"ltp":0.0,"tv":0.0,"id":9637111},{"batl":[[0,990,2.2]],"ltp":0.0,"tv":0.0,"id":20586366}]}]}
{"op":"mcm","clk":"4232780513","pt":1631525635472,"mc":[{"id":"1.187594320","rc":[{"batb":[[0,1.15,6.05],[1,1.14,223.75],[2,1.05,880.36]],"ltp":0.0,"tv":0.0,"id":9637111}]}]}
{"op":"mcm","clk":"4232816527","pt":1631526206614,"mc":[{"id":"1.187594320","marketDefinition":{"bspMarket":false,"turnInPlayEnabled":true,"persistenceEnabled":true,"marketBaseRate":5.0,"eventId":"30897898","eventTypeId":"2","numberOfWinners":1,"bettingType":"ODDS","marketType":"MATCH_ODDS","marketTime":"2021-09-13T14:15:00.000Z","suspendTime":"2021-09-13T14:15:00.000Z","bspReconciled":false,"complete":true,"inPlay":false,"crossMatching":true,"runnersVoidable":false,"numberOfActiveRunners":2,"betDelay":0,"status":"OPEN","runners":[{"status":"ACTIVE","sortPriority":1,"id":9637111,"name":"R Serban"},{"status":"ACTIVE","sortPriority":2,"id":20586366,"name":"S Milatova"}],"regulators":["MR_INT"],"countryCode":"GB","discountAllowed":true,"timezone":"GMT","openDate":"2021-09-13T14:00:00.000Z","version":4030512624,"name":"Match Odds","eventName":"R Serban v S Milatova"}}]}
{"op":"mcm","clk":"4232816673","pt":1631526208626,"mc":[{"id":"1.187594320","marketDefinition":{"bspMarket":false,"turnInPlayEnabled":true,"persistenceEnabled":true,"marketBaseRate":5.0,"eventId":"30897898","eventTypeId":"2","numberOfWinners":1,"bettingType":"ODDS","marketType":"MATCH_ODDS","marketTime":"2021-09-13T14:15:00.000Z","suspendTime":"2021-09-13T14:15:00.000Z","bspReconciled":false,"complete":true,"inPlay":false,"crossMatching":true,"runnersVoidable":false,"numberOfActiveRunners":2,"betDelay":0,"status":"OPEN","runners":[{"status":"ACTIVE","sortPriority":1,"id":9637111,"name":"R Serban"},{"status":"ACTIVE","sortPriority":2,"id":20586366,"name":"S Milatova"}],"regulators":["MR_INT"],"countryCode":"GB","discountAllowed":true,"timezone":"GMT","openDate":"2021-09-13T14:15:00.000Z","version":4030512624,"name":"Match Odds","eventName":"R Serban v S Milatova"}}]}
{"op":"mcm","clk":"4232907395","pt":1631527851929,"mc":[{"id":"1.187594320","marketDefinition":{"bspMarket":false,"turnInPlayEnabled":true,"persistenceEnabled":true,"marketBaseRate":5.0,"eventId":"30897898","eventTypeId":"2","numberOfWinners":1,"bettingType":"ODDS","marketType":"MATCH_ODDS","marketTime":"2021-09-13T14:35:00.000Z","suspendTime":"2021-09-13T14:35:00.000Z","bspReconciled":false,"complete":true,"inPlay":false,"crossMatching":true,"runnersVoidable":false,"numberOfActiveRunners":2,"betDelay":0,"status":"OPEN","runners":[{"status":"ACTIVE","sortPriority":1,"id":9637111,"name":"R Serban"},{"status":"ACTIVE","sortPriority":2,"id":20586366,"name":"S Milatova"}],"regulators":["MR_INT"],"countryCode":"GB","discountAllowed":true,"timezone":"GMT","openDate":"2021-09-13T14:15:00.000Z","version":4030529122,"name":"Match Odds","eventName":"R Serban v S Milatova"}}]}
{"op":"mcm","clk":"4232907485","pt":1631527853934,"mc":[{"id":"1.187594320","marketDefinition":{"bspMarket":false,"turnInPlayEnabled":true,"persistenceEnabled":true,"marketBaseRate":5.0,"eventId":"30897898","eventTypeId":"2","numberOfWinners":1,"bettingType":"ODDS","marketType":"MATCH_ODDS","marketTime":"2021-09-13T14:35:00.000Z","suspendTime":"2021-09-13T14:35:00.000Z","bspReconciled":false,"complete":true,"inPlay":false,"crossMatching":true,"runnersVoidable":false,"numberOfActiveRunners":2,"betDelay":0,"status":"OPEN","runners":[{"status":"ACTIVE","sortPriority":1,"id":9637111,"name":"R Serban"},{"status":"ACTIVE","sortPriority":2,"id":20586366,"name":"S Milatova"}],"regulators":["MR_INT"],"countryCode":"GB","discountAllowed":true,"timezone":"GMT","openDate":"2021-09-13T14:35:00.000Z","version":4030529122,"name":"Match Odds","eventName":"R Serban v S Milatova"}}]}
{"op":"mcm","clk":"4233096894","pt":1631530537016,"mc":[{"id":"1.187594320","marketDefinition":{"bspMarket":false,"turnInPlayEnabled":true,"persistenceEnabled":true,"marketBaseRate":5.0,"eventId":"30897898","eventTypeId":"2","numberOfWinners":1,"bettingType":"ODDS","marketType":"MATCH_ODDS","marketTime":"2021-09-13T14:00:00.000Z","suspendTime":"2021-09-13T14:00:00.000Z","bspReconciled":false,"complete":true,"inPlay":false,"crossMatching":true,"runnersVoidable":false,"numberOfActiveRunners":2,"betDelay":0,"status":"OPEN","runners":[{"status":"ACTIVE","sortPriority":1,"id":9637111,"name":"R Serban"},{"status":"ACTIVE","sortPriority":2,"id":20586366,"name":"S Milatova"}],"regulators":["MR_INT"],"countryCode":"GB","discountAllowed":true,"timezone":"GMT","openDate":"2021-09-13T14:35:00.000Z","version":4030565875,"name":"Match Odds","eventName":"R Serban v S Milatova"}}]}
{"op":"mcm","clk":"4233099630","pt":1631530575170,"mc":[{"id":"1.187594320","marketDefinition":{"bspMarket":false,"turnInPlayEnabled":true,"persistenceEnabled":true,"marketBaseRate":5.0,"eventId":"30897898","eventTypeId":"2","numberOfWinners":1,"bettingType":"ODDS","marketType":"MATCH_ODDS","marketTime":"2021-09-13T14:00:00.000Z","suspendTime":"2021-09-13T14:00:00.000Z","bspReconciled":false,"complete":true,"inPlay":false,"crossMatching":true,"runnersVoidable":false,"numberOfActiveRunners":2,"betDelay":0,"status":"OPEN","runners":[{"status":"ACTIVE","sortPriority":1,"id":9637111,"name":"R Serban"},{"status":"ACTIVE","sortPriority":2,"id":20586366,"name":"S Milatova"}],"regulators":["MR_INT"],"countryCode":"GB","discountAllowed":true,"timezone":"GMT","openDate":"2021-09-13T14:00:00.000Z","version":4030565875,"name":"Match Odds","eventName":"R Serban v S Milatova"}}]}
{"op":"mcm","clk":"4233183186","pt":1631531630827,"mc":[{"id":"1.187594320","marketDefinition":{"bspMarket":false,"turnInPlayEnabled":true,"persistenceEnabled":true,"marketBaseRate":5.0,"eventId":"30897898","eventTypeId":"2","numberOfWinners":1,"bettingType":"ODDS","marketType":"MATCH_ODDS","marketTime":"2021-09-13T14:10:00.000Z","suspendTime":"2021-09-13T14:10:00.000Z","bspReconciled":false,"complete":true,"inPlay":false,"crossMatching":true,"runnersVoidable":false,"numberOfActiveRunners":2,"betDelay":0,"status":"OPEN","runners":[{"status":"ACTIVE","sortPriority":1,"id":9637111,"name":"R Serban"},{"status":"ACTIVE","sortPriority":2,"id":20586366,"name":"S Milatova"}],"regulators":["MR_INT"],"countryCode":"GB","discountAllowed":true,"timezone":"GMT","openDate":"2021-09-13T14:00:00.000Z","version":4030580899,"name":"Match Odds","eventName":"R Serban v S Milatova"}}]}
{"op":"mcm","clk":"4233183422","pt":1631531633841,"mc":[{"id":"1.187594320","marketDefinition":{"bspMarket":false,"turnInPlayEnabled":true,"persistenceEnabled":true,"marketBaseRate":5.0,"eventId":"30897898","eventTypeId":"2","numberOfWinners":1,"bettingType":"ODDS","marketType":"MATCH_ODDS","marketTime":"2021-09-13T14:10:00.000Z","suspendTime":"2021-09-13T14:10:00.000Z","bspReconciled":false,"complete":true,"inPlay":false,"crossMatching":true,"runnersVoidable":false,"numberOfActiveRunners":2,"betDelay":0,"status":"OPEN","runners":[{"status":"ACTIVE","sortPriority":1,"id":9637111,"name":"R Serban"},{"status":"ACTIVE","sortPriority":2,"id":20586366,"name":"S Milatova"}],"regulators":["MR_INT"],"countryCode":"GB","discountAllowed":true,"timezone":"GMT","openDate":"2021-09-13T14:10:00.000Z","version":4030580899,"name":"Match Odds","eventName":"R Serban v S Milatova"}}]}
{"op":"mcm","clk":"4233449819","pt":1631535001951,"mc":[{"id":"1.187594320","rc":[{"batb":[[0,1.15,6.05],[1,1.14,298.34],[2,1.05,879.51]],"batl":[[0,1.82,2.66]],"ltp":0.0,"tv":0.0,"id":9637111},{"batb":[[0,5,10.44],[1,1.05,879.51]],"ltp":0.0,"tv":0.0,"id":20586366}]}]}
{"op":"mcm","clk":"4233607730","pt":1631536571231,"mc":[{"id":"1.187594320","marketDefinition":{"bspMarket":false,"turnInPlayEnabled":true,"persistenceEnabled":true,"marketBaseRate":5.0,"eventId":"30897898","eventTypeId":"2","numberOfWinners":1,"bettingType":"ODDS","marketType":"MATCH_ODDS","marketTime":"2021-09-13T14:20:00.000Z","suspendTime":"2021-09-13T14:20:00.000Z","bspReconciled":false,"complete":true,"inPlay":false,"crossMatching":true,"runnersVoidable":false,"numberOfActiveRunners":2,"betDelay":0,"status":"OPEN","runners":[{"status":"ACTIVE","sortPriority":1,"id":9637111,"name":"R Serban"},{"status":"ACTIVE","sortPriority":2,"id":20586366,"name":"S Milatova"}],"regulators":["MR_INT"],"countryCode":"GB","discountAllowed":true,"timezone":"GMT","openDate":"2021-09-13T14:10:00.000Z","version":4030646930,"name":"Match Odds","eventName":"R Serban v S Milatova"}}]}
{"op":"mcm","clk":"4233608005","pt":1631536574244,"mc":[{"id":"1.187594320","marketDefinition":{"bspMarket":false,"turnInPlayEnabled":true,"persistenceEnabled":true,"marketBaseRate":5.0,"eventId":"30897898","eventTypeId":"2","numberOfWinners":1,"bettingType":"ODDS","marketType":"MATCH_ODDS","marketTime":"2021-09-13T14:20:00.000Z","suspendTime":"2021-09-13T14:20:00.000Z","bspReconciled":false,"complete":true,"inPlay":false,"crossMatching":true,"runnersVoidable":false,"numberOfActiveRunners":2,"betDelay":0,"status":"OPEN","runners":[{"status":"ACTIVE","sortPriority":1,"id":9637111,"name":"R Serban"},{"status":"ACTIVE","sortPriority":2,"id":20586366,"name":"S Milatova"}],"regulators":["MR_INT"],"countryCode":"GB","discountAllowed":true,"timezone":"GMT","openDate":"2021-09-13T14:20:00.000Z","version":4030646930,"name":"Match Odds","eventName":"R Serban v S Milatova"}}]}
{"op":"mcm","clk":"4233638430","pt":1631536918889,"mc":[{"id":"1.187594320","rc":[{"batb":[[1,1.3,5],[2,1.05,879.51]],"ltp":0.0,"tv":0.0,"id":20586366}]}]}
{"op":"mcm","clk":"4233646921","pt":1631537023957,"mc":[{"id":"1.187594320","rc":[{"batb":[[1,1.3,10]],"ltp":0.0,"tv":0.0,"id":20586366}]}]}
{"op":"mcm","clk":"4233647642","pt":1631537033192,"mc":[{"id":"1.187594320","rc":[{"batb":[[1,1.3,5]],"ltp":0.0,"tv":0.0,"id":20586366}]}]}
{"op":"mcm","clk":"4233651480","pt":1631537080601,"mc":[{"id":"1.187594320","rc":[{"batb":[[1,1.3,10]],"ltp":0.0,"tv":0.0,"id":20586366}]}]}
{"op":"mcm","clk":"4233653713","pt":1631537108648,"mc":[{"id":"1.187594320","rc":[{"batb":[[1,1.3,5]],"ltp":0.0,"tv":0.0,"id":20586366}]}]}
{"op":"mcm","clk":"4233662812","pt":1631537226019,"mc":[{"id":"1.187594320","rc":[{"batl":[[0,1.4,100],[1,1.82,2.66],[2,990,2.2]],"ltp":0.0,"tv":0.0,"id":9637111}]}]}
{"op":"mcm","clk":"4233664202","pt":1631537242463,"mc":[{"id":"1.187594320","rc":[{"batl":[[0,1.5,100]],"ltp":0.0,"tv":0.0,"id":9637111}]}]}
{"op":"mcm","clk":"4233664369","pt":1631537244888,"mc":[{"id":"1.187594320","marketDefinition":{"bspMarket":false,"turnInPlayEnabled":true,"persistenceEnabled":true,"marketBaseRate":5.0,"eventId":"30897898","eventTypeId":"2","numberOfWinners":1,"bettingType":"ODDS","marketType":"MATCH_ODDS","marketTime":"2021-09-13T14:30:00.000Z","suspendTime":"2021-09-13T14:30:00.000Z","bspReconciled":false,"complete":true,"inPlay":false,"crossMatching":true,"runnersVoidable":false,"numberOfActiveRunners":2,"betDelay":0,"status":"OPEN","runners":[{"status":"ACTIVE","sortPriority":1,"id":9637111,"name":"R Serban"},{"status":"ACTIVE","sortPriority":2,"id":20586366,"name":"S Milatova"}],"regulators":["MR_INT"],"countryCode":"GB","discountAllowed":true,"timezone":"GMT","openDate":"2021-09-13T14:20:00.000Z","version":4030659516,"name":"Match Odds","eventName":"R Serban v S Milatova"}}]}
{"op":"mcm","clk":"4233664576","pt":1631537247903,"mc":[{"id":"1.187594320","marketDefinition":{"bspMarket":false,"turnInPlayEnabled":true,"persistenceEnabled":true,"marketBaseRate":5.0,"eventId":"30897898","eventTypeId":"2","numberOfWinners":1,"bettingType":"ODDS","marketType":"MATCH_ODDS","marketTime":"2021-09-13T14:30:00.000Z","suspendTime":"2021-09-13T14:30:00.000Z","bspReconciled":false,"complete":true,"inPlay":false,"crossMatching":true,"runnersVoidable":false,"numberOfActiveRunners":2,"betDelay":0,"status":"OPEN","runners":[{"status":"ACTIVE","sortPriority":1,"id":9637111,"name":"R Serban"},{"status":"ACTIVE","sortPriority":2,"id":20586366,"name":"S Milatova"}],"regulators":["MR_INT"],"countryCode":"GB","discountAllowed":true,"timezone":"GMT","openDate":"2021-09-13T14:30:00.000Z","version":4030659516,"name":"Match Odds","eventName":"R Serban v S Milatova"}}]}
{"op":"mcm","clk":"4233704287","pt":1631537853015,"mc":[{"id":"1.187594320","marketDefinition":{"bspMarket":false,"turnInPlayEnabled":true,"persistenceEnabled":true,"marketBaseRate":5.0,"eventId":"30897898","eventTypeId":"2","numberOfWinners":1,"bettingType":"ODDS","marketType":"MATCH_ODDS","marketTime":"2021-09-13T14:40:00.000Z","suspendTime":"2021-09-13T14:40:00.000Z","bspReconciled":false,"complete":true,"inPlay":false,"crossMatching":true,"runnersVoidable":false,"numberOfActiveRunners":2,"betDelay":0,"status":"OPEN","runners":[{"status":"ACTIVE","sortPriority":1,"id":9637111,"name":"R Serban"},{"status":"ACTIVE","sortPriority":2,"id":20586366,"name":"S Milatova"}],"regulators":["MR_INT"],"countryCode":"GB","discountAllowed":true,"timezone":"GMT","openDate":"2021-09-13T14:30:00.000Z","version":4030666595,"name":"Match Odds","eventName":"R Serban v S Milatova"}}]}
{"op":"mcm","clk":"4233706527","pt":1631537889204,"mc":[{"id":"1.187594320","marketDefinition":{"bspMarket":false,"turnInPlayEnabled":true,"persistenceEnabled":true,"marketBaseRate":5.0,"eventId":"30897898","eventTypeId":"2","numberOfWinners":1,"bettingType":"ODDS","marketType":"MATCH_ODDS","marketTime":"2021-09-13T14:40:00.000Z","suspendTime":"2021-09-13T14:40:00.000Z","bspReconciled":false,"complete":true,"inPlay":false,"crossMatching":true,"runnersVoidable":false,"numberOfActiveRunners":2,"betDelay":0,"status":"OPEN","runners":[{"status":"ACTIVE","sortPriority":1,"id":9637111,"name":"R Serban"},{"status":"ACTIVE","sortPriority":2,"id":20586366,"name":"S Milatova"}],"regulators":["MR_INT"],"countryCode":"GB","discountAllowed":true,"timezone":"GMT","openDate":"2021-09-13T14:40:00.000Z","version":4030666595,"name":"Match Odds","eventName":"R Serban v S Milatova"}}]}
{"op":"mcm","clk":"4233711874","pt":1631537974678,"mc":[{"id":"1.187594320","marketDefinition":{"bspMarket":false,"turnInPlayEnabled":true,"persistenceEnabled":true,"marketBaseRate":5.0,"eventId":"30897898","eventTypeId":"2","numberOfWinners":1,"bettingType":"ODDS","marketType":"MATCH_ODDS","marketTime":"2021-09-13T14:35:00.000Z","suspendTime":"2021-09-13T14:35:00.000Z","bspReconciled":false,"complete":true,"inPlay":false,"crossMatching":true,"runnersVoidable":false,"numberOfActiveRunners":2,"betDelay":0,"status":"OPEN","runners":[{"status":"ACTIVE","sortPriority":1,"id":9637111,"name":"R Serban"},{"status":"ACTIVE","sortPriority":2,"id":20586366,"name":"S Milatova"}],"regulators":["MR_INT"],"countryCode":"GB","discountAllowed":true,"timezone":"GMT","openDate":"2021-09-13T14:40:00.000Z","version":4030671031,"name":"Match Odds","eventName":"R Serban v S Milatova"}}]}
{"op":"mcm","clk":"4233711956","pt":1631537976689,"mc":[{"id":"1.187594320","marketDefinition":{"bspMarket":false,"turnInPlayEnabled":true,"persistenceEnabled":true,"marketBaseRate":5.0,"eventId":"30897898","eventTypeId":"2","numberOfWinners":1,"bettingType":"ODDS","marketType":"MATCH_ODDS","marketTime":"2021-09-13T14:35:00.000Z","suspendTime":"2021-09-13T14:35:00.000Z","bspReconciled":false,"complete":true,"inPlay":false,"crossMatching":true,"runnersVoidable":false,"numberOfActiveRunners":2,"betDelay":0,"status":"OPEN","runners":[{"status":"ACTIVE","sortPriority":1,"id":9637111,"name":"R Serban"},{"status":"ACTIVE","sortPriority":2,"id":20586366,"name":"S Milatova"}],"regulators":["MR_INT"],"countryCode":"GB","discountAllowed":true,"timezone":"GMT","openDate":"2021-09-13T14:35:00.000Z","version":4030671031,"name":"Match Odds","eventName":"R Serban v S Milatova"}}]}
{"op":"mcm","clk":"4233742073","pt":1631538338791,"mc":[{"id":"1.187594320","marketDefinition":{"bspMarket":false,"turnInPlayEnabled":true,"persistenceEnabled":true,"marketBaseRate":5.0,"eventId":"30897898","eventTypeId":"2","numberOfWinners":1,"bettingType":"ODDS","marketType":"MATCH_ODDS","marketTime":"2021-09-13T14:30:00.000Z","suspendTime":"2021-09-13T14:30:00.000Z","bspReconciled":false,"complete":true,"inPlay":false,"crossMatching":true,"runnersVoidable":false,"numberOfActiveRunners":2,"betDelay":0,"status":"OPEN","runners":[{"status":"ACTIVE","sortPriority":1,"id":9637111,"name":"R Serban"},{"status":"ACTIVE","sortPriority":2,"id":20586366,"name":"S Milatova"}],"regulators":["MR_INT"],"countryCode":"GB","discountAllowed":true,"timezone":"GMT","openDate":"2021-09-13T14:35:00.000Z","version":4030684915,"name":"Match Odds","eventName":"R Serban v S Milatova"}}]}
{"op":"mcm","clk":"4233742347","pt":1631538341817,"mc":[{"id":"1.187594320","marketDefinition":{"bspMarket":false,"turnInPlayEnabled":true,"persistenceEnabled":true,"marketBaseRate":5.0,"eventId":"30897898","eventTypeId":"2","numberOfWinners":1,"bettingType":"ODDS","marketType":"MATCH_ODDS","marketTime":"2021-09-13T14:30:00.000Z","suspendTime":"2021-09-13T14:30:00.000Z","bspReconciled":false,"complete":true,"inPlay":false,"crossMatching":true,"runnersVoidable":false,"numberOfActiveRunners":2,"betDelay":0,"status":"OPEN","runners":[{"status":"ACTIVE","sortPriority":1,"id":9637111,"name":"R Serban"},{"status":"ACTIVE","sortPriority":2,"id":20586366,"name":"S Milatova"}],"regulators":["MR_INT"],"countryCode":"GB","discountAllowed":true,"timezone":"GMT","openDate":"2021-09-13T14:30:00.000Z","version":4030684915,"name":"Match Odds","eventName":"R Serban v S Milatova"}}]}
{"op":"mcm","clk":"4233934021","pt":1631540182804,"mc":[{"id":"1.187594320","rc":[{"batb":[[0,1.15,6.04],[2,1.05,878.93]],"batl":[[1,1.82,2.66]],"ltp":0.0,"tv":0.0,"id":9637111},{"batb":[[2,1.01,7]],"ltp":0.0,"tv":0.0,"id":20586366}]}]}
{"op":"mcm","clk":"4233934857","pt":1631540190829,"mc":[{"id":"1.187594320","rc":[{"batl":[[0,1.48,43.7],[1,1.5,100],[2,1.82,2.66]],"ltp":0.0,"tv":0.0,"id":9637111}]}]}
{"op":"mcm","clk":"4233971658","pt":1631540635508,"mc":[{"id":"1.187594320","rc":[{"batl":[[0,1.47,100],[1,1.48,43.7]],"ltp":0.0,"tv":0.0,"id":9637111}]}]}
{"op":"mcm","clk":"4233981902","pt":1631540766672,"mc":[{"id":"1.187594320","rc":[{"batl":[[0,1.44,6.33],[1,1.47,100],[2,1.48,43.7]],"ltp":0.0,"tv":0.0,"id":9637111}]}]}
{"op":"mcm","clk":"4233984473","pt":1631540796734,"mc":[{"id":"1.187594320","rc":[{"batl":[[0,1.47,100],[1,1.48,43.7],[2,1.82,2.66]],"ltp":0.0,"tv":0.0,"id":9637111}]}]}
{"op":"mcm","clk":"4234120171","pt":1631542351357,"mc":[{"id":"1.187594320","rc":[{"trd":[[5,2.76]],"batb":[[0,5,9.06]],"ltp":5.0,"tv":2.76,"id":20586366}],"tv":2.76}]}
{"op":"mcm","clk":"4234120289","pt":1631542352344,"mc":[{"id":"1.187594320","rc":[{"batb":[[0,5,10.44]],"ltp":5.0,"tv":2.76,"id":20586366}]}]}
{"op":"mcm","clk":"4234127456","pt":1631542428964,"mc":[{"id":"1.187594320","rc":[{"batl":[[0,1.45,43.7],[1,1.47,100]],"ltp":0.0,"tv":0.0,"id":9637111}]}]}
{"op":"mcm","clk":"4234141139","pt":1631542558023,"mc":[{"id":"1.187594320","marketDefinition":{"bspMarket":false,"turnInPlayEnabled":true,"persistenceEnabled":true,"marketBaseRate":5.0,"eventId":"30897898","eventTypeId":"2","numberOfWinners":1,"bettingType":"ODDS","marketType":"MATCH_ODDS","marketTime":"2021-09-13T14:25:00.000Z","suspendTime":"2021-09-13T14:25:00.000Z","bspReconciled":false,"complete":true,"inPlay":false,"crossMatching":true,"runnersVoidable":false,"numberOfActiveRunners":2,"betDelay":0,"status":"OPEN","runners":[{"status":"ACTIVE","sortPriority":1,"id":9637111,"name":"R Serban"},{"status":"ACTIVE","sortPriority":2,"id":20586366,"name":"S Milatova"}],"regulators":["MR_INT"],"countryCode":"GB","discountAllowed":true,"timezone":"GMT","openDate":"2021-09-13T14:30:00.000Z","version":4030758189,"name":"Match Odds","eventName":"R Serban v S Milatova"}}]}
{"op":"mcm","clk":"4234141320","pt":1631542560034,"mc":[{"id":"1.187594320","marketDefinition":{"bspMarket":false,"turnInPlayEnabled":true,"persistenceEnabled":true,"marketBaseRate":5.0,"eventId":"30897898","eventTypeId":"2","numberOfWinners":1,"bettingType":"ODDS","marketType":"MATCH_ODDS","marketTime":"2021-09-13T14:25:00.000Z","suspendTime":"2021-09-13T14:25:00.000Z","bspReconciled":false,"complete":true,"inPlay":false,"crossMatching":true,"runnersVoidable":false,"numberOfActiveRunners":2,"betDelay":0,"status":"OPEN","runners":[{"status":"ACTIVE","sortPriority":1,"id":9637111,"name":"R Serban"},{"status":"ACTIVE","sortPriority":2,"id":20586366,"name":"S Milatova"}],"regulators":["MR_INT"],"countryCode":"GB","discountAllowed":true,"timezone":"GMT","openDate":"2021-09-13T14:25:00.000Z","version":4030758189,"name":"Match Odds","eventName":"R Serban v S Milatova"}}]}
{"op":"mcm","clk":"4234169930","pt":1631542863775,"mc":[{"id":"1.187594320","marketDefinition":{"bspMarket":false,"turnInPlayEnabled":true,"persistenceEnabled":true,"marketBaseRate":5.0,"eventId":"30897898","eventTypeId":"2","numberOfWinners":1,"bettingType":"ODDS","marketType":"MATCH_ODDS","marketTime":"2021-09-13T14:20:00.000Z","suspendTime":"2021-09-13T14:20:00.000Z","bspReconciled":false,"complete":true,"inPlay":false,"crossMatching":true,"runnersVoidable":false,"numberOfActiveRunners":2,"betDelay":0,"status":"OPEN","runners":[{"status":"ACTIVE","sortPriority":1,"id":9637111,"name":"R Serban"},{"status":"ACTIVE","sortPriority":2,"id":20586366,"name":"S Milatova"}],"regulators":["MR_INT"],"countryCode":"GB","discountAllowed":true,"timezone":"GMT","openDate":"2021-09-13T14:25:00.000Z","version":4030764464,"name":"Match Odds","eventName":"R Serban v S Milatova"}}]}
{"op":"mcm","clk":"4234170213","pt":1631542866793,"mc":[{"id":"1.187594320","marketDefinition":{"bspMarket":false,"turnInPlayEnabled":true,"persistenceEnabled":true,"marketBaseRate":5.0,"eventId":"30897898","eventTypeId":"2","numberOfWinners":1,"bettingType":"ODDS","marketType":"MATCH_ODDS","marketTime":"2021-09-13T14:20:00.000Z","suspendTime":"2021-09-13T14:20:00.000Z","bspReconciled":false,"complete":true,"inPlay":false,"crossMatching":true,"runnersVoidable":false,"numberOfActiveRunners":2,"betDelay":0,"status":"OPEN","runners":[{"status":"ACTIVE","sortPriority":1,"id":9637111,"name":"R Serban"},{"status":"ACTIVE","sortPriority":2,"id":20586366,"name":"S Milatova"}],"regulators":["MR_INT"],"countryCode":"GB","discountAllowed":true,"timezone":"GMT","openDate":"2021-09-13T14:20:00.000Z","version":4030764464,"name":"Match Odds","eventName":"R Serban v S Milatova"}}]}
{"op":"mcm","clk":"4234173713","pt":1631542906269,"mc":[{"id":"1.187594320","marketDefinition":{"bspMarket":false,"turnInPlayEnabled":true,"persistenceEnabled":true,"marketBaseRate":5.0,"eventId":"30897898","eventTypeId":"2","numberOfWinners":1,"bettingType":"ODDS","marketType":"MATCH_ODDS","marketTime":"2021-09-13T14:20:00.000Z","suspendTime":"2021-09-13T14:20:00.000Z","bspReconciled":false,"complete":true,"inPlay":true,"crossMatching":true,"runnersVoidable":false,"numberOfActiveRunners":2,"betDelay":5,"status":"OPEN","runners":[{"status":"ACTIVE","sortPriority":1,"id":9637111,"name":"R Serban"},{"status":"ACTIVE","sortPriority":2,"id":20586366,"name":"S Milatova"}],"regulators":["MR_INT"],"countryCode":"GB","discountAllowed":true,"timezone":"GMT","openDate":"2021-09-13T14:20:00.000Z","version":4030765102,"name":"Match Odds","eventName":"R Serban v S Milatova"},"rc":[{"batb":[[0,1.01,7],[1,1.14,0],[2,1.05,0]],"batl":[[0,1.47,100],[1,1.47,0],[2,1.82,0]],"ltp":0.0,"tv":0.0,"id":9637111},{"batb":[[0,1.3,5],[1,1.01,7],[2,1.01,0]],"ltp":5.0,"tv":2.76,"id":20586366}]}]}
{"op":"mcm","clk":"4234174168","pt":1631542911454,"mc":[{"id":"1.187594320","rc":[{"batb":[[0,1.12,249.99],[1,1.01,7]],"ltp":0.0,"tv":0.0,"id":9637111},{"batb":[[0,4.8,10],[1,1.3,5],[2,1.01,7]],"ltp":5.0,"tv":2.76,"id":20586366}]}]}
{"op":"mcm","clk":"4234192461","pt":1631543108241,"mc":[{"id":"1.187594320","rc":[{"batb":[[0,1.01,7],[1,1.01,0]],"ltp":0.0,"tv":0.0,"id":9637111},{"batb":[[0,1.3,5],[1,1.01,7],[2,1.01,0]],"ltp":5.0,"tv":2.76,"id":20586366}]}]}
{"op":"mcm","clk":"4234201091","pt":1631543196000,"mc":[{"id":"1.187594320","rc":[{"batb":[[0,1.02,2.17],[1,1.01,7]],"ltp":0.0,"tv":0.0,"id":9637111}]}]}
{"op":"mcm","clk":"4234204858","pt":1631543237200,"mc":[{"id":"1.187594320","rc":[{"batb":[[0,1.01,7],[1,1.01,0]],"ltp":0.0,"tv":0.0,"id":9637111}]}]}
{"op":"mcm","clk":"4234277951","pt":1631543867204,"mc":[{"id":"1.187594320","rc":[{"batb":[[0,3.5,86.16],[1,1.3,5],[2,1.01,7]],"ltp":5.0,"tv":2.76,"id":20586366}]}]}
{"op":"mcm","clk":"4234286030","pt":1631543934932,"mc":[{"id":"1.187594320","rc":[{"batb":[[0,1.3,5],[1,1.01,7],[2,1.01,0]],"ltp":5.0,"tv":2.76,"id":20586366}]}]}
{"op":"mcm","clk":"4234489886","pt":1631546265834,"mc":[{"id":"1.187594320","rc":[{"trd":[[5,2.77]],"ltp":5.0,"tv":2.76,"id":20586366}],"tv":2.76}]}
{"op":"mcm","clk":"4234647264","pt":1631548313300,"mc":[{"id":"1.187594320","rc":[{"batl":[[1,100,0.19]],"ltp":0.0,"tv":0.0,"id":9637111}]}]}
{"op":"mcm","clk":"4234647778","pt":1631548319975,"mc":[{"id":"1.187594320","rc":[{"batl":[[1,100,0]],"ltp":0.0,"tv":0.0,"id":9637111}]}]}
{"op":"mcm","clk":"4234648227","pt":1631548325322,"mc":[{"id":"1.187594320","rc":[{"batl":[[1,100,0.46]],"ltp":0.0,"tv":0.0,"id":9637111}]}]}
{"op":"mcm","clk":"4234655676","pt":1631548422545,"mc":[{"id":"1.187594320","rc":[{"batl":[[0,100,0.37]],"ltp":5.0,"tv":2.76,"id":20586366}]}]}
{"op":"mcm","clk":"4234712592","pt":1631549092280,"mc":[{"id":"1.187594320","rc":[{"batb":[[0,1.01,12]],"ltp":0.0,"tv":0.0,"id":9637111},{"batb":[[1,1.01,12]],"ltp":5.0,"tv":2.76,"id":20586366}]}]}
{"op":"mcm","clk":"4234713562","pt":1631549099967,"mc":[{"id":"1.187594320","rc":[{"batl":[[1,100,0]],"ltp":0.0,"tv":0.0,"id":9637111}]}]}
{"op":"mcm","clk":"4234761929","pt":1631549611133,"mc":[{"id":"1.187594320","rc":[{"batb":[[0,1.12,249.99],[1,1.01,12]],"ltp":0.0,"tv":0.0,"id":9637111},{"batb":[[0,4.8,10],[1,1.3,5],[2,1.01,12]],"ltp":5.0,"tv":2.76,"id":20586366}]}]}
{"op":"mcm","clk":"4234796007","pt":1631549994113,"mc":[{"id":"1.187594320","marketDefinition":{"bspMarket":false,"turnInPlayEnabled":true,"persistenceEnabled":true,"marketBaseRate":5.0,"eventId":"30897898","eventTypeId":"2","numberOfWinners":1,"bettingType":"ODDS","marketType":"MATCH_ODDS","marketTime":"2021-09-13T16:19:53.000Z","suspendTime":"2021-09-13T16:19:53.000Z","bspReconciled":false,"complete":true,"inPlay":true,"crossMatching":true,"runnersVoidable":false,"numberOfActiveRunners":2,"betDelay":5,"status":"OPEN","runners":[{"status":"ACTIVE","sortPriority":1,"id":9637111,"name":"R Serban"},{"status":"ACTIVE","sortPriority":2,"id":20586366,"name":"S Milatova"}],"regulators":["MR_INT"],"countryCode":"GB","discountAllowed":true,"timezone":"GMT","openDate":"2021-09-13T14:20:00.000Z","version":4030899815,"name":"Match Odds","eventName":"R Serban v S Milatova"},"rc":[{"batb":[[0,1.01,12],[1,1.01,0]],"ltp":0.0,"tv":0.0,"id":9637111}]}]}
{"op":"mcm","clk":"4234796291","pt":1631549997128,"mc":[{"id":"1.187594320","marketDefinition":{"bspMarket":false,"turnInPlayEnabled":true,"persistenceEnabled":true,"marketBaseRate":5.0,"eventId":"30897898","eventTypeId":"2","numberOfWinners":1,"bettingType":"ODDS","marketType":"MATCH_ODDS","marketTime":"2021-09-13T16:19:53.000Z","suspendTime":"2021-09-13T16:19:53.000Z","bspReconciled":false,"complete":true,"inPlay":true,"crossMatching":true,"runnersVoidable":false,"numberOfActiveRunners":2,"betDelay":5,"status":"OPEN","runners":[{"status":"ACTIVE","sortPriority":1,"id":9637111,"name":"R Serban"},{"status":"ACTIVE","sortPriority":2,"id":20586366,"name":"S Milatova"}],"regulators":["MR_INT"],"countryCode":"GB","discountAllowed":true,"timezone":"GMT","openDate":"2021-09-13T16:19:53.000Z","version":4030899815,"name":"Match Odds","eventName":"R Serban v S Milatova"}}]}
{"op":"mcm","clk":"4234796406","pt":1631549998706,"mc":[{"id":"1.187594320","rc":[{"batb":[[0,1.15,200],[1,1.01,12]],"ltp":0.0,"tv":0.0,"id":9637111}]}]}
{"op":"mcm","clk":"4234799577","pt":1631550030867,"mc":[{"id":"1.187594320","rc":[{"batb":[[0,1.01,12],[1,1.01,0]],"ltp":0.0,"tv":0.0,"id":9637111},{"batb":[[0,1.3,5],[1,1.01,12],[2,1.01,0]],"ltp":5.0,"tv":2.76,"id":20586366}]}]}
{"op":"mcm","clk":"4234802524","pt":1631550061648,"mc":[{"id":"1.187594320","rc":[{"batb":[[0,1.15,200],[1,1.01,12]],"ltp":0.0,"tv":0.0,"id":9637111},{"batb":[[0,4.8,10],[1,1.3,5],[2,1.01,12]],"ltp":5.0,"tv":2.76,"id":20586366}]}]}
{"op":"mcm","clk":"4234803412","pt":1631550072263,"mc":[{"id":"1.187594320","rc":[{"batb":[[0,1.01,12],[1,1.01,0]],"ltp":0.0,"tv":0.0,"id":9637111},{"batb":[[0,1.3,5],[1,1.01,12],[2,1.01,0]],"ltp":5.0,"tv":2.76,"id":20586366}]}]}
{"op":"mcm","clk":"4234805766","pt":1631550098409,"mc":[{"id":"1.187594320","rc":[{"batb":[[0,1.12,249.99],[1,1.01,12]],"ltp":0.0,"tv":0.0,"id":9637111},{"batb":[[0,5.3,10],[1,1.3,5],[2,1.01,12]],"ltp":5.0,"tv":2.76,"id":20586366}]}]}
{"op":"mcm","clk":"4234809036","pt":1631550133652,"mc":[{"id":"1.187594320","rc":[{"batb":[[0,1.01,12],[1,1.01,0]],"ltp":0.0,"tv":0.0,"id":9637111},{"batb":[[0,1.3,5],[1,1.01,12],[2,1.01,0]],"ltp":5.0,"tv":2.76,"id":20586366}]}]}
{"op":"mcm","clk":"4234809502","pt":1631550138603,"mc":[{"id":"1.187594320","rc":[{"batb":[[0,1.11,272.72],[1,1.01,12]],"ltp":0.0,"tv":0.0,"id":9637111},{"batb":[[0,5.8,10],[1,1.3,5],[2,1.01,12]],"ltp":5.0,"tv":2.76,"id":20586366}]}]}
{"op":"mcm","clk":"4234812193","pt":1631550167341,"mc":[{"id":"1.187594320","rc":[{"batb":[[0,1.01,12],[1,1.01,0]],"ltp":0.0,"tv":0.0,"id":9637111},{"batb":[[0,1.3,5],[1,1.01,12],[2,1.01,0]],"ltp":5.0,"tv":2.76,"id":20586366}]}]}
{"op":"mcm","clk":"4234812665","pt":1631550172209,"mc":[{"id":"1.187594320","rc":[{"batb":[[0,1.08,374.99],[1,1.01,12]],"ltp":0.0,"tv":0.0,"id":9637111},{"batb":[[0,6,10],[1,1.3,5],[2,1.01,12]],"ltp":5.0,"tv":2.76,"id":20586366}]}]}
{"op":"mcm","clk":"4234815715","pt":1631550200804,"mc":[{"id":"1.187594320","rc":[{"batb":[[0,1.01,12],[1,1.01,0]],"ltp":0.0,"tv":0.0,"id":9637111},{"batb":[[0,1.3,5],[1,1.01,12],[2,1.01,0]],"ltp":5.0,"tv":2.76,"id":20586366}]}]}
{"op":"mcm","clk":"4234820093","pt":1631550248860,"mc":[{"id":"1.187594320","rc":[{"batb":[[0,1.06,499.99],[1,1.01,12]],"ltp":0.0,"tv":0.0,"id":9637111},{"batb":[[0,7,10],[1,1.3,5],[2,1.01,12]],"ltp":5.0,"tv":2.76,"id":20586366}]}]}
{"op":"mcm","clk":"4234821705","pt":1631550265385,"mc":[{"id":"1.187594320","rc":[{"batb":[[0,1.01,12],[1,1.01,0]],"ltp":0.0,"tv":0.0,"id":9637111},{"batb":[[0,1.3,5],[1,1.01,12],[2,1.01,0]],"ltp":5.0,"tv":2.76,"id":20586366}]}]}
{"op":"mcm","clk":"4234822165","pt":1631550270309,"mc":[{"id":"1.187594320","rc":[{"batb":[[0,1.05,599.99],[1,1.01,12]],"ltp":0.0,"tv":0.0,"id":9637111},{"batb":[[0,7.6,10],[1,1.3,5],[2,1.01,12]],"ltp":5.0,"tv":2.76,"id":20586366}]}]}
{"op":"mcm","clk":"4234824947","pt":1631550299514,"mc":[{"id":"1.187594320","rc":[{"batb":[[0,1.01,12],[1,1.01,0]],"ltp":0.0,"tv":0.0,"id":9637111},{"batb":[[0,1.3,5],[1,1.01,12],[2,1.01,0]],"ltp":5.0,"tv":2.76,"id":20586366}]}]}
{"op":"mcm","clk":"4234825475","pt":1631550304438,"mc":[{"id":"1.187594320","rc":[{"batb":[[0,1.08,374.99],[1,1.01,12]],"ltp":0.0,"tv":0.0,"id":9637111},{"batb":[[0,6,10],[1,1.3,5],[2,1.01,12]],"ltp":5.0,"tv":2.76,"id":20586366}]}]}
{"op":"mcm","clk":"4234832903","pt":1631550382157,"mc":[{"id":"1.187594320","rc":[{"batb":[[0,1.01,12],[1,1.01,0]],"ltp":0.0,"tv":0.0,"id":9637111},{"batb":[[0,1.3,5],[1,1.01,12],[2,1.01,0]],"ltp":5.0,"tv":2.76,"id":20586366}]}]}
{"op":"mcm","clk":"4234834189","pt":1631550395968,"mc":[{"id":"1.187594320","rc":[{"batb":[[0,1.12,249.99],[1,1.01,12]],"ltp":0.0,"tv":0.0,"id":9637111},{"batb":[[0,5.3,10],[1,1.3,5],[2,1.01,12]],"ltp":5.0,"tv":2.76,"id":20586366}]}]}
{"op":"mcm","clk":"4234834826","pt":1631550403470,"mc":[{"id":"1.187594320","rc":[{"batb":[[0,1.01,12],[1,1.01,0]],"ltp":0.0,"tv":0.0,"id":9637111},{"batb":[[0,1.3,5],[1,1.01,12],[2,1.01,0]],"ltp":5.0,"tv":2.76,"id":20586366}]}]}
{"op":"mcm","clk":"4234835308","pt":1631550408397,"mc":[{"id":"1.187594320","rc":[{"batb":[[0,1.18,166.66],[1,1.01,12]],"ltp":0.0,"tv":0.0,"id":9637111},{"batb":[[0,4.3,10],[1,1.3,5],[2,1.01,12]],"ltp":5.0,"tv":2.76,"id":20586366}]}]}
{"op":"mcm","clk":"4234839407","pt":1631550454455,"mc":[{"id":"1.187594320","rc":[{"trd":[[4.3,6.94]],"batb":[[0,4.3,6.53]],"ltp":4.3,"tv":9.7,"id":20586366}],"tv":9.7}]}
{"op":"mcm","clk":"4234839423","pt":1631550454663,"mc":[{"id":"1.187594320","rc":[{"batb":[[0,1.3,5],[1,1.01,12],[2,1.01,0]],"ltp":4.3,"tv":9.7,"id":20586366}]}]}
{"op":"mcm","clk":"4234839825","pt":1631550459572,"mc":[{"id":"1.187594320","rc":[{"batb":[[0,4.3,10],[1,1.3,5],[2,1.01,12]],"ltp":4.3,"tv":9.7,"id":20586366}]}]}
{"op":"mcm","clk":"4234840139","pt":1631550462967,"mc":[{"id":"1.187594320","rc":[{"batb":[[0,1.3,5],[1,1.01,12],[2,1.01,0]],"ltp":4.3,"tv":9.7,"id":20586366}]}]}
{"op":"mcm","clk":"4234840523","pt":1631550467877,"mc":[{"id":"1.187594320","rc":[{"batb":[[0,4.1,10],[1,1.3,5],[2,1.01,12]],"ltp":4.3,"tv":9.7,"id":20586366}]}]}
{"op":"mcm","clk":"4234842621","pt":1631550491755,"mc":[{"id":"1.187594320","rc":[{"batb":[[0,1.01,12],[1,1.01,0]],"ltp":0.0,"tv":0.0,"id":9637111},{"batb":[[0,1.3,5],[1,1.01,12],[2,1.01,0]],"ltp":4.3,"tv":9.7,"id":20586366}]}]}
{"op":"mcm","clk":"4234843163","pt":1631550496649,"mc":[{"id":"1.187594320","rc":[{"batb":[[0,1.23,130.43],[1,1.01,12]],"ltp":0.0,"tv":0.0,"id":9637111},{"batb":[[0,3.7,11.11],[1,1.3,5],[2,1.01,12]],"ltp":4.3,"tv":9.7,"id":20586366}]}]}
{"op":"mcm","clk":"4234846405","pt":1631550533589,"mc":[{"id":"1.187594320","rc":[{"batb":[[0,1.01,12],[1,1.01,0]],"ltp":0.0,"tv":0.0,"id":9637111},{"batb":[[0,1.3,5],[1,1.01,12],[2,1.01,0]],"ltp":4.3,"tv":9.7,"id":20586366}]}]}
{"op":"mcm","clk":"4234849555","pt":1631550566881,"mc":[{"id":"1.187594320","rc":[{"batb":[[0,1.23,130.43],[1,1.01,12]],"ltp":0.0,"tv":0.0,"id":9637111},{"batb":[[0,3.7,11.11],[1,1.3,5],[2,1.01,12]],"ltp":4.3,"tv":9.7,"id":20586366}]}]}
{"op":"mcm","clk":"4234851749","pt":1631550590414,"mc":[{"id":"1.187594320","rc":[{"batb":[[0,1.01,12],[1,1.01,0]],"ltp":0.0,"tv":0.0,"id":9637111},{"batb":[[0,1.3,5],[1,1.01,12],[2,1.01,0]],"ltp":4.3,"tv":9.7,"id":20586366}]}]}
{"op":"mcm","clk":"4234859336","pt":1631550663597,"mc":[{"id":"1.187594320","rc":[{"batb":[[0,1.28,107.14],[1,1.01,12]],"ltp":0.0,"tv":0.0,"id":9637111},{"batb":[[0,3.3,13.04],[1,1.3,5],[2,1.01,12]],"ltp":4.3,"tv":9.7,"id":20586366}]}]}
{"op":"mcm","clk":"4234865370","pt":1631550722419,"mc":[{"id":"1.187594320","rc":[{"batb":[[0,1.01,12],[1,1.01,0]],"ltp":0.0,"tv":0.0,"id":9637111},{"batb":[[0,1.3,5],[1,1.01,12],[2,1.01,0]],"ltp":4.3,"tv":9.7,"id":20586366}]}]}
{"op":"mcm","clk":"4234866030","pt":1631550727422,"mc":[{"id":"1.187594320","rc":[{"batb":[[0,1.23,130.43],[1,1.01,12]],"ltp":0.0,"tv":0.0,"id":9637111},{"batb":[[0,3.7,11.11],[1,1.3,5],[2,1.01,12]],"ltp":4.3,"tv":9.7,"id":20586366}]}]}
{"op":"mcm","clk":"4234870310","pt":1631550769577,"mc":[{"id":"1.187594320","rc":[{"batb":[[0,1.01,12],[1,1.01,0]],"ltp":0.0,"tv":0.0,"id":9637111},{"batb":[[0,1.3,5],[1,1.01,12],[2,1.01,0]],"ltp":4.3,"tv":9.7,"id":20586366}]}]}
{"op":"mcm","clk":"4234870781","pt":1631550774562,"mc":[{"id":"1.187594320","rc":[{"batb":[[0,1.2,150],[1,1.01,12]],"ltp":0.0,"tv":0.0,"id":9637111},{"batb":[[0,3.95,10.16],[1,1.3,5],[2,1.01,12]],"ltp":4.3,"tv":9.7,"id":20586366}]}]}
{"op":"mcm","clk":"4234874683","pt":1631550813252,"mc":[{"id":"1.187594320","rc":[{"batb":[[0,1.01,12],[1,1.01,0]],"ltp":0.0,"tv":0.0,"id":9637111},{"batb":[[0,1.3,5],[1,1.01,12],[2,1.01,0]],"ltp":4.3,"tv":9.7,"id":20586366}]}]}
{"op":"mcm","clk":"4234875166","pt":1631550818255,"mc":[{"id":"1.187594320","rc":[{"batb":[[0,1.18,166.66],[1,1.01,12]],"ltp":0.0,"tv":0.0,"id":9637111},{"batb":[[0,4.1,10],[1,1.3,5],[2,1.01,12]],"ltp":4.3,"tv":9.7,"id":20586366}]}]}
{"op":"mcm","clk":"4234883963","pt":1631550904625,"mc":[{"id":"1.187594320","rc":[{"batb":[[0,1.01,12],[1,1.01,0]],"ltp":0.0,"tv":0.0,"id":9637111},{"batb":[[0,1.3,5],[1,1.01,12],[2,1.01,0]],"ltp":4.3,"tv":9.7,"id":20586366}]}]}
{"op":"mcm","clk":"4234884465","pt":1631550909501,"mc":[{"id":"1.187594320","rc":[{"batb":[[0,1.12,249.99],[1,1.01,12]],"ltp":0.0,"tv":0.0,"id":9637111},{"batb":[[0,5.3,10],[1,1.3,5],[2,1.01,12]],"ltp":4.3,"tv":9.7,"id":20586366}]}]}
{"op":"mcm","clk":"4234887403","pt":1631550937388,"mc":[{"id":"1.187594320","rc":[{"batb":[[0,1.01,12],[1,1.01,0]],"ltp":0.0,"tv":0.0,"id":9637111},{"batb":[[0,1.3,5],[1,1.01,12],[2,1.01,0]],"ltp":4.3,"tv":9.7,"id":20586366}]}]}
{"op":"mcm","clk":"4234887910","pt":1631550942273,"mc":[{"id":"1.187594320","rc":[{"batb":[[0,1.18,166.66],[1,1.01,12]],"ltp":0.0,"tv":0.0,"id":9637111},{"batb":[[0,4.3,10],[1,1.3,5],[2,1.01,12]],"ltp":4.3,"tv":9.7,"id":20586366}]}]}
{"op":"mcm","clk":"4234891986","pt":1631550982437,"mc":[{"id":"1.187594320","rc":[{"batb":[[0,1.01,12],[1,1.01,0]],"ltp":0.0,"tv":0.0,"id":9637111},{"batb":[[0,1.3,5],[1,1.01,12],[2,1.01,0]],"ltp":4.3,"tv":9.7,"id":20586366}]}]}
{"op":"mcm","clk":"4234892486","pt":1631550987343,"mc":[{"id":"1.187594320","rc":[{"batb":[[0,1.12,249.99],[1,1.01,12]],"ltp":0.0,"tv":0.0,"id":9637111},{"batb":[[0,5.3,10],[1,1.3,5],[2,1.01,12]],"ltp":4.3,"tv":9.7,"id":20586366}]}]}
{"op":"mcm","clk":"4234896815","pt":1631551029370,"mc":[{"id":"1.187594320","rc":[{"batb":[[0,1.01,12],[1,1.01,0]],"ltp":0.0,"tv":0.0,"id":9637111},{"batb":[[0,1.3,5],[1,1.01,12],[2,1.01,0]],"ltp":4.3,"tv":9.7,"id":20586366}]}]}
{"op":"mcm","clk":"4234897289","pt":1631551034274,"mc":[{"id":"1.187594320","rc":[{"batb":[[0,1.11,272.72],[1,1.01,12]],"ltp":0.0,"tv":0.0,"id":9637111},{"batb":[[0,5.8,10],[1,1.3,5],[2,1.01,12]],"ltp":4.3,"tv":9.7,"id":20586366}]}]}
{"op":"mcm","clk":"4234900187","pt":1631551062920,"mc":[{"id":"1.187594320","rc":[{"batb":[[0,1.01,12],[1,1.01,0]],"ltp":0.0,"tv":0.0,"id":9637111},{"batb":[[0,1.3,5],[1,1.01,12],[2,1.01,0]],"ltp":4.3,"tv":9.7,"id":20586366}]}]}
{"op":"mcm","clk":"4234900748","pt":1631551067817,"mc":[{"id":"1.187594320","rc":[{"batb":[[0,1.08,374.99],[1,1.01,12]],"ltp":0.0,"tv":0.0,"id":9637111},{"batb":[[0,6,10],[1,1.3,5],[2,1.01,12]],"ltp":4.3,"tv":9.7,"id":20586366}]}]}
{"op":"mcm","clk":"4234912581","pt":1631551182123,"mc":[{"id":"1.187594320","rc":[{"batb":[[0,1.01,12],[1,1.01,0]],"ltp":0.0,"tv":0.0,"id":9637111},{"batb":[[0,1.3,5],[1,1.01,12],[2,1.01,0]],"ltp":4.3,"tv":9.7,"id":20586366}]}]}
{"op":"mcm","clk":"4234913110","pt":1631551187038,"mc":[{"id":"1.187594320","rc":[{"batb":[[0,1.06,499.99],[1,1.01,12]],"ltp":0.0,"tv":0.0,"id":9637111},{"batb":[[0,7,10],[1,1.3,5],[2,1.01,12]],"ltp":4.3,"tv":9.7,"id":20586366}]}]}
{"op":"mcm","clk":"4234917480","pt":1631551228132,"mc":[{"id":"1.187594320","rc":[{"batb":[[0,1.01,12],[1,1.01,0]],"ltp":0.0,"tv":0.0,"id":9637111},{"batb":[[0,1.3,5],[1,1.01,12],[2,1.01,0]],"ltp":4.3,"tv":9.7,"id":20586366}]}]}
{"op":"mcm","clk":"4234918009","pt":1631551233095,"mc":[{"id":"1.187594320","rc":[{"batb":[[0,1.05,599.99],[1,1.01,12]],"ltp":0.0,"tv":0.0,"id":9637111},{"batb":[[0,7.6,10],[1,1.3,5],[2,1.01,12]],"ltp":4.3,"tv":9.7,"id":20586366}]}]}
{"op":"mcm","clk":"4234923166","pt":1631551284382,"mc":[{"id":"1.187594320","rc":[{"batb":[[0,1.01,12],[1,1.01,0]],"ltp":0.0,"tv":0.0,"id":9637111},{"batb":[[0,1.3,5],[1,1.01,12],[2,1.01,0]],"ltp":4.3,"tv":9.7,"id":20586366}]}]}
{"op":"mcm","clk":"4234923641","pt":1631551289392,"mc":[{"id":"1.187594320","rc":[{"batb":[[0,1.06,499.99],[1,1.01,12]],"ltp":0.0,"tv":0.0,"id":9637111},{"batb":[[0,7,10],[1,1.3,5],[2,1.01,12]],"ltp":4.3,"tv":9.7,"id":20586366}]}]}
{"op":"mcm","clk":"4234927326","pt":1631551328057,"mc":[{"id":"1.187594320","rc":[{"batb":[[0,1.01,12],[1,1.01,0]],"ltp":0.0,"tv":0.0,"id":9637111},{"batb":[[0,1.3,5],[1,1.01,12],[2,1.01,0]],"ltp":4.3,"tv":9.7,"id":20586366}]}]}
{"op":"mcm","clk":"4234927834","pt":1631551332962,"mc":[{"id":"1.187594320","rc":[{"batb":[[0,1.08,374.99],[1,1.01,12]],"ltp":0.0,"tv":0.0,"id":9637111},{"batb":[[0,6,10],[1,1.3,5],[2,1.01,12]],"ltp":4.3,"tv":9.7,"id":20586366}]}]}
{"op":"mcm","clk":"4234931526","pt":1631551372031,"mc":[{"id":"1.187594320","rc":[{"batb":[[0,1.01,12],[1,1.01,0]],"ltp":0.0,"tv":0.0,"id":9637111},{"batb":[[0,1.3,5],[1,1.01,12],[2,1.01,0]],"ltp":4.3,"tv":9.7,"id":20586366}]}]}
{"op":"mcm","clk":"4234932013","pt":1631551377054,"mc":[{"id":"1.187594320","rc":[{"batb":[[0,1.12,249.99],[1,1.01,12]],"ltp":0.0,"tv":0.0,"id":9637111},{"batb":[[0,5.3,10],[1,1.3,5],[2,1.01,12]],"ltp":4.3,"tv":9.7,"id":20586366}]}]}
{"op":"mcm","clk":"4234934741","pt":1631551403497,"mc":[{"id":"1.187594320","rc":[{"batb":[[0,1.01,12],[1,1.01,0]],"ltp":0.0,"tv":0.0,"id":9637111},{"batb":[[0,1.3,5],[1,1.01,12],[2,1.01,0]],"ltp":4.3,"tv":9.7,"id":20586366}]}]}
{"op":"mcm","clk":"4234935244","pt":1631551408402,"mc":[{"id":"1.187594320","rc":[{"batb":[[0,1.08,374.99],[1,1.01,12]],"ltp":0.0,"tv":0.0,"id":9637111},{"batb":[[0,6,10],[1,1.3,5],[2,1.01,12]],"ltp":4.3,"tv":9.7,"id":20586366}]}]}
{"op":"mcm","clk":"4234938705","pt":1631551440563,"mc":[{"id":"1.187594320","rc":[{"batb":[[0,1.01,12],[1,1.01,0]],"ltp":0.0,"tv":0.0,"id":9637111}]}]}
{"op":"mcm","clk":"4234939301","pt":1631551445561,"mc":[{"id":"1.187594320","rc":[{"batb":[[0,1.06,499.99],[1,1.01,12]],"ltp":0.0,"tv":0.0,"id":9637111}]}]}
{"op":"mcm","clk":"4234942457","pt":1631551473507,"mc":[{"id":"1.187594320","rc":[{"batb":[[0,1.01,12],[1,1.01,0]],"ltp":0.0,"tv":0.0,"id":9637111},{"batb":[[0,1.3,5],[1,1.01,12],[2,1.01,0]],"ltp":4.3,"tv":9.7,"id":20586366}]}]}
{"op":"mcm","clk":"4234942987","pt":1631551478413,"mc":[{"id":"1.187594320","rc":[{"batb":[[0,1.11,272.72],[1,1.01,12]],"ltp":0.0,"tv":0.0,"id":9637111},{"batb":[[0,5.8,10],[1,1.3,5],[2,1.01,12]],"ltp":4.3,"tv":9.7,"id":20586366}]}]}
{"op":"mcm","clk":"4234948023","pt":1631551523722,"mc":[{"id":"1.187594320","rc":[{"batb":[[0,1.01,12],[1,1.01,0]],"ltp":0.0,"tv":0.0,"id":9637111},{"batb":[[0,1.3,5],[1,1.01,12],[2,1.01,0]],"ltp":4.3,"tv":9.7,"id":20586366}]}]}
{"op":"mcm","clk":"4234948628","pt":1631551528723,"mc":[{"id":"1.187594320","rc":[{"batb":[[0,1.08,374.99],[1,1.01,12]],"ltp":0.0,"tv":0.0,"id":9637111},{"batb":[[0,6,10],[1,1.3,5],[2,1.01,12]],"ltp":4.3,"tv":9.7,"id":20586366}]}]}
{"op":"mcm","clk":"4234950193","pt":1631551543149,"mc":[{"id":"1.187594320","rc":[{"trd":[[1.08,3.42]],"batb":[[0,1.01,12],[1,1.01,0]],"ltp":1.08,"tv":3.41,"id":9637111}],"tv":13.11}]}
{"op":"mcm","clk":"4234950661","pt":1631551548051,"mc":[{"id":"1.187594320","rc":[{"batb":[[0,1.08,374.99],[1,1.01,12]],"ltp":1.08,"tv":3.41,"id":9637111}]}]}
{"op":"mcm","clk":"4234952153","pt":1631551562694,"mc":[{"id":"1.187594320","rc":[{"batb":[[0,1.01,12],[1,1.01,0]],"ltp":1.08,"tv":3.41,"id":9637111},{"batb":[[0,1.3,5],[1,1.01,12],[2,1.01,0]],"ltp":4.3,"tv":9.7,"id":20586366}]}]}
{"op":"mcm","clk":"4234952579","pt":1631551567581,"mc":[{"id":"1.187594320","rc":[{"batb":[[0,1.05,599.99],[1,1.01,12]],"ltp":1.08,"tv":3.41,"id":9637111},{"batb":[[0,7.6,10],[1,1.3,5],[2,1.01,12]],"ltp":4.3,"tv":9.7,"id":20586366}]}]}
{"op":"mcm","clk":"4234957716","pt":1631551618167,"mc":[{"id":"1.187594320","rc":[{"batb":[[0,1.01,12],[1,1.01,0]],"ltp":1.08,"tv":3.41,"id":9637111},{"batb":[[0,1.3,5],[1,1.01,12],[2,1.01,0]],"ltp":4.3,"tv":9.7,"id":20586366}]}]}
{"op":"mcm","clk":"4234958270","pt":1631551623190,"mc":[{"id":"1.187594320","rc":[{"batb":[[0,1.04,749.99],[1,1.01,12]],"ltp":1.08,"tv":3.41,"id":9637111},{"batb":[[0,8,10],[1,1.3,5],[2,1.01,12]],"ltp":4.3,"tv":9.7,"id":20586366}]}]}
{"op":"mcm","clk":"4234961550","pt":1631551653242,"mc":[{"id":"1.187594320","rc":[{"batb":[[0,1.01,12],[1,1.01,0]],"ltp":1.08,"tv":3.41,"id":9637111},{"batb":[[0,1.3,5],[1,1.01,12],[2,1.01,0]],"ltp":4.3,"tv":9.7,"id":20586366}]}]}
{"op":"mcm","clk":"4234962098","pt":1631551658351,"mc":[{"id":"1.187594320","rc":[{"batb":[[0,1.05,599.99],[1,1.01,12]],"ltp":1.08,"tv":3.41,"id":9637111},{"batb":[[0,7.6,10],[1,1.3,5],[2,1.01,12]],"ltp":4.3,"tv":9.7,"id":20586366}]}]}
{"op":"mcm","clk":"4234973367","pt":1631551683176,"mc":[{"id":"1.187594320","rc":[{"batb":[[0,1.01,12],[1,1.01,0]],"ltp":1.08,"tv":3.41,"id":9637111},{"batb":[[0,1.3,5],[1,1.01,12],[2,1.01,0]],"ltp":4.3,"tv":9.7,"id":20586366}]}]}
{"op":"mcm","clk":"4234973896","pt":1631551688221,"mc":[{"id":"1.187594320","rc":[{"batb":[[0,1.06,499.99],[1,1.01,12]],"ltp":1.08,"tv":3.41,"id":9637111},{"batb":[[0,7,10],[1,1.3,5],[2,1.01,12]],"ltp":4.3,"tv":9.7,"id":20586366}]}]}
{"op":"mcm","clk":"4234977355","pt":1631551721041,"mc":[{"id":"1.187594320","rc":[{"batb":[[0,1.01,12],[1,1.01,0]],"ltp":1.08,"tv":3.41,"id":9637111},{"batb":[[0,1.3,5],[1,1.01,12],[2,1.01,0]],"ltp":4.3,"tv":9.7,"id":20586366}]}]}
{"op":"mcm","clk":"4234977805","pt":1631551725952,"mc":[{"id":"1.187594320","rc":[{"batb":[[0,1.05,599.99],[1,1.01,12]],"ltp":1.08,"tv":3.41,"id":9637111},{"batb":[[0,7.6,10],[1,1.3,5],[2,1.01,12]],"ltp":4.3,"tv":9.7,"id":20586366}]}]}
{"op":"mcm","clk":"4234981766","pt":1631551763924,"mc":[{"id":"1.187594320","rc":[{"batb":[[0,1.01,12],[1,1.01,0]],"ltp":1.08,"tv":3.41,"id":9637111},{"batb":[[0,1.3,5],[1,1.01,12],[2,1.01,0]],"ltp":4.3,"tv":9.7,"id":20586366}]}]}
{"op":"mcm","clk":"4234982336","pt":1631551768955,"mc":[{"id":"1.187594320","rc":[{"batb":[[0,1.08,374.99],[1,1.01,12]],"ltp":1.08,"tv":3.41,"id":9637111},{"batb":[[0,6,10],[1,1.3,5],[2,1.01,12]],"ltp":4.3,"tv":9.7,"id":20586366}]}]}
{"op":"mcm","clk":"4235002052","pt":1631551970005,"mc":[{"id":"1.187594320","rc":[{"batb":[[0,1.01,12],[1,1.01,0]],"ltp":1.08,"tv":3.41,"id":9637111},{"batb":[[0,1.3,5],[1,1.01,12],[2,1.01,0]],"ltp":4.3,"tv":9.7,"id":20586366}]}]}
{"op":"mcm","clk":"4235002525","pt":1631551974948,"mc":[{"id":"1.187594320","rc":[{"batb":[[0,1.05,599.99],[1,1.01,12]],"ltp":1.08,"tv":3.41,"id":9637111},{"batb":[[0,7.6,10],[1,1.3,5],[2,1.01,12]],"ltp":4.3,"tv":9.7,"id":20586366}]}]}
{"op":"mcm","clk":"4235005975","pt":1631552008477,"mc":[{"id":"1.187594320","rc":[{"batb":[[0,1.01,12],[1,1.01,0]],"ltp":1.08,"tv":3.41,"id":9637111},{"batb":[[0,1.3,5],[1,1.01,12],[2,1.01,0]],"ltp":4.3,"tv":9.7,"id":20586366}]}]}
{"op":"mcm","clk":"4235006464","pt":1631552013382,"mc":[{"id":"1.187594320","rc":[{"batb":[[0,1.08,374.99],[1,1.01,12]],"ltp":1.08,"tv":3.41,"id":9637111},{"batb":[[0,6,10],[1,1.3,5],[2,1.01,12]],"ltp":4.3,"tv":9.7,"id":20586366}]}]}
{"op":"mcm","clk":"4235008936","pt":1631552039931,"mc":[{"id":"1.187594320","rc":[{"batb":[[0,1.01,12],[1,1.01,0]],"ltp":1.08,"tv":3.41,"id":9637111},{"batb":[[0,1.3,5],[1,1.01,12],[2,1.01,0]],"ltp":4.3,"tv":9.7,"id":20586366}]}]}
{"op":"mcm","clk":"4235009479","pt":1631552044890,"mc":[{"id":"1.187594320","rc":[{"batb":[[0,1.05,599.99],[1,1.01,12]],"ltp":1.08,"tv":3.41,"id":9637111},{"batb":[[0,7.6,10],[1,1.3,5],[2,1.01,12]],"ltp":4.3,"tv":9.7,"id":20586366}]}]}
{"op":"mcm","clk":"4235017171","pt":1631552119409,"mc":[{"id":"1.187594320","rc":[{"batb":[[0,1.01,12],[1,1.01,0]],"ltp":1.08,"tv":3.41,"id":9637111},{"batb":[[0,1.3,5],[1,1.01,12],[2,1.01,0]],"ltp":4.3,"tv":9.7,"id":20586366}]}]}
{"op":"mcm","clk":"4235017680","pt":1631552124308,"mc":[{"id":"1.187594320","rc":[{"batb":[[0,1.04,749.99],[1,1.01,12]],"ltp":1.08,"tv":3.41,"id":9637111},{"batb":[[0,8.6,10],[1,1.3,5],[2,1.01,12]],"ltp":4.3,"tv":9.7,"id":20586366}]}]}
{"op":"mcm","clk":"4235019549","pt":1631552141877,"mc":[{"id":"1.187594320","rc":[{"batb":[[0,1.3,5],[1,1.01,12],[2,1.01,0]],"ltp":4.3,"tv":9.7,"id":20586366}]}]}
{"op":"mcm","clk":"4235019990","pt":1631552146672,"mc":[{"id":"1.187594320","rc":[{"batb":[[0,7.6,10],[1,1.3,5],[2,1.01,12]],"ltp":4.3,"tv":9.7,"id":20586366}]}]}
{"op":"mcm","clk":"4235022466","pt":1631552169796,"mc":[{"id":"1.187594320","rc":[{"batb":[[0,1.3,5],[1,1.01,12],[2,1.01,0]],"ltp":4.3,"tv":9.7,"id":20586366}]}]}
{"op":"mcm","clk":"4235022984","pt":1631552174690,"mc":[{"id":"1.187594320","rc":[{"batb":[[0,8.6,10],[1,1.3,5],[2,1.01,12]],"ltp":4.3,"tv":9.7,"id":20586366}]}]}
{"op":"mcm","clk":"4235026319","pt":1631552208147,"mc":[{"id":"1.187594320","rc":[{"batb":[[0,1.01,12],[1,1.01,0]],"ltp":1.08,"tv":3.41,"id":9637111},{"batb":[[0,1.3,5],[1,1.01,12],[2,1.01,0]],"ltp":4.3,"tv":9.7,"id":20586366}]}]}
{"op":"mcm","clk":"4235026812","pt":1631552213024,"mc":[{"id":"1.187594320","rc":[{"batb":[[0,1.03,999.99],[1,1.01,12]],"ltp":1.08,"tv":3.41,"id":9637111},{"batb":[[0,9.6,10],[1,1.3,5],[2,1.01,12]],"ltp":4.3,"tv":9.7,"id":20586366}]}]}
{"op":"mcm","clk":"4235031283","pt":1631552257002,"mc":[{"id":"1.187594320","rc":[{"batb":[[0,1.01,12],[1,1.01,0]],"ltp":1.08,"tv":3.41,"id":9637111}]}]}
{"op":"mcm","clk":"4235031803","pt":1631552261995,"mc":[{"id":"1.187594320","rc":[{"batb":[[0,1.02,1499.99],[1,1.01,12]],"ltp":1.08,"tv":3.41,"id":9637111}]}]}
{"op":"mcm","clk":"4235086874","pt":1631552670835,"mc":[{"id":"1.187594320","rc":[{"trd":[[1.08,3.42]],"batb":[[0,1.01,12],[1,1.01,0]],"ltp":1.08,"tv":3.41,"id":9637111},{"trd":[[4.3,6.93],[5,2.77]],"batb":[[0,1.3,5],[1,1.01,12],[2,1.01,0]],"ltp":4.3,"tv":9.69,"id":20586366}],"tv":13.11}]}
{"op":"mcm","clk":"4235087646","pt":1631552675725,"mc":[{"id":"1.187594320","rc":[{"batb":[[0,11,10],[1,1.3,5],[2,1.01,12]],"ltp":4.3,"tv":9.69,"id":20586366}]}]}
{"op":"mcm","clk":"4235091263","pt":1631552700469,"mc":[{"id":"1.187594320","rc":[{"batb":[[0,1.3,5],[1,1.01,12],[2,1.01,0]],"ltp":4.3,"tv":9.69,"id":20586366}]}]}
{"op":"mcm","clk":"4235092072","pt":1631552705448,"mc":[{"id":"1.187594320","rc":[{"batb":[[0,14,10],[1,1.3,5],[2,1.01,12]],"ltp":4.3,"tv":9.69,"id":20586366}]}]}
{"op":"mcm","clk":"4235095395","pt":1631552726292,"mc":[{"id":"1.187594320","rc":[{"batb":[[0,1.3,5],[1,1.01,12],[2,1.01,0]],"ltp":4.3,"tv":9.69,"id":20586366}]}]}
{"op":"mcm","clk":"4235096142","pt":1631552731188,"mc":[{"id":"1.187594320","rc":[{"batb":[[0,11,10],[1,1.3,5],[2,1.01,12]],"ltp":4.3,"tv":9.69,"id":20586366}]}]}
{"op":"mcm","clk":"4235099183","pt":1631552751838,"mc":[{"id":"1.187594320","rc":[{"batb":[[0,1.3,5],[1,1.01,12],[2,1.01,0]],"ltp":4.3,"tv":9.69,"id":20586366}]}]}
{"op":"mcm","clk":"4235099965","pt":1631552756844,"mc":[{"id":"1.187594320","rc":[{"batb":[[0,12,10],[1,1.3,5],[2,1.01,12]],"ltp":4.3,"tv":9.69,"id":20586366}]}]}
{"op":"mcm","clk":"4235103760","pt":1631552781047,"mc":[{"id":"1.187594320","rc":[{"batb":[[0,1.3,5],[1,1.01,12],[2,1.01,0]],"ltp":4.3,"tv":9.69,"id":20586366}]}]}
{"op":"mcm","clk":"4235104592","pt":1631552786057,"mc":[{"id":"1.187594320","rc":[{"batb":[[0,14,10],[1,1.3,5],[2,1.01,12]],"ltp":4.3,"tv":9.69,"id":20586366}]}]}
{"op":"mcm","clk":"4235116119","pt":1631552857562,"mc":[{"id":"1.187594320","rc":[{"batb":[[0,1.3,5],[1,1.01,12],[2,1.01,0]],"ltp":4.3,"tv":9.69,"id":20586366}]}]}
{"op":"mcm","clk":"4235116900","pt":1631552862460,"mc":[{"id":"1.187594320","rc":[{"batb":[[0,12,10],[1,1.3,5],[2,1.01,12]],"ltp":4.3,"tv":9.69,"id":20586366}]}]}
{"op":"mcm","clk":"4235121530","pt":1631552891292,"mc":[{"id":"1.187594320","rc":[{"batb":[[0,1.3,5],[1,1.01,12],[2,1.01,0]],"ltp":4.3,"tv":9.69,"id":20586366}]}]}
{"op":"mcm","clk":"4235122271","pt":1631552896200,"mc":[{"id":"1.187594320","rc":[{"batb":[[0,1.02,1499.99],[1,1.01,12]],"ltp":1.08,"tv":3.41,"id":9637111},{"batb":[[0,10,10],[1,1.3,5],[2,1.01,12]],"ltp":4.3,"tv":9.69,"id":20586366}]}]}
{"op":"mcm","clk":"4235125363","pt":1631552916946,"mc":[{"id":"1.187594320","rc":[{"batb":[[0,1.01,12],[1,1.01,0]],"ltp":1.08,"tv":3.41,"id":9637111},{"batb":[[0,1.3,5],[1,1.01,12],[2,1.01,0]],"ltp":4.3,"tv":9.69,"id":20586366}]}]}
{"op":"mcm","clk":"4235126154","pt":1631552921849,"mc":[{"id":"1.187594320","rc":[{"batb":[[0,11,10],[1,1.3,5],[2,1.01,12]],"ltp":4.3,"tv":9.69,"id":20586366}]}]}
{"op":"mcm","clk":"4235128981","pt":1631552940040,"mc":[{"id":"1.187594320","rc":[{"batb":[[0,1.3,5],[1,1.01,12],[2,1.01,0]],"ltp":4.3,"tv":9.69,"id":20586366}]}]}
{"op":"mcm","clk":"4235129781","pt":1631552945048,"mc":[{"id":"1.187594320","rc":[{"batb":[[0,12,10],[1,1.3,5],[2,1.01,12]],"ltp":4.3,"tv":9.69,"id":20586366}]}]}
{"op":"mcm","clk":"4235130688","pt":1631552950836,"mc":[{"id":"1.187594320","rc":[{"batb":[[0,1.3,5],[1,1.01,12],[2,1.01,0]],"ltp":4.3,"tv":9.69,"id":20586366}]}]}
{"op":"mcm","clk":"4235131388","pt":1631552955786,"mc":[{"id":"1.187594320","rc":[{"batb":[[0,1.02,1499.99],[1,1.01,12]],"ltp":1.08,"tv":3.41,"id":9637111},{"batb":[[0,10,10],[1,1.3,5],[2,1.01,12]],"ltp":4.3,"tv":9.69,"id":20586366}]}]}
{"op":"mcm","clk":"4235135460","pt":1631552984734,"mc":[{"id":"1.187594320","rc":[{"batb":[[0,1.01,12],[1,1.01,0]],"ltp":1.08,"tv":3.41,"id":9637111},{"batb":[[0,1.3,5],[1,1.01,12],[2,1.01,0]],"ltp":4.3,"tv":9.69,"id":20586366}]}]}
{"op":"mcm","clk":"4235136200","pt":1631552989616,"mc":[{"id":"1.187594320","rc":[{"batb":[[0,1.03,999.99],[1,1.01,12]],"ltp":1.08,"tv":3.41,"id":9637111},{"batb":[[0,8.6,10],[1,1.3,5],[2,1.01,12]],"ltp":4.3,"tv":9.69,"id":20586366}]}]}
{"op":"mcm","clk":"4235143191","pt":1631553037478,"mc":[{"id":"1.187594320","rc":[{"batb":[[0,1.01,12],[1,1.01,0]],"ltp":1.08,"tv":3.41,"id":9637111},{"batb":[[0,1.3,5],[1,1.01,12],[2,1.01,0]],"ltp":4.3,"tv":9.69,"id":20586366}]}]}
{"op":"mcm","clk":"4235143931","pt":1631553042501,"mc":[{"id":"1.187594320","rc":[{"batb":[[0,1.02,1499.99],[1,1.01,12]],"ltp":1.08,"tv":3.41,"id":9637111},{"batb":[[0,10,10],[1,1.3,5],[2,1.01,12]],"ltp":4.3,"tv":9.69,"id":20586366}]}]}
{"op":"mcm","clk":"4235149223","pt":1631553077332,"mc":[{"id":"1.187594320","rc":[{"batb":[[0,1.01,12],[1,1.01,0]],"ltp":1.08,"tv":3.41,"id":9637111},{"batb":[[0,1.3,5],[1,1.01,12],[2,1.01,0]],"ltp":4.3,"tv":9.69,"id":20586366}]}]}
{"op":"mcm","clk":"4235150005","pt":1631553082333,"mc":[{"id":"1.187594320","rc":[{"batb":[[0,11,10],[1,1.3,5],[2,1.01,12]],"ltp":4.3,"tv":9.69,"id":20586366}]}]}
{"op":"mcm","clk":"4235155950","pt":1631553121475,"mc":[{"id":"1.187594320","rc":[{"batb":[[0,1.3,5],[1,1.01,12],[2,1.01,0]],"ltp":4.3,"tv":9.69,"id":20586366}]}]}
{"op":"mcm","clk":"4235156663","pt":1631553126385,"mc":[{"id":"1.187594320","rc":[{"batb":[[0,12,10],[1,1.3,5],[2,1.01,12]],"ltp":4.3,"tv":9.69,"id":20586366}]}]}
{"op":"mcm","clk":"4235161387","pt":1631553157830,"mc":[{"id":"1.187594320","rc":[{"batb":[[0,1.3,5],[1,1.01,12],[2,1.01,0]],"ltp":4.3,"tv":9.69,"id":20586366}]}]}
{"op":"mcm","clk":"4235162155","pt":1631553162731,"mc":[{"id":"1.187594320","rc":[{"batb":[[0,14,10],[1,1.3,5],[2,1.01,12]],"ltp":4.3,"tv":9.69,"id":20586366}]}]}
{"op":"mcm","clk":"4235177680","pt":1631553270090,"mc":[{"id":"1.187594320","rc":[{"batb":[[0,1.3,5],[1,1.01,12],[2,1.01,0]],"ltp":4.3,"tv":9.69,"id":20586366}]}]}
{"op":"mcm","clk":"4235178397","pt":1631553274998,"mc":[{"id":"1.187594320","rc":[{"batb":[[0,16,10],[1,1.3,5],[2,1.01,12]],"ltp":4.3,"tv":9.69,"id":20586366}]}]}
{"op":"mcm","clk":"4235181992","pt":1631553299405,"mc":[{"id":"1.187594320","rc":[{"trd":[[1.01,24]],"batl":[[0,1.01,88],[1,1.47,100]],"ltp":1.01,"tv":27.41,"id":9637111}],"tv":37.11}]}
{"op":"mcm","clk":"4235183182","pt":1631553307127,"mc":[{"id":"1.187594320","rc":[{"batb":[[0,1.3,5],[1,1.01,12],[2,1.01,0]],"ltp":4.3,"tv":9.69,"id":20586366}]}]}
{"op":"mcm","clk":"4235183946","pt":1631553312107,"mc":[{"id":"1.187594320","rc":[{"batb":[[0,14,10],[1,1.3,5],[2,1.01,12]],"ltp":4.3,"tv":9.69,"id":20586366}]}]}
{"op":"mcm","clk":"4235186874","pt":1631553331569,"mc":[{"id":"1.187594320","rc":[{"batb":[[0,1.3,5],[1,1.01,12],[2,1.01,0]],"ltp":4.3,"tv":9.69,"id":20586366}]}]}
{"op":"mcm","clk":"4235187610","pt":1631553336468,"mc":[{"id":"1.187594320","rc":[{"batb":[[0,16,10],[1,1.3,5],[2,1.01,12]],"ltp":4.3,"tv":9.69,"id":20586366}]}]}
{"op":"mcm","clk":"4235193676","pt":1631553375954,"mc":[{"id":"1.187594320","rc":[{"batb":[[0,1.3,5],[1,1.01,12],[2,1.01,0]],"ltp":4.3,"tv":9.69,"id":20586366}]}]}
{"op":"mcm","clk":"4235194428","pt":1631553380796,"mc":[{"id":"1.187594320","rc":[{"batb":[[0,19.5,10],[1,1.3,5],[2,1.01,12]],"ltp":4.3,"tv":9.69,"id":20586366}]}]}
{"op":"mcm","clk":"4235198850","pt":1631553408838,"mc":[{"id":"1.187594320","rc":[{"batb":[[0,1.3,5],[1,1.01,12],[2,1.01,0]],"ltp":4.3,"tv":9.69,"id":20586366}]}]}
{"op":"mcm","clk":"4235199692","pt":1631553413841,"mc":[{"id":"1.187594320","rc":[{"batb":[[0,24,10],[1,1.3,5],[2,1.01,12]],"ltp":4.3,"tv":9.69,"id":20586366}]}]}
{"op":"mcm","clk":"4235206808","pt":1631553459836,"mc":[{"id":"1.187594320","rc":[{"batb":[[0,1.3,5],[1,1.01,12],[2,1.01,0]],"ltp":4.3,"tv":9.69,"id":20586366}]}]}
{"op":"mcm","clk":"4235207504","pt":1631553464784,"mc":[{"id":"1.187594320","rc":[{"batb":[[0,19.5,10],[1,1.3,5],[2,1.01,12]],"ltp":4.3,"tv":9.69,"id":20586366}]}]}
{"op":"mcm","clk":"4235213237","pt":1631553504239,"mc":[{"id":"1.187594320","rc":[{"batb":[[0,1.3,5],[1,1.01,12],[2,1.01,0]],"ltp":4.3,"tv":9.69,"id":20586366}]}]}
{"op":"mcm","clk":"4235213921","pt":1631553509242,"mc":[{"id":"1.187594320","rc":[{"batb":[[0,24,10],[1,1.3,5],[2,1.01,12]],"ltp":4.3,"tv":9.69,"id":20586366}]}]}
{"op":"mcm","clk":"4235216311","pt":1631553527290,"mc":[{"id":"1.187594320","rc":[{"batb":[[0,1.3,5],[1,1.01,12],[2,1.01,0]],"ltp":4.3,"tv":9.69,"id":20586366}]}]}
{"op":"mcm","clk":"4235217002","pt":1631553532288,"mc":[{"id":"1.187594320","rc":[{"batb":[[0,19.5,10],[1,1.3,5],[2,1.01,12]],"ltp":4.3,"tv":9.69,"id":20586366}]}]}
{"op":"mcm","clk":"4235221993","pt":1631553568357,"mc":[{"id":"1.187594320","rc":[{"batb":[[0,1.3,5],[1,1.01,12],[2,1.01,0]],"ltp":4.3,"tv":9.69,"id":20586366}]}]}
{"op":"mcm","clk":"4235222733","pt":1631553573353,"mc":[{"id":"1.187594320","rc":[{"batb":[[0,16,10],[1,1.3,5],[2,1.01,12]],"ltp":4.3,"tv":9.69,"id":20586366}]}]}
{"op":"mcm","clk":"4235229858","pt":1631553624786,"mc":[{"id":"1.187594320","rc":[{"batb":[[0,1.3,5],[1,1.01,12],[2,1.01,0]],"ltp":4.3,"tv":9.69,"id":20586366}]}]}
{"op":"mcm","clk":"4235230546","pt":1631553629798,"mc":[{"id":"1.187594320","rc":[{"batb":[[0,24,10],[1,1.3,5],[2,1.01,12]],"ltp":4.3,"tv":9.69,"id":20586366}]}]}
{"op":"mcm","clk":"4235233943","pt":1631553653686,"mc":[{"id":"1.187594320","rc":[{"batb":[[0,1.3,5],[1,1.01,12],[2,1.01,0]],"ltp":4.3,"tv":9.69,"id":20586366}]}]}
{"op":"mcm","clk":"4235234657","pt":1631553658423,"mc":[{"id":"1.187594320","rc":[{"batb":[[0,19.5,10],[1,1.3,5],[2,1.01,12]],"ltp":4.3,"tv":9.69,"id":20586366}]}]}
{"op":"mcm","clk":"4235236602","pt":1631553671558,"mc":[{"id":"1.187594320","rc":[{"batb":[[0,1.3,5],[1,1.01,12],[2,1.01,0]],"ltp":4.3,"tv":9.69,"id":20586366}]}]}
{"op":"mcm","clk":"4235237300","pt":1631553676481,"mc":[{"id":"1.187594320","rc":[{"batb":[[0,16,10],[1,1.3,5],[2,1.01,12]],"ltp":4.3,"tv":9.69,"id":20586366}]}]}
{"op":"mcm","clk":"4235244688","pt":1631553726067,"mc":[{"id":"1.187594320","rc":[{"batb":[[0,1.3,5],[1,1.01,12],[2,1.01,0]],"ltp":4.3,"tv":9.69,"id":20586366}]}]}
{"op":"mcm","clk":"4235245453","pt":1631553731057,"mc":[{"id":"1.187594320","rc":[{"batb":[[0,12,10],[1,1.3,5],[2,1.01,12]],"ltp":4.3,"tv":9.69,"id":20586366}]}]}
{"op":"mcm","clk":"4235259107","pt":1631553825260,"mc":[{"id":"1.187594320","rc":[{"batb":[[0,1.3,5],[1,1.01,12],[2,1.01,0]],"ltp":4.3,"tv":9.69,"id":20586366}]}]}
{"op":"mcm","clk":"4235259177","pt":1631553825679,"mc":[{"id":"1.187594320","rc":[{"trd":[[1.01,103.5]],"batl":[[0,1.01,48.25]],"ltp":1.01,"tv":106.91,"id":9637111}],"tv":116.61}]}
{"op":"mcm","clk":"4235259904","pt":1631553830257,"mc":[{"id":"1.187594320","rc":[{"batb":[[0,10,10],[1,1.3,5],[2,1.01,12]],"ltp":4.3,"tv":9.69,"id":20586366}]}]}
{"op":"mcm","clk":"4235261992","pt":1631553844692,"mc":[{"id":"1.187594320","rc":[{"batb":[[0,1.3,5],[1,1.01,12],[2,1.01,0]],"ltp":4.3,"tv":9.69,"id":20586366}]}]}
{"op":"mcm","clk":"4235262685","pt":1631553849694,"mc":[{"id":"1.187594320","rc":[{"batb":[[0,8.6,10],[1,1.3,5],[2,1.01,12]],"ltp":4.3,"tv":9.69,"id":20586366}]}]}
{"op":"mcm","clk":"4235264241","pt":1631553860892,"mc":[{"id":"1.187594320","rc":[{"trd":[[1.01,198.9]],"batl":[[0,1.47,100.55],[1,1.47,0]],"ltp":1.01,"tv":202.31,"id":9637111}],"tv":212.01}]}
{"op":"mcm","clk":"4235265674","pt":1631553870410,"mc":[{"id":"1.187594320","rc":[{"trd":[[1.01,200]],"batb":[[0,1.01,722.15]],"batl":[[0,1.47,100]],"ltp":1.01,"tv":203.41,"id":9637111}],"tv":213.11}]}
{"op":"mcm","clk":"4235266441","pt":1631553875623,"mc":[{"id":"1.187594320","rc":[{"batb":[[0,1.04,749.99],[1,1.01,722.15]],"ltp":1.01,"tv":203.41,"id":9637111}]}]}
{"op":"mcm","clk":"4235266977","pt":1631553879119,"mc":[{"id":"1.187594320","rc":[{"batb":[[0,1.01,722.15],[1,1.01,0]],"ltp":1.01,"tv":203.41,"id":9637111},{"batb":[[0,1.3,5],[1,1.01,12],[2,1.01,0]],"ltp":4.3,"tv":9.69,"id":20586366}]}]}
{"op":"mcm","clk":"4235267711","pt":1631553884125,"mc":[{"id":"1.187594320","rc":[{"batb":[[0,1.02,1499.99],[1,1.01,722.15]],"ltp":1.01,"tv":203.41,"id":9637111},{"batb":[[0,10,10],[1,1.3,5],[2,1.01,12]],"ltp":4.3,"tv":9.69,"id":20586366}]}]}
{"op":"mcm","clk":"4235268628","pt":1631553890219,"mc":[{"id":"1.187594320","rc":[{"batb":[[1,1.01,0]],"ltp":1.01,"tv":203.41,"id":9637111}]}]}
{"op":"mcm","clk":"4235272267","pt":1631553914156,"mc":[{"id":"1.187594320","rc":[{"batb":[[0,1.3,5],[1,1.01,12],[2,1.01,0]],"ltp":4.3,"tv":9.69,"id":20586366}]}]}
{"op":"mcm","clk":"4235273036","pt":1631553919066,"mc":[{"id":"1.187594320","rc":[{"batb":[[0,12,10],[1,1.3,5],[2,1.01,12]],"ltp":4.3,"tv":9.69,"id":20586366}]}]}
{"op":"mcm","clk":"4235276024","pt":1631553939008,"mc":[{"id":"1.187594320","rc":[{"batb":[[0,1.3,5],[1,1.01,12],[2,1.01,0]],"ltp":4.3,"tv":9.69,"id":20586366}]}]}
{"op":"mcm","clk":"4235276743","pt":1631553943914,"mc":[{"id":"1.187594320","rc":[{"batb":[[0,1.03,999.99]],"ltp":1.01,"tv":203.41,"id":9637111},{"batb":[[0,9.6,10],[1,1.3,5],[2,1.01,12]],"ltp":4.3,"tv":9.69,"id":20586366}]}]}
{"op":"mcm","clk":"4235278824","pt":1631553957730,"mc":[{"id":"1.187594320","rc":[{"batb":[[0,1.3,5],[1,1.01,12],[2,1.01,0]],"ltp":4.3,"tv":9.69,"id":20586366}]}]}
{"op":"mcm","clk":"4235279621","pt":1631553962745,"mc":[{"id":"1.187594320","rc":[{"batb":[[0,1.02,1499.99]],"ltp":1.01,"tv":203.41,"id":9637111},{"batb":[[0,10,10],[1,1.3,5],[2,1.01,12]],"ltp":4.3,"tv":9.69,"id":20586366}]}]}
{"op":"mcm","clk":"4235280089","pt":1631553965741,"mc":[{"id":"1.187594320","rc":[{"batl":[[0,1.05,14.45],[1,1.47,100]],"ltp":1.01,"tv":203.41,"id":9637111}]}]}
{"op":"mcm","clk":"4235280709","pt":1631553970738,"mc":[{"id":"1.187594320","rc":[{"batb":[[0,1.3,5],[1,1.01,12],[2,1.01,0]],"ltp":4.3,"tv":9.69,"id":20586366}]}]}
{"op":"mcm","clk":"4235281412","pt":1631553975663,"mc":[{"id":"1.187594320","rc":[{"batb":[[0,7.6,10],[1,1.3,5],[2,1.01,12]],"ltp":4.3,"tv":9.69,"id":20586366}]}]}
{"op":"mcm","clk":"4235285792","pt":1631554007294,"mc":[{"id":"1.187594320","rc":[{"batb":[[0,1.02,722.7]],"ltp":1.01,"tv":203.41,"id":9637111}]}]}
{"op":"mcm","clk":"4235291127","pt":1631554043634,"mc":[{"id":"1.187594320","rc":[{"batb":[[0,1.3,5],[1,1.01,12],[2,1.01,0]],"ltp":4.3,"tv":9.69,"id":20586366}]}]}
{"op":"mcm","clk":"4235291805","pt":1631554048622,"mc":[{"id":"1.187594320","rc":[{"trd":[[1.05,28.89]],"batl":[[0,1.47,100.01],[1,1.47,0]],"ltp":1.05,"tv":232.3,"id":9637111},{"batb":[[0,6,10],[1,1.3,5],[2,1.01,12]],"ltp":4.3,"tv":9.69,"id":20586366}],"tv":242.0}]}
{"op":"mcm","clk":"4235293268","pt":1631554059236,"mc":[{"id":"1.187594320","rc":[{"batl":[[0,1.47,100]],"ltp":1.05,"tv":232.3,"id":9637111}]}]}
{"op":"mcm","clk":"4235294004","pt":1631554064563,"mc":[{"id":"1.187594320","rc":[{"batb":[[0,1.08,374.99],[1,1.02,722.7]],"ltp":1.05,"tv":232.3,"id":9637111}]}]}
{"op":"mcm","clk":"4235295230","pt":1631554073364,"mc":[{"id":"1.187594320","rc":[{"batb":[[0,1.02,722.7],[1,1.02,0]],"ltp":1.05,"tv":232.3,"id":9637111},{"batb":[[0,1.3,5],[1,1.01,12],[2,1.01,0]],"ltp":4.3,"tv":9.69,"id":20586366}]}]}
{"op":"mcm","clk":"4235295913","pt":1631554078371,"mc":[{"id":"1.187594320","rc":[{"batb":[[0,1.05,599.99],[1,1.02,722.7]],"ltp":1.05,"tv":232.3,"id":9637111},{"batb":[[0,7.6,10],[1,1.3,5],[2,1.01,12]],"ltp":4.3,"tv":9.69,"id":20586366}]}]}
{"op":"mcm","clk":"4235296427","pt":1631554082169,"mc":[{"id":"1.187594320","rc":[{"batb":[[1,1.02,0]],"ltp":1.05,"tv":232.3,"id":9637111}]}]}
{"op":"mcm","clk":"4235301760","pt":1631554119796,"mc":[{"id":"1.187594320","rc":[{"batb":[[0,1.3,5],[1,1.01,12],[2,1.01,0]],"ltp":4.3,"tv":9.69,"id":20586366}]}]}
{"op":"mcm","clk":"4235302397","pt":1631554124732,"mc":[{"id":"1.187594320","rc":[{"batb":[[0,1.03,999.99]],"ltp":1.05,"tv":232.3,"id":9637111},{"batb":[[0,8.6,10],[1,1.3,5],[2,1.01,12]],"ltp":4.3,"tv":9.69,"id":20586366}]}]}
{"op":"mcm","clk":"4235307313","pt":1631554161094,"mc":[{"id":"1.187594320","rc":[{"batb":[[0,1.3,5],[1,1.01,12],[2,1.01,0]],"ltp":4.3,"tv":9.69,"id":20586366}]}]}
{"op":"mcm","clk":"4235308026","pt":1631554166058,"mc":[{"id":"1.187594320","rc":[{"batb":[[0,1.02,1499.99]],"ltp":1.05,"tv":232.3,"id":9637111},{"batb":[[0,10,10],[1,1.3,5],[2,1.01,12]],"ltp":4.3,"tv":9.69,"id":20586366}]}]}
{"op":"mcm","clk":"4235312030","pt":1631554194906,"mc":[{"id":"1.187594320","rc":[{"batb":[[0,1.3,5],[1,1.01,12],[2,1.01,0]],"ltp":4.3,"tv":9.69,"id":20586366}]}]}
{"op":"mcm","clk":"4235312746","pt":1631554199816,"mc":[{"id":"1.187594320","rc":[{"batb":[[0,12,10],[1,1.3,5],[2,1.01,12]],"ltp":4.3,"tv":9.69,"id":20586366}]}]}
{"op":"mcm","clk":"4235327756","pt":1631554300633,"mc":[{"id":"1.187594320","rc":[{"batb":[[0,1.3,5],[1,1.01,12],[2,1.01,0]],"ltp":4.3,"tv":9.69,"id":20586366}]}]}
{"op":"mcm","clk":"4235328504","pt":1631554305640,"mc":[{"id":"1.187594320","rc":[{"batb":[[0,16,10],[1,1.3,5],[2,1.01,12]],"ltp":4.3,"tv":9.69,"id":20586366}]}]}
{"op":"mcm","clk":"4235330458","pt":1631554318663,"mc":[{"id":"1.187594320","rc":[{"batb":[[0,1.3,5],[1,1.01,12],[2,1.01,0]],"ltp":4.3,"tv":9.69,"id":20586366}]}]}
{"op":"mcm","clk":"4235331177","pt":1631554323663,"mc":[{"id":"1.187594320","rc":[{"batb":[[0,12,10],[1,1.3,5],[2,1.01,12]],"ltp":4.3,"tv":9.69,"id":20586366}]}]}
{"op":"mcm","clk":"4235336576","pt":1631554358799,"mc":[{"id":"1.187594320","rc":[{"batb":[[0,1.3,5],[1,1.01,12],[2,1.01,0]],"ltp":4.3,"tv":9.69,"id":20586366}]}]}
{"op":"mcm","clk":"4235337369","pt":1631554363818,"mc":[{"id":"1.187594320","rc":[{"batb":[[0,1.02,1499.99]],"ltp":1.05,"tv":232.3,"id":9637111},{"batb":[[0,10,10],[1,1.3,5],[2,1.01,12]],"ltp":4.3,"tv":9.69,"id":20586366}]}]}
{"op":"mcm","clk":"4235342153","pt":1631554395480,"mc":[{"id":"1.187594320","rc":[{"batb":[[0,1.3,5],[1,1.01,12],[2,1.01,0]],"ltp":4.3,"tv":9.69,"id":20586366}]}]}
{"op":"mcm","clk":"4235342837","pt":1631554400379,"mc":[{"id":"1.187594320","rc":[{"batb":[[0,1.04,749.99]],"ltp":1.05,"tv":232.3,"id":9637111},{"batb":[[0,8,10],[1,1.3,5],[2,1.01,12]],"ltp":4.3,"tv":9.69,"id":20586366}]}]}
{"op":"mcm","clk":"4235350188","pt":1631554449248,"mc":[{"id":"1.187594320","rc":[{"batb":[[0,1.3,5],[1,1.01,12],[2,1.01,0]],"ltp":4.3,"tv":9.69,"id":20586366}]}]}
{"op":"mcm","clk":"4235350956","pt":1631554454033,"mc":[{"id":"1.187594320","rc":[{"batb":[[0,1.03,999.99]],"ltp":1.05,"tv":232.3,"id":9637111},{"batb":[[0,8.6,10],[1,1.3,5],[2,1.01,12]],"ltp":4.3,"tv":9.69,"id":20586366}]}]}
{"op":"mcm","clk":"4235358390","pt":1631554501843,"mc":[{"id":"1.187594320","rc":[{"batb":[[0,1.3,5],[1,1.01,12],[2,1.01,0]],"ltp":4.3,"tv":9.69,"id":20586366}]}]}
{"op":"mcm","clk":"4235359115","pt":1631554506703,"mc":[{"id":"1.187594320","rc":[{"batb":[[0,12,10],[1,1.3,5],[2,1.01,12]],"ltp":4.3,"tv":9.69,"id":20586366}]}]}
{"op":"mcm","clk":"4235362879","pt":1631554530548,"mc":[{"id":"1.187594320","rc":[{"batb":[[0,1.3,5],[1,1.01,12],[2,1.01,0]],"ltp":4.3,"tv":9.69,"id":20586366}]}]}
{"op":"mcm","clk":"4235363686","pt":1631554535434,"mc":[{"id":"1.187594320","rc":[{"batb":[[0,1.03,999.99]],"ltp":1.05,"tv":232.3,"id":9637111},{"batb":[[0,8.6,10],[1,1.3,5],[2,1.01,12]],"ltp":4.3,"tv":9.69,"id":20586366}]}]}
{"op":"mcm","clk":"4235367782","pt":1631554560900,"mc":[{"id":"1.187594320","rc":[{"trd":[[8.6,5.04]],"batb":[[0,1.3,5],[1,1.01,12],[2,1.01,0]],"ltp":8.6,"tv":14.73,"id":20586366}],"tv":247.04}]}
{"op":"mcm","clk":"4235368545","pt":1631554565773,"mc":[{"id":"1.187594320","rc":[{"batb":[[0,9.6,10],[1,1.3,5],[2,1.01,12]],"ltp":8.6,"tv":14.73,"id":20586366}]}]}
{"op":"mcm","clk":"4235371422","pt":1631554585197,"mc":[{"id":"1.187594320","rc":[{"batb":[[0,1.3,5],[1,1.01,12],[2,1.01,0]],"ltp":8.6,"tv":14.73,"id":20586366}]}]}
{"op":"mcm","clk":"4235372122","pt":1631554590185,"mc":[{"id":"1.187594320","rc":[{"batb":[[0,1.05,599.99]],"ltp":1.05,"tv":232.3,"id":9637111},{"batb":[[0,7.6,10],[1,1.3,5],[2,1.01,12]],"ltp":8.6,"tv":14.73,"id":20586366}]}]}
{"op":"mcm","clk":"4235378997","pt":1631554636737,"mc":[{"id":"1.187594320","rc":[{"batb":[[0,1.3,5],[1,1.01,12],[2,1.01,0]],"ltp":8.6,"tv":14.73,"id":20586366}]}]}
{"op":"mcm","clk":"4235379718","pt":1631554641636,"mc":[{"id":"1.187594320","rc":[{"batb":[[0,1.08,374.99]],"ltp":1.05,"tv":232.3,"id":9637111},{"batb":[[0,6,10],[1,1.3,5],[2,1.01,12]],"ltp":8.6,"tv":14.73,"id":20586366}]}]}
{"op":"mcm","clk":"4235383544","pt":1631554667299,"mc":[{"id":"1.187594320","rc":[{"batb":[[0,1.3,5],[1,1.01,12],[2,1.01,0]],"ltp":8.6,"tv":14.73,"id":20586366}]}]}
{"op":"mcm","clk":"4235384248","pt":1631554672185,"mc":[{"id":"1.187594320","rc":[{"batb":[[0,1.05,599.99]],"ltp":1.05,"tv":232.3,"id":9637111},{"batb":[[0,7.6,10],[1,1.3,5],[2,1.01,12]],"ltp":8.6,"tv":14.73,"id":20586366}]}]}
{"op":"mcm","clk":"4235390834","pt":1631554714314,"mc":[{"id":"1.187594320","rc":[{"batb":[[0,1.3,5],[1,1.01,12],[2,1.01,0]],"ltp":8.6,"tv":14.73,"id":20586366}]}]}
{"op":"mcm","clk":"4235391582","pt":1631554719309,"mc":[{"id":"1.187594320","rc":[{"batb":[[0,1.03,999.99]],"ltp":1.05,"tv":232.3,"id":9637111},{"batb":[[0,8.6,10],[1,1.3,5],[2,1.01,12]],"ltp":8.6,"tv":14.73,"id":20586366}]}]}
{"op":"mcm","clk":"4235395004","pt":1631554742858,"mc":[{"id":"1.187594320","rc":[{"batb":[[0,1.3,5],[1,1.01,12],[2,1.01,0]],"ltp":8.6,"tv":14.73,"id":20586366}]}]}
{"op":"mcm","clk":"4235395726","pt":1631554747749,"mc":[{"id":"1.187594320","rc":[{"batb":[[0,1.02,1499.99]],"ltp":1.05,"tv":232.3,"id":9637111},{"batb":[[0,10,10],[1,1.3,5],[2,1.01,12]],"ltp":8.6,"tv":14.73,"id":20586366}]}]}
{"op":"mcm","clk":"4235399587","pt":1631554773290,"mc":[{"id":"1.187594320","rc":[{"batb":[[0,1.3,5],[1,1.01,12],[2,1.01,0]],"ltp":8.6,"tv":14.73,"id":20586366}]}]}
{"op":"mcm","clk":"4235400351","pt":1631554778211,"mc":[{"id":"1.187594320","rc":[{"batb":[[0,12,10],[1,1.3,5],[2,1.01,12]],"ltp":8.6,"tv":14.73,"id":20586366}]}]}
{"op":"mcm","clk":"4235417304","pt":1631554889447,"mc":[{"id":"1.187594320","rc":[{"batb":[[0,1.3,5],[1,1.01,12],[2,1.01,0]],"ltp":8.6,"tv":14.73,"id":20586366}]}]}
{"op":"mcm","clk":"4235417959","pt":1631554894381,"mc":[{"id":"1.187594320","rc":[{"batb":[[0,16,10],[1,1.3,5],[2,1.01,12]],"ltp":8.6,"tv":14.73,"id":20586366}]}]}
{"op":"mcm","clk":"4235421080","pt":1631554917023,"mc":[{"id":"1.187594320","rc":[{"batb":[[0,1.3,5],[1,1.01,12],[2,1.01,0]],"ltp":8.6,"tv":14.73,"id":20586366}]}]}
{"op":"mcm","clk":"4235421804","pt":1631554921932,"mc":[{"id":"1.187594320","rc":[{"batb":[[0,12,10],[1,1.3,5],[2,1.01,12]],"ltp":8.6,"tv":14.73,"id":20586366}]}]}
{"op":"mcm","clk":"4235424731","pt":1631554942322,"mc":[{"id":"1.187594320","rc":[{"batb":[[0,1.3,5],[1,1.01,12],[2,1.01,0]],"ltp":8.6,"tv":14.73,"id":20586366}]}]}
{"op":"mcm","clk":"4235425518","pt":1631554947138,"mc":[{"id":"1.187594320","rc":[{"batb":[[0,14,10],[1,1.3,5],[2,1.01,12]],"ltp":8.6,"tv":14.73,"id":20586366}]}]}
{"op":"mcm","clk":"4235429199","pt":1631554972791,"mc":[{"id":"1.187594320","rc":[{"batb":[[0,1.3,5],[1,1.01,12],[2,1.01,0]],"ltp":8.6,"tv":14.73,"id":20586366}]}]}
{"op":"mcm","clk":"4235429948","pt":1631554977798,"mc":[{"id":"1.187594320","rc":[{"batb":[[0,1.03,999.99]],"ltp":1.05,"tv":232.3,"id":9637111},{"batb":[[0,9.6,10],[1,1.3,5],[2,1.01,12]],"ltp":8.6,"tv":14.73,"id":20586366}]}]}
{"op":"mcm","clk":"4235434669","pt":1631555008625,"mc":[{"id":"1.187594320","rc":[{"batb":[[0,1.3,5],[1,1.01,12],[2,1.01,0]],"ltp":8.6,"tv":14.73,"id":20586366}]}]}
{"op":"mcm","clk":"4235435434","pt":1631555013558,"mc":[{"id":"1.187594320","rc":[{"batb":[[0,12,10],[1,1.3,5],[2,1.01,12]],"ltp":8.6,"tv":14.73,"id":20586366}]}]}
{"op":"mcm","clk":"4235439179","pt":1631555037991,"mc":[{"id":"1.187594320","rc":[{"batb":[[0,1.3,5],[1,1.01,12],[2,1.01,0]],"ltp":8.6,"tv":14.73,"id":20586366}]}]}
{"op":"mcm","clk":"4235439938","pt":1631555042863,"mc":[{"id":"1.187594320","rc":[{"batb":[[0,1.04,749.99]],"ltp":1.05,"tv":232.3,"id":9637111},{"batb":[[0,8.6,10],[1,1.3,5],[2,1.01,12]],"ltp":8.6,"tv":14.73,"id":20586366}]}]}
{"op":"mcm","clk":"4235444089","pt":1631555070516,"mc":[{"id":"1.187594320","rc":[{"batb":[[0,1.3,5],[1,1.01,12],[2,1.01,0]],"ltp":8.6,"tv":14.73,"id":20586366}]}]}
{"op":"mcm","clk":"4235444864","pt":1631555075543,"mc":[{"id":"1.187594320","rc":[{"batb":[[0,1.03,999.99]],"ltp":1.05,"tv":232.3,"id":9637111},{"batb":[[0,9.6,10],[1,1.3,5],[2,1.01,12]],"ltp":8.6,"tv":14.73,"id":20586366}]}]}
{"op":"mcm","clk":"4235446091","pt":1631555083550,"mc":[{"id":"1.187594320","rc":[{"batb":[[0,1.3,5],[1,1.01,12],[2,1.01,0]],"ltp":8.6,"tv":14.73,"id":20586366}]}]}
{"op":"mcm","clk":"4235446934","pt":1631555088567,"mc":[{"id":"1.187594320","rc":[{"batb":[[0,12,10],[1,1.3,5],[2,1.01,12]],"ltp":8.6,"tv":14.73,"id":20586366}]}]}
{"op":"mcm","clk":"4235450381","pt":1631555109545,"mc":[{"id":"1.187594320","rc":[{"batb":[[0,1.3,5],[1,1.01,12],[2,1.01,0]],"ltp":8.6,"tv":14.73,"id":20586366}]}]}
{"op":"mcm","clk":"4235451117","pt":1631555114459,"mc":[{"id":"1.187594320","rc":[{"batb":[[0,14,10],[1,1.3,5],[2,1.01,12]],"ltp":8.6,"tv":14.73,"id":20586366}]}]}
{"op":"mcm","clk":"4235453693","pt":1631555132020,"mc":[{"id":"1.187594320","rc":[{"batb":[[0,1.3,5],[1,1.01,12],[2,1.01,0]],"ltp":8.6,"tv":14.73,"id":20586366}]}]}
{"op":"mcm","clk":"4235454426","pt":1631555136995,"mc":[{"id":"1.187594320","rc":[{"batb":[[0,1.04,749.99]],"ltp":1.05,"tv":232.3,"id":9637111},{"batb":[[0,8.6,10],[1,1.3,5],[2,1.01,12]],"ltp":8.6,"tv":14.73,"id":20586366}]}]}
{"op":"mcm","clk":"4235458869","pt":1631555167479,"mc":[{"id":"1.187594320","rc":[{"batb":[[0,1.3,5],[1,1.01,12],[2,1.01,0]],"ltp":8.6,"tv":14.73,"id":20586366}]}]}
{"op":"mcm","clk":"4235459547","pt":1631555172346,"mc":[{"id":"1.187594320","rc":[{"batb":[[0,1.05,599.99]],"ltp":1.05,"tv":232.3,"id":9637111},{"batb":[[0,7.6,10],[1,1.3,5],[2,1.01,12]],"ltp":8.6,"tv":14.73,"id":20586366}]}]}
{"op":"mcm","clk":"4235465768","pt":1631555213718,"mc":[{"id":"1.187594320","rc":[{"batb":[[0,1.3,5],[1,1.01,12],[2,1.01,0]],"ltp":8.6,"tv":14.73,"id":20586366}]}]}
{"op":"mcm","clk":"4235466483","pt":1631555218685,"mc":[{"id":"1.187594320","rc":[{"batb":[[0,1.04,749.99]],"ltp":1.05,"tv":232.3,"id":9637111},{"batb":[[0,8,10],[1,1.3,5],[2,1.01,12]],"ltp":8.6,"tv":14.73,"id":20586366}]}]}
{"op":"mcm","clk":"4235471160","pt":1631555250357,"mc":[{"id":"1.187594320","rc":[{"batb":[[0,1.3,5],[1,1.01,12],[2,1.01,0]],"ltp":8.6,"tv":14.73,"id":20586366}]}]}
{"op":"mcm","clk":"4235471940","pt":1631555255342,"mc":[{"id":"1.187594320","rc":[{"batb":[[0,1.03,999.99]],"ltp":1.05,"tv":232.3,"id":9637111},{"batb":[[0,9.6,10],[1,1.3,5],[2,1.01,12]],"ltp":8.6,"tv":14.73,"id":20586366}]}]}
{"op":"mcm","clk":"4235476694","pt":1631555289074,"mc":[{"id":"1.187594320","rc":[{"batb":[[0,1.3,5],[1,1.01,12],[2,1.01,0]],"ltp":8.6,"tv":14.73,"id":20586366}]}]}
{"op":"mcm","clk":"4235477358","pt":1631555293995,"mc":[{"id":"1.187594320","rc":[{"batb":[[0,1.04,749.99]],"ltp":1.05,"tv":232.3,"id":9637111},{"batb":[[0,8,10],[1,1.3,5],[2,1.01,12]],"ltp":8.6,"tv":14.73,"id":20586366}]}]}
{"op":"mcm","clk":"4235481234","pt":1631555323431,"mc":[{"id":"1.187594320","rc":[{"batb":[[0,1.3,5],[1,1.01,12],[2,1.01,0]],"ltp":8.6,"tv":14.73,"id":20586366}]}]}
{"op":"mcm","clk":"4235481849","pt":1631555328338,"mc":[{"id":"1.187594320","rc":[{"batb":[[0,1.02,1499.99]],"ltp":1.05,"tv":232.3,"id":9637111},{"batb":[[0,10,10],[1,1.3,5],[2,1.01,12]],"ltp":8.6,"tv":14.73,"id":20586366}]}]}
{"op":"mcm","clk":"4235500535","pt":1631555484611,"mc":[{"id":"1.187594320","rc":[{"batb":[[0,1.3,5],[1,1.01,12],[2,1.01,0]],"ltp":8.6,"tv":14.73,"id":20586366}]}]}
{"op":"mcm","clk":"4235500981","pt":1631555489537,"mc":[{"id":"1.187594320","rc":[{"batb":[[0,11,10],[1,1.3,5],[2,1.01,12]],"ltp":8.6,"tv":14.73,"id":20586366}]}]}
{"op":"mcm","clk":"4235502313","pt":1631555502662,"mc":[{"id":"1.187594320","rc":[{"batb":[[0,1.3,5],[1,1.01,12],[2,1.01,0]],"ltp":8.6,"tv":14.73,"id":20586366}]}]}
{"op":"mcm","clk":"4235502787","pt":1631555507632,"mc":[{"id":"1.187594320","rc":[{"batb":[[0,14,10],[1,1.3,5],[2,1.01,12]],"ltp":8.6,"tv":14.73,"id":20586366}]}]}
{"op":"mcm","clk":"4235505464","pt":1631555532986,"mc":[{"id":"1.187594320","rc":[{"batb":[[0,1.3,5],[1,1.01,12],[2,1.01,0]],"ltp":8.6,"tv":14.73,"id":20586366}]}]}
{"op":"mcm","clk":"4235506013","pt":1631555537907,"mc":[{"id":"1.187594320","rc":[{"batb":[[0,1.02,1499.99]],"ltp":1.05,"tv":232.3,"id":9637111},{"batb":[[0,10,10],[1,1.3,5],[2,1.01,12]],"ltp":8.6,"tv":14.73,"id":20586366}]}]}
{"op":"mcm","clk":"4235509191","pt":1631555567142,"mc":[{"id":"1.187594320","rc":[{"batb":[[0,1.3,5],[1,1.01,12],[2,1.01,0]],"ltp":8.6,"tv":14.73,"id":20586366}]}]}
{"op":"mcm","clk":"4235509933","pt":1631555572142,"mc":[{"id":"1.187594320","rc":[{"batb":[[0,16,10],[1,1.3,5],[2,1.01,12]],"ltp":8.6,"tv":14.73,"id":20586366}]}]}
{"op":"mcm","clk":"4235513819","pt":1631555603491,"mc":[{"id":"1.187594320","rc":[{"batb":[[0,1.3,5],[1,1.01,12],[2,1.01,0]],"ltp":8.6,"tv":14.73,"id":20586366}]}]}
{"op":"mcm","clk":"4235514407","pt":1631555608476,"mc":[{"id":"1.187594320","rc":[{"batb":[[0,24,10],[1,1.3,5],[2,1.01,12]],"ltp":8.6,"tv":14.73,"id":20586366}]}]}
{"op":"mcm","clk":"4235517146","pt":1631555632829,"mc":[{"id":"1.187594320","rc":[{"batb":[[0,1.3,5],[1,1.01,12],[2,1.01,0]],"ltp":8.6,"tv":14.73,"id":20586366}]}]}
{"op":"mcm","clk":"4235517675","pt":1631555637798,"mc":[{"id":"1.187594320","rc":[{"batb":[[0,19.5,10],[1,1.3,5],[2,1.01,12]],"ltp":8.6,"tv":14.73,"id":20586366}]}]}
{"op":"mcm","clk":"4235519735","pt":1631555656242,"mc":[{"id":"1.187594320","rc":[{"batb":[[0,1.3,5],[1,1.01,12],[2,1.01,0]],"ltp":8.6,"tv":14.73,"id":20586366}]}]}
{"op":"mcm","clk":"4235523790","pt":1631555692614,"mc":[{"id":"1.187594320","marketDefinition":{"bspMarket":false,"turnInPlayEnabled":true,"persistenceEnabled":true,"marketBaseRate":5.0,"eventId":"30897898","eventTypeId":"2","numberOfWinners":1,"bettingType":"ODDS","marketType":"MATCH_ODDS","marketTime":"2021-09-13T16:19:53.000Z","suspendTime":"2021-09-13T16:19:53.000Z","bspReconciled":false,"complete":true,"inPlay":true,"crossMatching":true,"runnersVoidable":false,"numberOfActiveRunners":2,"betDelay":5,"status":"SUSPENDED","runners":[{"status":"ACTIVE","sortPriority":1,"id":9637111,"name":"R Serban"},{"status":"ACTIVE","sortPriority":2,"id":20586366,"name":"S Milatova"}],"regulators":["MR_INT"],"countryCode":"GB","discountAllowed":true,"timezone":"GMT","openDate":"2021-09-13T16:19:53.000Z","version":4031091656,"name":"Match Odds","eventName":"R Serban v S Milatova"}}]}
{"op":"mcm","clk":"4235524300","pt":1631555696865,"mc":[{"id":"1.187594320","tv":0.0}]}
{"op":"mcm","clk":"4235524392","pt":1631555697653,"mc":[{"id":"1.187594320","marketDefinition":{"bspMarket":false,"turnInPlayEnabled":true,"persistenceEnabled":true,"marketBaseRate":5.0,"eventId":"30897898","eventTypeId":"2","numberOfWinners":1,"bettingType":"ODDS","marketType":"MATCH_ODDS","marketTime":"2021-09-13T16:19:53.000Z","suspendTime":"2021-09-13T16:19:53.000Z","bspReconciled":false,"complete":true,"inPlay":true,"crossMatching":false,"runnersVoidable":false,"numberOfActiveRunners":0,"betDelay":5,"status":"CLOSED","settledTime":"2021-09-13T17:54:55.000Z","runners":[{"status":"WINNER","sortPriority":1,"id":9637111,"name":"R Serban"},{"status":"LOSER","sortPriority":2,"id":20586366,"name":"S Milatova"}],"regulators":["MR_INT"],"countryCode":"GB","discountAllowed":true,"timezone":"GMT","openDate":"2021-09-13T16:19:53.000Z","version":4031091814,"name":"Match Odds","eventName":"R Serban v S Milatova"}}]}
