{"op":"mcm","clk":"4226444541","pt":1631449156918,"mc":[{"id":"1.187553949","marketDefinition":{"bspMarket":false,"turnInPlayEnabled":true,"persistenceEnabled":true,"marketBaseRate":5.0,"eventId":"30895612","eventTypeId":"2","numberOfWinners":1,"bettingType":"ODDS","marketType":"MATCH_ODDS","marketTime":"2021-09-12T13:30:00.000Z","suspendTime":"2021-09-12T13:30:00.000Z","bspReconciled":false,"complete":true,"inPlay":false,"crossMatching":false,"runnersVoidable":false,"numberOfActiveRunners":2,"betDelay":0,"status":"OPEN","runners":[{"status":"ACTIVE","sortPriority":1,"id":9637111,"name":"R Serban"},{"status":"ACTIVE","sortPriority":2,"id":9637114,"name":"K Bejenaru"}],"regulators":["MR_INT"],"countryCode":"GB","discountAllowed":false,"timezone":"GMT","openDate":"2021-09-12T13:30:00.000Z","version":4028100676,"name":"Match Odds","eventName":"R Serban v K Bejenaru"},"rc":[{"batb":[[0,1.01,25]],"ltp":0.0,"tv":0.0,"id":9637111},{"batb":[[0,1.01,25]],"ltp":0.0,"tv":0.0,"id":9637114}]}]}
{"op":"mcm","clk":"4226444805","pt":1631449158464,"mc":[{"id":"1.187553949","marketDefinition":{"bspMarket":false,"turnInPlayEnabled":true,"persistenceEnabled":true,"marketBaseRate":5.0,"eventId":"30895612","eventTypeId":"2","numberOfWinners":1,"bettingType":"ODDS","marketType":"MATCH_ODDS","marketTime":"2021-09-12T13:30:00.000Z","suspendTime":"2021-09-12T13:30:00.000Z","bspReconciled":false,"complete":true,"inPlay":false,"crossMatching":false,"runnersVoidable":false,"numberOfActiveRunners":2,"betDelay":0,"status":"OPEN","runners":[{"status":"ACTIVE","sortPriority":1,"id":9637111,"name":"R Serban"},{"status":"ACTIVE","sortPriority":2,"id":9637114,"name":"K Bejenaru"}],"regulators":["MR_INT"],"countryCode":"GB","discountAllowed":true,"timezone":"GMT","openDate":"2021-09-12T13:30:00.000Z","version":4028100676,"name":"Match Odds","eventName":"R Serban v K Bejenaru"}}]}
{"op":"mcm","clk":"4226500008","pt":1631449512686,"mc":[{"id":"1.187553949","rc":[{"batb":[[0,1.02,307.83],[1,1.01,25]],"ltp":0.0,"tv":0.0,"id":9637111},{"batb":[[0,1.02,307.83],[1,1.01,25]],"ltp":0.0,"tv":0.0,"id":9637114}]}]}
{"op":"mcm","clk":"4226541423","pt":1631449808621,"mc":[{"id":"1.187553949","rc":[{"batb":[[1,1.01,7]],"ltp":0.0,"tv":0.0,"id":9637111},{"batb":[[1,1.01,7]],"ltp":0.0,"tv":0.0,"id":9637114}]}]}
{"op":"mcm","clk":"4226676014","pt":1631450647328,"mc":[{"id":"1.187553949","rc":[{"batb":[[0,1.22,204.96],[1,1.02,307.83],[2,1.01,7]],"ltp":0.0,"tv":0.0,"id":9637111},{"batb":[[0,3.75,16.39],[1,1.02,307.83],[2,1.01,7]],"ltp":0.0,"tv":0.0,"id":9637114}]}]}
{"op":"mcm","clk":"4226676251","pt":1631450648631,"mc":[{"id":"1.187553949","rc":[{"batl":[[0,11.5,41.9]],"ltp":0.0,"tv":0.0,"id":9637114}]}]}
{"op":"mcm","clk":"4226681505","pt":1631450677824,"mc":[{"id":"1.187553949","marketDefinition":{"bspMarket":false,"turnInPlayEnabled":true,"persistenceEnabled":true,"marketBaseRate":5.0,"eventId":"30895612","eventTypeId":"2","numberOfWinners":1,"bettingType":"ODDS","marketType":"MATCH_ODDS","marketTime":"2021-09-12T13:30:00.000Z","suspendTime":"2021-09-12T13:30:00.000Z","bspReconciled":false,"complete":true,"inPlay":false,"crossMatching":true,"runnersVoidable":false,"numberOfActiveRunners":2,"betDelay":0,"status":"OPEN","runners":[{"status":"ACTIVE","sortPriority":1,"id":9637111,"name":"R Serban"},{"status":"ACTIVE","sortPriority":2,"id":9637114,"name":"K Bejenaru"}],"regulators":["MR_INT"],"countryCode":"GB","discountAllowed":true,"timezone":"GMT","openDate":"2021-09-12T13:30:00.000Z","version":4028100676,"name":"Match Odds","eventName":"R Serban v K Bejenaru"}}]}
{"op":"mcm","clk":"4226681636","pt":1631450678684,"mc":[{"id":"1.187553949","rc":[{"batb":[[0,1.23,55.7],[1,1.22,204.96],[2,1.02,307.83]],"ltp":0.0,"tv":0.0,"id":9637111},{"batb":[[0,3.8,4.58],[1,3.75,16.39],[2,1.02,307.83]],"ltp":0.0,"tv":0.0,"id":9637114}]}]}
{"op":"mcm","clk":"4226682089","pt":1631450681050,"mc":[{"id":"1.187553949","rc":[{"batl":[[0,2,80]],"ltp":0.0,"tv":0.0,"id":9637111}]}]}
{"op":"mcm","clk":"4226725727","pt":1631450948455,"mc":[{"id":"1.187553949","rc":[{"batl":[[0,21,55.01]],"ltp":0.0,"tv":0.0,"id":9637114}]}]}
{"op":"mcm","clk":"4226874123","pt":1631451939271,"mc":[{"id":"1.187553949","rc":[{"batb":[[0,1.24,56.37],[1,1.23,55.7],[2,1.22,204.96]],"ltp":0.0,"tv":0.0,"id":9637111}]}]}
{"op":"mcm","clk":"4226874349","pt":1631451940497,"mc":[{"id":"1.187553949","rc":[{"batb":[[0,1.25,51.24],[1,1.24,56.37],[2,1.23,55.7]],"ltp":0.0,"tv":0.0,"id":9637111}]}]}
{"op":"mcm","clk":"4226912100","pt":1631452148585,"mc":[{"id":"1.187553949","rc":[{"batl":[[0,24,36.19]],"ltp":0.0,"tv":0.0,"id":9637114}]}]}
{"op":"mcm","clk":"4227026991","pt":1631452774368,"mc":[{"id":"1.187553949","rc":[{"batb":[[0,1.24,56.37],[1,1.22,204.96],[2,1.02,307.83]],"ltp":0.0,"tv":0.0,"id":9637111},{"batb":[[0,3.75,16.39],[1,1.02,307.83],[2,1.01,7]],"ltp":0.0,"tv":0.0,"id":9637114}]}]}
{"op":"mcm","clk":"4227027129","pt":1631452775026,"mc":[{"id":"1.187553949","rc":[{"batb":[[0,1.25,51.24],[1,1.24,56.37],[2,1.22,204.96]],"ltp":0.0,"tv":0.0,"id":9637111},{"batb":[[0,3.8,4.58],[1,3.75,16.39],[2,1.02,307.83]],"ltp":0.0,"tv":0.0,"id":9637114}]}]}
{"op":"mcm","clk":"4227037965","pt":1631452843222,"mc":[{"id":"1.187553949","rc":[{"batb":[[0,1.24,56.37],[1,1.22,204.96],[2,1.02,307.83]],"ltp":0.0,"tv":0.0,"id":9637111},{"batb":[[0,3.75,16.39],[1,1.02,307.83],[2,1.01,7]],"ltp":0.0,"tv":0.0,"id":9637114}]}]}
{"op":"mcm","clk":"4227038079","pt":1631452844141,"mc":[{"id":"1.187553949","rc":[{"batb":[[0,1.25,51.24],[1,1.24,56.37],[2,1.22,204.96]],"ltp":0.0,"tv":0.0,"id":9637111},{"batb":[[0,3.8,4.58],[1,3.75,16.39],[2,1.02,307.83]],"ltp":0.0,"tv":0.0,"id":9637114}]}]}
{"op":"mcm","clk":"4227149487","pt":1631453530678,"mc":[{"id":"1.187553949","marketDefinition":{"bspMarket":false,"turnInPlayEnabled":true,"persistenceEnabled":true,"marketBaseRate":5.0,"eventId":"30895612","eventTypeId":"2","numberOfWinners":1,"bettingType":"ODDS","marketType":"MATCH_ODDS","marketTime":"2021-09-12T13:30:00.000Z","suspendTime":"2021-09-12T13:30:00.000Z","bspReconciled":false,"complete":true,"inPlay":true,"crossMatching":true,"runnersVoidable":false,"numberOfActiveRunners":2,"betDelay":5,"status":"OPEN","runners":[{"status":"ACTIVE","sortPriority":1,"id":9637111,"name":"R Serban"},{"status":"ACTIVE","sortPriority":2,"id":9637114,"name":"K Bejenaru"}],"regulators":["MR_INT"],"countryCode":"GB","discountAllowed":true,"timezone":"GMT","openDate":"2021-09-12T13:30:00.000Z","version":4028395486,"name":"Match Odds","eventName":"R Serban v K Bejenaru"},"rc":[{"batb":[[0,1.01,7],[1,1.24,0],[2,1.22,0]],"ltp":0.0,"tv":0.0,"id":9637111},{"batb":[[0,1.01,7],[1,3.75,0],[2,1.02,0]],"ltp":0.0,"tv":0.0,"id":9637114}]}]}
{"op":"mcm","clk":"4227248975","pt":1631454165030,"mc":[{"id":"1.187553949","marketDefinition":{"bspMarket":false,"turnInPlayEnabled":true,"persistenceEnabled":true,"marketBaseRate":5.0,"eventId":"30895612","eventTypeId":"2","numberOfWinners":1,"bettingType":"ODDS","marketType":"MATCH_ODDS","marketTime":"2021-09-12T13:42:44.000Z","suspendTime":"2021-09-12T13:42:44.000Z","bspReconciled":false,"complete":true,"inPlay":true,"crossMatching":true,"runnersVoidable":false,"numberOfActiveRunners":2,"betDelay":5,"status":"OPEN","runners":[{"status":"ACTIVE","sortPriority":1,"id":9637111,"name":"R Serban"},{"status":"ACTIVE","sortPriority":2,"id":9637114,"name":"K Bejenaru"}],"regulators":["MR_INT"],"countryCode":"GB","discountAllowed":true,"timezone":"GMT","openDate":"2021-09-12T13:30:00.000Z","version":4028429384,"name":"Match Odds","eventName":"R Serban v K Bejenaru"}}]}
{"op":"mcm","clk":"4227249483","pt":1631454168042,"mc":[{"id":"1.187553949","marketDefinition":{"bspMarket":false,"turnInPlayEnabled":true,"persistenceEnabled":true,"marketBaseRate":5.0,"eventId":"30895612","eventTypeId":"2","numberOfWinners":1,"bettingType":"ODDS","marketType":"MATCH_ODDS","marketTime":"2021-09-12T13:42:44.000Z","suspendTime":"2021-09-12T13:42:44.000Z","bspReconciled":false,"complete":true,"inPlay":true,"crossMatching":true,"runnersVoidable":false,"numberOfActiveRunners":2,"betDelay":5,"status":"OPEN","runners":[{"status":"ACTIVE","sortPriority":1,"id":9637111,"name":"R Serban"},{"status":"ACTIVE","sortPriority":2,"id":9637114,"name":"K Bejenaru"}],"regulators":["MR_INT"],"countryCode":"GB","discountAllowed":true,"timezone":"GMT","openDate":"2021-09-12T13:42:44.000Z","version":4028429388,"name":"Match Odds","eventName":"R Serban v K Bejenaru"}}]}
{"op":"mcm","clk":"4227775929","pt":1631457390370,"mc":[{"id":"1.187553949","rc":[{"trd":[[2,64.05]],"batl":[[0,2,15.95]],"ltp":2.0,"tv":64.05,"id":9637111},{"trd":[[2,64.05]],"ltp":2.0,"tv":64.05,"id":9637114}],"tv":128.1}]}
{"op":"mcm","clk":"4227886726","pt":1631458037450,"mc":[{"id":"1.187553949","rc":[{"trd":[[2,80.91]],"batl":[[0,2,7.52]],"ltp":2.0,"tv":80.9,"id":9637111}],"tv":144.96}]}
{"op":"mcm","clk":"4227886960","pt":1631458038952,"mc":[{"id":"1.187553949","rc":[{"trd":[[2,95.95]],"ltp":2.0,"tv":95.95,"id":9637111}],"tv":160.0}]}
{"op":"mcm","clk":"4227887387","pt":1631458041934,"mc":[{"id":"1.187553949","rc":[{"batl":[[0,2,15.37]],"ltp":2.0,"tv":64.05,"id":9637114}]}]}
{"op":"mcm","clk":"4227897765","pt":1631458115691,"mc":[{"id":"1.187553949","rc":[{"batb":[[0,2,37.19],[1,1.01,7]],"ltp":2.0,"tv":95.95,"id":9637111}]}]}
{"op":"mcm","clk":"4227916145","pt":1631458262934,"mc":[{"id":"1.187553949","rc":[{"batb":[[0,1.01,7],[1,1.01,0]],"ltp":2.0,"tv":95.95,"id":9637111}]}]}
{"op":"mcm","clk":"4227916811","pt":1631458268199,"mc":[{"id":"1.187553949","rc":[{"batb":[[0,1.9,37.19],[1,1.01,7]],"ltp":2.0,"tv":95.95,"id":9637111}]}]}
{"op":"mcm","clk":"4228004774","pt":1631458983791,"mc":[{"id":"1.187553949","rc":[{"batb":[[0,1.01,7],[1,1.01,0]],"ltp":2.0,"tv":95.95,"id":9637111}]}]}
{"op":"mcm","clk":"4228385801","pt":1631461323179,"mc":[{"id":"1.187553949","marketDefinition":{"bspMarket":false,"turnInPlayEnabled":true,"persistenceEnabled":true,"marketBaseRate":5.0,"eventId":"30895612","eventTypeId":"2","numberOfWinners":1,"bettingType":"ODDS","marketType":"MATCH_ODDS","marketTime":"2021-09-12T13:42:44.000Z","suspendTime":"2021-09-12T13:42:44.000Z","bspReconciled":false,"complete":true,"inPlay":true,"crossMatching":true,"runnersVoidable":false,"numberOfActiveRunners":2,"betDelay":5,"status":"SUSPENDED","runners":[{"status":"ACTIVE","sortPriority":1,"id":9637111,"name":"R Serban"},{"status":"ACTIVE","sortPriority":2,"id":9637114,"name":"K Bejenaru"}],"regulators":["MR_INT"],"countryCode":"GB","discountAllowed":true,"timezone":"GMT","openDate":"2021-09-12T13:42:44.000Z","version":4028930895,"name":"Match Odds","eventName":"R Serban v K Bejenaru"}}]}
{"op":"mcm","clk":"4228386529","pt":1631461327241,"mc":[{"id":"1.187553949","marketDefinition":{"bspMarket":false,"turnInPlayEnabled":true,"persistenceEnabled":true,"marketBaseRate":5.0,"eventId":"30895612","eventTypeId":"2","numberOfWinners":1,"bettingType":"ODDS","marketType":"MATCH_ODDS","marketTime":"2021-09-12T13:42:44.000Z","suspendTime":"2021-09-12T13:42:44.000Z","bspReconciled":false,"complete":true,"inPlay":true,"crossMatching":false,"runnersVoidable":false,"numberOfActiveRunners":0,"betDelay":5,"status":"CLOSED","settledTime":"2021-09-12T15:42:05.000Z","runners":[{"status":"WINNER","sortPriority":1,"id":9637111,"name":"R Serban"},{"status":"LOSER","sortPriority":2,"id":9637114,"name":"K Bejenaru"}],"regulators":["MR_INT"],"countryCode":"GB","discountAllowed":true,"timezone":"GMT","openDate":"2021-09-12T13:42:44.000Z","version":4028930991,"name":"Match Odds","eventName":"R Serban v K Bejenaru"},"tv":0.0}]}
