{"op":"mcm","clk":"4217009396","pt":1631557092507,"mc":[{"id":"1.187566733","rc":[{"batb":[[1,1.08,2849.95],[2,1.07,527.3]],"ltp":1.1,"tv":128149.11,"id":9323645}]}]}
{"op":"mcm","clk":"4217009605","pt":1631557094015,"mc":[{"id":"1.187566733","rc":[{"trd":[[11,76.01]],"batb":[[0,10,113.59],[1,9.4,21.28],[2,8,13.43]],"ltp":11.0,"tv":14976.0,"id":8734382},{"trd":[[1.1,7865.37]],"batl":[[0,1.1,394.09]],"ltp":1.1,"tv":128158.24,"id":9323645}],"tv":143134.25}]}
{"op":"mcm","clk":"4217009739","pt":1631557094922,"mc":[{"id":"1.187566733","rc":[{"batl":[[0,1.1,1247.47]],"ltp":1.1,"tv":128158.24,"id":9323645}]}]}
{"op":"mcm","clk":"4217009914","pt":1631557096111,"mc":[{"id":"1.187566733","rc":[{"batl":[[0,1.1,2855.71]],"ltp":1.1,"tv":128158.24,"id":9323645}]}]}
{"op":"mcm","clk":"4217010040","pt":1631557096935,"mc":[{"id":"1.187566733","rc":[{"trd":[[11,76.26]],"ltp":11.0,"tv":14976.26,"id":8734382},{"trd":[[1.1,7873.8]],"batl":[[0,1.1,3259.22]],"ltp":1.1,"tv":128166.68,"id":9323645}],"tv":143142.94}]}
{"op":"mcm","clk":"4217010157","pt":1631557097702,"mc":[{"id":"1.187566733","rc":[{"batb":[[2,8.6,31.29]],"ltp":11.0,"tv":14976.26,"id":8734382},{"trd":[[1.1,7874.16]],"batl":[[0,1.1,3259.04]],"ltp":1.1,"tv":128167.04,"id":9323645}],"tv":143143.3}]}
{"op":"mcm","clk":"4217010368","pt":1631557099207,"mc":[{"id":"1.187566733","rc":[{"trd":[[11,97.6]],"ltp":11.0,"tv":14997.59,"id":8734382},{"trd":[[1.1,8087.47]],"batb":[[1,1.08,2741.43]],"batl":[[0,1.1,3045.73]],"ltp":1.1,"tv":128380.35,"id":9323645}],"tv":143377.95}]}
{"op":"mcm","clk":"4217010491","pt":1631557100114,"mc":[{"id":"1.187566733","rc":[{"trd":[[1.1,8087.87]],"batl":[[0,1.1,3045.53]],"ltp":1.1,"tv":128380.75,"id":9323645}],"tv":143378.35}]}
{"op":"mcm","clk":"4217010750","pt":1631557102006,"mc":[{"id":"1.187566733","rc":[{"batb":[[0,1.09,672.82]],"batl":[[0,1.1,3118.96],[1,1.11,5311.51]],"ltp":1.1,"tv":128380.75,"id":9323645}]}]}
{"op":"mcm","clk":"4217010940","pt":1631557103039,"mc":[{"id":"1.187566733","rc":[{"batl":[[0,13.5,176.7]],"ltp":11.0,"tv":14997.59,"id":8734382},{"batb":[[1,1.08,2654.94]],"batl":[[1,1.11,5012.06]],"ltp":1.1,"tv":128380.75,"id":9323645}]}]}
{"op":"mcm","clk":"4217011003","pt":1631557103534,"mc":[{"id":"1.187566733","rc":[{"batl":[[2,1.12,13.52]],"ltp":1.1,"tv":128380.75,"id":9323645}]}]}
{"op":"mcm","clk":"4217011197","pt":1631557105022,"mc":[{"id":"1.187566733","rc":[{"batb":[[1,8.6,31.29],[2,8,50.13]],"batl":[[0,990,0.01],[1,990,0]],"ltp":11.0,"tv":14997.59,"id":8734382},{"batb":[[1,1.08,418],[2,1.07,513.42]],"batl":[[1,1.11,3062.41],[2,1.13,2092.03]],"ltp":1.1,"tv":128380.75,"id":9323645}]}]}
{"op":"mcm","clk":"4217011267","pt":1631557105544,"mc":[{"id":"1.187566733","rc":[{"batb":[[0,8.6,31.29],[1,8,36.7],[2,7.2,36.42]],"ltp":11.0,"tv":14997.59,"id":8734382},{"batb":[[0,1.07,485.81],[1,1.05,1.71],[2,1.07,0]],"batl":[[0,1.1,2115.76],[1,1.13,2092.03],[2,1.14,1868.75]],"ltp":1.1,"tv":128380.75,"id":9323645}]}]}
{"op":"mcm","clk":"4217011417","pt":1631557106649,"mc":[{"id":"1.187566733","rc":[{"batb":[[1,1.05,0]],"batl":[[0,1.1,1706.76]],"ltp":1.1,"tv":128380.75,"id":9323645}]}]}
{"op":"mcm","clk":"4217011604","pt":1631557108138,"mc":[{"id":"1.187566733","rc":[{"batb":[[0,11,170.68],[1,8.6,31.29],[2,8,36.7]],"ltp":11.0,"tv":14997.59,"id":8734382},{"batb":[[0,1.08,264.97],[1,1.07,849.83]],"batl":[[1,1.13,2647.62]],"ltp":1.1,"tv":128380.75,"id":9323645}]}]}
{"op":"mcm","clk":"4217011785","pt":1631557109431,"mc":[{"id":"1.187566733","rc":[{"batl":[[0,1.09,500],[1,1.1,1706.76],[2,1.13,2647.62]],"ltp":1.1,"tv":128380.75,"id":9323645}]}]}
{"op":"mcm","clk":"4217012010","pt":1631557111127,"mc":[{"id":"1.187566733","rc":[{"trd":[[1.09,11179.47]],"batl":[[0,1.09,499.8]],"ltp":1.09,"tv":128381.15,"id":9323645}],"tv":143378.75}]}
{"op":"mcm","clk":"4217012115","pt":1631557111941,"mc":[{"id":"1.187566733","rc":[{"batb":[[0,8.6,31.29],[1,8,36.7],[2,7.2,36.42]],"ltp":11.0,"tv":14997.59,"id":8734382},{"batl":[[0,1.1,1706.76],[1,1.13,2647.62],[2,1.14,1868.75]],"ltp":1.09,"tv":128381.15,"id":9323645}]}]}
{"op":"mcm","clk":"4217012272","pt":1631557113040,"mc":[{"id":"1.187566733","rc":[{"batl":[[0,1.13,2647.62],[1,1.14,1868.75],[2,1.15,1865.34]],"ltp":1.09,"tv":128381.15,"id":9323645}]}]}
{"op":"mcm","clk":"4217012356","pt":1631557113636,"mc":[{"id":"1.187566733","rc":[{"batb":[[1,1.07,851.54]],"ltp":1.09,"tv":128381.15,"id":9323645}]}]}
{"op":"mcm","clk":"4217012459","pt":1631557114551,"mc":[{"id":"1.187566733","rc":[{"trd":[[1.13,1589.68]],"batl":[[0,1.13,2645.91]],"ltp":1.13,"tv":128384.56,"id":9323645}],"tv":143382.16}]}
{"op":"mcm","clk":"4217012568","pt":1631557115540,"mc":[{"id":"1.187566733","rc":[{"batb":[[0,1.08,266.68]],"ltp":1.13,"tv":128384.56,"id":9323645}]}]}
{"op":"mcm","clk":"4217013489","pt":1631557122722,"mc":[{"id":"1.187566733","rc":[{"trd":[[1.13,1668.12]],"batl":[[0,1.13,2606.69]],"ltp":1.13,"tv":128463.0,"id":9323645}],"tv":143460.6}]}
{"op":"mcm","clk":"4217013838","pt":1631557125461,"mc":[{"id":"1.187566733","rc":[{"batb":[[0,1.08,1.71],[1,1.07,487.52]],"ltp":1.13,"tv":128463.0,"id":9323645}]}]}
{"op":"mcm","clk":"4217014172","pt":1631557128156,"mc":[{"id":"1.187566733","rc":[{"batb":[[0,1.11,6.29],[1,1.08,1.71],[2,1.07,487.52]],"ltp":1.13,"tv":128463.0,"id":9323645}]}]}
{"op":"mcm","clk":"4217014208","pt":1631557128486,"mc":[{"id":"1.187566733","rc":[{"batl":[[0,10.5,14.28],[1,11,226.05],[2,11.5,7.14]],"ltp":11.0,"tv":14997.59,"id":8734382},{"trd":[[1.13,1789.76]],"batb":[[0,1.12,41.34],[1,1.11,4604.25],[2,1.1,2009.63]],"batl":[[0,1.13,2595.36],[1,1.14,4124.5]],"ltp":1.13,"tv":128584.65,"id":9323645}],"tv":143582.25}]}
{"op":"mcm","clk":"4217014362","pt":1631557129682,"mc":[{"id":"1.187566733","rc":[{"batb":[[1,8.4,17.86],[2,8.2,8.92]],"batl":[[0,10.5,8.57],[1,11,223.19],[2,11.5,4.28]],"ltp":11.0,"tv":14997.59,"id":8734382},{"batb":[[1,1.11,4929.02]],"batl":[[1,1.14,4126.69]],"ltp":1.13,"tv":128584.65,"id":9323645}]}]}
{"op":"mcm","clk":"4217014545","pt":1631557131054,"mc":[{"id":"1.187566733","rc":[{"batb":[[1,8.4,10.72],[2,8.2,5.35]],"batl":[[0,10.5,2.86],[1,11,220.33],[2,11.5,1.42]],"ltp":11.0,"tv":14997.59,"id":8734382},{"batb":[[1,1.11,1280.88]],"ltp":1.13,"tv":128584.65,"id":9323645}]}]}
{"op":"mcm","clk":"4217014648","pt":1631557131706,"mc":[{"id":"1.187566733","rc":[{"batb":[[2,1.1,2007.81]],"batl":[[1,1.14,4124.94]],"ltp":1.13,"tv":128584.65,"id":9323645}]}]}
{"op":"mcm","clk":"4217014786","pt":1631557132558,"mc":[{"id":"1.187566733","rc":[{"batb":[[1,8.4,3.58],[2,8.2,1.78]],"ltp":11.0,"tv":14997.59,"id":8734382}]}]}
{"op":"mcm","clk":"4217015105","pt":1631557134094,"mc":[{"id":"1.187566733","rc":[{"trd":[[8.6,93.93]],"batb":[[0,8.4,3.58],[1,8.2,1.78],[2,8,38.48]],"ltp":8.6,"tv":14998.35,"id":8734382},{"trd":[[1.13,1795.44]],"batl":[[0,1.13,1401.06]],"ltp":1.13,"tv":128590.33,"id":9323645}],"tv":143588.68}]}
{"op":"mcm","clk":"4217015653","pt":1631557135977,"mc":[{"id":"1.187566733","rc":[{"trd":[[1.12,9909.03]],"batb":[[0,1.11,1280.88],[1,1.1,2007.81],[2,1.09,395.34]],"batl":[[0,1.12,2803.07],[1,1.13,1401.06],[2,1.14,4124.94]],"ltp":1.12,"tv":128673.41,"id":9323645}],"tv":143671.77}]}
{"op":"mcm","clk":"4217015964","pt":1631557137013,"mc":[{"id":"1.187566733","rc":[{"batl":[[1,1.13,1789.46]],"ltp":1.12,"tv":128673.41,"id":9323645}]}]}
{"op":"mcm","clk":"4217016452","pt":1631557138913,"mc":[{"id":"1.187566733","rc":[{"batl":[[0,1.12,1422.31]],"ltp":1.12,"tv":128673.41,"id":9323645}]}]}
{"op":"mcm","clk":"4217016657","pt":1631557139963,"mc":[{"id":"1.187566733","rc":[{"trd":[[9.2,45.63]],"ltp":9.2,"tv":15013.24,"id":8734382},{"trd":[[1.11,6755.93],[1.12,10031.36]],"batb":[[0,1.11,929.67]],"batl":[[0,1.12,2065.87]],"ltp":1.11,"tv":129498.16,"id":9323645}],"tv":144511.41}]}
{"op":"mcm","clk":"4217017021","pt":1631557142123,"mc":[{"id":"1.187566733","rc":[{"batl":[[0,1.12,2080.38]],"ltp":1.11,"tv":129498.16,"id":9323645}]}]}
{"op":"mcm","clk":"4217017150","pt":1631557142977,"mc":[{"id":"1.187566733","rc":[{"trd":[[1.1,8121.14],[1.11,8675.65]],"batb":[[0,1.1,1991.17],[1,1.09,395.34],[2,1.08,1.71]],"ltp":1.1,"tv":131451.16,"id":9323645}],"tv":146464.4}]}
{"op":"mcm","clk":"4217017274","pt":1631557143871,"mc":[{"id":"1.187566733","rc":[{"trd":[[1.12,10031.76]],"batl":[[0,1.12,2080.19],[1,1.13,1709]],"ltp":1.12,"tv":131451.55,"id":9323645}],"tv":146464.8}]}
{"op":"mcm","clk":"4217017467","pt":1631557145191,"mc":[{"id":"1.187566733","rc":[{"batl":[[0,1.11,1000],[1,1.12,2791.34],[2,1.13,1309]],"ltp":1.12,"tv":131451.55,"id":9323645}]}]}
{"op":"mcm","clk":"4217017600","pt":1631557146187,"mc":[{"id":"1.187566733","rc":[{"batl":[[2,1.13,1259.52]],"ltp":1.12,"tv":131451.55,"id":9323645}]}]}
{"op":"mcm","clk":"4217017655","pt":1631557146560,"mc":[{"id":"1.187566733","rc":[{"trd":[[1.11,9752.07]],"batl":[[0,1.11,461.79],[1,1.12,2926.95],[2,1.13,970.53]],"ltp":1.11,"tv":132527.97,"id":9323645}],"tv":147541.22}]}
{"op":"mcm","clk":"4217017792","pt":1631557147766,"mc":[{"id":"1.187566733","rc":[{"batl":[[0,1.11,1693.79]],"ltp":1.11,"tv":132527.97,"id":9323645}]}]}
{"op":"mcm","clk":"4217017948","pt":1631557148976,"mc":[{"id":"1.187566733","rc":[{"trd":[[10,13.75]],"ltp":10.0,"tv":15023.66,"id":8734382},{"trd":[[1.11,9845.94]],"batl":[[0,1.11,2322.43],[2,1.13,1060.74]],"ltp":1.11,"tv":132621.84,"id":9323645}],"tv":147645.51}]}
{"op":"mcm","clk":"4217018080","pt":1631557149878,"mc":[{"id":"1.187566733","rc":[{"batb":[[0,6.8,38.63],[1,6.6,20.31],[2,6.4,36.76]],"batl":[[0,990,0.01],[1,11,0],[2,11.5,0]],"ltp":10.0,"tv":15023.66,"id":8734382},{"trd":[[1.11,10329.74]],"batb":[[0,1.09,395.34],[1,1.08,1.71],[2,1.07,1.71]],"batl":[[0,1.11,1358.02],[1,1.12,2025.44],[2,1.17,2118.93]],"ltp":1.11,"tv":133105.64,"id":9323645}],"tv":148129.31}]}
{"op":"mcm","clk":"4217018190","pt":1631557150595,"mc":[{"id":"1.187566733","rc":[{"batb":[[1,6.4,36.76],[2,6.2,40.97]],"ltp":10.0,"tv":15023.66,"id":8734382},{"trd":[[1.11,10330.14]],"batl":[[0,1.11,125.82]],"ltp":1.11,"tv":133106.04,"id":9323645}],"tv":148129.71}]}
{"op":"mcm","clk":"4217018571","pt":1631557153195,"mc":[{"id":"1.187566733","rc":[{"trd":[[1.11,10548.37]],"batb":[[0,1.09,696.2],[1,1.08,696.5]],"batl":[[0,1.11,16.71],[2,1.15,226.77]],"ltp":1.11,"tv":133324.26,"id":9323645}],"tv":148347.93}]}
{"op":"mcm","clk":"4217018616","pt":1631557153495,"mc":[{"id":"1.187566733","rc":[{"batb":[[0,1.09,300.86]],"ltp":1.11,"tv":133324.26,"id":9323645}]}]}
{"op":"mcm","clk":"4217019013","pt":1631557156201,"mc":[{"id":"1.187566733","rc":[{"batb":[[1,1.08,752.01]],"batl":[[2,1.15,278.43]],"ltp":1.11,"tv":133324.26,"id":9323645}]}]}
{"op":"mcm","clk":"4217019100","pt":1631557156677,"mc":[{"id":"1.187566733","rc":[{"batl":[[2,1.17,2118.93]],"ltp":1.11,"tv":133324.26,"id":9323645}]}]}
{"op":"mcm","clk":"4217019251","pt":1631557157884,"mc":[{"id":"1.187566733","rc":[{"batl":[[1,1.12,1314.29]],"ltp":1.11,"tv":133324.26,"id":9323645}]}]}
{"op":"mcm","clk":"4217019434","pt":1631557159203,"mc":[{"id":"1.187566733","rc":[{"batb":[[0,11,4.22],[1,10.5,12.96],[2,10,114.9]],"batl":[[0,12,185.96],[1,14,9.7],[2,14.5,9.44]],"ltp":10.0,"tv":15023.66,"id":8734382},{"batb":[[0,1.09,404.35],[2,1.07,29.32]],"batl":[[0,1.1,3729.95],[1,1.11,2716.71],[2,1.12,4093.63]],"ltp":1.11,"tv":133324.26,"id":9323645}]}]}
{"op":"mcm","clk":"4217019591","pt":1631557160206,"mc":[{"id":"1.187566733","rc":[{"trd":[[11,98.23]],"batb":[[0,10.5,12.96],[1,10,114.9],[2,9.8,12.56]],"ltp":11.0,"tv":15024.3,"id":8734382},{"trd":[[1.1,8145.02]],"batb":[[0,1.09,355.06],[2,1.07,29.79]],"batl":[[0,1.1,877.82]],"ltp":1.1,"tv":133348.14,"id":9323645}],"tv":148372.44}]}
{"op":"mcm","clk":"4217019691","pt":1631557160890,"mc":[{"id":"1.187566733","rc":[{"trd":[[1.1,8165.02]],"batl":[[0,1.1,867.82]],"ltp":1.1,"tv":133368.14,"id":9323645}],"tv":148392.44}]}
{"op":"mcm","clk":"4217019844","pt":1631557162209,"mc":[{"id":"1.187566733","rc":[{"trd":[[12,212.64]],"batb":[[0,11,4.22],[1,10.5,12.96],[2,10,114.9]],"batl":[[0,12,132.09]],"ltp":12.0,"tv":15078.17,"id":8734382},{"trd":[[1.09,12482.74]],"batb":[[0,1.09,49.29]],"batl":[[0,1.1,910.03]],"ltp":1.09,"tv":134671.41,"id":9323645}],"tv":149749.58}]}
{"op":"mcm","clk":"4217019861","pt":1631557162278,"mc":[{"id":"1.187566733","rc":[{"batl":[[2,1.12,2793.85]],"ltp":1.09,"tv":134671.41,"id":9323645}]}]}
{"op":"mcm","clk":"4217020071","pt":1631557163998,"mc":[{"id":"1.187566733","rc":[{"trd":[[11,102.31]],"batb":[[0,11,2.18]],"ltp":11.0,"tv":15082.25,"id":8734382},{"trd":[[1.1,8165.42]],"batl":[[0,1.1,1637.17]],"ltp":1.1,"tv":134671.81,"id":9323645}],"tv":149754.06}]}
{"op":"mcm","clk":"4217020158","pt":1631557164585,"mc":[{"id":"1.187566733","rc":[{"trd":[[11,102.93],[12,280.01]],"batb":[[0,11,1.87]],"batl":[[0,12,64.72]],"ltp":12.0,"tv":15150.23,"id":8734382},{"trd":[[1.09,13323.05],[1.1,8171.61]],"batb":[[0,1.08,752.01],[1,1.07,29.79],[2,1.06,525.75]],"batl":[[0,1.1,1634.08]],"ltp":1.09,"tv":135518.3,"id":9323645}],"tv":150668.54}]}
{"op":"mcm","clk":"4217020262","pt":1631557165398,"mc":[{"id":"1.187566733","rc":[{"batb":[[0,1.09,140.44],[1,1.08,913.91],[2,1.07,29.79]],"batl":[[0,1.1,1653.45]],"ltp":1.09,"tv":135518.3,"id":9323645}]}]}
{"op":"mcm","clk":"4217020489","pt":1631557167208,"mc":[{"id":"1.187566733","rc":[{"trd":[[12,318.92]],"batl":[[0,12,25.81]],"ltp":12.0,"tv":15189.14,"id":8734382},{"trd":[[1.09,14032.41]],"batb":[[0,1.08,913.91],[1,1.07,29.79],[2,1.06,525.75]],"ltp":1.09,"tv":136227.66,"id":9323645}],"tv":151416.81}]}
{"op":"mcm","clk":"4217020741","pt":1631557169393,"mc":[{"id":"1.187566733","rc":[{"batl":[[1,1.11,2700]],"ltp":1.09,"tv":136227.66,"id":9323645}]}]}
{"op":"mcm","clk":"4217020926","pt":1631557170910,"mc":[{"id":"1.187566733","rc":[{"batb":[[0,1.08,1055.65]],"batl":[[0,1.1,1658.8]],"ltp":1.09,"tv":136227.66,"id":9323645}]}]}
{"op":"mcm","clk":"4217021014","pt":1631557171593,"mc":[{"id":"1.187566733","rc":[{"batl":[[0,1.1,1791.08]],"ltp":1.09,"tv":136227.66,"id":9323645}]}]}
{"op":"mcm","clk":"4217021163","pt":1631557173010,"mc":[{"id":"1.187566733","rc":[{"trd":[[11,110.58],[12,344.73]],"batb":[[0,10.5,12.96],[1,10,114.9],[2,9.8,12.56]],"batl":[[0,14,9.7],[1,14.5,9.44],[2,15,9.44]],"ltp":12.0,"tv":15222.61,"id":8734382},{"trd":[[1.09,14316.6],[1.1,8210.72]],"batl":[[0,1.09,664.01],[1,1.1,1751.97],[2,1.11,2700]],"ltp":1.09,"tv":136550.97,"id":9323645}],"tv":151773.58}]}
{"op":"mcm","clk":"4217021292","pt":1631557174105,"mc":[{"id":"1.187566733","rc":[{"batb":[[0,8,36.7],[1,7.2,28.02],[2,6.8,38.63]],"batl":[[0,990,0.01],[1,14.5,0],[2,15,0]],"ltp":12.0,"tv":15222.61,"id":8734382},{"batb":[[0,1.08,1.71],[1,1.07,1.71]],"batl":[[1,1.1,407.28],[2,1.12,14.51]],"ltp":1.09,"tv":136550.97,"id":9323645}]}]}
{"op":"mcm","clk":"4217021379","pt":1631557174695,"mc":[{"id":"1.187566733","rc":[{"batl":[[1,1.1,132.28]],"ltp":1.09,"tv":136550.97,"id":9323645}]}]}
{"op":"mcm","clk":"4217021524","pt":1631557175904,"mc":[{"id":"1.187566733","rc":[{"batb":[[0,7.2,28.02],[1,6.4,22.15],[2,2.5,1.82]],"ltp":12.0,"tv":15222.61,"id":8734382},{"batl":[[0,1.1,132.28],[1,1.12,14.51],[2,1.16,1781.2]],"ltp":1.09,"tv":136550.97,"id":9323645}]}]}
{"op":"mcm","clk":"4217021654","pt":1631557176909,"mc":[{"id":"1.187566733","rc":[{"batl":[[0,1.09,1.71],[1,1.1,171.39],[2,1.12,14.51]],"ltp":1.09,"tv":136550.97,"id":9323645}]}]}
{"op":"mcm","clk":"4217021907","pt":1631557179196,"mc":[{"id":"1.187566733","rc":[{"batl":[[0,12.5,72.41],[1,990,0.01]],"ltp":12.0,"tv":15222.61,"id":8734382},{"batb":[[0,1.07,1.71],[1,1.06,525.75],[2,1.06,0]],"batl":[[2,1.16,1781.2]],"ltp":1.09,"tv":136550.97,"id":9323645}]}]}
{"op":"mcm","clk":"4217022031","pt":1631557180039,"mc":[{"id":"1.187566733","rc":[{"batl":[[0,990,0.01],[1,990,0]],"ltp":12.0,"tv":15222.61,"id":8734382},{"trd":[[1.09,14379.75]],"batb":[[0,1.09,588.31],[1,1.07,1.71],[2,1.06,525.75]],"batl":[[0,1.1,316.85],[1,1.11,408.82]],"ltp":1.09,"tv":136614.11,"id":9323645}],"tv":151836.73}]}
{"op":"mcm","clk":"4217022157","pt":1631557181002,"mc":[{"id":"1.187566733","rc":[{"trd":[[1.09,14927.75]],"batb":[[0,1.09,314.31]],"batl":[[1,1.11,261.35]],"ltp":1.09,"tv":137162.11,"id":9323645}],"tv":152384.73}]}
{"op":"mcm","clk":"4217022286","pt":1631557181896,"mc":[{"id":"1.187566733","rc":[{"batb":[[1,1.08,298.69],[2,1.07,1.71]],"ltp":1.09,"tv":137162.11,"id":9323645}]}]}
{"op":"mcm","clk":"4217022439","pt":1631557183108,"mc":[{"id":"1.187566733","rc":[{"trd":[[11,111.84]],"batb":[[0,8,26.64],[1,7.2,28.02],[2,6.4,22.15]],"ltp":11.0,"tv":15223.87,"id":8734382},{"trd":[[1.1,8223.35]],"batb":[[0,1.09,345.88]],"batl":[[0,1.1,321.35],[2,1.14,1699.96]],"ltp":1.1,"tv":137174.75,"id":9323645}],"tv":152398.62}]}
{"op":"mcm","clk":"4217022544","pt":1631557183902,"mc":[{"id":"1.187566733","rc":[{"batb":[[0,1.09,595.35]],"batl":[[0,1.1,1067.11]],"ltp":1.1,"tv":137174.75,"id":9323645}]}]}
{"op":"mcm","clk":"4217022673","pt":1631557184807,"mc":[{"id":"1.187566733","rc":[{"trd":[[1.09,16121.96]],"batb":[[0,1.08,298.69],[1,1.07,1.71],[2,1.06,525.75]],"batl":[[0,1.09,66.58],[1,1.1,1067.11],[2,1.11,261.35]],"ltp":1.09,"tv":138368.96,"id":9323645}],"tv":153592.83}]}
{"op":"mcm","clk":"4217022787","pt":1631557185771,"mc":[{"id":"1.187566733","rc":[{"batb":[[0,7.2,28.02],[1,6.4,22.15],[2,2.5,1.82]],"ltp":11.0,"tv":15223.87,"id":8734382},{"batl":[[1,1.1,119.64],[2,1.16,1781.2]],"ltp":1.09,"tv":138368.96,"id":9323645}]}]}
{"op":"mcm","clk":"4217022958","pt":1631557187011,"mc":[{"id":"1.187566733","rc":[{"batb":[[0,1.07,1.71],[1,1.06,525.75],[2,1.06,0]],"ltp":1.09,"tv":138368.96,"id":9323645}]}]}
{"op":"mcm","clk":"4217023112","pt":1631557188209,"mc":[{"id":"1.187566733","rc":[{"batb":[[0,1.07,208.29],[1,1.06,954.65]],"batl":[[0,1.1,119.64],[1,1.12,261.58],[2,1.13,338.67]],"ltp":1.09,"tv":138368.96,"id":9323645}]}]}
{"op":"mcm","clk":"4217023213","pt":1631557189038,"mc":[{"id":"1.187566733","rc":[{"batb":[[0,8,29.76],[1,7.2,28.02],[2,6.4,22.15]],"ltp":11.0,"tv":15223.87,"id":8734382}]}]}
{"op":"mcm","clk":"4217023531","pt":1631557191532,"mc":[{"id":"1.187566733","rc":[{"batl":[[0,1.1,76.98]],"ltp":1.09,"tv":138368.96,"id":9323645}]}]}
{"op":"mcm","clk":"4217023947","pt":1631557195047,"mc":[{"id":"1.187566733","rc":[{"batl":[[0,1.12,261.58],[1,1.13,338.67],[2,1.14,1788.68]],"ltp":1.09,"tv":138368.96,"id":9323645}]}]}
{"op":"mcm","clk":"4217024273","pt":1631557197451,"mc":[{"id":"1.187566733","rc":[{"batb":[[0,1.09,29.87],[1,1.07,208.29],[2,1.06,954.65]],"ltp":1.09,"tv":138368.96,"id":9323645}]}]}
{"op":"mcm","clk":"4217024571","pt":1631557199729,"mc":[{"id":"1.187566733","rc":[{"batb":[[0,1.11,1.71],[1,1.09,29.87],[2,1.07,208.29]],"ltp":1.09,"tv":138368.96,"id":9323645}]}]}
{"op":"mcm","clk":"4217024674","pt":1631557200557,"mc":[{"id":"1.187566733","rc":[{"batb":[[1,1.1,1.71],[2,1.09,29.87]],"ltp":1.09,"tv":138368.96,"id":9323645}]}]}
{"op":"mcm","clk":"4217025750","pt":1631557208960,"mc":[{"id":"1.187566733","rc":[{"batb":[[0,7.2,28.02],[1,6.4,22.15],[2,2.5,1.82]],"ltp":11.0,"tv":15223.87,"id":8734382},{"batl":[[0,1.16,1781.2],[1,1.23,31.44],[2,1.25,15]],"ltp":1.09,"tv":138368.96,"id":9323645}]}]}
{"op":"mcm","clk":"4217025935","pt":1631557210339,"mc":[{"id":"1.187566733","rc":[{"batb":[[0,1.07,206.58],[1,1.06,954.65],[2,1.09,0]],"ltp":1.09,"tv":138368.96,"id":9323645}]}]}
{"op":"mcm","clk":"4217026172","pt":1631557211970,"mc":[{"id":"1.187566733","rc":[{"batb":[[0,12,84.9],[1,11,18.18],[2,7.2,28.02]],"batl":[[0,15,7.56],[1,17.5,385.93],[2,990,0.01]],"ltp":11.0,"tv":15223.87,"id":8734382},{"batb":[[0,1.07,261.8],[2,1.05,28.13]],"batl":[[0,1.08,649.72],[1,1.09,5594.81],[2,1.1,13.76]],"ltp":1.09,"tv":138368.96,"id":9323645}]}]}
{"op":"mcm","clk":"4217026290","pt":1631557212759,"mc":[{"id":"1.187566733","rc":[{"batb":[[2,9.2,23.5]],"batl":[[2,18,1.66]],"ltp":11.0,"tv":15223.87,"id":8734382},{"trd":[[1.08,23327.83]],"batb":[[2,1.05,645.84]],"batl":[[0,1.08,640.79]],"ltp":1.08,"tv":138386.82,"id":9323645}],"tv":153610.69}]}
{"op":"mcm","clk":"4217026588","pt":1631557214939,"mc":[{"id":"1.187566733","rc":[{"batl":[[0,1.08,670.66]],"ltp":1.08,"tv":138386.82,"id":9323645}]}]}
{"op":"mcm","clk":"4217026745","pt":1631557216144,"mc":[{"id":"1.187566733","rc":[{"trd":[[13.5,141.91]],"ltp":13.5,"tv":15224.12,"id":8734382},{"trd":[[1.08,23337.06]],"batl":[[0,1.08,1181.24]],"ltp":1.08,"tv":138396.05,"id":9323645}],"tv":153620.17}]}
{"op":"mcm","clk":"4217026976","pt":1631557217858,"mc":[{"id":"1.187566733","rc":[{"trd":[[1.07,11548.63]],"batb":[[0,1.07,259.24]],"batl":[[0,1.08,1612.24]],"ltp":1.07,"tv":138401.17,"id":9323645}],"tv":153625.29}]}
{"op":"mcm","clk":"4217027141","pt":1631557219182,"mc":[{"id":"1.187566733","rc":[{"batb":[[1,11,42.55],[2,10,22.89]],"ltp":13.5,"tv":15224.12,"id":8734382},{"batl":[[2,1.1,2058.88]],"ltp":1.07,"tv":138401.17,"id":9323645}]}]}
{"op":"mcm","clk":"4217027608","pt":1631557222863,"mc":[{"id":"1.187566733","rc":[{"batl":[[0,17.5,385.93],[1,18,1.66],[2,19,1.68]],"ltp":13.5,"tv":15224.12,"id":8734382},{"batb":[[2,1.05,692.77]],"batl":[[0,1.08,1603.25]],"ltp":1.07,"tv":138401.17,"id":9323645}]}]}
{"op":"mcm","clk":"4217027683","pt":1631557223457,"mc":[{"id":"1.187566733","rc":[{"batl":[[1,1.09,5294.8]],"ltp":1.07,"tv":138401.17,"id":9323645}]}]}
{"op":"mcm","clk":"4217027999","pt":1631557225973,"mc":[{"id":"1.187566733","rc":[{"batl":[[0,15,8.65],[1,17.5,385.93],[2,18,1.66]],"ltp":13.5,"tv":15224.12,"id":8734382},{"batl":[[1,1.09,5470.67]],"ltp":1.07,"tv":138401.17,"id":9323645}]}]}
{"op":"mcm","clk":"4217028082","pt":1631557226554,"mc":[{"id":"1.187566733","rc":[{"batl":[[0,17.5,385.93],[1,18,1.66],[2,19,1.68]],"ltp":13.5,"tv":15224.12,"id":8734382},{"batb":[[0,1.07,260.95]],"batl":[[1,1.09,5294.8]],"ltp":1.07,"tv":138401.17,"id":9323645}]}]}
{"op":"mcm","clk":"4217028205","pt":1631557227558,"mc":[{"id":"1.187566733","rc":[{"batb":[[1,1.06,956.36]],"ltp":1.07,"tv":138401.17,"id":9323645}]}]}
{"op":"mcm","clk":"4217028352","pt":1631557228870,"mc":[{"id":"1.187566733","rc":[{"batb":[[0,1.07,205.73],[2,1.05,664.64]],"ltp":1.07,"tv":138401.17,"id":9323645}]}]}
{"op":"mcm","clk":"4217028398","pt":1631557229290,"mc":[{"id":"1.187566733","rc":[{"batl":[[0,15,8.65],[1,17.5,385.93],[2,18,1.66]],"ltp":13.5,"tv":15224.12,"id":8734382},{"batl":[[1,1.09,5470.67]],"ltp":1.07,"tv":138401.17,"id":9323645}]}]}
{"op":"mcm","clk":"4217029544","pt":1631557238191,"mc":[{"id":"1.187566733","rc":[{"batb":[[0,11,24.37],[1,10,22.89],[2,9.2,23.5]],"ltp":13.5,"tv":15224.12,"id":8734382},{"batb":[[0,1.07,1.71],[1,1.06,724.17],[2,1.05,664.16]],"batl":[[0,1.08,977.63],[1,1.1,2045.12],[2,1.11,1828.67]],"ltp":1.07,"tv":138401.17,"id":9323645}]}]}
{"op":"mcm","clk":"4217029678","pt":1631557239189,"mc":[{"id":"1.187566733","rc":[{"batb":[[0,10,22.89],[1,7.8,13.59],[2,7.2,28.02]],"ltp":13.5,"tv":15224.12,"id":8734382},{"batb":[[1,1.06,198.42]],"batl":[[0,1.08,29.87],[1,1.11,1828.67],[2,1.16,1781.2]],"ltp":1.07,"tv":138401.17,"id":9323645}]}]}
{"op":"mcm","clk":"4217029906","pt":1631557240981,"mc":[{"id":"1.187566733","rc":[{"batb":[[2,1.05,1109.07]],"batl":[[1,1.1,614.25],[2,1.11,1828.67]],"ltp":1.07,"tv":138401.17,"id":9323645}]}]}
{"op":"mcm","clk":"4217030050","pt":1631557242186,"mc":[{"id":"1.187566733","rc":[{"batb":[[0,11,22.87],[1,10,22.89],[2,7.8,13.59]],"ltp":13.5,"tv":15224.12,"id":8734382},{"batb":[[0,1.07,306.49]],"batl":[[1,1.1,2776.72]],"ltp":1.07,"tv":138401.17,"id":9323645}]}]}
{"op":"mcm","clk":"4217030444","pt":1631557245192,"mc":[{"id":"1.187566733","rc":[{"batb":[[1,1.06,1.71],[2,1.05,664.16]],"batl":[[1,1.1,2162.47]],"ltp":1.07,"tv":138401.17,"id":9323645}]}]}
{"op":"mcm","clk":"4217030544","pt":1631557245992,"mc":[{"id":"1.187566733","rc":[{"batb":[[0,10,22.89],[1,7.8,13.59],[2,7.2,28.02]],"ltp":13.5,"tv":15224.12,"id":8734382},{"batl":[[1,1.11,1828.67],[2,1.16,1781.2]],"ltp":1.07,"tv":138401.17,"id":9323645}]}]}
{"op":"mcm","clk":"4217030796","pt":1631557248083,"mc":[{"id":"1.187566733","rc":[{"batb":[[0,1.07,937.96]],"batl":[[0,1.08,570.04]],"ltp":1.07,"tv":138401.17,"id":9323645}]}]}
{"op":"mcm","clk":"4217030929","pt":1631557249183,"mc":[{"id":"1.187566733","rc":[{"batb":[[0,11,24.37],[1,10,22.89],[2,7.8,13.59]],"ltp":13.5,"tv":15224.12,"id":8734382},{"batl":[[1,1.1,2003.4],[2,1.11,1828.67]],"ltp":1.07,"tv":138401.17,"id":9323645}]}]}
{"op":"mcm","clk":"4217031036","pt":1631557250078,"mc":[{"id":"1.187566733","rc":[{"batb":[[0,10,22.89],[1,7.8,13.59],[2,7.2,28.02]],"ltp":13.5,"tv":15224.12,"id":8734382},{"batb":[[0,1.07,306.49]],"batl":[[0,1.08,29.87],[1,1.11,1828.67],[2,1.12,1799.19]],"ltp":1.07,"tv":138401.17,"id":9323645}]}]}
{"op":"mcm","clk":"4217031098","pt":1631557250602,"mc":[{"id":"1.187566733","rc":[{"batb":[[2,2.5,1.82]],"ltp":13.5,"tv":15224.12,"id":8734382},{"batl":[[2,1.23,1.45]],"ltp":1.07,"tv":138401.17,"id":9323645}]}]}
{"op":"mcm","clk":"4217031384","pt":1631557252708,"mc":[{"id":"1.187566733","rc":[{"batb":[[1,1.06,198.42],[2,1.05,1109.07]],"batl":[[1,1.1,614.25],[2,1.11,1828.67]],"ltp":1.07,"tv":138401.17,"id":9323645}]}]}
{"op":"mcm","clk":"4217031483","pt":1631557253595,"mc":[{"id":"1.187566733","rc":[{"batb":[[0,11,24.76],[1,10,22.89],[2,7.8,13.59]],"ltp":13.5,"tv":15224.12,"id":8734382},{"trd":[[1.08,23340.78]],"batl":[[0,1.08,28.01],[1,1.1,2889.51]],"ltp":1.08,"tv":138404.89,"id":9323645}],"tv":153629.01}]}
{"op":"mcm","clk":"4217031563","pt":1631557254284,"mc":[{"id":"1.187566733","rc":[{"batb":[[0,1.08,4.42],[1,1.07,306.49],[2,1.06,198.42]],"batl":[[0,1.1,2889.51],[1,1.11,1828.67],[2,1.12,1659.1]],"ltp":1.08,"tv":138404.89,"id":9323645}]}]}
{"op":"mcm","clk":"4217031742","pt":1631557255684,"mc":[{"id":"1.187566733","rc":[{"trd":[[1.1,8226.76]],"batl":[[0,1.1,2887.8]],"ltp":1.1,"tv":138408.31,"id":9323645}],"tv":153632.43}]}
{"op":"mcm","clk":"4217031883","pt":1631557256789,"mc":[{"id":"1.187566733","rc":[{"batb":[[0,1.09,1.71]],"ltp":1.1,"tv":138408.31,"id":9323645}]}]}
{"op":"mcm","clk":"4217032191","pt":1631557259414,"mc":[{"id":"1.187566733","rc":[{"batb":[[1,1.07,1.71]],"ltp":1.1,"tv":138408.31,"id":9323645}]}]}
{"op":"mcm","clk":"4217032446","pt":1631557261322,"mc":[{"id":"1.187566733","rc":[{"batb":[[2,1.06,1.71]],"ltp":1.1,"tv":138408.31,"id":9323645}]}]}
{"op":"mcm","clk":"4217032791","pt":1631557264207,"mc":[{"id":"1.187566733","rc":[{"batl":[[0,12,6.55],[1,13,26.92],[2,13.5,168.36]],"ltp":13.5,"tv":15224.12,"id":8734382},{"trd":[[1.1,8244.3]],"batb":[[1,1.08,5469.53],[2,1.07,1.71]],"batl":[[0,1.1,2904.31],[1,1.11,4162.99]],"ltp":1.1,"tv":138425.85,"id":9323645}],"tv":153649.97}]}
{"op":"mcm","clk":"4217032903","pt":1631557265108,"mc":[{"id":"1.187566733","rc":[{"batl":[[1,13,14.62]],"ltp":13.5,"tv":15224.12,"id":8734382},{"trd":[[1.1,8351.7]],"batb":[[1,1.08,3329.33]],"batl":[[0,1.1,2850.63],[1,1.11,4300.38],[2,1.12,1726.66]],"ltp":1.1,"tv":138533.24,"id":9323645}],"tv":153757.36}]}
{"op":"mcm","clk":"4217032975","pt":1631557265730,"mc":[{"id":"1.187566733","rc":[{"batl":[[1,13,10],[2,13.5,166.06]],"ltp":13.5,"tv":15224.12,"id":8734382},{"batl":[[1,1.11,4190.46],[2,1.12,1672.62]],"ltp":1.1,"tv":138533.24,"id":9323645}]}]}
{"op":"mcm","clk":"4217033220","pt":1631557267723,"mc":[{"id":"1.187566733","rc":[{"batb":[[0,10,22.89],[1,7.8,13.59],[2,6.4,22.91]],"ltp":13.5,"tv":15224.12,"id":8734382},{"batl":[[0,1.1,639.53]],"ltp":1.1,"tv":138533.24,"id":9323645}]}]}
{"op":"mcm","clk":"4217033399","pt":1631557269210,"mc":[{"id":"1.187566733","rc":[{"trd":[[11,112.15]],"ltp":11.0,"tv":15224.43,"id":8734382},{"trd":[[1.1,8360.98]],"batl":[[0,1.1,1573.86]],"ltp":1.1,"tv":138542.53,"id":9323645}],"tv":153766.96}]}
{"op":"mcm","clk":"4217033629","pt":1631557270941,"mc":[{"id":"1.187566733","rc":[{"batb":[[1,8,36.7],[2,7.8,13.59]],"ltp":11.0,"tv":15224.43,"id":8734382}]}]}
{"op":"mcm","clk":"4217034275","pt":1631557276155,"mc":[{"id":"1.187566733","rc":[{"batb":[[1,1.08,3324.88]],"ltp":1.1,"tv":138542.53,"id":9323645}]}]}
{"op":"mcm","clk":"4217034288","pt":1631557276217,"mc":[{"id":"1.187566733","rc":[{"batb":[[1,1.08,3102.42]],"ltp":1.1,"tv":138542.53,"id":9323645}]}]}
{"op":"mcm","clk":"4217034609","pt":1631557278826,"mc":[{"id":"1.187566733","rc":[{"batl":[[0,1.1,1575.57]],"ltp":1.1,"tv":138542.53,"id":9323645}]}]}
{"op":"mcm","clk":"4217034762","pt":1631557280043,"mc":[{"id":"1.187566733","rc":[{"batb":[[0,1.09,855.09]],"batl":[[1,1.11,4192.17]],"ltp":1.1,"tv":138542.53,"id":9323645}]}]}
{"op":"mcm","clk":"4217034945","pt":1631557281528,"mc":[{"id":"1.187566733","rc":[{"batb":[[1,1.08,2449.45]],"batl":[[0,1.1,967.51]],"ltp":1.1,"tv":138542.53,"id":9323645}]}]}
{"op":"mcm","clk":"4217035053","pt":1631557282431,"mc":[{"id":"1.187566733","rc":[{"batb":[[2,1.07,133.98]],"ltp":1.1,"tv":138542.53,"id":9323645}]}]}
{"op":"mcm","clk":"4217035376","pt":1631557284851,"mc":[{"id":"1.187566733","rc":[{"batl":[[2,1.12,1682.01]],"ltp":1.1,"tv":138542.53,"id":9323645}]}]}
{"op":"mcm","clk":"4217035913","pt":1631557289169,"mc":[{"id":"1.187566733","rc":[{"batb":[[0,8,36.7],[1,7.8,13.59],[2,7.2,29.47]],"ltp":11.0,"tv":15224.43,"id":8734382},{"batb":[[1,1.08,416.52]],"batl":[[0,1.1,942.23],[1,1.11,1.71],[2,1.12,9.39]],"ltp":1.1,"tv":138542.53,"id":9323645}]}]}
{"op":"mcm","clk":"4217036031","pt":1631557290075,"mc":[{"id":"1.187566733","rc":[{"batb":[[0,7.2,29.47],[1,6.4,22.91],[2,2.5,1.82]],"ltp":11.0,"tv":15224.43,"id":8734382},{"batb":[[1,1.08,1.71]],"batl":[[0,1.1,1.71]],"ltp":1.1,"tv":138542.53,"id":9323645}]}]}
{"op":"mcm","clk":"4217036256","pt":1631557291969,"mc":[{"id":"1.187566733","rc":[{"batb":[[2,1.07,748.15]],"ltp":1.1,"tv":138542.53,"id":9323645}]}]}
{"op":"mcm","clk":"4217036412","pt":1631557293143,"mc":[{"id":"1.187566733","rc":[{"batb":[[0,8,36.7],[1,7.2,29.47],[2,6.4,22.91]],"ltp":11.0,"tv":15224.43,"id":8734382}]}]}
{"op":"mcm","clk":"4217036534","pt":1631557294154,"mc":[{"id":"1.187566733","rc":[{"batb":[[0,7.2,29.47],[1,6.4,22.91],[2,2.5,1.82]],"ltp":11.0,"tv":15224.43,"id":8734382},{"batb":[[2,1.07,133.98]],"ltp":1.1,"tv":138542.53,"id":9323645}]}]}
{"op":"mcm","clk":"4217036903","pt":1631557297040,"mc":[{"id":"1.187566733","rc":[{"batb":[[0,1.09,1474.97]],"batl":[[0,1.1,309.36],[1,1.11,328.04]],"ltp":1.1,"tv":138542.53,"id":9323645}]}]}
{"op":"mcm","clk":"4217036994","pt":1631557297970,"mc":[{"id":"1.187566733","rc":[{"batb":[[0,1.09,855.09]],"batl":[[0,1.1,1.71],[1,1.11,1.71]],"ltp":1.1,"tv":138542.53,"id":9323645}]}]}
{"op":"mcm","clk":"4217037104","pt":1631557298871,"mc":[{"id":"1.187566733","rc":[{"trd":[[1.1,8361.89]],"batl":[[0,1.1,1.25]],"ltp":1.1,"tv":138543.43,"id":9323645}],"tv":153767.86}]}
{"op":"mcm","clk":"4217037244","pt":1631557300050,"mc":[{"id":"1.187566733","rc":[{"batb":[[0,1.1,188.2],[1,1.09,855.09],[2,1.08,1.71]],"batl":[[0,1.11,1.71],[1,1.12,9.39],[2,1.13,9.39]],"ltp":1.1,"tv":138543.43,"id":9323645}]}]}
{"op":"mcm","clk":"4217037393","pt":1631557301151,"mc":[{"id":"1.187566733","rc":[{"batb":[[0,8,36.7],[1,7.2,29.47],[2,6.4,22.91]],"ltp":11.0,"tv":15224.43,"id":8734382},{"trd":[[1.09,16720.34],[1.1,8738.25]],"batb":[[0,1.09,555.86],[1,1.08,1.71],[2,1.07,748.15]],"batl":[[2,1.13,607.33]],"ltp":1.09,"tv":139518.18,"id":9323645}],"tv":154742.61}]}
{"op":"mcm","clk":"4217037599","pt":1631557302773,"mc":[{"id":"1.187566733","rc":[{"batb":[[0,1.12,7.68],[1,1.09,555.86],[2,1.08,1.71]],"batl":[[0,1.13,607.33],[1,1.14,1934.47],[2,1.15,2554.22]],"ltp":1.09,"tv":139518.18,"id":9323645}]}]}
{"op":"mcm","clk":"4217038099","pt":1631557306871,"mc":[{"id":"1.187566733","rc":[{"batb":[[0,1.09,555.86],[1,1.08,1.71],[2,1.07,748.15]],"ltp":1.09,"tv":139518.18,"id":9323645}]}]}
{"op":"mcm","clk":"4217038269","pt":1631557308291,"mc":[{"id":"1.187566733","rc":[{"batl":[[0,1.1,160.44],[1,1.13,607.33],[2,1.14,1934.47]],"ltp":1.09,"tv":139518.18,"id":9323645}]}]}
{"op":"mcm","clk":"4217038628","pt":1631557310995,"mc":[{"id":"1.187566733","rc":[{"trd":[[11,113.99]],"ltp":11.0,"tv":15226.26,"id":8734382},{"trd":[[1.1,8756.62]],"batl":[[0,1.1,142.07]],"ltp":1.1,"tv":139536.54,"id":9323645}],"tv":154762.81}]}
{"op":"mcm","clk":"4217038760","pt":1631557311988,"mc":[{"id":"1.187566733","rc":[{"batb":[[1,1.08,11.09]],"batl":[[0,1.1,132.68]],"ltp":1.1,"tv":139536.54,"id":9323645}]}]}
{"op":"mcm","clk":"4217039007","pt":1631557313990,"mc":[{"id":"1.187566733","rc":[{"batb":[[2,1.07,133.98]],"ltp":1.1,"tv":139536.54,"id":9323645}]}]}
{"op":"mcm","clk":"4217039237","pt":1631557315675,"mc":[{"id":"1.187566733","rc":[{"batl":[[0,1.13,607.33],[1,1.14,1934.47],[2,1.15,1985.3]],"ltp":1.1,"tv":139536.54,"id":9323645}]}]}
{"op":"mcm","clk":"4217039430","pt":1631557317099,"mc":[{"id":"1.187566733","rc":[{"trd":[[8.6,96.45]],"batb":[[0,8,292.44]],"batl":[[0,9.2,5.75],[1,9.6,3.12],[2,9.8,1.56]],"ltp":8.6,"tv":15228.78,"id":8734382},{"trd":[[1.13,2297.85]],"batb":[[0,1.12,26.37],[1,1.11,4484.58],[2,1.09,555.86]],"batl":[[0,1.13,377.34]],"ltp":1.13,"tv":140038.96,"id":9323645}],"tv":155267.75}]}
{"op":"mcm","clk":"4217039584","pt":1631557318101,"mc":[{"id":"1.187566733","rc":[{"batb":[[0,8,296.2],[1,7.8,1.88],[2,7.6,1.88]],"ltp":8.6,"tv":15228.78,"id":8734382},{"trd":[[1.12,10039.78]],"batb":[[0,1.12,323.8],[1,1.11,922.39],[2,1.08,414.41]],"batl":[[2,1.15,1985.73]],"ltp":1.12,"tv":140046.98,"id":9323645}],"tv":155275.77}]}
{"op":"mcm","clk":"4217039847","pt":1631557320110,"mc":[{"id":"1.187566733","rc":[{"trd":[[1.12,10043.54]],"batb":[[0,1.12,321.92]],"ltp":1.12,"tv":140050.74,"id":9323645}],"tv":155279.53}]}
{"op":"mcm","clk":"4217039969","pt":1631557321048,"mc":[{"id":"1.187566733","rc":[{"batl":[[0,1.13,609.84]],"ltp":1.12,"tv":140050.74,"id":9323645}]}]}
{"op":"mcm","clk":"4217040181","pt":1631557322592,"mc":[{"id":"1.187566733","rc":[{"trd":[[8.6,96.86]],"ltp":8.6,"tv":15229.19,"id":8734382},{"trd":[[1.13,2367.62]],"batl":[[0,1.13,573.4]],"ltp":1.13,"tv":140120.5,"id":9323645}],"tv":155349.7}]}
{"op":"mcm","clk":"4217040385","pt":1631557324131,"mc":[{"id":"1.187566733","rc":[{"trd":[[1.12,10072.56],[1.13,2367.8]],"batb":[[0,1.12,307.41],[2,1.1,18.77]],"batl":[[0,1.13,1402.9]],"ltp":1.13,"tv":140149.71,"id":9323645}],"tv":155378.91}]}
{"op":"mcm","clk":"4217040544","pt":1631557325132,"mc":[{"id":"1.187566733","rc":[{"batb":[[0,1.12,648.76]],"ltp":1.13,"tv":140149.71,"id":9323645}]}]}
{"op":"mcm","clk":"4217040650","pt":1631557326029,"mc":[{"id":"1.187566733","rc":[{"trd":[[1.12,10075.98]],"batb":[[0,1.12,647.05]],"batl":[[0,1.13,1849.2]],"ltp":1.12,"tv":140153.12,"id":9323645}],"tv":155382.32}]}
{"op":"mcm","clk":"4217040750","pt":1631557326817,"mc":[{"id":"1.187566733","rc":[{"trd":[[8.6,111.48]],"ltp":8.6,"tv":15243.82,"id":8734382},{"trd":[[1.13,2479.1]],"batb":[[1,1.11,803.57]],"batl":[[0,1.13,1737.9]],"ltp":1.13,"tv":140264.42,"id":9323645}],"tv":155508.25}]}
{"op":"mcm","clk":"4217040906","pt":1631557328125,"mc":[{"id":"1.187566733","rc":[{"trd":[[1.12,10079.39]],"batb":[[0,1.12,645.34]],"ltp":1.12,"tv":140267.84,"id":9323645}],"tv":155511.66}]}
{"op":"mcm","clk":"4217041031","pt":1631557329125,"mc":[{"id":"1.187566733","rc":[{"trd":[[9.2,46.9]],"batl":[[0,9.2,5.12]],"ltp":9.2,"tv":15245.08,"id":8734382},{"trd":[[1.12,10479.46]],"batb":[[0,1.12,445.28],[1,1.11,490.34]],"ltp":1.12,"tv":140667.9,"id":9323645}],"tv":155912.99}]}
{"op":"mcm","clk":"4217041127","pt":1631557329706,"mc":[{"id":"1.187566733","rc":[{"batb":[[0,1.12,563.04]],"batl":[[0,1.13,1782.46],[1,1.14,2039.39]],"ltp":1.12,"tv":140667.9,"id":9323645}]}]}
{"op":"mcm","clk":"4217041383","pt":1631557331697,"mc":[{"id":"1.187566733","rc":[{"trd":[[1.13,2479.22]],"batl":[[0,1.13,1782.4]],"ltp":1.13,"tv":140668.02,"id":9323645}],"tv":155913.11}]}
{"op":"mcm","clk":"4217041527","pt":1631557332805,"mc":[{"id":"1.187566733","rc":[{"batl":[[1,1.14,2031.71],[2,1.15,1978.05]],"ltp":1.13,"tv":140668.02,"id":9323645}]}]}
{"op":"mcm","clk":"4217041924","pt":1631557336036,"mc":[{"id":"1.187566733","rc":[{"trd":[[1.13,2483.48]],"batb":[[0,1.12,411.14]],"batl":[[0,1.13,1780.27]],"ltp":1.13,"tv":140672.28,"id":9323645}],"tv":155917.37}]}
{"op":"mcm","clk":"4217042186","pt":1631557337951,"mc":[{"id":"1.187566733","rc":[{"trd":[[9.2,52.02]],"batl":[[0,9.6,3.12],[1,9.8,1.56],[2,10,263.28]],"ltp":9.2,"tv":15250.2,"id":8734382},{"trd":[[1.12,11343.72]],"batb":[[0,1.11,490.34],[1,1.1,18.77],[2,1.09,29.61]],"batl":[[0,1.12,46.87],[1,1.13,1780.27],[2,1.14,2031.71]],"ltp":1.12,"tv":141536.55,"id":9323645}],"tv":156786.76}]}
{"op":"mcm","clk":"4217042327","pt":1631557338950,"mc":[{"id":"1.187566733","rc":[{"batl":[[1,1.13,1749.49],[2,1.14,1926.79]],"ltp":1.12,"tv":141536.55,"id":9323645}]}]}
{"op":"mcm","clk":"4217042421","pt":1631557339539,"mc":[{"id":"1.187566733","rc":[{"trd":[[8.6,113.01],[9.2,57.72]],"ltp":8.6,"tv":15257.43,"id":8734382},{"trd":[[1.12,11390.59],[1.13,2495.09]],"batl":[[0,1.13,1737.88],[1,1.14,1926.79],[2,1.15,1978.05]],"ltp":1.13,"tv":141595.03,"id":9323645}],"tv":156852.46}]}
{"op":"mcm","clk":"4217042727","pt":1631557342139,"mc":[{"id":"1.187566733","rc":[{"batb":[[0,5.7,38.82],[1,5.1,39.04],[2,5,21.57]],"batl":[[0,13.5,2],[1,15.5,2],[2,10,0]],"ltp":8.6,"tv":15257.43,"id":8734382},{"batb":[[0,1.1,18.77],[1,1.08,446.47],[2,1.07,168.05]],"batl":[[0,1.13,692.58],[1,1.14,1.71],[2,1.15,1.71]],"ltp":1.13,"tv":141595.03,"id":9323645}]}]}
{"op":"mcm","clk":"4217042791","pt":1631557342616,"mc":[{"id":"1.187566733","rc":[{"batl":[[0,1.13,262.58]],"ltp":1.13,"tv":141595.03,"id":9323645}]}]}
{"op":"mcm","clk":"4217043089","pt":1631557345042,"mc":[{"id":"1.187566733","rc":[{"batb":[[1,5.2,19.13],[2,5.1,39.04]],"batl":[[0,12.5,2],[1,13.5,2],[2,15.5,2]],"ltp":8.6,"tv":15257.43,"id":8734382},{"batb":[[1,1.09,528.4],[2,1.08,569.69]],"batl":[[0,1.12,132.28],[1,1.13,262.58],[2,1.14,1.71]],"ltp":1.13,"tv":141595.03,"id":9323645}]}]}
{"op":"mcm","clk":"4217043240","pt":1631557346151,"mc":[{"id":"1.187566733","rc":[{"batb":[[0,5.2,19.13],[1,5.1,39.04],[2,2.5,1.82]],"batl":[[0,13.5,2],[1,15.5,2],[2,15.5,0]],"ltp":8.6,"tv":15257.43,"id":8734382},{"batb":[[1,1.09,497.79]],"batl":[[1,1.14,1.71],[2,1.15,1.71]],"ltp":1.13,"tv":141595.03,"id":9323645}]}]}
{"op":"mcm","clk":"4217043426","pt":1631557347628,"mc":[{"id":"1.187566733","rc":[{"batb":[[0,1.11,1.71],[1,1.1,18.77],[2,1.09,497.79]],"ltp":1.13,"tv":141595.03,"id":9323645}]}]}
{"op":"mcm","clk":"4217043620","pt":1631557349153,"mc":[{"id":"1.187566733","rc":[{"batb":[[0,10.5,12.96],[1,10,231.81],[2,9.8,12.56]],"batl":[[0,13.5,181.95],[1,14,9.7],[2,14.5,9.44]],"ltp":8.6,"tv":15257.43,"id":8734382},{"trd":[[1.1,8794.16],[1.11,10551.78]],"batb":[[0,1.09,497.79],[1,1.08,2873.75],[2,1.07,168.05]],"batl":[[0,1.1,446.18],[1,1.11,459.32],[2,1.12,132.28]],"ltp":1.1,"tv":141635.99,"id":9323645}],"tv":156893.42}]}
{"op":"mcm","clk":"4217043737","pt":1631557349959,"mc":[{"id":"1.187566733","rc":[{"trd":[[1.1,8811.56]],"batb":[[0,1.09,630.07],[1,1.08,2874.21]],"batl":[[0,1.1,437.48],[1,1.11,457.52]],"ltp":1.1,"tv":141653.39,"id":9323645}],"tv":156910.82}]}
{"op":"mcm","clk":"4217043952","pt":1631557351658,"mc":[{"id":"1.187566733","rc":[{"batb":[[0,11,3.72],[1,10.5,12.96],[2,10,231.81]],"batl":[[0,12,4.47],[1,13.5,181.95],[2,14,9.7]],"ltp":8.6,"tv":15257.43,"id":8734382},{"batl":[[0,1.1,474.73]],"ltp":1.1,"tv":141653.39,"id":9323645}]}]}
{"op":"mcm","clk":"4217044138","pt":1631557353067,"mc":[{"id":"1.187566733","rc":[{"batb":[[1,1.08,2842.15],[2,1.07,133.98]],"batl":[[0,1.1,932.09]],"ltp":1.1,"tv":141653.39,"id":9323645}]}]}
{"op":"mcm","clk":"4217044237","pt":1631557353764,"mc":[{"id":"1.187566733","rc":[{"batl":[[0,1.1,1290.09]],"ltp":1.1,"tv":141653.39,"id":9323645}]}]}
{"op":"mcm","clk":"4217044499","pt":1631557355862,"mc":[{"id":"1.187566733","rc":[{"batb":[[2,1.07,168.05]],"batl":[[2,1.12,18.77]],"ltp":1.1,"tv":141653.39,"id":9323645}]}]}
{"op":"mcm","clk":"4217044874","pt":1631557358755,"mc":[{"id":"1.187566733","rc":[{"batb":[[0,10.5,12.96],[1,10,231.81],[2,9.8,12.56]],"batl":[[0,13.5,181.95],[1,14,9.7],[2,14.5,9.44]],"ltp":8.6,"tv":15257.43,"id":8734382},{"batl":[[0,1.1,1252.84]],"ltp":1.1,"tv":141653.39,"id":9323645}]}]}
{"op":"mcm","clk":"4217044967","pt":1631557359450,"mc":[{"id":"1.187566733","rc":[{"batl":[[0,13.5,179.95]],"ltp":8.6,"tv":15257.43,"id":8734382}]}]}
{"op":"mcm","clk":"4217045138","pt":1631557360776,"mc":[{"id":"1.187566733","rc":[{"batl":[[1,1.11,167.91]],"ltp":1.1,"tv":141653.39,"id":9323645}]}]}
{"op":"mcm","clk":"4217045281","pt":1631557361866,"mc":[{"id":"1.187566733","rc":[{"batl":[[0,12,6.21],[1,13.5,179.95],[2,14,9.7]],"ltp":8.6,"tv":15257.43,"id":8734382},{"batl":[[0,1.1,1280.7]],"ltp":1.1,"tv":141653.39,"id":9323645}]}]}
{"op":"mcm","clk":"4217045438","pt":1631557363059,"mc":[{"id":"1.187566733","rc":[{"trd":[[1.1,8897.31]],"batb":[[1,1.08,2718.93]],"batl":[[0,1.1,1237.82]],"ltp":1.1,"tv":141739.13,"id":9323645}],"tv":156996.57}]}
{"op":"mcm","clk":"4217045886","pt":1631557366060,"mc":[{"id":"1.187566733","rc":[{"batb":[[0,1.09,659.92],[1,1.08,2664.22]],"batl":[[0,1.1,1260.1],[1,1.11,196.93]],"ltp":1.1,"tv":141739.13,"id":9323645}]}]}
{"op":"mcm","clk":"4217046172","pt":1631557368477,"mc":[{"id":"1.187566733","rc":[{"trd":[[1.1,8900.72]],"batl":[[0,1.1,1258.39]],"ltp":1.1,"tv":141742.55,"id":9323645}],"tv":156999.98}]}
{"op":"mcm","clk":"4217046375","pt":1631557370160,"mc":[{"id":"1.187566733","rc":[{"batb":[[0,8.2,12.59],[1,8,36.7],[2,7.2,29.32]],"batl":[[0,15.5,2],[1,18,2],[2,14,0]],"ltp":8.6,"tv":15257.43,"id":8734382},{"batb":[[0,1.09,132.28],[1,1.08,414.41]],"batl":[[0,1.1,815.36],[1,1.12,18.77],[2,1.13,132.28]],"ltp":1.1,"tv":141742.55,"id":9323645}]}]}
{"op":"mcm","clk":"4217046460","pt":1631557370890,"mc":[{"id":"1.187566733","rc":[{"batb":[[0,7.2,29.32],[1,6.6,20.98],[2,2.5,1.82]],"batl":[[0,18,2],[1,18,0]],"ltp":8.6,"tv":15257.43,"id":8734382},{"trd":[[1.1,8904.14]],"batb":[[1,1.08,11.09],[2,1.07,133.98]],"batl":[[0,1.12,18.77],[1,1.13,132.28],[2,1.14,133.98]],"ltp":1.1,"tv":141745.97,"id":9323645}],"tv":157003.4}]}
{"op":"mcm","clk":"4217046521","pt":1631557371374,"mc":[{"id":"1.187566733","rc":[{"batb":[[0,1.11,1.71],[1,1.09,132.28],[2,1.08,11.09]],"ltp":1.1,"tv":141745.97,"id":9323645}]}]}
{"op":"mcm","clk":"4217046722","pt":1631557372958,"mc":[{"id":"1.187566733","rc":[{"batl":[[1,1.13,394.87],[2,1.14,466.38]],"ltp":1.1,"tv":141745.97,"id":9323645}]}]}
{"op":"mcm","clk":"4217046891","pt":1631557374070,"mc":[{"id":"1.187566733","rc":[{"batb":[[0,8,27.85],[1,7.2,29.32],[2,6.6,20.98]],"ltp":8.6,"tv":15257.43,"id":8734382},{"batl":[[1,1.13,132.28],[2,1.14,1995.66]],"ltp":1.1,"tv":141745.97,"id":9323645}]}]}
{"op":"mcm","clk":"4217046933","pt":1631557374397,"mc":[{"id":"1.187566733","rc":[{"batb":[[0,7.2,29.32],[1,6.6,20.98],[2,2.5,1.82]],"ltp":8.6,"tv":15257.43,"id":8734382},{"batl":[[2,1.14,133.98]],"ltp":1.1,"tv":141745.97,"id":9323645}]}]}
{"op":"mcm","clk":"4217047295","pt":1631557377176,"mc":[{"id":"1.187566733","rc":[{"batl":[[0,15.5,2],[1,18,2]],"ltp":8.6,"tv":15257.43,"id":8734382},{"trd":[[1.11,10555.2]],"batb":[[0,1.09,752.16],[1,1.08,11.09],[2,1.07,171.05]],"batl":[[0,1.11,607],[1,1.12,18.77],[2,1.13,132.28]],"ltp":1.11,"tv":141749.38,"id":9323645}],"tv":157006.82}]}
{"op":"mcm","clk":"4217047364","pt":1631557377637,"mc":[{"id":"1.187566733","rc":[{"batb":[[0,8,36.7],[1,7.2,29.32],[2,6.6,20.98]],"ltp":8.6,"tv":15257.43,"id":8734382}]}]}
{"op":"mcm","clk":"4217047573","pt":1631557379197,"mc":[{"id":"1.187566733","rc":[{"batb":[[0,1.1,426.69],[1,1.09,752.16],[2,1.08,11.09]],"ltp":1.11,"tv":141749.38,"id":9323645}]}]}
{"op":"mcm","clk":"4217047664","pt":1631557380000,"mc":[{"id":"1.187566733","rc":[{"batl":[[1,1.12,374.35]],"ltp":1.11,"tv":141749.38,"id":9323645}]}]}
{"op":"mcm","clk":"4217047767","pt":1631557380568,"mc":[{"id":"1.187566733","rc":[{"batl":[[0,1.11,791]],"ltp":1.11,"tv":141749.38,"id":9323645}]}]}
{"op":"mcm","clk":"4217047858","pt":1631557381364,"mc":[{"id":"1.187566733","rc":[{"batb":[[1,1.09,619.88]],"ltp":1.11,"tv":141749.38,"id":9323645}]}]}
{"op":"mcm","clk":"4217048080","pt":1631557383004,"mc":[{"id":"1.187566733","rc":[{"trd":[[1.1,8910.97]],"batb":[[0,1.1,423.27],[1,1.08,11.09],[2,1.07,171.05]],"batl":[[0,1.11,184]],"ltp":1.1,"tv":141756.21,"id":9323645}],"tv":157013.64}]}
{"op":"mcm","clk":"4217048194","pt":1631557383895,"mc":[{"id":"1.187566733","rc":[{"batb":[[0,1.11,387.9],[1,1.1,423.27],[2,1.08,11.09]],"batl":[[0,1.12,374.35],[1,1.13,132.28],[2,1.14,2137.6]],"ltp":1.1,"tv":141756.21,"id":9323645}]}]}
{"op":"mcm","clk":"4217048338","pt":1631557385005,"mc":[{"id":"1.187566733","rc":[{"batb":[[0,1.1,423.27],[1,1.08,11.09],[2,1.07,171.05]],"ltp":1.1,"tv":141756.21,"id":9323645}]}]}
{"op":"mcm","clk":"4217048511","pt":1631557386061,"mc":[{"id":"1.187566733","rc":[{"batb":[[0,1.08,11.09],[1,1.07,802.52],[2,1.06,571.4]],"batl":[[0,1.11,29.87],[1,1.12,374.35],[2,1.13,393.96]],"ltp":1.1,"tv":141756.21,"id":9323645}]}]}
{"op":"mcm","clk":"4217048837","pt":1631557388707,"mc":[{"id":"1.187566733","rc":[{"batl":[[1,1.12,18.77]],"ltp":1.1,"tv":141756.21,"id":9323645}]}]}
{"op":"mcm","clk":"4217049005","pt":1631557390175,"mc":[{"id":"1.187566733","rc":[{"batl":[[0,18,2],[1,18,0]],"ltp":8.6,"tv":15257.43,"id":8734382},{"batb":[[1,1.07,133.98]],"ltp":1.1,"tv":141756.21,"id":9323645}]}]}
{"op":"mcm","clk":"4217049203","pt":1631557391902,"mc":[{"id":"1.187566733","rc":[{"batl":[[0,1.09,1.71]],"ltp":1.1,"tv":141756.21,"id":9323645}]}]}
{"op":"mcm","clk":"4217049345","pt":1631557393113,"mc":[{"id":"1.187566733","rc":[{"trd":[[9.2,60.01]],"batl":[[0,9.2,18.11],[1,9.4,2],[2,9.8,9.19]],"ltp":9.2,"tv":15259.72,"id":8734382},{"trd":[[1.09,16723.76],[1.12,11409.37],[1.13,2615.39]],"batb":[[0,1.12,409.1],[1,1.11,562.27],[2,1.09,9232.95]],"batl":[[0,1.13,370.94],[1,1.14,2470.91],[2,1.15,4200.38]],"ltp":1.13,"tv":141898.7,"id":9323645}],"tv":157158.42}]}
{"op":"mcm","clk":"4217049444","pt":1631557393901,"mc":[{"id":"1.187566733","rc":[{"batb":[[0,8,40.46],[1,7.8,1.88],[2,7.6,1.88]],"batl":[[2,9.8,3.06]],"ltp":9.2,"tv":15259.72,"id":8734382},{"batb":[[1,1.11,878.31]],"batl":[[2,1.15,4200.81]],"ltp":1.13,"tv":141898.7,"id":9323645}]}]}
{"op":"mcm","clk":"4217049848","pt":1631557397009,"mc":[{"id":"1.187566733","rc":[{"trd":[[8.6,114.72]],"ltp":8.6,"tv":15261.43,"id":8734382},{"trd":[[1.13,2628.38]],"batl":[[0,1.13,731.54]],"ltp":1.13,"tv":141911.69,"id":9323645}],"tv":157173.12}]}
{"op":"mcm","clk":"4217049972","pt":1631557397908,"mc":[{"id":"1.187566733","rc":[{"trd":[[1.12,11446.91]],"batb":[[0,1.12,390.33]],"batl":[[0,1.13,1087.54]],"ltp":1.12,"tv":141949.23,"id":9323645}],"tv":157210.66}]}
{"op":"mcm","clk":"4217050097","pt":1631557399004,"mc":[{"id":"1.187566733","rc":[{"trd":[[1.12,11484.46]],"batb":[[0,1.12,371.56]],"ltp":1.12,"tv":141986.78,"id":9323645}],"tv":157248.21}]}
{"op":"mcm","clk":"4217050194","pt":1631557399696,"mc":[{"id":"1.187566733","rc":[{"batb":[[1,1.11,898.31],[2,1.09,9260.67]],"ltp":1.12,"tv":141986.78,"id":9323645}]}]}
{"op":"mcm","clk":"4217050469","pt":1631557402016,"mc":[{"id":"1.187566733","rc":[{"batb":[[0,1.12,385.24]],"ltp":1.12,"tv":141986.78,"id":9323645}]}]}
{"op":"mcm","clk":"4217050688","pt":1631557403597,"mc":[{"id":"1.187566733","rc":[{"batl":[[0,1.13,1415.76]],"ltp":1.12,"tv":141986.78,"id":9323645}]}]}
{"op":"mcm","clk":"4217050853","pt":1631557404812,"mc":[{"id":"1.187566733","rc":[{"batb":[[1,1.11,557.98]],"ltp":1.12,"tv":141986.78,"id":9323645}]}]}
{"op":"mcm","clk":"4217051553","pt":1631557410115,"mc":[{"id":"1.187566733","rc":[{"trd":[[1.12,11884.46],[1.13,2688.76]],"batb":[[0,1.12,158.87]],"batl":[[0,1.13,1385.57],[1,1.14,2368.71]],"ltp":1.12,"tv":142447.16,"id":9323645}],"tv":157708.59}]}
{"op":"mcm","clk":"4217051838","pt":1631557412123,"mc":[{"id":"1.187566733","rc":[{"trd":[[8.6,119.78]],"ltp":8.6,"tv":15266.48,"id":8734382},{"trd":[[1.13,2727.28]],"batl":[[0,1.13,1347.05]],"ltp":1.13,"tv":142485.68,"id":9323645}],"tv":157752.17}]}
{"op":"mcm","clk":"4217051969","pt":1631557413016,"mc":[{"id":"1.187566733","rc":[{"trd":[[1.13,2767.28]],"batb":[[0,1.12,259.04],[1,1.11,663.83]],"batl":[[0,1.13,1430.16]],"ltp":1.13,"tv":142525.68,"id":9323645}],"tv":157792.17}]}
{"op":"mcm","clk":"4217052124","pt":1631557414165,"mc":[{"id":"1.187566733","rc":[{"batb":[[0,1.12,260.75],[1,1.11,648.75]],"ltp":1.13,"tv":142525.68,"id":9323645}]}]}
{"op":"mcm","clk":"4217052282","pt":1631557415334,"mc":[{"id":"1.187566733","rc":[{"batb":[[2,1.09,9392.95]],"ltp":1.13,"tv":142525.68,"id":9323645}]}]}
{"op":"mcm","clk":"4217052415","pt":1631557416335,"mc":[{"id":"1.187566733","rc":[{"batb":[[0,1.12,277.39]],"batl":[[0,1.13,1443.37],[1,1.14,2384.91]],"ltp":1.13,"tv":142525.68,"id":9323645}]}]}
{"op":"mcm","clk":"4217052618","pt":1631557417814,"mc":[{"id":"1.187566733","rc":[{"batb":[[0,5.7,38.82],[1,5.1,60.91],[2,2.5,1.82]],"batl":[[0,9.4,2],[1,12.5,2],[2,15.5,2]],"ltp":8.6,"tv":15266.48,"id":8734382},{"batb":[[0,1.12,1.71],[1,1.11,1.71],[2,1.09,160]],"batl":[[0,1.13,684.22],[1,1.14,133.98],[2,1.15,1.71]],"ltp":1.13,"tv":142525.68,"id":9323645}]}]}
{"op":"mcm","clk":"4217052819","pt":1631557419133,"mc":[{"id":"1.187566733","rc":[{"batl":[[1,15.5,2],[2,15.5,0]],"ltp":8.6,"tv":15266.48,"id":8734382},{"trd":[[1.13,2777.28]],"batb":[[2,1.1,28.85]],"batl":[[0,1.13,323.22]],"ltp":1.13,"tv":142535.68,"id":9323645}],"tv":157802.17}]}
{"op":"mcm","clk":"4217052970","pt":1631557420132,"mc":[{"id":"1.187566733","rc":[{"batl":[[0,15.5,2],[1,15.5,0]],"ltp":8.6,"tv":15266.48,"id":8734382},{"batb":[[0,1.11,1.71],[1,1.1,28.85],[2,1.09,132.28]],"ltp":1.13,"tv":142535.68,"id":9323645}]}]}
{"op":"mcm","clk":"4217053102","pt":1631557421131,"mc":[{"id":"1.187566733","rc":[{"trd":[[8.6,123.86]],"ltp":8.6,"tv":15270.57,"id":8734382},{"trd":[[1.13,2808.37]],"batb":[[0,1.1,28.85],[1,1.09,752.16],[2,1.08,456.56]],"batl":[[0,1.13,292.13]],"ltp":1.13,"tv":142566.77,"id":9323645}],"tv":157837.34}]}
{"op":"mcm","clk":"4217053241","pt":1631557422133,"mc":[{"id":"1.187566733","rc":[{"batl":[[0,12.5,2],[1,15.5,2]],"ltp":8.6,"tv":15270.57,"id":8734382},{"batb":[[1,1.09,162.89]],"batl":[[0,1.13,293.84]],"ltp":1.13,"tv":142566.77,"id":9323645}]}]}
{"op":"mcm","clk":"4217053293","pt":1631557422551,"mc":[{"id":"1.187566733","rc":[{"batl":[[0,15.5,2],[1,15.5,0]],"ltp":8.6,"tv":15270.57,"id":8734382},{"batb":[[1,1.09,132.28]],"ltp":1.13,"tv":142566.77,"id":9323645}]}]}
{"op":"mcm","clk":"4217053418","pt":1631557423711,"mc":[{"id":"1.187566733","rc":[{"batb":[[0,5.1,60.91],[1,2.5,1.82],[2,1.01,98.87]],"ltp":8.6,"tv":15270.57,"id":8734382},{"batl":[[0,1.13,1.71]],"ltp":1.13,"tv":142566.77,"id":9323645}]}]}
{"op":"mcm","clk":"4217053582","pt":1631557425030,"mc":[{"id":"1.187566733","rc":[{"trd":[[1.13,2811.78]],"batb":[[0,1.13,170.58],[1,1.12,429.45],[2,1.1,28.85]],"batl":[[0,1.14,508.83],[1,1.15,217.66],[2,1.16,3.41]],"ltp":1.13,"tv":142570.18,"id":9323645}],"tv":157840.76}]}
{"op":"mcm","clk":"4217053694","pt":1631557425816,"mc":[{"id":"1.187566733","rc":[{"batl":[[0,12.5,2],[1,15.5,2]],"ltp":8.6,"tv":15270.57,"id":8734382},{"trd":[[1.14,0.07]],"batl":[[0,1.14,508.8]],"ltp":1.14,"tv":142570.25,"id":9323645}],"tv":157840.83}]}
{"op":"mcm","clk":"4217053835","pt":1631557426928,"mc":[{"id":"1.187566733","rc":[{"batb":[[0,5.7,40.52],[1,5.1,60.91],[2,2.5,1.82]],"ltp":8.6,"tv":15270.57,"id":8734382}]}]}
{"op":"mcm","clk":"4217053977","pt":1631557428140,"mc":[{"id":"1.187566733","rc":[{"trd":[[1.13,2819.3]],"batb":[[0,1.13,166.82],[2,1.11,387.9]],"batl":[[1,1.15,502.12]],"ltp":1.13,"tv":142577.77,"id":9323645}],"tv":157848.35}]}
{"op":"mcm","clk":"4217054081","pt":1631557428926,"mc":[{"id":"1.187566733","rc":[{"batb":[[0,1.13,495.04],[1,1.12,561.73]],"ltp":1.13,"tv":142577.77,"id":9323645}]}]}
{"op":"mcm","clk":"4217054230","pt":1631557430140,"mc":[{"id":"1.187566733","rc":[{"batb":[[0,1.13,166.82],[1,1.12,785.02]],"batl":[[0,1.14,1097.26]],"ltp":1.13,"tv":142577.77,"id":9323645}]}]}
{"op":"mcm","clk":"4217054356","pt":1631557431049,"mc":[{"id":"1.187566733","rc":[{"batb":[[0,1.12,355.57],[1,1.11,387.9],[2,1.1,455.54]],"batl":[[0,1.14,720.7],[1,1.15,286.17]],"ltp":1.13,"tv":142577.77,"id":9323645}]}]}
{"op":"mcm","clk":"4217054464","pt":1631557431941,"mc":[{"id":"1.187566733","rc":[{"batb":[[0,1.13,1.71],[1,1.1,28.85],[2,1.09,160.89]],"batl":[[0,1.14,132.24]],"ltp":1.13,"tv":142577.77,"id":9323645}]}]}
{"op":"mcm","clk":"4217054500","pt":1631557432251,"mc":[{"id":"1.187566733","rc":[{"batl":[[0,15.5,2],[1,15.5,0]],"ltp":8.6,"tv":15270.57,"id":8734382},{"batb":[[2,1.09,132.28]],"ltp":1.13,"tv":142577.77,"id":9323645}]}]}
{"op":"mcm","clk":"4217054728","pt":1631557434042,"mc":[{"id":"1.187566733","rc":[{"batb":[[0,5.1,60.91],[1,2.5,1.82],[2,1.01,98.87]],"ltp":8.6,"tv":15270.57,"id":8734382},{"batb":[[2,1.09,752.16]],"batl":[[1,1.15,1.71]],"ltp":1.13,"tv":142577.77,"id":9323645}]}]}
{"op":"mcm","clk":"4217054860","pt":1631557434939,"mc":[{"id":"1.187566733","rc":[{"trd":[[1.13,2822.72]],"batb":[[0,1.1,28.85],[1,1.09,752.16],[2,1.08,456.56]],"ltp":1.13,"tv":142581.19,"id":9323645}],"tv":157851.76}]}
{"op":"mcm","clk":"4217054921","pt":1631557435456,"mc":[{"id":"1.187566733","rc":[{"batl":[[0,12.5,2],[1,15.5,2]],"ltp":8.6,"tv":15270.57,"id":8734382},{"batb":[[1,1.09,781.77]],"ltp":1.13,"tv":142581.19,"id":9323645}]}]}
{"op":"mcm","clk":"4217055117","pt":1631557436947,"mc":[{"id":"1.187566733","rc":[{"batb":[[0,5.7,40.62],[1,5.1,60.91],[2,2.5,1.82]],"ltp":8.6,"tv":15270.57,"id":8734382}]}]}
{"op":"mcm","clk":"4217055400","pt":1631557439064,"mc":[{"id":"1.187566733","rc":[{"batl":[[0,1.11,9.39],[1,1.14,132.24],[2,1.15,1.71]],"ltp":1.13,"tv":142581.19,"id":9323645}]}]}
{"op":"mcm","clk":"4217055790","pt":1631557441949,"mc":[{"id":"1.187566733","rc":[{"trd":[[8,13.69],[10,14.79]],"ltp":8.0,"tv":15285.3,"id":8734382},{"trd":[[1.11,10564.59],[1.14,96.13]],"batl":[[0,1.14,36.18],[1,1.15,1.71],[2,1.16,3.41]],"ltp":1.14,"tv":142686.64,"id":9323645}],"tv":157971.94}]}
{"op":"mcm","clk":"4217056181","pt":1631557444674,"mc":[{"id":"1.187566733","rc":[{"batb":[[0,5.1,60.91],[1,2.5,1.82],[2,1.01,98.87]],"ltp":8.0,"tv":15285.3,"id":8734382}]}]}
{"op":"mcm","clk":"4217056497","pt":1631557447036,"mc":[{"id":"1.187566733","rc":[{"batl":[[0,12,8.65],[1,12.5,2],[2,13.5,203.55]],"ltp":8.0,"tv":15285.3,"id":8734382},{"batb":[[2,1.08,3000.91]],"batl":[[0,1.11,4065.17],[1,1.12,3329.12],[2,1.13,67.56]],"ltp":1.14,"tv":142686.64,"id":9323645}]}]}
{"op":"mcm","clk":"4217056655","pt":1631557448143,"mc":[{"id":"1.187566733","rc":[{"batb":[[0,11,140.96],[1,5.1,60.91],[2,2.5,1.82]],"batl":[[2,13,11.54]],"ltp":8.0,"tv":15285.3,"id":8734382},{"trd":[[1.1,8986.07]],"batb":[[0,1.09,835.97],[1,1.08,3003.23],[2,1.07,195.66]],"batl":[[0,1.1,2888.54],[1,1.11,997.06],[2,1.12,3329.12]],"ltp":1.1,"tv":142761.74,"id":9323645}],"tv":158047.04}]}
{"op":"mcm","clk":"4217056799","pt":1631557449151,"mc":[{"id":"1.187566733","rc":[{"batb":[[1,8,13.51],[2,6.4,22.49]],"batl":[[2,13,2.3]],"ltp":8.0,"tv":15285.3,"id":8734382},{"batb":[[0,1.09,703.69],[1,1.08,2990.27],[2,1.07,61.68]],"batl":[[1,1.11,943],[2,1.12,3302.1]],"ltp":1.1,"tv":142761.74,"id":9323645}]}]}
{"op":"mcm","clk":"4217057089","pt":1631557451156,"mc":[{"id":"1.187566733","rc":[{"batb":[[1,1.08,2960.71],[2,1.07,27.61]],"batl":[[1,1.11,968.77]],"ltp":1.1,"tv":142761.74,"id":9323645}]}]}
{"op":"mcm","clk":"4217057224","pt":1631557452098,"mc":[{"id":"1.187566733","rc":[{"trd":[[11,121.99]],"batb":[[0,11,136.96]],"ltp":11.0,"tv":15293.3,"id":8734382},{"batl":[[0,1.1,3249.55]],"ltp":1.1,"tv":142761.74,"id":9323645}],"tv":158055.04}]}
{"op":"mcm","clk":"4217057515","pt":1631557454173,"mc":[{"id":"1.187566733","rc":[{"batb":[[1,8,50.21],[2,7.2,28.37]],"ltp":11.0,"tv":15293.3,"id":8734382},{"batl":[[0,1.1,3866.55]],"ltp":1.1,"tv":142761.74,"id":9323645}]}]}
{"op":"mcm","clk":"4217057843","pt":1631557456486,"mc":[{"id":"1.187566733","rc":[{"batl":[[0,1.1,3875.94]],"ltp":1.1,"tv":142761.74,"id":9323645}]}]}
{"op":"mcm","clk":"4217058232","pt":1631557459178,"mc":[{"id":"1.187566733","rc":[{"batl":[[1,1.11,810.28]],"ltp":1.1,"tv":142761.74,"id":9323645}]}]}
{"op":"mcm","clk":"4217058910","pt":1631557464384,"mc":[{"id":"1.187566733","rc":[{"batb":[[0,1.09,649.49],[2,1.06,513.17]],"ltp":1.1,"tv":142761.74,"id":9323645}]}]}
{"op":"mcm","clk":"4217059374","pt":1631557468107,"mc":[{"id":"1.187566733","rc":[{"trd":[[1.1,8991.61]],"batl":[[0,1.1,4214.51]],"ltp":1.1,"tv":142767.28,"id":9323645}],"tv":158060.58}]}
{"op":"mcm","clk":"4217059609","pt":1631557469898,"mc":[{"id":"1.187566733","rc":[{"batb":[[0,8,36.7],[1,7.2,28.37],[2,6.4,22.49]],"batl":[[0,990,0.01],[1,12.5,0],[2,13,0]],"ltp":11.0,"tv":15293.3,"id":8734382},{"batb":[[0,1.06,513.17],[1,1.08,0],[2,1.06,0]],"batl":[[0,1.1,967.73],[1,1.11,132.28],[2,1.13,9.39]],"ltp":1.1,"tv":142767.28,"id":9323645}]}]}
{"op":"mcm","clk":"4217059756","pt":1631557470908,"mc":[{"id":"1.187566733","rc":[{"batl":[[0,1.1,350.73]],"ltp":1.1,"tv":142767.28,"id":9323645}]}]}
{"op":"mcm","clk":"4217060020","pt":1631557472895,"mc":[{"id":"1.187566733","rc":[{"trd":[[11,127.96]],"ltp":11.0,"tv":15299.27,"id":8734382},{"trd":[[1.1,9051.34]],"batb":[[0,1.07,631.47],[1,1.06,513.17]],"batl":[[0,1.1,291]],"ltp":1.1,"tv":142827.01,"id":9323645}],"tv":158126.29}]}
{"op":"mcm","clk":"4217060306","pt":1631557475016,"mc":[{"id":"1.187566733","rc":[{"batb":[[0,1.07,1606.76]],"ltp":1.1,"tv":142827.01,"id":9323645}]}]}
{"op":"mcm","clk":"4217060696","pt":1631557478035,"mc":[{"id":"1.187566733","rc":[{"batl":[[0,1.08,1.71],[1,1.1,291],[2,1.11,132.28]],"ltp":1.1,"tv":142827.01,"id":9323645}]}]}
{"op":"mcm","clk":"4217060766","pt":1631557478527,"mc":[{"id":"1.187566733","rc":[{"batl":[[1,1.09,1.71],[2,1.1,291]],"ltp":1.1,"tv":142827.01,"id":9323645}]}]}
{"op":"mcm","clk":"4217061157","pt":1631557481329,"mc":[{"id":"1.187566733","rc":[{"trd":[[1.08,23344.19],[1.09,16727.18],[1.1,9633.46]],"batb":[[0,1.1,1137.31],[1,1.07,1606.76],[2,1.06,513.17]],"batl":[[0,1.11,132.28],[1,1.13,9.39],[2,1.14,2405.34]],"ltp":1.1,"tv":143415.96,"id":9323645}],"tv":158715.23}]}
{"op":"mcm","clk":"4217061397","pt":1631557483024,"mc":[{"id":"1.187566733","rc":[{"batb":[[0,1.1,1157.31],[1,1.08,426.69],[2,1.07,1606.76]],"ltp":1.1,"tv":143415.96,"id":9323645}]}]}
{"op":"mcm","clk":"4217061500","pt":1631557483646,"mc":[{"id":"1.187566733","rc":[{"batb":[[1,1.07,631.47],[2,1.06,513.17]],"ltp":1.1,"tv":143415.96,"id":9323645}]}]}
{"op":"mcm","clk":"4217061716","pt":1631557485127,"mc":[{"id":"1.187566733","rc":[{"batb":[[0,1.1,20]],"ltp":1.1,"tv":143415.96,"id":9323645}]}]}
{"op":"mcm","clk":"4217062180","pt":1631557488243,"mc":[{"id":"1.187566733","rc":[{"batb":[[0,1.07,631.47],[1,1.06,513.17],[2,1.06,0]],"batl":[[0,1.11,130.57]],"ltp":1.1,"tv":143415.96,"id":9323645}]}]}
{"op":"mcm","clk":"4217062446","pt":1631557490121,"mc":[{"id":"1.187566733","rc":[{"batb":[[0,1.1,1.71],[1,1.07,631.47],[2,1.06,513.17]],"batl":[[0,1.11,128.86]],"ltp":1.1,"tv":143415.96,"id":9323645}]}]}
{"op":"mcm","clk":"4217062709","pt":1631557492156,"mc":[{"id":"1.187566733","rc":[{"batl":[[0,1.13,9.39],[1,1.14,2405.34],[2,1.15,1901.18]],"ltp":1.1,"tv":143415.96,"id":9323645}]}]}
{"op":"mcm","clk":"4217063037","pt":1631557494553,"mc":[{"id":"1.187566733","rc":[{"batb":[[0,7.2,28.37],[1,6.4,22.49],[2,2.5,1.82]],"ltp":11.0,"tv":15299.27,"id":8734382},{"batb":[[0,1.11,20],[1,1.1,1.71],[2,1.07,631.47]],"batl":[[1,1.14,9.39],[2,1.15,9.39]],"ltp":1.1,"tv":143415.96,"id":9323645}]}]}
{"op":"mcm","clk":"4217063393","pt":1631557497145,"mc":[{"id":"1.187566733","rc":[{"batb":[[0,12,89.4],[1,11,178.13],[2,7.2,28.37]],"batl":[[0,15,237.43],[1,990,0.01]],"ltp":11.0,"tv":15299.27,"id":8734382},{"trd":[[1.1,9636.87],[1.11,10644.59]],"batb":[[0,1.07,631.47],[1,1.06,513.17],[2,1.07,0]],"batl":[[0,1.09,7481.69],[1,1.1,1850.12],[2,1.11,68.8]],"ltp":1.1,"tv":143499.37,"id":9323645}],"tv":158798.65}]}
{"op":"mcm","clk":"4217063500","pt":1631557497948,"mc":[{"id":"1.187566733","rc":[{"batb":[[0,11,178.13],[1,9,24.42],[2,7.8,14.01]],"batl":[[1,16,9.38],[2,16.5,4.7]],"ltp":11.0,"tv":15299.27,"id":8734382},{"trd":[[1.09,16745.04]],"batb":[[0,1.07,686.69],[1,1.06,515.53],[2,1.05,623.54]],"batl":[[0,1.09,1254.63],[1,1.1,1795.08],[2,1.11,13.76]],"ltp":1.09,"tv":143517.23,"id":9323645}],"tv":158816.51}]}
{"op":"mcm","clk":"4217063559","pt":1631557498360,"mc":[{"id":"1.187566733","rc":[{"batl":[[1,16,1.88],[2,17,1.88]],"ltp":11.0,"tv":15299.27,"id":8734382},{"batb":[[1,1.06,513.64]],"batl":[[0,1.09,1252.79]],"ltp":1.09,"tv":143517.23,"id":9323645}]}]}
{"op":"mcm","clk":"4217064073","pt":1631557502161,"mc":[{"id":"1.187566733","rc":[{"trd":[[12,348.34]],"ltp":12.0,"tv":15302.88,"id":8734382},{"trd":[[1.09,16784.84]],"batl":[[0,1.09,1885.87]],"ltp":1.09,"tv":143557.03,"id":9323645}],"tv":158859.92}]}
{"op":"mcm","clk":"4217064199","pt":1631557503057,"mc":[{"id":"1.187566733","rc":[{"batl":[[0,1.08,533.77],[1,1.09,1885.87],[2,1.1,1795.08]],"ltp":1.09,"tv":143557.03,"id":9323645}]}]}
{"op":"mcm","clk":"4217064402","pt":1631557504437,"mc":[{"id":"1.187566733","rc":[{"batb":[[0,11,201.55],[1,10,26.21],[2,9,24.42]],"ltp":12.0,"tv":15302.88,"id":8734382},{"batl":[[1,1.09,2018.15],[2,1.1,4162.47]],"ltp":1.09,"tv":143557.03,"id":9323645}]}]}
{"op":"mcm","clk":"4217064622","pt":1631557505862,"mc":[{"id":"1.187566733","rc":[{"trd":[[1.08,23472.19]],"batl":[[0,1.08,1101.97]],"ltp":1.08,"tv":143685.03,"id":9323645}],"tv":158987.92}]}
{"op":"mcm","clk":"4217065092","pt":1631557509073,"mc":[{"id":"1.187566733","rc":[{"trd":[[1.08,23475.91]],"batl":[[0,1.08,1100.11],[1,1.09,1770.54]],"ltp":1.08,"tv":143688.75,"id":9323645}],"tv":158991.64}]}
{"op":"mcm","clk":"4217065512","pt":1631557512136,"mc":[{"id":"1.187566733","rc":[{"trd":[[13.5,142.36]],"ltp":13.5,"tv":15303.33,"id":8734382},{"trd":[[1.08,23481.54]],"batl":[[0,1.08,1094.48]],"ltp":1.08,"tv":143694.38,"id":9323645}],"tv":158997.72}]}
{"op":"mcm","clk":"4217065862","pt":1631557514659,"mc":[{"id":"1.187566733","rc":[{"batb":[[0,1.07,633.18],[2,1.05,595.41]],"ltp":1.08,"tv":143694.38,"id":9323645}]}]}
{"op":"mcm","clk":"4217066007","pt":1631557515770,"mc":[{"id":"1.187566733","rc":[{"batb":[[1,1.06,515.34]],"ltp":1.08,"tv":143694.38,"id":9323645}]}]}
{"op":"mcm","clk":"4217066298","pt":1631557518143,"mc":[{"id":"1.187566733","rc":[{"trd":[[13.5,153.46]],"ltp":13.5,"tv":15314.43,"id":8734382},{"trd":[[1.08,23820.19]],"batb":[[2,1.05,597.11]],"batl":[[0,1.08,855.83]],"ltp":1.08,"tv":144033.03,"id":9323645}],"tv":159347.47}]}
{"op":"mcm","clk":"4217066534","pt":1631557519999,"mc":[{"id":"1.187566733","rc":[{"trd":[[1.08,24024.19]],"batl":[[0,1.08,753.83]],"ltp":1.08,"tv":144237.03,"id":9323645}],"tv":159551.47}]}
{"op":"mcm","clk":"4217067081","pt":1631557523951,"mc":[{"id":"1.187566733","rc":[{"batb":[[1,1.06,1226.5]],"batl":[[0,1.08,1165.97]],"ltp":1.08,"tv":144237.03,"id":9323645}]}]}
{"op":"mcm","clk":"4217067292","pt":1631557525383,"mc":[{"id":"1.187566733","rc":[{"trd":[[1.08,24027.79]],"batl":[[0,1.08,1164.17]],"ltp":1.08,"tv":144240.63,"id":9323645}],"tv":159555.07}]}
{"op":"mcm","clk":"4217067642","pt":1631557528064,"mc":[{"id":"1.187566733","rc":[{"batb":[[0,10,26.21],[1,9,24.42],[2,7.8,14.01]],"batl":[[0,990,0.01],[1,16,0],[2,17,0]],"ltp":13.5,"tv":15314.43,"id":8734382},{"trd":[[1.08,26339.75]],"batb":[[0,1.08,26.53],[1,1.07,1.71],[2,1.06,1226.03]],"batl":[[0,1.09,132.28],[1,1.11,1944.96],[2,1.13,9.39]],"ltp":1.08,"tv":146552.59,"id":9323645}],"tv":161867.02}]}
{"op":"mcm","clk":"4217067752","pt":1631557528964,"mc":[{"id":"1.187566733","rc":[{"batb":[[1,7.8,14.01],[2,7.2,28.37]],"ltp":13.5,"tv":15314.43,"id":8734382},{"batb":[[1,1.07,611.26],[2,1.06,712.86]],"ltp":1.08,"tv":146552.59,"id":9323645}]}]}
{"op":"mcm","clk":"4217068054","pt":1631557531058,"mc":[{"id":"1.187566733","rc":[{"batb":[[0,11,25.92],[1,10,26.21],[2,7.8,14.01]],"ltp":13.5,"tv":15314.43,"id":8734382},{"trd":[[1.08,26392.8]],"batb":[[0,1.08,20],[2,1.06,1350.29]],"batl":[[1,1.1,2262.41],[2,1.11,2553.67]],"ltp":1.08,"tv":146605.64,"id":9323645}],"tv":161920.08}]}
{"op":"mcm","clk":"4217068207","pt":1631557532060,"mc":[{"id":"1.187566733","rc":[{"batb":[[0,10,26.21],[1,7.8,14.01],[2,2.5,1.82]],"ltp":13.5,"tv":15314.43,"id":8734382},{"batb":[[2,1.06,712.86]],"batl":[[1,1.11,1944.96],[2,1.13,9.39]],"ltp":1.08,"tv":146605.64,"id":9323645}]}]}
{"op":"mcm","clk":"4217068250","pt":1631557532378,"mc":[{"id":"1.187566733","rc":[{"batb":[[0,1.08,120]],"ltp":1.08,"tv":146605.64,"id":9323645}]}]}
{"op":"mcm","clk":"4217068479","pt":1631557534164,"mc":[{"id":"1.187566733","rc":[{"batb":[[0,1.08,560.63],[1,1.07,797.98]],"batl":[[0,1.09,770.95]],"ltp":1.08,"tv":146605.64,"id":9323645}]}]}
{"op":"mcm","clk":"4217068622","pt":1631557535102,"mc":[{"id":"1.187566733","rc":[{"batb":[[0,11,24.67],[1,10,26.21],[2,7.8,14.01]],"ltp":13.5,"tv":15314.43,"id":8734382},{"batb":[[0,1.08,562.34]],"batl":[[0,1.09,750.45],[1,1.1,2329.94],[2,1.11,1944.96]],"ltp":1.08,"tv":146605.64,"id":9323645}]}]}
{"op":"mcm","clk":"4217068898","pt":1631557537199,"mc":[{"id":"1.187566733","rc":[{"batb":[[0,10,26.21],[1,7.8,14.01],[2,2.5,1.82]],"ltp":13.5,"tv":15314.43,"id":8734382},{"batb":[[0,1.08,21.71],[1,1.07,611.26]],"batl":[[0,1.09,130.57],[1,1.11,1944.96],[2,1.12,1722.23]],"ltp":1.08,"tv":146605.64,"id":9323645}]}]}
{"op":"mcm","clk":"4217068948","pt":1631557537524,"mc":[{"id":"1.187566733","rc":[{"batl":[[2,1.13,9.39]],"ltp":1.08,"tv":146605.64,"id":9323645}]}]}
{"op":"mcm","clk":"4217069273","pt":1631557540202,"mc":[{"id":"1.187566733","rc":[{"batb":[[2,1.06,1350.29]],"batl":[[0,1.09,730.21],[1,1.11,2553.67]],"ltp":1.08,"tv":146605.64,"id":9323645}]}]}
{"op":"mcm","clk":"4217069390","pt":1631557540996,"mc":[{"id":"1.187566733","rc":[{"batb":[[0,1.08,1.71]],"batl":[[0,1.09,130.57],[1,1.1,2.56],[2,1.11,2553.67]],"ltp":1.08,"tv":146605.64,"id":9323645}]}]}
{"op":"mcm","clk":"4217069544","pt":1631557542196,"mc":[{"id":"1.187566733","rc":[{"batl":[[2,1.11,2572.44]],"ltp":1.08,"tv":146605.64,"id":9323645}]}]}
{"op":"mcm","clk":"4217069780","pt":1631557543976,"mc":[{"id":"1.187566733","rc":[{"batb":[[0,11,25.62],[1,10,26.21],[2,7.8,14.01]],"ltp":13.5,"tv":15314.43,"id":8734382},{"batl":[[1,1.1,2408.02]],"ltp":1.08,"tv":146605.64,"id":9323645}]}]}
{"op":"mcm","clk":"4217069864","pt":1631557544663,"mc":[{"id":"1.187566733","rc":[{"batb":[[0,10,26.21],[1,7.8,14.01],[2,2.5,1.82]],"ltp":13.5,"tv":15314.43,"id":8734382},{"trd":[[1.09,16984.85]],"batl":[[0,1.09,30.55],[1,1.1,2.56]],"ltp":1.09,"tv":146805.66,"id":9323645}],"tv":162120.09}]}
{"op":"mcm","clk":"4217070019","pt":1631557545878,"mc":[{"id":"1.187566733","rc":[{"trd":[[1.08,26396.22]],"batb":[[0,1.07,611.26],[1,1.06,1350.29],[2,1.05,597.11]],"batl":[[0,1.08,14.29],[1,1.09,30.55],[2,1.1,2.56]],"ltp":1.08,"tv":146809.08,"id":9323645}],"tv":162123.51}]}
{"op":"mcm","clk":"4217070332","pt":1631557548181,"mc":[{"id":"1.187566733","rc":[{"trd":[[10,19.46],[11,128.22],[12,351.12],[13.5,154.6]],"batb":[[0,10,23.87]],"ltp":10.0,"tv":15323.27,"id":8734382},{"trd":[[1.08,26410.51],[1.09,17015.41],[1.1,9639.43]],"batl":[[0,1.11,2572.44],[1,1.12,1812.91],[2,1.13,9.39]],"ltp":1.1,"tv":146856.48,"id":9323645}],"tv":162179.76}]}
{"op":"mcm","clk":"4217070378","pt":1631557548604,"mc":[{"id":"1.187566733","rc":[{"batb":[[0,1.09,20],[1,1.07,611.26],[2,1.06,1350.29]],"ltp":1.1,"tv":146856.48,"id":9323645}]}]}
{"op":"mcm","clk":"4217071039","pt":1631557553768,"mc":[{"id":"1.187566733","rc":[{"trd":[[1.09,17025.77]],"batb":[[0,1.09,14.82],[2,1.06,712.86]],"ltp":1.09,"tv":146866.84,"id":9323645}],"tv":162190.12}]}
{"op":"mcm","clk":"4217071227","pt":1631557555196,"mc":[{"id":"1.187566733","rc":[{"batb":[[0,11,26.64],[1,10,23.87],[2,7.8,14.01]],"ltp":10.0,"tv":15323.27,"id":8734382},{"batb":[[0,1.09,132.28]],"batl":[[0,1.1,2345.37],[1,1.11,2572.44],[2,1.12,1812.91]],"ltp":1.09,"tv":146866.84,"id":9323645}]}]}
{"op":"mcm","clk":"4217071334","pt":1631557555984,"mc":[{"id":"1.187566733","rc":[{"trd":[[1.1,9699.16]],"batl":[[0,1.1,2315.51]],"ltp":1.1,"tv":146926.57,"id":9323645}],"tv":162249.84}]}
{"op":"mcm","clk":"4217071470","pt":1631557556989,"mc":[{"id":"1.187566733","rc":[{"batl":[[0,11.5,10.44],[1,12,201.84],[2,13,6.92]],"ltp":10.0,"tv":15323.27,"id":8734382},{"trd":[[1.1,9823.95]],"batb":[[0,1.09,1077.24],[1,1.08,27.81],[2,1.07,611.26]],"batl":[[0,1.1,2253.13],[1,1.11,2694.61],[2,1.12,4749.93]],"ltp":1.1,"tv":147051.36,"id":9323645}],"tv":162374.64}]}
{"op":"mcm","clk":"4217071554","pt":1631557557716,"mc":[{"id":"1.187566733","rc":[{"batb":[[1,1.08,435.24]],"batl":[[1,1.11,2722.08],[2,1.12,4763.45]],"ltp":1.1,"tv":147051.36,"id":9323645}]}]}
{"op":"mcm","clk":"4217072031","pt":1631557561081,"mc":[{"id":"1.187566733","rc":[{"batb":[[0,10,23.87],[1,7.8,14.01],[2,6.4,23.16]],"ltp":10.0,"tv":15323.27,"id":8734382},{"batb":[[2,1.07,1.71]],"batl":[[0,1.1,2641.21]],"ltp":1.1,"tv":147051.36,"id":9323645}]}]}
{"op":"mcm","clk":"4217072155","pt":1631557561874,"mc":[{"id":"1.187566733","rc":[{"batb":[[0,1.09,1075.53]],"ltp":1.1,"tv":147051.36,"id":9323645}]}]}
{"op":"mcm","clk":"4217072338","pt":1631557563186,"mc":[{"id":"1.187566733","rc":[{"batb":[[1,8,26.51],[2,7.8,14.01]],"ltp":10.0,"tv":15323.27,"id":8734382},{"trd":[[1.1,9827.95]],"batl":[[0,1.1,2639.21]],"ltp":1.1,"tv":147055.36,"id":9323645}],"tv":162378.64}]}
{"op":"mcm","clk":"4217072405","pt":1631557563716,"mc":[{"id":"1.187566733","rc":[{"batl":[[0,1.1,3016.92]],"ltp":1.1,"tv":147055.36,"id":9323645}]}]}
{"op":"mcm","clk":"4217072959","pt":1631557567812,"mc":[{"id":"1.187566733","rc":[{"batb":[[2,1.07,191.16]],"ltp":1.1,"tv":147055.36,"id":9323645}]}]}
{"op":"mcm","clk":"4217073044","pt":1631557568393,"mc":[{"id":"1.187566733","rc":[{"batb":[[0,1.09,750.45]],"ltp":1.1,"tv":147055.36,"id":9323645}]}]}
{"op":"mcm","clk":"4217073295","pt":1631557570030,"mc":[{"id":"1.187566733","rc":[{"batl":[[1,1.11,2705.02],[2,1.12,4747.24]],"ltp":1.1,"tv":147055.36,"id":9323645}]}]}
{"op":"mcm","clk":"4217073448","pt":1631557570927,"mc":[{"id":"1.187566733","rc":[{"trd":[[11,132.64]],"ltp":11.0,"tv":15327.69,"id":8734382},{"trd":[[1.1,9872.15]],"batl":[[0,1.1,2972.72]],"ltp":1.1,"tv":147099.56,"id":9323645}],"tv":162427.26}]}
{"op":"mcm","clk":"4217073909","pt":1631557574205,"mc":[{"id":"1.187566733","rc":[{"trd":[[1.1,10072.15]],"batb":[[1,1.08,407.89]],"batl":[[0,1.1,2872.72]],"ltp":1.1,"tv":147299.56,"id":9323645}],"tv":162627.26}]}
{"op":"mcm","clk":"4217073947","pt":1631557574547,"mc":[{"id":"1.187566733","rc":[{"batb":[[0,1.09,748.74]],"ltp":1.1,"tv":147299.56,"id":9323645}]}]}
{"op":"mcm","clk":"4217074172","pt":1631557576033,"mc":[{"id":"1.187566733","rc":[{"batb":[[0,1.09,745.33]],"ltp":1.1,"tv":147299.56,"id":9323645}]}]}
{"op":"mcm","clk":"4217074449","pt":1631557577930,"mc":[{"id":"1.187566733","rc":[{"trd":[[1.1,10076.15]],"batl":[[0,1.1,2870.72]],"ltp":1.1,"tv":147303.56,"id":9323645}],"tv":162631.26}]}
{"op":"mcm","clk":"4217074821","pt":1631557580731,"mc":[{"id":"1.187566733","rc":[{"trd":[[1.1,10160.15]],"batl":[[0,1.1,2828.72]],"ltp":1.1,"tv":147387.56,"id":9323645}],"tv":162715.26}]}
{"op":"mcm","clk":"4217075075","pt":1631557582639,"mc":[{"id":"1.187566733","rc":[{"trd":[[1.1,10164.15]],"batl":[[0,1.1,2826.72]],"ltp":1.1,"tv":147391.56,"id":9323645}],"tv":162719.26}]}
{"op":"mcm","clk":"4217075275","pt":1631557584154,"mc":[{"id":"1.187566733","rc":[{"batl":[[0,11.5,8.7],[2,13,1.15]],"ltp":11.0,"tv":15327.69,"id":8734382},{"batl":[[1,1.11,2691.51],[2,1.12,4740.48]],"ltp":1.1,"tv":147391.56,"id":9323645}]}]}
{"op":"mcm","clk":"4217075358","pt":1631557584740,"mc":[{"id":"1.187566733","rc":[{"batb":[[0,7.2,30.87],[1,6.4,23.16],[2,2.5,1.82]],"batl":[[0,990,0.01],[1,12,0],[2,13,0]],"ltp":11.0,"tv":15327.69,"id":8734382},{"batb":[[0,1.09,125.45],[1,1.07,191.16],[2,1.06,504.8]],"batl":[[0,1.1,377.71],[1,1.11,1.71],[2,1.12,2.56]],"ltp":1.1,"tv":147391.56,"id":9323645}]}]}
{"op":"mcm","clk":"4217075494","pt":1631557585629,"mc":[{"id":"1.187566733","rc":[{"trd":[[1.1,10263.88]],"batl":[[0,1.11,1.71],[1,1.12,2.56],[2,1.13,9.39]],"ltp":1.1,"tv":147491.28,"id":9323645}],"tv":162818.98}]}
{"op":"mcm","clk":"4217075639","pt":1631557586732,"mc":[{"id":"1.187566733","rc":[{"batl":[[0,11,12.52],[1,990,0.01]],"ltp":11.0,"tv":15327.69,"id":8734382}]}]}
{"op":"mcm","clk":"4217075806","pt":1631557587941,"mc":[{"id":"1.187566733","rc":[{"batb":[[0,8,28.39],[1,7.2,30.87],[2,6.4,23.16]],"ltp":11.0,"tv":15327.69,"id":8734382},{"batb":[[0,1.1,187.24],[1,1.09,125.45],[2,1.08,216.87]],"ltp":1.1,"tv":147491.28,"id":9323645}]}]}
{"op":"mcm","clk":"4217076141","pt":1631557590423,"mc":[{"id":"1.187566733","rc":[{"batb":[[0,1.1,196.26]],"ltp":1.1,"tv":147491.28,"id":9323645}]}]}
{"op":"mcm","clk":"4217076433","pt":1631557592727,"mc":[{"id":"1.187566733","rc":[{"batb":[[0,1.11,7.68],[1,1.1,196.26],[2,1.09,125.45]],"batl":[[0,1.12,2.56],[1,1.13,9.39],[2,1.14,2393.33]],"ltp":1.1,"tv":147491.28,"id":9323645}]}]}
{"op":"mcm","clk":"4217076590","pt":1631557593743,"mc":[{"id":"1.187566733","rc":[{"batb":[[0,7.2,30.87],[1,6.4,23.16],[2,2.5,1.82]],"ltp":11.0,"tv":15327.69,"id":8734382},{"batl":[[2,1.14,9.39]],"ltp":1.1,"tv":147491.28,"id":9323645}]}]}
{"op":"mcm","clk":"4217076829","pt":1631557595058,"mc":[{"id":"1.187566733","rc":[{"batb":[[0,1.1,196.26],[1,1.08,216.87],[2,1.07,605.45]],"ltp":1.1,"tv":147491.28,"id":9323645}]}]}
{"op":"mcm","clk":"4217077069","pt":1631557596848,"mc":[{"id":"1.187566733","rc":[{"trd":[[11,145.15]],"batb":[[0,12,92.06],[1,11.5,3.74],[2,11,158.88]],"batl":[[0,13.5,3.5],[1,15,266.92],[2,990,0.01]],"ltp":11.0,"tv":15340.21,"id":8734382},{"trd":[[1.1,10781.56]],"batb":[[0,1.08,271.57],[1,1.07,605.45],[2,1.06,532.67]],"batl":[[0,1.09,3796.28],[1,1.1,1553.69],[2,1.12,2.56]],"ltp":1.1,"tv":148008.97,"id":9323645}],"tv":163349.19}]}
{"op":"mcm","clk":"4217077222","pt":1631557598044,"mc":[{"id":"1.187566733","rc":[{"trd":[[12,380.02]],"batb":[[0,12,77.61]],"ltp":12.0,"tv":15369.12,"id":8734382},{"trd":[[1.09,17043.47]],"batb":[[1,1.07,633.96],[2,1.06,546.69]],"batl":[[0,1.09,3787.43],[1,1.1,1551.87]],"ltp":1.09,"tv":148026.67,"id":9323645}],"tv":163395.79}]}
{"op":"mcm","clk":"4217077621","pt":1631557600943,"mc":[{"id":"1.187566733","rc":[{"trd":[[1.09,17243.47]],"batl":[[0,1.09,4315.56]],"ltp":1.09,"tv":148226.67,"id":9323645}],"tv":163595.79}]}
{"op":"mcm","clk":"4217077755","pt":1631557601936,"mc":[{"id":"1.187566733","rc":[{"trd":[[1.08,26413.93]],"batb":[[0,1.08,269.86]],"batl":[[0,1.09,4603.56]],"ltp":1.08,"tv":148230.08,"id":9323645}],"tv":163599.21}]}
{"op":"mcm","clk":"4217077880","pt":1631557602840,"mc":[{"id":"1.187566733","rc":[{"batb":[[2,11,184.8]],"ltp":12.0,"tv":15369.12,"id":8734382},{"batl":[[1,1.1,3836.52],[2,1.11,2063.61]],"ltp":1.08,"tv":148230.08,"id":9323645}]}]}
{"op":"mcm","clk":"4217078078","pt":1631557604144,"mc":[{"id":"1.187566733","rc":[{"batb":[[1,1.07,772.06]],"batl":[[0,1.09,4605.27]],"ltp":1.08,"tv":148230.08,"id":9323645}]}]}
{"op":"mcm","clk":"4217078130","pt":1631557604559,"mc":[{"id":"1.187566733","rc":[{"trd":[[1.09,17283.47]],"batl":[[0,1.09,4585.27]],"ltp":1.09,"tv":148270.08,"id":9323645}],"tv":163639.21}]}
{"op":"mcm","clk":"4217078590","pt":1631557608227,"mc":[{"id":"1.187566733","rc":[{"batl":[[0,1.09,4457.24]],"ltp":1.09,"tv":148270.08,"id":9323645}]}]}
{"op":"mcm","clk":"4217078701","pt":1631557609232,"mc":[{"id":"1.187566733","rc":[{"batb":[[2,1.06,593.63]],"ltp":1.09,"tv":148270.08,"id":9323645}]}]}
{"op":"mcm","clk":"4217078940","pt":1631557611064,"mc":[{"id":"1.187566733","rc":[{"trd":[[1.09,17323.47]],"batl":[[0,1.09,4437.24]],"ltp":1.09,"tv":148310.08,"id":9323645}],"tv":163679.21}]}
{"op":"mcm","clk":"4217079094","pt":1631557612168,"mc":[{"id":"1.187566733","rc":[{"batl":[[1,1.1,3842.11]],"ltp":1.09,"tv":148310.08,"id":9323645}]}]}
{"op":"mcm","clk":"4217079277","pt":1631557613546,"mc":[{"id":"1.187566733","rc":[{"batb":[[0,1.08,215.16],[2,1.06,565.76]],"ltp":1.09,"tv":148310.08,"id":9323645}]}]}
{"op":"mcm","clk":"4217079735","pt":1631557617154,"mc":[{"id":"1.187566733","rc":[{"batb":[[0,1.08,245.03]],"ltp":1.09,"tv":148310.08,"id":9323645}]}]}
{"op":"mcm","clk":"4217079845","pt":1631557617948,"mc":[{"id":"1.187566733","rc":[{"trd":[[1.09,17549.07]],"batl":[[0,1.09,4324.44]],"ltp":1.09,"tv":148535.69,"id":9323645}],"tv":163904.81}]}
{"op":"mcm","clk":"4217080049","pt":1631557619554,"mc":[{"id":"1.187566733","rc":[{"trd":[[12,388.56]],"batb":[[0,12,73.34]],"ltp":12.0,"tv":15377.65,"id":8734382}],"tv":163913.34}]}
{"op":"mcm","clk":"4217080152","pt":1631557620348,"mc":[{"id":"1.187566733","rc":[{"trd":[[1.09,17629.07]],"batl":[[0,1.09,4284.44]],"ltp":1.09,"tv":148615.69,"id":9323645}],"tv":163993.34}]}
{"op":"mcm","clk":"4217080442","pt":1631557622357,"mc":[{"id":"1.187566733","rc":[{"trd":[[1.09,17669.07]],"batl":[[0,1.09,4264.44]],"ltp":1.09,"tv":148655.69,"id":9323645}],"tv":164033.34}]}
{"op":"mcm","clk":"4217080790","pt":1631557625081,"mc":[{"id":"1.187566733","rc":[{"batb":[[0,10,23.3],[1,7.6,14.69],[2,7.2,30.87]],"batl":[[0,990,0.01],[1,15,0],[2,990,0]],"ltp":12.0,"tv":15377.65,"id":8734382},{"batb":[[0,1.08,31.58],[1,1.07,191.16],[2,1.06,48.64]],"batl":[[0,1.09,289.71],[1,1.1,2290.24]],"ltp":1.09,"tv":148655.69,"id":9323645}]}]}
{"op":"mcm","clk":"4217080934","pt":1631557626182,"mc":[{"id":"1.187566733","rc":[{"batl":[[0,1.09,133.98],[1,1.1,5.59]],"ltp":1.09,"tv":148655.69,"id":9323645}]}]}
{"op":"mcm","clk":"4217080956","pt":1631557626393,"mc":[{"id":"1.187566733","rc":[{"batb":[[2,2.5,1.82]],"ltp":12.0,"tv":15377.65,"id":8734382}]}]}
{"op":"mcm","clk":"4217081180","pt":1631557628169,"mc":[{"id":"1.187566733","rc":[{"batb":[[2,1.06,686.07]],"batl":[[2,1.11,2625.28]],"ltp":1.09,"tv":148655.69,"id":9323645}]}]}
{"op":"mcm","clk":"4217081300","pt":1631557629164,"mc":[{"id":"1.187566733","rc":[{"batl":[[1,1.1,2197.47]],"ltp":1.09,"tv":148655.69,"id":9323645}]}]}
{"op":"mcm","clk":"4217081324","pt":1631557629392,"mc":[{"id":"1.187566733","rc":[{"batl":[[1,1.1,5.59]],"ltp":1.09,"tv":148655.69,"id":9323645}]}]}
{"op":"mcm","clk":"4217081764","pt":1631557633098,"mc":[{"id":"1.187566733","rc":[{"batb":[[2,1.06,48.64]],"batl":[[2,1.11,2063.61]],"ltp":1.09,"tv":148655.69,"id":9323645}]}]}
{"op":"mcm","clk":"4217082156","pt":1631557636090,"mc":[{"id":"1.187566733","rc":[{"trd":[[1.09,17673.4]],"batb":[[0,1.08,657.2]],"batl":[[0,1.09,491.78],[1,1.1,284.44]],"ltp":1.09,"tv":148660.02,"id":9323645}],"tv":164037.68}]}
{"op":"mcm","clk":"4217082298","pt":1631557636983,"mc":[{"id":"1.187566733","rc":[{"batb":[[0,1.08,31.58]],"batl":[[0,1.09,243.81],[1,1.1,2285.66]],"ltp":1.09,"tv":148660.02,"id":9323645}]}]}
{"op":"mcm","clk":"4217082436","pt":1631557637971,"mc":[{"id":"1.187566733","rc":[{"batl":[[0,1.09,131.81],[1,1.1,5.59]],"ltp":1.09,"tv":148660.02,"id":9323645}]}]}
{"op":"mcm","clk":"4217082557","pt":1631557639011,"mc":[{"id":"1.187566733","rc":[{"batb":[[0,11,24.37],[1,10,23.3],[2,7.6,14.69]],"ltp":12.0,"tv":15377.65,"id":8734382},{"trd":[[1.09,17873.42]],"batl":[[0,1.09,31.8]],"ltp":1.09,"tv":148860.04,"id":9323645}],"tv":164237.7}]}
{"op":"mcm","clk":"4217082666","pt":1631557639915,"mc":[{"id":"1.187566733","rc":[{"batb":[[0,10,23.3],[1,7.6,14.69],[2,2.5,1.82]],"ltp":12.0,"tv":15377.65,"id":8734382},{"batb":[[2,1.06,686.07]],"batl":[[2,1.11,2625.28]],"ltp":1.09,"tv":148860.04,"id":9323645}]}]}
{"op":"mcm","clk":"4217082864","pt":1631557641490,"mc":[{"id":"1.187566733","rc":[{"batl":[[1,1.1,1944.97],[2,1.12,21.33]],"ltp":1.09,"tv":148860.04,"id":9323645}]}]}
{"op":"mcm","clk":"4217083060","pt":1631557643015,"mc":[{"id":"1.187566733","rc":[{"batb":[[0,11,22.17],[1,10,23.3],[2,7.6,14.69]],"ltp":12.0,"tv":15377.65,"id":8734382},{"batb":[[0,1.09,112.43],[1,1.08,1.71],[2,1.07,1.71]],"batl":[[0,1.1,1944.97],[1,1.12,21.33],[2,1.13,9.39]],"ltp":1.09,"tv":148860.04,"id":9323645}]}]}
{"op":"mcm","clk":"4217083225","pt":1631557644121,"mc":[{"id":"1.187566733","rc":[{"batb":[[0,12.5,12],[1,12,6],[2,11.5,6]],"batl":[[0,15,7.28],[1,17.5,295.72],[2,990,0.01]],"ltp":12.0,"tv":15377.65,"id":8734382},{"trd":[[1.08,26417.34]],"batb":[[0,1.07,1.71],[1,1.06,686.07],[2,1.05,583.77]],"batl":[[0,1.08,3559.91],[1,1.09,4067.28],[2,1.1,1944.97]],"ltp":1.08,"tv":148863.46,"id":9323645}],"tv":164241.11}]}
{"op":"mcm","clk":"4217083333","pt":1631557645122,"mc":[{"id":"1.187566733","rc":[{"batb":[[0,13.5,71.42],[1,12.5,7.2],[2,12,3.6]],"batl":[[1,17,8.82],[2,17.5,300.14]],"ltp":12.0,"tv":15377.65,"id":8734382},{"trd":[[1.08,26435.36]],"batb":[[1,1.06,744.17]],"batl":[[0,1.08,3596.52],[1,1.09,3990.22]],"ltp":1.08,"tv":148881.48,"id":9323645}],"tv":164259.13}]}
{"op":"mcm","clk":"4217083377","pt":1631557645494,"mc":[{"id":"1.187566733","rc":[{"trd":[[15,169.24]],"batl":[[0,15,6.73],[1,17,1.76],[2,17.5,296.6]],"ltp":15.0,"tv":15378.2,"id":8734382},{"trd":[[1.07,11556.31]],"batb":[[0,1.06,742.28],[1,1.05,583.77],[2,1.04,770.59]],"batl":[[0,1.08,3605.91],[1,1.09,3988.38]],"ltp":1.07,"tv":148889.16,"id":9323645}],"tv":164267.36}]}
{"op":"mcm","clk":"4217083791","pt":1631557649110,"mc":[{"id":"1.187566733","rc":[{"batb":[[0,1.06,1136.12]],"batl":[[0,1.08,4443.71]],"ltp":1.07,"tv":148889.16,"id":9323645}]}]}
{"op":"mcm","clk":"4217084023","pt":1631557651109,"mc":[{"id":"1.187566733","rc":[{"trd":[[15,175.97]],"batl":[[0,17,1.76],[1,17.5,296.6],[2,990,0.89]],"ltp":15.0,"tv":15384.93,"id":8734382},{"trd":[[1.07,11654.66]],"batl":[[0,1.07,44.45],[1,1.08,4443.71],[2,1.09,3988.38]],"ltp":1.07,"tv":148987.51,"id":9323645}],"tv":164372.45}]}
{"op":"mcm","clk":"4217084252","pt":1631557653219,"mc":[{"id":"1.187566733","rc":[{"batb":[[0,1.07,145],[1,1.06,1136.12],[2,1.05,583.77]],"batl":[[0,1.08,4443.71],[1,1.09,3988.38],[2,1.1,1944.97]],"ltp":1.07,"tv":148987.51,"id":9323645}]}]}
{"op":"mcm","clk":"4217084551","pt":1631557655738,"mc":[{"id":"1.187566733","rc":[{"batl":[[0,1.08,4420.59]],"ltp":1.07,"tv":148987.51,"id":9323645}]}]}
{"op":"mcm","clk":"4217084707","pt":1631557657044,"mc":[{"id":"1.187566733","rc":[{"batb":[[0,1.07,165],[1,1.06,1847.28]],"batl":[[0,1.08,4148.77]],"ltp":1.07,"tv":148987.51,"id":9323645}]}]}
{"op":"mcm","clk":"4217084734","pt":1631557657249,"mc":[{"id":"1.187566733","rc":[{"batb":[[1,1.06,1136.12]],"ltp":1.07,"tv":148987.51,"id":9323645}]}]}
{"op":"mcm","clk":"4217084939","pt":1631557658955,"mc":[{"id":"1.187566733","rc":[{"batb":[[0,13.5,77.29]],"batl":[[1,17.5,311.43]],"ltp":15.0,"tv":15384.93,"id":8734382},{"batl":[[0,1.08,4390.12]],"ltp":1.07,"tv":148987.51,"id":9323645}]}]}
{"op":"mcm","clk":"4217085132","pt":1631557660640,"mc":[{"id":"1.187566733","rc":[{"batb":[[0,13.5,71.42]],"batl":[[1,17.5,296.6]],"ltp":15.0,"tv":15384.93,"id":8734382},{"batl":[[0,1.08,4316.77]],"ltp":1.07,"tv":148987.51,"id":9323645}]}]}
{"op":"mcm","clk":"4217085273","pt":1631557661847,"mc":[{"id":"1.187566733","rc":[{"trd":[[1.08,26455.36]],"batb":[[0,1.07,145]],"batl":[[0,1.08,4306.77]],"ltp":1.08,"tv":149007.51,"id":9323645}],"tv":164392.45}]}
{"op":"mcm","clk":"4217085457","pt":1631557663523,"mc":[{"id":"1.187566733","rc":[{"batb":[[0,13.5,77.29]],"batl":[[1,17.5,311.43]],"ltp":15.0,"tv":15384.93,"id":8734382},{"batl":[[0,1.08,4380.12]],"ltp":1.08,"tv":149007.51,"id":9323645}]}]}
{"op":"mcm","clk":"4217085640","pt":1631557665251,"mc":[{"id":"1.187566733","rc":[{"trd":[[1.08,26495.36]],"batl":[[0,1.08,4360.12]],"ltp":1.08,"tv":149047.51,"id":9323645}],"tv":164432.45}]}
{"op":"mcm","clk":"4217085989","pt":1631557668134,"mc":[{"id":"1.187566733","rc":[{"trd":[[1.08,27000.98]],"batl":[[0,1.08,4107.38]],"ltp":1.08,"tv":149553.13,"id":9323645}],"tv":164938.06}]}
{"op":"mcm","clk":"4217086443","pt":1631557671963,"mc":[{"id":"1.187566733","rc":[{"batb":[[0,1.07,754.56]],"ltp":1.08,"tv":149553.13,"id":9323645}]}]}
{"op":"mcm","clk":"4217086850","pt":1631557675157,"mc":[{"id":"1.187566733","rc":[{"batb":[[0,1.07,1139.49]],"ltp":1.08,"tv":149553.13,"id":9323645}]}]}
{"op":"mcm","clk":"4217086959","pt":1631557676057,"mc":[{"id":"1.187566733","rc":[{"trd":[[1.08,27200.98]],"batl":[[0,1.08,4007.38]],"ltp":1.08,"tv":149753.13,"id":9323645}],"tv":165138.06}]}
{"op":"mcm","clk":"4217087074","pt":1631557676942,"mc":[{"id":"1.187566733","rc":[{"trd":[[13.5,190.76]],"batb":[[0,13.5,59.21]],"ltp":13.5,"tv":15421.09,"id":8734382}],"tv":165174.22}]}
{"op":"mcm","clk":"4217087617","pt":1631557680982,"mc":[{"id":"1.187566733","rc":[{"trd":[[1.08,27280.98]],"batl":[[0,1.08,3967.38]],"ltp":1.08,"tv":149833.13,"id":9323645}],"tv":165254.22}]}
{"op":"mcm","clk":"4217088833","pt":1631557691384,"mc":[{"id":"1.187566733","rc":[{"trd":[[1.08,27380.98]],"batl":[[0,1.08,3917.38]],"ltp":1.08,"tv":149933.13,"id":9323645}],"tv":165354.22}]}
{"op":"mcm","clk":"4217089233","pt":1631557694895,"mc":[{"id":"1.187566733","rc":[{"trd":[[1.08,27580.98]],"batl":[[0,1.08,3817.38]],"ltp":1.08,"tv":150133.13,"id":9323645}],"tv":165554.22}]}
{"op":"mcm","clk":"4217090267","pt":1631557702785,"mc":[{"id":"1.187566733","rc":[{"batl":[[2,1.1,1939.38]],"ltp":1.08,"tv":150133.13,"id":9323645}]}]}
{"op":"mcm","clk":"4217090709","pt":1631557706413,"mc":[{"id":"1.187566733","rc":[{"trd":[[1.08,27620.98]],"batl":[[0,1.08,3797.38]],"ltp":1.08,"tv":150173.13,"id":9323645}],"tv":165594.22}]}
{"op":"mcm","clk":"4217091317","pt":1631557711319,"mc":[{"id":"1.187566733","rc":[{"batl":[[0,1.08,3798.31]],"ltp":1.08,"tv":150173.13,"id":9323645}]}]}
{"op":"mcm","clk":"4217091768","pt":1631557714996,"mc":[{"id":"1.187566733","rc":[{"trd":[[1.08,27820.98]],"batl":[[0,1.08,3698.31]],"ltp":1.08,"tv":150373.13,"id":9323645}],"tv":165794.22}]}
{"op":"mcm","clk":"4217092719","pt":1631557722527,"mc":[{"id":"1.187566733","rc":[{"trd":[[1.08,27860.98]],"batl":[[0,1.08,3678.31]],"ltp":1.08,"tv":150413.13,"id":9323645}],"tv":165834.22}]}
{"op":"mcm","clk":"4217093525","pt":1631557729157,"mc":[{"id":"1.187566733","rc":[{"batl":[[1,1.09,4120.66]],"ltp":1.08,"tv":150413.13,"id":9323645}]}]}
{"op":"mcm","clk":"4217093819","pt":1631557731530,"mc":[{"id":"1.187566733","rc":[{"batb":[[1,1.06,1080.38]],"batl":[[2,1.1,2071.66]],"ltp":1.08,"tv":150413.13,"id":9323645}]}]}
{"op":"mcm","clk":"4217094142","pt":1631557734153,"mc":[{"id":"1.187566733","rc":[{"trd":[[1.08,28060.98]],"batl":[[0,1.08,3578.31]],"ltp":1.08,"tv":150613.13,"id":9323645}],"tv":166034.22}]}
{"op":"mcm","clk":"4217094201","pt":1631557734525,"mc":[{"id":"1.187566733","rc":[{"batb":[[2,12,21.22]],"ltp":13.5,"tv":15421.09,"id":8734382},{"batb":[[2,1.05,867.95]],"batl":[[1,1.09,5735.46]],"ltp":1.08,"tv":150613.13,"id":9323645}]}]}
{"op":"mcm","clk":"4217094499","pt":1631557737148,"mc":[{"id":"1.187566733","rc":[{"trd":[[1.08,28334.98]],"batl":[[0,1.08,3441.31]],"ltp":1.08,"tv":150887.13,"id":9323645}],"tv":166308.22}]}
{"op":"mcm","clk":"4217094746","pt":1631557739358,"mc":[{"id":"1.187566733","rc":[{"batl":[[0,1.08,3630.76]],"ltp":1.08,"tv":150887.13,"id":9323645}]}]}
{"op":"mcm","clk":"4217094938","pt":1631557740843,"mc":[{"id":"1.187566733","rc":[{"trd":[[1.08,28374.98]],"batl":[[0,1.08,3610.76]],"ltp":1.08,"tv":150927.13,"id":9323645}],"tv":166348.22}]}
{"op":"mcm","clk":"4217095015","pt":1631557741461,"mc":[{"id":"1.187566733","rc":[{"batb":[[0,1.07,529.93]],"ltp":1.08,"tv":150927.13,"id":9323645}]}]}
{"op":"mcm","clk":"4217096127","pt":1631557750461,"mc":[{"id":"1.187566733","rc":[{"trd":[[1.08,28454.98]],"batl":[[0,1.08,3570.76]],"ltp":1.08,"tv":151007.13,"id":9323645}],"tv":166428.22}]}
{"op":"mcm","clk":"4217097396","pt":1631557759194,"mc":[{"id":"1.187566733","rc":[{"trd":[[1.08,28494.98]],"batb":[[0,1.07,145],[1,1.06,686.54]],"batl":[[0,1.08,2712.96]],"ltp":1.08,"tv":151047.13,"id":9323645}],"tv":166468.22}]}
{"op":"mcm","clk":"4217097425","pt":1631557759400,"mc":[{"id":"1.187566733","rc":[{"batb":[[2,1.05,285.88]],"ltp":1.08,"tv":151047.13,"id":9323645}]}]}
{"op":"mcm","clk":"4217098216","pt":1631557765815,"mc":[{"id":"1.187566733","rc":[{"trd":[[1.08,28694.98]],"batl":[[0,1.08,2612.96]],"ltp":1.08,"tv":151247.13,"id":9323645}],"tv":166668.22}]}
{"op":"mcm","clk":"4217099193","pt":1631557774003,"mc":[{"id":"1.187566733","rc":[{"batl":[[0,1.08,2423.51]],"ltp":1.08,"tv":151247.13,"id":9323645}]}]}
{"op":"mcm","clk":"4217099571","pt":1631557776847,"mc":[{"id":"1.187566733","rc":[{"batb":[[0,11,22.17],[1,8.8,26.18],[2,2.5,1.82]],"batl":[[0,990,0.01],[1,17.5,0],[2,990,0]],"ltp":13.5,"tv":15421.09,"id":8734382},{"batb":[[1,1.06,48.64]],"batl":[[0,1.08,178.32],[1,1.09,132.28]],"ltp":1.08,"tv":151247.13,"id":9323645}]}]}
{"op":"mcm","clk":"4217099686","pt":1631557777640,"mc":[{"id":"1.187566733","rc":[{"batl":[[0,1.08,10.32]],"ltp":1.08,"tv":151247.13,"id":9323645}]}]}
{"op":"mcm","clk":"4217100012","pt":1631557780021,"mc":[{"id":"1.187566733","rc":[{"batb":[[0,12,17.62],[1,11,22.17],[2,8.8,26.18]],"ltp":13.5,"tv":15421.09,"id":8734382},{"batb":[[0,1.06,48.64],[1,1.05,929.32],[2,1.04,742.18]],"batl":[[0,1.07,166.49],[1,1.08,10.32],[2,1.09,2147.34]],"ltp":1.08,"tv":151247.13,"id":9323645}]}]}
{"op":"mcm","clk":"4217100311","pt":1631557782329,"mc":[{"id":"1.187566733","rc":[{"batl":[[0,1.08,10.32],[1,1.09,2147.34],[2,1.1,2071.66]],"ltp":1.08,"tv":151247.13,"id":9323645}]}]}
{"op":"mcm","clk":"4217100779","pt":1631557785747,"mc":[{"id":"1.187566733","rc":[{"batb":[[1,1.05,285.88]],"batl":[[2,1.1,132.28]],"ltp":1.08,"tv":151247.13,"id":9323645}]}]}
{"op":"mcm","clk":"4217100918","pt":1631557786842,"mc":[{"id":"1.187566733","rc":[{"trd":[[1.08,28696.84]],"batb":[[0,1.08,8.46],[1,1.06,48.64],[2,1.05,285.88]],"batl":[[0,1.09,2147.34],[1,1.1,132.28],[2,1.12,21.33]],"ltp":1.08,"tv":151248.98,"id":9323645}],"tv":166670.08}]}
{"op":"mcm","clk":"4217101080","pt":1631557788056,"mc":[{"id":"1.187566733","rc":[{"batb":[[1,11,181.24]],"batl":[[0,14.5,10.34],[1,15,312.69],[2,15.5,5.16]],"ltp":13.5,"tv":15421.09,"id":8734382},{"trd":[[1.09,17891.12]],"batb":[[1,1.07,4062.43],[2,1.06,48.64]],"batl":[[0,1.09,2262.16],[1,1.1,1722.95]],"ltp":1.09,"tv":151266.68,"id":9323645}],"tv":166687.78}]}
{"op":"mcm","clk":"4217101225","pt":1631557789116,"mc":[{"id":"1.187566733","rc":[{"batb":[[1,11,194.88],[2,10.5,6.82]],"batl":[[0,14.5,6.2],[1,15,305.29],[2,15.5,3.1]],"ltp":13.5,"tv":15421.09,"id":8734382},{"batb":[[0,1.08,63.17],[1,1.07,1452.89],[2,1.06,76.51]],"batl":[[1,1.1,1725.23]],"ltp":1.09,"tv":151266.68,"id":9323645}]}]}
{"op":"mcm","clk":"4217101364","pt":1631557790052,"mc":[{"id":"1.187566733","rc":[{"batb":[[1,11,183.96],[2,10.5,1.36]],"batl":[[0,14.5,2.06],[1,15,303.23],[2,15.5,1.04]],"ltp":13.5,"tv":15421.09,"id":8734382},{"trd":[[1.08,28713.75]],"batb":[[0,1.08,854.71]],"batl":[[1,1.1,1723.41]],"ltp":1.08,"tv":151283.6,"id":9323645}],"tv":166704.7}]}
{"op":"mcm","clk":"4217101432","pt":1631557790632,"mc":[{"id":"1.187566733","rc":[{"batb":[[0,1.08,858.71]],"ltp":1.08,"tv":151283.6,"id":9323645}]}]}
{"op":"mcm","clk":"4217101589","pt":1631557791835,"mc":[{"id":"1.187566733","rc":[{"batb":[[0,11,183.96],[1,10.5,1.36],[2,10,1.36]],"ltp":13.5,"tv":15421.09,"id":8734382}]}]}
{"op":"mcm","clk":"4217101755","pt":1631557793153,"mc":[{"id":"1.187566733","rc":[{"batb":[[0,1.08,1288.71]],"batl":[[0,1.09,3123.28]],"ltp":1.08,"tv":151283.6,"id":9323645}]}]}
{"op":"mcm","clk":"4217101821","pt":1631557793623,"mc":[{"id":"1.187566733","rc":[{"batb":[[0,1.08,1420.98]],"batl":[[0,1.09,3448.28]],"ltp":1.08,"tv":151283.6,"id":9323645}]}]}
{"op":"mcm","clk":"4217102017","pt":1631557795041,"mc":[{"id":"1.187566733","rc":[{"batb":[[0,12,17.62],[1,11,183.96],[2,10.5,1.36]],"ltp":13.5,"tv":15421.09,"id":8734382},{"batb":[[1,1.07,1585.16]],"batl":[[1,1.1,3391.48],[2,1.11,1482.61]],"ltp":1.08,"tv":151283.6,"id":9323645}]}]}
{"op":"mcm","clk":"4217102672","pt":1631557800080,"mc":[{"id":"1.187566733","rc":[{"batb":[[1,1.07,1257.01]],"ltp":1.08,"tv":151283.6,"id":9323645}]}]}
{"op":"mcm","clk":"4217102700","pt":1631557800246,"mc":[{"id":"1.187566733","rc":[{"batb":[[0,1.08,620.98]],"ltp":1.08,"tv":151283.6,"id":9323645}]}]}
{"op":"mcm","clk":"4217103119","pt":1631557803137,"mc":[{"id":"1.187566733","rc":[{"batb":[[1,11,22.17],[2,8.8,26.18]],"batl":[[0,990,0.01],[1,15,0],[2,15.5,0]],"ltp":13.5,"tv":15421.09,"id":8734382},{"batb":[[0,1.08,190.98],[1,1.07,625.13]],"batl":[[0,1.09,1856.46],[1,1.1,1800.35]],"ltp":1.08,"tv":151283.6,"id":9323645}]}]}
{"op":"mcm","clk":"4217103239","pt":1631557803873,"mc":[{"id":"1.187566733","rc":[{"batb":[[0,11,22.17],[1,8,12.84],[2,2.5,1.82]],"ltp":13.5,"tv":15421.09,"id":8734382},{"batb":[[0,1.08,136.28],[1,1.07,132.28],[2,1.06,48.64]],"batl":[[0,1.09,136.23]],"ltp":1.08,"tv":151283.6,"id":9323645}]}]}
{"op":"mcm","clk":"4217103538","pt":1631557805960,"mc":[{"id":"1.187566733","rc":[{"batb":[[2,1.06,686.01]],"batl":[[1,1.1,2414.54]],"ltp":1.08,"tv":151283.6,"id":9323645}]}]}
{"op":"mcm","clk":"4217103722","pt":1631557807174,"mc":[{"id":"1.187566733","rc":[{"batb":[[0,12,17.62],[1,11,22.17],[2,8,12.84]],"batl":[[0,13,2],[1,990,0.01]],"ltp":13.5,"tv":15421.09,"id":8734382},{"batb":[[2,1.06,48.64]],"batl":[[0,1.09,1817.23]],"ltp":1.08,"tv":151283.6,"id":9323645}]}]}
{"op":"mcm","clk":"4217103828","pt":1631557807869,"mc":[{"id":"1.187566733","rc":[{"batb":[[0,11,22.17],[1,8,12.84],[2,2.5,1.82]],"ltp":13.5,"tv":15421.09,"id":8734382},{"trd":[[1.09,17931.12]],"batb":[[1,1.06,48.64],[2,1.05,891.53]],"batl":[[0,1.09,12.8]],"ltp":1.09,"tv":151323.6,"id":9323645}],"tv":166744.7}]}
{"op":"mcm","clk":"4217104122","pt":1631557809870,"mc":[{"id":"1.187566733","rc":[{"batb":[[0,11,28.08]],"batl":[[0,13,4.3],[1,13.5,160],[2,14,1.16]],"ltp":13.5,"tv":15421.09,"id":8734382},{"trd":[[1.09,17956.72],[1.1,10880.91]],"batb":[[0,1.08,3290]],"batl":[[0,1.1,2424.02],[1,1.11,4385.35],[2,1.12,34.83]],"ltp":1.1,"tv":151448.55,"id":9323645}],"tv":166869.65}]}
{"op":"mcm","clk":"4217104274","pt":1631557810979,"mc":[{"id":"1.187566733","rc":[{"batb":[[2,7.6,14.85]],"ltp":13.5,"tv":15421.09,"id":8734382},{"batb":[[0,1.09,132.28],[1,1.08,3715.33],[2,1.07,497.98]],"batl":[[1,1.11,4412.82],[2,1.12,48.35]],"ltp":1.1,"tv":151448.55,"id":9323645}]}]}
{"op":"mcm","clk":"4217104364","pt":1631557811671,"mc":[{"id":"1.187566733","rc":[{"batb":[[0,1.09,932.28]],"ltp":1.1,"tv":151448.55,"id":9323645}]}]}
{"op":"mcm","clk":"4217104668","pt":1631557813779,"mc":[{"id":"1.187566733","rc":[{"batb":[[1,1.08,4098.1]],"batl":[[0,1.1,3243.92]],"ltp":1.1,"tv":151448.55,"id":9323645}]}]}
{"op":"mcm","clk":"4217104823","pt":1631557814883,"mc":[{"id":"1.187566733","rc":[{"batb":[[0,1.09,1322.05]],"batl":[[0,1.1,3564.92]],"ltp":1.1,"tv":151448.55,"id":9323645}]}]}
{"op":"mcm","clk":"4217104965","pt":1631557815684,"mc":[{"id":"1.187566733","rc":[{"batb":[[0,1.09,522.05]],"ltp":1.1,"tv":151448.55,"id":9323645}]}]}
{"op":"mcm","clk":"4217105115","pt":1631557816681,"mc":[{"id":"1.187566733","rc":[{"batb":[[1,10,19.14],[2,8,12.84]],"batl":[[1,13.5,162.53]],"ltp":13.5,"tv":15421.09,"id":8734382},{"batb":[[1,1.08,4100.16],[2,1.07,1923.63]],"batl":[[2,1.12,1604.14]],"ltp":1.1,"tv":151448.55,"id":9323645}]}]}
{"op":"mcm","clk":"4217105233","pt":1631557817485,"mc":[{"id":"1.187566733","rc":[{"batl":[[1,1.11,4545.1]],"ltp":1.1,"tv":151448.55,"id":9323645}]}]}
{"op":"mcm","clk":"4217105426","pt":1631557818474,"mc":[{"id":"1.187566733","rc":[{"batl":[[2,1.12,1736.42]],"ltp":1.1,"tv":151448.55,"id":9323645}]}]}
{"op":"mcm","clk":"4217105790","pt":1631557821168,"mc":[{"id":"1.187566733","rc":[{"batb":[[0,11,22.17]],"batl":[[0,13,2],[1,13.5,2.53],[2,15.5,2.39]],"ltp":13.5,"tv":15421.09,"id":8734382},{"batb":[[0,1.09,132.28],[1,1.08,591.02]],"batl":[[0,1.1,2071.69],[1,1.11,1614.89],[2,1.12,1722.9]],"ltp":1.1,"tv":151448.55,"id":9323645}]}]}
{"op":"mcm","clk":"4217105900","pt":1631557821894,"mc":[{"id":"1.187566733","rc":[{"batb":[[0,10,19.14],[1,7.6,14.85],[2,2.5,1.82]],"batl":[[1,15.5,2.39],[2,990,0.01]],"ltp":13.5,"tv":15421.09,"id":8734382},{"batb":[[1,1.08,132.28]],"batl":[[0,1.1,82.62],[2,1.12,167.11]],"ltp":1.1,"tv":151448.55,"id":9323645}]}]}
{"op":"mcm","clk":"4217106232","pt":1631557824072,"mc":[{"id":"1.187566733","rc":[{"batb":[[0,1.09,128.86],[2,1.07,2555.04]],"batl":[[1,1.11,2223.55]],"ltp":1.1,"tv":151448.55,"id":9323645}]}]}
{"op":"mcm","clk":"4217106397","pt":1631557825083,"mc":[{"id":"1.187566733","rc":[{"batb":[[0,11,20.12],[1,10,19.14],[2,7.6,14.85]],"batl":[[1,13.5,2.31],[2,15.5,2.39]],"ltp":13.5,"tv":15421.09,"id":8734382},{"batb":[[1,1.08,134.34]],"batl":[[0,1.1,1962.24],[2,1.12,1603.85]],"ltp":1.1,"tv":151448.55,"id":9323645}]}]}
{"op":"mcm","clk":"4217106469","pt":1631557825393,"mc":[{"id":"1.187566733","rc":[{"batb":[[0,10,19.14],[1,7.6,14.85],[2,2.5,1.82]],"batl":[[1,15.5,2.39],[2,990,0.01]],"ltp":13.5,"tv":15421.09,"id":8734382},{"batb":[[1,1.08,132.28]],"batl":[[0,1.1,82.62]],"ltp":1.1,"tv":151448.55,"id":9323645}]}]}
{"op":"mcm","clk":"4217106765","pt":1631557827575,"mc":[{"id":"1.187566733","rc":[{"trd":[[1.1,11023.76]],"batl":[[0,1.1,11.19]],"ltp":1.1,"tv":151591.4,"id":9323645}],"tv":167012.5}]}
{"op":"mcm","clk":"4217107013","pt":1631557828995,"mc":[{"id":"1.187566733","rc":[{"trd":[[1.1,11265.92]],"batl":[[0,1.11,2223.55],[1,1.12,1603.85],[2,1.13,9.39]],"ltp":1.1,"tv":151833.56,"id":9323645}],"tv":167254.66}]}
{"op":"mcm","clk":"4217107610","pt":1631557833081,"mc":[{"id":"1.187566733","rc":[{"batb":[[0,1.1,8],[1,1.09,128.86],[2,1.08,132.28]],"ltp":1.1,"tv":151833.56,"id":9323645}]}]}
{"op":"mcm","clk":"4217108065","pt":1631557836101,"mc":[{"id":"1.187566733","rc":[{"trd":[[11,146.12]],"batl":[[1,13.5,2.91],[2,15.5,2.39]],"ltp":11.0,"tv":15422.06,"id":8734382},{"trd":[[1.1,11275.63]],"batb":[[0,1.09,128.86],[1,1.08,134.34],[2,1.07,1923.63]],"ltp":1.1,"tv":151843.27,"id":9323645}],"tv":167265.34}]}
{"op":"mcm","clk":"4217108192","pt":1631557836995,"mc":[{"id":"1.187566733","rc":[{"batb":[[0,1.1,1.71],[1,1.09,128.86],[2,1.08,134.34]],"ltp":1.1,"tv":151843.27,"id":9323645}]}]}
{"op":"mcm","clk":"4217108318","pt":1631557837892,"mc":[{"id":"1.187566733","rc":[{"batb":[[0,10,175.51]],"batl":[[0,12,226.94],[1,12.5,17.24],[2,13,3.24]],"ltp":11.0,"tv":15422.06,"id":8734382},{"trd":[[1.11,10768.41]],"batb":[[1,1.09,1099.97]],"batl":[[0,1.11,2300.58]],"ltp":1.11,"tv":151967.1,"id":9323645}],"tv":167389.16}]}
{"op":"mcm","clk":"4217108474","pt":1631557838897,"mc":[{"id":"1.187566733","rc":[{"batb":[[1,9.6,3.12],[2,9.4,1.56]],"ltp":11.0,"tv":15422.06,"id":8734382},{"batb":[[1,1.09,1493.46],[2,1.08,572.48]],"batl":[[1,1.12,1604.3]],"ltp":1.11,"tv":151967.1,"id":9323645}]}]}
{"op":"mcm","clk":"4217108949","pt":1631557841806,"mc":[{"id":"1.187566733","rc":[{"batb":[[1,1.09,1952.52]],"batl":[[0,1.11,3543.52]],"ltp":1.11,"tv":151967.1,"id":9323645}]}]}
{"op":"mcm","clk":"4217109133","pt":1631557842912,"mc":[{"id":"1.187566733","rc":[{"trd":[[10,20.12]],"batb":[[0,10,175.18]],"ltp":10.0,"tv":15422.72,"id":8734382},{"trd":[[1.11,10774.34]],"batb":[[0,1.1,11.85]],"batl":[[0,1.11,3540.56]],"ltp":1.11,"tv":151973.02,"id":9323645}],"tv":167395.75}]}
{"op":"mcm","clk":"4217109366","pt":1631557844511,"mc":[{"id":"1.187566733","rc":[{"batb":[[2,1.08,602.79]],"batl":[[2,1.13,1471.3]],"ltp":1.11,"tv":151973.02,"id":9323645}]}]}
{"op":"mcm","clk":"4217109583","pt":1631557845994,"mc":[{"id":"1.187566733","rc":[{"trd":[[1.11,10790.34]],"batl":[[0,1.11,3532.56]],"ltp":1.11,"tv":151989.02,"id":9323645}],"tv":167411.75}]}
{"op":"mcm","clk":"4217109733","pt":1631557847002,"mc":[{"id":"1.187566733","rc":[{"batb":[[0,1.1,694.55],[2,1.08,470.51]],"batl":[[0,1.11,3419.05],[1,1.12,1490.8]],"ltp":1.11,"tv":151989.02,"id":9323645}]}]}
{"op":"mcm","clk":"4217109759","pt":1631557847218,"mc":[{"id":"1.187566733","rc":[{"batb":[[0,1.1,1121.24]],"ltp":1.11,"tv":151989.02,"id":9323645}]}]}
{"op":"mcm","clk":"4217110137","pt":1631557849908,"mc":[{"id":"1.187566733","rc":[{"batb":[[0,1.1,1472.32],[1,1.09,1630.51]],"ltp":1.11,"tv":151989.02,"id":9323645}]}]}
{"op":"mcm","clk":"4217110313","pt":1631557851117,"mc":[{"id":"1.187566733","rc":[{"batb":[[0,10,18.81],[1,9.2,18.92],[2,7.2,16.95]],"batl":[[0,13,2],[1,13.5,4.91],[2,15.5,2.39]],"ltp":10.0,"tv":15422.72,"id":8734382},{"batb":[[0,1.1,1121.24],[1,1.09,254.52]],"batl":[[0,1.11,2054.18],[1,1.12,1490.35]],"ltp":1.11,"tv":151989.02,"id":9323645}]}]}
{"op":"mcm","clk":"4217110483","pt":1631557852017,"mc":[{"id":"1.187566733","rc":[{"batb":[[0,9.2,18.92],[1,7.2,16.95],[2,2.5,1.82]],"ltp":10.0,"tv":15422.72,"id":8734382},{"batb":[[0,1.1,1119.53]],"batl":[[0,1.11,270.43]],"ltp":1.11,"tv":151989.02,"id":9323645}]}]}
{"op":"mcm","clk":"4217110727","pt":1631557853809,"mc":[{"id":"1.187566733","rc":[{"trd":[[1.1,11279.04]],"batb":[[0,1.1,1117.83]],"ltp":1.1,"tv":151992.43,"id":9323645}],"tv":167415.16}]}
{"op":"mcm","clk":"4217111059","pt":1631557856012,"mc":[{"id":"1.187566733","rc":[{"trd":[[1.11,10990.34]],"batl":[[0,1.11,170.43],[2,1.13,9.39]],"ltp":1.11,"tv":152192.44,"id":9323645}],"tv":167615.17}]}
{"op":"mcm","clk":"4217111238","pt":1631557857120,"mc":[{"id":"1.187566733","rc":[{"batl":[[0,13.5,4.91],[1,15.5,2.39],[2,990,0.01]],"ltp":10.0,"tv":15422.72,"id":8734382},{"batb":[[1,1.09,750.4]],"batl":[[0,1.11,527.43],[1,1.12,2201.49]],"ltp":1.11,"tv":152192.44,"id":9323645}]}]}
{"op":"mcm","clk":"4217111544","pt":1631557859128,"mc":[{"id":"1.187566733","rc":[{"batb":[[1,1.09,301.11]],"batl":[[0,1.11,206.16]],"ltp":1.11,"tv":152192.44,"id":9323645}]}]}
{"op":"mcm","clk":"4217111691","pt":1631557860119,"mc":[{"id":"1.187566733","rc":[{"trd":[[10,22.12]],"ltp":10.0,"tv":15424.72,"id":8734382},{"trd":[[1.11,11008.36]],"batl":[[0,1.11,188.14]],"ltp":1.11,"tv":152210.46,"id":9323645}],"tv":167635.19}]}
{"op":"mcm","clk":"4217111996","pt":1631557862125,"mc":[{"id":"1.187566733","rc":[{"trd":[[1.11,11048.36]],"batb":[[2,1.08,901.94]],"batl":[[0,1.11,168.14],[1,1.12,2600.4]],"ltp":1.11,"tv":152250.46,"id":9323645}],"tv":167675.19}]}
{"op":"mcm","clk":"4217112318","pt":1631557864135,"mc":[{"id":"1.187566733","rc":[{"trd":[[1.1,11282.45]],"batb":[[0,1.1,1116.12]],"batl":[[0,1.11,177.53]],"ltp":1.1,"tv":152253.87,"id":9323645}],"tv":167678.6}]}
{"op":"mcm","clk":"4217112432","pt":1631557864826,"mc":[{"id":"1.187566733","rc":[{"batb":[[1,1.09,322.92]],"batl":[[0,1.11,194.25],[1,1.12,2621.5]],"ltp":1.1,"tv":152253.87,"id":9323645}]}]}
{"op":"mcm","clk":"4217112728","pt":1631557866631,"mc":[{"id":"1.187566733","rc":[{"batb":[[1,1.09,130.57],[2,1.08,470.51]],"ltp":1.1,"tv":152253.87,"id":9323645}]}]}
{"op":"mcm","clk":"4217112897","pt":1631557867729,"mc":[{"id":"1.187566733","rc":[{"batl":[[1,1.12,1910.36]],"ltp":1.1,"tv":152253.87,"id":9323645}]}]}
{"op":"mcm","clk":"4217113248","pt":1631557870144,"mc":[{"id":"1.187566733","rc":[{"batl":[[0,12,359.11],[1,12.5,2],[2,13.5,4.91]],"ltp":10.0,"tv":15424.72,"id":8734382},{"trd":[[1.11,11172.03]],"batb":[[0,1.1,2059.76],[1,1.09,224.19],[2,1.08,511.42]],"batl":[[0,1.11,217.91],[1,1.12,4126.81]],"ltp":1.11,"tv":152377.54,"id":9323645}],"tv":167802.27}]}
{"op":"mcm","clk":"4217113398","pt":1631557871143,"mc":[{"id":"1.187566733","rc":[{"batb":[[1,9,3.34],[2,8.8,1.66]],"ltp":10.0,"tv":15424.72,"id":8734382},{"trd":[[1.11,11417.78]],"batb":[[0,1.1,2367.84],[1,1.09,196.92],[2,1.08,459.15]],"batl":[[0,1.11,85.48],[2,1.13,9.83]],"ltp":1.11,"tv":152623.29,"id":9323645}],"tv":168048.01}]}
{"op":"mcm","clk":"4217113684","pt":1631557873149,"mc":[{"id":"1.187566733","rc":[{"batl":[[2,13.5,2.91]],"ltp":10.0,"tv":15424.72,"id":8734382},{"batb":[[0,1.1,2361.1],[2,1.08,428.84]],"batl":[[0,1.11,110.69],[1,1.12,4155.17]],"ltp":1.11,"tv":152623.29,"id":9323645}]}]}
{"op":"mcm","clk":"4217113817","pt":1631557874144,"mc":[{"id":"1.187566733","rc":[{"batb":[[0,1.1,2703.05]],"batl":[[0,1.11,85.48],[1,1.12,5083.43]],"ltp":1.11,"tv":152623.29,"id":9323645}]}]}
{"op":"mcm","clk":"4217113945","pt":1631557874939,"mc":[{"id":"1.187566733","rc":[{"batl":[[1,1.12,5049.29],[2,1.13,2.15]],"ltp":1.11,"tv":152623.29,"id":9323645}]}]}
{"op":"mcm","clk":"4217114133","pt":1631557876147,"mc":[{"id":"1.187566733","rc":[{"batl":[[2,13.5,4.91]],"ltp":10.0,"tv":15424.72,"id":8734382},{"trd":[[1.11,11431.25]],"batb":[[2,1.08,458.4]],"batl":[[0,1.11,259.74],[2,1.13,1494.47]],"ltp":1.11,"tv":152636.76,"id":9323645}],"tv":168061.49}]}
{"op":"mcm","clk":"4217114653","pt":1631557879562,"mc":[{"id":"1.187566733","rc":[{"trd":[[1.11,11471.25]],"batl":[[0,1.11,239.74]],"ltp":1.11,"tv":152676.76,"id":9323645}],"tv":168101.49}]}
{"op":"mcm","clk":"4217114824","pt":1631557880774,"mc":[{"id":"1.187566733","rc":[{"trd":[[1.1,11288.24]],"batb":[[0,1.1,2700.16]],"ltp":1.1,"tv":152682.54,"id":9323645}],"tv":168107.27}]}
{"op":"mcm","clk":"4217114936","pt":1631557881459,"mc":[{"id":"1.187566733","rc":[{"batb":[[0,1.1,2444.93]],"ltp":1.1,"tv":152682.54,"id":9323645}]}]}
{"op":"mcm","clk":"4217115193","pt":1631557883179,"mc":[{"id":"1.187566733","rc":[{"trd":[[10,29.35]],"ltp":10.0,"tv":15431.95,"id":8734382},{"trd":[[1.11,11536.38]],"batl":[[0,1.11,174.61],[1,1.12,5035.79]],"ltp":1.11,"tv":152747.67,"id":9323645}],"tv":168179.63}]}
{"op":"mcm","clk":"4217115572","pt":1631557885883,"mc":[{"id":"1.187566733","rc":[{"trd":[[1.1,11315.86]],"batb":[[0,1.1,2431.11]],"ltp":1.1,"tv":152775.3,"id":9323645}],"tv":168207.26}]}
{"op":"mcm","clk":"4217115644","pt":1631557886358,"mc":[{"id":"1.187566733","rc":[{"batl":[[0,12,343.83]],"ltp":10.0,"tv":15431.95,"id":8734382}]}]}
{"op":"mcm","clk":"4217116576","pt":1631557892682,"mc":[{"id":"1.187566733","rc":[{"batl":[[0,11,6.12],[1,12,343.83],[2,12.5,2]],"ltp":10.0,"tv":15431.95,"id":8734382},{"batb":[[0,1.1,2492.28]],"batl":[[1,1.12,5137.73]],"ltp":1.1,"tv":152775.3,"id":9323645}]}]}
{"op":"mcm","clk":"4217116679","pt":1631557893369,"mc":[{"id":"1.187566733","rc":[{"batl":[[0,12,343.83],[1,12.5,2],[2,13.5,4.91]],"ltp":10.0,"tv":15431.95,"id":8734382},{"trd":[[1.11,11540.8]],"batb":[[0,1.1,2431.11]],"batl":[[0,1.11,172.4],[1,1.12,5035.79]],"ltp":1.11,"tv":152779.72,"id":9323645}],"tv":168211.68}]}
{"op":"mcm","clk":"4217117024","pt":1631557895778,"mc":[{"id":"1.187566733","rc":[{"trd":[[10,34.64]],"ltp":10.0,"tv":15437.24,"id":8734382},{"trd":[[1.11,11628.46]],"batl":[[0,1.11,104.74]],"ltp":1.11,"tv":152867.38,"id":9323645}],"tv":168304.63}]}
{"op":"mcm","clk":"4217117094","pt":1631557896259,"mc":[{"id":"1.187566733","rc":[{"batl":[[0,11,6.12],[1,12,343.83],[2,12.5,2]],"ltp":10.0,"tv":15437.24,"id":8734382},{"batb":[[0,1.1,2492.28]],"batl":[[1,1.12,5137.73]],"ltp":1.11,"tv":152867.38,"id":9323645}]}]}
{"op":"mcm","clk":"4217118028","pt":1631557903095,"mc":[{"id":"1.187566733","rc":[{"batb":[[0,1.1,2473.51]],"ltp":1.11,"tv":152867.38,"id":9323645}]}]}
{"op":"mcm","clk":"4217118220","pt":1631557904479,"mc":[{"id":"1.187566733","rc":[{"batl":[[0,1.11,110.71]],"ltp":1.11,"tv":152867.38,"id":9323645}]}]}
{"op":"mcm","clk":"4217118360","pt":1631557905475,"mc":[{"id":"1.187566733","rc":[{"trd":[[1.1,12501.59],[1.11,11747.01]],"batb":[[0,1.1,1880.64]],"batl":[[0,1.11,51.43]],"ltp":1.11,"tv":154171.65,"id":9323645}],"tv":169608.9}]}
{"op":"mcm","clk":"4217118585","pt":1631557906985,"mc":[{"id":"1.187566733","rc":[{"batb":[[0,1.1,1274.51],[1,1.09,169.82]],"batl":[[1,1.12,4542.42]],"ltp":1.11,"tv":154171.65,"id":9323645}]}]}
{"op":"mcm","clk":"4217118988","pt":1631557909768,"mc":[{"id":"1.187566733","rc":[{"batb":[[1,1.09,614.45],[2,1.08,627.01]],"ltp":1.11,"tv":154171.65,"id":9323645}]}]}
{"op":"mcm","clk":"4217119186","pt":1631557911076,"mc":[{"id":"1.187566733","rc":[{"trd":[[10,40.35]],"batl":[[0,10,5.37],[1,11,6.12],[2,12,343.83]],"ltp":10.0,"tv":15442.96,"id":8734382},{"trd":[[1.11,11798.44]],"batl":[[0,1.12,4542.42],[1,1.13,1494.47],[2,1.14,1882.66]],"ltp":1.11,"tv":154223.09,"id":9323645}],"tv":169666.05}]}
{"op":"mcm","clk":"4217119276","pt":1631557911703,"mc":[{"id":"1.187566733","rc":[{"batb":[[0,8,20.26],[1,6.2,24.5],[2,2.5,1.82]],"batl":[[1,13.5,2],[2,15.5,4.39]],"ltp":10.0,"tv":15442.96,"id":8734382},{"batb":[[0,1.1,481.04],[1,1.09,575.2],[2,1.08,611.31]],"batl":[[0,1.12,5.97],[1,1.14,1882.66],[2,1.15,136.14]],"ltp":1.11,"tv":154223.09,"id":9323645}]}]}
{"op":"mcm","clk":"4217119474","pt":1631557913085,"mc":[{"id":"1.187566733","rc":[{"trd":[[10,45.72]],"batl":[[0,13.5,2],[1,15.5,4.39],[2,990,0.01]],"ltp":10.0,"tv":15448.32,"id":8734382},{"trd":[[1.11,11846.73]],"batl":[[0,1.11,87.25],[1,1.12,5.97],[2,1.14,1882.66]],"ltp":1.11,"tv":154271.38,"id":9323645}],"tv":169719.7}]}
{"op":"mcm","clk":"4217119568","pt":1631557913708,"mc":[{"id":"1.187566733","rc":[{"batb":[[0,6.2,24.5],[1,2.5,1.82],[2,1.01,98.87]],"ltp":10.0,"tv":15448.32,"id":8734382},{"batb":[[1,1.09,130.57],[2,1.08,442.7]],"batl":[[0,1.11,284.18],[2,1.23,31.44]],"ltp":1.11,"tv":154271.38,"id":9323645}]}]}
{"op":"mcm","clk":"4217119781","pt":1631557915190,"mc":[{"id":"1.187566733","rc":[{"batb":[[0,7.6,20.99],[1,6.2,24.5],[2,2.5,1.82]],"ltp":10.0,"tv":15448.32,"id":8734382},{"trd":[[1.1,12505.01]],"batb":[[0,1.1,479.33]],"batl":[[0,1.12,5.97],[1,1.15,1363.36]],"ltp":1.1,"tv":154274.79,"id":9323645}],"tv":169723.12}]}
{"op":"mcm","clk":"4217120041","pt":1631557916915,"mc":[{"id":"1.187566733","rc":[{"batb":[[0,8,20.85],[1,7.6,20.99],[2,6.2,24.5]],"ltp":10.0,"tv":15448.32,"id":8734382},{"trd":[[1.12,11904.32]],"batb":[[0,1.11,166.57],[1,1.1,917.37],[2,1.09,130.57]],"batl":[[0,1.12,513.11],[1,1.14,1449.5],[2,1.15,1363.36]],"ltp":1.12,"tv":154294.65,"id":9323645}],"tv":169742.97}]}
{"op":"mcm","clk":"4217120221","pt":1631557918190,"mc":[{"id":"1.187566733","rc":[{"batb":[[0,7.6,20.99],[1,6.2,24.5],[2,2.5,1.82]],"ltp":10.0,"tv":15448.32,"id":8734382},{"batb":[[0,1.1,479.33],[1,1.09,130.57],[2,1.08,442.7]],"batl":[[0,1.12,355.57],[1,1.15,1363.36],[2,1.23,31.44]],"ltp":1.12,"tv":154294.65,"id":9323645}]}]}
{"op":"mcm","clk":"4217120325","pt":1631557918809,"mc":[{"id":"1.187566733","rc":[{"batb":[[0,1.11,387.9],[1,1.1,479.33],[2,1.09,130.57]],"ltp":1.12,"tv":154294.65,"id":9323645}]}]}
{"op":"mcm","clk":"4217120435","pt":1631557919516,"mc":[{"id":"1.187566733","rc":[{"batb":[[0,1.1,479.33],[1,1.09,130.57],[2,1.08,442.7]],"ltp":1.12,"tv":154294.65,"id":9323645}]}]}
{"op":"mcm","clk":"4217120630","pt":1631557920715,"mc":[{"id":"1.187566733","rc":[{"batb":[[1,1.09,577.51],[2,1.08,608.97]],"batl":[[0,1.12,487.85],[1,1.14,445.41],[2,1.15,1501.6]],"ltp":1.12,"tv":154294.65,"id":9323645}]}]}
{"op":"mcm","clk":"4217120767","pt":1631557921627,"mc":[{"id":"1.187566733","rc":[{"batb":[[0,8,21.85],[1,7.6,20.99],[2,6.2,24.5]],"ltp":10.0,"tv":15448.32,"id":8734382},{"batl":[[0,1.11,132.28],[1,1.12,487.85],[2,1.14,1748.55]],"ltp":1.12,"tv":154294.65,"id":9323645}]}]}
{"op":"mcm","clk":"4217121164","pt":1631557924111,"mc":[{"id":"1.187566733","rc":[{"batb":[[1,1.09,130.57],[2,1.08,442.7]],"batl":[[1,1.12,132.28]],"ltp":1.12,"tv":154294.65,"id":9323645}]}]}
{"op":"mcm","clk":"4217121272","pt":1631557924852,"mc":[{"id":"1.187566733","rc":[{"batl":[[0,1.14,1748.55],[1,1.15,1501.6],[2,1.23,31.44]],"ltp":1.12,"tv":154294.65,"id":9323645}]}]}
{"op":"mcm","clk":"4217121453","pt":1631557926118,"mc":[{"id":"1.187566733","rc":[{"batb":[[0,8,243.39]],"batl":[[0,9,22.22],[1,9.2,13.1],[2,9.4,509.64]],"ltp":10.0,"tv":15448.32,"id":8734382},{"trd":[[1.14,112.79]],"batb":[[0,1.13,134.95],[1,1.12,66.38],[2,1.11,66.38]],"batl":[[0,1.14,1798.52]],"ltp":1.14,"tv":154311.31,"id":9323645}],"tv":169759.63}]}
{"op":"mcm","clk":"4217121605","pt":1631557927114,"mc":[{"id":"1.187566733","rc":[{"batb":[[2,7.4,20.28]],"batl":[[0,9,13.33],[2,9.4,2]],"ltp":10.0,"tv":15448.32,"id":8734382},{"trd":[[1.14,216.42]],"batb":[[0,1.13,80.08],[1,1.12,851.52],[2,1.11,39.83]],"batl":[[0,1.14,1746.72],[2,1.16,2.15]],"ltp":1.14,"tv":154414.94,"id":9323645}],"tv":169863.26}]}
{"op":"mcm","clk":"4217121763","pt":1631557928110,"mc":[{"id":"1.187566733","rc":[{"batb":[[2,7.4,4.06]],"ltp":10.0,"tv":15448.32,"id":8734382},{"batb":[[0,1.13,26.98],[1,1.12,824.97],[2,1.11,13.28]],"batl":[[2,1.23,31.87]],"ltp":1.14,"tv":154414.94,"id":9323645}]}]}
{"op":"mcm","clk":"4217121898","pt":1631557929045,"mc":[{"id":"1.187566733","rc":[{"batl":[[2,1.23,1.88]],"ltp":1.14,"tv":154414.94,"id":9323645}]}]}
{"op":"mcm","clk":"4217122043","pt":1631557929904,"mc":[{"id":"1.187566733","rc":[{"trd":[[8,20.31]],"batb":[[0,8,221.54]],"ltp":8.0,"tv":15454.94,"id":8734382},{"batb":[[0,1.13,145.85]],"batl":[[0,1.14,700.46],[1,1.15,1534.56]],"ltp":1.14,"tv":154414.94,"id":9323645}],"tv":169869.88}]}
{"op":"mcm","clk":"4217122226","pt":1631557931105,"mc":[{"id":"1.187566733","rc":[{"batb":[[1,1.12,826.68]],"ltp":1.14,"tv":154414.94,"id":9323645}]}]}
{"op":"mcm","clk":"4217122365","pt":1631557932041,"mc":[{"id":"1.187566733","rc":[{"batb":[[2,1.11,14.99]],"ltp":1.14,"tv":154414.94,"id":9323645}]}]}
{"op":"mcm","clk":"4217122521","pt":1631557932934,"mc":[{"id":"1.187566733","rc":[{"batb":[[0,1.13,28.69],[1,1.12,486.91]],"batl":[[0,1.14,915.48],[1,1.15,1363.36],[2,1.18,1352.19]],"ltp":1.14,"tv":154414.94,"id":9323645}]}]}
{"op":"mcm","clk":"4217122845","pt":1631557935138,"mc":[{"id":"1.187566733","rc":[{"trd":[[1.13,2880.1]],"batb":[[0,1.12,486.91],[1,1.11,14.99],[2,1.1,851.21]],"batl":[[0,1.13,345.09],[1,1.14,915.48],[2,1.15,1363.36]],"ltp":1.13,"tv":154472.31,"id":9323645}],"tv":169927.26}]}
{"op":"mcm","clk":"4217123175","pt":1631557937436,"mc":[{"id":"1.187566733","rc":[{"trd":[[1.13,3031.42]],"batb":[[0,1.12,349.59]],"batl":[[0,1.13,269.41]],"ltp":1.13,"tv":154623.64,"id":9323645}],"tv":170078.59}]}
{"op":"mcm","clk":"4217123309","pt":1631557938341,"mc":[{"id":"1.187566733","rc":[{"batl":[[0,1.13,801.93],[1,1.14,917.19]],"ltp":1.13,"tv":154623.64,"id":9323645}]}]}
{"op":"mcm","clk":"4217123488","pt":1631557939541,"mc":[{"id":"1.187566733","rc":[{"batl":[[2,1.15,1365.07]],"ltp":1.13,"tv":154623.64,"id":9323645}]}]}
{"op":"mcm","clk":"4217123848","pt":1631557941952,"mc":[{"id":"1.187566733","rc":[{"batb":[[0,7.2,21.92],[1,6.4,27.41],[2,6,27.39]],"batl":[[0,9.4,2],[1,11,2],[2,12.5,2]],"ltp":8.0,"tv":15454.94,"id":8734382},{"batb":[[0,1.12,20.5],[1,1.11,1.71]],"batl":[[0,1.13,269.41],[1,1.14,231.71],[2,1.15,1.71]],"ltp":1.13,"tv":154623.64,"id":9323645}]}]}
{"op":"mcm","clk":"4217123943","pt":1631557942641,"mc":[{"id":"1.187566733","rc":[{"batl":[[1,1.14,1.71]],"ltp":1.13,"tv":154623.64,"id":9323645}]}]}
{"op":"mcm","clk":"4217124281","pt":1631557945123,"mc":[{"id":"1.187566733","rc":[{"trd":[[1.13,3031.46]],"batl":[[0,1.13,269.4]],"ltp":1.13,"tv":154623.68,"id":9323645}],"tv":170078.62}]}
{"op":"mcm","clk":"4217124630","pt":1631557947750,"mc":[{"id":"1.187566733","rc":[{"batb":[[0,6.4,27.41],[1,5.3,18.63],[2,2.5,1.82]],"ltp":8.0,"tv":15454.94,"id":8734382},{"batl":[[0,1.14,1.71],[1,1.15,1.71],[2,1.16,1.71]],"ltp":1.13,"tv":154623.68,"id":9323645}]}]}
{"op":"mcm","clk":"4217124832","pt":1631557949031,"mc":[{"id":"1.187566733","rc":[{"batb":[[0,8.6,18.69],[1,6.4,27.41],[2,5.3,18.63]],"batl":[[0,9.4,21.69]],"ltp":8.0,"tv":15454.94,"id":8734382},{"batl":[[0,1.13,19.5],[1,1.14,1.71],[2,1.15,1.71]],"ltp":1.13,"tv":154623.68,"id":9323645}]}]}
{"op":"mcm","clk":"4217124870","pt":1631557949339,"mc":[{"id":"1.187566733","rc":[{"batb":[[0,6.4,27.41],[1,5.3,18.63],[2,2.5,1.82]],"batl":[[0,9.4,2]],"ltp":8.0,"tv":15454.94,"id":8734382},{"batl":[[0,1.14,1.71],[1,1.15,1.71],[2,1.16,1.71]],"ltp":1.13,"tv":154623.68,"id":9323645}]}]}
{"op":"mcm","clk":"4217125105","pt":1631557950931,"mc":[{"id":"1.187566733","rc":[{"batb":[[0,7.2,23.02],[1,6.4,27.41],[2,5.3,18.63]],"ltp":8.0,"tv":15454.94,"id":8734382},{"batl":[[0,1.14,271.1],[2,1.16,1239.72]],"ltp":1.13,"tv":154623.68,"id":9323645}]}]}
{"op":"mcm","clk":"4217125273","pt":1631557952029,"mc":[{"id":"1.187566733","rc":[{"batb":[[0,1.13,204],[1,1.12,319.18],[2,1.11,1.71]],"ltp":1.13,"tv":154623.68,"id":9323645}]}]}
{"op":"mcm","clk":"4217125377","pt":1631557952752,"mc":[{"id":"1.187566733","rc":[{"batb":[[1,1.12,674.76]],"ltp":1.13,"tv":154623.68,"id":9323645}]}]}
{"op":"mcm","clk":"4217125577","pt":1631557954137,"mc":[{"id":"1.187566733","rc":[{"batl":[[0,11,2],[1,12.5,2],[2,990,0.01]],"ltp":8.0,"tv":15454.94,"id":8734382},{"batb":[[1,1.12,300.39],[2,1.11,389.61]],"ltp":1.13,"tv":154623.68,"id":9323645}]}]}
{"op":"mcm","clk":"4217125639","pt":1631557954557,"mc":[{"id":"1.187566733","rc":[{"batb":[[2,1.11,1.71]],"ltp":1.13,"tv":154623.68,"id":9323645}]}]}
{"op":"mcm","clk":"4217125845","pt":1631557956037,"mc":[{"id":"1.187566733","rc":[{"batb":[[0,1.12,300.39],[1,1.11,1.71],[2,1.1,371.88]],"ltp":1.13,"tv":154623.68,"id":9323645}]}]}
{"op":"mcm","clk":"4217125964","pt":1631557956868,"mc":[{"id":"1.187566733","rc":[{"batl":[[0,1.14,272.81]],"ltp":1.13,"tv":154623.68,"id":9323645}]}]}
{"op":"mcm","clk":"4217126110","pt":1631557957869,"mc":[{"id":"1.187566733","rc":[{"trd":[[8,41.42],[8.6,124.08]],"batb":[[0,6.4,27.41],[1,5.3,18.63],[2,2.5,1.82]],"ltp":8.0,"tv":15476.28,"id":8734382},{"trd":[[1.13,3033.17],[1.14,364.57]],"batl":[[0,1.14,124.65],[2,1.16,1.71]],"ltp":1.14,"tv":154773.54,"id":9323645}],"tv":170249.82}]}
{"op":"mcm","clk":"4217126287","pt":1631557959147,"mc":[{"id":"1.187566733","rc":[{"trd":[[1.14,407.99]],"batb":[[0,1.14,202.29],[1,1.12,300.39],[2,1.11,1.71]],"batl":[[0,1.15,1.71],[1,1.16,1.71],[2,1.17,1.71]],"ltp":1.14,"tv":154816.96,"id":9323645}],"tv":170293.24}]}
{"op":"mcm","clk":"4217126383","pt":1631557959779,"mc":[{"id":"1.187566733","rc":[{"trd":[[1.14,487.54]],"batb":[[0,1.14,162.52]],"ltp":1.14,"tv":154896.51,"id":9323645}],"tv":170372.79}]}
{"op":"mcm","clk":"4217126581","pt":1631557961058,"mc":[{"id":"1.187566733","rc":[{"batb":[[0,7.2,22.57],[1,6.4,27.41],[2,5.3,18.63]],"ltp":8.0,"tv":15476.28,"id":8734382},{"batl":[[1,1.16,1407.48],[2,1.17,1230.43]],"ltp":1.14,"tv":154896.51,"id":9323645}]}]}
{"op":"mcm","clk":"4217126624","pt":1631557961368,"mc":[{"id":"1.187566733","rc":[{"batb":[[0,6.4,27.41],[1,5.3,18.63],[2,2.5,1.82]],"ltp":8.0,"tv":15476.28,"id":8734382},{"batl":[[1,1.16,1.71],[2,1.17,1.71]],"ltp":1.14,"tv":154896.51,"id":9323645}]}]}
{"op":"mcm","clk":"4217126879","pt":1631557963154,"mc":[{"id":"1.187566733","rc":[{"batb":[[0,8.2,9.14],[1,8,4.57],[2,7.8,4.57]],"batl":[[0,12.5,2],[1,990,0.01],[2,990,0]],"ltp":8.0,"tv":15476.28,"id":8734382},{"trd":[[1.12,11907.73],[1.14,812.58]],"batb":[[0,1.11,1.71],[1,1.1,344.94],[2,1.09,156.18]],"batl":[[0,1.12,3587.48],[1,1.14,87.72],[2,1.15,1.71]],"ltp":1.12,"tv":155224.96,"id":9323645}],"tv":170701.24}]}
{"op":"mcm","clk":"4217127028","pt":1631557964155,"mc":[{"id":"1.187566733","rc":[{"trd":[[10,50.45]],"batb":[[0,8.2,10.97],[1,8,5.48],[2,7.8,5.48]],"batl":[[0,11,100.34],[1,12.5,2],[2,990,0.01]],"ltp":10.0,"tv":15481.01,"id":8734382},{"trd":[[1.11,11998.23],[1.12,11924.83]],"batb":[[0,1.1,1375.24],[1,1.09,156.18],[2,1.07,768.05]],"batl":[[0,1.12,41.92],[1,1.13,2805.6],[2,1.14,108.33]],"ltp":1.12,"tv":155393.56,"id":9323645}],"tv":170874.57}]}
{"op":"mcm","clk":"4217127124","pt":1631557964743,"mc":[{"id":"1.187566733","rc":[{"batb":[[0,8.2,3.66],[1,8,1.82],[2,7.8,1.82]],"batl":[[1,11.5,2.6],[2,12,1.3]],"ltp":10.0,"tv":15481.01,"id":8734382},{"batb":[[1,1.09,156.64],[2,1.08,408.02]],"batl":[[2,1.14,106.58]],"ltp":1.12,"tv":155393.56,"id":9323645}]}]}
{"op":"mcm","clk":"4217127542","pt":1631557967772,"mc":[{"id":"1.187566733","rc":[{"batb":[[1,1.09,131.03]],"batl":[[0,1.12,687.54]],"ltp":1.12,"tv":155393.56,"id":9323645}]}]}
{"op":"mcm","clk":"4217127722","pt":1631557969044,"mc":[{"id":"1.187566733","rc":[{"batb":[[0,1.11,46.94],[1,1.1,1375.24],[2,1.09,131.03]],"ltp":1.12,"tv":155393.56,"id":9323645}]}]}
{"op":"mcm","clk":"4217127796","pt":1631557969564,"mc":[{"id":"1.187566733","rc":[{"trd":[[1.12,12026.03]],"batl":[[0,1.12,636.93]],"ltp":1.12,"tv":155494.76,"id":9323645}],"tv":170975.77}]}
{"op":"mcm","clk":"4217127947","pt":1631557970666,"mc":[{"id":"1.187566733","rc":[{"batb":[[2,1.09,157.64]],"ltp":1.12,"tv":155494.76,"id":9323645}]}]}
{"op":"mcm","clk":"4217128052","pt":1631557971467,"mc":[{"id":"1.187566733","rc":[{"batb":[[0,1.11,286.64],[1,1.1,1739.49]],"batl":[[0,1.12,1084.04],[1,1.13,2952.48]],"ltp":1.12,"tv":155494.76,"id":9323645}]}]}
{"op":"mcm","clk":"4217128263","pt":1631557972978,"mc":[{"id":"1.187566733","rc":[{"trd":[[1.12,12106.03]],"batl":[[0,1.12,1044.04]],"ltp":1.12,"tv":155574.76,"id":9323645}],"tv":171055.77}]}
{"op":"mcm","clk":"4217128525","pt":1631557974880,"mc":[{"id":"1.187566733","rc":[{"batl":[[0,1.12,1755.19]],"ltp":1.12,"tv":155574.76,"id":9323645}]}]}
{"op":"mcm","clk":"4217128847","pt":1631557977252,"mc":[{"id":"1.187566733","rc":[{"trd":[[1.12,12146.03]],"batl":[[0,1.12,1735.19]],"ltp":1.12,"tv":155614.76,"id":9323645}],"tv":171095.77}]}
{"op":"mcm","clk":"4217129101","pt":1631557978993,"mc":[{"id":"1.187566733","rc":[{"trd":[[1.12,12206.03]],"batl":[[0,1.12,1705.19]],"ltp":1.12,"tv":155674.76,"id":9323645}],"tv":171155.77}]}
{"op":"mcm","clk":"4217129255","pt":1631557979992,"mc":[{"id":"1.187566733","rc":[{"batl":[[0,1.12,995.75]],"ltp":1.12,"tv":155674.76,"id":9323645}]}]}
{"op":"mcm","clk":"4217129341","pt":1631557980698,"mc":[{"id":"1.187566733","rc":[{"batb":[[1,1.1,1712.64]],"batl":[[2,1.14,108.29]],"ltp":1.12,"tv":155674.76,"id":9323645}]}]}
{"op":"mcm","clk":"4217129661","pt":1631557982968,"mc":[{"id":"1.187566733","rc":[{"batl":[[0,10,5.69],[1,11,100.34],[2,11.5,2.6]],"ltp":10.0,"tv":15481.01,"id":8734382},{"trd":[[1.11,12003.97]],"batb":[[0,1.11,283.77]],"batl":[[0,1.12,1037.72]],"ltp":1.11,"tv":155680.5,"id":9323645}],"tv":171161.51}]}
{"op":"mcm","clk":"4217129999","pt":1631557985094,"mc":[{"id":"1.187566733","rc":[{"trd":[[1.11,12043.71],[1.12,12314.45]],"batb":[[0,1.11,263.89]],"batl":[[0,1.12,983.5]],"ltp":1.12,"tv":155828.66,"id":9323645}],"tv":171309.68}]}
{"op":"mcm","clk":"4217130152","pt":1631557986092,"mc":[{"id":"1.187566733","rc":[{"batb":[[0,7.6,20.04],[1,7,18.55],[2,6.8,21.63]],"batl":[[0,12.5,2],[1,13.5,2],[2,990,0.01]],"ltp":10.0,"tv":15481.01,"id":8734382},{"batb":[[0,1.11,24.19],[1,1.1,344.94],[2,1.09,157.18]],"batl":[[0,1.12,494.42],[1,1.13,1.71],[2,1.14,1.71]],"ltp":1.12,"tv":155828.66,"id":9323645}]}]}
{"op":"mcm","clk":"4217130252","pt":1631557986688,"mc":[{"id":"1.187566733","rc":[{"batb":[[0,6.8,21.63],[1,5.9,28.62],[2,2.5,1.82]],"batl":[[0,13.5,2],[1,990,0.01],[2,990,0]],"ltp":10.0,"tv":15481.01,"id":8734382},{"batb":[[1,1.1,1.71],[2,1.09,130.57]],"batl":[[0,1.12,1.71]],"ltp":1.12,"tv":155828.66,"id":9323645}]}]}
{"op":"mcm","clk":"4217130604","pt":1631557989103,"mc":[{"id":"1.187566733","rc":[{"batb":[[2,1.09,742.27]],"batl":[[0,1.12,48.64]],"ltp":1.12,"tv":155828.66,"id":9323645}]}]}
{"op":"mcm","clk":"4217130771","pt":1631557990122,"mc":[{"id":"1.187566733","rc":[{"batb":[[0,7.6,22.29],[1,6.8,21.63],[2,5.9,28.62]],"ltp":10.0,"tv":15481.01,"id":8734382},{"batb":[[2,1.09,130.57]],"ltp":1.12,"tv":155828.66,"id":9323645}]}]}
{"op":"mcm","clk":"4217130807","pt":1631557990336,"mc":[{"id":"1.187566733","rc":[{"batb":[[0,6.8,21.63],[1,5.9,28.62],[2,2.5,1.82]],"ltp":10.0,"tv":15481.01,"id":8734382}]}]}
{"op":"mcm","clk":"4217130970","pt":1631557991300,"mc":[{"id":"1.187566733","rc":[{"batl":[[0,1.12,1.71]],"ltp":1.12,"tv":155828.66,"id":9323645}]}]}
{"op":"mcm","clk":"4217131260","pt":1631557993195,"mc":[{"id":"1.187566733","rc":[{"batb":[[0,9.2,21.47],[1,6.8,21.63],[2,5.9,28.62]],"ltp":10.0,"tv":15481.01,"id":8734382},{"trd":[[1.11,12055.06]],"batb":[[0,1.11,595]],"batl":[[0,1.12,21.67],[1,1.13,591.75]],"ltp":1.11,"tv":155840.01,"id":9323645}],"tv":171321.02}]}
{"op":"mcm","clk":"4217131308","pt":1631557993502,"mc":[{"id":"1.187566733","rc":[{"batb":[[0,7.6,22.14]],"batl":[[0,12.5,2],[1,13.5,2],[2,990,0.01]],"ltp":10.0,"tv":15481.01,"id":8734382},{"batb":[[2,1.09,158.18]],"batl":[[0,1.12,1.71]],"ltp":1.11,"tv":155840.01,"id":9323645}]}]}
{"op":"mcm","clk":"4217131912","pt":1631557997198,"mc":[{"id":"1.187566733","rc":[{"trd":[[8.6,124.32],[9.2,60.22]],"ltp":8.6,"tv":15481.46,"id":8734382},{"trd":[[1.12,12316.16],[1.13,3035]],"batb":[[0,1.11,311.49]],"batl":[[0,1.14,1.71],[1,1.15,1263.47],[2,1.16,1225.8]],"ltp":1.13,"tv":155843.54,"id":9323645}],"tv":171325.0}]}
{"op":"mcm","clk":"4217131940","pt":1631557997409,"mc":[{"id":"1.187566733","rc":[{"batb":[[0,6.8,21.63],[1,5.9,28.62],[2,2.5,1.82]],"ltp":8.6,"tv":15481.46,"id":8734382},{"batl":[[1,1.15,1.71],[2,1.16,1.71]],"ltp":1.13,"tv":155843.54,"id":9323645}]}]}
{"op":"mcm","clk":"4217132177","pt":1631557999005,"mc":[{"id":"1.187566733","rc":[{"batb":[[0,1.12,2.56],[1,1.11,311.49],[2,1.1,1.71]],"ltp":1.13,"tv":155843.54,"id":9323645}]}]}
{"op":"mcm","clk":"4217132355","pt":1631558000210,"mc":[{"id":"1.187566733","rc":[{"batl":[[1,1.15,349.77],[2,1.16,231.43]],"ltp":1.13,"tv":155843.54,"id":9323645}]}]}
{"op":"mcm","clk":"4217132972","pt":1631558004097,"mc":[{"id":"1.187566733","rc":[{"batb":[[0,7.6,21.34],[1,6.8,21.63],[2,5.9,28.62]],"ltp":8.6,"tv":15481.46,"id":8734382},{"batl":[[1,1.15,1551.68]],"ltp":1.13,"tv":155843.54,"id":9323645}]}]}
{"op":"mcm","clk":"4217133140","pt":1631558005107,"mc":[{"id":"1.187566733","rc":[{"batb":[[0,6.8,21.63],[1,5.9,28.62],[2,2.5,1.82]],"batl":[[2,1000,2.01]],"ltp":8.6,"tv":15481.46,"id":8734382},{"trd":[[1.13,3055]],"batb":[[0,1.11,305.27],[1,1.1,1.71],[2,1.09,769.88]],"batl":[[1,1.15,349.77],[2,1.16,1362.97]],"ltp":1.13,"tv":155863.55,"id":9323645}],"tv":171345.01}]}
{"op":"mcm","clk":"4217133280","pt":1631558005996,"mc":[{"id":"1.187566733","rc":[{"batl":[[2,1000,0.41]],"ltp":8.6,"tv":15481.46,"id":8734382},{"batl":[[0,1.12,1.71],[1,1.14,1.71],[2,1.15,349.77]],"ltp":1.13,"tv":155863.55,"id":9323645}]}]}
{"op":"mcm","clk":"4217133591","pt":1631558008150,"mc":[{"id":"1.187566733","rc":[{"batl":[[0,12.5,2.8],[2,1000,2.01]],"ltp":8.6,"tv":15481.46,"id":8734382},{"trd":[[1.12,12319.58],[1.14,815.99],[1.15,49.16]],"batl":[[0,1.15,325.19],[1,1.16,1362.97],[2,1.17,996.21]],"ltp":1.15,"tv":155919.54,"id":9323645}],"tv":171401.0}]}
{"op":"mcm","clk":"4217133675","pt":1631558008625,"mc":[{"id":"1.187566733","rc":[{"batl":[[0,9.6,1.2],[1,12.5,2],[2,13.5,2]],"ltp":8.6,"tv":15481.46,"id":8734382}]}]}
{"op":"mcm","clk":"4217133897","pt":1631558010008,"mc":[{"id":"1.187566733","rc":[{"batl":[[0,9.4,1.2],[1,12.5,2.8]],"ltp":8.6,"tv":15481.46,"id":8734382}]}]}
{"op":"mcm","clk":"4217134056","pt":1631558011115,"mc":[{"id":"1.187566733","rc":[{"batb":[[0,7.6,21.89],[1,6.8,21.63],[2,5.9,28.62]],"batl":[[0,9.2,1.2],[1,10,1.2],[2,12.5,2]],"ltp":8.6,"tv":15481.46,"id":8734382},{"batl":[[0,1.15,1654.7],[1,1.16,1375.5]],"ltp":1.15,"tv":155919.54,"id":9323645}]}]}
{"op":"mcm","clk":"4217134143","pt":1631558011738,"mc":[{"id":"1.187566733","rc":[{"batb":[[0,6.8,21.63],[1,5.9,28.62],[2,2.5,1.82]],"batl":[[1,9.6,1.2],[2,12.5,2.4]],"ltp":8.6,"tv":15481.46,"id":8734382},{"batl":[[0,1.15,325.19]],"ltp":1.15,"tv":155919.54,"id":9323645}]}]}
{"op":"mcm","clk":"4217134283","pt":1631558012735,"mc":[{"id":"1.187566733","rc":[{"trd":[[1.15,65.16]],"batb":[[2,1.09,158.18]],"batl":[[0,1.15,317.19]],"ltp":1.15,"tv":155935.54,"id":9323645}],"tv":171417.0}]}
{"op":"mcm","clk":"4217134471","pt":1631558014120,"mc":[{"id":"1.187566733","rc":[{"trd":[[8.6,124.72],[9.2,61.02]],"batl":[[0,9.6,1.2],[1,12.5,2.4],[2,13.5,2]],"ltp":9.2,"tv":15482.66,"id":8734382},{"trd":[[1.12,12326.15],[1.13,3058.04]],"batb":[[0,1.11,296.12]],"ltp":1.12,"tv":155945.15,"id":9323645}],"tv":171427.81}]}
{"op":"mcm","clk":"4217134755","pt":1631558016021,"mc":[{"id":"1.187566733","rc":[{"batl":[[0,8.6,26.74],[1,8.8,3.74],[2,9,1.74]],"ltp":9.2,"tv":15482.66,"id":8734382},{"trd":[[1.12,12329.56],[1.15,184.4]],"batb":[[0,1.14,177.8],[1,1.13,769.42],[2,1.11,296.12]],"batl":[[0,1.15,308.8],[1,1.16,3579.49]],"ltp":1.15,"tv":156067.82,"id":9323645}],"tv":171550.48}]}
{"op":"mcm","clk":"4217134901","pt":1631558016915,"mc":[{"id":"1.187566733","rc":[{"batb":[[0,7.2,4.16],[1,7,2.08],[2,6.8,23.71]],"ltp":9.2,"tv":15482.66,"id":8734382},{"batb":[[0,1.14,440.47],[2,1.11,619.54]],"batl":[[2,1.17,996.64]],"ltp":1.15,"tv":156067.82,"id":9323645}]}]}
{"op":"mcm","clk":"4217135222","pt":1631558019024,"mc":[{"id":"1.187566733","rc":[{"batb":[[0,1.14,478.49]],"batl":[[0,1.15,335.45],[1,1.16,3616.56]],"ltp":1.15,"tv":156067.82,"id":9323645}]}]}
{"op":"mcm","clk":"4217135346","pt":1631558019936,"mc":[{"id":"1.187566733","rc":[{"trd":[[1.15,199.82]],"batl":[[0,1.15,737.63]],"ltp":1.15,"tv":156083.23,"id":9323645}],"tv":171565.89}]}
{"op":"mcm","clk":"4217135490","pt":1631558020920,"mc":[{"id":"1.187566733","rc":[{"trd":[[1.15,403.82]],"batl":[[0,1.15,635.63]],"ltp":1.15,"tv":156287.23,"id":9323645}],"tv":171769.89}]}
{"op":"mcm","clk":"4217135646","pt":1631558022127,"mc":[{"id":"1.187566733","rc":[{"trd":[[1.14,819.71]],"batb":[[0,1.14,476.63],[1,1.13,707.17]],"ltp":1.14,"tv":156290.95,"id":9323645}],"tv":171773.61}]}
{"op":"mcm","clk":"4217135684","pt":1631558022432,"mc":[{"id":"1.187566733","rc":[{"trd":[[1.15,432.83]],"batb":[[2,1.11,641.13]],"batl":[[0,1.15,621.12]],"ltp":1.15,"tv":156319.97,"id":9323645}],"tv":171802.63}]}
{"op":"mcm","clk":"4217135898","pt":1631558023963,"mc":[{"id":"1.187566733","rc":[{"batb":[[0,1.14,903.32]],"batl":[[0,1.15,818.12]],"ltp":1.15,"tv":156319.97,"id":9323645}]}]}
{"op":"mcm","clk":"4217136079","pt":1631558025145,"mc":[{"id":"1.187566733","rc":[{"trd":[[1.14,823.13]],"batb":[[0,1.14,963.31]],"batl":[[0,1.15,867.17],[1,1.16,3676.7]],"ltp":1.14,"tv":156323.38,"id":9323645}],"tv":171806.04}]}
{"op":"mcm","clk":"4217136332","pt":1631558026838,"mc":[{"id":"1.187566733","rc":[{"batl":[[0,1.15,868.88]],"ltp":1.14,"tv":156323.38,"id":9323645}]}]}
{"op":"mcm","clk":"4217136569","pt":1631558028151,"mc":[{"id":"1.187566733","rc":[{"trd":[[1.15,480.83]],"batb":[[1,1.13,375.06]],"batl":[[0,1.15,844.88]],"ltp":1.15,"tv":156371.38,"id":9323645}],"tv":171854.04}]}
{"op":"mcm","clk":"4217136692","pt":1631558029076,"mc":[{"id":"1.187566733","rc":[{"trd":[[1.15,520.83]],"batl":[[0,1.15,824.88]],"ltp":1.15,"tv":156411.38,"id":9323645}],"tv":171894.04}]}
{"op":"mcm","clk":"4217136860","pt":1631558029939,"mc":[{"id":"1.187566733","rc":[{"batb":[[1,1.13,363.71]],"ltp":1.15,"tv":156411.38,"id":9323645}]}]}
{"op":"mcm","clk":"4217137057","pt":1631558031141,"mc":[{"id":"1.187566733","rc":[{"batb":[[0,1.14,984.97]],"batl":[[0,1.15,842.1],[1,1.16,3697.81]],"ltp":1.15,"tv":156411.38,"id":9323645}]}]}
{"op":"mcm","clk":"4217137174","pt":1631558032037,"mc":[{"id":"1.187566733","rc":[{"trd":[[1.15,616.25]],"batl":[[0,1.15,794.38]],"ltp":1.15,"tv":156506.8,"id":9323645}],"tv":171989.46}]}
{"op":"mcm","clk":"4217137365","pt":1631558033037,"mc":[{"id":"1.187566733","rc":[{"trd":[[1.15,691.34]],"batb":[[0,1.14,957.63],[1,1.13,289.19]],"batl":[[0,1.15,719.42],[1,1.16,3708.77]],"ltp":1.15,"tv":156581.89,"id":9323645}],"tv":172064.55}]}
{"op":"mcm","clk":"4217137506","pt":1631558034044,"mc":[{"id":"1.187566733","rc":[{"trd":[[1.15,742.91]],"batb":[[1,1.13,274.55],[2,1.12,47.79]],"batl":[[0,1.15,693.63]],"ltp":1.15,"tv":156633.46,"id":9323645}],"tv":172116.12}]}
{"op":"mcm","clk":"4217137713","pt":1631558035155,"mc":[{"id":"1.187566733","rc":[{"batb":[[0,6,27.67],[1,5.9,28.62],[2,5.5,28.76]],"batl":[[0,8.8,2],[1,9.6,1.2],[2,10.5,2.4]],"ltp":9.2,"tv":15482.66,"id":8734382},{"batb":[[0,1.14,689.36],[1,1.13,17.73]],"batl":[[0,1.15,198.71],[1,1.16,1.71],[2,1.17,1.71]],"ltp":1.15,"tv":156633.46,"id":9323645}]}]}
{"op":"mcm","clk":"4217137852","pt":1631558036054,"mc":[{"id":"1.187566733","rc":[{"batb":[[0,5.5,28.76],[1,4.8,23.16],[2,2.6,1.2]],"ltp":9.2,"tv":15482.66,"id":8734382},{"batb":[[0,1.14,447.8]],"batl":[[0,1.15,18.49],[1,1.16,22.28]],"ltp":1.15,"tv":156633.46,"id":9323645}]}]}
{"op":"mcm","clk":"4217137996","pt":1631558037051,"mc":[{"id":"1.187566733","rc":[{"batb":[[0,1.14,441.2]],"batl":[[0,1.15,13.24],[1,1.16,15.85]],"ltp":1.15,"tv":156633.46,"id":9323645}]}]}
{"op":"mcm","clk":"4217138112","pt":1631558037948,"mc":[{"id":"1.187566733","rc":[{"batb":[[0,1.14,426.69]],"batl":[[0,1.15,1.71],[1,1.16,1.71]],"ltp":1.15,"tv":156633.46,"id":9323645}]}]}
{"op":"mcm","clk":"4217138211","pt":1631558038692,"mc":[{"id":"1.187566733","rc":[{"trd":[[7.6,0.26]],"batb":[[0,6,24.67],[1,5.5,28.76],[2,4.8,23.16]],"batl":[[0,7.6,4.8],[1,8.8,2],[2,9.6,1.2]],"ltp":7.6,"tv":15482.92,"id":8734382},{"trd":[[1.15,744.62]],"batl":[[0,1.16,1.71],[1,1.17,1.71],[2,1.18,1.71]],"ltp":1.15,"tv":156635.17,"id":9323645}],"tv":172118.09}]}
{"op":"mcm","clk":"4217138372","pt":1631558039750,"mc":[{"id":"1.187566733","rc":[{"batb":[[0,1.15,18.54],[1,1.14,426.69],[2,1.13,17.73]],"ltp":1.15,"tv":156635.17,"id":9323645}]}]}
{"op":"mcm","clk":"4217138595","pt":1631558041282,"mc":[{"id":"1.187566733","rc":[{"batb":[[0,1.14,426.69],[1,1.13,17.73],[2,1.12,47.79]],"ltp":1.15,"tv":156635.17,"id":9323645}]}]}
{"op":"mcm","clk":"4217138844","pt":1631558043065,"mc":[{"id":"1.187566733","rc":[{"batl":[[1,9.6,1.2],[2,10.5,2.4]],"ltp":7.6,"tv":15482.92,"id":8734382},{"batb":[[0,1.15,40],[1,1.14,426.69]],"ltp":1.15,"tv":156635.17,"id":9323645}]}]}
{"op":"mcm","clk":"4217139309","pt":1631558046183,"mc":[{"id":"1.187566733","rc":[{"trd":[[6,3.78],[6.2,0.33]],"batb":[[0,6,27.67]],"batl":[[0,6.4,37.4],[1,6.6,24.72],[2,6.8,11.36]],"ltp":6.0,"tv":15487.03,"id":8734382},{"trd":[[1.18,3.42],[1.19,1.71]],"batb":[[0,1.18,3801.36],[1,1.17,2.98],[2,1.15,40]],"batl":[[0,1.2,1468.5],[1,1.21,3247.07],[2,1.22,1050.49]],"ltp":1.19,"tv":156640.29,"id":9323645}],"tv":172127.32}]}
{"op":"mcm","clk":"4217139435","pt":1631558047148,"mc":[{"id":"1.187566733","rc":[{"batb":[[0,6,4.89],[1,5.8,25.86],[2,5.7,12.92]],"batl":[[1,6.6,6.54],[2,6.8,2.28]],"ltp":6.0,"tv":15487.03,"id":8734382},{"trd":[[1.2,2486.22]],"batb":[[0,1.19,215.41],[1,1.18,718.58],[2,1.17,138.51]],"batl":[[0,1.2,330.72],[1,1.21,3249.13]],"ltp":1.2,"tv":156737.92,"id":9323645}],"tv":172224.95}]}
{"op":"mcm","clk":"4217139559","pt":1631558047985,"mc":[{"id":"1.187566733","rc":[{"batb":[[1,5.8,5.18],[2,5.7,2.58]],"ltp":6.0,"tv":15487.03,"id":8734382},{"batb":[[2,1.17,158.51]],"batl":[[1,1.21,3247.48]],"ltp":1.2,"tv":156737.92,"id":9323645}]}]}
{"op":"mcm","clk":"4217139619","pt":1631558048361,"mc":[{"id":"1.187566733","rc":[{"batb":[[2,1.17,157.66]],"ltp":1.2,"tv":156737.92,"id":9323645}]}]}
{"op":"mcm","clk":"4217139822","pt":1631558049888,"mc":[{"id":"1.187566733","rc":[{"batb":[[1,1.18,746.46]],"batl":[[0,1.2,352.53],[1,1.21,3274.25]],"ltp":1.2,"tv":156737.92,"id":9323645}]}]}
{"op":"mcm","clk":"4217139985","pt":1631558051060,"mc":[{"id":"1.187566733","rc":[{"trd":[[6,10.1]],"batb":[[0,6,1.73]],"ltp":6.0,"tv":15493.35,"id":8734382},{"batl":[[0,1.2,755.4]],"ltp":1.2,"tv":156737.92,"id":9323645}],"tv":172231.27}]}
{"op":"mcm","clk":"4217140062","pt":1631558051682,"mc":[{"id":"1.187566733","rc":[{"batb":[[1,1.18,317.49],[2,1.15,231.29]],"batl":[[0,1.2,596.32],[1,1.21,3048.59]],"ltp":1.2,"tv":156737.92,"id":9323645}]}]}
{"op":"mcm","clk":"4217140258","pt":1631558053156,"mc":[{"id":"1.187566733","rc":[{"trd":[[6,15.61]],"batb":[[0,5.8,5.18],[1,5.7,2.58],[2,5.6,2.58]],"ltp":6.0,"tv":15498.86,"id":8734382},{"trd":[[1.2,2496.46]],"batb":[[2,1.15,247.12]],"batl":[[0,1.2,586.08]],"ltp":1.2,"tv":156748.16,"id":9323645}],"tv":172247.02}]}
{"op":"mcm","clk":"4217140464","pt":1631558054773,"mc":[{"id":"1.187566733","rc":[{"trd":[[6,36.95]],"ltp":6.0,"tv":15520.19,"id":8734382},{"trd":[[1.2,2603.12]],"batl":[[0,1.2,479.42],[1,1.21,3420.36]],"ltp":1.2,"tv":156854.82,"id":9323645}],"tv":172375.02}]}
{"op":"mcm","clk":"4217140731","pt":1631558057087,"mc":[{"id":"1.187566733","rc":[{"trd":[[1.2,2643.12]],"batb":[[0,1.19,347.68]],"batl":[[0,1.2,459.42]],"ltp":1.2,"tv":156894.82,"id":9323645}],"tv":172415.02}]}
{"op":"mcm","clk":"4217140840","pt":1631558057979,"mc":[{"id":"1.187566733","rc":[{"trd":[[6,68.57]],"ltp":6.0,"tv":15551.82,"id":8734382},{"trd":[[1.2,2801.23]],"batb":[[1,1.18,145.14]],"batl":[[0,1.2,728]],"ltp":1.2,"tv":157052.93,"id":9323645}],"tv":172604.75}]}
{"op":"mcm","clk":"4217140958","pt":1631558058870,"mc":[{"id":"1.187566733","rc":[{"trd":[[1.2,2878.78]],"batl":[[0,1.2,689.23]],"ltp":1.2,"tv":157130.48,"id":9323645}],"tv":172682.3}]}
{"op":"mcm","clk":"4217141018","pt":1631558059396,"mc":[{"id":"1.187566733","rc":[{"trd":[[1.19,300.27],[1.2,2996.32]],"batb":[[0,1.19,198.38]],"batl":[[0,1.2,630.46]],"ltp":1.2,"tv":157546.58,"id":9323645}],"tv":173098.4}]}
{"op":"mcm","clk":"4217141258","pt":1631558061074,"mc":[{"id":"1.187566733","rc":[{"batl":[[0,6.4,31.24]],"ltp":6.0,"tv":15551.82,"id":8734382},{"trd":[[1.2,3065.71]],"batl":[[0,1.2,595.76]],"ltp":1.2,"tv":157615.97,"id":9323645}],"tv":173167.79}]}
{"op":"mcm","clk":"4217141373","pt":1631558061965,"mc":[{"id":"1.187566733","rc":[{"batb":[[0,1.19,272.37],[2,1.17,132.71]],"ltp":1.2,"tv":157615.97,"id":9323645}]}]}
{"op":"mcm","clk":"4217141659","pt":1631558064071,"mc":[{"id":"1.187566733","rc":[{"batl":[[0,6.2,8.01],[1,6.4,31.24],[2,6.6,6.54]],"ltp":6.0,"tv":15551.82,"id":8734382},{"batl":[[1,1.21,3469.93]],"ltp":1.2,"tv":157615.97,"id":9323645}]}]}
{"op":"mcm","clk":"4217141679","pt":1631558064281,"mc":[{"id":"1.187566733","rc":[{"batl":[[0,6.4,31.24],[1,6.6,6.54],[2,6.8,2.28]],"ltp":6.0,"tv":15551.82,"id":8734382},{"batl":[[1,1.21,3420.36]],"ltp":1.2,"tv":157615.97,"id":9323645}]}]}
{"op":"mcm","clk":"4217142026","pt":1631558067180,"mc":[{"id":"1.187566733","rc":[{"batl":[[0,6.2,8.01],[1,6.4,31.24],[2,6.6,6.54]],"ltp":6.0,"tv":15551.82,"id":8734382},{"batl":[[0,1.2,645.26],[1,1.21,3469.93]],"ltp":1.2,"tv":157615.97,"id":9323645}]}]}
{"op":"mcm","clk":"4217142127","pt":1631558068119,"mc":[{"id":"1.187566733","rc":[{"trd":[[6,72.91]],"batl":[[0,6.4,31.24],[1,6.6,6.54],[2,6.8,2.28]],"ltp":6.0,"tv":15556.15,"id":8734382},{"trd":[[1.19,300.64],[1.2,3087.4]],"batb":[[0,1.19,272.18]],"batl":[[0,1.2,623.57],[1,1.21,3420.36]],"ltp":1.2,"tv":157638.03,"id":9323645}],"tv":173194.19}]}
{"op":"mcm","clk":"4217142498","pt":1631558070912,"mc":[{"id":"1.187566733","rc":[{"batb":[[0,4.8,56.24],[1,4.4,33.01],[2,4,35.92]],"batl":[[0,6.6,2],[1,7.8,2],[2,8.8,2]],"ltp":6.0,"tv":15556.15,"id":8734382},{"batb":[[2,1.17,132.28]],"batl":[[1,1.21,371.77],[2,1.23,1.45]],"ltp":1.2,"tv":157638.03,"id":9323645}]}]}
{"op":"mcm","clk":"4217142592","pt":1631558071589,"mc":[{"id":"1.187566733","rc":[{"batb":[[0,4.8,33.08]],"batl":[[1,8.8,2],[2,9.6,1.2]],"ltp":6.0,"tv":15556.15,"id":8734382},{"batb":[[0,1.19,132.28]],"batl":[[0,1.2,476.19],[1,1.23,1.45],[2,1.26,1124.72]],"ltp":1.2,"tv":157638.03,"id":9323645}]}]}
{"op":"mcm","clk":"4217142921","pt":1631558074206,"mc":[{"id":"1.187566733","rc":[{"batb":[[2,4.1,34.07]],"batl":[[0,8.8,2],[1,9.6,1.2],[2,990,0.41]],"ltp":6.0,"tv":15556.15,"id":8734382},{"batb":[[1,1.18,132.28]],"ltp":1.2,"tv":157638.03,"id":9323645}]}]}
{"op":"mcm","clk":"4217143054","pt":1631558075210,"mc":[{"id":"1.187566733","rc":[{"batb":[[0,4.4,33.01],[1,4.1,34.07],[2,2.6,1.2]],"ltp":6.0,"tv":15556.15,"id":8734382},{"batl":[[0,1.23,1.45],[1,1.29,1145.75],[2,1.3,9.06]],"ltp":1.2,"tv":157638.03,"id":9323645}]}]}
{"op":"mcm","clk":"4217143467","pt":1631558078135,"mc":[{"id":"1.187566733","rc":[{"batl":[[0,7.8,2],[1,8.8,2],[2,9.6,1.2]],"ltp":6.0,"tv":15556.15,"id":8734382},{"batb":[[0,1.2,37.55],[1,1.19,132.28],[2,1.18,132.28]],"ltp":1.2,"tv":157638.03,"id":9323645}]}]}
{"op":"mcm","clk":"4217143499","pt":1631558078395,"mc":[{"id":"1.187566733","rc":[{"batl":[[0,8.8,2],[1,9.6,1.2],[2,990,0.41]],"ltp":6.0,"tv":15556.15,"id":8734382}]}]}
{"op":"mcm","clk":"4217143732","pt":1631558079931,"mc":[{"id":"1.187566733","rc":[{"trd":[[4.4,20.02],[5.3,0.34]],"batb":[[0,4.4,30.34]],"batl":[[0,4.8,25],[1,5,4.43],[2,5.2,2]],"ltp":4.4,"tv":15561.83,"id":8734382},{"trd":[[1.2,3090.82],[1.23,1.45],[1.27,93.01]],"batb":[[0,1.25,41.34],[1,1.24,9.52],[2,1.2,36.25]],"batl":[[0,1.27,1622.75]],"ltp":1.27,"tv":157735.9,"id":9323645}],"tv":173297.74}]}
{"op":"mcm","clk":"4217143889","pt":1631558081032,"mc":[{"id":"1.187566733","rc":[{"trd":[[4.8,0.45]],"batb":[[0,4.6,6.52],[1,4.5,3.26],[2,4.4,33.6]],"batl":[[0,4.8,24.55]],"ltp":4.8,"tv":15562.28,"id":8734382},{"trd":[[1.26,1.71]],"batb":[[1,1.24,156.29],[2,1.2,181.09]],"ltp":1.26,"tv":157737.61,"id":9323645}],"tv":173299.9}]}
{"op":"mcm","clk":"4217144327","pt":1631558084121,"mc":[{"id":"1.187566733","rc":[{"trd":[[1.27,119.67]],"batl":[[0,1.27,1609.42]],"ltp":1.27,"tv":157764.27,"id":9323645}],"tv":173326.56}]}
{"op":"mcm","clk":"4217144423","pt":1631558084816,"mc":[{"id":"1.187566733","rc":[{"batb":[[0,1.25,43.05],[1,1.24,158]],"batl":[[1,1.28,1.71],[2,1.29,1147.46]],"ltp":1.27,"tv":157764.27,"id":9323645}]}]}
{"op":"mcm","clk":"4217144524","pt":1631558085499,"mc":[{"id":"1.187566733","rc":[{"trd":[[4.8,1.46]],"batl":[[0,4.8,23.54]],"ltp":4.8,"tv":15563.29,"id":8734382},{"trd":[[1.26,5.55]],"ltp":1.26,"tv":157768.11,"id":9323645}],"tv":173331.41}]}
{"op":"mcm","clk":"4217144692","pt":1631558086805,"mc":[{"id":"1.187566733","rc":[{"trd":[[4.8,9.3]],"batl":[[0,4.8,15.7]],"ltp":4.8,"tv":15571.13,"id":8734382},{"trd":[[1.26,35.42],[1.27,163.74]],"batl":[[0,1.27,1587.39]],"ltp":1.26,"tv":157842.04,"id":9323645}],"tv":173413.18}]}
{"op":"mcm","clk":"4217144826","pt":1631558087907,"mc":[{"id":"1.187566733","rc":[{"trd":[[4.8,9.75]],"batl":[[0,4.8,15.25]],"ltp":4.8,"tv":15571.58,"id":8734382},{"trd":[[1.26,37.12],[1.27,207.8]],"batb":[[0,1.25,165.06]],"batl":[[0,1.27,1982.53]],"ltp":1.26,"tv":157887.81,"id":9323645}],"tv":173459.4}]}
{"op":"mcm","clk":"4217144948","pt":1631558088811,"mc":[{"id":"1.187566733","rc":[{"trd":[[4.8,10.2]],"batl":[[0,4.8,14.8]],"ltp":4.8,"tv":15572.03,"id":8734382},{"trd":[[1.26,38.83],[1.27,248.31]],"batl":[[0,1.27,1962.28]],"ltp":1.27,"tv":157930.03,"id":9323645}],"tv":173502.07}]}
{"op":"mcm","clk":"4217145066","pt":1631558089820,"mc":[{"id":"1.187566733","rc":[{"trd":[[1.27,302.68]],"batl":[[0,1.27,1935.1]],"ltp":1.27,"tv":157984.4,"id":9323645}],"tv":173556.44}]}
{"op":"mcm","clk":"4217145205","pt":1631558090827,"mc":[{"id":"1.187566733","rc":[{"trd":[[1.27,332.68]],"batl":[[0,1.27,1920.1]],"ltp":1.27,"tv":158014.4,"id":9323645}],"tv":173586.44}]}
{"op":"mcm","clk":"4217145388","pt":1631558092126,"mc":[{"id":"1.187566733","rc":[{"trd":[[4.7,10]],"ltp":4.7,"tv":15582.03,"id":8734382},{"trd":[[1.27,499.15]],"batl":[[0,1.27,1818.37]],"ltp":1.27,"tv":158180.87,"id":9323645}],"tv":173762.91}]}
{"op":"mcm","clk":"4217145599","pt":1631558093821,"mc":[{"id":"1.187566733","rc":[{"trd":[[1.27,526.33]],"batl":[[0,1.27,1804.78]],"ltp":1.27,"tv":158208.05,"id":9323645}],"tv":173790.09}]}
{"op":"mcm","clk":"4217145804","pt":1631558095334,"mc":[{"id":"1.187566733","rc":[{"trd":[[1.27,553.52]],"batl":[[0,1.27,1791.19]],"ltp":1.27,"tv":158235.24,"id":9323645}],"tv":173817.27}]}
{"op":"mcm","clk":"4217146190","pt":1631558098115,"mc":[{"id":"1.187566733","rc":[{"trd":[[1.27,668.69]],"batl":[[0,1.27,1733.59]],"ltp":1.27,"tv":158350.41,"id":9323645}],"tv":173932.45}]}
{"op":"mcm","clk":"4217146535","pt":1631558100849,"mc":[{"id":"1.187566733","rc":[{"trd":[[4.7,10.85]],"batb":[[0,4.7,84.91],[1,4.6,6.52],[2,4.5,3.26]],"ltp":4.7,"tv":15582.88,"id":8734382}],"tv":173933.3}]}
{"op":"mcm","clk":"4217147029","pt":1631558104147,"mc":[{"id":"1.187566733","rc":[{"trd":[[1.27,866.54]],"batl":[[0,1.27,1634.68]],"ltp":1.27,"tv":158548.26,"id":9323645}],"tv":174131.15}]}
{"op":"mcm","clk":"4217147164","pt":1631558105047,"mc":[{"id":"1.187566733","rc":[{"trd":[[4.7,14.85]],"batb":[[0,4.7,82.92]],"ltp":4.7,"tv":15586.88,"id":8734382},{"trd":[[1.27,879.86]],"batl":[[0,1.27,1628.02]],"ltp":1.27,"tv":158561.58,"id":9323645}],"tv":174148.47}]}
{"op":"mcm","clk":"4217147344","pt":1631558106160,"mc":[{"id":"1.187566733","rc":[{"trd":[[4.7,40.45]],"batb":[[0,4.7,70.11]],"ltp":4.7,"tv":15612.48,"id":8734382}],"tv":174174.07}]}
{"op":"mcm","clk":"4217147911","pt":1631558109926,"mc":[{"id":"1.187566733","rc":[{"trd":[[1.27,907.05]],"batl":[[0,1.27,1614.43]],"ltp":1.27,"tv":158588.77,"id":9323645}],"tv":174201.25}]}
{"op":"mcm","clk":"4217148061","pt":1631558110936,"mc":[{"id":"1.187566733","rc":[{"trd":[[4.7,50.57]],"batb":[[0,4.7,65.05]],"ltp":4.7,"tv":15622.6,"id":8734382},{"trd":[[1.27,1004.23]],"batb":[[0,1.25,19.42],[1,1.24,11.23],[2,1.23,0.41]],"batl":[[0,1.27,132.41]],"ltp":1.27,"tv":158685.95,"id":9323645}],"tv":174308.56}]}
{"op":"mcm","clk":"4217148199","pt":1631558111841,"mc":[{"id":"1.187566733","rc":[{"trd":[[4.7,51.91]],"batb":[[0,4.7,64.38]],"ltp":4.7,"tv":15623.95,"id":8734382},{"batl":[[0,1.27,3.41]],"ltp":1.27,"tv":158685.95,"id":9323645}],"tv":174309.9}]}
{"op":"mcm","clk":"4217149206","pt":1631558119344,"mc":[{"id":"1.187566733","rc":[{"trd":[[4.7,102.27]],"batb":[[0,4.7,14.02]],"ltp":4.7,"tv":15674.31,"id":8734382},{"trd":[[1.27,1011.05],[1.28,188.31]],"batl":[[0,1.29,1147.46],[1,1.3,9.06],[2,1.45,6.9]],"ltp":1.28,"tv":158881.08,"id":9323645}],"tv":174555.39}]}
{"op":"mcm","clk":"4217149470","pt":1631558121346,"mc":[{"id":"1.187566733","rc":[{"batl":[[1,5.2,2],[2,5.3,5.66]],"ltp":4.7,"tv":15674.31,"id":8734382},{"batb":[[0,1.27,4],[1,1.25,1.71],[2,1.24,11.23]],"ltp":1.28,"tv":158881.08,"id":9323645}]}]}
{"op":"mcm","clk":"4217149690","pt":1631558122873,"mc":[{"id":"1.187566733","rc":[{"batb":[[0,4.6,6.52],[1,4.5,3.26],[2,4.4,33.6]],"ltp":4.7,"tv":15674.31,"id":8734382}]}]}
{"op":"mcm","clk":"4217149856","pt":1631558123982,"mc":[{"id":"1.187566733","rc":[{"trd":[[4.6,5.53]],"batb":[[0,4.5,4.25],[1,4.4,33.6],[2,2.6,1.2]],"ltp":4.6,"tv":15679.84,"id":8734382},{"trd":[[1.28,208.19]],"ltp":1.28,"tv":158900.96,"id":9323645}],"tv":174580.8}]}
{"op":"mcm","clk":"4217149909","pt":1631558124358,"mc":[{"id":"1.187566733","rc":[{"batl":[[0,4.8,21.2]],"ltp":4.6,"tv":15679.84,"id":8734382},{"batl":[[0,1.28,33.42],[1,1.29,1147.46],[2,1.3,9.06]],"ltp":1.28,"tv":158900.96,"id":9323645}]}]}
{"op":"mcm","clk":"4217150358","pt":1631558127786,"mc":[{"id":"1.187566733","rc":[{"batb":[[0,1.27,11.23]],"ltp":1.28,"tv":158900.96,"id":9323645}]}]}
{"op":"mcm","clk":"4217150624","pt":1631558129720,"mc":[{"id":"1.187566733","rc":[{"batl":[[0,4.8,14.8]],"ltp":4.6,"tv":15679.84,"id":8734382},{"batb":[[1,1.24,9.52],[2,1.23,0.41]],"batl":[[0,1.29,1145.75],[1,1.3,9.06],[2,1.45,6.9]],"ltp":1.28,"tv":158900.96,"id":9323645}]}]}
{"op":"mcm","clk":"4217151079","pt":1631558132987,"mc":[{"id":"1.187566733","rc":[{"trd":[[4.6,5.71]],"batb":[[0,4.5,4.16]],"batl":[[0,4.8,21.2]],"ltp":4.6,"tv":15680.02,"id":8734382},{"batl":[[0,1.28,109.61],[1,1.29,1145.75],[2,1.3,9.06]],"ltp":1.28,"tv":158900.96,"id":9323645}],"tv":174580.98}]}
{"op":"mcm","clk":"4217151360","pt":1631558134881,"mc":[{"id":"1.187566733","rc":[{"trd":[[1.28,213.97]],"batl":[[0,1.28,106.72]],"ltp":1.28,"tv":158906.74,"id":9323645}],"tv":174586.76}]}
{"op":"mcm","clk":"4217151483","pt":1631558135778,"mc":[{"id":"1.187566733","rc":[{"batl":[[0,1.28,30.53]],"ltp":1.28,"tv":158906.74,"id":9323645}]}]}
{"op":"mcm","clk":"4217151983","pt":1631558139382,"mc":[{"id":"1.187566733","rc":[{"batl":[[0,4.7,19.39],[1,4.8,21.2],[2,5.2,2]],"ltp":4.6,"tv":15680.02,"id":8734382}]}]}
{"op":"mcm","clk":"4217152356","pt":1631558142101,"mc":[{"id":"1.187566733","rc":[{"trd":[[4.6,6.61]],"batb":[[0,4.5,3.26]],"ltp":4.6,"tv":15680.92,"id":8734382},{"trd":[[1.28,278.27],[1.29,1861.55]],"batb":[[0,1.28,271.01],[1,1.27,11.23],[2,1.24,9.52]],"batl":[[0,1.29,851.59],[1,1.3,9.06],[2,1.45,6.9]],"ltp":1.29,"tv":159559.46,"id":9323645}],"tv":175240.39}]}
{"op":"mcm","clk":"4217152536","pt":1631558143162,"mc":[{"id":"1.187566733","rc":[{"trd":[[1.29,2430.42]],"batl":[[0,1.29,567.18]],"ltp":1.29,"tv":160128.33,"id":9323645}],"tv":175809.26}]}
{"op":"mcm","clk":"4217152814","pt":1631558145105,"mc":[{"id":"1.187566733","rc":[{"batl":[[1,4.8,14.8]],"ltp":4.6,"tv":15680.92,"id":8734382},{"batb":[[1,1.27,4]],"ltp":1.29,"tv":160128.33,"id":9323645}]}]}
{"op":"mcm","clk":"4217152948","pt":1631558146082,"mc":[{"id":"1.187566733","rc":[{"batb":[[0,1.28,272.61],[1,1.24,9.52],[2,1.23,0.41]],"ltp":1.29,"tv":160128.33,"id":9323645}]}]}
{"op":"mcm","clk":"4217153220","pt":1631558147980,"mc":[{"id":"1.187566733","rc":[{"batb":[[0,4.5,8.48]],"batl":[[0,4.7,28.28]],"ltp":4.6,"tv":15680.92,"id":8734382},{"batb":[[0,1.28,1.6]],"ltp":1.29,"tv":160128.33,"id":9323645}]}]}
{"op":"mcm","clk":"4217153484","pt":1631558149887,"mc":[{"id":"1.187566733","rc":[{"trd":[[1.29,2446.1]],"batb":[[0,1.28,3.6]],"batl":[[0,1.29,559.34]],"ltp":1.29,"tv":160144.01,"id":9323645}],"tv":175824.94}]}
{"op":"mcm","clk":"4217153760","pt":1631558151998,"mc":[{"id":"1.187566733","rc":[{"batb":[[0,4.5,3.26]],"batl":[[0,4.7,19.39]],"ltp":4.6,"tv":15680.92,"id":8734382},{"batl":[[2,1.43,396.91]],"ltp":1.29,"tv":160144.01,"id":9323645}]}]}
{"op":"mcm","clk":"4217153871","pt":1631558152789,"mc":[{"id":"1.187566733","rc":[{"trd":[[1.29,2454.1]],"batl":[[0,1.29,555.34],[2,1.43,595.37]],"ltp":1.29,"tv":160152.01,"id":9323645}],"tv":175832.94}]}
{"op":"mcm","clk":"4217153957","pt":1631558153381,"mc":[{"id":"1.187566733","rc":[{"batb":[[0,1.28,1.6]],"ltp":1.29,"tv":160152.01,"id":9323645}]}]}
{"op":"mcm","clk":"4217154200","pt":1631558155187,"mc":[{"id":"1.187566733","rc":[{"batb":[[0,4.5,8.48]],"batl":[[0,4.7,28.28]],"ltp":4.6,"tv":15680.92,"id":8734382},{"batb":[[0,1.24,9.52],[1,1.23,0.41],[2,1.23,0]],"ltp":1.29,"tv":160152.01,"id":9323645}]}]}
{"op":"mcm","clk":"4217154328","pt":1631558156085,"mc":[{"id":"1.187566733","rc":[{"trd":[[1.29,2554.1]],"batl":[[0,1.29,505.34]],"ltp":1.29,"tv":160252.01,"id":9323645}],"tv":175932.94}]}
{"op":"mcm","clk":"4217154403","pt":1631558156612,"mc":[{"id":"1.187566733","rc":[{"trd":[[4.4,53.62],[4.5,8.48]],"batb":[[0,2.6,1.2],[1,2.5,1.82],[2,1.67,1.2]],"ltp":4.4,"tv":15723.0,"id":8734382},{"trd":[[1.29,3594.45],[1.3,930.59]],"batb":[[0,1.3,67.57],[1,1.24,9.52],[2,1.23,0.41]],"batl":[[0,1.43,595.37],[1,1.45,6.9],[2,3.8,27.91]],"ltp":1.3,"tv":161424.22,"id":9323645}],"tv":177147.22}]}
{"op":"mcm","clk":"4217154581","pt":1631558157990,"mc":[{"id":"1.187566733","rc":[{"batb":[[1,1.25,273.08],[2,1.24,9.52]],"ltp":1.3,"tv":161424.22,"id":9323645}]}]}
{"op":"mcm","clk":"4217155334","pt":1631558163513,"mc":[{"id":"1.187566733","rc":[{"trd":[[1.3,1065.72]],"batb":[[0,1.25,273.08],[1,1.24,9.52],[2,1.23,0.41]],"batl":[[0,1.28,277.27],[1,1.43,595.37],[2,1.45,6.9]],"ltp":1.3,"tv":161559.35,"id":9323645}],"tv":177282.36}]}
{"op":"mcm","clk":"4217155802","pt":1631558166800,"mc":[{"id":"1.187566733","rc":[{"batl":[[0,4.7,19.39]],"ltp":4.4,"tv":15723.0,"id":8734382},{"trd":[[1.28,489.61]],"batl":[[0,1.28,171.6]],"ltp":1.28,"tv":161770.69,"id":9323645}],"tv":177493.7}]}
{"op":"mcm","clk":"4217156091","pt":1631558168921,"mc":[{"id":"1.187566733","rc":[{"trd":[[1.28,495.61]],"batl":[[0,1.28,168.6]],"ltp":1.28,"tv":161776.69,"id":9323645}],"tv":177499.7}]}
{"op":"mcm","clk":"4217156244","pt":1631558170032,"mc":[{"id":"1.187566733","rc":[{"batb":[[0,4.4,7.57],[1,4.2,30.67],[2,4,26.44]],"ltp":4.4,"tv":15723.0,"id":8734382},{"trd":[[1.28,532.41]],"batb":[[2,1.19,14.12]],"batl":[[0,1.28,150.2],[1,1.31,840.5],[2,1.33,798.5]],"ltp":1.28,"tv":161813.49,"id":9323645}],"tv":177536.5}]}
{"op":"mcm","clk":"4217156771","pt":1631558173623,"mc":[{"id":"1.187566733","rc":[{"trd":[[1.28,554.09]],"batl":[[0,1.28,139.36]],"ltp":1.28,"tv":161835.17,"id":9323645}],"tv":177558.18}]}
{"op":"mcm","clk":"4217156996","pt":1631558175106,"mc":[{"id":"1.187566733","rc":[{"batl":[[0,1.28,137.76],[1,1.3,284.46],[2,1.31,840.5]],"ltp":1.28,"tv":161835.17,"id":9323645}]}]}
{"op":"mcm","clk":"4217157306","pt":1631558177525,"mc":[{"id":"1.187566733","rc":[{"batl":[[1,1.3,285.81]],"ltp":1.28,"tv":161835.17,"id":9323645}]}]}
{"op":"mcm","clk":"4217157673","pt":1631558180012,"mc":[{"id":"1.187566733","rc":[{"batb":[[0,4.2,30.67],[1,4,26.44],[2,2.6,1.2]],"ltp":4.4,"tv":15723.0,"id":8734382}]}]}
{"op":"mcm","clk":"4217158089","pt":1631558182906,"mc":[{"id":"1.187566733","rc":[{"batb":[[0,4.5,5.22],[1,4.2,30.67],[2,4,26.44]],"batl":[[0,4.7,28.28]],"ltp":4.4,"tv":15723.0,"id":8734382}]}]}
{"op":"mcm","clk":"4217158623","pt":1631558186934,"mc":[{"id":"1.187566733","rc":[{"batl":[[0,1.3,285.81],[1,1.31,840.5],[2,1.33,798.5]],"ltp":1.28,"tv":161835.17,"id":9323645}]}]}
{"op":"mcm","clk":"4217158754","pt":1631558187927,"mc":[{"id":"1.187566733","rc":[{"batl":[[0,4.7,8.89]],"ltp":4.4,"tv":15723.0,"id":8734382}]}]}
{"op":"mcm","clk":"4217159009","pt":1631558189931,"mc":[{"id":"1.187566733","rc":[{"batb":[[0,1.25,273.2]],"ltp":1.28,"tv":161835.17,"id":9323645}]}]}
{"op":"mcm","clk":"4217159154","pt":1631558191024,"mc":[{"id":"1.187566733","rc":[{"batb":[[2,4.1,27.94]],"ltp":4.4,"tv":15723.0,"id":8734382},{"batl":[[2,1.32,874.61]],"ltp":1.28,"tv":161835.17,"id":9323645}]}]}
{"op":"mcm","clk":"4217159358","pt":1631558192440,"mc":[{"id":"1.187566733","rc":[{"batb":[[0,1.24,9.64],[1,1.19,14.12],[2,1.17,58.82]],"ltp":1.28,"tv":161835.17,"id":9323645}]}]}
{"op":"mcm","clk":"4217159501","pt":1631558193432,"mc":[{"id":"1.187566733","rc":[{"batl":[[0,1.3,284.46]],"ltp":1.28,"tv":161835.17,"id":9323645}]}]}
{"op":"mcm","clk":"4217159647","pt":1631558194639,"mc":[{"id":"1.187566733","rc":[{"trd":[[4.5,13.7]],"batb":[[0,4.2,30.67],[1,4.1,27.94],[2,4,26.44]],"ltp":4.5,"tv":15728.22,"id":8734382},{"trd":[[1.29,3612.66],[1.3,1634.59]],"batb":[[0,1.3,297.38],[1,1.24,9.64],[2,1.19,14.12]],"batl":[[0,1.31,840.5],[1,1.32,874.61],[2,1.33,798.5]],"ltp":1.3,"tv":162422.25,"id":9323645}],"tv":178150.48}]}
{"op":"mcm","clk":"4217159785","pt":1631558195741,"mc":[{"id":"1.187566733","rc":[{"batb":[[0,1.3,1027.78]],"ltp":1.3,"tv":162422.25,"id":9323645}]}]}
{"op":"mcm","clk":"4217159869","pt":1631558196325,"mc":[{"id":"1.187566733","rc":[{"batl":[[0,4.5,19.39],[1,4.7,8.89],[2,4.8,14.8]],"ltp":4.5,"tv":15728.22,"id":8734382}]}]}
{"op":"mcm","clk":"4217160114","pt":1631558198122,"mc":[{"id":"1.187566733","rc":[{"batl":[[0,4.5,25.39]],"ltp":4.5,"tv":15728.22,"id":8734382},{"trd":[[1.3,1934.21]],"batb":[[0,1.3,147.57],[1,1.24,9.52]],"ltp":1.3,"tv":162721.87,"id":9323645}],"tv":178450.1}]}
{"op":"mcm","clk":"4217160253","pt":1631558199063,"mc":[{"id":"1.187566733","rc":[{"trd":[[1.3,2047.98]],"batb":[[0,1.3,90.69]],"ltp":1.3,"tv":162835.64,"id":9323645}],"tv":178563.86}]}
{"op":"mcm","clk":"4217160364","pt":1631558199975,"mc":[{"id":"1.187566733","rc":[{"batl":[[0,4.5,6]],"ltp":4.5,"tv":15728.22,"id":8734382},{"trd":[[1.31,1799.51]],"batl":[[0,1.31,115.81]],"ltp":1.31,"tv":164285.15,"id":9323645}],"tv":180013.37}]}
{"op":"mcm","clk":"4217160637","pt":1631558202053,"mc":[{"id":"1.187566733","rc":[{"trd":[[1.31,2031.15]],"batb":[[0,1.31,719.64],[1,1.3,90.69],[2,1.24,9.52]],"batl":[[0,1.32,874.61],[1,1.33,798.5],[2,1.34,779.25]],"ltp":1.31,"tv":164516.79,"id":9323645}],"tv":180245.01}]}
{"op":"mcm","clk":"4217160765","pt":1631558203063,"mc":[{"id":"1.187566733","rc":[{"trd":[[1.31,2375.99],[1.32,2277.57]],"batb":[[0,1.31,1382.67]],"batl":[[0,1.32,21.37]],"ltp":1.32,"tv":166568.26,"id":9323645}],"tv":182296.48}]}
{"op":"mcm","clk":"4217160881","pt":1631558203943,"mc":[{"id":"1.187566733","rc":[{"trd":[[1.31,2926.56]],"batb":[[0,1.31,1107.38]],"ltp":1.31,"tv":167118.83,"id":9323645}],"tv":182847.06}]}
{"op":"mcm","clk":"4217161004","pt":1631558204981,"mc":[{"id":"1.187566733","rc":[{"batl":[[1,4.8,14.8],[2,5.2,2]],"ltp":4.5,"tv":15728.22,"id":8734382},{"batb":[[0,1.31,1107.49]],"ltp":1.31,"tv":167118.83,"id":9323645}]}]}
{"op":"mcm","clk":"4217161077","pt":1631558205561,"mc":[{"id":"1.187566733","rc":[{"batb":[[2,1.29,34.48]],"ltp":1.31,"tv":167118.83,"id":9323645}]}]}
{"op":"mcm","clk":"4217161175","pt":1631558206368,"mc":[{"id":"1.187566733","rc":[{"batl":[[0,4.8,14.8],[1,5.2,2],[2,5.3,5.66]],"ltp":4.5,"tv":15728.22,"id":8734382}]}]}
{"op":"mcm","clk":"4217161409","pt":1631558208081,"mc":[{"id":"1.187566733","rc":[{"trd":[[4.2,88.68],[4.3,87.6]],"batb":[[0,4.2,26.25]],"ltp":4.2,"tv":15744.82,"id":8734382},{"trd":[[1.31,2952.03]],"batb":[[0,1.31,1082.03]],"ltp":1.31,"tv":167144.3,"id":9323645}],"tv":182889.12}]}
{"op":"mcm","clk":"4217161543","pt":1631558209074,"mc":[{"id":"1.187566733","rc":[{"trd":[[4.2,127.44]],"batb":[[0,4.2,6.88]],"ltp":4.2,"tv":15783.58,"id":8734382}],"tv":182927.88}]}
{"op":"mcm","clk":"4217161880","pt":1631558211484,"mc":[{"id":"1.187566733","rc":[{"batb":[[0,1.3,90.8],[1,1.29,34.48],[2,1.28,18.39]],"ltp":1.31,"tv":167144.3,"id":9323645}]}]}
{"op":"mcm","clk":"4217162218","pt":1631558213893,"mc":[{"id":"1.187566733","rc":[{"batb":[[0,1.3,90.69]],"batl":[[0,1.32,288.05]],"ltp":1.31,"tv":167144.3,"id":9323645}]}]}
{"op":"mcm","clk":"4217162410","pt":1631558215166,"mc":[{"id":"1.187566733","rc":[{"batb":[[0,4,26.44],[1,3.9,30.06],[2,3.75,28.79]],"ltp":4.2,"tv":15783.58,"id":8734382},{"trd":[[1.32,2324.02]],"batl":[[0,1.32,264.81]],"ltp":1.32,"tv":167190.75,"id":9323645}],"tv":182974.34}]}
{"op":"mcm","clk":"4217162568","pt":1631558216164,"mc":[{"id":"1.187566733","rc":[{"trd":[[1.32,2853.65]],"batb":[[0,1.32,570.65],[1,1.3,90.69],[2,1.29,34.48]],"batl":[[0,1.33,798.5],[1,1.34,779.25],[2,1.36,707.57]],"ltp":1.32,"tv":167720.38,"id":9323645}],"tv":183503.97}]}
{"op":"mcm","clk":"4217162595","pt":1631558216371,"mc":[{"id":"1.187566733","rc":[{"batb":[[0,1.32,570.76]],"ltp":1.32,"tv":167720.38,"id":9323645}]}]}
{"op":"mcm","clk":"4217163281","pt":1631558221103,"mc":[{"id":"1.187566733","rc":[{"batl":[[0,4.5,7.46],[1,4.8,14.8],[2,5.2,2]],"ltp":4.2,"tv":15783.58,"id":8734382},{"trd":[[1.32,2888.14]],"batb":[[0,1.32,553.41]],"ltp":1.32,"tv":167754.87,"id":9323645}],"tv":183538.45}]}
{"op":"mcm","clk":"4217163316","pt":1631558221267,"mc":[{"id":"1.187566733","rc":[{"batb":[[2,1.24,9.52]],"ltp":1.32,"tv":167754.87,"id":9323645}]}]}
{"op":"mcm","clk":"4217163767","pt":1631558224205,"mc":[{"id":"1.187566733","rc":[{"batl":[[2,5.3,5.66]],"ltp":4.2,"tv":15783.58,"id":8734382},{"trd":[[1.32,3060.58],[1.33,2603.63],[1.34,2658.81]],"batb":[[0,1.32,467.18],[2,1.27,37.03]],"batl":[[0,1.34,553.75],[1,1.36,707.57],[2,1.45,307.79]],"ltp":1.32,"tv":169975.48,"id":9323645}],"tv":185759.06}]}
{"op":"mcm","clk":"4217163783","pt":1631558224271,"mc":[{"id":"1.187566733","rc":[{"batb":[[0,3.9,30.06],[1,3.75,28.79],[2,2.5,2.62]],"ltp":4.2,"tv":15783.58,"id":8734382}]}]}
{"op":"mcm","clk":"4217164752","pt":1631558230696,"mc":[{"id":"1.187566733","rc":[{"trd":[[3.9,113.26]],"batb":[[0,3.75,28.79],[1,2.5,2.62],[2,1.67,1.2]],"ltp":3.9,"tv":15813.64,"id":8734382},{"trd":[[1.34,3766.41],[1.35,7267.46]],"batb":[[0,1.35,212.68],[1,1.32,467.18],[2,1.3,90.69]],"batl":[[0,1.36,707.57],[1,1.45,307.79],[2,3.8,27.91]],"ltp":1.35,"tv":171169.94,"id":9323645}],"tv":186983.58}]}
{"op":"mcm","clk":"4217164837","pt":1631558231288,"mc":[{"id":"1.187566733","rc":[{"batl":[[0,4.8,14.8],[1,5.3,5.66],[2,5.4,2.84]],"ltp":3.9,"tv":15813.64,"id":8734382}]}]}
{"op":"mcm","clk":"4217165082","pt":1631558232973,"mc":[{"id":"1.187566733","rc":[{"batl":[[1,1.45,6.9]],"ltp":1.35,"tv":171169.94,"id":9323645}]}]}
{"op":"mcm","clk":"4217165261","pt":1631558234191,"mc":[{"id":"1.187566733","rc":[{"batl":[[0,4.4,5.25],[1,4.8,14.8],[2,5.3,5.66]],"ltp":3.9,"tv":15813.64,"id":8734382},{"trd":[[1.35,7335.55]],"batb":[[0,1.35,178.63],[1,1.33,85.34],[2,1.32,467.18]],"ltp":1.35,"tv":171238.03,"id":9323645}],"tv":187051.67}]}
{"op":"mcm","clk":"4217166040","pt":1631558239700,"mc":[{"id":"1.187566733","rc":[{"batb":[[1,1.33,115.64]],"ltp":1.35,"tv":171238.03,"id":9323645}]}]}
{"op":"mcm","clk":"4217166198","pt":1631558240801,"mc":[{"id":"1.187566733","rc":[{"batl":[[2,1.59,274.84]],"ltp":1.35,"tv":171238.03,"id":9323645}]}]}
{"op":"mcm","clk":"4217166804","pt":1631558245134,"mc":[{"id":"1.187566733","rc":[{"batl":[[0,4.8,14.8],[1,5.3,5.66],[2,5.4,2.84]],"ltp":3.9,"tv":15813.64,"id":8734382},{"trd":[[1.35,7348.17]],"batb":[[0,1.35,172.32]],"ltp":1.35,"tv":171250.65,"id":9323645}],"tv":187064.3}]}
{"op":"mcm","clk":"4217166835","pt":1631558245344,"mc":[{"id":"1.187566733","rc":[{"trd":[[1.36,2522.88]],"batl":[[0,1.36,705.57]],"ltp":1.36,"tv":171254.65,"id":9323645}],"tv":187068.3}]}
{"op":"mcm","clk":"4217167027","pt":1631558246609,"mc":[{"id":"1.187566733","rc":[{"trd":[[1.35,7434.38]],"batb":[[0,1.35,129.21]],"ltp":1.35,"tv":171340.86,"id":9323645}],"tv":187154.5}]}
{"op":"mcm","clk":"4217167167","pt":1631558247609,"mc":[{"id":"1.187566733","rc":[{"batl":[[0,4.3,6.33],[1,4.8,14.8],[2,5.3,5.66]],"ltp":3.9,"tv":15813.64,"id":8734382},{"trd":[[1.35,7485.46],[1.36,2812.01]],"batb":[[0,1.35,103.67],[2,1.3,90.69]],"batl":[[0,1.36,560.98]],"ltp":1.36,"tv":171681.07,"id":9323645}],"tv":187494.71}]}
{"op":"mcm","clk":"4217167446","pt":1631558249401,"mc":[{"id":"1.187566733","rc":[{"batb":[[1,1.33,85.34]],"ltp":1.36,"tv":171681.07,"id":9323645}]}]}
{"op":"mcm","clk":"4217167797","pt":1631558251814,"mc":[{"id":"1.187566733","rc":[{"trd":[[3.8,1.27]],"batb":[[0,2.5,2.62],[1,1.67,1.2],[2,1.13,1.2]],"ltp":3.8,"tv":15814.04,"id":8734382},{"trd":[[1.36,3935.18]],"batb":[[0,1.36,273.27],[1,1.35,103.67],[2,1.33,85.34]],"batl":[[0,1.45,6.9],[1,1.59,274.84],[2,3.8,27.46]],"ltp":1.36,"tv":172804.24,"id":9323645}],"tv":188618.29}]}
{"op":"mcm","clk":"4217168209","pt":1631558254810,"mc":[{"id":"1.187566733","rc":[{"batl":[[1,1.5,835.92],[2,1.59,274.39]],"ltp":1.36,"tv":172804.24,"id":9323645}]}]}
{"op":"mcm","clk":"4217168416","pt":1631558256226,"mc":[{"id":"1.187566733","rc":[{"batb":[[0,1.36,274.66]],"ltp":1.36,"tv":172804.24,"id":9323645}]}]}
{"op":"mcm","clk":"4217168627","pt":1631558257644,"mc":[{"id":"1.187566733","rc":[{"batl":[[0,4.8,14.8],[1,5.3,5.66],[2,5.4,2.84]],"ltp":3.8,"tv":15814.04,"id":8734382}]}]}
{"op":"mcm","clk":"4217168936","pt":1631558260027,"mc":[{"id":"1.187566733","rc":[{"batl":[[1,1.59,274.84],[2,3.8,27.46]],"ltp":1.36,"tv":172804.24,"id":9323645}]}]}
{"op":"mcm","clk":"4217169000","pt":1631558260547,"mc":[{"id":"1.187566733","rc":[{"batl":[[0,4.2,6.54],[1,4.8,14.8],[2,5.3,5.66]],"ltp":3.8,"tv":15814.04,"id":8734382},{"trd":[[1.36,3984.39]],"batb":[[0,1.36,250.05]],"ltp":1.36,"tv":172853.45,"id":9323645}],"tv":188667.49}]}
{"op":"mcm","clk":"4217169507","pt":1631558263966,"mc":[{"id":"1.187566733","rc":[{"trd":[[1.36,3987.09]],"batb":[[0,1.36,248.71]],"ltp":1.36,"tv":172856.14,"id":9323645}],"tv":188670.19}]}
{"op":"mcm","clk":"4217169652","pt":1631558264956,"mc":[{"id":"1.187566733","rc":[{"batl":[[1,1.54,835.92],[2,1.59,274.39]],"ltp":1.36,"tv":172856.14,"id":9323645}]}]}
{"op":"mcm","clk":"4217170474","pt":1631558270873,"mc":[{"id":"1.187566733","rc":[{"batl":[[0,4.8,14.8],[1,5.3,5.66],[2,5.4,2.84]],"ltp":3.8,"tv":15814.04,"id":8734382}]}]}
{"op":"mcm","clk":"4217170721","pt":1631558272566,"mc":[{"id":"1.187566733","rc":[{"batb":[[0,1.36,250.71]],"ltp":1.36,"tv":172856.14,"id":9323645}]}]}
{"op":"mcm","clk":"4217170893","pt":1631558273726,"mc":[{"id":"1.187566733","rc":[{"batl":[[0,4.1,6.34],[1,4.8,14.8],[2,5.3,5.66]],"ltp":3.8,"tv":15814.04,"id":8734382},{"trd":[[1.36,4033.93]],"batb":[[0,1.36,227.28]],"ltp":1.36,"tv":172902.99,"id":9323645}],"tv":188717.03}]}
{"op":"mcm","clk":"4217171004","pt":1631558274363,"mc":[{"id":"1.187566733","rc":[{"batb":[[1,1.33,85.34],[2,1.3,90.69]],"ltp":1.36,"tv":172902.99,"id":9323645}]}]}
{"op":"mcm","clk":"4217171327","pt":1631558276572,"mc":[{"id":"1.187566733","rc":[{"batb":[[0,1.36,3.39]],"ltp":1.36,"tv":172902.99,"id":9323645}]}]}
{"op":"mcm","clk":"4217171717","pt":1631558279361,"mc":[{"id":"1.187566733","rc":[{"trd":[[1.45,4254.91]],"batl":[[0,1.45,4.9]],"ltp":1.45,"tv":172906.99,"id":9323645}],"tv":188721.03}]}
{"op":"mcm","clk":"4217171903","pt":1631558280765,"mc":[{"id":"1.187566733","rc":[{"batb":[[0,1.38,1024.07],[1,1.36,3.39],[2,1.33,85.34]],"ltp":1.45,"tv":172906.99,"id":9323645}]}]}
{"op":"mcm","clk":"4217172039","pt":1631558281769,"mc":[{"id":"1.187566733","rc":[{"batl":[[1,1.46,9.02],[2,1.54,835.92]],"ltp":1.45,"tv":172906.99,"id":9323645}]}]}
{"op":"mcm","clk":"4217172194","pt":1631558282779,"mc":[{"id":"1.187566733","rc":[{"trd":[[3.2,48.5]],"batl":[[0,3.2,5.15],[1,4.1,6.34],[2,4.8,14.8]],"ltp":3.2,"tv":15816.26,"id":8734382},{"trd":[[1.45,4259.81]],"batl":[[0,1.46,9.02],[1,1.54,835.92],[2,1.59,274.39]],"ltp":1.45,"tv":172911.89,"id":9323645}],"tv":188728.15}]}
{"op":"mcm","clk":"4217172377","pt":1631558284081,"mc":[{"id":"1.187566733","rc":[{"batl":[[1,4.8,14.8],[2,5.3,5.66]],"ltp":3.2,"tv":15816.26,"id":8734382},{"batl":[[2,3.8,27.46]],"ltp":1.45,"tv":172911.89,"id":9323645}]}]}
{"op":"mcm","clk":"4217172607","pt":1631558285557,"mc":[{"id":"1.187566733","rc":[{"batl":[[1,1.53,285.6],[2,1.54,835.47]],"ltp":1.45,"tv":172911.89,"id":9323645}]}]}
{"op":"mcm","clk":"4217172823","pt":1631558286944,"mc":[{"id":"1.187566733","rc":[{"trd":[[3.2,53.64]],"batl":[[0,4,5.53]],"ltp":3.2,"tv":15821.4,"id":8734382},{"trd":[[1.38,1538.45],[1.45,4271.16]],"batb":[[0,1.38,1012.85]],"ltp":1.38,"tv":172945.66,"id":9323645}],"tv":188767.07}]}
{"op":"mcm","clk":"4217173253","pt":1631558290152,"mc":[{"id":"1.187566733","rc":[{"batl":[[2,3.8,27.46]],"ltp":1.38,"tv":172945.66,"id":9323645}]}]}
{"op":"mcm","clk":"4217173454","pt":1631558291673,"mc":[{"id":"1.187566733","rc":[{"batl":[[0,1.46,9.3]],"ltp":1.38,"tv":172945.66,"id":9323645}]}]}
{"op":"mcm","clk":"4217173570","pt":1631558292488,"mc":[{"id":"1.187566733","rc":[{"batl":[[1,1.51,835.92],[2,1.53,285.15]],"ltp":1.38,"tv":172945.66,"id":9323645}]}]}
{"op":"mcm","clk":"4217174015","pt":1631558295779,"mc":[{"id":"1.187566733","rc":[{"batb":[[0,1.39,437.63],[1,1.38,1012.85],[2,1.36,3.39]],"batl":[[1,1.53,285.6],[2,3.8,27.46]],"ltp":1.38,"tv":172945.66,"id":9323645}]}]}
{"op":"mcm","clk":"4217174197","pt":1631558297196,"mc":[{"id":"1.187566733","rc":[{"batl":[[0,4.8,14.8],[1,5.3,5.66],[2,5.4,2.84]],"ltp":3.2,"tv":15821.4,"id":8734382},{"batb":[[2,1.36,2]],"ltp":1.38,"tv":172945.66,"id":9323645}]}]}
{"op":"mcm","clk":"4217174451","pt":1631558299090,"mc":[{"id":"1.187566733","rc":[{"trd":[[1.45,4271.71],[1.46,391.32]],"batl":[[0,1.46,2.3],[1,1.52,835.92],[2,1.53,285.15]],"ltp":1.46,"tv":172959.66,"id":9323645}],"tv":188781.07}]}
{"op":"mcm","clk":"4217174600","pt":1631558300188,"mc":[{"id":"1.187566733","rc":[{"trd":[[1.39,2827.76]],"batb":[[0,1.39,417.04]],"ltp":1.39,"tv":173000.84,"id":9323645}],"tv":188822.25}]}
{"op":"mcm","clk":"4217175007","pt":1631558303190,"mc":[{"id":"1.187566733","rc":[{"batl":[[2,3.8,27.46]],"ltp":1.39,"tv":173000.84,"id":9323645}]}]}
{"op":"mcm","clk":"4217175071","pt":1631558303720,"mc":[{"id":"1.187566733","rc":[{"batl":[[1,1.51,308.34],[2,1.52,835.47]],"ltp":1.39,"tv":173000.84,"id":9323645}]}]}
{"op":"mcm","clk":"4217175417","pt":1631558306300,"mc":[{"id":"1.187566733","rc":[{"batb":[[0,1.38,1012.85],[1,1.36,2],[2,1.34,24.69]],"ltp":1.39,"tv":173000.84,"id":9323645}]}]}
{"op":"mcm","clk":"4217175922","pt":1631558310190,"mc":[{"id":"1.187566733","rc":[{"batb":[[0,1.39,200],[1,1.38,1012.85],[2,1.36,2]],"ltp":1.39,"tv":173000.84,"id":9323645}]}]}
{"op":"mcm","clk":"4217175994","pt":1631558310804,"mc":[{"id":"1.187566733","rc":[{"batb":[[0,2.06,1.2],[1,1.49,1.2],[2,1.09,1.2]],"ltp":3.2,"tv":15821.4,"id":8734382}]}]}
{"op":"mcm","clk":"4217176390","pt":1631558313869,"mc":[{"id":"1.187566733","rc":[{"batl":[[0,3.85,7.29],[1,4.8,14.8],[2,5.3,5.66]],"ltp":3.2,"tv":15821.4,"id":8734382},{"trd":[[1.39,2868.64]],"batb":[[0,1.39,179.56]],"batl":[[2,3.8,27.46]],"ltp":1.39,"tv":173041.72,"id":9323645}],"tv":188863.13}]}
{"op":"mcm","clk":"4217176855","pt":1631558317496,"mc":[{"id":"1.187566733","rc":[{"batl":[[1,1.5,1393.44],[2,1.51,307.89]],"ltp":1.39,"tv":173041.72,"id":9323645}]}]}
{"op":"mcm","clk":"4217177547","pt":1631558322182,"mc":[{"id":"1.187566733","rc":[{"batl":[[1,1.49,174.16],[2,1.5,1393.44]],"ltp":1.39,"tv":173041.72,"id":9323645}]}]}
{"op":"mcm","clk":"4217177815","pt":1631558324123,"mc":[{"id":"1.187566733","rc":[{"batl":[[0,4.8,14.8],[1,5.3,5.66],[2,5.4,2.84]],"ltp":3.2,"tv":15821.4,"id":8734382},{"batb":[[1,1.36,2],[2,1.33,85.34]],"ltp":1.39,"tv":173041.72,"id":9323645}]}]}
{"op":"mcm","clk":"4217178138","pt":1631558326389,"mc":[{"id":"1.187566733","rc":[{"trd":[[1.39,2908.08]],"batb":[[0,1.39,159.84],[1,1.36,23.58]],"ltp":1.39,"tv":173081.16,"id":9323645}],"tv":188902.57}]}
{"op":"mcm","clk":"4217178346","pt":1631558327915,"mc":[{"id":"1.187566733","rc":[{"trd":[[1.39,2910.78]],"batb":[[0,1.39,158.49]],"ltp":1.39,"tv":173083.86,"id":9323645}],"tv":188905.27}]}
{"op":"mcm","clk":"4217178619","pt":1631558329815,"mc":[{"id":"1.187566733","rc":[{"trd":[[1.39,2954.89]],"batb":[[0,1.39,136.43]],"ltp":1.39,"tv":173127.98,"id":9323645}],"tv":188949.39}]}
{"op":"mcm","clk":"4217179500","pt":1631558336141,"mc":[{"id":"1.187566733","rc":[{"trd":[[1.39,2989.37]],"batb":[[0,1.4,725.38],[1,1.39,119.19],[2,1.36,23.58]],"ltp":1.39,"tv":173162.46,"id":9323645}],"tv":188983.87}]}
{"op":"mcm","clk":"4217179597","pt":1631558336716,"mc":[{"id":"1.187566733","rc":[{"batb":[[2,1.36,2]],"ltp":1.39,"tv":173162.46,"id":9323645}]}]}
{"op":"mcm","clk":"4217179832","pt":1631558338415,"mc":[{"id":"1.187566733","rc":[{"trd":[[1.4,3003.43]],"batb":[[0,1.4,725.35]],"ltp":1.4,"tv":173162.51,"id":9323645}],"tv":188983.92}]}
{"op":"mcm","clk":"4217179999","pt":1631558339628,"mc":[{"id":"1.187566733","rc":[{"batl":[[0,3.7,7.29],[1,4.8,14.8],[2,5.3,5.66]],"ltp":3.2,"tv":15821.4,"id":8734382},{"trd":[[1.4,3041.56]],"batb":[[0,1.4,706.29]],"ltp":1.4,"tv":173200.64,"id":9323645}],"tv":189022.05}]}
{"op":"mcm","clk":"4217180130","pt":1631558340630,"mc":[{"id":"1.187566733","rc":[{"batl":[[2,3.8,27.91]],"ltp":1.4,"tv":173200.64,"id":9323645}]}]}
{"op":"mcm","clk":"4217180905","pt":1631558345930,"mc":[{"id":"1.187566733","rc":[{"batl":[[2,1.52,85.79]],"ltp":1.4,"tv":173200.64,"id":9323645}]}]}
{"op":"mcm","clk":"4217181014","pt":1631558346713,"mc":[{"id":"1.187566733","rc":[{"batb":[[1,2,1.82],[2,1.49,1.2]],"ltp":3.2,"tv":15821.4,"id":8734382}]}]}
{"op":"mcm","clk":"4217181128","pt":1631558347451,"mc":[{"id":"1.187566733","rc":[{"batl":[[2,1.52,256.47]],"ltp":1.4,"tv":173200.64,"id":9323645}]}]}
{"op":"mcm","clk":"4217181431","pt":1631558349820,"mc":[{"id":"1.187566733","rc":[{"batl":[[0,4.8,14.8],[1,5.3,5.66],[2,5.4,2.84]],"ltp":3.2,"tv":15821.4,"id":8734382}]}]}
{"op":"mcm","clk":"4217181861","pt":1631558352723,"mc":[{"id":"1.187566733","rc":[{"trd":[[3.5,35.55]],"ltp":3.5,"tv":15825.06,"id":8734382},{"trd":[[1.4,3068.99]],"batb":[[0,1.4,688],[2,1.38,19.57]],"ltp":1.4,"tv":173228.07,"id":9323645}],"tv":189053.14}]}
{"op":"mcm","clk":"4217181955","pt":1631558353353,"mc":[{"id":"1.187566733","rc":[{"trd":[[1.46,395.92]],"batb":[[0,1.46,27.7],[1,1.4,688],[2,1.39,119.19]],"batl":[[0,1.49,174.16],[1,1.52,256.47],[2,1.54,85.34]],"ltp":1.46,"tv":173232.67,"id":9323645}],"tv":189057.74}]}
{"op":"mcm","clk":"4217182581","pt":1631558357423,"mc":[{"id":"1.187566733","rc":[{"trd":[[1.4,3070.61],[1.46,451.32]],"batb":[[0,1.4,687.19],[1,1.39,119.19],[2,1.38,19.57]],"batl":[[0,1.46,290.73],[1,1.49,174.16],[2,1.52,256.47]],"ltp":1.4,"tv":173289.69,"id":9323645}],"tv":189114.76}]}
{"op":"mcm","clk":"4217182799","pt":1631558359052,"mc":[{"id":"1.187566733","rc":[{"batl":[[0,1.49,174.16],[1,1.52,256.47],[2,1.54,85.34]],"ltp":1.4,"tv":173289.69,"id":9323645}]}]}
{"op":"mcm","clk":"4217183347","pt":1631558363054,"mc":[{"id":"1.187566733","rc":[{"batb":[[2,1.36,2]],"ltp":1.4,"tv":173289.69,"id":9323645}]}]}
{"op":"mcm","clk":"4217183719","pt":1631558365972,"mc":[{"id":"1.187566733","rc":[{"batl":[[0,3.55,5.69],[1,4.8,14.8],[2,5.3,5.66]],"ltp":3.5,"tv":15825.06,"id":8734382},{"batl":[[0,1.41,17.67],[1,1.49,174.16],[2,1.52,256.47]],"ltp":1.4,"tv":173289.69,"id":9323645}]}]}
{"op":"mcm","clk":"4217184080","pt":1631558368457,"mc":[{"id":"1.187566733","rc":[{"batl":[[1,1.48,426.69],[2,1.49,174.16]],"ltp":1.4,"tv":173289.69,"id":9323645}]}]}
{"op":"mcm","clk":"4217184734","pt":1631558373141,"mc":[{"id":"1.187566733","rc":[{"trd":[[1.41,1889.76]],"batb":[[0,1.42,142.78],[1,1.4,687.19],[2,1.39,119.19]],"batl":[[0,1.48,426.69],[1,1.49,174.16],[2,1.52,256.47]],"ltp":1.41,"tv":173325.02,"id":9323645}],"tv":189150.09}]}
{"op":"mcm","clk":"4217184794","pt":1631558373659,"mc":[{"id":"1.187566733","rc":[{"batl":[[1,1.52,256.47],[2,1.54,85.34]],"ltp":1.41,"tv":173325.02,"id":9323645}]}]}
{"op":"mcm","clk":"4217184905","pt":1631558374446,"mc":[{"id":"1.187566733","rc":[{"batl":[[0,1.47,288.75],[1,1.48,426.69],[2,1.52,256.47]],"ltp":1.41,"tv":173325.02,"id":9323645}]}]}
{"op":"mcm","clk":"4217185095","pt":1631558375765,"mc":[{"id":"1.187566733","rc":[{"batb":[[1,1.41,853.39],[2,1.4,687.19]],"ltp":1.41,"tv":173325.02,"id":9323645}]}]}
{"op":"mcm","clk":"4217185611","pt":1631558379144,"mc":[{"id":"1.187566733","rc":[{"batb":[[1,1.4,687.19],[2,1.36,2]],"ltp":1.41,"tv":173325.02,"id":9323645}]}]}
{"op":"mcm","clk":"4217185736","pt":1631558380083,"mc":[{"id":"1.187566733","rc":[{"batb":[[1,1.41,119.19],[2,1.4,687.19]],"ltp":1.41,"tv":173325.02,"id":9323645}]}]}
{"op":"mcm","clk":"4217185783","pt":1631558380457,"mc":[{"id":"1.187566733","rc":[{"batb":[[2,1.36,2]],"ltp":1.41,"tv":173325.02,"id":9323645}]}]}
{"op":"mcm","clk":"4217186035","pt":1631558381877,"mc":[{"id":"1.187566733","rc":[{"trd":[[1.42,1632.62]],"batb":[[0,1.42,41.24]],"ltp":1.42,"tv":173528.14,"id":9323645}],"tv":189353.21}]}
{"op":"mcm","clk":"4217186222","pt":1631558383350,"mc":[{"id":"1.187566733","rc":[{"batl":[[0,4.8,14.8],[1,5.3,5.66],[2,5.4,2.84]],"ltp":3.5,"tv":15825.06,"id":8734382}]}]}
{"op":"mcm","clk":"4217186670","pt":1631558386461,"mc":[{"id":"1.187566733","rc":[{"trd":[[1.42,1666.6]],"batb":[[0,1.42,24.26]],"ltp":1.42,"tv":173562.11,"id":9323645}],"tv":189387.18}]}
{"op":"mcm","clk":"4217187155","pt":1631558390169,"mc":[{"id":"1.187566733","rc":[{"trd":[[1.42,1683.83]],"batb":[[0,1.42,15.65]],"ltp":1.42,"tv":173579.35,"id":9323645}],"tv":189404.42}]}
{"op":"mcm","clk":"4217187538","pt":1631558393074,"mc":[{"id":"1.187566733","rc":[{"trd":[[1.41,2128.14],[1.42,1715.13]],"batb":[[0,1.36,2],[1,1.33,85.34],[2,1.23,0.41]],"batl":[[1,1.52,256.47],[2,1.54,85.34]],"ltp":1.41,"tv":173849.02,"id":9323645}],"tv":189674.09}]}
{"op":"mcm","clk":"4217187824","pt":1631558394808,"mc":[{"id":"1.187566733","rc":[{"batb":[[0,1.37,10.99],[1,1.36,2],[2,1.33,85.34]],"batl":[[0,1.42,101.59],[1,1.47,288.75],[2,1.52,256.47]],"ltp":1.41,"tv":173849.02,"id":9323645}]}]}
{"op":"mcm","clk":"4217187963","pt":1631558395713,"mc":[{"id":"1.187566733","rc":[{"batl":[[0,1.41,104.07]],"ltp":1.41,"tv":173849.02,"id":9323645}]}]}
{"op":"mcm","clk":"4217188067","pt":1631558396409,"mc":[{"id":"1.187566733","rc":[{"batl":[[0,1.47,288.75],[1,1.52,256.47],[2,1.54,85.34]],"ltp":1.41,"tv":173849.02,"id":9323645}]}]}
{"op":"mcm","clk":"4217188369","pt":1631558398397,"mc":[{"id":"1.187566733","rc":[{"trd":[[1.47,506.6]],"batl":[[0,1.47,248.75]],"ltp":1.47,"tv":173929.03,"id":9323645}],"tv":189754.1}]}
{"op":"mcm","clk":"4217188782","pt":1631558401283,"mc":[{"id":"1.187566733","rc":[{"trd":[[3.1,20.3]],"ltp":3.1,"tv":15827.96,"id":8734382},{"trd":[[1.47,512.71]],"batl":[[0,1.47,242.64]],"ltp":1.47,"tv":173935.13,"id":9323645}],"tv":189763.09}]}
{"op":"mcm","clk":"4217190304","pt":1631558412293,"mc":[{"id":"1.187566733","rc":[{"batl":[[0,1.52,256.47],[1,1.54,85.34],[2,1.57,85.34]],"ltp":1.47,"tv":173935.13,"id":9323645}]}]}
{"op":"mcm","clk":"4217190670","pt":1631558414814,"mc":[{"id":"1.187566733","rc":[{"batl":[[0,3.5,2.86],[1,4.8,14.8],[2,5.3,5.66]],"ltp":3.1,"tv":15827.96,"id":8734382},{"batb":[[0,1.46,14.27],[1,1.44,256.02],[2,1.37,10.99]],"batl":[[0,1.48,14.47],[1,1.52,256.47],[2,1.54,85.34]],"ltp":1.47,"tv":173935.13,"id":9323645}]}]}
{"op":"mcm","clk":"4217190827","pt":1631558415915,"mc":[{"id":"1.187566733","rc":[{"batb":[[2,1.36,2]],"ltp":1.47,"tv":173935.13,"id":9323645}]}]}
{"op":"mcm","clk":"4217190923","pt":1631558416610,"mc":[{"id":"1.187566733","rc":[{"batl":[[1,1.51,141.13],[2,1.52,256.02]],"ltp":1.47,"tv":173935.13,"id":9323645}]}]}
{"op":"mcm","clk":"4217191265","pt":1631558419120,"mc":[{"id":"1.187566733","rc":[{"batl":[[0,1.48,113.65]],"ltp":1.47,"tv":173935.13,"id":9323645}]}]}
{"op":"mcm","clk":"4217191347","pt":1631558419602,"mc":[{"id":"1.187566733","rc":[{"trd":[[3.2,54.66]],"ltp":3.2,"tv":15828.97,"id":8734382},{"trd":[[1.46,477.64]],"batb":[[0,1.44,256.02],[1,1.36,2],[2,1.33,85.34]],"ltp":1.46,"tv":173961.46,"id":9323645}],"tv":189790.43}]}
{"op":"mcm","clk":"4217191566","pt":1631558421204,"mc":[{"id":"1.187566733","rc":[{"trd":[[2.96,53.55]],"batb":[[0,2,2.62],[1,1.49,1.2],[2,1.09,1.2]],"ltp":2.96,"tv":15829.37,"id":8734382},{"trd":[[1.48,1242.49],[1.5,239.32],[1.51,552.79],[1.52,856.96],[1.54,200.87]],"batb":[[0,1.54,1063.88],[1,1.44,256.02],[2,1.36,2]],"batl":[[0,1.57,85.34],[1,3.8,27.46],[2,8.8,7.23]],"ltp":1.54,"tv":175154.21,"id":9323645}],"tv":190983.58}]}
{"op":"mcm","clk":"4217191791","pt":1631558422849,"mc":[{"id":"1.187566733","rc":[{"trd":[[1.54,558.58]],"batb":[[0,1.54,885.06]],"ltp":1.54,"tv":175511.92,"id":9323645}],"tv":191341.29}]}
{"op":"mcm","clk":"4217191997","pt":1631558424124,"mc":[{"id":"1.187566733","rc":[{"trd":[[1.54,1219.19]],"batb":[[0,1.54,554.85],[1,1.48,17.07],[2,1.45,61.1]],"batl":[[0,1.56,90.01],[1,1.57,85.34],[2,3.8,27.46]],"ltp":1.54,"tv":176172.53,"id":9323645}],"tv":192001.9}]}
{"op":"mcm","clk":"4217192309","pt":1631558426124,"mc":[{"id":"1.187566733","rc":[{"trd":[[1.54,1389.82]],"batb":[[0,1.54,550.45]],"ltp":1.54,"tv":176343.16,"id":9323645}],"tv":192172.53}]}
{"op":"mcm","clk":"4217192398","pt":1631558426727,"mc":[{"id":"1.187566733","rc":[{"trd":[[1.54,1731.08]],"batb":[[0,1.54,379.87]],"ltp":1.54,"tv":176684.42,"id":9323645}],"tv":192513.79}]}
{"op":"mcm","clk":"4217192670","pt":1631558428726,"mc":[{"id":"1.187566733","rc":[{"batb":[[0,1.55,73.89],[1,1.54,459.89],[2,1.49,9.93]],"batl":[[0,1.56,157.52],[2,1.64,11.71]],"ltp":1.54,"tv":176684.42,"id":9323645}]}]}
{"op":"mcm","clk":"4217192996","pt":1631558431060,"mc":[{"id":"1.187566733","rc":[{"trd":[[1.54,2095.23],[1.55,147.79],[1.56,40]],"batb":[[0,1.54,277.87],[1,1.49,9.93],[2,1.48,17.07]],"batl":[[0,1.56,137.52]],"ltp":1.54,"tv":177236.36,"id":9323645}],"tv":193065.73}]}
{"op":"mcm","clk":"4217193044","pt":1631558431333,"mc":[{"id":"1.187566733","rc":[{"batb":[[0,1.54,197.84]],"batl":[[0,1.56,70.01]],"ltp":1.54,"tv":177236.36,"id":9323645}]}]}
{"op":"mcm","clk":"4217193341","pt":1631558433156,"mc":[{"id":"1.187566733","rc":[{"trd":[[1.54,2123.32]],"batb":[[0,1.55,254.36],[1,1.54,183.8],[2,1.49,9.93]],"batl":[[0,1.57,85.34],[1,1.64,11.71],[2,3.8,27.46]],"ltp":1.54,"tv":177264.45,"id":9323645}],"tv":193093.82}]}
{"op":"mcm","clk":"4217193430","pt":1631558433726,"mc":[{"id":"1.187566733","rc":[{"batl":[[0,6,26.06],[1,6.4,23.14],[2,7,22.06]],"ltp":2.96,"tv":15829.37,"id":8734382}]}]}
{"op":"mcm","clk":"4217193524","pt":1631558434355,"mc":[{"id":"1.187566733","rc":[{"batb":[[1,1.54,102.9]],"batl":[[1,1.62,256.02],[2,1.64,11.71]],"ltp":1.54,"tv":177264.45,"id":9323645}]}]}
{"op":"mcm","clk":"4217193771","pt":1631558436039,"mc":[{"id":"1.187566733","rc":[{"trd":[[1.55,175.9]],"batb":[[0,1.55,330]],"batl":[[0,1.57,146.1]],"ltp":1.55,"tv":177292.56,"id":9323645}],"tv":193121.93}]}
{"op":"mcm","clk":"4217193869","pt":1631558436728,"mc":[{"id":"1.187566733","rc":[{"batb":[[0,1.55,240.31]],"batl":[[0,1.57,85.34]],"ltp":1.55,"tv":177292.56,"id":9323645}]}]}
{"op":"mcm","clk":"4217194066","pt":1631558437943,"mc":[{"id":"1.187566733","rc":[{"batl":[[1,3.8,27.46],[2,8.8,7.23]],"ltp":1.55,"tv":177292.56,"id":9323645}]}]}
{"op":"mcm","clk":"4217194387","pt":1631558440143,"mc":[{"id":"1.187566733","rc":[{"batl":[[0,2.92,11.56],[1,3.05,12],[2,3.3,5.03]],"ltp":2.96,"tv":15829.37,"id":8734382},{"batl":[[0,1.56,23.77]],"ltp":1.55,"tv":177292.56,"id":9323645}]}]}
{"op":"mcm","clk":"4217194527","pt":1631558440941,"mc":[{"id":"1.187566733","rc":[{"batl":[[1,3.3,3.03],[2,4.3,105.25]],"ltp":2.96,"tv":15829.37,"id":8734382},{"batb":[[0,1.54,102.9],[1,1.49,9.93],[2,1.48,17.07]],"ltp":1.55,"tv":177292.56,"id":9323645}]}]}
{"op":"mcm","clk":"4217194632","pt":1631558441650,"mc":[{"id":"1.187566733","rc":[{"batb":[[1,1.48,17.07],[2,1.36,2]],"ltp":1.55,"tv":177292.56,"id":9323645}]}]}
{"op":"mcm","clk":"4217194860","pt":1631558443160,"mc":[{"id":"1.187566733","rc":[{"batl":[[0,3.3,3.03],[1,4.3,105.25],[2,6,26.06]],"ltp":2.96,"tv":15829.37,"id":8734382},{"batb":[[0,1.59,234.26],[1,1.57,149.7],[2,1.54,102.9]],"batl":[[0,3.8,27.46],[1,8.8,7.23],[2,44,7.23]],"ltp":1.55,"tv":177292.56,"id":9323645}]}]}
{"op":"mcm","clk":"4217195003","pt":1631558444063,"mc":[{"id":"1.187566733","rc":[{"batl":[[2,7,22.06]],"ltp":2.96,"tv":15829.37,"id":8734382},{"trd":[[1.59,17.51]],"batb":[[0,1.59,233.96],[2,1.56,76.19]],"batl":[[0,1.65,85.34],[1,3.8,27.46],[2,8.8,7.23]],"ltp":1.59,"tv":177293.15,"id":9323645}],"tv":193122.52}]}
{"op":"mcm","clk":"4217195185","pt":1631558445153,"mc":[{"id":"1.187566733","rc":[{"trd":[[1.59,477.76]],"batb":[[0,1.59,3.82],[1,1.56,76.19],[2,1.54,102.9]],"ltp":1.59,"tv":177753.39,"id":9323645}],"tv":193582.76}]}
{"op":"mcm","clk":"4217195292","pt":1631558445881,"mc":[{"id":"1.187566733","rc":[{"trd":[[2.7,0.82],[2.8,0.53]],"ltp":2.8,"tv":15830.72,"id":8734382},{"trd":[[1.56,40.96],[1.59,484.01]],"batb":[[0,1.54,102.9],[1,1.52,90.99],[2,1.48,17.07]],"ltp":1.56,"tv":177760.6,"id":9323645}],"tv":193591.33}]}
{"op":"mcm","clk":"4217195463","pt":1631558447043,"mc":[{"id":"1.187566733","rc":[{"batl":[[0,990,0.01],[1,4.3,0],[2,7,0]],"ltp":2.8,"tv":15830.72,"id":8734382},{"trd":[[1.55,344.53]],"batl":[[0,1.55,2.42],[1,1.65,85.34],[2,1.69,51.01]],"ltp":1.55,"tv":177929.24,"id":9323645}],"tv":193759.96}]}
{"op":"mcm","clk":"4217195573","pt":1631558447845,"mc":[{"id":"1.187566733","rc":[{"batb":[[1,1.48,17.07],[2,1.44,100]],"batl":[[2,3.8,27.46]],"ltp":1.55,"tv":177929.24,"id":9323645}]}]}
{"op":"mcm","clk":"4217195737","pt":1631558448957,"mc":[{"id":"1.187566733","rc":[{"trd":[[1.55,349.37]],"batl":[[0,1.65,170.68],[1,3.8,27.46],[2,8.8,7.23]],"ltp":1.55,"tv":177934.08,"id":9323645}],"tv":193764.8}]}
{"op":"mcm","clk":"4217195929","pt":1631558450178,"mc":[{"id":"1.187566733","rc":[{"trd":[[1.56,187.28]],"batb":[[0,1.56,3.03],[1,1.55,77.57],[2,1.54,175.1]],"ltp":1.56,"tv":178080.4,"id":9323645}],"tv":193911.12}]}
{"op":"mcm","clk":"4217196069","pt":1631558451053,"mc":[{"id":"1.187566733","rc":[{"batb":[[2,1.54,102.9]],"batl":[[1,1.69,256.02],[2,3.8,27.46]],"ltp":1.56,"tv":178080.4,"id":9323645}]}]}
{"op":"mcm","clk":"4217196117","pt":1631558451366,"mc":[{"id":"1.187566733","rc":[{"batb":[[0,1.55,155.15],[1,1.54,102.9],[2,1.48,17.07]],"ltp":1.56,"tv":178080.4,"id":9323645}]}]}
{"op":"mcm","clk":"4217196338","pt":1631558452850,"mc":[{"id":"1.187566733","rc":[{"trd":[[2.6,0.4]],"batb":[[0,2,2.22]],"ltp":2.6,"tv":15831.12,"id":8734382},{"trd":[[1.63,512.53],[1.65,341.26]],"batb":[[0,1.65,1233.39],[1,1.55,155.15],[2,1.54,102.9]],"batl":[[0,1.69,256.02],[1,3.8,27.46],[2,8.8,7.23]],"ltp":1.65,"tv":178934.2,"id":9323645}],"tv":194765.32}]}
{"op":"mcm","clk":"4217196504","pt":1631558453970,"mc":[{"id":"1.187566733","rc":[{"trd":[[1.65,1286.59]],"batb":[[0,1.65,760.83]],"ltp":1.65,"tv":179879.53,"id":9323645}],"tv":195710.65}]}
{"op":"mcm","clk":"4217196624","pt":1631558454762,"mc":[{"id":"1.187566733","rc":[{"batb":[[1,1.54,102.9],[2,1.48,17.07]],"ltp":1.65,"tv":179879.53,"id":9323645}]}]}
{"op":"mcm","clk":"4217196750","pt":1631558455665,"mc":[{"id":"1.187566733","rc":[{"trd":[[1.65,1428.42]],"batb":[[0,1.65,689.93],[1,1.63,11.09],[2,1.54,102.9]],"ltp":1.65,"tv":180021.36,"id":9323645}],"tv":195852.48}]}
{"op":"mcm","clk":"4217196840","pt":1631558456354,"mc":[{"id":"1.187566733","rc":[{"trd":[[1.65,1599.05]],"batb":[[0,1.65,604.64]],"ltp":1.65,"tv":180191.99,"id":9323645}],"tv":196023.11}]}
{"op":"mcm","clk":"4217196960","pt":1631558457256,"mc":[{"id":"1.187566733","rc":[{"trd":[[1.65,1769.69]],"batb":[[0,1.65,519.35]],"ltp":1.65,"tv":180362.62,"id":9323645}],"tv":196193.74}]}
{"op":"mcm","clk":"4217197350","pt":1631558460056,"mc":[{"id":"1.187566733","rc":[{"trd":[[1.65,1785.59]],"batb":[[0,1.65,511.4],[2,1.6,260.81]],"ltp":1.65,"tv":180378.52,"id":9323645}],"tv":196209.64}]}
{"op":"mcm","clk":"4217197661","pt":1631558462083,"mc":[{"id":"1.187566733","rc":[{"batl":[[0,3.8,27.46],[1,8.8,7.23],[2,44,7.23]],"ltp":1.65,"tv":180378.52,"id":9323645}]}]}
{"op":"mcm","clk":"4217197748","pt":1631558462667,"mc":[{"id":"1.187566733","rc":[{"trd":[[1.65,2808.65]],"batb":[[0,1.63,11.09],[1,1.6,260.81],[2,1.54,102.9]],"batl":[[0,1.65,43.04],[1,3.8,27.46],[2,8.8,7.23]],"ltp":1.65,"tv":181401.58,"id":9323645}],"tv":197232.71}]}
{"op":"mcm","clk":"4217197953","pt":1631558464190,"mc":[{"id":"1.187566733","rc":[{"batl":[[0,2.78,8.9],[1,2.82,12],[2,3.05,2]],"ltp":2.6,"tv":15831.12,"id":8734382},{"trd":[[1.6,26.94],[1.63,534.72]],"batb":[[0,1.6,247.34],[1,1.54,102.9],[2,1.49,10.33]],"ltp":1.6,"tv":181450.71,"id":9323645}],"tv":197281.83}]}
{"op":"mcm","clk":"4217198111","pt":1631558465148,"mc":[{"id":"1.187566733","rc":[{"trd":[[2.46,120]],"batl":[[1,3.15,3.17],[2,6.8,13.24]],"ltp":2.46,"tv":15951.12,"id":8734382},{"trd":[[1.69,174.66]],"batb":[[0,1.69,125.34],[1,1.6,247.34],[2,1.54,102.9]],"batl":[[0,3.8,27.46],[1,8.8,7.23],[2,44,7.23]],"ltp":1.69,"tv":181625.37,"id":9323645}],"tv":197576.49}]}
{"op":"mcm","clk":"4217198235","pt":1631558465990,"mc":[{"id":"1.187566733","rc":[{"batb":[[1,1.66,129.3],[2,1.6,247.34]],"ltp":1.69,"tv":181625.37,"id":9323645}]}]}
{"op":"mcm","clk":"4217198424","pt":1631558467051,"mc":[{"id":"1.187566733","rc":[{"batb":[[1,1.65,262.57]],"ltp":1.69,"tv":181625.37,"id":9323645}]}]}
{"op":"mcm","clk":"4217198516","pt":1631558467889,"mc":[{"id":"1.187566733","rc":[{"batb":[[1,1.63,256.02]],"batl":[[0,1.77,122.26],[1,3.8,27.46],[2,8.8,7.23]],"ltp":1.69,"tv":181625.37,"id":9323645}]}]}
{"op":"mcm","clk":"4217198695","pt":1631558469154,"mc":[{"id":"1.187566733","rc":[{"batl":[[1,3.1,23.99],[2,3.15,3.17]],"ltp":2.46,"tv":15951.12,"id":8734382},{"trd":[[1.63,536.38],[1.69,425.34]],"batb":[[0,1.63,255.19],[1,1.61,139.9]],"ltp":1.63,"tv":181877.71,"id":9323645}],"tv":197828.83}]}
{"op":"mcm","clk":"4217198723","pt":1631558469362,"mc":[{"id":"1.187566733","rc":[{"batl":[[1,3.15,3.17],[2,6.8,13.24]],"ltp":2.46,"tv":15951.12,"id":8734382}]}]}
{"op":"mcm","clk":"4217198962","pt":1631558470896,"mc":[{"id":"1.187566733","rc":[{"batb":[[0,1.67,75.49],[1,1.63,255.19],[2,1.61,139.9]],"batl":[[1,1.8,64.92],[2,3.8,27.46]],"ltp":1.63,"tv":181877.71,"id":9323645}]}]}
{"op":"mcm","clk":"4217199140","pt":1631558472081,"mc":[{"id":"1.187566733","rc":[{"batb":[[2,1.6,247.34]],"ltp":1.63,"tv":181877.71,"id":9323645}]}]}
{"op":"mcm","clk":"4217199167","pt":1631558472291,"mc":[{"id":"1.187566733","rc":[{"batb":[[1,1.64,76.42],[2,1.63,255.19]],"batl":[[0,1.76,65.82],[1,1.77,122.26],[2,1.8,64.92]],"ltp":1.63,"tv":181877.71,"id":9323645}]}]}
{"op":"mcm","clk":"4217199440","pt":1631558474093,"mc":[{"id":"1.187566733","rc":[{"trd":[[2.3,259.14]],"batl":[[2,3.35,46.7]],"ltp":2.3,"tv":15958.69,"id":8734382},{"trd":[[1.76,923.58]],"batb":[[0,1.64,76.42],[1,1.63,255.19],[2,1.6,247.34]],"batl":[[0,1.76,55.93]],"ltp":1.76,"tv":181887.6,"id":9323645}],"tv":197846.29}]}
{"op":"mcm","clk":"4217199534","pt":1631558474674,"mc":[{"id":"1.187566733","rc":[{"batl":[[0,3.15,3.17],[1,6.8,13.24],[2,7,6.61]],"ltp":2.3,"tv":15958.69,"id":8734382},{"batb":[[0,1.64,209.76]],"ltp":1.76,"tv":181887.6,"id":9323645}]}]}
{"op":"mcm","clk":"4217199729","pt":1631558475992,"mc":[{"id":"1.187566733","rc":[{"batb":[[0,1.64,343.1]],"ltp":1.76,"tv":181887.6,"id":9323645}]}]}
{"op":"mcm","clk":"4217199813","pt":1631558476572,"mc":[{"id":"1.187566733","rc":[{"batl":[[0,990,0.01],[1,6.8,0],[2,7,0]],"ltp":2.3,"tv":15958.69,"id":8734382}]}]}
{"op":"mcm","clk":"4217200036","pt":1631558478091,"mc":[{"id":"1.187566733","rc":[{"trd":[[1.64,38.54]],"batb":[[0,1.66,129.3]],"batl":[[0,1.77,122.26],[1,3.8,27.46],[2,8.8,7.23]],"ltp":1.64,"tv":181926.14,"id":9323645}],"tv":197884.83}]}
{"op":"mcm","clk":"4217200210","pt":1631558479177,"mc":[{"id":"1.187566733","rc":[{"batl":[[0,3.6,36.51],[1,990,0.01]],"ltp":2.3,"tv":15958.69,"id":8734382},{"batb":[[0,1.68,73.21],[1,1.66,129.3],[2,1.65,131.29]],"batl":[[1,1.79,9.75],[2,1.84,256.02]],"ltp":1.64,"tv":181926.14,"id":9323645}]}]}
{"op":"mcm","clk":"4217200223","pt":1631558479281,"mc":[{"id":"1.187566733","rc":[{"batb":[[0,1.66,129.3],[1,1.65,131.29],[2,1.63,255.19]],"ltp":1.64,"tv":181926.14,"id":9323645}]}]}
{"op":"mcm","clk":"4217200525","pt":1631558481286,"mc":[{"id":"1.187566733","rc":[{"batb":[[0,1.68,234.77],[1,1.66,129.3],[2,1.65,131.29]],"ltp":1.64,"tv":181926.14,"id":9323645}]}]}
{"op":"mcm","clk":"4217200669","pt":1631558482402,"mc":[{"id":"1.187566733","rc":[{"batl":[[0,2.3,10],[1,3.6,36.51],[2,990,0.01]],"ltp":2.3,"tv":15958.69,"id":8734382}]}]}
{"op":"mcm","clk":"4217200877","pt":1631558483771,"mc":[{"id":"1.187566733","rc":[{"batb":[[1,1.63,255.19],[2,1.61,9.69]],"ltp":1.64,"tv":181926.14,"id":9323645}]}]}
{"op":"mcm","clk":"4217201201","pt":1631558486088,"mc":[{"id":"1.187566733","rc":[{"batb":[[0,1.7,4457.13],[1,1.69,247.35],[2,1.68,234.77]],"ltp":1.64,"tv":181926.14,"id":9323645}]}]}
{"op":"mcm","clk":"4217201283","pt":1631558486677,"mc":[{"id":"1.187566733","rc":[{"batb":[[2,1.39,875.91]],"ltp":1.64,"tv":181926.14,"id":9323645}]}]}
{"op":"mcm","clk":"4217201444","pt":1631558487882,"mc":[{"id":"1.187566733","rc":[{"trd":[[1.77,295.39],[1.79,19.5],[1.84,591.88]],"batb":[[0,1.84,1232.69],[1,1.7,4457.13],[2,1.69,247.35]],"batl":[[0,3.8,27.46],[1,8.8,7.23],[2,44,7.23]],"ltp":1.84,"tv":182781.99,"id":9323645}],"tv":198740.68}]}
{"op":"mcm","clk":"4217201632","pt":1631558488994,"mc":[{"id":"1.187566733","rc":[{"trd":[[2.2,76.34]],"ltp":2.2,"tv":16035.03,"id":8734382},{"trd":[[1.84,1918.88]],"batb":[[0,1.84,523.68]],"batl":[[0,990,0.01],[1,8.8,0],[2,44,0]],"ltp":1.84,"tv":184108.98,"id":9323645}],"tv":200144.02}]}
{"op":"mcm","clk":"4217201849","pt":1631558490197,"mc":[{"id":"1.187566733","rc":[{"batl":[[1,3.3,3.03],[2,3.6,36.51]],"ltp":2.2,"tv":16035.03,"id":8734382},{"trd":[[1.84,1930.87]],"batb":[[0,1.84,517.68],[2,1.39,875.91]],"ltp":1.84,"tv":184120.98,"id":9323645}],"tv":200156.01}]}
{"op":"mcm","clk":"4217201981","pt":1631558491193,"mc":[{"id":"1.187566733","rc":[{"trd":[[1.84,2010.86]],"batb":[[0,1.84,477.7],[1,1.71,240.38],[2,1.7,4457.13]],"ltp":1.84,"tv":184200.97,"id":9323645}],"tv":200236.0}]}
{"op":"mcm","clk":"4217202104","pt":1631558492092,"mc":[{"id":"1.187566733","rc":[{"batl":[[1,2.78,11.34],[2,3.3,3.03]],"ltp":2.2,"tv":16035.03,"id":8734382},{"trd":[[1.84,2966.44]],"batb":[[0,1.7,4457.13],[1,1.39,875.91],[2,1.36,2]],"batl":[[0,1.82,46],[1,1.84,2],[2,990,0.01]],"ltp":1.84,"tv":185156.55,"id":9323645}],"tv":201191.58}]}
{"op":"mcm","clk":"4217202253","pt":1631558493201,"mc":[{"id":"1.187566733","rc":[{"batl":[[0,1.82,85.34],[1,1.83,85.34],[2,1.84,91.34]],"ltp":1.84,"tv":185156.55,"id":9323645}]}]}
{"op":"mcm","clk":"4217202384","pt":1631558493990,"mc":[{"id":"1.187566733","rc":[{"trd":[[2.3,269.14]],"batl":[[0,2.78,11.34],[1,3.3,3.03],[2,3.6,36.51]],"ltp":2.3,"tv":16045.03,"id":8734382},{"trd":[[1.7,414.02],[1.76,936.65]],"batb":[[0,1.72,503.18],[1,1.7,4393.84],[2,1.39,875.91]],"batl":[[0,1.82,256.02],[1,1.83,256.02],[2,1.84,818.72]],"ltp":1.7,"tv":185296.21,"id":9323645}],"tv":201341.25}]}
{"op":"mcm","clk":"4217202563","pt":1631558495208,"mc":[{"id":"1.187566733","rc":[{"trd":[[1.72,10.43]],"batb":[[0,1.72,497.97],[1,1.71,78.18],[2,1.7,4393.84]],"batl":[[0,1.81,60.8],[1,1.82,256.02],[2,1.83,256.02]],"ltp":1.72,"tv":185306.64,"id":9323645}],"tv":201351.68}]}
{"op":"mcm","clk":"4217202836","pt":1631558497112,"mc":[{"id":"1.187566733","rc":[{"batb":[[0,1.73,119.69],[1,1.72,497.97],[2,1.71,78.18]],"ltp":1.72,"tv":185306.64,"id":9323645}]}]}
{"op":"mcm","clk":"4217202937","pt":1631558497803,"mc":[{"id":"1.187566733","rc":[{"trd":[[2.22,7.36]],"ltp":2.22,"tv":16052.39,"id":8734382},{"trd":[[1.81,43.16]],"batb":[[1,1.72,542.54]],"batl":[[0,1.81,51.77]],"ltp":1.81,"tv":185315.67,"id":9323645}],"tv":201368.07}]}
{"op":"mcm","clk":"4217203132","pt":1631558499112,"mc":[{"id":"1.187566733","rc":[{"batl":[[0,3.05,46.3]],"ltp":2.22,"tv":16052.39,"id":8734382},{"batb":[[0,1.77,20.17],[1,1.76,40.55],[2,1.75,61.18]],"batl":[[0,1.8,69.72],[1,1.81,51.77],[2,1.82,369.79]],"ltp":1.81,"tv":185315.67,"id":9323645}]}]}
{"op":"mcm","clk":"4217203217","pt":1631558499691,"mc":[{"id":"1.187566733","rc":[{"batl":[[0,3.3,3.03],[1,3.6,36.51],[2,8,3.76]],"ltp":2.22,"tv":16052.39,"id":8734382}]}]}
{"op":"mcm","clk":"4217203354","pt":1631558500593,"mc":[{"id":"1.187566733","rc":[{"batb":[[0,1.73,164.01],[1,1.72,497.97],[2,1.71,78.18]],"batl":[[0,1.81,51.77],[1,1.82,369.79],[2,1.84,6]],"ltp":1.81,"tv":185315.67,"id":9323645}]}]}
{"op":"mcm","clk":"4217203540","pt":1631558502014,"mc":[{"id":"1.187566733","rc":[{"batl":[[0,2.66,14.11],[1,3.3,3.03],[2,3.6,36.51]],"ltp":2.22,"tv":16052.39,"id":8734382},{"trd":[[1.81,146.68],[1.82,739.39],[1.84,3002.87]],"batb":[[0,1.84,2531.85],[1,1.73,44.32],[2,1.72,497.97]],"batl":[[0,990,0.01],[1,1.82,0],[2,1.84,0]],"ltp":1.84,"tv":186195.02,"id":9323645}],"tv":202247.42}]}
{"op":"mcm","clk":"4217203680","pt":1631558503016,"mc":[{"id":"1.187566733","rc":[{"batl":[[0,3.15,49.5]],"ltp":2.22,"tv":16052.39,"id":8734382},{"trd":[[1.84,3176.39]],"batb":[[0,1.84,2445.11],[1,1.78,20.05],[2,1.77,40.32]],"ltp":1.84,"tv":186368.54,"id":9323645}],"tv":202420.94}]}
{"op":"mcm","clk":"4217203823","pt":1631558503921,"mc":[{"id":"1.187566733","rc":[{"trd":[[1.84,3231.69]],"batb":[[0,1.84,2417.47],[1,1.74,492.24],[2,1.73,44.32]],"ltp":1.84,"tv":186423.84,"id":9323645}],"tv":202476.24}]}
{"op":"mcm","clk":"4217204149","pt":1631558505829,"mc":[{"id":"1.187566733","rc":[{"batl":[[1,990,0.01],[2,3.6,0]],"ltp":2.22,"tv":16052.39,"id":8734382},{"trd":[[1.84,3256.13]],"batb":[[0,1.74,492.24],[1,1.73,44.32],[2,1.7,4393.84]],"ltp":1.84,"tv":186448.27,"id":9323645}],"tv":202500.67}]}
{"op":"mcm","clk":"4217204274","pt":1631558506621,"mc":[{"id":"1.187566733","rc":[{"batb":[[0,1.86,250.5],[1,1.74,492.24],[2,1.73,44.32]],"ltp":1.84,"tv":186448.27,"id":9323645}]}]}
{"op":"mcm","clk":"4217204497","pt":1631558508109,"mc":[{"id":"1.187566733","rc":[{"batb":[[2,1.7,4393.84]],"ltp":1.84,"tv":186448.27,"id":9323645}]}]}
{"op":"mcm","clk":"4217204612","pt":1631558508944,"mc":[{"id":"1.187566733","rc":[{"trd":[[1.84,3339.01],[1.86,554.58]],"batb":[[0,1.74,492.24],[1,1.4,11.69],[2,1.36,2]],"batl":[[0,1.84,62.21],[1,990,0.01]],"ltp":1.84,"tv":187032.16,"id":9323645}],"tv":203084.56}]}
{"op":"mcm","clk":"4217204747","pt":1631558509936,"mc":[{"id":"1.187566733","rc":[{"batl":[[0,2.24,20],[1,3.15,49.5],[2,990,0.01]],"ltp":2.22,"tv":16052.39,"id":8734382},{"batl":[[0,1.84,36.61]],"ltp":1.84,"tv":187032.16,"id":9323645}]}]}
{"op":"mcm","clk":"4217204918","pt":1631558511118,"mc":[{"id":"1.187566733","rc":[{"batb":[[0,2.18,2.02],[1,2,2.22],[2,1.49,1.2]],"ltp":2.22,"tv":16052.39,"id":8734382},{"batb":[[0,1.75,43.81],[1,1.74,492.24],[2,1.4,11.69]],"batl":[[0,1.86,4.36]],"ltp":1.84,"tv":187032.16,"id":9323645}]}]}
{"op":"mcm","clk":"4217205046","pt":1631558512025,"mc":[{"id":"1.187566733","rc":[{"trd":[[2.24,89.88]],"batb":[[0,2.18,14.46]],"batl":[[0,3.15,49.5],[1,990,0.01],[2,990,0]],"ltp":2.24,"tv":16055.85,"id":8734382},{"trd":[[1.8,151.85]],"batl":[[0,1.84,1.07]],"ltp":1.8,"tv":187036.47,"id":9323645}],"tv":203092.33}]}
{"op":"mcm","clk":"4217205333","pt":1631558514036,"mc":[{"id":"1.187566733","rc":[{"trd":[[2,300.45],[2.06,4.03],[2.18,0.9],[2.34,16.14]],"batb":[[0,2,1.12],[1,1.49,1.2],[2,1.09,1.2]],"batl":[[0,3.15,52.67]],"ltp":2.0,"tv":16075.09,"id":8734382},{"trd":[[1.84,3340.08]],"batb":[[0,1.75,157.6],[2,1.68,72.02]],"batl":[[0,990,0.01],[1,990,0]],"ltp":1.84,"tv":187037.54,"id":9323645}],"tv":203112.64}]}
{"op":"mcm","clk":"4217205470","pt":1631558515009,"mc":[{"id":"1.187566733","rc":[{"batb":[[1,1.97,15.22],[2,1.96,7.62]],"ltp":2.0,"tv":16075.09,"id":8734382},{"batb":[[0,1.75,271.38],[1,1.68,72.02],[2,1.4,11.69]],"batl":[[0,1.76,2],[1,1.8,24.83],[2,990,0.01]],"ltp":1.84,"tv":187037.54,"id":9323645}]}]}
{"op":"mcm","clk":"4217205593","pt":1631558515905,"mc":[{"id":"1.187566733","rc":[{"trd":[[1.76,940.65],[1.8,251.19]],"batb":[[0,1.84,101.59],[1,1.83,102.82],[2,1.8,55.01]],"batl":[[0,990,0.01],[1,1.8,0],[2,990,0]],"ltp":1.8,"tv":187140.87,"id":9323645}],"tv":203215.97}]}
{"op":"mcm","clk":"4217205752","pt":1631558517010,"mc":[{"id":"1.187566733","rc":[{"trd":[[2.18,9.57]],"ltp":2.18,"tv":16083.76,"id":8734382},{"trd":[[1.85,21.04]],"batb":[[0,1.85,452.76],[1,1.84,101.59],[2,1.83,102.82]],"ltp":1.85,"tv":187151.09,"id":9323645}],"tv":203234.86}]}
{"op":"mcm","clk":"4217205897","pt":1631558518037,"mc":[{"id":"1.187566733","rc":[{"batb":[[1,1.83,102.82],[2,1.82,104.07]],"ltp":1.85,"tv":187151.09,"id":9323645}]}]}
{"op":"mcm","clk":"4217206005","pt":1631558518847,"mc":[{"id":"1.187566733","rc":[{"trd":[[1.85,166.33]],"batb":[[0,1.85,380.1]],"ltp":1.85,"tv":187296.39,"id":9323645}],"tv":203380.15}]}
{"op":"mcm","clk":"4217206182","pt":1631558520009,"mc":[{"id":"1.187566733","rc":[{"trd":[[2.18,22.04]],"batl":[[0,2.64,61.93],[1,3.15,52.67],[2,990,0.01]],"ltp":2.18,"tv":16096.23,"id":8734382},{"trd":[[1.85,181.04]],"batb":[[0,1.85,365.4],[1,1.7,11.16],[2,1.68,72.02]],"ltp":1.85,"tv":187311.09,"id":9323645}],"tv":203407.33}]}
{"op":"mcm","clk":"4217206437","pt":1631558521950,"mc":[{"id":"1.187566733","rc":[{"trd":[[1.86,562.94]],"batb":[[0,1.86,95.04],[1,1.85,365.4],[2,1.7,11.16]],"ltp":1.86,"tv":187319.45,"id":9323645}],"tv":203415.69}]}
{"op":"mcm","clk":"4217206606","pt":1631558523110,"mc":[{"id":"1.187566733","rc":[{"trd":[[2.18,28.51]],"ltp":2.18,"tv":16102.71,"id":8734382},{"trd":[[1.86,575.89]],"batb":[[0,1.86,184],[2,1.84,2971.42]],"ltp":1.86,"tv":187332.4,"id":9323645}],"tv":203435.11}]}
{"op":"mcm","clk":"4217206704","pt":1631558523840,"mc":[{"id":"1.187566733","rc":[{"batb":[[0,1.86,283.22]],"ltp":1.86,"tv":187332.4,"id":9323645}]}]}
{"op":"mcm","clk":"4217207157","pt":1631558527055,"mc":[{"id":"1.187566733","rc":[{"trd":[[1.86,616.63]],"batb":[[0,1.86,262.85]],"ltp":1.86,"tv":187373.14,"id":9323645}],"tv":203475.85}]}
{"op":"mcm","clk":"4217207314","pt":1631558528155,"mc":[{"id":"1.187566733","rc":[{"batl":[[0,1.99,170.68],[1,990,0.01]],"ltp":1.86,"tv":187373.14,"id":9323645}]}]}
{"op":"mcm","clk":"4217207367","pt":1631558528528,"mc":[{"id":"1.187566733","rc":[{"trd":[[1.99,0.03]],"batl":[[0,1.99,170.66]],"ltp":1.99,"tv":187373.17,"id":9323645}],"tv":203475.88}]}
{"op":"mcm","clk":"4217207592","pt":1631558530163,"mc":[{"id":"1.187566733","rc":[{"batl":[[0,2.36,7.93],[1,2.64,61.93],[2,3.15,52.67]],"ltp":2.18,"tv":16102.71,"id":8734382},{"trd":[[1.86,706.52]],"batb":[[0,1.86,217.9],[1,1.84,2971.42],[2,1.68,72.02]],"batl":[[1,2.18,256.02],[2,990,0.01]],"ltp":1.86,"tv":187463.07,"id":9323645}],"tv":203565.78}]}
{"op":"mcm","clk":"4217207715","pt":1631558531050,"mc":[{"id":"1.187566733","rc":[{"batl":[[0,2.64,61.93],[1,3.15,52.67],[2,990,0.01]],"ltp":2.18,"tv":16102.71,"id":8734382},{"batb":[[2,1.76,91.45]],"ltp":1.86,"tv":187463.07,"id":9323645}]}]}
{"op":"mcm","clk":"4217207839","pt":1631558531834,"mc":[{"id":"1.187566733","rc":[{"batb":[[0,1.96,830.25],[1,1.87,361.49],[2,1.86,217.9]],"ltp":1.86,"tv":187463.07,"id":9323645}]}]}
{"op":"mcm","clk":"4217208025","pt":1631558533148,"mc":[{"id":"1.187566733","rc":[{"trd":[[1.96,19.82]],"batb":[[0,1.96,820.34]],"ltp":1.96,"tv":187482.88,"id":9323645}],"tv":203585.59}]}
{"op":"mcm","clk":"4217208344","pt":1631558535158,"mc":[{"id":"1.187566733","rc":[{"batl":[[1,2.8,52.42],[2,3.15,52.67]],"ltp":2.18,"tv":16102.71,"id":8734382},{"batl":[[0,1.98,121.65],[1,1.99,170.66],[2,2.18,256.02]],"ltp":1.96,"tv":187482.88,"id":9323645}]}]}
{"op":"mcm","clk":"4217208411","pt":1631558535632,"mc":[{"id":"1.187566733","rc":[{"trd":[[1.96,100.74]],"batb":[[0,1.96,779.89],[2,1.85,94.61]],"ltp":1.96,"tv":187563.8,"id":9323645}],"tv":203666.51}]}
{"op":"mcm","clk":"4217208624","pt":1631558537172,"mc":[{"id":"1.187566733","rc":[{"trd":[[1.96,298.7]],"batb":[[0,1.96,680.93],[2,1.86,102.09]],"ltp":1.96,"tv":187761.77,"id":9323645}],"tv":203864.48}]}
{"op":"mcm","clk":"4217208714","pt":1631558537540,"mc":[{"id":"1.187566733","rc":[{"trd":[[1.96,639.97]],"batb":[[0,1.96,510.35]],"ltp":1.96,"tv":188103.03,"id":9323645}],"tv":204205.74}]}
{"op":"mcm","clk":"4217208936","pt":1631558539165,"mc":[{"id":"1.187566733","rc":[{"trd":[[1.96,709.37]],"batb":[[0,1.96,475.66]],"ltp":1.96,"tv":188172.43,"id":9323645}],"tv":204275.14}]}
{"op":"mcm","clk":"4217209091","pt":1631558540167,"mc":[{"id":"1.187566733","rc":[{"trd":[[2,301.57]],"batb":[[0,1.49,1.2],[1,1.09,1.2],[2,1.02,10.39]],"batl":[[0,2.24,12.34],[1,2.64,61.93],[2,2.8,52.42]],"ltp":2.0,"tv":16103.83,"id":8734382},{"trd":[[1.96,794.24],[1.99,341.26],[2,142.63]],"batb":[[0,2,2757.33],[1,1.96,433.23],[2,1.87,361.49]],"batl":[[0,2.18,256.02],[1,990,0.01],[2,2.18,0]],"ltp":2.0,"tv":188684.48,"id":9323645}],"tv":204788.31}]}
{"op":"mcm","clk":"4217209216","pt":1631558541165,"mc":[{"id":"1.187566733","rc":[{"batl":[[0,2.02,100]],"ltp":2.0,"tv":16103.83,"id":8734382},{"trd":[[2,268.68]],"batb":[[0,2,2694.32]],"ltp":2.0,"tv":188810.52,"id":9323645}],"tv":204914.35}]}
{"op":"mcm","clk":"4217209323","pt":1631558542057,"mc":[{"id":"1.187566733","rc":[{"trd":[[2,582.8]],"batb":[[0,2,2537.31],[2,1.89,265.52]],"ltp":2.0,"tv":189124.64,"id":9323645}],"tv":205228.47}]}
{"op":"mcm","clk":"4217209474","pt":1631558543164,"mc":[{"id":"1.187566733","rc":[{"trd":[[2,306.57]],"batl":[[2,2.7,50.95]],"ltp":2.0,"tv":16108.83,"id":8734382},{"trd":[[2,621.48]],"batb":[[0,2,2465.12]],"ltp":2.0,"tv":189163.32,"id":9323645}],"tv":205272.15}]}
