{"op":"mcm","clk":"4230748206","pt":1631536195471,"mc":[{"id":"1.187557995","rc":[{"batb":[[0,1.17,1479.56],[1,1.16,1934.7],[2,1.14,953.45]],"batl":[[0,1.19,537.73]],"ltp":1.19,"tv":94344.18,"id":9342449}]}]}
{"op":"mcm","clk":"4230748368","pt":1631536197570,"mc":[{"id":"1.187557995","rc":[{"trd":[[1.19,65.23]],"batl":[[0,1.19,534.75]],"ltp":1.19,"tv":94350.13,"id":9342449}],"tv":103804.09}]}
{"op":"mcm","clk":"4230748450","pt":1631536198475,"mc":[{"id":"1.187557995","rc":[{"trd":[[1.19,65.29]],"batl":[[0,1.19,534.72]],"ltp":1.19,"tv":94350.19,"id":9342449}],"tv":103804.15}]}
{"op":"mcm","clk":"4230748681","pt":1631536201657,"mc":[{"id":"1.187557995","rc":[{"batl":[[0,1.19,589.18]],"ltp":1.19,"tv":94350.19,"id":9342449}]}]}
{"op":"mcm","clk":"4230748883","pt":1631536203704,"mc":[{"id":"1.187557995","rc":[{"batl":[[0,1.19,534.19]],"ltp":1.19,"tv":94350.19,"id":9342449},{"batb":[[0,6.2,69.42],[1,5.8,14.5],[2,5.7,2]],"batl":[[0,7,12.54],[2,8.2,39.68]],"ltp":6.2,"tv":9453.96,"id":9633869}]}]}
{"op":"mcm","clk":"4230748967","pt":1631536204503,"mc":[{"id":"1.187557995","rc":[{"batb":[[0,1.16,150],[1,1.14,263.63],[2,1.13,903.51]],"batl":[[0,1.21,15],[1,1.22,179.73],[2,1.24,404.98]],"ltp":1.19,"tv":94350.19,"id":9342449},{"batb":[[0,5.8,12.5],[1,5.3,53.56],[2,5.1,57.03]],"batl":[[0,7,6.12],[1,8.2,35.45],[2,8.4,46.73]],"ltp":6.2,"tv":9453.96,"id":9633869}]}]}
{"op":"mcm","clk":"4230749050","pt":1631536205502,"mc":[{"id":"1.187557995","rc":[{"batb":[[0,1.14,263.63],[1,1.13,903.51],[2,1.12,2139.58]],"batl":[[0,1.22,179.73],[1,1.24,404.98],[2,1.25,227.51]],"ltp":1.19,"tv":94350.19,"id":9342449},{"batb":[[0,5.3,53.56],[1,5.1,57.03],[2,5,50.92]],"batl":[[0,8.2,35.45],[1,8.4,46.73],[2,8.6,56.18]],"ltp":6.2,"tv":9453.96,"id":9633869}]}]}
{"op":"mcm","clk":"4230749150","pt":1631536206706,"mc":[{"id":"1.187557995","rc":[{"batb":[[1,1.13,2009.18]],"batl":[[1,1.23,381.52],[2,1.24,917.59]],"ltp":1.19,"tv":94350.19,"id":9342449}]}]}
{"op":"mcm","clk":"4230749229","pt":1631536207707,"mc":[{"id":"1.187557995","rc":[{"batl":[[0,1.22,590.48],[1,1.23,770.02]],"ltp":1.19,"tv":94350.19,"id":9342449},{"batb":[[0,5.5,7.9],[1,5.3,53.56],[2,5.1,57.03]],"ltp":6.2,"tv":9453.96,"id":9633869}]}]}
{"op":"mcm","clk":"4230749301","pt":1631536208292,"mc":[{"id":"1.187557995","rc":[{"batb":[[1,1.13,903.51]],"batl":[[0,1.22,179.73],[1,1.24,404.98],[2,1.25,227.51]],"ltp":1.19,"tv":94350.19,"id":9342449},{"batb":[[0,5.3,53.56],[1,5.1,57.03],[2,5,50.92]],"ltp":6.2,"tv":9453.96,"id":9633869}]}]}
{"op":"mcm","clk":"4230749581","pt":1631536211699,"mc":[{"id":"1.187557995","rc":[{"batb":[[0,1.16,924.59],[1,1.15,269.88],[2,1.14,263.63]],"batl":[[0,1.18,285.72],[1,1.19,683.29],[2,1.22,179.73]],"ltp":1.19,"tv":94350.19,"id":9342449}]}]}
{"op":"mcm","clk":"4230749666","pt":1631536212692,"mc":[{"id":"1.187557995","rc":[{"batb":[[0,5.7,41.26],[1,5.3,53.56],[2,5.1,57.03]],"batl":[[0,8,19.53],[1,8.2,35.45],[2,8.4,46.73]],"ltp":6.2,"tv":9453.96,"id":9633869}]}]}
{"op":"mcm","clk":"4230749724","pt":1631536213506,"mc":[{"id":"1.187557995","rc":[{"batb":[[0,1.15,229.13],[1,1.14,263.63],[2,1.13,903.51]],"batl":[[0,1.22,179.73],[1,1.24,404.98],[2,1.25,227.51]],"ltp":1.19,"tv":94350.19,"id":9342449},{"batb":[[0,5.3,53.56],[1,5.1,57.03],[2,5,50.92]],"batl":[[0,8.2,35.45],[1,8.4,46.73],[2,8.6,56.18]],"ltp":6.2,"tv":9453.96,"id":9633869}]}]}
{"op":"mcm","clk":"4230749925","pt":1631536216196,"mc":[{"id":"1.187557995","rc":[{"batb":[[2,1.13,2009.18]],"batl":[[1,1.23,381.52],[2,1.24,917.59]],"ltp":1.19,"tv":94350.19,"id":9342449}]}]}
{"op":"mcm","clk":"4230750117","pt":1631536218598,"mc":[{"id":"1.187557995","rc":[{"batb":[[2,1.13,1420.59]],"batl":[[0,1.22,650.98],[1,1.23,814.02]],"ltp":1.19,"tv":94350.19,"id":9342449},{"batb":[[0,5.5,7.4],[1,5.3,53.56],[2,5.1,57.03]],"ltp":6.2,"tv":9453.96,"id":9633869}]}]}
{"op":"mcm","clk":"4230750163","pt":1631536219121,"mc":[{"id":"1.187557995","rc":[{"batl":[[0,1.22,179.73],[1,1.23,381.52]],"ltp":1.19,"tv":94350.19,"id":9342449},{"batb":[[0,5.3,53.56],[1,5.1,57.03],[2,5,50.92]],"ltp":6.2,"tv":9453.96,"id":9633869}]}]}
{"op":"mcm","clk":"4230750299","pt":1631536221115,"mc":[{"id":"1.187557995","rc":[{"batb":[[1,1.12,1787.99],[2,1.11,943.76]],"ltp":1.19,"tv":94350.19,"id":9342449},{"batl":[[0,9.4,4.64],[1,12.5,2.81],[2,990,0.01]],"ltp":6.2,"tv":9453.96,"id":9633869}]}]}
{"op":"mcm","clk":"4230750506","pt":1631536223717,"mc":[{"id":"1.187557995","rc":[{"batb":[[0,1.21,3504.97],[2,1.11,250]],"batl":[[0,1.23,381.52],[1,1.24,917.59],[2,1.25,227.51]],"ltp":1.19,"tv":94350.19,"id":9342449}]}]}
{"op":"mcm","clk":"4230750558","pt":1631536224508,"mc":[{"id":"1.187557995","rc":[{"batb":[[0,1.21,395.08],[1,1.2,661.01],[2,1.19,3408.78]],"ltp":1.19,"tv":94350.19,"id":9342449},{"trd":[[5.3,20.58]],"batb":[[0,5.3,49.47]],"batl":[[0,5.8,2],[1,6,78.34],[2,6.2,39.16]],"ltp":5.3,"tv":9462.12,"id":9633869}],"tv":103812.31}]}
{"op":"mcm","clk":"4230750670","pt":1631536225713,"mc":[{"id":"1.187557995","rc":[{"batb":[[1,1.2,1157.4],[2,1.19,3546.42]],"batl":[[2,1.25,242.51]],"ltp":1.19,"tv":94350.19,"id":9342449},{"batb":[[0,5.3,104.9],[1,5.2,27.71],[2,5.1,99.37]],"batl":[[2,6.2,45.73]],"ltp":5.3,"tv":9462.12,"id":9633869}]}]}
{"op":"mcm","clk":"4230750720","pt":1631536226330,"mc":[{"id":"1.187557995","rc":[{"batl":[[0,1.23,434.11]],"ltp":1.19,"tv":94350.19,"id":9342449},{"batb":[[0,5.4,9.77],[1,5.3,104.9],[2,5.2,27.71]],"ltp":5.3,"tv":9462.12,"id":9633869}]}]}
{"op":"mcm","clk":"4230750936","pt":1631536228639,"mc":[{"id":"1.187557995","rc":[{"batb":[[0,1.22,97.76],[1,1.21,773.39],[2,1.2,1236.02]],"batl":[[0,1.23,595.39],[1,1.24,977.94]],"ltp":1.19,"tv":94350.19,"id":9342449}]}]}
{"op":"mcm","clk":"4230750998","pt":1631536229421,"mc":[{"id":"1.187557995","rc":[{"batl":[[2,6.2,39.16]],"ltp":5.3,"tv":9462.12,"id":9633869}]}]}
{"op":"mcm","clk":"4230751161","pt":1631536231459,"mc":[{"id":"1.187557995","rc":[{"batl":[[0,1.23,737.39]],"ltp":1.19,"tv":94350.19,"id":9342449}]}]}
{"op":"mcm","clk":"4230751278","pt":1631536232617,"mc":[{"id":"1.187557995","rc":[{"batb":[[2,1.2,1370.18]],"ltp":1.19,"tv":94350.19,"id":9342449},{"batl":[[1,6,85.04]],"ltp":5.3,"tv":9462.12,"id":9633869}]}]}
{"op":"mcm","clk":"4230751478","pt":1631536235014,"mc":[{"id":"1.187557995","rc":[{"batb":[[2,1.2,1291.56]],"batl":[[1,1.24,917.59]],"ltp":1.19,"tv":94350.19,"id":9342449}]}]}
{"op":"mcm","clk":"4230751600","pt":1631536236316,"mc":[{"id":"1.187557995","rc":[{"batl":[[0,1.23,805.42]],"ltp":1.19,"tv":94350.19,"id":9342449}]}]}
{"op":"mcm","clk":"4230751723","pt":1631536237630,"mc":[{"id":"1.187557995","rc":[{"batl":[[0,1.23,737.39]],"ltp":1.19,"tv":94350.19,"id":9342449},{"batb":[[1,5.3,49.47],[2,5.1,71.66]],"batl":[[1,6,6.7],[2,7,66.71]],"ltp":5.3,"tv":9462.12,"id":9633869}]}]}
{"op":"mcm","clk":"4230751791","pt":1631536238357,"mc":[{"id":"1.187557995","rc":[{"batb":[[0,1.2,134.16],[1,1.18,430.15],[2,1.16,237.07]],"batl":[[0,1.23,142],[1,1.25,15],[2,1.27,355.5]],"ltp":1.19,"tv":94350.19,"id":9342449},{"batb":[[0,5.1,14.63],[1,4.7,8.92],[2,4.6,74.06]],"batl":[[0,6,6.7],[1,7,43.51],[2,7.2,45.91]],"ltp":5.3,"tv":9462.12,"id":9633869}]}]}
{"op":"mcm","clk":"4230751871","pt":1631536239456,"mc":[{"id":"1.187557995","rc":[{"batb":[[0,1.18,430.15],[1,1.16,237.07],[2,1.15,1679.33]],"batl":[[0,1.27,355.5],[1,1.28,353.59],[2,1.29,207.61]],"ltp":1.19,"tv":94350.19,"id":9342449},{"batb":[[0,4.7,8.92],[1,4.6,74.06],[2,4.5,9.3]],"batl":[[0,7,43.51],[1,7.2,45.91],[2,7.4,51.81]],"ltp":5.3,"tv":9462.12,"id":9633869}]}]}
{"op":"mcm","clk":"4230751885","pt":1631536239764,"mc":[{"id":"1.187557995","rc":[{"batl":[[0,1.29,207.61],[1,1.3,529.82],[2,1.31,226.44]],"ltp":1.19,"tv":94350.19,"id":9342449},{"batb":[[0,4.6,74.06],[1,4.4,66.01],[2,4.3,76.74]],"ltp":5.3,"tv":9462.12,"id":9633869}]}]}
{"op":"mcm","clk":"4230752031","pt":1631536241553,"mc":[{"id":"1.187557995","rc":[{"batb":[[1,1.16,801.16],[2,1.15,2312.85]],"batl":[[0,1.28,311.68],[1,1.29,613.58],[2,1.3,529.82]],"ltp":1.19,"tv":94350.19,"id":9342449}]}]}
{"op":"mcm","clk":"4230752107","pt":1631536242482,"mc":[{"id":"1.187557995","rc":[{"batb":[[1,1.15,1366.28],[2,1.14,636.58]],"ltp":1.19,"tv":94350.19,"id":9342449},{"batl":[[0,7.8,4.47],[1,9.4,4.64],[2,10.5,3.49]],"ltp":5.3,"tv":9462.12,"id":9633869}]}]}
{"op":"mcm","clk":"4230752204","pt":1631536243670,"mc":[{"id":"1.187557995","rc":[{"batb":[[2,1.12,935.79]],"ltp":1.19,"tv":94350.19,"id":9342449}]}]}
{"op":"mcm","clk":"4230752295","pt":1631536244661,"mc":[{"id":"1.187557995","rc":[{"batb":[[0,1.25,1257.49]],"ltp":1.19,"tv":94350.19,"id":9342449}]}]}
{"op":"mcm","clk":"4230752388","pt":1631536245671,"mc":[{"id":"1.187557995","rc":[{"batb":[[0,1.26,214.27],[1,1.25,498.16],[2,1.24,1544.34]],"batl":[[0,1.27,185.36],[1,1.28,322.68],[2,1.29,613.58]],"ltp":1.19,"tv":94350.19,"id":9342449},{"trd":[[4.6,38.92]],"batb":[[0,4.7,50.32],[1,4.6,71.4],[2,4.5,3]],"batl":[[0,5.2,2],[1,7,22.35],[2,7.8,4.47]],"ltp":4.6,"tv":9471.42,"id":9633869}],"tv":103821.62}]}
{"op":"mcm","clk":"4230752459","pt":1631536246336,"mc":[{"id":"1.187557995","rc":[{"batb":[[2,1.24,1945.42]],"batl":[[0,1.28,311.68],[1,1.29,628.58],[2,1.3,529.82]],"ltp":1.19,"tv":94350.19,"id":9342449},{"batb":[[0,4.6,69.4],[1,4.4,83.65],[2,4.3,321.37]],"batl":[[0,5.2,9.31],[1,7.8,4.47],[2,9.4,4.64]],"ltp":4.6,"tv":9471.42,"id":9633869}]}]}
{"op":"mcm","clk":"4230752732","pt":1631536249381,"mc":[{"id":"1.187557995","rc":[{"batb":[[0,1.27,93.91],[1,1.26,516.23],[2,1.25,498.16]],"batl":[[0,1.28,412.99]],"ltp":1.19,"tv":94350.19,"id":9342449},{"batb":[[0,4.6,80.42]],"batl":[[0,5.1,22.35],[1,5.2,9.31],[2,7.8,4.47]],"ltp":4.6,"tv":9471.42,"id":9633869}]}]}
{"op":"mcm","clk":"4230752840","pt":1631536250683,"mc":[{"id":"1.187557995","rc":[{"batb":[[2,1.25,564.11]],"batl":[[1,1.29,701.72]],"ltp":1.19,"tv":94350.19,"id":9342449},{"batl":[[0,5.1,10],[1,5.2,2]],"ltp":4.6,"tv":9471.42,"id":9633869}]}]}
{"op":"mcm","clk":"4230752936","pt":1631536251676,"mc":[{"id":"1.187557995","rc":[{"batl":[[0,5.2,2],[1,7.8,4.47],[2,9.4,4.64]],"ltp":4.6,"tv":9471.42,"id":9633869}]}]}
{"op":"mcm","clk":"4230753035","pt":1631536252670,"mc":[{"id":"1.187557995","rc":[{"batl":[[1,5.6,45.32],[2,5.7,54.41]],"ltp":4.6,"tv":9471.42,"id":9633869}]}]}
{"op":"mcm","clk":"4230753109","pt":1631536253563,"mc":[{"id":"1.187557995","rc":[{"batl":[[0,5.1,7.4],[1,5.2,2],[2,5.6,45.32]],"ltp":4.6,"tv":9471.42,"id":9633869}]}]}
{"op":"mcm","clk":"4230753195","pt":1631536254599,"mc":[{"id":"1.187557995","rc":[{"batl":[[0,1.28,647.99]],"ltp":1.19,"tv":94350.19,"id":9342449},{"batl":[[0,5,10.28],[1,5.1,7.4],[2,5.2,2]],"ltp":4.6,"tv":9471.42,"id":9633869}]}]}
{"op":"mcm","clk":"4230753237","pt":1631536255073,"mc":[{"id":"1.187557995","rc":[{"batb":[[2,1.25,498.16]],"batl":[[1,1.29,628.58]],"ltp":1.19,"tv":94350.19,"id":9342449}]}]}
{"op":"mcm","clk":"4230753436","pt":1631536257401,"mc":[{"id":"1.187557995","rc":[{"batb":[[1,1.26,141.45],[2,1.22,407.16]],"batl":[[0,1.28,290.49],[1,1.29,15],[2,1.31,513.93]],"ltp":1.19,"tv":94350.19,"id":9342449},{"batb":[[0,4.4,17.64],[1,4.2,104.53],[2,4.1,10.24]],"batl":[[0,5.1,7.4],[1,5.6,45.32],[2,5.7,54.41]],"ltp":4.6,"tv":9471.42,"id":9633869}]}]}
{"op":"mcm","clk":"4230753556","pt":1631536258557,"mc":[{"id":"1.187557995","rc":[{"trd":[[1.27,155.94]],"batb":[[0,1.27,91.58]],"batl":[[0,1.28,55.49],[1,1.31,227.43],[2,1.32,334.36]],"ltp":1.27,"tv":94354.84,"id":9342449},{"batb":[[0,4.2,95.31],[1,4.1,10.24],[2,4,10.72]],"batl":[[0,5.6,45.32],[1,5.7,54.41],[2,5.8,59.75]],"ltp":4.6,"tv":9471.42,"id":9633869}],"tv":103826.26}]}
{"op":"mcm","clk":"4230753626","pt":1631536259400,"mc":[{"id":"1.187557995","rc":[{"batb":[[0,1.22,407.16],[1,1.21,749.24],[2,1.2,305.8]],"batl":[[0,1.31,227.43],[1,1.33,287.5],[2,1.34,217.67]],"ltp":1.27,"tv":94354.84,"id":9342449},{"batb":[[1,4,10.72],[2,3.95,60.09]],"ltp":4.6,"tv":9471.42,"id":9633869}]}]}
{"op":"mcm","clk":"4230753738","pt":1631536260590,"mc":[{"id":"1.187557995","rc":[{"batb":[[0,1.27,10],[1,1.22,407.16],[2,1.21,1072.62]],"batl":[[1,1.33,630.58],[2,1.34,548.39]],"ltp":1.27,"tv":94354.84,"id":9342449},{"batb":[[0,4.1,95.81]],"ltp":4.6,"tv":9471.42,"id":9633869}]}]}
{"op":"mcm","clk":"4230753978","pt":1631536263195,"mc":[{"id":"1.187557995","rc":[{"batb":[[0,1.27,20]],"ltp":1.27,"tv":94354.84,"id":9342449}]}]}
{"op":"mcm","clk":"4230754032","pt":1631536263768,"mc":[{"id":"1.187557995","rc":[{"batb":[[0,4.1,98.81],[1,4,13.72]],"ltp":4.6,"tv":9471.42,"id":9633869}]}]}
{"op":"mcm","clk":"4230754147","pt":1631536265275,"mc":[{"id":"1.187557995","rc":[{"batb":[[0,1.27,10]],"ltp":1.27,"tv":94354.84,"id":9342449}]}]}
{"op":"mcm","clk":"4230754429","pt":1631536268605,"mc":[{"id":"1.187557995","rc":[{"trd":[[1.31,1402.96]],"batl":[[0,1.31,217.43]],"ltp":1.31,"tv":94374.84,"id":9342449},{"batb":[[0,4.1,95.81],[1,4,10.72]],"ltp":4.6,"tv":9471.42,"id":9633869}],"tv":103846.26}]}
{"op":"mcm","clk":"4230754513","pt":1631536269699,"mc":[{"id":"1.187557995","rc":[{"batb":[[2,1.21,541.69]],"batl":[[0,1.31,550.93]],"ltp":1.31,"tv":94374.84,"id":9342449},{"batl":[[0,5.8,6.62],[1,6.6,5.26],[2,12.5,2.81]],"ltp":4.6,"tv":9471.42,"id":9633869}]}]}
{"op":"mcm","clk":"4230754593","pt":1631536270632,"mc":[{"id":"1.187557995","rc":[{"batb":[[1,1.2,506.52],[2,1.18,1157.17]],"batl":[[0,1.33,630.58],[1,1.34,548.39],[2,1.35,218.8]],"ltp":1.31,"tv":94374.84,"id":9342449},{"batl":[[0,6.6,5.26],[1,12.5,2.81],[2,990,0.01]],"ltp":4.6,"tv":9471.42,"id":9633869}]}]}
{"op":"mcm","clk":"4230754660","pt":1631536271315,"mc":[{"id":"1.187557995","rc":[{"batb":[[2,1.18,599.86]],"ltp":1.31,"tv":94374.84,"id":9342449}]}]}
{"op":"mcm","clk":"4230754761","pt":1631536272613,"mc":[{"id":"1.187557995","rc":[{"batb":[[0,1.3,409.24],[1,1.29,1898.05],[2,1.28,1438.96]],"ltp":1.31,"tv":94374.84,"id":9342449},{"trd":[[4.1,65.8]],"batb":[[0,4.1,90.62]],"ltp":4.1,"tv":9481.81,"id":9633869}],"tv":103856.65}]}
{"op":"mcm","clk":"4230754828","pt":1631536273564,"mc":[{"id":"1.187557995","rc":[{"batb":[[2,1.28,1938.9]],"batl":[[0,1.33,677.35],[2,1.35,233.8]],"ltp":1.31,"tv":94374.84,"id":9342449},{"batl":[[0,4.6,7.9],[1,5.1,33.1],[2,6.6,5.26]],"ltp":4.1,"tv":9481.81,"id":9633869}]}]}
{"op":"mcm","clk":"4230754909","pt":1631536274543,"mc":[{"id":"1.187557995","rc":[{"batb":[[2,1.28,1825.52]],"batl":[[2,1.35,218.8]],"ltp":1.31,"tv":94374.84,"id":9342449},{"batl":[[0,6.6,5.26],[1,12.5,2.81],[2,990,0.01]],"ltp":4.1,"tv":9481.81,"id":9633869}]}]}
{"op":"mcm","clk":"4230754993","pt":1631536275386,"mc":[{"id":"1.187557995","rc":[{"batb":[[0,1.31,10],[1,1.3,409.24],[2,1.29,1898.05]],"ltp":1.31,"tv":94374.84,"id":9342449}]}]}
{"op":"mcm","clk":"4230755109","pt":1631536276708,"mc":[{"id":"1.187557995","rc":[{"batb":[[0,1.31,157.52],[1,1.3,611.05]],"batl":[[0,1.32,57.92],[1,1.33,677.35],[2,1.34,548.39]],"ltp":1.31,"tv":94374.84,"id":9342449}]}]}
{"op":"mcm","clk":"4230755196","pt":1631536277691,"mc":[{"id":"1.187557995","rc":[{"batl":[[1,1.33,789.35]],"ltp":1.31,"tv":94374.84,"id":9342449},{"batb":[[1,4,30.72]],"batl":[[0,4.7,7.79],[1,6.6,5.26],[2,12.5,2.81]],"ltp":4.1,"tv":9481.81,"id":9633869}]}]}
{"op":"mcm","clk":"4230755248","pt":1631536278217,"mc":[{"id":"1.187557995","rc":[{"trd":[[1.31,1404.51]],"batb":[[0,1.31,356.14]],"ltp":1.31,"tv":94376.39,"id":9342449},{"batl":[[0,6.6,5.26],[1,12.5,2.81],[2,990,0.01]],"ltp":4.1,"tv":9481.81,"id":9633869}],"tv":103858.2}]}
{"op":"mcm","clk":"4230755346","pt":1631536279121,"mc":[{"id":"1.187557995","rc":[{"batl":[[0,4.7,55.89],[1,4.8,50.95],[2,4.9,57.47]],"ltp":4.1,"tv":9481.81,"id":9633869}]}]}
{"op":"mcm","clk":"4230755571","pt":1631536281312,"mc":[{"id":"1.187557995","rc":[{"batl":[[2,1.34,540.55]],"ltp":1.31,"tv":94376.39,"id":9342449},{"batl":[[0,4.6,7.9],[1,4.7,55.89],[2,4.8,50.95]],"ltp":4.1,"tv":9481.81,"id":9633869}]}]}
{"op":"mcm","clk":"4230755654","pt":1631536282302,"mc":[{"id":"1.187557995","rc":[{"batb":[[0,1.32,30.2],[1,1.31,267.35],[2,1.3,611.05]],"batl":[[0,1.33,861.79],[1,1.34,540.55],[2,1.35,218.8]],"ltp":1.31,"tv":94376.39,"id":9342449}]}]}
{"op":"mcm","clk":"4230755786","pt":1631536284138,"mc":[{"id":"1.187557995","rc":[{"batb":[[0,1.31,208.61],[1,1.3,611.05],[2,1.29,1898.05]],"batl":[[0,1.33,789.35]],"ltp":1.31,"tv":94376.39,"id":9342449}]}]}
{"op":"mcm","clk":"4230756055","pt":1631536287216,"mc":[{"id":"1.187557995","rc":[{"batl":[[0,4.5,33.1],[1,4.6,7.9],[2,4.7,55.89]],"ltp":4.1,"tv":9481.81,"id":9633869}]}]}
{"op":"mcm","clk":"4230756234","pt":1631536289339,"mc":[{"id":"1.187557995","rc":[{"trd":[[1.31,1422.36]],"batb":[[0,1.31,199.39]],"ltp":1.31,"tv":94394.24,"id":9342449}],"tv":103876.05}]}
{"op":"mcm","clk":"4230757727","pt":1631536307374,"mc":[{"id":"1.187557995","rc":[{"trd":[[1.33,2155.46]],"batl":[[0,1.33,749.35]],"ltp":1.33,"tv":94474.24,"id":9342449}],"tv":103956.05}]}
{"op":"mcm","clk":"4230758025","pt":1631536310563,"mc":[{"id":"1.187557995","rc":[{"batl":[[0,1.33,835.62]],"ltp":1.33,"tv":94474.24,"id":9342449}]}]}
{"op":"mcm","clk":"4230758098","pt":1631536311364,"mc":[{"id":"1.187557995","rc":[{"trd":[[1.31,1559.95]],"batb":[[0,1.31,130.7]],"ltp":1.31,"tv":94611.83,"id":9342449}],"tv":104093.64}]}
{"op":"mcm","clk":"4230761540","pt":1631536350277,"mc":[{"id":"1.187557995","rc":[{"trd":[[1.31,1599.95]],"batb":[[0,1.31,110.7]],"ltp":1.31,"tv":94651.83,"id":9342449}],"tv":104133.64}]}
{"op":"mcm","clk":"4230761834","pt":1631536353540,"mc":[{"id":"1.187557995","rc":[{"trd":[[1.31,1718.96]],"batb":[[0,1.31,51.19]],"ltp":1.31,"tv":94770.83,"id":9342449}],"tv":104252.65}]}
{"op":"mcm","clk":"4230763210","pt":1631536368668,"mc":[{"id":"1.187557995","rc":[{"batl":[[0,1.33,788.85]],"ltp":1.31,"tv":94770.83,"id":9342449},{"batl":[[0,4.6,7.9],[1,4.7,55.89],[2,4.8,50.95]],"ltp":4.1,"tv":9481.81,"id":9633869}]}]}
{"op":"mcm","clk":"4230763605","pt":1631536372693,"mc":[{"id":"1.187557995","rc":[{"batl":[[0,1.33,835.62]],"ltp":1.31,"tv":94770.83,"id":9342449},{"batl":[[0,4.5,17.17],[1,4.6,7.9],[2,4.7,55.89]],"ltp":4.1,"tv":9481.81,"id":9633869}]}]}
{"op":"mcm","clk":"4230763632","pt":1631536372959,"mc":[{"id":"1.187557995","rc":[{"batl":[[0,1.33,788.85]],"ltp":1.31,"tv":94770.83,"id":9342449},{"batl":[[0,4.6,7.9],[1,4.7,55.89],[2,4.8,50.95]],"ltp":4.1,"tv":9481.81,"id":9633869}]}]}
{"op":"mcm","clk":"4230764147","pt":1631536377862,"mc":[{"id":"1.187557995","rc":[{"trd":[[4.1,70.45]],"batb":[[0,4.1,88.29]],"ltp":4.1,"tv":9486.46,"id":9633869}],"tv":104257.3}]}
{"op":"mcm","clk":"4230764924","pt":1631536386068,"mc":[{"id":"1.187557995","rc":[{"trd":[[1.31,1720.5]],"batb":[[0,1.31,50.42]],"ltp":1.31,"tv":94772.38,"id":9342449}],"tv":104258.84}]}
{"op":"mcm","clk":"4230765471","pt":1631536391599,"mc":[{"id":"1.187557995","rc":[{"batb":[[0,1.28,571.34],[1,1.27,318.06],[2,1.26,789.25]],"batl":[[0,1.33,198.27],[1,1.38,410.38],[2,1.39,167.03]],"ltp":1.31,"tv":94772.38,"id":9342449},{"batb":[[1,4,20],[2,3.7,62.51]],"ltp":4.1,"tv":9486.46,"id":9633869}]}]}
{"op":"mcm","clk":"4230765546","pt":1631536392384,"mc":[{"id":"1.187557995","rc":[{"batb":[[0,1.28,235.95],[1,1.27,202.59]],"batl":[[0,1.38,147.13],[1,1.39,167.03],[2,1.4,227.49]],"ltp":1.31,"tv":94772.38,"id":9342449},{"batb":[[0,3.7,62.51],[1,3.6,65.86],[2,3.55,63.33]],"batl":[[0,4.7,55.89],[1,4.8,50.95],[2,4.9,65.52]],"ltp":4.1,"tv":9486.46,"id":9633869}]}]}
{"op":"mcm","clk":"4230765744","pt":1631536394520,"mc":[{"id":"1.187557995","rc":[{"batb":[[0,1.29,304.32],[1,1.28,235.95],[2,1.27,367.33]],"batl":[[0,1.32,273.8],[1,1.38,313.17],[2,1.39,444.89]],"ltp":1.31,"tv":94772.38,"id":9342449}]}]}
{"op":"mcm","clk":"4230765851","pt":1631536395611,"mc":[{"id":"1.187557995","rc":[{"batb":[[0,1.28,235.95],[1,1.27,367.33],[2,1.26,1262.53]],"batl":[[0,1.38,580.42],[1,1.39,444.89],[2,1.4,227.49]],"ltp":1.31,"tv":94772.38,"id":9342449},{"batb":[[1,3.6,76.85]],"ltp":4.1,"tv":9486.46,"id":9633869}]}]}
{"op":"mcm","clk":"4230765998","pt":1631536397100,"mc":[{"id":"1.187557995","rc":[{"batl":[[0,1.37,207.84],[1,1.38,580.42],[2,1.39,444.89]],"ltp":1.31,"tv":94772.38,"id":9342449}]}]}
{"op":"mcm","clk":"4230766182","pt":1631536399291,"mc":[{"id":"1.187557995","rc":[{"batb":[[2,1.26,1024.03]],"ltp":1.31,"tv":94772.38,"id":9342449}]}]}
{"op":"mcm","clk":"4230766259","pt":1631536400226,"mc":[{"id":"1.187557995","rc":[{"batl":[[0,1.37,214.84]],"ltp":1.31,"tv":94772.38,"id":9342449}]}]}
{"op":"mcm","clk":"4230766714","pt":1631536406006,"mc":[{"id":"1.187557995","rc":[{"trd":[[3.7,23.48]],"batb":[[0,3.7,62.31]],"ltp":3.7,"tv":9486.86,"id":9633869}],"tv":104259.24}]}
{"op":"mcm","clk":"4230766907","pt":1631536408297,"mc":[{"id":"1.187557995","rc":[{"batl":[[1,1.38,267.25],[2,1.41,259.5]],"ltp":1.31,"tv":94772.38,"id":9342449},{"batb":[[1,3.6,10.99],[2,3.4,12.76]],"ltp":3.7,"tv":9486.86,"id":9633869}]}]}
{"op":"mcm","clk":"4230767066","pt":1631536410216,"mc":[{"id":"1.187557995","rc":[{"batb":[[0,1.27,367.33],[1,1.26,1024.03],[2,1.25,699.69]],"batl":[[0,1.37,7],[1,1.38,6]],"ltp":1.31,"tv":94772.38,"id":9342449},{"batb":[[1,3.4,12.76],[2,1.97,1.05]],"ltp":3.7,"tv":9486.86,"id":9633869}]}]}
{"op":"mcm","clk":"4230767193","pt":1631536411626,"mc":[{"id":"1.187557995","rc":[{"batl":[[0,1.29,348.85],[1,1.3,388.71],[2,1.31,1459.92]],"ltp":1.31,"tv":94772.38,"id":9342449}]}]}
{"op":"mcm","clk":"4230767265","pt":1631536412406,"mc":[{"id":"1.187557995","rc":[{"trd":[[1.29,4875.51]],"batl":[[0,1.29,332.61],[1,1.3,403.71]],"ltp":1.29,"tv":94788.62,"id":9342449},{"trd":[[4.4,438.8]],"batb":[[0,4.5,79.41],[1,4.3,18.18],[2,4,104.01]],"ltp":4.4,"tv":9491.62,"id":9633869}],"tv":104280.24}]}
{"op":"mcm","clk":"4230767507","pt":1631536415410,"mc":[{"id":"1.187557995","rc":[{"batb":[[0,1.28,90.87],[1,1.27,735.06],[2,1.26,1024.03]],"batl":[[0,1.29,680.62]],"ltp":1.29,"tv":94788.62,"id":9342449},{"batb":[[0,4.5,81.41],[1,4.4,2],[2,4.3,20.18]],"ltp":4.4,"tv":9491.62,"id":9633869}]}]}
{"op":"mcm","clk":"4230767600","pt":1631536416443,"mc":[{"id":"1.187557995","rc":[{"trd":[[1.29,5540.37]],"batl":[[0,1.29,348.01],[1,1.3,388.71]],"ltp":1.29,"tv":95453.48,"id":9342449}],"tv":104945.1}]}
{"op":"mcm","clk":"4230767690","pt":1631536417637,"mc":[{"id":"1.187557995","rc":[{"batl":[[0,1.29,339.01],[2,1.31,1808.42]],"ltp":1.29,"tv":95453.48,"id":9342449},{"batb":[[0,4.5,79.41],[1,4.2,10.97],[2,4,116.73]],"ltp":4.4,"tv":9491.62,"id":9633869}]}]}
{"op":"mcm","clk":"4230767870","pt":1631536419633,"mc":[{"id":"1.187557995","rc":[{"batb":[[0,1.28,378.2],[1,1.27,918.19]],"batl":[[0,1.29,354.01],[1,1.3,781.61],[2,1.31,2175.5]],"ltp":1.29,"tv":95453.48,"id":9342449},{"trd":[[4.5,199.15]],"batb":[[0,4.2,10.97],[1,4.1,11.64]],"ltp":4.5,"tv":9650.39,"id":9633869}],"tv":105103.87}]}
{"op":"mcm","clk":"4230767952","pt":1631536420522,"mc":[{"id":"1.187557995","rc":[{"batl":[[0,1.29,400.05]],"ltp":1.29,"tv":95453.48,"id":9342449},{"batb":[[0,4.4,17.64],[1,4.2,10.97],[2,4.1,11.64]],"ltp":4.5,"tv":9650.39,"id":9633869}]}]}
{"op":"mcm","clk":"4230768020","pt":1631536421351,"mc":[{"id":"1.187557995","rc":[{"batb":[[1,1.27,996.04]],"batl":[[0,1.29,476.23]],"ltp":1.29,"tv":95453.48,"id":9342449}]}]}
{"op":"mcm","clk":"4230768215","pt":1631536423342,"mc":[{"id":"1.187557995","rc":[{"batb":[[0,1.28,287.33],[1,1.27,859.58]],"batl":[[0,1.29,341.21]],"ltp":1.29,"tv":95453.48,"id":9342449}]}]}
{"op":"mcm","clk":"4230768297","pt":1631536424437,"mc":[{"id":"1.187557995","rc":[{"batb":[[1,1.27,309.12],[2,1.25,1035.09]],"batl":[[0,1.29,295.17],[1,1.3,251.53],[2,1.32,516.46]],"ltp":1.29,"tv":95453.48,"id":9342449},{"batb":[[1,4.1,11.64],[2,4,116.73]],"batl":[[0,5,7.78],[1,5.1,40.98],[2,5.2,64.14]],"ltp":4.5,"tv":9650.39,"id":9633869}]}]}
{"op":"mcm","clk":"4230768390","pt":1631536425644,"mc":[{"id":"1.187557995","rc":[{"batb":[[0,1.25,227.43],[1,1.24,624.11],[2,1.23,658.54]],"batl":[[0,1.32,189.1],[1,1.34,428.3],[2,1.35,238.28]],"ltp":1.29,"tv":95453.48,"id":9342449},{"batb":[[0,4,104.01],[1,3.9,81.32],[2,3.85,79.89]],"batl":[[0,5.1,40.98],[1,5.2,64.14],[2,5.3,76.78]],"ltp":4.5,"tv":9650.39,"id":9633869}]}]}
{"op":"mcm","clk":"4230768609","pt":1631536427636,"mc":[{"id":"1.187557995","rc":[{"batb":[[0,1.26,238.35],[1,1.25,227.43],[2,1.24,990.96]],"batl":[[1,1.34,687.17],[2,1.35,555.61]],"ltp":1.29,"tv":95453.48,"id":9342449},{"batl":[[1,5.2,71.45]],"ltp":4.5,"tv":9650.39,"id":9633869}]}]}
{"op":"mcm","clk":"4230768704","pt":1631536428678,"mc":[{"id":"1.187557995","rc":[{"batb":[[0,1.25,227.43],[1,1.24,990.96],[2,1.23,1628.54]],"ltp":1.29,"tv":95453.48,"id":9342449},{"batb":[[0,3.95,54.64]],"batl":[[1,5.2,64.14]],"ltp":4.5,"tv":9650.39,"id":9633869}]}]}
{"op":"mcm","clk":"4230768945","pt":1631536431458,"mc":[{"id":"1.187557995","rc":[{"batb":[[1,1.24,624.11],[2,1.23,1076.35]],"batl":[[1,1.34,428.3],[2,1.35,238.28]],"ltp":1.29,"tv":95453.48,"id":9342449}]}]}
{"op":"mcm","clk":"4230769228","pt":1631536434634,"mc":[{"id":"1.187557995","rc":[{"batb":[[0,1.27,347.87],[1,1.26,711.74],[2,1.25,1583.39]],"batl":[[0,1.3,530.08],[1,1.31,545.17],[2,1.32,189.1]],"ltp":1.29,"tv":95453.48,"id":9342449}]}]}
{"op":"mcm","clk":"4230769282","pt":1631536435257,"mc":[{"id":"1.187557995","rc":[{"batb":[[0,3.95,57.64],[1,3.9,84.32]],"ltp":4.5,"tv":9650.39,"id":9633869}]}]}
{"op":"mcm","clk":"4230769448","pt":1631536437449,"mc":[{"id":"1.187557995","rc":[{"batb":[[0,1.27,579.65]],"batl":[[0,1.29,174.43],[1,1.3,530.08],[2,1.31,545.17]],"ltp":1.29,"tv":95453.48,"id":9342449}]}]}
{"op":"mcm","clk":"4230769546","pt":1631536438588,"mc":[{"id":"1.187557995","rc":[{"batb":[[0,1.27,231.78],[1,1.26,238.35],[2,1.25,227.43]],"batl":[[1,1.31,178.09],[2,1.32,189.1]],"ltp":1.29,"tv":95453.48,"id":9342449}]}]}
{"op":"mcm","clk":"4230769595","pt":1631536439060,"mc":[{"id":"1.187557995","rc":[{"batb":[[0,1.25,227.43],[1,1.24,624.11],[2,1.23,1076.35]],"batl":[[0,1.32,189.1],[1,1.33,216.35],[2,1.34,428.3]],"ltp":1.29,"tv":95453.48,"id":9342449}]}]}
{"op":"mcm","clk":"4230769658","pt":1631536439946,"mc":[{"id":"1.187557995","rc":[{"batl":[[0,1.33,216.35],[1,1.34,428.3],[2,1.35,238.28]],"ltp":1.29,"tv":95453.48,"id":9342449}]}]}
{"op":"mcm","clk":"4230769804","pt":1631536441460,"mc":[{"id":"1.187557995","rc":[{"batb":[[1,1.24,990.96],[2,1.23,1628.54]],"batl":[[1,1.34,687.17],[2,1.35,555.61]],"ltp":1.29,"tv":95453.48,"id":9342449}]}]}
{"op":"mcm","clk":"4230769963","pt":1631536443179,"mc":[{"id":"1.187557995","rc":[{"batb":[[1,1.24,624.11],[2,1.23,1076.35]],"batl":[[0,1.33,223.35],[1,1.34,428.3],[2,1.35,238.28]],"ltp":1.29,"tv":95453.48,"id":9342449},{"batb":[[0,4,3],[1,3.95,57.64],[2,3.9,84.32]],"ltp":4.5,"tv":9650.39,"id":9633869}]}]}
{"op":"mcm","clk":"4230770217","pt":1631536445675,"mc":[{"id":"1.187557995","rc":[{"batl":[[0,4.8,254.12],[1,5.1,40.98],[2,5.2,64.14]],"ltp":4.5,"tv":9650.39,"id":9633869}]}]}
{"op":"mcm","clk":"4230770235","pt":1631536445884,"mc":[{"id":"1.187557995","rc":[{"batb":[[0,1.28,270.61],[1,1.27,450.01],[2,1.25,227.43]],"batl":[[0,1.3,182.4],[1,1.31,372.19],[2,1.33,223.35]],"ltp":1.29,"tv":95453.48,"id":9342449},{"batl":[[0,5.1,40.98],[1,5.2,64.14],[2,5.3,76.78]],"ltp":4.5,"tv":9650.39,"id":9633869}]}]}
{"op":"mcm","clk":"4230770414","pt":1631536447654,"mc":[{"id":"1.187557995","rc":[{"batb":[[2,1.26,62.64]],"batl":[[2,1.32,94.68]],"ltp":1.29,"tv":95453.48,"id":9342449},{"batb":[[0,4.1,15],[1,4,3],[2,3.95,54.64]],"batl":[[0,5,22.96],[1,5.1,40.98],[2,5.2,64.14]],"ltp":4.5,"tv":9650.39,"id":9633869}]}]}
{"op":"mcm","clk":"4230770443","pt":1631536447972,"mc":[{"id":"1.187557995","rc":[{"batb":[[0,1.25,227.43],[1,1.24,624.11],[2,1.23,1076.35]],"batl":[[0,1.33,223.35],[1,1.34,428.3],[2,1.35,238.28]],"ltp":1.29,"tv":95453.48,"id":9342449},{"batb":[[0,4,3],[1,3.95,54.64],[2,3.9,81.32]],"batl":[[0,5.1,40.98],[1,5.2,64.14],[2,5.3,76.78]],"ltp":4.5,"tv":9650.39,"id":9633869}]}]}
{"op":"mcm","clk":"4230770643","pt":1631536450554,"mc":[{"id":"1.187557995","rc":[{"batb":[[0,1.28,216.22],[1,1.25,227.43],[2,1.24,624.11]],"batl":[[0,1.3,154.28],[1,1.33,223.35],[2,1.34,428.3]],"ltp":1.29,"tv":95453.48,"id":9342449}]}]}
{"op":"mcm","clk":"4230770744","pt":1631536451490,"mc":[{"id":"1.187557995","rc":[{"batb":[[0,1.25,227.43],[1,1.24,990.96],[2,1.23,1628.54]],"batl":[[0,1.33,223.35],[1,1.34,687.17],[2,1.35,555.61]],"ltp":1.29,"tv":95453.48,"id":9342449},{"batb":[[1,3.95,57.64]],"ltp":4.5,"tv":9650.39,"id":9633869}]}]}
{"op":"mcm","clk":"4230771973","pt":1631536464502,"mc":[{"id":"1.187557995","rc":[{"batl":[[1,1.34,272.75],[2,1.71,549.54]],"ltp":1.29,"tv":95453.48,"id":9342449},{"batb":[[1,3.95,54.64],[2,3.9,11.46]],"ltp":4.5,"tv":9650.39,"id":9633869}]}]}
{"op":"mcm","clk":"4230772101","pt":1631536465698,"mc":[{"id":"1.187557995","rc":[{"batb":[[0,1.24,536.11],[1,1.23,1628.54],[2,1.22,774.66]],"batl":[[0,1.26,11.52],[1,1.33,7],[2,1.34,272.75]],"ltp":1.29,"tv":95453.48,"id":9342449},{"batl":[[0,5.2,64.14],[1,5.3,76.78],[2,5.4,7.09]],"ltp":4.5,"tv":9650.39,"id":9633869}]}]}
{"op":"mcm","clk":"4230772149","pt":1631536466275,"mc":[{"id":"1.187557995","rc":[{"batb":[[2,1.22,244.45]],"batl":[[0,1.33,7],[1,1.34,272.75],[2,1.82,2.89]],"ltp":1.29,"tv":95453.48,"id":9342449}]}]}
{"op":"mcm","clk":"4230772289","pt":1631536467682,"mc":[{"id":"1.187557995","rc":[{"batl":[[0,1.26,243.55],[1,1.27,1552.39],[2,1.28,555.12]],"ltp":1.29,"tv":95453.48,"id":9342449},{"batb":[[0,4.1,397.24],[1,4,3],[2,3.95,54.64]],"ltp":4.5,"tv":9650.39,"id":9633869}]}]}
{"op":"mcm","clk":"4230772391","pt":1631536468717,"mc":[{"id":"1.187557995","rc":[{"trd":[[1.26,28.83]],"batl":[[0,1.26,226.64]],"ltp":1.26,"tv":95470.39,"id":9342449},{"trd":[[4.8,4.44]],"batb":[[0,4.7,86.08],[1,4.3,87.95],[2,4.2,15]],"ltp":4.8,"tv":9654.83,"id":9633869}],"tv":105125.22}]}
{"op":"mcm","clk":"4230772420","pt":1631536468977,"mc":[{"id":"1.187557995","rc":[{"batb":[[0,4.7,69.87],[2,4.1,3]],"ltp":4.8,"tv":9654.83,"id":9633869}]}]}
{"op":"mcm","clk":"4230772664","pt":1631536471684,"mc":[{"id":"1.187557995","rc":[{"batb":[[0,1.25,93.05],[1,1.24,821.19],[2,1.23,1628.54]],"batl":[[0,1.26,618.72],[1,1.27,1567.39]],"ltp":1.26,"tv":95470.39,"id":9342449}]}]}
{"op":"mcm","clk":"4230772732","pt":1631536472510,"mc":[{"id":"1.187557995","rc":[{"batl":[[1,1.27,1552.39]],"ltp":1.26,"tv":95470.39,"id":9342449},{"batb":[[0,4.8,15.78],[1,4.7,69.87],[2,4.3,87.95]],"ltp":4.8,"tv":9654.83,"id":9633869}]}]}
{"op":"mcm","clk":"4230772911","pt":1631536474392,"mc":[{"id":"1.187557995","rc":[{"batb":[[2,1.23,1801.97]],"ltp":1.26,"tv":95470.39,"id":9342449},{"batl":[[2,5.4,54.03]],"ltp":4.8,"tv":9654.83,"id":9633869}]}]}
{"op":"mcm","clk":"4230773014","pt":1631536475623,"mc":[{"id":"1.187557995","rc":[{"batl":[[0,1.26,633.72]],"ltp":1.26,"tv":95470.39,"id":9342449},{"batb":[[0,4.9,16.64],[1,4.8,15.78],[2,4.7,69.87]],"ltp":4.8,"tv":9654.83,"id":9633869}]}]}
{"op":"mcm","clk":"4230773151","pt":1631536477334,"mc":[{"id":"1.187557995","rc":[{"batl":[[0,1.26,580.02]],"ltp":1.26,"tv":95470.39,"id":9342449},{"batb":[[0,4.8,15.78],[1,4.7,69.87],[2,4.3,87.95]],"ltp":4.8,"tv":9654.83,"id":9633869}]}]}
{"op":"mcm","clk":"4230773234","pt":1631536478424,"mc":[{"id":"1.187557995","rc":[{"batb":[[1,1.24,898.95]],"batl":[[0,1.26,655.69]],"ltp":1.26,"tv":95470.39,"id":9342449}]}]}
{"op":"mcm","clk":"4230773262","pt":1631536478739,"mc":[{"id":"1.187557995","rc":[{"batb":[[1,1.24,821.19]],"batl":[[0,1.26,580.02]],"ltp":1.26,"tv":95470.39,"id":9342449}]}]}
{"op":"mcm","clk":"4230773453","pt":1631536480612,"mc":[{"id":"1.187557995","rc":[{"batb":[[0,1.24,757.26],[1,1.23,1801.97],[2,1.22,922.88]],"batl":[[0,1.26,513.03]],"ltp":1.26,"tv":95470.39,"id":9342449},{"trd":[[4.8,8.7]],"batb":[[0,4.8,13.65]],"ltp":4.8,"tv":9659.09,"id":9633869}],"tv":105129.48}]}
{"op":"mcm","clk":"4230773555","pt":1631536481620,"mc":[{"id":"1.187557995","rc":[{"batb":[[0,1.24,221.15],[1,1.23,1024.87],[2,1.22,678.43]],"batl":[[0,1.26,286.39],[1,1.29,237.65],[2,1.31,152.44]],"ltp":1.26,"tv":95470.39,"id":9342449},{"batl":[[0,5.4,54.03],[1,5.5,61.42],[2,5.6,58.25]],"ltp":4.8,"tv":9659.09,"id":9633869}]}]}
{"op":"mcm","clk":"4230773638","pt":1631536482487,"mc":[{"id":"1.187557995","rc":[{"batb":[[0,1.23,173.42],[1,1.22,678.43],[2,1.21,730.38]],"batl":[[0,1.26,15]],"ltp":1.26,"tv":95470.39,"id":9342449},{"batb":[[1,4.3,87.95],[2,4.2,51.23]],"batl":[[0,5.4,46.94]],"ltp":4.8,"tv":9659.09,"id":9633869}]}]}
{"op":"mcm","clk":"4230773729","pt":1631536483532,"mc":[{"id":"1.187557995","rc":[{"batl":[[0,1.29,237.65],[1,1.31,152.44],[2,1.32,178.09]],"ltp":1.26,"tv":95470.39,"id":9342449},{"batb":[[0,4.4,2]],"ltp":4.8,"tv":9659.09,"id":9633869}]}]}
{"op":"mcm","clk":"4230773810","pt":1631536484515,"mc":[{"id":"1.187557995","rc":[{"batb":[[1,1.22,983.66],[2,1.21,1346.06]],"batl":[[1,1.3,476.08],[2,1.31,520.15]],"ltp":1.26,"tv":95470.39,"id":9342449}]}]}
{"op":"mcm","clk":"4230773999","pt":1631536486691,"mc":[{"id":"1.187557995","rc":[{"batl":[[0,1.29,245.65]],"ltp":1.26,"tv":95470.39,"id":9342449},{"batb":[[1,4.3,90.95]],"ltp":4.8,"tv":9659.09,"id":9633869}]}]}
{"op":"mcm","clk":"4230774119","pt":1631536488202,"mc":[{"id":"1.187557995","rc":[{"batb":[[0,1.22,432.71],[1,1.21,476.48],[2,1.16,584.08]],"ltp":1.26,"tv":95470.39,"id":9342449},{"batl":[[0,990,0.01],[1,5.5,0],[2,5.6,0]],"ltp":4.8,"tv":9659.09,"id":9633869}]}]}
{"op":"mcm","clk":"4230774247","pt":1631536489509,"mc":[{"id":"1.187557995","rc":[{"batb":[[0,1.21,476.48],[1,1.16,584.08],[2,1.11,250]],"batl":[[0,1.3,476.08],[1,1.31,520.15],[2,1.32,170.09]],"ltp":1.26,"tv":95470.39,"id":9342449},{"batb":[[0,4.3,87.95],[1,4.2,51.23],[2,4.1,56.59]],"ltp":4.8,"tv":9659.09,"id":9633869}]}]}
{"op":"mcm","clk":"4230774284","pt":1631536489926,"mc":[{"id":"1.187557995","rc":[{"batb":[[1,1.11,250],[2,1.06,2.07]],"ltp":1.26,"tv":95470.39,"id":9342449}]}]}
{"op":"mcm","clk":"4230774437","pt":1631536491567,"mc":[{"id":"1.187557995","rc":[{"batb":[[0,1.27,460.88],[1,1.26,1992.09],[2,1.25,1473.22]],"batl":[[2,1.32,966.96]],"ltp":1.26,"tv":95470.39,"id":9342449},{"trd":[[4.3,29.91]],"batb":[[0,4.3,83.19]],"ltp":4.3,"tv":9668.61,"id":9633869}],"tv":105139.0}]}
{"op":"mcm","clk":"4230774518","pt":1631536492439,"mc":[{"id":"1.187557995","rc":[{"batb":[[1,1.26,2349.41]],"batl":[[0,1.3,491.08]],"ltp":1.26,"tv":95470.39,"id":9342449},{"batb":[[0,4.4,27.64],[1,4.3,83.19],[2,4.2,51.23]],"batl":[[0,5.2,7.31],[1,990,0.01]],"ltp":4.3,"tv":9668.61,"id":9633869}]}]}
{"op":"mcm","clk":"4230774638","pt":1631536493643,"mc":[{"id":"1.187557995","rc":[{"batl":[[0,1.3,551.15]],"ltp":1.26,"tv":95470.39,"id":9342449}]}]}
{"op":"mcm","clk":"4230774697","pt":1631536494322,"mc":[{"id":"1.187557995","rc":[{"trd":[[1.27,175.94]],"batb":[[0,1.27,450.88]],"ltp":1.27,"tv":95490.39,"id":9342449}],"tv":105159.0}]}
{"op":"mcm","clk":"4230774816","pt":1631536495632,"mc":[{"id":"1.187557995","rc":[{"batb":[[0,1.27,684.7],[2,1.25,1711.72]],"batl":[[0,1.3,727]],"ltp":1.27,"tv":95490.39,"id":9342449},{"batl":[[0,5.1,23.53],[1,5.2,7.31],[2,990,0.01]],"ltp":4.3,"tv":9668.61,"id":9633869}]}]}
{"op":"mcm","clk":"4230774879","pt":1631536496357,"mc":[{"id":"1.187557995","rc":[{"batb":[[0,1.28,161.81],[1,1.27,684.7],[2,1.26,2349.41]],"batl":[[0,1.29,260.41],[1,1.3,727],[2,1.31,520.15]],"ltp":1.27,"tv":95490.39,"id":9342449}]}]}
{"op":"mcm","clk":"4230774954","pt":1631536497236,"mc":[{"id":"1.187557995","rc":[{"batl":[[1,1.3,822]],"ltp":1.27,"tv":95490.39,"id":9342449}]}]}
{"op":"mcm","clk":"4230775035","pt":1631536498132,"mc":[{"id":"1.187557995","rc":[{"batb":[[2,1.26,2763.39]],"ltp":1.27,"tv":95490.39,"id":9342449},{"batl":[[0,4.9,7.45],[1,5.1,47.79],[2,5.2,62.98]],"ltp":4.3,"tv":9668.61,"id":9633869}]}]}
{"op":"mcm","clk":"4230775167","pt":1631536499536,"mc":[{"id":"1.187557995","rc":[{"batb":[[0,1.28,388.02]],"ltp":1.27,"tv":95490.39,"id":9342449},{"batl":[[1,5,9.4],[2,5.1,47.79]],"ltp":4.3,"tv":9668.61,"id":9633869}]}]}
{"op":"mcm","clk":"4230775356","pt":1631536501570,"mc":[{"id":"1.187557995","rc":[{"batl":[[0,4.8,10.42],[1,4.9,7.45],[2,5,9.4]],"ltp":4.3,"tv":9668.61,"id":9633869}]}]}
{"op":"mcm","clk":"4230775516","pt":1631536503446,"mc":[{"id":"1.187557995","rc":[{"batb":[[0,1.28,466.84],[1,1.27,639.44]],"batl":[[0,1.29,332.43]],"ltp":1.27,"tv":95490.39,"id":9342449}]}]}
{"op":"mcm","clk":"4230775608","pt":1631536504347,"mc":[{"id":"1.187557995","rc":[{"batb":[[0,1.28,388.02]],"batl":[[0,1.29,260.41]],"ltp":1.27,"tv":95490.39,"id":9342449}]}]}
{"op":"mcm","clk":"4230775683","pt":1631536505132,"mc":[{"id":"1.187557995","rc":[{"batb":[[0,1.28,226.21]],"batl":[[0,1.29,179.7]],"ltp":1.27,"tv":95490.39,"id":9342449}]}]}
{"op":"mcm","clk":"4230776542","pt":1631536514470,"mc":[{"id":"1.187557995","rc":[{"batb":[[0,1.25,860.95],[1,1.24,741.27],[2,1.23,1139.79]],"batl":[[0,1.3,110],[1,1.33,273.5],[2,1.34,272.75]],"ltp":1.27,"tv":95490.39,"id":9342449},{"batb":[[0,4.4,17.64],[1,4,10.97],[2,3.9,11.46]],"batl":[[0,5,9.4],[1,5.1,55.19],[2,5.2,55.67]],"ltp":4.3,"tv":9668.61,"id":9633869}]}]}
{"op":"mcm","clk":"4230776638","pt":1631536515458,"mc":[{"id":"1.187557995","rc":[{"batb":[[1,1.24,618.8]],"batl":[[0,1.33,273.5],[1,1.34,272.75],[2,1.36,455.63]],"ltp":1.27,"tv":95490.39,"id":9342449},{"batb":[[0,4,10.97],[1,3.9,11.46],[2,3.8,130.64]],"batl":[[1,5.1,47.79]],"ltp":4.3,"tv":9668.61,"id":9633869}]}]}
{"op":"mcm","clk":"4230776669","pt":1631536515862,"mc":[{"id":"1.187557995","rc":[{"batl":[[0,1.36,455.63],[1,1.37,194.93],[2,1.38,250.6]],"ltp":1.27,"tv":95490.39,"id":9342449},{"batb":[[0,3.8,130.64],[1,3.75,95.69],[2,3.7,89.47]],"ltp":4.3,"tv":9668.61,"id":9633869}]}]}
{"op":"mcm","clk":"4230776821","pt":1631536517638,"mc":[{"id":"1.187557995","rc":[{"batb":[[0,1.26,436.98],[1,1.25,860.95],[2,1.24,805.25]],"batl":[[0,1.35,331.01],[1,1.36,760.85],[2,1.37,194.93]],"ltp":1.27,"tv":95490.39,"id":9342449},{"batl":[[0,4.9,9.35],[1,5,9.4],[2,5.1,47.79]],"ltp":4.3,"tv":9668.61,"id":9633869}]}]}
{"op":"mcm","clk":"4230776866","pt":1631536517964,"mc":[{"id":"1.187557995","rc":[{"batb":[[0,1.25,860.95],[1,1.24,805.25],[2,1.23,1688.13]],"ltp":1.27,"tv":95490.39,"id":9342449},{"batl":[[0,5,9.4],[1,5.1,47.79],[2,5.2,55.67]],"ltp":4.3,"tv":9668.61,"id":9633869}]}]}
{"op":"mcm","clk":"4230776994","pt":1631536519376,"mc":[{"id":"1.187557995","rc":[{"batl":[[0,1.35,340.01],[1,1.36,768.85]],"ltp":1.27,"tv":95490.39,"id":9342449},{"batb":[[0,3.8,133.64],[1,3.75,98.69]],"ltp":4.3,"tv":9668.61,"id":9633869}]}]}
{"op":"mcm","clk":"4230777075","pt":1631536520272,"mc":[{"id":"1.187557995","rc":[{"batl":[[0,1.35,565.73]],"ltp":1.27,"tv":95490.39,"id":9342449},{"batb":[[0,3.85,3],[1,3.8,133.64],[2,3.75,98.69]],"ltp":4.3,"tv":9668.61,"id":9633869}]}]}
{"op":"mcm","clk":"4230777207","pt":1631536521474,"mc":[{"id":"1.187557995","rc":[{"batb":[[0,1.26,368.48],[1,1.25,860.95],[2,1.24,805.25]],"ltp":1.27,"tv":95490.39,"id":9342449},{"batl":[[0,4.9,7.35],[1,5,9.4],[2,5.1,47.79]],"ltp":4.3,"tv":9668.61,"id":9633869}]}]}
{"op":"mcm","clk":"4230777307","pt":1631536522679,"mc":[{"id":"1.187557995","rc":[{"batb":[[0,1.25,860.95],[1,1.24,805.25],[2,1.23,1688.13]],"batl":[[0,1.33,285.5],[1,1.34,9],[2,1.35,565.73]],"ltp":1.27,"tv":95490.39,"id":9342449},{"batb":[[0,4,10.72],[1,3.85,3],[2,3.8,133.64]],"batl":[[0,5,9.4],[1,5.1,47.79],[2,5.2,55.67]],"ltp":4.3,"tv":9668.61,"id":9633869}]}]}
{"op":"mcm","clk":"4230777342","pt":1631536522996,"mc":[{"id":"1.187557995","rc":[{"batb":[[1,1.24,433.27],[2,1.23,881.34]],"batl":[[0,1.35,565.73],[1,1.36,768.85],[2,1.37,194.93]],"ltp":1.27,"tv":95490.39,"id":9342449},{"batb":[[0,3.85,3],[1,3.8,133.64],[2,3.75,98.69]],"batl":[[1,5.2,8.28],[2,5.4,8.69]],"ltp":4.3,"tv":9668.61,"id":9633869}]}]}
{"op":"mcm","clk":"4230777505","pt":1631536524571,"mc":[{"id":"1.187557995","rc":[{"batl":[[0,1.35,331.01],[1,1.36,760.85]],"ltp":1.27,"tv":95490.39,"id":9342449},{"batb":[[0,3.8,130.64],[1,3.75,95.69],[2,3.7,89.47]],"ltp":4.3,"tv":9668.61,"id":9633869}]}]}
{"op":"mcm","clk":"4230777615","pt":1631536525667,"mc":[{"id":"1.187557995","rc":[{"trd":[[1.35,2396.36]],"batb":[[0,1.31,2919.84],[1,1.3,2833.96],[2,1.29,2833.96]],"batl":[[0,1.35,316.01],[2,1.37,2986.91]],"ltp":1.35,"tv":95505.39,"id":9342449},{"trd":[[3.85,129.51]],"ltp":3.85,"tv":9673.87,"id":9633869}],"tv":105179.26}]}
{"op":"mcm","clk":"4230777725","pt":1631536526652,"mc":[{"id":"1.187557995","rc":[{"batb":[[0,1.32,333.16],[1,1.31,1837.84],[2,1.3,1416.98]],"batl":[[2,1.37,962.72]],"ltp":1.35,"tv":95505.39,"id":9342449}]}]}
{"op":"mcm","clk":"4230777828","pt":1631536527649,"mc":[{"id":"1.187557995","rc":[{"batb":[[0,1.32,619.77]],"batl":[[0,1.35,378.36]],"ltp":1.35,"tv":95505.39,"id":9342449},{"batb":[[0,3.9,20.68],[1,3.8,130.64],[2,3.75,95.69]],"batl":[[0,4.5,8.01],[1,5,9.4],[2,5.2,8.28]],"ltp":3.85,"tv":9673.87,"id":9633869}]}]}
{"op":"mcm","clk":"4230778079","pt":1631536530495,"mc":[{"id":"1.187557995","rc":[{"batb":[[0,1.33,146.05],[1,1.32,834.47],[2,1.31,1837.84]],"batl":[[0,1.34,68.27],[1,1.35,607.92],[2,1.36,760.85]],"ltp":1.35,"tv":95505.39,"id":9342449}]}]}
{"op":"mcm","clk":"4230778145","pt":1631536531180,"mc":[{"id":"1.187557995","rc":[{"batb":[[1,1.32,895.89]],"ltp":1.35,"tv":95505.39,"id":9342449},{"batb":[[0,3.9,33.25]],"batl":[[0,4.4,45.9],[1,4.5,8.01],[2,5,9.4]],"ltp":3.85,"tv":9673.87,"id":9633869}]}]}
{"op":"mcm","clk":"4230778277","pt":1631536532511,"mc":[{"id":"1.187557995","rc":[{"batl":[[1,4.5,17.6],[2,4.9,8.95]],"ltp":3.85,"tv":9673.87,"id":9633869}]}]}
{"op":"mcm","clk":"4230778355","pt":1631536533288,"mc":[{"id":"1.187557995","rc":[{"batb":[[0,1.33,345.67],[1,1.32,562.73],[2,1.31,1459.92]],"batl":[[1,1.35,291.91],[2,1.36,455.63]],"ltp":1.35,"tv":95505.39,"id":9342449}]}]}
{"op":"mcm","clk":"4230778440","pt":1631536534224,"mc":[{"id":"1.187557995","rc":[{"trd":[[1.33,2258.18]],"batb":[[0,1.33,294.3]],"ltp":1.33,"tv":95608.11,"id":9342449}],"tv":105281.98}]}
{"op":"mcm","clk":"4230778651","pt":1631536536686,"mc":[{"id":"1.187557995","rc":[{"batb":[[0,3.9,20.68]],"ltp":3.85,"tv":9673.87,"id":9633869}]}]}
{"op":"mcm","clk":"4230778711","pt":1631536537303,"mc":[{"id":"1.187557995","rc":[{"batb":[[0,1.34,18.53],[1,1.33,258.21],[2,1.32,501.31]],"batl":[[0,1.35,291.91],[1,1.36,455.63],[2,1.37,962.72]],"ltp":1.33,"tv":95608.11,"id":9342449},{"batl":[[1,4.5,9.59]],"ltp":3.85,"tv":9673.87,"id":9633869}]}]}
{"op":"mcm","clk":"4230778772","pt":1631536537992,"mc":[{"id":"1.187557995","rc":[{"trd":[[1.34,14160.85]],"batb":[[0,1.34,12.25],[2,1.32,842.99]],"batl":[[0,1.35,614.63],[1,1.36,760.85]],"ltp":1.34,"tv":95614.39,"id":9342449},{"trd":[[3.95,219.01]],"ltp":3.95,"tv":9676.0,"id":9633869}],"tv":105290.39}]}
{"op":"mcm","clk":"4230778859","pt":1631536538995,"mc":[{"id":"1.187557995","rc":[{"batb":[[0,1.33,199.62],[1,1.32,842.99],[2,1.31,1837.85]],"batl":[[0,1.35,540.48]],"ltp":1.34,"tv":95614.39,"id":9342449}]}]}
{"op":"mcm","clk":"4230779022","pt":1631536540508,"mc":[{"id":"1.187557995","rc":[{"batl":[[0,4.4,54.03]],"ltp":3.95,"tv":9676.0,"id":9633869}]}]}
{"op":"mcm","clk":"4230779095","pt":1631536541199,"mc":[{"id":"1.187557995","rc":[{"batl":[[0,1.34,38.16],[1,1.35,540.48],[2,1.36,760.85]],"ltp":1.34,"tv":95614.39,"id":9342449},{"batl":[[0,4.4,8.13]],"ltp":3.95,"tv":9676.0,"id":9633869}]}]}
{"op":"mcm","clk":"4230779238","pt":1631536542715,"mc":[{"id":"1.187557995","rc":[{"batb":[[1,1.32,501.31],[2,1.29,348.81]],"batl":[[1,1.35,170.41],[2,1.45,249.5]],"ltp":1.34,"tv":95614.39,"id":9342449},{"batb":[[1,3.8,58.99],[2,3.25,87.95]],"ltp":3.95,"tv":9676.0,"id":9633869}]}]}
{"op":"mcm","clk":"4230779303","pt":1631536543296,"mc":[{"id":"1.187557995","rc":[{"batb":[[0,1.28,424.19],[1,1.27,350.62],[2,1.26,363.98]],"batl":[[0,1.35,15],[1,1.5,223.55],[2,1.51,174.5]],"ltp":1.34,"tv":95614.39,"id":9342449},{"batb":[[1,3.25,87.95],[2,3,20]],"batl":[[1,4.9,8.95],[2,5,9.4]],"ltp":3.95,"tv":9676.0,"id":9633869}]}]}
{"op":"mcm","clk":"4230779415","pt":1631536544400,"mc":[{"id":"1.187557995","rc":[{"batl":[[0,1.5,223.55],[1,1.51,174.5],[2,1.58,659.56]],"ltp":1.34,"tv":95614.39,"id":9342449},{"batb":[[0,3.25,87.95],[1,3,20],[2,2.96,19.38]],"batl":[[0,4.9,8.95],[1,5,9.4],[2,5.2,8.28]],"ltp":3.95,"tv":9676.0,"id":9633869}]}]}
{"op":"mcm","clk":"4230779522","pt":1631536545499,"mc":[{"id":"1.187557995","rc":[{"batb":[[1,1.27,528.38],[2,1.26,834.3]],"batl":[[0,1.43,157.49],[1,1.44,234.99],[2,1.5,223.55]],"ltp":1.34,"tv":95614.39,"id":9342449}]}]}
{"op":"mcm","clk":"4230779627","pt":1631536546507,"mc":[{"id":"1.187557995","rc":[{"batl":[[2,1.45,213.1]],"ltp":1.34,"tv":95614.39,"id":9342449},{"batb":[[1,3.2,17.02],[2,3,20]],"ltp":3.95,"tv":9676.0,"id":9633869}]}]}
{"op":"mcm","clk":"4230779731","pt":1631536547598,"mc":[{"id":"1.187557995","rc":[{"batb":[[1,1.27,350.62],[2,1.26,363.98]],"batl":[[0,1.45,6],[1,1.5,223.55],[2,1.51,174.5]],"ltp":1.34,"tv":95614.39,"id":9342449},{"batb":[[0,3.25,90.95],[1,3.2,3]],"ltp":3.95,"tv":9676.0,"id":9633869}]}]}
{"op":"mcm","clk":"4230779812","pt":1631536548687,"mc":[{"id":"1.187557995","rc":[{"batl":[[0,1.43,6],[1,1.45,6],[2,1.5,223.55]],"ltp":1.34,"tv":95614.39,"id":9342449},{"batb":[[0,3.3,3],[1,3.25,90.95],[2,3.2,3]],"ltp":3.95,"tv":9676.0,"id":9633869}]}]}
{"op":"mcm","clk":"4230779912","pt":1631536549703,"mc":[{"id":"1.187557995","rc":[{"batl":[[0,1.42,247.02],[1,1.43,6],[2,1.45,6]],"ltp":1.34,"tv":95614.39,"id":9342449}]}]}
{"op":"mcm","clk":"4230780001","pt":1631536550718,"mc":[{"id":"1.187557995","rc":[{"batb":[[0,1.34,325.74],[1,1.33,346.24],[2,1.29,328.81]],"batl":[[0,1.37,427.05],[1,1.38,283.31],[2,1.42,247.02]],"ltp":1.34,"tv":95614.39,"id":9342449},{"batb":[[2,3.2,18.47]],"batl":[[0,4.5,9.33],[1,4.9,8.95],[2,5,9.4]],"ltp":3.95,"tv":9676.0,"id":9633869}]}]}
{"op":"mcm","clk":"4230780156","pt":1631536552196,"mc":[{"id":"1.187557995","rc":[{"batb":[[2,1.29,451.74]],"ltp":1.34,"tv":95614.39,"id":9342449},{"batb":[[0,3.35,15],[1,3.3,3],[2,3.25,90.95]],"ltp":3.95,"tv":9676.0,"id":9633869}]}]}
{"op":"mcm","clk":"4230780502","pt":1631536555704,"mc":[{"id":"1.187557995","rc":[{"batb":[[0,1.34,19.36],[1,1.28,424.19],[2,1.27,350.62]],"batl":[[0,1.42,247.02],[1,1.43,6],[2,1.45,207.5]],"ltp":1.34,"tv":95614.39,"id":9342449},{"batb":[[0,3.3,3],[1,3.25,90.95],[2,3.2,18.47]],"batl":[[0,4.9,8.95],[1,5,9.4],[2,5.2,8.28]],"ltp":3.95,"tv":9676.0,"id":9633869}]}]}
{"op":"mcm","clk":"4230780678","pt":1631536557608,"mc":[{"id":"1.187557995","rc":[{"batb":[[2,1.27,528.38]],"batl":[[1,1.43,163.49],[2,1.44,234.99]],"ltp":1.34,"tv":95614.39,"id":9342449}]}]}
{"op":"mcm","clk":"4230780755","pt":1631536558437,"mc":[{"id":"1.187557995","rc":[{"batb":[[1,1.29,350.81],[2,1.28,424.19]],"ltp":1.34,"tv":95614.39,"id":9342449},{"batl":[[0,4.5,10.07],[1,4.9,8.95],[2,5,9.4]],"ltp":3.95,"tv":9676.0,"id":9633869}]}]}
{"op":"mcm","clk":"4230780797","pt":1631536558808,"mc":[{"id":"1.187557995","rc":[{"batb":[[1,1.28,424.19],[2,1.27,528.38]],"ltp":1.34,"tv":95614.39,"id":9342449},{"batl":[[0,4.9,8.95],[1,5,9.4],[2,5.2,8.28]],"ltp":3.95,"tv":9676.0,"id":9633869}]}]}
{"op":"mcm","clk":"4230781137","pt":1631536562214,"mc":[{"id":"1.187557995","rc":[{"batb":[[1,3.25,87.95],[2,3.2,15.47]],"ltp":3.95,"tv":9676.0,"id":9633869}]}]}
{"op":"mcm","clk":"4230781455","pt":1631536565509,"mc":[{"id":"1.187557995","rc":[{"batb":[[1,1.29,373.81],[2,1.28,424.19]],"ltp":1.34,"tv":95614.39,"id":9342449},{"batl":[[0,4.5,8.75],[1,4.9,8.95],[2,5,9.4]],"ltp":3.95,"tv":9676.0,"id":9633869}]}]}
{"op":"mcm","clk":"4230781489","pt":1631536565927,"mc":[{"id":"1.187557995","rc":[{"batb":[[1,1.28,424.19],[2,1.27,528.38]],"ltp":1.34,"tv":95614.39,"id":9342449},{"batl":[[0,4.9,8.95],[1,5,9.4],[2,5.2,8.28]],"ltp":3.95,"tv":9676.0,"id":9633869}]}]}
{"op":"mcm","clk":"4230781816","pt":1631536569543,"mc":[{"id":"1.187557995","rc":[{"trd":[[1.29,6159.99],[1.34,14199.56]],"batb":[[0,1.28,424.19],[1,1.27,528.38],[2,1.26,834.3]],"batl":[[1,1.43,6],[2,1.45,201.5]],"ltp":1.29,"tv":96272.72,"id":9342449}],"tv":105948.72}]}
{"op":"mcm","clk":"4230782117","pt":1631536572637,"mc":[{"id":"1.187557995","rc":[{"batb":[[0,1.27,528.38],[1,1.26,834.3],[2,1.25,396.73]],"batl":[[0,1.29,304.09],[1,1.3,386.23],[2,1.31,1459.92]],"ltp":1.29,"tv":96272.72,"id":9342449},{"batb":[[2,3,20]],"batl":[[1,5,391.9],[2,5.1,204.19]],"ltp":3.95,"tv":9676.0,"id":9633869}]}]}
{"op":"mcm","clk":"4230782202","pt":1631536573511,"mc":[{"id":"1.187557995","rc":[{"trd":[[1.29,6175.85]],"batl":[[0,1.29,288.23]],"ltp":1.29,"tv":96288.58,"id":9342449},{"trd":[[4.4,443.45]],"batb":[[0,4.2,90.38],[1,3.75,62.09],[2,3.35,377.09]],"ltp":4.4,"tv":9680.65,"id":9633869}],"tv":105969.23}]}
{"op":"mcm","clk":"4230782293","pt":1631536574415,"mc":[{"id":"1.187557995","rc":[{"trd":[[1.29,6666.43]],"batl":[[0,1.3,401.23],[1,1.31,1459.92],[2,1.32,1416.98]],"ltp":1.29,"tv":96779.16,"id":9342449},{"batb":[[0,4.3,18.18],[1,4.2,90.38],[2,3.75,62.09]],"batl":[[0,4.9,20.51]],"ltp":4.4,"tv":9680.65,"id":9633869}],"tv":106459.82}]}
{"op":"mcm","clk":"4230782496","pt":1631536576546,"mc":[{"id":"1.187557995","rc":[{"trd":[[4.3,35.22]],"batb":[[0,4.3,15.52]],"ltp":4.3,"tv":9685.97,"id":9633869}],"tv":106465.14}]}
{"op":"mcm","clk":"4230782624","pt":1631536577665,"mc":[{"id":"1.187557995","rc":[{"batb":[[0,1.28,10.66],[1,1.27,921.8],[2,1.26,896.15]],"batl":[[0,1.29,372.68],[1,1.3,721.32],[2,1.31,1824.61]],"ltp":1.29,"tv":96779.16,"id":9342449},{"batb":[[0,4.3,40.56]],"ltp":4.3,"tv":9685.97,"id":9633869}]}]}
{"op":"mcm","clk":"4230782688","pt":1631536578226,"mc":[{"id":"1.187557995","rc":[{"trd":[[1.27,652.48],[1.28,3323.53]],"batb":[[0,1.27,683.48],[1,1.26,896.15],[2,1.25,396.73]],"batl":[[0,1.29,198.99],[1,1.3,809.32]],"ltp":1.27,"tv":97277.02,"id":9342449},{"batb":[[0,4.3,15.52]],"ltp":4.3,"tv":9685.97,"id":9633869}],"tv":106962.99}]}
{"op":"mcm","clk":"4230782775","pt":1631536579230,"mc":[{"id":"1.187557995","rc":[{"batb":[[2,3.9,12.26]],"ltp":4.3,"tv":9685.97,"id":9633869}]}]}
{"op":"mcm","clk":"4230782946","pt":1631536580627,"mc":[{"id":"1.187557995","rc":[{"batl":[[0,1.29,213.99]],"ltp":1.27,"tv":97277.02,"id":9342449},{"batb":[[0,4.3,18.18]],"ltp":4.3,"tv":9685.97,"id":9633869}]}]}
{"op":"mcm","clk":"4230783052","pt":1631536581523,"mc":[{"id":"1.187557995","rc":[{"batb":[[0,4.4,25.04],[1,4.3,18.18],[2,4.2,90.38]],"batl":[[0,4.9,20.6],[2,5.1,211.59]],"ltp":4.3,"tv":9685.97,"id":9633869}]}]}
{"op":"mcm","clk":"4230783256","pt":1631536583561,"mc":[{"id":"1.187557995","rc":[{"batb":[[0,1.27,759.64],[1,1.26,834.3]],"batl":[[0,1.29,280.46]],"ltp":1.27,"tv":97277.02,"id":9342449}]}]}
{"op":"mcm","clk":"4230783283","pt":1631536583825,"mc":[{"id":"1.187557995","rc":[{"batb":[[0,1.27,683.48]],"batl":[[0,1.29,213.99],[1,1.3,739.04]],"ltp":1.27,"tv":97277.02,"id":9342449}]}]}
{"op":"mcm","clk":"4230783442","pt":1631536585642,"mc":[{"id":"1.187557995","rc":[{"batb":[[0,1.27,621.36]],"batl":[[0,1.29,133.58]],"ltp":1.27,"tv":97277.02,"id":9342449}]}]}
{"op":"mcm","clk":"4230783528","pt":1631536586529,"mc":[{"id":"1.187557995","rc":[{"trd":[[1.27,656.11]],"batb":[[0,1.27,619.54]],"ltp":1.27,"tv":97280.65,"id":9342449},{"batb":[[0,4.2,90.38],[1,3.9,12.26],[2,3.75,62.09]],"ltp":4.3,"tv":9685.97,"id":9633869}],"tv":106966.62}]}
{"op":"mcm","clk":"4230783629","pt":1631536587526,"mc":[{"id":"1.187557995","rc":[{"batb":[[0,1.24,811.46],[1,1.23,884.77],[2,1.21,20]],"batl":[[0,1.29,15],[1,1.3,88],[2,1.34,258.75]],"ltp":1.27,"tv":97280.65,"id":9342449},{"batb":[[0,3.9,12.26],[1,3.75,62.09],[2,3.7,12.62]],"batl":[[0,5.1,7.49],[1,5.2,8.28],[2,5.4,8.69]],"ltp":4.3,"tv":9685.97,"id":9633869}]}]}
{"op":"mcm","clk":"4230783713","pt":1631536588461,"mc":[{"id":"1.187557995","rc":[{"batl":[[0,1.34,258.75],[1,1.37,247.5],[2,1.42,7]],"ltp":1.27,"tv":97280.65,"id":9342449},{"batl":[[0,5.2,8.37],[1,5.4,8.69],[2,990,0.01]],"ltp":4.3,"tv":9685.97,"id":9633869}]}]}
{"op":"mcm","clk":"4230783847","pt":1631536589680,"mc":[{"id":"1.187557995","rc":[{"batb":[[0,1.24,378.19]],"batl":[[0,1.37,247.5],[1,1.42,7],[2,1.58,659.56]],"ltp":1.27,"tv":97280.65,"id":9342449},{"batb":[[0,4.3,25.04]],"batl":[[0,5.4,8.78],[1,990,0.01],[2,990,0]],"ltp":4.3,"tv":9685.97,"id":9633869}]}]}
{"op":"mcm","clk":"4230783954","pt":1631536590653,"mc":[{"id":"1.187557995","rc":[{"batb":[[1,1.23,1195.26],[2,1.22,578.55]],"batl":[[0,1.36,361.6],[1,1.37,539.97],[2,1.42,7]],"ltp":1.27,"tv":97280.65,"id":9342449},{"batb":[[0,3.8,59.58],[1,3.7,12.62],[2,3.4,3]],"batl":[[0,5.4,8.69]],"ltp":4.3,"tv":9685.97,"id":9633869}]}]}
{"op":"mcm","clk":"4230784031","pt":1631536591332,"mc":[{"id":"1.187557995","rc":[{"batb":[[0,1.26,226.58],[1,1.24,378.19],[2,1.23,1195.26]],"ltp":1.27,"tv":97280.65,"id":9342449}]}]}
{"op":"mcm","clk":"4230784154","pt":1631536592644,"mc":[{"id":"1.187557995","rc":[{"batb":[[0,1.24,378.19],[1,1.23,1195.26],[2,1.22,578.55]],"batl":[[0,1.34,296.25],[1,1.36,361.6],[2,1.37,547.97]],"ltp":1.27,"tv":97280.65,"id":9342449},{"batb":[[0,3.9,11.96],[1,3.8,59.58],[2,3.75,2]],"ltp":4.3,"tv":9685.97,"id":9633869}]}]}
{"op":"mcm","clk":"4230784234","pt":1631536593376,"mc":[{"id":"1.187557995","rc":[{"batb":[[0,1.28,160.52],[1,1.27,258.43],[2,1.26,237.33]],"batl":[[0,1.36,368.6],[1,1.37,547.97],[2,1.42,7]],"ltp":1.27,"tv":97280.65,"id":9342449},{"batb":[[0,3.8,62.58],[1,3.75,2],[2,3.7,15.62]],"batl":[[0,4.6,57.3],[1,4.7,56.88],[2,4.8,67.57]],"ltp":4.3,"tv":9685.97,"id":9633869}]}]}
{"op":"mcm","clk":"4230784388","pt":1631536595152,"mc":[{"id":"1.187557995","rc":[{"batb":[[0,3.85,3],[1,3.8,62.58],[2,3.75,2]],"ltp":4.3,"tv":9685.97,"id":9633869}]}]}
{"op":"mcm","clk":"4230784527","pt":1631536596660,"mc":[{"id":"1.187557995","rc":[{"batl":[[0,1.35,189.1],[1,1.36,368.6],[2,1.37,547.97]],"ltp":1.27,"tv":97280.65,"id":9342449}]}]}
{"op":"mcm","clk":"4230784747","pt":1631536599076,"mc":[{"id":"1.187557995","rc":[{"batb":[[0,1.24,378.19],[1,1.23,884.77],[2,1.21,20]],"ltp":1.27,"tv":97280.65,"id":9342449},{"batl":[[0,5.4,8.69],[1,990,0.01],[2,4.8,0]],"ltp":4.3,"tv":9685.97,"id":9633869}]}]}
{"op":"mcm","clk":"4230784860","pt":1631536600275,"mc":[{"id":"1.187557995","rc":[{"batl":[[1,1.36,361.6],[2,1.37,539.97]],"ltp":1.27,"tv":97280.65,"id":9342449},{"batb":[[0,3.8,59.58],[1,3.7,12.62],[2,3.4,3]],"ltp":4.3,"tv":9685.97,"id":9633869}]}]}
{"op":"mcm","clk":"4230785010","pt":1631536601584,"mc":[{"id":"1.187557995","rc":[{"trd":[[1.35,2411.36]],"batb":[[0,1.32,2897.72],[1,1.31,2812.5],[2,1.3,2812.5]],"batl":[[0,1.35,174.1]],"ltp":1.35,"tv":97295.65,"id":9342449},{"trd":[[3.85,134.77]],"batb":[[2,3.65,1047.94]],"ltp":3.85,"tv":9691.23,"id":9633869}],"tv":106986.88}]}
{"op":"mcm","clk":"4230785101","pt":1631536602577,"mc":[{"id":"1.187557995","rc":[{"batb":[[0,1.33,258.31],[1,1.32,2094.08],[2,1.31,1406.26]],"batl":[[0,1.36,361.6],[1,1.37,539.97],[2,1.42,7]],"ltp":1.35,"tv":97295.65,"id":9342449},{"batb":[[2,3.65,288.18]],"batl":[[0,5.4,8.78]],"ltp":3.85,"tv":9691.23,"id":9633869}]}]}
{"op":"mcm","clk":"4230785197","pt":1631536603465,"mc":[{"id":"1.187557995","rc":[{"batl":[[0,1.35,50.87],[1,1.36,361.6],[2,1.37,539.97]],"ltp":1.35,"tv":97295.65,"id":9342449},{"batb":[[0,3.85,34.27],[1,3.8,59.58],[2,3.7,12.62]],"batl":[[0,4.5,8.01],[1,5.4,8.78],[2,990,0.01]],"ltp":3.85,"tv":9691.23,"id":9633869}]}]}
{"op":"mcm","clk":"4230785523","pt":1631536606693,"mc":[{"id":"1.187557995","rc":[{"batb":[[0,1.34,78.14],[1,1.33,491.89],[2,1.32,2094.08]],"batl":[[0,1.35,215.61],[1,1.36,511.34]],"ltp":1.35,"tv":97295.65,"id":9342449},{"batl":[[0,4.4,26.77],[1,4.5,8.01],[2,5.4,8.78]],"ltp":3.85,"tv":9691.23,"id":9633869}]}]}
{"op":"mcm","clk":"4230785605","pt":1631536607679,"mc":[{"id":"1.187557995","rc":[{"trd":[[1.35,2441.54]],"batl":[[0,1.35,200.52]],"ltp":1.35,"tv":97325.82,"id":9342449}],"tv":107017.06}]}
{"op":"mcm","clk":"4230785664","pt":1631536608364,"mc":[{"id":"1.187557995","rc":[{"batl":[[1,4.5,17.24],[2,4.9,8.84]],"ltp":3.85,"tv":9691.23,"id":9633869}]}]}
{"op":"mcm","clk":"4230785730","pt":1631536609083,"mc":[{"id":"1.187557995","rc":[{"batl":[[1,4.5,63.85],[2,4.6,60.3]],"ltp":3.85,"tv":9691.23,"id":9633869}]}]}
{"op":"mcm","clk":"4230785848","pt":1631536610380,"mc":[{"id":"1.187557995","rc":[{"batl":[[0,1.35,260.52]],"ltp":1.35,"tv":97325.82,"id":9342449}]}]}
{"op":"mcm","clk":"4230786076","pt":1631536612683,"mc":[{"id":"1.187557995","rc":[{"batb":[[1,1.33,552.15]],"batl":[[0,1.35,318.05]],"ltp":1.35,"tv":97325.82,"id":9342449},{"batl":[[1,4.5,55.84]],"ltp":3.85,"tv":9691.23,"id":9633869}]}]}
{"op":"mcm","clk":"4230786109","pt":1631536612996,"mc":[{"id":"1.187557995","rc":[{"batb":[[1,1.33,491.89]],"batl":[[0,1.35,260.52],[1,1.36,445.9]],"ltp":1.35,"tv":97325.82,"id":9342449}]}]}
{"op":"mcm","clk":"4230786351","pt":1631536615510,"mc":[{"id":"1.187557995","rc":[{"trd":[[1.34,14204.21]],"batb":[[0,1.33,419.89],[1,1.32,2094.08],[2,1.31,1406.26]],"batl":[[0,1.35,180.8]],"ltp":1.34,"tv":97330.47,"id":9342449},{"batl":[[0,4.4,8.13]],"ltp":3.85,"tv":9691.23,"id":9633869}],"tv":107021.71}]}
{"op":"mcm","clk":"4230786455","pt":1631536616504,"mc":[{"id":"1.187557995","rc":[{"trd":[[1.35,2539.16]],"batl":[[0,1.35,131.98]],"ltp":1.35,"tv":97428.1,"id":9342449}],"tv":107119.33}]}
{"op":"mcm","clk":"4230786481","pt":1631536616722,"mc":[{"id":"1.187557995","rc":[{"batb":[[0,3.85,21.05]],"ltp":3.85,"tv":9691.23,"id":9633869}]}]}
{"op":"mcm","clk":"4230786659","pt":1631536618585,"mc":[{"id":"1.187557995","rc":[{"batl":[[0,4.3,26.77],[1,4.4,8.13],[2,4.5,55.84]],"ltp":3.85,"tv":9691.23,"id":9633869}]}]}
{"op":"mcm","clk":"4230786787","pt":1631536619696,"mc":[{"id":"1.187557995","rc":[{"batl":[[0,1.34,4.97],[1,1.35,131.98],[2,1.36,445.9]],"ltp":1.35,"tv":97428.1,"id":9342449}]}]}
{"op":"mcm","clk":"4230786851","pt":1631536620311,"mc":[{"id":"1.187557995","rc":[{"batb":[[0,1.3,361.16],[1,1.29,341.81],[2,1.28,189.85]],"batl":[[1,1.35,60],[2,1.44,227.43]],"ltp":1.35,"tv":97428.1,"id":9342449},{"batb":[[1,3.25,87.45],[2,3.2,55.17]],"batl":[[0,4.4,8.13],[1,4.5,55.84],[2,4.6,60.3]],"ltp":3.85,"tv":9691.23,"id":9633869}]}]}
{"op":"mcm","clk":"4230786962","pt":1631536621409,"mc":[{"id":"1.187557995","rc":[{"batl":[[1,1.44,227.43],[2,1.45,126.47]],"ltp":1.35,"tv":97428.1,"id":9342449},{"batb":[[0,3.25,87.45],[1,3.2,55.17],[2,3.15,111.08]],"batl":[[0,4.5,55.84],[1,4.6,60.3],[2,4.7,68.71]],"ltp":3.85,"tv":9691.23,"id":9633869}]}]}
{"op":"mcm","clk":"4230787056","pt":1631536622402,"mc":[{"id":"1.187557995","rc":[{"batl":[[0,1.34,12.81]],"ltp":1.35,"tv":97428.1,"id":9342449}]}]}
{"op":"mcm","clk":"4230787229","pt":1631536623487,"mc":[{"id":"1.187557995","rc":[{"trd":[[1.34,14229.83]],"batb":[[0,1.3,470.7]],"batl":[[0,1.44,380.04],[1,1.45,353.37],[2,1.46,397.06]],"ltp":1.34,"tv":97453.72,"id":9342449}],"tv":107144.96}]}
{"op":"mcm","clk":"4230787332","pt":1631536624025,"mc":[{"id":"1.187557995","rc":[{"batb":[[0,1.3,361.16]],"ltp":1.34,"tv":97453.72,"id":9342449}]}]}
{"op":"mcm","clk":"4230787689","pt":1631536626105,"mc":[{"id":"1.187557995","rc":[{"batl":[[0,1.44,386.04]],"ltp":1.34,"tv":97453.72,"id":9342449},{"batb":[[0,3.25,90.45],[1,3.2,58.17]],"ltp":3.85,"tv":9691.23,"id":9633869}]}]}
{"op":"mcm","clk":"4230788323","pt":1631536631872,"mc":[{"id":"1.187557995","rc":[{"batb":[[2,1.27,349.12]],"ltp":1.34,"tv":97453.72,"id":9342449},{"batl":[[0,4.5,9.23],[1,4.9,8.84],[2,5.4,8.69]],"ltp":3.85,"tv":9691.23,"id":9633869}]}]}
{"op":"mcm","clk":"4230788438","pt":1631536633155,"mc":[{"id":"1.187557995","rc":[{"batb":[[0,1.27,349.12],[1,1.26,447.48],[2,1.23,469.63]],"batl":[[0,1.44,158.61]],"ltp":1.34,"tv":97453.72,"id":9342449},{"batl":[[0,4.9,8.84],[1,5.4,8.69],[2,990,0.01]],"ltp":3.85,"tv":9691.23,"id":9633869}]}]}
{"op":"mcm","clk":"4230788595","pt":1631536634655,"mc":[{"id":"1.187557995","rc":[{"batb":[[0,1.41,256.84],[1,1.4,267.68],[2,1.39,2751.8]],"batl":[[0,1.44,152.61]],"ltp":1.34,"tv":97453.72,"id":9342449},{"batb":[[0,3.25,87.45],[1,3.2,55.17]],"batl":[[0,3.3,6.06],[1,4.9,8.84],[2,5.4,8.69]],"ltp":3.85,"tv":9691.23,"id":9633869}]}]}
{"op":"mcm","clk":"4230788688","pt":1631536635590,"mc":[{"id":"1.187557995","rc":[{"batb":[[1,1.4,481.82],[2,1.39,1375.9]],"ltp":1.34,"tv":97453.72,"id":9342449}]}]}
{"op":"mcm","clk":"4230788806","pt":1631536636691,"mc":[{"id":"1.187557995","rc":[{"batl":[[0,1.44,186.3]],"ltp":1.34,"tv":97453.72,"id":9342449},{"trd":[[3.3,12.12]],"batb":[[0,3.3,20.02],[1,3.25,105.48],[2,3.2,55.17]],"batl":[[0,4.9,8.84],[1,5.4,8.69],[2,990,0.01]],"ltp":3.3,"tv":9703.35,"id":9633869}],"tv":107157.08}]}
{"op":"mcm","clk":"4230788971","pt":1631536638617,"mc":[{"id":"1.187557995","rc":[{"trd":[[1.41,843.86]],"batb":[[0,1.41,254.84]],"ltp":1.41,"tv":97457.72,"id":9342449}],"tv":107161.08}]}
{"op":"mcm","clk":"4230789155","pt":1631536639691,"mc":[{"id":"1.187557995","rc":[{"batb":[[0,1.42,57.32],[1,1.41,457.43],[2,1.4,481.82]],"batl":[[0,1.43,119.99],[1,1.44,246.55],[2,1.45,353.37]],"ltp":1.41,"tv":97457.72,"id":9342449},{"trd":[[3.3,16.28]],"batb":[[0,3.3,17.94]],"batl":[[0,4.9,8.75]],"ltp":3.3,"tv":9707.51,"id":9633869}],"tv":107165.24}]}
{"op":"mcm","clk":"4230789248","pt":1631536640579,"mc":[{"id":"1.187557995","rc":[{"batb":[[0,1.42,188.29]],"batl":[[0,1.43,179.99]],"ltp":1.41,"tv":97457.72,"id":9342449},{"batl":[[0,3.8,8.96],[1,4.9,8.75],[2,5.4,8.69]],"ltp":3.3,"tv":9707.51,"id":9633869}]}]}
{"op":"mcm","clk":"4230789370","pt":1631536641473,"mc":[{"id":"1.187557995","rc":[{"trd":[[1.42,6594.01]],"batb":[[0,1.42,188.07]],"ltp":1.42,"tv":97458.17,"id":9342449},{"batb":[[1,3.25,111.54]],"batl":[[1,3.95,13.1],[2,4.4,9.09]],"ltp":3.3,"tv":9707.51,"id":9633869}],"tv":107165.68}]}
{"op":"mcm","clk":"4230789469","pt":1631536642678,"mc":[{"id":"1.187557995","rc":[{"batb":[[1,3.25,113.62]],"batl":[[2,4,55.58]],"ltp":3.3,"tv":9707.51,"id":9633869}]}]}
{"op":"mcm","clk":"4230789619","pt":1631536644291,"mc":[{"id":"1.187557995","rc":[{"trd":[[1.43,383.18]],"batl":[[0,1.44,246.55],[1,1.45,353.37],[2,1.46,397.06]],"ltp":1.43,"tv":97638.16,"id":9342449},{"trd":[[3.25,86.39],[3.3,130.17]],"batb":[[0,3.25,81.79],[1,3.2,55.17],[2,3.15,111.08]],"batl":[[0,3.95,13.1],[1,4,55.58],[2,4.1,56.28]],"ltp":3.25,"tv":9885.05,"id":9633869}],"tv":107523.21}]}
{"op":"mcm","clk":"4230789736","pt":1631536645593,"mc":[{"id":"1.187557995","rc":[{"trd":[[1.42,6611.02]],"batb":[[0,1.42,256.08]],"batl":[[0,1.43,69.02],[1,1.44,246.55],[2,1.45,353.37]],"ltp":1.42,"tv":97655.17,"id":9342449},{"trd":[[3.4,23.43]],"ltp":3.4,"tv":9887.18,"id":9633869}],"tv":107542.35}]}
{"op":"mcm","clk":"4230789822","pt":1631536646585,"mc":[{"id":"1.187557995","rc":[{"trd":[[1.43,387.83]],"batb":[[1,1.41,386.88]],"batl":[[0,1.43,66.7],[1,1.44,186.3]],"ltp":1.43,"tv":97659.81,"id":9342449},{"batl":[[0,3.75,44.2],[1,3.95,13.1],[2,4,55.58]],"ltp":3.4,"tv":9887.18,"id":9633869}],"tv":107547.0}]}
{"op":"mcm","clk":"4230789901","pt":1631536647517,"mc":[{"id":"1.187557995","rc":[{"batl":[[1,1.44,218.74],[2,1.45,413.37]],"ltp":1.43,"tv":97659.81,"id":9342449},{"batb":[[0,3.25,100.31]],"batl":[[0,3.7,9.12]],"ltp":3.4,"tv":9887.18,"id":9633869}]}]}
{"op":"mcm","clk":"4230789955","pt":1631536648089,"mc":[{"id":"1.187557995","rc":[{"batb":[[0,1.42,130.97]],"batl":[[0,1.44,186.3],[1,1.45,413.37],[2,1.46,397.06]],"ltp":1.43,"tv":97659.81,"id":9342449},{"batl":[[1,3.9,11.15],[2,3.95,13.1]],"ltp":3.4,"tv":9887.18,"id":9633869}]}]}
{"op":"mcm","clk":"4230790227","pt":1631536651194,"mc":[{"id":"1.187557995","rc":[{"batl":[[0,1.44,299.3]],"ltp":1.43,"tv":97659.81,"id":9342449}]}]}
{"op":"mcm","clk":"4230790392","pt":1631536652704,"mc":[{"id":"1.187557995","rc":[{"batb":[[0,1.34,238.5],[1,1.33,454.58],[2,1.32,172.57]],"batl":[[0,1.44,113],[1,1.45,60],[2,1.57,121.51]],"ltp":1.43,"tv":97659.81,"id":9342449},{"batb":[[0,3.25,26.66],[1,2.76,88.35],[2,2.74,104.75]],"batl":[[1,4,55.58],[2,4.1,56.28]],"ltp":3.4,"tv":9887.18,"id":9633869}]}]}
{"op":"mcm","clk":"4230790482","pt":1631536653595,"mc":[{"id":"1.187557995","rc":[{"batl":[[0,1.57,121.51],[1,1.58,123.53],[2,1.59,167.89]],"ltp":1.43,"tv":97659.81,"id":9342449},{"batb":[[0,2.76,88.35],[1,2.74,104.75],[2,2.72,161.41]],"batl":[[0,3.65,46.96]],"ltp":3.4,"tv":9887.18,"id":9633869}]}]}
{"op":"mcm","clk":"4230790522","pt":1631536653912,"mc":[{"id":"1.187557995","rc":[{"batl":[[0,4,55.58],[1,4.1,56.28],[2,4.2,74.04]],"ltp":3.4,"tv":9887.18,"id":9633869}]}]}
{"op":"mcm","clk":"4230790679","pt":1631536655636,"mc":[{"id":"1.187557995","rc":[{"batb":[[0,1.43,1.96],[1,1.38,97.33],[2,1.34,238.5]],"batl":[[0,1.57,390.19],[1,1.58,282.79]],"ltp":1.43,"tv":97659.81,"id":9342449}]}]}
{"op":"mcm","clk":"4230790784","pt":1631536656631,"mc":[{"id":"1.187557995","rc":[{"batb":[[1,1.34,238.5],[2,1.33,824.32]],"ltp":1.43,"tv":97659.81,"id":9342449}]}]}
{"op":"mcm","clk":"4230790822","pt":1631536656943,"mc":[{"id":"1.187557995","rc":[{"batb":[[0,1.43,119.09]],"ltp":1.43,"tv":97659.81,"id":9342449}]}]}
{"op":"mcm","clk":"4230791161","pt":1631536660135,"mc":[{"id":"1.187557995","rc":[{"batl":[[0,1.56,235.95],[1,1.57,390.19],[2,1.58,282.79]],"ltp":1.43,"tv":97659.81,"id":9342449}]}]}
{"op":"mcm","clk":"4230791444","pt":1631536663329,"mc":[{"id":"1.187557995","rc":[{"batb":[[1,1.35,309.67],[2,1.34,238.5]],"ltp":1.43,"tv":97659.81,"id":9342449},{"batl":[[0,3.9,12.95],[1,4,55.58],[2,4.1,56.28]],"ltp":3.4,"tv":9887.18,"id":9633869}]}]}
{"op":"mcm","clk":"4230791529","pt":1631536664011,"mc":[{"id":"1.187557995","rc":[{"trd":[[1.43,626.06]],"batb":[[0,1.35,309.67],[1,1.34,238.5],[2,1.33,824.32]],"batl":[[0,1.42,180.87],[1,1.56,235.95],[2,1.57,390.19]],"ltp":1.43,"tv":97898.04,"id":9342449}],"tv":107785.22}]}
{"op":"mcm","clk":"4230791765","pt":1631536666521,"mc":[{"id":"1.187557995","rc":[{"batl":[[1,1.55,6],[2,1.56,235.95]],"ltp":1.43,"tv":97898.04,"id":9342449},{"batb":[[0,2.8,3],[1,2.78,3],[2,2.76,88.35]],"ltp":3.4,"tv":9887.18,"id":9633869}]}]}
{"op":"mcm","clk":"4230791828","pt":1631536667202,"mc":[{"id":"1.187557995","rc":[{"batb":[[0,1.36,1369.63],[1,1.35,309.67],[2,1.34,238.5]],"ltp":1.43,"tv":97898.04,"id":9342449}]}]}
{"op":"mcm","clk":"4230792051","pt":1631536669498,"mc":[{"id":"1.187557995","rc":[{"batb":[[0,1.36,1624.31]],"ltp":1.43,"tv":97898.04,"id":9342449},{"batb":[[0,2.9,15],[1,2.8,3],[2,2.78,3]],"batl":[[0,3.85,42.8],[1,3.9,12.95],[2,4,55.58]],"ltp":3.4,"tv":9887.18,"id":9633869}]}]}
{"op":"mcm","clk":"4230792349","pt":1631536672637,"mc":[{"id":"1.187557995","rc":[{"batb":[[0,1.37,103.94],[1,1.36,1624.31],[2,1.35,309.67]],"ltp":1.43,"tv":97898.04,"id":9342449},{"batb":[[0,2.92,570.17],[1,2.9,15],[2,2.8,3]],"ltp":3.4,"tv":9887.18,"id":9633869}]}]}
{"op":"mcm","clk":"4230792361","pt":1631536672740,"mc":[{"id":"1.187557995","rc":[{"batb":[[1,2.8,3],[2,2.78,3]],"ltp":3.4,"tv":9887.18,"id":9633869}]}]}
{"op":"mcm","clk":"4230792715","pt":1631536675536,"mc":[{"id":"1.187557995","rc":[{"batb":[[0,1.37,94.55],[1,1.36,254.68],[2,1.34,238.5]],"batl":[[1,1.56,235.95],[2,1.57,390.19]],"ltp":1.43,"tv":97898.04,"id":9342449},{"batb":[[0,2.76,88.35],[1,2.74,104.75],[2,2.72,161.41]],"batl":[[0,4,55.58],[1,4.1,56.28],[2,4.2,74.04]],"ltp":3.4,"tv":9887.18,"id":9633869}]}]}
{"op":"mcm","clk":"4230792835","pt":1631536676331,"mc":[{"id":"1.187557995","rc":[{"batb":[[0,1.33,824.32],[1,1.32,868.87],[2,1.31,530.76]],"batl":[[1,1.57,390.19],[2,1.58,282.79]],"ltp":1.43,"tv":97898.04,"id":9342449},{"batl":[[2,4.2,83.77]],"ltp":3.4,"tv":9887.18,"id":9633869}]}]}
{"op":"mcm","clk":"4230793079","pt":1631536678847,"mc":[{"id":"1.187557995","rc":[{"batb":[[0,1.33,454.58],[1,1.32,507.71]],"batl":[[1,1.57,121.51],[2,1.58,123.53]],"ltp":1.43,"tv":97898.04,"id":9342449}]}]}
{"op":"mcm","clk":"4230793240","pt":1631536680413,"mc":[{"id":"1.187557995","rc":[{"batb":[[0,1.34,94.55],[1,1.33,454.58],[2,1.32,507.71]],"ltp":1.43,"tv":97898.04,"id":9342449}]}]}
{"op":"mcm","clk":"4230793334","pt":1631536681524,"mc":[{"id":"1.187557995","rc":[{"batl":[[0,3.6,308.98],[1,4,55.58],[2,4.1,56.28]],"ltp":3.4,"tv":9887.18,"id":9633869}]}]}
{"op":"mcm","clk":"4230793426","pt":1631536682544,"mc":[{"id":"1.187557995","rc":[{"trd":[[1.42,6972.76],[1.43,663.06]],"batb":[[0,1.43,269.36],[1,1.42,250.65],[2,1.35,157.7]],"batl":[[0,1.47,214.21]],"ltp":1.43,"tv":98296.78,"id":9342449},{"batb":[[0,2.82,81.04],[1,2.76,88.35],[2,2.74,104.75]],"batl":[[0,3.85,54.72]],"ltp":3.4,"tv":9887.18,"id":9633869}],"tv":108183.96}]}
{"op":"mcm","clk":"4230793607","pt":1631536684529,"mc":[{"id":"1.187557995","rc":[{"batb":[[2,1.4,353.66]],"ltp":1.43,"tv":98296.78,"id":9342449}]}]}
{"op":"mcm","clk":"4230793697","pt":1631536685630,"mc":[{"id":"1.187557995","rc":[{"batb":[[0,1.43,351.13]],"batl":[[0,1.46,192.16],[1,1.47,259.82],[2,1.57,121.51]],"ltp":1.43,"tv":98296.78,"id":9342449}]}]}
{"op":"mcm","clk":"4230793764","pt":1631536686374,"mc":[{"id":"1.187557995","rc":[{"batb":[[0,1.43,176.81]],"batl":[[1,1.47,214.21]],"ltp":1.43,"tv":98296.78,"id":9342449},{"batb":[[0,2.76,88.35],[1,2.74,104.75],[2,2.72,161.41]],"batl":[[0,4,55.58],[1,4.1,56.28],[2,4.2,83.77]],"ltp":3.4,"tv":9887.18,"id":9633869}]}]}
{"op":"mcm","clk":"4230793890","pt":1631536687649,"mc":[{"id":"1.187557995","rc":[{"batb":[[0,1.44,113.97],[1,1.43,18.93]],"batl":[[0,1.57,121.51],[1,1.58,123.53],[2,1.59,167.89]],"ltp":1.43,"tv":98296.78,"id":9342449}]}]}
{"op":"mcm","clk":"4230793943","pt":1631536688352,"mc":[{"id":"1.187557995","rc":[{"batb":[[0,1.43,18.93],[1,1.4,353.66],[2,1.34,292.16]],"ltp":1.43,"tv":98296.78,"id":9342449}]}]}
{"op":"mcm","clk":"4230794108","pt":1631536690125,"mc":[{"id":"1.187557995","rc":[{"batl":[[0,1.55,197.61],[1,1.56,204.68],[2,1.57,285.34]],"ltp":1.43,"tv":98296.78,"id":9342449}]}]}
{"op":"mcm","clk":"4230794303","pt":1631536692571,"mc":[{"id":"1.187557995","rc":[{"batb":[[0,1.34,292.16],[1,1.33,704.85],[2,1.32,868.66]],"batl":[[1,1.82,478.46],[2,2.08,1]],"ltp":1.43,"tv":98296.78,"id":9342449},{"batb":[[0,2.72,54.73],[1,2.3,24.88],[2,1.97,1.05]],"ltp":3.4,"tv":9887.18,"id":9633869}]}]}
{"op":"mcm","clk":"4230794458","pt":1631536694274,"mc":[{"id":"1.187557995","rc":[{"batb":[[0,1.33,704.85],[1,1.32,868.66],[2,1.31,530.76]],"batl":[[0,1.82,2.89],[1,2.08,1],[2,3.8,27.48]],"ltp":1.43,"tv":98296.78,"id":9342449}]}]}
{"op":"mcm","clk":"4230794626","pt":1631536695682,"mc":[{"id":"1.187557995","rc":[{"batl":[[0,1.36,878.86],[1,1.37,426.96],[2,1.43,18.71]],"ltp":1.43,"tv":98296.78,"id":9342449},{"batb":[[0,3.7,16.52],[1,2.72,54.73],[2,2.3,24.88]],"batl":[[2,4.2,334.22]],"ltp":3.4,"tv":9887.18,"id":9633869}]}]}
{"op":"mcm","clk":"4230794711","pt":1631536696475,"mc":[{"id":"1.187557995","rc":[{"trd":[[1.36,13422.62]],"batl":[[0,1.36,864.16],[2,1.82,2.89]],"ltp":1.36,"tv":98311.48,"id":9342449},{"trd":[[3.75,51.38]],"batb":[[0,3.75,62.17],[1,3.7,16.52],[2,3.2,91.71]],"ltp":3.75,"tv":9892.51,"id":9633869}],"tv":108203.99}]}
{"op":"mcm","clk":"4230794800","pt":1631536697366,"mc":[{"id":"1.187557995","rc":[{"batb":[[2,1.31,638.52]],"batl":[[2,1.38,60]],"ltp":1.36,"tv":98311.48,"id":9342449},{"batb":[[2,3.6,23.07]],"batl":[[2,4.2,342.6]],"ltp":3.75,"tv":9892.51,"id":9633869}]}]}
{"op":"mcm","clk":"4230795016","pt":1631536699585,"mc":[{"id":"1.187557995","rc":[{"batb":[[0,1.35,128.54],[1,1.33,704.85],[2,1.32,868.66]],"batl":[[0,1.36,1060.78]],"ltp":1.36,"tv":98311.48,"id":9342449},{"batb":[[0,3.8,82.37],[1,3.75,62.17],[2,3.7,16.52]],"ltp":3.75,"tv":9892.51,"id":9633869}]}]}
{"op":"mcm","clk":"4230795132","pt":1631536700690,"mc":[{"id":"1.187557995","rc":[{"batb":[[1,1.33,896.48]],"batl":[[0,1.36,1050.05],[2,1.43,404]],"ltp":1.36,"tv":98311.48,"id":9342449},{"batb":[[0,3.8,15]],"ltp":3.75,"tv":9892.51,"id":9633869}]}]}
{"op":"mcm","clk":"4230795324","pt":1631536702683,"mc":[{"id":"1.187557995","rc":[{"batl":[[2,1.43,4]],"ltp":1.36,"tv":98311.48,"id":9342449}]}]}
{"op":"mcm","clk":"4230795365","pt":1631536703053,"mc":[{"id":"1.187557995","rc":[{"batb":[[1,1.34,136.19],[2,1.33,896.48]],"ltp":1.36,"tv":98311.48,"id":9342449}]}]}
{"op":"mcm","clk":"4230795536","pt":1631536704706,"mc":[{"id":"1.187557995","rc":[{"batl":[[0,1.36,1385.05],[1,1.37,486.96]],"ltp":1.36,"tv":98311.48,"id":9342449},{"trd":[[3.8,4.26]],"batb":[[0,3.8,12.87],[2,3.7,38.74]],"ltp":3.8,"tv":9896.76,"id":9633869}],"tv":108208.25}]}
{"op":"mcm","clk":"4230795548","pt":1631536704759,"mc":[{"id":"1.187557995","rc":[{"batl":[[2,1.43,2]],"ltp":1.36,"tv":98311.48,"id":9342449}]}]}
{"op":"mcm","clk":"4230795787","pt":1631536706661,"mc":[{"id":"1.187557995","rc":[{"batb":[[1,1.34,203.62],[2,1.33,827.06]],"batl":[[2,1.45,207.84]],"ltp":1.36,"tv":98311.48,"id":9342449}]}]}
{"op":"mcm","clk":"4230795872","pt":1631536707497,"mc":[{"id":"1.187557995","rc":[{"batl":[[0,1.36,1419.31]],"ltp":1.36,"tv":98311.48,"id":9342449}]}]}
{"op":"mcm","clk":"4230795988","pt":1631536708702,"mc":[{"id":"1.187557995","rc":[{"batb":[[0,1.34,136.19],[1,1.33,827.06],[2,1.32,868.66]],"batl":[[0,1.36,1281.22]],"ltp":1.36,"tv":98311.48,"id":9342449}]}]}
{"op":"mcm","clk":"4230796066","pt":1631536709387,"mc":[{"id":"1.187557995","rc":[{"trd":[[1.36,13428.57]],"batl":[[0,1.36,1278.24]],"ltp":1.36,"tv":98317.43,"id":9342449}],"tv":108214.2}]}
{"op":"mcm","clk":"4230796178","pt":1631536710648,"mc":[{"id":"1.187557995","rc":[{"trd":[[3.8,4.44]],"batb":[[0,3.75,62.17],[1,3.7,38.74],[2,3.2,91.71]],"ltp":3.8,"tv":9896.95,"id":9633869}],"tv":108214.39}]}
{"op":"mcm","clk":"4230796618","pt":1631536714778,"mc":[{"id":"1.187557995","rc":[{"batb":[[0,3.8,14.77],[1,3.75,62.17],[2,3.7,38.74]],"ltp":3.8,"tv":9896.95,"id":9633869}]}]}
{"op":"mcm","clk":"4230796979","pt":1631536718694,"mc":[{"id":"1.187557995","rc":[{"trd":[[1.36,13438.57]],"batl":[[0,1.36,1273.24]],"ltp":1.36,"tv":98327.43,"id":9342449}],"tv":108224.39}]}
{"op":"mcm","clk":"4230797069","pt":1631536719586,"mc":[{"id":"1.187557995","rc":[{"trd":[[1.34,14231.53]],"batb":[[0,1.31,107.76],[1,1.3,581.15],[2,1.29,796.14]],"batl":[[0,1.36,841.26],[1,1.37,60]],"ltp":1.34,"tv":98329.14,"id":9342449},{"batb":[[0,3.7,22.22],[1,3.2,91.71],[2,3.1,16.34]],"batl":[[0,4.2,8.38],[1,4.4,9.09],[2,4.5,8.19]],"ltp":3.8,"tv":9896.95,"id":9633869}],"tv":108226.09}]}
{"op":"mcm","clk":"4230797148","pt":1631536720514,"mc":[{"id":"1.187557995","rc":[{"batb":[[0,1.3,246.17],[1,1.29,796.14],[2,1.28,671.15]],"batl":[[0,1.36,506.26],[1,1.45,207.84],[2,1.47,212.5]],"ltp":1.34,"tv":98329.14,"id":9342449},{"batb":[[0,3.2,91.71],[1,3.1,16.34],[2,2.88,17.71]],"batl":[[0,4.5,8.19],[1,4.6,9.66],[2,4.8,9.52]],"ltp":3.8,"tv":9896.95,"id":9633869}]}]}
{"op":"mcm","clk":"4230797320","pt":1631536722401,"mc":[{"id":"1.187557995","rc":[{"batl":[[1,1.44,156.94],[2,1.45,435.33]],"ltp":1.34,"tv":98329.14,"id":9342449}]}]}
{"op":"mcm","clk":"4230797459","pt":1631536723496,"mc":[{"id":"1.187557995","rc":[{"batb":[[0,1.3,623.85]],"ltp":1.34,"tv":98329.14,"id":9342449},{"batl":[[0,4.4,10.64],[1,4.5,8.19],[2,4.6,9.66]],"ltp":3.8,"tv":9896.95,"id":9633869}]}]}
{"op":"mcm","clk":"4230797485","pt":1631536723808,"mc":[{"id":"1.187557995","rc":[{"batb":[[0,1.3,246.17]],"ltp":1.34,"tv":98329.14,"id":9342449},{"batl":[[0,4.5,8.19],[1,4.6,9.66],[2,4.8,9.52]],"ltp":3.8,"tv":9896.95,"id":9633869}]}]}
{"op":"mcm","clk":"4230797933","pt":1631536728899,"mc":[{"id":"1.187557995","rc":[{"batl":[[1,1.45,207.84],[2,1.47,212.5]],"ltp":1.34,"tv":98329.14,"id":9342449}]}]}
{"op":"mcm","clk":"4230798078","pt":1631536730518,"mc":[{"id":"1.187557995","rc":[{"batb":[[0,1.3,570.15]],"batl":[[0,1.45,207.84],[1,1.47,212.5],[2,1.53,184.5]],"ltp":1.34,"tv":98329.14,"id":9342449},{"batl":[[0,4.4,9.89],[1,4.5,8.19],[2,4.6,9.66]],"ltp":3.8,"tv":9896.95,"id":9633869}]}]}
{"op":"mcm","clk":"4230798213","pt":1631536731602,"mc":[{"id":"1.187557995","rc":[{"batb":[[0,1.3,246.17]],"ltp":1.34,"tv":98329.14,"id":9342449},{"batl":[[0,4.1,283.85]],"ltp":3.8,"tv":9896.95,"id":9633869}]}]}
{"op":"mcm","clk":"4230798321","pt":1631536732718,"mc":[{"id":"1.187557995","rc":[{"batb":[[0,1.35,196.63],[1,1.31,96.05],[2,1.3,246.17]],"ltp":1.34,"tv":98329.14,"id":9342449},{"batb":[[0,3.25,72],[1,3.2,91.71],[2,3.1,16.34]],"batl":[[0,4.4,39.38]],"ltp":3.8,"tv":9896.95,"id":9633869}]}]}
{"op":"mcm","clk":"4230798348","pt":1631536732993,"mc":[{"id":"1.187557995","rc":[{"batb":[[1,1.3,246.17],[2,1.29,796.14]],"batl":[[0,1.44,154.98],[1,1.45,207.84],[2,1.47,212.5]],"ltp":1.34,"tv":98329.14,"id":9342449},{"batb":[[0,3.2,91.71],[1,3.1,16.34],[2,2.88,17.71]],"batl":[[0,4.5,8.19],[1,4.6,9.66],[2,4.8,9.52]],"ltp":3.8,"tv":9896.95,"id":9633869}]}]}
{"op":"mcm","clk":"4230798452","pt":1631536734504,"mc":[{"id":"1.187557995","rc":[{"batb":[[1,1.3,574.45]],"batl":[[0,1.43,353.66],[1,1.44,156.94],[2,1.45,435.33]],"ltp":1.34,"tv":98329.14,"id":9342449},{"batl":[[0,4.4,8.49],[1,4.5,8.19],[2,4.6,9.66]],"ltp":3.8,"tv":9896.95,"id":9633869}]}]}
{"op":"mcm","clk":"4230798619","pt":1631536736432,"mc":[{"id":"1.187557995","rc":[{"batb":[[0,1.35,24.18],[1,1.3,800.17]],"ltp":1.34,"tv":98329.14,"id":9342449}]}]}
{"op":"mcm","clk":"4230798751","pt":1631536738008,"mc":[{"id":"1.187557995","rc":[{"batl":[[0,1.44,156.94],[1,1.45,435.33],[2,1.47,212.5]],"ltp":1.34,"tv":98329.14,"id":9342449}]}]}
{"op":"mcm","clk":"4230798858","pt":1631536739141,"mc":[{"id":"1.187557995","rc":[{"batb":[[1,1.3,328.28]],"ltp":1.34,"tv":98329.14,"id":9342449}]}]}
{"op":"mcm","clk":"4230798997","pt":1631536740626,"mc":[{"id":"1.187557995","rc":[{"batb":[[0,1.42,361.61],[1,1.41,300.7],[2,1.4,268.36]],"batl":[[1,1.45,227.49],[2,1.47,928.06]],"ltp":1.34,"tv":98329.14,"id":9342449},{"batl":[[0,3.3,6.06],[1,4.4,8.49],[2,4.5,8.19]],"ltp":3.8,"tv":9896.95,"id":9633869}]}]}
{"op":"mcm","clk":"4230799073","pt":1631536741414,"mc":[{"id":"1.187557995","rc":[{"batb":[[1,1.41,507.22]],"batl":[[1,1.45,287.49]],"ltp":1.34,"tv":98329.14,"id":9342449},{"batb":[[0,3.25,16.07],[1,3.2,118.98],[2,3.1,16.34]],"batl":[[1,3.65,9.21],[2,4,42.45]],"ltp":3.8,"tv":9896.95,"id":9633869}]}]}
{"op":"mcm","clk":"4230799361","pt":1631536744426,"mc":[{"id":"1.187557995","rc":[{"batb":[[0,1.43,56.97],[1,1.42,701.71],[2,1.41,507.22]],"batl":[[0,1.44,390.28]],"ltp":1.34,"tv":98329.14,"id":9342449}]}]}
{"op":"mcm","clk":"4230799500","pt":1631536745527,"mc":[{"id":"1.187557995","rc":[{"batb":[[2,1.41,582.19]],"batl":[[1,1.45,352.9]],"ltp":1.34,"tv":98329.14,"id":9342449},{"batl":[[1,4,42.45],[2,4.4,8.49]],"ltp":3.8,"tv":9896.95,"id":9633869}]}]}
{"op":"mcm","clk":"4230799702","pt":1631536747618,"mc":[{"id":"1.187557995","rc":[{"batl":[[1,3.9,79.92],[2,3.95,58.65]],"ltp":3.8,"tv":9896.95,"id":9633869}]}]}
{"op":"mcm","clk":"4230799784","pt":1631536748647,"mc":[{"id":"1.187557995","rc":[{"batl":[[1,3.6,9.3],[2,3.9,79.92]],"ltp":3.8,"tv":9896.95,"id":9633869}]}]}
{"op":"mcm","clk":"4230799963","pt":1631536750535,"mc":[{"id":"1.187557995","rc":[{"trd":[[1.43,663.21]],"batb":[[0,1.43,56.89]],"ltp":1.43,"tv":98329.29,"id":9342449}],"tv":108226.25}]}
{"op":"mcm","clk":"4230800065","pt":1631536751684,"mc":[{"id":"1.187557995","rc":[{"batb":[[1,1.42,340.09],[2,1.41,460.12]],"batl":[[1,1.45,287.49],[2,1.58,124.92]],"ltp":1.43,"tv":98329.29,"id":9342449},{"batb":[[0,3.2,118.98],[1,2.82,3],[2,2.72,87.79]],"batl":[[0,3.6,9.3],[1,3.9,79.92],[2,3.95,58.65]],"ltp":3.8,"tv":9896.95,"id":9633869}]}]}
{"op":"mcm","clk":"4230800108","pt":1631536752041,"mc":[{"id":"1.187557995","rc":[{"trd":[[1.43,669.16]],"batb":[[0,1.43,53.92],[1,1.42,80.37],[2,1.36,228.35]],"batl":[[0,1.44,56.4],[1,1.45,60],[2,1.58,120.92]],"ltp":1.43,"tv":98335.24,"id":9342449},{"batb":[[0,3.2,27.27],[1,2.72,87.79],[2,2.7,81.19]],"ltp":3.8,"tv":9896.95,"id":9633869}],"tv":108232.19}]}
{"op":"mcm","clk":"4230800278","pt":1631536753458,"mc":[{"id":"1.187557995","rc":[{"batb":[[0,1.36,228.35],[1,1.35,314.67],[2,1.34,452.07]],"batl":[[0,1.52,219.76],[1,1.58,120.92],[2,1.59,152.37]],"ltp":1.43,"tv":98335.24,"id":9342449},{"batb":[[0,2.72,87.79],[1,2.7,81.19],[2,2.68,181.02]],"batl":[[0,3.9,79.92],[1,3.95,58.65],[2,4,67.05]],"ltp":3.8,"tv":9896.95,"id":9633869}]}]}
{"op":"mcm","clk":"4230800378","pt":1631536754652,"mc":[{"id":"1.187557995","rc":[{"batl":[[0,1.58,120.92],[1,1.59,152.37],[2,1.6,160.09]],"ltp":1.43,"tv":98335.24,"id":9342449},{"batb":[[0,2.72,87.94]],"ltp":3.8,"tv":9896.95,"id":9633869}]}]}
{"op":"mcm","clk":"4230800448","pt":1631536755439,"mc":[{"id":"1.187557995","rc":[{"batb":[[2,1.34,182.96]],"batl":[[0,1.57,287.45],[1,1.58,280.48],[2,1.59,152.37]],"ltp":1.43,"tv":98335.24,"id":9342449},{"batb":[[1,2.7,137.51],[2,2.68,124.28]],"ltp":3.8,"tv":9896.95,"id":9633869}]}]}
{"op":"mcm","clk":"4230800678","pt":1631536758243,"mc":[{"id":"1.187557995","rc":[{"batl":[[0,1.57,497.84]],"ltp":1.43,"tv":98335.24,"id":9342449}]}]}
{"op":"mcm","clk":"4230800759","pt":1631536759145,"mc":[{"id":"1.187557995","rc":[{"batl":[[0,1.56,210.39],[1,1.57,287.45],[2,1.58,280.48]],"ltp":1.43,"tv":98335.24,"id":9342449}]}]}
{"op":"mcm","clk":"4230800979","pt":1631536761429,"mc":[{"id":"1.187557995","rc":[{"batl":[[0,1.43,3.9],[1,1.56,210.39],[2,1.57,287.45]],"ltp":1.43,"tv":98335.24,"id":9342449}]}]}
{"op":"mcm","clk":"4230801180","pt":1631536763357,"mc":[{"id":"1.187557995","rc":[{"batb":[[0,1.36,225.72],[2,1.33,271.63]],"batl":[[1,1.46,10],[2,1.56,210.39]],"ltp":1.43,"tv":98335.24,"id":9342449},{"batl":[[0,3.9,11.45],[1,4.3,10.15],[2,4.4,8.49]],"ltp":3.8,"tv":9896.95,"id":9633869}]}]}
{"op":"mcm","clk":"4230801305","pt":1631536764670,"mc":[{"id":"1.187557995","rc":[{"trd":[[1.43,676.97],[1.44,892.18],[1.46,26.32]],"batl":[[0,1.56,210.39],[1,1.57,287.45],[2,1.58,280.48]],"ltp":1.46,"tv":98363.4,"id":9342449},{"trd":[[3.3,130.33]],"batb":[[0,2.72,87.79]],"ltp":3.3,"tv":9897.1,"id":9633869}],"tv":108260.51}]}
{"op":"mcm","clk":"4230801369","pt":1631536765358,"mc":[{"id":"1.187557995","rc":[{"batl":[[0,1.57,287.45],[1,1.58,280.48],[2,1.59,152.37]],"ltp":1.46,"tv":98363.4,"id":9342449}]}]}
{"op":"mcm","clk":"4230801482","pt":1631536766661,"mc":[{"id":"1.187557995","rc":[{"batb":[[0,1.56,2.62],[1,1.52,281.33],[2,1.51,191.88]],"batl":[[2,1.59,813.93]],"ltp":1.46,"tv":98363.4,"id":9342449},{"batl":[[0,2.82,7.09],[1,2.98,641.78],[2,3,622.9]],"ltp":3.3,"tv":9897.1,"id":9633869}]}]}
{"op":"mcm","clk":"4230801594","pt":1631536767664,"mc":[{"id":"1.187557995","rc":[{"trd":[[1.54,6.72],[1.56,11.13]],"batb":[[0,1.54,142.88]],"ltp":1.54,"tv":98369.97,"id":9342449},{"trd":[[2.8,1.46]],"batb":[[0,2.74,22.73],[1,2.72,87.79],[2,2.7,137.51]],"ltp":2.8,"tv":9898.56,"id":9633869}],"tv":108268.54}]}
{"op":"mcm","clk":"4230801651","pt":1631536768347,"mc":[{"id":"1.187557995","rc":[{"batl":[[0,1.57,321.85]],"ltp":1.54,"tv":98369.97,"id":9342449}]}]}
{"op":"mcm","clk":"4230801854","pt":1631536770564,"mc":[{"id":"1.187557995","rc":[{"batb":[[1,1.53,182.03],[2,1.52,281.33]],"batl":[[0,1.57,529.25]],"ltp":1.54,"tv":98369.97,"id":9342449}]}]}
{"op":"mcm","clk":"4230801943","pt":1631536771458,"mc":[{"id":"1.187557995","rc":[{"batb":[[0,1.54,322.34]],"batl":[[0,1.57,589.25]],"ltp":1.54,"tv":98369.97,"id":9342449},{"batb":[[0,2.76,34.09]],"ltp":2.8,"tv":9898.56,"id":9633869}]}]}
{"op":"mcm","clk":"4230802229","pt":1631536774626,"mc":[{"id":"1.187557995","rc":[{"batb":[[0,2.76,56.82]],"ltp":2.8,"tv":9898.56,"id":9633869}]}]}
{"op":"mcm","clk":"4230802570","pt":1631536778646,"mc":[{"id":"1.187557995","rc":[{"batl":[[0,1.56,10],[1,1.57,589.25],[2,1.58,280.48]],"ltp":1.54,"tv":98369.97,"id":9342449}]}]}
{"op":"mcm","clk":"4230802865","pt":1631536781521,"mc":[{"id":"1.187557995","rc":[{"batl":[[0,1.56,44.99]],"ltp":1.54,"tv":98369.97,"id":9342449},{"trd":[[2.82,8.54]],"batl":[[0,2.82,2.82]],"ltp":2.82,"tv":9907.1,"id":9633869}],"tv":108277.08}]}
{"op":"mcm","clk":"4230802982","pt":1631536782712,"mc":[{"id":"1.187557995","rc":[{"trd":[[1.54,8.32],[1.56,14.48]],"batb":[[0,1.54,321.54]],"batl":[[0,1.56,41.64]],"ltp":1.56,"tv":98374.92,"id":9342449},{"trd":[[2.78,1.89]],"ltp":2.78,"tv":9908.99,"id":9633869}],"tv":108283.92}]}
{"op":"mcm","clk":"4230803164","pt":1631536784428,"mc":[{"id":"1.187557995","rc":[{"trd":[[2.82,14.18]],"batl":[[0,2.98,641.78],[1,3,633.5],[2,3.05,622.9]],"ltp":2.82,"tv":9914.63,"id":9633869}],"tv":108289.56}]}
{"op":"mcm","clk":"4230803447","pt":1631536787511,"mc":[{"id":"1.187557995","rc":[{"trd":[[1.54,95.14],[1.56,14.75]],"batb":[[0,1.54,278.11]],"batl":[[0,1.56,41.37]],"ltp":1.54,"tv":98462.01,"id":9342449},{"trd":[[2.78,2.04]],"batl":[[0,2.96,18.67],[1,2.98,641.78],[2,3,633.5]],"ltp":2.78,"tv":9914.78,"id":9633869}],"tv":108376.8}]}
{"op":"mcm","clk":"4230804416","pt":1631536798646,"mc":[{"id":"1.187557995","rc":[{"trd":[[1.54,99.79]],"batb":[[0,1.54,275.78]],"batl":[[0,1.56,6.38]],"ltp":1.54,"tv":98466.66,"id":9342449}],"tv":108381.45}]}
{"op":"mcm","clk":"4230804483","pt":1631536799327,"mc":[{"id":"1.187557995","rc":[{"trd":[[1.54,143.2]],"batb":[[0,1.54,254.07]],"ltp":1.54,"tv":98510.08,"id":9342449}],"tv":108424.86}]}
{"op":"mcm","clk":"4230804874","pt":1631536803268,"mc":[{"id":"1.187557995","rc":[{"batb":[[2,1.48,348.05]],"batl":[[1,1.57,301.8],[2,1.58,120.92]],"ltp":1.54,"tv":98510.08,"id":9342449}]}]}
{"op":"mcm","clk":"4230805110","pt":1631536805680,"mc":[{"id":"1.187557995","rc":[{"batl":[[1,3,10.6],[2,3.1,89.88]],"ltp":2.78,"tv":9914.78,"id":9633869}]}]}
{"op":"mcm","clk":"4230805167","pt":1631536806255,"mc":[{"id":"1.187557995","rc":[{"batb":[[0,1.48,153.54],[1,1.47,377.23],[2,1.46,389.07]],"batl":[[1,1.57,60],[2,1.63,456.8]],"ltp":1.54,"tv":98510.08,"id":9342449},{"batb":[[0,2.76,34.09],[1,2.58,68.85],[2,2.56,82.42]],"batl":[[0,3,10.6],[1,3.1,72.93],[2,3.15,85.16]],"ltp":2.78,"tv":9914.78,"id":9633869}]}]}
{"op":"mcm","clk":"4230805283","pt":1631536807464,"mc":[{"id":"1.187557995","rc":[{"batl":[[1,1.63,456.8],[2,1.64,250.65]],"ltp":1.54,"tv":98510.08,"id":9342449},{"batb":[[0,2.58,68.85],[1,2.56,82.42],[2,2.54,182.54]],"batl":[[0,3.1,72.93],[1,3.15,85.16],[2,3.2,93.86]],"ltp":2.78,"tv":9914.78,"id":9633869}]}]}
{"op":"mcm","clk":"4230805324","pt":1631536807973,"mc":[{"id":"1.187557995","rc":[{"batl":[[0,1.54,4.03],[1,1.56,6.38],[2,1.63,456.8]],"ltp":1.54,"tv":98510.08,"id":9342449}]}]}
{"op":"mcm","clk":"4230805464","pt":1631536809645,"mc":[{"id":"1.187557995","rc":[{"batb":[[0,1.48,390.3],[1,1.47,202.34]],"batl":[[1,1.63,456.8],[2,1.64,250.65]],"ltp":1.54,"tv":98510.08,"id":9342449},{"batb":[[0,2.58,131.78],[2,2.54,116.18]],"batl":[[0,3.1,88.88]],"ltp":2.78,"tv":9914.78,"id":9633869}]}]}
{"op":"mcm","clk":"4230805472","pt":1631536809755,"mc":[{"id":"1.187557995","rc":[{"batb":[[0,1.48,153.54]],"ltp":1.54,"tv":98510.08,"id":9342449},{"batl":[[0,3.1,72.93]],"ltp":2.78,"tv":9914.78,"id":9633869}]}]}
{"op":"mcm","clk":"4230805639","pt":1631536811193,"mc":[{"id":"1.187557995","rc":[{"trd":[[1.54,147.23]],"batl":[[0,1.63,456.8],[1,1.64,250.65],[2,1.65,311.79]],"ltp":1.54,"tv":98514.11,"id":9342449},{"trd":[[2.58,47.58],[2.84,16.27]],"batb":[[0,2.58,107.99]],"ltp":2.58,"tv":9964.55,"id":9633869}],"tv":108478.66}]}
{"op":"mcm","clk":"4230805861","pt":1631536813384,"mc":[{"id":"1.187557995","rc":[{"batb":[[0,1.52,5.08],[1,1.51,10.21],[2,1.5,15.42]],"ltp":1.54,"tv":98514.11,"id":9342449}]}]}
{"op":"mcm","clk":"4230806132","pt":1631536816566,"mc":[{"id":"1.187557995","rc":[{"batl":[[0,3.1,88.58]],"ltp":2.58,"tv":9964.55,"id":9633869}]}]}
{"op":"mcm","clk":"4230806159","pt":1631536816875,"mc":[{"id":"1.187557995","rc":[{"batl":[[0,3.1,72.93]],"ltp":2.58,"tv":9964.55,"id":9633869}]}]}
{"op":"mcm","clk":"4230806745","pt":1631536823572,"mc":[{"id":"1.187557995","rc":[{"batl":[[0,3.1,88.18]],"ltp":2.58,"tv":9964.55,"id":9633869}]}]}
{"op":"mcm","clk":"4230806779","pt":1631536823881,"mc":[{"id":"1.187557995","rc":[{"batl":[[0,3.1,72.93]],"ltp":2.58,"tv":9964.55,"id":9633869}]}]}
{"op":"mcm","clk":"4230806949","pt":1631536825607,"mc":[{"id":"1.187557995","rc":[{"batl":[[0,3.3,14.35],[1,6,3],[2,6.4,3]],"ltp":2.58,"tv":9964.55,"id":9633869}]}]}
{"op":"mcm","clk":"4230807117","pt":1631536827278,"mc":[{"id":"1.187557995","rc":[{"batl":[[0,1.63,238.74]],"ltp":1.54,"tv":98514.11,"id":9342449}]}]}
{"op":"mcm","clk":"4230807231","pt":1631536828578,"mc":[{"id":"1.187557995","rc":[{"batb":[[0,1.58,220.08],[1,1.57,163.56],[2,1.52,5.08]],"ltp":1.54,"tv":98514.11,"id":9342449},{"batl":[[0,2.68,1059.7],[1,2.72,518.38],[2,2.74,259.19]],"ltp":2.58,"tv":9964.55,"id":9633869}]}]}
{"op":"mcm","clk":"4230807322","pt":1631536829620,"mc":[{"id":"1.187557995","rc":[{"batb":[[0,1.58,351.79],[2,1.54,1352.8]],"batl":[[1,1.64,310.65]],"ltp":1.54,"tv":98514.11,"id":9342449},{"trd":[[2.58,47.6]],"batb":[[0,2.58,107.98],[1,2.56,120.88]],"batl":[[1,2.72,172.8],[2,2.74,86.4]],"ltp":2.58,"tv":9964.57,"id":9633869}],"tv":108478.68}]}
{"op":"mcm","clk":"4230807356","pt":1631536829992,"mc":[{"id":"1.187557995","rc":[{"batb":[[0,2.58,128.15]],"ltp":2.58,"tv":9964.57,"id":9633869}]}]}
{"op":"mcm","clk":"4230807579","pt":1631536832613,"mc":[{"id":"1.187557995","rc":[{"batb":[[0,1.61,15.96],[1,1.6,32.13],[2,1.59,73.49]],"batl":[[0,1.62,71.66],[1,1.63,238.74],[2,1.64,310.65]],"ltp":1.54,"tv":98514.11,"id":9342449}]}]}
{"op":"mcm","clk":"4230807716","pt":1631536833716,"mc":[{"id":"1.187557995","rc":[{"batb":[[2,1.59,156.99]],"ltp":1.54,"tv":98514.11,"id":9342449}]}]}
{"op":"mcm","clk":"4230807891","pt":1631536835706,"mc":[{"id":"1.187557995","rc":[{"batb":[[1,1.6,115.21]],"ltp":1.54,"tv":98514.11,"id":9342449}]}]}
{"op":"mcm","clk":"4230807979","pt":1631536836694,"mc":[{"id":"1.187557995","rc":[{"trd":[[1.61,3.49]],"batb":[[0,1.61,12.47]],"ltp":1.61,"tv":98517.6,"id":9342449},{"trd":[[2.64,9.71]],"ltp":2.64,"tv":9966.7,"id":9633869}],"tv":108484.3}]}
{"op":"mcm","clk":"4230808064","pt":1631536837582,"mc":[{"id":"1.187557995","rc":[{"batb":[[2,1.59,313.48]],"ltp":1.61,"tv":98517.6,"id":9342449},{"batl":[[0,2.68,1152.54]],"ltp":2.64,"tv":9966.7,"id":9633869}]}]}
{"op":"mcm","clk":"4230808214","pt":1631536839405,"mc":[{"id":"1.187557995","rc":[{"batl":[[1,2.7,108.18],[2,2.72,172.8]],"ltp":2.64,"tv":9966.7,"id":9633869}]}]}
{"op":"mcm","clk":"4230808319","pt":1631536840611,"mc":[{"id":"1.187557995","rc":[{"batb":[[0,1.61,117.21]],"batl":[[0,1.62,135.76]],"ltp":1.61,"tv":98517.6,"id":9342449}]}]}
{"op":"mcm","clk":"4230808350","pt":1631536840924,"mc":[{"id":"1.187557995","rc":[{"batb":[[1,1.6,83.08],[2,1.59,239.99]],"batl":[[0,1.62,71.66]],"ltp":1.61,"tv":98517.6,"id":9342449}]}]}
{"op":"mcm","clk":"4230808517","pt":1631536842702,"mc":[{"id":"1.187557995","rc":[{"trd":[[1.62,71.66]],"batb":[[0,1.53,167.33],[1,1.52,491.48],[2,1.51,159.16]],"batl":[[0,1.62,205],[1,1.64,60],[2,1.68,244.46]],"ltp":1.62,"tv":98589.26,"id":9342449},{"trd":[[2.58,98.67],[2.6,44.65]],"batb":[[0,2.56,38.46],[1,2.44,93.97],[2,2.36,23.68]],"batl":[[0,2.8,11.18],[1,2.9,15.95],[2,3.3,14.35]],"ltp":2.58,"tv":10062.42,"id":9633869}],"tv":108651.68}]}
{"op":"mcm","clk":"4230808583","pt":1631536843429,"mc":[{"id":"1.187557995","rc":[{"batl":[[0,1.6,14.46],[1,1.68,244.46],[2,1.69,160.5]],"ltp":1.62,"tv":98589.26,"id":9342449},{"batb":[[0,2.44,93.97],[1,2.36,23.68],[2,1.97,1.05]],"batl":[[0,2.9,15.95],[1,3.3,14.35],[2,6,3]],"ltp":2.58,"tv":10062.42,"id":9633869}]}]}
{"op":"mcm","clk":"4230808673","pt":1631536844420,"mc":[{"id":"1.187557995","rc":[{"trd":[[1.6,329.89]],"batl":[[0,1.68,244.46],[1,1.69,160.5],[2,1.73,118.5]],"ltp":1.6,"tv":98618.19,"id":9342449}],"tv":108680.62}]}
{"op":"mcm","clk":"4230808837","pt":1631536846098,"mc":[{"id":"1.187557995","rc":[{"batb":[[2,1.5,160.25]],"ltp":1.6,"tv":98618.19,"id":9342449},{"trd":[[2.46,4]],"batb":[[0,2.46,70.3],[1,2.44,21.17],[2,2.36,23.68]],"ltp":2.46,"tv":10066.42,"id":9633869}],"tv":108684.62}]}
{"op":"mcm","clk":"4230809037","pt":1631536848594,"mc":[{"id":"1.187557995","rc":[{"batb":[[0,1.57,161.79],[1,1.56,167.63],[2,1.54,209.54]],"batl":[[0,1.61,302.4],[1,1.62,145.4],[2,1.68,244.46]],"ltp":1.6,"tv":98618.19,"id":9342449}]}]}
{"op":"mcm","clk":"4230809131","pt":1631536849642,"mc":[{"id":"1.187557995","rc":[{"batb":[[1,1.56,331.71],[2,1.54,258.87]],"batl":[[2,1.67,83.03]],"ltp":1.6,"tv":98618.19,"id":9342449},{"batb":[[0,2.48,59.39],[1,2.46,70.3],[2,2.44,21.17]],"batl":[[0,2.88,31.43],[1,2.9,15.95],[2,3.3,14.35]],"ltp":2.46,"tv":10066.42,"id":9633869}]}]}
{"op":"mcm","clk":"4230809201","pt":1631536850214,"mc":[{"id":"1.187557995","rc":[{"batb":[[1,1.56,167.63]],"ltp":1.6,"tv":98618.19,"id":9342449},{"batl":[[0,2.9,15.95],[1,3.3,14.35],[2,6,3]],"ltp":2.46,"tv":10066.42,"id":9633869}]}]}
{"op":"mcm","clk":"4230809415","pt":1631536852506,"mc":[{"id":"1.187557995","rc":[{"batl":[[0,1.61,175.26],[2,1.67,93.03]],"ltp":1.6,"tv":98618.19,"id":9342449}]}]}
{"op":"mcm","clk":"4230809482","pt":1631536853229,"mc":[{"id":"1.187557995","rc":[{"batb":[[0,1.58,70.4],[1,1.57,161.79],[2,1.56,167.63]],"ltp":1.6,"tv":98618.19,"id":9342449}]}]}
{"op":"mcm","clk":"4230809681","pt":1631536855620,"mc":[{"id":"1.187557995","rc":[{"batb":[[0,1.54,209.54],[1,1.53,167.33],[2,1.5,160.25]],"batl":[[0,1.61,9.15],[1,1.68,244.46],[2,1.69,160.5]],"ltp":1.6,"tv":98618.19,"id":9342449},{"batb":[[0,2.46,70.3],[1,2.44,21.17],[2,2.36,23.68]],"ltp":2.46,"tv":10066.42,"id":9633869}]}]}
{"op":"mcm","clk":"4230809954","pt":1631536858624,"mc":[{"id":"1.187557995","rc":[{"batb":[[0,1.55,71.36],[1,1.54,209.54],[2,1.53,167.33]],"batl":[[2,1.69,366.97]],"ltp":1.6,"tv":98618.19,"id":9342449}]}]}
{"op":"mcm","clk":"4230809973","pt":1631536858832,"mc":[{"id":"1.187557995","rc":[{"batb":[[0,1.54,209.54],[1,1.53,167.33],[2,1.51,317.85]],"ltp":1.6,"tv":98618.19,"id":9342449}]}]}
{"op":"mcm","clk":"4230810109","pt":1631536860513,"mc":[{"id":"1.187557995","rc":[{"trd":[[1.61,21.78]],"batb":[[0,1.54,210.16],[2,1.5,160.25]],"batl":[[0,1.68,244.46],[1,1.69,366.97],[2,1.71,240.43]],"ltp":1.61,"tv":98636.49,"id":9342449}],"tv":108702.91}]}
{"op":"mcm","clk":"4230810207","pt":1631536861440,"mc":[{"id":"1.187557995","rc":[{"batl":[[0,1.69,366.97],[1,1.71,240.43],[2,1.82,2.89]],"ltp":1.61,"tv":98636.49,"id":9342449}]}]}
{"op":"mcm","clk":"4230810315","pt":1631536862645,"mc":[{"id":"1.187557995","rc":[{"batb":[[0,1.64,3251.51],[1,1.54,210.16],[2,1.53,167.33]],"batl":[[0,1.69,206.47]],"ltp":1.61,"tv":98636.49,"id":9342449},{"batb":[[1,2.38,1607.14],[2,2.36,1583.56]],"batl":[[0,2.56,7.81],[1,2.6,1471.16],[2,2.62,1427.88]],"ltp":2.46,"tv":10066.42,"id":9633869}]}]}
{"op":"mcm","clk":"4230810400","pt":1631536863634,"mc":[{"id":"1.187557995","rc":[{"batb":[[0,1.64,171.08],[1,1.63,141.35],[2,1.54,210.16]],"batl":[[2,1.76,11.36]],"ltp":1.61,"tv":98636.49,"id":9342449},{"batb":[[1,2.38,441.96],[2,2.36,452.65]],"batl":[[1,2.6,735.58],[2,2.62,713.94]],"ltp":2.46,"tv":10066.42,"id":9633869}]}]}
{"op":"mcm","clk":"4230810471","pt":1631536864415,"mc":[{"id":"1.187557995","rc":[{"batb":[[0,1.64,287.81],[2,1.61,77.44]],"batl":[[1,1.7,60],[2,1.71,240.43]],"ltp":1.61,"tv":98636.49,"id":9342449},{"batb":[[1,2.42,42.25],[2,2.38,441.96]],"ltp":2.46,"tv":10066.42,"id":9633869}]}]}
{"op":"mcm","clk":"4230811369","pt":1631536867649,"mc":[{"id":"1.187557995","rc":[{"batb":[[0,1.67,40.38],[1,1.66,81.24],[2,1.65,143.04]],"batl":[[0,1.68,66.95],[1,1.69,206.47],[2,1.7,60]],"ltp":1.61,"tv":98636.49,"id":9342449}]}]}
{"op":"mcm","clk":"4230811429","pt":1631536868063,"mc":[{"id":"1.187557995","rc":[{"trd":[[2.46,62.12]],"batb":[[0,2.46,41.23]],"ltp":2.46,"tv":10124.53,"id":9633869}],"tv":108761.03}]}
{"op":"mcm","clk":"4230811675","pt":1631536870453,"mc":[{"id":"1.187557995","rc":[{"batb":[[1,1.66,148.8]],"ltp":1.61,"tv":98636.49,"id":9342449},{"batl":[[1,2.6,761.2]],"ltp":2.46,"tv":10124.53,"id":9633869}]}]}
{"op":"mcm","clk":"4230811772","pt":1631536871341,"mc":[{"id":"1.187557995","rc":[{"trd":[[1.67,1.4]],"batb":[[0,1.67,39.68]],"ltp":1.67,"tv":98637.88,"id":9342449},{"batl":[[1,2.58,26],[2,2.6,761.2]],"ltp":2.46,"tv":10124.53,"id":9633869}],"tv":108762.42}]}
{"op":"mcm","clk":"4230811862","pt":1631536872230,"mc":[{"id":"1.187557995","rc":[{"trd":[[1.67,7.78]],"batb":[[0,1.67,33.3]],"ltp":1.67,"tv":98644.26,"id":9342449},{"trd":[[2.5,4.26]],"ltp":2.5,"tv":10128.79,"id":9633869}],"tv":108773.06}]}
{"op":"mcm","clk":"4230812160","pt":1631536875570,"mc":[{"id":"1.187557995","rc":[{"batb":[[0,1.67,231.63],[1,1.66,67.56],[2,1.65,66.94]],"batl":[[0,1.68,212.95]],"ltp":1.67,"tv":98644.26,"id":9342449},{"trd":[[2.46,67.91]],"batb":[[0,2.46,38.33]],"ltp":2.46,"tv":10134.58,"id":9633869}],"tv":108778.85}]}
{"op":"mcm","clk":"4230812223","pt":1631536876359,"mc":[{"id":"1.187557995","rc":[{"trd":[[1.67,141.18]],"batb":[[0,1.67,164.92]],"ltp":1.67,"tv":98777.67,"id":9342449}],"tv":108912.26}]}
{"op":"mcm","clk":"4230812338","pt":1631536877663,"mc":[{"id":"1.187557995","rc":[{"batb":[[0,1.65,66.94],[1,1.64,3.82],[2,1.63,147.19]],"batl":[[0,1.68,146],[1,1.7,60],[2,1.72,226.58]],"ltp":1.67,"tv":98777.67,"id":9342449},{"batb":[[0,2.42,42.25],[1,2.36,81.09],[2,2.34,22.72]],"batl":[[0,2.58,4.75],[1,2.6,25.62],[2,2.62,25.5]],"ltp":2.46,"tv":10134.58,"id":9633869}]}]}
{"op":"mcm","clk":"4230812419","pt":1631536878446,"mc":[{"id":"1.187557995","rc":[{"batb":[[0,1.62,176.54],[1,1.59,625.73],[2,1.57,136.99]],"batl":[[0,1.72,226.58],[1,1.74,134.75],[2,1.77,135.5]],"ltp":1.67,"tv":98777.67,"id":9342449},{"batb":[[0,2.36,81.09],[1,2.34,22.72],[2,2.28,22.66]],"batl":[[0,2.62,20.75],[1,2.7,22.6],[2,2.9,15.95]],"ltp":2.46,"tv":10134.58,"id":9633869}]}]}
{"op":"mcm","clk":"4230812609","pt":1631536880572,"mc":[{"id":"1.187557995","rc":[{"batb":[[2,1.58,197.61]],"batl":[[1,1.74,302.02],[2,1.76,217.5]],"ltp":1.67,"tv":98777.67,"id":9342449},{"batb":[[1,2.34,104.56]],"ltp":2.46,"tv":10134.58,"id":9633869}]}]}
{"op":"mcm","clk":"4230812710","pt":1631536881423,"mc":[{"id":"1.187557995","rc":[{"batb":[[0,2.34,104.56],[1,2.28,22.66],[2,2.26,24.48]],"ltp":2.46,"tv":10134.58,"id":9633869}]}]}
{"op":"mcm","clk":"4230812824","pt":1631536882620,"mc":[{"id":"1.187557995","rc":[{"trd":[[1.72,0.75]],"batb":[[0,1.68,16],[1,1.62,176.54],[2,1.59,625.73]],"batl":[[0,1.72,226.2]],"ltp":1.72,"tv":98778.42,"id":9342449}],"tv":108913.01}]}
{"op":"mcm","clk":"4230813054","pt":1631536884697,"mc":[{"id":"1.187557995","rc":[{"batb":[[1,1.64,149.64],[2,1.62,180.87]],"ltp":1.72,"tv":98778.42,"id":9342449},{"batl":[[0,2.58,4.75],[1,2.62,25],[2,2.7,22.6]],"ltp":2.46,"tv":10134.58,"id":9633869}]}]}
{"op":"mcm","clk":"4230813065","pt":1631536884801,"mc":[{"id":"1.187557995","rc":[{"batb":[[1,1.62,176.54],[2,1.59,625.73]],"ltp":1.72,"tv":98778.42,"id":9342449},{"batl":[[0,2.62,20.75],[1,2.7,22.6],[2,2.9,15.95]],"ltp":2.46,"tv":10134.58,"id":9633869}]}]}
{"op":"mcm","clk":"4230813231","pt":1631536886636,"mc":[{"id":"1.187557995","rc":[{"batl":[[1,1.74,134.75],[2,1.77,135.5]],"ltp":1.72,"tv":98778.42,"id":9342449}]}]}
{"op":"mcm","clk":"4230813320","pt":1631536887511,"mc":[{"id":"1.187557995","rc":[{"trd":[[1.72,0.77]],"batb":[[0,1.68,18.32]],"batl":[[0,1.72,226.19],[1,1.82,2.89],[2,1.95,415.52]],"ltp":1.72,"tv":98778.44,"id":9342449},{"batb":[[0,2.34,81.84],[2,1.97,1.05]],"ltp":2.46,"tv":10134.58,"id":9633869}],"tv":108913.02}]}
{"op":"mcm","clk":"4230813425","pt":1631536888616,"mc":[{"id":"1.187557995","rc":[{"batb":[[2,1.59,199.84]],"ltp":1.72,"tv":98778.44,"id":9342449}]}]}
{"op":"mcm","clk":"4230813530","pt":1631536889711,"mc":[{"id":"1.187557995","rc":[{"trd":[[1.68,36.64]],"batb":[[0,1.62,176.54],[1,1.58,198.23],[2,1.57,299.32]],"batl":[[0,1.63,260.17],[1,1.64,138.74],[2,1.65,1159.1]],"ltp":1.68,"tv":98815.08,"id":9342449},{"batb":[[0,2.46,23.88],[1,2.34,81.84],[2,2.28,22.66]],"batl":[[1,2.9,15.95],[2,3.3,14.35]],"ltp":2.46,"tv":10134.58,"id":9633869}],"tv":108949.67}]}
{"op":"mcm","clk":"4230813630","pt":1631536890701,"mc":[{"id":"1.187557995","rc":[{"trd":[[1.62,136.29]],"batb":[[0,1.62,111.91]],"ltp":1.62,"tv":98879.71,"id":9342449},{"trd":[[2.62,81.5]],"batb":[[0,2.46,95.85],[1,2.28,22.66],[2,1.97,1.05]],"batl":[[0,2.68,7.46]],"ltp":2.62,"tv":10216.08,"id":9633869}],"tv":109095.8}]}
{"op":"mcm","clk":"4230813733","pt":1631536891589,"mc":[{"id":"1.187557995","rc":[{"batb":[[0,2.52,39.47],[1,2.46,95.85],[2,2.4,3]],"ltp":2.62,"tv":10216.08,"id":9633869}]}]}
{"op":"mcm","clk":"4230813782","pt":1631536892110,"mc":[{"id":"1.187557995","rc":[{"batb":[[1,2.46,99.85],[2,2.44,3]],"ltp":2.62,"tv":10216.08,"id":9633869}]}]}
{"op":"mcm","clk":"4230813911","pt":1631536893632,"mc":[{"id":"1.187557995","rc":[{"batl":[[1,2.8,11.18],[2,2.9,15.95]],"ltp":2.62,"tv":10216.08,"id":9633869}]}]}
{"op":"mcm","clk":"4230814025","pt":1631536894608,"mc":[{"id":"1.187557995","rc":[{"batb":[[0,1.62,239.91],[1,1.61,73.66],[2,1.58,197.61]],"batl":[[0,1.63,430.2]],"ltp":1.62,"tv":98879.71,"id":9342449},{"batb":[[1,2.48,88.29],[2,2.46,99.85]],"ltp":2.62,"tv":10216.08,"id":9633869}]}]}
{"op":"mcm","clk":"4230814142","pt":1631536895710,"mc":[{"id":"1.187557995","rc":[{"batl":[[0,1.63,329.39]],"ltp":1.62,"tv":98879.71,"id":9342449},{"batb":[[1,2.46,99.85],[2,2.44,3]],"ltp":2.62,"tv":10216.08,"id":9633869}]}]}
{"op":"mcm","clk":"4230814215","pt":1631536896597,"mc":[{"id":"1.187557995","rc":[{"batl":[[0,1.63,473.39]],"ltp":1.62,"tv":98879.71,"id":9342449},{"batl":[[1,2.8,29.95],[2,2.86,86.51]],"ltp":2.62,"tv":10216.08,"id":9633869}]}]}
{"op":"mcm","clk":"4230814407","pt":1631536898618,"mc":[{"id":"1.187557995","rc":[{"batl":[[1,1.64,198.74]],"ltp":1.62,"tv":98879.71,"id":9342449},{"batb":[[0,2.54,30.62],[1,2.52,39.47],[2,2.46,99.85]],"ltp":2.62,"tv":10216.08,"id":9633869}]}]}
{"op":"mcm","clk":"4230814553","pt":1631536900133,"mc":[{"id":"1.187557995","rc":[{"batb":[[0,2.46,99.85],[1,2.44,3],[2,2.4,98.02]],"ltp":2.62,"tv":10216.08,"id":9633869}]}]}
{"op":"mcm","clk":"4230814903","pt":1631536903514,"mc":[{"id":"1.187557995","rc":[{"batl":[[1,1.64,138.74]],"ltp":1.62,"tv":98879.71,"id":9342449},{"batb":[[0,2.48,47.56],[1,2.46,99.85],[2,2.44,3]],"ltp":2.62,"tv":10216.08,"id":9633869}]}]}
{"op":"mcm","clk":"4230814934","pt":1631536903827,"mc":[{"id":"1.187557995","rc":[{"trd":[[1.63,6.74]],"batb":[[0,1.62,111.91]],"batl":[[0,1.63,397.43]],"ltp":1.63,"tv":98886.45,"id":9342449},{"trd":[[2.58,102.92]],"batb":[[0,2.46,99.85],[1,2.44,3],[2,2.4,95.02]],"ltp":2.58,"tv":10220.34,"id":9633869}],"tv":109106.8}]}
{"op":"mcm","clk":"4230815095","pt":1631536905548,"mc":[{"id":"1.187557995","rc":[{"trd":[[1.62,146.29]],"batb":[[0,1.62,106.91]],"ltp":1.62,"tv":98896.45,"id":9342449},{"batb":[[1,2.4,95.02],[2,2.38,112.36]],"ltp":2.58,"tv":10220.34,"id":9633869}],"tv":109116.8}]}
{"op":"mcm","clk":"4230815176","pt":1631536906434,"mc":[{"id":"1.187557995","rc":[{"trd":[[1.62,224.97]],"batb":[[0,1.62,67.57]],"ltp":1.62,"tv":98975.13,"id":9342449}],"tv":109195.48}]}
{"op":"mcm","clk":"4230815278","pt":1631536907635,"mc":[{"id":"1.187557995","rc":[{"batb":[[0,2.52,39.47],[1,2.46,99.85],[2,2.4,95.02]],"batl":[[0,2.8,29.95],[1,2.86,86.51],[2,2.88,73.11]],"ltp":2.58,"tv":10220.34,"id":9633869}]}]}
{"op":"mcm","clk":"4230815341","pt":1631536908211,"mc":[{"id":"1.187557995","rc":[{"batb":[[0,1.56,653.04],[1,1.54,160.36],[2,1.53,354.46]],"batl":[[0,1.68,208.69],[1,1.71,240.44],[2,1.72,147.89]],"ltp":1.62,"tv":98975.13,"id":9342449},{"batb":[[1,2.46,71.97]],"ltp":2.58,"tv":10220.34,"id":9633869}]}]}
{"op":"mcm","clk":"4230815484","pt":1631536909625,"mc":[{"id":"1.187557995","rc":[{"batl":[[0,1.66,60],[1,1.68,208.69],[2,1.71,240.44]],"ltp":1.62,"tv":98975.13,"id":9342449},{"batb":[[0,2.46,71.97],[1,2.4,95.02],[2,2.38,112.36]],"batl":[[0,2.8,18.77]],"ltp":2.58,"tv":10220.34,"id":9633869}]}]}
{"op":"mcm","clk":"4230815566","pt":1631536910411,"mc":[{"id":"1.187557995","rc":[{"batl":[[0,1.68,208.69],[1,1.71,240.44],[2,1.72,147.89]],"ltp":1.62,"tv":98975.13,"id":9342449}]}]}
{"op":"mcm","clk":"4230815690","pt":1631536911460,"mc":[{"id":"1.187557995","rc":[{"batl":[[1,1.7,239.45],[2,1.71,240.44]],"ltp":1.62,"tv":98975.13,"id":9342449},{"batb":[[0,2.44,73.39]],"ltp":2.58,"tv":10220.34,"id":9633869}]}]}
{"op":"mcm","clk":"4230816000","pt":1631536914433,"mc":[{"id":"1.187557995","rc":[{"batb":[[0,1.63,29.75],[1,1.56,653.04],[2,1.54,160.36]],"ltp":1.62,"tv":98975.13,"id":9342449}]}]}
{"op":"mcm","clk":"4230816126","pt":1631536915961,"mc":[{"id":"1.187557995","rc":[{"batb":[[2,1.53,167.33]],"ltp":1.62,"tv":98975.13,"id":9342449},{"batl":[[1,2.9,15.95],[2,3.3,14.35]],"ltp":2.58,"tv":10220.34,"id":9633869}]}]}
{"op":"mcm","clk":"4230816272","pt":1631536917331,"mc":[{"id":"1.187557995","rc":[{"batb":[[1,1.53,167.95],[2,1.5,163.85]],"batl":[[0,1.7,239.45],[1,1.71,240.44],[2,1.72,383.35]],"ltp":1.62,"tv":98975.13,"id":9342449},{"batl":[[0,2.9,15.95],[1,6,3],[2,6.4,3]],"ltp":2.58,"tv":10220.34,"id":9633869}]}]}
{"op":"mcm","clk":"4230816401","pt":1631536918633,"mc":[{"id":"1.187557995","rc":[{"batl":[[0,2.54,7.87],[1,2.58,1482.56],[2,2.6,1438.96]],"ltp":2.58,"tv":10220.34,"id":9633869}]}]}
{"op":"mcm","clk":"4230816517","pt":1631536919626,"mc":[{"id":"1.187557995","rc":[{"batb":[[0,1.64,373.05],[1,1.63,141.45],[2,1.58,134.76]],"ltp":1.62,"tv":98975.13,"id":9342449},{"batl":[[1,2.58,741.28],[2,2.6,719.48]],"ltp":2.58,"tv":10220.34,"id":9633869}]}]}
{"op":"mcm","clk":"4230816620","pt":1631536920619,"mc":[{"id":"1.187557995","rc":[{"batb":[[2,1.61,77.44]],"ltp":1.62,"tv":98975.13,"id":9342449},{"batb":[[2,2.38,155.83]],"ltp":2.58,"tv":10220.34,"id":9633869}]}]}
{"op":"mcm","clk":"4230816691","pt":1631536921451,"mc":[{"id":"1.187557995","rc":[{"batb":[[1,1.63,178.09]],"ltp":1.62,"tv":98975.13,"id":9342449}]}]}
{"op":"mcm","clk":"4230816790","pt":1631536922445,"mc":[{"id":"1.187557995","rc":[{"batb":[[2,1.58,134.76]],"ltp":1.62,"tv":98975.13,"id":9342449}]}]}
{"op":"mcm","clk":"4230816902","pt":1631536923649,"mc":[{"id":"1.187557995","rc":[{"batb":[[0,1.68,7.84],[1,1.67,15.78],[2,1.66,23.82]],"batl":[[0,1.69,75.55],[1,1.7,239.45],[2,1.71,240.44]],"ltp":1.62,"tv":98975.13,"id":9342449}]}]}
{"op":"mcm","clk":"4230817084","pt":1631536925641,"mc":[{"id":"1.187557995","rc":[{"batl":[[2,2.6,745.1]],"ltp":2.58,"tv":10220.34,"id":9633869}]}]}
{"op":"mcm","clk":"4230817126","pt":1631536926159,"mc":[{"id":"1.187557995","rc":[{"batb":[[1,1.67,105.53]],"ltp":1.62,"tv":98975.13,"id":9342449}]}]}
{"op":"mcm","clk":"4230817230","pt":1631536927258,"mc":[{"id":"1.187557995","rc":[{"batl":[[0,2.54,34.37],[1,2.58,767.97],[2,2.6,756.95]],"ltp":2.58,"tv":10220.34,"id":9633869}]}]}
{"op":"mcm","clk":"4230817418","pt":1631536929262,"mc":[{"id":"1.187557995","rc":[{"trd":[[1.69,75.55],[1.7,130.05]],"batl":[[0,1.7,109.4],[1,1.71,240.44],[2,1.72,383.35]],"ltp":1.7,"tv":99180.73,"id":9342449},{"trd":[[2.42,91.34],[2.44,199.02]],"batb":[[0,2.4,95.02],[1,2.38,155.83],[2,2.36,562.95]],"ltp":2.42,"tv":10510.7,"id":9633869}],"tv":109691.43}]}
{"op":"mcm","clk":"4230817560","pt":1631536930674,"mc":[{"id":"1.187557995","rc":[{"batb":[[1,1.67,15.78]],"batl":[[0,1.78,143.75],[1,1.82,2.89],[2,2.08,1]],"ltp":1.7,"tv":99180.73,"id":9342449},{"batb":[[0,2.34,82.59],[1,2.28,28.16],[2,1.97,1.05]],"batl":[[0,2.44,20.67],[1,2.6,32.41],[2,2.64,4.68]],"ltp":2.42,"tv":10510.7,"id":9633869}]}]}
{"op":"mcm","clk":"4230817639","pt":1631536931461,"mc":[{"id":"1.187557995","rc":[{"trd":[[1.69,105.3]],"batb":[[0,1.68,130.79],[1,1.63,177.23],[2,1.58,134.76]],"batl":[[0,1.69,40.34],[1,1.78,143.75],[2,1.82,2.89]],"ltp":1.69,"tv":99210.48,"id":9342449},{"trd":[[2.44,219.69]],"batl":[[0,2.6,20.56],[1,6,3],[2,6.4,3]],"ltp":2.44,"tv":10531.37,"id":9633869}],"tv":109741.85}]}
{"op":"mcm","clk":"4230817776","pt":1631536932663,"mc":[{"id":"1.187557995","rc":[{"trd":[[1.69,105.32]],"batb":[[1,1.65,193.24],[2,1.63,177.23]],"batl":[[0,1.69,40.32],[1,1.7,58.19],[2,1.78,143.75]],"ltp":1.69,"tv":99210.5,"id":9342449},{"trd":[[2.44,219.71]],"batb":[[0,2.42,20.88],[1,2.34,82.59],[2,2.28,28.16]],"ltp":2.44,"tv":10531.39,"id":9633869}],"tv":109741.9}]}
{"op":"mcm","clk":"4230817898","pt":1631536933662,"mc":[{"id":"1.187557995","rc":[{"batb":[[0,1.65,164.93],[1,1.63,180.92],[2,1.59,235.02]],"batl":[[0,1.75,141.14],[1,1.77,213.23]],"ltp":1.69,"tv":99210.5,"id":9342449},{"batb":[[0,2.34,86.59],[1,2.32,87.43]],"batl":[[0,2.54,21.25],[1,2.6,24.92],[2,6,3]],"ltp":2.44,"tv":10531.39,"id":9633869}]}]}
{"op":"mcm","clk":"4230817960","pt":1631536934271,"mc":[{"id":"1.187557995","rc":[{"batb":[[0,1.63,177.23],[1,1.59,235.02],[2,1.58,291.04]],"ltp":1.69,"tv":99210.5,"id":9342449},{"batb":[[0,2.34,4]],"batl":[[0,2.6,20.56],[1,6,3],[2,6.4,3]],"ltp":2.44,"tv":10531.39,"id":9633869}]}]}
{"op":"mcm","clk":"4230818068","pt":1631536935370,"mc":[{"id":"1.187557995","rc":[{"batb":[[0,1.64,247.02],[1,1.63,177.23],[2,1.59,235.02]],"ltp":1.69,"tv":99210.5,"id":9342449}]}]}
{"op":"mcm","clk":"4230818292","pt":1631536937671,"mc":[{"id":"1.187557995","rc":[{"batb":[[1,1.63,181.46]],"ltp":1.69,"tv":99210.5,"id":9342449},{"batl":[[0,2.6,25.22]],"ltp":2.44,"tv":10531.39,"id":9633869}]}]}
{"op":"mcm","clk":"4230818448","pt":1631536939385,"mc":[{"id":"1.187557995","rc":[{"trd":[[1.64,14.46]],"batb":[[0,1.64,239.79],[2,1.58,132.25]],"ltp":1.64,"tv":99224.97,"id":9342449}],"tv":109756.36}]}
{"op":"mcm","clk":"4230818551","pt":1631536940610,"mc":[{"id":"1.187557995","rc":[{"batb":[[0,1.65,133.33],[1,1.64,239.79],[2,1.63,181.46]],"batl":[[0,1.75,137.14]],"ltp":1.64,"tv":99224.97,"id":9342449},{"batb":[[0,2.32,84.43],[1,2.28,28.16],[2,1.97,1.05]],"batl":[[0,2.54,20.25],[1,2.6,25.22],[2,990,0.01]],"ltp":2.44,"tv":10531.39,"id":9633869}]}]}
{"op":"mcm","clk":"4230818620","pt":1631536941194,"mc":[{"id":"1.187557995","rc":[{"batb":[[0,1.64,239.79],[1,1.63,181.46],[2,1.58,132.25]],"ltp":1.64,"tv":99224.97,"id":9342449},{"batl":[[0,2.6,25.22],[1,990,0.01],[2,990,0]],"ltp":2.44,"tv":10531.39,"id":9633869}]}]}
{"op":"mcm","clk":"4230818761","pt":1631536942659,"mc":[{"id":"1.187557995","rc":[{"batb":[[0,1.7,194.56],[1,1.69,123.55],[2,1.63,181.46]],"batl":[[2,1.78,734.69]],"ltp":1.64,"tv":99224.97,"id":9342449},{"batl":[[0,2.44,4.83],[1,2.46,8.13],[2,2.48,771.18]],"ltp":2.44,"tv":10531.39,"id":9633869}]}]}
{"op":"mcm","clk":"4230818844","pt":1631536943484,"mc":[{"id":"1.187557995","rc":[{"batb":[[0,1.7,296.23],[2,1.68,72.76]],"ltp":1.64,"tv":99224.97,"id":9342449},{"batb":[[2,2.26,47.61]],"ltp":2.44,"tv":10531.39,"id":9633869}]}]}
{"op":"mcm","clk":"4230818883","pt":1631536943973,"mc":[{"id":"1.187557995","rc":[{"batb":[[0,2.32,105.56]],"ltp":2.44,"tv":10531.39,"id":9633869}]}]}
{"op":"mcm","clk":"4230819127","pt":1631536946588,"mc":[{"id":"1.187557995","rc":[{"batb":[[0,1.73,49.53],[1,1.72,99.64],[2,1.71,137.82]],"batl":[[0,1.74,70.78],[1,1.75,137.14],[2,1.77,213.23]],"ltp":1.64,"tv":99224.97,"id":9342449}]}]}
{"op":"mcm","clk":"4230819391","pt":1631536949697,"mc":[{"id":"1.187557995","rc":[{"batb":[[1,1.72,170.51]],"batl":[[1,1.78,734.69],[2,1.79,633.56]],"ltp":1.64,"tv":99224.97,"id":9342449},{"batb":[[0,2.32,84.43]],"ltp":2.44,"tv":10531.39,"id":9633869}]}]}
{"op":"mcm","clk":"4230819476","pt":1631536950689,"mc":[{"id":"1.187557995","rc":[{"batl":[[2,2.48,783.5]],"ltp":2.44,"tv":10531.39,"id":9633869}]}]}
{"op":"mcm","clk":"4230819526","pt":1631536951382,"mc":[{"id":"1.187557995","rc":[{"trd":[[1.73,2.52]],"batb":[[0,1.73,48.27]],"batl":[[0,1.74,197.78]],"ltp":1.73,"tv":99227.49,"id":9342449}],"tv":109758.88}]}
{"op":"mcm","clk":"4230819776","pt":1631536953580,"mc":[{"id":"1.187557995","rc":[{"trd":[[1.74,165.67]],"batb":[[0,1.73,56.47],[1,1.72,70.87],[2,1.71,72.5]],"batl":[[0,1.74,50.61],[1,1.77,77.43],[2,1.78,734.69]],"ltp":1.74,"tv":99393.16,"id":9342449}],"tv":109924.56}]}
{"op":"mcm","clk":"4230819979","pt":1631536955602,"mc":[{"id":"1.187557995","rc":[{"batb":[[0,1.71,72.5],[1,1.7,104.72],[2,1.68,72.76]],"batl":[[1,1.78,734.69],[2,1.79,633.56]],"ltp":1.74,"tv":99393.16,"id":9342449}]}]}
{"op":"mcm","clk":"4230820056","pt":1631536956605,"mc":[{"id":"1.187557995","rc":[{"batb":[[0,1.73,353.32],[1,1.71,72.5],[2,1.7,104.72]],"ltp":1.74,"tv":99393.16,"id":9342449}]}]}
{"op":"mcm","clk":"4230820118","pt":1631536957282,"mc":[{"id":"1.187557995","rc":[{"batb":[[0,1.73,636.96]],"batl":[[0,1.74,127]],"ltp":1.74,"tv":99393.16,"id":9342449}]}]}
{"op":"mcm","clk":"4230820357","pt":1631536959694,"mc":[{"id":"1.187557995","rc":[{"trd":[[1.73,64.03]],"batb":[[0,1.73,606.2]],"ltp":1.73,"tv":99454.67,"id":9342449}],"tv":109986.06}]}
{"op":"mcm","clk":"4230820392","pt":1631536960007,"mc":[{"id":"1.187557995","rc":[{"trd":[[1.74,411.07]],"batl":[[0,1.74,4.3]],"ltp":1.74,"tv":99700.07,"id":9342449}],"tv":110231.46}]}
{"op":"mcm","clk":"4230820699","pt":1631536963188,"mc":[{"id":"1.187557995","rc":[{"trd":[[1.74,419.67]],"batb":[[0,1.74,83.99],[1,1.73,606.2],[2,1.71,72.5]],"batl":[[0,1.75,82.72]],"ltp":1.74,"tv":99708.67,"id":9342449}],"tv":110240.06}]}
{"op":"mcm","clk":"4230820897","pt":1631536965492,"mc":[{"id":"1.187557995","rc":[{"trd":[[1.74,424.32]],"batb":[[0,1.74,81.67]],"ltp":1.74,"tv":99713.32,"id":9342449}],"tv":110244.71}]}
{"op":"mcm","clk":"4230820995","pt":1631536966488,"mc":[{"id":"1.187557995","rc":[{"trd":[[1.74,430.18]],"batb":[[0,1.74,78.74]],"batl":[[0,1.77,106.07]],"ltp":1.74,"tv":99719.17,"id":9342449}],"tv":110250.57}]}
{"op":"mcm","clk":"4230821196","pt":1631536968712,"mc":[{"id":"1.187557995","rc":[{"batl":[[0,1.75,237],[1,1.77,106.07],[2,1.78,734.69]],"ltp":1.74,"tv":99719.17,"id":9342449}]}]}
{"op":"mcm","clk":"4230821511","pt":1631536971921,"mc":[{"id":"1.187557995","rc":[{"batl":[[0,1.75,360.06]],"ltp":1.74,"tv":99719.17,"id":9342449}]}]}
{"op":"mcm","clk":"4230821872","pt":1631536975947,"mc":[{"id":"1.187557995","rc":[{"trd":[[2.32,8]],"batb":[[0,2.32,80.43]],"ltp":2.32,"tv":10539.39,"id":9633869}],"tv":110258.57}]}
{"op":"mcm","clk":"4230822190","pt":1631536979655,"mc":[{"id":"1.187557995","rc":[{"batb":[[0,1.74,646.03]],"ltp":1.74,"tv":99719.17,"id":9342449}]}]}
{"op":"mcm","clk":"4230822454","pt":1631536982571,"mc":[{"id":"1.187557995","rc":[{"batl":[[1,1.76,136.5],[2,1.77,106.07]],"ltp":1.74,"tv":99719.17,"id":9342449}]}]}
{"op":"mcm","clk":"4230822878","pt":1631536987165,"mc":[{"id":"1.187557995","rc":[{"batb":[[0,1.74,929.68]],"ltp":1.74,"tv":99719.17,"id":9342449}]}]}
{"op":"mcm","clk":"4230823388","pt":1631536993161,"mc":[{"id":"1.187557995","rc":[{"batb":[[2,1.71,173.17]],"ltp":1.74,"tv":99719.17,"id":9342449},{"batb":[[0,2.3,85.44]],"ltp":2.32,"tv":10539.39,"id":9633869}]}]}
{"op":"mcm","clk":"4230823693","pt":1631536996795,"mc":[{"id":"1.187557995","rc":[{"trd":[[1.74,449.7]],"batb":[[0,1.74,919.92]],"ltp":1.74,"tv":99738.7,"id":9342449}],"tv":110278.09}]}
{"op":"mcm","clk":"4230823866","pt":1631536998584,"mc":[{"id":"1.187557995","rc":[{"trd":[[1.74,469.22]],"batb":[[0,1.74,910.16]],"ltp":1.74,"tv":99758.22,"id":9342449}],"tv":110297.61}]}
{"op":"mcm","clk":"4230825323","pt":1631537014698,"mc":[{"id":"1.187557995","rc":[{"trd":[[1.75,0.15]],"batl":[[0,1.75,359.91]],"ltp":1.75,"tv":99758.37,"id":9342449},{"trd":[[2.32,8.12]],"ltp":2.32,"tv":10539.51,"id":9633869}],"tv":110297.88}]}
{"op":"mcm","clk":"4230825658","pt":1631537018896,"mc":[{"id":"1.187557995","rc":[{"trd":[[1.74,469.35]],"batb":[[0,1.74,910.03]],"ltp":1.74,"tv":99758.5,"id":9342449},{"trd":[[2.36,0.09]],"ltp":2.36,"tv":10539.6,"id":9633869}],"tv":110298.1}]}
{"op":"mcm","clk":"4230826728","pt":1631537031034,"mc":[{"id":"1.187557995","rc":[{"batl":[[0,1.75,503.01]],"ltp":1.74,"tv":99758.5,"id":9342449},{"batb":[[0,2.32,107.94],[1,2.3,85.44],[2,2.28,28.16]],"ltp":2.36,"tv":10539.6,"id":9633869}]}]}
{"op":"mcm","clk":"4230826862","pt":1631537032623,"mc":[{"id":"1.187557995","rc":[{"batl":[[1,1.76,294.08]],"ltp":1.74,"tv":99758.5,"id":9342449},{"batb":[[1,2.3,206.02]],"batl":[[0,2.44,31.16]],"ltp":2.36,"tv":10539.6,"id":9633869}]}]}
{"op":"mcm","clk":"4230826899","pt":1631537033038,"mc":[{"id":"1.187557995","rc":[{"batl":[[2,1.77,273.02]],"ltp":1.74,"tv":99758.5,"id":9342449},{"batb":[[2,2.28,157.76]],"ltp":2.36,"tv":10539.6,"id":9633869}]}]}
{"op":"mcm","clk":"4230827809","pt":1631537043643,"mc":[{"id":"1.187557995","rc":[{"trd":[[1.75,222.79]],"batl":[[0,1.75,157.31]],"ltp":1.75,"tv":99981.14,"id":9342449},{"trd":[[2.32,391.92]],"batb":[[0,2.3,206.02],[1,2.28,157.76],[2,2.26,47.61]],"ltp":2.32,"tv":10923.4,"id":9633869}],"tv":110904.54}]}
{"op":"mcm","clk":"4230828053","pt":1631537046572,"mc":[{"id":"1.187557995","rc":[{"batl":[[0,1.75,380.1]],"ltp":1.75,"tv":99981.14,"id":9342449}]}]}
{"op":"mcm","clk":"4230828319","pt":1631537049721,"mc":[{"id":"1.187557995","rc":[{"batl":[[0,1.75,617.15]],"ltp":1.75,"tv":99981.14,"id":9342449}]}]}
{"op":"mcm","clk":"4230828602","pt":1631537053052,"mc":[{"id":"1.187557995","rc":[{"trd":[[1.75,232.79]],"batl":[[0,1.75,612.15]],"ltp":1.75,"tv":99991.14,"id":9342449}],"tv":110914.54}]}
{"op":"mcm","clk":"4230828914","pt":1631537056457,"mc":[{"id":"1.187557995","rc":[{"batb":[[0,1.74,59.09],[1,1.73,69.67]],"ltp":1.75,"tv":99991.14,"id":9342449}]}]}
{"op":"mcm","clk":"4230829005","pt":1631537057354,"mc":[{"id":"1.187557995","rc":[{"batb":[[0,1.71,173.17],[1,1.7,130.94],[2,1.68,72.76]],"batl":[[0,1.75,380.15]],"ltp":1.75,"tv":99991.14,"id":9342449}]}]}
{"op":"mcm","clk":"4230829251","pt":1631537059652,"mc":[{"id":"1.187557995","rc":[{"batb":[[0,1.72,222],[1,1.71,173.17],[2,1.7,130.94]],"ltp":1.75,"tv":99991.14,"id":9342449}]}]}
{"op":"mcm","clk":"4230829312","pt":1631537060238,"mc":[{"id":"1.187557995","rc":[{"batl":[[0,1.74,219.45],[1,1.75,380.15],[2,1.76,294.08]],"ltp":1.75,"tv":99991.14,"id":9342449},{"batl":[[2,2.48,810.98]],"ltp":2.32,"tv":10923.4,"id":9633869}]}]}
{"op":"mcm","clk":"4230829646","pt":1631537063654,"mc":[{"id":"1.187557995","rc":[{"batb":[[1,1.71,72.5],[2,1.7,127.72]],"batl":[[1,1.75,237.05],[2,1.76,136.5]],"ltp":1.75,"tv":99991.14,"id":9342449},{"batb":[[0,2.26,47.61],[1,2.18,99.58],[2,2.14,25.82]],"batl":[[0,2.44,26.33],[1,2.46,4.75],[2,2.48,39.8]],"ltp":2.32,"tv":10923.4,"id":9633869}]}]}
{"op":"mcm","clk":"4230829695","pt":1631537064170,"mc":[{"id":"1.187557995","rc":[{"batb":[[0,1.68,453.56],[1,1.66,110.88],[2,1.21,20]],"batl":[[0,1.79,60],[1,1.82,2.89],[2,1.87,148.5]],"ltp":1.75,"tv":99991.14,"id":9342449},{"batl":[[0,2.48,39.8],[1,990,0.01],[2,2.48,0]],"ltp":2.32,"tv":10923.4,"id":9633869}]}]}
{"op":"mcm","clk":"4230829823","pt":1631537065481,"mc":[{"id":"1.187557995","rc":[{"batb":[[0,1.68,380.8]],"batl":[[0,1.82,2.89],[1,1.87,148.5],[2,2.08,1]],"ltp":1.75,"tv":99991.14,"id":9342449},{"batb":[[0,2.18,99.58],[1,2.14,25.82],[2,1.97,1.05]],"batl":[[0,2.48,27.48]],"ltp":2.32,"tv":10923.4,"id":9633869}]}]}
{"op":"mcm","clk":"4230829928","pt":1631537066478,"mc":[{"id":"1.187557995","rc":[{"batb":[[0,1.68,376.94]],"ltp":1.75,"tv":99991.14,"id":9342449},{"batl":[[0,2.48,22.49]],"ltp":2.32,"tv":10923.4,"id":9633869}]}]}
{"op":"mcm","clk":"4230830039","pt":1631537067671,"mc":[{"id":"1.187557995","rc":[{"batb":[[0,1.69,235.95],[1,1.68,376.94],[2,1.66,110.88]],"ltp":1.75,"tv":99991.14,"id":9342449}]}]}
{"op":"mcm","clk":"4230830155","pt":1631537069090,"mc":[{"id":"1.187557995","rc":[{"batb":[[0,1.74,20],[1,1.69,235.95],[2,1.68,380.8]],"ltp":1.75,"tv":99991.14,"id":9342449},{"batl":[[0,2.48,27.48]],"ltp":2.32,"tv":10923.4,"id":9633869}]}]}
{"op":"mcm","clk":"4230830318","pt":1631537070678,"mc":[{"id":"1.187557995","rc":[{"batb":[[1,1.7,3.52],[2,1.69,235.95]],"ltp":1.75,"tv":99991.14,"id":9342449},{"batl":[[0,2.44,5.58],[1,2.48,27.48],[2,990,0.01]],"ltp":2.32,"tv":10923.4,"id":9633869}]}]}
{"op":"mcm","clk":"4230830369","pt":1631537071152,"mc":[{"id":"1.187557995","rc":[{"batb":[[1,1.69,235.95],[2,1.68,380.8]],"ltp":1.75,"tv":99991.14,"id":9342449},{"batl":[[0,2.48,27.48],[1,990,0.01],[2,990,0]],"ltp":2.32,"tv":10923.4,"id":9633869}]}]}
{"op":"mcm","clk":"4230830970","pt":1631537077579,"mc":[{"id":"1.187557995","rc":[{"batb":[[1,1.7,3.62],[2,1.69,235.95]],"ltp":1.75,"tv":99991.14,"id":9342449},{"batb":[[0,2.2,25.82],[1,2.18,99.58],[2,2.14,25.82]],"batl":[[0,2.44,5.33],[1,2.48,27.48],[2,990,0.01]],"ltp":2.32,"tv":10923.4,"id":9633869}]}]}
{"op":"mcm","clk":"4230831075","pt":1631537078682,"mc":[{"id":"1.187557995","rc":[{"batb":[[0,1.77,3983.04],[1,1.76,666.82],[2,1.75,663.84]],"ltp":1.75,"tv":99991.14,"id":9342449},{"batb":[[0,2.18,99.58],[1,2.14,25.82],[2,1.97,1.05]],"batl":[[0,2.32,5.11],[1,2.38,8.4],[2,2.48,27.48]],"ltp":2.32,"tv":10923.4,"id":9633869}]}]}
{"op":"mcm","clk":"4230831153","pt":1631537079668,"mc":[{"id":"1.187557995","rc":[{"batb":[[0,1.79,86.61],[1,1.77,2920.9],[2,1.76,135.74]],"batl":[[1,1.86,1263.44],[2,1.87,790.92]],"ltp":1.75,"tv":99991.14,"id":9342449},{"batb":[[2,2.06,118.99]],"ltp":2.32,"tv":10923.4,"id":9633869}]}]}
{"op":"mcm","clk":"4230831216","pt":1631537080397,"mc":[{"id":"1.187557995","rc":[{"batl":[[1,1.86,157.93],[2,1.87,298.16]],"ltp":1.75,"tv":99991.14,"id":9342449},{"batb":[[1,2.16,51.72],[2,2.14,25.82]],"batl":[[1,2.38,21.16]],"ltp":2.32,"tv":10923.4,"id":9633869}]}]}
{"op":"mcm","clk":"4230831506","pt":1631537083596,"mc":[{"id":"1.187557995","rc":[{"trd":[[1.82,121.48]],"batb":[[0,1.81,62.48],[1,1.8,67.3],[2,1.79,256.64]],"batl":[[0,1.84,64.74],[1,1.85,74.74],[2,1.86,157.93]],"ltp":1.82,"tv":100112.61,"id":9342449},{"batl":[[1,2.38,8.4]],"ltp":2.32,"tv":10923.4,"id":9633869}],"tv":111036.02}]}
{"op":"mcm","clk":"4230831660","pt":1631537085180,"mc":[{"id":"1.187557995","rc":[{"batl":[[1,2.34,29],[2,2.38,8.4]],"ltp":2.32,"tv":10923.4,"id":9633869}]}]}
{"op":"mcm","clk":"4230831777","pt":1631537086585,"mc":[{"id":"1.187557995","rc":[{"trd":[[1.81,184.09]],"batb":[[0,1.81,164.66],[1,1.8,233.58]],"batl":[[0,1.84,226.73],[1,1.85,236.52]],"ltp":1.81,"tv":100237.58,"id":9342449},{"batl":[[0,2.32,30.97],[1,2.34,131.44],[2,2.36,99.76]],"ltp":2.32,"tv":10923.4,"id":9633869}],"tv":111160.98}]}
{"op":"mcm","clk":"4230831936","pt":1631537088535,"mc":[{"id":"1.187557995","rc":[{"batl":[[0,1.84,284.73]],"ltp":1.81,"tv":100237.58,"id":9342449}]}]}
{"op":"mcm","clk":"4230832014","pt":1631537089709,"mc":[{"id":"1.187557995","rc":[{"trd":[[1.81,513.09]],"batb":[[0,1.8,233.74],[1,1.79,256.64],[2,1.76,144.96]],"batl":[[2,1.87,208.5]],"ltp":1.81,"tv":100566.58,"id":9342449}],"tv":111489.98}]}
{"op":"mcm","clk":"4230832090","pt":1631537090694,"mc":[{"id":"1.187557995","rc":[{"batb":[[0,1.82,76.36],[1,1.77,125.48],[2,1.76,2.98]],"batl":[[0,1.83,136.45],[1,1.87,60],[2,1.89,227.43]],"ltp":1.81,"tv":100566.58,"id":9342449},{"batb":[[0,2.16,51.72],[1,2.08,113.32],[2,2.06,258.7]],"batl":[[0,2.3,31.8],[1,2.32,5.11],[2,2.34,102.44]],"ltp":2.32,"tv":10923.4,"id":9633869}]}]}
{"op":"mcm","clk":"4230832153","pt":1631537091490,"mc":[{"id":"1.187557995","rc":[{"batb":[[1,1.77,122.37]],"batl":[[1,1.89,227.43],[2,1.93,112.77]],"ltp":1.81,"tv":100566.58,"id":9342449},{"batb":[[0,2.08,113.32],[1,2.06,258.7],[2,2.04,128.52]],"batl":[[0,2.3,26.55],[2,2.34,89.49]],"ltp":2.32,"tv":10923.4,"id":9633869}]}]}
{"op":"mcm","clk":"4230832193","pt":1631537092009,"mc":[{"id":"1.187557995","rc":[{"batb":[[0,1.77,122.37],[1,1.76,2.98],[2,1.75,130.3]],"batl":[[0,1.89,227.43],[1,1.93,112.77],[2,1.94,285.09]],"ltp":1.81,"tv":100566.58,"id":9342449}]}]}
{"op":"mcm","clk":"4230832304","pt":1631537093375,"mc":[{"id":"1.187557995","rc":[{"batl":[[1,1.9,156.75],[2,1.93,112.77]],"ltp":1.81,"tv":100566.58,"id":9342449},{"batb":[[0,2.1,28.94],[1,2.08,113.32],[2,2.06,258.7]],"ltp":2.32,"tv":10923.4,"id":9633869}]}]}
{"op":"mcm","clk":"4230832640","pt":1631537097582,"mc":[{"id":"1.187557995","rc":[{"batb":[[0,1.83,136.29],[1,1.77,125.48],[2,1.76,2.98]],"ltp":1.81,"tv":100566.58,"id":9342449},{"batl":[[0,2.3,32.1]],"ltp":2.32,"tv":10923.4,"id":9633869}]}]}
{"op":"mcm","clk":"4230832742","pt":1631537098676,"mc":[{"id":"1.187557995","rc":[{"trd":[[1.89,202.98]],"batb":[[1,1.77,122.37]],"batl":[[0,1.89,24.45],[1,1.93,112.77],[2,1.94,285.09]],"ltp":1.89,"tv":100769.56,"id":9342449},{"trd":[[2.12,180.93]],"batb":[[0,2.08,113.32],[1,2.06,258.7],[2,2.04,128.52]],"batl":[[0,2.3,26.55]],"ltp":2.12,"tv":11104.33,"id":9633869}],"tv":111873.9}]}
{"op":"mcm","clk":"4230832821","pt":1631537099581,"mc":[{"id":"1.187557995","rc":[{"batl":[[0,1.93,112.77],[1,1.94,285.09],[2,1.95,130.97]],"ltp":1.89,"tv":100769.56,"id":9342449}]}]}
{"op":"mcm","clk":"4230832907","pt":1631537100574,"mc":[{"id":"1.187557995","rc":[{"trd":[[1.83,9.76]],"batb":[[0,1.83,131.41],[1,1.78,340.72],[2,1.77,122.37]],"ltp":1.83,"tv":100779.32,"id":9342449}],"tv":111883.66}]}
{"op":"mcm","clk":"4230833000","pt":1631537101482,"mc":[{"id":"1.187557995","rc":[{"batb":[[0,1.84,77.23],[1,1.83,131.41],[2,1.78,340.72]],"batl":[[0,1.88,130.77],[1,1.9,136.05],[2,1.93,112.77]],"ltp":1.83,"tv":100779.32,"id":9342449},{"batb":[[0,2.1,29.84],[1,2.08,113.32],[2,2.06,258.7]],"ltp":2.12,"tv":11104.33,"id":9633869}]}]}
{"op":"mcm","clk":"4230833118","pt":1631537102711,"mc":[{"id":"1.187557995","rc":[{"batb":[[0,1.83,131.41],[1,1.78,340.72],[2,1.77,122.37]],"batl":[[0,1.92,124.03],[1,1.93,112.77],[2,1.94,285.09]],"ltp":1.83,"tv":100779.32,"id":9342449},{"batb":[[0,2.08,113.32],[1,2.06,258.7],[2,2.04,128.52]],"ltp":2.12,"tv":11104.33,"id":9633869}]}]}
{"op":"mcm","clk":"4230833215","pt":1631537103515,"mc":[{"id":"1.187557995","rc":[{"batl":[[0,1.92,247.02]],"ltp":1.83,"tv":100779.32,"id":9342449}]}]}
{"op":"mcm","clk":"4230833317","pt":1631537104614,"mc":[{"id":"1.187557995","rc":[{"batb":[[2,1.77,125.83]],"batl":[[0,1.89,121.51],[1,1.92,587.73],[2,1.93,112.77]],"ltp":1.83,"tv":100779.32,"id":9342449},{"batl":[[0,2.3,32.3]],"ltp":2.12,"tv":11104.33,"id":9633869}]}]}
{"op":"mcm","clk":"4230833437","pt":1631537105607,"mc":[{"id":"1.187557995","rc":[{"batb":[[2,1.77,122.37]],"batl":[[0,1.92,587.73],[1,1.93,112.77],[2,1.94,285.09]],"ltp":1.83,"tv":100779.32,"id":9342449},{"batl":[[0,2.3,26.55]],"ltp":2.12,"tv":11104.33,"id":9633869}]}]}
{"op":"mcm","clk":"4230833466","pt":1631537105920,"mc":[{"id":"1.187557995","rc":[{"batl":[[1,2.34,89.49],[2,2.36,99.76]],"ltp":2.12,"tv":11104.33,"id":9633869}]}]}
{"op":"mcm","clk":"4230833724","pt":1631537108391,"mc":[{"id":"1.187557995","rc":[{"batl":[[0,1.91,340.72],[1,1.92,247.02],[2,1.93,112.77]],"ltp":1.83,"tv":100779.32,"id":9342449}]}]}
{"op":"mcm","clk":"4230833790","pt":1631537109033,"mc":[{"id":"1.187557995","rc":[{"batl":[[1,2.48,27.48],[2,990,0.01]],"ltp":2.12,"tv":11104.33,"id":9633869}]}]}
{"op":"mcm","clk":"4230833886","pt":1631537110023,"mc":[{"id":"1.187557995","rc":[{"batl":[[0,1.92,247.02],[1,1.93,112.77],[2,1.94,285.09]],"ltp":1.83,"tv":100779.32,"id":9342449}]}]}
{"op":"mcm","clk":"4230834055","pt":1631537111610,"mc":[{"id":"1.187557995","rc":[{"batb":[[0,1.85,1270.28],[1,1.84,635.14],[2,1.83,766.55]],"batl":[[0,1.93,112.77],[1,1.94,285.09],[2,1.95,130.97]],"ltp":1.83,"tv":100779.32,"id":9342449},{"batl":[[0,2.14,2196.26],[1,2.28,8.77],[2,2.3,32.1]],"ltp":2.12,"tv":11104.33,"id":9633869}]}]}
{"op":"mcm","clk":"4230834165","pt":1631537112706,"mc":[{"id":"1.187557995","rc":[{"batb":[[0,1.88,73.72],[1,1.85,762.17],[2,1.84,381.08]],"batl":[[0,1.93,10.36],[2,1.95,1336.11]],"ltp":1.83,"tv":100779.32,"id":9342449},{"batb":[[0,2.06,258.7],[1,2.04,128.52],[2,1.97,1.05]],"batl":[[0,2.14,1317.76]],"ltp":2.12,"tv":11104.33,"id":9633869}]}]}
{"op":"mcm","clk":"4230834237","pt":1631537113435,"mc":[{"id":"1.187557995","rc":[{"batl":[[2,1.95,341.61]],"ltp":1.83,"tv":100779.32,"id":9342449},{"batb":[[1,2.04,186.21]],"batl":[[1,2.26,13.36],[2,2.28,8.77]],"ltp":2.12,"tv":11104.33,"id":9633869}]}]}
{"op":"mcm","clk":"4230834354","pt":1631537114623,"mc":[{"id":"1.187557995","rc":[{"batb":[[0,1.92,199.81],[1,1.88,73.72],[2,1.85,1102.89]],"ltp":1.83,"tv":100779.32,"id":9342449}]}]}
{"op":"mcm","clk":"4230834402","pt":1631537115001,"mc":[{"id":"1.187557995","rc":[{"batb":[[0,1.88,73.72],[1,1.85,762.17],[2,1.84,381.08]],"ltp":1.83,"tv":100779.32,"id":9342449}]}]}
{"op":"mcm","clk":"4230834563","pt":1631537116611,"mc":[{"id":"1.187557995","rc":[{"batb":[[0,1.9,61.37],[1,1.89,124.68],[2,1.88,414.44]],"batl":[[0,1.91,127.74],[1,1.92,194.31],[2,1.93,10.36]],"ltp":1.83,"tv":100779.32,"id":9342449},{"batl":[[1,2.28,8.77],[2,2.3,32.1]],"ltp":2.12,"tv":11104.33,"id":9633869}]}]}
{"op":"mcm","clk":"4230834700","pt":1631537118239,"mc":[{"id":"1.187557995","rc":[{"trd":[[1.91,114.35]],"batl":[[0,1.91,70.56]],"ltp":1.91,"tv":100893.68,"id":9342449},{"batb":[[2,2,111.77]],"batl":[[1,2.18,27.75],[2,2.28,8.77]],"ltp":2.12,"tv":11104.33,"id":9633869}],"tv":111998.01}]}
{"op":"mcm","clk":"4230834832","pt":1631537119608,"mc":[{"id":"1.187557995","rc":[{"trd":[[1.89,237.38],[1.9,122.73],[1.91,255.47],[1.92,445.28]],"batb":[[0,1.89,107.48],[1,1.88,414.44],[2,1.86,116.68]],"batl":[[0,1.92,26.13],[1,1.93,10.36],[2,1.94,399.6]],"ltp":1.89,"tv":101528.42,"id":9342449},{"batl":[[2,2.22,23.75]],"ltp":2.12,"tv":11104.33,"id":9633869}],"tv":112632.75}]}
{"op":"mcm","clk":"4230835021","pt":1631537121637,"mc":[{"id":"1.187557995","rc":[{"trd":[[1.91,420.47],[1.92,471.41]],"batl":[[0,1.93,10.36],[1,1.94,399.6],[2,1.95,341.61]],"ltp":1.92,"tv":101719.55,"id":9342449},{"trd":[[2.06,230.32],[2.08,573.77]],"batb":[[0,2.06,234.32]],"ltp":2.06,"tv":11328.71,"id":9633869}],"tv":113048.27}]}
{"op":"mcm","clk":"4230835105","pt":1631537122531,"mc":[{"id":"1.187557995","rc":[{"batb":[[0,1.89,62.33],[1,1.88,340.72],[2,1.87,129.27]],"batl":[[0,1.95,60],[1,2.06,30.25],[2,2.08,1]],"ltp":1.92,"tv":101719.55,"id":9342449},{"batb":[[0,2.04,57.69],[1,1.97,1.05],[2,1.95,211.12]],"batl":[[0,2.16,30.97],[2,2.24,13.47]],"ltp":2.06,"tv":11328.71,"id":9633869}]}]}
{"op":"mcm","clk":"4230835179","pt":1631537123418,"mc":[{"id":"1.187557995","rc":[{"trd":[[1.9,126.73],[1.92,476.27]],"batb":[[0,1.9,58.26]],"batl":[[0,1.92,63.01]],"ltp":1.9,"tv":101728.41,"id":9342449},{"batb":[[0,1.97,1.05],[1,1.95,211.12],[2,1.67,1.38]],"batl":[[2,2.3,32.1]],"ltp":2.06,"tv":11328.71,"id":9633869}],"tv":113057.12}]}
{"op":"mcm","clk":"4230835380","pt":1631537125538,"mc":[{"id":"1.187557995","rc":[{"batb":[[0,1.88,340.72],[1,1.87,129.27],[2,1.86,116.68]],"batl":[[0,2.06,30.25],[1,2.08,1],[2,990,0.01]],"ltp":1.9,"tv":101728.41,"id":9342449},{"batb":[[2,1.94,70.54]],"batl":[[2,2.2,28.18]],"ltp":2.06,"tv":11328.71,"id":9633869}]}]}
{"op":"mcm","clk":"4230835471","pt":1631537126316,"mc":[{"id":"1.187557995","rc":[{"batb":[[1,1.95,140.91]],"ltp":2.06,"tv":11328.71,"id":9633869}]}]}
{"op":"mcm","clk":"4230835582","pt":1631537127520,"mc":[{"id":"1.187557995","rc":[{"batl":[[0,2,340.72],[1,2.02,198.47],[2,2.06,30.25]],"ltp":1.9,"tv":101728.41,"id":9342449}]}]}
{"op":"mcm","clk":"4230835615","pt":1631537127834,"mc":[{"id":"1.187557995","rc":[{"batl":[[2,2.08,1]],"ltp":1.9,"tv":101728.41,"id":9342449}]}]}
{"op":"mcm","clk":"4230835780","pt":1631537129517,"mc":[{"id":"1.187557995","rc":[{"batb":[[0,1.85,115.77],[1,1.81,83.01],[2,1.21,20]],"batl":[[0,2,441.22]],"ltp":1.9,"tv":101728.41,"id":9342449},{"batb":[[0,2,106.96],[1,1.97,1.05],[2,1.95,140.91]],"batl":[[0,2.18,27.75],[1,990,0.01],[2,2.2,0]],"ltp":2.06,"tv":11328.71,"id":9633869}]}]}
{"op":"mcm","clk":"4230835870","pt":1631537130622,"mc":[{"id":"1.187557995","rc":[{"batl":[[0,1.88,1260.64],[1,1.89,625],[2,1.9,625]],"ltp":1.9,"tv":101728.41,"id":9342449}]}]}
{"op":"mcm","clk":"4230835952","pt":1631537131615,"mc":[{"id":"1.187557995","rc":[{"batb":[[2,1.74,95.4]],"batl":[[0,1.88,260.64],[1,1.89,283.5],[2,1.9,125]],"ltp":1.9,"tv":101728.41,"id":9342449},{"batb":[[0,2.14,105.19],[1,2.12,46.29],[2,2,234.82]],"batl":[[1,2.26,1039.82],[2,2.28,519.9]],"ltp":2.06,"tv":11328.71,"id":9633869}]}]}
{"op":"mcm","clk":"4230836033","pt":1631537132510,"mc":[{"id":"1.187557995","rc":[{"batl":[[2,1.9,185]],"ltp":1.9,"tv":101728.41,"id":9342449},{"trd":[[2.14,27.46]],"batb":[[0,2.14,91.47],[2,2.1,54.54]],"batl":[[1,2.26,129.98],[2,2.28,64.99]],"ltp":2.14,"tv":11356.17,"id":9633869}],"tv":113084.58}]}
{"op":"mcm","clk":"4230836137","pt":1631537133552,"mc":[{"id":"1.187557995","rc":[{"batl":[[1,1.89,683.5]],"ltp":1.9,"tv":101728.41,"id":9342449}]}]}
{"op":"mcm","clk":"4230836168","pt":1631537133817,"mc":[{"id":"1.187557995","rc":[{"batl":[[1,1.89,685.5]],"ltp":1.9,"tv":101728.41,"id":9342449}]}]}
{"op":"mcm","clk":"4230836319","pt":1631537135538,"mc":[{"id":"1.187557995","rc":[{"batb":[[0,1.86,139.67],[1,1.85,193.58],[2,1.82,340.72]],"batl":[[0,1.87,67.56],[1,1.88,417.51],[2,1.89,794.33]],"ltp":1.9,"tv":101728.41,"id":9342449}]}]}
{"op":"mcm","clk":"4230836408","pt":1631537136483,"mc":[{"id":"1.187557995","rc":[{"batb":[[1,1.85,268.12]],"batl":[[2,1.89,683.5]],"ltp":1.9,"tv":101728.41,"id":9342449}]}]}
{"op":"mcm","clk":"4230836509","pt":1631537137538,"mc":[{"id":"1.187557995","rc":[{"batb":[[2,1.82,468.36]],"batl":[[2,1.89,283.5]],"ltp":1.9,"tv":101728.41,"id":9342449},{"batl":[[1,2.22,25.75],[2,2.26,129.98]],"ltp":2.14,"tv":11356.17,"id":9633869}]}]}
{"op":"mcm","clk":"4230836581","pt":1631537138219,"mc":[{"id":"1.187557995","rc":[{"trd":[[1.86,53.27]],"batb":[[0,1.86,113.03]],"batl":[[0,1.87,249.56]],"ltp":1.86,"tv":101781.67,"id":9342449}],"tv":113137.85}]}
{"op":"mcm","clk":"4230836657","pt":1631537139055,"mc":[{"id":"1.187557995","rc":[{"trd":[[1.86,55.33]],"batb":[[0,1.86,188.12]],"ltp":1.86,"tv":101783.74,"id":9342449}],"tv":113139.91}]}
{"op":"mcm","clk":"4230836819","pt":1631537140359,"mc":[{"id":"1.187557995","rc":[{"batb":[[0,1.86,112],[1,1.85,74.54],[2,1.82,340.72]],"batl":[[1,1.88,58.59],[2,1.89,2]],"ltp":1.86,"tv":101783.74,"id":9342449},{"batb":[[1,2.1,54.54],[2,2.04,100.39]],"batl":[[0,2.28,28.59],[1,2.32,73.02],[2,2.34,106.94]],"ltp":2.14,"tv":11356.17,"id":9633869}]}]}
{"op":"mcm","clk":"4230836936","pt":1631537141457,"mc":[{"id":"1.187557995","rc":[{"batl":[[0,1.87,67.56]],"ltp":1.86,"tv":101783.74,"id":9342449},{"batb":[[0,2.04,100.39],[1,2.02,113.18],[2,2,355.52]],"ltp":2.14,"tv":11356.17,"id":9633869}]}]}
{"op":"mcm","clk":"4230837000","pt":1631537142136,"mc":[{"id":"1.187557995","rc":[{"batl":[[1,1.89,2],[2,1.97,107.61]],"ltp":1.86,"tv":101783.74,"id":9342449}]}]}
{"op":"mcm","clk":"4230837148","pt":1631537143432,"mc":[{"id":"1.187557995","rc":[{"trd":[[1.87,208.13]],"batb":[[0,1.87,216.09],[1,1.86,112],[2,1.85,74.54]],"batl":[[0,1.97,107.61],[1,1.98,136.98],[2,1.99,266.55]],"ltp":1.87,"tv":101918.85,"id":9342449},{"batl":[[0,2.22,27.25],[1,2.28,28.59],[2,2.32,86.07]],"ltp":2.14,"tv":11356.17,"id":9633869}],"tv":113275.02}]}
{"op":"mcm","clk":"4230837256","pt":1631537144579,"mc":[{"id":"1.187557995","rc":[{"batb":[[1,1.82,448.86],[2,1.79,140.31]],"batl":[[0,1.88,2],[1,1.95,557.92],[2,1.97,107.61]],"ltp":1.87,"tv":101918.85,"id":9342449},{"batl":[[2,2.32,73.02]],"ltp":2.14,"tv":11356.17,"id":9633869}]}]}
{"op":"mcm","clk":"4230837306","pt":1631537145041,"mc":[{"id":"1.187557995","rc":[{"batl":[[0,1.95,217.21],[1,1.97,107.61],[2,1.98,136.98]],"ltp":1.87,"tv":101918.85,"id":9342449}]}]}
{"op":"mcm","clk":"4230837593","pt":1631537147579,"mc":[{"id":"1.187557995","rc":[{"batb":[[0,1.82,448.86],[1,1.79,140.31],[2,1.76,122.72]],"batl":[[0,1.88,15],[1,1.95,217.21],[2,1.97,107.61]],"ltp":1.87,"tv":101918.85,"id":9342449}]}]}
{"op":"mcm","clk":"4230837674","pt":1631537148460,"mc":[{"id":"1.187557995","rc":[{"batb":[[0,1.82,340.72]],"batl":[[0,1.87,2],[1,1.88,15],[2,1.94,340.72]],"ltp":1.87,"tv":101918.85,"id":9342449},{"batl":[[0,2.28,28.59],[1,2.32,73.02],[2,2.34,106.94]],"ltp":2.14,"tv":11356.17,"id":9633869}]}]}
{"op":"mcm","clk":"4230837899","pt":1631537150580,"mc":[{"id":"1.187557995","rc":[{"batl":[[0,2.24,4],[1,2.26,447.23],[2,2.28,28.59]],"ltp":2.14,"tv":11356.17,"id":9633869}]}]}
{"op":"mcm","clk":"4230837948","pt":1631537151052,"mc":[{"id":"1.187557995","rc":[{"batb":[[0,1.86,257.79],[1,1.82,453.86],[2,1.79,140.31]],"batl":[[0,1.94,340.72],[1,1.95,217.21],[2,1.97,107.61]],"ltp":1.87,"tv":101918.85,"id":9342449},{"batl":[[0,2.22,28.25],[1,2.28,28.59],[2,2.32,73.02]],"ltp":2.14,"tv":11356.17,"id":9633869}]}]}
{"op":"mcm","clk":"4230838169","pt":1631537153377,"mc":[{"id":"1.187557995","rc":[{"batb":[[0,1.87,340.72],[1,1.86,257.79],[2,1.82,453.86]],"batl":[[1,1.97,107.61],[2,1.98,136.98]],"ltp":1.87,"tv":101918.85,"id":9342449}]}]}
{"op":"mcm","clk":"4230838268","pt":1631537154585,"mc":[{"id":"1.187557995","rc":[{"trd":[[1.87,212.78]],"batb":[[0,1.87,338.39]],"ltp":1.87,"tv":101923.5,"id":9342449}],"tv":113279.67}]}
{"op":"mcm","clk":"4230838367","pt":1631537155583,"mc":[{"id":"1.187557995","rc":[{"batb":[[1,1.86,21.06]],"batl":[[0,1.93,94.55],[1,1.94,340.72],[2,1.97,107.61]],"ltp":1.87,"tv":101923.5,"id":9342449}]}]}
{"op":"mcm","clk":"4230838697","pt":1631537159382,"mc":[{"id":"1.187557995","rc":[{"batb":[[0,1.86,21.06],[1,1.82,340.72],[2,1.79,140.31]],"ltp":1.87,"tv":101923.5,"id":9342449},{"batl":[[0,2.28,28.59],[1,990,0.01],[2,2.32,0]],"ltp":2.14,"tv":11356.17,"id":9633869}]}]}
{"op":"mcm","clk":"4230838766","pt":1631537160169,"mc":[{"id":"1.187557995","rc":[{"batl":[[0,1.94,340.72],[1,1.97,107.61],[2,1.98,136.98]],"ltp":1.87,"tv":101923.5,"id":9342449}]}]}
{"op":"mcm","clk":"4230838877","pt":1631537161474,"mc":[{"id":"1.187557995","rc":[{"batl":[[0,1.97,107.61],[1,1.98,136.98],[2,1.99,266.55]],"ltp":1.87,"tv":101923.5,"id":9342449}]}]}
{"op":"mcm","clk":"4230838962","pt":1631537162453,"mc":[{"id":"1.187557995","rc":[{"trd":[[1.87,214.78]],"batb":[[0,1.91,246.08],[1,1.9,2596.72],[2,1.89,123.04]],"batl":[[0,1.99,129.05],[1,2.08,1],[2,990,0.01]],"ltp":1.87,"tv":101925.5,"id":9342449},{"trd":[[2.14,29.21]],"batb":[[0,2,248.56],[1,1.97,1.05],[2,1.95,140.91]],"batl":[[0,2.24,8.93],[1,2.28,28.59],[2,990,0.01]],"ltp":2.14,"tv":11357.92,"id":9633869}],"tv":113283.42}]}
{"op":"mcm","clk":"4230839044","pt":1631537163398,"mc":[{"id":"1.187557995","rc":[{"batb":[[0,1.92,68.45],[1,1.91,246.08],[2,1.9,2596.72]],"batl":[[0,1.96,10.2],[1,1.99,189.05],[2,2.02,145.42]],"ltp":1.87,"tv":101925.5,"id":9342449},{"batb":[[0,2,308.56]],"batl":[[0,2.2,13.69],[1,2.24,8.93],[2,2.28,28.59]],"ltp":2.14,"tv":11357.92,"id":9633869}]}]}
{"op":"mcm","clk":"4230839303","pt":1631537166511,"mc":[{"id":"1.187557995","rc":[{"batb":[[0,1.94,116.49],[1,1.93,149.51],[2,1.92,409.17]],"batl":[[0,1.95,63.3],[1,1.96,102.12],[2,1.99,189.05]],"ltp":1.87,"tv":101925.5,"id":9342449}]}]}
{"op":"mcm","clk":"4230839379","pt":1631537167293,"mc":[{"id":"1.187557995","rc":[{"batb":[[2,1.92,479.7]],"batl":[[1,1.96,176.06]],"ltp":1.87,"tv":101925.5,"id":9342449}]}]}
{"op":"mcm","clk":"4230839602","pt":1631537169681,"mc":[{"id":"1.187557995","rc":[{"trd":[[1.94,380.17]],"batb":[[0,1.94,96.49]],"ltp":1.94,"tv":101965.5,"id":9342449},{"batl":[[0,2.14,122.61],[1,2.16,102.86],[2,2.18,158.32]],"ltp":2.14,"tv":11357.92,"id":9633869}],"tv":113323.42}]}
{"op":"mcm","clk":"4230839678","pt":1631537170510,"mc":[{"id":"1.187557995","rc":[{"batl":[[0,2.12,28.46],[1,2.14,122.61],[2,2.16,130.58]],"ltp":2.14,"tv":11357.92,"id":9633869}]}]}
{"op":"mcm","clk":"4230839788","pt":1631537171715,"mc":[{"id":"1.187557995","rc":[{"batb":[[1,1.97,208.89]],"ltp":2.14,"tv":11357.92,"id":9633869}]}]}
{"op":"mcm","clk":"4230839945","pt":1631537173514,"mc":[{"id":"1.187557995","rc":[{"batb":[[0,1.94,153.45],[1,1.93,71.26],[2,1.92,409.17]],"batl":[[1,1.96,102.12]],"ltp":1.94,"tv":101965.5,"id":9342449}]}]}
{"op":"mcm","clk":"4230840022","pt":1631537174303,"mc":[{"id":"1.187557995","rc":[{"batl":[[0,1.95,225.3]],"ltp":1.94,"tv":101965.5,"id":9342449}]}]}
{"op":"mcm","clk":"4230840121","pt":1631537175403,"mc":[{"id":"1.187557995","rc":[{"batb":[[0,1.93,71.26],[1,1.92,409.17],[2,1.91,246.08]],"batl":[[0,1.95,162]],"ltp":1.94,"tv":101965.5,"id":9342449}]}]}
{"op":"mcm","clk":"4230840249","pt":1631537176699,"mc":[{"id":"1.187557995","rc":[{"batb":[[0,1.94,53.6],[1,1.93,71.26],[2,1.92,409.17]],"ltp":1.94,"tv":101965.5,"id":9342449}]}]}
{"op":"mcm","clk":"4230840306","pt":1631537177419,"mc":[{"id":"1.187557995","rc":[{"trd":[[1.95,7437.01]],"batb":[[0,1.92,409.17],[1,1.9,101.26],[2,1.89,105.41]],"batl":[[0,1.95,141.39],[1,1.99,60],[2,2.08,1]],"ltp":1.95,"tv":102006.78,"id":9342449},{"batb":[[0,2,187.86],[2,1.92,121.91]],"batl":[[1,2.14,92.86]],"ltp":2.14,"tv":11357.92,"id":9633869}],"tv":113364.7}]}
{"op":"mcm","clk":"4230840415","pt":1631537178621,"mc":[{"id":"1.187557995","rc":[{"batb":[[0,1.92,340.72]],"batl":[[0,1.95,81.71],[1,2.08,1],[2,2.1,140.63]],"ltp":1.95,"tv":102006.78,"id":9342449},{"batb":[[0,1.97,208.89],[1,1.92,121.91],[2,1.91,270.59]],"ltp":2.14,"tv":11357.92,"id":9633869}]}]}
{"op":"mcm","clk":"4230840492","pt":1631537179499,"mc":[{"id":"1.187557995","rc":[{"batl":[[0,2.08,1],[1,2.1,140.63],[2,2.12,96.48]],"ltp":1.95,"tv":102006.78,"id":9342449}]}]}
{"op":"mcm","clk":"4230840612","pt":1631537180904,"mc":[{"id":"1.187557995","rc":[{"batb":[[0,1.97,1.05]],"ltp":2.14,"tv":11357.92,"id":9633869}]}]}
{"op":"mcm","clk":"4230840844","pt":1631537183599,"mc":[{"id":"1.187557995","rc":[{"batl":[[0,2.02,340.9],[1,2.08,1],[2,2.1,140.63]],"ltp":1.95,"tv":102006.78,"id":9342449},{"batb":[[1,1.94,113.29],[2,1.92,121.91]],"ltp":2.14,"tv":11357.92,"id":9633869}]}]}
{"op":"mcm","clk":"4230841405","pt":1631537190702,"mc":[{"id":"1.187557995","rc":[{"batb":[[0,1.9,101.26],[1,1.89,105.41],[2,1.88,102.8]],"batl":[[2,2.42,290.48]],"ltp":1.95,"tv":102006.78,"id":9342449},{"batb":[[2,1.89,76.32]],"ltp":2.14,"tv":11357.92,"id":9633869}]}]}
{"op":"mcm","clk":"4230841495","pt":1631537191695,"mc":[{"id":"1.187557995","rc":[{"trd":[[1.93,561.54]],"batb":[[0,1.88,102.8],[1,1.87,245.91],[2,1.86,249.72]],"batl":[[0,2.02,340.72]],"ltp":1.93,"tv":102007.15,"id":9342449},{"batl":[[0,2.14,92.86],[1,2.16,130.58],[2,2.18,126.57]],"ltp":2.14,"tv":11357.92,"id":9633869}],"tv":113365.07}]}
{"op":"mcm","clk":"4230841638","pt":1631537193216,"mc":[{"id":"1.187557995","rc":[{"batb":[[0,1.87,119.27],[1,1.86,133.54],[2,1.84,78.58]],"batl":[[0,1.91,10.47],[1,1.96,147.37],[2,1.97,1216.02]],"ltp":1.93,"tv":102007.15,"id":9342449},{"batb":[[0,2.06,684.47],[1,2.04,389.6],[2,2.02,342.23]],"batl":[[0,2.16,130.58],[1,2.18,126.57],[2,2.28,28.59]],"ltp":2.14,"tv":11357.92,"id":9633869}]}]}
{"op":"mcm","clk":"4230841782","pt":1631537194617,"mc":[{"id":"1.187557995","rc":[{"batb":[[2,1.85,158.79]],"ltp":1.93,"tv":102007.15,"id":9342449},{"batb":[[0,2.1,111.38],[1,2.06,684.47],[2,2.04,389.6]],"ltp":2.14,"tv":11357.92,"id":9633869}]}]}
{"op":"mcm","clk":"4230841964","pt":1631537196631,"mc":[{"id":"1.187557995","rc":[{"batl":[[1,1.92,404],[2,1.96,147.37]],"ltp":1.93,"tv":102007.15,"id":9342449}]}]}
{"op":"mcm","clk":"4230842041","pt":1631537197625,"mc":[{"id":"1.187557995","rc":[{"batb":[[0,1.89,99.05],[1,1.88,123.65],[2,1.87,182.57]],"batl":[[0,1.9,155.07],[1,1.91,71.47],[2,1.92,404]],"ltp":1.93,"tv":102007.15,"id":9342449},{"trd":[[2.1,306.6]],"batb":[[0,2.1,68.51]],"ltp":2.1,"tv":11443.77,"id":9633869}],"tv":113450.93}]}
{"op":"mcm","clk":"4230842229","pt":1631537199641,"mc":[{"id":"1.187557995","rc":[{"batl":[[2,1.92,402]],"ltp":1.93,"tv":102007.15,"id":9342449},{"batl":[[2,2.22,26.25]],"ltp":2.1,"tv":11443.77,"id":9633869}]}]}
{"op":"mcm","clk":"4230842289","pt":1631537200212,"mc":[{"id":"1.187557995","rc":[{"batl":[[1,1.91,152.29]],"ltp":1.93,"tv":102007.15,"id":9342449}]}]}
{"op":"mcm","clk":"4230842401","pt":1631537201556,"mc":[{"id":"1.187557995","rc":[{"batl":[[2,1.92,62]],"ltp":1.93,"tv":102007.15,"id":9342449},{"batb":[[1,2.08,55.55],[2,2.06,684.47]],"ltp":2.1,"tv":11443.77,"id":9633869}]}]}
{"op":"mcm","clk":"4230842450","pt":1631537202230,"mc":[{"id":"1.187557995","rc":[{"batl":[[1,1.91,150.01]],"ltp":1.93,"tv":102007.15,"id":9342449}]}]}
{"op":"mcm","clk":"4230842559","pt":1631537203355,"mc":[{"id":"1.187557995","rc":[{"trd":[[1.9,245.75]],"batb":[[0,1.89,150.54]],"batl":[[0,1.9,226.55]],"ltp":1.9,"tv":102126.17,"id":9342449}],"tv":113569.95}]}
{"op":"mcm","clk":"4230842635","pt":1631537204254,"mc":[{"id":"1.187557995","rc":[{"batb":[[2,1.87,119.27]],"batl":[[0,1.9,290.94],[1,1.91,91.29],[2,1.92,60]],"ltp":1.9,"tv":102126.17,"id":9342449}]}]}
{"op":"mcm","clk":"4230842853","pt":1631537206547,"mc":[{"id":"1.187557995","rc":[{"trd":[[1.9,249.75]],"batb":[[0,1.88,60.49],[1,1.87,119.27],[2,1.86,133.54]],"batl":[[0,1.9,217.08]],"ltp":1.9,"tv":102130.17,"id":9342449}],"tv":113573.95}]}
{"op":"mcm","clk":"4230842952","pt":1631537207536,"mc":[{"id":"1.187557995","rc":[{"batb":[[0,1.81,340.72],[1,1.79,140.31],[2,1.78,235.99]],"batl":[[0,1.9,133.29],[1,1.92,60],[2,2.02,340.72]],"ltp":1.9,"tv":102130.17,"id":9342449},{"batb":[[0,2.08,55.55],[1,1.97,1.05],[2,1.96,123.35]],"batl":[[0,2.28,111.46],[1,2.3,148.09],[2,2.32,99.15]],"ltp":2.1,"tv":11443.77,"id":9633869}]}]}
{"op":"mcm","clk":"4230843043","pt":1631537208467,"mc":[{"id":"1.187557995","rc":[{"trd":[[1.9,267.79]],"batl":[[0,1.9,2.29],[1,2.02,340.72],[2,2.06,115.17]],"ltp":1.9,"tv":102148.21,"id":9342449},{"batb":[[0,1.97,1.05],[1,1.96,123.35],[2,1.95,100.41]],"ltp":2.1,"tv":11443.77,"id":9633869}],"tv":113591.99}]}
{"op":"mcm","clk":"4230843251","pt":1631537210666,"mc":[{"id":"1.187557995","rc":[{"batb":[[0,1.82,114.14],[1,1.81,340.72],[2,1.79,140.31]],"ltp":1.9,"tv":102148.21,"id":9342449},{"batl":[[0,2.22,29.25],[1,2.28,111.46],[2,2.3,148.09]],"ltp":2.1,"tv":11443.77,"id":9633869}]}]}
{"op":"mcm","clk":"4230843322","pt":1631537211552,"mc":[{"id":"1.187557995","rc":[{"batb":[[0,1.82,151.62]],"ltp":1.9,"tv":102148.21,"id":9342449},{"batl":[[0,2.28,111.46],[1,2.3,148.09],[2,2.32,99.15]],"ltp":2.1,"tv":11443.77,"id":9633869}]}]}
{"op":"mcm","clk":"4230843341","pt":1631537211755,"mc":[{"id":"1.187557995","rc":[{"trd":[[1.9,270.08]],"batl":[[0,2.02,340.72],[1,2.06,115.17],[2,2.08,110.83]],"ltp":1.9,"tv":102150.5,"id":9342449},{"trd":[[2.1,308.67]],"batl":[[0,2.1,17.93],[1,2.28,111.46],[2,2.3,148.09]],"ltp":2.1,"tv":11445.84,"id":9633869}],"tv":113596.35}]}
{"op":"mcm","clk":"4230843493","pt":1631537213669,"mc":[{"id":"1.187557995","rc":[{"batl":[[0,2.1,22.93]],"ltp":2.1,"tv":11445.84,"id":9633869}]}]}
{"op":"mcm","clk":"4230843535","pt":1631537214046,"mc":[{"id":"1.187557995","rc":[{"batb":[[0,1.9,294.34],[1,1.82,277.26],[2,1.81,340.72]],"ltp":1.9,"tv":102150.5,"id":9342449},{"batb":[[0,1.99,18.08],[1,1.97,1.05],[2,1.96,123.35]],"batl":[[1,2.22,29.75],[2,2.28,111.46]],"ltp":2.1,"tv":11445.84,"id":9633869}]}]}
{"op":"mcm","clk":"4230843655","pt":1631537215445,"mc":[{"id":"1.187557995","rc":[{"batb":[[0,1.99,122.85]],"ltp":2.1,"tv":11445.84,"id":9633869}]}]}
{"op":"mcm","clk":"4230843728","pt":1631537216068,"mc":[{"id":"1.187557995","rc":[{"batb":[[1,1.85,340.72],[2,1.82,277.26]],"ltp":1.9,"tv":102150.5,"id":9342449}]}]}
{"op":"mcm","clk":"4230843914","pt":1631537218089,"mc":[{"id":"1.187557995","rc":[{"batb":[[0,1.91,37.15],[1,1.9,170.98],[2,1.85,340.72]],"batl":[[0,2,64.74],[1,2.02,340.72],[2,2.06,115.17]],"ltp":1.9,"tv":102150.5,"id":9342449}]}]}
{"op":"mcm","clk":"4230844015","pt":1631537218972,"mc":[{"id":"1.187557995","rc":[{"batb":[[0,1.9,170.98],[1,1.85,340.72],[2,1.82,277.26]],"batl":[[0,2.02,340.72],[1,2.06,115.17],[2,2.08,110.83]],"ltp":1.9,"tv":102150.5,"id":9342449}]}]}
{"op":"mcm","clk":"4230844531","pt":1631537224462,"mc":[{"id":"1.187557995","rc":[{"batb":[[2,1.82,125.64]],"ltp":1.9,"tv":102150.5,"id":9342449}]}]}
{"op":"mcm","clk":"4230844876","pt":1631537227900,"mc":[{"id":"1.187557995","rc":[{"batl":[[0,2.1,17.93]],"ltp":2.1,"tv":11445.84,"id":9633869}]}]}
{"op":"mcm","clk":"4230845030","pt":1631537229469,"mc":[{"id":"1.187557995","rc":[{"batb":[[0,1.99,104.77]],"ltp":2.1,"tv":11445.84,"id":9633869}]}]}
{"op":"mcm","clk":"4230845169","pt":1631537230976,"mc":[{"id":"1.187557995","rc":[{"trd":[[1.99,47.81]],"batb":[[0,1.99,99.77]],"ltp":1.99,"tv":11455.84,"id":9633869}],"tv":113606.35}]}
{"op":"mcm","clk":"4230845347","pt":1631537232691,"mc":[{"id":"1.187557995","rc":[{"batb":[[0,1.82,125.64],[1,1.79,140.31],[2,1.78,235.99]],"batl":[[1,2.08,1],[2,2.3,314.02]],"ltp":1.9,"tv":102150.5,"id":9342449},{"batb":[[2,1.93,71.71]],"ltp":1.99,"tv":11455.84,"id":9633869}]}]}
{"op":"mcm","clk":"4230845427","pt":1631537233376,"mc":[{"id":"1.187557995","rc":[{"trd":[[1.9,289.9]],"batb":[[0,1.78,235.99],[1,1.77,138.59],[2,1.76,137.87]],"ltp":1.9,"tv":102170.32,"id":9342449},{"trd":[[2.1,326.6]],"batl":[[0,2.28,82.87],[1,2.3,148.09],[2,2.32,99.15]],"ltp":2.1,"tv":11473.77,"id":9633869}],"tv":113644.1}]}
{"op":"mcm","clk":"4230845582","pt":1631537234682,"mc":[{"id":"1.187557995","rc":[{"batl":[[0,1.83,10.93],[1,1.84,2148.86],[2,1.9,152.85]],"ltp":1.9,"tv":102170.32,"id":9342449},{"batb":[[0,2.18,1077.98],[1,2.16,539],[2,2.14,539]],"ltp":2.1,"tv":11473.77,"id":9633869}]}]}
{"op":"mcm","clk":"4230845695","pt":1631537235680,"mc":[{"id":"1.187557995","rc":[{"batb":[[0,1.78,122.66],[2,1.76,838.87]],"ltp":1.9,"tv":102170.32,"id":9342449},{"batb":[[0,2.24,92.38],[1,2.18,215.6],[2,2.16,107.8]],"batl":[[0,2.3,148.09],[1,2.32,99.15],[2,2.44,8.2]],"ltp":2.1,"tv":11473.77,"id":9633869}]}]}
{"op":"mcm","clk":"4230845823","pt":1631537236715,"mc":[{"id":"1.187557995","rc":[{"batb":[[2,1.76,304.77]],"batl":[[2,1.85,60]],"ltp":1.9,"tv":102170.32,"id":9342449},{"batb":[[1,2.18,266.44]],"ltp":2.1,"tv":11473.77,"id":9633869}]}]}
{"op":"mcm","clk":"4230846048","pt":1631537238603,"mc":[{"id":"1.187557995","rc":[{"trd":[[1.81,518.39]],"ltp":1.81,"tv":102175.62,"id":9342449},{"trd":[[2.24,4.28]],"batb":[[0,2.24,88.1]],"ltp":2.24,"tv":11478.06,"id":9633869}],"tv":113653.68}]}
{"op":"mcm","clk":"4230846176","pt":1631537239705,"mc":[{"id":"1.187557995","rc":[{"batb":[[0,1.8,166.83],[1,1.79,391.38],[2,1.78,122.66]],"batl":[[0,1.81,154.47],[1,1.82,147.08],[2,1.83,10.93]],"ltp":1.81,"tv":102175.62,"id":9342449},{"batb":[[1,2.18,215.6]],"ltp":2.24,"tv":11478.06,"id":9633869}]}]}
{"op":"mcm","clk":"4230846234","pt":1631537240281,"mc":[{"id":"1.187557995","rc":[{"batb":[[1,1.79,115.76]],"ltp":1.81,"tv":102175.62,"id":9342449}]}]}
{"op":"mcm","clk":"4230846486","pt":1631537242471,"mc":[{"id":"1.187557995","rc":[{"batl":[[2,1.83,86.6]],"ltp":1.81,"tv":102175.62,"id":9342449},{"batl":[[1,2.32,124.26],[2,2.34,22.25]],"ltp":2.24,"tv":11478.06,"id":9633869}]}]}
{"op":"mcm","clk":"4230846581","pt":1631537243507,"mc":[{"id":"1.187557995","rc":[{"batl":[[2,1.83,146.6]],"ltp":1.81,"tv":102175.62,"id":9342449},{"batb":[[1,2.2,50],[2,2.18,215.6]],"ltp":2.24,"tv":11478.06,"id":9633869}]}]}
{"op":"mcm","clk":"4230846804","pt":1631537245518,"mc":[{"id":"1.187557995","rc":[{"batb":[[0,1.8,734.12]],"ltp":1.81,"tv":102175.62,"id":9342449}]}]}
{"op":"mcm","clk":"4230846876","pt":1631537246205,"mc":[{"id":"1.187557995","rc":[{"batl":[[1,1.82,78.95]],"ltp":1.81,"tv":102175.62,"id":9342449}]}]}
{"op":"mcm","clk":"4230846939","pt":1631537246917,"mc":[{"id":"1.187557995","rc":[{"batb":[[1,1.79,50.66]],"ltp":1.81,"tv":102175.62,"id":9342449}]}]}
{"op":"mcm","clk":"4230847075","pt":1631537248219,"mc":[{"id":"1.187557995","rc":[{"batb":[[0,1.8,621.9]],"batl":[[0,1.81,79]],"ltp":1.81,"tv":102175.62,"id":9342449}]}]}
{"op":"mcm","clk":"4230847314","pt":1631537250710,"mc":[{"id":"1.187557995","rc":[{"batb":[[2,1.76,129.73]],"batl":[[2,1.83,135.67]],"ltp":1.81,"tv":102175.62,"id":9342449},{"batb":[[2,2.1,78.05]],"batl":[[0,2.32,25.11],[1,2.34,22.25],[2,2.38,24.75]],"ltp":2.24,"tv":11478.06,"id":9633869}]}]}
{"op":"mcm","clk":"4230847379","pt":1631537251326,"mc":[{"id":"1.187557995","rc":[{"batb":[[0,1.8,567.29],[1,1.76,129.73],[2,1.75,129.03]],"batl":[[0,1.83,60],[1,1.9,95.36],[2,1.91,120.56]],"ltp":1.81,"tv":102175.62,"id":9342449},{"batb":[[0,2.2,50],[1,2.1,78.05],[2,2.08,231.96]],"ltp":2.24,"tv":11478.06,"id":9633869}]}]}
{"op":"mcm","clk":"4230847517","pt":1631537252585,"mc":[{"id":"1.187557995","rc":[{"batl":[[0,1.9,95.36],[1,1.91,120.56],[2,1.92,120.91]],"ltp":1.81,"tv":102175.62,"id":9342449},{"batb":[[0,2.1,78.05],[1,2.08,231.96],[2,2.06,109.7]],"batl":[[0,2.24,2.32],[1,2.32,25.11],[2,2.34,22.25]],"ltp":2.24,"tv":11478.06,"id":9633869}]}]}
{"op":"mcm","clk":"4230847686","pt":1631537254100,"mc":[{"id":"1.187557995","rc":[{"batb":[[0,1.81,283.65],[1,1.8,567.29],[2,1.76,129.73]],"ltp":1.81,"tv":102175.62,"id":9342449}]}]}
{"op":"mcm","clk":"4230847838","pt":1631537255504,"mc":[{"id":"1.187557995","rc":[{"batb":[[0,1.77,340.72],[1,1.76,129.73],[2,1.75,129.03]],"batl":[[0,1.88,104.77],[1,1.9,95.36],[2,1.91,120.56]],"ltp":1.81,"tv":102175.62,"id":9342449}]}]}
{"op":"mcm","clk":"4230847963","pt":1631537256600,"mc":[{"id":"1.187557995","rc":[{"batl":[[1,1.89,340.72],[2,1.9,95.36]],"ltp":1.81,"tv":102175.62,"id":9342449}]}]}
{"op":"mcm","clk":"4230848188","pt":1631537258626,"mc":[{"id":"1.187557995","rc":[{"trd":[[1.83,48.77]],"batb":[[0,1.83,280.87],[1,1.77,340.72],[2,1.76,129.73]],"ltp":1.83,"tv":102214.62,"id":9342449},{"batb":[[0,2.2,21.07],[1,2.1,78.05],[2,2.08,231.96]],"batl":[[1,2.26,20.75],[2,2.32,25.11]],"ltp":2.24,"tv":11478.06,"id":9633869}],"tv":113692.69}]}
{"op":"mcm","clk":"4230848208","pt":1631537258832,"mc":[{"id":"1.187557995","rc":[{"batb":[[0,2.1,78.05],[1,2.08,231.96],[2,2.06,109.7]],"batl":[[1,2.32,25.11],[2,2.34,22.25]],"ltp":2.24,"tv":11478.06,"id":9633869}]}]}
{"op":"mcm","clk":"4230848448","pt":1631537260731,"mc":[{"id":"1.187557995","rc":[{"batl":[[0,1.87,340.72],[1,1.88,104.77],[2,1.89,340.72]],"ltp":1.83,"tv":102214.62,"id":9342449}]}]}
{"op":"mcm","clk":"4230848635","pt":1631537262516,"mc":[{"id":"1.187557995","rc":[{"batb":[[0,1.83,21.81]],"ltp":1.83,"tv":102214.62,"id":9342449}]}]}
{"op":"mcm","clk":"4230848740","pt":1631537263618,"mc":[{"id":"1.187557995","rc":[{"trd":[[1.83,92.37]],"batb":[[0,1.77,340.72],[1,1.76,129.73],[2,1.75,129.03]],"ltp":1.83,"tv":102258.23,"id":9342449}],"tv":113736.29}]}
{"op":"mcm","clk":"4230848859","pt":1631537264707,"mc":[{"id":"1.187557995","rc":[{"batl":[[0,1.86,151.62],[1,1.87,340.72],[2,1.88,104.77]],"ltp":1.83,"tv":102258.23,"id":9342449}]}]}
{"op":"mcm","clk":"4230856888","pt":1631537269050,"mc":[{"id":"1.187557995","rc":[{"batl":[[1,1.88,104.77],[2,1.9,95.36]],"ltp":1.83,"tv":102258.23,"id":9342449}]}]}
{"op":"mcm","clk":"4230857008","pt":1631537270353,"mc":[{"id":"1.187557995","rc":[{"batl":[[0,1.85,340.72]],"ltp":1.83,"tv":102258.23,"id":9342449}]}]}
{"op":"mcm","clk":"4230857090","pt":1631537271246,"mc":[{"id":"1.187557995","rc":[{"batl":[[2,2.08,1]],"ltp":1.83,"tv":102258.23,"id":9342449},{"batb":[[0,2.08,114.73],[1,1.97,1.05],[2,1.95,132.51]],"ltp":2.24,"tv":11478.06,"id":9633869}]}]}
{"op":"mcm","clk":"4230857187","pt":1631537272339,"mc":[{"id":"1.187557995","rc":[{"trd":[[1.85,0.11]],"batb":[[0,1.73,128.13],[1,1.7,106.7],[2,1.69,124.95]],"batl":[[0,1.85,340.6]],"ltp":1.85,"tv":102258.34,"id":9342449},{"trd":[[2.16,0.09]],"batl":[[1,2.38,24.75],[2,2.42,89.91]],"ltp":2.16,"tv":11478.15,"id":9633869}],"tv":113736.5}]}
{"op":"mcm","clk":"4230857297","pt":1631537273534,"mc":[{"id":"1.187557995","rc":[{"trd":[[1.8,24.58]],"batl":[[0,1.77,3430.97],[1,1.85,356.24],[2,1.88,104.77]],"ltp":1.8,"tv":102261.23,"id":9342449},{"trd":[[2.24,6.61]],"batl":[[0,2.38,24.75],[1,2.42,89.91],[2,2.44,97.27]],"ltp":2.24,"tv":11480.47,"id":9633869}],"tv":113741.71}]}
{"op":"mcm","clk":"4230857407","pt":1631537274634,"mc":[{"id":"1.187557995","rc":[{"batl":[[0,1.77,11.3],[1,1.78,264.04],[2,1.79,132.02]],"ltp":1.8,"tv":102261.23,"id":9342449},{"batb":[[0,2.32,2025.86],[1,2.18,43.36],[2,2.08,114.73]],"ltp":2.24,"tv":11480.47,"id":9633869}]}]}
{"op":"mcm","clk":"4230857493","pt":1631537275456,"mc":[{"id":"1.187557995","rc":[{"batl":[[0,1.77,71.3]],"ltp":1.8,"tv":102261.23,"id":9342449},{"batb":[[0,2.36,80],[1,2.32,2025.86],[2,2.22,93.81]],"batl":[[2,2.44,217.66]],"ltp":2.24,"tv":11480.47,"id":9633869}]}]}
{"op":"mcm","clk":"4230857581","pt":1631537276347,"mc":[{"id":"1.187557995","rc":[{"batl":[[2,1.79,472.74]],"ltp":1.8,"tv":102261.23,"id":9342449}]}]}
{"op":"mcm","clk":"4230857802","pt":1631537278634,"mc":[{"id":"1.187557995","rc":[{"trd":[[1.74,577.81]],"batb":[[0,1.75,86.7],[1,1.73,128.13],[2,1.7,106.7]],"batl":[[0,1.76,64.74],[1,1.77,141.33],[2,1.78,264.04]],"ltp":1.74,"tv":102369.69,"id":9342449},{"trd":[[2.36,80.09]],"batb":[[0,2.32,2025.86],[1,2.28,46.87]],"ltp":2.36,"tv":11560.47,"id":9633869}],"tv":113930.17}]}
{"op":"mcm","clk":"4230857894","pt":1631537279461,"mc":[{"id":"1.187557995","rc":[{"batb":[[1,1.74,72.79],[2,1.73,198.16]],"batl":[[0,1.76,161.09]],"ltp":1.74,"tv":102369.69,"id":9342449},{"batb":[[1,2.22,93.81],[2,2.18,43.36]],"ltp":2.36,"tv":11560.47,"id":9633869}]}]}
{"op":"mcm","clk":"4230858091","pt":1631537281349,"mc":[{"id":"1.187557995","rc":[{"batb":[[1,2.22,175.58],[2,2.2,88.18]],"batl":[[2,2.44,243.49]],"ltp":2.36,"tv":11560.47,"id":9633869}]}]}
{"op":"mcm","clk":"4230858216","pt":1631537282546,"mc":[{"id":"1.187557995","rc":[{"batb":[[1,1.74,72.91]],"batl":[[0,1.76,290.09]],"ltp":1.74,"tv":102369.69,"id":9342449},{"batb":[[0,2.32,2071.31]],"batl":[[0,2.38,24.84],[1,2.4,23.74],[2,2.42,89.91]],"ltp":2.36,"tv":11560.47,"id":9633869}]}]}
{"op":"mcm","clk":"4230858297","pt":1631537283576,"mc":[{"id":"1.187557995","rc":[{"batl":[[1,1.77,81.33]],"ltp":1.74,"tv":102369.69,"id":9342449}]}]}
{"op":"mcm","clk":"4230858505","pt":1631537285668,"mc":[{"id":"1.187557995","rc":[{"batb":[[1,1.74,143.1],[2,1.73,128.13]],"batl":[[1,1.77,11.3]],"ltp":1.74,"tv":102369.69,"id":9342449}]}]}
{"op":"mcm","clk":"4230858717","pt":1631537287460,"mc":[{"id":"1.187557995","rc":[{"batb":[[0,1.74,72.91],[1,1.73,128.13],[2,1.72,125.84]],"batl":[[0,1.76,225.35]],"ltp":1.74,"tv":102369.69,"id":9342449},{"batb":[[0,2.32,2025.86]],"ltp":2.36,"tv":11560.47,"id":9633869}]}]}
{"op":"mcm","clk":"4230859055","pt":1631537290687,"mc":[{"id":"1.187557995","rc":[{"batb":[[0,2.32,2071.31]],"ltp":2.36,"tv":11560.47,"id":9633869}]}]}
{"op":"mcm","clk":"4230859326","pt":1631537293548,"mc":[{"id":"1.187557995","rc":[{"batl":[[0,1.76,285.35]],"ltp":1.74,"tv":102369.69,"id":9342449}]}]}
{"op":"mcm","clk":"4230859396","pt":1631537294374,"mc":[{"id":"1.187557995","rc":[{"trd":[[1.76,567.25]],"batl":[[0,1.76,1.75]],"ltp":1.76,"tv":102936.93,"id":9342449},{"batb":[[0,2.32,2025.86]],"ltp":2.36,"tv":11560.47,"id":9633869}],"tv":114497.41}]}
{"op":"mcm","clk":"4230859606","pt":1631537296595,"mc":[{"id":"1.187557995","rc":[{"batb":[[0,1.71,340.83],[1,1.7,392.88],[2,1.68,140.11]],"batl":[[1,1.79,340.72],[2,1.8,103.92]],"ltp":1.76,"tv":102936.93,"id":9342449},{"batb":[[0,2.22,175.58],[1,2.2,88.18],[2,2.18,109.57]],"batl":[[0,2.44,25.92],[1,2.48,21.49],[2,2.52,79.85]],"ltp":2.36,"tv":11560.47,"id":9633869}]}]}
{"op":"mcm","clk":"4230859700","pt":1631537297657,"mc":[{"id":"1.187557995","rc":[{"batl":[[0,1.79,340.72],[1,1.8,103.92],[2,1.82,134.21]],"ltp":1.76,"tv":102936.93,"id":9342449},{"batb":[[0,2.28,46.87],[1,2.22,175.58],[2,2.2,88.18]],"ltp":2.36,"tv":11560.47,"id":9633869}]}]}
{"op":"mcm","clk":"4230859710","pt":1631537297769,"mc":[{"id":"1.187557995","rc":[{"batb":[[0,2.22,175.58],[1,2.2,88.18],[2,2.18,109.57]],"ltp":2.36,"tv":11560.47,"id":9633869}]}]}
{"op":"mcm","clk":"4230859852","pt":1631537299577,"mc":[{"id":"1.187557995","rc":[{"batb":[[0,1.72,146.96],[1,1.71,340.72],[2,1.7,392.88]],"ltp":1.76,"tv":102936.93,"id":9342449},{"batl":[[0,2.4,23.08],[1,2.44,25.83],[2,2.48,21.49]],"ltp":2.36,"tv":11560.47,"id":9633869}]}]}
{"op":"mcm","clk":"4230859874","pt":1631537299784,"mc":[{"id":"1.187557995","rc":[{"batb":[[0,1.71,340.83],[1,1.7,392.88],[2,1.68,140.11]],"ltp":1.76,"tv":102936.93,"id":9342449},{"batl":[[0,2.44,25.92],[1,2.48,21.49],[2,2.52,79.85]],"ltp":2.36,"tv":11560.47,"id":9633869}]}]}
{"op":"mcm","clk":"4230860081","pt":1631537301905,"mc":[{"id":"1.187557995","rc":[{"batl":[[0,1.78,132.88],[1,1.79,340.72],[2,1.8,103.92]],"ltp":1.76,"tv":102936.93,"id":9342449}]}]}
{"op":"mcm","clk":"4230860339","pt":1631537304399,"mc":[{"id":"1.187557995","rc":[{"batb":[[1,1.7,127.12]],"ltp":1.76,"tv":102936.93,"id":9342449},{"batb":[[0,2.22,93.81],[1,2.08,26.56],[2,1.97,1.05]],"ltp":2.36,"tv":11560.47,"id":9633869}]}]}
{"op":"mcm","clk":"4230860457","pt":1631537305493,"mc":[{"id":"1.187557995","rc":[{"trd":[[1.73,64.16]],"batb":[[0,1.7,127.12],[1,1.66,124.65],[2,1.65,132.9]],"batl":[[0,1.79,340.72],[1,1.86,340.72],[2,2,80]],"ltp":1.73,"tv":102937.06,"id":9342449},{"trd":[[2.36,80.18]],"batl":[[0,2.44,25.83],[1,2.52,79.85],[2,2.54,80.68]],"ltp":2.36,"tv":11560.57,"id":9633869}],"tv":114497.64}]}
{"op":"mcm","clk":"4230860588","pt":1631537306690,"mc":[{"id":"1.187557995","rc":[{"trd":[[1.72,143.86]],"batl":[[0,1.73,1358.38],[1,1.74,679.2],[2,1.75,679.2]],"ltp":1.72,"tv":103080.15,"id":9342449},{"trd":[[2.4,154.46]],"batb":[[0,2.4,1572.51],[1,2.22,93.81],[2,2.08,26.56]],"ltp":2.4,"tv":11710.0,"id":9633869}],"tv":114790.16}]}
{"op":"mcm","clk":"4230860688","pt":1631537307678,"mc":[{"id":"1.187557995","rc":[{"batl":[[0,1.73,826.59],[1,1.74,407.52],[2,1.75,407.52]],"ltp":1.72,"tv":103080.15,"id":9342449},{"batb":[[0,2.4,900.09],[1,2.26,41.98],[2,2.22,93.81]],"ltp":2.4,"tv":11710.0,"id":9633869}]}]}
{"op":"mcm","clk":"4230860743","pt":1631537308399,"mc":[{"id":"1.187557995","rc":[{"trd":[[1.7,285.98]],"batb":[[0,1.7,16.2]],"ltp":1.7,"tv":103236.08,"id":9342449},{"trd":[[2.4,218.46],[2.44,317.34]],"batb":[[0,2.4,868.09],[1,2.34,44.77],[2,2.32,84.27]],"batl":[[0,2.52,79.85],[1,2.54,80.68],[2,2.56,115.12]],"ltp":2.4,"tv":11871.62,"id":9633869}],"tv":115107.71}]}
{"op":"mcm","clk":"4230860865","pt":1631537309698,"mc":[{"id":"1.187557995","rc":[{"batl":[[0,1.71,402],[1,1.73,826.59],[2,1.74,407.52]],"ltp":1.7,"tv":103236.08,"id":9342449}]}]}
{"op":"mcm","clk":"4230860919","pt":1631537310286,"mc":[{"id":"1.187557995","rc":[{"batl":[[1,1.72,116],[2,1.73,826.59]],"ltp":1.7,"tv":103236.08,"id":9342449}]}]}
{"op":"mcm","clk":"4230861045","pt":1631537311691,"mc":[{"id":"1.187557995","rc":[{"trd":[[1.65,362.82],[1.66,249.28],[1.7,318.38]],"batb":[[0,1.7,66.5],[1,1.64,162.79],[2,1.63,117.57]],"batl":[[0,1.72,299.69],[1,1.73,826.59],[2,1.74,407.52]],"ltp":1.65,"tv":103880.58,"id":9342449},{"trd":[[2.52,63.55]],"batl":[[0,2.56,115.12],[1,2.6,11.85],[2,2.64,7.58]],"ltp":2.52,"tv":11935.18,"id":9633869}],"tv":115815.76}]}
{"op":"mcm","clk":"4230861127","pt":1631537312568,"mc":[{"id":"1.187557995","rc":[{"batb":[[0,1.69,69.78]],"batl":[[0,1.7,41.37],[1,1.71,60.29],[2,1.72,55.99]],"ltp":1.65,"tv":103880.58,"id":9342449},{"batb":[[0,2.42,60.69],[1,2.4,868.09],[2,2.34,44.77]],"ltp":2.52,"tv":11935.18,"id":9633869}]}]}
{"op":"mcm","clk":"4230861200","pt":1631537313496,"mc":[{"id":"1.187557995","rc":[{"batb":[[0,1.64,162.79],[1,1.63,117.57],[2,1.61,139.09]],"ltp":1.65,"tv":103880.58,"id":9342449},{"batl":[[2,2.64,28.01]],"ltp":2.52,"tv":11935.18,"id":9633869}]}]}
{"op":"mcm","clk":"4230861302","pt":1631537314489,"mc":[{"id":"1.187557995","rc":[{"trd":[[1.65,509.82]],"batb":[[1,1.63,193.16]],"batl":[[0,1.66,132.44],[1,1.7,46.37],[2,1.71,65.29]],"ltp":1.65,"tv":104027.58,"id":9342449},{"batb":[[0,2.42,4],[1,2.4,872.09]],"ltp":2.52,"tv":11935.18,"id":9633869}],"tv":115962.76}]}
{"op":"mcm","clk":"4230861402","pt":1631537315692,"mc":[{"id":"1.187557995","rc":[{"trd":[[1.66,249.52]],"batl":[[0,1.66,132.32]],"ltp":1.66,"tv":104027.82,"id":9342449},{"batb":[[0,2.44,3],[1,2.42,4],[2,2.4,872.09]],"ltp":2.52,"tv":11935.18,"id":9633869}],"tv":115963.0}]}
{"op":"mcm","clk":"4230861597","pt":1631537317708,"mc":[{"id":"1.187557995","rc":[{"batb":[[0,1.65,69.89],[1,1.64,233.34],[2,1.63,193.16]],"batl":[[0,1.66,253.83],[1,1.67,205.37],[2,1.69,68.79]],"ltp":1.66,"tv":104027.82,"id":9342449}]}]}
{"op":"mcm","clk":"4230861686","pt":1631537318595,"mc":[{"id":"1.187557995","rc":[{"trd":[[1.65,649.6]],"batb":[[0,1.64,233.34],[1,1.63,193.16],[2,1.61,294.2]],"batl":[[0,1.65,28.66],[1,1.66,253.83],[2,1.67,205.37]],"ltp":1.65,"tv":104167.6,"id":9342449}],"tv":116102.78}]}
{"op":"mcm","clk":"4230861857","pt":1631537320715,"mc":[{"id":"1.187557995","rc":[{"trd":[[1.65,706.91],[1.66,251.72]],"batl":[[0,1.66,327.11],[1,1.67,205.37],[2,1.69,68.79]],"ltp":1.66,"tv":104227.11,"id":9342449}],"tv":116162.29}]}
{"op":"mcm","clk":"4230861936","pt":1631537321607,"mc":[{"id":"1.187557995","rc":[{"trd":[[1.64,61.33]],"batb":[[0,1.64,209.9]],"batl":[[0,1.66,534.11]],"ltp":1.64,"tv":104273.98,"id":9342449},{"batb":[[0,2.46,15],[1,2.44,3],[2,2.42,4]],"ltp":2.52,"tv":11935.18,"id":9633869}],"tv":116209.16}]}
{"op":"mcm","clk":"4230862047","pt":1631537322703,"mc":[{"id":"1.187557995","rc":[{"trd":[[1.64,202.43]],"batb":[[0,1.63,193.16],[1,1.61,294.2],[2,1.6,299.31]],"batl":[[0,1.64,70.63],[1,1.66,534.11],[2,1.67,205.37]],"ltp":1.64,"tv":104415.08,"id":9342449},{"batl":[[0,2.6,11.85],[1,2.64,28.01],[2,2.68,18.64]],"ltp":2.52,"tv":11935.18,"id":9633869}],"tv":116350.26}]}
{"op":"mcm","clk":"4230862125","pt":1631537323626,"mc":[{"id":"1.187557995","rc":[{"trd":[[1.64,343.7],[1.66,677.69]],"batb":[[2,1.6,148.09]],"batl":[[0,1.66,321.14],[1,1.67,205.37],[2,1.69,68.79]],"ltp":1.66,"tv":104982.32,"id":9342449}],"tv":116917.5}]}
{"op":"mcm","clk":"4230862227","pt":1631537324713,"mc":[{"id":"1.187557995","rc":[{"batl":[[0,1.65,30.01],[1,1.66,281.38],[2,1.67,205.37]],"ltp":1.66,"tv":104982.32,"id":9342449},{"batb":[[1,2.42,4],[2,2.4,872.09]],"ltp":2.52,"tv":11935.18,"id":9633869}]}]}
{"op":"mcm","clk":"4230862317","pt":1631537325514,"mc":[{"id":"1.187557995","rc":[{"trd":[[1.65,786.91]],"batl":[[0,1.65,39.62]],"ltp":1.65,"tv":105062.32,"id":9342449},{"batb":[[0,2.42,4],[1,2.4,868.09],[2,2.36,44.11]],"ltp":2.52,"tv":11935.18,"id":9633869}],"tv":116997.5}]}
{"op":"mcm","clk":"4230862428","pt":1631537326706,"mc":[{"id":"1.187557995","rc":[{"batb":[[1,1.62,129.39],[2,1.61,294.2]],"ltp":1.65,"tv":105062.32,"id":9342449}]}]}
{"op":"mcm","clk":"4230862438","pt":1631537326810,"mc":[{"id":"1.187557995","rc":[{"batb":[[1,1.62,144.88]],"batl":[[2,1.67,325.11]],"ltp":1.65,"tv":105062.32,"id":9342449}]}]}
{"op":"mcm","clk":"4230862601","pt":1631537328629,"mc":[{"id":"1.187557995","rc":[{"batl":[[1,1.66,316.81]],"ltp":1.65,"tv":105062.32,"id":9342449}]}]}
{"op":"mcm","clk":"4230862859","pt":1631537331706,"mc":[{"id":"1.187557995","rc":[{"batb":[[0,2.44,33.26],[1,2.42,4],[2,2.4,868.09]],"ltp":2.52,"tv":11935.18,"id":9633869}]}]}
{"op":"mcm","clk":"4230863080","pt":1631537334515,"mc":[{"id":"1.187557995","rc":[{"trd":[[1.65,796.67]],"batl":[[0,1.65,34.74]],"ltp":1.65,"tv":105072.08,"id":9342449}],"tv":117007.26}]}
{"op":"mcm","clk":"4230863292","pt":1631537337519,"mc":[{"id":"1.187557995","rc":[{"trd":[[1.65,816.19]],"batl":[[0,1.65,24.98]],"ltp":1.65,"tv":105091.61,"id":9342449}],"tv":117026.79}]}
{"op":"mcm","clk":"4230863374","pt":1631537338412,"mc":[{"id":"1.187557995","rc":[{"trd":[[1.65,866.15]],"batb":[[0,1.65,260.99],[1,1.63,193.16],[2,1.62,144.88]],"batl":[[0,1.66,316.81],[1,1.67,325.11],[2,1.68,126.42]],"ltp":1.65,"tv":105141.57,"id":9342449}],"tv":117076.75}]}
{"op":"mcm","clk":"4230863580","pt":1631537340704,"mc":[{"id":"1.187557995","rc":[{"trd":[[1.65,873.85]],"batb":[[0,1.65,253.29]],"ltp":1.65,"tv":105149.27,"id":9342449},{"trd":[[2.54,5]],"ltp":2.54,"tv":11940.18,"id":9633869}],"tv":117089.45}]}
{"op":"mcm","clk":"4230863661","pt":1631537341431,"mc":[{"id":"1.187557995","rc":[{"trd":[[1.65,919.32]],"batb":[[0,1.65,230.55],[1,1.64,17.57],[2,1.63,193.16]],"ltp":1.65,"tv":105194.73,"id":9342449}],"tv":117134.91}]}
{"op":"mcm","clk":"4230863940","pt":1631537344611,"mc":[{"id":"1.187557995","rc":[{"batb":[[0,1.65,233.25]],"batl":[[1,1.67,76],[2,1.69,211.04]],"ltp":1.65,"tv":105194.73,"id":9342449},{"batb":[[2,2.4,871.09]],"ltp":2.54,"tv":11940.18,"id":9633869}]}]}
{"op":"mcm","clk":"4230864075","pt":1631537346128,"mc":[{"id":"1.187557995","rc":[{"trd":[[1.66,687.45]],"batl":[[0,1.66,311.93]],"ltp":1.66,"tv":105204.49,"id":9342449}],"tv":117144.67}]}
{"op":"mcm","clk":"4230864179","pt":1631537347118,"mc":[{"id":"1.187557995","rc":[{"batb":[[0,1.65,268.33]],"ltp":1.66,"tv":105204.49,"id":9342449}]}]}
{"op":"mcm","clk":"4230864551","pt":1631537350955,"mc":[{"id":"1.187557995","rc":[{"batb":[[0,1.65,266.01]],"batl":[[2,1.68,340.72]],"ltp":1.66,"tv":105204.49,"id":9342449}]}]}
{"op":"mcm","clk":"4230864801","pt":1631537353575,"mc":[{"id":"1.187557995","rc":[{"batb":[[0,1.65,252.73],[1,1.63,75.59],[2,1.58,111.17]],"batl":[[0,1.66,207],[1,1.68,340.72],[2,1.69,142.25]],"ltp":1.66,"tv":105204.49,"id":9342449},{"batb":[[0,2.36,44.11],[1,2.32,84.27],[2,2.28,77.38]],"batl":[[1,2.72,85.99],[2,2.74,73.69]],"ltp":2.54,"tv":11940.18,"id":9633869}]}]}
{"op":"mcm","clk":"4230864877","pt":1631537354358,"mc":[{"id":"1.187557995","rc":[{"batb":[[1,1.58,111.17],[2,1.57,184.64]],"batl":[[0,1.68,340.72],[1,1.69,142.25],[2,1.7,340.72]],"ltp":1.66,"tv":105204.49,"id":9342449},{"batb":[[0,2.32,84.27],[1,2.28,77.38],[2,2.26,120.02]],"batl":[[0,2.72,85.99],[1,2.74,73.69],[2,2.76,114.49]],"ltp":2.54,"tv":11940.18,"id":9633869}]}]}
{"op":"mcm","clk":"4230864954","pt":1631537355247,"mc":[{"id":"1.187557995","rc":[{"batl":[[2,1.71,113.29]],"ltp":1.66,"tv":105204.49,"id":9342449},{"batl":[[0,2.5,5],[1,2.72,85.99],[2,2.74,73.69]],"ltp":2.54,"tv":11940.18,"id":9633869}]}]}
{"op":"mcm","clk":"4230865076","pt":1631537356660,"mc":[{"id":"1.187557995","rc":[{"batb":[[0,1.65,24.5]],"ltp":1.66,"tv":105204.49,"id":9342449},{"batb":[[1,2.3,86.36],[2,2.28,77.38]],"ltp":2.54,"tv":11940.18,"id":9633869}]}]}
{"op":"mcm","clk":"4230865139","pt":1631537357390,"mc":[{"id":"1.187557995","rc":[{"batl":[[1,1.71,113.29],[2,1.74,157.51]],"ltp":1.66,"tv":105204.49,"id":9342449},{"batb":[[0,2.3,86.36],[1,2.28,77.38],[2,2.26,120.02]],"ltp":2.54,"tv":11940.18,"id":9633869}]}]}
{"op":"mcm","clk":"4230865412","pt":1631537359697,"mc":[{"id":"1.187557995","rc":[{"batb":[[1,1.59,142.25],[2,1.58,111.17]],"ltp":1.66,"tv":105204.49,"id":9342449}]}]}
{"op":"mcm","clk":"4230865643","pt":1631537361567,"mc":[{"id":"1.187557995","rc":[{"batl":[[0,2.72,85.99],[1,2.74,73.69],[2,2.76,114.49]],"ltp":2.54,"tv":11940.18,"id":9633869}]}]}
{"op":"mcm","clk":"4230865734","pt":1631537362662,"mc":[{"id":"1.187557995","rc":[{"batb":[[2,1.56,184.33]],"ltp":1.66,"tv":105204.49,"id":9342449},{"batl":[[0,2.8,19.42],[1,2.82,19.25],[2,2.98,19.25]],"ltp":2.54,"tv":11940.18,"id":9633869}]}]}
{"op":"mcm","clk":"4230865811","pt":1631537363472,"mc":[{"id":"1.187557995","rc":[{"batb":[[1,1.54,145.02],[2,1.51,172.99]],"batl":[[0,1.74,157.51],[1,1.76,216.63],[2,1.77,136.78]],"ltp":1.66,"tv":105204.49,"id":9342449},{"batl":[[0,2.98,19.25],[1,6,3],[2,6.4,3]],"ltp":2.54,"tv":11940.18,"id":9633869}]}]}
{"op":"mcm","clk":"4230865905","pt":1631537364674,"mc":[{"id":"1.187557995","rc":[{"batl":[[0,2.46,5],[1,2.98,19.25],[2,6,3]],"ltp":2.54,"tv":11940.18,"id":9633869}]}]}
{"op":"mcm","clk":"4230865998","pt":1631537365661,"mc":[{"id":"1.187557995","rc":[{"batb":[[0,1.7,3.22],[1,1.69,1545.77],[2,1.68,3160.18]],"ltp":1.66,"tv":105204.49,"id":9342449},{"batl":[[0,2.44,4.83],[1,2.46,5],[2,2.52,7.94]],"ltp":2.54,"tv":11940.18,"id":9633869}]}]}
{"op":"mcm","clk":"4230866091","pt":1631537366701,"mc":[{"id":"1.187557995","rc":[{"batb":[[0,1.71,99.66],[1,1.7,3.22],[2,1.69,433.35]],"ltp":1.66,"tv":105204.49,"id":9342449}]}]}
{"op":"mcm","clk":"4230866172","pt":1631537367588,"mc":[{"id":"1.187557995","rc":[{"batl":[[0,1.74,190.92]],"ltp":1.66,"tv":105204.49,"id":9342449},{"batb":[[0,2.32,35.24],[1,2.3,86.36],[2,2.28,77.38]],"batl":[[2,2.48,12.32]],"ltp":2.54,"tv":11940.18,"id":9633869}]}]}
{"op":"mcm","clk":"4230866219","pt":1631537368110,"mc":[{"id":"1.187557995","rc":[{"batb":[[2,2.28,81.38]],"ltp":2.54,"tv":11940.18,"id":9633869}]}]}
{"op":"mcm","clk":"4230866468","pt":1631537370686,"mc":[{"id":"1.187557995","rc":[{"trd":[[1.72,148.97]],"batb":[[0,1.72,121.27],[1,1.71,99.66],[2,1.7,3.22]],"batl":[[0,1.73,166.95],[1,1.74,250.92],[2,1.76,216.63]],"ltp":1.72,"tv":105209.6,"id":9342449},{"batl":[[2,2.52,7.94]],"ltp":2.54,"tv":11940.18,"id":9633869}],"tv":117149.78}]}
{"op":"mcm","clk":"4230866663","pt":1631537372709,"mc":[{"id":"1.187557995","rc":[{"batb":[[0,1.72,404.91]],"ltp":1.72,"tv":105209.6,"id":9342449},{"batl":[[2,2.52,36.21]],"ltp":2.54,"tv":11940.18,"id":9633869}]}]}
{"op":"mcm","clk":"4230866737","pt":1631537373490,"mc":[{"id":"1.187557995","rc":[{"batl":[[0,2.44,17.33]],"ltp":2.54,"tv":11940.18,"id":9633869}]}]}
{"op":"mcm","clk":"4230866786","pt":1631537374010,"mc":[{"id":"1.187557995","rc":[{"batb":[[1,1.71,132.79]],"ltp":1.72,"tv":105209.6,"id":9342449}]}]}
{"op":"mcm","clk":"4230866920","pt":1631537375517,"mc":[{"id":"1.187557995","rc":[{"trd":[[1.72,156.22]],"batb":[[0,1.72,397.66]],"batl":[[1,1.74,337.73]],"ltp":1.72,"tv":105216.86,"id":9342449},{"trd":[[2.4,223.66]],"ltp":2.4,"tv":11945.38,"id":9633869}],"tv":117162.24}]}
{"op":"mcm","clk":"4230867242","pt":1631537378705,"mc":[{"id":"1.187557995","rc":[{"batb":[[0,1.72,431.24],[1,1.7,3.22],[2,1.69,72.23]],"batl":[[0,1.73,72.46],[1,1.83,93.05],[2,1.84,114.33]],"ltp":1.72,"tv":105216.86,"id":9342449},{"batb":[[0,2.22,49.18],[1,2.2,101.25],[2,2.18,196.8]],"batl":[[2,2.52,28.27]],"ltp":2.4,"tv":11945.38,"id":9633869}]}]}
{"op":"mcm","clk":"4230867335","pt":1631537379589,"mc":[{"id":"1.187557995","rc":[{"trd":[[1.72,1018.64]],"batb":[[0,1.7,3.22],[1,1.68,2.32],[2,1.65,116.84]],"batl":[[0,1.72,3098.24],[1,1.73,72.46],[2,1.78,160.99]],"ltp":1.72,"tv":106079.28,"id":9342449},{"batb":[[0,2.2,101.25],[1,2.18,196.8],[2,2.16,127.19]],"batl":[[0,2.44,4.83],[2,2.58,77.31]],"ltp":2.4,"tv":11945.38,"id":9633869}],"tv":118024.66}]}
{"op":"mcm","clk":"4230867371","pt":1631537379899,"mc":[{"id":"1.187557995","rc":[{"batl":[[1,1.78,160.99],[2,1.83,93.05]],"ltp":1.72,"tv":106079.28,"id":9342449}]}]}
{"op":"mcm","clk":"4230867525","pt":1631537381617,"mc":[{"id":"1.187557995","rc":[{"batl":[[2,1.82,189.09]],"ltp":1.72,"tv":106079.28,"id":9342449}]}]}
{"op":"mcm","clk":"4230867641","pt":1631537382715,"mc":[{"id":"1.187557995","rc":[{"batl":[[0,1.82,189.09],[1,1.83,93.05],[2,1.84,301.02]],"ltp":1.72,"tv":106079.28,"id":9342449}]}]}
{"op":"mcm","clk":"4230867693","pt":1631537383195,"mc":[{"id":"1.187557995","rc":[{"batl":[[1,2.58,77.31],[2,2.6,109.55]],"ltp":2.4,"tv":11945.38,"id":9633869}]}]}
{"op":"mcm","clk":"4230867781","pt":1631537384326,"mc":[{"id":"1.187557995","rc":[{"batb":[[1,1.65,363.86],[2,1.64,103.5]],"ltp":1.72,"tv":106079.28,"id":9342449}]}]}
{"op":"mcm","clk":"4230867963","pt":1631537386205,"mc":[{"id":"1.187557995","rc":[{"batb":[[0,1.73,11.07],[1,1.7,3.22],[2,1.65,363.86]],"batl":[[0,1.81,123.51],[1,1.82,189.09],[2,1.83,93.05]],"ltp":1.72,"tv":106079.28,"id":9342449}]}]}
{"op":"mcm","clk":"4230868097","pt":1631537387608,"mc":[{"id":"1.187557995","rc":[{"batb":[[0,1.7,3.22],[1,1.65,363.86],[2,1.63,161.19]],"ltp":1.72,"tv":106079.28,"id":9342449},{"batl":[[1,2.6,26.67],[2,2.98,19.25]],"ltp":2.4,"tv":11945.38,"id":9633869}]}]}
{"op":"mcm","clk":"4230868289","pt":1631537389625,"mc":[{"id":"1.187557995","rc":[{"trd":[[1.65,1662.19],[1.69,112.29],[1.7,324.82]],"batb":[[0,1.66,145.78],[1,1.63,157.23],[2,1.62,122.26]],"batl":[[2,1.83,412.55]],"ltp":1.65,"tv":106835.55,"id":9342449},{"trd":[[2.44,322.17],[2.52,68.56]],"batb":[[0,2.2,127.92]],"batl":[[0,2.52,23.26],[1,2.6,22.26],[2,990,0.01]],"ltp":2.52,"tv":11955.22,"id":9633869}],"tv":118790.77}]}
{"op":"mcm","clk":"4230868381","pt":1631537390713,"mc":[{"id":"1.187557995","rc":[{"batb":[[0,1.76,162.46],[1,1.74,1319.77],[2,1.73,1066.82]],"batl":[[0,1.82,189.09],[1,1.83,93.05],[2,1.84,301.02]],"ltp":1.65,"tv":106835.55,"id":9342449},{"batb":[[0,2.2,101.25],[1,2.18,679.32],[2,2.16,595.5]],"batl":[[0,2.32,5.11],[1,2.4,8.33],[2,2.6,22.26]],"ltp":2.52,"tv":11955.22,"id":9633869}]}]}
{"op":"mcm","clk":"4230868471","pt":1631537391712,"mc":[{"id":"1.187557995","rc":[{"batb":[[0,1.79,86.53],[1,1.76,162.46],[2,1.74,1319.77]],"ltp":1.65,"tv":106835.55,"id":9342449}]}]}
{"op":"mcm","clk":"4230868566","pt":1631537392603,"mc":[{"id":"1.187557995","rc":[{"batb":[[0,2.22,27.3],[1,2.2,101.25],[2,2.18,679.32]],"batl":[[2,2.42,24.15]],"ltp":2.52,"tv":11955.22,"id":9633869}]}]}
{"op":"mcm","clk":"4230868625","pt":1631537393325,"mc":[{"id":"1.187557995","rc":[{"batl":[[0,1.82,222.61]],"ltp":1.65,"tv":106835.55,"id":9342449}]}]}
{"op":"mcm","clk":"4230868750","pt":1631537394622,"mc":[{"id":"1.187557995","rc":[{"trd":[[1.79,206.9]],"batb":[[0,1.76,162.46],[1,1.74,1319.77],[2,1.73,1066.82]],"batl":[[0,1.77,250.19],[1,1.82,222.61],[2,1.83,93.05]],"ltp":1.79,"tv":107008.57,"id":9342449}],"tv":118963.79}]}
{"op":"mcm","clk":"4230868861","pt":1631537395714,"mc":[{"id":"1.187557995","rc":[{"trd":[[1.77,206.86]],"batb":[[1,1.75,69.28],[2,1.74,1319.77]],"batl":[[0,1.77,146.75],[1,1.81,292.29],[2,1.82,222.61]],"ltp":1.77,"tv":107215.43,"id":9342449}],"tv":119170.65}]}
{"op":"mcm","clk":"4230868957","pt":1631537396703,"mc":[{"id":"1.187557995","rc":[{"batb":[[1,1.74,1319.77],[2,1.73,1066.82]],"ltp":1.77,"tv":107215.43,"id":9342449}]}]}
{"op":"mcm","clk":"4230869016","pt":1631537397325,"mc":[{"id":"1.187557995","rc":[{"trd":[[1.77,500.36],[1.81,792.17]],"batb":[[0,1.76,339.8],[2,1.73,1209.08]],"batl":[[0,1.78,91.16],[1,1.81,155.4]],"ltp":1.81,"tv":107782.72,"id":9342449},{"batb":[[2,2.18,707.18]],"batl":[[0,2.32,29.72],[1,2.38,30.5],[2,2.4,8.33]],"ltp":2.52,"tv":11955.22,"id":9633869}],"tv":119737.94}]}
{"op":"mcm","clk":"4230869125","pt":1631537398418,"mc":[{"id":"1.187557995","rc":[{"batl":[[0,1.81,155.4],[1,1.82,222.61],[2,1.83,93.05]],"ltp":1.81,"tv":107782.72,"id":9342449},{"batl":[[2,2.4,37.11]],"ltp":2.52,"tv":11955.22,"id":9633869}]}]}
{"op":"mcm","clk":"4230869197","pt":1631537399209,"mc":[{"id":"1.187557995","rc":[{"batb":[[0,1.76,408.62]],"ltp":1.81,"tv":107782.72,"id":9342449},{"batl":[[0,2.32,42.77]],"ltp":2.52,"tv":11955.22,"id":9633869}]}]}
{"op":"mcm","clk":"4230869322","pt":1631537400513,"mc":[{"id":"1.187557995","rc":[{"trd":[[1.8,211.34],[1.81,1102.99],[1.82,191.14]],"batl":[[0,1.82,187.78],[1,1.83,93.05],[2,1.84,632.05]],"ltp":1.82,"tv":108349.97,"id":9342449}],"tv":120305.19}]}
{"op":"mcm","clk":"4230869441","pt":1631537401623,"mc":[{"id":"1.187557995","rc":[{"batb":[[0,1.76,71.8],[1,1.72,159.34],[2,1.71,284.1]],"batl":[[0,1.87,95.35],[1,1.88,414.64],[2,1.89,144.25]],"ltp":1.82,"tv":108349.97,"id":9342449},{"batb":[[0,2.14,103.47],[1,2.12,92.94],[2,2.1,219.03]],"batl":[[0,2.32,18.16],[1,2.4,23.24],[2,2.42,118.32]],"ltp":2.52,"tv":11955.22,"id":9633869}]}]}
{"op":"mcm","clk":"4230869530","pt":1631537402560,"mc":[{"id":"1.187557995","rc":[{"batb":[[0,1.82,2.32],[1,1.76,2.98],[2,1.72,159.34]],"ltp":1.82,"tv":108349.97,"id":9342449},{"batl":[[0,2.32,5.11]],"ltp":2.52,"tv":11955.22,"id":9633869}]}]}
{"op":"mcm","clk":"4230869647","pt":1631537403718,"mc":[{"id":"1.187557995","rc":[{"trd":[[1.82,195.79]],"batb":[[0,1.77,69.24],[2,1.72,539.24]],"batl":[[0,1.78,19.51],[1,1.79,36.47],[2,1.8,75.1]],"ltp":1.82,"tv":108354.61,"id":9342449},{"batb":[[0,2.14,130.79]],"ltp":2.52,"tv":11955.22,"id":9633869}],"tv":120309.84}]}
{"op":"mcm","clk":"4230869743","pt":1631537404707,"mc":[{"id":"1.187557995","rc":[{"batb":[[0,1.76,2.98],[1,1.73,144.13]],"ltp":1.82,"tv":108354.61,"id":9342449},{"batb":[[0,2.18,27.36],[1,2.14,130.79],[2,2.12,123.73]],"batl":[[1,2.38,26.25],[2,2.4,23.24]],"ltp":2.52,"tv":11955.22,"id":9633869}]}]}
{"op":"mcm","clk":"4230869831","pt":1631537405644,"mc":[{"id":"1.187557995","rc":[{"batb":[[0,1.76,3.96],[1,1.72,539.24],[2,1.71,287.67]],"batl":[[0,1.87,387.85],[1,1.88,414.64],[2,1.89,144.25]],"ltp":1.82,"tv":108354.61,"id":9342449},{"batb":[[0,2.14,130.79],[1,2.12,123.73],[2,2.1,219.03]],"batl":[[1,2.4,23.24],[2,2.42,123.57]],"ltp":2.52,"tv":11955.22,"id":9633869}]}]}
{"op":"mcm","clk":"4230869915","pt":1631537406537,"mc":[{"id":"1.187557995","rc":[{"batl":[[0,2.28,5],[1,2.32,5.11],[2,2.4,23.24]],"ltp":2.52,"tv":11955.22,"id":9633869}]}]}
{"op":"mcm","clk":"4230870008","pt":1631537407422,"mc":[{"id":"1.187557995","rc":[{"batb":[[1,1.74,230.18],[2,1.72,769.1]],"batl":[[0,1.8,137.36],[1,1.82,193.55],[2,1.87,387.85]],"ltp":1.82,"tv":108354.61,"id":9342449},{"trd":[[2.28,10]],"batl":[[0,2.32,5.11],[1,2.4,23.24],[2,2.42,123.57]],"ltp":2.28,"tv":11965.22,"id":9633869}],"tv":120319.84}]}
{"op":"mcm","clk":"4230870132","pt":1631537408622,"mc":[{"id":"1.187557995","rc":[{"trd":[[1.8,230.08]],"batb":[[1,1.72,539.24],[2,1.71,287.67]],"batl":[[0,1.8,127.99]],"ltp":1.8,"tv":108373.35,"id":9342449}],"tv":120338.57}]}
{"op":"mcm","clk":"4230870209","pt":1631537409455,"mc":[{"id":"1.187557995","rc":[{"batb":[[0,2.16,60.86],[1,2.14,130.79],[2,2.12,123.73]],"ltp":2.28,"tv":11965.22,"id":9633869}]}]}
{"op":"mcm","clk":"4230870248","pt":1631537409816,"mc":[{"id":"1.187557995","rc":[{"batl":[[2,1.86,235.95]],"ltp":1.8,"tv":108373.35,"id":9342449}]}]}
{"op":"mcm","clk":"4230870419","pt":1631537411648,"mc":[{"id":"1.187557995","rc":[{"batl":[[0,1.86,235.95],[1,1.87,387.85],[2,1.88,414.64]],"ltp":1.8,"tv":108373.35,"id":9342449},{"batb":[[0,2.14,130.79],[1,2.12,123.73],[2,2.1,219.03]],"ltp":2.28,"tv":11965.22,"id":9633869}]}]}
{"op":"mcm","clk":"4230870702","pt":1631537414631,"mc":[{"id":"1.187557995","rc":[{"batl":[[1,2,80],[2,2.08,1]],"ltp":1.8,"tv":108373.35,"id":9342449},{"batb":[[0,2.14,31.32],[1,2.12,30.79],[2,2.1,110.54]],"ltp":2.28,"tv":11965.22,"id":9633869}]}]}
{"op":"mcm","clk":"4230870809","pt":1631537415620,"mc":[{"id":"1.187557995","rc":[{"batb":[[0,1.76,2.98],[1,1.72,159.34]],"batl":[[0,2,80],[1,2.08,1],[2,2.16,347.55]],"ltp":1.8,"tv":108373.35,"id":9342449}]}]}
{"op":"mcm","clk":"4230870884","pt":1631537416249,"mc":[{"id":"1.187557995","rc":[{"trd":[[1.76,572.19]],"batb":[[0,1.72,159.85],[1,1.71,284.1],[2,1.7,140.3]],"ltp":1.76,"tv":108378.29,"id":9342449},{"batb":[[1,2.12,26.79]],"batl":[[2,2.42,118.32]],"ltp":2.28,"tv":11965.22,"id":9633869}],"tv":120343.52}]}
{"op":"mcm","clk":"4230870993","pt":1631537417512,"mc":[{"id":"1.187557995","rc":[{"trd":[[1.75,239.56],[1.76,573.21]],"batb":[[0,1.72,159.34]],"batl":[[0,1.74,166.95],[1,1.76,1303.22],[2,1.77,1386.18]],"ltp":1.75,"tv":108386.08,"id":9342449},{"trd":[[2.32,397.03]],"batb":[[0,2.28,85.16],[1,2.16,762.34],[2,2.14,31.32]],"batl":[[0,2.4,23.24],[1,2.42,118.32],[2,2.44,114.41]],"ltp":2.32,"tv":11970.33,"id":9633869}],"tv":120356.42}]}
{"op":"mcm","clk":"4230871107","pt":1631537418717,"mc":[{"id":"1.187557995","rc":[{"batb":[[0,2.34,81.34],[1,2.28,85.16],[2,2.22,49.18]],"batl":[[2,2.44,126.91]],"ltp":2.32,"tv":11970.33,"id":9633869}]}]}
{"op":"mcm","clk":"4230871211","pt":1631537419652,"mc":[{"id":"1.187557995","rc":[{"batl":[[1,1.76,1305.22]],"ltp":1.75,"tv":108386.08,"id":9342449}]}]}
{"op":"mcm","clk":"4230871250","pt":1631537420018,"mc":[{"id":"1.187557995","rc":[{"trd":[[1.74,634.09]],"batl":[[0,1.74,138.81],[1,1.76,1705.22]],"ltp":1.74,"tv":108442.36,"id":9342449},{"batb":[[1,2.28,88.16],[2,2.26,3]],"ltp":2.32,"tv":11970.33,"id":9633869}],"tv":120412.7}]}
{"op":"mcm","clk":"4230871382","pt":1631537421537,"mc":[{"id":"1.187557995","rc":[{"batb":[[0,1.73,13.77],[1,1.72,323.56],[2,1.71,284.1]],"batl":[[0,1.74,287.7]],"ltp":1.74,"tv":108442.36,"id":9342449}]}]}
{"op":"mcm","clk":"4230871449","pt":1631537422262,"mc":[{"id":"1.187557995","rc":[{"batl":[[0,1.74,321.11]],"ltp":1.74,"tv":108442.36,"id":9342449},{"batb":[[0,2.36,21.92],[1,2.34,81.34],[2,2.28,88.16]],"ltp":2.32,"tv":11970.33,"id":9633869}]}]}
{"op":"mcm","clk":"4230871555","pt":1631537423568,"mc":[{"id":"1.187557995","rc":[{"trd":[[1.74,1201.34]],"batl":[[0,1.74,37.5]],"ltp":1.74,"tv":109009.62,"id":9342449}],"tv":120979.95}]}
{"op":"mcm","clk":"4230871660","pt":1631537424665,"mc":[{"id":"1.187557995","rc":[{"trd":[[1.74,1231.08]],"batb":[[0,1.74,254.91],[1,1.73,13.77],[2,1.72,323.56]],"batl":[[0,1.76,1488.64],[1,1.77,1386.18],[2,1.78,1054.68]],"ltp":1.74,"tv":109039.35,"id":9342449},{"trd":[[2.36,102.1]],"batb":[[0,2.34,81.34],[1,2.28,88.16],[2,2.26,3]],"ltp":2.36,"tv":11992.25,"id":9633869}],"tv":121031.6}]}
{"op":"mcm","clk":"4230871743","pt":1631537425447,"mc":[{"id":"1.187557995","rc":[{"trd":[[1.74,1657.11]],"batb":[[0,1.74,41.87]],"ltp":1.74,"tv":109465.39,"id":9342449}],"tv":121457.64}]}
{"op":"mcm","clk":"4230871962","pt":1631537427647,"mc":[{"id":"1.187557995","rc":[{"trd":[[1.74,1723.08]],"batb":[[0,1.74,8.88],[1,1.73,139.78]],"batl":[[0,1.75,295.52],[1,1.76,1531.63],[2,1.77,1598.46]],"ltp":1.74,"tv":109531.36,"id":9342449}],"tv":121523.61}]}
{"op":"mcm","clk":"4230872053","pt":1631537428642,"mc":[{"id":"1.187557995","rc":[{"trd":[[1.75,398.81]],"batb":[[0,1.74,75.6],[1,1.73,126.01],[2,1.72,264.45]],"batl":[[0,1.75,183.97],[1,1.76,1608.31]],"ltp":1.75,"tv":109690.61,"id":9342449},{"batb":[[0,2.34,107.6]],"ltp":2.36,"tv":11992.25,"id":9633869}],"tv":121682.86}]}
{"op":"mcm","clk":"4230872146","pt":1631537429533,"mc":[{"id":"1.187557995","rc":[{"batl":[[1,1.76,1208.31]],"ltp":1.75,"tv":109690.61,"id":9342449},{"batl":[[0,2.4,23.39]],"ltp":2.36,"tv":11992.25,"id":9633869}]}]}
{"op":"mcm","clk":"4230872259","pt":1631537430636,"mc":[{"id":"1.187557995","rc":[{"trd":[[1.74,1804.93]],"batb":[[0,1.73,126.01],[1,1.72,264.45],[2,1.71,284.1]],"batl":[[0,1.75,393.97],[1,1.76,1131.63]],"ltp":1.74,"tv":109772.46,"id":9342449}],"tv":121764.71}]}
{"op":"mcm","clk":"4230872325","pt":1631537431269,"mc":[{"id":"1.187557995","rc":[{"batb":[[2,2.22,79.02]],"ltp":2.36,"tv":11992.25,"id":9633869}]}]}
{"op":"mcm","clk":"4230872611","pt":1631537434365,"mc":[{"id":"1.187557995","rc":[{"batb":[[2,2.26,4]],"ltp":2.36,"tv":11992.25,"id":9633869}]}]}
{"op":"mcm","clk":"4230872781","pt":1631537436555,"mc":[{"id":"1.187557995","rc":[{"batl":[[0,1.74,70.59],[1,1.75,393.97],[2,1.76,1131.63]],"ltp":1.74,"tv":109772.46,"id":9342449},{"batl":[[0,2.4,23.24]],"ltp":2.36,"tv":11992.25,"id":9633869}]}]}
{"op":"mcm","clk":"4230872868","pt":1631537437450,"mc":[{"id":"1.187557995","rc":[{"trd":[[1.74,1946.13],[1.75,824.85]],"batl":[[0,1.75,180.97],[1,1.76,1131.63],[2,1.77,1598.46]],"ltp":1.75,"tv":110339.7,"id":9342449}],"tv":122331.95}]}
{"op":"mcm","clk":"4230872943","pt":1631537437974,"mc":[{"id":"1.187557995","rc":[{"batl":[[2,1.77,1386.18]],"ltp":1.75,"tv":110339.7,"id":9342449}]}]}
{"op":"mcm","clk":"4230873101","pt":1631537439700,"mc":[{"id":"1.187557995","rc":[{"trd":[[1.75,855.53]],"batb":[[0,1.69,175.66],[1,1.67,4.26],[2,1.66,3.78]],"batl":[[0,1.75,165.63],[1,1.76,2],[2,1.81,360.5]],"ltp":1.75,"tv":110370.38,"id":9342449},{"batb":[[0,2.34,81.34],[1,2.22,79.02],[2,2.2,96.48]],"batl":[[0,2.44,12.5],[1,2.5,4.69],[2,2.52,5.26]],"ltp":2.36,"tv":11992.25,"id":9633869}],"tv":122362.63}]}
{"op":"mcm","clk":"4230873183","pt":1631537440489,"mc":[{"id":"1.187557995","rc":[{"batb":[[0,1.65,180.58],[1,1.63,143.86],[2,1.62,310.3]],"batl":[[0,1.83,2],[1,1.84,127.57],[2,1.85,421.32]],"ltp":1.75,"tv":110370.38,"id":9342449},{"batb":[[0,2.2,96.48],[1,2.18,89.8],[2,2.16,143.2]],"batl":[[0,2.58,94.56],[1,2.6,102.79],[2,2.62,142.23]],"ltp":2.36,"tv":11992.25,"id":9633869}]}]}
{"op":"mcm","clk":"4230873359","pt":1631537442266,"mc":[{"id":"1.187557995","rc":[{"batl":[[2,1.85,608.65]],"ltp":1.75,"tv":110370.38,"id":9342449}]}]}
{"op":"mcm","clk":"4230873518","pt":1631537443678,"mc":[{"id":"1.187557995","rc":[{"batl":[[0,1.82,4],[1,1.83,2],[2,1.84,127.57]],"ltp":1.75,"tv":110370.38,"id":9342449},{"batb":[[0,2.2,99.48],[1,2.18,93.8]],"ltp":2.36,"tv":11992.25,"id":9633869}]}]}
{"op":"mcm","clk":"4230873708","pt":1631537445664,"mc":[{"id":"1.187557995","rc":[{"batl":[[1,1.83,238.8]],"ltp":1.75,"tv":110370.38,"id":9342449}]}]}
{"op":"mcm","clk":"4230873824","pt":1631537446660,"mc":[{"id":"1.187557995","rc":[{"batb":[[0,1.66,4.28],[1,1.65,180.58],[2,1.63,143.86]],"batl":[[0,1.81,325.5],[1,1.82,4],[2,1.83,238.8]],"ltp":1.75,"tv":110370.38,"id":9342449},{"batb":[[0,2.22,26.34],[1,2.2,99.48],[2,2.18,93.8]],"batl":[[0,2.52,4.76],[1,2.58,94.56],[2,2.6,102.79]],"ltp":2.36,"tv":11992.25,"id":9633869}]}]}
{"op":"mcm","clk":"4230873847","pt":1631537446869,"mc":[{"id":"1.187557995","rc":[{"batb":[[0,1.65,180.58],[1,1.63,143.86],[2,1.62,310.3]],"batl":[[0,1.82,4],[1,1.83,238.8],[2,1.84,127.57]],"ltp":1.75,"tv":110370.38,"id":9342449},{"batb":[[0,2.2,99.48],[1,2.18,93.8],[2,2.16,143.2]],"batl":[[0,2.58,94.56],[1,2.6,102.79],[2,2.62,142.23]],"ltp":2.36,"tv":11992.25,"id":9633869}]}]}
{"op":"mcm","clk":"4230873988","pt":1631537448537,"mc":[{"id":"1.187557995","rc":[{"batb":[[1,1.62,163.04],[2,1.58,132.3]],"ltp":1.75,"tv":110370.38,"id":9342449},{"batl":[[0,2.62,19.25],[1,6,3],[2,6.4,3]],"ltp":2.36,"tv":11992.25,"id":9633869}]}]}
{"op":"mcm","clk":"4230874089","pt":1631537449637,"mc":[{"id":"1.187557995","rc":[{"batb":[[0,1.62,163.04],[1,1.58,132.3],[2,1.46,441.71]],"batl":[[1,1.83,2]],"ltp":1.75,"tv":110370.38,"id":9342449},{"batl":[[1,990,0.01],[2,6.4,0]],"ltp":2.36,"tv":11992.25,"id":9633869}]}]}
{"op":"mcm","clk":"4230874185","pt":1631537450630,"mc":[{"id":"1.187557995","rc":[{"batb":[[0,1.78,2057.06],[1,1.62,163.04],[2,1.58,132.3]],"ltp":1.75,"tv":110370.38,"id":9342449}]}]}
{"op":"mcm","clk":"4230874285","pt":1631537451621,"mc":[{"id":"1.187557995","rc":[{"batb":[[0,1.79,130.35],[1,1.77,1288.31],[2,1.76,1048.72]],"batl":[[0,1.84,127.57],[1,1.85,608.65],[2,1.86,123.6]],"ltp":1.75,"tv":110370.38,"id":9342449},{"batb":[[0,2.2,96.48],[1,2.18,89.8]],"batl":[[0,2.28,5.34],[1,2.38,8.4],[2,2.62,19.25]],"ltp":2.36,"tv":11992.25,"id":9633869}]}]}
{"op":"mcm","clk":"4230874381","pt":1631537452619,"mc":[{"id":"1.187557995","rc":[{"batb":[[1,1.77,1378.27]],"ltp":1.75,"tv":110370.38,"id":9342449},{"batl":[[1,2.32,13.05],[2,2.38,8.4]],"ltp":2.36,"tv":11992.25,"id":9633869}]}]}
{"op":"mcm","clk":"4230874508","pt":1631537454026,"mc":[{"id":"1.187557995","rc":[{"batl":[[0,1.84,158.31]],"ltp":1.75,"tv":110370.38,"id":9342449}]}]}
{"op":"mcm","clk":"4230874659","pt":1631537455645,"mc":[{"id":"1.187557995","rc":[{"batb":[[0,1.8,180.95],[1,1.79,130.35],[2,1.77,1378.27]],"batl":[[0,1.83,80.71],[1,1.84,158.31],[2,1.85,608.65]],"ltp":1.75,"tv":110370.38,"id":9342449}]}]}
{"op":"mcm","clk":"4230874735","pt":1631537456324,"mc":[{"id":"1.187557995","rc":[{"batl":[[1,2.38,8.4],[2,2.58,86.15]],"ltp":2.36,"tv":11992.25,"id":9633869}]}]}
{"op":"mcm","clk":"4230874953","pt":1631537458507,"mc":[{"id":"1.187557995","rc":[{"batl":[[0,1.83,412.21]],"ltp":1.75,"tv":110370.38,"id":9342449},{"batb":[[0,2.2,127.25]],"batl":[[1,2.34,31.5],[2,2.38,39.9]],"ltp":2.36,"tv":11992.25,"id":9633869}]}]}
{"op":"mcm","clk":"4230875049","pt":1631537459503,"mc":[{"id":"1.187557995","rc":[{"batb":[[2,1.77,1446.64]],"ltp":1.75,"tv":110370.38,"id":9342449},{"batl":[[1,2.3,13.15],[2,2.32,31.22]],"ltp":2.36,"tv":11992.25,"id":9633869}]}]}
{"op":"mcm","clk":"4230875169","pt":1631537460552,"mc":[{"id":"1.187557995","rc":[{"batb":[[0,2.22,18.08],[1,2.2,127.25],[2,2.18,89.8]],"ltp":2.36,"tv":11992.25,"id":9633869}]}]}
{"op":"mcm","clk":"4230875391","pt":1631537462642,"mc":[{"id":"1.187557995","rc":[{"batb":[[0,1.81,68.51],[1,1.8,180.95],[2,1.79,130.35]],"batl":[[0,1.82,66.35],[1,1.83,462.21],[2,1.84,158.31]],"ltp":1.75,"tv":110370.38,"id":9342449}]}]}
{"op":"mcm","clk":"4230875408","pt":1631537462850,"mc":[{"id":"1.187557995","rc":[{"batb":[[1,1.8,116.26]],"batl":[[1,1.83,381.5]],"ltp":1.75,"tv":110370.38,"id":9342449}]}]}
{"op":"mcm","clk":"4230875540","pt":1631537464525,"mc":[{"id":"1.187557995","rc":[{"batb":[[0,1.8,116.26],[1,1.79,130.35],[2,1.77,1446.64]],"batl":[[0,1.83,381.5],[1,1.84,158.31],[2,1.85,608.65]],"ltp":1.75,"tv":110370.38,"id":9342449},{"batb":[[0,2.2,127.25],[1,2.18,89.8],[2,2.16,143.2]],"ltp":2.36,"tv":11992.25,"id":9633869}]}]}
{"op":"mcm","clk":"4230875620","pt":1631537465412,"mc":[{"id":"1.187557995","rc":[{"batl":[[1,1.84,489.09]],"ltp":1.75,"tv":110370.38,"id":9342449},{"batb":[[1,2.18,117.66]],"ltp":2.36,"tv":11992.25,"id":9633869}]}]}
{"op":"mcm","clk":"4230875738","pt":1631537466715,"mc":[{"id":"1.187557995","rc":[{"trd":[[1.81,1323.85]],"batb":[[0,1.79,130.35],[1,1.77,366.12],[2,1.76,151.71]],"batl":[[0,1.81,291.57],[1,1.83,381.5],[2,1.84,489.09]],"ltp":1.81,"tv":110591.24,"id":9342449}],"tv":122583.49}]}
{"op":"mcm","clk":"4230875804","pt":1631537467550,"mc":[{"id":"1.187557995","rc":[{"batb":[[0,1.79,2.93],[1,1.77,68.37]],"batl":[[0,1.86,287.75],[1,1.9,60],[2,2,80]],"ltp":1.81,"tv":110591.24,"id":9342449},{"batb":[[0,2.16,29.03],[1,2.14,33.32],[2,2.12,109.2]],"ltp":2.36,"tv":11992.25,"id":9633869}]}]}
{"op":"mcm","clk":"4230875910","pt":1631537468646,"mc":[{"id":"1.187557995","rc":[{"batb":[[1,1.73,128.13],[2,1.7,436.12]],"batl":[[1,2,80],[2,2.08,1]],"ltp":1.81,"tv":110591.24,"id":9342449},{"batb":[[2,2.12,113.2]],"batl":[[1,2.38,25.75],[2,2.62,19.25]],"ltp":2.36,"tv":11992.25,"id":9633869}]}]}
{"op":"mcm","clk":"4230876008","pt":1631537469637,"mc":[{"id":"1.187557995","rc":[{"batb":[[0,1.79,124.38]],"batl":[[0,1.81,64.56],[1,1.82,59.97],[2,1.86,287.75]],"ltp":1.81,"tv":110591.24,"id":9342449}]}]}
{"op":"mcm","clk":"4230876086","pt":1631537470525,"mc":[{"id":"1.187557995","rc":[{"batb":[[0,1.79,2.93],[2,1.71,199.91]],"batl":[[0,1.81,400],[1,1.85,283.3]],"ltp":1.81,"tv":110591.24,"id":9342449}]}]}
{"op":"mcm","clk":"4230876238","pt":1631537472139,"mc":[{"id":"1.187557995","rc":[{"batb":[[0,2.18,18.08],[1,2.16,29.03],[2,2.14,33.32]],"ltp":2.36,"tv":11992.25,"id":9633869}]}]}
{"op":"mcm","clk":"4230876384","pt":1631537473648,"mc":[{"id":"1.187557995","rc":[{"batl":[[0,1.8,2.32],[1,1.86,287.75],[2,1.87,285.5]],"ltp":1.81,"tv":110591.24,"id":9342449}]}]}
{"op":"mcm","clk":"4230876468","pt":1631537474529,"mc":[{"id":"1.187557995","rc":[{"batb":[[1,1.76,3.73],[2,1.73,131.52]],"ltp":1.81,"tv":110591.24,"id":9342449},{"batl":[[1,2.32,5.36],[2,2.38,31.5]],"ltp":2.36,"tv":11992.25,"id":9633869}]}]}
{"op":"mcm","clk":"4230876541","pt":1631537475521,"mc":[{"id":"1.187557995","rc":[{"trd":[[1.78,6.84],[1.79,212.76]],"batb":[[0,1.73,128.13],[1,1.71,199.91],[2,1.69,244.47]],"batl":[[0,1.77,1849.75],[1,1.8,2.32],[2,1.86,287.75]],"ltp":1.78,"tv":110603.94,"id":9342449},{"trd":[[2.28,15.34]],"batl":[[0,2.38,25.75],[1,2.62,19.25],[2,990,0.01]],"ltp":2.28,"tv":11997.59,"id":9633869}],"tv":122601.53}]}
{"op":"mcm","clk":"4230876643","pt":1631537476522,"mc":[{"id":"1.187557995","rc":[{"batl":[[0,1.77,541.17],[1,1.78,1074.44],[2,1.79,1247.07]],"ltp":1.78,"tv":110603.94,"id":9342449},{"batb":[[0,2.28,87.91],[1,2.18,766.73],[2,2.16,29.03]],"ltp":2.28,"tv":11997.59,"id":9633869}]}]}
{"op":"mcm","clk":"4230876741","pt":1631537477662,"mc":[{"id":"1.187557995","rc":[{"batb":[[2,1.7,71.71]],"ltp":1.78,"tv":110603.94,"id":9342449},{"batb":[[0,2.36,80.58],[1,2.28,87.91],[2,2.2,216.89]],"batl":[[1,2.42,12.58],[2,2.46,8.13]],"ltp":2.28,"tv":11997.59,"id":9633869}]}]}
{"op":"mcm","clk":"4230876747","pt":1631537477768,"mc":[{"id":"1.187557995","rc":[{"batb":[[2,2.2,219.89]],"ltp":2.28,"tv":11997.59,"id":9633869}]}]}
{"op":"mcm","clk":"4230876906","pt":1631537479660,"mc":[{"id":"1.187557995","rc":[{"batb":[[2,2.26,4]],"ltp":2.28,"tv":11997.59,"id":9633869}]}]}
{"op":"mcm","clk":"4230876994","pt":1631537480647,"mc":[{"id":"1.187557995","rc":[{"trd":[[1.74,2055.36]],"batb":[[0,1.74,82.43],[1,1.73,128.13],[2,1.71,199.91]],"batl":[[0,1.76,169.49],[1,1.77,541.17],[2,1.78,1074.44]],"ltp":1.74,"tv":110713.17,"id":9342449},{"trd":[[2.36,182.69]],"batb":[[0,2.28,87.91],[1,2.26,4],[2,2.24,3]],"ltp":2.36,"tv":12078.17,"id":9633869}],"tv":122791.34}]}
{"op":"mcm","clk":"4230877036","pt":1631537481166,"mc":[{"id":"1.187557995","rc":[{"batb":[[1,1.73,208.91]],"batl":[[1,1.77,605.82]],"ltp":1.74,"tv":110713.17,"id":9342449}]}]}
{"op":"mcm","clk":"4230877266","pt":1631537484325,"mc":[{"id":"1.187557995","rc":[{"batl":[[0,1.76,309.49]],"ltp":1.74,"tv":110713.17,"id":9342449},{"batb":[[0,2.3,30.45],[1,2.28,87.91],[2,2.26,4]],"ltp":2.36,"tv":12078.17,"id":9633869}]}]}
{"op":"mcm","clk":"4230877486","pt":1631537486665,"mc":[{"id":"1.187557995","rc":[{"batb":[[0,1.74,66.74],[1,1.73,80.78],[2,1.7,71.71]],"batl":[[0,1.76,210.24],[1,1.77,64.65],[2,1.79,400]],"ltp":1.74,"tv":110713.17,"id":9342449},{"batb":[[0,2.26,4],[1,2.24,3],[2,2.2,151.24]],"batl":[[0,2.42,12.58],[1,2.6,88.25],[2,2.62,106.06]],"ltp":2.36,"tv":12078.17,"id":9633869}]}]}
{"op":"mcm","clk":"4230877567","pt":1631537487648,"mc":[{"id":"1.187557995","rc":[{"batb":[[1,1.62,109.02],[2,1.61,134.26]],"batl":[[0,1.76,70.24],[1,1.8,2.32],[2,1.82,317.25]],"ltp":1.74,"tv":110713.17,"id":9342449},{"batb":[[0,2.2,98.24],[1,2.18,4],[2,2.16,29.03]],"batl":[[0,2.6,88.25],[1,2.62,106.06],[2,2.64,92.29]],"ltp":2.36,"tv":12078.17,"id":9633869}]}]}
{"op":"mcm","clk":"4230877618","pt":1631537488164,"mc":[{"id":"1.187557995","rc":[{"batb":[[1,1.63,246.17],[2,1.62,109.02]],"batl":[[2,1.86,287.75]],"ltp":1.74,"tv":110713.17,"id":9342449}]}]}
{"op":"mcm","clk":"4230877772","pt":1631537489687,"mc":[{"id":"1.187557995","rc":[{"batb":[[0,1.63,246.17],[1,1.62,109.02],[2,1.61,134.26]],"batl":[[0,1.8,2.32],[1,1.86,287.75],[2,1.87,255.95]],"ltp":1.74,"tv":110713.17,"id":9342449},{"batb":[[0,2.2,26.17],[1,2.18,104.58]],"ltp":2.36,"tv":12078.17,"id":9633869}]}]}
{"op":"mcm","clk":"4230877862","pt":1631537490564,"mc":[{"id":"1.187557995","rc":[{"batl":[[1,2,80],[2,2.08,1]],"ltp":1.74,"tv":110713.17,"id":9342449},{"batb":[[0,2.18,104.58],[1,2.16,29.03],[2,2,8.68]],"ltp":2.36,"tv":12078.17,"id":9633869}]}]}
{"op":"mcm","clk":"4230878072","pt":1631537492688,"mc":[{"id":"1.187557995","rc":[{"batb":[[0,1.62,109.02],[1,1.61,134.26],[2,1.6,406.64]],"batl":[[0,1.65,1891.48],[1,1.8,2.32],[2,2,80]],"ltp":1.74,"tv":110713.17,"id":9342449}]}]}
{"op":"mcm","clk":"4230878131","pt":1631537493259,"mc":[{"id":"1.187557995","rc":[{"trd":[[1.66,691.73]],"batb":[[0,1.61,129.58],[1,1.6,406.64],[2,1.59,159.16]],"batl":[[0,1.71,11.7]],"ltp":1.66,"tv":110717.45,"id":9342449},{"trd":[[2.52,81.9]],"batb":[[0,2.52,1509.78],[1,2.5,1473.22],[2,2.48,1473.22]],"batl":[[0,2.64,87.61],[1,2.7,4.15],[2,2.74,1395.98]],"ltp":2.52,"tv":12091.51,"id":9633869}],"tv":122808.96}]}
{"op":"mcm","clk":"4230878281","pt":1631537494656,"mc":[{"id":"1.187557995","rc":[{"batl":[[0,1.65,208.69],[1,1.66,131.69],[2,1.67,374.5]],"ltp":1.66,"tv":110717.45,"id":9342449},{"trd":[[2.52,82.24]],"batb":[[0,2.62,60.67],[1,2.52,758.77],[2,2.5,736.6]],"batl":[[1,2.68,7.46],[2,2.7,4.15]],"ltp":2.52,"tv":12091.85,"id":9633869}],"tv":122809.3}]}
{"op":"mcm","clk":"4230878390","pt":1631537495643,"mc":[{"id":"1.187557995","rc":[{"batb":[[1,1.6,484.09]],"ltp":1.66,"tv":110717.45,"id":9342449},{"batl":[[1,2.66,11.64],[2,2.68,7.46]],"ltp":2.52,"tv":12091.85,"id":9633869}]}]}
{"op":"mcm","clk":"4230878559","pt":1631537497659,"mc":[{"id":"1.187557995","rc":[{"trd":[[1.62,281.88]],"batb":[[0,1.62,9.87],[1,1.61,129.58],[2,1.6,484.09]],"batl":[[0,1.64,77.86],[1,1.65,208.69],[2,1.66,131.69]],"ltp":1.62,"tv":110774.36,"id":9342449},{"trd":[[2.62,167.62]],"batb":[[0,2.52,758.77],[1,2.5,736.6],[2,2.48,820.36]],"ltp":2.62,"tv":12177.97,"id":9633869}],"tv":122952.33}]}
{"op":"mcm","clk":"4230878635","pt":1631537498599,"mc":[{"id":"1.187557995","rc":[{"batb":[[0,1.62,127.93],[1,1.61,191.63]],"batl":[[0,1.64,229.58],[1,1.65,272.24]],"ltp":1.62,"tv":110774.36,"id":9342449}]}]}
{"op":"mcm","clk":"4230878703","pt":1631537499365,"mc":[{"id":"1.187557995","rc":[{"trd":[[1.62,537.74]],"batb":[[0,1.61,191.63],[1,1.6,484.09],[2,1.59,159.16]],"batl":[[0,1.62,59.07],[1,1.64,229.58],[2,1.65,272.24]],"ltp":1.62,"tv":111030.22,"id":9342449}],"tv":123208.19}]}
{"op":"mcm","clk":"4230878815","pt":1631537500666,"mc":[{"id":"1.187557995","rc":[{"batl":[[2,2.68,42.38]],"ltp":2.62,"tv":12177.97,"id":9633869}]}]}
{"op":"mcm","clk":"4230878869","pt":1631537501289,"mc":[{"id":"1.187557995","rc":[{"batb":[[0,2.54,28.43],[1,2.52,758.77],[2,2.5,736.6]],"ltp":2.62,"tv":12177.97,"id":9633869}]}]}
{"op":"mcm","clk":"4230878959","pt":1631537502571,"mc":[{"id":"1.187557995","rc":[{"batb":[[0,1.61,298.31]],"batl":[[1,1.63,105.37],[2,1.64,229.58]],"ltp":1.62,"tv":111030.22,"id":9342449},{"batl":[[0,2.64,87.77]],"ltp":2.62,"tv":12177.97,"id":9633869}]}]}
{"op":"mcm","clk":"4230879135","pt":1631537504689,"mc":[{"id":"1.187557995","rc":[{"batl":[[0,1.62,324.72]],"ltp":1.62,"tv":111030.22,"id":9342449}]}]}
{"op":"mcm","clk":"4230879215","pt":1631537505572,"mc":[{"id":"1.187557995","rc":[{"batb":[[0,1.61,168.72]],"batl":[[2,1.64,151.72]],"ltp":1.62,"tv":111030.22,"id":9342449},{"batb":[[1,2.48,83.76],[2,2.44,41.66]],"batl":[[0,2.66,11.79],[1,2.68,34.92],[2,2.7,4.15]],"ltp":2.62,"tv":12177.97,"id":9633869}]}]}
{"op":"mcm","clk":"4230879318","pt":1631537506663,"mc":[{"id":"1.187557995","rc":[{"batb":[[0,1.6,77.45],[1,1.51,235.09],[2,1.5,116.37]],"batl":[[0,1.62,187],[1,1.72,217.21],[2,1.74,285.25]],"ltp":1.62,"tv":111030.22,"id":9342449},{"batb":[[0,2.38,78.41],[1,2.34,25.72],[2,2.32,106.04]],"batl":[[0,2.66,11.64],[2,2.98,72.34]],"ltp":2.62,"tv":12177.97,"id":9633869}]}]}
{"op":"mcm","clk":"4230879403","pt":1631537507601,"mc":[{"id":"1.187557995","rc":[{"batb":[[0,1.51,453.15],[1,1.5,116.37],[2,1.49,182.38]],"batl":[[0,1.62,104.43]],"ltp":1.62,"tv":111030.22,"id":9342449},{"batl":[[0,2.98,72.34],[1,3,82.64],[2,3.05,83.84]],"ltp":2.62,"tv":12177.97,"id":9633869}]}]}
{"op":"mcm","clk":"4230879447","pt":1631537508009,"mc":[{"id":"1.187557995","rc":[{"batl":[[0,1.72,217.21],[1,1.74,285.25],[2,1.75,119.5]],"ltp":1.62,"tv":111030.22,"id":9342449}]}]}
{"op":"mcm","clk":"4230879595","pt":1631537509615,"mc":[{"id":"1.187557995","rc":[{"batb":[[2,1.49,417.51]],"ltp":1.62,"tv":111030.22,"id":9342449},{"batb":[[0,2.36,79.91]],"ltp":2.62,"tv":12177.97,"id":9633869}]}]}
{"op":"mcm","clk":"4230879837","pt":1631537512207,"mc":[{"id":"1.187557995","rc":[{"batb":[[1,1.45,185.02],[2,1.38,454.63]],"ltp":1.62,"tv":111030.22,"id":9342449},{"batl":[[0,990,0.01],[1,3,0],[2,3.05,0]],"ltp":2.62,"tv":12177.97,"id":9633869}]}]}
{"op":"mcm","clk":"4230879975","pt":1631537513615,"mc":[{"id":"1.187557995","rc":[{"batb":[[0,1.45,185.02],[1,1.21,20],[2,1.2,100]],"batl":[[0,1.74,285.25],[1,1.75,119.5],[2,1.76,332.78]],"ltp":1.62,"tv":111030.22,"id":9342449}]}]}
{"op":"mcm","clk":"4230880065","pt":1631537514709,"mc":[{"id":"1.187557995","rc":[{"batl":[[0,1.75,119.5],[1,1.76,332.78],[2,1.77,182.11]],"ltp":1.62,"tv":111030.22,"id":9342449},{"batb":[[1,2.32,106.04],[2,2.3,96.02]],"ltp":2.62,"tv":12177.97,"id":9633869}]}]}
{"op":"mcm","clk":"4230880141","pt":1631537515491,"mc":[{"id":"1.187557995","rc":[{"batb":[[0,1.7,234.42],[1,1.69,123.09],[2,1.45,185.02]],"ltp":1.62,"tv":111030.22,"id":9342449},{"batl":[[0,2.46,777.44],[1,2.48,762.62],[2,2.5,754.56]],"ltp":2.62,"tv":12177.97,"id":9633869}]}]}
