{"op":"mcm","clk":"4210813258","pt":1631463863807,"mc":[{"id":"1.187557985","marketDefinition":{"bspMarket":false,"turnInPlayEnabled":true,"persistenceEnabled":true,"marketBaseRate":5.0,"eventId":"30896136","eventTypeId":"2","numberOfWinners":1,"bettingType":"ODDS","marketType":"MATCH_ODDS","marketTime":"2021-09-13T10:30:00.000Z","suspendTime":"2021-09-13T10:30:00.000Z","bspReconciled":false,"complete":true,"inPlay":false,"crossMatching":false,"runnersVoidable":false,"numberOfActiveRunners":2,"betDelay":0,"status":"OPEN","runners":[{"status":"ACTIVE","sortPriority":1,"id":5300820,"name":"Aleksandra Krunic"},{"status":"ACTIVE","sortPriority":2,"id":9629022,"name":"Susan Bandecchi"}],"regulators":["MR_INT"],"discountAllowed":false,"timezone":"UTC","openDate":"2021-09-13T10:30:00.000Z","version":4029094104,"name":"Match Odds","eventName":"Krunic v Bandecchi"},"rc":[{"batb":[[0,1.02,3615.07],[1,1.01,3615.07]],"ltp":0.0,"tv":0.0,"id":5300820},{"batb":[[0,1.02,3615.07],[1,1.01,3615.07]],"ltp":0.0,"tv":0.0,"id":9629022}]}]}
{"op":"mcm","clk":"4210813461","pt":1631463865691,"mc":[{"id":"1.187557985","marketDefinition":{"bspMarket":false,"turnInPlayEnabled":true,"persistenceEnabled":true,"marketBaseRate":5.0,"eventId":"30896136","eventTypeId":"2","numberOfWinners":1,"bettingType":"ODDS","marketType":"MATCH_ODDS","marketTime":"2021-09-13T10:30:00.000Z","suspendTime":"2021-09-13T10:30:00.000Z","bspReconciled":false,"complete":true,"inPlay":false,"crossMatching":false,"runnersVoidable":false,"numberOfActiveRunners":2,"betDelay":0,"status":"OPEN","runners":[{"status":"ACTIVE","sortPriority":1,"id":5300820,"name":"Aleksandra Krunic"},{"status":"ACTIVE","sortPriority":2,"id":9629022,"name":"Susan Bandecchi"}],"regulators":["MR_INT"],"discountAllowed":true,"timezone":"UTC","openDate":"2021-09-13T10:30:00.000Z","version":4029094104,"name":"Match Odds","eventName":"Krunic v Bandecchi"}}]}
{"op":"mcm","clk":"4210820559","pt":1631463919783,"mc":[{"id":"1.187557985","rc":[{"batb":[[1,1.01,3640.07]],"ltp":0.0,"tv":0.0,"id":5300820},{"batb":[[1,1.01,3640.07]],"ltp":0.0,"tv":0.0,"id":9629022}]}]}
{"op":"mcm","clk":"4211136913","pt":1631466467370,"mc":[{"id":"1.187557985","rc":[{"batb":[[0,1.32,66.7],[1,1.02,3615.07],[2,1.01,3640.07]],"ltp":0.0,"tv":0.0,"id":5300820},{"batb":[[0,1.98,38.19],[1,1.02,3615.07],[2,1.01,3640.07]],"ltp":0.0,"tv":0.0,"id":9629022}]}]}
{"op":"mcm","clk":"4211172485","pt":1631466735628,"mc":[{"id":"1.187557985","rc":[{"batl":[[0,990,2.2]],"ltp":0.0,"tv":0.0,"id":5300820},{"batl":[[0,990,2.2]],"ltp":0.0,"tv":0.0,"id":9629022}]}]}
{"op":"mcm","clk":"4211173306","pt":1631466741635,"mc":[{"id":"1.187557985","marketDefinition":{"bspMarket":false,"turnInPlayEnabled":true,"persistenceEnabled":true,"marketBaseRate":5.0,"eventId":"30896136","eventTypeId":"2","numberOfWinners":1,"bettingType":"ODDS","marketType":"MATCH_ODDS","marketTime":"2021-09-13T10:30:00.000Z","suspendTime":"2021-09-13T10:30:00.000Z","bspReconciled":false,"complete":true,"inPlay":false,"crossMatching":true,"runnersVoidable":false,"numberOfActiveRunners":2,"betDelay":0,"status":"OPEN","runners":[{"status":"ACTIVE","sortPriority":1,"id":5300820,"name":"Aleksandra Krunic"},{"status":"ACTIVE","sortPriority":2,"id":9629022,"name":"Susan Bandecchi"}],"regulators":["MR_INT"],"discountAllowed":true,"timezone":"UTC","openDate":"2021-09-13T10:30:00.000Z","version":4029094104,"name":"Match Odds","eventName":"Krunic v Bandecchi"}}]}
{"op":"mcm","clk":"4211197326","pt":1631466937429,"mc":[{"id":"1.187557985","rc":[{"batb":[[2,1.01,3734.01]],"ltp":0.0,"tv":0.0,"id":5300820},{"batb":[[2,1.01,3734.01]],"ltp":0.0,"tv":0.0,"id":9629022}]}]}
{"op":"mcm","clk":"4211228546","pt":1631467202425,"mc":[{"id":"1.187557985","rc":[{"batb":[[0,1.43,61.5]],"ltp":0.0,"tv":0.0,"id":5300820},{"batb":[[0,1.96,38.59]],"ltp":0.0,"tv":0.0,"id":9629022}]}]}
{"op":"mcm","clk":"4211331163","pt":1631468224807,"mc":[{"id":"1.187557985","rc":[{"batb":[[0,1.5,45.09],[1,1.43,61.5],[2,1.02,3615.07]],"ltp":0.0,"tv":0.0,"id":5300820},{"batb":[[0,2.62,13.91],[1,1.96,38.59],[2,1.02,3615.07]],"ltp":0.0,"tv":0.0,"id":9629022}]}]}
{"op":"mcm","clk":"4211344215","pt":1631468369006,"mc":[{"id":"1.187557985","rc":[{"batb":[[1,1.02,3615.07],[2,1.01,3734.01]],"ltp":0.0,"tv":0.0,"id":5300820},{"batb":[[0,2.64,30.34],[1,2.62,13.91]],"ltp":0.0,"tv":0.0,"id":9629022}]}]}
{"op":"mcm","clk":"4211352734","pt":1631468457313,"mc":[{"id":"1.187557985","rc":[{"batb":[[0,1.44,116.61]],"ltp":0.0,"tv":0.0,"id":5300820},{"batb":[[0,2.74,12.95],[1,2.64,30.34]],"ltp":0.0,"tv":0.0,"id":9629022}]}]}
{"op":"mcm","clk":"4211373065","pt":1631468702624,"mc":[{"id":"1.187557985","rc":[{"batb":[[1,1.02,3615.07],[2,1.01,3734.01]],"ltp":0.0,"tv":0.0,"id":9629022}]}]}
{"op":"mcm","clk":"4211374875","pt":1631468724565,"mc":[{"id":"1.187557985","rc":[{"batl":[[0,17.5,3.42],[1,990,2.2]],"ltp":0.0,"tv":0.0,"id":9629022}]}]}
{"op":"mcm","clk":"4211374903","pt":1631468724736,"mc":[{"id":"1.187557985","rc":[{"batl":[[0,9.2,3.42],[1,990,2.2]],"ltp":0.0,"tv":0.0,"id":5300820}]}]}
{"op":"mcm","clk":"4211430331","pt":1631469566949,"mc":[{"id":"1.187557985","rc":[{"batb":[[0,1.44,116.58]],"ltp":0.0,"tv":0.0,"id":5300820}]}]}
{"op":"mcm","clk":"4211728377","pt":1631472852906,"mc":[{"id":"1.187557985","rc":[{"batb":[[2,1.01,4206.86]],"ltp":0.0,"tv":0.0,"id":5300820},{"batb":[[2,1.01,4206.86]],"ltp":0.0,"tv":0.0,"id":9629022}]}]}
{"op":"mcm","clk":"4211877632","pt":1631474228426,"mc":[{"id":"1.187557985","rc":[{"batb":[[1,1.13,27.81],[2,1.02,3615.07]],"ltp":0.0,"tv":0.0,"id":5300820}]}]}
{"op":"mcm","clk":"4212162156","pt":1631476760603,"mc":[{"id":"1.187557985","rc":[{"batb":[[0,1.44,51.24]],"ltp":0.0,"tv":0.0,"id":5300820}]}]}
{"op":"mcm","clk":"4212162176","pt":1631476760807,"mc":[{"id":"1.187557985","rc":[{"batb":[[0,1.44,182]],"ltp":0.0,"tv":0.0,"id":5300820}]}]}
{"op":"mcm","clk":"4212205697","pt":1631477172264,"mc":[{"id":"1.187557985","rc":[{"batl":[[0,9.2,3.42]],"ltp":0.0,"tv":0.0,"id":5300820},{"batb":[[2,1.01,4211.83]],"batl":[[0,17.5,3.42]],"ltp":0.0,"tv":0.0,"id":9629022}]}]}
{"op":"mcm","clk":"4212250669","pt":1631477569127,"mc":[{"id":"1.187557985","rc":[{"trd":[[2.74,4]],"batb":[[0,2.74,10.95]],"ltp":2.74,"tv":4.0,"id":9629022}],"tv":4.0}]}
{"op":"mcm","clk":"4212251124","pt":1631477573056,"mc":[{"id":"1.187557985","rc":[{"batb":[[0,2.74,12.95]],"ltp":2.74,"tv":4.0,"id":9629022}]}]}
{"op":"mcm","clk":"4212252887","pt":1631477587571,"mc":[{"id":"1.187557985","rc":[{"batb":[[1,1.37,4],[2,1.02,3615.07]],"ltp":2.74,"tv":4.0,"id":9629022}]}]}
{"op":"mcm","clk":"4212274148","pt":1631477760100,"mc":[{"id":"1.187557985","rc":[{"batb":[[0,1.44,51.24]],"ltp":0.0,"tv":0.0,"id":5300820}]}]}
{"op":"mcm","clk":"4212274907","pt":1631477764889,"mc":[{"id":"1.187557985","rc":[{"batb":[[0,1.44,214.6]],"ltp":0.0,"tv":0.0,"id":5300820}]}]}
{"op":"mcm","clk":"4212559868","pt":1631481007188,"mc":[{"id":"1.187557985","rc":[{"batb":[[0,1.44,459.55]],"ltp":0.0,"tv":0.0,"id":5300820}]}]}
{"op":"mcm","clk":"4212650355","pt":1631482332371,"mc":[{"id":"1.187557985","rc":[{"batb":[[0,1.45,96.21],[1,1.44,459.55],[2,1.13,27.81]],"batl":[[0,1.95,481.57],[1,9.2,3.42],[2,990,2.2]],"ltp":0.0,"tv":0.0,"id":5300820},{"batb":[[0,2.8,74.17],[1,2.74,12.95],[2,1.37,4]],"ltp":2.74,"tv":4.0,"id":9629022}]}]}
{"op":"mcm","clk":"4212651975","pt":1631482358384,"mc":[{"id":"1.187557985","rc":[{"batb":[[1,1.44,51.24]],"batl":[[1,990,2.2],[2,990,0]],"ltp":0.0,"tv":0.0,"id":5300820}]}]}
{"op":"mcm","clk":"4212717747","pt":1631483408917,"mc":[{"id":"1.187557985","rc":[{"batl":[[0,1.55,853.75]],"ltp":0.0,"tv":0.0,"id":5300820}]}]}
{"op":"mcm","clk":"4212717932","pt":1631483412430,"mc":[{"id":"1.187557985","rc":[{"batl":[[1,1.56,853.75],[2,990,2.2]],"ltp":0.0,"tv":0.0,"id":5300820}]}]}
{"op":"mcm","clk":"4212718128","pt":1631483416404,"mc":[{"id":"1.187557985","rc":[{"batl":[[2,1.57,853.75]],"ltp":0.0,"tv":0.0,"id":5300820}]}]}
{"op":"mcm","clk":"4212816521","pt":1631485065720,"mc":[{"id":"1.187557985","rc":[{"batb":[[0,1.45,96.23],[2,1.13,27.8]],"batl":[[0,1.55,853.9],[1,1.56,853.9],[2,1.57,853.9]],"ltp":0.0,"tv":0.0,"id":5300820},{"batb":[[0,2.8,74.19]],"ltp":2.74,"tv":4.0,"id":9629022}]}]}
{"op":"mcm","clk":"4212864030","pt":1631485808230,"mc":[{"id":"1.187557985","rc":[{"batb":[[0,2.8,77.77]],"ltp":2.74,"tv":4.0,"id":9629022}]}]}
{"op":"mcm","clk":"4212941683","pt":1631487177213,"mc":[{"id":"1.187557985","rc":[{"batb":[[2,1.14,51.63]],"ltp":0.0,"tv":0.0,"id":5300820}]}]}
{"op":"mcm","clk":"4213083340","pt":1631490465668,"mc":[{"id":"1.187557985","rc":[{"batb":[[0,1.45,96.21],[2,1.14,51.63]],"batl":[[0,1.55,853.75],[1,1.56,853.75],[2,1.57,853.75]],"ltp":0.0,"tv":0.0,"id":5300820},{"batb":[[0,2.8,77.75]],"ltp":2.74,"tv":4.0,"id":9629022}]}]}
{"op":"mcm","clk":"4213230069","pt":1631495865679,"mc":[{"id":"1.187557985","rc":[{"batb":[[0,1.45,96.16],[2,1.14,51.63]],"batl":[[0,1.55,853.32],[1,1.56,853.32],[2,1.57,853.32]],"ltp":0.0,"tv":0.0,"id":5300820},{"batb":[[0,2.8,77.72]],"batl":[[0,17.5,3.41]],"ltp":2.74,"tv":4.0,"id":9629022}]}]}
{"op":"mcm","clk":"4213539538","pt":1631506665672,"mc":[{"id":"1.187557985","rc":[{"batb":[[0,1.45,96.14],[2,1.14,51.62]],"batl":[[0,1.55,853.1],[1,1.56,853.1],[2,1.57,853.1]],"ltp":0.0,"tv":0.0,"id":5300820},{"batb":[[0,2.8,77.7]],"ltp":2.74,"tv":4.0,"id":9629022}]}]}
{"op":"mcm","clk":"4213562519","pt":1631507401273,"mc":[{"id":"1.187557985","rc":[{"batb":[[1,1.44,76.86]],"ltp":0.0,"tv":0.0,"id":5300820},{"batb":[[1,2.74,19.43]],"ltp":2.74,"tv":4.0,"id":9629022}]}]}
{"op":"mcm","clk":"4213563969","pt":1631507465063,"mc":[{"id":"1.187557985","rc":[{"batb":[[0,1.45,861.86]],"ltp":0.0,"tv":0.0,"id":5300820}]}]}
{"op":"mcm","clk":"4213564005","pt":1631507465886,"mc":[{"id":"1.187557985","rc":[{"batb":[[0,1.45,96.14]],"ltp":0.0,"tv":0.0,"id":5300820}]}]}
{"op":"mcm","clk":"4213608651","pt":1631508851223,"mc":[{"id":"1.187557985","rc":[{"batb":[[2,1.18,98.33]],"ltp":0.0,"tv":0.0,"id":5300820}]}]}
{"op":"mcm","clk":"4213621473","pt":1631509291281,"mc":[{"id":"1.187557985","rc":[{"batb":[[0,1.45,96.14],[2,1.18,98.42]],"batl":[[0,1.55,853.17],[1,1.56,853.17],[2,1.57,853.17]],"ltp":0.0,"tv":0.0,"id":5300820},{"batb":[[0,2.8,77.7]],"ltp":2.74,"tv":4.0,"id":9629022}]}]}
{"op":"mcm","clk":"4213652486","pt":1631510440217,"mc":[{"id":"1.187557985","rc":[{"batl":[[0,7.8,2.57],[1,17.5,3.41],[2,29,48.39]],"ltp":2.74,"tv":4.0,"id":9629022}]}]}
{"op":"mcm","clk":"4213653481","pt":1631510465534,"mc":[{"id":"1.187557985","rc":[{"batl":[[1,29,48.39],[2,990,2.2]],"ltp":2.74,"tv":4.0,"id":9629022}]}]}
{"op":"mcm","clk":"4213663819","pt":1631510739943,"mc":[{"id":"1.187557985","rc":[{"batl":[[0,29,48.39],[1,990,2.2],[2,990,0]],"ltp":2.74,"tv":4.0,"id":9629022}]}]}
{"op":"mcm","clk":"4213664440","pt":1631510756672,"mc":[{"id":"1.187557985","rc":[{"batl":[[0,1.54,4.06],[1,1.55,853.17],[2,1.56,853.17]],"ltp":0.0,"tv":0.0,"id":5300820}]}]}
{"op":"mcm","clk":"4213745164","pt":1631513069630,"mc":[{"id":"1.187557985","rc":[{"batl":[[0,1.5,14.47],[1,1.54,4.06],[2,1.55,853.17]],"ltp":0.0,"tv":0.0,"id":5300820},{"batb":[[2,1.8,24.36]],"ltp":2.74,"tv":4.0,"id":9629022}]}]}
{"op":"mcm","clk":"4213753553","pt":1631513282756,"mc":[{"id":"1.187557985","rc":[{"batb":[[0,1.45,100.41]],"ltp":0.0,"tv":0.0,"id":5300820}]}]}
{"op":"mcm","clk":"4213762535","pt":1631513604189,"mc":[{"id":"1.187557985","rc":[{"batl":[[0,1.54,4.06],[1,1.55,853.17],[2,1.56,853.17]],"ltp":0.0,"tv":0.0,"id":5300820}]}]}
{"op":"mcm","clk":"4213762874","pt":1631513620509,"mc":[{"id":"1.187557985","rc":[{"trd":[[1.45,28.94]],"batb":[[0,1.45,85.94]],"ltp":1.45,"tv":28.93,"id":5300820},{"batb":[[0,2.82,74.44],[1,2.8,3.58],[2,2.74,19.43]],"ltp":2.74,"tv":4.0,"id":9629022}],"tv":32.93}]}
{"op":"mcm","clk":"4213763048","pt":1631513627461,"mc":[{"id":"1.187557985","rc":[{"batb":[[1,2.74,19.43],[2,1.8,24.36]],"ltp":2.74,"tv":4.0,"id":9629022}]}]}
{"op":"mcm","clk":"4213763180","pt":1631513634088,"mc":[{"id":"1.187557985","rc":[{"batb":[[0,2.82,78]],"ltp":2.74,"tv":4.0,"id":9629022}]}]}
{"op":"mcm","clk":"4213801290","pt":1631514662991,"mc":[{"id":"1.187557985","rc":[{"batb":[[2,1.2,219.96]],"ltp":1.45,"tv":28.93,"id":5300820}]}]}
{"op":"mcm","clk":"4213802861","pt":1631514698228,"mc":[{"id":"1.187557985","rc":[{"trd":[[1.54,8.13]],"batl":[[0,1.55,853.17],[1,1.56,853.17],[2,1.57,853.17]],"ltp":1.54,"tv":37.06,"id":5300820}],"tv":41.06}]}
{"op":"mcm","clk":"4213802896","pt":1631514699251,"mc":[{"id":"1.187557985","rc":[{"trd":[[1.55,41.96]],"batl":[[0,1.55,832.19]],"ltp":1.55,"tv":79.02,"id":5300820}],"tv":83.02}]}
{"op":"mcm","clk":"4213879780","pt":1631516631606,"mc":[{"id":"1.187557985","rc":[{"trd":[[1.45,28.96],[1.54,8.13],[1.55,41.97]],"batb":[[0,1.47,189.44],[1,1.45,85.95],[2,1.44,76.86]],"batl":[[0,1.55,832.33],[1,1.56,853.32],[2,1.57,853.32]],"ltp":1.55,"tv":79.05,"id":5300820},{"batb":[[0,2.82,78.01],[2,1.8,24.4]],"batl":[[0,8,5.74],[1,29,48.45],[2,990,2.2]],"ltp":2.74,"tv":4.0,"id":9629022}],"tv":83.05}]}
{"op":"mcm","clk":"4213879806","pt":1631516631916,"mc":[{"id":"1.187557985","rc":[{"batl":[[0,5.9,3.89]],"ltp":2.74,"tv":4.0,"id":9629022}]}]}
{"op":"mcm","clk":"4213880330","pt":1631516642341,"mc":[{"id":"1.187557985","rc":[{"batb":[[0,1.48,23.33],[1,1.47,189.44],[2,1.45,4.27]],"ltp":1.55,"tv":79.05,"id":5300820}]}]}
{"op":"mcm","clk":"4213891025","pt":1631516832098,"mc":[{"id":"1.187557985","rc":[{"trd":[[2.82,4]],"batb":[[0,2.82,76.01]],"ltp":2.82,"tv":7.99,"id":9629022}],"tv":87.05}]}
{"op":"mcm","clk":"4213896749","pt":1631516931788,"mc":[{"id":"1.187557985","rc":[{"batl":[[0,5.1,457.83]],"ltp":2.82,"tv":7.99,"id":9629022}]}]}
{"op":"mcm","clk":"4213916860","pt":1631517231609,"mc":[{"id":"1.187557985","rc":[{"batl":[[0,29,48.45],[1,990,2.2],[2,990,0]],"ltp":2.82,"tv":7.99,"id":9629022}]}]}
{"op":"mcm","clk":"4213916867","pt":1631517231713,"mc":[{"id":"1.187557985","rc":[{"batl":[[0,5,52.05],[1,29,48.45],[2,990,2.2]],"ltp":2.82,"tv":7.99,"id":9629022}]}]}
{"op":"mcm","clk":"4213961152","pt":1631517926851,"mc":[{"id":"1.187557985","rc":[{"batl":[[0,4.4,5.73]],"ltp":2.82,"tv":7.99,"id":9629022}]}]}
{"op":"mcm","clk":"4213977921","pt":1631518243131,"mc":[{"id":"1.187557985","rc":[{"trd":[[1.48,4]],"batb":[[0,1.48,21.33]],"ltp":1.48,"tv":83.05,"id":5300820}],"tv":91.04}]}
{"op":"mcm","clk":"4214091658","pt":1631520387960,"mc":[{"id":"1.187557985","rc":[{"batb":[[1,2.74,18]],"ltp":2.82,"tv":7.99,"id":9629022}]}]}
{"op":"mcm","clk":"4214101331","pt":1631520541501,"mc":[{"id":"1.187557985","rc":[{"batl":[[0,1.54,853.32],[1,1.55,832.33],[2,1.56,853.32]],"ltp":1.48,"tv":83.05,"id":5300820}]}]}
{"op":"mcm","clk":"4214106860","pt":1631520640469,"mc":[{"id":"1.187557985","rc":[{"batb":[[0,2.86,58.46],[1,2.82,3.56],[2,2.74,18]],"ltp":2.82,"tv":7.99,"id":9629022}]}]}
{"op":"mcm","clk":"4214143661","pt":1631521424665,"mc":[{"id":"1.187557985","rc":[{"batl":[[0,1.54,853.84]],"ltp":1.48,"tv":83.05,"id":5300820}]}]}
{"op":"mcm","clk":"4214143903","pt":1631521429089,"mc":[{"id":"1.187557985","rc":[{"batl":[[0,3.65,2.73],[1,4.4,5.73],[2,29,48.45]],"ltp":2.82,"tv":7.99,"id":9629022}]}]}
{"op":"mcm","clk":"4214148189","pt":1631521517407,"mc":[{"id":"1.187557985","rc":[{"batl":[[0,3.55,73.91],[1,3.65,2.73]],"ltp":2.82,"tv":7.99,"id":9629022}]}]}
{"op":"mcm","clk":"4214162449","pt":1631521802853,"mc":[{"id":"1.187557985","rc":[{"batb":[[2,2.74,24]],"ltp":2.82,"tv":7.99,"id":9629022}]}]}
{"op":"mcm","clk":"4214163008","pt":1631521812884,"mc":[{"id":"1.187557985","rc":[{"batb":[[1,2.74,24],[2,1.8,24.4]],"ltp":2.82,"tv":7.99,"id":9629022}]}]}
{"op":"mcm","clk":"4214168042","pt":1631521905881,"mc":[{"id":"1.187557985","rc":[{"batb":[[0,2.86,61.96]],"ltp":2.82,"tv":7.99,"id":9629022}]}]}
{"op":"mcm","clk":"4214194825","pt":1631522358696,"mc":[{"id":"1.187557985","rc":[{"batl":[[0,1.54,853.32]],"ltp":1.48,"tv":83.05,"id":5300820}]}]}
{"op":"mcm","clk":"4214201708","pt":1631522498130,"mc":[{"id":"1.187557985","rc":[{"batl":[[0,3.45,53.23],[1,3.55,73.91],[2,3.65,2.73]],"ltp":2.82,"tv":7.99,"id":9629022}]}]}
{"op":"mcm","clk":"4214205549","pt":1631522583325,"mc":[{"id":"1.187557985","rc":[{"batb":[[0,1.48,210.77],[1,1.45,4.27],[2,1.44,94.92]],"ltp":1.48,"tv":83.05,"id":5300820},{"batl":[[1,3.65,2.73],[2,29,48.45]],"ltp":2.82,"tv":7.99,"id":9629022}]}]}
{"op":"mcm","clk":"4214207785","pt":1631522639604,"mc":[{"id":"1.187557985","rc":[{"batb":[[0,1.48,189.44]],"ltp":1.48,"tv":83.05,"id":5300820}]}]}
{"op":"mcm","clk":"4214207791","pt":1631522639708,"mc":[{"id":"1.187557985","rc":[{"batb":[[1,1.45,89.44]],"ltp":1.48,"tv":83.05,"id":5300820}]}]}
{"op":"mcm","clk":"4214251894","pt":1631523368876,"mc":[{"id":"1.187557985","rc":[{"trd":[[1.48,5.67]],"batb":[[0,1.48,188.6]],"ltp":1.48,"tv":84.72,"id":5300820}],"tv":92.72}]}
{"op":"mcm","clk":"4214254443","pt":1631523408242,"mc":[{"id":"1.187557985","rc":[{"batb":[[2,1.44,100.92]],"ltp":1.48,"tv":84.72,"id":5300820}]}]}
{"op":"mcm","clk":"4214272924","pt":1631523690415,"mc":[{"id":"1.187557985","rc":[{"trd":[[1.45,28.95],[1.48,5.67],[1.54,8.13],[1.55,41.97]],"batb":[[0,1.48,188.63],[1,1.45,89.45]],"batl":[[0,1.54,853.46],[1,1.55,832.47],[2,1.56,853.46]],"ltp":1.48,"tv":84.72,"id":5300820},{"batb":[[0,2.86,61.97],[2,1.8,24.38]],"batl":[[0,3.45,53.28],[1,3.65,2.73],[2,29,48.42]],"ltp":2.82,"tv":7.99,"id":9629022}],"tv":92.72}]}
{"op":"mcm","clk":"4214283186","pt":1631523852331,"mc":[{"id":"1.187557985","rc":[{"batl":[[0,1.54,854.31]],"ltp":1.48,"tv":84.72,"id":5300820}]}]}
{"op":"mcm","clk":"4214312566","pt":1631524392582,"mc":[{"id":"1.187557985","rc":[{"batb":[[2,1.37,4]],"batl":[[0,3.45,152.81],[1,29,48.42],[2,990,2.2]],"ltp":2.82,"tv":7.99,"id":9629022}]}]}
{"op":"mcm","clk":"4214327374","pt":1631524616367,"mc":[{"id":"1.187557985","rc":[{"batl":[[0,1.54,857.76]],"ltp":1.48,"tv":84.72,"id":5300820}]}]}
{"op":"mcm","clk":"4214382857","pt":1631525400457,"mc":[{"id":"1.187557985","rc":[{"batb":[[1,1.46,55.66],[2,1.45,89.45]],"ltp":1.48,"tv":84.72,"id":5300820},{"batb":[[1,2.82,14.07],[2,2.74,24]],"ltp":2.82,"tv":7.99,"id":9629022}]}]}
{"op":"mcm","clk":"4214385310","pt":1631525437531,"mc":[{"id":"1.187557985","rc":[{"batb":[[1,1.47,43.63],[2,1.46,55.66]],"ltp":1.48,"tv":84.72,"id":5300820}]}]}
{"op":"mcm","clk":"4214385343","pt":1631525437997,"mc":[{"id":"1.187557985","rc":[{"batl":[[0,3.45,73.35]],"ltp":2.82,"tv":7.99,"id":9629022}]}]}
{"op":"mcm","clk":"4214405574","pt":1631525714700,"mc":[{"id":"1.187557985","rc":[{"trd":[[1.48,14.82]],"batb":[[0,1.48,184.06]],"ltp":1.48,"tv":93.87,"id":5300820}],"tv":101.87}]}
{"op":"mcm","clk":"4214507557","pt":1631526978484,"mc":[{"id":"1.187557985","rc":[{"trd":[[1.53,0.85]],"batl":[[0,1.54,856.9]],"ltp":1.53,"tv":94.73,"id":5300820},{"trd":[[2.86,2.51],[2.88,0.45]],"batb":[[0,2.86,60.72]],"ltp":2.86,"tv":10.95,"id":9629022}],"tv":105.68}]}
{"op":"mcm","clk":"4214602756","pt":1631528132140,"mc":[{"id":"1.187557985","rc":[{"batb":[[1,1.47,62.11]],"ltp":1.53,"tv":94.73,"id":5300820}]}]}
{"op":"mcm","clk":"4214607614","pt":1631528202559,"mc":[{"id":"1.187557985","rc":[{"trd":[[1.54,289.18]],"batl":[[0,1.54,575.85]],"ltp":1.54,"tv":375.78,"id":5300820},{"trd":[[2.84,152.4],[2.86,123.94]],"batb":[[0,2.82,14.07],[1,2.74,24],[2,1.43,3.41]],"ltp":2.84,"tv":284.78,"id":9629022}],"tv":660.57}]}
{"op":"mcm","clk":"4214607687","pt":1631528203592,"mc":[{"id":"1.187557985","rc":[{"batb":[[0,1.49,71.03],[1,1.48,184.06]],"ltp":1.54,"tv":375.78,"id":5300820},{"batb":[[0,2.86,34.26],[1,2.82,14.07],[2,2.74,24]],"batl":[[0,3.45,53.28]],"ltp":2.84,"tv":284.78,"id":9629022}]}]}
{"op":"mcm","clk":"4214621804","pt":1631528292660,"mc":[{"id":"1.187557985","rc":[{"batl":[[0,3.45,250.39]],"ltp":2.84,"tv":284.78,"id":9629022}]}]}
{"op":"mcm","clk":"4214625742","pt":1631528349939,"mc":[{"id":"1.187557985","rc":[{"batb":[[1,1.46,55.66],[2,1.45,4.27]],"ltp":1.54,"tv":375.78,"id":5300820}]}]}
{"op":"mcm","clk":"4214626905","pt":1631528367563,"mc":[{"id":"1.187557985","rc":[{"trd":[[1.49,142.05]],"batb":[[0,1.47,68.12]],"batl":[[0,1.49,195.36],[1,1.54,575.85],[2,1.55,832.47]],"ltp":1.49,"tv":517.83,"id":5300820},{"batb":[[0,2.86,75.69]],"batl":[[0,3.45,53.28]],"ltp":2.84,"tv":284.78,"id":9629022}],"tv":802.61}]}
{"op":"mcm","clk":"4214626936","pt":1631528368079,"mc":[{"id":"1.187557985","rc":[{"batb":[[1,1.45,4.27],[2,1.44,94.92]],"ltp":1.49,"tv":517.83,"id":5300820},{"batb":[[0,2.92,13.34],[1,2.86,75.69],[2,2.82,14.07]],"ltp":2.84,"tv":284.78,"id":9629022}]}]}
{"op":"mcm","clk":"4214626975","pt":1631528368855,"mc":[{"id":"1.187557985","rc":[{"trd":[[1.49,498.79]],"batl":[[0,1.49,16.99]],"ltp":1.49,"tv":874.57,"id":5300820}],"tv":1159.36}]}
{"op":"mcm","clk":"4214627049","pt":1631528370089,"mc":[{"id":"1.187557985","rc":[{"batb":[[0,2.86,75.69],[1,2.84,13.91]],"ltp":2.84,"tv":284.78,"id":9629022}]}]}
{"op":"mcm","clk":"4214629061","pt":1631528397521,"mc":[{"id":"1.187557985","rc":[{"batb":[[1,1.45,15.74]],"batl":[[0,1.48,16.99]],"ltp":1.49,"tv":874.57,"id":5300820}]}]}
{"op":"mcm","clk":"4214629483","pt":1631528402104,"mc":[{"id":"1.187557985","rc":[{"trd":[[1.47,33.98]],"batb":[[0,1.47,51.13],[1,1.45,72.64]],"batl":[[0,1.54,575.85],[1,1.55,832.47],[2,1.56,853.46]],"ltp":1.47,"tv":908.55,"id":5300820}],"tv":1193.34}]}
{"op":"mcm","clk":"4214632773","pt":1631528437191,"mc":[{"id":"1.187557985","rc":[{"batb":[[0,1.46,82.82]],"ltp":1.47,"tv":908.55,"id":5300820}]}]}
{"op":"mcm","clk":"4214633680","pt":1631528448263,"mc":[{"id":"1.187557985","rc":[{"batb":[[0,1.47,85.35],[1,1.46,82.82],[2,1.45,72.64]],"ltp":1.47,"tv":908.55,"id":5300820}]}]}
{"op":"mcm","clk":"4214653467","pt":1631528720177,"mc":[{"id":"1.187557985","rc":[{"trd":[[1.47,34.18]],"batb":[[0,1.47,85.24]],"ltp":1.47,"tv":908.75,"id":5300820}],"tv":1193.54}]}
{"op":"mcm","clk":"4214655975","pt":1631528751407,"mc":[{"id":"1.187557985","rc":[{"batb":[[0,1.48,31.97],[1,1.47,85.24],[2,1.46,138.48]],"ltp":1.47,"tv":908.75,"id":5300820}]}]}
{"op":"mcm","clk":"4214657077","pt":1631528765349,"mc":[{"id":"1.187557985","rc":[{"batb":[[0,1.49,31.97]],"ltp":1.47,"tv":908.75,"id":5300820}]}]}
{"op":"mcm","clk":"4214673311","pt":1631528995587,"mc":[{"id":"1.187557985","rc":[{"batl":[[0,1.54,577.85]],"ltp":1.47,"tv":908.75,"id":5300820},{"batb":[[1,2.82,14.07],[2,2.76,2.66]],"batl":[[0,3.05,2],[1,3.45,53.28],[2,29,48.42]],"ltp":2.84,"tv":284.78,"id":9629022}]}]}
{"op":"mcm","clk":"4214685776","pt":1631529213630,"mc":[{"id":"1.187557985","rc":[{"batb":[[1,1.47,87.24]],"ltp":1.47,"tv":908.75,"id":5300820}]}]}
{"op":"mcm","clk":"4214685949","pt":1631529216944,"mc":[{"id":"1.187557985","rc":[{"batb":[[1,1.47,88.24]],"ltp":1.47,"tv":908.75,"id":5300820}]}]}
{"op":"mcm","clk":"4214686262","pt":1631529222226,"mc":[{"id":"1.187557985","rc":[{"batb":[[1,1.47,86.24]],"ltp":1.47,"tv":908.75,"id":5300820}]}]}
{"op":"mcm","clk":"4214704660","pt":1631529510557,"mc":[{"id":"1.187557985","rc":[{"trd":[[1.54,293.18]],"batl":[[0,1.54,575.85]],"ltp":1.54,"tv":912.75,"id":5300820}],"tv":1197.54}]}
{"op":"mcm","clk":"4214708347","pt":1631529558620,"mc":[{"id":"1.187557985","marketDefinition":{"bspMarket":false,"turnInPlayEnabled":true,"persistenceEnabled":true,"marketBaseRate":5.0,"eventId":"30896136","eventTypeId":"2","numberOfWinners":1,"bettingType":"ODDS","marketType":"MATCH_ODDS","marketTime":"2021-09-13T10:40:00.000Z","suspendTime":"2021-09-13T10:40:00.000Z","bspReconciled":false,"complete":true,"inPlay":false,"crossMatching":true,"runnersVoidable":false,"numberOfActiveRunners":2,"betDelay":0,"status":"OPEN","runners":[{"status":"ACTIVE","sortPriority":1,"id":5300820,"name":"Aleksandra Krunic"},{"status":"ACTIVE","sortPriority":2,"id":9629022,"name":"Susan Bandecchi"}],"regulators":["MR_INT"],"discountAllowed":true,"timezone":"UTC","openDate":"2021-09-13T10:30:00.000Z","version":4030549566,"name":"Match Odds","eventName":"Krunic v Bandecchi"}}]}
{"op":"mcm","clk":"4214708627","pt":1631529561629,"mc":[{"id":"1.187557985","marketDefinition":{"bspMarket":false,"turnInPlayEnabled":true,"persistenceEnabled":true,"marketBaseRate":5.0,"eventId":"30896136","eventTypeId":"2","numberOfWinners":1,"bettingType":"ODDS","marketType":"MATCH_ODDS","marketTime":"2021-09-13T10:40:00.000Z","suspendTime":"2021-09-13T10:40:00.000Z","bspReconciled":false,"complete":true,"inPlay":false,"crossMatching":true,"runnersVoidable":false,"numberOfActiveRunners":2,"betDelay":0,"status":"OPEN","runners":[{"status":"ACTIVE","sortPriority":1,"id":5300820,"name":"Aleksandra Krunic"},{"status":"ACTIVE","sortPriority":2,"id":9629022,"name":"Susan Bandecchi"}],"regulators":["MR_INT"],"discountAllowed":true,"timezone":"UTC","openDate":"2021-09-13T10:40:00.000Z","version":4030549566,"name":"Match Odds","eventName":"Krunic v Bandecchi"}}]}
{"op":"mcm","clk":"4214717372","pt":1631529663567,"mc":[{"id":"1.187557985","rc":[{"batb":[[1,1.47,171.59]],"ltp":1.54,"tv":912.75,"id":5300820}]}]}
{"op":"mcm","clk":"4214729946","pt":1631529809706,"mc":[{"id":"1.187557985","rc":[{"batl":[[0,1.54,572.41]],"ltp":1.54,"tv":912.75,"id":5300820}]}]}
{"op":"mcm","clk":"4214730437","pt":1631529815112,"mc":[{"id":"1.187557985","rc":[{"batl":[[0,1.51,3.44],[1,1.54,572.41],[2,1.55,832.47]],"ltp":1.54,"tv":912.75,"id":5300820}]}]}
{"op":"mcm","clk":"4214730527","pt":1631529816098,"mc":[{"id":"1.187557985","rc":[{"batb":[[2,1.46,82.82]],"ltp":1.54,"tv":912.75,"id":5300820}]}]}
{"op":"mcm","clk":"4214733674","pt":1631529857116,"mc":[{"id":"1.187557985","marketDefinition":{"bspMarket":false,"turnInPlayEnabled":true,"persistenceEnabled":true,"marketBaseRate":5.0,"eventId":"30896136","eventTypeId":"2","numberOfWinners":1,"bettingType":"ODDS","marketType":"MATCH_ODDS","marketTime":"2021-09-13T10:50:00.000Z","suspendTime":"2021-09-13T10:50:00.000Z","bspReconciled":false,"complete":true,"inPlay":false,"crossMatching":true,"runnersVoidable":false,"numberOfActiveRunners":2,"betDelay":0,"status":"OPEN","runners":[{"status":"ACTIVE","sortPriority":1,"id":5300820,"name":"Aleksandra Krunic"},{"status":"ACTIVE","sortPriority":2,"id":9629022,"name":"Susan Bandecchi"}],"regulators":["MR_INT"],"discountAllowed":true,"timezone":"UTC","openDate":"2021-09-13T10:40:00.000Z","version":4030553195,"name":"Match Odds","eventName":"Krunic v Bandecchi"}}]}
{"op":"mcm","clk":"4214733900","pt":1631529860132,"mc":[{"id":"1.187557985","marketDefinition":{"bspMarket":false,"turnInPlayEnabled":true,"persistenceEnabled":true,"marketBaseRate":5.0,"eventId":"30896136","eventTypeId":"2","numberOfWinners":1,"bettingType":"ODDS","marketType":"MATCH_ODDS","marketTime":"2021-09-13T10:50:00.000Z","suspendTime":"2021-09-13T10:50:00.000Z","bspReconciled":false,"complete":true,"inPlay":false,"crossMatching":true,"runnersVoidable":false,"numberOfActiveRunners":2,"betDelay":0,"status":"OPEN","runners":[{"status":"ACTIVE","sortPriority":1,"id":5300820,"name":"Aleksandra Krunic"},{"status":"ACTIVE","sortPriority":2,"id":9629022,"name":"Susan Bandecchi"}],"regulators":["MR_INT"],"discountAllowed":true,"timezone":"UTC","openDate":"2021-09-13T10:50:00.000Z","version":4030553195,"name":"Match Odds","eventName":"Krunic v Bandecchi"}}]}
{"op":"mcm","clk":"4214749800","pt":1631530081114,"mc":[{"id":"1.187557985","rc":[{"batb":[[0,1.5,25],[1,1.49,31.97],[2,1.47,171.59]],"ltp":1.54,"tv":912.75,"id":5300820}]}]}
{"op":"mcm","clk":"4214750056","pt":1631530086072,"mc":[{"id":"1.187557985","rc":[{"batb":[[2,1.48,29.84]],"ltp":1.54,"tv":912.75,"id":5300820}]}]}
{"op":"mcm","clk":"4214759885","pt":1631530272414,"mc":[{"id":"1.187557985","rc":[{"trd":[[1.49,498.81],[1.5,50.01]],"batb":[[0,1.49,31.96],[1,1.48,29.84],[2,1.47,171.59]],"batl":[[0,1.51,430.17]],"ltp":1.49,"tv":962.79,"id":5300820},{"batb":[[0,2.88,13.62],[1,2.86,75.69],[2,2.82,14.07]],"ltp":2.84,"tv":284.78,"id":9629022}],"tv":1247.57}]}
{"op":"mcm","clk":"4214759977","pt":1631530274016,"mc":[{"id":"1.187557985","rc":[{"batl":[[1,1.52,426.73],[2,1.54,572.41]],"ltp":1.49,"tv":962.79,"id":5300820}]}]}
{"op":"mcm","clk":"4214760033","pt":1631530275308,"mc":[{"id":"1.187557985","rc":[{"trd":[[1.49,562.72]],"batb":[[0,1.48,29.84],[1,1.47,171.59],[2,1.45,72.64]],"ltp":1.49,"tv":1026.69,"id":5300820}],"tv":1311.48}]}
{"op":"mcm","clk":"4214760103","pt":1631530276397,"mc":[{"id":"1.187557985","rc":[{"batb":[[2,1.45,15.74]],"batl":[[2,1.53,426.73]],"ltp":1.49,"tv":1026.69,"id":5300820},{"batb":[[0,2.9,13.48],[1,2.88,13.62],[2,2.86,75.69]],"ltp":2.84,"tv":284.78,"id":9629022}]}]}
{"op":"mcm","clk":"4214760286","pt":1631530279828,"mc":[{"id":"1.187557985","rc":[{"batl":[[0,1.51,426.73]],"ltp":1.49,"tv":1026.69,"id":5300820}]}]}
{"op":"mcm","clk":"4214760554","pt":1631530284308,"mc":[{"id":"1.187557985","rc":[{"batl":[[0,1.49,3.44],[1,1.51,426.73],[2,1.52,426.73]],"ltp":1.49,"tv":1026.69,"id":5300820}]}]}
{"op":"mcm","clk":"4214763147","pt":1631530337843,"mc":[{"id":"1.187557985","rc":[{"batb":[[0,2.98,24.55],[1,2.9,13.48],[2,2.88,13.62]],"ltp":2.84,"tv":284.78,"id":9629022}]}]}
{"op":"mcm","clk":"4214768705","pt":1631530444600,"mc":[{"id":"1.187557985","rc":[{"trd":[[1.48,19.94]],"batb":[[0,1.47,171.59],[1,1.46,83.41]],"ltp":1.48,"tv":1031.82,"id":5300820}],"tv":1316.6}]}
{"op":"mcm","clk":"4214769492","pt":1631530458604,"mc":[{"id":"1.187557985","marketDefinition":{"bspMarket":false,"turnInPlayEnabled":true,"persistenceEnabled":true,"marketBaseRate":5.0,"eventId":"30896136","eventTypeId":"2","numberOfWinners":1,"bettingType":"ODDS","marketType":"MATCH_ODDS","marketTime":"2021-09-13T11:00:00.000Z","suspendTime":"2021-09-13T11:00:00.000Z","bspReconciled":false,"complete":true,"inPlay":false,"crossMatching":true,"runnersVoidable":false,"numberOfActiveRunners":2,"betDelay":0,"status":"OPEN","runners":[{"status":"ACTIVE","sortPriority":1,"id":5300820,"name":"Aleksandra Krunic"},{"status":"ACTIVE","sortPriority":2,"id":9629022,"name":"Susan Bandecchi"}],"regulators":["MR_INT"],"discountAllowed":true,"timezone":"UTC","openDate":"2021-09-13T10:50:00.000Z","version":4030564430,"name":"Match Odds","eventName":"Krunic v Bandecchi"},"rc":[{"batb":[[0,1.47,182.15]],"ltp":1.48,"tv":1031.82,"id":5300820}]}]}
{"op":"mcm","clk":"4214769560","pt":1631530459632,"mc":[{"id":"1.187557985","rc":[{"batb":[[1,1.46,94.13]],"ltp":1.48,"tv":1031.82,"id":5300820}]}]}
{"op":"mcm","clk":"4214769693","pt":1631530461500,"mc":[{"id":"1.187557985","marketDefinition":{"bspMarket":false,"turnInPlayEnabled":true,"persistenceEnabled":true,"marketBaseRate":5.0,"eventId":"30896136","eventTypeId":"2","numberOfWinners":1,"bettingType":"ODDS","marketType":"MATCH_ODDS","marketTime":"2021-09-13T11:00:00.000Z","suspendTime":"2021-09-13T11:00:00.000Z","bspReconciled":false,"complete":true,"inPlay":false,"crossMatching":true,"runnersVoidable":false,"numberOfActiveRunners":2,"betDelay":0,"status":"OPEN","runners":[{"status":"ACTIVE","sortPriority":1,"id":5300820,"name":"Aleksandra Krunic"},{"status":"ACTIVE","sortPriority":2,"id":9629022,"name":"Susan Bandecchi"}],"regulators":["MR_INT"],"discountAllowed":true,"timezone":"UTC","openDate":"2021-09-13T11:00:00.000Z","version":4030564430,"name":"Match Odds","eventName":"Krunic v Bandecchi"}}]}
{"op":"mcm","clk":"4214781288","pt":1631530630119,"mc":[{"id":"1.187557985","rc":[{"trd":[[1.48,22.61]],"ltp":1.48,"tv":1034.48,"id":5300820},{"trd":[[3.05,1.29]],"batl":[[0,3.45,61.16],[1,29,48.42],[2,990,2.2]],"ltp":3.05,"tv":286.07,"id":9629022}],"tv":1320.56}]}
{"op":"mcm","clk":"4214781359","pt":1631530631001,"mc":[{"id":"1.187557985","rc":[{"trd":[[3.05,2.71]],"batb":[[0,3.05,1.96],[1,2.98,24.55],[2,2.9,13.48]],"batl":[[0,3.45,60.45]],"ltp":3.05,"tv":287.49,"id":9629022}],"tv":1321.97}]}
{"op":"mcm","clk":"4214790288","pt":1631530740193,"mc":[{"id":"1.187557985","rc":[{"batb":[[0,1.47,171.59],[1,1.46,83.41]],"ltp":1.48,"tv":1034.48,"id":5300820}]}]}
{"op":"mcm","clk":"4214791624","pt":1631530758500,"mc":[{"id":"1.187557985","marketDefinition":{"bspMarket":false,"turnInPlayEnabled":true,"persistenceEnabled":true,"marketBaseRate":5.0,"eventId":"30896136","eventTypeId":"2","numberOfWinners":1,"bettingType":"ODDS","marketType":"MATCH_ODDS","marketTime":"2021-09-13T11:10:00.000Z","suspendTime":"2021-09-13T11:10:00.000Z","bspReconciled":false,"complete":true,"inPlay":false,"crossMatching":true,"runnersVoidable":false,"numberOfActiveRunners":2,"betDelay":0,"status":"OPEN","runners":[{"status":"ACTIVE","sortPriority":1,"id":5300820,"name":"Aleksandra Krunic"},{"status":"ACTIVE","sortPriority":2,"id":9629022,"name":"Susan Bandecchi"}],"regulators":["MR_INT"],"discountAllowed":true,"timezone":"UTC","openDate":"2021-09-13T11:00:00.000Z","version":4030568789,"name":"Match Odds","eventName":"Krunic v Bandecchi"},"rc":[{"batb":[[0,1.47,182.85],[1,1.46,94.7]],"ltp":1.48,"tv":1034.48,"id":5300820}]}]}
{"op":"mcm","clk":"4214791854","pt":1631530761306,"mc":[{"id":"1.187557985","marketDefinition":{"bspMarket":false,"turnInPlayEnabled":true,"persistenceEnabled":true,"marketBaseRate":5.0,"eventId":"30896136","eventTypeId":"2","numberOfWinners":1,"bettingType":"ODDS","marketType":"MATCH_ODDS","marketTime":"2021-09-13T11:10:00.000Z","suspendTime":"2021-09-13T11:10:00.000Z","bspReconciled":false,"complete":true,"inPlay":false,"crossMatching":true,"runnersVoidable":false,"numberOfActiveRunners":2,"betDelay":0,"status":"OPEN","runners":[{"status":"ACTIVE","sortPriority":1,"id":5300820,"name":"Aleksandra Krunic"},{"status":"ACTIVE","sortPriority":2,"id":9629022,"name":"Susan Bandecchi"}],"regulators":["MR_INT"],"discountAllowed":true,"timezone":"UTC","openDate":"2021-09-13T11:10:00.000Z","version":4030568789,"name":"Match Odds","eventName":"Krunic v Bandecchi"},"rc":[{"batl":[[0,3.45,53.28]],"ltp":3.05,"tv":287.49,"id":9629022}]}]}
{"op":"mcm","clk":"4214791989","pt":1631530762929,"mc":[{"id":"1.187557985","rc":[{"batl":[[0,3.45,60.45]],"ltp":3.05,"tv":287.49,"id":9629022}]}]}
{"op":"mcm","clk":"4214820182","pt":1631531100348,"mc":[{"id":"1.187557985","rc":[{"trd":[[1.45,28.91],[1.47,34.11],[1.48,22.57],[1.49,561.54],[1.5,49.97],[1.53,0.85],[1.54,292.61],[1.55,41.89]],"batb":[[0,1.47,182.52],[1,1.46,94.54],[2,1.45,27.09]],"batl":[[0,1.49,3.44],[1,1.51,425.89],[2,1.52,425.89]],"ltp":1.48,"tv":1032.45,"id":5300820},{"trd":[[2.82,3.99],[2.84,152.06],[2.86,123.69],[3.05,2.71]],"batb":[[0,3.05,1.95],[1,2.98,24.5],[2,2.9,13.45]],"batl":[[0,3.45,60.33],[1,4.1,7.23],[2,29,48.37]],"ltp":3.05,"tv":286.89,"id":9629022}],"tv":1319.35}]}
{"op":"mcm","clk":"4214825080","pt":1631531159111,"mc":[{"id":"1.187557985","rc":[{"batl":[[1,1.5,100],[2,1.51,425.89]],"ltp":1.48,"tv":1032.45,"id":5300820}]}]}
{"op":"mcm","clk":"4214839361","pt":1631531340227,"mc":[{"id":"1.187557985","rc":[{"batb":[[0,1.47,171.26],[1,1.46,83.25],[2,1.45,15.71]],"ltp":1.48,"tv":1032.45,"id":5300820}]}]}
{"op":"mcm","clk":"4214839447","pt":1631531341212,"mc":[{"id":"1.187557985","rc":[{"batb":[[2,2.92,13.31]],"ltp":3.05,"tv":286.89,"id":9629022}]}]}
{"op":"mcm","clk":"4214840630","pt":1631531357533,"mc":[{"id":"1.187557985","marketDefinition":{"bspMarket":false,"turnInPlayEnabled":true,"persistenceEnabled":true,"marketBaseRate":5.0,"eventId":"30896136","eventTypeId":"2","numberOfWinners":1,"bettingType":"ODDS","marketType":"MATCH_ODDS","marketTime":"2021-09-13T11:20:00.000Z","suspendTime":"2021-09-13T11:20:00.000Z","bspReconciled":false,"complete":true,"inPlay":false,"crossMatching":true,"runnersVoidable":false,"numberOfActiveRunners":2,"betDelay":0,"status":"OPEN","runners":[{"status":"ACTIVE","sortPriority":1,"id":5300820,"name":"Aleksandra Krunic"},{"status":"ACTIVE","sortPriority":2,"id":9629022,"name":"Susan Bandecchi"}],"regulators":["MR_INT"],"discountAllowed":true,"timezone":"UTC","openDate":"2021-09-13T11:10:00.000Z","version":4030577908,"name":"Match Odds","eventName":"Krunic v Bandecchi"},"rc":[{"batb":[[0,1.47,180.01]],"batl":[[1,1.5,108.63]],"ltp":1.48,"tv":1032.45,"id":5300820}]}]}
{"op":"mcm","clk":"4214840643","pt":1631531357735,"mc":[{"id":"1.187557985","rc":[{"batb":[[1,1.46,92.05]],"batl":[[2,1.51,434.57]],"ltp":1.48,"tv":1032.45,"id":5300820}]}]}
{"op":"mcm","clk":"4214840891","pt":1631531360656,"mc":[{"id":"1.187557985","marketDefinition":{"bspMarket":false,"turnInPlayEnabled":true,"persistenceEnabled":true,"marketBaseRate":5.0,"eventId":"30896136","eventTypeId":"2","numberOfWinners":1,"bettingType":"ODDS","marketType":"MATCH_ODDS","marketTime":"2021-09-13T11:20:00.000Z","suspendTime":"2021-09-13T11:20:00.000Z","bspReconciled":false,"complete":true,"inPlay":false,"crossMatching":true,"runnersVoidable":false,"numberOfActiveRunners":2,"betDelay":0,"status":"OPEN","runners":[{"status":"ACTIVE","sortPriority":1,"id":5300820,"name":"Aleksandra Krunic"},{"status":"ACTIVE","sortPriority":2,"id":9629022,"name":"Susan Bandecchi"}],"regulators":["MR_INT"],"discountAllowed":true,"timezone":"UTC","openDate":"2021-09-13T11:20:00.000Z","version":4030577908,"name":"Match Odds","eventName":"Krunic v Bandecchi"},"rc":[{"batl":[[0,3.45,53.16]],"ltp":3.05,"tv":286.89,"id":9629022}]}]}
{"op":"mcm","clk":"4214841062","pt":1631531363225,"mc":[{"id":"1.187557985","rc":[{"batl":[[0,3.45,60.32]],"ltp":3.05,"tv":286.89,"id":9629022}]}]}
{"op":"mcm","clk":"4214858599","pt":1631531598515,"mc":[{"id":"1.187557985","rc":[{"batb":[[2,2.96,103.01]],"ltp":3.05,"tv":286.89,"id":9629022}]}]}
{"op":"mcm","clk":"4214868404","pt":1631531739887,"mc":[{"id":"1.187557985","rc":[{"trd":[[1.47,262.4]],"batb":[[0,1.47,65.86],[2,1.45,25.1]],"ltp":1.47,"tv":1260.74,"id":5300820}],"tv":1547.63}]}
{"op":"mcm","clk":"4214869196","pt":1631531749537,"mc":[{"id":"1.187557985","rc":[{"trd":[[1.47,263.57]],"batb":[[0,1.47,65.27]],"ltp":1.47,"tv":1261.91,"id":5300820}],"tv":1548.81}]}
{"op":"mcm","clk":"4214883609","pt":1631531940162,"mc":[{"id":"1.187557985","rc":[{"batb":[[0,1.47,56.52],[1,1.46,83.25],[2,1.45,15.71]],"batl":[[1,1.5,100],[2,1.51,425.89]],"ltp":1.47,"tv":1261.91,"id":5300820}]}]}
{"op":"mcm","clk":"4214884404","pt":1631531949657,"mc":[{"id":"1.187557985","rc":[{"trd":[[1.47,289.81]],"batb":[[0,1.47,43.41]],"ltp":1.47,"tv":1288.15,"id":5300820}],"tv":1575.05}]}
{"op":"mcm","clk":"4214885151","pt":1631531957553,"mc":[{"id":"1.187557985","marketDefinition":{"bspMarket":false,"turnInPlayEnabled":true,"persistenceEnabled":true,"marketBaseRate":5.0,"eventId":"30896136","eventTypeId":"2","numberOfWinners":1,"bettingType":"ODDS","marketType":"MATCH_ODDS","marketTime":"2021-09-13T11:25:00.000Z","suspendTime":"2021-09-13T11:25:00.000Z","bspReconciled":false,"complete":true,"inPlay":false,"crossMatching":true,"runnersVoidable":false,"numberOfActiveRunners":2,"betDelay":0,"status":"OPEN","runners":[{"status":"ACTIVE","sortPriority":1,"id":5300820,"name":"Aleksandra Krunic"},{"status":"ACTIVE","sortPriority":2,"id":9629022,"name":"Susan Bandecchi"}],"regulators":["MR_INT"],"discountAllowed":true,"timezone":"UTC","openDate":"2021-09-13T11:20:00.000Z","version":4030582969,"name":"Match Odds","eventName":"Krunic v Bandecchi"}}]}
{"op":"mcm","clk":"4214885178","pt":1631531957678,"mc":[{"id":"1.187557985","rc":[{"batb":[[1,1.46,92.42]],"batl":[[1,1.5,109.04]],"ltp":1.47,"tv":1288.15,"id":5300820}]}]}
{"op":"mcm","clk":"4214885441","pt":1631531960570,"mc":[{"id":"1.187557985","marketDefinition":{"bspMarket":false,"turnInPlayEnabled":true,"persistenceEnabled":true,"marketBaseRate":5.0,"eventId":"30896136","eventTypeId":"2","numberOfWinners":1,"bettingType":"ODDS","marketType":"MATCH_ODDS","marketTime":"2021-09-13T11:25:00.000Z","suspendTime":"2021-09-13T11:25:00.000Z","bspReconciled":false,"complete":true,"inPlay":false,"crossMatching":true,"runnersVoidable":false,"numberOfActiveRunners":2,"betDelay":0,"status":"OPEN","runners":[{"status":"ACTIVE","sortPriority":1,"id":5300820,"name":"Aleksandra Krunic"},{"status":"ACTIVE","sortPriority":2,"id":9629022,"name":"Susan Bandecchi"}],"regulators":["MR_INT"],"discountAllowed":true,"timezone":"UTC","openDate":"2021-09-13T11:25:00.000Z","version":4030582969,"name":"Match Odds","eventName":"Krunic v Bandecchi"}}]}
{"op":"mcm","clk":"4214885478","pt":1631531960792,"mc":[{"id":"1.187557985","rc":[{"batl":[[0,3.45,53.16]],"ltp":3.05,"tv":286.89,"id":9629022}]}]}
{"op":"mcm","clk":"4214885643","pt":1631531962980,"mc":[{"id":"1.187557985","rc":[{"batl":[[0,3.45,60.32]],"ltp":3.05,"tv":286.89,"id":9629022}]}]}
{"op":"mcm","clk":"4214889665","pt":1631532013529,"mc":[{"id":"1.187557985","rc":[{"trd":[[1.47,294.15]],"batb":[[0,1.47,41.24],[2,1.45,24.92]],"batl":[[2,1.51,434.97]],"ltp":1.47,"tv":1292.49,"id":5300820}],"tv":1579.39}]}
{"op":"mcm","clk":"4214891062","pt":1631532029588,"mc":[{"id":"1.187557985","rc":[{"batb":[[0,1.47,135.88]],"ltp":1.47,"tv":1292.49,"id":5300820}]}]}
{"op":"mcm","clk":"4214902848","pt":1631532185769,"mc":[{"id":"1.187557985","rc":[{"batb":[[1,1.46,9.17]],"ltp":1.47,"tv":1292.49,"id":5300820},{"batb":[[1,2.96,103.01],[2,2.92,13.31]],"ltp":3.05,"tv":286.89,"id":9629022}]}]}
{"op":"mcm","clk":"4214907036","pt":1631532240232,"mc":[{"id":"1.187557985","rc":[{"batb":[[0,1.47,126.41],[1,1.45,15.71],[2,1.44,283.62]],"batl":[[1,1.5,100],[2,1.51,425.89]],"ltp":1.47,"tv":1292.49,"id":5300820}]}]}
{"op":"mcm","clk":"4214908640","pt":1631532260045,"mc":[{"id":"1.187557985","rc":[{"batl":[[0,3.45,53.16]],"ltp":3.05,"tv":286.89,"id":9629022}]}]}
{"op":"mcm","clk":"4214910790","pt":1631532285955,"mc":[{"id":"1.187557985","rc":[{"batb":[[2,1.44,188.7]],"ltp":1.47,"tv":1292.49,"id":5300820}]}]}
{"op":"mcm","clk":"4214912084","pt":1631532303320,"mc":[{"id":"1.187557985","marketDefinition":{"bspMarket":false,"turnInPlayEnabled":true,"persistenceEnabled":true,"marketBaseRate":5.0,"eventId":"30896136","eventTypeId":"2","numberOfWinners":1,"bettingType":"ODDS","marketType":"MATCH_ODDS","marketTime":"2021-09-13T11:25:00.000Z","suspendTime":"2021-09-13T11:25:00.000Z","bspReconciled":false,"complete":true,"inPlay":true,"crossMatching":true,"runnersVoidable":false,"numberOfActiveRunners":2,"betDelay":3,"status":"OPEN","runners":[{"status":"ACTIVE","sortPriority":1,"id":5300820,"name":"Aleksandra Krunic"},{"status":"ACTIVE","sortPriority":2,"id":9629022,"name":"Susan Bandecchi"}],"regulators":["MR_INT"],"discountAllowed":true,"timezone":"UTC","openDate":"2021-09-13T11:25:00.000Z","version":4030587494,"name":"Match Odds","eventName":"Krunic v Bandecchi"},"rc":[{"batb":[[0,1.45,4.26],[1,1.27,2.17],[2,1.2,2]],"batl":[[0,1.5,100],[1,1.51,425.89],[2,1.52,425.89]],"ltp":1.47,"tv":1292.49,"id":5300820},{"batb":[[0,1.43,3.41],[1,1.37,4],[2,1.2,2]],"batl":[[1,4.1,0],[2,29,0]],"ltp":3.05,"tv":286.89,"id":9629022}]}]}
{"op":"mcm","clk":"4214912338","pt":1631532306517,"mc":[{"id":"1.187557985","rc":[{"batl":[[0,1.5,105]],"ltp":1.47,"tv":1292.49,"id":5300820},{"batl":[[0,3.15,3],[1,3.45,53.16]],"ltp":3.05,"tv":286.89,"id":9629022}]}]}
{"op":"mcm","clk":"4214912347","pt":1631532306677,"mc":[{"id":"1.187557985","rc":[{"batl":[[0,1.5,100]],"ltp":1.47,"tv":1292.49,"id":5300820},{"batb":[[0,1.8,11.88],[1,1.43,3.41],[2,1.37,4]],"batl":[[0,3.45,53.16],[1,3.45,0]],"ltp":3.05,"tv":286.89,"id":9629022}]}]}
{"op":"mcm","clk":"4214913489","pt":1631532320509,"mc":[{"id":"1.187557985","rc":[{"trd":[[1.5,149.97],[1.51,425.89]],"batl":[[0,1.52,425.89],[1,1.53,425.89],[2,1.54,569.29]],"ltp":1.51,"tv":1818.39,"id":5300820},{"trd":[[2.96,217.26],[3,50]],"ltp":2.96,"tv":554.15,"id":9629022}],"tv":2372.54}]}
{"op":"mcm","clk":"4214913675","pt":1631532322485,"mc":[{"id":"1.187557985","rc":[{"batb":[[0,1.51,55.87],[1,1.5,231.58],[2,1.45,4.26]],"ltp":1.51,"tv":1818.39,"id":5300820},{"batb":[[0,2.76,49.29],[1,2.6,57.57],[2,1.8,11.88]],"ltp":2.96,"tv":554.15,"id":9629022}]}]}
{"op":"mcm","clk":"4214913790","pt":1631532323625,"mc":[{"id":"1.187557985","rc":[{"batb":[[0,1.51,130.24],[1,1.5,371.4],[2,1.46,1165.88]],"ltp":1.51,"tv":1818.39,"id":5300820}]}]}
{"op":"mcm","clk":"4214913879","pt":1631532324505,"mc":[{"id":"1.187557985","rc":[{"batb":[[0,1.51,83.76],[1,1.5,301.49],[2,1.45,4.26]],"ltp":1.51,"tv":1818.39,"id":5300820}]}]}
{"op":"mcm","clk":"4214913950","pt":1631532325329,"mc":[{"id":"1.187557985","rc":[{"trd":[[1.52,15.77]],"batb":[[0,1.51,79.37],[1,1.5,231.58]],"batl":[[0,1.52,415.13]],"ltp":1.52,"tv":1834.15,"id":5300820},{"trd":[[2.92,3]],"ltp":2.92,"tv":557.15,"id":9629022}],"tv":2391.31}]}
{"op":"mcm","clk":"4214914043","pt":1631532326212,"mc":[{"id":"1.187557985","rc":[{"trd":[[1.52,805.19]],"batb":[[0,1.51,5],[1,1.5,161.67]],"batl":[[0,1.53,425.89],[1,1.54,569.29],[2,1.55,956.36]],"ltp":1.52,"tv":2623.58,"id":5300820},{"trd":[[2.92,24.25]],"ltp":2.92,"tv":578.4,"id":9629022}],"tv":3201.99}]}
{"op":"mcm","clk":"4214914331","pt":1631532329429,"mc":[{"id":"1.187557985","rc":[{"trd":[[1.53,867.38]],"batb":[[0,1.53,31.51],[1,1.51,5],[2,1.5,161.67]],"batl":[[0,1.54,569.29],[1,1.55,956.36],[2,1.56,851.79]],"ltp":1.53,"tv":3490.1,"id":5300820},{"batl":[[0,2.96,3],[1,3.45,53.16]],"ltp":2.92,"tv":578.4,"id":9629022}],"tv":4068.51}]}
{"op":"mcm","clk":"4214914585","pt":1631532332465,"mc":[{"id":"1.187557985","rc":[{"trd":[[1.53,907]],"batb":[[0,1.53,204.24],[1,1.52,177.18],[2,1.51,5]],"ltp":1.53,"tv":3529.72,"id":5300820}],"tv":4108.13}]}
{"op":"mcm","clk":"4214915078","pt":1631532338240,"mc":[{"id":"1.187557985","rc":[{"batb":[[0,1.45,4.26],[1,1.44,191.21],[2,1.27,2.17]],"ltp":1.53,"tv":3529.72,"id":5300820},{"batb":[[0,2.6,57.57],[1,1.8,11.88],[2,1.43,3.41]],"batl":[[0,3.45,53.16],[1,3.45,0]],"ltp":2.92,"tv":578.4,"id":9629022}]}]}
{"op":"mcm","clk":"4214915325","pt":1631532341435,"mc":[{"id":"1.187557985","rc":[{"batb":[[0,1.45,9.26],[1,1.44,199.21]],"ltp":1.53,"tv":3529.72,"id":5300820},{"batl":[[0,3.3,2],[1,3.45,53.16]],"ltp":2.92,"tv":578.4,"id":9629022}]}]}
{"op":"mcm","clk":"4214915579","pt":1631532344643,"mc":[{"id":"1.187557985","rc":[{"batb":[[0,1.47,7],[1,1.46,7],[2,1.45,9.26]],"ltp":1.53,"tv":3529.72,"id":5300820},{"batl":[[0,3.15,3],[1,3.25,3],[2,3.3,2]],"ltp":2.92,"tv":578.4,"id":9629022}]}]}
{"op":"mcm","clk":"4214915619","pt":1631532345162,"mc":[{"id":"1.187557985","rc":[{"batb":[[0,1.52,160.31],[1,1.51,181.6],[2,1.47,7]],"batl":[[2,1.56,1055.75]],"ltp":1.53,"tv":3529.72,"id":5300820}]}]}
{"op":"mcm","clk":"4214915758","pt":1631532346832,"mc":[{"id":"1.187557985","rc":[{"batb":[[0,1.47,7],[1,1.46,7],[2,1.45,9.26]],"batl":[[2,1.56,851.79]],"ltp":1.53,"tv":3529.72,"id":5300820}]}]}
{"op":"mcm","clk":"4214916016","pt":1631532349831,"mc":[{"id":"1.187557985","rc":[{"batb":[[0,1.47,153.63],[1,1.46,215.49]],"ltp":1.53,"tv":3529.72,"id":5300820}]}]}
{"op":"mcm","clk":"4214916606","pt":1631532357462,"mc":[{"id":"1.187557985","rc":[{"batb":[[0,1.47,146.63],[1,1.46,208.49],[2,1.45,4.26]],"ltp":1.53,"tv":3529.72,"id":5300820},{"batl":[[1,3.45,53.16],[2,3.3,0]],"ltp":2.92,"tv":578.4,"id":9629022}]}]}
{"op":"mcm","clk":"4214916690","pt":1631532358450,"mc":[{"id":"1.187557985","rc":[{"batl":[[0,1.53,100],[1,1.54,569.29],[2,1.55,956.36]],"ltp":1.53,"tv":3529.72,"id":5300820},{"batl":[[0,3.45,53.16],[1,3.45,0]],"ltp":2.92,"tv":578.4,"id":9629022}]}]}
{"op":"mcm","clk":"4214916758","pt":1631532359480,"mc":[{"id":"1.187557985","rc":[{"trd":[[1.47,321.55]],"batb":[[0,1.47,132.93]],"batl":[[0,1.51,298.05],[1,1.52,1432.88],[2,1.53,1321.22]],"ltp":1.47,"tv":3557.12,"id":5300820},{"batl":[[0,3.25,323.65],[1,3.3,314.14],[2,3.35,314.14]],"ltp":2.92,"tv":578.4,"id":9629022}],"tv":4135.53}]}
{"op":"mcm","clk":"4214916854","pt":1631532360469,"mc":[{"id":"1.187557985","rc":[{"batb":[[0,1.46,208.49],[1,1.45,4.26],[2,1.44,191.21]],"ltp":1.47,"tv":3557.12,"id":5300820},{"batb":[[0,2.98,101.25],[1,2.76,49.37],[2,1.8,11.88]],"ltp":2.92,"tv":578.4,"id":9629022}]}]}
{"op":"mcm","clk":"4214916942","pt":1631532361464,"mc":[{"id":"1.187557985","rc":[{"batb":[[1,2.86,3],[2,2.84,3]],"ltp":2.92,"tv":578.4,"id":9629022}]}]}
{"op":"mcm","clk":"4214917130","pt":1631532363596,"mc":[{"id":"1.187557985","rc":[{"batb":[[0,1.46,348.57],[1,1.45,220.53]],"ltp":1.47,"tv":3557.12,"id":5300820}]}]}
{"op":"mcm","clk":"4214917432","pt":1631532367697,"mc":[{"id":"1.187557985","rc":[{"trd":[[1.46,14]],"batb":[[0,1.46,341.57]],"ltp":1.46,"tv":3571.12,"id":5300820}],"tv":4149.53}]}
{"op":"mcm","clk":"4214918020","pt":1631532375587,"mc":[{"id":"1.187557985","rc":[{"batb":[[0,1.45,4.26],[1,1.43,2377.09],[2,1.38,231.96]],"batl":[[0,1.53,100],[1,1.54,569.29],[2,1.55,956.36]],"ltp":1.46,"tv":3571.12,"id":5300820},{"batb":[[0,2.84,3],[1,2.76,49.37],[2,1.8,11.88]],"batl":[[0,3.45,53.16],[1,3.3,0],[2,3.35,0]],"ltp":2.92,"tv":578.4,"id":9629022}]}]}
{"op":"mcm","clk":"4214918043","pt":1631532375896,"mc":[{"id":"1.187557985","rc":[{"batb":[[1,1.38,231.96],[2,1.27,2.17]],"ltp":1.46,"tv":3571.12,"id":5300820}]}]}
{"op":"mcm","clk":"4214918253","pt":1631532378490,"mc":[{"id":"1.187557985","rc":[{"batb":[[1,1.4,200.84],[2,1.39,259.63]],"ltp":1.46,"tv":3571.12,"id":5300820}]}]}
{"op":"mcm","clk":"4214918273","pt":1631532378699,"mc":[{"id":"1.187557985","rc":[{"batb":[[1,1.38,231.96],[2,1.27,2.17]],"ltp":1.46,"tv":3571.12,"id":5300820}]}]}
{"op":"mcm","clk":"4214918492","pt":1631532381290,"mc":[{"id":"1.187557985","rc":[{"batb":[[0,1.45,268.94],[1,1.44,222.19],[2,1.38,231.96]],"batl":[[0,1.49,224.9],[1,1.5,184.58],[2,1.53,100]],"ltp":1.46,"tv":3571.12,"id":5300820}]}]}
{"op":"mcm","clk":"4214918683","pt":1631532383620,"mc":[{"id":"1.187557985","rc":[{"batb":[[0,1.45,4.26],[1,1.38,231.96],[2,1.27,2.17]],"batl":[[0,1.53,100],[1,1.54,569.29],[2,1.55,956.36]],"ltp":1.46,"tv":3571.12,"id":5300820}]}]}
{"op":"mcm","clk":"4214918910","pt":1631532386528,"mc":[{"id":"1.187557985","rc":[{"batb":[[1,1.4,200.84],[2,1.39,259.63]],"ltp":1.46,"tv":3571.12,"id":5300820}]}]}
{"op":"mcm","clk":"4214919329","pt":1631532391013,"mc":[{"id":"1.187557985","rc":[{"batb":[[1,1.38,231.96],[2,1.27,2.17]],"ltp":1.46,"tv":3571.12,"id":5300820}]}]}
{"op":"mcm","clk":"4214919580","pt":1631532393635,"mc":[{"id":"1.187557985","rc":[{"trd":[[1.53,1107]],"batl":[[0,1.54,569.29],[1,1.55,956.36],[2,1.56,851.79]],"ltp":1.53,"tv":3771.12,"id":5300820},{"batb":[[0,2.76,49.37],[1,1.8,11.88],[2,1.43,3.41]],"batl":[[0,2.94,1301.02],[1,2.96,1262.76],[2,2.98,1262.76]],"ltp":2.92,"tv":578.4,"id":9629022}],"tv":4349.53}]}
{"op":"mcm","clk":"4214919681","pt":1631532394628,"mc":[{"id":"1.187557985","rc":[{"batb":[[0,1.53,227.46],[1,1.52,177.3],[2,1.5,161.5]],"ltp":1.53,"tv":3771.12,"id":5300820},{"batb":[[1,2.58,59.33],[2,1.8,11.88]],"batl":[[0,2.94,650.52],[1,2.96,631.38],[2,2.98,631.38]],"ltp":2.92,"tv":578.4,"id":9629022}]}]}
{"op":"mcm","clk":"4214919744","pt":1631532395302,"mc":[{"id":"1.187557985","rc":[{"trd":[[1.53,1133.5]],"batb":[[0,1.53,214.21]],"ltp":1.53,"tv":3797.62,"id":5300820}],"tv":4376.03}]}
{"op":"mcm","clk":"4214919814","pt":1631532396137,"mc":[{"id":"1.187557985","rc":[{"batb":[[1,1.52,184.3],[2,1.51,5]],"ltp":1.53,"tv":3797.62,"id":5300820},{"batb":[[1,2.64,3],[2,2.62,4]],"ltp":2.92,"tv":578.4,"id":9629022}]}]}
{"op":"mcm","clk":"4214920058","pt":1631532398632,"mc":[{"id":"1.187557985","rc":[{"batl":[[2,1.56,932.99]],"ltp":1.53,"tv":3797.62,"id":5300820},{"batl":[[0,2.92,18.56],[1,2.94,650.52],[2,2.96,631.38]],"ltp":2.92,"tv":578.4,"id":9629022}]}]}
{"op":"mcm","clk":"4214920081","pt":1631532398841,"mc":[{"id":"1.187557985","rc":[{"batl":[[2,1.56,851.79]],"ltp":1.53,"tv":3797.62,"id":5300820},{"batl":[[0,2.94,650.52],[1,2.96,631.38],[2,2.98,631.38]],"ltp":2.92,"tv":578.4,"id":9629022}]}]}
{"op":"mcm","clk":"4214920918","pt":1631532407473,"mc":[{"id":"1.187557985","rc":[{"batb":[[0,1.49,2781.35],[1,1.45,11.26],[2,1.44,192.8]],"ltp":1.53,"tv":3797.62,"id":5300820},{"batb":[[0,2.64,3],[1,2.58,59.33],[2,1.8,11.88]],"batl":[[0,3.4,3],[1,3.45,53.16],[2,2.98,0]],"ltp":2.92,"tv":578.4,"id":9629022}]}]}
{"op":"mcm","clk":"4214920986","pt":1631532408253,"mc":[{"id":"1.187557985","rc":[{"batb":[[0,1.45,11.26],[1,1.44,192.8],[2,1.27,2.17]],"ltp":1.53,"tv":3797.62,"id":5300820}]}]}
{"op":"mcm","clk":"4214921195","pt":1631532410344,"mc":[{"id":"1.187557985","rc":[{"batb":[[0,1.46,219.31],[1,1.45,226.63],[2,1.44,192.8]],"ltp":1.53,"tv":3797.62,"id":5300820}]}]}
{"op":"mcm","clk":"4214921296","pt":1631532411434,"mc":[{"id":"1.187557985","rc":[{"batb":[[0,1.45,11.26],[1,1.44,198.8],[2,1.27,2.17]],"ltp":1.53,"tv":3797.62,"id":5300820},{"batl":[[0,3.25,3],[1,3.4,3],[2,3.45,53.16]],"ltp":2.92,"tv":578.4,"id":9629022}]}]}
{"op":"mcm","clk":"4214921496","pt":1631532413666,"mc":[{"id":"1.187557985","rc":[{"batl":[[0,3.2,2],[1,3.25,3],[2,3.4,3]],"ltp":2.92,"tv":578.4,"id":9629022}]}]}
{"op":"mcm","clk":"4214921629","pt":1631532415082,"mc":[{"id":"1.187557985","rc":[{"batb":[[0,1.52,137.95],[1,1.51,181.58],[2,1.45,11.26]],"batl":[[2,1.56,1077.48]],"ltp":1.53,"tv":3797.62,"id":5300820}]}]}
{"op":"mcm","clk":"4214921740","pt":1631532416074,"mc":[{"id":"1.187557985","rc":[{"batb":[[0,1.45,11.26],[1,1.44,198.8],[2,1.27,2.17]],"batl":[[2,1.56,851.79]],"ltp":1.53,"tv":3797.62,"id":5300820}]}]}
{"op":"mcm","clk":"4214922047","pt":1631532419067,"mc":[{"id":"1.187557985","rc":[{"batb":[[0,1.46,219.31],[1,1.45,226.63],[2,1.44,198.8]],"ltp":1.53,"tv":3797.62,"id":5300820}]}]}
{"op":"mcm","clk":"4214922655","pt":1631532425145,"mc":[{"id":"1.187557985","rc":[{"batb":[[2,1.44,192.8]],"batl":[[0,1.52,2.32],[1,1.54,569.29],[2,1.55,956.36]],"ltp":1.53,"tv":3797.62,"id":5300820},{"batl":[[1,3.45,53.16],[2,3.4,0]],"ltp":2.92,"tv":578.4,"id":9629022}]}]}
{"op":"mcm","clk":"4214923241","pt":1631532431558,"mc":[{"id":"1.187557985","rc":[{"batb":[[0,1.45,11.26],[1,1.44,192.8],[2,1.27,2.17]],"ltp":1.53,"tv":3797.62,"id":5300820}]}]}
{"op":"mcm","clk":"4214923435","pt":1631532433485,"mc":[{"id":"1.187557985","rc":[{"trd":[[1.52,807.52],[1.54,861.91],[1.55,998.26],[1.56,851.79]],"batl":[[0,1.57,851.79],[1,1.58,851.79],[2,1.6,851.79]],"ltp":1.56,"tv":6177.39,"id":5300820},{"trd":[[2.78,477.98],[2.8,529.42],[2.84,460.76],[2.92,25.46]],"batl":[[0,2.76,935.21],[1,2.96,10.02],[2,3.2,2]],"ltp":2.78,"tv":1895.71,"id":9629022}],"tv":8073.11}]}
{"op":"mcm","clk":"4214923534","pt":1631532434584,"mc":[{"id":"1.187557985","rc":[{"trd":[[1.57,851.79],[1.58,851.79],[1.6,315.84]],"batb":[[0,1.59,148.76],[1,1.45,11.26],[2,1.44,192.8]],"batl":[[0,1.6,693.87],[1,1.62,851.79],[2,1.65,237.01]],"ltp":1.6,"tv":8196.81,"id":5300820},{"trd":[[2.72,494.79],[2.74,492.07]],"batb":[[0,2.58,59.33],[1,2.46,427.59],[2,2.44,415.01]],"batl":[[0,2.72,351.56],[1,2.74,341.22],[2,2.76,682.44]],"ltp":2.72,"tv":2878.57,"id":9629022}],"tv":11075.39}]}
{"op":"mcm","clk":"4214923629","pt":1631532435572,"mc":[{"id":"1.187557985","rc":[{"trd":[[1.59,25.8]],"batb":[[0,1.59,135.86],[1,1.56,138.66],[2,1.51,159.16]],"batl":[[2,1.65,129.79]],"ltp":1.59,"tv":8222.61,"id":5300820},{"batb":[[1,2.46,495.12]],"ltp":2.72,"tv":2878.57,"id":9629022}],"tv":11101.19}]}
{"op":"mcm","clk":"4214923715","pt":1631532436454,"mc":[{"id":"1.187557985","rc":[{"batb":[[2,1.55,250.63]],"ltp":1.59,"tv":8222.61,"id":5300820}]}]}
{"op":"mcm","clk":"4214923810","pt":1631532437486,"mc":[{"id":"1.187557985","rc":[{"batb":[[1,1.57,6],[2,1.56,144.66]],"ltp":1.59,"tv":8222.61,"id":5300820},{"batb":[[1,2.46,497.12],[2,2.44,417.01]],"batl":[[1,2.74,344.22]],"ltp":2.72,"tv":2878.57,"id":9629022}]}]}
{"op":"mcm","clk":"4214923872","pt":1631532438174,"mc":[{"id":"1.187557985","rc":[{"batb":[[0,1.59,206.98],[1,1.58,152.91],[2,1.57,6]],"batl":[[2,1.64,193.02]],"ltp":1.59,"tv":8222.61,"id":5300820}]}]}
{"op":"mcm","clk":"4214924874","pt":1631532448579,"mc":[{"id":"1.187557985","rc":[{"trd":[[1.6,320.49]],"batl":[[0,1.6,691.54]],"ltp":1.6,"tv":8227.26,"id":5300820},{"batb":[[2,2.44,415.01]],"ltp":2.72,"tv":2878.57,"id":9629022}],"tv":11105.84}]}
{"op":"mcm","clk":"4214925124","pt":1631532451201,"mc":[{"id":"1.187557985","rc":[{"batb":[[0,1.51,159.16],[1,1.45,4.26],[2,1.27,2.17]],"batl":[[2,1.64,0]],"ltp":1.6,"tv":8227.26,"id":5300820},{"batb":[[0,2.46,69.53],[1,1.8,11.88],[2,1.5,106.96]],"batl":[[0,3.45,53.16],[1,2.74,0],[2,2.76,0]],"ltp":2.72,"tv":2878.57,"id":9629022}]}]}
{"op":"mcm","clk":"4214925412","pt":1631532454391,"mc":[{"id":"1.187557985","rc":[{"batb":[[0,1.53,263.31],[1,1.52,178],[2,1.51,165.16]],"batl":[[2,1.69,123.81]],"ltp":1.6,"tv":8227.26,"id":5300820},{"batl":[[0,2.98,2],[1,3.45,53.16]],"ltp":2.72,"tv":2878.57,"id":9629022}]}]}
{"op":"mcm","clk":"4214925585","pt":1631532456371,"mc":[{"id":"1.187557985","rc":[{"batl":[[1,1.62,425.89]],"ltp":1.6,"tv":8227.26,"id":5300820}]}]}
{"op":"mcm","clk":"4214925690","pt":1631532457577,"mc":[{"id":"1.187557985","rc":[{"batb":[[0,1.51,165.16],[1,1.5,7],[2,1.45,4.26]],"ltp":1.6,"tv":8227.26,"id":5300820}]}]}
{"op":"mcm","clk":"4214925945","pt":1631532460632,"mc":[{"id":"1.187557985","rc":[{"trd":[[1.6,1012.03],[1.62,425.89]],"batb":[[0,1.64,226.64],[1,1.63,136.22],[2,1.51,165.16]],"batl":[[0,1.69,123.81],[1,1.71,231.16],[2,1.69,0]],"ltp":1.62,"tv":9344.7,"id":5300820},{"trd":[[2.6,265.36],[2.66,415.97]],"batb":[[0,2.46,67.53],[1,2.38,1607.14],[2,2.36,1559.88]],"batl":[[0,2.6,1205.8],[1,2.62,1427.88],[2,2.64,1427.88]],"ltp":2.6,"tv":3559.9,"id":9629022}],"tv":12904.6}]}
{"op":"mcm","clk":"4214926042","pt":1631532461615,"mc":[{"id":"1.187557985","rc":[{"trd":[[1.64,44.33]],"batb":[[0,1.64,198.97],[2,1.61,123.93]],"ltp":1.64,"tv":9389.03,"id":5300820},{"trd":[[2.58,7]],"batb":[[1,2.38,441.96],[2,2.36,428.97]],"batl":[[0,2.6,735.58],[1,2.62,713.94],[2,2.64,713.94]],"ltp":2.58,"tv":3566.9,"id":9629022}],"tv":12955.93}]}
{"op":"mcm","clk":"4214926156","pt":1631532462610,"mc":[{"id":"1.187557985","rc":[{"trd":[[1.64,442.27]],"batb":[[0,1.63,136.22],[1,1.62,56.34]],"batl":[[0,1.64,226.93],[1,1.71,0]],"ltp":1.64,"tv":9786.97,"id":5300820}],"tv":13353.87}]}
{"op":"mcm","clk":"4214926237","pt":1631532463597,"mc":[{"id":"1.187557985","rc":[{"batb":[[1,1.62,97.5],[2,1.61,128.93]],"ltp":1.64,"tv":9786.97,"id":5300820},{"batl":[[0,2.6,738.58]],"ltp":2.58,"tv":3566.9,"id":9629022}]}]}
{"op":"mcm","clk":"4214926332","pt":1631532464598,"mc":[{"id":"1.187557985","rc":[{"batb":[[0,1.63,140.22],[1,1.62,50.55]],"ltp":1.64,"tv":9786.97,"id":5300820},{"batb":[[0,2.5,131.7],[1,2.46,67.53],[2,2.38,441.96]],"batl":[[0,2.58,4],[1,2.6,738.58],[2,2.62,713.94]],"ltp":2.58,"tv":3566.9,"id":9629022}]}]}
{"op":"mcm","clk":"4214926423","pt":1631532465531,"mc":[{"id":"1.187557985","rc":[{"batb":[[0,1.63,242.27],[1,1.62,144.74]],"batl":[[1,1.68,126.12],[2,1.7,236.51]],"ltp":1.64,"tv":9786.97,"id":5300820}]}]}
{"op":"mcm","clk":"4214926979","pt":1631532471885,"mc":[{"id":"1.187557985","rc":[{"batl":[[0,1.64,56.57]],"ltp":1.64,"tv":9786.97,"id":5300820}]}]}
{"op":"mcm","clk":"4214927235","pt":1631532474504,"mc":[{"id":"1.187557985","rc":[{"trd":[[1.63,58]],"batb":[[0,1.63,213.27]],"ltp":1.63,"tv":9844.97,"id":5300820}],"tv":13411.87}]}
{"op":"mcm","clk":"4214927266","pt":1631532474813,"mc":[{"id":"1.187557985","rc":[{"trd":[[1.63,72]],"batb":[[0,1.63,206.27]],"ltp":1.63,"tv":9858.96,"id":5300820},{"batl":[[0,2.6,738.58],[1,2.62,713.94],[2,2.64,713.94]],"ltp":2.58,"tv":3566.9,"id":9629022}],"tv":13425.87}]}
{"op":"mcm","clk":"4214927542","pt":1631532478236,"mc":[{"id":"1.187557985","rc":[{"batb":[[0,1.63,222.38],[1,1.62,139.74],[2,1.61,123.93]],"batl":[[1,1.68,141.66]],"ltp":1.63,"tv":9858.96,"id":5300820}]}]}
{"op":"mcm","clk":"4214927772","pt":1631532481212,"mc":[{"id":"1.187557985","rc":[{"batl":[[0,1.68,141.66],[1,1.7,236.51],[2,1.7,0]],"ltp":1.63,"tv":9858.96,"id":5300820}]}]}
{"op":"mcm","clk":"4214929079","pt":1631532498133,"mc":[{"id":"1.187557985","rc":[{"batb":[[0,1.63,4],[1,1.61,123.93],[2,1.6,2271.44]],"ltp":1.63,"tv":9858.96,"id":5300820}]}]}
{"op":"mcm","clk":"4214929304","pt":1631532500936,"mc":[{"id":"1.187557985","rc":[{"batl":[[0,1.79,174.19],[1,1.81,191.82],[2,2.24,302.67]],"ltp":1.63,"tv":9858.96,"id":5300820}]}]}
{"op":"mcm","clk":"4214929395","pt":1631532502359,"mc":[{"id":"1.187557985","rc":[{"batb":[[2,1.57,140.05]],"ltp":1.63,"tv":9858.96,"id":5300820}]}]}
{"op":"mcm","clk":"4214931022","pt":1631532525379,"mc":[{"id":"1.187557985","rc":[{"batl":[[2,2.24,0]],"ltp":1.63,"tv":9858.96,"id":5300820}]}]}
{"op":"mcm","clk":"4214931392","pt":1631532531487,"mc":[{"id":"1.187557985","rc":[{"batb":[[0,1.61,123.93],[1,1.57,140.05],[2,1.56,160.79]],"ltp":1.63,"tv":9858.96,"id":5300820},{"batb":[[0,2.46,67.53],[1,2.36,4],[2,2.34,4]],"batl":[[0,3.45,53.16],[1,2.62,0],[2,2.64,0]],"ltp":2.58,"tv":3566.9,"id":9629022}]}]}
{"op":"mcm","clk":"4214931406","pt":1631532531694,"mc":[{"id":"1.187557985","rc":[{"batb":[[0,1.57,140.05],[1,1.56,160.79],[2,1.55,141.67]],"ltp":1.63,"tv":9858.96,"id":5300820},{"batb":[[0,2.36,4],[1,2.34,4],[2,2.26,84.27]],"ltp":2.58,"tv":3566.9,"id":9629022}]}]}
{"op":"mcm","clk":"4214931559","pt":1631532534275,"mc":[{"id":"1.187557985","rc":[{"batb":[[0,1.55,141.67],[1,1.5,7],[2,1.45,4.26]],"batl":[[0,1.63,2.32],[1,1.81,0]],"ltp":1.63,"tv":9858.96,"id":5300820}]}]}
{"op":"mcm","clk":"4214931597","pt":1631532534896,"mc":[{"id":"1.187557985","rc":[{"batl":[[1,1.74,5]],"ltp":1.63,"tv":9858.96,"id":5300820}]}]}
{"op":"mcm","clk":"4214931752","pt":1631532537583,"mc":[{"id":"1.187557985","rc":[{"trd":[[1.63,76.64],[1.65,4.64]],"batb":[[0,1.65,193.83],[1,1.64,133.54],[2,1.55,141.67]],"batl":[[0,1.7,141.41],[1,1.72,227.27],[2,1.74,5]],"ltp":1.65,"tv":9868.25,"id":5300820}],"tv":13435.16}]}
{"op":"mcm","clk":"4214931842","pt":1631532539290,"mc":[{"id":"1.187557985","rc":[{"trd":[[1.65,9.29]],"batb":[[0,1.65,191.51]],"ltp":1.65,"tv":9872.89,"id":5300820}],"tv":13439.8}]}
{"op":"mcm","clk":"4214931908","pt":1631532540376,"mc":[{"id":"1.187557985","rc":[{"batb":[[0,1.55,141.67],[1,1.5,7],[2,1.45,4.26]],"batl":[[0,1.7,4],[1,1.74,5],[2,1.74,0]],"ltp":1.65,"tv":9872.89,"id":5300820},{"batb":[[0,2.42,4],[1,2.4,3],[2,2.36,4]],"ltp":2.58,"tv":3566.9,"id":9629022}]}]}
{"op":"mcm","clk":"4214931924","pt":1631532540689,"mc":[{"id":"1.187557985","rc":[{"batb":[[2,2.26,84.27]],"ltp":2.58,"tv":3566.9,"id":9629022}]}]}
{"op":"mcm","clk":"4214932105","pt":1631532543761,"mc":[{"id":"1.187557985","rc":[{"batb":[[0,1.57,136.01],[1,1.56,160.79],[2,1.55,141.67]],"batl":[[2,1.79,177.71]],"ltp":1.65,"tv":9872.89,"id":5300820}]}]}
{"op":"mcm","clk":"4214932194","pt":1631532545003,"mc":[{"id":"1.187557985","rc":[{"batl":[[2,1.79,0]],"ltp":1.65,"tv":9872.89,"id":5300820}]}]}
{"op":"mcm","clk":"4214932282","pt":1631532546662,"mc":[{"id":"1.187557985","rc":[{"batl":[[0,1.6,3926.88],[1,1.66,17.98],[2,1.7,4]],"ltp":1.65,"tv":9872.89,"id":5300820}]}]}
{"op":"mcm","clk":"4214932334","pt":1631532547488,"mc":[{"id":"1.187557985","rc":[{"trd":[[1.57,877.77]],"batb":[[0,1.56,160.79],[1,1.55,141.67],[2,1.5,7]],"batl":[[0,1.7,4],[1,1.74,5],[2,1.7,0]],"ltp":1.57,"tv":9898.87,"id":5300820},{"batb":[[0,2.62,538.18],[1,2.6,269.09],[2,2.58,269.09]],"ltp":2.58,"tv":3566.9,"id":9629022}],"tv":13465.78}]}
{"op":"mcm","clk":"4214932401","pt":1631532548572,"mc":[{"id":"1.187557985","rc":[{"batb":[[2,1.5,168.75]],"batl":[[0,1.61,165.92],[1,1.62,139.24],[2,1.7,4]],"ltp":1.57,"tv":9898.87,"id":5300820},{"batb":[[1,2.6,326.91]],"batl":[[0,3.25,6.15],[1,3.45,53.16]],"ltp":2.58,"tv":3566.9,"id":9629022}]}]}
{"op":"mcm","clk":"4214932537","pt":1631532550593,"mc":[{"id":"1.187557985","rc":[{"batb":[[0,1.56,290.52],[1,1.55,307.21]],"batl":[[2,1.69,244.44]],"ltp":1.57,"tv":9898.87,"id":5300820}]}]}
{"op":"mcm","clk":"4214932545","pt":1631532550698,"mc":[{"id":"1.187557985","rc":[{"batl":[[2,1.69,6]],"ltp":1.57,"tv":9898.87,"id":5300820},{"batl":[[0,2.78,4],[1,3.25,6.15],[2,3.45,53.16]],"ltp":2.58,"tv":3566.9,"id":9629022}]}]}
{"op":"mcm","clk":"4214932630","pt":1631532552296,"mc":[{"id":"1.187557985","rc":[{"batb":[[2,1.5,161.75]],"ltp":1.57,"tv":9898.87,"id":5300820}]}]}
{"op":"mcm","clk":"4214932781","pt":1631532555088,"mc":[{"id":"1.187557985","rc":[{"batb":[[0,1.58,20.68],[1,1.56,290.52],[2,1.55,307.21]],"ltp":1.57,"tv":9898.87,"id":5300820}]}]}
{"op":"mcm","clk":"4214932964","pt":1631532558300,"mc":[{"id":"1.187557985","rc":[{"trd":[[1.61,4.64]],"batl":[[0,1.61,163.6],[2,1.67,34.5]],"ltp":1.61,"tv":9903.52,"id":5300820},{"batl":[[1,2.8,5.22],[2,3.25,6.15]],"ltp":2.58,"tv":3566.9,"id":9629022}],"tv":13470.42}]}
{"op":"mcm","clk":"4214933179","pt":1631532561517,"mc":[{"id":"1.187557985","marketDefinition":{"bspMarket":false,"turnInPlayEnabled":true,"persistenceEnabled":true,"marketBaseRate":5.0,"eventId":"30896136","eventTypeId":"2","numberOfWinners":1,"bettingType":"ODDS","marketType":"MATCH_ODDS","marketTime":"2021-09-13T11:30:00.000Z","suspendTime":"2021-09-13T11:30:00.000Z","bspReconciled":false,"complete":true,"inPlay":true,"crossMatching":true,"runnersVoidable":false,"numberOfActiveRunners":2,"betDelay":3,"status":"OPEN","runners":[{"status":"ACTIVE","sortPriority":1,"id":5300820,"name":"Aleksandra Krunic"},{"status":"ACTIVE","sortPriority":2,"id":9629022,"name":"Susan Bandecchi"}],"regulators":["MR_INT"],"discountAllowed":true,"timezone":"UTC","openDate":"2021-09-13T11:25:00.000Z","version":4030590681,"name":"Match Odds","eventName":"Krunic v Bandecchi"},"rc":[{"batl":[[2,2.86,4.75]],"ltp":2.58,"tv":3566.9,"id":9629022}]}]}
{"op":"mcm","clk":"4214933237","pt":1631532562501,"mc":[{"id":"1.187557985","rc":[{"batb":[[1,1.5,161.75],[2,1.45,4.26]],"batl":[[0,1.67,34.5],[1,1.69,6],[2,1.7,33.55]],"ltp":1.61,"tv":9903.52,"id":5300820},{"batb":[[0,2.44,3],[1,2.42,70.63],[2,1.8,11.88]],"batl":[[0,2.86,4.75],[1,3.45,53.16],[2,2.86,0]],"ltp":2.58,"tv":3566.9,"id":9629022}]}]}
{"op":"mcm","clk":"4214933252","pt":1631532562709,"mc":[{"id":"1.187557985","rc":[{"batl":[[0,1.69,6],[1,1.71,33.5],[2,2.04,388.3]],"ltp":1.61,"tv":9903.52,"id":5300820}]}]}
{"op":"mcm","clk":"4214933359","pt":1631532564411,"mc":[{"id":"1.187557985","marketDefinition":{"bspMarket":false,"turnInPlayEnabled":true,"persistenceEnabled":true,"marketBaseRate":5.0,"eventId":"30896136","eventTypeId":"2","numberOfWinners":1,"bettingType":"ODDS","marketType":"MATCH_ODDS","marketTime":"2021-09-13T11:30:00.000Z","suspendTime":"2021-09-13T11:30:00.000Z","bspReconciled":false,"complete":true,"inPlay":true,"crossMatching":true,"runnersVoidable":false,"numberOfActiveRunners":2,"betDelay":3,"status":"OPEN","runners":[{"status":"ACTIVE","sortPriority":1,"id":5300820,"name":"Aleksandra Krunic"},{"status":"ACTIVE","sortPriority":2,"id":9629022,"name":"Susan Bandecchi"}],"regulators":["MR_INT"],"discountAllowed":true,"timezone":"UTC","openDate":"2021-09-13T11:30:00.000Z","version":4030590681,"name":"Match Odds","eventName":"Krunic v Bandecchi"},"rc":[{"batb":[[1,1.54,48.12],[2,1.5,161.75]],"ltp":1.61,"tv":9903.52,"id":5300820},{"batb":[[2,2.4,6.41]],"ltp":2.58,"tv":3566.9,"id":9629022}]}]}
{"op":"mcm","clk":"4214933414","pt":1631532565297,"mc":[{"id":"1.187557985","rc":[{"batb":[[2,1.51,255.23]],"batl":[[1,1.7,195.13],[2,1.71,33.5]],"ltp":1.61,"tv":9903.52,"id":5300820}]}]}
{"op":"mcm","clk":"4214933476","pt":1631532566228,"mc":[{"id":"1.187557985","rc":[{"batb":[[2,1.5,161.75]],"batl":[[0,1.67,5],[1,1.69,6]],"ltp":1.61,"tv":9903.52,"id":5300820},{"batb":[[0,2.48,3],[1,2.46,3],[2,2.44,3]],"ltp":2.58,"tv":3566.9,"id":9629022}]}]}
{"op":"mcm","clk":"4214933613","pt":1631532568614,"mc":[{"id":"1.187557985","rc":[{"batl":[[1,1.68,4],[2,1.69,6]],"ltp":1.61,"tv":9903.52,"id":5300820}]}]}
{"op":"mcm","clk":"4214933641","pt":1631532569132,"mc":[{"id":"1.187557985","rc":[{"batb":[[1,1.56,291.84],[2,1.55,165.55]],"batl":[[0,1.61,171.64],[1,1.62,139.24],[2,1.67,5]],"ltp":1.61,"tv":9903.52,"id":5300820}]}]}
{"op":"mcm","clk":"4214933763","pt":1631532571254,"mc":[{"id":"1.187557985","rc":[{"batb":[[1,1.54,48.12],[2,1.5,161.75]],"batl":[[0,1.67,5],[1,1.68,4],[2,1.69,6]],"ltp":1.61,"tv":9903.52,"id":5300820}]}]}
{"op":"mcm","clk":"4214933805","pt":1631532571931,"mc":[{"id":"1.187557985","rc":[{"batb":[[0,1.54,48.12],[1,1.5,161.75],[2,1.45,4.26]],"ltp":1.61,"tv":9903.52,"id":5300820}]}]}
{"op":"mcm","clk":"4214933950","pt":1631532574126,"mc":[{"id":"1.187557985","rc":[{"batb":[[1,1.51,255.23],[2,1.5,350.26]],"ltp":1.61,"tv":9903.52,"id":5300820}]}]}
{"op":"mcm","clk":"4214934008","pt":1631532575012,"mc":[{"id":"1.187557985","rc":[{"batb":[[0,1.61,20.68],[1,1.54,48.12],[2,1.51,255.23]],"ltp":1.61,"tv":9903.52,"id":5300820}]}]}
{"op":"mcm","clk":"4214934086","pt":1631532576621,"mc":[{"id":"1.187557985","rc":[{"trd":[[1.67,4.64]],"batl":[[0,1.67,2.68]],"ltp":1.67,"tv":9908.16,"id":5300820}],"tv":13475.07}]}
{"op":"mcm","clk":"4214934272","pt":1631532579419,"mc":[{"id":"1.187557985","rc":[{"batl":[[0,1.68,4],[1,1.71,33.5],[2,2.04,388.3]],"ltp":1.67,"tv":9908.16,"id":5300820},{"batb":[[1,2.42,70.63],[2,2.4,6.41]],"ltp":2.58,"tv":3566.9,"id":9629022}]}]}
{"op":"mcm","clk":"4214934408","pt":1631532581648,"mc":[{"id":"1.187557985","rc":[{"trd":[[1.54,888.41],[1.61,46]],"batb":[[0,1.54,34.87],[1,1.51,255.23],[2,1.5,350.26]],"batl":[[0,1.56,293.08],[1,1.57,155.71],[2,1.61,20.5]],"ltp":1.54,"tv":9976.02,"id":5300820},{"batb":[[0,2.76,851.44],[1,2.74,425.72],[2,2.72,425.72]],"ltp":2.58,"tv":3566.9,"id":9629022}],"tv":13542.93}]}
{"op":"mcm","clk":"4214934484","pt":1631532582533,"mc":[{"id":"1.187557985","rc":[{"batl":[[2,1.68,4]],"ltp":1.54,"tv":9976.02,"id":5300820},{"batb":[[0,2.76,219.57],[1,2.74,85.14],[2,2.72,85.14]],"batl":[[1,3.4,5.88],[2,3.45,53.16]],"ltp":2.58,"tv":3566.9,"id":9629022}]}]}
{"op":"mcm","clk":"4214934610","pt":1631532584455,"mc":[{"id":"1.187557985","rc":[{"batl":[[2,1.67,4]],"ltp":1.54,"tv":9976.02,"id":5300820}]}]}
{"op":"mcm","clk":"4214934808","pt":1631532587853,"mc":[{"id":"1.187557985","rc":[{"batl":[[0,1.56,419.08]],"ltp":1.54,"tv":9976.02,"id":5300820}]}]}
{"op":"mcm","clk":"4214935009","pt":1631532590869,"mc":[{"id":"1.187557985","rc":[{"trd":[[2.86,129.69]],"batl":[[0,2.86,1.75]],"ltp":2.86,"tv":3572.9,"id":9629022}],"tv":13548.93}]}
{"op":"mcm","clk":"4214935257","pt":1631532594402,"mc":[{"id":"1.187557985","rc":[{"batb":[[0,2.76,49.29],[1,2.58,58.58],[2,2.5,3]],"batl":[[1,2.96,4]],"ltp":2.86,"tv":3572.9,"id":9629022}]}]}
{"op":"mcm","clk":"4214935325","pt":1631532595554,"mc":[{"id":"1.187557985","rc":[{"batb":[[0,1.46,179.08],[1,1.45,4.26],[2,1.38,454.63]],"batl":[[0,1.67,4],[1,1.68,4],[2,1.71,33.5]],"ltp":1.54,"tv":9976.02,"id":5300820},{"batb":[[0,2.58,58.58],[1,2.5,3],[2,2.48,3]],"batl":[[0,2.96,4],[1,3.45,53.16],[2,3.45,0]],"ltp":2.86,"tv":3572.9,"id":9629022}]}]}
{"op":"mcm","clk":"4214935341","pt":1631532595803,"mc":[{"id":"1.187557985","rc":[{"batl":[[2,2.04,388.3]],"ltp":1.54,"tv":9976.02,"id":5300820}]}]}
{"op":"mcm","clk":"4214935499","pt":1631532598506,"mc":[{"id":"1.187557985","rc":[{"batb":[[0,1.5,7],[1,1.49,6],[2,1.46,186.08]],"batl":[[1,2.04,388.3],[2,2.04,0]],"ltp":1.54,"tv":9976.02,"id":5300820},{"batb":[[2,1.8,11.88]],"ltp":2.86,"tv":3572.9,"id":9629022}]}]}
{"op":"mcm","clk":"4214935513","pt":1631532598712,"mc":[{"id":"1.187557985","rc":[{"batl":[[0,1.64,4],[1,1.67,4],[2,2.04,388.3]],"ltp":1.54,"tv":9976.02,"id":5300820},{"batb":[[0,2.58,61.58],[1,2.56,4],[2,2.5,3]],"ltp":2.86,"tv":3572.9,"id":9629022}]}]}
{"op":"mcm","clk":"4214935727","pt":1631532601649,"mc":[{"id":"1.187557985","rc":[{"batb":[[2,1.47,6]],"ltp":1.54,"tv":9976.02,"id":5300820}]}]}
{"op":"mcm","clk":"4214935760","pt":1631532602119,"mc":[{"id":"1.187557985","rc":[{"batb":[[0,1.52,277.01],[1,1.51,183.6],[2,1.5,7]],"batl":[[0,1.57,253.74],[1,1.58,152.24],[2,1.64,4]],"ltp":1.54,"tv":9976.02,"id":5300820}]}]}
{"op":"mcm","clk":"4214935941","pt":1631532604646,"mc":[{"id":"1.187557985","rc":[{"batb":[[1,1.51,188.6]],"ltp":1.54,"tv":9976.02,"id":5300820},{"batl":[[0,2.94,2],[1,2.96,4],[2,3.45,53.16]],"ltp":2.86,"tv":3572.9,"id":9629022}]}]}
{"op":"mcm","clk":"4214935951","pt":1631532604757,"mc":[{"id":"1.187557985","rc":[{"batb":[[0,1.51,5],[1,1.5,7],[2,1.49,6]],"batl":[[0,1.64,4],[1,1.67,4],[2,2.04,388.3]],"ltp":1.54,"tv":9976.02,"id":5300820}]}]}
{"op":"mcm","clk":"4214936158","pt":1631532607947,"mc":[{"id":"1.187557985","rc":[{"batl":[[0,1.62,223.54],[1,1.63,136],[2,1.64,4]],"ltp":1.54,"tv":9976.02,"id":5300820}]}]}
{"op":"mcm","clk":"4214936333","pt":1631532610630,"mc":[{"id":"1.187557985","rc":[{"batb":[[0,1.57,220.99],[1,1.56,161.17],[2,1.51,5]],"batl":[[2,1.65,637.5]],"ltp":1.54,"tv":9976.02,"id":5300820},{"batb":[[0,2.58,58.58],[1,1.8,11.88],[2,1.7,16.97]],"batl":[[0,2.8,683.04],[1,2.82,662.94],[2,2.84,662.94]],"ltp":2.86,"tv":3572.9,"id":9629022}]}]}
{"op":"mcm","clk":"4214936396","pt":1631532611642,"mc":[{"id":"1.187557985","rc":[{"trd":[[1.57,903.75]],"batb":[[0,1.57,208],[1,1.56,301.25]],"ltp":1.57,"tv":10002.0,"id":5300820},{"batb":[[1,2.38,73.72],[2,1.8,11.88]],"ltp":2.86,"tv":3572.9,"id":9629022}],"tv":13574.91}]}
{"op":"mcm","clk":"4214936537","pt":1631532613582,"mc":[{"id":"1.187557985","rc":[{"batb":[[1,1.56,306.25],[2,1.55,7]],"ltp":1.57,"tv":10002.0,"id":5300820},{"batb":[[1,2.5,4],[2,2.48,4]],"batl":[[0,2.78,3],[1,2.8,683.04],[2,2.82,662.94]],"ltp":2.86,"tv":3572.9,"id":9629022}]}]}
{"op":"mcm","clk":"4214937199","pt":1631532623548,"mc":[{"id":"1.187557985","rc":[{"batb":[[0,1.5,160.33],[1,1.45,4.26],[2,1.4,7]],"batl":[[0,2.04,388.3],[1,1.63,0],[2,1.65,0]],"ltp":1.57,"tv":10002.0,"id":5300820},{"batb":[[0,2.5,4],[1,2.48,4],[2,2.38,73.72]],"batl":[[0,3.45,53.16],[1,2.8,0],[2,2.82,0]],"ltp":2.86,"tv":3572.9,"id":9629022}]}]}
{"op":"mcm","clk":"4214937362","pt":1631532626529,"mc":[{"id":"1.187557985","rc":[{"batb":[[0,1.51,225.65],[1,1.5,348.71],[2,1.45,4.26]],"batl":[[0,1.72,226.22],[1,1.74,218.3],[2,2.04,388.3]],"ltp":1.57,"tv":10002.0,"id":5300820}]}]}
{"op":"mcm","clk":"4214937373","pt":1631532626742,"mc":[{"id":"1.187557985","rc":[{"batb":[[1,1.5,353.71],[2,1.49,7]],"batl":[[0,1.67,5],[1,1.72,226.22],[2,1.74,218.3]],"ltp":1.57,"tv":10002.0,"id":5300820},{"batb":[[1,2.38,73.72],[2,1.8,11.88]],"batl":[[0,3,3],[1,3.45,53.16]],"ltp":2.86,"tv":3572.9,"id":9629022}]}]}
{"op":"mcm","clk":"4214937468","pt":1631532628151,"mc":[{"id":"1.187557985","rc":[{"batl":[[1,2.04,388.3],[2,1.74,0]],"ltp":1.57,"tv":10002.0,"id":5300820}]}]}
{"op":"mcm","clk":"4214937581","pt":1631532630188,"mc":[{"id":"1.187557985","rc":[{"batb":[[0,1.51,230.65]],"ltp":1.57,"tv":10002.0,"id":5300820},{"batb":[[1,2.48,3],[2,2.38,73.72]],"batl":[[0,2.98,2],[1,3,3],[2,3.45,53.16]],"ltp":2.86,"tv":3572.9,"id":9629022}]}]}
{"op":"mcm","clk":"4214937678","pt":1631532631453,"mc":[{"id":"1.187557985","rc":[{"trd":[[1.51,452.55]],"batb":[[0,1.51,217.32]],"batl":[[0,1.55,161.99],[1,1.56,1386.14],[2,1.57,1189.9]],"ltp":1.51,"tv":10028.66,"id":5300820}],"tv":13601.57}]}
{"op":"mcm","clk":"4214937728","pt":1631532632345,"mc":[{"id":"1.187557985","rc":[{"batb":[[0,2.76,49.79],[1,2.58,58.66],[2,2.5,4]],"batl":[[2,3.45,58.96]],"ltp":2.86,"tv":3572.9,"id":9629022}]}]}
{"op":"mcm","clk":"4214937775","pt":1631532633335,"mc":[{"id":"1.187557985","rc":[{"batb":[[2,2.52,3]],"batl":[[0,2.96,3],[1,2.98,2],[2,3,3]],"ltp":2.86,"tv":3572.9,"id":9629022}]}]}
{"op":"mcm","clk":"4214938041","pt":1631532637566,"mc":[{"id":"1.187557985","rc":[{"batb":[[0,1.51,264.31],[1,1.5,402.63]],"ltp":1.51,"tv":10028.66,"id":5300820},{"batb":[[1,2.66,5.28],[2,2.58,58.66]],"batl":[[1,2.98,6.75],[2,3,7.76]],"ltp":2.86,"tv":3572.9,"id":9629022}]}]}
{"op":"mcm","clk":"4214938216","pt":1631532639959,"mc":[{"id":"1.187557985","rc":[{"trd":[[1.51,493.05]],"batb":[[0,1.51,244.06],[1,1.5,397.63],[2,1.48,710.72]],"ltp":1.51,"tv":10069.16,"id":5300820}],"tv":13642.07}]}
{"op":"mcm","clk":"4214938399","pt":1631532642556,"mc":[{"id":"1.187557985","rc":[{"batb":[[2,1.46,178.66]],"batl":[[1,1.56,160.18],[2,1.6,42.51]],"ltp":1.51,"tv":10069.16,"id":5300820},{"batl":[[1,2.98,4.75],[2,3,4.76]],"ltp":2.86,"tv":3572.9,"id":9629022}]}]}
{"op":"mcm","clk":"4214938458","pt":1631532643593,"mc":[{"id":"1.187557985","rc":[{"batb":[[0,1.5,48.92],[1,1.46,178.66],[2,1.45,4.26]],"batl":[[0,1.64,43.68],[1,1.66,5],[2,1.67,5]],"ltp":1.51,"tv":10069.16,"id":5300820},{"batb":[[0,2.58,58.66],[1,2.56,5.33],[2,2.52,3]],"batl":[[0,3,4.76],[1,3.45,53.16],[2,3,0]],"ltp":2.86,"tv":3572.9,"id":9629022}]}]}
{"op":"mcm","clk":"4214938660","pt":1631532646614,"mc":[{"id":"1.187557985","rc":[{"batl":[[0,1.61,5],[1,1.64,47.68],[2,1.66,5]],"ltp":1.51,"tv":10069.16,"id":5300820},{"batb":[[0,2.58,61.66],[1,2.56,8.33]],"ltp":2.86,"tv":3572.9,"id":9629022}]}]}
{"op":"mcm","clk":"4214938835","pt":1631532649396,"mc":[{"id":"1.187557985","rc":[{"batb":[[0,2.62,3],[1,2.6,3],[2,2.58,61.66]],"ltp":2.86,"tv":3572.9,"id":9629022}]}]}
{"op":"mcm","clk":"4214938890","pt":1631532650193,"mc":[{"id":"1.187557985","rc":[{"batb":[[0,1.52,222.92],[1,1.51,183.45],[2,1.5,48.92]],"batl":[[0,1.56,149.85],[1,1.57,156.51],[2,1.61,5]],"ltp":1.51,"tv":10069.16,"id":5300820}]}]}
{"op":"mcm","clk":"4214939097","pt":1631532653575,"mc":[{"id":"1.187557985","rc":[{"batb":[[0,1.5,48.92],[1,1.46,178.66],[2,1.45,4.26]],"batl":[[0,1.61,5],[1,1.64,47.68],[2,1.66,5]],"ltp":1.51,"tv":10069.16,"id":5300820}]}]}
{"op":"mcm","clk":"4214939310","pt":1631532656591,"mc":[{"id":"1.187557985","rc":[{"batb":[[0,1.51,48.99],[1,1.5,48.92],[2,1.46,178.66]],"batl":[[0,1.61,162.67],[1,1.62,139.39],[2,1.64,47.68]],"ltp":1.51,"tv":10069.16,"id":5300820},{"batl":[[0,2.98,4.25],[1,3,4.76],[2,3.45,53.16]],"ltp":2.86,"tv":3572.9,"id":9629022}]}]}
{"op":"mcm","clk":"4214939347","pt":1631532657209,"mc":[{"id":"1.187557985","rc":[{"batb":[[0,1.5,48.92],[1,1.46,178.66],[2,1.45,4.26]],"ltp":1.51,"tv":10069.16,"id":5300820},{"batl":[[0,3,4.76],[1,3.45,53.16],[2,3.45,0]],"ltp":2.86,"tv":3572.9,"id":9629022}]}]}
{"op":"mcm","clk":"4214939414","pt":1631532658610,"mc":[{"id":"1.187557985","rc":[{"batb":[[0,1.57,145.15],[1,1.56,160.97],[2,1.5,48.92]],"batl":[[0,1.61,157.67],[2,1.63,1173.32]],"ltp":1.51,"tv":10069.16,"id":5300820},{"batb":[[0,2.58,58.66],[1,2.56,5.33],[2,1.8,11.88]],"batl":[[0,2.84,673.42],[1,2.86,653.6],[2,2.88,653.6]],"ltp":2.86,"tv":3572.9,"id":9629022}]}]}
{"op":"mcm","clk":"4214939475","pt":1631532659596,"mc":[{"id":"1.187557985","rc":[{"trd":[[1.57,929.89]],"batb":[[0,1.57,132.08],[1,1.56,300.88]],"ltp":1.57,"tv":10095.3,"id":5300820},{"batb":[[2,2.36,75.15]],"ltp":2.86,"tv":3572.9,"id":9629022}],"tv":13668.21}]}
{"op":"mcm","clk":"4214939582","pt":1631532661480,"mc":[{"id":"1.187557985","rc":[{"batb":[[2,1.55,5]],"ltp":1.57,"tv":10095.3,"id":5300820},{"batl":[[0,2.78,3],[1,2.82,3],[2,2.84,673.42]],"ltp":2.86,"tv":3572.9,"id":9629022}]}]}
{"op":"mcm","clk":"4214939886","pt":1631532666386,"mc":[{"id":"1.187557985","rc":[{"batb":[[2,2.5,5.64]],"ltp":2.86,"tv":3572.9,"id":9629022}]}]}
{"op":"mcm","clk":"4214940373","pt":1631532675621,"mc":[{"id":"1.187557985","rc":[{"batb":[[0,1.54,48.62],[1,1.51,56.99],[2,1.5,48.92]],"batl":[[0,1.64,43.68],[1,1.66,32.75],[2,1.7,31.65]],"ltp":1.57,"tv":10095.3,"id":5300820},{"batb":[[0,2.56,5.33],[1,2.5,5.64],[2,2.42,5.63]],"batl":[[0,2.86,5.25],[1,2.98,4.25],[2,3,4.76]],"ltp":2.86,"tv":3572.9,"id":9629022}]}]}
{"op":"mcm","clk":"4214940395","pt":1631532675927,"mc":[{"id":"1.187557985","rc":[{"batb":[[0,1.51,56.99],[1,1.49,164.93],[2,1.45,4.26]],"batl":[[0,1.7,31.65],[1,2.04,388.3],[2,1.7,0]],"ltp":1.57,"tv":10095.3,"id":5300820},{"batb":[[0,2.42,5.63],[1,2.36,75.15],[2,1.8,11.88]],"batl":[[0,2.98,4.25],[1,3.45,53.16],[2,3,0]],"ltp":2.86,"tv":3572.9,"id":9629022}]}]}
{"op":"mcm","clk":"4214940524","pt":1631532678527,"mc":[{"id":"1.187557985","rc":[{"batb":[[1,1.5,176.19],[2,1.49,358.4]],"batl":[[1,1.72,129.45],[2,1.74,218.83]],"ltp":1.57,"tv":10095.3,"id":5300820}]}]}
{"op":"mcm","clk":"4214940584","pt":1631532679622,"mc":[{"id":"1.187557985","rc":[{"batb":[[1,1.5,5],[2,1.49,164.93]],"batl":[[0,1.7,36.65],[1,2.04,388.3],[2,1.74,0]],"ltp":1.57,"tv":10095.3,"id":5300820},{"batb":[[0,2.52,3],[1,2.5,4],[2,2.42,8.63]],"batl":[[0,2.98,7.25]],"ltp":2.86,"tv":3572.9,"id":9629022}]}]}
{"op":"mcm","clk":"4214940764","pt":1631532682525,"mc":[{"id":"1.187557985","rc":[{"batb":[[0,1.54,48.12],[1,1.51,56.99],[2,1.5,5]],"batl":[[0,1.66,37.25],[1,1.67,4],[2,1.7,36.65]],"ltp":1.57,"tv":10095.3,"id":5300820},{"batb":[[1,2.5,9.6]],"batl":[[0,2.86,4.25],[1,2.98,7.25],[2,3.45,53.16]],"ltp":2.86,"tv":3572.9,"id":9629022}]}]}
{"op":"mcm","clk":"4214940783","pt":1631532682834,"mc":[{"id":"1.187557985","rc":[{"batb":[[0,1.59,133.27],[1,1.58,153.29],[2,1.51,56.99]],"batl":[[0,1.63,146.23],[1,1.64,133.44],[2,1.66,5]],"ltp":1.57,"tv":10095.3,"id":5300820},{"batb":[[1,2.5,4]],"batl":[[0,2.98,7.25],[1,3.45,53.16],[2,3.45,0]],"ltp":2.86,"tv":3572.9,"id":9629022}]}]}
{"op":"mcm","clk":"4214940929","pt":1631532685425,"mc":[{"id":"1.187557985","rc":[{"batb":[[0,1.51,56.99],[1,1.5,5],[2,1.49,164.93]],"batl":[[0,1.66,5],[1,1.67,4],[2,1.7,36.65]],"ltp":1.57,"tv":10095.3,"id":5300820}]}]}
{"op":"mcm","clk":"4214941042","pt":1631532687804,"mc":[{"id":"1.187557985","rc":[{"batb":[[1,1.5,181.19],[2,1.49,358.4]],"ltp":1.57,"tv":10095.3,"id":5300820}]}]}
{"op":"mcm","clk":"4214941222","pt":1631532692516,"mc":[{"id":"1.187557985","rc":[{"batb":[[1,1.49,164.93],[2,1.45,4.26]],"ltp":1.57,"tv":10095.3,"id":5300820},{"batb":[[1,2.42,5.63],[2,2.36,75.15]],"ltp":2.86,"tv":3572.9,"id":9629022}]}]}
{"op":"mcm","clk":"4214941260","pt":1631532693244,"mc":[{"id":"1.187557985","rc":[{"trd":[[1.66,82.05],[1.67,20.66]],"batl":[[0,1.7,36.65],[1,1.72,129.45],[2,1.74,218.83]],"ltp":1.67,"tv":10193.37,"id":5300820},{"trd":[[2.5,5.36],[2.52,3]],"batb":[[0,2.42,5.63],[1,2.36,75.15],[2,1.8,11.88]],"ltp":2.5,"tv":3581.26,"id":9629022}],"tv":13774.64}]}
{"op":"mcm","clk":"4214941328","pt":1631532694538,"mc":[{"id":"1.187557985","rc":[{"batl":[[0,1.7,31.65]],"ltp":1.67,"tv":10193.37,"id":5300820},{"batb":[[2,2.34,1634.62]],"batl":[[0,2.56,1494.14],[1,2.58,1450.2],[2,2.6,1450.2]],"ltp":2.5,"tv":3581.26,"id":9629022}]}]}
{"op":"mcm","clk":"4214941378","pt":1631532695613,"mc":[{"id":"1.187557985","rc":[{"trd":[[1.67,50.15]],"batb":[[0,1.67,172.15],[1,1.66,127.92],[2,1.65,112.97]],"ltp":1.67,"tv":10222.86,"id":5300820},{"trd":[[2.5,8.36]],"batb":[[2,2.34,449.53]],"batl":[[0,2.56,747.06],[1,2.58,725.1],[2,2.6,725.1]],"ltp":2.5,"tv":3584.26,"id":9629022}],"tv":13807.13}]}
{"op":"mcm","clk":"4214941518","pt":1631532698352,"mc":[{"id":"1.187557985","rc":[{"batb":[[2,1.65,116.97]],"ltp":1.67,"tv":10222.86,"id":5300820},{"batl":[[0,2.54,3],[1,2.56,747.06],[2,2.58,725.1]],"ltp":2.5,"tv":3584.26,"id":9629022}]}]}
{"op":"mcm","clk":"4214942353","pt":1631532714361,"mc":[{"id":"1.187557985","rc":[{"batb":[[0,1.58,45.56],[1,1.56,137.65],[2,1.53,54.33]],"batl":[[0,1.84,32.03],[1,1.91,27.5],[2,2.04,388.3]],"ltp":1.67,"tv":10222.86,"id":5300820},{"batb":[[0,2.18,6.36],[1,2.12,101.25],[2,2.08,7.81]],"batl":[[0,2.74,4.98],[1,2.9,4.25],[2,2.98,4.25]],"ltp":2.5,"tv":3584.26,"id":9629022}]}]}
{"op":"mcm","clk":"4214942374","pt":1631532714673,"mc":[{"id":"1.187557985","rc":[{"batb":[[0,1.56,137.65],[1,1.53,54.33],[2,1.52,7]],"batl":[[0,1.91,27.5],[1,2.04,388.3],[2,2.04,0]],"ltp":1.67,"tv":10222.86,"id":5300820},{"batb":[[0,2.12,101.25],[1,2.08,7.81],[2,1.7,16.97]],"batl":[[0,2.9,4.25],[1,2.98,4.25],[2,3.45,53.16]],"ltp":2.5,"tv":3584.26,"id":9629022}]}]}
{"op":"mcm","clk":"4214942517","pt":1631532717585,"mc":[{"id":"1.187557985","rc":[{"batl":[[0,1.84,5],[1,1.91,27.5],[2,2.04,388.3]],"ltp":1.67,"tv":10222.86,"id":5300820},{"batb":[[0,2.18,4],[1,2.16,3],[2,2.12,101.25]],"ltp":2.5,"tv":3584.26,"id":9629022}]}]}
{"op":"mcm","clk":"4214942564","pt":1631532718461,"mc":[{"id":"1.187557985","rc":[{"batb":[[0,1.57,236.92],[1,1.56,299.07],[2,1.53,54.33]],"batl":[[1,1.85,4],[2,1.9,4]],"ltp":1.67,"tv":10222.86,"id":5300820},{"batb":[[2,2.12,105.25]],"batl":[[0,2.8,3],[1,2.9,4.25],[2,2.98,4.25]],"ltp":2.5,"tv":3584.26,"id":9629022}]}]}
{"op":"mcm","clk":"4214942737","pt":1631532721577,"mc":[{"id":"1.187557985","rc":[{"trd":[[1.57,955.87]],"batb":[[0,1.57,223.93]],"batl":[[0,1.6,1762.5],[1,1.62,209.25],[2,1.63,136.21]],"ltp":1.57,"tv":10248.84,"id":5300820},{"batb":[[0,2.54,555.12],[1,2.52,277.56],[2,2.5,277.56]],"ltp":2.5,"tv":3584.26,"id":9629022}],"tv":13833.11}]}
{"op":"mcm","clk":"4214942787","pt":1631532722600,"mc":[{"id":"1.187557985","rc":[{"batb":[[0,2.56,59.83],[1,2.54,185.04],[2,2.52,92.52]],"batl":[[0,2.72,108],[1,2.74,54],[2,2.76,54]],"ltp":2.5,"tv":3584.26,"id":9629022}]}]}
{"op":"mcm","clk":"4214943069","pt":1631532728093,"mc":[{"id":"1.187557985","rc":[{"trd":[[1.6,1016.03]],"batb":[[2,1.54,48.62]],"batl":[[0,1.6,1760.5]],"ltp":1.6,"tv":10252.84,"id":5300820}],"tv":13837.11}]}
{"op":"mcm","clk":"4214943557","pt":1631532738526,"mc":[{"id":"1.187557985","rc":[{"batb":[[0,1.54,48.62],[1,1.53,54.33],[2,1.52,7]],"batl":[[0,1.66,40.25],[1,1.7,34.15],[2,1.83,4]],"ltp":1.6,"tv":10252.84,"id":5300820},{"batb":[[0,2.5,5.5],[1,2.42,6.44],[2,2.34,76.82]],"batl":[[0,2.8,3],[1,2.86,4.32],[2,2.9,4.25]],"ltp":2.5,"tv":3584.26,"id":9629022}]}]}
{"op":"mcm","clk":"4214943569","pt":1631532738734,"mc":[{"id":"1.187557985","rc":[{"batb":[[0,1.51,50.99],[1,1.5,161.92],[2,1.45,4.26]],"batl":[[0,1.7,34.15],[1,1.83,4],[2,1.91,27.5]],"ltp":1.6,"tv":10252.84,"id":5300820},{"batb":[[0,2.42,6.44],[1,2.34,76.82],[2,2.2,4]],"batl":[[0,2.98,4.25],[1,3.45,53.16],[2,2.9,0]],"ltp":2.5,"tv":3584.26,"id":9629022}]}]}
{"op":"mcm","clk":"4214943730","pt":1631532741532,"mc":[{"id":"1.187557985","rc":[{"batb":[[1,1.5,425.32],[2,1.49,194.08]],"batl":[[1,1.73,156.97],[2,1.75,214.65]],"ltp":1.6,"tv":10252.84,"id":5300820}]}]}
{"op":"mcm","clk":"4214943784","pt":1631532742516,"mc":[{"id":"1.187557985","rc":[{"batb":[[0,1.51,57.99],[1,1.5,167.92],[2,1.45,4.26]],"batl":[[0,1.66,5],[1,1.67,5],[2,1.7,39.15]],"ltp":1.6,"tv":10252.84,"id":5300820},{"batb":[[0,2.5,3],[1,2.48,3],[2,2.42,9.44]],"batl":[[0,2.94,3],[1,2.98,7.25],[2,3.45,53.16]],"ltp":2.5,"tv":3584.26,"id":9629022}]}]}
{"op":"mcm","clk":"4214943877","pt":1631532744534,"mc":[{"id":"1.187557985","rc":[{"batl":[[0,2.78,375.68],[1,2.94,3],[2,2.98,7.25]],"ltp":2.5,"tv":3584.26,"id":9629022}]}]}
{"op":"mcm","clk":"4214943919","pt":1631532745626,"mc":[{"id":"1.187557985","rc":[{"batb":[[0,1.59,223.94],[1,1.58,153.7],[2,1.54,47.12]],"batl":[[0,1.64,192.75],[1,1.65,130.5],[2,1.66,44.25]],"ltp":1.6,"tv":10252.84,"id":5300820},{"batb":[[0,2.5,8.79]],"batl":[[0,2.86,5.25]],"ltp":2.5,"tv":3584.26,"id":9629022}]}]}
{"op":"mcm","clk":"4214943924","pt":1631532745723,"mc":[{"id":"1.187557985","rc":[{"batb":[[2,1.51,57.99]],"batl":[[2,1.66,5]],"ltp":1.6,"tv":10252.84,"id":5300820},{"batb":[[0,2.5,3]],"batl":[[0,2.94,3],[1,2.98,7.25],[2,3.45,53.16]],"ltp":2.5,"tv":3584.26,"id":9629022}]}]}
{"op":"mcm","clk":"4214943996","pt":1631532747315,"mc":[{"id":"1.187557985","rc":[{"batb":[[0,1.51,57.99],[1,1.5,167.92],[2,1.45,4.26]],"batl":[[0,1.66,5],[1,1.67,5],[2,1.7,39.15]],"ltp":1.6,"tv":10252.84,"id":5300820}]}]}
{"op":"mcm","clk":"4214944139","pt":1631532750249,"mc":[{"id":"1.187557985","rc":[{"batb":[[1,1.5,431.32],[2,1.49,194.08]],"ltp":1.6,"tv":10252.84,"id":5300820}]}]}
{"op":"mcm","clk":"4214944427","pt":1631532756175,"mc":[{"id":"1.187557985","rc":[{"batb":[[1,1.5,425.32]],"batl":[[1,1.7,34.15],[2,1.73,156.97]],"ltp":1.6,"tv":10252.84,"id":5300820},{"batb":[[1,2.42,6.44],[2,2.34,76.82]],"batl":[[1,2.98,4.25]],"ltp":2.5,"tv":3584.26,"id":9629022}]}]}
{"op":"mcm","clk":"4214944580","pt":1631532759600,"mc":[{"id":"1.187557985","rc":[{"batb":[[1,1.5,429.32]],"ltp":1.6,"tv":10252.84,"id":5300820},{"batb":[[1,2.48,3],[2,2.42,6.44]],"ltp":2.5,"tv":3584.26,"id":9629022}]}]}
{"op":"mcm","clk":"4214944589","pt":1631532759704,"mc":[{"id":"1.187557985","rc":[{"batb":[[1,1.5,165.92],[2,1.45,4.26]],"ltp":1.6,"tv":10252.84,"id":5300820}]}]}
{"op":"mcm","clk":"4214944670","pt":1631532761087,"mc":[{"id":"1.187557985","rc":[{"trd":[[1.66,92.05],[1.67,54.64]],"batl":[[0,1.7,34.15],[1,1.73,156.97],[2,1.75,214.65]],"ltp":1.67,"tv":10267.33,"id":5300820},{"trd":[[2.5,11.36]],"batb":[[0,2.42,6.44],[1,2.34,76.82],[2,1.7,16.97]],"ltp":2.5,"tv":3587.26,"id":9629022}],"tv":13854.6}]}
{"op":"mcm","clk":"4214944751","pt":1631532762603,"mc":[{"id":"1.187557985","rc":[{"batb":[[0,1.65,1172.03],[1,1.64,1125],[2,1.63,1125]],"ltp":1.67,"tv":10267.33,"id":5300820},{"batb":[[2,2.3,457.34]],"batl":[[0,2.54,2.88],[1,2.94,3],[2,2.98,10.96]],"ltp":2.5,"tv":3587.26,"id":9629022}]}]}
{"op":"mcm","clk":"4214944814","pt":1631532763589,"mc":[{"id":"1.187557985","rc":[{"trd":[[1.68,24.84]],"batb":[[0,1.68,137.67],[1,1.67,125.16],[2,1.66,110.71]],"ltp":1.68,"tv":10292.17,"id":5300820}],"tv":13879.44}]}
{"op":"mcm","clk":"4214944864","pt":1631532764472,"mc":[{"id":"1.187557985","rc":[{"batb":[[0,1.68,142.67],[1,1.67,129.16]],"ltp":1.68,"tv":10292.17,"id":5300820},{"batl":[[0,2.48,2],[1,2.54,2.88],[2,2.92,3]],"ltp":2.5,"tv":3587.26,"id":9629022}]}]}
{"op":"mcm","clk":"4214944910","pt":1631532765613,"mc":[{"id":"1.187557985","rc":[{"batb":[[2,1.66,116.71]],"ltp":1.68,"tv":10292.17,"id":5300820},{"batl":[[1,2.52,3],[2,2.54,2.88]],"ltp":2.5,"tv":3587.26,"id":9629022}]}]}
{"op":"mcm","clk":"4214945465","pt":1631532775612,"mc":[{"id":"1.187557985","rc":[{"batb":[[2,2.26,3]],"ltp":2.5,"tv":3587.26,"id":9629022}]}]}
{"op":"mcm","clk":"4214945520","pt":1631532776394,"mc":[{"id":"1.187557985","rc":[{"batb":[[0,1.65,2096.71],[1,1.59,42.11],[2,1.58,134.14]],"batl":[[0,1.91,27.5],[1,2.04,388.3],[2,810,0.07]],"ltp":1.68,"tv":10292.17,"id":5300820},{"batb":[[0,2.12,102.68],[1,2.08,7.56],[2,1.7,16.97]],"batl":[[0,2.7,5.35],[1,2.86,4.75],[2,2.92,3]],"ltp":2.5,"tv":3587.26,"id":9629022}]}]}
{"op":"mcm","clk":"4214945584","pt":1631532777591,"mc":[{"id":"1.187557985","rc":[{"batb":[[0,1.58,134.14],[1,1.54,47.12],[2,1.52,5]],"ltp":1.68,"tv":10292.17,"id":5300820},{"batl":[[0,2.86,4.75],[1,2.92,3],[2,2.98,4.25]],"ltp":2.5,"tv":3587.26,"id":9629022}]}]}
{"op":"mcm","clk":"4214945703","pt":1631532779618,"mc":[{"id":"1.187557985","rc":[{"batl":[[0,1.84,34.03],[1,1.85,4],[2,1.9,4]],"ltp":1.68,"tv":10292.17,"id":5300820},{"batb":[[0,2.18,9.86],[1,2.16,4],[2,2.12,106.68]],"ltp":2.5,"tv":3587.26,"id":9629022}]}]}
{"op":"mcm","clk":"4214945749","pt":1631532780499,"mc":[{"id":"1.187557985","rc":[{"batl":[[0,1.84,4]],"ltp":1.68,"tv":10292.17,"id":5300820},{"batb":[[0,2.18,3]],"ltp":2.5,"tv":3587.26,"id":9629022}]}]}
{"op":"mcm","clk":"4214945810","pt":1631532781545,"mc":[{"id":"1.187557985","rc":[{"batl":[[0,2.54,404.1],[1,2.86,4.75],[2,2.92,3]],"ltp":2.5,"tv":3587.26,"id":9629022}]}]}
{"op":"mcm","clk":"4214945850","pt":1631532782325,"mc":[{"id":"1.187557985","rc":[{"batl":[[2,1.89,4]],"ltp":1.68,"tv":10292.17,"id":5300820},{"batl":[[0,2.86,4.75],[1,2.92,3],[2,2.98,4.25]],"ltp":2.5,"tv":3587.26,"id":9629022}]}]}
{"op":"mcm","clk":"4214945893","pt":1631532783213,"mc":[{"id":"1.187557985","rc":[{"batb":[[0,1.7,234.08],[1,1.68,243.88],[2,1.58,134.14]],"batl":[[0,1.76,161.48],[1,1.78,202.89],[2,1.84,31.03]],"ltp":1.68,"tv":10292.17,"id":5300820},{"batb":[[0,2.18,10.36]],"ltp":2.5,"tv":3587.26,"id":9629022}]}]}
{"op":"mcm","clk":"4214945976","pt":1631532784615,"mc":[{"id":"1.187557985","rc":[{"batb":[[0,1.59,48.11],[1,1.58,134.14],[2,1.54,47.12]],"batl":[[0,1.84,4],[1,1.85,4],[2,1.89,4]],"ltp":1.68,"tv":10292.17,"id":5300820},{"batb":[[0,2.18,3]],"batl":[[0,2.7,4.65],[1,2.86,4.75],[2,2.92,3]],"ltp":2.5,"tv":3587.26,"id":9629022}]}]}
{"op":"mcm","clk":"4214946012","pt":1631532785340,"mc":[{"id":"1.187557985","rc":[{"batb":[[0,1.58,134.14],[1,1.54,47.12],[2,1.52,5]],"ltp":1.68,"tv":10292.17,"id":5300820},{"batl":[[0,2.86,4.75],[1,2.92,3],[2,2.98,4.25]],"ltp":2.5,"tv":3587.26,"id":9629022}]}]}
{"op":"mcm","clk":"4214946077","pt":1631532787113,"mc":[{"id":"1.187557985","rc":[{"batb":[[0,1.58,304.97],[1,1.57,157.29],[2,1.54,47.12]],"batl":[[2,1.89,141.48]],"ltp":1.68,"tv":10292.17,"id":5300820}]}]}
{"op":"mcm","clk":"4214946139","pt":1631532788216,"mc":[{"id":"1.187557985","rc":[{"batl":[[0,1.83,4],[1,1.84,4],[2,1.85,4]],"ltp":1.68,"tv":10292.17,"id":5300820},{"batb":[[0,2.2,3],[1,2.18,3],[2,2.16,4]],"ltp":2.5,"tv":3587.26,"id":9629022}]}]}
{"op":"mcm","clk":"4214946329","pt":1631532791643,"mc":[{"id":"1.187557985","rc":[{"batl":[[1,1.89,141.48],[2,1.91,189.52]],"ltp":1.68,"tv":10292.17,"id":5300820},{"batb":[[1,2.12,102.68],[2,2.08,7.56]],"ltp":2.5,"tv":3587.26,"id":9629022}]}]}
{"op":"mcm","clk":"4214946484","pt":1631532794646,"mc":[{"id":"1.187557985","rc":[{"batl":[[1,1.84,30.78],[2,1.89,4]],"ltp":1.68,"tv":10292.17,"id":5300820},{"batb":[[1,2.18,10.47],[2,2.12,102.68]],"ltp":2.5,"tv":3587.26,"id":9629022}]}]}
{"op":"mcm","clk":"4214946536","pt":1631532795633,"mc":[{"id":"1.187557985","rc":[{"batl":[[1,1.89,4],[2,1.91,27.5]],"ltp":1.68,"tv":10292.17,"id":5300820},{"batb":[[1,2.18,4]],"ltp":2.5,"tv":3587.26,"id":9629022}]}]}
{"op":"mcm","clk":"4214946647","pt":1631532797655,"mc":[{"id":"1.187557985","rc":[{"trd":[[1.58,877.77]],"batb":[[0,1.58,291.98],[2,1.55,678.63]],"batl":[[0,1.63,272.56],[1,1.64,133.16],[2,1.65,1159.1]],"ltp":1.58,"tv":10318.15,"id":5300820}],"tv":13905.42}]}
{"op":"mcm","clk":"4214946704","pt":1631532798336,"mc":[{"id":"1.187557985","rc":[{"batb":[[0,2.54,61.67],[1,2.32,78.74],[2,2.2,3]],"ltp":2.5,"tv":3587.26,"id":9629022}]}]}
{"op":"mcm","clk":"4214946762","pt":1631532799270,"mc":[{"id":"1.187557985","rc":[{"batb":[[0,1.59,34.69],[1,1.58,291.98],[2,1.57,157.29]],"ltp":1.58,"tv":10318.15,"id":5300820},{"batb":[[2,2.28,15]],"batl":[[0,2.84,23.75],[1,2.86,4.75],[2,2.92,3]],"ltp":2.5,"tv":3587.26,"id":9629022}]}]}
{"op":"mcm","clk":"4214946932","pt":1631532802486,"mc":[{"id":"1.187557985","rc":[{"batl":[[0,2.86,4.75],[1,2.92,3],[2,2.98,4.25]],"ltp":2.5,"tv":3587.26,"id":9629022}]}]}
{"op":"mcm","clk":"4214947006","pt":1631532803572,"mc":[{"id":"1.187557985","rc":[{"batb":[[1,2.46,5.51],[2,2.38,5.67]],"batl":[[0,2.82,5.25],[1,2.86,4.75],[2,2.92,3]],"ltp":2.5,"tv":3587.26,"id":9629022}]}]}
{"op":"mcm","clk":"4214947124","pt":1631532805638,"mc":[{"id":"1.187557985","rc":[{"batl":[[0,2.82,49.48]],"ltp":2.5,"tv":3587.26,"id":9629022}]}]}
{"op":"mcm","clk":"4214947150","pt":1631532806259,"mc":[{"id":"1.187557985","rc":[{"batl":[[0,2.82,5.25]],"ltp":2.5,"tv":3587.26,"id":9629022}]}]}
{"op":"mcm","clk":"4214947303","pt":1631532809155,"mc":[{"id":"1.187557985","rc":[{"batl":[[0,1.63,257.58]],"ltp":1.58,"tv":10318.15,"id":5300820},{"batl":[[0,2.8,44.23],[1,2.82,5.25],[2,2.86,4.75]],"ltp":2.5,"tv":3587.26,"id":9629022}]}]}
{"op":"mcm","clk":"4214948001","pt":1631532822661,"mc":[{"id":"1.187557985","rc":[{"batb":[[0,1.55,40.99],[1,1.54,47.12],[2,1.52,55.24]],"batl":[[0,1.72,38.66],[1,1.83,4],[2,1.91,27.5]],"ltp":1.58,"tv":10318.15,"id":5300820},{"batb":[[0,2.38,5.67],[1,2.32,78.49],[2,2.22,4]],"batl":[[0,2.82,5.25],[1,2.86,4.75],[2,2.92,3]],"ltp":2.5,"tv":3587.26,"id":9629022}]}]}
{"op":"mcm","clk":"4214948011","pt":1631532822868,"mc":[{"id":"1.187557985","rc":[{"batb":[[0,1.52,55.24],[1,1.5,160.92],[2,1.45,4.26]],"ltp":1.58,"tv":10318.15,"id":5300820},{"batl":[[0,2.92,3],[1,2.94,4.75],[2,3.45,53.16]],"ltp":2.5,"tv":3587.26,"id":9629022}]}]}
{"op":"mcm","clk":"4214948157","pt":1631532825407,"mc":[{"id":"1.187557985","rc":[{"batb":[[1,1.51,169.58],[2,1.5,349.25]],"batl":[[1,1.74,176.01],[2,1.76,210.57]],"ltp":1.58,"tv":10318.15,"id":5300820}]}]}
{"op":"mcm","clk":"4214948218","pt":1631532826506,"mc":[{"id":"1.187557985","rc":[{"batb":[[0,1.52,50.24],[1,1.5,160.92],[2,1.45,4.26]],"batl":[[0,1.71,6],[1,1.72,38.66],[2,1.83,4]],"ltp":1.58,"tv":10318.15,"id":5300820},{"batb":[[0,2.4,4],[1,2.38,8.67],[2,2.32,78.49]],"batl":[[0,2.94,4.75],[1,3.45,53.16],[2,3.45,0]],"ltp":2.5,"tv":3587.26,"id":9629022}]}]}
{"op":"mcm","clk":"4214948325","pt":1631532828582,"mc":[{"id":"1.187557985","rc":[{"batl":[[0,1.63,18.77],[1,1.71,6],[2,1.72,43.66]],"ltp":1.58,"tv":10318.15,"id":5300820},{"batb":[[0,2.58,19.56],[1,2.4,4],[2,2.38,8.67]],"batl":[[0,2.68,21.64],[1,2.94,4.75],[2,3.45,53.16]],"ltp":2.5,"tv":3587.26,"id":9629022}]}]}
{"op":"mcm","clk":"4214948386","pt":1631532829611,"mc":[{"id":"1.187557985","rc":[{"batb":[[0,1.6,171.16],[1,1.59,149.91],[2,1.52,50.24]],"batl":[[0,1.65,229.5],[1,1.66,127.66],[2,1.68,47.64]],"ltp":1.58,"tv":10318.15,"id":5300820},{"batb":[[0,2.46,9.01],[1,2.44,4],[2,2.4,4]],"batl":[[0,2.94,8.75],[1,3.45,53.16],[2,3.45,0]],"ltp":2.5,"tv":3587.26,"id":9629022}]}]}
{"op":"mcm","clk":"4214948430","pt":1631532830492,"mc":[{"id":"1.187557985","rc":[{"batb":[[2,1.55,50.59]],"batl":[[2,1.68,5]],"ltp":1.58,"tv":10318.15,"id":5300820},{"batb":[[0,2.46,3]],"batl":[[0,2.82,4.36],[1,2.94,8.75],[2,3.45,53.16]],"ltp":2.5,"tv":3587.26,"id":9629022}]}]}
{"op":"mcm","clk":"4214948533","pt":1631532832410,"mc":[{"id":"1.187557985","rc":[{"batb":[[0,1.55,50.59],[1,1.52,50.24],[2,1.5,160.92]],"batl":[[0,1.68,5],[1,1.69,5],[2,1.71,6]],"ltp":1.58,"tv":10318.15,"id":5300820}]}]}
{"op":"mcm","clk":"4214948605","pt":1631532833608,"mc":[{"id":"1.187557985","rc":[{"batb":[[0,1.61,126.6]],"ltp":1.58,"tv":10318.15,"id":5300820},{"batl":[[0,2.94,8.75],[1,3.45,53.16],[2,3.45,0]],"ltp":2.5,"tv":3587.26,"id":9629022}]}]}
{"op":"mcm","clk":"4214948622","pt":1631532833814,"mc":[{"id":"1.187557985","rc":[{"batb":[[0,1.52,50.24],[1,1.5,160.92],[2,1.45,4.26]],"ltp":1.58,"tv":10318.15,"id":5300820}]}]}
{"op":"mcm","clk":"4214948723","pt":1631532835317,"mc":[{"id":"1.187557985","rc":[{"batb":[[1,1.51,169.58],[2,1.5,349.25]],"ltp":1.58,"tv":10318.15,"id":5300820}]}]}
{"op":"mcm","clk":"4214948817","pt":1631532837285,"mc":[{"id":"1.187557985","rc":[{"batl":[[2,1.72,43.66]],"ltp":1.58,"tv":10318.15,"id":5300820},{"batb":[[2,2.38,5.67]],"ltp":2.5,"tv":3587.26,"id":9629022}]}]}
{"op":"mcm","clk":"4214948931","pt":1631532839523,"mc":[{"id":"1.187557985","rc":[{"batb":[[0,1.55,42.19],[1,1.52,50.24],[2,1.51,169.58]],"ltp":1.58,"tv":10318.15,"id":5300820},{"batl":[[0,2.82,4.75],[1,2.94,8.75],[2,3.45,53.16]],"ltp":2.5,"tv":3587.26,"id":9629022}]}]}
{"op":"mcm","clk":"4214948988","pt":1631532840509,"mc":[{"id":"1.187557985","rc":[{"batb":[[0,1.52,50.24],[1,1.51,169.58],[2,1.5,349.25]],"batl":[[0,1.69,5],[1,1.72,38.66],[2,1.74,176.01]],"ltp":1.58,"tv":10318.15,"id":5300820},{"batb":[[1,2.38,5.67],[2,2.32,78.49]],"batl":[[0,2.94,8.75],[1,3.45,53.16],[2,3.45,0]],"ltp":2.5,"tv":3587.26,"id":9629022}]}]}
{"op":"mcm","clk":"4214949151","pt":1631532842404,"mc":[{"id":"1.187557985","rc":[{"batb":[[1,1.5,160.92],[2,1.45,4.26]],"ltp":1.58,"tv":10318.15,"id":5300820}]}]}
{"op":"mcm","clk":"4214949230","pt":1631532843638,"mc":[{"id":"1.187557985","rc":[{"batl":[[0,1.68,38.89],[1,1.69,5],[2,1.72,38.66]],"ltp":1.58,"tv":10318.15,"id":5300820},{"batb":[[0,2.46,9.38]],"ltp":2.5,"tv":3587.26,"id":9629022}]}]}
{"op":"mcm","clk":"4214949286","pt":1631532844633,"mc":[{"id":"1.187557985","rc":[{"trd":[[1.68,102.62]],"batl":[[0,1.69,5],[1,1.72,38.66],[2,1.74,176.01]],"ltp":1.68,"tv":10395.93,"id":5300820},{"batb":[[0,2.46,3],[1,2.44,4],[2,2.38,5.67]],"ltp":2.5,"tv":3587.26,"id":9629022}],"tv":13983.2}]}
{"op":"mcm","clk":"4214949353","pt":1631532845622,"mc":[{"id":"1.187557985","rc":[{"batb":[[0,1.68,243.39],[1,1.67,125.38],[2,1.66,1152.12]],"batl":[[0,1.72,38.66],[1,1.74,176.01],[2,1.76,210.57]],"ltp":1.68,"tv":10395.93,"id":5300820},{"batb":[[0,2.38,5.67],[1,2.32,78.49],[2,2.3,457.34]],"batl":[[0,2.54,2.75],[1,2.94,8.75],[2,2.96,6.76]],"ltp":2.5,"tv":3587.26,"id":9629022}]}]}
{"op":"mcm","clk":"4214949413","pt":1631532846512,"mc":[{"id":"1.187557985","rc":[{"trd":[[1.68,127.46]],"batb":[[0,1.68,230.97],[1,1.67,234]],"ltp":1.68,"tv":10420.77,"id":5300820}],"tv":14008.04}]}
{"op":"mcm","clk":"4214949505","pt":1631532847509,"mc":[{"id":"1.187557985","rc":[{"trd":[[1.68,139.46]],"batb":[[0,1.68,224.97]],"ltp":1.68,"tv":10432.77,"id":5300820},{"batl":[[1,2.7,43.75],[2,2.94,8.75]],"ltp":2.5,"tv":3587.26,"id":9629022}],"tv":14020.04}]}
{"op":"mcm","clk":"4214949576","pt":1631532848643,"mc":[{"id":"1.187557985","rc":[{"batb":[[1,1.67,240],[2,1.66,1158.12]],"ltp":1.68,"tv":10432.77,"id":5300820},{"batl":[[0,2.46,3],[1,2.5,4],[2,2.54,2.75]],"ltp":2.5,"tv":3587.26,"id":9629022}]}]}
{"op":"mcm","clk":"4214949743","pt":1631532851513,"mc":[{"id":"1.187557985","rc":[{"trd":[[2.46,2.6]],"batl":[[0,2.46,1.7]],"ltp":2.46,"tv":3589.86,"id":9629022}],"tv":14022.64}]}
{"op":"mcm","clk":"4214949914","pt":1631532854626,"mc":[{"id":"1.187557985","rc":[{"batb":[[0,1.7,42.47],[1,1.68,224.97],[2,1.67,240]],"ltp":1.68,"tv":10432.77,"id":5300820},{"batl":[[0,2.44,8.5],[1,2.46,1.7],[2,2.5,4]],"ltp":2.46,"tv":3589.86,"id":9629022}]}]}
{"op":"mcm","clk":"4214949926","pt":1631532854835,"mc":[{"id":"1.187557985","rc":[{"batb":[[0,1.68,224.97],[1,1.67,240],[2,1.66,1158.12]],"ltp":1.68,"tv":10432.77,"id":5300820}]}]}
{"op":"mcm","clk":"4214950148","pt":1631532858391,"mc":[{"id":"1.187557985","rc":[{"batb":[[0,1.69,42.47],[1,1.68,224.97],[2,1.67,240]],"ltp":1.68,"tv":10432.77,"id":5300820}]}]}
{"op":"mcm","clk":"4214950475","pt":1631532864646,"mc":[{"id":"1.187557985","rc":[{"batb":[[0,1.61,47.09],[1,1.6,295.12],[2,1.59,335.76]],"batl":[[0,1.86,32.25],[1,1.88,246.24],[2,1.89,226.15]],"ltp":1.68,"tv":10432.77,"id":5300820},{"batb":[[0,2.16,6.53],[1,2.14,233.31],[2,2.12,268.04]],"batl":[[0,2.64,5.68],[1,2.66,148.29],[2,2.68,163.18]],"ltp":2.46,"tv":3589.86,"id":9629022}]}]}
{"op":"mcm","clk":"4214950490","pt":1631532864857,"mc":[{"id":"1.187557985","rc":[{"batb":[[0,1.6,295.12],[1,1.59,335.76],[2,1.58,447.53]],"batl":[[0,1.88,246.24],[1,1.89,226.15],[2,1.9,354.45]],"ltp":1.68,"tv":10432.77,"id":5300820},{"batb":[[0,2.14,233.31],[1,2.12,268.04],[2,2.1,400.82]],"batl":[[0,2.66,148.29],[1,2.68,163.18],[2,2.7,184.03]],"ltp":2.46,"tv":3589.86,"id":9629022}]}]}
{"op":"mcm","clk":"4214950651","pt":1631532867455,"mc":[{"id":"1.187557985","rc":[{"batb":[[2,1.58,709.83]],"batl":[[2,1.9,498.56]],"ltp":1.68,"tv":10432.77,"id":5300820}]}]}
{"op":"mcm","clk":"4214950734","pt":1631532868554,"mc":[{"id":"1.187557985","rc":[{"batb":[[2,1.58,447.53]],"batl":[[0,1.86,5],[1,1.87,4],[2,1.88,250.24]],"ltp":1.68,"tv":10432.77,"id":5300820},{"batb":[[0,2.16,4],[1,2.14,237.31],[2,2.12,272.04]],"ltp":2.46,"tv":3589.86,"id":9629022}]}]}
{"op":"mcm","clk":"4214950941","pt":1631532871467,"mc":[{"id":"1.187557985","rc":[{"batb":[[0,1.71,203.04],[1,1.69,238.75],[2,1.6,295.12]],"batl":[[0,1.77,180.13],[1,1.79,199.18],[2,1.86,5]],"ltp":1.68,"tv":10432.77,"id":5300820}]}]}
{"op":"mcm","clk":"4214951017","pt":1631532872565,"mc":[{"id":"1.187557985","rc":[{"batb":[[2,1.61,44.09]],"batl":[[2,1.85,25]],"ltp":1.68,"tv":10432.77,"id":5300820},{"batb":[[0,2.18,20],[1,2.16,11.78],[2,2.14,237.31]],"batl":[[0,2.64,4.93],[1,2.66,148.29],[2,2.68,163.18]],"ltp":2.46,"tv":3589.86,"id":9629022}]}]}
{"op":"mcm","clk":"4214951145","pt":1631532874355,"mc":[{"id":"1.187557985","rc":[{"batb":[[0,1.6,295.12],[1,1.59,335.76],[2,1.58,447.53]],"batl":[[0,1.86,5],[1,1.87,4],[2,1.88,250.24]],"ltp":1.68,"tv":10432.77,"id":5300820},{"batb":[[0,2.16,4],[1,2.14,237.31],[2,2.12,272.04]],"batl":[[0,2.66,148.29],[1,2.68,163.18],[2,2.7,184.03]],"ltp":2.46,"tv":3589.86,"id":9629022}]}]}
{"op":"mcm","clk":"4214951338","pt":1631532877578,"mc":[{"id":"1.187557985","rc":[{"batb":[[2,1.58,709.83]],"ltp":1.68,"tv":10432.77,"id":5300820}]}]}
{"op":"mcm","clk":"4214951578","pt":1631532881086,"mc":[{"id":"1.187557985","rc":[{"batl":[[1,1.93,25.5],[2,2.04,388.3]],"ltp":1.68,"tv":10432.77,"id":5300820},{"batb":[[1,2.1,105.27],[2,2.06,7.58]],"ltp":2.46,"tv":3589.86,"id":9629022}]}]}
{"op":"mcm","clk":"4214951817","pt":1631532884494,"mc":[{"id":"1.187557985","rc":[{"trd":[[1.6,1042.01]],"batb":[[0,1.59,335.76],[1,1.58,709.83],[2,1.57,157.68]],"batl":[[0,1.63,185.95],[1,1.64,133.48],[2,1.65,1159.1]],"ltp":1.6,"tv":10458.75,"id":5300820},{"batl":[[0,2.68,158.54],[1,2.7,184.03],[2,2.8,4.22]],"ltp":2.46,"tv":3589.86,"id":9629022}],"tv":14048.62}]}
{"op":"mcm","clk":"4214951862","pt":1631532885070,"mc":[{"id":"1.187557985","rc":[{"batb":[[0,2.54,62.26],[1,2.32,79.66],[2,2.16,4]],"ltp":2.46,"tv":3589.86,"id":9629022}]}]}
{"op":"mcm","clk":"4214951962","pt":1631532886589,"mc":[{"id":"1.187557985","rc":[{"batb":[[2,2.26,20]],"ltp":2.46,"tv":3589.86,"id":9629022}]}]}
{"op":"mcm","clk":"4214952034","pt":1631532887582,"mc":[{"id":"1.187557985","rc":[{"batb":[[0,1.59,376.54]],"ltp":1.6,"tv":10458.75,"id":5300820},{"batb":[[1,2.46,3],[2,2.44,4]],"batl":[[0,2.68,179.48]],"ltp":2.46,"tv":3589.86,"id":9629022}]}]}
{"op":"mcm","clk":"4214952245","pt":1631532890474,"mc":[{"id":"1.187557985","rc":[{"batb":[[1,2.46,9.01]],"ltp":2.46,"tv":3589.86,"id":9629022}]}]}
{"op":"mcm","clk":"4214952590","pt":1631532895786,"mc":[{"id":"1.187557985","rc":[{"batl":[[0,1.63,170.77]],"ltp":1.6,"tv":10458.75,"id":5300820}]}]}
{"op":"mcm","clk":"4214953572","pt":1631532908569,"mc":[{"id":"1.187557985","rc":[{"batb":[[0,1.58,395.27],[1,1.57,157.68],[2,1.55,39.99]],"batl":[[2,1.68,32.14]],"ltp":1.6,"tv":10458.75,"id":5300820},{"batb":[[1,2.46,6.01]],"batl":[[0,2.82,4.36],[1,2.94,4.75],[2,3.45,53.16]],"ltp":2.46,"tv":3589.86,"id":9629022}]}]}
{"op":"mcm","clk":"4214953610","pt":1631532909045,"mc":[{"id":"1.187557985","rc":[{"batb":[[0,1.52,50.24],[1,1.51,157.49],[2,1.45,4.26]],"batl":[[0,1.72,34.91],[1,1.85,5],[2,1.93,25.5]],"ltp":1.6,"tv":10458.75,"id":5300820},{"batb":[[0,2.44,4],[1,2.38,5.96],[2,2.32,79.66]],"batl":[[0,2.94,4.75],[1,3.45,53.16],[2,3.45,0]],"ltp":2.46,"tv":3589.86,"id":9629022}]}]}
{"op":"mcm","clk":"4214953863","pt":1631532912567,"mc":[{"id":"1.187557985","rc":[{"batl":[[0,1.69,4],[1,1.7,5],[2,1.72,34.91]],"ltp":1.6,"tv":10458.75,"id":5300820},{"batb":[[1,2.42,4],[2,2.38,5.96]],"batl":[[0,2.94,7.75]],"ltp":2.46,"tv":3589.86,"id":9629022}]}]}
{"op":"mcm","clk":"4214954010","pt":1631532914588,"mc":[{"id":"1.187557985","rc":[{"batb":[[0,1.6,261.48],[1,1.59,150.25],[2,1.52,50.24]],"batl":[[0,1.65,143.58],[1,1.66,127.94],[2,1.69,4]],"ltp":1.6,"tv":10458.75,"id":5300820}]}]}
{"op":"mcm","clk":"4214954056","pt":1631532915284,"mc":[{"id":"1.187557985","rc":[{"batb":[[2,1.53,132.65]],"ltp":1.6,"tv":10458.75,"id":5300820},{"batb":[[0,2.44,24]],"batl":[[0,2.92,23.75],[1,2.94,7.75],[2,3.45,53.16]],"ltp":2.46,"tv":3589.86,"id":9629022}]}]}
{"op":"mcm","clk":"4214954124","pt":1631532916060,"mc":[{"id":"1.187557985","rc":[{"batb":[[2,1.55,44.99]],"batl":[[2,1.68,34.14]],"ltp":1.6,"tv":10458.75,"id":5300820},{"batb":[[0,2.46,5.88],[1,2.44,24],[2,2.42,4]],"batl":[[0,2.82,4.25]],"ltp":2.46,"tv":3589.86,"id":9629022}]}]}
{"op":"mcm","clk":"4214954363","pt":1631532919309,"mc":[{"id":"1.187557985","rc":[{"batl":[[0,2.8,23.75],[1,2.82,4.25],[2,2.94,7.75]],"ltp":2.46,"tv":3589.86,"id":9629022}]}]}
{"op":"mcm","clk":"4214954609","pt":1631532922595,"mc":[{"id":"1.187557985","rc":[{"batb":[[0,1.52,55.24],[1,1.51,163.49],[2,1.45,4.26]],"batl":[[0,1.69,4],[1,1.7,5],[2,1.72,34.91]],"ltp":1.6,"tv":10458.75,"id":5300820},{"batb":[[0,2.44,24],[1,2.42,4],[2,2.38,5.96]],"batl":[[0,2.94,7.75],[1,3.45,53.16],[2,2.94,0]],"ltp":2.46,"tv":3589.86,"id":9629022}]}]}
{"op":"mcm","clk":"4214954748","pt":1631532924574,"mc":[{"id":"1.187557985","rc":[{"batb":[[1,1.51,420.57],[2,1.5,188.87]],"ltp":1.6,"tv":10458.75,"id":5300820}]}]}
{"op":"mcm","clk":"4214954814","pt":1631532925605,"mc":[{"id":"1.187557985","rc":[{"batl":[[0,1.69,53.68],[1,1.72,34.91],[2,1.75,199.92]],"ltp":1.6,"tv":10458.75,"id":5300820},{"batb":[[1,2.38,5.96],[2,2.32,79.66]],"batl":[[0,2.78,52.98],[1,2.94,7.75],[2,3.45,53.16]],"ltp":2.46,"tv":3589.86,"id":9629022}]}]}
{"op":"mcm","clk":"4214954871","pt":1631532926189,"mc":[{"id":"1.187557985","rc":[{"batb":[[1,1.51,414.57]],"batl":[[0,1.69,24]],"ltp":1.6,"tv":10458.75,"id":5300820},{"batl":[[0,2.94,7.75],[1,3.45,53.16],[2,3.45,0]],"ltp":2.46,"tv":3589.86,"id":9629022}]}]}
{"op":"mcm","clk":"4214955018","pt":1631532927968,"mc":[{"id":"1.187557985","rc":[{"batb":[[1,2.42,4],[2,2.38,5.96]],"ltp":2.46,"tv":3589.86,"id":9629022}]}]}
{"op":"mcm","clk":"4214955130","pt":1631532929432,"mc":[{"id":"1.187557985","rc":[{"batb":[[0,1.53,132.65],[1,1.52,55.24],[2,1.51,421.57]],"ltp":1.6,"tv":10458.75,"id":5300820}]}]}
{"op":"mcm","clk":"4214955358","pt":1631532932580,"mc":[{"id":"1.187557985","rc":[{"batb":[[0,1.53,5]],"ltp":1.6,"tv":10458.75,"id":5300820},{"batl":[[0,2.9,3],[1,2.92,3],[2,2.94,7.75]],"ltp":2.46,"tv":3589.86,"id":9629022}]}]}
{"op":"mcm","clk":"4214955844","pt":1631532939577,"mc":[{"id":"1.187557985","rc":[{"batb":[[1,2.38,5.96],[2,2.32,79.66]],"ltp":2.46,"tv":3589.86,"id":9629022}]}]}
{"op":"mcm","clk":"4214956045","pt":1631532942597,"mc":[{"id":"1.187557985","rc":[{"batb":[[0,1.55,108.17],[1,1.53,5],[2,1.52,50.24]],"ltp":1.6,"tv":10458.75,"id":5300820},{"batb":[[1,2.42,4],[2,2.38,5.96]],"ltp":2.46,"tv":3589.86,"id":9629022}]}]}
{"op":"mcm","clk":"4214956082","pt":1631532943117,"mc":[{"id":"1.187557985","rc":[{"batb":[[0,1.53,5],[1,1.52,50.24],[2,1.51,414.57]],"ltp":1.6,"tv":10458.75,"id":5300820}]}]}
{"op":"mcm","clk":"4214956339","pt":1631532946534,"mc":[{"id":"1.187557985","rc":[{"batb":[[1,1.52,56.24]],"ltp":1.6,"tv":10458.75,"id":5300820},{"batl":[[1,2.94,4.75],[2,3.45,53.16]],"ltp":2.46,"tv":3589.86,"id":9629022}]}]}
{"op":"mcm","clk":"4214956384","pt":1631532947424,"mc":[{"id":"1.187557985","rc":[{"batl":[[0,1.69,4]],"ltp":1.6,"tv":10458.75,"id":5300820},{"batb":[[0,2.44,4]],"ltp":2.46,"tv":3589.86,"id":9629022}]}]}
{"op":"mcm","clk":"4214956535","pt":1631532949608,"mc":[{"id":"1.187557985","rc":[{"batb":[[0,1.56,96.39],[1,1.53,5],[2,1.52,56.24]],"batl":[[0,1.68,35.14],[1,1.69,4],[2,1.72,34.91]],"ltp":1.6,"tv":10458.75,"id":5300820},{"batb":[[0,2.46,6.01],[1,2.44,4],[2,2.42,4]],"batl":[[0,2.88,24.3],[1,2.9,3],[2,2.94,4.75]],"ltp":2.46,"tv":3589.86,"id":9629022}]}]}
{"op":"mcm","clk":"4214956578","pt":1631532950133,"mc":[{"id":"1.187557985","rc":[{"batb":[[0,1.53,5],[1,1.52,56.24],[2,1.51,414.57]],"batl":[[0,1.69,4],[1,1.72,34.91],[2,1.75,199.92]],"ltp":1.6,"tv":10458.75,"id":5300820},{"batb":[[0,2.44,4],[1,2.42,4],[2,2.38,5.96]],"batl":[[0,2.9,3],[1,2.94,4.75],[2,3.45,53.16]],"ltp":2.46,"tv":3589.86,"id":9629022}]}]}
{"op":"mcm","clk":"4214956804","pt":1631532953420,"mc":[{"id":"1.187557985","rc":[{"batb":[[0,1.55,43.99],[1,1.53,5],[2,1.52,56.24]],"ltp":1.6,"tv":10458.75,"id":5300820},{"batl":[[0,2.82,4.75],[1,2.9,3],[2,2.94,4.75]],"ltp":2.46,"tv":3589.86,"id":9629022}]}]}
{"op":"mcm","clk":"4214956830","pt":1631532953736,"mc":[{"id":"1.187557985","rc":[{"batb":[[0,1.53,5],[1,1.52,56.24],[2,1.51,414.57]],"ltp":1.6,"tv":10458.75,"id":5300820},{"batl":[[0,2.9,3],[1,2.94,4.75],[2,3.45,53.16]],"ltp":2.46,"tv":3589.86,"id":9629022}]}]}
{"op":"mcm","clk":"4214957016","pt":1631532956544,"mc":[{"id":"1.187557985","rc":[{"batl":[[0,1.68,34.89],[1,1.69,4],[2,1.72,34.91]],"ltp":1.6,"tv":10458.75,"id":5300820},{"batb":[[0,2.46,5.38],[1,2.44,4],[2,2.42,4]],"ltp":2.46,"tv":3589.86,"id":9629022}]}]}
{"op":"mcm","clk":"4214957084","pt":1631532957454,"mc":[{"id":"1.187557985","rc":[{"batb":[[1,1.52,50.24]],"batl":[[0,1.69,4],[1,1.72,34.91],[2,1.75,199.92]],"ltp":1.6,"tv":10458.75,"id":5300820},{"batb":[[0,2.44,4],[1,2.38,5.96],[2,2.32,79.66]],"ltp":2.46,"tv":3589.86,"id":9629022}]}]}
{"op":"mcm","clk":"4214957331","pt":1631532960607,"mc":[{"id":"1.187557985","rc":[{"batb":[[0,1.55,50.99],[1,1.53,5],[2,1.52,54.24]],"ltp":1.6,"tv":10458.75,"id":5300820},{"batb":[[1,2.42,4],[2,2.38,5.96]],"batl":[[0,2.82,4.36],[1,2.9,3],[2,2.94,4.75]],"ltp":2.46,"tv":3589.86,"id":9629022}]}]}
{"op":"mcm","clk":"4214957363","pt":1631532960924,"mc":[{"id":"1.187557985","rc":[{"batb":[[0,1.53,5],[1,1.52,54.24],[2,1.51,157.49]],"ltp":1.6,"tv":10458.75,"id":5300820},{"batl":[[0,2.9,3],[1,2.94,4.75],[2,3.45,53.16]],"ltp":2.46,"tv":3589.86,"id":9629022}]}]}
{"op":"mcm","clk":"4214957507","pt":1631532962647,"mc":[{"id":"1.187557985","rc":[{"trd":[[1.69,8]],"batb":[[0,1.69,468.25],[1,1.53,5],[2,1.52,54.24]],"batl":[[0,1.72,34.91],[1,1.75,199.92],[2,1.77,206.61]],"ltp":1.69,"tv":10466.75,"id":5300820}],"tv":14056.62}]}
{"op":"mcm","clk":"4214957583","pt":1631532963642,"mc":[{"id":"1.187557985","rc":[{"batb":[[0,1.65,26.73]],"batl":[[0,1.68,40.14],[1,1.72,34.91],[2,1.78,2148.88]],"ltp":1.69,"tv":10466.75,"id":5300820},{"batb":[[0,2.46,5.88],[1,2.38,5.96],[2,2.32,79.66]],"batl":[[0,2.48,1542.34],[1,2.5,1496.98],[2,2.52,1496.98]],"ltp":2.46,"tv":3589.86,"id":9629022}]}]}
{"op":"mcm","clk":"4214957668","pt":1631532964641,"mc":[{"id":"1.187557985","rc":[{"trd":[[1.67,67.06],[1.68,219.74],[1.69,16.56]],"batb":[[0,1.68,107.36],[1,1.65,26.73],[2,1.59,131.04]],"batl":[[0,1.72,34.91],[1,1.78,590.94],[2,1.79,1042.84]],"ltp":1.67,"tv":10568.01,"id":5300820},{"trd":[[2.46,8.48],[2.48,8.36]],"batb":[[0,2.38,5.96],[1,2.32,79.66],[2,2.1,106.11]],"batl":[[0,2.48,762.82],[1,2.5,748.48],[2,2.52,748.48]],"ltp":2.48,"tv":3604.1,"id":9629022}],"tv":14172.12}]}
{"op":"mcm","clk":"4214957738","pt":1631532965626,"mc":[{"id":"1.187557985","rc":[{"batl":[[0,1.7,6],[1,1.72,34.91],[2,1.78,590.94]],"ltp":1.67,"tv":10568.01,"id":5300820}]}]}
{"op":"mcm","clk":"4214957802","pt":1631532966660,"mc":[{"id":"1.187557985","rc":[{"batb":[[0,1.68,111.36],[1,1.67,5],[2,1.65,26.73]],"batl":[[0,1.72,34.91],[1,1.78,590.94],[2,1.79,1042.84]],"ltp":1.67,"tv":10568.01,"id":5300820},{"batl":[[0,2.46,3],[1,2.48,762.82],[2,2.5,748.48]],"ltp":2.48,"tv":3604.1,"id":9629022}]}]}
{"op":"mcm","clk":"4214957859","pt":1631532967444,"mc":[{"id":"1.187557985","rc":[{"batb":[[0,1.68,107.36],[1,1.65,26.73],[2,1.59,131.04]],"ltp":1.67,"tv":10568.01,"id":5300820},{"batl":[[0,2.48,762.82],[1,2.5,748.48],[2,2.52,748.48]],"ltp":2.48,"tv":3604.1,"id":9629022}]}]}
{"op":"mcm","clk":"4214957930","pt":1631532968531,"mc":[{"id":"1.187557985","rc":[{"batl":[[0,1.72,102.6]],"ltp":1.67,"tv":10568.01,"id":5300820},{"batl":[[1,2.5,778.89]],"ltp":2.48,"tv":3604.1,"id":9629022}]}]}
{"op":"mcm","clk":"4214957941","pt":1631532968741,"mc":[{"id":"1.187557985","rc":[{"batl":[[0,1.72,34.91]],"ltp":1.67,"tv":10568.01,"id":5300820},{"batl":[[1,2.5,748.48]],"ltp":2.48,"tv":3604.1,"id":9629022}]}]}
{"op":"mcm","clk":"4214958041","pt":1631532970043,"mc":[{"id":"1.187557985","rc":[{"batb":[[2,1.6,53.84]],"ltp":1.67,"tv":10568.01,"id":5300820},{"batb":[[2,2.16,7.78]],"ltp":2.48,"tv":3604.1,"id":9629022}]}]}
{"op":"mcm","clk":"4214958159","pt":1631532971661,"mc":[{"id":"1.187557985","rc":[{"batb":[[2,1.61,48.09]],"ltp":1.67,"tv":10568.01,"id":5300820}]}]}
{"op":"mcm","clk":"4214958367","pt":1631532974949,"mc":[{"id":"1.187557985","rc":[{"batb":[[0,1.69,179.21],[1,1.68,107.36],[2,1.67,249.06]],"batl":[[1,1.74,119.6],[2,1.76,210.91]],"ltp":1.67,"tv":10568.01,"id":5300820}]}]}
{"op":"mcm","clk":"4214958442","pt":1631532975980,"mc":[{"id":"1.187557985","rc":[{"batl":[[2,1.76,218.41]],"ltp":1.67,"tv":10568.01,"id":5300820},{"batb":[[1,2.32,85.34]],"ltp":2.48,"tv":3604.1,"id":9629022}]}]}
{"op":"mcm","clk":"4214959063","pt":1631532984340,"mc":[{"id":"1.187557985","rc":[{"trd":[[1.72,34.91],[1.74,21.68]],"batl":[[0,1.76,7.5],[1,1.78,590.94],[2,1.79,1042.84]],"ltp":1.74,"tv":10624.6,"id":5300820},{"trd":[[2.34,16.12],[2.38,37.15]],"batb":[[0,2.32,85.34],[1,2.16,7.78],[2,2.1,106.11]],"ltp":2.34,"tv":3657.37,"id":9629022}],"tv":14281.98}]}
{"op":"mcm","clk":"4214959295","pt":1631532987571,"mc":[{"id":"1.187557985","rc":[{"batb":[[1,1.67,249.06],[2,1.61,48.09]],"batl":[[0,1.75,213.85],[1,1.76,7.5],[2,1.77,206.63]],"ltp":1.74,"tv":10624.6,"id":5300820},{"batb":[[0,2.32,5.68]],"batl":[[0,2.6,5.92],[1,2.64,4.68],[2,2.68,5.39]],"ltp":2.34,"tv":3657.37,"id":9629022}]}]}
{"op":"mcm","clk":"4214959369","pt":1631532988361,"mc":[{"id":"1.187557985","rc":[{"batb":[[0,1.59,131.04],[1,1.56,52.33],[2,1.52,50.24]],"batl":[[0,1.93,25.5],[1,2.04,388.3],[2,810,0.07]],"ltp":1.74,"tv":10624.6,"id":5300820},{"batb":[[0,2.1,106.11],[1,2.06,8.08],[2,1.7,16.97]],"batl":[[0,2.8,4.57],[1,2.94,4.75],[2,3.45,53.16]],"ltp":2.34,"tv":3657.37,"id":9629022}]}]}
{"op":"mcm","clk":"4214959530","pt":1631532990563,"mc":[{"id":"1.187557985","rc":[{"batb":[[1,1.58,131.21],[2,1.56,52.33]],"ltp":1.74,"tv":10624.6,"id":5300820}]}]}
{"op":"mcm","clk":"4214959603","pt":1631532991558,"mc":[{"id":"1.187557985","rc":[{"batb":[[0,1.59,191.94],[1,1.58,284.9]],"batl":[[0,1.91,158.65],[1,1.93,182.42],[2,2.04,388.3]],"ltp":1.74,"tv":10624.6,"id":5300820},{"batb":[[0,2.1,109.94],[1,2.08,4],[2,2.06,8.08]],"ltp":2.34,"tv":3657.37,"id":9629022}]}]}
{"op":"mcm","clk":"4214959655","pt":1631532992491,"mc":[{"id":"1.187557985","rc":[{"batl":[[0,1.91,3],[1,1.93,25.5]],"ltp":1.74,"tv":10624.6,"id":5300820}]}]}
{"op":"mcm","clk":"4214959796","pt":1631532994577,"mc":[{"id":"1.187557985","rc":[{"batb":[[2,1.56,57.33]],"batl":[[0,1.64,6.26],[1,1.91,3],[2,1.93,25.5]],"ltp":1.74,"tv":10624.6,"id":5300820},{"batl":[[0,2.74,3],[1,2.8,4.57],[2,2.94,4.75]],"ltp":2.34,"tv":3657.37,"id":9629022}]}]}
{"op":"mcm","clk":"4214959862","pt":1631532995466,"mc":[{"id":"1.187557985","rc":[{"trd":[[1.59,51.6]],"batb":[[0,1.59,179.04]],"batl":[[0,1.64,2192.94],[1,1.65,130.5],[2,1.91,3]],"ltp":1.59,"tv":10650.4,"id":5300820},{"batb":[[0,2.54,752.94],[1,2.52,730.82],[2,2.5,730.82]],"batl":[[1,2.78,378.37],[2,2.8,371.82]],"ltp":2.34,"tv":3657.37,"id":9629022}],"tv":14307.78}]}
{"op":"mcm","clk":"4214959945","pt":1631532996659,"mc":[{"id":"1.187557985","rc":[{"batl":[[0,1.64,239.37],[2,1.66,7.5]],"ltp":1.59,"tv":10650.4,"id":5300820},{"batb":[[1,2.52,799.01]],"ltp":2.34,"tv":3657.37,"id":9629022}]}]}
{"op":"mcm","clk":"4214959987","pt":1631532997282,"mc":[{"id":"1.187557985","rc":[{"batb":[[0,1.6,38.14],[1,1.59,179.04],[2,1.58,284.9]],"ltp":1.59,"tv":10650.4,"id":5300820},{"batl":[[0,2.72,15],[1,2.74,3],[2,2.78,378.37]],"ltp":2.34,"tv":3657.37,"id":9629022}]}]}
{"op":"mcm","clk":"4214960268","pt":1631533000580,"mc":[{"id":"1.187557985","rc":[{"batl":[[2,1.8,15]],"ltp":1.59,"tv":10650.4,"id":5300820},{"batb":[[1,2.52,794.08]],"batl":[[0,2.74,3],[1,2.78,378.37],[2,2.8,371.82]],"ltp":2.34,"tv":3657.37,"id":9629022}]}]}
{"op":"mcm","clk":"4214960389","pt":1631533002188,"mc":[{"id":"1.187557985","rc":[{"batl":[[2,1.69,31.79]],"ltp":1.59,"tv":10650.4,"id":5300820}]}]}
{"op":"mcm","clk":"4214960492","pt":1631533003594,"mc":[{"id":"1.187557985","rc":[{"batl":[[1,1.65,138]],"ltp":1.59,"tv":10650.4,"id":5300820},{"batb":[[0,2.54,757.81]],"ltp":2.34,"tv":3657.37,"id":9629022}]}]}
{"op":"mcm","clk":"4214960562","pt":1631533004579,"mc":[{"id":"1.187557985","rc":[{"batb":[[0,1.59,179.04],[1,1.58,284.9],[2,1.56,52.33]],"batl":[[0,1.64,223.74]],"ltp":1.59,"tv":10650.4,"id":5300820},{"batb":[[0,2.54,4.87],[1,2.52,63.26],[2,2.44,9.42]],"batl":[[0,2.8,4.57],[1,2.86,5.49],[2,2.9,4.45]],"ltp":2.34,"tv":3657.37,"id":9629022}]}]}
{"op":"mcm","clk":"4214960639","pt":1631533005576,"mc":[{"id":"1.187557985","rc":[{"batb":[[0,1.53,76.33],[1,1.52,154.98],[2,1.45,4.26]],"batl":[[0,1.69,31.79],[1,1.73,28.87],[2,1.9,4]],"ltp":1.59,"tv":10650.4,"id":5300820},{"batb":[[0,2.44,9.42],[1,2.42,3],[2,2.36,6.43]],"batl":[[0,2.9,4.45],[1,3.45,53.16],[2,2.9,0]],"ltp":2.34,"tv":3657.37,"id":9629022}]}]}
{"op":"mcm","clk":"4214960652","pt":1631533005781,"mc":[{"id":"1.187557985","rc":[{"batl":[[0,1.73,28.87],[1,1.9,4],[2,1.91,3]],"ltp":1.59,"tv":10650.4,"id":5300820},{"batb":[[0,2.44,3]],"ltp":2.34,"tv":3657.37,"id":9629022}]}]}
{"op":"mcm","clk":"4214960778","pt":1631533007663,"mc":[{"id":"1.187557985","rc":[{"batb":[[1,1.52,300.84],[2,1.51,183.35]],"batl":[[1,1.75,130.87],[2,1.77,206.93]],"ltp":1.59,"tv":10650.4,"id":5300820}]}]}
{"op":"mcm","clk":"4214960852","pt":1631533008498,"mc":[{"id":"1.187557985","rc":[{"batb":[[0,1.56,71.08],[1,1.53,76.33],[2,1.52,300.84]],"ltp":1.59,"tv":10650.4,"id":5300820},{"batl":[[0,2.8,4.82],[1,2.9,4.45],[2,3.45,53.16]],"ltp":2.34,"tv":3657.37,"id":9629022}]}]}
{"op":"mcm","clk":"4214960908","pt":1631533009383,"mc":[{"id":"1.187557985","rc":[{"batb":[[0,1.53,76.33],[1,1.52,300.84],[2,1.51,183.35]],"batl":[[0,1.7,4],[1,1.73,28.87],[2,1.75,130.87]],"ltp":1.59,"tv":10650.4,"id":5300820},{"batl":[[0,2.9,7.45],[1,3.45,53.16],[2,3.45,0]],"ltp":2.34,"tv":3657.37,"id":9629022}]}]}
{"op":"mcm","clk":"4214960973","pt":1631533010373,"mc":[{"id":"1.187557985","rc":[{"batb":[[1,2.36,6.43],[2,2.3,80.84]],"batl":[[0,2.56,112.16],[1,2.9,7.45],[2,3.45,53.16]],"ltp":2.34,"tv":3657.37,"id":9629022}]}]}
{"op":"mcm","clk":"4214961147","pt":1631533012613,"mc":[{"id":"1.187557985","rc":[{"batb":[[0,1.56,76.58],[1,1.53,76.33],[2,1.52,300.84]],"batl":[[0,1.69,38.5],[1,1.7,4],[2,1.73,28.87]],"ltp":1.59,"tv":10650.4,"id":5300820},{"batb":[[0,2.44,8.92]],"batl":[[1,2.8,4.42],[2,2.9,7.45]],"ltp":2.34,"tv":3657.37,"id":9629022}]}]}
{"op":"mcm","clk":"4214961217","pt":1631533013601,"mc":[{"id":"1.187557985","rc":[{"batb":[[0,1.53,76.33],[1,1.52,300.84],[2,1.51,183.35]],"batl":[[0,1.7,4],[1,1.73,28.87],[2,1.75,130.87]],"ltp":1.59,"tv":10650.4,"id":5300820},{"batb":[[0,2.44,3],[1,2.42,3],[2,2.36,6.43]],"batl":[[0,2.9,7.45],[1,3.45,53.16],[2,2.9,0]],"ltp":2.34,"tv":3657.37,"id":9629022}]}]}
{"op":"mcm","clk":"4214961651","pt":1631533019508,"mc":[{"id":"1.187557985","rc":[{"batb":[[1,1.52,154.98],[2,1.45,4.26]],"batl":[[0,1.69,32.5],[1,1.7,4],[2,1.73,28.87]],"ltp":1.59,"tv":10650.4,"id":5300820},{"batb":[[0,2.44,8.92]],"ltp":2.34,"tv":3657.37,"id":9629022}]}]}
{"op":"mcm","clk":"4214961721","pt":1631533020508,"mc":[{"id":"1.187557985","rc":[{"trd":[[1.7,12.31]],"batl":[[0,1.73,28.87],[1,1.75,130.87],[2,1.77,206.93]],"ltp":1.7,"tv":10662.71,"id":5300820},{"trd":[[2.44,3]],"batb":[[0,2.42,3],[1,2.36,6.43],[2,2.3,80.84]],"ltp":2.44,"tv":3660.37,"id":9629022}],"tv":14323.09}]}
{"op":"mcm","clk":"4214961806","pt":1631533021504,"mc":[{"id":"1.187557985","rc":[{"batb":[[0,1.65,75.53],[1,1.53,76.33],[2,1.52,154.98]],"ltp":1.7,"tv":10662.71,"id":5300820},{"batl":[[0,2.48,1542.34],[1,2.5,1496.98],[2,2.52,1496.98]],"ltp":2.44,"tv":3660.37,"id":9629022}]}]}
{"op":"mcm","clk":"4214961875","pt":1631533022615,"mc":[{"id":"1.187557985","rc":[{"trd":[[1.7,37.01]],"batb":[[0,1.7,128.2],[1,1.68,349.51],[2,1.65,75.53]],"ltp":1.7,"tv":10687.41,"id":5300820},{"batb":[[0,2.36,6.43],[1,2.3,80.84],[2,2.08,107.61]],"batl":[[0,2.48,771.18],[1,2.5,748.48],[2,2.52,748.48]],"ltp":2.44,"tv":3660.37,"id":9629022}],"tv":14347.79}]}
{"op":"mcm","clk":"4214961945","pt":1631533023615,"mc":[{"id":"1.187557985","rc":[{"batl":[[1,1.75,138.37]],"ltp":1.7,"tv":10687.41,"id":5300820},{"batb":[[1,2.34,5.59],[2,2.3,80.84]],"ltp":2.44,"tv":3660.37,"id":9629022}]}]}
{"op":"mcm","clk":"4214962011","pt":1631533024615,"mc":[{"id":"1.187557985","rc":[{"batb":[[1,1.68,353.51],[2,1.67,4]],"ltp":1.7,"tv":10687.41,"id":5300820},{"batl":[[0,2.46,3],[1,2.48,771.18],[2,2.5,748.48]],"ltp":2.44,"tv":3660.37,"id":9629022}]}]}
{"op":"mcm","clk":"4214962061","pt":1631533025195,"mc":[{"id":"1.187557985","rc":[{"batl":[[1,1.75,155.01]],"ltp":1.7,"tv":10687.41,"id":5300820}]}]}
{"op":"mcm","clk":"4214962186","pt":1631533026607,"mc":[{"id":"1.187557985","rc":[{"batb":[[0,1.71,141.68],[1,1.7,128.2],[2,1.68,353.51]],"ltp":1.7,"tv":10687.41,"id":5300820}]}]}
{"op":"mcm","clk":"4214962269","pt":1631533027558,"mc":[{"id":"1.187557985","rc":[{"batb":[[0,1.7,128.2],[1,1.68,353.51],[2,1.67,4]],"ltp":1.7,"tv":10687.41,"id":5300820}]}]}
{"op":"mcm","clk":"4214962502","pt":1631533030424,"mc":[{"id":"1.187557985","rc":[{"batl":[[0,2.44,15],[1,2.46,3],[2,2.48,771.18]],"ltp":2.44,"tv":3660.37,"id":9629022}]}]}
{"op":"mcm","clk":"4214962661","pt":1631533032514,"mc":[{"id":"1.187557985","rc":[{"trd":[[1.7,51.47]],"batb":[[0,1.7,120.97]],"ltp":1.7,"tv":10701.87,"id":5300820}],"tv":14362.25}]}
{"op":"mcm","clk":"4214962739","pt":1631533033508,"mc":[{"id":"1.187557985","rc":[{"batb":[[0,1.71,36.67],[1,1.7,120.97],[2,1.68,353.51]],"ltp":1.7,"tv":10701.87,"id":5300820}]}]}
{"op":"mcm","clk":"4214962781","pt":1631533034025,"mc":[{"id":"1.187557985","rc":[{"trd":[[1.71,14.15]],"batb":[[0,1.71,22.52]],"ltp":1.71,"tv":10716.02,"id":5300820},{"trd":[[2.42,10]],"ltp":2.42,"tv":3670.37,"id":9629022}],"tv":14386.4}]}
{"op":"mcm","clk":"4214963046","pt":1631533037630,"mc":[{"id":"1.187557985","rc":[{"trd":[[1.73,28.87],[1.75,104.7]],"batb":[[0,1.7,120.97],[1,1.68,353.51],[2,1.65,75.53]],"batl":[[0,1.75,50.31],[1,1.77,206.93],[2,1.89,265.1]],"ltp":1.75,"tv":10849.59,"id":5300820},{"trd":[[2.32,78.98],[2.34,27.3],[2.36,34.02]],"batb":[[0,2.3,80.84],[1,2.22,3],[2,2.12,235.26]],"batl":[[0,2.46,3],[1,2.54,16.75],[2,2.62,5.75]],"ltp":2.32,"tv":3794.55,"id":9629022}],"tv":14644.15}]}
{"op":"mcm","clk":"4214963095","pt":1631533038251,"mc":[{"id":"1.187557985","rc":[{"batb":[[0,1.68,4],[1,1.62,74.04],[2,1.6,281.41]],"batl":[[0,1.75,7.5],[1,1.89,265.1],[2,1.9,290.94]],"ltp":1.75,"tv":10849.59,"id":5300820},{"batb":[[0,2.22,3],[1,2.12,235.26],[2,2.1,195.37]],"batl":[[1,2.62,5.75],[2,2.66,155.94]],"ltp":2.32,"tv":3794.55,"id":9629022}]}]}
{"op":"mcm","clk":"4214963179","pt":1631533039448,"mc":[{"id":"1.187557985","rc":[{"batb":[[0,1.73,100],[1,1.68,4],[2,1.62,74.04]],"batl":[[0,1.89,265.1],[1,1.9,290.94],[2,1.91,247.78]],"ltp":1.75,"tv":10849.59,"id":5300820}]}]}
{"op":"mcm","clk":"4214963262","pt":1631533040551,"mc":[{"id":"1.187557985","rc":[{"batb":[[1,1.62,74.04],[2,1.6,281.41]],"ltp":1.75,"tv":10849.59,"id":5300820},{"batb":[[0,2.3,23.07]],"batl":[[0,2.62,5.75],[1,2.66,155.94],[2,2.68,180.02]],"ltp":2.32,"tv":3794.55,"id":9629022}]}]}
{"op":"mcm","clk":"4214963323","pt":1631533041336,"mc":[{"id":"1.187557985","rc":[{"batb":[[0,2.12,235.26],[1,2.1,195.37],[2,2.08,403.09]],"ltp":2.32,"tv":3794.55,"id":9629022}]}]}
{"op":"mcm","clk":"4214963386","pt":1631533042117,"mc":[{"id":"1.187557985","rc":[{"batb":[[2,1.6,444.76]],"ltp":1.75,"tv":10849.59,"id":5300820}]}]}
{"op":"mcm","clk":"4214963457","pt":1631533042944,"mc":[{"id":"1.187557985","rc":[{"batl":[[0,1.89,270.1]],"ltp":1.75,"tv":10849.59,"id":5300820},{"batb":[[0,2.12,239.26],[1,2.1,199.37]],"ltp":2.32,"tv":3794.55,"id":9629022}]}]}
{"op":"mcm","clk":"4214963548","pt":1631533043938,"mc":[{"id":"1.187557985","rc":[{"batl":[[0,1.84,4],[1,1.89,270.1],[2,1.9,290.94]],"ltp":1.75,"tv":10849.59,"id":5300820}]}]}
{"op":"mcm","clk":"4214963916","pt":1631533048568,"mc":[{"id":"1.187557985","rc":[{"batb":[[0,1.62,74.04],[1,1.6,444.76],[2,1.59,558.81]],"ltp":1.75,"tv":10849.59,"id":5300820}]}]}
{"op":"mcm","clk":"4214963941","pt":1631533048832,"mc":[{"id":"1.187557985","rc":[{"batb":[[0,1.6,444.76],[1,1.59,558.81],[2,1.58,402.86]],"ltp":1.75,"tv":10849.59,"id":5300820},{"batl":[[0,2.66,155.94],[1,2.68,180.02],[2,2.7,250.73]],"ltp":2.32,"tv":3794.55,"id":9629022}]}]}
{"op":"mcm","clk":"4214964287","pt":1631533053145,"mc":[{"id":"1.187557985","rc":[{"batb":[[0,1.6,281.41],[1,1.59,408.88]],"ltp":1.75,"tv":10849.59,"id":5300820}]}]}
{"op":"mcm","clk":"4214964398","pt":1631533054241,"mc":[{"id":"1.187557985","rc":[{"batl":[[0,1.73,60],[1,1.84,4],[2,1.89,270.1]],"ltp":1.75,"tv":10849.59,"id":5300820},{"batb":[[1,2.1,195.37]],"ltp":2.32,"tv":3794.55,"id":9629022}]}]}
{"op":"mcm","clk":"4214964498","pt":1631533055647,"mc":[{"id":"1.187557985","rc":[{"batb":[[0,1.62,95.04],[1,1.6,281.41],[2,1.59,408.88]],"ltp":1.75,"tv":10849.59,"id":5300820},{"batl":[[0,2.62,6.46],[1,2.66,155.94],[2,2.68,180.02]],"ltp":2.32,"tv":3794.55,"id":9629022}]}]}
{"op":"mcm","clk":"4214964584","pt":1631533056637,"mc":[{"id":"1.187557985","rc":[{"trd":[[1.73,148.87]],"batb":[[0,1.73,109.46],[1,1.71,229.09],[2,1.6,281.41]],"batl":[[0,1.84,4],[1,1.89,265.1],[2,1.9,290.94]],"ltp":1.73,"tv":10969.59,"id":5300820},{"batl":[[0,2.66,155.94],[1,2.68,180.02],[2,2.7,250.73]],"ltp":2.32,"tv":3794.55,"id":9629022}],"tv":14764.15}]}
{"op":"mcm","clk":"4214964636","pt":1631533057255,"mc":[{"id":"1.187557985","rc":[{"batb":[[0,1.6,281.41],[1,1.59,408.88],[2,1.58,402.86]],"ltp":1.73,"tv":10969.59,"id":5300820}]}]}
{"op":"mcm","clk":"4214964956","pt":1631533061157,"mc":[{"id":"1.187557985","rc":[{"batb":[[1,1.59,686.97],[2,1.58,556.92]],"ltp":1.73,"tv":10969.59,"id":5300820}]}]}
{"op":"mcm","clk":"4214965085","pt":1631533062560,"mc":[{"id":"1.187557985","rc":[{"batb":[[0,1.62,95.04],[1,1.6,281.41],[2,1.59,686.97]],"ltp":1.73,"tv":10969.59,"id":5300820},{"batl":[[0,2.62,6.25],[1,2.66,155.94],[2,2.68,180.02]],"ltp":2.32,"tv":3794.55,"id":9629022}]}]}
{"op":"mcm","clk":"4214965111","pt":1631533062765,"mc":[{"id":"1.187557985","rc":[{"batb":[[0,1.6,281.41],[1,1.59,686.97],[2,1.58,556.92]],"ltp":1.73,"tv":10969.59,"id":5300820},{"batl":[[0,2.66,155.94],[1,2.68,180.02],[2,2.7,250.73]],"ltp":2.32,"tv":3794.55,"id":9629022}]}]}
{"op":"mcm","clk":"4214965566","pt":1631533068577,"mc":[{"id":"1.187557985","rc":[{"batb":[[0,1.59,129.96],[1,1.57,70.57],[2,1.53,76.33]],"ltp":1.73,"tv":10969.59,"id":5300820},{"batl":[[0,2.76,4.27],[1,2.9,4.45],[2,3.45,53.16]],"ltp":2.32,"tv":3794.55,"id":9629022}]}]}
{"op":"mcm","clk":"4214965657","pt":1631533069564,"mc":[{"id":"1.187557985","rc":[{"batl":[[0,1.89,265.1],[1,1.9,290.94],[2,1.91,247.78]],"ltp":1.73,"tv":10969.59,"id":5300820}]}]}
{"op":"mcm","clk":"4214965835","pt":1631533071565,"mc":[{"id":"1.187557985","rc":[{"batb":[[0,1.85,2147.98],[1,1.83,1318.5],[2,1.82,1014.34]],"batl":[[0,1.9,290.94],[1,1.91,247.78],[2,1.92,163.12]],"ltp":1.73,"tv":10969.59,"id":5300820},{"batb":[[0,2.1,195.37],[1,2.08,403.09],[2,1.6,99.04]],"batl":[[0,2.22,24.75],[1,2.66,7.52],[2,2.76,4.27]],"ltp":2.32,"tv":3794.55,"id":9629022}]}]}
{"op":"mcm","clk":"4214965913","pt":1631533072654,"mc":[{"id":"1.187557985","rc":[{"trd":[[1.85,23.26]],"batb":[[0,1.85,178.37],[2,1.82,1095.68]],"batl":[[1,1.91,255.28]],"ltp":1.85,"tv":10992.85,"id":5300820},{"batb":[[0,2.1,222.64],[2,1.88,74.31]],"batl":[[1,2.34,6.47],[2,2.66,7.52]],"ltp":2.32,"tv":3794.55,"id":9629022}],"tv":14787.41}]}
{"op":"mcm","clk":"4214965993","pt":1631533073589,"mc":[{"id":"1.187557985","rc":[{"batb":[[0,1.86,31.3],[1,1.85,178.37],[2,1.83,1318.5]],"ltp":1.85,"tv":10992.85,"id":5300820},{"batl":[[2,2.36,21.35]],"ltp":2.32,"tv":3794.55,"id":9629022}]}]}
{"op":"mcm","clk":"4214966088","pt":1631533074588,"mc":[{"id":"1.187557985","rc":[{"batb":[[0,1.86,35.3],[1,1.85,182.37]],"ltp":1.85,"tv":10992.85,"id":5300820},{"batb":[[2,2,4]],"batl":[[1,2.64,3],[2,2.66,7.52]],"ltp":2.32,"tv":3794.55,"id":9629022}]}]}
{"op":"mcm","clk":"4214966178","pt":1631533075477,"mc":[{"id":"1.187557985","rc":[{"batb":[[0,1.86,4]],"ltp":1.85,"tv":10992.85,"id":5300820}]}]}
{"op":"mcm","clk":"4214966343","pt":1631533077481,"mc":[{"id":"1.187557985","rc":[{"batl":[[0,2.2,47.33],[1,2.22,24.75],[2,2.64,3]],"ltp":2.32,"tv":3794.55,"id":9629022}]}]}
{"op":"mcm","clk":"4214966413","pt":1631533078261,"mc":[{"id":"1.187557985","rc":[{"batb":[[0,1.87,31.3],[1,1.86,4],[2,1.85,182.37]],"ltp":1.85,"tv":10992.85,"id":5300820},{"batl":[[2,2.32,6.52]],"ltp":2.32,"tv":3794.55,"id":9629022}]}]}
{"op":"mcm","clk":"4214966798","pt":1631533083366,"mc":[{"id":"1.187557985","rc":[{"batb":[[2,1.85,178.34]],"ltp":1.85,"tv":10992.85,"id":5300820}]}]}
{"op":"mcm","clk":"4214967163","pt":1631533088305,"mc":[{"id":"1.187557985","rc":[{"trd":[[1.9,138.76]],"batb":[[2,1.85,174.34]],"batl":[[0,1.9,152.17]],"ltp":1.9,"tv":11131.62,"id":5300820},{"trd":[[2.1,570.82]],"batb":[[0,2.08,403.09],[1,2,4],[2,1.88,74.31]],"batl":[[2,2.42,6.75]],"ltp":2.1,"tv":4365.37,"id":9629022}],"tv":15497.0}]}
{"op":"mcm","clk":"4214967439","pt":1631533091580,"mc":[{"id":"1.187557985","rc":[{"batb":[[0,1.82,81.34],[1,1.81,8.33],[2,1.71,76.19]],"batl":[[0,1.91,7.5],[1,2.3,314.02],[2,1.92,0]],"ltp":1.9,"tv":11131.62,"id":5300820},{"batb":[[0,2.08,107.45],[1,2.06,28.3]],"batl":[[0,2.24,6.73],[1,2.42,6.75],[2,2.58,5.44]],"ltp":2.1,"tv":4365.37,"id":9629022}]}]}
{"op":"mcm","clk":"4214967532","pt":1631533092525,"mc":[{"id":"1.187557985","rc":[{"batb":[[0,1.69,104.35],[1,1.64,79.57],[2,1.63,75.23]],"batl":[[0,2.3,314.02],[1,2.3,0]],"ltp":1.9,"tv":11131.62,"id":5300820},{"batb":[[0,1.88,74.31],[1,1.5,106.96],[2,1.43,3.41]],"batl":[[0,2.58,5.44],[1,2.6,6.16],[2,2.64,3]],"ltp":2.1,"tv":4365.37,"id":9629022}]}]}
{"op":"mcm","clk":"4214967671","pt":1631533094510,"mc":[{"id":"1.187557985","rc":[{"batb":[[0,1.7,229.6],[1,1.69,104.35],[2,1.68,244.09]],"batl":[[0,2.16,128.48],[1,2.18,109.49],[2,2.3,314.02]],"ltp":1.9,"tv":11131.62,"id":5300820}]}]}
{"op":"mcm","clk":"4214968177","pt":1631533095749,"mc":[{"id":"1.187557985","rc":[{"batb":[[1,1.69,110.35],[2,1.68,250.09]],"batl":[[0,2.14,4],[1,2.16,128.48],[2,2.18,109.49]],"ltp":1.9,"tv":11131.62,"id":5300820},{"batb":[[0,1.88,78.31],[1,1.87,5],[2,1.5,106.96]],"batl":[[0,2.46,3],[1,2.58,5.44],[2,2.6,6.16]],"ltp":2.1,"tv":4365.37,"id":9629022}]}]}
{"op":"mcm","clk":"4214968545","pt":1631533098612,"mc":[{"id":"1.187557985","rc":[{"batb":[[0,1.71,82.19],[1,1.7,229.6],[2,1.69,110.35]],"ltp":1.9,"tv":11131.62,"id":5300820},{"batl":[[0,2.42,6.25],[1,2.46,3],[2,2.58,5.44]],"ltp":2.1,"tv":4365.37,"id":9629022}]}]}
{"op":"mcm","clk":"4214968570","pt":1631533098923,"mc":[{"id":"1.187557985","rc":[{"batb":[[0,1.7,229.6],[1,1.69,110.35],[2,1.68,250.09]],"ltp":1.9,"tv":11131.62,"id":5300820},{"batl":[[0,2.46,3],[1,2.58,5.44],[2,2.6,6.16]],"ltp":2.1,"tv":4365.37,"id":9629022}]}]}
{"op":"mcm","clk":"4214969017","pt":1631533104223,"mc":[{"id":"1.187557985","rc":[{"batb":[[0,1.69,104.35],[1,1.64,79.57],[2,1.63,75.23]],"batl":[[1,2.3,314.02],[2,2.18,0]],"ltp":1.9,"tv":11131.62,"id":5300820},{"batl":[[0,2.58,5.44],[1,2.6,6.16],[2,2.64,3]],"ltp":2.1,"tv":4365.37,"id":9629022}]}]}
{"op":"mcm","clk":"4214969223","pt":1631533106614,"mc":[{"id":"1.187557985","rc":[{"trd":[[1.69,41.26]],"batb":[[0,1.69,92],[1,1.67,629.86],[2,1.66,611.35]],"ltp":1.69,"tv":11156.32,"id":5300820},{"batb":[[0,2.3,831.52],[1,2.28,807.06],[2,2.26,807.06]],"ltp":2.1,"tv":4365.37,"id":9629022}],"tv":15521.7}]}
{"op":"mcm","clk":"4214969295","pt":1631533107602,"mc":[{"id":"1.187557985","rc":[{"batb":[[0,1.7,229.6],[1,1.69,101.02],[2,1.68,244.09]],"batl":[[0,1.76,166.38],[1,1.78,203.08],[2,1.81,7.5]],"ltp":1.69,"tv":11156.32,"id":5300820},{"batb":[[0,2.3,913.61]],"batl":[[0,2.46,6.2],[1,2.58,5.44],[2,2.6,6.16]],"ltp":2.1,"tv":4365.37,"id":9629022}]}]}
{"op":"mcm","clk":"4214969439","pt":1631533109426,"mc":[{"id":"1.187557985","rc":[{"batb":[[0,1.7,233.6]],"batl":[[2,1.96,20]],"ltp":1.69,"tv":11156.32,"id":5300820},{"batl":[[0,2.44,4],[1,2.46,6.2],[2,2.58,5.44]],"ltp":2.1,"tv":4365.37,"id":9629022}]}]}
{"op":"mcm","clk":"4214969494","pt":1631533109996,"mc":[{"id":"1.187557985","rc":[{"batl":[[0,2.42,3],[1,2.44,4],[2,2.46,6.2]],"ltp":2.1,"tv":4365.37,"id":9629022}]}]}
{"op":"mcm","clk":"4214969630","pt":1631533111513,"mc":[{"id":"1.187557985","rc":[{"batb":[[0,1.71,48.22],[1,1.7,233.6],[2,1.69,101.02]],"ltp":1.69,"tv":11156.32,"id":5300820}]}]}
{"op":"mcm","clk":"4214969719","pt":1631533112614,"mc":[{"id":"1.187557985","rc":[{"batl":[[2,1.79,7.5]],"ltp":1.69,"tv":11156.32,"id":5300820}]}]}
{"op":"mcm","clk":"4214969876","pt":1631533114635,"mc":[{"id":"1.187557985","rc":[{"batl":[[0,2.4,31],[1,2.42,3],[2,2.44,4]],"ltp":2.1,"tv":4365.37,"id":9629022}]}]}
{"op":"mcm","clk":"4214969969","pt":1631533115600,"mc":[{"id":"1.187557985","rc":[{"batb":[[2,2.26,830.86]],"batl":[[0,2.4,15]],"ltp":2.1,"tv":4365.37,"id":9629022}]}]}
{"op":"mcm","clk":"4214970353","pt":1631533120450,"mc":[{"id":"1.187557985","rc":[{"batb":[[0,1.73,100],[1,1.71,20],[2,1.7,4]],"batl":[[0,1.76,149.19]],"ltp":1.69,"tv":11156.32,"id":5300820}]}]}
{"op":"mcm","clk":"4214970527","pt":1631533122535,"mc":[{"id":"1.187557985","rc":[{"batb":[[1,1.69,9.02],[2,1.64,79.57]],"batl":[[0,1.79,7.5],[1,2.12,3],[2,2.3,314.02]],"ltp":1.69,"tv":11156.32,"id":5300820},{"batb":[[0,2.26,23.8],[1,2.08,108.03],[2,1.89,4]],"batl":[[0,2.46,6.2],[1,2.58,5.44],[2,2.6,6.16]],"ltp":2.1,"tv":4365.37,"id":9629022}]}]}
{"op":"mcm","clk":"4214970605","pt":1631533123469,"mc":[{"id":"1.187557985","rc":[{"batb":[[1,1.64,79.57],[2,1.63,75.23]],"batl":[[0,2.12,3],[1,2.3,314.02],[2,2.3,0]],"ltp":1.69,"tv":11156.32,"id":5300820},{"batb":[[0,2.08,107.61],[1,1.89,4],[2,1.7,16.97]],"batl":[[0,2.58,5.44],[1,2.6,6.16],[2,2.68,6.14]],"ltp":2.1,"tv":4365.37,"id":9629022}]}]}
{"op":"mcm","clk":"4214970648","pt":1631533123982,"mc":[{"id":"1.187557985","rc":[{"batb":[[0,1.6,91.69],[1,1.59,128.7],[2,1.58,87.56]],"ltp":1.69,"tv":11156.32,"id":5300820},{"batl":[[0,2.68,6.14],[1,2.74,5.48],[2,2.76,4.27]],"ltp":2.1,"tv":4365.37,"id":9629022}]}]}
{"op":"mcm","clk":"4214970796","pt":1631533125657,"mc":[{"id":"1.187557985","rc":[{"batb":[[0,1.6,314.39],[1,1.59,368]],"batl":[[0,1.93,163.53],[1,1.95,152.12],[2,2.12,3]],"ltp":1.69,"tv":11156.32,"id":5300820},{"batl":[[1,2.7,5.75],[2,2.74,5.48]],"ltp":2.1,"tv":4365.37,"id":9629022}]}]}
{"op":"mcm","clk":"4214970876","pt":1631533126652,"mc":[{"id":"1.187557985","rc":[{"batl":[[0,1.93,4],[1,2.12,3],[2,2.3,314.02]],"ltp":1.69,"tv":11156.32,"id":5300820},{"batb":[[0,2.08,111.61],[1,2.06,4],[2,1.89,4]],"ltp":2.1,"tv":4365.37,"id":9629022}]}]}
{"op":"mcm","clk":"4214970921","pt":1631533127281,"mc":[{"id":"1.187557985","rc":[{"batb":[[0,1.76,100],[1,1.64,85.07],[2,1.6,314.39]],"ltp":1.69,"tv":11156.32,"id":5300820},{"batl":[[0,2.58,6.25],[1,2.68,10.14],[2,2.7,5.75]],"ltp":2.1,"tv":4365.37,"id":9629022}]}]}
{"op":"mcm","clk":"4214971014","pt":1631533128584,"mc":[{"id":"1.187557985","rc":[{"trd":[[1.76,33.8]],"batb":[[0,1.76,83.1],[1,1.6,314.39],[2,1.59,368]],"ltp":1.76,"tv":11190.12,"id":5300820},{"batl":[[0,2.68,10.14],[1,2.7,5.75],[2,2.74,5.48]],"ltp":2.1,"tv":4365.37,"id":9629022}],"tv":15555.5}]}
{"op":"mcm","clk":"4214971107","pt":1631533129568,"mc":[{"id":"1.187557985","rc":[{"trd":[[1.6,1067.81],[1.76,200]],"batb":[[0,1.6,301.49],[1,1.59,368],[2,1.58,87.56]],"batl":[[0,1.65,2088.04],[1,1.66,127.9],[2,1.93,4]],"ltp":1.6,"tv":11382.12,"id":5300820},{"batb":[[0,2.52,1517.86],[1,2.5,1473.22],[2,2.48,1473.22]],"batl":[[2,2.74,1401.46]],"ltp":2.1,"tv":4365.37,"id":9629022}],"tv":15747.5}]}
{"op":"mcm","clk":"4214971200","pt":1631533130564,"mc":[{"id":"1.187557985","rc":[{"batb":[[0,1.6,305.49],[1,1.59,371]],"batl":[[0,1.65,195.18],[2,1.76,162.87]],"ltp":1.6,"tv":11382.12,"id":5300820},{"batb":[[0,2.52,823.37],[1,2.5,736.6],[2,2.48,736.6]],"batl":[[0,2.66,5.82],[1,2.68,10.14],[2,2.7,5.75]],"ltp":2.1,"tv":4365.37,"id":9629022}]}]}
{"op":"mcm","clk":"4214971285","pt":1631533131551,"mc":[{"id":"1.187557985","rc":[{"batl":[[2,1.76,465.57]],"ltp":1.6,"tv":11382.12,"id":5300820}]}]}
{"op":"mcm","clk":"4214971368","pt":1631533132573,"mc":[{"id":"1.187557985","rc":[{"batb":[[0,1.61,38.47],[1,1.6,305.49],[2,1.59,380.76]],"batl":[[2,1.76,497.46]],"ltp":1.6,"tv":11382.12,"id":5300820},{"batl":[[0,2.66,8.82]],"ltp":2.1,"tv":4365.37,"id":9629022}]}]}
{"op":"mcm","clk":"4214971436","pt":1631533133574,"mc":[{"id":"1.187557985","rc":[{"batl":[[2,1.69,7.5]],"ltp":1.6,"tv":11382.12,"id":5300820}]}]}
{"op":"mcm","clk":"4214971513","pt":1631533134571,"mc":[{"id":"1.187557985","rc":[{"batl":[[2,1.76,31.89]],"ltp":1.6,"tv":11382.12,"id":5300820}]}]}
{"op":"mcm","clk":"4214971561","pt":1631533135185,"mc":[{"id":"1.187557985","rc":[{"batl":[[2,1.76,4]],"ltp":1.6,"tv":11382.12,"id":5300820},{"batl":[[0,2.64,27.92],[1,2.66,8.82],[2,2.68,10.14]],"ltp":2.1,"tv":4365.37,"id":9629022}]}]}
{"op":"mcm","clk":"4214971636","pt":1631533136281,"mc":[{"id":"1.187557985","rc":[{"batl":[[2,1.71,35.5]],"ltp":1.6,"tv":11382.12,"id":5300820}]}]}
{"op":"mcm","clk":"4214971698","pt":1631533137069,"mc":[{"id":"1.187557985","rc":[{"batl":[[2,1.68,7.5]],"ltp":1.6,"tv":11382.12,"id":5300820}]}]}
{"op":"mcm","clk":"4214971775","pt":1631533138056,"mc":[{"id":"1.187557985","rc":[{"batb":[[2,2.48,756.87]],"ltp":2.1,"tv":4365.37,"id":9629022}]}]}
{"op":"mcm","clk":"4214972065","pt":1631533141356,"mc":[{"id":"1.187557985","rc":[{"batl":[[0,1.65,179.4]],"ltp":1.6,"tv":11382.12,"id":5300820},{"trd":[[2.52,12.8]],"batb":[[0,2.52,818.47]],"ltp":2.52,"tv":4375.17,"id":9629022}],"tv":15757.29}]}
{"op":"mcm","clk":"4214972091","pt":1631533141671,"mc":[{"id":"1.187557985","rc":[{"batb":[[2,1.59,377.76]],"ltp":1.6,"tv":11382.12,"id":5300820}]}]}
{"op":"mcm","clk":"4214972261","pt":1631533143559,"mc":[{"id":"1.187557985","rc":[{"batb":[[0,1.6,305.49],[1,1.59,377.76],[2,1.58,87.56]],"ltp":1.6,"tv":11382.12,"id":5300820},{"batl":[[0,2.66,8.82],[1,2.68,10.14],[2,2.7,5.75]],"ltp":2.52,"tv":4375.17,"id":9629022}]}]}
{"op":"mcm","clk":"4214972306","pt":1631533144108,"mc":[{"id":"1.187557985","rc":[{"batb":[[0,1.59,9.76],[1,1.55,83.19],[2,1.52,152.8]],"batl":[[0,1.68,7.5],[1,1.75,32.06],[2,2.16,347.55]],"ltp":1.6,"tv":11382.12,"id":5300820},{"batb":[[0,2.48,20.27],[1,2.32,6.64],[2,2.3,81.76]],"batl":[[0,2.66,5.82],[1,2.82,5.25],[2,3.45,53.16]],"ltp":2.52,"tv":4375.17,"id":9629022}]}]}
{"op":"mcm","clk":"4214972416","pt":1631533145397,"mc":[{"id":"1.187557985","rc":[{"batb":[[0,1.55,83.19],[1,1.52,152.8],[2,1.45,4.26]],"batl":[[0,1.75,32.06],[1,2.16,347.55],[2,2.16,0]],"ltp":1.6,"tv":11382.12,"id":5300820},{"batb":[[0,2.32,6.64],[1,2.3,81.76],[2,1.6,99.04]],"batl":[[0,2.82,5.25],[1,3.45,53.16],[2,3.45,0]],"ltp":2.52,"tv":4375.17,"id":9629022}]}]}
{"op":"mcm","clk":"4214972607","pt":1631533147581,"mc":[{"id":"1.187557985","rc":[{"batb":[[1,1.53,153.39],[2,1.52,331.35]],"batl":[[1,1.77,166.94],[2,1.79,199.35]],"ltp":1.6,"tv":11382.12,"id":5300820}]}]}
{"op":"mcm","clk":"4214972691","pt":1631533148577,"mc":[{"id":"1.187557985","rc":[{"batb":[[0,1.55,88.19],[1,1.54,6],[2,1.52,152.8]],"batl":[[1,2.16,347.55],[2,1.79,0]],"ltp":1.6,"tv":11382.12,"id":5300820},{"batl":[[0,2.82,8.25]],"ltp":2.52,"tv":4375.17,"id":9629022}]}]}
{"op":"mcm","clk":"4214972892","pt":1631533151379,"mc":[{"id":"1.187557985","rc":[{"batb":[[0,1.62,233.8],[1,1.61,143.35],[2,1.57,5]],"batl":[[0,1.67,144.4],[1,1.69,241.97],[2,1.75,32.06]],"ltp":1.6,"tv":11382.12,"id":5300820}]}]}
{"op":"mcm","clk":"4214972957","pt":1631533152481,"mc":[{"id":"1.187557985","rc":[{"batl":[[2,1.74,56.65]],"ltp":1.6,"tv":11382.12,"id":5300820},{"batb":[[0,2.34,33.2],[1,2.32,6.64],[2,2.3,81.76]],"batl":[[0,2.8,41.25],[1,2.82,8.25],[2,3.45,53.16]],"ltp":2.52,"tv":4375.17,"id":9629022}]}]}
{"op":"mcm","clk":"4214972991","pt":1631533152895,"mc":[{"id":"1.187557985","rc":[{"batb":[[0,1.57,5],[1,1.56,5],[2,1.55,88.19]],"batl":[[0,1.75,32.06],[1,2.16,347.55],[2,1000,2.89]],"ltp":1.6,"tv":11382.12,"id":5300820},{"batb":[[0,2.32,6.64],[1,2.3,81.76],[2,1.6,99.04]],"batl":[[0,2.82,8.25],[1,3.45,53.16],[2,3.45,0]],"ltp":2.52,"tv":4375.17,"id":9629022}]}]}
{"op":"mcm","clk":"4214973120","pt":1631533154623,"mc":[{"id":"1.187557985","rc":[{"batl":[[0,1.71,31.5],[1,1.75,32.06],[2,2.16,347.55]],"ltp":1.6,"tv":11382.12,"id":5300820},{"batl":[[0,2.76,3],[1,2.82,8.25],[2,3.45,53.16]],"ltp":2.52,"tv":4375.17,"id":9629022}]}]}
{"op":"mcm","clk":"4214973202","pt":1631533155568,"mc":[{"id":"1.187557985","rc":[{"batl":[[0,1.75,32.06],[1,1.77,166.94],[2,1.79,199.35]],"ltp":1.6,"tv":11382.12,"id":5300820}]}]}
{"op":"mcm","clk":"4214973764","pt":1631533161602,"mc":[{"id":"1.187557985","rc":[{"batb":[[2,1.55,83.19]],"ltp":1.6,"tv":11382.12,"id":5300820}]}]}
{"op":"mcm","clk":"4214973845","pt":1631533162486,"mc":[{"id":"1.187557985","rc":[{"batb":[[1,1.55,83.19],[2,1.53,153.39]],"batl":[[0,2.16,347.55],[1,1.77,0],[2,1.79,0]],"ltp":1.6,"tv":11382.12,"id":5300820}]}]}
{"op":"mcm","clk":"4214974212","pt":1631533165446,"mc":[{"id":"1.187557985","rc":[{"trd":[[1.57,965.43],[1.58,1054.89]],"batb":[[0,1.55,83.19],[1,1.53,153.39],[2,1.52,331.35]],"batl":[[0,1.57,117.94],[1,1.58,152.83],[2,1.71,33.5]],"ltp":1.57,"tv":11568.8,"id":5300820},{"trd":[[2.74,497.55]],"batb":[[0,2.7,708.32],[1,2.68,687.5],[2,2.66,687.5]],"batl":[[0,2.82,5.25],[1,2.98,352.98],[2,3,342.6]],"ltp":2.74,"tv":4380.65,"id":9629022}],"tv":15949.45}]}
{"op":"mcm","clk":"4214974326","pt":1631533166593,"mc":[{"id":"1.187557985","rc":[{"batb":[[0,2.72,52.72],[1,2.7,708.32],[2,2.68,705.35]],"ltp":2.74,"tv":4380.65,"id":9629022}]}]}
{"op":"mcm","clk":"4214974424","pt":1631533167479,"mc":[{"id":"1.187557985","rc":[{"batl":[[2,1.71,167.99]],"ltp":1.57,"tv":11568.8,"id":5300820}]}]}
{"op":"mcm","clk":"4214974550","pt":1631533168519,"mc":[{"id":"1.187557985","rc":[{"trd":[[1.57,1083.29]],"batl":[[0,1.57,59.01],[2,1.7,5]],"ltp":1.57,"tv":11686.66,"id":5300820}],"tv":16067.31}]}
{"op":"mcm","clk":"4214974645","pt":1631533169612,"mc":[{"id":"1.187557985","rc":[{"batb":[[1,1.53,201.84]],"batl":[[0,1.58,152.83],[1,1.59,7.5]],"ltp":1.57,"tv":11686.66,"id":5300820}]}]}
{"op":"mcm","clk":"4214974738","pt":1631533170402,"mc":[{"id":"1.187557985","rc":[{"batl":[[1,1.7,5],[2,1.71,167.99]],"ltp":1.57,"tv":11686.66,"id":5300820},{"batb":[[2,2.68,687.5]],"ltp":2.74,"tv":4380.65,"id":9629022}]}]}
{"op":"mcm","clk":"4214974941","pt":1631533172242,"mc":[{"id":"1.187557985","rc":[{"batb":[[1,1.53,235.31]],"batl":[[0,1.58,275.09],[1,1.59,148.64],[2,1.63,42.5]],"ltp":1.57,"tv":11686.66,"id":5300820}]}]}
{"op":"mcm","clk":"4214975022","pt":1631533173227,"mc":[{"id":"1.187557985","rc":[{"batl":[[0,1.58,282.59]],"ltp":1.57,"tv":11686.66,"id":5300820},{"batb":[[0,2.74,17.24],[1,2.72,52.72],[2,2.7,708.32]],"ltp":2.74,"tv":4380.65,"id":9629022}]}]}
{"op":"mcm","clk":"4214975418","pt":1631533177598,"mc":[{"id":"1.187557985","rc":[{"trd":[[2.74,515.21]],"batb":[[0,2.74,8.41]],"ltp":2.74,"tv":4398.31,"id":9629022}],"tv":16084.97}]}
{"op":"mcm","clk":"4214975466","pt":1631533178222,"mc":[{"id":"1.187557985","rc":[{"batl":[[0,1.58,303.27]],"ltp":1.57,"tv":11686.66,"id":5300820}]}]}
{"op":"mcm","clk":"4214975575","pt":1631533179619,"mc":[{"id":"1.187557985","rc":[{"trd":[[1.58,1154.89]],"batl":[[0,1.58,253.27]],"ltp":1.58,"tv":11786.66,"id":5300820}],"tv":16184.97}]}
{"op":"mcm","clk":"4214975671","pt":1631533180821,"mc":[{"id":"1.187557985","rc":[{"batb":[[1,2.72,61.55]],"ltp":2.74,"tv":4398.31,"id":9629022}]}]}
{"op":"mcm","clk":"4214975843","pt":1631533182907,"mc":[{"id":"1.187557985","rc":[{"batb":[[1,1.53,271.67]],"ltp":1.58,"tv":11786.66,"id":5300820}]}]}
{"op":"mcm","clk":"4214976367","pt":1631533189513,"mc":[{"id":"1.187557985","rc":[{"trd":[[2.74,519.21]],"batb":[[0,2.74,6.41]],"ltp":2.74,"tv":4402.31,"id":9629022}],"tv":16188.97}]}
{"op":"mcm","clk":"4214976656","pt":1631533193052,"mc":[{"id":"1.187557985","rc":[{"batl":[[0,1.58,232.59]],"ltp":1.58,"tv":11786.66,"id":5300820},{"batb":[[2,2.7,710.32]],"ltp":2.74,"tv":4402.31,"id":9629022}]}]}
{"op":"mcm","clk":"4214976901","pt":1631533196053,"mc":[{"id":"1.187557985","rc":[{"batl":[[0,1.57,20.68],[1,1.58,232.59],[2,1.59,148.64]],"ltp":1.58,"tv":11786.66,"id":5300820}]}]}
{"op":"mcm","clk":"4214977152","pt":1631533199221,"mc":[{"id":"1.187557985","rc":[{"batb":[[0,1.51,20.25],[1,1.49,52.01],[2,1.48,314.54]],"batl":[[1,1.58,7.5],[2,1.63,42.5]],"ltp":1.58,"tv":11786.66,"id":5300820},{"batb":[[1,2.72,8.83],[2,2.7,2]],"batl":[[0,3.05,4.1],[1,3.1,156.09],[2,3.15,139.66]],"ltp":2.74,"tv":4402.31,"id":9629022}]}]}
{"op":"mcm","clk":"4214977259","pt":1631533200436,"mc":[{"id":"1.187557985","rc":[{"batl":[[1,1.63,42.5],[2,1.65,226.64]],"ltp":1.58,"tv":11786.66,"id":5300820},{"batb":[[0,2.58,5.06],[1,2.54,178.19],[2,2.52,274.12]],"ltp":2.74,"tv":4402.31,"id":9629022}]}]}
{"op":"mcm","clk":"4214977456","pt":1631533202426,"mc":[{"id":"1.187557985","rc":[{"batb":[[1,1.48,314.54],[2,1.47,413.91]],"batl":[[2,1.65,417.83]],"ltp":1.58,"tv":11786.66,"id":5300820},{"batl":[[0,2.98,3]],"ltp":2.74,"tv":4402.31,"id":9629022}]}]}
{"op":"mcm","clk":"4214977540","pt":1631533203369,"mc":[{"id":"1.187557985","rc":[{"trd":[[1.57,1087.93]],"batl":[[0,1.57,18.36],[2,1.7,5]],"ltp":1.57,"tv":11791.3,"id":5300820},{"batb":[[1,2.52,63.43],[2,2.5,5.52]],"ltp":2.74,"tv":4402.31,"id":9629022}],"tv":16193.62}]}
{"op":"mcm","clk":"4214977606","pt":1631533203957,"mc":[{"id":"1.187557985","rc":[{"trd":[[1.57,1091.93]],"batl":[[0,1.57,16.36]],"ltp":1.57,"tv":11795.3,"id":5300820}],"tv":16197.62}]}
{"op":"mcm","clk":"4214977763","pt":1631533205567,"mc":[{"id":"1.187557985","rc":[{"batb":[[1,1.49,58.01],[2,1.48,314.54]],"ltp":1.57,"tv":11795.3,"id":5300820},{"batl":[[1,3.05,4.1],[2,3.1,156.09]],"ltp":2.74,"tv":4402.31,"id":9629022}]}]}
{"op":"mcm","clk":"4214977855","pt":1631533206359,"mc":[{"id":"1.187557985","rc":[{"trd":[[1.47,349.13],[1.5,167.93],[1.51,533.55]],"batb":[[0,1.47,400.12],[1,1.46,590.85],[2,1.45,460.79]],"batl":[[0,1.5,239.94],[1,1.51,1447.87],[2,1.52,1229.32]],"ltp":1.5,"tv":11881.34,"id":5300820},{"trd":[[2.98,3]],"batl":[[0,3.15,139.66],[1,3.2,183.33],[2,3.25,3.7]],"ltp":2.98,"tv":4405.31,"id":9629022}],"tv":16286.66}]}
{"op":"mcm","clk":"4214977985","pt":1631533207651,"mc":[{"id":"1.187557985","rc":[{"batb":[[0,2.94,105.94],[1,2.88,15.95],[2,2.74,51.55]],"batl":[[2,3.25,8.7]],"ltp":2.98,"tv":4405.31,"id":9629022}]}]}
{"op":"mcm","clk":"4214978127","pt":1631533209170,"mc":[{"id":"1.187557985","rc":[{"batb":[[1,1.46,597.85],[2,1.45,466.79]],"ltp":1.5,"tv":11881.34,"id":5300820},{"batb":[[2,2.76,4]],"batl":[[0,3.15,156.24]],"ltp":2.98,"tv":4405.31,"id":9629022}]}]}
{"op":"mcm","clk":"4214978268","pt":1631533210576,"mc":[{"id":"1.187557985","rc":[{"batb":[[2,2.86,3]],"ltp":2.98,"tv":4405.31,"id":9629022}]}]}
{"op":"mcm","clk":"4214978359","pt":1631533211465,"mc":[{"id":"1.187557985","rc":[{"batb":[[0,2.94,131.24]],"ltp":2.98,"tv":4405.31,"id":9629022}]}]}
{"op":"mcm","clk":"4214978434","pt":1631533212146,"mc":[{"id":"1.187557985","rc":[{"batb":[[1,2.86,3],[2,2.84,3]],"ltp":2.98,"tv":4405.31,"id":9629022}]}]}
{"op":"mcm","clk":"4214978650","pt":1631533214645,"mc":[{"id":"1.187557985","rc":[{"batl":[[0,1.5,292.94],[1,1.51,1455.37]],"ltp":1.5,"tv":11881.34,"id":5300820}]}]}
{"op":"mcm","clk":"4214978702","pt":1631533215363,"mc":[{"id":"1.187557985","rc":[{"batb":[[0,2.96,15.3],[1,2.94,131.24],[2,2.86,3]],"ltp":2.98,"tv":4405.31,"id":9629022}]}]}
{"op":"mcm","clk":"4214979223","pt":1631533221147,"mc":[{"id":"1.187557985","rc":[{"batb":[[2,1.45,460.79]],"batl":[[0,1.49,7.23],[1,1.5,292.94],[2,1.51,1455.37]],"ltp":1.5,"tv":11881.34,"id":5300820}]}]}
{"op":"mcm","clk":"4214979413","pt":1631533223488,"mc":[{"id":"1.187557985","rc":[{"batb":[[0,1.45,4.26],[1,1.44,11.3],[2,1.41,60.89]],"batl":[[1,1.5,53],[2,1.51,7.5]],"ltp":1.5,"tv":11881.34,"id":5300820},{"batb":[[1,2.76,178.36],[2,2.74,241.24]],"batl":[[0,3.25,5],[1,3.45,56.66],[2,3.5,119.53]],"ltp":2.98,"tv":4405.31,"id":9629022}]}]}
{"op":"mcm","clk":"4214979510","pt":1631533224574,"mc":[{"id":"1.187557985","rc":[{"batb":[[0,1.45,11.26],[1,1.41,60.89],[2,1.4,286.63]],"batl":[[1,1.57,395.27],[2,1.58,329.94]],"ltp":1.5,"tv":11881.34,"id":5300820},{"batb":[[0,2.84,2]],"batl":[[0,3.45,56.66],[1,3.5,119.53],[2,3.55,147.15]],"ltp":2.98,"tv":4405.31,"id":9629022}]}]}
{"op":"mcm","clk":"4214979520","pt":1631533224685,"mc":[{"id":"1.187557985","rc":[{"batb":[[0,1.45,4.26]],"ltp":1.5,"tv":11881.34,"id":5300820},{"batb":[[0,2.76,178.36],[1,2.74,241.24],[2,2.72,234.33]],"ltp":2.98,"tv":4405.31,"id":9629022}]}]}
{"op":"mcm","clk":"4214979684","pt":1631533226455,"mc":[{"id":"1.187557985","rc":[{"batl":[[0,1.57,616.98],[1,1.58,482.18],[2,1.59,428.71]],"ltp":1.5,"tv":11881.34,"id":5300820}]}]}
{"op":"mcm","clk":"4214980370","pt":1631533234565,"mc":[{"id":"1.187557985","rc":[{"batb":[[2,1.39,279.97]],"ltp":1.5,"tv":11881.34,"id":5300820},{"batl":[[1,3.75,3.18],[2,3.55,0]],"ltp":2.98,"tv":4405.31,"id":9629022}]}]}
{"op":"mcm","clk":"4214980418","pt":1631533235396,"mc":[{"id":"1.187557985","rc":[{"batb":[[2,1.38,226.94]],"batl":[[0,1.57,395.27],[1,1.58,329.94]],"ltp":1.5,"tv":11881.34,"id":5300820}]}]}
{"op":"mcm","clk":"4214980562","pt":1631533237480,"mc":[{"id":"1.187557985","rc":[{"batb":[[0,1.52,44.74],[1,1.45,4.26],[2,1.41,60.89]],"batl":[[2,1.59,2834.37]],"ltp":1.5,"tv":11881.34,"id":5300820},{"batl":[[0,2.94,7.75],[1,2.98,1283.56],[2,3,1245.8]],"ltp":2.98,"tv":4405.31,"id":9629022}]}]}
{"op":"mcm","clk":"4214980645","pt":1631533238579,"mc":[{"id":"1.187557985","rc":[{"trd":[[1.52,834.18]],"batb":[[0,1.52,341.56],[1,1.51,339.51],[2,1.45,4.26]],"batl":[[0,1.57,616.98],[1,1.58,482.18],[2,1.59,1090.27]],"ltp":1.52,"tv":11908.0,"id":5300820},{"batl":[[1,2.98,641.78],[2,3,622.9]],"ltp":2.98,"tv":4405.31,"id":9629022}],"tv":16313.32}]}
{"op":"mcm","clk":"4214980703","pt":1631533239357,"mc":[{"id":"1.187557985","rc":[{"batb":[[2,1.5,10.6]],"batl":[[2,1.59,1097.77]],"ltp":1.52,"tv":11908.0,"id":5300820},{"batl":[[2,3,628.2]],"ltp":2.98,"tv":4405.31,"id":9629022}]}]}
{"op":"mcm","clk":"4214980807","pt":1631533240660,"mc":[{"id":"1.187557985","rc":[{"batl":[[0,2.92,3],[1,2.94,7.75],[2,2.96,3]],"ltp":2.98,"tv":4405.31,"id":9629022}]}]}
{"op":"mcm","clk":"4214980832","pt":1631533240971,"mc":[{"id":"1.187557985","rc":[{"batl":[[0,1.57,571.48]],"ltp":1.52,"tv":11908.0,"id":5300820},{"batb":[[1,2.74,236.45]],"ltp":2.98,"tv":4405.31,"id":9629022}]}]}
{"op":"mcm","clk":"4214980954","pt":1631533242582,"mc":[{"id":"1.187557985","rc":[{"batl":[[0,1.57,659.98]],"ltp":1.52,"tv":11908.0,"id":5300820},{"batl":[[0,2.9,20.65],[1,2.92,3],[2,2.94,7.75]],"ltp":2.98,"tv":4405.31,"id":9629022}]}]}
{"op":"mcm","clk":"4214980961","pt":1631533242684,"mc":[{"id":"1.187557985","rc":[{"batb":[[2,1.46,7]],"batl":[[0,1.57,571.48]],"ltp":1.52,"tv":11908.0,"id":5300820},{"batl":[[0,2.92,3],[1,2.94,7.75],[2,2.96,3]],"ltp":2.98,"tv":4405.31,"id":9629022}]}]}
{"op":"mcm","clk":"4214981066","pt":1631533243980,"mc":[{"id":"1.187557985","rc":[{"batb":[[0,1.53,37.25],[1,1.52,341.56],[2,1.51,339.51]],"ltp":1.52,"tv":11908.0,"id":5300820}]}]}
{"op":"mcm","clk":"4214981215","pt":1631533245911,"mc":[{"id":"1.187557985","rc":[{"batb":[[2,1.51,350.01]],"ltp":1.52,"tv":11908.0,"id":5300820},{"batl":[[2,2.96,8.35]],"ltp":2.98,"tv":4405.31,"id":9629022}]}]}
{"op":"mcm","clk":"4214981710","pt":1631533252506,"mc":[{"id":"1.187557985","rc":[{"batb":[[0,1.51,10.5],[1,1.46,57.38],[2,1.45,10.26]],"batl":[[0,1.57,16.36],[1,1.59,7.5],[2,1.64,39.68]],"ltp":1.52,"tv":11908.0,"id":5300820},{"batb":[[0,2.7,17.64],[1,2.56,5.58],[2,2.54,62.84]],"batl":[[0,2.96,5.35],[1,3.2,3.38],[2,3.3,3.85]],"ltp":2.98,"tv":4405.31,"id":9629022}]}]}
{"op":"mcm","clk":"4214981782","pt":1631533253393,"mc":[{"id":"1.187557985","rc":[{"batb":[[0,1.46,57.38],[1,1.45,10.26],[2,1.44,56.67]],"batl":[[1,1.64,39.68],[2,1.64,0]],"ltp":1.52,"tv":11908.0,"id":5300820},{"batb":[[0,2.56,5.58],[1,2.54,62.84],[2,1.8,11.88]],"batl":[[0,3.2,3.38],[1,3.3,3.85],[2,3.45,56.66]],"ltp":2.98,"tv":4405.31,"id":9629022}]}]}
{"op":"mcm","clk":"4214981862","pt":1631533254424,"mc":[{"id":"1.187557985","rc":[{"batb":[[0,1.45,10.26],[1,1.43,194.39],[2,1.41,60.89]],"ltp":1.52,"tv":11908.0,"id":5300820},{"batl":[[0,3.45,56.66],[1,3.5,3.45],[2,3.75,3.18]],"ltp":2.98,"tv":4405.31,"id":9629022}]}]}
{"op":"mcm","clk":"4214981953","pt":1631533255520,"mc":[{"id":"1.187557985","rc":[{"batb":[[1,1.44,324.78],[2,1.43,426.05]],"batl":[[2,1.65,184.74]],"ltp":1.52,"tv":11908.0,"id":5300820}]}]}
{"op":"mcm","clk":"4214982015","pt":1631533256496,"mc":[{"id":"1.187557985","rc":[{"batl":[[0,2.76,77.08],[1,3.45,56.66],[2,3.5,3.45]],"ltp":2.98,"tv":4405.31,"id":9629022}]}]}
{"op":"mcm","clk":"4214982044","pt":1631533256911,"mc":[{"id":"1.187557985","rc":[{"batb":[[0,1.46,54.88],[1,1.45,10.26],[2,1.44,330.78]],"ltp":1.52,"tv":11908.0,"id":5300820},{"batl":[[1,3.2,4.03],[2,3.25,3]],"ltp":2.98,"tv":4405.31,"id":9629022}]}]}
{"op":"mcm","clk":"4214982221","pt":1631533259510,"mc":[{"id":"1.187557985","rc":[{"batl":[[2,1.65,0]],"ltp":1.52,"tv":11908.0,"id":5300820}]}]}
{"op":"mcm","clk":"4214982450","pt":1631533262590,"mc":[{"id":"1.187557985","rc":[{"trd":[[1.46,41.78],[1.56,988.16]],"batb":[[0,1.45,4.26],[1,1.44,330.78],[2,1.43,426.05]],"batl":[[0,1.48,212.15],[1,1.49,191.66],[2,1.57,16.36]],"ltp":1.46,"tv":12072.15,"id":5300820},{"trd":[[2.76,77.08]],"batb":[[0,3.05,627.06],[1,3,608.6],[2,2.98,608.6]],"batl":[[0,3.4,309.37],[1,3.45,602.62],[2,3.5,549.41]],"ltp":2.76,"tv":4482.39,"id":9629022}],"tv":16554.55}]}
{"op":"mcm","clk":"4214982518","pt":1631533263525,"mc":[{"id":"1.187557985","rc":[{"batb":[[0,1.45,15.44]],"batl":[[2,1.53,7.5]],"ltp":1.46,"tv":12072.15,"id":5300820},{"batb":[[1,3,707.76]],"ltp":2.76,"tv":4482.39,"id":9629022}]}]}
{"op":"mcm","clk":"4214982598","pt":1631533264620,"mc":[{"id":"1.187557985","rc":[{"batl":[[2,1.57,16.36]],"ltp":1.46,"tv":12072.15,"id":5300820},{"trd":[[3.05,12.5]],"batb":[[0,3.05,622.16]],"ltp":3.05,"tv":4492.18,"id":9629022}],"tv":16564.34}]}
{"op":"mcm","clk":"4214982679","pt":1631533265618,"mc":[{"id":"1.187557985","rc":[{"batb":[[0,1.45,36.74]],"batl":[[2,1.56,81.8]],"ltp":1.46,"tv":12072.15,"id":5300820},{"batl":[[0,3.3,4.94],[1,3.4,309.37],[2,3.45,602.62]],"ltp":3.05,"tv":4492.18,"id":9629022}]}]}
{"op":"mcm","clk":"4214983004","pt":1631533269531,"mc":[{"id":"1.187557985","rc":[{"batl":[[2,1.52,40.26]],"ltp":1.46,"tv":12072.15,"id":5300820},{"batl":[[0,3.25,30.73],[1,3.3,4.94],[2,3.4,309.37]],"ltp":3.05,"tv":4492.18,"id":9629022}]}]}
{"op":"mcm","clk":"4214983097","pt":1631533270618,"mc":[{"id":"1.187557985","rc":[{"batl":[[2,1.51,7.5]],"ltp":1.46,"tv":12072.15,"id":5300820}]}]}
{"op":"mcm","clk":"4214983182","pt":1631533271612,"mc":[{"id":"1.187557985","rc":[{"batl":[[0,1.46,10],[1,1.48,212.15],[2,1.49,191.66]],"ltp":1.46,"tv":12072.15,"id":5300820}]}]}
{"op":"mcm","clk":"4214983275","pt":1631533272544,"mc":[{"id":"1.187557985","rc":[{"trd":[[1.45,33.25]],"batb":[[0,1.45,34.57]],"batl":[[0,1.46,10.72]],"ltp":1.45,"tv":12076.5,"id":5300820}],"tv":16568.69}]}
{"op":"mcm","clk":"4214983348","pt":1631533273524,"mc":[{"id":"1.187557985","rc":[{"trd":[[1.45,36.15]],"batb":[[0,1.45,33.12]],"ltp":1.45,"tv":12079.39,"id":5300820}],"tv":16571.58}]}
{"op":"mcm","clk":"4214983426","pt":1631533274611,"mc":[{"id":"1.187557985","rc":[{"trd":[[1.45,41.93]],"batb":[[0,1.45,30.23]],"batl":[[1,1.48,196.55]],"ltp":1.45,"tv":12085.17,"id":5300820}],"tv":16577.36}]}
{"op":"mcm","clk":"4214983500","pt":1631533275550,"mc":[{"id":"1.187557985","rc":[{"trd":[[1.45,43.37]],"batb":[[0,1.45,21.3]],"batl":[[0,1.46,10]],"ltp":1.45,"tv":12086.62,"id":5300820}],"tv":16578.8}]}
{"op":"mcm","clk":"4214983639","pt":1631533277112,"mc":[{"id":"1.187557985","rc":[{"batb":[[0,1.44,6],[1,1.43,33.63],[2,1.38,307.73]],"batl":[[1,1.51,7.5],[2,1.52,40.26]],"ltp":1.45,"tv":12086.62,"id":5300820},{"batb":[[0,2.96,15.3],[1,2.92,4.19],[2,2.8,5.03]],"batl":[[0,3.3,4.94],[1,3.45,53.16],[2,3.65,112.18]],"ltp":3.05,"tv":4492.18,"id":9629022}]}]}
{"op":"mcm","clk":"4214983766","pt":1631533278617,"mc":[{"id":"1.187557985","rc":[{"batb":[[0,1.38,307.73],[1,1.37,515.55],[2,1.36,754.02]],"batl":[[0,1.46,10.72],[1,1.52,40.26],[2,1.55,42.7]],"ltp":1.45,"tv":12086.62,"id":5300820},{"batb":[[0,2.92,4.19],[1,2.8,5.03],[2,2.78,199.3]],"batl":[[0,3.45,53.16],[1,3.65,112.18],[2,3.7,165.84]],"ltp":3.05,"tv":4492.18,"id":9629022}]}]}
{"op":"mcm","clk":"4214983899","pt":1631533280439,"mc":[{"id":"1.187557985","rc":[{"batb":[[1,1.37,711.21],[2,1.36,1045.57]],"batl":[[0,1.46,10]],"ltp":1.45,"tv":12086.62,"id":5300820}]}]}
{"op":"mcm","clk":"4214984072","pt":1631533282521,"mc":[{"id":"1.187557985","rc":[{"batb":[[0,1.4,8],[1,1.39,8],[2,1.38,307.73]],"batl":[[0,1.55,42.7],[1,1.56,535.62],[2,1.57,475.38]],"ltp":1.45,"tv":12086.62,"id":5300820},{"batb":[[0,2.8,5.03],[1,2.78,199.3],[2,2.76,206.93]],"ltp":3.05,"tv":4492.18,"id":9629022}]}]}
{"op":"mcm","clk":"4214984276","pt":1631533285222,"mc":[{"id":"1.187557985","rc":[{"batl":[[1,1.57,16.36],[2,1.57,0]],"ltp":1.45,"tv":12086.62,"id":5300820},{"batb":[[1,2.78,49.79],[2,1.8,11.88]],"ltp":3.05,"tv":4492.18,"id":9629022}]}]}
{"op":"mcm","clk":"4214984530","pt":1631533288344,"mc":[{"id":"1.187557985","rc":[{"trd":[[1.38,12.98],[1.39,16],[1.4,147]],"batb":[[0,1.37,711.21],[1,1.36,1045.57],[2,1.33,75.53]],"batl":[[0,1.4,259.97],[1,1.41,242.11],[2,1.55,42.7]],"ltp":1.38,"tv":12262.6,"id":5300820},{"trd":[[3.45,53.16]],"batb":[[0,3.45,554.34],[1,3.4,538.04],[2,3.35,538.04]],"batl":[[0,3.7,165.84],[1,3.75,190.68],[2,3.9,490.4]],"ltp":3.45,"tv":4545.34,"id":9629022}],"tv":16807.94}]}
{"op":"mcm","clk":"4214984620","pt":1631533289449,"mc":[{"id":"1.187557985","rc":[{"batb":[[0,1.37,760.52]],"batl":[[2,1.45,7.5]],"ltp":1.38,"tv":12262.6,"id":5300820},{"batb":[[1,3.4,611.34]],"batl":[[0,3.7,170.4]],"ltp":3.45,"tv":4545.34,"id":9629022}]}]}
{"op":"mcm","clk":"4214984795","pt":1631533291564,"mc":[{"id":"1.187557985","rc":[{"trd":[[1.4,207.7]],"batb":[[0,1.37,800.56]],"batl":[[0,1.4,229.62]],"ltp":1.4,"tv":12323.3,"id":5300820},{"batl":[[0,3.7,184.96]],"ltp":3.45,"tv":4545.34,"id":9629022}],"tv":16868.64}]}
{"op":"mcm","clk":"4214984929","pt":1631533293131,"mc":[{"id":"1.187557985","rc":[{"batl":[[2,1.49,158.18]],"ltp":1.4,"tv":12323.3,"id":5300820}]}]}
{"op":"mcm","clk":"4214985073","pt":1631533295262,"mc":[{"id":"1.187557985","rc":[{"batl":[[2,1.43,66.5]],"ltp":1.4,"tv":12323.3,"id":5300820}]}]}
{"op":"mcm","clk":"4214985349","pt":1631533298659,"mc":[{"id":"1.187557985","rc":[{"trd":[[1.37,30]],"batb":[[0,1.37,785.56]],"batl":[[0,1.4,321.62]],"ltp":1.37,"tv":12353.3,"id":5300820}],"tv":16898.64}]}
{"op":"mcm","clk":"4214985702","pt":1631533302582,"mc":[{"id":"1.187557985","rc":[{"batb":[[0,1.37,302.91],[1,1.36,536.4]],"ltp":1.37,"tv":12353.3,"id":5300820},{"batb":[[0,3.4,73.3],[1,3.3,3.28],[2,3.25,13.33]],"batl":[[0,3.7,4.56],[1,3.75,3.18],[2,4.1,129.36]],"ltp":3.45,"tv":4545.34,"id":9629022}]}]}
{"op":"mcm","clk":"4214985793","pt":1631533303633,"mc":[{"id":"1.187557985","rc":[{"batb":[[0,1.37,51.48],[1,1.32,442.12],[2,1.31,727.22]],"batl":[[0,1.43,66.5],[1,1.46,339.75],[2,1.47,301.8]],"ltp":1.37,"tv":12353.3,"id":5300820},{"batb":[[0,3.3,3.28],[1,3.25,13.33],[2,3.15,174.23]],"batl":[[1,4.1,126.81],[2,4.2,134.07]],"ltp":3.45,"tv":4545.34,"id":9629022}]}]}
{"op":"mcm","clk":"4214985868","pt":1631533304461,"mc":[{"id":"1.187557985","rc":[{"batb":[[0,1.37,2.17]],"batl":[[0,1.46,339.75],[1,1.47,301.8],[2,1.48,365.34]],"ltp":1.37,"tv":12353.3,"id":5300820},{"batb":[[0,3.15,174.23],[1,3.1,288.15],[2,3.05,198.26]],"batl":[[0,4.1,126.81],[1,4.2,134.07],[2,4.3,158.82]],"ltp":3.45,"tv":4545.34,"id":9629022}]}]}
{"op":"mcm","clk":"4214986020","pt":1631533306336,"mc":[{"id":"1.187557985","rc":[{"batb":[[2,1.31,1125.64]],"batl":[[0,1.46,629.6],[1,1.47,503.63]],"ltp":1.37,"tv":12353.3,"id":5300820}]}]}
{"op":"mcm","clk":"4214986117","pt":1631533307640,"mc":[{"id":"1.187557985","rc":[{"batl":[[0,1.44,16.36],[1,1.46,631.6],[2,1.47,503.63]],"ltp":1.37,"tv":12353.3,"id":5300820},{"batb":[[0,3.15,177.23],[1,3.1,291.15]],"batl":[[0,4.1,128.81]],"ltp":3.45,"tv":4545.34,"id":9629022}]}]}
{"op":"mcm","clk":"4214986179","pt":1631533308267,"mc":[{"id":"1.187557985","rc":[{"batb":[[2,1.31,727.22]],"batl":[[1,1.46,341.75],[2,1.47,301.8]],"ltp":1.37,"tv":12353.3,"id":5300820}]}]}
{"op":"mcm","clk":"4214986374","pt":1631533310461,"mc":[{"id":"1.187557985","rc":[{"batl":[[0,1.4,19.34],[1,1.43,58.5],[2,1.44,16.36]],"ltp":1.37,"tv":12353.3,"id":5300820},{"batb":[[0,3.55,18.79],[1,3.3,3.78],[2,3.15,177.23]],"batl":[[0,3.7,21.25],[1,4.1,128.81],[2,4.2,134.07]],"ltp":3.45,"tv":4545.34,"id":9629022}]}]}
{"op":"mcm","clk":"4214986397","pt":1631533310775,"mc":[{"id":"1.187557985","rc":[{"batb":[[1,1.36,181.12],[2,1.35,301.99]],"batl":[[0,1.39,297.65],[1,1.4,249.43]],"ltp":1.37,"tv":12353.3,"id":5300820},{"batb":[[0,3.15,177.23],[1,3.1,291.15],[2,3.05,198.26]],"batl":[[0,4.1,128.81],[1,4.2,134.07],[2,4.3,158.82]],"ltp":3.45,"tv":4545.34,"id":9629022}]}]}
{"op":"mcm","clk":"4214986706","pt":1631533314476,"mc":[{"id":"1.187557985","rc":[{"batb":[[1,1.32,442.12],[2,1.31,727.22]],"batl":[[0,1.44,16.36],[1,1.46,341.75],[2,1.47,301.8]],"ltp":1.37,"tv":12353.3,"id":5300820}]}]}
{"op":"mcm","clk":"4214986978","pt":1631533317653,"mc":[{"id":"1.187557985","rc":[{"batb":[[2,1.31,1125.64]],"batl":[[0,1.43,59.5],[1,1.44,16.36],[2,1.46,631.6]],"ltp":1.37,"tv":12353.3,"id":5300820},{"batb":[[0,3.3,3.68],[1,3.15,177.23],[2,3.1,291.15]],"ltp":3.45,"tv":4545.34,"id":9629022}]}]}
{"op":"mcm","clk":"4214987009","pt":1631533317964,"mc":[{"id":"1.187557985","rc":[{"batl":[[0,1.44,16.36],[1,1.46,631.6],[2,1.47,503.63]],"ltp":1.37,"tv":12353.3,"id":5300820},{"batb":[[0,3.15,177.23],[1,3.1,291.15],[2,3.05,198.26]],"ltp":3.45,"tv":4545.34,"id":9629022}]}]}
{"op":"mcm","clk":"4214987075","pt":1631533318786,"mc":[{"id":"1.187557985","rc":[{"batl":[[0,1.43,7.23],[1,1.44,16.36],[2,1.46,631.6]],"ltp":1.37,"tv":12353.3,"id":5300820}]}]}
{"op":"mcm","clk":"4214987213","pt":1631533320199,"mc":[{"id":"1.187557985","rc":[{"batl":[[0,1.44,16.36],[1,1.46,631.6],[2,1.47,503.63]],"ltp":1.37,"tv":12353.3,"id":5300820},{"batb":[[1,3.1,288.15]],"ltp":3.45,"tv":4545.34,"id":9629022}]}]}
{"op":"mcm","clk":"4214987308","pt":1631533321201,"mc":[{"id":"1.187557985","rc":[{"batl":[[0,1.43,63.5],[1,1.44,16.36],[2,1.46,631.6]],"ltp":1.37,"tv":12353.3,"id":5300820},{"batb":[[0,3.3,3.88],[1,3.15,177.23],[2,3.1,288.15]],"ltp":3.45,"tv":4545.34,"id":9629022}]}]}
{"op":"mcm","clk":"4214987364","pt":1631533321777,"mc":[{"id":"1.187557985","rc":[{"batl":[[0,1.44,16.36],[1,1.46,631.6],[2,1.47,503.63]],"ltp":1.37,"tv":12353.3,"id":5300820},{"batb":[[0,3.15,177.23],[1,3.1,288.15],[2,3.05,198.26]],"ltp":3.45,"tv":4545.34,"id":9629022}]}]}
{"op":"mcm","clk":"4214987910","pt":1631533328392,"mc":[{"id":"1.187557985","rc":[{"batl":[[0,1.43,65.5],[1,1.44,16.36],[2,1.46,631.6]],"ltp":1.37,"tv":12353.3,"id":5300820},{"batb":[[0,3.3,3.58],[1,3.15,177.23],[2,3.1,288.15]],"ltp":3.45,"tv":4545.34,"id":9629022}]}]}
{"op":"mcm","clk":"4214987939","pt":1631533328701,"mc":[{"id":"1.187557985","rc":[{"batl":[[0,1.44,16.36],[1,1.46,631.6],[2,1.47,503.63]],"ltp":1.37,"tv":12353.3,"id":5300820},{"batb":[[0,3.15,177.23],[1,3.1,288.15],[2,3.05,198.26]],"ltp":3.45,"tv":4545.34,"id":9629022}]}]}
{"op":"mcm","clk":"4214988637","pt":1631533337104,"mc":[{"id":"1.187557985","rc":[{"batl":[[1,1.46,63.25],[2,44,7.23]],"ltp":1.37,"tv":12353.3,"id":5300820},{"batb":[[0,3.15,7.03],[1,3.1,90.96],[2,2,11.88]],"ltp":3.45,"tv":4545.34,"id":9629022}]}]}
{"op":"mcm","clk":"4214988838","pt":1631533339603,"mc":[{"id":"1.187557985","rc":[{"trd":[[1.37,34.34]],"batb":[[0,1.32,442.12],[1,1.31,1125.64],[2,1.3,954.77]],"ltp":1.37,"tv":12357.64,"id":5300820},{"batl":[[0,4.2,134.07],[1,4.3,158.82],[2,4.5,2.51]],"ltp":3.45,"tv":4545.34,"id":9629022}],"tv":16902.98}]}
{"op":"mcm","clk":"4214988903","pt":1631533340389,"mc":[{"id":"1.187557985","rc":[{"batl":[[0,1.34,251.73],[1,1.35,296.99],[2,1.44,16.36]],"ltp":1.37,"tv":12357.64,"id":5300820},{"batb":[[0,3.9,490.4],[1,3.85,475.96],[2,3.8,475.96]],"ltp":3.45,"tv":4545.34,"id":9629022}]}]}
{"op":"mcm","clk":"4214988983","pt":1631533341426,"mc":[{"id":"1.187557985","rc":[{"batb":[[0,1.32,495.15]],"batl":[[2,1.4,7.5]],"ltp":1.37,"tv":12357.64,"id":5300820},{"batb":[[2,3.8,531.69]],"batl":[[0,4.1,4.25],[1,4.2,134.07],[2,4.3,158.82]],"ltp":3.45,"tv":4545.34,"id":9629022}]}]}
{"op":"mcm","clk":"4214989034","pt":1631533341899,"mc":[{"id":"1.187557985","rc":[{"batl":[[2,1.42,81.8]],"ltp":1.37,"tv":12357.64,"id":5300820}]}]}
{"op":"mcm","clk":"4214989157","pt":1631533343405,"mc":[{"id":"1.187557985","rc":[{"batl":[[1,4.2,148.55]],"ltp":3.45,"tv":4545.34,"id":9629022}]}]}
{"op":"mcm","clk":"4214989222","pt":1631533344183,"mc":[{"id":"1.187557985","rc":[{"batl":[[0,1.34,678.72]],"ltp":1.37,"tv":12357.64,"id":5300820},{"batb":[[0,3.9,645.8]],"ltp":3.45,"tv":4545.34,"id":9629022}]}]}
{"op":"mcm","clk":"4214989351","pt":1631533345599,"mc":[{"id":"1.187557985","rc":[{"batl":[[0,1.34,761.72]],"ltp":1.37,"tv":12357.64,"id":5300820}]}]}
{"op":"mcm","clk":"4214989461","pt":1631533346897,"mc":[{"id":"1.187557985","rc":[{"batb":[[1,1.31,1154.7]],"batl":[[2,1.41,303.63]],"ltp":1.37,"tv":12357.64,"id":5300820}]}]}
{"op":"mcm","clk":"4214989702","pt":1631533349596,"mc":[{"id":"1.187557985","rc":[{"batl":[[2,1.38,7.5]],"ltp":1.37,"tv":12357.64,"id":5300820}]}]}
{"op":"mcm","clk":"4214989734","pt":1631533350013,"mc":[{"id":"1.187557985","rc":[{"trd":[[1.34,33.44]],"batl":[[0,1.34,745]],"ltp":1.34,"tv":12391.08,"id":5300820}],"tv":16936.42}]}
{"op":"mcm","clk":"4214990076","pt":1631533353895,"mc":[{"id":"1.187557985","rc":[{"trd":[[1.32,68.72]],"batb":[[0,1.32,460.79]],"ltp":1.32,"tv":12459.8,"id":5300820}],"tv":17005.15}]}
{"op":"mcm","clk":"4214990175","pt":1631533355041,"mc":[{"id":"1.187557985","rc":[{"trd":[[1.32,93.72]],"batb":[[0,1.32,448.29]],"ltp":1.32,"tv":12484.8,"id":5300820}],"tv":17030.15}]}
{"op":"mcm","clk":"4214991160","pt":1631533365209,"mc":[{"id":"1.187557985","rc":[{"batb":[[0,1.32,463.29]],"ltp":1.32,"tv":12484.8,"id":5300820}]}]}
{"op":"mcm","clk":"4214992894","pt":1631533384426,"mc":[{"id":"1.187557985","rc":[{"batb":[[0,1.32,448.29]],"ltp":1.32,"tv":12484.8,"id":5300820}]}]}
{"op":"mcm","clk":"4214993149","pt":1631533387543,"mc":[{"id":"1.187557985","rc":[{"trd":[[1.32,93.88],[1.34,63.44]],"batb":[[0,1.32,448.21]],"batl":[[0,1.34,730]],"ltp":1.34,"tv":12514.96,"id":5300820}],"tv":17060.31}]}
{"op":"mcm","clk":"4214995675","pt":1631533417479,"mc":[{"id":"1.187557985","rc":[{"trd":[[1.32,94.04]],"batb":[[0,1.32,448.13]],"ltp":1.32,"tv":12515.12,"id":5300820}],"tv":17060.47}]}
{"op":"mcm","clk":"4214996465","pt":1631533425600,"mc":[{"id":"1.187557985","rc":[{"trd":[[1.32,494.05],[1.34,67.74]],"batb":[[0,1.32,248.13]],"batl":[[0,1.34,727.85]],"ltp":1.32,"tv":12919.42,"id":5300820}],"tv":17464.77}]}
{"op":"mcm","clk":"4214996876","pt":1631533430125,"mc":[{"id":"1.187557985","rc":[{"batl":[[2,1.38,75]],"ltp":1.32,"tv":12919.42,"id":5300820}]}]}
{"op":"mcm","clk":"4214997398","pt":1631533436447,"mc":[{"id":"1.187557985","rc":[{"batl":[[1,4.2,134.07]],"ltp":3.45,"tv":4545.34,"id":9629022}]}]}
{"op":"mcm","clk":"4215001118","pt":1631533483200,"mc":[{"id":"1.187557985","rc":[{"batb":[[0,1.32,53.03],[1,1.29,464.8],[2,1.28,523.22]],"batl":[[0,1.34,83],[1,1.38,75],[2,1.41,367.85]],"ltp":1.32,"tv":12919.42,"id":5300820},{"batb":[[0,3.65,11.32],[1,3.6,10.88],[2,3.45,147.18]],"batl":[[1,4.5,125.87],[2,4.6,144.45]],"ltp":3.45,"tv":4545.34,"id":9629022}]}]}
{"op":"mcm","clk":"4215001197","pt":1631533484396,"mc":[{"id":"1.187557985","rc":[{"batb":[[0,1.29,464.8],[1,1.28,523.22],[2,1.27,1039.85]],"batl":[[0,1.41,367.85],[1,1.42,321.63],[2,1.43,470.75]],"ltp":1.32,"tv":12919.42,"id":5300820},{"batb":[[0,3.45,147.18],[1,3.4,224.22],[2,3.35,217.69]],"batl":[[0,4.5,125.87],[1,4.6,144.45],[2,4.7,156.98]],"ltp":3.45,"tv":4545.34,"id":9629022}]}]}
{"op":"mcm","clk":"4215001431","pt":1631533487634,"mc":[{"id":"1.187557985","rc":[{"batb":[[0,1.29,472.8],[1,1.28,531.22]],"batl":[[0,1.38,6],[1,1.39,9],[2,1.41,373.85]],"ltp":1.32,"tv":12919.42,"id":5300820},{"batb":[[0,3.6,2],[1,3.55,3],[2,3.45,149.18]],"batl":[[0,4.5,127.87]],"ltp":3.45,"tv":4545.34,"id":9629022}]}]}
{"op":"mcm","clk":"4215001579","pt":1631533489578,"mc":[{"id":"1.187557985","rc":[{"batl":[[2,1.4,7]],"ltp":1.32,"tv":12919.42,"id":5300820},{"batb":[[2,3.5,3]],"ltp":3.45,"tv":4545.34,"id":9629022}]}]}
{"op":"mcm","clk":"4215001648","pt":1631533490457,"mc":[{"id":"1.187557985","rc":[{"batb":[[0,1.32,449.86],[1,1.31,356.43],[2,1.29,472.8]],"batl":[[0,1.35,156.36],[1,1.36,287.14],[2,1.38,12.75]],"ltp":1.32,"tv":12919.42,"id":5300820},{"batb":[[0,3.6,8.69]],"ltp":3.45,"tv":4545.34,"id":9629022}]}]}
{"op":"mcm","clk":"4215001704","pt":1631533491131,"mc":[{"id":"1.187557985","rc":[{"batl":[[2,1.38,84]],"ltp":1.32,"tv":12919.42,"id":5300820},{"batb":[[0,3.6,11.98]],"ltp":3.45,"tv":4545.34,"id":9629022}]}]}
{"op":"mcm","clk":"4215001857","pt":1631533493478,"mc":[{"id":"1.187557985","rc":[{"batb":[[0,1.29,472.8],[1,1.28,531.22],[2,1.27,1039.85]],"batl":[[0,1.38,6],[1,1.39,9],[2,1.4,262.54]],"ltp":1.32,"tv":12919.42,"id":5300820},{"batb":[[0,3.6,2]],"ltp":3.45,"tv":4545.34,"id":9629022}]}]}
{"op":"mcm","clk":"4215002036","pt":1631533496238,"mc":[{"id":"1.187557985","rc":[{"batb":[[1,1.28,768.5],[2,1.27,1459.16]],"batl":[[2,1.4,490.36]],"ltp":1.32,"tv":12919.42,"id":5300820}]}]}
{"op":"mcm","clk":"4215002348","pt":1631533500544,"mc":[{"id":"1.187557985","rc":[{"batb":[[1,1.28,760.5]],"batl":[[0,1.4,490.36],[1,1.41,610.22],[2,1.42,321.63]],"ltp":1.32,"tv":12919.42,"id":5300820},{"batb":[[1,3.5,3],[2,3.45,147.18]],"ltp":3.45,"tv":4545.34,"id":9629022}]}]}
{"op":"mcm","clk":"4215002504","pt":1631533502596,"mc":[{"id":"1.187557985","rc":[{"batb":[[0,1.29,95.81],[1,1.27,444.31],[2,1.23,255.54]],"ltp":1.32,"tv":12919.42,"id":5300820},{"batl":[[0,4.5,4.51],[1,4.8,2.32],[2,4.7,0]],"ltp":3.45,"tv":4545.34,"id":9629022}]}]}
{"op":"mcm","clk":"4215002525","pt":1631533502858,"mc":[{"id":"1.187557985","rc":[{"batb":[[0,1.29,8]],"ltp":1.32,"tv":12919.42,"id":5300820},{"batb":[[1,3.45,147.18],[2,3.4,224.22]],"batl":[[0,4.5,2]],"ltp":3.45,"tv":4545.34,"id":9629022}]}]}
{"op":"mcm","clk":"4215002696","pt":1631533504651,"mc":[{"id":"1.187557985","rc":[{"batb":[[0,1.37,13.14],[1,1.29,8],[2,1.28,10]],"batl":[[0,1.39,7],[1,1.4,490.36],[2,1.41,610.22]],"ltp":1.32,"tv":12919.42,"id":5300820},{"batb":[[1,3.55,2],[2,3.45,147.18]],"ltp":3.45,"tv":4545.34,"id":9629022}]}]}
{"op":"mcm","clk":"4215002793","pt":1631533505589,"mc":[{"id":"1.187557985","rc":[{"batb":[[0,1.37,226.8],[1,1.36,3104.39],[2,1.35,2729.78]],"batl":[[0,1.4,483.36],[1,1.41,610.22],[2,1.42,321.63]],"ltp":1.32,"tv":12919.42,"id":5300820},{"batb":[[0,3.45,147.18],[1,3.4,224.22],[2,3.35,1359.47]],"batl":[[0,4.3,4.65],[1,4.5,2],[2,4.8,2.32]],"ltp":3.45,"tv":4545.34,"id":9629022}]}]}
{"op":"mcm","clk":"4215002876","pt":1631533506584,"mc":[{"id":"1.187557985","rc":[{"batb":[[1,1.36,1945.18],[2,1.35,1364.88]],"batl":[[0,1.38,14.49],[1,1.4,483.36],[2,1.41,610.22]],"ltp":1.32,"tv":12919.42,"id":5300820},{"batb":[[2,3.35,531.68]],"ltp":3.45,"tv":4545.34,"id":9629022}]}]}
{"op":"mcm","clk":"4215002947","pt":1631533507577,"mc":[{"id":"1.187557985","rc":[{"batb":[[1,1.36,1995.18]],"ltp":1.32,"tv":12919.42,"id":5300820},{"batl":[[0,3.8,4.48],[1,4.2,10],[2,4.3,4.65]],"ltp":3.45,"tv":4545.34,"id":9629022}]}]}
{"op":"mcm","clk":"4215003035","pt":1631533508564,"mc":[{"id":"1.187557985","rc":[{"batb":[[0,1.37,233.8],[1,1.36,2001.18]],"ltp":1.32,"tv":12919.42,"id":5300820},{"batl":[[0,3.75,2],[1,3.8,4.48],[2,4.2,2]],"ltp":3.45,"tv":4545.34,"id":9629022}]}]}
{"op":"mcm","clk":"4215003101","pt":1631533509400,"mc":[{"id":"1.187557985","rc":[{"batl":[[0,3.7,2],[1,3.75,2],[2,3.8,4.48]],"ltp":3.45,"tv":4545.34,"id":9629022}]}]}
{"op":"mcm","clk":"4215003202","pt":1631533510602,"mc":[{"id":"1.187557985","rc":[{"batb":[[1,1.36,1951.18]],"ltp":1.32,"tv":12919.42,"id":5300820},{"batl":[[2,4.2,2]],"ltp":3.45,"tv":4545.34,"id":9629022}]}]}
{"op":"mcm","clk":"4215003279","pt":1631533511584,"mc":[{"id":"1.187557985","rc":[{"batb":[[0,1.37,279.94]],"ltp":1.32,"tv":12919.42,"id":5300820}]}]}
{"op":"mcm","clk":"4215003362","pt":1631533512573,"mc":[{"id":"1.187557985","rc":[{"batl":[[2,4,135.63]],"ltp":3.45,"tv":4545.34,"id":9629022}]}]}
{"op":"mcm","clk":"4215003396","pt":1631533513101,"mc":[{"id":"1.187557985","rc":[{"batb":[[0,1.37,329.25]],"ltp":1.32,"tv":12919.42,"id":5300820}]}]}
{"op":"mcm","clk":"4215003484","pt":1631533514391,"mc":[{"id":"1.187557985","rc":[{"batl":[[0,3.7,16.56]],"ltp":3.45,"tv":4545.34,"id":9629022}]}]}
{"op":"mcm","clk":"4215003895","pt":1631533519614,"mc":[{"id":"1.187557985","rc":[{"batb":[[0,1.37,49.31],[1,1.33,377.11],[2,1.32,741.28]],"batl":[[0,1.4,255.54],[1,1.41,6.72],[2,1.43,7.5]],"ltp":1.32,"tv":12919.42,"id":5300820},{"batb":[[0,3.4,8.41],[1,3.3,13.04],[2,3.25,7.21]],"batl":[[0,3.7,4.56],[1,4,135.63],[2,4.1,118.82]],"ltp":3.45,"tv":4545.34,"id":9629022}]}]}
{"op":"mcm","clk":"4215003971","pt":1631533520613,"mc":[{"id":"1.187557985","rc":[{"batb":[[0,1.33,377.11],[1,1.32,741.28],[2,1.31,416.54]],"batl":[[2,1.44,77.19]],"ltp":1.32,"tv":12919.42,"id":5300820},{"batb":[[1,3.25,7.21],[2,3.1,135.76]],"batl":[[0,4,135.63],[1,4.1,118.82],[2,4.2,192.17]],"ltp":3.45,"tv":4545.34,"id":9629022}]}]}
{"op":"mcm","clk":"4215004129","pt":1631533522515,"mc":[{"id":"1.187557985","rc":[{"batb":[[1,1.32,1118],[2,1.31,771.85]],"ltp":1.32,"tv":12919.42,"id":5300820}]}]}
{"op":"mcm","clk":"4215004230","pt":1631533523613,"mc":[{"id":"1.187557985","rc":[{"batb":[[0,1.33,386.11],[1,1.32,1127]],"ltp":1.32,"tv":12919.42,"id":5300820}]}]}
{"op":"mcm","clk":"4215004279","pt":1631533524293,"mc":[{"id":"1.187557985","rc":[{"batl":[[0,1.44,16.36],[1,1.47,199.3],[2,1.48,720.97]],"ltp":1.32,"tv":12919.42,"id":5300820},{"batb":[[0,3.25,3],[1,3.1,135.76],[2,3.05,250.7]],"ltp":3.45,"tv":4545.34,"id":9629022}]}]}
{"op":"mcm","clk":"4215004565","pt":1631533527597,"mc":[{"id":"1.187557985","rc":[{"batl":[[0,1.44,77.69]],"ltp":1.32,"tv":12919.42,"id":5300820},{"batb":[[0,3.25,6.65],[1,3.2,3],[2,3.1,135.76]],"ltp":3.45,"tv":4545.34,"id":9629022}]}]}
{"op":"mcm","clk":"4215004620","pt":1631533528424,"mc":[{"id":"1.187557985","rc":[{"batb":[[0,1.33,9],[1,1.32,378.08],[2,1.3,255.54]],"batl":[[0,1.44,21.36]],"ltp":1.32,"tv":12919.42,"id":5300820},{"batb":[[0,3.25,3]],"batl":[[0,4.2,4.38],[1,4.5,2.55],[2,4.8,2.32]],"ltp":3.45,"tv":4545.34,"id":9629022}]}]}
{"op":"mcm","clk":"4215004772","pt":1631533530093,"mc":[{"id":"1.187557985","rc":[{"trd":[[1.44,29.28]],"batl":[[0,1.44,1.72]],"ltp":1.44,"tv":12948.7,"id":5300820},{"batb":[[0,3.1,135.76],[1,3.05,250.7],[2,3,226.84]],"ltp":3.45,"tv":4545.34,"id":9629022}],"tv":17494.05}]}
{"op":"mcm","clk":"4215004906","pt":1631533531414,"mc":[{"id":"1.187557985","rc":[{"trd":[[1.44,32.72]],"batb":[[0,1.44,164.73],[1,1.43,231.01],[2,1.34,1675]],"batl":[[0,1.47,199.3],[1,1.48,720.97],[2,1.49,315.43]],"ltp":1.44,"tv":12952.14,"id":5300820},{"batb":[[1,3.05,595.58],[2,3,561.57]],"batl":[[0,3.4,562.5],[1,3.45,545.96],[2,3.5,545.96]],"ltp":3.45,"tv":4545.34,"id":9629022}],"tv":17497.49}]}
{"op":"mcm","clk":"4215005000","pt":1631533532524,"mc":[{"id":"1.187557985","rc":[{"trd":[[1.44,60.7]],"batb":[[0,1.44,150.74],[1,1.43,429.75],[2,1.41,46.85]],"ltp":1.44,"tv":12980.12,"id":5300820},{"batl":[[0,3.4,567.34]],"ltp":3.45,"tv":4545.34,"id":9629022}],"tv":17525.47}]}
{"op":"mcm","clk":"4215005085","pt":1631533533516,"mc":[{"id":"1.187557985","rc":[{"batb":[[2,3,576.57]],"ltp":3.45,"tv":4545.34,"id":9629022}]}]}
{"op":"mcm","clk":"4215005195","pt":1631533534619,"mc":[{"id":"1.187557985","rc":[{"batb":[[0,1.44,158.74],[1,1.43,436.75]],"ltp":1.44,"tv":12980.12,"id":5300820},{"batl":[[0,3.35,3],[1,3.4,567.34],[2,3.45,545.96]],"ltp":3.45,"tv":4545.34,"id":9629022}]}]}
{"op":"mcm","clk":"4215005360","pt":1631533536644,"mc":[{"id":"1.187557985","rc":[{"batb":[[0,1.44,203.74],[2,1.42,255.54]],"ltp":1.44,"tv":12980.12,"id":5300820},{"batl":[[0,3.35,30.93],[1,3.4,562.5]],"ltp":3.45,"tv":4545.34,"id":9629022}]}]}
{"op":"mcm","clk":"4215005421","pt":1631533537431,"mc":[{"id":"1.187557985","rc":[{"batl":[[0,3.35,3]],"ltp":3.45,"tv":4545.34,"id":9629022}]}]}
{"op":"mcm","clk":"4215005513","pt":1631533538636,"mc":[{"id":"1.187557985","rc":[{"trd":[[1.47,449.13]],"batl":[[0,1.47,149.3]],"ltp":1.47,"tv":13080.12,"id":5300820}],"tv":17625.47}]}
{"op":"mcm","clk":"4215005586","pt":1631533539523,"mc":[{"id":"1.187557985","rc":[{"batl":[[0,3.3,3],[1,3.35,7.89],[2,3.4,562.5]],"ltp":3.45,"tv":4545.34,"id":9629022}]}]}
{"op":"mcm","clk":"4215005688","pt":1631533540624,"mc":[{"id":"1.187557985","rc":[{"batb":[[2,1.42,301.83]],"ltp":1.47,"tv":13080.12,"id":5300820}]}]}
{"op":"mcm","clk":"4215005844","pt":1631533542543,"mc":[{"id":"1.187557985","rc":[{"trd":[[1.44,65.28]],"batb":[[0,1.44,199.16]],"ltp":1.44,"tv":13084.7,"id":5300820},{"trd":[[3.3,8]],"batl":[[0,3.35,7.89],[1,3.4,562.5],[2,3.45,545.96]],"ltp":3.3,"tv":4553.34,"id":9629022}],"tv":17638.05}]}
{"op":"mcm","clk":"4215006134","pt":1631533546616,"mc":[{"id":"1.187557985","rc":[{"batl":[[0,1.47,201.3]],"ltp":1.44,"tv":13084.7,"id":5300820}]}]}
{"op":"mcm","clk":"4215006151","pt":1631533546833,"mc":[{"id":"1.187557985","rc":[{"batb":[[1,1.43,429.75]],"ltp":1.44,"tv":13084.7,"id":5300820},{"batl":[[0,3.3,27.93],[1,3.35,7.89],[2,3.4,562.5]],"ltp":3.3,"tv":4553.34,"id":9629022}]}]}
{"op":"mcm","clk":"4215006405","pt":1631533550037,"mc":[{"id":"1.187557985","rc":[{"batb":[[1,1.43,437.75]],"ltp":1.44,"tv":13084.7,"id":5300820}]}]}
{"op":"mcm","clk":"4215006546","pt":1631533551657,"mc":[{"id":"1.187557985","rc":[{"batb":[[0,1.42,301.83],[1,1.4,255.54],[2,1.39,376.48]],"batl":[[0,1.48,255.54],[1,1.5,7.5],[2,1.53,46.5]],"ltp":1.44,"tv":13084.7,"id":5300820},{"batb":[[0,3,15],[1,2.88,4.46],[2,2.8,226.96]],"batl":[[0,3.35,4.89],[1,3.55,145.73],[2,3.6,161.61]],"ltp":3.3,"tv":4553.34,"id":9629022}]}]}
{"op":"mcm","clk":"4215006610","pt":1631533552452,"mc":[{"id":"1.187557985","rc":[{"batb":[[0,1.42,255.54]],"batl":[[1,1.53,46.5],[2,1.56,324.64]],"ltp":1.44,"tv":13084.7,"id":5300820},{"batb":[[0,2.88,4.46],[1,2.8,226.96],[2,2.78,212.61]],"batl":[[0,3.55,145.73],[1,3.6,161.61],[2,3.65,185.09]],"ltp":3.3,"tv":4553.34,"id":9629022}]}]}
{"op":"mcm","clk":"4215006698","pt":1631533553644,"mc":[{"id":"1.187557985","rc":[{"batb":[[0,1.39,376.48],[1,1.38,588.8],[2,1.37,600.67]],"batl":[[0,1.53,46.5],[1,1.56,324.64],[2,1.57,346.45]],"ltp":1.44,"tv":13084.7,"id":5300820}]}]}
{"op":"mcm","clk":"4215006758","pt":1631533554535,"mc":[{"id":"1.187557985","rc":[{"batb":[[1,1.38,978],[2,1.37,884.37]],"batl":[[0,1.55,169.96],[1,1.56,485.44]],"ltp":1.44,"tv":13084.7,"id":5300820},{"batb":[[0,2.8,226.96],[1,2.78,212.61],[2,2.76,249.09]],"ltp":3.3,"tv":4553.34,"id":9629022}]}]}
{"op":"mcm","clk":"4215006921","pt":1631533556469,"mc":[{"id":"1.187557985","rc":[{"batl":[[0,1.57,46.5],[1,1.77,507.52],[2,44,7.23]],"ltp":1.44,"tv":13084.7,"id":5300820},{"batb":[[0,2.8,48.62],[1,2.74,4.52],[2,2,11.88]],"ltp":3.3,"tv":4553.34,"id":9629022}]}]}
{"op":"mcm","clk":"4215006988","pt":1631533557339,"mc":[{"id":"1.187557985","rc":[{"batl":[[0,1.54,7],[1,1.55,7],[2,1.56,5]],"ltp":1.44,"tv":13084.7,"id":5300820},{"batb":[[0,2.88,3],[1,2.86,3],[2,2.8,52.62]],"ltp":3.3,"tv":4553.34,"id":9629022}]}]}
{"op":"mcm","clk":"4215007174","pt":1631533559648,"mc":[{"id":"1.187557985","rc":[{"trd":[[1.39,44.78]],"batb":[[0,1.39,362.1]],"batl":[[0,1.42,290.76],[1,1.43,227.42],[2,1.54,7]],"ltp":1.39,"tv":13113.48,"id":5300820},{"batb":[[0,3.35,570.9],[1,3.3,554.1],[2,3.25,554.1]],"ltp":3.3,"tv":4553.34,"id":9629022}],"tv":17666.82}]}
{"op":"mcm","clk":"4215007237","pt":1631533560433,"mc":[{"id":"1.187557985","rc":[{"batb":[[2,1.37,933.68]],"batl":[[2,1.45,7.5]],"ltp":1.39,"tv":13113.48,"id":5300820},{"batb":[[1,3.3,632.09]],"batl":[[2,3.65,189.69]],"ltp":3.3,"tv":4553.34,"id":9629022}]}]}
{"op":"mcm","clk":"4215007339","pt":1631533561556,"mc":[{"id":"1.187557985","rc":[{"batb":[[0,1.39,400.1]],"ltp":1.39,"tv":13113.48,"id":5300820}]}]}
{"op":"mcm","clk":"4215007502","pt":1631533563644,"mc":[{"id":"1.187557985","rc":[{"batl":[[1,1.43,482.96]],"ltp":1.39,"tv":13113.48,"id":5300820}]}]}
{"op":"mcm","clk":"4215007580","pt":1631533564572,"mc":[{"id":"1.187557985","rc":[{"batl":[[0,1.42,377.76],[2,1.52,35]],"ltp":1.39,"tv":13113.48,"id":5300820}]}]}
{"op":"mcm","clk":"4215007716","pt":1631533566437,"mc":[{"id":"1.187557985","rc":[{"batl":[[2,1.49,51.5]],"ltp":1.39,"tv":13113.48,"id":5300820}]}]}
{"op":"mcm","clk":"4215007870","pt":1631533568583,"mc":[{"id":"1.187557985","rc":[{"batl":[[2,1.44,7.5]],"ltp":1.39,"tv":13113.48,"id":5300820},{"batb":[[2,3.25,567.43]],"ltp":3.3,"tv":4553.34,"id":9629022}]}]}
{"op":"mcm","clk":"4215007985","pt":1631533570097,"mc":[{"id":"1.187557985","rc":[{"trd":[[3.35,0.24]],"batb":[[0,3.35,570.78]],"ltp":3.35,"tv":4553.58,"id":9629022}],"tv":17667.06}]}
{"op":"mcm","clk":"4215008075","pt":1631533571284,"mc":[{"id":"1.187557985","rc":[{"batl":[[0,1.42,374.73]],"ltp":1.39,"tv":13113.48,"id":5300820}]}]}
{"op":"mcm","clk":"4215008769","pt":1631533579583,"mc":[{"id":"1.187557985","rc":[{"batb":[[0,1.38,622.92],[1,1.37,333.01],[2,1.33,76.53]],"ltp":1.39,"tv":13113.48,"id":5300820},{"batb":[[0,3.3,77.99],[1,3.25,13.33],[2,2.94,106.44]],"batl":[[0,3.65,4.6],[1,4.1,2.35],[2,4.2,2.38]],"ltp":3.35,"tv":4553.58,"id":9629022}]}]}
{"op":"mcm","clk":"4215008798","pt":1631533580057,"mc":[{"id":"1.187557985","rc":[{"batb":[[0,1.37,49.31],[1,1.32,364.82],[2,1.3,255.54]],"batl":[[0,1.43,255.54],[1,1.44,7.5],[2,1.49,51.5]],"ltp":1.39,"tv":13113.48,"id":5300820},{"batb":[[0,3.25,13.33],[1,2.94,106.44],[2,2.9,3]],"batl":[[1,4.2,2.38],[2,4.5,2.55]],"ltp":3.35,"tv":4553.58,"id":9629022}]}]}
{"op":"mcm","clk":"4215008916","pt":1631533581390,"mc":[{"id":"1.187557985","rc":[{"batb":[[0,1.32,364.82],[1,1.3,255.54],[2,1.29,81.81]],"batl":[[1,1.49,51.5],[2,1.53,47.5]],"ltp":1.39,"tv":13113.48,"id":5300820},{"batb":[[0,2.94,106.44],[1,2.9,3],[2,2.88,4.71]],"batl":[[0,4.2,2.38],[1,4.5,2.55],[2,4.8,2.32]],"ltp":3.35,"tv":4553.58,"id":9629022}]}]}
{"op":"mcm","clk":"4215009059","pt":1631533583266,"mc":[{"id":"1.187557985","rc":[{"batb":[[0,1.33,356.78],[1,1.32,704.91],[2,1.3,255.54]],"batl":[[2,1.51,298.86]],"ltp":1.39,"tv":13113.48,"id":5300820},{"batl":[[0,4.1,2.85],[1,4.2,2.38],[2,4.5,2.55]],"ltp":3.35,"tv":4553.58,"id":9629022}]}]}
{"op":"mcm","clk":"4215009169","pt":1631533584569,"mc":[{"id":"1.187557985","rc":[{"batb":[[1,1.32,713.91],[2,1.31,8]],"batl":[[0,1.51,298.86],[1,1.52,176.96],[2,1.53,47.5]],"ltp":1.39,"tv":13113.48,"id":5300820},{"batl":[[1,4.2,5.38]],"ltp":3.35,"tv":4553.58,"id":9629022}]}]}
{"op":"mcm","clk":"4215009303","pt":1631533586507,"mc":[{"id":"1.187557985","rc":[{"batb":[[0,1.33,365.78]],"ltp":1.39,"tv":13113.48,"id":5300820},{"batl":[[0,4.1,5.85]],"ltp":3.35,"tv":4553.58,"id":9629022}]}]}
{"op":"mcm","clk":"4215009389","pt":1631533587513,"mc":[{"id":"1.187557985","rc":[{"batl":[[0,1.49,55.5],[1,1.5,5],[2,1.51,304.86]],"ltp":1.39,"tv":13113.48,"id":5300820},{"batb":[[0,3,3],[1,2.98,3],[2,2.96,4]],"ltp":3.35,"tv":4553.58,"id":9629022}]}]}
{"op":"mcm","clk":"4215009415","pt":1631533587778,"mc":[{"id":"1.187557985","rc":[{"batl":[[0,1.49,7],[2,1.51,6]],"ltp":1.39,"tv":13113.48,"id":5300820}]}]}
{"op":"mcm","clk":"4215009611","pt":1631533590420,"mc":[{"id":"1.187557985","rc":[{"batl":[[0,1.35,14.81],[1,1.37,2791.98],[2,1.38,2709.86]],"ltp":1.39,"tv":13113.48,"id":5300820},{"batl":[[1,4.2,916.1],[2,4.3,883.94]],"ltp":3.35,"tv":4553.58,"id":9629022}]}]}
{"op":"mcm","clk":"4215009697","pt":1631533591614,"mc":[{"id":"1.187557985","rc":[{"batl":[[1,1.36,284.47],[2,1.37,1671.83]],"ltp":1.39,"tv":13113.48,"id":5300820},{"batb":[[0,3.7,60.17],[1,3.2,86.44],[2,3,3]],"batl":[[1,4.2,255.83],[2,4.3,243.08]],"ltp":3.35,"tv":4553.58,"id":9629022}]}]}
{"op":"mcm","clk":"4215009770","pt":1631533592531,"mc":[{"id":"1.187557985","rc":[{"batb":[[0,1.33,415.75],[1,1.32,766.94]],"ltp":1.39,"tv":13113.48,"id":5300820},{"batb":[[1,3.55,11.76],[2,3.25,15]],"batl":[[0,4,14.18],[1,4.1,10.1],[2,4.2,255.83]],"ltp":3.35,"tv":4553.58,"id":9629022}]}]}
{"op":"mcm","clk":"4215009987","pt":1631533595558,"mc":[{"id":"1.187557985","rc":[{"batl":[[1,1.36,540.01]],"ltp":1.39,"tv":13113.48,"id":5300820}]}]}
{"op":"mcm","clk":"4215010140","pt":1631533597543,"mc":[{"id":"1.187557985","rc":[{"batb":[[1,1.32,757.94],[2,1.3,255.54]],"ltp":1.39,"tv":13113.48,"id":5300820},{"batb":[[1,3.3,12.26]],"batl":[[2,4.2,252.83]],"ltp":3.35,"tv":4553.58,"id":9629022}]}]}
{"op":"mcm","clk":"4215010349","pt":1631533600143,"mc":[{"id":"1.187557985","rc":[{"trd":[[1.35,19.52]],"batl":[[0,1.35,5.05]],"ltp":1.35,"tv":13133.0,"id":5300820},{"batb":[[1,3.65,11.32],[2,3.3,12.26]],"ltp":3.35,"tv":4553.58,"id":9629022}],"tv":17686.58}]}
{"op":"mcm","clk":"4215010851","pt":1631533607258,"mc":[{"id":"1.187557985","rc":[{"trd":[[1.35,29.62]],"batb":[[0,1.35,8.73],[1,1.33,415.75],[2,1.32,757.94]],"batl":[[0,1.36,540.01],[1,1.37,1671.83],[2,1.38,1362.42]],"ltp":1.35,"tv":13143.1,"id":5300820}],"tv":17696.68}]}
{"op":"mcm","clk":"4215010943","pt":1631533608471,"mc":[{"id":"1.187557985","rc":[{"batb":[[1,1.32,53.03],[2,1.3,255.54]],"batl":[[0,1.36,255.54],[1,1.38,7.5],[2,1.43,6.5]],"ltp":1.35,"tv":13143.1,"id":5300820},{"batb":[[0,3.65,11.32],[1,3.3,8.28],[2,3.2,203.58]],"batl":[[0,4.1,4.25],[1,4.5,124.64],[2,4.6,144.16]],"ltp":3.35,"tv":4553.58,"id":9629022}]}]}
{"op":"mcm","clk":"4215011014","pt":1631533609460,"mc":[{"id":"1.187557985","rc":[{"batb":[[1,1.29,487.86],[2,1.28,554.11]],"batl":[[1,1.43,6.5],[2,1.45,261.94]],"ltp":1.35,"tv":13143.1,"id":5300820},{"batb":[[0,3.3,8.28],[1,3.2,203.58],[2,3.15,162.38]],"batl":[[0,4.5,124.64],[1,4.6,144.16],[2,4.7,148.42]],"ltp":3.35,"tv":4553.58,"id":9629022}]}]}
{"op":"mcm","clk":"4215011076","pt":1631533610526,"mc":[{"id":"1.187557985","rc":[{"trd":[[1.35,47.08]],"batb":[[0,1.29,487.86],[1,1.28,554.11],[2,1.27,885.95]],"ltp":1.35,"tv":13160.56,"id":5300820}],"tv":17714.14}]}
{"op":"mcm","clk":"4215011145","pt":1631533611478,"mc":[{"id":"1.187557985","rc":[{"batb":[[1,1.28,756.07],[2,1.27,1304.78]],"batl":[[1,1.43,73],[2,1.44,64.16]],"ltp":1.35,"tv":13160.56,"id":5300820},{"batb":[[0,3.3,11.86],[1,3.25,11.7],[2,3.2,203.58]],"ltp":3.35,"tv":4553.58,"id":9629022}]}]}
{"op":"mcm","clk":"4215011237","pt":1631533612583,"mc":[{"id":"1.187557985","rc":[{"batb":[[1,1.28,554.11],[2,1.27,885.95]],"ltp":1.35,"tv":13160.56,"id":5300820}]}]}
{"op":"mcm","clk":"4215011380","pt":1631533614151,"mc":[{"id":"1.187557985","rc":[{"batl":[[0,1.45,261.94],[1,1.46,410.13],[2,1.47,525.57]],"ltp":1.35,"tv":13160.56,"id":5300820},{"batb":[[0,3.2,203.58],[1,3.15,162.38],[2,3.1,184.11]],"ltp":3.35,"tv":4553.58,"id":9629022}]}]}
{"op":"mcm","clk":"4215011532","pt":1631533616281,"mc":[{"id":"1.187557985","rc":[{"batb":[[0,1.34,441.59],[1,1.33,329.32],[2,1.29,487.86]],"batl":[[0,1.38,371.61],[1,1.39,256.96],[2,1.45,261.94]],"ltp":1.35,"tv":13160.56,"id":5300820}]}]}
{"op":"mcm","clk":"4215011624","pt":1631533617434,"mc":[{"id":"1.187557985","rc":[{"batl":[[2,1.42,93.32]],"ltp":1.35,"tv":13160.56,"id":5300820},{"batb":[[0,3.35,15],[1,3.3,14.06],[2,3.25,3]],"batl":[[0,4.4,48.85],[1,4.5,124.64],[2,4.6,144.16]],"ltp":3.35,"tv":4553.58,"id":9629022}]}]}
{"op":"mcm","clk":"4215011655","pt":1631533617963,"mc":[{"id":"1.187557985","rc":[{"batb":[[0,1.36,2.32],[1,1.34,441.59],[2,1.33,329.32]],"ltp":1.35,"tv":13160.56,"id":5300820}]}]}
{"op":"mcm","clk":"4215011752","pt":1631533619378,"mc":[{"id":"1.187557985","rc":[{"batb":[[1,1.34,697.13]],"ltp":1.35,"tv":13160.56,"id":5300820}]}]}
{"op":"mcm","clk":"4215011815","pt":1631533620481,"mc":[{"id":"1.187557985","rc":[{"batb":[[1,1.35,151.69],[2,1.34,697.13]],"ltp":1.35,"tv":13160.56,"id":5300820}]}]}
{"op":"mcm","clk":"4215011896","pt":1631533621585,"mc":[{"id":"1.187557985","rc":[{"batb":[[2,1.34,441.59]],"ltp":1.35,"tv":13160.56,"id":5300820}]}]}
{"op":"mcm","clk":"4215011961","pt":1631533622575,"mc":[{"id":"1.187557985","rc":[{"batb":[[2,1.29,487.86]],"batl":[[0,1.42,93.32],[1,1.43,67.5],[2,1.45,267.94]],"ltp":1.35,"tv":13160.56,"id":5300820},{"batb":[[1,3.3,6.58]],"ltp":3.35,"tv":4553.58,"id":9629022}]}]}
{"op":"mcm","clk":"4215011988","pt":1631533622841,"mc":[{"id":"1.187557985","rc":[{"batb":[[1,1.29,487.86],[2,1.28,554.11]],"batl":[[0,1.43,6],[1,1.45,267.94],[2,1.46,410.13]],"ltp":1.35,"tv":13160.56,"id":5300820},{"batb":[[0,3.3,3],[1,3.25,3],[2,3.2,206.58]],"batl":[[0,4.5,124.64],[1,4.6,144.16],[2,4.7,148.42]],"ltp":3.35,"tv":4553.58,"id":9629022}]}]}
{"op":"mcm","clk":"4215012150","pt":1631533625351,"mc":[{"id":"1.187557985","rc":[{"batb":[[2,1.28,756.07]],"batl":[[1,1.45,597.32],[2,1.46,618.04]],"ltp":1.35,"tv":13160.56,"id":5300820}]}]}
{"op":"mcm","clk":"4215012448","pt":1631533629468,"mc":[{"id":"1.187557985","rc":[{"batl":[[0,1.43,58.5],[1,1.45,591.32]],"ltp":1.35,"tv":13160.56,"id":5300820},{"batb":[[0,3.3,6.78],[1,3.2,203.58],[2,3.15,162.38]],"ltp":3.35,"tv":4553.58,"id":9629022}]}]}
{"op":"mcm","clk":"4215012484","pt":1631533630096,"mc":[{"id":"1.187557985","rc":[{"batl":[[0,1.43,6]],"ltp":1.35,"tv":13160.56,"id":5300820},{"batb":[[0,3.3,3]],"ltp":3.35,"tv":4553.58,"id":9629022}]}]}
{"op":"mcm","clk":"4215012582","pt":1631533631657,"mc":[{"id":"1.187557985","rc":[{"batb":[[1,1.29,81.81],[2,1.27,450.83]],"ltp":1.35,"tv":13160.56,"id":5300820},{"batl":[[0,4.5,2.55],[1,4.8,2.32],[2,4.9,2.25]],"ltp":3.35,"tv":4553.58,"id":9629022}]}]}
{"op":"mcm","clk":"4215012663","pt":1631533632593,"mc":[{"id":"1.187557985","rc":[{"batb":[[1,1.27,450.83],[2,1.26,357.52]],"ltp":1.35,"tv":13160.56,"id":5300820},{"batb":[[1,3.25,3],[2,3.2,203.58]],"batl":[[0,4.8,2.32],[1,4.9,2.25],[2,4.9,0]],"ltp":3.35,"tv":4553.58,"id":9629022}]}]}
{"op":"mcm","clk":"4215012833","pt":1631533634609,"mc":[{"id":"1.187557985","rc":[{"batb":[[0,1.41,277.5],[1,1.4,2987.16],[2,1.39,2651.78]],"batl":[[0,1.45,591.32],[1,1.46,618.04],[2,1.47,3127.61]],"ltp":1.35,"tv":13160.56,"id":5300820},{"batb":[[0,3.2,203.58],[1,3.15,162.38],[2,3.1,184.11]],"batl":[[0,3.45,2.7],[1,4,5],[2,4.8,2.32]],"ltp":3.35,"tv":4553.58,"id":9629022}]}]}
{"op":"mcm","clk":"4215012903","pt":1631533635618,"mc":[{"id":"1.187557985","rc":[{"batb":[[1,1.4,1837.33],[2,1.39,1325.88]],"batl":[[0,1.42,14.08],[1,1.45,591.32],[2,1.46,618.04]],"ltp":1.35,"tv":13160.56,"id":5300820}]}]}
{"op":"mcm","clk":"4215012954","pt":1631533636400,"mc":[{"id":"1.187557985","rc":[{"batl":[[2,1.46,625.54]],"ltp":1.35,"tv":13160.56,"id":5300820},{"batb":[[0,3.2,217.21]],"batl":[[1,3.65,4.6],[2,4,5]],"ltp":3.35,"tv":4553.58,"id":9629022}]}]}
{"op":"mcm","clk":"4215013037","pt":1631533637600,"mc":[{"id":"1.187557985","rc":[{"batb":[[0,1.41,334.2],[1,1.4,1844.33]],"ltp":1.35,"tv":13160.56,"id":5300820},{"batl":[[0,3.45,5.7],[2,3.95,3]],"ltp":3.35,"tv":4553.58,"id":9629022}]}]}
{"op":"mcm","clk":"4215013189","pt":1631533639639,"mc":[{"id":"1.187557985","rc":[{"batb":[[0,1.41,589.74]],"ltp":1.35,"tv":13160.56,"id":5300820},{"batl":[[1,3.95,3],[2,4,5]],"ltp":3.35,"tv":4553.58,"id":9629022}]}]}
{"op":"mcm","clk":"4215013246","pt":1631533640637,"mc":[{"id":"1.187557985","rc":[{"batl":[[1,1.45,593.23]],"ltp":1.35,"tv":13160.56,"id":5300820},{"batl":[[0,3.4,13.5],[1,3.45,5.7],[2,3.95,3]],"ltp":3.35,"tv":4553.58,"id":9629022}]}]}
{"op":"mcm","clk":"4215013299","pt":1631533641558,"mc":[{"id":"1.187557985","rc":[{"batb":[[0,1.41,1019.89]],"ltp":1.35,"tv":13160.56,"id":5300820},{"batl":[[1,3.45,181.5],[2,3.9,119.87]],"ltp":3.35,"tv":4553.58,"id":9629022}]}]}
{"op":"mcm","clk":"4215013341","pt":1631533642352,"mc":[{"id":"1.187557985","rc":[{"batb":[[2,1.39,1373.91]],"batl":[[1,1.45,591.32]],"ltp":1.35,"tv":13160.56,"id":5300820}]}]}
{"op":"mcm","clk":"4215013404","pt":1631533643441,"mc":[{"id":"1.187557985","rc":[{"trd":[[1.41,26.38]],"batb":[[0,1.41,1006.7]],"ltp":1.41,"tv":13186.94,"id":5300820},{"batl":[[2,3.6,4.65]],"ltp":3.35,"tv":4553.58,"id":9629022}],"tv":17740.52}]}
{"op":"mcm","clk":"4215014002","pt":1631533652352,"mc":[{"id":"1.187557985","rc":[{"batb":[[1,1.4,1837.33]],"ltp":1.41,"tv":13186.94,"id":5300820}]}]}
{"op":"mcm","clk":"4215014157","pt":1631533654502,"mc":[{"id":"1.187557985","rc":[{"batb":[[0,1.41,255.54],[1,1.39,48.03],[2,1.34,521.46]],"batl":[[0,1.46,7.5],[1,1.47,6.16],[2,1.48,6.74]],"ltp":1.41,"tv":13186.94,"id":5300820},{"batb":[[0,3.2,13.63],[1,3.1,8.74],[2,3.05,9.29]],"batl":[[0,3.6,4.65],[1,3.9,119.87],[2,3.95,138.32]],"ltp":3.35,"tv":4553.58,"id":9629022}]}]}
{"op":"mcm","clk":"4215014235","pt":1631533655476,"mc":[{"id":"1.187557985","rc":[{"batb":[[1,1.34,521.46],[2,1.33,722.93]],"batl":[[0,1.49,255.54],[1,1.55,50.1],[2,1.57,46.5]],"ltp":1.41,"tv":13186.94,"id":5300820},{"batb":[[0,2.8,4.98],[1,2.76,50.71],[2,2.74,151.16]],"batl":[[0,3.9,119.87],[1,3.95,138.32],[2,4,139.7]],"ltp":3.35,"tv":4553.58,"id":9629022}]}]}
{"op":"mcm","clk":"4215014305","pt":1631533656564,"mc":[{"id":"1.187557985","rc":[{"batb":[[0,1.34,521.46],[1,1.33,467.39],[2,1.32,819.37]],"batl":[[0,1.58,269.38],[1,1.59,294.28],[2,1.6,419.73]],"ltp":1.41,"tv":13186.94,"id":5300820},{"batb":[[0,2.76,50.71],[1,2.74,146.64],[2,2.72,217.95]],"ltp":3.35,"tv":4553.58,"id":9629022}]}]}
{"op":"mcm","clk":"4215014373","pt":1631533657592,"mc":[{"id":"1.187557985","rc":[{"batb":[[1,1.33,917.85],[2,1.32,1161.95]],"batl":[[0,1.57,219.27],[1,1.58,422.45],[2,1.59,294.28]],"ltp":1.41,"tv":13186.94,"id":5300820}]}]}
{"op":"mcm","clk":"4215014528","pt":1631533659579,"mc":[{"id":"1.187557985","rc":[{"batl":[[0,1.54,6],[1,1.55,6],[2,1.57,219.27]],"ltp":1.41,"tv":13186.94,"id":5300820},{"batb":[[0,2.8,3],[1,2.78,3],[2,2.76,50.71]],"ltp":3.35,"tv":4553.58,"id":9629022}]}]}
{"op":"mcm","clk":"4215014589","pt":1631533660460,"mc":[{"id":"1.187557985","rc":[{"batb":[[1,1.33,467.39],[2,1.32,819.37]],"batl":[[0,1.56,7],[1,1.57,5],[2,1.58,269.38]],"ltp":1.41,"tv":13186.94,"id":5300820},{"batb":[[0,2.76,53.71],[1,2.74,149.64],[2,2.72,217.95]],"ltp":3.35,"tv":4553.58,"id":9629022}]}]}
{"op":"mcm","clk":"4215014781","pt":1631533663370,"mc":[{"id":"1.187557985","rc":[{"batl":[[0,1.55,43.7],[1,1.56,7],[2,1.57,5]],"ltp":1.41,"tv":13186.94,"id":5300820},{"batb":[[0,2.84,4],[1,2.82,3],[2,2.8,4.38]],"ltp":3.35,"tv":4553.58,"id":9629022}]}]}
{"op":"mcm","clk":"4215014865","pt":1631533664567,"mc":[{"id":"1.187557985","rc":[{"batl":[[0,1.56,7],[1,1.57,5],[2,1.58,269.38]],"ltp":1.41,"tv":13186.94,"id":5300820},{"batb":[[2,2.76,53.71]],"ltp":3.35,"tv":4553.58,"id":9629022}]}]}
{"op":"mcm","clk":"4215022826","pt":1631533667187,"mc":[{"id":"1.187557985","rc":[{"batb":[[1,1.33,917.85],[2,1.32,1161.95]],"batl":[[1,1.57,224.27],[2,1.58,422.45]],"ltp":1.41,"tv":13186.94,"id":5300820}]}]}
{"op":"mcm","clk":"4215023315","pt":1631533674410,"mc":[{"id":"1.187557985","rc":[{"batl":[[0,1.55,6],[1,1.77,507.52],[2,44,7.23]],"ltp":1.41,"tv":13186.94,"id":5300820},{"batb":[[1,2.76,50.71],[2,2.6,4.89]],"ltp":3.35,"tv":4553.58,"id":9629022}]}]}
{"op":"mcm","clk":"4215023460","pt":1631533676622,"mc":[{"id":"1.187557985","rc":[{"batl":[[0,1.37,2345.76],[1,1.55,6],[2,1.77,507.52]],"ltp":1.41,"tv":13186.94,"id":5300820}]}]}
{"op":"mcm","clk":"4215023525","pt":1631533677609,"mc":[{"id":"1.187557985","rc":[{"batl":[[0,1.35,14.81],[1,1.37,1797.7],[2,1.38,1620.17]],"ltp":1.41,"tv":13186.94,"id":5300820},{"batb":[[1,2.8,4.58],[2,2.76,50.71]],"batl":[[0,3.95,138.32],[1,4,139.7],[2,4.2,250.45]],"ltp":3.35,"tv":4553.58,"id":9629022}]}]}
{"op":"mcm","clk":"4215023592","pt":1631533678595,"mc":[{"id":"1.187557985","rc":[{"batb":[[2,1.32,1214.98]],"ltp":1.41,"tv":13186.94,"id":5300820},{"batb":[[0,3.65,60.92],[1,3.55,11.76],[2,3.15,89.04]],"batl":[[2,4.1,4.25]],"ltp":3.35,"tv":4553.58,"id":9629022}]}]}
{"op":"mcm","clk":"4215023651","pt":1631533679525,"mc":[{"id":"1.187557985","rc":[{"batb":[[0,1.34,560.64]],"ltp":1.41,"tv":13186.94,"id":5300820}]}]}
{"op":"mcm","clk":"4215023734","pt":1631533680822,"mc":[{"id":"1.187557985","rc":[{"batl":[[0,3.95,152.35]],"ltp":3.35,"tv":4553.58,"id":9629022}]}]}
{"op":"mcm","clk":"4215023875","pt":1631533682398,"mc":[{"id":"1.187557985","rc":[{"batb":[[0,3.65,80.92]],"ltp":3.35,"tv":4553.58,"id":9629022}]}]}
{"op":"mcm","clk":"4215023955","pt":1631533683626,"mc":[{"id":"1.187557985","rc":[{"batl":[[2,1.38,1631.45]],"ltp":1.41,"tv":13186.94,"id":5300820},{"batb":[[1,3.15,89.04],[2,2.86,4]],"ltp":3.35,"tv":4553.58,"id":9629022}]}]}
{"op":"mcm","clk":"4215024020","pt":1631533684517,"mc":[{"id":"1.187557985","rc":[{"batb":[[1,3.3,12.36],[2,3.2,155.89]],"ltp":3.35,"tv":4553.58,"id":9629022}]}]}
{"op":"mcm","clk":"4215024132","pt":1631533686121,"mc":[{"id":"1.187557985","rc":[{"batb":[[1,3.6,11.53],[2,3.3,12.36]],"ltp":3.35,"tv":4553.58,"id":9629022}]}]}
{"op":"mcm","clk":"4215024320","pt":1631533688923,"mc":[{"id":"1.187557985","rc":[{"trd":[[1.35,51.73]],"batl":[[0,1.35,12.49]],"ltp":1.35,"tv":13191.58,"id":5300820}],"tv":17745.17}]}
{"op":"mcm","clk":"4215024374","pt":1631533690118,"mc":[{"id":"1.187557985","rc":[{"trd":[[1.34,267.74]],"batb":[[0,1.34,460.64]],"ltp":1.34,"tv":13391.58,"id":5300820}],"tv":17945.17}]}
{"op":"mcm","clk":"4215024686","pt":1631533694622,"mc":[{"id":"1.187557985","rc":[{"trd":[[1.35,57.24]],"batl":[[0,1.35,6.98]],"ltp":1.35,"tv":13397.09,"id":5300820},{"trd":[[3.85,1.93]],"ltp":3.85,"tv":4555.51,"id":9629022}],"tv":17952.61}]}
{"op":"mcm","clk":"4215024981","pt":1631533699233,"mc":[{"id":"1.187557985","rc":[{"batb":[[0,1.32,53.03],[1,1.29,538.19],[2,1.28,388.12]],"batl":[[0,1.38,11.28],[1,1.43,60],[2,1.46,352.41]],"ltp":1.35,"tv":13397.09,"id":5300820},{"batb":[[0,3.6,11.53],[1,3.3,12.36],[2,3.2,155.89]],"batl":[[0,4.1,4.25],[1,4.4,132.72],[2,4.5,111.58]],"ltp":3.85,"tv":4555.51,"id":9629022}]}]}
{"op":"mcm","clk":"4215025067","pt":1631533700435,"mc":[{"id":"1.187557985","rc":[{"batb":[[0,1.29,538.19],[1,1.28,388.12],[2,1.27,1008.41]],"batl":[[0,1.38,3.78],[1,1.46,352.41],[2,1.47,353.94]],"ltp":1.35,"tv":13397.09,"id":5300820},{"batb":[[0,3.2,155.89],[1,3.15,228.13],[2,3.1,243.37]],"batl":[[0,4.4,132.72],[1,4.5,111.58],[2,4.6,155.11]],"ltp":3.85,"tv":4555.51,"id":9629022}]}]}
{"op":"mcm","clk":"4215025085","pt":1631533700799,"mc":[{"id":"1.187557985","rc":[{"batl":[[0,1.46,352.41],[1,1.47,353.94],[2,1.48,450.96]],"ltp":1.35,"tv":13397.09,"id":5300820}]}]}
{"op":"mcm","clk":"4215025198","pt":1631533702619,"mc":[{"id":"1.187557985","rc":[{"batb":[[0,1.33,9],[1,1.32,10],[2,1.29,538.19]],"ltp":1.35,"tv":13397.09,"id":5300820}]}]}
{"op":"mcm","clk":"4215025274","pt":1631533703607,"mc":[{"id":"1.187557985","rc":[{"batb":[[0,1.31,4],[1,1.3,4],[2,1.29,542.19]],"ltp":1.35,"tv":13397.09,"id":5300820},{"batl":[[0,4.1,3],[1,4.3,3],[2,4.4,132.72]],"ltp":3.85,"tv":4555.51,"id":9629022}]}]}
{"op":"mcm","clk":"4215025296","pt":1631533703920,"mc":[{"id":"1.187557985","rc":[{"batb":[[0,1.29,538.19],[1,1.28,388.12],[2,1.27,1008.41]],"batl":[[0,1.46,359.41]],"ltp":1.35,"tv":13397.09,"id":5300820},{"batb":[[0,3.2,157.89],[1,3.15,230.13]],"batl":[[0,4.4,132.72],[1,4.5,111.58],[2,4.6,155.11]],"ltp":3.85,"tv":4555.51,"id":9629022}]}]}
