{"op":"mcm","clk":"4234571352","pt":1631547305453,"mc":[{"id":"1.187560677","rc":[{"batb":[[0,4.5,2.1],[1,4.3,2.38],[2,3,5.96]],"batl":[[0,7.8,2],[1,7.8,0]],"ltp":6.4,"tv":1077.19,"id":7588306},{"batb":[[0,1.15,174.83],[1,1.05,477.27],[2,1.03,497.12]],"batl":[[0,1.28,95.34],[1,1.3,88.85],[2,1.56,73.64]],"ltp":1.17,"tv":19662.55,"id":11439844}]}]}
{"op":"mcm","clk":"4234571371","pt":1631547305767,"mc":[{"id":"1.187560677","rc":[{"batb":[[0,4.3,2.38],[1,3,5.96],[2,2.6,3.73]],"ltp":6.4,"tv":1077.19,"id":7588306},{"batl":[[0,1.3,88.85],[1,1.56,73.64],[2,1.94,3.08]],"ltp":1.17,"tv":19662.55,"id":11439844}]}]}
{"op":"mcm","clk":"4234571588","pt":1631547308681,"mc":[{"id":"1.187560677","rc":[{"batb":[[0,4.5,5.16],[1,4.3,8.16],[2,3,5.96]],"ltp":6.4,"tv":1077.19,"id":7588306},{"batl":[[0,1.28,6.84],[1,1.3,94.9],[2,1.56,73.64]],"ltp":1.17,"tv":19662.55,"id":11439844}]}]}
{"op":"mcm","clk":"4234571636","pt":1631547309260,"mc":[{"id":"1.187560677","rc":[{"batb":[[0,4.3,2.38],[1,3,5.96],[2,2.6,3.73]],"ltp":6.4,"tv":1077.19,"id":7588306},{"batl":[[0,1.3,88.85],[1,1.56,73.64],[2,1.94,3.08]],"ltp":1.17,"tv":19662.55,"id":11439844}]}]}
{"op":"mcm","clk":"4234571827","pt":1631547311470,"mc":[{"id":"1.187560677","rc":[{"batl":[[0,7,2],[1,7.8,2]],"ltp":6.4,"tv":1077.19,"id":7588306},{"batb":[[0,1.17,138.97],[1,1.15,174.83],[2,1.05,477.27]],"ltp":1.17,"tv":19662.55,"id":11439844}]}]}
{"op":"mcm","clk":"4234571900","pt":1631547312467,"mc":[{"id":"1.187560677","rc":[{"batb":[[0,4.5,2.1],[1,4.3,2.38],[2,3,5.96]],"batl":[[0,7.8,2],[1,7.8,0]],"ltp":6.4,"tv":1077.19,"id":7588306},{"batb":[[0,1.15,174.83],[1,1.05,477.27],[2,1.03,497.12]],"batl":[[0,1.28,83.34],[1,1.3,88.85],[2,1.56,73.64]],"ltp":1.17,"tv":19662.55,"id":11439844}]}]}
{"op":"mcm","clk":"4234571922","pt":1631547312782,"mc":[{"id":"1.187560677","rc":[{"batb":[[0,4.3,2.38],[1,3,5.96],[2,2.6,3.73]],"ltp":6.4,"tv":1077.19,"id":7588306},{"batl":[[0,1.3,88.85],[1,1.56,73.64],[2,1.94,3.08]],"ltp":1.17,"tv":19662.55,"id":11439844}]}]}
{"op":"mcm","clk":"4234572061","pt":1631547314459,"mc":[{"id":"1.187560677","rc":[{"batb":[[0,6,5.74],[1,5.8,6.9],[2,4.3,2.38]],"batl":[[0,6.4,4.53],[1,6.8,163.99],[2,7.8,2]],"ltp":6.4,"tv":1077.19,"id":7588306},{"batb":[[1,1.03,497.12],[2,1.01,577.96]],"batl":[[0,1.2,23.15],[1,1.21,918.22],[2,1.3,88.85]],"ltp":1.17,"tv":19662.55,"id":11439844}]}]}
{"op":"mcm","clk":"4234572299","pt":1631547317061,"mc":[{"id":"1.187560677","rc":[{"batb":[[1,1.09,790.61],[2,1.03,497.12]],"ltp":1.17,"tv":19662.55,"id":11439844}]}]}
{"op":"mcm","clk":"4234572398","pt":1631547318265,"mc":[{"id":"1.187560677","rc":[{"batl":[[0,1.2,97.15]],"ltp":1.17,"tv":19662.55,"id":11439844}]}]}
{"op":"mcm","clk":"4234572639","pt":1631547321561,"mc":[{"id":"1.187560677","rc":[{"batb":[[2,5,7.06]],"batl":[[2,7,35.27]],"ltp":6.4,"tv":1077.19,"id":7588306},{"batb":[[0,1.16,379.33],[1,1.15,460],[2,1.14,467.66]],"batl":[[0,1.2,23.15],[2,1.25,106.84]],"ltp":1.17,"tv":19662.55,"id":11439844}]}]}
{"op":"mcm","clk":"4234572895","pt":1631547324788,"mc":[{"id":"1.187560677","rc":[{"batl":[[0,1.19,247],[1,1.2,23.15],[2,1.21,918.22]],"ltp":1.17,"tv":19662.55,"id":11439844}]}]}
{"op":"mcm","clk":"4234573125","pt":1631547328976,"mc":[{"id":"1.187560677","rc":[{"batb":[[2,5.1,6.58]],"ltp":6.4,"tv":1077.19,"id":7588306}]}]}
{"op":"mcm","clk":"4234573408","pt":1631547333577,"mc":[{"id":"1.187560677","rc":[{"batb":[[0,6,3.74],[1,5.1,6.58],[2,5,7.06]],"batl":[[0,7,35.27],[1,7.2,34.58],[2,7.4,50.85]],"ltp":6.4,"tv":1077.19,"id":7588306},{"batl":[[1,1.2,5.63],[2,1.24,116.21]],"ltp":1.17,"tv":19662.55,"id":11439844}]}]}
{"op":"mcm","clk":"4234573507","pt":1631547334577,"mc":[{"id":"1.187560677","rc":[{"batb":[[1,5,4.98],[2,4.8,44.99]],"ltp":6.4,"tv":1077.19,"id":7588306},{"batl":[[0,1.2,5.63],[1,1.25,6.42],[2,1.26,252.95]],"ltp":1.17,"tv":19662.55,"id":11439844}]}]}
{"op":"mcm","clk":"4234573532","pt":1631547334788,"mc":[{"id":"1.187560677","rc":[{"batb":[[1,4.8,44.99],[2,4.7,62.62]],"ltp":6.4,"tv":1077.19,"id":7588306},{"batl":[[1,1.26,252.95],[2,1.27,286.04]],"ltp":1.17,"tv":19662.55,"id":11439844}]}]}
{"op":"mcm","clk":"4234573802","pt":1631547338676,"mc":[{"id":"1.187560677","rc":[{"batb":[[1,4.8,2.58],[2,4.7,2.22]],"ltp":6.4,"tv":1077.19,"id":7588306},{"batl":[[1,1.26,89.75],[2,1.27,103.5]],"ltp":1.17,"tv":19662.55,"id":11439844}]}]}
{"op":"mcm","clk":"4234573869","pt":1631547339575,"mc":[{"id":"1.187560677","rc":[{"batb":[[2,3,5.96]],"ltp":6.4,"tv":1077.19,"id":7588306},{"batl":[[2,1.56,73.64]],"ltp":1.17,"tv":19662.55,"id":11439844}]}]}
{"op":"mcm","clk":"4234574033","pt":1631547341606,"mc":[{"id":"1.187560677","rc":[{"batb":[[0,6.4,173.13],[1,6.2,6.46],[2,5.1,6.68]],"batl":[[0,7.2,40.28],[1,7.4,50.85],[2,7.6,157.29]],"ltp":6.4,"tv":1077.19,"id":7588306},{"batl":[[0,1.18,51.45],[1,1.24,106.21],[2,1.25,98.94]],"ltp":1.17,"tv":19662.55,"id":11439844}]}]}
{"op":"mcm","clk":"4234574047","pt":1631547341804,"mc":[{"id":"1.187560677","rc":[{"batb":[[2,5.1,4.54]],"ltp":6.4,"tv":1077.19,"id":7588306},{"batl":[[1,1.24,6.23],[2,1.26,89.75]],"ltp":1.17,"tv":19662.55,"id":11439844}]}]}
{"op":"mcm","clk":"4234574474","pt":1631547348401,"mc":[{"id":"1.187560677","rc":[{"batb":[[2,5.4,40.71]],"batl":[[2,7.6,195.22]],"ltp":6.4,"tv":1077.19,"id":7588306},{"batb":[[1,1.15,651.03],[2,1.14,689.28]],"batl":[[0,1.18,128.45],[1,1.23,200.45],[2,1.24,237.52]],"ltp":1.17,"tv":19662.55,"id":11439844}]}]}
{"op":"mcm","clk":"4234574622","pt":1631547350415,"mc":[{"id":"1.187560677","rc":[{"batb":[[2,6,5.78]],"ltp":6.4,"tv":1077.19,"id":7588306},{"batl":[[1,1.2,129.36],[2,1.21,132.81]],"ltp":1.17,"tv":19662.55,"id":11439844}]}]}
{"op":"mcm","clk":"4234574720","pt":1631547351699,"mc":[{"id":"1.187560677","rc":[{"batb":[[0,6.4,3.16],[1,5.7,5.82],[2,5.4,40.71]],"batl":[[0,7.6,37.93],[1,7.8,42.09],[2,8,40.36]],"ltp":6.4,"tv":1077.19,"id":7588306},{"batb":[[0,1.15,191.03],[1,1.14,420.94],[2,1.13,373.98]],"batl":[[0,1.18,5.75],[1,1.21,132.81],[2,1.23,200.45]],"ltp":1.17,"tv":19662.55,"id":11439844}]}]}
{"op":"mcm","clk":"4234574732","pt":1631547352007,"mc":[{"id":"1.187560677","rc":[{"batb":[[1,5.7,2]],"ltp":6.4,"tv":1077.19,"id":7588306},{"batl":[[1,1.21,126.5]],"ltp":1.17,"tv":19662.55,"id":11439844}]}]}
{"op":"mcm","clk":"4234574975","pt":1631547355707,"mc":[{"id":"1.187560677","rc":[{"batl":[[1,7.8,44.09]],"ltp":6.4,"tv":1077.19,"id":7588306},{"batb":[[0,1.15,367.86]],"ltp":1.17,"tv":19662.55,"id":11439844}]}]}
{"op":"mcm","clk":"4234575103","pt":1631547357524,"mc":[{"id":"1.187560677","rc":[{"batb":[[1,6.2,18.72],[2,5.7,2]],"batl":[[0,7,22.06],[1,7.6,37.93],[2,7.8,44.09]],"ltp":6.4,"tv":1077.19,"id":7588306},{"batl":[[1,1.19,19.5],[2,1.21,126.5]],"ltp":1.17,"tv":19662.55,"id":11439844}]}]}
{"op":"mcm","clk":"4234575181","pt":1631547358715,"mc":[{"id":"1.187560677","rc":[{"batb":[[1,5.7,5.72],[2,5.4,40.71]],"batl":[[0,7.6,37.93],[1,7.8,44.09],[2,8,40.36]],"ltp":6.4,"tv":1077.19,"id":7588306},{"batl":[[1,1.21,133],[2,1.23,200.45]],"ltp":1.17,"tv":19662.55,"id":11439844}]}]}
{"op":"mcm","clk":"4234575256","pt":1631547359609,"mc":[{"id":"1.187560677","rc":[{"batb":[[1,5.7,2]],"ltp":6.4,"tv":1077.19,"id":7588306},{"trd":[[1.15,499.12]],"batb":[[0,1.15,134.88]],"batl":[[1,1.21,126.5]],"ltp":1.15,"tv":20128.51,"id":11439844}],"tv":21205.71}]}
{"op":"mcm","clk":"4234575701","pt":1631547365523,"mc":[{"id":"1.187560677","rc":[{"batb":[[1,6,5.78],[2,5.7,2]],"ltp":6.4,"tv":1077.19,"id":7588306},{"batl":[[1,1.2,132.16],[2,1.21,126.5]],"ltp":1.15,"tv":20128.51,"id":11439844}]}]}
{"op":"mcm","clk":"4234575739","pt":1631547366146,"mc":[{"id":"1.187560677","rc":[{"batb":[[1,5.7,2],[2,5.1,4.54]],"ltp":6.4,"tv":1077.19,"id":7588306},{"batl":[[1,1.21,126.5],[2,1.24,6.23]],"ltp":1.15,"tv":20128.51,"id":11439844}]}]}
{"op":"mcm","clk":"4234575942","pt":1631547368626,"mc":[{"id":"1.187560677","rc":[{"batb":[[0,6.8,4.93]],"batl":[[2,8,47.94]],"ltp":6.4,"tv":1077.19,"id":7588306},{"batb":[[1,1.14,1184.04]],"batl":[[0,1.16,30.09],[1,1.17,1147.4],[2,1.18,103.46]],"ltp":1.15,"tv":20128.51,"id":11439844}]}]}
{"op":"mcm","clk":"4234576131","pt":1631547371131,"mc":[{"id":"1.187560677","rc":[{"batb":[[2,3,5.96]],"ltp":6.4,"tv":1077.19,"id":7588306}]}]}
{"op":"mcm","clk":"4234576196","pt":1631547371849,"mc":[{"id":"1.187560677","rc":[{"trd":[[1.16,7.22]],"batl":[[0,1.16,26.48]],"ltp":1.16,"tv":20135.73,"id":11439844}],"tv":21212.93}]}
{"op":"mcm","clk":"4234576431","pt":1631547374938,"mc":[{"id":"1.187560677","rc":[{"batb":[[1,6.4,5.66],[2,6,31.22]],"batl":[[1,7.8,79.86],[2,8,83.48]],"ltp":6.4,"tv":1077.19,"id":7588306},{"batb":[[1,1.14,1410.31],[2,1.13,595.02]],"batl":[[2,1.18,244.46]],"ltp":1.16,"tv":20135.73,"id":11439844}]}]}
{"op":"mcm","clk":"4234576536","pt":1631547376726,"mc":[{"id":"1.187560677","rc":[{"batl":[[0,1.16,205.48]],"ltp":1.16,"tv":20135.73,"id":11439844}]}]}
{"op":"mcm","clk":"4234576729","pt":1631547379749,"mc":[{"id":"1.187560677","rc":[{"batl":[[2,1.18,174.9]],"ltp":1.16,"tv":20135.73,"id":11439844}]}]}
{"op":"mcm","clk":"4234576918","pt":1631547382054,"mc":[{"id":"1.187560677","rc":[{"batl":[[2,8,75.9]],"ltp":6.4,"tv":1077.19,"id":7588306},{"batl":[[0,1.16,179]],"ltp":1.16,"tv":20135.73,"id":11439844}]}]}
{"op":"mcm","clk":"4234577015","pt":1631547383461,"mc":[{"id":"1.187560677","rc":[{"batb":[[0,6.8,2.93]],"batl":[[0,7.8,35.78],[1,8,35.53],[2,8.2,46.6]],"ltp":6.4,"tv":1077.19,"id":7588306},{"batb":[[0,1.14,425.59],[1,1.13,221.04],[2,1.12,359.12]],"batl":[[1,1.17,5.62],[2,1.18,141]],"ltp":1.16,"tv":20135.73,"id":11439844}]}]}
{"op":"mcm","clk":"4234577137","pt":1631547384659,"mc":[{"id":"1.187560677","rc":[{"batb":[[1,6.4,2]],"ltp":6.4,"tv":1077.19,"id":7588306},{"batl":[[0,1.17,5.62],[1,1.18,134.25],[2,1.2,226.89]],"ltp":1.16,"tv":20135.73,"id":11439844}]}]}
{"op":"mcm","clk":"4234577372","pt":1631547387487,"mc":[{"id":"1.187560677","rc":[{"batb":[[0,6.8,4.93]],"batl":[[0,7.8,37.78]],"ltp":6.4,"tv":1077.19,"id":7588306},{"batb":[[0,1.15,178.43],[1,1.14,425.59],[2,1.13,221.04]],"batl":[[0,1.17,130.12]],"ltp":1.16,"tv":20135.73,"id":11439844}]}]}
{"op":"mcm","clk":"4234577458","pt":1631547388578,"mc":[{"id":"1.187560677","rc":[{"batb":[[0,6.8,2.93]],"batl":[[0,7.8,35.78]],"ltp":6.4,"tv":1077.19,"id":7588306},{"batb":[[0,1.14,425.59],[1,1.13,221.04],[2,1.12,359.12]],"batl":[[0,1.17,5.62]],"ltp":1.16,"tv":20135.73,"id":11439844}]}]}
{"op":"mcm","clk":"4234577836","pt":1631547394675,"mc":[{"id":"1.187560677","rc":[{"batb":[[0,6.8,4.93],[2,3,5.96]],"batl":[[0,8.2,2],[1,8,0],[2,8.2,0]],"ltp":6.4,"tv":1077.19,"id":7588306},{"batb":[[0,1.14,199.32],[1,1.06,969.79],[2,1.03,497.12]],"batl":[[0,1.16,265],[1,1.17,149.12],[2,1.18,134.25]],"ltp":1.16,"tv":20135.73,"id":11439844}]}]}
{"op":"mcm","clk":"4234577892","pt":1631547395613,"mc":[{"id":"1.187560677","rc":[{"batb":[[0,6.4,5.61],[1,3,5.96],[2,2.6,3.73]],"ltp":6.4,"tv":1077.19,"id":7588306},{"batl":[[0,1.18,140.5],[1,1.39,17.9],[2,1.56,73.64]],"ltp":1.16,"tv":20135.73,"id":11439844}]}]}
{"op":"mcm","clk":"4234577904","pt":1631547395875,"mc":[{"id":"1.187560677","rc":[{"batb":[[0,6.4,2]],"ltp":6.4,"tv":1077.19,"id":7588306},{"batl":[[0,1.18,134.25]],"ltp":1.16,"tv":20135.73,"id":11439844}]}]}
{"op":"mcm","clk":"4234578312","pt":1631547401710,"mc":[{"id":"1.187560677","rc":[{"batb":[[0,6.8,3.28],[1,6.4,2],[2,3,5.96]],"batl":[[0,7.8,2],[1,8.2,2]],"ltp":6.4,"tv":1077.19,"id":7588306},{"batb":[[0,1.15,184.03],[1,1.14,199.32],[2,1.06,969.79]],"batl":[[0,1.17,6.03],[1,1.18,134.25],[2,1.39,17.9]],"ltp":1.16,"tv":20135.73,"id":11439844}]}]}
{"op":"mcm","clk":"4234578373","pt":1631547402711,"mc":[{"id":"1.187560677","rc":[{"batb":[[0,6.8,2],[1,6.4,5.21]],"batl":[[0,8.2,2],[1,8.2,0]],"ltp":6.4,"tv":1077.19,"id":7588306},{"batb":[[0,1.14,199.32],[1,1.03,497.12],[2,1.01,577.96]],"batl":[[0,1.17,145.5],[1,1.18,141]],"ltp":1.16,"tv":20135.73,"id":11439844}]}]}
{"op":"mcm","clk":"4234578425","pt":1631547403596,"mc":[{"id":"1.187560677","rc":[{"batb":[[0,6.4,127.24],[1,3,5.96],[2,2.6,3.73]],"batl":[[0,7.2,607.74],[1,8,326.88],[2,8.2,4.5]],"ltp":6.4,"tv":1077.19,"id":7588306},{"batb":[[0,1.15,173.92],[1,1.14,199.32],[2,1.03,497.12]],"batl":[[0,1.18,160.84],[1,1.39,17.9],[2,1.56,73.64]],"ltp":1.16,"tv":20135.73,"id":11439844}]}]}
{"op":"mcm","clk":"4234578450","pt":1631547404015,"mc":[{"id":"1.187560677","rc":[{"batl":[[0,7.2,8.46],[2,8.2,2]],"ltp":6.4,"tv":1077.19,"id":7588306},{"batb":[[0,1.15,34.78]],"ltp":1.16,"tv":20135.73,"id":11439844}]}]}
{"op":"mcm","clk":"4234578585","pt":1631547405790,"mc":[{"id":"1.187560677","rc":[{"batb":[[2,1.08,836.91]],"ltp":1.16,"tv":20135.73,"id":11439844}]}]}
{"op":"mcm","clk":"4234578965","pt":1631547410809,"mc":[{"id":"1.187560677","rc":[{"batb":[[1,6,5.93],[2,5.5,6.36]],"batl":[[1,7.8,35.16],[2,8,365.34]],"ltp":6.4,"tv":1077.19,"id":7588306},{"batb":[[0,1.15,194.41],[1,1.14,411.12],[2,1.13,294.45]],"batl":[[1,1.2,120.86],[2,1.21,125.43]],"ltp":1.16,"tv":20135.73,"id":11439844}]}]}
{"op":"mcm","clk":"4234579202","pt":1631547414012,"mc":[{"id":"1.187560677","rc":[{"batl":[[0,1.18,240.84]],"ltp":1.16,"tv":20135.73,"id":11439844}]}]}
{"op":"mcm","clk":"4234579863","pt":1631547422625,"mc":[{"id":"1.187560677","rc":[{"batb":[[0,6,3.93],[1,5.5,6.36],[2,5.1,35.66]],"batl":[[0,7.8,33.16],[1,8,38.46],[2,8.2,44.21]],"ltp":6.4,"tv":1077.19,"id":7588306},{"batb":[[0,1.14,411.12],[1,1.13,294.45],[2,1.12,323.07]],"batl":[[0,1.2,6.58],[1,1.21,5.93],[2,1.22,6.75]],"ltp":1.16,"tv":20135.73,"id":11439844}]}]}
{"op":"mcm","clk":"4234579877","pt":1631547422936,"mc":[{"id":"1.187560677","rc":[{"batb":[[0,5.5,2],[1,5.1,35.66],[2,5,55.53]],"ltp":6.4,"tv":1077.19,"id":7588306},{"batl":[[0,1.24,187.08],[1,1.25,194.07],[2,1.26,187.59]],"ltp":1.16,"tv":20135.73,"id":11439844}]}]}
{"op":"mcm","clk":"4234580108","pt":1631547425712,"mc":[{"id":"1.187560677","rc":[{"batl":[[0,1.17,258],[1,1.24,187.08],[2,1.25,194.07]],"ltp":1.16,"tv":20135.73,"id":11439844}]}]}
{"op":"mcm","clk":"4234580211","pt":1631547426649,"mc":[{"id":"1.187560677","rc":[{"batl":[[0,1.22,126.25]],"ltp":1.16,"tv":20135.73,"id":11439844}]}]}
{"op":"mcm","clk":"4234580496","pt":1631547429530,"mc":[{"id":"1.187560677","rc":[{"batb":[[0,6,5.78],[1,5.5,2],[2,5.1,35.66]],"batl":[[0,7.8,35.16]],"ltp":6.4,"tv":1077.19,"id":7588306},{"batb":[[0,1.15,146.23],[1,1.14,411.12],[2,1.13,294.45]],"batl":[[0,1.2,136.71],[1,1.21,115.5],[2,1.22,126.25]],"ltp":1.16,"tv":20135.73,"id":11439844}]}]}
{"op":"mcm","clk":"4234580533","pt":1631547430150,"mc":[{"id":"1.187560677","rc":[{"batb":[[0,5.5,2],[1,5.1,35.66],[2,5,55.53]],"batl":[[0,7.8,33.16]],"ltp":6.4,"tv":1077.19,"id":7588306},{"batb":[[0,1.14,411.12],[1,1.13,294.45],[2,1.12,323.07]],"batl":[[0,1.22,126.25],[1,1.24,187.08],[2,1.25,194.07]],"ltp":1.16,"tv":20135.73,"id":11439844}]}]}
{"op":"mcm","clk":"4234581356","pt":1631547440653,"mc":[{"id":"1.187560677","rc":[{"batb":[[0,6,2],[1,5.5,2],[2,5.1,35.66]],"batl":[[0,7.8,35.16]],"ltp":6.4,"tv":1077.19,"id":7588306},{"batb":[[0,1.15,155.23],[1,1.14,411.12],[2,1.13,294.45]],"batl":[[0,1.2,122.98],[1,1.21,105.5],[2,1.22,126.25]],"ltp":1.16,"tv":20135.73,"id":11439844}]}]}
{"op":"mcm","clk":"4234581411","pt":1631547441236,"mc":[{"id":"1.187560677","rc":[{"batb":[[0,5.5,2],[1,5.1,35.66],[2,5,55.53]],"batl":[[0,7.8,33.16]],"ltp":6.4,"tv":1077.19,"id":7588306},{"batb":[[0,1.14,411.12],[1,1.13,294.45],[2,1.12,323.07]],"batl":[[0,1.22,126.25],[1,1.24,187.08],[2,1.25,194.07]],"ltp":1.16,"tv":20135.73,"id":11439844}]}]}
{"op":"mcm","clk":"4234581497","pt":1631547442274,"mc":[{"id":"1.187560677","rc":[{"batb":[[1,3,5.96],[2,2.6,3.73]],"ltp":6.4,"tv":1077.19,"id":7588306},{"batl":[[0,1.39,17.9],[1,1.56,73.64],[2,1.94,3.08]],"ltp":1.16,"tv":20135.73,"id":11439844}]}]}
{"op":"mcm","clk":"4234581684","pt":1631547444696,"mc":[{"id":"1.187560677","rc":[{"batb":[[0,5.5,6.39]],"ltp":6.4,"tv":1077.19,"id":7588306},{"batl":[[0,1.21,6.31],[1,1.22,6.75],[2,1.39,17.9]],"ltp":1.16,"tv":20135.73,"id":11439844}]}]}
{"op":"mcm","clk":"4234581748","pt":1631547445478,"mc":[{"id":"1.187560677","rc":[{"batb":[[0,6.8,4.93],[1,6.4,6.24],[2,5.5,2]],"ltp":6.4,"tv":1077.19,"id":7588306},{"batb":[[0,1.15,24.32],[1,1.14,1254.43],[2,1.13,294.45]],"batl":[[0,1.16,22.16],[1,1.17,1049.96],[2,1.18,54.87]],"ltp":1.16,"tv":20135.73,"id":11439844}]}]}
{"op":"mcm","clk":"4234582153","pt":1631547452059,"mc":[{"id":"1.187560677","rc":[{"batb":[[2,5.9,46.09]],"batl":[[1,8,69.01],[2,8.2,76.9]],"ltp":6.4,"tv":1077.19,"id":7588306},{"batb":[[1,1.14,1485.37],[2,1.13,576.88]],"ltp":1.16,"tv":20135.73,"id":11439844}]}]}
{"op":"mcm","clk":"4234582527","pt":1631547456997,"mc":[{"id":"1.187560677","rc":[{"batl":[[2,1.21,198.13]],"ltp":1.16,"tv":20135.73,"id":11439844}]}]}
{"op":"mcm","clk":"4234583144","pt":1631547466681,"mc":[{"id":"1.187560677","rc":[{"batl":[[0,1.16,227.16]],"ltp":1.16,"tv":20135.73,"id":11439844}]}]}
{"op":"mcm","clk":"4234583282","pt":1631547468775,"mc":[{"id":"1.187560677","rc":[{"trd":[[1.16,113.8]],"batl":[[0,1.16,173.87]],"ltp":1.16,"tv":20242.31,"id":11439844}],"tv":21319.51}]}
{"op":"mcm","clk":"4234583939","pt":1631547479023,"mc":[{"id":"1.187560677","rc":[{"batb":[[0,1.14,1485.37],[1,1.13,576.88],[2,1.12,597.14]],"ltp":1.16,"tv":20242.31,"id":11439844}]}]}
{"op":"mcm","clk":"4234584118","pt":1631547481945,"mc":[{"id":"1.187560677","rc":[{"batl":[[0,7.6,5.94],[1,7.8,33.16],[2,8,69.01]],"ltp":6.4,"tv":1077.19,"id":7588306},{"batl":[[1,1.17,1091.13]],"ltp":1.16,"tv":20242.31,"id":11439844}]}]}
{"op":"mcm","clk":"4234584567","pt":1631547489916,"mc":[{"id":"1.187560677","rc":[{"trd":[[7.6,2.02]],"batl":[[0,7.6,3.92]],"ltp":7.6,"tv":1079.21,"id":7588306},{"trd":[[1.15,512.46]],"ltp":1.15,"tv":20255.65,"id":11439844}],"tv":21334.87}]}
{"op":"mcm","clk":"4234585242","pt":1631547500153,"mc":[{"id":"1.187560677","rc":[{"batl":[[0,7.8,33.16],[1,8,69.01],[2,8.2,76.9]],"ltp":7.6,"tv":1079.21,"id":7588306},{"batl":[[1,1.17,1049.96]],"ltp":1.15,"tv":20255.65,"id":11439844}]}]}
{"op":"mcm","clk":"4234585426","pt":1631547503068,"mc":[{"id":"1.187560677","rc":[{"batl":[[0,7.6,3.92],[1,7.8,33.16],[2,8,69.01]],"ltp":7.6,"tv":1079.21,"id":7588306}]}]}
{"op":"mcm","clk":"4234587514","pt":1631547536700,"mc":[{"id":"1.187560677","rc":[{"batb":[[1,6.4,11.6]],"batl":[[1,7.8,35.16]],"ltp":7.6,"tv":1079.21,"id":7588306},{"batb":[[0,1.15,158.43],[1,1.14,1485.37],[2,1.13,576.88]],"batl":[[2,1.18,154]],"ltp":1.15,"tv":20255.65,"id":11439844}]}]}
{"op":"mcm","clk":"4234588734","pt":1631547555515,"mc":[{"id":"1.187560677","rc":[{"batb":[[1,6.4,5.36]],"batl":[[0,7.8,35.16],[1,8,69.01],[2,8.2,76.9]],"ltp":7.6,"tv":1079.21,"id":7588306},{"batb":[[1,1.14,642.06]],"batl":[[1,1.17,29.12]],"ltp":1.15,"tv":20255.65,"id":11439844}]}]}
{"op":"mcm","clk":"4234588806","pt":1631547556646,"mc":[{"id":"1.187560677","rc":[{"batb":[[0,6.4,2],[1,5.9,46.09],[2,5.8,36.15]],"batl":[[0,8,30.55],[1,8.2,34.69],[2,8.4,47.11]],"ltp":7.6,"tv":1079.21,"id":7588306},{"batb":[[0,1.14,430.25],[1,1.13,282.43],[2,1.12,274.07]],"batl":[[0,1.18,147.75],[1,1.21,198.13],[2,1.22,210]],"ltp":1.15,"tv":20255.65,"id":11439844}]}]}
{"op":"mcm","clk":"4234589221","pt":1631547562491,"mc":[{"id":"1.187560677","rc":[{"batb":[[0,6.8,5.18],[1,6.4,2],[2,5.9,46.09]],"batl":[[0,7.8,2],[1,8,30.55],[2,8.2,34.69]],"ltp":7.6,"tv":1079.21,"id":7588306},{"batb":[[0,1.15,165.63],[1,1.14,430.25],[2,1.13,282.43]],"batl":[[0,1.17,152.53],[1,1.18,147.75],[2,1.21,198.13]],"ltp":1.15,"tv":20255.65,"id":11439844}]}]}
{"op":"mcm","clk":"4234589273","pt":1631547563486,"mc":[{"id":"1.187560677","rc":[{"batb":[[0,6.4,5.76],[1,5.9,46.09],[2,5.8,36.15]],"batl":[[0,8,30.55],[1,8.2,34.69],[2,8.4,47.11]],"ltp":7.6,"tv":1079.21,"id":7588306},{"batb":[[0,1.14,430.25],[1,1.13,282.43],[2,1.12,274.07]],"batl":[[0,1.18,154.5],[1,1.21,198.13],[2,1.22,210]],"ltp":1.15,"tv":20255.65,"id":11439844}]}]}
{"op":"mcm","clk":"4234589311","pt":1631547564272,"mc":[{"id":"1.187560677","rc":[{"batb":[[0,6.4,2]],"ltp":7.6,"tv":1079.21,"id":7588306},{"batl":[[0,1.17,90],[1,1.18,147.75],[2,1.21,198.13]],"ltp":1.15,"tv":20255.65,"id":11439844}]}]}
{"op":"mcm","clk":"4234589440","pt":1631547566669,"mc":[{"id":"1.187560677","rc":[{"batl":[[0,1.18,147.75],[1,1.21,198.13],[2,1.22,210]],"ltp":1.15,"tv":20255.65,"id":11439844}]}]}
{"op":"mcm","clk":"4234589931","pt":1631547574886,"mc":[{"id":"1.187560677","rc":[{"batb":[[1,3,5.96],[2,2.6,3.73]],"ltp":7.6,"tv":1079.21,"id":7588306},{"batl":[[0,1.39,17.9],[1,1.56,73.64],[2,1.94,3.08]],"ltp":1.15,"tv":20255.65,"id":11439844}]}]}
{"op":"mcm","clk":"4234590036","pt":1631547576677,"mc":[{"id":"1.187560677","rc":[{"batb":[[0,6.8,2.93],[1,6.4,2],[2,3,5.96]],"ltp":7.6,"tv":1079.21,"id":7588306},{"batl":[[0,1.17,6.5],[1,1.39,17.9],[2,1.56,73.64]],"ltp":1.15,"tv":20255.65,"id":11439844}]}]}
{"op":"mcm","clk":"4234590083","pt":1631547577668,"mc":[{"id":"1.187560677","rc":[{"batb":[[0,7.6,110.6],[1,7.2,4.72],[2,7,28.58]],"ltp":7.6,"tv":1079.21,"id":7588306},{"batl":[[0,1.15,32.81],[1,1.16,29.44],[2,1.39,17.9]],"ltp":1.15,"tv":20255.65,"id":11439844}]}]}
{"op":"mcm","clk":"4234590093","pt":1631547577875,"mc":[{"id":"1.187560677","rc":[{"batb":[[2,7,5.72]],"batl":[[0,8.2,34.69],[1,8.4,47.11],[2,8.6,8.34]],"ltp":7.6,"tv":1079.21,"id":7588306}]}]}
{"op":"mcm","clk":"4234590373","pt":1631547583710,"mc":[{"id":"1.187560677","rc":[{"batb":[[0,7.6,160.01],[1,7.2,62.27]],"ltp":7.6,"tv":1079.21,"id":7588306},{"batl":[[0,1.15,359.38],[1,1.16,386.7]],"ltp":1.15,"tv":20255.65,"id":11439844}]}]}
{"op":"mcm","clk":"4234590401","pt":1631547584282,"mc":[{"id":"1.187560677","rc":[{"batb":[[1,1.13,463.16]],"batl":[[2,1.17,174.53]],"ltp":1.15,"tv":20255.65,"id":11439844}]}]}
{"op":"mcm","clk":"4234590420","pt":1631547584909,"mc":[{"id":"1.187560677","rc":[{"batl":[[2,8.6,39.2]],"ltp":7.6,"tv":1079.21,"id":7588306},{"batb":[[1,1.13,709.54],[2,1.12,609.58]],"ltp":1.15,"tv":20255.65,"id":11439844}]}]}
{"op":"mcm","clk":"4234590590","pt":1631547588306,"mc":[{"id":"1.187560677","rc":[{"batl":[[0,1.15,479.38]],"ltp":1.15,"tv":20255.65,"id":11439844}]}]}
{"op":"mcm","clk":"4234590755","pt":1631547591486,"mc":[{"id":"1.187560677","rc":[{"batb":[[0,7.2,2.72],[1,6.8,5.18],[2,6,37.97]],"batl":[[0,8.6,30.86],[1,8.8,35.65],[2,9,32.84]],"ltp":7.6,"tv":1079.21,"id":7588306},{"batb":[[0,1.13,427.11],[1,1.12,335.51],[2,1.11,370.21]],"batl":[[0,1.15,120],[1,1.16,5.72]],"ltp":1.15,"tv":20255.65,"id":11439844}]}]}
{"op":"mcm","clk":"4234590817","pt":1631547592630,"mc":[{"id":"1.187560677","rc":[{"batb":[[1,6.8,2]],"ltp":7.6,"tv":1079.21,"id":7588306},{"batl":[[0,1.16,5.72],[1,1.17,168.5],[2,1.2,223.68]],"ltp":1.15,"tv":20255.65,"id":11439844}]}]}
{"op":"mcm","clk":"4234590938","pt":1631547594619,"mc":[{"id":"1.187560677","rc":[{"batb":[[0,7.2,4.72]],"batl":[[0,8.8,2],[1,8.8,0],[2,9,0]],"ltp":7.6,"tv":1079.21,"id":7588306},{"batb":[[0,1.13,180.73],[1,1.01,577.96],[2,1.11,0]],"batl":[[0,1.16,169.44]],"ltp":1.15,"tv":20255.65,"id":11439844}]}]}
{"op":"mcm","clk":"4234590982","pt":1631547595090,"mc":[{"id":"1.187560677","rc":[{"batb":[[0,7.2,2.72]],"ltp":7.6,"tv":1079.21,"id":7588306},{"batl":[[0,1.16,5.72],[1,1.2,223.68],[2,1.21,205.94]],"ltp":1.15,"tv":20255.65,"id":11439844}]}]}
{"op":"mcm","clk":"4234591116","pt":1631547597634,"mc":[{"id":"1.187560677","rc":[{"batl":[[0,8,7.15],[1,8.6,196.84],[2,8.8,2]],"ltp":7.6,"tv":1079.21,"id":7588306},{"batl":[[0,1.16,647.91]],"ltp":1.15,"tv":20255.65,"id":11439844}]}]}
{"op":"mcm","clk":"4234591524","pt":1631547604612,"mc":[{"id":"1.187560677","rc":[{"batb":[[1,6.8,4.98],[2,6,75.34]],"batl":[[1,8.2,2],[2,8.4,28.59]],"ltp":7.6,"tv":1079.21,"id":7588306},{"batb":[[0,1.14,171.32],[1,1.13,400.23],[2,1.12,226.71]],"batl":[[1,1.17,156.53],[2,1.2,439.35]],"ltp":1.15,"tv":20255.65,"id":11439844}]}]}
{"op":"mcm","clk":"4234591671","pt":1631547607331,"mc":[{"id":"1.187560677","rc":[{"batb":[[0,7.2,4.72]],"ltp":7.6,"tv":1079.21,"id":7588306},{"batl":[[0,1.15,266],[1,1.16,804.13],[2,1.17,156.53]],"ltp":1.15,"tv":20255.65,"id":11439844}]}]}
{"op":"mcm","clk":"4234591955","pt":1631547612639,"mc":[{"id":"1.187560677","rc":[{"batb":[[2,6,37.37]],"batl":[[0,8.2,2],[1,8.4,28.59],[2,8.6,42.04]],"ltp":7.6,"tv":1079.21,"id":7588306},{"batl":[[1,1.16,161.94]],"ltp":1.15,"tv":20255.65,"id":11439844}]}]}
{"op":"mcm","clk":"4234591997","pt":1631547613625,"mc":[{"id":"1.187560677","rc":[{"batb":[[0,6.8,4.98],[1,6,37.37],[2,5.9,42.18]],"batl":[[0,8.4,28.59],[1,8.6,42.04],[2,8.8,35.78]],"ltp":7.6,"tv":1079.21,"id":7588306},{"batb":[[0,1.13,400.23],[1,1.12,226.71],[2,1.11,275.38]],"batl":[[0,1.17,156.53],[1,1.2,215.67],[2,1.21,205.6]],"ltp":1.15,"tv":20255.65,"id":11439844}]}]}
{"op":"mcm","clk":"4234592005","pt":1631547613836,"mc":[{"id":"1.187560677","rc":[{"batb":[[0,6.8,2]],"ltp":7.6,"tv":1079.21,"id":7588306},{"batl":[[0,1.17,150.5]],"ltp":1.15,"tv":20255.65,"id":11439844}]}]}
{"op":"mcm","clk":"4234592295","pt":1631547618693,"mc":[{"id":"1.187560677","rc":[{"batb":[[1,3,5.96],[2,2.6,3.73]],"ltp":7.6,"tv":1079.21,"id":7588306},{"batl":[[0,1.39,17.9],[1,1.56,73.64],[2,1.94,3.08]],"ltp":1.15,"tv":20255.65,"id":11439844}]}]}
{"op":"mcm","clk":"4234592346","pt":1631547619679,"mc":[{"id":"1.187560677","rc":[{"batb":[[0,7.2,3.17],[1,6.8,2],[2,3,5.96]],"batl":[[0,8.2,2],[1,8.4,28.59],[2,8.6,42.04]],"ltp":7.6,"tv":1079.21,"id":7588306},{"batb":[[0,1.14,157.32],[1,1.13,400.23],[2,1.12,226.71]],"batl":[[0,1.16,6.22],[1,1.39,17.9],[2,1.56,73.64]],"ltp":1.15,"tv":20255.65,"id":11439844}]}]}
{"op":"mcm","clk":"4234592392","pt":1631547620617,"mc":[{"id":"1.187560677","rc":[{"batb":[[0,6.8,2],[1,3,5.96],[2,2.6,3.73]],"batl":[[0,8.4,28.59],[1,8.6,42.04],[2,8.8,35.78]],"ltp":7.6,"tv":1079.21,"id":7588306},{"batb":[[0,1.13,400.23],[1,1.12,226.71],[2,1.11,275.38]],"batl":[[0,1.39,17.9],[1,1.56,73.64],[2,1.94,3.08]],"ltp":1.15,"tv":20255.65,"id":11439844}]}]}
{"op":"mcm","clk":"4234592433","pt":1631547621292,"mc":[{"id":"1.187560677","rc":[{"batb":[[0,7.6,4.59],[1,7,5.72],[2,6.8,2]],"batl":[[1,8.6,46.93]],"ltp":7.6,"tv":1079.21,"id":7588306},{"batl":[[0,1.15,1085.78],[1,1.39,17.9],[2,1.56,73.64]],"ltp":1.15,"tv":20255.65,"id":11439844}]}]}
{"op":"mcm","clk":"4234592656","pt":1631547624232,"mc":[{"id":"1.187560677","rc":[{"batl":[[1,1.38,987.41],[2,1.39,17.9]],"ltp":1.15,"tv":20255.65,"id":11439844}]}]}
{"op":"mcm","clk":"4234592856","pt":1631547627932,"mc":[{"id":"1.187560677","rc":[{"batb":[[1,7.2,5.17],[2,7,5.72]],"ltp":7.6,"tv":1079.21,"id":7588306},{"batb":[[1,1.12,443.25]],"batl":[[1,1.16,153.19],[2,1.17,165]],"ltp":1.15,"tv":20255.65,"id":11439844}]}]}
{"op":"mcm","clk":"4234593049","pt":1631547631214,"mc":[{"id":"1.187560677","rc":[{"batl":[[0,1.15,1158.78]],"ltp":1.15,"tv":20255.65,"id":11439844}]}]}
{"op":"mcm","clk":"4234593333","pt":1631547635707,"mc":[{"id":"1.187560677","rc":[{"batb":[[0,7.6,2.59],[1,6.8,2],[2,3,5.96]],"batl":[[0,9.4,2],[1,8.6,0],[2,8.8,0]],"ltp":7.6,"tv":1079.21,"id":7588306},{"batb":[[0,1.12,216.54],[1,1.05,1085.43],[2,1.01,577.96]],"batl":[[0,1.15,78.7],[1,1.17,158.5],[2,1.38,987.41]],"ltp":1.15,"tv":20255.65,"id":11439844}]}]}
{"op":"mcm","clk":"4234593365","pt":1631547636333,"mc":[{"id":"1.187560677","rc":[{"batl":[[0,1.15,5.7]],"ltp":1.15,"tv":20255.65,"id":11439844}]}]}
{"op":"mcm","clk":"4234593497","pt":1631547638624,"mc":[{"id":"1.187560677","rc":[{"batb":[[1,7.2,5.07],[2,6.8,2]],"ltp":7.6,"tv":1079.21,"id":7588306},{"batl":[[1,1.16,150.44],[2,1.17,158.5]],"ltp":1.15,"tv":20255.65,"id":11439844}]}]}
{"op":"mcm","clk":"4234593538","pt":1631547639300,"mc":[{"id":"1.187560677","rc":[{"batb":[[1,6.8,2],[2,3,5.96]],"ltp":7.6,"tv":1079.21,"id":7588306},{"batl":[[1,1.17,158.5],[2,1.38,987.41]],"ltp":1.15,"tv":20255.65,"id":11439844}]}]}
{"op":"mcm","clk":"4234593724","pt":1631547642537,"mc":[{"id":"1.187560677","rc":[{"batb":[[1,6.8,5.48]],"batl":[[0,8.8,2],[1,9.4,2]],"ltp":7.6,"tv":1079.21,"id":7588306},{"batb":[[0,1.13,190.73],[1,1.12,216.54],[2,1.05,1085.43]],"batl":[[1,1.17,165]],"ltp":1.15,"tv":20255.65,"id":11439844}]}]}
{"op":"mcm","clk":"4234593747","pt":1631547642857,"mc":[{"id":"1.187560677","rc":[{"batb":[[1,6.8,2]],"batl":[[0,9.4,2],[1,9.4,0]],"ltp":7.6,"tv":1079.21,"id":7588306},{"batb":[[0,1.12,216.54],[1,1.05,1085.43],[2,1.01,577.96]],"batl":[[1,1.17,158.5]],"ltp":1.15,"tv":20255.65,"id":11439844}]}]}
{"op":"mcm","clk":"4234593827","pt":1631547644307,"mc":[{"id":"1.187560677","rc":[{"batl":[[0,1.15,76.7]],"ltp":1.15,"tv":20255.65,"id":11439844}]}]}
{"op":"mcm","clk":"4234593999","pt":1631547647325,"mc":[{"id":"1.187560677","rc":[{"batl":[[0,1.15,5.7]],"ltp":1.15,"tv":20255.65,"id":11439844}]}]}
{"op":"mcm","clk":"4234594065","pt":1631547648526,"mc":[{"id":"1.187560677","rc":[{"batb":[[0,6.8,2],[1,3,5.96],[2,2.6,3.73]],"ltp":7.6,"tv":1079.21,"id":7588306},{"batl":[[0,1.17,158.5],[1,1.38,987.41],[2,1.39,17.9]],"ltp":1.15,"tv":20255.65,"id":11439844}]}]}
{"op":"mcm","clk":"4234594129","pt":1631547649513,"mc":[{"id":"1.187560677","rc":[{"batb":[[0,6.8,5.43]],"batl":[[0,8.8,2],[1,9.4,2]],"ltp":7.6,"tv":1079.21,"id":7588306},{"batb":[[0,1.13,203.73],[1,1.12,216.54],[2,1.05,1085.43]],"batl":[[0,1.17,165]],"ltp":1.15,"tv":20255.65,"id":11439844}]}]}
{"op":"mcm","clk":"4234594200","pt":1631547650553,"mc":[{"id":"1.187560677","rc":[{"batb":[[0,6.8,2]],"batl":[[0,9.4,2],[1,9.4,0]],"ltp":7.6,"tv":1079.21,"id":7588306},{"batb":[[0,1.12,216.54],[1,1.05,1085.43],[2,1.01,577.96]],"batl":[[0,1.14,150],[1,1.17,158.5],[2,1.38,987.41]],"ltp":1.15,"tv":20255.65,"id":11439844}]}]}
{"op":"mcm","clk":"4234594226","pt":1631547650821,"mc":[{"id":"1.187560677","rc":[{"batl":[[0,1.17,158.5],[1,1.38,987.41],[2,1.39,17.9]],"ltp":1.15,"tv":20255.65,"id":11439844}]}]}
{"op":"mcm","clk":"4234594410","pt":1631547652652,"mc":[{"id":"1.187560677","rc":[{"batb":[[0,7.2,4.97],[1,6.8,2],[2,3,5.96]],"ltp":7.6,"tv":1079.21,"id":7588306},{"batl":[[0,1.16,166.44],[1,1.17,158.5],[2,1.38,987.41]],"ltp":1.15,"tv":20255.65,"id":11439844}]}]}
{"op":"mcm","clk":"4234594491","pt":1631547653362,"mc":[{"id":"1.187560677","rc":[{"batb":[[0,6.8,2],[1,3,5.96],[2,2.6,3.73]],"batl":[[0,8.8,2],[1,9.4,2]],"ltp":7.6,"tv":1079.21,"id":7588306},{"batb":[[0,1.13,210.73],[1,1.12,216.54],[2,1.05,1085.43]],"batl":[[0,1.17,158.5],[1,1.38,987.41],[2,1.39,17.9]],"ltp":1.15,"tv":20255.65,"id":11439844}]}]}
{"op":"mcm","clk":"4234594548","pt":1631547653742,"mc":[{"id":"1.187560677","rc":[{"batl":[[0,9.4,2],[1,9.4,0]],"ltp":7.6,"tv":1079.21,"id":7588306},{"batb":[[0,1.12,216.54],[1,1.05,1085.43],[2,1.01,577.96]],"ltp":1.15,"tv":20255.65,"id":11439844}]}]}
{"op":"mcm","clk":"4234595101","pt":1631547656666,"mc":[{"id":"1.187560677","rc":[{"batb":[[0,6.8,5.13]],"ltp":7.6,"tv":1079.21,"id":7588306},{"batl":[[0,1.17,165]],"ltp":1.15,"tv":20255.65,"id":11439844}]}]}
{"op":"mcm","clk":"4234595209","pt":1631547657426,"mc":[{"id":"1.187560677","rc":[{"batb":[[0,6.8,2]],"ltp":7.6,"tv":1079.21,"id":7588306},{"batl":[[0,1.38,987.41],[1,1.39,17.9],[2,1.56,73.64]],"ltp":1.15,"tv":20255.65,"id":11439844}]}]}
{"op":"mcm","clk":"4234595302","pt":1631547658359,"mc":[{"id":"1.187560677","rc":[{"batb":[[1,1.01,577.96],[2,1.01,0]],"ltp":1.15,"tv":20255.65,"id":11439844}]}]}
{"op":"mcm","clk":"4234595431","pt":1631547659705,"mc":[{"id":"1.187560677","rc":[{"batb":[[0,8.6,110.28],[1,7.8,25.64],[2,6.8,2]],"batl":[[1,10,8.76]],"ltp":7.6,"tv":1079.21,"id":7588306},{"batb":[[1,1.11,783.29],[2,1.01,577.96]],"batl":[[0,1.13,39.07],[1,1.38,987.41],[2,1.39,17.9]],"ltp":1.15,"tv":20255.65,"id":11439844}]}]}
{"op":"mcm","clk":"4234595467","pt":1631547660087,"mc":[{"id":"1.187560677","rc":[{"batb":[[1,8,4.45],[2,7.8,5.12]],"ltp":7.6,"tv":1079.21,"id":7588306},{"batl":[[1,1.14,31],[2,1.38,987.41]],"ltp":1.15,"tv":20255.65,"id":11439844}]}]}
{"op":"mcm","clk":"4234595639","pt":1631547662534,"mc":[{"id":"1.187560677","rc":[{"batb":[[2,1.04,1281.74]],"ltp":1.15,"tv":20255.65,"id":11439844}]}]}
{"op":"mcm","clk":"4234596043","pt":1631547667130,"mc":[{"id":"1.187560677","rc":[{"batl":[[1,10,38.3],[2,10.5,30.81]],"ltp":7.6,"tv":1079.21,"id":7588306},{"batb":[[1,1.11,1350.81],[2,1.1,294.53]],"batl":[[2,1.15,186]],"ltp":1.15,"tv":20255.65,"id":11439844}]}]}
{"op":"mcm","clk":"4234596319","pt":1631547670532,"mc":[{"id":"1.187560677","rc":[{"batl":[[0,1.13,239.07]],"ltp":1.15,"tv":20255.65,"id":11439844}]}]}
{"op":"mcm","clk":"4234596357","pt":1631547671048,"mc":[{"id":"1.187560677","rc":[{"trd":[[1.12,4]],"batb":[[0,1.12,214.54]],"ltp":1.12,"tv":20259.65,"id":11439844}],"tv":21338.87}]}
{"op":"mcm","clk":"4234598337","pt":1631547685156,"mc":[{"id":"1.187560677","rc":[{"batb":[[0,8,2.45],[1,7.6,4.79],[2,7.2,4.82]],"batl":[[0,10,29.54],[1,10.5,30.81],[2,11,35.05]],"ltp":7.6,"tv":1079.21,"id":7588306},{"batb":[[0,1.11,303.93],[1,1.1,294.53],[2,1.09,388.63]],"batl":[[0,1.13,200],[1,1.14,5.75]],"ltp":1.12,"tv":20259.65,"id":11439844}]}]}
{"op":"mcm","clk":"4234598834","pt":1631547687563,"mc":[{"id":"1.187560677","rc":[{"batb":[[0,7.6,4.79],[1,7.2,4.82],[2,6.6,37.55]],"ltp":7.6,"tv":1079.21,"id":7588306},{"batl":[[0,1.15,186],[1,1.16,156.44],[2,1.18,215.96]],"ltp":1.12,"tv":20259.65,"id":11439844}]}]}
{"op":"mcm","clk":"4234598871","pt":1631547688175,"mc":[{"id":"1.187560677","rc":[{"batb":[[0,7.2,2],[1,6.6,37.55],[2,6.4,39.79]],"ltp":7.6,"tv":1079.21,"id":7588306},{"batl":[[0,1.16,149.72],[1,1.18,215.96],[2,1.19,212.42]],"ltp":1.12,"tv":20259.65,"id":11439844}]}]}
{"op":"mcm","clk":"4234598946","pt":1631547689485,"mc":[{"id":"1.187560677","rc":[{"batl":[[0,10.5,2],[1,10.5,0],[2,11,0]],"ltp":7.6,"tv":1079.21,"id":7588306},{"batb":[[0,1.04,1281.74],[1,1.01,577.96],[2,1.09,0]],"batl":[[0,1.18,215.96],[1,1.19,212.42],[2,1.2,228.1]],"ltp":1.12,"tv":20259.65,"id":11439844}]}]}
{"op":"mcm","clk":"4234599078","pt":1631547691672,"mc":[{"id":"1.187560677","rc":[{"batb":[[0,1.01,577.96],[1,1.01,0]],"ltp":1.12,"tv":20259.65,"id":11439844}]}]}
{"op":"mcm","clk":"4234599141","pt":1631547692650,"mc":[{"id":"1.187560677","rc":[{"batl":[[0,9.2,7.8],[1,9.8,4.08],[2,10,212.03]],"ltp":7.6,"tv":1079.21,"id":7588306},{"batl":[[0,1.14,744.38],[1,1.18,215.96],[2,1.19,212.42]],"ltp":1.12,"tv":20259.65,"id":11439844}]}]}
{"op":"mcm","clk":"4234599255","pt":1631547694948,"mc":[{"id":"1.187560677","rc":[{"batb":[[0,1.05,1085.43],[1,1.01,577.96]],"ltp":1.12,"tv":20259.65,"id":11439844}]}]}
{"op":"mcm","clk":"4234599435","pt":1631547698682,"mc":[{"id":"1.187560677","rc":[{"batb":[[0,7.6,2],[1,7.2,2],[2,6.6,37.55]],"ltp":7.6,"tv":1079.21,"id":7588306},{"batl":[[1,1.15,170.3],[2,1.16,160.22]],"ltp":1.12,"tv":20259.65,"id":11439844}]}]}
{"op":"mcm","clk":"4234599573","pt":1631547701354,"mc":[{"id":"1.187560677","rc":[{"batb":[[0,1.06,76.21],[1,1.05,1085.43],[2,1.01,577.96]],"ltp":1.12,"tv":20259.65,"id":11439844}]}]}
{"op":"mcm","clk":"4234599599","pt":1631547701872,"mc":[{"id":"1.187560677","rc":[{"batl":[[0,1.14,837.38]],"ltp":1.12,"tv":20259.65,"id":11439844}]}]}
{"op":"mcm","clk":"4234599665","pt":1631547703273,"mc":[{"id":"1.187560677","rc":[{"batb":[[0,7.2,2],[1,3,5.96],[2,2.6,3.73]],"ltp":7.6,"tv":1079.21,"id":7588306},{"batb":[[0,1.05,1085.43],[1,1.01,577.96],[2,1.01,0]],"batl":[[0,1.14,93],[1,1.16,160.22],[2,1.38,987.41]],"ltp":1.12,"tv":20259.65,"id":11439844}]}]}
{"op":"mcm","clk":"4234599735","pt":1631547704469,"mc":[{"id":"1.187560677","rc":[{"batl":[[0,1.16,160.22],[1,1.38,987.41],[2,1.39,17.9]],"ltp":1.12,"tv":20259.65,"id":11439844}]}]}
{"op":"mcm","clk":"4234599940","pt":1631547707484,"mc":[{"id":"1.187560677","rc":[{"batl":[[0,1.13,6.72],[1,1.16,160.22],[2,1.38,987.41]],"ltp":1.12,"tv":20259.65,"id":11439844}]}]}
{"op":"mcm","clk":"4234599996","pt":1631547708597,"mc":[{"id":"1.187560677","rc":[{"batl":[[1,1.15,688.19],[2,1.16,160.22]],"ltp":1.12,"tv":20259.65,"id":11439844}]}]}
{"op":"mcm","clk":"4234600024","pt":1631547709088,"mc":[{"id":"1.187560677","rc":[{"batl":[[1,1.16,160.22],[2,1.38,987.41]],"ltp":1.12,"tv":20259.65,"id":11439844}]}]}
{"op":"mcm","clk":"4234600104","pt":1631547710707,"mc":[{"id":"1.187560677","rc":[{"batb":[[0,7.6,2],[1,7.2,2],[2,3,5.96]],"ltp":7.6,"tv":1079.21,"id":7588306},{"batl":[[1,1.15,162.3],[2,1.16,160.22]],"ltp":1.12,"tv":20259.65,"id":11439844}]}]}
{"op":"mcm","clk":"4234600122","pt":1631547711005,"mc":[{"id":"1.187560677","rc":[{"batb":[[0,7.2,2],[1,3,5.96],[2,2.6,3.73]],"ltp":7.6,"tv":1079.21,"id":7588306},{"batl":[[1,1.16,160.22],[2,1.38,987.41]],"ltp":1.12,"tv":20259.65,"id":11439844}]}]}
{"op":"mcm","clk":"4234600250","pt":1631547713613,"mc":[{"id":"1.187560677","rc":[{"batl":[[2,1.17,161.5]],"ltp":1.12,"tv":20259.65,"id":11439844}]}]}
{"op":"mcm","clk":"4234600329","pt":1631547714601,"mc":[{"id":"1.187560677","rc":[{"batl":[[2,1.38,987.41]],"ltp":1.12,"tv":20259.65,"id":11439844}]}]}
{"op":"mcm","clk":"4234600771","pt":1631547721618,"mc":[{"id":"1.187560677","rc":[{"batb":[[0,7.6,2],[1,7.2,2],[2,3,5.96]],"ltp":7.6,"tv":1079.21,"id":7588306},{"batb":[[0,1.01,577.96],[1,1.01,0]],"batl":[[1,1.15,166.5],[2,1.16,160.22]],"ltp":1.12,"tv":20259.65,"id":11439844}]}]}
{"op":"mcm","clk":"4234600777","pt":1631547721722,"mc":[{"id":"1.187560677","rc":[{"batb":[[0,7.2,2],[1,3,5.96],[2,2.6,3.73]],"ltp":7.6,"tv":1079.21,"id":7588306},{"batl":[[1,1.16,160.22],[2,1.38,987.41]],"ltp":1.12,"tv":20259.65,"id":11439844}]}]}
{"op":"mcm","clk":"4234600893","pt":1631547723398,"mc":[{"id":"1.187560677","rc":[{"trd":[[8.6,0.88]],"batl":[[0,8.6,4.66]],"ltp":8.6,"tv":1080.09,"id":7588306},{"trd":[[1.13,6.72]],"batb":[[0,1.14,28.7],[1,1.13,845.06],[2,1.01,577.96]],"batl":[[0,1.15,21.13],[1,1.16,1408.21]],"ltp":1.13,"tv":20266.37,"id":11439844}],"tv":21346.47}]}
{"op":"mcm","clk":"4234601027","pt":1631547725310,"mc":[{"id":"1.187560677","rc":[{"trd":[[1.14,3.42]],"batb":[[0,1.14,26.99],[2,1.06,969.79]],"ltp":1.14,"tv":20269.79,"id":11439844}],"tv":21349.89}]}
{"op":"mcm","clk":"4234601201","pt":1631547728189,"mc":[{"id":"1.187560677","rc":[{"batl":[[0,8.2,45.63],[1,8.6,4.66],[2,8.8,47.3]],"ltp":8.6,"tv":1080.09,"id":7588306},{"batb":[[0,1.14,355.26],[1,1.13,1213.41]],"ltp":1.14,"tv":20269.79,"id":11439844}]}]}
{"op":"mcm","clk":"4234601356","pt":1631547730422,"mc":[{"id":"1.187560677","rc":[{"batb":[[0,7.6,57.54],[1,7.2,83.05],[2,6.8,2]],"batl":[[1,8.6,34.19],[2,8.8,77.11]],"ltp":8.6,"tv":1080.09,"id":7588306},{"batb":[[1,1.13,1478.09],[2,1.12,316.57]],"batl":[[0,1.15,401.42],[1,1.16,1911.28],[2,1.17,142.5]],"ltp":1.14,"tv":20269.79,"id":11439844}]}]}
{"op":"mcm","clk":"4234601420","pt":1631547731407,"mc":[{"id":"1.187560677","rc":[{"batl":[[0,1.15,609.42]],"ltp":1.14,"tv":20269.79,"id":11439844}]}]}
{"op":"mcm","clk":"4234601639","pt":1631547735315,"mc":[{"id":"1.187560677","rc":[{"batb":[[0,1.14,328.27]],"batl":[[0,1.15,588.29]],"ltp":1.14,"tv":20269.79,"id":11439844}]}]}
{"op":"mcm","clk":"4234601820","pt":1631547738220,"mc":[{"id":"1.187560677","rc":[{"batb":[[0,1.14,355.26]],"batl":[[0,1.15,611.11]],"ltp":1.14,"tv":20269.79,"id":11439844}]}]}
{"op":"mcm","clk":"4234601943","pt":1631547740606,"mc":[{"id":"1.187560677","rc":[{"trd":[[1.15,514.17]],"batl":[[0,1.15,610.25]],"ltp":1.15,"tv":20271.49,"id":11439844}],"tv":21351.59}]}
{"op":"mcm","clk":"4234602061","pt":1631547742519,"mc":[{"id":"1.187560677","rc":[{"batb":[[0,7.2,2],[1,6.8,2],[2,6,41.49]],"batl":[[0,8.6,29.53],[1,8.8,29.82],[2,9,32.45]],"ltp":8.6,"tv":1080.09,"id":7588306},{"batb":[[0,1.13,264.68],[1,1.12,316.57],[2,1.11,292.61]],"batl":[[0,1.15,208],[1,1.16,160.22]],"ltp":1.15,"tv":20271.49,"id":11439844}]}]}
{"op":"mcm","clk":"4234602120","pt":1631547743610,"mc":[{"id":"1.187560677","rc":[{"batb":[[0,6.8,2],[1,6,41.49],[2,5.9,39.14]],"ltp":8.6,"tv":1080.09,"id":7588306},{"batl":[[0,1.14,36.73],[1,1.17,142.5],[2,1.2,227.74]],"ltp":1.15,"tv":20271.49,"id":11439844}]}]}
{"op":"mcm","clk":"4234602327","pt":1631547747748,"mc":[{"id":"1.187560677","rc":[{"batl":[[0,1.17,142.5],[1,1.2,227.74],[2,1.21,217.63]],"ltp":1.15,"tv":20271.49,"id":11439844}]}]}
{"op":"mcm","clk":"4234602507","pt":1631547750760,"mc":[{"id":"1.187560677","rc":[{"batb":[[0,1.06,969.79],[1,1.01,577.96],[2,1.11,0]],"ltp":1.15,"tv":20271.49,"id":11439844}]}]}
{"op":"mcm","clk":"4234602630","pt":1631547753615,"mc":[{"id":"1.187560677","rc":[{"batl":[[0,8.2,24.4]],"ltp":8.6,"tv":1080.09,"id":7588306},{"batb":[[0,1.14,847.86],[1,1.06,969.79],[2,1.01,577.96]],"batl":[[0,1.16,17.04],[1,1.17,1248.69],[2,1.2,227.74]],"ltp":1.15,"tv":20271.49,"id":11439844}]}]}
{"op":"mcm","clk":"4234602675","pt":1631547754645,"mc":[{"id":"1.187560677","rc":[{"trd":[[7.2,1.71]],"batl":[[0,8.2,4.88],[1,250,2.99]],"ltp":7.2,"tv":1081.8,"id":7588306},{"trd":[[1.16,124.38]],"batl":[[0,1.16,6.46]],"ltp":1.16,"tv":20282.07,"id":11439844}],"tv":21363.88}]}
{"op":"mcm","clk":"4234602690","pt":1631547754852,"mc":[{"id":"1.187560677","rc":[{"batl":[[1,250,0]],"ltp":7.2,"tv":1081.8,"id":7588306}]}]}
{"op":"mcm","clk":"4234602910","pt":1631547760050,"mc":[{"id":"1.187560677","rc":[{"batb":[[0,7.2,4.82],[1,6.8,5.23],[2,6,41.49]],"ltp":7.2,"tv":1081.8,"id":7588306},{"batl":[[0,1.16,176.9],[1,1.17,1254.72]],"ltp":1.16,"tv":20282.07,"id":11439844}]}]}
{"op":"mcm","clk":"4234603083","pt":1631547764864,"mc":[{"id":"1.187560677","rc":[{"batl":[[0,1.16,170.44]],"ltp":1.16,"tv":20282.07,"id":11439844}]}]}
{"op":"mcm","clk":"4234603220","pt":1631547767649,"mc":[{"id":"1.187560677","rc":[{"batl":[[0,7.6,4.94],[1,8.2,4.88]],"ltp":7.2,"tv":1081.8,"id":7588306},{"batl":[[1,1.17,1302.21]],"ltp":1.16,"tv":20282.07,"id":11439844}]}]}
{"op":"mcm","clk":"4234603249","pt":1631547768274,"mc":[{"id":"1.187560677","rc":[{"batb":[[0,7.2,2]],"ltp":7.2,"tv":1081.8,"id":7588306},{"batl":[[0,1.16,250.22]],"ltp":1.16,"tv":20282.07,"id":11439844}]}]}
{"op":"mcm","clk":"4234603439","pt":1631547771439,"mc":[{"id":"1.187560677","rc":[{"batb":[[0,7.2,5.02]],"ltp":7.2,"tv":1081.8,"id":7588306},{"batl":[[0,1.16,256.69]],"ltp":1.16,"tv":20282.07,"id":11439844}]}]}
{"op":"mcm","clk":"4234603473","pt":1631547772056,"mc":[{"id":"1.187560677","rc":[{"batb":[[0,7.2,55.71],[1,6.8,72.12]],"ltp":7.2,"tv":1081.8,"id":7588306},{"batl":[[0,1.16,571.32],[1,1.17,1691.02]],"ltp":1.16,"tv":20282.07,"id":11439844}]}]}
{"op":"mcm","clk":"4234603553","pt":1631547773357,"mc":[{"id":"1.187560677","rc":[{"batb":[[0,7.2,5.02],[1,6.8,5.23],[2,3,5.96]],"ltp":7.2,"tv":1081.8,"id":7588306},{"batb":[[0,1.06,969.79],[1,1.01,577.96],[2,1.01,0]],"batl":[[0,1.16,256.69],[1,1.17,148.53],[2,1.38,987.41]],"ltp":1.16,"tv":20282.07,"id":11439844}]}]}
{"op":"mcm","clk":"4234603606","pt":1631547774344,"mc":[{"id":"1.187560677","rc":[{"batb":[[0,6.8,2],[1,3,5.96],[2,2.6,3.73]],"ltp":7.2,"tv":1081.8,"id":7588306},{"batl":[[0,1.17,142.5],[1,1.38,987.41],[2,1.39,17.9]],"ltp":1.16,"tv":20282.07,"id":11439844}]}]}
{"op":"mcm","clk":"4234603784","pt":1631547777570,"mc":[{"id":"1.187560677","rc":[{"batb":[[0,1.01,577.96],[1,1.01,0]],"ltp":1.16,"tv":20282.07,"id":11439844}]}]}
{"op":"mcm","clk":"4234603899","pt":1631547779662,"mc":[{"id":"1.187560677","rc":[{"batl":[[0,7.2,4.76],[1,8,25]],"ltp":7.2,"tv":1081.8,"id":7588306},{"batb":[[0,1.15,706.74],[1,1.01,577.96]],"batl":[[1,1.18,1099.05],[2,1.38,987.41]],"ltp":1.16,"tv":20282.07,"id":11439844}]}]}
{"op":"mcm","clk":"4234603962","pt":1631547780655,"mc":[{"id":"1.187560677","rc":[{"batl":[[1,8,5]],"ltp":7.2,"tv":1081.8,"id":7588306},{"batb":[[1,1.02,626.67],[2,1.01,577.96]],"ltp":1.16,"tv":20282.07,"id":11439844}]}]}
{"op":"mcm","clk":"4234603977","pt":1631547780866,"mc":[{"id":"1.187560677","rc":[{"batb":[[1,1.07,907.25]],"ltp":1.16,"tv":20282.07,"id":11439844}]}]}
{"op":"mcm","clk":"4234604127","pt":1631547784383,"mc":[{"id":"1.187560677","rc":[{"batb":[[1,3.7,92.81],[2,3.6,106.22]],"ltp":7.2,"tv":1081.8,"id":7588306},{"batl":[[0,1.17,256.5],[2,1.37,250.68]],"ltp":1.16,"tv":20282.07,"id":11439844}]}]}
{"op":"mcm","clk":"4234604227","pt":1631547786395,"mc":[{"id":"1.187560677","rc":[{"batb":[[0,6.8,52.03],[1,6.4,66.81],[2,6,2]],"ltp":7.2,"tv":1081.8,"id":7588306},{"batl":[[0,1.17,547.26],[1,1.18,1461.43],[2,1.2,126.53]],"ltp":1.16,"tv":20282.07,"id":11439844}]}]}
{"op":"mcm","clk":"4234604245","pt":1631547786752,"mc":[{"id":"1.187560677","rc":[{"batl":[[1,8,32.06],[2,8.2,34.79]],"ltp":7.2,"tv":1081.8,"id":7588306},{"batb":[[1,1.14,268.29],[2,1.13,259.27]],"ltp":1.16,"tv":20282.07,"id":11439844}]}]}
{"op":"mcm","clk":"4234605158","pt":1631547808097,"mc":[{"id":"1.187560677","rc":[{"trd":[[7.2,1.72]],"batl":[[0,7.2,4.75]],"ltp":7.2,"tv":1081.81,"id":7588306},{"trd":[[1.16,124.42]],"ltp":1.16,"tv":20282.11,"id":11439844}],"tv":21363.92}]}
{"op":"mcm","clk":"4234605284","pt":1631547810195,"mc":[{"id":"1.187560677","rc":[{"batb":[[0,6,2],[1,5.5,2],[2,5.2,48.03]],"batl":[[0,8,27.06],[1,8.2,34.79],[2,8.4,36.48]],"ltp":7.2,"tv":1081.81,"id":7588306},{"batb":[[0,1.14,268.29],[1,1.13,259.27],[2,1.12,364.85]],"batl":[[0,1.17,114],[1,1.2,126.53],[2,1.21,111.5]],"ltp":1.16,"tv":20282.11,"id":11439844}]}]}
{"op":"mcm","clk":"4234605365","pt":1631547811512,"mc":[{"id":"1.187560677","rc":[{"batb":[[0,5.5,2],[1,5.2,48.03],[2,5.1,52.33]],"ltp":7.2,"tv":1081.81,"id":7588306},{"batl":[[0,1.22,117.75],[1,1.24,184.77],[2,1.25,196.28]],"ltp":1.16,"tv":20282.11,"id":11439844}]}]}
{"op":"mcm","clk":"4234605516","pt":1631547814698,"mc":[{"id":"1.187560677","rc":[{"batb":[[0,6,2],[1,5.5,2],[2,5.2,48.03]],"ltp":7.2,"tv":1081.81,"id":7588306},{"batl":[[0,1.2,122.43],[1,1.21,119.5],[2,1.22,117.75]],"ltp":1.16,"tv":20282.11,"id":11439844}]}]}
{"op":"mcm","clk":"4234605563","pt":1631547815627,"mc":[{"id":"1.187560677","rc":[{"batb":[[0,6.8,39.88]],"batl":[[0,7.4,40.29],[1,7.8,92.36],[2,8,27.06]],"ltp":7.2,"tv":1081.81,"id":7588306},{"batl":[[0,1.17,38.5],[1,1.22,117.75],[2,1.24,184.77]],"ltp":1.16,"tv":20282.11,"id":11439844}]}]}
{"op":"mcm","clk":"4234605583","pt":1631547815934,"mc":[{"id":"1.187560677","rc":[{"batb":[[0,5.5,2],[1,5.2,48.03],[2,5.1,52.33]],"batl":[[0,8,27.06],[1,8.2,34.79],[2,8.4,36.48]],"ltp":7.2,"tv":1081.81,"id":7588306},{"batl":[[0,1.22,117.75],[1,1.24,184.77],[2,1.25,196.28]],"ltp":1.16,"tv":20282.11,"id":11439844}]}]}
{"op":"mcm","clk":"4234605710","pt":1631547818546,"mc":[{"id":"1.187560677","rc":[{"batb":[[0,6,2],[1,5.5,2],[2,5.2,48.03]],"ltp":7.2,"tv":1081.81,"id":7588306},{"batl":[[0,1.2,109.58],[1,1.21,116.5],[2,1.22,117.75]],"ltp":1.16,"tv":20282.11,"id":11439844}]}]}
{"op":"mcm","clk":"4234605724","pt":1631547818800,"mc":[{"id":"1.187560677","rc":[{"batb":[[0,5.5,2],[1,5.2,48.03],[2,5.1,52.33]],"ltp":7.2,"tv":1081.81,"id":7588306},{"batl":[[0,1.22,117.75],[1,1.24,184.77],[2,1.25,196.28]],"ltp":1.16,"tv":20282.11,"id":11439844}]}]}
{"op":"mcm","clk":"4234606291","pt":1631547829550,"mc":[{"id":"1.187560677","rc":[{"batb":[[0,1.07,907.25],[1,1.01,577.96],[2,1.12,0]],"ltp":1.16,"tv":20282.11,"id":11439844}]}]}
{"op":"mcm","clk":"4234606379","pt":1631547831321,"mc":[{"id":"1.187560677","rc":[{"batb":[[0,1.01,577.96],[1,1.01,0]],"ltp":1.16,"tv":20282.11,"id":11439844}]}]}
{"op":"mcm","clk":"4234606458","pt":1631547832633,"mc":[{"id":"1.187560677","rc":[{"batb":[[0,5.7,4.63],[1,5.5,2],[2,5.2,48.03]],"batl":[[0,6,4.02],[1,6.4,6.24],[2,7.2,417.06]],"ltp":7.2,"tv":1081.81,"id":7588306},{"batl":[[0,1.22,1027.68]],"ltp":1.16,"tv":20282.11,"id":11439844}]}]}
{"op":"mcm","clk":"4234606597","pt":1631547835337,"mc":[{"id":"1.187560677","rc":[{"batb":[[0,1.03,497.16],[1,1.01,577.96]],"ltp":1.16,"tv":20282.11,"id":11439844}]}]}
{"op":"mcm","clk":"4234606770","pt":1631547838516,"mc":[{"id":"1.187560677","rc":[{"batb":[[0,1.05,477.27],[1,1.03,497.16],[2,1.01,577.96]],"ltp":1.16,"tv":20282.11,"id":11439844}]}]}
{"op":"mcm","clk":"4234606813","pt":1631547839347,"mc":[{"id":"1.187560677","rc":[{"batl":[[2,6.8,30.74]],"ltp":7.2,"tv":1081.81,"id":7588306},{"batb":[[0,1.17,215.71],[1,1.16,226.94],[2,1.15,276.01]],"ltp":1.16,"tv":20282.11,"id":11439844}]}]}
{"op":"mcm","clk":"4234606926","pt":1631547841557,"mc":[{"id":"1.187560677","rc":[{"batb":[[1,5.5,64.41],[2,5.3,75.39]],"ltp":7.2,"tv":1081.81,"id":7588306},{"batl":[[0,1.22,1385.06],[1,1.23,324.86],[2,1.24,184.77]],"ltp":1.16,"tv":20282.11,"id":11439844}]}]}
{"op":"mcm","clk":"4234606961","pt":1631547842131,"mc":[{"id":"1.187560677","rc":[{"batb":[[0,5.7,63.63],[1,5.5,136.85]],"ltp":7.2,"tv":1081.81,"id":7588306},{"batl":[[0,1.21,277.97],[1,1.22,1711.63],[2,1.23,324.86]],"ltp":1.16,"tv":20282.11,"id":11439844}]}]}
{"op":"mcm","clk":"4234607329","pt":1631547848670,"mc":[{"id":"1.187560677","rc":[{"batb":[[0,4.7,2.32],[1,4.5,2.72],[2,4.4,2.86]],"batl":[[0,6.8,30.74],[1,7,41.98],[2,7.2,37.7]],"ltp":7.2,"tv":1081.81,"id":7588306},{"batl":[[0,1.22,76],[1,1.27,91.5],[2,1.28,88.59]],"ltp":1.16,"tv":20282.11,"id":11439844}]}]}
{"op":"mcm","clk":"4234607405","pt":1631547849349,"mc":[{"id":"1.187560677","rc":[{"batb":[[0,4.4,2.86],[1,4.3,49.28],[2,4.2,62.94]],"ltp":7.2,"tv":1081.81,"id":7588306},{"batl":[[0,1.29,75.5],[1,1.31,230.16],[2,1.32,173.44]],"ltp":1.16,"tv":20282.11,"id":11439844}]}]}
{"op":"mcm","clk":"4234609658","pt":1631547866709,"mc":[{"id":"1.187560677","rc":[{"batb":[[0,4.7,2.52],[1,4.4,2.86],[2,4.3,49.28]],"ltp":7.2,"tv":1081.81,"id":7588306},{"batl":[[0,1.27,92.5],[1,1.29,75.5],[2,1.31,230.16]],"ltp":1.16,"tv":20282.11,"id":11439844}]}]}
{"op":"mcm","clk":"4234609687","pt":1631547866978,"mc":[{"id":"1.187560677","rc":[{"batb":[[0,4.4,2.86],[1,4.3,49.28],[2,4.2,62.94]],"ltp":7.2,"tv":1081.81,"id":7588306},{"batl":[[0,1.29,75.5],[1,1.31,230.16],[2,1.32,173.44]],"ltp":1.16,"tv":20282.11,"id":11439844}]}]}
{"op":"mcm","clk":"4234609796","pt":1631547868171,"mc":[{"id":"1.187560677","rc":[{"batb":[[0,1.05,477.27],[1,1.03,497.16],[2,1.01,577.96]],"ltp":1.16,"tv":20282.11,"id":11439844}]}]}
{"op":"mcm","clk":"4234610113","pt":1631547871505,"mc":[{"id":"1.187560677","rc":[{"batl":[[0,5,4.2],[1,5.1,7.84]],"ltp":7.2,"tv":1081.81,"id":7588306},{"batb":[[0,1.25,16.78],[1,1.23,784.85],[2,1.05,477.27]],"batl":[[0,1.27,16.86],[1,1.28,807.7],[2,1.29,75.5]],"ltp":1.16,"tv":20282.11,"id":11439844}]}]}
{"op":"mcm","clk":"4234610238","pt":1631547872779,"mc":[{"id":"1.187560677","rc":[{"batb":[[2,1.13,639.32]],"ltp":1.16,"tv":20282.11,"id":11439844}]}]}
{"op":"mcm","clk":"4234610797","pt":1631547878194,"mc":[{"id":"1.187560677","rc":[{"batl":[[2,5.7,38.56]],"ltp":7.2,"tv":1081.81,"id":7588306},{"batb":[[2,1.21,181.23]],"ltp":1.16,"tv":20282.11,"id":11439844}]}]}
{"op":"mcm","clk":"4234611090","pt":1631547881405,"mc":[{"id":"1.187560677","rc":[{"batl":[[0,1.27,400.86]],"ltp":1.16,"tv":20282.11,"id":11439844}]}]}
{"op":"mcm","clk":"4234611447","pt":1631547885711,"mc":[{"id":"1.187560677","rc":[{"batb":[[0,3.6,49.44],[1,3.55,58.13],[2,3.5,75.48]],"batl":[[0,5.7,38.56],[1,5.8,37.36],[2,5.9,53.72]],"ltp":7.2,"tv":1081.81,"id":7588306},{"batb":[[0,1.21,181.23],[1,1.2,191.35],[2,1.19,300.24]],"batl":[[0,1.39,128.24],[1,1.4,221.85],[2,1.41,153.03]],"ltp":1.16,"tv":20282.11,"id":11439844}]}]}
{"op":"mcm","clk":"4234611519","pt":1631547886714,"mc":[{"id":"1.187560677","rc":[{"batl":[[0,5,70.77],[1,5.1,79.3],[2,5.7,38.56]],"ltp":7.2,"tv":1081.81,"id":7588306},{"batb":[[0,1.25,283.08],[1,1.24,326.14],[2,1.21,181.23]],"ltp":1.16,"tv":20282.11,"id":11439844}]}]}
{"op":"mcm","clk":"4234611544","pt":1631547886926,"mc":[{"id":"1.187560677","rc":[{"batl":[[0,5.7,38.56],[1,5.8,37.36],[2,5.9,53.72]],"ltp":7.2,"tv":1081.81,"id":7588306},{"batb":[[0,1.21,181.23],[1,1.2,191.35],[2,1.19,300.24]],"ltp":1.16,"tv":20282.11,"id":11439844}]}]}
{"op":"mcm","clk":"4234611759","pt":1631547889724,"mc":[{"id":"1.187560677","rc":[{"batb":[[0,3.5,3.44],[1,3,5.96],[2,2.6,3.73]],"ltp":7.2,"tv":1081.81,"id":7588306},{"batl":[[0,1.4,68.34],[1,1.53,724.69],[2,1.56,73.64]],"ltp":1.16,"tv":20282.11,"id":11439844}]}]}
{"op":"mcm","clk":"4234611993","pt":1631547892616,"mc":[{"id":"1.187560677","rc":[{"batb":[[0,5.3,6.48],[1,3.5,3.44],[2,3,5.96]],"ltp":7.2,"tv":1081.81,"id":7588306},{"batb":[[0,1.22,18.06],[1,1.21,181.23],[2,1.2,547.84]],"batl":[[0,1.23,2314.86],[1,1.24,870.91],[2,1.4,68.34]],"ltp":1.16,"tv":20282.11,"id":11439844}]}]}
{"op":"mcm","clk":"4234612013","pt":1631547892824,"mc":[{"id":"1.187560677","rc":[{"batb":[[0,5.3,4.4]],"batl":[[0,5.8,37.36],[1,5.9,53.72],[2,6,71.3]],"ltp":7.2,"tv":1081.81,"id":7588306},{"batl":[[0,1.23,32.52]],"ltp":1.16,"tv":20282.11,"id":11439844}]}]}
{"op":"mcm","clk":"4234612521","pt":1631547898590,"mc":[{"id":"1.187560677","rc":[{"batb":[[0,5.3,67.72],[1,5.1,83.13],[2,3.5,3.44]],"ltp":7.2,"tv":1081.81,"id":7588306},{"batl":[[0,1.23,505.37],[1,1.24,1212.83]],"ltp":1.16,"tv":20282.11,"id":11439844}]}]}
{"op":"mcm","clk":"4234612564","pt":1631547899325,"mc":[{"id":"1.187560677","rc":[{"batb":[[2,4,3.18]],"ltp":7.2,"tv":1081.81,"id":7588306},{"batl":[[2,1.33,80.5]],"ltp":1.16,"tv":20282.11,"id":11439844}]}]}
{"op":"mcm","clk":"4234613163","pt":1631547905313,"mc":[{"id":"1.187560677","rc":[{"trd":[[5.3,6.1]],"batb":[[0,5.3,64.67]],"ltp":5.3,"tv":1087.91,"id":7588306}],"tv":21370.02}]}
{"op":"mcm","clk":"4234613281","pt":1631547906743,"mc":[{"id":"1.187560677","rc":[{"trd":[[1.23,105.73]],"batl":[[0,1.23,452.51]],"ltp":1.23,"tv":20387.84,"id":11439844}],"tv":21475.75}]}
{"op":"mcm","clk":"4234613731","pt":1631547911622,"mc":[{"id":"1.187560677","rc":[{"batb":[[0,5.3,63.32]],"batl":[[2,6.6,35.96]],"ltp":5.3,"tv":1087.91,"id":7588306},{"batb":[[0,1.21,181.23],[1,1.2,191.35],[2,1.19,300.24]],"batl":[[1,1.24,341.92]],"ltp":1.23,"tv":20387.84,"id":11439844}]}]}
{"op":"mcm","clk":"4234613781","pt":1631547912143,"mc":[{"id":"1.187560677","rc":[{"batb":[[0,3.9,43.29],[1,3.85,48.76],[2,3.8,79.97]],"batl":[[0,6.6,35.96],[1,6.8,37.23],[2,7,37.03]],"ltp":5.3,"tv":1087.91,"id":7588306},{"batb":[[0,1.18,220.88],[1,1.17,280.64],[2,1.16,233.33]],"batl":[[0,1.35,131.63],[1,1.36,164.84],[2,1.37,296.13]],"ltp":1.23,"tv":20387.84,"id":11439844}]}]}
{"op":"mcm","clk":"4234614318","pt":1631547918350,"mc":[{"id":"1.187560677","rc":[{"batl":[[0,1.35,209.13]],"ltp":1.23,"tv":20387.84,"id":11439844}]}]}
{"op":"mcm","clk":"4234615763","pt":1631547935076,"mc":[{"id":"1.187560677","rc":[{"batb":[[0,1.11,694.47],[1,1.05,477.27],[2,1.03,497.16]],"ltp":1.23,"tv":20387.84,"id":11439844}]}]}
{"op":"mcm","clk":"4234615898","pt":1631547936702,"mc":[{"id":"1.187560677","rc":[{"batl":[[0,1.33,77.5],[1,1.35,209.13],[2,1.36,164.84]],"ltp":1.23,"tv":20387.84,"id":11439844}]}]}
{"op":"mcm","clk":"4234615910","pt":1631547936910,"mc":[{"id":"1.187560677","rc":[{"batb":[[0,1.05,477.27],[1,1.03,497.16],[2,1.01,577.96]],"batl":[[0,1.35,209.13],[1,1.36,164.84],[2,1.37,296.13]],"ltp":1.23,"tv":20387.84,"id":11439844}]}]}
{"op":"mcm","clk":"4234616037","pt":1631547938384,"mc":[{"id":"1.187560677","rc":[{"batl":[[0,4.3,3.77],[1,4.6,8.7]],"ltp":5.3,"tv":1087.91,"id":7588306},{"batb":[[0,1.22,3553],[1,1.05,477.27],[2,1.03,497.16]],"batl":[[0,1.32,667.01],[1,1.35,209.13],[2,1.36,164.84]],"ltp":1.23,"tv":20387.84,"id":11439844}]}]}
{"op":"mcm","clk":"4234616232","pt":1631547940612,"mc":[{"id":"1.187560677","rc":[{"batb":[[1,1.16,584.68],[2,1.05,477.27]],"ltp":1.23,"tv":20387.84,"id":11439844}]}]}
{"op":"mcm","clk":"4234616289","pt":1631547941400,"mc":[{"id":"1.187560677","rc":[{"batb":[[2,1.1,298.3]],"ltp":1.23,"tv":20387.84,"id":11439844}]}]}
{"op":"mcm","clk":"4234616401","pt":1631547942682,"mc":[{"id":"1.187560677","rc":[{"trd":[[4.3,7.54]],"batb":[[0,4.3,8.27],[1,3.9,43.29],[2,3.85,48.76]],"batl":[[0,4.6,8.7],[1,4.6,0]],"ltp":4.3,"tv":1095.45,"id":7588306},{"batl":[[0,1.3,131.3],[1,1.32,667.01],[2,1.35,209.13]],"ltp":1.23,"tv":20387.84,"id":11439844}],"tv":21483.29}]}
{"op":"mcm","clk":"4234616450","pt":1631547943309,"mc":[{"id":"1.187560677","rc":[{"batb":[[0,4.3,2]],"ltp":4.3,"tv":1095.45,"id":7588306},{"batl":[[0,1.31,1770]],"ltp":1.23,"tv":20387.84,"id":11439844}]}]}
{"op":"mcm","clk":"4234616489","pt":1631547943892,"mc":[{"id":"1.187560677","rc":[{"batb":[[0,3.9,43.29],[1,3.85,48.76],[2,3.8,79.97]],"ltp":4.3,"tv":1095.45,"id":7588306}]}]}
{"op":"mcm","clk":"4234616580","pt":1631547945098,"mc":[{"id":"1.187560677","rc":[{"batl":[[1,5.1,38.89],[2,5.2,42.74]],"ltp":4.3,"tv":1095.45,"id":7588306},{"batb":[[0,1.24,146.33],[1,1.23,201.19],[2,1.22,3748.67]],"ltp":1.23,"tv":20387.84,"id":11439844}]}]}
{"op":"mcm","clk":"4234616805","pt":1631547947726,"mc":[{"id":"1.187560677","rc":[{"batb":[[0,4.2,83.77],[1,4.1,112.55],[2,3.9,43.29]],"ltp":4.3,"tv":1095.45,"id":7588306},{"batl":[[0,1.31,2038.59],[1,1.32,1016.6]],"ltp":1.23,"tv":20387.84,"id":11439844}]}]}
{"op":"mcm","clk":"4234617276","pt":1631547952941,"mc":[{"id":"1.187560677","rc":[{"batl":[[1,1.32,995.65]],"ltp":1.23,"tv":20387.84,"id":11439844}]}]}
{"op":"mcm","clk":"4234617400","pt":1631547954230,"mc":[{"id":"1.187560677","rc":[{"batb":[[0,3.2,57.2],[1,3.15,60.72],[2,3.1,73]],"batl":[[0,5.1,38.89],[1,5.2,42.74],[2,5.3,64.29]],"ltp":4.3,"tv":1095.45,"id":7588306},{"batb":[[2,1.22,195.67]],"batl":[[0,1.46,170.92],[1,1.47,139.47],[2,1.48,184.35]],"ltp":1.23,"tv":20387.84,"id":11439844}]}]}
{"op":"mcm","clk":"4234617646","pt":1631547956703,"mc":[{"id":"1.187560677","rc":[{"batb":[[1,3.15,57.29]],"ltp":4.3,"tv":1095.45,"id":7588306},{"batl":[[0,1.46,117.17]],"ltp":1.23,"tv":20387.84,"id":11439844}]}]}
{"op":"mcm","clk":"4234617959","pt":1631547959709,"mc":[{"id":"1.187560677","rc":[{"batb":[[0,4,21.35],[1,3.2,57.2],[2,3.15,57.29]],"batl":[[0,4.4,20.69],[1,5.1,38.89],[2,5.2,42.74]],"ltp":4.3,"tv":1095.45,"id":7588306},{"batl":[[0,1.33,21.5],[1,1.46,117.17],[2,1.47,139.47]],"ltp":1.23,"tv":20387.84,"id":11439844}]}]}
{"op":"mcm","clk":"4234618018","pt":1631547960340,"mc":[{"id":"1.187560677","rc":[{"batb":[[0,3.2,57.2],[1,3.15,61.52],[2,3.1,73]],"batl":[[0,5.1,38.89],[1,5.2,42.74],[2,5.3,64.29]],"ltp":4.3,"tv":1095.45,"id":7588306},{"batl":[[0,1.46,174.42],[1,1.47,139.47],[2,1.48,184.35]],"ltp":1.23,"tv":20387.84,"id":11439844}]}]}
{"op":"mcm","clk":"4234619271","pt":1631547974544,"mc":[{"id":"1.187560677","rc":[{"batl":[[1,5.2,44.97]],"ltp":4.3,"tv":1095.45,"id":7588306},{"batb":[[0,1.24,255.6],[2,1.22,307.51]],"ltp":1.23,"tv":20387.84,"id":11439844}]}]}
{"op":"mcm","clk":"4234619304","pt":1631547974852,"mc":[{"id":"1.187560677","rc":[{"batl":[[1,5.2,42.74]],"ltp":4.3,"tv":1095.45,"id":7588306},{"batb":[[0,1.24,146.33]],"ltp":1.23,"tv":20387.84,"id":11439844}]}]}
{"op":"mcm","clk":"4234619546","pt":1631547977342,"mc":[{"id":"1.187560677","rc":[{"batb":[[0,2.92,4.44],[1,2.6,3.73],[2,2.2,42.6]],"ltp":4.3,"tv":1095.45,"id":7588306},{"batl":[[0,1.53,724.69],[1,1.56,73.64],[2,1.94,3.08]],"ltp":1.23,"tv":20387.84,"id":11439844}]}]}
{"op":"mcm","clk":"4234619818","pt":1631547980454,"mc":[{"id":"1.187560677","rc":[{"trd":[[5,3.95]],"batb":[[0,5,2.16],[1,4.8,4.61],[2,4.4,9.1]],"batl":[[0,5.2,42.74],[1,5.3,64.29],[2,5.5,216.07]],"ltp":5.0,"tv":1099.4,"id":7588306},{"trd":[[1.25,212.8]],"batl":[[0,1.25,10.18],[1,1.32,2720.93],[2,1.53,724.69]],"ltp":1.25,"tv":20403.64,"id":11439844}],"tv":21503.04}]}
{"op":"mcm","clk":"4234620419","pt":1631547987571,"mc":[{"id":"1.187560677","rc":[{"batl":[[2,1.5,44.39]],"ltp":1.25,"tv":20403.64,"id":11439844}]}]}
{"op":"mcm","clk":"4234620648","pt":1631547990348,"mc":[{"id":"1.187560677","rc":[{"batb":[[1,4.4,9.1],[2,3,10.96]],"ltp":5.0,"tv":1099.4,"id":7588306},{"batl":[[0,1.25,175.18]],"ltp":1.25,"tv":20403.64,"id":11439844}]}]}
{"op":"mcm","clk":"4234620671","pt":1631547990749,"mc":[{"id":"1.187560677","rc":[{"batl":[[0,5.3,64.29],[1,5.5,216.07],[2,5.6,2]],"ltp":5.0,"tv":1099.4,"id":7588306},{"batb":[[0,1.23,201.19],[1,1.22,307.51],[2,1.18,128.36]],"ltp":1.25,"tv":20403.64,"id":11439844}]}]}
{"op":"mcm","clk":"4234620833","pt":1631547993382,"mc":[{"id":"1.187560677","rc":[{"batl":[[0,5.1,4.04],[1,5.3,64.29],[2,5.5,216.07]],"ltp":5.0,"tv":1099.4,"id":7588306},{"batl":[[1,1.26,25.52],[2,1.32,2720.93]],"ltp":1.25,"tv":20403.64,"id":11439844}]}]}
{"op":"mcm","clk":"4234621418","pt":1631548001591,"mc":[{"id":"1.187560677","rc":[{"trd":[[1.25,234.88]],"batl":[[0,1.25,164.14]],"ltp":1.25,"tv":20425.72,"id":11439844}],"tv":21525.12}]}
{"op":"mcm","clk":"4234621729","pt":1631548005697,"mc":[{"id":"1.187560677","rc":[{"batb":[[1,4.4,4.55]],"ltp":5.0,"tv":1099.4,"id":7588306}]}]}
{"op":"mcm","clk":"4234621805","pt":1631548006596,"mc":[{"id":"1.187560677","rc":[{"batb":[[0,3,5.96],[1,2.72,4.84],[2,2.6,3.73]],"batl":[[0,7.4,2],[1,5.3,0],[2,5.5,0]],"ltp":5.0,"tv":1099.4,"id":7588306},{"batb":[[0,1.16,147.53],[1,1.05,477.27],[2,1.03,497.16]],"batl":[[0,1.56,73.64],[1,1.58,46.75],[2,1.94,3.08]],"ltp":1.25,"tv":20425.72,"id":11439844}]}]}
{"op":"mcm","clk":"4234622023","pt":1631548009481,"mc":[{"id":"1.187560677","rc":[{"batl":[[0,6.6,2],[1,7.4,2]],"ltp":5.0,"tv":1099.4,"id":7588306},{"batb":[[0,1.18,131.36],[1,1.16,147.53],[2,1.05,477.27]],"ltp":1.25,"tv":20425.72,"id":11439844}]}]}
{"op":"mcm","clk":"4234622087","pt":1631548010211,"mc":[{"id":"1.187560677","rc":[{"batl":[[0,7.4,2],[1,7.4,0]],"ltp":5.0,"tv":1099.4,"id":7588306},{"batb":[[0,1.16,147.53],[1,1.05,477.27],[2,1.03,497.16]],"ltp":1.25,"tv":20425.72,"id":11439844}]}]}
{"op":"mcm","clk":"4234622637","pt":1631548016503,"mc":[{"id":"1.187560677","rc":[{"batl":[[0,6.6,2.01],[1,7.4,2]],"ltp":5.0,"tv":1099.4,"id":7588306},{"batb":[[0,1.18,154.36],[1,1.16,147.53],[2,1.05,477.27]],"ltp":1.25,"tv":20425.72,"id":11439844}]}]}
{"op":"mcm","clk":"4234622690","pt":1631548017181,"mc":[{"id":"1.187560677","rc":[{"batl":[[0,7.4,2],[1,7.4,0]],"ltp":5.0,"tv":1099.4,"id":7588306},{"batb":[[0,1.16,147.53],[1,1.05,477.27],[2,1.03,497.16]],"ltp":1.25,"tv":20425.72,"id":11439844}]}]}
{"op":"mcm","clk":"4234622946","pt":1631548020311,"mc":[{"id":"1.187560677","rc":[{"batl":[[1,1.94,3.08],[2,3.8,27.43]],"ltp":1.25,"tv":20425.72,"id":11439844}]}]}
{"op":"mcm","clk":"4234623111","pt":1631548022511,"mc":[{"id":"1.187560677","rc":[{"batb":[[0,6,5.41],[1,5.8,6.9],[2,4.8,914.67]],"batl":[[0,6.4,3.5],[1,7.2,255.16],[2,7.4,2]],"ltp":5.0,"tv":1099.4,"id":7588306},{"batb":[[1,1.03,497.16],[2,1.01,577.96]],"batl":[[0,1.2,29.27],[1,1.56,73.64],[2,1.94,3.08]],"ltp":1.25,"tv":20425.72,"id":11439844}]}]}
{"op":"mcm","clk":"4234623384","pt":1631548026225,"mc":[{"id":"1.187560677","rc":[{"batb":[[1,1.09,790.61],[2,1.03,497.16]],"batl":[[1,1.47,815.13],[2,1.56,73.64]],"ltp":1.25,"tv":20425.72,"id":11439844}]}]}
{"op":"mcm","clk":"4234623663","pt":1631548029411,"mc":[{"id":"1.187560677","rc":[{"batb":[[1,1.15,395.24],[2,1.14,278.87]],"batl":[[1,1.28,90.59],[2,1.3,255.8]],"ltp":1.25,"tv":20425.72,"id":11439844}]}]}
{"op":"mcm","clk":"4234623713","pt":1631548029947,"mc":[{"id":"1.187560677","rc":[{"batb":[[0,6,61.69],[2,5.7,74.21]],"ltp":5.0,"tv":1099.4,"id":7588306},{"batl":[[0,1.2,310.65],[1,1.21,349.59],[2,1.28,90.59]],"ltp":1.25,"tv":20425.72,"id":11439844}]}]}
{"op":"mcm","clk":"4234623790","pt":1631548031131,"mc":[{"id":"1.187560677","rc":[{"batl":[[2,7.4,49.44]],"ltp":5.0,"tv":1099.4,"id":7588306},{"batb":[[0,1.16,450.22],[1,1.15,782.34]],"ltp":1.25,"tv":20425.72,"id":11439844}]}]}
{"op":"mcm","clk":"4234623910","pt":1631548032442,"mc":[{"id":"1.187560677","rc":[{"batl":[[0,1.2,415.65]],"ltp":1.25,"tv":20425.72,"id":11439844}]}]}
{"op":"mcm","clk":"4234624208","pt":1631548036632,"mc":[{"id":"1.187560677","rc":[{"trd":[[1.2,2.78]],"batl":[[0,1.2,309.26]],"ltp":1.2,"tv":20428.5,"id":11439844}],"tv":21527.9}]}
{"op":"mcm","clk":"4234624464","pt":1631548039744,"mc":[{"id":"1.187560677","rc":[{"batl":[[0,1.19,369],[1,1.2,309.26],[2,1.21,349.59]],"ltp":1.2,"tv":20428.5,"id":11439844}]}]}
{"op":"mcm","clk":"4234625047","pt":1631548046560,"mc":[{"id":"1.187560677","rc":[{"batb":[[0,6,58.28]],"batl":[[0,7.2,255.16],[1,7.4,49.44],[2,7.6,31.07]],"ltp":5.0,"tv":1099.4,"id":7588306},{"batl":[[1,1.2,293.61]],"ltp":1.2,"tv":20428.5,"id":11439844}]}]}
{"op":"mcm","clk":"4234625272","pt":1631548049669,"mc":[{"id":"1.187560677","rc":[{"batb":[[1,5.7,74.21],[2,4.5,2.58]],"batl":[[0,7.4,49.44],[1,7.6,31.07],[2,7.8,98.49]],"ltp":5.0,"tv":1099.4,"id":7588306}]}]}
{"op":"mcm","clk":"4234625349","pt":1631548050667,"mc":[{"id":"1.187560677","rc":[{"batb":[[0,4.3,49.43],[1,4.2,56.33],[2,4.1,60.47]],"batl":[[0,7.6,31.07],[1,7.8,41.42],[2,8,37.05]],"ltp":5.0,"tv":1099.4,"id":7588306},{"batb":[[0,1.15,395.24],[1,1.14,278.87],[2,1.13,368.38]],"batl":[[0,1.3,170.95],[1,1.31,266.88],[2,1.32,159.98]],"ltp":1.2,"tv":20428.5,"id":11439844}]}]}
{"op":"mcm","clk":"4234625738","pt":1631548055257,"mc":[{"id":"1.187560677","rc":[{"batb":[[0,4.2,3.07],[1,3,5.96],[2,2.6,3.73]],"ltp":5.0,"tv":1099.4,"id":7588306},{"batl":[[0,1.31,91.5],[1,1.47,815.13],[2,1.56,73.64]],"ltp":1.2,"tv":20428.5,"id":11439844}]}]}
{"op":"mcm","clk":"4234625887","pt":1631548056677,"mc":[{"id":"1.187560677","rc":[{"batl":[[0,7.4,2],[1,7.6,31.07],[2,7.8,41.42]],"ltp":5.0,"tv":1099.4,"id":7588306},{"batb":[[0,1.16,177.03],[1,1.15,395.24],[2,1.14,278.87]],"ltp":1.2,"tv":20428.5,"id":11439844}]}]}
{"op":"mcm","clk":"4234625984","pt":1631548057690,"mc":[{"id":"1.187560677","rc":[{"batb":[[0,4.5,2.58],[1,4.2,3.07],[2,3,5.96]],"batl":[[0,7.6,31.07],[1,7.8,41.42],[2,8,37.05]],"ltp":5.0,"tv":1099.4,"id":7588306},{"batb":[[0,1.15,395.24],[1,1.14,278.87],[2,1.13,368.38]],"batl":[[0,1.28,89.59],[1,1.31,91.5],[2,1.47,815.13]],"ltp":1.2,"tv":20428.5,"id":11439844}]}]}
{"op":"mcm","clk":"4234626048","pt":1631548058474,"mc":[{"id":"1.187560677","rc":[{"batb":[[0,6,276.47]],"batl":[[0,7.6,35.84]],"ltp":5.0,"tv":1099.4,"id":7588306},{"batb":[[1,1.14,1286.88]],"batl":[[0,1.17,49.57],[1,1.18,33.9],[2,1.2,1382.34]],"ltp":1.2,"tv":20428.5,"id":11439844}]}]}
{"op":"mcm","clk":"4234626542","pt":1631548064568,"mc":[{"id":"1.187560677","rc":[{"batb":[[0,6.2,2],[1,6,278.47],[2,4.2,3.07]],"ltp":5.0,"tv":1099.4,"id":7588306},{"batb":[[1,1.14,1467.7],[2,1.13,561.11]],"batl":[[2,1.19,126.5]],"ltp":1.2,"tv":20428.5,"id":11439844}]}]}
{"op":"mcm","clk":"4234626618","pt":1631548065370,"mc":[{"id":"1.187560677","rc":[{"batb":[[1,6,276.47],[2,5.2,43.04]],"ltp":5.0,"tv":1099.4,"id":7588306},{"batb":[[1,1.14,1678.34],[2,1.13,813.28]],"ltp":1.2,"tv":20428.5,"id":11439844}]}]}
{"op":"mcm","clk":"4234626847","pt":1631548068092,"mc":[{"id":"1.187560677","rc":[{"batb":[[1,6,278.47]],"ltp":5.0,"tv":1099.4,"id":7588306}]}]}
{"op":"mcm","clk":"4234627119","pt":1631548071372,"mc":[{"id":"1.187560677","rc":[{"batl":[[0,1.17,155.57]],"ltp":1.2,"tv":20428.5,"id":11439844}]}]}
{"op":"mcm","clk":"4234627335","pt":1631548073469,"mc":[{"id":"1.187560677","rc":[{"batb":[[1,6,2]],"batl":[[0,8.2,33.11],[1,8.4,33.09],[2,8.6,34.77]],"ltp":5.0,"tv":1099.4,"id":7588306},{"batb":[[0,1.14,391.46],[1,1.13,444.9],[2,1.12,274.96]],"batl":[[0,1.17,106],[1,1.19,126.5],[2,1.2,134.13]],"ltp":1.2,"tv":20428.5,"id":11439844}]}]}
{"op":"mcm","clk":"4234627428","pt":1631548074579,"mc":[{"id":"1.187560677","rc":[{"batb":[[0,6,2],[1,5.2,43.04],[2,5.1,42.74]],"ltp":5.0,"tv":1099.4,"id":7588306},{"batl":[[0,1.2,134.13],[1,1.24,202.17],[2,1.25,171.6]],"ltp":1.2,"tv":20428.5,"id":11439844}]}]}
{"op":"mcm","clk":"4234627702","pt":1631548077499,"mc":[{"id":"1.187560677","rc":[{"batb":[[1,3,5.96],[2,2.6,3.73]],"batl":[[0,8.2,31.11]],"ltp":5.0,"tv":1099.4,"id":7588306},{"batb":[[0,1.14,210.64]],"batl":[[1,1.39,17.9],[2,1.47,815.13]],"ltp":1.2,"tv":20428.5,"id":11439844}]}]}
{"op":"mcm","clk":"4234627822","pt":1631548079070,"mc":[{"id":"1.187560677","rc":[{"batl":[[2,1.56,73.64]],"ltp":1.2,"tv":20428.5,"id":11439844}]}]}
{"op":"mcm","clk":"4234627933","pt":1631548080497,"mc":[{"id":"1.187560677","rc":[{"batb":[[0,6.8,5.88],[1,6,2],[2,3,5.96]],"batl":[[0,8.4,33.09],[1,8.6,40.55],[2,8.8,2]],"ltp":5.0,"tv":1099.4,"id":7588306},{"batb":[[0,1.13,444.9],[1,1.12,274.96],[2,1.01,577.96]],"batl":[[0,1.15,826.89],[1,1.2,134.13],[2,1.39,17.9]],"ltp":1.2,"tv":20428.5,"id":11439844}]}]}
{"op":"mcm","clk":"4234628210","pt":1631548083604,"mc":[{"id":"1.187560677","rc":[{"trd":[[1.15,554.17]],"batb":[[2,1.06,935.82]],"batl":[[0,1.15,806.89]],"ltp":1.15,"tv":20468.5,"id":11439844}],"tv":21567.9}]}
{"op":"mcm","clk":"4234629138","pt":1631548094689,"mc":[{"id":"1.187560677","rc":[{"batb":[[0,7.6,52.01],[1,7.4,68.21],[2,6.8,5.88]],"ltp":5.0,"tv":1099.4,"id":7588306},{"batl":[[1,1.16,775.91],[2,1.2,134.13]],"ltp":1.15,"tv":20468.5,"id":11439844}]}]}
{"op":"mcm","clk":"4234629239","pt":1631548095604,"mc":[{"id":"1.187560677","rc":[{"batl":[[0,8.6,40.55],[1,8.8,2],[2,9.2,157.05]],"ltp":5.0,"tv":1099.4,"id":7588306},{"batl":[[0,1.14,54.23],[1,1.15,905.89],[2,1.16,775.91]],"ltp":1.15,"tv":20468.5,"id":11439844}]}]}
{"op":"mcm","clk":"4234629376","pt":1631548097016,"mc":[{"id":"1.187560677","rc":[{"batb":[[1,6.8,5.88],[2,6,2]],"ltp":5.0,"tv":1099.4,"id":7588306},{"trd":[[1.14,10.48]],"batl":[[0,1.14,50.7]],"ltp":1.14,"tv":20475.56,"id":11439844}],"tv":21574.96}]}
{"op":"mcm","clk":"4234630096","pt":1631548105429,"mc":[{"id":"1.187560677","rc":[{"trd":[[1.14,30.09]],"batl":[[0,1.14,40.89]],"ltp":1.14,"tv":20495.17,"id":11439844}],"tv":21594.57}]}
{"op":"mcm","clk":"4234631163","pt":1631548118869,"mc":[{"id":"1.187560677","rc":[{"trd":[[1.13,26.72]],"batb":[[0,1.13,434.9]],"ltp":1.13,"tv":20515.17,"id":11439844}],"tv":21614.57}]}
{"op":"mcm","clk":"4234631836","pt":1631548128470,"mc":[{"id":"1.187560677","rc":[{"trd":[[7.6,4.8],[8,5.83]],"batb":[[0,7.6,50.62]],"batl":[[0,8.6,5.78]],"ltp":7.6,"tv":1108.01,"id":7588306},{"trd":[[1.14,70.98]],"batb":[[0,1.13,182.73],[1,1.06,935.82],[2,1.01,105.79]],"batl":[[0,1.15,905.89],[1,1.16,775.91],[2,1.2,134.13]],"ltp":1.14,"tv":20556.06,"id":11439844}],"tv":21664.07}]}
{"op":"mcm","clk":"4234631998","pt":1631548131443,"mc":[{"id":"1.187560677","rc":[{"batb":[[0,6.8,5.88],[1,6,2],[2,1.6,767.39]],"ltp":7.6,"tv":1108.01,"id":7588306},{"batl":[[1,1.2,134.13],[2,1.39,17.9]],"ltp":1.14,"tv":20556.06,"id":11439844}]}]}
{"op":"mcm","clk":"4234638874","pt":1631548212263,"mc":[{"id":"1.187560677","rc":[{"batb":[[2,1.01,120.59]],"ltp":1.14,"tv":20556.06,"id":11439844}]}]}
{"op":"mcm","clk":"4234638969","pt":1631548213366,"mc":[{"id":"1.187560677","rc":[{"batb":[[0,1.6,767.39],[1,1.3,5],[2,1.01,105.79]],"batl":[[0,990,0.01],[1,8.8,0],[2,9.2,0]],"ltp":7.6,"tv":1108.01,"id":7588306},{"batb":[[0,1.06,935.82],[1,1.01,120.59],[2,1.01,0]],"batl":[[0,1.15,99],[1,1.39,17.9],[2,1.4,1040.75]],"ltp":1.14,"tv":20556.06,"id":11439844}]}]}
{"op":"mcm","clk":"4234639068","pt":1631548214369,"mc":[{"id":"1.187560677","rc":[{"batb":[[1,1.02,5.95],[2,1.01,120.59]],"batl":[[0,1.39,17.9],[1,1.4,1040.75],[2,1.94,3.08]],"ltp":1.14,"tv":20556.06,"id":11439844}]}]}
{"op":"mcm","clk":"4234639147","pt":1631548215362,"mc":[{"id":"1.187560677","rc":[{"batb":[[1,1.04,2.97],[2,1.03,3.73]],"ltp":1.14,"tv":20556.06,"id":11439844}]}]}
{"op":"mcm","clk":"4234639363","pt":1631548217637,"mc":[{"id":"1.187560677","rc":[{"batb":[[1,1.05,2.23],[2,1.04,2.97]],"ltp":1.14,"tv":20556.06,"id":11439844}]}]}
{"op":"mcm","clk":"4234639500","pt":1631548219475,"mc":[{"id":"1.187560677","rc":[{"batb":[[0,1.06,2.22]],"ltp":1.14,"tv":20556.06,"id":11439844}]}]}
{"op":"mcm","clk":"4234639585","pt":1631548220467,"mc":[{"id":"1.187560677","rc":[{"batl":[[0,7.6,3.84],[1,8,97.62],[2,990,0.01]],"ltp":7.6,"tv":1108.01,"id":7588306},{"batb":[[0,1.14,35.08],[1,1.07,2.22],[2,1.06,2.22]],"batl":[[0,1.17,882.7],[1,1.39,17.9],[2,1.4,1040.75]],"ltp":1.14,"tv":20556.06,"id":11439844}]}]}
{"op":"mcm","clk":"4234639712","pt":1631548222041,"mc":[{"id":"1.187560677","rc":[{"batb":[[1,1.08,2.21],[2,1.07,2.22]],"ltp":1.14,"tv":20556.06,"id":11439844}]}]}
{"op":"mcm","clk":"4234639820","pt":1631548223661,"mc":[{"id":"1.187560677","rc":[{"batl":[[0,7.6,39.94]],"ltp":7.6,"tv":1108.01,"id":7588306},{"batb":[[2,1.07,909.46]],"ltp":1.14,"tv":20556.06,"id":11439844}]}]}
{"op":"mcm","clk":"4234640062","pt":1631548226703,"mc":[{"id":"1.187560677","rc":[{"batl":[[0,1.17,944.7]],"ltp":1.14,"tv":20556.06,"id":11439844}]}]}
{"op":"mcm","clk":"4234640104","pt":1631548227382,"mc":[{"id":"1.187560677","rc":[{"batb":[[0,6.8,2],[1,6.4,2],[2,1.6,767.39]],"batl":[[2,8.2,2]],"ltp":7.6,"tv":1108.01,"id":7588306},{"batb":[[0,1.14,212.9],[1,1.13,184.73],[2,1.08,2.21]],"batl":[[0,1.17,1097.2],[1,1.18,148.25],[2,1.39,17.9]],"ltp":1.14,"tv":20556.06,"id":11439844}]}]}
{"op":"mcm","clk":"4234640177","pt":1631548228480,"mc":[{"id":"1.187560677","rc":[{"batl":[[0,1.17,1035.2]],"ltp":1.14,"tv":20556.06,"id":11439844}]}]}
{"op":"mcm","clk":"4234640268","pt":1631548229588,"mc":[{"id":"1.187560677","rc":[{"batb":[[0,1.14,213.13]],"ltp":1.14,"tv":20556.06,"id":11439844}]}]}
{"op":"mcm","clk":"4234640331","pt":1631548230169,"mc":[{"id":"1.187560677","rc":[{"batb":[[2,1.08,2.4]],"ltp":1.14,"tv":20556.06,"id":11439844}]}]}
{"op":"mcm","clk":"4234640475","pt":1631548231592,"mc":[{"id":"1.187560677","rc":[{"batb":[[0,6.4,2],[1,1.6,767.39],[2,1.3,5]],"batl":[[0,7.6,36.1],[1,8.2,2],[2,8.8,2]],"ltp":7.6,"tv":1108.01,"id":7588306},{"batb":[[0,1.14,178.05],[2,1.08,2.65]],"batl":[[0,1.16,225]],"ltp":1.14,"tv":20556.06,"id":11439844}]}]}
{"op":"mcm","clk":"4234640590","pt":1631548232695,"mc":[{"id":"1.187560677","rc":[{"batb":[[2,1.08,3.08]],"batl":[[0,1.18,148.25],[1,1.39,17.9],[2,1.4,1040.75]],"ltp":1.14,"tv":20556.06,"id":11439844}]}]}
{"op":"mcm","clk":"4234640662","pt":1631548233484,"mc":[{"id":"1.187560677","rc":[{"batb":[[1,1.13,184.98]],"ltp":1.14,"tv":20556.06,"id":11439844}]}]}
{"op":"mcm","clk":"4234640762","pt":1631548234375,"mc":[{"id":"1.187560677","rc":[{"batb":[[0,6.8,2],[1,6.4,2],[2,1.6,767.39]],"ltp":7.6,"tv":1108.01,"id":7588306},{"batl":[[0,1.17,137.5],[1,1.18,148.25],[2,1.39,17.9]],"ltp":1.14,"tv":20556.06,"id":11439844}]}]}
{"op":"mcm","clk":"4234640932","pt":1631548236586,"mc":[{"id":"1.187560677","rc":[{"batb":[[0,6.4,2],[1,1.6,767.39],[2,1.3,5]],"ltp":7.6,"tv":1108.01,"id":7588306},{"batl":[[0,1.18,148.25],[1,1.39,17.9],[2,1.4,1040.75]],"ltp":1.14,"tv":20556.06,"id":11439844}]}]}
{"op":"mcm","clk":"4234641355","pt":1631548240621,"mc":[{"id":"1.187560677","rc":[{"batb":[[0,6.8,2],[1,6.4,2],[2,1.6,767.39]],"ltp":7.6,"tv":1108.01,"id":7588306},{"batl":[[0,1.17,144.5],[1,1.18,148.25],[2,1.39,17.9]],"ltp":1.14,"tv":20556.06,"id":11439844}]}]}
{"op":"mcm","clk":"4234641404","pt":1631548241248,"mc":[{"id":"1.187560677","rc":[{"batb":[[0,6.4,2],[1,1.6,767.39],[2,1.3,5]],"batl":[[0,6.8,17.26],[1,7.6,36.1],[2,8.2,2]],"ltp":7.6,"tv":1108.01,"id":7588306},{"batl":[[0,1.18,148.25],[1,1.39,17.9],[2,1.4,1040.75]],"ltp":1.14,"tv":20556.06,"id":11439844}]}]}
{"op":"mcm","clk":"4234641672","pt":1631548244554,"mc":[{"id":"1.187560677","rc":[{"trd":[[6.8,17.6]],"batl":[[0,7.6,36.1],[1,8.2,2],[2,8.8,2]],"ltp":6.8,"tv":1125.27,"id":7588306},{"trd":[[1.17,102.34]],"ltp":1.17,"tv":20656.39,"id":11439844}],"tv":21781.67}]}
{"op":"mcm","clk":"4234641828","pt":1631548246699,"mc":[{"id":"1.187560677","rc":[{"trd":[[1.18,168.43]],"batl":[[0,1.39,17.9],[1,1.4,1040.75],[2,1.94,3.08]],"ltp":1.18,"tv":20658.39,"id":11439844}],"tv":21783.67}]}
{"op":"mcm","clk":"4234641925","pt":1631548248065,"mc":[{"id":"1.187560677","rc":[{"batl":[[0,8.8,2],[1,990,0.01],[2,8.8,0]],"ltp":6.8,"tv":1125.27,"id":7588306},{"batb":[[0,1.13,185.21],[1,1.08,3.08],[2,1.07,2.22]],"ltp":1.18,"tv":20658.39,"id":11439844}]}]}
{"op":"mcm","clk":"4234642011","pt":1631548249176,"mc":[{"id":"1.187560677","rc":[{"trd":[[1.14,71.44]],"batb":[[0,1.13,206.98],[1,1.12,865.83],[2,1.08,2.87]],"batl":[[0,1.14,31.43],[1,1.15,1280.67],[2,1.16,34.48]],"ltp":1.14,"tv":20658.85,"id":11439844}],"tv":21784.13}]}
{"op":"mcm","clk":"4234642257","pt":1631548252098,"mc":[{"id":"1.187560677","rc":[{"trd":[[1.14,134.3]],"batl":[[0,1.15,1280.67],[1,1.16,34.48],[2,1.39,17.9]],"ltp":1.14,"tv":20721.71,"id":11439844}],"tv":21846.99}]}
{"op":"mcm","clk":"4234642554","pt":1631548255184,"mc":[{"id":"1.187560677","rc":[{"batl":[[0,1.14,180],[1,1.15,1280.67],[2,1.16,34.48]],"ltp":1.14,"tv":20721.71,"id":11439844}]}]}
{"op":"mcm","clk":"4234642654","pt":1631548256174,"mc":[{"id":"1.187560677","rc":[{"batb":[[0,7.2,4.92],[1,6.8,5.08],[2,6.4,2]],"batl":[[1,10.5,2],[2,12.5,2]],"ltp":6.8,"tv":1125.27,"id":7588306},{"batb":[[2,1.11,237.81]],"batl":[[2,1.16,205.67]],"ltp":1.14,"tv":20721.71,"id":11439844}]}]}
{"op":"mcm","clk":"4234642941","pt":1631548259375,"mc":[{"id":"1.187560677","rc":[{"batl":[[2,11,2]],"ltp":6.8,"tv":1125.27,"id":7588306},{"batb":[[0,1.13,184.98]],"ltp":1.14,"tv":20721.71,"id":11439844}]}]}
{"op":"mcm","clk":"4234643463","pt":1631548265199,"mc":[{"id":"1.187560677","rc":[{"batl":[[0,8.6,5.91],[1,8.8,2],[2,10.5,2]],"ltp":6.8,"tv":1125.27,"id":7588306},{"batl":[[1,1.15,1327.42]],"ltp":1.14,"tv":20721.71,"id":11439844}]}]}
{"op":"mcm","clk":"4234643548","pt":1631548266304,"mc":[{"id":"1.187560677","rc":[{"batl":[[1,1.15,1327.64]],"ltp":1.14,"tv":20721.71,"id":11439844}]}]}
{"op":"mcm","clk":"4234644091","pt":1631548273421,"mc":[{"id":"1.187560677","rc":[{"batb":[[2,1.6,767.39]],"batl":[[0,13.5,2],[1,990,0.01],[2,10.5,0]],"ltp":6.8,"tv":1125.27,"id":7588306},{"batb":[[0,1.09,1.12],[1,1.08,2.21],[2,1.07,2.22]],"batl":[[1,1.16,171.41],[2,1.17,6.03]],"ltp":1.14,"tv":20721.71,"id":11439844}]}]}
{"op":"mcm","clk":"4234644172","pt":1631548274514,"mc":[{"id":"1.187560677","rc":[{"trd":[[8,23.88]],"batb":[[0,6.8,5.08],[1,1.6,767.39],[2,1.3,5]],"ltp":8.0,"tv":1143.32,"id":7588306},{"trd":[[1.14,260.96]],"batl":[[0,1.17,6.25],[1,1.39,17.9],[2,1.4,1040.75]],"ltp":1.14,"tv":20848.37,"id":11439844}],"tv":21991.7}]}
{"op":"mcm","clk":"4234644192","pt":1631548274725,"mc":[{"id":"1.187560677","rc":[{"batb":[[0,6.8,2]],"ltp":8.0,"tv":1143.32,"id":7588306},{"batl":[[0,1.39,18.11],[1,1.4,1040.75],[2,1.94,3.08]],"ltp":1.14,"tv":20848.37,"id":11439844}]}]}
{"op":"mcm","clk":"4234644314","pt":1631548276307,"mc":[{"id":"1.187560677","rc":[{"batl":[[0,1.17,167.72],[1,1.39,17.9],[2,1.4,1040.75]],"ltp":1.14,"tv":20848.37,"id":11439844}]}]}
{"op":"mcm","clk":"4234644363","pt":1631548276935,"mc":[{"id":"1.187560677","rc":[{"batb":[[1,1.08,299.52]],"ltp":1.14,"tv":20848.37,"id":11439844}]}]}
{"op":"mcm","clk":"4234645008","pt":1631548284524,"mc":[{"id":"1.187560677","rc":[{"batb":[[0,7.2,3.12],[1,6.8,2],[2,1.6,767.39]],"ltp":8.0,"tv":1143.32,"id":7588306},{"batl":[[0,1.16,6.94],[1,1.17,167.5],[2,1.39,17.9]],"ltp":1.14,"tv":20848.37,"id":11439844}]}]}
{"op":"mcm","clk":"4234645103","pt":1631548285624,"mc":[{"id":"1.187560677","rc":[{"batb":[[0,7.2,2],[1,6.8,5.18]],"ltp":8.0,"tv":1143.32,"id":7588306},{"batl":[[0,1.16,148.19],[1,1.17,173.59]],"ltp":1.14,"tv":20848.37,"id":11439844}]}]}
{"op":"mcm","clk":"4234645128","pt":1631548285946,"mc":[{"id":"1.187560677","rc":[{"batb":[[0,6.8,2],[1,1.6,767.39],[2,1.3,5]],"ltp":8.0,"tv":1143.32,"id":7588306},{"batl":[[0,1.17,167.72],[1,1.39,17.9],[2,1.4,1040.75]],"ltp":1.14,"tv":20848.37,"id":11439844}]}]}
{"op":"mcm","clk":"4234645279","pt":1631548287356,"mc":[{"id":"1.187560677","rc":[{"batl":[[0,11,2],[1,13.5,2],[2,990,0.01]],"ltp":8.0,"tv":1143.32,"id":7588306},{"batb":[[0,1.1,252.66],[1,1.09,267.8],[2,1.08,299.52]],"ltp":1.14,"tv":20848.37,"id":11439844}]}]}
{"op":"mcm","clk":"4234645344","pt":1631548288346,"mc":[{"id":"1.187560677","rc":[{"batl":[[0,13.5,2],[1,990,0.01],[2,990,0]],"ltp":8.0,"tv":1143.32,"id":7588306},{"batb":[[0,1.09,1.12],[1,1.08,299.52],[2,1.07,2.22]],"ltp":1.14,"tv":20848.37,"id":11439844}]}]}
{"op":"mcm","clk":"4234645444","pt":1631548289659,"mc":[{"id":"1.187560677","rc":[{"batl":[[0,1.39,18.11],[1,1.4,1040.75],[2,1.94,3.08]],"ltp":1.14,"tv":20848.37,"id":11439844}]}]}
{"op":"mcm","clk":"4234645629","pt":1631548291542,"mc":[{"id":"1.187560677","rc":[{"batb":[[0,7.2,3.22],[1,6.8,2],[2,1.6,767.39]],"batl":[[0,11,2],[1,13.5,2],[2,990,0.01]],"ltp":8.0,"tv":1143.32,"id":7588306},{"batb":[[0,1.1,254.76],[1,1.09,307.8],[2,1.08,299.52]],"batl":[[0,1.16,6.19],[1,1.39,17.9],[2,1.4,1040.75]],"ltp":1.14,"tv":20848.37,"id":11439844}]}]}
{"op":"mcm","clk":"4234645665","pt":1631548292055,"mc":[{"id":"1.187560677","rc":[{"batb":[[0,9.2,2.07],[1,8.6,4.66],[2,6.8,2]],"batl":[[0,11,5.91],[1,12,133.44],[2,13.5,2]],"ltp":8.0,"tv":1143.32,"id":7588306},{"trd":[[1.12,4.42],[1.13,27.21]],"batb":[[0,1.1,293.41]],"batl":[[0,1.12,1391.35],[1,1.39,18.11]],"ltp":1.12,"tv":20849.29,"id":11439844}],"tv":21992.61}]}
{"op":"mcm","clk":"4234646187","pt":1631548298660,"mc":[{"id":"1.187560677","rc":[{"batb":[[2,8,2]],"ltp":8.0,"tv":1143.32,"id":7588306},{"trd":[[1.11,0.44]],"batb":[[0,1.1,293.19]],"batl":[[0,1.11,273.78],[1,1.12,1391.35],[2,1.14,169.75]],"ltp":1.11,"tv":20849.73,"id":11439844}],"tv":21993.06}]}
{"op":"mcm","clk":"4234646199","pt":1631548298770,"mc":[{"id":"1.187560677","rc":[{"batb":[[2,8,4.83]],"ltp":8.0,"tv":1143.32,"id":7588306},{"batl":[[2,1.14,176.5]],"ltp":1.11,"tv":20849.73,"id":11439844}]}]}
{"op":"mcm","clk":"4234646395","pt":1631548301215,"mc":[{"id":"1.187560677","rc":[{"trd":[[1.11,7.4]],"batl":[[0,1.11,270.3]],"ltp":1.11,"tv":20856.69,"id":11439844}],"tv":22000.02}]}
{"op":"mcm","clk":"4234646611","pt":1631548304637,"mc":[{"id":"1.187560677","rc":[{"trd":[[11,5.91],[12,133.44]],"batl":[[0,13.5,2],[1,15.5,2],[2,18,2]],"ltp":12.0,"tv":1282.67,"id":7588306},{"trd":[[1.09,2084.68],[1.1,645.47]],"batb":[[0,1.08,299.52],[1,1.07,421.29],[2,1.06,393.8]],"batl":[[0,1.09,343.55],[1,1.11,270.3],[2,1.12,1391.35]],"ltp":1.09,"tv":23586.84,"id":11439844}],"tv":24869.52}]}
{"op":"mcm","clk":"4234646851","pt":1631548307648,"mc":[{"id":"1.187560677","rc":[{"trd":[[1.09,2129.76]],"batl":[[0,1.09,321.02]],"ltp":1.09,"tv":23631.92,"id":11439844}],"tv":24914.59}]}
{"op":"mcm","clk":"4234646971","pt":1631548309408,"mc":[{"id":"1.187560677","rc":[{"batl":[[0,1.11,270.3],[1,1.12,1391.35],[2,1.14,176.93]],"ltp":1.09,"tv":23631.92,"id":11439844}]}]}
{"op":"mcm","clk":"4234647202","pt":1631548312521,"mc":[{"id":"1.187560677","rc":[{"batl":[[0,13.5,45.11],[1,15.5,51.27]],"ltp":12.0,"tv":1282.67,"id":7588306},{"batb":[[0,1.08,838.4],[1,1.07,1134.96]],"batl":[[0,1.1,321.02],[1,1.11,270.3],[2,1.12,1391.35]],"ltp":1.09,"tv":23631.92,"id":11439844}]}]}
{"op":"mcm","clk":"4234647260","pt":1631548313250,"mc":[{"id":"1.187560677","rc":[{"batb":[[0,10,47.79],[1,9.2,59.88],[2,8.6,4.66]],"ltp":12.0,"tv":1282.67,"id":7588306},{"batl":[[1,1.11,700.89],[2,1.12,1866.28]],"ltp":1.09,"tv":23631.92,"id":11439844}]}]}
{"op":"mcm","clk":"4234647359","pt":1631548314342,"mc":[{"id":"1.187560677","rc":[{"batb":[[0,11,45.7],[1,10,103.82],[2,9.2,59.88]],"ltp":12.0,"tv":1282.67,"id":7588306},{"batl":[[0,1.1,778.04],[1,1.11,1205.67],[2,1.12,1811.62]],"ltp":1.09,"tv":23631.92,"id":11439844}]}]}
{"op":"mcm","clk":"4234647582","pt":1631548317255,"mc":[{"id":"1.187560677","rc":[{"batl":[[0,12,7.18],[1,13.5,45.11],[2,15.5,51.27]],"ltp":12.0,"tv":1282.67,"id":7588306},{"batl":[[1,1.11,1277.46]],"ltp":1.09,"tv":23631.92,"id":11439844}]}]}
{"op":"mcm","clk":"4234647746","pt":1631548319551,"mc":[{"id":"1.187560677","rc":[{"batl":[[0,13.5,45.11],[1,15.5,51.27],[2,18,2]],"ltp":12.0,"tv":1282.67,"id":7588306},{"batl":[[1,1.11,1205.67],[2,1.12,480.64]],"ltp":1.09,"tv":23631.92,"id":11439844}]}]}
{"op":"mcm","clk":"4234647840","pt":1631548320644,"mc":[{"id":"1.187560677","rc":[{"batb":[[0,8,4.83],[1,7.6,4.99],[2,7.2,5.69]],"batl":[[0,26,2],[1,990,0.01],[2,18,0]],"ltp":12.0,"tv":1282.67,"id":7588306},{"batb":[[0,1.08,2.21],[1,1.07,2.22],[2,1.06,2.22]],"batl":[[0,1.1,321.02],[1,1.11,270.3],[2,1.14,176.93]],"ltp":1.09,"tv":23631.92,"id":11439844}]}]}
{"op":"mcm","clk":"4234647972","pt":1631548322250,"mc":[{"id":"1.187560677","rc":[{"batl":[[1,1.14,176.93],[2,1.15,168.82]],"ltp":1.09,"tv":23631.92,"id":11439844}]}]}
{"op":"mcm","clk":"4234648066","pt":1631548323347,"mc":[{"id":"1.187560677","rc":[{"batl":[[1,1.14,177.16]],"ltp":1.09,"tv":23631.92,"id":11439844}]}]}
{"op":"mcm","clk":"4234648134","pt":1631548324188,"mc":[{"id":"1.187560677","rc":[{"batl":[[0,1.1,321.2]],"ltp":1.09,"tv":23631.92,"id":11439844}]}]}
{"op":"mcm","clk":"4234648264","pt":1631548325739,"mc":[{"id":"1.187560677","rc":[{"trd":[[1.1,649.47]],"batl":[[0,1.1,319.19]],"ltp":1.1,"tv":23635.92,"id":11439844}],"tv":24918.6}]}
{"op":"mcm","clk":"4234648353","pt":1631548327149,"mc":[{"id":"1.187560677","rc":[{"batb":[[0,8,2.83],[1,7.6,2.99]],"ltp":12.0,"tv":1282.67,"id":7588306},{"batl":[[1,1.14,7.41],[2,1.15,6.12]],"ltp":1.1,"tv":23635.92,"id":11439844}]}]}
{"op":"mcm","clk":"4234648546","pt":1631548329540,"mc":[{"id":"1.187560677","rc":[{"batb":[[0,13.5,12.39],[1,11.5,17.4],[2,8,2.83]],"batl":[[0,17.5,8.3],[1,21,114.64],[2,26,2]],"ltp":12.0,"tv":1282.67,"id":7588306},{"trd":[[1.08,4.42]],"batb":[[0,1.07,2.22],[1,1.06,2.22],[2,1.05,2295.12]],"batl":[[0,1.08,359.83],[1,1.1,319.19],[2,1.11,4923.37]],"ltp":1.08,"tv":23640.34,"id":11439844}],"tv":24923.02}]}
{"op":"mcm","clk":"4234648622","pt":1631548330474,"mc":[{"id":"1.187560677","rc":[{"batb":[[1,11.5,3.48]],"ltp":12.0,"tv":1282.67,"id":7588306}]}]}
{"op":"mcm","clk":"4234648782","pt":1631548332663,"mc":[{"id":"1.187560677","rc":[{"batl":[[0,1.08,459.83]],"ltp":1.08,"tv":23640.34,"id":11439844}]}]}
{"op":"mcm","clk":"4234648927","pt":1631548334277,"mc":[{"id":"1.187560677","rc":[{"batl":[[0,1.08,582.83]],"ltp":1.08,"tv":23640.34,"id":11439844}]}]}
{"op":"mcm","clk":"4234649051","pt":1631548335583,"mc":[{"id":"1.187560677","rc":[{"batl":[[1,1.09,2.21],[2,1.1,319.19]],"ltp":1.08,"tv":23640.34,"id":11439844}]}]}
{"op":"mcm","clk":"4234649186","pt":1631548337043,"mc":[{"id":"1.187560677","rc":[{"trd":[[13.5,1.8]],"batb":[[0,13.5,11.49],[2,10,2.24]],"ltp":13.5,"tv":1284.47,"id":7588306}],"tv":24924.82}]}
{"op":"mcm","clk":"4234649389","pt":1631548339652,"mc":[{"id":"1.187560677","rc":[{"batb":[[0,13.5,8.66]],"batl":[[0,21,114.64],[1,26,2],[2,990,0.01]],"ltp":13.5,"tv":1284.47,"id":7588306},{"batl":[[0,1.08,538.44]],"ltp":1.08,"tv":23640.34,"id":11439844}]}]}
{"op":"mcm","clk":"4234649603","pt":1631548342583,"mc":[{"id":"1.187560677","rc":[{"batl":[[0,17.5,9.13],[1,21,114.64],[2,26,2]],"ltp":13.5,"tv":1284.47,"id":7588306},{"batl":[[0,1.08,578.31]],"ltp":1.08,"tv":23640.34,"id":11439844}]}]}
{"op":"mcm","clk":"4234649984","pt":1631548347184,"mc":[{"id":"1.187560677","rc":[{"batl":[[0,21,114.64],[1,26,2],[2,990,0.01]],"ltp":13.5,"tv":1284.47,"id":7588306},{"batl":[[0,1.08,538.44]],"ltp":1.08,"tv":23640.34,"id":11439844}]}]}
{"op":"mcm","clk":"4234650229","pt":1631548350159,"mc":[{"id":"1.187560677","rc":[{"batl":[[0,17.5,9.13],[1,21,114.64],[2,26,2]],"ltp":13.5,"tv":1284.47,"id":7588306},{"trd":[[1.07,4.14]],"batb":[[0,1.06,2.37],[1,1.05,2295.12],[2,1.04,2.97]],"batl":[[0,1.08,578.31]],"ltp":1.07,"tv":23644.48,"id":11439844}],"tv":24928.96}]}
{"op":"mcm","clk":"4234650351","pt":1631548351574,"mc":[{"id":"1.187560677","rc":[{"batb":[[1,10,2.24],[2,8.6,2.19]],"batl":[[0,26,2],[1,990,0.01],[2,26,0]],"ltp":13.5,"tv":1284.47,"id":7588306},{"batb":[[1,1.05,2.23]],"batl":[[0,1.08,538.44]],"ltp":1.07,"tv":23644.48,"id":11439844}]}]}
{"op":"mcm","clk":"4234650418","pt":1631548352404,"mc":[{"id":"1.187560677","rc":[{"batb":[[0,10,2.24],[1,8.6,2.19],[2,8,2.83]],"batl":[[0,990,0.01],[1,990,0]],"ltp":13.5,"tv":1284.47,"id":7588306},{"batl":[[0,1.08,100]],"ltp":1.07,"tv":23644.48,"id":11439844}]}]}
{"op":"mcm","clk":"4234650984","pt":1631548358473,"mc":[{"id":"1.187560677","rc":[{"trd":[[13.5,5.77]],"batb":[[0,11,100.78],[1,10,2.24],[2,8.6,2.19]],"batl":[[0,15,154.19],[1,990,0.01]],"ltp":13.5,"tv":1288.44,"id":7588306},{"trd":[[1.08,153.25]],"batb":[[0,1.07,187.06],[1,1.06,2.22],[2,1.05,2.23]],"batl":[[0,1.09,2.98],[1,1.1,1327.05],[2,1.11,222.73]],"ltp":1.08,"tv":23793.31,"id":11439844}],"tv":25081.76}]}
{"op":"mcm","clk":"4234651038","pt":1631548359409,"mc":[{"id":"1.187560677","rc":[{"batb":[[0,1.07,37.52]],"ltp":1.08,"tv":23793.31,"id":11439844}]}]}
{"op":"mcm","clk":"4234651803","pt":1631548368588,"mc":[{"id":"1.187560677","rc":[{"batb":[[0,11,96.89]],"ltp":13.5,"tv":1288.44,"id":7588306},{"batl":[[1,1.1,1288.13]],"ltp":1.08,"tv":23793.31,"id":11439844}]}]}
{"op":"mcm","clk":"4234652040","pt":1631548371596,"mc":[{"id":"1.187560677","rc":[{"batl":[[0,15,161.7]],"ltp":13.5,"tv":1288.44,"id":7588306},{"batl":[[0,1.09,100.42]],"ltp":1.08,"tv":23793.31,"id":11439844}]}]}
{"op":"mcm","clk":"4234652570","pt":1631548378293,"mc":[{"id":"1.187560677","rc":[{"trd":[[1.07,24.15]],"batb":[[0,1.07,27.52]],"ltp":1.07,"tv":23813.32,"id":11439844}],"tv":25101.76}]}
{"op":"mcm","clk":"4234652682","pt":1631548379601,"mc":[{"id":"1.187560677","rc":[{"batb":[[0,8,5.28],[1,7.6,2.99],[2,7.2,5.69]],"batl":[[0,990,0.01],[1,990,0]],"ltp":13.5,"tv":1288.44,"id":7588306},{"batb":[[0,1.06,2.22],[1,1.05,2.23],[2,1.04,2.97]],"batl":[[0,1.09,2.98],[1,1.1,319.19],[2,1.14,193.16]],"ltp":1.07,"tv":23813.32,"id":11439844}]}]}
{"op":"mcm","clk":"4234652833","pt":1631548381541,"mc":[{"id":"1.187560677","rc":[{"trd":[[1.08,153.43]],"batl":[[0,1.09,2.89]],"ltp":1.08,"tv":23813.5,"id":11439844}],"tv":25101.95}]}
{"op":"mcm","clk":"4234653098","pt":1631548385139,"mc":[{"id":"1.187560677","rc":[{"batb":[[1,7.8,2.43],[2,7.6,2.99]],"ltp":13.5,"tv":1288.44,"id":7588306},{"batl":[[0,1.08,2.9],[1,1.09,2.21],[2,1.1,319.19]],"ltp":1.08,"tv":23813.5,"id":11439844}]}]}
{"op":"mcm","clk":"4234653265","pt":1631548387543,"mc":[{"id":"1.187560677","rc":[{"trd":[[10,6.81],[11,37.83],[12,133.64],[13.5,6]],"batl":[[0,11,69.58],[1,11.5,3.48],[2,990,0.01]],"ltp":10.0,"tv":1327.6,"id":7588306},{"trd":[[1.08,156.33],[1.09,2131.97],[1.1,968.67],[1.11,7.63]],"batb":[[0,1.1,635],[1,1.06,2.22],[2,1.05,2.23]],"batl":[[0,1.13,1424.01],[1,1.14,192.74],[2,1.15,189.42]],"ltp":1.11,"tv":24138.03,"id":11439844}],"tv":25465.64}]}
{"op":"mcm","clk":"4234653394","pt":1631548389258,"mc":[{"id":"1.187560677","rc":[{"batb":[[2,1.05,1087.66]],"ltp":1.11,"tv":24138.03,"id":11439844}]}]}
{"op":"mcm","clk":"4234653763","pt":1631548394604,"mc":[{"id":"1.187560677","rc":[{"batb":[[2,7.6,6.23]],"ltp":10.0,"tv":1327.6,"id":7588306}]}]}
{"op":"mcm","clk":"4234653920","pt":1631548397070,"mc":[{"id":"1.187560677","rc":[{"batl":[[0,11,63.5]],"ltp":10.0,"tv":1327.6,"id":7588306}]}]}
{"op":"mcm","clk":"4234654033","pt":1631548398673,"mc":[{"id":"1.187560677","rc":[{"batb":[[1,1.07,2.51],[2,1.06,2.22]],"ltp":1.11,"tv":24138.03,"id":11439844}]}]}
{"op":"mcm","clk":"4234654113","pt":1631548399966,"mc":[{"id":"1.187560677","rc":[{"batl":[[0,11,68.09]],"ltp":10.0,"tv":1327.6,"id":7588306},{"batb":[[0,1.1,680.85],[1,1.08,2.45],[2,1.07,2.51]],"batl":[[0,1.12,61.07],[1,1.13,1424.01],[2,1.14,192.74]],"ltp":1.11,"tv":24138.03,"id":11439844}]}]}
{"op":"mcm","clk":"4234654637","pt":1631548407623,"mc":[{"id":"1.187560677","rc":[{"batl":[[0,990,0.01],[1,11.5,0],[2,990,0]],"ltp":10.0,"tv":1327.6,"id":7588306},{"batb":[[0,1.08,2.45],[1,1.07,2.51],[2,1.06,4.4]],"batl":[[0,1.14,192.93],[1,1.15,189.42],[2,1.16,166.94]],"ltp":1.11,"tv":24138.03,"id":11439844}]}]}
{"op":"mcm","clk":"4234654708","pt":1631548408665,"mc":[{"id":"1.187560677","rc":[{"batb":[[0,7.6,3.24],[1,7.2,3.02],[2,1.6,767.39]],"ltp":10.0,"tv":1327.6,"id":7588306},{"batb":[[0,1.08,2.9],[2,1.06,2.22]],"batl":[[0,1.15,183.95],[1,1.16,6.72],[2,1.23,29.83]],"ltp":1.11,"tv":24138.03,"id":11439844}]}]}
{"op":"mcm","clk":"4234655089","pt":1631548414606,"mc":[{"id":"1.187560677","rc":[{"batb":[[0,8,2.95],[1,7.6,3.24],[2,7.2,6.54]],"ltp":10.0,"tv":1327.6,"id":7588306},{"batl":[[0,1.14,209.18],[1,1.15,183.52],[2,1.16,6.72]],"ltp":1.11,"tv":24138.03,"id":11439844}]}]}
{"op":"mcm","clk":"4234655158","pt":1631548415489,"mc":[{"id":"1.187560677","rc":[{"batb":[[0,7.6,3.24],[1,7.2,3.02],[2,1.6,767.39]],"ltp":10.0,"tv":1327.6,"id":7588306},{"batl":[[0,1.15,183.95],[1,1.16,6.72],[2,1.23,29.83]],"ltp":1.11,"tv":24138.03,"id":11439844}]}]}
{"op":"mcm","clk":"4234655308","pt":1631548417571,"mc":[{"id":"1.187560677","rc":[{"batl":[[1,1.16,195.44]],"ltp":1.11,"tv":24138.03,"id":11439844}]}]}
{"op":"mcm","clk":"4234655371","pt":1631548418506,"mc":[{"id":"1.187560677","rc":[{"batl":[[1,1.16,6.72]],"ltp":1.11,"tv":24138.03,"id":11439844}]}]}
{"op":"mcm","clk":"4234655624","pt":1631548421696,"mc":[{"id":"1.187560677","rc":[{"batb":[[0,8,3.47],[1,7.6,3.24],[2,7.2,3.02]],"ltp":10.0,"tv":1327.6,"id":7588306},{"batl":[[0,1.14,211.68],[1,1.15,183.52],[2,1.16,6.72]],"ltp":1.11,"tv":24138.03,"id":11439844}]}]}
{"op":"mcm","clk":"4234655644","pt":1631548422011,"mc":[{"id":"1.187560677","rc":[{"batb":[[0,7.6,3.24],[1,7.2,3.02],[2,1.6,767.39]],"ltp":10.0,"tv":1327.6,"id":7588306},{"batl":[[0,1.15,183.95],[1,1.16,6.72],[2,1.23,29.83]],"ltp":1.11,"tv":24138.03,"id":11439844}]}]}
{"op":"mcm","clk":"4234656081","pt":1631548427689,"mc":[{"id":"1.187560677","rc":[{"batb":[[1,1.6,767.39],[2,1.3,5]],"ltp":10.0,"tv":1327.6,"id":7588306},{"batl":[[0,1.23,30.48],[1,1.25,14.92],[2,1.38,987.41]],"ltp":1.11,"tv":24138.03,"id":11439844}]}]}
{"op":"mcm","clk":"4234656266","pt":1631548430395,"mc":[{"id":"1.187560677","rc":[{"batb":[[0,12,9.8],[1,7.6,3.24],[2,1.6,767.39]],"batl":[[0,15,120.76],[1,990,0.01]],"ltp":10.0,"tv":1327.6,"id":7588306},{"trd":[[1.09,2132.35],[1.1,969.17]],"batb":[[0,1.08,2.45]],"batl":[[0,1.09,445.28],[1,1.12,4534.09],[2,1.23,30.48]],"ltp":1.09,"tv":24138.92,"id":11439844}],"tv":25466.53}]}
{"op":"mcm","clk":"4234656388","pt":1631548432694,"mc":[{"id":"1.187560677","rc":[{"batb":[[1,1.07,140.36]],"ltp":1.09,"tv":24138.92,"id":11439844}]}]}
{"op":"mcm","clk":"4234656649","pt":1631548436227,"mc":[{"id":"1.187560677","rc":[{"trd":[[1.08,161.24]],"batb":[[0,1.07,140.36],[1,1.06,2.22],[2,1.05,2.23]],"batl":[[0,1.08,1.44],[1,1.09,445.28],[2,1.12,4534.09]],"ltp":1.08,"tv":24143.83,"id":11439844}],"tv":25471.43}]}
{"op":"mcm","clk":"4234656712","pt":1631548437111,"mc":[{"id":"1.187560677","rc":[{"batb":[[1,9.2,2.67],[2,8.6,2.59]],"ltp":10.0,"tv":1327.6,"id":7588306},{"batl":[[2,1.12,4746.3]],"ltp":1.08,"tv":24143.83,"id":11439844}]}]}
{"op":"mcm","clk":"4234657453","pt":1631548447650,"mc":[{"id":"1.187560677","rc":[{"batl":[[2,1.12,4746.55]],"ltp":1.08,"tv":24143.83,"id":11439844}]}]}
{"op":"mcm","clk":"4234657525","pt":1631548448542,"mc":[{"id":"1.187560677","rc":[{"batl":[[1,1.09,447.66],[2,1.12,4746.75]],"ltp":1.08,"tv":24143.83,"id":11439844}]}]}
{"op":"mcm","clk":"4234657572","pt":1631548449061,"mc":[{"id":"1.187560677","rc":[{"batb":[[0,9.2,2.67],[1,8.6,2.59],[2,8,2.33]],"batl":[[0,990,0.01],[1,990,0]],"ltp":10.0,"tv":1327.6,"id":7588306},{"batl":[[1,1.09,2.38],[2,1.12,212.66]],"ltp":1.08,"tv":24143.83,"id":11439844}]}]}
{"op":"mcm","clk":"4234658796","pt":1631548461432,"mc":[{"id":"1.187560677","rc":[{"trd":[[11,37.85],[12,133.86],[13.5,6.12]],"batb":[[0,8.6,2.59],[1,8,2.33],[2,1.6,767.39]],"batl":[[0,11,7.28],[1,12,238.74],[2,990,0.01]],"ltp":11.0,"tv":1327.96,"id":7588306},{"trd":[[1.08,162.68],[1.09,2134.73],[1.1,969.37]],"batb":[[0,1.1,36.38],[1,1.07,140.36],[2,1.06,2.22]],"batl":[[0,1.12,77.42],[1,1.13,1914.14],[2,1.14,184.49]],"ltp":1.1,"tv":24147.85,"id":11439844}],"tv":25475.82}]}
{"op":"mcm","clk":"4234659117","pt":1631548465042,"mc":[{"id":"1.187560677","rc":[{"batb":[[0,8,2.33],[1,1.6,767.39],[2,1.3,5]],"ltp":11.0,"tv":1327.96,"id":7588306},{"batl":[[1,1.13,1731.64]],"ltp":1.1,"tv":24147.85,"id":11439844}]}]}
{"op":"mcm","clk":"4234659353","pt":1631548468157,"mc":[{"id":"1.187560677","rc":[{"batb":[[1,7.2,2.87],[2,1.6,767.39]],"ltp":11.0,"tv":1327.96,"id":7588306},{"batb":[[1,1.08,2.64],[2,1.07,140.36]],"ltp":1.1,"tv":24147.85,"id":11439844}]}]}
{"op":"mcm","clk":"4234659460","pt":1631548469563,"mc":[{"id":"1.187560677","rc":[{"trd":[[1.11,8.14]],"batb":[[0,1.11,9.93],[1,1.1,36.38],[2,1.08,2.64]],"batl":[[0,1.12,77.17]],"ltp":1.11,"tv":24148.35,"id":11439844}],"tv":25476.32}]}
{"op":"mcm","clk":"4234659674","pt":1631548472687,"mc":[{"id":"1.187560677","rc":[{"trd":[[1.11,28]],"batb":[[0,1.1,36.38],[1,1.08,2.64],[2,1.07,140.36]],"ltp":1.11,"tv":24168.21,"id":11439844}],"tv":25496.18}]}
{"op":"mcm","clk":"4234659917","pt":1631548475668,"mc":[{"id":"1.187560677","rc":[{"batb":[[1,1.08,2.85]],"ltp":1.11,"tv":24168.21,"id":11439844}]}]}
{"op":"mcm","clk":"4234660238","pt":1631548479498,"mc":[{"id":"1.187560677","rc":[{"batb":[[0,7.2,2.87],[1,1.6,767.39],[2,1.3,5]],"batl":[[0,990,0.01],[1,12,0],[2,990,0]],"ltp":11.0,"tv":1327.96,"id":7588306},{"batb":[[0,1.08,2.85],[1,1.07,140.36],[2,1.06,2.22]],"batl":[[0,1.16,158.87],[1,1.23,29.83],[2,1.25,14.92]],"ltp":1.11,"tv":24168.21,"id":11439844}]}]}
{"op":"mcm","clk":"4234660478","pt":1631548482700,"mc":[{"id":"1.187560677","rc":[{"batb":[[0,1.08,3.13]],"ltp":1.11,"tv":24168.21,"id":11439844}]}]}
{"op":"mcm","clk":"4234660777","pt":1631548486568,"mc":[{"id":"1.187560677","rc":[{"batl":[[0,9.2,542.69],[1,11,2.09],[2,990,0.01]],"ltp":11.0,"tv":1327.96,"id":7588306},{"batb":[[0,1.12,999.28],[1,1.08,3.13],[2,1.07,140.36]],"batl":[[0,1.14,57.42],[1,1.15,1319.34],[2,1.16,158.22]],"ltp":1.11,"tv":24168.21,"id":11439844}]}]}
{"op":"mcm","clk":"4234660829","pt":1631548487093,"mc":[{"id":"1.187560677","rc":[{"batl":[[0,9.2,10.97],[1,990,0.01],[2,990,0]],"ltp":11.0,"tv":1327.96,"id":7588306}]}]}
{"op":"mcm","clk":"4234661416","pt":1631548494083,"mc":[{"id":"1.187560677","rc":[{"batb":[[0,8,3.33],[1,7.2,2.87],[2,1.6,767.39]],"batl":[[1,11,2],[2,12.5,2]],"ltp":11.0,"tv":1327.96,"id":7588306},{"batb":[[1,1.1,228.11],[2,1.09,257.82]],"batl":[[0,1.14,257.17]],"ltp":1.11,"tv":24168.21,"id":11439844}]}]}
{"op":"mcm","clk":"4234661715","pt":1631548497416,"mc":[{"id":"1.187560677","rc":[{"batb":[[1,7.6,3.24],[2,7.2,2.87]],"ltp":11.0,"tv":1327.96,"id":7588306},{"batl":[[1,1.15,1511.84]],"ltp":1.11,"tv":24168.21,"id":11439844}]}]}
{"op":"mcm","clk":"4234662123","pt":1631548502396,"mc":[{"id":"1.187560677","rc":[{"batb":[[0,7.6,3.24],[1,1.6,767.39],[2,1.3,5]],"batl":[[0,12.5,2],[1,990,0.01],[2,12.5,0]],"ltp":11.0,"tv":1327.96,"id":7588306},{"batb":[[0,1.09,258.09],[1,1.08,2.64],[2,1.07,140.36]],"batl":[[0,1.15,193.15],[1,1.23,29.83],[2,1.25,14.92]],"ltp":1.11,"tv":24168.21,"id":11439844}]}]}
{"op":"mcm","clk":"4234662419","pt":1631548505694,"mc":[{"id":"1.187560677","rc":[{"batb":[[0,8,3.2],[1,7.6,3.24],[2,1.6,767.39]],"batl":[[0,11,2],[1,12.5,2],[2,990,0.01]],"ltp":11.0,"tv":1327.96,"id":7588306},{"batb":[[0,1.1,266.71],[1,1.09,257.82],[2,1.08,2.64]],"batl":[[0,1.14,202.68],[1,1.15,192.72],[2,1.23,29.83]],"ltp":1.11,"tv":24168.21,"id":11439844}]}]}
{"op":"mcm","clk":"4234662439","pt":1631548505902,"mc":[{"id":"1.187560677","rc":[{"batb":[[0,7.6,3.24],[1,1.6,767.39],[2,1.3,5]],"batl":[[0,12.5,2],[1,990,0.01],[2,990,0]],"ltp":11.0,"tv":1327.96,"id":7588306},{"batb":[[0,1.09,258.09],[1,1.08,2.64],[2,1.07,140.36]],"batl":[[0,1.15,193.15],[1,1.23,29.83],[2,1.25,14.92]],"ltp":1.11,"tv":24168.21,"id":11439844}]}]}
{"op":"mcm","clk":"4234663007","pt":1631548512634,"mc":[{"id":"1.187560677","rc":[{"batb":[[0,8,3.08],[1,7.6,3.24],[2,1.6,767.39]],"batl":[[0,11,2],[1,12.5,2],[2,990,0.01]],"ltp":11.0,"tv":1327.96,"id":7588306},{"batb":[[0,1.1,246.41],[1,1.09,257.82],[2,1.08,2.64]],"batl":[[0,1.14,198.18],[1,1.15,192.72],[2,1.23,29.83]],"ltp":1.11,"tv":24168.21,"id":11439844}]}]}
{"op":"mcm","clk":"4234663024","pt":1631548512843,"mc":[{"id":"1.187560677","rc":[{"batb":[[0,7.6,3.24],[1,1.6,767.39],[2,1.3,5]],"batl":[[0,12.5,2],[1,990,0.01],[2,990,0]],"ltp":11.0,"tv":1327.96,"id":7588306},{"batb":[[0,1.09,258.09],[1,1.08,2.64],[2,1.07,140.36]],"batl":[[0,1.15,193.15],[1,1.23,29.83],[2,1.25,14.92]],"ltp":1.11,"tv":24168.21,"id":11439844}]}]}
{"op":"mcm","clk":"4234663161","pt":1631548514534,"mc":[{"id":"1.187560677","rc":[{"batl":[[0,1.23,30.48],[1,1.25,14.92],[2,1.38,987.41]],"ltp":1.11,"tv":24168.21,"id":11439844}]}]}
{"op":"mcm","clk":"4234663321","pt":1631548516342,"mc":[{"id":"1.187560677","rc":[{"batl":[[0,11,2],[1,12.5,2],[2,990,0.01]],"ltp":11.0,"tv":1327.96,"id":7588306},{"batb":[[0,1.1,212.11],[1,1.09,257.82],[2,1.08,2.64]],"ltp":1.11,"tv":24168.21,"id":11439844}]}]}
{"op":"mcm","clk":"4234663430","pt":1631548517622,"mc":[{"id":"1.187560677","rc":[{"batb":[[0,9.2,10.12],[1,7.6,3.24],[2,1.6,767.39]],"batl":[[0,11,10.41],[1,12,212.01],[2,12.5,2]],"ltp":11.0,"tv":1327.96,"id":7588306},{"batb":[[0,1.1,362.11]],"batl":[[0,1.11,157.23],[1,1.12,2460.75],[2,1.13,96.19]],"ltp":1.11,"tv":24168.21,"id":11439844}]}]}
{"op":"mcm","clk":"4234663479","pt":1631548518242,"mc":[{"id":"1.187560677","rc":[{"batl":[[1,1.12,1398.95]],"ltp":1.11,"tv":24168.21,"id":11439844}]}]}
{"op":"mcm","clk":"4234663836","pt":1631548522662,"mc":[{"id":"1.187560677","rc":[{"batl":[[0,11,58.41],[2,12.5,58.13]],"ltp":11.0,"tv":1327.96,"id":7588306},{"batb":[[0,1.1,842.16],[1,1.09,901.58]],"ltp":1.11,"tv":24168.21,"id":11439844}]}]}
{"op":"mcm","clk":"4234663928","pt":1631548523657,"mc":[{"id":"1.187560677","rc":[{"batb":[[0,10,45.52],[1,9.2,75.09],[2,7.6,3.24]],"ltp":11.0,"tv":1327.96,"id":7588306},{"batl":[[0,1.11,567.36],[1,1.12,1932.72]],"ltp":1.11,"tv":24168.21,"id":11439844}]}]}
{"op":"mcm","clk":"4234663952","pt":1631548523869,"mc":[{"id":"1.187560677","rc":[{"batb":[[2,8.6,3.09]],"ltp":11.0,"tv":1327.96,"id":7588306},{"batl":[[2,1.13,308.69]],"ltp":1.11,"tv":24168.21,"id":11439844}]}]}
{"op":"mcm","clk":"4234664439","pt":1631548529253,"mc":[{"id":"1.187560677","rc":[{"batl":[[1,1.12,1831.6]],"ltp":1.11,"tv":24168.21,"id":11439844}]}]}
{"op":"mcm","clk":"4234665131","pt":1631548538651,"mc":[{"id":"1.187560677","rc":[{"batb":[[0,8,2.95],[1,1.6,767.39],[2,1.3,5]],"batl":[[0,15.5,3],[1,18,2],[2,21,2]],"ltp":11.0,"tv":1327.96,"id":7588306},{"batb":[[0,1.08,3.13],[1,1.07,333.36],[2,1.06,219.22]],"batl":[[0,1.13,96.19],[1,1.14,186.99],[2,1.23,30.05]],"ltp":1.11,"tv":24168.21,"id":11439844}]}]}
{"op":"mcm","clk":"4234665357","pt":1631548541367,"mc":[{"id":"1.187560677","rc":[{"batb":[[0,8,7.95],[1,7.6,5],[2,1.6,767.39]],"ltp":11.0,"tv":1327.96,"id":7588306},{"batl":[[1,1.14,293.99],[2,1.15,108.22]],"ltp":1.11,"tv":24168.21,"id":11439844}]}]}
{"op":"mcm","clk":"4234665548","pt":1631548543538,"mc":[{"id":"1.187560677","rc":[{"batl":[[0,1.12,773.74],[1,1.13,96.19],[2,1.14,293.99]],"ltp":1.11,"tv":24168.21,"id":11439844}]}]}
{"op":"mcm","clk":"4234665592","pt":1631548544063,"mc":[{"id":"1.187560677","rc":[{"batl":[[0,1.13,96.19],[1,1.14,293.99],[2,1.15,108.22]],"ltp":1.11,"tv":24168.21,"id":11439844}]}]}
{"op":"mcm","clk":"4234665682","pt":1631548545462,"mc":[{"id":"1.187560677","rc":[{"batb":[[0,8.6,2.79],[1,8,7.95],[2,7.6,5]],"ltp":11.0,"tv":1327.96,"id":7588306},{"batl":[[0,1.13,297.69]],"ltp":1.11,"tv":24168.21,"id":11439844}]}]}
{"op":"mcm","clk":"4234665721","pt":1631548545990,"mc":[{"id":"1.187560677","rc":[{"batb":[[0,8,7.95],[1,7.6,5],[2,1.6,767.39]],"ltp":11.0,"tv":1327.96,"id":7588306},{"batl":[[0,1.13,96.19]],"ltp":1.11,"tv":24168.21,"id":11439844}]}]}
{"op":"mcm","clk":"4234665764","pt":1631548546781,"mc":[{"id":"1.187560677","rc":[{"batl":[[2,1.15,302.32]],"ltp":1.11,"tv":24168.21,"id":11439844}]}]}
{"op":"mcm","clk":"4234666243","pt":1631548552668,"mc":[{"id":"1.187560677","rc":[{"trd":[[8,38.6],[8.6,13.52]],"batb":[[0,8.6,3.29],[1,7.6,5.59]],"ltp":8.0,"tv":1355.32,"id":7588306},{"trd":[[1.13,123.41]],"batl":[[0,1.13,205.5]],"ltp":1.13,"tv":24264.41,"id":11439844}],"tv":25619.73}]}
{"op":"mcm","clk":"4234666289","pt":1631548553087,"mc":[{"id":"1.187560677","rc":[{"batb":[[0,7.6,5.59],[1,1.6,767.39],[2,1.3,5]],"ltp":8.0,"tv":1355.32,"id":7588306},{"batl":[[0,1.14,293.99],[1,1.15,302.32],[2,1.23,29.83]],"ltp":1.13,"tv":24264.41,"id":11439844}]}]}
{"op":"mcm","clk":"4234666348","pt":1631548553770,"mc":[{"id":"1.187560677","rc":[{"batl":[[2,1.2,55.46]],"ltp":1.13,"tv":24264.41,"id":11439844}]}]}
{"op":"mcm","clk":"4234666499","pt":1631548555396,"mc":[{"id":"1.187560677","rc":[{"batb":[[0,8,3.79],[1,7.6,5],[2,1.6,767.39]],"ltp":8.0,"tv":1355.32,"id":7588306}]}]}
{"op":"mcm","clk":"4234667024","pt":1631548561510,"mc":[{"id":"1.187560677","rc":[{"batb":[[0,8,132.51]],"batl":[[0,9,4.44],[1,9.2,4.51],[2,9.4,3]],"ltp":8.0,"tv":1355.32,"id":7588306},{"batb":[[0,1.12,133],[1,1.1,150.27],[2,1.09,161.21]],"batl":[[0,1.13,101],[1,1.14,293.99],[2,1.15,302.32]],"ltp":1.13,"tv":24264.41,"id":11439844}]}]}
{"op":"mcm","clk":"4234667556","pt":1631548567714,"mc":[{"id":"1.187560677","rc":[{"batb":[[1,7.6,8.19]],"ltp":8.0,"tv":1355.32,"id":7588306},{"batb":[[0,1.12,133.21],[1,1.11,13.13],[2,1.1,397.95]],"ltp":1.13,"tv":24264.41,"id":11439844}]}]}
{"op":"mcm","clk":"4234667593","pt":1631548568180,"mc":[{"id":"1.187560677","rc":[{"batb":[[2,6.4,35.29]],"ltp":8.0,"tv":1355.32,"id":7588306},{"batb":[[2,1.1,638.1]],"ltp":1.13,"tv":24264.41,"id":11439844}]}]}
{"op":"mcm","clk":"4234668258","pt":1631548576605,"mc":[{"id":"1.187560677","rc":[{"trd":[[1.12,22.46]],"batb":[[0,1.12,124.19]],"ltp":1.12,"tv":24282.45,"id":11439844}],"tv":25637.77}]}
{"op":"mcm","clk":"4234668789","pt":1631548582419,"mc":[{"id":"1.187560677","rc":[{"batb":[[0,7.6,8.78],[1,6.4,35.29],[2,6.2,47.42]],"batl":[[0,10.5,24.84],[1,11,37.56],[2,11.5,29.95]],"ltp":8.0,"tv":1355.32,"id":7588306},{"batb":[[0,1.11,13.33],[1,1.1,638.1],[2,1.09,721.78]],"batl":[[0,1.14,107.24],[1,1.15,302.32],[2,1.19,161.7]],"ltp":1.12,"tv":24282.45,"id":11439844}]}]}
{"op":"mcm","clk":"4234669071","pt":1631548585615,"mc":[{"id":"1.187560677","rc":[{"batb":[[1,7.2,6],[2,6.4,35.29]],"batl":[[0,11,5],[1,12.5,5],[2,13.5,3]],"ltp":8.0,"tv":1355.32,"id":7588306},{"batb":[[1,1.1,397.95],[2,1.09,417.82]],"batl":[[2,1.16,100]],"ltp":1.12,"tv":24282.45,"id":11439844}]}]}
{"op":"mcm","clk":"4234669106","pt":1631548586032,"mc":[{"id":"1.187560677","rc":[{"batb":[[0,7.6,8.19]],"ltp":8.0,"tv":1355.32,"id":7588306},{"batl":[[0,1.15,302.55],[1,1.16,100],[2,1.19,161.7]],"ltp":1.12,"tv":24282.45,"id":11439844}]}]}
{"op":"mcm","clk":"4234669315","pt":1631548588644,"mc":[{"id":"1.187560677","rc":[{"batl":[[0,8.6,247.71],[1,8.8,22.72],[2,11,5]],"ltp":8.0,"tv":1355.32,"id":7588306},{"trd":[[1.14,261.44]],"batb":[[0,1.14,21.43],[1,1.11,13.33],[2,1.1,397.95]],"batl":[[0,1.15,335.35],[1,1.16,965.41]],"ltp":1.14,"tv":24282.93,"id":11439844}],"tv":25638.25}]}
{"op":"mcm","clk":"4234669330","pt":1631548588851,"mc":[{"id":"1.187560677","rc":[{"batb":[[2,6.4,41.29]],"batl":[[0,8.6,158.65],[1,8.8,7.54],[2,9.4,3]],"ltp":8.0,"tv":1355.32,"id":7588306},{"batb":[[1,1.13,127],[2,1.12,133.21]],"batl":[[2,1.18,105]],"ltp":1.14,"tv":24282.93,"id":11439844}]}]}
{"op":"mcm","clk":"4234669443","pt":1631548590342,"mc":[{"id":"1.187560677","rc":[{"batb":[[2,1.12,145.24]],"ltp":1.14,"tv":24282.93,"id":11439844}]}]}
{"op":"mcm","clk":"4234669516","pt":1631548591540,"mc":[{"id":"1.187560677","rc":[{"trd":[[1.14,304.3]],"batb":[[0,1.13,138.1],[1,1.12,145.24],[2,1.11,154.13]],"ltp":1.14,"tv":24325.79,"id":11439844}],"tv":25681.11}]}
{"op":"mcm","clk":"4234670050","pt":1631548599062,"mc":[{"id":"1.187560677","rc":[{"batl":[[0,1.15,302.32]],"ltp":1.14,"tv":24325.79,"id":11439844}]}]}
{"op":"mcm","clk":"4234670274","pt":1631548601665,"mc":[{"id":"1.187560677","rc":[{"batl":[[0,8.6,165.53]],"ltp":8.0,"tv":1355.32,"id":7588306},{"batb":[[1,1.12,133.21]],"batl":[[0,1.15,356.82]],"ltp":1.14,"tv":24325.79,"id":11439844}]}]}
{"op":"mcm","clk":"4234670319","pt":1631548602551,"mc":[{"id":"1.187560677","rc":[{"batl":[[0,8.6,158.65]],"ltp":8.0,"tv":1355.32,"id":7588306},{"batb":[[0,1.13,138.36]],"batl":[[0,1.15,302.32]],"ltp":1.14,"tv":24325.79,"id":11439844}]}]}
{"op":"mcm","clk":"4234670461","pt":1631548604787,"mc":[{"id":"1.187560677","rc":[{"batl":[[0,8.6,165.53]],"ltp":8.0,"tv":1355.32,"id":7588306},{"batl":[[0,1.15,356.82]],"ltp":1.14,"tv":24325.79,"id":11439844}]}]}
{"op":"mcm","clk":"4234670522","pt":1631548605984,"mc":[{"id":"1.187560677","rc":[{"batb":[[0,1.13,127.25]],"ltp":1.14,"tv":24325.79,"id":11439844}]}]}
{"op":"mcm","clk":"4234673744","pt":1631548648943,"mc":[{"id":"1.187560677","rc":[{"batb":[[2,6.8,3.43]],"batl":[[2,9.4,5]],"ltp":8.0,"tv":1355.32,"id":7588306},{"batb":[[1,1.12,343.25],[2,1.11,399.72]],"batl":[[2,1.17,176.5]],"ltp":1.14,"tv":24325.79,"id":11439844}]}]}
{"op":"mcm","clk":"4234673953","pt":1631548651716,"mc":[{"id":"1.187560677","rc":[{"trd":[[1.13,137.85]],"batb":[[0,1.13,120.03]],"ltp":1.13,"tv":24340.23,"id":11439844}],"tv":25695.55}]}
{"op":"mcm","clk":"4234674079","pt":1631548653655,"mc":[{"id":"1.187560677","rc":[{"batl":[[0,8.8,3],[1,9.4,5],[2,10.5,5]],"ltp":8.0,"tv":1355.32,"id":7588306},{"batl":[[0,1.15,302.32],[1,1.16,100]],"ltp":1.13,"tv":24340.23,"id":11439844}]}]}
{"op":"mcm","clk":"4234674105","pt":1631548654130,"mc":[{"id":"1.187560677","rc":[{"batb":[[0,6.4,9.81],[1,1.6,767.39],[2,1.3,5]],"batl":[[0,9.4,3],[1,10.5,5],[2,11,3]],"ltp":8.0,"tv":1355.32,"id":7588306},{"batb":[[0,1.12,133.46],[1,1.11,399.72],[2,1.1,164.71]],"batl":[[0,1.18,275.47],[1,1.2,55.46],[2,1.38,987.41]],"ltp":1.13,"tv":24340.23,"id":11439844}]}]}
{"op":"mcm","clk":"4234674256","pt":1631548656635,"mc":[{"id":"1.187560677","rc":[{"batb":[[1,6.2,6],[2,6,7]],"ltp":8.0,"tv":1355.32,"id":7588306},{"batl":[[1,1.19,94],[2,1.2,161.46]],"ltp":1.13,"tv":24340.23,"id":11439844}]}]}
{"op":"mcm","clk":"4234674320","pt":1631548657633,"mc":[{"id":"1.187560677","rc":[{"batb":[[0,6.4,3.81],[1,1.6,767.39],[2,1.3,5]],"ltp":8.0,"tv":1355.32,"id":7588306},{"batl":[[0,1.18,170.47],[1,1.2,55.46],[2,1.38,987.41]],"ltp":1.13,"tv":24340.23,"id":11439844}]}]}
{"op":"mcm","clk":"4234674460","pt":1631548659657,"mc":[{"id":"1.187560677","rc":[{"batl":[[0,9.2,103.02],[1,9.4,3],[2,10.5,5]],"ltp":8.0,"tv":1355.32,"id":7588306},{"trd":[[1.13,138.35]],"batb":[[0,1.12,133.21]],"batl":[[0,1.13,21.23],[1,1.14,625],[2,1.15,1584.25]],"ltp":1.13,"tv":24340.73,"id":11439844}],"tv":25696.05}]}
{"op":"mcm","clk":"4234674531","pt":1631548660645,"mc":[{"id":"1.187560677","rc":[{"batb":[[0,8.6,10.79],[1,8,5],[2,7.6,5]],"ltp":8.0,"tv":1355.32,"id":7588306},{"batl":[[0,1.13,269.73],[1,1.14,104],[2,1.15,1554.11]],"ltp":1.13,"tv":24340.73,"id":11439844}]}]}
{"op":"mcm","clk":"4234674899","pt":1631548666267,"mc":[{"id":"1.187560677","rc":[{"batb":[[2,7.6,8.49]],"batl":[[1,9.4,5]],"ltp":8.0,"tv":1355.32,"id":7588306},{"batb":[[0,1.12,318]],"batl":[[2,1.15,1750.21]],"ltp":1.13,"tv":24340.73,"id":11439844}]}]}
{"op":"mcm","clk":"4234674992","pt":1631548667569,"mc":[{"id":"1.187560677","rc":[{"batb":[[0,7.6,3.49],[1,7.2,9.27],[2,6.4,3.81]],"batl":[[0,9.6,25.04],[1,9.8,29.73],[2,10,34.9]],"ltp":8.0,"tv":1355.32,"id":7588306},{"batb":[[0,1.11,696.91],[1,1.1,502.7],[2,1.09,564.93]],"batl":[[0,1.15,196.32],[1,1.16,296.22],[2,1.18,170.25]],"ltp":1.13,"tv":24340.73,"id":11439844}]}]}
{"op":"mcm","clk":"4234675006","pt":1631548667727,"mc":[{"id":"1.187560677","rc":[{"batb":[[0,7.2,9.27],[1,6.4,3.81],[2,6.2,41.52]],"ltp":8.0,"tv":1355.32,"id":7588306},{"batl":[[0,1.16,296.44],[1,1.18,170.25],[2,1.19,175.41]],"ltp":1.13,"tv":24340.73,"id":11439844}]}]}
{"op":"mcm","clk":"4234675206","pt":1631548670547,"mc":[{"id":"1.187560677","rc":[{"batb":[[1,6.8,6],[2,6.4,9.81]],"ltp":8.0,"tv":1355.32,"id":7588306},{"batl":[[1,1.17,107],[2,1.18,280.25]],"ltp":1.13,"tv":24340.73,"id":11439844}]}]}
{"op":"mcm","clk":"4234675421","pt":1631548673578,"mc":[{"id":"1.187560677","rc":[{"batl":[[0,1.16,296.69]],"ltp":1.13,"tv":24340.73,"id":11439844}]}]}
{"op":"mcm","clk":"4234675501","pt":1631548674550,"mc":[{"id":"1.187560677","rc":[{"batb":[[0,7.6,3.19],[1,7.2,9.27],[2,6.8,6]],"ltp":8.0,"tv":1355.32,"id":7588306},{"batl":[[0,1.15,185.77],[1,1.16,296.22],[2,1.17,107]],"ltp":1.13,"tv":24340.73,"id":11439844}]}]}
{"op":"mcm","clk":"4234675527","pt":1631548674863,"mc":[{"id":"1.187560677","rc":[{"batb":[[0,7.2,9.27],[1,6.8,6],[2,6.4,9.81]],"ltp":8.0,"tv":1355.32,"id":7588306},{"batl":[[0,1.16,296.69],[1,1.17,107],[2,1.18,280.25]],"ltp":1.13,"tv":24340.73,"id":11439844}]}]}
{"op":"mcm","clk":"4234675623","pt":1631548676059,"mc":[{"id":"1.187560677","rc":[{"batl":[[0,10.5,5],[1,11,3],[2,12.5,3]],"ltp":8.0,"tv":1355.32,"id":7588306},{"batb":[[0,1.11,399.92],[1,1.1,164.71],[2,1.09,161.21]],"ltp":1.13,"tv":24340.73,"id":11439844}]}]}
{"op":"mcm","clk":"4234675858","pt":1631548679354,"mc":[{"id":"1.187560677","rc":[{"trd":[[8,38.64]],"batl":[[0,8,3.94],[1,8.8,3],[2,9,4.44]],"ltp":8.0,"tv":1355.36,"id":7588306},{"trd":[[1.14,304.55]],"batb":[[0,1.13,127],[1,1.12,3936.03],[2,1.11,399.72]],"batl":[[0,1.16,296.44],[1,1.17,1035.34]],"ltp":1.14,"tv":24340.98,"id":11439844}],"tv":25696.35}]}
{"op":"mcm","clk":"4234676601","pt":1631548689156,"mc":[{"id":"1.187560677","rc":[{"batl":[[0,8.8,3],[1,9,4.44],[2,9.4,3]],"ltp":8.0,"tv":1355.36,"id":7588306}]}]}
{"op":"mcm","clk":"4234676800","pt":1631548692289,"mc":[{"id":"1.187560677","rc":[{"batl":[[0,8,3.94],[1,8.8,3],[2,9,4.44]],"ltp":8.0,"tv":1355.36,"id":7588306}]}]}
{"op":"mcm","clk":"4234677035","pt":1631548695596,"mc":[{"id":"1.187560677","rc":[{"batb":[[0,6.4,9.81],[1,6,3.93],[2,1.6,767.39]],"batl":[[0,9.4,3],[1,10.5,5],[2,11,3]],"ltp":8.0,"tv":1355.36,"id":7588306},{"batb":[[0,1.12,133.48],[1,1.11,154.13],[2,1.1,164.71]],"batl":[[0,1.18,280.47],[1,1.19,185.5],[2,1.2,224.34]],"ltp":1.14,"tv":24340.98,"id":11439844}]}]}
{"op":"mcm","clk":"4234677057","pt":1631548695905,"mc":[{"id":"1.187560677","rc":[{"batb":[[0,6.4,6]],"ltp":8.0,"tv":1355.36,"id":7588306},{"batl":[[0,1.18,110.22]],"ltp":1.14,"tv":24340.98,"id":11439844}]}]}
{"op":"mcm","clk":"4234677238","pt":1631548698570,"mc":[{"id":"1.187560677","rc":[{"batl":[[1,1.19,286.5],[2,1.2,326.34]],"ltp":1.14,"tv":24340.98,"id":11439844}]}]}
{"op":"mcm","clk":"4234677521","pt":1631548702595,"mc":[{"id":"1.187560677","rc":[{"batb":[[0,6.4,9.66]],"ltp":8.0,"tv":1355.36,"id":7588306},{"batl":[[0,1.18,277.47]],"ltp":1.14,"tv":24340.98,"id":11439844}]}]}
{"op":"mcm","clk":"4234677566","pt":1631548703068,"mc":[{"id":"1.187560677","rc":[{"batb":[[0,6.4,6]],"ltp":8.0,"tv":1355.36,"id":7588306},{"batl":[[0,1.18,110.22],[1,1.19,101]],"ltp":1.14,"tv":24340.98,"id":11439844}]}]}
{"op":"mcm","clk":"4234677853","pt":1631548706572,"mc":[{"id":"1.187560677","rc":[{"batl":[[1,1.19,261.5]],"ltp":1.14,"tv":24340.98,"id":11439844}]}]}
{"op":"mcm","clk":"4234678140","pt":1631548710379,"mc":[{"id":"1.187560677","rc":[{"batl":[[1,1.19,101]],"ltp":1.14,"tv":24340.98,"id":11439844}]}]}
{"op":"mcm","clk":"4234678383","pt":1631548713679,"mc":[{"id":"1.187560677","rc":[{"batl":[[1,1.19,283.5],[2,1.2,224.34]],"ltp":1.14,"tv":24340.98,"id":11439844}]}]}
{"op":"mcm","clk":"4234678393","pt":1631548713784,"mc":[{"id":"1.187560677","rc":[{"batl":[[1,1.19,101]],"ltp":1.14,"tv":24340.98,"id":11439844}]}]}
{"op":"mcm","clk":"4234678597","pt":1631548716680,"mc":[{"id":"1.187560677","rc":[{"trd":[[7.6,4.83]],"batl":[[0,6.8,13.43],[1,7.4,3],[2,8.2,3]],"ltp":7.6,"tv":1355.39,"id":7588306},{"trd":[[1.15,554.39]],"batb":[[0,1.16,113],[1,1.14,4813.91],[2,1.13,127.27]],"batl":[[0,1.18,110],[1,1.19,133.86]],"ltp":1.15,"tv":24341.2,"id":11439844}],"tv":25696.59}]}
{"op":"mcm","clk":"4234678886","pt":1631548720697,"mc":[{"id":"1.187560677","rc":[{"trd":[[6.8,18.22]],"batl":[[0,6.8,12.81]],"ltp":6.8,"tv":1356.01,"id":7588306},{"trd":[[1.17,105.95]],"ltp":1.17,"tv":24344.81,"id":11439844}],"tv":25700.82}]}
{"op":"mcm","clk":"4234679067","pt":1631548723406,"mc":[{"id":"1.187560677","rc":[{"batb":[[2,5.1,4.44]],"ltp":6.8,"tv":1356.01,"id":7588306}]}]}
{"op":"mcm","clk":"4234679549","pt":1631548730402,"mc":[{"id":"1.187560677","rc":[{"batb":[[1,1.14,4814.14]],"ltp":1.17,"tv":24344.81,"id":11439844}]}]}
{"op":"mcm","clk":"4234679678","pt":1631548732432,"mc":[{"id":"1.187560677","rc":[{"batb":[[0,5.1,4.44],[1,4.8,4.08],[2,1.6,767.39]],"batl":[[0,8.2,3],[1,8.8,3],[2,9.4,3]],"ltp":6.8,"tv":1356.01,"id":7588306},{"batb":[[0,1.14,121.23],[1,1.13,127.27],[2,1.12,133.21]],"batl":[[0,1.2,55.46],[1,1.24,161.23],[2,1.26,160.25]],"ltp":1.17,"tv":24344.81,"id":11439844}]}]}
{"op":"mcm","clk":"4234679695","pt":1631548732742,"mc":[{"id":"1.187560677","rc":[{"batb":[[0,4.8,4.08],[1,1.6,767.39],[2,1.3,5]],"ltp":6.8,"tv":1356.01,"id":7588306},{"batl":[[1,1.26,160.25],[2,1.39,17.9]],"ltp":1.17,"tv":24344.81,"id":11439844}]}]}
{"op":"mcm","clk":"4234680203","pt":1631548739561,"mc":[{"id":"1.187560677","rc":[{"batb":[[0,5.1,4.54],[1,4.8,4.08],[2,1.6,767.39]],"ltp":6.8,"tv":1356.01,"id":7588306},{"batl":[[0,1.17,72.2],[1,1.2,55.46],[2,1.24,164.23]],"ltp":1.17,"tv":24344.81,"id":11439844}]}]}
{"op":"mcm","clk":"4234680217","pt":1631548739721,"mc":[{"id":"1.187560677","rc":[{"batb":[[0,4.8,4.08],[1,1.6,767.39],[2,1.3,5]],"ltp":6.8,"tv":1356.01,"id":7588306},{"batl":[[2,1.26,160.25]],"ltp":1.17,"tv":24344.81,"id":11439844}]}]}
{"op":"mcm","clk":"4234680527","pt":1631548743851,"mc":[{"id":"1.187560677","rc":[{"trd":[[1.17,117.71]],"batl":[[0,1.17,66.32]],"ltp":1.17,"tv":24356.57,"id":11439844}],"tv":25712.58}]}
{"op":"mcm","clk":"4234680738","pt":1631548746590,"mc":[{"id":"1.187560677","rc":[{"batb":[[0,5.1,4.44],[1,4.8,4.08],[2,1.6,767.39]],"ltp":6.8,"tv":1356.01,"id":7588306},{"batl":[[2,1.24,150.73]],"ltp":1.17,"tv":24356.57,"id":11439844}]}]}
{"op":"mcm","clk":"4234680817","pt":1631548747535,"mc":[{"id":"1.187560677","rc":[{"batb":[[0,4.8,4.08],[1,1.6,767.39],[2,1.3,5]],"batl":[[1,9.4,3],[2,10.5,3]],"ltp":6.8,"tv":1356.01,"id":7588306},{"batb":[[1,1.12,133.48],[2,1.11,154.13]],"batl":[[2,1.26,160.25]],"ltp":1.17,"tv":24356.57,"id":11439844}]}]}
{"op":"mcm","clk":"4234681053","pt":1631548750564,"mc":[{"id":"1.187560677","rc":[{"batb":[[0,7.2,13.37],[1,6.8,6],[2,6.4,12.24]],"batl":[[0,7.6,3.44],[1,8,223.21],[2,8.2,3]],"ltp":6.8,"tv":1356.01,"id":7588306},{"batl":[[0,1.16,271.14],[1,1.17,170.32],[2,1.18,1069.37]],"ltp":1.17,"tv":24356.57,"id":11439844}]}]}
{"op":"mcm","clk":"4234682791","pt":1631548771403,"mc":[{"id":"1.187560677","rc":[{"batb":[[0,5.3,4.28],[1,1.6,767.39],[2,1.3,5]],"batl":[[0,9.4,3],[1,10.5,3],[2,11,3]],"ltp":6.8,"tv":1356.01,"id":7588306},{"batb":[[0,1.12,133.71],[1,1.11,154.13],[2,1.1,164.71]],"batl":[[0,1.17,66.32],[1,1.2,55.46],[2,1.23,152.5]],"ltp":1.17,"tv":24356.57,"id":11439844}]}]}
{"op":"mcm","clk":"4234683078","pt":1631548774567,"mc":[{"id":"1.187560677","rc":[{"batb":[[0,5.7,4.12],[1,5.3,4.28],[2,1.6,767.39]],"ltp":6.8,"tv":1356.01,"id":7588306},{"batb":[[0,1.16,17.05],[1,1.12,133.71],[2,1.11,154.13]],"batl":[[2,1.21,156.5]],"ltp":1.17,"tv":24356.57,"id":11439844}]}]}
{"op":"mcm","clk":"4234683111","pt":1631548774881,"mc":[{"id":"1.187560677","rc":[{"batb":[[0,5.3,4.28],[1,1.6,767.39],[2,1.3,5]],"batl":[[0,9.4,3.45]],"ltp":6.8,"tv":1356.01,"id":7588306},{"batl":[[2,1.23,152.5]],"ltp":1.17,"tv":24356.57,"id":11439844}]}]}
{"op":"mcm","clk":"4234683343","pt":1631548777707,"mc":[{"id":"1.187560677","rc":[{"batb":[[1,1.12,145.74]],"batl":[[0,1.2,55.46],[1,1.23,152.5],[2,1.31,2]],"ltp":1.17,"tv":24356.57,"id":11439844}]}]}
{"op":"mcm","clk":"4234683611","pt":1631548780698,"mc":[{"id":"1.187560677","rc":[{"trd":[[7.2,2.17]],"batb":[[0,8,17.05],[1,7.6,126.36],[2,7.4,5.4]],"batl":[[0,9.2,194.1],[1,9.4,3],[2,10.5,3]],"ltp":7.2,"tv":1356.46,"id":7588306},{"trd":[[1.14,305.01],[1.16,161.32]],"batb":[[0,1.12,145.5],[1,1.11,154.13],[2,1.1,164.71]],"batl":[[0,1.14,391.84],[1,1.15,154.47],[2,1.17,107]],"ltp":1.14,"tv":24393.93,"id":11439844}],"tv":25750.39}]}
{"op":"mcm","clk":"4234683820","pt":1631548783166,"mc":[{"id":"1.187560677","rc":[{"trd":[[1.14,321.75]],"batl":[[0,1.14,383.47]],"ltp":1.14,"tv":24410.67,"id":11439844}],"tv":25767.13}]}
{"op":"mcm","clk":"4234683882","pt":1631548784105,"mc":[{"id":"1.187560677","rc":[{"batl":[[1,1.15,108]],"ltp":1.14,"tv":24410.67,"id":11439844}]}]}
{"op":"mcm","clk":"4234684071","pt":1631548786714,"mc":[{"id":"1.187560677","rc":[{"batl":[[1,9.4,5],[2,10.5,5]],"ltp":7.2,"tv":1356.46,"id":7588306},{"batb":[[0,1.12,364.79],[1,1.11,417.72]],"batl":[[2,1.16,198.22]],"ltp":1.14,"tv":24410.67,"id":11439844}]}]}
{"op":"mcm","clk":"4234684354","pt":1631548790482,"mc":[{"id":"1.187560677","rc":[{"batl":[[0,9.2,185.3]],"ltp":7.2,"tv":1356.46,"id":7588306},{"batl":[[0,1.14,348.75]],"ltp":1.14,"tv":24410.67,"id":11439844}]}]}
{"op":"mcm","clk":"4234684618","pt":1631548793620,"mc":[{"id":"1.187560677","rc":[{"batb":[[0,7.2,3.67],[1,6.8,9.83],[2,5.3,4.28]],"batl":[[0,10.5,5],[1,11,3],[2,12.5,3]],"ltp":7.2,"tv":1356.46,"id":7588306},{"batb":[[0,1.12,12.5]],"batl":[[0,1.16,198.22],[1,1.17,282.5],[2,1.2,55.46]],"ltp":1.14,"tv":24410.67,"id":11439844}]}]}
{"op":"mcm","clk":"4234684677","pt":1631548794311,"mc":[{"id":"1.187560677","rc":[{"batb":[[0,6.8,9.83],[1,5.3,4.28],[2,1.6,767.39]],"batl":[[0,10.5,5.45]],"ltp":7.2,"tv":1356.46,"id":7588306},{"batl":[[0,1.17,282.5],[1,1.2,55.46],[2,1.23,152.5]],"ltp":1.14,"tv":24410.67,"id":11439844}]}]}
{"op":"mcm","clk":"4234684883","pt":1631548796624,"mc":[{"id":"1.187560677","rc":[{"trd":[[8,39.09]],"batb":[[1,6.4,6],[2,5.3,4.28]],"batl":[[0,9.4,2],[1,10.5,5],[2,11,3]],"ltp":8.0,"tv":1356.91,"id":7588306},{"trd":[[1.11,31.99],[1.12,46.94],[1.13,138.88],[1.14,324.91]],"batb":[[0,1.12,215.79],[1,1.11,415.72]],"batl":[[1,1.18,104],[2,1.19,107]],"ltp":1.11,"tv":24442.82,"id":11439844}],"tv":25799.74}]}
{"op":"mcm","clk":"4234684964","pt":1631548797680,"mc":[{"id":"1.187560677","rc":[{"batl":[[0,10.5,5],[1,11,3],[2,12.5,3]],"ltp":8.0,"tv":1356.91,"id":7588306},{"batb":[[0,1.11,415.72],[1,1.1,164.71],[2,1.09,161.21]],"ltp":1.11,"tv":24442.82,"id":11439844}]}]}
{"op":"mcm","clk":"4234685159","pt":1631548799694,"mc":[{"id":"1.187560677","rc":[{"batl":[[0,1.17,282.73]],"ltp":1.11,"tv":24442.82,"id":11439844}]}]}
{"op":"mcm","clk":"4234685627","pt":1631548803592,"mc":[{"id":"1.187560677","rc":[{"batl":[[0,9.4,2],[1,10.5,5],[2,11,3]],"ltp":8.0,"tv":1356.91,"id":7588306},{"batb":[[0,1.12,202.54],[1,1.11,415.72],[2,1.1,164.71]],"ltp":1.11,"tv":24442.82,"id":11439844}]}]}
{"op":"mcm","clk":"4234685690","pt":1631548804227,"mc":[{"id":"1.187560677","rc":[{"batl":[[0,10.5,5],[1,11,3],[2,12.5,3]],"ltp":8.0,"tv":1356.91,"id":7588306},{"batb":[[0,1.11,415.72],[1,1.1,164.71],[2,1.09,161.21]],"ltp":1.11,"tv":24442.82,"id":11439844}]}]}
{"op":"mcm","clk":"4234685888","pt":1631548806338,"mc":[{"id":"1.187560677","rc":[{"batb":[[0,1.12,12.03],[1,1.11,415.72],[2,1.1,164.71]],"ltp":1.11,"tv":24442.82,"id":11439844}]}]}
{"op":"mcm","clk":"4234686082","pt":1631548808540,"mc":[{"id":"1.187560677","rc":[{"batb":[[1,5.3,4.28],[2,1.6,767.39]],"ltp":8.0,"tv":1356.91,"id":7588306},{"batb":[[0,1.11,415.72],[1,1.1,164.71],[2,1.09,161.21]],"batl":[[1,1.23,152.5],[2,1.31,2]],"ltp":1.11,"tv":24442.82,"id":11439844}]}]}
{"op":"mcm","clk":"4234686302","pt":1631548810705,"mc":[{"id":"1.187560677","rc":[{"trd":[[7.6,4.86]],"batb":[[1,6.4,174.35],[2,5.3,4.28]],"batl":[[0,7.6,189.28],[1,7.8,570.84],[2,9.4,2]],"ltp":7.6,"tv":1356.94,"id":7588306},{"trd":[[1.15,554.62]],"batb":[[0,1.12,203.04],[1,1.11,415.72],[2,1.1,164.71]],"batl":[[0,1.17,319.81]],"ltp":1.15,"tv":24443.05,"id":11439844}],"tv":25800.0}]}
{"op":"mcm","clk":"4234686328","pt":1631548811013,"mc":[{"id":"1.187560677","rc":[{"batb":[[0,7.2,6],[1,6.8,9.83],[2,6.4,174.35]],"batl":[[0,7.6,168.25],[1,8.2,3],[2,9.4,5]],"ltp":7.6,"tv":1356.94,"id":7588306},{"batb":[[0,1.14,121],[1,1.12,336.04],[2,1.11,415.72]],"batl":[[0,1.16,95],[1,1.17,319.81],[2,1.23,152.5]],"ltp":1.15,"tv":24443.05,"id":11439844}]}]}
{"op":"mcm","clk":"4234686564","pt":1631548813545,"mc":[{"id":"1.187560677","rc":[{"trd":[[7.6,4.93]],"batl":[[0,7.6,168.18]],"ltp":7.6,"tv":1357.01,"id":7588306},{"trd":[[1.15,555.09]],"batb":[[1,1.13,22.21],[2,1.12,336.04]],"ltp":1.15,"tv":24443.53,"id":11439844}],"tv":25800.55}]}
{"op":"mcm","clk":"4234686870","pt":1631548817153,"mc":[{"id":"1.187560677","rc":[{"batl":[[0,1.16,104.02],[2,1.21,183.5]],"ltp":1.15,"tv":24443.53,"id":11439844}]}]}
{"op":"mcm","clk":"4234687041","pt":1631548819560,"mc":[{"id":"1.187560677","rc":[{"trd":[[7.6,8.75]],"batl":[[0,7.6,164.36]],"ltp":7.6,"tv":1360.83,"id":7588306},{"trd":[[1.15,580.3]],"ltp":1.15,"tv":24468.73,"id":11439844}],"tv":25829.57}]}
{"op":"mcm","clk":"4234687088","pt":1631548820135,"mc":[{"id":"1.187560677","rc":[{"trd":[[7.6,9.28]],"batl":[[0,7.6,163.83]],"ltp":7.6,"tv":1361.36,"id":7588306},{"trd":[[1.15,583.78]],"ltp":1.15,"tv":24472.21,"id":11439844}],"tv":25833.58}]}
{"op":"mcm","clk":"4234687275","pt":1631548822644,"mc":[{"id":"1.187560677","rc":[{"batb":[[1,1.12,336.04],[2,1.11,415.72]],"ltp":1.15,"tv":24472.21,"id":11439844}]}]}
{"op":"mcm","clk":"4234687638","pt":1631548826669,"mc":[{"id":"1.187560677","rc":[{"trd":[[1.16,165.66]],"batb":[[0,1.14,121.25],[1,1.12,348.07]],"batl":[[0,1.16,101.85]],"ltp":1.16,"tv":24476.55,"id":11439844}],"tv":25837.92}]}
{"op":"mcm","clk":"4234687645","pt":1631548826730,"mc":[{"id":"1.187560677","rc":[{"batl":[[1,7.8,47.64],[2,8.2,59.3]],"ltp":7.6,"tv":1361.36,"id":7588306},{"batb":[[0,1.15,323.16],[1,1.14,526.26],[2,1.12,348.07]],"ltp":1.16,"tv":24476.55,"id":11439844}]}]}
{"op":"mcm","clk":"4234687989","pt":1631548830457,"mc":[{"id":"1.187560677","rc":[{"batb":[[0,7.2,68.24],[1,7,78.44],[2,6.8,9.83]],"ltp":7.6,"tv":1361.36,"id":7588306},{"batl":[[1,1.17,1172.17]],"ltp":1.16,"tv":24476.55,"id":11439844}]}]}
{"op":"mcm","clk":"4234688019","pt":1631548830878,"mc":[{"id":"1.187560677","rc":[{"trd":[[1.15,872.58]],"batb":[[0,1.15,178.75]],"ltp":1.15,"tv":24765.35,"id":11439844}],"tv":26126.72}]}
{"op":"mcm","clk":"4234688140","pt":1631548832583,"mc":[{"id":"1.187560677","rc":[{"batl":[[2,1.2,55.46]],"ltp":1.15,"tv":24765.35,"id":11439844}]}]}
{"op":"mcm","clk":"4234688241","pt":1631548833576,"mc":[{"id":"1.187560677","rc":[{"batl":[[0,7.8,47.64],[1,8.2,59.3],[2,9.4,5]],"ltp":7.6,"tv":1361.36,"id":7588306},{"batb":[[2,1.12,348.57]],"batl":[[1,1.17,1134.86]],"ltp":1.15,"tv":24765.35,"id":11439844}]}]}
{"op":"mcm","clk":"4234688276","pt":1631548834053,"mc":[{"id":"1.187560677","rc":[{"batb":[[0,5.7,3.92],[1,5.3,4.28],[2,1.6,767.39]],"batl":[[0,9.4,5],[1,10.5,3],[2,11,3]],"ltp":7.6,"tv":1361.36,"id":7588306},{"batb":[[0,1.12,145.78],[1,1.11,152.13],[2,1.1,164.71]],"batl":[[0,1.16,9.02],[1,1.2,55.46],[2,1.21,183.5]],"ltp":1.15,"tv":24765.35,"id":11439844}]}]}
{"op":"mcm","clk":"4234688867","pt":1631548841321,"mc":[{"id":"1.187560677","rc":[{"batb":[[0,1.12,133.75]],"ltp":1.15,"tv":24765.35,"id":11439844}]}]}
{"op":"mcm","clk":"4234688987","pt":1631548842381,"mc":[{"id":"1.187560677","rc":[{"batb":[[0,8,21],[1,7.6,5],[2,6.8,6]],"batl":[[0,8.6,5.22],[1,9.4,5],[2,10.5,3]],"ltp":7.6,"tv":1361.36,"id":7588306},{"trd":[[1.14,325.4]],"batb":[[0,1.13,924.63],[1,1.12,133.22],[2,1.11,152.13]],"batl":[[0,1.14,352.5],[1,1.15,141.78],[2,1.16,1184.57]],"ltp":1.14,"tv":24765.85,"id":11439844}],"tv":26127.21}]}
{"op":"mcm","clk":"4234689520","pt":1631548848292,"mc":[{"id":"1.187560677","rc":[{"batb":[[2,7.2,3.42]],"batl":[[2,10.5,5]],"ltp":7.6,"tv":1361.36,"id":7588306},{"batb":[[1,1.12,343.76],[2,1.11,371.72]],"batl":[[2,1.16,1388.29]],"ltp":1.14,"tv":24765.85,"id":11439844}]}]}
{"op":"mcm","clk":"4234689600","pt":1631548849299,"mc":[{"id":"1.187560677","rc":[{"batl":[[1,8.8,50.14],[2,9.2,24.6]],"ltp":7.6,"tv":1361.36,"id":7588306},{"batb":[[0,1.13,1315.15],[1,1.12,1092.95],[2,1.11,643.16]],"ltp":1.14,"tv":24765.85,"id":11439844}]}]}
{"op":"mcm","clk":"4234689769","pt":1631548851199,"mc":[{"id":"1.187560677","rc":[{"batl":[[0,1.14,362.81]],"ltp":1.14,"tv":24765.85,"id":11439844}]}]}
{"op":"mcm","clk":"4234689981","pt":1631548853501,"mc":[{"id":"1.187560677","rc":[{"batb":[[0,8,76.04],[1,7.6,66.02]],"ltp":7.6,"tv":1361.36,"id":7588306},{"batl":[[0,1.14,749.06],[1,1.15,545.09]],"ltp":1.14,"tv":24765.85,"id":11439844}]}]}
{"op":"mcm","clk":"4234690296","pt":1631548856604,"mc":[{"id":"1.187560677","rc":[{"batl":[[2,1.16,1379.27]],"ltp":1.14,"tv":24765.85,"id":11439844}]}]}
{"op":"mcm","clk":"4234690475","pt":1631548858295,"mc":[{"id":"1.187560677","rc":[{"batl":[[1,1.15,545.33]],"ltp":1.14,"tv":24765.85,"id":11439844}]}]}
{"op":"mcm","clk":"4234690807","pt":1631548861707,"mc":[{"id":"1.187560677","rc":[{"batb":[[0,8,5],[1,7.6,5]],"batl":[[0,9.2,24.6],[1,9.4,34.75],[2,9.6,44.06]],"ltp":7.6,"tv":1361.36,"id":7588306},{"batb":[[0,1.12,627.68],[1,1.11,643.16],[2,1.1,461.52]],"batl":[[0,1.14,108.31],[1,1.15,107.25],[2,1.16,203.72]],"ltp":1.14,"tv":24765.85,"id":11439844}]}]}
{"op":"mcm","clk":"4234690850","pt":1631548862182,"mc":[{"id":"1.187560677","rc":[{"batb":[[0,6.8,9.38],[1,5.9,41.46],[2,5.8,49.85]],"batl":[[1,9.4,31.75]],"ltp":7.6,"tv":1361.36,"id":7588306},{"batb":[[0,1.12,494.68]],"batl":[[0,1.14,10.31],[1,1.17,288.75],[2,1.2,55.46]],"ltp":1.14,"tv":24765.85,"id":11439844}]}]}
{"op":"mcm","clk":"4234691074","pt":1631548864800,"mc":[{"id":"1.187560677","rc":[{"batb":[[1,6.4,6],[2,5.9,41.46]],"ltp":7.6,"tv":1361.36,"id":7588306},{"batl":[[2,1.18,101]],"ltp":1.14,"tv":24765.85,"id":11439844}]}]}
{"op":"mcm","clk":"4234691247","pt":1631548866426,"mc":[{"id":"1.187560677","rc":[{"trd":[[8,39.99]],"batb":[[1,5.9,41.46],[2,5.8,49.85]],"batl":[[0,10.5,5],[1,11,3],[2,12.5,3]],"ltp":8.0,"tv":1362.26,"id":7588306},{"trd":[[1.14,331.71]],"batb":[[0,1.11,372.23],[1,1.1,164.71],[2,1.09,161.21]],"batl":[[0,1.14,4],[2,1.2,55.46]],"ltp":1.14,"tv":24772.16,"id":11439844}],"tv":26134.42}]}
{"op":"mcm","clk":"4234691381","pt":1631548867728,"mc":[{"id":"1.187560677","rc":[{"batl":[[0,1.17,288.75],[1,1.2,55.46],[2,1.21,377.87]],"ltp":1.14,"tv":24772.16,"id":11439844}]}]}
{"op":"mcm","clk":"4234691496","pt":1631548869093,"mc":[{"id":"1.187560677","rc":[{"trd":[[7.2,6.38],[7.6,9.32]],"batb":[[0,7.2,6],[1,6.8,13.97],[2,5.9,41.46]],"batl":[[0,7.6,230.73],[1,8.2,3],[2,9.4,3]],"ltp":7.2,"tv":1366.51,"id":7588306},{"trd":[[1.15,872.82],[1.16,191.79]],"batb":[[0,1.14,121],[1,1.12,133.51],[2,1.11,371.72]],"batl":[[0,1.16,76.87],[1,1.17,288.5],[2,1.19,907.62]],"ltp":1.16,"tv":24798.53,"id":11439844}],"tv":26165.05}]}
{"op":"mcm","clk":"4234691690","pt":1631548871390,"mc":[{"id":"1.187560677","rc":[{"batb":[[1,1.13,11.39],[2,1.12,133.22]],"ltp":1.16,"tv":24798.53,"id":11439844}]}]}
{"op":"mcm","clk":"4234691727","pt":1631548871915,"mc":[{"id":"1.187560677","rc":[{"batb":[[0,1.14,131.31]],"ltp":1.16,"tv":24798.53,"id":11439844}]}]}
{"op":"mcm","clk":"4234692065","pt":1631548876036,"mc":[{"id":"1.187560677","rc":[{"batl":[[2,8.6,33.25]],"ltp":7.2,"tv":1366.51,"id":7588306},{"batb":[[1,1.13,231.1],[2,1.12,412.34]],"ltp":1.16,"tv":24798.53,"id":11439844}]}]}
{"op":"mcm","clk":"4234692154","pt":1631548877238,"mc":[{"id":"1.187560677","rc":[{"batb":[[0,1.14,121]],"ltp":1.16,"tv":24798.53,"id":11439844}]}]}
{"op":"mcm","clk":"4234692339","pt":1631548879336,"mc":[{"id":"1.187560677","rc":[{"batb":[[1,6.8,9.38]],"ltp":7.2,"tv":1366.51,"id":7588306}]}]}
{"op":"mcm","clk":"4234692575","pt":1631548882244,"mc":[{"id":"1.187560677","rc":[{"batl":[[0,7.6,238.67]],"ltp":7.2,"tv":1366.51,"id":7588306},{"batl":[[1,1.17,330.14]],"ltp":1.16,"tv":24798.53,"id":11439844}]}]}
{"op":"mcm","clk":"4234692778","pt":1631548883642,"mc":[{"id":"1.187560677","rc":[{"batb":[[0,5,40.95],[1,4.9,42.56],[2,4.8,63.11]],"batl":[[0,8.6,33.25],[1,8.8,32.15],[2,9,45.74]],"ltp":7.2,"tv":1366.51,"id":7588306},{"batb":[[0,1.13,231.1],[1,1.12,412.34],[2,1.11,486.41]],"batl":[[0,1.2,55.46],[1,1.23,6],[2,1.25,322.9]],"ltp":1.16,"tv":24798.53,"id":11439844}]}]}
{"op":"mcm","clk":"4234693248","pt":1631548886626,"mc":[{"id":"1.187560677","rc":[{"batb":[[0,5.5,4.24],[1,5,40.95],[2,4.9,42.56]],"ltp":7.2,"tv":1366.51,"id":7588306},{"batl":[[1,1.22,164.25],[2,1.23,6]],"ltp":1.16,"tv":24798.53,"id":11439844}]}]}
{"op":"mcm","clk":"4234693340","pt":1631548887251,"mc":[{"id":"1.187560677","rc":[{"batb":[[0,5,40.95],[1,4.9,42.56],[2,4.8,63.11]],"ltp":7.2,"tv":1366.51,"id":7588306},{"batb":[[0,1.13,231.36]],"batl":[[1,1.23,6],[2,1.25,322.9]],"ltp":1.16,"tv":24798.53,"id":11439844}]}]}
{"op":"mcm","clk":"4234694825","pt":1631548900466,"mc":[{"id":"1.187560677","rc":[{"batb":[[0,5.5,4.24],[1,5,40.95],[2,4.9,42.56]],"ltp":7.2,"tv":1366.51,"id":7588306},{"batl":[[1,1.22,154.25],[2,1.23,6]],"ltp":1.16,"tv":24798.53,"id":11439844}]}]}
{"op":"mcm","clk":"4234694861","pt":1631548900734,"mc":[{"id":"1.187560677","rc":[{"batb":[[0,5,40.95],[1,4.9,42.56],[2,4.8,63.11]],"ltp":7.2,"tv":1366.51,"id":7588306},{"batl":[[1,1.23,6],[2,1.25,322.9]],"ltp":1.16,"tv":24798.53,"id":11439844}]}]}
{"op":"mcm","clk":"4234695420","pt":1631548905379,"mc":[{"id":"1.187560677","rc":[{"trd":[[1.13,142.36],[1.14,332.23]],"batb":[[0,1.13,229.36]],"ltp":1.13,"tv":24802.53,"id":11439844}],"tv":26169.05}]}
{"op":"mcm","clk":"4234695642","pt":1631548907445,"mc":[{"id":"1.187560677","rc":[{"batb":[[0,5.5,4.24],[1,5,40.95],[2,4.9,42.56]],"ltp":7.2,"tv":1366.51,"id":7588306},{"batl":[[1,1.22,164.25],[2,1.23,6]],"ltp":1.13,"tv":24802.53,"id":11439844}]}]}
{"op":"mcm","clk":"4234695762","pt":1631548908651,"mc":[{"id":"1.187560677","rc":[{"batb":[[0,5,40.95],[1,4.9,42.56],[2,4.8,63.11]],"ltp":7.2,"tv":1366.51,"id":7588306},{"batl":[[1,1.23,6],[2,1.25,322.9]],"ltp":1.13,"tv":24802.53,"id":11439844}]}]}
{"op":"mcm","clk":"4234696600","pt":1631548917301,"mc":[{"id":"1.187560677","rc":[{"batl":[[0,9.4,3],[1,10.5,3],[2,11,3]],"ltp":7.2,"tv":1366.51,"id":7588306},{"batb":[[0,1.13,9.65],[1,1.12,133.22],[2,1.11,152.13]],"ltp":1.13,"tv":24802.53,"id":11439844}]}]}
{"op":"mcm","clk":"4234696715","pt":1631548918659,"mc":[{"id":"1.187560677","rc":[{"batl":[[1,1.22,169.75],[2,1.23,6]],"ltp":1.13,"tv":24802.53,"id":11439844}]}]}
{"op":"mcm","clk":"4234696796","pt":1631548919453,"mc":[{"id":"1.187560677","rc":[{"batl":[[1,1.23,6],[2,1.25,322.9]],"ltp":1.13,"tv":24802.53,"id":11439844}]}]}
{"op":"mcm","clk":"4234696882","pt":1631548920601,"mc":[{"id":"1.187560677","rc":[{"trd":[[6,3.87]],"batb":[[0,5,160.33]],"batl":[[0,6.2,6.46],[1,7.6,942.39],[2,8.2,3]],"ltp":6.0,"tv":1370.38,"id":7588306},{"trd":[[1.2,60.81]],"batb":[[0,1.14,121],[1,1.13,136.65],[2,1.12,133.22]],"batl":[[0,1.2,16.77],[1,1.22,35.27],[2,1.23,6]],"ltp":1.2,"tv":24860.56,"id":11439844}],"tv":26230.95}]}
{"op":"mcm","clk":"4234697060","pt":1631548922594,"mc":[{"id":"1.187560677","rc":[{"trd":[[6.2,0.1]],"batl":[[0,6.2,6.36]],"ltp":6.2,"tv":1370.48,"id":7588306},{"trd":[[1.19,0.54]],"ltp":1.19,"tv":24861.1,"id":11439844}],"tv":26231.59}]}
{"op":"mcm","clk":"4234697543","pt":1631548927389,"mc":[{"id":"1.187560677","rc":[{"batl":[[2,7.8,2]],"ltp":6.2,"tv":1370.48,"id":7588306},{"batb":[[0,1.15,8.83],[1,1.14,129.89],[2,1.13,146.38]],"ltp":1.19,"tv":24861.1,"id":11439844}]}]}
{"op":"mcm","clk":"4234697890","pt":1631548930511,"mc":[{"id":"1.187560677","rc":[{"batl":[[1,1.23,6],[2,1.25,800.42]],"ltp":1.19,"tv":24861.1,"id":11439844}]}]}
{"op":"mcm","clk":"4234698055","pt":1631548932081,"mc":[{"id":"1.187560677","rc":[{"batl":[[0,1.23,6],[1,1.25,800.42],[2,1.26,182.67]],"ltp":1.19,"tv":24861.1,"id":11439844}]}]}
{"op":"mcm","clk":"4234698209","pt":1631548933487,"mc":[{"id":"1.187560677","rc":[{"trd":[[6.2,0.5]],"batl":[[0,6.2,12.16]],"ltp":6.2,"tv":1370.88,"id":7588306},{"trd":[[1.19,2.65]],"batl":[[0,1.21,38.38],[1,1.23,6],[2,1.25,800.42]],"ltp":1.19,"tv":24863.21,"id":11439844}],"tv":26234.1}]}
{"op":"mcm","clk":"4234698411","pt":1631548935602,"mc":[{"id":"1.187560677","rc":[{"trd":[[6.2,3.72]],"batl":[[0,6.2,8.94]],"ltp":6.2,"tv":1374.1,"id":7588306},{"trd":[[1.19,19.42]],"batb":[[1,1.14,130.16]],"ltp":1.19,"tv":24879.98,"id":11439844}],"tv":26254.08}]}
{"op":"mcm","clk":"4234698989","pt":1631548942410,"mc":[{"id":"1.187560677","rc":[{"batb":[[2,1.13,146.67]],"ltp":1.19,"tv":24879.98,"id":11439844}]}]}
{"op":"mcm","clk":"4234699563","pt":1631548949634,"mc":[{"id":"1.187560677","rc":[{"batb":[[0,3.5,5.28],[1,1.3,5],[2,1.01,105.79]],"batl":[[0,8.2,3],[1,8.8,5],[2,9.4,3]],"ltp":6.2,"tv":1374.1,"id":7588306},{"batb":[[0,1.14,121.27],[1,1.13,146.67],[2,1.12,133.22]],"batl":[[0,1.23,6],[1,1.31,2],[2,1.39,17.9]],"ltp":1.19,"tv":24879.98,"id":11439844}]}]}
{"op":"mcm","clk":"4234699633","pt":1631548950430,"mc":[{"id":"1.187560677","rc":[{"batl":[[0,1.19,9.02],[1,1.23,6],[2,1.31,2]],"ltp":1.19,"tv":24879.98,"id":11439844}]}]}
{"op":"mcm","clk":"4234700229","pt":1631548956507,"mc":[{"id":"1.187560677","rc":[{"batb":[[0,3.85,4.57],[1,3.5,5.28],[2,1.3,5]],"batl":[[0,7.8,2],[1,8.2,3],[2,8.8,5]],"ltp":6.2,"tv":1374.1,"id":7588306},{"batb":[[0,1.15,8.03],[1,1.14,121.27],[2,1.13,146.67]],"ltp":1.19,"tv":24879.98,"id":11439844}]}]}
{"op":"mcm","clk":"4234700307","pt":1631548957539,"mc":[{"id":"1.187560677","rc":[{"trd":[[6.2,5.45]],"batb":[[0,3.5,5.28],[1,1.3,5],[2,1.01,105.79]],"batl":[[0,8.2,3],[1,8.8,5],[2,9.4,3]],"ltp":6.2,"tv":1375.83,"id":7588306},{"trd":[[1.19,28.44]],"batb":[[0,1.14,121.27],[1,1.13,146.67],[2,1.12,133.22]],"batl":[[0,1.23,6],[1,1.31,2],[2,1.39,17.9]],"ltp":1.19,"tv":24889.0,"id":11439844}],"tv":26264.83}]}
{"op":"mcm","clk":"4234700323","pt":1631548957745,"mc":[{"id":"1.187560677","rc":[{"batl":[[0,7.8,3],[1,8.2,3],[2,8.8,5]],"ltp":6.2,"tv":1375.83,"id":7588306},{"batb":[[0,1.15,117],[1,1.14,121.27],[2,1.13,146.67]],"ltp":1.19,"tv":24889.0,"id":11439844}]}]}
{"op":"mcm","clk":"4234700457","pt":1631548959325,"mc":[{"id":"1.187560677","rc":[{"batb":[[0,5.3,20.78],[1,3.5,5.28],[2,1.3,5]],"batl":[[0,6,26.06],[1,7.8,3],[2,8.2,3]],"ltp":6.2,"tv":1375.83,"id":7588306},{"batl":[[0,1.23,25.5]],"ltp":1.19,"tv":24889.0,"id":11439844}]}]}
{"op":"mcm","clk":"4234700563","pt":1631548960353,"mc":[{"id":"1.187560677","rc":[{"batb":[[0,3.5,5.28],[1,1.3,5],[2,1.01,105.79]],"batl":[[0,7.8,3],[1,8.2,3],[2,8.8,5]],"ltp":6.2,"tv":1375.83,"id":7588306},{"batl":[[0,1.23,6]],"ltp":1.19,"tv":24889.0,"id":11439844}]}]}
{"op":"mcm","clk":"4234700917","pt":1631548963653,"mc":[{"id":"1.187560677","rc":[{"batb":[[0,3.85,5.37],[1,3.5,5.28],[2,1.3,5]],"batl":[[0,7.8,5]],"ltp":6.2,"tv":1375.83,"id":7588306},{"batb":[[0,1.15,125.23]],"batl":[[2,1.35,119.3]],"ltp":1.19,"tv":24889.0,"id":11439844}]}]}
{"op":"mcm","clk":"4234700944","pt":1631548963817,"mc":[{"id":"1.187560677","rc":[{"batb":[[0,3.5,5.28],[1,1.3,5],[2,1.01,105.79]],"batl":[[0,7.8,3]],"ltp":6.2,"tv":1375.83,"id":7588306},{"batb":[[0,1.15,117]],"batl":[[2,1.39,17.9]],"ltp":1.19,"tv":24889.0,"id":11439844}]}]}
{"op":"mcm","clk":"4234701607","pt":1631548970635,"mc":[{"id":"1.187560677","rc":[{"batb":[[0,3.85,5.17],[1,3.5,5.28],[2,1.3,5]],"ltp":6.2,"tv":1375.83,"id":7588306},{"batl":[[2,1.35,131.9]],"ltp":1.19,"tv":24889.0,"id":11439844}]}]}
{"op":"mcm","clk":"4234701650","pt":1631548971051,"mc":[{"id":"1.187560677","rc":[{"batb":[[0,3.5,5.28],[1,1.3,5],[2,1.01,105.79]],"ltp":6.2,"tv":1375.83,"id":7588306},{"batl":[[2,1.39,17.9]],"ltp":1.19,"tv":24889.0,"id":11439844}]}]}
{"op":"mcm","clk":"4234702163","pt":1631548976346,"mc":[{"id":"1.187560677","rc":[{"trd":[[5.3,7.49]],"batb":[[0,3.75,305.04],[1,3.5,5.28],[2,1.3,5]],"batl":[[0,6,3],[1,6.4,1704.02],[2,6.6,3]],"ltp":5.3,"tv":1377.22,"id":7588306},{"trd":[[1.23,111.73]],"batb":[[0,1.29,31],[1,1.28,97.19],[2,1.2,100]],"batl":[[0,1.3,24.86],[2,1.4,123.46]],"ltp":1.23,"tv":24895.0,"id":11439844}],"tv":26272.22}]}
{"op":"mcm","clk":"4234702257","pt":1631548977337,"mc":[{"id":"1.187560677","rc":[{"trd":[[4.3,9.25]],"ltp":4.3,"tv":1378.93,"id":7588306},{"trd":[[1.3,7.26]],"batl":[[0,1.3,19.22]],"ltp":1.3,"tv":24900.64,"id":11439844}],"tv":26279.57}]}
{"op":"mcm","clk":"4234702466","pt":1631548979568,"mc":[{"id":"1.187560677","rc":[{"trd":[[1.29,62.7]],"batb":[[0,1.28,97.19],[1,1.2,100],[2,1.19,103]],"ltp":1.29,"tv":24962.64,"id":11439844}],"tv":26341.57}]}
{"op":"mcm","clk":"4234703250","pt":1631548987660,"mc":[{"id":"1.187560677","rc":[{"batb":[[0,1.28,71]],"batl":[[0,1.31,2],[1,1.4,123.46],[2,1.94,3.08]],"ltp":1.29,"tv":24962.64,"id":11439844}]}]}
{"op":"mcm","clk":"4234703513","pt":1631548990475,"mc":[{"id":"1.187560677","rc":[{"batl":[[0,4.5,4.74],[1,6,3],[2,6.4,1704.02]],"ltp":4.3,"tv":1378.93,"id":7588306},{"batl":[[0,1.3,19.22],[1,1.31,2],[2,1.4,123.46]],"ltp":1.29,"tv":24962.64,"id":11439844}]}]}
{"op":"mcm","clk":"4234704209","pt":1631548998277,"mc":[{"id":"1.187560677","rc":[{"trd":[[1.3,12.13]],"batl":[[0,1.3,16.79]],"ltp":1.3,"tv":24967.5,"id":11439844}],"tv":26346.43}]}
{"op":"mcm","clk":"4234704329","pt":1631548999678,"mc":[{"id":"1.187560677","rc":[{"trd":[[1.28,32.92]],"batb":[[0,1.28,70.08]],"ltp":1.28,"tv":24969.34,"id":11439844}],"tv":26348.27}]}
{"op":"mcm","clk":"4234704415","pt":1631549000405,"mc":[{"id":"1.187560677","rc":[{"batb":[[0,4.3,72.18],[1,4.2,92.55],[2,4,6.15]],"ltp":4.3,"tv":1378.93,"id":7588306},{"batl":[[0,1.3,255.53],[1,1.31,298.73],[2,1.33,195.5]],"ltp":1.28,"tv":24969.34,"id":11439844}]}]}
{"op":"mcm","clk":"4234704536","pt":1631549001598,"mc":[{"id":"1.187560677","rc":[{"batb":[[2,3.75,305.04]],"batl":[[1,5.8,57.81],[2,6,64.73]],"ltp":4.3,"tv":1378.93,"id":7588306},{"batb":[[1,1.21,277.11],[2,1.2,408.66]],"batl":[[2,1.4,123.46]],"ltp":1.28,"tv":24969.34,"id":11439844}]}]}
{"op":"mcm","clk":"4234704949","pt":1631549006017,"mc":[{"id":"1.187560677","rc":[{"trd":[[4.3,109.22]],"batb":[[0,4.3,22.2]],"ltp":4.3,"tv":1478.9,"id":7588306}],"tv":26448.25}]}
{"op":"mcm","clk":"4234705093","pt":1631549007478,"mc":[{"id":"1.187560677","rc":[{"batb":[[2,4,6.08]],"ltp":4.3,"tv":1478.9,"id":7588306},{"batl":[[2,1.33,183.5]],"ltp":1.28,"tv":24969.34,"id":11439844}]}]}
{"op":"mcm","clk":"4234705187","pt":1631549008595,"mc":[{"id":"1.187560677","rc":[{"batb":[[2,3.75,305.04]],"batl":[[0,5.8,57.81],[1,6,64.73],[2,6.4,1704.02]],"ltp":4.3,"tv":1478.9,"id":7588306},{"batl":[[0,1.3,238.74],[2,1.4,123.46]],"ltp":1.28,"tv":24969.34,"id":11439844}]}]}
{"op":"mcm","clk":"4234705474","pt":1631549011510,"mc":[{"id":"1.187560677","rc":[{"batl":[[0,4.5,5.44],[1,4.6,77.59],[2,4.7,87.82]],"ltp":4.3,"tv":1478.9,"id":7588306},{"batb":[[1,1.27,606.05],[2,1.21,277.11]],"batl":[[0,1.3,16.79]],"ltp":1.28,"tv":24969.34,"id":11439844}]}]}
{"op":"mcm","clk":"4234705524","pt":1631549012185,"mc":[{"id":"1.187560677","rc":[{"batl":[[1,1.31,296.73]],"ltp":1.28,"tv":24969.34,"id":11439844}]}]}
{"op":"mcm","clk":"4234705789","pt":1631549015424,"mc":[{"id":"1.187560677","rc":[{"batb":[[2,4,7.08]],"ltp":4.3,"tv":1478.9,"id":7588306},{"batl":[[2,1.33,194.5]],"ltp":1.28,"tv":24969.34,"id":11439844}]}]}
{"op":"mcm","clk":"4234705840","pt":1631549016006,"mc":[{"id":"1.187560677","rc":[{"batb":[[0,3.75,305.04],[1,3.5,5.28],[2,1.3,5]],"batl":[[1,6,3],[2,6.4,1704.02]],"ltp":4.3,"tv":1478.9,"id":7588306},{"batb":[[1,1.2,100],[2,1.19,103]],"batl":[[1,1.4,123.46],[2,1.94,3.08]],"ltp":1.28,"tv":24969.34,"id":11439844}]}]}
{"op":"mcm","clk":"4234706149","pt":1631549019332,"mc":[{"id":"1.187560677","rc":[{"trd":[[1.3,12.89]],"batl":[[0,1.3,16.41]],"ltp":1.3,"tv":24970.1,"id":11439844}],"tv":26449.01}]}
{"op":"mcm","clk":"4234706361","pt":1631549021613,"mc":[{"id":"1.187560677","rc":[{"batb":[[0,3.5,5.28],[1,1.3,5],[2,1.01,105.79]],"batl":[[0,6,3],[1,6.4,3],[2,6.6,3]],"ltp":4.3,"tv":1478.9,"id":7588306},{"batl":[[0,1.4,123.46],[1,1.94,3.08],[2,3.8,27.43]],"ltp":1.3,"tv":24970.1,"id":11439844}]}]}
{"op":"mcm","clk":"4234706444","pt":1631549022607,"mc":[{"id":"1.187560677","rc":[{"batb":[[0,4,6.83]],"ltp":4.3,"tv":1478.9,"id":7588306},{"batb":[[0,1.2,100],[1,1.19,103],[2,1.18,106]],"batl":[[0,1.33,173.5],[1,1.4,123.46],[2,1.94,3.08]],"ltp":1.3,"tv":24970.1,"id":11439844}]}]}
{"op":"mcm","clk":"4234706967","pt":1631549028448,"mc":[{"id":"1.187560677","rc":[{"batb":[[0,1.2,100.26]],"ltp":1.3,"tv":24970.1,"id":11439844}]}]}
{"op":"mcm","clk":"4234707043","pt":1631549029543,"mc":[{"id":"1.187560677","rc":[{"batb":[[0,1.2,100.52]],"ltp":1.3,"tv":24970.1,"id":11439844}]}]}
{"op":"mcm","clk":"4234707097","pt":1631549030117,"mc":[{"id":"1.187560677","rc":[{"trd":[[4,25.88]],"batb":[[0,3.6,211.06]],"batl":[[0,4,200.03],[1,4.4,2],[2,6,3]],"ltp":4.0,"tv":1504.72,"id":7588306},{"trd":[[1.33,370.48]],"batb":[[0,1.31,65],[1,1.3,4.3],[2,1.2,100]],"batl":[[0,1.4,123.46],[1,1.94,3.08],[2,3.8,27.43]],"ltp":1.33,"tv":25307.42,"id":11439844}],"tv":26812.15}]}
{"op":"mcm","clk":"4234707373","pt":1631549033313,"mc":[{"id":"1.187560677","rc":[{"trd":[[4,30.35]],"batl":[[0,4,195.56],[1,4.2,8.06],[2,4.4,2]],"ltp":4.0,"tv":1509.19,"id":7588306},{"trd":[[1.33,383.92]],"ltp":1.33,"tv":25320.86,"id":11439844}],"tv":26830.06}]}
{"op":"mcm","clk":"4234707660","pt":1631549036559,"mc":[{"id":"1.187560677","rc":[{"batb":[[0,3.9,3.56],[1,3.6,211.06],[2,1.3,5]],"ltp":4.0,"tv":1509.19,"id":7588306},{"batb":[[2,1.28,96.82]],"batl":[[0,1.34,98.25],[1,1.4,123.46],[2,1.94,3.08]],"ltp":1.33,"tv":25320.86,"id":11439844}]}]}
{"op":"mcm","clk":"4234708010","pt":1631549040520,"mc":[{"id":"1.187560677","rc":[{"batb":[[1,3.75,3.83],[2,3.7,3.52]],"batl":[[1,4.4,2],[2,4.5,4.45]],"ltp":4.0,"tv":1509.19,"id":7588306},{"batb":[[2,1.29,81.24]],"batl":[[1,1.36,93.32],[2,1.37,97.5]],"ltp":1.33,"tv":25320.86,"id":11439844}]}]}
{"op":"mcm","clk":"4234708207","pt":1631549042663,"mc":[{"id":"1.187560677","rc":[{"batb":[[0,3.7,3.52],[1,1.3,5],[2,1.01,105.79]],"batl":[[0,4.4,2],[1,4.8,4.27],[2,6,3]],"ltp":4.0,"tv":1509.19,"id":7588306},{"batb":[[0,1.3,4.3],[1,1.27,4.87],[2,1.2,100]],"batl":[[0,1.4,123.46],[1,1.94,3.08],[2,3.8,27.43]],"ltp":1.33,"tv":25320.86,"id":11439844}]}]}
{"op":"mcm","clk":"4234708253","pt":1631549043127,"mc":[{"id":"1.187560677","rc":[{"trd":[[3.9,127.79]],"batl":[[1,4.8,2.27]],"ltp":3.9,"tv":1509.28,"id":7588306},{"trd":[[1.35,9965.18]],"batb":[[1,1.2,100],[2,1.19,103]],"ltp":1.35,"tv":25321.12,"id":11439844}],"tv":26830.41}]}
{"op":"mcm","clk":"4234708365","pt":1631549044530,"mc":[{"id":"1.187560677","rc":[{"batb":[[0,1.3,3.78]],"ltp":1.35,"tv":25321.12,"id":11439844}]}]}
{"op":"mcm","clk":"4234708528","pt":1631549046560,"mc":[{"id":"1.187560677","rc":[{"batb":[[1,1.27,92.87],[2,1.2,100]],"batl":[[0,1.37,86.5],[1,1.4,123.46],[2,1.94,3.08]],"ltp":1.35,"tv":25321.12,"id":11439844}]}]}
{"op":"mcm","clk":"4234708622","pt":1631549047661,"mc":[{"id":"1.187560677","rc":[{"batb":[[2,1.2,100.52]],"ltp":1.35,"tv":25321.12,"id":11439844}]}]}
{"op":"mcm","clk":"4234708771","pt":1631549049546,"mc":[{"id":"1.187560677","rc":[{"batl":[[1,4.8,4.27]],"ltp":3.9,"tv":1509.28,"id":7588306},{"batb":[[1,1.27,97.48]],"ltp":1.35,"tv":25321.12,"id":11439844}]}]}
{"op":"mcm","clk":"4234708801","pt":1631549049856,"mc":[{"id":"1.187560677","rc":[{"batl":[[1,4.8,2.27]],"ltp":3.9,"tv":1509.28,"id":7588306},{"batb":[[1,1.27,92.87]],"batl":[[2,1.94,3.33]],"ltp":1.35,"tv":25321.12,"id":11439844}]}]}
{"op":"mcm","clk":"4234709451","pt":1631549056688,"mc":[{"id":"1.187560677","rc":[{"batl":[[1,4.8,4.27]],"ltp":3.9,"tv":1509.28,"id":7588306},{"batb":[[1,1.27,97.74]],"ltp":1.35,"tv":25321.12,"id":11439844}]}]}
{"op":"mcm","clk":"4234709500","pt":1631549057180,"mc":[{"id":"1.187560677","rc":[{"batl":[[0,4.8,2.27],[1,6,3],[2,6.4,3]],"ltp":3.9,"tv":1509.28,"id":7588306},{"batb":[[0,1.27,92.87],[1,1.2,100.52],[2,1.19,103]],"batl":[[0,1.4,123.46],[1,1.94,3.33],[2,3.8,27.43]],"ltp":1.35,"tv":25321.12,"id":11439844}]}]}
{"op":"mcm","clk":"4234709714","pt":1631549059686,"mc":[{"id":"1.187560677","rc":[{"batb":[[0,4.3,5.36],[1,4.1,11.54],[2,3.95,50.64]],"batl":[[0,4.5,7.1],[1,4.8,2.27],[2,6,3]],"ltp":3.9,"tv":1509.28,"id":7588306},{"batb":[[0,1.29,697.99],[1,1.27,92.87],[2,1.2,100.52]],"batl":[[0,1.31,909.64],[1,1.32,108.11],[2,1.34,679.37]],"ltp":1.35,"tv":25321.12,"id":11439844}]}]}
{"op":"mcm","clk":"4234709735","pt":1631549059952,"mc":[{"id":"1.187560677","rc":[{"trd":[[4.3,110.28]],"batb":[[0,4.3,4.3],[2,3.95,10.12]],"ltp":4.3,"tv":1510.34,"id":7588306},{"trd":[[1.31,3.52]],"batb":[[1,1.27,166.87]],"batl":[[0,1.32,108.11],[1,1.34,679.37],[2,1.4,123.46]],"ltp":1.31,"tv":25324.6,"id":11439844}],"tv":26834.95}]}
{"op":"mcm","clk":"4234710323","pt":1631549066666,"mc":[{"id":"1.187560677","rc":[{"trd":[[4.3,113.98]],"batb":[[0,4.1,12.14],[1,4,3.29]],"batl":[[2,5.2,2.03]],"ltp":4.3,"tv":1514.04,"id":7588306},{"trd":[[1.31,15.65]],"batb":[[2,1.24,118.77]],"batl":[[1,1.33,90.5],[2,1.34,776.62]],"ltp":1.31,"tv":25336.74,"id":11439844}],"tv":26850.78}]}
{"op":"mcm","clk":"4234710617","pt":1631549070091,"mc":[{"id":"1.187560677","rc":[{"batb":[[0,4.1,11.54]],"batl":[[0,4.8,2.27],[1,5.2,2.03],[2,5.6,2]],"ltp":4.3,"tv":1514.04,"id":7588306}]}]}
{"op":"mcm","clk":"4234710893","pt":1631549072964,"mc":[{"id":"1.187560677","rc":[{"batl":[[0,4.4,5.71],[1,4.8,2.27],[2,5.2,2.03]],"ltp":4.3,"tv":1514.04,"id":7588306},{"batl":[[0,1.31,17.84],[1,1.32,108.11],[2,1.33,90.5]],"ltp":1.31,"tv":25336.74,"id":11439844}]}]}
{"op":"mcm","clk":"4234711239","pt":1631549076961,"mc":[{"id":"1.187560677","rc":[{"batl":[[0,4.8,2.27],[1,5.2,2.03],[2,5.6,2]],"ltp":4.3,"tv":1514.04,"id":7588306},{"batl":[[0,1.32,108.11],[1,1.33,90.5],[2,1.34,776.62]],"ltp":1.31,"tv":25336.74,"id":11439844}]}]}
{"op":"mcm","clk":"4234711493","pt":1631549079886,"mc":[{"id":"1.187560677","rc":[{"batl":[[0,4.4,5.71],[1,4.8,2.27],[2,5.2,2.03]],"ltp":4.3,"tv":1514.04,"id":7588306},{"batl":[[0,1.31,17.84],[1,1.32,108.11],[2,1.33,90.5]],"ltp":1.31,"tv":25336.74,"id":11439844}]}]}
{"op":"mcm","clk":"4234712003","pt":1631549085668,"mc":[{"id":"1.187560677","rc":[{"trd":[[4.2,2]],"ltp":4.2,"tv":1516.04,"id":7588306},{"trd":[[1.31,22.06]],"batl":[[0,1.31,11.43]],"ltp":1.31,"tv":25343.15,"id":11439844}],"tv":26859.19}]}
{"op":"mcm","clk":"4234712143","pt":1631549087189,"mc":[{"id":"1.187560677","rc":[{"batb":[[0,3.9,3.46],[1,1.3,5],[2,1.01,105.79]],"batl":[[0,5.6,2],[1,6,3],[2,6.4,3]],"ltp":4.2,"tv":1516.04,"id":7588306},{"batb":[[0,1.22,113.36],[1,1.2,100],[2,1.19,103]],"batl":[[0,1.34,97.25],[1,1.4,123.46],[2,1.44,94.65]],"ltp":1.31,"tv":25343.15,"id":11439844}]}]}
{"op":"mcm","clk":"4234712434","pt":1631549090616,"mc":[{"id":"1.187560677","rc":[{"batl":[[0,5.2,2.28],[1,5.6,2],[2,6,3]],"ltp":4.2,"tv":1516.04,"id":7588306},{"batb":[[0,1.24,100.77],[1,1.22,113.36],[2,1.2,100]],"ltp":1.31,"tv":25343.15,"id":11439844}]}]}
{"op":"mcm","clk":"4234712459","pt":1631549090780,"mc":[{"id":"1.187560677","rc":[{"batl":[[0,5.6,2],[1,6,3],[2,6.4,3]],"ltp":4.2,"tv":1516.04,"id":7588306},{"batb":[[0,1.22,113.36],[1,1.2,100],[2,1.19,103]],"ltp":1.31,"tv":25343.15,"id":11439844}]}]}
{"op":"mcm","clk":"4234712726","pt":1631549093703,"mc":[{"id":"1.187560677","rc":[{"batl":[[0,4.2,839.64],[1,4.6,3.64],[2,5.6,2]],"ltp":4.2,"tv":1516.04,"id":7588306},{"batb":[[0,1.3,153.84],[1,1.22,113.36],[2,1.2,100]],"ltp":1.31,"tv":25343.15,"id":11439844}]}]}
{"op":"mcm","clk":"4234712769","pt":1631549094234,"mc":[{"id":"1.187560677","rc":[{"trd":[[4,38.21]],"batl":[[0,4,2.17],[1,5.6,2],[2,6,3]],"ltp":4.0,"tv":1523.9,"id":7588306},{"trd":[[1.33,578.92]],"batb":[[0,1.33,415.57],[1,1.31,65],[2,1.3,30.76]],"batl":[[1,1.35,15],[2,1.38,628.63]],"ltp":1.33,"tv":25538.15,"id":11439844}],"tv":27062.05}]}
{"op":"mcm","clk":"4234712953","pt":1631549095893,"mc":[{"id":"1.187560677","rc":[{"batl":[[0,5.6,2],[1,6,3],[2,6.4,3]],"ltp":4.0,"tv":1523.9,"id":7588306},{"batl":[[1,1.38,628.63],[2,1.4,123.46]],"ltp":1.33,"tv":25538.15,"id":11439844}]}]}
{"op":"mcm","clk":"4234713436","pt":1631549098813,"mc":[{"id":"1.187560677","rc":[{"batb":[[0,3.9,9.21]],"ltp":4.0,"tv":1523.9,"id":7588306},{"trd":[[1.34,1974.96]],"batb":[[0,1.33,429.13]],"batl":[[0,1.34,85.31]],"ltp":1.34,"tv":25562.02,"id":11439844}],"tv":27085.93}]}
{"op":"mcm","clk":"4234713629","pt":1631549100605,"mc":[{"id":"1.187560677","rc":[{"batb":[[1,3.75,3.31],[2,3.7,3.32]],"batl":[[0,4.5,2.57],[1,4.8,2.52],[2,5.6,2]],"ltp":4.0,"tv":1523.9,"id":7588306},{"batl":[[1,1.36,67.07],[2,1.37,69.5]],"ltp":1.34,"tv":25562.02,"id":11439844}]}]}
{"op":"mcm","clk":"4234714022","pt":1631549104035,"mc":[{"id":"1.187560677","rc":[{"batb":[[0,3.9,3.46]],"ltp":4.0,"tv":1523.9,"id":7588306},{"batb":[[0,1.33,415.57]],"ltp":1.34,"tv":25562.02,"id":11439844}]}]}
{"op":"mcm","clk":"4234714470","pt":1631549107631,"mc":[{"id":"1.187560677","rc":[{"batb":[[0,3.9,9.21]],"ltp":4.0,"tv":1523.9,"id":7588306},{"trd":[[1.33,902.22]],"batb":[[0,1.33,267.48]],"ltp":1.33,"tv":25885.32,"id":11439844}],"tv":27409.23}]}
{"op":"mcm","clk":"4234715574","pt":1631549117640,"mc":[{"id":"1.187560677","rc":[{"batb":[[2,1.3,15.38]],"ltp":1.33,"tv":25885.32,"id":11439844}]}]}
{"op":"mcm","clk":"4234715637","pt":1631549118158,"mc":[{"id":"1.187560677","rc":[{"batb":[[0,3.7,3.32],[1,1.3,5],[2,1.01,105.79]],"batl":[[0,4.8,2.52],[1,6,3],[2,6.4,3]],"ltp":4.0,"tv":1523.9,"id":7588306},{"batb":[[0,1.27,97.87],[1,1.2,100.52],[2,1.19,103]],"batl":[[0,1.4,123.46],[1,1.44,94.65],[2,1.94,3.33]],"ltp":1.33,"tv":25885.32,"id":11439844}]}]}
{"op":"mcm","clk":"4234716033","pt":1631549121562,"mc":[{"id":"1.187560677","rc":[{"batb":[[0,1.34,10],[1,1.27,97.87],[2,1.2,100.52]],"batl":[[0,1.37,60.5],[1,1.4,123.46],[2,1.44,94.65]],"ltp":1.33,"tv":25885.32,"id":11439844}]}]}
{"op":"mcm","clk":"4234716434","pt":1631549124685,"mc":[{"id":"1.187560677","rc":[{"trd":[[3.95,19.3]],"batb":[[0,3.75,3.39],[1,3.7,3.32],[2,1.3,5]],"ltp":3.95,"tv":1527.29,"id":7588306},{"trd":[[1.34,1984.96]],"batb":[[0,1.27,97.87],[1,1.2,100.52],[2,1.19,103]],"batl":[[0,1.36,72.57],[1,1.37,60.5],[2,1.4,123.46]],"ltp":1.34,"tv":25895.32,"id":11439844}],"tv":27422.62}]}
{"op":"mcm","clk":"4234716478","pt":1631549125061,"mc":[{"id":"1.187560677","rc":[{"batb":[[0,3.7,3.32],[1,1.3,5],[2,1.01,105.79]],"ltp":3.95,"tv":1527.29,"id":7588306},{"batl":[[0,1.37,60.5],[1,1.4,123.46],[2,1.44,94.65]],"ltp":1.34,"tv":25895.32,"id":11439844}]}]}
{"op":"mcm","clk":"4234717455","pt":1631549131654,"mc":[{"id":"1.187560677","rc":[{"batb":[[0,3.75,3.23],[1,3.7,3.32],[2,1.3,5]],"batl":[[0,4.5,2.41],[1,4.8,2.52],[2,6,3]],"ltp":3.95,"tv":1527.29,"id":7588306},{"batb":[[0,1.29,79.81],[1,1.27,97.87],[2,1.2,100.52]],"batl":[[0,1.36,70.57],[1,1.37,60.5],[2,1.4,123.46]],"ltp":1.34,"tv":25895.32,"id":11439844}]}]}
{"op":"mcm","clk":"4234717502","pt":1631549131971,"mc":[{"id":"1.187560677","rc":[{"batb":[[0,3.7,3.32],[1,1.3,5],[2,1.01,105.79]],"batl":[[0,4.8,2.52],[1,6,3],[2,6.4,3]],"ltp":3.95,"tv":1527.29,"id":7588306},{"batb":[[0,1.27,97.87],[1,1.2,100.52],[2,1.19,103]],"batl":[[0,1.37,60.5],[1,1.4,123.46],[2,1.44,94.65]],"ltp":1.34,"tv":25895.32,"id":11439844}]}]}
{"op":"mcm","clk":"4234718497","pt":1631549142567,"mc":[{"id":"1.187560677","rc":[{"batb":[[0,3.75,2.91],[1,3.7,3.32],[2,1.3,5]],"batl":[[0,4.5,2.07],[1,4.8,2.52],[2,6,3]],"ltp":3.95,"tv":1527.29,"id":7588306},{"batb":[[0,1.29,72.81],[1,1.27,97.87],[2,1.2,100.52]],"batl":[[0,1.36,62.82],[1,1.37,60.5],[2,1.4,123.46]],"ltp":1.34,"tv":25895.32,"id":11439844}]}]}
{"op":"mcm","clk":"4234718551","pt":1631549143173,"mc":[{"id":"1.187560677","rc":[{"batb":[[0,4.2,4.67]],"batl":[[0,4.7,268.29]],"ltp":3.95,"tv":1527.29,"id":7588306},{"batb":[[0,1.28,98.33]],"batl":[[0,1.3,22.31],[1,1.31,45.5],[2,1.32,30.3]],"ltp":1.34,"tv":25895.32,"id":11439844}]}]}
{"op":"mcm","clk":"4234718972","pt":1631549148784,"mc":[{"id":"1.187560677","rc":[{"trd":[[1.28,48.76]],"batb":[[0,1.28,90.41]],"ltp":1.28,"tv":25911.16,"id":11439844}],"tv":27438.46}]}
{"op":"mcm","clk":"4234719073","pt":1631549150262,"mc":[{"id":"1.187560677","rc":[{"batb":[[1,3.9,2.96],[2,3.75,2.87]],"batl":[[2,5.6,2.01]],"ltp":3.95,"tv":1527.29,"id":7588306},{"batb":[[2,1.22,116.86]],"ltp":1.28,"tv":25911.16,"id":11439844}]}]}
{"op":"mcm","clk":"4234719836","pt":1631549158990,"mc":[{"id":"1.187560677","rc":[{"batb":[[0,1.28,71]],"batl":[[0,1.31,45.5],[1,1.32,30.3],[2,1.34,65.75]],"ltp":1.28,"tv":25911.16,"id":11439844}]}]}
{"op":"mcm","clk":"4234720080","pt":1631549161926,"mc":[{"id":"1.187560677","rc":[{"batb":[[0,4.4,4.77],[1,4.2,4.67],[2,3.9,2.96]],"ltp":3.95,"tv":1527.29,"id":7588306},{"batb":[[0,1.28,90.41]],"ltp":1.28,"tv":25911.16,"id":11439844}]}]}
{"op":"mcm","clk":"4234720702","pt":1631549169704,"mc":[{"id":"1.187560677","rc":[{"batl":[[1,1.32,15.15]],"ltp":1.28,"tv":25911.16,"id":11439844}]}]}
{"op":"mcm","clk":"4234720737","pt":1631549170124,"mc":[{"id":"1.187560677","rc":[{"batb":[[0,3.75,2.87],[1,1.3,5],[2,1.01,105.79]],"batl":[[0,6,3],[1,6.4,5.04],[2,6.6,3]],"ltp":3.95,"tv":1527.29,"id":7588306},{"batb":[[0,1.2,100.52],[1,1.19,250.71],[2,1.18,106]],"batl":[[0,1.36,73.32],[1,1.4,123.46],[2,1.44,94.65]],"ltp":1.28,"tv":25911.16,"id":11439844}]}]}
{"op":"mcm","clk":"4234721024","pt":1631549173613,"mc":[{"id":"1.187560677","rc":[{"batl":[[0,5.6,2.01],[1,6,3],[2,6.4,5.04]],"ltp":3.95,"tv":1527.29,"id":7588306},{"batb":[[0,1.22,98.86],[1,1.2,100],[2,1.19,250.71]],"ltp":1.28,"tv":25911.16,"id":11439844}]}]}
{"op":"mcm","clk":"4234721121","pt":1631549174711,"mc":[{"id":"1.187560677","rc":[{"batl":[[0,6,3],[1,6.4,5.04],[2,6.6,3]],"ltp":3.95,"tv":1527.29,"id":7588306},{"batb":[[0,1.2,100.52],[1,1.19,250.71],[2,1.18,106]],"batl":[[0,1.32,464.25],[1,1.36,73.32],[2,1.4,123.46]],"ltp":1.28,"tv":25911.16,"id":11439844}]}]}
{"op":"mcm","clk":"4234721229","pt":1631549175703,"mc":[{"id":"1.187560677","rc":[{"batb":[[0,4.5,19.42],[1,3.75,2.87],[2,1.3,5]],"batl":[[0,4.7,21.15],[1,6,3],[2,6.4,5.04]],"ltp":3.95,"tv":1527.29,"id":7588306},{"batl":[[0,1.29,21.5]],"ltp":1.28,"tv":25911.16,"id":11439844}]}]}
{"op":"mcm","clk":"4234721261","pt":1631549176013,"mc":[{"id":"1.187560677","rc":[{"batb":[[0,3.75,2.87],[1,1.3,5],[2,1.01,105.79]],"batl":[[0,6,3],[1,6.4,5.04],[2,6.6,3]],"ltp":3.95,"tv":1527.29,"id":7588306},{"batl":[[0,1.36,73.32],[1,1.4,123.46],[2,1.44,94.65]],"ltp":1.28,"tv":25911.16,"id":11439844}]}]}
{"op":"mcm","clk":"4234721598","pt":1631549179314,"mc":[{"id":"1.187560677","rc":[{"batb":[[0,1.21,7.39],[1,1.2,100],[2,1.19,250.71]],"ltp":1.28,"tv":25911.16,"id":11439844}]}]}
{"op":"mcm","clk":"4234722167","pt":1631549184401,"mc":[{"id":"1.187560677","rc":[{"batl":[[0,5.6,2.01],[1,6,3],[2,6.4,5.04]],"ltp":3.95,"tv":1527.29,"id":7588306},{"batb":[[0,1.22,131.36],[1,1.21,6.87],[2,1.2,100]],"ltp":1.28,"tv":25911.16,"id":11439844}]}]}
{"op":"mcm","clk":"4234722303","pt":1631549185440,"mc":[{"id":"1.187560677","rc":[{"batl":[[0,6,3],[1,6.4,5.04],[2,6.6,3]],"ltp":3.95,"tv":1527.29,"id":7588306},{"batb":[[0,1.22,7.08]],"ltp":1.28,"tv":25911.16,"id":11439844}]}]}
{"op":"mcm","clk":"4234722591","pt":1631549187332,"mc":[{"id":"1.187560677","rc":[{"batb":[[0,3.9,2.56],[1,3.75,2.87],[2,1.3,5]],"ltp":3.95,"tv":1527.29,"id":7588306},{"batl":[[0,1.34,86.25],[1,1.36,73.32],[2,1.4,123.46]],"ltp":1.28,"tv":25911.16,"id":11439844}]}]}
{"op":"mcm","clk":"4234722721","pt":1631549188222,"mc":[{"id":"1.187560677","rc":[{"batb":[[0,3.75,2.87],[1,1.3,5],[2,1.01,105.79]],"ltp":3.95,"tv":1527.29,"id":7588306},{"batl":[[0,1.36,73.32],[1,1.4,123.46],[2,1.44,94.65]],"ltp":1.28,"tv":25911.16,"id":11439844}]}]}
{"op":"mcm","clk":"4234723393","pt":1631549195642,"mc":[{"id":"1.187560677","rc":[{"batl":[[0,6.4,2.04],[1,8.2,3],[2,8.8,3]],"ltp":3.95,"tv":1527.29,"id":7588306},{"batb":[[2,1.19,147.71]],"ltp":1.28,"tv":25911.16,"id":11439844}]}]}
{"op":"mcm","clk":"4234723421","pt":1631549195955,"mc":[{"id":"1.187560677","rc":[{"batl":[[0,1.4,123.46],[1,1.44,94.65],[2,1.94,3.33]],"ltp":1.28,"tv":25911.16,"id":11439844}]}]}
{"op":"mcm","clk":"4234723521","pt":1631549197048,"mc":[{"id":"1.187560677","rc":[{"batb":[[1,1.19,147.71],[2,1.14,121.27]],"ltp":1.28,"tv":25911.16,"id":11439844}]}]}
{"op":"mcm","clk":"4234723656","pt":1631549198663,"mc":[{"id":"1.187560677","rc":[{"batb":[[0,5.2,7.7],[1,5.1,4.24],[2,3.75,2.87]],"batl":[[0,5.5,4.31],[1,5.7,216.7],[2,6.4,2.04]],"ltp":3.95,"tv":1527.29,"id":7588306},{"batb":[[0,1.21,95.52]],"batl":[[0,1.24,91.07],[1,1.3,2625.95],[2,1.4,123.46]],"ltp":1.28,"tv":25911.16,"id":11439844}]}]}
{"op":"mcm","clk":"4234724253","pt":1631549205237,"mc":[{"id":"1.187560677","rc":[{"batb":[[2,4,2.68]],"ltp":3.95,"tv":1527.29,"id":7588306},{"batl":[[2,1.33,83.5]],"ltp":1.28,"tv":25911.16,"id":11439844}]}]}
{"op":"mcm","clk":"4234724351","pt":1631549206451,"mc":[{"id":"1.187560677","rc":[{"trd":[[5.5,2.32]],"batl":[[0,5.5,1.99]],"ltp":5.5,"tv":1529.61,"id":7588306},{"trd":[[1.22,11.5]],"batb":[[0,1.21,95]],"ltp":1.22,"tv":25922.66,"id":11439844}],"tv":27452.28}]}
{"op":"mcm","clk":"4234724522","pt":1631549208470,"mc":[{"id":"1.187560677","rc":[{"batb":[[2,4.3,2.78]],"ltp":5.5,"tv":1529.61,"id":7588306},{"batl":[[1,1.3,2696.2]],"ltp":1.22,"tv":25922.66,"id":11439844}]}]}
{"op":"mcm","clk":"4234725255","pt":1631549216646,"mc":[{"id":"1.187560677","rc":[{"batl":[[0,5.7,216.7],[1,6.4,2.04],[2,8.2,3]],"ltp":5.5,"tv":1529.61,"id":7588306},{"batl":[[0,1.24,52.48]],"ltp":1.22,"tv":25922.66,"id":11439844}]}]}
{"op":"mcm","clk":"4234725469","pt":1631549219562,"mc":[{"id":"1.187560677","rc":[{"batb":[[0,1.22,16.82],[1,1.21,95],[2,1.19,147.71]],"batl":[[0,1.23,17.45],[1,1.24,52.48],[2,1.3,2696.2]],"ltp":1.22,"tv":25922.66,"id":11439844}]}]}
{"op":"mcm","clk":"4234725861","pt":1631549224085,"mc":[{"id":"1.187560677","rc":[{"batb":[[0,4,2.68],[1,1.3,5],[2,1.01,105.79]],"batl":[[0,8.2,3],[1,8.8,5],[2,9.4,3]],"ltp":5.5,"tv":1529.61,"id":7588306},{"batb":[[0,1.14,121.27],[1,1.13,331.67],[2,1.12,133.22]],"batl":[[0,1.33,83.5],[1,1.4,123.96],[2,1.44,94.65]],"ltp":1.22,"tv":25922.66,"id":11439844}]}]}
{"op":"mcm","clk":"4234727839","pt":1631549244692,"mc":[{"id":"1.187560677","rc":[{"batb":[[0,4.3,2.48],[1,4,2.68],[2,1.3,5]],"ltp":5.5,"tv":1529.61,"id":7588306},{"batl":[[0,1.3,87.85],[1,1.33,83.5],[2,1.4,123.96]],"ltp":1.22,"tv":25922.66,"id":11439844}]}]}
{"op":"mcm","clk":"4234727866","pt":1631549244902,"mc":[{"id":"1.187560677","rc":[{"batb":[[0,4,2.68],[1,1.3,5],[2,1.01,105.79]],"ltp":5.5,"tv":1529.61,"id":7588306},{"batl":[[0,1.33,83.5],[1,1.4,123.96],[2,1.44,94.65]],"ltp":1.22,"tv":25922.66,"id":11439844}]}]}
{"op":"mcm","clk":"4234728292","pt":1631549249598,"mc":[{"id":"1.187560677","rc":[{"batl":[[0,8.8,5],[1,9.4,3],[2,10.5,3]],"ltp":5.5,"tv":1529.61,"id":7588306},{"batb":[[0,1.13,331.95],[1,1.12,133.22],[2,1.11,152.13]],"batl":[[0,1.4,123.96],[1,1.44,94.65],[2,1.94,3.33]],"ltp":1.22,"tv":25922.66,"id":11439844}]}]}
{"op":"mcm","clk":"4234728312","pt":1631549249901,"mc":[{"id":"1.187560677","rc":[{"batl":[[0,8.8,3]],"ltp":5.5,"tv":1529.61,"id":7588306},{"batb":[[0,1.13,137.22]],"ltp":1.22,"tv":25922.66,"id":11439844}]}]}
{"op":"mcm","clk":"4234728558","pt":1631549252529,"mc":[{"id":"1.187560677","rc":[{"batb":[[0,7.2,7.23],[1,7,5.72],[2,6.8,6]],"batl":[[0,7.6,4.25],[1,7.8,3],[2,8,212.13]],"ltp":5.5,"tv":1529.61,"id":7588306},{"batb":[[0,1.15,117],[1,1.13,137.22],[2,1.12,133.22]],"batl":[[0,1.16,64.22],[1,1.17,91],[2,1.18,99]],"ltp":1.22,"tv":25922.66,"id":11439844}]}]}
{"op":"mcm","clk":"4234728583","pt":1631549252737,"mc":[{"id":"1.187560677","rc":[{"batb":[[1,1.13,127.57]],"ltp":1.22,"tv":25922.66,"id":11439844}]}]}
{"op":"mcm","clk":"4234729472","pt":1631549262513,"mc":[{"id":"1.187560677","rc":[{"trd":[[1.15,878.32]],"batb":[[0,1.15,114.25]],"ltp":1.15,"tv":25928.16,"id":11439844}],"tv":27457.78}]}
{"op":"mcm","clk":"4234729863","pt":1631549266622,"mc":[{"id":"1.187560677","rc":[{"trd":[[1.16,199.01]],"batl":[[0,1.16,60.61]],"ltp":1.16,"tv":25935.38,"id":11439844}],"tv":27465.0}]}
{"op":"mcm","clk":"4234730701","pt":1631549275721,"mc":[{"id":"1.187560677","rc":[{"trd":[[1.16,205.97]],"batl":[[0,1.16,57.13]],"ltp":1.16,"tv":25942.34,"id":11439844}],"tv":27471.96}]}
{"op":"mcm","clk":"4234731564","pt":1631549284677,"mc":[{"id":"1.187560677","rc":[{"trd":[[7.2,9.08]],"batb":[[0,7.2,5.88]],"ltp":7.2,"tv":1532.31,"id":7588306}],"tv":27474.66}]}
{"op":"mcm","clk":"4234732355","pt":1631549292446,"mc":[{"id":"1.187560677","rc":[{"trd":[[7.2,10.94]],"batb":[[0,7.2,4.95]],"ltp":7.2,"tv":1534.17,"id":7588306}],"tv":27476.52}]}
{"op":"mcm","clk":"4234732585","pt":1631549294867,"mc":[{"id":"1.187560677","rc":[{"batb":[[0,7.2,3.42]],"batl":[[0,7.8,3],[1,8,212.13],[2,8.8,3]],"ltp":7.2,"tv":1534.17,"id":7588306}]}]}
{"op":"mcm","clk":"4234732852","pt":1631549297784,"mc":[{"id":"1.187560677","rc":[{"batl":[[0,7.6,6.41],[1,7.8,3],[2,8,212.13]],"ltp":7.2,"tv":1534.17,"id":7588306},{"batl":[[1,1.17,141.61]],"ltp":1.16,"tv":25942.34,"id":11439844}]}]}
{"op":"mcm","clk":"4234733297","pt":1631549302668,"mc":[{"id":"1.187560677","rc":[{"batl":[[0,7.8,3],[1,8,212.13],[2,8.8,3]],"ltp":7.2,"tv":1534.17,"id":7588306},{"batl":[[1,1.17,91],[2,1.19,91]],"ltp":1.16,"tv":25942.34,"id":11439844}]}]}
{"op":"mcm","clk":"4234733610","pt":1631549305579,"mc":[{"id":"1.187560677","rc":[{"batb":[[0,7.2,9.42]],"batl":[[0,7.6,6.41],[1,7.8,3],[2,8,212.13]],"ltp":7.2,"tv":1534.17,"id":7588306},{"trd":[[1.16,206.05]],"batl":[[0,1.16,166.09],[1,1.17,141.61]],"ltp":1.16,"tv":25942.42,"id":11439844}],"tv":27476.6}]}
{"op":"mcm","clk":"4234734587","pt":1631549317101,"mc":[{"id":"1.187560677","rc":[{"trd":[[7.2,25.39]],"batb":[[0,7.2,2.19]],"ltp":7.2,"tv":1548.62,"id":7588306}],"tv":27491.05}]}
{"op":"mcm","clk":"4234736874","pt":1631549342849,"mc":[{"id":"1.187560677","rc":[{"batb":[[1,1.13,315.3]],"ltp":1.16,"tv":25942.42,"id":11439844}]}]}
{"op":"mcm","clk":"4234737168","pt":1631549346036,"mc":[{"id":"1.187560677","rc":[{"batb":[[1,1.14,121.27],[2,1.13,315.03]],"ltp":1.16,"tv":25942.42,"id":11439844}]}]}
{"op":"mcm","clk":"4234739390","pt":1631549366678,"mc":[{"id":"1.187560677","rc":[{"batb":[[0,6,2],[1,5.5,2.12],[2,1.3,5]],"batl":[[0,8.8,5],[1,9.4,3],[2,10.5,3]],"ltp":7.2,"tv":1548.62,"id":7588306},{"batb":[[0,1.14,121.27],[1,1.13,315.03],[2,1.12,133.22]],"batl":[[0,1.19,91],[1,1.2,107.43],[2,1.22,105.25]],"ltp":1.16,"tv":25942.42,"id":11439844}]}]}
{"op":"mcm","clk":"4234739473","pt":1631549367406,"mc":[{"id":"1.187560677","rc":[{"batb":[[0,5.5,2.12],[1,1.3,5],[2,1.01,105.79]],"ltp":7.2,"tv":1548.62,"id":7588306},{"batl":[[1,1.22,105.25],[2,1.34,168.22]],"ltp":1.16,"tv":25942.42,"id":11439844}]}]}
{"op":"mcm","clk":"4234739690","pt":1631549369569,"mc":[{"id":"1.187560677","rc":[{"batl":[[1,1.2,96],[2,1.22,105.25]],"ltp":1.16,"tv":25942.42,"id":11439844}]}]}
{"op":"mcm","clk":"4234740503","pt":1631549377766,"mc":[{"id":"1.187560677","rc":[{"batl":[[0,1.2,96],[1,1.22,105.25],[2,1.34,168.22]],"ltp":1.16,"tv":25942.42,"id":11439844}]}]}
{"op":"mcm","clk":"4234740998","pt":1631549382880,"mc":[{"id":"1.187560677","rc":[{"batl":[[0,1.22,105.25],[1,1.34,168.22],[2,1.39,18.43]],"ltp":1.16,"tv":25942.42,"id":11439844}]}]}
{"op":"mcm","clk":"4234741229","pt":1631549385594,"mc":[{"id":"1.187560677","rc":[{"batb":[[0,7.4,27.02],[1,7.2,2.02],[2,5.5,2.12]],"batl":[[0,8.6,192.91],[1,8.8,5],[2,9.4,3]],"ltp":7.2,"tv":1548.62,"id":7588306},{"batl":[[0,1.15,39.33],[1,1.16,781.17],[2,1.22,105.25]],"ltp":1.16,"tv":25942.42,"id":11439844}]}]}
{"op":"mcm","clk":"4234741264","pt":1631549385853,"mc":[{"id":"1.187560677","rc":[{"batb":[[0,7.6,5],[1,7.4,5.4],[2,7.2,8.02]],"ltp":7.2,"tv":1548.62,"id":7588306},{"batl":[[0,1.15,132.33],[1,1.16,872.17],[2,1.18,99]],"ltp":1.16,"tv":25942.42,"id":11439844}]}]}
{"op":"mcm","clk":"4234741862","pt":1631549392559,"mc":[{"id":"1.187560677","rc":[{"batl":[[2,9.4,5]],"ltp":7.2,"tv":1548.62,"id":7588306},{"batb":[[2,1.12,347.01]],"batl":[[2,1.17,140.5]],"ltp":1.16,"tv":25942.42,"id":11439844}]}]}
{"op":"mcm","clk":"4234742030","pt":1631549394615,"mc":[{"id":"1.187560677","rc":[{"batb":[[0,6.4,8],[1,1.3,5],[2,1.01,105.79]],"batl":[[0,8.8,3],[1,9.4,5],[2,10.5,3]],"ltp":7.2,"tv":1548.62,"id":7588306},{"batb":[[0,1.13,127.57],[1,1.12,347.01],[2,1.11,141]],"batl":[[0,1.18,246.75],[1,1.34,168.22],[2,1.39,18.43]],"ltp":1.16,"tv":25942.42,"id":11439844}]}]}
{"op":"mcm","clk":"4234742303","pt":1631549397600,"mc":[{"id":"1.187560677","rc":[{"batb":[[0,6.8,2],[1,6.4,8],[2,1.3,5]],"batl":[[0,8.8,5]],"ltp":7.2,"tv":1548.62,"id":7588306},{"batb":[[0,1.13,305.3]],"batl":[[0,1.17,146.5],[1,1.18,246.75],[2,1.19,105]],"ltp":1.16,"tv":25942.42,"id":11439844}]}]}
{"op":"mcm","clk":"4234742325","pt":1631549397806,"mc":[{"id":"1.187560677","rc":[{"batb":[[0,6.4,2],[1,1.3,5],[2,1.01,105.79]],"batl":[[0,8.8,3]],"ltp":7.2,"tv":1548.62,"id":7588306},{"batb":[[0,1.13,127.57]],"batl":[[0,1.18,147.75],[1,1.34,168.22],[2,1.39,18.43]],"ltp":1.16,"tv":25942.42,"id":11439844}]}]}
{"op":"mcm","clk":"4234742635","pt":1631549400679,"mc":[{"id":"1.187560677","rc":[{"batb":[[0,8,5],[1,7.8,5.12],[2,7.6,7]],"batl":[[1,9.2,150.78],[2,9.4,5]],"ltp":7.2,"tv":1548.62,"id":7588306},{"trd":[[1.14,332.78]],"batb":[[0,1.13,127.3]],"batl":[[0,1.14,153.31],[1,1.15,1283.67],[2,1.16,107]],"ltp":1.14,"tv":25942.97,"id":11439844}],"tv":27491.59}]}
{"op":"mcm","clk":"4234742920","pt":1631549403387,"mc":[{"id":"1.187560677","rc":[{"trd":[[1.14,360.02]],"batl":[[0,1.14,139.69]],"ltp":1.14,"tv":25970.21,"id":11439844}],"tv":27518.83}]}
{"op":"mcm","clk":"4234743478","pt":1631549409582,"mc":[{"id":"1.187560677","rc":[{"batb":[[1,7.6,7],[2,7.2,8]],"batl":[[0,8.8,5],[1,9.4,5],[2,10.5,3]],"ltp":7.2,"tv":1548.62,"id":7588306},{"batb":[[0,1.13,313.03]],"batl":[[0,1.14,97],[1,1.15,124.7],[2,1.16,269.72]],"ltp":1.14,"tv":25970.21,"id":11439844}]}]}
{"op":"mcm","clk":"4234743521","pt":1631549409995,"mc":[{"id":"1.187560677","rc":[{"batb":[[0,7.2,8],[1,1.3,5],[2,1.01,105.79]],"batl":[[0,9.4,5],[1,10.5,3],[2,11,3]],"ltp":7.2,"tv":1548.62,"id":7588306},{"batb":[[0,1.12,347.31],[1,1.11,141],[2,1.1,150.27]],"batl":[[0,1.16,107],[1,1.34,168.22],[2,1.39,18.43]],"ltp":1.14,"tv":25970.21,"id":11439844}]}]}
{"op":"mcm","clk":"4234743887","pt":1631549413695,"mc":[{"id":"1.187560677","rc":[{"batb":[[1,6.8,6],[2,6.4,6]],"ltp":7.2,"tv":1548.62,"id":7588306},{"batl":[[0,1.16,267.97],[1,1.17,95],[2,1.18,91]],"ltp":1.14,"tv":25970.21,"id":11439844}]}]}
{"op":"mcm","clk":"4234744033","pt":1631549415512,"mc":[{"id":"1.187560677","rc":[{"batl":[[0,1.16,268.24]],"ltp":1.14,"tv":25970.21,"id":11439844}]}]}
{"op":"mcm","clk":"4234744485","pt":1631549420615,"mc":[{"id":"1.187560677","rc":[{"trd":[[1.12,61.34],[1.13,142.96]],"batb":[[0,1.12,339.81]],"ltp":1.12,"tv":25985.21,"id":11439844}],"tv":27533.83}]}
{"op":"mcm","clk":"4234745172","pt":1631549427533,"mc":[{"id":"1.187560677","rc":[{"batb":[[0,7.6,2],[1,7.2,8],[2,6.8,6]],"batl":[[0,8.8,2],[1,9.4,5],[2,10.5,3]],"ltp":7.2,"tv":1548.62,"id":7588306},{"batb":[[0,1.13,177.73],[1,1.12,339.81],[2,1.11,141]],"batl":[[0,1.15,180.57],[1,1.16,267.97],[2,1.17,95]],"ltp":1.12,"tv":25985.21,"id":11439844}]}]}
{"op":"mcm","clk":"4234745190","pt":1631549427736,"mc":[{"id":"1.187560677","rc":[{"batb":[[0,7.2,8],[1,6.8,6],[2,6.4,6]],"batl":[[0,9.4,5],[1,10.5,3],[2,11,3]],"ltp":7.2,"tv":1548.62,"id":7588306},{"batb":[[0,1.12,339.81],[1,1.11,141],[2,1.1,150.27]],"batl":[[0,1.16,268.24],[1,1.17,95],[2,1.18,91]],"ltp":1.12,"tv":25985.21,"id":11439844}]}]}
{"op":"mcm","clk":"4234745338","pt":1631549429138,"mc":[{"id":"1.187560677","rc":[{"batl":[[0,8,5.18],[1,9,4.44],[2,9.4,5]],"ltp":7.2,"tv":1548.62,"id":7588306},{"batb":[[0,1.14,914.73],[1,1.13,127],[2,1.12,339.81]],"batl":[[0,1.16,322.73],[1,1.17,1338.87]],"ltp":1.12,"tv":25985.21,"id":11439844}]}]}
{"op":"mcm","clk":"4234745425","pt":1631549430133,"mc":[{"id":"1.187560677","rc":[{"trd":[[1.15,878.87],[1.16,643.85]],"batb":[[0,1.15,239.96],[1,1.14,914.73],[2,1.13,127]],"batl":[[0,1.16,103.58]],"ltp":1.16,"tv":26423.56,"id":11439844}],"tv":27972.19}]}
{"op":"mcm","clk":"4234746039","pt":1631549436715,"mc":[{"id":"1.187560677","rc":[{"batb":[[2,6.4,8]],"batl":[[1,8.8,2],[2,9,4.44]],"ltp":7.2,"tv":1548.62,"id":7588306},{"trd":[[1.15,879.47]],"batb":[[0,1.15,239.66],[2,1.13,345.73]],"batl":[[2,1.18,228.25]],"ltp":1.15,"tv":26424.16,"id":11439844}],"tv":27972.78}]}
{"op":"mcm","clk":"4234746112","pt":1631549437656,"mc":[{"id":"1.187560677","rc":[{"trd":[[1.15,879.91]],"batb":[[0,1.15,239.44]],"ltp":1.15,"tv":26424.6,"id":11439844}],"tv":27973.23}]}
{"op":"mcm","clk":"4234746374","pt":1631549440736,"mc":[{"id":"1.187560677","rc":[{"batb":[[1,1.14,912.62]],"ltp":1.15,"tv":26424.6,"id":11439844}]}]}
{"op":"mcm","clk":"4234746788","pt":1631549445433,"mc":[{"id":"1.187560677","rc":[{"batb":[[1,1.14,912.91]],"ltp":1.15,"tv":26424.6,"id":11439844}]}]}
{"op":"mcm","clk":"4234746880","pt":1631549446366,"mc":[{"id":"1.187560677","rc":[{"batb":[[0,6.4,6],[1,6.2,2.02],[2,4.4,26.17]],"batl":[[0,8.8,2],[1,9.4,5],[2,10.5,3]],"ltp":7.2,"tv":1548.62,"id":7588306},{"batb":[[1,1.13,346.02],[2,1.12,339.81]],"batl":[[0,1.18,91],[1,1.19,143.5],[2,1.34,168.22]],"ltp":1.15,"tv":26424.6,"id":11439844}]}]}
{"op":"mcm","clk":"4234747233","pt":1631549449567,"mc":[{"id":"1.187560677","rc":[{"batb":[[0,6.4,8.01],[2,4.7,23.91]],"ltp":7.2,"tv":1548.62,"id":7588306},{"batb":[[0,1.14,254.78],[1,1.13,345.73]],"batl":[[0,1.18,220.75],[1,1.19,248.5],[2,1.2,96]],"ltp":1.15,"tv":26424.6,"id":11439844}]}]}
{"op":"mcm","clk":"4234747370","pt":1631549450659,"mc":[{"id":"1.187560677","rc":[{"batb":[[0,6.4,6]],"batl":[[0,8.4,2.4],[1,8.8,2],[2,9.4,5]],"ltp":7.2,"tv":1548.62,"id":7588306},{"batl":[[0,1.18,91]],"ltp":1.15,"tv":26424.6,"id":11439844}]}]}
{"op":"mcm","clk":"4234747425","pt":1631549451178,"mc":[{"id":"1.187560677","rc":[{"batl":[[0,8.8,2],[1,9.4,5],[2,10.5,3]],"ltp":7.2,"tv":1548.62,"id":7588306}]}]}
{"op":"mcm","clk":"4234747634","pt":1631549453571,"mc":[{"id":"1.187560677","rc":[{"batb":[[0,6.2,2.02],[1,4.7,23.91],[2,1.3,5]],"ltp":7.2,"tv":1548.62,"id":7588306},{"batb":[[2,1.12,340.05]],"batl":[[0,1.19,248.5],[1,1.2,96],[2,1.34,168.22]],"ltp":1.15,"tv":26424.6,"id":11439844}]}]}
{"op":"mcm","clk":"4234747742","pt":1631549454573,"mc":[{"id":"1.187560677","rc":[{"batb":[[1,1.13,346.04]],"ltp":1.15,"tv":26424.6,"id":11439844}]}]}
{"op":"mcm","clk":"4234748420","pt":1631549461682,"mc":[{"id":"1.187560677","rc":[{"batb":[[0,6.4,5.13],[1,6.2,2.02],[2,6,90.96]],"batl":[[0,6.8,4.94],[1,7,28.58],[2,7.2,217.56]],"ltp":7.2,"tv":1548.62,"id":7588306},{"batb":[[0,1.16,23.03],[1,1.14,254.78],[2,1.13,346.04]],"batl":[[1,1.2,550.81]],"ltp":1.15,"tv":26424.6,"id":11439844}]}]}
{"op":"mcm","clk":"4234748518","pt":1631549462663,"mc":[{"id":"1.187560677","rc":[{"batl":[[1,7,5.72]],"ltp":7.2,"tv":1548.62,"id":7588306},{"batb":[[0,1.16,136.03]],"ltp":1.15,"tv":26424.6,"id":11439844}]}]}
{"op":"mcm","clk":"4234748558","pt":1631549463074,"mc":[{"id":"1.187560677","rc":[{"trd":[[1.19,400.99]],"batb":[[0,1.16,358.31],[1,1.13,346.33],[2,1.12,340.05]],"batl":[[0,1.19,62.24]],"ltp":1.19,"tv":26797.16,"id":11439844}],"tv":28345.79}]}
{"op":"mcm","clk":"4234749061","pt":1631549468289,"mc":[{"id":"1.187560677","rc":[{"batb":[[1,1.14,166.11],[2,1.13,346.04]],"ltp":1.19,"tv":26797.16,"id":11439844}]}]}
{"op":"mcm","clk":"4234750274","pt":1631549480698,"mc":[{"id":"1.187560677","rc":[{"batb":[[0,3.8,41.27],[1,1.3,5],[2,1.01,105.79]],"batl":[[0,8.2,2],[1,8.8,2],[2,9.4,5]],"ltp":7.2,"tv":1548.62,"id":7588306},{"batb":[[0,1.16,222.28]],"batl":[[0,1.34,168.22],[1,1.39,18.43],[2,1.44,94.65]],"ltp":1.19,"tv":26797.16,"id":11439844}]}]}
{"op":"mcm","clk":"4234750585","pt":1631549483712,"mc":[{"id":"1.187560677","rc":[{"batb":[[0,3.95,38.25],[1,3.8,41.27],[2,1.3,5]],"ltp":7.2,"tv":1548.62,"id":7588306},{"batb":[[1,1.15,233.94],[2,1.14,166.11]],"ltp":1.19,"tv":26797.16,"id":11439844}]}]}
{"op":"mcm","clk":"4234750614","pt":1631549484031,"mc":[{"id":"1.187560677","rc":[{"batb":[[1,1.3,5],[2,1.01,105.79]],"ltp":7.2,"tv":1548.62,"id":7588306},{"batb":[[0,1.15,233.94],[1,1.14,166.11],[2,1.13,346.04]],"ltp":1.19,"tv":26797.16,"id":11439844}]}]}
{"op":"mcm","clk":"4234751839","pt":1631549495548,"mc":[{"id":"1.187560677","rc":[{"batb":[[1,1.14,287.11]],"ltp":1.19,"tv":26797.16,"id":11439844}]}]}
{"op":"mcm","clk":"4234751990","pt":1631549497121,"mc":[{"id":"1.187560677","rc":[{"batb":[[2,1.13,219.04]],"ltp":1.19,"tv":26797.16,"id":11439844}]}]}
{"op":"mcm","clk":"4234752237","pt":1631549499680,"mc":[{"id":"1.187560677","rc":[{"batl":[[0,8,5.94],[1,8.2,2],[2,8.6,247.56]],"ltp":7.2,"tv":1548.62,"id":7588306},{"batl":[[0,1.16,49.68],[1,1.17,1076.62],[2,1.18,169.5]],"ltp":1.19,"tv":26797.16,"id":11439844}]}]}
{"op":"mcm","clk":"4234752330","pt":1631549500569,"mc":[{"id":"1.187560677","rc":[{"batb":[[0,7.2,6],[1,6.8,6],[2,5.4,34.31]],"ltp":7.2,"tv":1548.62,"id":7588306},{"batb":[[1,1.14,547.3]],"batl":[[0,1.16,149.68],[1,1.17,1170.62],[2,1.18,33.9]],"ltp":1.19,"tv":26797.16,"id":11439844}]}]}
{"op":"mcm","clk":"4234753408","pt":1631549513017,"mc":[{"id":"1.187560677","rc":[{"trd":[[7.2,53.39]],"batb":[[0,6.8,6],[1,5.4,34.31],[2,4.8,23.74]],"ltp":7.2,"tv":1576.62,"id":7588306},{"trd":[[1.16,743.16]],"batl":[[0,1.16,50.37]],"ltp":1.16,"tv":26896.47,"id":11439844}],"tv":28473.1}]}
{"op":"mcm","clk":"4234754310","pt":1631549522494,"mc":[{"id":"1.187560677","rc":[{"batl":[[0,8.2,2],[1,8.8,2],[2,9.4,5]],"ltp":7.2,"tv":1576.62,"id":7588306},{"batl":[[1,1.17,94],[2,1.2,94]],"ltp":1.16,"tv":26896.47,"id":11439844}]}]}
{"op":"mcm","clk":"4234754366","pt":1631549523114,"mc":[{"id":"1.187560677","rc":[{"batb":[[0,4.8,23.74],[1,1.3,5],[2,1.01,105.79]],"batl":[[0,8.8,2],[1,9.4,5],[2,10.5,3]],"ltp":7.2,"tv":1576.62,"id":7588306},{"batb":[[0,1.14,260.48],[1,1.13,219.04],[2,1.12,340.05]],"batl":[[0,1.2,94],[1,1.34,168.22],[2,1.39,18.43]],"ltp":1.16,"tv":26896.47,"id":11439844}]}]}
{"op":"mcm","clk":"4234754665","pt":1631549526512,"mc":[{"id":"1.187560677","rc":[{"batb":[[1,4.7,24.41],[2,1.3,5]],"ltp":7.2,"tv":1576.62,"id":7588306}]}]}
{"op":"mcm","clk":"4234754723","pt":1631549526827,"mc":[{"id":"1.187560677","rc":[{"batb":[[0,4.7,24.41],[1,1.3,5],[2,1.01,105.79]],"ltp":7.2,"tv":1576.62,"id":7588306}]}]}
{"op":"mcm","clk":"4234755400","pt":1631549533712,"mc":[{"id":"1.187560677","rc":[{"batl":[[0,6.6,30.3],[1,7.6,430.54],[2,7.8,2.57]],"ltp":7.2,"tv":1576.62,"id":7588306},{"batb":[[0,1.19,19.59],[1,1.14,260.48],[2,1.13,219.04]],"batl":[[0,1.2,103.29],[1,1.21,1238.25],[2,1.34,168.22]],"ltp":1.16,"tv":26896.47,"id":11439844}]}]}
{"op":"mcm","clk":"4234755478","pt":1631549534605,"mc":[{"id":"1.187560677","rc":[{"batb":[[1,3.85,41.19],[2,1.3,5]],"batl":[[0,6.6,6.06],[1,7.4,8.14],[2,7.6,430.54]],"ltp":7.2,"tv":1576.62,"id":7588306},{"batb":[[0,1.19,203.29],[1,1.16,433.98],[2,1.14,381.48]],"ltp":1.16,"tv":26896.47,"id":11439844}]}]}
{"op":"mcm","clk":"4234755500","pt":1631549534941,"mc":[{"id":"1.187560677","rc":[{"batb":[[2,1.14,121.29]],"ltp":1.16,"tv":26896.47,"id":11439844}]}]}
{"op":"mcm","clk":"4234755950","pt":1631549540422,"mc":[{"id":"1.187560677","rc":[{"batb":[[2,1.14,298.11]],"ltp":1.16,"tv":26896.47,"id":11439844}]}]}
{"op":"mcm","clk":"4234756217","pt":1631549543644,"mc":[{"id":"1.187560677","rc":[{"batb":[[0,4.8,20.89],[1,4.7,24.41],[2,3.85,41.19]],"ltp":7.2,"tv":1576.62,"id":7588306}]}]}
{"op":"mcm","clk":"4234756832","pt":1631549550583,"mc":[{"id":"1.187560677","rc":[{"batb":[[0,3.85,41.19],[1,1.3,5],[2,1.01,105.79]],"batl":[[0,8.2,2],[1,8.8,2],[2,9.4,5]],"ltp":7.2,"tv":1576.62,"id":7588306},{"batb":[[0,1.16,222.7],[1,1.14,298.11],[2,1.13,346.04]],"batl":[[0,1.34,168.22],[1,1.39,18.43],[2,1.44,94.65]],"ltp":1.16,"tv":26896.47,"id":11439844}]}]}
{"op":"mcm","clk":"4234758476","pt":1631549568434,"mc":[{"id":"1.187560677","rc":[{"batb":[[0,4.8,5.42],[1,3.85,41.19],[2,1.3,5]],"batl":[[0,5,3.86],[1,5.1,7.84],[2,5.4,7.19]],"ltp":7.2,"tv":1576.62,"id":7588306},{"batb":[[0,1.23,95.63],[1,1.22,943.42],[2,1.17,109]],"batl":[[0,1.27,869.7],[1,1.34,168.22],[2,1.44,95.15]],"ltp":1.16,"tv":26896.47,"id":11439844}]}]}
{"op":"mcm","clk":"4234758583","pt":1631549569434,"mc":[{"id":"1.187560677","rc":[{"batb":[[2,2.8,18.54]],"ltp":7.2,"tv":1576.62,"id":7588306},{"trd":[[1.27,261.98]],"batb":[[2,1.2,178.33]],"batl":[[0,1.27,741.22]],"ltp":1.27,"tv":27153.45,"id":11439844}],"tv":28730.08}]}
{"op":"mcm","clk":"4234758773","pt":1631549571634,"mc":[{"id":"1.187560677","rc":[{"trd":[[5,11.67]],"batb":[[0,5,56.72],[1,4.8,5.42],[2,3.85,41.19]],"batl":[[0,5.1,7.84],[1,5.4,7.19],[2,7,3]],"ltp":5.0,"tv":1584.34,"id":7588306}],"tv":28737.8}]}
{"op":"mcm","clk":"4234758808","pt":1631549572051,"mc":[{"id":"1.187560677","rc":[{"trd":[[5,19.21]],"batb":[[0,4.8,5.42],[1,3.85,41.19],[2,2.8,18.54]],"ltp":5.0,"tv":1591.88,"id":7588306}],"tv":28745.34}]}
{"op":"mcm","clk":"4234759032","pt":1631549574872,"mc":[{"id":"1.187560677","rc":[{"batl":[[2,7,5]],"ltp":5.0,"tv":1591.88,"id":7588306}]}]}
{"op":"mcm","clk":"4234759437","pt":1631549579675,"mc":[{"id":"1.187560677","rc":[{"batb":[[0,2.8,18.54],[1,1.3,5],[2,1.01,105.79]],"batl":[[0,7,5],[1,7.4,3],[2,7.8,3]],"ltp":5.0,"tv":1591.88,"id":7588306},{"batb":[[0,1.2,178.33],[1,1.17,241.97],[2,1.16,113]],"batl":[[0,1.34,168.22],[1,1.44,95.15],[2,1.94,3.33]],"ltp":1.27,"tv":27153.45,"id":11439844}]}]}
{"op":"mcm","clk":"4234759698","pt":1631549582574,"mc":[{"id":"1.187560677","rc":[{"batb":[[0,2.84,17.78],[1,2.8,18.54],[2,1.3,5]],"ltp":5.0,"tv":1591.88,"id":7588306},{"batb":[[1,1.19,185.29],[2,1.17,241.97]],"ltp":1.27,"tv":27153.45,"id":11439844}]}]}
{"op":"mcm","clk":"4234759736","pt":1631549583145,"mc":[{"id":"1.187560677","rc":[{"batb":[[1,1.3,5],[2,1.01,105.79]],"ltp":5.0,"tv":1591.88,"id":7588306},{"batb":[[0,1.19,185.29],[1,1.17,241.97],[2,1.16,113]],"ltp":1.27,"tv":27153.45,"id":11439844}]}]}
{"op":"mcm","clk":"4234759866","pt":1631549584572,"mc":[{"id":"1.187560677","rc":[{"batl":[[0,5.1,3.94],[1,7,5],[2,7.4,3]],"ltp":5.0,"tv":1591.88,"id":7588306}]}]}
{"op":"mcm","clk":"4234759907","pt":1631549585046,"mc":[{"id":"1.187560677","rc":[{"batl":[[0,7,5],[1,7.4,3],[2,7.8,3]],"ltp":5.0,"tv":1591.88,"id":7588306}]}]}
{"op":"mcm","clk":"4234761858","pt":1631549610211,"mc":[{"id":"1.187560677","rc":[{"batl":[[1,7.8,3],[2,8.2,2]],"ltp":5.0,"tv":1591.88,"id":7588306},{"batb":[[2,1.15,117]],"ltp":1.27,"tv":27153.45,"id":11439844}]}]}
{"op":"mcm","clk":"4234762050","pt":1631549612711,"mc":[{"id":"1.187560677","rc":[{"batb":[[0,4.8,946.88],[1,2.84,17.78],[2,1.3,5]],"batl":[[0,6.8,182.71],[1,7,5],[2,7.8,3]],"ltp":5.0,"tv":1591.88,"id":7588306},{"batb":[[0,1.19,206.46]],"batl":[[0,1.2,8.78],[1,1.21,3575.02],[2,1.23,2.91]],"ltp":1.27,"tv":27153.45,"id":11439844}]}]}
{"op":"mcm","clk":"4234762101","pt":1631549613508,"mc":[{"id":"1.187560677","rc":[{"batb":[[1,4.7,24.07],[2,3.8,41.44]],"ltp":5.0,"tv":1591.88,"id":7588306},{"batb":[[2,1.16,224.04]],"batl":[[1,1.21,33.06],[2,1.34,168.22]],"ltp":1.27,"tv":27153.45,"id":11439844}]}]}
{"op":"mcm","clk":"4234762568","pt":1631549619295,"mc":[{"id":"1.187560677","rc":[{"batl":[[2,7.8,5]],"ltp":5.0,"tv":1591.88,"id":7588306}]}]}
{"op":"mcm","clk":"4234764159","pt":1631549638607,"mc":[{"id":"1.187560677","rc":[{"batb":[[0,3.8,41.44],[1,1.3,5],[2,1.01,105.79]],"batl":[[0,7.8,5],[1,8.2,2],[2,8.8,2]],"ltp":5.0,"tv":1591.88,"id":7588306},{"batb":[[0,1.16,224.04],[1,1.15,303.63],[2,1.14,298.11]],"batl":[[0,1.34,168.22],[1,1.44,95.15],[2,1.94,3.33]],"ltp":1.27,"tv":27153.45,"id":11439844}]}]}
{"op":"mcm","clk":"4234766858","pt":1631549666671,"mc":[{"id":"1.187560677","rc":[{"batb":[[0,4.8,5.23],[1,3.8,41.44],[2,1.3,5]],"batl":[[0,5,12.17],[1,5.2,7.53],[2,5.5,284.29]],"ltp":5.0,"tv":1591.88,"id":7588306},{"batb":[[0,1.24,95.02],[1,1.18,106],[2,1.17,109]],"batl":[[0,1.28,917.6],[1,1.34,168.22],[2,1.44,95.15]],"ltp":1.27,"tv":27153.45,"id":11439844}]}]}
{"op":"mcm","clk":"4234766949","pt":1631549667513,"mc":[{"id":"1.187560677","rc":[{"trd":[[4.8,5.23]],"batb":[[0,3.8,41.44],[1,2.8,18.37]],"ltp":4.8,"tv":1597.11,"id":7588306},{"trd":[[1.27,281.75]],"batb":[[0,1.27,108.15],[1,1.24,95.02],[2,1.2,178.24]],"ltp":1.27,"tv":27173.22,"id":11439844}],"tv":28770.34}]}
{"op":"mcm","clk":"4234767839","pt":1631549677674,"mc":[{"id":"1.187560677","rc":[{"batl":[[0,5,8]],"ltp":4.8,"tv":1597.11,"id":7588306}]}]}
{"op":"mcm","clk":"4234768080","pt":1631549680665,"mc":[{"id":"1.187560677","rc":[{"batl":[[0,5,12.6]],"ltp":4.8,"tv":1597.11,"id":7588306},{"trd":[[1.27,317.16]],"batb":[[0,1.27,90.44],[1,1.25,18.39],[2,1.24,95.02]],"ltp":1.27,"tv":27208.63,"id":11439844}],"tv":28805.75}]}
{"op":"mcm","clk":"4234768230","pt":1631549682707,"mc":[{"id":"1.187560677","rc":[{"trd":[[1.28,51.76]],"batl":[[0,1.28,916.1]],"ltp":1.28,"tv":27211.63,"id":11439844}],"tv":28808.75}]}
{"op":"mcm","clk":"4234768293","pt":1631549683508,"mc":[{"id":"1.187560677","rc":[{"trd":[[4.5,19.37]],"ltp":4.5,"tv":1616.49,"id":7588306},{"trd":[[1.28,119.9]],"batl":[[0,1.28,847.96],[1,1.44,95.15],[2,1.94,3.33]],"ltp":1.28,"tv":27279.77,"id":11439844}],"tv":28896.26}]}
{"op":"mcm","clk":"4234768509","pt":1631549686610,"mc":[{"id":"1.187560677","rc":[{"batl":[[0,5.2,7.53],[1,6.6,5.01],[2,7,3]],"ltp":4.5,"tv":1616.49,"id":7588306},{"batb":[[1,1.24,95.02],[2,1.2,178.24]],"batl":[[0,1.44,95.15],[1,1.94,3.33],[2,3.8,27.43]],"ltp":1.28,"tv":27279.77,"id":11439844}]}]}
{"op":"mcm","clk":"4234768555","pt":1631549687031,"mc":[{"id":"1.187560677","rc":[{"batb":[[0,2.8,18.37],[1,1.3,5],[2,1.01,105.79]],"batl":[[0,6.6,5.01],[1,7,3],[2,7.4,3]],"ltp":4.5,"tv":1616.49,"id":7588306},{"batb":[[0,1.2,178.24],[1,1.18,246.86],[2,1.17,109]],"ltp":1.28,"tv":27279.77,"id":11439844}]}]}
{"op":"mcm","clk":"4234768829","pt":1631549690294,"mc":[{"id":"1.187560677","rc":[{"batb":[[0,2.82,18.12]],"ltp":4.5,"tv":1616.49,"id":7588306}]}]}
{"op":"mcm","clk":"4234769019","pt":1631549692622,"mc":[{"id":"1.187560677","rc":[{"batl":[[0,6.4,3],[1,6.6,5.01],[2,7,3]],"ltp":4.5,"tv":1616.49,"id":7588306},{"batb":[[1,1.19,103],[2,1.18,246.86]],"ltp":1.28,"tv":27279.77,"id":11439844}]}]}
{"op":"mcm","clk":"4234769966","pt":1631549702947,"mc":[{"id":"1.187560677","rc":[{"batl":[[1,6.6,2.01],[2,7.4,3]],"ltp":4.5,"tv":1616.49,"id":7588306},{"batb":[[2,1.18,140.86]],"ltp":1.28,"tv":27279.77,"id":11439844}]}]}
{"op":"mcm","clk":"4234770280","pt":1631549705631,"mc":[{"id":"1.187560677","rc":[{"batl":[[0,6,3.93],[1,6.4,3],[2,6.6,2.01]],"ltp":4.5,"tv":1616.49,"id":7588306},{"batb":[[0,1.2,197.9]],"batl":[[0,1.21,165.28],[1,1.22,985.54],[2,1.44,95.15]],"ltp":1.28,"tv":27279.77,"id":11439844}]}]}
{"op":"mcm","clk":"4234770377","pt":1631549706635,"mc":[{"id":"1.187560677","rc":[{"batb":[[0,4.7,25.16],[1,3.8,42.53],[2,2.82,18.12]],"ltp":4.5,"tv":1616.49,"id":7588306},{"trd":[[1.21,4]],"batl":[[0,1.21,31.06],[2,1.39,2.21]],"ltp":1.21,"tv":27283.77,"id":11439844}],"tv":28900.26}]}
{"op":"mcm","clk":"4234770409","pt":1631549707053,"mc":[{"id":"1.187560677","rc":[{"batb":[[2,1.3,5]],"ltp":4.5,"tv":1616.49,"id":7588306}]}]}
{"op":"mcm","clk":"4234771266","pt":1631549716161,"mc":[{"id":"1.187560677","rc":[{"batl":[[2,1.44,95.15]],"ltp":1.21,"tv":27283.77,"id":11439844}]}]}
{"op":"mcm","clk":"4234771479","pt":1631549718633,"mc":[{"id":"1.187560677","rc":[{"batb":[[0,4.7,45.69]],"ltp":4.5,"tv":1616.49,"id":7588306}]}]}
{"op":"mcm","clk":"4234772078","pt":1631549724574,"mc":[{"id":"1.187560677","rc":[{"batb":[[0,4.7,25.16]],"batl":[[0,7,2],[1,7.4,3],[2,7.8,5]],"ltp":4.5,"tv":1616.49,"id":7588306},{"batb":[[0,1.2,178.24],[1,1.17,150.97],[2,1.16,329.75]],"batl":[[0,1.44,95.15],[1,1.94,3.33],[2,3.8,27.43]],"ltp":1.21,"tv":27283.77,"id":11439844}]}]}
{"op":"mcm","clk":"4234772142","pt":1631549725256,"mc":[{"id":"1.187560677","rc":[{"batb":[[0,3.8,42.53],[1,1.3,5],[2,1.01,105.79]],"batl":[[0,7.4,3],[1,7.8,5],[2,8.2,2]],"ltp":4.5,"tv":1616.49,"id":7588306},{"batb":[[0,1.16,329.75],[1,1.15,303.63],[2,1.14,298.11]],"ltp":1.21,"tv":27283.77,"id":11439844}]}]}
{"op":"mcm","clk":"4234772457","pt":1631549728510,"mc":[{"id":"1.187560677","rc":[{"batl":[[0,7,2],[1,7.4,3],[2,7.8,5]],"ltp":4.5,"tv":1616.49,"id":7588306},{"batb":[[0,1.17,145.97],[1,1.16,329.75],[2,1.15,303.63]],"ltp":1.21,"tv":27283.77,"id":11439844}]}]}
{"op":"mcm","clk":"4234772490","pt":1631549728782,"mc":[{"id":"1.187560677","rc":[{"batl":[[0,7.4,3],[1,7.8,5],[2,8.2,2]],"ltp":4.5,"tv":1616.49,"id":7588306},{"batb":[[0,1.16,329.75],[1,1.15,303.63],[2,1.14,298.11]],"ltp":1.21,"tv":27283.77,"id":11439844}]}]}
{"op":"mcm","clk":"4234773086","pt":1631549735580,"mc":[{"id":"1.187560677","rc":[{"batl":[[0,7,2],[1,7.4,3],[2,7.8,5]],"ltp":4.5,"tv":1616.49,"id":7588306},{"batb":[[0,1.17,142.97],[1,1.16,329.75],[2,1.15,303.63]],"ltp":1.21,"tv":27283.77,"id":11439844}]}]}
{"op":"mcm","clk":"4234773104","pt":1631549735796,"mc":[{"id":"1.187560677","rc":[{"batl":[[0,7.4,3],[1,7.8,5],[2,8.2,2]],"ltp":4.5,"tv":1616.49,"id":7588306},{"batb":[[0,1.16,329.75],[1,1.15,303.63],[2,1.14,298.11]],"ltp":1.21,"tv":27283.77,"id":11439844}]}]}
{"op":"mcm","clk":"4234773384","pt":1631549738683,"mc":[{"id":"1.187560677","rc":[{"batl":[[0,4.7,42.56],[1,4.9,757.38],[2,5.4,3.25]],"ltp":4.5,"tv":1616.49,"id":7588306}]}]}
{"op":"mcm","clk":"4234773478","pt":1631549739625,"mc":[{"id":"1.187560677","rc":[{"batb":[[0,4.5,244.36],[1,3.8,42.53],[2,1.3,5]],"batl":[[0,4.7,12.31],[1,5,7.81],[2,5.3,226.72]],"ltp":4.5,"tv":1616.49,"id":7588306},{"batb":[[0,1.25,93.73],[1,1.19,103],[2,1.18,106]],"ltp":1.21,"tv":27283.77,"id":11439844}]}]}
{"op":"mcm","clk":"4234773528","pt":1631549740096,"mc":[{"id":"1.187560677","rc":[{"batb":[[2,2.8,18.62]],"ltp":4.5,"tv":1616.49,"id":7588306},{"batb":[[0,1.27,125.65],[1,1.25,93.73],[2,1.2,174.47]],"batl":[[1,1.49,1.96],[2,1.94,3.08]],"ltp":1.21,"tv":27283.77,"id":11439844}]}]}
{"op":"mcm","clk":"4234773774","pt":1631549743126,"mc":[{"id":"1.187560677","rc":[{"trd":[[4.7,25.97]],"batl":[[0,5,7.81],[1,5.3,226.72],[2,6.4,3]],"ltp":4.7,"tv":1641.11,"id":7588306}],"tv":28924.88}]}
{"op":"mcm","clk":"4234773982","pt":1631549745322,"mc":[{"id":"1.187560677","rc":[{"batl":[[2,6,2.01]],"ltp":4.7,"tv":1641.11,"id":7588306},{"batb":[[2,1.2,301.74]],"ltp":1.21,"tv":27283.77,"id":11439844}]}]}
{"op":"mcm","clk":"4234774390","pt":1631549750544,"mc":[{"id":"1.187560677","rc":[{"batl":[[1,1.94,3.33],[2,3.8,27.43]],"ltp":1.21,"tv":27283.77,"id":11439844}]}]}
{"op":"mcm","clk":"4234774591","pt":1631549752944,"mc":[{"id":"1.187560677","rc":[{"batb":[[0,4.5,237.62]],"ltp":4.7,"tv":1641.11,"id":7588306}]}]}
{"op":"mcm","clk":"4234774765","pt":1631549754532,"mc":[{"id":"1.187560677","rc":[{"batb":[[0,2.8,18.62],[1,1.3,5],[2,1.01,105.79]],"batl":[[0,6,2.01],[1,6.4,3],[2,6.6,3]],"ltp":4.7,"tv":1641.11,"id":7588306},{"batb":[[0,1.2,301.74],[1,1.19,103],[2,1.18,106]],"ltp":1.21,"tv":27283.77,"id":11439844}]}]}
{"op":"mcm","clk":"4234774790","pt":1631549754831,"mc":[{"id":"1.187560677","rc":[{"batl":[[0,6.4,3],[1,6.6,3],[2,7,5]],"ltp":4.7,"tv":1641.11,"id":7588306},{"batb":[[0,1.2,174.47]],"ltp":1.21,"tv":27283.77,"id":11439844}]}]}
{"op":"mcm","clk":"4234775296","pt":1631549760829,"mc":[{"id":"1.187560677","rc":[{"batl":[[0,6,3],[1,6.4,3],[2,6.6,3]],"ltp":4.7,"tv":1641.11,"id":7588306},{"batb":[[0,1.2,274.47]],"ltp":1.21,"tv":27283.77,"id":11439844}]}]}
{"op":"mcm","clk":"4234775372","pt":1631549761723,"mc":[{"id":"1.187560677","rc":[{"batl":[[0,6,5.36]],"ltp":4.7,"tv":1641.11,"id":7588306},{"batb":[[0,1.2,391.79]],"ltp":1.21,"tv":27283.77,"id":11439844}]}]}
{"op":"mcm","clk":"4234775629","pt":1631549764715,"mc":[{"id":"1.187560677","rc":[{"batb":[[0,3.3,11.77],[1,2.8,18.62],[2,1.3,5]],"ltp":4.7,"tv":1641.11,"id":7588306}]}]}
{"op":"mcm","clk":"4234776732","pt":1631549778907,"mc":[{"id":"1.187560677","rc":[{"batl":[[1,7,5],[2,7.4,3]],"ltp":4.7,"tv":1641.11,"id":7588306},{"batb":[[1,1.17,248.97],[2,1.16,113]],"ltp":1.21,"tv":27283.77,"id":11439844}]}]}
{"op":"mcm","clk":"4234776939","pt":1631549781683,"mc":[{"id":"1.187560677","rc":[{"batb":[[0,4.5,1114.02],[1,3.3,11.77],[2,2.8,18.62]],"batl":[[0,6,9.61]],"ltp":4.7,"tv":1641.11,"id":7588306},{"batb":[[0,1.2,413.04],[1,1.18,1197.3],[2,1.17,248.97]],"batl":[[0,1.22,60.31],[1,1.44,95.15],[2,1.94,3.33]],"ltp":1.21,"tv":27283.77,"id":11439844}]}]}
{"op":"mcm","clk":"4234777015","pt":1631549782517,"mc":[{"id":"1.187560677","rc":[{"batb":[[0,4.6,26.42],[1,4.5,1114.02],[2,3.7,22.31]],"ltp":4.7,"tv":1641.11,"id":7588306},{"batb":[[2,1.17,459.76]],"batl":[[1,1.41,2.21],[2,1.44,94.65]],"ltp":1.21,"tv":27283.77,"id":11439844}]}]}
{"op":"mcm","clk":"4234777624","pt":1631549788992,"mc":[{"id":"1.187560677","rc":[{"batl":[[1,6.6,2.01],[2,7,5]],"ltp":4.7,"tv":1641.11,"id":7588306},{"batb":[[1,1.18,1322.66]],"ltp":1.21,"tv":27283.77,"id":11439844}]}]}
{"op":"mcm","clk":"4234777951","pt":1631549792809,"mc":[{"id":"1.187560677","rc":[{"batl":[[1,1.44,95.15],[2,1.94,3.33]],"ltp":1.21,"tv":27283.77,"id":11439844}]}]}
{"op":"mcm","clk":"4234778541","pt":1631549800589,"mc":[{"id":"1.187560677","rc":[{"batb":[[0,3.7,22.31],[1,3.3,11.77],[2,1.3,5]],"batl":[[0,7,5],[1,7.4,3],[2,7.8,5]],"ltp":4.7,"tv":1641.11,"id":7588306},{"batb":[[0,1.17,459.76],[1,1.16,113],[2,1.15,303.63]],"batl":[[0,1.44,95.15],[1,1.94,3.33],[2,3.8,27.43]],"ltp":1.21,"tv":27283.77,"id":11439844}]}]}
{"op":"mcm","clk":"4234778933","pt":1631549805540,"mc":[{"id":"1.187560677","rc":[{"batb":[[0,5.3,18.48],[1,3.7,22.31],[2,3.3,11.77]],"batl":[[0,5.8,18.92],[1,7,5],[2,7.4,3]],"ltp":4.7,"tv":1641.11,"id":7588306},{"batl":[[0,1.23,20.5],[1,1.44,95.15],[2,1.94,3.33]],"ltp":1.21,"tv":27283.77,"id":11439844}]}]}
{"op":"mcm","clk":"4234778956","pt":1631549805808,"mc":[{"id":"1.187560677","rc":[{"batb":[[0,3.7,22.31],[1,3.3,11.77],[2,1.3,5]],"batl":[[0,7,5],[1,7.4,3],[2,7.8,5]],"ltp":4.7,"tv":1641.11,"id":7588306},{"batl":[[0,1.44,95.15],[1,1.94,3.33],[2,3.8,27.43]],"ltp":1.21,"tv":27283.77,"id":11439844}]}]}
{"op":"mcm","clk":"4234779094","pt":1631549807639,"mc":[{"id":"1.187560677","rc":[{"batl":[[0,6.6,2.01],[1,7,5],[2,7.4,3]],"ltp":4.7,"tv":1641.11,"id":7588306},{"batb":[[0,1.18,143.86],[1,1.17,459.76],[2,1.16,113]],"ltp":1.21,"tv":27283.77,"id":11439844}]}]}
{"op":"mcm","clk":"4234779126","pt":1631549808002,"mc":[{"id":"1.187560677","rc":[{"batl":[[0,7,5],[1,7.4,3],[2,7.8,5]],"ltp":4.7,"tv":1641.11,"id":7588306},{"batb":[[0,1.17,459.76],[1,1.16,113],[2,1.15,303.63]],"ltp":1.21,"tv":27283.77,"id":11439844}]}]}
{"op":"mcm","clk":"4234780000","pt":1631549818408,"mc":[{"id":"1.187560677","rc":[{"batl":[[0,6.6,2.01],[1,7,5],[2,7.4,3]],"ltp":4.7,"tv":1641.11,"id":7588306},{"batb":[[0,1.18,134.86],[1,1.17,459.76],[2,1.16,113]],"ltp":1.21,"tv":27283.77,"id":11439844}]}]}
{"op":"mcm","clk":"4234780034","pt":1631549818883,"mc":[{"id":"1.187560677","rc":[{"batl":[[0,7,5],[1,7.4,3],[2,7.8,5]],"ltp":4.7,"tv":1641.11,"id":7588306},{"batb":[[0,1.17,459.76],[1,1.16,113],[2,1.15,303.63]],"ltp":1.21,"tv":27283.77,"id":11439844}]}]}
{"op":"mcm","clk":"4234780329","pt":1631549822615,"mc":[{"id":"1.187560677","rc":[{"batb":[[1,1.3,5],[2,1.01,105.79]],"ltp":4.7,"tv":1641.11,"id":7588306}]}]}
{"op":"mcm","clk":"4234780547","pt":1631549825397,"mc":[{"id":"1.187560677","rc":[{"batb":[[0,3.75,9.86],[1,3.7,22.31],[2,1.3,5]],"ltp":4.7,"tv":1641.11,"id":7588306}]}]}
{"op":"mcm","clk":"4234780938","pt":1631549829386,"mc":[{"id":"1.187560677","rc":[{"batl":[[0,6.6,2.01],[1,7,5],[2,7.4,3]],"ltp":4.7,"tv":1641.11,"id":7588306},{"batb":[[0,1.18,127.36],[1,1.17,459.76],[2,1.16,113]],"ltp":1.21,"tv":27283.77,"id":11439844}]}]}
{"op":"mcm","clk":"4234780974","pt":1631549829730,"mc":[{"id":"1.187560677","rc":[{"batl":[[0,7,5],[1,7.4,3],[2,7.8,5]],"ltp":4.7,"tv":1641.11,"id":7588306},{"batb":[[0,1.17,459.76],[1,1.16,113],[2,1.15,303.63]],"ltp":1.21,"tv":27283.77,"id":11439844}]}]}
{"op":"mcm","clk":"4234781164","pt":1631549832184,"mc":[{"id":"1.187560677","rc":[{"batl":[[0,7,2]],"ltp":4.7,"tv":1641.11,"id":7588306},{"batb":[[0,1.17,350.76]],"ltp":1.21,"tv":27283.77,"id":11439844}]}]}
{"op":"mcm","clk":"4234781343","pt":1631549834712,"mc":[{"id":"1.187560677","rc":[{"batb":[[0,6.4,5.47],[1,3.75,9.86],[2,3.7,22.31]],"batl":[[0,6.8,4.11],[1,7,2],[2,7.4,3]],"ltp":4.7,"tv":1641.11,"id":7588306},{"trd":[[1.17,459.59]],"batb":[[0,1.17,179.81]],"batl":[[0,1.19,1103.45],[1,1.2,2292.44],[2,1.44,95.15]],"ltp":1.17,"tv":27625.65,"id":11439844}],"tv":29266.76}]}
{"op":"mcm","clk":"4234781407","pt":1631549835613,"mc":[{"id":"1.187560677","rc":[{"trd":[[6.8,22.33],[7,4]],"batb":[[0,7.2,4],[1,6.8,6],[2,6.4,5.47]],"batl":[[0,7.4,3],[1,7.6,194.72],[2,7.8,5]],"ltp":7.0,"tv":1649.22,"id":7588306},{"trd":[[1.17,843.08]],"batb":[[0,1.16,113],[1,1.15,303.63],[2,1.14,298.11]],"batl":[[0,1.17,5.33],[1,1.19,1103.45],[2,1.36,1.71]],"ltp":1.17,"tv":28009.14,"id":11439844}],"tv":29658.36}]}
{"op":"mcm","clk":"4234781445","pt":1631549836194,"mc":[{"id":"1.187560677","rc":[{"batb":[[1,1.15,537.49]],"ltp":1.17,"tv":28009.14,"id":11439844}]}]}
{"op":"mcm","clk":"4234781597","pt":1631549838249,"mc":[{"id":"1.187560677","rc":[{"trd":[[7.2,57.95]],"batb":[[0,7.2,1.72]],"ltp":7.2,"tv":1653.78,"id":7588306},{"trd":[[1.17,853.74]],"batl":[[0,1.19,1103.45],[1,1.36,1.71],[2,1.44,95.15]],"ltp":1.17,"tv":28019.8,"id":11439844}],"tv":29673.58}]}
{"op":"mcm","clk":"4234781634","pt":1631549838716,"mc":[{"id":"1.187560677","rc":[{"batl":[[2,1.39,18.43]],"ltp":1.17,"tv":28019.8,"id":11439844}]}]}
{"op":"mcm","clk":"4234781896","pt":1631549841916,"mc":[{"id":"1.187560677","rc":[{"batl":[[1,1.22,108.75],[2,1.23,117.5]],"ltp":1.17,"tv":28019.8,"id":11439844}]}]}
{"op":"mcm","clk":"4234782195","pt":1631549845214,"mc":[{"id":"1.187560677","rc":[{"batb":[[2,5.5,2.12]],"ltp":7.2,"tv":1653.78,"id":7588306}]}]}
{"op":"mcm","clk":"4234782452","pt":1631549848245,"mc":[{"id":"1.187560677","rc":[{"trd":[[7.2,61.39]],"batb":[[0,6.8,6],[1,5.5,2.12],[2,5.1,21.94]],"batl":[[0,7.2,6.84],[1,7.4,3],[2,7.6,194.72]],"ltp":7.2,"tv":1657.22,"id":7588306},{"batl":[[0,1.18,32.45],[1,1.19,1103.45],[2,1.22,108.75]],"ltp":1.17,"tv":28019.8,"id":11439844}],"tv":29677.02}]}
{"op":"mcm","clk":"4234782730","pt":1631549851855,"mc":[{"id":"1.187560677","rc":[{"batl":[[1,7.4,5]],"ltp":7.2,"tv":1657.22,"id":7588306},{"batb":[[0,1.16,248.03]],"ltp":1.17,"tv":28019.8,"id":11439844}]}]}
{"op":"mcm","clk":"4234783248","pt":1631549857578,"mc":[{"id":"1.187560677","rc":[{"batl":[[0,7.4,5],[1,7.8,5],[2,8.2,2]],"ltp":7.2,"tv":1657.22,"id":7588306},{"batl":[[0,1.22,108.75],[1,1.23,117.5],[2,1.24,109.73]],"ltp":1.17,"tv":28019.8,"id":11439844}]}]}
{"op":"mcm","clk":"4234783296","pt":1631549858136,"mc":[{"id":"1.187560677","rc":[{"batb":[[0,5.1,2.14],[1,4.4,28.35],[2,3.75,9.86]],"batl":[[0,7.4,3]],"ltp":7.2,"tv":1657.22,"id":7588306},{"batb":[[0,1.16,113]],"batl":[[0,1.39,18.43],[1,1.44,94.65],[2,1.94,3.33]],"ltp":1.17,"tv":28019.8,"id":11439844}]}]}
{"op":"mcm","clk":"4234783631","pt":1631549861582,"mc":[{"id":"1.187560677","rc":[{"batb":[[1,4.6,26]],"ltp":7.2,"tv":1657.22,"id":7588306},{"batb":[[1,1.15,303.63],[2,1.14,545.55]],"batl":[[0,1.24,98.23],[1,1.39,18.43],[2,1.44,94.65]],"ltp":1.17,"tv":28019.8,"id":11439844}]}]}
{"op":"mcm","clk":"4234784135","pt":1631549866860,"mc":[{"id":"1.187560677","rc":[{"batl":[[0,7.8,5],[1,8.2,2],[2,8.8,2]],"ltp":7.2,"tv":1657.22,"id":7588306},{"batb":[[0,1.15,303.63],[1,1.14,545.55],[2,1.13,346.04]],"ltp":1.17,"tv":28019.8,"id":11439844}]}]}
{"op":"mcm","clk":"4234784541","pt":1631549871463,"mc":[{"id":"1.187560677","rc":[{"batl":[[0,1.23,111.5],[1,1.24,98.23],[2,1.39,18.43]],"ltp":1.17,"tv":28019.8,"id":11439844}]}]}
{"op":"mcm","clk":"4234784611","pt":1631549872146,"mc":[{"id":"1.187560677","rc":[{"batl":[[0,1.24,98.23],[1,1.39,18.43],[2,1.44,94.65]],"ltp":1.17,"tv":28019.8,"id":11439844}]}]}
{"op":"mcm","clk":"4234784918","pt":1631549875357,"mc":[{"id":"1.187560677","rc":[{"batb":[[0,5.5,2],[1,5.1,2.14],[2,4.6,26]],"batl":[[0,7.4,2],[1,7.8,5],[2,8.2,2]],"ltp":7.2,"tv":1657.22,"id":7588306},{"batb":[[0,1.16,161.28],[1,1.15,303.63],[2,1.14,545.55]],"batl":[[0,1.22,102.75],[1,1.23,109.5],[2,1.24,98.23]],"ltp":1.17,"tv":28019.8,"id":11439844}]}]}
{"op":"mcm","clk":"4234785047","pt":1631549876454,"mc":[{"id":"1.187560677","rc":[{"batb":[[0,5.1,2.14],[1,4.6,26],[2,3.75,9.86]],"batl":[[0,7.8,5],[1,8.2,2],[2,8.8,2]],"ltp":7.2,"tv":1657.22,"id":7588306},{"batb":[[0,1.15,303.63],[1,1.14,545.55],[2,1.13,346.04]],"batl":[[0,1.24,98.23],[1,1.39,18.43],[2,1.44,94.65]],"ltp":1.17,"tv":28019.8,"id":11439844}]}]}
{"op":"mcm","clk":"4234785541","pt":1631549881593,"mc":[{"id":"1.187560677","rc":[{"batb":[[0,5.7,4.38],[1,5.1,2.14],[2,4.6,26]],"batl":[[0,5.8,6.9],[1,6,5.23],[2,6.4,218.27]],"ltp":7.2,"tv":1657.22,"id":7588306},{"batb":[[0,1.17,19.97],[1,1.15,303.63],[2,1.14,545.55]],"batl":[[0,1.23,1000.36],[1,1.24,98.23],[2,1.39,18.43]],"ltp":1.17,"tv":28019.8,"id":11439844}]}]}
{"op":"mcm","clk":"4234785660","pt":1631549882697,"mc":[{"id":"1.187560677","rc":[{"batl":[[2,6.4,230.27]],"ltp":7.2,"tv":1657.22,"id":7588306},{"batb":[[0,1.2,176.32],[1,1.19,371],[2,1.17,214.31]],"ltp":1.17,"tv":28019.8,"id":11439844}]}]}
{"op":"mcm","clk":"4234785669","pt":1631549882804,"mc":[{"id":"1.187560677","rc":[{"batl":[[2,1.39,20.14]],"ltp":1.17,"tv":28019.8,"id":11439844}]}]}
{"op":"mcm","clk":"4234786166","pt":1631549888407,"mc":[{"id":"1.187560677","rc":[{"batb":[[2,1.18,132.86]],"batl":[[2,1.29,86.5]],"ltp":1.17,"tv":28019.8,"id":11439844}]}]}
{"op":"mcm","clk":"4234787354","pt":1631549903614,"mc":[{"id":"1.187560677","rc":[{"trd":[[1.22,11.52]],"ltp":1.22,"tv":28019.82,"id":11439844}],"tv":29677.04}]}
{"op":"mcm","clk":"4234787544","pt":1631549905600,"mc":[{"id":"1.187560677","rc":[{"batb":[[0,5.1,2.14],[1,4.6,26],[2,4.4,2.41]],"batl":[[0,6.4,12],[1,6.6,2],[2,7,2]],"ltp":7.2,"tv":1657.22,"id":7588306},{"batl":[[0,1.24,98.23],[1,1.29,86.5],[2,1.32,82.36]],"ltp":1.22,"tv":28019.82,"id":11439844}]}]}
{"op":"mcm","clk":"4234787630","pt":1631549906399,"mc":[{"id":"1.187560677","rc":[{"batb":[[0,4.1,2.94],[1,3.75,52.97],[2,1.3,5]],"batl":[[0,7,2],[1,7.4,3],[2,7.8,5]],"ltp":7.2,"tv":1657.22,"id":7588306},{"batb":[[0,1.17,347.28],[1,1.16,371],[2,1.15,303.63]],"batl":[[0,1.32,82.36],[1,1.39,18.43],[2,1.44,94.65]],"ltp":1.22,"tv":28019.82,"id":11439844}]}]}
{"op":"mcm","clk":"4234787914","pt":1631549909593,"mc":[{"id":"1.187560677","rc":[{"batl":[[0,6.6,2],[1,7,2],[2,7.4,3]],"ltp":7.2,"tv":1657.22,"id":7588306},{"batb":[[0,1.18,149.86],[1,1.17,347.28],[2,1.16,371]],"ltp":1.22,"tv":28019.82,"id":11439844}]}]}
{"op":"mcm","clk":"4234787945","pt":1631549909900,"mc":[{"id":"1.187560677","rc":[{"batl":[[0,7,2],[1,7.4,3],[2,7.8,5]],"ltp":7.2,"tv":1657.22,"id":7588306},{"batb":[[0,1.17,347.28],[1,1.16,371],[2,1.15,303.63]],"ltp":1.22,"tv":28019.82,"id":11439844}]}]}
{"op":"mcm","clk":"4234788174","pt":1631549912629,"mc":[{"id":"1.187560677","rc":[{"batb":[[0,4.4,2.41],[1,4.1,2.94],[2,3.75,52.97]],"ltp":7.2,"tv":1657.22,"id":7588306},{"batl":[[0,1.29,91.5],[1,1.32,82.36],[2,1.39,18.43]],"ltp":1.22,"tv":28019.82,"id":11439844}]}]}
