{"op":"mcm","clk":"4214285727","pt":1631523892115,"mc":[{"id":"1.187607461","marketDefinition":{"bspMarket":false,"turnInPlayEnabled":true,"persistenceEnabled":true,"marketBaseRate":5.0,"eventId":"30898293","eventTypeId":"2","numberOfWinners":1,"bettingType":"ODDS","marketType":"MATCH_ODDS","marketTime":"2021-09-13T15:00:00.000Z","suspendTime":"2021-09-13T15:00:00.000Z","bspReconciled":false,"complete":true,"inPlay":false,"crossMatching":false,"runnersVoidable":false,"numberOfActiveRunners":2,"betDelay":0,"status":"OPEN","runners":[{"status":"ACTIVE","sortPriority":1,"id":14036296,"name":"E Avanesyan"},{"status":"ACTIVE","sortPriority":2,"id":16100628,"name":"G Maristany Zuleta de Reales"}],"regulators":["MR_INT"],"countryCode":"GB","discountAllowed":false,"timezone":"GMT","openDate":"2021-09-13T15:00:00.000Z","version":4030485517,"name":"Match Odds","eventName":"E Avanesyan v G Maristany Zuleta De Reales"},"rc":[{"batb":[[0,1.01,25]],"ltp":0.0,"tv":0.0,"id":16100628},{"batb":[[0,1.01,25]],"ltp":0.0,"tv":0.0,"id":14036296}]}]}
{"op":"mcm","clk":"4214285817","pt":1631523893902,"mc":[{"id":"1.187607461","marketDefinition":{"bspMarket":false,"turnInPlayEnabled":true,"persistenceEnabled":true,"marketBaseRate":5.0,"eventId":"30898293","eventTypeId":"2","numberOfWinners":1,"bettingType":"ODDS","marketType":"MATCH_ODDS","marketTime":"2021-09-13T15:00:00.000Z","suspendTime":"2021-09-13T15:00:00.000Z","bspReconciled":false,"complete":true,"inPlay":false,"crossMatching":false,"runnersVoidable":false,"numberOfActiveRunners":2,"betDelay":0,"status":"OPEN","runners":[{"status":"ACTIVE","sortPriority":1,"id":14036296,"name":"E Avanesyan"},{"status":"ACTIVE","sortPriority":2,"id":16100628,"name":"G Maristany Zuleta de Reales"}],"regulators":["MR_INT"],"countryCode":"GB","discountAllowed":true,"timezone":"GMT","openDate":"2021-09-13T15:00:00.000Z","version":4030485517,"name":"Match Odds","eventName":"E Avanesyan v G Maristany Zuleta De Reales"}}]}
{"op":"mcm","clk":"4214310324","pt":1631524353170,"mc":[{"id":"1.187607461","rc":[{"batl":[[0,990,2.2]],"ltp":0.0,"tv":0.0,"id":16100628},{"batl":[[0,990,2.2]],"ltp":0.0,"tv":0.0,"id":14036296}]}]}
{"op":"mcm","clk":"4214319697","pt":1631524509124,"mc":[{"id":"1.187607461","rc":[{"batb":[[0,1.01,7]],"ltp":0.0,"tv":0.0,"id":16100628},{"batb":[[0,1.01,7]],"ltp":0.0,"tv":0.0,"id":14036296}]}]}
{"op":"mcm","clk":"4214457274","pt":1631526290480,"mc":[{"id":"1.187607461","rc":[{"batb":[[0,2.2,26.1],[1,1.01,7]],"ltp":0.0,"tv":0.0,"id":16100628},{"batb":[[0,1.62,50.52],[1,1.01,7]],"ltp":0.0,"tv":0.0,"id":14036296}]}]}
{"op":"mcm","clk":"4214458958","pt":1631526311136,"mc":[{"id":"1.187607461","marketDefinition":{"bspMarket":false,"turnInPlayEnabled":true,"persistenceEnabled":true,"marketBaseRate":5.0,"eventId":"30898293","eventTypeId":"2","numberOfWinners":1,"bettingType":"ODDS","marketType":"MATCH_ODDS","marketTime":"2021-09-13T15:00:00.000Z","suspendTime":"2021-09-13T15:00:00.000Z","bspReconciled":false,"complete":true,"inPlay":false,"crossMatching":true,"runnersVoidable":false,"numberOfActiveRunners":2,"betDelay":0,"status":"OPEN","runners":[{"status":"ACTIVE","sortPriority":1,"id":14036296,"name":"E Avanesyan"},{"status":"ACTIVE","sortPriority":2,"id":16100628,"name":"G Maristany Zuleta de Reales"}],"regulators":["MR_INT"],"countryCode":"GB","discountAllowed":true,"timezone":"GMT","openDate":"2021-09-13T15:00:00.000Z","version":4030485517,"name":"Match Odds","eventName":"E Avanesyan v G Maristany Zuleta De Reales"}}]}
{"op":"mcm","clk":"4214722521","pt":1631529723863,"mc":[{"id":"1.187607461","rc":[{"batl":[[0,2.84,106.55],[1,990,2.2]],"ltp":0.0,"tv":0.0,"id":16100628}]}]}
{"op":"mcm","clk":"4214777268","pt":1631530576246,"mc":[{"id":"1.187607461","rc":[{"batb":[[0,2.24,25.26]],"ltp":0.0,"tv":0.0,"id":16100628},{"batb":[[0,1.57,54.95]],"ltp":0.0,"tv":0.0,"id":14036296}]}]}
{"op":"mcm","clk":"4215015118","pt":1631533665519,"mc":[{"id":"1.187607461","rc":[{"batl":[[0,2.84,106.32]],"ltp":0.0,"tv":0.0,"id":16100628}]}]}
{"op":"mcm","clk":"4215121517","pt":1631534936690,"mc":[{"id":"1.187607461","rc":[{"batb":[[1,1.05,874.55],[2,1.01,7]],"ltp":0.0,"tv":0.0,"id":16100628},{"batb":[[1,1.05,874.55],[2,1.01,7]],"ltp":0.0,"tv":0.0,"id":14036296}]}]}
{"op":"mcm","clk":"4215223811","pt":1631536186474,"mc":[{"id":"1.187607461","rc":[{"batb":[[0,2.5,20.88]],"ltp":0.0,"tv":0.0,"id":16100628},{"batb":[[0,1.5,62.65]],"ltp":0.0,"tv":0.0,"id":14036296}]}]}
{"op":"mcm","clk":"4215224562","pt":1631536198783,"mc":[{"id":"1.187607461","rc":[{"batl":[[0,2.22,2.19],[1,990,2.2]],"ltp":0.0,"tv":0.0,"id":14036296}]}]}
{"op":"mcm","clk":"4215267012","pt":1631536866736,"mc":[{"id":"1.187607461","rc":[{"batl":[[0,990,2.2],[1,990,0]],"ltp":0.0,"tv":0.0,"id":14036296}]}]}
{"op":"mcm","clk":"4215282325","pt":1631537138070,"mc":[{"id":"1.187607461","rc":[{"batl":[[0,2.24,2.18],[1,990,2.2]],"ltp":0.0,"tv":0.0,"id":14036296}]}]}
{"op":"mcm","clk":"4215336532","pt":1631538001226,"mc":[{"id":"1.187607461","rc":[{"batb":[[0,2.5,27.84]],"ltp":0.0,"tv":0.0,"id":16100628},{"batb":[[0,1.5,83.53]],"ltp":0.0,"tv":0.0,"id":14036296}]}]}
{"op":"mcm","clk":"4215385279","pt":1631538640638,"mc":[{"id":"1.187607461","rc":[{"batb":[[1,1.05,873.97]],"batl":[[0,2.84,106.46]],"ltp":0.0,"tv":0.0,"id":16100628},{"batb":[[1,1.05,873.97]],"batl":[[0,990,2.2],[1,990,0]],"ltp":0.0,"tv":0.0,"id":14036296}]}]}
{"op":"mcm","clk":"4215407531","pt":1631538916239,"mc":[{"id":"1.187607461","rc":[{"batl":[[0,2.2,2.21],[1,990,2.2]],"ltp":0.0,"tv":0.0,"id":14036296}]}]}
{"op":"mcm","clk":"4215471655","pt":1631539615744,"mc":[{"id":"1.187607461","marketDefinition":{"bspMarket":false,"turnInPlayEnabled":true,"persistenceEnabled":true,"marketBaseRate":5.0,"eventId":"30898293","eventTypeId":"2","numberOfWinners":1,"bettingType":"ODDS","marketType":"MATCH_ODDS","marketTime":"2021-09-13T15:10:00.000Z","suspendTime":"2021-09-13T15:10:00.000Z","bspReconciled":false,"complete":true,"inPlay":false,"crossMatching":true,"runnersVoidable":false,"numberOfActiveRunners":2,"betDelay":0,"status":"OPEN","runners":[{"status":"ACTIVE","sortPriority":1,"id":14036296,"name":"E Avanesyan"},{"status":"ACTIVE","sortPriority":2,"id":16100628,"name":"G Maristany Zuleta de Reales"}],"regulators":["MR_INT"],"countryCode":"GB","discountAllowed":true,"timezone":"GMT","openDate":"2021-09-13T15:00:00.000Z","version":4030708187,"name":"Match Odds","eventName":"E Avanesyan v G Maristany Zuleta De Reales"}}]}
{"op":"mcm","clk":"4215471778","pt":1631539617753,"mc":[{"id":"1.187607461","marketDefinition":{"bspMarket":false,"turnInPlayEnabled":true,"persistenceEnabled":true,"marketBaseRate":5.0,"eventId":"30898293","eventTypeId":"2","numberOfWinners":1,"bettingType":"ODDS","marketType":"MATCH_ODDS","marketTime":"2021-09-13T15:10:00.000Z","suspendTime":"2021-09-13T15:10:00.000Z","bspReconciled":false,"complete":true,"inPlay":false,"crossMatching":true,"runnersVoidable":false,"numberOfActiveRunners":2,"betDelay":0,"status":"OPEN","runners":[{"status":"ACTIVE","sortPriority":1,"id":14036296,"name":"E Avanesyan"},{"status":"ACTIVE","sortPriority":2,"id":16100628,"name":"G Maristany Zuleta de Reales"}],"regulators":["MR_INT"],"countryCode":"GB","discountAllowed":true,"timezone":"GMT","openDate":"2021-09-13T15:10:00.000Z","version":4030708187,"name":"Match Odds","eventName":"E Avanesyan v G Maristany Zuleta De Reales"}}]}
{"op":"mcm","clk":"4215471836","pt":1631539618713,"mc":[{"id":"1.187607461","rc":[{"batl":[[0,990,2.2],[1,990,0]],"ltp":0.0,"tv":0.0,"id":14036296}]}]}
{"op":"mcm","clk":"4215471854","pt":1631539618921,"mc":[{"id":"1.187607461","rc":[{"batl":[[0,2,2.44],[1,990,2.2]],"ltp":0.0,"tv":0.0,"id":14036296}]}]}
{"op":"mcm","clk":"4215514129","pt":1631540229192,"mc":[{"id":"1.187607461","marketDefinition":{"bspMarket":false,"turnInPlayEnabled":true,"persistenceEnabled":true,"marketBaseRate":5.0,"eventId":"30898293","eventTypeId":"2","numberOfWinners":1,"bettingType":"ODDS","marketType":"MATCH_ODDS","marketTime":"2021-09-13T15:20:00.000Z","suspendTime":"2021-09-13T15:20:00.000Z","bspReconciled":false,"complete":true,"inPlay":false,"crossMatching":true,"runnersVoidable":false,"numberOfActiveRunners":2,"betDelay":0,"status":"OPEN","runners":[{"status":"ACTIVE","sortPriority":1,"id":14036296,"name":"E Avanesyan"},{"status":"ACTIVE","sortPriority":2,"id":16100628,"name":"G Maristany Zuleta de Reales"}],"regulators":["MR_INT"],"countryCode":"GB","discountAllowed":true,"timezone":"GMT","openDate":"2021-09-13T15:10:00.000Z","version":4030721080,"name":"Match Odds","eventName":"E Avanesyan v G Maristany Zuleta De Reales"}}]}
{"op":"mcm","clk":"4215514356","pt":1631540232538,"mc":[{"id":"1.187607461","marketDefinition":{"bspMarket":false,"turnInPlayEnabled":true,"persistenceEnabled":true,"marketBaseRate":5.0,"eventId":"30898293","eventTypeId":"2","numberOfWinners":1,"bettingType":"ODDS","marketType":"MATCH_ODDS","marketTime":"2021-09-13T15:20:00.000Z","suspendTime":"2021-09-13T15:20:00.000Z","bspReconciled":false,"complete":true,"inPlay":false,"crossMatching":true,"runnersVoidable":false,"numberOfActiveRunners":2,"betDelay":0,"status":"OPEN","runners":[{"status":"ACTIVE","sortPriority":1,"id":14036296,"name":"E Avanesyan"},{"status":"ACTIVE","sortPriority":2,"id":16100628,"name":"G Maristany Zuleta de Reales"}],"regulators":["MR_INT"],"countryCode":"GB","discountAllowed":true,"timezone":"GMT","openDate":"2021-09-13T15:20:00.000Z","version":4030721080,"name":"Match Odds","eventName":"E Avanesyan v G Maristany Zuleta De Reales"},"rc":[{"batl":[[0,2.12,2.3]],"ltp":0.0,"tv":0.0,"id":14036296}]}]}
{"op":"mcm","clk":"4215514751","pt":1631540238838,"mc":[{"id":"1.187607461","rc":[{"batl":[[0,2.2,2.22]],"ltp":0.0,"tv":0.0,"id":14036296}]}]}
{"op":"mcm","clk":"4215517942","pt":1631540290526,"mc":[{"id":"1.187607461","marketDefinition":{"bspMarket":false,"turnInPlayEnabled":true,"persistenceEnabled":true,"marketBaseRate":5.0,"eventId":"30898293","eventTypeId":"2","numberOfWinners":1,"bettingType":"ODDS","marketType":"MATCH_ODDS","marketTime":"2021-09-13T15:15:00.000Z","suspendTime":"2021-09-13T15:15:00.000Z","bspReconciled":false,"complete":true,"inPlay":false,"crossMatching":true,"runnersVoidable":false,"numberOfActiveRunners":2,"betDelay":0,"status":"OPEN","runners":[{"status":"ACTIVE","sortPriority":1,"id":14036296,"name":"E Avanesyan"},{"status":"ACTIVE","sortPriority":2,"id":16100628,"name":"G Maristany Zuleta de Reales"}],"regulators":["MR_INT"],"countryCode":"GB","discountAllowed":true,"timezone":"GMT","openDate":"2021-09-13T15:20:00.000Z","version":4030721362,"name":"Match Odds","eventName":"E Avanesyan v G Maristany Zuleta De Reales"}}]}
{"op":"mcm","clk":"4215518103","pt":1631540292894,"mc":[{"id":"1.187607461","marketDefinition":{"bspMarket":false,"turnInPlayEnabled":true,"persistenceEnabled":true,"marketBaseRate":5.0,"eventId":"30898293","eventTypeId":"2","numberOfWinners":1,"bettingType":"ODDS","marketType":"MATCH_ODDS","marketTime":"2021-09-13T15:15:00.000Z","suspendTime":"2021-09-13T15:15:00.000Z","bspReconciled":false,"complete":true,"inPlay":false,"crossMatching":true,"runnersVoidable":false,"numberOfActiveRunners":2,"betDelay":0,"status":"OPEN","runners":[{"status":"ACTIVE","sortPriority":1,"id":14036296,"name":"E Avanesyan"},{"status":"ACTIVE","sortPriority":2,"id":16100628,"name":"G Maristany Zuleta de Reales"}],"regulators":["MR_INT"],"countryCode":"GB","discountAllowed":true,"timezone":"GMT","openDate":"2021-09-13T15:15:00.000Z","version":4030721362,"name":"Match Odds","eventName":"E Avanesyan v G Maristany Zuleta De Reales"},"rc":[{"batl":[[0,2.22,2.2]],"ltp":0.0,"tv":0.0,"id":14036296}]}]}
{"op":"mcm","clk":"4215518481","pt":1631540299609,"mc":[{"id":"1.187607461","rc":[{"batl":[[0,990,2.2],[1,990,0]],"ltp":0.0,"tv":0.0,"id":14036296}]}]}
{"op":"mcm","clk":"4215518501","pt":1631540299927,"mc":[{"id":"1.187607461","rc":[{"batl":[[0,2.2,2.22],[1,990,2.2]],"ltp":0.0,"tv":0.0,"id":14036296}]}]}
{"op":"mcm","clk":"4215547306","pt":1631540796885,"mc":[{"id":"1.187607461","rc":[{"batl":[[0,990,2.2],[1,990,0]],"ltp":0.0,"tv":0.0,"id":14036296}]}]}
{"op":"mcm","clk":"4215549191","pt":1631540826851,"mc":[{"id":"1.187607461","rc":[{"batl":[[0,2.04,2.39],[1,990,2.2]],"ltp":0.0,"tv":0.0,"id":14036296}]}]}
{"op":"mcm","clk":"4215599206","pt":1631541647840,"mc":[{"id":"1.187607461","marketDefinition":{"bspMarket":false,"turnInPlayEnabled":true,"persistenceEnabled":true,"marketBaseRate":5.0,"eventId":"30898293","eventTypeId":"2","numberOfWinners":1,"bettingType":"ODDS","marketType":"MATCH_ODDS","marketTime":"2021-09-13T15:25:00.000Z","suspendTime":"2021-09-13T15:25:00.000Z","bspReconciled":false,"complete":true,"inPlay":false,"crossMatching":true,"runnersVoidable":false,"numberOfActiveRunners":2,"betDelay":0,"status":"OPEN","runners":[{"status":"ACTIVE","sortPriority":1,"id":14036296,"name":"E Avanesyan"},{"status":"ACTIVE","sortPriority":2,"id":16100628,"name":"G Maristany Zuleta de Reales"}],"regulators":["MR_INT"],"countryCode":"GB","discountAllowed":true,"timezone":"GMT","openDate":"2021-09-13T15:15:00.000Z","version":4030746147,"name":"Match Odds","eventName":"E Avanesyan v G Maristany Zuleta De Reales"}}]}
{"op":"mcm","clk":"4215599339","pt":1631541649850,"mc":[{"id":"1.187607461","marketDefinition":{"bspMarket":false,"turnInPlayEnabled":true,"persistenceEnabled":true,"marketBaseRate":5.0,"eventId":"30898293","eventTypeId":"2","numberOfWinners":1,"bettingType":"ODDS","marketType":"MATCH_ODDS","marketTime":"2021-09-13T15:25:00.000Z","suspendTime":"2021-09-13T15:25:00.000Z","bspReconciled":false,"complete":true,"inPlay":false,"crossMatching":true,"runnersVoidable":false,"numberOfActiveRunners":2,"betDelay":0,"status":"OPEN","runners":[{"status":"ACTIVE","sortPriority":1,"id":14036296,"name":"E Avanesyan"},{"status":"ACTIVE","sortPriority":2,"id":16100628,"name":"G Maristany Zuleta de Reales"}],"regulators":["MR_INT"],"countryCode":"GB","discountAllowed":true,"timezone":"GMT","openDate":"2021-09-13T15:25:00.000Z","version":4030746147,"name":"Match Odds","eventName":"E Avanesyan v G Maristany Zuleta De Reales"}}]}
{"op":"mcm","clk":"4215599354","pt":1631541650032,"mc":[{"id":"1.187607461","rc":[{"batl":[[0,990,2.2],[1,990,0]],"ltp":0.0,"tv":0.0,"id":14036296}]}]}
{"op":"mcm","clk":"4215599426","pt":1631541651433,"mc":[{"id":"1.187607461","rc":[{"batl":[[0,2.04,2.39],[1,990,2.2]],"ltp":0.0,"tv":0.0,"id":14036296}]}]}
{"op":"mcm","clk":"4215694210","pt":1631543101672,"mc":[{"id":"1.187607461","rc":[{"batb":[[0,2.52,8.41],[1,2.5,27.84],[2,1.05,873.97]],"ltp":0.0,"tv":0.0,"id":16100628},{"batb":[[0,1.55,23.22],[1,1.5,83.53],[2,1.05,873.97]],"batl":[[0,1.98,2.46]],"ltp":0.0,"tv":0.0,"id":14036296}]}]}
{"op":"mcm","clk":"4215694884","pt":1631543110698,"mc":[{"id":"1.187607461","rc":[{"batl":[[0,990,2.2],[1,990,0]],"ltp":0.0,"tv":0.0,"id":14036296}]}]}
{"op":"mcm","clk":"4215712895","pt":1631543401624,"mc":[{"id":"1.187607461","rc":[{"batl":[[0,2.18,2.61],[1,990,2.2]],"ltp":0.0,"tv":0.0,"id":14036296}]}]}
{"op":"mcm","clk":"4215739493","pt":1631543701872,"mc":[{"id":"1.187607461","rc":[{"batl":[[0,990,2.2],[1,990,0]],"ltp":0.0,"tv":0.0,"id":14036296}]}]}
{"op":"mcm","clk":"4215766293","pt":1631544001844,"mc":[{"id":"1.187607461","rc":[{"batl":[[0,1.93,2.95],[1,990,2.2]],"ltp":0.0,"tv":0.0,"id":14036296}]}]}
{"op":"mcm","clk":"4215788864","pt":1631544270802,"mc":[{"id":"1.187607461","rc":[{"batb":[[2,1.01,7]],"ltp":0.0,"tv":0.0,"id":14036296}]}]}
{"op":"mcm","clk":"4215788889","pt":1631544271112,"mc":[{"id":"1.187607461","rc":[{"batb":[[2,1.01,7]],"ltp":0.0,"tv":0.0,"id":16100628}]}]}
{"op":"mcm","clk":"4215789771","pt":1631544282815,"mc":[{"id":"1.187607461","rc":[{"batb":[[2,1.25,174.79]],"batl":[[1,2.4,43.7],[2,990,2.2]],"ltp":0.0,"tv":0.0,"id":14036296}]}]}
{"op":"mcm","clk":"4215838599","pt":1631544801527,"mc":[{"id":"1.187607461","rc":[{"batl":[[1,1.95,2.66],[2,2.4,43.7]],"ltp":0.0,"tv":0.0,"id":14036296}]}]}
{"op":"mcm","clk":"4215937491","pt":1631546101347,"mc":[{"id":"1.187607461","rc":[{"batb":[[0,2.52,8.42],[2,2.34,111.94]],"batl":[[0,2.84,106.47]],"ltp":0.0,"tv":0.0,"id":16100628},{"batb":[[0,1.55,23.25],[2,1.48,312.5]],"batl":[[2,2.4,43.65]],"ltp":0.0,"tv":0.0,"id":14036296}]}]}
{"op":"mcm","clk":"4215967134","pt":1631546402016,"mc":[{"id":"1.187607461","rc":[{"batl":[[0,1.95,2.66],[1,2.4,43.65],[2,990,2.2]],"ltp":0.0,"tv":0.0,"id":14036296}]}]}
{"op":"mcm","clk":"4215971348","pt":1631546444831,"mc":[{"id":"1.187607461","marketDefinition":{"bspMarket":false,"turnInPlayEnabled":true,"persistenceEnabled":true,"marketBaseRate":5.0,"eventId":"30898293","eventTypeId":"2","numberOfWinners":1,"bettingType":"ODDS","marketType":"MATCH_ODDS","marketTime":"2021-09-13T15:20:00.000Z","suspendTime":"2021-09-13T15:20:00.000Z","bspReconciled":false,"complete":true,"inPlay":false,"crossMatching":true,"runnersVoidable":false,"numberOfActiveRunners":2,"betDelay":0,"status":"OPEN","runners":[{"status":"ACTIVE","sortPriority":1,"id":14036296,"name":"E Avanesyan"},{"status":"ACTIVE","sortPriority":2,"id":16100628,"name":"G Maristany Zuleta de Reales"}],"regulators":["MR_INT"],"countryCode":"GB","discountAllowed":true,"timezone":"GMT","openDate":"2021-09-13T15:25:00.000Z","version":4030824574,"name":"Match Odds","eventName":"E Avanesyan v G Maristany Zuleta De Reales"}}]}
{"op":"mcm","clk":"4215971658","pt":1631546447856,"mc":[{"id":"1.187607461","marketDefinition":{"bspMarket":false,"turnInPlayEnabled":true,"persistenceEnabled":true,"marketBaseRate":5.0,"eventId":"30898293","eventTypeId":"2","numberOfWinners":1,"bettingType":"ODDS","marketType":"MATCH_ODDS","marketTime":"2021-09-13T15:20:00.000Z","suspendTime":"2021-09-13T15:20:00.000Z","bspReconciled":false,"complete":true,"inPlay":false,"crossMatching":true,"runnersVoidable":false,"numberOfActiveRunners":2,"betDelay":0,"status":"OPEN","runners":[{"status":"ACTIVE","sortPriority":1,"id":14036296,"name":"E Avanesyan"},{"status":"ACTIVE","sortPriority":2,"id":16100628,"name":"G Maristany Zuleta de Reales"}],"regulators":["MR_INT"],"countryCode":"GB","discountAllowed":true,"timezone":"GMT","openDate":"2021-09-13T15:20:00.000Z","version":4030824574,"name":"Match Odds","eventName":"E Avanesyan v G Maristany Zuleta De Reales"}}]}
{"op":"mcm","clk":"4215977315","pt":1631546502276,"mc":[{"id":"1.187607461","marketDefinition":{"bspMarket":false,"turnInPlayEnabled":true,"persistenceEnabled":true,"marketBaseRate":5.0,"eventId":"30898293","eventTypeId":"2","numberOfWinners":1,"bettingType":"ODDS","marketType":"MATCH_ODDS","marketTime":"2021-09-13T15:20:00.000Z","suspendTime":"2021-09-13T15:20:00.000Z","bspReconciled":false,"complete":true,"inPlay":true,"crossMatching":true,"runnersVoidable":false,"numberOfActiveRunners":2,"betDelay":5,"status":"OPEN","runners":[{"status":"ACTIVE","sortPriority":1,"id":14036296,"name":"E Avanesyan"},{"status":"ACTIVE","sortPriority":2,"id":16100628,"name":"G Maristany Zuleta de Reales"}],"regulators":["MR_INT"],"countryCode":"GB","discountAllowed":true,"timezone":"GMT","openDate":"2021-09-13T15:20:00.000Z","version":4030826749,"name":"Match Odds","eventName":"E Avanesyan v G Maristany Zuleta De Reales"},"rc":[{"batb":[[0,1.01,7],[1,2.5,0],[2,2.34,0]],"batl":[[1,990,0]],"ltp":0.0,"tv":0.0,"id":16100628},{"batb":[[0,1.01,7],[1,1.5,0],[2,1.48,0]],"ltp":0.0,"tv":0.0,"id":14036296}]}]}
{"op":"mcm","clk":"4215977854","pt":1631546507476,"mc":[{"id":"1.187607461","rc":[{"batb":[[0,2.46,20.54],[1,1.01,7]],"ltp":0.0,"tv":0.0,"id":16100628},{"batb":[[0,1.48,62.5],[1,1.01,7]],"ltp":0.0,"tv":0.0,"id":14036296}]}]}
{"op":"mcm","clk":"4216019952","pt":1631547048714,"mc":[{"id":"1.187607461","rc":[{"batb":[[0,1.01,7],[1,1.01,0]],"ltp":0.0,"tv":0.0,"id":16100628}]}]}
{"op":"mcm","clk":"4216019979","pt":1631547048948,"mc":[{"id":"1.187607461","marketDefinition":{"bspMarket":false,"turnInPlayEnabled":true,"persistenceEnabled":true,"marketBaseRate":5.0,"eventId":"30898293","eventTypeId":"2","numberOfWinners":1,"bettingType":"ODDS","marketType":"MATCH_ODDS","marketTime":"2021-09-13T15:30:48.000Z","suspendTime":"2021-09-13T15:30:48.000Z","bspReconciled":false,"complete":true,"inPlay":true,"crossMatching":true,"runnersVoidable":false,"numberOfActiveRunners":2,"betDelay":5,"status":"OPEN","runners":[{"status":"ACTIVE","sortPriority":1,"id":14036296,"name":"E Avanesyan"},{"status":"ACTIVE","sortPriority":2,"id":16100628,"name":"G Maristany Zuleta de Reales"}],"regulators":["MR_INT"],"countryCode":"GB","discountAllowed":true,"timezone":"GMT","openDate":"2021-09-13T15:20:00.000Z","version":4030835131,"name":"Match Odds","eventName":"E Avanesyan v G Maristany Zuleta De Reales"}}]}
{"op":"mcm","clk":"4216020109","pt":1631547050958,"mc":[{"id":"1.187607461","marketDefinition":{"bspMarket":false,"turnInPlayEnabled":true,"persistenceEnabled":true,"marketBaseRate":5.0,"eventId":"30898293","eventTypeId":"2","numberOfWinners":1,"bettingType":"ODDS","marketType":"MATCH_ODDS","marketTime":"2021-09-13T15:30:48.000Z","suspendTime":"2021-09-13T15:30:48.000Z","bspReconciled":false,"complete":true,"inPlay":true,"crossMatching":true,"runnersVoidable":false,"numberOfActiveRunners":2,"betDelay":5,"status":"OPEN","runners":[{"status":"ACTIVE","sortPriority":1,"id":14036296,"name":"E Avanesyan"},{"status":"ACTIVE","sortPriority":2,"id":16100628,"name":"G Maristany Zuleta de Reales"}],"regulators":["MR_INT"],"countryCode":"GB","discountAllowed":true,"timezone":"GMT","openDate":"2021-09-13T15:30:48.000Z","version":4030835131,"name":"Match Odds","eventName":"E Avanesyan v G Maristany Zuleta De Reales"}}]}
{"op":"mcm","clk":"4216020278","pt":1631547053678,"mc":[{"id":"1.187607461","rc":[{"batb":[[0,2.5,20],[1,1.01,7]],"ltp":0.0,"tv":0.0,"id":16100628}]}]}
{"op":"mcm","clk":"4216020752","pt":1631547061012,"mc":[{"id":"1.187607461","rc":[{"batb":[[0,1.01,7],[1,1.01,0]],"ltp":0.0,"tv":0.0,"id":16100628},{"batb":[[0,1.01,7],[1,1.01,0]],"ltp":0.0,"tv":0.0,"id":14036296}]}]}
{"op":"mcm","clk":"4216021071","pt":1631547065913,"mc":[{"id":"1.187607461","rc":[{"batb":[[0,2.34,22.38],[1,1.01,7]],"ltp":0.0,"tv":0.0,"id":16100628},{"batb":[[0,1.55,54.54],[1,1.01,7]],"ltp":0.0,"tv":0.0,"id":14036296}]}]}
{"op":"mcm","clk":"4216022023","pt":1631547078523,"mc":[{"id":"1.187607461","rc":[{"batb":[[0,1.01,7],[1,1.01,0]],"ltp":0.0,"tv":0.0,"id":16100628},{"batb":[[0,1.01,7],[1,1.01,0]],"ltp":0.0,"tv":0.0,"id":14036296}]}]}
{"op":"mcm","clk":"4216022429","pt":1631547083503,"mc":[{"id":"1.187607461","rc":[{"batb":[[0,2.5,20],[1,1.01,7]],"ltp":0.0,"tv":0.0,"id":16100628},{"batb":[[0,1.48,62.5],[1,1.01,7]],"ltp":0.0,"tv":0.0,"id":14036296}]}]}
{"op":"mcm","clk":"4216023514","pt":1631547100165,"mc":[{"id":"1.187607461","rc":[{"batb":[[0,1.01,7],[1,1.01,0]],"ltp":0.0,"tv":0.0,"id":16100628},{"batb":[[0,1.01,7],[1,1.01,0]],"ltp":0.0,"tv":0.0,"id":14036296}]}]}
{"op":"mcm","clk":"4216023761","pt":1631547104981,"mc":[{"id":"1.187607461","rc":[{"batb":[[0,2.34,22.38],[1,1.01,7]],"ltp":0.0,"tv":0.0,"id":16100628},{"batb":[[0,1.55,54.54],[1,1.01,7]],"ltp":0.0,"tv":0.0,"id":14036296}]}]}
{"op":"mcm","clk":"4216024867","pt":1631547120922,"mc":[{"id":"1.187607461","rc":[{"batb":[[0,1.01,7],[1,1.01,0]],"ltp":0.0,"tv":0.0,"id":16100628},{"batb":[[0,1.01,7],[1,1.01,0]],"ltp":0.0,"tv":0.0,"id":14036296}]}]}
{"op":"mcm","clk":"4216025159","pt":1631547125855,"mc":[{"id":"1.187607461","rc":[{"batb":[[0,2.5,20],[1,1.01,7]],"ltp":0.0,"tv":0.0,"id":16100628},{"batb":[[0,1.48,62.5],[1,1.01,7]],"ltp":0.0,"tv":0.0,"id":14036296}]}]}
{"op":"mcm","clk":"4216026942","pt":1631547154102,"mc":[{"id":"1.187607461","rc":[{"batb":[[0,1.01,7],[1,1.01,0]],"ltp":0.0,"tv":0.0,"id":16100628},{"batb":[[0,1.01,7],[1,1.01,0]],"ltp":0.0,"tv":0.0,"id":14036296}]}]}
{"op":"mcm","clk":"4216027246","pt":1631547158980,"mc":[{"id":"1.187607461","rc":[{"batb":[[0,2.26,23.8],[1,1.01,7]],"ltp":0.0,"tv":0.0,"id":16100628},{"batb":[[0,1.58,51.72],[1,1.01,7]],"ltp":0.0,"tv":0.0,"id":14036296}]}]}
{"op":"mcm","clk":"4216027757","pt":1631547166782,"mc":[{"id":"1.187607461","rc":[{"batb":[[0,1.01,7],[1,1.01,0]],"ltp":0.0,"tv":0.0,"id":16100628},{"batb":[[0,1.01,7],[1,1.01,0]],"ltp":0.0,"tv":0.0,"id":14036296}]}]}
{"op":"mcm","clk":"4216028057","pt":1631547171709,"mc":[{"id":"1.187607461","rc":[{"batb":[[0,2.2,24.99],[1,1.01,7]],"ltp":0.0,"tv":0.0,"id":16100628},{"batb":[[0,1.6,49.99],[1,1.01,7]],"ltp":0.0,"tv":0.0,"id":14036296}]}]}
{"op":"mcm","clk":"4216029436","pt":1631547190148,"mc":[{"id":"1.187607461","rc":[{"batb":[[0,1.01,7],[1,1.01,0]],"ltp":0.0,"tv":0.0,"id":16100628},{"batb":[[0,1.01,7],[1,1.01,0]],"ltp":0.0,"tv":0.0,"id":14036296}]}]}
{"op":"mcm","clk":"4216029840","pt":1631547195041,"mc":[{"id":"1.187607461","rc":[{"batb":[[0,2,30],[1,1.01,7]],"ltp":0.0,"tv":0.0,"id":16100628},{"batb":[[0,1.73,41.09],[1,1.01,7]],"ltp":0.0,"tv":0.0,"id":14036296}]}]}
{"op":"mcm","clk":"4216033851","pt":1631547243368,"mc":[{"id":"1.187607461","rc":[{"batb":[[0,1.01,7],[1,1.01,0]],"ltp":0.0,"tv":0.0,"id":14036296}]}]}
{"op":"mcm","clk":"4216034224","pt":1631547248412,"mc":[{"id":"1.187607461","rc":[{"batb":[[0,1.71,42.25],[1,1.01,7]],"ltp":0.0,"tv":0.0,"id":14036296}]}]}
{"op":"mcm","clk":"4216034918","pt":1631547257905,"mc":[{"id":"1.187607461","rc":[{"batb":[[0,1.01,7],[1,1.01,0]],"ltp":0.0,"tv":0.0,"id":16100628},{"batb":[[0,1.01,7],[1,1.01,0]],"ltp":0.0,"tv":0.0,"id":14036296}]}]}
{"op":"mcm","clk":"4216035258","pt":1631547262813,"mc":[{"id":"1.187607461","rc":[{"batb":[[0,1.98,30.61],[1,1.01,7]],"ltp":0.0,"tv":0.0,"id":16100628},{"batb":[[0,1.78,38.46],[1,1.01,7]],"ltp":0.0,"tv":0.0,"id":14036296}]}]}
{"op":"mcm","clk":"4216037042","pt":1631547286501,"mc":[{"id":"1.187607461","rc":[{"batb":[[0,1.01,7],[1,1.01,0]],"ltp":0.0,"tv":0.0,"id":16100628},{"batb":[[0,1.01,7],[1,1.01,0]],"ltp":0.0,"tv":0.0,"id":14036296}]}]}
{"op":"mcm","clk":"4216037422","pt":1631547291428,"mc":[{"id":"1.187607461","rc":[{"batb":[[0,2.06,28.3],[1,1.01,7]],"ltp":0.0,"tv":0.0,"id":16100628},{"batb":[[0,1.71,42.25],[1,1.01,7]],"ltp":0.0,"tv":0.0,"id":14036296}]}]}
{"op":"mcm","clk":"4216041159","pt":1631547341964,"mc":[{"id":"1.187607461","rc":[{"batb":[[0,1.01,7],[1,1.01,0]],"ltp":0.0,"tv":0.0,"id":16100628},{"batb":[[0,1.01,7],[1,1.01,0]],"ltp":0.0,"tv":0.0,"id":14036296}]}]}
{"op":"mcm","clk":"4216041526","pt":1631547346871,"mc":[{"id":"1.187607461","rc":[{"batb":[[0,1.88,34.09],[1,1.01,7]],"ltp":0.0,"tv":0.0,"id":16100628},{"batb":[[0,1.85,35.29],[1,1.01,7]],"ltp":0.0,"tv":0.0,"id":14036296}]}]}
{"op":"mcm","clk":"4216041616","pt":1631547348070,"mc":[{"id":"1.187607461","rc":[{"batb":[[1,1.58,422.65],[2,1.01,7]],"ltp":0.0,"tv":0.0,"id":14036296}]}]}
{"op":"mcm","clk":"4216042098","pt":1631547354766,"mc":[{"id":"1.187607461","rc":[{"batb":[[0,1.01,7],[1,1.01,0]],"ltp":0.0,"tv":0.0,"id":16100628},{"batb":[[0,1.01,7],[1,1.58,0],[2,1.01,0]],"ltp":0.0,"tv":0.0,"id":14036296}]}]}
{"op":"mcm","clk":"4216042377","pt":1631547359391,"mc":[{"id":"1.187607461","rc":[{"batb":[[0,1.78,38.46],[1,1.01,7]],"ltp":0.0,"tv":0.0,"id":16100628},{"batb":[[0,1.98,30.61],[1,1.01,7]],"ltp":0.0,"tv":0.0,"id":14036296}]}]}
{"op":"mcm","clk":"4216042452","pt":1631547360390,"mc":[{"id":"1.187607461","rc":[{"batb":[[1,1.62,421.6],[2,1.01,7]],"ltp":0.0,"tv":0.0,"id":14036296}]}]}
{"op":"mcm","clk":"4216044638","pt":1631547387800,"mc":[{"id":"1.187607461","rc":[{"batb":[[0,1.01,7],[1,1.01,0]],"ltp":0.0,"tv":0.0,"id":16100628},{"batb":[[0,1.62,421.6],[1,1.01,7],[2,1.01,0]],"ltp":0.0,"tv":0.0,"id":14036296}]}]}
{"op":"mcm","clk":"4216045042","pt":1631547392802,"mc":[{"id":"1.187607461","rc":[{"batb":[[0,1.85,35.29],[1,1.01,7]],"ltp":0.0,"tv":0.0,"id":16100628},{"batb":[[0,1.88,34.09],[1,1.62,421.6],[2,1.01,7]],"ltp":0.0,"tv":0.0,"id":14036296}]}]}
{"op":"mcm","clk":"4216045741","pt":1631547401608,"mc":[{"id":"1.187607461","rc":[{"batb":[[0,1.01,7],[1,1.01,0]],"ltp":0.0,"tv":0.0,"id":16100628},{"batb":[[0,1.62,421.6],[1,1.01,7],[2,1.01,0]],"ltp":0.0,"tv":0.0,"id":14036296}]}]}
{"op":"mcm","clk":"4216046101","pt":1631547406517,"mc":[{"id":"1.187607461","rc":[{"batb":[[0,1.88,34.09],[1,1.01,7]],"ltp":0.0,"tv":0.0,"id":16100628},{"batb":[[0,1.85,35.29],[1,1.62,421.6],[2,1.01,7]],"ltp":0.0,"tv":0.0,"id":14036296}]}]}
{"op":"mcm","clk":"4216047973","pt":1631547428851,"mc":[{"id":"1.187607461","rc":[{"batb":[[0,1.01,7],[1,1.01,0]],"ltp":0.0,"tv":0.0,"id":16100628},{"batb":[[0,1.01,7],[1,1.62,0],[2,1.01,0]],"ltp":0.0,"tv":0.0,"id":14036296}]}]}
{"op":"mcm","clk":"4216048473","pt":1631547433880,"mc":[{"id":"1.187607461","rc":[{"batb":[[0,1.78,38.46],[1,1.01,7]],"ltp":0.0,"tv":0.0,"id":16100628},{"batb":[[0,1.98,30.61],[1,1.01,7]],"ltp":0.0,"tv":0.0,"id":14036296}]}]}
{"op":"mcm","clk":"4216048499","pt":1631547434144,"mc":[{"id":"1.187607461","rc":[{"batb":[[1,1.67,415.84],[2,1.01,7]],"ltp":0.0,"tv":0.0,"id":14036296}]}]}
{"op":"mcm","clk":"4216050058","pt":1631547453107,"mc":[{"id":"1.187607461","rc":[{"batb":[[0,1.01,7],[1,1.01,0]],"ltp":0.0,"tv":0.0,"id":16100628},{"batb":[[0,1.67,415.84],[1,1.01,7],[2,1.01,0]],"ltp":0.0,"tv":0.0,"id":14036296}]}]}
{"op":"mcm","clk":"4216050485","pt":1631547458092,"mc":[{"id":"1.187607461","rc":[{"batb":[[0,1.73,41.09],[1,1.01,7]],"ltp":0.0,"tv":0.0,"id":16100628},{"batb":[[0,2,30],[1,1.67,415.84],[2,1.01,7]],"ltp":0.0,"tv":0.0,"id":14036296}]}]}
{"op":"mcm","clk":"4216051086","pt":1631547464797,"mc":[{"id":"1.187607461","rc":[{"batb":[[0,1.01,7],[1,1.01,0]],"ltp":0.0,"tv":0.0,"id":16100628},{"batb":[[0,1.67,415.84],[1,1.01,7],[2,1.01,0]],"ltp":0.0,"tv":0.0,"id":14036296}]}]}
{"op":"mcm","clk":"4216051515","pt":1631547469820,"mc":[{"id":"1.187607461","rc":[{"batb":[[0,1.65,46.15],[1,1.01,7]],"ltp":0.0,"tv":0.0,"id":16100628},{"batb":[[0,2.1,27.27],[1,1.67,415.84],[2,1.01,7]],"ltp":0.0,"tv":0.0,"id":14036296}]}]}
{"op":"mcm","clk":"4216055039","pt":1631547512179,"mc":[{"id":"1.187607461","rc":[{"batb":[[0,1.01,7],[1,1.01,0]],"ltp":0.0,"tv":0.0,"id":16100628},{"batb":[[0,1.67,415.84],[1,1.01,7],[2,1.01,0]],"ltp":0.0,"tv":0.0,"id":14036296}]}]}
{"op":"mcm","clk":"4216055446","pt":1631547517155,"mc":[{"id":"1.187607461","rc":[{"batb":[[0,1.78,38.46],[1,1.01,7]],"ltp":0.0,"tv":0.0,"id":16100628},{"batb":[[0,1.98,30.61],[1,1.67,415.84],[2,1.01,7]],"ltp":0.0,"tv":0.0,"id":14036296}]}]}
{"op":"mcm","clk":"4216057519","pt":1631547543192,"mc":[{"id":"1.187607461","rc":[{"batb":[[0,1.01,7],[1,1.01,0]],"ltp":0.0,"tv":0.0,"id":16100628},{"batb":[[0,1.67,415.84],[1,1.01,7],[2,1.01,0]],"ltp":0.0,"tv":0.0,"id":14036296}]}]}
{"op":"mcm","clk":"4216057984","pt":1631547548215,"mc":[{"id":"1.187607461","rc":[{"batb":[[0,1.85,35.29],[1,1.01,7]],"ltp":0.0,"tv":0.0,"id":16100628},{"batb":[[0,1.88,34.09],[1,1.67,415.84],[2,1.01,7]],"ltp":0.0,"tv":0.0,"id":14036296}]}]}
{"op":"mcm","clk":"4216059017","pt":1631547560676,"mc":[{"id":"1.187607461","rc":[{"batb":[[1,1.01,7],[2,1.01,0]],"ltp":0.0,"tv":0.0,"id":14036296}]}]}
{"op":"mcm","clk":"4216059590","pt":1631547567190,"mc":[{"id":"1.187607461","rc":[{"batb":[[0,1.01,7],[1,1.01,0]],"ltp":0.0,"tv":0.0,"id":16100628},{"batb":[[0,1.01,7],[1,1.01,0]],"ltp":0.0,"tv":0.0,"id":14036296}]}]}
{"op":"mcm","clk":"4216060398","pt":1631547577092,"mc":[{"id":"1.187607461","rc":[{"batb":[[0,1.85,35.29],[1,1.01,7]],"ltp":0.0,"tv":0.0,"id":16100628},{"batb":[[0,1.88,34.09],[1,1.01,7]],"ltp":0.0,"tv":0.0,"id":14036296}]}]}
{"op":"mcm","clk":"4216060974","pt":1631547584182,"mc":[{"id":"1.187607461","rc":[{"batb":[[0,1.01,7],[1,1.01,0]],"ltp":0.0,"tv":0.0,"id":16100628},{"batb":[[0,1.01,7],[1,1.01,0]],"ltp":0.0,"tv":0.0,"id":14036296}]}]}
{"op":"mcm","clk":"4216061505","pt":1631547589821,"mc":[{"id":"1.187607461","rc":[{"batb":[[0,1.73,41.09],[1,1.01,7]],"ltp":0.0,"tv":0.0,"id":16100628},{"batb":[[0,2,30],[1,1.67,415.84],[2,1.01,7]],"ltp":0.0,"tv":0.0,"id":14036296}]}]}
{"op":"mcm","clk":"4216064250","pt":1631547622733,"mc":[{"id":"1.187607461","rc":[{"batb":[[0,1.01,7],[1,1.01,0]],"ltp":0.0,"tv":0.0,"id":16100628},{"batb":[[0,1.67,415.84],[1,1.01,7],[2,1.01,0]],"ltp":0.0,"tv":0.0,"id":14036296}]}]}
{"op":"mcm","clk":"4216064615","pt":1631547627629,"mc":[{"id":"1.187607461","rc":[{"batb":[[0,1.85,35.29],[1,1.01,7]],"ltp":0.0,"tv":0.0,"id":16100628},{"batb":[[0,1.88,34.09],[1,1.67,415.84],[2,1.01,7]],"ltp":0.0,"tv":0.0,"id":14036296}]}]}
{"op":"mcm","clk":"4216066840","pt":1631547655530,"mc":[{"id":"1.187607461","rc":[{"batb":[[0,1.01,7],[1,1.01,0]],"ltp":0.0,"tv":0.0,"id":16100628},{"batb":[[0,1.67,415.84],[1,1.01,7],[2,1.01,0]],"ltp":0.0,"tv":0.0,"id":14036296}]}]}
{"op":"mcm","clk":"4216067500","pt":1631547660130,"mc":[{"id":"1.187607461","rc":[{"batb":[[0,1.73,41.09],[1,1.01,7]],"ltp":0.0,"tv":0.0,"id":16100628},{"batb":[[0,2,30],[1,1.67,415.84],[2,1.01,7]],"ltp":0.0,"tv":0.0,"id":14036296}]}]}
{"op":"mcm","clk":"4216068584","pt":1631547671530,"mc":[{"id":"1.187607461","rc":[{"trd":[[1.73,31.76]],"batb":[[0,1.01,7],[1,1.01,0]],"ltp":1.73,"tv":31.76,"id":16100628}],"tv":31.76}]}
{"op":"mcm","clk":"4216069011","pt":1631547676531,"mc":[{"id":"1.187607461","rc":[{"batb":[[0,1.73,41.09],[1,1.01,7]],"ltp":1.73,"tv":31.76,"id":16100628}]}]}
{"op":"mcm","clk":"4216070887","pt":1631547687249,"mc":[{"id":"1.187607461","rc":[{"batb":[[0,1.01,7],[1,1.01,0]],"ltp":1.73,"tv":31.76,"id":16100628},{"batb":[[0,1.67,415.84],[1,1.01,7],[2,1.01,0]],"ltp":0.0,"tv":0.0,"id":14036296}]}]}
{"op":"mcm","clk":"4216071268","pt":1631547692129,"mc":[{"id":"1.187607461","rc":[{"batb":[[0,1.85,35.29],[1,1.01,7]],"ltp":1.73,"tv":31.76,"id":16100628},{"batb":[[0,1.88,34.09],[1,1.67,415.84],[2,1.01,7]],"ltp":0.0,"tv":0.0,"id":14036296}]}]}
{"op":"mcm","clk":"4216072757","pt":1631547712896,"mc":[{"id":"1.187607461","rc":[{"trd":[[1.85,14.44]],"batb":[[0,1.01,7],[1,1.01,0]],"ltp":1.85,"tv":46.2,"id":16100628}],"tv":46.2}]}
{"op":"mcm","clk":"4216072878","pt":1631547714554,"mc":[{"id":"1.187607461","rc":[{"batb":[[0,1.67,415.84],[1,1.01,7],[2,1.01,0]],"ltp":0.0,"tv":0.0,"id":14036296}]}]}
{"op":"mcm","clk":"4216073104","pt":1631547717776,"mc":[{"id":"1.187607461","rc":[{"batb":[[0,1.85,35.29],[1,1.01,7]],"ltp":1.85,"tv":46.2,"id":16100628}]}]}
{"op":"mcm","clk":"4216073116","pt":1631547717984,"mc":[{"id":"1.187607461","rc":[{"batb":[[0,1.01,7],[1,1.01,0]],"ltp":1.85,"tv":46.2,"id":16100628}]}]}
{"op":"mcm","clk":"4216073209","pt":1631547719496,"mc":[{"id":"1.187607461","rc":[{"batb":[[0,1.78,38.46],[1,1.67,415.84],[2,1.01,7]],"ltp":0.0,"tv":0.0,"id":14036296}]}]}
{"op":"mcm","clk":"4216073473","pt":1631547722983,"mc":[{"id":"1.187607461","rc":[{"batb":[[0,1.98,30.61],[1,1.01,7]],"ltp":1.85,"tv":46.2,"id":16100628}]}]}
{"op":"mcm","clk":"4216076834","pt":1631547772673,"mc":[{"id":"1.187607461","rc":[{"batl":[[0,2.24,24.21],[1,2.84,106.47]],"ltp":1.85,"tv":46.2,"id":16100628}]}]}
{"op":"mcm","clk":"4216079399","pt":1631547808006,"mc":[{"id":"1.187607461","rc":[{"batb":[[1,1.01,7],[2,1.01,0]],"ltp":0.0,"tv":0.0,"id":14036296}]}]}
{"op":"mcm","clk":"4216080172","pt":1631547820217,"mc":[{"id":"1.187607461","rc":[{"batb":[[0,1.01,7],[1,1.01,0]],"ltp":1.85,"tv":46.2,"id":16100628},{"batb":[[0,1.01,7],[1,1.01,0]],"ltp":0.0,"tv":0.0,"id":14036296}]}]}
{"op":"mcm","clk":"4216080504","pt":1631547825003,"mc":[{"id":"1.187607461","rc":[{"batb":[[0,2.06,28.3],[1,1.01,7]],"ltp":1.85,"tv":46.2,"id":16100628},{"batb":[[0,1.65,46.15],[1,1.01,7]],"ltp":0.0,"tv":0.0,"id":14036296}]}]}
{"op":"mcm","clk":"4216080716","pt":1631547828247,"mc":[{"id":"1.187607461","rc":[{"batl":[[0,2.84,106.47],[1,2.84,0]],"ltp":1.85,"tv":46.2,"id":16100628}]}]}
{"op":"mcm","clk":"4216081288","pt":1631547838150,"mc":[{"id":"1.187607461","rc":[{"batl":[[0,1.9,24.21]],"ltp":0.0,"tv":0.0,"id":14036296}]}]}
{"op":"mcm","clk":"4216081702","pt":1631547844535,"mc":[{"id":"1.187607461","rc":[{"batb":[[0,1.01,7],[1,1.01,0]],"ltp":1.85,"tv":46.2,"id":16100628}]}]}
{"op":"mcm","clk":"4216081917","pt":1631547847869,"mc":[{"id":"1.187607461","rc":[{"batb":[[0,1.66,30],[1,1.65,46.15],[2,1.01,7]],"ltp":0.0,"tv":0.0,"id":14036296}]}]}
{"op":"mcm","clk":"4216082060","pt":1631547849455,"mc":[{"id":"1.187607461","rc":[{"batb":[[0,2.1,27.27],[1,1.01,7]],"ltp":1.85,"tv":46.2,"id":16100628}]}]}
{"op":"mcm","clk":"4216083170","pt":1631547858469,"mc":[{"id":"1.187607461","rc":[{"batb":[[0,1.01,7],[1,1.01,0]],"ltp":1.85,"tv":46.2,"id":16100628},{"batb":[[1,1.01,7],[2,1.01,0]],"ltp":0.0,"tv":0.0,"id":14036296}]}]}
{"op":"mcm","clk":"4216083648","pt":1631547863352,"mc":[{"id":"1.187607461","rc":[{"batb":[[0,1.88,34.09],[1,1.01,7]],"ltp":1.85,"tv":46.2,"id":16100628},{"batb":[[0,1.85,35.29],[1,1.66,30],[2,1.01,7]],"ltp":0.0,"tv":0.0,"id":14036296}]}]}
{"op":"mcm","clk":"4216083777","pt":1631547864857,"mc":[{"id":"1.187607461","rc":[{"batb":[[2,1.58,422.65]],"ltp":0.0,"tv":0.0,"id":14036296}]}]}
{"op":"mcm","clk":"4216085752","pt":1631547884502,"mc":[{"id":"1.187607461","rc":[{"batb":[[0,1.01,7],[1,1.01,0]],"ltp":1.85,"tv":46.2,"id":16100628},{"batb":[[0,1.66,30],[1,1.58,422.65],[2,1.01,7]],"ltp":0.0,"tv":0.0,"id":14036296}]}]}
{"op":"mcm","clk":"4216085894","pt":1631547886130,"mc":[{"id":"1.187607461","rc":[{"batb":[[1,1.01,7],[2,1.01,0]],"ltp":0.0,"tv":0.0,"id":14036296}]}]}
{"op":"mcm","clk":"4216086152","pt":1631547889426,"mc":[{"id":"1.187607461","rc":[{"batb":[[0,1.85,35.29],[1,1.01,7]],"ltp":1.85,"tv":46.2,"id":16100628},{"batb":[[0,1.88,34.09],[1,1.66,30],[2,1.01,7]],"ltp":0.0,"tv":0.0,"id":14036296}]}]}
{"op":"mcm","clk":"4216086408","pt":1631547892244,"mc":[{"id":"1.187607461","rc":[{"batb":[[2,1.62,421.6]],"ltp":0.0,"tv":0.0,"id":14036296}]}]}
{"op":"mcm","clk":"4216087791","pt":1631547906533,"mc":[{"id":"1.187607461","rc":[{"batb":[[1,1.62,421.6],[2,1.01,7]],"ltp":0.0,"tv":0.0,"id":14036296}]}]}
{"op":"mcm","clk":"4216089099","pt":1631547920299,"mc":[{"id":"1.187607461","rc":[{"batl":[[0,2.1,24.21],[1,2.84,106.47]],"ltp":1.85,"tv":46.2,"id":16100628}]}]}
{"op":"mcm","clk":"4216089681","pt":1631547925490,"mc":[{"id":"1.187607461","rc":[{"batb":[[0,1.01,7],[1,1.01,0]],"ltp":1.85,"tv":46.2,"id":16100628},{"batb":[[0,1.62,421.6],[1,1.01,7],[2,1.01,0]],"ltp":0.0,"tv":0.0,"id":14036296}]}]}
{"op":"mcm","clk":"4216089810","pt":1631547926704,"mc":[{"id":"1.187607461","rc":[{"batb":[[0,1.01,7],[1,1.01,0]],"ltp":0.0,"tv":0.0,"id":14036296}]}]}
{"op":"mcm","clk":"4216090094","pt":1631547929154,"mc":[{"id":"1.187607461","rc":[{"batb":[[0,1.9,24.21],[1,1.01,7]],"ltp":1.85,"tv":46.2,"id":16100628}]}]}
{"op":"mcm","clk":"4216090211","pt":1631547930477,"mc":[{"id":"1.187607461","rc":[{"batb":[[0,1.71,42.25]],"ltp":1.85,"tv":46.2,"id":16100628},{"batb":[[0,2.06,28.3],[1,1.01,7]],"ltp":0.0,"tv":0.0,"id":14036296}]}]}
{"op":"mcm","clk":"4216090433","pt":1631547932489,"mc":[{"id":"1.187607461","rc":[{"batb":[[1,1.67,415.84],[2,1.01,7]],"ltp":0.0,"tv":0.0,"id":14036296}]}]}
{"op":"mcm","clk":"4216091244","pt":1631547940500,"mc":[{"id":"1.187607461","rc":[{"batb":[[0,1.8,24.21],[1,1.71,42.25],[2,1.01,7]],"ltp":1.85,"tv":46.2,"id":16100628}]}]}
{"op":"mcm","clk":"4216091449","pt":1631547942784,"mc":[{"id":"1.187607461","rc":[{"batl":[[0,2.84,106.47],[1,2.84,0]],"ltp":1.85,"tv":46.2,"id":16100628}]}]}
{"op":"mcm","clk":"4216093478","pt":1631547963205,"mc":[{"id":"1.187607461","rc":[{"batb":[[0,1.71,42.25],[1,1.01,7],[2,1.01,0]],"ltp":1.85,"tv":46.2,"id":16100628}]}]}
{"op":"mcm","clk":"4216094349","pt":1631547971539,"mc":[{"id":"1.187607461","rc":[{"batb":[[0,1.01,7],[1,1.01,0]],"ltp":1.85,"tv":46.2,"id":16100628},{"batb":[[0,1.67,415.84],[1,1.01,7],[2,1.01,0]],"ltp":0.0,"tv":0.0,"id":14036296}]}]}
{"op":"mcm","clk":"4216094842","pt":1631547976450,"mc":[{"id":"1.187607461","rc":[{"batb":[[0,1.85,35.29],[1,1.01,7]],"ltp":1.85,"tv":46.2,"id":16100628},{"batb":[[0,1.88,34.09],[1,1.67,415.84],[2,1.01,7]],"ltp":0.0,"tv":0.0,"id":14036296}]}]}
{"op":"mcm","clk":"4216094979","pt":1631547977969,"mc":[{"id":"1.187607461","rc":[{"batl":[[0,2.06,24.21]],"ltp":0.0,"tv":0.0,"id":14036296}]}]}
{"op":"mcm","clk":"4216095763","pt":1631547985188,"mc":[{"id":"1.187607461","rc":[{"batl":[[0,2.1,24.21]],"ltp":0.0,"tv":0.0,"id":14036296}]}]}
{"op":"mcm","clk":"4216096916","pt":1631547995972,"mc":[{"id":"1.187607461","rc":[{"batb":[[1,1.01,7],[2,1.01,0]],"ltp":0.0,"tv":0.0,"id":14036296}]}]}
{"op":"mcm","clk":"4216097615","pt":1631548003386,"mc":[{"id":"1.187607461","rc":[{"batb":[[0,1.01,7],[1,1.01,0]],"ltp":1.85,"tv":46.2,"id":16100628},{"batb":[[0,1.01,7],[1,1.01,0]],"ltp":0.0,"tv":0.0,"id":14036296}]}]}
{"op":"mcm","clk":"4216098055","pt":1631548008278,"mc":[{"id":"1.187607461","rc":[{"batb":[[0,1.65,46.15],[1,1.01,7]],"ltp":1.85,"tv":46.2,"id":16100628}]}]}
{"op":"mcm","clk":"4216098141","pt":1631548009381,"mc":[{"id":"1.187607461","rc":[{"batb":[[0,2.1,27.27],[1,1.01,7]],"ltp":0.0,"tv":0.0,"id":14036296}]}]}
{"op":"mcm","clk":"4216098623","pt":1631548014793,"mc":[{"id":"1.187607461","rc":[{"batl":[[0,2,24.21],[1,2.84,106.47]],"ltp":1.85,"tv":46.2,"id":16100628}]}]}
{"op":"mcm","clk":"4216099013","pt":1631548018910,"mc":[{"id":"1.187607461","rc":[{"batl":[[0,2.32,24.21]],"ltp":0.0,"tv":0.0,"id":14036296}]}]}
{"op":"mcm","clk":"4216100503","pt":1631548036228,"mc":[{"id":"1.187607461","rc":[{"batb":[[0,1.01,7],[1,1.01,0]],"ltp":1.85,"tv":46.2,"id":16100628},{"batb":[[0,1.01,7],[1,1.01,0]],"ltp":0.0,"tv":0.0,"id":14036296}]}]}
{"op":"mcm","clk":"4216100973","pt":1631548041155,"mc":[{"id":"1.187607461","rc":[{"batb":[[0,1.78,38.46],[1,1.01,7]],"ltp":1.85,"tv":46.2,"id":16100628},{"batb":[[0,1.98,30.61],[1,1.01,7]],"ltp":0.0,"tv":0.0,"id":14036296}]}]}
{"op":"mcm","clk":"4216101667","pt":1631548048156,"mc":[{"id":"1.187607461","rc":[{"batl":[[0,2.84,106.47],[1,2.84,0]],"ltp":1.85,"tv":46.2,"id":16100628}]}]}
{"op":"mcm","clk":"4216101866","pt":1631548050458,"mc":[{"id":"1.187607461","rc":[{"batb":[[0,1.01,7],[1,1.01,0]],"ltp":1.85,"tv":46.2,"id":16100628},{"batb":[[0,1.01,7],[1,1.01,0]],"ltp":0.0,"tv":0.0,"id":14036296}]}]}
{"op":"mcm","clk":"4216102264","pt":1631548055359,"mc":[{"id":"1.187607461","rc":[{"batb":[[0,1.85,35.29],[1,1.01,7]],"ltp":1.85,"tv":46.2,"id":16100628},{"batb":[[0,1.88,34.09],[1,1.01,7]],"ltp":0.0,"tv":0.0,"id":14036296}]}]}
{"op":"mcm","clk":"4216104475","pt":1631548081100,"mc":[{"id":"1.187607461","rc":[{"batb":[[0,1.01,7],[1,1.01,0]],"ltp":1.85,"tv":46.2,"id":16100628},{"batb":[[0,1.01,7],[1,1.01,0]],"ltp":0.0,"tv":0.0,"id":14036296}]}]}
{"op":"mcm","clk":"4216104916","pt":1631548086110,"mc":[{"id":"1.187607461","rc":[{"batb":[[0,1.73,41.09],[1,1.01,7]],"ltp":1.85,"tv":46.2,"id":16100628},{"batb":[[0,2,30],[1,1.01,7]],"ltp":0.0,"tv":0.0,"id":14036296}]}]}
{"op":"mcm","clk":"4216108266","pt":1631548123642,"mc":[{"id":"1.187607461","rc":[{"batb":[[0,1.01,7],[1,1.01,0]],"ltp":1.85,"tv":46.2,"id":16100628},{"batb":[[0,1.01,7],[1,1.01,0]],"ltp":0.0,"tv":0.0,"id":14036296}]}]}
{"op":"mcm","clk":"4216108626","pt":1631548128523,"mc":[{"id":"1.187607461","rc":[{"batb":[[0,1.65,46.15],[1,1.01,7]],"ltp":1.85,"tv":46.2,"id":16100628},{"batb":[[0,2.1,27.27],[1,1.01,7]],"ltp":0.0,"tv":0.0,"id":14036296}]}]}
{"op":"mcm","clk":"4216108826","pt":1631548131127,"mc":[{"id":"1.187607461","rc":[{"batb":[[1,1.74,410.28],[2,1.01,7]],"ltp":0.0,"tv":0.0,"id":14036296}]}]}
{"op":"mcm","clk":"4216109837","pt":1631548142259,"mc":[{"id":"1.187607461","rc":[{"batb":[[0,1.74,410.28],[1,1.01,7],[2,1.01,0]],"ltp":0.0,"tv":0.0,"id":14036296}]}]}
{"op":"mcm","clk":"4216110250","pt":1631548147250,"mc":[{"id":"1.187607461","rc":[{"batb":[[0,2.16,25.86],[1,1.74,410.28],[2,1.01,7]],"ltp":0.0,"tv":0.0,"id":14036296}]}]}
{"op":"mcm","clk":"4216110652","pt":1631548151561,"mc":[{"id":"1.187607461","rc":[{"trd":[[1.65,17.06]],"batb":[[0,1.01,7],[1,1.01,0]],"ltp":1.65,"tv":63.25,"id":16100628}],"tv":63.25}]}
{"op":"mcm","clk":"4216111085","pt":1631548155874,"mc":[{"id":"1.187607461","rc":[{"batb":[[0,1.74,410.28],[1,1.01,7],[2,1.01,0]],"ltp":0.0,"tv":0.0,"id":14036296}]}]}
{"op":"mcm","clk":"4216111603","pt":1631548160869,"mc":[{"id":"1.187607461","rc":[{"batb":[[0,1.98,30.61],[1,1.74,410.28],[2,1.01,7]],"ltp":0.0,"tv":0.0,"id":14036296}]}]}
{"op":"mcm","clk":"4216111687","pt":1631548161656,"mc":[{"id":"1.187607461","rc":[{"batb":[[0,1.78,38.46],[1,1.01,7]],"ltp":1.65,"tv":63.25,"id":16100628}]}]}
{"op":"mcm","clk":"4216113410","pt":1631548182032,"mc":[{"id":"1.187607461","rc":[{"batb":[[0,1.01,7],[1,1.01,0]],"ltp":1.65,"tv":63.25,"id":16100628},{"batb":[[0,1.74,410.28],[1,1.01,7],[2,1.01,0]],"ltp":0.0,"tv":0.0,"id":14036296}]}]}
{"op":"mcm","clk":"4216113919","pt":1631548187039,"mc":[{"id":"1.187607461","rc":[{"batb":[[0,1.63,47.61],[1,1.01,7]],"ltp":1.65,"tv":63.25,"id":16100628},{"batb":[[0,2.16,25.86],[1,1.74,410.28],[2,1.01,7]],"ltp":0.0,"tv":0.0,"id":14036296}]}]}
{"op":"mcm","clk":"4216116044","pt":1631548208473,"mc":[{"id":"1.187607461","rc":[{"batb":[[0,1.01,7],[1,1.01,0]],"ltp":1.65,"tv":63.25,"id":16100628},{"batb":[[0,1.01,7],[1,1.74,0],[2,1.01,0]],"ltp":0.0,"tv":0.0,"id":14036296}]}]}
{"op":"mcm","clk":"4216116553","pt":1631548213474,"mc":[{"id":"1.187607461","rc":[{"batb":[[0,1.51,58.82],[1,1.01,7]],"ltp":1.65,"tv":63.25,"id":16100628},{"batb":[[0,2.42,21.12],[1,1.01,7]],"ltp":0.0,"tv":0.0,"id":14036296}]}]}
{"op":"mcm","clk":"4216116631","pt":1631548214274,"mc":[{"id":"1.187607461","rc":[{"batb":[[1,1.82,407.19],[2,1.01,7]],"ltp":0.0,"tv":0.0,"id":14036296}]}]}
{"op":"mcm","clk":"4216118028","pt":1631548228130,"mc":[{"id":"1.187607461","rc":[{"batb":[[0,1.01,7],[1,1.01,0]],"ltp":1.65,"tv":63.25,"id":16100628},{"batb":[[0,1.82,407.19],[1,1.01,7],[2,1.01,0]],"ltp":0.0,"tv":0.0,"id":14036296}]}]}
{"op":"mcm","clk":"4216118533","pt":1631548233011,"mc":[{"id":"1.187607461","rc":[{"batb":[[0,1.63,47.61],[1,1.01,7]],"ltp":1.65,"tv":63.25,"id":16100628},{"batb":[[0,2.16,25.86],[1,1.82,407.19],[2,1.01,7]],"ltp":0.0,"tv":0.0,"id":14036296}]}]}
{"op":"mcm","clk":"4216119518","pt":1631548243556,"mc":[{"id":"1.187607461","rc":[{"batb":[[0,1.01,7],[1,1.01,0]],"ltp":1.65,"tv":63.25,"id":16100628},{"batb":[[0,1.82,407.19],[1,1.01,7],[2,1.01,0]],"ltp":0.0,"tv":0.0,"id":14036296}]}]}
{"op":"mcm","clk":"4216120017","pt":1631548248495,"mc":[{"id":"1.187607461","rc":[{"batb":[[0,1.6,49.99],[1,1.01,7]],"ltp":1.65,"tv":63.25,"id":16100628},{"batb":[[0,2.2,24.99],[1,1.82,407.19],[2,1.01,7]],"ltp":0.0,"tv":0.0,"id":14036296}]}]}
{"op":"mcm","clk":"4216120722","pt":1631548255496,"mc":[{"id":"1.187607461","rc":[{"batb":[[0,1.01,7],[1,1.01,0]],"ltp":1.65,"tv":63.25,"id":16100628},{"batb":[[0,1.82,407.19],[1,1.01,7],[2,1.01,0]],"ltp":0.0,"tv":0.0,"id":14036296}]}]}
{"op":"mcm","clk":"4216121175","pt":1631548260376,"mc":[{"id":"1.187607461","rc":[{"batb":[[0,1.51,58.82],[1,1.01,7]],"ltp":1.65,"tv":63.25,"id":16100628},{"batb":[[0,2.42,21.12],[1,1.82,407.19],[2,1.01,7]],"ltp":0.0,"tv":0.0,"id":14036296}]}]}
{"op":"mcm","clk":"4216121545","pt":1631548264421,"mc":[{"id":"1.187607461","rc":[{"batb":[[0,1.61,160.61],[1,1.51,58.82],[2,1.01,7]],"ltp":1.65,"tv":63.25,"id":16100628}]}]}
{"op":"mcm","clk":"4216122509","pt":1631548275315,"mc":[{"id":"1.187607461","rc":[{"batb":[[1,1.01,7],[2,1.01,0]],"ltp":1.65,"tv":63.25,"id":16100628},{"batb":[[0,1.82,407.19],[1,1.01,7],[2,1.01,0]],"ltp":0.0,"tv":0.0,"id":14036296}]}]}
{"op":"mcm","clk":"4216122929","pt":1631548280322,"mc":[{"id":"1.187607461","rc":[{"batb":[[0,1.63,47.61],[1,1.61,160.61],[2,1.01,7]],"ltp":1.65,"tv":63.25,"id":16100628},{"batb":[[0,2.16,25.86],[1,1.82,407.19],[2,1.01,7]],"ltp":0.0,"tv":0.0,"id":14036296}]}]}
{"op":"mcm","clk":"4216123446","pt":1631548285725,"mc":[{"id":"1.187607461","rc":[{"batb":[[1,1.01,7],[2,1.01,0]],"ltp":1.65,"tv":63.25,"id":16100628}]}]}
{"op":"mcm","clk":"4216124003","pt":1631548291640,"mc":[{"id":"1.187607461","rc":[{"batb":[[0,1.7,160.61],[1,1.63,47.61],[2,1.01,7]],"ltp":1.65,"tv":63.25,"id":16100628}]}]}
{"op":"mcm","clk":"4216124627","pt":1631548298662,"mc":[{"id":"1.187607461","rc":[{"batb":[[1,1.01,7],[2,1.01,0]],"ltp":1.65,"tv":63.25,"id":16100628},{"batb":[[0,1.82,407.19],[1,1.01,7],[2,1.01,0]],"ltp":0.0,"tv":0.0,"id":14036296}]}]}
{"op":"mcm","clk":"4216124696","pt":1631548299359,"mc":[{"id":"1.187607461","rc":[{"batb":[[0,1.01,7],[1,1.01,0]],"ltp":0.0,"tv":0.0,"id":14036296}]}]}
{"op":"mcm","clk":"4216125069","pt":1631548303549,"mc":[{"id":"1.187607461","rc":[{"batb":[[0,1.71,42.25],[1,1.7,160.61],[2,1.01,7]],"ltp":1.65,"tv":63.25,"id":16100628},{"batb":[[0,2.06,28.3],[1,1.01,7]],"ltp":0.0,"tv":0.0,"id":14036296}]}]}
{"op":"mcm","clk":"4216125255","pt":1631548305367,"mc":[{"id":"1.187607461","rc":[{"batb":[[1,1.67,415.84],[2,1.01,7]],"ltp":0.0,"tv":0.0,"id":14036296}]}]}
{"op":"mcm","clk":"4216125426","pt":1631548306768,"mc":[{"id":"1.187607461","rc":[{"batb":[[1,1.01,7],[2,1.01,0]],"ltp":1.65,"tv":63.25,"id":16100628}]}]}
{"op":"mcm","clk":"4216126152","pt":1631548316264,"mc":[{"id":"1.187607461","rc":[{"batb":[[0,1.01,7],[1,1.01,0]],"ltp":1.65,"tv":63.25,"id":16100628},{"batb":[[0,1.67,415.84],[1,1.01,7],[2,1.01,0]],"ltp":0.0,"tv":0.0,"id":14036296}]}]}
{"op":"mcm","clk":"4216126287","pt":1631548317570,"mc":[{"id":"1.187607461","rc":[{"batb":[[0,1.01,7],[1,1.01,0]],"ltp":0.0,"tv":0.0,"id":14036296}]}]}
{"op":"mcm","clk":"4216126605","pt":1631548321163,"mc":[{"id":"1.187607461","rc":[{"batb":[[0,1.6,49.99],[1,1.01,7]],"ltp":1.65,"tv":63.25,"id":16100628},{"batb":[[0,2.2,24.99],[1,1.01,7]],"ltp":0.0,"tv":0.0,"id":14036296}]}]}
{"op":"mcm","clk":"4216126820","pt":1631548323497,"mc":[{"id":"1.187607461","rc":[{"batb":[[1,1.74,410.28],[2,1.01,7]],"ltp":0.0,"tv":0.0,"id":14036296}]}]}
{"op":"mcm","clk":"4216127711","pt":1631548333910,"mc":[{"id":"1.187607461","rc":[{"batb":[[0,1.01,7],[1,1.01,0]],"ltp":1.65,"tv":63.25,"id":16100628},{"batb":[[0,1.74,410.28],[1,1.01,7],[2,1.01,0]],"ltp":0.0,"tv":0.0,"id":14036296}]}]}
{"op":"mcm","clk":"4216128187","pt":1631548338810,"mc":[{"id":"1.187607461","rc":[{"batb":[[0,1.58,51.72],[1,1.01,7]],"ltp":1.65,"tv":63.25,"id":16100628},{"batb":[[0,2.26,23.8],[1,1.74,410.28],[2,1.01,7]],"ltp":0.0,"tv":0.0,"id":14036296}]}]}
{"op":"mcm","clk":"4216128930","pt":1631548346401,"mc":[{"id":"1.187607461","rc":[{"batb":[[0,1.01,7],[1,1.01,0]],"ltp":1.65,"tv":63.25,"id":16100628},{"batb":[[0,1.01,7],[1,1.74,0],[2,1.01,0]],"ltp":0.0,"tv":0.0,"id":14036296}]}]}
{"op":"mcm","clk":"4216129461","pt":1631548351728,"mc":[{"id":"1.187607461","rc":[{"batb":[[0,1.51,58.82],[1,1.01,7]],"ltp":1.65,"tv":63.25,"id":16100628},{"batb":[[0,2.42,21.12],[1,1.86,404.54],[2,1.01,7]],"ltp":0.0,"tv":0.0,"id":14036296}]}]}
{"op":"mcm","clk":"4216130829","pt":1631548365722,"mc":[{"id":"1.187607461","rc":[{"batb":[[0,1.01,7],[1,1.01,0]],"ltp":1.65,"tv":63.25,"id":16100628},{"batb":[[0,1.86,404.54],[1,1.01,7],[2,1.01,0]],"ltp":0.0,"tv":0.0,"id":14036296}]}]}
{"op":"mcm","clk":"4216131290","pt":1631548370721,"mc":[{"id":"1.187607461","rc":[{"batb":[[0,1.48,62.5],[1,1.01,7]],"ltp":1.65,"tv":63.25,"id":16100628},{"batb":[[0,2.5,20],[1,1.86,404.54],[2,1.01,7]],"ltp":0.0,"tv":0.0,"id":14036296}]}]}
{"op":"mcm","clk":"4216132250","pt":1631548381544,"mc":[{"id":"1.187607461","rc":[{"batb":[[0,1.01,7],[1,1.01,0]],"ltp":1.65,"tv":63.25,"id":16100628},{"batb":[[0,1.01,7],[1,1.86,0],[2,1.01,0]],"ltp":0.0,"tv":0.0,"id":14036296}]}]}
{"op":"mcm","clk":"4216132472","pt":1631548383850,"mc":[{"id":"1.187607461","rc":[{"batl":[[0,1.48,50],[1,2.84,106.47]],"ltp":1.65,"tv":63.25,"id":16100628}]}]}
{"op":"mcm","clk":"4216133535","pt":1631548395149,"mc":[{"id":"1.187607461","rc":[{"batl":[[0,2.84,106.47],[1,2.84,0]],"ltp":1.65,"tv":63.25,"id":16100628}]}]}
{"op":"mcm","clk":"4216133651","pt":1631548396450,"mc":[{"id":"1.187607461","rc":[{"batb":[[0,2.2,24.99],[1,1.74,410.28],[2,1.01,7]],"ltp":0.0,"tv":0.0,"id":14036296}]}]}
{"op":"mcm","clk":"4216133882","pt":1631548398778,"mc":[{"id":"1.187607461","rc":[{"batb":[[0,1.48,11.35],[1,1.01,7]],"ltp":1.65,"tv":63.25,"id":16100628}]}]}
{"op":"mcm","clk":"4216133918","pt":1631548399191,"mc":[{"id":"1.187607461","rc":[{"batb":[[0,1.01,7],[1,1.01,0]],"ltp":1.65,"tv":63.25,"id":16100628}]}]}
{"op":"mcm","clk":"4216134100","pt":1631548400857,"mc":[{"id":"1.187607461","rc":[{"batb":[[0,1.6,49.99],[1,1.48,11.35],[2,1.01,7]],"ltp":1.65,"tv":63.25,"id":16100628}]}]}
{"op":"mcm","clk":"4216134140","pt":1631548401268,"mc":[{"id":"1.187607461","rc":[{"batb":[[1,1.01,7],[2,1.01,0]],"ltp":1.65,"tv":63.25,"id":16100628}]}]}
{"op":"mcm","clk":"4216134288","pt":1631548402883,"mc":[{"id":"1.187607461","rc":[{"batb":[[0,1.01,7],[1,1.01,0]],"ltp":1.65,"tv":63.25,"id":16100628},{"batb":[[0,1.74,410.28],[1,1.01,7],[2,1.01,0]],"ltp":0.0,"tv":0.0,"id":14036296}]}]}
{"op":"mcm","clk":"4216134761","pt":1631548407884,"mc":[{"id":"1.187607461","rc":[{"batb":[[0,1.71,42.25],[1,1.01,7]],"ltp":1.65,"tv":63.25,"id":16100628},{"batb":[[0,2.06,28.3],[1,1.74,410.28],[2,1.01,7]],"ltp":0.0,"tv":0.0,"id":14036296}]}]}
{"op":"mcm","clk":"4216137951","pt":1631548443637,"mc":[{"id":"1.187607461","rc":[{"batb":[[0,1.01,7],[1,1.01,0]],"ltp":1.65,"tv":63.25,"id":16100628},{"batb":[[0,1.74,410.28],[1,1.01,7],[2,1.01,0]],"ltp":0.0,"tv":0.0,"id":14036296}]}]}
{"op":"mcm","clk":"4216138004","pt":1631548444417,"mc":[{"id":"1.187607461","rc":[{"batb":[[0,1.01,7],[1,1.01,0]],"ltp":0.0,"tv":0.0,"id":14036296}]}]}
{"op":"mcm","clk":"4216138388","pt":1631548448644,"mc":[{"id":"1.187607461","rc":[{"batb":[[0,1.78,38.46],[1,1.01,7]],"ltp":1.65,"tv":63.25,"id":16100628},{"batb":[[0,1.98,30.61],[1,1.01,7]],"ltp":0.0,"tv":0.0,"id":14036296}]}]}
{"op":"mcm","clk":"4216138486","pt":1631548449881,"mc":[{"id":"1.187607461","rc":[{"batb":[[1,1.62,421.6],[2,1.01,7]],"ltp":0.0,"tv":0.0,"id":14036296}]}]}
{"op":"mcm","clk":"4216138498","pt":1631548449958,"mc":[{"id":"1.187607461","rc":[{"batl":[[0,2.04,160.61]],"ltp":0.0,"tv":0.0,"id":14036296}]}]}
{"op":"mcm","clk":"4216139235","pt":1631548456936,"mc":[{"id":"1.187607461","rc":[{"batl":[[0,2.1,160.61]],"ltp":0.0,"tv":0.0,"id":14036296}]}]}
{"op":"mcm","clk":"4216147023","pt":1631548543383,"mc":[{"id":"1.187607461","rc":[{"batb":[[0,1.01,7],[1,1.01,0]],"ltp":1.65,"tv":63.25,"id":16100628},{"batb":[[0,1.62,421.6],[1,1.01,7],[2,1.01,0]],"ltp":0.0,"tv":0.0,"id":14036296}]}]}
{"op":"mcm","clk":"4216147496","pt":1631548548349,"mc":[{"id":"1.187607461","rc":[{"batb":[[0,1.85,35.29],[1,1.01,7]],"ltp":1.65,"tv":63.25,"id":16100628},{"batb":[[0,1.88,34.09],[1,1.62,421.6],[2,1.01,7]],"ltp":0.0,"tv":0.0,"id":14036296}]}]}
{"op":"mcm","clk":"4216148159","pt":1631548556493,"mc":[{"id":"1.187607461","rc":[{"batb":[[0,1.01,7],[1,1.01,0]],"ltp":1.65,"tv":63.25,"id":16100628},{"batb":[[0,1.62,421.6],[1,1.01,7],[2,1.01,0]],"ltp":0.0,"tv":0.0,"id":14036296}]}]}
{"op":"mcm","clk":"4216148611","pt":1631548561407,"mc":[{"id":"1.187607461","rc":[{"batb":[[0,1.88,34.09],[1,1.01,7]],"ltp":1.65,"tv":63.25,"id":16100628},{"batb":[[0,1.85,35.29],[1,1.62,421.6],[2,1.01,7]],"ltp":0.0,"tv":0.0,"id":14036296}]}]}
{"op":"mcm","clk":"4216148742","pt":1631548562716,"mc":[{"id":"1.187607461","rc":[{"batb":[[0,1.9,160.61],[1,1.85,35.29],[2,1.62,421.6]],"ltp":0.0,"tv":0.0,"id":14036296}]}]}
{"op":"mcm","clk":"4216148872","pt":1631548564171,"mc":[{"id":"1.187607461","rc":[{"batb":[[0,1.85,35.29],[1,1.62,421.6],[2,1.01,7]],"ltp":0.0,"tv":0.0,"id":14036296}]}]}
{"op":"mcm","clk":"4216149510","pt":1631548571532,"mc":[{"id":"1.187607461","rc":[{"batl":[[0,2,160.61]],"ltp":0.0,"tv":0.0,"id":14036296}]}]}
{"op":"mcm","clk":"4216150658","pt":1631548584152,"mc":[{"id":"1.187607461","rc":[{"batb":[[0,1.01,7],[1,1.01,0]],"ltp":1.65,"tv":63.25,"id":16100628},{"batb":[[0,1.62,421.6],[1,1.01,7],[2,1.01,0]],"ltp":0.0,"tv":0.0,"id":14036296}]}]}
{"op":"mcm","clk":"4216150744","pt":1631548585142,"mc":[{"id":"1.187607461","rc":[{"batb":[[0,1.01,7],[1,1.01,0]],"ltp":0.0,"tv":0.0,"id":14036296}]}]}
{"op":"mcm","clk":"4216151071","pt":1631548589005,"mc":[{"id":"1.187607461","rc":[{"batb":[[0,2.1,27.27],[1,1.01,7]],"ltp":1.65,"tv":63.25,"id":16100628},{"batb":[[0,1.65,46.15],[1,1.01,7]],"ltp":0.0,"tv":0.0,"id":14036296}]}]}
{"op":"mcm","clk":"4216151242","pt":1631548591132,"mc":[{"id":"1.187607461","rc":[{"batb":[[1,1.5,433.24],[2,1.01,7]],"ltp":0.0,"tv":0.0,"id":14036296}]}]}
{"op":"mcm","clk":"4216151615","pt":1631548594948,"mc":[{"id":"1.187607461","rc":[{"batl":[[0,1.9,160.61]],"ltp":0.0,"tv":0.0,"id":14036296}]}]}
{"op":"mcm","clk":"4216152740","pt":1631548607772,"mc":[{"id":"1.187607461","rc":[{"batb":[[0,1.66,160.61],[1,1.65,46.15],[2,1.5,433.24]],"ltp":0.0,"tv":0.0,"id":14036296}]}]}
{"op":"mcm","clk":"4216152916","pt":1631548609597,"mc":[{"id":"1.187607461","rc":[{"batb":[[1,1.5,433.24],[2,1.01,7]],"ltp":0.0,"tv":0.0,"id":14036296}]}]}
{"op":"mcm","clk":"4216153205","pt":1631548613092,"mc":[{"id":"1.187607461","rc":[{"batb":[[0,1.5,433.24],[1,1.01,7],[2,1.01,0]],"ltp":0.0,"tv":0.0,"id":14036296}]}]}
{"op":"mcm","clk":"4216153344","pt":1631548614604,"mc":[{"id":"1.187607461","rc":[{"batb":[[0,1.63,47.61],[1,1.5,433.24],[2,1.01,7]],"ltp":0.0,"tv":0.0,"id":14036296}]}]}
{"op":"mcm","clk":"4216153774","pt":1631548619706,"mc":[{"id":"1.187607461","rc":[{"batb":[[0,1.01,7],[1,1.01,0]],"ltp":1.65,"tv":63.25,"id":16100628},{"batb":[[0,1.5,433.24],[1,1.01,7],[2,1.01,0]],"ltp":0.0,"tv":0.0,"id":14036296}]}]}
{"op":"mcm","clk":"4216153845","pt":1631548620591,"mc":[{"id":"1.187607461","rc":[{"batb":[[0,1.01,7],[1,1.01,0]],"ltp":0.0,"tv":0.0,"id":14036296}]}]}
{"op":"mcm","clk":"4216154178","pt":1631548624713,"mc":[{"id":"1.187607461","rc":[{"batb":[[0,1.98,30.61],[1,1.01,7]],"ltp":1.65,"tv":63.25,"id":16100628},{"batb":[[0,1.78,38.46],[1,1.01,7]],"batl":[[0,1.83,160.61]],"ltp":0.0,"tv":0.0,"id":14036296}]}]}
{"op":"mcm","clk":"4216154305","pt":1631548626319,"mc":[{"id":"1.187607461","rc":[{"batb":[[1,1.55,426.74],[2,1.01,7]],"ltp":0.0,"tv":0.0,"id":14036296}]}]}
{"op":"mcm","clk":"4216154808","pt":1631548632994,"mc":[{"id":"1.187607461","rc":[{"batl":[[0,2,160.61]],"ltp":0.0,"tv":0.0,"id":14036296}]}]}
{"op":"mcm","clk":"4216156558","pt":1631548653236,"mc":[{"id":"1.187607461","rc":[{"batb":[[0,1.01,7],[1,1.01,0]],"ltp":1.65,"tv":63.25,"id":16100628},{"batb":[[0,1.01,7],[1,1.55,0],[2,1.01,0]],"ltp":0.0,"tv":0.0,"id":14036296}]}]}
{"op":"mcm","clk":"4216157065","pt":1631548658556,"mc":[{"id":"1.187607461","rc":[{"batb":[[0,2.16,25.86],[1,1.01,7]],"ltp":1.65,"tv":63.25,"id":16100628},{"batb":[[0,1.63,47.61],[1,1.46,442.16],[2,1.01,7]],"ltp":0.0,"tv":0.0,"id":14036296}]}]}
{"op":"mcm","clk":"4216158701","pt":1631548676424,"mc":[{"id":"1.187607461","rc":[{"batl":[[0,1.83,160.61]],"ltp":0.0,"tv":0.0,"id":14036296}]}]}
{"op":"mcm","clk":"4216159756","pt":1631548688049,"mc":[{"id":"1.187607461","rc":[{"batb":[[0,1.01,7],[1,1.01,0]],"ltp":1.65,"tv":63.25,"id":16100628},{"batb":[[0,1.46,442.16],[1,1.01,7],[2,1.01,0]],"ltp":0.0,"tv":0.0,"id":14036296}]}]}
{"op":"mcm","clk":"4216159891","pt":1631548689466,"mc":[{"id":"1.187607461","rc":[{"batb":[[0,1.01,7],[1,1.01,0]],"ltp":0.0,"tv":0.0,"id":14036296}]}]}
{"op":"mcm","clk":"4216160227","pt":1631548692977,"mc":[{"id":"1.187607461","rc":[{"batb":[[0,2,30],[1,1.01,7]],"ltp":1.65,"tv":63.25,"id":16100628},{"batb":[[0,1.73,41.09],[1,1.01,7]],"ltp":0.0,"tv":0.0,"id":14036296}]}]}
{"op":"mcm","clk":"4216160402","pt":1631548695283,"mc":[{"id":"1.187607461","rc":[{"batb":[[1,1.52,431.8],[2,1.01,7]],"ltp":0.0,"tv":0.0,"id":14036296}]}]}
{"op":"mcm","clk":"4216160653","pt":1631548698570,"mc":[{"id":"1.187607461","rc":[{"batl":[[0,2.08,160.61]],"ltp":0.0,"tv":0.0,"id":14036296}]}]}
{"op":"mcm","clk":"4216161345","pt":1631548706205,"mc":[{"id":"1.187607461","rc":[{"batl":[[0,1.95,160.61]],"ltp":0.0,"tv":0.0,"id":14036296}]}]}
{"op":"mcm","clk":"4216161692","pt":1631548710484,"mc":[{"id":"1.187607461","rc":[{"batb":[[0,1.01,7],[1,1.01,0]],"ltp":1.65,"tv":63.25,"id":16100628},{"batb":[[0,1.52,431.8],[1,1.01,7],[2,1.01,0]],"ltp":0.0,"tv":0.0,"id":14036296}]}]}
{"op":"mcm","clk":"4216162130","pt":1631548715378,"mc":[{"id":"1.187607461","rc":[{"batb":[[0,2.06,28.3],[1,1.01,7]],"ltp":1.65,"tv":63.25,"id":16100628},{"batb":[[0,1.71,42.25],[1,1.52,431.8],[2,1.01,7]],"ltp":0.0,"tv":0.0,"id":14036296}]}]}
{"op":"mcm","clk":"4216162913","pt":1631548724710,"mc":[{"id":"1.187607461","rc":[{"batb":[[1,1.01,7],[2,1.01,0]],"ltp":0.0,"tv":0.0,"id":14036296}]}]}
{"op":"mcm","clk":"4216163357","pt":1631548730141,"mc":[{"id":"1.187607461","rc":[{"batb":[[0,1.01,7],[1,1.01,0]],"ltp":1.65,"tv":63.25,"id":16100628},{"batb":[[0,1.01,7],[1,1.01,0]],"ltp":0.0,"tv":0.0,"id":14036296}]}]}
{"op":"mcm","clk":"4216163763","pt":1631548735030,"mc":[{"id":"1.187607461","rc":[{"batb":[[0,2.26,23.8],[1,1.01,7]],"ltp":1.65,"tv":63.25,"id":16100628},{"batb":[[0,1.58,51.72],[1,1.01,7]],"ltp":0.0,"tv":0.0,"id":14036296}]}]}
{"op":"mcm","clk":"4216164226","pt":1631548740447,"mc":[{"id":"1.187607461","rc":[{"batl":[[0,1.8,160.61]],"ltp":0.0,"tv":0.0,"id":14036296}]}]}
{"op":"mcm","clk":"4216164411","pt":1631548742440,"mc":[{"id":"1.187607461","rc":[{"batb":[[1,1.57,160.61],[2,1.01,7]],"ltp":0.0,"tv":0.0,"id":14036296}]}]}
{"op":"mcm","clk":"4216169100","pt":1631548792730,"mc":[{"id":"1.187607461","rc":[{"batb":[[0,1.01,7],[1,1.01,0]],"ltp":1.65,"tv":63.25,"id":16100628},{"batb":[[0,1.57,160.61],[1,1.01,7],[2,1.01,0]],"ltp":0.0,"tv":0.0,"id":14036296}]}]}
{"op":"mcm","clk":"4216169335","pt":1631548795518,"mc":[{"id":"1.187607461","rc":[{"batb":[[0,1.01,7],[1,1.01,0]],"ltp":0.0,"tv":0.0,"id":14036296}]}]}
{"op":"mcm","clk":"4216169544","pt":1631548797731,"mc":[{"id":"1.187607461","rc":[{"batb":[[0,2.1,27.27],[1,1.01,7]],"ltp":1.65,"tv":63.25,"id":16100628},{"batb":[[0,1.65,46.15],[1,1.01,7]],"ltp":0.0,"tv":0.0,"id":14036296}]}]}
{"op":"mcm","clk":"4216170068","pt":1631548802834,"mc":[{"id":"1.187607461","rc":[{"batl":[[0,1.9,160.61]],"ltp":0.0,"tv":0.0,"id":14036296}]}]}
{"op":"mcm","clk":"4216171411","pt":1631548816360,"mc":[{"id":"1.187607461","rc":[{"batb":[[0,1.01,7],[1,1.01,0]],"ltp":1.65,"tv":63.25,"id":16100628},{"batb":[[0,1.01,7],[1,1.01,0]],"ltp":0.0,"tv":0.0,"id":14036296}]}]}
{"op":"mcm","clk":"4216171887","pt":1631548821381,"mc":[{"id":"1.187607461","rc":[{"batb":[[0,2.06,28.3],[1,1.01,7]],"ltp":1.65,"tv":63.25,"id":16100628},{"batb":[[0,1.71,42.25],[1,1.01,7]],"ltp":0.0,"tv":0.0,"id":14036296}]}]}
{"op":"mcm","clk":"4216172879","pt":1631548831658,"mc":[{"id":"1.187607461","rc":[{"batb":[[0,1.01,7],[1,1.01,0]],"ltp":1.65,"tv":63.25,"id":16100628},{"batb":[[0,1.01,7],[1,1.01,0]],"ltp":0.0,"tv":0.0,"id":14036296}]}]}
{"op":"mcm","clk":"4216173337","pt":1631548836572,"mc":[{"id":"1.187607461","rc":[{"batb":[[0,2.26,23.8],[1,1.01,7]],"ltp":1.65,"tv":63.25,"id":16100628},{"batb":[[0,1.58,51.72],[1,1.01,7]],"ltp":0.0,"tv":0.0,"id":14036296}]}]}
{"op":"mcm","clk":"4216174063","pt":1631548844006,"mc":[{"id":"1.187607461","rc":[{"batl":[[0,1.8,160.61]],"ltp":0.0,"tv":0.0,"id":14036296}]}]}
{"op":"mcm","clk":"4216176867","pt":1631548871386,"mc":[{"id":"1.187607461","rc":[{"batb":[[0,1.01,7],[1,1.01,0]],"ltp":1.65,"tv":63.25,"id":16100628},{"batb":[[0,1.01,7],[1,1.01,0]],"ltp":0.0,"tv":0.0,"id":14036296}]}]}
{"op":"mcm","clk":"4216177305","pt":1631548876293,"mc":[{"id":"1.187607461","rc":[{"batb":[[0,2.5,20],[1,1.01,7]],"ltp":1.65,"tv":63.25,"id":16100628},{"batb":[[0,1.48,62.5],[1,1.01,7]],"ltp":0.0,"tv":0.0,"id":14036296}]}]}
{"op":"mcm","clk":"4216178028","pt":1631548883631,"mc":[{"id":"1.187607461","rc":[{"batl":[[0,1.66,160.61]],"ltp":0.0,"tv":0.0,"id":14036296}]}]}
{"op":"mcm","clk":"4216179351","pt":1631548894825,"mc":[{"id":"1.187607461","rc":[{"trd":[[2.84,1.88]],"batl":[[0,2.84,104.59]],"ltp":2.84,"tv":65.13,"id":16100628},{"trd":[[1.54,3.47]],"ltp":1.54,"tv":3.46,"id":14036296}],"tv":68.6}]}
{"op":"mcm","clk":"4216179594","pt":1631548897919,"mc":[{"id":"1.187607461","rc":[{"batb":[[0,1.01,7],[1,1.01,0]],"ltp":2.84,"tv":65.13,"id":16100628},{"batb":[[0,1.01,7],[1,1.01,0]],"ltp":1.54,"tv":3.46,"id":14036296}]}]}
{"op":"mcm","clk":"4216180104","pt":1631548902838,"mc":[{"id":"1.187607461","rc":[{"batb":[[0,2.26,23.8],[1,1.01,7]],"ltp":2.84,"tv":65.13,"id":16100628},{"batb":[[0,1.58,51.72],[1,1.01,7]],"ltp":1.54,"tv":3.46,"id":14036296}]}]}
{"op":"mcm","clk":"4216182361","pt":1631548927854,"mc":[{"id":"1.187607461","rc":[{"batb":[[0,1.01,7],[1,1.01,0]],"ltp":2.84,"tv":65.13,"id":16100628},{"batb":[[0,1.01,7],[1,1.01,0]],"ltp":1.54,"tv":3.46,"id":14036296}]}]}
{"op":"mcm","clk":"4216182901","pt":1631548932854,"mc":[{"id":"1.187607461","rc":[{"batb":[[0,1.98,30.61],[1,1.01,7]],"ltp":2.84,"tv":65.13,"id":16100628},{"batb":[[0,1.78,38.46],[1,1.01,7]],"ltp":1.54,"tv":3.46,"id":14036296}]}]}
{"op":"mcm","clk":"4216185391","pt":1631548959606,"mc":[{"id":"1.187607461","rc":[{"batb":[[0,1.01,7],[1,1.01,0]],"ltp":2.84,"tv":65.13,"id":16100628},{"batb":[[0,1.01,7],[1,1.01,0]],"ltp":1.54,"tv":3.46,"id":14036296}]}]}
{"op":"mcm","clk":"4216185876","pt":1631548964592,"mc":[{"id":"1.187607461","rc":[{"batb":[[0,1.71,42.25],[1,1.01,7]],"ltp":2.84,"tv":65.13,"id":16100628},{"batb":[[0,2.06,28.3],[1,1.01,7]],"ltp":1.54,"tv":3.46,"id":14036296}]}]}
{"op":"mcm","clk":"4216188491","pt":1631548993858,"mc":[{"id":"1.187607461","rc":[{"batl":[[0,2.24,160.61]],"ltp":1.54,"tv":3.46,"id":14036296}]}]}
{"op":"mcm","clk":"4216194718","pt":1631549067642,"mc":[{"id":"1.187607461","rc":[{"batb":[[0,1.01,7],[1,1.01,0]],"ltp":2.84,"tv":65.13,"id":16100628},{"batb":[[0,1.01,7],[1,1.01,0]],"ltp":1.54,"tv":3.46,"id":14036296}]}]}
{"op":"mcm","clk":"4216195128","pt":1631549072543,"mc":[{"id":"1.187607461","rc":[{"batb":[[0,1.63,47.61],[1,1.01,7]],"ltp":2.84,"tv":65.13,"id":16100628},{"batb":[[0,2.16,25.86],[1,1.01,7]],"ltp":1.54,"tv":3.46,"id":14036296}]}]}
{"op":"mcm","clk":"4216195875","pt":1631549080879,"mc":[{"id":"1.187607461","rc":[{"batl":[[0,2.42,160.61]],"ltp":1.54,"tv":3.46,"id":14036296}]}]}
{"op":"mcm","clk":"4216196668","pt":1631549088588,"mc":[{"id":"1.187607461","rc":[{"batb":[[0,1.01,12],[1,1.01,0]],"ltp":2.84,"tv":65.13,"id":16100628},{"batb":[[0,1.01,12],[1,1.01,0]],"ltp":1.54,"tv":3.46,"id":14036296}]}]}
{"op":"mcm","clk":"4216197168","pt":1631549093593,"mc":[{"id":"1.187607461","rc":[{"batb":[[0,1.51,58.82],[1,1.01,12]],"ltp":2.84,"tv":65.13,"id":16100628}]}]}
{"op":"mcm","clk":"4216197371","pt":1631549095268,"mc":[{"id":"1.187607461","rc":[{"batb":[[0,2.42,21.12],[1,1.01,12]],"ltp":1.54,"tv":3.46,"id":14036296}]}]}
{"op":"mcm","clk":"4216198032","pt":1631549099702,"mc":[{"id":"1.187607461","rc":[{"batb":[[0,1.61,160.61],[1,1.51,58.82],[2,1.01,12]],"ltp":2.84,"tv":65.13,"id":16100628}]}]}
{"op":"mcm","clk":"4216198456","pt":1631549103197,"mc":[{"id":"1.187607461","rc":[{"batl":[[0,1.83,160.61],[1,2.84,104.59]],"ltp":2.84,"tv":65.13,"id":16100628}]}]}
{"op":"mcm","clk":"4216200523","pt":1631549121726,"mc":[{"id":"1.187607461","rc":[{"batb":[[1,1.01,12],[2,1.01,0]],"ltp":2.84,"tv":65.13,"id":16100628},{"batb":[[0,1.01,12],[1,1.01,0]],"ltp":1.54,"tv":3.46,"id":14036296}]}]}
{"op":"mcm","clk":"4216200689","pt":1631549123244,"mc":[{"id":"1.187607461","rc":[{"batl":[[0,2.84,104.59],[1,2.84,0]],"ltp":2.84,"tv":65.13,"id":16100628}]}]}
{"op":"mcm","clk":"4216201042","pt":1631549126736,"mc":[{"id":"1.187607461","rc":[{"batb":[[1,1.6,49.99],[2,1.01,12]],"ltp":2.84,"tv":65.13,"id":16100628},{"batb":[[0,2.2,24.99],[1,1.01,12]],"ltp":1.54,"tv":3.46,"id":14036296}]}]}
{"op":"mcm","clk":"4216201082","pt":1631549127149,"mc":[{"id":"1.187607461","rc":[{"batb":[[0,1.6,49.99],[1,1.01,12],[2,1.01,0]],"ltp":2.84,"tv":65.13,"id":16100628}]}]}
{"op":"mcm","clk":"4216201933","pt":1631549132836,"mc":[{"id":"1.187607461","rc":[{"batb":[[0,1.7,160.61],[1,1.6,49.99],[2,1.01,12]],"ltp":2.84,"tv":65.13,"id":16100628}]}]}
{"op":"mcm","clk":"4216206219","pt":1631549179520,"mc":[{"id":"1.187607461","rc":[{"batb":[[1,1.01,12],[2,1.01,0]],"ltp":2.84,"tv":65.13,"id":16100628},{"batb":[[0,1.01,12],[1,1.01,0]],"ltp":1.54,"tv":3.46,"id":14036296}]}]}
{"op":"mcm","clk":"4216206806","pt":1631549184510,"mc":[{"id":"1.187607461","rc":[{"batb":[[1,1.63,47.61],[2,1.01,12]],"ltp":2.84,"tv":65.13,"id":16100628},{"batb":[[0,2.16,25.86],[1,1.01,12]],"ltp":1.54,"tv":3.46,"id":14036296}]}]}
{"op":"mcm","clk":"4216209137","pt":1631549206074,"mc":[{"id":"1.187607461","rc":[{"batb":[[1,1.01,12],[2,1.01,0]],"ltp":2.84,"tv":65.13,"id":16100628},{"batb":[[0,1.01,12],[1,1.01,0]],"ltp":1.54,"tv":3.46,"id":14036296}]}]}
{"op":"mcm","clk":"4216209258","pt":1631549207332,"mc":[{"id":"1.187607461","rc":[{"batb":[[0,1.01,12],[1,1.01,0]],"ltp":2.84,"tv":65.13,"id":16100628}]}]}
{"op":"mcm","clk":"4216209614","pt":1631549211082,"mc":[{"id":"1.187607461","rc":[{"batb":[[0,1.48,62.5],[1,1.01,12]],"ltp":2.84,"tv":65.13,"id":16100628},{"batb":[[0,2.5,20],[1,1.01,12]],"ltp":1.54,"tv":3.46,"id":14036296}]}]}
{"op":"mcm","clk":"4216210072","pt":1631549215549,"mc":[{"id":"1.187607461","rc":[{"batb":[[0,1.57,160.61],[1,1.48,62.5],[2,1.01,12]],"ltp":2.84,"tv":65.13,"id":16100628}]}]}
{"op":"mcm","clk":"4216210327","pt":1631549217947,"mc":[{"id":"1.187607461","rc":[{"batl":[[0,1.8,160.61],[1,2.84,104.59]],"ltp":2.84,"tv":65.13,"id":16100628}]}]}
{"op":"mcm","clk":"4216212460","pt":1631549238891,"mc":[{"id":"1.187607461","rc":[{"batb":[[1,1.01,12],[2,1.01,0]],"ltp":2.84,"tv":65.13,"id":16100628},{"batb":[[0,1.01,12],[1,1.01,0]],"ltp":1.54,"tv":3.46,"id":14036296}]}]}
{"op":"mcm","clk":"4216212613","pt":1631549240503,"mc":[{"id":"1.187607461","rc":[{"batb":[[0,1.01,12],[1,1.01,0]],"ltp":2.84,"tv":65.13,"id":16100628}]}]}
{"op":"mcm","clk":"4216212965","pt":1631549243804,"mc":[{"id":"1.187607461","rc":[{"batb":[[0,1.45,66.66],[1,1.01,12]],"batl":[[0,2.84,104.59],[1,2.84,0]],"ltp":2.84,"tv":65.13,"id":16100628},{"batb":[[0,2.58,18.98],[1,1.01,12]],"ltp":1.54,"tv":3.46,"id":14036296}]}]}
{"op":"mcm","clk":"4216213344","pt":1631549248028,"mc":[{"id":"1.187607461","rc":[{"batb":[[0,1.5,160.61],[1,1.45,66.66],[2,1.01,12]],"ltp":2.84,"tv":65.13,"id":16100628}]}]}
{"op":"mcm","clk":"4216213469","pt":1631549249334,"mc":[{"id":"1.187607461","rc":[{"batl":[[0,1.7,160.61],[1,2.84,104.59]],"ltp":2.84,"tv":65.13,"id":16100628}]}]}
{"op":"mcm","clk":"4216217262","pt":1631549289363,"mc":[{"id":"1.187607461","rc":[{"batb":[[1,1.01,12],[2,1.01,0]],"ltp":2.84,"tv":65.13,"id":16100628},{"batb":[[0,1.01,12],[1,1.01,0]],"ltp":1.54,"tv":3.46,"id":14036296}]}]}
{"op":"mcm","clk":"4216217648","pt":1631549294371,"mc":[{"id":"1.187607461","rc":[{"batb":[[1,1.42,71.42],[2,1.01,12]],"ltp":2.84,"tv":65.13,"id":16100628},{"batb":[[0,2.66,18.07],[1,1.01,12]],"ltp":1.54,"tv":3.46,"id":14036296}]}]}
{"op":"mcm","clk":"4216218028","pt":1631549299705,"mc":[{"id":"1.187607461","rc":[{"batb":[[0,1.42,71.42],[1,1.01,12],[2,1.01,0]],"ltp":2.84,"tv":65.13,"id":16100628}]}]}
{"op":"mcm","clk":"4216218586","pt":1631549306202,"mc":[{"id":"1.187607461","rc":[{"batb":[[0,1.44,321.22],[1,1.42,71.42],[2,1.01,12]],"ltp":2.84,"tv":65.13,"id":16100628}]}]}
{"op":"mcm","clk":"4216218683","pt":1631549307409,"mc":[{"id":"1.187607461","rc":[{"batb":[[1,1.01,12],[2,1.01,0]],"ltp":2.84,"tv":65.13,"id":16100628},{"batb":[[0,1.01,12],[1,1.01,0]],"ltp":1.54,"tv":3.46,"id":14036296}]}]}
{"op":"mcm","clk":"4216219100","pt":1631549312407,"mc":[{"id":"1.187607461","rc":[{"batb":[[1,1.38,78.94],[2,1.01,12]],"ltp":2.84,"tv":65.13,"id":16100628},{"batb":[[0,2.84,16.3],[1,1.01,12]],"ltp":1.54,"tv":3.46,"id":14036296}]}]}
{"op":"mcm","clk":"4216219618","pt":1631549318407,"mc":[{"id":"1.187607461","rc":[{"batb":[[1,1.01,12],[2,1.01,0]],"ltp":2.84,"tv":65.13,"id":16100628},{"batb":[[0,1.01,12],[1,1.01,0]],"ltp":1.54,"tv":3.46,"id":14036296}]}]}
{"op":"mcm","clk":"4216220035","pt":1631549323346,"mc":[{"id":"1.187607461","rc":[{"batb":[[0,1.45,66.66],[1,1.44,321.22],[2,1.01,12]],"ltp":2.84,"tv":65.13,"id":16100628},{"batb":[[0,2.58,18.98],[1,1.01,12]],"ltp":1.54,"tv":3.46,"id":14036296}]}]}
{"op":"mcm","clk":"4216220292","pt":1631549326327,"mc":[{"id":"1.187607461","rc":[{"batb":[[1,1.01,12],[2,1.01,0]],"ltp":2.84,"tv":65.13,"id":16100628}]}]}
{"op":"mcm","clk":"4216220810","pt":1631549332465,"mc":[{"id":"1.187607461","rc":[{"batb":[[0,1.5,321.22],[1,1.45,66.66],[2,1.01,12]],"ltp":2.84,"tv":65.13,"id":16100628}]}]}
{"op":"mcm","clk":"4216222190","pt":1631549349019,"mc":[{"id":"1.187607461","rc":[{"batb":[[1,1.01,12],[2,1.01,0]],"ltp":2.84,"tv":65.13,"id":16100628},{"batb":[[0,1.01,12],[1,1.01,0]],"ltp":1.54,"tv":3.46,"id":14036296}]}]}
{"op":"mcm","clk":"4216222330","pt":1631549350637,"mc":[{"id":"1.187607461","rc":[{"batb":[[0,1.01,12],[1,1.01,0]],"ltp":2.84,"tv":65.13,"id":16100628}]}]}
{"op":"mcm","clk":"4216222675","pt":1631549354040,"mc":[{"id":"1.187607461","rc":[{"batb":[[0,1.38,78.94],[1,1.01,12]],"ltp":2.84,"tv":65.13,"id":16100628},{"batb":[[0,2.84,16.3],[1,1.01,12]],"ltp":1.54,"tv":3.46,"id":14036296}]}]}
{"op":"mcm","clk":"4216223039","pt":1631549358121,"mc":[{"id":"1.187607461","rc":[{"batb":[[0,1.44,321.22],[1,1.38,78.94],[2,1.01,12]],"ltp":2.84,"tv":65.13,"id":16100628}]}]}
{"op":"mcm","clk":"4216224761","pt":1631549377868,"mc":[{"id":"1.187607461","rc":[{"batb":[[1,1.01,12],[2,1.01,0]],"ltp":2.84,"tv":65.13,"id":16100628},{"batb":[[0,1.01,12],[1,1.01,0]],"ltp":1.54,"tv":3.46,"id":14036296}]}]}
{"op":"mcm","clk":"4216225109","pt":1631549381874,"mc":[{"id":"1.187607461","rc":[{"batl":[[0,2.84,104.59],[1,2.84,0]],"ltp":2.84,"tv":65.13,"id":16100628}]}]}
{"op":"mcm","clk":"4216225217","pt":1631549382872,"mc":[{"id":"1.187607461","rc":[{"batb":[[0,1.45,66.66],[1,1.44,321.22],[2,1.01,12]],"ltp":2.84,"tv":65.13,"id":16100628},{"batb":[[0,2.58,18.98],[1,1.01,12]],"ltp":1.54,"tv":3.46,"id":14036296}]}]}
{"op":"mcm","clk":"4216225298","pt":1631549383656,"mc":[{"id":"1.187607461","rc":[{"batb":[[1,1.01,12],[2,1.01,0]],"ltp":2.84,"tv":65.13,"id":16100628}]}]}
{"op":"mcm","clk":"4216225796","pt":1631549388769,"mc":[{"id":"1.187607461","rc":[{"batb":[[0,1.5,160.61],[1,1.45,66.66],[2,1.01,12]],"ltp":2.84,"tv":65.13,"id":16100628}]}]}
{"op":"mcm","clk":"4216225954","pt":1631549390677,"mc":[{"id":"1.187607461","rc":[{"batb":[[0,1.45,66.66],[1,1.01,12],[2,1.01,0]],"ltp":2.84,"tv":65.13,"id":16100628}]}]}
{"op":"mcm","clk":"4216226075","pt":1631549392085,"mc":[{"id":"1.187607461","rc":[{"batl":[[0,1.7,160.61],[1,2.84,104.59]],"ltp":2.84,"tv":65.13,"id":16100628}]}]}
{"op":"mcm","clk":"4216227444","pt":1631549406771,"mc":[{"id":"1.187607461","rc":[{"batb":[[0,1.5,321.22],[1,1.45,66.66],[2,1.01,12]],"ltp":2.84,"tv":65.13,"id":16100628}]}]}
{"op":"mcm","clk":"4216227506","pt":1631549407489,"mc":[{"id":"1.187607461","rc":[{"batb":[[0,1.45,66.66],[1,1.01,12],[2,1.01,0]],"ltp":2.84,"tv":65.13,"id":16100628}]}]}
{"op":"mcm","clk":"4216228055","pt":1631549413581,"mc":[{"id":"1.187607461","rc":[{"batb":[[0,1.01,12],[1,1.01,0]],"ltp":2.84,"tv":65.13,"id":16100628},{"batb":[[0,1.01,12],[1,1.01,0]],"ltp":1.54,"tv":3.46,"id":14036296}]}]}
{"op":"mcm","clk":"4216228480","pt":1631549418587,"mc":[{"id":"1.187607461","rc":[{"batb":[[0,1.48,62.5],[1,1.01,12]],"ltp":2.84,"tv":65.13,"id":16100628},{"batb":[[0,2.5,20],[1,1.01,12]],"ltp":1.54,"tv":3.46,"id":14036296}]}]}
{"op":"mcm","clk":"4216228726","pt":1631549421391,"mc":[{"id":"1.187607461","rc":[{"batl":[[0,2.84,104.59],[1,2.84,0]],"ltp":2.84,"tv":65.13,"id":16100628}]}]}
{"op":"mcm","clk":"4216229338","pt":1631549428210,"mc":[{"id":"1.187607461","rc":[{"trd":[[1.67,29.94]],"batb":[[0,1.67,130.67],[1,1.48,62.5],[2,1.01,12]],"ltp":1.67,"tv":95.07,"id":16100628},{"trd":[[2.5,20]],"batb":[[0,1.01,12],[1,1.01,0]],"ltp":2.5,"tv":23.46,"id":14036296}],"tv":118.54}]}
{"op":"mcm","clk":"4216229811","pt":1631549433324,"mc":[{"id":"1.187607461","rc":[{"batb":[[0,2.36,22.05],[1,1.01,12]],"ltp":2.5,"tv":23.46,"id":14036296}]}]}
{"op":"mcm","clk":"4216230038","pt":1631549435935,"mc":[{"id":"1.187607461","rc":[{"batb":[[0,1.48,62.5],[1,1.01,12],[2,1.01,0]],"ltp":1.67,"tv":95.07,"id":16100628}]}]}
{"op":"mcm","clk":"4216230914","pt":1631549445637,"mc":[{"id":"1.187607461","rc":[{"batb":[[0,1.01,12],[1,1.01,0]],"ltp":1.67,"tv":95.07,"id":16100628},{"batb":[[0,1.01,12],[1,1.01,0]],"ltp":2.5,"tv":23.46,"id":14036296}]}]}
{"op":"mcm","clk":"4216231332","pt":1631549450545,"mc":[{"id":"1.187607461","rc":[{"batb":[[0,1.45,66.66],[1,1.01,12]],"ltp":1.67,"tv":95.07,"id":16100628},{"batb":[[0,2.58,18.98],[1,1.01,12]],"ltp":2.5,"tv":23.46,"id":14036296}]}]}
{"op":"mcm","clk":"4216234415","pt":1631549484606,"mc":[{"id":"1.187607461","rc":[{"batb":[[0,1.01,12],[1,1.01,0]],"ltp":1.67,"tv":95.07,"id":16100628},{"batb":[[0,1.01,12],[1,1.01,0]],"ltp":2.5,"tv":23.46,"id":14036296}]}]}
{"op":"mcm","clk":"4216235025","pt":1631549489575,"mc":[{"id":"1.187607461","rc":[{"batb":[[0,1.42,71.42],[1,1.01,12]],"ltp":1.67,"tv":95.07,"id":16100628},{"batb":[[0,2.66,18.07],[1,1.01,12]],"ltp":2.5,"tv":23.46,"id":14036296}]}]}
{"op":"mcm","clk":"4216235286","pt":1631549492717,"mc":[{"id":"1.187607461","rc":[{"batb":[[0,1.01,12],[1,1.01,0]],"ltp":1.67,"tv":95.07,"id":16100628},{"batb":[[0,1.01,12],[1,1.01,0]],"ltp":2.5,"tv":23.46,"id":14036296}]}]}
{"op":"mcm","clk":"4216235671","pt":1631549497635,"mc":[{"id":"1.187607461","rc":[{"batb":[[0,1.48,62.5],[1,1.01,12]],"ltp":1.67,"tv":95.07,"id":16100628},{"batb":[[0,2.5,20],[1,1.01,12]],"ltp":2.5,"tv":23.46,"id":14036296}]}]}
{"op":"mcm","clk":"4216235889","pt":1631549500567,"mc":[{"id":"1.187607461","rc":[{"batb":[[0,1.65,160.61],[1,1.48,62.5],[2,1.01,12]],"ltp":1.67,"tv":95.07,"id":16100628}]}]}
{"op":"mcm","clk":"4216235925","pt":1631549501093,"mc":[{"id":"1.187607461","rc":[{"batb":[[0,1.48,62.5],[1,1.01,12],[2,1.01,0]],"ltp":1.67,"tv":95.07,"id":16100628}]}]}
{"op":"mcm","clk":"4216236353","pt":1631549506660,"mc":[{"id":"1.187607461","rc":[{"trd":[[1.67,59.88]],"batb":[[0,1.67,130.67],[1,1.48,62.5],[2,1.01,12]],"ltp":1.67,"tv":125.01,"id":16100628},{"trd":[[2.5,40]],"batb":[[0,1.01,12],[1,1.01,0]],"ltp":2.5,"tv":43.46,"id":14036296}],"tv":168.48}]}
{"op":"mcm","clk":"4216236543","pt":1631549508903,"mc":[{"id":"1.187607461","rc":[{"batb":[[0,1.48,62.5],[1,1.01,12],[2,1.01,0]],"ltp":1.67,"tv":125.01,"id":16100628}]}]}
{"op":"mcm","clk":"4216236768","pt":1631549511877,"mc":[{"id":"1.187607461","rc":[{"batb":[[0,2.36,22.05],[1,1.01,12]],"ltp":2.5,"tv":43.46,"id":14036296}]}]}
{"op":"mcm","clk":"4216237410","pt":1631549518718,"mc":[{"id":"1.187607461","rc":[{"batb":[[0,1.67,160.61]],"ltp":1.67,"tv":125.01,"id":16100628},{"batb":[[0,1.01,12],[1,1.01,0]],"ltp":2.5,"tv":43.46,"id":14036296}]}]}
{"op":"mcm","clk":"4216237512","pt":1631549519607,"mc":[{"id":"1.187607461","rc":[{"batb":[[0,1.01,12],[1,1.01,0]],"ltp":1.67,"tv":125.01,"id":16100628}]}]}
{"op":"mcm","clk":"4216237882","pt":1631549523631,"mc":[{"id":"1.187607461","rc":[{"batb":[[0,1.45,66.66],[1,1.01,12]],"ltp":1.67,"tv":125.01,"id":16100628},{"batb":[[0,2.58,18.98],[1,1.01,12]],"ltp":2.5,"tv":43.46,"id":14036296}]}]}
{"op":"mcm","clk":"4216237922","pt":1631549524001,"mc":[{"id":"1.187607461","rc":[{"batl":[[0,1.48,1.71],[1,2.84,104.59]],"ltp":1.67,"tv":125.01,"id":16100628}]}]}
{"op":"mcm","clk":"4216238562","pt":1631549530803,"mc":[{"id":"1.187607461","rc":[{"batl":[[0,2.84,104.59],[1,2.84,0]],"ltp":1.67,"tv":125.01,"id":16100628}]}]}
{"op":"mcm","clk":"4216239062","pt":1631549536413,"mc":[{"id":"1.187607461","rc":[{"batb":[[0,1.01,12],[1,1.01,0]],"ltp":1.67,"tv":125.01,"id":16100628},{"batb":[[0,1.01,12],[1,1.01,0]],"ltp":2.5,"tv":43.46,"id":14036296}]}]}
{"op":"mcm","clk":"4216239319","pt":1631549538906,"mc":[{"id":"1.187607461","rc":[{"batl":[[0,1.45,1.71],[1,2.84,104.59]],"ltp":1.67,"tv":125.01,"id":16100628}]}]}
{"op":"mcm","clk":"4216239572","pt":1631549541459,"mc":[{"id":"1.187607461","rc":[{"batb":[[0,1.38,78.94],[1,1.01,12]],"ltp":1.67,"tv":125.01,"id":16100628},{"batb":[[0,2.84,16.3],[1,1.01,12]],"ltp":2.5,"tv":43.46,"id":14036296}]}]}
{"op":"mcm","clk":"4216240350","pt":1631549550766,"mc":[{"id":"1.187607461","rc":[{"batb":[[0,1.4,160.61],[1,1.38,78.94],[2,1.01,12]],"ltp":1.67,"tv":125.01,"id":16100628}]}]}
{"op":"mcm","clk":"4216240534","pt":1631549552923,"mc":[{"id":"1.187607461","rc":[{"batb":[[1,1.01,12],[2,1.01,0]],"ltp":1.67,"tv":125.01,"id":16100628},{"batb":[[0,1.01,12],[1,1.01,0]],"ltp":2.5,"tv":43.46,"id":14036296}]}]}
{"op":"mcm","clk":"4216240999","pt":1631549558037,"mc":[{"id":"1.187607461","rc":[{"batb":[[0,1.01,12],[1,1.01,0]],"ltp":1.67,"tv":125.01,"id":16100628},{"batb":[[0,2.58,18.98],[1,1.01,12]],"ltp":2.5,"tv":43.46,"id":14036296}]}]}
{"op":"mcm","clk":"4216242592","pt":1631549575130,"mc":[{"id":"1.187607461","rc":[{"batb":[[0,1.01,12],[1,1.01,0]],"ltp":2.5,"tv":43.46,"id":14036296}]}]}
{"op":"mcm","clk":"4216243057","pt":1631549580045,"mc":[{"id":"1.187607461","rc":[{"batb":[[0,2.5,20],[1,1.01,12]],"ltp":2.5,"tv":43.46,"id":14036296}]}]}
{"op":"mcm","clk":"4216244034","pt":1631549590488,"mc":[{"id":"1.187607461","rc":[{"trd":[[1.45,3.42],[1.67,89.82]],"batb":[[0,1.67,68.35],[1,1.01,12]],"batl":[[0,2.84,104.59],[1,2.84,0]],"ltp":1.67,"tv":158.37,"id":16100628},{"trd":[[2.5,60]],"batb":[[0,1.01,12],[1,1.01,0]],"ltp":2.5,"tv":63.46,"id":14036296}],"tv":221.84}]}
{"op":"mcm","clk":"4216244135","pt":1631549591689,"mc":[{"id":"1.187607461","rc":[{"batb":[[0,1.01,12],[1,1.01,0]],"ltp":1.67,"tv":158.37,"id":16100628}]}]}
{"op":"mcm","clk":"4216244511","pt":1631549595446,"mc":[{"id":"1.187607461","rc":[{"batb":[[0,1.48,62.5],[1,1.01,12]],"ltp":1.67,"tv":158.37,"id":16100628},{"batb":[[0,2.36,22.05],[1,1.01,12]],"ltp":2.5,"tv":63.46,"id":14036296}]}]}
{"op":"mcm","clk":"4216248600","pt":1631549639918,"mc":[{"id":"1.187607461","rc":[{"batb":[[0,1.01,12],[1,1.01,0]],"ltp":1.67,"tv":158.37,"id":16100628},{"batb":[[0,1.01,12],[1,1.01,0]],"ltp":2.5,"tv":63.46,"id":14036296}]}]}
{"op":"mcm","clk":"4216249073","pt":1631549644873,"mc":[{"id":"1.187607461","rc":[{"batb":[[0,1.45,66.66],[1,1.01,12]],"ltp":1.67,"tv":158.37,"id":16100628},{"batb":[[0,2.58,18.98],[1,1.01,12]],"ltp":2.5,"tv":63.46,"id":14036296}]}]}
{"op":"mcm","clk":"4216251359","pt":1631549666987,"mc":[{"id":"1.187607461","rc":[{"batb":[[0,1.01,12],[1,1.01,0]],"ltp":1.67,"tv":158.37,"id":16100628},{"batb":[[0,1.01,12],[1,1.01,0]],"ltp":2.5,"tv":63.46,"id":14036296}]}]}
{"op":"mcm","clk":"4216251794","pt":1631549671811,"mc":[{"id":"1.187607461","rc":[{"batb":[[0,1.38,78.94],[1,1.01,12]],"ltp":1.67,"tv":158.37,"id":16100628},{"batb":[[0,2.84,16.3],[1,1.01,12]],"ltp":2.5,"tv":63.46,"id":14036296}]}]}
{"op":"mcm","clk":"4216255344","pt":1631549708638,"mc":[{"id":"1.187607461","rc":[{"batb":[[0,1.01,12],[1,1.01,0]],"ltp":1.67,"tv":158.37,"id":16100628},{"batb":[[0,1.01,12],[1,1.01,0]],"ltp":2.5,"tv":63.46,"id":14036296}]}]}
{"op":"mcm","clk":"4216255786","pt":1631549713543,"mc":[{"id":"1.187607461","rc":[{"batb":[[0,1.42,71.42],[1,1.01,12]],"ltp":1.67,"tv":158.37,"id":16100628},{"batb":[[0,2.66,18.07],[1,1.01,12]],"ltp":2.5,"tv":63.46,"id":14036296}]}]}
{"op":"mcm","clk":"4216256497","pt":1631549721260,"mc":[{"id":"1.187607461","rc":[{"batb":[[0,1.01,12],[1,1.01,0]],"ltp":1.67,"tv":158.37,"id":16100628},{"batb":[[0,1.01,12],[1,1.01,0]],"ltp":2.5,"tv":63.46,"id":14036296}]}]}
{"op":"mcm","clk":"4216257024","pt":1631549726307,"mc":[{"id":"1.187607461","rc":[{"batb":[[0,1.38,78.94],[1,1.01,12]],"ltp":1.67,"tv":158.37,"id":16100628},{"batb":[[0,2.84,16.3],[1,1.01,12]],"ltp":2.5,"tv":63.46,"id":14036296}]}]}
{"op":"mcm","clk":"4216258849","pt":1631549744803,"mc":[{"id":"1.187607461","rc":[{"batb":[[0,1.01,12],[1,1.01,0]],"ltp":1.67,"tv":158.37,"id":16100628},{"batb":[[0,1.01,12],[1,1.01,0]],"ltp":2.5,"tv":63.46,"id":14036296}]}]}
{"op":"mcm","clk":"4216259345","pt":1631549749708,"mc":[{"id":"1.187607461","rc":[{"batb":[[0,1.31,96.77],[1,1.01,12]],"ltp":1.67,"tv":158.37,"id":16100628},{"batb":[[0,3.15,13.95],[1,1.01,12]],"ltp":2.5,"tv":63.46,"id":14036296}]}]}
{"op":"mcm","clk":"4216261145","pt":1631549767331,"mc":[{"id":"1.187607461","rc":[{"batb":[[0,1.32,100],[1,1.31,96.77],[2,1.01,12]],"ltp":1.67,"tv":158.37,"id":16100628}]}]}
{"op":"mcm","clk":"4216261399","pt":1631549769636,"mc":[{"id":"1.187607461","rc":[{"batl":[[0,1.46,50],[1,2.84,104.59]],"ltp":1.67,"tv":158.37,"id":16100628}]}]}
{"op":"mcm","clk":"4216261580","pt":1631549771365,"mc":[{"id":"1.187607461","rc":[{"batl":[[0,1.46,150]],"ltp":1.67,"tv":158.37,"id":16100628}]}]}
{"op":"mcm","clk":"4216261658","pt":1631549772154,"mc":[{"id":"1.187607461","rc":[{"batl":[[0,1.46,200]],"ltp":1.67,"tv":158.37,"id":16100628}]}]}
{"op":"mcm","clk":"4216268413","pt":1631549840551,"mc":[{"id":"1.187607461","rc":[{"batb":[[0,1.31,96.77],[1,1.01,12],[2,1.01,0]],"batl":[[0,2.84,104.59],[1,2.84,0]],"ltp":1.67,"tv":158.37,"id":16100628}]}]}
{"op":"mcm","clk":"4216308100","pt":1631550165998,"mc":[{"id":"1.187607461","rc":[{"batb":[[0,1.01,12],[1,1.01,0]],"ltp":1.67,"tv":158.37,"id":16100628},{"batb":[[0,1.01,12],[1,1.01,0]],"ltp":2.5,"tv":63.46,"id":14036296}]}]}
{"op":"mcm","clk":"4216308592","pt":1631550171006,"mc":[{"id":"1.187607461","rc":[{"batb":[[0,1.27,111.11],[1,1.01,12]],"ltp":1.67,"tv":158.37,"id":16100628},{"batb":[[0,3.4,12.5],[1,1.01,12]],"ltp":2.5,"tv":63.46,"id":14036296}]}]}
{"op":"mcm","clk":"4216311025","pt":1631550195191,"mc":[{"id":"1.187607461","rc":[{"batb":[[0,1.01,12],[1,1.01,0]],"ltp":1.67,"tv":158.37,"id":16100628},{"batb":[[0,1.01,12],[1,1.01,0]],"ltp":2.5,"tv":63.46,"id":14036296}]}]}
{"op":"mcm","clk":"4216311407","pt":1631550200204,"mc":[{"id":"1.187607461","rc":[{"batb":[[0,1.34,88.23],[1,1.01,12]],"ltp":1.67,"tv":158.37,"id":16100628},{"batb":[[0,3,15],[1,1.01,12]],"ltp":2.5,"tv":63.46,"id":14036296}]}]}
{"op":"mcm","clk":"4216312978","pt":1631550218414,"mc":[{"id":"1.187607461","rc":[{"trd":[[1.34,7.96]],"batb":[[0,1.01,12],[1,1.01,0]],"ltp":1.34,"tv":166.33,"id":16100628}],"tv":229.8}]}
{"op":"mcm","clk":"4216313411","pt":1631550223452,"mc":[{"id":"1.187607461","rc":[{"batb":[[0,1.34,88.23],[1,1.01,12]],"ltp":1.34,"tv":166.33,"id":16100628}]}]}
{"op":"mcm","clk":"4216314048","pt":1631550230333,"mc":[{"id":"1.187607461","rc":[{"batb":[[0,1.01,12],[1,1.01,0]],"ltp":1.34,"tv":166.33,"id":16100628},{"batb":[[0,1.01,12],[1,1.01,0]],"ltp":2.5,"tv":63.46,"id":14036296}]}]}
{"op":"mcm","clk":"4216314443","pt":1631550235268,"mc":[{"id":"1.187607461","rc":[{"batb":[[0,1.27,111.11],[1,1.01,12]],"ltp":1.34,"tv":166.33,"id":16100628},{"batb":[[0,3.4,12.5],[1,1.01,12]],"ltp":2.5,"tv":63.46,"id":14036296}]}]}
{"op":"mcm","clk":"4216316434","pt":1631550256875,"mc":[{"id":"1.187607461","rc":[{"batb":[[0,1.01,12],[1,1.01,0]],"ltp":1.34,"tv":166.33,"id":16100628},{"batb":[[0,1.01,12],[1,1.01,0]],"ltp":2.5,"tv":63.46,"id":14036296}]}]}
{"op":"mcm","clk":"4216316859","pt":1631550261786,"mc":[{"id":"1.187607461","rc":[{"batb":[[0,1.34,88.23],[1,1.01,12]],"ltp":1.34,"tv":166.33,"id":16100628},{"batb":[[0,3,15],[1,1.01,12]],"ltp":2.5,"tv":63.46,"id":14036296}]}]}
{"op":"mcm","clk":"4216318624","pt":1631550282030,"mc":[{"id":"1.187607461","rc":[{"batb":[[0,1.01,12],[1,1.01,0]],"ltp":1.34,"tv":166.33,"id":16100628},{"batb":[[0,1.01,12],[1,1.01,0]],"ltp":2.5,"tv":63.46,"id":14036296}]}]}
{"op":"mcm","clk":"4216319031","pt":1631550286941,"mc":[{"id":"1.187607461","rc":[{"batb":[[0,1.27,111.11],[1,1.01,12]],"ltp":1.34,"tv":166.33,"id":16100628},{"batb":[[0,3.4,12.5],[1,1.01,12]],"ltp":2.5,"tv":63.46,"id":14036296}]}]}
{"op":"mcm","clk":"4216322641","pt":1631550326917,"mc":[{"id":"1.187607461","rc":[{"batb":[[0,1.01,12],[1,1.01,0]],"ltp":1.34,"tv":166.33,"id":16100628},{"batb":[[0,1.01,12],[1,1.01,0]],"ltp":2.5,"tv":63.46,"id":14036296}]}]}
{"op":"mcm","clk":"4216323134","pt":1631550331822,"mc":[{"id":"1.187607461","rc":[{"batb":[[0,1.18,166.66],[1,1.01,12]],"ltp":1.34,"tv":166.33,"id":16100628},{"batb":[[0,4.1,10],[1,1.01,12]],"ltp":2.5,"tv":63.46,"id":14036296}]}]}
{"op":"mcm","clk":"4216328474","pt":1631550383205,"mc":[{"id":"1.187607461","rc":[{"batb":[[0,1.01,12],[1,1.01,0]],"ltp":1.34,"tv":166.33,"id":16100628},{"batb":[[0,1.01,12],[1,1.01,0]],"ltp":2.5,"tv":63.46,"id":14036296}]}]}
{"op":"mcm","clk":"4216328986","pt":1631550388121,"mc":[{"id":"1.187607461","rc":[{"batb":[[0,1.23,130.43],[1,1.01,12]],"ltp":1.34,"tv":166.33,"id":16100628},{"batb":[[0,3.7,11.11],[1,1.01,12]],"ltp":2.5,"tv":63.46,"id":14036296}]}]}
{"op":"mcm","clk":"4216332902","pt":1631550426145,"mc":[{"id":"1.187607461","rc":[{"batb":[[0,1.01,12],[1,1.01,0]],"ltp":1.34,"tv":166.33,"id":16100628},{"batb":[[0,1.01,12],[1,1.01,0]],"ltp":2.5,"tv":63.46,"id":14036296}]}]}
{"op":"mcm","clk":"4216333454","pt":1631550431177,"mc":[{"id":"1.187607461","rc":[{"batb":[[0,1.28,107.14],[1,1.01,12]],"ltp":1.34,"tv":166.33,"id":16100628},{"batb":[[0,3.3,13.04],[1,1.01,12]],"ltp":2.5,"tv":63.46,"id":14036296}]}]}
{"op":"mcm","clk":"4216335280","pt":1631550447989,"mc":[{"id":"1.187607461","rc":[{"batb":[[0,1.01,12],[1,1.01,0]],"ltp":1.34,"tv":166.33,"id":16100628},{"batb":[[0,1.01,12],[1,1.01,0]],"ltp":2.5,"tv":63.46,"id":14036296}]}]}
{"op":"mcm","clk":"4216335854","pt":1631550452983,"mc":[{"id":"1.187607461","rc":[{"batb":[[0,1.34,88.23],[1,1.01,12]],"ltp":1.34,"tv":166.33,"id":16100628},{"batb":[[0,3,15],[1,1.01,12]],"ltp":2.5,"tv":63.46,"id":14036296}]}]}
{"op":"mcm","clk":"4216341163","pt":1631550505851,"mc":[{"id":"1.187607461","rc":[{"batb":[[0,1.01,12],[1,1.01,0]],"ltp":1.34,"tv":166.33,"id":16100628},{"batb":[[0,1.01,12],[1,1.01,0]],"ltp":2.5,"tv":63.46,"id":14036296}]}]}
{"op":"mcm","clk":"4216341635","pt":1631550510744,"mc":[{"id":"1.187607461","rc":[{"batb":[[0,1.28,107.14],[1,1.01,12]],"ltp":1.34,"tv":166.33,"id":16100628},{"batb":[[0,3.3,13.04],[1,1.01,12]],"ltp":2.5,"tv":63.46,"id":14036296}]}]}
{"op":"mcm","clk":"4216343914","pt":1631550534572,"mc":[{"id":"1.187607461","rc":[{"batb":[[0,1.01,12],[1,1.01,0]],"ltp":1.34,"tv":166.33,"id":16100628},{"batb":[[0,1.01,12],[1,1.01,0]],"ltp":2.5,"tv":63.46,"id":14036296}]}]}
{"op":"mcm","clk":"4216344399","pt":1631550539569,"mc":[{"id":"1.187607461","rc":[{"batb":[[0,1.38,78.94],[1,1.01,12]],"ltp":1.34,"tv":166.33,"id":16100628},{"batb":[[0,2.84,16.3],[1,1.01,12]],"ltp":2.5,"tv":63.46,"id":14036296}]}]}
{"op":"mcm","clk":"4216347246","pt":1631550570235,"mc":[{"id":"1.187607461","rc":[{"batb":[[0,1.01,12],[1,1.01,0]],"ltp":1.34,"tv":166.33,"id":16100628},{"batb":[[0,1.01,12],[1,1.01,0]],"ltp":2.5,"tv":63.46,"id":14036296}]}]}
{"op":"mcm","clk":"4216347716","pt":1631550575144,"mc":[{"id":"1.187607461","rc":[{"batb":[[0,1.45,66.66],[1,1.01,12]],"ltp":1.34,"tv":166.33,"id":16100628},{"batb":[[0,2.58,18.98],[1,1.01,12]],"ltp":2.5,"tv":63.46,"id":14036296}]}]}
{"op":"mcm","clk":"4216353892","pt":1631550641527,"mc":[{"id":"1.187607461","rc":[{"batb":[[0,1.01,12],[1,1.01,0]],"ltp":1.34,"tv":166.33,"id":16100628},{"batb":[[0,1.01,12],[1,1.01,0]],"ltp":2.5,"tv":63.46,"id":14036296}]}]}
{"op":"mcm","clk":"4216354368","pt":1631550646461,"mc":[{"id":"1.187607461","rc":[{"batb":[[0,1.51,58.82],[1,1.01,12]],"ltp":1.34,"tv":166.33,"id":16100628},{"batb":[[0,2.42,21.12],[1,1.01,12]],"ltp":2.5,"tv":63.46,"id":14036296}]}]}
{"op":"mcm","clk":"4216359230","pt":1631550704934,"mc":[{"id":"1.187607461","rc":[{"batb":[[0,1.01,12],[1,1.01,0]],"ltp":1.34,"tv":166.33,"id":16100628},{"batb":[[0,1.01,12],[1,1.01,0]],"ltp":2.5,"tv":63.46,"id":14036296}]}]}
{"op":"mcm","clk":"4216359558","pt":1631550709868,"mc":[{"id":"1.187607461","rc":[{"batb":[[0,1.6,49.99],[1,1.01,12]],"ltp":1.34,"tv":166.33,"id":16100628},{"batb":[[0,2.2,24.99],[1,1.01,12]],"ltp":2.5,"tv":63.46,"id":14036296}]}]}
{"op":"mcm","clk":"4216366495","pt":1631550805456,"mc":[{"id":"1.187607461","rc":[{"batb":[[0,1.01,12],[1,1.01,0]],"ltp":1.34,"tv":166.33,"id":16100628},{"batb":[[0,1.01,12],[1,1.01,0]],"ltp":2.5,"tv":63.46,"id":14036296}]}]}
{"op":"mcm","clk":"4216366852","pt":1631550810413,"mc":[{"id":"1.187607461","rc":[{"batb":[[0,1.51,58.82],[1,1.01,12]],"ltp":1.34,"tv":166.33,"id":16100628},{"batb":[[0,2.42,21.12],[1,1.01,12]],"ltp":2.5,"tv":63.46,"id":14036296}]}]}
{"op":"mcm","clk":"4216368202","pt":1631550828444,"mc":[{"id":"1.187607461","rc":[{"batb":[[0,1.01,12],[1,1.01,0]],"ltp":1.34,"tv":166.33,"id":16100628},{"batb":[[0,1.01,12],[1,1.01,0]],"ltp":2.5,"tv":63.46,"id":14036296}]}]}
{"op":"mcm","clk":"4216368588","pt":1631550833339,"mc":[{"id":"1.187607461","rc":[{"batb":[[0,1.48,62.5],[1,1.01,12]],"ltp":1.34,"tv":166.33,"id":16100628},{"batb":[[0,2.5,20],[1,1.01,12]],"ltp":2.5,"tv":63.46,"id":14036296}]}]}
{"op":"mcm","clk":"4216370026","pt":1631550850336,"mc":[{"id":"1.187607461","rc":[{"batb":[[0,1.01,12],[1,1.01,0]],"ltp":1.34,"tv":166.33,"id":16100628},{"batb":[[0,1.01,12],[1,1.01,0]],"ltp":2.5,"tv":63.46,"id":14036296}]}]}
{"op":"mcm","clk":"4216370465","pt":1631550855277,"mc":[{"id":"1.187607461","rc":[{"batb":[[0,1.6,49.99],[1,1.01,12]],"ltp":1.34,"tv":166.33,"id":16100628},{"batb":[[0,2.2,24.99],[1,1.01,12]],"ltp":2.5,"tv":63.46,"id":14036296}]}]}
{"op":"mcm","clk":"4216371845","pt":1631550872190,"mc":[{"id":"1.187607461","rc":[{"batb":[[0,1.01,12],[1,1.01,0]],"ltp":1.34,"tv":166.33,"id":16100628},{"batb":[[0,1.01,12],[1,1.01,0]],"ltp":2.5,"tv":63.46,"id":14036296}]}]}
{"op":"mcm","clk":"4216372211","pt":1631550877203,"mc":[{"id":"1.187607461","rc":[{"batb":[[0,1.71,42.25],[1,1.01,12]],"ltp":1.34,"tv":166.33,"id":16100628},{"batb":[[0,2.06,28.3],[1,1.01,12]],"ltp":2.5,"tv":63.46,"id":14036296}]}]}
{"op":"mcm","clk":"4216373688","pt":1631550894821,"mc":[{"id":"1.187607461","rc":[{"batb":[[0,1.01,12],[1,1.01,0]],"ltp":1.34,"tv":166.33,"id":16100628},{"batb":[[0,1.01,12],[1,1.01,0]],"ltp":2.5,"tv":63.46,"id":14036296}]}]}
{"op":"mcm","clk":"4216374158","pt":1631550899824,"mc":[{"id":"1.187607461","rc":[{"batb":[[0,1.78,38.46],[1,1.01,12]],"ltp":1.34,"tv":166.33,"id":16100628},{"batb":[[0,1.98,30.61],[1,1.01,12]],"ltp":2.5,"tv":63.46,"id":14036296}]}]}
{"op":"mcm","clk":"4216375120","pt":1631550910601,"mc":[{"id":"1.187607461","rc":[{"batb":[[0,1.01,12],[1,1.01,0]],"ltp":1.34,"tv":166.33,"id":16100628},{"batb":[[0,1.01,12],[1,1.01,0]],"ltp":2.5,"tv":63.46,"id":14036296}]}]}
{"op":"mcm","clk":"4216375537","pt":1631550915544,"mc":[{"id":"1.187607461","rc":[{"batb":[[0,1.73,41.09],[1,1.01,12]],"ltp":1.34,"tv":166.33,"id":16100628},{"batb":[[0,2,30],[1,1.01,12]],"ltp":2.5,"tv":63.46,"id":14036296}]}]}
{"op":"mcm","clk":"4216376613","pt":1631550929249,"mc":[{"id":"1.187607461","rc":[{"batb":[[0,1.01,12],[1,1.01,0]],"ltp":1.34,"tv":166.33,"id":16100628},{"batb":[[0,1.01,12],[1,1.01,0]],"ltp":2.5,"tv":63.46,"id":14036296}]}]}
{"op":"mcm","clk":"4216377002","pt":1631550934242,"mc":[{"id":"1.187607461","rc":[{"batb":[[0,1.71,42.25],[1,1.01,12]],"ltp":1.34,"tv":166.33,"id":16100628},{"batb":[[0,2.06,28.3],[1,1.01,12]],"ltp":2.5,"tv":63.46,"id":14036296}]}]}
{"op":"mcm","clk":"4216378933","pt":1631550957368,"mc":[{"id":"1.187607461","rc":[{"batb":[[0,1.01,12],[1,1.01,0]],"ltp":1.34,"tv":166.33,"id":16100628},{"batb":[[0,1.01,12],[1,1.01,0]],"ltp":2.5,"tv":63.46,"id":14036296}]}]}
{"op":"mcm","clk":"4216379360","pt":1631550962391,"mc":[{"id":"1.187607461","rc":[{"batb":[[0,1.78,38.46],[1,1.01,12]],"ltp":1.34,"tv":166.33,"id":16100628},{"batb":[[0,1.98,30.61],[1,1.01,12]],"ltp":2.5,"tv":63.46,"id":14036296}]}]}
{"op":"mcm","clk":"4216382427","pt":1631550998730,"mc":[{"id":"1.187607461","rc":[{"batb":[[0,1.01,12],[1,1.01,0]],"ltp":1.34,"tv":166.33,"id":16100628},{"batb":[[0,1.01,12],[1,1.01,0]],"ltp":2.5,"tv":63.46,"id":14036296}]}]}
{"op":"mcm","clk":"4216382819","pt":1631551003719,"mc":[{"id":"1.187607461","rc":[{"batb":[[0,1.88,34.09],[1,1.01,12]],"ltp":1.34,"tv":166.33,"id":16100628},{"batb":[[0,1.85,35.29],[1,1.01,12]],"ltp":2.5,"tv":63.46,"id":14036296}]}]}
{"op":"mcm","clk":"4216384831","pt":1631551029878,"mc":[{"id":"1.187607461","rc":[{"batb":[[0,1.01,12],[1,1.01,0]],"ltp":1.34,"tv":166.33,"id":16100628},{"batb":[[0,1.01,12],[1,1.01,0]],"ltp":2.5,"tv":63.46,"id":14036296}]}]}
{"op":"mcm","clk":"4216385147","pt":1631551034756,"mc":[{"id":"1.187607461","rc":[{"batb":[[0,2,30],[1,1.01,12]],"ltp":1.34,"tv":166.33,"id":16100628},{"batb":[[0,1.73,41.09],[1,1.01,12]],"ltp":2.5,"tv":63.46,"id":14036296}]}]}
{"op":"mcm","clk":"4216386731","pt":1631551056890,"mc":[{"id":"1.187607461","rc":[{"batb":[[0,1.01,12],[1,1.01,0]],"ltp":1.34,"tv":166.33,"id":16100628},{"batb":[[0,1.01,12],[1,1.01,0]],"ltp":2.5,"tv":63.46,"id":14036296}]}]}
{"op":"mcm","clk":"4216387064","pt":1631551061783,"mc":[{"id":"1.187607461","rc":[{"batb":[[0,1.88,34.09],[1,1.01,12]],"ltp":1.34,"tv":166.33,"id":16100628},{"batb":[[0,1.85,35.29],[1,1.01,12]],"ltp":2.5,"tv":63.46,"id":14036296}]}]}
{"op":"mcm","clk":"4216389566","pt":1631551095189,"mc":[{"id":"1.187607461","rc":[{"batb":[[0,1.01,12],[1,1.01,0]],"ltp":1.34,"tv":166.33,"id":16100628},{"batb":[[0,1.01,12],[1,1.01,0]],"ltp":2.5,"tv":63.46,"id":14036296}]}]}
{"op":"mcm","clk":"4216389953","pt":1631551100112,"mc":[{"id":"1.187607461","rc":[{"batb":[[0,1.98,30.61],[1,1.01,12]],"ltp":1.34,"tv":166.33,"id":16100628},{"batb":[[0,1.78,38.46],[1,1.01,12]],"ltp":2.5,"tv":63.46,"id":14036296}]}]}
{"op":"mcm","clk":"4216390656","pt":1631551109412,"mc":[{"id":"1.187607461","rc":[{"batb":[[0,1.01,12],[1,1.01,0]],"ltp":1.34,"tv":166.33,"id":16100628},{"batb":[[0,1.01,12],[1,1.01,0]],"ltp":2.5,"tv":63.46,"id":14036296}]}]}
{"op":"mcm","clk":"4216391032","pt":1631551114335,"mc":[{"id":"1.187607461","rc":[{"batb":[[0,1.85,35.29],[1,1.01,12]],"ltp":1.34,"tv":166.33,"id":16100628},{"batb":[[0,1.88,34.09],[1,1.01,12]],"ltp":2.5,"tv":63.46,"id":14036296}]}]}
{"op":"mcm","clk":"4216392996","pt":1631551139964,"mc":[{"id":"1.187607461","rc":[{"batb":[[0,1.01,12],[1,1.01,0]],"ltp":1.34,"tv":166.33,"id":16100628},{"batb":[[0,1.01,12],[1,1.01,0]],"ltp":2.5,"tv":63.46,"id":14036296}]}]}
{"op":"mcm","clk":"4216393405","pt":1631551144970,"mc":[{"id":"1.187607461","rc":[{"batb":[[0,1.98,30.61],[1,1.01,12]],"ltp":1.34,"tv":166.33,"id":16100628},{"batb":[[0,1.78,38.46],[1,1.01,12]],"ltp":2.5,"tv":63.46,"id":14036296}]}]}
{"op":"mcm","clk":"4216396938","pt":1631551186717,"mc":[{"id":"1.187607461","rc":[{"batb":[[0,1.01,12],[1,1.01,0]],"ltp":1.34,"tv":166.33,"id":16100628},{"batb":[[0,1.01,12],[1,1.01,0]],"ltp":2.5,"tv":63.46,"id":14036296}]}]}
{"op":"mcm","clk":"4216397272","pt":1631551191719,"mc":[{"id":"1.187607461","rc":[{"batb":[[0,1.85,35.29],[1,1.01,12]],"ltp":1.34,"tv":166.33,"id":16100628},{"batb":[[0,1.88,34.09],[1,1.01,12]],"ltp":2.5,"tv":63.46,"id":14036296}]}]}
{"op":"mcm","clk":"4216400231","pt":1631551231649,"mc":[{"id":"1.187607461","rc":[{"batb":[[0,1.01,12],[1,1.01,0]],"ltp":1.34,"tv":166.33,"id":16100628},{"batb":[[0,1.01,12],[1,1.01,0]],"ltp":2.5,"tv":63.46,"id":14036296}]}]}
{"op":"mcm","clk":"4216400612","pt":1631551236661,"mc":[{"id":"1.187607461","rc":[{"batb":[[0,1.71,42.25],[1,1.01,12]],"ltp":1.34,"tv":166.33,"id":16100628},{"batb":[[0,2.06,28.3],[1,1.01,12]],"ltp":2.5,"tv":63.46,"id":14036296}]}]}
{"op":"mcm","clk":"4216404683","pt":1631551288126,"mc":[{"id":"1.187607461","rc":[{"batb":[[0,1.01,12],[1,1.01,0]],"ltp":1.34,"tv":166.33,"id":16100628},{"batb":[[0,1.01,12],[1,1.01,0]],"ltp":2.5,"tv":63.46,"id":14036296}]}]}
{"op":"mcm","clk":"4216405037","pt":1631551293150,"mc":[{"id":"1.187607461","rc":[{"batb":[[0,1.6,49.99],[1,1.01,12]],"ltp":1.34,"tv":166.33,"id":16100628},{"batb":[[0,2.2,24.99],[1,1.01,12]],"ltp":2.5,"tv":63.46,"id":14036296}]}]}
{"op":"mcm","clk":"4216412519","pt":1631551388712,"mc":[{"id":"1.187607461","rc":[{"batb":[[0,1.01,12],[1,1.01,0]],"ltp":1.34,"tv":166.33,"id":16100628},{"batb":[[0,1.01,12],[1,1.01,0]],"ltp":2.5,"tv":63.46,"id":14036296}]}]}
{"op":"mcm","clk":"4216412896","pt":1631551393741,"mc":[{"id":"1.187607461","rc":[{"batb":[[0,1.51,58.82],[1,1.01,12]],"ltp":1.34,"tv":166.33,"id":16100628},{"batb":[[0,2.42,21.12],[1,1.01,12]],"ltp":2.5,"tv":63.46,"id":14036296}]}]}
{"op":"mcm","clk":"4216413808","pt":1631551406442,"mc":[{"id":"1.187607461","rc":[{"batb":[[0,1.01,12],[1,1.01,0]],"ltp":1.34,"tv":166.33,"id":16100628},{"batb":[[0,1.01,12],[1,1.01,0]],"ltp":2.5,"tv":63.46,"id":14036296}]}]}
{"op":"mcm","clk":"4216414184","pt":1631551411333,"mc":[{"id":"1.187607461","rc":[{"batb":[[0,1.6,49.99],[1,1.01,12]],"ltp":1.34,"tv":166.33,"id":16100628},{"batb":[[0,2.2,24.99],[1,1.01,12]],"ltp":2.5,"tv":63.46,"id":14036296}]}]}
{"op":"mcm","clk":"4216415236","pt":1631551426457,"mc":[{"id":"1.187607461","rc":[{"batb":[[0,1.01,12],[1,1.01,0]],"ltp":1.34,"tv":166.33,"id":16100628},{"batb":[[0,1.01,12],[1,1.01,0]],"ltp":2.5,"tv":63.46,"id":14036296}]}]}
{"op":"mcm","clk":"4216415616","pt":1631551431477,"mc":[{"id":"1.187607461","rc":[{"batb":[[0,1.48,62.5],[1,1.01,12]],"ltp":1.34,"tv":166.33,"id":16100628},{"batb":[[0,2.5,20],[1,1.01,12]],"ltp":2.5,"tv":63.46,"id":14036296}]}]}
{"op":"mcm","clk":"4216418934","pt":1631551473093,"mc":[{"id":"1.187607461","rc":[{"batb":[[0,1.01,12],[1,1.01,0]],"ltp":1.34,"tv":166.33,"id":16100628},{"batb":[[0,1.01,12],[1,1.01,0]],"ltp":2.5,"tv":63.46,"id":14036296}]}]}
{"op":"mcm","clk":"4216419251","pt":1631551477988,"mc":[{"id":"1.187607461","rc":[{"batb":[[0,1.58,51.72],[1,1.01,12]],"ltp":1.34,"tv":166.33,"id":16100628},{"batb":[[0,2.26,23.8],[1,1.01,12]],"ltp":2.5,"tv":63.46,"id":14036296}]}]}
{"op":"mcm","clk":"4216420221","pt":1631551491626,"mc":[{"id":"1.187607461","rc":[{"batb":[[0,1.01,12],[1,1.01,0]],"ltp":1.34,"tv":166.33,"id":16100628},{"batb":[[0,1.01,12],[1,1.01,0]],"ltp":2.5,"tv":63.46,"id":14036296}]}]}
{"op":"mcm","clk":"4216420610","pt":1631551496531,"mc":[{"id":"1.187607461","rc":[{"batb":[[0,1.71,42.25],[1,1.01,12]],"ltp":1.34,"tv":166.33,"id":16100628},{"batb":[[0,2.06,28.3],[1,1.01,12]],"ltp":2.5,"tv":63.46,"id":14036296}]}]}
{"op":"mcm","clk":"4216421925","pt":1631551509645,"mc":[{"id":"1.187607461","rc":[{"batb":[[0,1.01,12],[1,1.01,0]],"ltp":1.34,"tv":166.33,"id":16100628},{"batb":[[0,1.01,12],[1,1.01,0]],"ltp":2.5,"tv":63.46,"id":14036296}]}]}
{"op":"mcm","clk":"4216422295","pt":1631551514647,"mc":[{"id":"1.187607461","rc":[{"batb":[[0,1.85,35.29],[1,1.01,12]],"ltp":1.34,"tv":166.33,"id":16100628},{"batb":[[0,1.88,34.09],[1,1.01,12]],"ltp":2.5,"tv":63.46,"id":14036296}]}]}
{"op":"mcm","clk":"4216423994","pt":1631551536868,"mc":[{"id":"1.187607461","rc":[{"batb":[[0,1.01,12],[1,1.01,0]],"ltp":1.34,"tv":166.33,"id":16100628},{"batb":[[0,1.01,12],[1,1.01,0]],"ltp":2.5,"tv":63.46,"id":14036296}]}]}
{"op":"mcm","clk":"4216424329","pt":1631551541934,"mc":[{"id":"1.187607461","rc":[{"batb":[[0,1.73,41.09],[1,1.01,12]],"ltp":1.34,"tv":166.33,"id":16100628},{"batb":[[0,2,30],[1,1.01,12]],"ltp":2.5,"tv":63.46,"id":14036296}]}]}
{"op":"mcm","clk":"4216425572","pt":1631551562430,"mc":[{"id":"1.187607461","rc":[{"batb":[[0,1.01,12],[1,1.01,0]],"ltp":1.34,"tv":166.33,"id":16100628},{"batb":[[0,1.01,12],[1,1.01,0]],"ltp":2.5,"tv":63.46,"id":14036296}]}]}
{"op":"mcm","clk":"4216425871","pt":1631551567360,"mc":[{"id":"1.187607461","rc":[{"batb":[[0,1.71,42.25],[1,1.01,12]],"ltp":1.34,"tv":166.33,"id":16100628},{"batb":[[0,2.06,28.3],[1,1.01,12]],"ltp":2.5,"tv":63.46,"id":14036296}]}]}
{"op":"mcm","clk":"4216427442","pt":1631551590890,"mc":[{"id":"1.187607461","rc":[{"trd":[[2.06,39.65]],"batb":[[0,1.01,12],[1,1.01,0]],"ltp":2.06,"tv":103.11,"id":14036296}],"tv":269.45}]}
{"op":"mcm","clk":"4216427806","pt":1631551595801,"mc":[{"id":"1.187607461","rc":[{"batb":[[0,1.96,31.25],[1,1.01,12]],"ltp":2.06,"tv":103.11,"id":14036296}]}]}
{"op":"mcm","clk":"4216428493","pt":1631551606010,"mc":[{"id":"1.187607461","rc":[{"batb":[[0,1.01,12],[1,1.01,0]],"ltp":1.34,"tv":166.33,"id":16100628},{"batb":[[0,1.01,12],[1,1.01,0]],"ltp":2.06,"tv":103.11,"id":14036296}]}]}
{"op":"mcm","clk":"4216428893","pt":1631551610917,"mc":[{"id":"1.187607461","rc":[{"batb":[[0,1.78,38.46],[1,1.01,12]],"ltp":1.34,"tv":166.33,"id":16100628},{"batb":[[0,1.98,30.61],[1,1.01,12]],"ltp":2.06,"tv":103.11,"id":14036296}]}]}
{"op":"mcm","clk":"4216431277","pt":1631551646944,"mc":[{"id":"1.187607461","rc":[{"batb":[[0,1.01,12],[1,1.01,0]],"ltp":1.34,"tv":166.33,"id":16100628},{"batb":[[0,1.01,12],[1,1.01,0]],"ltp":2.06,"tv":103.11,"id":14036296}]}]}
{"op":"mcm","clk":"4216431593","pt":1631551651972,"mc":[{"id":"1.187607461","rc":[{"batb":[[0,1.71,42.25],[1,1.01,12]],"ltp":1.34,"tv":166.33,"id":16100628},{"batb":[[0,2.06,28.3],[1,1.01,12]],"ltp":2.06,"tv":103.11,"id":14036296}]}]}
{"op":"mcm","clk":"4216434178","pt":1631551689111,"mc":[{"id":"1.187607461","rc":[{"batb":[[0,1.01,12],[1,1.01,0]],"ltp":1.34,"tv":166.33,"id":16100628},{"batb":[[0,1.01,12],[1,1.01,0]],"ltp":2.06,"tv":103.11,"id":14036296}]}]}
{"op":"mcm","clk":"4216434511","pt":1631551694121,"mc":[{"id":"1.187607461","rc":[{"batb":[[0,1.73,41.09],[1,1.01,12]],"ltp":1.34,"tv":166.33,"id":16100628},{"batb":[[0,2,30],[1,1.01,12]],"ltp":2.06,"tv":103.11,"id":14036296}]}]}
{"op":"mcm","clk":"4216436362","pt":1631551720987,"mc":[{"id":"1.187607461","rc":[{"batb":[[0,1.01,12],[1,1.01,0]],"ltp":1.34,"tv":166.33,"id":16100628},{"batb":[[0,1.01,12],[1,1.01,0]],"ltp":2.06,"tv":103.11,"id":14036296}]}]}
{"op":"mcm","clk":"4216436734","pt":1631551725895,"mc":[{"id":"1.187607461","rc":[{"batb":[[0,1.65,46.15],[1,1.01,12]],"ltp":1.34,"tv":166.33,"id":16100628},{"batb":[[0,2.1,27.27],[1,1.01,12]],"ltp":2.06,"tv":103.11,"id":14036296}]}]}
{"op":"mcm","clk":"4216442924","pt":1631551810226,"mc":[{"id":"1.187607461","rc":[{"batb":[[0,1.01,12],[1,1.01,0]],"ltp":1.34,"tv":166.33,"id":16100628},{"batb":[[0,1.01,12],[1,1.01,0]],"ltp":2.06,"tv":103.11,"id":14036296}]}]}
{"op":"mcm","clk":"4216443215","pt":1631551815110,"mc":[{"id":"1.187607461","rc":[{"batb":[[0,1.78,38.46],[1,1.01,12]],"ltp":1.34,"tv":166.33,"id":16100628},{"batb":[[0,1.98,30.61],[1,1.01,12]],"ltp":2.06,"tv":103.11,"id":14036296}]}]}
{"op":"mcm","clk":"4216445064","pt":1631551842183,"mc":[{"id":"1.187607461","rc":[{"batb":[[0,1.01,12],[1,1.01,0]],"ltp":1.34,"tv":166.33,"id":16100628},{"batb":[[0,1.01,12],[1,1.01,0]],"ltp":2.06,"tv":103.11,"id":14036296}]}]}
{"op":"mcm","clk":"4216445376","pt":1631551847120,"mc":[{"id":"1.187607461","rc":[{"batb":[[0,1.88,34.09],[1,1.01,12]],"ltp":1.34,"tv":166.33,"id":16100628},{"batb":[[0,1.88,34.09],[1,1.01,12]],"ltp":2.06,"tv":103.11,"id":14036296}]}]}
{"op":"mcm","clk":"4216446495","pt":1631551863662,"mc":[{"id":"1.187607461","rc":[{"batb":[[0,1.01,12],[1,1.01,0]],"ltp":1.34,"tv":166.33,"id":16100628},{"batb":[[0,1.01,12],[1,1.01,0]],"ltp":2.06,"tv":103.11,"id":14036296}]}]}
{"op":"mcm","clk":"4216446840","pt":1631551868559,"mc":[{"id":"1.187607461","rc":[{"batb":[[0,1.98,30.61],[1,1.01,12]],"ltp":1.34,"tv":166.33,"id":16100628},{"batb":[[0,1.78,38.46],[1,1.01,12]],"ltp":2.06,"tv":103.11,"id":14036296}]}]}
{"op":"mcm","clk":"4216449263","pt":1631551904302,"mc":[{"id":"1.187607461","rc":[{"batb":[[0,1.01,12],[1,1.01,0]],"ltp":1.34,"tv":166.33,"id":16100628},{"batb":[[0,1.01,12],[1,1.01,0]],"ltp":2.06,"tv":103.11,"id":14036296}]}]}
{"op":"mcm","clk":"4216449624","pt":1631551909312,"mc":[{"id":"1.187607461","rc":[{"batb":[[0,2,30],[1,1.01,12]],"ltp":1.34,"tv":166.33,"id":16100628},{"batb":[[0,1.73,41.09],[1,1.01,12]],"ltp":2.06,"tv":103.11,"id":14036296}]}]}
{"op":"mcm","clk":"4216451597","pt":1631551938041,"mc":[{"id":"1.187607461","rc":[{"batb":[[0,1.01,12],[1,1.01,0]],"ltp":1.34,"tv":166.33,"id":16100628},{"batb":[[0,1.01,12],[1,1.01,0]],"ltp":2.06,"tv":103.11,"id":14036296}]}]}
{"op":"mcm","clk":"4216451915","pt":1631551943020,"mc":[{"id":"1.187607461","rc":[{"batb":[[0,1.88,34.09],[1,1.01,12]],"ltp":1.34,"tv":166.33,"id":16100628},{"batb":[[0,1.85,35.29],[1,1.01,12]],"ltp":2.06,"tv":103.11,"id":14036296}]}]}
{"op":"mcm","clk":"4216453143","pt":1631551960062,"mc":[{"id":"1.187607461","rc":[{"batb":[[0,1.01,12],[1,1.01,0]],"ltp":2.06,"tv":103.11,"id":14036296}]}]}
{"op":"mcm","clk":"4216453537","pt":1631551965072,"mc":[{"id":"1.187607461","rc":[{"batb":[[0,1.88,34.09],[1,1.01,12]],"ltp":2.06,"tv":103.11,"id":14036296}]}]}
{"op":"mcm","clk":"4216455017","pt":1631551986371,"mc":[{"id":"1.187607461","rc":[{"batb":[[0,1.01,12],[1,1.01,0]],"ltp":1.34,"tv":166.33,"id":16100628}]}]}
{"op":"mcm","clk":"4216455382","pt":1631551991382,"mc":[{"id":"1.187607461","rc":[{"batb":[[0,1.85,35.29],[1,1.01,12]],"ltp":1.34,"tv":166.33,"id":16100628}]}]}
{"op":"mcm","clk":"4216458396","pt":1631552033458,"mc":[{"id":"1.187607461","rc":[{"batb":[[0,1.01,12],[1,1.01,0]],"ltp":1.34,"tv":166.33,"id":16100628},{"batb":[[0,1.01,12],[1,1.01,0]],"ltp":2.06,"tv":103.11,"id":14036296}]}]}
{"op":"mcm","clk":"4216458780","pt":1631552038475,"mc":[{"id":"1.187607461","rc":[{"batb":[[0,1.78,38.46],[1,1.01,12]],"ltp":1.34,"tv":166.33,"id":16100628},{"batb":[[0,1.98,30.61],[1,1.01,12]],"ltp":2.06,"tv":103.11,"id":14036296}]}]}
{"op":"mcm","clk":"4216465408","pt":1631552125456,"mc":[{"id":"1.187607461","rc":[{"batb":[[0,1.01,12],[1,1.01,0]],"ltp":1.34,"tv":166.33,"id":16100628},{"batb":[[0,1.01,12],[1,1.01,0]],"ltp":2.06,"tv":103.11,"id":14036296}]}]}
{"op":"mcm","clk":"4216465816","pt":1631552130370,"mc":[{"id":"1.187607461","rc":[{"batb":[[0,1.88,34.09],[1,1.01,12]],"ltp":1.34,"tv":166.33,"id":16100628},{"batb":[[0,1.85,35.29],[1,1.01,12]],"ltp":2.06,"tv":103.11,"id":14036296}]}]}
{"op":"mcm","clk":"4216467097","pt":1631552146784,"mc":[{"id":"1.187607461","rc":[{"batb":[[0,1.01,12],[1,1.01,0]],"ltp":1.34,"tv":166.33,"id":16100628},{"batb":[[0,1.01,12],[1,1.01,0]],"ltp":2.06,"tv":103.11,"id":14036296}]}]}
{"op":"mcm","clk":"4216467448","pt":1631552151679,"mc":[{"id":"1.187607461","rc":[{"batb":[[0,2.06,28.3],[1,1.01,12]],"ltp":1.34,"tv":166.33,"id":16100628},{"batb":[[0,1.71,42.25],[1,1.01,12]],"ltp":2.06,"tv":103.11,"id":14036296}]}]}
{"op":"mcm","clk":"4216468037","pt":1631552160000,"mc":[{"id":"1.187607461","rc":[{"batb":[[0,1.01,12],[1,1.01,0]],"ltp":1.34,"tv":166.33,"id":16100628},{"batb":[[0,1.01,12],[1,1.01,0]],"ltp":2.06,"tv":103.11,"id":14036296}]}]}
{"op":"mcm","clk":"4216468463","pt":1631552165002,"mc":[{"id":"1.187607461","rc":[{"batb":[[0,2,30],[1,1.01,12]],"ltp":1.34,"tv":166.33,"id":16100628},{"batb":[[0,1.73,41.09],[1,1.01,12]],"ltp":2.06,"tv":103.11,"id":14036296}]}]}
{"op":"mcm","clk":"4216468917","pt":1631552170902,"mc":[{"id":"1.187607461","rc":[{"batb":[[0,1.01,12],[1,1.01,0]],"ltp":1.34,"tv":166.33,"id":16100628},{"batb":[[0,1.01,12],[1,1.01,0]],"ltp":2.06,"tv":103.11,"id":14036296}]}]}
{"op":"mcm","clk":"4216469322","pt":1631552175895,"mc":[{"id":"1.187607461","rc":[{"batb":[[0,2.06,28.3],[1,1.01,12]],"ltp":1.34,"tv":166.33,"id":16100628},{"batb":[[0,1.71,42.25],[1,1.01,12]],"ltp":2.06,"tv":103.11,"id":14036296}]}]}
{"op":"mcm","clk":"4216471158","pt":1631552199697,"mc":[{"id":"1.187607461","rc":[{"batb":[[0,1.01,12],[1,1.01,0]],"ltp":1.34,"tv":166.33,"id":16100628},{"batb":[[0,1.01,12],[1,1.01,0]],"ltp":2.06,"tv":103.11,"id":14036296}]}]}
{"op":"mcm","clk":"4216471525","pt":1631552204704,"mc":[{"id":"1.187607461","rc":[{"batb":[[0,2,30],[1,1.01,12]],"ltp":1.34,"tv":166.33,"id":16100628},{"batb":[[0,1.73,41.09],[1,1.01,12]],"ltp":2.06,"tv":103.11,"id":14036296}]}]}
{"op":"mcm","clk":"4216473298","pt":1631552227722,"mc":[{"id":"1.187607461","rc":[{"batb":[[0,1.01,12],[1,1.01,0]],"ltp":1.34,"tv":166.33,"id":16100628},{"batb":[[0,1.01,12],[1,1.01,0]],"ltp":2.06,"tv":103.11,"id":14036296}]}]}
{"op":"mcm","clk":"4216473659","pt":1631552232606,"mc":[{"id":"1.187607461","rc":[{"batb":[[0,2.1,27.27],[1,1.01,12]],"ltp":1.34,"tv":166.33,"id":16100628},{"batb":[[0,1.65,46.15],[1,1.01,12]],"ltp":2.06,"tv":103.11,"id":14036296}]}]}
{"op":"mcm","clk":"4216478578","pt":1631552300760,"mc":[{"id":"1.187607461","rc":[{"trd":[[2.1,54.53]],"batb":[[0,1.01,12],[1,1.01,0]],"batl":[[0,2.1,58.01],[1,2.84,104.59]],"ltp":2.1,"tv":220.86,"id":16100628}],"tv":323.98}]}
{"op":"mcm","clk":"4216478755","pt":1631552303510,"mc":[{"id":"1.187607461","rc":[{"batl":[[0,2.84,104.59],[1,2.84,0]],"ltp":2.1,"tv":220.86,"id":16100628}]}]}
{"op":"mcm","clk":"4216478897","pt":1631552305922,"mc":[{"id":"1.187607461","rc":[{"batb":[[0,1.98,30.61],[1,1.01,12]],"ltp":2.1,"tv":220.86,"id":16100628}]}]}
{"op":"mcm","clk":"4216480049","pt":1631552323569,"mc":[{"id":"1.187607461","rc":[{"batb":[[0,1.01,12],[1,1.01,0]],"ltp":2.1,"tv":220.86,"id":16100628},{"batb":[[0,1.01,12],[1,1.01,0]],"ltp":2.06,"tv":103.11,"id":14036296}]}]}
{"op":"mcm","clk":"4216480388","pt":1631552328461,"mc":[{"id":"1.187607461","rc":[{"batb":[[0,2.26,23.8],[1,1.01,12]],"ltp":2.1,"tv":220.86,"id":16100628},{"batb":[[0,1.58,51.72],[1,1.01,12]],"ltp":2.06,"tv":103.11,"id":14036296}]}]}
{"op":"mcm","clk":"4216481544","pt":1631552343585,"mc":[{"id":"1.187607461","rc":[{"batb":[[0,1.01,12],[1,1.01,0]],"ltp":2.1,"tv":220.86,"id":16100628},{"batb":[[0,1.01,12],[1,1.01,0]],"ltp":2.06,"tv":103.11,"id":14036296}]}]}
{"op":"mcm","clk":"4216481941","pt":1631552348468,"mc":[{"id":"1.187607461","rc":[{"batb":[[0,2.16,25.86],[1,1.01,12]],"ltp":2.1,"tv":220.86,"id":16100628},{"batb":[[0,1.63,47.61],[1,1.01,12]],"ltp":2.06,"tv":103.11,"id":14036296}]}]}
{"op":"mcm","clk":"4216482266","pt":1631552352966,"mc":[{"id":"1.187607461","rc":[{"batb":[[0,1.01,12],[1,1.01,0]],"ltp":2.1,"tv":220.86,"id":16100628},{"batb":[[0,1.01,12],[1,1.01,0]],"ltp":2.06,"tv":103.11,"id":14036296}]}]}
{"op":"mcm","clk":"4216482686","pt":1631552357984,"mc":[{"id":"1.187607461","rc":[{"batb":[[0,2.1,27.27],[1,1.01,12]],"ltp":2.1,"tv":220.86,"id":16100628},{"batb":[[0,1.65,46.15],[1,1.01,12]],"ltp":2.06,"tv":103.11,"id":14036296}]}]}
{"op":"mcm","clk":"4216482977","pt":1631552361711,"mc":[{"id":"1.187607461","rc":[{"batb":[[0,1.01,12],[1,1.01,0]],"ltp":2.1,"tv":220.86,"id":16100628},{"batb":[[0,1.01,12],[1,1.01,0]],"ltp":2.06,"tv":103.11,"id":14036296}]}]}
{"op":"mcm","clk":"4216483690","pt":1631552366696,"mc":[{"id":"1.187607461","rc":[{"batb":[[0,1.71,42.25],[1,1.01,12]],"ltp":2.1,"tv":220.86,"id":16100628},{"batb":[[0,2.06,28.3],[1,1.01,12]],"ltp":2.06,"tv":103.11,"id":14036296}]}]}
{"op":"mcm","clk":"4216485116","pt":1631552384246,"mc":[{"id":"1.187607461","rc":[{"batb":[[0,1.01,12],[1,1.01,0]],"ltp":2.1,"tv":220.86,"id":16100628},{"batb":[[0,1.01,12],[1,1.01,0]],"ltp":2.06,"tv":103.11,"id":14036296}]}]}
{"op":"mcm","clk":"4216485543","pt":1631552389115,"mc":[{"id":"1.187607461","rc":[{"batb":[[0,1.65,46.15],[1,1.01,12]],"ltp":2.1,"tv":220.86,"id":16100628},{"batb":[[0,2.1,27.27],[1,1.01,12]],"ltp":2.06,"tv":103.11,"id":14036296}]}]}
{"op":"mcm","clk":"4216486385","pt":1631552398931,"mc":[{"id":"1.187607461","rc":[{"batb":[[0,1.01,12],[1,1.01,0]],"ltp":2.1,"tv":220.86,"id":16100628},{"batb":[[0,1.01,12],[1,1.01,0]],"ltp":2.06,"tv":103.11,"id":14036296}]}]}
{"op":"mcm","clk":"4216487010","pt":1631552403901,"mc":[{"id":"1.187607461","rc":[{"trd":[[1.34,7.96],[1.45,3.42],[1.65,17.06],[1.73,31.78],[1.85,14.45],[2.1,54.55]],"batb":[[0,2,30],[1,1.01,12]],"batl":[[0,2.84,104.58]],"ltp":2.1,"tv":220.91,"id":16100628},{"trd":[[1.54,3.46],[2.06,39.67]],"batb":[[0,1.73,41.09],[1,1.01,12]],"ltp":2.06,"tv":103.13,"id":14036296}],"tv":324.04}]}
{"op":"mcm","clk":"4216488689","pt":1631552420401,"mc":[{"id":"1.187607461","rc":[{"batb":[[0,1.01,12],[1,1.01,0]],"ltp":2.1,"tv":220.91,"id":16100628},{"batb":[[0,1.01,12],[1,1.01,0]],"ltp":2.06,"tv":103.13,"id":14036296}]}]}
{"op":"mcm","clk":"4216489174","pt":1631552425404,"mc":[{"id":"1.187607461","rc":[{"batb":[[0,2.5,20],[1,1.01,12]],"ltp":2.1,"tv":220.91,"id":16100628},{"batb":[[0,1.48,62.5],[1,1.01,12]],"ltp":2.06,"tv":103.13,"id":14036296}]}]}
{"op":"mcm","clk":"4216491942","pt":1631552456566,"mc":[{"id":"1.187607461","rc":[{"batb":[[0,1.01,12],[1,1.01,0]],"ltp":2.1,"tv":220.91,"id":16100628},{"batb":[[0,1.01,12],[1,1.01,0]],"ltp":2.06,"tv":103.13,"id":14036296}]}]}
{"op":"mcm","clk":"4216492521","pt":1631552461564,"mc":[{"id":"1.187607461","rc":[{"batb":[[0,1.98,30.61],[1,1.01,12]],"ltp":2.1,"tv":220.91,"id":16100628},{"batb":[[0,1.78,38.46],[1,1.67,29.95],[2,1.01,12]],"ltp":2.06,"tv":103.13,"id":14036296}]}]}
{"op":"mcm","clk":"4216492566","pt":1631552461988,"mc":[{"id":"1.187607461","rc":[{"batb":[[1,1.01,12],[2,1.01,0]],"ltp":2.06,"tv":103.13,"id":14036296}]}]}
{"op":"mcm","clk":"4216492845","pt":1631552464568,"mc":[{"id":"1.187607461","rc":[{"batl":[[0,1.9,2.6]],"ltp":2.06,"tv":103.13,"id":14036296}]}]}
{"op":"mcm","clk":"4216494823","pt":1631552484816,"mc":[{"id":"1.187607461","rc":[{"batb":[[0,1.01,12],[1,1.01,0]],"ltp":2.1,"tv":220.91,"id":16100628},{"batb":[[0,1.01,12],[1,1.01,0]],"ltp":2.06,"tv":103.13,"id":14036296}]}]}
{"op":"mcm","clk":"4216495304","pt":1631552489700,"mc":[{"id":"1.187607461","rc":[{"batb":[[0,1.65,46.15],[1,1.01,12]],"ltp":2.1,"tv":220.91,"id":16100628}]}]}
{"op":"mcm","clk":"4216495510","pt":1631552492221,"mc":[{"id":"1.187607461","rc":[{"batb":[[0,2.1,27.27],[1,1.01,12]],"ltp":2.06,"tv":103.13,"id":14036296}]}]}
{"op":"mcm","clk":"4216497203","pt":1631552508430,"mc":[{"id":"1.187607461","rc":[{"batb":[[0,1.01,12],[1,1.01,0]],"ltp":2.1,"tv":220.91,"id":16100628},{"batb":[[0,1.01,12],[1,1.01,0]],"ltp":2.06,"tv":103.13,"id":14036296}]}]}
{"op":"mcm","clk":"4216497695","pt":1631552513432,"mc":[{"id":"1.187607461","rc":[{"batb":[[0,1.38,78.94],[1,1.01,12]],"ltp":2.1,"tv":220.91,"id":16100628},{"batb":[[0,2.84,16.3],[1,1.01,12]],"ltp":2.06,"tv":103.13,"id":14036296}]}]}
{"op":"mcm","clk":"4216502739","pt":1631552561581,"mc":[{"id":"1.187607461","rc":[{"batb":[[0,1.01,12],[1,1.01,0]],"ltp":2.1,"tv":220.91,"id":16100628},{"batb":[[0,1.01,12],[1,1.01,0]],"ltp":2.06,"tv":103.13,"id":14036296}]}]}
{"op":"mcm","clk":"4216503227","pt":1631552566581,"mc":[{"id":"1.187607461","rc":[{"batb":[[0,1.31,96.77],[1,1.01,12]],"ltp":2.1,"tv":220.91,"id":16100628},{"batb":[[0,3.15,13.95],[1,1.01,12]],"ltp":2.06,"tv":103.13,"id":14036296}]}]}
{"op":"mcm","clk":"4216504507","pt":1631552578880,"mc":[{"id":"1.187607461","rc":[{"batb":[[0,1.01,12],[1,1.01,0]],"ltp":2.1,"tv":220.91,"id":16100628},{"batb":[[0,1.01,12],[1,1.01,0]],"ltp":2.06,"tv":103.13,"id":14036296}]}]}
{"op":"mcm","clk":"4216505077","pt":1631552583797,"mc":[{"id":"1.187607461","rc":[{"batb":[[0,1.18,166.66],[1,1.01,12]],"ltp":2.1,"tv":220.91,"id":16100628},{"batb":[[0,4.3,10],[1,1.01,12]],"ltp":2.06,"tv":103.13,"id":14036296}]}]}
{"op":"mcm","clk":"4216507329","pt":1631552605590,"mc":[{"id":"1.187607461","rc":[{"trd":[[1.18,289.08]],"batb":[[0,1.01,12],[1,1.01,0]],"ltp":1.18,"tv":509.99,"id":16100628}],"tv":613.12}]}
{"op":"mcm","clk":"4216507844","pt":1631552610472,"mc":[{"id":"1.187607461","rc":[{"batb":[[0,1.11,272.72],[1,1.01,12]],"ltp":1.18,"tv":509.99,"id":16100628}]}]}
{"op":"mcm","clk":"4216509933","pt":1631552631151,"mc":[{"id":"1.187607461","rc":[{"batb":[[0,1.01,12],[1,1.01,0]],"ltp":1.18,"tv":509.99,"id":16100628},{"batb":[[0,1.01,12],[1,1.01,0]],"ltp":2.06,"tv":103.13,"id":14036296}]}]}
{"op":"mcm","clk":"4216510439","pt":1631552636090,"mc":[{"id":"1.187607461","rc":[{"batb":[[0,1.31,96.77],[1,1.01,12]],"ltp":1.18,"tv":509.99,"id":16100628},{"batb":[[0,3.15,13.95],[1,1.01,12]],"ltp":2.06,"tv":103.13,"id":14036296}]}]}
{"op":"mcm","clk":"4216512741","pt":1631552658329,"mc":[{"id":"1.187607461","rc":[{"batb":[[0,1.01,12],[1,1.01,0]],"ltp":1.18,"tv":509.99,"id":16100628},{"batb":[[0,1.01,12],[1,1.01,0]],"ltp":2.06,"tv":103.13,"id":14036296}]}]}
{"op":"mcm","clk":"4216513277","pt":1631552663341,"mc":[{"id":"1.187607461","rc":[{"batb":[[0,1.6,49.99],[1,1.01,12]],"ltp":1.18,"tv":509.99,"id":16100628},{"batb":[[0,2.2,24.99],[1,1.01,12]],"ltp":2.06,"tv":103.13,"id":14036296}]}]}
{"op":"mcm","clk":"4216515421","pt":1631552684494,"mc":[{"id":"1.187607461","rc":[{"batb":[[0,1.01,12],[1,1.01,0]],"ltp":1.18,"tv":509.99,"id":16100628},{"batb":[[0,1.01,12],[1,1.01,0]],"ltp":2.06,"tv":103.13,"id":14036296}]}]}
{"op":"mcm","clk":"4216515925","pt":1631552689520,"mc":[{"id":"1.187607461","rc":[{"batb":[[0,1.28,107.14],[1,1.01,12]],"ltp":1.18,"tv":509.99,"id":16100628},{"batb":[[0,3.3,13.04],[1,1.01,12]],"ltp":2.06,"tv":103.13,"id":14036296}]}]}
{"op":"mcm","clk":"4216516998","pt":1631552699524,"mc":[{"id":"1.187607461","rc":[{"batb":[[0,1.01,12],[1,1.01,0]],"ltp":1.18,"tv":509.99,"id":16100628},{"batb":[[0,1.01,12],[1,1.01,0]],"ltp":2.06,"tv":103.13,"id":14036296}]}]}
{"op":"mcm","clk":"4216517579","pt":1631552704356,"mc":[{"id":"1.187607461","rc":[{"batb":[[0,1.27,111.11],[1,1.01,12]],"ltp":1.18,"tv":509.99,"id":16100628},{"batb":[[0,3.4,12.5],[1,1.01,12]],"ltp":2.06,"tv":103.13,"id":14036296}]}]}
{"op":"mcm","clk":"4216519085","pt":1631552717879,"mc":[{"id":"1.187607461","rc":[{"batb":[[0,1.01,12],[1,1.01,0]],"ltp":1.18,"tv":509.99,"id":16100628},{"batb":[[0,1.01,12],[1,1.01,0]],"ltp":2.06,"tv":103.13,"id":14036296}]}]}
{"op":"mcm","clk":"4216519636","pt":1631552722882,"mc":[{"id":"1.187607461","rc":[{"batb":[[0,1.48,62.5],[1,1.01,12]],"ltp":1.18,"tv":509.99,"id":16100628},{"batb":[[0,2.5,20],[1,1.01,12]],"ltp":2.06,"tv":103.13,"id":14036296}]}]}
{"op":"mcm","clk":"4216520188","pt":1631552728556,"mc":[{"id":"1.187607461","rc":[{"trd":[[1.48,125]],"batb":[[0,1.01,12],[1,1.01,0]],"ltp":1.48,"tv":634.99,"id":16100628},{"batb":[[0,3.1,2],[1,2.5,20],[2,1.01,12]],"ltp":2.06,"tv":103.13,"id":14036296}],"tv":738.12}]}
{"op":"mcm","clk":"4216520227","pt":1631552729088,"mc":[{"id":"1.187607461","rc":[{"batb":[[0,2.5,20],[1,1.01,12],[2,1.01,0]],"ltp":2.06,"tv":103.13,"id":14036296}]}]}
{"op":"mcm","clk":"4216520707","pt":1631552733498,"mc":[{"id":"1.187607461","rc":[{"batb":[[0,1.41,73.17],[1,1.01,12]],"ltp":1.48,"tv":634.99,"id":16100628}]}]}
{"op":"mcm","clk":"4216522438","pt":1631552751090,"mc":[{"id":"1.187607461","rc":[{"batb":[[0,1.01,12],[1,1.01,0]],"ltp":1.48,"tv":634.99,"id":16100628},{"batb":[[0,1.01,12],[1,1.01,0]],"ltp":2.06,"tv":103.13,"id":14036296}]}]}
{"op":"mcm","clk":"4216522961","pt":1631552755994,"mc":[{"id":"1.187607461","rc":[{"batb":[[0,1.23,130.43],[1,1.01,12]],"ltp":1.48,"tv":634.99,"id":16100628},{"batb":[[0,3.7,11.11],[1,1.01,12]],"ltp":2.06,"tv":103.13,"id":14036296}]}]}
{"op":"mcm","clk":"4216527446","pt":1631552800236,"mc":[{"id":"1.187607461","rc":[{"batb":[[0,1.01,12],[1,1.01,0]],"ltp":1.48,"tv":634.99,"id":16100628},{"batb":[[0,1.01,12],[1,1.01,0]],"ltp":2.06,"tv":103.13,"id":14036296}]}]}
{"op":"mcm","clk":"4216527982","pt":1631552805281,"mc":[{"id":"1.187607461","rc":[{"batb":[[0,1.08,374.99],[1,1.01,12]],"ltp":1.48,"tv":634.99,"id":16100628},{"batb":[[0,6,10],[1,1.01,12]],"ltp":2.06,"tv":103.13,"id":14036296}]}]}
{"op":"mcm","clk":"4216529174","pt":1631552817073,"mc":[{"id":"1.187607461","rc":[{"batb":[[0,1.01,12],[1,1.01,0]],"ltp":1.48,"tv":634.99,"id":16100628},{"batb":[[0,1.01,12],[1,1.01,0]],"ltp":2.06,"tv":103.13,"id":14036296}]}]}
{"op":"mcm","clk":"4216529691","pt":1631552821997,"mc":[{"id":"1.187607461","rc":[{"batb":[[0,1.18,166.66],[1,1.01,12]],"ltp":1.48,"tv":634.99,"id":16100628},{"batb":[[0,4.3,10],[1,1.01,12]],"ltp":2.06,"tv":103.13,"id":14036296}]}]}
{"op":"mcm","clk":"4216531181","pt":1631552834124,"mc":[{"id":"1.187607461","rc":[{"batb":[[0,1.01,12],[1,1.01,0]],"ltp":1.48,"tv":634.99,"id":16100628},{"batb":[[0,1.01,12],[1,1.01,0]],"ltp":2.06,"tv":103.13,"id":14036296}]}]}
{"op":"mcm","clk":"4216531716","pt":1631552839097,"mc":[{"id":"1.187607461","rc":[{"batb":[[0,1.15,200],[1,1.01,12]],"ltp":1.48,"tv":634.99,"id":16100628},{"batb":[[0,4.8,10],[1,1.01,12]],"ltp":2.06,"tv":103.13,"id":14036296}]}]}
{"op":"mcm","clk":"4216533896","pt":1631552858568,"mc":[{"id":"1.187607461","rc":[{"batb":[[0,1.01,12],[1,1.01,0]],"ltp":1.48,"tv":634.99,"id":16100628},{"batb":[[0,1.01,12],[1,1.01,0]],"ltp":2.06,"tv":103.13,"id":14036296}]}]}
{"op":"mcm","clk":"4216534430","pt":1631552863564,"mc":[{"id":"1.187607461","rc":[{"batb":[[0,12,10],[1,1.01,12]],"ltp":2.06,"tv":103.13,"id":14036296}]}]}
{"op":"mcm","clk":"4216536854","pt":1631552891078,"mc":[{"id":"1.187607461","rc":[{"batb":[[0,1.01,12],[1,1.01,0]],"ltp":2.06,"tv":103.13,"id":14036296}]}]}
{"op":"mcm","clk":"4216541575","pt":1631552946869,"mc":[{"id":"1.187607461","marketDefinition":{"bspMarket":false,"turnInPlayEnabled":true,"persistenceEnabled":true,"marketBaseRate":5.0,"eventId":"30898293","eventTypeId":"2","numberOfWinners":1,"bettingType":"ODDS","marketType":"MATCH_ODDS","marketTime":"2021-09-13T15:30:48.000Z","suspendTime":"2021-09-13T15:30:48.000Z","bspReconciled":false,"complete":true,"inPlay":true,"crossMatching":true,"runnersVoidable":false,"numberOfActiveRunners":2,"betDelay":5,"status":"SUSPENDED","runners":[{"status":"ACTIVE","sortPriority":1,"id":14036296,"name":"E Avanesyan"},{"status":"ACTIVE","sortPriority":2,"id":16100628,"name":"G Maristany Zuleta de Reales"}],"regulators":["MR_INT"],"countryCode":"GB","discountAllowed":true,"timezone":"GMT","openDate":"2021-09-13T15:30:48.000Z","version":4030989773,"name":"Match Odds","eventName":"E Avanesyan v G Maristany Zuleta De Reales"}}]}
{"op":"mcm","clk":"4216542048","pt":1631552952524,"mc":[{"id":"1.187607461","tv":0.0}]}
{"op":"mcm","clk":"4216542169","pt":1631552953912,"mc":[{"id":"1.187607461","marketDefinition":{"bspMarket":false,"turnInPlayEnabled":true,"persistenceEnabled":true,"marketBaseRate":5.0,"eventId":"30898293","eventTypeId":"2","numberOfWinners":1,"bettingType":"ODDS","marketType":"MATCH_ODDS","marketTime":"2021-09-13T15:30:48.000Z","suspendTime":"2021-09-13T15:30:48.000Z","bspReconciled":false,"complete":true,"inPlay":true,"crossMatching":false,"runnersVoidable":false,"numberOfActiveRunners":0,"betDelay":5,"status":"CLOSED","settledTime":"2021-09-13T17:09:09.000Z","runners":[{"status":"LOSER","sortPriority":1,"id":14036296,"name":"E Avanesyan"},{"status":"WINNER","sortPriority":2,"id":16100628,"name":"G Maristany Zuleta de Reales"}],"regulators":["MR_INT"],"countryCode":"GB","discountAllowed":true,"timezone":"GMT","openDate":"2021-09-13T15:30:48.000Z","version":4030989817,"name":"Match Odds","eventName":"E Avanesyan v G Maristany Zuleta De Reales"}}]}
